Workbook

Sheet Sheet1
A1: Site Name | B1: Month | C1: Year | D1: Purchased Electricity Kwh | E1: Purchased Electricity Tariff ($/Kwh) | F1: Total Renewable Energy Production Kwh | G1: Electricity Total Budgeted | H1: Electricity Total Budgeted Cost ($) | I1: LPG Kitchen (Liters) | J1: LPG Kitchen $/Liters | K1: LPG Total Budgeted | L1: LPG Total Budgeted Cost ($) | M1: Fuel Oil Hot-Water Boilers (Liter) Liter | N1: Fuel Oil Hot-Water Boilers (Liter) $/Liter | O1: Fuel Oil Total Budgeted | P1: Fuel Oil Total Budgeted Cost ($) | Q1: District Energy Heating KWh | R1: District Energy Heating $/KWh | S1: Heating District Energy Total Budgeted | T1: Heating District Energy Total Budgeted Cost ($) | U1: Water Utility Supply (m3) m3 | V1: Water Utility Supply (m3) $/m3 | W1: Water Total Budgeted | X1: Water Total Budgeted Cost ($) | Y1: Room Nights | Z1: Total Guests
A2: Annabelle | B2: 1 | C2: 2026 | D2: =Worksheet!D86 -> 82116 | E2: =Worksheet!E86 -> 0.18 | F2: =Worksheet!AJ86 -> 15177 | G2: =Worksheet!I86 -> 124702 | H2: =Worksheet!J86 -> 31425 | I2: =Worksheet!K86 -> 1344 | J2: =Worksheet!L86 -> 0.76 | K2: =Worksheet!N86 -> 2237 | L2: =Worksheet!O86 -> 1566 | M2: =Worksheet!AP86 -> 8259 | N2: =Worksheet!AQ86 -> 0.74 | O2: =Worksheet!AX86 -> 0 | P2: =Worksheet!AY86 -> 0 | Q2: =Worksheet!P86 -> 0 | R2: =Worksheet!Q86 -> 0 | S2: =Worksheet!S86 -> 131947 | T2: =Worksheet!T86 -> 0 | U2: =Worksheet!U86 -> 76 | V2: =Worksheet!V86 -> 2.9 | W2: =Worksheet!X86 -> 807 | X2: =Worksheet!Y86 -> 2342 | Y2: =Worksheet!Z86 -> 1194 | Z2: =Worksheet!AC86 -> 1806
A3: Annabelle | B3: 2 | C3: 2026 | D3: =Worksheet!D87 -> 53711 | E3: =Worksheet!E87 -> 0.11 | F3: =Worksheet!AJ87 -> 25405 | G3: =Worksheet!I87 -> 125023 | H3: =Worksheet!J87 -> 31506 | I3: =Worksheet!K87 -> 500 | J3: =Worksheet!L87 -> 0.76 | K3: =Worksheet!N87 -> 2549 | L3: =Worksheet!O87 -> 1784 | M3: =Worksheet!AP87 -> 2143 | N3: =Worksheet!AQ87 -> 0.74 | O3: =Worksheet!AX87 -> 0 | P3: =Worksheet!AY87 -> 0 | Q3: =Worksheet!P87 -> 0 | R3: =Worksheet!Q87 -> 0 | S3: =Worksheet!S87 -> 198349 | T3: =Worksheet!T87 -> 0 | U3: =Worksheet!U87 -> 0 | V3: =Worksheet!V87 -> 0 | W3: =Worksheet!X87 -> 662 | X3: =Worksheet!Y87 -> 1602 | Y3: =Worksheet!Z87 -> 198 | Z3: =Worksheet!AC87 -> 377
A4: Annabelle | B4: 3 | C4: 2026 | D4: =Worksheet!D88 -> 146529 | E4: =Worksheet!E88 -> 0.16 | F4: =Worksheet!AJ88 -> 29080 | G4: =Worksheet!I88 -> 152841 | H4: =Worksheet!J88 -> 38516 | I4: =Worksheet!K88 -> 2825 | J4: =Worksheet!L88 -> 0.88 | K4: =Worksheet!N88 -> 3481 | L4: =Worksheet!O88 -> 2437 | M4: =Worksheet!AP88 -> 13232 | N4: =Worksheet!AQ88 -> 0.83 | O4: =Worksheet!AX88 -> 0 | P4: =Worksheet!AY88 -> 0 | Q4: =Worksheet!P88 -> 23461 | R4: =Worksheet!Q88 -> 0.0938 | S4: =Worksheet!S88 -> 183128 | T4: =Worksheet!T88 -> 2230 | U4: =Worksheet!U88 -> 1394 | V4: =Worksheet!V88 -> 2.88 | W4: =Worksheet!X88 -> 5072 | X4: =Worksheet!Y88 -> 12273 | Y4: =Worksheet!Z88 -> 3186 | Z4: =Worksheet!AC88 -> 5494
A5: Annabelle | B5: 4 | C5: 2026 | D5: =Worksheet!D89 -> 157388 | E5: =Worksheet!E89 -> 0.19 | F5: =Worksheet!AJ89 -> 27544 | G5: =Worksheet!I89 -> 178614 | H5: =Worksheet!J89 -> 45011 | I5: =Worksheet!K89 -> 3132 | J5: =Worksheet!L89 -> 1.03 | K5: =Worksheet!N89 -> 4411 | L5: =Worksheet!O89 -> 3088 | M5: =Worksheet!AP89 -> 10582 | N5: =Worksheet!AQ89 -> 1.08 | O5: =Worksheet!AX89 -> 1198 | P5: =Worksheet!AY89 -> 791 | Q5: =Worksheet!P89 -> 26762 | R5: =Worksheet!Q89 -> 0.1131 | S5: =Worksheet!S89 -> 164934 | T5: =Worksheet!T89 -> 2299 | U5: =Worksheet!U89 -> 2996 | V5: =Worksheet!V89 -> 2.88 | W5: =Worksheet!X89 -> 3509 | X5: =Worksheet!Y89 -> 8491 | Y5: =Worksheet!Z89 -> 5315 | Z5: =Worksheet!AC89 -> 9107
A6: Annabelle | B6: 5 | C6: 2026 | D6: 148633 | E6: =Worksheet!E91 -> 0.23 | F6: 34871 | G6: =Worksheet!I91 -> 303801 | H6: =Worksheet!J91 -> 77469 | I6: =Worksheet!K91 -> 7462 | J6: 0.62 | K6: =Worksheet!N91 -> 6682 | L6: =Worksheet!O91 -> 3063 | M6: 11342 | N6: 0.88 | O6: =Worksheet!AX91 -> 17582 | P6: =Worksheet!AY91 -> 11769 | Q6: =Worksheet!P91 -> 0 | R6: =Worksheet!Q91 -> 0 | S6: =Worksheet!S91 -> 77414 | T6: =Worksheet!T91 -> 7834 | U6: 3377 | V6: 2.42 | W6: =Worksheet!X91 -> 2997 | X6: =Worksheet!Y91 -> 4136 | Y6: 5907 | Z6: 11083
A7: Annabelle | B7: 6 | C7: 2026 | D7: 194344 | E7: =Worksheet!E92 -> 0.22 | F7: 46910 | G7: =Worksheet!I92 -> 202116 | H7: =Worksheet!J92 -> 50933 | I7: 3149 | J7: 0.62 | K7: =Worksheet!N92 -> 4079 | L7: =Worksheet!O92 -> 2855 | M7: =Worksheet!AP92 -> 4167 | N7: =Worksheet!AQ92 -> 0.88 | O7: =Worksheet!AX92 -> 0 | P7: =Worksheet!AY92 -> 0 | Q7: =Worksheet!P92 -> 0 | R7: =Worksheet!Q92 -> 0 | S7: =Worksheet!S92 -> 53273 | T7: =Worksheet!T92 -> 961 | U7: =Worksheet!U92 -> 3657 | V7: =Worksheet!V92 -> 2.42 | W7: =Worksheet!X92 -> 4092 | X7: =Worksheet!Y92 -> 9903 | Y7: =Worksheet!Z92 -> 6115 | Z7: =Worksheet!AC92 -> 11926
A8: Annabelle | B8: 7 | C8: 2026 | D8: =Worksheet!D93 -> 0 | E8: =Worksheet!E93 -> 0 | F8: =Worksheet!AJ93 -> 0 | G8: =Worksheet!I93 -> 218956 | H8: =Worksheet!J93 -> 55177 | I8: =Worksheet!K93 -> 0 | J8: =Worksheet!L93 -> 0 | K8: =Worksheet!N93 -> 3544 | L8: =Worksheet!O93 -> 2481 | M8: =Worksheet!AP93 -> 0 | N8: =Worksheet!AQ93 -> 0 | O8: =Worksheet!AX93 -> 0 | P8: =Worksheet!AY93 -> 0 | Q8: =Worksheet!P93 -> 0 | R8: =Worksheet!Q93 -> 0 | S8: =Worksheet!S93 -> 31777 | T8: =Worksheet!T93 -> 1530 | U8: =Worksheet!U93 -> 0 | V8: =Worksheet!V93 -> 0 | W8: =Worksheet!X93 -> 4399 | X8: =Worksheet!Y93 -> 10645 | Y8: =Worksheet!Z93 -> 0 | Z8: =Worksheet!AC93 -> 0
A9: Annabelle | B9: 8 | C9: 2026 | D9: =Worksheet!D94 -> 0 | E9: =Worksheet!E94 -> 0 | F9: =Worksheet!AJ94 -> 0 | G9: =Worksheet!I94 -> 236941 | H9: =Worksheet!J94 -> 59709 | I9: =Worksheet!K94 -> 0 | J9: =Worksheet!L94 -> 0 | K9: =Worksheet!N94 -> 4263 | L9: =Worksheet!O94 -> 2984 | M9: =Worksheet!AP94 -> 0 | N9: =Worksheet!AQ94 -> 0 | O9: =Worksheet!AX94 -> 0 | P9: =Worksheet!AY94 -> 0 | Q9: =Worksheet!P94 -> 0 | R9: =Worksheet!Q94 -> 0 | S9: =Worksheet!S94 -> 33894 | T9: =Worksheet!T94 -> 1377 | U9: =Worksheet!U94 -> 0 | V9: =Worksheet!V94 -> 0 | W9: =Worksheet!X94 -> 5196 | X9: =Worksheet!Y94 -> 12573 | Y9: =Worksheet!Z94 -> 0 | Z9: =Worksheet!AC94 -> 0
A10: Annabelle | B10: 9 | C10: 2026 | D10: =Worksheet!D95 -> 0 | E10: =Worksheet!E95 -> 0 | F10: =Worksheet!AJ95 -> 0 | G10: =Worksheet!I95 -> 245452 | H10: =Worksheet!J95 -> 61854 | I10: =Worksheet!K95 -> 0 | J10: =Worksheet!L95 -> 0 | K10: =Worksheet!N95 -> 3720 | L10: =Worksheet!O95 -> 2604 | M10: =Worksheet!AP95 -> 0 | N10: =Worksheet!AQ95 -> 0 | O10: =Worksheet!AX95 -> 0 | P10: =Worksheet!AY95 -> 0 | Q10: =Worksheet!P95 -> 0 | R10: =Worksheet!Q95 -> 0 | S10: =Worksheet!S95 -> 31298 | T10: =Worksheet!T95 -> 511 | U10: =Worksheet!U95 -> 0 | V10: =Worksheet!V95 -> 0 | W10: =Worksheet!X95 -> 3574 | X10: =Worksheet!Y95 -> 8649 | Y10: =Worksheet!Z95 -> 0 | Z10: =Worksheet!AC95 -> 0
A11: Annabelle | B11: 10 | C11: 2026 | D11: =Worksheet!D96 -> 0 | E11: =Worksheet!E96 -> 0 | F11: =Worksheet!AJ96 -> 0 | G11: =Worksheet!I96 -> 204561 | H11: =Worksheet!J96 -> 51549 | I11: =Worksheet!K96 -> 0 | J11: =Worksheet!L96 -> 0 | K11: =Worksheet!N96 -> 4649 | L11: =Worksheet!O96 -> 3254 | M11: =Worksheet!AP96 -> 0 | N11: =Worksheet!AQ96 -> 0 | O11: =Worksheet!AX96 -> 1034 | P11: =Worksheet!AY96 -> 693 | Q11: =Worksheet!P96 -> 0 | R11: =Worksheet!Q96 -> 0 | S11: =Worksheet!S96 -> 57582 | T11: =Worksheet!T96 -> 2522 | U11: =Worksheet!U96 -> 0 | V11: =Worksheet!V96 -> 0 | W11: =Worksheet!X96 -> 4648 | X11: =Worksheet!Y96 -> 11248 | Y11: =Worksheet!Z96 -> 0 | Z11: =Worksheet!AC96 -> 0
A12: Annabelle | B12: 11 | C12: 2026 | D12: =Worksheet!D97 -> 0 | E12: =Worksheet!E97 -> 0 | F12: =Worksheet!AJ97 -> 0 | G12: =Worksheet!I97 -> 163791 | H12: =Worksheet!J97 -> 41725 | I12: =Worksheet!K97 -> 0 | J12: =Worksheet!L97 -> 0 | K12: =Worksheet!N97 -> 3731 | L12: =Worksheet!O97 -> 2612 | M12: =Worksheet!AP97 -> 0 | N12: =Worksheet!AQ97 -> 0 | O12: =Worksheet!AX97 -> 0 | P12: =Worksheet!AY97 -> 0 | Q12: =Worksheet!P97 -> 0 | R12: =Worksheet!Q97 -> 0 | S12: =Worksheet!S97 -> 73256 | T12: =Worksheet!T97 -> 1024 | U12: =Worksheet!U97 -> 0 | V12: =Worksheet!V97 -> 0 | W12: =Worksheet!X97 -> 3565 | X12: =Worksheet!Y97 -> 8627 | Y12: =Worksheet!Z97 -> 0 | Z12: =Worksheet!AC97 -> 0
A13: Annabelle | B13: 12 | C13: 2026 | D13: =Worksheet!D98 -> 0 | E13: =Worksheet!E98 -> 0 | F13: =Worksheet!AJ98 -> 0 | G13: =Worksheet!I98 -> 140763 | H13: =Worksheet!J98 -> 35472 | I13: =Worksheet!K98 -> 0 | J13: =Worksheet!L98 -> 0 | K13: =Worksheet!N98 -> 2600 | L13: =Worksheet!O98 -> 1820 | M13: =Worksheet!AP98 -> 0 | N13: =Worksheet!AQ98 -> 0 | O13: =Worksheet!AX98 -> 0 | P13: =Worksheet!AY98 -> 0 | Q13: =Worksheet!P98 -> 0 | R13: =Worksheet!Q98 -> 0 | S13: =Worksheet!S98 -> 126000 | T13: =Worksheet!T98 -> 0 | U13: =Worksheet!U98 -> 0 | V13: =Worksheet!V98 -> 0 | W13: =Worksheet!X98 -> 2139 | X13: =Worksheet!Y98 -> 5177 | Y13: =Worksheet!Z98 -> 0 | Z13: =Worksheet!AC98 -> 0

Sheet Worksheet
A1: Site Name | B1: Month | C1: Year | D1: Purchased Electricity kWh | E1: Purchased Electricity Tariff ($/kWh) | F1: Maximum Demand KVA/KW | G1: Maximum Demand Tariff ($/KVA || $/KW) | H1: Fixed Fees Cost ($) | I1: Electricity Total Budgeted | J1: Electricity Total Budgeted Cost ($) | K1: LPG Kitchen (Liters) | L1: LPG Kitchen $/Liters | M1: LPG Fixed Cost | N1: LPG Total Budgeted | O1: LPG Total Budgeted Cost ($) | P1: District Energy Heating kWh | Q1: District Energy Heating $/kWh | R1: Heating Fixed Cost | S1: Heating District Energy Total Budgeted | T1: Heating District Energy Total Budgeted Cost ($) | U1: Water Utility Supply (m3) m3 | V1: Water Utility Supply (m3) $/m3 | W1: Water Fixed Cost | X1: Water Total Budgeted | Y1: Water Total Budgeted Cost ($) | Z1: Room Nights | AA1: Room Nights Budget | AB1: Total Guests Budget | AC1: Total Guests | AD1: Laundry Load | AE1: Cooling Degree Day | AF1: Heating Degree Day | AG1: Onsite Generators kWh | AH1: Onsite Generators Cost ($) | AI1: Average PF | AJ1: Total Renewable Energy Production kWh | AK1: Total Renewable Energy Cost ($) | AL1: Total Renewable Energy Exported kWh | AM1: Total Renewable Energy Exported Cost ($) | AN1: Total Electricity Cost | AO1: Total Electricity kWh | AP1: Fuel Oil Hot-Water Boilers (Liter) Liter | AQ1: Fuel Oil Hot-Water Boilers (Liter) $/Liter | AR1: Fuel Oil Steam Boilers (Liter) Liter | AS1: Fuel Oil Steam Boilers (Liter) $/Liter | AT1: Fuel Oil Others (Liter) Liter | AU1: Fuel Oil Others (Liter) $/Liter | AV1: Onsite Generator Fuel Oil Liter | AW1: Onsite Generator Fuel Oil $/Liter | AX1: Fuel Oil Total Budgeted | AY1: Fuel Oil Total Budgeted Cost ($) | AZ1: LPG Hot-Water Boilers (Liters) | BA1: LPG Hot-Water Boilers $/Liters | BB1: LPG Steam Boilers (Liters) | BC1: LPG Steam Boilers $/Liters | BD1: Water RO (m3) m3 | BE1: Water RO (m3) $/m3 | BF1: Water Cisterns (m3) m3 | BG1: Water Cisterns (m3) $/m3 | BH1: Food Covers | BI1: Revenue | BJ1: Forex
A2: Annabelle | B2: 1 | C2: 2019 | D2: 172333 | E2: 0.15 | F2: 0 | G2: 0 | H2: 0 | I2: 155000 | J2: 24769 | K2: 4963 | L2: 0.444 | M2: 0 | N2: 5200 | O2: 2704 | P2: 0 | Q2: 0 | S2: 0 | T2: 949 | U2: 1256 | V2: 2.1323 | W2: 0 | X2: 2476 | Y2: 5280 | Z2: 5868 | AC2: 11119 | AD2: 0 | AG2: 0 | AH2: 0 | AJ2: 0 | AK2: 0 | AM2: 0 | AN2: 25850 | AO2: 172333 | AP2: 20980 | AQ2: 0.68 | AV2: 0 | AW2: 0 | AX2: 26000 | AY2: 17160 | AZ2: 0 | BA2: 0 | BB2: 0 | BC2: 0 | BD2: 0 | BE2: 0 | BF2: 0 | BG2: 0 | BH2: 0 | BJ2: 1
A3: Annabelle | B3: 2 | C3: 2019 | D3: 156988 | E3: 0.15 | F3: 0 | G3: 0 | H3: 0 | I3: 160000 | J3: 25568 | K3: 6214 | L3: 0.453 | M3: 0 | N3: 3600 | O3: 1872 | P3: 0 | Q3: 0 | S3: 0 | T3: 795 | U3: 3442 | V3: 2.0164 | W3: 0 | X3: 3142 | Y3: 6336 | Z3: 6460 | AC3: 12020 | AD3: 0 | AG3: 0 | AH3: 0 | AJ3: 0 | AK3: 0 | AM3: 0 | AN3: 23234 | AO3: 156988 | AP3: 15120 | AQ3: 0.51 | AV3: 0 | AW3: 0 | AX3: 24000 | AY3: 15840 | AZ3: 0 | BA3: 0 | BB3: 0 | BC3: 0 | BD3: 0 | BE3: 0 | BF3: 0 | BG3: 0 | BH3: 0 | BJ3: 1
A4: Annabelle | B4: 3 | C4: 2019 | D4: 174995 | E4: 0.15 | F4: 0 | G4: 0 | H4: 0 | I4: 190000 | J4: 30362 | K4: 5278 | L4: 0.316 | M4: 0 | N4: 4500 | O4: 2340 | P4: 0 | Q4: 0 | S4: 0 | T4: 943 | U4: 3416 | V4: 2.0144 | W4: 0 | X4: 4174 | Y4: 8410 | Z4: 7161 | AC4: 13479 | AD4: 0 | AG4: 0 | AH4: 0 | AJ4: 0 | AK4: 0 | AM4: 0 | AN4: 25374 | AO4: 174995 | AP4: 15080 | AQ4: 0.66 | AV4: 0 | AW4: 0 | AX4: 17000 | AY4: 11220 | AZ4: 0 | BA4: 0 | BB4: 0 | BC4: 0 | BD4: 0 | BE4: 0 | BF4: 0 | BG4: 0 | BH4: 0 | BJ4: 1
A5: Annabelle | B5: 4 | C5: 2019 | D5: 182624 | E5: 0.15 | F5: 0 | G5: 0 | H5: 0 | I5: 190000 | J5: 33417 | K5: 5308 | L5: 0.499 | M5: 0 | N5: 8166 | O5: 3838 | P5: 0 | Q5: 0 | S5: 0 | T5: 1065 | U5: 3746 | V5: 1.9388 | W5: 0 | X5: 5070 | Y5: 9830 | Z5: 7018 | AC5: 13914 | AD5: 0 | AG5: 0 | AH5: 0 | AJ5: 0 | AK5: 0 | AM5: 0 | AN5: 26846 | AO5: 182624 | AP5: 16800 | AQ5: 0.65 | AV5: 0 | AW5: 0 | AX5: 16521 | AY5: 10590 | AZ5: 0 | BA5: 0 | BB5: 0 | BC5: 0 | BD5: 0 | BE5: 0 | BF5: 0 | BG5: 0 | BH5: 0 | BJ5: 1
A6: Annabelle | B6: 5 | C6: 2019 | D6: 222859 | E6: 0.16 | F6: 0 | G6: 0 | H6: 0 | I6: 263932 | J6: 43749 | K6: 4945 | L6: 0.495 | M6: 0 | N6: 5749 | O6: 2702 | P6: 0 | Q6: 0 | S6: 0 | T6: 580 | U6: 3817 | V6: 1.9452 | W6: 0 | X6: 4476 | Y6: 8707 | Z6: 6507 | AC6: 12912 | AD6: 0 | AG6: 0 | AH6: 0 | AJ6: 0 | AK6: 0 | AM6: 0 | AN6: 34989 | AO6: 222859 | AP6: 9780 | AQ6: 0.66 | AV6: 0 | AW6: 0 | AX6: 6890 | AY6: 4437 | AZ6: 0 | BA6: 0 | BB6: 0 | BC6: 0 | BD6: 0 | BE6: 0 | BF6: 0 | BG6: 0 | BH6: 0 | BJ6: 1
A7: Annabelle | B7: 6 | C7: 2019 | D7: 313305 | E7: 0.19 | F7: 0 | G7: 0 | H7: 0 | I7: 327988 | J7: 52384 | K7: 4977 | L7: 0.478 | M7: 0 | N7: 5859 | O7: 2994 | P7: 0 | Q7: 0 | S7: 0 | T7: 570 | U7: 3920 | V7: 1.9535 | W7: 0 | X7: 3345 | Y7: 6536 | Z7: 6559 | AC7: 12796 | AD7: 0 | AG7: 0 | AH7: 0 | AJ7: 0 | AK7: 0 | AM7: 0 | AN7: 58275 | AO7: 313305 | AP7: 7680 | AQ7: 0.65 | AV7: 0 | AW7: 0 | AX7: 5527 | AY7: 3913 | AZ7: 0 | BA7: 0 | BB7: 0 | BC7: 0 | BD7: 0 | BE7: 0 | BF7: 0 | BG7: 0 | BH7: 0 | BJ7: 1
A8: Annabelle | B8: 7 | C8: 2019 | D8: 371075 | E8: 0.18 | F8: 0 | G8: 0 | H8: 0 | I8: 366009 | J8: 65668 | K8: 4755 | L8: 0.454 | M8: 0 | N8: 4501 | O8: 2984 | P8: 0 | Q8: 0 | S8: 0 | T8: 470 | U8: 3972 | V8: 2.2263 | W8: 0 | X8: 4380 | Y8: 9752 | Z8: 5658 | AC8: 11964 | AD8: 0 | AG8: 0 | AH8: 0 | AJ8: 0 | AK8: 0 | AM8: 0 | AN8: 66422 | AO8: 371075 | AP8: 6720 | AQ8: 0.69 | AV8: 0 | AW8: 0 | AX8: 4523 | AY8: 3121 | AZ8: 0 | BA8: 0 | BB8: 0 | BC8: 0 | BD8: 0 | BE8: 0 | BF8: 0 | BG8: 0 | BH8: 0 | BJ8: 1
A9: Annabelle | B9: 8 | C9: 2019 | D9: 352685 | E9: 0.18 | F9: 0 | G9: 0 | H9: 0 | I9: 368312 | J9: 67645 | K9: 4862 | L9: 0.45 | M9: 0 | N9: 5303 | O9: 2784 | P9: 0 | Q9: 0 | S9: 0 | T9: 495 | U9: 4105 | V9: 2.2278 | W9: 0 | X9: 4338 | Y9: 9666 | Z9: 6231 | AC9: 13547 | AD9: 0 | AG9: 0 | AH9: 0 | AJ9: 0 | AK9: 0 | AM9: 0 | AN9: 64541 | AO9: 352685 | AP9: 5540 | AQ9: 0.66 | AV9: 0 | AW9: 0 | AX9: 4230 | AY9: 2919 | AZ9: 0 | BA9: 0 | BB9: 0 | BC9: 0 | BD9: 0 | BE9: 0 | BF9: 0 | BG9: 0 | BH9: 0 | BJ9: 1
A10: Annabelle | B10: 9 | C10: 2019 | D10: 309098 | E10: 0.19 | F10: 0 | G10: 0 | H10: 0 | I10: 330356 | J10: 56557 | K10: 4561 | L10: 0.409 | M10: 0 | N10: 5035 | O10: 2719 | P10: 0 | Q10: 0 | S10: 0 | T10: 444 | U10: 3749 | V10: 2.2238 | W10: 0 | X10: 3686 | Y10: 8199 | Z10: 6189 | AC10: 11866 | AD10: 0 | AG10: 0 | AH10: 0 | AJ10: 0 | AK10: 0 | AM10: 0 | AN10: 58420 | AO10: 309098 | AP10: 3780 | AQ10: 0.67 | AV10: 0 | AW10: 0 | AX10: 3725 | AY10: 2697 | AZ10: 0 | BA10: 0 | BB10: 0 | BC10: 0 | BD10: 0 | BE10: 0 | BF10: 0 | BG10: 0 | BH10: 0 | BJ10: 1
A11: Annabelle | B11: 10 | C11: 2019 | D11: 263139 | E11: 0.16 | F11: 0 | G11: 0 | H11: 0 | I11: 270935 | J11: 48033 | K11: 5125 | L11: 0.435 | M11: 0 | N11: 4841 | O11: 2677 | P11: 0 | Q11: 0 | S11: 0 | T11: 612 | U11: 4112 | V11: 2.2279 | W11: 0 | X11: 3861 | Y11: 8603 | Z11: 6813 | AC11: 13451 | AD11: 0 | AG11: 0 | AH11: 0 | AJ11: 0 | AK11: 0 | AM11: 0 | AN11: 42629 | AO11: 263139 | AP11: 7370 | AQ11: 0.67 | AV11: 0 | AW11: 0 | AX11: 8218 | AY11: 5950 | AZ11: 0 | BA11: 0 | BB11: 0 | BC11: 0 | BD11: 0 | BE11: 0 | BF11: 0 | BG11: 0 | BH11: 0 | BJ11: 1
A12: Annabelle | B12: 11 | C12: 2019 | D12: 192061 | E12: 0.16 | F12: 0 | G12: 0 | H12: 0 | I12: 186734 | J12: 28560 | K12: 4904 | L12: 0.457 | M12: 0 | N12: 4844 | O12: 2635 | P12: 0 | Q12: 0 | S12: 0 | T12: 1075 | U12: 3997 | V12: 2.2267 | W12: 0 | X12: 2429 | Y12: 5409 | Z12: 7012 | AC12: 13113 | AD12: 0 | AG12: 0 | AH12: 0 | AJ12: 0 | AK12: 0 | AM12: 0 | AN12: 30538 | AO12: 192061 | AP12: 6630 | AQ12: 0.67 | AV12: 0 | AW12: 0 | AX12: 8223 | AY12: 6134 | AZ12: 0 | BA12: 0 | BB12: 0 | BC12: 0 | BD12: 0 | BE12: 0 | BF12: 0 | BG12: 0 | BH12: 0 | BJ12: 1
A13: Annabelle | B13: 12 | C13: 2019 | D13: 168571 | E13: 0.16 | F13: 0 | G13: 0 | H13: 0 | I13: 170000 | J13: 28581 | K13: 5062 | L13: 0.477 | M13: 0 | N13: 3975 | O13: 2067 | P13: 0 | Q13: 0 | S13: 0 | T13: 1311 | U13: 3285 | V13: 2.2174 | W13: 0 | X13: 2473 | Y13: 5485 | Z13: 6256 | AC13: 11440 | AD13: 0 | AG13: 0 | AH13: 0 | AJ13: 0 | AK13: 0 | AM13: 0 | AN13: 26971 | AO13: 168571 | AP13: 14560 | AQ13: 0.65 | AV13: 0 | AW13: 0 | AX13: 17885 | AY13: 11804 | AZ13: 0 | BA13: 0 | BB13: 0 | BC13: 0 | BD13: 0 | BE13: 0 | BF13: 0 | BG13: 0 | BH13: 0 | BJ13: 1
... A25: Annabelle | B25: 12 | C25: 2020 | D25: 40902 | E25: 0.13 | F25: 0 | G25: 0 | H25: 0 | I25: 122289 | J25: 19697 | K25: 500 | L25: 0.46 | M25: 0 | N25: 3648 | O25: 1751 | P25: 0 | Q25: 0 | S25: 0 | T25: 0 | U25: 679 | V25: 2.5243 | W25: 0 | X25: 2093 | Y25: 5284 | Z25: 1000 | AC25: 1271 | AD25: 0 | AG25: 0 | AH25: 0 | AJ25: 0 | AK25: 0 | AM25: 0 | AN25: 5276 | AO25: 40902 | AP25: 3600 | AQ25: 0.46 | AV25: 0 | AW25: 0 | AX25: 10525 | AY25: 6841 | AZ25: 0 | BA25: 0 | BB25: 0 | BC25: 0 | BD25: 0 | BE25: 0 | BF25: 0 | BG25: 0 | BH25: 0 | BJ25: 1
A26: Annabelle | B26: 1 | C26: 2021 | D26: 52563 | E26: 0.12 | F26: 0 | G26: 0 | H26: 0 | I26: 3964 | J26: 0 | K26: 0 | L26: 0 | M26: 0 | N26: 0 | O26: 0 | P26: 0 | Q26: 0 | S26: 0 | T26: 0 | U26: 245 | V26: 2.2857 | W26: 0 | X26: 0 | Y26: 0 | Z26: 2270 | AC26: 3057 | AD26: 0 | AG26: 0 | AH26: 0 | AJ26: 0 | AK26: 0 | AM26: 0 | AN26: 6360 | AO26: 52563 | AP26: 5740 | AQ26: 0.46 | AV26: 0 | AW26: 0 | AZ26: 0 | BA26: 0 | BB26: 0 | BC26: 0 | BD26: 0 | BE26: 0 | BF26: 0 | BG26: 0 | BH26: 0 | BJ26: 1
A27: Annabelle | B27: 2 | C27: 2021 | D27: 25827 | E27: 0.13 | F27: 0 | G27: 0 | H27: 0 | I27: 0 | J27: 0 | K27: 0 | L27: 0 | M27: 0 | N27: 0 | O27: 0 | P27: 0 | Q27: 0 | S27: 0 | T27: 0 | U27: 676 | V27: 1.7663 | W27: 0 | X27: 0 | Y27: 0 | Z27: 5 | AC27: 10 | AD27: 0 | AG27: 0 | AH27: 0 | AJ27: 0 | AK27: 0 | AM27: 0 | AN27: 3254 | AO27: 25827 | AV27: 0 | AW27: 0 | AZ27: 0 | BA27: 0 | BB27: 0 | BC27: 0 | BD27: 0 | BE27: 0 | BF27: 0 | BG27: 0 | BH27: 0 | BJ27: 1
A28: Annabelle | B28: 3 | C28: 2021 | D28: 62984 | E28: 0.14 | F28: 0 | G28: 0 | H28: 0 | I28: 83179 | J28: 12065 | K28: 0 | L28: 0.46 | M28: 0 | N28: 2478 | O28: 793 | P28: 0 | Q28: 0 | S28: 0 | T28: 0 | U28: 1654 | V28: 2.1977 | W28: 0 | X28: 1488 | Y28: 3271 | Z28: 1137 | AC28: 2629 | AD28: 0 | AG28: 0 | AH28: 0 | AJ28: 0 | AK28: 0 | AM28: 0 | AN28: 8881 | AO28: 62984 | AP28: 8020 | AQ28: 0.5 | AV28: 0 | AW28: 0 | AX28: 7150 | AY28: 4719 | AZ28: 0 | BA28: 0 | BB28: 0 | BC28: 0 | BD28: 0 | BE28: 0 | BF28: 0 | BG28: 0 | BH28: 0 | BJ28: 1
A29: Annabelle | B29: 4 | C29: 2021 | D29: 116793 | E29: 0.14 | F29: 0 | G29: 0 | H29: 0 | I29: 139243 | J29: 20509 | K29: 1455 | L29: 0.376 | M29: 0 | N29: 4038 | O29: 2019 | P29: 0 | Q29: 0 | S29: 0 | T29: 0 | U29: 1652 | V29: 2.1973 | W29: 0 | X29: 2519 | Y29: 5537 | Z29: 1762 | AC29: 3369 | AD29: 0 | AG29: 0 | AH29: 0 | AJ29: 0 | AK29: 0 | AM29: 0 | AN29: 16701 | AO29: 116793 | AP29: 9580 | AQ29: 0.6 | AV29: 0 | AW29: 0 | AX29: 12883 | AY29: 8374 | AZ29: 0 | BA29: 0 | BB29: 0 | BC29: 0 | BD29: 0 | BE29: 0 | BF29: 0 | BG29: 0 | BH29: 0 | BJ29: 1
A30: Annabelle | B30: 5 | C30: 2021 | D30: 153573 | E30: 0.15 | F30: 0 | G30: 0 | H30: 0 | I30: 204399 | J30: 32061 | K30: 1644 | L30: 0.447 | M30: 0 | N30: 4494 | O30: 2247 | P30: 0 | Q30: 0 | S30: 0 | T30: 0 | U30: 2244 | V30: 2.193 | W30: 0 | X30: 3105 | Y30: 6810 | Z30: 1189 | AC30: 2040 | AD30: 0 | AG30: 0 | AH30: 0 | AJ30: 0 | AK30: 0 | AM30: 0 | AN30: 23343 | AO30: 153573 | AP30: 5266 | AQ30: 0.59 | AV30: 0 | AW30: 0 | AX30: 8974 | AY30: 5923 | AZ30: 0 | BA30: 0 | BB30: 0 | BC30: 0 | BD30: 0 | BE30: 0 | BF30: 0 | BG30: 0 | BH30: 0 | BJ30: 1
A31: Annabelle | B31: 6 | C31: 2021 | D31: 226807 | E31: 0.18 | F31: 0 | G31: 0 | H31: 0 | I31: 284270 | J31: 52777 | K31: 2217 | L31: 0.447 | M31: 0 | N31: 4496 | O31: 2158 | P31: 0 | Q31: 0 | S31: 0 | T31: 0 | U31: 2300 | V31: 2.19 | W31: 0 | X31: 3172 | Y31: 6948 | Z31: 2064 | AC31: 3907 | AD31: 0 | AG31: 0 | AH31: 0 | AJ31: 0 | AK31: 0 | AM31: 0 | AN31: 41279 | AO31: 226807 | AP31: 3480 | AQ31: 0.41 | AV31: 0 | AW31: 0 | AX31: 6994 | AY31: 4546 | AZ31: 0 | BA31: 0 | BB31: 0 | BC31: 0 | BD31: 0 | BE31: 0 | BF31: 0 | BG31: 0 | BH31: 0 | BJ31: 1
A32: Annabelle | B32: 7 | C32: 2021 | D32: 311641 | E32: 0.18 | F32: 0 | G32: 0 | H32: 0 | I32: 408769 | J32: 73327 | K32: 3185 | L32: 0.498 | M32: 0 | N32: 5282 | O32: 2377 | P32: 0 | Q32: 0 | S32: 0 | T32: 0 | U32: 2516 | V32: 2.2019 | W32: 0 | X32: 4423 | Y32: 9741 | Z32: 2310 | AC32: 4583 | AD32: 0 | AG32: 0 | AH32: 0 | AJ32: 0 | AK32: 0 | AM32: 0 | AN32: 56407 | AO32: 311641 | AP32: 3620 | AQ32: 0.63 | AV32: 0 | AW32: 0 | AX32: 7414 | AY32: 5116 | AZ32: 0 | BA32: 0 | BB32: 0 | BC32: 0 | BD32: 0 | BE32: 0 | BF32: 0 | BG32: 0 | BH32: 0 | BJ32: 1
A33: Annabelle | B33: 8 | C33: 2021 | D33: 368246 | E33: 0.18 | F33: 0 | G33: 0 | H33: 0 | I33: 364771 | J33: 66634 | K33: 3110 | L33: 0.52 | M33: 0 | N33: 5024 | O33: 2261 | P33: 0 | Q33: 0 | S33: 0 | T33: 0 | U33: 3240 | V33: 2.216 | W33: 0 | X33: 4268 | Y33: 9458 | Z33: 3888 | AC33: 8401 | AD33: 0 | AG33: 0 | AH33: 0 | AJ33: 0 | AK33: 0 | AM33: 0 | AN33: 66284 | AO33: 368246 | AP33: 3980 | AQ33: 0.58 | AV33: 0 | AW33: 0 | AX33: 5771 | AY33: 3809 | AZ33: 0 | BA33: 0 | BB33: 0 | BC33: 0 | BD33: 0 | BE33: 0 | BF33: 0 | BG33: 0 | BH33: 0 | BJ33: 1
A34: Annabelle | B34: 9 | C34: 2021 | D34: 285473 | E34: 0.19 | F34: 0 | G34: 0 | H34: 0 | I34: 290639 | J34: 54917 | K34: 2785 | L34: 0.55 | M34: 0 | N34: 4280 | O34: 1755 | P34: 0 | Q34: 0 | S34: 0 | T34: 0 | U34: 2810 | V34: 2.3616 | W34: 0 | X34: 3319 | Y34: 7839 | Z34: 3620 | AC34: 6621 | AD34: 0 | AG34: 0 | AH34: 0 | AJ34: 0 | AK34: 0 | AM34: 0 | AN34: 54525 | AO34: 285473 | AP34: 4260 | AQ34: 0.64 | AV34: 0 | AW34: 0 | AX34: 3533 | AY34: 2367 | AZ34: 0 | BA34: 0 | BB34: 0 | BC34: 0 | BD34: 0 | BE34: 0 | BF34: 0 | BG34: 0 | BH34: 0 | BJ34: 1
A35: Annabelle | B35: 10 | C35: 2021 | D35: 266723 | E35: 0.2 | F35: 0 | G35: 0 | H35: 0 | I35: 246639 | J35: 39962 | K35: 4282 | L35: 0.57 | M35: 0 | N35: 4757 | O35: 2093 | P35: 0 | Q35: 0 | S35: 0 | T35: 0 | U35: 3606 | V35: 2.2219 | W35: 0 | X35: 3867 | Y35: 8594 | Z35: 6372 | AC35: 12759 | AD35: 0 | AG35: 0 | AH35: 0 | AJ35: 0 | AK35: 0 | AM35: 0 | AN35: 52544 | AO35: 266723 | AP35: 8620 | AQ35: 0.58 | AV35: 0 | AW35: 0 | AX35: 6873 | AY35: 4605 | AZ35: 0 | BA35: 0 | BB35: 0 | BC35: 0 | BD35: 0 | BE35: 0 | BF35: 0 | BG35: 0 | BH35: 0 | BJ35: 1
A36: Annabelle | B36: 11 | C36: 2021 | D36: 189874 | E36: 0.21 | F36: 0 | G36: 0 | H36: 0 | I36: 160398 | J36: 25527 | K36: 3732 | L36: 0.67 | M36: 0 | N36: 4070 | O36: 1872 | P36: 0 | Q36: 0 | S36: 0 | T36: 0 | U36: 3296 | V36: 2.2178 | W36: 0 | X36: 3351 | Y36: 7433 | Z36: 5905 | AC36: 11104 | AD36: 0 | AG36: 0 | AH36: 0 | AJ36: 0 | AK36: 0 | AM36: 0 | AN36: 38924 | AO36: 189874 | AP36: 12080 | AQ36: 0.73 | AV36: 0 | AW36: 0 | AX36: 5503 | AY36: 3687 | AZ36: 0 | BA36: 0 | BB36: 0 | BC36: 0 | BD36: 0 | BE36: 0 | BF36: 0 | BG36: 0 | BH36: 0 | BJ36: 1
A37: Annabelle | B37: 12 | C37: 2021 | D37: 140763 | E37: 0.2 | F37: 0 | G37: 0 | H37: 0 | I37: 61145 | J37: 0 | K37: 3301 | L37: 0.65 | M37: 0 | N37: 0 | O37: 0 | P37: 0 | Q37: 0 | S37: 0 | T37: 0 | U37: 2285 | V37: 2.1934 | W37: 0 | X37: 0 | Y37: 0 | Z37: 3033 | AC37: 5416 | AD37: 0 | AG37: 0 | AH37: 0 | AJ37: 0 | AK37: 0 | AM37: 0 | AN37: 28153 | AO37: 140763 | AP37: 8655 | AQ37: 0.74 | AV37: 0 | AW37: 0 | AX37: 0 | AZ37: 0 | BA37: 0 | BB37: 0 | BC37: 0 | BD37: 0 | BE37: 0 | BF37: 0 | BG37: 0 | BH37: 0 | BJ37: 1
A38: Annabelle | B38: 1 | C38: 2022 | D38: 123469 | E38: 0.19 | F38: 0 | G38: 0 | H38: 0 | I38: 123469 | J38: 27348 | K38: 2615 | L38: 0.67 | M38: 0 | N38: 3983 | O38: 1832 | P38: 150494 | Q38: 0.0847 | S38: 67032 | T38: 5679 | U38: 1476 | V38: 2.15 | W38: 0 | X38: 1053 | Y38: 2269 | Z38: 1622 | AC38: 2729 | AD38: 0 | AG38: 0 | AH38: 0 | AJ38: 0 | AK38: 0 | AM38: 0 | AN38: 23089 | AO38: 123469 | AP38: 0 | AQ38: 0 | AV38: 0 | AW38: 0 | AX38: 0 | AZ38: 0 | BA38: 0 | BB38: 0 | BC38: 0 | BD38: 0 | BE38: 0 | BF38: 0 | BG38: 0 | BH38: 0 | BJ38: 1
A39: Annabelle | B39: 2 | C39: 2022 | D39: 113911 | E39: 0.18 | F39: 0 | G39: 0 | H39: 0 | I39: 113911 | J39: 24366 | K39: 2813 | L39: 0.63 | M39: 0 | N39: 2891 | O39: 1243 | P39: 155635 | Q39: 0.0847 | S39: 74592 | T39: 6320 | U39: 1779 | V39: 2.19 | W39: 0 | X39: 1940 | Y39: 4255 | Z39: 2980 | AC39: 5216 | AD39: 0 | AG39: 0 | AH39: 0 | AJ39: 0 | AK39: 0 | AM39: 0 | AN39: 20504 | AO39: 113911 | AP39: 160 | AQ39: 0.72 | AV39: 0 | AW39: 0 | AX39: 0 | AZ39: 0 | BA39: 0 | BB39: 0 | BC39: 0 | BD39: 0 | BE39: 0 | BF39: 0 | BG39: 0 | BH39: 0 | BJ39: 1
A40: Annabelle | B40: 3 | C40: 2022 | D40: 154893 | E40: 0.23 | F40: 0 | G40: 0 | H40: 0 | I40: 154893 | J40: 34851 | K40: 3664 | L40: 0.71 | M40: 0 | N40: 3348 | O40: 1540 | P40: 227758 | Q40: 0.0847 | S40: 123984 | T40: 10504 | U40: 2776 | V40: 2.19 | W40: 0 | X40: 2486 | Y40: 5436 | Z40: 4582 | AC40: 8590 | AD40: 0 | AG40: 0 | AH40: 0 | AJ40: 0 | AK40: 0 | AM40: 0 | AN40: 35006 | AO40: 154893 | AP40: 140 | AQ40: 0.73 | AV40: 0 | AW40: 0 | AX40: 0 | AZ40: 0 | BA40: 0 | BB40: 0 | BC40: 0 | BD40: 0 | BE40: 0 | BF40: 0 | BG40: 0 | BH40: 0 | BJ40: 1
A41: Annabelle | B41: 4 | C41: 2022 | D41: 188855 | E41: 0.23 | F41: 0 | G41: 0 | H41: 0 | I41: 154572 | J41: 34779 | K41: 4549 | L41: 0.73 | M41: 0 | N41: 4537 | O41: 2223 | P41: 198500 | Q41: 0.0847 | S41: 0 | T41: 0 | U41: 3758 | V41: 2.22 | W41: 0 | X41: 3528 | Y41: 7840 | Z41: 6172 | AC41: 12832 | AD41: 0 | AG41: 0 | AH41: 0 | AJ41: 0 | AK41: 0 | AM41: 0 | AN41: 43814 | AO41: 188855 | AP41: 0 | AQ41: 0 | AV41: 0 | AW41: 0 | AX41: 18461 | AY41: 12184 | AZ41: 0 | BA41: 0 | BB41: 0 | BC41: 0 | BD41: 0 | BE41: 0 | BF41: 0 | BG41: 0 | BH41: 0 | BJ41: 1
A42: Annabelle | B42: 5 | C42: 2022 | D42: 221809 | E42: 0.25 | F42: 0 | G42: 0 | H42: 0 | I42: 189124 | J42: 42553 | K42: 4125 | L42: 0.7 | M42: 0 | N42: 4160 | O42: 1997 | P42: 108108 | Q42: 0.0847 | S42: 0 | T42: 0 | U42: 3973 | V42: 2.23 | W42: 0 | X42: 3941 | Y42: 8776 | Z42: 5894 | AC42: 11361 | AD42: 0 | AG42: 0 | AH42: 0 | AJ42: 0 | AK42: 0 | AM42: 0 | AN42: 54343 | AO42: 221809 | AP42: 0 | AQ42: 0 | AV42: 0 | AW42: 0 | AX42: 10780 | AY42: 7007 | AZ42: 0 | BA42: 0 | BB42: 0 | BC42: 0 | BD42: 0 | BE42: 0 | BF42: 0 | BG42: 0 | BH42: 0 | BJ42: 1
A43: Annabelle | B43: 6 | C43: 2022 | D43: 294114 | E43: 0.33 | F43: 0 | G43: 0 | H43: 0 | I43: 298067 | J43: 67065 | K43: 4303 | L43: 0.77 | M43: 0 | N43: 4774 | O43: 2196 | P43: 51862 | Q43: 0.1058 | S43: 0 | T43: 0 | U43: 3757 | V43: 2.24 | W43: 0 | X43: 5005 | Y43: 11196 | Z43: 5977 | AC43: 11878 | AD43: 0 | AG43: 0 | AH43: 0 | AJ43: 0 | AK43: 0 | AM43: 0 | AN43: 97352 | AO43: 294114 | AP43: 620 | AQ43: 1.05 | AV43: 0 | AW43: 0 | AX43: 9532 | AY43: 6291 | AZ43: 0 | BA43: 0 | BB43: 0 | BC43: 0 | BD43: 0 | BE43: 0 | BF43: 0 | BG43: 0 | BH43: 0 | BJ43: 1
A44: Annabelle | B44: 7 | C44: 2022 | D44: 360191 | E44: 0.33 | F44: 0 | G44: 0 | H44: 0 | I44: 371775 | J44: 83649 | K44: 4637 | L44: 0.78 | M44: 0 | N44: 5304 | O44: 2493 | P44: 54180 | Q44: 0.0992 | S44: 0 | T44: 0 | U44: 4033 | V44: 2.35 | W44: 0 | X44: 5091 | Y44: 11965 | Z44: 5937 | AC44: 12747 | AD44: 0 | AG44: 0 | AH44: 0 | AJ44: 0 | AK44: 0 | AM44: 0 | AN44: 119583 | AO44: 360191 | AP44: 0 | AQ44: 0 | AV44: 0 | AW44: 0 | AX44: 9791 | AY44: 6560 | AZ44: 0 | BA44: 0 | BB44: 0 | BC44: 0 | BD44: 0 | BE44: 0 | BF44: 0 | BG44: 0 | BH44: 0 | BJ44: 1
A45: Annabelle | B45: 8 | C45: 2022 | D45: 393401 | E45: 0.33 | F45: 0 | G45: 0 | H45: 0 | I45: 387042 | J45: 87084 | K45: 3133 | L45: 0.73 | M45: 0 | N45: 5278 | O45: 2375 | P45: 53374 | Q45: 0.0992 | S45: 0 | T45: 0 | U45: 4022 | V45: 2.35 | W45: 0 | X45: 5145 | Y45: 12093 | Z45: 6064 | AC45: 14395 | AD45: 0 | AG45: 0 | AH45: 0 | AJ45: 0 | AK45: 0 | AM45: 0 | AN45: 131003 | AO45: 393401 | AP45: 0 | AQ45: 0 | AV45: 0 | AW45: 0 | AX45: 7893 | AY45: 5288 | AZ45: 0 | BA45: 0 | BB45: 0 | BC45: 0 | BD45: 0 | BE45: 0 | BF45: 0 | BG45: 0 | BH45: 0 | BJ45: 1
A46: Annabelle | B46: 9 | C46: 2022 | D46: 327771 | E46: 0.32 | F46: 0 | G46: 0 | H46: 0 | I46: 281729 | J46: 63389 | K46: 3788 | L46: 0.69 | M46: 0 | N46: 4145 | O46: 1741 | P46: 51106 | Q46: 0.1167 | S46: 0 | T46: 0 | U46: 3814 | V46: 2.35 | W46: 0 | X46: 4244 | Y46: 9974 | Z46: 5932 | AC46: 11392 | AD46: 0 | AG46: 0 | AH46: 0 | AJ46: 0 | AK46: 0 | AM46: 0 | AN46: 105214 | AO46: 327771 | AP46: 0 | AQ46: 0 | AV46: 0 | AW46: 0 | AX46: 4467 | AY46: 2993 | AZ46: 0 | BA46: 0 | BB46: 0 | BC46: 0 | BD46: 0 | BE46: 0 | BF46: 0 | BG46: 0 | BH46: 0 | BJ46: 1
A47: Annabelle | B47: 10 | C47: 2022 | D47: 257626 | E47: 0.28 | F47: 0 | G47: 0 | H47: 0 | I47: 257848 | J47: 58016 | K47: 4518 | L47: 0.82 | M47: 0 | N47: 50 | O47: 2143 | P47: 77742 | Q47: 0.0992 | S47: 0 | T47: 0 | U47: 3825 | V47: 2.35 | W47: 0 | X47: 4472 | Y47: 10510 | Z47: 6495 | AC47: 13192 | AD47: 0 | AG47: 0 | AH47: 0 | AJ47: 0 | AK47: 0 | AM47: 0 | AN47: 72651 | AO47: 257626 | AP47: 1660 | AQ47: 0.96 | AV47: 0 | AW47: 0 | AX47: 9331 | AY47: 6252 | AZ47: 0 | BA47: 0 | BB47: 0 | BC47: 0 | BD47: 0 | BE47: 0 | BF47: 0 | BG47: 0 | BH47: 0 | BJ47: 1
A48: Annabelle | B48: 11 | C48: 2022 | D48: 177666 | E48: 0.28 | F48: 0 | G48: 0 | H48: 0 | I48: 145087 | J48: 32644 | K48: 8048 | L48: 0.6 | M48: 0 | N48: 3682 | O48: 1841 | P48: 80917 | Q48: 0.0992 | S48: 0 | T48: 0 | U48: 2691 | V48: 2.4 | W48: 0 | X48: 3187 | Y48: 7651 | Z48: 4747 | AC48: 9084 | AD48: 0 | AG48: 0 | AH48: 0 | AJ48: 0 | AK48: 0 | AM48: 0 | AN48: 49924 | AO48: 177666 | AP48: 0 | AQ48: 0 | AV48: 0 | AW48: 0 | AX48: 6472 | AY48: 4336 | AZ48: 0 | BA48: 0 | BB48: 0 | BC48: 0 | BD48: 0 | BE48: 0 | BF48: 0 | BG48: 0 | BH48: 0 | BJ48: 1
A49: Annabelle | B49: 12 | C49: 2022 | D49: 135051 | E49: 0.28 | F49: 0 | G49: 0 | H49: 0 | I49: 79759 | J49: 17946 | K49: 2524 | L49: 0.84 | M49: 0 | N49: 2404 | O49: 1322 | P49: 0 | Q49: 0.0992 | S49: 0 | T49: 0 | U49: 1965 | V49: 1.99 | W49: 0 | X49: 2059 | Y49: 4103 | Z49: 2234 | AC49: 4185 | AD49: 0 | AG49: 0 | AH49: 0 | AJ49: 0 | AK49: 0 | AM49: 0 | AN49: 37949 | AO49: 135051 | AP49: 0 | AQ49: 0 | AV49: 0 | AW49: 0 | AX49: 8921 | AY49: 6245 | AZ49: 0 | BA49: 0 | BB49: 0 | BC49: 0 | BD49: 0 | BE49: 0 | BF49: 0 | BG49: 0 | BH49: 0 | BJ49: 1
A50: Annabelle | B50: 1 | C50: 2023 | D50: 124702 | E50: 0.28 | F50: 0 | G50: 0 | H50: 0 | I50: 123469 | J50: 31170 | K50: 2237 | L50: 0.77 | M50: 0 | N50: 2484 | O50: 1739 | P50: 131947 | Q50: 0.1151 | S50: 150494 | T50: 17319 | U50: 1958 | V50: 2.4 | W50: 0 | X50: 1059 | Y50: 2543 | Z50: 1956 | AC50: 0 | AD50: 0 | AE50: 0.1 | AF50: 72 | AG50: 0 | AH50: 0 | AJ50: 0 | AK50: 0 | AM50: 0 | AN50: 34418 | AO50: 124702 | AP50: 0 | AQ50: 0 | AV50: 0 | AW50: 0 | AX50: 0 | AY50: 0 | AZ50: 0 | BA50: 0 | BB50: 0 | BC50: 0 | BD50: 0 | BE50: 0 | BF50: 0 | BG50: 0 | BH50: 0 | BJ50: 1
A51: Annabelle | B51: 2 | C51: 2023 | D51: 125023 | E51: 0.28 | F51: 0 | G51: 0 | H51: 0 | I51: 113911 | J51: 28757 | K51: 2548 | L51: 0.63 | M51: 0 | N51: 3 | O51: 2 | P51: 198349 | Q51: 0.1151 | S51: 155635 | T51: 17910 | U51: 2226 | V51: 2.37 | W51: 0 | X51: 1298 | Y51: 3078 | Z51: 2871 | AC51: 0 | AD51: 0 | AE51: 1.2 | AF51: 110.4 | AG51: 0 | AH51: 0 | AJ51: 0 | AK51: 0 | AM51: 0 | AN51: 35256 | AO51: 125023 | AP51: 0 | AQ51: 0 | AV51: 0 | AW51: 0 | AX51: 0 | AY51: 0 | AZ51: 0 | BA51: 0 | BB51: 0 | BC51: 0 | BD51: 0 | BE51: 0 | BF51: 0 | BG51: 0 | BH51: 0 | BJ51: 1
...
