Workbook

Sheet TOTAL
A1: Site Name | B1: Day | C1: Month | D1: Year | E1: Total Electricity Kwh | F1: Electricity Tariff ($/Kwh) | G1: Natual Gas (m3) | H1: Natural Gas $/m3 | I1: Water Utility Supply (m3) m3 | J1: Water Utility Supply (m3) $/m3 | K1: Room Nights | L1: Total Guests
A2: Hampshire | B2: 1 | C2: 9 | D2: 2019 | E2: =(Submetering!E2+Submetering!F2) -> 10920 | F2: 0.142 | G2: =Submetering!M2 -> 1164 | H2: 0.21 | I2: =Submetering!N2 -> 229 | J2: 2.06 | K2: ='Hampshire Daily'!B5 -> 66 | L2: =Submetering!Y2 -> 170
A3: Hampshire | B3: =B2+1 -> 2 | C3: 9 | D3: 2019 | E3: =Submetering!E3+Submetering!F3 -> 10840 | F3: 0.142 | G3: =Submetering!M3 -> 1188 | H3: 0.21 | I3: =Submetering!N3 -> 216 | J3: 2.06 | K3: ='Hampshire Daily'!B6 -> 51 | L3: =Submetering!Y3 -> 124
A4: Hampshire | B4: =B3+1 -> 3 | C4: 9 | D4: 2019 | E4: =Submetering!E4+Submetering!F4 -> 10560 | F4: 0.142 | G4: =Submetering!M4 -> 1006 | H4: 0.21 | I4: =Submetering!N4 -> 201 | J4: 2.06 | K4: ='Hampshire Daily'!B7 -> 88 | L4: =Submetering!Y4 -> 125
A5: Hampshire | B5: =B4+1 -> 4 | C5: 9 | D5: 2019 | E5: =Submetering!E5+Submetering!F5 -> 11360 | F5: 0.142 | G5: =Submetering!M5 -> 1084 | H5: 0.21 | I5: =Submetering!N5 -> 147 | J5: 2.06 | K5: ='Hampshire Daily'!B8 -> 86 | L5: =Submetering!Y5 -> 117
A6: Hampshire | B6: =B5+1 -> 5 | C6: 9 | D6: 2019 | E6: =Submetering!E6+Submetering!F6 -> 11110 | F6: 0.142 | G6: =Submetering!M6 -> 1198 | H6: 0.21 | I6: =Submetering!N6 -> 195 | J6: 2.06 | K6: ='Hampshire Daily'!B9 -> 50 | L6: =Submetering!Y6 -> 95
A7: Hampshire | B7: =B6+1 -> 6 | C7: 9 | D7: 2019 | E7: =Submetering!E7+Submetering!F7 -> 10550 | F7: 0.142 | G7: =Submetering!M7 -> 1229 | H7: 0.21 | I7: =Submetering!N7 -> 184 | J7: 2.06 | K7: ='Hampshire Daily'!B10 -> 103 | L7: =Submetering!Y7 -> 212
A8: Hampshire | B8: =B7+1 -> 7 | C8: 9 | D8: 2019 | E8: =Submetering!E8+Submetering!F8 -> 10530 | F8: 0.142 | G8: =Submetering!M8 -> 1413 | H8: 0.21 | I8: =Submetering!N8 -> 196 | J8: 2.06 | K8: ='Hampshire Daily'!B11 -> 114 | L8: =Submetering!Y8 -> 233
A9: Hampshire | B9: =B8+1 -> 8 | C9: 9 | D9: 2019 | E9: =Submetering!E9+Submetering!F9 -> 11200 | F9: 0.142 | G9: =Submetering!M9 -> 1448 | H9: 0.21 | I9: =Submetering!N9 -> 190 | J9: 2.06 | K9: ='Hampshire Daily'!B12 -> 55 | L9: =Submetering!Y9 -> 99
A10: Hampshire | B10: =B9+1 -> 9 | C10: 9 | D10: 2019 | E10: =Submetering!E10+Submetering!F10 -> 10180 | F10: 0.142 | G10: =Submetering!M10 -> 1238 | H10: 0.21 | I10: =Submetering!N10 -> 190 | J10: 2.06 | K10: ='Hampshire Daily'!B13 -> 70 | L10: =Submetering!Y10 -> 104
A11: Hampshire | B11: =B10+1 -> 10 | C11: 9 | D11: 2019 | E11: =Submetering!E11+Submetering!F11 -> 10450 | F11: 0.142 | G11: =Submetering!M11 -> 1415 | H11: 0.21 | I11: =Submetering!N11 -> 190 | J11: 2.06 | K11: ='Hampshire Daily'!B14 -> 60 | L11: =Submetering!Y11 -> 96
A12: Hampshire | B12: =B11+1 -> 11 | C12: 9 | D12: 2019 | E12: =Submetering!E12+Submetering!F12 -> 10550 | F12: 0.142 | G12: =Submetering!M12 -> 1198 | H12: 0.21 | I12: =Submetering!N12 -> 193 | J12: 2.06 | K12: ='Hampshire Daily'!B15 -> 126 | L12: =Submetering!Y12 -> 143
A13: Hampshire | B13: =B12+1 -> 12 | C13: 9 | D13: 2019 | E13: =Submetering!E13+Submetering!F13 -> 11370 | F13: 0.142 | G13: =Submetering!M13 -> 1151 | H13: 0.21 | I13: =Submetering!N13 -> 190 | J13: 2.06 | K13: ='Hampshire Daily'!B16 -> 127 | L13: =Submetering!Y13 -> 148
A14: Hampshire | B14: =B13+1 -> 13 | C14: 9 | D14: 2019 | E14: =Submetering!E14+Submetering!F14 -> 11190 | F14: 0.142 | G14: =Submetering!M14 -> 1101 | H14: 0.21 | I14: =Submetering!N14 -> 190 | J14: 2.06 | K14: ='Hampshire Daily'!B17 -> 89 | L14: =Submetering!Y14 -> 162
... A31: Hampshire | B31: =B30+1 -> 30 | C31: 9 | D31: 2019 | E31: =Submetering!E31+Submetering!F31 -> 11450 | F31: 0.142 | G31: =Submetering!M31 -> 1382 | H31: 0.21 | I31: =Submetering!N31 -> 185 | J31: 2.06 | K31: ='Hampshire Daily'!B34 -> 68 | L31: =Submetering!Y31 -> 91

Sheet Submetering
A1: Site Name | B1: Day | C1: Month | D1: Year | E1: Meter 1- KWh | F1: Meter 2- KWh | G1: East MCC- KWh | H1: South MCC 1- KWh | I1: South MCC 2- KWh | J1: West MCC- KWh | K1: Kitchen - KWh | L1: SPA - KWh | M1: Gas- KWh | N1: Main Site Water Meter - m3 | O1: Chiller 2- m3 | P1: Chiller 3- m3 | Q1: Chiller 4- m3 | R1: Hard Water Supply- m3 | S1: Pool Supply- m3 | T1: CL02- m3 | U1: LTHW SPA- m3 | V1: LTHW East- m3 | W1: Chilled make-up- m3 | X1: Room Nights | Y1: Total Guests
A2: Hampshire | B2: 1 | C2: 9 | D2: 2019 | E2: =IF(('Hampshire Daily'!D5-'Hampshire Daily'!D4<0), "0",('Hampshire Daily'!D5-'Hampshire Daily'!D4)*10) -> 4270 | F2: =IF(('Hampshire Daily'!F5-'Hampshire Daily'!F4<0), "0",('Hampshire Daily'!F5-'Hampshire Daily'!F4)*10) -> 6650 | G2: =IF(('Hampshire Daily'!H5-'Hampshire Daily'!H4<0), "0",'Hampshire Daily'!H5-'Hampshire Daily'!H4) -> 627 | H2: =IF(('Hampshire Daily'!I5-'Hampshire Daily'!I4<0), "0",'Hampshire Daily'!I5-'Hampshire Daily'!I4) -> 0 | I2: =IF(('Hampshire Daily'!J5-'Hampshire Daily'!J4<0), "0",'Hampshire Daily'!J5-'Hampshire Daily'!J4) -> 0 | J2: =IF(('Hampshire Daily'!K5-'Hampshire Daily'!K4<0), "0",'Hampshire Daily'!K5-'Hampshire Daily'!K4) -> 0 | K2: =IF(('Hampshire Daily'!L5-'Hampshire Daily'!L4<0), "0",'Hampshire Daily'!L5-'Hampshire Daily'!L4) -> 1124 | L2: =IF(('Hampshire Daily'!M5-'Hampshire Daily'!M4<0), "0",'Hampshire Daily'!M5-'Hampshire Daily'!M4) -> 724 | M2: =IF(('Hampshire Daily'!N5-'Hampshire Daily'!N4<0), "0",'Hampshire Daily'!N5-'Hampshire Daily'!N4) -> 1164 | N2: =IF(('Hampshire Daily'!O5-'Hampshire Daily'!O4<0), "0",'Hampshire Daily'!O5-'Hampshire Daily'!O4) -> 229 | ... Q2: =IF(('Hampshire Daily'!R5-'Hampshire Daily'!R4<0), "0",'Hampshire Daily'!R5-'Hampshire Daily'!R4) -> 2 | R2: =IF(('Hampshire Daily'!U5-'Hampshire Daily'!U4<0), "0",'Hampshire Daily'!U5-'Hampshire Daily'!U4) -> 13 | S2: =IF(('Hampshire Daily'!V5-'Hampshire Daily'!V4<0), "0",'Hampshire Daily'!V5-'Hampshire Daily'!V4) -> 0 | T2: =IF(('Hampshire Daily'!X5-'Hampshire Daily'!W4<0), "0",'Hampshire Daily'!X5-'Hampshire Daily'!W4) -> 326.654 | U2: =IF(('Hampshire Daily'!Y5-'Hampshire Daily'!X4<0), "0",'Hampshire Daily'!Y5-'Hampshire Daily'!X4) -> 454.524 | V2: =IF(('Hampshire Daily'!Z5-'Hampshire Daily'!Y4<0), "0",'Hampshire Daily'!Z5-'Hampshire Daily'!Y4) -> 3019.891 | W2: =IF(('Hampshire Daily'!#REF!-'Hampshire Daily'!Z4<0), "0",'Hampshire Daily'!#REF!-'Hampshire Daily'!Z4) -> #REF! | X2: ='Hampshire Daily'!B5 -> 66 | Y2: ='Hampshire Daily'!C5 -> 170
A3: Hampshire | B3: =B2+1 -> 2 | C3: 9 | D3: 2019 | E3: =IF(('Hampshire Daily'!D6-'Hampshire Daily'!D5<0), "0",('Hampshire Daily'!D6-'Hampshire Daily'!D5)*10) -> 4170 | F3: =IF(('Hampshire Daily'!F6-'Hampshire Daily'!F5<0), "0",('Hampshire Daily'!F6-'Hampshire Daily'!F5)*10) -> 6670 | G3: =IF(('Hampshire Daily'!H6-'Hampshire Daily'!H5<0), "0",'Hampshire Daily'!H6-'Hampshire Daily'!H5) -> 645 | H3: =IF(('Hampshire Daily'!I6-'Hampshire Daily'!I5<0), "0",'Hampshire Daily'!I6-'Hampshire Daily'!I5) -> 0 | I3: =IF(('Hampshire Daily'!J6-'Hampshire Daily'!J5<0), "0",'Hampshire Daily'!J6-'Hampshire Daily'!J5) -> 0 | J3: =IF(('Hampshire Daily'!K6-'Hampshire Daily'!K5<0), "0",'Hampshire Daily'!K6-'Hampshire Daily'!K5) -> 0 | K3: =IF(('Hampshire Daily'!L6-'Hampshire Daily'!L5<0), "0",'Hampshire Daily'!L6-'Hampshire Daily'!L5) -> 1124 | L3: =IF(('Hampshire Daily'!M6-'Hampshire Daily'!M5<0), "0",'Hampshire Daily'!M6-'Hampshire Daily'!M5) -> 738 | M3: =IF(('Hampshire Daily'!N6-'Hampshire Daily'!N5<0), "0",'Hampshire Daily'!N6-'Hampshire Daily'!N5) -> 1188 | N3: =IF(('Hampshire Daily'!O6-'Hampshire Daily'!O5<0), "0",'Hampshire Daily'!O6-'Hampshire Daily'!O5) -> 216 | ... Q3: =IF(('Hampshire Daily'!R6-'Hampshire Daily'!R5<0), "0",'Hampshire Daily'!R6-'Hampshire Daily'!R5) -> 1 | R3: =IF(('Hampshire Daily'!U6-'Hampshire Daily'!U5<0), "0",'Hampshire Daily'!U6-'Hampshire Daily'!U5) -> 12 | S3: =IF(('Hampshire Daily'!V6-'Hampshire Daily'!V5<0), "0",'Hampshire Daily'!V6-'Hampshire Daily'!V5) -> 1 | T3: =IF(('Hampshire Daily'!X6-'Hampshire Daily'!X5<0), "0",'Hampshire Daily'!X6-'Hampshire Daily'!X5) -> 0.057 | U3: =IF(('Hampshire Daily'!Y6-'Hampshire Daily'!Y5<0), "0",'Hampshire Daily'!Y6-'Hampshire Daily'!Y5) -> 0.02 | V3: =IF(('Hampshire Daily'!Z6-'Hampshire Daily'!Z5<0), "0",'Hampshire Daily'!Z6-'Hampshire Daily'!Z5) -> 2.597 | W3: =IF(('Hampshire Daily'!#REF!-'Hampshire Daily'!#REF!<0), "0",'Hampshire Daily'!#REF!-'Hampshire Daily'!#REF!) -> #REF! | X3: ='Hampshire Daily'!B6 -> 51 | Y3: ='Hampshire Daily'!C6 -> 124
A4: Hampshire | B4: =B3+1 -> 3 | C4: 9 | D4: 2019 | E4: =IF(('Hampshire Daily'!D7-'Hampshire Daily'!D6<0), "0",('Hampshire Daily'!D7-'Hampshire Daily'!D6)*10) -> 4280 | F4: =IF(('Hampshire Daily'!F7-'Hampshire Daily'!F6<0), "0",('Hampshire Daily'!F7-'Hampshire Daily'!F6)*10) -> 6280 | G4: =IF(('Hampshire Daily'!H7-'Hampshire Daily'!H6<0), "0",'Hampshire Daily'!H7-'Hampshire Daily'!H6) -> 562 | H4: =IF(('Hampshire Daily'!I7-'Hampshire Daily'!I6<0), "0",'Hampshire Daily'!I7-'Hampshire Daily'!I6) -> 0 | I4: =IF(('Hampshire Daily'!J7-'Hampshire Daily'!J6<0), "0",'Hampshire Daily'!J7-'Hampshire Daily'!J6) -> 0 | J4: =IF(('Hampshire Daily'!K7-'Hampshire Daily'!K6<0), "0",'Hampshire Daily'!K7-'Hampshire Daily'!K6) -> 0 | K4: =IF(('Hampshire Daily'!L7-'Hampshire Daily'!L6<0), "0",'Hampshire Daily'!L7-'Hampshire Daily'!L6) -> 1124 | L4: =IF(('Hampshire Daily'!M7-'Hampshire Daily'!M6<0), "0",'Hampshire Daily'!M7-'Hampshire Daily'!M6) -> 711 | M4: =IF(('Hampshire Daily'!N7-'Hampshire Daily'!N6<0), "0",'Hampshire Daily'!N7-'Hampshire Daily'!N6) -> 1006 | N4: =IF(('Hampshire Daily'!O7-'Hampshire Daily'!O6<0), "0",'Hampshire Daily'!O7-'Hampshire Daily'!O6) -> 201 | ... Q4: =IF(('Hampshire Daily'!R7-'Hampshire Daily'!R6<0), "0",'Hampshire Daily'!R7-'Hampshire Daily'!R6) -> 1 | R4: =IF(('Hampshire Daily'!U7-'Hampshire Daily'!U6<0), "0",'Hampshire Daily'!U7-'Hampshire Daily'!U6) -> 10 | S4: =IF(('Hampshire Daily'!V7-'Hampshire Daily'!V6<0), "0",'Hampshire Daily'!V7-'Hampshire Daily'!V6) -> 8 | T4: =IF(('Hampshire Daily'!X7-'Hampshire Daily'!X6<0), "0",'Hampshire Daily'!X7-'Hampshire Daily'!X6) -> 0.055 | U4: =IF(('Hampshire Daily'!Y7-'Hampshire Daily'!Y6<0), "0",'Hampshire Daily'!Y7-'Hampshire Daily'!Y6) -> 0.022 | V4: =IF(('Hampshire Daily'!Z7-'Hampshire Daily'!Z6<0), "0",'Hampshire Daily'!Z7-'Hampshire Daily'!Z6) -> 0.543 | W4: =IF(('Hampshire Daily'!#REF!-'Hampshire Daily'!#REF!<0), "0",'Hampshire Daily'!#REF!-'Hampshire Daily'!#REF!) -> #REF! | X4: ='Hampshire Daily'!B7 -> 88 | Y4: ='Hampshire Daily'!C7 -> 125
A5: Hampshire | B5: =B4+1 -> 4 | C5: 9 | D5: 2019 | E5: =IF(('Hampshire Daily'!D8-'Hampshire Daily'!D7<0), "0",('Hampshire Daily'!D8-'Hampshire Daily'!D7)*10) -> 4670 | F5: =IF(('Hampshire Daily'!F8-'Hampshire Daily'!F7<0), "0",('Hampshire Daily'!F8-'Hampshire Daily'!F7)*10) -> 6690 | G5: =IF(('Hampshire Daily'!H8-'Hampshire Daily'!H7<0), "0",'Hampshire Daily'!H8-'Hampshire Daily'!H7) -> 585 | H5: =IF(('Hampshire Daily'!I8-'Hampshire Daily'!I7<0), "0",'Hampshire Daily'!I8-'Hampshire Daily'!I7) -> 0 | I5: =IF(('Hampshire Daily'!J8-'Hampshire Daily'!J7<0), "0",'Hampshire Daily'!J8-'Hampshire Daily'!J7) -> 0 | J5: =IF(('Hampshire Daily'!K8-'Hampshire Daily'!K7<0), "0",'Hampshire Daily'!K8-'Hampshire Daily'!K7) -> 0 | K5: =IF(('Hampshire Daily'!L8-'Hampshire Daily'!L7<0), "0",'Hampshire Daily'!L8-'Hampshire Daily'!L7) -> 1127 | L5: =IF(('Hampshire Daily'!M8-'Hampshire Daily'!M7<0), "0",'Hampshire Daily'!M8-'Hampshire Daily'!M7) -> 738 | M5: =IF(('Hampshire Daily'!N8-'Hampshire Daily'!N7<0), "0",'Hampshire Daily'!N8-'Hampshire Daily'!N7) -> 1084 | N5: =IF(('Hampshire Daily'!O8-'Hampshire Daily'!O7<0), "0",'Hampshire Daily'!O8-'Hampshire Daily'!O7) -> 147 | ... Q5: =IF(('Hampshire Daily'!R8-'Hampshire Daily'!R7<0), "0",'Hampshire Daily'!R8-'Hampshire Daily'!R7) -> 1 | R5: =IF(('Hampshire Daily'!U8-'Hampshire Daily'!U7<0), "0",'Hampshire Daily'!U8-'Hampshire Daily'!U7) -> 11 | S5: =IF(('Hampshire Daily'!V8-'Hampshire Daily'!V7<0), "0",'Hampshire Daily'!V8-'Hampshire Daily'!V7) -> 0 | T5: =IF(('Hampshire Daily'!X8-'Hampshire Daily'!X7<0), "0",'Hampshire Daily'!X8-'Hampshire Daily'!X7) -> 0.05 | U5: =IF(('Hampshire Daily'!Y8-'Hampshire Daily'!Y7<0), "0",'Hampshire Daily'!Y8-'Hampshire Daily'!Y7) -> 0.034 | V5: =IF(('Hampshire Daily'!Z8-'Hampshire Daily'!Z7<0), "0",'Hampshire Daily'!Z8-'Hampshire Daily'!Z7) -> 0.356 | W5: =IF(('Hampshire Daily'!#REF!-'Hampshire Daily'!#REF!<0), "0",'Hampshire Daily'!#REF!-'Hampshire Daily'!#REF!) -> #REF! | X5: ='Hampshire Daily'!B8 -> 86 | Y5: ='Hampshire Daily'!C8 -> 117
A6: Hampshire | B6: =B5+1 -> 5 | C6: 9 | D6: 2019 | E6: =IF(('Hampshire Daily'!D9-'Hampshire Daily'!D8<0), "0",('Hampshire Daily'!D9-'Hampshire Daily'!D8)*10) -> 4480 | F6: =IF(('Hampshire Daily'!F9-'Hampshire Daily'!F8<0), "0",('Hampshire Daily'!F9-'Hampshire Daily'!F8)*10) -> 6630 | G6: =IF(('Hampshire Daily'!H9-'Hampshire Daily'!H8<0), "0",'Hampshire Daily'!H9-'Hampshire Daily'!H8) -> 643 | H6: =IF(('Hampshire Daily'!I9-'Hampshire Daily'!I8<0), "0",'Hampshire Daily'!I9-'Hampshire Daily'!I8) -> 0 | I6: =IF(('Hampshire Daily'!J9-'Hampshire Daily'!J8<0), "0",'Hampshire Daily'!J9-'Hampshire Daily'!J8) -> 0 | J6: =IF(('Hampshire Daily'!K9-'Hampshire Daily'!K8<0), "0",'Hampshire Daily'!K9-'Hampshire Daily'!K8) -> 0 | K6: =IF(('Hampshire Daily'!L9-'Hampshire Daily'!L8<0), "0",'Hampshire Daily'!L9-'Hampshire Daily'!L8) -> 1003 | L6: =IF(('Hampshire Daily'!M9-'Hampshire Daily'!M8<0), "0",'Hampshire Daily'!M9-'Hampshire Daily'!M8) -> 733 | M6: =IF(('Hampshire Daily'!N9-'Hampshire Daily'!N8<0), "0",'Hampshire Daily'!N9-'Hampshire Daily'!N8) -> 1198 | N6: =IF(('Hampshire Daily'!O9-'Hampshire Daily'!O8<0), "0",'Hampshire Daily'!O9-'Hampshire Daily'!O8) -> 195 | ... Q6: =IF(('Hampshire Daily'!R9-'Hampshire Daily'!R8<0), "0",'Hampshire Daily'!R9-'Hampshire Daily'!R8) -> 2 | R6: =IF(('Hampshire Daily'!U9-'Hampshire Daily'!U8<0), "0",'Hampshire Daily'!U9-'Hampshire Daily'!U8) -> 8 | S6: =IF(('Hampshire Daily'!V9-'Hampshire Daily'!V8<0), "0",'Hampshire Daily'!V9-'Hampshire Daily'!V8) -> 0 | T6: =IF(('Hampshire Daily'!X9-'Hampshire Daily'!X8<0), "0",'Hampshire Daily'!X9-'Hampshire Daily'!X8) -> 0.053 | U6: =IF(('Hampshire Daily'!Y9-'Hampshire Daily'!Y8<0), "0",'Hampshire Daily'!Y9-'Hampshire Daily'!Y8) -> 0.004 | V6: =IF(('Hampshire Daily'!Z9-'Hampshire Daily'!Z8<0), "0",'Hampshire Daily'!Z9-'Hampshire Daily'!Z8) -> 0 | W6: =IF(('Hampshire Daily'!#REF!-'Hampshire Daily'!#REF!<0), "0",'Hampshire Daily'!#REF!-'Hampshire Daily'!#REF!) -> #REF! | X6: ='Hampshire Daily'!B9 -> 50 | Y6: ='Hampshire Daily'!C9 -> 95
A7: Hampshire | B7: =B6+1 -> 6 | C7: 9 | D7: 2019 | E7: =IF(('Hampshire Daily'!D10-'Hampshire Daily'!D9<0), "0",('Hampshire Daily'!D10-'Hampshire Daily'!D9)*10) -> 4070 | F7: =IF(('Hampshire Daily'!F10-'Hampshire Daily'!F9<0), "0",('Hampshire Daily'!F10-'Hampshire Daily'!F9)*10) -> 6480 | G7: =IF(('Hampshire Daily'!H10-'Hampshire Daily'!H9<0), "0",'Hampshire Daily'!H10-'Hampshire Daily'!H9) -> 651 | H7: =IF(('Hampshire Daily'!I10-'Hampshire Daily'!I9<0), "0",'Hampshire Daily'!I10-'Hampshire Daily'!I9) -> 0 | I7: =IF(('Hampshire Daily'!J10-'Hampshire Daily'!J9<0), "0",'Hampshire Daily'!J10-'Hampshire Daily'!J9) -> 0 | J7: =IF(('Hampshire Daily'!K10-'Hampshire Daily'!K9<0), "0",'Hampshire Daily'!K10-'Hampshire Daily'!K9) -> 0 | K7: =IF(('Hampshire Daily'!L10-'Hampshire Daily'!L9<0), "0",'Hampshire Daily'!L10-'Hampshire Daily'!L9) -> 1015 | L7: =IF(('Hampshire Daily'!M10-'Hampshire Daily'!M9<0), "0",'Hampshire Daily'!M10-'Hampshire Daily'!M9) -> 740 | M7: =IF(('Hampshire Daily'!N10-'Hampshire Daily'!N9<0), "0",'Hampshire Daily'!N10-'Hampshire Daily'!N9) -> 1229 | N7: =IF(('Hampshire Daily'!O10-'Hampshire Daily'!O9<0), "0",'Hampshire Daily'!O10-'Hampshire Daily'!O9) -> 184 | ... Q7: =IF(('Hampshire Daily'!R10-'Hampshire Daily'!R9<0), "0",'Hampshire Daily'!R10-'Hampshire Daily'!R9) -> 0 | R7: =IF(('Hampshire Daily'!U10-'Hampshire Daily'!U9<0), "0",'Hampshire Daily'!U10-'Hampshire Daily'!U9) -> 9 | S7: =IF(('Hampshire Daily'!V10-'Hampshire Daily'!V9<0), "0",'Hampshire Daily'!V10-'Hampshire Daily'!V9) -> 1 | T7: =IF(('Hampshire Daily'!X10-'Hampshire Daily'!X9<0), "0",'Hampshire Daily'!X10-'Hampshire Daily'!X9) -> 0.055 | U7: =IF(('Hampshire Daily'!Y10-'Hampshire Daily'!Y9<0), "0",'Hampshire Daily'!Y10-'Hampshire Daily'!Y9) -> 0.008 | V7: =IF(('Hampshire Daily'!Z10-'Hampshire Daily'!Z9<0), "0",'Hampshire Daily'!Z10-'Hampshire Daily'!Z9) -> 0 | W7: =IF(('Hampshire Daily'!#REF!-'Hampshire Daily'!#REF!<0), "0",'Hampshire Daily'!#REF!-'Hampshire Daily'!#REF!) -> #REF! | X7: ='Hampshire Daily'!B10 -> 103 | Y7: ='Hampshire Daily'!C10 -> 212
A8: Hampshire | B8: =B7+1 -> 7 | C8: 9 | D8: 2019 | E8: =IF(('Hampshire Daily'!D11-'Hampshire Daily'!D10<0), "0",('Hampshire Daily'!D11-'Hampshire Daily'!D10)*10) -> 4010 | F8: =IF(('Hampshire Daily'!F11-'Hampshire Daily'!F10<0), "0",('Hampshire Daily'!F11-'Hampshire Daily'!F10)*10) -> 6520 | G8: =IF(('Hampshire Daily'!H11-'Hampshire Daily'!H10<0), "0",'Hampshire Daily'!H11-'Hampshire Daily'!H10) -> 704 | H8: =IF(('Hampshire Daily'!I11-'Hampshire Daily'!I10<0), "0",'Hampshire Daily'!I11-'Hampshire Daily'!I10) -> 0 | I8: =IF(('Hampshire Daily'!J11-'Hampshire Daily'!J10<0), "0",'Hampshire Daily'!J11-'Hampshire Daily'!J10) -> 0 | J8: =IF(('Hampshire Daily'!K11-'Hampshire Daily'!K10<0), "0",'Hampshire Daily'!K11-'Hampshire Daily'!K10) -> 0 | K8: =IF(('Hampshire Daily'!L11-'Hampshire Daily'!L10<0), "0",'Hampshire Daily'!L11-'Hampshire Daily'!L10) -> 1073 | L8: =IF(('Hampshire Daily'!M11-'Hampshire Daily'!M10<0), "0",'Hampshire Daily'!M11-'Hampshire Daily'!M10) -> 778 | M8: =IF(('Hampshire Daily'!N11-'Hampshire Daily'!N10<0), "0",'Hampshire Daily'!N11-'Hampshire Daily'!N10) -> 1413 | N8: =IF(('Hampshire Daily'!O11-'Hampshire Daily'!O10<0), "0",'Hampshire Daily'!O11-'Hampshire Daily'!O10) -> 196 | ... Q8: =IF(('Hampshire Daily'!R11-'Hampshire Daily'!R10<0), "0",'Hampshire Daily'!R11-'Hampshire Daily'!R10) -> 0 | R8: =IF(('Hampshire Daily'!U11-'Hampshire Daily'!U10<0), "0",'Hampshire Daily'!U11-'Hampshire Daily'!U10) -> 9 | S8: =IF(('Hampshire Daily'!V11-'Hampshire Daily'!V10<0), "0",'Hampshire Daily'!V11-'Hampshire Daily'!V10) -> 1 | T8: =IF(('Hampshire Daily'!X11-'Hampshire Daily'!X10<0), "0",'Hampshire Daily'!X11-'Hampshire Daily'!X10) -> 0.059 | U8: =IF(('Hampshire Daily'!Y11-'Hampshire Daily'!Y10<0), "0",'Hampshire Daily'!Y11-'Hampshire Daily'!Y10) -> 0.025 | V8: =IF(('Hampshire Daily'!Z11-'Hampshire Daily'!Z10<0), "0",'Hampshire Daily'!Z11-'Hampshire Daily'!Z10) -> 0.002 | W8: =IF(('Hampshire Daily'!#REF!-'Hampshire Daily'!#REF!<0), "0",'Hampshire Daily'!#REF!-'Hampshire Daily'!#REF!) -> #REF! | X8: ='Hampshire Daily'!B11 -> 114 | Y8: ='Hampshire Daily'!C11 -> 233
A9: Hampshire | B9: =B8+1 -> 8 | C9: 9 | D9: 2019 | E9: =IF(('Hampshire Daily'!D12-'Hampshire Daily'!D11<0), "0",('Hampshire Daily'!D12-'Hampshire Daily'!D11)*10) -> 4170 | F9: =IF(('Hampshire Daily'!F12-'Hampshire Daily'!F11<0), "0",('Hampshire Daily'!F12-'Hampshire Daily'!F11)*10) -> 7030 | G9: =IF(('Hampshire Daily'!H12-'Hampshire Daily'!H11<0), "0",'Hampshire Daily'!H12-'Hampshire Daily'!H11) -> 633 | H9: =IF(('Hampshire Daily'!I12-'Hampshire Daily'!I11<0), "0",'Hampshire Daily'!I12-'Hampshire Daily'!I11) -> 0 | I9: =IF(('Hampshire Daily'!J12-'Hampshire Daily'!J11<0), "0",'Hampshire Daily'!J12-'Hampshire Daily'!J11) -> 0 | J9: =IF(('Hampshire Daily'!K12-'Hampshire Daily'!K11<0), "0",'Hampshire Daily'!K12-'Hampshire Daily'!K11) -> 0 | K9: =IF(('Hampshire Daily'!L12-'Hampshire Daily'!L11<0), "0",'Hampshire Daily'!L12-'Hampshire Daily'!L11) -> 1124 | L9: =IF(('Hampshire Daily'!M12-'Hampshire Daily'!M11<0), "0",'Hampshire Daily'!M12-'Hampshire Daily'!M11) -> 778 | M9: =IF(('Hampshire Daily'!N12-'Hampshire Daily'!N11<0), "0",'Hampshire Daily'!N12-'Hampshire Daily'!N11) -> 1448 | N9: =IF(('Hampshire Daily'!O12-'Hampshire Daily'!O11<0), "0",'Hampshire Daily'!O12-'Hampshire Daily'!O11) -> 190 | ... Q9: =IF(('Hampshire Daily'!R12-'Hampshire Daily'!R11<0), "0",'Hampshire Daily'!R12-'Hampshire Daily'!R11) -> 0 | R9: =IF(('Hampshire Daily'!U12-'Hampshire Daily'!U11<0), "0",'Hampshire Daily'!U12-'Hampshire Daily'!U11) -> 9 | S9: =IF(('Hampshire Daily'!V12-'Hampshire Daily'!V11<0), "0",'Hampshire Daily'!V12-'Hampshire Daily'!V11) -> 0 | T9: =IF(('Hampshire Daily'!X12-'Hampshire Daily'!X11<0), "0",'Hampshire Daily'!X12-'Hampshire Daily'!X11) -> 0.06 | U9: =IF(('Hampshire Daily'!Y12-'Hampshire Daily'!Y11<0), "0",'Hampshire Daily'!Y12-'Hampshire Daily'!Y11) -> 0.017 | V9: =IF(('Hampshire Daily'!Z12-'Hampshire Daily'!Z11<0), "0",'Hampshire Daily'!Z12-'Hampshire Daily'!Z11) -> 0 | W9: =IF(('Hampshire Daily'!#REF!-'Hampshire Daily'!#REF!<0), "0",'Hampshire Daily'!#REF!-'Hampshire Daily'!#REF!) -> #REF! | X9: ='Hampshire Daily'!B12 -> 55 | Y9: ='Hampshire Daily'!C12 -> 99
A10: Hampshire | B10: =B9+1 -> 9 | C10: 9 | D10: 2019 | E10: =IF(('Hampshire Daily'!D13-'Hampshire Daily'!D12<0), "0",('Hampshire Daily'!D13-'Hampshire Daily'!D12)*10) -> 3720 | F10: =IF(('Hampshire Daily'!F13-'Hampshire Daily'!F12<0), "0",('Hampshire Daily'!F13-'Hampshire Daily'!F12)*10) -> 6460 | G10: =IF(('Hampshire Daily'!H13-'Hampshire Daily'!H12<0), "0",'Hampshire Daily'!H13-'Hampshire Daily'!H12) -> 646 | H10: =IF(('Hampshire Daily'!I13-'Hampshire Daily'!I12<0), "0",'Hampshire Daily'!I13-'Hampshire Daily'!I12) -> 0 | I10: =IF(('Hampshire Daily'!J13-'Hampshire Daily'!J12<0), "0",'Hampshire Daily'!J13-'Hampshire Daily'!J12) -> 0 | J10: =IF(('Hampshire Daily'!K13-'Hampshire Daily'!K12<0), "0",'Hampshire Daily'!K13-'Hampshire Daily'!K12) -> 0 | K10: =IF(('Hampshire Daily'!L13-'Hampshire Daily'!L12<0), "0",'Hampshire Daily'!L13-'Hampshire Daily'!L12) -> 860 | L10: =IF(('Hampshire Daily'!M13-'Hampshire Daily'!M12<0), "0",'Hampshire Daily'!M13-'Hampshire Daily'!M12) -> 705 | M10: =IF(('Hampshire Daily'!N13-'Hampshire Daily'!N12<0), "0",'Hampshire Daily'!N13-'Hampshire Daily'!N12) -> 1238 | N10: =IF(('Hampshire Daily'!O13-'Hampshire Daily'!O12<0), "0",'Hampshire Daily'!O13-'Hampshire Daily'!O12) -> 190 | ... Q10: =IF(('Hampshire Daily'!R13-'Hampshire Daily'!R12<0), "0",'Hampshire Daily'!R13-'Hampshire Daily'!R12) -> 0 | R10: =IF(('Hampshire Daily'!U13-'Hampshire Daily'!U12<0), "0",'Hampshire Daily'!U13-'Hampshire Daily'!U12) -> 7 | S10: =IF(('Hampshire Daily'!V13-'Hampshire Daily'!V12<0), "0",'Hampshire Daily'!V13-'Hampshire Daily'!V12) -> 5 | T10: =IF(('Hampshire Daily'!X13-'Hampshire Daily'!X12<0), "0",'Hampshire Daily'!X13-'Hampshire Daily'!X12) -> 0.046 | U10: =IF(('Hampshire Daily'!Y13-'Hampshire Daily'!Y12<0), "0",'Hampshire Daily'!Y13-'Hampshire Daily'!Y12) -> 0.017 | V10: =IF(('Hampshire Daily'!Z13-'Hampshire Daily'!Z12<0), "0",'Hampshire Daily'!Z13-'Hampshire Daily'!Z12) -> 0 | W10: =IF(('Hampshire Daily'!#REF!-'Hampshire Daily'!#REF!<0), "0",'Hampshire Daily'!#REF!-'Hampshire Daily'!#REF!) -> #REF! | X10: ='Hampshire Daily'!B13 -> 70 | Y10: ='Hampshire Daily'!C13 -> 104
A11: Hampshire | B11: =B10+1 -> 10 | C11: 9 | D11: 2019 | E11: =IF(('Hampshire Daily'!D14-'Hampshire Daily'!D13<0), "0",('Hampshire Daily'!D14-'Hampshire Daily'!D13)*10) -> 4010 | F11: =IF(('Hampshire Daily'!F14-'Hampshire Daily'!F13<0), "0",('Hampshire Daily'!F14-'Hampshire Daily'!F13)*10) -> 6440 | G11: =IF(('Hampshire Daily'!H14-'Hampshire Daily'!H13<0), "0",'Hampshire Daily'!H14-'Hampshire Daily'!H13) -> 679 | H11: =IF(('Hampshire Daily'!I14-'Hampshire Daily'!I13<0), "0",'Hampshire Daily'!I14-'Hampshire Daily'!I13) -> 0 | I11: =IF(('Hampshire Daily'!J14-'Hampshire Daily'!J13<0), "0",'Hampshire Daily'!J14-'Hampshire Daily'!J13) -> 0 | J11: =IF(('Hampshire Daily'!K14-'Hampshire Daily'!K13<0), "0",'Hampshire Daily'!K14-'Hampshire Daily'!K13) -> 0 | K11: =IF(('Hampshire Daily'!L14-'Hampshire Daily'!L13<0), "0",'Hampshire Daily'!L14-'Hampshire Daily'!L13) -> 1124 | L11: =IF(('Hampshire Daily'!M14-'Hampshire Daily'!M13<0), "0",'Hampshire Daily'!M14-'Hampshire Daily'!M13) -> 809 | M11: =IF(('Hampshire Daily'!N14-'Hampshire Daily'!N13<0), "0",'Hampshire Daily'!N14-'Hampshire Daily'!N13) -> 1415 | N11: =IF(('Hampshire Daily'!O14-'Hampshire Daily'!O13<0), "0",'Hampshire Daily'!O14-'Hampshire Daily'!O13) -> 190 | ... Q11: =IF(('Hampshire Daily'!R14-'Hampshire Daily'!R13<0), "0",'Hampshire Daily'!R14-'Hampshire Daily'!R13) -> 0 | R11: =IF(('Hampshire Daily'!U14-'Hampshire Daily'!U13<0), "0",'Hampshire Daily'!U14-'Hampshire Daily'!U13) -> 10 | S11: =IF(('Hampshire Daily'!V14-'Hampshire Daily'!V13<0), "0",'Hampshire Daily'!V14-'Hampshire Daily'!V13) -> 0 | T11: =IF(('Hampshire Daily'!X14-'Hampshire Daily'!X13<0), "0",'Hampshire Daily'!X14-'Hampshire Daily'!X13) -> 0.071 | U11: =IF(('Hampshire Daily'!Y14-'Hampshire Daily'!Y13<0), "0",'Hampshire Daily'!Y14-'Hampshire Daily'!Y13) -> 0.061 | V11: =IF(('Hampshire Daily'!Z14-'Hampshire Daily'!Z13<0), "0",'Hampshire Daily'!Z14-'Hampshire Daily'!Z13) -> 0 | W11: =IF(('Hampshire Daily'!#REF!-'Hampshire Daily'!#REF!<0), "0",'Hampshire Daily'!#REF!-'Hampshire Daily'!#REF!) -> #REF! | X11: ='Hampshire Daily'!B14 -> 60 | Y11: ='Hampshire Daily'!C14 -> 96
A12: Hampshire | B12: =B11+1 -> 11 | C12: 9 | D12: 2019 | E12: =IF(('Hampshire Daily'!D15-'Hampshire Daily'!D14<0), "0",('Hampshire Daily'!D15-'Hampshire Daily'!D14)*10) -> 4190 | F12: =IF(('Hampshire Daily'!F15-'Hampshire Daily'!F14<0), "0",('Hampshire Daily'!F15-'Hampshire Daily'!F14)*10) -> 6360 | G12: =IF(('Hampshire Daily'!H15-'Hampshire Daily'!H14<0), "0",'Hampshire Daily'!H15-'Hampshire Daily'!H14) -> 631 | H12: =IF(('Hampshire Daily'!I15-'Hampshire Daily'!I14<0), "0",'Hampshire Daily'!I15-'Hampshire Daily'!I14) -> 0 | I12: =IF(('Hampshire Daily'!J15-'Hampshire Daily'!J14<0), "0",'Hampshire Daily'!J15-'Hampshire Daily'!J14) -> 0 | J12: =IF(('Hampshire Daily'!K15-'Hampshire Daily'!K14<0), "0",'Hampshire Daily'!K15-'Hampshire Daily'!K14) -> 0 | K12: =IF(('Hampshire Daily'!L15-'Hampshire Daily'!L14<0), "0",'Hampshire Daily'!L15-'Hampshire Daily'!L14) -> 1124 | L12: =IF(('Hampshire Daily'!M15-'Hampshire Daily'!M14<0), "0",'Hampshire Daily'!M15-'Hampshire Daily'!M14) -> 769 | M12: =IF(('Hampshire Daily'!N15-'Hampshire Daily'!N14<0), "0",'Hampshire Daily'!N15-'Hampshire Daily'!N14) -> 1198 | N12: =IF(('Hampshire Daily'!O15-'Hampshire Daily'!O14<0), "0",'Hampshire Daily'!O15-'Hampshire Daily'!O14) -> 193 | ... Q12: =IF(('Hampshire Daily'!R15-'Hampshire Daily'!R14<0), "0",'Hampshire Daily'!R15-'Hampshire Daily'!R14) -> 1 | R12: =IF(('Hampshire Daily'!U15-'Hampshire Daily'!U14<0), "0",'Hampshire Daily'!U15-'Hampshire Daily'!U14) -> 9 | S12: =IF(('Hampshire Daily'!V15-'Hampshire Daily'!V14<0), "0",'Hampshire Daily'!V15-'Hampshire Daily'!V14) -> 1 | T12: =IF(('Hampshire Daily'!X15-'Hampshire Daily'!X14<0), "0",'Hampshire Daily'!X15-'Hampshire Daily'!X14) -> 0.046 | U12: =IF(('Hampshire Daily'!Y15-'Hampshire Daily'!Y14<0), "0",'Hampshire Daily'!Y15-'Hampshire Daily'!Y14) -> 0.097 | V12: =IF(('Hampshire Daily'!Z15-'Hampshire Daily'!Z14<0), "0",'Hampshire Daily'!Z15-'Hampshire Daily'!Z14) -> 0 | W12: =IF(('Hampshire Daily'!#REF!-'Hampshire Daily'!#REF!<0), "0",'Hampshire Daily'!#REF!-'Hampshire Daily'!#REF!) -> #REF! | X12: ='Hampshire Daily'!B15 -> 126 | Y12: ='Hampshire Daily'!C15 -> 143
A13: Hampshire | B13: =B12+1 -> 12 | C13: 9 | D13: 2019 | E13: =IF(('Hampshire Daily'!D16-'Hampshire Daily'!D15<0), "0",('Hampshire Daily'!D16-'Hampshire Daily'!D15)*10) -> 4650 | F13: =IF(('Hampshire Daily'!F16-'Hampshire Daily'!F15<0), "0",('Hampshire Daily'!F16-'Hampshire Daily'!F15)*10) -> 6720 | G13: =IF(('Hampshire Daily'!H16-'Hampshire Daily'!H15<0), "0",'Hampshire Daily'!H16-'Hampshire Daily'!H15) -> 668 | H13: =IF(('Hampshire Daily'!I16-'Hampshire Daily'!I15<0), "0",'Hampshire Daily'!I16-'Hampshire Daily'!I15) -> 0 | I13: =IF(('Hampshire Daily'!J16-'Hampshire Daily'!J15<0), "0",'Hampshire Daily'!J16-'Hampshire Daily'!J15) -> 0 | J13: =IF(('Hampshire Daily'!K16-'Hampshire Daily'!K15<0), "0",'Hampshire Daily'!K16-'Hampshire Daily'!K15) -> 0 | K13: =IF(('Hampshire Daily'!L16-'Hampshire Daily'!L15<0), "0",'Hampshire Daily'!L16-'Hampshire Daily'!L15) -> 1124 | L13: =IF(('Hampshire Daily'!M16-'Hampshire Daily'!M15<0), "0",'Hampshire Daily'!M16-'Hampshire Daily'!M15) -> 796 | M13: =IF(('Hampshire Daily'!N16-'Hampshire Daily'!N15<0), "0",'Hampshire Daily'!N16-'Hampshire Daily'!N15) -> 1151 | N13: =IF(('Hampshire Daily'!O16-'Hampshire Daily'!O15<0), "0",'Hampshire Daily'!O16-'Hampshire Daily'!O15) -> 190 | ... Q13: =IF(('Hampshire Daily'!R16-'Hampshire Daily'!R15<0), "0",'Hampshire Daily'!R16-'Hampshire Daily'!R15) -> 1 | R13: =IF(('Hampshire Daily'!U16-'Hampshire Daily'!U15<0), "0",'Hampshire Daily'!U16-'Hampshire Daily'!U15) -> 10 | S13: =IF(('Hampshire Daily'!V16-'Hampshire Daily'!V15<0), "0",'Hampshire Daily'!V16-'Hampshire Daily'!V15) -> 0 | T13: =IF(('Hampshire Daily'!X16-'Hampshire Daily'!X15<0), "0",'Hampshire Daily'!X16-'Hampshire Daily'!X15) -> 0.044 | U13: =IF(('Hampshire Daily'!Y16-'Hampshire Daily'!Y15<0), "0",'Hampshire Daily'!Y16-'Hampshire Daily'!Y15) -> 0.027 | V13: =IF(('Hampshire Daily'!Z16-'Hampshire Daily'!Z15<0), "0",'Hampshire Daily'!Z16-'Hampshire Daily'!Z15) -> 0 | W13: =IF(('Hampshire Daily'!#REF!-'Hampshire Daily'!#REF!<0), "0",'Hampshire Daily'!#REF!-'Hampshire Daily'!#REF!) -> #REF! | X13: ='Hampshire Daily'!B16 -> 127 | Y13: ='Hampshire Daily'!C16 -> 148
A14: Hampshire | B14: =B13+1 -> 13 | C14: 9 | D14: 2019 | E14: =IF(('Hampshire Daily'!D17-'Hampshire Daily'!D16<0), "0",('Hampshire Daily'!D17-'Hampshire Daily'!D16)*10) -> 4720 | F14: =IF(('Hampshire Daily'!F17-'Hampshire Daily'!F16<0), "0",('Hampshire Daily'!F17-'Hampshire Daily'!F16)*10) -> 6470 | G14: =IF(('Hampshire Daily'!H17-'Hampshire Daily'!H16<0), "0",'Hampshire Daily'!H17-'Hampshire Daily'!H16) -> 610 | H14: =IF(('Hampshire Daily'!I17-'Hampshire Daily'!I16<0), "0",'Hampshire Daily'!I17-'Hampshire Daily'!I16) -> 0 | I14: =IF(('Hampshire Daily'!J17-'Hampshire Daily'!J16<0), "0",'Hampshire Daily'!J17-'Hampshire Daily'!J16) -> 0 | J14: =IF(('Hampshire Daily'!K17-'Hampshire Daily'!K16<0), "0",'Hampshire Daily'!K17-'Hampshire Daily'!K16) -> 0 | K14: =IF(('Hampshire Daily'!L17-'Hampshire Daily'!L16<0), "0",'Hampshire Daily'!L17-'Hampshire Daily'!L16) -> 1124 | L14: =IF(('Hampshire Daily'!M17-'Hampshire Daily'!M16<0), "0",'Hampshire Daily'!M17-'Hampshire Daily'!M16) -> 757 | M14: =IF(('Hampshire Daily'!N17-'Hampshire Daily'!N16<0), "0",'Hampshire Daily'!N17-'Hampshire Daily'!N16) -> 1101 | N14: =IF(('Hampshire Daily'!O17-'Hampshire Daily'!O16<0), "0",'Hampshire Daily'!O17-'Hampshire Daily'!O16) -> 190 | ... Q14: =IF(('Hampshire Daily'!R17-'Hampshire Daily'!R16<0), "0",'Hampshire Daily'!R17-'Hampshire Daily'!R16) -> 2 | R14: =IF(('Hampshire Daily'!U17-'Hampshire Daily'!U16<0), "0",'Hampshire Daily'!U17-'Hampshire Daily'!U16) -> 8 | S14: =IF(('Hampshire Daily'!V17-'Hampshire Daily'!V16<0), "0",'Hampshire Daily'!V17-'Hampshire Daily'!V16) -> 0 | T14: =IF(('Hampshire Daily'!X17-'Hampshire Daily'!X16<0), "0",'Hampshire Daily'!X17-'Hampshire Daily'!X16) -> 0.066 | U14: =IF(('Hampshire Daily'!Y17-'Hampshire Daily'!Y16<0), "0",'Hampshire Daily'!Y17-'Hampshire Daily'!Y16) -> 0.029 | V14: =IF(('Hampshire Daily'!Z17-'Hampshire Daily'!Z16<0), "0",'Hampshire Daily'!Z17-'Hampshire Daily'!Z16) -> 0 | W14: =IF(('Hampshire Daily'!#REF!-'Hampshire Daily'!#REF!<0), "0",'Hampshire Daily'!#REF!-'Hampshire Daily'!#REF!) -> #REF! | X14: ='Hampshire Daily'!B17 -> 89 | Y14: ='Hampshire Daily'!C17 -> 162
... A17: Hampshire | B17: =B16+1 -> 16 | C17: 9 | D17: 2019 | E17: =IF(('Hampshire Daily'!D20-'Hampshire Daily'!D19<0), "0",('Hampshire Daily'!D20-'Hampshire Daily'!D19)*10) -> 5010 | F17: =IF(('Hampshire Daily'!F20-'Hampshire Daily'!F19<0), "0",('Hampshire Daily'!F20-'Hampshire Daily'!F19)*10) -> 6830 | G17: =IF(('Hampshire Daily'!H20-'Hampshire Daily'!H19<0), "0",'Hampshire Daily'!H20-'Hampshire Daily'!H19) -> 640 | H17: =IF(('Hampshire Daily'!I20-'Hampshire Daily'!I19<0), "0",'Hampshire Daily'!I20-'Hampshire Daily'!I19) -> 0 | I17: =IF(('Hampshire Daily'!J20-'Hampshire Daily'!J19<0), "0",'Hampshire Daily'!J20-'Hampshire Daily'!J19) -> 0 | J17: =IF(('Hampshire Daily'!K20-'Hampshire Daily'!K19<0), "0",'Hampshire Daily'!K20-'Hampshire Daily'!K19) -> 0 | K17: =IF(('Hampshire Daily'!L20-'Hampshire Daily'!L19<0), "0",'Hampshire Daily'!L20-'Hampshire Daily'!L19) -> 289 | L17: =IF(('Hampshire Daily'!M20-'Hampshire Daily'!M19<0), "0",'Hampshire Daily'!M20-'Hampshire Daily'!M19) -> 757 | M17: =IF(('Hampshire Daily'!N20-'Hampshire Daily'!N19<0), "0",'Hampshire Daily'!N20-'Hampshire Daily'!N19) -> 1088 | N17: =IF(('Hampshire Daily'!O20-'Hampshire Daily'!O19<0), "0",'Hampshire Daily'!O20-'Hampshire Daily'!O19) -> 203 | ... Q17: =IF(('Hampshire Daily'!R20-'Hampshire Daily'!R19<0), "0",'Hampshire Daily'!R20-'Hampshire Daily'!R19) -> 3 | R17: =IF(('Hampshire Daily'!U20-'Hampshire Daily'!U19<0), "0",'Hampshire Daily'!U20-'Hampshire Daily'!U19) -> 9 | S17: =IF(('Hampshire Daily'!V20-'Hampshire Daily'!V19<0), "0",'Hampshire Daily'!V20-'Hampshire Daily'!V19) -> 25 | T17: =IF(('Hampshire Daily'!X20-'Hampshire Daily'!X19<0), "0",'Hampshire Daily'!X20-'Hampshire Daily'!X19) -> 0.075 | U17: =IF(('Hampshire Daily'!Y20-'Hampshire Daily'!Y19<0), "0",'Hampshire Daily'!Y20-'Hampshire Daily'!Y19) -> 0.013 | V17: =IF(('Hampshire Daily'!Z20-'Hampshire Daily'!Z19<0), "0",'Hampshire Daily'!Z20-'Hampshire Daily'!Z19) -> 0 | W17: =IF(('Hampshire Daily'!#REF!-'Hampshire Daily'!#REF!<0), "0",'Hampshire Daily'!#REF!-'Hampshire Daily'!#REF!) -> #REF! | X17: ='Hampshire Daily'!B20 -> 66 | Y17: ='Hampshire Daily'!C20 -> 108
A18: Hampshire | B18: =B17+1 -> 17 | C18: 9 | D18: 2019 | E18: =IF(('Hampshire Daily'!D21-'Hampshire Daily'!D20<0), "0",('Hampshire Daily'!D21-'Hampshire Daily'!D20)*10) -> 4700 | F18: =IF(('Hampshire Daily'!F21-'Hampshire Daily'!F20<0), "0",('Hampshire Daily'!F21-'Hampshire Daily'!F20)*10) -> 6620 | G18: =IF(('Hampshire Daily'!H21-'Hampshire Daily'!H20<0), "0",'Hampshire Daily'!H21-'Hampshire Daily'!H20) -> 637 | H18: =IF(('Hampshire Daily'!I21-'Hampshire Daily'!I20<0), "0",'Hampshire Daily'!I21-'Hampshire Daily'!I20) -> 0 | I18: =IF(('Hampshire Daily'!J21-'Hampshire Daily'!J20<0), "0",'Hampshire Daily'!J21-'Hampshire Daily'!J20) -> 0 | J18: =IF(('Hampshire Daily'!K21-'Hampshire Daily'!K20<0), "0",'Hampshire Daily'!K21-'Hampshire Daily'!K20) -> 0 | K18: =IF(('Hampshire Daily'!L21-'Hampshire Daily'!L20<0), "0",'Hampshire Daily'!L21-'Hampshire Daily'!L20) -> 942 | L18: =IF(('Hampshire Daily'!M21-'Hampshire Daily'!M20<0), "0",'Hampshire Daily'!M21-'Hampshire Daily'!M20) -> 795 | M18: =IF(('Hampshire Daily'!N21-'Hampshire Daily'!N20<0), "0",'Hampshire Daily'!N21-'Hampshire Daily'!N20) -> 1224 | N18: =IF(('Hampshire Daily'!O21-'Hampshire Daily'!O20<0), "0",'Hampshire Daily'!O21-'Hampshire Daily'!O20) -> 183 | ... Q18: =IF(('Hampshire Daily'!R21-'Hampshire Daily'!R20<0), "0",'Hampshire Daily'!R21-'Hampshire Daily'!R20) -> 2 | R18: =IF(('Hampshire Daily'!U21-'Hampshire Daily'!U20<0), "0",'Hampshire Daily'!U21-'Hampshire Daily'!U20) -> 8 | S18: =IF(('Hampshire Daily'!V21-'Hampshire Daily'!V20<0), "0",'Hampshire Daily'!V21-'Hampshire Daily'!V20) -> 0 | T18: =IF(('Hampshire Daily'!Y21-'Hampshire Daily'!X20<0), "0",'Hampshire Daily'!Y21-'Hampshire Daily'!X20) -> 454.029 | U18: =IF(('Hampshire Daily'!Z21-'Hampshire Daily'!Y20<0), "0",'Hampshire Daily'!Z21-'Hampshire Daily'!Y20) -> 3022.91 | V18: =IF(('Hampshire Daily'!#REF!-'Hampshire Daily'!Z20<0), "0",'Hampshire Daily'!#REF!-'Hampshire Daily'!Z20) -> #REF! | W18: =IF(('Hampshire Daily'!#REF!-'Hampshire Daily'!#REF!<0), "0",'Hampshire Daily'!#REF!-'Hampshire Daily'!#REF!) -> #REF! | X18: ='Hampshire Daily'!B21 -> 107 | Y18: ='Hampshire Daily'!C21 -> 164
A19: Hampshire | B19: =B18+1 -> 18 | C19: 9 | D19: 2019 | E19: =IF(('Hampshire Daily'!D22-'Hampshire Daily'!D21<0), "0",('Hampshire Daily'!D22-'Hampshire Daily'!D21)*10) -> 4870 | F19: =IF(('Hampshire Daily'!F22-'Hampshire Daily'!F21<0), "0",('Hampshire Daily'!F22-'Hampshire Daily'!F21)*10) -> 5730 | G19: =IF(('Hampshire Daily'!H22-'Hampshire Daily'!H21<0), "0",'Hampshire Daily'!H22-'Hampshire Daily'!H21) -> 701 | H19: =IF(('Hampshire Daily'!I22-'Hampshire Daily'!I21<0), "0",'Hampshire Daily'!I22-'Hampshire Daily'!I21) -> 0 | I19: =IF(('Hampshire Daily'!J22-'Hampshire Daily'!J21<0), "0",'Hampshire Daily'!J22-'Hampshire Daily'!J21) -> 0 | J19: =IF(('Hampshire Daily'!K22-'Hampshire Daily'!K21<0), "0",'Hampshire Daily'!K22-'Hampshire Daily'!K21) -> 0 | K19: =IF(('Hampshire Daily'!L22-'Hampshire Daily'!L21<0), "0",'Hampshire Daily'!L22-'Hampshire Daily'!L21) -> 1035 | L19: =IF(('Hampshire Daily'!M22-'Hampshire Daily'!M21<0), "0",'Hampshire Daily'!M22-'Hampshire Daily'!M21) -> 779 | M19: =IF(('Hampshire Daily'!N22-'Hampshire Daily'!N21<0), "0",'Hampshire Daily'!N22-'Hampshire Daily'!N21) -> 1381 | N19: =IF(('Hampshire Daily'!O22-'Hampshire Daily'!O21<0), "0",'Hampshire Daily'!O22-'Hampshire Daily'!O21) -> 185 | ... Q19: =IF(('Hampshire Daily'!R22-'Hampshire Daily'!R21<0), "0",'Hampshire Daily'!R22-'Hampshire Daily'!R21) -> 0 | R19: =IF(('Hampshire Daily'!U22-'Hampshire Daily'!U21<0), "0",'Hampshire Daily'!U22-'Hampshire Daily'!U21) -> 8 | S19: =IF(('Hampshire Daily'!V22-'Hampshire Daily'!V21<0), "0",'Hampshire Daily'!V22-'Hampshire Daily'!V21) -> 2 | T19: =IF(('Hampshire Daily'!Y22-'Hampshire Daily'!Y21<0), "0",'Hampshire Daily'!Y22-'Hampshire Daily'!Y21) -> 0.034 | U19: =IF(('Hampshire Daily'!Z22-'Hampshire Daily'!Z21<0), "0",'Hampshire Daily'!Z22-'Hampshire Daily'!Z21) -> 0 | V19: =IF(('Hampshire Daily'!#REF!-'Hampshire Daily'!#REF!<0), "0",'Hampshire Daily'!#REF!-'Hampshire Daily'!#REF!) -> #REF! | W19: =IF(('Hampshire Daily'!#REF!-'Hampshire Daily'!#REF!<0), "0",'Hampshire Daily'!#REF!-'Hampshire Daily'!#REF!) -> #REF! | X19: ='Hampshire Daily'!B22 -> 128 | Y19: ='Hampshire Daily'!C22 -> 177
A20: Hampshire | B20: =B19+1 -> 19 | C20: 9 | D20: 2019 | E20: =IF(('Hampshire Daily'!D23-'Hampshire Daily'!D22<0), "0",('Hampshire Daily'!D23-'Hampshire Daily'!D22)*10) -> 5420 | F20: =IF(('Hampshire Daily'!F23-'Hampshire Daily'!F22<0), "0",('Hampshire Daily'!F23-'Hampshire Daily'!F22)*10) -> 5860 | G20: =IF(('Hampshire Daily'!H23-'Hampshire Daily'!H22<0), "0",'Hampshire Daily'!H23-'Hampshire Daily'!H22) -> 769 | H20: =IF(('Hampshire Daily'!I23-'Hampshire Daily'!I22<0), "0",'Hampshire Daily'!I23-'Hampshire Daily'!I22) -> 0 | I20: =IF(('Hampshire Daily'!J23-'Hampshire Daily'!J22<0), "0",'Hampshire Daily'!J23-'Hampshire Daily'!J22) -> 0 | J20: =IF(('Hampshire Daily'!K23-'Hampshire Daily'!K22<0), "0",'Hampshire Daily'!K23-'Hampshire Daily'!K22) -> 0 | K20: =IF(('Hampshire Daily'!L23-'Hampshire Daily'!L22<0), "0",'Hampshire Daily'!L23-'Hampshire Daily'!L22) -> 1035 | L20: =IF(('Hampshire Daily'!M23-'Hampshire Daily'!M22<0), "0",'Hampshire Daily'!M23-'Hampshire Daily'!M22) -> 799 | M20: =IF(('Hampshire Daily'!N23-'Hampshire Daily'!N22<0), "0",'Hampshire Daily'!N23-'Hampshire Daily'!N22) -> 1477 | N20: =IF(('Hampshire Daily'!O23-'Hampshire Daily'!O22<0), "0",'Hampshire Daily'!O23-'Hampshire Daily'!O22) -> 200 | ... Q20: =IF(('Hampshire Daily'!R23-'Hampshire Daily'!R22<0), "0",'Hampshire Daily'!R23-'Hampshire Daily'!R22) -> 0 | R20: =IF(('Hampshire Daily'!U23-'Hampshire Daily'!U22<0), "0",'Hampshire Daily'!U23-'Hampshire Daily'!U22) -> 11 | S20: =IF(('Hampshire Daily'!V23-'Hampshire Daily'!V22<0), "0",'Hampshire Daily'!V23-'Hampshire Daily'!V22) -> 1 | T20: =IF(('Hampshire Daily'!Y23-'Hampshire Daily'!Y22<0), "0",'Hampshire Daily'!Y23-'Hampshire Daily'!Y22) -> 0.024 | U20: =IF(('Hampshire Daily'!Z23-'Hampshire Daily'!Z22<0), "0",'Hampshire Daily'!Z23-'Hampshire Daily'!Z22) -> 0 | V20: =IF(('Hampshire Daily'!#REF!-'Hampshire Daily'!#REF!<0), "0",'Hampshire Daily'!#REF!-'Hampshire Daily'!#REF!) -> #REF! | W20: =IF(('Hampshire Daily'!#REF!-'Hampshire Daily'!#REF!<0), "0",'Hampshire Daily'!#REF!-'Hampshire Daily'!#REF!) -> #REF! | X20: ='Hampshire Daily'!B23 -> 75 | Y20: ='Hampshire Daily'!C23 -> 136
A21: Hampshire | B21: =B20+1 -> 20 | C21: 9 | D21: 2019 | E21: =IF(('Hampshire Daily'!D24-'Hampshire Daily'!D23<0), "0",('Hampshire Daily'!D24-'Hampshire Daily'!D23)*10) -> 5600 | F21: =IF(('Hampshire Daily'!F24-'Hampshire Daily'!F23<0), "0",('Hampshire Daily'!F24-'Hampshire Daily'!F23)*10) -> 5910 | G21: =IF(('Hampshire Daily'!H24-'Hampshire Daily'!H23<0), "0",'Hampshire Daily'!H24-'Hampshire Daily'!H23) -> 778 | H21: =IF(('Hampshire Daily'!I24-'Hampshire Daily'!I23<0), "0",'Hampshire Daily'!I24-'Hampshire Daily'!I23) -> 0 | I21: =IF(('Hampshire Daily'!J24-'Hampshire Daily'!J23<0), "0",'Hampshire Daily'!J24-'Hampshire Daily'!J23) -> 0 | J21: =IF(('Hampshire Daily'!K24-'Hampshire Daily'!K23<0), "0",'Hampshire Daily'!K24-'Hampshire Daily'!K23) -> 0 | K21: =IF(('Hampshire Daily'!L24-'Hampshire Daily'!L23<0), "0",'Hampshire Daily'!L24-'Hampshire Daily'!L23) -> 1035 | L21: =IF(('Hampshire Daily'!M24-'Hampshire Daily'!M23<0), "0",'Hampshire Daily'!M24-'Hampshire Daily'!M23) -> 795 | M21: =IF(('Hampshire Daily'!N24-'Hampshire Daily'!N23<0), "0",'Hampshire Daily'!N24-'Hampshire Daily'!N23) -> 1409 | N21: =IF(('Hampshire Daily'!O24-'Hampshire Daily'!O23<0), "0",'Hampshire Daily'!O24-'Hampshire Daily'!O23) -> 187 | ... Q21: =IF(('Hampshire Daily'!R24-'Hampshire Daily'!R23<0), "0",'Hampshire Daily'!R24-'Hampshire Daily'!R23) -> 0 | R21: =IF(('Hampshire Daily'!U24-'Hampshire Daily'!U23<0), "0",'Hampshire Daily'!U24-'Hampshire Daily'!U23) -> 15 | S21: =IF(('Hampshire Daily'!V24-'Hampshire Daily'!V23<0), "0",'Hampshire Daily'!V24-'Hampshire Daily'!V23) -> 1 | T21: =IF(('Hampshire Daily'!Y24-'Hampshire Daily'!Y23<0), "0",'Hampshire Daily'!Y24-'Hampshire Daily'!Y23) -> 0.028 | U21: =IF(('Hampshire Daily'!Z24-'Hampshire Daily'!Z23<0), "0",'Hampshire Daily'!Z24-'Hampshire Daily'!Z23) -> 0 | V21: =IF(('Hampshire Daily'!#REF!-'Hampshire Daily'!#REF!<0), "0",'Hampshire Daily'!#REF!-'Hampshire Daily'!#REF!) -> #REF! | W21: =IF(('Hampshire Daily'!#REF!-'Hampshire Daily'!#REF!<0), "0",'Hampshire Daily'!#REF!-'Hampshire Daily'!#REF!) -> #REF! | X21: ='Hampshire Daily'!B24 -> 66 | Y21: ='Hampshire Daily'!C24 -> 177
A22: Hampshire | B22: =B21+1 -> 21 | C22: 9 | D22: 2019 | E22: =IF(('Hampshire Daily'!D25-'Hampshire Daily'!D24<0), "0",('Hampshire Daily'!D25-'Hampshire Daily'!D24)*10) -> 4820 | F22: =IF(('Hampshire Daily'!F25-'Hampshire Daily'!F24<0), "0",('Hampshire Daily'!F25-'Hampshire Daily'!F24)*10) -> 6680 | G22: =IF(('Hampshire Daily'!H25-'Hampshire Daily'!H24<0), "0",'Hampshire Daily'!H25-'Hampshire Daily'!H24) -> 778 | H22: =IF(('Hampshire Daily'!I25-'Hampshire Daily'!I24<0), "0",'Hampshire Daily'!I25-'Hampshire Daily'!I24) -> 0 | I22: =IF(('Hampshire Daily'!J25-'Hampshire Daily'!J24<0), "0",'Hampshire Daily'!J25-'Hampshire Daily'!J24) -> 0 | J22: =IF(('Hampshire Daily'!K25-'Hampshire Daily'!K24<0), "0",'Hampshire Daily'!K25-'Hampshire Daily'!K24) -> 0 | K22: =IF(('Hampshire Daily'!L25-'Hampshire Daily'!L24<0), "0",'Hampshire Daily'!L25-'Hampshire Daily'!L24) -> 1035 | L22: =IF(('Hampshire Daily'!M25-'Hampshire Daily'!M24<0), "0",'Hampshire Daily'!M25-'Hampshire Daily'!M24) -> 795 | M22: =IF(('Hampshire Daily'!N25-'Hampshire Daily'!N24<0), "0",'Hampshire Daily'!N25-'Hampshire Daily'!N24) -> 1282 | N22: =IF(('Hampshire Daily'!O25-'Hampshire Daily'!O24<0), "0",'Hampshire Daily'!O25-'Hampshire Daily'!O24) -> 187 | ... Q22: =IF(('Hampshire Daily'!R25-'Hampshire Daily'!R24<0), "0",'Hampshire Daily'!R25-'Hampshire Daily'!R24) -> 1.5 | R22: =IF(('Hampshire Daily'!U25-'Hampshire Daily'!U24<0), "0",'Hampshire Daily'!U25-'Hampshire Daily'!U24) -> 7.5 | S22: =IF(('Hampshire Daily'!V25-'Hampshire Daily'!V24<0), "0",'Hampshire Daily'!V25-'Hampshire Daily'!V24) -> 0 | T22: =IF(('Hampshire Daily'!Y25-'Hampshire Daily'!Y24<0), "0",'Hampshire Daily'!Y25-'Hampshire Daily'!Y24) -> 0.014 | U22: =IF(('Hampshire Daily'!Z25-'Hampshire Daily'!Z24<0), "0",'Hampshire Daily'!Z25-'Hampshire Daily'!Z24) -> 0 | V22: =IF(('Hampshire Daily'!#REF!-'Hampshire Daily'!#REF!<0), "0",'Hampshire Daily'!#REF!-'Hampshire Daily'!#REF!) -> #REF! | W22: =IF(('Hampshire Daily'!#REF!-'Hampshire Daily'!#REF!<0), "0",'Hampshire Daily'!#REF!-'Hampshire Daily'!#REF!) -> #REF! | X22: ='Hampshire Daily'!B25 -> 121 | Y22: ='Hampshire Daily'!C25 -> 304
A23: Hampshire | B23: =B22+1 -> 22 | C23: 9 | D23: 2019 | E23: =IF(('Hampshire Daily'!D26-'Hampshire Daily'!D25<0), "0",('Hampshire Daily'!D26-'Hampshire Daily'!D25)*10) -> 4820 | F23: =IF(('Hampshire Daily'!F26-'Hampshire Daily'!F25<0), "0",('Hampshire Daily'!F26-'Hampshire Daily'!F25)*10) -> 6680 | G23: =IF(('Hampshire Daily'!H26-'Hampshire Daily'!H25<0), "0",'Hampshire Daily'!H26-'Hampshire Daily'!H25) -> 778 | H23: =IF(('Hampshire Daily'!I26-'Hampshire Daily'!I25<0), "0",'Hampshire Daily'!I26-'Hampshire Daily'!I25) -> 0 | I23: =IF(('Hampshire Daily'!J26-'Hampshire Daily'!J25<0), "0",'Hampshire Daily'!J26-'Hampshire Daily'!J25) -> 0 | J23: =IF(('Hampshire Daily'!K26-'Hampshire Daily'!K25<0), "0",'Hampshire Daily'!K26-'Hampshire Daily'!K25) -> 0 | K23: =IF(('Hampshire Daily'!L26-'Hampshire Daily'!L25<0), "0",'Hampshire Daily'!L26-'Hampshire Daily'!L25) -> 1035 | L23: =IF(('Hampshire Daily'!M26-'Hampshire Daily'!M25<0), "0",'Hampshire Daily'!M26-'Hampshire Daily'!M25) -> 795 | M23: =IF(('Hampshire Daily'!N26-'Hampshire Daily'!N25<0), "0",'Hampshire Daily'!N26-'Hampshire Daily'!N25) -> 1283 | N23: =IF(('Hampshire Daily'!O26-'Hampshire Daily'!O25<0), "0",'Hampshire Daily'!O26-'Hampshire Daily'!O25) -> 187 | ... Q23: =IF(('Hampshire Daily'!R26-'Hampshire Daily'!R25<0), "0",'Hampshire Daily'!R26-'Hampshire Daily'!R25) -> 1.5 | R23: =IF(('Hampshire Daily'!U26-'Hampshire Daily'!U25<0), "0",'Hampshire Daily'!U26-'Hampshire Daily'!U25) -> 7.5 | S23: =IF(('Hampshire Daily'!V26-'Hampshire Daily'!V25<0), "0",'Hampshire Daily'!V26-'Hampshire Daily'!V25) -> 1 | T23: =IF(('Hampshire Daily'!Y26-'Hampshire Daily'!Y25<0), "0",'Hampshire Daily'!Y26-'Hampshire Daily'!Y25) -> 0.042 | U23: =IF(('Hampshire Daily'!Z26-'Hampshire Daily'!Z25<0), "0",'Hampshire Daily'!Z26-'Hampshire Daily'!Z25) -> 0.045 | V23: =IF(('Hampshire Daily'!#REF!-'Hampshire Daily'!#REF!<0), "0",'Hampshire Daily'!#REF!-'Hampshire Daily'!#REF!) -> #REF! | W23: =IF(('Hampshire Daily'!#REF!-'Hampshire Daily'!#REF!<0), "0",'Hampshire Daily'!#REF!-'Hampshire Daily'!#REF!) -> #REF! | X23: ='Hampshire Daily'!B26 -> 120 | Y23: ='Hampshire Daily'!C26 -> 189
A24: Hampshire | B24: =B23+1 -> 23 | C24: 9 | D24: 2019 | E24: =IF(('Hampshire Daily'!D27-'Hampshire Daily'!D26<0), "0",('Hampshire Daily'!D27-'Hampshire Daily'!D26)*10) -> 5510 | F24: =IF(('Hampshire Daily'!F27-'Hampshire Daily'!F26<0), "0",('Hampshire Daily'!F27-'Hampshire Daily'!F26)*10) -> 7600 | G24: =IF(('Hampshire Daily'!H27-'Hampshire Daily'!H26<0), "0",'Hampshire Daily'!H27-'Hampshire Daily'!H26) -> 780 | H24: =IF(('Hampshire Daily'!I27-'Hampshire Daily'!I26<0), "0",'Hampshire Daily'!I27-'Hampshire Daily'!I26) -> 0 | I24: =IF(('Hampshire Daily'!J27-'Hampshire Daily'!J26<0), "0",'Hampshire Daily'!J27-'Hampshire Daily'!J26) -> 0 | J24: =IF(('Hampshire Daily'!K27-'Hampshire Daily'!K26<0), "0",'Hampshire Daily'!K27-'Hampshire Daily'!K26) -> 0 | K24: =IF(('Hampshire Daily'!L27-'Hampshire Daily'!L26<0), "0",'Hampshire Daily'!L27-'Hampshire Daily'!L26) -> 1035 | L24: =IF(('Hampshire Daily'!M27-'Hampshire Daily'!M26<0), "0",'Hampshire Daily'!M27-'Hampshire Daily'!M26) -> 795 | M24: =IF(('Hampshire Daily'!N27-'Hampshire Daily'!N26<0), "0",'Hampshire Daily'!N27-'Hampshire Daily'!N26) -> 1454 | N24: =IF(('Hampshire Daily'!O27-'Hampshire Daily'!O26<0), "0",'Hampshire Daily'!O27-'Hampshire Daily'!O26) -> 189.7 | ... Q24: =IF(('Hampshire Daily'!R27-'Hampshire Daily'!R26<0), "0",'Hampshire Daily'!R27-'Hampshire Daily'!R26) -> 3 | R24: =IF(('Hampshire Daily'!U27-'Hampshire Daily'!U26<0), "0",'Hampshire Daily'!U27-'Hampshire Daily'!U26) -> 8 | S24: =IF(('Hampshire Daily'!V27-'Hampshire Daily'!V26<0), "0",'Hampshire Daily'!V27-'Hampshire Daily'!V26) -> 0 | T24: =IF(('Hampshire Daily'!Y27-'Hampshire Daily'!Y26<0), "0",'Hampshire Daily'!Y27-'Hampshire Daily'!Y26) -> 0.011 | U24: =IF(('Hampshire Daily'!Z27-'Hampshire Daily'!Z26<0), "0",'Hampshire Daily'!Z27-'Hampshire Daily'!Z26) -> 0 | V24: =IF(('Hampshire Daily'!#REF!-'Hampshire Daily'!#REF!<0), "0",'Hampshire Daily'!#REF!-'Hampshire Daily'!#REF!) -> #REF! | W24: =IF(('Hampshire Daily'!#REF!-'Hampshire Daily'!#REF!<0), "0",'Hampshire Daily'!#REF!-'Hampshire Daily'!#REF!) -> #REF! | X24: ='Hampshire Daily'!B27 -> 106 | Y24: ='Hampshire Daily'!C27 -> 119
A25: Hampshire | B25: =B24+1 -> 24 | C25: 9 | D25: 2019 | E25: =IF(('Hampshire Daily'!D28-'Hampshire Daily'!D27<0), "0",('Hampshire Daily'!D28-'Hampshire Daily'!D27)*10) -> 5310 | F25: =IF(('Hampshire Daily'!F28-'Hampshire Daily'!F27<0), "0",('Hampshire Daily'!F28-'Hampshire Daily'!F27)*10) -> 0 | G25: =IF(('Hampshire Daily'!H28-'Hampshire Daily'!H27<0), "0",'Hampshire Daily'!H28-'Hampshire Daily'!H27) -> 769 | H25: =IF(('Hampshire Daily'!I28-'Hampshire Daily'!I27<0), "0",'Hampshire Daily'!I28-'Hampshire Daily'!I27) -> 0 | I25: =IF(('Hampshire Daily'!J28-'Hampshire Daily'!J27<0), "0",'Hampshire Daily'!J28-'Hampshire Daily'!J27) -> 0 | J25: =IF(('Hampshire Daily'!K28-'Hampshire Daily'!K27<0), "0",'Hampshire Daily'!K28-'Hampshire Daily'!K27) -> 0 | K25: =IF(('Hampshire Daily'!L28-'Hampshire Daily'!L27<0), "0",'Hampshire Daily'!L28-'Hampshire Daily'!L27) -> 1035 | L25: =IF(('Hampshire Daily'!M28-'Hampshire Daily'!M27<0), "0",'Hampshire Daily'!M28-'Hampshire Daily'!M27) -> 777 | M25: =IF(('Hampshire Daily'!N28-'Hampshire Daily'!N27<0), "0",'Hampshire Daily'!N28-'Hampshire Daily'!N27) -> 1393 | N25: =IF(('Hampshire Daily'!O28-'Hampshire Daily'!O27<0), "0",'Hampshire Daily'!O28-'Hampshire Daily'!O27) -> 203.3 | ... Q25: =IF(('Hampshire Daily'!R28-'Hampshire Daily'!R27<0), "0",'Hampshire Daily'!R28-'Hampshire Daily'!R27) -> 2 | R25: =IF(('Hampshire Daily'!U28-'Hampshire Daily'!U27<0), "0",'Hampshire Daily'!U28-'Hampshire Daily'!U27) -> 8 | S25: =IF(('Hampshire Daily'!V28-'Hampshire Daily'!V27<0), "0",'Hampshire Daily'!V28-'Hampshire Daily'!V27) -> 0 | T25: =IF(('Hampshire Daily'!Y28-'Hampshire Daily'!Y27<0), "0",'Hampshire Daily'!Y28-'Hampshire Daily'!Y27) -> 0.024 | U25: =IF(('Hampshire Daily'!Z28-'Hampshire Daily'!Z27<0), "0",'Hampshire Daily'!Z28-'Hampshire Daily'!Z27) -> 0.117 | V25: =IF(('Hampshire Daily'!#REF!-'Hampshire Daily'!#REF!<0), "0",'Hampshire Daily'!#REF!-'Hampshire Daily'!#REF!) -> #REF! | W25: =IF(('Hampshire Daily'!#REF!-'Hampshire Daily'!#REF!<0), "0",'Hampshire Daily'!#REF!-'Hampshire Daily'!#REF!) -> #REF! | X25: ='Hampshire Daily'!B28 -> 81 | Y25: ='Hampshire Daily'!C28 -> 100
A26: Hampshire | B26: =B25+1 -> 25 | C26: 9 | D26: 2019 | E26: =IF(('Hampshire Daily'!D29-'Hampshire Daily'!D28<0), "0",('Hampshire Daily'!D29-'Hampshire Daily'!D28)*10) -> 3800 | F26: =IF(('Hampshire Daily'!F29-'Hampshire Daily'!F28<0), "0",('Hampshire Daily'!F29-'Hampshire Daily'!F28)*10) -> 5450 | G26: =IF(('Hampshire Daily'!H29-'Hampshire Daily'!H28<0), "0",'Hampshire Daily'!H29-'Hampshire Daily'!H28) -> 755 | H26: =IF(('Hampshire Daily'!I29-'Hampshire Daily'!I28<0), "0",'Hampshire Daily'!I29-'Hampshire Daily'!I28) -> 0 | I26: =IF(('Hampshire Daily'!J29-'Hampshire Daily'!J28<0), "0",'Hampshire Daily'!J29-'Hampshire Daily'!J28) -> 0 | J26: =IF(('Hampshire Daily'!K29-'Hampshire Daily'!K28<0), "0",'Hampshire Daily'!K29-'Hampshire Daily'!K28) -> 0 | K26: =IF(('Hampshire Daily'!L29-'Hampshire Daily'!L28<0), "0",'Hampshire Daily'!L29-'Hampshire Daily'!L28) -> 1035 | L26: =IF(('Hampshire Daily'!M29-'Hampshire Daily'!M28<0), "0",'Hampshire Daily'!M29-'Hampshire Daily'!M28) -> 788 | M26: =IF(('Hampshire Daily'!N29-'Hampshire Daily'!N28<0), "0",'Hampshire Daily'!N29-'Hampshire Daily'!N28) -> 1049 | N26: =IF(('Hampshire Daily'!O29-'Hampshire Daily'!O28<0), "0",'Hampshire Daily'!O29-'Hampshire Daily'!O28) -> 149 | ... Q26: =IF(('Hampshire Daily'!R29-'Hampshire Daily'!R28<0), "0",'Hampshire Daily'!R29-'Hampshire Daily'!R28) -> 1 | R26: =IF(('Hampshire Daily'!U29-'Hampshire Daily'!U28<0), "0",'Hampshire Daily'!U29-'Hampshire Daily'!U28) -> 7 | S26: =IF(('Hampshire Daily'!V29-'Hampshire Daily'!V28<0), "0",'Hampshire Daily'!V29-'Hampshire Daily'!V28) -> 1 | T26: =IF(('Hampshire Daily'!Y29-'Hampshire Daily'!Y28<0), "0",'Hampshire Daily'!Y29-'Hampshire Daily'!Y28) -> 781040.27 | U26: =IF(('Hampshire Daily'!Z29-'Hampshire Daily'!Z28<0), "0",'Hampshire Daily'!Z29-'Hampshire Daily'!Z28) -> 0.429 | V26: =IF(('Hampshire Daily'!#REF!-'Hampshire Daily'!#REF!<0), "0",'Hampshire Daily'!#REF!-'Hampshire Daily'!#REF!) -> #REF! | W26: =IF(('Hampshire Daily'!#REF!-'Hampshire Daily'!#REF!<0), "0",'Hampshire Daily'!#REF!-'Hampshire Daily'!#REF!) -> #REF! | X26: ='Hampshire Daily'!B29 -> 129 | Y26: ='Hampshire Daily'!C29 -> 146
A27: Hampshire | B27: =B26+1 -> 26 | C27: 9 | D27: 2019 | E27: =IF(('Hampshire Daily'!D30-'Hampshire Daily'!D29<0), "0",('Hampshire Daily'!D30-'Hampshire Daily'!D29)*10) -> 5350 | F27: =IF(('Hampshire Daily'!F30-'Hampshire Daily'!F29<0), "0",('Hampshire Daily'!F30-'Hampshire Daily'!F29)*10) -> 5920 | G27: =IF(('Hampshire Daily'!H30-'Hampshire Daily'!H29<0), "0",'Hampshire Daily'!H30-'Hampshire Daily'!H29) -> 777 | H27: =IF(('Hampshire Daily'!I30-'Hampshire Daily'!I29<0), "0",'Hampshire Daily'!I30-'Hampshire Daily'!I29) -> 0 | I27: =IF(('Hampshire Daily'!J30-'Hampshire Daily'!J29<0), "0",'Hampshire Daily'!J30-'Hampshire Daily'!J29) -> 0 | J27: =IF(('Hampshire Daily'!K30-'Hampshire Daily'!K29<0), "0",'Hampshire Daily'!K30-'Hampshire Daily'!K29) -> 0 | K27: =IF(('Hampshire Daily'!L30-'Hampshire Daily'!L29<0), "0",'Hampshire Daily'!L30-'Hampshire Daily'!L29) -> 1001 | L27: =IF(('Hampshire Daily'!M30-'Hampshire Daily'!M29<0), "0",'Hampshire Daily'!M30-'Hampshire Daily'!M29) -> 789 | M27: =IF(('Hampshire Daily'!N30-'Hampshire Daily'!N29<0), "0",'Hampshire Daily'!N30-'Hampshire Daily'!N29) -> 1214 | N27: =IF(('Hampshire Daily'!O30-'Hampshire Daily'!O29<0), "0",'Hampshire Daily'!O30-'Hampshire Daily'!O29) -> 170 | ... Q27: =IF(('Hampshire Daily'!R30-'Hampshire Daily'!R29<0), "0",'Hampshire Daily'!R30-'Hampshire Daily'!R29) -> 1 | R27: =IF(('Hampshire Daily'!U30-'Hampshire Daily'!U29<0), "0",'Hampshire Daily'!U30-'Hampshire Daily'!U29) -> 7 | S27: =IF(('Hampshire Daily'!V30-'Hampshire Daily'!V29<0), "0",'Hampshire Daily'!V30-'Hampshire Daily'!V29) -> 0 | T27: =IF(('Hampshire Daily'!Y30-'Hampshire Daily'!Y29<0), "0",'Hampshire Daily'!Y30-'Hampshire Daily'!Y29) -> 26 | U27: =IF(('Hampshire Daily'!Z30-'Hampshire Daily'!Z29<0), "0",'Hampshire Daily'!Z30-'Hampshire Daily'!Z29) -> 0 | V27: =IF(('Hampshire Daily'!#REF!-'Hampshire Daily'!#REF!<0), "0",'Hampshire Daily'!#REF!-'Hampshire Daily'!#REF!) -> #REF! | W27: =IF(('Hampshire Daily'!#REF!-'Hampshire Daily'!#REF!<0), "0",'Hampshire Daily'!#REF!-'Hampshire Daily'!#REF!) -> #REF! | X27: ='Hampshire Daily'!B30 -> 59 | Y27: ='Hampshire Daily'!C30 -> 93
A28: Hampshire | B28: =B27+1 -> 27 | C28: 9 | D28: 2019 | E28: =IF(('Hampshire Daily'!D31-'Hampshire Daily'!D30<0), "0",('Hampshire Daily'!D31-'Hampshire Daily'!D30)*10) -> 4710 | F28: =IF(('Hampshire Daily'!F31-'Hampshire Daily'!F30<0), "0",('Hampshire Daily'!F31-'Hampshire Daily'!F30)*10) -> 6570 | G28: =IF(('Hampshire Daily'!H31-'Hampshire Daily'!H30<0), "0",'Hampshire Daily'!H31-'Hampshire Daily'!H30) -> 800 | H28: =IF(('Hampshire Daily'!I31-'Hampshire Daily'!I30<0), "0",'Hampshire Daily'!I31-'Hampshire Daily'!I30) -> 0 | I28: =IF(('Hampshire Daily'!J31-'Hampshire Daily'!J30<0), "0",'Hampshire Daily'!J31-'Hampshire Daily'!J30) -> 0 | J28: =IF(('Hampshire Daily'!K31-'Hampshire Daily'!K30<0), "0",'Hampshire Daily'!K31-'Hampshire Daily'!K30) -> 0 | K28: =IF(('Hampshire Daily'!L31-'Hampshire Daily'!L30<0), "0",'Hampshire Daily'!L31-'Hampshire Daily'!L30) -> 1035 | L28: =IF(('Hampshire Daily'!M31-'Hampshire Daily'!M30<0), "0",'Hampshire Daily'!M31-'Hampshire Daily'!M30) -> 791 | M28: =IF(('Hampshire Daily'!N31-'Hampshire Daily'!N30<0), "0",'Hampshire Daily'!N31-'Hampshire Daily'!N30) -> 1260 | N28: =IF(('Hampshire Daily'!O31-'Hampshire Daily'!O30<0), "0",'Hampshire Daily'!O31-'Hampshire Daily'!O30) -> 176 | ... Q28: =IF(('Hampshire Daily'!R31-'Hampshire Daily'!R30<0), "0",'Hampshire Daily'!R31-'Hampshire Daily'!R30) -> 2 | R28: =IF(('Hampshire Daily'!U31-'Hampshire Daily'!U30<0), "0",'Hampshire Daily'!U31-'Hampshire Daily'!U30) -> 8 | S28: =IF(('Hampshire Daily'!V31-'Hampshire Daily'!V30<0), "0",'Hampshire Daily'!V31-'Hampshire Daily'!V30) -> 1 | T28: =IF(('Hampshire Daily'!Y31-'Hampshire Daily'!Y30<0), "0",'Hampshire Daily'!Y31-'Hampshire Daily'!Y30) -> 0 | U28: =IF(('Hampshire Daily'!Z31-'Hampshire Daily'!Z30<0), "0",'Hampshire Daily'!Z31-'Hampshire Daily'!Z30) -> 0 | V28: =IF(('Hampshire Daily'!#REF!-'Hampshire Daily'!#REF!<0), "0",'Hampshire Daily'!#REF!-'Hampshire Daily'!#REF!) -> #REF! | W28: =IF(('Hampshire Daily'!#REF!-'Hampshire Daily'!#REF!<0), "0",'Hampshire Daily'!#REF!-'Hampshire Daily'!#REF!) -> #REF! | X28: ='Hampshire Daily'!B31 -> 66 | Y28: ='Hampshire Daily'!C31 -> 168
A29: Hampshire | B29: =B28+1 -> 28 | C29: 9 | D29: 2019 | E29: =IF(('Hampshire Daily'!D32-'Hampshire Daily'!D31<0), "0",('Hampshire Daily'!D32-'Hampshire Daily'!D31)*10) -> 4750 | F29: =IF(('Hampshire Daily'!F32-'Hampshire Daily'!F31<0), "0",('Hampshire Daily'!F32-'Hampshire Daily'!F31)*10) -> 6940 | G29: =IF(('Hampshire Daily'!H32-'Hampshire Daily'!H31<0), "0",'Hampshire Daily'!H32-'Hampshire Daily'!H31) -> 788 | H29: =IF(('Hampshire Daily'!I32-'Hampshire Daily'!I31<0), "0",'Hampshire Daily'!I32-'Hampshire Daily'!I31) -> 0 | I29: =IF(('Hampshire Daily'!J32-'Hampshire Daily'!J31<0), "0",'Hampshire Daily'!J32-'Hampshire Daily'!J31) -> 0 | J29: =IF(('Hampshire Daily'!K32-'Hampshire Daily'!K31<0), "0",'Hampshire Daily'!K32-'Hampshire Daily'!K31) -> 0 | K29: =IF(('Hampshire Daily'!L32-'Hampshire Daily'!L31<0), "0",'Hampshire Daily'!L32-'Hampshire Daily'!L31) -> 1035 | L29: =IF(('Hampshire Daily'!M32-'Hampshire Daily'!M31<0), "0",'Hampshire Daily'!M32-'Hampshire Daily'!M31) -> 846 | M29: =IF(('Hampshire Daily'!N32-'Hampshire Daily'!N31<0), "0",'Hampshire Daily'!N32-'Hampshire Daily'!N31) -> 1428 | N29: =IF(('Hampshire Daily'!O32-'Hampshire Daily'!O31<0), "0",'Hampshire Daily'!O32-'Hampshire Daily'!O31) -> 192 | ... Q29: =IF(('Hampshire Daily'!R32-'Hampshire Daily'!R31<0), "0",'Hampshire Daily'!R32-'Hampshire Daily'!R31) -> 2 | R29: =IF(('Hampshire Daily'!U32-'Hampshire Daily'!U31<0), "0",'Hampshire Daily'!U32-'Hampshire Daily'!U31) -> 8 | S29: =IF(('Hampshire Daily'!V32-'Hampshire Daily'!V31<0), "0",'Hampshire Daily'!V32-'Hampshire Daily'!V31) -> 1 | T29: =IF(('Hampshire Daily'!Y32-'Hampshire Daily'!Y31<0), "0",'Hampshire Daily'!Y32-'Hampshire Daily'!Y31) -> 0.036 | U29: =IF(('Hampshire Daily'!Z32-'Hampshire Daily'!Z31<0), "0",'Hampshire Daily'!Z32-'Hampshire Daily'!Z31) -> 0 | V29: =IF(('Hampshire Daily'!#REF!-'Hampshire Daily'!#REF!<0), "0",'Hampshire Daily'!#REF!-'Hampshire Daily'!#REF!) -> #REF! | W29: =IF(('Hampshire Daily'!#REF!-'Hampshire Daily'!#REF!<0), "0",'Hampshire Daily'!#REF!-'Hampshire Daily'!#REF!) -> #REF! | X29: ='Hampshire Daily'!B32 -> 119 | Y29: ='Hampshire Daily'!C32 -> 283
