Workbook

Sheet TOTAL
A1: Site Name | B1: Day | C1: Month | D1: Year | E1: Total Electricity Kwh | F1: Electricity Tariff ($/Kwh) | G1: Water Utility Supply (m3) m3 | H1: Water Utility Supply (m3) $/m3 | I1: Room Nights | J1: Total Guests | K1: Cooling Degree Day
A2: Doha | B2: 1 | C2: 9 | D2: 2019 | E2: =0.75*INDEX('13 - Electrical Readings'!$H$8:$H$988,1+(2*(ROWS(A$1:A1)-1)))+INDEX('13 - Electrical Readings'!$Q$8:$Q$988,1+(2*(ROWS(A$1:A1)-1))) -> 58123.25 | F2: 0.041 | G2: =0.75*INDEX('9 - Water Readings'!$F$8:$F$988,1+(2*(ROWS(A$1:A1)-1)))+INDEX('9 - Water Readings'!$M$8:$M$988,1+(2*(ROWS(A$1:A1)-1))) -> 222.75 | H2: 1.5571913 | I2: ='Submetering '!AA2 -> 0 | J2: ='Submetering '!AB2 -> 0 | K2: ='Submetering '!AC2 -> 17.3
A3: Doha | B3: =B2+1 -> 2 | C3: 9 | D3: 2019 | E3: =0.75*INDEX('13 - Electrical Readings'!$H$8:$H$988,1+(2*(ROWS(A$1:A2)-1)))+INDEX('13 - Electrical Readings'!$Q$8:$Q$988,1+(2*(ROWS(A$1:A2)-1))) -> 64887 | F3: 0.041 | G3: =0.75*INDEX('9 - Water Readings'!$F$8:$F$988,1+(2*(ROWS(A$1:A2)-1)))+INDEX('9 - Water Readings'!$M$8:$M$988,1+(2*(ROWS(A$1:A2)-1))) -> 209 | H3: 1.5571913 | I3: ='Submetering '!AA3 -> 0 | J3: ='Submetering '!AB3 -> 0 | K3: ='Submetering '!AC3 -> 15
A4: Doha | B4: =B3+1 -> 3 | C4: 9 | D4: 2019 | E4: =0.75*INDEX('13 - Electrical Readings'!$H$8:$H$988,1+(2*(ROWS(A$1:A3)-1)))+INDEX('13 - Electrical Readings'!$Q$8:$Q$988,1+(2*(ROWS(A$1:A3)-1))) -> 62838.5 | F4: 0.041 | G4: =0.75*INDEX('9 - Water Readings'!$F$8:$F$988,1+(2*(ROWS(A$1:A3)-1)))+INDEX('9 - Water Readings'!$M$8:$M$988,1+(2*(ROWS(A$1:A3)-1))) -> 200 | H4: 1.5571913 | I4: ='Submetering '!AA4 -> 0 | J4: ='Submetering '!AB4 -> 0 | K4: ='Submetering '!AC4 -> 14
A5: Doha | B5: =B4+1 -> 4 | C5: 9 | D5: 2019 | E5: =0.75*INDEX('13 - Electrical Readings'!$H$8:$H$988,1+(2*(ROWS(A$1:A4)-1)))+INDEX('13 - Electrical Readings'!$Q$8:$Q$988,1+(2*(ROWS(A$1:A4)-1))) -> 62533.75 | F5: 0.041 | G5: =0.75*INDEX('9 - Water Readings'!$F$8:$F$988,1+(2*(ROWS(A$1:A4)-1)))+INDEX('9 - Water Readings'!$M$8:$M$988,1+(2*(ROWS(A$1:A4)-1))) -> 222.25 | H5: 1.5571913 | I5: ='Submetering '!AA5 -> 0 | J5: ='Submetering '!AB5 -> 0 | K5: ='Submetering '!AC5 -> 16.6
A6: Doha | B6: =B5+1 -> 5 | C6: 9 | D6: 2019 | E6: =0.75*INDEX('13 - Electrical Readings'!$H$8:$H$988,1+(2*(ROWS(A$1:A5)-1)))+INDEX('13 - Electrical Readings'!$Q$8:$Q$988,1+(2*(ROWS(A$1:A5)-1))) -> 62443.75 | F6: 0.041 | G6: =0.75*INDEX('9 - Water Readings'!$F$8:$F$988,1+(2*(ROWS(A$1:A5)-1)))+INDEX('9 - Water Readings'!$M$8:$M$988,1+(2*(ROWS(A$1:A5)-1))) -> 207.25 | H6: 1.5571913 | I6: ='Submetering '!AA6 -> 0 | J6: ='Submetering '!AB6 -> 0 | K6: ='Submetering '!AC6 -> 15.5
A7: Doha | B7: =B6+1 -> 6 | C7: 9 | D7: 2019 | E7: =0.75*INDEX('13 - Electrical Readings'!$H$8:$H$988,1+(2*(ROWS(A$1:A6)-1)))+INDEX('13 - Electrical Readings'!$Q$8:$Q$988,1+(2*(ROWS(A$1:A6)-1))) -> 64085.25 | F7: 0.041 | G7: =0.75*INDEX('9 - Water Readings'!$F$8:$F$988,1+(2*(ROWS(A$1:A6)-1)))+INDEX('9 - Water Readings'!$M$8:$M$988,1+(2*(ROWS(A$1:A6)-1))) -> 225.5 | H7: 1.5571913 | I7: ='Submetering '!AA7 -> 0 | J7: ='Submetering '!AB7 -> 0 | K7: ='Submetering '!AC7 -> 14.4
A8: Doha | B8: =B7+1 -> 7 | C8: 9 | D8: 2019 | E8: =0.75*INDEX('13 - Electrical Readings'!$H$8:$H$988,1+(2*(ROWS(A$1:A7)-1)))+INDEX('13 - Electrical Readings'!$Q$8:$Q$988,1+(2*(ROWS(A$1:A7)-1))) -> 59646.25 | F8: 0.041 | G8: =0.75*INDEX('9 - Water Readings'!$F$8:$F$988,1+(2*(ROWS(A$1:A7)-1)))+INDEX('9 - Water Readings'!$M$8:$M$988,1+(2*(ROWS(A$1:A7)-1))) -> 203.75 | H8: 1.5571913 | I8: ='Submetering '!AA8 -> 0 | J8: ='Submetering '!AB8 -> 0 | K8: ='Submetering '!AC8 -> 17.8
A9: Doha | B9: =B8+1 -> 8 | C9: 9 | D9: 2019 | E9: =0.75*INDEX('13 - Electrical Readings'!$H$8:$H$988,1+(2*(ROWS(A$1:A8)-1)))+INDEX('13 - Electrical Readings'!$Q$8:$Q$988,1+(2*(ROWS(A$1:A8)-1))) -> 55413 | F9: 0.041 | G9: =0.75*INDEX('9 - Water Readings'!$F$8:$F$988,1+(2*(ROWS(A$1:A8)-1)))+INDEX('9 - Water Readings'!$M$8:$M$988,1+(2*(ROWS(A$1:A8)-1))) -> 194.25 | H9: 1.5571913 | I9: ='Submetering '!AA9 -> 0 | J9: ='Submetering '!AB9 -> 0 | K9: ='Submetering '!AC9 -> 17
A10: Doha | B10: =B9+1 -> 9 | C10: 9 | D10: 2019 | E10: =0.75*INDEX('13 - Electrical Readings'!$H$8:$H$988,1+(2*(ROWS(A$1:A9)-1)))+INDEX('13 - Electrical Readings'!$Q$8:$Q$988,1+(2*(ROWS(A$1:A9)-1))) -> 51165.5 | F10: 0.041 | G10: =0.75*INDEX('9 - Water Readings'!$F$8:$F$988,1+(2*(ROWS(A$1:A9)-1)))+INDEX('9 - Water Readings'!$M$8:$M$988,1+(2*(ROWS(A$1:A9)-1))) -> 116 | H10: 1.5571913 | I10: ='Submetering '!AA10 -> 0 | J10: ='Submetering '!AB10 -> 0 | K10: ='Submetering '!AC10 -> 15.9
A11: Doha | B11: =B10+1 -> 10 | C11: 9 | D11: 2019 | E11: =0.75*INDEX('13 - Electrical Readings'!$H$8:$H$988,1+(2*(ROWS(A$1:A10)-1)))+INDEX('13 - Electrical Readings'!$Q$8:$Q$988,1+(2*(ROWS(A$1:A10)-1))) -> 53007.75 | F11: 0.041 | G11: =0.75*INDEX('9 - Water Readings'!$F$8:$F$988,1+(2*(ROWS(A$1:A10)-1)))+INDEX('9 - Water Readings'!$M$8:$M$988,1+(2*(ROWS(A$1:A10)-1))) -> 132.25 | H11: 1.5571913 | I11: ='Submetering '!AA11 -> 0 | J11: ='Submetering '!AB11 -> 0 | K11: ='Submetering '!AC11 -> 14.2
A12: Doha | B12: =B11+1 -> 11 | C12: 9 | D12: 2019 | E12: =0.75*INDEX('13 - Electrical Readings'!$H$8:$H$988,1+(2*(ROWS(A$1:A11)-1)))+INDEX('13 - Electrical Readings'!$Q$8:$Q$988,1+(2*(ROWS(A$1:A11)-1))) -> 57097.25 | F12: 0.041 | G12: =0.75*INDEX('9 - Water Readings'!$F$8:$F$988,1+(2*(ROWS(A$1:A11)-1)))+INDEX('9 - Water Readings'!$M$8:$M$988,1+(2*(ROWS(A$1:A11)-1))) -> 107 | H12: 1.5571913 | I12: ='Submetering '!AA12 -> 0 | J12: ='Submetering '!AB12 -> 0 | K12: ='Submetering '!AC12 -> 14.4
A13: Doha | B13: =B12+1 -> 12 | C13: 9 | D13: 2019 | E13: =0.75*INDEX('13 - Electrical Readings'!$H$8:$H$988,1+(2*(ROWS(A$1:A12)-1)))+INDEX('13 - Electrical Readings'!$Q$8:$Q$988,1+(2*(ROWS(A$1:A12)-1))) -> 59779.5 | F13: 0.041 | G13: =0.75*INDEX('9 - Water Readings'!$F$8:$F$988,1+(2*(ROWS(A$1:A12)-1)))+INDEX('9 - Water Readings'!$M$8:$M$988,1+(2*(ROWS(A$1:A12)-1))) -> 99.25 | H13: 1.5571913 | I13: ='Submetering '!AA13 -> 0 | J13: ='Submetering '!AB13 -> 0 | K13: ='Submetering '!AC13 -> 14.4
A14: Doha | B14: =B13+1 -> 13 | C14: 9 | D14: 2019 | E14: =0.75*INDEX('13 - Electrical Readings'!$H$8:$H$988,1+(2*(ROWS(A$1:A13)-1)))+INDEX('13 - Electrical Readings'!$Q$8:$Q$988,1+(2*(ROWS(A$1:A13)-1))) -> 62459 | F14: 0.041 | G14: =0.75*INDEX('9 - Water Readings'!$F$8:$F$988,1+(2*(ROWS(A$1:A13)-1)))+INDEX('9 - Water Readings'!$M$8:$M$988,1+(2*(ROWS(A$1:A13)-1))) -> 132 | H14: 1.5571913 | I14: ='Submetering '!AA14 -> 0 | J14: ='Submetering '!AB14 -> 0 | K14: ='Submetering '!AC14 -> 14
... A31: Doha | B31: =B30+1 -> 30 | C31: 9 | D31: 2019 | E31: =0.75*INDEX('13 - Electrical Readings'!$H$8:$H$988,1+(2*(ROWS(A$1:A30)-1)))+INDEX('13 - Electrical Readings'!$Q$8:$Q$988,1+(2*(ROWS(A$1:A30)-1))) -> 52600 | F31: 0.041 | G31: =0.75*INDEX('9 - Water Readings'!$F$8:$F$988,1+(2*(ROWS(A$1:A30)-1)))+INDEX('9 - Water Readings'!$M$8:$M$988,1+(2*(ROWS(A$1:A30)-1))) -> 170 | H31: 1.5571913 | I31: ='Submetering '!AA31 -> 0 | J31: ='Submetering '!AB31 -> 0 | K31: ='Submetering '!AC31 -> 14

Sheet Submetering 
A1: Site Name | B1: Day | C1: Month | D1: Year | E1: CP Chillers 157691 (KWh) | F1: CP Chillers 157692 (KWh) | G1: CP Chillers 157693 (KWh) | H1: CP Chillers 157694 (KWh) | I1: CP Chillers 167609 (KWh) | J1: Town House 166443 (KWh) | K1: Hotel 157687 (KWh) | L1: Hotel 157688 (KWh) | M1: Hotel 157689 (KWh) | N1: Hotel 157690 (KWh) | O1: SPA (KWh) | P1: Marina (KWh) | Q1: Nobu (KWh) | R1: CP F/F (m3) | S1: CP Chillers (m3) | T1: CP Parking (m3) | U1: Town House (m3) | V1: Spa B (m3) | W1: Spa A (m3) | X1: CW Hotel A (m3) | Y1: CCW Hotel B (m3) | Z1: Marina (m3) | AA1: Room Nights | AB1: Total Guests | AC1: Cooling Degree Day
A2: Doha | B2: 1 | C2: 9 | D2: 2019 | E2: =INDEX('13 - Electrical Readings'!$C$8:$C$988,1+(2*(ROWS(A$1:A1)-1))) -> 9121 | F2: =INDEX('13 - Electrical Readings'!$D$6:$D$988,1+(2*(ROWS(A$1:A2)-1))) -> 11322 | G2: =INDEX('13 - Electrical Readings'!$E$6:$E$988,1+(2*(ROWS(A$1:A2)-1))) -> 9316 | H2: =INDEX('13 - Electrical Readings'!$F$6:$F$988,1+(2*(ROWS(A$1:A2)-1))) -> 5296 | I2: =INDEX('13 - Electrical Readings'!$G$6:$G$988,1+(2*(ROWS(A$1:A2)-1))) -> 12 | J2: =INDEX('13 - Electrical Readings'!$I$6:$I$988,1+(2*(ROWS(A$1:A2)-1))) -> 1999 | K2: =INDEX('13 - Electrical Readings'!$J$6:$J$988,1+(2*(ROWS(B$1:B2)-1))) -> 5166 | L2: =INDEX('13 - Electrical Readings'!$K$6:$K$988,1+(2*(ROWS(C$1:C2)-1))) -> 1966 | M2: =INDEX('13 - Electrical Readings'!$L$6:$L$988,1+(2*(ROWS(D$1:D2)-1))) -> 2570 | N2: =INDEX('13 - Electrical Readings'!$M$6:$M$988,1+(2*(ROWS(E$1:E2)-1))) -> 6019 | O2: =INDEX('13 - Electrical Readings'!$N$6:$N$988,1+(2*(ROWS(E$1:E2)-1))) -> 8719 | P2: =INDEX('13 - Electrical Readings'!$O$6:$O$988,1+(2*(ROWS(E$1:E2)-1))) -> 3454 | Q2: =INDEX('13 - Electrical Readings'!$P$6:$P$988,1+(2*(ROWS(F$1:F2)-1))) -> 1930 | R2: =INDEX('9 - Water Readings'!$C$8:$C$988,1+(2*(ROWS(A$1:A1)-1))) -> 0 | S2: =INDEX('9 - Water Readings'!$D$8:$D$987,1+(2*(ROWS(A$1:A1)-1))) -> 0 | T2: =INDEX('9 - Water Readings'!$E$8:$E$988,1+(2*(ROWS(A$1:A1)-1))) -> 5 | U2: =INDEX('9 - Water Readings'!$G$8:$G$987,1+(2*(ROWS(A$1:A1)-1))) -> 0 | V2: =INDEX('9 - Water Readings'!$H$8:$H$988,1+(2*(ROWS(A$1:A1)-1))) -> 0 | W2: =INDEX('9 - Water Readings'!$I$8:$I$988,1+(2*(ROWS(A$1:A1)-1))) -> 58 | X2: =INDEX('9 - Water Readings'!$J$8:$J$988,1+(2*(ROWS(A$1:A1)-1))) -> 127 | Y2: =INDEX('9 - Water Readings'!$K$8:$K$988,1+(2*(ROWS(A$1:A1)-1))) -> 0 | Z2: =INDEX('9 - Water Readings'!$L$8:$L$988,1+(2*(ROWS(A$1:A1)-1))) -> 34 | AA2: ='9 - Water Readings'!Q7 -> 0 | AB2: ='9 - Water Readings'!R7 -> 0 | AC2: ='9 - Water Readings'!S7 -> 17.3
A3: Doha | B3: =B2+1 -> 2 | C3: 9 | D3: 2019 | E3: =INDEX('13 - Electrical Readings'!$C$8:$C$988,1+(2*(ROWS(A$1:A2)-1))) -> 19878 | F3: =INDEX('13 - Electrical Readings'!$D$6:$D$988,1+(2*(ROWS(A$1:A3)-1))) -> 13404 | G3: =INDEX('13 - Electrical Readings'!$E$6:$E$988,1+(2*(ROWS(A$1:A3)-1))) -> 4691 | H3: =INDEX('13 - Electrical Readings'!$F$6:$F$988,1+(2*(ROWS(A$1:A3)-1))) -> 5356 | I3: =INDEX('13 - Electrical Readings'!$G$6:$G$988,1+(2*(ROWS(A$1:A3)-1))) -> 15 | J3: =INDEX('13 - Electrical Readings'!$I$6:$I$988,1+(2*(ROWS(A$1:A3)-1))) -> 2023 | K3: =INDEX('13 - Electrical Readings'!$J$6:$J$988,1+(2*(ROWS(B$1:B3)-1))) -> 5238 | L3: =INDEX('13 - Electrical Readings'!$K$6:$K$988,1+(2*(ROWS(C$1:C3)-1))) -> 1855 | M3: =INDEX('13 - Electrical Readings'!$L$6:$L$988,1+(2*(ROWS(D$1:D3)-1))) -> 2530 | N3: =INDEX('13 - Electrical Readings'!$M$6:$M$988,1+(2*(ROWS(E$1:E3)-1))) -> 5966 | O3: =INDEX('13 - Electrical Readings'!$N$6:$N$988,1+(2*(ROWS(E$1:E3)-1))) -> 8779 | P3: =INDEX('13 - Electrical Readings'!$O$6:$O$988,1+(2*(ROWS(E$1:E3)-1))) -> 3448 | Q3: =INDEX('13 - Electrical Readings'!$P$6:$P$988,1+(2*(ROWS(F$1:F3)-1))) -> 2540 | R3: =INDEX('9 - Water Readings'!$C$8:$C$988,1+(2*(ROWS(A$1:A2)-1))) -> 0 | S3: =INDEX('9 - Water Readings'!$D$8:$D$987,1+(2*(ROWS(A$1:A2)-1))) -> 0 | T3: =INDEX('9 - Water Readings'!$E$8:$E$988,1+(2*(ROWS(A$1:A2)-1))) -> 8 | U3: =INDEX('9 - Water Readings'!$G$8:$G$987,1+(2*(ROWS(A$1:A2)-1))) -> 0 | V3: =INDEX('9 - Water Readings'!$H$8:$H$988,1+(2*(ROWS(A$1:A2)-1))) -> 0 | W3: =INDEX('9 - Water Readings'!$I$8:$I$988,1+(2*(ROWS(A$1:A2)-1))) -> 53 | X3: =INDEX('9 - Water Readings'!$J$8:$J$988,1+(2*(ROWS(A$1:A2)-1))) -> 104 | Y3: =INDEX('9 - Water Readings'!$K$8:$K$988,1+(2*(ROWS(A$1:A2)-1))) -> 0 | Z3: =INDEX('9 - Water Readings'!$L$8:$L$988,1+(2*(ROWS(A$1:A2)-1))) -> 46 | AA3: ='9 - Water Readings'!Q8 -> 0 | AB3: ='9 - Water Readings'!R8 -> 0 | AC3: ='9 - Water Readings'!S8 -> 15
A4: Doha | B4: =B3+1 -> 3 | C4: 9 | D4: 2019 | E4: =INDEX('13 - Electrical Readings'!$C$8:$C$988,1+(2*(ROWS(A$1:A3)-1))) -> 18933 | F4: =INDEX('13 - Electrical Readings'!$D$6:$D$988,1+(2*(ROWS(A$1:A4)-1))) -> 12726 | G4: =INDEX('13 - Electrical Readings'!$E$6:$E$988,1+(2*(ROWS(A$1:A4)-1))) -> 4511 | H4: =INDEX('13 - Electrical Readings'!$F$6:$F$988,1+(2*(ROWS(A$1:A4)-1))) -> 5282 | I4: =INDEX('13 - Electrical Readings'!$G$6:$G$988,1+(2*(ROWS(A$1:A4)-1))) -> 14 | J4: =INDEX('13 - Electrical Readings'!$I$6:$I$988,1+(2*(ROWS(A$1:A4)-1))) -> 1981 | K4: =INDEX('13 - Electrical Readings'!$J$6:$J$988,1+(2*(ROWS(B$1:B4)-1))) -> 5187 | L4: =INDEX('13 - Electrical Readings'!$K$6:$K$988,1+(2*(ROWS(C$1:C4)-1))) -> 1824 | M4: =INDEX('13 - Electrical Readings'!$L$6:$L$988,1+(2*(ROWS(D$1:D4)-1))) -> 2317 | N4: =INDEX('13 - Electrical Readings'!$M$6:$M$988,1+(2*(ROWS(E$1:E4)-1))) -> 5847 | O4: =INDEX('13 - Electrical Readings'!$N$6:$N$988,1+(2*(ROWS(E$1:E4)-1))) -> 8161 | P4: =INDEX('13 - Electrical Readings'!$O$6:$O$988,1+(2*(ROWS(E$1:E4)-1))) -> 3932 | Q4: =INDEX('13 - Electrical Readings'!$P$6:$P$988,1+(2*(ROWS(F$1:F4)-1))) -> 2490 | R4: =INDEX('9 - Water Readings'!$C$8:$C$988,1+(2*(ROWS(A$1:A3)-1))) -> 0 | S4: =INDEX('9 - Water Readings'!$D$8:$D$987,1+(2*(ROWS(A$1:A3)-1))) -> 0 | T4: =INDEX('9 - Water Readings'!$E$8:$E$988,1+(2*(ROWS(A$1:A3)-1))) -> 4 | U4: =INDEX('9 - Water Readings'!$G$8:$G$987,1+(2*(ROWS(A$1:A3)-1))) -> 0 | V4: =INDEX('9 - Water Readings'!$H$8:$H$988,1+(2*(ROWS(A$1:A3)-1))) -> 0 | W4: =INDEX('9 - Water Readings'!$I$8:$I$988,1+(2*(ROWS(A$1:A3)-1))) -> 49 | X4: =INDEX('9 - Water Readings'!$J$8:$J$988,1+(2*(ROWS(A$1:A3)-1))) -> 110 | Y4: =INDEX('9 - Water Readings'!$K$8:$K$988,1+(2*(ROWS(A$1:A3)-1))) -> 0 | Z4: =INDEX('9 - Water Readings'!$L$8:$L$988,1+(2*(ROWS(A$1:A3)-1))) -> 38 | AA4: ='9 - Water Readings'!Q9 -> 0 | AB4: ='9 - Water Readings'!R9 -> 0 | AC4: ='9 - Water Readings'!S9 -> 14
A5: Doha | B5: =B4+1 -> 4 | C5: 9 | D5: 2019 | E5: =INDEX('13 - Electrical Readings'!$C$8:$C$988,1+(2*(ROWS(A$1:A4)-1))) -> 17434 | F5: =INDEX('13 - Electrical Readings'!$D$6:$D$988,1+(2*(ROWS(A$1:A5)-1))) -> 11736 | G5: =INDEX('13 - Electrical Readings'!$E$6:$E$988,1+(2*(ROWS(A$1:A5)-1))) -> 4650 | H5: =INDEX('13 - Electrical Readings'!$F$6:$F$988,1+(2*(ROWS(A$1:A5)-1))) -> 5416 | I5: =INDEX('13 - Electrical Readings'!$G$6:$G$988,1+(2*(ROWS(A$1:A5)-1))) -> 13 | J5: =INDEX('13 - Electrical Readings'!$I$6:$I$988,1+(2*(ROWS(A$1:A5)-1))) -> 2104 | K5: =INDEX('13 - Electrical Readings'!$J$6:$J$988,1+(2*(ROWS(B$1:B5)-1))) -> 5349 | L5: =INDEX('13 - Electrical Readings'!$K$6:$K$988,1+(2*(ROWS(C$1:C5)-1))) -> 1824 | M5: =INDEX('13 - Electrical Readings'!$L$6:$L$988,1+(2*(ROWS(D$1:D5)-1))) -> 2411 | N5: =INDEX('13 - Electrical Readings'!$M$6:$M$988,1+(2*(ROWS(E$1:E5)-1))) -> 6047 | O5: =INDEX('13 - Electrical Readings'!$N$6:$N$988,1+(2*(ROWS(E$1:E5)-1))) -> 8736 | P5: =INDEX('13 - Electrical Readings'!$O$6:$O$988,1+(2*(ROWS(E$1:E5)-1))) -> 4066 | Q5: =INDEX('13 - Electrical Readings'!$P$6:$P$988,1+(2*(ROWS(F$1:F5)-1))) -> 2560 | R5: =INDEX('9 - Water Readings'!$C$8:$C$988,1+(2*(ROWS(A$1:A4)-1))) -> 0 | S5: =INDEX('9 - Water Readings'!$D$8:$D$987,1+(2*(ROWS(A$1:A4)-1))) -> 0 | T5: =INDEX('9 - Water Readings'!$E$8:$E$988,1+(2*(ROWS(A$1:A4)-1))) -> 3 | U5: =INDEX('9 - Water Readings'!$G$8:$G$987,1+(2*(ROWS(A$1:A4)-1))) -> 0 | V5: =INDEX('9 - Water Readings'!$H$8:$H$988,1+(2*(ROWS(A$1:A4)-1))) -> 0 | W5: =INDEX('9 - Water Readings'!$I$8:$I$988,1+(2*(ROWS(A$1:A4)-1))) -> 59 | X5: =INDEX('9 - Water Readings'!$J$8:$J$988,1+(2*(ROWS(A$1:A4)-1))) -> 119 | Y5: =INDEX('9 - Water Readings'!$K$8:$K$988,1+(2*(ROWS(A$1:A4)-1))) -> 0 | Z5: =INDEX('9 - Water Readings'!$L$8:$L$988,1+(2*(ROWS(A$1:A4)-1))) -> 42 | AA5: ='9 - Water Readings'!Q10 -> 0 | AB5: ='9 - Water Readings'!R10 -> 0 | AC5: ='9 - Water Readings'!S10 -> 16.6
A6: Doha | B6: =B5+1 -> 5 | C6: 9 | D6: 2019 | E6: =INDEX('13 - Electrical Readings'!$C$8:$C$988,1+(2*(ROWS(A$1:A5)-1))) -> 18010 | F6: =INDEX('13 - Electrical Readings'!$D$6:$D$988,1+(2*(ROWS(A$1:A6)-1))) -> 6534 | G6: =INDEX('13 - Electrical Readings'!$E$6:$E$988,1+(2*(ROWS(A$1:A6)-1))) -> 4516 | H6: =INDEX('13 - Electrical Readings'!$F$6:$F$988,1+(2*(ROWS(A$1:A6)-1))) -> 10733 | I6: =INDEX('13 - Electrical Readings'!$G$6:$G$988,1+(2*(ROWS(A$1:A6)-1))) -> 12 | J6: =INDEX('13 - Electrical Readings'!$I$6:$I$988,1+(2*(ROWS(A$1:A6)-1))) -> 1966 | K6: =INDEX('13 - Electrical Readings'!$J$6:$J$988,1+(2*(ROWS(B$1:B6)-1))) -> 5210 | L6: =INDEX('13 - Electrical Readings'!$K$6:$K$988,1+(2*(ROWS(C$1:C6)-1))) -> 1790 | M6: =INDEX('13 - Electrical Readings'!$L$6:$L$988,1+(2*(ROWS(D$1:D6)-1))) -> 2320 | N6: =INDEX('13 - Electrical Readings'!$M$6:$M$988,1+(2*(ROWS(E$1:E6)-1))) -> 5893 | O6: =INDEX('13 - Electrical Readings'!$N$6:$N$988,1+(2*(ROWS(E$1:E6)-1))) -> 8761 | P6: =INDEX('13 - Electrical Readings'!$O$6:$O$988,1+(2*(ROWS(E$1:E6)-1))) -> 3770 | Q6: =INDEX('13 - Electrical Readings'!$P$6:$P$988,1+(2*(ROWS(F$1:F6)-1))) -> 2880 | R6: =INDEX('9 - Water Readings'!$C$8:$C$988,1+(2*(ROWS(A$1:A5)-1))) -> 0 | S6: =INDEX('9 - Water Readings'!$D$8:$D$987,1+(2*(ROWS(A$1:A5)-1))) -> 4 | T6: =INDEX('9 - Water Readings'!$E$8:$E$988,1+(2*(ROWS(A$1:A5)-1))) -> 3 | U6: =INDEX('9 - Water Readings'!$G$8:$G$987,1+(2*(ROWS(A$1:A5)-1))) -> 0 | V6: =INDEX('9 - Water Readings'!$H$8:$H$988,1+(2*(ROWS(A$1:A5)-1))) -> 0 | W6: =INDEX('9 - Water Readings'!$I$8:$I$988,1+(2*(ROWS(A$1:A5)-1))) -> 57 | X6: =INDEX('9 - Water Readings'!$J$8:$J$988,1+(2*(ROWS(A$1:A5)-1))) -> 105 | Y6: =INDEX('9 - Water Readings'!$K$8:$K$988,1+(2*(ROWS(A$1:A5)-1))) -> 0 | Z6: =INDEX('9 - Water Readings'!$L$8:$L$988,1+(2*(ROWS(A$1:A5)-1))) -> 40 | AA6: ='9 - Water Readings'!Q11 -> 0 | AB6: ='9 - Water Readings'!R11 -> 0 | AC6: ='9 - Water Readings'!S11 -> 15.5
A7: Doha | B7: =B6+1 -> 6 | C7: 9 | D7: 2019 | E7: =INDEX('13 - Electrical Readings'!$C$8:$C$988,1+(2*(ROWS(A$1:A6)-1))) -> 18982 | F7: =INDEX('13 - Electrical Readings'!$D$6:$D$988,1+(2*(ROWS(A$1:A7)-1))) -> 587 | G7: =INDEX('13 - Electrical Readings'!$E$6:$E$988,1+(2*(ROWS(A$1:A7)-1))) -> 4547 | H7: =INDEX('13 - Electrical Readings'!$F$6:$F$988,1+(2*(ROWS(A$1:A7)-1))) -> 17159 | I7: =INDEX('13 - Electrical Readings'!$G$6:$G$988,1+(2*(ROWS(A$1:A7)-1))) -> 12 | J7: =INDEX('13 - Electrical Readings'!$I$6:$I$988,1+(2*(ROWS(A$1:A7)-1))) -> 2058 | K7: =INDEX('13 - Electrical Readings'!$J$6:$J$988,1+(2*(ROWS(B$1:B7)-1))) -> 5426 | L7: =INDEX('13 - Electrical Readings'!$K$6:$K$988,1+(2*(ROWS(C$1:C7)-1))) -> 1862 | M7: =INDEX('13 - Electrical Readings'!$L$6:$L$988,1+(2*(ROWS(D$1:D7)-1))) -> 2456 | N7: =INDEX('13 - Electrical Readings'!$M$6:$M$988,1+(2*(ROWS(E$1:E7)-1))) -> 5401 | O7: =INDEX('13 - Electrical Readings'!$N$6:$N$988,1+(2*(ROWS(E$1:E7)-1))) -> 9247 | P7: =INDEX('13 - Electrical Readings'!$O$6:$O$988,1+(2*(ROWS(E$1:E7)-1))) -> 3660 | Q7: =INDEX('13 - Electrical Readings'!$P$6:$P$988,1+(2*(ROWS(F$1:F7)-1))) -> 3010 | R7: =INDEX('9 - Water Readings'!$C$8:$C$988,1+(2*(ROWS(A$1:A6)-1))) -> 0 | S7: =INDEX('9 - Water Readings'!$D$8:$D$987,1+(2*(ROWS(A$1:A6)-1))) -> 0 | T7: =INDEX('9 - Water Readings'!$E$8:$E$988,1+(2*(ROWS(A$1:A6)-1))) -> 6 | U7: =INDEX('9 - Water Readings'!$G$8:$G$987,1+(2*(ROWS(A$1:A6)-1))) -> 0 | V7: =INDEX('9 - Water Readings'!$H$8:$H$988,1+(2*(ROWS(A$1:A6)-1))) -> 0 | W7: =INDEX('9 - Water Readings'!$I$8:$I$988,1+(2*(ROWS(A$1:A6)-1))) -> 75 | X7: =INDEX('9 - Water Readings'!$J$8:$J$988,1+(2*(ROWS(A$1:A6)-1))) -> 97 | Y7: =INDEX('9 - Water Readings'!$K$8:$K$988,1+(2*(ROWS(A$1:A6)-1))) -> 0 | Z7: =INDEX('9 - Water Readings'!$L$8:$L$988,1+(2*(ROWS(A$1:A6)-1))) -> 49 | AA7: ='9 - Water Readings'!Q12 -> 0 | AB7: ='9 - Water Readings'!R12 -> 0 | AC7: ='9 - Water Readings'!S12 -> 14.4
A8: Doha | B8: =B7+1 -> 7 | C8: 9 | D8: 2019 | E8: =INDEX('13 - Electrical Readings'!$C$8:$C$988,1+(2*(ROWS(A$1:A7)-1))) -> 16562 | F8: =INDEX('13 - Electrical Readings'!$D$6:$D$988,1+(2*(ROWS(A$1:A8)-1))) -> 621 | G8: =INDEX('13 - Electrical Readings'!$E$6:$E$988,1+(2*(ROWS(A$1:A8)-1))) -> 4491 | H8: =INDEX('13 - Electrical Readings'!$F$6:$F$988,1+(2*(ROWS(A$1:A8)-1))) -> 16063 | I8: =INDEX('13 - Electrical Readings'!$G$6:$G$988,1+(2*(ROWS(A$1:A8)-1))) -> 18 | J8: =INDEX('13 - Electrical Readings'!$I$6:$I$988,1+(2*(ROWS(A$1:A8)-1))) -> 1976 | K8: =INDEX('13 - Electrical Readings'!$J$6:$J$988,1+(2*(ROWS(B$1:B8)-1))) -> 4887 | L8: =INDEX('13 - Electrical Readings'!$K$6:$K$988,1+(2*(ROWS(C$1:C8)-1))) -> 1747 | M8: =INDEX('13 - Electrical Readings'!$L$6:$L$988,1+(2*(ROWS(D$1:D8)-1))) -> 2312 | N8: =INDEX('13 - Electrical Readings'!$M$6:$M$988,1+(2*(ROWS(E$1:E8)-1))) -> 5461 | O8: =INDEX('13 - Electrical Readings'!$N$6:$N$988,1+(2*(ROWS(E$1:E8)-1))) -> 8292 | P8: =INDEX('13 - Electrical Readings'!$O$6:$O$988,1+(2*(ROWS(E$1:E8)-1))) -> 3915 | Q8: =INDEX('13 - Electrical Readings'!$P$6:$P$988,1+(2*(ROWS(F$1:F8)-1))) -> 2740 | R8: =INDEX('9 - Water Readings'!$C$8:$C$988,1+(2*(ROWS(A$1:A7)-1))) -> 1 | S8: =INDEX('9 - Water Readings'!$D$8:$D$987,1+(2*(ROWS(A$1:A7)-1))) -> 0 | T8: =INDEX('9 - Water Readings'!$E$8:$E$988,1+(2*(ROWS(A$1:A7)-1))) -> 4 | U8: =INDEX('9 - Water Readings'!$G$8:$G$987,1+(2*(ROWS(A$1:A7)-1))) -> 0 | V8: =INDEX('9 - Water Readings'!$H$8:$H$988,1+(2*(ROWS(A$1:A7)-1))) -> 0 | W8: =INDEX('9 - Water Readings'!$I$8:$I$988,1+(2*(ROWS(A$1:A7)-1))) -> 39 | X8: =INDEX('9 - Water Readings'!$J$8:$J$988,1+(2*(ROWS(A$1:A7)-1))) -> 113 | Y8: =INDEX('9 - Water Readings'!$K$8:$K$988,1+(2*(ROWS(A$1:A7)-1))) -> 0 | Z8: =INDEX('9 - Water Readings'!$L$8:$L$988,1+(2*(ROWS(A$1:A7)-1))) -> 48 | AA8: ='9 - Water Readings'!Q13 -> 0 | AB8: ='9 - Water Readings'!R13 -> 0 | AC8: ='9 - Water Readings'!S13 -> 17.8
A9: Doha | B9: =B8+1 -> 8 | C9: 9 | D9: 2019 | E9: =INDEX('13 - Electrical Readings'!$C$8:$C$988,1+(2*(ROWS(A$1:A8)-1))) -> 11029 | F9: =INDEX('13 - Electrical Readings'!$D$6:$D$988,1+(2*(ROWS(A$1:A9)-1))) -> 594 | G9: =INDEX('13 - Electrical Readings'!$E$6:$E$988,1+(2*(ROWS(A$1:A9)-1))) -> 3879 | H9: =INDEX('13 - Electrical Readings'!$F$6:$F$988,1+(2*(ROWS(A$1:A9)-1))) -> 16741 | I9: =INDEX('13 - Electrical Readings'!$G$6:$G$988,1+(2*(ROWS(A$1:A9)-1))) -> 17 | J9: =INDEX('13 - Electrical Readings'!$I$6:$I$988,1+(2*(ROWS(A$1:A9)-1))) -> 2027 | K9: =INDEX('13 - Electrical Readings'!$J$6:$J$988,1+(2*(ROWS(B$1:B9)-1))) -> 4919 | L9: =INDEX('13 - Electrical Readings'!$K$6:$K$988,1+(2*(ROWS(C$1:C9)-1))) -> 1820 | M9: =INDEX('13 - Electrical Readings'!$L$6:$L$988,1+(2*(ROWS(D$1:D9)-1))) -> 2416 | N9: =INDEX('13 - Electrical Readings'!$M$6:$M$988,1+(2*(ROWS(E$1:E9)-1))) -> 5791 | O9: =INDEX('13 - Electrical Readings'!$N$6:$N$988,1+(2*(ROWS(E$1:E9)-1))) -> 7737 | P9: =INDEX('13 - Electrical Readings'!$O$6:$O$988,1+(2*(ROWS(E$1:E9)-1))) -> 3888 | Q9: =INDEX('13 - Electrical Readings'!$P$6:$P$988,1+(2*(ROWS(F$1:F9)-1))) -> 2620 | R9: =INDEX('9 - Water Readings'!$C$8:$C$988,1+(2*(ROWS(A$1:A8)-1))) -> 0 | S9: =INDEX('9 - Water Readings'!$D$8:$D$987,1+(2*(ROWS(A$1:A8)-1))) -> 0 | T9: =INDEX('9 - Water Readings'!$E$8:$E$988,1+(2*(ROWS(A$1:A8)-1))) -> 7 | U9: =INDEX('9 - Water Readings'!$G$8:$G$987,1+(2*(ROWS(A$1:A8)-1))) -> 0 | V9: =INDEX('9 - Water Readings'!$H$8:$H$988,1+(2*(ROWS(A$1:A8)-1))) -> 0 | W9: =INDEX('9 - Water Readings'!$I$8:$I$988,1+(2*(ROWS(A$1:A8)-1))) -> 7 | X9: =INDEX('9 - Water Readings'!$J$8:$J$988,1+(2*(ROWS(A$1:A8)-1))) -> 117 | Y9: =INDEX('9 - Water Readings'!$K$8:$K$988,1+(2*(ROWS(A$1:A8)-1))) -> 0 | Z9: =INDEX('9 - Water Readings'!$L$8:$L$988,1+(2*(ROWS(A$1:A8)-1))) -> 65 | AA9: ='9 - Water Readings'!Q14 -> 0 | AB9: ='9 - Water Readings'!R14 -> 0 | AC9: ='9 - Water Readings'!S14 -> 17
A10: Doha | B10: =B9+1 -> 9 | C10: 9 | D10: 2019 | E10: =INDEX('13 - Electrical Readings'!$C$8:$C$988,1+(2*(ROWS(A$1:A9)-1))) -> 5 | F10: =INDEX('13 - Electrical Readings'!$D$6:$D$988,1+(2*(ROWS(A$1:A10)-1))) -> 6528 | G10: =INDEX('13 - Electrical Readings'!$E$6:$E$988,1+(2*(ROWS(A$1:A10)-1))) -> 7544 | H10: =INDEX('13 - Electrical Readings'!$F$6:$F$988,1+(2*(ROWS(A$1:A10)-1))) -> 12428 | I10: =INDEX('13 - Electrical Readings'!$G$6:$G$988,1+(2*(ROWS(A$1:A10)-1))) -> 13 | J10: =INDEX('13 - Electrical Readings'!$I$6:$I$988,1+(2*(ROWS(A$1:A10)-1))) -> 2086 | K10: =INDEX('13 - Electrical Readings'!$J$6:$J$988,1+(2*(ROWS(B$1:B10)-1))) -> 5248 | L10: =INDEX('13 - Electrical Readings'!$K$6:$K$988,1+(2*(ROWS(C$1:C10)-1))) -> 1554 | M10: =INDEX('13 - Electrical Readings'!$L$6:$L$988,1+(2*(ROWS(D$1:D10)-1))) -> 2343 | N10: =INDEX('13 - Electrical Readings'!$M$6:$M$988,1+(2*(ROWS(E$1:E10)-1))) -> 5795 | O10: =INDEX('13 - Electrical Readings'!$N$6:$N$988,1+(2*(ROWS(E$1:E10)-1))) -> 7756 | P10: =INDEX('13 - Electrical Readings'!$O$6:$O$988,1+(2*(ROWS(E$1:E10)-1))) -> 3895 | Q10: =INDEX('13 - Electrical Readings'!$P$6:$P$988,1+(2*(ROWS(F$1:F10)-1))) -> 2600 | R10: =INDEX('9 - Water Readings'!$C$8:$C$988,1+(2*(ROWS(A$1:A9)-1))) -> 0 | S10: =INDEX('9 - Water Readings'!$D$8:$D$987,1+(2*(ROWS(A$1:A9)-1))) -> 0 | T10: =INDEX('9 - Water Readings'!$E$8:$E$988,1+(2*(ROWS(A$1:A9)-1))) -> 4 | U10: =INDEX('9 - Water Readings'!$G$8:$G$987,1+(2*(ROWS(A$1:A9)-1))) -> 0 | V10: =INDEX('9 - Water Readings'!$H$8:$H$988,1+(2*(ROWS(A$1:A9)-1))) -> 0 | W10: =INDEX('9 - Water Readings'!$I$8:$I$988,1+(2*(ROWS(A$1:A9)-1))) -> 8 | X10: =INDEX('9 - Water Readings'!$J$8:$J$988,1+(2*(ROWS(A$1:A9)-1))) -> 47 | Y10: =INDEX('9 - Water Readings'!$K$8:$K$988,1+(2*(ROWS(A$1:A9)-1))) -> 0 | Z10: =INDEX('9 - Water Readings'!$L$8:$L$988,1+(2*(ROWS(A$1:A9)-1))) -> 58 | AA10: ='9 - Water Readings'!Q15 -> 0 | AB10: ='9 - Water Readings'!R15 -> 0 | AC10: ='9 - Water Readings'!S15 -> 15.9
A11: Doha | B11: =B10+1 -> 10 | C11: 9 | D11: 2019 | E11: =INDEX('13 - Electrical Readings'!$C$8:$C$988,1+(2*(ROWS(A$1:A10)-1))) -> 4 | F11: =INDEX('13 - Electrical Readings'!$D$6:$D$988,1+(2*(ROWS(A$1:A11)-1))) -> 12708 | G11: =INDEX('13 - Electrical Readings'!$E$6:$E$988,1+(2*(ROWS(A$1:A11)-1))) -> 11199 | H11: =INDEX('13 - Electrical Readings'!$F$6:$F$988,1+(2*(ROWS(A$1:A11)-1))) -> 5238 | I11: =INDEX('13 - Electrical Readings'!$G$6:$G$988,1+(2*(ROWS(A$1:A11)-1))) -> 16 | J11: =INDEX('13 - Electrical Readings'!$I$6:$I$988,1+(2*(ROWS(A$1:A11)-1))) -> 1993 | K11: =INDEX('13 - Electrical Readings'!$J$6:$J$988,1+(2*(ROWS(B$1:B11)-1))) -> 5269 | L11: =INDEX('13 - Electrical Readings'!$K$6:$K$988,1+(2*(ROWS(C$1:C11)-1))) -> 1602 | M11: =INDEX('13 - Electrical Readings'!$L$6:$L$988,1+(2*(ROWS(D$1:D11)-1))) -> 2228 | N11: =INDEX('13 - Electrical Readings'!$M$6:$M$988,1+(2*(ROWS(E$1:E11)-1))) -> 5725 | O11: =INDEX('13 - Electrical Readings'!$N$6:$N$988,1+(2*(ROWS(E$1:E11)-1))) -> 7790 | P11: =INDEX('13 - Electrical Readings'!$O$6:$O$988,1+(2*(ROWS(E$1:E11)-1))) -> 3617 | Q11: =INDEX('13 - Electrical Readings'!$P$6:$P$988,1+(2*(ROWS(F$1:F11)-1))) -> 2910 | R11: =INDEX('9 - Water Readings'!$C$8:$C$988,1+(2*(ROWS(A$1:A10)-1))) -> 0 | S11: =INDEX('9 - Water Readings'!$D$8:$D$987,1+(2*(ROWS(A$1:A10)-1))) -> 0 | T11: =INDEX('9 - Water Readings'!$E$8:$E$988,1+(2*(ROWS(A$1:A10)-1))) -> 3 | U11: =INDEX('9 - Water Readings'!$G$8:$G$987,1+(2*(ROWS(A$1:A10)-1))) -> 0 | V11: =INDEX('9 - Water Readings'!$H$8:$H$988,1+(2*(ROWS(A$1:A10)-1))) -> 0 | W11: =INDEX('9 - Water Readings'!$I$8:$I$988,1+(2*(ROWS(A$1:A10)-1))) -> 13 | X11: =INDEX('9 - Water Readings'!$J$8:$J$988,1+(2*(ROWS(A$1:A10)-1))) -> 0 | Y11: =INDEX('9 - Water Readings'!$K$8:$K$988,1+(2*(ROWS(A$1:A10)-1))) -> 0 | Z11: =INDEX('9 - Water Readings'!$L$8:$L$988,1+(2*(ROWS(A$1:A10)-1))) -> 117 | AA11: ='9 - Water Readings'!Q16 -> 0 | AB11: ='9 - Water Readings'!R16 -> 0 | AC11: ='9 - Water Readings'!S16 -> 14.2
A12: Doha | B12: =B11+1 -> 11 | C12: 9 | D12: 2019 | E12: =INDEX('13 - Electrical Readings'!$C$8:$C$988,1+(2*(ROWS(A$1:A11)-1))) -> 7436 | F12: =INDEX('13 - Electrical Readings'!$D$6:$D$988,1+(2*(ROWS(A$1:A12)-1))) -> 5253 | G12: =INDEX('13 - Electrical Readings'!$E$6:$E$988,1+(2*(ROWS(A$1:A12)-1))) -> 8849 | H12: =INDEX('13 - Electrical Readings'!$F$6:$F$988,1+(2*(ROWS(A$1:A12)-1))) -> 5108 | I12: =INDEX('13 - Electrical Readings'!$G$6:$G$988,1+(2*(ROWS(A$1:A12)-1))) -> 8925 | J12: =INDEX('13 - Electrical Readings'!$I$6:$I$988,1+(2*(ROWS(A$1:A12)-1))) -> 1989 | K12: =INDEX('13 - Electrical Readings'!$J$6:$J$988,1+(2*(ROWS(B$1:B12)-1))) -> 5286 | L12: =INDEX('13 - Electrical Readings'!$K$6:$K$988,1+(2*(ROWS(C$1:C12)-1))) -> 1568 | M12: =INDEX('13 - Electrical Readings'!$L$6:$L$988,1+(2*(ROWS(D$1:D12)-1))) -> 2195 | N12: =INDEX('13 - Electrical Readings'!$M$6:$M$988,1+(2*(ROWS(E$1:E12)-1))) -> 5789 | O12: =INDEX('13 - Electrical Readings'!$N$6:$N$988,1+(2*(ROWS(E$1:E12)-1))) -> 7881 | P12: =INDEX('13 - Electrical Readings'!$O$6:$O$988,1+(2*(ROWS(E$1:E12)-1))) -> 3691 | Q12: =INDEX('13 - Electrical Readings'!$P$6:$P$988,1+(2*(ROWS(F$1:F12)-1))) -> 2020 | R12: =INDEX('9 - Water Readings'!$C$8:$C$988,1+(2*(ROWS(A$1:A11)-1))) -> 1 | S12: =INDEX('9 - Water Readings'!$D$8:$D$987,1+(2*(ROWS(A$1:A11)-1))) -> 0 | T12: =INDEX('9 - Water Readings'!$E$8:$E$988,1+(2*(ROWS(A$1:A11)-1))) -> 3 | U12: =INDEX('9 - Water Readings'!$G$8:$G$987,1+(2*(ROWS(A$1:A11)-1))) -> 0 | V12: =INDEX('9 - Water Readings'!$H$8:$H$988,1+(2*(ROWS(A$1:A11)-1))) -> 0 | W12: =INDEX('9 - Water Readings'!$I$8:$I$988,1+(2*(ROWS(A$1:A11)-1))) -> 12 | X12: =INDEX('9 - Water Readings'!$J$8:$J$988,1+(2*(ROWS(A$1:A11)-1))) -> 0 | Y12: =INDEX('9 - Water Readings'!$K$8:$K$988,1+(2*(ROWS(A$1:A11)-1))) -> 0 | Z12: =INDEX('9 - Water Readings'!$L$8:$L$988,1+(2*(ROWS(A$1:A11)-1))) -> 92 | AA12: ='9 - Water Readings'!Q17 -> 0 | AB12: ='9 - Water Readings'!R17 -> 0 | AC12: ='9 - Water Readings'!S17 -> 14.4
A13: Doha | B13: =B12+1 -> 12 | C13: 9 | D13: 2019 | E13: =INDEX('13 - Electrical Readings'!$C$8:$C$988,1+(2*(ROWS(A$1:A12)-1))) -> 10787 | F13: =INDEX('13 - Electrical Readings'!$D$6:$D$988,1+(2*(ROWS(A$1:A13)-1))) -> 637 | G13: =INDEX('13 - Electrical Readings'!$E$6:$E$988,1+(2*(ROWS(A$1:A13)-1))) -> 3890 | H13: =INDEX('13 - Electrical Readings'!$F$6:$F$988,1+(2*(ROWS(A$1:A13)-1))) -> 5036 | I13: =INDEX('13 - Electrical Readings'!$G$6:$G$988,1+(2*(ROWS(A$1:A13)-1))) -> 18708 | J13: =INDEX('13 - Electrical Readings'!$I$6:$I$988,1+(2*(ROWS(A$1:A13)-1))) -> 2017 | K13: =INDEX('13 - Electrical Readings'!$J$6:$J$988,1+(2*(ROWS(B$1:B13)-1))) -> 5215 | L13: =INDEX('13 - Electrical Readings'!$K$6:$K$988,1+(2*(ROWS(C$1:C13)-1))) -> 1502 | M13: =INDEX('13 - Electrical Readings'!$L$6:$L$988,1+(2*(ROWS(D$1:D13)-1))) -> 2068 | N13: =INDEX('13 - Electrical Readings'!$M$6:$M$988,1+(2*(ROWS(E$1:E13)-1))) -> 5750 | O13: =INDEX('13 - Electrical Readings'!$N$6:$N$988,1+(2*(ROWS(E$1:E13)-1))) -> 7820 | P13: =INDEX('13 - Electrical Readings'!$O$6:$O$988,1+(2*(ROWS(E$1:E13)-1))) -> 3514 | Q13: =INDEX('13 - Electrical Readings'!$P$6:$P$988,1+(2*(ROWS(F$1:F13)-1))) -> 2600 | R13: =INDEX('9 - Water Readings'!$C$8:$C$988,1+(2*(ROWS(A$1:A12)-1))) -> 0 | S13: =INDEX('9 - Water Readings'!$D$8:$D$987,1+(2*(ROWS(A$1:A12)-1))) -> 0 | T13: =INDEX('9 - Water Readings'!$E$8:$E$988,1+(2*(ROWS(A$1:A12)-1))) -> 3 | U13: =INDEX('9 - Water Readings'!$G$8:$G$987,1+(2*(ROWS(A$1:A12)-1))) -> 0 | V13: =INDEX('9 - Water Readings'!$H$8:$H$988,1+(2*(ROWS(A$1:A12)-1))) -> 0 | W13: =INDEX('9 - Water Readings'!$I$8:$I$988,1+(2*(ROWS(A$1:A12)-1))) -> 14 | X13: =INDEX('9 - Water Readings'!$J$8:$J$988,1+(2*(ROWS(A$1:A12)-1))) -> 0 | Y13: =INDEX('9 - Water Readings'!$K$8:$K$988,1+(2*(ROWS(A$1:A12)-1))) -> 0 | Z13: =INDEX('9 - Water Readings'!$L$8:$L$988,1+(2*(ROWS(A$1:A12)-1))) -> 83 | AA13: ='9 - Water Readings'!Q18 -> 0 | AB13: ='9 - Water Readings'!R18 -> 0 | AC13: ='9 - Water Readings'!S18 -> 14.4
A14: Doha | B14: =B13+1 -> 13 | C14: 9 | D14: 2019 | E14: =INDEX('13 - Electrical Readings'!$C$8:$C$988,1+(2*(ROWS(A$1:A13)-1))) -> 16073 | F14: =INDEX('13 - Electrical Readings'!$D$6:$D$988,1+(2*(ROWS(A$1:A14)-1))) -> 4000 | G14: =INDEX('13 - Electrical Readings'!$E$6:$E$988,1+(2*(ROWS(A$1:A14)-1))) -> 4615 | H14: =INDEX('13 - Electrical Readings'!$F$6:$F$988,1+(2*(ROWS(A$1:A14)-1))) -> 4750 | I14: =INDEX('13 - Electrical Readings'!$G$6:$G$988,1+(2*(ROWS(A$1:A14)-1))) -> 10026 | J14: =INDEX('13 - Electrical Readings'!$I$6:$I$988,1+(2*(ROWS(A$1:A14)-1))) -> 2254 | K14: =INDEX('13 - Electrical Readings'!$J$6:$J$988,1+(2*(ROWS(B$1:B14)-1))) -> 5825 | L14: =INDEX('13 - Electrical Readings'!$K$6:$K$988,1+(2*(ROWS(C$1:C14)-1))) -> 1494 | M14: =INDEX('13 - Electrical Readings'!$L$6:$L$988,1+(2*(ROWS(D$1:D14)-1))) -> 2218 | N14: =INDEX('13 - Electrical Readings'!$M$6:$M$988,1+(2*(ROWS(E$1:E14)-1))) -> 5578 | O14: =INDEX('13 - Electrical Readings'!$N$6:$N$988,1+(2*(ROWS(E$1:E14)-1))) -> 8735 | P14: =INDEX('13 - Electrical Readings'!$O$6:$O$988,1+(2*(ROWS(E$1:E14)-1))) -> 3647 | Q14: =INDEX('13 - Electrical Readings'!$P$6:$P$988,1+(2*(ROWS(F$1:F14)-1))) -> 3110 | R14: =INDEX('9 - Water Readings'!$C$8:$C$988,1+(2*(ROWS(A$1:A13)-1))) -> 0 | S14: =INDEX('9 - Water Readings'!$D$8:$D$987,1+(2*(ROWS(A$1:A13)-1))) -> 25 | T14: =INDEX('9 - Water Readings'!$E$8:$E$988,1+(2*(ROWS(A$1:A13)-1))) -> 3 | U14: =INDEX('9 - Water Readings'!$G$8:$G$987,1+(2*(ROWS(A$1:A13)-1))) -> 0 | V14: =INDEX('9 - Water Readings'!$H$8:$H$988,1+(2*(ROWS(A$1:A13)-1))) -> 0 | W14: =INDEX('9 - Water Readings'!$I$8:$I$988,1+(2*(ROWS(A$1:A13)-1))) -> 16 | X14: =INDEX('9 - Water Readings'!$J$8:$J$988,1+(2*(ROWS(A$1:A13)-1))) -> 0 | Y14: =INDEX('9 - Water Readings'!$K$8:$K$988,1+(2*(ROWS(A$1:A13)-1))) -> 0 | Z14: =INDEX('9 - Water Readings'!$L$8:$L$988,1+(2*(ROWS(A$1:A13)-1))) -> 95 | AA14: ='9 - Water Readings'!Q19 -> 0 | AB14: ='9 - Water Readings'!R19 -> 0 | AC14: ='9 - Water Readings'!S19 -> 14
... A31: Doha | B31: =B30+1 -> 30 | C31: 9 | D31: 2019 | E31: =INDEX('13 - Electrical Readings'!$C$8:$C$988,1+(2*(ROWS(A$1:A30)-1))) -> 15 | F31: =INDEX('13 - Electrical Readings'!$D$6:$D$988,1+(2*(ROWS(A$1:A31)-1))) -> 12114 | G31: =INDEX('13 - Electrical Readings'!$E$6:$E$988,1+(2*(ROWS(A$1:A31)-1))) -> 15700 | H31: =INDEX('13 - Electrical Readings'!$F$6:$F$988,1+(2*(ROWS(A$1:A31)-1))) -> 5310 | I31: =INDEX('13 - Electrical Readings'!$G$6:$G$988,1+(2*(ROWS(A$1:A31)-1))) -> 17 | J31: =INDEX('13 - Electrical Readings'!$I$6:$I$988,1+(2*(ROWS(A$1:A31)-1))) -> 1809 | K31: =INDEX('13 - Electrical Readings'!$J$6:$J$988,1+(2*(ROWS(B$1:B31)-1))) -> 3113 | L31: =INDEX('13 - Electrical Readings'!$K$6:$K$988,1+(2*(ROWS(C$1:C31)-1))) -> 1105 | M31: =INDEX('13 - Electrical Readings'!$L$6:$L$988,1+(2*(ROWS(D$1:D31)-1))) -> 1808 | N31: =INDEX('13 - Electrical Readings'!$M$6:$M$988,1+(2*(ROWS(E$1:E31)-1))) -> 5275 | O31: =INDEX('13 - Electrical Readings'!$N$6:$N$988,1+(2*(ROWS(E$1:E31)-1))) -> 8476 | P31: =INDEX('13 - Electrical Readings'!$O$6:$O$988,1+(2*(ROWS(E$1:E31)-1))) -> 3507 | Q31: =INDEX('13 - Electrical Readings'!$P$6:$P$988,1+(2*(ROWS(F$1:F31)-1))) -> 2640 | R31: =INDEX('9 - Water Readings'!$C$8:$C$988,1+(2*(ROWS(A$1:A30)-1))) -> 0 | S31: =INDEX('9 - Water Readings'!$D$8:$D$987,1+(2*(ROWS(A$1:A30)-1))) -> 0 | T31: =INDEX('9 - Water Readings'!$E$8:$E$988,1+(2*(ROWS(A$1:A30)-1))) -> 0 | U31: =INDEX('9 - Water Readings'!$G$8:$G$987,1+(2*(ROWS(A$1:A30)-1))) -> 0 | V31: =INDEX('9 - Water Readings'!$H$8:$H$988,1+(2*(ROWS(A$1:A30)-1))) -> 0 | W31: =INDEX('9 - Water Readings'!$I$8:$I$988,1+(2*(ROWS(A$1:A30)-1))) -> 32 | X31: =INDEX('9 - Water Readings'!$J$8:$J$988,1+(2*(ROWS(A$1:A30)-1))) -> 83 | Y31: =INDEX('9 - Water Readings'!$K$8:$K$988,1+(2*(ROWS(A$1:A30)-1))) -> 0 | Z31: =INDEX('9 - Water Readings'!$L$8:$L$988,1+(2*(ROWS(A$1:A30)-1))) -> 55 | AA31: ='9 - Water Readings'!Q36 -> 0 | AB31: ='9 - Water Readings'!R36 -> 0 | AC31: ='9 - Water Readings'!S36 -> 14

Sheet 13 - Electrical Readings
F2: Central Plant Engineering
F3: Daily Electrical Meter Readings | N3: Month:SEPTEMBER 2019
B5: Date | C5: CP Chillers | D5: CP Chillers | E5: CP Chillers | F5: CP Chillers | G5: CP Chillers | H5: CP Total kWh | I5: Town House | J5: Hotel | K5: Hotel | L5: Hotel | M5: Hotel | N5: Spa | O5: Marina | P5: Nobu | Q5: Hotel Total kWh | R5: Grand Total kWh
C6: 157691 | D6: 157692 | E6: 157693 | F6: 157694 | G6: 167609 | I6: 166443 | J6: 157687 | K6: 157688 | L6: 157689 | M6: 157690 | N6: 174390 | O6: 173992 | P6: 1180004
B7: 1 | C7: 13967115 | D7: 10455328 | E7: 19078328 | F7: 18472906 | G7: 12631483 | I7: 4300812 | J7: 19218459 | K7: 5576982 | L7: 9204085 | M7: 12517544 | N7: 18523298 | O7: 5629800 | P7: 4884720
B8: Consumption | C8: =C7-13957994 -> 9121 | D8: =D7-10444006 -> 11322 | E8: =E7-19069012 -> 9316 | F8: =F7-18467610 -> 5296 | G8: =G7-12631471 -> 12 | H8: =SUM(C8:G8) -> 35067 | I8: =I7-4298813 -> 1999 | J8: =J7-19213293 -> 5166 | K8: =K7-5575016 -> 1966 | L8: =L7-9201515 -> 2570 | M8: =M7-12511525 -> 6019 | N8: =N7-18514579 -> 8719 | O8: =O7-5626346 -> 3454 | P8: =P7-4882790 -> 1930 | Q8: =SUM(I8:P8) -> 31823 | R8: =SUM(H8,Q8) -> 66890
B9: 2 | C9: 13986993 | D9: 10468732 | E9: 19083019 | F9: 18478262 | G9: 12631498 | I9: 4302835 | J9: 19223697 | K9: 5578837 | L9: 9206615 | M9: 12523510 | N9: 18532077 | O9: 5633248 | P9: 4887260
B10: Consumption | C10: =C9-C7 -> 19878 | D10: =D9-D7 -> 13404 | E10: =E9-E7 -> 4691 | F10: =F9-F7 -> 5356 | G10: =G9-G7 -> 15 | H10: =SUM(C10:G10) -> 43344 | I10: =I9-I7 -> 2023 | J10: =J9-J7 -> 5238 | K10: =K9-K7 -> 1855 | L10: =L9-L7 -> 2530 | M10: =M9-M7 -> 5966 | N10: =N9-N7 -> 8779 | O10: =O9-O7 -> 3448 | P10: =P9-P7 -> 2540 | Q10: =SUM(I10:P10) -> 32379 | R10: =SUM(H10,Q10) -> 75723
B11: 3 | C11: 14005926 | D11: 10481458 | E11: 19087530 | F11: 18483544 | G11: 12631512 | I11: 4304816 | J11: 19228884 | K11: 5580661 | L11: 9208932 | M11: 12529357 | N11: 18540238 | O11: 5637180 | P11: 4889750
B12: Consumption | C12: =C11-C9 -> 18933 | D12: =D11-D9 -> 12726 | E12: =E11-E9 -> 4511 | F12: =F11-F9 -> 5282 | G12: =G11-G9 -> 14 | H12: =SUM(C12:G12) -> 41466 | I12: =I11-I9 -> 1981 | J12: =J11-J9 -> 5187 | K12: =K11-K9 -> 1824 | L12: =L11-L9 -> 2317 | M12: =M11-M9 -> 5847 | N12: =N11-N9 -> 8161 | O12: =O11-O9 -> 3932 | P12: =P11-P9 -> 2490 | Q12: =SUM(I12:P12) -> 31739 | R12: =SUM(H12,Q12) -> 73205
B13: 4 | C13: 14023360 | D13: 10493194 | E13: 19092180 | F13: 18488960 | G13: 12631525 | I13: 4306920 | J13: 19234233 | K13: 5582485 | L13: 9211343 | M13: 12535404 | N13: 18548974 | O13: 5641246 | P13: 4892310
B14: Consumption | C14: =C13-C11 -> 17434 | D14: =D13-D11 -> 11736 | E14: =E13-E11 -> 4650 | F14: =F13-F11 -> 5416 | G14: =G13-G11 -> 13 | H14: =SUM(C14:G14) -> 39249 | I14: =I13-I11 -> 2104 | J14: =J13-J11 -> 5349 | K14: =K13-K11 -> 1824 | L14: =L13-L11 -> 2411 | M14: =M13-M11 -> 6047 | N14: =N13-N11 -> 8736 | O14: =O13-O11 -> 4066 | P14: =P13-P11 -> 2560 | Q14: =SUM(I14:P14) -> 33097 | R14: =SUM(H14,Q14) -> 72346
B15: 5 | C15: 14041370 | D15: 10499728 | E15: 19096696 | F15: 18499693 | G15: 12631537 | I15: 4308886 | J15: 19239443 | K15: 5584275 | L15: 9213663 | M15: 12541297 | N15: 18557735 | O15: 5645016 | P15: 4895190
B16: Consumption | C16: =C15-C13 -> 18010 | D16: =D15-D13 -> 6534 | E16: =E15-E13 -> 4516 | F16: =F15-F13 -> 10733 | G16: =G15-G13 -> 12 | H16: =SUM(C16:G16) -> 39805 | I16: =I15-I13 -> 1966 | J16: =J15-J13 -> 5210 | K16: =K15-K13 -> 1790 | L16: =L15-L13 -> 2320 | M16: =M15-M13 -> 5893 | N16: =N15-N13 -> 8761 | O16: =O15-O13 -> 3770 | P16: =P15-P13 -> 2880 | Q16: =SUM(I16:P16) -> 32590 | R16: =SUM(H16,Q16) -> 72395
B17: 6 | C17: 14060352 | D17: 10500315 | E17: 19101243 | F17: 18516852 | G17: 12631549 | I17: 4310944 | J17: 19244869 | K17: 5586137 | L17: 9216119 | M17: 12546698 | N17: 18566982 | O17: 5648676 | P17: 4898200
B18: Consumption | C18: =C17-C15 -> 18982 | D18: =D17-D15 -> 587 | E18: =E17-E15 -> 4547 | F18: =F17-F15 -> 17159 | G18: =G17-G15 -> 12 | H18: =SUM(C18:G18) -> 41287 | I18: =I17-I15 -> 2058 | J18: =J17-J15 -> 5426 | K18: =K17-K15 -> 1862 | L18: =L17-L15 -> 2456 | M18: =M17-M15 -> 5401 | N18: =N17-N15 -> 9247 | O18: =O17-O15 -> 3660 | P18: =P17-P15 -> 3010 | Q18: =SUM(I18:P18) -> 33120 | R18: =SUM(H18,Q18) -> 74407
B19: 7 | C19: 14076914 | D19: 10500936 | E19: 19105734 | F19: 18532915 | G19: 12631567 | I19: 4312920 | J19: 19249756 | K19: 5587884 | L19: 9218431 | M19: 12552159 | N19: 18575274 | O19: 5652591 | P19: 4900940
B20: Consumption | C20: =C19-C17 -> 16562 | D20: =D19-D17 -> 621 | E20: =E19-E17 -> 4491 | F20: =F19-F17 -> 16063 | G20: =G19-G17 -> 18 | H20: =SUM(C20:G20) -> 37755 | I20: =I19-I17 -> 1976 | J20: =J19-J17 -> 4887 | K20: =K19-K17 -> 1747 | L20: =L19-L17 -> 2312 | M20: =M19-M17 -> 5461 | N20: =N19-N17 -> 8292 | O20: =O19-O17 -> 3915 | P20: =P19-P17 -> 2740 | Q20: =SUM(I20:P20) -> 31330 | R20: =SUM(H20,Q20) -> 69085
B21: 8 | C21: 14087943 | D21: 10501530 | E21: 19109613 | F21: 18549656 | G21: 12631584 | I21: 4314947 | J21: 19254675 | K21: 5589704 | L21: 9220847 | M21: 12557950 | N21: 18583011 | O21: 5656479 | P21: 4903560
B22: Consumption | C22: =C21-C19 -> 11029 | D22: =D21-D19 -> 594 | E22: =E21-E19 -> 3879 | F22: =F21-F19 -> 16741 | G22: =G21-G19 -> 17 | H22: =SUM(C22:G22) -> 32260 | I22: =I21-I19 -> 2027 | J22: =J21-J19 -> 4919 | K22: =K21-K19 -> 1820 | L22: =L21-L19 -> 2416 | M22: =M21-M19 -> 5791 | N22: =N21-N19 -> 7737 | O22: =O21-O19 -> 3888 | P22: =P21-P19 -> 2620 | Q22: =SUM(I22:P22) -> 31218 | R22: =SUM(H22,Q22) -> 63478
B23: 9 | C23: 14087948 | D23: 10508058 | E23: 19117157 | F23: 18562084 | G23: 12631597 | I23: 4317033 | J23: 19259923 | K23: 5591258 | L23: 9223190 | M23: 12563745 | N23: 18590767 | O23: 5660374 | P23: 4906160
B24: Consumption | C24: =C23-C21 -> 5 | D24: =D23-D21 -> 6528 | E24: =E23-E21 -> 7544 | F24: =F23-F21 -> 12428 | G24: =G23-G21 -> 13 | H24: =SUM(C24:G24) -> 26518 | I24: =I23-I21 -> 2086 | J24: =J23-J21 -> 5248 | K24: =K23-K21 -> 1554 | L24: =L23-L21 -> 2343 | M24: =M23-M21 -> 5795 | N24: =N23-N21 -> 7756 | O24: =O23-O21 -> 3895 | P24: =P23-P21 -> 2600 | Q24: =SUM(I24:P24) -> 31277 | R24: =SUM(H24,Q24) -> 57795
B25: 10 | C25: 14087952 | D25: 10520766 | E25: 19128356 | F25: 18567322 | G25: 12631613 | I25: 4319026 | J25: 19265192 | K25: 5592860 | L25: 9225418 | M25: 12569470 | N25: 18598557 | O25: 5663991 | P25: 4909070
B26: Consumption | C26: =C25-C23 -> 4 | D26: =D25-D23 -> 12708 | E26: =E25-E23 -> 11199 | F26: =F25-F23 -> 5238 | G26: =G25-G23 -> 16 | H26: =SUM(C26:G26) -> 29165 | I26: =I25-I23 -> 1993 | J26: =J25-J23 -> 5269 | K26: =K25-K23 -> 1602 | L26: =L25-L23 -> 2228 | M26: =M25-M23 -> 5725 | N26: =N25-N23 -> 7790 | O26: =O25-O23 -> 3617 | P26: =P25-P23 -> 2910 | Q26: =SUM(I26:P26) -> 31134 | R26: =SUM(H26,Q26) -> 60299
B27: 11 | C27: 14095388 | D27: 10526019 | E27: 19137205 | F27: 18572430 | G27: 12640538 | I27: 4321015 | J27: 19270478 | K27: 5594428 | L27: 9227613 | M27: 12575259 | N27: 18606438 | O27: 5667682 | P27: 4911090
B28: Consumption | C28: =C27-C25 -> 7436 | D28: =D27-D25 -> 5253 | E28: =E27-E25 -> 8849 | F28: =F27-F25 -> 5108 | G28: =G27-G25 -> 8925 | H28: =SUM(C28:G28) -> 35571 | I28: =I27-I25 -> 1989 | J28: =J27-J25 -> 5286 | K28: =K27-K25 -> 1568 | L28: =L27-L25 -> 2195 | M28: =M27-M25 -> 5789 | N28: =N27-N25 -> 7881 | O28: =O27-O25 -> 3691 | P28: =P27-P25 -> 2020 | Q28: =SUM(I28:P28) -> 30419 | R28: =SUM(H28,Q28) -> 65990
B29: 12 | C29: 14106175 | D29: 10526656 | E29: 19141095 | F29: 18577466 | G29: 12659246 | I29: 4323032 | J29: 19275693 | K29: 5595930 | L29: 9229681 | M29: 12581009 | N29: 18614258 | O29: 5671196 | P29: 4913690
B30: Consumption | C30: =C29-C27 -> 10787 | D30: =D29-D27 -> 637 | E30: =E29-E27 -> 3890 | F30: =F29-F27 -> 5036 | G30: =G29-G27 -> 18708 | H30: =SUM(C30:G30) -> 39058 | I30: =I29-I27 -> 2017 | J30: =J29-J27 -> 5215 | K30: =K29-K27 -> 1502 | L30: =L29-L27 -> 2068 | M30: =M29-M27 -> 5750 | N30: =N29-N27 -> 7820 | O30: =O29-O27 -> 3514 | P30: =P29-P27 -> 2600 | Q30: =SUM(I30:P30) -> 30486 | R30: =SUM(H30,Q30) -> 69544
B31: 13 | C31: 14122248 | D31: 10530656 | E31: 19145710 | F31: 18582216 | G31: 12669272 | I31: 4325286 | J31: 19281518 | K31: 5597424 | L31: 9231899 | M31: 12586587 | N31: 18622993 | O31: 5674843 | P31: 4916800
B32: Consumption | C32: =C31-C29 -> 16073 | D32: =D31-D29 -> 4000 | E32: =E31-E29 -> 4615 | F32: =F31-F29 -> 4750 | G32: =G31-G29 -> 10026 | H32: =SUM(C32:G32) -> 39464 | I32: =I31-I29 -> 2254 | J32: =J31-J29 -> 5825 | K32: =K31-K29 -> 1494 | L32: =L31-L29 -> 2218 | M32: =M31-M29 -> 5578 | N32: =N31-N29 -> 8735 | O32: =O31-O29 -> 3647 | P32: =P31-P29 -> 3110 | Q32: =SUM(I32:P32) -> 32861 | R32: =SUM(H32,Q32) -> 72325
B33: 14 | C33: 14140369 | D33: 10532495 | E33: 19149894 | F33: 18587012 | G33: 12680420 | I33: 4327116 | J33: 19285927 | K33: 5598821 | L33: 9233656 | M33: 12591698 | N33: 18629808 | O33: 5677729 | P33: 4919100
B34: Consumption | C34: =C33-C31 -> 18121 | D34: =D33-D31 -> 1839 | E34: =E33-E31 -> 4184 | F34: =F33-F31 -> 4796 | G34: =G33-G31 -> 11148 | H34: =SUM(C34:G34) -> 40088 | I34: =I33-I31 -> 1830 | J34: =J33-J31 -> 4409 | K34: =K33-K31 -> 1397 | L34: =L33-L31 -> 1757 | M34: =M33-M31 -> 5111 | N34: =N33-N31 -> 6815 | O34: =O33-O31 -> 2886 | P34: =P33-P31 -> 2300 | Q34: =SUM(I34:P34) -> 26505 | R34: =SUM(H34,Q34) -> 66593
B35: 15 | C35: 14147253 | D35: 10533316 | E35: 19154706 | F35: 18598659 | G35: 12698493 | I35: 4329344 | J35: 19291170 | K35: 5600323 | L35: 9235840 | M35: 12597730 | N35: 18637785 | O35: 5681060 | P35: 4921750
B36: Consumption | C36: =C35-C33 -> 6884 | D36: =D35-D33 -> 821 | E36: =E35-E33 -> 4812 | F36: =F35-F33 -> 11647 | G36: =G35-G33 -> 18073 | H36: =SUM(C36:G36) -> 42237 | I36: =I35-I33 -> 2228 | J36: =J35-J33 -> 5243 | K36: =K35-K33 -> 1502 | L36: =L35-L33 -> 2184 | M36: =M35-M33 -> 6032 | N36: =N35-N33 -> 7977 | O36: =O35-O33 -> 3331 | P36: =P35-P33 -> 2650 | Q36: =SUM(I36:P36) -> 31147 | R36: =SUM(H36,Q36) -> 73384
B37: 16 | C37: 14147259 | D37: 10534015 | E37: 19159140 | F37: 18613046 | G37: 12714725 | I37: 4331310 | J37: 19296205 | K37: 5601654 | L37: 9237973 | M37: 12603541 | N37: 18645655 | O37: 5684307 | P37: 4924410
B38: Consumption | C38: =C37-C35 -> 6 | D38: =D37-D35 -> 699 | E38: =E37-E35 -> 4434 | F38: =F37-F35 -> 14387 | G38: =G37-G35 -> 16232 | H38: =SUM(C38:G38) -> 35758 | I38: =I37-I35 -> 1966 | J38: =J37-J35 -> 5035 | K38: =K37-K35 -> 1331 | L38: =L37-L35 -> 2133 | M38: =M37-M35 -> 5811 | N38: =N37-N35 -> 7870 | O38: =O37-O35 -> 3247 | P38: =P37-P35 -> 2660 | Q38: =SUM(I38:P38) -> 30053 | R38: =SUM(H38,Q38) -> 65811
B39: 17 | C39: 14147264 | D39: 10534737 | E39: 19163466 | F39: 18629620 | G39: 12729609 | I39: 4333406 | J39: 19301443 | K39: 5603014 | L39: 9240116 | M39: 12609500 | N39: 18653792 | O39: 5687470 | P39: 4927100
B40: Consumption | C40: =C39-C37 -> 5 | D40: =D39-D37 -> 722 | E40: =E39-E37 -> 4326 | F40: =F39-F37 -> 16574 | G40: =G39-G37 -> 14884 | H40: =SUM(C40:G40) -> 36511 | I40: =I39-I37 -> 2096 | J40: =J39-J37 -> 5238 | K40: =K39-K37 -> 1360 | L40: =L39-L37 -> 2143 | M40: =M39-M37 -> 5959 | N40: =N39-N37 -> 8137 | O40: =O39-O37 -> 3163 | P40: =P39-P37 -> 2690 | Q40: =SUM(I40:P40) -> 30786 | R40: =SUM(H40,Q40) -> 67297
B41: 18 | C41: 14147274 | D41: 10535451 | E41: 19167719 | F41: 18645119 | G41: 12743731 | I41: 4335416 | J41: 19306693 | K41: 5604525 | L41: 9242260 | M41: 12615426 | N41: 18662265 | O41: 5690424 | P41: 4929660
B42: Consumption | C42: =C41-C39 -> 10 | D42: =D41-D39 -> 714 | E42: =E41-E39 -> 4253 | F42: =F41-F39 -> 15499 | G42: =G41-G39 -> 14122 | H42: =SUM(C42:G42) -> 34598 | I42: =I41-I39 -> 2010 | J42: =J41-J39 -> 5250 | K42: =K41-K39 -> 1511 | L42: =L41-L39 -> 2144 | M42: =M41-M39 -> 5926 | N42: =N41-N39 -> 8473 | O42: =O41-O39 -> 2954 | P42: =P41-P39 -> 2560 | Q42: =SUM(I42:P42) -> 30828 | R42: =SUM(H42,Q42) -> 65426
...

Sheet 9 - Water Readings
F2: Central Plant Engineering
F3: Daily Water Meter Readings | M3: Month: SEPTEMBER 2019
B5: Date | C5: CP F/F | D5: CP Chillers | E5: CP Parking | F5: CP Total M3 | G5: Town House | H5: Spa B | I5: Spa A | J5: CW Hotel A | K5: CCW Hotel B | L5: Marina | M5: Hotel Total M3 | N5: Grand Total M3 | P5: Day | Q5: Room Nights | R5: Total Guests | S5: Cooling Degree Day
C6: 130465 | D6: 130460 | E6: 130461 | G6: 130464 | H6: 130456 | I6: 130457 | J6: 130458 | K6: 130459 | L6: 130466
B7: 1 | C7: 6519 | D7: 289 | E7: 43930 | G7: 199618 | H7: 153768 | I7: 144582 | J7: 696970 | K7: 599391 | L7: 404635 | P7: 1 | Q7: 0 | R7: 0 | S7: 17.3 | U7: Note: The following water meters are not working
B8: Consumption | C8: =C7-6519 -> 0 | D8: =D7-289 -> 0 | E8: =E7-43925 -> 5 | F8: =SUM(C8:E8) -> 5 | G8: 0 | H8: 0 | I8: =I7-144524 -> 58 | J8: =J7-696843 -> 127 | K8: 0 | L8: =L7-404601 -> 34 | M8: =SUM(G8:L8) -> 219 | N8: =SUM(F8,M8) -> 224 | P8: 2 | Q8: 0 | R8: 0 | S8: 15 | U8: # Town House -130464
B9: 2 | C9: 6519 | D9: 289 | E9: 43938 | G9: 199618 | H9: 153768 | I9: 144635 | J9: 697074 | K9: 599391 | L9: 404681 | P9: 3 | Q9: 0 | R9: 0 | S9: 14 | U9: # Spa B - 130456
B10: Consumption | C10: =C9-C7 -> 0 | D10: =D9-D7 -> 0 | E10: =E9-E7 -> 8 | F10: =SUM(C10:E10) -> 8 | G10: =G9-G7 -> 0 | H10: =H9-H7 -> 0 | I10: =I9-I7 -> 53 | J10: =J9-J7 -> 104 | K10: =K9-K7 -> 0 | L10: =L9-L7 -> 46 | M10: =SUM(G10:L10) -> 203 | N10: =SUM(F10,M10) -> 211 | P10: 4 | Q10: 0 | R10: 0 | S10: 16.6 | U10: # CCW Hotel B - 130459
B11: 3 | C11: 6519 | D11: 289 | E11: 43942 | G11: 199618 | H11: 153768 | I11: 144684 | J11: 697184 | K11: 599391 | L11: 404719 | P11: 5 | Q11: 0 | R11: 0 | S11: 15.5
B12: Consumption | C12: =C11-C9 -> 0 | D12: =D11-D9 -> 0 | E12: =E11-E9 -> 4 | F12: =SUM(C12:E12) -> 4 | G12: =G11-G9 -> 0 | H12: =H11-H9 -> 0 | I12: =I11-I9 -> 49 | J12: =J11-J9 -> 110 | K12: =K11-K9 -> 0 | L12: =L11-L9 -> 38 | M12: =SUM(G12:L12) -> 197 | N12: =SUM(F12,M12) -> 201 | P12: 6 | Q12: 0 | R12: 0 | S12: 14.4
B13: 4 | C13: 6519 | D13: 289 | E13: 43945 | G13: 199618 | H13: 153768 | I13: 144743 | J13: 697303 | K13: 599391 | L13: 404761 | P13: 7 | Q13: 0 | R13: 0 | S13: 17.8
B14: Consumption | C14: =C13-C11 -> 0 | D14: =D13-D11 -> 0 | E14: =E13-E11 -> 3 | F14: =SUM(C14:E14) -> 3 | G14: =G13-G11 -> 0 | H14: =H13-H11 -> 0 | I14: =I13-I11 -> 59 | J14: =J13-J11 -> 119 | K14: =K13-K11 -> 0 | L14: =L13-L11 -> 42 | M14: =SUM(G14:L14) -> 220 | N14: =SUM(F14,M14) -> 223 | P14: 8 | Q14: 0 | R14: 0 | S14: 17 | U14: Note: Hotel clossed for renovation from 15 th June 2019
B15: 5 | C15: 6519 | D15: 293 | E15: 43948 | G15: 199618 | H15: 153768 | I15: 144800 | J15: 697408 | K15: 599391 | L15: 404801 | P15: 9 | Q15: 0 | R15: 0 | S15: 15.9
B16: Consumption | C16: =C15-C13 -> 0 | D16: =D15-D13 -> 4 | E16: =E15-E13 -> 3 | F16: =SUM(C16:E16) -> 7 | G16: =G15-G13 -> 0 | H16: =H15-H13 -> 0 | I16: =I15-I13 -> 57 | J16: =J15-J13 -> 105 | K16: =K15-K13 -> 0 | L16: =L15-L13 -> 40 | M16: =SUM(G16:L16) -> 202 | N16: =SUM(F16,M16) -> 209 | P16: 10 | Q16: 0 | R16: 0 | S16: 14.2
B17: 6 | C17: 6519 | D17: 293 | E17: 43954 | G17: 199618 | H17: 153768 | I17: 144875 | J17: 697505 | K17: 599391 | L17: 404850 | P17: 11 | Q17: 0 | R17: 0 | S17: 14.4
B18: Consumption | C18: =C17-C15 -> 0 | D18: =D17-D15 -> 0 | E18: =E17-E15 -> 6 | F18: =SUM(C18:E18) -> 6 | G18: =G17-G15 -> 0 | H18: =H17-H15 -> 0 | I18: =I17-I15 -> 75 | J18: =J17-J15 -> 97 | K18: =K17-K15 -> 0 | L18: =L17-L15 -> 49 | M18: =SUM(G18:L18) -> 221 | N18: =SUM(F18,M18) -> 227 | P18: 12 | Q18: 0 | R18: 0 | S18: 14.4
B19: 7 | C19: 6520 | D19: 293 | E19: 43958 | G19: 199618 | H19: 153768 | I19: 144914 | J19: 697618 | K19: 599391 | L19: 404898 | P19: 13 | Q19: 0 | R19: 0 | S19: 14
B20: Consumption | C20: =C19-C17 -> 1 | D20: =D19-D17 -> 0 | E20: =E19-E17 -> 4 | F20: =SUM(C20:E20) -> 5 | G20: =G19-G17 -> 0 | H20: =H19-H17 -> 0 | I20: =I19-I17 -> 39 | J20: =J19-J17 -> 113 | K20: 0 | L20: =L19-L17 -> 48 | M20: =SUM(G20:L20) -> 200 | N20: =SUM(F20,M20) -> 205 | P20: 14 | Q20: 0 | R20: 0 | S20: 14.3
B21: 8 | C21: 6520 | D21: 293 | E21: 43965 | G21: 199618 | H21: 153768 | I21: 144921 | J21: 697735 | K21: 599391 | L21: 404963 | P21: 15 | Q21: 0 | R21: 0 | S21: 12.8
B22: Consumption | C22: =C21-C19 -> 0 | D22: =D21-D19 -> 0 | E22: =E21-E19 -> 7 | F22: =SUM(C22:E22) -> 7 | G22: =G21-G19 -> 0 | H22: =H21-H19 -> 0 | I22: =I21-I19 -> 7 | J22: =J21-J19 -> 117 | K22: 0 | L22: =L21-L19 -> 65 | M22: =SUM(G22:L22) -> 189 | N22: =SUM(F22,M22) -> 196 | P22: 16 | Q22: 0 | R22: 0 | S22: 13.4
B23: 9 | C23: 6520 | D23: 293 | E23: 43969 | G23: 199618 | H23: 153768 | I23: 144929 | J23: 697782 | K23: 599391 | L23: 405021 | P23: 17 | Q23: 0 | R23: 0 | S23: 13.6
B24: Consumption | C24: =C23-C21 -> 0 | D24: =D23-D21 -> 0 | E24: =E23-E21 -> 4 | F24: =SUM(C24:E24) -> 4 | G24: =G23-G21 -> 0 | H24: =H23-H21 -> 0 | I24: =I23-I21 -> 8 | J24: =J23-J21 -> 47 | K24: =K23-K21 -> 0 | L24: =L23-L21 -> 58 | M24: =SUM(G24:L24) -> 113 | N24: =SUM(F24,M24) -> 117 | P24: 18 | Q24: 0 | R24: 0 | S24: 14.3
B25: 10 | C25: 6520 | D25: 293 | E25: 43972 | G25: 199618 | H25: 153768 | I25: 144942 | J25: 697782 | K25: 599391 | L25: 405138 | P25: 19 | Q25: 0 | R25: 0 | S25: 13.6
B26: Consumption | C26: =C25-C23 -> 0 | D26: =D25-D23 -> 0 | E26: =E25-E23 -> 3 | F26: =SUM(C26:E26) -> 3 | G26: =G25-G23 -> 0 | H26: =H25-H23 -> 0 | I26: =I25-I23 -> 13 | J26: =J25-J23 -> 0 | K26: =K25-K23 -> 0 | L26: =L25-L23 -> 117 | M26: =SUM(G26:L26) -> 130 | N26: =SUM(F26,M26) -> 133 | P26: 20 | Q26: 0 | R26: 0 | S26: 13.4
B27: 11 | C27: 6521 | D27: 293 | E27: 43975 | G27: 199618 | H27: 153768 | I27: 144954 | J27: 697782 | K27: 599391 | L27: 405230 | P27: 21 | Q27: 0 | R27: 0 | S27: 14.4
B28: Consumption | C28: =C27-C25 -> 1 | D28: =D27-D25 -> 0 | E28: =E27-E25 -> 3 | F28: =SUM(C28:E28) -> 4 | G28: =G27-G25 -> 0 | H28: =H27-H25 -> 0 | I28: =I27-I25 -> 12 | J28: =J27-J25 -> 0 | K28: =K27-K25 -> 0 | L28: =L27-L25 -> 92 | M28: =SUM(G28:L28) -> 104 | N28: =SUM(F28,M28) -> 108 | P28: 22 | Q28: 0 | R28: 0 | S28: 13.8
B29: 12 | C29: 6521 | D29: 293 | E29: 43978 | G29: 199618 | H29: 153768 | I29: 144968 | J29: 697782 | K29: 599391 | L29: 405313 | P29: 23 | Q29: 0 | R29: 0 | S29: 14.5
B30: Consumption | C30: =C29-C27 -> 0 | D30: =D29-D27 -> 0 | E30: =E29-E27 -> 3 | F30: =SUM(C30:E30) -> 3 | G30: =G29-G27 -> 0 | H30: =H29-H27 -> 0 | I30: =I29-I27 -> 14 | J30: =J29-J27 -> 0 | K30: =K29-K27 -> 0 | L30: =L29-L27 -> 83 | M30: =SUM(G30:L30) -> 97 | N30: =SUM(F30,M30) -> 100 | P30: 24 | Q30: 0 | R30: 0 | S30: 13.2
B31: 13 | C31: 6521 | D31: 318 | E31: 43981 | G31: 199618 | H31: 153768 | I31: 144984 | J31: 697782 | K31: 599391 | L31: 405408 | P31: 24 | Q31: 0 | R31: 0 | S31: 13.4
B32: Consumption | C32: =C31-C29 -> 0 | D32: =D31-D29 -> 25 | E32: =E31-E29 -> 3 | F32: =SUM(C32:E32) -> 28 | G32: =G31-G29 -> 0 | H32: =H31-H29 -> 0 | I32: =I31-I29 -> 16 | J32: =J31-J29 -> 0 | K32: =K31-K29 -> 0 | L32: =L31-L29 -> 95 | M32: =SUM(G32:L32) -> 111 | N32: =SUM(F32,M32) -> 139 | P32: 26 | Q32: 0 | R32: 0 | S32: 13.6
B33: 14 | C33: 6521 | D33: 318 | E33: 43985 | G33: 199618 | H33: 153768 | I33: 144992 | J33: 697782 | K33: 599391 | L33: 405465 | P33: 27 | Q33: 0 | R33: 0 | S33: 13.4
B34: Consumption | C34: =C33-C31 -> 0 | D34: =D33-D31 -> 0 | E34: =E33-E31 -> 4 | F34: =SUM(C34:E34) -> 4 | G34: =G33-G31 -> 0 | H34: =H33-H31 -> 0 | I34: =I33-I31 -> 8 | J34: =J33-J31 -> 0 | K34: =K33-K31 -> 0 | L34: =L33-L31 -> 57 | M34: =SUM(G34:L34) -> 65 | N34: =SUM(F34,M34) -> 69 | P34: 28 | Q34: 0 | R34: 0 | S34: 13.7
B35: 15 | C35: 6521 | D35: 318 | E35: 43985 | G35: 199618 | H35: 153768 | I35: 145003 | J35: 697782 | K35: 599391 | L35: 405530 | P35: 29 | Q35: 0 | R35: 0 | S35: 14.2
B36: Consumption | C36: =C35-C33 -> 0 | D36: =D35-D33 -> 0 | E36: =E35-E33 -> 0 | F36: =SUM(C36:E36) -> 0 | G36: =G35-G33 -> 0 | H36: =H35-H33 -> 0 | I36: =I35-I33 -> 11 | J36: =J35-J33 -> 0 | K36: =K35-K33 -> 0 | L36: =L35-L33 -> 65 | M36: =SUM(G36:L36) -> 76 | N36: =SUM(F36,M36) -> 76 | P36: 30 | Q36: 0 | R36: 0 | S36: 14
B37: 16 | C37: 6522 | D37: 318 | E37: 43985 | G37: 199618 | H37: 153768 | I37: 145029 | J37: 697782 | K37: 599391 | L37: 405601
B38: Consumption | C38: =C37-C35 -> 1 | D38: =D37-D35 -> 0 | E38: =E37-E35 -> 0 | F38: =SUM(C38:E38) -> 1 | G38: =G37-G35 -> 0 | H38: =H37-H35 -> 0 | I38: =I37-I35 -> 26 | J38: =J37-J35 -> 0 | K38: =K37-K35 -> 0 | L38: =L37-L35 -> 71 | M38: =SUM(G38:L38) -> 97 | N38: =SUM(F38,M38) -> 98 | Q38: =SUM(Q7:Q37) -> 0 | R38: =SUM(R7:R37) -> 0 | S38: =SUM(S6:S36) -> 434.1
B39: 17 | C39: 6522 | D39: 319 | E39: 43985 | G39: 199618 | H39: 153768 | I39: 145053 | J39: 697782 | K39: 599391 | L39: 405661
B40: Consumption | C40: =C39-C37 -> 0 | D40: =D39-D37 -> 1 | E40: =E39-E37 -> 0 | F40: =SUM(C40:E40) -> 1 | G40: =G39-G37 -> 0 | H40: =H39-H37 -> 0 | I40: =I39-I37 -> 24 | J40: =J39-J37 -> 0 | K40: =K39-K37 -> 0 | L40: =L39-L37 -> 60 | M40: =SUM(G40:L40) -> 84 | N40: =SUM(F40,M40) -> 85
B41: 18 | C41: 6530 | D41: 319 | E41: 43985 | G41: 199618 | H41: 153768 | I41: 145063 | J41: 697782 | K41: 599391 | L41: 405734
B42: Consumption | C42: =C41-C39 -> 8 | D42: =D41-D39 -> 0 | E42: =E41-E39 -> 0 | F42: =SUM(C42:E42) -> 8 | G42: =G41-G39 -> 0 | H42: =H41-H39 -> 0 | I42: =I41-I39 -> 10 | J42: =J41-J39 -> 0 | K42: =K41-K39 -> 0 | L42: =L41-L39 -> 73 | M42: =SUM(G42:L42) -> 83 | N42: =SUM(F42,M42) -> 91
...
