Workbook

Sheet Total
A1: Site Name | B1: Day | C1: Month | D1: Year | E1: Total Electricity Kwh | F1: Electricity Tariff ($/Kwh) | G1: Total Fuel Oil (Liters) | H1: Fuel Oil $/Liter | I1: LPG (Kg) | J1: LPG $/Kg | K1: Water Utility Supply (m3) m3 | L1: Water Utility Supply (m3) $/m3 | M1: Irrigation Water (m3) m3 | N1: Irrigation water $/m3 | O1: Room Nights
A2: Beirut | B2: 1 | C2: 10 | D2: 2019 | E2: =ELEC!N3 -> 30214 | F2: =SUM('EDl log'!T4) -> 0.10781691 | G2: =-tanks!AW6 -> 839.1 | H2: =SUM(tanks!AV6) -> 0.54 | I2: =('B5'!AU5)*0.51 -> 137.7 | J2: ='B5'!AX5/0.51 -> 1.372549 | K2: =WATER!I6 -> 132 | L2: =SUM(WATER!J6) -> 3.4928446 | M2: =WATER!Q6 -> 0 | N2: 0.6 | O2: =ELEC!B3 -> 158.999
A3: Beirut | B3: =B2+1 -> 2 | C3: 10 | D3: 2019 | E3: =ELEC!N4 -> 32504 | F3: =SUM('EDl log'!T5) -> 0.09055399 | G3: =-tanks!AW7 -> 802.6 | H3: =SUM(tanks!AV7) -> 0.54 | I3: =('B5'!AU6)*0.51 -> 122.4 | J3: ='B5'!AX6/0.51 -> 1.372549 | K3: =WATER!I7 -> 132 | L3: =SUM(WATER!J7) -> 3.4928446 | M3: =WATER!Q7 -> 0 | N3: 0.6 | O3: =ELEC!B4 -> 161.989
A4: Beirut | B4: =B3+1 -> 3 | C4: 10 | D4: 2019 | E4: =ELEC!N5 -> 29402 | F4: =SUM('EDl log'!T6) -> 0.1021838 | G4: =-tanks!AW8 -> 812.6 | H4: =SUM(tanks!AV8) -> 0.54 | I4: =('B5'!AU7)*0.51 -> 107.1 | J4: ='B5'!AX7/0.51 -> 1.372549 | K4: =WATER!I8 -> 185 | L4: =SUM(WATER!J8) -> 2.9677594 | M4: =WATER!Q8 -> 0 | N4: 0.6 | O4: =ELEC!B5 -> 188.991
A5: Beirut | B5: =B4+1 -> 4 | C5: 10 | D5: 2019 | E5: =ELEC!N6 -> 32164 | F5: =SUM('EDl log'!T7) -> 0.046038231 | G5: =-tanks!AW9 -> 932.5 | H5: =SUM(tanks!AV9) -> 0.54666 | I5: =('B5'!AU8)*0.51 -> 290.7 | J5: ='B5'!AX8/0.51 -> 1.372549 | K5: =WATER!I9 -> 306 | L5: =SUM(WATER!J9) -> 1.5121421 | M5: =WATER!Q9 -> 0 | N5: 0.6 | O5: =ELEC!B6 -> 191.82
A6: Beirut | B6: =B5+1 -> 5 | C6: 10 | D6: 2019 | E6: =ELEC!N7 -> 31146 | F6: =SUM('EDl log'!T8) -> 0.077974873 | G6: =-tanks!AW10 -> 1032.5 | H6: =SUM(tanks!AV10) -> 0.54666 | I6: =('B5'!AU9)*0.51 -> 229.5 | J6: ='B5'!AX9/0.51 -> 1.372549 | K6: =WATER!I10 -> 212 | L6: =SUM(WATER!J10) -> 2.8012051 | M6: =WATER!Q10 -> 0 | N6: 0.6 | O6: =ELEC!B7 -> 177.008
A7: Beirut | B7: =B6+1 -> 6 | C7: 10 | D7: 2019 | E7: =ELEC!N8 -> 26276.8 | F7: =SUM('EDl log'!T9) -> 0.075158299 | G7: =-tanks!AW11 -> 1043.2 | H7: =SUM(tanks!AV11) -> 0.54666 | I7: =('B5'!AU10)*0.51 -> 137.7 | J7: ='B5'!AX10/0.51 -> 1.372549 | K7: =WATER!I11 -> 325 | L7: =SUM(WATER!J11) -> 1.42374 | M7: =WATER!Q11 -> 0 | N7: 0.6 | O7: =ELEC!B8 -> 131.997
A8: Beirut | B8: =B7+1 -> 7 | C8: 10 | D8: 2019 | E8: =ELEC!N9 -> 29097.4 | F8: =SUM('EDl log'!T10) -> 0.079356749 | G8: =-tanks!AW12 -> 861.8 | H8: =SUM(tanks!AV12) -> 0.54666 | I8: =('B5'!AU11)*0.51 -> 183.6 | J8: ='B5'!AX11/0.51 -> 1.372549 | K8: =WATER!I12 -> 212 | L8: =SUM(WATER!J12) -> 2.8012051 | M8: =WATER!Q12 -> 0 | N8: 0.6 | O8: =ELEC!B9 -> 125.005
A9: Beirut | B9: =B8+1 -> 8 | C9: 10 | D9: 2019 | E9: =ELEC!N10 -> 28488.6 | F9: =SUM('EDl log'!T11) -> 0.075329674 | G9: =-tanks!AW13 -> 807.8 | H9: =SUM(tanks!AV13) -> 0.54666 | I9: =('B5'!AU12)*0.51 -> 122.4 | J9: ='B5'!AX12/0.51 -> 1.372549 | K9: =WATER!I13 -> 355 | L9: =SUM(WATER!J13) -> 1.5512549 | M9: =WATER!Q13 -> 0 | N9: 0.6 | O9: =ELEC!B10 -> 150.995
A10: Beirut | B10: =B9+1 -> 9 | C10: 10 | D10: 2019 | E10: =ELEC!N11 -> 30559.4 | F10: =SUM('EDl log'!T12) -> 0.07805182 | G10: =-tanks!AW14 -> 880.7 | H10: =SUM(tanks!AV14) -> 0.54666 | I10: =('B5'!AU13)*0.51 -> 107.1 | J10: ='B5'!AX13/0.51 -> 1.372549 | K10: =WATER!I14 -> 145 | L10: =SUM(WATER!J14) -> 3.1911413 | M10: =WATER!Q14 -> 0 | N10: 0.6 | O10: =ELEC!B11 -> 165.991
A11: Beirut | B11: =B10+1 -> 10 | C11: 10 | D11: 2019 | E11: =ELEC!N12 -> 34481.8 | F11: =SUM('EDl log'!T13) -> 0.079007137 | G11: =-tanks!AW15 -> 839.1 | H11: =SUM(tanks!AV15) -> 0.54666 | I11: =('B5'!AU14)*0.51 -> 122.4 | J11: ='B5'!AX14/0.51 -> 1.372549 | K11: =WATER!I15 -> 357 | L11: =SUM(WATER!J15) -> 1.5425644 | M11: =WATER!Q15 -> 0 | N11: 0.6 | O11: =ELEC!B12 -> 198.007
A12: Beirut | B12: =B11+1 -> 11 | C12: 10 | D12: 2019 | E12: =ELEC!N13 -> 30373.2 | F12: =SUM('EDl log'!T14) -> 0.047027516 | G12: =-tanks!AW16 -> 821.9 | H12: =SUM(tanks!AV16) -> 0.55 | I12: =('B5'!AU15)*0.51 -> 367.2 | J12: ='B5'!AX15/0.51 -> 1.372549 | K12: =WATER!I16 -> 132 | L12: =SUM(WATER!J16) -> 3.4928446 | M12: =WATER!Q16 -> 0 | N12: 0.6 | O12: =ELEC!B13 -> 194.994
A13: Beirut | B13: =B12+1 -> 12 | C13: 10 | D13: 2019 | E13: =ELEC!N14 -> 30850 | F13: =SUM('EDl log'!T15) -> 0.072366846 | G13: =-tanks!AW17 -> 844.2 | H13: =SUM(tanks!AV17) -> 0.55 | I13: =('B5'!AU16)*0.51 -> 76.5 | J13: ='B5'!AX16/0.51 -> 1.372549 | K13: =WATER!I17 -> 654 | L13: =SUM(WATER!J17) -> 0.36993193 | M13: =WATER!Q17 -> 0 | N13: 0.6 | O13: =ELEC!B14 -> 135.01
A14: Beirut | B14: =B13+1 -> 13 | C14: 10 | D14: 2019 | E14: =ELEC!N15 -> 30370.4 | F14: =SUM('EDl log'!T16) -> 0.0711857 | G14: =-tanks!AW18 -> 925.3 | H14: =SUM(tanks!AV18) -> 0.55 | I14: =('B5'!AU17)*0.51 -> 183.6 | J14: ='B5'!AX17/0.51 -> 1.372549 | K14: =WATER!I18 -> 133 | L14: =SUM(WATER!J18) -> 3.4790638 | M14: =WATER!Q18 -> 0 | N14: 0.6 | O14: =ELEC!B15 -> 121.003
... A32: Beirut | B32: =B31+1 -> 31 | C32: 10 | D32: 2019 | E32: =ELEC!N33 -> 0 | F32: =SUM('EDl log'!T34) -> 0 | G32: =-tanks!AW36 -> 0 | H32: =SUM(tanks!AV36) -> 0.55 | I32: =('B5'!AU35)*0.51 -> 0 | J32: ='B5'!AX35/0.51 -> 1.372549 | K32: =WATER!I36 -> 0 | L32: =SUM(WATER!J36) -> 0 | M32: =WATER!Q36 -> 0 | N32: 0.6 | O32: =ELEC!B33 -> 0

Sheet Submetering
A1: Site Name | B1: Day | C1: Month | D1: Year | E1: ATS1 Kwh | F1: ATS2 Kwh | G1: ATS3 Kwh | H1: ATS4 Kwh | I1: ATS5 Kwh | J1: Guest (m3) | K1: Kitchen & Laundry (m3) | L1: Room Nights
A2: Beirut | B2: 1 | C2: 10 | D2: 2019 | E2: =ELEC!M3 -> 5576 | F2: =ELEC!K3 -> 5414 | G2: =ELEC!I3 -> 4010 | H2: =ELEC!E3 -> 11780 | I2: =ELEC!G3 -> 3434 | J2: =WATER!Y6 -> 100 | K2: =WATER!AJ6 -> 48 | L2: =ELEC!B3 -> 158.999
A3: Beirut | B3: =B2+1 -> 2 | C3: 10 | D3: 2019 | E3: =ELEC!M4 -> 5830 | F3: =ELEC!K4 -> 6116 | G3: =ELEC!I4 -> 4362 | H3: =ELEC!E4 -> 12412 | I3: =ELEC!G4 -> 3784 | J3: =WATER!Y7 -> 25 | K3: =WATER!AJ7 -> 90 | L3: =ELEC!B4 -> 161.989
A4: Beirut | B4: =B3+1 -> 3 | C4: 10 | D4: 2019 | E4: =ELEC!M5 -> 5750 | F4: =ELEC!K5 -> 7216 | G4: =ELEC!I5 -> 4016 | H4: =ELEC!E5 -> 8900 | I4: =ELEC!G5 -> 3520 | J4: =WATER!Y8 -> 77 | K4: =WATER!AJ8 -> 102 | L4: =ELEC!B5 -> 188.991
A5: Beirut | B5: =B4+1 -> 4 | C5: 10 | D5: 2019 | E5: =ELEC!M6 -> 5848 | F5: =ELEC!K6 -> 5344 | G5: =ELEC!I6 -> 4342 | H5: =ELEC!E6 -> 12838 | I5: =ELEC!G6 -> 3792 | J5: =WATER!Y9 -> 136 | K5: =WATER!AJ9 -> 134 | L5: =ELEC!B6 -> 191.82
A6: Beirut | B6: =B5+1 -> 5 | C6: 10 | D6: 2019 | E6: =ELEC!M7 -> 5596 | F6: =ELEC!K7 -> 5198 | G6: =ELEC!I7 -> 4316 | H6: =ELEC!E7 -> 12226 | I6: =ELEC!G7 -> 3810 | J6: =WATER!Y10 -> 23 | K6: =WATER!AJ10 -> 97 | L6: =ELEC!B7 -> 177.008
A7: Beirut | B7: =B6+1 -> 6 | C7: 10 | D7: 2019 | E7: =ELEC!M8 -> 4540 | F7: =ELEC!K8 -> 4004 | G7: =ELEC!I8 -> 3684 | H7: =ELEC!E8 -> 10966 | I7: =ELEC!G8 -> 3082.8 | J7: =WATER!Y11 -> 88 | K7: =WATER!AJ11 -> 99 | L7: =ELEC!B8 -> 131.997
A8: Beirut | B8: =B7+1 -> 7 | C8: 10 | D8: 2019 | E8: =ELEC!M9 -> 5220 | F8: =ELEC!K9 -> 5526 | G8: =ELEC!I9 -> 4044 | H8: =ELEC!E9 -> 10792 | I8: =ELEC!G9 -> 3515.4 | J8: =WATER!Y12 -> 116 | K8: =WATER!AJ12 -> 34 | L8: =ELEC!B9 -> 125.005
A9: Beirut | B9: =B8+1 -> 8 | C9: 10 | D9: 2019 | E9: =ELEC!M10 -> 5216 | F9: =ELEC!K10 -> 3636 | G9: =ELEC!I10 -> 4056 | H9: =ELEC!E10 -> 12040 | I9: =ELEC!G10 -> 3540.6 | J9: =WATER!Y13 -> 97 | K9: =WATER!AJ13 -> 146 | L9: =ELEC!B10 -> 150.995
A10: Beirut | B10: =B9+1 -> 9 | C10: 10 | D10: 2019 | E10: =ELEC!M11 -> 7068 | F10: =ELEC!K11 -> 4976 | G10: =ELEC!I11 -> 4182 | H10: =ELEC!E11 -> 10628 | I10: =ELEC!G11 -> 3705.4 | J10: =WATER!Y14 -> 62 | K10: =WATER!AJ14 -> 119 | L10: =ELEC!B11 -> 165.991
A11: Beirut | B11: =B10+1 -> 10 | C11: 10 | D11: 2019 | E11: =ELEC!M12 -> 11152 | F11: =ELEC!K12 -> 4192 | G11: =ELEC!I12 -> 4536 | H11: =ELEC!E12 -> 10552 | I11: =ELEC!G12 -> 4049.8 | J11: =WATER!Y15 -> 107 | K11: =WATER!AJ15 -> 134 | L11: =ELEC!B12 -> 198.007
A12: Beirut | B12: =B11+1 -> 11 | C12: 10 | D12: 2019 | E12: =ELEC!M13 -> 6476 | F12: =ELEC!K13 -> 6918 | G12: =ELEC!I13 -> 4046 | H12: =ELEC!E13 -> 9476 | I12: =ELEC!G13 -> 3457.2 | J12: =WATER!Y16 -> 251 | K12: =WATER!AJ16 -> 103 | L12: =ELEC!B13 -> 194.994
A13: Beirut | B13: =B12+1 -> 12 | C13: 10 | D13: 2019 | E13: =ELEC!M14 -> 6960 | F13: =ELEC!K14 -> 8562 | G13: =ELEC!I14 -> 4318 | H13: =ELEC!E14 -> 7284 | I13: =ELEC!G14 -> 3726 | J13: =WATER!Y17 -> 80 | K13: =WATER!AJ17 -> 51 | L13: =ELEC!B14 -> 135.01
A14: Beirut | B14: =B13+1 -> 13 | C14: 10 | D14: 2019 | E14: =ELEC!M15 -> 11470 | F14: =ELEC!K15 -> 4040 | G14: =ELEC!I15 -> 4352 | H14: =ELEC!E15 -> 6856 | I14: =ELEC!G15 -> 3652.4 | J14: =WATER!Y18 -> 19 | K14: =WATER!AJ18 -> 76 | L14: =ELEC!B15 -> 121.003
... A32: Beirut | B32: =B31+1 -> 31 | C32: 10 | D32: 2019 | E32: =ELEC!M33 -> 0 | F32: =ELEC!K33 -> 0 | G32: =ELEC!I33 -> 0 | H32: =ELEC!E33 -> 0 | I32: =ELEC!G33 -> 0 | J32: =WATER!Y36 -> 0 | K32: =WATER!AJ36 -> 0 | L32: =ELEC!B33 -> 0

Sheet ELEC
A1: OOC | B1: Room OCC | D1: MDB3 | E1: MDB3/day | F1: EMDB2 | G1: EMDB2/day | H1: EMDB1 | I1: EMDB1/day | J1: MDB2 | K1: mdb2/day | L1: MDB1 | M1: MDB1/Day | N1: Total KWH | O1: KWH/Rooc | P1: Gen MHW | Q1: Gen/Day KWH | R1: EDL KWH | S1: CH1 RH | T1: RH | U1: C1h1 power | V1: CH1 Con KWH | W1: CH2 RH | X1: RH | Y1: Ch2 power | Z1: CH2 Con KWH | AA1: CH3 RH | AB1: RH | AC1: Ch3 power | AD1: CH3 Con KWH | AE1: RH total | AF1: KWH total | AG1: AVG chiller KW/Hr
A2: 0.7652 | B2: 175.996 | C2: 43738 | D2: 30782304 | E2: 13854 | F2: 3199141 | G2: 3784.8 | H2: 16972776 | I2: 4402 | J2: 27970652 | K2: 5446 | L2: 22059422 | M2: 6092 | N2: 33578.8 | O2: 226.87612 | P2: 14905.282 | Q2: 10578 | R2: 23000.8 | S2: 7954 | T2: 0 | U2: 931661 | V2: 0 | W2: 31411 | X2: 10 | Y2: 534793 | Z2: 2196 | AA2: 34291 | AB2: 24 | AC2: 613447 | AD2: 5698 | AE2: 34 | AF2: 7894 | AG2: 232.17647 | AH2: 0 | AI2: -47568596
A3: ='General information '!F6 -> 0.6913 | B3: =SUM(230*A3) -> 158.999 | C3: 43739 | D3: 30794084 | E3: =D3-D2 -> 11780 | F3: 3202575 | G3: =F3-F2 -> 3434 | H3: 16976786 | I3: =H3-H2 -> 4010 | J3: 27976066 | K3: =J3-J2 -> 5414 | L3: 22064998 | M3: =L3-L2 -> 5576 | N3: =M3+K3+I3+G3+E3 -> 30214 | O3: =IF(B3>0,N3/B3,0) -> 190.02635 | P3: 14915.716 | Q3: =(P3-P2)*1000 -> 10434 | R3: =+N3-Q3 -> 19780 | S3: 7954 | T3: =S3-S2 -> 0 | U3: 931661 | V3: =U3-U2 -> 0 | W3: 31421 | X3: =W3-W2 -> 10 | Y3: 537236 | Z3: =Y3-Y2 -> 2443 | AA3: 34310 | AB3: =AA3-AA2 -> 19 | AC3: 618417 | AD3: =AC3-AC2 -> 4970 | AE3: =AB3+X3+T3 -> 29 | AF3: =V3+Z3+AD3 -> 7413 | AG3: =IF(AE3>0,AF3/AE3,0) -> 255.62069
A4: ='General information '!F7 -> 0.7043 | B4: =SUM(230*A4) -> 161.989 | C4: 43740 | D4: 30806496 | E4: =D4-D3 -> 12412 | F4: 3206359 | G4: =F4-F3 -> 3784 | H4: 16981148 | I4: =H4-H3 -> 4362 | J4: 27982182 | K4: =J4-J3 -> 6116 | L4: 22070828 | M4: =L4-L3 -> 5830 | N4: =M4+K4+I4+G4+E4 -> 32504 | O4: =IF(B4>0,N4/B4,0) -> 200.6556 | P4: 14926 | Q4: =(P4-P3)*1000 -> 10284 | R4: =N4-Q4 -> 22220 | S4: =S3 -> 7954 | T4: =S4-S3 -> 0 | U4: =U3 -> 931661 | V4: =U4-U3 -> 0 | W4: 31432 | X4: =W4-W3 -> 11 | Y4: 539496 | Z4: =Y4-Y3 -> 2260 | AA4: 34332 | AB4: =AA4-AA3 -> 22 | AC4: 623604 | AD4: =AC4-AC3 -> 5187 | AE4: =AB4+X4+T4 -> 33 | AF4: =V4+Z4+AD4 -> 7447 | AG4: =IF(AE4>0,AF4/AE4,0) -> 225.66667
A5: ='General information '!F8 -> 0.8217 | B5: =SUM(230*A5) -> 188.991 | C5: 43741 | D5: 30815396 | E5: =D5-D4 -> 8900 | F5: 3209879 | G5: =F5-F4 -> 3520 | H5: 16985164 | I5: =H5-H4 -> 4016 | J5: 27989398 | K5: =J5-J4 -> 7216 | L5: 22076578 | M5: =L5-L4 -> 5750 | N5: =M5+K5+I5+G5+E5 -> 29402 | O5: =IF(B5>0,N5/B5,0) -> 155.57355 | P5: 14937.113 | Q5: =(P5-P4)*1000 -> 11113 | R5: =N5-Q5 -> 18289 | S5: =S4 -> 7954 | T5: =S5-S4 -> 0 | U5: =U4 -> 931661 | V5: =U5-U4 -> 0 | W5: 31452 | X5: =W5-W4 -> 20 | Y5: 544350 | Z5: =Y5-Y4 -> 4854 | AA5: 34340 | AB5: =AA5-AA4 -> 8 | AC5: 625359 | AD5: =AC5-AC4 -> 1755 | AE5: =AB5+X5+T5 -> 28 | AF5: =V5+Z5+AD5 -> 6609 | AG5: =IF(AE5>0,AF5/AE5,0) -> 236.03571 | AI5: =R5-'EDl log'!B3 -> -48526813
A6: ='General information '!F9 -> 0.834 | B6: =SUM(230*A6) -> 191.82 | C6: 43742 | D6: 30828234 | E6: =D6-D5 -> 12838 | F6: 3213671 | G6: =F6-F5 -> 3792 | H6: 16989506 | I6: =H6-H5 -> 4342 | J6: 27994742 | K6: =J6-J5 -> 5344 | L6: 22082426 | M6: =L6-L5 -> 5848 | N6: =M6+K6+I6+G6+E6 -> 32164 | O6: =IF(B6>0,N6/B6,0) -> 167.67803 | P6: 14944.5 | Q6: =(P6-P5)*1000 -> 7387 | R6: =N6-Q6 -> 24777 | S6: =S5 -> 7954 | T6: =S6-S5 -> 0 | U6: 931661 | V6: =U6-U5 -> 0 | W6: 31463 | X6: =W6-W5 -> 11 | Y6: 546324 | Z6: =Y6-Y5 -> 1974 | AA6: 34363 | AB6: =AA6-AA5 -> 23 | AC6: 630287 | AD6: =AC6-AC5 -> 4928 | AE6: =AB6+X6+T6 -> 34 | AF6: =V6+Z6+AD6 -> 6902 | AG6: =IF(AE6>0,AF6/AE6,0) -> 203 | AI6: =R6-'EDl log'!B4 -> -48530520
A7: ='General information '!F10 -> 0.7696 | B7: =SUM(230*A7) -> 177.008 | C7: 43743 | D7: 30840460 | E7: =D7-D6 -> 12226 | F7: 3217481 | G7: =F7-F6 -> 3810 | H7: 16993822 | I7: =H7-H6 -> 4316 | J7: 27999940 | K7: =J7-J6 -> 5198 | L7: 22088022 | M7: =L7-L6 -> 5596 | N7: =M7+K7+I7+G7+E7 -> 31146 | O7: =IF(B7>0,N7/B7,0) -> 175.95815 | P7: 14949.3 | Q7: =(P7-P6)*1000 -> 4800 | R7: =N7-Q24 -> 31146 | S7: =S6 -> 7954 | T7: =S7-S6 -> 0 | U7: =U6 -> 931661 | V7: =U7-U6 -> 0 | W7: 31472 | X7: =W7-W6 -> 9 | Y7: 548371 | Z7: =Y7-Y6 -> 2047 | AA7: 34384 | AB7: =AA7-AA6 -> 21 | AC7: 635089 | AD7: =AC7-AC6 -> 4802 | AE7: =AB7+X7+T7 -> 30 | AF7: =V7+Z7+AD7 -> 6849 | AG7: =IF(AE7>0,AF7/AE7,0) -> 228.3 | AI7: =R7-'EDl log'!B5 -> -48535368
A8: ='General information '!F11 -> 0.5739 | B8: =SUM(230*A8) -> 131.997 | C8: 43744 | D8: 30851426 | E8: =D8-D7 -> 10966 | F8: 3220563.8 | G8: =F8-F7 -> 3082.8 | H8: 16997506 | I8: =H8-H7 -> 3684 | J8: 28003944 | K8: =J8-J7 -> 4004 | L8: 22092562 | M8: =L8-L7 -> 4540 | N8: =M8+K8+I8+G8+E8 -> 26276.8 | O8: =IF(B8>0,N8/B8,0) -> 199.07119 | P8: 14953.444 | Q8: =(P8-P7)*1000 -> 4144 | R8: =N8-Q8 -> 22132.8 | S8: =S7 -> 7954 | T8: =S8-S7 -> 0 | U8: =U7 -> 931661 | V8: =U8-U7 -> 0 | W8: 31481 | X8: =W8-W7 -> 9 | Y8: 549937 | Z8: =Y8-Y7 -> 1566 | AA8: 34408 | AB8: =AA8-AA7 -> 24 | AC8: 640293 | AD8: =AC8-AC7 -> 5204 | AE8: =AB8+X8+T8 -> 33 | AF8: =V8+Z8+AD8 -> 6770 | AG8: =IF(AE8>0,AF8/AE8,0) -> 205.15152 | AI8: =R8-'EDl log'!B6 -> -48554069
A9: ='General information '!F12 -> 0.5435 | B9: =SUM(230*A9) -> 125.005 | C9: 43745 | D9: 30862218 | E9: =D9-D8 -> 10792 | F9: 3224079.2 | G9: =F9-F8 -> 3515.4 | H9: 17001550 | I9: =H9-H8 -> 4044 | J9: 28009470 | K9: =J9-J8 -> 5526 | L9: 22097782 | M9: =L9-L8 -> 5220 | N9: =M9+K9+I9+G9+E9 -> 29097.4 | O9: =IF(B9>0,N9/B9,0) -> 232.76989 | P9: 14958.183 | Q9: =(P9-P8)*1000 -> 4739 | R9: =N9-Q9 -> 24358.4 | S9: =S8 -> 7954 | T9: =S9-S8 -> 0 | U9: =U8 -> 931661 | V9: =U9-U8 -> 0 | W9: 31492 | X9: =W9-W8 -> 11 | Y9: 552458 | Z9: =Y9-Y8 -> 2521 | AA9: 34426 | AB9: =AA9-AA8 -> 18 | AC9: 644100 | AD9: =AC9-AC8 -> 3807 | AE9: =AB9+X9+T9 -> 29 | AF9: =V9+Z9+AD9 -> 6328 | AG9: =IF(AE9>0,AF9/AE9,0) -> 218.2069 | AI9: =R9-'EDl log'!B7 -> -48564582
A10: ='General information '!F13 -> 0.6565 | B10: =SUM(230*A10) -> 150.995 | C10: 43746 | D10: 30874258 | E10: =D10-D9 -> 12040 | F10: 3227619.8 | G10: =F10-F9 -> 3540.6 | H10: 17005606 | I10: =H10-H9 -> 4056 | J10: 28013106 | K10: =J10-J9 -> 3636 | L10: 22102998 | M10: =L10-L9 -> 5216 | N10: =M10+K10+I10+G10+E10 -> 28488.6 | O10: =IF(B10>0,N10/B10,0) -> 188.67247 | P10: 14962.741 | Q10: =(P10-P9)*1000 -> 4558 | R10: =N10-Q10 -> 23930.6 | S10: =S9 -> 7954 | T10: =S10-S9 -> 0 | U10: =U9 -> 931661 | V10: =U10-U9 -> 0 | W10: 31496 | X10: =W10-W9 -> 4 | Y10: 553173 | Z10: =Y10-Y9 -> 715 | AA10: 34450 | AB10: =AA10-AA9 -> 24 | AC10: 649709 | AD10: =AC10-AC9 -> 5609 | AE10: =AB10+X10+T10 -> 28 | AF10: =V10+Z10+AD10 -> 6324 | AG10: =IF(AE10>0,AF10/AE10,0) -> 225.85714 | AI10: =R10-'EDl log'!B8 -> -48578669
A11: ='General information '!F14 -> 0.7217 | B11: =SUM(230*A11) -> 165.991 | C11: 43747 | D11: 30884886 | E11: =D11-D10 -> 10628 | F11: 3231325.2 | G11: =F11-F10 -> 3705.4 | H11: 17009788 | I11: =H11-H10 -> 4182 | J11: 28018082 | K11: =J11-J10 -> 4976 | L11: 22110066 | M11: =L11-L10 -> 7068 | N11: =M11+K11+I11+G11+E11 -> 30559.4 | O11: =IF(B11>0,N11/B11,0) -> 184.10275 | P11: 14967.167 | Q11: =(P11-P10)*1000 -> 4426 | R11: =N11-Q11 -> 26133.4 | S11: 7962 | T11: =S11-S10 -> 8 | U11: 933540 | V11: =U11-U10 -> 1879 | W11: 31505 | X11: =W11-W10 -> 9 | Y11: 555087 | Z11: =Y11-Y10 -> 1914 | AA11: 34466 | AB11: =AA11-AA10 -> 16 | AC11: 653590 | AD11: =AC11-AC10 -> 3881 | AE11: =AB11+X11+T11 -> 33 | AF11: =V11+Z11+AD11 -> 7674 | AG11: =IF(AE11>0,AF11/AE11,0) -> 232.54545 | AI11: =R11-'EDl log'!B9 -> -48587708
A12: ='General information '!F15 -> 0.8609 | B12: =SUM(230*A12) -> 198.007 | C12: 43748 | D12: 30895438 | E12: =D12-D11 -> 10552 | F12: 3235375 | G12: =F12-F11 -> 4049.8 | H12: 17014324 | I12: =H12-H11 -> 4536 | J12: 28022274 | K12: =J12-J11 -> 4192 | L12: 22121218 | M12: =L12-L11 -> 11152 | N12: =M12+K12+I12+G12+E12 -> 34481.8 | O12: =IF(B12>0,N12/B12,0) -> 174.14435 | P12: 14976.67 | Q12: =(P12-P11)*1000 -> 9503 | R12: =N12-Q12 -> 24978.8 | S12: 7981 | T12: =S12-S11 -> 19 | U12: 937922 | V12: =U12-U11 -> 4382 | W12: 31509 | X12: =W12-W11 -> 4 | Y12: 555980 | Z12: =Y12-Y11 -> 893 | AA12: 34480 | AB12: =AA12-AA11 -> 14 | AC12: 656281 | AD12: =AC12-AC11 -> 2691 | AE12: =AB12+X12+T12 -> 37 | AF12: =V12+Z12+AD12 -> 7966 | AG12: =IF(AE12>0,AF12/AE12,0) -> 215.2973 | AI12: =R12-'EDl log'!B10 -> -48601367
A13: ='General information '!F16 -> 0.8478 | B13: =SUM(230*A13) -> 194.994 | C13: 43749 | D13: 30904914 | E13: =D13-D12 -> 9476 | F13: 3238832.2 | G13: =F13-F12 -> 3457.2 | H13: 17018370 | I13: =H13-H12 -> 4046 | J13: 28029192 | K13: =J13-J12 -> 6918 | L13: 22127694 | M13: =L13-L12 -> 6476 | N13: =M13+K13+I13+G13+E13 -> 30373.2 | O13: =IF(B13>0,N13/B13,0) -> 155.76479 | P13: 14987.311 | Q13: =(P13-P12)*1000 -> 10641 | R13: =N13-Q13 -> 19732.2 | S13: 7988 | T13: =S13-S12 -> 7 | U13: 939330 | V13: =U13-U12 -> 1408 | W13: 31527 | X13: =W13-W12 -> 18 | Y13: 559535 | Z13: =Y13-Y12 -> 3555 | AA13: 34491 | AB13: =AA13-AA12 -> 11 | AC13: 658290 | AD13: =AC13-AC12 -> 2009 | AE13: =AB13+X13+T13 -> 36 | AF13: =V13+Z13+AD13 -> 6972 | AG13: =IF(AE13>0,AF13/AE13,0) -> 193.66667 | AI13: =R13-'EDl log'!B11 -> -48618904
A14: ='General information '!F17 -> 0.587 | B14: =SUM(230*A14) -> 135.01 | C14: 43750 | D14: 30912198 | E14: =D14-D13 -> 7284 | F14: 3242558.2 | G14: =F14-F13 -> 3726 | H14: 17022688 | I14: =H14-H13 -> 4318 | J14: 28037754 | K14: =J14-J13 -> 8562 | L14: 22134654 | M14: =L14-L13 -> 6960 | N14: =M14+K14+I14+G14+E14 -> 30850 | O14: =IF(B14>0,N14/B14,0) -> 228.50159 | P14: 14991.858 | Q14: =(P14-P13)*1000 -> 4547 | R14: =N14-Q14 -> 26303 | S14: 7994 | T14: =S14-S13 -> 6 | U14: 940660 | V14: =U14-U13 -> 1330 | W14: 31549 | X14: =W14-W13 -> 22 | Y14: 564560 | Z14: =Y14-Y13 -> 5025 | AA14: 34492 | AB14: =AA14-AA13 -> 1 | AC14: 658475 | AD14: =AC14-AC13 -> 185 | AE14: =AB14+X14+T14 -> 29 | AF14: =V14+Z14+AD14 -> 6540 | AG14: =IF(AE14>0,AF14/AE14,0) -> 225.51724 | AI14: =R14-'EDl log'!B12 -> -48625713
A15: ='General information '!F18 -> 0.5261 | B15: =SUM(230*A15) -> 121.003 | C15: 43751 | D15: 30919054 | E15: =D15-D14 -> 6856 | F15: 3246210.6 | G15: =F15-F14 -> 3652.4 | H15: 17027040 | I15: =H15-H14 -> 4352 | J15: 28041794 | K15: =J15-J14 -> 4040 | L15: 22146124 | M15: =L15-L14 -> 11470 | N15: =M15+K15+I15+G15+E15 -> 30370.4 | O15: =IF(B15>0,N15/B15,0) -> 250.98882 | P15: 14995.875 | Q15: =(P15-P14)*1000 -> 4017 | R15: =N15-Q15 -> 26353.4 | S15: 8019 | T15: =S15-S14 -> 25 | U15: 946922 | V15: =U15-U14 -> 6262 | W15: 31555 | X15: =W15-W14 -> 6 | Y15: 565780 | Z15: =Y15-Y14 -> 1220 | AA15: =AA14 -> 34492 | AB15: =AA15-AA14 -> 0 | AC15: =AC14 -> 658475 | AD15: =AC15-AC14 -> 0 | AE15: =AB15+X15+T15 -> 31 | AF15: =V15+Z15+AD15 -> 7482 | AG15: =IF(AE15>0,AF15/AE15,0) -> 241.35484 | AI15: =R15-'EDl log'!B13 -> -48638573
A16: ='General information '!F19 -> 0.5826 | B16: =SUM(230*A16) -> 133.998 | C16: 43752 | D16: 30926498 | E16: =D16-D15 -> 7444 | F16: 3249618 | G16: =F16-F15 -> 3407.4 | H16: 17031052 | I16: =H16-H15 -> 4012 | J16: 28048670 | K16: =J16-J15 -> 6876 | L16: 22153700 | M16: =L16-L15 -> 7576 | N16: =M16+K16+I16+G16+E16 -> 29315.4 | O16: =IF(B16>0,N16/B16,0) -> 218.77491 | P16: 15007.06 | Q16: =(P16-P15)*1000 -> 11185 | R16: =N16-Q16 -> 18130.4 | S16: 8031 | T16: =S16-S15 -> 12 | U16: 949426 | V16: =U16-U15 -> 2504 | W16: 31574 | X16: =W16-W15 -> 19 | Y16: 569805 | Z16: =Y16-Y15 -> 4025 | AA16: 34492 | AB16: =AA16-AA15 -> 0 | AC16: 658787 | AD16: =AC16-AC15 -> 312 | AE16: =AB16+X16+T16 -> 31 | AF16: =V16+Z16+AD16 -> 6841 | AG16: =IF(AE16>0,AF16/AE16,0) -> 220.67742 | AI16: =R16-'EDl log'!B14 -> -48657029
A17: ='General information '!F20 -> 0 | B17: =SUM(230*A17) -> 0 | C17: 43753 | D17: =D16 -> 30926498 | E17: =D17-D16 -> 0 | F17: =F16 -> 3249618 | G17: =F17-F16 -> 0 | H17: =H16 -> 17031052 | I17: =H17-H16 -> 0 | J17: =J16 -> 28048670 | K17: =J17-J16 -> 0 | L17: =L16 -> 22153700 | M17: =L17-L16 -> 0 | N17: =M17+K17+I17+G17+E17 -> 0 | O17: =IF(B17>0,N17/B17,0) -> 0 | P17: =P16 -> 15007.06 | Q17: =(P17-P16)*1000 -> 0 | R17: =N17-Q17 -> 0 | S17: =S16 -> 8031 | T17: =S17-S16 -> 0 | U17: =U16 -> 949426 | V17: =U17-U16 -> 0 | W17: =W16 -> 31574 | X17: =W17-W16 -> 0 | Y17: =Y16 -> 569805 | Z17: =Y17-Y16 -> 0 | AA17: =AA16 -> 34492 | AB17: =AA17-AA16 -> 0 | AC17: =AC16 -> 658787 | AD17: =AC17-AC16 -> 0 | AE17: =AB17+X17+T17 -> 0 | AF17: =V17+Z17+AD17 -> 0 | AG17: =IF(AE17>0,AF17/AE17,0) -> 0 | AI17: =R17-'EDl log'!B15 -> -48688662
A18: ='General information '!F21 -> 0 | B18: =SUM(230*A18) -> 0 | C18: 43754 | D18: =D17 -> 30926498 | E18: =D18-D17 -> 0 | F18: =F17 -> 3249618 | G18: =F18-F17 -> 0 | H18: =H17 -> 17031052 | I18: =H18-H17 -> 0 | J18: =J17 -> 28048670 | K18: =J18-J17 -> 0 | L18: =L17 -> 22153700 | M18: =L18-L17 -> 0 | N18: =M18+K18+I18+G18+E18 -> 0 | O18: =IF(B18>0,N18/B18,0) -> 0 | P18: =P17 -> 15007.06 | Q18: =(P18-P17)*1000 -> 0 | R18: =N18-Q18 -> 0 | S18: =S17 -> 8031 | T18: =S18-S17 -> 0 | U18: =U17 -> 949426 | V18: =U18-U17 -> 0 | W18: =W17 -> 31574 | X18: =W18-W17 -> 0 | Y18: =Y17 -> 569805 | Z18: =Y18-Y17 -> 0 | AA18: =AA17 -> 34492 | AB18: =AA18-AA17 -> 0 | AC18: =AC17 -> 658787 | AD18: =AC18-AC17 -> 0 | AE18: =AB18+X18+T18 -> 0 | AF18: =V18+Z18+AD18 -> 0 | AG18: =IF(AE18>0,AF18/AE18,0) -> 0 | AI18: =R18-'EDl log'!B16 -> -48702158
A19: ='General information '!F22 -> 0 | B19: =SUM(230*A19) -> 0 | C19: 43755 | D19: =D18 -> 30926498 | E19: =D19-D18 -> 0 | F19: =F18 -> 3249618 | G19: =F19-F18 -> 0 | H19: =H18 -> 17031052 | I19: =H19-H18 -> 0 | J19: =J18 -> 28048670 | K19: =J19-J18 -> 0 | L19: =L18 -> 22153700 | M19: =L19-L18 -> 0 | N19: =M19+K19+I19+G19+E19 -> 0 | O19: =IF(B19>0,N19/B19,0) -> 0 | P19: =P18 -> 15007.06 | Q19: =(P19-P18)*1000 -> 0 | R19: =N19-Q19 -> 0 | S19: =S18 -> 8031 | T19: =S19-S18 -> 0 | U19: =U18 -> 949426 | V19: =U19-U18 -> 0 | W19: =W18 -> 31574 | X19: =W19-W18 -> 0 | Y19: =Y18 -> 569805 | Z19: =Y19-Y18 -> 0 | AA19: =AA18 -> 34492 | AB19: =AA19-AA18 -> 0 | AC19: =AC18 -> 658787 | AD19: =AC19-AC18 -> 0 | AE19: =AB19+X19+T19 -> 0 | AF19: =V19+Z19+AD19 -> 0 | AG19: =IF(AE19>0,AF19/AE19,0) -> 0 | AI19: =R19-'EDl log'!B17 -> -48711532
A20: ='General information '!F23 -> 0 | B20: =SUM(230*A20) -> 0 | C20: 43756 | D20: =D19 -> 30926498 | E20: =D20-D19 -> 0 | F20: =F19 -> 3249618 | G20: =F20-F19 -> 0 | H20: =H19 -> 17031052 | I20: =H20-H19 -> 0 | J20: =J19 -> 28048670 | K20: =J20-J19 -> 0 | L20: =L19 -> 22153700 | M20: =L20-L19 -> 0 | N20: =M20+K20+I20+G20+E20 -> 0 | O20: =IF(B20>0,N20/B20,0) -> 0 | P20: =P19 -> 15007.06 | Q20: =(P20-P19)*1000 -> 0 | R20: =N20-Q20 -> 0 | S20: =S19 -> 8031 | T20: =S20-S19 -> 0 | U20: =U19 -> 949426 | V20: =U20-U19 -> 0 | W20: =W19 -> 31574 | X20: =W20-W19 -> 0 | Y20: =Y19 -> 569805 | Z20: =Y20-Y19 -> 0 | AA20: =AA19 -> 34492 | AB20: =AA20-AA19 -> 0 | AC20: =AC19 -> 658787 | AD20: =AC20-AC19 -> 0 | AE20: =AB20+X20+T20 -> 0 | AF20: =V20+Z20+AD20 -> 0 | AG20: =IF(AE20>0,AF20/AE20,0) -> 0 | AI20: =R20-'EDl log'!B18 -> -48711532
A21: ='General information '!F24 -> 0 | B21: =SUM(230*A21) -> 0 | C21: 43757 | D21: =D20 -> 30926498 | E21: =D21-D20 -> 0 | F21: =F20 -> 3249618 | G21: =F21-F20 -> 0 | H21: =H20 -> 17031052 | I21: =H21-H20 -> 0 | J21: =J20 -> 28048670 | K21: =J21-J20 -> 0 | L21: =L20 -> 22153700 | M21: =L21-L20 -> 0 | N21: =M21+K21+I21+G21+E21 -> 0 | O21: =IF(B21>0,N21/B21,0) -> 0 | P21: =P20 -> 15007.06 | Q21: =(P21-P20)*1000 -> 0 | R21: =N21-Q21 -> 0 | S21: =S20 -> 8031 | T21: =S21-S20 -> 0 | U21: =U20 -> 949426 | V21: =U21-U20 -> 0 | W21: =W20 -> 31574 | X21: =W21-W20 -> 0 | Y21: =Y20 -> 569805 | Z21: =Y21-Y20 -> 0 | AA21: =AA20 -> 34492 | AB21: =AA21-AA20 -> 0 | AC21: =AC20 -> 658787 | AD21: =AC21-AC20 -> 0 | AE21: =AB21+X21+T21 -> 0 | AF21: =V21+Z21+AD21 -> 0 | AG21: =IF(AE21>0,AF21/AE21,0) -> 0 | AI21: =R21-'EDl log'!B19 -> -48711532
A22: ='General information '!F25 -> 0 | B22: =SUM(230*A22) -> 0 | C22: 43758 | D22: =D21 -> 30926498 | E22: =D22-D21 -> 0 | F22: =F21 -> 3249618 | G22: =F22-F21 -> 0 | H22: =H21 -> 17031052 | I22: =H22-H21 -> 0 | J22: =J21 -> 28048670 | K22: =J22-J21 -> 0 | L22: =L21 -> 22153700 | M22: =L22-L21 -> 0 | N22: =M22+K22+I22+G22+E22 -> 0 | O22: =IF(B22>0,N22/B22,0) -> 0 | P22: =P21 -> 15007.06 | Q22: =(P22-P21)*1000 -> 0 | R22: =N22-Q22 -> 0 | S22: =S21 -> 8031 | T22: =S22-S21 -> 0 | U22: =U21 -> 949426 | V22: =U22-U21 -> 0 | W22: =W21 -> 31574 | X22: =W22-W21 -> 0 | Y22: =Y21 -> 569805 | Z22: =Y22-Y21 -> 0 | AA22: =AA21 -> 34492 | AB22: =AA22-AA21 -> 0 | AC22: =AC21 -> 658787 | AD22: =AC22-AC21 -> 0 | AE22: =AB22+X22+T22 -> 0 | AF22: =V22+Z22+AD22 -> 0 | AG22: =IF(AE22>0,AF22/AE22,0) -> 0 | AI22: =R22-'EDl log'!B20 -> -48711532
A23: ='General information '!F26 -> 0 | B23: =SUM(230*A23) -> 0 | C23: 43759 | D23: =D22 -> 30926498 | E23: =D23-D22 -> 0 | F23: =F22 -> 3249618 | G23: =F23-F22 -> 0 | H23: =H22 -> 17031052 | I23: =H23-H22 -> 0 | J23: =J22 -> 28048670 | K23: =J23-J22 -> 0 | L23: =L22 -> 22153700 | M23: =L23-L22 -> 0 | N23: =M23+K23+I23+G23+E23 -> 0 | O23: =IF(B23>0,N23/B23,0) -> 0 | P23: =P22 -> 15007.06 | Q23: =(P23-P22)*1000 -> 0 | R23: =N23-Q23 -> 0 | S23: =S22 -> 8031 | T23: =S23-S22 -> 0 | U23: =U22 -> 949426 | V23: =U23-U22 -> 0 | W23: =W22 -> 31574 | X23: =W23-W22 -> 0 | Y23: =Y22 -> 569805 | Z23: =Y23-Y22 -> 0 | AA23: =AA22 -> 34492 | AB23: =AA23-AA22 -> 0 | AC23: =AC22 -> 658787 | AD23: =AC23-AC22 -> 0 | AE23: =AB23+X23+T23 -> 0 | AF23: =V23+Z23+AD23 -> 0 | AG23: =IF(AE23>0,AF23/AE23,0) -> 0 | AI23: =R23-'EDl log'!B21 -> -48711532
A24: ='General information '!F27 -> 0 | B24: =SUM(230*A24) -> 0 | C24: 43760 | D24: =D23 -> 30926498 | E24: =D24-D23 -> 0 | F24: =F23 -> 3249618 | G24: =F24-F23 -> 0 | H24: =H23 -> 17031052 | I24: =H24-H23 -> 0 | J24: =J23 -> 28048670 | K24: =J24-J23 -> 0 | L24: =L23 -> 22153700 | M24: =L24-L23 -> 0 | N24: =M24+K24+I24+G24+E24 -> 0 | O24: =IF(B24>0,N24/B24,0) -> 0 | P24: =P23 -> 15007.06 | Q24: =(P24-P23)*1000 -> 0 | R24: =N24-Q24 -> 0 | S24: =S23 -> 8031 | T24: =S24-S23 -> 0 | U24: =U23 -> 949426 | V24: =U24-U23 -> 0 | W24: =W23 -> 31574 | X24: =W24-W23 -> 0 | Y24: =Y23 -> 569805 | Z24: =Y24-Y23 -> 0 | AA24: =AA23 -> 34492 | AB24: =AA24-AA23 -> 0 | AC24: =AC23 -> 658787 | AD24: =AC24-AC23 -> 0 | AE24: =AB24+X24+T24 -> 0 | AF24: =V24+Z24+AD24 -> 0 | AG24: =IF(AE24>0,AF24/AE24,0) -> 0 | AI24: =R24-'EDl log'!B22 -> -48711532
A25: ='General information '!F28 -> 0 | B25: =SUM(230*A25) -> 0 | C25: 43761 | D25: =D24 -> 30926498 | E25: =D25-D24 -> 0 | F25: =F24 -> 3249618 | G25: =F25-F24 -> 0 | H25: =H24 -> 17031052 | I25: =H25-H24 -> 0 | J25: =J24 -> 28048670 | K25: =J25-J24 -> 0 | L25: =L24 -> 22153700 | M25: =L25-L24 -> 0 | N25: =M25+K25+I25+G25+E25 -> 0 | O25: =IF(B25>0,N25/B25,0) -> 0 | P25: =P24 -> 15007.06 | Q25: =(P25-P24)*1000 -> 0 | R25: =N25-Q25 -> 0 | S25: =S24 -> 8031 | T25: =S25-S24 -> 0 | U25: =U24 -> 949426 | V25: =U25-U24 -> 0 | W25: =W24 -> 31574 | X25: =W25-W24 -> 0 | Y25: =Y24 -> 569805 | Z25: =Y25-Y24 -> 0 | AA25: =AA24 -> 34492 | AB25: =AA25-AA24 -> 0 | AC25: =AC24 -> 658787 | AD25: =AC25-AC24 -> 0 | AE25: =AB25+X25+T25 -> 0 | AF25: =V25+Z25+AD25 -> 0 | AG25: =IF(AE25>0,AF25/AE25,0) -> 0 | AI25: =R25-'EDl log'!B23 -> -48711532
A26: ='General information '!F29 -> 0 | B26: =SUM(230*A26) -> 0 | C26: 43762 | D26: =D25 -> 30926498 | E26: =D26-D25 -> 0 | F26: =F25 -> 3249618 | G26: =F26-F25 -> 0 | H26: =H25 -> 17031052 | I26: =H26-H25 -> 0 | J26: =J25 -> 28048670 | K26: =J26-J25 -> 0 | L26: =L25 -> 22153700 | M26: =L26-L25 -> 0 | N26: =M26+K26+I26+G26+E26 -> 0 | O26: =IF(B26>0,N26/B26,0) -> 0 | P26: =P25 -> 15007.06 | Q26: =(P26-P25)*1000 -> 0 | R26: =N26-Q26 -> 0 | S26: =S25 -> 8031 | T26: =S26-S25 -> 0 | U26: =U25 -> 949426 | V26: =U26-U25 -> 0 | W26: =W25 -> 31574 | X26: =W26-W25 -> 0 | Y26: =Y25 -> 569805 | Z26: =Y26-Y25 -> 0 | AA26: =AA25 -> 34492 | AB26: =AA26-AA25 -> 0 | AC26: =AC25 -> 658787 | AD26: =AC26-AC25 -> 0 | AE26: =AB26+X26+T26 -> 0 | AF26: =V26+Z26+AD26 -> 0 | AG26: =IF(AE26>0,AF26/AE26,0) -> 0 | AI26: =R26-'EDl log'!B24 -> -48711532
A27: ='General information '!F30 -> 0 | B27: =SUM(230*A27) -> 0 | C27: 43763 | D27: =D26 -> 30926498 | E27: =D27-D26 -> 0 | F27: =F26 -> 3249618 | G27: =F27-F26 -> 0 | H27: =H26 -> 17031052 | I27: =H27-H26 -> 0 | J27: =J26 -> 28048670 | K27: =J27-J26 -> 0 | L27: =L26 -> 22153700 | M27: =L27-L26 -> 0 | N27: =M27+K27+I27+G27+E27 -> 0 | O27: =IF(B27>0,N27/B27,0) -> 0 | P27: =P26 -> 15007.06 | Q27: =(P27-P26)*1000 -> 0 | R27: =N27-Q27 -> 0 | S27: =S26 -> 8031 | T27: =S27-S26 -> 0 | U27: =U26 -> 949426 | V27: =U27-U26 -> 0 | W27: =W26 -> 31574 | X27: =W27-W26 -> 0 | Y27: =Y26 -> 569805 | Z27: =Y27-Y26 -> 0 | AA27: =AA26 -> 34492 | AB27: =AA27-AA26 -> 0 | AC27: =AC26 -> 658787 | AD27: =AC27-AC26 -> 0 | AE27: =AB27+X27+T27 -> 0 | AF27: =V27+Z27+AD27 -> 0 | AG27: =IF(AE27>0,AF27/AE27,0) -> 0 | AI27: =R27-'EDl log'!B25 -> -48711532
A28: ='General information '!F31 -> 0 | B28: =SUM(230*A28) -> 0 | C28: 43764 | D28: =D27 -> 30926498 | E28: =D28-D27 -> 0 | F28: =F27 -> 3249618 | G28: =F28-F27 -> 0 | H28: =H27 -> 17031052 | I28: =H28-H27 -> 0 | J28: =J27 -> 28048670 | K28: =J28-J27 -> 0 | L28: =L27 -> 22153700 | M28: =L28-L27 -> 0 | N28: =M28+K28+I28+G28+E28 -> 0 | O28: =IF(B28>0,N28/B28,0) -> 0 | P28: =P27 -> 15007.06 | Q28: =(P28-P27)*1000 -> 0 | R28: =N28-Q28 -> 0 | S28: =S27 -> 8031 | T28: =S28-S27 -> 0 | U28: =U27 -> 949426 | V28: =U28-U27 -> 0 | W28: =W27 -> 31574 | X28: =W28-W27 -> 0 | Y28: =Y27 -> 569805 | Z28: =Y28-Y27 -> 0 | AA28: =AA27 -> 34492 | AB28: =AA28-AA27 -> 0 | AC28: =AC27 -> 658787 | AD28: =AC28-AC27 -> 0 | AE28: =AB28+X28+T28 -> 0 | AF28: =V28+Z28+AD28 -> 0 | AG28: =IF(AE28>0,AF28/AE28,0) -> 0 | AI28: =R28-'EDl log'!B26 -> -48711532
... A33: ='General information '!F36 -> 0 | B33: =SUM(230*A33) -> 0 | C33: 43769 | D33: =D32 -> 30926498 | E33: =D33-D32 -> 0 | F33: =F32 -> 3249618 | G33: =F33-F32 -> 0 | H33: =H32 -> 17031052 | I33: =H33-H32 -> 0 | J33: =J32 -> 28048670 | K33: =J33-J32 -> 0 | L33: =L32 -> 22153700 | M33: =L33-L32 -> 0 | N33: =M33+K33+I33+G33+E33 -> 0 | O33: =IF(B33>0,N33/B33,0) -> 0 | P33: =P32 -> 15007.06 | Q33: =(P33-P32)*1000 -> 0 | R33: =N33-Q33 -> 0 | S33: =S32 -> 8031 | T33: =S33-S32 -> 0 | U33: =U32 -> 949426 | V33: =U33-U32 -> 0 | W33: =W32 -> 31574 | X33: =W33-W32 -> 0 | Y33: =Y32 -> 569805 | Z33: =Y33-Y32 -> 0 | AA33: =AA32 -> 34492 | AB33: =AA33-AA32 -> 0 | AC33: =AC32 -> 658787 | AD33: =AC33-AC32 -> 0 | AE33: =AB33+X33+T33 -> 0 | AF33: =V33+Z33+AD33 -> 0 | AG33: =IF(AE33>0,AF33/AE33,0) -> 0 | AI33: =R33-'EDl log'!B31 -> -48711532

Sheet B5
F1: Boiler A | J1: =J36 -> 76.791667 | K1: Boiler B | P1: Boiler C | V1: Boiler | X1: SteamA | AC1: SteamB | AH1: Steam | AI1: Boiler & steam | AL1: Total Boiler Runing H | AM1: Total Steam Runing H | AN1: GAS1 % | AO1: GAS1/L | AP1: GAS2% | AQ1: Gas2/L | AR1: GAS3% | AS1: GAS3/L | AU1: Gas Cons | AV1: Delivery | AW1: Cost/L
B2: Level Tank Gen | C2: Level tank Boiler | D2: Daily Cons Bo. | E2: Boiler litter | F2: Boiler A | G2: Run Hr a | H2: Boiler A fuel | I2: Daily consumption | J2: AVG | K2: index Run H | L2: Run Hrb | M2: Boiler B Fuel | O2: Daily consumption | P2: Boiler C | S2: Run C | U2: Total RH | V2: Total Fuel | X2: SteamA | Y2: Run SA | Z2: Steam A Conter | AA2: Liters | AC2: SteamB | AD2: Run SteamB | AE2: Steam B Conter | AF2: SB Litters | AG2: Avg | AH2: Total Fuel | AI2: Total Fuel
S3: 0
A4: =ELEC!C2 -> 43738 | B4: =[1]B5!B34 -> 202 | C4: =[1]B5!C34 -> 219 | D4: =[1]B5!D34 -> -29 | E4: =[1]B5!E34 -> -243.02 | F4: =[1]B5!F34 -> 1128 | G4: =[1]B5!G34 -> 0 | H4: =[1]B5!H34 -> 316410 | I4: =[1]B5!I34 -> 0 | ... AX4: =[1]B5!AX34 -> 0.7
A5: =ELEC!C3 -> 43739 | B5: 188 | C5: 194 | D5: =C4-C5 -> 25 | E5: =D5*8.38 -> 209.5 | F5: 1130 | G5: =F5-F4 -> 2 | H5: 316537 | I5: =SUM(H5-H4) -> 127 | J5: 1 | K5: =K4 -> 1523 | L5: =K5-K4 -> 0 | M5: =M4 -> 111660 | N5: =M5-M4 -> 0 | O5: =SUM(L5*$J$1) -> 0 | P5: 1334 | Q5: 116399 | R5: =Q5-Q4 -> 169 | S5: =SUM(P5-P4) -> 2 | T5: =SUM(S5*$T$2) -> 0 | U5: =SUM(G5+L5+S5) -> 4 | V5: =R5+N5+I5:I5 -> 296 | W5: =SUM(V5/U5) -> 74 | X5: 2185 | Y5: =X5-X4 -> 0 | Z5: 123531.8 | AA5: =Z5-Z4 -> 0 | AB5: =SUM(Y5*$AB$2) -> 0 | AC5: 1390 | AD5: =AC5-AC4 -> 12 | AE5: 337942.5 | AF5: =AE5-AE4 -> 543.1 | AG5: =IF(AD5>0,AF5/AD5,0) -> 45.258333 | AH5: =AF5+AA5 -> 543.1 | AI5: =SUM(AH5+V5) -> 839.1 | AJ5: =-tanks!AW6 -> 839.1 | AK5: =SUM(AJ5-AI5) -> 0 | AL5: =S5+L5+G5 -> 4 | AM5: =Y5+AD5 -> 12 | AN5: 68 | AO5: =(AN5/100)*3000 -> 2040 | AP5: 66 | AQ5: =(AP5/100)*3000 -> 1980 | AR5: 66 | AS5: =(AR5/100)*3000 -> 1980 | AT5: =SUM(AO5+AQ5+AS5) -> 6000 | AU5: =AT4-AT5+AV5 -> 270 | AV5: 0 | AW5: 0 | AX5: =IF(AV5>0,AW5,AX4) -> 0.7
A6: =ELEC!C4 -> 43740 | B6: 174 | C6: 180 | D6: =C5-C6 -> 14 | E6: =D6*8.38 -> 117.32 | F6: 1133 | G6: =F6-F5 -> 3 | H6: 316814 | I6: =SUM(H6-H5) -> 277 | J6: =IF(G6>0,I6/G6,0) -> 92.333333 | K6: =K5 -> 1523 | L6: =K6-K5 -> 0 | M6: =M5 -> 111660 | N6: =M6-M5 -> 0 | O6: =SUM(L6*$J$1) -> 0 | P6: 1335 | Q6: 116416 | R6: =Q6-Q5 -> 17 | S6: =SUM(P6-P5) -> 1 | T6: =SUM(S6*$T$2) -> 0 | U6: =SUM(G6+L6+S6) -> 4 | V6: =R6+N6+I6:I6 -> 294 | W6: =SUM(V6/U6) -> 73.5 | X6: =X5 -> 2185 | Y6: =X6-X5 -> 0 | Z6: =Z5 -> 123531.8 | AA6: =Z6-Z5 -> 0 | AB6: =SUM(Y6*$AB$2) -> 0 | AC6: 1401 | AD6: =AC6-AC5 -> 11 | AE6: 338451.1 | AF6: =AE6-AE5 -> 508.6 | AG6: =IF(AD6>0,AF6/AD6,0) -> 46.236364 | AH6: =AF6+AA6 -> 508.6 | AI6: =SUM(AH6+V6) -> 802.6 | AJ6: =-tanks!AW7 -> 802.6 | AK6: =SUM(AJ6-AI6) -> 0 | AL6: =S6+L6+G6 -> 4 | AM6: =Y6+AD6 -> 11 | AN6: 65 | AO6: =(AN6/100)*3000 -> 1950 | AP6: 64 | AQ6: =(AP6/100)*3000 -> 1920 | AR6: 63 | AS6: =(AR6/100)*3000 -> 1890 | AT6: =SUM(AO6+AQ6+AS6) -> 5760 | AU6: =AT5-AT6+AV6 -> 240 | AX6: =IF(AV6>0,AW6,AX5) -> 0.7
A7: =ELEC!C5 -> 43741 | B7: 159 | C7: 165 | D7: =C6-C7 -> 15 | E7: =D7*8.38 -> 125.7 | F7: 1135 | G7: =F7-F6 -> 2 | H7: 316977 | I7: =SUM(H7-H6) -> 163 | J7: =IF(G7>0,I7/G7,0) -> 81.5 | K7: =K6 -> 1523 | L7: =K7-K6 -> 0 | M7: =M6 -> 111660 | N7: =M7-M6 -> 0 | O7: 1 | P7: 1336 | Q7: 116541 | R7: =Q7-Q6 -> 125 | S7: =SUM(P7-P6) -> 1 | T7: =SUM(S7*$T$2) -> 0 | U7: =SUM(G7+L7+S7) -> 3 | V7: =R7+N7+I7:I7 -> 288 | W7: =SUM(V7/U7) -> 96 | X7: =X6 -> 2185 | Y7: =X7-X6 -> 0 | Z7: =Z6 -> 123531.8 | AA7: =Z7-Z6 -> 0 | AB7: =SUM(Y7*$AB$2) -> 0 | AC7: 1412 | AD7: =AC7-AC6 -> 11 | AE7: 338975.7 | AF7: =AE7-AE6 -> 524.6 | AG7: =IF(AD7>0,AF7/AD7,0) -> 47.690909 | AH7: =AF7+AA7 -> 524.6 | AI7: =SUM(AH7+V7) -> 812.6 | AJ7: =-tanks!AW8 -> 812.6 | AK7: =SUM(AJ7-AI7) -> 0 | AL7: =S7+L7+G7 -> 3 | AM7: =Y7+AD7 -> 11 | AN7: 63 | AO7: =(AN7/100)*3000 -> 1890 | AP7: 61 | AQ7: =(AP7/100)*3000 -> 1830 | AR7: 61 | AS7: =(AR7/100)*3000 -> 1830 | AT7: =SUM(AO7+AQ7+AS7) -> 5550 | AU7: =AT6-AT7+AV7 -> 210 | AX7: =IF(AV7>0,AW7,AX6) -> 0.7
A8: =ELEC!C6 -> 43742 | B8: 204 | C8: 210 | D8: =C7-C8 -> -45 | E8: =D8*8.38 -> -377.1 | F8: =F7 -> 1135 | G8: =F8-F7 -> 0 | H8: =H7 -> 316977 | I8: =SUM(H8-H7) -> 0 | J8: =IF(G8>0,I8/G8,0) -> 0 | K8: =K7 -> 1523 | L8: =K8-K7 -> 0 | M8: =M7 -> 111660 | N8: =M8-M7 -> 0 | O8: =SUM(L8*$J$1) -> 0 | P8: 1339 | Q8: 116834 | R8: =Q8-Q7 -> 293 | S8: =SUM(P8-P7) -> 3 | T8: =SUM(S8*$T$2) -> 0 | U8: =SUM(G8+L8+S8) -> 3 | V8: =R8+N8+I8:I8 -> 293 | W8: =SUM(V8/U8) -> 97.666667 | X8: =X7 -> 2185 | Y8: =X8-X7 -> 0 | Z8: =Z7 -> 123531.8 | AA8: =Z8-Z7 -> 0 | AB8: =SUM(Y8*$AB$2) -> 0 | AC8: 1426 | AD8: =AC8-AC7 -> 14 | AE8: 339615.2 | AF8: =AE8-AE7 -> 639.5 | AG8: =IF(AD8>0,AF8/AD8,0) -> 45.678571 | AH8: =AF8+AA8 -> 639.5 | AI8: =SUM(AH8+V8) -> 932.5 | AJ8: =-tanks!AW9 -> 932.5 | AK8: =SUM(AJ8-AI8) -> 0 | AL8: =S8+L8+G8 -> 3 | AM8: =Y8+AD8 -> 14 | AN8: 80 | AO8: =(AN8/100)*3000 -> 2400 | AP8: 83 | AQ8: =(AP8/100)*3000 -> 2490 | AR8: 83 | AS8: =(AR8/100)*3000 -> 2490 | AT8: =SUM(AO8+AQ8+AS8) -> 7380 | AU8: =AT7-AT8+AV8 -> 570 | AV8: 2400 | AW8: 0.7 | AX8: =IF(AV8>0,AW8,AX7) -> 0.7
A9: =ELEC!C7 -> 43743 | B9: 194 | C9: 201 | D9: =C8-C9 -> 9 | E9: =D9*8.38 -> 75.42 | F9: 1138 | G9: =F9-F8 -> 3 | H9: 317190 | I9: =SUM(H9-H8) -> 213 | J9: =IF(G9>0,I9/G9,0) -> 71 | K9: =K8 -> 1523 | L9: =K9-K8 -> 0 | M9: =M8 -> 111660 | N9: =M9-M8 -> 0 | O9: =SUM(L9*$J$1) -> 0 | P9: 1342 | Q9: 117015 | R9: =Q9-Q8 -> 181 | S9: =SUM(P9-P8) -> 3 | T9: =SUM(S9*$T$2) -> 0 | U9: =SUM(G9+L9+S9) -> 6 | V9: =R9+N9+I9:I9 -> 394 | W9: =SUM(V9/U9) -> 65.666667 | X9: =X8 -> 2185 | Y9: =X9-X8 -> 0 | Z9: =Z8 -> 123531.8 | AA9: =Z9-Z8 -> 0 | AB9: =SUM(Y9*$AB$2) -> 0 | AC9: 1440 | AD9: =AC9-AC8 -> 14 | AE9: 340253.7 | AF9: =AE9-AE8 -> 638.5 | AG9: =IF(AD9>0,AF9/AD9,0) -> 45.607143 | AH9: =AF9+AA9 -> 638.5 | AI9: =SUM(AH9+V9) -> 1032.5 | AJ9: =-tanks!AW10 -> 1032.5 | AK9: =SUM(AJ9-AI9) -> 0 | AL9: =S9+L9+G9 -> 6 | AM9: =Y9+AD9 -> 14 | AN9: 77 | AO9: =(AN9/100)*3000 -> 2310 | AP9: 77 | AQ9: =(AP9/100)*3000 -> 2310 | AR9: 77 | AS9: =(AR9/100)*3000 -> 2310 | AT9: =SUM(AO9+AQ9+AS9) -> 6930 | AU9: =AT8-AT9+AV9 -> 450 | AX9: =IF(AV9>0,AW9,AX8) -> 0.7
A10: =ELEC!C8 -> 43744 | B10: 186 | C10: 192 | D10: =C9-C10 -> 9 | E10: =D10*8.38 -> 75.42 | F10: 1142 | G10: =F10-F9 -> 4 | H10: 317483 | I10: =SUM(H10-H9) -> 293 | J10: =IF(G10>0,I10/G10,0) -> 73.25 | K10: =K9 -> 1523 | L10: =K10-K9 -> 0 | M10: =M9 -> 111660 | N10: =M10-M9 -> 0 | O10: =SUM(L10*$J$1) -> 0 | P10: 1343 | Q10: 117137 | R10: =Q10-Q9 -> 122 | S10: =SUM(P10-P9) -> 1 | T10: =SUM(S10*$T$2) -> 0 | U10: =SUM(G10+L10+S10) -> 5 | V10: =R10+N10+I10:I10 -> 415 | W10: =SUM(V10/U10) -> 83 | X10: =X9 -> 2185 | Y10: =X10-X9 -> 0 | Z10: =Z9 -> 123531.8 | AA10: =Z10-Z9 -> 0 | AB10: =SUM(Y10*$AB$2) -> 0 | AC10: 1453 | AD10: =AC10-AC9 -> 13 | AE10: 340881.9 | AF10: =AE10-AE9 -> 628.2 | AG10: =IF(AD10>0,AF10/AD10,0) -> 48.323077 | AH10: =AF10+AA10 -> 628.2 | AI10: =SUM(AH10+V10) -> 1043.2 | AJ10: =-tanks!AW11 -> 1043.2 | AK10: =SUM(AJ10-AI10) -> 0 | AL10: =S10+L10+G10 -> 5 | AM10: =Y10+AD10 -> 13 | AN10: 74 | AO10: =(AN10/100)*3000 -> 2220 | AP10: 74 | AQ10: =(AP10/100)*3000 -> 2220 | AR10: 74 | AS10: =(AR10/100)*3000 -> 2220 | AT10: =SUM(AO10+AQ10+AS10) -> 6660 | AU10: =AT9-AT10+AV10 -> 270 | AX10: =IF(AV10>0,AW10,AX9) -> 0.7
A11: =ELEC!C9 -> 43745 | B11: 177 | C11: 184 | D11: =C10-C11 -> 8 | E11: =D11*8.38 -> 67.04 | F11: =F10 -> 1142 | G11: =F11-F10 -> 0 | H11: =H10 -> 317483 | I11: =SUM(H11-H10) -> 0 | J11: =IF(G11>0,I11/G11,0) -> 0 | K11: =K10 -> 1523 | L11: =K11-K10 -> 0 | M11: =M10 -> 111660 | N11: =M11-M10 -> 0 | O11: =SUM(L11*$J$1) -> 0 | P11: 1346 | Q11: 117373 | R11: =Q11-Q10 -> 236 | S11: =SUM(P11-P10) -> 3 | T11: =SUM(S11*$T$2) -> 0 | U11: =SUM(G11+L11+S11) -> 3 | V11: =R11+N11+I11:I11 -> 236 | W11: =SUM(V11/U11) -> 78.666667 | X11: =X10 -> 2185 | Y11: =X11-X10 -> 0 | Z11: =Z10 -> 123531.8 | AA11: =Z11-Z10 -> 0 | AB11: =SUM(Y11*$AB$2) -> 0 | AC11: 1469 | AD11: =AC11-AC10 -> 16 | AE11: 341507.7 | AF11: =AE11-AE10 -> 625.8 | AG11: =IF(AD11>0,AF11/AD11,0) -> 39.1125 | AH11: =AF11+AA11 -> 625.8 | AI11: =SUM(AH11+V11) -> 861.8 | AJ11: =-tanks!AW12 -> 861.8 | AK11: =SUM(AJ11-AI11) -> 0 | AL11: =S11+L11+G11 -> 3 | AM11: =Y11+AD11 -> 16 | AN11: 70 | AO11: =(AN11/100)*3000 -> 2100 | AP11: 70 | AQ11: =(AP11/100)*3000 -> 2100 | AR11: 70 | AS11: =(AR11/100)*3000 -> 2100 | AT11: =SUM(AO11+AQ11+AS11) -> 6300 | AU11: =AT10-AT11+AV11 -> 360 | AX11: =IF(AV11>0,AW11,AX10) -> 0.7
A12: =ELEC!C10 -> 43746 | B12: 169 | C12: 175 | D12: =C11-C12 -> 9 | E12: =D12*8.38 -> 75.42 | F12: 1143 | G12: =F12-F11 -> 1 | H12: 317603 | I12: =SUM(H12-H11) -> 120 | J12: =IF(G12>0,I12/G12,0) -> 120 | K12: =K11 -> 1523 | L12: =K12-K11 -> 0 | M12: =M11 -> 111660 | N12: =M12-M11 -> 0 | O12: =SUM(L12*$J$1) -> 0 | P12: 1348 | Q12: 117536 | R12: =Q12-Q11 -> 163 | S12: =SUM(P12-P11) -> 2 | T12: =SUM(S12*$T$2) -> 0 | U12: =SUM(G12+L12+S12) -> 3 | V12: =R12+N12+I12:I12 -> 283 | W12: =SUM(V12/U12) -> 94.333333 | X12: =X11 -> 2185 | Y12: =X12-X11 -> 0 | Z12: =Z11 -> 123531.8 | AA12: =Z12-Z11 -> 0 | AB12: =SUM(Y12*$AB$2) -> 0 | AC12: 1481 | AD12: =AC12-AC11 -> 12 | AE12: 342032.5 | AF12: =AE12-AE11 -> 524.8 | AG12: =IF(AD12>0,AF12/AD12,0) -> 43.733333 | AH12: =AF12+AA12 -> 524.8 | AI12: =SUM(AH12+V12) -> 807.8 | AJ12: =-tanks!AW13 -> 807.8 | AK12: =SUM(AJ12-AI12) -> 0 | AL12: =S12+L12+G12 -> 3 | AM12: =Y12+AD12 -> 12 | AN12: 68 | AO12: =(AN12/100)*3000 -> 2040 | AP12: 67 | AQ12: =(AP12/100)*3000 -> 2010 | AR12: 67 | AS12: =(AR12/100)*3000 -> 2010 | AT12: =SUM(AO12+AQ12+AS12) -> 6060 | AU12: =AT11-AT12+AV12 -> 240 | AX12: =IF(AV12>0,AW12,AX11) -> 0.7
A13: =ELEC!C11 -> 43747 | B13: 160 | C13: 166 | D13: =C12-C13 -> 9 | E13: =D13*8.38 -> 75.42 | F13: 1145 | G13: =F13-F12 -> 2 | H13: 317736 | I13: =SUM(H13-H12) -> 133 | J13: =IF(G13>0,I13/G13,0) -> 66.5 | K13: 1523 | L13: =K13-K12 -> 0 | M13: =M12 -> 111660 | N13: =M13-M12 -> 0 | O13: =SUM(L13*$J$1) -> 0 | P13: 1350 | Q13: 117720 | R13: =Q13-Q12 -> 184 | S13: =SUM(P13-P12) -> 2 | T13: =SUM(S13*$T$2) -> 0 | U13: =SUM(G13+L13+S13) -> 4 | V13: =R13+N13+I13:I13 -> 317 | W13: =SUM(V13/U13) -> 79.25 | X13: 2185 | Y13: =X13-X12 -> 0 | Z13: 123531.8 | AA13: =Z13-Z12 -> 0 | AB13: =SUM(Y13*$AB$2) -> 0 | AC13: 1494 | AD13: =AC13-AC12 -> 13 | AE13: 342596.2 | AF13: =AE13-AE12 -> 563.7 | AG13: =IF(AD13>0,AF13/AD13,0) -> 43.361538 | AH13: =AF13+AA13 -> 563.7 | AI13: =SUM(AH13+V13) -> 880.7 | AJ13: =-tanks!AW14 -> 880.7 | AK13: =SUM(AJ13-AI13) -> 0 | AL13: =S13+L13+G13 -> 4 | AM13: =Y13+AD13 -> 13 | AN13: 65 | AO13: =(AN13/100)*3000 -> 1950 | AP13: 65 | AQ13: =(AP13/100)*3000 -> 1950 | AR13: 65 | AS13: =(AR13/100)*3000 -> 1950 | AT13: =SUM(AO13+AQ13+AS13) -> 5850 | AU13: =AT12-AT13+AV13 -> 210 | AX13: =IF(AV13>0,AW13,AX12) -> 0.7
A14: =ELEC!C12 -> 43748 | B14: 148 | C14: 154 | D14: =C13-C14 -> 12 | E14: =D14*8.38 -> 100.56 | F14: 1145 | G14: =F14-F13 -> 0 | H14: 317736 | I14: =SUM(H14-H13) -> 0 | J14: =IF(G14>0,I14/G14,0) -> 0 | K14: =K13 -> 1523 | L14: =K14-K13 -> 0 | M14: =M13 -> 111660 | N14: =M14-M13 -> 0 | O14: =SUM(L14*$J$1) -> 0 | P14: 1353 | Q14: 117973 | R14: =Q14-Q13 -> 253 | S14: =SUM(P14-P13) -> 3 | T14: =SUM(S14*$T$2) -> 0 | U14: =SUM(G14+L14+S14) -> 3 | V14: =R14+N14+I14:I14 -> 253 | W14: =SUM(V14/U14) -> 84.333333 | X14: 2185 | Y14: =X14-X13 -> 0 | Z14: 123531.8 | AA14: =Z14-Z13 -> 0 | AB14: =SUM(Y14*$AB$2) -> 0 | AC14: 1507 | AD14: =AC14-AC13 -> 13 | AE14: 343182.3 | AF14: =AE14-AE13 -> 586.1 | AG14: =IF(AD14>0,AF14/AD14,0) -> 45.084615 | AH14: =AF14+AA14 -> 586.1 | AI14: =SUM(AH14+V14) -> 839.1 | AJ14: =-tanks!AW15 -> 839.1 | AK14: =SUM(AJ14-AI14) -> 0 | AL14: =S14+L14+G14 -> 3 | AM14: =Y14+AD14 -> 13 | AN14: 63 | AO14: =(AN14/100)*3000 -> 1890 | AP14: 62 | AQ14: =(AP14/100)*3000 -> 1860 | AR14: 62 | AS14: =(AR14/100)*3000 -> 1860 | AT14: =SUM(AO14+AQ14+AS14) -> 5610 | AU14: =AT13-AT14+AV14 -> 240 | AX14: =IF(AV14>0,AW14,AX13) -> 0.7
A15: =ELEC!C13 -> 43749 | B15: 208 | C15: 214 | D15: =C14-C15 -> -60 | E15: =D15*8.38 -> -502.8 | F15: 1148 | G15: =F15-F14 -> 3 | H15: 317932 | I15: =SUM(H15-H14) -> 196 | J15: =IF(G15>0,I15/G15,0) -> 65.333333 | K15: =K14 -> 1523 | L15: =K15-K14 -> 0 | M15: =M14 -> 111660 | N15: =M15-M14 -> 0 | O15: =SUM(L15*$J$1) -> 0 | P15: 1355 | Q15: 118124 | R15: =Q15-Q14 -> 151 | S15: =SUM(P15-P14) -> 2 | T15: =SUM(S15*$T$2) -> 0 | U15: =SUM(G15+L15+S15) -> 5 | V15: =R15+N15+I15:I15 -> 347 | W15: =SUM(V15/U15) -> 69.4 | X15: =X14 -> 2185 | Y15: =X15-X14 -> 0 | Z15: =Z14 -> 123531.8 | AA15: =Z15-Z14 -> 0 | AB15: =SUM(Y15*$AB$2) -> 0 | AC15: 1517 | AD15: =AC15-AC14 -> 10 | AE15: 343657.2 | AF15: =AE15-AE14 -> 474.9 | AG15: =IF(AD15>0,AF15/AD15,0) -> 47.49 | AH15: =AF15+AA15 -> 474.9 | AI15: =SUM(AH15+V15) -> 821.9 | AJ15: =-tanks!AW16 -> 821.9 | AK15: =SUM(AJ15-AI15) -> 0 | AL15: =S15+L15+G15 -> 5 | AM15: =Y15+AD15 -> 10 | AN15: 83 | AO15: =(AN15/100)*3000 -> 2490 | AP15: 80 | AQ15: =(AP15/100)*3000 -> 2400 | AR15: 80 | AS15: =(AR15/100)*3000 -> 2400 | AT15: =SUM(AO15+AQ15+AS15) -> 7290 | AU15: =AT14-AT15+AV15 -> 720 | AV15: 2400 | AW15: 0.7 | AX15: =IF(AV15>0,AW15,AX14) -> 0.7
A16: =ELEC!C14 -> 43750 | B16: 200 | C16: 206 | D16: =C15-C16 -> 8 | E16: =D16*8.38 -> 67.04 | F16: 1150 | G16: =F16-F15 -> 2 | H16: 318104 | I16: =SUM(H16-H15) -> 172 | J16: =IF(G16>0,I16/G16,0) -> 86 | K16: =K15 -> 1523 | L16: =K16-K15 -> 0 | M16: =M15 -> 111660 | N16: =M16-M15 -> 0 | O16: =SUM(L16*$J$1) -> 0 | P16: 1356 | Q16: 118236 | R16: =Q16-Q15 -> 112 | S16: =SUM(P16-P15) -> 1 | T16: =SUM(S16*$T$2) -> 0 | U16: =SUM(G16+L16+S16) -> 3 | V16: =R16+N16+I16:I16 -> 284 | W16: =SUM(V16/U16) -> 94.666667 | X16: =X15 -> 2185 | Y16: =X16-X15 -> 0 | Z16: =Z15 -> 123531.8 | AA16: =Z16-Z15 -> 0 | AB16: =SUM(Y16*$AB$2) -> 0 | AC16: 1529 | AD16: =AC16-AC15 -> 12 | AE16: 344217.4 | AF16: =AE16-AE15 -> 560.2 | AG16: =IF(AD16>0,AF16/AD16,0) -> 46.683333 | AH16: =AF16+AA16 -> 560.2 | AI16: =SUM(AH16+V16) -> 844.2 | AJ16: =-tanks!AW17 -> 844.2 | AK16: =SUM(AJ16-AI16) -> 0 | AL16: =S16+L16+G16 -> 3 | AM16: =Y16+AD16 -> 12 | AN16: 80 | AO16: =(AN16/100)*3000 -> 2400 | AP16: 79 | AQ16: =(AP16/100)*3000 -> 2370 | AR16: 79 | AS16: =(AR16/100)*3000 -> 2370 | AT16: =SUM(AO16+AQ16+AS16) -> 7140 | AU16: =AT15-AT16+AV16 -> 150 | AX16: =IF(AV16>0,AW16,AX15) -> 0.7
A17: =ELEC!C15 -> 43751 | B17: 192 | C17: 198 | D17: =C16-C17 -> 8 | E17: =D17*8.38 -> 67.04 | F17: =F16 -> 1150 | G17: =F17-F16 -> 0 | H17: =H16 -> 318104 | I17: =SUM(H17-H16) -> 0 | J17: =IF(G17>0,I17/G17,0) -> 0 | K17: =K16 -> 1523 | L17: =K17-K16 -> 0 | M17: =M16 -> 111660 | N17: =M17-M16 -> 0 | O17: =SUM(L17*$J$1) -> 0 | P17: 1360 | Q17: 118540 | R17: =Q17-Q16 -> 304 | S17: =SUM(P17-P16) -> 4 | T17: =SUM(S17*$T$2) -> 0 | U17: =SUM(G17+L17+S17) -> 4 | V17: =R17+N17+I17:I17 -> 304 | X17: =X16 -> 2185 | Y17: =X17-X16 -> 0 | Z17: =Z16 -> 123531.8 | AA17: =Z17-Z16 -> 0 | AB17: =SUM(Y17*$AB$2) -> 0 | AC17: 1542 | AD17: =AC17-AC16 -> 13 | AE17: 344838.7 | AF17: =AE17-AE16 -> 621.3 | AG17: =IF(AD17>0,AF17/AD17,0) -> 47.792308 | AH17: =AF17+AA17 -> 621.3 | AI17: =SUM(AH17+V17) -> 925.3 | AJ17: =-tanks!AW18 -> 925.3 | AK17: =SUM(AJ17-AI17) -> 0 | AL17: =S17+L17+G17 -> 4 | AM17: =Y17+AD17 -> 13 | AN17: 75 | AO17: =(AN17/100)*3000 -> 2250 | AP17: 75 | AQ17: =(AP17/100)*3000 -> 2250 | AR17: 76 | AS17: =(AR17/100)*3000 -> 2280 | AT17: =SUM(AO17+AQ17+AS17) -> 6780 | AU17: =AT16-AT17+AV17 -> 360 | AX17: =IF(AV17>0,AW17,AX16) -> 0.7
A18: =ELEC!C16 -> 43752 | B18: 178 | C18: 184 | D18: =C17-C18 -> 14 | E18: =D18*8.38 -> 117.32 | F18: 1151 | G18: =F18-F17 -> 1 | H18: 318215 | I18: =SUM(H18-H17) -> 111 | J18: =IF(G18>0,I18/G18,0) -> 111 | K18: 1523 | L18: =K18-K17 -> 0 | M18: 111660 | N18: =M18-M17 -> 0 | O18: =SUM(L18*$J$1) -> 0 | P18: 1361 | Q18: 118669 | R18: =Q18-Q17 -> 129 | S18: =SUM(P18-P17) -> 1 | T18: =SUM(S18*$T$2) -> 0 | U18: =SUM(G18+L18+S18) -> 2 | V18: =R18+N18+I18:I18 -> 240 | X18: 2185 | Y18: =X18-X17 -> 0 | Z18: 123531.8 | AA18: =Z18-Z17 -> 0 | AB18: =SUM(Y18*$AB$2) -> 0 | AC18: 1552 | AD18: =AC18-AC17 -> 10 | AE18: 345307 | AF18: =AE18-AE17 -> 468.3 | AG18: =IF(AD18>0,AF18/AD18,0) -> 46.83 | AH18: =AF18+AA18 -> 468.3 | AI18: =SUM(AH18+V18) -> 708.3 | AJ18: =-tanks!AW19 -> 708.3 | AK18: =SUM(AJ18-AI18) -> 0 | AL18: =S18+L18+G18 -> 2 | AM18: =Y18+AD18 -> 10 | AN18: 74 | AO18: =(AN18/100)*3000 -> 2220 | AP18: 74 | AQ18: =(AP18/100)*3000 -> 2220 | AR18: 74 | AS18: =(AR18/100)*3000 -> 2220 | AT18: =SUM(AO18+AQ18+AS18) -> 6660 | AU18: =AT17-AT18+AV18 -> 120 | AX18: =IF(AV18>0,AW18,AX17) -> 0.7
A19: =ELEC!C17 -> 43753 | B19: =B18 -> 178 | C19: =C18 -> 184 | D19: =C18-C19 -> 0 | E19: =D19*8.38 -> 0 | F19: =F18 -> 1151 | G19: =F19-F18 -> 0 | H19: =H18 -> 318215 | I19: =SUM(H19-H18) -> 0 | J19: =IF(G19>0,I19/G19,0) -> 0 | K19: =K18 -> 1523 | L19: =K19-K18 -> 0 | M19: =M18 -> 111660 | N19: =M19-M18 -> 0 | O19: =SUM(L19*$J$1) -> 0 | P19: =P18 -> 1361 | Q19: =Q18 -> 118669 | R19: =Q19-Q18 -> 0 | S19: =SUM(P19-P18) -> 0 | T19: =SUM(S19*$T$2) -> 0 | U19: =SUM(G19+L19+S19) -> 0 | V19: =R19+N19+I19:I19 -> 0 | X19: =X18 -> 2185 | Y19: =X19-X18 -> 0 | Z19: =Z18 -> 123531.8 | AA19: =Z19-Z18 -> 0 | AB19: =SUM(Y19*$AB$2) -> 0 | AC19: =AC18 -> 1552 | AD19: =AC19-AC18 -> 0 | AE19: =AE18 -> 345307 | AF19: =AE19-AE18 -> 0 | AG19: =IF(AD19>0,AF19/AD19,0) -> 0 | AH19: =AF19+AA19 -> 0 | AI19: =SUM(AH19+V19) -> 0 | AJ19: =-tanks!AW20 -> 0 | AK19: =SUM(AJ19-AI19) -> 0 | AL19: =S19+L20+G19 -> 0 | AM19: =Y19+AD19 -> 0 | AN19: =AN18 -> 74 | AO19: =(AN19/100)*3000 -> 2220 | AP19: =AP18 -> 74 | AQ19: =(AP19/100)*3000 -> 2220 | AR19: =AR18 -> 74 | AS19: =(AR19/100)*3000 -> 2220 | AT19: =SUM(AO19+AQ19+AS19) -> 6660 | AU19: =AT18-AT19+AV19 -> 0 | AX19: =IF(AV19>0,AW19,AX18) -> 0.7
A20: =ELEC!C18 -> 43754 | B20: =B19 -> 178 | C20: =C19 -> 184 | D20: =C19-C20 -> 0 | E20: =D20*8.38 -> 0 | F20: =F19 -> 1151 | G20: =F20-F19 -> 0 | H20: =H19 -> 318215 | I20: =SUM(H20-H19) -> 0 | J20: =IF(G20>0,I20/G20,0) -> 0 | K20: =K19 -> 1523 | L20: =K20-K19 -> 0 | M20: =M19 -> 111660 | N20: =M20-M19 -> 0 | O20: =SUM(L20*$J$1) -> 0 | P20: =P19 -> 1361 | Q20: =Q19 -> 118669 | R20: =Q20-Q19 -> 0 | S20: =SUM(P20-P19) -> 0 | T20: =SUM(S20*$T$2) -> 0 | U20: =SUM(G20+L20+S20) -> 0 | V20: =R20+N20+I20:I20 -> 0 | X20: =X19 -> 2185 | Y20: =X20-X19 -> 0 | Z20: =Z19 -> 123531.8 | AA20: =Z20-Z19 -> 0 | AB20: =SUM(Y20*$AB$2) -> 0 | AC20: =AC19 -> 1552 | AD20: =AC20-AC19 -> 0 | AE20: =AE19 -> 345307 | AF20: =AE20-AE19 -> 0 | AG20: =IF(AD20>0,AF20/AD20,0) -> 0 | AH20: =AF20+AA20 -> 0 | AI20: =SUM(AH20+V20) -> 0 | AJ20: =-tanks!AW21 -> 0 | AK20: =SUM(AJ20-AI20) -> 0 | AL20: =S20+L21+G20 -> 0 | AM20: =Y20+AD20 -> 0 | AN20: =AN19 -> 74 | AO20: =(AN20/100)*3000 -> 2220 | AP20: =AP19 -> 74 | AQ20: =(AP20/100)*3000 -> 2220 | AR20: =AR19 -> 74 | AS20: =(AR20/100)*3000 -> 2220 | AT20: =SUM(AO20+AQ20+AS20) -> 6660 | AU20: =AT19-AT20+AV20 -> 0 | AX20: =IF(AV20>0,AW20,AX19) -> 0.7
A21: =ELEC!C19 -> 43755 | B21: =B20 -> 178 | C21: =C20 -> 184 | D21: =C20-C21 -> 0 | E21: =D21*8.38 -> 0 | F21: =F20 -> 1151 | G21: =F21-F20 -> 0 | H21: =H20 -> 318215 | I21: =SUM(H21-H20) -> 0 | J21: =IF(G21>0,I21/G21,0) -> 0 | K21: =K20 -> 1523 | L21: =K21-K20 -> 0 | M21: =M20 -> 111660 | N21: =M21-M20 -> 0 | O21: =SUM(L21*$J$1) -> 0 | P21: =P20 -> 1361 | Q21: =Q20 -> 118669 | R21: =Q21-Q20 -> 0 | S21: =SUM(P21-P20) -> 0 | T21: =SUM(S21*$T$2) -> 0 | U21: =SUM(G21+L21+S21) -> 0 | V21: =R21+N21+I21:I21 -> 0 | X21: =X20 -> 2185 | Y21: =X21-X20 -> 0 | Z21: =Z20 -> 123531.8 | AA21: =Z21-Z20 -> 0 | AB21: =SUM(Y21*$AB$2) -> 0 | AC21: =AC20 -> 1552 | AD21: =AC21-AC20 -> 0 | AE21: =AE20 -> 345307 | AF21: =AE21-AE20 -> 0 | AG21: =IF(AD21>0,AF21/AD21,0) -> 0 | AH21: =AF21+AA21 -> 0 | AI21: =SUM(AH21+V21) -> 0 | AJ21: =-tanks!AW22 -> 0 | AK21: =SUM(AJ21-AI21) -> 0 | AL21: =S21+L21+G21 -> 0 | AM21: =Y21+AD21 -> 0 | AN21: =AN20 -> 74 | AO21: =(AN21/100)*3000 -> 2220 | AP21: =AP20 -> 74 | AQ21: =(AP21/100)*3000 -> 2220 | AR21: =AR20 -> 74 | AS21: =(AR21/100)*3000 -> 2220 | AT21: =SUM(AO21+AQ21+AS21) -> 6660 | AU21: =AT20-AT21+AV21 -> 0 | AX21: =IF(AV21>0,AW21,AX20) -> 0.7
A22: =ELEC!C20 -> 43756 | B22: =B21 -> 178 | C22: =C21 -> 184 | D22: =C21-C22 -> 0 | E22: =D22*8.38 -> 0 | F22: =F21 -> 1151 | G22: =F22-F21 -> 0 | H22: =H21 -> 318215 | I22: =SUM(H22-H21) -> 0 | J22: =IF(G22>0,I22/G22,0) -> 0 | K22: =K21 -> 1523 | L22: =K22-K21 -> 0 | M22: =M21 -> 111660 | N22: =M22-M21 -> 0 | O22: =SUM(L22*$J$1) -> 0 | P22: =P21 -> 1361 | Q22: =Q21 -> 118669 | R22: =Q22-Q21 -> 0 | S22: =SUM(P22-P21) -> 0 | T22: =SUM(S22*$T$2) -> 0 | U22: =SUM(G22+L22+S22) -> 0 | V22: =R22+N22+I22:I22 -> 0 | X22: =X21 -> 2185 | Y22: =X22-X21 -> 0 | Z22: =Z21 -> 123531.8 | AA22: =Z22-Z21 -> 0 | AB22: =SUM(Y22*$AB$2) -> 0 | AC22: =AC21 -> 1552 | AD22: =AC22-AC21 -> 0 | AE22: =AE21 -> 345307 | AF22: =AE22-AE21 -> 0 | AG22: =IF(AD22>0,AF22/AD22,0) -> 0 | AH22: =AF22+AA22 -> 0 | AI22: =SUM(AH22+V22) -> 0 | AJ22: =-tanks!AW23 -> 0 | AK22: =SUM(AJ22-AI22) -> 0 | AL22: =S22+L22+G22 -> 0 | AM22: =Y22+AD22 -> 0 | AN22: =AN21 -> 74 | AO22: =(AN22/100)*3000 -> 2220 | AP22: =AP21 -> 74 | AQ22: =(AP22/100)*3000 -> 2220 | AR22: =AR21 -> 74 | AS22: =(AR22/100)*3000 -> 2220 | AT22: =SUM(AO22+AQ22+AS22) -> 6660 | AU22: =AT21-AT22+AV22 -> 0 | AX22: =IF(AV22>0,AW22,AX21) -> 0.7
A23: =ELEC!C21 -> 43757 | B23: =B22 -> 178 | C23: =C22 -> 184 | D23: =C22-C23 -> 0 | E23: =D23*8.38 -> 0 | F23: =F22 -> 1151 | G23: =F23-F22 -> 0 | H23: =H22 -> 318215 | I23: =SUM(H23-H22) -> 0 | J23: =IF(G23>0,I23/G23,0) -> 0 | K23: =K22 -> 1523 | L23: =K23-K22 -> 0 | M23: =M22 -> 111660 | N23: =M23-M22 -> 0 | O23: =SUM(L23*$J$1) -> 0 | P23: =P22 -> 1361 | Q23: =Q22 -> 118669 | R23: =Q23-Q22 -> 0 | S23: =SUM(P23-P22) -> 0 | T23: =SUM(S23*$T$2) -> 0 | U23: =SUM(G23+L23+S23) -> 0 | V23: =R23+N23+I23:I23 -> 0 | X23: =X22 -> 2185 | Y23: =X23-X22 -> 0 | Z23: =Z22 -> 123531.8 | AA23: =Z23-Z22 -> 0 | AB23: =SUM(Y23*$AB$2) -> 0 | AC23: =AC22 -> 1552 | AD23: =AC23-AC22 -> 0 | AE23: =AE22 -> 345307 | AF23: =AE23-AE22 -> 0 | AG23: =IF(AD23>0,AF23/AD23,0) -> 0 | AH23: =AF23+AA23 -> 0 | AI23: =SUM(AH23+V23) -> 0 | AJ23: =-tanks!AW24 -> 0 | AK23: =SUM(AJ23-AI23) -> 0 | AL23: =S23+L23+G23 -> 0 | AM23: =Y23+AD23 -> 0 | AN23: =AN22 -> 74 | AO23: =(AN23/100)*3000 -> 2220 | AP23: =AP22 -> 74 | AQ23: =(AP23/100)*3000 -> 2220 | AR23: =AR22 -> 74 | AS23: =(AR23/100)*3000 -> 2220 | AT23: =SUM(AO23+AQ23+AS23) -> 6660 | AU23: =AT22-AT23+AV23 -> 0 | AX23: =IF(AV23>0,AW23,AX22) -> 0.7
A24: =ELEC!C22 -> 43758 | B24: =B23 -> 178 | C24: =C23 -> 184 | D24: =C23-C24 -> 0 | E24: =D24*8.38 -> 0 | F24: =F23 -> 1151 | G24: =F24-F23 -> 0 | H24: =H23 -> 318215 | I24: =SUM(H24-H23) -> 0 | J24: =IF(G24>0,I24/G24,0) -> 0 | K24: =K23 -> 1523 | L24: =K24-K23 -> 0 | M24: =M23 -> 111660 | N24: =M24-M23 -> 0 | O24: =SUM(L24*$J$1) -> 0 | P24: =P23 -> 1361 | Q24: =Q23 -> 118669 | R24: =Q24-Q23 -> 0 | S24: =SUM(P24-P23) -> 0 | T24: =SUM(S24*$T$2) -> 0 | U24: =SUM(G24+L24+S24) -> 0 | V24: =R24+N24+I24:I24 -> 0 | X24: =X23 -> 2185 | Y24: =X24-X23 -> 0 | Z24: =Z23 -> 123531.8 | AA24: =Z24-Z23 -> 0 | AB24: =SUM(Y24*$AB$2) -> 0 | AC24: =AC23 -> 1552 | AD24: =AC24-AC23 -> 0 | AE24: =AE23 -> 345307 | AF24: =AE24-AE23 -> 0 | AG24: =IF(AD24>0,AF24/AD24,0) -> 0 | AH24: =AF24+AA24 -> 0 | AI24: =SUM(AH24+V24) -> 0 | AJ24: =-tanks!AW25 -> 0 | AK24: =SUM(AJ24-AI24) -> 0 | AL24: =S24+L24+G24 -> 0 | AM24: =Y24+AD24 -> 0 | AN24: =AN23 -> 74 | AO24: =(AN24/100)*3000 -> 2220 | AP24: =AP23 -> 74 | AQ24: =(AP24/100)*3000 -> 2220 | AR24: =AR23 -> 74 | AS24: =(AR24/100)*3000 -> 2220 | AT24: =SUM(AO24+AQ24+AS24) -> 6660 | AU24: =AT23-AT24+AV24 -> 0 | AX24: =IF(AV24>0,AW24,AX23) -> 0.7
A25: =ELEC!C23 -> 43759 | B25: =B24 -> 178 | C25: =C24 -> 184 | D25: =C24-C25 -> 0 | E25: =D25*8.38 -> 0 | F25: =F24 -> 1151 | G25: =F25-F24 -> 0 | H25: =H24 -> 318215 | I25: =SUM(H25-H24) -> 0 | J25: =IF(G25>0,I25/G25,0) -> 0 | K25: =K24 -> 1523 | L25: =K25-K24 -> 0 | M25: =M24 -> 111660 | N25: =M25-M24 -> 0 | O25: =SUM(L25*$J$1) -> 0 | P25: =P24 -> 1361 | Q25: =Q24 -> 118669 | R25: =Q25-Q24 -> 0 | S25: =SUM(P25-P24) -> 0 | T25: =SUM(S25*$T$2) -> 0 | U25: =SUM(G25+L25+S25) -> 0 | V25: =R25+N25+I25:I25 -> 0 | X25: =X24 -> 2185 | Y25: =X25-X24 -> 0 | Z25: =Z24 -> 123531.8 | AA25: =Z25-Z24 -> 0 | AB25: =SUM(Y25*$AB$2) -> 0 | AC25: =AC24 -> 1552 | AD25: =AC25-AC24 -> 0 | AE25: =AE24 -> 345307 | AF25: =AE25-AE24 -> 0 | AG25: =IF(AD25>0,AF25/AD25,0) -> 0 | AH25: =AF25+AA25 -> 0 | AI25: =SUM(AH25+V25) -> 0 | AJ25: =-tanks!AW26 -> 0 | AK25: =SUM(AJ25-AI25) -> 0 | AL25: =S25+L25+G25 -> 0 | AM25: =Y25+AD25 -> 0 | AN25: =AN24 -> 74 | AO25: =(AN25/100)*3000 -> 2220 | AP25: =AP24 -> 74 | AQ25: =(AP25/100)*3000 -> 2220 | AR25: =AR24 -> 74 | AS25: =(AR25/100)*3000 -> 2220 | AT25: =SUM(AO25+AQ25+AS25) -> 6660 | AU25: =AT24-AT25+AV25 -> 0 | AX25: =IF(AV25>0,AW25,AX24) -> 0.7
A26: =ELEC!C24 -> 43760 | B26: =B25 -> 178 | C26: =C25 -> 184 | D26: =C25-C26 -> 0 | E26: =D26*8.38 -> 0 | F26: =F25 -> 1151 | G26: =F26-F25 -> 0 | H26: =H25 -> 318215 | I26: =SUM(H26-H25) -> 0 | J26: =IF(G26>0,I26/G26,0) -> 0 | K26: =K25 -> 1523 | L26: =K26-K25 -> 0 | M26: =M25 -> 111660 | N26: =M26-M25 -> 0 | O26: =SUM(L26*$J$1) -> 0 | P26: =P25 -> 1361 | Q26: =Q25 -> 118669 | R26: =Q26-Q25 -> 0 | S26: =SUM(P26-P25) -> 0 | T26: =SUM(S26*$T$2) -> 0 | U26: =SUM(G26+L26+S26) -> 0 | V26: =R26+N26+I26:I26 -> 0 | X26: =X25 -> 2185 | Y26: =X26-X25 -> 0 | Z26: =Z25 -> 123531.8 | AA26: =Z26-Z25 -> 0 | AB26: =SUM(Y26*$AB$2) -> 0 | AC26: =AC25 -> 1552 | AD26: =AC26-AC25 -> 0 | AE26: =AE25 -> 345307 | AF26: =AE26-AE25 -> 0 | AG26: =IF(AD26>0,AF26/AD26,0) -> 0 | AH26: =AF26+AA26 -> 0 | AI26: =SUM(AH26+V26) -> 0 | AJ26: =-tanks!AW27 -> 0 | AK26: =SUM(AJ26-AI26) -> 0 | AL26: =S26+L26+G26 -> 0 | AM26: =Y26+AD26 -> 0 | AN26: =AN25 -> 74 | AO26: =(AN26/100)*3000 -> 2220 | AP26: =AP25 -> 74 | AQ26: =(AP26/100)*3000 -> 2220 | AR26: =AR25 -> 74 | AS26: =(AR26/100)*3000 -> 2220 | AT26: =SUM(AO26+AQ26+AS26) -> 6660 | AU26: =AT25-AT26+AV26 -> 0 | AX26: =IF(AV26>0,AW26,AX25) -> 0.7
A27: =ELEC!C25 -> 43761 | B27: =B26 -> 178 | C27: =C26 -> 184 | D27: =C26-C27 -> 0 | E27: =D27*8.38 -> 0 | F27: =F26 -> 1151 | G27: =F27-F26 -> 0 | H27: =H26 -> 318215 | I27: =SUM(H27-H26) -> 0 | J27: =IF(G27>0,I27/G27,0) -> 0 | K27: =K26 -> 1523 | L27: =K27-K26 -> 0 | M27: =M26 -> 111660 | N27: =M27-M26 -> 0 | O27: =SUM(L27*$J$1) -> 0 | P27: =P26 -> 1361 | Q27: =Q26 -> 118669 | R27: =Q27-Q26 -> 0 | S27: =SUM(P27-P26) -> 0 | T27: =SUM(S27*$T$2) -> 0 | U27: =SUM(G27+L27+S27) -> 0 | V27: =R27+N27+I27:I27 -> 0 | X27: =X26 -> 2185 | Y27: =X27-X26 -> 0 | Z27: =Z26 -> 123531.8 | AA27: =Z27-Z26 -> 0 | AB27: =SUM(Y27*$AB$2) -> 0 | AC27: =AC26 -> 1552 | AD27: =AC27-AC26 -> 0 | AE27: =AE26 -> 345307 | AF27: =AE27-AE26 -> 0 | AG27: =IF(AD27>0,AF27/AD27,0) -> 0 | AH27: =AF27+AA27 -> 0 | AI27: =SUM(AH27+V27) -> 0 | AJ27: =-tanks!AW28 -> 0 | AK27: =SUM(AJ27-AI27) -> 0 | AL27: =S27+L27+G27 -> 0 | AM27: =Y27+AD27 -> 0 | AN27: =AN26 -> 74 | AO27: =(AN27/100)*3000 -> 2220 | AP27: =AP26 -> 74 | AQ27: =(AP27/100)*3000 -> 2220 | AR27: =AR26 -> 74 | AS27: =(AR27/100)*3000 -> 2220 | AT27: =SUM(AO27+AQ27+AS27) -> 6660 | AU27: =AT26-AT27+AV27 -> 0 | AX27: =IF(AV27>0,AW27,AX26) -> 0.7
A28: =ELEC!C26 -> 43762 | B28: =B27 -> 178 | C28: =C27 -> 184 | D28: =C27-C28 -> 0 | E28: =D28*8.38 -> 0 | F28: =F27 -> 1151 | G28: =F28-F27 -> 0 | H28: =H27 -> 318215 | I28: =SUM(H28-H27) -> 0 | J28: =IF(G28>0,I28/G28,0) -> 0 | K28: =K27 -> 1523 | L28: =K28-K27 -> 0 | M28: =M27 -> 111660 | N28: =M28-M27 -> 0 | O28: =SUM(L28*$J$1) -> 0 | P28: =P27 -> 1361 | Q28: =Q27 -> 118669 | R28: =Q28-Q27 -> 0 | S28: =SUM(P28-P27) -> 0 | T28: =SUM(S28*$T$2) -> 0 | U28: =SUM(G28+L28+S28) -> 0 | V28: =R28+N28+I28:I28 -> 0 | X28: =X27 -> 2185 | Y28: =X28-X27 -> 0 | Z28: =Z27 -> 123531.8 | AA28: =Z28-Z27 -> 0 | AB28: =SUM(Y28*$AB$2) -> 0 | AC28: =AC27 -> 1552 | AD28: =AC28-AC27 -> 0 | AE28: =AE27 -> 345307 | AF28: =AE28-AE27 -> 0 | AG28: =IF(AD28>0,AF28/AD28,0) -> 0 | AH28: =AF28+AA28 -> 0 | AI28: =SUM(AH28+V28) -> 0 | AJ28: =-tanks!AW29 -> 0 | AK28: =SUM(AJ28-AI28) -> 0 | AL28: =S28+L28+G28 -> 0 | AM28: =Y28+AD28 -> 0 | AN28: =AN27 -> 74 | AO28: =(AN28/100)*3000 -> 2220 | AP28: =AP27 -> 74 | AQ28: =(AP28/100)*3000 -> 2220 | AR28: =AR27 -> 74 | AS28: =(AR28/100)*3000 -> 2220 | AT28: =SUM(AO28+AQ28+AS28) -> 6660 | AU28: =AT27-AT28+AV28 -> 0 | AX28: =IF(AV28>0,AW28,AX27) -> 0.7
