Workbook

Sheet TOTAL
A1: Site Name | B1: Day | C1: Month | D1: Year | E1: Total Electricity Kwh | F1: Electricity Tariff ($/Kwh) | G1: LPG (Kg) | H1: LPG $/Kg | I1: District Energy Heating Kwh | J1: District Energy Heating $/Kwh | K1: Water Utility Supply (m3) m3 | L1: Water Utility Supply (m3) $/m3 | M1: Room Nights | N1: Total Guests | O1: Utilities day cost dh
A2: Marrakech | B2: 1 | C2: 10 | D2: 2019 | E2: ='Consommation du 01.10 au 31.10'!M10 -> 25689 | F2: 1.002 | G2: ='Consommation du 01.10 au 31.10'!U10 -> 333.9 | H2: 8.0278 | I2: ='Consommation du 01.10 au 31.10'!Y10*1000 -> 8580 | J2: 0.84 | K2: ='Consommation du 01.10 au 31.10'!D10 -> 580 | L2: 12.67 | M2: ='Consommation du 01.10 au 31.10'!AC10 -> 121 | N2: 240 | O2: =E2*F2+G2*H2+I2*J2+K2*L2 -> 42976.66
A3: Marrakech | B3: =B2+1 -> 2 | C3: 10 | D3: 2019 | E3: ='Consommation du 01.10 au 31.10'!M11 -> 24721 | F3: 1.002 | G3: ='Consommation du 01.10 au 31.10'!U11 -> 296.8 | H3: 8.0278 | I3: ='Consommation du 01.10 au 31.10'!Y11*1000 -> 8840 | J3: 0.84 | K3: ='Consommation du 01.10 au 31.10'!D11 -> 590 | L3: 12.67 | M3: ='Consommation du 01.10 au 31.10'!AC11 -> 123 | N3: 248 | O3: =E3*F3+G3*H3+I3*J3+K3*L3 -> 42053.993
A4: Marrakech | B4: =B3+1 -> 3 | C4: 10 | D4: 2019 | E4: ='Consommation du 01.10 au 31.10'!M12 -> 23269 | F4: 1.002 | G4: ='Consommation du 01.10 au 31.10'!U12 -> 185.5 | H4: 8.0278 | I4: ='Consommation du 01.10 au 31.10'!Y12*1000 -> 10870 | J4: 0.84 | K4: ='Consommation du 01.10 au 31.10'!D12 -> 670 | L4: 12.67 | M4: ='Consommation du 01.10 au 31.10'!AC12 -> 128 | N4: 264 | O4: =E4*F4+G4*H4+I4*J4+K4*L4 -> 42424.395
A5: Marrakech | B5: =B4+1 -> 4 | C5: 10 | D5: 2019 | E5: ='Consommation du 01.10 au 31.10'!M13 -> 23869 | F5: 1.002 | G5: ='Consommation du 01.10 au 31.10'!U13 -> 185.5 | H5: 8.0278 | I5: ='Consommation du 01.10 au 31.10'!Y13*1000 -> 11880 | J5: 0.84 | K5: ='Consommation du 01.10 au 31.10'!D13 -> 520 | L5: 12.67 | M5: ='Consommation du 01.10 au 31.10'!AC13 -> 133 | N5: 278 | O5: =E5*F5+G5*H5+I5*J5+K5*L5 -> 41973.495
A6: Marrakech | B6: =B5+1 -> 5 | C6: 10 | D6: 2019 | E6: ='Consommation du 01.10 au 31.10'!M14 -> 23606 | F6: 1.002 | G6: ='Consommation du 01.10 au 31.10'!U14 -> 445.2 | H6: 8.0278 | I6: ='Consommation du 01.10 au 31.10'!Y14*1000 -> 11490 | J6: 0.84 | K6: ='Consommation du 01.10 au 31.10'!D14 -> 600 | L6: 12.67 | M6: ='Consommation du 01.10 au 31.10'!AC14 -> 135 | N6: 281 | O6: =E6*F6+G6*H6+I6*J6+K6*L6 -> 44480.789
A7: Marrakech | B7: =B6+1 -> 6 | C7: 10 | D7: 2019 | E7: ='Consommation du 01.10 au 31.10'!M15 -> 24479 | F7: 1.002 | G7: ='Consommation du 01.10 au 31.10'!U15 -> 445.2 | H7: 8.0278 | I7: ='Consommation du 01.10 au 31.10'!Y15*1000 -> 11800 | J7: 0.84 | K7: ='Consommation du 01.10 au 31.10'!D15 -> 580 | L7: 12.67 | M7: ='Consommation du 01.10 au 31.10'!AC15 -> 136 | N7: 282 | O7: =E7*F7+G7*H7+I7*J7+K7*L7 -> 45362.535
A8: Marrakech | B8: =B7+1 -> 7 | C8: 10 | D8: 2019 | E8: ='Consommation du 01.10 au 31.10'!M16 -> 24844 | F8: 1.002 | G8: ='Consommation du 01.10 au 31.10'!U16 -> 630.7 | H8: 8.0278 | I8: ='Consommation du 01.10 au 31.10'!Y16*1000 -> 10190 | J8: 0.84 | K8: ='Consommation du 01.10 au 31.10'!D16 -> 550 | L8: 12.67 | M8: ='Consommation du 01.10 au 31.10'!AC16 -> 132 | N8: 249 | O8: =E8*F8+G8*H8+I8*J8+K8*L8 -> 45484.921
A9: Marrakech | B9: =B8+1 -> 8 | C9: 10 | D9: 2019 | E9: ='Consommation du 01.10 au 31.10'!M17 -> 24734 | F9: 1.002 | G9: ='Consommation du 01.10 au 31.10'!U17 -> 408.1 | H9: 8.0278 | I9: ='Consommation du 01.10 au 31.10'!Y17*1000 -> 10860 | J9: 0.84 | K9: ='Consommation du 01.10 au 31.10'!D17 -> 560 | L9: 12.67 | M9: ='Consommation du 01.10 au 31.10'!AC17 -> 130 | N9: 238 | O9: =E9*F9+G9*H9+I9*J9+K9*L9 -> 44277.213
A10: Marrakech | B10: =B9+1 -> 9 | C10: 10 | D10: 2019 | E10: ='Consommation du 01.10 au 31.10'!M18 -> 24708 | F10: 1.002 | G10: ='Consommation du 01.10 au 31.10'!U18 -> 779.1 | H10: 8.0278 | I10: ='Consommation du 01.10 au 31.10'!Y18*1000 -> 7680 | J10: 0.84 | K10: ='Consommation du 01.10 au 31.10'!D18 -> 540 | L10: 12.67 | M10: ='Consommation du 01.10 au 31.10'!AC18 -> 130 | N10: 233 | O10: =E10*F10+G10*H10+I10*J10+K10*L10 -> 44304.875
A11: Marrakech | B11: =B10+1 -> 10 | C11: 10 | D11: 2019 | E11: ='Consommation du 01.10 au 31.10'!M19 -> 24768 | F11: 1.002 | G11: ='Consommation du 01.10 au 31.10'!U19 -> 704.9 | H11: 8.0278 | I11: ='Consommation du 01.10 au 31.10'!Y19*1000 -> 7320 | J11: 0.84 | K11: ='Consommation du 01.10 au 31.10'!D19 -> 640 | L11: 12.67 | M11: ='Consommation du 01.10 au 31.10'!AC19 -> 105 | N11: 192 | O11: =E11*F11+G11*H11+I11*J11+K11*L11 -> 44733.932
A12: Marrakech | B12: =B11+1 -> 11 | C12: 10 | D12: 2019 | E12: ='Consommation du 01.10 au 31.10'!M20 -> 27285 | F12: 1.002 | G12: ='Consommation du 01.10 au 31.10'!U20 -> 1150.1 | H12: 8.0278 | I12: ='Consommation du 01.10 au 31.10'!Y20*1000 -> 5040 | J12: 0.84 | K12: ='Consommation du 01.10 au 31.10'!D20 -> 630 | L12: 12.67 | M12: ='Consommation du 01.10 au 31.10'!AC20 -> 130 | N12: 219 | O12: =E12*F12+G12*H12+I12*J12+K12*L12 -> 48788.043
A13: Marrakech | B13: =B12+1 -> 12 | C13: 10 | D13: 2019 | E13: ='Consommation du 01.10 au 31.10'!M21 -> 29109 | F13: 1.002 | G13: ='Consommation du 01.10 au 31.10'!U21 -> 742 | H13: 8.0278 | I13: ='Consommation du 01.10 au 31.10'!Y21*1000 -> 3010 | J13: 0.84 | K13: ='Consommation du 01.10 au 31.10'!D21 -> 550 | L13: 12.67 | M13: ='Consommation du 01.10 au 31.10'!AC21 -> 138 | N13: 228 | O13: =E13*F13+G13*H13+I13*J13+K13*L13 -> 44620.746
A14: Marrakech | B14: =B13+1 -> 13 | C14: 10 | D14: 2019 | E14: ='Consommation du 01.10 au 31.10'!M22 -> 28077 | F14: 1.002 | G14: ='Consommation du 01.10 au 31.10'!U22 -> 593.6 | H14: 8.0278 | I14: ='Consommation du 01.10 au 31.10'!Y22*1000 -> 19560 | J14: 0.84 | K14: ='Consommation du 01.10 au 31.10'!D22 -> 600 | L14: 12.67 | M14: ='Consommation du 01.10 au 31.10'!AC22 -> 122 | N14: 189 | O14: =E14*F14+G14*H14+I14*J14+K14*L14 -> 56930.856
... A24: Marrakech | B24: =B23+1 -> 23 | C24: 10 | D24: 2019 | E24: ='Consommation du 01.10 au 31.10'!M32 -> 17435 | F24: 1.002 | G24: ='Consommation du 01.10 au 31.10'!U32 -> 1780.8 | H24: 8.0278 | I24: ='Consommation du 01.10 au 31.10'!Y32*1000 -> 11260 | J24: 0.84 | K24: ='Consommation du 01.10 au 31.10'!D32 -> 630 | L24: 12.67 | M24: ='Consommation du 01.10 au 31.10'!AC32 -> 126 | N24: 301 | O24: =E24*F24+G24*H24+I24*J24+K24*L24 -> 49206.276
A25: Marrakech | B25: =B24+1 -> 24 | C25: 10 | D25: 2019 | E25: ='Consommation du 01.10 au 31.10'!M33 -> 0 | F25: 1.002 | G25: ='Consommation du 01.10 au 31.10'!U33 -> 0 | H25: 8.0278 | I25: ='Consommation du 01.10 au 31.10'!Y33*1000 -> 0 | J25: 0.84 | K25: ='Consommation du 01.10 au 31.10'!D33 -> 0 | L25: 12.67 | M25: ='Consommation du 01.10 au 31.10'!AC33 -> 0 | O25: =E25*F25+G25*H25+I25*J25+K25*L25 -> 0
A26: Marrakech | B26: =B25+1 -> 25 | C26: 10 | D26: 2019 | E26: ='Consommation du 01.10 au 31.10'!M34 -> 0 | F26: 1.002 | G26: ='Consommation du 01.10 au 31.10'!U34 -> 0 | H26: 8.0278 | I26: ='Consommation du 01.10 au 31.10'!Y34*1000 -> 0 | J26: 0.84 | K26: ='Consommation du 01.10 au 31.10'!D34 -> 0 | L26: 12.67 | M26: ='Consommation du 01.10 au 31.10'!AC34 -> 0 | O26: =E26*F26+G26*H26+I26*J26+K26*L26 -> 0
A27: Marrakech | B27: =B26+1 -> 26 | C27: 10 | D27: 2019 | E27: ='Consommation du 01.10 au 31.10'!M35 -> 0 | F27: 1.002 | G27: ='Consommation du 01.10 au 31.10'!U35 -> 0 | H27: 8.0278 | I27: ='Consommation du 01.10 au 31.10'!Y35*1000 -> 0 | J27: 0.84 | K27: ='Consommation du 01.10 au 31.10'!D35 -> 0 | L27: 12.67 | M27: ='Consommation du 01.10 au 31.10'!AC35 -> 0 | O27: =E27*F27+G27*H27+I27*J27+K27*L27 -> 0
A28: Marrakech | B28: =B27+1 -> 27 | C28: 10 | D28: 2019 | E28: ='Consommation du 01.10 au 31.10'!M36 -> 0 | F28: 1.002 | G28: ='Consommation du 01.10 au 31.10'!U36 -> 0 | H28: 8.0278 | I28: ='Consommation du 01.10 au 31.10'!Y36*1000 -> 0 | J28: 0.84 | K28: ='Consommation du 01.10 au 31.10'!D36 -> 0 | L28: 12.67 | M28: ='Consommation du 01.10 au 31.10'!AC36 -> 0 | O28: =E28*F28+G28*H28+I28*J28+K28*L28 -> 0
A29: Marrakech | B29: =B28+1 -> 28 | C29: 10 | D29: 2019 | E29: ='Consommation du 01.10 au 31.10'!M37 -> 0 | F29: 1.002 | G29: ='Consommation du 01.10 au 31.10'!U37 -> 0 | H29: 8.0278 | I29: ='Consommation du 01.10 au 31.10'!Y37*1000 -> 0 | J29: 0.84 | K29: ='Consommation du 01.10 au 31.10'!D37 -> 0 | L29: 12.67 | M29: ='Consommation du 01.10 au 31.10'!AC37 -> 0 | O29: =E29*F29+G29*H29+I29*J29+K29*L29 -> 0
A30: Marrakech | B30: =B29+1 -> 29 | C30: 10 | D30: 2019 | E30: ='Consommation du 01.10 au 31.10'!M38 -> 0 | F30: 1.002 | G30: ='Consommation du 01.10 au 31.10'!U38 -> 0 | H30: 8.0278 | I30: ='Consommation du 01.10 au 31.10'!Y38*1000 -> 0 | J30: 0.84 | K30: ='Consommation du 01.10 au 31.10'!D38 -> 0 | L30: 12.67 | M30: ='Consommation du 01.10 au 31.10'!AC38 -> 0
A31: Marrakech | B31: =B30+1 -> 30 | C31: 10 | D31: 2019 | E31: ='Consommation du 01.10 au 31.10'!M39 -> 0 | F31: 1.002 | G31: ='Consommation du 01.10 au 31.10'!U39 -> 0 | H31: 8.0278 | I31: ='Consommation du 01.10 au 31.10'!Y39*1000 -> 0 | J31: 0.84 | K31: ='Consommation du 01.10 au 31.10'!D39 -> 0 | L31: 12.67 | M31: ='Consommation du 01.10 au 31.10'!AC39 -> 0
A32: Marrakech | B32: =B31+1 -> 31 | C32: 10 | D32: 2019 | E32: ='Consommation du 01.10 au 31.10'!M40 -> 0 | F32: 1.002 | G32: ='Consommation du 01.10 au 31.10'!U40 -> 0 | H32: 8.0278 | I32: ='Consommation du 01.10 au 31.10'!Y40*1000 -> 0 | J32: 0.84 | K32: ='Consommation du 01.10 au 31.10'!D40 -> 0 | L32: 12.67 | M32: ='Consommation du 01.10 au 31.10'!AC40 -> 0

Sheet Consommation du 01.10 au 31.10
B8: Date | D8: Cons Eau/Hotel | F8: Consommation du jour en DH | J8: ELECTRICITE en KWH | M8: total | O8: Consommation du jour en DH | Q8: Cons Elec/Villa | S8: Cons Elec/RIAD | U8: GAZ en Kg | W8: Consommation du jour en DH | AB8: Temp moyenne du jour °C | AC8: Room Nights | AD8: % Occupation | AE8: Temp Piscine Adulte à 7h00 °C | AF8: Temp Piscine Adulte à 15h00 °C | AG8: Temp Piscine famille à 07h00 ° C | AH8: Temp Piscine famille à 15h00 ° C
J9: creuse 81 | K9: pleine 82 | L9: pointe 83 | X9: Compteur AVEO Mwh | Y9: consommation eau choud en Mwh | Z9: consommation du jour en DH
B10: 43739 | D10: ='Suivi EAU-ELEC'!C15 -> 580 | F10: =D10*12.67 -> 7348.6 | J10: ='Suivi EAU-ELEC'!E15 -> 7408 | K10: ='Suivi EAU-ELEC'!G15 -> 12795 | L10: ='Suivi EAU-ELEC'!I15 -> 5486 | M10: =L10+K10+J10 -> 25689 | O10: =M10*1.002 -> 25740.378 | U10: ='Suvi Gaz'!O10 -> 333.9 | W10: =U10*7.61305 -> 2541.9974 | X10: 14704.65 | Y10: =IF(X11<X10,0,X11-X10) -> 8.58 | Z10: =Y10*0.84*1000 -> 7207.2 | AB10: 35 | AC10: 121 | AD10: 0.9167 | AE10: 27 | AF10: 28 | AG10: 26 | AH10: 27
B11: =B10+1 -> 43740 | D11: ='Suivi EAU-ELEC'!C16 -> 590 | F11: =D11*12.67 -> 7475.3 | J11: ='Suivi EAU-ELEC'!E16 -> 7584 | K11: ='Suivi EAU-ELEC'!G16 -> 12155 | L11: ='Suivi EAU-ELEC'!I16 -> 4982 | M11: =L11+K11+J11 -> 24721 | O11: =M11*1.002 -> 24770.442 | U11: ='Suvi Gaz'!O11 -> 296.8 | W11: =U11*7.61305 -> 2259.5532 | X11: 14713.23 | Y11: =IF(X12<X11,0,X12-X11) -> 8.84 | Z11: =Y11*0.84*1000 -> 7425.6 | AB11: 30 | AC11: 123 | AD11: 0.8913 | AE11: 27 | AF11: 27 | AG11: 26 | AH11: 27
B12: =B11+1 -> 43741 | D12: ='Suivi EAU-ELEC'!C17 -> 670 | F12: =D12*12.67 -> 8488.9 | J12: ='Suivi EAU-ELEC'!E17 -> 6958 | K12: ='Suivi EAU-ELEC'!G17 -> 11612 | L12: ='Suivi EAU-ELEC'!I17 -> 4699 | M12: =L12+K12+J12 -> 23269 | O12: =M12*1.002 -> 23315.538 | U12: ='Suvi Gaz'!O12 -> 185.5 | W12: =U12*7.61305 -> 1412.2208 | X12: 14722.07 | Y12: =IF(X13<X12,0,X13-X12) -> 10.87 | Z12: =Y12*0.84*1000 -> 9130.8 | AB12: 27 | AC12: 128 | AD12: 0.9343 | AE12: 26 | AF12: 27 | AG12: 26 | AH12: 27
B13: =B12+1 -> 43742 | D13: ='Suivi EAU-ELEC'!C18 -> 520 | F13: =D13*12.67 -> 6588.4 | J13: ='Suivi EAU-ELEC'!E18 -> 7290 | K13: ='Suivi EAU-ELEC'!G18 -> 11551 | L13: ='Suivi EAU-ELEC'!I18 -> 5028 | M13: =L13+K13+J13 -> 23869 | O13: =M13*1.002 -> 23916.738 | U13: ='Suvi Gaz'!O13 -> 185.5 | W13: =U13*7.61305 -> 1412.2208 | X13: 14732.94 | Y13: =IF(X14<X13,0,X14-X13) -> 11.88 | Z13: =Y13*0.84*1000 -> 9979.2 | AB13: 29 | AC13: 133 | AD13: 0.9708 | AE13: 26.5 | AF13: 27 | AG13: 26 | AH13: 27
B14: =B13+1 -> 43743 | D14: ='Suivi EAU-ELEC'!C19 -> 600 | F14: =D14*12.67 -> 7602 | J14: ='Suivi EAU-ELEC'!E19 -> 7194 | K14: ='Suivi EAU-ELEC'!G19 -> 11304 | L14: ='Suivi EAU-ELEC'!I19 -> 5108 | M14: =L14+K14+J14 -> 23606 | O14: =M14*1.002 -> 23653.212 | U14: ='Suvi Gaz'!O14 -> 445.2 | W14: =U14*7.61305 -> 3389.3299 | X14: 14744.82 | Y14: =IF(X15<X14,0,X15-X14) -> 11.49 | Z14: =Y14*0.84*1000 -> 9651.6 | AB14: 30 | AC14: 135 | AD14: 0.9854 | AE14: 26.5 | AF14: 28 | AG14: 26 | AH14: 27.5
B15: =B14+1 -> 43744 | D15: ='Suivi EAU-ELEC'!C20 -> 580 | F15: =D15*12.67 -> 7348.6 | J15: ='Suivi EAU-ELEC'!E20 -> 7476 | K15: ='Suivi EAU-ELEC'!G20 -> 11878 | L15: ='Suivi EAU-ELEC'!I20 -> 5125 | M15: =L15+K15+J15 -> 24479 | O15: =M15*1.002 -> 24527.958 | U15: ='Suvi Gaz'!O15 -> 445.2 | W15: =U15*7.61305 -> 3389.3299 | X15: 14756.31 | Y15: =IF(X16<X15,0,X16-X15) -> 11.8 | Z15: =Y15*0.84*1000 -> 9912 | AB15: 32 | AC15: 136 | AD15: 0.9855 | AE15: 27.5 | AF15: 28 | AG15: 27 | AH15: 28
B16: =B15+1 -> 43745 | D16: ='Suivi EAU-ELEC'!C21 -> 550 | F16: =D16*12.67 -> 6968.5 | J16: ='Suivi EAU-ELEC'!E21 -> 7485 | K16: ='Suivi EAU-ELEC'!G21 -> 12020 | L16: ='Suivi EAU-ELEC'!I21 -> 5339 | M16: =L16+K16+J16 -> 24844 | O16: =M16*1.002 -> 24893.688 | U16: ='Suvi Gaz'!O16 -> 630.7 | W16: =U16*7.61305 -> 4801.5506 | X16: 14768.11 | Y16: =IF(X17<X16,0,X17-X16) -> 10.19 | Z16: =Y16*0.84*1000 -> 8559.6 | AB16: 32 | AC16: 132 | AD16: 0.9635 | AE16: 27.5 | AF16: 29 | AG16: 27.5 | AH16: 27.5
B17: =B16+1 -> 43746 | D17: ='Suivi EAU-ELEC'!C22 -> 560 | F17: =D17*12.67 -> 7095.2 | J17: ='Suivi EAU-ELEC'!E22 -> 7374 | K17: ='Suivi EAU-ELEC'!G22 -> 11736 | L17: ='Suivi EAU-ELEC'!I22 -> 5624 | M17: =L17+K17+J17 -> 24734 | O17: =M17*1.002 -> 24783.468 | U17: ='Suvi Gaz'!O17 -> 408.1 | W17: =U17*7.61305 -> 3106.8857 | X17: 14778.3 | Y17: =IF(X18<X17,0,X18-X17) -> 10.86 | Z17: =Y17*0.84*1000 -> 9122.4 | AB17: 32 | AC17: 130 | AD17: 0.9559 | AE17: 27.5 | AF17: 28 | AG17: 27.5 | AH17: 28
B18: =B17+1 -> 43747 | D18: ='Suivi EAU-ELEC'!C23 -> 540 | F18: =D18*12.67 -> 6841.8 | J18: ='Suivi EAU-ELEC'!E23 -> 7277 | K18: ='Suivi EAU-ELEC'!G23 -> 11970 | L18: ='Suivi EAU-ELEC'!I23 -> 5461 | M18: =L18+K18+J18 -> 24708 | O18: =M18*1.002 -> 24757.416 | U18: ='Suvi Gaz'!O18 -> 779.1 | W18: =U18*7.61305 -> 5931.3273 | X18: 14789.16 | Y18: =IF(X19<X18,0,X19-X18) -> 7.68 | Z18: =Y18*0.84*1000 -> 6451.2 | AB18: 31 | AC18: 130 | AD18: 0.942 | AE18: 27.5 | AF18: 27.5 | AG18: 27.5 | AH18: 27.5
B19: =B18+1 -> 43748 | D19: ='Suivi EAU-ELEC'!C24 -> 640 | F19: =D19*12.67 -> 8108.8 | J19: ='Suivi EAU-ELEC'!E24 -> 7484 | K19: ='Suivi EAU-ELEC'!G24 -> 11290 | L19: ='Suivi EAU-ELEC'!I24 -> 5994 | M19: =L19+K19+J19 -> 24768 | O19: =M19*1.002 -> 24817.536 | U19: ='Suvi Gaz'!O19 -> 704.9 | W19: =U19*7.61305 -> 5366.4389 | X19: 14796.84 | Y19: =IF(X20<X19,0,X20-X19) -> 7.32 | Z19: =Y19*0.84*1000 -> 6148.8 | AB19: 30 | AC19: 105 | AD19: 0.7664 | AE19: 28 | AF19: 29 | AG19: 26.5 | AH19: 27
B20: =B19+1 -> 43749 | D20: ='Suivi EAU-ELEC'!C25 -> 630 | F20: =D20*12.67 -> 7982.1 | J20: ='Suivi EAU-ELEC'!E25 -> 7778 | K20: ='Suivi EAU-ELEC'!G25 -> 13204 | L20: ='Suivi EAU-ELEC'!I25 -> 6303 | M20: =L20+K20+J20 -> 27285 | O20: =M20*1.002 -> 27339.57 | U20: ='Suvi Gaz'!O20 -> 1150.1 | W20: =U20*7.61305 -> 8755.7688 | X20: 14804.16 | Y20: =IF(X21<X20,0,X21-X20) -> 5.04 | Z20: =Y20*0.84*1000 -> 4233.6 | AA20: 14 | AB20: 28 | AC20: 130 | AD20: 0.9353 | AE20: 28 | AF20: 30 | AG20: 26.5 | AH20: 28
B21: =B20+1 -> 43750 | D21: ='Suivi EAU-ELEC'!C26 -> 550 | F21: =D21*12.67 -> 6968.5 | J21: ='Suivi EAU-ELEC'!E26 -> 8277 | K21: ='Suivi EAU-ELEC'!G26 -> 14267 | L21: ='Suivi EAU-ELEC'!I26 -> 6565 | M21: =L21+K21+J21 -> 29109 | O21: =M21*1.002 -> 29167.218 | U21: ='Suvi Gaz'!O21 -> 742 | W21: =U21*7.61305 -> 5648.8831 | X21: 14809.2 | Y21: =IF(X22<X21,0,X22-X21) -> 3.01 | Z21: =Y21*0.84*1000 -> 2528.4 | AA21: 14 | AB21: 29 | AC21: 138 | AD21: 0.9928 | AE21: 27.5 | AF21: 30 | AG21: 27.5 | AH21: 28
B22: =B21+1 -> 43751 | D22: ='Suivi EAU-ELEC'!C27 -> 600 | F22: =D22*12.67 -> 7602 | J22: ='Suivi EAU-ELEC'!E27 -> 8116 | K22: ='Suivi EAU-ELEC'!G27 -> 14498 | L22: ='Suivi EAU-ELEC'!I27 -> 5463 | M22: =L22+K22+J22 -> 28077 | O22: =M22*1.002 -> 28133.154 | U22: ='Suvi Gaz'!O22 -> 593.6 | W22: =U22*7.61305 -> 4519.1065 | X22: 14812.21 | Y22: =IF(X23<X22,0,X23-X22) -> 19.56 | Z22: =Y22*0.84*1000 -> 16430.4 | AB22: 29 | AC22: 122 | AD22: 0.8971 | AE22: 27.5 | AF22: 30 | AG22: 28 | AH22: 27
B23: =B22+1 -> 43752 | D23: ='Suivi EAU-ELEC'!C28 -> 680 | F23: =D23*12.67 -> 8615.6 | J23: ='Suivi EAU-ELEC'!E28 -> 7441 | K23: ='Suivi EAU-ELEC'!G28 -> 12784 | L23: ='Suivi EAU-ELEC'!I28 -> 5425 | M23: =L23+K23+J23 -> 25650 | O23: =M23*1.002 -> 25701.3 | U23: ='Suvi Gaz'!O23 -> 593.6 | W23: =U23*7.61305 -> 4519.1065 | X23: 14831.77 | Y23: =IF(X24<X23,0,X24-X23) -> 11.42 | Z23: =Y23*0.84*1000 -> 9592.8 | AB23: 23 | AC23: 116 | AD23: 0.8529 | AE23: 27.5 | AF23: 28.5 | AG23: 27.5 | AH23: 27
B24: =B23+1 -> 43753 | D24: ='Suivi EAU-ELEC'!C29 -> 510 | F24: =D24*12.67 -> 6461.7 | J24: ='Suivi EAU-ELEC'!E29 -> 6947 | K24: ='Suivi EAU-ELEC'!G29 -> 10033 | L24: ='Suivi EAU-ELEC'!I29 -> 4424 | M24: =L24+K24+J24 -> 21404 | O24: =M24*1.002 -> 21446.808 | U24: ='Suvi Gaz'!O24 -> 259.7 | W24: =U24*7.61305 -> 1977.1091 | X24: 14843.19 | Y24: =IF(X25<X24,0,X25-X24) -> 12.97 | Z24: =Y24*0.84*1000 -> 10894.8 | AB24: 24 | AC24: 99 | AD24: 0.7388 | AE24: 27.5 | AF24: 29 | AG24: 23 | AH24: 24
B25: =B24+1 -> 43754 | D25: ='Suivi EAU-ELEC'!C30 -> 600 | F25: =D25*12.67 -> 7602 | J25: ='Suivi EAU-ELEC'!E30 -> 6518 | K25: ='Suivi EAU-ELEC'!G30 -> 9313 | L25: ='Suivi EAU-ELEC'!I30 -> 4276 | M25: =L25+K25+J25 -> 20107 | O25: =M25*1.002 -> 20147.214 | U25: ='Suvi Gaz'!O25 -> 259.7 | W25: =U25*7.61305 -> 1977.1091 | X25: 14856.16 | Y25: =IF(X26<X25,0,X26-X25) -> 13.27 | Z25: =Y25*0.84*1000 -> 11146.8 | AB25: 22 | AC25: 100 | AD25: 0.7692 | AE25: 27 | AF25: 28 | AG25: 27 | AH25: 28
B26: =B25+1 -> 43755 | D26: ='Suivi EAU-ELEC'!C31 -> 520 | F26: =D26*12.67 -> 6588.4 | J26: ='Suivi EAU-ELEC'!E31 -> 6512 | K26: ='Suivi EAU-ELEC'!G31 -> 9075 | L26: ='Suivi EAU-ELEC'!I31 -> 4165 | M26: =L26+K26+J26 -> 19752 | O26: =M26*1.002 -> 19791.504 | U26: ='Suvi Gaz'!O26 -> 556.5 | W26: =U26*7.61305 -> 4236.6623 | X26: 14869.43 | Y26: =IF(X27<X26,0,X27-X26) -> 13.31 | Z26: =Y26*0.84*1000 -> 11180.4 | AB26: 22 | AC26: 121 | AD26: 0.8832 | AE26: 26.5 | AF26: 29 | AG26: 26.5 | AH26: 27.5
B27: =B26+1 -> 43756 | D27: ='Suivi EAU-ELEC'!C32 -> 510 | F27: =D27*12.67 -> 6461.7 | J27: ='Suivi EAU-ELEC'!E32 -> 6399 | K27: ='Suivi EAU-ELEC'!G32 -> 9218 | L27: ='Suivi EAU-ELEC'!I32 -> 4463 | M27: =L27+K27+J27 -> 20080 | O27: =M27*1.002 -> 20120.16 | U27: ='Suvi Gaz'!O27 -> 445.2 | W27: =U27*7.61305 -> 3389.3299 | X27: 14882.74 | Y27: =IF(X28<X27,0,X28-X27) -> 13.27 | Z27: =Y27*0.84*1000 -> 11146.8 | AB27: 25 | AC27: 131 | AD27: 0.9562 | AE27: 27 | AF27: 29 | AG27: 27.5 | AH27: 29
B28: =B27+1 -> 43757 | D28: ='Suivi EAU-ELEC'!C33 -> 590 | F28: =D28*12.67 -> 7475.3 | J28: ='Suivi EAU-ELEC'!E33 -> 7030 | K28: ='Suivi EAU-ELEC'!G33 -> 9740 | L28: ='Suivi EAU-ELEC'!I33 -> 4712 | M28: =L28+K28+J28 -> 21482 | O28: =M28*1.002 -> 21524.964 | U28: ='Suvi Gaz'!O28 -> 556.5 | W28: =U28*7.61305 -> 4236.6623 | X28: 14896.01 | Y28: =IF(X29<X28,0,X29-X28) -> 14.35 | Z28: =Y28*0.84*1000 -> 12054 | AB28: 25 | AC28: 133 | AD28: 0.9779 | AE28: 27 | AF28: 29 | AG28: 27 | AH28: 29
B29: =B28+1 -> 43758 | D29: ='Suivi EAU-ELEC'!C34 -> 550 | F29: =D29*12.67 -> 6968.5 | J29: ='Suivi EAU-ELEC'!E34 -> 6284 | K29: ='Suivi EAU-ELEC'!G34 -> 8085 | L29: ='Suivi EAU-ELEC'!I34 -> 4134 | M29: =L29+K29+J29 -> 18503 | O29: =M29*1.002 -> 18540.006 | U29: ='Suvi Gaz'!O29 -> 333.9 | W29: =U29*7.61305 -> 2541.9974 | X29: 14910.36 | Y29: =IF(X30<X29,0,X30-X29) -> 16.16 | Z29: =Y29*0.84*1000 -> 13574.4 | AB29: 22 | AC29: 126 | AD29: 0.9403 | AE29: 27 | AF29: 29 | AG29: 27 | AH29: 29
B30: =B29+1 -> 43759 | D30: ='Suivi EAU-ELEC'!C35 -> 570 | F30: =D30*12.67 -> 7221.9 | J30: ='Suivi EAU-ELEC'!E35 -> 5372 | K30: ='Suivi EAU-ELEC'!G35 -> 8306 | L30: ='Suivi EAU-ELEC'!I35 -> 4163 | M30: =L30+K30+J30 -> 17841 | O30: =M30*1.002 -> 17876.682 | U30: ='Suvi Gaz'!O30 -> 445.2 | W30: =U30*7.61305 -> 3389.3299 | X30: 14926.52 | Y30: =IF(X31<X30,0,X31-X30) -> 17.79 | Z30: =Y30*0.84*1000 -> 14943.6 | AB30: 18 | AC30: 128 | AD30: 0.9343 | AE30: 27 | AF30: 27.5 | AG30: 27 | AH30: 27.5
B31: =B30+1 -> 43760 | D31: ='Suivi EAU-ELEC'!C36 -> 640 | F31: =D31*12.67 -> 8108.8 | J31: ='Suivi EAU-ELEC'!E36 -> 5992 | K31: ='Suivi EAU-ELEC'!G36 -> 7636 | L31: ='Suivi EAU-ELEC'!I36 -> 3867 | M31: =L31+K31+J31 -> 17495 | O31: =M31*1.002 -> 17529.99 | U31: ='Suvi Gaz'!O31 -> 630.7 | W31: =U31*7.61305 -> 4801.5506 | X31: 14944.31 | Y31: =IF(X32<X31,0,X32-X31) -> 18.46 | Z31: =Y31*0.84*1000 -> 15506.4 | AB31: 18 | AC31: 133 | AD31: 0.9638 | AE31: 26 | AF31: 26.5 | AG31: 26.5 | AH31: 27
B32: =B31+1 -> 43761 | D32: ='Suivi EAU-ELEC'!C37 -> 630 | F32: =D32*12.67 -> 7982.1 | J32: ='Suivi EAU-ELEC'!E37 -> 5500 | K32: ='Suivi EAU-ELEC'!G37 -> 7753 | L32: ='Suivi EAU-ELEC'!I37 -> 4182 | M32: =L32+K32+J32 -> 17435 | O32: =M32*1.002 -> 17469.87 | U32: ='Suvi Gaz'!O32 -> 1780.8 | W32: =U32*7.61305 -> 13557.319 | X32: 14962.77 | Y32: =IF(X33<X32,0,X33-X32) -> 11.26 | Z32: =Y32*0.84*1000 -> 9458.4 | AB32: 17 | AC32: 126 | AD32: 0.913 | AE32: 27 | AG32: 28
B33: =B32+1 -> 43762 | D33: ='Suivi EAU-ELEC'!C38 -> 0 | F33: =D33*12.67 -> 0 | J33: ='Suivi EAU-ELEC'!E38 -> 0 | K33: ='Suivi EAU-ELEC'!G38 -> 0 | L33: ='Suivi EAU-ELEC'!I38 -> 0 | M33: =L33+K33+J33 -> 0 | O33: =M33*1.002 -> 0 | U33: ='Suvi Gaz'!O33 -> 0 | W33: =U33*7.61305 -> 0 | X33: 14974.03 | Y33: =IF(X34<X33,0,X34-X33) -> 0 | Z33: =Y33*0.84*1000 -> 0 | AH33: 28
B34: =B33+1 -> 43763 | D34: ='Suivi EAU-ELEC'!C39 -> 0 | F34: =D34*12.67 -> 0 | J34: ='Suivi EAU-ELEC'!E39 -> 0 | K34: ='Suivi EAU-ELEC'!G39 -> 0 | L34: ='Suivi EAU-ELEC'!I39 -> 0 | M34: =L34+K34+J34 -> 0 | O34: =M34*1.002 -> 0 | U34: ='Suvi Gaz'!O34 -> 0 | W34: =U34*7.61305 -> 0 | Y34: =IF(X35<X34,0,X35-X34) -> 0 | Z34: =Y34*0.84*1000 -> 0 | AH34: 28
B35: =B34+1 -> 43764 | D35: ='Suivi EAU-ELEC'!C40 -> 0 | F35: =D35*12.67 -> 0 | J35: ='Suivi EAU-ELEC'!E40 -> 0 | K35: ='Suivi EAU-ELEC'!G40 -> 0 | L35: ='Suivi EAU-ELEC'!I40 -> 0 | M35: =L35+K35+J35 -> 0 | O35: =M35*1.002 -> 0 | U35: ='Suvi Gaz'!O35 -> 0 | W35: =U35*7.61305 -> 0 | Y35: =IF(X36<X35,0,X36-X35) -> 0 | Z35: =Y35*0.84*1000 -> 0
B36: =B35+1 -> 43765 | D36: ='Suivi EAU-ELEC'!C41 -> 0 | F36: =D36*12.67 -> 0 | J36: ='Suivi EAU-ELEC'!E41 -> 0 | K36: ='Suivi EAU-ELEC'!G41 -> 0 | L36: ='Suivi EAU-ELEC'!I41 -> 0 | M36: =L36+K36+J36 -> 0 | O36: =M36*1.002 -> 0 | U36: ='Suvi Gaz'!O36 -> 0 | W36: =U36*7.61305 -> 0 | Y36: =IF(X37<X36,0,X37-X36) -> 0 | Z36: =Y36*0.84*1000 -> 0
B37: =B36+1 -> 43766 | D37: ='Suivi EAU-ELEC'!C42 -> 0 | F37: =D37*12.67 -> 0 | J37: ='Suivi EAU-ELEC'!E42 -> 0 | K37: ='Suivi EAU-ELEC'!G42 -> 0 | L37: ='Suivi EAU-ELEC'!I42 -> 0 | M37: =L37+K37+J37 -> 0 | O37: =M37*1.002 -> 0 | U37: ='Suvi Gaz'!O37 -> 0 | W37: =U37*7.61305 -> 0 | Y37: =IF(X38<X37,0,X38-X37) -> 0 | Z37: =Y37*0.84*1000 -> 0
B38: =B37+1 -> 43767 | D38: ='Suivi EAU-ELEC'!C43 -> 0 | F38: =D38*12.67 -> 0 | J38: ='Suivi EAU-ELEC'!E43 -> 0 | K38: ='Suivi EAU-ELEC'!G43 -> 0 | L38: ='Suivi EAU-ELEC'!I43 -> 0 | M38: =L38+K38+J38 -> 0 | O38: =M38*1.002 -> 0 | U38: ='Suvi Gaz'!O38 -> 0 | W38: =U38*7.61305 -> 0 | Y38: =IF(X39<X38,0,X39-X38) -> 0 | Z38: =Y38*0.84*1000 -> 0
B39: =B38+1 -> 43768 | D39: ='Suivi EAU-ELEC'!C44 -> 0 | F39: =D39*12.67 -> 0 | J39: ='Suivi EAU-ELEC'!E44 -> 0 | K39: ='Suivi EAU-ELEC'!G44 -> 0 | L39: ='Suivi EAU-ELEC'!I44 -> 0 | M39: =L39+K39+J39 -> 0 | O39: =M39*1.002 -> 0 | U39: ='Suvi Gaz'!O39 -> 0 | W39: =U39*7.61305 -> 0 | Y39: =IF(X40<X39,0,X40-X39) -> 0 | Z39: =Y39*0.84*1000 -> 0
B40: =B39+1 -> 43769 | D40: ='Suivi EAU-ELEC'!C45 -> 0 | F40: =D40*12.67 -> 0 | J40: ='Suivi EAU-ELEC'!E45 -> 0 | K40: ='Suivi EAU-ELEC'!G45 -> 0 | L40: ='Suivi EAU-ELEC'!I45 -> 0 | M40: =L40+K40+J40 -> 0 | O40: =M40*1.002 -> 0 | U40: ='Suvi Gaz'!O40 -> 0 | W40: =U40*7.61305 -> 0 | Y40: =IF(X41<X40,0,X41-X40) -> 0 | Z40: =Y40*0.84*1000 -> 0
D41: =SUM(D10:D40) -> 13410 | F41: =SUM(F10:H40) -> 169904.7 | J41: =SUM(J10:J40) -> 161696 | K41: =SUM(K10:K40) -> 252223 | L41: =SUM(L10:L40) -> 114988 | M41: =SUM(M10:M40) -> 528907 | O41: =SUM(O10:O40) -> 529964.81 | Q41: =SUM(Q10:Q40) -> 0 | S41: =SUM(S10:S40) -> 0 | U41: =SUM(U10:U40) -> 12762.4 | W41: =SUM(W10:W40) -> 97160.789 | Z41: =SUM(Z10:Z40) -> 226279.2
A43: ELECTRICITE / Kw/h | D43: creuse 81 | F43: 1.002 | G43: =J41 -> 161696 | J43: =G43*F43 -> 162019.39 | L43: =J43+J44+J45 -> 529964.81
D44: pleine 82 | F44: 1.002 | G44: =K41 -> 252223 | J44: =G44*F44 -> 252727.45
D45: pointe 83 | F45: 1.002 | G45: =L41 -> 114988 | J45: =G45*F45 -> 115217.98
A46: EAU HOTEL M3 | F46: 12.67 | G46: =D41 -> 13410 | J46: =G46*F46 -> 169904.7 | L46: =J46 -> 169904.7
A47: GAZ Kg | F47: 7.61305 | G47: =U41 -> 12762.4 | J47: =G47*F47 -> 97160.789 | L47: =J47 -> 97160.789

Sheet Suvi Gaz
D1: suivi Gaz
Q2: 803 | T2: 519 | W2: 800 | Z2: 802
B3: Relvé C1 | C3: cons C1 | D3: Relvé C2 | E3: cons C2 | F3: Relvé C3 | G3: cons C3 | H3: Relvé C4 | I3: cons C4 | J3: ∑ des relevés | K3: moyen general % | L3: con.j | M3: ∑ de volume en L | N3: cons./jen L | O3: cons./jen Kg | P3: cons./jen DH | Q3: livraison C1 | R3: %Avant | S3: % Après | T3: livraison C2 | U3: %Avant | V3: % Après | W3: livraison C3 | X3: %Avant | Y3: % Après | Z3: livraison C4 | AA3: %Avant | AB3: % Après | AC3: total livraison | AD3: moyen general % Avant L | AE3: moyen general % Aaprés L
A4: 43733 | B4: 65 | C4: =IF(AC4>0,((B4-R4)+(S4-B5)),IF(B5=0, ,(B4-B5))) -> -19 | D4: 67 | E4: =IF(AC4>0,((D4-U4)+(V4-D5)),IF(D5=0, ,(D4-D5))) -> -18 | F4: 62 | G4: =IF(AC4>0,((F4-X4)+(Y4-F5)),IF(F5=0, ,(F4-F5))) -> -22 | H4: 65 | I4: =IF(AC4>0,((H4-AA4)+(AB4-H5)),IF(H5=0, ,(H4-H5))) -> -19 | J4: =B4+D4+F4+H4 -> 259 | K4: =J4/4 -> 64.75 | L4: =IF(AC4>0,((K4-AD4)+(AE4-K5)),IF(K5=0, ,(K4-K5))) -> -19.5 | M4: =7000*4 -> 28000 | N4: =L4*M4/100 -> -5460 | O4: =N4*0.53 -> -2893.8 | P4: =O4*7.61305 -> -22030.644 | AC4: =Q4+T4+W4+Z4 -> 0 | AD4: =(R4+U4+X4+AA4)/4 -> 0 | AE4: =(S4+V4+Y4+AB4)/4 -> 0
A5: =A4+1 -> 43734 | B5: 84 | C5: =IF(AC5>0,((B5-R5)+(S5-B6)),IF(B6=0, ,(B5-B6))) -> 22 | D5: 85 | E5: =IF(AC5>0,((D5-U5)+(V5-D6)),IF(D6=0, ,(D5-D6))) -> 21 | F5: 84 | G5: =IF(AC5>0,((F5-X5)+(Y5-F6)),IF(F6=0, ,(F5-F6))) -> 24 | H5: 84 | I5: =IF(AC5>0,((H5-AA5)+(AB5-H6)),IF(H6=0, ,(H5-H6))) -> 22 | J5: =B5+D5+F5+H5 -> 337 | K5: =J5/4 -> 84.25 | L5: =IF(AC5>0,((K5-AD5)+(AE5-K6)),IF(K6=0, ,(K5-K6))) -> 22.25 | M5: =7000*4 -> 28000 | N5: =L5*M5/100 -> 6230 | O5: =N5*0.53 -> 3301.9 | P5: =O5*7.61305 -> 25137.53 | Q5: 2392 | R5: 64 | S5: 85 | T5: 1920 | U5: 65 | V5: 85 | W5: 2109 | X5: 62 | Y5: 85 | Z5: 1919 | AA5: 64 | AB5: 85 | AC5: =Q5+T5+W5+Z5 -> 8340 | AD5: =(R5+U5+X5+AA5)/4 -> 63.75 | AE5: =(S5+V5+Y5+AB5)/4 -> 85
A6: =A5+1 -> 43735 | B6: 83 | C6: =IF(AC6>0,((B6-R6)+(S6-B7)),IF(B7=0, ,(B6-B7))) -> 1 | D6: 84 | E6: =IF(AC6>0,((D6-U6)+(V6-D7)),IF(D7=0, ,(D6-D7))) -> 1 | F6: 83 | G6: =IF(AC6>0,((F6-X6)+(Y6-F7)),IF(F7=0, ,(F6-F7))) -> 2 | H6: 83 | I6: =IF(AC6>0,((H6-AA6)+(AB6-H7)),IF(H7=0, ,(H6-H7))) -> 3 | J6: =B6+D6+F6+H6 -> 333 | K6: =J6/4 -> 83.25 | L6: =IF(AC6>0,((K6-AD6)+(AE6-K7)),IF(K7=0, ,(K6-K7))) -> 1.75 | M6: =7000*4 -> 28000 | N6: =L6*M6/100 -> 490 | O6: =N6*0.53 -> 259.7 | P6: =O6*7.61305 -> 1977.1091 | AC6: =Q6+T6+W6+Z6 -> 0 | AD6: =(R6+U6+X6+AA6)/4 -> 0 | AE6: =(S6+V6+Y6+AB6)/4 -> 0
A7: =A6+1 -> 43736 | B7: 82 | C7: =IF(AC7>0,((B7-R7)+(S7-B8)),IF(B8=0, ,(B7-B8))) -> 3 | D7: 83 | E7: =IF(AC7>0,((D7-U7)+(V7-D8)),IF(D8=0, ,(D7-D8))) -> 1 | F7: 81 | G7: =IF(AC7>0,((F7-X7)+(Y7-F8)),IF(F8=0, ,(F7-F8))) -> 3 | H7: 80 | I7: =IF(AC7>0,((H7-AA7)+(AB7-H8)),IF(H8=0, ,(H7-H8))) -> 1 | J7: =B7+D7+F7+H7 -> 326 | K7: =J7/4 -> 81.5 | L7: =IF(AC7>0,((K7-AD7)+(AE7-K8)),IF(K8=0, ,(K7-K8))) -> 2 | M7: =7000*4 -> 28000 | N7: =L7*M7/100 -> 560 | O7: =N7*0.53 -> 296.8 | P7: =O7*7.61305 -> 2259.5532 | AC7: =Q7+T7+W7+Z7 -> 0 | AD7: =(R7+U7+X7+AA7)/4 -> 0 | AE7: =(S7+V7+Y7+AB7)/4 -> 0
A8: =A7+1 -> 43737 | B8: 79 | C8: =IF(AC8>0,((B8-R8)+(S8-B9)),IF(B9=0, ,(B8-B9))) -> 4 | D8: 82 | E8: =IF(AC8>0,((D8-U8)+(V8-D9)),IF(D9=0, ,(D8-D9))) -> 3 | F8: 78 | G8: =IF(AC8>0,((F8-X8)+(Y8-F9)),IF(F9=0, ,(F8-F9))) -> 3 | H8: 79 | I8: =IF(AC8>0,((H8-AA8)+(AB8-H9)),IF(H9=0, ,(H8-H9))) -> 4 | J8: =B8+D8+F8+H8 -> 318 | K8: =J8/4 -> 79.5 | L8: =IF(AC8>0,((K8-AD8)+(AE8-K9)),IF(K9=0, ,(K8-K9))) -> 3.5 | M8: =7000*4 -> 28000 | N8: =L8*M8/100 -> 980 | O8: =N8*0.53 -> 519.4 | P8: =O8*7.61305 -> 3954.2182 | AC8: =Q8+T8+W8+Z8 -> 0 | AD8: =(R8+U8+X8+AA8)/4 -> 0 | AE8: =(S8+V8+Y8+AB8)/4 -> 0
A9: =A8+1 -> 43738 | B9: 75 | C9: =IF(AC9>0,((B9-R9)+(S9-B10)),IF(B10=0, ,(B9-B10))) -> 3 | D9: 79 | E9: =IF(AC9>0,((D9-U9)+(V9-D10)),IF(D10=0, ,(D9-D10))) -> 5 | F9: 75 | G9: =IF(AC9>0,((F9-X9)+(Y9-F10)),IF(F10=0, ,(F9-F10))) -> 5 | H9: 75 | I9: =IF(AC9>0,((H9-AA9)+(AB9-H10)),IF(H10=0, ,(H9-H10))) -> 4 | J9: =B9+D9+F9+H9 -> 304 | K9: =J9/4 -> 76 | L9: =IF(AC9>0,((K9-AD9)+(AE9-K10)),IF(K10=0, ,(K9-K10))) -> 4.25 | M9: =7000*4 -> 28000 | N9: =L9*M9/100 -> 1190 | O9: =N9*0.53 -> 630.7 | P9: =O9*7.61305 -> 4801.5506 | AC9: =Q9+T9+W9+Z9 -> 0 | AD9: =(R9+U9+X9+AA9)/4 -> 0 | AE9: =(S9+V9+Y9+AB9)/4 -> 0
A10: =A9+1 -> 43739 | B10: 72 | C10: =IF(AC10>0,((B10-R10)+(S10-B11)),IF(B11=0, ,(B10-B11))) -> 2 | D10: 74 | E10: =IF(AC10>0,((D10-U10)+(V10-D11)),IF(D11=0, ,(D10-D11))) -> 3 | F10: 70 | G10: =IF(AC10>0,((F10-X10)+(Y10-F11)),IF(F11=0, ,(F10-F11))) -> 2 | H10: 71 | I10: =IF(AC10>0,((H10-AA10)+(AB10-H11)),IF(H11=0, ,(H10-H11))) -> 2 | J10: =B10+D10+F10+H10 -> 287 | K10: =J10/4 -> 71.75 | L10: =IF(AC10>0,((K10-AD10)+(AE10-K11)),IF(K11=0, ,(K10-K11))) -> 2.25 | M10: =7000*4 -> 28000 | N10: =L10*M10/100 -> 630 | O10: =N10*0.53 -> 333.9 | P10: =O10*7.61305 -> 2541.9974 | AC10: =Q10+T10+W10+Z10 -> 0 | AD10: =(R10+U10+X10+AA10)/4 -> 0 | AE10: =(S10+V10+Y10+AB10)/4 -> 0
A11: =A10+1 -> 43740 | B11: 70 | C11: =IF(AC11>0,((B11-R11)+(S11-B12)),IF(B12=0, ,(B11-B12))) -> 2 | D11: 71 | E11: =IF(AC11>0,((D11-U11)+(V11-D12)),IF(D12=0, ,(D11-D12))) -> 1 | F11: 68 | G11: =IF(AC11>0,((F11-X11)+(Y11-F12)),IF(F12=0, ,(F11-F12))) -> 3 | H11: 69 | I11: =IF(AC11>0,((H11-AA11)+(AB11-H12)),IF(H12=0, ,(H11-H12))) -> 2 | J11: =B11+D11+F11+H11 -> 278 | K11: =J11/4 -> 69.5 | L11: =IF(AC11>0,((K11-AD11)+(AE11-K12)),IF(K12=0, ,(K11-K12))) -> 2 | M11: =7000*4 -> 28000 | N11: =L11*M11/100 -> 560 | O11: =N11*0.53 -> 296.8 | P11: =O11*7.61305 -> 2259.5532 | AC11: =Q11+T11+W11+Z11 -> 0 | AD11: =(R11+U11+X11+AA11)/4 -> 0 | AE11: =(S11+V11+Y11+AB11)/4 -> 0
A12: =A11+1 -> 43741 | B12: 68 | C12: =IF(AC12>0,((B12-R12)+(S12-B13)),IF(B13=0, ,(B12-B13))) -> 1 | D12: 70 | E12: =IF(AC12>0,((D12-U12)+(V12-D13)),IF(D13=0, ,(D12-D13))) -> 1 | F12: 65 | G12: =IF(AC12>0,((F12-X12)+(Y12-F13)),IF(F13=0, ,(F12-F13))) -> 1 | H12: 67 | I12: =IF(AC12>0,((H12-AA12)+(AB12-H13)),IF(H13=0, ,(H12-H13))) -> 2 | J12: =B12+D12+F12+H12 -> 270 | K12: =J12/4 -> 67.5 | L12: =IF(AC12>0,((K12-AD12)+(AE12-K13)),IF(K13=0, ,(K12-K13))) -> 1.25 | M12: =7000*4 -> 28000 | N12: =L12*M12/100 -> 350 | O12: =N12*0.53 -> 185.5 | P12: =O12*7.61305 -> 1412.2208 | Q12: 1590 | R12: 68 | S12: 85 | T12: 1514 | U12: 70 | V12: 85 | W12: 1647 | X12: 65 | Y12: 85 | Z12: 1722 | AA12: 66 | AB12: 85 | AC12: =Q12+T12+W12+Z12 -> 6473 | AD12: =(R12+U12+X12+AA12)/4 -> 67.25 | AE12: =(S12+V12+Y12+AB12)/4 -> 85
A13: =A12+1 -> 43742 | B13: 84 | C13: =IF(AC13>0,((B13-R13)+(S13-B14)),IF(B14=0, ,(B13-B14))) -> 0 | D13: 84 | E13: =IF(AC13>0,((D13-U13)+(V13-D14)),IF(D14=0, ,(D13-D14))) -> 0 | F13: 84 | G13: =IF(AC13>0,((F13-X13)+(Y13-F14)),IF(F14=0, ,(F13-F14))) -> 3 | H13: 84 | I13: =IF(AC13>0,((H13-AA13)+(AB13-H14)),IF(H14=0, ,(H13-H14))) -> 2 | J13: =B13+D13+F13+H13 -> 336 | K13: =J13/4 -> 84 | L13: =IF(AC13>0,((K13-AD13)+(AE13-K14)),IF(K14=0, ,(K13-K14))) -> 1.25 | M13: =7000*4 -> 28000 | N13: =L13*M13/100 -> 350 | O13: =N13*0.53 -> 185.5 | P13: =O13*7.61305 -> 1412.2208 | AC13: =Q13+T13+W13+Z13 -> 0 | AD13: =(R13+U13+X13+AA13)/4 -> 0 | AE13: =(S13+V13+Y13+AB13)/4 -> 0
A14: =A13+1 -> 43743 | B14: 84 | C14: =IF(AC14>0,((B14-R14)+(S14-B15)),IF(B15=0, ,(B14-B15))) -> 4 | D14: 84 | E14: =IF(AC14>0,((D14-U14)+(V14-D15)),IF(D15=0, ,(D14-D15))) -> 3 | F14: 81 | G14: =IF(AC14>0,((F14-X14)+(Y14-F15)),IF(F15=0, ,(F14-F15))) -> 2 | H14: 82 | I14: =IF(AC14>0,((H14-AA14)+(AB14-H15)),IF(H15=0, ,(H14-H15))) -> 3 | J14: =B14+D14+F14+H14 -> 331 | K14: =J14/4 -> 82.75 | L14: =IF(AC14>0,((K14-AD14)+(AE14-K15)),IF(K15=0, ,(K14-K15))) -> 3 | M14: =7000*4 -> 28000 | N14: =L14*M14/100 -> 840 | O14: =N14*0.53 -> 445.2 | P14: =O14*7.61305 -> 3389.3299 | AC14: =Q14+T14+W14+Z14 -> 0 | AD14: =(R14+U14+X14+AA14)/4 -> 0 | AE14: =(S14+V14+Y14+AB14)/4 -> 0
A15: =A14+1 -> 43744 | B15: 80 | C15: =IF(AC15>0,((B15-R15)+(S15-B16)),IF(B16=0, ,(B15-B16))) -> 2 | D15: 81 | E15: =IF(AC15>0,((D15-U15)+(V15-D16)),IF(D16=0, ,(D15-D16))) -> 2 | F15: 79 | G15: =IF(AC15>0,((F15-X15)+(Y15-F16)),IF(F16=0, ,(F15-F16))) -> 5 | H15: 79 | I15: =IF(AC15>0,((H15-AA15)+(AB15-H16)),IF(H16=0, ,(H15-H16))) -> 3 | J15: =B15+D15+F15+H15 -> 319 | K15: =J15/4 -> 79.75 | L15: =IF(AC15>0,((K15-AD15)+(AE15-K16)),IF(K16=0, ,(K15-K16))) -> 3 | M15: =7000*4 -> 28000 | N15: =L15*M15/100 -> 840 | O15: =N15*0.53 -> 445.2 | P15: =O15*7.61305 -> 3389.3299 | AC15: =Q15+T15+W15+Z15 -> 0 | AD15: =(R15+U15+X15+AA15)/4 -> 0 | AE15: =(S15+V15+Y15+AB15)/4 -> 0
A16: =A15+1 -> 43745 | B16: 78 | C16: =IF(AC16>0,((B16-R16)+(S16-B17)),IF(B17=0, ,(B16-B17))) -> 6 | D16: 79 | E16: =IF(AC16>0,((D16-U16)+(V16-D17)),IF(D17=0, ,(D16-D17))) -> 5 | F16: 74 | G16: =IF(AC16>0,((F16-X16)+(Y16-F17)),IF(F17=0, ,(F16-F17))) -> 3 | H16: 76 | I16: =IF(AC16>0,((H16-AA16)+(AB16-H17)),IF(H17=0, ,(H16-H17))) -> 3 | J16: =B16+D16+F16+H16 -> 307 | K16: =J16/4 -> 76.75 | L16: =IF(AC16>0,((K16-AD16)+(AE16-K17)),IF(K17=0, ,(K16-K17))) -> 4.25 | M16: =7000*4 -> 28000 | N16: =L16*M16/100 -> 1190 | O16: =N16*0.53 -> 630.7 | P16: =O16*7.61305 -> 4801.5506 | AC16: =Q16+T16+W16+Z16 -> 0 | AD16: =(R16+U16+X16+AA16)/4 -> 0 | AE16: =(S16+V16+Y16+AB16)/4 -> 0
A17: =A16+1 -> 43746 | B17: 72 | C17: =IF(AC17>0,((B17-R17)+(S17-B18)),IF(B18=0, ,(B17-B18))) -> 2 | D17: 74 | E17: =IF(AC17>0,((D17-U17)+(V17-D18)),IF(D18=0, ,(D17-D18))) -> 3 | F17: 71 | G17: =IF(AC17>0,((F17-X17)+(Y17-F18)),IF(F18=0, ,(F17-F18))) -> 3 | H17: 73 | I17: =IF(AC17>0,((H17-AA17)+(AB17-H18)),IF(H18=0, ,(H17-H18))) -> 3 | J17: =B17+D17+F17+H17 -> 290 | K17: =J17/4 -> 72.5 | L17: =IF(AC17>0,((K17-AD17)+(AE17-K18)),IF(K18=0, ,(K17-K18))) -> 2.75 | M17: =7000*4 -> 28000 | N17: =L17*M17/100 -> 770 | O17: =N17*0.53 -> 408.1 | P17: =O17*7.61305 -> 3106.8857 | AC17: =Q17+T17+W17+Z17 -> 0 | AD17: =(R17+U17+X17+AA17)/4 -> 0 | AE17: =(S17+V17+Y17+AB17)/4 -> 0
A18: =A17+1 -> 43747 | B18: 70 | C18: =IF(AC18>0,((B18-R18)+(S18-B19)),IF(B19=0, ,(B18-B19))) -> 5 | D18: 71 | E18: =IF(AC18>0,((D18-U18)+(V18-D19)),IF(D19=0, ,(D18-D19))) -> 3 | F18: 68 | G18: =IF(AC18>0,((F18-X18)+(Y18-F19)),IF(F19=0, ,(F18-F19))) -> 6 | H18: 70 | I18: =IF(AC18>0,((H18-AA18)+(AB18-H19)),IF(H19=0, ,(H18-H19))) -> 7 | J18: =B18+D18+F18+H18 -> 279 | K18: =J18/4 -> 69.75 | L18: =IF(AC18>0,((K18-AD18)+(AE18-K19)),IF(K19=0, ,(K18-K19))) -> 5.25 | M18: =7000*4 -> 28000 | N18: =L18*M18/100 -> 1470 | O18: =N18*0.53 -> 779.1 | P18: =O18*7.61305 -> 5931.3273 | AC18: =Q18+T18+W18+Z18 -> 0 | AD18: =(R18+U18+X18+AA18)/4 -> 0 | AE18: =(S18+V18+Y18+AB18)/4 -> 0
A19: =A18+1 -> 43748 | B19: 65 | D19: 68 | F19: 62 | H19: 63 | I19: =IF(AC19>0,((H19-AA19)+(AB19-H20)),IF(H20=0, ,(H19-H20))) -> 3 | J19: =B19+D19+F19+H19 -> 258 | K19: =J19/4 -> 64.5 | L19: =IF(AC19>0,((K19-AD19)+(AE19-K20)),IF(K20=0, ,(K19-K20))) -> 4.75 | M19: =7000*4 -> 28000 | N19: =L19*M19/100 -> 1330 | O19: =N19*0.53 -> 704.9 | P19: =O19*8.0278 -> 5658.7962 | AC19: =Q19+T19+W19+Z19 -> 0 | AD19: =(R19+U19+X19+AA19)/4 -> 0 | AE19: =(S19+V19+Y19+AB19)/4 -> 0
A20: =A19+1 -> 43749 | B20: 60 | C20: =IF(AC20>0,((B20-R20)+(S20-B21)),IF(B21=0, ,(B20-B21))) -> 8 | D20: 61 | E20: =IF(AC20>0,((D20-U20)+(V20-D21)),IF(D21=0, ,(D20-D21))) -> 4 | F20: 58 | G20: =IF(AC20>0,((F20-X20)+(Y20-F21)),IF(F21=0, ,(F20-F21))) -> 9 | H20: 60 | I20: =IF(AC20>0,((H20-AA20)+(AB20-H21)),IF(H21=0, ,(H20-H21))) -> 10 | J20: =B20+D20+F20+H20 -> 239 | K20: =J20/4 -> 59.75 | L20: =IF(AC20>0,((K20-AD20)+(AE20-K21)),IF(K21=0, ,(K20-K21))) -> 7.75 | M20: =7000*4 -> 28000 | N20: =L20*M20/100 -> 2170 | O20: =N20*0.53 -> 1150.1 | P20: =O20*8.0278 -> 9232.7728 | AC20: =Q20+T20+W20+Z20 -> 0 | AD20: =(R20+U20+X20+AA20)/4 -> 0 | AE20: =(S20+V20+Y20+AB20)/4 -> 0
A21: =A20+1 -> 43750 | B21: 52 | C21: =IF(AC21>0,((B21-R21)+(S21-B22)),IF(B22=0, ,(B21-B22))) -> 4 | D21: 57 | E21: =IF(AC21>0,((D21-U21)+(V21-D22)),IF(D22=0, ,(D21-D22))) -> 7 | F21: 49 | G21: =IF(AC21>0,((F21-X21)+(Y21-F22)),IF(F22=0, ,(F21-F22))) -> 6 | H21: 50 | I21: =IF(AC21>0,((H21-AA21)+(AB21-H22)),IF(H22=0, ,(H21-H22))) -> 3 | J21: =B21+D21+F21+H21 -> 208 | K21: =J21/4 -> 52 | L21: =IF(AC21>0,((K21-AD21)+(AE21-K22)),IF(K22=0, ,(K21-K22))) -> 5 | M21: =7000*4 -> 28000 | N21: =L21*M21/100 -> 1400 | O21: =N21*0.53 -> 742 | P21: =O21*8.0278 -> 5956.6276 | AC21: =Q21+T21+W21+Z21 -> 0 | AD21: =(R21+U21+X21+AA21)/4 -> 0 | AE21: =(S21+V21+Y21+AB21)/4 -> 0
A22: =A21+1 -> 43751 | B22: 48 | C22: =IF(AC22>0,((B22-R22)+(S22-B23)),IF(B23=0, ,(B22-B23))) -> 6 | D22: 50 | E22: =IF(AC22>0,((D22-U22)+(V22-D23)),IF(D23=0, ,(D22-D23))) -> 2 | F22: 43 | G22: =IF(AC22>0,((F22-X22)+(Y22-F23)),IF(F23=0, ,(F22-F23))) -> 3 | H22: 47 | I22: =IF(AC22>0,((H22-AA22)+(AB22-H23)),IF(H23=0, ,(H22-H23))) -> 5 | J22: =B22+D22+F22+H22 -> 188 | K22: =J22/4 -> 47 | L22: =IF(AC22>0,((K22-AD22)+(AE22-K23)),IF(K23=0, ,(K22-K23))) -> 4 | M22: =7000*4 -> 28000 | N22: =L22*M22/100 -> 1120 | O22: =N22*0.53 -> 593.6 | P22: =O22*8.0278 -> 4765.3021 | AC22: =Q22+T22+W22+Z22 -> 0 | AD22: =(R22+U22+X22+AA22)/4 -> 0 | AE22: =(S22+V22+Y22+AB22)/4 -> 0
A23: =A22+1 -> 43752 | B23: 42 | C23: =IF(AC23>0,((B23-R23)+(S23-B24)),IF(B24=0, ,(B23-B24))) -> 3 | D23: 48 | E23: =IF(AC23>0,((D23-U23)+(V23-D24)),IF(D24=0, ,(D23-D24))) -> 8 | F23: 40 | G23: =IF(AC23>0,((F23-X23)+(Y23-F24)),IF(F24=0, ,(F23-F24))) -> 3 | H23: 42 | I23: =IF(AC23>0,((H23-AA23)+(AB23-H24)),IF(H24=0, ,(H23-H24))) -> 2 | J23: =B23+D23+F23+H23 -> 172 | K23: =J23/4 -> 43 | L23: =IF(AC23>0,((K23-AD23)+(AE23-K24)),IF(K24=0, ,(K23-K24))) -> 4 | M23: =7000*4 -> 28000 | N23: =L23*M23/100 -> 1120 | O23: =N23*0.53 -> 593.6 | P23: =O23*8.0278 -> 4765.3021 | AC23: =Q23+T23+W23+Z23 -> 0 | AD23: =(R23+U23+X23+AA23)/4 -> 0 | AE23: =(S23+V23+Y23+AB23)/4 -> 0
A24: =A23+1 -> 43753 | B24: 39 | C24: =IF(AC24>0,((B24-R24)+(S24-B25)),IF(B25=0, ,(B24-B25))) -> 2 | D24: 40 | E24: =IF(AC24>0,((D24-U24)+(V24-D25)),IF(D25=0, ,(D24-D25))) -> 2 | F24: 37 | G24: =IF(AC24>0,((F24-X24)+(Y24-F25)),IF(F25=0, ,(F24-F25))) -> 3 | H24: 40 | I24: =IF(AC24>0,((H24-AA24)+(AB24-H25)),IF(H25=0, ,(H24-H25))) -> 0 | J24: =B24+D24+F24+H24 -> 156 | K24: =J24/4 -> 39 | L24: =IF(AC24>0,((K24-AD24)+(AE24-K25)),IF(K25=0, ,(K24-K25))) -> 1.75 | M24: =7000*4 -> 28000 | N24: =L24*M24/100 -> 490 | O24: =N24*0.53 -> 259.7 | P24: =O24*8.0278 -> 2084.8197 | Q24: 3602 | R24: 39 | S24: 86 | T24: 3606 | U24: 40 | V24: 86 | W24: 3801 | X24: 37 | Y24: 85 | Z24: 2501 | AA24: 40 | AB24: 80 | AC24: =Q24+T24+W24+Z24 -> 13510 | AD24: =(R24+U24+X24+AA24)/4 -> 39 | AE24: =(S24+V24+Y24+AB24)/4 -> 84.25
A25: =A24+1 -> 43754 | B25: 84 | C25: =IF(AC25>0,((B25-R25)+(S25-B26)),IF(B26=0, ,(B25-B26))) -> 2 | D25: 84 | E25: =IF(AC25>0,((D25-U25)+(V25-D26)),IF(D26=0, ,(D25-D26))) -> 1 | F25: 82 | G25: =IF(AC25>0,((F25-X25)+(Y25-F26)),IF(F26=0, ,(F25-F26))) -> 4 | H25: 80 | I25: =IF(AC25>0,((H25-AA25)+(AB25-H26)),IF(H26=0, ,(H25-H26))) -> 0 | J25: =B25+D25+F25+H25 -> 330 | K25: =J25/4 -> 82.5 | L25: =IF(AC25>0,((K25-AD25)+(AE25-K26)),IF(K26=0, ,(K25-K26))) -> 1.75 | M25: =7000*4 -> 28000 | N25: =L25*M25/100 -> 490 | O25: =N25*0.53 -> 259.7 | P25: =O25*8.0278 -> 2084.8197 | AC25: =Q25+T25+W25+Z25 -> 0 | AD25: =(R25+U25+X25+AA25)/4 -> 0 | AE25: =(S25+V25+Y25+AB25)/4 -> 0
A26: =A25+1 -> 43755 | B26: 82 | C26: =IF(AC26>0,((B26-R26)+(S26-B27)),IF(B27=0, ,(B26-B27))) -> 4 | D26: 83 | E26: =IF(AC26>0,((D26-U26)+(V26-D27)),IF(D27=0, ,(D26-D27))) -> 4 | F26: 78 | G26: =IF(AC26>0,((F26-X26)+(Y26-F27)),IF(F27=0, ,(F26-F27))) -> 3 | H26: 80 | I26: =IF(AC26>0,((H26-AA26)+(AB26-H27)),IF(H27=0, ,(H26-H27))) -> 4 | J26: =B26+D26+F26+H26 -> 323 | K26: =J26/4 -> 80.75 | L26: =IF(AC26>0,((K26-AD26)+(AE26-K27)),IF(K27=0, ,(K26-K27))) -> 3.75 | M26: =7000*4 -> 28000 | N26: =L26*M26/100 -> 1050 | O26: =N26*0.53 -> 556.5 | P26: =O26*8.0278 -> 4467.4707 | AC26: =Q26+T26+W26+Z26 -> 0 | AD26: =(R26+U26+X26+AA26)/4 -> 0 | AE26: =(S26+V26+Y26+AB26)/4 -> 0
A27: =A26+1 -> 43756 | B27: 78 | C27: =IF(AC27>0,((B27-R27)+(S27-B28)),IF(B28=0, ,(B27-B28))) -> 3 | D27: 79 | E27: =IF(AC27>0,((D27-U27)+(V27-D28)),IF(D28=0, ,(D27-D28))) -> 3 | F27: 75 | G27: =IF(AC27>0,((F27-X27)+(Y27-F28)),IF(F28=0, ,(F27-F28))) -> 4 | H27: 76 | I27: =IF(AC27>0,((H27-AA27)+(AB27-H28)),IF(H28=0, ,(H27-H28))) -> 2 | J27: =B27+D27+F27+H27 -> 308 | K27: =J27/4 -> 77 | L27: =IF(AC27>0,((K27-AD27)+(AE27-K28)),IF(K28=0, ,(K27-K28))) -> 3 | M27: 28000 | N27: =L27*M27/100 -> 840 | O27: =N27*0.53 -> 445.2 | P27: =O27*8.0278 -> 3573.9766 | AC27: =Q27+T27+W27+Z27 -> 0 | AD27: =(R27+U27+X27+AA27)/4 -> 0 | AE27: =(S27+V27+Y27+AB27)/4 -> 0
A28: =A27+1 -> 43757 | B28: 75 | C28: =IF(AC28>0,((B28-R28)+(S28-B29)),IF(B29=0, ,(B28-B29))) -> 4 | D28: 76 | E28: =IF(AC28>0,((D28-U28)+(V28-D29)),IF(D29=0, ,(D28-D29))) -> 4 | F28: 71 | G28: =IF(AC28>0,((F28-X28)+(Y28-F29)),IF(F29=0, ,(F28-F29))) -> 3 | H28: 74 | I28: =IF(AC28>0,((H28-AA28)+(AB28-H29)),IF(H29=0, ,(H28-H29))) -> 4 | J28: =B28+D28+F28+H28 -> 296 | K28: =J28/4 -> 74 | L28: =IF(AC28>0,((K28-AD28)+(AE28-K29)),IF(K29=0, ,(K28-K29))) -> 3.75 | M28: =7000*4 -> 28000 | N28: =L28*M28/100 -> 1050 | O28: =N28*0.53 -> 556.5 | P28: =O28*8.0278 -> 4467.4707 | AC28: =Q28+T28+W28+Z28 -> 0 | AD28: =(R28+U28+X28+AA28)/4 -> 0 | AE28: =(S28+V28+Y28+AB28)/4 -> 0
A29: =A28+1 -> 43758 | B29: 71 | C29: =IF(AC29>0,((B29-R29)+(S29-B30)),IF(B30=0, ,(B29-B30))) -> 3 | D29: 72 | E29: =IF(AC29>0,((D29-U29)+(V29-D30)),IF(D30=0, ,(D29-D30))) -> 2 | F29: 68 | G29: =IF(AC29>0,((F29-X29)+(Y29-F30)),IF(F30=0, ,(F29-F30))) -> 3 | H29: 70 | I29: =IF(AC29>0,((H29-AA29)+(AB29-H30)),IF(H30=0, ,(H29-H30))) -> 1 | J29: =B29+D29+F29+H29 -> 281 | K29: =J29/4 -> 70.25 | L29: =IF(AC29>0,((K29-AD29)+(AE29-K30)),IF(K30=0, ,(K29-K30))) -> 2.25 | M29: =7000*4 -> 28000 | N29: =L29*M29/100 -> 630 | O29: =N29*0.53 -> 333.9 | P29: =O29*8.0278 -> 2680.4824 | AC29: =Q29+T29+W29+Z29 -> 0 | AD29: =(R29+U29+X29+AA29)/4 -> 0 | AE29: =(S29+V29+Y29+AB29)/4 -> 0
A30: =A29+1 -> 43759 | B30: 68 | C30: =IF(AC30>0,((B30-R30)+(S30-B31)),IF(B31=0, ,(B30-B31))) -> 2 | D30: 70 | E30: =IF(AC30>0,((D30-U30)+(V30-D31)),IF(D31=0, ,(D30-D31))) -> 3 | F30: 65 | G30: =IF(AC30>0,((F30-X30)+(Y30-F31)),IF(F31=0, ,(F30-F31))) -> 4 | H30: 69 | I30: =IF(AC30>0,((H30-AA30)+(AB30-H31)),IF(H31=0, ,(H30-H31))) -> 3 | J30: =B30+D30+F30+H30 -> 272 | K30: =J30/4 -> 68 | L30: =IF(AC30>0,((K30-AD30)+(AE30-K31)),IF(K31=0, ,(K30-K31))) -> 3 | M30: =7000*4 -> 28000 | N30: =L30*M30/100 -> 840 | O30: =N30*0.53 -> 445.2 | P30: =O30*8.0278 -> 3573.9766 | AC30: =Q30+T30+W30+Z30 -> 0 | AD30: =(R30+U30+X30+AA30)/4 -> 0 | AE30: =(S30+V30+Y30+AB30)/4 -> 0
A31: =A30+1 -> 43760 | B31: 66 | C31: =IF(AC31>0,((B31-R31)+(S31-B32)),IF(B32=0, ,(B31-B32))) -> 5 | D31: 67 | E31: =IF(AC31>0,((D31-U31)+(V31-D32)),IF(D32=0, ,(D31-D32))) -> 5 | F31: 61 | G31: =IF(AC31>0,((F31-X31)+(Y31-F32)),IF(F32=0, ,(F31-F32))) -> 2 | H31: 66 | I31: =IF(AC31>0,((H31-AA31)+(AB31-H32)),IF(H32=0, ,(H31-H32))) -> 5 | J31: =B31+D31+F31+H31 -> 260 | K31: =J31/4 -> 65 | L31: =IF(AC31>0,((K31-AD31)+(AE31-K32)),IF(K32=0, ,(K31-K32))) -> 4.25 | M31: =7000*4 -> 28000 | N31: =L31*M31/100 -> 1190 | O31: =N31*0.53 -> 630.7 | P31: =O31*8.0278 -> 5063.1335 | AC31: =Q31+T31+W31+Z31 -> 0 | AD31: =(R31+U31+X31+AA31)/4 -> 0 | AE31: =(S31+V31+Y31+AB31)/4 -> 0
A32: =A31+1 -> 43761 | B32: 61 | C32: =IF(AC32>0,((B32-R32)+(S32-B33)),IF(B33=0, ,(B32-B33))) -> 11 | D32: 62 | E32: =IF(AC32>0,((D32-U32)+(V32-D33)),IF(D33=0, ,(D32-D33))) -> 12 | F32: 59 | G32: =IF(AC32>0,((F32-X32)+(Y32-F33)),IF(F33=0, ,(F32-F33))) -> 14 | H32: 61 | I32: =IF(AC32>0,((H32-AA32)+(AB32-H33)),IF(H33=0, ,(H32-H33))) -> 11 | J32: =B32+D32+F32+H32 -> 243 | K32: =J32/4 -> 60.75 | L32: =IF(AC32>0,((K32-AD32)+(AE32-K33)),IF(K33=0, ,(K32-K33))) -> 12 | M32: =7000*4 -> 28000 | N32: =L32*M32/100 -> 3360 | O32: =N32*0.53 -> 1780.8 | P32: =O32*8.0278 -> 14295.906 | AC32: =Q32+T32+W32+Z32 -> 0 | AD32: =(R32+U32+X32+AA32)/4 -> 0 | AE32: =(S32+V32+Y32+AB32)/4 -> 0
A33: =A32+1 -> 43762 | B33: 50 | C33: =IF(AC33>0,((B33-R33)+(S33-B34)),IF(B34=0, ,(B33-B34))) -> 0 | D33: 50 | E33: =IF(AC33>0,((D33-U33)+(V33-D34)),IF(D34=0, ,(D33-D34))) -> 0 | F33: 45 | G33: =IF(AC33>0,((F33-X33)+(Y33-F34)),IF(F34=0, ,(F33-F34))) -> 0 | H33: 50 | I33: =IF(AC33>0,((H33-AA33)+(AB33-H34)),IF(H34=0, ,(H33-H34))) -> 0 | J33: =B33+D33+F33+H33 -> 195 | K33: =J33/4 -> 48.75 | L33: =IF(AC33>0,((K33-AD33)+(AE33-K34)),IF(K34=0, ,(K33-K34))) -> 0 | M33: =7000*4 -> 28000 | N33: =L33*M33/100 -> 0 | O33: =N33*0.53 -> 0 | P33: =O33*8.0278 -> 0 | AC33: =Q33+T33+W33+Z33 -> 0 | AD33: =(R33+U33+X33+AA33)/4 -> 0 | AE33: =(S33+V33+Y33+AB33)/4 -> 0
A34: =A33+1 -> 43763 | C34: =IF(AC34>0,((B34-R34)+(S34-B35)),IF(B35=0, ,(B34-B35))) -> 0 | E34: =IF(AC34>0,((D34-U34)+(V34-D35)),IF(D35=0, ,(D34-D35))) -> 0 | G34: =IF(AC34>0,((F34-X34)+(Y34-F35)),IF(F35=0, ,(F34-F35))) -> 0 | I34: =IF(AC34>0,((H34-AA34)+(AB34-H35)),IF(H35=0, ,(H34-H35))) -> 0 | J34: =B34+D34+F34+H34 -> 0 | K34: =J34/4 -> 0 | L34: =IF(AC34>0,((K34-AD34)+(AE34-K35)),IF(K35=0, ,(K34-K35))) -> 0 | M34: =7000*4 -> 28000 | N34: =L34*M34/100 -> 0 | O34: =N34*0.53 -> 0 | P34: =O34*8.0278 -> 0 | AC34: =Q34+T34+W34+Z34 -> 0 | AD34: =(R34+U34+X34+AA34)/4 -> 0 | AE34: =(S34+V34+Y34+AB34)/4 -> 0
A35: =A34+1 -> 43764 | C35: =IF(AC35>0,((B35-R35)+(S35-B36)),IF(B36=0, ,(B35-B36))) -> 0 | E35: =IF(AC35>0,((D35-U35)+(V35-D36)),IF(D36=0, ,(D35-D36))) -> 0 | G35: =IF(AC35>0,((F35-X35)+(Y35-F36)),IF(F36=0, ,(F35-F36))) -> 0 | I35: =IF(AC35>0,((H35-AA35)+(AB35-H36)),IF(H36=0, ,(H35-H36))) -> 0 | J35: =B35+D35+F35+H35 -> 0 | K35: =J35/4 -> 0 | L35: =IF(AC35>0,((K35-AD35)+(AE35-K36)),IF(K36=0, ,(K35-K36))) -> 0 | M35: =7000*4 -> 28000 | N35: =L35*M35/100 -> 0 | O35: =N35*0.53 -> 0 | P35: =O35*8.0278 -> 0 | AC35: =Q35+T35+W35+Z35 -> 0 | AD35: =(R35+U35+X35+AA35)/4 -> 0 | AE35: =(S35+V35+Y35+AB35)/4 -> 0
A36: =A35+1 -> 43765 | C36: =IF(AC36>0,((B36-R36)+(S36-B37)),IF(B37=0, ,(B36-B37))) -> 0 | E36: =IF(AC36>0,((D36-U36)+(V36-D37)),IF(D37=0, ,(D36-D37))) -> 0 | G36: =IF(AC36>0,((F36-X36)+(Y36-F37)),IF(F37=0, ,(F36-F37))) -> 0 | I36: =IF(AC36>0,((H36-AA36)+(AB36-H37)),IF(H37=0, ,(H36-H37))) -> 0 | J36: =B36+D36+F36+H36 -> 0 | K36: =J36/4 -> 0 | L36: =IF(AC36>0,((K36-AD36)+(AE36-K37)),IF(K37=0, ,(K36-K37))) -> 0 | M36: =7000*4 -> 28000 | N36: =L36*M36/100 -> 0 | O36: =N36*0.53 -> 0 | P36: =O36*8.0278 -> 0 | AC36: =Q36+T36+W36+Z36 -> 0 | AD36: =(R36+U36+X36+AA36)/4 -> 0 | AE36: =(S36+V36+Y36+AB36)/4 -> 0
A37: =A36+1 -> 43766 | C37: =IF(AC37>0,((B37-R37)+(S37-B38)),IF(B38=0, ,(B37-B38))) -> 0 | E37: =IF(AC37>0,((D37-U37)+(V37-D38)),IF(D38=0, ,(D37-D38))) -> 0 | G37: =IF(AC37>0,((F37-X37)+(Y37-F38)),IF(F38=0, ,(F37-F38))) -> 0 | I37: =IF(AC37>0,((H37-AA37)+(AB37-H38)),IF(H38=0, ,(H37-H38))) -> 0 | J37: =B37+D37+F37+H37 -> 0 | K37: =J37/4 -> 0 | L37: =IF(AC37>0,((K37-AD37)+(AE37-K38)),IF(K38=0, ,(K37-K38))) -> 0 | M37: =7000*4 -> 28000 | N37: =L37*M37/100 -> 0 | O37: =N37*0.53 -> 0 | P37: =O37*8.0278 -> 0 | AC37: =Q37+T37+W37+Z37 -> 0 | AD37: =(R37+U37+X37+AA37)/4 -> 0 | AE37: =(S37+V37+Y37+AB37)/4 -> 0
A38: =A37+1 -> 43767 | C38: =IF(AC38>0,((B38-R38)+(S38-B39)),IF(B39=0, ,(B38-B39))) -> 0 | E38: =IF(AC38>0,((D38-U38)+(V38-D39)),IF(D39=0, ,(D38-D39))) -> 0 | G38: =IF(AC38>0,((F38-X38)+(Y38-F39)),IF(F39=0, ,(F38-F39))) -> 0 | I38: =IF(AC38>0,((H38-AA38)+(AB38-H39)),IF(H39=0, ,(H38-H39))) -> 0 | J38: =B38+D38+F38+H38 -> 0 | K38: =J38/4 -> 0 | L38: =IF(AC38>0,((K38-AD38)+(AE38-K39)),IF(K39=0, ,(K38-K39))) -> 0 | M38: =7000*4 -> 28000 | N38: =L38*M38/100 -> 0 | O38: =N38*0.53 -> 0 | P38: =O38*8.0278 -> 0 | AC38: =Q38+T38+W38+Z38 -> 0 | AD38: =(R38+U38+X38+AA38)/4 -> 0 | AE38: =(S38+V38+Y38+AB38)/4 -> 0
A39: =A38+1 -> 43768 | C39: =IF(AC39>0,((B39-R39)+(S39-B40)),IF(B40=0, ,(B39-B40))) -> 0 | E39: =IF(AC39>0,((D39-U39)+(V39-D40)),IF(D40=0, ,(D39-D40))) -> 0 | G39: =IF(AC39>0,((F39-X39)+(Y39-F40)),IF(F40=0, ,(F39-F40))) -> 0 | I39: =IF(AC39>0,((H39-AA39)+(AB39-H40)),IF(H40=0, ,(H39-H40))) -> 0 | J39: =B39+D39+F39+H39 -> 0 | K39: =J39/4 -> 0 | L39: =IF(AC39>0,((K39-AD39)+(AE39-K40)),IF(K40=0, ,(K39-K40))) -> 0 | M39: =7000*4 -> 28000 | N39: =L39*M39/100 -> 0 | O39: =N39*0.53 -> 0 | P39: =O39*8.0278 -> 0 | AC39: =Q39+T39+W39+Z39 -> 0 | AD39: =(R39+U39+X39+AA39)/4 -> 0 | AE39: =(S39+V39+Y39+AB39)/4 -> 0
A40: =A39+1 -> 43769 | C40: =IF(AC40>0,((B40-R40)+(S40-B41)),IF(B41=0, ,(B40-B41))) -> 0 | E40: =IF(AC40>0,((D40-U40)+(V40-D41)),IF(D41=0, ,(D40-D41))) -> 0 | G40: =IF(AC40>0,((F40-X40)+(Y40-F41)),IF(F41=0, ,(F40-F41))) -> 0 | I40: =IF(AC40>0,((H40-AA40)+(AB40-H41)),IF(H41=0, ,(H40-H41))) -> 0 | J40: =B40+D40+F40+H40 -> 0 | K40: =J40/4 -> 0 | L40: =IF(AC40>0,((K40-AD40)+(AE40-K41)),IF(K41=0, ,(K40-K41))) -> 0 | M40: =7000*4 -> 28000 | N40: =L40*M40/100 -> 0 | O40: =N40*0.53 -> 0 | P40: =O40*8.0278 -> 0 | AC40: =Q40+T40+W40+Z40 -> 0 | AD40: =(R40+U40+X40+AA40)/4 -> 0 | AE40: =(S40+V40+Y40+AB40)/4 -> 0
...

Sheet Suivi EAU-ELEC
C1: Suivi Compteur d'Eau- électricité RADEEMA -
A7: Date | B7: Eau m3 | D7: Electricité Kw/h
B8: Compteur | C8: Consommation | D8: Compteur H.Creuse | E8: Consommation H.Creuse | F8: Compteur H.Pleine | G8: Consommation H.Pleine | H8: Compteur H.Pointe | I8: Consommation H.Pointe
A9: 43733 | B9: 113024 | C9: =IF(B10<B9,0,B10-B9)*10 -> 540 | D9: 17471642 | E9: =IF(D10<D9,0,D10-D9) -> 7420 | F9: 31662475 | G9: =IF(F10<F9,0,F10-F9) -> 13250 | H9: 13980637 | I9: =IF(H10<H9,0,H10-H9) -> 5581
A10: =A9+1 -> 43734 | B10: 113078 | C10: =IF(B11<B10,0,B11-B10)*10 -> 570 | D10: 17479062 | E10: =IF(D11<D10,0,D11-D10) -> 6535 | F10: 31675725 | G10: =IF(F11<F10,0,F11-F10) -> 12652 | H10: 13986218 | I10: =IF(H11<H10,0,H11-H10) -> 5145
A11: =A10+1 -> 43735 | B11: 113135 | C11: =IF(B12<B11,0,B12-B11)*10 -> 670 | D11: 17485597 | E11: =IF(D12<D11,0,D12-D11) -> 7122 | F11: 31688377 | G11: =IF(F12<F11,0,F12-F11) -> 13514 | H11: 13991363 | I11: =IF(H12<H11,0,H12-H11) -> 5412
A12: =A11+1 -> 43736 | B12: 113202 | C12: =IF(B13<B12,0,B13-B12)*10 -> 560 | D12: 17492719 | E12: =IF(D13<D12,0,D13-D12) -> 6579 | F12: 31701891 | G12: =IF(F13<F12,0,F13-F12) -> 13945 | H12: 13996775 | I12: =IF(H13<H12,0,H13-H12) -> 4847
A13: =A12+1 -> 43737 | B13: 113258 | C13: =IF(B14<B13,0,B14-B13)*10 -> 570 | D13: 17499298 | E13: =IF(D14<D13,0,D14-D13) -> 6427 | F13: 31715836 | G13: =IF(F14<F13,0,F14-F13) -> 12835 | H13: 14001622 | I13: =IF(H14<H13,0,H14-H13) -> 5000
A14: =A13+1 -> 43738 | B14: 113315 | C14: =IF(B15<B14,0,B15-B14)*10 -> 560 | D14: 17505725 | E14: =IF(D15<D14,0,D15-D14) -> 6497 | F14: 31728671 | G14: =IF(F15<F14,0,F15-F14) -> 13658 | H14: 14006622 | I14: =IF(H15<H14,0,H15-H14) -> 5221
A15: =A14+1 -> 43739 | B15: 113371 | C15: =IF(B16<B15,0,B16-B15)*10 -> 580 | D15: 17512222 | E15: =IF(D16<D15,0,D16-D15) -> 7408 | F15: 31742329 | G15: =IF(F16<F15,0,F16-F15) -> 12795 | H15: 14011843 | I15: =IF(H16<H15,0,H16-H15) -> 5486
A16: =A15+1 -> 43740 | B16: 113429 | C16: =IF(B17<B16,0,B17-B16)*10 -> 590 | D16: 17519630 | E16: =IF(D17<D16,0,D17-D16) -> 7584 | F16: 31755124 | G16: =IF(F17<F16,0,F17-F16) -> 12155 | H16: 14017329 | I16: =IF(H17<H16,0,H17-H16) -> 4982
A17: =A16+1 -> 43741 | B17: 113488 | C17: =IF(B18<B17,0,B18-B17)*10 -> 670 | D17: 17527214 | E17: =IF(D18<D17,0,D18-D17) -> 6958 | F17: 31767279 | G17: =IF(F18<F17,0,F18-F17) -> 11612 | H17: 14022311 | I17: =IF(H18<H17,0,H18-H17) -> 4699
A18: =A17+1 -> 43742 | B18: 113555 | C18: =IF(B19<B18,0,B19-B18)*10 -> 520 | D18: 17534172 | E18: =IF(D19<D18,0,D19-D18) -> 7290 | F18: 31778891 | G18: =IF(F19<F18,0,F19-F18) -> 11551 | H18: 14027010 | I18: =IF(H19<H18,0,H19-H18) -> 5028
A19: =A18+1 -> 43743 | B19: 113607 | C19: =IF(B20<B19,0,B20-B19)*10 -> 600 | D19: 17541462 | E19: =IF(D20<D19,0,D20-D19) -> 7194 | F19: 31790442 | G19: =IF(F20<F19,0,F20-F19) -> 11304 | H19: 14032038 | I19: =IF(H20<H19,0,H20-H19) -> 5108
A20: =A19+1 -> 43744 | B20: 113667 | C20: =IF(B21<B20,0,B21-B20)*10 -> 580 | D20: 17548656 | E20: =IF(D21<D20,0,D21-D20) -> 7476 | F20: 31801746 | G20: =IF(F21<F20,0,F21-F20) -> 11878 | H20: 14037146 | I20: =IF(H21<H20,0,H21-H20) -> 5125
A21: =A20+1 -> 43745 | B21: 113725 | C21: =IF(B22<B21,0,B22-B21)*10 -> 550 | D21: 17556132 | E21: =IF(D22<D21,0,D22-D21) -> 7485 | F21: 31813624 | G21: =IF(F22<F21,0,F22-F21) -> 12020 | H21: 14042271 | I21: =IF(H22<H21,0,H22-H21) -> 5339
... A38: =A37+1 -> 43762 | B38: 114712 | C38: =IF(B39<B38,0,B39-B38)*10 -> 0 | D38: 17673918 | E38: =IF(D39<D38,0,D39-D38) -> 0 | F38: 31994552 | G38: =IF(F39<F38,0,F39-F38) -> 0 | H38: 14126831 | I38: =IF(H39<H38,0,H39-H38) -> 0
A39: =A38+1 -> 43763 | C39: =IF(B40<B39,0,B40-B39)*10 -> 0 | E39: =IF(D40<D39,0,D40-D39) -> 0 | G39: =IF(F40<F39,0,F40-F39) -> 0 | I39: =IF(H40<H39,0,H40-H39) -> 0
A40: =A39+1 -> 43764 | C40: =IF(B41<B40,0,B41-B40)*10 -> 0 | E40: =IF(D41<D40,0,D41-D40) -> 0 | G40: =IF(F41<F40,0,F41-F40) -> 0 | I40: =IF(H41<H40,0,H41-H40) -> 0
A41: =A40+1 -> 43765 | C41: =IF(B42<B41,0,B42-B41)*10 -> 0 | E41: =IF(D42<D41,0,D42-D41) -> 0 | G41: =IF(F42<F41,0,F42-F41) -> 0 | I41: =IF(H42<H41,0,H42-H41) -> 0
A42: =A41+1 -> 43766 | C42: =IF(B43<B42,0,B43-B42)*10 -> 0 | E42: =IF(D43<D42,0,D43-D42) -> 0 | G42: =IF(F43<F42,0,F43-F42) -> 0 | I42: =IF(H43<H42,0,H43-H42) -> 0
A43: =A42+1 -> 43767 | C43: =IF(B44<B43,0,B44-B43)*10 -> 0 | E43: =IF(D44<D43,0,D44-D43) -> 0 | G43: =IF(F44<F43,0,F44-F43) -> 0 | I43: =IF(H44<H43,0,H44-H43) -> 0
A44: =A43+1 -> 43768 | C44: =IF(B45<B44,0,B45-B44)*10 -> 0 | E44: =IF(D45<D44,0,D45-D44) -> 0 | G44: =IF(F45<F44,0,F45-F44) -> 0 | I44: =IF(H45<H44,0,H45-H44) -> 0
A45: =A44+1 -> 43769 | C45: =IF(B46<B45,0,B46-B45)*10 -> 0 | E45: =IF(D46<D45,0,D46-D45) -> 0 | G45: =IF(F46<F45,0,F46-F45) -> 0 | I45: =IF(H46<H45,0,H46-H45) -> 0
A46: =A45+1 -> 43770 | C46: =IF(B47<B46,0,B47-B46)*10 -> 0 | E46: =IF(D47<D46,0,D47-D46) -> 0 | G46: =IF(F47<F46,0,F47-F46) -> 0 | I46: =IF(H47<H46,0,H47-H46) -> 0
A47: =A46+1 -> 43771 | C47: =IF(B48<B47,0,B48-B47)*10 -> 0 | E47: =IF(D48<D47,0,D48-D47) -> 0 | G47: =IF(F48<F47,0,F48-F47) -> 0 | I47: =IF(H48<H47,0,H48-H47) -> 0
C48: =SUM(C15:C45) -> 13410 | E48: =SUM(E15:E45) -> 161696 | G48: =SUM(G15:G45) -> 252223 | I48: =SUM(I15:I45) -> 114988
G58: =IF(F59<F58,0,F59-F58) -> 0

Sheet Feuil1
