Workbook

Sheet TOTAL
A1: Site Name | B1: Day | C1: Month | D1: Year | E1: Total Electricity Kwh | F1: Electricity Tariff ($/Kwh) | G1: Natual Gas (m3) | H1: Natural Gas $/m3 | I1: Water Utility Supply (m3) m3 | J1: Water Utility Supply (m3) $/m3 | K1: Room Nights | L1: Total Guests
A2: Budapest | B2: 1 | C2: 10 | D2: 2019 | E2: 18172 | F2: 0.077909228 | G2: 1439 | H2: 0.24162482 | I2: 174 | J2: 1.6865699 | K2: 172 | L2: 245
A3: Budapest | B3: =B2+1 -> 2 | C3: 10 | D3: 2019 | E3: 18788 | F3: 0.077909228 | G3: 1489 | H3: 0.24162482 | I3: 188 | J3: =J2 -> 1.6865699 | K3: 164 | L3: 253
A4: Budapest | B4: =B3+1 -> 3 | C4: 10 | D4: 2019 | E4: 17952 | F4: 0.077909228 | G4: 1886 | H4: 0.24162482 | I4: 166 | J4: =J3 -> 1.6865699 | K4: 134 | L4: 221
A5: Budapest | B5: =B4+1 -> 4 | C5: 10 | D5: 2019 | E5: 17160 | F5: 0.077909228 | G5: 1741 | H5: 0.24162482 | I5: 174 | J5: =J4 -> 1.6865699 | K5: 151 | L5: 257
A6: Budapest | B6: =B5+1 -> 5 | C6: 10 | D6: 2019 | E6: 16456 | F6: 0.077909228 | G6: 1743 | H6: 0.24162482 | I6: 170 | J6: =J5 -> 1.6865699 | K6: 133 | L6: 219
A7: Budapest | B7: =B6+1 -> 6 | C7: 10 | D7: 2019 | E7: 17336 | F7: 0.077909228 | G7: 1721 | H7: 0.24162482 | I7: 150 | J7: =J6 -> 1.6865699 | K7: 116 | L7: 183
A8: Budapest | B8: =B7+1 -> 7 | C8: 10 | D8: 2019 | E8: 16632 | F8: 0.077909228 | G8: 1924 | H8: 0.24162482 | I8: 161 | J8: =J7 -> 1.6865699 | K8: 150 | L8: 233
A9: Budapest | B9: =B8+1 -> 8 | C9: 10 | D9: 2019 | E9: 17204 | F9: 0.077909228 | G9: 1915 | H9: 0.24162482 | I9: 168 | J9: =J8 -> 1.6865699 | K9: 158 | L9: 244
A10: Budapest | B10: =B9+1 -> 9 | C10: 10 | D10: 2019 | E10: 18084 | F10: 0.077909228 | G10: 1629 | H10: 0.24162482 | I10: 178 | J10: =J9 -> 1.6865699 | K10: 154 | L10: 233
A11: Budapest | B11: =B10+1 -> 10 | C11: 10 | D11: 2019 | E11: 17644 | F11: 0.077909228 | G11: 1661 | H11: 0.24162482 | I11: 171 | J11: =J10 -> 1.6865699 | K11: 175 | L11: 258
A12: Budapest | B12: =B11+1 -> 11 | C12: 10 | D12: 2019 | E12: 18128 | F12: 0.077909228 | G12: 1709 | H12: 0.24162482 | I12: 185 | J12: =J11 -> 1.6865699 | K12: 160 | L12: 263
A13: Budapest | B13: =B12+1 -> 12 | C13: 10 | D13: 2019 | E13: 17952 | F13: 0.077909228 | G13: 1727 | H13: 0.24162482 | I13: 190 | J13: =J12 -> 1.6865699 | K13: 143 | L13: 239
A14: Budapest | B14: =B13+1 -> 13 | C14: 10 | D14: 2019 | E14: 16324 | F14: 0.077909228 | G14: 1625 | H14: 0.24162482 | I14: 184 | J14: =J13 -> 1.6865699 | K14: 161 | L14: 247
... A21: Budapest | B21: =B20+1 -> 20 | C21: 10 | D21: 2019 | E21: 19228 | F21: 0.077909228 | G21: 1629 | H21: 0.24162482 | I21: 187 | J21: =J20 -> 1.6865699 | K21: 173 | L21: 243
A22: Budapest | B22: =B21+1 -> 21 | C22: 10 | D22: 2019 | E22: 0 | F22: 0.077909228 | G22: 0 | H22: 0.24162482 | I22: 0 | J22: =J21 -> 1.6865699 | K22: 0 | L22: 0
A23: Budapest | B23: =B22+1 -> 22 | C23: 10 | D23: 2019 | E23: 0 | F23: 0.077909228 | G23: 0 | H23: 0.24162482 | I23: 0 | J23: =J22 -> 1.6865699 | K23: 0 | L23: 0
A24: Budapest | B24: =B23+1 -> 23 | C24: 10 | D24: 2019 | E24: 0 | F24: 0.077909228 | G24: 0 | H24: 0.24162482 | I24: 0 | J24: =J23 -> 1.6865699 | K24: 0 | L24: 0
A25: Budapest | B25: =B24+1 -> 24 | C25: 10 | D25: 2019 | E25: 0 | F25: 0.077909228 | G25: 0 | H25: 0.24162482 | I25: 0 | J25: =J24 -> 1.6865699 | K25: 0 | L25: 0
A26: Budapest | B26: =B25+1 -> 25 | C26: 10 | D26: 2019 | E26: 0 | F26: 0.077909228 | G26: 0 | H26: 0.24162482 | I26: 0 | J26: =J25 -> 1.6865699 | K26: 0 | L26: 0
A27: Budapest | B27: =B26+1 -> 26 | C27: 10 | D27: 2019 | E27: 0 | F27: 0.077909228 | G27: 0 | H27: 0.24162482 | I27: 0 | J27: =J26 -> 1.6865699 | K27: 0 | L27: 0
A28: Budapest | B28: =B27+1 -> 27 | C28: 10 | D28: 2019 | E28: 0 | F28: 0.077909228 | G28: 0 | H28: 0.24162482 | I28: 0 | J28: =J27 -> 1.6865699 | K28: 0 | L28: 0
A29: Budapest | B29: =B28+1 -> 28 | C29: 10 | D29: 2019 | E29: 0 | F29: 0.077909228 | G29: 0 | H29: 0.24162482 | I29: 0 | J29: =J28 -> 1.6865699 | K29: 0 | L29: 0
A30: Budapest | B30: =B29+1 -> 29 | C30: 10 | D30: 2019 | E30: 0 | F30: 0.077909228 | G30: 0 | H30: 0.24162482 | I30: 0 | J30: =J29 -> 1.6865699 | K30: 0 | L30: 0
A31: Budapest | B31: =B30+1 -> 30 | C31: 10 | D31: 2019 | E31: 0 | F31: 0.077909228 | G31: 0 | H31: 0.24162482 | I31: 0 | J31: =J30 -> 1.6865699 | K31: 0 | L31: 0
A32: Budapest | B32: =B31+1 -> 31 | C32: 10 | D32: 2019 | E32: 0 | F32: 0.077909228 | G32: 0 | H32: 0.24162482 | I32: 0 | J32: =J31 -> 1.6865699 | K32: 0 | L32: 0

Sheet Submetering
A1: Site Name | B1: Day | C1: Month | D1: Year | E1: B074 Nagy - m3 | F1: B074 Hotel napi+torony-m3 | G1: B074 Hotel napi-torony -m3 | H1: B057 Nagy - m3 | I1: B074 mosoda víz-m3 | J1: B054 konyha -m3 | K1: HMV konyha -m3 | L1: HMV Hotel -m3 | M1: B 105 Gozakna -m3 | N1: Boiler C. Water -m3 | O1: kazan tapviz jobb -m3 | P1: CT-Spare Water Total -m3 | Q1: SPA Total -m3 | R1: Garage Total -m3 | S1: Steam Total -m3 | T1: Meter #1 -m3 | U1: Meter #2-m3 | V1: Steam Boiler #1 -m3 | W1: Steam Boiler #2 -m3 | X1: Elec. Supply 1 - Kwh | Y1: Elec. Supply 2 - Kwh | Z1: Hotel Absolute Daily -KWh | AA1: Hotel Absolut napi fogyasztas-hutok -KWh | AB1: 18 GARAGE -KWh | AC1: GARAGE + PALACE SUMMA DAYLI - KWh | AD1: Chiller 1 -KWh | AE1: Chiller 2 -KWh | AF1: Room Nights | AG1: Total Guests
A2: Budapest | B2: 1 | C2: 5 | D2: 2019 | E2: =IF(('FS Budapest'!C5-'FS Budapest'!C4)<0,"0",('FS Budapest'!C5-'FS Budapest'!C4)) -> 68 | F2: =IF(('FS Budapest'!D5-'FS Budapest'!D4)<0,"0",('FS Budapest'!D5-'FS Budapest'!D4)) -> 83 | G2: =IF(('FS Budapest'!E5-'FS Budapest'!Y5)<0,"0",('FS Budapest'!E5-'FS Budapest'!Y5)) -> 55 | H2: =IF(('FS Budapest'!H5-'FS Budapest'!H4)<0,"0",('FS Budapest'!H5-'FS Budapest'!H4)) -> 58 | I2: =IF(('FS Budapest'!I5-'FS Budapest'!I4)<0,"0",('FS Budapest'!I5-'FS Budapest'!I4)) -> 21 | J2: =IF(('FS Budapest'!K5-'FS Budapest'!K4)<0,"0",('FS Budapest'!K5-'FS Budapest'!K4)) -> 6 | K2: =IF(('FS Budapest'!M5-'FS Budapest'!M4)<0,"0",('FS Budapest'!M5-'FS Budapest'!M4)) -> 8 | L2: =IF(('FS Budapest'!O5-'FS Budapest'!O4)<0,"0",('FS Budapest'!O5-'FS Budapest'!O4)) -> 13 | M2: =IF(('FS Budapest'!Q5-'FS Budapest'!Q4)<0,"0",('FS Budapest'!Q5-'FS Budapest'!Q4)) -> 3 | N2: =IF(('FS Budapest'!S5-'FS Budapest'!S4)<0,"0",('FS Budapest'!S5-'FS Budapest'!S4)) -> 1 | O2: =IF(('FS Budapest'!V5-'FS Budapest'!V4)<0,"0",('FS Budapest'!V5-'FS Budapest'!V4)) -> 6 | P2: =IF(('FS Budapest'!X5-'FS Budapest'!X4)<0,"0",('FS Budapest'!X5-'FS Budapest'!X4)) -> 28 | Q2: ='FS Budapest'!AB5 -> 4 | R2: ='FS Budapest'!AE5 -> 0 | S2: ='FS Budapest'!AF5 -> 10 | T2: =IF(('FS Budapest'!AK5-'FS Budapest'!AK4)<0,"0",('FS Budapest'!AK5-'FS Budapest'!AK4)) -> 1683 | U2: =IF(('FS Budapest'!AM5-'FS Budapest'!AM4)<0,"0",('FS Budapest'!AM5-'FS Budapest'!AM4)) -> 40 | V2: =IF(('FS Budapest'!AO5-'FS Budapest'!AO4)<0,"0",('FS Budapest'!AO5-'FS Budapest'!AO4)) -> 0 | W2: =IF(('FS Budapest'!AQ5-'FS Budapest'!AQ4)<0,"0",('FS Budapest'!AQ5-'FS Budapest'!AQ4)) -> 485 | X2: ='FS Budapest'!AY5 -> 0 | Y2: =IF(('FS Budapest'!BA5-'FS Budapest'!BA4)<0,"0",('FS Budapest'!BA5-'FS Budapest'!BA4)*4400) -> 18172 | Z2: ='FS Budapest'!BI5 -> 18172 | AA2: ='FS Budapest'!BJ5 -> 15379 | AB2: =IF(('FS Budapest'!BK5-'FS Budapest'!BK4)<0,"0",('FS Budapest'!BK5-'FS Budapest'!BK4)*100) -> 461 | AC2: ='FS Budapest'!BM5 -> 18633 | AD2: =IF(('FS Budapest'!BP5-'FS Budapest'!BP4)<0,"0",('FS Budapest'!BP5-'FS Budapest'!BP4)) -> 19 | AE2: =IF(('FS Budapest'!BR5-'FS Budapest'!BR4)<0,"0",('FS Budapest'!BR5-'FS Budapest'!BR4)) -> 2774 | AF2: ='FS Budapest'!BU5 -> 99 | AG2: ='FS Budapest'!BV5 -> 171
A3: Budapest | B3: =B2+1 -> 2 | C3: 5 | D3: 2019 | E3: =IF(('FS Budapest'!C6-'FS Budapest'!C5)<0,"0",('FS Budapest'!C6-'FS Budapest'!C5)) -> 84 | F3: =IF(('FS Budapest'!D6-'FS Budapest'!D5)<0,"0",('FS Budapest'!D6-'FS Budapest'!D5)) -> 105 | G3: =IF(('FS Budapest'!E6-'FS Budapest'!Y6)<0,"0",('FS Budapest'!E6-'FS Budapest'!Y6)) -> 72 | H3: =IF(('FS Budapest'!H6-'FS Budapest'!H5)<0,"0",('FS Budapest'!H6-'FS Budapest'!H5)) -> 108 | I3: =IF(('FS Budapest'!I6-'FS Budapest'!I5)<0,"0",('FS Budapest'!I6-'FS Budapest'!I5)) -> 25 | J3: =IF(('FS Budapest'!K6-'FS Budapest'!K5)<0,"0",('FS Budapest'!K6-'FS Budapest'!K5)) -> 8 | K3: =IF(('FS Budapest'!M6-'FS Budapest'!M5)<0,"0",('FS Budapest'!M6-'FS Budapest'!M5)) -> 10 | L3: =IF(('FS Budapest'!O6-'FS Budapest'!O5)<0,"0",('FS Budapest'!O6-'FS Budapest'!O5)) -> 19 | M3: =IF(('FS Budapest'!Q6-'FS Budapest'!Q5)<0,"0",('FS Budapest'!Q6-'FS Budapest'!Q5)) -> 2 | N3: =IF(('FS Budapest'!S6-'FS Budapest'!S5)<0,"0",('FS Budapest'!S6-'FS Budapest'!S5)) -> 1 | O3: =IF(('FS Budapest'!V6-'FS Budapest'!V5)<0,"0",('FS Budapest'!V6-'FS Budapest'!V5)) -> 7 | P3: =IF(('FS Budapest'!X6-'FS Budapest'!X5)<0,"0",('FS Budapest'!X6-'FS Budapest'!X5)) -> 33 | Q3: ='FS Budapest'!AB6 -> 3 | R3: ='FS Budapest'!AE6 -> 3 | S3: ='FS Budapest'!AF6 -> 10 | T3: =IF(('FS Budapest'!AK6-'FS Budapest'!AK5)<0,"0",('FS Budapest'!AK6-'FS Budapest'!AK5)) -> 1491 | U3: =IF(('FS Budapest'!AM6-'FS Budapest'!AM5)<0,"0",('FS Budapest'!AM6-'FS Budapest'!AM5)) -> 33 | V3: =IF(('FS Budapest'!AO6-'FS Budapest'!AO5)<0,"0",('FS Budapest'!AO6-'FS Budapest'!AO5)) -> 0 | W3: =IF(('FS Budapest'!AQ6-'FS Budapest'!AQ5)<0,"0",('FS Budapest'!AQ6-'FS Budapest'!AQ5)) -> 501 | X3: ='FS Budapest'!AY6 -> 0 | Y3: =IF(('FS Budapest'!BA6-'FS Budapest'!BA5)<0,"0",('FS Budapest'!BA6-'FS Budapest'!BA5)*4400) -> 19404 | Z3: ='FS Budapest'!BI6 -> 19404 | AA3: ='FS Budapest'!BJ6 -> 16712 | AB3: =IF(('FS Budapest'!BK6-'FS Budapest'!BK5)<0,"0",('FS Budapest'!BK6-'FS Budapest'!BK5)*100) -> 584 | AC3: ='FS Budapest'!BM6 -> 19988 | AD3: =IF(('FS Budapest'!BP6-'FS Budapest'!BP5)<0,"0",('FS Budapest'!BP6-'FS Budapest'!BP5)) -> 19 | AE3: =IF(('FS Budapest'!BR6-'FS Budapest'!BR5)<0,"0",('FS Budapest'!BR6-'FS Budapest'!BR5)) -> 2673 | AF3: ='FS Budapest'!BU6 -> 179 | AG3: ='FS Budapest'!BV6 -> 322
A4: Budapest | B4: =B3+1 -> 3 | C4: 5 | D4: 2019 | E4: =IF(('FS Budapest'!C7-'FS Budapest'!C6)<0,"0",('FS Budapest'!C7-'FS Budapest'!C6)) -> 84 | F4: =IF(('FS Budapest'!D7-'FS Budapest'!D6)<0,"0",('FS Budapest'!D7-'FS Budapest'!D6)) -> 103 | G4: =IF(('FS Budapest'!E7-'FS Budapest'!Y7)<0,"0",('FS Budapest'!E7-'FS Budapest'!Y7)) -> 78 | H4: =IF(('FS Budapest'!H7-'FS Budapest'!H6)<0,"0",('FS Budapest'!H7-'FS Budapest'!H6)) -> 95 | I4: =IF(('FS Budapest'!I7-'FS Budapest'!I6)<0,"0",('FS Budapest'!I7-'FS Budapest'!I6)) -> 24 | J4: =IF(('FS Budapest'!K7-'FS Budapest'!K6)<0,"0",('FS Budapest'!K7-'FS Budapest'!K6)) -> 7 | K4: =IF(('FS Budapest'!M7-'FS Budapest'!M6)<0,"0",('FS Budapest'!M7-'FS Budapest'!M6)) -> 8 | L4: =IF(('FS Budapest'!O7-'FS Budapest'!O6)<0,"0",('FS Budapest'!O7-'FS Budapest'!O6)) -> 25 | M4: =IF(('FS Budapest'!Q7-'FS Budapest'!Q6)<0,"0",('FS Budapest'!Q7-'FS Budapest'!Q6)) -> 3 | N4: =IF(('FS Budapest'!S7-'FS Budapest'!S6)<0,"0",('FS Budapest'!S7-'FS Budapest'!S6)) -> 2 | O4: =IF(('FS Budapest'!V7-'FS Budapest'!V6)<0,"0",('FS Budapest'!V7-'FS Budapest'!V6)) -> 7 | P4: =IF(('FS Budapest'!X7-'FS Budapest'!X6)<0,"0",('FS Budapest'!X7-'FS Budapest'!X6)) -> 25 | Q4: ='FS Budapest'!AB7 -> 4 | R4: ='FS Budapest'!AE7 -> 1 | S4: ='FS Budapest'!AF7 -> 12 | T4: =IF(('FS Budapest'!AK7-'FS Budapest'!AK6)<0,"0",('FS Budapest'!AK7-'FS Budapest'!AK6)) -> 1359 | U4: =IF(('FS Budapest'!AM7-'FS Budapest'!AM6)<0,"0",('FS Budapest'!AM7-'FS Budapest'!AM6)) -> 39 | V4: =IF(('FS Budapest'!AO7-'FS Budapest'!AO6)<0,"0",('FS Budapest'!AO7-'FS Budapest'!AO6)) -> 0 | W4: =IF(('FS Budapest'!AQ7-'FS Budapest'!AQ6)<0,"0",('FS Budapest'!AQ7-'FS Budapest'!AQ6)) -> 514 | X4: ='FS Budapest'!AY7 -> 0 | Y4: =IF(('FS Budapest'!BA7-'FS Budapest'!BA6)<0,"0",('FS Budapest'!BA7-'FS Budapest'!BA6)*4400) -> 18260 | Z4: ='FS Budapest'!BI7 -> 18260 | AA4: ='FS Budapest'!BJ7 -> 15834 | AB4: =IF(('FS Budapest'!BK7-'FS Budapest'!BK6)<0,"0",('FS Budapest'!BK7-'FS Budapest'!BK6)*100) -> 589 | AC4: ='FS Budapest'!BM7 -> 18849 | AD4: =IF(('FS Budapest'!BP7-'FS Budapest'!BP6)<0,"0",('FS Budapest'!BP7-'FS Budapest'!BP6)) -> 18 | AE4: =IF(('FS Budapest'!BR7-'FS Budapest'!BR6)<0,"0",('FS Budapest'!BR7-'FS Budapest'!BR6)) -> 2408 | AF4: ='FS Budapest'!BU7 -> 171 | AG4: ='FS Budapest'!BV7 -> 316
A5: Budapest | B5: =B4+1 -> 4 | C5: 5 | D5: 2019 | E5: =IF(('FS Budapest'!C8-'FS Budapest'!C7)<0,"0",('FS Budapest'!C8-'FS Budapest'!C7)) -> 93 | F5: =IF(('FS Budapest'!D8-'FS Budapest'!D7)<0,"0",('FS Budapest'!D8-'FS Budapest'!D7)) -> 105 | G5: =IF(('FS Budapest'!E8-'FS Budapest'!Y8)<0,"0",('FS Budapest'!E8-'FS Budapest'!Y8)) -> 88 | H5: =IF(('FS Budapest'!H8-'FS Budapest'!H7)<0,"0",('FS Budapest'!H8-'FS Budapest'!H7)) -> 88 | I5: =IF(('FS Budapest'!I8-'FS Budapest'!I7)<0,"0",('FS Budapest'!I8-'FS Budapest'!I7)) -> 24 | J5: =IF(('FS Budapest'!K8-'FS Budapest'!K7)<0,"0",('FS Budapest'!K8-'FS Budapest'!K7)) -> 7 | K5: =IF(('FS Budapest'!M8-'FS Budapest'!M7)<0,"0",('FS Budapest'!M8-'FS Budapest'!M7)) -> 11 | L5: =IF(('FS Budapest'!O8-'FS Budapest'!O7)<0,"0",('FS Budapest'!O8-'FS Budapest'!O7)) -> 33 | M5: =IF(('FS Budapest'!Q8-'FS Budapest'!Q7)<0,"0",('FS Budapest'!Q8-'FS Budapest'!Q7)) -> 2 | N5: =IF(('FS Budapest'!S8-'FS Budapest'!S7)<0,"0",('FS Budapest'!S8-'FS Budapest'!S7)) -> 2 | O5: =IF(('FS Budapest'!V8-'FS Budapest'!V7)<0,"0",('FS Budapest'!V8-'FS Budapest'!V7)) -> 6 | P5: =IF(('FS Budapest'!X8-'FS Budapest'!X7)<0,"0",('FS Budapest'!X8-'FS Budapest'!X7)) -> 17 | Q5: ='FS Budapest'!AB8 -> 3 | R5: ='FS Budapest'!AE8 -> 2 | S5: ='FS Budapest'!AF8 -> 10 | T5: =IF(('FS Budapest'!AK8-'FS Budapest'!AK7)<0,"0",('FS Budapest'!AK8-'FS Budapest'!AK7)) -> 1570 | U5: =IF(('FS Budapest'!AM8-'FS Budapest'!AM7)<0,"0",('FS Budapest'!AM8-'FS Budapest'!AM7)) -> 42 | V5: =IF(('FS Budapest'!AO8-'FS Budapest'!AO7)<0,"0",('FS Budapest'!AO8-'FS Budapest'!AO7)) -> 0 | W5: =IF(('FS Budapest'!AQ8-'FS Budapest'!AQ7)<0,"0",('FS Budapest'!AQ8-'FS Budapest'!AQ7)) -> 521 | X5: ='FS Budapest'!AY8 -> 0 | Y5: =IF(('FS Budapest'!BA8-'FS Budapest'!BA7)<0,"0",('FS Budapest'!BA8-'FS Budapest'!BA7)*4400) -> 18040 | Z5: ='FS Budapest'!BI8 -> 18040 | AA5: ='FS Budapest'!BJ8 -> 15805 | AB5: =IF(('FS Budapest'!BK8-'FS Budapest'!BK7)<0,"0",('FS Budapest'!BK8-'FS Budapest'!BK7)*100) -> 511 | AC5: ='FS Budapest'!BM8 -> 18551 | AD5: =IF(('FS Budapest'!BP8-'FS Budapest'!BP7)<0,"0",('FS Budapest'!BP8-'FS Budapest'!BP7)) -> 20 | AE5: =IF(('FS Budapest'!BR8-'FS Budapest'!BR7)<0,"0",('FS Budapest'!BR8-'FS Budapest'!BR7)) -> 2215 | AF5: ='FS Budapest'!BU8 -> 170 | AG5: ='FS Budapest'!BV8 -> 315
A6: Budapest | B6: =B5+1 -> 5 | C6: 5 | D6: 2019 | E6: =IF(('FS Budapest'!C9-'FS Budapest'!C8)<0,"0",('FS Budapest'!C9-'FS Budapest'!C8)) -> 85 | F6: =IF(('FS Budapest'!D9-'FS Budapest'!D8)<0,"0",('FS Budapest'!D9-'FS Budapest'!D8)) -> 103 | G6: =IF(('FS Budapest'!E9-'FS Budapest'!Y9)<0,"0",('FS Budapest'!E9-'FS Budapest'!Y9)) -> 86 | H6: =IF(('FS Budapest'!H9-'FS Budapest'!H8)<0,"0",('FS Budapest'!H9-'FS Budapest'!H8)) -> 91 | I6: =IF(('FS Budapest'!I9-'FS Budapest'!I8)<0,"0",('FS Budapest'!I9-'FS Budapest'!I8)) -> 26 | J6: =IF(('FS Budapest'!K9-'FS Budapest'!K8)<0,"0",('FS Budapest'!K9-'FS Budapest'!K8)) -> 6 | K6: =IF(('FS Budapest'!M9-'FS Budapest'!M8)<0,"0",('FS Budapest'!M9-'FS Budapest'!M8)) -> 8 | L6: =IF(('FS Budapest'!O9-'FS Budapest'!O8)<0,"0",('FS Budapest'!O9-'FS Budapest'!O8)) -> 33 | M6: =IF(('FS Budapest'!Q9-'FS Budapest'!Q8)<0,"0",('FS Budapest'!Q9-'FS Budapest'!Q8)) -> 2 | N6: =IF(('FS Budapest'!S9-'FS Budapest'!S8)<0,"0",('FS Budapest'!S9-'FS Budapest'!S8)) -> 1 | O6: =IF(('FS Budapest'!V9-'FS Budapest'!V8)<0,"0",('FS Budapest'!V9-'FS Budapest'!V8)) -> 7 | P6: =IF(('FS Budapest'!X9-'FS Budapest'!X8)<0,"0",('FS Budapest'!X9-'FS Budapest'!X8)) -> 17 | Q6: ='FS Budapest'!AB9 -> 3 | R6: ='FS Budapest'!AE9 -> 2 | S6: ='FS Budapest'!AF9 -> 10 | T6: =IF(('FS Budapest'!AK9-'FS Budapest'!AK8)<0,"0",('FS Budapest'!AK9-'FS Budapest'!AK8)) -> 1897 | U6: =IF(('FS Budapest'!AM9-'FS Budapest'!AM8)<0,"0",('FS Budapest'!AM9-'FS Budapest'!AM8)) -> 51 | V6: =IF(('FS Budapest'!AO9-'FS Budapest'!AO8)<0,"0",('FS Budapest'!AO9-'FS Budapest'!AO8)) -> 0 | W6: =IF(('FS Budapest'!AQ9-'FS Budapest'!AQ8)<0,"0",('FS Budapest'!AQ9-'FS Budapest'!AQ8)) -> 519 | X6: ='FS Budapest'!AY9 -> 0 | Y6: =IF(('FS Budapest'!BA9-'FS Budapest'!BA8)<0,"0",('FS Budapest'!BA9-'FS Budapest'!BA8)*4400) -> 18172 | Z6: ='FS Budapest'!BI9 -> 18172 | AA6: ='FS Budapest'!BJ9 -> 15932 | AB6: =IF(('FS Budapest'!BK9-'FS Budapest'!BK8)<0,"0",('FS Budapest'!BK9-'FS Budapest'!BK8)*100) -> 508 | AC6: ='FS Budapest'!BM9 -> 18680 | AD6: =IF(('FS Budapest'!BP9-'FS Budapest'!BP8)<0,"0",('FS Budapest'!BP9-'FS Budapest'!BP8)) -> 19 | AE6: =IF(('FS Budapest'!BR9-'FS Budapest'!BR8)<0,"0",('FS Budapest'!BR9-'FS Budapest'!BR8)) -> 2221 | AF6: ='FS Budapest'!BU9 -> 167 | AG6: ='FS Budapest'!BV9 -> 841
A7: Budapest | B7: =B6+1 -> 6 | C7: 5 | D7: 2019 | E7: =IF(('FS Budapest'!C10-'FS Budapest'!C9)<0,"0",('FS Budapest'!C10-'FS Budapest'!C9)) -> 88 | F7: =IF(('FS Budapest'!D10-'FS Budapest'!D9)<0,"0",('FS Budapest'!D10-'FS Budapest'!D9)) -> 105 | G7: =IF(('FS Budapest'!E10-'FS Budapest'!Y10)<0,"0",('FS Budapest'!E10-'FS Budapest'!Y10)) -> 88 | H7: =IF(('FS Budapest'!H10-'FS Budapest'!H9)<0,"0",('FS Budapest'!H10-'FS Budapest'!H9)) -> 100 | I7: =IF(('FS Budapest'!I10-'FS Budapest'!I9)<0,"0",('FS Budapest'!I10-'FS Budapest'!I9)) -> 27 | J7: =IF(('FS Budapest'!K10-'FS Budapest'!K9)<0,"0",('FS Budapest'!K10-'FS Budapest'!K9)) -> 8 | K7: =IF(('FS Budapest'!M10-'FS Budapest'!M9)<0,"0",('FS Budapest'!M10-'FS Budapest'!M9)) -> 10 | L7: =IF(('FS Budapest'!O10-'FS Budapest'!O9)<0,"0",('FS Budapest'!O10-'FS Budapest'!O9)) -> 31 | M7: =IF(('FS Budapest'!Q10-'FS Budapest'!Q9)<0,"0",('FS Budapest'!Q10-'FS Budapest'!Q9)) -> 2 | N7: =IF(('FS Budapest'!S10-'FS Budapest'!S9)<0,"0",('FS Budapest'!S10-'FS Budapest'!S9)) -> 1 | O7: =IF(('FS Budapest'!V10-'FS Budapest'!V9)<0,"0",('FS Budapest'!V10-'FS Budapest'!V9)) -> 7 | P7: =IF(('FS Budapest'!X10-'FS Budapest'!X9)<0,"0",('FS Budapest'!X10-'FS Budapest'!X9)) -> 17 | Q7: ='FS Budapest'!AB10 -> 4 | R7: ='FS Budapest'!AE10 -> 1 | S7: ='FS Budapest'!AF10 -> 10 | T7: =IF(('FS Budapest'!AK10-'FS Budapest'!AK9)<0,"0",('FS Budapest'!AK10-'FS Budapest'!AK9)) -> 2527 | U7: =IF(('FS Budapest'!AM10-'FS Budapest'!AM9)<0,"0",('FS Budapest'!AM10-'FS Budapest'!AM9)) -> 39 | V7: =IF(('FS Budapest'!AO10-'FS Budapest'!AO9)<0,"0",('FS Budapest'!AO10-'FS Budapest'!AO9)) -> 0 | W7: =IF(('FS Budapest'!AQ10-'FS Budapest'!AQ9)<0,"0",('FS Budapest'!AQ10-'FS Budapest'!AQ9)) -> 520 | X7: ='FS Budapest'!AY10 -> 0 | Y7: =IF(('FS Budapest'!BA10-'FS Budapest'!BA9)<0,"0",('FS Budapest'!BA10-'FS Budapest'!BA9)*4400) -> 19140 | Z7: ='FS Budapest'!BI10 -> 19140 | AA7: ='FS Budapest'!BJ10 -> 16866 | AB7: =IF(('FS Budapest'!BK10-'FS Budapest'!BK9)<0,"0",('FS Budapest'!BK10-'FS Budapest'!BK9)*100) -> 502 | AC7: ='FS Budapest'!BM10 -> 19642 | AD7: =IF(('FS Budapest'!BP10-'FS Budapest'!BP9)<0,"0",('FS Budapest'!BP10-'FS Budapest'!BP9)) -> 19 | AE7: =IF(('FS Budapest'!BR10-'FS Budapest'!BR9)<0,"0",('FS Budapest'!BR10-'FS Budapest'!BR9)) -> 2255 | AF7: ='FS Budapest'!BU10 -> 174 | AG7: ='FS Budapest'!BV10 -> 302
A8: Budapest | B8: =B7+1 -> 7 | C8: 5 | D8: 2019 | E8: =IF(('FS Budapest'!C11-'FS Budapest'!C10)<0,"0",('FS Budapest'!C11-'FS Budapest'!C10)) -> 69 | F8: =IF(('FS Budapest'!D11-'FS Budapest'!D10)<0,"0",('FS Budapest'!D11-'FS Budapest'!D10)) -> 77 | G8: =IF(('FS Budapest'!E11-'FS Budapest'!Y11)<0,"0",('FS Budapest'!E11-'FS Budapest'!Y11)) -> 58 | H8: =IF(('FS Budapest'!H11-'FS Budapest'!H10)<0,"0",('FS Budapest'!H11-'FS Budapest'!H10)) -> 87 | I8: =IF(('FS Budapest'!I11-'FS Budapest'!I10)<0,"0",('FS Budapest'!I11-'FS Budapest'!I10)) -> 27 | J8: =IF(('FS Budapest'!K11-'FS Budapest'!K10)<0,"0",('FS Budapest'!K11-'FS Budapest'!K10)) -> 6 | K8: =IF(('FS Budapest'!M11-'FS Budapest'!M10)<0,"0",('FS Budapest'!M11-'FS Budapest'!M10)) -> 9 | L8: =IF(('FS Budapest'!O11-'FS Budapest'!O10)<0,"0",('FS Budapest'!O11-'FS Budapest'!O10)) -> 16 | M8: =IF(('FS Budapest'!Q11-'FS Budapest'!Q10)<0,"0",('FS Budapest'!Q11-'FS Budapest'!Q10)) -> 1 | N8: =IF(('FS Budapest'!S11-'FS Budapest'!S10)<0,"0",('FS Budapest'!S11-'FS Budapest'!S10)) -> 1 | O8: =IF(('FS Budapest'!V11-'FS Budapest'!V10)<0,"0",('FS Budapest'!V11-'FS Budapest'!V10)) -> 7 | P8: =IF(('FS Budapest'!X11-'FS Budapest'!X10)<0,"0",('FS Budapest'!X11-'FS Budapest'!X10)) -> 19 | Q8: ='FS Budapest'!AB11 -> 3 | R8: ='FS Budapest'!AE11 -> 0 | S8: ='FS Budapest'!AF11 -> 9 | T8: =IF(('FS Budapest'!AK11-'FS Budapest'!AK10)<0,"0",('FS Budapest'!AK11-'FS Budapest'!AK10)) -> 1731 | U8: =IF(('FS Budapest'!AM11-'FS Budapest'!AM10)<0,"0",('FS Budapest'!AM11-'FS Budapest'!AM10)) -> 35 | V8: =IF(('FS Budapest'!AO11-'FS Budapest'!AO10)<0,"0",('FS Budapest'!AO11-'FS Budapest'!AO10)) -> 0 | W8: =IF(('FS Budapest'!AQ11-'FS Budapest'!AQ10)<0,"0",('FS Budapest'!AQ11-'FS Budapest'!AQ10)) -> 627 | X8: ='FS Budapest'!AY11 -> 0 | Y8: =IF(('FS Budapest'!BA11-'FS Budapest'!BA10)<0,"0",('FS Budapest'!BA11-'FS Budapest'!BA10)*4400) -> 17468 | Z8: ='FS Budapest'!BI11 -> 17468 | AA8: ='FS Budapest'!BJ11 -> 15997 | AB8: =IF(('FS Budapest'!BK11-'FS Budapest'!BK10)<0,"0",('FS Budapest'!BK11-'FS Budapest'!BK10)*100) -> 801 | AC8: ='FS Budapest'!BM11 -> 18269 | AD8: =IF(('FS Budapest'!BP11-'FS Budapest'!BP10)<0,"0",('FS Budapest'!BP11-'FS Budapest'!BP10)) -> 19 | AE8: =IF(('FS Budapest'!BR11-'FS Budapest'!BR10)<0,"0",('FS Budapest'!BR11-'FS Budapest'!BR10)) -> 1452 | AF8: ='FS Budapest'!BU11 -> 113 | AG8: ='FS Budapest'!BV11 -> 163
A9: Budapest | B9: =B8+1 -> 8 | C9: 5 | D9: 2019 | E9: =IF(('FS Budapest'!C12-'FS Budapest'!C11)<0,"0",('FS Budapest'!C12-'FS Budapest'!C11)) -> 68 | F9: =IF(('FS Budapest'!D12-'FS Budapest'!D11)<0,"0",('FS Budapest'!D12-'FS Budapest'!D11)) -> 81 | G9: =IF(('FS Budapest'!E12-'FS Budapest'!Y12)<0,"0",('FS Budapest'!E12-'FS Budapest'!Y12)) -> 61 | H9: =IF(('FS Budapest'!H12-'FS Budapest'!H11)<0,"0",('FS Budapest'!H12-'FS Budapest'!H11)) -> 93 | I9: =IF(('FS Budapest'!I12-'FS Budapest'!I11)<0,"0",('FS Budapest'!I12-'FS Budapest'!I11)) -> 27 | J9: =IF(('FS Budapest'!K12-'FS Budapest'!K11)<0,"0",('FS Budapest'!K12-'FS Budapest'!K11)) -> 6 | K9: =IF(('FS Budapest'!M12-'FS Budapest'!M11)<0,"0",('FS Budapest'!M12-'FS Budapest'!M11)) -> 8 | L9: =IF(('FS Budapest'!O12-'FS Budapest'!O11)<0,"0",('FS Budapest'!O12-'FS Budapest'!O11)) -> 16 | M9: =IF(('FS Budapest'!Q12-'FS Budapest'!Q11)<0,"0",('FS Budapest'!Q12-'FS Budapest'!Q11)) -> 1 | N9: =IF(('FS Budapest'!S12-'FS Budapest'!S11)<0,"0",('FS Budapest'!S12-'FS Budapest'!S11)) -> 2 | O9: =IF(('FS Budapest'!V12-'FS Budapest'!V11)<0,"0",('FS Budapest'!V12-'FS Budapest'!V11)) -> 6 | P9: =IF(('FS Budapest'!X12-'FS Budapest'!X11)<0,"0",('FS Budapest'!X12-'FS Budapest'!X11)) -> 20 | Q9: ='FS Budapest'!AB12 -> 4 | R9: ='FS Budapest'!AE12 -> 3 | S9: ='FS Budapest'!AF12 -> 9 | T9: =IF(('FS Budapest'!AK12-'FS Budapest'!AK11)<0,"0",('FS Budapest'!AK12-'FS Budapest'!AK11)) -> 1366 | U9: =IF(('FS Budapest'!AM12-'FS Budapest'!AM11)<0,"0",('FS Budapest'!AM12-'FS Budapest'!AM11)) -> 46 | V9: =IF(('FS Budapest'!AO12-'FS Budapest'!AO11)<0,"0",('FS Budapest'!AO12-'FS Budapest'!AO11)) -> 0 | W9: =IF(('FS Budapest'!AQ12-'FS Budapest'!AQ11)<0,"0",('FS Budapest'!AQ12-'FS Budapest'!AQ11)) -> 373 | X9: ='FS Budapest'!AY12 -> 0 | Y9: =IF(('FS Budapest'!BA12-'FS Budapest'!BA11)<0,"0",('FS Budapest'!BA12-'FS Budapest'!BA11)*4400) -> 17116 | Z9: ='FS Budapest'!BI12 -> 17116 | AA9: ='FS Budapest'!BJ12 -> 15299 | AB9: =IF(('FS Budapest'!BK12-'FS Budapest'!BK11)<0,"0",('FS Budapest'!BK12-'FS Budapest'!BK11)*100) -> 612 | AC9: ='FS Budapest'!BM12 -> 17728 | AD9: =IF(('FS Budapest'!BP12-'FS Budapest'!BP11)<0,"0",('FS Budapest'!BP12-'FS Budapest'!BP11)) -> 19 | AE9: =IF(('FS Budapest'!BR12-'FS Budapest'!BR11)<0,"0",('FS Budapest'!BR12-'FS Budapest'!BR11)) -> 1798 | AF9: ='FS Budapest'!BU12 -> 174 | AG9: ='FS Budapest'!BV12 -> 249
A10: Budapest | B10: =B9+1 -> 9 | C10: 5 | D10: 2019 | E10: =IF(('FS Budapest'!C13-'FS Budapest'!C12)<0,"0",('FS Budapest'!C13-'FS Budapest'!C12)) -> 68 | F10: =IF(('FS Budapest'!D13-'FS Budapest'!D12)<0,"0",('FS Budapest'!D13-'FS Budapest'!D12)) -> 82 | G10: =IF(('FS Budapest'!E13-'FS Budapest'!Y13)<0,"0",('FS Budapest'!E13-'FS Budapest'!Y13)) -> 68 | H10: =IF(('FS Budapest'!H13-'FS Budapest'!H12)<0,"0",('FS Budapest'!H13-'FS Budapest'!H12)) -> 91 | I10: =IF(('FS Budapest'!I13-'FS Budapest'!I12)<0,"0",('FS Budapest'!I13-'FS Budapest'!I12)) -> 24 | J10: =IF(('FS Budapest'!K13-'FS Budapest'!K12)<0,"0",('FS Budapest'!K13-'FS Budapest'!K12)) -> 6 | K10: =IF(('FS Budapest'!M13-'FS Budapest'!M12)<0,"0",('FS Budapest'!M13-'FS Budapest'!M12)) -> 10 | L10: =IF(('FS Budapest'!O13-'FS Budapest'!O12)<0,"0",('FS Budapest'!O13-'FS Budapest'!O12)) -> 18 | M10: =IF(('FS Budapest'!Q13-'FS Budapest'!Q12)<0,"0",('FS Budapest'!Q13-'FS Budapest'!Q12)) -> 2 | N10: =IF(('FS Budapest'!S13-'FS Budapest'!S12)<0,"0",('FS Budapest'!S13-'FS Budapest'!S12)) -> 1 | O10: =IF(('FS Budapest'!V13-'FS Budapest'!V12)<0,"0",('FS Budapest'!V13-'FS Budapest'!V12)) -> 7 | P10: =IF(('FS Budapest'!X13-'FS Budapest'!X12)<0,"0",('FS Budapest'!X13-'FS Budapest'!X12)) -> 14 | Q10: ='FS Budapest'!AB13 -> 3 | R10: ='FS Budapest'!AE13 -> 1 | S10: ='FS Budapest'!AF13 -> 10 | T10: =IF(('FS Budapest'!AK13-'FS Budapest'!AK12)<0,"0",('FS Budapest'!AK13-'FS Budapest'!AK12)) -> 1445 | U10: =IF(('FS Budapest'!AM13-'FS Budapest'!AM12)<0,"0",('FS Budapest'!AM13-'FS Budapest'!AM12)) -> 36 | V10: =IF(('FS Budapest'!AO13-'FS Budapest'!AO12)<0,"0",('FS Budapest'!AO13-'FS Budapest'!AO12)) -> 0 | W10: =IF(('FS Budapest'!AQ13-'FS Budapest'!AQ12)<0,"0",('FS Budapest'!AQ13-'FS Budapest'!AQ12)) -> 532 | X10: ='FS Budapest'!AY13 -> 0 | Y10: =IF(('FS Budapest'!BA13-'FS Budapest'!BA12)<0,"0",('FS Budapest'!BA13-'FS Budapest'!BA12)*4400) -> 18128 | Z10: ='FS Budapest'!BI13 -> 18128 | AA10: ='FS Budapest'!BJ13 -> 16621 | AB10: =IF(('FS Budapest'!BK13-'FS Budapest'!BK12)<0,"0",('FS Budapest'!BK13-'FS Budapest'!BK12)*100) -> 587 | AC10: ='FS Budapest'!BM13 -> 18715 | AD10: =IF(('FS Budapest'!BP13-'FS Budapest'!BP12)<0,"0",('FS Budapest'!BP13-'FS Budapest'!BP12)) -> 19 | AE10: =IF(('FS Budapest'!BR13-'FS Budapest'!BR12)<0,"0",('FS Budapest'!BR13-'FS Budapest'!BR12)) -> 1488 | AF10: ='FS Budapest'!BU13 -> 162 | AG10: ='FS Budapest'!BV13 -> 241
A11: Budapest | B11: =B10+1 -> 10 | C11: 5 | D11: 2019 | E11: =IF(('FS Budapest'!C14-'FS Budapest'!C13)<0,"0",('FS Budapest'!C14-'FS Budapest'!C13)) -> 71 | F11: =IF(('FS Budapest'!D14-'FS Budapest'!D13)<0,"0",('FS Budapest'!D14-'FS Budapest'!D13)) -> 84 | G11: =IF(('FS Budapest'!E14-'FS Budapest'!Y14)<0,"0",('FS Budapest'!E14-'FS Budapest'!Y14)) -> 63 | H11: =IF(('FS Budapest'!H14-'FS Budapest'!H13)<0,"0",('FS Budapest'!H14-'FS Budapest'!H13)) -> 95 | I11: =IF(('FS Budapest'!I14-'FS Budapest'!I13)<0,"0",('FS Budapest'!I14-'FS Budapest'!I13)) -> 26 | J11: =IF(('FS Budapest'!K14-'FS Budapest'!K13)<0,"0",('FS Budapest'!K14-'FS Budapest'!K13)) -> 6 | K11: =IF(('FS Budapest'!M14-'FS Budapest'!M13)<0,"0",('FS Budapest'!M14-'FS Budapest'!M13)) -> 8 | L11: =IF(('FS Budapest'!O14-'FS Budapest'!O13)<0,"0",('FS Budapest'!O14-'FS Budapest'!O13)) -> 21 | M11: =IF(('FS Budapest'!Q14-'FS Budapest'!Q13)<0,"0",('FS Budapest'!Q14-'FS Budapest'!Q13)) -> 2 | N11: =IF(('FS Budapest'!S14-'FS Budapest'!S13)<0,"0",('FS Budapest'!S14-'FS Budapest'!S13)) -> 1 | O11: =IF(('FS Budapest'!V14-'FS Budapest'!V13)<0,"0",('FS Budapest'!V14-'FS Budapest'!V13)) -> 7 | P11: =IF(('FS Budapest'!X14-'FS Budapest'!X13)<0,"0",('FS Budapest'!X14-'FS Budapest'!X13)) -> 21 | Q11: ='FS Budapest'!AB14 -> 4 | R11: ='FS Budapest'!AE14 -> 3 | S11: ='FS Budapest'!AF14 -> 10 | T11: =IF(('FS Budapest'!AK14-'FS Budapest'!AK13)<0,"0",('FS Budapest'!AK14-'FS Budapest'!AK13)) -> 1339 | U11: =IF(('FS Budapest'!AM14-'FS Budapest'!AM13)<0,"0",('FS Budapest'!AM14-'FS Budapest'!AM13)) -> 38 | V11: =IF(('FS Budapest'!AO14-'FS Budapest'!AO13)<0,"0",('FS Budapest'!AO14-'FS Budapest'!AO13)) -> 0 | W11: =IF(('FS Budapest'!AQ14-'FS Budapest'!AQ13)<0,"0",('FS Budapest'!AQ14-'FS Budapest'!AQ13)) -> 534 | X11: ='FS Budapest'!AY14 -> 0 | Y11: =IF(('FS Budapest'!BA14-'FS Budapest'!BA13)<0,"0",('FS Budapest'!BA14-'FS Budapest'!BA13)*4400) -> 17908 | Z11: ='FS Budapest'!BI14 -> 17908 | AA11: ='FS Budapest'!BJ14 -> 15709 | AB11: =IF(('FS Budapest'!BK14-'FS Budapest'!BK13)<0,"0",('FS Budapest'!BK14-'FS Budapest'!BK13)*100) -> 599 | AC11: ='FS Budapest'!BM14 -> 18507 | AD11: =IF(('FS Budapest'!BP14-'FS Budapest'!BP13)<0,"0",('FS Budapest'!BP14-'FS Budapest'!BP13)) -> 19 | AE11: =IF(('FS Budapest'!BR14-'FS Budapest'!BR13)<0,"0",('FS Budapest'!BR14-'FS Budapest'!BR13)) -> 2180 | AF11: ='FS Budapest'!BU14 -> 101 | AG11: ='FS Budapest'!BV14 -> 171
A12: Budapest | B12: =B11+1 -> 11 | C12: 5 | D12: 2019 | E12: =IF(('FS Budapest'!C15-'FS Budapest'!C14)<0,"0",('FS Budapest'!C15-'FS Budapest'!C14)) -> 66 | F12: =IF(('FS Budapest'!D15-'FS Budapest'!D14)<0,"0",('FS Budapest'!D15-'FS Budapest'!D14)) -> 76 | G12: =IF(('FS Budapest'!E15-'FS Budapest'!Y15)<0,"0",('FS Budapest'!E15-'FS Budapest'!Y15)) -> 48 | H12: =IF(('FS Budapest'!H15-'FS Budapest'!H14)<0,"0",('FS Budapest'!H15-'FS Budapest'!H14)) -> 84 | I12: =IF(('FS Budapest'!I15-'FS Budapest'!I14)<0,"0",('FS Budapest'!I15-'FS Budapest'!I14)) -> 22 | J12: =IF(('FS Budapest'!K15-'FS Budapest'!K14)<0,"0",('FS Budapest'!K15-'FS Budapest'!K14)) -> 6 | K12: =IF(('FS Budapest'!M15-'FS Budapest'!M14)<0,"0",('FS Budapest'!M15-'FS Budapest'!M14)) -> 9 | L12: =IF(('FS Budapest'!O15-'FS Budapest'!O14)<0,"0",('FS Budapest'!O15-'FS Budapest'!O14)) -> 12 | M12: =IF(('FS Budapest'!Q15-'FS Budapest'!Q14)<0,"0",('FS Budapest'!Q15-'FS Budapest'!Q14)) -> 2 | N12: =IF(('FS Budapest'!S15-'FS Budapest'!S14)<0,"0",('FS Budapest'!S15-'FS Budapest'!S14)) -> 2 | O12: =IF(('FS Budapest'!V15-'FS Budapest'!V14)<0,"0",('FS Budapest'!V15-'FS Budapest'!V14)) -> 6 | P12: =IF(('FS Budapest'!X15-'FS Budapest'!X14)<0,"0",('FS Budapest'!X15-'FS Budapest'!X14)) -> 28 | Q12: ='FS Budapest'!AB15 -> 3 | R12: ='FS Budapest'!AE15 -> 2 | S12: ='FS Budapest'!AF15 -> 10 | T12: =IF(('FS Budapest'!AK15-'FS Budapest'!AK14)<0,"0",('FS Budapest'!AK15-'FS Budapest'!AK14)) -> 1305 | U12: =IF(('FS Budapest'!AM15-'FS Budapest'!AM14)<0,"0",('FS Budapest'!AM15-'FS Budapest'!AM14)) -> 39 | V12: =IF(('FS Budapest'!AO15-'FS Budapest'!AO14)<0,"0",('FS Budapest'!AO15-'FS Budapest'!AO14)) -> 0 | W12: =IF(('FS Budapest'!AQ15-'FS Budapest'!AQ14)<0,"0",('FS Budapest'!AQ15-'FS Budapest'!AQ14)) -> 535 | X12: ='FS Budapest'!AY15 -> 0 | Y12: =IF(('FS Budapest'!BA15-'FS Budapest'!BA14)<0,"0",('FS Budapest'!BA15-'FS Budapest'!BA14)*4400) -> 17556 | Z12: ='FS Budapest'!BI15 -> 17556 | AA12: ='FS Budapest'!BJ15 -> 14987 | AB12: =IF(('FS Budapest'!BK15-'FS Budapest'!BK14)<0,"0",('FS Budapest'!BK15-'FS Budapest'!BK14)*100) -> 494 | AC12: ='FS Budapest'!BM15 -> 18050 | AD12: =IF(('FS Budapest'!BP15-'FS Budapest'!BP14)<0,"0",('FS Budapest'!BP15-'FS Budapest'!BP14)) -> 19 | AE12: =IF(('FS Budapest'!BR15-'FS Budapest'!BR14)<0,"0",('FS Budapest'!BR15-'FS Budapest'!BR14)) -> 2550 | AF12: ='FS Budapest'!BU15 -> 92 | AG12: ='FS Budapest'!BV15 -> 163
A13: Budapest | B13: =B12+1 -> 12 | C13: 5 | D13: 2019 | E13: =IF(('FS Budapest'!C16-'FS Budapest'!C15)<0,"0",('FS Budapest'!C16-'FS Budapest'!C15)) -> 62 | F13: =IF(('FS Budapest'!D16-'FS Budapest'!D15)<0,"0",('FS Budapest'!D16-'FS Budapest'!D15)) -> 79 | G13: =IF(('FS Budapest'!E16-'FS Budapest'!Y16)<0,"0",('FS Budapest'!E16-'FS Budapest'!Y16)) -> 53 | H13: =IF(('FS Budapest'!H16-'FS Budapest'!H15)<0,"0",('FS Budapest'!H16-'FS Budapest'!H15)) -> 93 | I13: =IF(('FS Budapest'!I16-'FS Budapest'!I15)<0,"0",('FS Budapest'!I16-'FS Budapest'!I15)) -> 25 | J13: =IF(('FS Budapest'!K16-'FS Budapest'!K15)<0,"0",('FS Budapest'!K16-'FS Budapest'!K15)) -> 5 | K13: =IF(('FS Budapest'!M16-'FS Budapest'!M15)<0,"0",('FS Budapest'!M16-'FS Budapest'!M15)) -> 8 | L13: =IF(('FS Budapest'!O16-'FS Budapest'!O15)<0,"0",('FS Budapest'!O16-'FS Budapest'!O15)) -> 13 | M13: =IF(('FS Budapest'!Q16-'FS Budapest'!Q15)<0,"0",('FS Budapest'!Q16-'FS Budapest'!Q15)) -> 3 | N13: =IF(('FS Budapest'!S16-'FS Budapest'!S15)<0,"0",('FS Budapest'!S16-'FS Budapest'!S15)) -> 2 | O13: =IF(('FS Budapest'!V16-'FS Budapest'!V15)<0,"0",('FS Budapest'!V16-'FS Budapest'!V15)) -> 8 | P13: =IF(('FS Budapest'!X16-'FS Budapest'!X15)<0,"0",('FS Budapest'!X16-'FS Budapest'!X15)) -> 26 | Q13: ='FS Budapest'!AB16 -> 3 | R13: ='FS Budapest'!AE16 -> 2 | S13: ='FS Budapest'!AF16 -> 13 | T13: =IF(('FS Budapest'!AK16-'FS Budapest'!AK15)<0,"0",('FS Budapest'!AK16-'FS Budapest'!AK15)) -> 1237 | U13: =IF(('FS Budapest'!AM16-'FS Budapest'!AM15)<0,"0",('FS Budapest'!AM16-'FS Budapest'!AM15)) -> 48 | V13: =IF(('FS Budapest'!AO16-'FS Budapest'!AO15)<0,"0",('FS Budapest'!AO16-'FS Budapest'!AO15)) -> 0 | W13: =IF(('FS Budapest'!AQ16-'FS Budapest'!AQ15)<0,"0",('FS Budapest'!AQ16-'FS Budapest'!AQ15)) -> 550 | X13: ='FS Budapest'!AY16 -> 0 | Y13: =IF(('FS Budapest'!BA16-'FS Budapest'!BA15)<0,"0",('FS Budapest'!BA16-'FS Budapest'!BA15)*4400) -> 17556 | Z13: ='FS Budapest'!BI16 -> 17556 | AA13: ='FS Budapest'!BJ16 -> 14945 | AB13: =IF(('FS Budapest'!BK16-'FS Budapest'!BK15)<0,"0",('FS Budapest'!BK16-'FS Budapest'!BK15)*100) -> 542 | AC13: ='FS Budapest'!BM16 -> 18098 | AD13: =IF(('FS Budapest'!BP16-'FS Budapest'!BP15)<0,"0",('FS Budapest'!BP16-'FS Budapest'!BP15)) -> 19 | AE13: =IF(('FS Budapest'!BR16-'FS Budapest'!BR15)<0,"0",('FS Budapest'!BR16-'FS Budapest'!BR15)) -> 2592 | AF13: ='FS Budapest'!BU16 -> 101 | AG13: ='FS Budapest'!BV16 -> 168
A14: Budapest | B14: =B13+1 -> 13 | C14: 5 | D14: 2019 | E14: =IF(('FS Budapest'!C17-'FS Budapest'!C16)<0,"0",('FS Budapest'!C17-'FS Budapest'!C16)) -> 49 | F14: =IF(('FS Budapest'!D17-'FS Budapest'!D16)<0,"0",('FS Budapest'!D17-'FS Budapest'!D16)) -> 81 | G14: =IF(('FS Budapest'!E17-'FS Budapest'!Y17)<0,"0",('FS Budapest'!E17-'FS Budapest'!Y17)) -> 58 | H14: =IF(('FS Budapest'!H17-'FS Budapest'!H16)<0,"0",('FS Budapest'!H17-'FS Budapest'!H16)) -> 108 | I14: =IF(('FS Budapest'!I17-'FS Budapest'!I16)<0,"0",('FS Budapest'!I17-'FS Budapest'!I16)) -> 26 | J14: =IF(('FS Budapest'!K17-'FS Budapest'!K16)<0,"0",('FS Budapest'!K17-'FS Budapest'!K16)) -> 5 | K14: =IF(('FS Budapest'!M17-'FS Budapest'!M16)<0,"0",('FS Budapest'!M17-'FS Budapest'!M16)) -> 10 | L14: =IF(('FS Budapest'!O17-'FS Budapest'!O16)<0,"0",('FS Budapest'!O17-'FS Budapest'!O16)) -> 15 | M14: =IF(('FS Budapest'!Q17-'FS Budapest'!Q16)<0,"0",('FS Budapest'!Q17-'FS Budapest'!Q16)) -> 0 | N14: =IF(('FS Budapest'!S17-'FS Budapest'!S16)<0,"0",('FS Budapest'!S17-'FS Budapest'!S16)) -> 1 | O14: =IF(('FS Budapest'!V17-'FS Budapest'!V16)<0,"0",('FS Budapest'!V17-'FS Budapest'!V16)) -> 6 | P14: =IF(('FS Budapest'!X17-'FS Budapest'!X16)<0,"0",('FS Budapest'!X17-'FS Budapest'!X16)) -> 23 | Q14: ='FS Budapest'!AB17 -> 4 | R14: ='FS Budapest'!AE17 -> 2 | S14: ='FS Budapest'!AF17 -> 7 | T14: =IF(('FS Budapest'!AK17-'FS Budapest'!AK16)<0,"0",('FS Budapest'!AK17-'FS Budapest'!AK16)) -> 1414 | U14: =IF(('FS Budapest'!AM17-'FS Budapest'!AM16)<0,"0",('FS Budapest'!AM17-'FS Budapest'!AM16)) -> 40 | V14: =IF(('FS Budapest'!AO17-'FS Budapest'!AO16)<0,"0",('FS Budapest'!AO17-'FS Budapest'!AO16)) -> 0 | W14: =IF(('FS Budapest'!AQ17-'FS Budapest'!AQ16)<0,"0",('FS Budapest'!AQ17-'FS Budapest'!AQ16)) -> 569 | X14: ='FS Budapest'!AY17 -> 0 | Y14: =IF(('FS Budapest'!BA17-'FS Budapest'!BA16)<0,"0",('FS Budapest'!BA17-'FS Budapest'!BA16)*4400) -> 17028 | Z14: ='FS Budapest'!BI17 -> 17028 | AA14: ='FS Budapest'!BJ17 -> 14899 | AB14: =IF(('FS Budapest'!BK17-'FS Budapest'!BK16)<0,"0",('FS Budapest'!BK17-'FS Budapest'!BK16)*100) -> 624 | AC14: ='FS Budapest'!BM17 -> 17652 | AD14: =IF(('FS Budapest'!BP17-'FS Budapest'!BP16)<0,"0",('FS Budapest'!BP17-'FS Budapest'!BP16)) -> 19 | AE14: =IF(('FS Budapest'!BR17-'FS Budapest'!BR16)<0,"0",('FS Budapest'!BR17-'FS Budapest'!BR16)) -> 2110 | AF14: ='FS Budapest'!BU17 -> 131 | AG14: ='FS Budapest'!BV17 -> 194
... A32: Budapest | B32: =B31+1 -> 31 | C32: 5 | D32: 2019 | E32: =IF(('FS Budapest'!C35-'FS Budapest'!C34)<0,"0",('FS Budapest'!C35-'FS Budapest'!C34)) -> 99 | F32: =IF(('FS Budapest'!D35-'FS Budapest'!D34)<0,"0",('FS Budapest'!D35-'FS Budapest'!D34)) -> 116 | G32: =IF(('FS Budapest'!E35-'FS Budapest'!Y35)<0,"0",('FS Budapest'!E35-'FS Budapest'!Y35)) -> 85 | H32: =IF(('FS Budapest'!H35-'FS Budapest'!H34)<0,"0",('FS Budapest'!H35-'FS Budapest'!H34)) -> 91 | I32: =IF(('FS Budapest'!I35-'FS Budapest'!I34)<0,"0",('FS Budapest'!I35-'FS Budapest'!I34)) -> 29 | J32: =IF(('FS Budapest'!K35-'FS Budapest'!K34)<0,"0",('FS Budapest'!K35-'FS Budapest'!K34)) -> 6 | K32: =IF(('FS Budapest'!M35-'FS Budapest'!M34)<0,"0",('FS Budapest'!M35-'FS Budapest'!M34)) -> 8 | L32: =IF(('FS Budapest'!O35-'FS Budapest'!O34)<0,"0",('FS Budapest'!O35-'FS Budapest'!O34)) -> 23 | M32: =IF(('FS Budapest'!Q35-'FS Budapest'!Q34)<0,"0",('FS Budapest'!Q35-'FS Budapest'!Q34)) -> 2 | N32: =IF(('FS Budapest'!S35-'FS Budapest'!S34)<0,"0",('FS Budapest'!S35-'FS Budapest'!S34)) -> 1 | O32: =IF(('FS Budapest'!V35-'FS Budapest'!V34)<0,"0",('FS Budapest'!V35-'FS Budapest'!V34)) -> 6 | P32: =IF(('FS Budapest'!X35-'FS Budapest'!X34)<0,"0",('FS Budapest'!X35-'FS Budapest'!X34)) -> 31 | Q32: ='FS Budapest'!AB35 -> 4 | R32: ='FS Budapest'!AE35 -> 4 | S32: ='FS Budapest'!AF35 -> 9 | T32: =IF(('FS Budapest'!AK35-'FS Budapest'!AK34)<0,"0",('FS Budapest'!AK35-'FS Budapest'!AK34)) -> 1318 | U32: =IF(('FS Budapest'!AM35-'FS Budapest'!AM34)<0,"0",('FS Budapest'!AM35-'FS Budapest'!AM34)) -> 37 | V32: =IF(('FS Budapest'!AO35-'FS Budapest'!AO34)<0,"0",('FS Budapest'!AO35-'FS Budapest'!AO34)) -> 0 | W32: =IF(('FS Budapest'!AQ35-'FS Budapest'!AQ34)<0,"0",('FS Budapest'!AQ35-'FS Budapest'!AQ34)) -> 512 | X32: ='FS Budapest'!AY35 -> 0 | Y32: =IF(('FS Budapest'!BA35-'FS Budapest'!BA34)<0,"0",('FS Budapest'!BA35-'FS Budapest'!BA34)*4400) -> 18744 | Z32: ='FS Budapest'!BI35 -> 18744 | AA32: ='FS Budapest'!BJ35 -> 15732 | AB32: =IF(('FS Budapest'!BK35-'FS Budapest'!BK34)<0,"0",('FS Budapest'!BK35-'FS Budapest'!BK34)*100) -> 613 | AC32: ='FS Budapest'!BM35 -> 19357 | AD32: =IF(('FS Budapest'!BP35-'FS Budapest'!BP34)<0,"0",('FS Budapest'!BP35-'FS Budapest'!BP34)) -> 441 | AE32: =IF(('FS Budapest'!BR35-'FS Budapest'!BR34)<0,"0",('FS Budapest'!BR35-'FS Budapest'!BR34)) -> 2571 | AF32: ='FS Budapest'!BU35 -> 175 | AG32: ='FS Budapest'!BV35 -> 317

Sheet FS Budapest
B1: WATER (Víz)& SEWAGE | AK1: GAS (Gáz) | AW1: Villany / Electricity | BU1: Room Nights | BV1: Room Nights
C2: 1. supply water | E2: hotel | H2: 2.supply | I2: laundry | K2: kitchen | M2: DHW kitchen | O2: DHW hotel | Q2: steam pit | S2: boiler cooling | U2: left steam supply | V2: right steam supply | X2: tower | Z2: pool | AA2: jacuzzi | AC2: 1.garage supply | AD2: 2.garage supply | AK2: 1.gas supply | AM2: 2.gas supply | AO2: steam boiler 1 | AQ2: steam boiler 2 | AW2: Elec supply1. | AZ2: Elec supply2. | BK2: garage | BP2: chiller1 | BR2: chiller2
C3: B074 Nagy | D3: B074 Szálloda | E3: B074 szálloda napi+torony | F3: B074 szálloda napi-torony | H3: B057 Nagy | I3: B074 mosoda víz | J3: B074 mosoda víz napi | K3: B054 konyha | L3: B054 konyha napi | M3: HMV konyha | N3: ösz | O3: HMV szálloda | P3: ösz | Q3: B 105 Gőzakna | R3: /Pit/ Gőzakna össz | S3: Kazán hűtővíz | T3: Kazán hűtővíz össz | U3: kazán tápvíz ball | V3: kazán tápvíz jobb | W3: kazán tápvíz össz | X3: CT-PÓTVÍZ | Y3: CT-PÓTVÍZ össz | Z3: Úszó medence | AA3: Jakuczi medence | AB3: SPA össz | AC3: Garázs kicsi | AD3: Garázs nagy | AE3: garázs össz | AF3: Gőz össz. | AG3: össz: | AH3: [össz] | AI3: Tervezett | AJ3: Megvalósult | AK3: 1 mérő | AL3: 1-es mérő napi fogy. | AM3: 2 mérő | AN3: 2-es mérő napi fogy. | AO3: Gőzkazán 1 | AQ3: Gőzkazán 2 | AS3: össz: | AT3: [össz] | AU3: Tervezett | AV3: Megvalósult | AW3: 8.2 | AX3: 18 | AY3: 1-es mérő napifogy. | AZ3: 8.2 | BA3: 18 | BB3: 2-es mérő napifogy. | BC3: 8.2 össz | BD3: ÉJSZAKAI INPULZUS [8.2 össz] | BE3: ÉJSZAKAI FOGYASZTÁS KWh | BF3: 8.3 össz | BG3: NAPPALI INPULZUS [8.3 össz] | BH3: NAPPALI FOGYASZTÁS KWh | BI3: hotel absolut napi fogyasztás KWh | BJ3: hotel absolut napi fogyasztás-hütők KWh | BK3: 18 GARAGE | BL3: GARAGE NAPI FOGYASZTÁS KWh | BM3: GARAGE + PALACE SUMMA DAYLI KWh | BN3: Tervezett | BO3: Megvalósult | BP3: HŰTŐ 1 | BQ3: HŰTŐ 1 NAPI | BR3: HŰTŐ 2 | BS3: HŰTŐ 2 NAPI | BT3: HŰTŐ 1+2 NAPI | BU3: Room Nights | BV3: # Guests
A4: 0 | C4: 44909 | D4: 201111 | H4: 99265 | I4: 69512 | K4: 12675 | M4: 9378 | O4: 17741 | Q4: 55452 | S4: 24895 | U4: 8750 | V4: 281 | X4: 23950 | Z4: 7330 | AA4: 6650 | AC4: 1803 | AD4: 1241 | AG4: 144174 | AI4: 170 | AJ4: -18 | AK4: 1099926 | AM4: 46015 | AO4: 50698 | AQ4: 21909 | AS4: 1147545 | AU4: 1700 | AV4: 64 | AX4: 27.49 | BA4: 11482.63 | BC4: 0 | BD4: 0 | BE4: 0 | BF4: 11510.12 | BG4: 4.2 | BK4: 22121.86 | BP4: 2529698 | BR4: 3476834 | BT4: 2320
A5: 1 | C5: 44977 | D5: 201194 | E5: =D5-D4 -> 83 | F5: =E5-Y5 -> 55 | H5: 99323 | I5: 69533 | J5: =I5-I4 -> 21 | K5: 12681 | L5: =K5-[2]Április2019!K34 -> 12681 | M5: 9386 | N5: =M5-[2]Április2019!M34 -> 9386 | O5: 17754 | P5: 14 | Q5: 55455 | R5: =Q5-Q4 -> 3 | S5: 24896 | T5: =S5-S4 -> 1 | U5: 8750 | V5: 287 | W5: =(U5+V5)-(U4+V4) -> 6 | X5: 23978 | Y5: =X5-X4 -> 28 | Z5: 7333 | AA5: 6651 | AB5: =(Z5+AA5)-(Z4+AA4) -> 4 | AC5: 1803 | AD5: 1241 | AE5: =AC5+AD5-AC4-AD4 -> 0 | AF5: =R5+T5+W5 -> 10 | AG5: =B5+C5+G5+H5 -> 144300 | AH5: 126 | AI5: 165 | AJ5: =AI5-AH5 -> 39 | AK5: 1101609 | AL5: =AK5-AK4 -> 1683 | AM5: 46055 | AN5: =AM5-AM4 -> 40 | AO5: 50698 | AP5: =AO5-AO4 -> 0 | AQ5: 22394 | AR5: =AQ5-AQ4 -> 485 | AS5: =SUM(AK5:AL5) -> 1103292 | AT5: 1723 | AU5: 1400 | AV5: =AU5-AT5 -> -323 | AX5: 27.49 | AY5: 0 | AZ5: 0 | BA5: 11486.76 | BB5: =(BA5-BA4)*4400 -> 18172 | BC5: =(AW5+AZ5) -> 0 | BD5: =BC5-AW5 -> 0 | BE5: =BD5*4400 -> 0 | BF5: =AX5+BA5 -> 11514.25 | BG5: =BF5-[1]Április2019!BF33 -> 4.13 | BH5: =BG5*4400 -> 18172 | BI5: 18172 | BJ5: 15379 | BK5: 22126.47 | BL5: =(BK5-BK4)*100 -> 461 | BM5: 18633 | BN5: 18000 | BO5: =BN5-BM5 -> -633 | BP5: 2529717 | BQ5: 19 | BR5: 3479608 | BS5: 2774 | BT5: =BQ5+BS5 -> 2793 | BU5: 99 | BV5: 171
A6: 2 | C6: 45061 | D6: 201299 | E6: =D6-D5 -> 105 | F6: =E6-Y6 -> 72 | H6: 99431 | I6: 69558 | J6: =I6-I5 -> 25 | K6: 12689 | L6: =K6-K5 -> 8 | M6: 9396 | N6: =M6-M5 -> 10 | O6: 17773 | P6: =O6-O5 -> 19 | Q6: 55457 | R6: =Q6-Q5 -> 2 | S6: 24897 | T6: =S6-S5 -> 1 | U6: 8750 | V6: 294 | W6: =(U6+V6)-(U5+V5) -> 7 | X6: 24011 | Y6: =X6-X5 -> 33 | Z6: 7335 | AA6: 6652 | AB6: =(Z6+AA6)-(Z5+AA5) -> 3 | AC6: 1804 | AD6: 1243 | AE6: =AC6+AD6-AC5-AD5 -> 3 | AF6: =R6+T6+W6 -> 10 | AG6: =B6+C6+G6+H6 -> 144492 | AH6: 192 | AI6: 165 | AJ6: =AI6-AH6 -> -27 | AK6: 1103100 | AL6: =AK6-AK5 -> 1491 | AM6: 46088 | AN6: =AM6-AM5 -> 33 | AO6: 50698 | AP6: =AO6-AO5 -> 0 | AQ6: 22895 | AR6: =AQ6-AQ5 -> 501 | AS6: =SUM(AK6:AM6) -> 1150679 | AT6: 1531 | AU6: 1400 | AV6: =AU6-AT6 -> -131 | AX6: 27.49 | AY6: 0 | AZ6: 0 | BA6: 11491.17 | BB6: =(BA6-BA5)*4400 -> 19404 | BC6: =(AW6+AZ6) -> 0 | BD6: =BC6-AW6 -> 0 | BE6: =BD6*4400 -> 0 | BF6: =AX6+BA6 -> 11518.66 | BG6: =BF6-BF5 -> 4.41 | BH6: =BG6*4400 -> 19404 | BI6: 19404 | BJ6: 16712 | BK6: 22132.31 | BL6: =(BK6-BK5)*100 -> 584 | BM6: 19988 | BN6: 18000 | BO6: =BN6-BM6 -> -1988 | BP6: 2529736 | BQ6: 19 | BR6: 3482281 | BS6: 2673 | BT6: =BQ6+BS6 -> 2692 | BU6: 179 | BV6: 322
A7: 3 | C7: 45145 | D7: 201402 | E7: =D7-D6 -> 103 | F7: =E7-Y7 -> 78 | H7: 99526 | I7: 69582 | J7: =I7-I6 -> 24 | K7: 12696 | L7: =K7-K6 -> 7 | M7: 9404 | N7: =M7-M6 -> 8 | O7: 17798 | P7: =O7-O6 -> 25 | Q7: 55460 | R7: =Q7-Q6 -> 3 | S7: 24899 | T7: =S7-S6 -> 2 | U7: 8750 | V7: 301 | W7: =(U7+V7)-(U6+V6) -> 7 | X7: 24036 | Y7: =X7-X6 -> 25 | Z7: 7338 | AA7: 6653 | AB7: =(Z7+AA7)-(Z6+AA6) -> 4 | AC7: 1805 | AD7: 1243 | AE7: =AC7+AD7-AC6-AD6 -> 1 | AF7: =R7+T7+W7 -> 12 | AG7: =B7+C7+G7+H7 -> 144671 | AH7: 179 | AI7: 165 | AJ7: =AI7-AH7 -> -14 | AK7: 1104459 | AL7: =AK7-AK6 -> 1359 | AM7: 46127 | AN7: =AM7-AM6 -> 39 | AO7: 50698 | AP7: =AO7-AO6 -> 0 | AQ7: 23409 | AR7: =AQ7-AQ6 -> 514 | AS7: =SUM(AK7:AM7) -> 1151945 | AT7: 1392 | AU7: 1400 | AV7: =AU7-AT7 -> 8 | AX7: 27.49 | AY7: 0 | AZ7: 0 | BA7: 11495.32 | BB7: =(BA7-BA6)*4400 -> 18260 | BC7: =(AW7+AZ7) -> 0 | BD7: =BC7-AW7 -> 0 | BE7: =BD7*4400 -> 0 | BF7: =AX7+BA7 -> 11522.81 | BG7: =BF7-BF6 -> 4.15 | BH7: =BG7*4400 -> 18260 | BI7: 18260 | BJ7: 15834 | BK7: 22138.2 | BL7: =(BK7-BK6)*100 -> 589 | BM7: 18849 | BN7: 18000 | BO7: =BN7-BM7 -> -849 | BP7: 2529754 | BQ7: 18 | BR7: 3484689 | BS7: 2408 | BT7: =BQ7+BS7 -> 2426 | BU7: 171 | BV7: 316
A8: 4 | C8: 45238 | D8: 201507 | E8: =D8-D7 -> 105 | F8: =E8-Y8 -> 88 | H8: 99614 | I8: 69606 | J8: =I8-I7 -> 24 | K8: 12703 | L8: =K8-K7 -> 7 | M8: 9415 | N8: =M8-M7 -> 11 | O8: 17831 | P8: =O8-O7 -> 33 | Q8: 55462 | R8: =Q8-Q7 -> 2 | S8: 24901 | T8: =S8-S7 -> 2 | U8: 8750 | V8: 307 | W8: =(U8+V8)-(U7+V7) -> 6 | X8: 24053 | Y8: =X8-X7 -> 17 | Z8: 7340 | AA8: 6654 | AB8: =(Z8+AA8)-(Z7+AA7) -> 3 | AC8: 1806 | AD8: 1244 | AE8: =AC8+AD8-AC7-AD7 -> 2 | AF8: =R8+T8+W8 -> 10 | AG8: =B8+C8+G8+H8 -> 144852 | AH8: 181 | AI8: 165 | AJ8: =AI8-AH8 -> -16 | AK8: 1106029 | AL8: =AK8-AK7 -> 1570 | AM8: 46169 | AN8: =AM8-AM7 -> 42 | AO8: 50698 | AP8: =AO8-AO7 -> 0 | AQ8: 23930 | AR8: =AQ8-AQ7 -> 521 | AS8: =SUM(AK8:AM8) -> 1153768 | AT8: 1609 | AU8: 1400 | AV8: =AU8-AT8 -> -209 | AX8: 27.49 | AY8: 0 | AZ8: 0 | BA8: 11499.42 | BB8: =(BA8-BA7)*4400 -> 18040 | BC8: =(AW8+AZ8) -> 0 | BD8: =BC8-AW8 -> 0 | BE8: =BD8*4400 -> 0 | BF8: =AX8+BA8 -> 11526.91 | BG8: =BF8-BF7 -> 4.1 | BH8: =BG8*4400 -> 18040 | BI8: 18040 | BJ8: 15805 | BK8: 22143.31 | BL8: =(BK8-BK7)*100 -> 511 | BM8: 18551 | BN8: 18000 | BO8: =BN8-BM8 -> -551 | BP8: 2529774 | BQ8: 20 | BR8: 3486904 | BS8: 2215 | BT8: =BQ8+BS8 -> 2235 | BU8: 170 | BV8: 315
A9: 5 | C9: 45323 | D9: 201610 | E9: =D9-D8 -> 103 | F9: =E9-Y9 -> 86 | H9: 99705 | I9: 69632 | J9: =I9-I8 -> 26 | K9: 12709 | L9: =K9-K8 -> 6 | M9: 9423 | N9: =M9-M8 -> 8 | O9: 17864 | P9: =O9-O8 -> 33 | Q9: 55464 | R9: =Q9-Q8 -> 2 | S9: 24902 | T9: =S9-S8 -> 1 | U9: 8750 | V9: 314 | W9: =(U9+V9)-(U8+V8) -> 7 | X9: 24070 | Y9: =X9-X8 -> 17 | Z9: 7342 | AA9: 6655 | AB9: =(Z9+AA9)-(Z8+AA8) -> 3 | AC9: 1807 | AD9: 1245 | AE9: =AC9+AD9-AC8-AD8 -> 2 | AF9: =R9+T9+W9 -> 10 | AG9: =B9+C9+G9+H9 -> 145028 | AH9: 176 | AI9: 165 | AJ9: =AI9-AH9 -> -11 | AK9: 1107926 | AL9: =AK9-AK8 -> 1897 | AM9: 46220 | AN9: =AM9-AM8 -> 51 | AO9: 50698 | AP9: =AO9-AO8 -> 0 | AQ9: 24449 | AR9: =AQ9-AQ8 -> 519 | AS9: =SUM(AK9:AM9) -> 1156043 | AT9: 1939 | AU9: 1400 | AV9: =AU9-AT9 -> -539 | AX9: 27.49 | AY9: 0 | AZ9: 0 | BA9: 11503.55 | BB9: =(BA9-BA8)*4400 -> 18172 | BC9: =(AW9+AZ9) -> 0 | BD9: =BC9-AW9 -> 0 | BE9: =BD9*4400 -> 0 | BF9: =AX9+BA9 -> 11531.04 | BG9: =BF9-BF8 -> 4.13 | BH9: =BG9*4400 -> 18172 | BI9: 18172 | BJ9: 15932 | BK9: 22148.39 | BL9: =(BK9-BK8)*100 -> 508 | BM9: 18680 | BN9: 18000 | BO9: =BN9-BM9 -> -680 | BP9: 2529793 | BQ9: 19 | BR9: 3489125 | BS9: 2221 | BT9: =BQ9+BS9 -> 2240 | BU9: 167 | BV9: 841
A10: 6 | C10: 45411 | D10: 201715 | E10: =D10-D9 -> 105 | F10: =E10-Y10 -> 88 | H10: 99805 | I10: 69659 | J10: =I10-I9 -> 27 | K10: 12717 | L10: =K10-K9 -> 8 | M10: 9433 | N10: =M10-M9 -> 10 | O10: 17895 | P10: =O10-O9 -> 31 | Q10: 55466 | R10: =Q10-Q9 -> 2 | S10: 24903 | T10: =S10-S9 -> 1 | U10: 8750 | V10: 321 | W10: =(U10+V10)-(U9+V9) -> 7 | X10: 24087 | Y10: =X10-X9 -> 17 | Z10: 7345 | AA10: 6656 | AB10: =(Z10+AA10)-(Z9+AA9) -> 4 | AC10: 1807 | AD10: 1246 | AE10: =AC10+AD10-AC9-AD9 -> 1 | AF10: =R10+T10+W10 -> 10 | AG10: =B10+C10+G10+H10 -> 145216 | AH10: 188 | AI10: 165 | AJ10: =AI10-AH10 -> -23 | AK10: 1110453 | AL10: =AK10-AK9 -> 2527 | AM10: 46259 | AN10: =AM10-AM9 -> 39 | AO10: 50698 | AP10: =AO10-AO9 -> 0 | AQ10: 24969 | AR10: =AQ10-AQ9 -> 520 | AS10: =SUM(AK10:AM10) -> 1159239 | AT10: 2578 | AU10: 1400 | AV10: =AU10-AT10 -> -1178 | AX10: 27.49 | AY10: 0 | AZ10: 0 | BA10: 11507.9 | BB10: =(BA10-BA9)*4400 -> 19140 | BC10: =(AW10+AZ10) -> 0 | BD10: =BC10-AW10 -> 0 | BE10: =BD10*4400 -> 0 | BF10: =AX10+BA10 -> 11535.39 | BG10: =BF10-BF9 -> 4.35 | BH10: =BG10*4400 -> 19140 | BI10: 19140 | BJ10: 16866 | BK10: 22153.41 | BL10: =(BK10-BK9)*100 -> 502 | BM10: 19642 | BN10: 18000 | BO10: =BN10-BM10 -> -1642 | BP10: 2529812 | BQ10: 19 | BR10: 3491380 | BS10: 2255 | BT10: =BQ10+BS10 -> 2274 | BU10: 174 | BV10: 302
A11: 7 | C11: 45480 | D11: 201792 | E11: =D11-D10 -> 77 | F11: =E11-Y11 -> 58 | H11: 99892 | I11: 69686 | J11: =I11-I10 -> 27 | K11: 12723 | L11: =K11-K10 -> 6 | M11: 9442 | N11: =M11-M10 -> 9 | O11: 17911 | P11: =O11-O10 -> 16 | Q11: 55467 | R11: =Q11-Q10 -> 1 | S11: 24904 | T11: =S11-S10 -> 1 | U11: 8750 | V11: 328 | W11: =(U11+V11)-(U10+V10) -> 7 | X11: 24106 | Y11: =X11-X10 -> 19 | Z11: 7347 | AA11: 6657 | AB11: =(Z11+AA11)-(Z10+AA10) -> 3 | AC11: 1807 | AD11: 1246 | AE11: =AC11+AD11-AC10-AD10 -> 0 | AF11: =R11+T11+W11 -> 9 | AG11: =B11+C11+G11+H11 -> 145372 | AH11: 156 | AI11: 165 | AJ11: =AI11-AH11 -> 9 | AK11: 1112184 | AL11: =AK11-AK10 -> 1731 | AM11: 46294 | AN11: =AM11-AM10 -> 35 | AO11: 50698 | AP11: =AO11-AO10 -> 0 | AQ11: 25596 | AR11: =AQ11-AQ10 -> 627 | AS11: =SUM(AK11:AM11) -> 1160209 | AT11: 1770 | AU11: 1400 | AV11: =AU11-AT11 -> -370 | AX11: 27.49 | AY11: 0 | AZ11: 0 | BA11: 11511.87 | BB11: =(BA11-BA10)*4400 -> 17468 | BC11: =(AW11+AZ11) -> 0 | BD11: =BC11-AW11 -> 0 | BE11: =BD11*4400 -> 0 | BF11: =AX11+BA11 -> 11539.36 | BG11: =BF11-BF10 -> 3.97 | BH11: =BG11*4400 -> 17468 | BI11: 17468 | BJ11: 15997 | BK11: 22161.42 | BL11: =(BK11-BK10)*100 -> 801 | BM11: 18269 | BN11: 18000 | BO11: =BN11-BM11 -> -269 | BP11: 2529831 | BQ11: 19 | BR11: 3492832 | BS11: 1452 | BT11: =BQ11+BS11 -> 1471 | BU11: 113 | BV11: 163
A12: 8 | C12: 45548 | D12: 201873 | E12: =D12-D11 -> 81 | F12: =E12-Y12 -> 61 | H12: 99985 | I12: 69713 | J12: =I12-I11 -> 27 | K12: 12729 | L12: =K12-K11 -> 6 | M12: 9450 | N12: =M12-M11 -> 8 | O12: 17927 | P12: =O12-O11 -> 16 | Q12: 55468 | R12: =Q12-Q11 -> 1 | S12: 24906 | T12: =S12-S11 -> 2 | U12: 8750 | V12: 334 | W12: =(U12+V12)-(U11+V11) -> 6 | X12: 24126 | Y12: =X12-X11 -> 20 | Z12: 7350 | AA12: 6658 | AB12: =(Z12+AA12)-(Z11+AA11) -> 4 | AC12: 1809 | AD12: 1247 | AE12: =AC12+AD12-AC11-AD11 -> 3 | AF12: =R12+T12+W12 -> 9 | AG12: =B12+C12+G12+H12 -> 145533 | AH12: 161 | AI12: 166 | AJ12: =AI12-AH12 -> 5 | AK12: 1113550 | AL12: =AK12-AK11 -> 1366 | AM12: 46340 | AN12: =AM12-AM11 -> 46 | AO12: 50698 | AP12: =AO12-AO11 -> 0 | AQ12: 25969 | AR12: =AQ12-AQ11 -> 373 | AS12: =SUM(AK12:AM12) -> 1161256 | AT12: 1401 | AU12: 1401 | AV12: =AU12-AT12 -> 0 | AX12: 27.49 | BA12: 11515.76 | BB12: =(BA12-BA11)*4400 -> 17116 | BC12: =(AW12+AZ12) -> 0 | BD12: =BC12-AW12 -> 0 | BE12: =BD12*4400 -> 0 | BF12: =AX12+BA12 -> 11543.25 | BG12: =BF12-BF11 -> 3.89 | BH12: =BG12*4400 -> 17116 | BI12: 17116 | BJ12: 15299 | BK12: 22167.54 | BL12: =(BK12-BK11)*100 -> 612 | BM12: 17728 | BN12: 18001 | BO12: =BN12-BM12 -> 273 | BP12: 2529850 | BQ12: 19 | BR12: 3494630 | BS12: 1798 | BT12: =BQ12+BS12 -> 1817 | BU12: 174 | BV12: 249
A13: 9 | C13: 45616 | D13: 201955 | E13: =D13-D12 -> 82 | F13: =E13-Y13 -> 68 | H13: 100076 | I13: 69737 | J13: =I13-I12 -> 24 | K13: 12735 | L13: =K13-K12 -> 6 | M13: 9460 | N13: =M13-M12 -> 10 | O13: 17945 | P13: =O13-O12 -> 18 | Q13: 55470 | R13: =Q13-Q12 -> 2 | S13: 24907 | T13: =S13-S12 -> 1 | U13: 8750 | V13: 341 | W13: =(U13+V13)-(U12+V12) -> 7 | X13: 24140 | Y13: =X13-X12 -> 14 | Z13: 7352 | AA13: 6659 | AB13: =(Z13+AA13)-(Z12+AA12) -> 3 | AC13: 1809 | AD13: 1248 | AE13: =AC13+AD13-AC12-AD12 -> 1 | AF13: =R13+T13+W13 -> 10 | AG13: =B13+C13+G13+H13 -> 145692 | AH13: 159 | AI13: 167 | AJ13: =AI13-AH13 -> 8 | AK13: 1114995 | AL13: =AK13-AK12 -> 1445 | AM13: 46376 | AN13: =AM13-AM12 -> 36 | AO13: 50698 | AP13: =AO13-AO12 -> 0 | AQ13: 26501 | AR13: =AQ13-AQ12 -> 532 | AS13: =SUM(AK13:AM13) -> 1162816 | AT13: 1491 | AU13: 1402 | AV13: =AU13-AT13 -> -89 | AX13: 27.49 | BA13: 11519.88 | BB13: =(BA13-BA12)*4400 -> 18128 | BC13: =(AW13+AZ13) -> 0 | BD13: =BC13-AW13 -> 0 | BE13: =BD13*4400 -> 0 | BF13: =AX13+BA13 -> 11547.37 | BG13: =BF13-BF12 -> 4.12 | BH13: =BG13*4400 -> 18128 | BI13: 18128 | BJ13: 16621 | BK13: 22173.41 | BL13: =(BK13-BK12)*100 -> 587 | BM13: 18715 | BN13: 18002 | BO13: =BN13-BM13 -> -713 | BP13: 2529869 | BQ13: 19 | BR13: 3496118 | BS13: 1488 | BT13: =BQ13+BS13 -> 1507 | BU13: 162 | BV13: 241
A14: 10 | C14: 45687 | D14: 202039 | E14: =D14-D13 -> 84 | F14: =E14-Y14 -> 63 | H14: 100171 | I14: 69763 | J14: =I14-I13 -> 26 | K14: 12741 | L14: =K14-K13 -> 6 | M14: 9468 | N14: =M14-M13 -> 8 | O14: 17966 | P14: =O14-O13 -> 21 | Q14: 55472 | R14: =Q14-Q13 -> 2 | S14: 24908 | T14: =S14-S13 -> 1 | U14: 8750 | V14: 348 | W14: =(U14+V14)-(U13+V13) -> 7 | X14: 24161 | Y14: =X14-X13 -> 21 | Z14: 7355 | AA14: 6660 | AB14: =(Z14+AA14)-(Z13+AA13) -> 4 | AC14: 1811 | AD14: 1249 | AE14: =AC14+AD14-AC13-AD13 -> 3 | AF14: =R14+T14+W14 -> 10 | AG14: =B14+C14+G14+H14 -> 145858 | AH14: 166 | AI14: 168 | AJ14: =AI14-AH14 -> 2 | AK14: 1116334 | AL14: =AK14-AK13 -> 1339 | AM14: 46414 | AN14: =AM14-AM13 -> 38 | AO14: 50698 | AP14: =AO14-AO13 -> 0 | AQ14: 27035 | AR14: =AQ14-AQ13 -> 534 | AS14: =SUM(AK14:AM14) -> 1164087 | AT14: 1375 | AU14: 1403 | AV14: =AU14-AT14 -> 28 | AX14: 27.49 | BA14: 11523.95 | BB14: =(BA14-BA13)*4400 -> 17908 | BC14: =(AW14+AZ14) -> 0 | BD14: =BC14-AW14 -> 0 | BE14: =BD14*4400 -> 0 | BF14: =AX14+BA14 -> 11551.44 | BG14: =BF14-BF13 -> 4.07 | BH14: =BG14*4400 -> 17908 | BI14: 17908 | BJ14: 15709 | BK14: 22179.4 | BL14: =(BK14-BK13)*100 -> 599 | BM14: 18507 | BN14: 18003 | BO14: =BN14-BM14 -> -504 | BP14: 2529888 | BQ14: 19 | BR14: 3498298 | BS14: 2180 | BT14: =BQ14+BS14 -> 2199 | BU14: 101 | BV14: 171
A15: 11 | C15: 45753 | D15: 202115 | E15: =D15-D14 -> 76 | F15: =E15-Y15 -> 48 | H15: 100255 | I15: 69785 | J15: =I15-I14 -> 22 | K15: 12747 | L15: =K15-K14 -> 6 | M15: 9477 | N15: =M15-M14 -> 9 | O15: 17978 | P15: =O15-O14 -> 12 | Q15: 55474 | R15: =Q15-Q14 -> 2 | S15: 24910 | T15: =S15-S14 -> 2 | U15: 8750 | V15: 354 | W15: =(U15+V15)-(U14+V14) -> 6 | X15: 24189 | Y15: =X15-X14 -> 28 | Z15: 7357 | AA15: 6661 | AB15: =(Z15+AA15)-(Z14+AA14) -> 3 | AC15: 1812 | AD15: 1250 | AE15: =AC15+AD15-AC14-AD14 -> 2 | AF15: =R15+T15+W15 -> 10 | AG15: =B15+C15+G15+H15 -> 146008 | AH15: 150 | AI15: 169 | AJ15: =AI15-AH15 -> 19 | AK15: 1117639 | AL15: =AK15-AK14 -> 1305 | AM15: 46453 | AN15: =AM15-AM14 -> 39 | AO15: 50698 | AP15: =AO15-AO14 -> 0 | AQ15: 27570 | AR15: =AQ15-AQ14 -> 535 | AS15: =SUM(AK15:AM15) -> 1165397 | AT15: 1343 | AU15: 1404 | AV15: =AU15-AT15 -> 61 | AX15: 27.49 | BA15: 11527.94 | BB15: =(BA15-BA14)*4400 -> 17556 | BC15: =(AW15+AZ15) -> 0 | BD15: =BC15-AW15 -> 0 | BE15: =BD15*4400 -> 0 | BF15: =AX15+BA15 -> 11555.43 | BG15: =BF15-BF14 -> 3.99 | BH15: =BG15*4400 -> 17556 | BI15: 17556 | BJ15: 14987 | BK15: 22184.34 | BL15: =(BK15-BK14)*100 -> 494 | BM15: 18050 | BN15: 18004 | BO15: =BN15-BM15 -> -46 | BP15: 2529907 | BQ15: 19 | BR15: 3500848 | BS15: 2550 | BT15: =BQ15+BS15 -> 2569 | BU15: 92 | BV15: 163
A16: 12 | C16: 45815 | D16: 202194 | E16: =D16-D15 -> 79 | F16: =E16-Y16 -> 53 | H16: 100348 | I16: 69810 | J16: =I16-I15 -> 25 | K16: 12752 | L16: =K16-K15 -> 5 | M16: 9485 | N16: =M16-M15 -> 8 | O16: 17991 | P16: =O16-O15 -> 13 | Q16: 55477 | R16: =Q16-Q15 -> 3 | S16: 24912 | T16: =S16-S15 -> 2 | U16: 8750 | V16: 362 | W16: =(U16+V16)-(U15+V15) -> 8 | X16: 24215 | Y16: =X16-X15 -> 26 | Z16: 7359 | AA16: 6662 | AB16: =(Z16+AA16)-(Z15+AA15) -> 3 | AC16: 1813 | AD16: 1251 | AE16: =AC16+AD16-AC15-AD15 -> 2 | AF16: =R16+T16+W16 -> 13 | AG16: =B16+C16+G16+H16 -> 146163 | AH16: 155 | AI16: 170 | AJ16: =AI16-AH16 -> 15 | AK16: 1118876 | AL16: =AK16-AK15 -> 1237 | AM16: 46501 | AN16: =AM16-AM15 -> 48 | AO16: 50698 | AP16: =AO16-AO15 -> 0 | AQ16: 28120 | AR16: =AQ16-AQ15 -> 550 | AS16: =SUM(AK16:AM16) -> 1166614 | AT16: 1276 | AU16: 1405 | AV16: =AU16-AT16 -> 129 | AX16: 27.49 | BA16: 11531.93 | BB16: =(BA16-BA15)*4400 -> 17556 | BC16: =(AW16+AZ16) -> 0 | BD16: =BC16-AW16 -> 0 | BE16: =BD16*4400 -> 0 | BF16: =AX16+BA16 -> 11559.42 | BG16: =BF16-BF15 -> 3.99 | BH16: =BG16*4400 -> 17556 | BI16: 17556 | BJ16: 14945 | BK16: 22189.76 | BL16: =(BK16-BK15)*100 -> 542 | BM16: 18098 | BN16: 18005 | BO16: =BN16-BM16 -> -93 | BP16: 2529926 | BQ16: 19 | BR16: 3503440 | BS16: 2592 | BT16: =BQ16+BS16 -> 2611 | BU16: 101 | BV16: 168
A17: 13 | C17: 45864 | D17: 202275 | E17: =D17-D16 -> 81 | F17: =E17-Y17 -> 58 | H17: 100456 | I17: 69836 | J17: =I17-I16 -> 26 | K17: 12757 | L17: =K17-K16 -> 5 | M17: 9495 | N17: =M17-M16 -> 10 | O17: 18006 | P17: =O17-O16 -> 15 | Q17: 55477 | R17: =Q17-Q16 -> 0 | S17: 24913 | T17: =S17-S16 -> 1 | U17: 8750 | V17: 368 | W17: =(U17+V17)-(U16+V16) -> 6 | X17: 24238 | Y17: =X17-X16 -> 23 | Z17: 7362 | AA17: 6663 | AB17: =(Z17+AA17)-(Z16+AA16) -> 4 | AC17: 1814 | AD17: 1252 | AE17: =AC17+AD17-AC16-AD16 -> 2 | AF17: =R17+T17+W17 -> 7 | AG17: =B17+C17+G17+H17 -> 146320 | AH17: 157 | AI17: 171 | AJ17: =AI17-AH17 -> 14 | AK17: 1120290 | AL17: =AK17-AK16 -> 1414 | AM17: 46541 | AN17: =AM17-AM16 -> 40 | AO17: 50698 | AP17: =AO17-AO16 -> 0 | AQ17: 28689 | AR17: =AQ17-AQ16 -> 569 | AS17: =SUM(AK17:AM17) -> 1168245 | AT17: 1462 | AU17: 1406 | AV17: =AU17-AT17 -> -56 | AX17: 27.49 | BA17: 11535.8 | BB17: =(BA17-BA16)*4400 -> 17028 | BC17: =(AW17+AZ17) -> 0 | BD17: =BC17-AW17 -> 0 | BE17: =BD17*4400 -> 0 | BF17: =AX17+BA17 -> 11563.29 | BG17: =BF17-BF16 -> 3.87 | BH17: =BG17*4400 -> 17028 | BI17: 17028 | BJ17: 14899 | BK17: 22196 | BL17: =(BK17-BK16)*100 -> 624 | BM17: 17652 | BN17: 18006 | BO17: =BN17-BM17 -> 354 | BP17: 2529945 | BQ17: 19 | BR17: 3505550 | BS17: 2110 | BT17: =BQ17+BS17 -> 2129 | BU17: 131 | BV17: 194
A18: 14 | C18: 45920 | D18: 202344 | E18: =D18-D17 -> 69 | F18: =E18-Y18 -> 55 | H18: 100548 | I18: 69862 | J18: =I18-I17 -> 26 | K18: 12763 | L18: =K18-K17 -> 6 | M18: 9502 | N18: =M18-M17 -> 7 | O18: 18024 | P18: =O18-O17 -> 18 | Q18: 55479 | R18: =Q18-Q17 -> 2 | S18: 24914 | T18: =S18-S17 -> 1 | U18: 8750 | V18: 375 | W18: =(U18+V18)-(U17+V17) -> 7 | X18: 24252 | Y18: =X18-X17 -> 14 | Z18: 7364 | AA18: 6664 | AB18: =(Z18+AA18)-(Z17+AA17) -> 3 | AC18: 1815 | AD18: 1253 | AE18: =AC18+AD18-AC17-AD17 -> 2 | AF18: =R18+T18+W18 -> 10 | AG18: =B18+C18+G18+H18 -> 146468 | AH18: 148 | AI18: 172 | AJ18: =AI18-AH18 -> 24 | AK18: 1122288 | AL18: =AK18-AK17 -> 1998 | AM18: 46587 | AN18: =AM18-AM17 -> 46 | AO18: 50698 | AP18: =AO18-AO17 -> 0 | AQ18: 29134 | AR18: =AQ18-AQ17 -> 445 | AS18: =SUM(AK18:AM18) -> 1170873 | AT18: 2038 | AU18: 1407 | AV18: =AU18-AT18 -> -631 | AX18: 27.49 | BA18: 11539.6 | BB18: =(BA18-BA17)*4400 -> 16720 | BC18: =(AW18+AZ18) -> 0 | BD18: =BC18-AW18 -> 0 | BE18: =BD18*4400 -> 0 | BF18: =AX18+BA18 -> 11567.09 | BG18: =BF18-BF17 -> 3.8 | BH18: =BG18*4400 -> 16720 | BI18: 16720 | BJ18: 15610 | BK18: 22201.9 | BL18: =(BK18-BK17)*100 -> 590 | BM18: 17310 | BN18: 18007 | BO18: =BN18-BM18 -> 697 | BP18: 2529964 | BQ18: 19 | BR18: 3506641 | BS18: 1091 | BT18: =BQ18+BS18 -> 1110 | BU18: 136 | BV18: 201
