Workbook

Sheet Total
A1: Site Name | B1: Day | C1: Month | D1: Year | E1: Total Electricity Kwh | F1: Electricity Tariff ($/Kwh) | G1: LPG (Kg) | H1: LPG $/Kg | I1: Water Utility Supply (m3) m3 | J1: Water Utility Supply (m3) $/m3 | K1: Room Nights | L1: Utilities day cost dh
A2: Serengeti | B2: 1 | C2: 10 | D2: 2019 | E2: ='UTILITY REPORT 1'!F3 -> 5669 | F2: =('UTILITY REPORT 1'!E3*'UTILITY REPORT 1'!D3)/'UTILITY REPORT 1'!F3 -> 0.38445581 | G2: =IF('Utility summery'!M6<0,"0",'Utility summery'!M6) -> 95.964 | H2: 0 | I2: =IF('UTILITY REPORT 1'!G3<0,"0",'UTILITY REPORT 1'!G3) -> 130 | J2: 0 | K2: ='UTILITY REPORT 1'!C3 -> 48 | L2: =E2*F2+G2*H2+#REF!*#REF!+I2*J2 -> #REF!
A3: Serengeti | B3: =B2+1 -> 2 | C3: 10 | D3: 2019 | E3: ='UTILITY REPORT 1'!F4 -> 6159 | F3: =('UTILITY REPORT 1'!E4*'UTILITY REPORT 1'!D4)/'UTILITY REPORT 1'!F4 -> 0.40150187 | G3: =IF('Utility summery'!M7<0,"0",'Utility summery'!M7) -> 112.596 | H3: 0 | I3: =IF('UTILITY REPORT 1'!G4<0,"0",'UTILITY REPORT 1'!G4) -> 128 | J3: 0 | K3: ='UTILITY REPORT 1'!C4 -> 62 | L3: =E3*F3+G3*H3+#REF!*#REF!+I3*J3 -> #REF!
A4: Serengeti | B4: =B3+1 -> 3 | C4: 10 | D4: 2019 | E4: ='UTILITY REPORT 1'!F5 -> 6580 | F4: =('UTILITY REPORT 1'!E5*'UTILITY REPORT 1'!D5)/'UTILITY REPORT 1'!F5 -> 0.38820517 | G4: =IF('Utility summery'!M8<0,"0",'Utility summery'!M8) -> 116.16 | H4: 0 | I4: =IF('UTILITY REPORT 1'!G5<0,"0",'UTILITY REPORT 1'!G5) -> 120 | J4: 0 | K4: ='UTILITY REPORT 1'!C5 -> 41 | L4: =E4*F4+G4*H4+#REF!*#REF!+I4*J4 -> #REF!
A5: Serengeti | B5: =B4+1 -> 4 | C5: 10 | D5: 2019 | E5: ='UTILITY REPORT 1'!F6 -> 6223 | F5: =('UTILITY REPORT 1'!E6*'UTILITY REPORT 1'!D6)/'UTILITY REPORT 1'!F6 -> 0.39232203 | G5: =IF('Utility summery'!M9<0,"0",'Utility summery'!M9) -> 117.92 | H5: 0 | I5: =IF('UTILITY REPORT 1'!G6<0,"0",'UTILITY REPORT 1'!G6) -> 120 | J5: 0 | K5: ='UTILITY REPORT 1'!C6 -> 47 | L5: =E5*F5+G5*H5+#REF!*#REF!+I5*J5 -> #REF!
A6: Serengeti | B6: =B5+1 -> 5 | C6: 10 | D6: 2019 | E6: ='UTILITY REPORT 1'!F7 -> 5984 | F6: =('UTILITY REPORT 1'!E7*'UTILITY REPORT 1'!D7)/'UTILITY REPORT 1'!F7 -> 0.39076872 | G6: =IF('Utility summery'!M10<0,"0",'Utility summery'!M10) -> 121.44 | H6: 0 | I6: =IF('UTILITY REPORT 1'!G7<0,"0",'UTILITY REPORT 1'!G7) -> 114 | J6: 0 | K6: ='UTILITY REPORT 1'!C7 -> 53 | L6: =E6*F6+G6*H6+#REF!*#REF!+I6*J6 -> #REF!
A7: Serengeti | B7: =B6+1 -> 6 | C7: 10 | D7: 2019 | E7: ='UTILITY REPORT 1'!F8 -> 6103 | F7: =('UTILITY REPORT 1'!E8*'UTILITY REPORT 1'!D8)/'UTILITY REPORT 1'!F8 -> 0.40617729 | G7: =IF('Utility summery'!M11<0,"0",'Utility summery'!M11) -> 120.56 | H7: 0 | I7: =IF('UTILITY REPORT 1'!G8<0,"0",'UTILITY REPORT 1'!G8) -> 126 | J7: 0 | K7: ='UTILITY REPORT 1'!C8 -> 41 | L7: =E7*F7+G7*H7+#REF!*#REF!+I7*J7 -> #REF!
A8: Serengeti | B8: =B7+1 -> 7 | C8: 10 | D8: 2019 | E8: ='UTILITY REPORT 1'!F9 -> 5576 | F8: =('UTILITY REPORT 1'!E9*'UTILITY REPORT 1'!D9)/'UTILITY REPORT 1'!F9 -> 0.40825681 | G8: =IF('Utility summery'!M12<0,"0",'Utility summery'!M12) -> 119.68 | H8: 0 | I8: =IF('UTILITY REPORT 1'!G9<0,"0",'UTILITY REPORT 1'!G9) -> 116 | J8: 0 | K8: ='UTILITY REPORT 1'!C9 -> 58 | L8: =E8*F8+G8*H8+#REF!*#REF!+I8*J8 -> #REF!
A9: Serengeti | B9: =B8+1 -> 8 | C9: 10 | D9: 2019 | E9: ='UTILITY REPORT 1'!F10 -> 5532 | F9: =('UTILITY REPORT 1'!E10*'UTILITY REPORT 1'!D10)/'UTILITY REPORT 1'!F10 -> 0.40535069 | G9: =IF('Utility summery'!M13<0,"0",'Utility summery'!M13) -> 118.36 | H9: 0 | I9: =IF('UTILITY REPORT 1'!G10<0,"0",'UTILITY REPORT 1'!G10) -> 120 | J9: 0 | K9: ='UTILITY REPORT 1'!C10 -> 12 | L9: =E9*F9+G9*H9+#REF!*#REF!+I9*J9 -> #REF!
A10: Serengeti | B10: =B9+1 -> 9 | C10: 10 | D10: 2019 | E10: ='UTILITY REPORT 1'!F11 -> 6233 | F10: =('UTILITY REPORT 1'!E11*'UTILITY REPORT 1'!D11)/'UTILITY REPORT 1'!F11 -> 0.38990374 | G10: =IF('Utility summery'!M14<0,"0",'Utility summery'!M14) -> 117.04 | H10: 0 | I10: =IF('UTILITY REPORT 1'!G11<0,"0",'UTILITY REPORT 1'!G11) -> 107 | J10: 0 | K10: ='UTILITY REPORT 1'!C11 -> 34 | L10: =E10*F10+G10*H10+#REF!*#REF!+I10*J10 -> #REF!
A11: Serengeti | B11: =B10+1 -> 10 | C11: 10 | D11: 2019 | E11: ='UTILITY REPORT 1'!F12 -> 6063 | F11: =('UTILITY REPORT 1'!E12*'UTILITY REPORT 1'!D12)/'UTILITY REPORT 1'!F12 -> 0.40636154 | G11: =IF('Utility summery'!M15<0,"0",'Utility summery'!M15) -> 116.16 | H11: 0 | I11: =IF('UTILITY REPORT 1'!G12<0,"0",'UTILITY REPORT 1'!G12) -> 123 | J11: 0 | K11: ='UTILITY REPORT 1'!C12 -> 25 | L11: =E11*F11+G11*H11+#REF!*#REF!+I11*J11 -> #REF!
A12: Serengeti | B12: =B11+1 -> 11 | C12: 10 | D12: 2019 | E12: ='UTILITY REPORT 1'!F13 -> 5967 | F12: =('UTILITY REPORT 1'!E13*'UTILITY REPORT 1'!D13)/'UTILITY REPORT 1'!F13 -> 0.38716105 | G12: =IF('Utility summery'!M16<0,"0",'Utility summery'!M16) -> 110.88 | H12: 0 | I12: =IF('UTILITY REPORT 1'!G13<0,"0",'UTILITY REPORT 1'!G13) -> 112 | J12: 0 | K12: ='UTILITY REPORT 1'!C13 -> 35 | L12: =E12*F12+G12*H12+#REF!*#REF!+I12*J12 -> #REF!
A13: Serengeti | B13: =B12+1 -> 12 | C13: 10 | D13: 2019 | E13: ='UTILITY REPORT 1'!F14 -> 5863 | F13: =('UTILITY REPORT 1'!E14*'UTILITY REPORT 1'!D14)/'UTILITY REPORT 1'!F14 -> 0.41432202 | G13: =IF('Utility summery'!M17<0,"0",'Utility summery'!M17) -> 108.24 | H13: 0 | I13: =IF('UTILITY REPORT 1'!G14<0,"0",'UTILITY REPORT 1'!G14) -> 128 | J13: 0 | K13: ='UTILITY REPORT 1'!C14 -> 32 | L13: =E13*F13+G13*H13+#REF!*#REF!+I13*J13 -> #REF!
A14: Serengeti | B14: =B13+1 -> 13 | C14: 10 | D14: 2019 | E14: ='UTILITY REPORT 1'!F15 -> 5720 | F14: =('UTILITY REPORT 1'!E15*'UTILITY REPORT 1'!D15)/'UTILITY REPORT 1'!F15 -> 0.39327448 | G14: =IF('Utility summery'!M18<0,"0",'Utility summery'!M18) -> 104.28 | H14: 0 | I14: =IF('UTILITY REPORT 1'!G15<0,"0",'UTILITY REPORT 1'!G15) -> 114 | J14: 0 | K14: ='UTILITY REPORT 1'!C15 -> 30 | L14: =E14*F14+G14*H14+#REF!*#REF!+I14*J14 -> #REF!
... A31: Serengeti | B31: =B30+1 -> 30 | C31: 10 | D31: 2019 | E31: ='UTILITY REPORT 1'!F32 -> 5192 | F31: =('UTILITY REPORT 1'!E32*'UTILITY REPORT 1'!D32)/'UTILITY REPORT 1'!F32 -> 0.39170647 | G31: =IF('Utility summery'!M35<0,"0",'Utility summery'!M35) -> 106.92 | H31: 0 | I31: =IF('UTILITY REPORT 1'!G32<0,"0",'UTILITY REPORT 1'!G32) -> 99 | J31: 0 | K31: ='UTILITY REPORT 1'!C32 -> 32 | L31: =E31*F31+G31*H31+#REF!*#REF!+I31*J31 -> #REF!
A32: Serengeti | B32: =B31+1 -> 31 | C32: 10 | D32: 2019 | E32: ='UTILITY REPORT 1'!F33 -> 5234 | F32: =('UTILITY REPORT 1'!E33*'UTILITY REPORT 1'!D33)/'UTILITY REPORT 1'!F33 -> 0.40627054 | G32: =IF('Utility summery'!M36<0,"0",'Utility summery'!M36) -> 119.68 | H32: 0 | I32: =IF('UTILITY REPORT 1'!G33<0,"0",'UTILITY REPORT 1'!G33) -> 111 | J32: 0 | K32: ='UTILITY REPORT 1'!C33 -> 25

Sheet Submetering
A1: Site Name | B1: Day | C1: Month | D1: Year | E1: Transport Consumption (LT) | F1: Generators Consumption (LT) | G1: Total Electricity Kwh | H1: Kitchen (KWh) | I1: Laundry (KWh) | J1: STP (M3) | K1: RO prodution (M3) | L1: Amani Restaurant (M3) | M1: Kitchen (M3) | N1: Laundry (M3) | O1: Laundry (M3) | P1: Total water consumption (m3) | Q1: Borehole #1 (M3) | R1: Borehole #2 (M3) | S1: Borehole #3 (M3) | T1: Borehole #4 (M3) | U1: Borehole #5 (M3) | V1: Borehole #6 (M3) | W1: Total Bore Holes production (m3)
A2: Serengeti | B2: 1 | C2: 10 | D2: 2019 | E2: ='UTILITY REPORT 1'!I3 -> 203.28 | F2: ='UTILITY REPORT 1'!E3 -> 2179.48 | G2: ='UTILITY REPORT 1'!F3 -> 5669 | H2: =IF('Kit report'!F4<0,"0",'Kit report'!F4) -> 420 | I2: =IF('Kit report'!X4<0,"0",'Kit report'!X4) -> 740 | J2: =IF('Utility summery'!H6<0,"0",'Utility summery'!H6) -> 41 | K2: =IF('UTILITY REPORT 1'!H3<0,"0",'UTILITY REPORT 1'!H3) -> 26 | L2: =IF('Kit report'!Q4<0,"0",'Kit report'!Q4) -> 2 | M2: =IF('Kit report'!L4<0,"0",'Kit report'!L4) -> 11 | N2: =IF('Kit report'!AC4<0,"0",'Kit report'!AC4) -> 15149.1 | O2: =K2*E2+H2*I2+#REF!*#REF!+J2*L2 -> #REF! | P2: ='Water-Meter'!E6 -> 130 | Q2: =IF('Water-Meter'!U6<0,"0",'Water-Meter'!U6) -> 25 | R2: =IF('Water-Meter'!X6<0,"0",'Water-Meter'!X6) -> 51 | S2: =IF('Water-Meter'!AA6<0,"0",'Water-Meter'!AA6) -> 50 | T2: =IF('Water-Meter'!AD6<0,"0",'Water-Meter'!AD6) -> 0 | U2: =IF('Water-Meter'!AG6<0,"0",'Water-Meter'!AG6) -> 13 | V2: =IF('Water-Meter'!AJ6<0,"0",'Water-Meter'!AJ6) -> 21 | W2: ='Water-Meter'!AN6 -> 160
A3: Serengeti | B3: =B2+1 -> 2 | C3: 10 | D3: 2019 | E3: ='UTILITY REPORT 1'!I4 -> 31.45 | F3: ='UTILITY REPORT 1'!E4 -> 2472.85 | G3: ='UTILITY REPORT 1'!F4 -> 6159 | H3: =IF('Kit report'!F5<0,"0",'Kit report'!F5) -> 480 | I3: =IF('Kit report'!X5<0,"0",'Kit report'!X5) -> 900 | J3: =IF('Utility summery'!H7<0,"0",'Utility summery'!H7) -> 44 | K3: =IF('UTILITY REPORT 1'!H4<0,"0",'UTILITY REPORT 1'!H4) -> 177 | L3: =IF('Kit report'!Q5<0,"0",'Kit report'!Q5) -> 4 | M3: =IF('Kit report'!L5<0,"0",'Kit report'!L5) -> 20 | N3: =IF('Kit report'!AC5<0,"0",'Kit report'!AC5) -> 7 | O3: =K3*E3+H3*I3+#REF!*#REF!+J3*L3 -> #REF! | P3: ='Water-Meter'!E7 -> 128 | Q3: =IF('Water-Meter'!U7<0,"0",'Water-Meter'!U7) -> 29 | R3: =IF('Water-Meter'!X7<0,"0",'Water-Meter'!X7) -> 54 | S3: =IF('Water-Meter'!AA7<0,"0",'Water-Meter'!AA7) -> 52 | T3: =IF('Water-Meter'!AD7<0,"0",'Water-Meter'!AD7) -> 0 | U3: =IF('Water-Meter'!AG7<0,"0",'Water-Meter'!AG7) -> 13 | V3: =IF('Water-Meter'!AJ7<0,"0",'Water-Meter'!AJ7) -> 20 | W3: ='Water-Meter'!AN7 -> 168
A4: Serengeti | B4: =B3+1 -> 3 | C4: 10 | D4: 2019 | E4: ='UTILITY REPORT 1'!I5 -> 106.26 | F4: ='UTILITY REPORT 1'!E5 -> 2554.39 | G4: ='UTILITY REPORT 1'!F5 -> 6580 | H4: =IF('Kit report'!F6<0,"0",'Kit report'!F6) -> 504 | I4: =IF('Kit report'!X6<0,"0",'Kit report'!X6) -> 940 | J4: =IF('Utility summery'!H8<0,"0",'Utility summery'!H8) -> 41 | K4: =IF('UTILITY REPORT 1'!H5<0,"0",'UTILITY REPORT 1'!H5) -> 128 | L4: =IF('Kit report'!Q6<0,"0",'Kit report'!Q6) -> 3 | M4: =IF('Kit report'!L6<0,"0",'Kit report'!L6) -> 18 | N4: =IF('Kit report'!AC6<0,"0",'Kit report'!AC6) -> 9 | O4: =K4*E4+H4*I4+#REF!*#REF!+J4*L4 -> #REF! | P4: ='Water-Meter'!E8 -> 120 | Q4: =IF('Water-Meter'!U8<0,"0",'Water-Meter'!U8) -> 30 | R4: =IF('Water-Meter'!X8<0,"0",'Water-Meter'!X8) -> 52 | S4: =IF('Water-Meter'!AA8<0,"0",'Water-Meter'!AA8) -> 51 | T4: =IF('Water-Meter'!AD8<0,"0",'Water-Meter'!AD8) -> 0 | U4: =IF('Water-Meter'!AG8<0,"0",'Water-Meter'!AG8) -> 12 | V4: =IF('Water-Meter'!AJ8<0,"0",'Water-Meter'!AJ8) -> 22 | W4: ='Water-Meter'!AN8 -> 167
A5: Serengeti | B5: =B4+1 -> 4 | C5: 10 | D5: 2019 | E5: ='UTILITY REPORT 1'!I6 -> 292.31 | F5: ='UTILITY REPORT 1'!E6 -> 2441.42 | G5: ='UTILITY REPORT 1'!F6 -> 6223 | H5: =IF('Kit report'!F7<0,"0",'Kit report'!F7) -> 516 | I5: =IF('Kit report'!X7<0,"0",'Kit report'!X7) -> 920 | J5: =IF('Utility summery'!H9<0,"0",'Utility summery'!H9) -> 69 | K5: =IF('UTILITY REPORT 1'!H6<0,"0",'UTILITY REPORT 1'!H6) -> 115 | L5: =IF('Kit report'!Q7<0,"0",'Kit report'!Q7) -> 4 | M5: =IF('Kit report'!L7<0,"0",'Kit report'!L7) -> 13 | N5: =IF('Kit report'!AC7<0,"0",'Kit report'!AC7) -> 12 | O5: =K5*E5+H5*I5+#REF!*#REF!+J5*L5 -> #REF! | P5: ='Water-Meter'!E9 -> 120 | Q5: =IF('Water-Meter'!U9<0,"0",'Water-Meter'!U9) -> 41 | R5: =IF('Water-Meter'!X9<0,"0",'Water-Meter'!X9) -> 48 | S5: =IF('Water-Meter'!AA9<0,"0",'Water-Meter'!AA9) -> 62 | T5: =IF('Water-Meter'!AD9<0,"0",'Water-Meter'!AD9) -> 15 | U5: =IF('Water-Meter'!AG9<0,"0",'Water-Meter'!AG9) -> 10 | V5: =IF('Water-Meter'!AJ9<0,"0",'Water-Meter'!AJ9) -> 18 | W5: ='Water-Meter'!AN9 -> 194
A6: Serengeti | B6: =B5+1 -> 5 | C6: 10 | D6: 2019 | E6: ='UTILITY REPORT 1'!I7 -> 79.16 | F6: ='UTILITY REPORT 1'!E7 -> 2338.36 | G6: ='UTILITY REPORT 1'!F7 -> 5984 | H6: =IF('Kit report'!F8<0,"0",'Kit report'!F8) -> 540 | I6: =IF('Kit report'!X8<0,"0",'Kit report'!X8) -> 1040 | J6: =IF('Utility summery'!H10<0,"0",'Utility summery'!H10) -> 44 | K6: =IF('UTILITY REPORT 1'!H7<0,"0",'UTILITY REPORT 1'!H7) -> 86 | L6: =IF('Kit report'!Q8<0,"0",'Kit report'!Q8) -> 3 | M6: =IF('Kit report'!L8<0,"0",'Kit report'!L8) -> 15 | N6: =IF('Kit report'!AC8<0,"0",'Kit report'!AC8) -> 11 | O6: =K6*E6+H6*I6+#REF!*#REF!+J6*L6 -> #REF! | P6: ='Water-Meter'!E10 -> 114 | Q6: =IF('Water-Meter'!U10<0,"0",'Water-Meter'!U10) -> 29 | R6: =IF('Water-Meter'!X10<0,"0",'Water-Meter'!X10) -> 50 | S6: =IF('Water-Meter'!AA10<0,"0",'Water-Meter'!AA10) -> 63 | T6: =IF('Water-Meter'!AD10<0,"0",'Water-Meter'!AD10) -> 9 | U6: =IF('Water-Meter'!AG10<0,"0",'Water-Meter'!AG10) -> 11 | V6: =IF('Water-Meter'!AJ10<0,"0",'Water-Meter'!AJ10) -> 20 | W6: ='Water-Meter'!AN10 -> 182
A7: Serengeti | B7: =B6+1 -> 6 | C7: 10 | D7: 2019 | E7: ='UTILITY REPORT 1'!I8 -> 115.65 | F7: ='UTILITY REPORT 1'!E8 -> 2478.9 | G7: ='UTILITY REPORT 1'!F8 -> 6103 | H7: =IF('Kit report'!F9<0,"0",'Kit report'!F9) -> 444 | I7: =IF('Kit report'!X9<0,"0",'Kit report'!X9) -> 1060 | J7: =IF('Utility summery'!H11<0,"0",'Utility summery'!H11) -> 48 | K7: =IF('UTILITY REPORT 1'!H8<0,"0",'UTILITY REPORT 1'!H8) -> 114 | L7: =IF('Kit report'!Q9<0,"0",'Kit report'!Q9) -> 2 | M7: =IF('Kit report'!L9<0,"0",'Kit report'!L9) -> 16 | N7: =IF('Kit report'!AC9<0,"0",'Kit report'!AC9) -> 7 | O7: =K7*E7+H7*I7+#REF!*#REF!+J7*L7 -> #REF! | P7: ='Water-Meter'!E11 -> 126 | Q7: =IF('Water-Meter'!U11<0,"0",'Water-Meter'!U11) -> 30 | R7: =IF('Water-Meter'!X11<0,"0",'Water-Meter'!X11) -> 51 | S7: =IF('Water-Meter'!AA11<0,"0",'Water-Meter'!AA11) -> 68 | T7: =IF('Water-Meter'!AD11<0,"0",'Water-Meter'!AD11) -> 8 | U7: =IF('Water-Meter'!AG11<0,"0",'Water-Meter'!AG11) -> 11 | V7: =IF('Water-Meter'!AJ11<0,"0",'Water-Meter'!AJ11) -> 21 | W7: ='Water-Meter'!AN11 -> 189
A8: Serengeti | B8: =B7+1 -> 7 | C8: 10 | D8: 2019 | E8: ='UTILITY REPORT 1'!I9 -> 74.81 | F8: ='UTILITY REPORT 1'!E9 -> 2276.44 | G8: ='UTILITY REPORT 1'!F9 -> 5576 | H8: =IF('Kit report'!F10<0,"0",'Kit report'!F10) -> 528 | I8: =IF('Kit report'!X10<0,"0",'Kit report'!X10) -> 1120 | J8: =IF('Utility summery'!H12<0,"0",'Utility summery'!H12) -> 45 | K8: =IF('UTILITY REPORT 1'!H9<0,"0",'UTILITY REPORT 1'!H9) -> 107 | L8: =IF('Kit report'!Q10<0,"0",'Kit report'!Q10) -> 3 | M8: =IF('Kit report'!L10<0,"0",'Kit report'!L10) -> 13 | N8: =IF('Kit report'!AC10<0,"0",'Kit report'!AC10) -> 13 | O8: =K8*E8+H8*I8+#REF!*#REF!+J8*L8 -> #REF! | P8: ='Water-Meter'!E12 -> 116 | Q8: =IF('Water-Meter'!U12<0,"0",'Water-Meter'!U12) -> 30 | R8: =IF('Water-Meter'!X12<0,"0",'Water-Meter'!X12) -> 49 | S8: =IF('Water-Meter'!AA12<0,"0",'Water-Meter'!AA12) -> 56 | T8: =IF('Water-Meter'!AD12<0,"0",'Water-Meter'!AD12) -> 8 | U8: =IF('Water-Meter'!AG12<0,"0",'Water-Meter'!AG12) -> 6 | V8: =IF('Water-Meter'!AJ12<0,"0",'Water-Meter'!AJ12) -> 19 | W8: ='Water-Meter'!AN12 -> 168
A9: Serengeti | B9: =B8+1 -> 8 | C9: 10 | D9: 2019 | E9: ='UTILITY REPORT 1'!I10 -> 94.01 | F9: ='UTILITY REPORT 1'!E10 -> 2242.4 | G9: ='UTILITY REPORT 1'!F10 -> 5532 | H9: =IF('Kit report'!F11<0,"0",'Kit report'!F11) -> 492 | I9: =IF('Kit report'!X11<0,"0",'Kit report'!X11) -> 900 | J9: =IF('Utility summery'!H13<0,"0",'Utility summery'!H13) -> 50 | K9: =IF('UTILITY REPORT 1'!H10<0,"0",'UTILITY REPORT 1'!H10) -> 52 | L9: =IF('Kit report'!Q11<0,"0",'Kit report'!Q11) -> 2 | M9: =IF('Kit report'!L11<0,"0",'Kit report'!L11) -> 14 | N9: =IF('Kit report'!AC11<0,"0",'Kit report'!AC11) -> 10 | O9: =K9*E9+H9*I9+#REF!*#REF!+J9*L9 -> #REF! | P9: ='Water-Meter'!E13 -> 120 | Q9: =IF('Water-Meter'!U13<0,"0",'Water-Meter'!U13) -> 32 | R9: =IF('Water-Meter'!X13<0,"0",'Water-Meter'!X13) -> 50 | S9: =IF('Water-Meter'!AA13<0,"0",'Water-Meter'!AA13) -> 58 | T9: =IF('Water-Meter'!AD13<0,"0",'Water-Meter'!AD13) -> 8 | U9: =IF('Water-Meter'!AG13<0,"0",'Water-Meter'!AG13) -> 14 | V9: =IF('Water-Meter'!AJ13<0,"0",'Water-Meter'!AJ13) -> 20 | W9: ='Water-Meter'!AN13 -> 182
A10: Serengeti | B10: =B9+1 -> 9 | C10: 10 | D10: 2019 | E10: ='UTILITY REPORT 1'!I11 -> 284.83 | F10: ='UTILITY REPORT 1'!E11 -> 2430.27 | G10: ='UTILITY REPORT 1'!F11 -> 6233 | H10: =IF('Kit report'!F12<0,"0",'Kit report'!F12) -> 528 | I10: =IF('Kit report'!X12<0,"0",'Kit report'!X12) -> 860 | J10: =IF('Utility summery'!H14<0,"0",'Utility summery'!H14) -> 48 | K10: =IF('UTILITY REPORT 1'!H11<0,"0",'UTILITY REPORT 1'!H11) -> 33 | L10: =IF('Kit report'!Q12<0,"0",'Kit report'!Q12) -> 3 | M10: =IF('Kit report'!L12<0,"0",'Kit report'!L12) -> 17 | N10: =IF('Kit report'!AC12<0,"0",'Kit report'!AC12) -> 7 | O10: =K10*E10+H10*I10+#REF!*#REF!+J10*L10 -> #REF! | P10: ='Water-Meter'!E14 -> 107 | Q10: =IF('Water-Meter'!U14<0,"0",'Water-Meter'!U14) -> 31 | R10: =IF('Water-Meter'!X14<0,"0",'Water-Meter'!X14) -> 49 | S10: =IF('Water-Meter'!AA14<0,"0",'Water-Meter'!AA14) -> 58 | T10: =IF('Water-Meter'!AD14<0,"0",'Water-Meter'!AD14) -> 8 | U10: =IF('Water-Meter'!AG14<0,"0",'Water-Meter'!AG14) -> 10 | V10: =IF('Water-Meter'!AJ14<0,"0",'Water-Meter'!AJ14) -> 20 | W10: ='Water-Meter'!AN14 -> 176
A11: Serengeti | B11: =B10+1 -> 10 | C11: 10 | D11: 2019 | E11: ='UTILITY REPORT 1'!I12 -> 106.04 | F11: ='UTILITY REPORT 1'!E12 -> 2463.77 | G11: ='UTILITY REPORT 1'!F12 -> 6063 | H11: =IF('Kit report'!F13<0,"0",'Kit report'!F13) -> 528 | I11: =IF('Kit report'!X13<0,"0",'Kit report'!X13) -> 780 | J11: =IF('Utility summery'!H15<0,"0",'Utility summery'!H15) -> 47 | K11: =IF('UTILITY REPORT 1'!H12<0,"0",'UTILITY REPORT 1'!H12) -> 82 | L11: =IF('Kit report'!Q13<0,"0",'Kit report'!Q13) -> 4 | M11: =IF('Kit report'!L13<0,"0",'Kit report'!L13) -> 14 | N11: =IF('Kit report'!AC13<0,"0",'Kit report'!AC13) -> 11 | O11: =K11*E11+H11*I11+#REF!*#REF!+J11*L11 -> #REF! | P11: ='Water-Meter'!E15 -> 123 | Q11: =IF('Water-Meter'!U15<0,"0",'Water-Meter'!U15) -> 30 | R11: =IF('Water-Meter'!X15<0,"0",'Water-Meter'!X15) -> 50 | S11: =IF('Water-Meter'!AA15<0,"0",'Water-Meter'!AA15) -> 56 | T11: =IF('Water-Meter'!AD15<0,"0",'Water-Meter'!AD15) -> 8 | U11: =IF('Water-Meter'!AG15<0,"0",'Water-Meter'!AG15) -> 0 | V11: =IF('Water-Meter'!AJ15<0,"0",'Water-Meter'!AJ15) -> 19 | W11: ='Water-Meter'!AN15 -> 163
A12: Serengeti | B12: =B11+1 -> 11 | C12: 10 | D12: 2019 | E12: ='UTILITY REPORT 1'!I13 -> 263.09 | F12: ='UTILITY REPORT 1'!E13 -> 2310.19 | G12: ='UTILITY REPORT 1'!F13 -> 5967 | H12: =IF('Kit report'!F14<0,"0",'Kit report'!F14) -> 528 | I12: =IF('Kit report'!X14<0,"0",'Kit report'!X14) -> 900 | J12: =IF('Utility summery'!H16<0,"0",'Utility summery'!H16) -> 47 | K12: =IF('UTILITY REPORT 1'!H13<0,"0",'UTILITY REPORT 1'!H13) -> 115 | L12: =IF('Kit report'!Q14<0,"0",'Kit report'!Q14) -> 4 | M12: =IF('Kit report'!L14<0,"0",'Kit report'!L14) -> 17 | N12: =IF('Kit report'!AC14<0,"0",'Kit report'!AC14) -> 9 | O12: =K12*E12+H12*I12+#REF!*#REF!+J12*L12 -> #REF! | P12: ='Water-Meter'!E16 -> 112 | Q12: =IF('Water-Meter'!U16<0,"0",'Water-Meter'!U16) -> 29 | R12: =IF('Water-Meter'!X16<0,"0",'Water-Meter'!X16) -> 52 | S12: =IF('Water-Meter'!AA16<0,"0",'Water-Meter'!AA16) -> 63 | T12: =IF('Water-Meter'!AD16<0,"0",'Water-Meter'!AD16) -> 8 | U12: =IF('Water-Meter'!AG16<0,"0",'Water-Meter'!AG16) -> 0 | V12: =IF('Water-Meter'!AJ16<0,"0",'Water-Meter'!AJ16) -> 23 | W12: ='Water-Meter'!AN16 -> 175
A13: Serengeti | B13: =B12+1 -> 12 | C13: 10 | D13: 2019 | E13: ='UTILITY REPORT 1'!I14 -> 309.36 | F13: ='UTILITY REPORT 1'!E14 -> 2429.17 | G13: ='UTILITY REPORT 1'!F14 -> 5863 | H13: =IF('Kit report'!F15<0,"0",'Kit report'!F15) -> 552 | I13: =IF('Kit report'!X15<0,"0",'Kit report'!X15) -> 860 | J13: =IF('Utility summery'!H17<0,"0",'Utility summery'!H17) -> 46 | K13: =IF('UTILITY REPORT 1'!H14<0,"0",'UTILITY REPORT 1'!H14) -> 21 | L13: =IF('Kit report'!Q15<0,"0",'Kit report'!Q15) -> 3 | M13: =IF('Kit report'!L15<0,"0",'Kit report'!L15) -> 14 | N13: =IF('Kit report'!AC15<0,"0",'Kit report'!AC15) -> 9 | O13: =K13*E13+H13*I13+#REF!*#REF!+J13*L13 -> #REF! | P13: ='Water-Meter'!E17 -> 128 | Q13: =IF('Water-Meter'!U17<0,"0",'Water-Meter'!U17) -> 30 | R13: =IF('Water-Meter'!X17<0,"0",'Water-Meter'!X17) -> 51 | S13: =IF('Water-Meter'!AA17<0,"0",'Water-Meter'!AA17) -> 57 | T13: =IF('Water-Meter'!AD17<0,"0",'Water-Meter'!AD17) -> 8 | U13: =IF('Water-Meter'!AG17<0,"0",'Water-Meter'!AG17) -> 0 | V13: =IF('Water-Meter'!AJ17<0,"0",'Water-Meter'!AJ17) -> 19 | W13: ='Water-Meter'!AN17 -> 165
A14: Serengeti | B14: =B13+1 -> 13 | C14: 10 | D14: 2019 | E14: ='UTILITY REPORT 1'!I15 -> 63.78 | F14: ='UTILITY REPORT 1'!E15 -> 2249.53 | G14: ='UTILITY REPORT 1'!F15 -> 5720 | H14: =IF('Kit report'!F16<0,"0",'Kit report'!F16) -> 480 | I14: =IF('Kit report'!X16<0,"0",'Kit report'!X16) -> 1040 | J14: =IF('Utility summery'!H18<0,"0",'Utility summery'!H18) -> 51 | K14: =IF('UTILITY REPORT 1'!H15<0,"0",'UTILITY REPORT 1'!H15) -> 102 | L14: =IF('Kit report'!Q16<0,"0",'Kit report'!Q16) -> 2 | M14: =IF('Kit report'!L16<0,"0",'Kit report'!L16) -> 14 | N14: =IF('Kit report'!AC16<0,"0",'Kit report'!AC16) -> 9 | O14: =K14*E14+H14*I14+#REF!*#REF!+J14*L14 -> #REF! | P14: ='Water-Meter'!E18 -> 114 | Q14: =IF('Water-Meter'!U18<0,"0",'Water-Meter'!U18) -> 30 | R14: =IF('Water-Meter'!X18<0,"0",'Water-Meter'!X18) -> 44 | S14: =IF('Water-Meter'!AA18<0,"0",'Water-Meter'!AA18) -> 52 | T14: =IF('Water-Meter'!AD18<0,"0",'Water-Meter'!AD18) -> 6 | U14: =IF('Water-Meter'!AG18<0,"0",'Water-Meter'!AG18) -> 12 | V14: =IF('Water-Meter'!AJ18<0,"0",'Water-Meter'!AJ18) -> 18 | W14: ='Water-Meter'!AN18 -> 162
... A31: Serengeti | B31: =B30+1 -> 30 | C31: 10 | D31: 2019 | E31: ='UTILITY REPORT 1'!I32 -> 25.52 | F31: ='UTILITY REPORT 1'!E32 -> 2033.74 | G31: ='UTILITY REPORT 1'!F32 -> 5192 | H31: =IF('Kit report'!F33<0,"0",'Kit report'!F33) -> 960 | I31: =IF('Kit report'!X33<0,"0",'Kit report'!X33) -> 1880 | J31: =IF('Utility summery'!H35<0,"0",'Utility summery'!H35) -> 31 | K31: =IF('UTILITY REPORT 1'!H32<0,"0",'UTILITY REPORT 1'!H32) -> 122 | L31: =IF('Kit report'!Q33<0,"0",'Kit report'!Q33) -> 3 | M31: =IF('Kit report'!L33<0,"0",'Kit report'!L33) -> 16 | N31: =IF('Kit report'!AC33<0,"0",'Kit report'!AC33) -> 8 | O31: =K31*E31+H31*I31+#REF!*#REF!+J31*L31 -> #REF! | P31: ='Water-Meter'!E35 -> 99 | Q31: =IF('Water-Meter'!U35<0,"0",'Water-Meter'!U35) -> 29 | R31: =IF('Water-Meter'!X35<0,"0",'Water-Meter'!X35) -> 51 | S31: =IF('Water-Meter'!AA35<0,"0",'Water-Meter'!AA35) -> 56 | T31: =IF('Water-Meter'!AD35<0,"0",'Water-Meter'!AD35) -> 8 | U31: =IF('Water-Meter'!AG35<0,"0",'Water-Meter'!AG35) -> 14 | V31: =IF('Water-Meter'!AJ35<0,"0",'Water-Meter'!AJ35) -> 19 | W31: ='Water-Meter'!AN35 -> 177
A32: Serengeti | B32: =B31+1 -> 31 | C32: 10 | D32: 2019 | E32: ='UTILITY REPORT 1'!I33 -> 533.66 | F32: ='UTILITY REPORT 1'!E33 -> 2126.42 | G32: ='UTILITY REPORT 1'!F33 -> 5234 | H32: =IF('Kit report'!F34<0,"0",'Kit report'!F34) -> 516 | I32: =IF('Kit report'!X34<0,"0",'Kit report'!X34) -> 800 | J32: =IF('Utility summery'!H36<0,"0",'Utility summery'!H36) -> 30 | K32: =IF('UTILITY REPORT 1'!H33<0,"0",'UTILITY REPORT 1'!H33) -> 45 | L32: =IF('Kit report'!Q34<0,"0",'Kit report'!Q34) -> 3 | M32: =IF('Kit report'!L34<0,"0",'Kit report'!L34) -> 15 | N32: =IF('Kit report'!AC34<0,"0",'Kit report'!AC34) -> 10 | P32: ='Water-Meter'!E36 -> 111 | Q32: =IF('Water-Meter'!U36<0,"0",'Water-Meter'!U36) -> 30 | R32: =IF('Water-Meter'!X36<0,"0",'Water-Meter'!X36) -> 50 | S32: =IF('Water-Meter'!AA36<0,"0",'Water-Meter'!AA36) -> 45 | T32: =IF('Water-Meter'!AD36<0,"0",'Water-Meter'!AD36) -> 6 | U32: =IF('Water-Meter'!AG36<0,"0",'Water-Meter'!AG36) -> 15 | V32: =IF('Water-Meter'!AJ36<0,"0",'Water-Meter'!AJ36) -> 20 | W32: ='Water-Meter'!AN36 -> 166
L33: =IF('Kit report'!Q35<0,"0",'Kit report'!Q35) -> 91

Sheet UTILITY REPORT 1
A1: OCTOBER UTILITY REPORT
A2: Date | B2: % | C2: Guest Rooms Occupied | D2: Diesel cost Per Liter ($) | E2: Diesel consumption (LT) | F2: Power production (KW) | G2: Water consumption (M3) | H2: RO prodution (M3) | I2: Transport Consupmtion (LT)
A3: 43739 | B3: =Gen!B11 -> 0.623 | C3: ='Summery Report'!E5 -> 48 | D3: 1 | E3: =Gen!S11 -> 2179.48 | F3: =Gen!T11 -> 5669 | G3: ='Water-Meter'!E6 -> 130 | H3: ='Utility report '!AC6 -> 26 | I3: =Gen!AJ11 -> 203.28
A4: 43740 | B4: =Gen!B12 -> 0.779 | C4: ='Summery Report'!E6 -> 62 | D4: 1 | E4: =Gen!S12 -> 2472.85 | F4: =Gen!T12 -> 6159 | G4: ='Water-Meter'!E7 -> 128 | H4: ='Utility report '!AC7 -> 177 | I4: =Gen!AJ12 -> 31.45
A5: 43741 | B5: =Gen!B13 -> 0.532 | C5: ='Summery Report'!E7 -> 41 | D5: 1 | E5: =Gen!S13 -> 2554.39 | F5: =Gen!T13 -> 6580 | G5: ='Water-Meter'!E8 -> 120 | H5: ='Utility report '!AC8 -> 128 | I5: =Gen!AJ13 -> 106.26
A6: 43742 | B6: =Gen!B14 -> 0.61 | C6: ='Summery Report'!E8 -> 47 | D6: 1 | E6: =Gen!S14 -> 2441.42 | F6: =Gen!T14 -> 6223 | G6: ='Water-Meter'!E9 -> 120 | H6: ='Utility report '!AC9 -> 115 | I6: =Gen!AJ14 -> 292.31
A7: 43743 | B7: =Gen!B15 -> 0.688 | C7: ='Summery Report'!E9 -> 53 | D7: 1 | E7: =Gen!S15 -> 2338.36 | F7: =Gen!T15 -> 5984 | G7: ='Water-Meter'!E10 -> 114 | H7: ='Utility report '!AC10 -> 86 | I7: =Gen!AJ15 -> 79.16
A8: 43744 | B8: =Gen!B16 -> 0.532 | C8: ='Summery Report'!E10 -> 41 | D8: 1 | E8: =Gen!S16 -> 2478.9 | F8: =Gen!T16 -> 6103 | G8: ='Water-Meter'!E11 -> 126 | H8: ='Utility report '!AC11 -> 114 | I8: =Gen!AJ16 -> 115.65
A9: 43745 | B9: =Gen!B17 -> 0.753 | C9: ='Summery Report'!E11 -> 58 | D9: 1 | E9: =Gen!S17 -> 2276.44 | F9: =Gen!T17 -> 5576 | G9: ='Water-Meter'!E12 -> 116 | H9: ='Utility report '!AC12 -> 107 | I9: =Gen!AJ17 -> 74.81
A10: 43746 | B10: =Gen!B18 -> 0.156 | C10: ='Summery Report'!E12 -> 12 | D10: 1 | E10: =Gen!S18 -> 2242.4 | F10: =Gen!T18 -> 5532 | G10: ='Water-Meter'!E13 -> 120 | H10: ='Utility report '!AC13 -> 52 | I10: =Gen!AJ18 -> 94.01
A11: 43747 | B11: =Gen!B19 -> 0.442 | C11: ='Summery Report'!E13 -> 34 | D11: 1 | E11: =Gen!S19 -> 2430.27 | F11: =Gen!T19 -> 6233 | G11: ='Water-Meter'!E14 -> 107 | H11: ='Utility report '!AC14 -> 33 | I11: =Gen!AJ19 -> 284.83
A12: 43748 | B12: =Gen!B20 -> 0.325 | C12: ='Summery Report'!E14 -> 25 | D12: 1 | E12: =Gen!S20 -> 2463.77 | F12: =Gen!T20 -> 6063 | G12: ='Water-Meter'!E15 -> 123 | H12: ='Utility report '!AC15 -> 82 | I12: =Gen!AJ20 -> 106.04
A13: 43749 | B13: =Gen!B21 -> 0.455 | C13: ='Summery Report'!E15 -> 35 | D13: 1 | E13: =Gen!S21 -> 2310.19 | F13: =Gen!T21 -> 5967 | G13: ='Water-Meter'!E16 -> 112 | H13: ='Utility report '!AC16 -> 115 | I13: =Gen!AJ21 -> 263.09
A14: 43750 | B14: =Gen!B22 -> 0.416 | C14: ='Summery Report'!E16 -> 32 | D14: 1 | E14: =Gen!S22 -> 2429.17 | F14: =Gen!T22 -> 5863 | G14: ='Water-Meter'!E17 -> 128 | H14: ='Utility report '!AC17 -> 21 | I14: =Gen!AJ22 -> 309.36
... A33: 43769 | B33: =Gen!B41 -> 0.325 | C33: ='Summery Report'!E35 -> 25 | D33: 1 | E33: =Gen!S41 -> 2126.42 | F33: =Gen!T41 -> 5234 | G33: ='Water-Meter'!E36 -> 111 | H33: ='Utility report '!AC36 -> 45 | I33: =Gen!AJ41 -> 533.66

Sheet Utility summery
A4: Date | B4: Room Occupied | C4: Electricity Units Generated KW | D4: Diseal | G4: Water | J4: Gas | N4: Cost of utilites
D5: Generator | E5: Transport | F5: Total | G5: RO | H5: STP | I5: Total Consumption | J5: 2 ton | K5: 1 Ton | L5: 1 Ton | M5: Total consumption | N5: Electricity /1.4$/liter | O5: Diseal for Transport | P5: Gas /2.38$/Kg | Q5: Total HLP Cost | R5: Electricity Cost/Room $ | S5: cost/Room $
A6: =[1]Gen!A11 -> 43739 | B6: ='Summery Report'!E5 -> 48 | C6: ='Daily report Gen'!AA6 -> 416 | D6: =Gen!S11 -> 2179.48 | E6: =Gen!AJ11 -> 203.28 | F6: =Gen!AR11 -> 2382.76 | G6: ='Utility report '!AC6 -> 26 | H6: ='Utility report '!AE6 -> 41 | I6: ='Water-Meter'!E6 -> 130 | J6: ='Lpg (2)'!B10 -> 85 | K6: ='Lpg (2)'!C10 -> 41 | L6: ='Lpg (2)'!D10 -> 85 | M6: ='Lpg (2)'!G10 -> 95.964 | O6: =E6 -> 203.28 | P6: ='[1]Lpg (2)'!#REF! -> #REF! | Q6: ='[1]Summery Report'!#REF! -> #REF! | R6: =N6/B6 -> 0 | S6: =Q6/B6 -> #REF!
A7: =[1]Gen!A12 -> 43740 | B7: ='Summery Report'!E6 -> 62 | C7: ='Daily report Gen'!AA7 -> 409 | D7: =Gen!S12 -> 2472.85 | E7: =Gen!AJ12 -> 31.45 | F7: =Gen!AR12 -> 2504.3 | G7: ='Utility report '!AC7 -> 177 | H7: ='Utility report '!AE7 -> 44 | I7: ='Water-Meter'!E7 -> 128 | J7: ='Lpg (2)'!B11 -> 85 | K7: ='Lpg (2)'!C11 -> 38 | L7: ='Lpg (2)'!D11 -> 85 | M7: ='Lpg (2)'!G11 -> 112.596 | N7: =D7*1.4 -> 3461.99 | O7: =E7*1.4 -> 44.03 | P7: ='[1]Lpg (2)'!#REF! -> #REF! | Q7: ='[1]Summery Report'!#REF! -> #REF! | R7: =N7/B7 -> 55.838548 | S7: =Q7/B7 -> #REF!
A8: =[1]Gen!A13 -> 43741 | B8: ='Summery Report'!E7 -> 41 | C8: ='Daily report Gen'!AA8 -> 453 | D8: =Gen!S13 -> 2554.39 | E8: =Gen!AJ13 -> 106.26 | F8: =Gen!AR13 -> 2660.65 | G8: ='Utility report '!AC8 -> 128 | H8: ='Utility report '!AE8 -> 41 | I8: ='Water-Meter'!E8 -> 120 | J8: ='Lpg (2)'!B12 -> 85 | K8: ='Lpg (2)'!C12 -> 33 | L8: ='Lpg (2)'!D12 -> 85 | M8: ='Lpg (2)'!G12 -> 116.16 | N8: =D8*1.4 -> 3576.146 | O8: =E8*1.4 -> 148.764 | P8: ='[1]Lpg (2)'!#REF! -> #REF! | Q8: ='[1]Summery Report'!#REF! -> #REF! | R8: =N8/B8 -> 87.223073 | S8: =Q8/B8 -> #REF!
A9: =[1]Gen!A14 -> 43742 | B9: ='Summery Report'!E8 -> 47 | C9: ='Daily report Gen'!AA9 -> 562 | D9: =Gen!S14 -> 2441.42 | E9: =Gen!AJ14 -> 292.31 | F9: =Gen!AR14 -> 2733.73 | G9: ='Utility report '!AC9 -> 115 | H9: ='Utility report '!AE9 -> 69 | I9: ='Water-Meter'!E9 -> 120 | J9: ='Lpg (2)'!B13 -> 85 | K9: ='Lpg (2)'!C13 -> 29 | L9: ='Lpg (2)'!D13 -> 85 | M9: ='Lpg (2)'!G13 -> 117.92 | N9: =D9*1.4 -> 3417.988 | O9: =E9*1.4 -> 409.234 | P9: ='[1]Lpg (2)'!#REF! -> #REF! | Q9: ='[1]Summery Report'!#REF! -> #REF! | R9: =N9/B9 -> 72.723149 | S9: =Q9/B9 -> #REF!
A10: =[1]Gen!A15 -> 43743 | B10: ='Summery Report'!E9 -> 53 | C10: ='Daily report Gen'!AA10 -> 497 | D10: =Gen!S15 -> 2338.36 | E10: =Gen!AJ15 -> 79.16 | F10: =Gen!AR15 -> 2417.52 | G10: ='Utility report '!AC10 -> 86 | H10: ='Utility report '!AE10 -> 44 | I10: ='Water-Meter'!E10 -> 114 | J10: ='Lpg (2)'!B14 -> 85 | K10: ='Lpg (2)'!C14 -> 24 | L10: ='Lpg (2)'!D14 -> 85 | M10: ='Lpg (2)'!G14 -> 121.44 | N10: =D10*1.4 -> 3273.704 | O10: =E10*1.4 -> 110.824 | P10: ='[1]Lpg (2)'!#REF! -> #REF! | Q10: ='[1]Summery Report'!#REF! -> #REF! | R10: =N10/B10 -> 61.768 | S10: =Q10/B10 -> #REF!
A11: =[1]Gen!A16 -> 43744 | B11: ='Summery Report'!E10 -> 41 | C11: ='Daily report Gen'!AA11 -> 498 | D11: =Gen!S16 -> 2478.9 | E11: =Gen!AJ16 -> 115.65 | F11: =Gen!AR16 -> 2594.55 | G11: ='Utility report '!AC11 -> 114 | H11: ='Utility report '!AE11 -> 48 | I11: ='Water-Meter'!E11 -> 126 | J11: ='Lpg (2)'!B15 -> 85 | K11: ='Lpg (2)'!C15 -> 19 | L11: ='Lpg (2)'!D15 -> 85 | M11: ='Lpg (2)'!G15 -> 120.56 | N11: =D11*1.4 -> 3470.46 | O11: =E11*1.4 -> 161.91 | P11: ='[1]Lpg (2)'!#REF! -> #REF! | Q11: ='[1]Summery Report'!#REF! -> #REF! | R11: =N11/B11 -> 84.645366 | S11: =Q11/B11 -> #REF!
A12: =[1]Gen!A17 -> 43745 | B12: ='Summery Report'!E11 -> 58 | C12: ='Daily report Gen'!AA12 -> 496 | D12: =Gen!S17 -> 2276.44 | E12: =Gen!AJ17 -> 74.81 | F12: =Gen!AR17 -> 2351.25 | G12: ='Utility report '!AC12 -> 107 | H12: ='Utility report '!AE12 -> 45 | I12: ='Water-Meter'!E12 -> 116 | J12: ='Lpg (2)'!B16 -> 85 | K12: ='Lpg (2)'!C16 -> 15 | L12: ='Lpg (2)'!D16 -> 85 | M12: ='Lpg (2)'!G16 -> 119.68 | N12: =D12*1.4 -> 3187.016 | O12: =E12*1.4 -> 104.734 | P12: ='[1]Lpg (2)'!#REF! -> #REF! | Q12: ='[1]Summery Report'!#REF! -> #REF! | R12: =N12/B12 -> 54.948552 | S12: =Q12/B12 -> #REF!
A13: =[1]Gen!A18 -> 43746 | B13: ='Summery Report'!E12 -> 12 | C13: ='Daily report Gen'!AA13 -> 498 | D13: =Gen!S18 -> 2242.4 | E13: =Gen!AJ18 -> 94.01 | F13: =Gen!AR18 -> 2336.41 | G13: ='Utility report '!AC13 -> 52 | H13: ='Utility report '!AE13 -> 50 | I13: ='Water-Meter'!E13 -> 120 | J13: ='Lpg (2)'!B17 -> 85 | K13: ='Lpg (2)'!C17 -> 9 | L13: ='Lpg (2)'!D17 -> 85 | M13: ='Lpg (2)'!G17 -> 118.36 | N13: =D13*1.4 -> 3139.36 | O13: =E13*1.4 -> 131.614 | P13: ='[1]Lpg (2)'!#REF! -> #REF! | Q13: ='[1]Summery Report'!#REF! -> #REF! | R13: =N13/B13 -> 261.61333 | S13: =Q13/B13 -> #REF!
A14: =[1]Gen!A19 -> 43747 | B14: ='Summery Report'!E13 -> 34 | C14: ='Daily report Gen'!AA14 -> 486 | D14: =Gen!S19 -> 2430.27 | E14: =Gen!AJ19 -> 284.83 | F14: =Gen!AR19 -> 2715.1 | G14: ='Utility report '!AC14 -> 33 | H14: ='Utility report '!AE14 -> 48 | I14: ='Water-Meter'!E14 -> 107 | J14: ='Lpg (2)'!B18 -> 85 | K14: ='Lpg (2)'!C18 -> 5 | L14: ='Lpg (2)'!D18 -> 76 | M14: ='Lpg (2)'!G18 -> 117.04 | N14: =D14*1.4 -> 3402.378 | O14: =E14*1.4 -> 398.762 | P14: ='[1]Lpg (2)'!#REF! -> #REF! | Q14: ='[1]Summery Report'!#REF! -> #REF! | R14: =N14/B14 -> 100.06994 | S14: =Q14/B14 -> #REF!
A15: =[1]Gen!A20 -> 43748 | B15: ='Summery Report'!E14 -> 25 | C15: ='Daily report Gen'!AA15 -> 490 | D15: =Gen!S20 -> 2463.77 | E15: =Gen!AJ20 -> 106.04 | F15: =Gen!AR20 -> 2569.81 | G15: ='Utility report '!AC15 -> 82 | H15: ='Utility report '!AE15 -> 47 | I15: ='Water-Meter'!E15 -> 123 | J15: ='Lpg (2)'!B19 -> 85 | K15: ='Lpg (2)'!C19 -> 5 | L15: ='Lpg (2)'!D19 -> 74 | M15: ='Lpg (2)'!G19 -> 116.16 | N15: =D15*1.4 -> 3449.278 | O15: =E15*1.4 -> 148.456 | P15: ='[1]Lpg (2)'!#REF! -> #REF! | Q15: ='[1]Summery Report'!#REF! -> #REF! | R15: =N15/B15 -> 137.97112 | S15: =Q15/B15 -> #REF!
A16: =[1]Gen!A21 -> 43749 | B16: ='Summery Report'!E15 -> 35 | C16: ='Daily report Gen'!AA16 -> 498 | D16: =Gen!S21 -> 2310.19 | E16: =Gen!AJ21 -> 263.09 | F16: =Gen!AR21 -> 2573.28 | G16: ='Utility report '!AC16 -> 115 | H16: ='Utility report '!AE16 -> 47 | I16: ='Water-Meter'!E16 -> 112 | J16: ='Lpg (2)'!B20 -> 85 | K16: ='Lpg (2)'!C20 -> 5 | L16: ='Lpg (2)'!D20 -> 72 | M16: ='Lpg (2)'!G20 -> 110.88 | N16: =D16*1.4 -> 3234.266 | O16: =E16*1.4 -> 368.326 | P16: ='[1]Lpg (2)'!#REF! -> #REF! | Q16: ='[1]Summery Report'!#REF! -> #REF! | R16: =N16/B16 -> 92.4076 | S16: =Q16/B16 -> #REF!
A17: =[1]Gen!A22 -> 43750 | B17: ='Summery Report'!E16 -> 32 | C17: ='Daily report Gen'!AA17 -> 503 | D17: =Gen!S22 -> 2429.17 | E17: =Gen!AJ22 -> 309.36 | F17: =Gen!AR22 -> 2738.53 | G17: ='Utility report '!AC17 -> 21 | H17: ='Utility report '!AE17 -> 46 | I17: ='Water-Meter'!E17 -> 128 | J17: ='Lpg (2)'!B21 -> 85 | K17: ='Lpg (2)'!C21 -> 5 | L17: ='Lpg (2)'!D21 -> 68 | M17: ='Lpg (2)'!G21 -> 108.24 | N17: =D17*1.4 -> 3400.838 | O17: =E17*1.4 -> 433.104 | P17: ='[1]Lpg (2)'!#REF! -> #REF! | Q17: ='[1]Summery Report'!#REF! -> #REF! | R17: =N17/B17 -> 106.27619 | S17: =Q17/B17 -> #REF!
A18: =[1]Gen!A23 -> 43751 | B18: ='Summery Report'!E17 -> 30 | C18: ='Daily report Gen'!AA18 -> 498 | D18: =Gen!S23 -> 2249.53 | E18: =Gen!AJ23 -> 63.78 | F18: =Gen!AR23 -> 2313.31 | G18: ='Utility report '!AC18 -> 102 | H18: ='Utility report '!AE18 -> 51 | I18: ='Water-Meter'!E18 -> 114 | J18: ='Lpg (2)'!B22 -> 85 | K18: ='Lpg (2)'!C22 -> 5 | L18: ='Lpg (2)'!D22 -> 65 | M18: ='Lpg (2)'!G22 -> 104.28 | N18: =D18*1.4 -> 3149.342 | O18: =E18*1.4 -> 89.292 | P18: ='[1]Lpg (2)'!#REF! -> #REF! | Q18: ='[1]Summery Report'!#REF! -> #REF! | R18: =N18/B18 -> 104.97807 | S18: =Q18/B18 -> #REF!
... A32: =[1]Gen!A37 -> 43765 | B32: ='Summery Report'!E31 -> 52 | C32: ='Daily report Gen'!AA32 -> 481 | D32: =Gen!S37 -> 2323.74 | E32: =Gen!AJ37 -> 280.63 | F32: =Gen!AR37 -> 2604.37 | G32: ='Utility report '!AC32 -> 117 | H32: ='Utility report '!AE32 -> 30 | I32: ='Water-Meter'!E32 -> 114 | J32: ='Lpg (2)'!B36 -> 80 | K32: ='Lpg (2)'!C36 -> 85 | L32: ='Lpg (2)'!D36 -> 85 | M32: ='Lpg (2)'!G36 -> 115.28 | N32: =D32*1.4 -> 3253.236 | O32: =E32*1.4 -> 392.882 | P32: ='[1]Lpg (2)'!#REF! -> #REF! | Q32: ='[1]Summery Report'!#REF! -> #REF! | R32: =N32/B32 -> 62.562231 | S32: =Q32/B32 -> #REF!
A33: =[1]Gen!A38 -> 43766 | B33: ='Summery Report'!E32 -> 21 | C33: ='Daily report Gen'!AA33 -> 478 | D33: =Gen!S38 -> 2031.83 | E33: =Gen!AJ38 -> 676.29 | F33: =Gen!AR38 -> 2708.12 | G33: ='Utility report '!AC33 -> 118 | H33: ='Utility report '!AE33 -> 44 | I33: ='Water-Meter'!E33 -> 111 | J33: ='Lpg (2)'!B37 -> 78 | K33: ='Lpg (2)'!C37 -> 85 | L33: ='Lpg (2)'!D37 -> 85 | M33: ='Lpg (2)'!G37 -> 110.44 | N33: =D33*1.4 -> 2844.562 | O33: =E33*1.4 -> 946.806 | P33: ='[1]Lpg (2)'!#REF! -> #REF! | Q33: ='[1]Summery Report'!#REF! -> #REF! | R33: =N33/B33 -> 135.45533 | S33: =Q33/B33 -> #REF! | T33: =3124/13 -> 240.30769
A34: =[1]Gen!A39 -> 43767 | B34: ='Summery Report'!E33 -> 32 | C34: ='Daily report Gen'!AA34 -> 405 | D34: =Gen!S39 -> 2131.37 | E34: =Gen!AJ39 -> 120.7 | F34: =Gen!AR39 -> 2252.07 | G34: ='Utility report '!AC34 -> 116 | H34: ='Utility report '!AE34 -> 38 | I34: ='Water-Meter'!E34 -> 100 | J34: ='Lpg (2)'!B38 -> 77 | K34: ='Lpg (2)'!C38 -> 85 | L34: ='Lpg (2)'!D38 -> 85 | M34: ='Lpg (2)'!G38 -> 109.56 | N34: =D34*1.4 -> 2983.918 | O34: =E34*1.4 -> 168.98 | P34: ='[1]Lpg (2)'!#REF! -> #REF! | Q34: ='[1]Summery Report'!#REF! -> #REF! | R34: =N34/B34 -> 93.247437 | S34: =Q34/B34 -> #REF!
A35: =[1]Gen!A40 -> 43768 | B35: ='Summery Report'!E34 -> 32 | C35: ='Daily report Gen'!AA35 -> 417 | D35: =Gen!S40 -> 2033.74 | E35: =Gen!AJ40 -> 25.52 | F35: =Gen!AR40 -> 2059.26 | G35: ='Utility report '!AC35 -> 122 | H35: ='Utility report '!AE35 -> 31 | I35: ='Water-Meter'!E35 -> 99 | J35: ='Lpg (2)'!B39 -> 76 | K35: ='Lpg (2)'!C39 -> 85 | L35: ='Lpg (2)'!D39 -> 85 | M35: ='Lpg (2)'!G39 -> 106.92 | N35: =D35*1.4 -> 2847.236 | O35: =E35*1.4 -> 35.728 | P35: ='[1]Lpg (2)'!#REF! -> #REF! | Q35: ='[1]Summery Report'!#REF! -> #REF! | R35: =N35/B35 -> 88.976125 | S35: =Q35/B35 -> #REF!
A36: =[1]Gen!A41 -> 43769 | B36: ='Summery Report'!E35 -> 25 | C36: ='Daily report Gen'!AA36 -> 430 | D36: =Gen!S41 -> 2126.42 | E36: =Gen!AJ41 -> 533.66 | F36: =Gen!AR41 -> 2660.08 | G36: ='Utility report '!AC36 -> 45 | H36: ='Utility report '!AE36 -> 30 | I36: ='Water-Meter'!E36 -> 111 | J36: ='Lpg (2)'!B40 -> 75 | K36: ='Lpg (2)'!C40 -> 85 | L36: ='Lpg (2)'!D40 -> 85 | M36: ='Lpg (2)'!G40 -> 119.68 | N36: =D36*1.4 -> 2976.988 | O36: =E36*1.4 -> 747.124 | P36: ='[1]Lpg (2)'!#REF! -> #REF! | Q36: ='[1]Summery Report'!#REF! -> #REF! | R36: =N36/B36 -> 119.07952 | S36: =Q36/B36 -> #REF!
A37: =[1]Gen!A42 -> #REF! | B37: ='Summery Report'!E36 -> 0 | D37: =Gen!S42 -> 0 | E37: =Gen!AJ42 -> 0 | F37: =Gen!AR42 -> 0 | G37: ='Utility report '!AC37 -> -15088 | H37: ='Utility report '!AE37 -> -190819 | J37: ='Lpg (2)'!B41 -> 0 | K37: ='Lpg (2)'!C41 -> 0 | L37: ='Lpg (2)'!D41 -> 0 | M37: ='Lpg (2)'!G41 -> -296060.16 | Q37: ='[1]Summery Report'!#REF! -> #REF! | S37: =Q37/B37 -> #REF!
A39: Total | B39: =SUM(B7:B37) -> 1057 | C39: =SUM(C7:C35) -> 13820 | D39: =SUM(D7:D35) -> 67600.34 | E39: =SUM(E7:E35) -> 5969.06 | F39: =SUM(F7:F35) -> 73569.4 | G39: =SUM(G7:G35) -> 2744 | H39: =SUM(H7:H35) -> 1201 | I39: =SUM(I7:I35) -> 3340 | J39: =SUM(J7:J35) -> 2425 | ... S39: =SUM(S7:S35) -> #REF!

Sheet Utility report 
A1: DAILY UTILITY REPORT AUG 2019
A2: Date | B2: Total occupancy | H2: Diesel balance LTS | I2: Diesel Deliveries | J2: Gen.Diesel consumption LTS | L2: Total Diesel consumption LTS | M2: Water Meter reading | N2: Water consumption m³ | O2: R.O WATER PRODUCTION LTRS + TIME | AA2: Total RO production | AB2: RO Meter reading | AD2: 0 | AF2: GAS TANK A | AG2: GAS TANK B | AH2: GAS TANK C | AI2: Total Gas Tanks | AJ2: Kg /day | AK2: TOTAL GAS cons.
A3: Rate Tsh /$ | B3: 1640 | C3: Diesel cost / lits | D3: 2175 | F3: =SUM(D3/B3) -> 1.3262195 | H3: =SUM([1]Gen!C9) -> 35806.65 | K3: Transport consumption | M3: Balance | O3: PLANT NO 1 | S3: PLANT NO 2 | W3: PLANT NO 3 | AA3: /day | AB3: Balance | AC3: Production | AD3: 0 | AE3: Production | AF3: Capacity | AG3: Capacity | AH3: Capacity | AI3: Kg | AJ3: /day | AK3: /day
B4: Rooms OCC | C4: % | D4: Guest Rooms Occ | F4: Electricity Production Cost /Room Occ by guest | G4: All Cost /Room Occ by guest | O4: Flow M3 | P4: Reading Hours Meter | Q4: Hrs | R4: total production M3 | S4: Flow M3 | T4: Reading Hours Meter | U4: Hrs | V4: total production M3 | W4: Flow M3 | Y4: Hrs | Z4: total production M3 | AA4: M3 | AC4: M3 | AE4: M3 | AF4: 2000 | AG4: 1000 | AH4: 1000 | AI4: =SUM([2]Sheet1!$AA$36) -> 950 | AJ4: Kg | AK4: M3
P5: 18502 | T5: 15719 | X5: 20670 | AB5: 12273 | AD5: 189547 | AF5: 0.85 | AG5: 0.85 | AH5: 0.85
A6: =[1]Gen!A11 -> 43739 | B6: ='Summery Report'!E5 -> 48 | C6: =Gen!B11 -> 0.623 | D6: ='Summery Report'!D5 -> 48 | E6: =SUM(F3) -> 1.3262195 | F6: =SUM(J6*E6)/D6 -> 60.218102 | G6: =SUM(L6*E6)/D6 -> 65.834642 | H6: =SUM([1]Gen!C11) -> 47806.65 | I6: =Gen!D11 -> 12000 | J6: =Gen!S11 -> 2179.48 | K6: =Gen!AJ11 -> 203.28 | L6: =SUM(J6:K6) -> 2382.76 | M6: ='Water-Meter'!K46 -> 531.2547 | P6: 18502 | Q6: =SUM(P6-P5) -> 0 | R6: =SUM(Q6*O6) -> 0 | S6: 4.7 | T6: 15719 | U6: =T6-T5 -> 0 | V6: - | W6: 5 | X6: 20685 | Y6: =X6-X5 -> 15 | Z6: =Y6-Y5 -> 15 | AA6: =Z6-Z5 -> 15 | AB6: 12299 | AC6: =AB6-AB5 -> 26 | AD6: 189588 | AE6: =AD6-AD5 -> 41 | AF6: ='Lpg (2)'!B10*2000/85 -> 2000 | AG6: ='Lpg (2)'!C10*1000/85 -> 482.35294 | AH6: ='Lpg (2)'!D10*1000/85 -> 1000 | AI6: =SUM(AF6*2000)+(AG6*1000)+(AH6*1000) -> 5482352.9 | AJ6: =SUM(AI5-AI6) -> -5482352.9
A7: =[1]Gen!A12 -> 43740 | B7: ='Summery Report'!E6 -> 62 | C7: =Gen!B12 -> 0.779 | D7: ='Summery Report'!D6 -> 62 | E7: =SUM(E6) -> 1.3262195 | F7: =SUM(J7*E7)/D7 -> 52.895837 | G7: =SUM(L7*E7)/D7 -> 53.568573 | H7: =Gen!C12 -> 45423.89 | I7: =Gen!D12 -> 0 | J7: =Gen!S12 -> 2472.85 | K7: =Gen!AJ12 -> 31.45 | L7: =SUM(J7:K7) -> 2504.3 | M7: ='Water-Meter'!K47 -> 535.4545 | P7: 18502 | Q7: =SUM(P7-P6) -> 0 | R7: =SUM(Q7*O7) -> 0 | S7: 4.7 | T7: 15719 | U7: =T7-T6 -> 0 | V7: =SUM(U7*S7) -> 0 | X7: 20709 | Y7: =X7-X6 -> 24 | Z7: =SUM(Y7*W7) -> 0 | AA7: =SUM(Z7*X9) -> 0 | AB7: 12476 | AC7: =AB7-AB6 -> 177 | AD7: 189632 | AE7: =AD7-AD6 -> 44 | AF7: ='Lpg (2)'!B11*2000/85 -> 2000 | AG7: ='Lpg (2)'!C11*1000/85 -> 447.05882 | AH7: ='Lpg (2)'!D11*1000/85 -> 1000 | AI7: =SUM(AF6*2000)+(AG7*1000)+(AH7*1000) -> 5447058.8 | AJ7: =SUM(AI6-AI7) -> 35294.118
A8: =[1]Gen!A13 -> 43741 | B8: ='Summery Report'!E7 -> 41 | C8: =Gen!B13 -> 0.532 | D8: ='Summery Report'!D7 -> 41 | E8: =SUM(E7) -> 1.3262195 | F8: =SUM(J8*E8)/D8 -> 82.626387 | G8: =SUM(L8*E8)/D8 -> 86.06356 | H8: =Gen!C13 -> 42919.59 | I8: =Gen!D13 -> 0 | J8: =Gen!S13 -> 2554.39 | K8: =Gen!AJ13 -> 106.26 | L8: =SUM(J8:K8) -> 2660.65 | M8: ='Water-Meter'!K48 -> 481.86559 | P8: 18502 | Q8: =SUM(P8-P7) -> 0 | R8: =SUM(Q8*O8) -> 0 | S8: 4.7 | T8: 15719 | U8: =T8-T7 -> 0 | V8: =SUM(U8*S8) -> 0 | X8: 20734 | Y8: =X8-X7 -> 25 | Z8: =SUM(Y8*W8) -> 0 | AA8: =SUM(Z8*X10) -> 0 | AB8: 12604 | AC8: =AB8-AB7 -> 128 | AD8: 189673 | AE8: =AD8-AD7 -> 41 | AF8: ='Lpg (2)'!B12*2000/85 -> 2000 | AG8: ='Lpg (2)'!C12*1000/85 -> 388.23529 | AH8: ='Lpg (2)'!D12*1000/85 -> 1000 | AI8: =SUM(AF7*2000)+(AG8*1000)+(AH8*1000) -> 5388235.3 | AJ8: =SUM(AI7-AI8) -> 58823.529
A9: =[1]Gen!A14 -> 43742 | B9: ='Summery Report'!E8 -> 47 | C9: =Gen!B14 -> 0.61 | D9: ='Summery Report'!D8 -> 47 | E9: =SUM(E8) -> 1.3262195 | F9: =SUM(J9*E9)/D9 -> 68.890614 | G9: =SUM(L9*E9)/D9 -> 77.138852 | H9: =Gen!C14 -> 40258.94 | I9: =Gen!D14 -> 0 | J9: =Gen!S14 -> 2441.42 | K9: =Gen!AJ14 -> 292.31 | L9: =SUM(J9:K9) -> 2733.73 | M9: ='Water-Meter'!K49 -> 437.09114 | P9: 18502 | Q9: =SUM(P9-P8) -> 0 | R9: =SUM(Q9*O9) -> 0 | S9: 4.7 | T9: 15719 | U9: =T9-T8 -> 0 | V9: =SUM(U9*S9) -> 0 | X9: 20757 | Y9: =X9-X8 -> 23 | Z9: =SUM(Y9*W9) -> 0 | AA9: =SUM(Z9*X11) -> 0 | AB9: 12719 | AC9: =AB9-AB8 -> 115 | AD9: 189742 | AE9: =AD9-AD8 -> 69 | AF9: ='Lpg (2)'!B13*2000/85 -> 2000 | AG9: ='Lpg (2)'!C13*1000/85 -> 341.17647 | AH9: ='Lpg (2)'!D13*1000/85 -> 1000 | AI9: =SUM(AF8*2000)+(AG9*1000)+(AH9*1000) -> 5341176.5 | AJ9: =SUM(AI8-AI9) -> 47058.824
A10: =[1]Gen!A15 -> 43743 | B10: ='Summery Report'!E9 -> 53 | C10: =Gen!B15 -> 0.688 | D10: ='Summery Report'!D9 -> 53 | E10: =SUM(E9) -> 1.3262195 | F10: =SUM(J10*E10)/D10 -> 58.512805 | G10: =SUM(L10*E10)/D10 -> 60.493626 | H10: =Gen!C15 -> 37525.21 | I10: =Gen!D15 -> 0 | J10: =Gen!S15 -> 2338.36 | K10: =Gen!AJ15 -> 79.16 | L10: =SUM(J10:K10) -> 2417.52 | M10: ='Water-Meter'!K50 -> 457.43884 | P10: 18502 | Q10: =SUM(P10-P9) -> 0 | R10: =SUM(Q10*O10) -> 0 | S10: 4.7 | T10: 15719 | U10: =T10-T9 -> 0 | V10: =SUM(U10*S10) -> 0 | W10: 5 | X10: 20776 | Y10: =X10-X9 -> 19 | Z10: =SUM(Y10*W10) -> 95 | AA10: =SUM(Z10*X12) -> 1978280 | AB10: 12805 | AC10: =AB10-AB9 -> 86 | AD10: 189786 | AE10: =AD10-AD9 -> 44 | AF10: ='Lpg (2)'!B14*2000/85 -> 2000 | AG10: ='Lpg (2)'!C14*1000/85 -> 282.35294 | AH10: ='Lpg (2)'!D14*1000/85 -> 1000 | AI10: =SUM(AF9*2000)+(AG10*1000)+(AH10*1000) -> 5282352.9 | AJ10: =SUM(AI9-AI10) -> 58823.529
A11: =[1]Gen!A16 -> 43744 | B11: ='Summery Report'!E10 -> 41 | C11: =Gen!B16 -> 0.532 | D11: ='Summery Report'!D10 -> 41 | E11: =SUM(E10) -> 1.3262195 | F11: =SUM(J11*E11)/D11 -> 80.184526 | G11: =SUM(L11*E11)/D11 -> 83.925435 | H11: =Gen!C16 -> 35107.69 | I11: =Gen!D16 -> 0 | J11: =Gen!S16 -> 2478.9 | K11: =Gen!AJ16 -> 115.65 | L11: =SUM(J11:K11) -> 2594.55 | M11: ='Water-Meter'!K51 -> 440.11465 | P11: 18502 | Q11: =SUM(P11-P10) -> 0 | R11: =SUM(Q11*O11) -> 0 | S11: 4.7 | T11: 15719 | U11: =T11-T10 -> 0 | V11: =SUM(U11*S11) -> 0 | W11: 4.8 | X11: 20801 | Y11: =X11-X10 -> 25 | Z11: =SUM(Y11*W11) -> 120 | AA11: =SUM(Z11*X13) -> 2499240 | AB11: 12919 | AC11: =AB11-AB10 -> 114 | AD11: 189834 | AE11: =AD11-AD10 -> 48 | AF11: ='Lpg (2)'!B15*2000/85 -> 2000 | AG11: ='Lpg (2)'!C15*1000/85 -> 223.52941 | AH11: ='Lpg (2)'!D15*1000/85 -> 1000 | AI11: =SUM(AF10*2000)+(AG11*1000)+(AH11*1000) -> 5223529.4 | AJ11: =SUM(AI10-AI11) -> 58823.529
A12: =[1]Gen!A17 -> 43745 | B12: ='Summery Report'!E11 -> 58 | C12: =Gen!B17 -> 0.753 | D12: ='Summery Report'!D11 -> 58 | E12: =SUM(E11) -> 1.3262195 | F12: =SUM(J12*E12)/D12 -> 52.052744 | G12: =SUM(L12*E12)/D12 -> 53.763338 | H12: =Gen!C17 -> 47513.14 | I12: =Gen!D17 -> 15000 | J12: =Gen!S17 -> 2276.44 | K12: =Gen!AJ17 -> 74.81 | L12: =SUM(J12:K12) -> 2351.25 | M12: ='Water-Meter'!K52 -> 426.40713 | O12: 3.4 | P12: 18502 | Q12: =SUM(P12-P11) -> 0 | R12: =SUM(Q12*O12) -> 0 | S12: 4.7 | T12: 15719 | U12: =T12-T11 -> 0 | V12: =SUM(U12*S12) -> 0 | W12: 5.1 | X12: 20824 | Y12: =X12-X11 -> 23 | Z12: =SUM(Y12*W12) -> 117.3 | AA12: =SUM(Z12*X14) -> 2443007.1 | AB12: 13026 | AC12: =AB12-AB11 -> 107 | AD12: 189879 | AE12: =AD12-AD11 -> 45 | AF12: ='Lpg (2)'!B16*2000/85 -> 2000 | AG12: ='Lpg (2)'!C16*1000/85 -> 176.47059 | AH12: ='Lpg (2)'!D16*1000/85 -> 1000 | AI12: =SUM(AF11*2000)+(AG12*1000)+(AH12*1000) -> 5176470.6 | AJ12: =SUM(AI11-AI12) -> 47058.824
A13: =[1]Gen!A18 -> 43746 | B13: ='Summery Report'!E12 -> 12 | C13: =Gen!B18 -> 0.156 | D13: ='Summery Report'!D12 -> 12 | E13: =SUM(E12) -> 1.3262195 | F13: =SUM(J13*E13)/D13 -> 247.82622 | G13: =SUM(L13*E13)/D13 -> 258.21604 | H13: =Gen!C18 -> 45161.89 | I13: =Gen!D18 -> 0 | J13: =Gen!S18 -> 2242.4 | K13: =Gen!AJ18 -> 94.01 | L13: =SUM(J13:K13) -> 2336.41 | M13: ='Water-Meter'!K53 -> 405.62538 | O13: 2.1 | P13: 18518 | Q13: =SUM(P13-P12) -> 16 | R13: =SUM(Q13*O13) -> 33.6 | S13: 4.7 | T13: 15719 | U13: =T13-T12 -> 0 | V13: =SUM(U13*S13) -> 0 | W13: 5.1 | X13: 20827 | Y13: =X13-X12 -> 3 | Z13: =SUM(Y13*W13) -> 15.3 | AA13: =SUM(Z13*X15) -> 318882.6 | AB13: 13078 | AC13: =AB13-AB12 -> 52 | AD13: 189929 | AE13: =AD13-AD12 -> 50 | AF13: ='Lpg (2)'!B17*2000/85 -> 2000 | AG13: ='Lpg (2)'!C17*1000/85 -> 105.88235 | AH13: ='Lpg (2)'!D17*1000/85 -> 1000 | AI13: =SUM(AF12*2000)+(AG13*1000)+(AH13*1000) -> 5105882.4 | AJ13: =SUM(AI12-AI13) -> 70588.235
A14: =[1]Gen!A19 -> 43747 | B14: ='Summery Report'!E13 -> 34 | C14: =Gen!B19 -> 0.442 | D14: ='Summery Report'!D13 -> 34 | E14: =SUM(E13) -> 1.3262195 | F14: =SUM(J14*E14)/D14 -> 94.79622 | G14: =SUM(L14*E14)/D14 -> 105.90643 | H14: =Gen!C19 -> 42825.48 | I14: =Gen!D19 -> 0 | J14: =Gen!S19 -> 2430.27 | K14: =Gen!AJ19 -> 284.83 | L14: =SUM(J14:K14) -> 2715.1 | M14: ='Water-Meter'!K54 -> 446.72541 | O14: 2.3 | P14: 18532 | Q14: =SUM(P14-P13) -> 14 | R14: =SUM(Q14*O14) -> 32.2 | S14: 4.7 | T14: 15719 | U14: =T14-T13 -> 0 | V14: =SUM(U14*S14) -> 0 | W14: 5.1 | X14: 20827 | Y14: =X14-X13 -> 0 | Z14: =SUM(Y14*W14) -> 0 | AA14: =SUM(Z14*X16) -> 0 | AB14: 13111 | AC14: =AB14-AB13 -> 33 | AD14: 189977 | AE14: =AD14-AD13 -> 48 | AF14: ='Lpg (2)'!B18*2000/85 -> 2000 | AG14: ='Lpg (2)'!C18*1000/85 -> 58.823529 | AH14: ='Lpg (2)'!D18*1000/85 -> 894.11765 | AI14: =SUM(AF13*2000)+(AG14*1000)+(AH14*1000) -> 4952941.2 | AJ14: =SUM(AI13-AI14) -> 152941.18
A15: =[1]Gen!A20 -> 43748 | B15: ='Summery Report'!E14 -> 25 | C15: =Gen!B20 -> 0.325 | D15: ='Summery Report'!D14 -> 25 | E15: =SUM(E14) -> 1.3262195 | F15: =SUM(J15*E15)/D15 -> 130.69999 | G15: =SUM(L15*E15)/D15 -> 136.32529 | H15: =Gen!C20 -> 40110.38 | I15: =Gen!D20 -> 0 | J15: =Gen!S20 -> 2463.77 | K15: =Gen!AJ20 -> 106.04 | L15: =SUM(J15:K15) -> 2569.81 | M15: ='Water-Meter'!K55 -> 451.5578 | O15: 2.3 | P15: 18532 | Q15: =SUM(P15-P14) -> 0 | R15: =SUM(Q15*O15) -> 0 | S15: 4.7 | T15: 15719 | U15: =T15-T14 -> 0 | V15: =SUM(U15*S15) -> 0 | W15: 3.2 | X15: 20842 | Y15: =X15-X14 -> 15 | Z15: =SUM(Y15*W15) -> 48 | AA15: =SUM(Z15*X17) -> 1001760 | AB15: 13193 | AC15: =AB15-AB14 -> 82 | AD15: 190024 | AE15: =AD15-AD14 -> 47 | AF15: ='Lpg (2)'!B19*2000/85 -> 2000 | AG15: ='Lpg (2)'!C19*1000/85 -> 58.823529 | AH15: ='Lpg (2)'!D19*1000/85 -> 870.58824 | AI15: =SUM(AF15*2000)+(AG15*1000)+(AH15*1000) -> 4929411.8 | AJ15: =SUM(AI14-AI15) -> 23529.412
A16: =[1]Gen!A21 -> 43749 | B16: ='Summery Report'!E15 -> 35 | C16: =Gen!B21 -> 0.455 | D16: ='Summery Report'!D15 -> 35 | E16: =SUM(E15) -> 1.3262195 | F16: =SUM(J16*E16)/D16 -> 87.537687 | G16: =SUM(L16*E16)/D16 -> 97.50669 | H16: =Gen!C21 -> 37540.57 | I16: =Gen!D21 -> 0 | J16: =Gen!S21 -> 2310.19 | K16: =Gen!AJ21 -> 263.09 | L16: =SUM(J16:K16) -> 2573.28 | M16: ='Water-Meter'!K56 -> 427.47815 | O16: 2.3 | P16: 18532 | Q16: =SUM(P16-P15) -> 0 | R16: =SUM(Q16*O16) -> 0 | S16: 4.7 | T16: 15719 | U16: =T16-T15 -> 0 | V16: =SUM(U16*S16) -> 0 | W16: 5.1 | X16: 20866 | Y16: =X16-X15 -> 24 | Z16: =SUM(Y16*W16) -> 122.4 | AA16: =SUM(Z16*X18) -> 2557058.4 | AB16: 13308 | AC16: =AB16-AB15 -> 115 | AD16: 190071 | AE16: =AD16-AD15 -> 47 | AF16: ='Lpg (2)'!B20*2000/85 -> 2000 | AG16: ='Lpg (2)'!C20*1000/85 -> 58.823529 | AH16: ='Lpg (2)'!D20*1000/85 -> 847.05882 | AI16: =SUM(AF16*2000)+(AG16*1000)+(AH16*1000) -> 4905882.4 | AJ16: =SUM(AI15-AI16) -> 23529.412
A17: =[1]Gen!A22 -> 43750 | B17: ='Summery Report'!E16 -> 32 | C17: =Gen!B22 -> 0.416 | D17: ='Summery Report'!D16 -> 32 | E17: =SUM(E16) -> 1.3262195 | F17: =SUM(J17*E17)/D17 -> 100.6754 | G17: =SUM(L17*E17)/D17 -> 113.49662 | H17: =Gen!C22 -> 34967.29 | I17: =Gen!D22 -> 0 | J17: =Gen!S22 -> 2429.17 | K17: =Gen!AJ22 -> 309.36 | L17: =SUM(J17:K17) -> 2738.53 | M17: ='Water-Meter'!K57 -> 395.83546 | O17: 2.3 | P17: 18532 | Q17: =SUM(P18-P16) -> 0 | R17: =SUM(Q17*O17) -> 0 | S17: 4.7 | T17: 15719 | U17: =T17-T16 -> 0 | V17: =SUM(U17*S17) -> 0 | W17: 5 | X17: 20870 | Y17: =X17-X16 -> 4 | Z17: =SUM(Y17*W17) -> 20 | AA17: =SUM(Z17*X19) -> 417880 | AB17: 13329 | AC17: =AB17-AB16 -> 21 | AD17: 190117 | AE17: =AD17-AD16 -> 46 | AF17: ='Lpg (2)'!B21*2000/85 -> 2000 | AG17: ='Lpg (2)'!C21*1000/85 -> 58.823529 | AH17: ='Lpg (2)'!D21*1000/85 -> 800 | AI17: =SUM(AF17*2000)+(AG17*1000)+(AH17*1000) -> 4858823.5 | AJ17: =SUM(AI16-AI17) -> 47058.824
A18: =[1]Gen!A23 -> 43751 | B18: ='Summery Report'!E17 -> 30 | C18: =Gen!B23 -> 0.39 | D18: ='Summery Report'!D17 -> 30 | E18: =SUM(E17) -> 1.3262195 | F18: =SUM(J18*E18)/D18 -> 99.445686 | G18: =SUM(L18*E18)/D18 -> 102.26523 | H18: =Gen!C23 -> 32228.76 | I18: =Gen!D23 -> 0 | J18: =Gen!S23 -> 2249.53 | K18: =Gen!AJ23 -> 63.78 | L18: =SUM(J18:K18) -> 2313.31 | M18: ='Water-Meter'!K58 -> 434.03479 | O18: 2.3 | P18: 18532 | R18: =SUM(Q18*O18) -> 0 | S18: 4.7 | T18: 15719 | U18: =T18-T17 -> 0 | V18: =SUM(U18*S18) -> 0 | W18: 5.2 | X18: 20891 | Y18: =X18-X17 -> 21 | Z18: =SUM(Y18*W18) -> 109.2 | AA18: =SUM(Z18*X20) -> 2282716.8 | AB18: 13431 | AC18: =AB18-AB17 -> 102 | AD18: 190168 | AE18: =AD18-AD17 -> 51 | AF18: ='Lpg (2)'!B22*2000/85 -> 2000 | AG18: ='Lpg (2)'!C22*1000/85 -> 58.823529 | AH18: ='Lpg (2)'!D22*1000/85 -> 764.70588 | AI18: =SUM(AF18*2000)+(AG18*1000)+(AH18*1000) -> 4823529.4 | AJ18: =SUM(AI17-AI18) -> 35294.118
A19: =[1]Gen!A24 -> 43752 | B19: ='Summery Report'!E18 -> 49 | C19: =Gen!B24 -> 0.636 | D19: ='Summery Report'!D18 -> 49 | E19: =SUM(E18) -> 1.3262195 | F19: =SUM(J19*E19)/D19 -> 65.619988 | G19: =SUM(L19*E19)/D19 -> 72.299804 | H19: =Gen!C24 -> 29915.45 | I19: =Gen!D24 -> 0 | J19: =Gen!S24 -> 2424.47 | K19: =Gen!AJ24 -> 246.8 | L19: =SUM(J19:K19) -> 2671.27 | M19: ='Water-Meter'!K59 -> 491.18387 | O19: 2.3 | P19: 18532 | R19: =SUM(Q19*O19) -> 0 | S19: 4.7 | T19: 15719 | U19: =T19-T18 -> 0 | V19: =SUM(U19*S19) -> 0 | W19: 5.2 | X19: 20894 | Y19: =X19-X18 -> 3 | Z19: =SUM(Y19*W19) -> 15.6 | AA19: =SUM(Z19*X21) -> 326476.8 | AB19: 13444 | AC19: =AB19-AB18 -> 13 | AD19: 190218 | AE19: =AD19-AD18 -> 50 | AF19: ='Lpg (2)'!B23*2000/85 -> 2000 | AG19: ='Lpg (2)'!C23*1000/85 -> 58.823529 | AH19: ='Lpg (2)'!D23*1000/85 -> 682.35294 | AI19: =SUM(AF19*2000)+(AG19*1000)+(AH19*1000) -> 4741176.5 | AJ19: =SUM(AI18-AI19) -> 82352.941
A20: =[1]Gen!A25 -> 43753 | B20: ='Summery Report'!E19 -> 66 | C20: =Gen!B25 -> 0.844 | D20: ='Summery Report'!D19 -> 66 | E20: =SUM(E19) -> 1.3262195 | F20: =SUM(J20*E20)/D20 -> 53.698025 | G20: =SUM(L20*E20)/D20 -> 55.316817 | H20: =Gen!C25 -> 42244.18 | I20: =Gen!D25 -> 15000 | J20: =Gen!S25 -> 2672.31 | K20: =Gen!AJ25 -> 80.56 | L20: =SUM(J20:K20) -> 2752.87 | M20: ='Water-Meter'!K60 -> 505.79747 | O20: 2.3 | P20: 18532 | Q20: =SUM(P20-P19) -> 0 | R20: =SUM(Q20*O20) -> 0 | S20: 4.7 | T20: 15719 | U20: =T20-T19 -> 0 | V20: =SUM(U20*S20) -> 0 | W20: 5.4 | X20: 20904 | Y20: =X20-X19 -> 10 | Z20: =SUM(Y20*W20) -> 54 | AA20: =SUM(Z20*X22) -> 1130922 | AB20: 13492 | AC20: =AB20-AB19 -> 48 | AD20: 190269 | AE20: =AD20-AD19 -> 51 | AF20: ='Lpg (2)'!B24*2000/85 -> 2000 | AG20: ='Lpg (2)'!C24*1000/85 -> 58.823529 | AH20: ='Lpg (2)'!D24*1000/85 -> 623.52941 | AI20: =SUM(AF20*2000)+(AG20*1000)+(AH20*1000) -> 4682352.9 | AJ20: =SUM(AI19-AI20) -> 58823.529
A21: =[1]Gen!A26 -> 43754 | B21: ='Summery Report'!E20 -> 63 | C21: =Gen!B26 -> 0.818 | D21: ='Summery Report'!D20 -> 63 | E21: =SUM(E20) -> 1.3262195 | F21: =SUM(J21*E21)/D21 -> 57.71581 | G21: =SUM(L21*E21)/D21 -> 59.13297 | H21: =Gen!C26 -> 39491.31 | I21: =Gen!D26 -> 0 | J21: =Gen!S26 -> 2741.7 | K21: =Gen!AJ26 -> 67.32 | L21: =SUM(J21:K21) -> 2809.02 | M21: ='Water-Meter'!K61 -> 466.71867 | O21: 2.3 | P21: 18532 | Q21: =SUM(P21-P20) -> 0 | R21: =SUM(Q21*O21) -> 0 | S21: 4.7 | T21: 15719 | U21: =T21-T20 -> 0 | V21: =SUM(U21*S21) -> 0 | W21: 4.9 | X21: 20928 | Y21: =X21-X20 -> 24 | Z21: =SUM(Y21*W21) -> 117.6 | AA21: =SUM(Z21*X23) -> 2465484 | AB21: 13611 | AC21: =AB21-AB20 -> 119 | AD21: 190318 | AE21: =AD21-AD20 -> 49 | AF21: ='Lpg (2)'!B25*2000/85 -> 2000 | AG21: ='Lpg (2)'!C25*1000/85 -> 58.823529 | AH21: ='Lpg (2)'!D25*1000/85 -> 564.70588 | AI21: =SUM(AF21*2000)+(AG21*1000)+(AH21*1000) -> 4623529.4 | AJ21: =SUM(AI20-AI21) -> 58823.529
A22: =[1]Gen!A27 -> 43755 | B22: ='Summery Report'!E21 -> 16 | C22: =Gen!B27 -> 0.208 | D22: ='Summery Report'!D21 -> 16 | E22: =SUM(E21) -> 1.3262195 | F22: =SUM(J22*E22)/D22 -> 192.39384 | G22: =SUM(L22*E22)/D22 -> 241.953 | H22: =Gen!C27 -> 36682.29 | I22: =Gen!D27 -> 0 | J22: =Gen!S27 -> 2321.11 | K22: =Gen!AJ27 -> 597.9 | L22: =SUM(J22:K22) -> 2919.01 | M22: ='Water-Meter'!K62 -> 489.58383 | O22: 2.3 | P22: 18532 | Q22: =SUM(P22-P21) -> 0 | R22: =SUM(Q22*O22) -> 0 | S22: 4.7 | T22: 15719 | U22: =T22-T21 -> 0 | V22: =SUM(U22*S22) -> 0 | W22: 5.3 | X22: 20943 | Y22: =X22-X21 -> 15 | Z22: =SUM(Y22*W22) -> 79.5 | AA22: =SUM(Z22*X24) -> 1666717.5 | AB22: 13681 | AC22: =AB22-AB21 -> 70 | AD22: 190359 | AE22: =AD22-AD21 -> 41 | AF22: ='Lpg (2)'!B26*2000/85 -> 2000 | AG22: ='Lpg (2)'!C26*1000/85 -> 58.823529 | AH22: ='Lpg (2)'!D26*1000/85 -> 517.64706 | AI22: =SUM(AF22*2000)+(AG22*1000)+(AH22*1000) -> 4576470.6 | AJ22: =SUM(AI21-AI22) -> 47058.824
A23: =[1]Gen!A28 -> 43756 | B23: ='Summery Report'!E22 -> 17 | C23: =Gen!B28 -> 0.221 | D23: ='Summery Report'!D22 -> 17 | E23: =SUM(E22) -> 1.3262195 | F23: =SUM(J23*E23)/D23 -> 172.00599 | G23: =SUM(L23*E23)/D23 -> 189.77187 | H23: =Gen!C28 -> 33763.28 | I23: =Gen!D28 -> 0 | J23: =Gen!S28 -> 2204.84 | K23: =Gen!AJ28 -> 227.73 | L23: =SUM(J23:K23) -> 2432.57 | M23: ='Water-Meter'!K63 -> 511.7188 | O23: 2.3 | P23: 18532 | Q23: =SUM(P23-P22) -> 0 | R23: =SUM(Q23*O23) -> 0 | S23: 4.7 | T23: 15719 | U23: =T23-T22 -> 0 | V23: =SUM(U23*S23) -> 0 | W23: 5.3 | X23: 20965 | Y23: =X23-X22 -> 22 | Z23: =SUM(Y23*W23) -> 116.6 | AA23: =SUM(Z23*X25) -> 2449882.6 | AB23: 13790 | AC23: =AB23-AB22 -> 109 | AD23: 190369 | AE23: =AD23-AD22 -> 10 | AF23: ='Lpg (2)'!B27*2000/85 -> 2000 | AG23: ='Lpg (2)'!C27*1000/85 -> 58.823529 | AH23: ='Lpg (2)'!D27*1000/85 -> 458.82353 | AI23: =SUM(AF23*2000)+(AG23*1000)+(AH23*1000) -> 4517647.1 | AJ23: =SUM(AI22-AI23) -> 58823.529
A24: =[1]Gen!A29 -> 43757 | B24: ='Summery Report'!E23 -> 9 | C24: =Gen!B29 -> 0.117 | D24: ='Summery Report'!D23 -> 9 | E24: =SUM(E23) -> 1.3262195 | F24: =SUM(J24*E24)/D24 -> 271.90152 | G24: =SUM(L24*E24)/D24 -> 284.91174 | H24: =Gen!C29 -> 31330.71 | I24: =Gen!D29 -> 0 | J24: =Gen!S29 -> 1845.18 | K24: =Gen!AJ29 -> 88.29 | L24: =SUM(J24:K24) -> 1933.47 | M24: ='Water-Meter'!K64 -> 514.91402 | O24: 2.3 | P24: 18532 | Q24: =SUM(P24-P23) -> 0 | R24: =SUM(Q24*O24) -> 0 | S24: 4.7 | T24: 15719 | U24: =T24-T23 -> 0 | V24: =SUM(U24*S24) -> 0 | W24: 5 | X24: 20965 | Y24: =X24-X23 -> 0 | Z24: =SUM(Y24*W24) -> 0 | AA24: =SUM(Z24*X26) -> 0 | AB24: 13899 | AC24: =AB24-AB23 -> 109 | AD24: 190376 | AE24: =AD24-AD23 -> 7 | AF24: ='Lpg (2)'!B28*2000/85 -> 2000 | AG24: ='Lpg (2)'!C28*1000/85 -> 58.823529 | AH24: ='Lpg (2)'!D28*1000/85 -> 411.76471 | AI24: =SUM(AF24*2000)+(AG24*1000)+(AH24*1000) -> 4470588.2 | AJ24: =SUM(AI23-AI24) -> 47058.824
A25: =[1]Gen!A30 -> 43758 | B25: ='Summery Report'!E24 -> 44 | C25: =Gen!B30 -> 0.571 | D25: ='Summery Report'!D24 -> 44 | E25: =SUM(E24) -> 1.3262195 | F25: =SUM(J25*E25)/D25 -> 84.305664 | G25: =SUM(L25*E25)/D25 -> 89.849262 | H25: =Gen!C30 -> 29397.24 | I25: =Gen!D30 -> 0 | J25: =Gen!S30 -> 2797.01 | K25: =Gen!AJ30 -> 183.92 | L25: =SUM(J25:K25) -> 2980.93 | M25: ='Water-Meter'!K65 -> 534.97374 | O25: 2.3 | P25: 18532 | Q25: =SUM(P25-P24) -> 0 | R25: =SUM(Q25*O25) -> 0 | S25: 4.7 | T25: 15719 | U25: =T25-T24 -> 0 | V25: =SUM(U25*S25) -> 0 | W25: 5 | X25: 21011 | Y25: =X25-X24 -> 46 | Z25: =SUM(Y25*W25) -> 230 | AA25: =SUM(Z25*X27) -> 4842190 | AB25: 14008 | AC25: =AB25-AB24 -> 109 | AD25: 190426 | AE25: =AD25-AD24 -> 50 | AF25: ='Lpg (2)'!B29*2000/85 -> 2000 | AG25: ='Lpg (2)'!C29*1000/85 -> 58.823529 | AH25: ='Lpg (2)'!D29*1000/85 -> 341.17647 | AI25: =SUM(AF25*2000)+(AG25*1000)+(AH25*1000) -> 4400000 | AJ25: =SUM(AI24-AI25) -> 70588.235
A26: =[1]Gen!A31 -> 43759 | B26: ='Summery Report'!E25 -> 43 | C26: =Gen!B31 -> 0.558 | D26: ='Summery Report'!D25 -> 43 | E26: =SUM(E25) -> 1.3262195 | F26: =SUM(J26*E26)/D26 -> 69.77025 | G26: =SUM(L26*E26)/D26 -> 75.07667 | H26: =Gen!C31 -> 41416.31 | I26: =Gen!D31 -> 15000 | J26: =Gen!S31 -> 2262.16 | K26: =Gen!AJ31 -> 172.05 | L26: =SUM(J26:K26) -> 2434.21 | M26: ='Water-Meter'!K66 -> 501.4901 | O26: 2.3 | P26: 18532 | Q26: =SUM(P26-P25) -> 0 | R26: =SUM(Q26*O26) -> 0 | S26: 4.7 | T26: 15719 | U26: =T26-T25 -> 0 | V26: =SUM(U26*S26) -> 0 | W26: 5 | X26: 21036 | Y26: =X26-X25 -> 25 | Z26: =SUM(Y26*W26) -> 125 | AA26: =SUM(Z26*X28) -> 2633375 | AB26: 14121 | AC26: =AB26-AB25 -> 113 | AD26: 190475 | AE26: =AD26-AD25 -> 49 | AF26: ='Lpg (2)'!B30*2000/85 -> 2000 | AG26: ='Lpg (2)'!C30*1000/85 -> 58.823529 | AH26: ='Lpg (2)'!D30*1000/85 -> 282.35294 | AI26: =SUM(AF26*2000)+(AG26*1000)+(AH26*1000) -> 4341176.5 | AJ26: =SUM(AI25-AI26) -> 58823.529
A27: =[1]Gen!A32 -> 43760 | B27: ='Summery Report'!E26 -> 31 | C27: =Gen!B32 -> 0.403 | D27: ='Summery Report'!D26 -> 31 | E27: =SUM(E26) -> 1.3262195 | F27: =SUM(J27*E27)/D27 -> 97.834786 | G27: =SUM(L27*E27)/D27 -> 98.631801 | H27: =Gen!C32 -> 38982.1 | I27: =Gen!D32 -> 0 | J27: =Gen!S32 -> 2286.86 | K27: =Gen!AJ32 -> 18.63 | L27: =SUM(J27:K27) -> 2305.49 | M27: ='Water-Meter'!K67 -> 596.98933 | O27: 2.3 | P27: 18537 | Q27: =SUM(P27-P26) -> 5 | R27: =SUM(Q27*O27) -> 11.5 | S27: 4.7 | T27: 15719 | U27: =T27-T26 -> 0 | V27: =SUM(U27*S27) -> 0 | W27: 5 | X27: 21053 | Y27: =X27-X26 -> 17 | Z27: =SUM(Y27*W27) -> 85 | AA27: =SUM(Z27*X29) -> 1792650 | AB27: 14208 | AC27: =AB27-AB26 -> 87 | AD27: 190505 | AE27: =AD27-AD26 -> 30 | AF27: ='Lpg (2)'!B31*2000/85 -> 2000 | AG27: ='Lpg (2)'!C31*1000/85 -> 1000 | AH27: ='Lpg (2)'!D31*1000/85 -> 1000 | AI27: =SUM(AF27*2000)+(AG27*1000)+(AH27*1000) -> 6000000 | AJ27: =SUM(AI26-AI27) -> -1658823.5
