Workbook
Name _IV99999: [1]Water!$IB$30257

Sheet Total
A1: Site Name | B1: Day | C1: Month | D1: Year | E1: Total Electricity Kwh | F1: Electricity Tariff ($/Kwh) | G1: Natual Gas (m3) | H1: Natural Gas $/m3 | I1: Water Utility Supply (m3) m3 | J1: Water Utility Supply (m3) $/m3 | K1: Room Nights
A2: Cairo at The First Residence | B2: 1 | C2: 11 | D2: 2019 | E2: =Elect!BL6 -> 27326.036 | F2: 1.15 | G2: =Gas!K7 -> 52933.9 | H2: 3.8 | I2: =Water!H7 -> 193.72 | J2: 10 | K2: =Elect!BM6 -> 244
A3: Cairo at The First Residence | B3: =B2+1 -> 2 | C3: 11 | D3: 2019 | E3: =Elect!BL7 -> 30676.86 | F3: 1.15 | G3: =Gas!K8 -> 17968.7 | H3: 3.8 | I3: =Water!H8 -> 302.76 | J3: 10 | K3: =Elect!BM7 -> 230
A4: Cairo at The First Residence | B4: =B3+1 -> 3 | C4: 11 | D4: 2019 | E4: =Elect!BL8 -> 33350.76 | F4: 1.15 | G4: =Gas!K9 -> 18178.7 | H4: 3.8 | I4: =Water!H9 -> 350.9 | J4: 10 | K4: =Elect!BM8 -> 252
A5: Cairo at The First Residence | B5: =B4+1 -> 4 | C5: 11 | D5: 2019 | E5: =Elect!BL9 -> 31544.6 | F5: 1.15 | G5: =Gas!K10 -> 17968.7 | H5: 3.8 | I5: =Water!H10 -> 175.74 | J5: 10 | K5: =Elect!BM9 -> 243
A6: Cairo at The First Residence | B6: =B5+1 -> 5 | C6: 11 | D6: 2019 | E6: =Elect!BL10 -> 31623.31 | F6: 1.15 | G6: =Gas!K11 -> 17919.7 | H6: 3.8 | I6: =Water!H11 -> 188.5 | J6: 10 | K6: =Elect!BM10 -> 248
A7: Cairo at The First Residence | B7: =B6+1 -> 6 | C7: 11 | D7: 2019 | E7: =Elect!BL11 -> 31949.8 | F7: 1.15 | G7: =Gas!K12 -> 1749.54 | H7: 3.8 | I7: =Water!H12 -> 156.6 | J7: 10 | K7: =Elect!BM11 -> 249
A8: Cairo at The First Residence | B8: =B7+1 -> 7 | C8: 11 | D8: 2019 | E8: =Elect!BL12 -> 33054 | F8: 1.15 | G8: =Gas!K13 -> 2040.7 | H8: 3.8 | I8: =Water!H13 -> 182.12 | J8: 10 | K8: =Elect!BM12 -> 223
A9: Cairo at The First Residence | B9: =B8+1 -> 8 | C9: 11 | D9: 2019 | E9: =Elect!BL13 -> 33110.82 | F9: 1.15 | G9: =Gas!K14 -> 1532.1 | H9: 3.8 | I9: =Water!H14 -> 163.56 | J9: 10 | K9: =Elect!BM13 -> 235
A10: Cairo at The First Residence | B10: =B9+1 -> 9 | C10: 11 | D10: 2019 | E10: =Elect!BL14 -> 33250.73 | F10: 1.15 | G10: =Gas!K15 -> 1907.6 | H10: 3.8 | I10: =Water!H15 -> 198.94 | J10: 10 | K10: =Elect!BM14 -> 231
A11: Cairo at The First Residence | B11: =B10+1 -> 10 | C11: 11 | D11: 2019 | E11: =Elect!BL15 -> 33132.51 | F11: 1.15 | G11: =Gas!K16 -> 1554.48 | H11: 3.8 | I11: =Water!H16 -> 262.74 | J11: 10 | K11: =Elect!BM15 -> 225
A12: Cairo at The First Residence | B12: =B11+1 -> 11 | C12: 11 | D12: 2019 | E12: =Elect!BL16 -> 31634.9 | F12: 1.15 | G12: =Gas!K17 -> 0 | H12: 3.8 | I12: =Water!H17 -> 179.8 | J12: 10 | K12: =Elect!BM16 -> 173
A13: Cairo at The First Residence | B13: =B12+1 -> 12 | C13: 11 | D13: 2019 | E13: =Elect!BL17 -> 0 | F13: 1.15 | G13: =Gas!K18 -> 0 | H13: 3.8 | I13: =Water!H18 -> 209.96 | J13: 10 | K13: =Elect!BM17 -> 0
A14: Cairo at The First Residence | B14: =B13+1 -> 13 | C14: 11 | D14: 2019 | E14: =Elect!BL18 -> 0 | F14: 1.15 | G14: =Gas!K19 -> 0 | H14: 3.8 | I14: =Water!H19 -> 0 | J14: 10 | K14: =Elect!BM18 -> 0
... A32: Cairo at The First Residence | B32: =B31+1 -> 31 | C32: 11 | D32: 2019 | E32: =Elect!BL36 -> 0 | F32: 1.15 | G32: =Gas!K37 -> 0 | H32: 3.8 | I32: =Water!H37 -> 0 | J32: 10 | K32: =Elect!BM36 -> 0

Sheet Submetering
A1: Site Name | B1: Day | C1: Month | D1: Year | E1: Electricity | F1: Main Feeder -KWh | G1: T2+T8 -KWh | H1: La Gourmandize -KWh | I1: Casino 3rd floor EM -KWh | J1: Casino 3rd floor Normal -KWh | K1: Chiller 1 -KWh | L1: Chiller 2 -KWh | M1: Chiller 3 -KWh | N1: Chiller 4 -KWh | O1: Cooling towers -KWh | P1: Chiller Pumps -KWh | Q1: LG Bakery -KWh | R1: Mall Ceiling light -KWh | S1: New chiller for Second floor -KWh | T1: LG Bakery light ( Old lockers ) -KWh | U1: MCCR1 -KWh | V1: Children Swimming pool -KWh | W1: DPH1 -KWh | X1: Main G2 -KWh | Y1: Casino Emergency -KWh | Z1: L / A -KWh | AA1: L / B -KWh | AB1: L / C -KWh | AC1: Water | AD1: Main water meter 1 -m3 | AE1: Main water meter 2 -m3 | AF1: Main water meter 3 -m3 | AG1: Gas | AH1: Main Gas Flow Meter -m3 | AI1: Laundry Gas Flow Meter -m3 | AJ1: Gourmandize Gas Flow Meter -m3 | AK1: Room Nights
A2: Cairo at The First Residence | B2: 1 | C2: 11 | D2: 2019 | F2: =Elect!J6 -> 5546 | G2: =Elect!K6 -> 3765 | H2: =Elect!Q6 -> 810 | I2: =Elect!W6 -> 181 | J2: =Elect!Y6 -> 200 | K2: =Elect!AA6 -> 0 | L2: =Elect!AC6 -> 518.87 | M2: =Elect!AE6 -> 3965.46 | N2: =Elect!AG6 -> 0 | O2: =Elect!AI6 -> 560.21 | P2: =Elect!AK6 -> 1168.65 | Q2: =Elect!AN6 -> 1241 | R2: =Elect!AP6 -> 360 | S2: =Elect!AR6 -> 30.69 | T2: =Elect!AT6 -> 215 | U2: =Elect!AV6 -> 646 | V2: =Elect!AX6 -> 47.256062 | W2: =Elect!AZ6 -> 5588 | X2: =Elect!BB6 -> 6628.9 | Y2: =Elect!BE6 -> 0 | Z2: =Elect!BG6 -> 1556 | AA2: =Elect!BI6 -> 65 | AB2: =Elect!BK6 -> 195 | AD2: =Water!C7 -> 191.4 | AE2: =Water!E7 -> 0 | AF2: =Water!G7 -> 2.32 | AH2: =Gas!C7 -> 52671.4 | AI2: =Gas!E7 -> 262.5 | AJ2: =Gas!G7 -> 83 | AK2: =Elect!BM6 -> 244
A3: Cairo at The First Residence | B3: =B2+1 -> 2 | C3: 11 | D3: 2019 | F3: =Elect!J7 -> 6508 | G3: =Elect!K7 -> 4025 | H3: =Elect!Q7 -> 780 | I3: =Elect!W7 -> 145 | J3: =Elect!Y7 -> 232 | K3: =Elect!AA7 -> 0 | L3: =Elect!AC7 -> 1754.3 | M3: =Elect!AE7 -> 3907.16 | N3: =Elect!AG7 -> 0 | O3: =Elect!AI7 -> 497.14 | P3: =Elect!AK7 -> 2570.5 | Q3: =Elect!AN7 -> 1096 | R3: =Elect!AP7 -> 274 | S3: =Elect!AR7 -> 36.96 | T3: =Elect!AT7 -> 256 | U3: =Elect!AV7 -> 893 | V3: =Elect!AX7 -> 67 | W3: =Elect!AZ7 -> 6409 | X3: =Elect!BB7 -> 5627.8 | Y3: =Elect!BE7 -> 0 | Z3: =Elect!BG7 -> 1287 | AA3: =Elect!BI7 -> 94 | AB3: =Elect!BK7 -> 170 | AD3: =Water!C8 -> 301.6 | AE3: =Water!E8 -> 0 | AF3: =Water!G8 -> 1.16 | AH3: =Gas!C8 -> 17776.2 | AI3: =Gas!E8 -> 192.5 | AJ3: =Gas!G8 -> 83 | AK3: =Elect!BM7 -> 230
A4: Cairo at The First Residence | B4: =B3+1 -> 3 | C4: 11 | D4: 2019 | F4: =Elect!J8 -> 6603 | G4: =Elect!K8 -> 4233 | H4: =Elect!Q8 -> 780 | I4: =Elect!W8 -> 147 | J4: =Elect!Y8 -> 227 | K4: =Elect!AA8 -> 0 | L4: =Elect!AC8 -> 3999.38 | M4: =Elect!AE8 -> 2526.51 | N4: =Elect!AG8 -> 0 | O4: =Elect!AI8 -> 520.46 | P4: =Elect!AK8 -> 2820.66 | Q4: =Elect!AN8 -> 1559 | R4: =Elect!AP8 -> 277 | S4: =Elect!AR8 -> 42.35 | T4: =Elect!AT8 -> 261 | U4: =Elect!AV8 -> 1016 | V4: =Elect!AX8 -> 67 | W4: =Elect!AZ8 -> 6681 | X4: =Elect!BB8 -> 6197.4 | Y4: =Elect!BE8 -> 0 | Z4: =Elect!BG8 -> 1376 | AA4: =Elect!BI8 -> 98 | AB4: =Elect!BK8 -> 184 | AD4: =Water!C9 -> 348 | AE4: =Water!E9 -> 0 | AF4: =Water!G9 -> 2.9 | AH4: =Gas!C9 -> 17776.2 | AI4: =Gas!E9 -> 402.5 | AJ4: =Gas!G9 -> 83 | AK4: =Elect!BM8 -> 252
A5: Cairo at The First Residence | B5: =B4+1 -> 4 | C5: 11 | D5: 2019 | F5: =Elect!J9 -> 6318 | G5: =Elect!K9 -> 3858 | H5: =Elect!Q9 -> 810 | I5: =Elect!W9 -> 142 | J5: =Elect!Y9 -> 221 | K5: =Elect!AA9 -> 0 | L5: =Elect!AC9 -> 2162.4 | M5: =Elect!AE9 -> 3657 | N5: =Elect!AG9 -> 0 | O5: =Elect!AI9 -> 516.22 | P5: =Elect!AK9 -> 2670.14 | Q5: =Elect!AN9 -> 1784 | R5: =Elect!AP9 -> 272 | S5: =Elect!AR9 -> 36.74 | T5: =Elect!AT9 -> 253 | U5: =Elect!AV9 -> 965 | V5: =Elect!AX9 -> 66 | W5: =Elect!AZ9 -> 6211 | X5: =Elect!BB9 -> 5823.1 | Y5: =Elect!BE9 -> 0 | Z5: =Elect!BG9 -> 1274 | AA5: =Elect!BI9 -> 89 | AB5: =Elect!BK9 -> 172 | AD5: =Water!C10 -> 174 | AE5: =Water!E10 -> 0 | AF5: =Water!G10 -> 1.74 | AH5: =Gas!C10 -> 17776.2 | AI5: =Gas!E10 -> 192.5 | AJ5: =Gas!G10 -> 83 | AK5: =Elect!BM9 -> 243
A6: Cairo at The First Residence | B6: =B5+1 -> 5 | C6: 11 | D6: 2019 | F6: =Elect!J10 -> 6001 | G6: =Elect!K10 -> 3791 | H6: =Elect!Q10 -> 720 | I6: =Elect!W10 -> 145 | J6: =Elect!Y10 -> 227 | K6: =Elect!AA10 -> 0 | L6: =Elect!AC10 -> 3764.06 | M6: =Elect!AE10 -> 2410.97 | N6: =Elect!AG10 -> 0 | O6: =Elect!AI10 -> 548.55 | P6: =Elect!AK10 -> 2714.66 | Q6: =Elect!AN10 -> 1825 | R6: =Elect!AP10 -> 266 | S6: =Elect!AR10 -> 39.27 | T6: =Elect!AT10 -> 230 | U6: =Elect!AV10 -> 967 | V6: =Elect!AX10 -> 69 | W6: =Elect!AZ10 -> 6312 | X6: =Elect!BB10 -> 5755.8 | Y6: =Elect!BE10 -> 0 | Z6: =Elect!BG10 -> 1317 | AA6: =Elect!BI10 -> 92 | AB6: =Elect!BK10 -> 177 | AD6: =Water!C11 -> 185.6 | AE6: =Water!E11 -> 0 | AF6: =Water!G11 -> 2.9 | AH6: =Gas!C11 -> 17776.2 | AI6: =Gas!E11 -> 143.5 | AJ6: =Gas!G11 -> 123 | AK6: =Elect!BM10 -> 248
A7: Cairo at The First Residence | B7: =B6+1 -> 6 | C7: 11 | D7: 2019 | F7: =Elect!J11 -> 6229 | G7: =Elect!K11 -> 3847 | H7: =Elect!Q11 -> 840 | I7: =Elect!W11 -> 142 | J7: =Elect!Y11 -> 227 | K7: =Elect!AA11 -> 0 | L7: =Elect!AC11 -> 3758.76 | M7: =Elect!AE11 -> 2607.6 | N7: =Elect!AG11 -> 0 | O7: =Elect!AI11 -> 623.28 | P7: =Elect!AK11 -> 2698.76 | Q7: =Elect!AN11 -> 1733 | R7: =Elect!AP11 -> 253 | S7: =Elect!AR11 -> 39.6 | T7: =Elect!AT11 -> 251 | U7: =Elect!AV11 -> 949 | V7: =Elect!AX11 -> 69 | W7: =Elect!AZ11 -> 6355 | X7: =Elect!BB11 -> 5542.8 | Y7: =Elect!BE11 -> 0 | Z7: =Elect!BG11 -> 1222 | AA7: =Elect!BI11 -> 84 | AB7: =Elect!BK11 -> 168 | AD7: =Water!C12 -> 156.6 | AE7: =Water!E12 -> 0 | AF7: =Water!G12 -> 0 | AH7: =Gas!C12 -> 1583.64 | AI7: =Gas!E12 -> 165.9 | AJ7: =Gas!G12 -> 69 | AK7: =Elect!BM11 -> 249
A8: Cairo at The First Residence | B8: =B7+1 -> 7 | C8: 11 | D8: 2019 | F8: =Elect!J12 -> 6417 | G8: =Elect!K12 -> 3969 | H8: =Elect!Q12 -> 780 | I8: =Elect!W12 -> 146 | J8: =Elect!Y12 -> 219 | K8: =Elect!AA12 -> 0 | L8: =Elect!AC12 -> 2892.74 | M8: =Elect!AE12 -> 3838.79 | N8: =Elect!AG12 -> 0 | O8: =Elect!AI12 -> 828.39 | P8: =Elect!AK12 -> 3037.96 | Q8: =Elect!AN12 -> 1553 | R8: =Elect!AP12 -> 261 | S8: =Elect!AR12 -> 43.12 | T8: =Elect!AT12 -> 249 | U8: =Elect!AV12 -> 958 | V8: =Elect!AX12 -> 69 | W8: =Elect!AZ12 -> 6250 | X8: =Elect!BB12 -> 5876 | Y8: =Elect!BE12 -> 0 | Z8: =Elect!BG12 -> 1360 | AA8: =Elect!BI12 -> 86 | AB8: =Elect!BK12 -> 135 | AD8: =Water!C13 -> 179.8 | AE8: =Water!E13 -> 0 | AF8: =Water!G13 -> 2.32 | AH8: =Gas!C13 -> 1839.1 | AI8: =Gas!E13 -> 201.6 | AJ8: =Gas!G13 -> 95 | AK8: =Elect!BM12 -> 223
A9: Cairo at The First Residence | B9: =B8+1 -> 8 | C9: 11 | D9: 2019 | F9: =Elect!J13 -> 6335 | G9: =Elect!K13 -> 3899 | H9: =Elect!Q13 -> 780 | I9: =Elect!W13 -> 143 | J9: =Elect!Y13 -> 234 | K9: =Elect!AA13 -> 0 | L9: =Elect!AC13 -> 3502.77 | M9: =Elect!AE13 -> 3723.78 | N9: =Elect!AG13 -> 0 | O9: =Elect!AI13 -> 668.33 | P9: =Elect!AK13 -> 3078.77 | Q9: =Elect!AN13 -> 1722 | R9: =Elect!AP13 -> 258 | S9: =Elect!AR13 -> 39.27 | T9: =Elect!AT13 -> 228 | U9: =Elect!AV13 -> 959 | V9: =Elect!AX13 -> 68 | W9: =Elect!AZ13 -> 6226 | X9: =Elect!BB13 -> 5521.9 | Y9: =Elect!BE13 -> 0 | Z9: =Elect!BG13 -> 1241 | AA9: =Elect!BI13 -> 89 | AB9: =Elect!BK13 -> 212 | AD9: =Water!C14 -> 162.4 | AE9: =Water!E14 -> 0 | AF9: =Water!G14 -> 1.16 | AH9: =Gas!C14 -> 1203.1 | AI9: =Gas!E14 -> 329 | AJ9: =Gas!G14 -> 85 | AK9: =Elect!BM13 -> 235
A10: Cairo at The First Residence | B10: =B9+1 -> 9 | C10: 11 | D10: 2019 | F10: =Elect!J14 -> 6566 | G10: =Elect!K14 -> 5112 | H10: =Elect!Q14 -> 660 | I10: =Elect!W14 -> 146 | J10: =Elect!Y14 -> 236 | K10: =Elect!AA14 -> 0 | L10: =Elect!AC14 -> 3356.49 | M10: =Elect!AE14 -> 3458.78 | N10: =Elect!AG14 -> 0 | O10: =Elect!AI14 -> 660.91 | P10: =Elect!AK14 -> 3366.56 | Q10: =Elect!AN14 -> 1708 | R10: =Elect!AP14 -> 275 | S10: =Elect!AR14 -> 40.59 | T10: =Elect!AT14 -> 227 | U10: =Elect!AV14 -> 870 | V10: =Elect!AX14 -> 69 | W10: =Elect!AZ14 -> 6195 | X10: =Elect!BB14 -> 5797.4 | Y10: =Elect!BE14 -> 0 | Z10: =Elect!BG14 -> 1361 | AA10: =Elect!BI14 -> 90 | AB10: =Elect!BK14 -> 176 | AD10: =Water!C15 -> 197.2 | AE10: =Water!E15 -> 0 | AF10: =Water!G15 -> 1.74 | AH10: =Gas!C15 -> 1791.4 | AI10: =Gas!E15 -> 116.2 | AJ10: =Gas!G15 -> 127 | AK10: =Elect!BM14 -> 231
A11: Cairo at The First Residence | B11: =B10+1 -> 10 | C11: 11 | D11: 2019 | F11: =Elect!J15 -> 6366 | G11: =Elect!K15 -> 3944 | H11: =Elect!Q15 -> 720 | I11: =Elect!W15 -> 146 | J11: =Elect!Y15 -> 234 | K11: =Elect!AA15 -> 0 | L11: =Elect!AC15 -> 3710.53 | M11: =Elect!AE15 -> 2958.46 | N11: =Elect!AG15 -> 0 | O11: =Elect!AI15 -> 582.47 | P11: =Elect!AK15 -> 3192.19 | Q11: =Elect!AN15 -> 1961 | R11: =Elect!AP15 -> 283 | S11: =Elect!AR15 -> 41.36 | T11: =Elect!AT15 -> 240 | U11: =Elect!AV15 -> 939 | V11: =Elect!AX15 -> 70 | W11: =Elect!AZ15 -> 6223 | X11: =Elect!BB15 -> 5845.5 | Y11: =Elect!BE15 -> 0 | Z11: =Elect!BG15 -> 1360 | AA11: =Elect!BI15 -> 93 | AB11: =Elect!BK15 -> 177 | AD11: =Water!C16 -> 261 | AE11: =Water!E16 -> 0 | AF11: =Water!G16 -> 1.74 | AH11: =Gas!C16 -> 1275.18 | AI11: =Gas!E16 -> 279.3 | AJ11: =Gas!G16 -> 91 | AK11: =Elect!BM15 -> 225
A12: Cairo at The First Residence | B12: =B11+1 -> 11 | C12: 11 | D12: 2019 | F12: =Elect!J16 -> 6123 | G12: =Elect!K16 -> 3800 | H12: =Elect!Q16 -> 780 | I12: =Elect!W16 -> 142 | J12: =Elect!Y16 -> 220 | K12: =Elect!AA16 -> 0 | L12: =Elect!AC16 -> 3693.04 | M12: =Elect!AE16 -> 2557.25 | N12: =Elect!AG16 -> 0 | O12: =Elect!AI16 -> 628.58 | P12: =Elect!AK16 -> 3239.36 | Q12: =Elect!AN16 -> 1598 | R12: =Elect!AP16 -> 262 | S12: =Elect!AR16 -> 39.27 | T12: =Elect!AT16 -> 238 | U12: =Elect!AV16 -> 758 | V12: =Elect!AX16 -> 67 | W12: =Elect!AZ16 -> 6005 | X12: =Elect!BB16 -> 5646.4 | Y12: =Elect!BE16 -> 0 | Z12: =Elect!BG16 -> 1311 | AA12: =Elect!BI16 -> 78 | AB12: =Elect!BK16 -> 171 | AD12: =Water!C17 -> 179.8 | AE12: =Water!E17 -> 0 | AF12: =Water!G17 -> 0 | AH12: =Gas!C17 -> 0 | AI12: =Gas!E17 -> 0 | AJ12: =Gas!G17 -> 0 | AK12: =Elect!BM16 -> 173
A13: Cairo at The First Residence | B13: =B12+1 -> 12 | C13: 11 | D13: 2019 | F13: =Elect!J17 -> 0 | G13: =Elect!K17 -> 0 | H13: =Elect!Q17 -> 0 | I13: =Elect!W17 -> 0 | J13: =Elect!Y17 -> 0 | K13: =Elect!AA17 -> 0 | L13: =Elect!AC17 -> 0 | M13: =Elect!AE17 -> 0 | N13: =Elect!AG17 -> 0 | O13: =Elect!AI17 -> 0 | P13: =Elect!AK17 -> 0 | Q13: =Elect!AN17 -> 0 | R13: =Elect!AP17 -> 0 | S13: =Elect!AR17 -> 0 | T13: =Elect!AT17 -> 0 | U13: =Elect!AV17 -> 0 | V13: =Elect!AX17 -> 0 | W13: =Elect!AZ17 -> 0 | X13: =Elect!BB17 -> 0 | Y13: =Elect!BE17 -> 0 | Z13: =Elect!BG17 -> 0 | AA13: =Elect!BI17 -> 0 | AB13: =Elect!BK17 -> 0 | AD13: =Water!C18 -> 208.8 | AE13: =Water!E18 -> 0 | AF13: =Water!G18 -> 1.16 | AH13: =Gas!C18 -> 0 | AI13: =Gas!E18 -> 0 | AJ13: =Gas!G18 -> 0 | AK13: =Elect!BM17 -> 0
A14: Cairo at The First Residence | B14: =B13+1 -> 13 | C14: 11 | D14: 2019 | F14: =Elect!J18 -> 0 | G14: =Elect!K18 -> 0 | H14: =Elect!Q18 -> 0 | I14: =Elect!W18 -> 0 | J14: =Elect!Y18 -> 0 | K14: =Elect!AA18 -> 0 | L14: =Elect!AC18 -> 0 | M14: =Elect!AE18 -> 0 | N14: =Elect!AG18 -> 0 | O14: =Elect!AI18 -> 0 | P14: =Elect!AK18 -> 0 | Q14: =Elect!AN18 -> 0 | R14: =Elect!AP18 -> 0 | S14: =Elect!AR18 -> 0 | T14: =Elect!AT18 -> 0 | U14: =Elect!AV18 -> 0 | V14: =Elect!AX18 -> 0 | W14: =Elect!AZ18 -> 0 | X14: =Elect!BB18 -> 0 | Y14: =Elect!BE18 -> 0 | Z14: =Elect!BG18 -> 0 | AA14: =Elect!BI18 -> 0 | AB14: =Elect!BK18 -> 0 | AD14: =Water!C19 -> 0 | AE14: =Water!E19 -> 0 | AF14: =Water!G19 -> 0 | AH14: =Gas!C19 -> 0 | AI14: =Gas!E19 -> 0 | AJ14: =Gas!G19 -> 0 | AK14: =Elect!BM18 -> 0
... A32: Cairo at The First Residence | B32: =B31+1 -> 31 | C32: 11 | D32: 2019 | F32: =Elect!J36 -> 0 | G32: =Elect!K36 -> 0 | H32: =Elect!Q36 -> 0 | I32: =Elect!W36 -> 0 | J32: =Elect!Y36 -> 0 | K32: =Elect!AA36 -> 0 | L32: =Elect!AC36 -> 0 | M32: =Elect!AE36 -> 0 | N32: =Elect!AG36 -> 0 | O32: =Elect!AI36 -> 0 | P32: =Elect!AK36 -> 0 | Q32: =Elect!AN36 -> 0 | R32: =Elect!AP36 -> 0 | S32: =Elect!AR36 -> 0 | T32: =Elect!AT36 -> 0 | U32: =Elect!AV36 -> 0 | V32: =Elect!AX36 -> 0 | W32: =Elect!AZ36 -> 0 | X32: =Elect!BB36 -> 0 | Y32: =Elect!BE36 -> 0 | Z32: =Elect!BG36 -> 0 | AA32: =Elect!BI36 -> 0 | AB32: =Elect!BK36 -> 0 | AD32: =Water!C37 -> 0 | AE32: =Water!E37 -> 0 | AF32: =Water!G37 -> 0 | AH32: =Gas!C37 -> 0 | AI32: =Gas!E37 -> 0 | AJ32: =Gas!G37 -> 0 | AK32: =Elect!BM36 -> 0

Sheet Elect
A1: November | M1: Electricity | BL1: Power Taxes | BM1: 0.0006 | BN1: Max Demand | BP1: 500 | BQ1: Electricity UP | BS1: 0.46
BL2: Light Taxes | BM2: 0.03 | BN2: PF Penalty | BQ2: Max. Demand UP | BS2: 30
A3: Date | B3: COUNTER (1) | D3: MD | F3: KVAR | H3: n | I3: Guest Rooms Consumption | R3: Casino Consumption | AD3: Plant Room Shared Loads | AW3: To Be Charged By First Arabian | BG3: From Main Panel G2 | BL3: Total Consumption. | BM3: No. Of | BN3: KWH/ | BO3: No. Of | BP3: KWH/ | BQ3: Total Cost | BR3: L.E\ | BS3: L.E\
B4: Reading | C4: Consp. F: *800 | D4: Reading | E4: Consp F: 80 | F4: Reading | G4: Consp. F:*10 | I4: Main Feeder | J4: Consp | K4: T2+T8 | L4: Trans T2 | M4: Consp | N4: Trans T8 | O4: Consp | P4: La Gourmandize | Q4: Consp *30 | R4: Casino 1 | S4: Consp | T4: Casino 2 | U4: Consp | V4: Casino 3rd floor EM | W4: Consp | X4: Casino 3rd floor Normal | Y4: Consp | Z4: Chiller 1 | AA4: Consp 53% | AB4: Chiller 2 | AC4: Consp 53% | AD4: Chiller 3 | AE4: Consp 53% | AF4: Chiller 4 | AG4: Consp 53% | AH4: Cooling towers | AI4: Consp 53% | AJ4: Chiller Pumps | AK4: Consp 53% | AL4: Total Plant Room Consp | AM4: LG Bakery | AN4: Consp | AO4: Mall Ceiling light | AP4: Consp | AQ4: New chiller for Second floor | AR4: Consp | AS4: LG Bakery light ( Old lockers ) | AT4: Consp | AU4: MCCR1 | AV4: Consp | AW4: Children Swimming pool | AX4: Consp | AY4: DPH1 | AZ4: Consp | BA4: Main G2 | BB4: Consp | BC4: Total Consp From First Arabian | BD4: Casino Emergency | BE4: Consp | BF4: L / A | BG4: Consp | BH4: L / B | BI4: Consp | BJ4: L / C | BK4: Consp | BM4: Rooms | BN4: room | BO4: guest | BP4: guest | BR4: Room | BS4: Guest
A5: Last Month Reading | I5: 19931247 | J5: =IF(I5>=I4,I5-I4,0) -> 0 | K5: =M5+O5 -> 0 | L5: 281178 | M5: =IF(L5>=L4,L5-L4,0) -> 0 | N5: 358777 | O5: =IF(N5>=N4,N5-N4,0) -> 0 | P5: 207244 | Q5: =IF(P5>=P4,P5-P4,0)*30 -> 0 | R5: 702925 | S5: =IF(R5>=R4,R5-R4,0) -> 0 | T5: 344001 | U5: =IF(T5>=T4,T5-T4,0) -> 0 | V5: 67827 | W5: =IF(V5>=V4,V5-V4,0) -> 0 | X5: 131607 | Y5: =IF(X5>=X4,X5-X4,0) -> 0 | Z5: 315108 | AA5: =IF(Z5>=Z4,Z5-Z4,0)*0.53 -> 0 | AB5: 434034 | AC5: =IF(AB5>=AB4,AB5-AB4,0)*0.53 -> 0 | AD5: 387409 | AE5: =IF(AD5>=AD4,AD5-AD4,0)*0.53 -> 0 | AF5: 575976 | AG5: =IF(AF5>=AF4,AF5-AF4,0)*0.53 -> 0 | AH5: 119352 | AI5: =IF(AH5>=AH4,AH5-AH4,0)*0.53 -> 0 | AJ5: 581303 | AK5: =IF(AJ5>=AJ4,AJ5-AJ4,0)*0.53 -> 0 | AL5: =AA5+AC5+AE5+AG5+AI5+AK5 -> 0 | AM5: 6745757 | AN5: =IF(AM5>=AM4,AM5-AM4,0) -> 0 | AO5: 494779 | AP5: =IF(AO5>=AO4,AO5-AO4,0) -> 0 | AQ5: 839798 | AR5: =IF(AQ5>=AQ4,AQ5-AQ4,0)*0.11 -> 0 | AS5: 748372 | AT5: =IF(AS5>=AS4,AS5-AS4,0) -> 0 | AU5: 2018180 | AV5: =IF(AU5>=AU4,AU5-AU4,0) -> 0 | AW5: 186816.74 | AX5: 0 | AY5: 15856310 | AZ5: =IF(AY5>=AY4,AY5-AY4,0) -> 0 | BA5: 19267225 | BB5: =IF(BA5>=BA4,BA5-BA4,0)-(0.6*BG5)-(0.5*BI5)-BK5-BE5 -> 0 | BC5: =AN5+AP5+AR5+AT5+AV5+AX5+AZ5+BB5 -> 0 | BD5: 1323286 | BE5: =IF(BD5>=BD4,BD5-BD4,0) -> 0 | BF5: 2964015 | BG5: =IF(BF5>=BF4,BF5-BF4,0) -> 0 | BH5: 329717 | BI5: =IF(BH5>=BH4,BH5-BH4,0) -> 0 | BJ5: 364749 | BK5: =IF(BJ5>=BJ4,BJ5-BJ4,0) -> 0
A6: 1 | C6: =IF(+B6-B5>0,B6-B5,(B6-B5)>0)*800 -> 0 | E6: =IF(+D6-D5>0,D6-D5,(D6-D5)>0)*80 -> 0 | G6: =IF(+F6-F5>0,F6-F5,(F6-F5)>0)*10 -> 0 | H6: 56 | I6: 19936793 | J6: =IF(I6>=I5,I6-I5,0) -> 5546 | K6: =M6+O6 -> 3765 | L6: 284102 | M6: =IF(L6>=L5,L6-L5,0) -> 2924 | N6: 359618 | O6: =IF(N6>=N5,N6-N5,0) -> 841 | P6: 207271 | Q6: =IF(P6>=P5,P6-P5,0)*30 -> 810 | R6: 702925 | S6: =IF(R6>=R5,R6-R5,0) -> 0 | T6: 344001 | U6: =IF(T6>=T5,T6-T5,0) -> 0 | V6: 68008 | W6: =IF(V6>=V5,V6-V5,0) -> 181 | X6: 131807 | Y6: =IF(X6>=X5,X6-X5,0) -> 200 | Z6: 315108 | AA6: =IF(Z6>=Z5,Z6-Z5,0)*0.53 -> 0 | AB6: 435013 | AC6: =IF(AB6>=AB5,AB6-AB5,0)*0.53 -> 518.87 | AD6: 394891 | AE6: =IF(AD6>=AD5,AD6-AD5,0)*0.53 -> 3965.46 | AF6: 575976 | AG6: =IF(AF6>=AF5,AF6-AF5,0)*0.53 -> 0 | AH6: 120409 | AI6: =IF(AH6>=AH5,AH6-AH5,0)*0.53 -> 560.21 | AJ6: 583508 | AK6: =IF(AJ6>=AJ5,AJ6-AJ5,0)*0.53 -> 1168.65 | AL6: =AA6+AC6+AE6+AG6+AI6+AK6 -> 6213.19 | AM6: 6746998 | AN6: =IF(AM6>=AM5,AM6-AM5,0) -> 1241 | AO6: 495139 | AP6: =IF(AO6>=AO5,AO6-AO5,0) -> 360 | AQ6: 840077 | AR6: =IF(AQ6>=AQ5,AQ6-AQ5,0)*0.11 -> 30.69 | AS6: 748587 | AT6: =IF(AS6>=AS5,AS6-AS5,0) -> 215 | AU6: 2018826 | AV6: =IF(AU6>=AU5,AU6-AU5,0) -> 646 | AW6: 186864 | AX6: =IF(AW6>=AW5,AW6-AW5,0) -> 47.256062 | AY6: 15861898 | AZ6: =IF(AY6>=AY5,AY6-AY5,0) -> 5588 | BA6: 19275015 | BB6: =IF(BA6>=BA5,BA6-BA5,0)-(0.6*BG6)-(0.5*BI6)-BK6-BE6 -> 6628.9 | BC6: =AN6+AP6+AR6+AT6+AV6+AX6+AZ6+BB6 -> 14756.846 | BD6: 1323286 | BE6: =IF(BD6>=BD5,BD6-BD5,0) -> 0 | BF6: 2965571 | BG6: =IF(BF6>=BF5,BF6-BF5,0) -> 1556 | BH6: 329782 | BI6: =IF(BH6>=BH5,BH6-BH5,0) -> 65 | BJ6: 364944 | BK6: =IF(BJ6>=BJ5,BJ6-BJ5,0) -> 195 | BL6: =J6+Q6+AL6+BC6 -> 27326.036 | BM6: 244 | BN6: =IF(BL6>0,BL6/#REF!,0) -> #REF! | BP6: =IF(BL6>0,BL6/BO6,0) -> #DIV/0! | BQ6: =BL6*BS1 -> 12569.977 | BR6: =IF(BQ6>0,BQ6/#REF!,0) -> #REF! | BS6: =IF(BQ6>0,BQ6/BO6,0) -> #DIV/0!
A7: 2 | I7: 19943301 | J7: =IF(I7>=I6,I7-I6,0) -> 6508 | K7: =M7+O7 -> 4025 | L7: 286575 | M7: =IF(L7>=L6,L7-L6,0) -> 2473 | N7: 361170 | O7: =IF(N7>=N6,N7-N6,0) -> 1552 | P7: 207297 | Q7: =IF(P7>=P6,P7-P6,0)*30 -> 780 | R7: 702925 | S7: =IF(R7>=R6,R7-R6,0) -> 0 | T7: 344001 | U7: =IF(T7>=T6,T7-T6,0) -> 0 | V7: 68153 | W7: =IF(V7>=V6,V7-V6,0) -> 145 | X7: 132039 | Y7: =IF(X7>=X6,X7-X6,0) -> 232 | Z7: 315108 | AA7: =IF(Z7>=Z6,Z7-Z6,0)*0.53 -> 0 | AB7: 438323 | AC7: =IF(AB7>=AB6,AB7-AB6,0)*0.53 -> 1754.3 | AD7: 402263 | AE7: =IF(AD7>=AD6,AD7-AD6,0)*0.53 -> 3907.16 | AF7: 575976 | AG7: =IF(AF7>=AF6,AF7-AF6,0)*0.53 -> 0 | AH7: 121347 | AI7: =IF(AH7>=AH6,AH7-AH6,0)*0.53 -> 497.14 | AJ7: 588358 | AK7: =IF(AJ7>=AJ6,AJ7-AJ6,0)*0.53 -> 2570.5 | AL7: =AA7+AC7+AE7+AG7+AI7+AK7 -> 8729.1 | AM7: 6748094 | AN7: =IF(AM7>=AM6,AM7-AM6,0) -> 1096 | AO7: 495413 | AP7: =IF(AO7>=AO6,AO7-AO6,0) -> 274 | AQ7: 840413 | AR7: =IF(AQ7>=AQ6,AQ7-AQ6,0)*0.11 -> 36.96 | AS7: 748843 | AT7: =IF(AS7>=AS6,AS7-AS6,0) -> 256 | AU7: 2019719 | AV7: =IF(AU7>=AU6,AU7-AU6,0) -> 893 | AW7: 186931 | AX7: =IF(AW7>=AW6,AW7-AW6,0) -> 67 | AY7: 15868307 | AZ7: =IF(AY7>=AY6,AY7-AY6,0) -> 6409 | BA7: 19281632 | BB7: =IF(BA7>=BA6,BA7-BA6,0)-(0.6*BG7)-(0.5*BI7)-BK7-BE7 -> 5627.8 | BC7: =AN7+AP7+AR7+AT7+AV7+AX7+AZ7+BB7 -> 14659.76 | BD7: 1323286 | BE7: =IF(BD7>=BD6,BD7-BD6,0) -> 0 | BF7: 2966858 | BG7: =IF(BF7>=BF6,BF7-BF6,0) -> 1287 | BH7: 329876 | BI7: =IF(BH7>=BH6,BH7-BH6,0) -> 94 | BJ7: 365114 | BK7: =IF(BJ7>=BJ6,BJ7-BJ6,0) -> 170 | BL7: =J7+Q7+AL7+BC7 -> 30676.86 | BM7: 230 | BN7: =IF(BL7>0,BL7/BM6,0) -> 125.72484 | BP7: =IF(BL7>0,BL7/BO7,0) -> #DIV/0! | BQ7: =BL7*BS1 -> 14111.356 | BR7: =IF(BQ7>0,BQ7/BM6,0) -> 57.833425 | BS7: =IF(BQ7>0,BQ7/BO7,0) -> #DIV/0!
A8: 3 | C8: =IF(+B8-B7>0,B8-B7,(B8-B7)>0)*800 -> 0 | E8: =IF(+D8-D7>0,D8-D7,(D8-D7)>0)*80 -> 0 | G8: =IF(+F8-F7>0,F8-F7,(F8-F7)>0)*10 -> 0 | H8: 57 | I8: 19949904 | J8: =IF(I8>=I7,I8-I7,0) -> 6603 | K8: =M8+O8 -> 4233 | L8: 289080 | M8: =IF(L8>=L7,L8-L7,0) -> 2505 | N8: 362898 | O8: =IF(N8>=N7,N8-N7,0) -> 1728 | P8: 207323 | Q8: =IF(P8>=P7,P8-P7,0)*30 -> 780 | R8: 702925 | S8: =IF(R8>=R7,R8-R7,0) -> 0 | T8: 344001 | U8: =IF(T8>=T7,T8-T7,0) -> 0 | V8: 68300 | W8: =IF(V8>=V7,V8-V7,0) -> 147 | X8: 132266 | Y8: =IF(X8>=X7,X8-X7,0) -> 227 | Z8: 315108 | AA8: =IF(Z8>=Z7,Z8-Z7,0)*0.53 -> 0 | AB8: 445869 | AC8: =IF(AB8>=AB7,AB8-AB7,0)*0.53 -> 3999.38 | AD8: 407030 | AE8: =IF(AD8>=AD7,AD8-AD7,0)*0.53 -> 2526.51 | AF8: 575976 | AG8: =IF(AF8>=AF7,AF8-AF7,0)*0.53 -> 0 | AH8: 122329 | AI8: =IF(AH8>=AH7,AH8-AH7,0)*0.53 -> 520.46 | AJ8: 593680 | AK8: =IF(AJ8>=AJ7,AJ8-AJ7,0)*0.53 -> 2820.66 | AL8: =AA8+AC8+AE8+AG8+AI8+AK8 -> 9867.01 | AM8: 6749653 | AN8: =IF(AM8>=AM7,AM8-AM7,0) -> 1559 | AO8: 495690 | AP8: =IF(AO8>=AO7,AO8-AO7,0) -> 277 | AQ8: 840798 | AR8: =IF(AQ8>=AQ7,AQ8-AQ7,0)*0.11 -> 42.35 | AS8: 749104 | AT8: =IF(AS8>=AS7,AS8-AS7,0) -> 261 | AU8: 2020735 | AV8: =IF(AU8>=AU7,AU8-AU7,0) -> 1016 | AW8: 186998 | AX8: =IF(AW8>=AW7,AW8-AW7,0) -> 67 | AY8: 15874988 | AZ8: =IF(AY8>=AY7,AY8-AY7,0) -> 6681 | BA8: 19288888 | BB8: =IF(BA8>=BA7,BA8-BA7,0)-(0.6*BG8)-(0.5*BI8)-BK8-BE8 -> 6197.4 | BC8: =AN8+AP8+AR8+AT8+AV8+AX8+AZ8+BB8 -> 16100.75 | BD8: 1323286 | BE8: =IF(BD8>=BD7,BD8-BD7,0) -> 0 | BF8: 2968234 | BG8: =IF(BF8>=BF7,BF8-BF7,0) -> 1376 | BH8: 329974 | BI8: =IF(BH8>=BH7,BH8-BH7,0) -> 98 | BJ8: 365298 | BK8: =IF(BJ8>=BJ7,BJ8-BJ7,0) -> 184 | BL8: =J8+Q8+AL8+BC8 -> 33350.76 | BM8: 252 | BN8: =IF(BL8>0,BL8/BM7,0) -> 145.0033 | BP8: =IF(BL8>0,BL8/BO8,0) -> #DIV/0! | BQ8: =BL8*BS1 -> 15341.35 | BR8: =IF(BQ8>0,BQ8/BM7,0) -> 66.70152 | BS8: =IF(BQ8>0,BQ8/BO8,0) -> #DIV/0!
A9: 4 | C9: =IF(+B9-B8>0,B9-B8,(B9-B8)>0)*800 -> 0 | E9: =IF(+D9-D8>0,D9-D8,(D9-D8)>0)*80 -> 0 | G9: =IF(+F9-F8>0,F9-F8,(F9-F8)>0)*10 -> 0 | I9: 19956222 | J9: =IF(I9>=I8,I9-I8,0) -> 6318 | K9: =M9+O9 -> 3858 | L9: 291297 | M9: =IF(L9>=L8,L9-L8,0) -> 2217 | N9: 364539 | O9: =IF(N9>=N8,N9-N8,0) -> 1641 | P9: 207350 | Q9: =IF(P9>=P8,P9-P8,0)*30 -> 810 | R9: 702925 | S9: =IF(R9>=R8,R9-R8,0) -> 0 | T9: 344001 | U9: =IF(T9>=T8,T9-T8,0) -> 0 | V9: 68442 | W9: =IF(V9>=V8,V9-V8,0) -> 142 | X9: 132487 | Y9: =IF(X9>=X8,X9-X8,0) -> 221 | Z9: 315108 | AA9: =IF(Z9>=Z8,Z9-Z8,0)*0.53 -> 0 | AB9: 449949 | AC9: =IF(AB9>=AB8,AB9-AB8,0)*0.53 -> 2162.4 | AD9: 413930 | AE9: =IF(AD9>=AD8,AD9-AD8,0)*0.53 -> 3657 | AF9: 575976 | AG9: =IF(AF9>=AF8,AF9-AF8,0)*0.53 -> 0 | AH9: 123303 | AI9: =IF(AH9>=AH8,AH9-AH8,0)*0.53 -> 516.22 | AJ9: 598718 | AK9: =IF(AJ9>=AJ8,AJ9-AJ8,0)*0.53 -> 2670.14 | AL9: =AA9+AC9+AE9+AG9+AI9+AK9 -> 9005.76 | AM9: 6751437 | AN9: =IF(AM9>=AM8,AM9-AM8,0) -> 1784 | AO9: 495962 | AP9: =IF(AO9>=AO8,AO9-AO8,0) -> 272 | AQ9: 841132 | AR9: =IF(AQ9>=AQ8,AQ9-AQ8,0)*0.11 -> 36.74 | AS9: 749357 | AT9: =IF(AS9>=AS8,AS9-AS8,0) -> 253 | AU9: 2021700 | AV9: =IF(AU9>=AU8,AU9-AU8,0) -> 965 | AW9: 187064 | AX9: =IF(AW9>=AW8,AW9-AW8,0) -> 66 | AY9: 15881199 | AZ9: =IF(AY9>=AY8,AY9-AY8,0) -> 6211 | BA9: 19295692 | BB9: =IF(BA9>=BA8,BA9-BA8,0)-(0.6*BG9)-(0.5*BI9)-BK9-BE9 -> 5823.1 | BC9: =AN9+AP9+AR9+AT9+AV9+AX9+AZ9+BB9 -> 15410.84 | BD9: 1323286 | BE9: =IF(BD9>=BD8,BD9-BD8,0) -> 0 | BF9: 2969508 | BG9: =IF(BF9>=BF8,BF9-BF8,0) -> 1274 | BH9: 330063 | BI9: =IF(BH9>=BH8,BH9-BH8,0) -> 89 | BJ9: 365470 | BK9: =IF(BJ9>=BJ8,BJ9-BJ8,0) -> 172 | BL9: =J9+Q9+AL9+BC9 -> 31544.6 | BM9: 243 | BN9: =IF(BL9>0,BL9/BM8,0) -> 125.17698 | BP9: =IF(BL9>0,BL9/BO9,0) -> #DIV/0! | BQ9: =BL9*BS1 -> 14510.516 | BR9: =IF(BQ9>0,BQ9/BM8,0) -> 57.581413 | BS9: =IF(BQ9>0,BQ9/BO9,0) -> #DIV/0!
A10: 5 | C10: =IF(+B10-B9>0,B10-B9,(B10-B9)>0)*800 -> 0 | E10: =IF(+D10-D9>0,D10-D9,(D10-D9)>0)*80 -> 0 | G10: =IF(+F10-F9>0,F10-F9,(F10-F9)>0)*10 -> 0 | H10: 58 | I10: 19962223 | J10: =IF(I10>=I9,I10-I9,0) -> 6001 | K10: =M10+O10 -> 3791 | L10: 293469 | M10: =IF(L10>=L9,L10-L9,0) -> 2172 | N10: 366158 | O10: =IF(N10>=N9,N10-N9,0) -> 1619 | P10: 207374 | Q10: =IF(P10>=P9,P10-P9,0)*30 -> 720 | R10: 702925 | S10: =IF(R10>=R9,R10-R9,0) -> 0 | T10: 344001 | U10: =IF(T10>=T9,T10-T9,0) -> 0 | V10: 68587 | W10: =IF(V10>=V9,V10-V9,0) -> 145 | X10: 132714 | Y10: =IF(X10>=X9,X10-X9,0) -> 227 | Z10: 315108 | AA10: =IF(Z10>=Z9,Z10-Z9,0)*0.53 -> 0 | AB10: 457051 | AC10: =IF(AB10>=AB9,AB10-AB9,0)*0.53 -> 3764.06 | AD10: 418479 | AE10: =IF(AD10>=AD9,AD10-AD9,0)*0.53 -> 2410.97 | AF10: 575976 | AG10: =IF(AF10>=AF9,AF10-AF9,0)*0.53 -> 0 | AH10: 124338 | AI10: =IF(AH10>=AH9,AH10-AH9,0)*0.53 -> 548.55 | AJ10: 603840 | AK10: =IF(AJ10>=AJ9,AJ10-AJ9,0)*0.53 -> 2714.66 | AL10: =AA10+AC10+AE10+AG10+AI10+AK10 -> 9438.24 | AM10: 6753262 | AN10: =IF(AM10>=AM9,AM10-AM9,0) -> 1825 | AO10: 496228 | AP10: =IF(AO10>=AO9,AO10-AO9,0) -> 266 | AQ10: 841489 | AR10: =IF(AQ10>=AQ9,AQ10-AQ9,0)*0.11 -> 39.27 | AS10: 749587 | AT10: =IF(AS10>=AS9,AS10-AS9,0) -> 230 | AU10: 2022667 | AV10: =IF(AU10>=AU9,AU10-AU9,0) -> 967 | AW10: 187133 | AX10: =IF(AW10>=AW9,AW10-AW9,0) -> 69 | AY10: 15887511 | AZ10: =IF(AY10>=AY9,AY10-AY9,0) -> 6312 | BA10: 19302461 | BB10: =IF(BA10>=BA9,BA10-BA9,0)-(0.6*BG10)-(0.5*BI10)-BK10-BE10 -> 5755.8 | BC10: =AN10+AP10+AR10+AT10+AV10+AX10+AZ10+BB10 -> 15464.07 | BD10: 1323286 | BE10: =IF(BD10>=BD9,BD10-BD9,0) -> 0 | BF10: 2970825 | BG10: =IF(BF10>=BF9,BF10-BF9,0) -> 1317 | BH10: 330155 | BI10: =IF(BH10>=BH9,BH10-BH9,0) -> 92 | BJ10: 365647 | BK10: =IF(BJ10>=BJ9,BJ10-BJ9,0) -> 177 | BL10: =J10+Q10+AL10+BC10 -> 31623.31 | BM10: 248 | BN10: =IF(BL10>0,BL10/BM9,0) -> 130.13708 | BP10: =IF(BL10>0,BL10/BO10,0) -> #DIV/0! | BQ10: =BL10*BS1 -> 14546.723 | BR10: =IF(BQ10>0,BQ10/BM9,0) -> 59.863056 | BS10: =IF(BQ10>0,BQ10/BO10,0) -> #DIV/0!
A11: 6 | C11: =IF(+B11-B10>0,B11-B10,(B11-B10)>0)*800 -> 0 | E11: =IF(+D11-D10>0,D11-D10,(D11-D10)>0)*80 -> 0 | G11: =IF(+F11-F10>0,F11-F10,(F11-F10)>0)*10 -> 0 | I11: 19968452 | J11: =IF(I11>=I10,I11-I10,0) -> 6229 | K11: =M11+O11 -> 3847 | L11: 295613 | M11: =IF(L11>=L10,L11-L10,0) -> 2144 | N11: 367861 | O11: =IF(N11>=N10,N11-N10,0) -> 1703 | P11: 207402 | Q11: =IF(P11>=P10,P11-P10,0)*30 -> 840 | R11: 702925 | S11: =IF(R11>=R10,R11-R10,0) -> 0 | T11: 344001 | U11: =IF(T11>=T10,T11-T10,0) -> 0 | V11: 68729 | W11: =IF(V11>=V10,V11-V10,0) -> 142 | X11: 132941 | Y11: =IF(X11>=X10,X11-X10,0) -> 227 | Z11: 315108 | AA11: =IF(Z11>=Z10,Z11-Z10,0)*0.53 -> 0 | AB11: 464143 | AC11: =IF(AB11>=AB10,AB11-AB10,0)*0.53 -> 3758.76 | AD11: 423399 | AE11: =IF(AD11>=AD10,AD11-AD10,0)*0.53 -> 2607.6 | AF11: 575976 | AG11: =IF(AF11>=AF10,AF11-AF10,0)*0.53 -> 0 | AH11: 125514 | AI11: =IF(AH11>=AH10,AH11-AH10,0)*0.53 -> 623.28 | AJ11: 608932 | AK11: =IF(AJ11>=AJ10,AJ11-AJ10,0)*0.53 -> 2698.76 | AL11: =AA11+AC11+AE11+AG11+AI11+AK11 -> 9688.4 | AM11: 6754995 | AN11: =IF(AM11>=AM10,AM11-AM10,0) -> 1733 | AO11: 496481 | AP11: =IF(AO11>=AO10,AO11-AO10,0) -> 253 | AQ11: 841849 | AR11: =IF(AQ11>=AQ10,AQ11-AQ10,0)*0.11 -> 39.6 | AS11: 749838 | AT11: =IF(AS11>=AS10,AS11-AS10,0) -> 251 | AU11: 2023616 | AV11: =IF(AU11>=AU10,AU11-AU10,0) -> 949 | AW11: 187202 | AX11: =IF(AW11>=AW10,AW11-AW10,0) -> 69 | AY11: 15893866 | AZ11: =IF(AY11>=AY10,AY11-AY10,0) -> 6355 | BA11: 19308947 | BB11: =IF(BA11>=BA10,BA11-BA10,0)-(0.6*BG11)-(0.5*BI11)-BK11-BE11 -> 5542.8 | BC11: =AN11+AP11+AR11+AT11+AV11+AX11+AZ11+BB11 -> 15192.4 | BD11: 1323286 | BE11: =IF(BD11>=BD10,BD11-BD10,0) -> 0 | BF11: 2972047 | BG11: =IF(BF11>=BF10,BF11-BF10,0) -> 1222 | BH11: 330239 | BI11: =IF(BH11>=BH10,BH11-BH10,0) -> 84 | BJ11: 365815 | BK11: =IF(BJ11>=BJ10,BJ11-BJ10,0) -> 168 | BL11: =J11+Q11+AL11+BC11 -> 31949.8 | BM11: 249 | BN11: =IF(BL11>0,BL11/BM10,0) -> 128.82984 | BP11: =IF(BL11>0,BL11/BO11,0) -> #DIV/0! | BQ11: =BL11*BS1 -> 14696.908 | BR11: =IF(BQ11>0,BQ11/BM10,0) -> 59.261726 | BS11: =IF(BQ11>0,BQ11/BO11,0) -> #DIV/0!
A12: 7 | C12: =IF(+B12-B11>0,B12-B11,(B12-B11)>0)*800 -> 0 | E12: =IF(+D12-D11>0,D12-D11,(D12-D11)>0)*80 -> 0 | G12: =IF(+F12-F11>0,F12-F11,(F12-F11)>0)*10 -> 0 | H12: 59 | I12: 19974869 | J12: =IF(I12>=I11,I12-I11,0) -> 6417 | K12: =M12+O12 -> 3969 | L12: 297925 | M12: =IF(L12>=L11,L12-L11,0) -> 2312 | N12: 369518 | O12: =IF(N12>=N11,N12-N11,0) -> 1657 | P12: 207428 | Q12: =IF(P12>=P11,P12-P11,0)*30 -> 780 | R12: 702925 | S12: =IF(R12>=R11,R12-R11,0) -> 0 | T12: 344001 | U12: =IF(T12>=T11,T12-T11,0) -> 0 | V12: 68875 | W12: =IF(V12>=V11,V12-V11,0) -> 146 | X12: 133160 | Y12: =IF(X12>=X11,X12-X11,0) -> 219 | Z12: 315108 | AA12: =IF(Z12>=Z11,Z12-Z11,0)*0.53 -> 0 | AB12: 469601 | AC12: =IF(AB12>=AB11,AB12-AB11,0)*0.53 -> 2892.74 | AD12: 430642 | AE12: =IF(AD12>=AD11,AD12-AD11,0)*0.53 -> 3838.79 | AF12: 575976 | AG12: =IF(AF12>=AF11,AF12-AF11,0)*0.53 -> 0 | AH12: 127077 | AI12: =IF(AH12>=AH11,AH12-AH11,0)*0.53 -> 828.39 | AJ12: 614664 | AK12: =IF(AJ12>=AJ11,AJ12-AJ11,0)*0.53 -> 3037.96 | AL12: =AA12+AC12+AE12+AG12+AI12+AK12 -> 10597.88 | AM12: 6756548 | AN12: =IF(AM12>=AM11,AM12-AM11,0) -> 1553 | AO12: 496742 | AP12: =IF(AO12>=AO11,AO12-AO11,0) -> 261 | AQ12: 842241 | AR12: =IF(AQ12>=AQ11,AQ12-AQ11,0)*0.11 -> 43.12 | AS12: 750087 | AT12: =IF(AS12>=AS11,AS12-AS11,0) -> 249 | AU12: 2024574 | AV12: =IF(AU12>=AU11,AU12-AU11,0) -> 958 | AW12: 187271 | AX12: =IF(AW12>=AW11,AW12-AW11,0) -> 69 | AY12: 15900116 | AZ12: =IF(AY12>=AY11,AY12-AY11,0) -> 6250 | BA12: 19315817 | BB12: =IF(BA12>=BA11,BA12-BA11,0)-(0.6*BG12)-(0.5*BI12)-BK12-BE12 -> 5876 | BC12: =AN12+AP12+AR12+AT12+AV12+AX12+AZ12+BB12 -> 15259.12 | BD12: 1323286 | BE12: =IF(BD12>=BD11,BD12-BD11,0) -> 0 | BF12: 2973407 | BG12: =IF(BF12>=BF11,BF12-BF11,0) -> 1360 | BH12: 330325 | BI12: =IF(BH12>=BH11,BH12-BH11,0) -> 86 | BJ12: 365950 | BK12: =IF(BJ12>=BJ11,BJ12-BJ11,0) -> 135 | BL12: =J12+Q12+AL12+BC12 -> 33054 | BM12: 223 | BN12: =IF(BL12>0,BL12/BM11,0) -> 132.74699 | BP12: =IF(BL12>0,BL12/BO12,0) -> #DIV/0! | BQ12: =BL12*BS1 -> 15204.84 | BR12: =IF(BQ12>0,BQ12/BM11,0) -> 61.063614 | BS12: =IF(BQ12>0,BQ12/BO12,0) -> #DIV/0!
A13: 8 | C13: =IF(+B13-B12>0,B13-B12,(B13-B12)>0)*800 -> 0 | E13: =IF(+D13-D12>0,D13-D12,(D13-D12)>0)*80 -> 0 | G13: =IF(+F13-F12>0,F13-F12,(F13-F12)>0)*10 -> 0 | I13: 19981204 | J13: =IF(I13>=I12,I13-I12,0) -> 6335 | K13: =M13+O13 -> 3899 | L13: 300254 | M13: =IF(L13>=L12,L13-L12,0) -> 2329 | N13: 371088 | O13: =IF(N13>=N12,N13-N12,0) -> 1570 | P13: 207454 | Q13: =IF(P13>=P12,P13-P12,0)*30 -> 780 | R13: 702925 | S13: =IF(R13>=R12,R13-R12,0) -> 0 | T13: 344001 | U13: =IF(T13>=T12,T13-T12,0) -> 0 | V13: 69018 | W13: =IF(V13>=V12,V13-V12,0) -> 143 | X13: 133394 | Y13: =IF(X13>=X12,X13-X12,0) -> 234 | Z13: 315108 | AA13: =IF(Z13>=Z12,Z13-Z12,0)*0.53 -> 0 | AB13: 476210 | AC13: =IF(AB13>=AB12,AB13-AB12,0)*0.53 -> 3502.77 | AD13: 437668 | AE13: =IF(AD13>=AD12,AD13-AD12,0)*0.53 -> 3723.78 | AF13: 575976 | AG13: =IF(AF13>=AF12,AF13-AF12,0)*0.53 -> 0 | AH13: 128338 | AI13: =IF(AH13>=AH12,AH13-AH12,0)*0.53 -> 668.33 | AJ13: 620473 | AK13: =IF(AJ13>=AJ12,AJ13-AJ12,0)*0.53 -> 3078.77 | AL13: =AA13+AC13+AE13+AG13+AI13+AK13 -> 10973.65 | AM13: 6758270 | AN13: =IF(AM13>=AM12,AM13-AM12,0) -> 1722 | AO13: 497000 | AP13: =IF(AO13>=AO12,AO13-AO12,0) -> 258 | AQ13: 842598 | AR13: =IF(AQ13>=AQ12,AQ13-AQ12,0)*0.11 -> 39.27 | AS13: 750315 | AT13: =IF(AS13>=AS12,AS13-AS12,0) -> 228 | AU13: 2025533 | AV13: =IF(AU13>=AU12,AU13-AU12,0) -> 959 | AW13: 187339 | AX13: =IF(AW13>=AW12,AW13-AW12,0) -> 68 | AY13: 15906342 | AZ13: =IF(AY13>=AY12,AY13-AY12,0) -> 6226 | BA13: 19322340 | BB13: =IF(BA13>=BA12,BA13-BA12,0)-(0.6*BG13)-(0.5*BI13)-BK13-BE13 -> 5521.9 | BC13: =AN13+AP13+AR13+AT13+AV13+AX13+AZ13+BB13 -> 15022.17 | BD13: 1323286 | BE13: =IF(BD13>=BD12,BD13-BD12,0) -> 0 | BF13: 2974648 | BG13: =IF(BF13>=BF12,BF13-BF12,0) -> 1241 | BH13: 330414 | BI13: =IF(BH13>=BH12,BH13-BH12,0) -> 89 | BJ13: 366162 | BK13: =IF(BJ13>=BJ12,BJ13-BJ12,0) -> 212 | BL13: =J13+Q13+AL13+BC13 -> 33110.82 | BM13: 235 | BN13: =IF(BL13>0,BL13/BM12,0) -> 148.47901 | BP13: =IF(BL13>0,BL13/BO13,0) -> #DIV/0! | BQ13: =BL13*BS1 -> 15230.977 | BR13: =IF(BQ13>0,BQ13/BM12,0) -> 68.300346 | BS13: =IF(BQ13>0,BQ13/BO13,0) -> #DIV/0!
A14: 9 | C14: =IF(+B14-B13>0,B14-B13,(B14-B13)>0)*800 -> 0 | E14: =IF(+D14-D13>0,D14-D13,(D14-D13)>0)*80 -> 0 | G14: =IF(+F14-F13>0,F14-F13,(F14-F13)>0)*10 -> 0 | H14: 60 | I14: 19987770 | J14: =IF(I14>=I13,I14-I13,0) -> 6566 | K14: =M14+O14 -> 5112 | L14: 302622 | M14: =IF(L14>=L13,L14-L13,0) -> 2368 | N14: 373832 | O14: =IF(N14>=N13,N14-N13,0) -> 2744 | P14: 207476 | Q14: =IF(P14>=P13,P14-P13,0)*30 -> 660 | R14: 702925 | S14: =IF(R14>=R13,R14-R13,0) -> 0 | T14: 344001 | U14: =IF(T14>=T13,T14-T13,0) -> 0 | V14: 69164 | W14: =IF(V14>=V13,V14-V13,0) -> 146 | X14: 133630 | Y14: =IF(X14>=X13,X14-X13,0) -> 236 | Z14: 315108 | AA14: =IF(Z14>=Z13,Z14-Z13,0)*0.53 -> 0 | AB14: 482543 | AC14: =IF(AB14>=AB13,AB14-AB13,0)*0.53 -> 3356.49 | AD14: 444194 | AE14: =IF(AD14>=AD13,AD14-AD13,0)*0.53 -> 3458.78 | AF14: 575976 | AG14: =IF(AF14>=AF13,AF14-AF13,0)*0.53 -> 0 | AH14: 129585 | AI14: =IF(AH14>=AH13,AH14-AH13,0)*0.53 -> 660.91 | AJ14: 626825 | AK14: =IF(AJ14>=AJ13,AJ14-AJ13,0)*0.53 -> 3366.56 | AL14: =AA14+AC14+AE14+AG14+AI14+AK14 -> 10842.74 | AM14: 6759978 | AN14: =IF(AM14>=AM13,AM14-AM13,0) -> 1708 | AO14: 497275 | AP14: =IF(AO14>=AO13,AO14-AO13,0) -> 275 | AQ14: 842967 | AR14: =IF(AQ14>=AQ13,AQ14-AQ13,0)*0.11 -> 40.59 | AS14: 750542 | AT14: =IF(AS14>=AS13,AS14-AS13,0) -> 227 | AU14: 2026403 | AV14: =IF(AU14>=AU13,AU14-AU13,0) -> 870 | AW14: 187408 | AX14: =IF(AW14>=AW13,AW14-AW13,0) -> 69 | AY14: 15912537 | AZ14: =IF(AY14>=AY13,AY14-AY13,0) -> 6195 | BA14: 19329175 | BB14: =IF(BA14>=BA13,BA14-BA13,0)-(0.6*BG14)-(0.5*BI14)-BK14-BE14 -> 5797.4 | BC14: =AN14+AP14+AR14+AT14+AV14+AX14+AZ14+BB14 -> 15181.99 | BD14: 1323286 | BE14: =IF(BD14>=BD13,BD14-BD13,0) -> 0 | BF14: 2976009 | BG14: =IF(BF14>=BF13,BF14-BF13,0) -> 1361 | BH14: 330504 | BI14: =IF(BH14>=BH13,BH14-BH13,0) -> 90 | BJ14: 366338 | BK14: =IF(BJ14>=BJ13,BJ14-BJ13,0) -> 176 | BL14: =J14+Q14+AL14+BC14 -> 33250.73 | BM14: 231 | BN14: =IF(BL14>0,BL14/BM13,0) -> 141.49247 | BP14: =IF(BL14>0,BL14/BO14,0) -> #DIV/0! | BQ14: =BL14*BS1 -> 15295.336 | BR14: =IF(BQ14>0,BQ14/BM13,0) -> 65.086535 | BS14: =IF(BQ14>0,BQ14/BO14,0) -> #DIV/0!
A15: 10 | C15: =IF(+B15-B14>0,B15-B14,(B15-B14)>0)*800 -> 0 | E15: =IF(+D15-D14>0,D15-D14,(D15-D14)>0)*80 -> 0 | G15: =IF(+F15-F14>0,F15-F14,(F15-F14)>0)*10 -> 0 | I15: 19994136 | J15: =IF(I15>=I14,I15-I14,0) -> 6366 | K15: =M15+O15 -> 3944 | L15: 304871 | M15: =IF(L15>=L14,L15-L14,0) -> 2249 | N15: 375527 | O15: =IF(N15>=N14,N15-N14,0) -> 1695 | P15: 207500 | Q15: =IF(P15>=P14,P15-P14,0)*30 -> 720 | R15: 702925 | S15: =IF(R15>=R14,R15-R14,0) -> 0 | T15: 344001 | U15: =IF(T15>=T14,T15-T14,0) -> 0 | V15: 69310 | W15: =IF(V15>=V14,V15-V14,0) -> 146 | X15: 133864 | Y15: =IF(X15>=X14,X15-X14,0) -> 234 | Z15: 315108 | AA15: =IF(Z15>=Z14,Z15-Z14,0)*0.53 -> 0 | AB15: 489544 | AC15: =IF(AB15>=AB14,AB15-AB14,0)*0.53 -> 3710.53 | AD15: 449776 | AE15: =IF(AD15>=AD14,AD15-AD14,0)*0.53 -> 2958.46 | AF15: 575976 | AG15: =IF(AF15>=AF14,AF15-AF14,0)*0.53 -> 0 | AH15: 130684 | AI15: =IF(AH15>=AH14,AH15-AH14,0)*0.53 -> 582.47 | AJ15: 632848 | AK15: =IF(AJ15>=AJ14,AJ15-AJ14,0)*0.53 -> 3192.19 | AL15: =AA15+AC15+AE15+AG15+AI15+AK15 -> 10443.65 | AM15: 6761939 | AN15: =IF(AM15>=AM14,AM15-AM14,0) -> 1961 | AO15: 497558 | AP15: =IF(AO15>=AO14,AO15-AO14,0) -> 283 | AQ15: 843343 | AR15: =IF(AQ15>=AQ14,AQ15-AQ14,0)*0.11 -> 41.36 | AS15: 750782 | AT15: =IF(AS15>=AS14,AS15-AS14,0) -> 240 | AU15: 2027342 | AV15: =IF(AU15>=AU14,AU15-AU14,0) -> 939 | AW15: 187478 | AX15: =IF(AW15>=AW14,AW15-AW14,0) -> 70 | AY15: 15918760 | AZ15: =IF(AY15>=AY14,AY15-AY14,0) -> 6223 | BA15: 19336060 | BB15: =IF(BA15>=BA14,BA15-BA14,0)-(0.6*BG15)-(0.5*BI15)-BK15-BE15 -> 5845.5 | BC15: =AN15+AP15+AR15+AT15+AV15+AX15+AZ15+BB15 -> 15602.86 | BD15: 1323286 | BE15: =IF(BD15>=BD14,BD15-BD14,0) -> 0 | BF15: 2977369 | BG15: =IF(BF15>=BF14,BF15-BF14,0) -> 1360 | BH15: 330597 | BI15: =IF(BH15>=BH14,BH15-BH14,0) -> 93 | BJ15: 366515 | BK15: =IF(BJ15>=BJ14,BJ15-BJ14,0) -> 177 | BL15: =J15+Q15+AL15+BC15 -> 33132.51 | BM15: 225 | BN15: =IF(BL15>0,BL15/BM14,0) -> 143.43078 | BP15: =IF(BL15>0,BL15/BO15,0) -> #DIV/0! | BQ15: =BL15*BS1 -> 15240.955 | BR15: =IF(BQ15>0,BQ15/BM14,0) -> 65.978158 | BS15: =IF(BQ15>0,BQ15/BO15,0) -> #DIV/0!
A16: 11 | C16: =IF(+B16-B15>0,B16-B15,(B16-B15)>0)*800 -> 0 | E16: =IF(+D16-D15>0,D16-D15,(D16-D15)>0)*80 -> 0 | G16: =IF(+F16-F15>0,F16-F15,(F16-F15)>0)*10 -> 0 | H16: 61 | I16: 20000259 | J16: =IF(I16>=I15,I16-I15,0) -> 6123 | K16: =M16+O16 -> 3800 | L16: 307018 | M16: =IF(L16>=L15,L16-L15,0) -> 2147 | N16: 377180 | O16: =IF(N16>=N15,N16-N15,0) -> 1653 | P16: 207526 | Q16: =IF(P16>=P15,P16-P15,0)*30 -> 780 | R16: 702925 | S16: =IF(R16>=R15,R16-R15,0) -> 0 | T16: 344001 | U16: =IF(T16>=T15,T16-T15,0) -> 0 | V16: 69452 | W16: =IF(V16>=V15,V16-V15,0) -> 142 | X16: 134084 | Y16: =IF(X16>=X15,X16-X15,0) -> 220 | Z16: 315108 | AA16: =IF(Z16>=Z15,Z16-Z15,0)*0.53 -> 0 | AB16: 496512 | AC16: =IF(AB16>=AB15,AB16-AB15,0)*0.53 -> 3693.04 | AD16: 454601 | AE16: =IF(AD16>=AD15,AD16-AD15,0)*0.53 -> 2557.25 | AF16: 575972 | AG16: =IF(AF16>=AF15,AF16-AF15,0)*0.53 -> 0 | AH16: 131870 | AI16: =IF(AH16>=AH15,AH16-AH15,0)*0.53 -> 628.58 | AJ16: 638960 | AK16: =IF(AJ16>=AJ15,AJ16-AJ15,0)*0.53 -> 3239.36 | AL16: =AA16+AC16+AE16+AG16+AI16+AK16 -> 10118.23 | AM16: 6763537 | AN16: =IF(AM16>=AM15,AM16-AM15,0) -> 1598 | AO16: 497820 | AP16: =IF(AO16>=AO15,AO16-AO15,0) -> 262 | AQ16: 843700 | AR16: =IF(AQ16>=AQ15,AQ16-AQ15,0)*0.11 -> 39.27 | AS16: 751020 | AT16: =IF(AS16>=AS15,AS16-AS15,0) -> 238 | AU16: 2028100 | AV16: =IF(AU16>=AU15,AU16-AU15,0) -> 758 | AW16: 187545 | AX16: =IF(AW16>=AW15,AW16-AW15,0) -> 67 | AY16: 15924765 | AZ16: =IF(AY16>=AY15,AY16-AY15,0) -> 6005 | BA16: 19342703 | BB16: =IF(BA16>=BA15,BA16-BA15,0)-(0.6*BG16)-(0.5*BI16)-BK16-BE16 -> 5646.4 | BC16: =AN16+AP16+AR16+AT16+AV16+AX16+AZ16+BB16 -> 14613.67 | BD16: 1323286 | BE16: =IF(BD16>=BD15,BD16-BD15,0) -> 0 | BF16: 2978680 | BG16: =IF(BF16>=BF15,BF16-BF15,0) -> 1311 | BH16: 330675 | BI16: =IF(BH16>=BH15,BH16-BH15,0) -> 78 | BJ16: 366686 | BK16: =IF(BJ16>=BJ15,BJ16-BJ15,0) -> 171 | BL16: =J16+Q16+AL16+BC16 -> 31634.9 | BM16: 173 | BN16: =IF(BL16>0,BL16/BM15,0) -> 140.59956 | BP16: =IF(BL16>0,BL16/BO16,0) -> #DIV/0! | BQ16: =BL16*BS1 -> 14552.054 | BR16: =IF(BQ16>0,BQ16/BM15,0) -> 64.675796 | BS16: =IF(BQ16>0,BQ16/BO16,0) -> #DIV/0!
A17: 12 | C17: =IF(+B17-B16>0,B17-B16,(B17-B16)>0)*800 -> 0 | E17: =IF(+D17-D16>0,D17-D16,(D17-D16)>0)*80 -> 0 | G17: =IF(+F17-F16>0,F17-F16,(F17-F16)>0)*10 -> 0 | J17: =IF(I17>=I16,I17-I16,0) -> 0 | K17: =M17+O17 -> 0 | M17: =IF(L17>=L16,L17-L16,0) -> 0 | O17: =IF(N17>=N16,N17-N16,0) -> 0 | Q17: =IF(P17>=P16,P17-P16,0)*30 -> 0 | S17: =IF(R17>=R16,R17-R16,0) -> 0 | U17: =IF(T17>=T16,T17-T16,0) -> 0 | W17: =IF(V17>=V16,V17-V16,0) -> 0 | Y17: =IF(X17>=X16,X17-X16,0) -> 0 | AA17: =IF(Z17>=Z16,Z17-Z16,0)*0.53 -> 0 | AC17: =IF(AB17>=AB16,AB17-AB16,0)*0.53 -> 0 | AE17: =IF(AD17>=AD16,AD17-AD16,0)*0.53 -> 0 | AG17: =IF(AF17>=AF16,AF17-AF16,0)*0.53 -> 0 | AI17: =IF(AH17>=AH16,AH17-AH16,0)*0.53 -> 0 | AK17: =IF(AJ17>=AJ16,AJ17-AJ16,0)*0.53 -> 0 | AL17: =AA17+AC17+AE17+AG17+AI17+AK17 -> 0 | AN17: =IF(AM17>=AM16,AM17-AM16,0) -> 0 | AP17: =IF(AO17>=AO16,AO17-AO16,0) -> 0 | AR17: =IF(AQ17>=AQ16,AQ17-AQ16,0)*0.11 -> 0 | AT17: =IF(AS17>=AS16,AS17-AS16,0) -> 0 | AV17: =IF(AU17>=AU16,AU17-AU16,0) -> 0 | AX17: =IF(AW17>=AW16,AW17-AW16,0) -> 0 | AZ17: =IF(AY17>=AY16,AY17-AY16,0) -> 0 | BB17: =IF(BA17>=BA16,BA17-BA16,0)-(0.6*BG17)-(0.5*BI17)-BK17-BE17 -> 0 | BC17: =AN17+AP17+AR17+AT17+AV17+AX17+AZ17+BB17 -> 0 | BE17: =IF(BD17>=BF16,BD17-BF16,0) -> 0 | BG17: =IF(BF17>=BF16,BF17-BF16,0) -> 0 | BI17: =IF(BH17>=BH16,BH17-BH16,0) -> 0 | BK17: =IF(BJ17>=BJ16,BJ17-BJ16,0) -> 0 | BL17: =J17+Q17+AL17+BC17 -> 0 | BN17: =IF(BL17>0,BL17/BM16,0) -> 0 | BP17: =IF(BL17>0,BL17/BO17,0) -> 0 | BQ17: =BL17*BS1 -> 0 | BR17: =IF(BQ17>0,BQ17/BM16,0) -> 0 | BS17: =IF(BQ17>0,BQ17/BO17,0) -> 0
A18: 13 | C18: =IF(+B18-B17>0,B18-B17,(B18-B17)>0)*800 -> 0 | E18: =IF(+D18-D17>0,D18-D17,(D18-D17)>0)*80 -> 0 | G18: =IF(+F18-F17>0,F18-F17,(F18-F17)>0)*10 -> 0 | H18: 62 | J18: =IF(I18>=I17,I18-I17,0) -> 0 | K18: =M18+O18 -> 0 | M18: =IF(L18>=L17,L18-L17,0) -> 0 | O18: =IF(N18>=N17,N18-N17,0) -> 0 | Q18: =IF(P18>=P17,P18-P17,0)*30 -> 0 | S18: =IF(R18>=R17,R18-R17,0) -> 0 | U18: =IF(T18>=T17,T18-T17,0) -> 0 | W18: =IF(V18>=V17,V18-V17,0) -> 0 | Y18: =IF(X18>=X17,X18-X17,0) -> 0 | AA18: =IF(Z18>=Z17,Z18-Z17,0)*0.53 -> 0 | AC18: =IF(AB18>=AB17,AB18-AB17,0)*0.53 -> 0 | AE18: =IF(AD18>=AD17,AD18-AD17,0)*0.53 -> 0 | AG18: =IF(AF18>=AF17,AF18-AF17,0)*0.53 -> 0 | AI18: =IF(AH18>=AH17,AH18-AH17,0)*0.53 -> 0 | AK18: =IF(AJ18>=AJ17,AJ18-AJ17,0)*0.53 -> 0 | AL18: =AA18+AC18+AE18+AG18+AI18+AK18 -> 0 | AN18: =IF(AM18>=AM17,AM18-AM17,0) -> 0 | AP18: =IF(AO18>=AO17,AO18-AO17,0) -> 0 | AR18: =IF(AQ18>=AQ17,AQ18-AQ17,0)*0.11 -> 0 | AT18: =IF(AS18>=AS17,AS18-AS17,0) -> 0 | AV18: =IF(AU18>=AU17,AU18-AU17,0) -> 0 | AX18: =IF(AW18>=AW17,AW18-AW17,0) -> 0 | AZ18: =IF(AY18>=AY17,AY18-AY17,0) -> 0 | BB18: =IF(BA18>=BA17,BA18-BA17,0)-(0.6*BG18)-(0.5*BI18)-BK18-BE18 -> 0 | BC18: =AN18+AP18+AR18+AT18+AV18+AX18+AZ18+BB18 -> 0 | BE18: =IF(BD18>=BD17,BD18-BD17,0) -> 0 | BG18: =IF(BF18>=BF17,BF18-BF17,0) -> 0 | BI18: =IF(BH18>=BH17,BH18-BH17,0) -> 0 | BK18: =IF(BJ18>=BJ17,BJ18-BJ17,0) -> 0 | BL18: =J18+Q18+AL18+BC18 -> 0 | BN18: =IF(BL18>0,BL18/BM17,0) -> 0 | BP18: =IF(BL18>0,BL18/BO18,0) -> 0 | BQ18: =BL18*BS1 -> 0 | BR18: =IF(BQ18>0,BQ18/BM17,0) -> 0 | BS18: =IF(BQ18>0,BQ18/BO18,0) -> 0
A19: 14 | C19: =IF(+B19-B18>0,B19-B18,(B19-B18)>0)*800 -> 0 | E19: =IF(+D19-D18>0,D19-D18,(D19-D18)>0)*80 -> 0 | G19: =IF(+F19-F18>0,F19-F18,(F19-F18)>0)*10 -> 0 | J19: =IF(I19>=I18,I19-I18,0) -> 0 | K19: =M19+O19 -> 0 | M19: =IF(L19>=L18,L19-L18,0) -> 0 | O19: =IF(N19>=N18,N19-N18,0) -> 0 | Q19: =IF(P19>=P18,P19-P18,0)*30 -> 0 | S19: =IF(R19>=R18,R19-R18,0) -> 0 | U19: =IF(T19>=T18,T19-T18,0) -> 0 | W19: =IF(V19>=V18,V19-V18,0) -> 0 | Y19: =IF(X19>=X18,X19-X18,0) -> 0 | AA19: =IF(Z19>=Z18,Z19-Z18,0)*0.53 -> 0 | AC19: =IF(AB19>=AB18,AB19-AB18,0)*0.53 -> 0 | AE19: =IF(AD19>=AD18,AD19-AD18,0)*0.53 -> 0 | AG19: =IF(AF19>=AF18,AF19-AF18,0)*0.53 -> 0 | AI19: =IF(AH19>=AH18,AH19-AH18,0)*0.53 -> 0 | AK19: =IF(AJ19>=AJ18,AJ19-AJ18,0)*0.53 -> 0 | AL19: =AA19+AC19+AE19+AG19+AI19+AK19 -> 0 | AN19: =IF(AM19>=AM18,AM19-AM18,0) -> 0 | AP19: =IF(AO19>=AO18,AO19-AO18,0) -> 0 | AR19: =IF(AQ19>=AQ18,AQ19-AQ18,0)*0.11 -> 0 | AT19: =IF(AS19>=AS18,AS19-AS18,0) -> 0 | AV19: =IF(AU19>=AU18,AU19-AU18,0) -> 0 | AX19: =IF(AW19>=AW18,AW19-AW18,0) -> 0 | AZ19: =IF(AY19>=AY18,AY19-AY18,0) -> 0 | BB19: =IF(BA19>=BA18,BA19-BA18,0)-(0.6*BG19)-(0.5*BI19)-BK19-BE19 -> 0 | BC19: =AN19+AP19+AR19+AT19+AV19+AX19+AZ19+BB19 -> 0 | BE19: =IF(BD19>=BD18,BD19-BD18,0) -> 0 | BG19: =IF(BF19>=BF18,BF19-BF18,0) -> 0 | BI19: =IF(BH19>=BH18,BH19-BH18,0) -> 0 | BK19: =IF(BJ19>=BJ18,BJ19-BJ18,0) -> 0 | BL19: =J19+Q19+AL19+BC19 -> 0 | BN19: =IF(BL19>0,BL19/BM18,0) -> 0 | BP19: =IF(BL19>0,BL19/BO19,0) -> 0 | BQ19: =BL19*BS1 -> 0 | BR19: =IF(BQ19>0,BQ19/BM18,0) -> 0 | BS19: =IF(BQ19>0,BQ19/BO19,0) -> 0
A20: 15 | C20: =IF(+B20-B19>0,B20-B19,(B20-B19)>0)*800 -> 0 | E20: =IF(+D20-D19>0,D20-D19,(D20-D19)>0)*80 -> 0 | G20: =IF(+F20-F19>0,F20-F19,(F20-F19)>0)*10 -> 0 | H20: 63 | J20: =IF(I20>=I19,I20-I19,0) -> 0 | K20: =M20+O20 -> 0 | M20: =IF(L20>=L19,L20-L19,0) -> 0 | O20: =IF(N20>=N19,N20-N19,0) -> 0 | Q20: =IF(P20>=P19,P20-P19,0)*30 -> 0 | S20: =IF(R20>=R19,R20-R19,0) -> 0 | U20: =IF(T20>=T19,T20-T19,0) -> 0 | W20: =IF(V20>=V19,V20-V19,0) -> 0 | Y20: =IF(X20>=X19,X20-X19,0) -> 0 | AA20: =IF(Z20>=Z19,Z20-Z19,0)*0.53 -> 0 | AC20: =IF(AB20>=AB19,AB20-AB19,0)*0.53 -> 0 | AE20: =IF(AD20>=AD19,AD20-AD19,0)*0.53 -> 0 | AG20: =IF(AF20>=AF19,AF20-AF19,0)*0.53 -> 0 | AI20: =IF(AH20>=AH19,AH20-AH19,0)*0.53 -> 0 | AK20: =IF(AJ20>=AJ19,AJ20-AJ19,0)*0.53 -> 0 | AL20: =AA20+AC20+AE20+AG20+AI20+AK20 -> 0 | AN20: =IF(AM20>=AM19,AM20-AM19,0) -> 0 | AP20: =IF(AO20>=AO19,AO20-AO19,0) -> 0 | AR20: =IF(AQ20>=AQ19,AQ20-AQ19,0)*0.11 -> 0 | AT20: =IF(AS20>=AS19,AS20-AS19,0) -> 0 | AV20: =IF(AU20>=AU19,AU20-AU19,0) -> 0 | AX20: =IF(AW20>=AW19,AW20-AW19,0) -> 0 | AZ20: =IF(AY20>=AY19,AY20-AY19,0) -> 0 | BB20: =IF(BA20>=BA19,BA20-BA19,0)-(0.6*BG20)-(0.5*BI20)-BK20-BE20 -> 0 | BC20: =AN20+AP20+AR20+AT20+AV20+AX20+AZ20+BB20 -> 0 | BE20: =IF(BD20>=BD19,BD20-BD19,0) -> 0 | BG20: =IF(BF20>=BF19,BF20-BF19,0) -> 0 | BI20: =IF(BH20>=BH19,BH20-BH19,0) -> 0 | BK20: =IF(BJ20>=BJ19,BJ20-BJ19,0) -> 0 | BL20: =J20+Q20+AL20+BC20 -> 0 | BN20: =IF(BL20>0,BL20/BM20,0) -> 0 | BP20: =IF(BL20>0,BL20/BO20,0) -> 0 | BQ20: =BL20*BS1 -> 0 | BR20: =IF(BQ20>0,BQ20/BM20,0) -> 0 | BS20: =IF(BQ20>0,BQ20/BO20,0) -> 0
A21: 16 | C21: =IF(+B21-B20>0,B21-B20,(B21-B20)>0)*800 -> 0 | E21: =IF(+D21-D20>0,D21-D20,(D21-D20)>0)*80 -> 0 | G21: =IF(+F21-F20>0,F21-F20,(F21-F20)>0)*10 -> 0 | J21: =IF(I21>=I20,I21-I20,0) -> 0 | K21: =M21+O21 -> 0 | M21: =IF(L21>=L20,L21-L20,0) -> 0 | O21: =IF(N21>=N20,N21-N20,0) -> 0 | Q21: =IF(P21>=P20,P21-P20,0)*30 -> 0 | S21: =IF(R21>=R20,R21-R20,0) -> 0 | U21: =IF(T21>=T20,T21-T20,0) -> 0 | W21: =IF(V21>=V20,V21-V20,0) -> 0 | Y21: =IF(X21>=X20,X21-X20,0) -> 0 | AA21: =IF(Z21>=Z20,Z21-Z20,0)*0.53 -> 0 | AC21: =IF(AB21>=AB20,AB21-AB20,0)*0.53 -> 0 | AE21: =IF(AD21>=AD20,AD21-AD20,0)*0.53 -> 0 | AG21: =IF(AF21>=AF20,AF21-AF20,0)*0.53 -> 0 | AI21: =IF(AH21>=AH20,AH21-AH20,0)*0.53 -> 0 | AK21: =IF(AJ21>=AJ20,AJ21-AJ20,0)*0.53 -> 0 | AL21: =AA21+AC21+AE21+AG21+AI21+AK21 -> 0 | AN21: =IF(AM21>=AM20,AM21-AM20,0) -> 0 | AP21: =IF(AO21>=AO20,AO21-AO20,0) -> 0 | AR21: =IF(AQ21>=AQ20,AQ21-AQ20,0)*0.11 -> 0 | AT21: =IF(AS21>=AS20,AS21-AS20,0) -> 0 | AV21: =IF(AU21>=AU20,AU21-AU20,0) -> 0 | AX21: =IF(AW21>=AW20,AW21-AW20,0) -> 0 | AZ21: =IF(AY21>=AY20,AY21-AY20,0) -> 0 | BB21: =IF(BA21>=BA20,BA21-BA20,0)-(0.6*BG21)-(0.5*BI21)-BK21-BE21 -> 0 | BC21: =AN21+AP21+AR21+AT21+AV21+AX21+AZ21+BB21 -> 0 | BE21: =IF(BD21>=BD20,BD21-BD20,0) -> 0 | BG21: =IF(BF21>=BF20,BF21-BF20,0) -> 0 | BI21: =IF(BH21>=BH20,BH21-BH20,0) -> 0 | BK21: =IF(BJ21>=BJ20,BJ21-BJ20,0) -> 0 | BL21: =J21+Q21+AL21+BC21 -> 0 | BN21: =IF(BL21>0,BL21/BM21,0) -> 0 | BP21: =IF(BL21>0,BL21/BO21,0) -> 0 | BQ21: =BL21*BS1 -> 0 | BR21: =IF(BQ21>0,BQ21/BM21,0) -> 0 | BS21: =IF(BQ21>0,BQ21/BO21,0) -> 0
A22: 17 | C22: =IF(+B22-B21>0,B22-B21,(B22-B21)>0)*800 -> 0 | E22: =IF(+D22-D21>0,D22-D21,(D22-D21)>0)*80 -> 0 | G22: =IF(+F22-F21>0,F22-F21,(F22-F21)>0)*10 -> 0 | H22: 64 | J22: =IF(I22>=I21,I22-I21,0) -> 0 | K22: =M22+O22 -> 0 | M22: =IF(L22>=L21,L22-L21,0) -> 0 | O22: =IF(N22>=N21,N22-N21,0) -> 0 | Q22: =IF(P22>=P21,P22-P21,0)*30 -> 0 | S22: =IF(R22>=R21,R22-R21,0) -> 0 | U22: =IF(T22>=T21,T22-T21,0) -> 0 | W22: =IF(V22>=V21,V22-V21,0) -> 0 | Y22: =IF(X22>=X21,X22-X21,0) -> 0 | AA22: =IF(Z22>=Z21,Z22-Z21,0)*0.53 -> 0 | AC22: =IF(AB22>=AB21,AB22-AB21,0)*0.53 -> 0 | AE22: =IF(AD22>=AD21,AD22-AD21,0)*0.53 -> 0 | AG22: =IF(AF22>=AF21,AF22-AF21,0)*0.53 -> 0 | AI22: =IF(AH22>=AH21,AH22-AH21,0)*0.53 -> 0 | AK22: =IF(AJ22>=AJ21,AJ22-AJ21,0)*0.53 -> 0 | AL22: =AA22+AC22+AE22+AG22+AI22+AK22 -> 0 | AN22: =IF(AM22>=AM21,AM22-AM21,0) -> 0 | AP22: =IF(AO22>=AO21,AO22-AO21,0) -> 0 | AR22: =IF(AQ22>=AQ21,AQ22-AQ21,0)*0.11 -> 0 | AT22: =IF(AS22>=AS21,AS22-AS21,0) -> 0 | AV22: =IF(AU22>=AU21,AU22-AU21,0) -> 0 | AX22: =IF(AW22>=AW21,AW22-AW21,0) -> 0 | AZ22: =IF(AY22>=AY21,AY22-AY21,0) -> 0 | BB22: =IF(BA22>=BA21,BA22-BA21,0)-(0.6*BG22)-(0.5*BI22)-BK22-BE22 -> 0 | BC22: =AN22+AP22+AR22+AT22+AV22+AX22+AZ22+BB22 -> 0 | BE22: =IF(BD22>=BD21,BD22-BD21,0) -> 0 | BG22: =IF(BF22>=BF21,BF22-BF21,0) -> 0 | BI22: =IF(BH22>=BH21,BH22-BH21,0) -> 0 | BK22: =IF(BJ22>=BJ21,BJ22-BJ21,0) -> 0 | BL22: =J22+Q22+AL22+BC22 -> 0 | BN22: =IF(BL22>0,BL22/BM22,0) -> 0 | BP22: =IF(BL22>0,BL22/BO22,0) -> 0 | BQ22: =BL22*BS1 -> 0 | BR22: =IF(BQ22>0,BQ22/BM22,0) -> 0 | BS22: =IF(BQ22>0,BQ22/BO22,0) -> 0
A23: 18 | C23: =IF(+B23-B22>0,B23-B22,(B23-B22)>0)*800 -> 0 | E23: =IF(+D23-D22>0,D23-D22,(D23-D22)>0)*80 -> 0 | G23: =IF(+F23-F22>0,F23-F22,(F23-F22)>0)*10 -> 0 | J23: =IF(I23>=I22,I23-I22,0) -> 0 | K23: =M23+O23 -> 0 | M23: =IF(L23>=L22,L23-L22,0) -> 0 | O23: =IF(N23>=N22,N23-N22,0) -> 0 | Q23: =IF(P23>=P22,P23-P22,0)*30 -> 0 | S23: =IF(R23>=R22,R23-R22,0) -> 0 | U23: =IF(T23>=T22,T23-T22,0) -> 0 | W23: =IF(V23>=V22,V23-V22,0) -> 0 | Y23: =IF(X23>=X22,X23-X22,0) -> 0 | AA23: =IF(Z23>=Z22,Z23-Z22,0)*0.53 -> 0 | AC23: =IF(AB23>=AB22,AB23-AB22,0)*0.53 -> 0 | AE23: =IF(AD23>=AD22,AD23-AD22,0)*0.53 -> 0 | AG23: =IF(AF23>=AF22,AF23-AF22,0)*0.53 -> 0 | AI23: =IF(AH23>=AH22,AH23-AH22,0)*0.53 -> 0 | AK23: =IF(AJ23>=AJ22,AJ23-AJ22,0)*0.53 -> 0 | AL23: =AA23+AC23+AE23+AG23+AI23+AK23 -> 0 | AN23: =IF(AM23>=AM22,AM23-AM22,0) -> 0 | AP23: =IF(AO23>=AO22,AO23-AO22,0) -> 0 | AR23: =IF(AQ23>=AQ22,AQ23-AQ22,0)*0.11 -> 0 | AT23: =IF(AS23>=AS22,AS23-AS22,0) -> 0 | AV23: =IF(AU23>=AU22,AU23-AU22,0) -> 0 | AX23: =IF(AW23>=AW22,AW23-AW22,0) -> 0 | AZ23: =IF(AY23>=AY22,AY23-AY22,0) -> 0 | BB23: =IF(BA23>=BA22,BA23-BA22,0)-(0.6*BG23)-(0.5*BI23)-BK23-BE23 -> 0 | BC23: =AN23+AP23+AR23+AT23+AV23+AX23+AZ23+BB23 -> 0 | BE23: =IF(BD23>=BD22,BD23-BD22,0) -> 0 | BG23: =IF(BF23>=BF22,BF23-BF22,0) -> 0 | BI23: =IF(BH23>=BH22,BH23-BH22,0) -> 0 | BK23: =IF(BJ23>=BJ22,BJ23-BJ22,0) -> 0 | BL23: =J23+Q23+AL23+BC23 -> 0 | BN23: =IF(BL23>0,BL23/BM23,0) -> 0 | BP23: =IF(BL23>0,BL23/BO23,0) -> 0 | BQ23: =BL23*BS1 -> 0 | BR23: =IF(BQ23>0,BQ23/BM23,0) -> 0 | BS23: =IF(BQ23>0,BQ23/BO23,0) -> 0
A24: 19 | C24: =IF(+B24-B23>0,B24-B23,(B24-B23)>0)*800 -> 0 | E24: =IF(+D24-D23>0,D24-D23,(D24-D23)>0)*80 -> 0 | G24: =IF(+F24-F23>0,F24-F23,(F24-F23)>0)*10 -> 0 | H24: 65 | J24: =IF(I24>=I23,I24-I23,0) -> 0 | K24: =M24+O24 -> 0 | M24: =IF(L24>=L23,L24-L23,0) -> 0 | O24: =IF(N24>=N23,N24-N23,0) -> 0 | Q24: =IF(P24>=P23,P24-P23,0)*30 -> 0 | S24: =IF(R24>=R23,R24-R23,0) -> 0 | U24: =IF(T24>=T23,T24-T23,0) -> 0 | W24: =IF(V24>=V23,V24-V23,0) -> 0 | Y24: =IF(X24>=X23,X24-X23,0) -> 0 | AA24: =IF(Z24>=Z23,Z24-Z23,0)*0.53 -> 0 | AC24: =IF(AB24>=AB23,AB24-AB23,0)*0.53 -> 0 | AE24: =IF(AD24>=AD23,AD24-AD23,0)*0.53 -> 0 | AG24: =IF(AF24>=AF23,AF24-AF23,0)*0.53 -> 0 | AI24: =IF(AH24>=AH23,AH24-AH23,0)*0.53 -> 0 | AK24: =IF(AJ24>=AJ23,AJ24-AJ23,0)*0.53 -> 0 | AL24: =AA24+AC24+AE24+AG24+AI24+AK24 -> 0 | AN24: =IF(AM24>=AM23,AM24-AM23,0) -> 0 | AP24: =IF(AO24>=AO23,AO24-AO23,0) -> 0 | AR24: =IF(AQ24>=AQ23,AQ24-AQ23,0)*0.11 -> 0 | AT24: =IF(AS24>=AS23,AS24-AS23,0) -> 0 | AV24: =IF(AU24>=AU23,AU24-AU23,0) -> 0 | AX24: =IF(AW24>=AW23,AW24-AW23,0) -> 0 | AZ24: =IF(AY24>=AY23,AY24-AY23,0) -> 0 | BB24: =IF(BA24>=BA23,BA24-BA23,0)-(0.6*BG24)-(0.5*BI24)-BK24-BE24 -> 0 | BC24: =AN24+AP24+AR24+AT24+AV24+AX24+AZ24+BB24 -> 0 | BE24: =IF(BD24>=BD23,BD24-BD23,0) -> 0 | BG24: =IF(BF24>=BF23,BF24-BF23,0) -> 0 | BI24: =IF(BH24>=BH23,BH24-BH23,0) -> 0 | BK24: =IF(BJ24>=BJ23,BJ24-BJ23,0) -> 0 | BL24: =J24+Q24+AL24+BC24 -> 0 | BN24: =IF(BL24>0,BL24/BM24,0) -> 0 | BP24: =IF(BL24>0,BL24/BO24,0) -> 0 | BQ24: =BL24*BS1 -> 0 | BR24: =IF(BQ24>0,BQ24/BM24,0) -> 0 | BS24: =IF(BQ24>0,BQ24/BO24,0) -> 0
A25: 20 | C25: =IF(+B25-B24>0,B25-B24,(B25-B24)>0)*800 -> 0 | E25: =IF(+D25-D24>0,D25-D24,(D25-D24)>0)*80 -> 0 | G25: =IF(+F25-F24>0,F25-F24,(F25-F24)>0)*10 -> 0 | J25: =IF(I25>=I24,I25-I24,0) -> 0 | K25: =M25+O25 -> 0 | M25: =IF(L25>=L24,L25-L24,0) -> 0 | O25: =IF(N25>=N24,N25-N24,0) -> 0 | Q25: =IF(P25>=P24,P25-P24,0)*30 -> 0 | S25: =IF(R25>=R24,R25-R24,0) -> 0 | U25: =IF(T25>=T24,T25-T24,0) -> 0 | W25: =IF(V25>=V24,V25-V24,0) -> 0 | Y25: =IF(X25>=X24,X25-X24,0) -> 0 | AA25: =IF(Z25>=Z24,Z25-Z24,0)*0.53 -> 0 | AC25: =IF(AB25>=AB24,AB25-AB24,0)*0.53 -> 0 | AE25: =IF(AD25>=AD24,AD25-AD24,0)*0.53 -> 0 | AG25: =IF(AF25>=AF24,AF25-AF24,0)*0.53 -> 0 | AI25: =IF(AH25>=AH24,AH25-AH24,0)*0.53 -> 0 | AK25: =IF(AJ25>=AJ24,AJ25-AJ24,0)*0.53 -> 0 | AL25: =AA25+AC25+AE25+AG25+AI25+AK25 -> 0 | AN25: =IF(AM25>=AM24,AM25-AM24,0) -> 0 | AP25: =IF(AO25>=AO24,AO25-AO24,0) -> 0 | AR25: =IF(AQ25>=AQ24,AQ25-AQ24,0)*0.11 -> 0 | AT25: =IF(AS25>=AS24,AS25-AS24,0) -> 0 | AV25: =IF(AU25>=AU24,AU25-AU24,0) -> 0 | AX25: =IF(AW25>=AW24,AW25-AW24,0) -> 0 | AZ25: =IF(AY25>=AY24,AY25-AY24,0) -> 0 | BB25: =IF(BA25>=BA24,BA25-BA24,0)-(0.6*BG25)-(0.5*BI25)-BK25-BE25 -> 0 | BC25: =AN25+AP25+AR25+AT25+AV25+AX25+AZ25+BB25 -> 0 | BE25: =IF(BD25>=BD24,BD25-BD24,0) -> 0 | BG25: =IF(BF25>=BF24,BF25-BF24,0) -> 0 | BI25: =IF(BH25>=BH24,BH25-BH24,0) -> 0 | BK25: =IF(BJ25>=BJ24,BJ25-BJ24,0) -> 0 | BL25: =J25+Q25+AL25+BC25 -> 0 | BN25: =IF(BL25>0,BL25/BM25,0) -> 0 | BP25: =IF(BL25>0,BL25/BO25,0) -> 0 | BQ25: =BL25*BS1 -> 0 | BR25: =IF(BQ25>0,BQ25/BM25,0) -> 0 | BS25: =IF(BQ25>0,BQ25/BO25,0) -> 0
A26: 21 | C26: =IF(+B26-B25>0,B26-B25,(B26-B25)>0)*800 -> 0 | E26: =IF(+D26-D25>0,D26-D25,(D26-D25)>0)*80 -> 0 | G26: =IF(+F26-F25>0,F26-F25,(F26-F25)>0)*10 -> 0 | H26: 66 | J26: =IF(I26>=I25,I26-I25,0) -> 0 | K26: =M26+O26 -> 0 | M26: =IF(L26>=L25,L26-L25,0) -> 0 | O26: =IF(N26>=N25,N26-N25,0) -> 0 | Q26: =IF(P26>=P25,P26-P25,0)*30 -> 0 | S26: =IF(R26>=R25,R26-R25,0) -> 0 | U26: =IF(T26>=T25,T26-T25,0) -> 0 | W26: =IF(V26>=V25,V26-V25,0) -> 0 | Y26: =IF(X26>=X25,X26-X25,0) -> 0 | AA26: =IF(Z26>=Z25,Z26-Z25,0)*0.53 -> 0 | AC26: =IF(AB26>=AB25,AB26-AB25,0)*0.53 -> 0 | AE26: =IF(AD26>=AD25,AD26-AD25,0)*0.53 -> 0 | AG26: =IF(AF26>=AF25,AF26-AF25,0)*0.53 -> 0 | AI26: =IF(AH26>=AH25,AH26-AH25,0)*0.53 -> 0 | AK26: =IF(AJ26>=AJ25,AJ26-AJ25,0)*0.53 -> 0 | AL26: =AA26+AC26+AE26+AG26+AI26+AK26 -> 0 | AN26: =IF(AM26>=AM25,AM26-AM25,0) -> 0 | AP26: =IF(AO26>=AO25,AO26-AO25,0) -> 0 | AR26: =IF(AQ26>=AQ25,AQ26-AQ25,0)*0.11 -> 0 | AT26: =IF(AS26>=AS25,AS26-AS25,0) -> 0 | AV26: =IF(AU26>=AU25,AU26-AU25,0) -> 0 | AX26: =IF(AW26>=AW25,AW26-AW25,0) -> 0 | AZ26: =IF(AY26>=AY25,AY26-AY25,0) -> 0 | BB26: =IF(BA26>=BA25,BA26-BA25,0)-(0.6*BG26)-(0.5*BI26)-BK26-BE26 -> 0 | BC26: =AN26+AP26+AR26+AT26+AV26+AX26+AZ26+BB26 -> 0 | BE26: =IF(BD26>=BD25,BD26-BD25,0) -> 0 | BG26: =IF(BF26>=BF25,BF26-BF25,0) -> 0 | BI26: =IF(BH26>=BH25,BH26-BH25,0) -> 0 | BK26: =IF(BJ26>=BJ25,BJ26-BJ25,0) -> 0 | BL26: =J26+Q26+AL26+BC26 -> 0 | BN26: =IF(BL26>0,BL26/BM26,0) -> 0 | BP26: =IF(BL26>0,BL26/BO26,0) -> 0 | BQ26: =BL26*BS1 -> 0 | BR26: =IF(BQ26>0,BQ26/BM26,0) -> 0 | BS26: =IF(BQ26>0,BQ26/BO26,0) -> 0
A27: 22 | C27: =IF(+B27-B26>0,B27-B26,(B27-B26)>0)*800 -> 0 | E27: =IF(+D27-D26>0,D27-D26,(D27-D26)>0)*80 -> 0 | G27: =IF(+F27-F26>0,F27-F26,(F27-F26)>0)*10 -> 0 | J27: =IF(I27>=I26,I27-I26,0) -> 0 | K27: =M27+O27 -> 0 | M27: =IF(L27>=L26,L27-L26,0) -> 0 | O27: =IF(N27>=N26,N27-N26,0) -> 0 | Q27: =IF(P27>=P26,P27-P26,0)*30 -> 0 | S27: =IF(R27>=R26,R27-R26,0) -> 0 | U27: =IF(T27>=T26,T27-T26,0) -> 0 | W27: =IF(V27>=V26,V27-V26,0) -> 0 | Y27: =IF(X27>=X26,X27-X26,0) -> 0 | AA27: =IF(Z27>=Z26,Z27-Z26,0)*0.53 -> 0 | AC27: =IF(AB27>=AB26,AB27-AB26,0)*0.53 -> 0 | AE27: =IF(AD27>=AD26,AD27-AD26,0)*0.53 -> 0 | AG27: =IF(AF27>=AF26,AF27-AF26,0)*0.53 -> 0 | AI27: =IF(AH27>=AH26,AH27-AH26,0)*0.53 -> 0 | AK27: =IF(AJ27>=AJ26,AJ27-AJ26,0)*0.53 -> 0 | AL27: =AA27+AC27+AE27+AG27+AI27+AK27 -> 0 | AN27: =IF(AM27>=AM26,AM27-AM26,0) -> 0 | AP27: =IF(AO27>=AO26,AO27-AO26,0) -> 0 | AR27: =IF(AQ27>=AQ26,AQ27-AQ26,0)*0.11 -> 0 | AT27: =IF(AS27>=AS26,AS27-AS26,0) -> 0 | AV27: =IF(AU27>=AU26,AU27-AU26,0) -> 0 | AX27: =IF(AW27>=AW26,AW27-AW26,0) -> 0 | AZ27: =IF(AY27>=AY26,AY27-AY26,0) -> 0 | BB27: =IF(BA27>=BA26,BA27-BA26,0)-(0.6*BG27)-(0.5*BI27)-BK27-BE27 -> 0 | BC27: =AN27+AP27+AR27+AT27+AV27+AX27+AZ27+BB27 -> 0 | BE27: =IF(BD27>=BD26,BD27-BD26,0) -> 0 | BG27: =IF(BF27>=BF26,BF27-BF26,0) -> 0 | BI27: =IF(BH27>=BH26,BH27-BH26,0) -> 0 | BK27: =IF(BJ27>=BJ26,BJ27-BJ26,0) -> 0 | BL27: =J27+Q27+AL27+BC27 -> 0 | BN27: =IF(BL27>0,BL27/BM27,0) -> 0 | BP27: =IF(BL27>0,BL27/BO27,0) -> 0 | BQ27: =BL27*BS1 -> 0 | BR27: =IF(BQ27>0,BQ27/BM27,0) -> 0 | BS27: =IF(BQ27>0,BQ27/BO27,0) -> 0
A28: 23 | C28: =IF(+B28-B27>0,B28-B27,(B28-B27)>0)*800 -> 0 | E28: =IF(+D28-D27>0,D28-D27,(D28-D27)>0)*80 -> 0 | G28: =IF(+F28-F27>0,F28-F27,(F28-F27)>0)*10 -> 0 | H28: 67 | J28: =IF(I28>=I27,I28-I27,0) -> 0 | K28: =M28+O28 -> 0 | M28: =IF(L28>=L27,L28-L27,0) -> 0 | O28: =IF(N28>=N27,N28-N27,0) -> 0 | Q28: =IF(P28>=P27,P28-P27,0)*30 -> 0 | S28: =IF(R28>=R27,R28-R27,0) -> 0 | U28: =IF(T28>=T27,T28-T27,0) -> 0 | W28: =IF(V28>=V27,V28-V27,0) -> 0 | Y28: =IF(X28>=X27,X28-X27,0) -> 0 | AA28: =IF(Z28>=Z27,Z28-Z27,0)*0.53 -> 0 | AC28: =IF(AB28>=AB27,AB28-AB27,0)*0.53 -> 0 | AE28: =IF(AD28>=AD27,AD28-AD27,0)*0.53 -> 0 | AG28: =IF(AF28>=AF27,AF28-AF27,0)*0.53 -> 0 | AI28: =IF(AH28>=AH27,AH28-AH27,0)*0.53 -> 0 | AK28: =IF(AJ28>=AJ27,AJ28-AJ27,0)*0.53 -> 0 | AL28: =AA28+AC28+AE28+AG28+AI28+AK28 -> 0 | AN28: =IF(AM28>=AM27,AM28-AM27,0) -> 0 | AP28: =IF(AO28>=AO27,AO28-AO27,0) -> 0 | AR28: =IF(AQ28>=AQ27,AQ28-AQ27,0)*0.11 -> 0 | AT28: =IF(AS28>=AS27,AS28-AS27,0) -> 0 | AV28: =IF(AU28>=AU27,AU28-AU27,0) -> 0 | AX28: =IF(AW28>=AW27,AW28-AW27,0) -> 0 | AZ28: =IF(AY28>=AY27,AY28-AY27,0) -> 0 | BB28: =IF(BA28>=BA27,BA28-BA27,0)-(0.6*BG28)-(0.5*BI28)-BK28-BE28 -> 0 | BC28: =AN28+AP28+AR28+AT28+AV28+AX28+AZ28+BB28 -> 0 | BE28: =IF(BD28>=BD27,BD28-BD27,0) -> 0 | BG28: =IF(BF28>=BF27,BF28-BF27,0) -> 0 | BI28: =IF(BH28>=BH27,BH28-BH27,0) -> 0 | BK28: =IF(BJ28>=BJ27,BJ28-BJ27,0) -> 0 | BL28: =J28+Q28+AL28+BC28 -> 0 | BN28: =IF(BL28>0,BL28/BM28,0) -> 0 | BP28: =IF(BL28>0,BL28/BO28,0) -> 0 | BQ28: =BL28*BS1 -> 0 | BR28: =IF(BQ28>0,BQ28/BM28,0) -> 0 | BS28: =IF(BQ28>0,BQ28/BO28,0) -> 0
