Workbook

Sheet Total
A1: Site Name | B1: Day | C1: Month | D1: Year | E1: Total Electricity Kwh | F1: Electricity Tariff ($/Kwh) | G1: LPG (Kg) | H1: LPG $/Kg | I1: Water Utility Supply (m3) m3 | J1: Water Utility Supply (m3) $/m3 | K1: Room Nights | L1: Utilities day cost dh
A2: Serengeti | B2: 1 | C2: 11 | D2: 2019 | E2: ='UTILITY REPORT 1'!F3 -> 5703 | F2: =('UTILITY REPORT 1'!E3*'UTILITY REPORT 1'!D3)/'UTILITY REPORT 1'!F3 -> 0.42050149 | G2: =IF('Utility summery'!M6<0,"0",'Utility summery'!M6) -> 208.34 | H2: 0 | I2: =IF('UTILITY REPORT 1'!G3<0,"0",'UTILITY REPORT 1'!G3) -> 128 | J2: 0 | K2: ='UTILITY REPORT 1'!C3 -> 66 | L2: =E2*F2+G2*H2+#REF!*#REF!+I2*J2 -> #REF!
A3: Serengeti | B3: =B2+1 -> 2 | C3: 11 | D3: 2019 | E3: ='UTILITY REPORT 1'!F4 -> 6052 | F3: =('UTILITY REPORT 1'!E4*'UTILITY REPORT 1'!D4)/'UTILITY REPORT 1'!F4 -> 0.41351124 | G3: =IF('Utility summery'!M7<0,"0",'Utility summery'!M7) -> 101.376 | H3: 0 | I3: =IF('UTILITY REPORT 1'!G4<0,"0",'UTILITY REPORT 1'!G4) -> 139 | J3: 0 | K3: ='UTILITY REPORT 1'!C4 -> 58 | L3: =E3*F3+G3*H3+#REF!*#REF!+I3*J3 -> #REF!
A4: Serengeti | B4: =B3+1 -> 3 | C4: 11 | D4: 2019 | E4: ='UTILITY REPORT 1'!F5 -> 5227 | F4: =('UTILITY REPORT 1'!E5*'UTILITY REPORT 1'!D5)/'UTILITY REPORT 1'!F5 -> 0.39924048 | G4: =IF('Utility summery'!M8<0,"0",'Utility summery'!M8) -> 101.464 | H4: 0 | I4: =IF('UTILITY REPORT 1'!G5<0,"0",'UTILITY REPORT 1'!G5) -> 132 | J4: 0 | K4: ='UTILITY REPORT 1'!C5 -> 9 | L4: =E4*F4+G4*H4+#REF!*#REF!+I4*J4 -> #REF!
A5: Serengeti | B5: =B4+1 -> 4 | C5: 11 | D5: 2019 | E5: ='UTILITY REPORT 1'!F6 -> 4812 | F5: =('UTILITY REPORT 1'!E6*'UTILITY REPORT 1'!D6)/'UTILITY REPORT 1'!F6 -> 0.38117415 | G5: =IF('Utility summery'!M9<0,"0",'Utility summery'!M9) -> 132.616 | H5: 0 | I5: =IF('UTILITY REPORT 1'!G6<0,"0",'UTILITY REPORT 1'!G6) -> 100 | J5: 0 | K5: ='UTILITY REPORT 1'!C6 -> 10 | L5: =E5*F5+G5*H5+#REF!*#REF!+I5*J5 -> #REF!
A6: Serengeti | B6: =B5+1 -> 5 | C6: 11 | D6: 2019 | E6: ='UTILITY REPORT 1'!F7 -> 5035 | F6: =('UTILITY REPORT 1'!E7*'UTILITY REPORT 1'!D7)/'UTILITY REPORT 1'!F7 -> 0.42059583 | G6: =IF('Utility summery'!M10<0,"0",'Utility summery'!M10) -> 147.18 | H6: 0 | I6: =IF('UTILITY REPORT 1'!G7<0,"0",'UTILITY REPORT 1'!G7) -> 119 | J6: 0 | K6: ='UTILITY REPORT 1'!C7 -> 25 | L6: =E6*F6+G6*H6+#REF!*#REF!+I6*J6 -> #REF!
A7: Serengeti | B7: =B6+1 -> 6 | C7: 11 | D7: 2019 | E7: ='UTILITY REPORT 1'!F8 -> 5420 | F7: =('UTILITY REPORT 1'!E8*'UTILITY REPORT 1'!D8)/'UTILITY REPORT 1'!F8 -> 0.44939668 | G7: =IF('Utility summery'!M11<0,"0",'Utility summery'!M11) -> 144.672 | H7: 0 | I7: =IF('UTILITY REPORT 1'!G8<0,"0",'UTILITY REPORT 1'!G8) -> 110 | J7: 0 | K7: ='UTILITY REPORT 1'!C8 -> 24 | L7: =E7*F7+G7*H7+#REF!*#REF!+I7*J7 -> #REF!
A8: Serengeti | B8: =B7+1 -> 7 | C8: 11 | D8: 2019 | E8: ='UTILITY REPORT 1'!F9 -> 5338 | F8: =('UTILITY REPORT 1'!E9*'UTILITY REPORT 1'!D9)/'UTILITY REPORT 1'!F9 -> 0.41775197 | G8: =IF('Utility summery'!M12<0,"0",'Utility summery'!M12) -> 149.072 | H8: 0 | I8: =IF('UTILITY REPORT 1'!G9<0,"0",'UTILITY REPORT 1'!G9) -> 95 | J8: 0 | K8: ='UTILITY REPORT 1'!C9 -> 17 | L8: =E8*F8+G8*H8+#REF!*#REF!+I8*J8 -> #REF!
A9: Serengeti | B9: =B8+1 -> 8 | C9: 11 | D9: 2019 | E9: ='UTILITY REPORT 1'!F10 -> 5670 | F9: =('UTILITY REPORT 1'!E10*'UTILITY REPORT 1'!D10)/'UTILITY REPORT 1'!F10 -> 0.37044974 | G9: =IF('Utility summery'!M13<0,"0",'Utility summery'!M13) -> 152.064 | H9: 0 | I9: =IF('UTILITY REPORT 1'!G10<0,"0",'UTILITY REPORT 1'!G10) -> 120 | J9: 0 | K9: ='UTILITY REPORT 1'!C10 -> 13 | L9: =E9*F9+G9*H9+#REF!*#REF!+I9*J9 -> #REF!
A10: Serengeti | B10: =B9+1 -> 9 | C10: 11 | D10: 2019 | E10: ='UTILITY REPORT 1'!F11 -> 5594 | F10: =('UTILITY REPORT 1'!E11*'UTILITY REPORT 1'!D11)/'UTILITY REPORT 1'!F11 -> 0.3807955 | G10: =IF('Utility summery'!M14<0,"0",'Utility summery'!M14) -> 152.284 | H10: 0 | I10: =IF('UTILITY REPORT 1'!G11<0,"0",'UTILITY REPORT 1'!G11) -> 96 | J10: 0 | K10: ='UTILITY REPORT 1'!C11 -> 13 | L10: =E10*F10+G10*H10+#REF!*#REF!+I10*J10 -> #REF!
A11: Serengeti | B11: =B10+1 -> 10 | C11: 11 | D11: 2019 | E11: ='UTILITY REPORT 1'!F12 -> 5487 | F11: =('UTILITY REPORT 1'!E12*'UTILITY REPORT 1'!D12)/'UTILITY REPORT 1'!F12 -> 0.4085657 | G11: =IF('Utility summery'!M15<0,"0",'Utility summery'!M15) -> 103.488 | H11: 0 | I11: =IF('UTILITY REPORT 1'!G12<0,"0",'UTILITY REPORT 1'!G12) -> 124 | J11: 0 | K11: ='UTILITY REPORT 1'!C12 -> 36 | L11: =E11*F11+G11*H11+#REF!*#REF!+I11*J11 -> #REF!
A12: Serengeti | B12: =B11+1 -> 11 | C12: 11 | D12: 2019 | E12: ='UTILITY REPORT 1'!F13 -> 6542 | F12: =('UTILITY REPORT 1'!E13*'UTILITY REPORT 1'!D13)/'UTILITY REPORT 1'!F13 -> 0.4054494 | G12: =IF('Utility summery'!M16<0,"0",'Utility summery'!M16) -> 101.772 | H12: 0 | I12: =IF('UTILITY REPORT 1'!G13<0,"0",'UTILITY REPORT 1'!G13) -> 131 | J12: 0 | K12: ='UTILITY REPORT 1'!C13 -> 73 | L12: =E12*F12+G12*H12+#REF!*#REF!+I12*J12 -> #REF!
A13: Serengeti | B13: =B12+1 -> 12 | C13: 11 | D13: 2019 | E13: ='UTILITY REPORT 1'!F14 -> 6667 | F13: =('UTILITY REPORT 1'!E14*'UTILITY REPORT 1'!D14)/'UTILITY REPORT 1'!F14 -> 0.3880996 | G13: =IF('Utility summery'!M17<0,"0",'Utility summery'!M17) -> 115.192 | H13: 0 | I13: =IF('UTILITY REPORT 1'!G14<0,"0",'UTILITY REPORT 1'!G14) -> 136 | J13: 0 | K13: ='UTILITY REPORT 1'!C14 -> 73 | L13: =E13*F13+G13*H13+#REF!*#REF!+I13*J13 -> #REF!
A14: Serengeti | B14: =B13+1 -> 13 | C14: 11 | D14: 2019 | E14: ='UTILITY REPORT 1'!F15 -> 5860 | F14: =('UTILITY REPORT 1'!E15*'UTILITY REPORT 1'!D15)/'UTILITY REPORT 1'!F15 -> 0.38045734 | G14: =IF('Utility summery'!M18<0,"0",'Utility summery'!M18) -> 98.472 | H14: 0 | I14: =IF('UTILITY REPORT 1'!G15<0,"0",'UTILITY REPORT 1'!G15) -> 123 | J14: 0 | K14: ='UTILITY REPORT 1'!C15 -> 39 | L14: =E14*F14+G14*H14+#REF!*#REF!+I14*J14 -> #REF!
... A31: Serengeti | B31: =B30+1 -> 30 | C31: 11 | D31: 2019 | E31: ='UTILITY REPORT 1'!F32 -> 0 | F31: =('UTILITY REPORT 1'!E32*'UTILITY REPORT 1'!D32)/'UTILITY REPORT 1'!F32 -> #DIV/0! | G31: =IF('Utility summery'!M35<0,"0",'Utility summery'!M35) -> 0 | H31: 0 | I31: =IF('UTILITY REPORT 1'!G32<0,"0",'UTILITY REPORT 1'!G32) -> 0 | J31: 0 | K31: ='UTILITY REPORT 1'!C32 -> 0 | L31: =E31*F31+G31*H31+#REF!*#REF!+I31*J31 -> #DIV/0!
A32: Serengeti | B32: 1 | C32: 12 | D32: 2019 | E32: ='UTILITY REPORT 1'!F33 -> 0 | F32: =('UTILITY REPORT 1'!E33*'UTILITY REPORT 1'!D33)/'UTILITY REPORT 1'!F33 -> #DIV/0! | G32: =IF('Utility summery'!M36<0,"0",'Utility summery'!M36) -> 0 | H32: 0 | I32: =IF('UTILITY REPORT 1'!G33<0,"0",'UTILITY REPORT 1'!G33) -> 0 | J32: 0 | K32: ='UTILITY REPORT 1'!C33 -> 0

Sheet Submetering
A1: Site Name | B1: Day | C1: Month | D1: Year | E1: Transport Consumption (LT) | F1: Generators Consumption (LT) | G1: Total Electricity Kwh | H1: Kitchen (KWh) | I1: Laundry (KWh) | J1: STP (M3) | K1: RO prodution (M3) | L1: Amani Restaurant (M3) | M1: Kitchen (M3) | N1: Laundry (M3) | O1: Laundry (M3) | P1: Total water Consumption (M3) | Q1: Borehole #1 (M3) | R1: Borehole #2 (M3) | S1: Borehole #3 (M3) | T1: Borehole #4 (M3) | U1: Borehole #5 (M3) | V1: Borehole #6 (M3) | W1: Total Bore holes production (M3) | X1: Room Nights
A2: Serengeti | B2: 1 | C2: 11 | D2: 2019 | E2: ='UTILITY REPORT 1'!I3 -> 69.05 | F2: ='UTILITY REPORT 1'!E3 -> 2398.12 | G2: ='UTILITY REPORT 1'!F3 -> 5703 | H2: =IF('Kit report'!F4<0,"0",'Kit report'!F4) -> 516 | I2: =IF('Kit report'!X4<0,"0",'Kit report'!X4) -> 860 | J2: =IF('Utility summery'!H6<0,"0",'Utility summery'!H6) -> 36 | K2: =IF('UTILITY REPORT 1'!H3<0,"0",'UTILITY REPORT 1'!H3) -> 120 | L2: ='Water-Meter'!K6 -> 3 | M2: ='Water-Meter'!H6 -> 16 | N2: ='Water-Meter'!Q6 -> 13 | O2: =K2*E2+H2*I2+#REF!*#REF!+J2*L2 -> #REF! | P2: ='Water-Meter'!E6 -> 128 | Q2: =IF('Water-Meter'!U6<0,"0",'Water-Meter'!U6) -> 30 | R2: =IF('Water-Meter'!X6<0,"0",'Water-Meter'!X6) -> 50 | S2: =IF('Water-Meter'!AA6<0,"0",'Water-Meter'!AA6) -> 65 | T2: =IF('Water-Meter'!AD6<0,"0",'Water-Meter'!AD6) -> 7 | U2: =IF('Water-Meter'!AG6<0,"0",'Water-Meter'!AG6) -> 14 | V2: =IF('Water-Meter'!AJ6<0,"0",'Water-Meter'!AJ6) -> 19 | W2: ='Water-Meter'!AN6 -> 185 | X2: =Total!K2 -> 66
A3: Serengeti | B3: =B2+1 -> 2 | C3: 11 | D3: 2019 | E3: ='UTILITY REPORT 1'!I4 -> 659.55 | F3: ='UTILITY REPORT 1'!E4 -> 2502.57 | G3: ='UTILITY REPORT 1'!F4 -> 6052 | H3: =IF('Kit report'!F5<0,"0",'Kit report'!F5) -> 516 | I3: =IF('Kit report'!X5<0,"0",'Kit report'!X5) -> 900 | J3: =IF('Utility summery'!H7<0,"0",'Utility summery'!H7) -> 30 | K3: =IF('UTILITY REPORT 1'!H4<0,"0",'UTILITY REPORT 1'!H4) -> 120 | L3: ='Water-Meter'!K7 -> 3 | M3: ='Water-Meter'!H7 -> 23 | N3: ='Water-Meter'!Q7 -> 8 | O3: =K3*E3+H3*I3+#REF!*#REF!+J3*L3 -> #REF! | P3: ='Water-Meter'!E7 -> 139 | Q3: =IF('Water-Meter'!U7<0,"0",'Water-Meter'!U7) -> 29 | R3: =IF('Water-Meter'!X7<0,"0",'Water-Meter'!X7) -> 51 | S3: =IF('Water-Meter'!AA7<0,"0",'Water-Meter'!AA7) -> 55 | T3: =IF('Water-Meter'!AD7<0,"0",'Water-Meter'!AD7) -> 7 | U3: =IF('Water-Meter'!AG7<0,"0",'Water-Meter'!AG7) -> 14 | V3: =IF('Water-Meter'!AJ7<0,"0",'Water-Meter'!AJ7) -> 19 | W3: ='Water-Meter'!AN7 -> 175 | X3: =Total!K3 -> 58
A4: Serengeti | B4: =B3+1 -> 3 | C4: 11 | D4: 2019 | E4: ='UTILITY REPORT 1'!I5 -> 261.5 | F4: ='UTILITY REPORT 1'!E5 -> 2086.83 | G4: ='UTILITY REPORT 1'!F5 -> 5227 | H4: =IF('Kit report'!F6<0,"0",'Kit report'!F6) -> 492 | I4: =IF('Kit report'!X6<0,"0",'Kit report'!X6) -> 820 | J4: =IF('Utility summery'!H8<0,"0",'Utility summery'!H8) -> 38 | K4: =IF('UTILITY REPORT 1'!H5<0,"0",'UTILITY REPORT 1'!H5) -> 125 | L4: ='Water-Meter'!K8 -> 6 | M4: ='Water-Meter'!H8 -> 15 | N4: ='Water-Meter'!Q8 -> 13 | O4: =K4*E4+H4*I4+#REF!*#REF!+J4*L4 -> #REF! | P4: ='Water-Meter'!E8 -> 132 | Q4: =IF('Water-Meter'!U8<0,"0",'Water-Meter'!U8) -> 29 | R4: =IF('Water-Meter'!X8<0,"0",'Water-Meter'!X8) -> 51 | S4: =IF('Water-Meter'!AA8<0,"0",'Water-Meter'!AA8) -> 55 | T4: =IF('Water-Meter'!AD8<0,"0",'Water-Meter'!AD8) -> 7 | U4: =IF('Water-Meter'!AG8<0,"0",'Water-Meter'!AG8) -> 14 | V4: =IF('Water-Meter'!AJ8<0,"0",'Water-Meter'!AJ8) -> 20 | W4: ='Water-Meter'!AN8 -> 176 | X4: =Total!K4 -> 9
A5: Serengeti | B5: =B4+1 -> 4 | C5: 11 | D5: 2019 | E5: ='UTILITY REPORT 1'!I6 -> 17.39 | F5: ='UTILITY REPORT 1'!E6 -> 1834.21 | G5: ='UTILITY REPORT 1'!F6 -> 4812 | H5: =IF('Kit report'!F7<0,"0",'Kit report'!F7) -> 552 | I5: =IF('Kit report'!X7<0,"0",'Kit report'!X7) -> 1060 | J5: =IF('Utility summery'!H9<0,"0",'Utility summery'!H9) -> 40 | K5: =IF('UTILITY REPORT 1'!H6<0,"0",'UTILITY REPORT 1'!H6) -> 32 | L5: ='Water-Meter'!K9 -> 4 | M5: ='Water-Meter'!H9 -> 15 | N5: ='Water-Meter'!Q9 -> 15 | O5: =K5*E5+H5*I5+#REF!*#REF!+J5*L5 -> #REF! | P5: ='Water-Meter'!E9 -> 100 | Q5: =IF('Water-Meter'!U9<0,"0",'Water-Meter'!U9) -> 30 | R5: =IF('Water-Meter'!X9<0,"0",'Water-Meter'!X9) -> 51 | S5: =IF('Water-Meter'!AA9<0,"0",'Water-Meter'!AA9) -> 55 | T5: =IF('Water-Meter'!AD9<0,"0",'Water-Meter'!AD9) -> 6 | U5: =IF('Water-Meter'!AG9<0,"0",'Water-Meter'!AG9) -> 14 | V5: =IF('Water-Meter'!AJ9<0,"0",'Water-Meter'!AJ9) -> 18 | W5: ='Water-Meter'!AN9 -> 174 | X5: =Total!K5 -> 10
A6: Serengeti | B6: =B5+1 -> 5 | C6: 11 | D6: 2019 | E6: ='UTILITY REPORT 1'!I7 -> 18.94 | F6: ='UTILITY REPORT 1'!E7 -> 2117.7 | G6: ='UTILITY REPORT 1'!F7 -> 5035 | H6: =IF('Kit report'!F8<0,"0",'Kit report'!F8) -> 564 | I6: =IF('Kit report'!X8<0,"0",'Kit report'!X8) -> 860 | J6: =IF('Utility summery'!H10<0,"0",'Utility summery'!H10) -> 41 | K6: =IF('UTILITY REPORT 1'!H7<0,"0",'UTILITY REPORT 1'!H7) -> 0 | L6: ='Water-Meter'!K10 -> 1 | M6: ='Water-Meter'!H10 -> 15 | N6: ='Water-Meter'!Q10 -> 2 | O6: =K6*E6+H6*I6+#REF!*#REF!+J6*L6 -> #REF! | P6: ='Water-Meter'!E10 -> 119 | Q6: =IF('Water-Meter'!U10<0,"0",'Water-Meter'!U10) -> 29 | R6: =IF('Water-Meter'!X10<0,"0",'Water-Meter'!X10) -> 50 | S6: =IF('Water-Meter'!AA10<0,"0",'Water-Meter'!AA10) -> 55 | T6: =IF('Water-Meter'!AD10<0,"0",'Water-Meter'!AD10) -> 7 | U6: =IF('Water-Meter'!AG10<0,"0",'Water-Meter'!AG10) -> 14 | V6: =IF('Water-Meter'!AJ10<0,"0",'Water-Meter'!AJ10) -> 19 | W6: ='Water-Meter'!AN10 -> 174 | X6: =Total!K6 -> 25
A7: Serengeti | B7: =B6+1 -> 6 | C7: 11 | D7: 2019 | E7: ='UTILITY REPORT 1'!I8 -> 142.33 | F7: ='UTILITY REPORT 1'!E8 -> 2435.73 | G7: ='UTILITY REPORT 1'!F8 -> 5420 | H7: =IF('Kit report'!F9<0,"0",'Kit report'!F9) -> 504 | I7: =IF('Kit report'!X9<0,"0",'Kit report'!X9) -> 860 | J7: =IF('Utility summery'!H11<0,"0",'Utility summery'!H11) -> 39 | K7: =IF('UTILITY REPORT 1'!H8<0,"0",'UTILITY REPORT 1'!H8) -> 107 | L7: ='Water-Meter'!K11 -> 4 | M7: ='Water-Meter'!H11 -> 13 | N7: ='Water-Meter'!Q11 -> 8 | O7: =K7*E7+H7*I7+#REF!*#REF!+J7*L7 -> #REF! | P7: ='Water-Meter'!E11 -> 110 | Q7: =IF('Water-Meter'!U11<0,"0",'Water-Meter'!U11) -> 30 | R7: =IF('Water-Meter'!X11<0,"0",'Water-Meter'!X11) -> 53 | S7: =IF('Water-Meter'!AA11<0,"0",'Water-Meter'!AA11) -> 54 | T7: =IF('Water-Meter'!AD11<0,"0",'Water-Meter'!AD11) -> 6 | U7: =IF('Water-Meter'!AG11<0,"0",'Water-Meter'!AG11) -> 14 | V7: =IF('Water-Meter'!AJ11<0,"0",'Water-Meter'!AJ11) -> 18 | W7: ='Water-Meter'!AN11 -> 175 | X7: =Total!K7 -> 24
A8: Serengeti | B8: =B7+1 -> 7 | C8: 11 | D8: 2019 | E8: ='UTILITY REPORT 1'!I9 -> 241.32 | F8: ='UTILITY REPORT 1'!E9 -> 2229.96 | G8: ='UTILITY REPORT 1'!F9 -> 5338 | H8: =IF('Kit report'!F10<0,"0",'Kit report'!F10) -> 468 | I8: =IF('Kit report'!X10<0,"0",'Kit report'!X10) -> 700 | J8: =IF('Utility summery'!H12<0,"0",'Utility summery'!H12) -> 30 | K8: =IF('UTILITY REPORT 1'!H9<0,"0",'UTILITY REPORT 1'!H9) -> 112 | L8: ='Water-Meter'!K12 -> 3 | M8: ='Water-Meter'!H12 -> 10 | N8: ='Water-Meter'!Q12 -> 7 | O8: =K8*E8+H8*I8+#REF!*#REF!+J8*L8 -> #REF! | P8: ='Water-Meter'!E12 -> 95 | Q8: =IF('Water-Meter'!U12<0,"0",'Water-Meter'!U12) -> 30 | R8: =IF('Water-Meter'!X12<0,"0",'Water-Meter'!X12) -> 51 | S8: =IF('Water-Meter'!AA12<0,"0",'Water-Meter'!AA12) -> 55 | T8: =IF('Water-Meter'!AD12<0,"0",'Water-Meter'!AD12) -> 7 | U8: =IF('Water-Meter'!AG12<0,"0",'Water-Meter'!AG12) -> 14 | V8: =IF('Water-Meter'!AJ12<0,"0",'Water-Meter'!AJ12) -> 19 | W8: ='Water-Meter'!AN12 -> 176 | X8: =Total!K8 -> 17
A9: Serengeti | B9: =B8+1 -> 8 | C9: 11 | D9: 2019 | E9: ='UTILITY REPORT 1'!I10 -> 159.05 | F9: ='UTILITY REPORT 1'!E10 -> 2100.45 | G9: ='UTILITY REPORT 1'!F10 -> 5670 | H9: =IF('Kit report'!F11<0,"0",'Kit report'!F11) -> 516 | I9: =IF('Kit report'!X11<0,"0",'Kit report'!X11) -> 740 | J9: =IF('Utility summery'!H13<0,"0",'Utility summery'!H13) -> 52 | K9: =IF('UTILITY REPORT 1'!H10<0,"0",'UTILITY REPORT 1'!H10) -> 109 | L9: ='Water-Meter'!K13 -> 3 | M9: ='Water-Meter'!H13 -> 14 | N9: ='Water-Meter'!Q13 -> 10 | O9: =K9*E9+H9*I9+#REF!*#REF!+J9*L9 -> #REF! | P9: ='Water-Meter'!E13 -> 120 | Q9: =IF('Water-Meter'!U13<0,"0",'Water-Meter'!U13) -> 29 | R9: =IF('Water-Meter'!X13<0,"0",'Water-Meter'!X13) -> 52 | S9: =IF('Water-Meter'!AA13<0,"0",'Water-Meter'!AA13) -> 54 | T9: =IF('Water-Meter'!AD13<0,"0",'Water-Meter'!AD13) -> 5 | U9: =IF('Water-Meter'!AG13<0,"0",'Water-Meter'!AG13) -> 14 | V9: =IF('Water-Meter'!AJ13<0,"0",'Water-Meter'!AJ13) -> 18 | W9: ='Water-Meter'!AN13 -> 172 | X9: =Total!K9 -> 13
A10: Serengeti | B10: =B9+1 -> 9 | C10: 11 | D10: 2019 | E10: ='UTILITY REPORT 1'!I11 -> 122.96 | F10: ='UTILITY REPORT 1'!E11 -> 2130.17 | G10: ='UTILITY REPORT 1'!F11 -> 5594 | H10: =IF('Kit report'!F12<0,"0",'Kit report'!F12) -> 492 | I10: =IF('Kit report'!X12<0,"0",'Kit report'!X12) -> 800 | J10: =IF('Utility summery'!H14<0,"0",'Utility summery'!H14) -> 37 | K10: =IF('UTILITY REPORT 1'!H11<0,"0",'UTILITY REPORT 1'!H11) -> 110 | L10: ='Water-Meter'!K14 -> 3 | M10: ='Water-Meter'!H14 -> 20 | N10: ='Water-Meter'!Q14 -> 8 | O10: =K10*E10+H10*I10+#REF!*#REF!+J10*L10 -> #REF! | P10: ='Water-Meter'!E14 -> 96 | Q10: =IF('Water-Meter'!U14<0,"0",'Water-Meter'!U14) -> 31 | R10: =IF('Water-Meter'!X14<0,"0",'Water-Meter'!X14) -> 51 | S10: =IF('Water-Meter'!AA14<0,"0",'Water-Meter'!AA14) -> 55 | T10: =IF('Water-Meter'!AD14<0,"0",'Water-Meter'!AD14) -> 7 | U10: =IF('Water-Meter'!AG14<0,"0",'Water-Meter'!AG14) -> 14 | V10: =IF('Water-Meter'!AJ14<0,"0",'Water-Meter'!AJ14) -> 18 | W10: ='Water-Meter'!AN14 -> 176 | X10: =Total!K10 -> 13
A11: Serengeti | B11: =B10+1 -> 10 | C11: 11 | D11: 2019 | E11: ='UTILITY REPORT 1'!I12 -> 231.5 | F11: ='UTILITY REPORT 1'!E12 -> 2241.8 | G11: ='UTILITY REPORT 1'!F12 -> 5487 | H11: =IF('Kit report'!F13<0,"0",'Kit report'!F13) -> 480 | I11: =IF('Kit report'!X13<0,"0",'Kit report'!X13) -> 720 | J11: =IF('Utility summery'!H15<0,"0",'Utility summery'!H15) -> 35 | K11: =IF('UTILITY REPORT 1'!H12<0,"0",'UTILITY REPORT 1'!H12) -> 81 | L11: ='Water-Meter'!K15 -> 2 | M11: ='Water-Meter'!H15 -> 18 | N11: ='Water-Meter'!Q15 -> 8 | O11: =K11*E11+H11*I11+#REF!*#REF!+J11*L11 -> #REF! | P11: ='Water-Meter'!E15 -> 124 | Q11: =IF('Water-Meter'!U15<0,"0",'Water-Meter'!U15) -> 30 | R11: =IF('Water-Meter'!X15<0,"0",'Water-Meter'!X15) -> 52 | S11: =IF('Water-Meter'!AA15<0,"0",'Water-Meter'!AA15) -> 55 | T11: =IF('Water-Meter'!AD15<0,"0",'Water-Meter'!AD15) -> 6 | U11: =IF('Water-Meter'!AG15<0,"0",'Water-Meter'!AG15) -> 14 | V11: =IF('Water-Meter'!AJ15<0,"0",'Water-Meter'!AJ15) -> 18 | W11: ='Water-Meter'!AN15 -> 175 | X11: =Total!K11 -> 36
A12: Serengeti | B12: =B11+1 -> 11 | C12: 11 | D12: 2019 | E12: ='UTILITY REPORT 1'!I13 -> 0 | F12: ='UTILITY REPORT 1'!E13 -> 2652.45 | G12: ='UTILITY REPORT 1'!F13 -> 6542 | H12: =IF('Kit report'!F14<0,"0",'Kit report'!F14) -> 576 | I12: =IF('Kit report'!X14<0,"0",'Kit report'!X14) -> 980 | J12: =IF('Utility summery'!H16<0,"0",'Utility summery'!H16) -> 30 | K12: =IF('UTILITY REPORT 1'!H13<0,"0",'UTILITY REPORT 1'!H13) -> 117 | L12: ='Water-Meter'!K16 -> 3 | M12: ='Water-Meter'!H16 -> 16 | N12: ='Water-Meter'!Q16 -> 12 | O12: =K12*E12+H12*I12+#REF!*#REF!+J12*L12 -> #REF! | P12: ='Water-Meter'!E16 -> 131 | Q12: =IF('Water-Meter'!U16<0,"0",'Water-Meter'!U16) -> 27 | R12: =IF('Water-Meter'!X16<0,"0",'Water-Meter'!X16) -> 52 | S12: =IF('Water-Meter'!AA16<0,"0",'Water-Meter'!AA16) -> 55 | T12: =IF('Water-Meter'!AD16<0,"0",'Water-Meter'!AD16) -> 7 | U12: =IF('Water-Meter'!AG16<0,"0",'Water-Meter'!AG16) -> 14 | V12: =IF('Water-Meter'!AJ16<0,"0",'Water-Meter'!AJ16) -> 19 | W12: ='Water-Meter'!AN16 -> 174 | X12: =Total!K12 -> 73
A13: Serengeti | B13: =B12+1 -> 12 | C13: 11 | D13: 2019 | E13: ='UTILITY REPORT 1'!I14 -> 187.81 | F13: ='UTILITY REPORT 1'!E14 -> 2587.46 | G13: ='UTILITY REPORT 1'!F14 -> 6667 | H13: =IF('Kit report'!F15<0,"0",'Kit report'!F15) -> 528 | I13: =IF('Kit report'!X15<0,"0",'Kit report'!X15) -> 860 | J13: =IF('Utility summery'!H17<0,"0",'Utility summery'!H17) -> 41 | K13: =IF('UTILITY REPORT 1'!H14<0,"0",'UTILITY REPORT 1'!H14) -> 42 | L13: ='Water-Meter'!K17 -> 2 | M13: ='Water-Meter'!H17 -> 19 | N13: ='Water-Meter'!Q17 -> 10 | O13: =K13*E13+H13*I13+#REF!*#REF!+J13*L13 -> #REF! | P13: ='Water-Meter'!E17 -> 136 | Q13: =IF('Water-Meter'!U17<0,"0",'Water-Meter'!U17) -> 29 | R13: =IF('Water-Meter'!X17<0,"0",'Water-Meter'!X17) -> 49 | S13: =IF('Water-Meter'!AA17<0,"0",'Water-Meter'!AA17) -> 52 | T13: =IF('Water-Meter'!AD17<0,"0",'Water-Meter'!AD17) -> 7 | U13: =IF('Water-Meter'!AG17<0,"0",'Water-Meter'!AG17) -> 14 | V13: =IF('Water-Meter'!AJ17<0,"0",'Water-Meter'!AJ17) -> 18 | W13: ='Water-Meter'!AN17 -> 169 | X13: =Total!K13 -> 73
A14: Serengeti | B14: =B13+1 -> 13 | C14: 11 | D14: 2019 | E14: ='UTILITY REPORT 1'!I15 -> 450.31 | F14: ='UTILITY REPORT 1'!E15 -> 2229.48 | G14: ='UTILITY REPORT 1'!F15 -> 5860 | H14: =IF('Kit report'!F16<0,"0",'Kit report'!F16) -> 504 | I14: =IF('Kit report'!X16<0,"0",'Kit report'!X16) -> 700 | J14: =IF('Utility summery'!H18<0,"0",'Utility summery'!H18) -> 40 | K14: =IF('UTILITY REPORT 1'!H15<0,"0",'UTILITY REPORT 1'!H15) -> 112 | L14: ='Water-Meter'!K18 -> 2 | M14: ='Water-Meter'!H18 -> 19 | N14: ='Water-Meter'!Q18 -> 6 | O14: =K14*E14+H14*I14+#REF!*#REF!+J14*L14 -> #REF! | P14: ='Water-Meter'!E18 -> 123 | Q14: =IF('Water-Meter'!U18<0,"0",'Water-Meter'!U18) -> 29 | R14: =IF('Water-Meter'!X18<0,"0",'Water-Meter'!X18) -> 50 | S14: =IF('Water-Meter'!AA18<0,"0",'Water-Meter'!AA18) -> 53 | T14: =IF('Water-Meter'!AD18<0,"0",'Water-Meter'!AD18) -> 6 | U14: =IF('Water-Meter'!AG18<0,"0",'Water-Meter'!AG18) -> 14 | V14: =IF('Water-Meter'!AJ18<0,"0",'Water-Meter'!AJ18) -> 18 | W14: ='Water-Meter'!AN18 -> 170 | X14: =Total!K14 -> 39
... A31: Serengeti | B31: =B30+1 -> 30 | C31: 11 | D31: 2019 | E31: ='UTILITY REPORT 1'!I32 -> 0 | F31: ='UTILITY REPORT 1'!E32 -> 0 | G31: ='UTILITY REPORT 1'!F32 -> 0 | H31: =IF('Kit report'!F33<0,"0",'Kit report'!F33) -> 0 | I31: =IF('Kit report'!X33<0,"0",'Kit report'!X33) -> 0 | J31: =IF('Utility summery'!H35<0,"0",'Utility summery'!H35) -> 0 | K31: =IF('UTILITY REPORT 1'!H32<0,"0",'UTILITY REPORT 1'!H32) -> 0 | L31: ='Water-Meter'!K35 -> 0 | M31: ='Water-Meter'!H35 -> 0 | N31: ='Water-Meter'!Q35 -> 0 | O31: =K31*E31+H31*I31+#REF!*#REF!+J31*L31 -> #REF! | P31: ='Water-Meter'!E35 -> 0 | Q31: =IF('Water-Meter'!U35<0,"0",'Water-Meter'!U35) -> 0 | R31: =IF('Water-Meter'!X35<0,"0",'Water-Meter'!X35) -> 0 | S31: =IF('Water-Meter'!AA35<0,"0",'Water-Meter'!AA35) -> 0 | T31: =IF('Water-Meter'!AD35<0,"0",'Water-Meter'!AD35) -> 0 | U31: =IF('Water-Meter'!AG35<0,"0",'Water-Meter'!AG35) -> 0 | V31: =IF('Water-Meter'!AJ35<0,"0",'Water-Meter'!AJ35) -> 0 | W31: ='Water-Meter'!AN35 -> 0 | X31: =Total!K31 -> 0
A32: Serengeti | B32: 1 | C32: 12 | D32: 2019 | E32: ='UTILITY REPORT 1'!I33 -> 0 | F32: ='UTILITY REPORT 1'!E33 -> 0 | G32: ='UTILITY REPORT 1'!F33 -> 0 | H32: =IF('Kit report'!F34<0,"0",'Kit report'!F34) -> 0 | I32: =IF('Kit report'!X34<0,"0",'Kit report'!X34) -> 0 | J32: =IF('Utility summery'!H36<0,"0",'Utility summery'!H36) -> 0 | K32: =IF('UTILITY REPORT 1'!H33<0,"0",'UTILITY REPORT 1'!H33) -> 0 | L32: ='Water-Meter'!K36 -> 0 | M32: ='Water-Meter'!H36 -> 0 | N32: ='Water-Meter'!Q36 -> 0 | P32: ='Water-Meter'!E36 -> 0 | Q32: =IF('Water-Meter'!U36<0,"0",'Water-Meter'!U36) -> 0 | R32: =IF('Water-Meter'!X36<0,"0",'Water-Meter'!X36) -> 0 | S32: =IF('Water-Meter'!AA36<0,"0",'Water-Meter'!AA36) -> 0 | T32: =IF('Water-Meter'!AD36<0,"0",'Water-Meter'!AD36) -> 0 | U32: =IF('Water-Meter'!AG36<0,"0",'Water-Meter'!AG36) -> 0 | V32: =IF('Water-Meter'!AJ36<0,"0",'Water-Meter'!AJ36) -> 0 | W32: ='Water-Meter'!AN36 -> 0 | X32: =Total!K32 -> 0

Sheet UTILITY REPORT 1
A1: NOVEMBER UTILITY REPORT
A2: Date | B2: % | C2: Guest Rooms Occupied | D2: Diesel cost Per Liter ($) | E2: Diesel consumption (LT) | F2: Power production (KW) | G2: Water consumption (M3) | H2: RO prodution (M3) | I2: Transport Consupmtion (LT)
A3: 43770 | B3: =Gen!B11 -> 0.87 | C3: ='Summery Report'!E5 -> 66 | D3: 1 | E3: =Gen!S11 -> 2398.12 | F3: =Gen!T11 -> 5703 | G3: ='Water-Meter'!E6 -> 128 | H3: ='Utility report '!AC6 -> 120 | I3: =Gen!AJ11 -> 69.05
A4: 43771 | B4: =Gen!B12 -> 0.766 | C4: ='Summery Report'!E6 -> 58 | D4: 1 | E4: =Gen!S12 -> 2502.57 | F4: =Gen!T12 -> 6052 | G4: ='Water-Meter'!E7 -> 139 | H4: ='Utility report '!AC7 -> 120 | I4: =Gen!AJ12 -> 659.55
A5: 43772 | B5: =Gen!B13 -> 0.11 | C5: ='Summery Report'!E7 -> 9 | D5: 1 | E5: =Gen!S13 -> 2086.83 | F5: =Gen!T13 -> 5227 | G5: ='Water-Meter'!E8 -> 132 | H5: ='Utility report '!AC8 -> 125 | I5: =Gen!AJ13 -> 261.5
A6: 43773 | B6: =Gen!B14 -> 0.13 | C6: ='Summery Report'!E8 -> 10 | D6: 1 | E6: =Gen!S14 -> 1834.21 | F6: =Gen!T14 -> 4812 | G6: ='Water-Meter'!E9 -> 100 | H6: ='Utility report '!AC9 -> 32 | I6: =Gen!AJ14 -> 17.39
A7: 43774 | B7: =Gen!B15 -> 0.506 | C7: ='Summery Report'!E9 -> 25 | D7: 1 | E7: =Gen!S15 -> 2117.7 | F7: =Gen!T15 -> 5035 | G7: ='Water-Meter'!E10 -> 119 | H7: ='Utility report '!AC10 -> 0 | I7: =Gen!AJ15 -> 18.94
A8: 43775 | B8: =Gen!B16 -> 0.312 | C8: ='Summery Report'!E10 -> 24 | D8: 1 | E8: =Gen!S16 -> 2435.73 | F8: =Gen!T16 -> 5420 | G8: ='Water-Meter'!E11 -> 110 | H8: ='Utility report '!AC11 -> 107 | I8: =Gen!AJ16 -> 142.33
A9: 43776 | B9: =Gen!B17 -> 0.195 | C9: ='Summery Report'!E11 -> 17 | D9: 1 | E9: =Gen!S17 -> 2229.96 | F9: =Gen!T17 -> 5338 | G9: ='Water-Meter'!E12 -> 95 | H9: ='Utility report '!AC12 -> 112 | I9: =Gen!AJ17 -> 241.32
A10: 43777 | B10: =Gen!B18 -> 0.169 | C10: ='Summery Report'!E12 -> 13 | D10: 1 | E10: =Gen!S18 -> 2100.45 | F10: =Gen!T18 -> 5670 | G10: ='Water-Meter'!E13 -> 120 | H10: ='Utility report '!AC13 -> 109 | I10: =Gen!AJ18 -> 159.05
A11: 43778 | B11: =Gen!B19 -> 0.169 | C11: ='Summery Report'!E13 -> 13 | D11: 1 | E11: =Gen!S19 -> 2130.17 | F11: =Gen!T19 -> 5594 | G11: ='Water-Meter'!E14 -> 96 | H11: ='Utility report '!AC14 -> 110 | I11: =Gen!AJ19 -> 122.96
A12: 43779 | B12: =Gen!B20 -> 0.468 | C12: ='Summery Report'!E14 -> 36 | D12: 1 | E12: =Gen!S20 -> 2241.8 | F12: =Gen!T20 -> 5487 | G12: ='Water-Meter'!E15 -> 124 | H12: ='Utility report '!AC15 -> 81 | I12: =Gen!AJ20 -> 231.5
A13: 43780 | B13: =Gen!B21 -> 0.948 | C13: ='Summery Report'!E15 -> 73 | D13: 1 | E13: =Gen!S21 -> 2652.45 | F13: =Gen!T21 -> 6542 | G13: ='Water-Meter'!E16 -> 131 | H13: ='Utility report '!AC16 -> 117 | I13: =Gen!AJ21 -> 0
A14: 43781 | B14: =Gen!B22 -> 0.935 | C14: ='Summery Report'!E16 -> 73 | D14: 1 | E14: =Gen!S22 -> 2587.46 | F14: =Gen!T22 -> 6667 | G14: ='Water-Meter'!E17 -> 136 | H14: ='Utility report '!AC17 -> 42 | I14: =Gen!AJ22 -> 187.81
... A33: 43800 | B33: =Gen!B41 -> 0 | C33: ='Summery Report'!E35 -> 0 | D33: 1 | E33: =Gen!S41 -> 0 | F33: =Gen!T41 -> 0 | G33: ='Water-Meter'!E36 -> 0 | H33: ='Utility report '!AC36 -> 0 | I33: =Gen!AJ41 -> 0

Sheet Utility summery
A4: Date | B4: Room Occupied | C4: Electricity Units Generated KW | D4: Diseal | G4: Water | J4: Gas | N4: Cost of utilites
D5: Generator | E5: Transport | F5: Total | G5: RO | H5: STP | I5: Total Consumption | J5: 2 ton | K5: 1 Ton | L5: 1 Ton | M5: Total consumption | N5: Electricity /1.4$/liter | O5: Diseal for Transport | P5: Gas /2.38$/Kg | Q5: Total HLP Cost | R5: Electricity Cost/Room $ | S5: cost/Room $
A6: =Gen!A11 -> 43770 | B6: ='Summery Report'!E5 -> 66 | C6: =Gen!T11 -> 5703 | D6: =Gen!S11 -> 2398.12 | E6: =Gen!AJ11 -> 69.05 | F6: =Gen!AR11 -> 2467.17 | G6: ='Utility report '!AC6 -> 120 | H6: ='Utility report '!AE6 -> 36 | I6: ='Water-Meter'!E6 -> 128 | J6: ='Lpg (2)'!B10 -> 73 | K6: ='Lpg (2)'!C10 -> 85 | L6: ='Lpg (2)'!D10 -> 85 | M6: ='Lpg (2)'!G10 -> 208.34 | O6: =E6 -> 69.05 | P6: ='[1]Lpg (2)'!#REF! -> #REF! | Q6: ='[1]Summery Report'!#REF! -> #REF! | R6: =N6/B6 -> 0 | S6: =Q6/B6 -> #REF!
A7: =Gen!A12 -> 43771 | B7: ='Summery Report'!E6 -> 58 | C7: =Gen!T12 -> 6052 | D7: =Gen!S12 -> 2502.57 | E7: =Gen!AJ12 -> 659.55 | F7: =Gen!AR12 -> 3162.12 | G7: ='Utility report '!AC7 -> 120 | H7: ='Utility report '!AE7 -> 30 | I7: ='Water-Meter'!E7 -> 139 | J7: ='Lpg (2)'!B11 -> 70 | K7: ='Lpg (2)'!C11 -> 85 | L7: ='Lpg (2)'!D11 -> 85 | M7: ='Lpg (2)'!G11 -> 101.376 | N7: =D7*1.4 -> 3503.598 | O7: =E7*1.4 -> 923.37 | P7: ='[1]Lpg (2)'!#REF! -> #REF! | Q7: ='[1]Summery Report'!#REF! -> #REF! | R7: =N7/B7 -> 60.406862 | S7: =Q7/B7 -> #REF!
A8: =Gen!A13 -> 43772 | B8: ='Summery Report'!E7 -> 9 | C8: =Gen!T13 -> 5227 | D8: =Gen!S13 -> 2086.83 | E8: =Gen!AJ13 -> 261.5 | F8: =Gen!AR13 -> 2348.33 | G8: ='Utility report '!AC8 -> 125 | H8: ='Utility report '!AE8 -> 38 | I8: ='Water-Meter'!E8 -> 132 | J8: ='Lpg (2)'!B12 -> 66 | K8: ='Lpg (2)'!C12 -> 85 | L8: ='Lpg (2)'!D12 -> 85 | M8: ='Lpg (2)'!G12 -> 101.464 | N8: =D8*1.4 -> 2921.562 | O8: =E8*1.4 -> 366.1 | P8: ='[1]Lpg (2)'!#REF! -> #REF! | Q8: ='[1]Summery Report'!#REF! -> #REF! | R8: =N8/B8 -> 324.618 | S8: =Q8/B8 -> #REF!
A9: =Gen!A14 -> 43773 | B9: ='Summery Report'!E8 -> 10 | C9: =Gen!T14 -> 4812 | D9: =Gen!S14 -> 1834.21 | E9: =Gen!AJ14 -> 17.39 | F9: =Gen!AR14 -> 1851.6 | G9: ='Utility report '!AC9 -> 32 | H9: ='Utility report '!AE9 -> 40 | I9: ='Water-Meter'!E9 -> 100 | J9: ='Lpg (2)'!B13 -> 62 | K9: ='Lpg (2)'!C13 -> 85 | L9: ='Lpg (2)'!D13 -> 85 | M9: ='Lpg (2)'!G13 -> 132.616 | N9: =D9*1.4 -> 2567.894 | O9: =E9*1.4 -> 24.346 | P9: ='[1]Lpg (2)'!#REF! -> #REF! | Q9: ='[1]Summery Report'!#REF! -> #REF! | R9: =N9/B9 -> 256.7894 | S9: =Q9/B9 -> #REF!
A10: =Gen!A15 -> 43774 | B10: ='Summery Report'!E9 -> 25 | C10: =Gen!T15 -> 5035 | D10: =Gen!S15 -> 2117.7 | E10: =Gen!AJ15 -> 18.94 | F10: =Gen!AR15 -> 2136.64 | G10: ='Utility report '!AC10 -> 0 | H10: ='Utility report '!AE10 -> 41 | I10: ='Water-Meter'!E10 -> 119 | J10: ='Lpg (2)'!B14 -> 60 | K10: ='Lpg (2)'!C14 -> 85 | L10: ='Lpg (2)'!D14 -> 85 | M10: ='Lpg (2)'!G14 -> 147.18 | N10: =D10*1.4 -> 2964.78 | O10: =E10*1.4 -> 26.516 | P10: ='[1]Lpg (2)'!#REF! -> #REF! | Q10: ='[1]Summery Report'!#REF! -> #REF! | R10: =N10/B10 -> 118.5912 | S10: =Q10/B10 -> #REF!
A11: =Gen!A16 -> 43775 | B11: ='Summery Report'!E10 -> 24 | C11: =Gen!T16 -> 5420 | D11: =Gen!S16 -> 2435.73 | E11: =Gen!AJ16 -> 142.33 | F11: =Gen!AR16 -> 2578.06 | G11: ='Utility report '!AC11 -> 107 | H11: ='Utility report '!AE11 -> 39 | I11: ='Water-Meter'!E11 -> 110 | J11: ='Lpg (2)'!B15 -> 56 | K11: ='Lpg (2)'!C15 -> 85 | L11: ='Lpg (2)'!D15 -> 85 | M11: ='Lpg (2)'!G15 -> 144.672 | N11: =D11*1.4 -> 3410.022 | O11: =E11*1.4 -> 199.262 | P11: ='[1]Lpg (2)'!#REF! -> #REF! | Q11: ='[1]Summery Report'!#REF! -> #REF! | R11: =N11/B11 -> 142.08425 | S11: =Q11/B11 -> #REF!
A12: =Gen!A17 -> 43776 | B12: ='Summery Report'!E11 -> 17 | C12: =Gen!T17 -> 5338 | D12: =Gen!S17 -> 2229.96 | E12: =Gen!AJ17 -> 241.32 | F12: =Gen!AR17 -> 2471.28 | G12: ='Utility report '!AC12 -> 112 | H12: ='Utility report '!AE12 -> 30 | I12: ='Water-Meter'!E12 -> 95 | J12: ='Lpg (2)'!B16 -> 54 | K12: ='Lpg (2)'!C16 -> 85 | L12: ='Lpg (2)'!D16 -> 85 | M12: ='Lpg (2)'!G16 -> 149.072 | N12: =D12*1.4 -> 3121.944 | O12: =E12*1.4 -> 337.848 | P12: ='[1]Lpg (2)'!#REF! -> #REF! | Q12: ='[1]Summery Report'!#REF! -> #REF! | R12: =N12/B12 -> 183.64376 | S12: =Q12/B12 -> #REF!
A13: =Gen!A18 -> 43777 | B13: ='Summery Report'!E12 -> 13 | C13: =Gen!T18 -> 5670 | D13: =Gen!S18 -> 2100.45 | E13: =Gen!AJ18 -> 159.05 | F13: =Gen!AR18 -> 2259.5 | G13: ='Utility report '!AC13 -> 109 | H13: ='Utility report '!AE13 -> 52 | I13: ='Water-Meter'!E13 -> 120 | J13: ='Lpg (2)'!B17 -> 50 | K13: ='Lpg (2)'!C17 -> 85 | L13: ='Lpg (2)'!D17 -> 85 | M13: ='Lpg (2)'!G17 -> 152.064 | N13: =D13*1.4 -> 2940.63 | O13: =E13*1.4 -> 222.67 | P13: ='[1]Lpg (2)'!#REF! -> #REF! | Q13: ='[1]Summery Report'!#REF! -> #REF! | R13: =N13/B13 -> 226.20231 | S13: =Q13/B13 -> #REF!
A14: =Gen!A19 -> 43778 | B14: ='Summery Report'!E13 -> 13 | C14: =Gen!T19 -> 5594 | D14: =Gen!S19 -> 2130.17 | E14: =Gen!AJ19 -> 122.96 | F14: =Gen!AR19 -> 2253.13 | G14: ='Utility report '!AC14 -> 110 | H14: ='Utility report '!AE14 -> 37 | I14: ='Water-Meter'!E14 -> 96 | J14: ='Lpg (2)'!B18 -> 47 | K14: ='Lpg (2)'!C18 -> 85 | L14: ='Lpg (2)'!D18 -> 85 | M14: ='Lpg (2)'!G18 -> 152.284 | N14: =D14*1.4 -> 2982.238 | O14: =E14*1.4 -> 172.144 | P14: ='[1]Lpg (2)'!#REF! -> #REF! | Q14: ='[1]Summery Report'!#REF! -> #REF! | R14: =N14/B14 -> 229.40292 | S14: =Q14/B14 -> #REF!
A15: =Gen!A20 -> 43779 | B15: ='Summery Report'!E14 -> 36 | C15: =Gen!T20 -> 5487 | D15: =Gen!S20 -> 2241.8 | E15: =Gen!AJ20 -> 231.5 | F15: =Gen!AR20 -> 2473.3 | G15: ='Utility report '!AC15 -> 81 | H15: ='Utility report '!AE15 -> 35 | I15: ='Water-Meter'!E15 -> 124 | J15: ='Lpg (2)'!B19 -> 45 | K15: ='Lpg (2)'!C19 -> 85 | L15: ='Lpg (2)'!D19 -> 85 | M15: ='Lpg (2)'!G19 -> 103.488 | N15: =D15*1.4 -> 3138.52 | O15: =E15*1.4 -> 324.1 | P15: ='[1]Lpg (2)'!#REF! -> #REF! | Q15: ='[1]Summery Report'!#REF! -> #REF! | R15: =N15/B15 -> 87.181111 | S15: =Q15/B15 -> #REF!
A16: =Gen!A21 -> 43780 | B16: ='Summery Report'!E15 -> 73 | C16: =Gen!T21 -> 6542 | D16: =Gen!S21 -> 2652.45 | E16: =Gen!AJ21 -> 0 | F16: =Gen!AR21 -> 2652.45 | G16: ='Utility report '!AC16 -> 117 | H16: ='Utility report '!AE16 -> 30 | I16: ='Water-Meter'!E16 -> 131 | J16: ='Lpg (2)'!B20 -> 42 | K16: ='Lpg (2)'!C20 -> 85 | L16: ='Lpg (2)'!D20 -> 85 | M16: ='Lpg (2)'!G20 -> 101.772 | N16: =D16*1.4 -> 3713.43 | O16: =E16*1.4 -> 0 | P16: ='[1]Lpg (2)'!#REF! -> #REF! | Q16: ='[1]Summery Report'!#REF! -> #REF! | R16: =N16/B16 -> 50.868904 | S16: =Q16/B16 -> #REF!
A17: =Gen!A22 -> 43781 | B17: ='Summery Report'!E16 -> 73 | C17: =Gen!T22 -> 6667 | D17: =Gen!S22 -> 2587.46 | E17: =Gen!AJ22 -> 187.81 | F17: =Gen!AR22 -> 2775.27 | G17: ='Utility report '!AC17 -> 42 | H17: ='Utility report '!AE17 -> 41 | I17: ='Water-Meter'!E17 -> 136 | J17: ='Lpg (2)'!B21 -> 39 | K17: ='Lpg (2)'!C21 -> 85 | L17: ='Lpg (2)'!D21 -> 85 | M17: ='Lpg (2)'!G21 -> 115.192 | N17: =D17*1.4 -> 3622.444 | O17: =E17*1.4 -> 262.934 | P17: ='[1]Lpg (2)'!#REF! -> #REF! | Q17: ='[1]Summery Report'!#REF! -> #REF! | R17: =N17/B17 -> 49.622521 | S17: =Q17/B17 -> #REF!
A18: =Gen!A23 -> 43782 | B18: ='Summery Report'!E17 -> 39 | C18: =Gen!T23 -> 5860 | D18: =Gen!S23 -> 2229.48 | E18: =Gen!AJ23 -> 450.31 | F18: =Gen!AR23 -> 2679.79 | G18: ='Utility report '!AC18 -> 112 | H18: ='Utility report '!AE18 -> 40 | I18: ='Water-Meter'!E18 -> 123 | J18: ='Lpg (2)'!B22 -> 35 | K18: ='Lpg (2)'!C22 -> 85 | L18: ='Lpg (2)'!D22 -> 85 | M18: ='Lpg (2)'!G22 -> 98.472 | N18: =D18*1.4 -> 3121.272 | O18: =E18*1.4 -> 630.434 | P18: ='[1]Lpg (2)'!#REF! -> #REF! | Q18: ='[1]Summery Report'!#REF! -> #REF! | R18: =N18/B18 -> 80.032615 | S18: =Q18/B18 -> #REF!
... A32: =Gen!A37 -> 43796 | B32: ='Summery Report'!E31 -> 0 | C32: =Gen!T37 -> 0 | D32: =Gen!S37 -> 0 | E32: =Gen!AJ37 -> 0 | F32: =Gen!AR37 -> 0 | G32: ='Utility report '!AC32 -> 0 | H32: ='Utility report '!AE32 -> 0 | I32: ='Water-Meter'!E32 -> 0 | J32: ='Lpg (2)'!B36 -> 0 | K32: ='Lpg (2)'!C36 -> 0 | L32: ='Lpg (2)'!D36 -> 0 | M32: ='Lpg (2)'!G36 -> 0 | N32: =D32*1.4 -> 0 | O32: =E32*1.4 -> 0 | P32: ='[1]Lpg (2)'!#REF! -> #REF! | Q32: ='[1]Summery Report'!#REF! -> #REF! | R32: =N32/B32 -> #DIV/0! | S32: =Q32/B32 -> #REF!
A33: =Gen!A38 -> 43797 | B33: ='Summery Report'!E32 -> 0 | C33: =Gen!T38 -> 0 | D33: =Gen!S38 -> 0 | E33: =Gen!AJ38 -> 0 | F33: =Gen!AR38 -> 0 | G33: ='Utility report '!AC33 -> 0 | H33: ='Utility report '!AE33 -> 0 | I33: ='Water-Meter'!E33 -> 0 | J33: ='Lpg (2)'!B37 -> 0 | K33: ='Lpg (2)'!C37 -> 0 | L33: ='Lpg (2)'!D37 -> 0 | M33: ='Lpg (2)'!G37 -> 0 | N33: =D33*1.4 -> 0 | O33: =E33*1.4 -> 0 | P33: ='[1]Lpg (2)'!#REF! -> #REF! | Q33: ='[1]Summery Report'!#REF! -> #REF! | R33: =N33/B33 -> #DIV/0! | S33: =Q33/B33 -> #REF! | T33: =3124/13 -> 240.30769
A34: =Gen!A39 -> 43798 | B34: ='Summery Report'!E33 -> 0 | C34: =Gen!T39 -> 0 | D34: =Gen!S39 -> 0 | E34: =Gen!AJ39 -> 0 | F34: =Gen!AR39 -> 0 | G34: ='Utility report '!AC34 -> 0 | H34: ='Utility report '!AE34 -> 0 | I34: ='Water-Meter'!E34 -> 0 | J34: ='Lpg (2)'!B38 -> 0 | K34: ='Lpg (2)'!C38 -> 0 | L34: ='Lpg (2)'!D38 -> 0 | M34: ='Lpg (2)'!G38 -> 0 | N34: =D34*1.4 -> 0 | O34: =E34*1.4 -> 0 | P34: ='[1]Lpg (2)'!#REF! -> #REF! | Q34: ='[1]Summery Report'!#REF! -> #REF! | R34: =N34/B34 -> #DIV/0! | S34: =Q34/B34 -> #REF!
A35: =Gen!A40 -> 43799 | B35: ='Summery Report'!E34 -> 0 | C35: =Gen!T40 -> 0 | D35: =Gen!S40 -> 0 | E35: =Gen!AJ40 -> 0 | F35: =Gen!AR40 -> 0 | G35: ='Utility report '!AC35 -> 0 | H35: ='Utility report '!AE35 -> 0 | I35: ='Water-Meter'!E35 -> 0 | J35: ='Lpg (2)'!B39 -> 0 | K35: ='Lpg (2)'!C39 -> 0 | L35: ='Lpg (2)'!D39 -> 0 | M35: ='Lpg (2)'!G39 -> 0 | N35: =D35*1.4 -> 0 | O35: =E35*1.4 -> 0 | P35: ='[1]Lpg (2)'!#REF! -> #REF! | Q35: ='[1]Summery Report'!#REF! -> #REF! | R35: =N35/B35 -> #DIV/0! | S35: =Q35/B35 -> #REF!
A36: =Gen!A41 -> 43800 | B36: ='Summery Report'!E35 -> 0 | C36: =Gen!T41 -> 0 | D36: =Gen!S41 -> 0 | E36: =Gen!AJ41 -> 0 | F36: =Gen!AR41 -> 0 | G36: ='Utility report '!AC36 -> 0 | H36: ='Utility report '!AE36 -> 0 | I36: ='Water-Meter'!E36 -> 0 | J36: ='Lpg (2)'!B40 -> 0 | K36: ='Lpg (2)'!C40 -> 0 | L36: ='Lpg (2)'!D40 -> 0 | M36: ='Lpg (2)'!G40 -> 0 | N36: =D36*1.4 -> 0 | O36: =E36*1.4 -> 0 | P36: ='[1]Lpg (2)'!#REF! -> #REF! | Q36: ='[1]Summery Report'!#REF! -> #REF! | R36: =N36/B36 -> #DIV/0! | S36: =Q36/B36 -> #REF!
A37: =[1]Gen!A42 -> #REF! | B37: ='Summery Report'!E36 -> 0 | C37: =Gen!T42 -> 0 | D37: =Gen!S42 -> 0 | E37: =Gen!AJ42 -> 0 | F37: =Gen!AR42 -> 0 | G37: ='Utility report '!AC37 -> 0 | H37: ='Utility report '!AE37 -> 0 | I37: ='Water-Meter'!E37 -> 0 | J37: ='Lpg (2)'!B41 -> 0 | K37: ='Lpg (2)'!C41 -> 0 | L37: ='Lpg (2)'!D41 -> 0 | M37: ='Lpg (2)'!G41 -> 0 | Q37: ='[1]Summery Report'!#REF! -> #REF! | S37: =Q37/B37 -> #REF!
A39: Total | B39: =SUM(B7:B37) -> 598 | C39: =SUM(C7:C35) -> 113366 | D39: =SUM(D7:D35) -> 45495.04 | E39: =SUM(E7:E35) -> 3815.35 | F39: =SUM(F7:F35) -> 49310.39 | G39: =SUM(G7:G35) -> -15208 | H39: =SUM(H7:H35) -> -190855 | I39: =SUM(I7:I35) -> 2365 | J39: =SUM(J7:J35) -> 846 | ... S39: =SUM(S7:S35) -> #REF!

Sheet Utility report 
A1: DAILY UTILITY REPORT NOV 2019
A2: Date | B2: Total occupancy | H2: Diesel balance LTS | I2: Diesel Deliveries | J2: Gen.Diesel consumption LTS | L2: Total Diesel consumption LTS | M2: Water Meter reading | N2: Water consumption m³ | O2: R.O WATER PRODUCTION LTRS + TIME | AA2: Total RO production | AB2: RO Meter reading | AD2: 0 | AF2: GAS TANK A | AG2: GAS TANK B | AH2: GAS TANK C | AI2: Total Gas Tanks | AJ2: Kg /day | AK2: TOTAL GAS cons.
A3: Rate Tsh /$ | B3: 1640 | C3: Diesel cost / lits | D3: 2175 | F3: =SUM(D3/B3) -> 1.3262195 | H3: =Gen!C11 -> 35194.41 | K3: Transport consumption | M3: Balance | O3: PLANT NO 1 | S3: PLANT NO 2 | W3: PLANT NO 3 | AA3: /day | AB3: Balance | AC3: Production | AD3: 0 | AE3: Production | AF3: Capacity | AG3: Capacity | AH3: Capacity | AI3: Kg | AJ3: /day | AK3: /day
B4: Rooms OCC | C4: % | D4: Guest Rooms Occ | F4: Electricity Production Cost /Room Occ by guest | G4: All Cost /Room Occ by guest | O4: Flow M3 | P4: Reading Hours Meter | Q4: Hrs | R4: total production M3 | S4: Flow M3 | T4: Reading Hours Meter | U4: Hrs | V4: total production M3 | W4: Flow M3 | Y4: Hrs | Z4: total production M3 | AA4: M3 | AC4: M3 | AE4: M3 | AF4: 2000 | AG4: 1000 | AH4: 1000 | AI4: =SUM([2]Sheet1!$AA$36) -> 950 | AJ4: Kg | AK4: M3
P5: 18537 | T5: 15719 | W5: 5.4 | X5: 21237 | AB5: 15088 | AD5: 190819 | AF5: 0.85 | AG5: 0.85 | AH5: 0.85
A6: =Gen!A11 -> 43770 | B6: ='Summery Report'!E5 -> 66 | C6: =Gen!B11 -> 0.87 | D6: ='Summery Report'!E5 -> 66 | E6: =SUM(F3) -> 1.3262195 | F6: =SUM(J6*E6)/D6 -> 48.188387 | G6: =SUM(L6*E6)/D6 -> 49.575894 | H6: =Gen!C11 -> 35194.41 | I6: =Gen!E11 -> 18000 | J6: =Gen!S11 -> 2398.12 | K6: =Gen!AJ11 -> 69.05 | L6: =SUM(J6:K6) -> 2467.17 | M6: ='Water-Meter'!K46 -> 422.72167 | N6: ='Water-Meter'!E6 -> 128 | P6: 18537 | Q6: =SUM(P6-P5) -> 0 | R6: =SUM(Q6*O6) -> 0 | T6: 15719 | U6: =T6-T5 -> 0 | V6: - | X6: 21261 | Y6: =X6-X5 -> 24 | Z6: =Y6-Y5 -> 24 | AA6: =Z6-Z5 -> 24 | AB6: 15208 | AC6: =AB6-AB5 -> 120 | AD6: 190855 | AE6: =AD6-AD5 -> 36 | AF6: ='Lpg (2)'!B10*2000/85 -> 1717.6471 | AG6: ='Lpg (2)'!C10*1000/85 -> 1000 | AH6: ='Lpg (2)'!D10*1000/85 -> 1000 | AI6: =SUM(AF6*2000)+(AG6*1000)+(AH6*1000) -> 5435294.1 | AJ6: =SUM(AI5-AI6) -> -5435294.1
A7: =Gen!A12 -> 43771 | B7: ='Summery Report'!E6 -> 58 | C7: =Gen!B12 -> 0.766 | D7: ='Summery Report'!E6 -> 58 | E7: =SUM(E6) -> 1.3262195 | F7: =SUM(J7*E7)/D7 -> 57.223399 | G7: =SUM(L7*E7)/D7 -> 72.304573 | H7: =Gen!C12 -> 50727.24 | I7: =Gen!E12 -> 0 | J7: =Gen!S12 -> 2502.57 | K7: =Gen!AJ12 -> 659.55 | L7: =SUM(J7:K7) -> 3162.12 | M7: ='Water-Meter'!K47 -> 391.26405 | N7: ='Water-Meter'!E7 -> 139 | P7: 18537 | Q7: =SUM(P7-P6) -> 0 | R7: =SUM(Q7*O7) -> 0 | T7: 15719 | U7: =T7-T6 -> 0 | V7: =SUM(U7*S7) -> 0 | X7: 21284 | Y7: =X7-X6 -> 23 | Z7: =SUM(Y7*W7) -> 0 | AA7: =SUM(Z7*X9) -> 0 | AB7: 15328 | AC7: =AB7-AB6 -> 120 | AD7: 190885 | AE7: =AD7-AD6 -> 30 | AF7: ='Lpg (2)'!B11*2000/85 -> 1647.0588 | AG7: ='Lpg (2)'!C11*1000/85 -> 1000 | AH7: ='Lpg (2)'!D11*1000/85 -> 1000 | AI7: =SUM(AF6*2000)+(AG7*1000)+(AH7*1000) -> 5435294.1 | AJ7: =SUM(AI6-AI7) -> 0
A8: =Gen!A13 -> 43772 | B8: ='Summery Report'!E7 -> 9 | C8: =Gen!B13 -> 0.11 | D8: ='Summery Report'!E7 -> 9 | E8: =SUM(E7) -> 1.3262195 | F8: =SUM(J8*E8)/D8 -> 307.51052 | G8: =SUM(L8*E8)/D8 -> 346.04456 | H8: =Gen!C13 -> 47565.12 | I8: =Gen!E13 -> 0 | J8: =Gen!S13 -> 2086.83 | K8: =Gen!AJ13 -> 261.5 | L8: =SUM(J8:K8) -> 2348.33 | M8: ='Water-Meter'!K48 -> 341.7809 | N8: ='Water-Meter'!E8 -> 132 | P8: 18537 | Q8: =SUM(P8-P7) -> 0 | R8: =SUM(Q8*O8) -> 0 | T8: 15719 | U8: =T8-T7 -> 0 | V8: =SUM(U8*S8) -> 0 | X8: 21287 | Y8: =X8-X7 -> 3 | Z8: =SUM(Y8*W8) -> 0 | AA8: =SUM(Z8*X10) -> 0 | AB8: 15453 | AC8: =AB8-AB7 -> 125 | AD8: 190923 | AE8: =AD8-AD7 -> 38 | AF8: ='Lpg (2)'!B12*2000/85 -> 1552.9412 | AG8: ='Lpg (2)'!C12*1000/85 -> 1000 | AH8: ='Lpg (2)'!D12*1000/85 -> 1000 | AI8: =SUM(AF7*2000)+(AG8*1000)+(AH8*1000) -> 5294117.6 | AJ8: =SUM(AI7-AI8) -> 141176.47
A9: =Gen!A14 -> 43773 | B9: ='Summery Report'!E8 -> 10 | C9: =Gen!B14 -> 0.13 | D9: ='Summery Report'!E8 -> 10 | E9: =SUM(E8) -> 1.3262195 | F9: =SUM(J9*E9)/D9 -> 243.25651 | G9: =SUM(L9*E9)/D9 -> 245.5628 | H9: =Gen!C14 -> 45216.79 | I9: =Gen!E14 -> 0 | J9: =Gen!S14 -> 1834.21 | K9: =Gen!AJ14 -> 17.39 | L9: =SUM(J9:K9) -> 1851.6 | M9: ='Water-Meter'!K49 -> 436.21568 | N9: ='Water-Meter'!E9 -> 100 | P9: 18537 | Q9: =SUM(P9-P8) -> 0 | R9: =SUM(Q9*O9) -> 0 | T9: 15719 | U9: =T9-T8 -> 0 | V9: =SUM(U9*S9) -> 0 | X9: 21287 | Y9: =X9-X8 -> 0 | Z9: =SUM(Y9*W9) -> 0 | AA9: =SUM(Z9*X11) -> 0 | AB9: 15485 | AC9: =AB9-AB8 -> 32 | AD9: 190963 | AE9: =AD9-AD8 -> 40 | AF9: ='Lpg (2)'!B13*2000/85 -> 1458.8235 | AG9: ='Lpg (2)'!C13*1000/85 -> 1000 | AH9: ='Lpg (2)'!D13*1000/85 -> 1000 | AI9: =SUM(AF8*2000)+(AG9*1000)+(AH9*1000) -> 5105882.4 | AJ9: =SUM(AI8-AI9) -> 188235.29
A10: =Gen!A15 -> 43774 | B10: ='Summery Report'!E9 -> 25 | C10: =Gen!B15 -> 0.506 | D10: ='Summery Report'!E9 -> 25 | E10: =SUM(E9) -> 1.3262195 | F10: =SUM(J10*E10)/D10 -> 112.3414 | G10: =SUM(L10*E10)/D10 -> 113.34615 | H10: =Gen!C15 -> 43365.19 | I10: =Gen!E15 -> 0 | J10: =Gen!S15 -> 2117.7 | K10: =Gen!AJ15 -> 18.94 | L10: =SUM(J10:K10) -> 2136.64 | M10: ='Water-Meter'!K50 -> 453.26024 | N10: ='Water-Meter'!E10 -> 119 | P10: 18537 | Q10: =SUM(P10-P9) -> 0 | R10: =SUM(Q10*O10) -> 0 | T10: 15719 | U10: =T10-T9 -> 0 | V10: =SUM(U10*S10) -> 0 | X10: 21287 | Y10: =X10-X9 -> 0 | Z10: =SUM(Y10*W10) -> 0 | AA10: =SUM(Z10*X12) -> 0 | AB10: 15485 | AC10: =AB10-AB9 -> 0 | AD10: 191004 | AE10: =AD10-AD9 -> 41 | AF10: ='Lpg (2)'!B14*2000/85 -> 1411.7647 | AG10: ='Lpg (2)'!C14*1000/85 -> 1000 | AH10: ='Lpg (2)'!D14*1000/85 -> 1000 | AI10: =SUM(AF9*2000)+(AG10*1000)+(AH10*1000) -> 4917647.1 | AJ10: =SUM(AI9-AI10) -> 188235.29
A11: =Gen!A16 -> 43775 | B11: ='Summery Report'!E10 -> 24 | C11: =Gen!B16 -> 0.312 | D11: ='Summery Report'!E10 -> 24 | E11: =SUM(E10) -> 1.3262195 | F11: =SUM(J11*E11)/D11 -> 134.59636 | G11: =SUM(L11*E11)/D11 -> 142.46139 | H11: =Gen!C16 -> 41228.55 | I11: =Gen!E16 -> 0 | J11: =Gen!S16 -> 2435.73 | K11: =Gen!AJ16 -> 142.33 | L11: =SUM(J11:K11) -> 2578.06 | M11: ='Water-Meter'!K51 -> 447.32465 | N11: ='Water-Meter'!E11 -> 110 | P11: 18537 | Q11: =SUM(P11-P10) -> 0 | R11: =SUM(Q11*O11) -> 0 | T11: 15719 | U11: =T11-T10 -> 0 | V11: =SUM(U11*S11) -> 0 | W11: 5 | X11: 21339 | Y11: =X11-X10 -> 52 | Z11: =SUM(Y11*W11) -> 260 | AA11: =SUM(Z11*X13) -> 5560620 | AB11: 15592 | AC11: =AB11-AB10 -> 107 | AD11: 191043 | AE11: =AD11-AD10 -> 39 | AF11: ='Lpg (2)'!B15*2000/85 -> 1317.6471 | AG11: ='Lpg (2)'!C15*1000/85 -> 1000 | AH11: ='Lpg (2)'!D15*1000/85 -> 1000 | AI11: =SUM(AF10*2000)+(AG11*1000)+(AH11*1000) -> 4823529.4 | AJ11: =SUM(AI10-AI11) -> 94117.647
A12: =Gen!A17 -> 43776 | B12: ='Summery Report'!E11 -> 17 | C12: =Gen!B17 -> 0.195 | D12: ='Summery Report'!E11 -> 17 | E12: =SUM(E11) -> 1.3262195 | F12: =SUM(J12*E12)/D12 -> 173.96567 | G12: =SUM(L12*E12)/D12 -> 192.79175 | H12: =Gen!C17 -> 38650.49 | I12: =Gen!E17 -> 0 | J12: =Gen!S17 -> 2229.96 | K12: =Gen!AJ17 -> 241.32 | L12: =SUM(J12:K12) -> 2471.28 | M12: ='Water-Meter'!K52 -> 455.82346 | N12: ='Water-Meter'!E12 -> 95 | P12: 18537 | Q12: =SUM(P12-P11) -> 0 | R12: =SUM(Q12*O12) -> 0 | T12: 15719 | U12: =T12-T11 -> 0 | V12: =SUM(U12*S12) -> 0 | W12: 5 | X12: 21363 | Y12: =X12-X11 -> 24 | Z12: =SUM(Y12*W12) -> 120 | AA12: =SUM(Z12*X14) -> 2569320 | AB12: 15704 | AC12: =AB12-AB11 -> 112 | AD12: 191073 | AE12: =AD12-AD11 -> 30 | AF12: ='Lpg (2)'!B16*2000/85 -> 1270.5882 | AG12: ='Lpg (2)'!C16*1000/85 -> 1000 | AH12: ='Lpg (2)'!D16*1000/85 -> 1000 | AI12: =SUM(AF11*2000)+(AG12*1000)+(AH12*1000) -> 4635294.1 | AJ12: =SUM(AI11-AI12) -> 188235.29
A13: =Gen!A18 -> 43777 | B13: ='Summery Report'!E12 -> 13 | C13: =Gen!B18 -> 0.169 | D13: ='Summery Report'!E12 -> 13 | E13: =SUM(E12) -> 1.3262195 | F13: =SUM(J13*E13)/D13 -> 214.28137 | G13: =SUM(L13*E13)/D13 -> 230.50715 | H13: =Gen!C18 -> 51179.21 | I13: =Gen!E18 -> 15000 | J13: =Gen!S18 -> 2100.45 | K13: =Gen!AJ18 -> 159.05 | L13: =SUM(J13:K13) -> 2259.5 | M13: ='Water-Meter'!K53 -> 434.47053 | N13: ='Water-Meter'!E13 -> 120 | P13: 18537 | Q13: =SUM(P13-P12) -> 0 | R13: =SUM(Q13*O13) -> 0 | T13: 15719 | U13: =T13-T12 -> 0 | V13: =SUM(U13*S13) -> 0 | W13: 5 | X13: 21387 | Y13: =X13-X12 -> 24 | Z13: =SUM(Y13*W13) -> 120 | AA13: =SUM(Z13*X15) -> 2571360 | AB13: 15813 | AC13: =AB13-AB12 -> 109 | AD13: 191125 | AE13: =AD13-AD12 -> 52 | AF13: ='Lpg (2)'!B17*2000/85 -> 1176.4706 | AG13: ='Lpg (2)'!C17*1000/85 -> 1000 | AH13: ='Lpg (2)'!D17*1000/85 -> 1000 | AI13: =SUM(AF12*2000)+(AG13*1000)+(AH13*1000) -> 4541176.5 | AJ13: =SUM(AI12-AI13) -> 94117.647
A14: =Gen!A19 -> 43778 | B14: ='Summery Report'!E13 -> 13 | C14: =Gen!B19 -> 0.169 | D14: ='Summery Report'!E13 -> 13 | E14: =SUM(E13) -> 1.3262195 | F14: =SUM(J14*E14)/D14 -> 217.31331 | G14: =SUM(L14*E14)/D14 -> 229.85731 | H14: =Gen!C19 -> 48919.71 | I14: =Gen!E19 -> 0 | J14: =Gen!S19 -> 2130.17 | K14: =Gen!AJ19 -> 122.96 | L14: =SUM(J14:K14) -> 2253.13 | M14: ='Water-Meter'!K54 -> 428.07494 | N14: ='Water-Meter'!E14 -> 96 | P14: 18537 | Q14: =SUM(P14-P13) -> 0 | R14: =SUM(Q14*O14) -> 0 | T14: 15719 | U14: =T14-T13 -> 0 | V14: =SUM(U14*S14) -> 0 | W14: 5 | X14: 21411 | Y14: =X14-X13 -> 24 | Z14: =SUM(Y14*W14) -> 120 | AA14: =SUM(Z14*X16) -> 2574120 | AB14: 15923 | AC14: =AB14-AB13 -> 110 | AD14: 191162 | AE14: =AD14-AD13 -> 37 | AF14: ='Lpg (2)'!B18*2000/85 -> 1105.8824 | AG14: ='Lpg (2)'!C18*1000/85 -> 1000 | AH14: ='Lpg (2)'!D18*1000/85 -> 1000 | AI14: =SUM(AF13*2000)+(AG14*1000)+(AH14*1000) -> 4352941.2 | AJ14: =SUM(AI13-AI14) -> 188235.29
A15: =Gen!A20 -> 43779 | B15: ='Summery Report'!E14 -> 36 | C15: =Gen!B20 -> 0.468 | D15: ='Summery Report'!E14 -> 36 | E15: =SUM(E14) -> 1.3262195 | F15: =SUM(J15*E15)/D15 -> 82.586636 | G15: =SUM(L15*E15)/D15 -> 91.114964 | H15: =Gen!C20 -> 46666.58 | I15: =Gen!E20 -> 0 | J15: =Gen!S20 -> 2241.8 | K15: =Gen!AJ20 -> 231.5 | L15: =SUM(J15:K15) -> 2473.3 | M15: ='Water-Meter'!K55 -> 426.59128 | N15: ='Water-Meter'!E15 -> 124 | P15: 18537 | Q15: =SUM(P15-P14) -> 0 | R15: =SUM(Q15*O15) -> 0 | T15: 15719 | U15: =T15-T14 -> 0 | V15: =SUM(U15*S15) -> 0 | W15: 5.3 | X15: 21428 | Y15: =X15-X14 -> 17 | Z15: =SUM(Y15*W15) -> 90.1 | AA15: =SUM(Z15*X17) -> 1933546 | AB15: 16004 | AC15: =AB15-AB14 -> 81 | AD15: 191197 | AE15: =AD15-AD14 -> 35 | AF15: ='Lpg (2)'!B19*2000/85 -> 1058.8235 | AG15: ='Lpg (2)'!C19*1000/85 -> 1000 | AH15: ='Lpg (2)'!D19*1000/85 -> 1000 | AI15: =SUM(AF15*2000)+(AG15*1000)+(AH15*1000) -> 4117647.1 | AJ15: =SUM(AI14-AI15) -> 235294.12
A16: =Gen!A21 -> 43780 | B16: ='Summery Report'!E15 -> 73 | C16: =Gen!B21 -> 0.948 | D16: ='Summery Report'!E15 -> 73 | E16: =SUM(E15) -> 1.3262195 | F16: =SUM(J16*E16)/D16 -> 48.188095 | G16: =SUM(L16*E16)/D16 -> 48.188095 | H16: =Gen!C21 -> 44193.28 | I16: =Gen!E21 -> 0 | J16: =Gen!S21 -> 2652.45 | K16: =Gen!AJ21 -> 0 | L16: =SUM(J16:K16) -> 2652.45 | M16: ='Water-Meter'!K56 -> 387.25523 | N16: ='Water-Meter'!E16 -> 131 | P16: 18537 | Q16: =SUM(P16-P15) -> 0 | R16: =SUM(Q16*O16) -> 0 | T16: 15719 | U16: =T16-T15 -> 0 | V16: =SUM(U16*S16) -> 0 | W16: 5.3 | X16: 21451 | Y16: =X16-X15 -> 23 | Z16: =SUM(Y16*W16) -> 121.9 | AA16: =SUM(Z16*X18) -> 2618899.6 | AB16: 16121 | AC16: =AB16-AB15 -> 117 | AD16: 191227 | AE16: =AD16-AD15 -> 30 | AF16: ='Lpg (2)'!B20*2000/85 -> 988.23529 | AG16: ='Lpg (2)'!C20*1000/85 -> 1000 | AH16: ='Lpg (2)'!D20*1000/85 -> 1000 | AI16: =SUM(AF16*2000)+(AG16*1000)+(AH16*1000) -> 3976470.6 | AJ16: =SUM(AI15-AI16) -> 141176.47
A17: =Gen!A22 -> 43781 | B17: ='Summery Report'!E16 -> 73 | C17: =Gen!B22 -> 0.935 | D17: ='Summery Report'!E16 -> 73 | E17: =SUM(E16) -> 1.3262195 | F17: =SUM(J17*E17)/D17 -> 47.007396 | G17: =SUM(L17*E17)/D17 -> 50.419414 | H17: =Gen!C22 -> 41540.83 | I17: =Gen!E22 -> 0 | J17: =Gen!S22 -> 2587.46 | K17: =Gen!AJ22 -> 187.81 | L17: =SUM(J17:K17) -> 2775.27 | M17: ='Water-Meter'!K57 -> 340.02931 | N17: ='Water-Meter'!E17 -> 136 | P17: 18537 | Q17: =SUM(P18-P16) -> 0 | R17: =SUM(Q17*O17) -> 0 | T17: 15719 | U17: =T17-T16 -> 0 | V17: =SUM(U17*S17) -> 0 | X17: 21460 | Y17: =X17-X16 -> 9 | Z17: =SUM(Y17*W17) -> 0 | AA17: =SUM(Z17*X19) -> 0 | AB17: 16163 | AC17: =AB17-AB16 -> 42 | AD17: 191268 | AE17: =AD17-AD16 -> 41 | AF17: ='Lpg (2)'!B21*2000/85 -> 917.64706 | AG17: ='Lpg (2)'!C21*1000/85 -> 1000 | AH17: ='Lpg (2)'!D21*1000/85 -> 1000 | AI17: =SUM(AF17*2000)+(AG17*1000)+(AH17*1000) -> 3835294.1 | AJ17: =SUM(AI16-AI17) -> 141176.47
A18: =Gen!A23 -> 43782 | B18: ='Summery Report'!E17 -> 39 | C18: =Gen!B23 -> 0.481 | D18: ='Summery Report'!E17 -> 39 | E18: =SUM(E17) -> 1.3262195 | F18: =SUM(J18*E18)/D18 -> 75.814869 | G18: =SUM(L18*E18)/D18 -> 91.127943 | H18: =Gen!C23 -> 38765.56 | I18: =Gen!E23 -> 0 | J18: =Gen!S23 -> 2229.48 | K18: =Gen!AJ23 -> 450.31 | L18: =SUM(J18:K18) -> 2679.79 | M18: ='Water-Meter'!K58 -> 413.74011 | N18: ='Water-Meter'!E18 -> 123 | P18: 18537 | R18: =SUM(Q18*O18) -> 0 | T18: 15719 | U18: =T18-T17 -> 0 | V18: =SUM(U18*S18) -> 0 | X18: 21484 | Y18: =X18-X17 -> 24 | Z18: =SUM(Y18*W18) -> 0 | AA18: =SUM(Z18*X20) -> 0 | AB18: 16275 | AC18: =AB18-AB17 -> 112 | AD18: 191308 | AE18: =AD18-AD17 -> 40 | AF18: ='Lpg (2)'!B22*2000/85 -> 823.52941 | AG18: ='Lpg (2)'!C22*1000/85 -> 1000 | AH18: ='Lpg (2)'!D22*1000/85 -> 1000 | AI18: =SUM(AF18*2000)+(AG18*1000)+(AH18*1000) -> 3647058.8 | AJ18: =SUM(AI17-AI18) -> 188235.29
A19: =Gen!A24 -> 43783 | B19: ='Summery Report'!E18 -> 41 | C19: =Gen!B24 -> 0.526 | D19: ='Summery Report'!E18 -> 41 | E19: =SUM(E18) -> 1.3262195 | F19: =SUM(J19*E19)/D19 -> 76.608908 | G19: =SUM(L19*E19)/D19 -> 85.782789 | H19: =Gen!C24 -> 36085.77 | I19: =Gen!E24 -> 0 | J19: =Gen!S24 -> 2368.36 | K19: =Gen!AJ24 -> 283.61 | L19: =SUM(J19:K19) -> 2651.97 | M19: ='Water-Meter'!K59 -> 354.58075 | N19: ='Water-Meter'!E19 -> 118 | P19: 18537 | R19: =SUM(Q19*O19) -> 0 | T19: 15719 | U19: =T19-T18 -> 0 | V19: =SUM(U19*S19) -> 0 | X19: 21508 | Y19: =X19-X18 -> 24 | Z19: =SUM(Y19*W19) -> 0 | AA19: =SUM(Z19*X21) -> 0 | AB19: 16388 | AC19: =AB19-AB18 -> 113 | AD19: 191349 | AE19: =AD19-AD18 -> 41 | AF19: ='Lpg (2)'!B23*2000/85 -> 705.88235 | AG19: ='Lpg (2)'!C23*1000/85 -> 1000 | AH19: ='Lpg (2)'!D23*1000/85 -> 1000 | AI19: =SUM(AF19*2000)+(AG19*1000)+(AH19*1000) -> 3411764.7 | AJ19: =SUM(AI18-AI19) -> 235294.12
A20: =Gen!A25 -> 43784 | B20: ='Summery Report'!E19 -> 17 | C20: =Gen!B25 -> 0.221 | D20: ='Summery Report'!E19 -> 17 | E20: =SUM(E19) -> 1.3262195 | F20: =SUM(J20*E20)/D20 -> 166.45225 | G20: =SUM(L20*E20)/D20 -> 185.97342 | H20: =Gen!C25 -> 33433.8 | I20: =Gen!E25 -> 18000 | J20: =Gen!S25 -> 2133.65 | K20: =Gen!AJ25 -> 250.23 | L20: =SUM(J20:K20) -> 2383.88 | M20: ='Water-Meter'!K60 -> 376.47359 | N20: ='Water-Meter'!E20 -> 107 | P20: 18537 | Q20: =SUM(P20-P19) -> 0 | R20: =SUM(Q20*O20) -> 0 | T20: 15719 | U20: =T20-T19 -> 0 | V20: =SUM(U20*S20) -> 0 | W20: 5 | X20: 21533 | Y20: =X20-X19 -> 25 | Z20: =SUM(Y20*W20) -> 125 | AA20: =SUM(Z20*X22) -> 2697625 | AB20: 16498 | AC20: =AB20-AB19 -> 110 | AD20: 191381 | AE20: =AD20-AD19 -> 32 | AF20: ='Lpg (2)'!B24*2000/85 -> 752.94118 | AG20: ='Lpg (2)'!C24*1000/85 -> 1000 | AH20: ='Lpg (2)'!D24*1000/85 -> 1000 | AI20: =SUM(AF20*2000)+(AG20*1000)+(AH20*1000) -> 3505882.4 | AJ20: =SUM(AI19-AI20) -> -94117.647
A21: =Gen!A26 -> 43785 | B21: ='Summery Report'!E20 -> 12 | C21: =Gen!B26 -> 0.156 | D21: ='Summery Report'!E20 -> 12 | E21: =SUM(E20) -> 1.3262195 | F21: =SUM(J21*E21)/D21 -> 231.99116 | G21: =SUM(L21*E21)/D21 -> 252.17843 | H21: =Gen!C26 -> 49049.92 | I21: =Gen!E26 -> 0 | J21: =Gen!S26 -> 2099.12 | K21: =Gen!AJ26 -> 182.66 | L21: =SUM(J21:K21) -> 2281.78 | M21: ='Water-Meter'!K61 -> 360.88326 | N21: ='Water-Meter'!E21 -> 115 | P21: 18537 | Q21: =SUM(P21-P20) -> 0 | R21: =SUM(Q21*O21) -> 0 | T21: 15719 | U21: =T21-T20 -> 0 | V21: =SUM(U21*S21) -> 0 | W21: 5 | X21: 21557 | Y21: =X21-X20 -> 24 | Z21: =SUM(Y21*W21) -> 120 | AA21: =SUM(Z21*X23) -> 2591640 | AB21: 16608 | AC21: =AB21-AB20 -> 110 | AD21: 191411 | AE21: =AD21-AD20 -> 30 | AF21: ='Lpg (2)'!B25*2000/85 -> 705.88235 | AG21: ='Lpg (2)'!C25*1000/85 -> 1000 | AH21: ='Lpg (2)'!D25*1000/85 -> 1000 | AI21: =SUM(AF21*2000)+(AG21*1000)+(AH21*1000) -> 3411764.7 | AJ21: =SUM(AI20-AI21) -> 94117.647
A22: =Gen!A27 -> 43786 | B22: ='Summery Report'!E21 -> 48 | C22: =Gen!B27 -> 0.623 | D22: ='Summery Report'!E21 -> 48 | E22: =SUM(E21) -> 1.3262195 | F22: =SUM(J22*E22)/D22 -> 66.164263 | G22: =SUM(L22*E22)/D22 -> 69.738977 | H22: =Gen!C27 -> 46768.14 | I22: =Gen!E27 -> 0 | J22: =Gen!S27 -> 2394.69 | K22: =Gen!AJ27 -> 129.38 | L22: =SUM(J22:K22) -> 2524.07 | M22: ='Water-Meter'!K62 -> 315.97577 | N22: ='Water-Meter'!E22 -> 127 | P22: 18537 | Q22: =SUM(P22-P21) -> 0 | R22: =SUM(Q22*O22) -> 0 | T22: 15719 | U22: =T22-T21 -> 0 | V22: =SUM(U22*S22) -> 0 | W22: 5 | X22: 21581 | Y22: =X22-X21 -> 24 | Z22: =SUM(Y22*W22) -> 120 | AA22: =SUM(Z22*X24) -> 2594520 | AB22: 16718 | AC22: =AB22-AB21 -> 110 | AD22: 191458 | AE22: =AD22-AD21 -> 47 | AF22: ='Lpg (2)'!B26*2000/85 -> 635.29412 | AG22: ='Lpg (2)'!C26*1000/85 -> 1000 | AH22: ='Lpg (2)'!D26*1000/85 -> 1000 | AI22: =SUM(AF22*2000)+(AG22*1000)+(AH22*1000) -> 3270588.2 | AJ22: =SUM(AI21-AI22) -> 141176.47
A23: =Gen!A28 -> 43787 | B23: ='Summery Report'!E22 -> 40 | C23: =Gen!B28 -> 0.519 | D23: ='Summery Report'!E22 -> 40 | E23: =SUM(E22) -> 1.3262195 | F23: =SUM(J23*E23)/D23 -> 75.34253 | G23: =SUM(L23*E23)/D23 -> 80.660339 | H23: =Gen!C28 -> 44244.07 | I23: =Gen!E28 -> 0 | J23: =Gen!S28 -> 2272.4 | K23: =Gen!AJ28 -> 160.39 | L23: =SUM(J23:K23) -> 2432.79 | M23: ='Water-Meter'!K63 -> 338.30512 | N23: ='Water-Meter'!E23 -> 106 | P23: 18537 | Q23: =SUM(P23-P22) -> 0 | R23: =SUM(Q23*O23) -> 0 | T23: 15719 | U23: =T23-T22 -> 0 | V23: =SUM(U23*S23) -> 0 | W23: 5 | X23: 21597 | Y23: =X23-X22 -> 16 | Z23: =SUM(Y23*W23) -> 80 | AA23: =SUM(Z23*X25) -> 1730800 | AB23: 16795 | AC23: =AB23-AB22 -> 77 | AD23: 191488 | AE23: =AD23-AD22 -> 30 | AF23: ='Lpg (2)'!B27*2000/85 -> 588.23529 | AG23: ='Lpg (2)'!C27*1000/85 -> 1000 | AH23: ='Lpg (2)'!D27*1000/85 -> 1000 | AI23: =SUM(AF23*2000)+(AG23*1000)+(AH23*1000) -> 3176470.6 | AJ23: =SUM(AI22-AI23) -> 94117.647
A24: =Gen!A29 -> 43788 | B24: ='Summery Report'!E23 -> 7 | C24: =Gen!B29 -> 0.091 | D24: ='Summery Report'!E23 -> 7 | E24: =SUM(E23) -> 1.3262195 | F24: =SUM(J24*E24)/D24 -> 351.12609 | G24: =SUM(L24*E24)/D24 -> 371.53661 | H24: =Gen!C29 -> 41811.28 | I24: =Gen!E29 -> 0 | J24: =Gen!S29 -> 1853.3 | K24: =Gen!AJ29 -> 107.73 | L24: =SUM(J24:K24) -> 1961.03 | M24: ='Water-Meter'!K64 -> 310.06303 | N24: ='Water-Meter'!E24 -> 98 | P24: 18537 | Q24: =SUM(P24-P23) -> 0 | R24: =SUM(Q24*O24) -> 0 | T24: 15719 | U24: =T24-T23 -> 0 | V24: =SUM(U24*S24) -> 0 | W24: 5.1 | X24: 21621 | Y24: =X24-X23 -> 24 | Z24: =SUM(Y24*W24) -> 122.4 | AA24: =SUM(Z24*X26) -> 2651061.6 | AB24: 16908 | AC24: =AB24-AB23 -> 113 | AD24: 191528 | AE24: =AD24-AD23 -> 40 | AF24: ='Lpg (2)'!B28*2000/85 -> 541.17647 | AG24: ='Lpg (2)'!C28*1000/85 -> 1000 | AH24: ='Lpg (2)'!D28*1000/85 -> 1000 | AI24: =SUM(AF24*2000)+(AG24*1000)+(AH24*1000) -> 3082352.9 | AJ24: =SUM(AI23-AI24) -> 94117.647
A25: =Gen!A30 -> 43789 | B25: ='Summery Report'!E24 -> 9 | C25: =Gen!B30 -> 0.117 | D25: ='Summery Report'!E24 -> 9 | E25: =SUM(E24) -> 1.3262195 | F25: =SUM(J25*E25)/D25 -> 271.819 | G25: =SUM(L25*E25)/D25 -> 284.22505 | H25: =Gen!C30 -> 39850.25 | I25: =Gen!E30 -> 0 | J25: =Gen!S30 -> 1844.62 | K25: =Gen!AJ30 -> 84.19 | L25: =SUM(J25:K25) -> 1928.81 | M25: ='Water-Meter'!K65 -> 334.37794 | N25: ='Water-Meter'!E25 -> 79 | P25: 18537 | Q25: =SUM(P25-P24) -> 0 | R25: =SUM(Q25*O25) -> 0 | T25: 15719 | U25: =T25-T24 -> 0 | V25: =SUM(U25*S25) -> 0 | W25: 5 | X25: 21635 | Y25: =X25-X24 -> 14 | Z25: =SUM(Y25*W25) -> 70 | AA25: =SUM(Z25*X27) -> 1517810 | AB25: 16970 | AC25: =AB25-AB24 -> 62 | AD25: 191585 | AE25: =AD25-AD24 -> 57 | AF25: ='Lpg (2)'!B29*2000/85 -> 470.58824 | AG25: ='Lpg (2)'!C29*1000/85 -> 1000 | AH25: ='Lpg (2)'!D29*1000/85 -> 1000 | AI25: =SUM(AF25*2000)+(AG25*1000)+(AH25*1000) -> 2941176.5 | AJ25: =SUM(AI24-AI25) -> 141176.47
A26: =Gen!A31 -> 43790 | B26: ='Summery Report'!E25 -> 10 | C26: =Gen!B31 -> 0.13 | D26: ='Summery Report'!E25 -> 10 | E26: =SUM(E25) -> 1.3262195 | F26: =SUM(J26*E26)/D26 -> 206.5189 | G26: =SUM(L26*E26)/D26 -> 211.57976 | H26: =Gen!C31 -> 37921.44 | I26: =Gen!E31 -> 0 | J26: =Gen!S31 -> 1557.2 | K26: =Gen!AJ31 -> 38.16 | L26: =SUM(J26:K26) -> 1595.36 | M26: ='Water-Meter'!K66 -> 361.96437 | N26: ='Water-Meter'!E26 -> 95 | P26: 18537 | Q26: =SUM(P26-P25) -> 0 | R26: =SUM(Q26*O26) -> 0 | T26: 15719 | U26: =T26-T25 -> 0 | V26: =SUM(U26*S26) -> 0 | W26: 4.9 | X26: 21659 | Y26: =X26-X25 -> 24 | Z26: =SUM(Y26*W26) -> 117.6 | AA26: =SUM(Z26*X28) -> 0 | AB26: 17078 | AC26: =AB26-AB25 -> 108 | AD26: 191627 | AE26: =AD26-AD25 -> 42 | AF26: ='Lpg (2)'!B30*2000/85 -> 423.52941 | AG26: ='Lpg (2)'!C30*1000/85 -> 1000 | AH26: ='Lpg (2)'!D30*1000/85 -> 1000 | AI26: =SUM(AF26*2000)+(AG26*1000)+(AH26*1000) -> 2847058.8 | AJ26: =SUM(AI25-AI26) -> 94117.647
A27: =Gen!A32 -> 43791 | B27: ='Summery Report'!E26 -> 11 | C27: =Gen!B32 -> 0.143 | D27: ='Summery Report'!E26 -> 11 | E27: =SUM(E26) -> 1.3262195 | F27: =SUM(J27*E27)/D27 -> 219.77748 | G27: =SUM(L27*E27)/D27 -> 230.1871 | H27: =Gen!C32 -> 36326.08 | I27: =Gen!E32 -> 0 | J27: =Gen!S32 -> 1822.89 | K27: =Gen!AJ32 -> 86.34 | L27: =SUM(J27:K27) -> 1909.23 | M27: ='Water-Meter'!K67 -> 354.93009 | N27: ='Water-Meter'!E27 -> 95 | P27: 18537 | Q27: =SUM(P27-P26) -> 0 | R27: =SUM(Q27*O27) -> 0 | T27: 15719 | U27: =T27-T26 -> 0 | V27: =SUM(U27*S27) -> 0 | W27: 4.9 | X27: 21683 | Y27: =X27-X26 -> 24 | Z27: =SUM(Y27*W27) -> 117.6 | AA27: =SUM(Z27*X29) -> 0 | AB27: 17186 | AC27: =AB27-AB26 -> 108 | AD27: 191657 | AE27: =AD27-AD26 -> 30 | AF27: ='Lpg (2)'!B31*2000/85 -> 352.94118 | AG27: ='Lpg (2)'!C31*1000/85 -> 1000 | AH27: ='Lpg (2)'!D31*1000/85 -> 1000 | AI27: =SUM(AF27*2000)+(AG27*1000)+(AH27*1000) -> 2705882.4 | AJ27: =SUM(AI26-AI27) -> 141176.47
A28: =Gen!A33 -> 43792 | B28: ='Summery Report'!E27 -> 13 | C28: =Gen!B33 -> 0.169 | D28: ='Summery Report'!E27 -> 13 | E28: =SUM(E27) -> 1.3262195 | F28: =SUM(J28*E28)/D28 -> 0 | G28: =SUM(L28*E28)/D28 -> 0 | H28: =Gen!C33 -> 34416.85 | I28: =Gen!E33 -> 15000 | J28: =Gen!S33 -> 0 | K28: =Gen!AJ33 -> 0 | L28: =SUM(J28:K28) -> 0 | M28: ='Water-Meter'!K68 -> 0 | N28: ='Water-Meter'!E28 -> 0 | Q28: =SUM(P28-P27) -> -18537 | R28: =SUM(Q28*O28) -> 0 | U28: =T28-T27 -> -15719 | V28: =SUM(U28*S28) -> 0 | Y28: =X28-X27 -> -21683 | Z28: =SUM(Y28*W28) -> 0 | AA28: =SUM(Z28*X30) -> 0 | AC28: =SUM(AB28-AB27) -> -17186 | AE28: =AD28-AD27 -> -191657 | AF28: ='Lpg (2)'!B32*2000/85 -> 0 | AG28: ='Lpg (2)'!C32*1000/85 -> 0 | AH28: ='Lpg (2)'!D32*1000/85 -> 0 | AI28: =SUM(AF28*2000)+(AG28*1000)+(AH28*1000) -> 0 | AJ28: =SUM(AI27-AI28) -> 2705882.4
