Workbook

Sheet TOTAL
A1: Site Name | B1: Day | C1: Month | D1: Year | E1: Total Electricity Kwh | F1: Electricity Tariff ($/Kwh) | G1: LPG (Kg) | H1: LPG $/Kg | I1: District Energy Heating Kwh | J1: District Energy Heating $/Kwh | K1: Water Utility Supply (m3) m3 | L1: Water Utility Supply (m3) $/m3 | M1: Room Nights | N1: Total Guests | O1: Utilities day cost dh
A2: Marrakech | B2: 1 | C2: 11 | D2: 2019 | E2: ='Consommation du 01.11 au 30.11'!M10 -> 20734 | F2: 1.002 | G2: ='Consommation du 01.11 au 30.11'!U10 -> 519.4 | H2: 8.3673 | I2: ='Consommation du 01.11 au 30.11'!Y10*1000 -> 13920 | J2: 0.84 | K2: ='Consommation du 01.11 au 30.11'!D10 -> 650 | L2: 12.67 | M2: ='Consommation du 01.11 au 30.11'!AC10 -> 137 | N2: 290 | O2: =E2*F2+G2*H2+I2*J2+K2*L2 -> 45049.744
A3: Marrakech | B3: =B2+1 -> 2 | C3: 11 | D3: 2019 | E3: ='Consommation du 01.11 au 30.11'!M11 -> 21601 | F3: 1.002 | G3: ='Consommation du 01.11 au 30.11'!U11 -> 853.3 | H3: 8.3673 | I3: ='Consommation du 01.11 au 30.11'!Y11*1000 -> 13600 | J3: 0.84 | K3: ='Consommation du 01.11 au 30.11'!D11 -> 490 | L3: 12.67 | M3: ='Consommation du 01.11 au 30.11'!AC11 -> 132 | N3: 272 | O3: =E3*F3+G3*H3+I3*J3+K3*L3 -> 46416.319
A4: Marrakech | B4: =B3+1 -> 3 | C4: 11 | D4: 2019 | E4: ='Consommation du 01.11 au 30.11'!M12 -> 19293 | F4: 1.002 | G4: ='Consommation du 01.11 au 30.11'!U12 -> 371 | H4: 8.3673 | I4: ='Consommation du 01.11 au 30.11'!Y12*1000 -> 15940 | J4: 0.84 | K4: ='Consommation du 01.11 au 30.11'!D12 -> 530 | L4: 12.67 | M4: ='Consommation du 01.11 au 30.11'!AC12 -> 109 | N4: 208 | O4: =E4*F4+G4*H4+I4*J4+K4*L4 -> 42540.554
A5: Marrakech | B5: =B4+1 -> 4 | C5: 11 | D5: 2019 | E5: ='Consommation du 01.11 au 30.11'!M13 -> 19635 | F5: 1.002 | G5: ='Consommation du 01.11 au 30.11'!U13 -> 296.8 | H5: 8.3673 | I5: ='Consommation du 01.11 au 30.11'!Y13*1000 -> 13990 | J5: 0.84 | K5: ='Consommation du 01.11 au 30.11'!D13 -> 530 | L5: 12.67 | M5: ='Consommation du 01.11 au 30.11'!AC13 -> 128 | N5: 239 | O5: =E5*F5+G5*H5+I5*J5+K5*L5 -> 40624.385
A6: Marrakech | B6: =B5+1 -> 5 | C6: 11 | D6: 2019 | E6: ='Consommation du 01.11 au 30.11'!M14 -> 18421 | F6: 1.002 | G6: ='Consommation du 01.11 au 30.11'!U14 -> 482.3 | H6: 8.3673 | I6: ='Consommation du 01.11 au 30.11'!Y14*1000 -> 13860 | J6: 0.84 | K6: ='Consommation du 01.11 au 30.11'!D14 -> 820 | L6: 12.67 | M6: ='Consommation du 01.11 au 30.11'!AC14 -> 138 | N6: 253 | O6: =E6*F6+G6*H6+I6*J6+K6*L6 -> 44525.191
A7: Marrakech | B7: =B6+1 -> 6 | C7: 11 | D7: 2019 | E7: ='Consommation du 01.11 au 30.11'!M15 -> 18315 | F7: 1.002 | G7: ='Consommation du 01.11 au 30.11'!U15 -> 482.3 | H7: 8.3673 | I7: ='Consommation du 01.11 au 30.11'!Y15*1000 -> 14740 | J7: 0.84 | K7: ='Consommation du 01.11 au 30.11'!D15 -> 570 | L7: 12.67 | M7: ='Consommation du 01.11 au 30.11'!AC15 -> 132 | N7: 243 | O7: =E7*F7+G7*H7+I7*J7+K7*L7 -> 41990.679
A8: Marrakech | B8: =B7+1 -> 7 | C8: 11 | D8: 2019 | E8: ='Consommation du 01.11 au 30.11'!M16 -> 17804 | F8: 1.002 | G8: ='Consommation du 01.11 au 30.11'!U16 -> 556.5 | H8: 8.3673 | I8: ='Consommation du 01.11 au 30.11'!Y16*1000 -> 15790 | J8: 0.84 | K8: ='Consommation du 01.11 au 30.11'!D16 -> 530 | L8: 12.67 | M8: ='Consommation du 01.11 au 30.11'!AC16 -> 116 | N8: 221 | O8: =E8*F8+G8*H8+I8*J8+K8*L8 -> 42474.71
A9: Marrakech | B9: =B8+1 -> 8 | C9: 11 | D9: 2019 | E9: ='Consommation du 01.11 au 30.11'!M17 -> 17945 | F9: 1.002 | G9: ='Consommation du 01.11 au 30.11'!U17 -> 964.6 | H9: 8.3673 | I9: ='Consommation du 01.11 au 30.11'!Y17*1000 -> 15530 | J9: 0.84 | K9: ='Consommation du 01.11 au 30.11'!D17 -> 520 | L9: 12.67 | M9: ='Consommation du 01.11 au 30.11'!AC17 -> 138 | N9: 275 | O9: =E9*F9+G9*H9+I9*J9+K9*L9 -> 45685.588
A10: Marrakech | B10: =B9+1 -> 9 | C10: 11 | D10: 2019 | E10: ='Consommation du 01.11 au 30.11'!M18 -> 13611 | F10: 1.002 | G10: ='Consommation du 01.11 au 30.11'!U18 -> 630.7 | H10: 8.3673 | I10: ='Consommation du 01.11 au 30.11'!Y18*1000 -> 18380 | J10: 0.84 | K10: ='Consommation du 01.11 au 30.11'!D18 -> 430 | L10: 12.67 | M10: ='Consommation du 01.11 au 30.11'!AC18 -> 137 | N10: 272 | O10: =E10*F10+G10*H10+I10*J10+K10*L10 -> 39802.778
A11: Marrakech | B11: =B10+1 -> 10 | C11: 11 | D11: 2019 | E11: ='Consommation du 01.11 au 30.11'!M19 -> 14552 | F11: 1.002 | G11: ='Consommation du 01.11 au 30.11'!U19 -> 742 | H11: 8.3673 | I11: ='Consommation du 01.11 au 30.11'!Y19*1000 -> 17980 | J11: 0.84 | K11: ='Consommation du 01.11 au 30.11'!D19 -> 460 | L11: 12.67 | M11: ='Consommation du 01.11 au 30.11'!AC19 -> 117 | N11: 222 | O11: =E11*F11+G11*H11+I11*J11+K11*L11 -> 41721.041
A12: Marrakech | B12: =B11+1 -> 11 | C12: 11 | D12: 2019 | E12: ='Consommation du 01.11 au 30.11'!M20 -> 16092 | F12: 1.002 | G12: ='Consommation du 01.11 au 30.11'!U20 -> 630.7 | H12: 8.3673 | I12: ='Consommation du 01.11 au 30.11'!Y20*1000 -> 16990 | J12: 0.84 | K12: ='Consommation du 01.11 au 30.11'!D20 -> 480 | L12: 12.67 | M12: ='Consommation du 01.11 au 30.11'!AC20 -> 94 | N12: 179 | O12: =E12*F12+G12*H12+I12*J12+K12*L12 -> 41754.64
A13: Marrakech | B13: =B12+1 -> 12 | C13: 11 | D13: 2019 | E13: ='Consommation du 01.11 au 30.11'!M21 -> 18546 | F13: 1.002 | G13: ='Consommation du 01.11 au 30.11'!U21 -> 779.1 | H13: 8.3673 | I13: ='Consommation du 01.11 au 30.11'!Y21*1000 -> 15050 | J13: 0.84 | K13: ='Consommation du 01.11 au 30.11'!D21 -> 470 | L13: 12.67 | M13: ='Consommation du 01.11 au 30.11'!AC21 -> 114 | N13: 172 | O13: =E13*F13+G13*H13+I13*J13+K13*L13 -> 43698.955
A14: Marrakech | B14: =B13+1 -> 13 | C14: 11 | D14: 2019 | E14: ='Consommation du 01.11 au 30.11'!M22 -> 17364 | F14: 1.002 | G14: ='Consommation du 01.11 au 30.11'!U22 -> 593.6 | H14: 8.3673 | I14: ='Consommation du 01.11 au 30.11'!Y22*1000 -> 15720 | J14: 0.84 | K14: ='Consommation du 01.11 au 30.11'!D22 -> 470 | L14: 12.67 | M14: ='Consommation du 01.11 au 30.11'!AC22 -> 118 | N14: 181 | O14: =E14*F14+G14*H14+I14*J14+K14*L14 -> 41525.257
... A29: Marrakech | B29: =B28+1 -> 28 | C29: 11 | D29: 2019 | E29: ='Consommation du 01.11 au 30.11'!M37 -> 15423 | F29: 1.002 | G29: ='Consommation du 01.11 au 30.11'!U37 -> 853.3 | H29: 8.3673 | I29: ='Consommation du 01.11 au 30.11'!Y37*1000 -> 14200 | J29: 0.84 | K29: ='Consommation du 01.11 au 30.11'!D37 -> 450 | L29: 12.67 | M29: ='Consommation du 01.11 au 30.11'!AC37 -> 123 | N29: 248 | O29: =E29*F29+G29*H29+I29*J29+K29*L29 -> 40223.163
A30: Marrakech | B30: =B29+1 -> 29 | C30: 11 | D30: 2019 | E30: ='Consommation du 01.11 au 30.11'!M38 -> 17188 | F30: 1.002 | G30: ='Consommation du 01.11 au 30.11'!U38 -> 630.7 | H30: 8.3673 | I30: ='Consommation du 01.11 au 30.11'!Y38*1000 -> 13630 | J30: 0.84 | K30: ='Consommation du 01.11 au 30.11'!D38 -> 410 | L30: 12.67 | M30: ='Consommation du 01.11 au 30.11'!AC38 -> 137 | N30: 277
A31: Marrakech | B31: =B30+1 -> 30 | C31: 11 | D31: 2019 | E31: ='Consommation du 01.11 au 30.11'!M39 -> 0 | F31: 1.002 | G31: ='Consommation du 01.11 au 30.11'!U39 -> 0 | H31: 8.3673 | I31: ='Consommation du 01.11 au 30.11'!Y39*1000 -> 0 | J31: 0.84 | K31: ='Consommation du 01.11 au 30.11'!D39 -> 0 | L31: 12.67 | M31: ='Consommation du 01.11 au 30.11'!AC39 -> 0

Sheet Consommation du 01.11 au 30.11
B8: Date | D8: Cons Eau/Hotel | F8: Consommation du jour en DH | J8: ELECTRICITE en KWH | M8: total | O8: Consommation du jour en DH | Q8: Cons Elec/Villa | S8: Cons Elec/RIAD | U8: GAZ en Kg | W8: Consommation du jour en DH | AB8: Temp moyenne du jour °C | AC8: Room Nights | AD8: % Occupation | AE8: Temp Piscine Adulte à 7h00 °C | AF8: Temp Piscine Adulte à 15h00 °C | AG8: Temp Piscine famille à 07h00 ° C | AH8: Temp Piscine famille à 15h00 ° C
J9: creuse 81 | K9: pleine 82 | L9: pointe 83 | X9: Compteur AVEO Mwh | Y9: consommation eau choud en Mwh | Z9: consommation du jour en DH
B10: 43770 | D10: ='Suivi EAU-ELEC'!C16 -> 650 | F10: =D10*12.67 -> 8235.5 | J10: ='Suivi EAU-ELEC'!E16 -> 6601 | K10: ='Suivi EAU-ELEC'!G16 -> 9635 | L10: ='Suivi EAU-ELEC'!I16 -> 4498 | M10: =L10+K10+J10 -> 20734 | O10: =M10*1.002 -> 20775.468 | U10: ='Suvi Gaz'!O11 -> 519.4 | W10: =U10*8.3673 -> 4345.9756 | X10: 15088.7 | Y10: =IF(X11<X10,0,X11-X10) -> 13.92 | Z10: =Y10*0.84*1000 -> 11692.8 | AB10: 27 | AC10: 137 | AD10: 0.9856 | AE10: 29.8 | AF10: 30.5 | AG10: 28 | AH10: 29
B11: =B10+1 -> 43771 | D11: ='Suivi EAU-ELEC'!C17 -> 490 | F11: =D11*12.67 -> 6208.3 | J11: ='Suivi EAU-ELEC'!E17 -> 6829 | K11: ='Suivi EAU-ELEC'!G17 -> 9858 | L11: ='Suivi EAU-ELEC'!I17 -> 4914 | M11: =L11+K11+J11 -> 21601 | O11: =M11*1.002 -> 21644.202 | U11: ='Suvi Gaz'!O12 -> 853.3 | W11: =U11*8.3673 -> 7139.8171 | X11: 15102.62 | Y11: =IF(X12<X11,0,X12-X11) -> 13.6 | Z11: =Y11*0.84*1000 -> 11424 | AB11: 26 | AC11: 132 | AD11: 0.9706 | AE11: 29.8 | AF11: 31 | AG11: 27.6 | AH11: 29.5
B12: =B11+1 -> 43772 | D12: ='Suivi EAU-ELEC'!C18 -> 530 | F12: =D12*12.67 -> 6715.1 | J12: ='Suivi EAU-ELEC'!E18 -> 6220 | K12: ='Suivi EAU-ELEC'!G18 -> 8922 | L12: ='Suivi EAU-ELEC'!I18 -> 4151 | M12: =L12+K12+J12 -> 19293 | O12: =M12*1.002 -> 19331.586 | U12: ='Suvi Gaz'!O13 -> 371 | W12: =U12*8.3673 -> 3104.2683 | X12: 15116.22 | Y12: =IF(X13<X12,0,X13-X12) -> 15.94 | Z12: =Y12*0.84*1000 -> 13389.6 | AB12: 21 | AC12: 109 | AD12: 0.8258 | AE12: 30 | AF12: 30 | AG12: 26.4 | AH12: 29.5
B13: =B12+1 -> 43773 | D13: ='Suivi EAU-ELEC'!C19 -> 530 | F13: =D13*12.67 -> 6715.1 | J13: ='Suivi EAU-ELEC'!E19 -> 5895 | K13: ='Suivi EAU-ELEC'!G19 -> 9460 | L13: ='Suivi EAU-ELEC'!I19 -> 4280 | M13: =L13+K13+J13 -> 19635 | O13: =M13*1.002 -> 19674.27 | U13: ='Suvi Gaz'!O14 -> 296.8 | W13: =U13*8.3673 -> 2483.4146 | X13: 15132.16 | Y13: =IF(X14<X13,0,X14-X13) -> 13.99 | Z13: =Y13*0.84*1000 -> 11751.6 | AB13: 21 | AC13: 128 | AD13: 0.9275 | AE13: 30 | AF13: 30 | AG13: 25.6 | AH13: 25.8
B14: =B13+1 -> 43774 | D14: ='Suivi EAU-ELEC'!C20 -> 820 | F14: =D14*12.67 -> 10389.4 | J14: ='Suivi EAU-ELEC'!E20 -> 5595 | K14: ='Suivi EAU-ELEC'!G20 -> 9063 | L14: ='Suivi EAU-ELEC'!I20 -> 3763 | M14: =L14+K14+J14 -> 18421 | O14: =M14*1.002 -> 18457.842 | U14: ='Suvi Gaz'!O15 -> 482.3 | W14: =U14*8.3673 -> 4035.5488 | X14: 15146.15 | Y14: =IF(X15<X14,0,X15-X14) -> 13.86 | Z14: =Y14*0.84*1000 -> 11642.4 | AB14: 18 | AC14: 138 | AD14: 0.9928 | AE14: 29.8 | AF14: 30 | AG14: 28.5 | AH14: 29
B15: =B14+1 -> 43775 | D15: ='Suivi EAU-ELEC'!C21 -> 570 | F15: =D15*12.67 -> 7221.9 | J15: ='Suivi EAU-ELEC'!E21 -> 5443 | K15: ='Suivi EAU-ELEC'!G21 -> 8722 | L15: ='Suivi EAU-ELEC'!I21 -> 4150 | M15: =L15+K15+J15 -> 18315 | O15: =M15*1.002 -> 18351.63 | U15: ='Suvi Gaz'!O16 -> 482.3 | W15: =U15*8.3673 -> 4035.5488 | X15: 15160.01 | Y15: =IF(X16<X15,0,X16-X15) -> 14.74 | Z15: =Y15*0.84*1000 -> 12381.6 | AB15: 20 | AC15: 132 | AD15: 0.9496 | AE15: 28.6 | AF15: 29 | AG15: 26 | AH15: 27
B16: =B15+1 -> 43776 | D16: ='Suivi EAU-ELEC'!C22 -> 530 | F16: =D16*12.67 -> 6715.1 | J16: ='Suivi EAU-ELEC'!E22 -> 5630 | K16: ='Suivi EAU-ELEC'!G22 -> 7812 | L16: ='Suivi EAU-ELEC'!I22 -> 4362 | M16: =L16+K16+J16 -> 17804 | O16: =M16*1.002 -> 17839.608 | U16: ='Suvi Gaz'!O17 -> 556.5 | W16: =U16*8.3673 -> 4656.4025 | X16: 15174.75 | Y16: =IF(X17<X16,0,X17-X16) -> 15.79 | Z16: =Y16*0.84*1000 -> 13263.6 | AB16: 20 | AC16: 116 | AD16: 0.8467 | AE16: 28.8 | AF16: 29 | AG16: 26.5 | AH16: 27
B17: =B16+1 -> 43777 | D17: ='Suivi EAU-ELEC'!C23 -> 520 | F17: =D17*12.67 -> 6588.4 | J17: ='Suivi EAU-ELEC'!E23 -> 5438 | K17: ='Suivi EAU-ELEC'!G23 -> 8595 | L17: ='Suivi EAU-ELEC'!I23 -> 3912 | M17: =L17+K17+J17 -> 17945 | O17: =M17*1.002 -> 17980.89 | U17: ='Suvi Gaz'!O18 -> 964.6 | W17: =U17*8.3673 -> 8071.0976 | X17: 15190.54 | Y17: =IF(X18<X17,0,X18-X17) -> 15.53 | Z17: =Y17*0.84*1000 -> 13045.2 | AB17: 19 | AC17: 138 | AD17: 1 | AE17: 26.5 | AF17: 29 | AG17: 28.5 | AH17: 27
B18: =B17+1 -> 43778 | D18: ='Suivi EAU-ELEC'!C24 -> 430 | F18: =D18*12.67 -> 5448.1 | J18: ='Suivi EAU-ELEC'!E24 -> 4337 | K18: ='Suivi EAU-ELEC'!G24 -> 6359 | L18: ='Suivi EAU-ELEC'!I24 -> 2915 | M18: =L18+K18+J18 -> 13611 | O18: =M18*1.002 -> 13638.222 | U18: ='Suvi Gaz'!O19 -> 630.7 | W18: =U18*8.3673 -> 5277.2561 | X18: 15206.07 | Y18: =IF(X19<X18,0,X19-X18) -> 18.38 | Z18: =Y18*0.84*1000 -> 15439.2 | AB18: 18 | AC18: 137 | AD18: 0.9856 | AE18: 27 | AF18: 28.5 | AG18: 26.5 | AH18: 27.5
B19: =B18+1 -> 43779 | D19: ='Suivi EAU-ELEC'!C25 -> 460 | F19: =D19*12.67 -> 5828.2 | J19: ='Suivi EAU-ELEC'!E25 -> 5086 | K19: ='Suivi EAU-ELEC'!G25 -> 6258 | L19: ='Suivi EAU-ELEC'!I25 -> 3208 | M19: =L19+K19+J19 -> 14552 | O19: =M19*1.002 -> 14581.104 | U19: ='Suvi Gaz'!O20 -> 742 | W19: =U19*8.3673 -> 6208.5366 | X19: 15224.45 | Y19: =IF(X20<X19,0,X20-X19) -> 17.98 | Z19: =Y19*0.84*1000 -> 15103.2 | AB19: 18 | AC19: 117 | AD19: 0.854 | AE19: 27 | AF19: 27 | AG19: 26.4 | AH19: 26.5
B20: =B19+1 -> 43780 | D20: ='Suivi EAU-ELEC'!C26 -> 480 | F20: =D20*12.67 -> 6081.6 | J20: ='Suivi EAU-ELEC'!E26 -> 5322 | K20: ='Suivi EAU-ELEC'!G26 -> 6525 | L20: ='Suivi EAU-ELEC'!I26 -> 4245 | M20: =L20+K20+J20 -> 16092 | O20: =M20*1.002 -> 16124.184 | U20: ='Suvi Gaz'!O21 -> 630.7 | W20: =U20*8.3673 -> 5277.2561 | X20: 15242.43 | Y20: =IF(X21<X20,0,X21-X20) -> 16.99 | Z20: =Y20*0.84*1000 -> 14271.6 | AA20: 14 | AB20: 20 | AC20: 94 | AD20: 0.7015 | AE20: 27 | AF20: 27.5 | AG20: 26.5 | AH20: 26.8
B21: =B20+1 -> 43781 | D21: ='Suivi EAU-ELEC'!C27 -> 470 | F21: =D21*12.67 -> 5954.9 | J21: ='Suivi EAU-ELEC'!E27 -> 5848 | K21: ='Suivi EAU-ELEC'!G27 -> 8265 | L21: ='Suivi EAU-ELEC'!I27 -> 4433 | M21: =L21+K21+J21 -> 18546 | O21: =M21*1.002 -> 18583.092 | U21: ='Suvi Gaz'!O22 -> 779.1 | W21: =U21*8.3673 -> 6518.9634 | X21: 15259.42 | Y21: =IF(X22<X21,0,X22-X21) -> 15.05 | Z21: =Y21*0.84*1000 -> 12642 | AA21: 14 | AB21: 21 | AC21: 114 | AD21: 0.8507 | AE21: 27 | AF21: 27.5 | AG21: 27 | AH21: 27
B22: =B21+1 -> 43782 | D22: ='Suivi EAU-ELEC'!C28 -> 470 | F22: =D22*12.67 -> 5954.9 | J22: ='Suivi EAU-ELEC'!E28 -> 5368 | K22: ='Suivi EAU-ELEC'!G28 -> 8155 | L22: ='Suivi EAU-ELEC'!I28 -> 3841 | M22: =L22+K22+J22 -> 17364 | O22: =M22*1.002 -> 17398.728 | U22: ='Suvi Gaz'!O23 -> 593.6 | W22: =U22*8.3673 -> 4966.8293 | X22: 15274.47 | Y22: =IF(X23<X22,0,X23-X22) -> 15.72 | Z22: =Y22*0.84*1000 -> 13204.8 | AB22: 20 | AC22: 118 | AD22: 0.8939 | AE22: 27.4 | AF22: 28 | AG22: 27 | AH22: 28
B23: =B22+1 -> 43783 | D23: ='Suivi EAU-ELEC'!C29 -> 430 | F23: =D23*12.67 -> 5448.1 | J23: ='Suivi EAU-ELEC'!E29 -> 4313 | K23: ='Suivi EAU-ELEC'!G29 -> 6837 | L23: ='Suivi EAU-ELEC'!I29 -> 3030 | M23: =L23+K23+J23 -> 14180 | O23: =M23*1.002 -> 14208.36 | U23: ='Suvi Gaz'!O24 -> 630.7 | W23: =U23*8.3673 -> 5277.2561 | X23: 15290.19 | Y23: =IF(X24<X23,0,X24-X23) -> 14.27 | Z23: =Y23*0.84*1000 -> 11986.8 | AB23: 20 | AC23: 89 | AD23: 0.6642 | AE23: 27.5 | AF23: 28 | AG23: 27.5 | AH23: 27.8
B24: =B23+1 -> 43784 | D24: ='Suivi EAU-ELEC'!C30 -> 430 | F24: =D24*12.67 -> 5448.1 | J24: ='Suivi EAU-ELEC'!E30 -> 4161 | K24: ='Suivi EAU-ELEC'!G30 -> 5876 | L24: ='Suivi EAU-ELEC'!I30 -> 2895 | M24: =L24+K24+J24 -> 12932 | O24: =M24*1.002 -> 12957.864 | U24: ='Suvi Gaz'!O25 -> 1150.1 | W24: =U24*8.3673 -> 9623.2317 | X24: 15304.46 | Y24: =IF(X25<X24,0,X25-X24) -> 15.14 | Z24: =Y24*0.84*1000 -> 12717.6 | AB24: 15 | AC24: 91 | AD24: 0.7109 | AE24: 27.7 | AF24: 28 | AG24: 28.2 | AH24: 28.5
B25: =B24+1 -> 43785 | D25: ='Suivi EAU-ELEC'!C31 -> 490 | F25: =D25*12.67 -> 6208.3 | J25: ='Suivi EAU-ELEC'!E31 -> 4067 | K25: ='Suivi EAU-ELEC'!G31 -> 6236 | L25: ='Suivi EAU-ELEC'!I31 -> 2792 | M25: =L25+K25+J25 -> 13095 | O25: =M25*1.002 -> 13121.19 | U25: ='Suvi Gaz'!O26 -> 408.1 | W25: =U25*8.3673 -> 3414.6951 | X25: 15319.6 | Y25: =IF(X26<X25,0,X26-X25) -> 17.15 | Z25: =Y25*0.84*1000 -> 14406 | AB25: 12 | AC25: 93 | AD25: 0.6992 | AE25: 27.4 | AF25: 28 | AG25: 27.5 | AH25: 28
B26: =B25+1 -> 43786 | D26: ='Suivi EAU-ELEC'!C32 -> 410 | F26: =D26*12.67 -> 5194.7 | J26: ='Suivi EAU-ELEC'!E32 -> 3975 | K26: ='Suivi EAU-ELEC'!G32 -> 6075 | L26: ='Suivi EAU-ELEC'!I32 -> 2771 | M26: =L26+K26+J26 -> 12821 | O26: =M26*1.002 -> 12846.642 | U26: ='Suvi Gaz'!O27 -> 816.2 | W26: =U26*8.3673 -> 6829.3903 | X26: 15336.75 | Y26: =IF(X27<X26,0,X27-X26) -> 16.21 | Z26: =Y26*0.84*1000 -> 13616.4 | AB26: 15 | AC26: 109 | AD26: 0.845 | AE26: 26.5 | AF26: 27 | AG26: 26.5 | AH26: 27
B27: =B26+1 -> 43787 | D27: ='Suivi EAU-ELEC'!C33 -> 550 | F27: =D27*12.67 -> 6968.5 | J27: ='Suivi EAU-ELEC'!E33 -> 4348 | K27: ='Suivi EAU-ELEC'!G33 -> 6368 | L27: ='Suivi EAU-ELEC'!I33 -> 2967 | M27: =L27+K27+J27 -> 13683 | O27: =M27*1.002 -> 13710.366 | U27: ='Suvi Gaz'!O28 -> 927.5 | W27: =U27*8.3673 -> 7760.6708 | X27: 15352.96 | Y27: =IF(X28<X27,0,X28-X27) -> 14.57 | Z27: =Y27*0.84*1000 -> 12238.8 | AB27: 17 | AC27: 92 | AD27: 0.697 | AE27: 26.4 | AF27: 27 | AG27: 26.4 | AH27: 27
B28: =B27+1 -> 43788 | D28: ='Suivi EAU-ELEC'!C34 -> 460 | F28: =D28*12.67 -> 5828.2 | J28: ='Suivi EAU-ELEC'!E34 -> 4553 | K28: ='Suivi EAU-ELEC'!G34 -> 6645 | L28: ='Suivi EAU-ELEC'!I34 -> 3164 | M28: =L28+K28+J28 -> 14362 | O28: =M28*1.002 -> 14390.724 | U28: ='Suvi Gaz'!O29 -> 779.1 | W28: =U28*8.3673 -> 6518.9634 | X28: 15367.53 | Y28: =IF(X29<X28,0,X29-X28) -> 15.56 | Z28: =Y28*0.84*1000 -> 13070.4 | AB28: 16 | AC28: 75 | AD28: 0.5682 | AE28: 26.5 | AF28: 27 | AG28: 26.8 | AH28: 27
B29: =B28+1 -> 43789 | D29: ='Suivi EAU-ELEC'!C35 -> 460 | F29: =D29*12.67 -> 5828.2 | J29: ='Suivi EAU-ELEC'!E35 -> 4410 | K29: ='Suivi EAU-ELEC'!G35 -> 6637 | L29: ='Suivi EAU-ELEC'!I35 -> 2897 | M29: =L29+K29+J29 -> 13944 | O29: =M29*1.002 -> 13971.888 | U29: ='Suvi Gaz'!O30 -> 556.5 | W29: =U29*8.3673 -> 4656.4025 | X29: 15383.09 | Y29: =IF(X30<X29,0,X30-X29) -> 14.44 | Z29: =Y29*0.84*1000 -> 12129.6 | AB29: 17 | AC29: 54 | AD29: 0.406 | AE29: 26.4 | AF29: 27 | AG29: 26.3 | AH29: 27
B30: =B29+1 -> 43790 | D30: ='Suivi EAU-ELEC'!C36 -> 420 | F30: =D30*12.67 -> 5321.4 | J30: ='Suivi EAU-ELEC'!E36 -> 4378 | K30: ='Suivi EAU-ELEC'!G36 -> 6594 | L30: ='Suivi EAU-ELEC'!I36 -> 2937 | M30: =L30+K30+J30 -> 13909 | O30: =M30*1.002 -> 13936.818 | U30: ='Suvi Gaz'!O31 -> 1484 | W30: =U30*8.3673 -> 12417.073 | X30: 15397.53 | Y30: =IF(X31<X30,0,X31-X30) -> 8.81 | Z30: =Y30*0.84*1000 -> 7400.4 | AB30: 13 | AC30: 132 | AD30: 0.9565 | AE30: 27.4 | AF30: 28 | AG30: 27.4 | AH30: 28
B31: =B30+1 -> 43791 | D31: ='Suivi EAU-ELEC'!C37 -> 410 | F31: =D31*12.67 -> 5194.7 | J31: ='Suivi EAU-ELEC'!E37 -> 4174 | K31: ='Suivi EAU-ELEC'!G37 -> 6364 | L31: ='Suivi EAU-ELEC'!I37 -> 2851 | M31: =L31+K31+J31 -> 13389 | O31: =M31*1.002 -> 13415.778 | U31: ='Suvi Gaz'!O32 -> 593.6 | W31: =U31*8.3673 -> 4966.8293 | X31: 15406.34 | Y31: =IF(X32<X31,0,X32-X31) -> 14.85 | Z31: =Y31*0.84*1000 -> 12474 | AB31: 22 | AC31: 133 | AD31: 0.9638 | AE31: 27.4 | AF31: 28 | AG31: 27.5 | AH31: 28
B32: =B31+1 -> 43792 | D32: ='Suivi EAU-ELEC'!C38 -> 340 | F32: =D32*12.67 -> 4307.8 | J32: ='Suivi EAU-ELEC'!E38 -> 4180 | K32: ='Suivi EAU-ELEC'!G38 -> 5976 | L32: ='Suivi EAU-ELEC'!I38 -> 3168 | M32: =L32+K32+J32 -> 13324 | O32: =M32*1.002 -> 13350.648 | U32: ='Suvi Gaz'!O33 -> 816.2 | W32: =U32*8.3673 -> 6829.3903 | X32: 15421.19 | Y32: =IF(X33<X32,0,X33-X32) -> 12.6 | Z32: =Y32*0.84*1000 -> 10584 | AB32: 17 | AC32: 41 | AD32: 0.3203 | AE32: 27.5 | AF32: 28 | AG32: 28 | AH32: 29
B33: =B32+1 -> 43793 | D33: ='Suivi EAU-ELEC'!C39 -> 390 | F33: =D33*12.67 -> 4941.3 | J33: ='Suivi EAU-ELEC'!E39 -> 4665 | K33: ='Suivi EAU-ELEC'!G39 -> 6034 | L33: ='Suivi EAU-ELEC'!I39 -> 3347 | M33: =L33+K33+J33 -> 14046 | O33: =M33*1.002 -> 14074.092 | U33: ='Suvi Gaz'!O34 -> 333.9 | W33: =U33*8.3673 -> 2793.8415 | X33: 15433.79 | Y33: =IF(X34<X33,0,X34-X33) -> 18.27 | Z33: =Y33*0.84*1000 -> 15346.8 | AB33: 18 | AC33: 71 | AD33: 0.5635 | AE33: 28 | AF33: 29 | AG33: 29 | AH33: 29
... B38: =B37+1 -> 43798 | D38: ='Suivi EAU-ELEC'!C44 -> 410 | F38: =D38*12.67 -> 5194.7 | J38: ='Suivi EAU-ELEC'!E44 -> 5693 | K38: ='Suivi EAU-ELEC'!G44 -> 7168 | L38: ='Suivi EAU-ELEC'!I44 -> 4327 | M38: =L38+K38+J38 -> 17188 | O38: =M38*1.002 -> 17222.376 | U38: ='Suvi Gaz'!O39 -> 630.7 | W38: =U38*8.3673 -> 5277.2561 | X38: 15515.07 | Y38: =IF(X39<X38,0,X39-X38) -> 13.63 | Z38: =Y38*0.84*1000 -> 11449.2 | AB38: 23 | AC38: 137 | AD38: 0.9928 | AE38: 28 | AF38: 29 | AG38: 28.5 | AH38: 29
B39: =B38+1 -> 43799 | D39: ='Suivi EAU-ELEC'!C45 -> 0 | F39: =D39*12.67 -> 0 | J39: ='Suivi EAU-ELEC'!E45 -> 0 | K39: ='Suivi EAU-ELEC'!G45 -> 0 | L39: ='Suivi EAU-ELEC'!I45 -> 0 | M39: =L39+K39+J39 -> 0 | O39: =M39*1.002 -> 0 | U39: ='Suvi Gaz'!O40 -> 0 | W39: =U39*8.3673 -> 0 | X39: 15528.7 | Y39: =IF(X40<X39,0,X40-X39) -> 0 | Z39: =Y39*0.84*1000 -> 0
B40: =B39+1 -> 43800 | D40: ='Suivi EAU-ELEC'!C46 -> 0 | F40: =D40*12.67 -> 0 | J40: ='Suivi EAU-ELEC'!E46 -> 0 | K40: ='Suivi EAU-ELEC'!G46 -> 0 | L40: ='Suivi EAU-ELEC'!I46 -> 0 | M40: =L40+K40+J40 -> 0 | O40: =M40*1.002 -> 0 | U40: ='Suvi Gaz'!O41 -> 0 | W40: =U40*8.3673 -> 0 | Y40: =IF(X41<X40,0,X41-X40) -> 0 | Z40: =Y40*0.84*1000 -> 0
D41: =SUM(D10:D39) -> 13800 | F41: =SUM(F10:H39) -> 174846 | J41: =SUM(J10:J39) -> 144996 | K41: =SUM(K10:K39) -> 212141 | L41: =SUM(L10:L39) -> 103580 | M41: =SUM(M10:M39) -> 460717 | O41: =SUM(O10:Q39) -> 461638.43 | S41: =SUM(S10:S40) -> 0 | U41: =SUM(U10:U39) -> 19217.8 | W41: =SUM(W10:W39) -> 160801.1 | Y41: =SUM(Y10:Y39) -> 440 | Z41: =SUM(Z10:Z39) -> 369600
A43: ELECTRICITE / Kw/h | D43: creuse 81 | F43: 1.002 | G43: =J41 -> 144996 | J43: =G43*F43 -> 145285.99 | L43: =J43+J44+J45 -> 461638.43
D44: pleine 82 | F44: 1.002 | G44: =K41 -> 212141 | J44: =G44*F44 -> 212565.28
D45: pointe 83 | F45: 1.002 | G45: =L41 -> 103580 | J45: =G45*F45 -> 103787.16
A46: EAU HOTEL M3 | F46: 12.67 | G46: =D41 -> 13800 | J46: =G46*F46 -> 174846 | L46: =J46 -> 174846
A47: GAZ Kg | F47: 8.3673 | G47: =U41 -> 19217.8 | J47: =G47*F47 -> 160801.1 | L47: =J47 -> 160801.1

Sheet Suvi Gaz
D1: suivi Gaz
Q2: 803 | T2: 519 | W2: 800 | Z2: 802
B3: Relvé C1 | C3: cons C1 | D3: Relvé C2 | E3: cons C2 | F3: Relvé C3 | G3: cons C3 | H3: Relvé C4 | I3: cons C4 | J3: ∑ des relevés | K3: moyen general % | L3: con.j | M3: ∑ de volume en L | N3: cons./jen L | O3: cons./jen Kg | P3: cons./jen DH | Q3: livraison C1 | R3: %Avant | S3: % Après | T3: livraison C2 | U3: %Avant | V3: % Après | W3: livraison C3 | X3: %Avant | Y3: % Après | Z3: livraison C4 | AA3: %Avant | AB3: % Après | AC3: total livraison | AD3: moyen general % Avant L | AE3: moyen general % Aaprés L
A4: 43763 | B4: 71 | C4: =IF(AC4>0,((B4-R4)+(S4-B5)),IF(B5=0, ,(B4-B5))) -> 5 | D4: 72 | E4: =IF(AC4>0,((D4-U4)+(V4-D5)),IF(D5=0, ,(D4-D5))) -> 4 | F4: 70 | G4: =IF(AC4>0,((F4-X4)+(Y4-F5)),IF(F5=0, ,(F4-F5))) -> 7 | H4: 70 | I4: =IF(AC4>0,((H4-AA4)+(AB4-H5)),IF(H5=0, ,(H4-H5))) -> 6 | J4: =B4+D4+F4+H4 -> 283 | K4: =J4/4 -> 70.75 | L4: =IF(AC4>0,((K4-AD4)+(AE4-K5)),IF(K5=0, ,(K4-K5))) -> 5.5 | M4: =7000*4 -> 28000 | N4: =L4*M4/100 -> 1540 | O4: =N4*0.53 -> 816.2 | P4: =O4*8.3673 -> 6829.3903 | AC4: =Q4+T4+W4+Z4 -> 0 | AD4: =(R4+U4+X4+AA4)/4 -> 0 | AE4: =(S4+V4+Y4+AB4)/4 -> 0
A5: 43764 | B5: 66 | C5: =IF(AC5>0,((B5-R5)+(S5-B6)),IF(B6=0, ,(B5-B6))) -> 3 | D5: 68 | E5: =IF(AC5>0,((D5-U5)+(V5-D6)),IF(D6=0, ,(D5-D6))) -> 3 | F5: 63 | G5: =IF(AC5>0,((F5-X5)+(Y5-F6)),IF(F6=0, ,(F5-F6))) -> 2 | H5: 64 | I5: =IF(AC5>0,((H5-AA5)+(AB5-H6)),IF(H6=0, ,(H5-H6))) -> 2 | J5: =B5+D5+F5+H5 -> 261 | K5: =J5/4 -> 65.25 | L5: =IF(AC5>0,((K5-AD5)+(AE5-K6)),IF(K6=0, ,(K5-K6))) -> 2.5 | M5: =7000*4 -> 28000 | N5: =L5*M5/100 -> 700 | O5: =N5*0.53 -> 371 | P5: =O5*8.3673 -> 3104.2683 | AC5: =Q5+T5+W5+Z5 -> 0 | AD5: =(R5+U5+X5+AA5)/4 -> 0 | AE5: =(S5+V5+Y5+AB5)/4 -> 0
A6: 43765 | B6: 63 | C6: =IF(AC6>0,((B6-R6)+(S6-B7)),IF(B7=0, ,(B6-B7))) -> 3 | D6: 65 | E6: =IF(AC6>0,((D6-U6)+(V6-D7)),IF(D7=0, ,(D6-D7))) -> 3 | F6: 61 | G6: =IF(AC6>0,((F6-X6)+(Y6-F7)),IF(F7=0, ,(F6-F7))) -> 1 | H6: 62 | I6: =IF(AC6>0,((H6-AA6)+(AB6-H7)),IF(H7=0, ,(H6-H7))) -> 2 | J6: =B6+D6+F6+H6 -> 251 | K6: =J6/4 -> 62.75 | L6: =IF(AC6>0,((K6-AD6)+(AE6-K7)),IF(K7=0, ,(K6-K7))) -> 2.25 | M6: =7000*4 -> 28000 | N6: =L6*M6/100 -> 630 | O6: =N6*0.53 -> 333.9 | P6: =O6*8.3673 -> 2793.8415 | AC6: =Q6+T6+W6+Z6 -> 0 | AD6: =(R6+U6+X6+AA6)/4 -> 0 | AE6: =(S6+V6+Y6+AB6)/4 -> 0
A7: 43766 | B7: 60 | C7: =IF(AC7>0,((B7-R7)+(S7-B8)),IF(B8=0, ,(B7-B8))) -> 2 | D7: 62 | E7: =IF(AC7>0,((D7-U7)+(V7-D8)),IF(D8=0, ,(D7-D8))) -> 2 | F7: 60 | G7: =IF(AC7>0,((F7-X7)+(Y7-F8)),IF(F8=0, ,(F7-F8))) -> 5 | H7: 60 | I7: =IF(AC7>0,((H7-AA7)+(AB7-H8)),IF(H8=0, ,(H7-H8))) -> 3 | J7: =B7+D7+F7+H7 -> 242 | K7: =J7/4 -> 60.5 | L7: =IF(AC7>0,((K7-AD7)+(AE7-K8)),IF(K8=0, ,(K7-K8))) -> 3 | M7: =7000*4 -> 28000 | N7: =L7*M7/100 -> 840 | O7: =N7*0.53 -> 445.2 | P7: =O7*8.3673 -> 3725.122 | AC7: =Q7+T7+W7+Z7 -> 0 | AD7: =(R7+U7+X7+AA7)/4 -> 0 | AE7: =(S7+V7+Y7+AB7)/4 -> 0
A8: 43767 | B8: 58 | C8: =IF(AC8>0,((B8-R8)+(S8-B9)),IF(B9=0, ,(B8-B9))) -> 8 | D8: 60 | E8: =IF(AC8>0,((D8-U8)+(V8-D9)),IF(D9=0, ,(D8-D9))) -> 6 | F8: 55 | G8: =IF(AC8>0,((F8-X8)+(Y8-F9)),IF(F9=0, ,(F8-F9))) -> 5 | H8: 57 | I8: =IF(AC8>0,((H8-AA8)+(AB8-H9)),IF(H9=0, ,(H8-H9))) -> 5 | J8: =B8+D8+F8+H8 -> 230 | K8: =J8/4 -> 57.5 | L8: =IF(AC8>0,((K8-AD8)+(AE8-K9)),IF(K9=0, ,(K8-K9))) -> 6 | M8: =7000*4 -> 28000 | N8: =L8*M8/100 -> 1680 | O8: =N8*0.53 -> 890.4 | P8: =O8*8.3673 -> 7450.2439 | AC8: =Q8+T8+W8+Z8 -> 0 | AD8: =(R8+U8+X8+AA8)/4 -> 0 | AE8: =(S8+V8+Y8+AB8)/4 -> 0
A9: 43768 | B9: 50 | C9: =IF(AC9>0,((B9-R9)+(S9-B10)),IF(B10=0, ,(B9-B10))) -> 5 | D9: 54 | E9: =IF(AC9>0,((D9-U9)+(V9-D10)),IF(D10=0, ,(D9-D10))) -> 5 | F9: 50 | G9: =IF(AC9>0,((F9-X9)+(Y9-F10)),IF(F10=0, ,(F9-F10))) -> 9 | H9: 52 | I9: =IF(AC9>0,((H9-AA9)+(AB9-H10)),IF(H10=0, ,(H9-H10))) -> 8 | J9: =B9+D9+F9+H9 -> 206 | K9: =J9/4 -> 51.5 | L9: =IF(AC9>0,((K9-AD9)+(AE9-K10)),IF(K10=0, ,(K9-K10))) -> 6.75 | M9: =7000*4 -> 28000 | N9: =L9*M9/100 -> 1890 | O9: =N9*0.53 -> 1001.7 | P9: =O9*8.3673 -> 8381.5244 | AC9: =Q9+T9+W9+Z9 -> 0 | AD9: =(R9+U9+X9+AA9)/4 -> 0 | AE9: =(S9+V9+Y9+AB9)/4 -> 0
A10: 43769 | B10: 45 | C10: =IF(AC10>0,((B10-R10)+(S10-B11)),IF(B11=0, ,(B10-B11))) -> 4 | D10: 49 | E10: =IF(AC10>0,((D10-U10)+(V10-D11)),IF(D11=0, ,(D10-D11))) -> 5 | F10: 41 | G10: =IF(AC10>0,((F10-X10)+(Y10-F11)),IF(F11=0, ,(F10-F11))) -> 6 | H10: 44 | I10: =IF(AC10>0,((H10-AA10)+(AB10-H11)),IF(H11=0, ,(H10-H11))) -> 5 | J10: =B10+D10+F10+H10 -> 179 | K10: =J10/4 -> 44.75 | L10: =IF(AC10>0,((K10-AD10)+(AE10-K11)),IF(K11=0, ,(K10-K11))) -> 5 | M10: =7000*4 -> 28000 | N10: =L10*M10/100 -> 1400 | O10: =N10*0.53 -> 742 | P10: =O10*8.3673 -> 6208.5366 | Q10: 2998 | R10: 45 | S10: 85 | T10: 3006 | U10: 45 | V10: 85 | W10: 3303 | X10: 40 | Y10: 85 | Z10: 3202 | AA10: 44 | AB10: 85 | AC10: =Q10+T10+W10+Z10 -> 12509 | AD10: =(R10+U10+X10+AA10)/4 -> 43.5 | AE10: =(S10+V10+Y10+AB10)/4 -> 85
A11: 43770 | B11: 81 | C11: =IF(AC11>0,((B11-R11)+(S11-B12)),IF(B12=0, ,(B11-B12))) -> 2 | D11: 84 | E11: =IF(AC11>0,((D11-U11)+(V11-D12)),IF(D12=0, ,(D11-D12))) -> 4 | F11: 80 | G11: =IF(AC11>0,((F11-X11)+(Y11-F12)),IF(F12=0, ,(F11-F12))) -> 5 | H11: 80 | I11: =IF(AC11>0,((H11-AA11)+(AB11-H12)),IF(H12=0, ,(H11-H12))) -> 3 | J11: =B11+D11+F11+H11 -> 325 | K11: =J11/4 -> 81.25 | L11: =IF(AC11>0,((K11-AD11)+(AE11-K12)),IF(K12=0, ,(K11-K12))) -> 3.5 | M11: =7000*4 -> 28000 | N11: =L11*M11/100 -> 980 | O11: =N11*0.53 -> 519.4 | P11: =O11*8.3673 -> 4345.9756 | AC11: =Q11+T11+W11+Z11 -> 0 | AD11: =(R11+U11+X11+AA11)/4 -> 0 | AE11: =(S11+V11+Y11+AB11)/4 -> 0
A12: 43771 | B12: 79 | C12: =IF(AC12>0,((B12-R12)+(S12-B13)),IF(B13=0, ,(B12-B13))) -> 7 | D12: 80 | E12: =IF(AC12>0,((D12-U12)+(V12-D13)),IF(D13=0, ,(D12-D13))) -> 5 | F12: 75 | G12: =IF(AC12>0,((F12-X12)+(Y12-F13)),IF(F13=0, ,(F12-F13))) -> 5 | H12: 77 | I12: =IF(AC12>0,((H12-AA12)+(AB12-H13)),IF(H13=0, ,(H12-H13))) -> 6 | J12: =B12+D12+F12+H12 -> 311 | K12: =J12/4 -> 77.75 | L12: =IF(AC12>0,((K12-AD12)+(AE12-K13)),IF(K13=0, ,(K12-K13))) -> 5.75 | M12: =7000*4 -> 28000 | N12: =L12*M12/100 -> 1610 | O12: =N12*0.53 -> 853.3 | P12: =O12*8.3673 -> 7139.8171 | AC12: =Q12+T12+W12+Z12 -> 0 | AD12: =(R12+U12+X12+AA12)/4 -> 0 | AE12: =(S12+V12+Y12+AB12)/4 -> 0
A13: 43772 | B13: 72 | C13: =IF(AC13>0,((B13-R13)+(S13-B14)),IF(B14=0, ,(B13-B14))) -> 2 | D13: 75 | E13: =IF(AC13>0,((D13-U13)+(V13-D14)),IF(D14=0, ,(D13-D14))) -> 5 | F13: 70 | G13: =IF(AC13>0,((F13-X13)+(Y13-F14)),IF(F14=0, ,(F13-F14))) -> 2 | H13: 71 | I13: =IF(AC13>0,((H13-AA13)+(AB13-H14)),IF(H14=0, ,(H13-H14))) -> 1 | J13: =B13+D13+F13+H13 -> 288 | K13: =J13/4 -> 72 | L13: =IF(AC13>0,((K13-AD13)+(AE13-K14)),IF(K14=0, ,(K13-K14))) -> 2.5 | M13: =7000*4 -> 28000 | N13: =L13*M13/100 -> 700 | O13: =N13*0.53 -> 371 | P13: =O13*8.3673 -> 3104.2683 | AC13: =Q13+T13+W13+Z13 -> 0 | AD13: =(R13+U13+X13+AA13)/4 -> 0 | AE13: =(S13+V13+Y13+AB13)/4 -> 0
A14: 43773 | B14: 70 | C14: =IF(AC14>0,((B14-R14)+(S14-B15)),IF(B15=0, ,(B14-B15))) -> 2 | D14: 70 | E14: =IF(AC14>0,((D14-U14)+(V14-D15)),IF(D15=0, ,(D14-D15))) -> 0 | F14: 68 | G14: =IF(AC14>0,((F14-X14)+(Y14-F15)),IF(F15=0, ,(F14-F15))) -> 2 | H14: 70 | I14: =IF(AC14>0,((H14-AA14)+(AB14-H15)),IF(H15=0, ,(H14-H15))) -> 4 | J14: =B14+D14+F14+H14 -> 278 | K14: =J14/4 -> 69.5 | L14: =IF(AC14>0,((K14-AD14)+(AE14-K15)),IF(K15=0, ,(K14-K15))) -> 2 | M14: =7000*4 -> 28000 | N14: =L14*M14/100 -> 560 | O14: =N14*0.53 -> 296.8 | P14: =O14*8.3673 -> 2483.4146 | AC14: =Q14+T14+W14+Z14 -> 0 | AD14: =(R14+U14+X14+AA14)/4 -> 0 | AE14: =(S14+V14+Y14+AB14)/4 -> 0
A15: 43774 | B15: 68 | C15: =IF(AC15>0,((B15-R15)+(S15-B16)),IF(B16=0, ,(B15-B16))) -> 3 | D15: 70 | E15: =IF(AC15>0,((D15-U15)+(V15-D16)),IF(D16=0, ,(D15-D16))) -> 2 | F15: 66 | G15: =IF(AC15>0,((F15-X15)+(Y15-F16)),IF(F16=0, ,(F15-F16))) -> 4 | H15: 66 | I15: =IF(AC15>0,((H15-AA15)+(AB15-H16)),IF(H16=0, ,(H15-H16))) -> 4 | J15: =B15+D15+F15+H15 -> 270 | K15: =J15/4 -> 67.5 | L15: =IF(AC15>0,((K15-AD15)+(AE15-K16)),IF(K16=0, ,(K15-K16))) -> 3.25 | M15: =7000*4 -> 28000 | N15: =L15*M15/100 -> 910 | O15: =N15*0.53 -> 482.3 | P15: =O15*8.3673 -> 4035.5488 | AC15: =Q15+T15+W15+Z15 -> 0 | AD15: =(R15+U15+X15+AA15)/4 -> 0 | AE15: =(S15+V15+Y15+AB15)/4 -> 0
A16: 43775 | B16: 65 | C16: =IF(AC16>0,((B16-R16)+(S16-B17)),IF(B17=0, ,(B16-B17))) -> 4 | D16: 68 | E16: =IF(AC16>0,((D16-U16)+(V16-D17)),IF(D17=0, ,(D16-D17))) -> 4 | F16: 62 | G16: =IF(AC16>0,((F16-X16)+(Y16-F17)),IF(F17=0, ,(F16-F17))) -> 2 | H16: 62 | I16: =IF(AC16>0,((H16-AA16)+(AB16-H17)),IF(H17=0, ,(H16-H17))) -> 3 | J16: =B16+D16+F16+H16 -> 257 | K16: =J16/4 -> 64.25 | L16: =IF(AC16>0,((K16-AD16)+(AE16-K17)),IF(K17=0, ,(K16-K17))) -> 3.25 | M16: =7000*4 -> 28000 | N16: =L16*M16/100 -> 910 | O16: =N16*0.53 -> 482.3 | P16: =O16*8.3673 -> 4035.5488 | AC16: =Q16+T16+W16+Z16 -> 0 | AD16: =(R16+U16+X16+AA16)/4 -> 0 | AE16: =(S16+V16+Y16+AB16)/4 -> 0
A17: 43776 | B17: 61 | C17: =IF(AC17>0,((B17-R17)+(S17-B18)),IF(B18=0, ,(B17-B18))) -> 2 | D17: 64 | E17: =IF(AC17>0,((D17-U17)+(V17-D18)),IF(D18=0, ,(D17-D18))) -> 4 | F17: 60 | G17: =IF(AC17>0,((F17-X17)+(Y17-F18)),IF(F18=0, ,(F17-F18))) -> 4 | H17: 59 | I17: =IF(AC17>0,((H17-AA17)+(AB17-H18)),IF(H18=0, ,(H17-H18))) -> 5 | J17: =B17+D17+F17+H17 -> 244 | K17: =J17/4 -> 61 | L17: =IF(AC17>0,((K17-AD17)+(AE17-K18)),IF(K18=0, ,(K17-K18))) -> 3.75 | M17: =7000*4 -> 28000 | N17: =L17*M17/100 -> 1050 | O17: =N17*0.53 -> 556.5 | P17: =O17*8.3673 -> 4656.4025 | AC17: =Q17+T17+W17+Z17 -> 0 | AD17: =(R17+U17+X17+AA17)/4 -> 0 | AE17: =(S17+V17+Y17+AB17)/4 -> 0
A18: 43777 | B18: 59 | C18: =IF(AC18>0,((B18-R18)+(S18-B19)),IF(B19=0, ,(B18-B19))) -> 4 | D18: 60 | E18: =IF(AC18>0,((D18-U18)+(V18-D19)),IF(D19=0, ,(D18-D19))) -> 2 | F18: 56 | G18: =IF(AC18>0,((F18-X18)+(Y18-F19)),IF(F19=0, ,(F18-F19))) -> 12 | H18: 54 | I18: =IF(AC18>0,((H18-AA18)+(AB18-H19)),IF(H19=0, ,(H18-H19))) -> 8 | J18: =B18+D18+F18+H18 -> 229 | K18: =J18/4 -> 57.25 | L18: =IF(AC18>0,((K18-AD18)+(AE18-K19)),IF(K19=0, ,(K18-K19))) -> 6.5 | M18: =7000*4 -> 28000 | N18: =L18*M18/100 -> 1820 | O18: =N18*0.53 -> 964.6 | P18: =O18*8.3673 -> 8071.0976 | Q18: 2570 | R18: 55 | S18: 85 | T18: 2000 | U18: 58 | V18: 85 | W18: 3129 | X18: 45 | Y18: 85 | Z18: 2940 | AA18: 48 | AB18: 85 | AC18: =Q18+T18+W18+Z18 -> 10639 | AD18: =(R18+U18+X18+AA18)/4 -> 51.5 | AE18: =(S18+V18+Y18+AB18)/4 -> 85
A19: 43778 | B19: 85 | C19: =IF(AC19>0,((B19-R19)+(S19-B20)),IF(B20=0, ,(B19-B20))) -> 5 | D19: 85 | E19: =IF(AC19>0,((D19-U19)+(V19-D20)),IF(D20=0, ,(D19-D20))) -> 3 | F19: 84 | G19: =IF(AC19>0,((F19-X19)+(Y19-F20)),IF(F20=0, ,(F19-F20))) -> 4 | H19: 83 | I19: =IF(AC19>0,((H19-AA19)+(AB19-H20)),IF(H20=0, ,(H19-H20))) -> 5 | J19: =B19+D19+F19+H19 -> 337 | K19: =J19/4 -> 84.25 | L19: =IF(AC19>0,((K19-AD19)+(AE19-K20)),IF(K20=0, ,(K19-K20))) -> 4.25 | M19: =7000*4 -> 28000 | N19: =L19*M19/100 -> 1190 | O19: =N19*0.53 -> 630.7 | P19: =O19*8.3673 -> 5277.2561 | AC19: =Q19+T19+W19+Z19 -> 0 | AD19: =(R19+U19+X19+AA19)/4 -> 0 | AE19: =(S19+V19+Y19+AB19)/4 -> 0
A20: 43779 | B20: 80 | C20: =IF(AC20>0,((B20-R20)+(S20-B21)),IF(B21=0, ,(B20-B21))) -> 4 | D20: 82 | E20: =IF(AC20>0,((D20-U20)+(V20-D21)),IF(D21=0, ,(D20-D21))) -> 3 | F20: 80 | G20: =IF(AC20>0,((F20-X20)+(Y20-F21)),IF(F21=0, ,(F20-F21))) -> 7 | H20: 78 | I20: =IF(AC20>0,((H20-AA20)+(AB20-H21)),IF(H21=0, ,(H20-H21))) -> 6 | J20: =B20+D20+F20+H20 -> 320 | K20: =J20/4 -> 80 | L20: =IF(AC20>0,((K20-AD20)+(AE20-K21)),IF(K21=0, ,(K20-K21))) -> 5 | M20: =7000*4 -> 28000 | N20: =L20*M20/100 -> 1400 | O20: =N20*0.53 -> 742 | P20: =O20*8.3673 -> 6208.5366 | AC20: =Q20+T20+W20+Z20 -> 0 | AD20: =(R20+U20+X20+AA20)/4 -> 0 | AE20: =(S20+V20+Y20+AB20)/4 -> 0
A21: 43780 | B21: 76 | C21: =IF(AC21>0,((B21-R21)+(S21-B22)),IF(B22=0, ,(B21-B22))) -> 4 | D21: 79 | E21: =IF(AC21>0,((D21-U21)+(V21-D22)),IF(D22=0, ,(D21-D22))) -> 6 | F21: 73 | G21: =IF(AC21>0,((F21-X21)+(Y21-F22)),IF(F22=0, ,(F21-F22))) -> 4 | H21: 72 | I21: =IF(AC21>0,((H21-AA21)+(AB21-H22)),IF(H22=0, ,(H21-H22))) -> 3 | J21: =B21+D21+F21+H21 -> 300 | K21: =J21/4 -> 75 | L21: =IF(AC21>0,((K21-AD21)+(AE21-K22)),IF(K22=0, ,(K21-K22))) -> 4.25 | M21: =7000*4 -> 28000 | N21: =L21*M21/100 -> 1190 | O21: =N21*0.53 -> 630.7 | P21: =O21*8.3673 -> 5277.2561 | AC21: =Q21+T21+W21+Z21 -> 0 | AD21: =(R21+U21+X21+AA21)/4 -> 0 | AE21: =(S21+V21+Y21+AB21)/4 -> 0
A22: 43781 | B22: 72 | C22: =IF(AC22>0,((B22-R22)+(S22-B23)),IF(B23=0, ,(B22-B23))) -> 5 | D22: 73 | E22: =IF(AC22>0,((D22-U22)+(V22-D23)),IF(D23=0, ,(D22-D23))) -> 5 | F22: 69 | G22: =IF(AC22>0,((F22-X22)+(Y22-F23)),IF(F23=0, ,(F22-F23))) -> 6 | H22: 69 | I22: =IF(AC22>0,((H22-AA22)+(AB22-H23)),IF(H23=0, ,(H22-H23))) -> 5 | J22: =B22+D22+F22+H22 -> 283 | K22: =J22/4 -> 70.75 | L22: =IF(AC22>0,((K22-AD22)+(AE22-K23)),IF(K23=0, ,(K22-K23))) -> 5.25 | M22: =7000*4 -> 28000 | N22: =L22*M22/100 -> 1470 | O22: =N22*0.53 -> 779.1 | P22: =O22*8.3673 -> 6518.9634 | AC22: =Q22+T22+W22+Z22 -> 0 | AD22: =(R22+U22+X22+AA22)/4 -> 0 | AE22: =(S22+V22+Y22+AB22)/4 -> 0
A23: 43782 | B23: 67 | C23: =IF(AC23>0,((B23-R23)+(S23-B24)),IF(B24=0, ,(B23-B24))) -> 5 | D23: 68 | E23: =IF(AC23>0,((D23-U23)+(V23-D24)),IF(D24=0, ,(D23-D24))) -> 5 | F23: 63 | G23: =IF(AC23>0,((F23-X23)+(Y23-F24)),IF(F24=0, ,(F23-F24))) -> 3 | H23: 64 | I23: =IF(AC23>0,((H23-AA23)+(AB23-H24)),IF(H24=0, ,(H23-H24))) -> 3 | J23: =B23+D23+F23+H23 -> 262 | K23: =J23/4 -> 65.5 | L23: =IF(AC23>0,((K23-AD23)+(AE23-K24)),IF(K24=0, ,(K23-K24))) -> 4 | M23: =7000*4 -> 28000 | N23: =L23*M23/100 -> 1120 | O23: =N23*0.53 -> 593.6 | P23: =O23*8.3673 -> 4966.8293 | AC23: =Q23+T23+W23+Z23 -> 0 | AD23: =(R23+U23+X23+AA23)/4 -> 0 | AE23: =(S23+V23+Y23+AB23)/4 -> 0
A24: 43783 | B24: 62 | C24: =IF(AC24>0,((B24-R24)+(S24-B25)),IF(B25=0, ,(B24-B25))) -> 2 | D24: 63 | E24: =IF(AC24>0,((D24-U24)+(V24-D25)),IF(D25=0, ,(D24-D25))) -> 3 | F24: 60 | G24: =IF(AC24>0,((F24-X24)+(Y24-F25)),IF(F25=0, ,(F24-F25))) -> 7 | H24: 61 | I24: =IF(AC24>0,((H24-AA24)+(AB24-H25)),IF(H25=0, ,(H24-H25))) -> 5 | J24: =B24+D24+F24+H24 -> 246 | K24: =J24/4 -> 61.5 | L24: =IF(AC24>0,((K24-AD24)+(AE24-K25)),IF(K25=0, ,(K24-K25))) -> 4.25 | M24: =7000*4 -> 28000 | N24: =L24*M24/100 -> 1190 | O24: =N24*0.53 -> 630.7 | P24: =O24*8.3673 -> 5277.2561 | AC24: =Q24+T24+W24+Z24 -> 0 | AD24: =(R24+U24+X24+AA24)/4 -> 0 | AE24: =(S24+V24+Y24+AB24)/4 -> 0
A25: 43784 | B25: 60 | C25: =IF(AC25>0,((B25-R25)+(S25-B26)),IF(B26=0, ,(B25-B26))) -> 14 | D25: 60 | E25: =IF(AC25>0,((D25-U25)+(V25-D26)),IF(D26=0, ,(D25-D26))) -> 10 | F25: 53 | G25: =IF(AC25>0,((F25-X25)+(Y25-F26)),IF(F26=0, ,(F25-F26))) -> 3 | H25: 56 | I25: =IF(AC25>0,((H25-AA25)+(AB25-H26)),IF(H26=0, ,(H25-H26))) -> 4 | J25: =B25+D25+F25+H25 -> 229 | K25: =J25/4 -> 57.25 | L25: =IF(AC25>0,((K25-AD25)+(AE25-K26)),IF(K26=0, ,(K25-K26))) -> 7.75 | M25: =7000*4 -> 28000 | N25: =L25*M25/100 -> 2170 | O25: =N25*0.53 -> 1150.1 | P25: =O25*8.3673 -> 9623.2317 | Q25: 2002 | R25: 56 | S25: 81 | T25: 1999 | U25: 58 | V25: 83 | W25: 1402 | X25: 50 | Y25: 68 | Z25: 1010 | AA25: 50 | AB25: 63 | AC25: =Q25+T25+W25+Z25 -> 6413 | AD25: =(R25+U25+X25+AA25)/4 -> 53.5 | AE25: =(S25+V25+Y25+AB25)/4 -> 73.75
A26: 43785 | B26: 71 | C26: =IF(AC26>0,((B26-R26)+(S26-B27)),IF(B27=0, ,(B26-B27))) -> 2 | D26: 75 | E26: =IF(AC26>0,((D26-U26)+(V26-D27)),IF(D27=0, ,(D26-D27))) -> 6 | F26: 68 | G26: =IF(AC26>0,((F26-X26)+(Y26-F27)),IF(F27=0, ,(F26-F27))) -> 3 | H26: 65 | I26: =IF(AC26>0,((H26-AA26)+(AB26-H27)),IF(H27=0, ,(H26-H27))) -> 0 | J26: =B26+D26+F26+H26 -> 279 | K26: =J26/4 -> 69.75 | L26: =IF(AC26>0,((K26-AD26)+(AE26-K27)),IF(K27=0, ,(K26-K27))) -> 2.75 | M26: =7000*4 -> 28000 | N26: =L26*M26/100 -> 770 | O26: =N26*0.53 -> 408.1 | P26: =O26*8.3673 -> 3414.6951 | AC26: =Q26+T26+W26+Z26 -> 0 | AD26: =(R26+U26+X26+AA26)/4 -> 0 | AE26: =(S26+V26+Y26+AB26)/4 -> 0
A27: 43786 | B27: 69 | C27: =IF(AC27>0,((B27-R27)+(S27-B28)),IF(B28=0, ,(B27-B28))) -> 6 | D27: 69 | E27: =IF(AC27>0,((D27-U27)+(V27-D28)),IF(D28=0, ,(D27-D28))) -> 6 | F27: 65 | G27: =IF(AC27>0,((F27-X27)+(Y27-F28)),IF(F28=0, ,(F27-F28))) -> 6 | H27: 65 | I27: =IF(AC27>0,((H27-AA27)+(AB27-H28)),IF(H28=0, ,(H27-H28))) -> 4 | J27: =B27+D27+F27+H27 -> 268 | K27: =J27/4 -> 67 | L27: =IF(AC27>0,((K27-AD27)+(AE27-K28)),IF(K28=0, ,(K27-K28))) -> 5.5 | M27: 28000 | N27: =L27*M27/100 -> 1540 | O27: =N27*0.53 -> 816.2 | P27: =O27*8.3673 -> 6829.3903 | AC27: =Q27+T27+W27+Z27 -> 0 | AD27: =(R27+U27+X27+AA27)/4 -> 0 | AE27: =(S27+V27+Y27+AB27)/4 -> 0
A28: 43787 | B28: 63 | C28: =IF(AC28>0,((B28-R28)+(S28-B29)),IF(B29=0, ,(B28-B29))) -> 5 | D28: 63 | E28: =IF(AC28>0,((D28-U28)+(V28-D29)),IF(D29=0, ,(D28-D29))) -> 5 | F28: 59 | G28: =IF(AC28>0,((F28-X28)+(Y28-F29)),IF(F29=0, ,(F28-F29))) -> 9 | H28: 61 | I28: =IF(AC28>0,((H28-AA28)+(AB28-H29)),IF(H29=0, ,(H28-H29))) -> 6 | J28: =B28+D28+F28+H28 -> 246 | K28: =J28/4 -> 61.5 | L28: =IF(AC28>0,((K28-AD28)+(AE28-K29)),IF(K29=0, ,(K28-K29))) -> 6.25 | M28: =7000*4 -> 28000 | N28: =L28*M28/100 -> 1750 | O28: =N28*0.53 -> 927.5 | P28: =O28*8.3673 -> 7760.6708 | AC28: =Q28+T28+W28+Z28 -> 0 | AD28: =(R28+U28+X28+AA28)/4 -> 0 | AE28: =(S28+V28+Y28+AB28)/4 -> 0
A29: 43788 | B29: 58 | C29: =IF(AC29>0,((B29-R29)+(S29-B30)),IF(B30=0, ,(B29-B30))) -> 4 | D29: 58 | E29: =IF(AC29>0,((D29-U29)+(V29-D30)),IF(D30=0, ,(D29-D30))) -> 6 | F29: 50 | G29: =IF(AC29>0,((F29-X29)+(Y29-F30)),IF(F30=0, ,(F29-F30))) -> 5 | H29: 55 | I29: =IF(AC29>0,((H29-AA29)+(AB29-H30)),IF(H30=0, ,(H29-H30))) -> 6 | J29: =B29+D29+F29+H29 -> 221 | K29: =J29/4 -> 55.25 | L29: =IF(AC29>0,((K29-AD29)+(AE29-K30)),IF(K30=0, ,(K29-K30))) -> 5.25 | M29: =7000*4 -> 28000 | N29: =L29*M29/100 -> 1470 | O29: =N29*0.53 -> 779.1 | P29: =O29*8.3673 -> 6518.9634 | Q29: 2706 | R29: 55 | S29: 87 | T29: 2854 | U29: 52 | V29: 86 | W29: 3110 | X29: 46 | Y29: 85 | Z29: 3006 | AA29: 51 | AB29: 87 | AC29: =Q29+T29+W29+Z29 -> 11676 | AD29: =(R29+U29+X29+AA29)/4 -> 51 | AE29: =(S29+V29+Y29+AB29)/4 -> 86.25
A30: 43789 | B30: 86 | C30: =IF(AC30>0,((B30-R30)+(S30-B31)),IF(B31=0, ,(B30-B31))) -> 4 | D30: 86 | E30: =IF(AC30>0,((D30-U30)+(V30-D31)),IF(D31=0, ,(D30-D31))) -> 2 | F30: 84 | G30: =IF(AC30>0,((F30-X30)+(Y30-F31)),IF(F31=0, ,(F30-F31))) -> 4 | H30: 85 | I30: =IF(AC30>0,((H30-AA30)+(AB30-H31)),IF(H31=0, ,(H30-H31))) -> 5 | J30: =B30+D30+F30+H30 -> 341 | K30: =J30/4 -> 85.25 | L30: =IF(AC30>0,((K30-AD30)+(AE30-K31)),IF(K31=0, ,(K30-K31))) -> 3.75 | M30: =7000*4 -> 28000 | N30: =L30*M30/100 -> 1050 | O30: =N30*0.53 -> 556.5 | P30: =O30*8.3673 -> 4656.4025 | AC30: =Q30+T30+W30+Z30 -> 0 | AD30: =(R30+U30+X30+AA30)/4 -> 0 | AE30: =(S30+V30+Y30+AB30)/4 -> 0
A31: 43790 | B31: 82 | C31: =IF(AC31>0,((B31-R31)+(S31-B32)),IF(B32=0, ,(B31-B32))) -> 7 | D31: 84 | E31: =IF(AC31>0,((D31-U31)+(V31-D32)),IF(D32=0, ,(D31-D32))) -> 12 | F31: 80 | G31: =IF(AC31>0,((F31-X31)+(Y31-F32)),IF(F32=0, ,(F31-F32))) -> 11 | H31: 80 | I31: =IF(AC31>0,((H31-AA31)+(AB31-H32)),IF(H32=0, ,(H31-H32))) -> 10 | J31: =B31+D31+F31+H31 -> 326 | K31: =J31/4 -> 81.5 | L31: =IF(AC31>0,((K31-AD31)+(AE31-K32)),IF(K32=0, ,(K31-K32))) -> 10 | M31: =7000*4 -> 28000 | N31: =L31*M31/100 -> 2800 | O31: =N31*0.53 -> 1484 | P31: =O31*8.3673 -> 12417.073 | AC31: =Q31+T31+W31+Z31 -> 0 | AD31: =(R31+U31+X31+AA31)/4 -> 0 | AE31: =(S31+V31+Y31+AB31)/4 -> 0
A32: 43791 | B32: 75 | C32: =IF(AC32>0,((B32-R32)+(S32-B33)),IF(B33=0, ,(B32-B33))) -> 7 | D32: 72 | E32: =IF(AC32>0,((D32-U32)+(V32-D33)),IF(D33=0, ,(D32-D33))) -> 2 | F32: 69 | G32: =IF(AC32>0,((F32-X32)+(Y32-F33)),IF(F33=0, ,(F32-F33))) -> 4 | H32: 70 | I32: =IF(AC32>0,((H32-AA32)+(AB32-H33)),IF(H33=0, ,(H32-H33))) -> 3 | J32: =B32+D32+F32+H32 -> 286 | K32: =J32/4 -> 71.5 | L32: =IF(AC32>0,((K32-AD32)+(AE32-K33)),IF(K33=0, ,(K32-K33))) -> 4 | M32: =7000*4 -> 28000 | N32: =L32*M32/100 -> 1120 | O32: =N32*0.53 -> 593.6 | P32: =O32*8.3673 -> 4966.8293 | AC32: =Q32+T32+W32+Z32 -> 0 | AD32: =(R32+U32+X32+AA32)/4 -> 0 | AE32: =(S32+V32+Y32+AB32)/4 -> 0
A33: 43792 | B33: 68 | C33: =IF(AC33>0,((B33-R33)+(S33-B34)),IF(B34=0, ,(B33-B34))) -> 5 | D33: 70 | E33: =IF(AC33>0,((D33-U33)+(V33-D34)),IF(D34=0, ,(D33-D34))) -> 6 | F33: 65 | G33: 0 | H33: 67 | I33: =IF(AC33>0,((H33-AA33)+(AB33-H34)),IF(H34=0, ,(H33-H34))) -> 6 | J33: =B33+D33+F33+H33 -> 270 | K33: =J33/4 -> 67.5 | L33: =IF(AC33>0,((K33-AD33)+(AE33-K34)),IF(K34=0, ,(K33-K34))) -> 5.5 | M33: =7000*4 -> 28000 | N33: =L33*M33/100 -> 1540 | O33: =N33*0.53 -> 816.2 | P33: =O33*8.3673 -> 6829.3903 | AC33: =Q33+T33+W33+Z33 -> 0 | AD33: =(R33+U33+X33+AA33)/4 -> 0 | AE33: =(S33+V33+Y33+AB33)/4 -> 0
A34: 43793 | B34: 63 | C34: =IF(AC34>0,((B34-R34)+(S34-B35)),IF(B35=0, ,(B34-B35))) -> 3 | D34: 64 | E34: =IF(AC34>0,((D34-U34)+(V34-D35)),IF(D35=0, ,(D34-D35))) -> 2 | F34: 60 | G34: =IF(AC34>0,((F34-X34)+(Y34-F35)),IF(F35=0, ,(F34-F35))) -> 1 | H34: 61 | I34: =IF(AC34>0,((H34-AA34)+(AB34-H35)),IF(H35=0, ,(H34-H35))) -> 3 | J34: =B34+D34+F34+H34 -> 248 | K34: =J34/4 -> 62 | L34: =IF(AC34>0,((K34-AD34)+(AE34-K35)),IF(K35=0, ,(K34-K35))) -> 2.25 | M34: =7000*4 -> 28000 | N34: =L34*M34/100 -> 630 | O34: =N34*0.53 -> 333.9 | P34: =O34*8.3673 -> 2793.8415 | AC34: =Q34+T34+W34+Z34 -> 0 | AD34: =(R34+U34+X34+AA34)/4 -> 0 | AE34: =(S34+V34+Y34+AB34)/4 -> 0
A35: 43794 | B35: 60 | C35: =IF(AC35>0,((B35-R35)+(S35-B36)),IF(B36=0, ,(B35-B36))) -> 3 | D35: 62 | E35: =IF(AC35>0,((D35-U35)+(V35-D36)),IF(D36=0, ,(D35-D36))) -> 0 | F35: 59 | G35: =IF(AC35>0,((F35-X35)+(Y35-F36)),IF(F36=0, ,(F35-F36))) -> 1 | H35: 58 | I35: =IF(AC35>0,((H35-AA35)+(AB35-H36)),IF(H36=0, ,(H35-H36))) -> 3 | J35: =B35+D35+F35+H35 -> 239 | K35: =J35/4 -> 59.75 | L35: =IF(AC35>0,((K35-AD35)+(AE35-K36)),IF(K36=0, ,(K35-K36))) -> 1.75 | M35: =7000*4 -> 28000 | N35: =L35*M35/100 -> 490 | O35: =N35*0.53 -> 259.7 | P35: =O35*8.3673 -> 2172.9878 | Q35: 2531 | R35: 57 | S35: 85 | T35: 2180 | U35: 62 | V35: 85 | W35: 2356 | X35: 58 | Y35: 85 | Z35: 2505 | AA35: 55 | AB35: 85 | AC35: =Q35+T35+W35+Z35 -> 9572 | AD35: =(R35+U35+X35+AA35)/4 -> 58 | AE35: =(S35+V35+Y35+AB35)/4 -> 85
A36: 43795 | B36: 85 | C36: =IF(AC36>0,((B36-R36)+(S36-B37)),IF(B37=0, ,(B36-B37))) -> 0 | D36: 85 | E36: =IF(AC36>0,((D36-U36)+(V36-D37)),IF(D37=0, ,(D36-D37))) -> 0 | F36: 85 | G36: =IF(AC36>0,((F36-X36)+(Y36-F37)),IF(F37=0, ,(F36-F37))) -> 4 | H36: 85 | I36: =IF(AC36>0,((H36-AA36)+(AB36-H37)),IF(H37=0, ,(H36-H37))) -> 2 | J36: =B36+D36+F36+H36 -> 340 | K36: =J36/4 -> 85 | L36: =IF(AC36>0,((K36-AD36)+(AE36-K37)),IF(K37=0, ,(K36-K37))) -> 1.5 | M36: =7000*4 -> 28000 | N36: =L36*M36/100 -> 420 | O36: =N36*0.53 -> 222.6 | P36: =O36*8.3673 -> 1862.561 | AC36: =Q36+T36+W36+Z36 -> 0 | AD36: =(R36+U36+X36+AA36)/4 -> 0 | AE36: =(S36+V36+Y36+AB36)/4 -> 0
A37: 43796 | B37: 85 | C37: =IF(AC37>0,((B37-R37)+(S37-B38)),IF(B38=0, ,(B37-B38))) -> 5 | D37: 85 | E37: =IF(AC37>0,((D37-U37)+(V37-D38)),IF(D38=0, ,(D37-D38))) -> 5 | F37: 81 | G37: =IF(AC37>0,((F37-X37)+(Y37-F38)),IF(F38=0, ,(F37-F38))) -> 6 | H37: 83 | I37: =IF(AC37>0,((H37-AA37)+(AB37-H38)),IF(H38=0, ,(H37-H38))) -> 7 | J37: =B37+D37+F37+H37 -> 334 | K37: =J37/4 -> 83.5 | L37: =IF(AC37>0,((K37-AD37)+(AE37-K38)),IF(K38=0, ,(K37-K38))) -> 5.75 | M37: =7000*4 -> 28000 | N37: =L37*M37/100 -> 1610 | O37: =N37*0.53 -> 853.3 | P37: =O37*8.3673 -> 7139.8171 | AC37: =Q37+T37+W37+Z37 -> 0 | AD37: =(R37+U37+X37+AA37)/4 -> 0 | AE37: =(S37+V37+Y37+AB37)/4 -> 0
A38: 43797 | B38: 80 | C38: =IF(AC38>0,((B38-R38)+(S38-B39)),IF(B39=0, ,(B38-B39))) -> 8 | D38: 80 | E38: =IF(AC38>0,((D38-U38)+(V38-D39)),IF(D39=0, ,(D38-D39))) -> 5 | F38: 75 | G38: =IF(AC38>0,((F38-X38)+(Y38-F39)),IF(F39=0, ,(F38-F39))) -> 5 | H38: 76 | I38: =IF(AC38>0,((H38-AA38)+(AB38-H39)),IF(H39=0, ,(H38-H39))) -> 5 | J38: =B38+D38+F38+H38 -> 311 | K38: =J38/4 -> 77.75 | L38: =IF(AC38>0,((K38-AD38)+(AE38-K39)),IF(K39=0, ,(K38-K39))) -> 5.75 | M38: =7000*4 -> 28000 | N38: =L38*M38/100 -> 1610 | O38: =N38*0.53 -> 853.3 | P38: =O38*8.3673 -> 7139.8171 | AC38: =Q38+T38+W38+Z38 -> 0 | AD38: =(R38+U38+X38+AA38)/4 -> 0 | AE38: =(S38+V38+Y38+AB38)/4 -> 0
A39: 43798 | B39: 72 | C39: =IF(AC39>0,((B39-R39)+(S39-B40)),IF(B40=0, ,(B39-B40))) -> 3 | D39: 75 | E39: =IF(AC39>0,((D39-U39)+(V39-D40)),IF(D40=0, ,(D39-D40))) -> 5 | F39: 70 | G39: =IF(AC39>0,((F39-X39)+(Y39-F40)),IF(F40=0, ,(F39-F40))) -> 5 | H39: 71 | I39: =IF(AC39>0,((H39-AA39)+(AB39-H40)),IF(H40=0, ,(H39-H40))) -> 4 | J39: =B39+D39+F39+H39 -> 288 | K39: =J39/4 -> 72 | L39: =IF(AC39>0,((K39-AD39)+(AE39-K40)),IF(K40=0, ,(K39-K40))) -> 4.25 | M39: =7000*4 -> 28000 | N39: =L39*M39/100 -> 1190 | O39: =N39*0.53 -> 630.7 | P39: =O39*8.3673 -> 5277.2561 | AC39: =Q39+T39+W39+Z39 -> 0 | AD39: =(R39+U39+X39+AA39)/4 -> 0 | AE39: =(S39+V39+Y39+AB39)/4 -> 0
A40: 43799 | B40: 69 | C40: =IF(AC40>0,((B40-R40)+(S40-B41)),IF(B41=0, ,(B40-B41))) -> 0 | D40: 70 | E40: =IF(AC40>0,((D40-U40)+(V40-D41)),IF(D41=0, ,(D40-D41))) -> 0 | F40: 65 | G40: =IF(AC40>0,((F40-X40)+(Y40-F41)),IF(F41=0, ,(F40-F41))) -> 0 | H40: 67 | I40: =IF(AC40>0,((H40-AA40)+(AB40-H41)),IF(H41=0, ,(H40-H41))) -> 0 | J40: =B40+D40+F40+H40 -> 271 | K40: =J40/4 -> 67.75 | L40: =IF(AC40>0,((K40-AD40)+(AE40-K41)),IF(K41=0, ,(K40-K41))) -> 0 | M40: =7000*4 -> 28000 | N40: =L40*M40/100 -> 0 | O40: =N40*0.53 -> 0 | P40: =O40*8.3673 -> 0 | AC40: =Q40+T40+W40+Z40 -> 0 | AD40: =(R40+U40+X40+AA40)/4 -> 0 | AE40: =(S40+V40+Y40+AB40)/4 -> 0
...

Sheet Suivi EAU-ELEC
C1: Suivi Compteur d'Eau- électricité RADEEMA -
A7: Date | B7: Eau m3 | D7: Electricité Kw/h
B8: Compteur | C8: Consommation | D8: Compteur H.Creuse | E8: Consommation H.Creuse | F8: Compteur H.Pleine | G8: Consommation H.Pleine | H8: Compteur H.Pointe | I8: Consommation H.Pointe
A9: 43763 | B9: 114875 | C9: =IF(B10<B9,0,B10-B9)*10 -> 690 | D9: 17679100 | E9: =IF(D10<D9,0,D10-D9) -> 5571 | F9: 32002464 | G9: =IF(F10<F9,0,F10-F9) -> 7589 | H9: 14131015 | I9: =IF(H10<H9,0,H10-H9) -> 4519
A10: =A9+1 -> 43764 | B10: 114944 | C10: =IF(B11<B10,0,B11-B10)*10 -> 650 | D10: 17684671 | E10: =IF(D11<D10,0,D11-D10) -> 5493 | F10: 32010053 | G10: =IF(F11<F10,0,F11-F10) -> 10538 | H10: 14135534 | I10: =IF(H11<H10,0,H11-H10) -> 4235
A11: =A10+1 -> 43765 | B11: 115009 | C11: =IF(B12<B11,0,B12-B11)*10 -> 640 | D11: 17690164 | E11: =IF(D12<D11,0,D12-D11) -> 5688 | F11: 32020591 | G11: =IF(F12<F11,0,F12-F11) -> 8983 | H11: 14139769 | I11: =IF(H12<H11,0,H12-H11) -> 4422
A12: =A11+1 -> 43766 | B12: 115073 | C12: =IF(B13<B12,0,B13-B12)*10 -> 610 | D12: 17695852 | E12: =IF(D13<D12,0,D13-D12) -> 5785 | F12: 32029574 | G12: =IF(F13<F12,0,F13-F12) -> 9670 | H12: 14144191 | I12: =IF(H13<H12,0,H13-H12) -> 4425
A13: =A12+1 -> 43767 | B13: 115134 | C13: =IF(B14<B13,0,B14-B13)*10 -> 660 | D13: 17701637 | E13: =IF(D14<D13,0,D14-D13) -> 5422 | F13: 32039244 | G13: =IF(F14<F13,0,F14-F13) -> 10019 | H13: 14148616 | I13: =IF(H14<H13,0,H14-H13) -> 4597
A14: =A13+1 -> 43768 | B14: 115200 | C14: =IF(B15<B14,0,B15-B14)*10 -> 580 | D14: 17707059 | E14: =IF(D15<D14,0,D15-D14) -> 6093 | F14: 32049263 | G14: =IF(F15<F14,0,F15-F14) -> 9585 | H14: 14153213 | I14: =IF(H15<H14,0,H15-H14) -> 4305
A15: =A14+1 -> 43769 | B15: 115258 | C15: =IF(B16<B15,0,B16-B15)*10 -> 590 | D15: 17713152 | E15: =IF(D16<D15,0,D16-D15) -> 6238 | F15: 32058848 | G15: =IF(F16<F15,0,F16-F15) -> 9588 | H15: 14157518 | I15: =IF(H16<H15,0,H16-H15) -> 4610
A16: =A15+1 -> 43770 | B16: 115317 | C16: =IF(B17<B16,0,B17-B16)*10 -> 650 | D16: 17719390 | E16: =IF(D17<D16,0,D17-D16) -> 6601 | F16: 32068436 | G16: =IF(F17<F16,0,F17-F16) -> 9635 | H16: 14162128 | I16: =IF(H17<H16,0,H17-H16) -> 4498
A17: =A16+1 -> 43771 | B17: 115382 | C17: =IF(B18<B17,0,B18-B17)*10 -> 490 | D17: 17725991 | E17: =IF(D18<D17,0,D18-D17) -> 6829 | F17: 32078071 | G17: =IF(F18<F17,0,F18-F17) -> 9858 | H17: 14166626 | I17: =IF(H18<H17,0,H18-H17) -> 4914
A18: =A17+1 -> 43772 | B18: 115431 | C18: =IF(B19<B18,0,B19-B18)*10 -> 530 | D18: 17732820 | E18: =IF(D19<D18,0,D19-D18) -> 6220 | F18: 32087929 | G18: =IF(F19<F18,0,F19-F18) -> 8922 | H18: 14171540 | I18: =IF(H19<H18,0,H19-H18) -> 4151
A19: =A18+1 -> 43773 | B19: 115484 | C19: =IF(B20<B19,0,B20-B19)*10 -> 530 | D19: 17739040 | E19: =IF(D20<D19,0,D20-D19) -> 5895 | F19: 32096851 | G19: =IF(F20<F19,0,F20-F19) -> 9460 | H19: 14175691 | I19: =IF(H20<H19,0,H20-H19) -> 4280
A20: =A19+1 -> 43774 | B20: 115537 | C20: =IF(B21<B20,0,B21-B20)*10 -> 820 | D20: 17744935 | E20: =IF(D21<D20,0,D21-D20) -> 5595 | F20: 32106311 | G20: =IF(F21<F20,0,F21-F20) -> 9063 | H20: 14179971 | I20: =IF(H21<H20,0,H21-H20) -> 3763
A21: =A20+1 -> 43775 | B21: 115619 | C21: =IF(B22<B21,0,B22-B21)*10 -> 570 | D21: 17750530 | E21: =IF(D22<D21,0,D22-D21) -> 5443 | F21: 32115374 | G21: =IF(F22<F21,0,F22-F21) -> 8722 | H21: 14183734 | I21: =IF(H22<H21,0,H22-H21) -> 4150
... A45: =A44+1 -> 43799 | B45: 116697 | C45: =IF(B46<B45,0,B46-B45)*10 -> 0 | D45: 17864386 | E45: =IF(D46<D45,0,D46-D45) -> 0 | F45: 32280577 | G45: =IF(F46<F45,0,F46-F45) -> 0 | H45: 14265708 | I45: =IF(H46<H45,0,H46-H45) -> 0
A46: =A45+1 -> 43800 | C46: =IF(B47<B46,0,B47-B46)*10 -> 0 | E46: =IF(D47<D46,0,D47-D46) -> 0 | G46: =IF(F47<F46,0,F47-F46) -> 0 | I46: =IF(H47<H46,0,H47-H46) -> 0
A47: =A46+1 -> 43801 | C47: =IF(B48<B47,0,B48-B47)*10 -> 0 | E47: =IF(D48<D47,0,D48-D47) -> 0 | G47: =IF(F48<F47,0,F48-F47) -> 0 | I47: =IF(H48<H47,0,H48-H47) -> 0
C48: =SUM(C16:C45) -> 13800 | E48: =SUM(E16:E45) -> 144996 | G48: =SUM(G16:G45) -> 212141 | I48: =SUM(I16:I45) -> 103580
G58: =IF(F59<F58,0,F59-F58) -> 0

Sheet Feuil1
