Workbook

Sheet Total
A1: Site Name | B1: Day | C1: Month | D1: Year | E1: Total Electricity Kwh | F1: Electricity Tariff ($/Kwh) | G1: LPG (Kg) | H1: LPG $/Kg | I1: Water Utility Supply (m3) m3 | J1: Water Utility Supply (m3) $/m3 | K1: Room Nights | L1: Utilities day cost dh
A2: Serengeti | B2: 1 | C2: 12 | D2: 2018 | E2: =Gen!T11 -> 4555 | F2: =Gen!S11/Gen!T11 -> 0.40068716 | G2: =IF('Utility summery'!M6<0,"0",'Utility summery'!M6) -> 149.292 | H2: 2.38 | I2: =IF('Water-Meter'!E6<0,"0",'Water-Meter'!E6) -> 99 | J2: 0 | K2: ='Summery Report'!E5 -> 15 | L2: =E2*F2+G2*H2+#REF!*#REF!+I2*J2 -> #REF!
A3: Serengeti | B3: =B2+1 -> 2 | C3: 12 | D3: 2018 | E3: =Gen!T12 -> 4679 | F3: =Gen!S12/Gen!T12 -> 0.39221842 | G3: =IF('Utility summery'!M7<0,"0",'Utility summery'!M7) -> 78.892 | H3: 2.38 | I3: =IF('Water-Meter'!E7<0,"0",'Water-Meter'!E7) -> 100 | J3: 0 | K3: ='Summery Report'!E6 -> 13 | L3: =E3*F3+G3*H3+#REF!*#REF!+I3*J3 -> #REF!
A4: Serengeti | B4: =B3+1 -> 3 | C4: 12 | D4: 2018 | E4: =Gen!T13 -> 4437 | F4: =Gen!S13/Gen!T13 -> 0.62385621 | G4: =IF('Utility summery'!M8<0,"0",'Utility summery'!M8) -> 126.544 | H4: 2.38 | I4: =IF('Water-Meter'!E8<0,"0",'Water-Meter'!E8) -> 90 | J4: 0 | K4: ='Summery Report'!E7 -> 13 | L4: =E4*F4+G4*H4+#REF!*#REF!+I4*J4 -> #REF!
A5: Serengeti | B5: =B4+1 -> 4 | C5: 12 | D5: 2018 | E5: =Gen!T14 -> 4694 | F5: =Gen!S14/Gen!T14 -> 0.4069983 | G5: =IF('Utility summery'!M9<0,"0",'Utility summery'!M9) -> 101.332 | H5: 2.38 | I5: =IF('Water-Meter'!E9<0,"0",'Water-Meter'!E9) -> 87 | J5: 0 | K5: ='Summery Report'!E8 -> 15 | L5: =E5*F5+G5*H5+#REF!*#REF!+I5*J5 -> #REF!
A6: Serengeti | B6: =B5+1 -> 5 | C6: 12 | D6: 2018 | E6: =Gen!T15 -> 4359 | F6: =Gen!S15/Gen!T15 -> 0.40956183 | G6: =IF('Utility summery'!M10<0,"0",'Utility summery'!M10) -> 111.628 | H6: 2.38 | I6: =IF('Water-Meter'!E10<0,"0",'Water-Meter'!E10) -> 84 | J6: 0 | K6: ='Summery Report'!E9 -> 12 | L6: =E6*F6+G6*H6+#REF!*#REF!+I6*J6 -> #REF!
A7: Serengeti | B7: =B6+1 -> 6 | C7: 12 | D7: 2018 | E7: =Gen!T16 -> 4710 | F7: =Gen!S16/Gen!T16 -> 0.40421656 | G7: =IF('Utility summery'!M11<0,"0",'Utility summery'!M11) -> 105.644 | H7: 2.38 | I7: =IF('Water-Meter'!E11<0,"0",'Water-Meter'!E11) -> 108 | J7: 0 | K7: ='Summery Report'!E10 -> 15 | L7: =E7*F7+G7*H7+#REF!*#REF!+I7*J7 -> #REF!
A8: Serengeti | B8: =B7+1 -> 7 | C8: 12 | D8: 2018 | E8: =Gen!T17 -> 4875 | F8: =Gen!S17/Gen!T17 -> 0.41234667 | G8: =IF('Utility summery'!M12<0,"0",'Utility summery'!M12) -> 116.16 | H8: 2.38 | I8: =IF('Water-Meter'!E12<0,"0",'Water-Meter'!E12) -> 93 | J8: 0 | K8: ='Summery Report'!E11 -> 20 | L8: =E8*F8+G8*H8+#REF!*#REF!+I8*J8 -> #REF!
A9: Serengeti | B9: =B8+1 -> 8 | C9: 12 | D9: 2018 | E9: =Gen!T18 -> 4801 | F9: =Gen!S18/Gen!T18 -> 0.40063737 | G9: =IF('Utility summery'!M13<0,"0",'Utility summery'!M13) -> 149.556 | H9: 2.38 | I9: =IF('Water-Meter'!E13<0,"0",'Water-Meter'!E13) -> 103 | J9: 0 | K9: ='Summery Report'!E12 -> 23 | L9: =E9*F9+G9*H9+#REF!*#REF!+I9*J9 -> #REF!
A10: Serengeti | B10: =B9+1 -> 9 | C10: 12 | D10: 2018 | E10: =Gen!T19 -> 4909 | F10: =Gen!S19/Gen!T19 -> 0.41628845 | G10: =IF('Utility summery'!M14<0,"0",'Utility summery'!M14) -> 158.4 | H10: 2.38 | I10: =IF('Water-Meter'!E14<0,"0",'Water-Meter'!E14) -> 125 | J10: 0 | K10: ='Summery Report'!E13 -> 37 | L10: =E10*F10+G10*H10+#REF!*#REF!+I10*J10 -> #REF!
A11: Serengeti | B11: =B10+1 -> 10 | C11: 12 | D11: 2018 | E11: =Gen!T20 -> 5316 | F11: =Gen!S20/Gen!T20 -> 0.39564146 | G11: =IF('Utility summery'!M15<0,"0",'Utility summery'!M15) -> 197.208 | H11: 2.38 | I11: =IF('Water-Meter'!E15<0,"0",'Water-Meter'!E15) -> 114 | J11: 0 | K11: ='Summery Report'!E14 -> 44 | L11: =E11*F11+G11*H11+#REF!*#REF!+I11*J11 -> #REF!
A12: Serengeti | B12: =B11+1 -> 11 | C12: 12 | D12: 2018 | E12: =Gen!T21 -> 4922 | F12: =Gen!S21/Gen!T21 -> 0.41534539 | G12: =IF('Utility summery'!M16<0,"0",'Utility summery'!M16) -> 121.836 | H12: 2.38 | I12: =IF('Water-Meter'!E16<0,"0",'Water-Meter'!E16) -> 114 | J12: 0 | K12: ='Summery Report'!E15 -> 45 | L12: =E12*F12+G12*H12+#REF!*#REF!+I12*J12 -> #REF!
A13: Serengeti | B13: =B12+1 -> 12 | C13: 12 | D13: 2018 | E13: =Gen!T22 -> 4870 | F13: =Gen!S22/Gen!T22 -> 0.39368378 | G13: =IF('Utility summery'!M17<0,"0",'Utility summery'!M17) -> 127.292 | H13: 2.38 | I13: =IF('Water-Meter'!E17<0,"0",'Water-Meter'!E17) -> 105 | J13: 0 | K13: ='Summery Report'!E16 -> 21 | L13: =E13*F13+G13*H13+#REF!*#REF!+I13*J13 -> #REF!
A14: Serengeti | B14: =B13+1 -> 13 | C14: 12 | D14: 2018 | E14: =Gen!T23 -> 4660 | F14: =Gen!S23/Gen!T23 -> 0.40591845 | G14: =IF('Utility summery'!M18<0,"0",'Utility summery'!M18) -> 119.636 | H14: 2.38 | I14: =IF('Water-Meter'!E18<0,"0",'Water-Meter'!E18) -> 111 | J14: 0 | K14: ='Summery Report'!E17 -> 23 | L14: =E14*F14+G14*H14+#REF!*#REF!+I14*J14 -> #REF!
... A31: Serengeti | B31: =B30+1 -> 30 | C31: 12 | D31: 2018 | E31: =Gen!T40 -> 7378 | F31: =Gen!S40/Gen!T40 -> 0.42999593 | G31: =IF('Utility summery'!M35<0,"0",'Utility summery'!M35) -> 106.568 | H31: 2.38 | I31: =IF('Water-Meter'!E35<0,"0",'Water-Meter'!E35) -> 156 | J31: 0 | K31: ='Summery Report'!E34 -> 61 | L31: =E31*F31+G31*H31+#REF!*#REF!+I31*J31 -> #REF!
A32: Serengeti | B32: =B31+1 -> 31 | C32: 12 | D32: 2018 | E32: =Gen!T41 -> 7255 | F32: =Gen!S41/Gen!T41 -> 0.42160717 | G32: =IF('Utility summery'!M36<0,"0",'Utility summery'!M36) -> 122.54 | H32: 2.38 | I32: =IF('Water-Meter'!E36<0,"0",'Water-Meter'!E36) -> 120 | J32: 0 | K32: ='Summery Report'!E35 -> 66

Sheet Utility summery
A4: Date | B4: Room Occupied | C4: Electricity Units Generated KW | D4: Diseal | G4: Water | J4: Gas | N4: Cost of utilites
D5: Generator | E5: Transport | F5: Total | G5: RO | H5: STP | I5: Total Consumption | J5: 2 ton | K5: 1 Ton | L5: 1 Ton | M5: Total consumption | N5: Electricity /1.4$/liter | O5: Diseal for Transport | P5: Gas /2.38$/Kg | Q5: Total HLP Cost | R5: Electricity Cost/Room $ | S5: cost/Room $
A6: =Gen!A11 -> 43435 | B6: ='Summery Report'!D5 -> 15 | C6: ='Daily report Gen'!AA6 -> 430 | D6: =Gen!S11 -> 1825.13 | E6: =Gen!AJ11 -> 42.79 | F6: =Gen!AR11 -> 1867.92 | G6: ='Utility report'!AA5 -> 0 | H6: ='Utility report'!AF6 -> 65 | I6: ='Utility report'!AE6 -> 0.65656566 | J6: ='Lpg (2)'!B10 -> 85 | K6: ='Lpg (2)'!C12 -> 85 | L6: ='Lpg (2)'!D10 -> 75 | M6: ='Lpg (2)'!N10 -> 149.292 | O6: =E6 -> 42.79 | P6: ='Lpg (2)'!G10 -> 150000 | Q6: ='Summery Report'!Q5 -> 54169.68 | R6: =N6/B6 -> 0 | S6: =Q6/B6 -> 3611.312
A7: =Gen!A12 -> 43436 | B7: ='Summery Report'!D6 -> 13 | C7: ='Daily report Gen'!AA7 -> 410 | D7: =Gen!S12 -> 1835.19 | E7: =Gen!AJ12 -> 90.6 | F7: =SUM(D7+E7) -> 1925.79 | G7: ='Utility report'!AA6 -> #VALUE! | H7: ='Utility report'!AF7 -> 45 | I7: ='Utility report'!AE7 -> 0.45 | J7: ='Lpg (2)'!B11 -> 85 | K7: ='Lpg (2)'!C11 -> 85 | L7: ='Lpg (2)'!D11 -> 61 | M7: ='Lpg (2)'!N11 -> 78.892 | N7: =D7*1.4 -> 2569.266 | O7: =E7*1.4 -> 126.84 | P7: ='Lpg (2)'!G11 -> 122000 | Q7: ='Summery Report'!Q6 -> 55847.91 | R7: =N7/B7 -> 197.63585 | S7: =Q7/B7 -> 4295.9931
A8: =Gen!A13 -> 43437 | B8: ='Summery Report'!D7 -> 13 | C8: ='Daily report Gen'!AA8 -> 421 | D8: =Gen!S13 -> 2768.05 | E8: =Gen!AJ13 -> 108.37 | F8: =SUM(D8+E8) -> 2876.42 | G8: ='Utility report'!AA7 -> 956010 | H8: ='Utility report'!AF8 -> 47 | I8: ='Utility report'!AE8 -> 0.52222222 | J8: ='Lpg (2)'!B12 -> 85 | K8: ='Lpg (2)'!C12 -> 85 | L8: ='Lpg (2)'!D12 -> 52 | M8: ='Lpg (2)'!N12 -> 126.544 | N8: =D8*1.4 -> 3875.27 | O8: =E8*1.4 -> 151.718 | P8: ='Lpg (2)'!G12 -> 104000 | Q8: ='Summery Report'!Q7 -> 83416.18 | R8: =N8/B8 -> 298.09769 | S8: =Q8/B8 -> 6416.6292
A9: =Gen!A14 -> 43438 | B9: ='Summery Report'!D8 -> 15 | C9: ='Daily report Gen'!AA9 -> 417 | D9: =Gen!S14 -> 1910.45 | E9: =Gen!AJ14 -> 110.05 | F9: =SUM(D9+E9) -> 2020.5 | G9: ='Utility report'!AA8 -> 1040878.8 | H9: ='Utility report'!AF9 -> 73 | I9: ='Utility report'!AE9 -> 0.83908046 | J9: ='Lpg (2)'!B13 -> 85 | K9: ='Lpg (2)'!C13 -> 85 | L9: ='Lpg (2)'!D13 -> 45 | M9: ='Lpg (2)'!N13 -> 101.332 | N9: =D9*1.4 -> 2674.63 | O9: =E9*1.4 -> 154.07 | P9: ='Lpg (2)'!G13 -> 90000 | Q9: ='Summery Report'!Q8 -> 58594.5 | R9: =N9/B9 -> 178.30867 | S9: =Q9/B9 -> 3906.3
A10: =Gen!A15 -> 43439 | B10: ='Summery Report'!D9 -> 12 | C10: ='Daily report Gen'!AA10 -> 369 | D10: =Gen!S15 -> 1785.28 | E10: =Gen!AJ15 -> 0 | F10: =SUM(D10+E10) -> 1785.28 | G10: ='Utility report'!AA9 -> 1042314 | H10: ='Utility report'!AF10 -> 53 | I10: ='Utility report'!AE10 -> 0.63095238 | J10: ='Lpg (2)'!B14 -> 85 | K10: ='Lpg (2)'!C14 -> 85 | L10: ='Lpg (2)'!D14 -> 40 | M10: ='Lpg (2)'!N14 -> 111.628 | N10: =D10*1.4 -> 2499.392 | O10: =E10*1.4 -> 0 | P10: ='Lpg (2)'!G14 -> 80000 | Q10: ='Summery Report'!Q9 -> 51773.12 | R10: =N10/B10 -> 208.28267 | S10: =Q10/B10 -> 4314.4267
A11: =Gen!A16 -> 43440 | B11: ='Summery Report'!D10 -> 15 | C11: ='Daily report Gen'!AA11 -> 416 | D11: =Gen!S16 -> 1903.86 | E11: =Gen!AJ16 -> 247.65 | F11: =SUM(D11+E11) -> 2151.51 | G11: ='Utility report'!AA10 -> 1087819.2 | H11: ='Utility report'!AF11 -> 57 | I11: ='Utility report'!AE11 -> 0.52777778 | J11: ='Lpg (2)'!B15 -> 85 | K11: ='Lpg (2)'!C15 -> 85 | L11: ='Lpg (2)'!D15 -> 36 | M11: ='Lpg (2)'!N15 -> 105.644 | N11: =D11*1.4 -> 2665.404 | O11: =E11*1.4 -> 346.71 | P11: ='Lpg (2)'!G15 -> 72000 | Q11: ='Summery Report'!Q10 -> 62393.79 | R11: =N11/B11 -> 177.6936 | S11: =Q11/B11 -> 4159.586
A12: =Gen!A17 -> 43441 | B12: ='Summery Report'!D11 -> 20 | C12: ='Daily report Gen'!AA12 -> 389 | D12: =Gen!S17 -> 2010.19 | E12: =Gen!AJ17 -> 224.17 | F12: =SUM(D12+E12) -> 2234.36 | G12: ='Utility report'!AA11 -> 1089379.2 | H12: ='Utility report'!AF12 -> 53 | I12: ='Utility report'!AE12 -> 0.56989247 | J12: ='Lpg (2)'!B16 -> 85 | K12: ='Lpg (2)'!C16 -> 85 | L12: ='Lpg (2)'!D16 -> 30 | M12: ='Lpg (2)'!N16 -> 116.16 | N12: =D12*1.4 -> 2814.266 | O12: =E12*1.4 -> 313.838 | P12: ='Lpg (2)'!G16 -> 60000 | Q12: ='Summery Report'!Q11 -> 64796.44 | R12: =N12/B12 -> 140.7133 | S12: =Q12/B12 -> 3239.822
A13: =Gen!A18 -> 43442 | B13: ='Summery Report'!D12 -> 23 | C13: ='Daily report Gen'!AA13 -> 410 | D13: =Gen!S18 -> 1923.46 | E13: =Gen!AJ18 -> 114 | F13: =SUM(D13+E13) -> 2037.46 | G13: ='Utility report'!AA12 -> 136258.2 | H13: ='Utility report'!AF13 -> 53 | I13: ='Utility report'!AE13 -> 0.51456311 | J13: ='Lpg (2)'!B17 -> 85 | K13: ='Lpg (2)'!C17 -> 85 | L13: ='Lpg (2)'!D17 -> 23 | M13: ='Lpg (2)'!N17 -> 149.556 | N13: =D13*1.4 -> 2692.844 | O13: =E13*1.4 -> 159.6 | P13: ='Lpg (2)'!G17 -> 46000 | Q13: ='Summery Report'!Q12 -> 59086.34 | R13: =N13/B13 -> 117.08017 | S13: =Q13/B13 -> 2568.9713
A14: =Gen!A19 -> 43443 | B14: ='Summery Report'!D13 -> 37 | C14: ='Daily report Gen'!AA14 -> 426 | D14: =Gen!S19 -> 2043.56 | E14: =Gen!AJ19 -> 534.56 | F14: =SUM(D14+E14) -> 2578.12 | G14: ='Utility report'!AA13 -> 1138540 | H14: ='Utility report'!AF14 -> 59 | I14: ='Utility report'!AE14 -> 0.472 | J14: ='Lpg (2)'!B18 -> 85 | K14: ='Lpg (2)'!C18 -> 85 | L14: ='Lpg (2)'!D18 -> 16 | M14: ='Lpg (2)'!N18 -> 158.4 | N14: =D14*1.4 -> 2860.984 | O14: =E14*1.4 -> 748.384 | P14: ='Lpg (2)'!G18 -> 32000 | Q14: ='Summery Report'!Q13 -> 74765.48 | R14: =N14/B14 -> 77.323892 | S14: =Q14/B14 -> 2020.6886
A15: =Gen!A20 -> 43444 | B15: ='Summery Report'!D14 -> 44 | C15: ='Daily report Gen'!AA15 -> 420 | D15: =Gen!S20 -> 2103.23 | E15: =Gen!AJ20 -> 438 | F15: =SUM(D15+E15) -> 2541.23 | G15: ='Utility report'!AA14 -> 482377.5 | H15: ='Utility report'!AF15 -> 120 | I15: ='Utility report'!AE15 -> 1.0526316 | J15: ='Lpg (2)'!B19 -> 85 | K15: ='Lpg (2)'!C19 -> 85 | L15: ='Lpg (2)'!D19 -> 9 | M15: ='Lpg (2)'!N19 -> 197.208 | N15: =D15*1.4 -> 2944.522 | O15: =E15*1.4 -> 613.2 | P15: ='Lpg (2)'!G19 -> 18000 | Q15: ='Summery Report'!Q14 -> 73695.67 | R15: =N15/B15 -> 66.920955 | S15: =Q15/B15 -> 1674.9016
A16: =Gen!A21 -> 43445 | B16: ='Summery Report'!D15 -> 45 | C16: ='Daily report Gen'!AA16 -> 425 | D16: =Gen!S21 -> 2044.33 | E16: =Gen!AJ21 -> 222.33 | F16: =SUM(D16+E16) -> 2266.66 | G16: ='Utility report'!AA15 -> 1981444.8 | H16: ='Utility report'!AF16 -> 59 | I16: ='Utility report'!AE16 -> 0.51754386 | J16: ='Lpg (2)'!B20 -> 85 | K16: ='Lpg (2)'!C20 -> 85 | L16: ='Lpg (2)'!D20 -> 2 | M16: ='Lpg (2)'!N20 -> 121.836 | N16: =D16*1.4 -> 2862.062 | O16: =E16*1.4 -> 311.262 | P16: ='Lpg (2)'!G20 -> 4000 | Q16: ='Summery Report'!Q15 -> 65733.14 | R16: =N16/B16 -> 63.601378 | S16: =Q16/B16 -> 1460.7364
A17: =Gen!A22 -> 43446 | B17: ='Summery Report'!D16 -> 21 | C17: ='Daily report Gen'!AA17 -> 420 | D17: =Gen!S22 -> 1917.24 | E17: =Gen!AJ22 -> 198.24 | F17: =SUM(D17+E17) -> 2115.48 | G17: ='Utility report'!AA16 -> 1054380 | H17: ='Utility report'!AF17 -> 74 | I17: ='Utility report'!AE17 -> 0.7047619 | J17: ='Lpg (2)'!B21 -> 85 | K17: ='Lpg (2)'!C21 -> 78 | L17: ='Lpg (2)'!D21 -> 0 | M17: ='Lpg (2)'!N21 -> 127.292 | N17: =D17*1.4 -> 2684.136 | O17: =E17*1.4 -> 277.536 | P17: ='Lpg (2)'!G21 -> 0 | Q17: ='Summery Report'!Q16 -> 61348.92 | R17: =N17/B17 -> 127.816 | S17: =Q17/B17 -> 2921.3771
A18: =Gen!A23 -> 43447 | B18: ='Summery Report'!D17 -> 23 | C18: ='Daily report Gen'!AA18 -> 435 | D18: =Gen!S23 -> 1891.58 | E18: =Gen!AJ23 -> 114.1 | F18: =SUM(D18+E18) -> 2005.68 | G18: ='Utility report'!AA17 -> 1055160 | H18: ='Utility report'!AF18 -> 74 | I18: ='Utility report'!AE18 -> 0.66666667 | J18: ='Lpg (2)'!B22 -> 85 | K18: ='Lpg (2)'!C22 -> 66 | L18: ='Lpg (2)'!D22 -> 0 | M18: ='Lpg (2)'!N22 -> 119.636 | N18: =D18*1.4 -> 2648.212 | O18: =E18*1.4 -> 159.74 | P18: ='Lpg (2)'!G22 -> 0 | Q18: ='Summery Report'!Q17 -> 58164.72 | R18: =N18/B18 -> 115.13965 | S18: =Q18/B18 -> 2528.9009
... A32: =Gen!A37 -> 43461 | B32: ='Summery Report'!D31 -> 60 | C32: ='Daily report Gen'!AA32 -> 575 | D32: =Gen!S37 -> 2635.34 | E32: =Gen!AJ37 -> 203.69 | F32: =SUM(D32+E32) -> 2839.03 | G32: ='Utility report'!AA31 -> 0 | H32: ='Utility report'!AF32 -> 74 | I32: ='Utility report'!AE32 -> 0.46540881 | J32: ='Lpg (2)'!B36 -> 83 | K32: ='Lpg (2)'!C36 -> 0 | L32: ='Lpg (2)'!D36 -> 0 | M32: ='Lpg (2)'!N36 -> 108.46 | N32: =D32*1.4 -> 3689.476 | O32: =E32*1.4 -> 285.166 | P32: ='Lpg (2)'!G36 -> 0 | Q32: ='Summery Report'!Q31 -> 82331.87 | R32: =N32/B32 -> 61.491267 | S32: =Q32/B32 -> 1372.1978
A33: =Gen!A38 -> 43462 | B33: ='Summery Report'!D32 -> 62 | C33: ='Daily report Gen'!AA33 -> 630 | D33: =Gen!S38 -> 3043.34 | E33: =Gen!AJ38 -> 321.45 | F33: =SUM(D33+E33) -> 3364.79 | G33: ='Utility report'!AA32 -> 0 | H33: ='Utility report'!AF33 -> 72 | I33: ='Utility report'!AE33 -> 0.43902439 | J33: ='Lpg (2)'!B37 -> 80 | K33: ='Lpg (2)'!C37 -> 0 | L33: ='Lpg (2)'!D37 -> 0 | M33: ='Lpg (2)'!N37 -> 123.024 | N33: =D33*1.4 -> 4260.676 | O33: =E33*1.4 -> 450.03 | P33: ='Lpg (2)'!G37 -> 0 | Q33: ='Summery Report'!Q32 -> 97578.91 | R33: =N33/B33 -> 68.720581 | S33: =Q33/B33 -> 1573.8534 | T33: =3124/13 -> 240.30769
A34: =Gen!A39 -> 43463 | B34: ='Summery Report'!D33 -> 73 | C34: ='Daily report Gen'!AA34 -> 640 | D34: =Gen!S39 -> 2871.98 | E34: =Gen!AJ39 -> 247.04 | F34: =SUM(D34+E34) -> 3119.02 | G34: ='Utility report'!AA33 -> 206352.4 | H34: ='Utility report'!AF34 -> 70 | I34: ='Utility report'!AE34 -> 0.40462428 | J34: ='Lpg (2)'!B38 -> 79 | K34: ='Lpg (2)'!C38 -> 0 | L34: ='Lpg (2)'!D38 -> 0 | M34: ='Lpg (2)'!N38 -> 111.056 | N34: =D34*1.4 -> 4020.772 | O34: =E34*1.4 -> 345.856 | P34: ='Lpg (2)'!G38 -> 0 | Q34: ='Summery Report'!Q33 -> 90451.58 | R34: =N34/B34 -> 55.079068 | S34: =Q34/B34 -> 1239.0627
A35: =Gen!A40 -> 43464 | B35: ='Summery Report'!D34 -> 61 | C35: ='Daily report Gen'!AA35 -> 596 | D35: =Gen!S40 -> 3172.51 | E35: =Gen!AJ40 -> 120.12 | F35: =SUM(D35+E35) -> 3292.63 | G35: ='Utility report'!AA34 -> 0 | H35: ='Utility report'!AF35 -> 71 | I35: ='Utility report'!AE35 -> 0.45512821 | J35: ='Lpg (2)'!B39 -> 76 | K35: ='Lpg (2)'!C39 -> 0 | L35: ='Lpg (2)'!D39 -> 0 | M35: ='Lpg (2)'!N39 -> 106.568 | N35: =D35*1.4 -> 4441.514 | O35: =E35*1.4 -> 168.168 | P35: ='Lpg (2)'!G39 -> 0 | Q35: ='Summery Report'!Q34 -> 95486.27 | R35: =N35/B35 -> 72.811705 | S35: =Q35/B35 -> 1565.3487
A36: =Gen!A41 -> 43465 | B36: ='Summery Report'!D35 -> 66 | C36: ='Daily report Gen'!AA36 -> 568 | D36: =Gen!S41 -> 3058.76 | E36: =Gen!AJ41 -> 1284.14 | F36: =SUM(D36+E36) -> 4342.9 | G36: ='Utility report'!AA35 -> 0 | H36: ='Utility report'!AF36 -> -180052 | I36: ='Utility report'!AE36 -> -1500.4333 | J36: ='Lpg (2)'!B40 -> 72 | K36: ='Lpg (2)'!B39 -> 76 | L36: ='Lpg (2)'!C39 -> 0 | M36: ='Lpg (2)'!N40 -> 122.54 | N36: =D36*1.4 -> 4282.264 | O36: =E36*1.4 -> 1797.796 | P36: ='Lpg (2)'!G40 -> 0 | Q36: ='Summery Report'!Q35 -> 125944.1 | R36: =N36/B36 -> 64.882788 | S36: =Q36/B36 -> 1908.2439
A37: =Gen!A42 -> 0 | B37: ='Summery Report'!D36 -> 55 | E37: ='Utility report'!K34 -> 247.04 | Q37: ='Summery Report'!Q36 -> 0 | S37: =Q37/B37 -> 0
A39: Total | B39: =SUM(B7:B37) -> 1145 | C39: =SUM(C7:C35) -> 13091 | D39: =SUM(D7:D35) -> 66337.33 | E39: =SUM(E7:E35) -> 8369.87 | F39: =SUM(F7:F35) -> 74707.2 | G39: =SUM(G7:G35) -> #VALUE! | H39: =SUM(H7:H35) -> 1898 | I39: =SUM(I7:I35) -> 16.205169 | J39: =SUM(J7:J35) -> 2443 | ... S39: =SUM(S7:S35) -> 78969.616

Sheet Utility report
A1: DAILY UTILITY REPORT OCTOBER 2018
A2: Date | B2: Total occupancy | H2: Diesel balance LTS | I2: Diesel Deliveries | J2: Gen.Diesel consumption LTS | L2: Total Diesel consumption LTS | M2: Water Meter reading | N2: Water consumption m³ | O2: R.O WATER PRODUCTION LTRS + TIME | AA2: Total RO production | AB2: RO Meter reading | AD2: 0 | AE2: STP water production | AG2: GAS TANK A | AH2: GAS TANK B | AI2: GAS TANK C | AJ2: Total Gas Tanks | AK2: Kg /day | AL2: TOTAL GAS cons.
A3: Rate Tsh /$ | B3: 1640 | C3: Diesel cost / lits | D3: 2175 | F3: =SUM(D3/B3) -> 1.3262195 | H3: =SUM(Gen!C9) -> #REF! | K3: Transport consumption | M3: Balance | O3: PLANT NO 1 | S3: PLANT NO 2 | W3: PLANT NO 3 | AA3: /day | AB3: Balance | AC3: Production | AD3: 0 | AE3: % / W cons | AF3: Production | AG3: Capacity | AH3: Capacity | AI3: Capacity | AJ3: Kg | AK3: /day | AL3: /day
B4: Rooms OCC | C4: % | D4: Guest Rooms Occ | F4: Electricity Production Cost /Room Occ by guest | G4: All Cost /Room Occ by guest | O4: Flow M3 | P4: Reading Hours Meter | Q4: Hrs | R4: total production M3 | S4: Flow M3 | T4: Reading Hours Meter | U4: Hrs | V4: total production M3 | W4: Flow M3 | Y4: Hrs | Z4: total production M3 | AA4: M3 | AC4: M3 | AE4: % | AF4: M3 | AG4: 2000 | AH4: 1000 | AI4: 1000 | AJ4: =SUM([1]Sheet1!$AA$36) -> 950 | AK4: Kg | AL4: M3
M5: ='Water-Meter'!D5 -> 173149 | P5: 16896 | T5: 15027 | X5: 17291 | AB5: 96419 | AD5: 178089 | AG5: 0.85 | AH5: 0.85 | AI5: 0.17
A6: =Gen!A11 -> 43435 | B6: ='Summery Report'!E5 -> 15 | C6: =SUM(Gen!B11) -> 0.168 | D6: ='Summery Report'!E5 -> 15 | E6: =SUM(F3) -> 1.3262195 | F6: =SUM(J6*E6)/D6 -> 161.3682 | G6: =SUM(L6*E6)/D6 -> 165.15146 | H6: =SUM(Gen!C11) -> #REF! | I6: =SUM(Gen!D11) -> 0 | J6: =SUM(Gen!S11) -> 1825.13 | K6: =Gen!AJ11 -> 42.79 | L6: =SUM(J6:K6) -> 1867.92 | M6: ='Water-Meter'!D6 -> 173248 | N6: ='Water-Meter'!E6 -> 99 | O6: 2.3 | P6: 16896 | Q6: =SUM(P6-P5) -> 0 | R6: =SUM(Q6*O6) -> 0 | T6: 15027 | U6: =T6-T5 -> 0 | V6: - | W6: 2.7 | X6: 17311 | Y6: =X6-X5 -> 20 | Z6: - | AA6: =SUM(Z6*X8) -> #VALUE! | AB6: 96494 | AC6: =AB6-AB5 -> 75 | AD6: 178154 | AE6: =SUM(AF6/N6) -> 0.65656566 | AF6: =AD6-AD5 -> 65 | AG6: ='Lpg (2)'!B9*2000/85 -> 0 | AH6: ='Lpg (2)'!C9*1000/85 -> 0 | AI6: ='Lpg (2)'!D9*1000/85 -> 0 | AJ6: =SUM(AG6*2000)+(AH6*1000)+(AI6*1000) -> 0 | AK6: =SUM(AJ5-AJ6) -> 0
A7: =Gen!A12 -> 43436 | B7: =SUM(77*C7) -> 11.0033 | C7: =SUM(Gen!B12) -> 0.1429 | D7: =SUM('Summery Report'!E6) -> 13 | E7: =SUM(E6) -> 1.3262195 | F7: =SUM(J7*E7)/D7 -> 187.22037 | G7: =SUM(L7*E7)/D7 -> 196.4631 | H7: =SUM(Gen!C12) -> #REF! | I7: =SUM(Gen!D12) -> 0 | J7: =SUM(Gen!S12) -> 1835.19 | K7: =Gen!AJ12 -> 90.6 | L7: =SUM(J7:K7) -> 1925.79 | M7: ='Water-Meter'!D7 -> 173348 | N7: ='Water-Meter'!E7 -> 100 | O7: 2.3 | P7: 16941 | Q7: =SUM(P7-P6) -> 45 | R7: =SUM(Q7*O7) -> 103.5 | T7: 15027 | U7: =T7-T6 -> 0 | V7: =SUM(U7*S7) -> 0 | W7: 2.2 | X7: 17336 | Y7: =X7-X6 -> 25 | Z7: =SUM(Y7*W7) -> 55 | AA7: =SUM(Z7*X9) -> 956010 | AB7: 96591 | AC7: =SUM(AB7-AB6) -> 97 | AD7: 178199 | AE7: =SUM(AF7/N7) -> 0.45 | AF7: =AD7-AD6 -> 45 | AG7: ='Lpg (2)'!B10*2000/85 -> 2000 | AH7: ='Lpg (2)'!C10*1000/85 -> 1000 | AI7: ='Lpg (2)'!D10*1000/85 -> 882.35294 | AJ7: =SUM(AG6*2000)+(AH7*1000)+(AI7*1000) -> 1882352.9 | AK7: =SUM(AJ6-AJ7) -> -1882352.9
A8: =Gen!A13 -> 43437 | B8: =SUM(77*C8) -> 11.0033 | C8: =SUM(Gen!B13) -> 0.1429 | D8: =SUM('Summery Report'!E7) -> 13 | E8: =SUM(E7) -> 1.3262195 | F8: =SUM(J8*E8)/D8 -> 282.38784 | G8: =SUM(L8*E8)/D8 -> 293.44341 | H8: =SUM(Gen!C13) -> #REF! | I8: =SUM(Gen!D13) -> 0 | J8: =SUM(Gen!S13) -> 2768.05 | K8: =Gen!AJ13 -> 108.37 | L8: =SUM(J8:K8) -> 2876.42 | M8: ='Water-Meter'!D8 -> 173438 | N8: ='Water-Meter'!E8 -> 90 | O8: 1.2 | P8: 16965 | Q8: =SUM(P8-P7) -> 24 | R8: =SUM(Q8*O8) -> 28.8 | T8: 15027 | U8: =T8-T7 -> 0 | V8: =SUM(U8*S8) -> 0 | W8: 2.6 | X8: 17359 | Y8: =X8-X7 -> 23 | Z8: =SUM(Y8*W8) -> 59.8 | AA8: =SUM(Z8*X10) -> 1040878.8 | AB8: 96668 | AC8: =SUM(AB8-AB7) -> 77 | AD8: 178246 | AE8: =SUM(AF8/N8) -> 0.52222222 | AF8: =AD8-AD7 -> 47 | AG8: ='Lpg (2)'!B11*2000/85 -> 2000 | AH8: ='Lpg (2)'!C11*1000/85 -> 1000 | AI8: ='Lpg (2)'!D11*1000/85 -> 717.64706 | AJ8: =SUM(AG7*2000)+(AH8*1000)+(AI8*1000) -> 5717647.1 | AK8: =SUM(AJ7-AJ8) -> -3835294.1
A9: =Gen!A14 -> 43438 | B9: =SUM(77*C9) -> 12.9976 | C9: =SUM(Gen!B14) -> 0.1688 | D9: =SUM('Summery Report'!E8) -> 15 | E9: =SUM(E8) -> 1.3262195 | F9: =SUM(J9*E9)/D9 -> 168.91174 | G9: =SUM(L9*E9)/D9 -> 178.64177 | H9: =SUM(Gen!C14) -> #REF! | I9: =SUM(Gen!D14) -> 17000 | J9: =SUM(Gen!S14) -> 1910.45 | K9: =Gen!AJ14 -> 110.05 | L9: =SUM(J9:K9) -> 2020.5 | M9: ='Water-Meter'!D9 -> 173525 | N9: ='Water-Meter'!E9 -> 87 | O9: 1.2 | P9: 16988 | Q9: =SUM(P9-P8) -> 23 | R9: =SUM(Q9*O9) -> 27.6 | T9: 15027 | U9: =T9-T8 -> 0 | V9: =SUM(U9*S9) -> 0 | W9: 2.6 | X9: 17382 | Y9: =X9-X8 -> 23 | Z9: =SUM(Y9*W9) -> 59.8 | AA9: =SUM(Z9*X11) -> 1042314 | AB9: 96751 | AC9: =SUM(AB9-AB8) -> 83 | AD9: 178319 | AE9: =SUM(AF9/N9) -> 0.83908046 | AF9: =AD9-AD8 -> 73 | AG9: ='Lpg (2)'!B12*2000/85 -> 2000 | AH9: ='Lpg (2)'!C12*1000/85 -> 1000 | AI9: ='Lpg (2)'!D12*1000/85 -> 611.76471 | AJ9: =SUM(AG8*2000)+(AH9*1000)+(AI9*1000) -> 5611764.7 | AK9: =SUM(AJ8-AJ9) -> 105882.35
A10: =Gen!A15 -> 43439 | B10: =SUM(77*C10) -> 16.0006 | C10: =SUM(Gen!B15) -> 0.2078 | D10: =SUM('Summery Report'!E9) -> 12 | E10: =SUM(E9) -> 1.3262195 | F10: =SUM(J10*E10)/D10 -> 197.3061 | G10: =SUM(L10*E10)/D10 -> 197.3061 | H10: =SUM(Gen!C15) -> #REF! | I10: =SUM(Gen!D15) -> 0 | J10: =SUM(Gen!S15) -> 1785.28 | K10: =Gen!AJ15 -> 0 | L10: =SUM(J10:K10) -> 1785.28 | M10: ='Water-Meter'!D10 -> 173609 | N10: ='Water-Meter'!E10 -> 84 | O10: 1.2 | P10: 16994 | Q10: =SUM(P10-P9) -> 6 | R10: =SUM(Q10*O10) -> 7.2 | T10: 15027 | U10: =T10-T9 -> 0 | V10: =SUM(U10*S10) -> 0 | W10: 2.6 | X10: 17406 | Y10: =X10-X9 -> 24 | Z10: =SUM(Y10*W10) -> 62.4 | AA10: =SUM(Z10*X12) -> 1087819.2 | AB10: 96816 | AC10: =SUM(AB10-AB9) -> 65 | AD10: 178372 | AE10: =SUM(AF10/N10) -> 0.63095238 | AF10: =AD10-AD9 -> 53 | AG10: ='Lpg (2)'!B13*2000/85 -> 2000 | AH10: ='Lpg (2)'!C13*1000/85 -> 1000 | AI10: ='Lpg (2)'!D13*1000/85 -> 529.41176 | AJ10: =SUM(AG9*2000)+(AH10*1000)+(AI10*1000) -> 5529411.8 | AK10: =SUM(AJ9-AJ10) -> 82352.941
A11: =Gen!A16 -> 43440 | B11: =SUM(77*C11) -> 22.9999 | C11: =SUM(Gen!B16) -> 0.2987 | D11: =SUM('Summery Report'!E10) -> 15 | E11: =SUM(E10) -> 1.3262195 | F11: =SUM(J11*E11)/D11 -> 168.32909 | G11: =SUM(L11*E11)/D11 -> 190.22497 | H11: =SUM(Gen!C16) -> #REF! | I11: =SUM(Gen!D16) -> 0 | J11: =SUM(Gen!S16) -> 1903.86 | K11: =Gen!AJ16 -> 247.65 | L11: =SUM(J11:K11) -> 2151.51 | M11: ='Water-Meter'!D11 -> 173717 | N11: ='Water-Meter'!E11 -> 108 | O11: 1.2 | P11: 17009 | Q11: =SUM(P11-P10) -> 15 | R11: =SUM(Q11*O11) -> 18 | T11: 15027 | U11: =T11-T10 -> 0 | V11: =SUM(U11*S11) -> 0 | W11: 2.6 | X11: 17430 | Y11: =X11-X10 -> 24 | Z11: =SUM(Y11*W11) -> 62.4 | AA11: =SUM(Z11*X13) -> 1089379.2 | AB11: 96861 | AC11: =SUM(AB11-AB10) -> 45 | AD11: 178429 | AE11: =SUM(AF11/N11) -> 0.52777778 | AF11: =AD11-AD10 -> 57 | AG11: ='Lpg (2)'!B14*2000/85 -> 2000 | AH11: ='Lpg (2)'!C14*1000/85 -> 1000 | AI11: ='Lpg (2)'!D14*1000/85 -> 470.58824 | AJ11: =SUM(AG10*2000)+(AH11*1000)+(AI11*1000) -> 5470588.2 | AK11: =SUM(AJ10-AJ11) -> 58823.529
A12: =Gen!A17 -> 43441 | B12: =SUM(77*C12) -> 19.0036 | C12: =SUM(Gen!B17) -> 0.2468 | D12: =SUM('Summery Report'!E11) -> 20 | E12: =SUM(E11) -> 1.3262195 | F12: =SUM(J12*E12)/D12 -> 133.29766 | G12: =SUM(L12*E12)/D12 -> 148.16259 | H12: =SUM(Gen!C17) -> #REF! | I12: =SUM(Gen!D17) -> 0 | J12: =SUM(Gen!S17) -> 2010.19 | K12: =Gen!AJ17 -> 224.17 | L12: =SUM(J12:K12) -> 2234.36 | M12: ='Water-Meter'!D12 -> 173810 | N12: ='Water-Meter'!E12 -> 93 | P12: 17033 | Q12: =SUM(P12-P11) -> 24 | R12: =SUM(Q12*O12) -> 0 | T12: 15027 | U12: =T12-T11 -> 0 | V12: =SUM(U12*S12) -> 0 | W12: 2.6 | X12: 17433 | Y12: =X12-X11 -> 3 | Z12: =SUM(Y12*W12) -> 7.8 | AA12: =SUM(Z12*X14) -> 136258.2 | AB12: 96973 | AC12: =SUM(AB12-AB11) -> 112 | AD12: 178482 | AE12: =SUM(AF12/N12) -> 0.56989247 | AF12: =AD12-AD11 -> 53 | AG12: ='Lpg (2)'!B15*2000/85 -> 2000 | AH12: ='Lpg (2)'!C15*1000/85 -> 1000 | AI12: ='Lpg (2)'!D15*1000/85 -> 423.52941 | AJ12: =SUM(AG11*2000)+(AH12*1000)+(AI12*1000) -> 5423529.4 | AK12: =SUM(AJ11-AJ12) -> 47058.824
A13: =Gen!A18 -> 43442 | B13: =SUM(77*C13) -> 21.9989 | C13: =SUM(Gen!B18) -> 0.2857 | D13: =SUM('Summery Report'!E12) -> 23 | E13: =SUM(E12) -> 1.3262195 | F13: =SUM(J13*E13)/D13 -> 110.91001 | G13: =SUM(L13*E13)/D13 -> 117.48344 | H13: =SUM(Gen!C18) -> #REF! | I13: =SUM(Gen!D18) -> 0 | J13: =SUM(Gen!S18) -> 1923.46 | K13: =Gen!AJ18 -> 114 | L13: =SUM(J13:K13) -> 2037.46 | M13: ='Water-Meter'!D13 -> 173913 | N13: ='Water-Meter'!E13 -> 103 | P13: 17038 | Q13: =SUM(P13-P12) -> 5 | R13: =SUM(Q13*O13) -> 0 | T13: 15027 | U13: =T13-T12 -> 0 | V13: =SUM(U13*S13) -> 0 | W13: 2.6 | X13: 17458 | Y13: =X13-X12 -> 25 | Z13: =SUM(Y13*W13) -> 65 | AA13: =SUM(Z13*X15) -> 1138540 | AB13: 96993 | AC13: =SUM(AB13-AB12) -> 20 | AD13: 178535 | AE13: =SUM(AF13/N13) -> 0.51456311 | AF13: =AD13-AD12 -> 53 | AG13: ='Lpg (2)'!B16*2000/85 -> 2000 | AH13: ='Lpg (2)'!C16*1000/85 -> 1000 | AI13: ='Lpg (2)'!D16*1000/85 -> 352.94118 | AJ13: =SUM(AG12*2000)+(AH13*1000)+(AI13*1000) -> 5352941.2 | AK13: =SUM(AJ12-AJ13) -> 70588.235
A14: =Gen!A19 -> 43443 | B14: =SUM(77*C14) -> 35.9975 | C14: =SUM(Gen!B19) -> 0.4675 | D14: =SUM('Summery Report'!E13) -> 37 | E14: =SUM(E13) -> 1.3262195 | F14: =SUM(J14*E14)/D14 -> 73.248896 | G14: =SUM(L14*E14)/D14 -> 92.409542 | H14: =SUM(Gen!C19) -> #REF! | I14: =SUM(Gen!D19) -> 0 | J14: =SUM(Gen!S19) -> 2043.56 | K14: =Gen!AJ19 -> 534.56 | L14: =SUM(J14:K14) -> 2578.12 | M14: ='Water-Meter'!D14 -> 174038 | N14: ='Water-Meter'!E14 -> 125 | O14: 1.2 | P14: 17064 | Q14: =SUM(P14-P13) -> 26 | R14: =SUM(Q14*O14) -> 31.2 | T14: 15027 | U14: =T14-T13 -> 0 | V14: =SUM(U14*S14) -> 0 | W14: 2.5 | X14: 17469 | Y14: =X14-X13 -> 11 | Z14: =SUM(Y14*W14) -> 27.5 | AA14: =SUM(Z14*X16) -> 482377.5 | AB14: 97031 | AC14: =SUM(AB14-AB13) -> 38 | AD14: 178594 | AE14: =SUM(AF14/N14) -> 0.472 | AF14: =AD14-AD13 -> 59 | AG14: ='Lpg (2)'!B17*2000/85 -> 2000 | AH14: ='Lpg (2)'!C17*1000/85 -> 1000 | AI14: ='Lpg (2)'!D17*1000/85 -> 270.58824 | AJ14: =SUM(AG13*2000)+(AH14*1000)+(AI14*1000) -> 5270588.2 | AK14: =SUM(AJ13-AJ14) -> 82352.941
A15: =Gen!A20 -> 43444 | B15: =SUM(77*C15) -> 42.9968 | C15: =SUM(Gen!B20) -> 0.5584 | D15: =SUM('Summery Report'!E14) -> 44 | E15: =SUM(E14) -> 1.3262195 | F15: =SUM(J15*E15)/D15 -> 63.394197 | G15: =SUM(L15*E15)/D15 -> 76.596109 | H15: =SUM(Gen!C20) -> #REF! | I15: =SUM(Gen!D20) -> 12000 | J15: =SUM(Gen!S20) -> 2103.23 | K15: =Gen!AJ20 -> 438 | L15: =SUM(J15:K15) -> 2541.23 | M15: ='Water-Meter'!D15 -> 174152 | N15: ='Water-Meter'!E15 -> 114 | O15: 1.2 | P15: 17064 | Q15: =SUM(P15-P14) -> 0 | R15: =SUM(Q15*O15) -> 0 | S15: 2.5 | T15: 15046 | U15: =T15-T14 -> 19 | V15: =SUM(U15*S15) -> 47.5 | W15: 2.4 | X15: 17516 | Y15: =X15-X14 -> 47 | Z15: =SUM(Y15*W15) -> 112.8 | AA15: =SUM(Z15*X17) -> 1981444.8 | AB15: 97126 | AC15: =SUM(AB15-AB14) -> 95 | AD15: 178714 | AE15: =SUM(AF15/N15) -> 1.0526316 | AF15: =AD15-AD14 -> 120 | AG15: ='Lpg (2)'!B18*2000/85 -> 2000 | AH15: ='Lpg (2)'!C18*1000/85 -> 1000 | AI15: ='Lpg (2)'!D18*1000/85 -> 188.23529 | AJ15: =SUM(AG15*2000)+(AH15*1000)+(AI15*1000) -> 5188235.3 | AK15: =SUM(AJ14-AJ15) -> 82352.941
A16: =Gen!A21 -> 43445 | B16: =SUM(77*C16) -> 43.9978 | C16: =SUM(Gen!B21) -> 0.5714 | D16: =SUM('Summery Report'!E15) -> 45 | E16: =SUM(E15) -> 1.3262195 | F16: =SUM(J16*E16)/D16 -> 60.249563 | G16: =SUM(L16*E16)/D16 -> 66.801972 | H16: =SUM(Gen!C21) -> #REF! | I16: =SUM(Gen!D21) -> 0 | J16: =SUM(Gen!S21) -> 2044.33 | K16: =Gen!AJ21 -> 222.33 | L16: =SUM(J16:K16) -> 2266.66 | M16: ='Water-Meter'!D16 -> 174266 | N16: ='Water-Meter'!E16 -> 114 | O16: 1.2 | P16: 17064 | Q16: =SUM(P16-P15) -> 0 | R16: =SUM(Q16*O16) -> 0 | S16: 2.5 | T16: 15071 | U16: =T16-T15 -> 25 | V16: =SUM(U16*S16) -> 62.5 | W16: 2.4 | X16: 17541 | Y16: =X16-X15 -> 25 | Z16: =SUM(Y16*W16) -> 60 | AA16: =SUM(Z16*X18) -> 1054380 | AB16: 97333 | AC16: =SUM(AB16-AB15) -> 207 | AD16: 178773 | AE16: =SUM(AF16/N16) -> 0.51754386 | AF16: =AD16-AD15 -> 59 | AG16: ='Lpg (2)'!B19*2000/85 -> 2000 | AH16: ='Lpg (2)'!C19*1000/85 -> 1000 | AI16: ='Lpg (2)'!D19*1000/85 -> 105.88235 | AJ16: =SUM(AG16*2000)+(AH16*1000)+(AI16*1000) -> 5105882.4 | AK16: =SUM(AJ15-AJ16) -> 82352.941
A17: =Gen!A22 -> 43446 | B17: =SUM(77*C17) -> 18.0026 | C17: =SUM(Gen!B22) -> 0.2338 | D17: =SUM('Summery Report'!E16) -> 21 | E17: =SUM(E16) -> 1.3262195 | F17: =SUM(J17*E17)/D17 -> 121.08005 | G17: =SUM(L17*E17)/D17 -> 133.59956 | H17: =SUM(Gen!C22) -> #REF! | I17: =SUM(Gen!D22) -> 0 | J17: =SUM(Gen!S22) -> 1917.24 | K17: =Gen!AJ22 -> 198.24 | L17: =SUM(J17:K17) -> 2115.48 | M17: ='Water-Meter'!D17 -> 174371 | N17: ='Water-Meter'!E17 -> 105 | O17: 1.2 | P17: 17064 | Q17: =SUM(P17-P16) -> 0 | R17: =SUM(Q17*O17) -> 0 | S17: 2.5 | T17: 15096 | U17: =T17-T16 -> 25 | V17: =SUM(U17*S17) -> 62.5 | W17: 2.4 | X17: 17566 | Y17: =X17-X16 -> 25 | Z17: =SUM(Y17*W17) -> 60 | AA17: =SUM(Z17*X19) -> 1055160 | AB17: 97450 | AC17: =SUM(AB17-AB16) -> 117 | AD17: 178847 | AE17: =SUM(AF17/N17) -> 0.7047619 | AF17: =AD17-AD16 -> 74 | AG17: ='Lpg (2)'!B20*2000/85 -> 2000 | AH17: ='Lpg (2)'!C20*1000/85 -> 1000 | AI17: ='Lpg (2)'!D20*1000/85 -> 23.529412 | AJ17: =SUM(AG17*2000)+(AH17*1000)+(AI17*1000) -> 5023529.4 | AK17: =SUM(AJ16-AJ17) -> 82352.941
A18: =Gen!A23 -> 43447 | B18: =SUM(77*C18) -> 20.9979 | C18: =SUM(Gen!B23) -> 0.2727 | D18: =SUM('Summery Report'!E17) -> 23 | E18: =SUM(E17) -> 1.3262195 | F18: =SUM(J18*E18)/D18 -> 109.07175 | G18: =SUM(L18*E18)/D18 -> 115.65095 | H18: =SUM(Gen!C23) -> #REF! | I18: =SUM(Gen!D23) -> 0 | J18: =SUM(Gen!S23) -> 1891.58 | K18: =Gen!AJ23 -> 114.1 | L18: =SUM(J18:K18) -> 2005.68 | M18: ='Water-Meter'!D18 -> 174482 | N18: ='Water-Meter'!E18 -> 111 | O18: 1.2 | P18: 17064 | Q18: =SUM(P18-P17) -> 0 | R18: =SUM(Q18*O18) -> 0 | S18: 2.5 | T18: 15096 | U18: =T18-T17 -> 0 | V18: =SUM(U18*S18) -> 0 | W18: 2.4 | X18: 17573 | Y18: =X18-X17 -> 7 | Z18: =SUM(Y18*W18) -> 16.8 | AA18: =SUM(Z18*X20) -> 295965.6 | AB18: 97479 | AC18: =SUM(AB18-AB17) -> 29 | AD18: 178921 | AE18: =SUM(AF18/N18) -> 0.66666667 | AF18: =AD18-AD17 -> 74 | AG18: ='Lpg (2)'!B21*2000/85 -> 2000 | AH18: ='Lpg (2)'!C21*1000/85 -> 917.64706 | AI18: ='Lpg (2)'!D21*1000/85 -> 0 | AJ18: =SUM(AG18*2000)+(AH18*1000)+(AI18*1000) -> 4917647.1 | AK18: =SUM(AJ17-AJ18) -> 105882.35
A19: =Gen!A24 -> 43448 | B19: =SUM(77*C19) -> 19.9815 | C19: =SUM(Gen!B24) -> 0.2595 | D19: =SUM('Summery Report'!E18) -> 21 | E19: =SUM(E18) -> 1.3262195 | F19: =SUM(J19*E19)/D19 -> 125.82918 | G19: =SUM(L19*E19)/D19 -> 145.75531 | H19: =SUM(Gen!C24) -> #REF! | I19: =SUM(Gen!D24) -> 0 | J19: =SUM(Gen!S24) -> 1992.44 | K19: =Gen!AJ24 -> 315.52 | L19: =SUM(J19:K19) -> 2307.96 | M19: ='Water-Meter'!D19 -> 174582 | N19: ='Water-Meter'!E19 -> 100 | O19: 1.2 | P19: 17064 | Q19: =SUM(P19-P18) -> 0 | R19: =SUM(Q19*O19) -> 0 | S19: 2.5 | T19: 15096 | U19: =T19-T18 -> 0 | V19: =SUM(U19*S19) -> 0 | W19: 2.4 | X19: 17586 | Y19: =X19-X18 -> 13 | Z19: =SUM(Y19*W19) -> 31.2 | AA19: =SUM(Z19*X21) -> 550399.2 | AB19: 97530 | AC19: =SUM(AB19-AB18) -> 51 | AD19: 178977 | AE19: =SUM(AF19/N19) -> 0.56 | AF19: =AD19-AD18 -> 56 | AG19: ='Lpg (2)'!B22*2000/85 -> 2000 | AH19: ='Lpg (2)'!C22*1000/85 -> 776.47059 | AI19: ='Lpg (2)'!D22*1000/85 -> 0 | AJ19: =SUM(AG19*2000)+(AH19*1000)+(AI19*1000) -> 4776470.6 | AK19: =SUM(AJ18-AJ19) -> 141176.47
A20: =Gen!A25 -> 43449 | B20: =SUM(77*C20) -> 10.0023 | C20: =SUM(Gen!B25) -> 0.1299 | D20: =SUM('Summery Report'!E19) -> 11 | E20: =SUM(E19) -> 1.3262195 | F20: =SUM(J20*E20)/D20 -> 233.65335 | G20: =SUM(L20*E20)/D20 -> 302.53478 | H20: =SUM(Gen!C25) -> #REF! | I20: =SUM(Gen!D25) -> 0 | J20: =SUM(Gen!S25) -> 1937.98 | K20: =Gen!AJ25 -> 571.32 | L20: =SUM(J20:K20) -> 2509.3 | M20: ='Water-Meter'!D20 -> 174669 | N20: ='Water-Meter'!E20 -> 87 | O20: 1.2 | P20: 17064 | Q20: =SUM(P20-P19) -> 0 | R20: =SUM(Q20*O20) -> 0 | S20: 2.5 | T20: 15096 | U20: =T20-T19 -> 0 | V20: =SUM(U20*S20) -> 0 | W20: 2.4 | X20: 17617 | Y20: =X20-X19 -> 31 | Z20: =SUM(Y20*W20) -> 74.4 | AA20: =SUM(Z20*X22) -> 1314127.2 | AB20: 97591 | AC20: =SUM(AB20-AB19) -> 61 | AD20: 179014 | AE20: =SUM(AF20/N20) -> 0.42528736 | AF20: =AD20-AD19 -> 37 | AG20: ='Lpg (2)'!B23*2000/85 -> 2000 | AH20: ='Lpg (2)'!C23*1000/85 -> 705.88235 | AI20: ='Lpg (2)'!D23*1000/85 -> 0 | AJ20: =SUM(AG20*2000)+(AH20*1000)+(AI20*1000) -> 4705882.4 | AK20: =SUM(AJ19-AJ20) -> 70588.235
A21: =Gen!A26 -> 43450 | B21: =SUM(77*C21) -> 19.9969 | C21: =SUM(Gen!B26) -> 0.2597 | D21: =SUM('Summery Report'!E20) -> 21 | E21: =SUM(E20) -> 1.3262195 | F21: =SUM(J21*E21)/D21 -> 128.96727 | G21: =SUM(L21*E21)/D21 -> 150.17036 | H21: =SUM(Gen!C26) -> #REF! | I21: =SUM(Gen!D26) -> 12000 | J21: =SUM(Gen!S26) -> 2042.13 | K21: =Gen!AJ26 -> 335.74 | L21: =SUM(J21:K21) -> 2377.87 | M21: ='Water-Meter'!D21 -> 174774 | N21: ='Water-Meter'!E21 -> 105 | O21: 2.6 | P21: 17097 | Q21: =SUM(P21-P20) -> 33 | R21: =SUM(Q21*O21) -> 85.8 | S21: 2.5 | T21: 15096 | U21: =T21-T20 -> 0 | V21: =SUM(U21*S21) -> 0 | W21: 2.3 | X21: 17641 | Y21: =X21-X20 -> 24 | Z21: =SUM(Y21*W21) -> 55.2 | AA21: =SUM(Z21*X23) -> 976432.8 | AB21: 97691 | AC21: =SUM(AB21-AB20) -> 100 | AD21: 179014 | AE21: =SUM(AF21/N21) -> 0 | AF21: =AD21-AD20 -> 0 | AG21: ='Lpg (2)'!B24*2000/85 -> 2000 | AH21: ='Lpg (2)'!C24*1000/85 -> 658.82353 | AI21: ='Lpg (2)'!D24*1000/85 -> 0 | AJ21: =SUM(AG21*2000)+(AH21*1000)+(AI21*1000) -> 4658823.5 | AK21: =SUM(AJ20-AJ21) -> 47058.824
A22: =Gen!A27 -> 43451 | B22: =SUM(77*C22) -> 22.9999 | C22: =SUM(Gen!B27) -> 0.2987 | D22: =SUM('Summery Report'!E21) -> 24 | E22: =SUM(E21) -> 1.3262195 | F22: =SUM(J22*E22)/D22 -> 115.99226 | G22: =SUM(L22*E22)/D22 -> 148.11496 | H22: =SUM(Gen!C27) -> #REF! | I22: =SUM(Gen!D27) -> 0 | J22: =SUM(Gen!S27) -> 2099.06 | K22: =Gen!AJ27 -> 581.31 | L22: =SUM(J22:K22) -> 2680.37 | M22: ='Water-Meter'!D22 -> 174883 | N22: ='Water-Meter'!E22 -> 109 | O22: 2.6 | P22: 17121 | Q22: =SUM(P22-P21) -> 24 | R22: =SUM(Q22*O22) -> 62.4 | S22: 2.5 | T22: 15096 | U22: =T22-T21 -> 0 | V22: =SUM(U22*S22) -> 0 | W22: 2.3 | X22: 17663 | Y22: =X22-X21 -> 22 | Z22: =SUM(Y22*W22) -> 50.6 | AA22: =SUM(Z22*X24) -> 895822.4 | AB22: 97796 | AC22: =SUM(AB22-AB21) -> 105 | AD22: 179063 | AE22: =SUM(AF22/N22) -> 0.44954128 | AF22: =AD22-AD21 -> 49 | AG22: ='Lpg (2)'!B25*2000/85 -> 2000 | AH22: ='Lpg (2)'!C25*1000/85 -> 611.76471 | AI22: ='Lpg (2)'!D25*1000/85 -> 0 | AJ22: =SUM(AG22*2000)+(AH22*1000)+(AI22*1000) -> 4611764.7 | AK22: =SUM(AJ21-AJ22) -> 47058.824
A23: =Gen!A28 -> 43452 | B23: =SUM(77*C23) -> 39.0005 | C23: =SUM(Gen!B28) -> 0.5065 | D23: =SUM('Summery Report'!E22) -> 41 | E23: =SUM(E22) -> 1.3262195 | F23: =SUM(J23*E23)/D23 -> 76.726004 | G23: =SUM(L23*E23)/D23 -> 82.733131 | H23: =SUM(Gen!C28) -> #REF! | I23: =SUM(Gen!D28) -> 0 | J23: =SUM(Gen!S28) -> 2371.98 | K23: =Gen!AJ28 -> 185.71 | L23: =SUM(J23:K23) -> 2557.69 | M23: ='Water-Meter'!D23 -> 174997 | N23: ='Water-Meter'!E23 -> 114 | O23: 2.6 | P23: 17145 | Q23: =SUM(P23-P22) -> 24 | R23: =SUM(Q23*O23) -> 62.4 | S23: 2.5 | T23: 15096 | U23: =T23-T22 -> 0 | V23: =SUM(U23*S23) -> 0 | W23: 2.3 | X23: 17689 | Y23: =X23-X22 -> 26 | Z23: =SUM(Y23*W23) -> 59.8 | AA23: =SUM(Z23*X25) -> 1058878.6 | AB23: 97900 | AC23: =SUM(AB23-AB22) -> 104 | AD23: 179111 | AE23: =SUM(AF23/N23) -> 0.42105263 | AF23: =AD23-AD22 -> 48 | AG23: ='Lpg (2)'!B26*2000/85 -> 2000 | AH23: ='Lpg (2)'!C26*1000/85 -> 576.47059 | AI23: ='Lpg (2)'!D26*1000/85 -> 0 | AJ23: =SUM(AG23*2000)+(AH23*1000)+(AI23*1000) -> 4576470.6 | AK23: =SUM(AJ22-AJ23) -> 35294.118
A24: =Gen!A29 -> 43453 | B24: =SUM(77*C24) -> 34.0032 | C24: =SUM(Gen!B29) -> 0.4416 | D24: =SUM('Summery Report'!E23) -> 35 | E24: =SUM(E23) -> 1.3262195 | F24: =SUM(J24*E24)/D24 -> 85.588524 | G24: =SUM(L24*E24)/D24 -> 90.059778 | H24: =SUM(Gen!C29) -> #REF! | I24: =SUM(Gen!D29) -> 0 | J24: =SUM(Gen!S29) -> 2258.75 | K24: =Gen!AJ29 -> 118 | L24: =SUM(J24:K24) -> 2376.75 | M24: ='Water-Meter'!D24 -> 175107 | N24: ='Water-Meter'!E24 -> 110 | O24: 2.6 | P24: 17160 | Q24: =SUM(P24-P23) -> 15 | R24: =SUM(Q24*O24) -> 39 | S24: 2.5 | T24: 15096 | U24: =T24-T23 -> 0 | V24: =SUM(U24*S24) -> 0 | W24: 2.3 | X24: 17704 | Y24: =X24-X23 -> 15 | Z24: =SUM(Y24*W24) -> 34.5 | AA24: =SUM(Z24*X26) -> 611719.5 | AB24: 97960 | AC24: =SUM(AB24-AB23) -> 60 | AD24: 179219 | AE24: =SUM(AF24/N24) -> 0.98181818 | AF24: =AD24-AD23 -> 108 | AG24: ='Lpg (2)'!B27*2000/85 -> 2000 | AH24: ='Lpg (2)'!C27*1000/85 -> 435.29412 | AI24: ='Lpg (2)'!D27*1000/85 -> 0 | AJ24: =SUM(AG24*2000)+(AH24*1000)+(AI24*1000) -> 4435294.1 | AK24: =SUM(AJ23-AJ24) -> 141176.47
A25: =Gen!A30 -> 43454 | B25: =SUM(77*C25) -> 31.0002 | C25: =SUM(Gen!B30) -> 0.4026 | D25: =SUM('Summery Report'!E24) -> 34 | E25: =SUM(E24) -> 1.3262195 | F25: =SUM(J25*E25)/D25 -> 91.873077 | G25: =SUM(L25*E25)/D25 -> 118.79104 | H25: =SUM(Gen!C30) -> #REF! | I25: =SUM(Gen!D30) -> 0 | J25: =SUM(Gen!S30) -> 2355.33 | K25: =Gen!AJ30 -> 690.09 | L25: =SUM(J25:K25) -> 3045.42 | M25: ='Water-Meter'!D25 -> 175230 | N25: ='Water-Meter'!E25 -> 123 | O25: 2.6 | P25: 17160 | Q25: =SUM(P25-P24) -> 0 | R25: =SUM(Q25*O25) -> 0 | S25: 2.5 | T25: 15107 | U25: =T25-T24 -> 11 | V25: =SUM(U25*S25) -> 27.5 | W25: 2.3 | X25: 17707 | Y25: =X25-X24 -> 3 | Z25: =SUM(Y25*W25) -> 6.9 | AA25: =SUM(Z25*X27) -> 122392.2 | AB25: 97983 | AC25: =SUM(AB25-AB24) -> 23 | AD25: 179300 | AE25: =SUM(AF25/N25) -> 0.65853659 | AF25: =AD25-AD24 -> 81 | AG25: ='Lpg (2)'!B28*2000/85 -> 2000 | AH25: ='Lpg (2)'!C28*1000/85 -> 341.17647 | AI25: ='Lpg (2)'!D28*1000/85 -> 0 | AJ25: =SUM(AG25*2000)+(AH25*1000)+(AI25*1000) -> 4341176.5 | AK25: =SUM(AJ24-AJ25) -> 94117.647
A26: =Gen!A31 -> 43455 | B26: =SUM(77*C26) -> 37.9995 | C26: =SUM(Gen!B31) -> 0.4935 | D26: =SUM('Summery Report'!E25) -> 41 | E26: =SUM(E25) -> 1.3262195 | F26: =SUM(J26*E26)/D26 -> 69.849717 | G26: =SUM(L26*E26)/D26 -> 87.458678 | H26: =SUM(Gen!C31) -> #REF! | I26: =SUM(Gen!D31) -> 0 | J26: =SUM(Gen!S31) -> 2159.4 | K26: =Gen!AJ31 -> 544.38 | L26: =SUM(J26:K26) -> 2703.78 | M26: ='Water-Meter'!D26 -> 175360 | N26: ='Water-Meter'!E26 -> 130 | O26: 2.5 | P26: 17163 | Q26: =SUM(P26-P25) -> 3 | R26: =SUM(Q26*O26) -> 7.5 | S26: 2.5 | T26: 15128 | U26: =T26-T25 -> 21 | V26: =SUM(U26*S26) -> 52.5 | W26: 2.8 | X26: 17731 | Y26: =X26-X25 -> 24 | Z26: =SUM(Y26*W26) -> 67.2 | AA26: =SUM(Z26*X28) -> 1192732.8 | AB26: 98110 | AC26: =SUM(AB26-AB25) -> 127 | AD26: 179381 | AE26: =SUM(AF26/N26) -> 0.62307692 | AF26: =AD26-AD25 -> 81 | AG26: ='Lpg (2)'!B29*2000/85 -> 2000 | AH26: ='Lpg (2)'!C29*1000/85 -> 235.29412 | AI26: ='Lpg (2)'!D29*1000/85 -> 0 | AJ26: =SUM(AG26*2000)+(AH26*1000)+(AI26*1000) -> 4235294.1 | AK26: =SUM(AJ25-AJ26) -> 105882.35
A27: =Gen!A32 -> 43456 | B27: =SUM(77*C27) -> 37.9995 | C27: =SUM(Gen!B32) -> 0.4935 | D27: =SUM('Summery Report'!E26) -> 41 | E27: =SUM(E26) -> 1.3262195 | F27: =SUM(J27*E27)/D27 -> 80.900037 | G27: =SUM(L27*E27)/D27 -> 91.339326 | H27: =SUM(Gen!C32) -> #REF! | I27: =SUM(Gen!D32) -> 16800 | J27: =SUM(Gen!S32) -> 2501.02 | K27: =Gen!AJ32 -> 322.73 | L27: =SUM(J27:K27) -> 2823.75 | M27: ='Water-Meter'!D27 -> 175490 | N27: ='Water-Meter'!E27 -> 130 | O27: 2.5 | P27: 17164 | Q27: =SUM(P27-P26) -> 1 | R27: =SUM(Q27*O27) -> 2.5 | S27: 2.5 | T27: 15128 | U27: =T27-T26 -> 0 | V27: =SUM(U27*S27) -> 0 | W27: 2.8 | X27: 17738 | Y27: =X27-X26 -> 7 | Z27: =SUM(Y27*W27) -> 19.6 | AA27: =SUM(Z27*X29) -> 347880.4 | AB27: 98145 | AC27: =SUM(AB27-AB26) -> 35 | AD27: 179466 | AE27: =SUM(AF27/N27) -> 0.65384615 | AF27: =AD27-AD26 -> 85 | AG27: ='Lpg (2)'!B30*2000/85 -> 2000 | AH27: ='Lpg (2)'!C30*1000/85 -> 176.47059 | AI27: ='Lpg (2)'!D30*1000/85 -> 0 | AJ27: =SUM(AG27*2000)+(AH27*1000)+(AI27*1000) -> 4176470.6 | AK27: =SUM(AJ26-AJ27) -> 58823.529
A28: =Gen!A33 -> 43457 | B28: =SUM(77*C28) -> 34.3112 | C28: =SUM(Gen!B33) -> 0.4456 | D28: =SUM('Summery Report'!E27) -> 35 | E28: =SUM(E27) -> 1.3262195 | F28: =SUM(J28*E28)/D28 -> 90.011276 | G28: =SUM(L28*E28)/D28 -> 93.569713 | H28: =SUM(Gen!C33) -> #REF! | I28: =SUM(Gen!D33) -> 0 | J28: =SUM(Gen!S33) -> 2375.47 | K28: =Gen!AJ33 -> 93.91 | L28: =SUM(J28:K28) -> 2469.38 | M28: ='Water-Meter'!D28 -> 175621 | N28: ='Water-Meter'!E28 -> 131 | P28: 17164 | Q28: =SUM(P28-P27) -> 0 | R28: =SUM(Q28*O28) -> 0 | T28: 15128 | U28: =T28-T27 -> 0 | V28: =SUM(U28*S28) -> 0 | W28: 2.4 | X28: 17749 | Y28: =X28-X27 -> 11 | Z28: =SUM(Y28*W28) -> 26.4 | AA28: =SUM(Z28*X30) -> 468784.8 | AB28: 98175 | AC28: =SUM(AB28-AB27) -> 30 | AD28: 179541 | AE28: =SUM(AF28/N28) -> 0.57251908 | AF28: =AD28-AD27 -> 75 | AG28: ='Lpg (2)'!B31*2000/85 -> 2000 | AH28: ='Lpg (2)'!C31*1000/85 -> 129.41176 | AI28: ='Lpg (2)'!D31*1000/85 -> 0 | AJ28: =SUM(AG28*2000)+(AH28*1000)+(AI28*1000) -> 4129411.8 | AK28: =SUM(AJ27-AJ28) -> 47058.824
A29: =Gen!A34 -> 43458 | B29: =SUM(77*C29) -> 39.0005 | C29: =SUM(Gen!B34) -> 0.5065 | D29: =SUM('Summery Report'!E28) -> 40 | E29: =SUM(E28) -> 1.3262195 | F29: =SUM(J29*E29)/D29 -> 89.794345 | G29: =SUM(L29*E29)/D29 -> 115.86351 | H29: =SUM(Gen!C34) -> #REF! | I29: =SUM(Gen!D34) -> 0 | J29: =SUM(Gen!S34) -> 2708.28 | K29: =Gen!AJ34 -> 786.27 | L29: =SUM(J29:K29) -> 3494.55 | M29: ='Water-Meter'!D29 -> 175733 | N29: ='Water-Meter'!E29 -> 112 | P29: 17164 | Q29: =SUM(P29-P28) -> 0 | R29: =SUM(Q29*O29) -> 0 | T29: 15128 | U29: =T29-T28 -> 0 | V29: =SUM(U29*S29) -> 0 | X29: 17749 | Y29: =X29-X28 -> 0 | Z29: =SUM(Y29*W29) -> 0 | AA29: =SUM(Z29*X31) -> 0 | AB29: 98175 | AC29: =SUM(AB29-AB28) -> 0 | AD29: 179618 | AE29: =SUM(AF29/N29) -> 0.6875 | AF29: =AD29-AD28 -> 77 | AG29: ='Lpg (2)'!B32*2000/85 -> 2000 | AH29: ='Lpg (2)'!C32*1000/85 -> 82.352941 | AI29: ='Lpg (2)'!D32*1000/85 -> 0 | AJ29: =SUM(AG29*2000)+(AH29*1000)+(AI29*1000) -> 4082352.9 | AK29: =SUM(AJ28-AJ29) -> 47058.824
A30: =Gen!A35 -> 43459 | B30: =SUM(77*C30) -> 73.0037 | C30: =SUM(Gen!B35) -> 0.9481 | D30: =SUM('Summery Report'!E29) -> 73 | E30: =SUM(E29) -> 1.3262195 | F30: =SUM(J30*E30)/D30 -> 51.057634 | G30: =SUM(L30*E30)/D30 -> 54.226754 | H30: =SUM(Gen!C35) -> #REF! | I30: =SUM(Gen!D35) -> 0 | J30: =SUM(Gen!S35) -> 2810.4 | K30: =Gen!AJ35 -> 174.44 | L30: =SUM(J30:K30) -> 2984.84 | M30: ='Water-Meter'!D30 -> 175880 | N30: ='Water-Meter'!E30 -> 147 | P30: 17164 | Q30: =SUM(P30-P29) -> 0 | R30: =SUM(Q30*O30) -> 0 | T30: 15128 | U30: =T30-T29 -> 0 | V30: =SUM(U30*S30) -> 0 | W30: 2.3 | X30: 17757 | Y30: =X30-X29 -> 8 | Z30: =SUM(Y30*W30) -> 18.4 | AA30: =SUM(Z30*X32) -> 326765.6 | AB30: 98196 | AC30: =SUM(AB30-AB29) -> 21 | AD30: 179691 | AE30: =SUM(AF30/N30) -> 0.49659864 | AF30: =AD30-AD29 -> 73 | AG30: ='Lpg (2)'!B33*2000/85 -> 2000 | AH30: ='Lpg (2)'!C33*1000/85 -> 47.058824 | AI30: ='Lpg (2)'!D33*1000/85 -> 0 | AJ30: =SUM(AG30*2000)+(AH30*1000)+(AI30*1000) -> 4047058.8 | AK30: =SUM(AJ29-AJ30) -> 35294.118
A31: =Gen!A36 -> 43460 | B31: =SUM(77*C31) -> 70.0007 | C31: =SUM(Gen!B36) -> 0.9091 | D31: =SUM('Summery Report'!E30) -> 70 | E31: =SUM(E30) -> 1.3262195 | F31: =SUM(J31*E31)/D31 -> 54.289743 | G31: =SUM(L31*E31)/D31 -> 61.036032 | H31: =SUM(Gen!C36) -> #REF! | I31: =SUM(Gen!D36) -> 0 | J31: =SUM(Gen!S36) -> 2865.5 | K31: =Gen!AJ36 -> 356.08 | L31: =SUM(J31:K31) -> 3221.58 | M31: ='Water-Meter'!D31 -> 176047 | N31: ='Water-Meter'!E31 -> 167 | P31: 17164 | Q31: =SUM(P31-P30) -> 0 | R31: =SUM(Q31*O31) -> 0 | T31: 15128 | U31: =T31-T30 -> 0 | V31: =SUM(U31*S31) -> 0 | X31: 17757 | Y31: =X31-X30 -> 0 | Z31: =SUM(Y31*W31) -> 0 | AA31: =SUM(Z31*X33) -> 0 | AB31: 98196 | AC31: =SUM(AB31-AB30) -> 0 | AD31: 179765 | AE31: =SUM(AF31/N31) -> 0.44311377 | AF31: =AD31-AD30 -> 74 | AG31: ='Lpg (2)'!B34*2000/85 -> 2000 | AH31: ='Lpg (2)'!C34*1000/85 -> #VALUE! | AI31: ='Lpg (2)'!D34*1000/85 -> 0 | AJ31: =SUM(AG31*2000)+(AH31*1000)+(AI31*1000) -> #VALUE! | AK31: =SUM(AJ30-AJ31) -> #VALUE!
A32: =Gen!A37 -> 43461 | B32: =SUM(77*C32) -> 58.9974 | C32: =SUM(Gen!B37) -> 0.7662 | D32: =SUM('Summery Report'!E31) -> 60 | E32: =SUM(E31) -> 1.3262195 | F32: =SUM(J32*E32)/D32 -> 58.250655 | G32: =SUM(L32*E32)/D32 -> 62.75295 | H32: =SUM(Gen!C37) -> #REF! | I32: =SUM(Gen!D37) -> 0 | J32: =SUM(Gen!S37) -> 2635.34 | K32: =Gen!AJ37 -> 203.69 | L32: =SUM(J32:K32) -> 2839.03 | M32: ='Water-Meter'!D32 -> 176206 | N32: ='Water-Meter'!E32 -> 159 | P32: 17164 | Q32: =SUM(P32-P31) -> 0 | R32: =SUM(Q32*O32) -> 0 | T32: 15128 | U32: =T32-T31 -> 0 | V32: =SUM(U32*S32) -> 0 | X32: 17759 | Y32: =X32-X31 -> 2 | Z32: =SUM(Y32*W32) -> 0 | AA32: =SUM(Z32*X34) -> 0 | AB32: 98202 | AC32: =SUM(AB32-AB31) -> 6 | AD32: 179839 | AE32: =SUM(AF32/N32) -> 0.46540881 | AF32: =AD32-AD31 -> 74 | AG32: ='Lpg (2)'!B35*2000/85 -> 2000 | AH32: ='Lpg (2)'!C35*1000/85 -> 0 | AI32: ='Lpg (2)'!D35*1000/85 -> 0 | AJ32: =SUM(AG32*2000)+(AH32*1000)+(AI32*1000) -> 4000000 | AK32: =SUM(AJ31-AJ32) -> #VALUE!
A33: =Gen!A38 -> 43462 | B33: =SUM(77*C33) -> 59.9984 | C33: =SUM(Gen!B38) -> 0.7792 | D33: =SUM('Summery Report'!E32) -> 62 | E33: =SUM(E32) -> 1.3262195 | F33: =SUM(J33*E33)/D33 -> 65.098982 | G33: =SUM(L33*E33)/D33 -> 71.975002 | H33: =SUM(Gen!C38) -> #REF! | I33: =SUM(Gen!D38) -> 12000 | J33: =SUM(Gen!S38) -> 3043.34 | K33: =Gen!AJ38 -> 321.45 | L33: =SUM(J33:K33) -> 3364.79 | M33: ='Water-Meter'!D33 -> 176370 | N33: ='Water-Meter'!E33 -> 164 | P33: 17164 | Q33: =SUM(P33-P32) -> 0 | R33: =SUM(Q33*O33) -> 0 | T33: 15128 | U33: =T33-T32 -> 0 | V33: =SUM(U33*S33) -> 0 | W33: 2.9 | X33: 17763 | Y33: =X33-X32 -> 4 | Z33: =SUM(Y33*W33) -> 11.6 | AA33: =SUM(Z33*X35) -> 206352.4 | AB33: 98213 | AC33: =SUM(AB33-AB32) -> 11 | AD33: 179911 | AE33: =SUM(AF33/N33) -> 0.43902439 | AF33: =AD33-AD32 -> 72 | AG33: ='Lpg (2)'!B36*2000/85 -> 1952.9412 | AH33: ='Lpg (2)'!C36*1000/85 -> 0 | AI33: ='Lpg (2)'!D36*1000/85 -> 0 | AJ33: =SUM(AG33*2000)+(AH33*1000)+(AI33*1000) -> 3905882.4 | AK33: =SUM(AJ32-AJ33) -> 94117.647
A34: =Gen!A39 -> 43463 | B34: =SUM(77*C34) -> 71.0017 | C34: =SUM(Gen!B39) -> 0.9221 | D34: =SUM('Summery Report'!E33) -> 73 | E34: =SUM(E33) -> 1.3262195 | F34: =SUM(J34*E34)/D34 -> 52.176382 | G34: =SUM(L34*E34)/D34 -> 56.664455 | H34: =SUM(Gen!C39) -> #REF! | I34: =SUM(Gen!D39) -> 0 | J34: =SUM(Gen!S39) -> 2871.98 | K34: =Gen!AJ39 -> 247.04 | L34: =SUM(J34:K34) -> 3119.02 | M34: ='Water-Meter'!D34 -> 176543 | N34: ='Water-Meter'!E34 -> 173 | P34: 17168 | Q34: =SUM(P34-P33) -> 4 | R34: =SUM(Q34*O34) -> 0 | T34: 15128 | U34: =T34-T33 -> 0 | V34: =SUM(U34*S34) -> 0 | W34: 3 | X34: 17770 | Y34: =X34-X33 -> 7 | Z34: =SUM(Y34*W34) -> 21 | AA34: =SUM(Z34*X36) -> 0 | AB34: 98235 | AC34: =SUM(AB34-AB33) -> 22 | AD34: 179981 | AE34: =SUM(AF34/N34) -> 0.40462428 | AF34: =AD34-AD33 -> 70 | AG34: ='Lpg (2)'!B37*2000/85 -> 1882.3529 | AH34: ='Lpg (2)'!C37*1000/85 -> 0 | AI34: ='Lpg (2)'!D37*1000/85 -> 0 | AJ34: =SUM(AG34*2000)+(AH34*1000)+(AI34*1000) -> 3764705.9 | AK34: =SUM(AJ33-AJ34) -> 141176.47
A35: =Gen!A40 -> 43464 | B35: =SUM(77*C35) -> 59.9984 | C35: =SUM(Gen!B40) -> 0.7792 | D35: =SUM('Summery Report'!E34) -> 61 | E35: =SUM(E34) -> 1.3262195 | F35: =SUM(J35*E35)/D35 -> 68.974503 | G35: =SUM(L35*E35)/D35 -> 71.586068 | H35: =SUM(Gen!C40) -> #REF! | I35: =SUM(Gen!D40) -> 0 | J35: =SUM(Gen!S40) -> 3172.51 | K35: =Gen!AJ40 -> 120.12 | L35: =SUM(J35:K35) -> 3292.63 | M35: ='Water-Meter'!D35 -> 176699 | N35: ='Water-Meter'!E35 -> 156 | Q35: =SUM(P35-P34) -> -17168 | R35: =SUM(Q35*O35) -> 0 | U35: =T35-T34 -> -15128 | V35: =SUM(U35*S35) -> 0 | X35: 17789 | Y35: =X35-X34 -> 19 | Z35: =SUM(Y35*W35) -> 0 | AA35: =SUM(Z35*X37) -> 0 | AB35: 98310 | AC35: =SUM(AB35-AB34) -> 75 | AD35: 180052 | AE35: =SUM(AF35/N35) -> 0.45512821 | AF35: =AD35-AD34 -> 71 | AG35: ='Lpg (2)'!B38*2000/85 -> 1858.8235 | AH35: ='Lpg (2)'!C38*1000/85 -> 0 | AI35: ='Lpg (2)'!D38*1000/85 -> 0 | AJ35: =SUM(AG35*2000)+(AH35*1000)+(AI35*1000) -> 3717647.1 | AK35: =SUM(AJ34-AJ35) -> 47058.824
A36: =Gen!A41 -> 43465 | B36: =SUM(77*C36) -> 65.0034 | C36: =SUM(Gen!B41) -> 0.8442 | D36: =SUM('Summery Report'!E35) -> 66 | E36: =SUM(E35) -> 1.3262195 | F36: =SUM(J36*E36)/D36 -> 61.463442 | G36: =SUM(L36*E36)/D36 -> 87.267253 | H36: =SUM(Gen!C41) -> #REF! | I36: =SUM(Gen!D41) -> 12000 | J36: =SUM(Gen!S41) -> 3058.76 | K36: =Gen!AJ41 -> 1284.14 | L36: =SUM(J36:K36) -> 4342.9 | M36: ='Water-Meter'!D36 -> 176819 | N36: ='Water-Meter'!E36 -> 120 | Q36: =SUM(P36-P35) -> 0 | R36: =SUM(Q36*O36) -> 0 | U36: =T36-T35 -> 0 | V36: =SUM(U36*S36) -> 0 | Y36: =X36-X35 -> -17789 | Z36: =SUM(Y36*W36) -> 0 | AA36: =SUM(Z36*X38) -> 0 | AC36: =SUM(AB36-AB35) -> -98310 | AE36: =SUM(AF36/N36) -> -1500.4333 | AF36: =AD36-AD35 -> -180052 | AG36: ='Lpg (2)'!B39*2000/85 -> 1788.2353 | AH36: ='Lpg (2)'!C39*1000/85 -> 0 | AI36: ='Lpg (2)'!D39*1000/85 -> 0 | AJ36: =SUM(AG36*1000)+(AH36*1000)+(AI36*2000) -> 1788235.3 | AK36: =SUM(AJ35-AJ36) -> 1929411.8
A37: Nb Day | B37: 0 | J37: =SUM(J6:J36) -> 71221.22 | L37: =SUM(J37:K37) -> 71221.22 | N37: ='Water-Meter'!E37 -> -176819 | AC37: =SUM(AB37-AB36) -> 0 | AE37: =SUM(AF37/N37) -> 0 | AF37: =AD37-AD36 -> 0 | AK37: =SUM(AK6:AK36) -> #VALUE! | AL37: =SUM(AL6:AL36) -> 0

Sheet Kit report
B1: KITCHEN THREE PHASE KWH METER READING | H1: KITCHEN WATER METER READING | M1: AMANI Restaurant WATER METER READING | T1: LAUNDRY THREE PHASE KWH METER READING | Y1: LAUNDRY WATER METER READING
A2: Occ % | B2: DATE | C2: READING TIME | D2: METER READING OPEN | E2: METER READING ClOSE | F2: UNIT USED Kwh | H2: DATE | I2: READING TIME | J2: METER READING OPEN Cbm | K2: METER READING ClOSE Cbm | L2: UNIT USED Cbm | M2: DATE | N2: READING TIME | O2: METER READING OPEN Cbm | P2: METER READING ClOSE Cbm | Q2: UNIT USED Cbm | R2: Cost Per day Elct+Water $ | S2: % as per the total Lodge consumption | T2: DATE | U2: READING TIME | V2: METER READING OPEN (Kwh) | W2: METER READING ClOSE (Kwh) | X2: UNIT USED Kwh | Y2: DATE | Z2: READING TIME | AA2: METER READING OPEN Cbm | AB2: METER READING ClOSE Cbm | AC2: UNIT USED Cbm
A3: 43070 | B3: Close Last Month | F3: X120 | H3: Close Last Month | K3: ='Water-Meter'!G5 -> 31114 | M3: Close Last Month | P3: ='Water-Meter'!J5 -> 6197 | T3: Close Last Month | W3: 5758.8 | X3: =(W3-V3)*200 -> 1151760 | Y3: Close Last Month | AB3: ='Water-Meter'!P5 -> 15270
A4: =Gen!B11 -> 0.168 | B4: =Gen!A11 -> 43435 | D4: =E3 -> 0 | E4: 6968.7 | F4: =SUM(E4-D4)*120 -> 836244 | H4: =B4 -> 43435 | J4: =SUM(K3) -> 31114 | K4: ='Water-Meter'!G6 -> 31126 | L4: =SUM(K4-J4) -> 12 | M4: =H4 -> 43435 | O4: =SUM(P3) -> 6197 | P4: ='Water-Meter'!J6 -> 6201 | Q4: =SUM(P4-O4) -> 4 | R4: =SUM(Q4/1615) -> 0.0024767802 | S4: =SUM(F4/Gen!T10) -> #DIV/0! | T4: =M4 -> 43435 | V4: =W3 -> 5758.8 | W4: 5760.4 | X4: =(W4-V4)*200 -> 320 | Y4: =T4 -> 43435 | AA4: 3397.9 | AB4: ='Water-Meter'!P6 -> 15280 | AC4: =SUM(AB4-AA4) -> 11882.1
A5: =Gen!B12 -> 0.1429 | B5: =Gen!A12 -> 43436 | D5: =E4 -> 6968.7 | E5: 6971.2 | F5: =SUM(E5-D5)*120 -> 300 | H5: =B5 -> 43436 | J5: =SUM(K4) -> 31126 | K5: ='Water-Meter'!G7 -> 31137 | L5: =SUM(K5-J5) -> 11 | M5: =H5 -> 43436 | O5: =SUM(P4) -> 6201 | P5: ='Water-Meter'!J7 -> 6204 | Q5: =SUM(P5-O5) -> 3 | R5: =SUM(Q5/1615) -> 0.0018575851 | S5: =SUM(F5/Gen!T11) -> 0.06586169 | T5: =M5 -> 43436 | V5: =W4 -> 5760.4 | W5: 5762.7 | X5: =(W5-V5)*200 -> 460 | Y5: =T5 -> 43436 | AA5: =SUM(AB4) -> 15280 | AB5: ='Water-Meter'!P7 -> 15292 | AC5: =SUM(AB5-AA5) -> 12
A6: =Gen!B13 -> 0.1429 | B6: =Gen!A13 -> 43437 | D6: =E5 -> 6971.2 | E6: 6973.3 | F6: =SUM(E6-D6)*120 -> 252 | H6: =B6 -> 43437 | J6: =SUM(K5) -> 31137 | K6: ='Water-Meter'!G8 -> 31148 | L6: =SUM(K6-J6) -> 11 | M6: =H6 -> 43437 | O6: =SUM(P5) -> 6204 | P6: ='Water-Meter'!J8 -> 6207 | Q6: =SUM(P6-O6) -> 3 | R6: =SUM(Q6/1615) -> 0.0018575851 | S6: =SUM(F6/Gen!T12) -> 0.053857662 | T6: =M6 -> 43437 | V6: =W5 -> 5762.7 | W6: 5764.3 | X6: =(W6-V6)*200 -> 320 | Y6: =T6 -> 43437 | AA6: =SUM(AB5) -> 15292 | AB6: ='Water-Meter'!P8 -> 15305 | AC6: =SUM(AB6-AA6) -> 13
A7: =Gen!B14 -> 0.1688 | B7: =Gen!A14 -> 43438 | D7: =E6 -> 6973.3 | E7: 6975.9 | F7: =SUM(E7-D7)*120 -> 312 | H7: =B7 -> 43438 | J7: =SUM(K6) -> 31148 | K7: ='Water-Meter'!G9 -> 31160 | L7: =SUM(K7-J7) -> 12 | M7: =H7 -> 43438 | O7: =SUM(P6) -> 6207 | P7: ='Water-Meter'!J9 -> 6210 | Q7: =SUM(P7-O7) -> 3 | R7: =SUM(Q7/1615) -> 0.0018575851 | S7: =SUM(F7/Gen!T13) -> 0.070317782 | T7: =M7 -> 43438 | V7: =W6 -> 5764.3 | W7: 5766.9 | X7: =(W7-V7)*200 -> 520 | Y7: =T7 -> 43438 | AA7: =SUM(AB6) -> 15305 | AB7: ='Water-Meter'!P9 -> 15317 | AC7: =SUM(AB7-AA7) -> 12
A8: =Gen!B15 -> 0.2078 | B8: =Gen!A15 -> 43439 | D8: =E7 -> 6975.9 | E8: 6978.5 | F8: =SUM(E8-D8)*120 -> 312 | H8: =B8 -> 43439 | J8: =SUM(K7) -> 31160 | K8: ='Water-Meter'!G10 -> 31172 | L8: =SUM(K8-J8) -> 12 | M8: =H8 -> 43439 | O8: =SUM(P7) -> 6210 | P8: ='Water-Meter'!J10 -> 6213 | Q8: =SUM(P8-O8) -> 3 | R8: =SUM(Q8/1615) -> 0.0018575851 | S8: =SUM(F8/Gen!T14) -> 0.066467831 | T8: =M8 -> 43439 | V8: =W7 -> 5766.9 | W8: 5769.1 | X8: =(W8-V8)*200 -> 440 | Y8: =T8 -> 43439 | AA8: =SUM(AB7) -> 15317 | AB8: ='Water-Meter'!P10 -> 15326 | AC8: =SUM(AB8-AA8) -> 9
A9: =Gen!B16 -> 0.2987 | B9: =Gen!A16 -> 43440 | D9: =E8 -> 6978.5 | E9: 6981.1 | F9: =SUM(E9-D9)*120 -> 312 | H9: =B9 -> 43440 | J9: =SUM(K8) -> 31172 | K9: ='Water-Meter'!G11 -> 31186 | L9: =SUM(K9-J9) -> 14 | M9: =H9 -> 43440 | O9: =SUM(P8) -> 6213 | P9: ='Water-Meter'!J11 -> 6216 | Q9: =SUM(P9-O9) -> 3 | R9: =SUM(Q9/1615) -> 0.0018575851 | S9: =SUM(F9/Gen!T15) -> 0.07157605 | T9: =M9 -> 43440 | V9: =W8 -> 5769.1 | W9: 5771.7 | X9: =(W9-V9)*200 -> 520 | Y9: =T9 -> 43440 | AA9: =SUM(AB8) -> 15326 | AB9: ='Water-Meter'!P11 -> 15336 | AC9: =SUM(AB9-AA9) -> 10
A10: =Gen!B17 -> 0.2468 | B10: =Gen!A17 -> 43441 | D10: =E9 -> 6981.1 | E10: 6983.2 | F10: =SUM(E10-D10)*120 -> 252 | H10: =B10 -> 43441 | J10: =SUM(K9) -> 31186 | K10: ='Water-Meter'!G12 -> 31199 | L10: =SUM(K10-J10) -> 13 | M10: =H10 -> 43441 | O10: =SUM(P9) -> 6216 | P10: ='Water-Meter'!J12 -> 6220 | Q10: =SUM(P10-O10) -> 4 | R10: =SUM(Q10/1615) -> 0.0024767802 | S10: =SUM(F10/Gen!T16) -> 0.053503185 | T10: =M10 -> 43441 | V10: =W9 -> 5771.7 | W10: 5773.8 | X10: =(W10-V10)*200 -> 420 | Y10: =T10 -> 43441 | AA10: =SUM(AB9) -> 15336 | AB10: ='Water-Meter'!P12 -> 15348 | AC10: =SUM(AB10-AA10) -> 12 | AH10: 5850
A11: =Gen!B18 -> 0.2857 | B11: =Gen!A18 -> 43442 | D11: =E10 -> 6983.2 | E11: 6985.5 | F11: =SUM(E11-D11)*120 -> 276 | H11: =B11 -> 43442 | J11: =SUM(K10) -> 31199 | K11: ='Water-Meter'!G13 -> 31213 | L11: =SUM(K11-J11) -> 14 | M11: =H11 -> 43442 | O11: =SUM(P10) -> 6220 | P11: ='Water-Meter'!J13 -> 6223 | Q11: =SUM(P11-O11) -> 3 | R11: =SUM(Q11/1615) -> 0.0018575851 | S11: =SUM(F11/Gen!T17) -> 0.056615385 | T11: =M11 -> 43442 | V11: =W10 -> 5773.8 | W11: 5776.4 | X11: =(W11-V11)*200 -> 520 | Y11: =T11 -> 43442 | AA11: =SUM(AB10) -> 15348 | AB11: ='Water-Meter'!P13 -> 15352 | AC11: =SUM(AB11-AA11) -> 4
A12: =Gen!B19 -> 0.4675 | B12: =Gen!A19 -> 43443 | D12: =E11 -> 6985.5 | E12: 6987.9 | F12: =SUM(E12-D12)*120 -> 288 | H12: =B12 -> 43443 | J12: =SUM(K11) -> 31213 | K12: ='Water-Meter'!G14 -> 31228 | L12: =SUM(K12-J12) -> 15 | M12: =H12 -> 43443 | O12: =SUM(P11) -> 6223 | P12: ='Water-Meter'!J14 -> 6226 | Q12: =SUM(P12-O12) -> 3 | R12: =SUM(Q12/1615) -> 0.0018575851 | S12: =SUM(F12/Gen!T18) -> 0.059987503 | T12: =M12 -> 43443 | V12: =W11 -> 5776.4 | W12: 5779.6 | X12: =(W12-V12)*200 -> 640 | Y12: =T12 -> 43443 | AA12: =SUM(AB11) -> 15352 | AB12: ='Water-Meter'!P14 -> 15361
A13: =Gen!B20 -> 0.5584 | B13: =Gen!A20 -> 43444 | D13: =E12 -> 6987.9 | E13: 6990.1 | F13: =SUM(E13-D13)*120 -> 264 | H13: =B13 -> 43444 | J13: =SUM(K12) -> 31228 | K13: ='Water-Meter'!G15 -> 31244 | L13: =SUM(K13-J13) -> 16 | M13: =H13 -> 43444 | O13: =SUM(P12) -> 6226 | P13: ='Water-Meter'!J15 -> 6235 | Q13: =SUM(P13-O13) -> 9 | R13: =SUM(Q13/1615) -> 0.0055727554 | S13: =SUM(F13/Gen!T19) -> 0.053778774 | T13: =M13 -> 43444 | V13: =W12 -> 5779.6 | W13: 5783.3 | X13: =(W13-V13)*200 -> 740 | Y13: =T13 -> 43444 | AA13: =SUM(AB12) -> 15361 | AB13: ='Water-Meter'!P15 -> 15382 | AC13: =SUM(AB13-AA13) -> 21
A14: =Gen!B21 -> 0.5714 | B14: =Gen!A21 -> 43445 | D14: =E13 -> 6990.1 | E14: 6992.4 | F14: =SUM(E14-D14)*120 -> 276 | H14: =B14 -> 43445 | J14: =SUM(K13) -> 31244 | K14: ='Water-Meter'!G16 -> 31259 | L14: =SUM(K14-J14) -> 15 | M14: =H14 -> 43445 | O14: =SUM(P13) -> 6235 | P14: ='Water-Meter'!J16 -> 6239 | Q14: =SUM(P14-O14) -> 4 | R14: =SUM(Q14/1615) -> 0.0024767802 | S14: =SUM(F14/Gen!T20) -> 0.051918736 | T14: =M14 -> 43445 | V14: =W13 -> 5783.3 | W14: 5787.7 | X14: =(W14-V14)*200 -> 880 | Y14: =T14 -> 43445 | AA14: =SUM(AB13) -> 15382 | AB14: ='Water-Meter'!P16 -> 15395 | AC14: =SUM(AB14-AA14) -> 13
A15: =Gen!B22 -> 0.2338 | B15: =Gen!A22 -> 43446 | D15: =E14 -> 6992.4 | E15: 6994.6 | F15: =SUM(E15-D15)*120 -> 264 | H15: =B15 -> 43446 | J15: =SUM(K14) -> 31259 | K15: ='Water-Meter'!G17 -> 31273 | L15: =SUM(K15-J15) -> 14 | M15: =H15 -> 43446 | O15: =SUM(P14) -> 6239 | P15: ='Water-Meter'!J17 -> 6244 | Q15: =SUM(P15-O15) -> 5 | R15: =SUM(Q15/1615) -> 0.0030959752 | S15: =SUM(F15/Gen!T21) -> 0.053636733 | T15: =M15 -> 43446 | V15: =W14 -> 5787.7 | W15: 5790.7 | X15: =(W15-V15)*200 -> 600 | Y15: =T15 -> 43446 | AA15: =SUM(AB14) -> 15395 | AB15: ='Water-Meter'!P17 -> 15410 | AC15: =SUM(AB15-AA15) -> 15
A16: =Gen!B23 -> 0.2727 | B16: =Gen!A23 -> 43447 | D16: =E15 -> 6994.6 | E16: 6996.9 | F16: =SUM(E16-D16)*120 -> 276 | H16: =B16 -> 43447 | J16: =SUM(K15) -> 31273 | K16: ='Water-Meter'!G18 -> 31288 | L16: =SUM(K16-J16) -> 15 | M16: =H16 -> 43447 | O16: =SUM(P15) -> 6244 | P16: ='Water-Meter'!J18 -> 6246 | Q16: =SUM(P16-O16) -> 2 | R16: =SUM(Q16/1615) -> 0.0012383901 | S16: =SUM(F16/Gen!T22) -> 0.056673511 | T16: =M16 -> 43447 | V16: =W15 -> 5790.7 | W16: 5793.6 | X16: =(W16-V16)*200 -> 580 | Y16: =T16 -> 43447 | AA16: =SUM(AB15) -> 15410 | AB16: ='Water-Meter'!P18 -> 15421 | AC16: =SUM(AB16-AA16) -> 11
A17: =Gen!B24 -> 0.2595 | B17: =Gen!A24 -> 43448 | D17: =E16 -> 6996.9 | E17: 6999.3 | F17: =SUM(E17-D17)*120 -> 288 | H17: =B17 -> 43448 | J17: =SUM(K16) -> 31288 | K17: ='Water-Meter'!G19 -> 31303 | L17: =SUM(K17-J17) -> 15 | M17: =H17 -> 43448 | O17: =SUM(P16) -> 6246 | P17: ='Water-Meter'!J19 -> 6249 | Q17: =SUM(P17-O17) -> 3 | R17: =SUM(Q17/1615) -> 0.0018575851 | S17: =SUM(F17/Gen!T23) -> 0.061802575 | T17: =M17 -> 43448 | V17: =W16 -> 5793.6 | W17: 5797.8 | X17: =(W17-V17)*200 -> 840 | Y17: =T17 -> 43448 | AA17: =SUM(AB16) -> 15421 | AB17: ='Water-Meter'!P19 -> 15442 | AC17: =SUM(AB17-AA17) -> 21
