Workbook

Sheet TOTAL
A1: Site Name | B1: Day | C1: Month | D1: Year | E1: Total Electricity Kwh | F1: Electricity Tariff ($/Kwh) | G1: LPG (Kg) | H1: LPG $/Kg | I1: District Energy Heating Kwh | J1: District Energy Heating $/Kwh | K1: Water Utility Supply (m3) m3 | L1: Water Utility Supply (m3) $/m3 | M1: Room Nights | N1: Total Guests | O1: Utilities day cost dh
A2: Marrakech | B2: 1 | C2: 12 | D2: 2019 | E2: ='Consommation du 01.12 au 31.12'!M10 -> 14042 | F2: 1.002 | G2: ='Consommation du 01.12 au 31.12'!U10 -> 333.9 | H2: 8.3673 | I2: ='Consommation du 01.12 au 31.12'!Y10*1000 -> 17830 | J2: 0.53 | K2: ='Consommation du 01.12 au 31.12'!D10 -> 500 | L2: 12.67 | M2: ='Consommation du 01.12 au 31.12'!AC10 -> 130 | N2: 249 | O2: =E2*F2+G2*H2+I2*J2+K2*L2 -> 32648.825
A3: Marrakech | B3: =B2+1 -> 2 | C3: 12 | D3: 2019 | E3: ='Consommation du 01.12 au 31.12'!M11 -> 13796 | F3: 1.002 | G3: ='Consommation du 01.12 au 31.12'!U11 -> 816.2 | H3: 8.3673 | I3: ='Consommation du 01.12 au 31.12'!Y11*1000 -> 16860 | J3: 0.53 | K3: ='Consommation du 01.12 au 31.12'!D11 -> 380 | L3: 12.67 | M3: ='Consommation du 01.12 au 31.12'!AC11 -> 106 | N3: 201 | O3: =E3*F3+G3*H3+I3*J3+K3*L3 -> 34403.382
A4: Marrakech | B4: =B3+1 -> 3 | C4: 12 | D4: 2019 | E4: ='Consommation du 01.12 au 31.12'!M12 -> 13691 | F4: 1.002 | G4: ='Consommation du 01.12 au 31.12'!U12 -> 927.5 | H4: 8.3673 | I4: ='Consommation du 01.12 au 31.12'!Y12*1000 -> 15520 | J4: 0.53 | K4: ='Consommation du 01.12 au 31.12'!D12 -> 380 | L4: 12.67 | M4: ='Consommation du 01.12 au 31.12'!AC12 -> 83 | N4: 161 | O4: =E4*F4+G4*H4+I4*J4+K4*L4 -> 34519.253
A5: Marrakech | B5: =B4+1 -> 4 | C5: 12 | D5: 2019 | E5: ='Consommation du 01.12 au 31.12'!M13 -> 13296 | F5: 1.002 | G5: ='Consommation du 01.12 au 31.12'!U13 -> 445.2 | H5: 8.3673 | I5: ='Consommation du 01.12 au 31.12'!Y13*1000 -> 16580 | J5: 0.53 | K5: ='Consommation du 01.12 au 31.12'!D13 -> 440 | L5: 12.67 | M5: ='Consommation du 01.12 au 31.12'!AC13 -> 37 | N5: 69 | O5: =E5*F5+G5*H5+I5*J5+K5*L5 -> 31409.914
A6: Marrakech | B6: =B5+1 -> 5 | C6: 12 | D6: 2019 | E6: ='Consommation du 01.12 au 31.12'!M14 -> 12704 | F6: 1.002 | G6: ='Consommation du 01.12 au 31.12'!U14 -> 1298.5 | H6: 8.3673 | I6: ='Consommation du 01.12 au 31.12'!Y14*1000 -> 11330 | J6: 0.53 | K6: ='Consommation du 01.12 au 31.12'!D14 -> 450 | L6: 12.67 | M6: ='Consommation du 01.12 au 31.12'!AC14 -> 55 | N6: 104 | O6: =E6*F6+G6*H6+I6*J6+K6*L6 -> 35300.747
A7: Marrakech | B7: =B6+1 -> 6 | C7: 12 | D7: 2019 | E7: ='Consommation du 01.12 au 31.12'!M15 -> 13452 | F7: 1.002 | G7: ='Consommation du 01.12 au 31.12'!U15 -> 1335.6 | H7: 8.3673 | I7: ='Consommation du 01.12 au 31.12'!Y15*1000 -> 7230 | J7: 0.53 | K7: ='Consommation du 01.12 au 31.12'!D15 -> 370 | L7: 12.67 | M7: ='Consommation du 01.12 au 31.12'!AC15 -> 67 | N7: 129 | O7: =E7*F7+G7*H7+I7*J7+K7*L7 -> 33174.07
A8: Marrakech | B8: =B7+1 -> 7 | C8: 12 | D8: 2019 | E8: ='Consommation du 01.12 au 31.12'!M16 -> 13108 | F8: 1.002 | G8: ='Consommation du 01.12 au 31.12'!U16 -> 556.5 | H8: 8.3673 | I8: ='Consommation du 01.12 au 31.12'!Y16*1000 -> 17710 | J8: 0.53 | K8: ='Consommation du 01.12 au 31.12'!D16 -> 380 | L8: 12.67 | M8: ='Consommation du 01.12 au 31.12'!AC16 -> 65 | N8: 128 | O8: =E8*F8+G8*H8+I8*J8+K8*L8 -> 31991.518
A9: Marrakech | B9: =B8+1 -> 8 | C9: 12 | D9: 2019 | E9: ='Consommation du 01.12 au 31.12'!M17 -> 12885 | F9: 1.002 | G9: ='Consommation du 01.12 au 31.12'!U17 -> 742 | H9: 8.3673 | I9: ='Consommation du 01.12 au 31.12'!Y17*1000 -> 18850 | J9: 0.53 | K9: ='Consommation du 01.12 au 31.12'!D17 -> 380 | L9: 12.67 | M9: ='Consommation du 01.12 au 31.12'!AC17 -> 57 | N9: 106 | O9: =E9*F9+G9*H9+I9*J9+K9*L9 -> 33924.407
A10: Marrakech | B10: =B9+1 -> 9 | C10: 12 | D10: 2019 | E10: ='Consommation du 01.12 au 31.12'!M18 -> 13441 | F10: 1.002 | G10: ='Consommation du 01.12 au 31.12'!U18 -> 593.6 | H10: 8.3673 | I10: ='Consommation du 01.12 au 31.12'!Y18*1000 -> 15920 | J10: 0.53 | K10: ='Consommation du 01.12 au 31.12'!D18 -> 450 | L10: 12.67 | M10: ='Consommation du 01.12 au 31.12'!AC18 -> 70 | N10: 114 | O10: =E10*F10+G10*H10+I10*J10+K10*L10 -> 32573.811
A11: Marrakech | B11: =B10+1 -> 10 | C11: 12 | D11: 2019 | E11: ='Consommation du 01.12 au 31.12'!M19 -> 13544 | F11: 1.002 | G11: ='Consommation du 01.12 au 31.12'!U19 -> 1261.4 | H11: 8.3673 | I11: ='Consommation du 01.12 au 31.12'!Y19*1000 -> 12460 | J11: 0.53 | K11: ='Consommation du 01.12 au 31.12'!D19 -> 400 | L11: 12.67 | M11: ='Consommation du 01.12 au 31.12'!AC19 -> 90 | N11: 130 | O11: =E11*F11+G11*H11+I11*J11+K11*L11 -> 35797.4
A12: Marrakech | B12: =B11+1 -> 11 | C12: 12 | D12: 2019 | E12: ='Consommation du 01.12 au 31.12'!M20 -> 14330 | F12: 1.002 | G12: ='Consommation du 01.12 au 31.12'!U20 -> 1113 | H12: 8.3673 | I12: ='Consommation du 01.12 au 31.12'!Y20*1000 -> 11460 | J12: 0.53 | K12: ='Consommation du 01.12 au 31.12'!D20 -> 440 | L12: 12.67 | M12: ='Consommation du 01.12 au 31.12'!AC20 -> 106 | N12: 152 | O12: =E12*F12+G12*H12+I12*J12+K12*L12 -> 35320.065
A13: Marrakech | B13: =B12+1 -> 12 | C13: 12 | D13: 2019 | E13: ='Consommation du 01.12 au 31.12'!M21 -> 14499 | F13: 1.002 | G13: ='Consommation du 01.12 au 31.12'!U21 -> 853.3 | H13: 8.3673 | I13: ='Consommation du 01.12 au 31.12'!Y21*1000 -> 15980 | J13: 0.53 | K13: ='Consommation du 01.12 au 31.12'!D21 -> 470 | L13: 12.67 | M13: ='Consommation du 01.12 au 31.12'!AC21 -> 79 | N13: 122 | O13: =E13*F13+G13*H13+I13*J13+K13*L13 -> 36092.115
A14: Marrakech | B14: =B13+1 -> 13 | C14: 12 | D14: 2019 | E14: ='Consommation du 01.12 au 31.12'!M22 -> 14718 | F14: 1.002 | G14: ='Consommation du 01.12 au 31.12'!U22 -> 148.4 | H14: 8.3673 | I14: ='Consommation du 01.12 au 31.12'!Y22*1000 -> 16850 | J14: 0.53 | K14: ='Consommation du 01.12 au 31.12'!D22 -> 410 | L14: 12.67 | M14: ='Consommation du 01.12 au 31.12'!AC22 -> 78 | N14: 136 | O14: =E14*F14+G14*H14+I14*J14+K14*L14 -> 30114.343
... A20: Marrakech | B20: =B19+1 -> 19 | C20: 12 | D20: 2019 | E20: ='Consommation du 01.12 au 31.12'!M28 -> 13187 | F20: 1.002 | G20: ='Consommation du 01.12 au 31.12'!U28 -> 1075.9 | H20: 8.3673 | I20: ='Consommation du 01.12 au 31.12'!Y28*1000 -> 15340 | J20: 0.53 | K20: ='Consommation du 01.12 au 31.12'!D28 -> 400 | L20: 12.67 | M20: ='Consommation du 01.12 au 31.12'!AC28 -> 62 | N20: 132 | O20: =E20*F20+G20*H20+I20*J20+K20*L20 -> 35413.952
A21: Marrakech | B21: =B20+1 -> 20 | C21: 12 | D21: 2019 | E21: ='Consommation du 01.12 au 31.12'!M29 -> 0 | F21: 1.002 | G21: ='Consommation du 01.12 au 31.12'!U29 -> 0 | H21: 8.3673 | I21: ='Consommation du 01.12 au 31.12'!Y29*1000 -> 0 | J21: 0.53 | K21: ='Consommation du 01.12 au 31.12'!D29 -> 0 | L21: 12.67 | M21: ='Consommation du 01.12 au 31.12'!AC29 -> 0 | O21: =E21*F21+G21*H21+I21*J21+K21*L21 -> 0
A22: Marrakech | B22: =B21+1 -> 21 | C22: 12 | D22: 2019 | E22: ='Consommation du 01.12 au 31.12'!M30 -> 0 | F22: 1.002 | G22: ='Consommation du 01.12 au 31.12'!U30 -> 0 | H22: 8.3673 | I22: ='Consommation du 01.12 au 31.12'!Y30*1000 -> 0 | J22: 0.53 | K22: ='Consommation du 01.12 au 31.12'!D30 -> 0 | L22: 12.67 | M22: ='Consommation du 01.12 au 31.12'!AC30 -> 0 | O22: =E22*F22+G22*H22+I22*J22+K22*L22 -> 0
A23: Marrakech | B23: =B22+1 -> 22 | C23: 12 | D23: 2019 | E23: ='Consommation du 01.12 au 31.12'!M31 -> 0 | F23: 1.002 | G23: ='Consommation du 01.12 au 31.12'!U31 -> 0 | H23: 8.3673 | I23: ='Consommation du 01.12 au 31.12'!Y31*1000 -> 0 | J23: 0.53 | K23: ='Consommation du 01.12 au 31.12'!D31 -> 0 | L23: 12.67 | M23: ='Consommation du 01.12 au 31.12'!AC31 -> 0 | O23: =E23*F23+G23*H23+I23*J23+K23*L23 -> 0
A24: Marrakech | B24: =B23+1 -> 23 | C24: 12 | D24: 2019 | E24: ='Consommation du 01.12 au 31.12'!M32 -> 0 | F24: 1.002 | G24: ='Consommation du 01.12 au 31.12'!U32 -> 0 | H24: 8.3673 | I24: ='Consommation du 01.12 au 31.12'!Y32*1000 -> 0 | J24: 0.53 | K24: ='Consommation du 01.12 au 31.12'!D32 -> 0 | L24: 12.67 | M24: ='Consommation du 01.12 au 31.12'!AC32 -> 0 | O24: =E24*F24+G24*H24+I24*J24+K24*L24 -> 0
A25: Marrakech | B25: =B24+1 -> 24 | C25: 12 | D25: 2019 | E25: ='Consommation du 01.12 au 31.12'!M33 -> 0 | F25: 1.002 | G25: ='Consommation du 01.12 au 31.12'!U33 -> 0 | H25: 8.3673 | I25: ='Consommation du 01.12 au 31.12'!Y33*1000 -> 0 | J25: 0.53 | K25: ='Consommation du 01.12 au 31.12'!D33 -> 0 | L25: 12.67 | M25: ='Consommation du 01.12 au 31.12'!AC33 -> 0 | O25: =E25*F25+G25*H25+I25*J25+K25*L25 -> 0
A26: Marrakech | B26: =B25+1 -> 25 | C26: 12 | D26: 2019 | E26: ='Consommation du 01.12 au 31.12'!M34 -> 0 | F26: 1.002 | G26: ='Consommation du 01.12 au 31.12'!U34 -> 0 | H26: 8.3673 | I26: ='Consommation du 01.12 au 31.12'!Y34*1000 -> 0 | J26: 0.53 | K26: ='Consommation du 01.12 au 31.12'!D34 -> 0 | L26: 12.67 | M26: ='Consommation du 01.12 au 31.12'!AC34 -> 0 | O26: =E26*F26+G26*H26+I26*J26+K26*L26 -> 0
A27: Marrakech | B27: =B26+1 -> 26 | C27: 12 | D27: 2019 | E27: ='Consommation du 01.12 au 31.12'!M35 -> 0 | F27: 1.002 | G27: ='Consommation du 01.12 au 31.12'!U35 -> 0 | H27: 8.3673 | I27: ='Consommation du 01.12 au 31.12'!Y35*1000 -> 0 | J27: 0.53 | K27: ='Consommation du 01.12 au 31.12'!D35 -> 0 | L27: 12.67 | M27: ='Consommation du 01.12 au 31.12'!AC35 -> 0 | O27: =E27*F27+G27*H27+I27*J27+K27*L27 -> 0
A28: Marrakech | B28: =B27+1 -> 27 | C28: 12 | D28: 2019 | E28: ='Consommation du 01.12 au 31.12'!M36 -> 0 | F28: 1.002 | G28: ='Consommation du 01.12 au 31.12'!U36 -> 0 | H28: 8.3673 | I28: ='Consommation du 01.12 au 31.12'!Y36*1000 -> 0 | J28: 0.53 | K28: ='Consommation du 01.12 au 31.12'!D36 -> 0 | L28: 12.67 | M28: ='Consommation du 01.12 au 31.12'!AC36 -> 0 | O28: =E28*F28+G28*H28+I28*J28+K28*L28 -> 0
A29: Marrakech | B29: =B28+1 -> 28 | C29: 12 | D29: 2019 | E29: ='Consommation du 01.12 au 31.12'!M37 -> 0 | F29: 1.002 | G29: ='Consommation du 01.12 au 31.12'!U37 -> 0 | H29: 8.3673 | I29: ='Consommation du 01.12 au 31.12'!Y37*1000 -> 0 | J29: 0.53 | K29: ='Consommation du 01.12 au 31.12'!D37 -> 0 | L29: 12.67 | M29: ='Consommation du 01.12 au 31.12'!AC37 -> 0 | O29: =E29*F29+G29*H29+I29*J29+K29*L29 -> 0
A30: Marrakech | B30: =B29+1 -> 29 | C30: 12 | D30: 2019 | E30: ='Consommation du 01.12 au 31.12'!M38 -> 0 | F30: 1.002 | G30: ='Consommation du 01.12 au 31.12'!U38 -> 0 | H30: 8.3673 | I30: ='Consommation du 01.12 au 31.12'!Y38*1000 -> 0 | J30: 0.53 | K30: ='Consommation du 01.12 au 31.12'!D38 -> 0 | L30: 12.67 | M30: ='Consommation du 01.12 au 31.12'!AC38 -> 0
A31: Marrakech | B31: =B30+1 -> 30 | C31: 12 | D31: 2019 | E31: ='Consommation du 01.12 au 31.12'!M39 -> 0 | F31: 1.002 | G31: ='Consommation du 01.12 au 31.12'!U39 -> 0 | H31: 8.3673 | I31: ='Consommation du 01.12 au 31.12'!Y39*1000 -> 0 | J31: 0.53 | K31: ='Consommation du 01.12 au 31.12'!D39 -> 0 | L31: 12.67 | M31: ='Consommation du 01.12 au 31.12'!AC39 -> 0
A32: Marrakech | B32: =B31+1 -> 31 | C32: 12 | D32: 2019 | E32: ='Consommation du 01.12 au 31.12'!M40 -> 0 | F32: 1 | G32: ='Consommation du 01.12 au 31.12'!U40 -> 0 | H32: 8.3673 | I32: ='Consommation du 01.12 au 31.12'!Y40*1000 -> 0 | J32: 0.53 | K32: ='Consommation du 01.12 au 31.12'!D40 -> 0 | L32: 12.67 | M32: ='Consommation du 01.12 au 31.12'!AC40 -> 0

Sheet Consommation du 01.12 au 31.12
B8: Date | D8: Cons Eau/Hotel | F8: Consommation du jour en DH | J8: ELECTRICITE en KWH | M8: total | O8: Consommation du jour en DH | Q8: Cons Elec/Villa | S8: Cons Elec/RIAD | U8: GAZ en Kg | W8: Consommation du jour en DH | AB8: Temp moyenne du jour °C | AC8: Room Nights | AD8: % Occupation | AE8: Temp Piscine Adulte à 7h00 °C | AF8: Temp Piscine Adulte à 15h00 °C | AG8: Temp Piscine famille à 07h00 ° C | AH8: Temp Piscine famille à 15h00 ° C
J9: creuse 81 | K9: pleine 82 | L9: pointe 83 | X9: Compteur AVEO Mwh | Y9: consommation eau choud en Mwh | Z9: consommation du jour en DH
B10: 43800 | D10: ='Suivi EAU-ELEC'!C15 -> 500 | F10: =D10*12.67 -> 6335 | J10: ='Suivi EAU-ELEC'!E15 -> 4473 | K10: ='Suivi EAU-ELEC'!G15 -> 6523 | L10: ='Suivi EAU-ELEC'!I15 -> 3046 | M10: =L10+K10+J10 -> 14042 | O10: =M10*1.002 -> 14070.084 | U10: ='Suvi Gaz'!O10 -> 333.9 | W10: =U10*8.3673 -> 2793.8415 | X10: 15540.78 | Y10: =IF(X11<X10,0,X11-X10) -> 17.83 | Z10: =Y10*0.53*1000 -> 9449.9 | AB10: 22 | AC10: 130 | AD10: 0.9848 | AE10: 28 | AF10: 29 | AG10: 28.6 | AH10: 29
B11: =B10+1 -> 43801 | D11: ='Suivi EAU-ELEC'!C16 -> 380 | F11: =D11*12.67 -> 4814.6 | J11: ='Suivi EAU-ELEC'!E16 -> 4297 | K11: ='Suivi EAU-ELEC'!G16 -> 6427 | L11: ='Suivi EAU-ELEC'!I16 -> 3072 | M11: =L11+K11+J11 -> 13796 | O11: =M11*1.002 -> 13823.592 | U11: ='Suvi Gaz'!O11 -> 816.2 | W11: =U11*8.3673 -> 6829.3903 | X11: 15558.61 | Y11: =IF(X12<X11,0,X12-X11) -> 16.86 | Z11: =Y11*0.53*1000 -> 8935.8 | AB11: 22 | AC11: 106 | AD11: 0.8346 | AE11: 27.5 | AF11: 28 | AG11: 27.6 | AH11: 28
B12: =B11+1 -> 43802 | D12: ='Suivi EAU-ELEC'!C17 -> 380 | F12: =D12*12.67 -> 4814.6 | J12: ='Suivi EAU-ELEC'!E17 -> 4166 | K12: ='Suivi EAU-ELEC'!G17 -> 6581 | L12: ='Suivi EAU-ELEC'!I17 -> 2944 | M12: =L12+K12+J12 -> 13691 | O12: =M12*1.002 -> 13718.382 | U12: ='Suvi Gaz'!O12 -> 927.5 | W12: =U12*8.3673 -> 7760.6708 | X12: 15575.47 | Y12: =IF(X13<X12,0,X13-X12) -> 15.52 | Z12: =Y12*0.53*1000 -> 8225.6 | AB12: 22 | AC12: 83 | AD12: 0.6288 | AE12: 27 | AF12: 28 | AG12: 27 | AH12: 28
B13: =B12+1 -> 43803 | D13: ='Suivi EAU-ELEC'!C18 -> 440 | F13: =D13*12.67 -> 5574.8 | J13: ='Suivi EAU-ELEC'!E18 -> 4200 | K13: ='Suivi EAU-ELEC'!G18 -> 6277 | L13: ='Suivi EAU-ELEC'!I18 -> 2819 | M13: =L13+K13+J13 -> 13296 | O13: =M13*1.002 -> 13322.592 | U13: ='Suvi Gaz'!O13 -> 445.2 | W13: =U13*8.3673 -> 3725.122 | X13: 15590.99 | Y13: =IF(X14<X13,0,X14-X13) -> 16.58 | Z13: =Y13*0.53*1000 -> 8787.4 | AB13: 15 | AC13: 37 | AD13: 0.3109 | AE13: 26.7 | AF13: 28 | AG13: 26.8 | AH13: 28
B14: =B13+1 -> 43804 | D14: ='Suivi EAU-ELEC'!C19 -> 450 | F14: =D14*12.67 -> 5701.5 | J14: ='Suivi EAU-ELEC'!E19 -> 3869 | K14: ='Suivi EAU-ELEC'!G19 -> 6022 | L14: ='Suivi EAU-ELEC'!I19 -> 2813 | M14: =L14+K14+J14 -> 12704 | O14: =M14*1.002 -> 12729.408 | U14: ='Suvi Gaz'!O14 -> 1298.5 | W14: =U14*8.3673 -> 10864.939 | X14: 15607.57 | Y14: =IF(X15<X14,0,X15-X14) -> 11.33 | Z14: =Y14*0.53*1000 -> 6004.9 | AB14: 16 | AC14: 55 | AD14: 0.4297 | AE14: 26.2 | AF14: 27 | AG14: 26.2 | AH14: 27
B15: =B14+1 -> 43805 | D15: ='Suivi EAU-ELEC'!C20 -> 370 | F15: =D15*12.67 -> 4687.9 | J15: ='Suivi EAU-ELEC'!E20 -> 3891 | K15: ='Suivi EAU-ELEC'!G20 -> 6732 | L15: ='Suivi EAU-ELEC'!I20 -> 2829 | M15: =L15+K15+J15 -> 13452 | O15: =M15*1.002 -> 13478.904 | U15: ='Suvi Gaz'!O15 -> 1335.6 | W15: =U15*8.3673 -> 11175.366 | X15: 15618.9 | Y15: =IF(X16<X15,0,X16-X15) -> 7.23 | Z15: =Y15*0.53*1000 -> 3831.9 | AB15: 15 | AC15: 67 | AD15: 0.5038 | AE15: 27 | AF15: 28 | AG15: 28 | AH15: 28.5
B16: =B15+1 -> 43806 | D16: ='Suivi EAU-ELEC'!C21 -> 380 | F16: =D16*12.67 -> 4814.6 | J16: ='Suivi EAU-ELEC'!E21 -> 3996 | K16: ='Suivi EAU-ELEC'!G21 -> 6185 | L16: ='Suivi EAU-ELEC'!I21 -> 2927 | M16: =L16+K16+J16 -> 13108 | O16: =M16*1.002 -> 13134.216 | U16: ='Suvi Gaz'!O16 -> 556.5 | W16: =U16*8.3673 -> 4656.4025 | X16: 15626.13 | Y16: =IF(X17<X16,0,X17-X16) -> 17.71 | Z16: =Y16*0.53*1000 -> 9386.3 | AB16: 16 | AC16: 65 | AD16: 0.5118 | AE16: 28 | AF16: 28 | AG16: 28.8 | AH16: 29
B17: =B16+1 -> 43807 | D17: ='Suivi EAU-ELEC'!C22 -> 380 | F17: =D17*12.67 -> 4814.6 | J17: ='Suivi EAU-ELEC'!E22 -> 4022 | K17: ='Suivi EAU-ELEC'!G22 -> 6025 | L17: ='Suivi EAU-ELEC'!I22 -> 2838 | M17: =L17+K17+J17 -> 12885 | O17: =M17*1.002 -> 12910.77 | U17: ='Suvi Gaz'!O17 -> 742 | W17: =U17*8.3673 -> 6208.5366 | X17: 15643.84 | Y17: =IF(X18<X17,0,X18-X17) -> 18.85 | Z17: =Y17*0.53*1000 -> 9990.5 | AB17: 16 | AC17: 57 | AD17: 0.4351 | AE17: 28 | AF17: 29 | AG17: 28.6 | AH17: 29
B18: =B17+1 -> 43808 | D18: ='Suivi EAU-ELEC'!C23 -> 450 | F18: =D18*12.67 -> 5701.5 | J18: ='Suivi EAU-ELEC'!E23 -> 4155 | K18: ='Suivi EAU-ELEC'!G23 -> 6276 | L18: ='Suivi EAU-ELEC'!I23 -> 3010 | M18: =L18+K18+J18 -> 13441 | O18: =M18*1.002 -> 13467.882 | U18: ='Suvi Gaz'!O18 -> 593.6 | W18: =U18*8.3673 -> 4966.8293 | X18: 15662.69 | Y18: =IF(X19<X18,0,X19-X18) -> 15.92 | Z18: =Y18*0.53*1000 -> 8437.6 | AB18: 17 | AC18: 70 | AD18: 0.5469 | AE18: 27.8 | AF18: 29 | AG18: 27.8 | AH18: 29
B19: =B18+1 -> 43809 | D19: ='Suivi EAU-ELEC'!C24 -> 400 | F19: =D19*12.67 -> 5068 | J19: ='Suivi EAU-ELEC'!E24 -> 4166 | K19: ='Suivi EAU-ELEC'!G24 -> 6425 | L19: ='Suivi EAU-ELEC'!I24 -> 2953 | M19: =L19+K19+J19 -> 13544 | O19: =M19*1.002 -> 13571.088 | U19: ='Suvi Gaz'!O19 -> 1261.4 | W19: =U19*8.3673 -> 10554.512 | X19: 15678.61 | Y19: =IF(X20<X19,0,X20-X19) -> 12.46 | Z19: =Y19*0.53*1000 -> 6603.8 | AB19: 18 | AC19: 90 | AD19: 0.7031 | AE19: 27.5 | AF19: 28 | AG19: 27.5 | AH19: 28
B20: =B19+1 -> 43810 | D20: ='Suivi EAU-ELEC'!C25 -> 440 | F20: =D20*12.67 -> 5574.8 | J20: ='Suivi EAU-ELEC'!E25 -> 4717 | K20: ='Suivi EAU-ELEC'!G25 -> 6392 | L20: ='Suivi EAU-ELEC'!I25 -> 3221 | M20: =L20+K20+J20 -> 14330 | O20: =M20*1.002 -> 14358.66 | U20: ='Suvi Gaz'!O20 -> 1113 | W20: =U20*8.3673 -> 9312.8049 | X20: 15691.07 | Y20: =IF(X21<X20,0,X21-X20) -> 11.46 | Z20: =Y20*0.53*1000 -> 6073.8 | AA20: 14 | AB20: 18 | AC20: 106 | AD20: 0.8281 | AE20: 27.6 | AF20: 28 | AG20: 27.5 | AH20: 28
B21: =B20+1 -> 43811 | D21: ='Suivi EAU-ELEC'!C26 -> 470 | F21: =D21*12.67 -> 5954.9 | J21: ='Suivi EAU-ELEC'!E26 -> 4350 | K21: ='Suivi EAU-ELEC'!G26 -> 6907 | L21: ='Suivi EAU-ELEC'!I26 -> 3242 | M21: =L21+K21+J21 -> 14499 | O21: =M21*1.002 -> 14527.998 | U21: ='Suvi Gaz'!O21 -> 853.3 | W21: =U21*8.3673 -> 7139.8171 | X21: 15702.53 | Y21: =IF(X22<X21,0,X22-X21) -> 15.98 | Z21: =Y21*0.53*1000 -> 8469.4 | AA21: 14 | AB21: 16 | AC21: 79 | AD21: 0.6423 | AE21: 27.8 | AF21: 28 | AG21: 27.8 | AH21: 28
B22: =B21+1 -> 43812 | D22: ='Suivi EAU-ELEC'!C27 -> 410 | F22: =D22*12.67 -> 5194.7 | J22: ='Suivi EAU-ELEC'!E27 -> 4884 | K22: ='Suivi EAU-ELEC'!G27 -> 6348 | L22: ='Suivi EAU-ELEC'!I27 -> 3486 | M22: =L22+K22+J22 -> 14718 | O22: =M22*1.002 -> 14747.436 | U22: ='Suvi Gaz'!O22 -> 148.4 | W22: =U22*8.3673 -> 1241.7073 | X22: 15718.51 | Y22: =IF(X23<X22,0,X23-X22) -> 16.85 | Z22: =Y22*0.53*1000 -> 8930.5 | AB22: 21 | AC22: 78 | AD22: 0.5865 | AE22: 27.6 | AF22: 28 | AG22: 27.2 | AH22: 28
B23: =B22+1 -> 43813 | D23: ='Suivi EAU-ELEC'!C28 -> 490 | F23: =D23*12.67 -> 6208.3 | J23: ='Suivi EAU-ELEC'!E28 -> 4095 | K23: ='Suivi EAU-ELEC'!G28 -> 5927 | L23: ='Suivi EAU-ELEC'!I28 -> 2954 | M23: =L23+K23+J23 -> 12976 | O23: =M23*1.002 -> 13001.952 | U23: ='Suvi Gaz'!O23 -> 1001.7 | W23: =U23*8.3673 -> 8381.5244 | X23: 15735.36 | Y23: =IF(X24<X23,0,X24-X23) -> 14.62 | Z23: =Y23*0.53*1000 -> 7748.6 | AB23: 19 | AC23: 75 | AD23: 0.5474 | AE23: 27.3 | AF23: 28 | AG23: 27.6 | AH23: 28
B24: =B23+1 -> 43814 | D24: ='Suivi EAU-ELEC'!C29 -> 500 | F24: =D24*12.67 -> 6335 | J24: ='Suivi EAU-ELEC'!E29 -> 3903 | K24: ='Suivi EAU-ELEC'!G29 -> 6043 | L24: ='Suivi EAU-ELEC'!I29 -> 2713 | M24: =L24+K24+J24 -> 12659 | O24: =M24*1.002 -> 12684.318 | U24: ='Suvi Gaz'!O24 -> 964.6 | W24: =U24*8.3673 -> 8071.0976 | X24: 15749.98 | Y24: =IF(X25<X24,0,X25-X24) -> 16.66 | Z24: =Y24*0.53*1000 -> 8829.8 | AB24: 19 | AC24: 79 | AD24: 0.5852 | AE24: 27.5 | AF24: 28 | AG24: 27.5 | AH24: 28
B25: =B24+1 -> 43815 | D25: ='Suivi EAU-ELEC'!C30 -> 400 | F25: =D25*12.67 -> 5068 | J25: ='Suivi EAU-ELEC'!E30 -> 4579 | K25: ='Suivi EAU-ELEC'!G30 -> 6190 | L25: ='Suivi EAU-ELEC'!I30 -> 3137 | M25: =L25+K25+J25 -> 13906 | O25: =M25*1.002 -> 13933.812 | U25: ='Suvi Gaz'!O25 -> 779.1 | W25: =U25*8.3673 -> 6518.9634 | X25: 15766.64 | Y25: =IF(X26<X25,0,X26-X25) -> 14.86 | Z25: =Y25*0.53*1000 -> 7875.8 | AB25: 21 | AC25: 63 | AD25: 0.4846 | AE25: 27 | AF25: 28 | AG25: 28 | AH25: 29
B26: =B25+1 -> 43816 | D26: ='Suivi EAU-ELEC'!C31 -> 420 | F26: =D26*12.67 -> 5321.4 | J26: ='Suivi EAU-ELEC'!E31 -> 3071 | K26: ='Suivi EAU-ELEC'!G31 -> 6411 | L26: ='Suivi EAU-ELEC'!I31 -> 3087 | M26: =L26+K26+J26 -> 12569 | O26: =M26*1.002 -> 12594.138 | U26: ='Suvi Gaz'!O26 -> 1150.1 | W26: =U26*8.3673 -> 9623.2317 | X26: 15781.5 | Y26: =IF(X27<X26,0,X27-X26) -> 8.83 | Z26: =Y26*0.53*1000 -> 4679.9 | AB26: 11 | AC26: 47 | AD26: 0.3534 | AE26: 25.8 | AF26: 26 | AG26: 25.8 | AH26: 29
B27: =B26+1 -> 43817 | D27: ='Suivi EAU-ELEC'!C32 -> 540 | F27: =D27*12.67 -> 6841.8 | J27: ='Suivi EAU-ELEC'!E32 -> 4123 | K27: ='Suivi EAU-ELEC'!G32 -> 6230 | L27: ='Suivi EAU-ELEC'!I32 -> 2788 | M27: =L27+K27+J27 -> 13141 | O27: =M27*1.002 -> 13167.282 | U27: ='Suvi Gaz'!O27 -> 1595.3 | W27: =U27*8.3673 -> 13348.354 | X27: 15790.33 | Y27: =IF(X28<X27,0,X28-X27) -> 11.17 | Z27: =Y27*0.53*1000 -> 5920.1 | AB27: 15 | AC27: 57 | AD27: 0.4161 | AE27: 25.8 | AF27: 26 | AG27: 26 | AH27: 26
B28: =B27+1 -> 43818 | D28: ='Suivi EAU-ELEC'!C33 -> 400 | F28: =D28*12.67 -> 5068 | J28: ='Suivi EAU-ELEC'!E33 -> 4185 | K28: ='Suivi EAU-ELEC'!G33 -> 6102 | L28: ='Suivi EAU-ELEC'!I33 -> 2900 | M28: =L28+K28+J28 -> 13187 | O28: =M28*1.002 -> 13213.374 | U28: ='Suvi Gaz'!O28 -> 1075.9 | W28: =U28*8.3673 -> 9002.3781 | X28: 15801.5 | Y28: =IF(X29<X28,0,X29-X28) -> 15.34 | Z28: =Y28*0.53*1000 -> 8130.2 | AB28: 18 | AC28: 62 | AD28: 0.4593 | AE28: 26.4 | AF28: 27 | AG28: 26.5 | AH28: 27
B29: =B28+1 -> 43819 | D29: ='Suivi EAU-ELEC'!C34 -> 0 | F29: =D29*12.67 -> 0 | J29: ='Suivi EAU-ELEC'!E34 -> 0 | K29: ='Suivi EAU-ELEC'!G34 -> 0 | L29: ='Suivi EAU-ELEC'!I34 -> 0 | M29: =L29+K29+J29 -> 0 | O29: =M29*1.002 -> 0 | U29: ='Suvi Gaz'!O29 -> 0 | W29: =U29*8.3673 -> 0 | X29: 15816.84 | Y29: =IF(X30<X29,0,X30-X29) -> 0 | Z29: =Y29*0.53*1000 -> 0
B30: =B29+1 -> 43820 | D30: ='Suivi EAU-ELEC'!C35 -> 0 | F30: =D30*12.67 -> 0 | J30: ='Suivi EAU-ELEC'!E35 -> 0 | K30: ='Suivi EAU-ELEC'!G35 -> 0 | L30: ='Suivi EAU-ELEC'!I35 -> 0 | M30: =L30+K30+J30 -> 0 | O30: =M30*1.002 -> 0 | U30: ='Suvi Gaz'!O30 -> 0 | W30: =U30*8.3673 -> 0 | Y30: =IF(X31<X30,0,X31-X30) -> 0 | Z30: =Y30*0.53*1000 -> 0
B31: =B30+1 -> 43821 | D31: ='Suivi EAU-ELEC'!C36 -> 0 | F31: =D31*12.67 -> 0 | J31: ='Suivi EAU-ELEC'!E36 -> 0 | K31: ='Suivi EAU-ELEC'!G36 -> 0 | L31: ='Suivi EAU-ELEC'!I36 -> 0 | M31: =L31+K31+J31 -> 0 | O31: =M31*1.002 -> 0 | U31: ='Suvi Gaz'!O31 -> 0 | W31: =U31*8.3673 -> 0 | Y31: =IF(X32<X31,0,X32-X31) -> 0 | Z31: =Y31*0.53*1000 -> 0
B32: =B31+1 -> 43822 | D32: ='Suivi EAU-ELEC'!C37 -> 0 | F32: =D32*12.67 -> 0 | J32: ='Suivi EAU-ELEC'!E37 -> 0 | K32: ='Suivi EAU-ELEC'!G37 -> 0 | L32: ='Suivi EAU-ELEC'!I37 -> 0 | M32: =L32+K32+J32 -> 0 | O32: =M32*1.002 -> 0 | U32: ='Suvi Gaz'!O32 -> 0 | W32: =U32*8.3673 -> 0 | Y32: =IF(X33<X32,0,X33-X32) -> 0 | Z32: =Y32*0.53*1000 -> 0
B33: =B32+1 -> 43823 | D33: ='Suivi EAU-ELEC'!C38 -> 0 | F33: =D33*12.67 -> 0 | J33: ='Suivi EAU-ELEC'!E38 -> 0 | K33: ='Suivi EAU-ELEC'!G38 -> 0 | L33: ='Suivi EAU-ELEC'!I38 -> 0 | M33: =L33+K33+J33 -> 0 | O33: =M33*1.002 -> 0 | U33: ='Suvi Gaz'!O33 -> 0 | W33: =U33*8.3673 -> 0 | Y33: =IF(X34<X33,0,X34-X33) -> 0 | Z33: =Y33*0.53*1000 -> 0
B34: =B33+1 -> 43824 | D34: ='Suivi EAU-ELEC'!C39 -> 0 | F34: =D34*12.67 -> 0 | J34: ='Suivi EAU-ELEC'!E39 -> 0 | K34: ='Suivi EAU-ELEC'!G39 -> 0 | L34: ='Suivi EAU-ELEC'!I39 -> 0 | M34: =L34+K34+J34 -> 0 | O34: =M34*1.002 -> 0 | U34: ='Suvi Gaz'!O34 -> 0 | W34: =U34*8.3673 -> 0 | Y34: =IF(X35<X34,0,X35-X34) -> 0 | Z34: =Y34*0.53*1000 -> 0
B35: =B34+1 -> 43825 | D35: ='Suivi EAU-ELEC'!C40 -> 0 | F35: =D35*12.67 -> 0 | J35: ='Suivi EAU-ELEC'!E40 -> 0 | K35: ='Suivi EAU-ELEC'!G40 -> 0 | L35: ='Suivi EAU-ELEC'!I40 -> 0 | M35: =L35+K35+J35 -> 0 | O35: =M35*1.002 -> 0 | U35: ='Suvi Gaz'!O35 -> 0 | W35: =U35*8.3673 -> 0 | Y35: =IF(X36<X35,0,X36-X35) -> 0 | Z35: =Y35*0.53*1000 -> 0
B36: =B35+1 -> 43826 | D36: ='Suivi EAU-ELEC'!C41 -> 0 | F36: =D36*12.67 -> 0 | J36: ='Suivi EAU-ELEC'!E41 -> 0 | K36: ='Suivi EAU-ELEC'!G41 -> 0 | L36: ='Suivi EAU-ELEC'!I41 -> 0 | M36: =L36+K36+J36 -> 0 | O36: =M36*1.002 -> 0 | U36: ='Suvi Gaz'!O36 -> 0 | W36: =U36*8.3673 -> 0 | Y36: =IF(X37<X36,0,X37-X36) -> 0 | Z36: =Y36*0.53*1000 -> 0
B37: =B36+1 -> 43827 | D37: ='Suivi EAU-ELEC'!C42 -> 0 | F37: =D37*12.67 -> 0 | J37: ='Suivi EAU-ELEC'!E42 -> 0 | K37: ='Suivi EAU-ELEC'!G42 -> 0 | L37: ='Suivi EAU-ELEC'!I42 -> 0 | M37: =L37+K37+J37 -> 0 | O37: =M37*1.002 -> 0 | U37: ='Suvi Gaz'!O37 -> 0 | W37: =U37*8.3673 -> 0 | Y37: =IF(X38<X37,0,X38-X37) -> 0 | Z37: =Y37*0.53*1000 -> 0
B38: =B37+1 -> 43828 | D38: ='Suivi EAU-ELEC'!C43 -> 0 | F38: =D38*12.67 -> 0 | J38: ='Suivi EAU-ELEC'!E43 -> 0 | K38: ='Suivi EAU-ELEC'!G43 -> 0 | L38: ='Suivi EAU-ELEC'!I43 -> 0 | M38: =L38+K38+J38 -> 0 | O38: =M38*1.002 -> 0 | U38: ='Suvi Gaz'!O38 -> 0 | W38: =U38*8.3673 -> 0 | Y38: =IF(X39<X38,0,X39-X38) -> 0 | Z38: =Y38*0.53*1000 -> 0
B39: =B38+1 -> 43829 | D39: ='Suivi EAU-ELEC'!C44 -> 0 | F39: =D39*12.67 -> 0 | J39: ='Suivi EAU-ELEC'!E44 -> 0 | K39: ='Suivi EAU-ELEC'!G44 -> 0 | L39: ='Suivi EAU-ELEC'!I44 -> 0 | M39: =L39+K39+J39 -> 0 | O39: =M39*1.002 -> 0 | U39: ='Suvi Gaz'!O39 -> 0 | W39: =U39*8.3673 -> 0 | Y39: =IF(X40<X39,0,X40-X39) -> 0 | Z39: =Y39*0.53*1000 -> 0
B40: =B39+1 -> 43830 | D40: ='Suivi EAU-ELEC'!C45 -> 0 | F40: =D40*12.67 -> 0 | J40: ='Suivi EAU-ELEC'!E45 -> 0 | K40: ='Suivi EAU-ELEC'!G45 -> 0 | L40: ='Suivi EAU-ELEC'!I45 -> 0 | M40: =L40+K40+J40 -> 0 | O40: =M40*1.002 -> 0 | U40: ='Suvi Gaz'!O40 -> 0 | W40: =U40*8.3673 -> 0 | Y40: =IF(X41<X40,0,X41-X40) -> 0 | Z40: =Y40*0.53*1000 -> 0
D41: =SUM(D10:D39) -> 8200 | F41: =SUM(F10:H40) -> 103894 | J41: =SUM(J10:J40) -> 79142 | K41: =SUM(K10:K40) -> 120023 | L41: =SUM(L10:L40) -> 56779 | M41: =SUM(M10:M40) -> 255944 | O41: =SUM(O10:Q40) -> 256455.89 | S41: =SUM(S10:S40) -> 0 | U41: =SUM(U10:U40) -> 16991.8 | W41: =SUM(W10:W40) -> 142175.49 | Y41: =SUM(Y10:Y40) -> 276.06 | Z41: =SUM(Z10:Z40) -> 146311.8
A43: ELECTRICITE / Kw/h | D43: creuse 81 | F43: 1.002 | G43: =J41 -> 79142 | J43: =G43*F43 -> 79300.284 | L43: =J43+J44+J45 -> 256455.89
D44: pleine 82 | F44: 1.002 | G44: =K41 -> 120023 | J44: =G44*F44 -> 120263.05
D45: pointe 83 | F45: 1.002 | G45: =L41 -> 56779 | J45: =G45*F45 -> 56892.558
A46: EAU HOTEL M3 | F46: 12.67 | G46: =D41 -> 8200 | J46: =G46*F46 -> 103894 | L46: =J46 -> 103894
A47: GAZ Kg | F47: 8.3673 | G47: =U41 -> 16991.8 | J47: =G47*F47 -> 142175.49 | L47: =J47 -> 142175.49

Sheet Suvi Gaz
D1: suivi Gaz
Q2: 803 | T2: 519 | W2: 800 | Z2: 802
B3: Relvé C1 | C3: cons C1 | D3: Relvé C2 | E3: cons C2 | F3: Relvé C3 | G3: cons C3 | H3: Relvé C4 | I3: cons C4 | J3: ∑ des relevés | K3: moyen general % | L3: con.j | M3: ∑ de volume en L | N3: cons./jen L | O3: cons./jen Kg | P3: cons./jen DH | Q3: livraison C1 | R3: %Avant | S3: % Après | T3: livraison C2 | U3: %Avant | V3: % Après | W3: livraison C3 | X3: %Avant | Y3: % Après | Z3: livraison C4 | AA3: %Avant | AB3: % Après | AC3: total livraison | AD3: moyen general % Avant L | AE3: moyen general % Aaprés L
A4: 43794 | B4: 60 | C4: =IF(AC4>0,((B4-R4)+(S4-B5)),IF(B5=0, ,(B4-B5))) -> 3 | D4: 62 | E4: =IF(AC4>0,((D4-U4)+(V4-D5)),IF(D5=0, ,(D4-D5))) -> 0 | F4: 59 | G4: =IF(AC4>0,((F4-X4)+(Y4-F5)),IF(F5=0, ,(F4-F5))) -> 1 | H4: 58 | I4: =IF(AC4>0,((H4-AA4)+(AB4-H5)),IF(H5=0, ,(H4-H5))) -> 3 | J4: =B4+D4+F4+H4 -> 239 | K4: =J4/4 -> 59.75 | L4: =IF(AC4>0,((K4-AD4)+(AE4-K5)),IF(K5=0, ,(K4-K5))) -> 1.75 | M4: =7000*4 -> 28000 | N4: =L4*M4/100 -> 490 | O4: =N4*0.53 -> 259.7 | P4: =O4*8.3673 -> 2172.9878 | Q4: 2531 | R4: 57 | S4: 85 | T4: 2180 | U4: 62 | V4: 85 | W4: 2356 | X4: 58 | Y4: 85 | Z4: 2505 | AA4: 55 | AB4: 85 | AC4: =Q4+T4+W4+Z4 -> 9572 | AD4: =(R4+U4+X4+AA4)/4 -> 58 | AE4: =(S4+V4+Y4+AB4)/4 -> 85
A5: 43795 | B5: 85 | C5: =IF(AC5>0,((B5-R5)+(S5-B6)),IF(B6=0, ,(B5-B6))) -> 0 | D5: 85 | E5: =IF(AC5>0,((D5-U5)+(V5-D6)),IF(D6=0, ,(D5-D6))) -> 0 | F5: 85 | G5: =IF(AC5>0,((F5-X5)+(Y5-F6)),IF(F6=0, ,(F5-F6))) -> 4 | H5: 85 | I5: =IF(AC5>0,((H5-AA5)+(AB5-H6)),IF(H6=0, ,(H5-H6))) -> 2 | J5: =B5+D5+F5+H5 -> 340 | K5: =J5/4 -> 85 | L5: =IF(AC5>0,((K5-AD5)+(AE5-K6)),IF(K6=0, ,(K5-K6))) -> 1.5 | M5: =7000*4 -> 28000 | N5: =L5*M5/100 -> 420 | O5: =N5*0.53 -> 222.6 | P5: =O5*8.3673 -> 1862.561 | AC5: =Q5+T5+W5+Z5 -> 0 | AD5: =(R5+U5+X5+AA5)/4 -> 0 | AE5: =(S5+V5+Y5+AB5)/4 -> 0
A6: 43796 | B6: 85 | C6: =IF(AC6>0,((B6-R6)+(S6-B7)),IF(B7=0, ,(B6-B7))) -> 5 | D6: 85 | E6: =IF(AC6>0,((D6-U6)+(V6-D7)),IF(D7=0, ,(D6-D7))) -> 5 | F6: 81 | G6: =IF(AC6>0,((F6-X6)+(Y6-F7)),IF(F7=0, ,(F6-F7))) -> 6 | H6: 83 | I6: =IF(AC6>0,((H6-AA6)+(AB6-H7)),IF(H7=0, ,(H6-H7))) -> 7 | J6: =B6+D6+F6+H6 -> 334 | K6: =J6/4 -> 83.5 | L6: =IF(AC6>0,((K6-AD6)+(AE6-K7)),IF(K7=0, ,(K6-K7))) -> 5.75 | M6: =7000*4 -> 28000 | N6: =L6*M6/100 -> 1610 | O6: =N6*0.53 -> 853.3 | P6: =O6*8.3673 -> 7139.8171 | AC6: =Q6+T6+W6+Z6 -> 0 | AD6: =(R6+U6+X6+AA6)/4 -> 0 | AE6: =(S6+V6+Y6+AB6)/4 -> 0
A7: 43797 | B7: 80 | C7: =IF(AC7>0,((B7-R7)+(S7-B8)),IF(B8=0, ,(B7-B8))) -> 8 | D7: 80 | E7: =IF(AC7>0,((D7-U7)+(V7-D8)),IF(D8=0, ,(D7-D8))) -> 5 | F7: 75 | G7: =IF(AC7>0,((F7-X7)+(Y7-F8)),IF(F8=0, ,(F7-F8))) -> 5 | H7: 76 | I7: =IF(AC7>0,((H7-AA7)+(AB7-H8)),IF(H8=0, ,(H7-H8))) -> 5 | J7: =B7+D7+F7+H7 -> 311 | K7: =J7/4 -> 77.75 | L7: =IF(AC7>0,((K7-AD7)+(AE7-K8)),IF(K8=0, ,(K7-K8))) -> 5.75 | M7: =7000*4 -> 28000 | N7: =L7*M7/100 -> 1610 | O7: =N7*0.53 -> 853.3 | P7: =O7*8.3673 -> 7139.8171 | AC7: =Q7+T7+W7+Z7 -> 0 | AD7: =(R7+U7+X7+AA7)/4 -> 0 | AE7: =(S7+V7+Y7+AB7)/4 -> 0
A8: 43798 | B8: 72 | C8: =IF(AC8>0,((B8-R8)+(S8-B9)),IF(B9=0, ,(B8-B9))) -> 3 | D8: 75 | E8: =IF(AC8>0,((D8-U8)+(V8-D9)),IF(D9=0, ,(D8-D9))) -> 5 | F8: 70 | G8: =IF(AC8>0,((F8-X8)+(Y8-F9)),IF(F9=0, ,(F8-F9))) -> 5 | H8: 71 | I8: =IF(AC8>0,((H8-AA8)+(AB8-H9)),IF(H9=0, ,(H8-H9))) -> 4 | J8: =B8+D8+F8+H8 -> 288 | K8: =J8/4 -> 72 | L8: =IF(AC8>0,((K8-AD8)+(AE8-K9)),IF(K9=0, ,(K8-K9))) -> 4.25 | M8: =7000*4 -> 28000 | N8: =L8*M8/100 -> 1190 | O8: =N8*0.53 -> 630.7 | P8: =O8*8.3673 -> 5277.2561 | AC8: =Q8+T8+W8+Z8 -> 0 | AD8: =(R8+U8+X8+AA8)/4 -> 0 | AE8: =(S8+V8+Y8+AB8)/4 -> 0
A9: 43799 | B9: 69 | C9: =IF(AC9>0,((B9-R9)+(S9-B10)),IF(B10=0, ,(B9-B10))) -> 8 | D9: 70 | E9: =IF(AC9>0,((D9-U9)+(V9-D10)),IF(D10=0, ,(D9-D10))) -> 6 | F9: 65 | G9: =IF(AC9>0,((F9-X9)+(Y9-F10)),IF(F10=0, ,(F9-F10))) -> 6 | H9: 67 | I9: =IF(AC9>0,((H9-AA9)+(AB9-H10)),IF(H10=0, ,(H9-H10))) -> 6 | J9: =B9+D9+F9+H9 -> 271 | K9: =J9/4 -> 67.75 | L9: =IF(AC9>0,((K9-AD9)+(AE9-K10)),IF(K10=0, ,(K9-K10))) -> 6.5 | M9: =7000*4 -> 28000 | N9: =L9*M9/100 -> 1820 | O9: =N9*0.53 -> 964.6 | P9: =O9*8.3673 -> 8071.0976 | AC9: =Q9+T9+W9+Z9 -> 0 | AD9: =(R9+U9+X9+AA9)/4 -> 0 | AE9: =(S9+V9+Y9+AB9)/4 -> 0
A10: 43800 | B10: 61 | C10: =IF(AC10>0,((B10-R10)+(S10-B11)),IF(B11=0, ,(B10-B11))) -> 1 | D10: 64 | E10: =IF(AC10>0,((D10-U10)+(V10-D11)),IF(D11=0, ,(D10-D11))) -> 3 | F10: 59 | G10: =IF(AC10>0,((F10-X10)+(Y10-F11)),IF(F11=0, ,(F10-F11))) -> 4 | H10: 61 | I10: =IF(AC10>0,((H10-AA10)+(AB10-H11)),IF(H11=0, ,(H10-H11))) -> 1 | J10: =B10+D10+F10+H10 -> 245 | K10: =J10/4 -> 61.25 | L10: =IF(AC10>0,((K10-AD10)+(AE10-K11)),IF(K11=0, ,(K10-K11))) -> 2.25 | M10: =7000*4 -> 28000 | N10: =L10*M10/100 -> 630 | O10: =N10*0.53 -> 333.9 | P10: =O10*8.3673 -> 2793.8415 | AC10: =Q10+T10+W10+Z10 -> 0 | AD10: =(R10+U10+X10+AA10)/4 -> 0 | AE10: =(S10+V10+Y10+AB10)/4 -> 0
A11: 43801 | B11: 60 | C11: =IF(AC11>0,((B11-R11)+(S11-B12)),IF(B12=0, ,(B11-B12))) -> 2 | D11: 61 | E11: =IF(AC11>0,((D11-U11)+(V11-D12)),IF(D12=0, ,(D11-D12))) -> 7 | F11: 55 | G11: =IF(AC11>0,((F11-X11)+(Y11-F12)),IF(F12=0, ,(F11-F12))) -> 7 | H11: 60 | I11: =IF(AC11>0,((H11-AA11)+(AB11-H12)),IF(H12=0, ,(H11-H12))) -> 6 | J11: =B11+D11+F11+H11 -> 236 | K11: =J11/4 -> 59 | L11: =IF(AC11>0,((K11-AD11)+(AE11-K12)),IF(K12=0, ,(K11-K12))) -> 5.5 | M11: =7000*4 -> 28000 | N11: =L11*M11/100 -> 1540 | O11: =N11*0.53 -> 816.2 | P11: =O11*8.3673 -> 6829.3903 | AC11: =Q11+T11+W11+Z11 -> 0 | AD11: =(R11+U11+X11+AA11)/4 -> 0 | AE11: =(S11+V11+Y11+AB11)/4 -> 0
A12: 43802 | B12: 58 | C12: =IF(AC12>0,((B12-R12)+(S12-B13)),IF(B13=0, ,(B12-B13))) -> 8 | D12: 54 | E12: =IF(AC12>0,((D12-U12)+(V12-D13)),IF(D13=0, ,(D12-D13))) -> 5 | F12: 48 | G12: =IF(AC12>0,((F12-X12)+(Y12-F13)),IF(F13=0, ,(F12-F13))) -> 7 | H12: 54 | I12: =IF(AC12>0,((H12-AA12)+(AB12-H13)),IF(H13=0, ,(H12-H13))) -> 5 | J12: =B12+D12+F12+H12 -> 214 | K12: =J12/4 -> 53.5 | L12: =IF(AC12>0,((K12-AD12)+(AE12-K13)),IF(K13=0, ,(K12-K13))) -> 6.25 | M12: =7000*4 -> 28000 | N12: =L12*M12/100 -> 1750 | O12: =N12*0.53 -> 927.5 | P12: =O12*8.3673 -> 7760.6708 | Q12: 2060 | R12: 50 | S12: 85 | T12: 3162 | U12: 50 | V12: 85 | W12: 3002 | X12: 45 | Y12: 85 | Z12: 3000 | AA12: 50 | AB12: 85 | AC12: =Q12+T12+W12+Z12 -> 11224 | AD12: =(R12+U12+X12+AA12)/4 -> 48.75 | AE12: =(S12+V12+Y12+AB12)/4 -> 85
A13: 43803 | B13: 85 | C13: =IF(AC13>0,((B13-R13)+(S13-B14)),IF(B14=0, ,(B13-B14))) -> 3 | D13: 84 | E13: =IF(AC13>0,((D13-U13)+(V13-D14)),IF(D14=0, ,(D13-D14))) -> 2 | F13: 81 | G13: =IF(AC13>0,((F13-X13)+(Y13-F14)),IF(F14=0, ,(F13-F14))) -> 2 | H13: 84 | I13: =IF(AC13>0,((H13-AA13)+(AB13-H14)),IF(H14=0, ,(H13-H14))) -> 5 | J13: =B13+D13+F13+H13 -> 334 | K13: =J13/4 -> 83.5 | L13: =IF(AC13>0,((K13-AD13)+(AE13-K14)),IF(K14=0, ,(K13-K14))) -> 3 | M13: =7000*4 -> 28000 | N13: =L13*M13/100 -> 840 | O13: =N13*0.53 -> 445.2 | P13: =O13*8.3673 -> 3725.122 | AC13: =Q13+T13+W13+Z13 -> 0 | AD13: =(R13+U13+X13+AA13)/4 -> 0 | AE13: =(S13+V13+Y13+AB13)/4 -> 0
A14: 43804 | B14: 82 | C14: =IF(AC14>0,((B14-R14)+(S14-B15)),IF(B15=0, ,(B14-B15))) -> 7 | D14: 82 | E14: =IF(AC14>0,((D14-U14)+(V14-D15)),IF(D15=0, ,(D14-D15))) -> 10 | F14: 79 | G14: =IF(AC14>0,((F14-X14)+(Y14-F15)),IF(F15=0, ,(F14-F15))) -> 11 | H14: 79 | I14: =IF(AC14>0,((H14-AA14)+(AB14-H15)),IF(H15=0, ,(H14-H15))) -> 7 | J14: =B14+D14+F14+H14 -> 322 | K14: =J14/4 -> 80.5 | L14: =IF(AC14>0,((K14-AD14)+(AE14-K15)),IF(K15=0, ,(K14-K15))) -> 8.75 | M14: =7000*4 -> 28000 | N14: =L14*M14/100 -> 2450 | O14: =N14*0.53 -> 1298.5 | P14: =O14*8.3673 -> 10864.939 | AC14: =Q14+T14+W14+Z14 -> 0 | AD14: =(R14+U14+X14+AA14)/4 -> 0 | AE14: =(S14+V14+Y14+AB14)/4 -> 0
A15: 43805 | B15: 75 | C15: =IF(AC15>0,((B15-R15)+(S15-B16)),IF(B16=0, ,(B15-B16))) -> 11 | D15: 72 | E15: =IF(AC15>0,((D15-U15)+(V15-D16)),IF(D16=0, ,(D15-D16))) -> 6 | F15: 68 | G15: =IF(AC15>0,((F15-X15)+(Y15-F16)),IF(F16=0, ,(F15-F16))) -> 8 | H15: 72 | I15: =IF(AC15>0,((H15-AA15)+(AB15-H16)),IF(H16=0, ,(H15-H16))) -> 11 | J15: =B15+D15+F15+H15 -> 287 | K15: =J15/4 -> 71.75 | L15: =IF(AC15>0,((K15-AD15)+(AE15-K16)),IF(K16=0, ,(K15-K16))) -> 9 | M15: =7000*4 -> 28000 | N15: =L15*M15/100 -> 2520 | O15: =N15*0.53 -> 1335.6 | P15: =O15*8.3673 -> 11175.366 | AC15: =Q15+T15+W15+Z15 -> 0 | AD15: =(R15+U15+X15+AA15)/4 -> 0 | AE15: =(S15+V15+Y15+AB15)/4 -> 0
A16: 43806 | B16: 64 | C16: =IF(AC16>0,((B16-R16)+(S16-B17)),IF(B17=0, ,(B16-B17))) -> 4 | D16: 66 | E16: =IF(AC16>0,((D16-U16)+(V16-D17)),IF(D17=0, ,(D16-D17))) -> 5 | F16: 60 | G16: =IF(AC16>0,((F16-X16)+(Y16-F17)),IF(F17=0, ,(F16-F17))) -> 3 | H16: 61 | I16: =IF(AC16>0,((H16-AA16)+(AB16-H17)),IF(H17=0, ,(H16-H17))) -> 3 | J16: =B16+D16+F16+H16 -> 251 | K16: =J16/4 -> 62.75 | L16: =IF(AC16>0,((K16-AD16)+(AE16-K17)),IF(K17=0, ,(K16-K17))) -> 3.75 | M16: =7000*4 -> 28000 | N16: =L16*M16/100 -> 1050 | O16: =N16*0.53 -> 556.5 | P16: =O16*8.3673 -> 4656.4025 | AC16: =Q16+T16+W16+Z16 -> 0 | AD16: =(R16+U16+X16+AA16)/4 -> 0 | AE16: =(S16+V16+Y16+AB16)/4 -> 0
A17: 43807 | B17: 60 | C17: =IF(AC17>0,((B17-R17)+(S17-B18)),IF(B18=0, ,(B17-B18))) -> 3 | D17: 61 | E17: =IF(AC17>0,((D17-U17)+(V17-D18)),IF(D18=0, ,(D17-D18))) -> 3 | F17: 57 | G17: =IF(AC17>0,((F17-X17)+(Y17-F18)),IF(F18=0, ,(F17-F18))) -> 7 | H17: 58 | I17: =IF(AC17>0,((H17-AA17)+(AB17-H18)),IF(H18=0, ,(H17-H18))) -> 7 | J17: =B17+D17+F17+H17 -> 236 | K17: =J17/4 -> 59 | L17: =IF(AC17>0,((K17-AD17)+(AE17-K18)),IF(K18=0, ,(K17-K18))) -> 5 | M17: =7000*4 -> 28000 | N17: =L17*M17/100 -> 1400 | O17: =N17*0.53 -> 742 | P17: =O17*8.3673 -> 6208.5366 | AC17: =Q17+T17+W17+Z17 -> 0 | AD17: =(R17+U17+X17+AA17)/4 -> 0 | AE17: =(S17+V17+Y17+AB17)/4 -> 0
A18: 43808 | B18: 57 | C18: =IF(AC18>0,((B18-R18)+(S18-B19)),IF(B19=0, ,(B18-B19))) -> 2 | D18: 58 | E18: =IF(AC18>0,((D18-U18)+(V18-D19)),IF(D19=0, ,(D18-D19))) -> 3 | F18: 50 | G18: =IF(AC18>0,((F18-X18)+(Y18-F19)),IF(F19=0, ,(F18-F19))) -> 6 | H18: 51 | I18: =IF(AC18>0,((H18-AA18)+(AB18-H19)),IF(H19=0, ,(H18-H19))) -> 5 | J18: =B18+D18+F18+H18 -> 216 | K18: =J18/4 -> 54 | L18: =IF(AC18>0,((K18-AD18)+(AE18-K19)),IF(K19=0, ,(K18-K19))) -> 4 | M18: =7000*4 -> 28000 | N18: =L18*M18/100 -> 1120 | O18: =N18*0.53 -> 593.6 | P18: =O18*8.3673 -> 4966.8293 | Q18: 3002 | R18: 55 | S18: 85 | T18: 2500 | U18: 55 | V18: 85 | W18: 2501 | X18: 48 | Y18: 85 | Z18: 2303 | AA18: 50 | AB18: 85 | AC18: =Q18+T18+W18+Z18 -> 10306 | AD18: =(R18+U18+X18+AA18)/4 -> 52 | AE18: =(S18+V18+Y18+AB18)/4 -> 85
A19: 43809 | B19: 85 | C19: =IF(AC19>0,((B19-R19)+(S19-B20)),IF(B20=0, ,(B19-B20))) -> 10 | D19: 85 | E19: =IF(AC19>0,((D19-U19)+(V19-D20)),IF(D20=0, ,(D19-D20))) -> 6 | F19: 81 | G19: =IF(AC19>0,((F19-X19)+(Y19-F20)),IF(F20=0, ,(F19-F20))) -> 10 | H19: 81 | I19: =IF(AC19>0,((H19-AA19)+(AB19-H20)),IF(H20=0, ,(H19-H20))) -> 8 | J19: =B19+D19+F19+H19 -> 332 | K19: =J19/4 -> 83 | L19: =IF(AC19>0,((K19-AD19)+(AE19-K20)),IF(K20=0, ,(K19-K20))) -> 8.5 | M19: =7000*4 -> 28000 | N19: =L19*M19/100 -> 2380 | O19: =N19*0.53 -> 1261.4 | P19: =O19*8.3673 -> 10554.512 | AC19: =Q19+T19+W19+Z19 -> 0 | AD19: =(R19+U19+X19+AA19)/4 -> 0 | AE19: =(S19+V19+Y19+AB19)/4 -> 0
A20: 43810 | B20: 75 | C20: =IF(AC20>0,((B20-R20)+(S20-B21)),IF(B21=0, ,(B20-B21))) -> 7 | D20: 79 | E20: =IF(AC20>0,((D20-U20)+(V20-D21)),IF(D21=0, ,(D20-D21))) -> 9 | F20: 71 | G20: =IF(AC20>0,((F20-X20)+(Y20-F21)),IF(F21=0, ,(F20-F21))) -> 7 | H20: 73 | I20: =IF(AC20>0,((H20-AA20)+(AB20-H21)),IF(H21=0, ,(H20-H21))) -> 7 | J20: =B20+D20+F20+H20 -> 298 | K20: =J20/4 -> 74.5 | L20: =IF(AC20>0,((K20-AD20)+(AE20-K21)),IF(K21=0, ,(K20-K21))) -> 7.5 | M20: =7000*4 -> 28000 | N20: =L20*M20/100 -> 2100 | O20: =N20*0.53 -> 1113 | P20: =O20*8.3673 -> 9312.8049 | AC20: =Q20+T20+W20+Z20 -> 0 | AD20: =(R20+U20+X20+AA20)/4 -> 0 | AE20: =(S20+V20+Y20+AB20)/4 -> 0
A21: 43811 | B21: 68 | C21: =IF(AC21>0,((B21-R21)+(S21-B22)),IF(B22=0, ,(B21-B22))) -> 7 | D21: 70 | E21: =IF(AC21>0,((D21-U21)+(V21-D22)),IF(D22=0, ,(D21-D22))) -> 6 | F21: 64 | G21: =IF(AC21>0,((F21-X21)+(Y21-F22)),IF(F22=0, ,(F21-F22))) -> 4 | H21: 66 | I21: =IF(AC21>0,((H21-AA21)+(AB21-H22)),IF(H22=0, ,(H21-H22))) -> 6 | J21: =B21+D21+F21+H21 -> 268 | K21: =J21/4 -> 67 | L21: =IF(AC21>0,((K21-AD21)+(AE21-K22)),IF(K22=0, ,(K21-K22))) -> 5.75 | M21: =7000*4 -> 28000 | N21: =L21*M21/100 -> 1610 | O21: =N21*0.53 -> 853.3 | P21: =O21*8.3673 -> 7139.8171 | AC21: =Q21+T21+W21+Z21 -> 0 | AD21: =(R21+U21+X21+AA21)/4 -> 0 | AE21: =(S21+V21+Y21+AB21)/4 -> 0
A22: 43812 | B22: 61 | C22: =IF(AC22>0,((B22-R22)+(S22-B23)),IF(B23=0, ,(B22-B23))) -> 2 | D22: 64 | E22: =IF(AC22>0,((D22-U22)+(V22-D23)),IF(D23=0, ,(D22-D23))) -> 2 | F22: 60 | G22: =IF(AC22>0,((F22-X22)+(Y22-F23)),IF(F23=0, ,(F22-F23))) -> 0 | H22: 60 | I22: =IF(AC22>0,((H22-AA22)+(AB22-H23)),IF(H23=0, ,(H22-H23))) -> 0 | J22: =B22+D22+F22+H22 -> 245 | K22: =J22/4 -> 61.25 | L22: =IF(AC22>0,((K22-AD22)+(AE22-K23)),IF(K23=0, ,(K22-K23))) -> 1 | M22: =7000*4 -> 28000 | N22: =L22*M22/100 -> 280 | O22: =N22*0.53 -> 148.4 | P22: =O22*8.3673 -> 1241.7073 | Q22: 2497 | R22: 59 | S22: 85 | T22: 2234 | U22: 62 | V22: 85 | W22: 2248 | X22: 60 | Y22: 85 | Z22: 2418 | AA22: 60 | AB22: 85 | AC22: =Q22+T22+W22+Z22 -> 9397 | AD22: =(R22+U22+X22+AA22)/4 -> 60.25 | AE22: =(S22+V22+Y22+AB22)/4 -> 85
A23: 43813 | B23: 85 | C23: =IF(AC23>0,((B23-R23)+(S23-B24)),IF(B24=0, ,(B23-B24))) -> 5 | D23: 85 | E23: =IF(AC23>0,((D23-U23)+(V23-D24)),IF(D24=0, ,(D23-D24))) -> 5 | F23: 85 | G23: =IF(AC23>0,((F23-X23)+(Y23-F24)),IF(F24=0, ,(F23-F24))) -> 9 | H23: 85 | I23: =IF(AC23>0,((H23-AA23)+(AB23-H24)),IF(H24=0, ,(H23-H24))) -> 8 | J23: =B23+D23+F23+H23 -> 340 | K23: =J23/4 -> 85 | L23: =IF(AC23>0,((K23-AD23)+(AE23-K24)),IF(K24=0, ,(K23-K24))) -> 6.75 | M23: =7000*4 -> 28000 | N23: =L23*M23/100 -> 1890 | O23: =N23*0.53 -> 1001.7 | P23: =O23*8.3673 -> 8381.5244 | AC23: =Q23+T23+W23+Z23 -> 0 | AD23: =(R23+U23+X23+AA23)/4 -> 0 | AE23: =(S23+V23+Y23+AB23)/4 -> 0
A24: 43814 | B24: 80 | C24: =IF(AC24>0,((B24-R24)+(S24-B25)),IF(B25=0, ,(B24-B25))) -> 8 | D24: 80 | E24: =IF(AC24>0,((D24-U24)+(V24-D25)),IF(D25=0, ,(D24-D25))) -> 6 | F24: 76 | G24: =IF(AC24>0,((F24-X24)+(Y24-F25)),IF(F25=0, ,(F24-F25))) -> 6 | H24: 77 | I24: =IF(AC24>0,((H24-AA24)+(AB24-H25)),IF(H25=0, ,(H24-H25))) -> 6 | J24: =B24+D24+F24+H24 -> 313 | K24: =J24/4 -> 78.25 | L24: =IF(AC24>0,((K24-AD24)+(AE24-K25)),IF(K25=0, ,(K24-K25))) -> 6.5 | M24: =7000*4 -> 28000 | N24: =L24*M24/100 -> 1820 | O24: =N24*0.53 -> 964.6 | P24: =O24*8.3673 -> 8071.0976 | AC24: =Q24+T24+W24+Z24 -> 0 | AD24: =(R24+U24+X24+AA24)/4 -> 0 | AE24: =(S24+V24+Y24+AB24)/4 -> 0
A25: 43815 | B25: 72 | C25: =IF(AC25>0,((B25-R25)+(S25-B26)),IF(B26=0, ,(B25-B26))) -> 4 | D25: 74 | E25: =IF(AC25>0,((D25-U25)+(V25-D26)),IF(D26=0, ,(D25-D26))) -> 6 | F25: 70 | G25: =IF(AC25>0,((F25-X25)+(Y25-F26)),IF(F26=0, ,(F25-F26))) -> 5 | H25: 71 | I25: =IF(AC25>0,((H25-AA25)+(AB25-H26)),IF(H26=0, ,(H25-H26))) -> 6 | J25: =B25+D25+F25+H25 -> 287 | K25: =J25/4 -> 71.75 | L25: =IF(AC25>0,((K25-AD25)+(AE25-K26)),IF(K26=0, ,(K25-K26))) -> 5.25 | M25: =7000*4 -> 28000 | N25: =L25*M25/100 -> 1470 | O25: =N25*0.53 -> 779.1 | P25: =O25*8.3673 -> 6518.9634 | AC25: =Q25+T25+W25+Z25 -> 0 | AD25: =(R25+U25+X25+AA25)/4 -> 0 | AE25: =(S25+V25+Y25+AB25)/4 -> 0
A26: 43816 | B26: 68 | C26: =IF(AC26>0,((B26-R26)+(S26-B27)),IF(B27=0, ,(B26-B27))) -> 8 | D26: 68 | E26: =IF(AC26>0,((D26-U26)+(V26-D27)),IF(D27=0, ,(D26-D27))) -> 8 | F26: 65 | G26: =IF(AC26>0,((F26-X26)+(Y26-F27)),IF(F27=0, ,(F26-F27))) -> 10 | H26: 65 | I26: =IF(AC26>0,((H26-AA26)+(AB26-H27)),IF(H27=0, ,(H26-H27))) -> 5 | J26: =B26+D26+F26+H26 -> 266 | K26: =J26/4 -> 66.5 | L26: =IF(AC26>0,((K26-AD26)+(AE26-K27)),IF(K27=0, ,(K26-K27))) -> 7.75 | M26: =7000*4 -> 28000 | N26: =L26*M26/100 -> 2170 | O26: =N26*0.53 -> 1150.1 | P26: =O26*8.3673 -> 9623.2317 | AC26: =Q26+T26+W26+Z26 -> 0 | AD26: =(R26+U26+X26+AA26)/4 -> 0 | AE26: =(S26+V26+Y26+AB26)/4 -> 0
A27: 43817 | B27: 60 | C27: =IF(AC27>0,((B27-R27)+(S27-B28)),IF(B28=0, ,(B27-B28))) -> 11 | D27: 60 | E27: =IF(AC27>0,((D27-U27)+(V27-D28)),IF(D28=0, ,(D27-D28))) -> 10 | F27: 55 | G27: =IF(AC27>0,((F27-X27)+(Y27-F28)),IF(F28=0, ,(F27-F28))) -> 10 | H27: 60 | I27: =IF(AC27>0,((H27-AA27)+(AB27-H28)),IF(H28=0, ,(H27-H28))) -> 12 | J27: =B27+D27+F27+H27 -> 235 | K27: =J27/4 -> 58.75 | L27: =IF(AC27>0,((K27-AD27)+(AE27-K28)),IF(K28=0, ,(K27-K28))) -> 10.75 | M27: 28000 | N27: =L27*M27/100 -> 3010 | O27: =N27*0.53 -> 1595.3 | P27: =O27*8.3673 -> 13348.354 | AC27: =Q27+T27+W27+Z27 -> 0 | AD27: =(R27+U27+X27+AA27)/4 -> 0 | AE27: =(S27+V27+Y27+AB27)/4 -> 0
A28: 43818 | B28: 49 | C28: =IF(AC28>0,((B28-R28)+(S28-B29)),IF(B29=0, ,(B28-B29))) -> 9 | D28: 50 | E28: =IF(AC28>0,((D28-U28)+(V28-D29)),IF(D29=0, ,(D28-D29))) -> 5 | F28: 45 | G28: =IF(AC28>0,((F28-X28)+(Y28-F29)),IF(F29=0, ,(F28-F29))) -> 7 | H28: 48 | I28: =IF(AC28>0,((H28-AA28)+(AB28-H29)),IF(H29=0, ,(H28-H29))) -> 8 | J28: =B28+D28+F28+H28 -> 192 | K28: =J28/4 -> 48 | L28: =IF(AC28>0,((K28-AD28)+(AE28-K29)),IF(K29=0, ,(K28-K29))) -> 7.25 | M28: =7000*4 -> 28000 | N28: =L28*M28/100 -> 2030 | O28: =N28*0.53 -> 1075.9 | P28: =O28*8.3673 -> 9002.3781 | AC28: =Q28+T28+W28+Z28 -> 0 | AD28: =(R28+U28+X28+AA28)/4 -> 0 | AE28: =(S28+V28+Y28+AB28)/4 -> 0
A29: 43819 | B29: 40 | C29: =IF(AC29>0,((B29-R29)+(S29-B30)),IF(B30=0, ,(B29-B30))) -> 0 | D29: 45 | E29: =IF(AC29>0,((D29-U29)+(V29-D30)),IF(D30=0, ,(D29-D30))) -> 0 | F29: 38 | G29: =IF(AC29>0,((F29-X29)+(Y29-F30)),IF(F30=0, ,(F29-F30))) -> 0 | H29: 40 | I29: =IF(AC29>0,((H29-AA29)+(AB29-H30)),IF(H30=0, ,(H29-H30))) -> 0 | J29: =B29+D29+F29+H29 -> 163 | K29: =J29/4 -> 40.75 | L29: =IF(AC29>0,((K29-AD29)+(AE29-K30)),IF(K30=0, ,(K29-K30))) -> 0 | M29: =7000*4 -> 28000 | N29: =L29*M29/100 -> 0 | O29: =N29*0.53 -> 0 | P29: =O29*8.3673 -> 0 | AC29: =Q29+T29+W29+Z29 -> 0 | AD29: =(R29+U29+X29+AA29)/4 -> 0 | AE29: =(S29+V29+Y29+AB29)/4 -> 0
A30: 43820 | C30: =IF(AC30>0,((B30-R30)+(S30-B31)),IF(B31=0, ,(B30-B31))) -> 0 | E30: =IF(AC30>0,((D30-U30)+(V30-D31)),IF(D31=0, ,(D30-D31))) -> 0 | G30: =IF(AC30>0,((F30-X30)+(Y30-F31)),IF(F31=0, ,(F30-F31))) -> 0 | I30: =IF(AC30>0,((H30-AA30)+(AB30-H31)),IF(H31=0, ,(H30-H31))) -> 0 | J30: =B30+D30+F30+H30 -> 0 | K30: =J30/4 -> 0 | L30: =IF(AC30>0,((K30-AD30)+(AE30-K31)),IF(K31=0, ,(K30-K31))) -> 0 | M30: =7000*4 -> 28000 | N30: =L30*M30/100 -> 0 | O30: =N30*0.53 -> 0 | P30: =O30*8.3673 -> 0 | AC30: =Q30+T30+W30+Z30 -> 0 | AD30: =(R30+U30+X30+AA30)/4 -> 0 | AE30: =(S30+V30+Y30+AB30)/4 -> 0
A31: 43821 | C31: =IF(AC31>0,((B31-R31)+(S31-B32)),IF(B32=0, ,(B31-B32))) -> 0 | E31: =IF(AC31>0,((D31-U31)+(V31-D32)),IF(D32=0, ,(D31-D32))) -> 0 | G31: =IF(AC31>0,((F31-X31)+(Y31-F32)),IF(F32=0, ,(F31-F32))) -> 0 | I31: =IF(AC31>0,((H31-AA31)+(AB31-H32)),IF(H32=0, ,(H31-H32))) -> 0 | J31: =B31+D31+F31+H31 -> 0 | K31: =J31/4 -> 0 | L31: =IF(AC31>0,((K31-AD31)+(AE31-K32)),IF(K32=0, ,(K31-K32))) -> 0 | M31: =7000*4 -> 28000 | N31: =L31*M31/100 -> 0 | O31: =N31*0.53 -> 0 | P31: =O31*8.3673 -> 0 | AC31: =Q31+T31+W31+Z31 -> 0 | AD31: =(R31+U31+X31+AA31)/4 -> 0 | AE31: =(S31+V31+Y31+AB31)/4 -> 0
A32: 43822 | C32: =IF(AC32>0,((B32-R32)+(S32-B33)),IF(B33=0, ,(B32-B33))) -> 0 | E32: =IF(AC32>0,((D32-U32)+(V32-D33)),IF(D33=0, ,(D32-D33))) -> 0 | G32: =IF(AC32>0,((F32-X32)+(Y32-F33)),IF(F33=0, ,(F32-F33))) -> 0 | I32: =IF(AC32>0,((H32-AA32)+(AB32-H33)),IF(H33=0, ,(H32-H33))) -> 0 | J32: =B32+D32+F32+H32 -> 0 | K32: =J32/4 -> 0 | L32: =IF(AC32>0,((K32-AD32)+(AE32-K33)),IF(K33=0, ,(K32-K33))) -> 0 | M32: =7000*4 -> 28000 | N32: =L32*M32/100 -> 0 | O32: =N32*0.53 -> 0 | P32: =O32*8.3673 -> 0 | AC32: =Q32+T32+W32+Z32 -> 0 | AD32: =(R32+U32+X32+AA32)/4 -> 0 | AE32: =(S32+V32+Y32+AB32)/4 -> 0
A33: 43823 | C33: =IF(AC33>0,((B33-R33)+(S33-B34)),IF(B34=0, ,(B33-B34))) -> 0 | E33: =IF(AC33>0,((D33-U33)+(V33-D34)),IF(D34=0, ,(D33-D34))) -> 0 | G33: =IF(AC33>0,((F33-X33)+(Y33-F34)),IF(F34=0, ,(F33-F34))) -> 0 | I33: =IF(AC33>0,((H33-AA33)+(AB33-H34)),IF(H34=0, ,(H33-H34))) -> 0 | J33: =B33+D33+F33+H33 -> 0 | K33: =J33/4 -> 0 | L33: =IF(AC33>0,((K33-AD33)+(AE33-K34)),IF(K34=0, ,(K33-K34))) -> 0 | M33: =7000*4 -> 28000 | N33: =L33*M33/100 -> 0 | O33: =N33*0.53 -> 0 | P33: =O33*8.3673 -> 0 | AC33: =Q33+T33+W33+Z33 -> 0 | AD33: =(R33+U33+X33+AA33)/4 -> 0 | AE33: =(S33+V33+Y33+AB33)/4 -> 0
A34: 43824 | C34: =IF(AC34>0,((B34-R34)+(S34-B35)),IF(B35=0, ,(B34-B35))) -> 0 | E34: =IF(AC34>0,((D34-U34)+(V34-D35)),IF(D35=0, ,(D34-D35))) -> 0 | G34: =IF(AC34>0,((F34-X34)+(Y34-F35)),IF(F35=0, ,(F34-F35))) -> 0 | I34: =IF(AC34>0,((H34-AA34)+(AB34-H35)),IF(H35=0, ,(H34-H35))) -> 0 | J34: =B34+D34+F34+H34 -> 0 | K34: =J34/4 -> 0 | L34: =IF(AC34>0,((K34-AD34)+(AE34-K35)),IF(K35=0, ,(K34-K35))) -> 0 | M34: =7000*4 -> 28000 | N34: =L34*M34/100 -> 0 | O34: =N34*0.53 -> 0 | P34: =O34*8.3673 -> 0 | AC34: =Q34+T34+W34+Z34 -> 0 | AD34: =(R34+U34+X34+AA34)/4 -> 0 | AE34: =(S34+V34+Y34+AB34)/4 -> 0
A35: 43825 | C35: =IF(AC35>0,((B35-R35)+(S35-B36)),IF(B36=0, ,(B35-B36))) -> 0 | E35: =IF(AC35>0,((D35-U35)+(V35-D36)),IF(D36=0, ,(D35-D36))) -> 0 | G35: =IF(AC35>0,((F35-X35)+(Y35-F36)),IF(F36=0, ,(F35-F36))) -> 0 | I35: =IF(AC35>0,((H35-AA35)+(AB35-H36)),IF(H36=0, ,(H35-H36))) -> 0 | J35: =B35+D35+F35+H35 -> 0 | K35: =J35/4 -> 0 | L35: =IF(AC35>0,((K35-AD35)+(AE35-K36)),IF(K36=0, ,(K35-K36))) -> 0 | M35: =7000*4 -> 28000 | N35: =L35*M35/100 -> 0 | O35: =N35*0.53 -> 0 | P35: =O35*8.3673 -> 0 | AC35: =Q35+T35+W35+Z35 -> 0 | AD35: =(R35+U35+X35+AA35)/4 -> 0 | AE35: =(S35+V35+Y35+AB35)/4 -> 0
A36: 43826 | C36: =IF(AC36>0,((B36-R36)+(S36-B37)),IF(B37=0, ,(B36-B37))) -> 0 | E36: =IF(AC36>0,((D36-U36)+(V36-D37)),IF(D37=0, ,(D36-D37))) -> 0 | G36: =IF(AC36>0,((F36-X36)+(Y36-F37)),IF(F37=0, ,(F36-F37))) -> 0 | I36: =IF(AC36>0,((H36-AA36)+(AB36-H37)),IF(H37=0, ,(H36-H37))) -> 0 | J36: =B36+D36+F36+H36 -> 0 | K36: =J36/4 -> 0 | L36: =IF(AC36>0,((K36-AD36)+(AE36-K37)),IF(K37=0, ,(K36-K37))) -> 0 | M36: =7000*4 -> 28000 | N36: =L36*M36/100 -> 0 | O36: =N36*0.53 -> 0 | P36: =O36*8.3673 -> 0 | AC36: =Q36+T36+W36+Z36 -> 0 | AD36: =(R36+U36+X36+AA36)/4 -> 0 | AE36: =(S36+V36+Y36+AB36)/4 -> 0
A37: 43827 | C37: =IF(AC37>0,((B37-R37)+(S37-B38)),IF(B38=0, ,(B37-B38))) -> 0 | E37: =IF(AC37>0,((D37-U37)+(V37-D38)),IF(D38=0, ,(D37-D38))) -> 0 | G37: =IF(AC37>0,((F37-X37)+(Y37-F38)),IF(F38=0, ,(F37-F38))) -> 0 | I37: =IF(AC37>0,((H37-AA37)+(AB37-H38)),IF(H38=0, ,(H37-H38))) -> 0 | J37: =B37+D37+F37+H37 -> 0 | K37: =J37/4 -> 0 | L37: =IF(AC37>0,((K37-AD37)+(AE37-K38)),IF(K38=0, ,(K37-K38))) -> 0 | M37: =7000*4 -> 28000 | N37: =L37*M37/100 -> 0 | O37: =N37*0.53 -> 0 | P37: =O37*8.3673 -> 0 | AC37: =Q37+T37+W37+Z37 -> 0 | AD37: =(R37+U37+X37+AA37)/4 -> 0 | AE37: =(S37+V37+Y37+AB37)/4 -> 0
A38: 43828 | C38: =IF(AC38>0,((B38-R38)+(S38-B39)),IF(B39=0, ,(B38-B39))) -> 0 | E38: =IF(AC38>0,((D38-U38)+(V38-D39)),IF(D39=0, ,(D38-D39))) -> 0 | G38: =IF(AC38>0,((F38-X38)+(Y38-F39)),IF(F39=0, ,(F38-F39))) -> 0 | I38: =IF(AC38>0,((H38-AA38)+(AB38-H39)),IF(H39=0, ,(H38-H39))) -> 0 | J38: =B38+D38+F38+H38 -> 0 | K38: =J38/4 -> 0 | L38: =IF(AC38>0,((K38-AD38)+(AE38-K39)),IF(K39=0, ,(K38-K39))) -> 0 | M38: =7000*4 -> 28000 | N38: =L38*M38/100 -> 0 | O38: =N38*0.53 -> 0 | P38: =O38*8.3673 -> 0 | AC38: =Q38+T38+W38+Z38 -> 0 | AD38: =(R38+U38+X38+AA38)/4 -> 0 | AE38: =(S38+V38+Y38+AB38)/4 -> 0
A39: 43829 | C39: =IF(AC39>0,((B39-R39)+(S39-B40)),IF(B40=0, ,(B39-B40))) -> 0 | E39: =IF(AC39>0,((D39-U39)+(V39-D40)),IF(D40=0, ,(D39-D40))) -> 0 | G39: =IF(AC39>0,((F39-X39)+(Y39-F40)),IF(F40=0, ,(F39-F40))) -> 0 | I39: =IF(AC39>0,((H39-AA39)+(AB39-H40)),IF(H40=0, ,(H39-H40))) -> 0 | J39: =B39+D39+F39+H39 -> 0 | K39: =J39/4 -> 0 | L39: =IF(AC39>0,((K39-AD39)+(AE39-K40)),IF(K40=0, ,(K39-K40))) -> 0 | M39: =7000*4 -> 28000 | N39: =L39*M39/100 -> 0 | O39: =N39*0.53 -> 0 | P39: =O39*8.3673 -> 0 | AC39: =Q39+T39+W39+Z39 -> 0 | AD39: =(R39+U39+X39+AA39)/4 -> 0 | AE39: =(S39+V39+Y39+AB39)/4 -> 0
A40: 43830 | C40: =IF(AC40>0,((B40-R40)+(S40-B41)),IF(B41=0, ,(B40-B41))) -> 0 | E40: =IF(AC40>0,((D40-U40)+(V40-D41)),IF(D41=0, ,(D40-D41))) -> 0 | G40: =IF(AC40>0,((F40-X40)+(Y40-F41)),IF(F41=0, ,(F40-F41))) -> 0 | I40: =IF(AC40>0,((H40-AA40)+(AB40-H41)),IF(H41=0, ,(H40-H41))) -> 0 | J40: =B40+D40+F40+H40 -> 0 | K40: =J40/4 -> 0 | L40: =IF(AC40>0,((K40-AD40)+(AE40-K41)),IF(K41=0, ,(K40-K41))) -> 0 | M40: =7000*4 -> 28000 | N40: =L40*M40/100 -> 0 | O40: =N40*0.53 -> 0 | P40: =O40*8.3673 -> 0 | AC40: =Q40+T40+W40+Z40 -> 0 | AD40: =(R40+U40+X40+AA40)/4 -> 0 | AE40: =(S40+V40+Y40+AB40)/4 -> 0
...

Sheet Suivi EAU-ELEC
C1: Suivi Compteur d'Eau- électricité RADEEMA -
A7: Date | B7: Eau m3 | D7: Electricité Kw/h
B8: Compteur | C8: Consommation | D8: Compteur H.Creuse | E8: Consommation H.Creuse | F8: Compteur H.Pleine | G8: Consommation H.Pleine | H8: Compteur H.Pointe | I8: Consommation H.Pointe
A9: 43794 | B9: 116491 | C9: =IF(B10<B9,0,B10-B9)*10 -> 380 | D9: 17840226 | E9: =IF(D10<D9,0,D10-D9) -> 4088 | F9: 32245707 | G9: =IF(F10<F9,0,F10-F9) -> 6732 | H9: 14247619 | I9: =IF(H10<H9,0,H10-H9) -> 2861
A10: =A9+1 -> 43795 | B10: 116529 | C10: =IF(B11<B10,0,B11-B10)*10 -> 410 | D10: 17844314 | E10: =IF(D11<D10,0,D11-D10) -> 5043 | F10: 32252439 | G10: =IF(F11<F10,0,F11-F10) -> 6965 | H10: 14250480 | I10: =IF(H11<H10,0,H11-H10) -> 3782
A11: =A10+1 -> 43796 | B11: 116570 | C11: =IF(B12<B11,0,B12-B11)*10 -> 410 | D11: 17849357 | E11: =IF(D12<D11,0,D12-D11) -> 4706 | F11: 32259404 | G11: =IF(F12<F11,0,F12-F11) -> 7225 | H11: 14254262 | I11: =IF(H12<H11,0,H12-H11) -> 3106
A12: =A11+1 -> 43797 | B12: 116611 | C12: =IF(B13<B12,0,B13-B12)*10 -> 450 | D12: 17854063 | E12: =IF(D13<D12,0,D13-D12) -> 4630 | F12: 32266629 | G12: =IF(F13<F12,0,F13-F12) -> 6780 | H12: 14257368 | I12: =IF(H13<H12,0,H13-H12) -> 4013
A13: =A12+1 -> 43798 | B13: 116656 | C13: =IF(B14<B13,0,B14-B13)*10 -> 410 | D13: 17858693 | E13: =IF(D14<D13,0,D14-D13) -> 5693 | F13: 32273409 | G13: =IF(F14<F13,0,F14-F13) -> 7168 | H13: 14261381 | I13: =IF(H14<H13,0,H14-H13) -> 4327
A14: =A13+1 -> 43799 | B14: 116697 | C14: =IF(B15<B14,0,B15-B14)*10 -> 480 | D14: 17864386 | E14: =IF(D15<D14,0,D15-D14) -> 5120 | F14: 32280577 | G14: =IF(F15<F14,0,F15-F14) -> 7294 | H14: 14265708 | I14: =IF(H15<H14,0,H15-H14) -> 4256
A15: =A14+1 -> 43800 | B15: 116745 | C15: =IF(B16<B15,0,B16-B15)*10 -> 500 | D15: 17869506 | E15: =IF(D16<D15,0,D16-D15) -> 4473 | F15: 32287871 | G15: =IF(F16<F15,0,F16-F15) -> 6523 | H15: 14269964 | I15: =IF(H16<H15,0,H16-H15) -> 3046
A16: =A15+1 -> 43801 | B16: 116795 | C16: =IF(B17<B16,0,B17-B16)*10 -> 380 | D16: 17873979 | E16: =IF(D17<D16,0,D17-D16) -> 4297 | F16: 32294394 | G16: =IF(F17<F16,0,F17-F16) -> 6427 | H16: 14273010 | I16: =IF(H17<H16,0,H17-H16) -> 3072
A17: =A16+1 -> 43802 | B17: 116833 | C17: =IF(B18<B17,0,B18-B17)*10 -> 380 | D17: 17878276 | E17: =IF(D18<D17,0,D18-D17) -> 4166 | F17: 32300821 | G17: =IF(F18<F17,0,F18-F17) -> 6581 | H17: 14276082 | I17: =IF(H18<H17,0,H18-H17) -> 2944
A18: =A17+1 -> 43803 | B18: 116871 | C18: =IF(B19<B18,0,B19-B18)*10 -> 440 | D18: 17882442 | E18: =IF(D19<D18,0,D19-D18) -> 4200 | F18: 32307402 | G18: =IF(F19<F18,0,F19-F18) -> 6277 | H18: 14279026 | I18: =IF(H19<H18,0,H19-H18) -> 2819
A19: =A18+1 -> 43804 | B19: 116915 | C19: =IF(B20<B19,0,B20-B19)*10 -> 450 | D19: 17886642 | E19: =IF(D20<D19,0,D20-D19) -> 3869 | F19: 32313679 | G19: =IF(F20<F19,0,F20-F19) -> 6022 | H19: 14281845 | I19: =IF(H20<H19,0,H20-H19) -> 2813
A20: =A19+1 -> 43805 | B20: 116960 | C20: =IF(B21<B20,0,B21-B20)*10 -> 370 | D20: 17890511 | E20: =IF(D21<D20,0,D21-D20) -> 3891 | F20: 32319701 | G20: =IF(F21<F20,0,F21-F20) -> 6732 | H20: 14284658 | I20: =IF(H21<H20,0,H21-H20) -> 2829
A21: =A20+1 -> 43806 | B21: 116997 | C21: =IF(B22<B21,0,B22-B21)*10 -> 380 | D21: 17894402 | E21: =IF(D22<D21,0,D22-D21) -> 3996 | F21: 32326433 | G21: =IF(F22<F21,0,F22-F21) -> 6185 | H21: 14287487 | I21: =IF(H22<H21,0,H22-H21) -> 2927
... A34: =A33+1 -> 43819 | B34: 117565 | C34: =IF(B35<B34,0,B35-B34)*10 -> 0 | D34: 17948648 | E34: =IF(D35<D34,0,D35-D34) -> 0 | F34: 32407894 | G34: =IF(F35<F34,0,F35-F34) -> 0 | H34: 14326743 | I34: =IF(H35<H34,0,H35-H34) -> 0
A35: =A34+1 -> 43820 | C35: =IF(B36<B35,0,B36-B35)*10 -> 0 | E35: =IF(D36<D35,0,D36-D35) -> 0 | G35: =IF(F36<F35,0,F36-F35) -> 0 | I35: =IF(H36<H35,0,H36-H35) -> 0
A36: =A35+1 -> 43821 | C36: =IF(B37<B36,0,B37-B36)*10 -> 0 | E36: =IF(D37<D36,0,D37-D36) -> 0 | G36: =IF(F37<F36,0,F37-F36) -> 0 | I36: =IF(H37<H36,0,H37-H36) -> 0
A37: =A36+1 -> 43822 | C37: =IF(B38<B37,0,B38-B37)*10 -> 0 | E37: =IF(D38<D37,0,D38-D37) -> 0 | G37: =IF(F38<F37,0,F38-F37) -> 0 | I37: =IF(H38<H37,0,H38-H37) -> 0
A38: =A37+1 -> 43823 | C38: =IF(B39<B38,0,B39-B38)*10 -> 0 | E38: =IF(D39<D38,0,D39-D38) -> 0 | G38: =IF(F39<F38,0,F39-F38) -> 0 | I38: =IF(H39<H38,0,H39-H38) -> 0
A39: =A38+1 -> 43824 | C39: =IF(B40<B39,0,B40-B39)*10 -> 0 | E39: =IF(D40<D39,0,D40-D39) -> 0 | G39: =IF(F40<F39,0,F40-F39) -> 0 | I39: =IF(H40<H39,0,H40-H39) -> 0
A40: =A39+1 -> 43825 | C40: =IF(B41<B40,0,B41-B40)*10 -> 0 | E40: =IF(D41<D40,0,D41-D40) -> 0 | G40: =IF(F41<F40,0,F41-F40) -> 0 | I40: =IF(H41<H40,0,H41-H40) -> 0
A41: =A40+1 -> 43826 | C41: =IF(B42<B41,0,B42-B41)*10 -> 0 | E41: =IF(D42<D41,0,D42-D41) -> 0 | G41: =IF(F42<F41,0,F42-F41) -> 0 | I41: =IF(H42<H41,0,H42-H41) -> 0
A42: =A41+1 -> 43827 | C42: =IF(B43<B42,0,B43-B42)*10 -> 0 | E42: =IF(D43<D42,0,D43-D42) -> 0 | G42: =IF(F43<F42,0,F43-F42) -> 0 | I42: =IF(H43<H42,0,H43-H42) -> 0
A43: =A42+1 -> 43828 | C43: =IF(B44<B43,0,B44-B43)*10 -> 0 | E43: =IF(D44<D43,0,D44-D43) -> 0 | G43: =IF(F44<F43,0,F44-F43) -> 0 | I43: =IF(H44<H43,0,H44-H43) -> 0
A44: =A43+1 -> 43829 | C44: =IF(B45<B44,0,B45-B44)*10 -> 0 | E44: =IF(D45<D44,0,D45-D44) -> 0 | G44: =IF(F45<F44,0,F45-F44) -> 0 | I44: =IF(H45<H44,0,H45-H44) -> 0
A45: =A44+1 -> 43830 | C45: =IF(B46<B45,0,B46-B45)*10 -> 0 | E45: =IF(D46<D45,0,D46-D45) -> 0 | G45: =IF(F46<F45,0,F46-F45) -> 0 | I45: =IF(H46<H45,0,H46-H45) -> 0
A46: =A45+1 -> 43831 | C46: =IF(B47<B46,0,B47-B46)*10 -> 0 | E46: =IF(D47<D46,0,D47-D46) -> 0 | G46: =IF(F47<F46,0,F47-F46) -> 0 | I46: =IF(H47<H46,0,H47-H46) -> 0
A47: =A46+1 -> 43832 | C47: =IF(B48<B47,0,B48-B47)*10 -> 0 | E47: =IF(D48<D47,0,D48-D47) -> 0 | G47: =IF(F48<F47,0,F48-F47) -> 0 | I47: =IF(H48<H47,0,H48-H47) -> 0
C48: =SUM(C16:C45) -> 7700 | E48: =SUM(E16:E45) -> 74669 | G48: =SUM(G16:G45) -> 113500 | I48: =SUM(I16:I45) -> 53733
G58: =IF(F59<F58,0,F59-F58) -> 0

Sheet Feuil1
