Workbook

Sheet TOTAL
A1: Site Name | B1: Day | C1: Month | D1: Year | E1: Total Electricity Kwh | F1: Electricity Tariff ($/Kwh) | G1: LPG (Kg) | H1: LPG $/Kg | I1: Water Utility Supply (m3) m3 | J1: Water Utility Supply (m3) $/m3 | K1: Room Nights
A2: Seychelles at Desroches Island | B2: 1 | C2: 12 | D2: 2019 | E2: =Submetering!E2+Submetering!F2+Submetering!G2+Submetering!H2-Submetering!AV2 -> 8250 | F2: 0.5876503 | G2: =(Submetering!AX2+Submetering!AY2+Submetering!AZ2+Submetering!BA2+Submetering!BB2) -> 21.978 | H2: 0.99 | I2: ='FS Desroches Daily'!CM4 -> 75 | J2: 10.487298 | K2: ='FS Desroches Daily'!CN4 -> 24
A3: Seychelles at Desroches Island | B3: =B2+1 -> 2 | C3: 12 | D3: 2019 | E3: =Submetering!E3+Submetering!F3+Submetering!G3+Submetering!H3-Submetering!AV3 -> 6740 | F3: =F2 -> 0.5876503 | G3: =(Submetering!AX3+Submetering!AY3+Submetering!AZ3+Submetering!BA3+Submetering!BB3) -> 27.4725 | H3: =H2 -> 0.99 | I3: ='FS Desroches Daily'!CM5 -> 67.9 | J3: =J2 -> 10.487298 | K3: ='FS Desroches Daily'!CN5 -> 22
A4: Seychelles at Desroches Island | B4: =B3+1 -> 3 | C4: 12 | D4: 2019 | E4: =Submetering!E4+Submetering!F4+Submetering!G4+Submetering!H4-Submetering!AV4 -> 7250 | F4: =F3 -> 0.5876503 | G4: =(Submetering!AX4+Submetering!AY4+Submetering!AZ4+Submetering!BA4+Submetering!BB4) -> 21.978 | H4: =H3 -> 0.99 | I4: ='FS Desroches Daily'!CM6 -> 72 | J4: =J3 -> 10.487298 | K4: ='FS Desroches Daily'!CN6 -> 20
A5: Seychelles at Desroches Island | B5: =B4+1 -> 4 | C5: 12 | D5: 2019 | E5: =Submetering!E5+Submetering!F5+Submetering!G5+Submetering!H5-Submetering!AV5 -> 7490 | F5: =F4 -> 0.5876503 | G5: =(Submetering!AX5+Submetering!AY5+Submetering!AZ5+Submetering!BA5+Submetering!BB5) -> 25.641 | H5: =H4 -> 0.99 | I5: ='FS Desroches Daily'!CM7 -> 79 | J5: =J4 -> 10.487298 | K5: ='FS Desroches Daily'!CN7 -> 17
A6: Seychelles at Desroches Island | B6: =B5+1 -> 5 | C6: 12 | D6: 2019 | E6: =Submetering!E6+Submetering!F6+Submetering!G6+Submetering!H6-Submetering!AV6 -> 7190 | F6: =F5 -> 0.5876503 | G6: =(Submetering!AX6+Submetering!AY6+Submetering!AZ6+Submetering!BA6+Submetering!BB6) -> 23.8095 | H6: =H5 -> 0.99 | I6: ='FS Desroches Daily'!CM8 -> 77 | J6: =J5 -> 10.487298 | K6: ='FS Desroches Daily'!CN8 -> 4
A7: Seychelles at Desroches Island | B7: =B6+1 -> 6 | C7: 12 | D7: 2019 | E7: =Submetering!E7+Submetering!F7+Submetering!G7+Submetering!H7-Submetering!AV7 -> 7820 | F7: =F6 -> 0.5876503 | G7: =(Submetering!AX7+Submetering!AY7+Submetering!AZ7+Submetering!BA7+Submetering!BB7) -> 20.1465 | H7: =H6 -> 0.99 | I7: ='FS Desroches Daily'!CM9 -> 78 | J7: =J6 -> 10.487298 | K7: ='FS Desroches Daily'!CN9 -> 7
A8: Seychelles at Desroches Island | B8: =B7+1 -> 7 | C8: 12 | D8: 2019 | E8: =Submetering!E8+Submetering!F8+Submetering!G8+Submetering!H8-Submetering!AV8 -> 7330 | F8: =F7 -> 0.5876503 | G8: =(Submetering!AX8+Submetering!AY8+Submetering!AZ8+Submetering!BA8+Submetering!BB8) -> 21.978 | H8: =H7 -> 0.99 | I8: ='FS Desroches Daily'!CM10 -> 73 | J8: =J7 -> 10.487298 | K8: ='FS Desroches Daily'!CN10 -> -3
A9: Seychelles at Desroches Island | B9: =B8+1 -> 8 | C9: 12 | D9: 2019 | E9: =Submetering!E9+Submetering!F9+Submetering!G9+Submetering!H9-Submetering!AV9 -> 7540 | F9: =F8 -> 0.5876503 | G9: =(Submetering!AX9+Submetering!AY9+Submetering!AZ9+Submetering!BA9+Submetering!BB9) -> 27.4725 | H9: =H8 -> 0.99 | I9: ='FS Desroches Daily'!CM11 -> 60.9 | J9: =J8 -> 10.487298 | K9: ='FS Desroches Daily'!CN11 -> 3
A10: Seychelles at Desroches Island | B10: =B9+1 -> 9 | C10: 12 | D10: 2019 | E10: =Submetering!E10+Submetering!F10+Submetering!G10+Submetering!H10-Submetering!AV10 -> 8220 | F10: =F9 -> 0.5876503 | G10: =(Submetering!AX10+Submetering!AY10+Submetering!AZ10+Submetering!BA10+Submetering!BB10) -> 23.8095 | H10: =H9 -> 0.99 | I10: ='FS Desroches Daily'!CM12 -> 79.6 | J10: =J9 -> 10.487298 | K10: ='FS Desroches Daily'!CN12 -> 15
A11: Seychelles at Desroches Island | B11: =B10+1 -> 10 | C11: 12 | D11: 2019 | E11: =Submetering!E11+Submetering!F11+Submetering!G11+Submetering!H11-Submetering!AV11 -> 7590 | F11: =F10 -> 0.5876503 | G11: =(Submetering!AX11+Submetering!AY11+Submetering!AZ11+Submetering!BA11+Submetering!BB11) -> 21.978 | H11: =H10 -> 0.99 | I11: ='FS Desroches Daily'!CM13 -> 88 | J11: =J10 -> 10.487298 | K11: ='FS Desroches Daily'!CN13 -> 17
A12: Seychelles at Desroches Island | B12: =B11+1 -> 11 | C12: 12 | D12: 2019 | E12: =Submetering!E12+Submetering!F12+Submetering!G12+Submetering!H12-Submetering!AV12 -> 9060 | F12: =F11 -> 0.5876503 | G12: =(Submetering!AX12+Submetering!AY12+Submetering!AZ12+Submetering!BA12+Submetering!BB12) -> 29.304 | H12: =H11 -> 0.99 | I12: ='FS Desroches Daily'!CM14 -> 106 | J12: =J11 -> 10.487298 | K12: ='FS Desroches Daily'!CN14 -> 21
A13: Seychelles at Desroches Island | B13: =B12+1 -> 12 | C13: 12 | D13: 2019 | E13: =Submetering!E13+Submetering!F13+Submetering!G13+Submetering!H13-Submetering!AV13 -> 9420 | F13: =F12 -> 0.5876503 | G13: =(Submetering!AX13+Submetering!AY13+Submetering!AZ13+Submetering!BA13+Submetering!BB13) -> 23.8095 | H13: =H12 -> 0.99 | I13: ='FS Desroches Daily'!CM15 -> 139.2 | J13: =J12 -> 10.487298 | K13: ='FS Desroches Daily'!CN15 -> 27
A14: Seychelles at Desroches Island | B14: =B13+1 -> 13 | C14: 12 | D14: 2019 | E14: =Submetering!E14+Submetering!F14+Submetering!G14+Submetering!H14-Submetering!AV14 -> 9850 | F14: =F13 -> 0.5876503 | G14: =(Submetering!AX14+Submetering!AY14+Submetering!AZ14+Submetering!BA14+Submetering!BB14) -> 31.1355 | H14: =H13 -> 0.99 | I14: ='FS Desroches Daily'!CM16 -> 121 | J14: =J13 -> 10.487298 | K14: ='FS Desroches Daily'!CN16 -> 30
... A32: Seychelles at Desroches Island | B32: =B31+1 -> 31 | C32: 12 | D32: 2019 | E32: =Submetering!E32+Submetering!F32+Submetering!G32+Submetering!H32-Submetering!AV32 -> 0 | F32: =F31 -> 0.5876503 | G32: =(Submetering!AX32+Submetering!AY32+Submetering!AZ32+Submetering!BA32+Submetering!BB32) -> 0 | H32: =H31 -> 0.99 | I32: ='FS Desroches Daily'!CM34 -> 0 | J32: =J31 -> 10.487298 | K32: ='FS Desroches Daily'!CN34 -> 0

Sheet Submetering
A1: Site Name | B1: Day | C1: Month | D1: Year | E1: TRF CQ6 -KWh | F1: TRF FQ7 -KWh | G1: MSB BOH Q8 -KWh | H1: EX MAIN Q3 -KWh | I1: TRF DQ2 -KWh | J1: TRF B Q1 -KWh | K1: CANCAN shop -KWh | L1: CANCAN store -KWh | M1: Laundry EQU P D.B -KWh | N1: Laundry lighting -KWh | O1: PANTRY 1 -KWh | P1: PANTRY 2 -KWh | Q1: SPA LIGHT HOUSE -KWh | R1: PANTRY 3 -KWh | S1: PANTRY 4 -KWh | T1: VMC -KWh | U1: VILLA 100/157 -KWh | V1: VILLA 101/158 -KWh | W1: VILLA 102/159 -KWh | X1: VILLA 103/160 -KWh | Y1: VILLA 104/161 -KWh | Z1: VILLA 105/162 -KWh | AA1: VILLA 106/163 -KWh | AB1: VILLA 107/164 -KWh | AC1: VILLA 108/165 -KWh | AD1: VILLA 109/166 -KWh | AE1: VILLA 110 -KWh | AF1: KUMAR&KUMAR -KWh | AG1: BLOCK 15 -KWh | AH1: BLOCK 16 -KWh | AI1: BLOCK 17 -KWh | AJ1: BLOCK 18 -KWh | AK1: BLOCK 19 -KWh | AL1: BLOCK 20 -KWh | AM1: BLOCK 21 -KWh | AN1: BLOCK 22 -KWh | AO1: BLOCK 23 -KWh | AP1: BLOCK 24 -KWh | AQ1: Exhaust Kitchen (Main) -KWh | AR1: Exhaust Kitchen (Breakfast) -KWh | AS1: Exhaust Lighthouse -KWh | AT1: Exhaust Canteen -KWh | AU1: Cold Store -KWh | AV1: RO Plant -KWh | AW1: Water (m3) | AX1: Main kitchen M1 (9598630) - Kg | AY1: Main kitchen M2 (9598611) -Kg | AZ1: Main kitchen M3 (9249533) -Kg | BA1: Lighthouse -Kg | BB1: Canteen -Kg | BC1: Room Nights
A2: Seychelles at Desroches Island | B2: 1 | C2: 12 | D2: 2019 | E2: ='FS Desroches Daily'!D4 -> 1400 | F2: ='FS Desroches Daily'!F4 -> 3000 | G2: ='FS Desroches Daily'!H4 -> 3100 | H2: ='FS Desroches Daily'!J4 -> 1380 | I2: ='FS Desroches Daily'!L4 -> 2600 | J2: ='FS Desroches Daily'!N4 -> 1690 | K2: ='FS Desroches Daily'!P4 -> 21 | L2: ='FS Desroches Daily'!R4 -> 9 | M2: ='FS Desroches Daily'!T4 -> 786 | N2: ='FS Desroches Daily'!V4 -> 236 | O2: ='FS Desroches Daily'!X4 -> 250 | P2: ='FS Desroches Daily'!Z4 -> 2600 | Q2: ='FS Desroches Daily'!AB4 -> 420 | R2: ='FS Desroches Daily'!AD4 -> 330 | S2: ='FS Desroches Daily'!AF4 -> 760 | T2: ='FS Desroches Daily'!AH4 -> 1.6 | U2: ='FS Desroches Daily'!AJ4 -> 370 | V2: ='FS Desroches Daily'!AL4 -> 0.05 | W2: ='FS Desroches Daily'!AN4 -> 0.17 | X2: ='FS Desroches Daily'!AP4 -> 0.09 | Y2: ='FS Desroches Daily'!AR4 -> 60 | Z2: ='FS Desroches Daily'!AT4 -> 60 | AA2: ='FS Desroches Daily'!AT4 -> 60 | AB2: ='FS Desroches Daily'!AV4 -> 90 | AC2: ='FS Desroches Daily'!AZ4 -> 40 | AD2: ='FS Desroches Daily'!BB4 -> 30 | AE2: ='FS Desroches Daily'!BD4 -> 0 | AF2: ='FS Desroches Daily'!BF4 -> 52 | AG2: ='FS Desroches Daily'!BH4 -> 20 | AH2: ='FS Desroches Daily'!BJ4 -> 30 | AI2: ='FS Desroches Daily'!BL4 -> 30 | AJ2: ='FS Desroches Daily'!BN4 -> 30 | AK2: ='FS Desroches Daily'!BP4 -> 40 | AL2: ='FS Desroches Daily'!BR4 -> 130 | AM2: ='FS Desroches Daily'!BT4 -> 30 | AN2: ='FS Desroches Daily'!BV4 -> 25 | AO2: ='FS Desroches Daily'!BX4 -> 30 | AP2: ='FS Desroches Daily'!BZ4 -> 47 | AQ2: ='FS Desroches Daily'!CB4 -> 28.5 | AR2: ='FS Desroches Daily'!CD4 -> 12.2 | AS2: ='FS Desroches Daily'!CF4 -> 15.6 | AT2: ='FS Desroches Daily'!CH4 -> 72.2 | AU2: ='FS Desroches Daily'!CJ4 -> 258 | AV2: ='FS Desroches Daily'!CL4 -> 630 | AW2: ='FS Desroches Daily'!CM4 -> 75 | AX2: =IF(LPG!F9-LPG!F8<0,"0",(LPG!F9-LPG!F8)*1.8315) -> 10.989 | AY2: =IF(LPG!H9-LPG!H8<0,"0",(LPG!H9-LPG!H8)*1.8315) -> 1.8315 | AZ2: =IF(LPG!J9-LPG!J8<0,"0",(LPG!J9-LPG!J8)*1.8315) -> 1.8315 | BA2: =IF(LPG!M9-LPG!M8<0,"0",(LPG!M9-LPG!M8)*1.8315) -> 3.663 | BB2: =IF(LPG!Q9-LPG!Q8<0,"0",(LPG!Q9-LPG!Q8)*1.8315) -> 3.663 | BC2: ='FS Desroches Daily'!CN4 -> 24
A3: Seychelles at Desroches Island | B3: =B2+1 -> 2 | C3: 12 | D3: 2019 | E3: ='FS Desroches Daily'!D5 -> 1100 | F3: ='FS Desroches Daily'!F5 -> 2600 | G3: ='FS Desroches Daily'!H5 -> 2600 | H3: ='FS Desroches Daily'!J5 -> 1040 | I3: ='FS Desroches Daily'!L5 -> 2300 | J3: ='FS Desroches Daily'!N5 -> 1290 | K3: ='FS Desroches Daily'!P5 -> 18 | L3: ='FS Desroches Daily'!R5 -> 8 | M3: ='FS Desroches Daily'!T5 -> 1107 | N3: ='FS Desroches Daily'!V5 -> 478 | O3: ='FS Desroches Daily'!X5 -> 250 | P3: ='FS Desroches Daily'!Z5 -> 2500 | Q3: ='FS Desroches Daily'!AB5 -> 380 | R3: ='FS Desroches Daily'!AD5 -> 250 | S3: ='FS Desroches Daily'!AF5 -> 620 | T3: ='FS Desroches Daily'!AH5 -> 1.1 | U3: ='FS Desroches Daily'!AJ5 -> 270 | V3: ='FS Desroches Daily'!AL5 -> 0.07 | W3: ='FS Desroches Daily'!AN5 -> 0.13 | X3: ='FS Desroches Daily'!AP5 -> 0.08 | Y3: ='FS Desroches Daily'!AR5 -> 50 | Z3: ='FS Desroches Daily'!AT5 -> 70 | AA3: ='FS Desroches Daily'!AT5 -> 70 | AB3: ='FS Desroches Daily'!AV5 -> 100 | AC3: ='FS Desroches Daily'!AZ5 -> 40 | AD3: ='FS Desroches Daily'!BB5 -> 40 | AE3: ='FS Desroches Daily'!BD5 -> 30 | AF3: ='FS Desroches Daily'!BF5 -> 60 | AG3: ='FS Desroches Daily'!BH5 -> 20 | AH3: ='FS Desroches Daily'!BJ5 -> 30 | AI3: ='FS Desroches Daily'!BL5 -> 30 | AJ3: ='FS Desroches Daily'!BN5 -> 30 | AK3: ='FS Desroches Daily'!BP5 -> 30 | AL3: ='FS Desroches Daily'!BR5 -> 25 | AM3: ='FS Desroches Daily'!BT5 -> 30 | AN3: ='FS Desroches Daily'!BV5 -> 25 | AO3: ='FS Desroches Daily'!BX5 -> 20 | AP3: ='FS Desroches Daily'!BZ5 -> 36 | AQ3: ='FS Desroches Daily'!CB5 -> 28.4 | AR3: ='FS Desroches Daily'!CD5 -> 12.6 | AS3: ='FS Desroches Daily'!CF5 -> 14.5 | AT3: ='FS Desroches Daily'!CH5 -> 40.8 | AU3: ='FS Desroches Daily'!CJ5 -> 233 | AV3: ='FS Desroches Daily'!CL5 -> 600 | AW3: ='FS Desroches Daily'!CM5 -> 67.9 | AX3: =IF(LPG!F10-LPG!F9<0,"0",(LPG!F10-LPG!F9)*1.8315) -> 14.652 | AY3: =IF(LPG!H10-LPG!H9<0,"0",(LPG!H10-LPG!H9)*1.8315) -> 3.663 | AZ3: =IF(LPG!J10-LPG!J9<0,"0",(LPG!J10-LPG!J9)*1.8315) -> 0 | BA3: =IF(LPG!M10-LPG!M9<0,"0",(LPG!M10-LPG!M9)*1.8315) -> 1.8315 | BB3: =IF(LPG!Q10-LPG!Q9<0,"0",(LPG!Q10-LPG!Q9)*1.8315) -> 7.326 | BC3: ='FS Desroches Daily'!CN5 -> 22
A4: Seychelles at Desroches Island | B4: =B3+1 -> 3 | C4: 12 | D4: 2019 | E4: ='FS Desroches Daily'!D6 -> 1200 | F4: ='FS Desroches Daily'!F6 -> 2900 | G4: ='FS Desroches Daily'!H6 -> 2700 | H4: ='FS Desroches Daily'!J6 -> 1120 | I4: ='FS Desroches Daily'!L6 -> 2200 | J4: ='FS Desroches Daily'!N6 -> 1240 | K4: ='FS Desroches Daily'!P6 -> 19 | L4: ='FS Desroches Daily'!R6 -> 0 | M4: ='FS Desroches Daily'!T6 | N4: ='FS Desroches Daily'!V6 -> 289 | O4: ='FS Desroches Daily'!X6 -> 0 | P4: ='FS Desroches Daily'!Z6 -> 2500 | Q4: ='FS Desroches Daily'!AB6 -> 200 | R4: ='FS Desroches Daily'!AD6 -> 290 | S4: ='FS Desroches Daily'!AF6 -> 610 | T4: ='FS Desroches Daily'!AH6 -> 1.2 | U4: ='FS Desroches Daily'!AJ6 -> 280 | V4: ='FS Desroches Daily'!AL6 -> 0.08 | W4: ='FS Desroches Daily'!AN6 -> 0.13 | X4: ='FS Desroches Daily'!AP6 | Y4: ='FS Desroches Daily'!AR6 -> 40 | Z4: ='FS Desroches Daily'!AT6 -> 80 | AA4: ='FS Desroches Daily'!AT6 -> 80 | AB4: ='FS Desroches Daily'!AV6 -> 110 | AC4: ='FS Desroches Daily'!AZ6 -> 30 | AD4: ='FS Desroches Daily'!BB6 -> 40 | AE4: ='FS Desroches Daily'!BD6 -> 20 | AF4: ='FS Desroches Daily'!BF6 -> 48 | AG4: ='FS Desroches Daily'!BH6 -> 20 | AH4: ='FS Desroches Daily'!BJ6 -> 20 | AI4: ='FS Desroches Daily'!BL6 -> 30 | AJ4: ='FS Desroches Daily'!BN6 -> 30 | AK4: ='FS Desroches Daily'!BP6 -> 20 | AL4: ='FS Desroches Daily'!BR6 -> 23 | AM4: ='FS Desroches Daily'!BT6 -> 30 | AN4: ='FS Desroches Daily'!BV6 -> 22 | AO4: ='FS Desroches Daily'!BX6 -> 30 | AP4: ='FS Desroches Daily'!BZ6 -> 33 | AQ4: ='FS Desroches Daily'!CB6 -> 27.6 | AR4: ='FS Desroches Daily'!CD6 -> 12.6 | AS4: ='FS Desroches Daily'!CF6 -> 0.4 | AT4: ='FS Desroches Daily'!CH6 -> 51 | AU4: ='FS Desroches Daily'!CJ6 -> 236 | AV4: ='FS Desroches Daily'!CL6 -> 670 | AW4: ='FS Desroches Daily'!CM6 -> 72 | AX4: =IF(LPG!F11-LPG!F10<0,"0",(LPG!F11-LPG!F10)*1.8315) -> 12.8205 | AY4: =IF(LPG!H11-LPG!H10<0,"0",(LPG!H11-LPG!H10)*1.8315) -> 3.663 | AZ4: =IF(LPG!J11-LPG!J10<0,"0",(LPG!J11-LPG!J10)*1.8315) -> 0 | BA4: =IF(LPG!M11-LPG!M10<0,"0",(LPG!M11-LPG!M10)*1.8315) -> 0 | BB4: =IF(LPG!Q11-LPG!Q10<0,"0",(LPG!Q11-LPG!Q10)*1.8315) -> 5.4945 | BC4: ='FS Desroches Daily'!CN6 -> 20
A5: Seychelles at Desroches Island | B5: =B4+1 -> 4 | C5: 12 | D5: 2019 | E5: ='FS Desroches Daily'!D7 -> 1300 | F5: ='FS Desroches Daily'!F7 -> 2800 | G5: ='FS Desroches Daily'!H7 -> 2900 | H5: ='FS Desroches Daily'!J7 -> 1180 | I5: ='FS Desroches Daily'!L7 -> 2300 | J5: ='FS Desroches Daily'!N7 -> 1360 | K5: ='FS Desroches Daily'!P7 -> 19 | L5: ='FS Desroches Daily'!R7 -> 6 | M5: ='FS Desroches Daily'!T7 -> 1148 | N5: ='FS Desroches Daily'!V7 -> 341 | O5: ='FS Desroches Daily'!X7 -> 320 | P5: ='FS Desroches Daily'!Z7 -> 2600 | Q5: ='FS Desroches Daily'!AB7 -> 390 | R5: ='FS Desroches Daily'!AD7 -> 250 | S5: ='FS Desroches Daily'!AF7 -> 620 | T5: ='FS Desroches Daily'!AH7 -> 1.3 | U5: ='FS Desroches Daily'!AJ7 -> 290 | V5: ='FS Desroches Daily'!AL7 -> 0.08 | W5: ='FS Desroches Daily'!AN7 -> 0.17 | X5: ='FS Desroches Daily'!AP7 -> 0.51 | Y5: ='FS Desroches Daily'!AR7 -> 50 | Z5: ='FS Desroches Daily'!AT7 -> 70 | AA5: ='FS Desroches Daily'!AT7 -> 70 | AB5: ='FS Desroches Daily'!AV7 -> 110 | AC5: ='FS Desroches Daily'!AZ7 -> 40 | AD5: ='FS Desroches Daily'!BB7 -> 30 | AE5: ='FS Desroches Daily'!BD7 -> 20 | AF5: ='FS Desroches Daily'!BF7 -> 25 | AG5: ='FS Desroches Daily'!BH7 -> 20 | AH5: ='FS Desroches Daily'!BJ7 -> 30 | AI5: ='FS Desroches Daily'!BL7 -> 40 | AJ5: ='FS Desroches Daily'!BN7 -> 30 | AK5: ='FS Desroches Daily'!BP7 -> 30 | AL5: ='FS Desroches Daily'!BR7 -> 23 | AM5: ='FS Desroches Daily'!BT7 -> 30 | AN5: ='FS Desroches Daily'!BV7 -> 26 | AO5: ='FS Desroches Daily'!BX7 -> 30 | AP5: ='FS Desroches Daily'!BZ7 -> 42 | AQ5: ='FS Desroches Daily'!CB7 -> 23.2 | AR5: ='FS Desroches Daily'!CD7 -> 5.6 | AS5: ='FS Desroches Daily'!CF7 -> 11.6 | AT5: ='FS Desroches Daily'!CH7 -> 92.3 | AU5: ='FS Desroches Daily'!CJ7 -> 258 | AV5: ='FS Desroches Daily'!CL7 -> 690 | AW5: ='FS Desroches Daily'!CM7 -> 79 | AX5: =IF(LPG!F12-LPG!F11<0,"0",(LPG!F12-LPG!F11)*1.8315) -> 14.652 | AY5: =IF(LPG!H12-LPG!H11<0,"0",(LPG!H12-LPG!H11)*1.8315) -> 3.663 | AZ5: =IF(LPG!J12-LPG!J11<0,"0",(LPG!J12-LPG!J11)*1.8315) -> 0 | BA5: =IF(LPG!M12-LPG!M11<0,"0",(LPG!M12-LPG!M11)*1.8315) -> 3.663 | BB5: =IF(LPG!Q12-LPG!Q11<0,"0",(LPG!Q12-LPG!Q11)*1.8315) -> 3.663 | BC5: ='FS Desroches Daily'!CN7 -> 17
A6: Seychelles at Desroches Island | B6: =B5+1 -> 5 | C6: 12 | D6: 2019 | E6: ='FS Desroches Daily'!D8 -> 1400 | F6: ='FS Desroches Daily'!F8 -> 2500 | G6: ='FS Desroches Daily'!H8 -> 2700 | H6: ='FS Desroches Daily'!J8 -> 1210 | I6: ='FS Desroches Daily'!L8 -> 2200 | J6: ='FS Desroches Daily'!N8 -> 1130 | K6: ='FS Desroches Daily'!P8 -> 18 | L6: ='FS Desroches Daily'!R8 -> 6 | M6: ='FS Desroches Daily'!T8 -> 1856 | N6: ='FS Desroches Daily'!V8 -> 381 | O6: ='FS Desroches Daily'!X8 -> 300 | P6: ='FS Desroches Daily'!Z8 -> 2200 | Q6: ='FS Desroches Daily'!AB8 -> 280 | R6: ='FS Desroches Daily'!AD8 -> 270 | S6: ='FS Desroches Daily'!AF8 -> 490 | T6: ='FS Desroches Daily'!AH8 -> 1.3 | U6: ='FS Desroches Daily'!AJ8 -> 310 | V6: ='FS Desroches Daily'!AL8 -> 0.08 | W6: ='FS Desroches Daily'!AN8 -> 0.14 | X6: ='FS Desroches Daily'!AP8 -> 0.09 | Y6: ='FS Desroches Daily'!AR8 -> 40 | Z6: ='FS Desroches Daily'!AT8 -> 80 | AA6: ='FS Desroches Daily'!AT8 -> 80 | AB6: ='FS Desroches Daily'!AV8 -> 110 | AC6: ='FS Desroches Daily'!AZ8 -> 50 | AD6: ='FS Desroches Daily'!BB8 -> 40 | AE6: ='FS Desroches Daily'!BD8 -> 20 | AF6: ='FS Desroches Daily'!BF8 -> 21 | AG6: ='FS Desroches Daily'!BH8 -> 20 | AH6: ='FS Desroches Daily'!BJ8 -> 30 | AI6: ='FS Desroches Daily'!BL8 -> 30 | AJ6: ='FS Desroches Daily'!BN8 -> 30 | AK6: ='FS Desroches Daily'!BP8 -> 30 | AL6: ='FS Desroches Daily'!BR8 -> 26 | AM6: ='FS Desroches Daily'!BT8 -> 20 | AN6: ='FS Desroches Daily'!BV8 -> 20 | AO6: ='FS Desroches Daily'!BX8 -> 30 | AP6: ='FS Desroches Daily'!BZ8 -> 57 | AQ6: ='FS Desroches Daily'!CB8 -> 16.8 | AR6: ='FS Desroches Daily'!CD8 -> 10.7 | AS6: ='FS Desroches Daily'!CF8 -> 0.3 | AT6: ='FS Desroches Daily'!CH8 -> 30.7 | AU6: ='FS Desroches Daily'!CJ8 -> 248 | AV6: ='FS Desroches Daily'!CL8 -> 620 | AW6: ='FS Desroches Daily'!CM8 -> 77 | AX6: =IF(LPG!F13-LPG!F12<0,"0",(LPG!F13-LPG!F12)*1.8315) -> 12.8205 | AY6: =IF(LPG!H13-LPG!H12<0,"0",(LPG!H13-LPG!H12)*1.8315) -> 3.663 | AZ6: =IF(LPG!J13-LPG!J12<0,"0",(LPG!J13-LPG!J12)*1.8315) -> 0 | BA6: =IF(LPG!M13-LPG!M12<0,"0",(LPG!M13-LPG!M12)*1.8315) -> 0 | BB6: =IF(LPG!Q13-LPG!Q12<0,"0",(LPG!Q13-LPG!Q12)*1.8315) -> 7.326 | BC6: ='FS Desroches Daily'!CN8 -> 4
A7: Seychelles at Desroches Island | B7: =B6+1 -> 6 | C7: 12 | D7: 2019 | E7: ='FS Desroches Daily'!D9 -> 1200 | F7: ='FS Desroches Daily'!F9 -> 2800 | G7: ='FS Desroches Daily'!H9 -> 3100 | H7: ='FS Desroches Daily'!J9 -> 1390 | I7: ='FS Desroches Daily'!L9 -> 2400 | J7: ='FS Desroches Daily'!N9 -> 1260 | K7: ='FS Desroches Daily'!P9 -> 17 | L7: ='FS Desroches Daily'!R9 -> 8 | M7: ='FS Desroches Daily'!T9 -> 903 | N7: ='FS Desroches Daily'!V9 -> 385 | O7: ='FS Desroches Daily'!X9 -> 290 | P7: ='FS Desroches Daily'!Z9 -> 2400 | Q7: ='FS Desroches Daily'!AB9 -> 380 | R7: ='FS Desroches Daily'!AD9 -> 260 | S7: ='FS Desroches Daily'!AF9 -> 500 | T7: ='FS Desroches Daily'!AH9 -> 1.1 | U7: ='FS Desroches Daily'!AJ9 -> 320 | V7: ='FS Desroches Daily'!AL9 -> 0.09 | W7: ='FS Desroches Daily'!AN9 -> 0.15 | X7: ='FS Desroches Daily'!AP9 -> 0.08 | Y7: ='FS Desroches Daily'!AR9 -> 30 | Z7: ='FS Desroches Daily'!AT9 -> 80 | AA7: ='FS Desroches Daily'!AT9 -> 80 | AB7: ='FS Desroches Daily'!AV9 -> 80 | AC7: ='FS Desroches Daily'!AZ9 -> 40 | AD7: ='FS Desroches Daily'!BB9 -> 40 | AE7: ='FS Desroches Daily'!BD9 -> 20 | AF7: ='FS Desroches Daily'!BF9 -> 45 | AG7: ='FS Desroches Daily'!BH9 -> 20 | AH7: ='FS Desroches Daily'!BJ9 -> 40 | AI7: ='FS Desroches Daily'!BL9 -> 20 | AJ7: ='FS Desroches Daily'!BN9 -> 30 | AK7: ='FS Desroches Daily'!BP9 -> 40 | AL7: ='FS Desroches Daily'!BR9 -> 28 | AM7: ='FS Desroches Daily'!BT9 -> 40 | AN7: ='FS Desroches Daily'!BV9 -> 20 | AO7: ='FS Desroches Daily'!BX9 -> 30 | AP7: ='FS Desroches Daily'!BZ9 -> 61 | AQ7: ='FS Desroches Daily'!CB9 -> 21.5 | AR7: ='FS Desroches Daily'!CD9 -> 11.4 | AS7: ='FS Desroches Daily'!CF9 -> 10.1 | AT7: ='FS Desroches Daily'!CH9 -> 41 | AU7: ='FS Desroches Daily'!CJ9 -> 279 | AV7: ='FS Desroches Daily'!CL9 -> 670 | AW7: ='FS Desroches Daily'!CM9 -> 78 | AX7: =IF(LPG!F14-LPG!F13<0,"0",(LPG!F14-LPG!F13)*1.8315) -> 9.1575 | AY7: =IF(LPG!H14-LPG!H13<0,"0",(LPG!H14-LPG!H13)*1.8315) -> 3.663 | AZ7: =IF(LPG!J14-LPG!J13<0,"0",(LPG!J14-LPG!J13)*1.8315) -> 0 | BA7: =IF(LPG!M14-LPG!M13<0,"0",(LPG!M14-LPG!M13)*1.8315) -> 3.663 | BB7: =IF(LPG!Q14-LPG!Q13<0,"0",(LPG!Q14-LPG!Q13)*1.8315) -> 3.663 | BC7: ='FS Desroches Daily'!CN9 -> 7
A8: Seychelles at Desroches Island | B8: =B7+1 -> 7 | C8: 12 | D8: 2019 | E8: ='FS Desroches Daily'!D10 -> 1100 | F8: ='FS Desroches Daily'!F10 -> 2700 | G8: ='FS Desroches Daily'!H10 -> 2700 | H8: ='FS Desroches Daily'!J10 -> 1440 | I8: ='FS Desroches Daily'!L10 -> 2400 | J8: ='FS Desroches Daily'!N10 -> 1100 | K8: ='FS Desroches Daily'!P10 -> 20 | L8: ='FS Desroches Daily'!R10 -> 6 | M8: ='FS Desroches Daily'!T10 -> 790 | N8: ='FS Desroches Daily'!V10 -> 409 | O8: ='FS Desroches Daily'!X10 -> 340 | P8: ='FS Desroches Daily'!Z10 -> 2300 | Q8: ='FS Desroches Daily'!AB10 -> 270 | R8: ='FS Desroches Daily'!AD10 -> 240 | S8: ='FS Desroches Daily'!AF10 -> 510 | T8: ='FS Desroches Daily'!AH10 -> 1.8 | U8: ='FS Desroches Daily'!AJ10 -> 300 | V8: ='FS Desroches Daily'!AL10 -> 0.14 | W8: ='FS Desroches Daily'!AN10 -> 0.11 | X8: ='FS Desroches Daily'!AP10 -> 0.05 | Y8: ='FS Desroches Daily'!AR10 -> 40 | Z8: ='FS Desroches Daily'!AT10 -> 70 | AA8: ='FS Desroches Daily'!AT10 -> 70 | AB8: ='FS Desroches Daily'!AV10 -> 60 | AC8: ='FS Desroches Daily'!AZ10 -> 30 | AD8: ='FS Desroches Daily'!BB10 -> 60 | AE8: ='FS Desroches Daily'!BD10 -> 20 | AF8: ='FS Desroches Daily'!BF10 -> 54 | AG8: ='FS Desroches Daily'!BH10 -> 30 | AH8: ='FS Desroches Daily'!BJ10 -> 40 | AI8: ='FS Desroches Daily'!BL10 -> 40 | AJ8: ='FS Desroches Daily'!BN10 -> 40 | AK8: ='FS Desroches Daily'!BP10 -> 50 | AL8: ='FS Desroches Daily'!BR10 -> 36 | AM8: ='FS Desroches Daily'!BT10 -> 30 | AN8: ='FS Desroches Daily'!BV10 -> 37 | AO8: ='FS Desroches Daily'!BX10 -> 40 | AP8: ='FS Desroches Daily'!BZ10 -> 87 | AQ8: ='FS Desroches Daily'!CB10 -> 26.5 | AR8: ='FS Desroches Daily'!CD10 -> 10.4 | AS8: ='FS Desroches Daily'!CF10 -> 5 | AT8: ='FS Desroches Daily'!CH10 -> 84.7 | AU8: ='FS Desroches Daily'!CJ10 -> 317 | AV8: ='FS Desroches Daily'!CL10 -> 610 | AW8: ='FS Desroches Daily'!CM10 -> 73 | AX8: =IF(LPG!F15-LPG!F14<0,"0",(LPG!F15-LPG!F14)*1.8315) -> 10.989 | AY8: =IF(LPG!H15-LPG!H14<0,"0",(LPG!H15-LPG!H14)*1.8315) -> 1.8315 | AZ8: =IF(LPG!J15-LPG!J14<0,"0",(LPG!J15-LPG!J14)*1.8315) -> 1.8315 | BA8: =IF(LPG!M15-LPG!M14<0,"0",(LPG!M15-LPG!M14)*1.8315) -> 0 | BB8: =IF(LPG!Q15-LPG!Q14<0,"0",(LPG!Q15-LPG!Q14)*1.8315) -> 7.326 | BC8: ='FS Desroches Daily'!CN10 -> -3
A9: Seychelles at Desroches Island | B9: =B8+1 -> 8 | C9: 12 | D9: 2019 | E9: ='FS Desroches Daily'!D11 -> 1200 | F9: ='FS Desroches Daily'!F11 -> 2700 | G9: ='FS Desroches Daily'!H11 -> 2700 | H9: ='FS Desroches Daily'!J11 -> 1490 | I9: ='FS Desroches Daily'!L11 -> 2400 | J9: ='FS Desroches Daily'!N11 -> 1530 | K9: ='FS Desroches Daily'!P11 -> 1 | L9: ='FS Desroches Daily'!R11 -> 9 | M9: ='FS Desroches Daily'!T11 -> 957 | N9: ='FS Desroches Daily'!V11 -> 380 | O9: ='FS Desroches Daily'!X11 -> 310 | P9: ='FS Desroches Daily'!Z11 -> 2400 | Q9: ='FS Desroches Daily'!AB11 -> 420 | R9: ='FS Desroches Daily'!AD11 -> 250 | S9: ='FS Desroches Daily'!AF11 -> 680 | T9: ='FS Desroches Daily'!AH11 -> 1.7 | U9: ='FS Desroches Daily'!AJ11 -> 320 | V9: ='FS Desroches Daily'!AL11 -> 0.15 | W9: ='FS Desroches Daily'!AN11 -> 0.09 | X9: ='FS Desroches Daily'!AP11 -> 0.04 | Y9: ='FS Desroches Daily'!AR11 -> 30 | Z9: ='FS Desroches Daily'!AT11 -> 70 | AA9: ='FS Desroches Daily'!AT11 -> 70 | AB9: ='FS Desroches Daily'!AV11 -> 70 | AC9: ='FS Desroches Daily'!AZ11 -> 40 | AD9: ='FS Desroches Daily'!BB11 -> 40 | AE9: ='FS Desroches Daily'!BD11 -> 0 | AF9: ='FS Desroches Daily'!BF11 -> 48 | AG9: ='FS Desroches Daily'!BH11 -> 30 | AH9: ='FS Desroches Daily'!BJ11 -> 50 | AI9: ='FS Desroches Daily'!BL11 -> 50 | AJ9: ='FS Desroches Daily'!BN11 -> 40 | AK9: ='FS Desroches Daily'!BP11 -> 40 | AL9: ='FS Desroches Daily'!BR11 -> 34 | AM9: ='FS Desroches Daily'!BT11 -> 30 | AN9: ='FS Desroches Daily'!BV11 -> 42 | AO9: ='FS Desroches Daily'!BX11 -> 40 | AP9: ='FS Desroches Daily'!BZ11 -> 63 | AQ9: ='FS Desroches Daily'!CB11 -> 33.3 | AR9: ='FS Desroches Daily'!CD11 -> 12.8 | AS9: ='FS Desroches Daily'!CF11 -> 4.8 | AT9: ='FS Desroches Daily'!CH11 -> 56.6 | AU9: ='FS Desroches Daily'!CJ11 -> 309 | AV9: ='FS Desroches Daily'!CL11 -> 550 | AW9: ='FS Desroches Daily'!CM11 -> 60.9 | AX9: =IF(LPG!F16-LPG!F15<0,"0",(LPG!F16-LPG!F15)*1.8315) -> 12.8205 | AY9: =IF(LPG!H16-LPG!H15<0,"0",(LPG!H16-LPG!H15)*1.8315) -> 1.8315 | AZ9: =IF(LPG!J16-LPG!J15<0,"0",(LPG!J16-LPG!J15)*1.8315) -> 0 | BA9: =IF(LPG!M16-LPG!M15<0,"0",(LPG!M16-LPG!M15)*1.8315) -> 5.4945 | BB9: =IF(LPG!Q16-LPG!Q15<0,"0",(LPG!Q16-LPG!Q15)*1.8315) -> 7.326 | BC9: ='FS Desroches Daily'!CN11 -> 3
A10: Seychelles at Desroches Island | B10: =B9+1 -> 9 | C10: 12 | D10: 2019 | E10: ='FS Desroches Daily'!D12 -> 1800 | F10: ='FS Desroches Daily'!F12 -> 2800 | G10: ='FS Desroches Daily'!H12 -> 2900 | H10: ='FS Desroches Daily'!J12 -> 1420 | I10: ='FS Desroches Daily'!L12 -> 2400 | J10: ='FS Desroches Daily'!N12 -> 1500 | K10: ='FS Desroches Daily'!P12 -> 20 | L10: ='FS Desroches Daily'!R12 -> 9 | M10: ='FS Desroches Daily'!T12 -> 854 | N10: ='FS Desroches Daily'!V12 -> 394 | O10: ='FS Desroches Daily'!X12 -> 270 | P10: ='FS Desroches Daily'!Z12 -> 2600 | Q10: ='FS Desroches Daily'!AB12 -> 470 | R10: ='FS Desroches Daily'!AD12 -> 280 | S10: ='FS Desroches Daily'!AF12 -> 670 | T10: ='FS Desroches Daily'!AH12 -> 2 | U10: ='FS Desroches Daily'!AJ12 -> 300 | V10: ='FS Desroches Daily'!AL12 -> 0.29 | W10: ='FS Desroches Daily'!AN12 -> 0.17 | X10: ='FS Desroches Daily'!AP12 -> 0.07 | Y10: ='FS Desroches Daily'!AR12 -> 70 | Z10: ='FS Desroches Daily'!AT12 -> 70 | AA10: ='FS Desroches Daily'!AT12 -> 70 | AB10: ='FS Desroches Daily'!AV12 -> 160 | AC10: ='FS Desroches Daily'!AZ12 -> 20 | AD10: ='FS Desroches Daily'!BB12 -> 120 | AE10: ='FS Desroches Daily'!BD12 -> 20 | AF10: ='FS Desroches Daily'!BF12 -> 34 | AG10: ='FS Desroches Daily'!BH12 -> 30 | AH10: ='FS Desroches Daily'!BJ12 -> 40 | AI10: ='FS Desroches Daily'!BL12 -> 30 | AJ10: ='FS Desroches Daily'!BN12 -> 30 | AK10: ='FS Desroches Daily'!BP12 -> 40 | AL10: ='FS Desroches Daily'!BR12 -> 29 | AM10: ='FS Desroches Daily'!BT12 -> 30 | AN10: ='FS Desroches Daily'!BV12 -> 29 | AO10: ='FS Desroches Daily'!BX12 -> 40 | AP10: ='FS Desroches Daily'!BZ12 -> 70 | AQ10: ='FS Desroches Daily'!CB12 -> 34.4 | AR10: ='FS Desroches Daily'!CD12 -> 11.8 | AS10: ='FS Desroches Daily'!CF12 -> 7.3 | AT10: ='FS Desroches Daily'!CH12 -> 55 | AU10: ='FS Desroches Daily'!CJ12 -> 315 | AV10: ='FS Desroches Daily'!CL12 -> 700 | AW10: ='FS Desroches Daily'!CM12 -> 79.6 | AX10: =IF(LPG!F17-LPG!F16<0,"0",(LPG!F17-LPG!F16)*1.8315) -> 9.1575 | AY10: =IF(LPG!H17-LPG!H16<0,"0",(LPG!H17-LPG!H16)*1.8315) -> 3.663 | AZ10: =IF(LPG!J17-LPG!J16<0,"0",(LPG!J17-LPG!J16)*1.8315) -> 1.8315 | BA10: =IF(LPG!M17-LPG!M16<0,"0",(LPG!M17-LPG!M16)*1.8315) -> 3.663 | BB10: =IF(LPG!Q17-LPG!Q16<0,"0",(LPG!Q17-LPG!Q16)*1.8315) -> 5.4945 | BC10: ='FS Desroches Daily'!CN12 -> 15
A11: Seychelles at Desroches Island | B11: =B10+1 -> 10 | C11: 12 | D11: 2019 | E11: ='FS Desroches Daily'!D13 -> 1800 | F11: ='FS Desroches Daily'!F13 -> 2600 | G11: ='FS Desroches Daily'!H13 -> 2500 | H11: ='FS Desroches Daily'!J13 -> 1200 | I11: ='FS Desroches Daily'!L13 -> 2000 | J11: ='FS Desroches Daily'!N13 -> 1240 | K11: ='FS Desroches Daily'!P13 -> 19 | L11: ='FS Desroches Daily'!R13 -> 6 | M11: ='FS Desroches Daily'!T13 -> 933 | N11: ='FS Desroches Daily'!V13 -> 428 | O11: ='FS Desroches Daily'!X13 -> 230 | P11: ='FS Desroches Daily'!Z13 -> 2400 | Q11: ='FS Desroches Daily'!AB13 -> 370 | R11: ='FS Desroches Daily'!AD13 -> 370 | S11: ='FS Desroches Daily'!AF13 -> 570 | T11: ='FS Desroches Daily'!AH13 -> 2.2 | U11: ='FS Desroches Daily'!AJ13 -> 390 | V11: ='FS Desroches Daily'!AL13 -> 0.25 | W11: ='FS Desroches Daily'!AN13 -> 0.23 | X11: ='FS Desroches Daily'!AP13 -> 0.19 | Y11: ='FS Desroches Daily'!AR13 -> 70 | Z11: ='FS Desroches Daily'!AT13 -> 60 | AA11: ='FS Desroches Daily'!AT13 -> 60 | AB11: ='FS Desroches Daily'!AV13 -> 130 | AC11: ='FS Desroches Daily'!AZ13 -> 40 | AD11: ='FS Desroches Daily'!BB13 -> 110 | AE11: ='FS Desroches Daily'!BD13 -> 50 | AF11: ='FS Desroches Daily'!BF13 -> 45 | AG11: ='FS Desroches Daily'!BH13 -> 20 | AH11: ='FS Desroches Daily'!BJ13 -> 40 | AI11: ='FS Desroches Daily'!BL13 -> 40 | AJ11: ='FS Desroches Daily'!BN13 -> 30 | AK11: ='FS Desroches Daily'!BP13 -> 40 | AL11: ='FS Desroches Daily'!BR13 -> 28 | AM11: ='FS Desroches Daily'!BT13 -> 40 | AN11: ='FS Desroches Daily'!BV13 -> 32 | AO11: ='FS Desroches Daily'!BX13 -> 30 | AP11: ='FS Desroches Daily'!BZ13 -> 73 | AQ11: ='FS Desroches Daily'!CB13 -> 41.5 | AR11: ='FS Desroches Daily'!CD13 -> 9.2 | AS11: ='FS Desroches Daily'!CF13 -> 0.4 | AT11: ='FS Desroches Daily'!CH13 -> 51 | AU11: ='FS Desroches Daily'!CJ13 -> 241 | AV11: ='FS Desroches Daily'!CL13 -> 510 | AW11: ='FS Desroches Daily'!CM13 -> 88 | AX11: =IF(LPG!F18-LPG!F17<0,"0",(LPG!F18-LPG!F17)*1.8315) -> 12.8205 | AY11: =IF(LPG!H18-LPG!H17<0,"0",(LPG!H18-LPG!H17)*1.8315) -> 3.663 | AZ11: =IF(LPG!J18-LPG!J17<0,"0",(LPG!J18-LPG!J17)*1.8315) -> 1.8315 | BA11: =IF(LPG!M18-LPG!M17<0,"0",(LPG!M18-LPG!M17)*1.8315) -> 0 | BB11: =IF(LPG!Q18-LPG!Q17<0,"0",(LPG!Q18-LPG!Q17)*1.8315) -> 3.663 | BC11: ='FS Desroches Daily'!CN13 -> 17
A12: Seychelles at Desroches Island | B12: =B11+1 -> 11 | C12: 12 | D12: 2019 | E12: ='FS Desroches Daily'!D14 -> 2000 | F12: ='FS Desroches Daily'!F14 -> 3000 | G12: ='FS Desroches Daily'!H14 -> 3200 | H12: ='FS Desroches Daily'!J14 -> 1490 | I12: ='FS Desroches Daily'!L14 -> 2300 | J12: ='FS Desroches Daily'!N14 -> 1690 | K12: ='FS Desroches Daily'!P14 -> 19 | L12: ='FS Desroches Daily'!R14 -> 8 | M12: ='FS Desroches Daily'!T14 -> 829 | N12: ='FS Desroches Daily'!V14 -> 386 | O12: ='FS Desroches Daily'!X14 -> 410 | P12: ='FS Desroches Daily'!Z14 -> 2500 | Q12: ='FS Desroches Daily'!AB14 -> 330 | R12: ='FS Desroches Daily'!AD14 -> 400 | S12: ='FS Desroches Daily'!AF14 -> 680 | T12: ='FS Desroches Daily'!AH14 -> 1.8 | U12: ='FS Desroches Daily'!AJ14 -> 410 | V12: ='FS Desroches Daily'!AL14 -> 0.24 | W12: ='FS Desroches Daily'!AN14 -> 0.25 | X12: ='FS Desroches Daily'!AP14 -> 0.2 | Y12: ='FS Desroches Daily'!AR14 -> 90 | Z12: ='FS Desroches Daily'!AT14 -> 70 | AA12: ='FS Desroches Daily'!AT14 -> 70 | AB12: ='FS Desroches Daily'!AV14 -> 110 | AC12: ='FS Desroches Daily'!AZ14 -> 70 | AD12: ='FS Desroches Daily'!BB14 -> 90 | AE12: ='FS Desroches Daily'!BD14 -> 20 | AF12: ='FS Desroches Daily'!BF14 -> 49 | AG12: ='FS Desroches Daily'!BH14 -> 30 | AH12: ='FS Desroches Daily'!BJ14 -> 40 | AI12: ='FS Desroches Daily'!BL14 -> 30 | AJ12: ='FS Desroches Daily'!BN14 -> 40 | AK12: ='FS Desroches Daily'!BP14 -> 40 | AL12: ='FS Desroches Daily'!BR14 -> 33 | AM12: ='FS Desroches Daily'!BT14 -> 40 | AN12: ='FS Desroches Daily'!BV14 -> 34 | AO12: ='FS Desroches Daily'!BX14 -> 40 | AP12: ='FS Desroches Daily'!BZ14 -> 66 | AQ12: ='FS Desroches Daily'!CB14 -> 36.9 | AR12: ='FS Desroches Daily'!CD14 -> 12.4 | AS12: ='FS Desroches Daily'!CF14 -> 17.2 | AT12: ='FS Desroches Daily'!CH14 -> 61.6 | AU12: ='FS Desroches Daily'!CJ14 -> 282 | AV12: ='FS Desroches Daily'!CL14 -> 630 | AW12: ='FS Desroches Daily'!CM14 -> 106 | AX12: =IF(LPG!F19-LPG!F18<0,"0",(LPG!F19-LPG!F18)*1.8315) -> 10.989 | AY12: =IF(LPG!H19-LPG!H18<0,"0",(LPG!H19-LPG!H18)*1.8315) -> 3.663 | AZ12: =IF(LPG!J19-LPG!J18<0,"0",(LPG!J19-LPG!J18)*1.8315) -> 1.8315 | BA12: =IF(LPG!M19-LPG!M18<0,"0",(LPG!M19-LPG!M18)*1.8315) -> 5.4945 | BB12: =IF(LPG!Q19-LPG!Q18<0,"0",(LPG!Q19-LPG!Q18)*1.8315) -> 7.326 | BC12: ='FS Desroches Daily'!CN14 -> 21
A13: Seychelles at Desroches Island | B13: =B12+1 -> 12 | C13: 12 | D13: 2019 | E13: ='FS Desroches Daily'!D15 -> 2200 | F13: ='FS Desroches Daily'!F15 -> 3200 | G13: ='FS Desroches Daily'!H15 -> 3100 | H13: ='FS Desroches Daily'!J15 -> 1670 | I13: ='FS Desroches Daily'!L15 -> 2200 | J13: ='FS Desroches Daily'!N15 -> 1600 | K13: ='FS Desroches Daily'!P15 -> 17 | L13: ='FS Desroches Daily'!R15 -> 10 | M13: ='FS Desroches Daily'!T15 -> 1171 | N13: ='FS Desroches Daily'!V15 -> 509 | O13: ='FS Desroches Daily'!X15 -> 480 | P13: ='FS Desroches Daily'!Z15 -> 2700 | Q13: ='FS Desroches Daily'!AB15 -> 320 | R13: ='FS Desroches Daily'!AD15 -> 510 | S13: ='FS Desroches Daily'!AF15 -> 640 | T13: ='FS Desroches Daily'!AH15 -> 1.9 | U13: ='FS Desroches Daily'!AJ15 -> 420 | V13: ='FS Desroches Daily'!AL15 -> 0.23 | W13: ='FS Desroches Daily'!AN15 -> 0.21 | X13: ='FS Desroches Daily'!AP15 -> 0.2 | Y13: ='FS Desroches Daily'!AR15 -> 80 | Z13: ='FS Desroches Daily'!AT15 -> 70 | AA13: ='FS Desroches Daily'!AT15 -> 70 | AB13: ='FS Desroches Daily'!AV15 -> 250 | AC13: ='FS Desroches Daily'!AZ15 -> 50 | AD13: ='FS Desroches Daily'!BB15 -> 70 | AE13: ='FS Desroches Daily'!BD15 -> 30 | AF13: ='FS Desroches Daily'!BF15 -> 45 | AG13: ='FS Desroches Daily'!BH15 -> 40 | AH13: ='FS Desroches Daily'!BJ15 -> 50 | AI13: ='FS Desroches Daily'!BL15 -> 40 | AJ13: ='FS Desroches Daily'!BN15 -> 40 | AK13: ='FS Desroches Daily'!BP15 -> 50 | AL13: ='FS Desroches Daily'!BR15 -> 36 | AM13: ='FS Desroches Daily'!BT15 -> 40 | AN13: ='FS Desroches Daily'!BV15 -> 36 | AO13: ='FS Desroches Daily'!BX15 -> 40 | AP13: ='FS Desroches Daily'!BZ15 -> 67 | AQ13: ='FS Desroches Daily'!CB15 -> 37.6 | AR13: ='FS Desroches Daily'!CD15 -> 14.6 | AS13: ='FS Desroches Daily'!CF15 -> 19 | AT13: ='FS Desroches Daily'!CH15 -> 62.4 | AU13: ='FS Desroches Daily'!CJ15 -> 351 | AV13: ='FS Desroches Daily'!CL15 -> 750 | AW13: ='FS Desroches Daily'!CM15 -> 139.2 | AX13: =IF(LPG!F20-LPG!F19<0,"0",(LPG!F20-LPG!F19)*1.8315) -> 12.8205 | AY13: =IF(LPG!H20-LPG!H19<0,"0",(LPG!H20-LPG!H19)*1.8315) -> 1.8315 | AZ13: =IF(LPG!J20-LPG!J19<0,"0",(LPG!J20-LPG!J19)*1.8315) -> 1.8315 | BA13: =IF(LPG!M20-LPG!M19<0,"0",(LPG!M20-LPG!M19)*1.8315) -> 0 | BB13: =IF(LPG!Q20-LPG!Q19<0,"0",(LPG!Q20-LPG!Q19)*1.8315) -> 7.326 | BC13: ='FS Desroches Daily'!CN15 -> 27
A14: Seychelles at Desroches Island | B14: =B13+1 -> 13 | C14: 12 | D14: 2019 | E14: ='FS Desroches Daily'!D16 -> 2500 | F14: ='FS Desroches Daily'!F16 -> 3100 | G14: ='FS Desroches Daily'!H16 -> 3500 | H14: ='FS Desroches Daily'!J16 -> 1650 | I14: ='FS Desroches Daily'!L16 -> 2200 | J14: ='FS Desroches Daily'!N16 -> 1870 | K14: ='FS Desroches Daily'!P16 -> 25 | L14: ='FS Desroches Daily'!R16 -> 12 | M14: ='FS Desroches Daily'!T16 -> 991 | N14: ='FS Desroches Daily'!V16 -> 508 | O14: ='FS Desroches Daily'!X16 -> 410 | P14: ='FS Desroches Daily'!Z16 -> 2600 | Q14: ='FS Desroches Daily'!AB16 -> 510 | R14: ='FS Desroches Daily'!AD16 -> 580 | S14: ='FS Desroches Daily'!AF16 -> 700 | T14: ='FS Desroches Daily'!AH16 -> 2.3 | U14: ='FS Desroches Daily'!AJ16 -> 460 | V14: ='FS Desroches Daily'!AL16 -> 0.25 | W14: ='FS Desroches Daily'!AN16 -> 0.29 | X14: ='FS Desroches Daily'!AP16 -> 0.23 | Y14: ='FS Desroches Daily'!AR16 -> 50 | Z14: ='FS Desroches Daily'!AT16 -> 90 | AA14: ='FS Desroches Daily'!AT16 -> 90 | AB14: ='FS Desroches Daily'!AV16 -> 230 | AC14: ='FS Desroches Daily'!AZ16 -> 340 | AD14: ='FS Desroches Daily'!BB16 -> 70 | AE14: ='FS Desroches Daily'!BD16 -> 20 | AF14: ='FS Desroches Daily'!BF16 -> 55 | AG14: ='FS Desroches Daily'!BH16 -> 20 | AH14: ='FS Desroches Daily'!BJ16 -> 50 | AI14: ='FS Desroches Daily'!BL16 -> 50 | AJ14: ='FS Desroches Daily'!BN16 -> 40 | AK14: ='FS Desroches Daily'!BP16 -> 50 | AL14: ='FS Desroches Daily'!BR16 -> 43 | AM14: ='FS Desroches Daily'!BT16 -> 50 | AN14: ='FS Desroches Daily'!BV16 -> 39 | AO14: ='FS Desroches Daily'!BX16 -> 50 | AP14: ='FS Desroches Daily'!BZ16 -> 64 | AQ14: ='FS Desroches Daily'!CB16 -> 33.7 | AR14: ='FS Desroches Daily'!CD16 -> 8 | AS14: ='FS Desroches Daily'!CF16 -> 3.4 | AT14: ='FS Desroches Daily'!CH16 -> 50.3 | AU14: ='FS Desroches Daily'!CJ16 -> 360 | AV14: ='FS Desroches Daily'!CL16 -> 900 | AW14: ='FS Desroches Daily'!CM16 -> 121 | AX14: =IF(LPG!F21-LPG!F20<0,"0",(LPG!F21-LPG!F20)*1.8315) -> 16.4835 | AY14: =IF(LPG!H21-LPG!H20<0,"0",(LPG!H21-LPG!H20)*1.8315) -> 3.663 | AZ14: =IF(LPG!J21-LPG!J20<0,"0",(LPG!J21-LPG!J20)*1.8315) -> 0 | BA14: =IF(LPG!M21-LPG!M20<0,"0",(LPG!M21-LPG!M20)*1.8315) -> 7.326 | BB14: =IF(LPG!Q21-LPG!Q20<0,"0",(LPG!Q21-LPG!Q20)*1.8315) -> 3.663 | BC14: ='FS Desroches Daily'!CN16 -> 30
... A32: Seychelles at Desroches Island | B32: =B31+1 -> 31 | C32: 12 | D32: 2019 | E32: ='FS Desroches Daily'!D34 -> 0 | F32: ='FS Desroches Daily'!F34 -> 0 | G32: ='FS Desroches Daily'!H34 -> 0 | H32: ='FS Desroches Daily'!J34 -> 0 | I32: ='FS Desroches Daily'!L34 -> 0 | J32: ='FS Desroches Daily'!N34 -> 0 | K32: ='FS Desroches Daily'!P34 -> 0 | L32: ='FS Desroches Daily'!R34 -> 0 | M32: ='FS Desroches Daily'!T34 -> 0 | N32: ='FS Desroches Daily'!V34 -> 0 | O32: ='FS Desroches Daily'!X34 -> 0 | P32: ='FS Desroches Daily'!Z34 -> 0 | Q32: ='FS Desroches Daily'!AB34 -> 0 | R32: ='FS Desroches Daily'!AD34 -> 0 | S32: ='FS Desroches Daily'!AF34 -> 0 | T32: ='FS Desroches Daily'!AH34 -> 0 | U32: ='FS Desroches Daily'!AJ34 -> 0 | V32: ='FS Desroches Daily'!AL34 -> 0 | W32: ='FS Desroches Daily'!AN34 -> 0 | X32: ='FS Desroches Daily'!AP34 -> 0 | Y32: ='FS Desroches Daily'!AR34 -> 0 | Z32: ='FS Desroches Daily'!AT34 -> 0 | AA32: ='FS Desroches Daily'!AT34 -> 0 | AB32: ='FS Desroches Daily'!AV34 -> 0 | AC32: ='FS Desroches Daily'!AZ34 -> 0 | AD32: ='FS Desroches Daily'!BB34 -> 0 | AE32: ='FS Desroches Daily'!BD34 -> 0 | AF32: ='FS Desroches Daily'!BF34 -> 0 | AG32: ='FS Desroches Daily'!BH34 -> 0 | AH32: ='FS Desroches Daily'!BJ34 -> 0 | AI32: ='FS Desroches Daily'!BL34 -> 0 | AJ32: ='FS Desroches Daily'!BN34 -> 0 | AK32: ='FS Desroches Daily'!BP34 -> 0 | AL32: ='FS Desroches Daily'!BR34 -> 0 | AM32: ='FS Desroches Daily'!BT34 -> 0 | AN32: ='FS Desroches Daily'!BV34 -> 0 | AO32: ='FS Desroches Daily'!BX34 -> 0 | AP32: ='FS Desroches Daily'!BZ34 -> 0 | AQ32: ='FS Desroches Daily'!CB34 -> 0 | AR32: ='FS Desroches Daily'!CD34 -> 0 | AS32: ='FS Desroches Daily'!CF34 -> 0 | AT32: ='FS Desroches Daily'!CH34 -> 0 | AU32: ='FS Desroches Daily'!CJ34 -> 0 | AV32: ='FS Desroches Daily'!CL34 -> 0 | AW32: ='FS Desroches Daily'!CM34 -> 0 | AX32: =IF(LPG!F39-LPG!F38<0,"0",(LPG!F39-LPG!F38)*1.8315) -> 0 | AY32: =IF(LPG!H39-LPG!H38<0,"0",(LPG!H39-LPG!H38)*1.8315) -> 0 | AZ32: =IF(LPG!J39-LPG!J38<0,"0",(LPG!J39-LPG!J38)*1.8315) -> 0 | BA32: =IF(LPG!M39-LPG!M38<0,"0",(LPG!M39-LPG!M38)*1.8315) -> 0 | BB32: =IF(LPG!Q39-LPG!Q38<0,"0",(LPG!Q39-LPG!Q38)*1.8315) -> 0 | BC32: ='FS Desroches Daily'!CN34 -> 0
E33: =SUM(E2:E32) -> 50800 | F33: =SUM(F2:F32) -> 77500 | G33: =SUM(G2:G32) -> 76900 | H33: =SUM(H2:H32) -> 34760 | I33: =SUM(I2:I32) -> 59000 | J33: =SUM(J2:J32) -> 38300 | K33: =SUM(K2:K32) -> 451 | L33: =SUM(L2:L32) -> 179 | ... BC33: =SUM(BC2:BC32) -> 626
E35: =E33/E37 -> 0.18856859 | G35: =G33-M36 -> 38563 | AE35: =SUM(U33:AE33) -> 27882.87 | AG35: =SUM(AG33:AP33) -> 9488
G36: =G35-633*14 -> 29701 | M36: =M33+N33 -> 38337
E37: =E33+F33+G33+H33+J33-633*14 -> 269398 | G37: =M36/E37 -> 0.14230618 | M37: =AE35 -> 27882.87
L38: =M38/E37 -> 0.035219267 | M38: =AG35 -> 9488
E39: =19000/30 -> 633.33333

Sheet FS Desroches Daily
A1: Days | C1: TRF CQ6 (GWH) | E1: TRF FQ7 (GWH) | G1: MSB BOH Q8 (GWH) | I1: EX MAIN Q3 (MWH) | K1: TRF DQ2 (GWH) | M1: TRF B Q1 (MWH) | O1: CANCAN shop (KWH) | Q1: CANCAN store (KWH) | S1: laundry EQU P D.B (KWH) | U1: laundry lighting (KWH) | W1: PANTRY 1 MSB-F (MWH) | Y1: PANTRY 2 MSB-E M-kitchen (GWH) | AA1: SPA LIGHT HOUSE MSB-A1 (MWH) | AC1: PANTRY 3 MSB-A near v 22 (MWH) | AE1: PANTRY 4 MSB-B near v 33 (MWH) | AG1: VMC (KWH) | AI1: VILLA 100 (MWH) | AK1: VILLA 101 (KWH) | AM1: VILLA 102 (KWH) | AO1: VILLA 103 (KWH) | AQ1: VILLA 104 (MWH) | AS1: VILLA 105 (MWH) | AU1: VILLA 106 (MWH) | AW1: VILLA 107 (MWH) | AY1: VILLA 108 (MWH) | BA1: VILLA 109 (MWH) | BC1: VILLA 110 (MWH) | BE1: KUMAR& KUMAR | BG1: BLOCK 15 | BI1: BLOCK 16 | BK1: BLOCK 17 | BM1: BLOCK 18 | BO1: BLOCK 19 | BQ1: BLOCK 20 | BS1: BLOCK 21 | BU1: BLOCK 22 | BW1: BLOCK 23 | BY1: BLOCK 24 | CA1: Exhaust Kitchen (Main) | CC1: Exhaust Kitchen (Breakfast) | CE1: Exhaust Lighthouse | CG1: Exhaust Canteen | CI1: Cold Store | CK1: RO Plant | CM1: Water
A2: Date | C2: Reading GWH | D2: Difference KWH | E2: Reading GWH | F2: Difference KWH | G2: Reading GWH | H2: Difference KWH | I2: Reading MWH | J2: Difference KWH | K2: Reading GWH | L2: Difference KWH | M2: Reading MWH | N2: Difference KWH | O2: Reading KWH | P2: Difference KWH | Q2: Reading KWH | R2: Difference KWH | S2: Reading KWH | T2: Difference KWH | U2: Reading KWH | V2: Difference KWH | W2: Reading MWH | X2: Difference KWH | Y2: Reading GWH | Z2: Difference KWH | AA2: Reading MWH | AB2: Difference KWH | AC2: Reading MWH | AD2: Difference KWH | AE2: Reading MWH | AF2: Difference KWH | AG2: Reading KWH | AH2: Difference KWH | AI2: Reading MWH | AJ2: Difference KWH | AK2: Reading KWH | AL2: Difference KWH | AM2: Reading KWH | AN2: Difference KWH | AO2: Reading KWH | AP2: Difference KWH | AQ2: Reading MWH | AR2: Difference KWH | AS2: Reading MWH | AT2: Difference KWH | AU2: Reading MWH | AV2: Difference KWH | AW2: Reading MWH | AX2: Difference KWH | AY2: Reading MWH | AZ2: Difference KWH | BA2: Reading MWH | BB2: Difference KWH | BC2: Reading MWH | BD2: Difference KWH | BE2: Reading KWH | BF2: Difference KWH | BG2: Reading MWH | BH2: Difference KWH | BI2: Reading MWH | BJ2: Difference KWH | BK2: Reading MWH | BL2: Difference KWH | BM2: Reading MWH | BN2: Difference KWH | BO2: Reading MWH | BP2: Difference KWH | BQ2: Reading KWH | BR2: Difference KWH | BS2: Reading MWH | BT2: Difference KWH | BU2: Reading KWH | BV2: Difference KWH | BW2: Reading MWH | BX2: Difference KWH | BY2: Reading KWH | BZ2: Difference KWH | CA2: Reading KWH | CB2: Difference KWH | CC2: Reading KWH | CD2: Difference KWH | CE2: Reading KWH | CF2: Difference KWH | CG2: Reading KWH | CH2: Difference KWH | CI2: Reading KWH | CJ2: Difference KWH | CK2: Reading MWH | CL2: Difference KWH | CM2: m3 | CN2: ROOM NIGHTS | CO2: TOTAL GUESTS
A3: 43799 | C3: 1.3163 | E3: 2.2175 | G3: 2.0559 | I3: 959.14 | K3: 1.4674 | M3: 920.23 | O3: 10262 | Q3: 4080 | S3: 671888 | U3: 272003 | W3: 267.63 | Y3: 1.9707 | AA3: 264.18 | AC3: 241.55 | AE3: 351.74 | AG3: 929.3 | AI3: 333.79 | AK3: 114.06 | AM3: 115.96 | AO3: 115.53 | AQ3: 192.54 | AS3: 314.68 | AU3: 239.45 | AW3: 270.91 | AY3: 324.21 | BA3: 341.65 | BC3: 195.9 | BE3: 20597 | BG3: 218.35 | BI3: 274.38 | BK3: 222.26 | BM3: 205.52 | BO3: 269.02 | BQ3: 32427 | BS3: 186.58 | BU3: 23440 | BW3: 215.9 | BY3: 38567 | CA3: 22930.3 | CC3: 9814.3 | CE3: 4602.9 | CG3: 34740.3 | CI3: 805009 | CK3: 467.47 | CM3: 82 | CN3: 21 | CO3: 42
A4: 43800 | C4: 1.3177 | D4: =IF((C4-C3<0), "0",(C4-C3)*1000000) -> 1400 | E4: 2.2205 | F4: =IF((E4-E3<0), "0",(E4-E3)*1000000) -> 3000 | G4: 2.059 | H4: =IF((G4-G3<0), "0",(G4-G3)*1000000) -> 3100 | I4: 960.52 | J4: =IF((I4-I3<0), "0",(I4-I3)*1000) -> 1380 | K4: 1.47 | L4: =IF((K4-K3<0), "0",(K4-K3)*1000000) -> 2600 | M4: 921.92 | N4: =IF((M4-M3<0), "",(M4-M3)*1000) -> 1690 | O4: 10283 | P4: =IF((O4-O3<0), "",O4-O3) -> 21 | Q4: 4089 | R4: =IF((Q4-Q3<0), "",Q4-Q3) -> 9 | S4: 672674 | T4: =IF((S4-S3<0), "",S4-S3) -> 786 | U4: 272239 | V4: =IF((U4-U3<0), "",U4-U3) -> 236 | W4: 267.88 | X4: =IF((W4-W3<0), "",(W4-W3)*1000) -> 250 | Y4: 1.9733 | Z4: =IF((Y4-Y3<0), "",(Y4-Y3)*1000000) -> 2600 | AA4: 264.6 | AB4: =IF((AA4-AA3<0), "",(AA4-AA3)*1000) -> 420 | AC4: 241.88 | AD4: =IF((AC4-AC3<0), "",(AC4-AC3)*1000) -> 330 | AE4: 352.5 | AF4: =IF((AE4-AE3<0), "",(AE4-AE3)*1000) -> 760 | AG4: 930.9 | AH4: =IF((AG4-AG3<0), "",AG4-AG3) -> 1.6 | AI4: 334.16 | AJ4: =IF((AI4-AI3<0), "",(AI4-AI3)*1000) -> 370 | AK4: 114.11 | AL4: =IF((AK4-AK3<0), "",AK4-AK3) -> 0.05 | AM4: 116.13 | AN4: =IF((AM4-AM3<0), "",AM4-AM3) -> 0.17 | AO4: 115.62 | AP4: =IF((AO4-AO3<0), "",AO4-AO3) -> 0.09 | AQ4: 192.6 | AR4: =IF((AQ4-AQ3<0), "",(AQ4-AQ3)*1000) -> 60 | AS4: 314.74 | AT4: =IF((AS4-AS3<0), "",(AS4-AS3)*1000) -> 60 | AU4: 239.54 | AV4: =IF((AU4-AU3<0), "",(AU4-AU3)*1000) -> 90 | AW4: 271 | AX4: =IF((AW4-AW3<0), "",(AW4-AW3)*1000) -> 90 | AY4: 324.25 | AZ4: =IF((AY4-AY3<0), "",(AY4-AY3)*1000) -> 40 | BA4: 341.68 | BB4: =IF((BA4-BA3<0), "",(BA4-BA3)*1000) -> 30 | BC4: 195.9 | BD4: =IF((BC4-BC3<0), "",(BC4-BC3)*1000) -> 0 | BE4: 20649 | BF4: =IF((BE4-BE3<0), "",BE4-BE3) -> 52 | BG4: 218.37 | BH4: =IF((BG4-BG3<0), "",(BG4-BG3)*1000) -> 20 | BI4: 274.41 | BJ4: =IF((BI4-BI3<0), "",(BI4-BI3)*1000) -> 30 | BK4: 222.29 | BL4: =IF((BK4-BK3<0), "",(BK4-BK3)*1000) -> 30 | BM4: 205.55 | BN4: =IF((BM4-BM3<0), "",(BM4-BM3)*1000) -> 30 | BO4: 269.06 | BP4: =IF((BO4-BO3<0), "",(BO4-BO3)*1000) -> 40 | BQ4: 32557 | BR4: =IF((BQ4-BQ3<0), "",BQ4-BQ3) -> 130 | BS4: 186.61 | BT4: =IF((BS4-BS3<0), "",(BS4-BS3)*1000) -> 30 | BU4: 23465 | BV4: =IF((BU4-BU3<0), "",BU4-BU3) -> 25 | BW4: 215.93 | BX4: =IF((BW4-BW3<0), "",(BW4-BW3)*1000) -> 30 | BY4: 38614 | BZ4: =IF((BY4-BY3<0), "",BY4-BY3) -> 47 | CA4: 22958.8 | CB4: =IF((CA4-CA3<0), "",CA4-CA3) -> 28.5 | CC4: 9826.5 | CD4: =IF((CC4-CC3<0), "",CC4-CC3) -> 12.2 | CE4: 4618.5 | CF4: =IF((CE4-CE3<0), "",CE4-CE3) -> 15.6 | CG4: 34812.5 | CH4: =IF((CG4-CG3<0), "",CG4-CG3) -> 72.2 | CI4: 805267 | CJ4: =IF((CI4-CI3<0), "",CI4-CI3) -> 258 | CK4: 468.1 | CL4: =IF((CK4-CK3<0), "",(CK4-CK3)*1000) -> 630 | CM4: 75 | CN4: 24 | CO4: 46
A5: 43801 | C5: 1.3188 | D5: =IF((C5-C4<0), "0",(C5-C4)*1000000) -> 1100 | E5: 2.2231 | F5: =IF((E5-E4<0), "0",(E5-E4)*1000000) -> 2600 | G5: 2.0616 | H5: =IF((G5-G4<0), "0",(G5-G4)*1000000) -> 2600 | I5: 961.56 | J5: =IF((I5-I4<0), "0",(I5-I4)*1000) -> 1040 | K5: 1.4723 | L5: =IF((K5-K4<0), "0",(K5-K4)*1000000) -> 2300 | M5: 923.21 | N5: =IF((M5-M4<0), "",(M5-M4)*1000) -> 1290 | O5: 10301 | P5: =IF((O5-O4<0), "",O5-O4) -> 18 | Q5: 4097 | R5: =IF((Q5-Q4<0), "",Q5-Q4) -> 8 | S5: 673781 | T5: =IF((S5-S4<0), "",S5-S4) -> 1107 | U5: 272717 | V5: =IF((U5-U4<0), "",U5-U4) -> 478 | W5: 268.13 | X5: =IF((W5-W4<0), "",(W5-W4)*1000) -> 250 | Y5: 1.9758 | Z5: =IF((Y5-Y4<0), "",(Y5-Y4)*1000000) -> 2500 | AA5: 264.98 | AB5: =IF((AA5-AA4<0), "",(AA5-AA4)*1000) -> 380 | AC5: 242.13 | AD5: =IF((AC5-AC4<0), "",(AC5-AC4)*1000) -> 250 | AE5: 353.12 | AF5: =IF((AE5-AE4<0), "",(AE5-AE4)*1000) -> 620 | AG5: 932 | AH5: =IF((AG5-AG4<0), "",AG5-AG4) -> 1.1 | AI5: 334.43 | AJ5: =IF((AI5-AI4<0), "",(AI5-AI4)*1000) -> 270 | AK5: 114.18 | AL5: =IF((AK5-AK4<0), "",AK5-AK4) -> 0.07 | AM5: 116.26 | AN5: =IF((AM5-AM4<0), "",AM5-AM4) -> 0.13 | AO5: 115.7 | AP5: =IF((AO5-AO4<0), "",AO5-AO4) -> 0.08 | AQ5: 192.65 | AR5: =IF((AQ5-AQ4<0), "",(AQ5-AQ4)*1000) -> 50 | AS5: 314.81 | AT5: =IF((AS5-AS4<0), "",(AS5-AS4)*1000) -> 70 | AU5: 239.64 | AV5: =IF((AU5-AU4<0), "",(AU5-AU4)*1000) -> 100 | AW5: 271.08 | AX5: =IF((AW5-AW4<0), "",(AW5-AW4)*1000) -> 80 | AY5: 324.29 | AZ5: =IF((AY5-AY4<0), "",(AY5-AY4)*1000) -> 40 | BA5: 341.72 | BB5: =IF((BA5-BA4<0), "",(BA5-BA4)*1000) -> 40 | BC5: 195.93 | BD5: =IF((BC5-BC4<0), "",(BC5-BC4)*1000) -> 30 | BE5: 20709 | BF5: =IF((BE5-BE4<0), "",BE5-BE4) -> 60 | BG5: 218.39 | BH5: =IF((BG5-BG4<0), "",(BG5-BG4)*1000) -> 20 | BI5: 274.44 | BJ5: =IF((BI5-BI4<0), "",(BI5-BI4)*1000) -> 30 | BK5: 222.32 | BL5: =IF((BK5-BK4<0), "",(BK5-BK4)*1000) -> 30 | BM5: 205.58 | BN5: =IF((BM5-BM4<0), "",(BM5-BM4)*1000) -> 30 | BO5: 269.09 | BP5: =IF((BO5-BO4<0), "",(BO5-BO4)*1000) -> 30 | BQ5: 32582 | BR5: =IF((BQ5-BQ4<0), "",BQ5-BQ4) -> 25 | BS5: 186.64 | BT5: =IF((BS5-BS4<0), "",(BS5-BS4)*1000) -> 30 | BU5: 23490 | BV5: =IF((BU5-BU4<0), "",BU5-BU4) -> 25 | BW5: 215.95 | BX5: =IF((BW5-BW4<0), "",(BW5-BW4)*1000) -> 20 | BY5: 38650 | BZ5: =IF((BY5-BY4<0), "",BY5-BY4) -> 36 | CA5: 22987.2 | CB5: =IF((CA5-CA4<0), "",CA5-CA4) -> 28.4 | CC5: 9839.1 | CD5: =IF((CC5-CC4<0), "",CC5-CC4) -> 12.6 | CE5: 4633 | CF5: =IF((CE5-CE4<0), "",CE5-CE4) -> 14.5 | CG5: 34853.3 | CH5: =IF((CG5-CG4<0), "",CG5-CG4) -> 40.8 | CI5: 805500 | CJ5: =IF((CI5-CI4<0), "",CI5-CI4) -> 233 | CK5: 468.7 | CL5: =IF((CK5-CK4<0), "",(CK5-CK4)*1000) -> 600 | CM5: 67.9 | CN5: 22 | CO5: 42
A6: 43802 | C6: 1.32 | D6: =IF((C6-C5<0), "0",(C6-C5)*1000000) -> 1200 | E6: 2.226 | F6: =IF((E6-E5<0), "0",(E6-E5)*1000000) -> 2900 | G6: 2.0643 | H6: =IF((G6-G5<0), "0",(G6-G5)*1000000) -> 2700 | I6: 962.68 | J6: =IF((I6-I5<0), "0",(I6-I5)*1000) -> 1120 | K6: 1.4745 | L6: =IF((K6-K5<0), "0",(K6-K5)*1000000) -> 2200 | M6: 924.45 | N6: =IF((M6-M5<0), "",(M6-M5)*1000) -> 1240 | O6: 10320 | P6: =IF((O6-O5<0), "",O6-O5) -> 19 | Q6: 4097 | R6: =IF((Q6-Q5<0), "",Q6-Q5) -> 0 | S6: 673388 | T6: =IF((S6-S5<0), "",S6-S5) | U6: 273006 | V6: =IF((U6-U5<0), "",U6-U5) -> 289 | W6: 268.45 | Y6: 1.9783 | Z6: =IF((Y6-Y5<0), "",(Y6-Y5)*1000000) -> 2500 | AA6: 265.18 | AB6: =IF((AA6-AA5<0), "",(AA6-AA5)*1000) -> 200 | AC6: 242.42 | AD6: =IF((AC6-AC5<0), "",(AC6-AC5)*1000) -> 290 | AE6: 353.73 | AF6: =IF((AE6-AE5<0), "",(AE6-AE5)*1000) -> 610 | AG6: 933.2 | AH6: =IF((AG6-AG5<0), "",AG6-AG5) -> 1.2 | AI6: 334.71 | AJ6: =IF((AI6-AI5<0), "",(AI6-AI5)*1000) -> 280 | AK6: 114.26 | AL6: =IF((AK6-AK5<0), "",AK6-AK5) -> 0.08 | AM6: 116.39 | AN6: =IF((AM6-AM5<0), "",AM6-AM5) -> 0.13 | AO6: 115.39 | AP6: =IF((AO6-AO5<0), "",AO6-AO5) | AQ6: 192.69 | AR6: =IF((AQ6-AQ5<0), "",(AQ6-AQ5)*1000) -> 40 | AS6: 314.89 | AT6: =IF((AS6-AS5<0), "",(AS6-AS5)*1000) -> 80 | AU6: 239.75 | AV6: =IF((AU6-AU5<0), "",(AU6-AU5)*1000) -> 110 | AW6: 271.15 | AX6: =IF((AW6-AW5<0), "",(AW6-AW5)*1000) -> 70 | AY6: 324.32 | AZ6: =IF((AY6-AY5<0), "",(AY6-AY5)*1000) -> 30 | BA6: 341.76 | BB6: =IF((BA6-BA5<0), "",(BA6-BA5)*1000) -> 40 | BC6: 195.95 | BD6: =IF((BC6-BC5<0), "",(BC6-BC5)*1000) -> 20 | BE6: 20757 | BF6: =IF((BE6-BE5<0), "",BE6-BE5) -> 48 | BG6: 218.41 | BH6: =IF((BG6-BG5<0), "",(BG6-BG5)*1000) -> 20 | BI6: 274.46 | BJ6: =IF((BI6-BI5<0), "",(BI6-BI5)*1000) -> 20 | BK6: 222.35 | BL6: =IF((BK6-BK5<0), "",(BK6-BK5)*1000) -> 30 | BM6: 205.61 | BN6: =IF((BM6-BM5<0), "",(BM6-BM5)*1000) -> 30 | BO6: 269.11 | BP6: =IF((BO6-BO5<0), "",(BO6-BO5)*1000) -> 20 | BQ6: 32605 | BR6: =IF((BQ6-BQ5<0), "",BQ6-BQ5) -> 23 | BS6: 186.67 | BT6: =IF((BS6-BS5<0), "",(BS6-BS5)*1000) -> 30 | BU6: 23512 | BV6: =IF((BU6-BU5<0), "",BU6-BU5) -> 22 | BW6: 215.98 | BX6: =IF((BW6-BW5<0), "",(BW6-BW5)*1000) -> 30 | BY6: 38683 | BZ6: =IF((BY6-BY5<0), "",BY6-BY5) -> 33 | CA6: 23014.8 | CB6: =IF((CA6-CA5<0), "",CA6-CA5) -> 27.6 | CC6: 9851.7 | CD6: =IF((CC6-CC5<0), "",CC6-CC5) -> 12.6 | CE6: 4633.4 | CF6: =IF((CE6-CE5<0), "",CE6-CE5) -> 0.4 | CG6: 34904.3 | CH6: =IF((CG6-CG5<0), "",CG6-CG5) -> 51 | CI6: 805736 | CJ6: =IF((CI6-CI5<0), "",CI6-CI5) -> 236 | CK6: 469.37 | CL6: =IF((CK6-CK5<0), "",(CK6-CK5)*1000) -> 670 | CM6: 72 | CN6: 20 | CO6: 37
A7: 43803 | C7: 1.3213 | D7: =IF((C7-C6<0), "0",(C7-C6)*1000000) -> 1300 | E7: 2.2288 | F7: =IF((E7-E6<0), "0",(E7-E6)*1000000) -> 2800 | G7: 2.0672 | H7: =IF((G7-G6<0), "0",(G7-G6)*1000000) -> 2900 | I7: 963.86 | J7: =IF((I7-I6<0), "0",(I7-I6)*1000) -> 1180 | K7: 1.4768 | L7: =IF((K7-K6<0), "0",(K7-K6)*1000000) -> 2300 | M7: 925.81 | N7: =IF((M7-M6<0), "",(M7-M6)*1000) -> 1360 | O7: 10339 | P7: =IF((O7-O6<0), "",O7-O6) -> 19 | Q7: 4103 | R7: =IF((Q7-Q6<0), "",Q7-Q6) -> 6 | S7: 674536 | T7: =IF((S7-S6<0), "",S7-S6) -> 1148 | U7: 273347 | V7: =IF((U7-U6<0), "",U7-U6) -> 341 | W7: 268.77 | X7: =IF((W7-W6<0), "",(W7-W6)*1000) -> 320 | Y7: 1.9809 | Z7: =IF((Y7-Y6<0), "",(Y7-Y6)*1000000) -> 2600 | AA7: 265.57 | AB7: =IF((AA7-AA6<0), "",(AA7-AA6)*1000) -> 390 | AC7: 242.67 | AD7: =IF((AC7-AC6<0), "",(AC7-AC6)*1000) -> 250 | AE7: 354.35 | AF7: =IF((AE7-AE6<0), "",(AE7-AE6)*1000) -> 620 | AG7: 934.5 | AH7: =IF((AG7-AG6<0), "",AG7-AG6) -> 1.3 | AI7: 335 | AJ7: =IF((AI7-AI6<0), "",(AI7-AI6)*1000) -> 290 | AK7: 114.34 | AL7: =IF((AK7-AK6<0), "",AK7-AK6) -> 0.08 | AM7: 116.56 | AN7: =IF((AM7-AM6<0), "",AM7-AM6) -> 0.17 | AO7: 115.9 | AP7: =IF((AO7-AO6<0), "",AO7-AO6) -> 0.51 | AQ7: 192.74 | AR7: =IF((AQ7-AQ6<0), "",(AQ7-AQ6)*1000) -> 50 | AS7: 314.96 | AT7: =IF((AS7-AS6<0), "",(AS7-AS6)*1000) -> 70 | AU7: 239.86 | AV7: =IF((AU7-AU6<0), "",(AU7-AU6)*1000) -> 110 | AW7: 271.25 | AX7: =IF((AW7-AW6<0), "",(AW7-AW6)*1000) -> 100 | AY7: 324.36 | AZ7: =IF((AY7-AY6<0), "",(AY7-AY6)*1000) -> 40 | BA7: 341.79 | BB7: =IF((BA7-BA6<0), "",(BA7-BA6)*1000) -> 30 | BC7: 195.97 | BD7: =IF((BC7-BC6<0), "",(BC7-BC6)*1000) -> 20 | BE7: 20782 | BF7: =IF((BE7-BE6<0), "",BE7-BE6) -> 25 | BG7: 218.43 | BH7: =IF((BG7-BG6<0), "",(BG7-BG6)*1000) -> 20 | BI7: 274.49 | BJ7: =IF((BI7-BI6<0), "",(BI7-BI6)*1000) -> 30 | BK7: 222.39 | BL7: =IF((BK7-BK6<0), "",(BK7-BK6)*1000) -> 40 | BM7: 205.64 | BN7: =IF((BM7-BM6<0), "",(BM7-BM6)*1000) -> 30 | BO7: 269.14 | BP7: =IF((BO7-BO6<0), "",(BO7-BO6)*1000) -> 30 | BQ7: 32628 | BR7: =IF((BQ7-BQ6<0), "",BQ7-BQ6) -> 23 | BS7: 186.7 | BT7: =IF((BS7-BS6<0), "",(BS7-BS6)*1000) -> 30 | BU7: 23538 | BV7: =IF((BU7-BU6<0), "",BU7-BU6) -> 26 | BW7: 216.01 | BX7: =IF((BW7-BW6<0), "",(BW7-BW6)*1000) -> 30 | BY7: 38725 | BZ7: =IF((BY7-BY6<0), "",BY7-BY6) -> 42 | CA7: 23038 | CB7: =IF((CA7-CA6<0), "",CA7-CA6) -> 23.2 | CC7: 9857.3 | CD7: =IF((CC7-CC6<0), "",CC7-CC6) -> 5.6 | CE7: 4645 | CF7: =IF((CE7-CE6<0), "",CE7-CE6) -> 11.6 | CG7: 34996.6 | CH7: =IF((CG7-CG6<0), "",CG7-CG6) -> 92.3 | CI7: 805994 | CJ7: =IF((CI7-CI6<0), "",CI7-CI6) -> 258 | CK7: 470.06 | CL7: =IF((CK7-CK6<0), "",(CK7-CK6)*1000) -> 690 | CM7: 79 | CN7: 17 | CO7: 35
A8: 43804 | C8: 1.3227 | D8: =IF((C8-C7<0), "0",(C8-C7)*1000000) -> 1400 | E8: 2.2313 | F8: =IF((E8-E7<0), "0",(E8-E7)*1000000) -> 2500 | G8: 2.0699 | H8: =IF((G8-G7<0), "0",(G8-G7)*1000000) -> 2700 | I8: 965.07 | J8: =IF((I8-I7<0), "0",(I8-I7)*1000) -> 1210 | K8: 1.479 | L8: =IF((K8-K7<0), "0",(K8-K7)*1000000) -> 2200 | M8: 926.94 | N8: =IF((M8-M7<0), "",(M8-M7)*1000) -> 1130 | O8: 10357 | P8: =IF((O8-O7<0), "",O8-O7) -> 18 | Q8: 4109 | R8: =IF((Q8-Q7<0), "",Q8-Q7) -> 6 | S8: 676392 | T8: =IF((S8-S7<0), "",S8-S7) -> 1856 | U8: 273728 | V8: =IF((U8-U7<0), "",U8-U7) -> 381 | W8: 269.07 | X8: =IF((W8-W7<0), "",(W8-W7)*1000) -> 300 | Y8: 1.9831 | Z8: =IF((Y8-Y7<0), "",(Y8-Y7)*1000000) -> 2200 | AA8: 265.85 | AB8: =IF((AA8-AA7<0), "",(AA8-AA7)*1000) -> 280 | AC8: 242.94 | AD8: =IF((AC8-AC7<0), "",(AC8-AC7)*1000) -> 270 | AE8: 354.84 | AF8: =IF((AE8-AE7<0), "",(AE8-AE7)*1000) -> 490 | AG8: 935.8 | AH8: =IF((AG8-AG7<0), "",AG8-AG7) -> 1.3 | AI8: 335.31 | AJ8: =IF((AI8-AI7<0), "",(AI8-AI7)*1000) -> 310 | AK8: 114.42 | AL8: =IF((AK8-AK7<0), "",AK8-AK7) -> 0.08 | AM8: 116.7 | AN8: =IF((AM8-AM7<0), "",AM8-AM7) -> 0.14 | AO8: 115.99 | AP8: =IF((AO8-AO7<0), "",AO8-AO7) -> 0.09 | AQ8: 192.78 | AR8: =IF((AQ8-AQ7<0), "",(AQ8-AQ7)*1000) -> 40 | AS8: 315.04 | AT8: =IF((AS8-AS7<0), "",(AS8-AS7)*1000) -> 80 | AU8: 239.97 | AV8: =IF((AU8-AU7<0), "",(AU8-AU7)*1000) -> 110 | AW8: 271.35 | AX8: =IF((AW8-AW7<0), "",(AW8-AW7)*1000) -> 100 | AY8: 324.41 | AZ8: =IF((AY8-AY7<0), "",(AY8-AY7)*1000) -> 50 | BA8: 341.83 | BB8: =IF((BA8-BA7<0), "",(BA8-BA7)*1000) -> 40 | BC8: 195.99 | BD8: =IF((BC8-BC7<0), "",(BC8-BC7)*1000) -> 20 | BE8: 20803 | BF8: =IF((BE8-BE7<0), "",BE8-BE7) -> 21 | BG8: 218.45 | BH8: =IF((BG8-BG7<0), "",(BG8-BG7)*1000) -> 20 | BI8: 274.52 | BJ8: =IF((BI8-BI7<0), "",(BI8-BI7)*1000) -> 30 | BK8: 222.42 | BL8: =IF((BK8-BK7<0), "",(BK8-BK7)*1000) -> 30 | BM8: 205.67 | BN8: =IF((BM8-BM7<0), "",(BM8-BM7)*1000) -> 30 | BO8: 269.17 | BP8: =IF((BO8-BO7<0), "",(BO8-BO7)*1000) -> 30 | BQ8: 32654 | BR8: =IF((BQ8-BQ7<0), "",BQ8-BQ7) -> 26 | BS8: 186.72 | BT8: =IF((BS8-BS7<0), "",(BS8-BS7)*1000) -> 20 | BU8: 23558 | BV8: =IF((BU8-BU7<0), "",BU8-BU7) -> 20 | BW8: 216.04 | BX8: =IF((BW8-BW7<0), "",(BW8-BW7)*1000) -> 30 | BY8: 38782 | BZ8: =IF((BY8-BY7<0), "",BY8-BY7) -> 57 | CA8: 23054.8 | CB8: =IF((CA8-CA7<0), "",CA8-CA7) -> 16.8 | CC8: 9868 | CD8: =IF((CC8-CC7<0), "",CC8-CC7) -> 10.7 | CE8: 4645.3 | CF8: =IF((CE8-CE7<0), "",CE8-CE7) -> 0.3 | CG8: 35027.3 | CH8: =IF((CG8-CG7<0), "",CG8-CG7) -> 30.7 | CI8: 806242 | CJ8: =IF((CI8-CI7<0), "",CI8-CI7) -> 248 | CK8: 470.68 | CL8: =IF((CK8-CK7<0), "",(CK8-CK7)*1000) -> 620 | CM8: 77 | CN8: 4 | CO8: 18
A9: 43805 | C9: 1.3239 | D9: =IF((C9-C8<0), "0",(C9-C8)*1000000) -> 1200 | E9: 2.2341 | F9: =IF((E9-E8<0), "0",(E9-E8)*1000000) -> 2800 | G9: 2.073 | H9: =IF((G9-G8<0), "0",(G9-G8)*1000000) -> 3100 | I9: 966.46 | J9: =IF((I9-I8<0), "0",(I9-I8)*1000) -> 1390 | K9: 1.4814 | L9: =IF((K9-K8<0), "0",(K9-K8)*1000000) -> 2400 | M9: 928.2 | N9: =IF((M9-M8<0), "",(M9-M8)*1000) -> 1260 | O9: 10374 | P9: =IF((O9-O8<0), "",O9-O8) -> 17 | Q9: 4117 | R9: =IF((Q9-Q8<0), "",Q9-Q8) -> 8 | S9: 677295 | T9: =IF((S9-S8<0), "",S9-S8) -> 903 | U9: 274113 | V9: =IF((U9-U8<0), "",U9-U8) -> 385 | W9: 269.36 | X9: =IF((W9-W8<0), "",(W9-W8)*1000) -> 290 | Y9: 1.9855 | Z9: =IF((Y9-Y8<0), "",(Y9-Y8)*1000000) -> 2400 | AA9: 266.23 | AB9: =IF((AA9-AA8<0), "",(AA9-AA8)*1000) -> 380 | AC9: 243.2 | AD9: =IF((AC9-AC8<0), "",(AC9-AC8)*1000) -> 260 | AE9: 355.34 | AF9: =IF((AE9-AE8<0), "",(AE9-AE8)*1000) -> 500 | AG9: 936.9 | AH9: =IF((AG9-AG8<0), "",AG9-AG8) -> 1.1 | AI9: 335.63 | AJ9: =IF((AI9-AI8<0), "",(AI9-AI8)*1000) -> 320 | AK9: 114.51 | AL9: =IF((AK9-AK8<0), "",AK9-AK8) -> 0.09 | AM9: 116.85 | AN9: =IF((AM9-AM8<0), "",AM9-AM8) -> 0.15 | AO9: 116.07 | AP9: =IF((AO9-AO8<0), "",AO9-AO8) -> 0.08 | AQ9: 192.81 | AR9: =IF((AQ9-AQ8<0), "",(AQ9-AQ8)*1000) -> 30 | AS9: 315.12 | AT9: =IF((AS9-AS8<0), "",(AS9-AS8)*1000) -> 80 | AU9: 240.05 | AV9: =IF((AU9-AU8<0), "",(AU9-AU8)*1000) -> 80 | AW9: 271.43 | AX9: =IF((AW9-AW8<0), "",(AW9-AW8)*1000) -> 80 | AY9: 324.45 | AZ9: =IF((AY9-AY8<0), "",(AY9-AY8)*1000) -> 40 | BA9: 341.87 | BB9: =IF((BA9-BA8<0), "",(BA9-BA8)*1000) -> 40 | BC9: 196.01 | BD9: =IF((BC9-BC8<0), "",(BC9-BC8)*1000) -> 20 | BE9: 20848 | BF9: =IF((BE9-BE8<0), "",BE9-BE8) -> 45 | BG9: 218.47 | BH9: =IF((BG9-BG8<0), "",(BG9-BG8)*1000) -> 20 | BI9: 274.56 | BJ9: =IF((BI9-BI8<0), "",(BI9-BI8)*1000) -> 40 | BK9: 222.44 | BL9: =IF((BK9-BK8<0), "",(BK9-BK8)*1000) -> 20 | BM9: 205.7 | BN9: =IF((BM9-BM8<0), "",(BM9-BM8)*1000) -> 30 | BO9: 269.21 | BP9: =IF((BO9-BO8<0), "",(BO9-BO8)*1000) -> 40 | BQ9: 32682 | BR9: =IF((BQ9-BQ8<0), "",BQ9-BQ8) -> 28 | BS9: 186.76 | BT9: =IF((BS9-BS8<0), "",(BS9-BS8)*1000) -> 40 | BU9: 23578 | BV9: =IF((BU9-BU8<0), "",BU9-BU8) -> 20 | BW9: 216.07 | BX9: =IF((BW9-BW8<0), "",(BW9-BW8)*1000) -> 30 | BY9: 38843 | BZ9: =IF((BY9-BY8<0), "",BY9-BY8) -> 61 | CA9: 23076.3 | CB9: =IF((CA9-CA8<0), "",CA9-CA8) -> 21.5 | CC9: 9879.4 | CD9: =IF((CC9-CC8<0), "",CC9-CC8) -> 11.4 | CE9: 4655.4 | CF9: =IF((CE9-CE8<0), "",CE9-CE8) -> 10.1 | CG9: 35068.3 | CH9: =IF((CG9-CG8<0), "",CG9-CG8) -> 41 | CI9: 806521 | CJ9: =IF((CI9-CI8<0), "",CI9-CI8) -> 279 | CK9: 471.35 | CL9: =IF((CK9-CK8<0), "",(CK9-CK8)*1000) -> 670 | CM9: 78 | CN9: 7 | CO9: 20
