Workbook

Sheet Total
A1: Site Name | B1: Day | C1: Month | D1: Year | E1: Total Electricity Kwh | F1: Electricity Tariff ($/Kwh) | G1: Total Fuel Oil (Liters) | H1: Fuel Oil $/Liter | I1: LPG (Kg) | J1: LPG $/Kg | K1: Water Utility Supply (m3) m3 | L1: Water Utility Supply (m3) $/m3 | M1: Irrigation Water (m3) m3 | N1: Irrigation water $/m3 | O1: Room Nights
A2: Beirut | B2: 1 | C2: 12 | D2: 2019 | E2: =ELEC!N3 -> 14340.2 | F2: =SUM('EDl log'!T4) -> 0.033593648 | G2: =-tanks!AW6 -> 229 | H2: =SUM(tanks!AV6) -> 0.5337 | I2: =('B5'!AU5)*0.51 -> 30.6 | J2: ='B5'!AX5/0.51 -> 1.372549 | K2: =WATER!I6 -> 155 | L2: =SUM(WATER!J6) -> 1.5608741 | M2: =WATER!Q6 -> 0 | N2: 0.6 | O2: =ELEC!B3 -> 35.995
A3: Beirut | B3: =B2+1 -> 2 | C3: 12 | D3: 2019 | E3: =ELEC!N4 -> 14840 | F3: =SUM('EDl log'!T5) -> 0.08214287 | G3: =-tanks!AW7 -> 329 | H3: =SUM(tanks!AV7) -> 0.5337 | I3: =('B5'!AU6)*0.51 -> 76.5 | J3: ='B5'!AX6/0.51 -> 1.372549 | K3: =WATER!I7 -> 0 | L3: =SUM(WATER!J7) -> 0 | M3: =WATER!Q7 -> 0 | N3: 0.6 | O3: =ELEC!B4 -> 29.992
A4: Beirut | B4: =B3+1 -> 3 | C4: 12 | D4: 2019 | E4: =ELEC!N5 -> 15111 | F4: =SUM('EDl log'!T6) -> 0.082147141 | G4: =-tanks!AW8 -> 624.7 | H4: =SUM(tanks!AV8) -> 0.5337 | I4: =('B5'!AU7)*0.51 -> 45.9 | J4: ='B5'!AX7/0.51 -> 1.372549 | K4: =WATER!I8 -> 266 | L4: =SUM(WATER!J8) -> 1.4524642 | M4: =WATER!Q8 -> 0 | N4: 0.6 | O4: =ELEC!B5 -> 35.006
A5: Beirut | B5: =B4+1 -> 4 | C5: 12 | D5: 2019 | E5: =ELEC!N6 -> 15739 | F5: =SUM('EDl log'!T7) -> 0.075278175 | G5: =-tanks!AW9 -> 449.9 | H5: =SUM(tanks!AV9) -> 0.5337 | I5: =('B5'!AU8)*0.51 -> 168.3 | J5: ='B5'!AX8/0.51 -> 1.372549 | K5: =WATER!I9 -> 0 | L5: =SUM(WATER!J9) -> 0 | M5: =WATER!Q9 -> 0 | N5: 0.6 | O5: =ELEC!B6 -> 41.009
A6: Beirut | B6: =B5+1 -> 5 | C6: 12 | D6: 2019 | E6: =ELEC!N7 -> 13473 | F6: =SUM('EDl log'!T8) -> 0.093921303 | G6: =-tanks!AW10 -> 498 | H6: =SUM(tanks!AV10) -> 0.5337 | I6: =('B5'!AU9)*0.51 -> 163.2 | J6: ='B5'!AX9/0.51 -> 1.372549 | K6: =WATER!I10 -> 189 | L6: =SUM(WATER!J10) -> 1.2800819 | M6: =WATER!Q10 -> 0 | N6: 0.6 | O6: =ELEC!B7 -> 48.99
A7: Beirut | B7: =B6+1 -> 6 | C7: 12 | D7: 2019 | E7: =ELEC!N8 -> 14010.4 | F7: =SUM('EDl log'!T9) -> 0.093858029 | G7: =-tanks!AW11 -> 705.8 | H7: =SUM(tanks!AV11) -> 0.5337 | I7: =('B5'!AU10)*0.51 -> 15.3 | J7: ='B5'!AX10/0.51 -> 1.372549 | K7: =WATER!I11 -> 0 | L7: =SUM(WATER!J11) -> 0 | M7: =WATER!Q11 -> 0 | N7: 0.6 | O7: =ELEC!B8 -> 40.94
A8: Beirut | B8: =B7+1 -> 7 | C8: 12 | D8: 2019 | E8: =ELEC!N9 -> 15285.6 | F8: =SUM('EDl log'!T10) -> 0.08271187 | G8: =-tanks!AW12 -> 960.3 | H8: =SUM(tanks!AV12) -> 0.5337 | I8: =('B5'!AU11)*0.51 -> 45.9 | J8: ='B5'!AX11/0.51 -> 1.372549 | K8: =WATER!I12 -> 158 | L8: =SUM(WATER!J12) -> 1.5312372 | M8: =WATER!Q12 -> 0 | N8: 0.6 | O8: =ELEC!B9 -> 31.97
A9: Beirut | B9: =B8+1 -> 8 | C9: 12 | D9: 2019 | E9: =ELEC!N10 -> 16664 | F9: =SUM('EDl log'!T11) -> 0.065420619 | G9: =-tanks!AW13 -> 642 | H9: =SUM(tanks!AV13) -> 0.5337 | I9: =('B5'!AU12)*0.51 -> 0 | J9: ='B5'!AX12/0.51 -> 1.372549 | K9: =WATER!I13 -> 80 | L9: =SUM(WATER!J13) -> 4.6841935 | M9: =WATER!Q13 -> 0 | N9: 0.6 | O9: =ELEC!B10 -> 37.306
A10: Beirut | B10: =B9+1 -> 9 | C10: 12 | D10: 2019 | E10: =ELEC!N11 -> 13515 | F10: =SUM('EDl log'!T12) -> 0.087412424 | G10: =-tanks!AW14 -> 624 | H10: =SUM(tanks!AV14) -> 0.5337 | I10: =('B5'!AU13)*0.51 -> 198.9 | J10: ='B5'!AX13/0.51 -> 1.372549 | K10: =WATER!I14 -> 124 | L10: =SUM(WATER!J14) -> 3.0354475 | M10: =WATER!Q14 -> 0 | N10: 0.6 | O10: =ELEC!B11 -> 39.997
A11: Beirut | B11: =B10+1 -> 10 | C11: 12 | D11: 2019 | E11: =ELEC!N12 -> 15465 | F11: =SUM('EDl log'!T13) -> 0.075832705 | G11: =-tanks!AW15 -> 762.2 | H11: =SUM(tanks!AV15) -> 0.5337 | I11: =('B5'!AU14)*0.51 -> 76.5 | J11: ='B5'!AX14/0.51 -> 1.372549 | K11: =WATER!I15 -> 0 | L11: =SUM(WATER!J15) -> 0 | M11: =WATER!Q15 -> 0 | N11: 0.6 | O11: =ELEC!B12 -> 43.01
A12: Beirut | B12: =B11+1 -> 11 | C12: 12 | D12: 2019 | E12: =ELEC!N13 -> 13877 | F12: =SUM('EDl log'!T14) -> 0.086183857 | G12: =-tanks!AW16 -> 838.2 | H12: =SUM(tanks!AV16) -> 0.5337 | I12: =('B5'!AU15)*0.51 -> 91.8 | J12: ='B5'!AX15/0.51 -> 1.372549 | K12: =WATER!I16 -> 0 | L12: =SUM(WATER!J16) -> 0 | M12: =WATER!Q16 -> 0 | N12: 0.6 | O12: =ELEC!B13 -> 35.995
A13: Beirut | B13: =B12+1 -> 12 | C13: 12 | D13: 2019 | E13: =ELEC!N14 -> 14595 | F13: =SUM('EDl log'!T15) -> 0.016696053 | G13: =-tanks!AW17 -> 661 | H13: =SUM(tanks!AV17) -> 0.5271 | I13: =('B5'!AU16)*0.51 -> 163.2 | J13: ='B5'!AX16/0.51 -> 1.372549 | K13: =WATER!I17 -> 0 | L13: =SUM(WATER!J17) -> 0 | M13: =WATER!Q17 -> 0 | N13: 0.6 | O13: =ELEC!B14 -> 50.002
A14: Beirut | B14: =B13+1 -> 13 | C14: 12 | D14: 2019 | E14: =ELEC!N15 -> 15369 | F14: =SUM('EDl log'!T16) -> 0.081696924 | G14: =-tanks!AW18 -> 867 | H14: =SUM(tanks!AV18) -> 0.5271 | I14: =('B5'!AU17)*0.51 -> 137.7 | J14: ='B5'!AX17/0.51 -> 1.372549 | K14: =WATER!I18 -> 0 | L14: =SUM(WATER!J18) -> 0 | M14: =WATER!Q18 -> 0 | N14: 0.6 | O14: =ELEC!B15 -> 54.004
... A32: Beirut | B32: =B31+1 -> 31 | C32: 12 | D32: 2019 | E32: =ELEC!N33 -> 16085 | F32: =SUM('EDl log'!T34) -> 0.14031883 | G32: =-tanks!AW36 -> 1284.8 | H32: =SUM(tanks!AV36) -> 0.5634 | I32: =('B5'!AU35)*0.51 -> 137.7 | J32: ='B5'!AX35/0.51 -> 1.372549 | K32: =WATER!I36 -> 345 | L32: =SUM(WATER!J36) -> 1.3363927 | M32: =WATER!Q36 -> 0 | N32: 0.6 | O32: =ELEC!B33 -> 115

Sheet Submetering
A1: Site Name | B1: Day | C1: Month | D1: Year | E1: ATS1 Kwh | F1: ATS2 Kwh | G1: ATS3 Kwh | H1: ATS4 Kwh | I1: ATS5 Kwh | J1: Guest (m3) | K1: Kitchen & Laundry (m3) | L1: Room Nights
A2: Beirut | B2: 1 | C2: 12 | D2: 2019 | E2: =ELEC!M3 -> 3450 | F2: =ELEC!K3 -> 3210 | G2: =ELEC!I3 -> 2218 | H2: =ELEC!E3 -> 3450 | I2: =ELEC!G3 -> 2012.2 | J2: =WATER!Y6 -> 113 | K2: =WATER!AJ6 -> 35 | L2: =ELEC!B3 -> 35.995
A3: Beirut | B3: =B2+1 -> 2 | C3: 12 | D3: 2019 | E3: =ELEC!M4 -> 4524 | F3: =ELEC!K4 -> 2202 | G3: =ELEC!I4 -> 2244 | H3: =ELEC!E4 -> 3828 | I3: =ELEC!G4 -> 2042 | J3: =WATER!Y7 -> 27 | K3: =WATER!AJ7 -> 21 | L3: =ELEC!B4 -> 29.992
A4: Beirut | B4: =B3+1 -> 3 | C4: 12 | D4: 2019 | E4: =ELEC!M5 -> 4354 | F4: =ELEC!K5 -> 1416 | G4: =ELEC!I5 -> 2516 | H4: =ELEC!E5 -> 4548 | I4: =ELEC!G5 -> 2277 | J4: =WATER!Y8 -> 104 | K4: =WATER!AJ8 -> 78 | L4: =ELEC!B5 -> 35.006
A5: Beirut | B5: =B4+1 -> 4 | C5: 12 | D5: 2019 | E5: =ELEC!M6 -> 3900 | F5: =ELEC!K6 -> 2232 | G5: =ELEC!I6 -> 2650 | H5: =ELEC!E6 -> 4648 | I5: =ELEC!G6 -> 2309 | J5: =WATER!Y9 -> 1 | K5: =WATER!AJ9 -> 0 | L5: =ELEC!B6 -> 41.009
A6: Beirut | B6: =B5+1 -> 5 | C6: 12 | D6: 2019 | E6: =ELEC!M7 -> 3310 | F6: =ELEC!K7 -> 1824 | G6: =ELEC!I7 -> 2222 | H6: =ELEC!E7 -> 4060 | I6: =ELEC!G7 -> 2057 | J6: =WATER!Y10 -> 11 | K6: =WATER!AJ10 -> 38 | L6: =ELEC!B7 -> 48.99
A7: Beirut | B7: =B6+1 -> 6 | C7: 12 | D7: 2019 | E7: =ELEC!M8 -> 3446 | F7: =ELEC!K8 -> 2080 | G7: =ELEC!I8 -> 2504 | H7: =ELEC!E8 -> 3720 | I7: =ELEC!G8 -> 2260.4 | J7: =WATER!Y11 -> 28 | K7: =WATER!AJ11 -> 15 | L7: =ELEC!B8 -> 40.94
A8: Beirut | B8: =B7+1 -> 7 | C8: 12 | D8: 2019 | E8: =ELEC!M9 -> 4540 | F8: =ELEC!K9 -> 2520 | G8: =ELEC!I9 -> 2602 | H8: =ELEC!E9 -> 3377 | I8: =ELEC!G9 -> 2246.6 | J8: =WATER!Y12 -> 33 | K8: =WATER!AJ12 -> 57 | L8: =ELEC!B9 -> 31.97
A9: Beirut | B9: =B8+1 -> 8 | C9: 12 | D9: 2019 | E9: =ELEC!M10 -> 5412 | F9: =ELEC!K10 -> 1704 | G9: =ELEC!I10 -> 2798 | H9: =ELEC!E10 -> 4255 | I9: =ELEC!G10 -> 2495 | J9: =WATER!Y13 -> 80 | K9: =WATER!AJ13 -> 44 | L9: =ELEC!B10 -> 37.306
A10: Beirut | B10: =B9+1 -> 9 | C10: 12 | D10: 2019 | E10: =ELEC!M11 -> 3200 | F10: =ELEC!K11 -> 1756 | G10: =ELEC!I11 -> 2430 | H10: =ELEC!E11 -> 4060 | I10: =ELEC!G11 -> 2069 | J10: =WATER!Y14 -> 78 | K10: =WATER!AJ14 -> 59 | L10: =ELEC!B11 -> 39.997
A11: Beirut | B11: =B10+1 -> 10 | C11: 12 | D11: 2019 | E11: =ELEC!M12 -> 3872 | F11: =ELEC!K12 -> 2888 | G11: =ELEC!I12 -> 2722 | H11: =ELEC!E12 -> 3728 | I11: =ELEC!G12 -> 2255 | J11: =WATER!Y15 -> 19 | K11: =WATER!AJ15 -> 10 | L11: =ELEC!B12 -> 43.01
A12: Beirut | B12: =B11+1 -> 11 | C12: 12 | D12: 2019 | E12: =ELEC!M13 -> 3464 | F12: =ELEC!K13 -> 2582 | G12: =ELEC!I13 -> 2336 | H12: =ELEC!E13 -> 3320 | I12: =ELEC!G13 -> 2175 | J12: =WATER!Y16 -> 130 | K12: =WATER!AJ16 -> 75 | L12: =ELEC!B13 -> 35.995
A13: Beirut | B13: =B12+1 -> 12 | C13: 12 | D13: 2019 | E13: =ELEC!M14 -> 4710 | F13: =ELEC!K14 -> 1540 | G13: =ELEC!I14 -> 2592 | H13: =ELEC!E14 -> 3472 | I13: =ELEC!G14 -> 2281 | J13: =WATER!Y17 -> 0 | K13: =WATER!AJ17 -> 0 | L13: =ELEC!B14 -> 50.002
A14: Beirut | B14: =B13+1 -> 13 | C14: 12 | D14: 2019 | E14: =ELEC!M15 -> 5078 | F14: =ELEC!K15 -> 1666 | G14: =ELEC!I15 -> 2620 | H14: =ELEC!E15 -> 3724 | I14: =ELEC!G15 -> 2281 | J14: =WATER!Y18 -> 100 | K14: =WATER!AJ18 -> 44 | L14: =ELEC!B15 -> 54.004
... A32: Beirut | B32: =B31+1 -> 31 | C32: 12 | D32: 2019 | E32: =ELEC!M33 -> 4076 | F32: =ELEC!K33 -> 3048 | G32: =ELEC!I33 -> 2804 | H32: =ELEC!E33 -> 3678 | I32: =ELEC!G33 -> 2479 | J32: =WATER!Y36 -> 114 | K32: =WATER!AJ36 -> 94 | L32: =ELEC!B33 -> 115

Sheet ELEC
A1: OOC | B1: Room OCC | D1: MDB3 | E1: MDB3/day | F1: EMDB2 | G1: EMDB2/day | H1: EMDB1 | I1: EMDB1/day | J1: MDB2 | K1: mdb2/day | L1: MDB1 | M1: MDB1/Day | N1: Total KWH | O1: KWH/Rooc | P1: Gen MHW | Q1: Gen/Day KWH | R1: EDL KWH | S1: CH1 RH | T1: RH | U1: C1h1 power | V1: CH1 Con KWH | W1: CH2 RH | X1: RH | Y1: Ch2 power | Z1: CH2 Con KWH | AA1: CH3 RH | AB1: RH | AC1: Ch3 power | AD1: CH3 Con KWH | AE1: RH total | AF1: KWH total | AG1: AVG chiller KW/Hr
A2: 0.1391 | B2: 0.1391 | C2: 43799 | D2: =[1]ELEC!D32 -> 31186772 | E2: =[1]ELEC!E32 -> 4138 | F2: =[1]ELEC!F32 -> 3359570.8 | G2: =[1]ELEC!G32 -> 1999.6 | H2: =[1]ELEC!H32 -> 17141916 | I2: =[1]ELEC!I32 -> 2298 | J2: =[1]ELEC!J32 -> 28164866 | K2: =[1]ELEC!K32 -> 2448 | ... AI2: =[1]ELEC!AI32 -> -49039346
A3: ='General information '!F6 -> 0.1565 | B3: =SUM(230*A3) -> 35.995 | C3: 43800 | D3: 31190222 | E3: =D3-D2 -> 3450 | F3: 3361583 | G3: =F3-F2 -> 2012.2 | H3: 17144134 | I3: =H3-H2 -> 2218 | J3: 28168076 | K3: =J3-J2 -> 3210 | L3: 22389572 | M3: =L3-L2 -> 3450 | N3: =M3+K3+I3+G3+E3 -> 14340.2 | O3: =IF(B3>0,N3/B3,0) -> 398.39422 | P3: 15138.832 | Q3: =(P3-P2)*1000 -> 2532 | R3: =+N3-Q3 -> 11808.2 | S3: 8243 | T3: =S3-S2 -> 0 | U3: 997154 | V3: =U3-U2 -> 0 | W3: 31722 | X3: =W3-W2 -> 9 | Y3: 602126 | Z3: =Y3-Y2 -> 1608 | AA3: 34785 | AB3: =AA3-AA2 -> 1 | AC3: 723032 | AD3: =AC3-AC2 -> 172 | AE3: =AB3+X3+T3 -> 10 | AF3: =V3+Z3+AD3 -> 1780 | AG3: =IF(AE3>0,AF3/AE3,0) -> 178
A4: ='General information '!F7 -> 0.1304 | B4: =SUM(230*A4) -> 29.992 | C4: 43801 | D4: 31194050 | E4: =D4-D3 -> 3828 | F4: 3363625 | G4: =F4-F3 -> 2042 | H4: 17146378 | I4: =H4-H3 -> 2244 | J4: 28170278 | K4: =J4-J3 -> 2202 | L4: 22394096 | M4: =L4-L3 -> 4524 | N4: =M4+K4+I4+G4+E4 -> 14840 | O4: =IF(B4>0,N4/B4,0) -> 494.79861 | P4: 15141 | Q4: =(P4-P3)*1000 -> 2168 | R4: =N4-Q4 -> 12672 | S4: 8243 | T4: =S4-S3 -> 0 | U4: 997154 | V4: =U4-U3 -> 0 | W4: 31726 | X4: =W4-W3 -> 4 | Y4: 602797 | Z4: =Y4-Y3 -> 671 | AA4: 34786 | AB4: =AA4-AA3 -> 1 | AC4: 723180 | AD4: =AC4-AC3 -> 148 | AE4: =AB4+X4+T4 -> 5 | AF4: =V4+Z4+AD4 -> 819 | AG4: =IF(AE4>0,AF4/AE4,0) -> 163.8
A5: ='General information '!F8 -> 0.1522 | B5: =SUM(230*A5) -> 35.006 | C5: 43802 | D5: 31198598 | E5: =D5-D4 -> 4548 | F5: 3365902 | G5: =F5-F4 -> 2277 | H5: 17148894 | I5: =H5-H4 -> 2516 | J5: 28171694 | K5: =J5-J4 -> 1416 | L5: 22398450 | M5: =L5-L4 -> 4354 | N5: =M5+K5+I5+G5+E5 -> 15111 | O5: =IF(B5>0,N5/B5,0) -> 431.66886 | P5: 15143 | Q5: =(P5-P4)*1000 -> 2000 | R5: =N5-Q5 -> 13111 | S5: 8250 | T5: =S5-S4 -> 7 | U5: 998610 | V5: =U5-U4 -> 1456 | W5: 31726 | X5: =W5-W4 -> 0 | Y5: 602797 | Z5: =Y5-Y4 -> 0 | AA5: 34790 | AB5: =AA5-AA4 -> 4 | AC5: 723951 | AD5: =AC5-AC4 -> 771 | AE5: =AB5+X5+T5 -> 11 | AF5: =V5+Z5+AD5 -> 2227 | AG5: =IF(AE5>0,AF5/AE5,0) -> 202.45455 | AI5: =R5-'EDl log'!B3 -> -49058311
A6: ='General information '!F9 -> 0.1783 | B6: =SUM(230*A6) -> 41.009 | C6: 43803 | D6: 31203246 | E6: =D6-D5 -> 4648 | F6: 3368211 | G6: =F6-F5 -> 2309 | H6: 17151544 | I6: =H6-H5 -> 2650 | J6: 28173926 | K6: =J6-J5 -> 2232 | L6: 22402350 | M6: =L6-L5 -> 3900 | N6: =M6+K6+I6+G6+E6 -> 15739 | O6: =IF(B6>0,N6/B6,0) -> 383.7938 | P6: 15145.572 | Q6: =(P6-P5)*1000 -> 2572 | R6: =N6-Q6 -> 13167 | S6: 8250 | T6: =S6-S5 -> 0 | U6: 998610 | V6: =U6-U5 -> 0 | W6: 31729 | X6: =W6-W5 -> 3 | Y6: 603353 | Z6: =Y6-Y5 -> 556 | AA6: 34794 | AB6: =AA6-AA5 -> 4 | AC6: 724812 | AD6: =AC6-AC5 -> 861 | AE6: =AB6+X6+T6 -> 7 | AF6: =V6+Z6+AD6 -> 1417 | AG6: =IF(AE6>0,AF6/AE6,0) -> 202.42857 | AI6: =R6-'EDl log'!B4 -> -49064334
A7: ='General information '!F10 -> 0.213 | B7: =SUM(230*A7) -> 48.99 | C7: 43804 | D7: 31207306 | E7: =D7-D6 -> 4060 | F7: 3370268 | G7: =F7-F6 -> 2057 | H7: 17153766 | I7: =H7-H6 -> 2222 | J7: 28175750 | K7: =J7-J6 -> 1824 | L7: 22405660 | M7: =L7-L6 -> 3310 | N7: =M7+K7+I7+G7+E7 -> 13473 | O7: =IF(B7>0,N7/B7,0) -> 275.01531 | P7: 15148.07 | Q7: =(P7-P6)*1000 -> 2498 | R7: =N7-Q24 -> 11459 | S7: 8251 | T7: =S7-S6 -> 1 | U7: 998851 | V7: =U7-U6 -> 241 | W7: 31731 | X7: =W7-W6 -> 2 | Y7: 603870 | Z7: =Y7-Y6 -> 517 | AA7: 34797 | AB7: =AA7-AA6 -> 3 | AC7: 725528 | AD7: =AC7-AC6 -> 716 | AE7: =AB7+X7+T7 -> 6 | AF7: =V7+Z7+AD7 -> 1474 | AG7: =IF(AE7>0,AF7/AE7,0) -> 245.66667 | AI7: =R7-'EDl log'!B5 -> -49072542
A8: ='General information '!F11 -> 0.178 | B8: =SUM(230*A8) -> 40.94 | C8: 43805 | D8: 31211026 | E8: =D8-D7 -> 3720 | F8: 3372528.4 | G8: =F8-F7 -> 2260.4 | H8: 17156270 | I8: =H8-H7 -> 2504 | J8: 28177830 | K8: =J8-J7 -> 2080 | L8: 22409106 | M8: =L8-L7 -> 3446 | N8: =M8+K8+I8+G8+E8 -> 14010.4 | O8: =IF(B8>0,N8/B8,0) -> 342.21788 | P8: 15151.126 | Q8: =(P8-P7)*1000 -> 3056 | R8: =N8-Q8 -> 10954.4 | S8: =S7 -> 8251 | T8: =S8-S7 -> 0 | U8: =U7 -> 998851 | V8: =U8-U7 -> 0 | W8: 31734 | X8: =W8-W7 -> 3 | Y8: 604422 | Z8: =Y8-Y7 -> 552 | AA8: 34800 | AB8: =AA8-AA7 -> 3 | AC8: 726031 | AD8: =AC8-AC7 -> 503 | AE8: =AB8+X8+T8 -> 6 | AF8: =V8+Z8+AD8 -> 1055 | AG8: =IF(AE8>0,AF8/AE8,0) -> 175.83333 | AI8: =R8-'EDl log'!B6 -> -49079680
A9: ='General information '!F12 -> 0.139 | B9: =SUM(230*A9) -> 31.97 | C9: 43806 | D9: 31214403 | E9: =D9-D8 -> 3377 | F9: 3374775 | G9: =F9-F8 -> 2246.6 | H9: 17158872 | I9: =H9-H8 -> 2602 | J9: 28180350 | K9: =J9-J8 -> 2520 | L9: 22413646 | M9: =L9-L8 -> 4540 | N9: =M9+K9+I9+G9+E9 -> 15285.6 | O9: =IF(B9>0,N9/B9,0) -> 478.12324 | P9: 15153 | Q9: =(P9-P8)*1000 -> 1874 | R9: =N9-Q9 -> 13411.6 | S9: 8256 | T9: =S9-S8 -> 5 | U9: 999625 | V9: =U9-U8 -> 774 | W9: 31740 | X9: =W9-W8 -> 6 | Y9: 605454 | Z9: =Y9-Y8 -> 1032 | AA9: =AA8 -> 34800 | AB9: =AA9-AA8 -> 0 | AC9: =AC8 -> 726031 | AD9: =AC9-AC8 -> 0 | AE9: =AB9+X9+T9 -> 11 | AF9: =V9+Z9+AD9 -> 1806 | AG9: =IF(AE9>0,AF9/AE9,0) -> 164.18182 | AI9: =R9-'EDl log'!B7 -> -49084228
A10: ='General information '!F13 -> 0.1622 | B10: =SUM(230*A10) -> 37.306 | C10: 43807 | D10: 31218658 | E10: =D10-D9 -> 4255 | F10: 3377270 | G10: =F10-F9 -> 2495 | H10: 17161670 | I10: =H10-H9 -> 2798 | J10: 28182054 | K10: =J10-J9 -> 1704 | L10: 22419058 | M10: =L10-L9 -> 5412 | N10: =M10+K10+I10+G10+E10 -> 16664 | O10: =IF(B10>0,N10/B10,0) -> 446.68418 | P10: 15155 | Q10: =(P10-P9)*1000 -> 2000 | R10: =N10-Q10 -> 14664 | S10: 8261 | T10: =S10-S9 -> 5 | U10: 1000550 | V10: =U10-U9 -> 925 | W10: =W9 -> 31740 | X10: =W10-W9 -> 0 | Y10: =Y9 -> 605454 | Z10: =Y10-Y9 -> 0 | AA10: =AA9 -> 34800 | AB10: =AA10-AA9 -> 0 | AC10: =AC9 -> 726031 | AD10: =AC10-AC9 -> 0 | AE10: =AB10+X10+T10 -> 5 | AF10: =V10+Z10+AD10 -> 925 | AG10: =IF(AE10>0,AF10/AE10,0) -> 185 | AI10: =R10-'EDl log'!B8 -> -49088646
A11: ='General information '!F14 -> 0.1739 | B11: =SUM(230*A11) -> 39.997 | C11: 43808 | D11: 31222718 | E11: =D11-D10 -> 4060 | F11: 3379339 | G11: =F11-F10 -> 2069 | H11: 17164100 | I11: =H11-H10 -> 2430 | J11: 28183810 | K11: =J11-J10 -> 1756 | L11: 22422258 | M11: =L11-L10 -> 3200 | N11: =M11+K11+I11+G11+E11 -> 13515 | O11: =IF(B11>0,N11/B11,0) -> 337.90034 | P11: 15157.742 | Q11: =(P11-P10)*1000 -> 2742 | R11: =N11-Q11 -> 10773 | S11: 8261 | T11: =S11-S10 -> 0 | U11: 1000550 | V11: =U11-U10 -> 0 | W11: 31741 | X11: =W11-W10 -> 1 | Y11: 605655 | Z11: =Y11-Y10 -> 201 | AA11: 34806 | AB11: =AA11-AA10 -> 6 | AC11: 727030 | AD11: =AC11-AC10 -> 999 | AE11: =AB11+X11+T11 -> 7 | AF11: =V11+Z11+AD11 -> 1200 | AG11: =IF(AE11>0,AF11/AE11,0) -> 171.42857 | AI11: =R11-'EDl log'!B9 -> -49098226
A12: ='General information '!F15 -> 0.187 | B12: =SUM(230*A12) -> 43.01 | C12: 43809 | D12: 31226446 | E12: =D12-D11 -> 3728 | F12: 3381594 | G12: =F12-F11 -> 2255 | H12: 17166822 | I12: =H12-H11 -> 2722 | J12: 28186698 | K12: =J12-J11 -> 2888 | L12: 22426130 | M12: =L12-L11 -> 3872 | N12: =M12+K12+I12+G12+E12 -> 15465 | O12: =IF(B12>0,N12/B12,0) -> 359.56754 | P12: 15159.75 | Q12: =(P12-P11)*1000 -> 2008 | R12: =N12-Q12 -> 13457 | S12: 8261 | T12: =S12-S11 -> 0 | U12: =U11 -> 1000550 | V12: =U12-U11 -> 0 | W12: 31747 | X12: =W12-W11 -> 6 | Y12: 606821 | Z12: =Y12-Y11 -> 1166 | AA12: 34807 | AB12: =AA12-AA11 -> 1 | AC12: 727218 | AD12: =AC12-AC11 -> 188 | AE12: =AB12+X12+T12 -> 7 | AF12: =V12+Z12+AD12 -> 1354 | AG12: =IF(AE12>0,AF12/AE12,0) -> 193.42857 | AI12: =R12-'EDl log'!B10 -> -49102351
A13: ='General information '!F16 -> 0.1565 | B13: =SUM(230*A13) -> 35.995 | C13: 43810 | D13: 31229766 | E13: =D13-D12 -> 3320 | F13: 3383769 | G13: =F13-F12 -> 2175 | H13: 17169158 | I13: =H13-H12 -> 2336 | J13: 28189280 | K13: =J13-J12 -> 2582 | L13: 22429594 | M13: =L13-L12 -> 3464 | N13: =M13+K13+I13+G13+E13 -> 13877 | O13: =IF(B13>0,N13/B13,0) -> 385.52577 | P13: 15162.092 | Q13: =(P13-P12)*1000 -> 2342 | R13: =N13-Q13 -> 11535 | S13: 8263 | T13: =S13-S12 -> 2 | U13: 1000939 | V13: =U13-U12 -> 389 | W13: 31754 | X13: =W13-W12 -> 7 | Y13: 608041 | Z13: =Y13-Y12 -> 1220 | AA13: 34807 | AB13: =AA13-AA12 -> 0 | AC13: 727224 | AD13: =AC13-AC12 -> 6 | AE13: =AB13+X13+T13 -> 9 | AF13: =V13+Z13+AD13 -> 1615 | AG13: =IF(AE13>0,AF13/AE13,0) -> 179.44444 | AI13: =R13-'EDl log'!B11 -> -49111708
A14: ='General information '!F17 -> 0.2174 | B14: =SUM(230*A14) -> 50.002 | C14: 43811 | D14: 31233238 | E14: =D14-D13 -> 3472 | F14: 3386050 | G14: =F14-F13 -> 2281 | H14: 17171750 | I14: =H14-H13 -> 2592 | J14: 28190820 | K14: =J14-J13 -> 1540 | L14: 22434304 | M14: =L14-L13 -> 4710 | N14: =M14+K14+I14+G14+E14 -> 14595 | O14: =IF(B14>0,N14/B14,0) -> 291.88832 | P14: 15164 | Q14: =(P14-P13)*1000 -> 1908 | R14: =N14-Q14 -> 12687 | S14: 8268 | T14: =S14-S13 -> 5 | U14: 1001888 | V14: =U14-U13 -> 949 | W14: =W13 -> 31754 | X14: =W14-W13 -> 0 | Y14: =Y13 -> 608041 | Z14: =Y14-Y13 -> 0 | AA14: 34807 | AB14: =AA14-AA13 -> 0 | AC14: 727224 | AD14: =AC14-AC13 -> 0 | AE14: =AB14+X14+T14 -> 5 | AF14: =V14+Z14+AD14 -> 949 | AG14: =IF(AE14>0,AF14/AE14,0) -> 189.8 | AI14: =R14-'EDl log'!B12 -> -49116423
A15: ='General information '!F18 -> 0.2348 | B15: =SUM(230*A15) -> 54.004 | C15: 43812 | D15: 31236962 | E15: =D15-D14 -> 3724 | F15: 3388331 | G15: =F15-F14 -> 2281 | H15: 17174370 | I15: =H15-H14 -> 2620 | J15: 28192486 | K15: =J15-J14 -> 1666 | L15: 22439382 | M15: =L15-L14 -> 5078 | N15: =M15+K15+I15+G15+E15 -> 15369 | O15: =IF(B15>0,N15/B15,0) -> 284.59003 | P15: 15167.365 | Q15: =(P15-P14)*1000 -> 3365 | R15: =N15-Q15 -> 12004 | S15: 8274 | T15: =S15-S14 -> 6 | U15: 1003357 | V15: =U15-U14 -> 1469 | W15: =W14 -> 31754 | X15: =W15-W14 -> 0 | Y15: =Y14 -> 608041 | Z15: =Y15-Y14 -> 0 | AA15: 34807 | AB15: =AA15-AA14 -> 0 | AC15: 727224 | AD15: =AC15-AC14 -> 0 | AE15: =AB15+X15+T15 -> 6 | AF15: =V15+Z15+AD15 -> 1469 | AG15: =IF(AE15>0,AF15/AE15,0) -> 244.83333 | AI15: =R15-'EDl log'!B13 -> -49124045
A16: ='General information '!F19 -> 0.1696 | B16: =SUM(230*A16) -> 39.008 | C16: 43813 | D16: 31241914 | E16: =D16-D15 -> 4952 | F16: 3390622 | G16: =F16-F15 -> 2291 | H16: 17176926 | I16: =H16-H15 -> 2556 | J16: 28194198 | K16: =J16-J15 -> 1712 | L16: 22443578 | M16: =L16-L15 -> 4196 | N16: =M16+K16+I16+G16+E16 -> 15707 | O16: =IF(B16>0,N16/B16,0) -> 402.66099 | P16: 15170 | Q16: =(P16-P15)*1000 -> 2635 | R16: =N16-Q16 -> 13072 | S16: 8276 | T16: =S16-S15 -> 2 | U16: 1003625 | V16: =U16-U15 -> 268 | W16: =W15 -> 31754 | X16: =W16-W15 -> 0 | Y16: =Y15 -> 608041 | Z16: =Y16-Y15 -> 0 | AA16: 34814 | AB16: =AA16-AA15 -> 7 | AC16: 728587 | AD16: =AC16-AC15 -> 1363 | AE16: =AB16+X16+T16 -> 9 | AF16: =V16+Z16+AD16 -> 1631 | AG16: =IF(AE16>0,AF16/AE16,0) -> 181.22222 | AI16: =R16-'EDl log'!B14 -> -49128902
A17: ='General information '!F20 -> 0.1652 | B17: =SUM(230*A17) -> 37.996 | C17: 43814 | D17: 31244638 | E17: =D17-D16 -> 2724 | F17: 3392505 | G17: =F17-F16 -> 1883 | H17: 17178990 | I17: =H17-H16 -> 2064 | J17: 28195700 | K17: =J17-J16 -> 1502 | L17: 22448270 | M17: =L17-L16 -> 4692 | N17: =M17+K17+I17+G17+E17 -> 12865 | O17: =IF(B17>0,N17/B17,0) -> 338.58827 | P17: 15173.151 | Q17: =(P17-P16)*1000 -> 3151 | R17: =N17-Q17 -> 9714 | S17: 8281 | T17: =S17-S16 -> 5 | U17: 1004738 | V17: =U17-U16 -> 1113 | W17: =W16 -> 31754 | X17: =W17-W16 -> 0 | Y17: =Y16 -> 608041 | Z17: =Y17-Y16 -> 0 | AA17: 34814 | AB17: =AA17-AA16 -> 0 | AC17: 728587 | AD17: =AC17-AC16 -> 0 | AE17: =AB17+X17+T17 -> 5 | AF17: =V17+Z17+AD17 -> 1113 | AG17: =IF(AE17>0,AF17/AE17,0) -> 222.6 | AI17: =R17-'EDl log'!B15 -> -49138374
A18: ='General information '!F21 -> 0.139 | B18: =SUM(230*A18) -> 31.97 | C18: 43815 | D18: 31248006 | E18: =D18-D17 -> 3368 | F18: 3394920 | G18: =F18-F17 -> 2415 | H18: 17181474 | I18: =H18-H17 -> 2484 | J18: 28197594 | K18: =J18-J17 -> 1894 | L18: 22453650 | M18: =L18-L17 -> 5380 | N18: =M18+K18+I18+G18+E18 -> 15541 | O18: =IF(B18>0,N18/B18,0) -> 486.11198 | P18: 15175 | Q18: =(P18-P17)*1000 -> 1849 | R18: =N18-Q18 -> 13692 | S18: 8289 | T18: =S18-S17 -> 8 | U18: 1006290 | V18: =U18-U17 -> 1552 | W18: =W17 -> 31754 | X18: =W18-W17 -> 0 | Y18: =Y17 -> 608041 | Z18: =Y18-Y17 -> 0 | AA18: 34815 | AB18: =AA18-AA17 -> 1 | AC18: 728865 | AD18: =AC18-AC17 -> 278 | AE18: =AB18+X18+T18 -> 9 | AF18: =V18+Z18+AD18 -> 1830 | AG18: =IF(AE18>0,AF18/AE18,0) -> 203.33333 | AI18: =R18-'EDl log'!B16 -> -49141112
A19: ='General information '!F22 -> 0.1522 | B19: =SUM(230*A19) -> 35.006 | C19: 43816 | D19: 31251974 | E19: =D19-D18 -> 3968 | F19: 3397263.6 | G19: =F19-F18 -> 2343.6 | H19: 17183904 | I19: =H19-H18 -> 2430 | J19: 28199448 | K19: =J19-J18 -> 1854 | L19: 22458564 | M19: =L19-L18 -> 4914 | N19: =M19+K19+I19+G19+E19 -> 15509.6 | O19: =IF(B19>0,N19/B19,0) -> 443.05548 | P19: 15178.213 | Q19: =(P19-P18)*1000 -> 3213 | R19: =N19-Q19 -> 12296.6 | S19: 8295 | T19: =S19-S18 -> 6 | U19: 1007268 | V19: =U19-U18 -> 978 | W19: 31756 | X19: =W19-W18 -> 2 | Y19: 608569 | Z19: =Y19-Y18 -> 528 | AA19: 34818 | AB19: =AA19-AA18 -> 3 | AC19: 729401 | AD19: =AC19-AC18 -> 536 | AE19: =AB19+X19+T19 -> 11 | AF19: =V19+Z19+AD19 -> 2042 | AG19: =IF(AE19>0,AF19/AE19,0) -> 185.63636 | AI19: =R19-'EDl log'!B17 -> -49148889
A20: ='General information '!F23 -> 0.1696 | B20: =SUM(230*A20) -> 39.008 | C20: 43817 | D20: 31256188 | E20: =D20-D19 -> 4214 | F20: 3399524 | G20: =F20-F19 -> 2260.4 | H20: 17186358 | I20: =H20-H19 -> 2454 | J20: 28201890 | K20: =J20-J19 -> 2442 | L20: 22462278 | M20: =L20-L19 -> 3714 | N20: =M20+K20+I20+G20+E20 -> 15084.4 | O20: =IF(B20>0,N20/B20,0) -> 386.70016 | P20: 15180.468 | Q20: =(P20-P19)*1000 -> 2255 | R20: =N20-Q20 -> 12829.4 | S20: 8295 | T20: =S20-S19 -> 0 | U20: 1007268 | V20: =U20-U19 -> 0 | W20: 31756 | X20: =W20-W19 -> 0 | Y20: 609395 | Z20: =Y20-Y19 -> 826 | AA20: 34822 | AB20: =AA20-AA19 -> 4 | AC20: 730176 | AD20: =AC20-AC19 -> 775 | AE20: =AB20+X20+T20 -> 4 | AF20: =V20+Z20+AD20 -> 1601 | AG20: =IF(AE20>0,AF20/AE20,0) -> 400.25 | AI20: =R20-'EDl log'!B18 -> -49153814
A21: ='General information '!F24 -> 0.1739 | B21: =SUM(230*A21) -> 39.997 | C21: 43818 | D21: 31260094 | E21: =D21-D20 -> 3906 | F21: 3401960 | G21: =F21-F20 -> 2436 | H21: 17189050 | I21: =H21-H20 -> 2692 | J21: 28204438 | K21: =J21-J20 -> 2548 | L21: 22466890 | M21: =L21-L20 -> 4612 | N21: =M21+K21+I21+G21+E21 -> 16194 | O21: =IF(B21>0,N21/B21,0) -> 404.88037 | P21: 15182.561 | Q21: =(P21-P20)*1000 -> 2093 | R21: =N21-Q21 -> 14101 | S21: 8299 | T21: =S21-S20 -> 4 | U21: 1007937 | V21: =U21-U20 -> 669 | W21: 31764 | X21: =W21-W20 -> 8 | Y21: 610237 | Z21: =Y21-Y20 -> 842 | AA21: 34823 | AB21: =AA21-AA20 -> 1 | AC21: 730342 | AD21: =AC21-AC20 -> 166 | AE21: =AB21+X21+T21 -> 13 | AF21: =V21+Z21+AD21 -> 1677 | AG21: =IF(AE21>0,AF21/AE21,0) -> 129 | AI21: =R21-'EDl log'!B19 -> -49159251
A22: ='General information '!F25 -> 0.2478 | B22: =SUM(230*A22) -> 56.994 | C22: 43819 | D22: 31264518 | E22: =D22-D21 -> 4424 | F22: 3404378 | G22: =F22-F21 -> 2418 | H22: 17191568 | I22: =H22-H21 -> 2518 | J22: 28207352 | K22: =J22-J21 -> 2914 | L22: 22470576 | M22: =L22-L21 -> 3686 | N22: =M22+K22+I22+G22+E22 -> 15960 | O22: =IF(B22>0,N22/B22,0) -> 280.02948 | P22: 15185.235 | Q22: =(P22-P21)*1000 -> 2674 | R22: =N22-Q22 -> 13286 | S22: 8299 | T22: =S22-S21 -> 0 | U22: =U21 -> 1007937 | V22: =U22-U21 -> 0 | W22: 31771 | X22: =W22-W21 -> 7 | Y22: 611383 | Z22: =Y22-Y21 -> 1146 | AA22: 34827 | AB22: =AA22-AA21 -> 4 | AC22: 731256 | AD22: =AC22-AC21 -> 914 | AE22: =AB22+X22+T22 -> 11 | AF22: =V22+Z22+AD22 -> 2060 | AG22: =IF(AE22>0,AF22/AE22,0) -> 187.27273 | AI22: =R22-'EDl log'!B20 -> -49166753
A23: ='General information '!F26 -> 0.1826 | B23: =SUM(230*A23) -> 41.998 | C23: 43820 | D23: 31267894 | E23: =D23-D22 -> 3376 | F23: 3406655.2 | G23: =F23-F22 -> 2277.2 | H23: 17194074 | I23: =H23-H22 -> 2506 | J23: 28209816 | K23: =J23-J22 -> 2464 | L23: 22474218 | M23: =L23-L22 -> 3642 | N23: =M23+K23+I23+G23+E23 -> 14265.2 | O23: =IF(B23>0,N23/B23,0) -> 339.66379 | P23: 15187.7 | Q23: =(P23-P22)*1000 -> 2465 | R23: =N23-Q23 -> 11800.2 | S23: 8300 | T23: =S23-S22 -> 1 | U23: 1008255 | V23: =U23-U22 -> 318 | W23: 31775 | X23: =W23-W22 -> 4 | Y23: 612256 | Z23: =Y23-Y22 -> 873 | AA23: 34828 | AB23: =AA23-AA22 -> 1 | AC23: 731481 | AD23: =AC23-AC22 -> 225 | AE23: =AB23+X23+T23 -> 6 | AF23: =V23+Z23+AD23 -> 1416 | AG23: =IF(AE23>0,AF23/AE23,0) -> 236 | AI23: =R23-'EDl log'!B21 -> -49174888
A24: ='General information '!F27 -> 0.2609 | B24: =SUM(230*A24) -> 60.007 | C24: 43821 | D24: 31272316 | E24: =D24-D23 -> 4422 | F24: 3409014 | G24: =F24-F23 -> 2358.8 | H24: 17196654 | I24: =H24-H23 -> 2580 | J24: 28211594 | K24: =J24-J23 -> 1778 | L24: 22478254 | M24: =L24-L23 -> 4036 | N24: =M24+K24+I24+G24+E24 -> 15174.8 | O24: =IF(B24>0,N24/B24,0) -> 252.88383 | P24: 15189.714 | Q24: =(P24-P23)*1000 -> 2014 | R24: =N24-Q24 -> 13160.8 | S24: 8301 | T24: =S24-S23 -> 1 | U24: 1008471 | V24: =U24-U23 -> 216 | W24: 31775 | X24: =W24-W23 -> 0 | Y24: 612256 | Z24: =Y24-Y23 -> 0 | AA24: 34833 | AB24: =AA24-AA23 -> 5 | AC24: 732546 | AD24: =AC24-AC23 -> 1065 | AE24: =AB24+X24+T24 -> 6 | AF24: =V24+Z24+AD24 -> 1281 | AG24: =IF(AE24>0,AF24/AE24,0) -> 213.5 | AI24: =R24-'EDl log'!B22 -> -49180843
A25: ='General information '!F28 -> 0.2565 | B25: =SUM(230*A25) -> 58.995 | C25: 43822 | D25: 31276616 | E25: =D25-D24 -> 4300 | F25: 3411391.2 | G25: =F25-F24 -> 2377.2 | H25: 17199264 | I25: =H25-H24 -> 2610 | J25: 28213838 | K25: =J25-J24 -> 2244 | L25: 22484236 | M25: =L25-L24 -> 5982 | N25: =M25+K25+I25+G25+E25 -> 17513.2 | O25: =IF(B25>0,N25/B25,0) -> 296.85906 | P25: 15193.016 | Q25: =(P25-P24)*1000 -> 3302 | R25: =N25-Q25 -> 14211.2 | S25: 8308 | T25: =S25-S24 -> 7 | U25: 1010079 | V25: =U25-U24 -> 1608 | W25: 31779 | X25: =W25-W24 -> 4 | Y25: 612978 | Z25: =Y25-Y24 -> 722 | AA25: 34834 | AB25: =AA25-AA24 -> 1 | AC25: 732838 | AD25: =AC25-AC24 -> 292 | AE25: =AB25+X25+T25 -> 12 | AF25: =V25+Z25+AD25 -> 2622 | AG25: =IF(AE25>0,AF25/AE25,0) -> 218.5 | AI25: =R25-'EDl log'!B23 -> -49186639
A26: ='General information '!F29 -> 0.2174 | B26: =SUM(230*A26) -> 50.002 | C26: 43823 | D26: 31280234 | E26: =D26-D25 -> 3618 | F26: 3413858 | G26: =F26-F25 -> 2466.8 | H26: 17201710 | I26: =H26-H25 -> 2446 | J26: 28215286 | K26: =J26-J25 -> 1448 | L26: 22489650 | M26: =L26-L25 -> 5414 | N26: =M26+K26+I26+G26+E26 -> 15392.8 | O26: =IF(B26>0,N26/B26,0) -> 307.84369 | P26: 15195 | Q26: =(P26-P25)*1000 -> 1984 | R26: =N26-Q26 -> 13408.8 | S26: 8315 | T26: =S26-S25 -> 7 | U26: 1011339 | V26: =U26-U25 -> 1260 | W26: =W25 -> 31779 | X26: =W26-W25 -> 0 | Y26: =Y25 -> 612978 | Z26: =Y26-Y25 -> 0 | AA26: =AA25 -> 34834 | AB26: =AA26-AA25 -> 0 | AC26: =AC25 -> 732838 | AD26: =AC26-AC25 -> 0 | AE26: =AB26+X26+T26 -> 7 | AF26: =V26+Z26+AD26 -> 1260 | AG26: =IF(AE26>0,AF26/AE26,0) -> 180 | AI26: =R26-'EDl log'!B24 -> -49193514
A27: ='General information '!F30 -> 0.2043 | B27: =SUM(230*A27) -> 46.989 | C27: 43824 | D27: 31283878 | E27: =D27-D26 -> 3644 | F27: 3416254 | G27: =F27-F26 -> 2396 | H27: 17204112 | I27: =H27-H26 -> 2402 | J27: 28216598 | K27: =J27-J26 -> 1312 | L27: 22493590 | M27: =L27-L26 -> 3940 | N27: =M27+K27+I27+G27+E27 -> 13694 | O27: =IF(B27>0,N27/B27,0) -> 291.42991 | P27: 15198 | Q27: =(P27-P26)*1000 -> 3000 | R27: =N27-Q27 -> 10694 | S27: 8315 | T27: =S27-S26 -> 0 | U27: 1011339 | V27: =U27-U26 -> 0 | W27: 31779 | X27: =W27-W26 -> 0 | Y27: 612978 | Z27: =Y27-Y26 -> 0 | AA27: 34840 | AB27: =AA27-AA26 -> 6 | AC27: 733811 | AD27: =AC27-AC26 -> 973 | AE27: =AB27+X27+T27 -> 6 | AF27: =V27+Z27+AD27 -> 973 | AG27: =IF(AE27>0,AF27/AE27,0) -> 162.16667 | AI27: =R27-'EDl log'!B25 -> -49203082
A28: ='General information '!F31 -> 0.2174 | B28: =SUM(230*A28) -> 50.002 | C28: 43825 | D28: 31286950 | E28: =D28-D27 -> 3072 | F28: 3418544 | G28: =F28-F27 -> 2290 | H28: 17206454 | I28: =H28-H27 -> 2342 | J28: 28218982 | K28: =J28-J27 -> 2384 | L28: 22497322 | M28: =L28-L27 -> 3732 | N28: =M28+K28+I28+G28+E28 -> 13820 | O28: =IF(B28>0,N28/B28,0) -> 276.38894 | P28: 15201.177 | Q28: =(P28-P27)*1000 -> 3177 | R28: =N28-Q28 -> 10643 | S28: 8315 | T28: =S28-S27 -> 0 | U28: 1011339 | V28: =U28-U27 -> 0 | W28: 31783 | X28: =W28-W27 -> 4 | Y28: 613817 | Z28: =Y28-Y27 -> 839 | AA28: 34840 | AB28: =AA28-AA27 -> 0 | AC28: 733811 | AD28: =AC28-AC27 -> 0 | AE28: =AB28+X28+T28 -> 4 | AF28: =V28+Z28+AD28 -> 839 | AG28: =IF(AE28>0,AF28/AE28,0) -> 209.75 | AI28: =R28-'EDl log'!B26 -> -49210466
A29: ='General information '!F32 -> 0.2913 | B29: =SUM(230*A29) -> 66.999 | C29: 43826 | D29: 31290742 | E29: =D29-D28 -> 3792 | F29: 3421098 | G29: =F29-F28 -> 2554 | H29: 17208996 | I29: =H29-H28 -> 2542 | J29: 28220566 | K29: =J29-J28 -> 1584 | L29: 22503438 | M29: =L29-L28 -> 6116 | N29: =M29+K29+I29+G29+E29 -> 16588 | O29: =IF(B29>0,N29/B29,0) -> 247.58578 | P29: 15205 | Q29: =(P29-P28)*1000 -> 3823 | R29: =N29-Q29 -> 12765 | S29: 8322 | T29: =S29-S28 -> 7 | U29: 1012777 | V29: =U29-U28 -> 1438 | W29: 31783 | X29: =W29-W28 -> 0 | Y29: =Y28 -> 613817 | Z29: =Y29-Y28 -> 0 | AA29: =AA28 -> 34840 | AB29: =AA29-AA28 -> 0 | AC29: =AC28 -> 733811 | AD29: =AC29-AC28 -> 0 | AE29: =AB29+X29+T29 -> 7 | AF29: =V29+Z29+AD29 -> 1438 | AG29: =IF(AE29>0,AF29/AE29,0) -> 205.42857 | AI29: =R29-'EDl log'!B27 -> -49214894
A30: ='General information '!F33 -> 0.2913 | B30: =SUM(230*A30) -> 66.999 | C30: 43827 | D30: 31294576 | E30: =D30-D29 -> 3834 | F30: 3423614 | G30: =F30-F29 -> 2516 | H30: 17211568 | I30: =H30-H29 -> 2572 | J30: 28222350 | K30: =J30-J29 -> 1784 | L30: 22508414 | M30: =L30-L29 -> 4976 | N30: =M30+K30+I30+G30+E30 -> 15682 | O30: =IF(B30>0,N30/B30,0) -> 234.06319 | P30: 15208 | Q30: =(P30-P29)*1000 -> 3000 | R30: =N30-Q30 -> 12682 | S30: 8325 | T30: =S30-S29 -> 3 | U30: 1013316 | V30: =U30-U29 -> 539 | W30: 31785 | X30: =W30-W29 -> 2 | Y30: 614104 | Z30: =Y30-Y29 -> 287 | AA30: 34844 | AB30: =AA30-AA29 -> 4 | AC30: 734373 | AD30: =AC30-AC29 -> 562 | AE30: =AB30+X30+T30 -> 9 | AF30: =V30+Z30+AD30 -> 1388 | AG30: =IF(AE30>0,AF30/AE30,0) -> 154.22222 | AI30: =R30-'EDl log'!B28 -> -49220756
A31: ='General information '!F34 -> 0.345 | B31: =SUM(230*A31) -> 79.35 | C31: 43828 | D31: 31299550 | E31: =D31-D30 -> 4974 | F31: 3426257 | G31: =F31-F30 -> 2643 | H31: 17214298 | I31: =H31-H30 -> 2730 | J31: 28224982 | K31: =J31-J30 -> 2632 | L31: 22513108 | M31: =L31-L30 -> 4694 | N31: =M31+K31+I31+G31+E31 -> 17673 | O31: =IF(B31>0,N31/B31,0) -> 222.72212 | P31: 15211.678 | Q31: =(P31-P30)*1000 -> 3678 | R31: =N31-Q31 -> 13995 | S31: 8325 | T31: =S31-S30 -> 0 | U31: 1013316 | V31: =U31-U30 -> 0 | W31: 31790 | X31: =W31-W30 -> 5 | Y31: 615043 | Z31: =Y31-Y30 -> 939 | AA31: 34848 | AB31: =AA31-AA30 -> 4 | AC31: 735114 | AD31: =AC31-AC30 -> 741 | AE31: =AB31+X31+T31 -> 9 | AF31: =V31+Z31+AD31 -> 1680 | AG31: =IF(AE31>0,AF31/AE31,0) -> 186.66667 | AI31: =R31-'EDl log'!B29 -> -49225048
A32: ='General information '!F35 -> 0.345 | B32: =SUM(230*A32) -> 79.35 | C32: 43829 | D32: 31304560 | E32: =D32-D31 -> 5010 | F32: 3428870 | G32: =F32-F31 -> 2613 | H32: 17217114 | I32: =H32-H31 -> 2816 | J32: 28227042 | K32: =J32-J31 -> 2060 | L32: 22518770 | M32: =L32-L31 -> 5662 | N32: =M32+K32+I32+G32+E32 -> 18161 | O32: =IF(B32>0,N32/B32,0) -> 228.87209 | P32: 15214.705 | Q32: =(P32-P31)*1000 -> 3027 | R32: =N32-Q32 -> 15134 | S32: 8334 | T32: =S32-S31 -> 9 | U32: 1014633 | V32: =U32-U31 -> 1317 | W32: 31790 | X32: =W32-W31 -> 0 | Y32: =Y31 -> 615043 | Z32: =Y32-Y31 -> 0 | AA32: 34851 | AB32: =AA32-AA31 -> 3 | AC32: 735699 | AD32: =AC32-AC31 -> 585 | AE32: =AB32+X32+T32 -> 12 | AF32: =V32+Z32+AD32 -> 1902 | AG32: =IF(AE32>0,AF32/AE32,0) -> 158.5 | AI32: =R32-'EDl log'!B30 -> -49230051
A33: ='General information '!F36 -> 0.5 | B33: =SUM(230*A33) -> 115 | C33: 43830 | D33: 31308238 | E33: =D33-D32 -> 3678 | F33: 3431349 | G33: =F33-F32 -> 2479 | H33: 17219918 | I33: =H33-H32 -> 2804 | J33: 28230090 | K33: =J33-J32 -> 3048 | L33: 22522846 | M33: =L33-L32 -> 4076 | N33: =M33+K33+I33+G33+E33 -> 16085 | O33: =IF(B33>0,N33/B33,0) -> 139.86957 | P33: 15218.2 | Q33: =(P33-P32)*1000 -> 3495 | R33: =N33-Q33 -> 12590 | S33: =S32 -> 8334 | T33: =S33-S32 -> 0 | U33: =U32 -> 1014633 | V33: =U33-U32 -> 0 | W33: 31800 | X33: =W33-W32 -> 10 | Y33: 616769 | Z33: =Y33-Y32 -> 1726 | AA33: =AA32 -> 34851 | AB33: =AA33-AA32 -> 0 | AC33: =AC32 -> 735699 | AD33: =AC33-AC32 -> 0 | AE33: =AB33+X33+T33 -> 10 | AF33: =V33+Z33+AD33 -> 1726 | AG33: =IF(AE33>0,AF33/AE33,0) -> 172.6 | AI33: =R33-'EDl log'!B31 -> -49239434

Sheet B5
F1: Boiler A | J1: =J36 -> 76.667478 | K1: Boiler B | P1: Boiler C | V1: Boiler | X1: SteamA | AC1: SteamB | AH1: Steam | AI1: Boiler & steam | AL1: Total Boiler Runing H | AM1: Total Steam Runing H | AN1: GAS1 % | AO1: GAS1/L | AP1: GAS2% | AQ1: Gas2/L | AR1: GAS3% | AS1: GAS3/L | AU1: Gas Cons | AV1: Delivery | AW1: Cost/L
B2: Level Tank Gen | C2: Level tank Boiler | D2: Daily Cons Bo. | E2: Boiler litter | F2: Boiler A | G2: Run Hr a | H2: Boiler A fuel | I2: Daily consumption | J2: AVG | K2: index Run H | L2: Run Hrb | M2: Boiler B Fuel | O2: Daily consumption | P2: Boiler C | S2: Run C | U2: Total RH | V2: Total Fuel | X2: SteamA | Y2: Run SA | Z2: Steam A Conter | AA2: Liters | AC2: SteamB | AD2: Run SteamB | AE2: Steam B Conter | AF2: SB Litters | AG2: Avg | AH2: Total Fuel | AI2: Total Fuel
S3: 0
A4: 43799 | B4: =[1]B5!B34 -> 217 | C4: =[1]B5!C34 -> 223 | D4: =[1]B5!D34 -> 3 | E4: =[1]B5!E34 -> 25.14 | F4: =[1]B5!F34 -> 1192 | G4: =[1]B5!G34 -> 2 | H4: =[1]B5!H34 -> 321489 | I4: =[1]B5!I34 -> 155 | ... AX4: =[1]B5!AX34 -> 0.7
A5: 43800 | B5: 214 | C5: 219 | D5: =C4-C5 -> 4 | E5: =D5*8.38 -> 33.52 | F5: 1192 | G5: =F5-F4 -> 0 | H5: 321489 | I5: =SUM(H5-H4) -> 0 | J5: 1 | K5: 1567 | L5: =K5-K4 -> 1 | M5: 114381 | N5: =M5-M4 -> 108 | O5: =SUM(L5*$J$1) -> 76.667478 | P5: 1410 | Q5: 122817 | R5: =Q5-Q4 -> 121 | S5: =SUM(P5-P4) -> 2 | T5: =SUM(S5*$T$2) -> 0 | U5: =SUM(G5+L5+S5) -> 3 | V5: =R5+N5+I5:I5 -> 229 | W5: =SUM(V5/U5) -> 76.333333 | X5: 2239 | Y5: =X5-X4 -> 0 | Z5: 126340 | AA5: =Z5-Z4 -> 0 | AB5: =SUM(Y5*$AB$2) -> 0 | AC5: 1688 | AD5: =AC5-AC4 -> 0 | AE5: 351848 | AF5: =AE5-AE4 -> 0 | AG5: =IF(AD5>0,AF5/AD5,0) -> 0 | AH5: =AF5+AA5 -> 0 | AI5: =SUM(AH5+V5) -> 229 | AJ5: =-tanks!AW6 -> 229 | AK5: =SUM(AJ5-AI5) -> 0 | AL5: =S5+L5+G5 -> 3 | AM5: =Y5+AD5 -> 0 | AN5: 78 | AO5: =(AN5/100)*3000 -> 2340 | AP5: 77 | AQ5: =(AP5/100)*3000 -> 2310 | AR5: 78 | AS5: =(AR5/100)*3000 -> 2340 | AT5: =SUM(AO5+AQ5+AS5) -> 6990 | AU5: =AT4-AT5+AV5 -> 60 | AX5: =IF(AV5>0,AW5,AX4) -> 0.7
A6: 43801 | B6: 210 | C6: 216 | D6: =C5-C6 -> 3 | E6: =D6*8.38 -> 25.14 | F6: 1194 | G6: =F6-F5 -> 2 | H6: 321606 | I6: =SUM(H6-H5) -> 117 | J6: =IF(G6>0,I6/G6,0) -> 58.5 | K6: 1567 | L6: =K6-K5 -> 0 | M6: 114381 | N6: =M6-M5 -> 0 | O6: =SUM(L6*$J$1) -> 0 | P6: 1411 | Q6: 122915 | R6: =Q6-Q5 -> 98 | S6: =SUM(P6-P5) -> 1 | T6: =SUM(S6*$T$2) -> 0 | U6: =SUM(G6+L6+S6) -> 3 | V6: =R6+N6+I6:I6 -> 215 | W6: =SUM(V6/U6) -> 71.666667 | X6: 2241 | Y6: =X6-X5 -> 2 | Z6: 126454 | AA6: =Z6-Z5 -> 114 | AB6: =SUM(Y6*$AB$2) -> 0 | AC6: 1688 | AD6: =AC6-AC5 -> 0 | AE6: =AE5 -> 351848 | AF6: =AE6-AE5 -> 0 | AG6: =IF(AD6>0,AF6/AD6,0) -> 0 | AH6: =AF6+AA6 -> 114 | AI6: =SUM(AH6+V6) -> 329 | AJ6: =-tanks!AW7 -> 329 | AK6: =SUM(AJ6-AI6) -> 0 | AL6: =S6+L6+G6 -> 3 | AM6: =Y6+AD6 -> 2 | AN6: 75 | AO6: =(AN6/100)*3000 -> 2250 | AP6: 75 | AQ6: =(AP6/100)*3000 -> 2250 | AR6: =AR5 -> 78 | AS6: =(AR6/100)*3000 -> 2340 | AT6: =SUM(AO6+AQ6+AS6) -> 6840 | AU6: =AT5-AT6+AV6 -> 150 | AX6: =IF(AV6>0,AW6,AX5) -> 0.7
A7: 43802 | B7: 205 | C7: 210 | D7: =C6-C7 -> 6 | E7: =D7*8.38 -> 50.28 | F7: 1196 | G7: =F7-F6 -> 2 | H7: 321743 | I7: =SUM(H7-H6) -> 137 | J7: =IF(G7>0,I7/G7,0) -> 68.5 | K7: 1568 | L7: =K7-K6 -> 1 | M7: 114414 | N7: =M7-M6 -> 33 | O7: 1 | P7: 1412 | Q7: 123007 | R7: =Q7-Q6 -> 92 | S7: =SUM(P7-P6) -> 1 | T7: =SUM(S7*$T$2) -> 0 | U7: =SUM(G7+L7+S7) -> 4 | V7: =R7+N7+I7:I7 -> 262 | W7: =SUM(V7/U7) -> 65.5 | X7: 2248 | Y7: =X7-X6 -> 7 | Z7: 126816 | AA7: =Z7-Z6 -> 362 | AB7: =SUM(Y7*$AB$2) -> 0 | AC7: 1688 | AD7: =AC7-AC6 -> 0 | AE7: 351848.7 | AF7: =AE7-AE6 -> 0.7 | AG7: =IF(AD7>0,AF7/AD7,0) -> 0 | AH7: =AF7+AA7 -> 362.7 | AI7: =SUM(AH7+V7) -> 624.7 | AJ7: =-tanks!AW8 -> 624.7 | AK7: =SUM(AJ7-AI7) -> 0 | AL7: =S7+L7+G7 -> 4 | AM7: =Y7+AD7 -> 7 | AN7: 75 | AO7: =(AN7/100)*3000 -> 2250 | AP7: 75 | AQ7: =(AP7/100)*3000 -> 2250 | AR7: 75 | AS7: =(AR7/100)*3000 -> 2250 | AT7: =SUM(AO7+AQ7+AS7) -> 6750 | AU7: =AT6-AT7+AV7 -> 90 | AX7: =IF(AV7>0,AW7,AX6) -> 0.7
A8: 43803 | B8: 201 | C8: 207 | D8: =C7-C8 -> 3 | E8: =D8*8.38 -> 25.14 | F8: 1199 | G8: =F8-F7 -> 3 | H8: 321991 | I8: =SUM(H8-H7) -> 248 | J8: =IF(G8>0,I8/G8,0) -> 82.666667 | K8: 1568 | L8: =K8-K7 -> 0 | M8: 114414 | N8: =M8-M7 -> 0 | O8: =SUM(L8*$J$1) -> 0 | P8: 1414 | Q8: 123208 | R8: =Q8-Q7 -> 201 | S8: =SUM(P8-P7) -> 2 | T8: =SUM(S8*$T$2) -> 0 | U8: =SUM(G8+L8+S8) -> 5 | V8: =R8+N8+I8:I8 -> 449 | W8: =SUM(V8/U8) -> 89.8 | X8: 2248 | Y8: =X8-X7 -> 0 | Z8: 126816.9 | AA8: =Z8-Z7 -> 0.9 | AB8: =SUM(Y8*$AB$2) -> 0 | AC8: 1688 | AD8: =AC8-AC7 -> 0 | AE8: 351848.7 | AF8: =AE8-AE7 -> 0 | AG8: =IF(AD8>0,AF8/AD8,0) -> 0 | AH8: =AF8+AA8 -> 0.9 | AI8: =SUM(AH8+V8) -> 449.9 | AJ8: =-tanks!AW9 -> 449.9 | AK8: =SUM(AJ8-AI8) -> 0 | AL8: =S8+L8+G8 -> 5 | AM8: =Y8+AD8 -> 0 | AN8: 71 | AO8: =(AN8/100)*3000 -> 2130 | AP8: 71 | AQ8: =(AP8/100)*3000 -> 2130 | AR8: 72 | AS8: =(AR8/100)*3000 -> 2160 | AT8: =SUM(AO8+AQ8+AS8) -> 6420 | AU8: =AT7-AT8+AV8 -> 330 | AX8: =IF(AV8>0,AW8,AX7) -> 0.7
A9: 43804 | B9: 196 | C9: 202 | D9: =C8-C9 -> 5 | E9: =D9*8.38 -> 41.9 | F9: 1200 | G9: =F9-F8 -> 1 | H9: 322096 | I9: =SUM(H9-H8) -> 105 | J9: =IF(G9>0,I9/G9,0) -> 105 | K9: 1574 | L9: =K9-K8 -> 6 | M9: 114807 | N9: =M9-M8 -> 393 | O9: =SUM(L9*$J$1) -> 460.00487 | P9: 1414 | Q9: 123208 | R9: =Q9-Q8 -> 0 | S9: =SUM(P9-P8) -> 0 | T9: =SUM(S9*$T$2) -> 0 | U9: =SUM(G9+L9+S9) -> 7 | V9: =R9+N9+I9:I9 -> 498 | W9: =SUM(V9/U9) -> 71.142857 | X9: 2248 | Y9: =X9-X8 -> 0 | Z9: =Z8 -> 126816.9 | AA9: =Z9-Z8 -> 0 | AB9: =SUM(Y9*$AB$2) -> 0 | AC9: 1688 | AD9: =AC9-AC8 -> 0 | AE9: 351848.7 | AF9: =AE9-AE8 -> 0 | AG9: =IF(AD9>0,AF9/AD9,0) -> 0 | AH9: =AF9+AA9 -> 0 | AI9: =SUM(AH9+V9) -> 498 | AJ9: =-tanks!AW10 -> 498 | AK9: =SUM(AJ9-AI9) -> 0 | AL9: =S9+L9+G9 -> 7 | AM9: =Y9+AD9 -> 0 | AN9: 80 | AO9: =(AN9/100)*3000 -> 2400 | AP9: 80 | AQ9: =(AP9/100)*3000 -> 2400 | AR9: 80 | AS9: =(AR9/100)*3000 -> 2400 | AT9: =SUM(AO9+AQ9+AS9) -> 7200 | AU9: =AT8-AT9+AV9 -> 320 | AV9: 1100 | AW9: 0.7 | AX9: =IF(AV9>0,AW9,AX8) -> 0.7
A10: 43805 | B10: 190 | C10: 196 | D10: =C9-C10 -> 6 | E10: =D10*8.38 -> 50.28 | F10: =F9 -> 1200 | G10: =F10-F9 -> 0 | H10: =H9 -> 322096 | I10: =SUM(H10-H9) -> 0 | J10: =IF(G10>0,I10/G10,0) -> 0 | K10: 1578 | L10: =K10-K9 -> 4 | M10: 115056 | N10: =M10-M9 -> 249 | O10: =SUM(L10*$J$1) -> 306.66991 | P10: 1417 | Q10: 123458 | R10: =Q10-Q9 -> 250 | S10: =SUM(P10-P9) -> 3 | T10: =SUM(S10*$T$2) -> 0 | U10: =SUM(G10+L10+S10) -> 7 | V10: =R10+N10+I10:I10 -> 499 | W10: =SUM(V10/U10) -> 71.285714 | X10: 2252 | Y10: =X10-X9 -> 4 | Z10: 127023.7 | AA10: =Z10-Z9 -> 206.8 | AB10: =SUM(Y10*$AB$2) -> 0 | AC10: =AC9 -> 1688 | AD10: =AC10-AC9 -> 0 | AE10: =AE9 -> 351848.7 | AF10: =AE10-AE9 -> 0 | AG10: =IF(AD10>0,AF10/AD10,0) -> 0 | AH10: =AF10+AA10 -> 206.8 | AI10: =SUM(AH10+V10) -> 705.8 | AJ10: =-tanks!AW11 -> 705.8 | AK10: =SUM(AJ10-AI10) -> 0 | AL10: =S10+L10+G10 -> 7 | AM10: =Y10+AD10 -> 4 | AN10: =AN9 -> 80 | AO10: =(AN10/100)*3000 -> 2400 | AP10: 79 | AQ10: =(AP10/100)*3000 -> 2370 | AR10: =AR9 -> 80 | AS10: =(AR10/100)*3000 -> 2400 | AT10: =SUM(AO10+AQ10+AS10) -> 7170 | AU10: =AT9-AT10+AV10 -> 30 | AX10: =IF(AV10>0,AW10,AX9) -> 0.7
A11: 43806 | B11: 184 | C11: 190 | D11: =C10-C11 -> 6 | E11: =D11*8.38 -> 50.28 | F11: 1203 | G11: =F11-F10 -> 3 | H11: 322362 | I11: =SUM(H11-H10) -> 266 | J11: =IF(G11>0,I11/G11,0) -> 88.666667 | K11: 1578 | L11: =K11-K10 -> 0 | M11: =M10 -> 115056 | N11: =M11-M10 -> 0 | O11: =SUM(L11*$J$1) -> 0 | P11: 1421 | Q11: 123775 | R11: =Q11-Q10 -> 317 | S11: =SUM(P11-P10) -> 4 | T11: =SUM(S11*$T$2) -> 0 | U11: =SUM(G11+L11+S11) -> 7 | V11: =R11+N11+I11:I11 -> 583 | W11: =SUM(V11/U11) -> 83.285714 | X11: 2259 | Y11: =X11-X10 -> 7 | Z11: 127401 | AA11: =Z11-Z10 -> 377.3 | AB11: =SUM(Y11*$AB$2) -> 0 | AC11: =AC10 -> 1688 | AD11: =AC11-AC10 -> 0 | AE11: =AE10 -> 351848.7 | AF11: =AE11-AE10 -> 0 | AG11: =IF(AD11>0,AF11/AD11,0) -> 0 | AH11: =AF11+AA11 -> 377.3 | AI11: =SUM(AH11+V11) -> 960.3 | AJ11: =-tanks!AW12 -> 960.3 | AK11: =SUM(AJ11-AI11) -> 0 | AL11: =S11+L11+G11 -> 7 | AM11: =Y11+AD11 -> 7 | AN11: 79 | AO11: =(AN11/100)*3000 -> 2370 | AP11: 78 | AQ11: =(AP11/100)*3000 -> 2340 | AR11: 79 | AS11: =(AR11/100)*3000 -> 2370 | AT11: =SUM(AO11+AQ11+AS11) -> 7080 | AU11: =AT10-AT11+AV11 -> 90 | AX11: =IF(AV11>0,AW11,AX10) -> 0.7
A12: 43807 | B12: 180 | C12: 186 | D12: =C11-C12 -> 4 | E12: =D12*8.38 -> 33.52 | F12: 1208 | G12: =F12-F11 -> 5 | H12: 322713 | I12: =SUM(H12-H11) -> 351 | J12: =IF(G12>0,I12/G12,0) -> 70.2 | K12: 1582 | L12: =K12-K11 -> 4 | M12: 115313 | N12: =M12-M11 -> 257 | O12: =SUM(L12*$J$1) -> 306.66991 | P12: 1422 | Q12: 123809 | R12: =Q12-Q11 -> 34 | S12: =SUM(P12-P11) -> 1 | T12: =SUM(S12*$T$2) -> 0 | U12: =SUM(G12+L12+S12) -> 10 | V12: =R12+N12+I12:I12 -> 642 | W12: =SUM(V12/U12) -> 64.2 | X12: =X11 -> 2259 | Y12: =X12-X11 -> 0 | Z12: =Z11 -> 127401 | AA12: =Z12-Z11 -> 0 | AB12: =SUM(Y12*$AB$2) -> 0 | AC12: =AC11 -> 1688 | AD12: =AC12-AC11 -> 0 | AE12: =AE11 -> 351848.7 | AF12: =AE12-AE11 -> 0 | AG12: =IF(AD12>0,AF12/AD12,0) -> 0 | AH12: =AF12+AA12 -> 0 | AI12: =SUM(AH12+V12) -> 642 | AJ12: =-tanks!AW13 -> 642 | AK12: =SUM(AJ12-AI12) -> 0 | AL12: =S12+L12+G12 -> 10 | AM12: =Y12+AD12 -> 0 | AN12: =AN11 -> 79 | AO12: =(AN12/100)*3000 -> 2370 | AP12: =AP11 -> 78 | AQ12: =(AP12/100)*3000 -> 2340 | AR12: =AR11 -> 79 | AS12: =(AR12/100)*3000 -> 2370 | AT12: =SUM(AO12+AQ12+AS12) -> 7080 | AU12: =AT11-AT12+AV12 -> 0 | AX12: =IF(AV12>0,AW12,AX11) -> 0.7
A13: 43808 | B13: 175 | C13: 181 | D13: =C12-C13 -> 5 | E13: =D13*8.38 -> 41.9 | F13: 1208 | G13: =F13-F12 -> 0 | H13: 322713 | I13: =SUM(H13-H12) -> 0 | J13: =IF(G13>0,I13/G13,0) -> 0 | K13: 1588 | L13: =K13-K12 -> 6 | M13: 115663 | N13: =M13-M12 -> 350 | O13: =SUM(L13*$J$1) -> 460.00487 | P13: 1425 | Q13: 124083 | R13: =Q13-Q12 -> 274 | S13: =SUM(P13-P12) -> 3 | T13: =SUM(S13*$T$2) -> 0 | U13: =SUM(G13+L13+S13) -> 9 | V13: =R13+N13+I13:I13 -> 624 | W13: =SUM(V13/U13) -> 69.333333 | X13: 2259 | Y13: =X13-X12 -> 0 | Z13: 127401 | AA13: =Z13-Z12 -> 0 | AB13: =SUM(Y13*$AB$2) -> 0 | AC13: 1688 | AD13: =AC13-AC12 -> 0 | AE13: 351848.7 | AF13: =AE13-AE12 -> 0 | AG13: =IF(AD13>0,AF13/AD13,0) -> 0 | AH13: =AF13+AA13 -> 0 | AI13: =SUM(AH13+V13) -> 624 | AJ13: =-tanks!AW14 -> 624 | AK13: =SUM(AJ13-AI13) -> 0 | AL13: =S13+L13+G13 -> 9 | AM13: =Y13+AD13 -> 0 | AN13: 74 | AO13: =(AN13/100)*3000 -> 2220 | AP13: 74 | AQ13: =(AP13/100)*3000 -> 2220 | AR13: 75 | AS13: =(AR13/100)*3000 -> 2250 | AT13: =SUM(AO13+AQ13+AS13) -> 6690 | AU13: =AT12-AT13+AV13 -> 390 | AX13: =IF(AV13>0,AW13,AX12) -> 0.7
A14: 43809 | B14: 170 | C14: 176 | D14: =C13-C14 -> 5 | E14: =D14*8.38 -> 41.9 | F14: 1211 | G14: =F14-F13 -> 3 | H14: 322970 | I14: =SUM(H14-H13) -> 257 | J14: =IF(G14>0,I14/G14,0) -> 85.666667 | K14: 1588 | L14: =K14-K13 -> 0 | M14: =M13 -> 115663 | N14: =M14-M13 -> 0 | O14: =SUM(L14*$J$1) -> 0 | P14: 1430 | Q14: 124498 | R14: =Q14-Q13 -> 415 | S14: =SUM(P14-P13) -> 5 | T14: =SUM(S14*$T$2) -> 0 | U14: =SUM(G14+L14+S14) -> 8 | V14: =R14+N14+I14:I14 -> 672 | W14: =SUM(V14/U14) -> 84 | X14: 2261 | Y14: =X14-X13 -> 2 | Z14: 127491.2 | AA14: =Z14-Z13 -> 90.2 | AB14: =SUM(Y14*$AB$2) -> 0 | AC14: 1688 | AD14: =AC14-AC13 -> 0 | AE14: 351848.7 | AF14: =AE14-AE13 -> 0 | AG14: =IF(AD14>0,AF14/AD14,0) -> 0 | AH14: =AF14+AA14 -> 90.2 | AI14: =SUM(AH14+V14) -> 762.2 | AJ14: =-tanks!AW15 -> 762.2 | AK14: =SUM(AJ14-AI14) -> 0 | AL14: =S14+L14+G14 -> 8 | AM14: =Y14+AD14 -> 2 | AN14: 72 | AO14: =(AN14/100)*3000 -> 2160 | AP14: 72 | AQ14: =(AP14/100)*3000 -> 2160 | AR14: 74 | AS14: =(AR14/100)*3000 -> 2220 | AT14: =SUM(AO14+AQ14+AS14) -> 6540 | AU14: =AT13-AT14+AV14 -> 150 | AX14: =IF(AV14>0,AW14,AX13) -> 0.7
A15: 43810 | B15: 164 | C15: 170 | D15: =C14-C15 -> 6 | E15: =D15*8.38 -> 50.28 | F15: 1215 | G15: =F15-F14 -> 4 | H15: 323283 | I15: =SUM(H15-H14) -> 313 | J15: =IF(G15>0,I15/G15,0) -> 78.25 | K15: 1590 | L15: =K15-K14 -> 2 | M15: 115777 | N15: =M15-M14 -> 114 | O15: =SUM(L15*$J$1) -> 153.33496 | P15: 1430 | Q15: 124499 | R15: =Q15-Q14 -> 1 | S15: =SUM(P15-P14) -> 0 | T15: =SUM(S15*$T$2) -> 0 | U15: =SUM(G15+L15+S15) -> 6 | V15: =R15+N15+I15:I15 -> 428 | W15: =SUM(V15/U15) -> 71.333333 | X15: 2269 | Y15: =X15-X14 -> 8 | Z15: 127901.4 | AA15: =Z15-Z14 -> 410.2 | AB15: =SUM(Y15*$AB$2) -> 0 | AC15: 1688 | AD15: =AC15-AC14 -> 0 | AE15: 351848.7 | AF15: =AE15-AE14 -> 0 | AG15: =IF(AD15>0,AF15/AD15,0) -> 0 | AH15: =AF15+AA15 -> 410.2 | AI15: =SUM(AH15+V15) -> 838.2 | AJ15: =-tanks!AW16 -> 838.2 | AK15: =SUM(AJ15-AI15) -> 0 | AL15: =S15+L15+G15 -> 6 | AM15: =Y15+AD15 -> 8 | AN15: 70 | AO15: =(AN15/100)*3000 -> 2100 | AP15: 70 | AQ15: =(AP15/100)*3000 -> 2100 | AR15: 72 | AS15: =(AR15/100)*3000 -> 2160 | AT15: =SUM(AO15+AQ15+AS15) -> 6360 | AU15: =AT14-AT15+AV15 -> 180 | AX15: =IF(AV15>0,AW15,AX14) -> 0.7
A16: 43811 | B16: 202 | C16: 208 | D16: =C15-C16 -> -38 | E16: =D16*8.38 -> -318.44 | F16: 1215 | G16: =F16-F15 -> 0 | H16: 323283 | I16: =SUM(H16-H15) -> 0 | J16: =IF(G16>0,I16/G16,0) -> 0 | K16: 1595 | L16: =K16-K15 -> 5 | M16: 116112 | N16: =M16-M15 -> 335 | O16: =SUM(L16*$J$1) -> 383.33739 | P16: 1434 | Q16: 124825 | R16: =Q16-Q15 -> 326 | S16: =SUM(P16-P15) -> 4 | T16: =SUM(S16*$T$2) -> 0 | U16: =SUM(G16+L16+S16) -> 9 | V16: =R16+N16+I16:I16 -> 661 | W16: =SUM(V16/U16) -> 73.444444 | X16: 2269 | Y16: =X16-X15 -> 0 | Z16: =Z15 -> 127901.4 | AA16: =Z16-Z15 -> 0 | AB16: =SUM(Y16*$AB$2) -> 0 | AC16: 1688 | AD16: =AC16-AC15 -> 0 | AE16: =AE15 -> 351848.7 | AF16: =AE16-AE15 -> 0 | AG16: =IF(AD16>0,AF16/AD16,0) -> 0 | AH16: =AF16+AA16 -> 0 | AI16: =SUM(AH16+V16) -> 661 | AJ16: =-tanks!AW17 -> 661 | AK16: =SUM(AJ16-AI16) -> 0 | AL16: =S16+L16+G16 -> 9 | AM16: =Y16+AD16 -> 0 | AN16: 78 | AO16: =(AN16/100)*3000 -> 2340 | AP16: 78 | AQ16: =(AP16/100)*3000 -> 2340 | AR16: 82 | AS16: =(AR16/100)*3000 -> 2460 | AT16: =SUM(AO16+AQ16+AS16) -> 7140 | AU16: =AT15-AT16+AV16 -> 320 | AV16: 1100 | AW16: 0.7 | AX16: =IF(AV16>0,AW16,AX15) -> 0.7
A17: 43812 | B17: 196 | C17: 203 | D17: =C16-C17 -> 5 | E17: =D17*8.38 -> 41.9 | F17: 1220 | G17: =F17-F16 -> 5 | H17: 323679 | I17: =SUM(H17-H16) -> 396 | J17: =IF(G17>0,I17/G17,0) -> 79.2 | K17: 1595 | L17: =K17-K16 -> 0 | M17: 116112 | N17: =M17-M16 -> 0 | O17: =SUM(L17*$J$1) -> 0 | P17: 1440 | Q17: 125296 | R17: =Q17-Q16 -> 471 | S17: =SUM(P17-P16) -> 6 | T17: =SUM(S17*$T$2) -> 0 | U17: =SUM(G17+L17+S17) -> 11 | V17: =R17+N17+I17:I17 -> 867 | X17: 2269 | Y17: =X17-X16 -> 0 | Z17: 127901.4 | AA17: =Z17-Z16 -> 0 | AB17: =SUM(Y17*$AB$2) -> 0 | AC17: 1688 | AD17: =AC17-AC16 -> 0 | AE17: 351848.7 | AF17: =AE17-AE16 -> 0 | AG17: =IF(AD17>0,AF17/AD17,0) -> 0 | AH17: =AF17+AA17 -> 0 | AI17: =SUM(AH17+V17) -> 867 | AJ17: =-tanks!AW18 -> 867 | AK17: =SUM(AJ17-AI17) -> 0 | AL17: =S17+L17+G17 -> 11 | AM17: =Y17+AD17 -> 0 | AN17: 75 | AO17: =(AN17/100)*3000 -> 2250 | AP17: 75 | AQ17: =(AP17/100)*3000 -> 2250 | AR17: 79 | AS17: =(AR17/100)*3000 -> 2370 | AT17: =SUM(AO17+AQ17+AS17) -> 6870 | AU17: =AT16-AT17+AV17 -> 270 | AX17: =IF(AV17>0,AW17,AX16) -> 0.7
A18: 43813 | B18: 189 | C18: 195 | D18: =C17-C18 -> 8 | E18: =D18*8.38 -> 67.04 | F18: 1225 | G18: =F18-F17 -> 5 | H18: 324117 | I18: =SUM(H18-H17) -> 438 | J18: =IF(G18>0,I18/G18,0) -> 87.6 | K18: 1600 | L18: =K18-K17 -> 5 | M18: 116468 | N18: =M18-M17 -> 356 | O18: =SUM(L18*$J$1) -> 383.33739 | P18: =P17 -> 1440 | Q18: =Q17 -> 125296 | R18: =Q18-Q17 -> 0 | S18: =SUM(P18-P17) -> 0 | T18: =SUM(S18*$T$2) -> 0 | U18: =SUM(G18+L18+S18) -> 10 | V18: =R18+N18+I18:I18 -> 794 | X18: 2271 | Y18: =X18-X17 -> 2 | Z18: 128025.8 | AA18: =Z18-Z17 -> 124.4 | AB18: =SUM(Y18*$AB$2) -> 0 | AC18: =AC17 -> 1688 | AD18: =AC18-AC17 -> 0 | AE18: =AE17 -> 351848.7 | AF18: =AE18-AE17 -> 0 | AG18: =IF(AD18>0,AF18/AD18,0) -> 0 | AH18: =AF18+AA18 -> 124.4 | AI18: =SUM(AH18+V18) -> 918.4 | AJ18: =-tanks!AW19 -> 918.4 | AK18: =SUM(AJ18-AI18) -> 0 | AL18: =S18+L18+G18 -> 10 | AM18: =Y18+AD18 -> 2 | AN18: 74 | AO18: =(AN18/100)*3000 -> 2220 | AP18: 74 | AQ18: =(AP18/100)*3000 -> 2220 | AR18: 78 | AS18: =(AR18/100)*3000 -> 2340 | AT18: =SUM(AO18+AQ18+AS18) -> 6780 | AU18: =AT17-AT18+AV18 -> 90 | AX18: =IF(AV18>0,AW18,AX17) -> 0.7
A19: 43814 | B19: 183 | C19: 189 | D19: =C18-C19 -> 6 | E19: =D19*8.38 -> 50.28 | F19: 1225 | G19: =F19-F18 -> 0 | H19: 324117 | I19: =SUM(H19-H18) -> 0 | J19: =IF(G19>0,I19/G19,0) -> 0 | K19: 1605 | L19: =K19-K18 -> 5 | M19: 116836 | N19: =M19-M18 -> 368 | O19: =SUM(L19*$J$1) -> 383.33739 | P19: 1445 | Q19: 125686 | R19: =Q19-Q18 -> 390 | S19: =SUM(P19-P18) -> 5 | T19: =SUM(S19*$T$2) -> 0 | U19: =SUM(G19+L19+S19) -> 10 | V19: =R19+N19+I19:I19 -> 758 | X19: 2279 | Y19: =X19-X18 -> 8 | Z19: 128431.1 | AA19: =Z19-Z18 -> 405.3 | AB19: =SUM(Y19*$AB$2) -> 0 | AC19: 1688 | AD19: =AC19-AC18 -> 0 | AE19: 351848.7 | AF19: =AE19-AE18 -> 0 | AG19: =IF(AD19>0,AF19/AD19,0) -> 0 | AH19: =AF19+AA19 -> 405.3 | AI19: =SUM(AH19+V19) -> 1163.3 | AJ19: =-tanks!AW20 -> 1163.3 | AK19: =SUM(AJ19-AI19) -> 0 | AL19: =S19+L20+G19 -> 5 | AM19: =Y19+AD19 -> 8 | AN19: 72 | AO19: =(AN19/100)*3000 -> 2160 | AP19: 74 | AQ19: =(AP19/100)*3000 -> 2220 | AR19: 76 | AS19: =(AR19/100)*3000 -> 2280 | AT19: =SUM(AO19+AQ19+AS19) -> 6660 | AU19: =AT18-AT19+AV19 -> 120 | AX19: =IF(AV19>0,AW19,AX18) -> 0.7
A20: 43815 | B20: 177 | C20: 182 | D20: =C19-C20 -> 7 | E20: =D20*8.38 -> 58.66 | F20: 1231 | G20: =F20-F19 -> 6 | H20: 324528 | I20: =SUM(H20-H19) -> 411 | J20: =IF(G20>0,I20/G20,0) -> 68.5 | K20: =K19 -> 1605 | L20: =K20-K19 -> 0 | M20: =M19 -> 116836 | N20: =M20-M19 -> 0 | O20: =SUM(L20*$J$1) -> 0 | P20: 1450 | Q20: 126115 | R20: =Q20-Q19 -> 429 | S20: =SUM(P20-P19) -> 5 | T20: =SUM(S20*$T$2) -> 0 | U20: =SUM(G20+L20+S20) -> 11 | V20: =R20+N20+I20:I20 -> 840 | X20: =X19 -> 2279 | Y20: =X20-X19 -> 0 | Z20: =Z19 -> 128431.1 | AA20: =Z20-Z19 -> 0 | AB20: =SUM(Y20*$AB$2) -> 0 | AC20: =AC19 -> 1688 | AD20: =AC20-AC19 -> 0 | AE20: =AE19 -> 351848.7 | AF20: =AE20-AE19 -> 0 | AG20: =IF(AD20>0,AF20/AD20,0) -> 0 | AH20: =AF20+AA20 -> 0 | AI20: =SUM(AH20+V20) -> 840 | AJ20: =-tanks!AW21 -> 840 | AK20: =SUM(AJ20-AI20) -> 0 | AL20: =S20+L21+G20 -> 16 | AM20: =Y20+AD20 -> 0 | AN20: =AN19 -> 72 | AO20: =(AN20/100)*3000 -> 2160 | AP20: =AP19 -> 74 | AQ20: =(AP20/100)*3000 -> 2220 | AR20: =AR19 -> 76 | AS20: =(AR20/100)*3000 -> 2280 | AT20: =SUM(AO20+AQ20+AS20) -> 6660 | AU20: =AT19-AT20+AV20 -> 0 | AX20: =IF(AV20>0,AW20,AX19) -> 0.7
A21: 43816 | B21: 187 | C21: 193 | D21: =C20-C21 -> -11 | E21: =D21*8.38 -> -92.18 | F21: 1235 | G21: =F21-F20 -> 4 | H21: 324849 | I21: =SUM(H21-H20) -> 321 | J21: =IF(G21>0,I21/G21,0) -> 80.25 | K21: 1610 | L21: =K21-K20 -> 5 | M21: 117178 | N21: =M21-M20 -> 342 | O21: =SUM(L21*$J$1) -> 383.33739 | P21: 1452 | Q21: 126239 | R21: =Q21-Q20 -> 124 | S21: =SUM(P21-P20) -> 2 | T21: =SUM(S21*$T$2) -> 0 | U21: =SUM(G21+L21+S21) -> 11 | V21: =R21+N21+I21:I21 -> 787 | X21: 2279 | Y21: =X21-X20 -> 0 | Z21: 128431.1 | AA21: =Z21-Z20 -> 0 | AB21: =SUM(Y21*$AB$2) -> 0 | AC21: 1688 | AD21: =AC21-AC20 -> 0 | AE21: 351848.7 | AF21: =AE21-AE20 -> 0 | AG21: =IF(AD21>0,AF21/AD21,0) -> 0 | AH21: =AF21+AA21 -> 0 | AI21: =SUM(AH21+V21) -> 787 | AJ21: =-tanks!AW22 -> 787 | AK21: =SUM(AJ21-AI21) -> 0 | AL21: =S21+L21+G21 -> 11 | AM21: =Y21+AD21 -> 0 | AN21: 69 | AO21: =(AN21/100)*3000 -> 2070 | AP21: 70 | AQ21: =(AP21/100)*3000 -> 2100 | AR21: 71 | AS21: =(AR21/100)*3000 -> 2130 | AT21: =SUM(AO21+AQ21+AS21) -> 6300 | AU21: =AT20-AT21+AV21 -> 360 | AX21: =IF(AV21>0,AW21,AX20) -> 0.7
A22: 43817 | B22: 225 | C22: 229 | D22: =C21-C22 -> -36 | E22: =D22*8.38 -> -301.68 | F22: 1238 | G22: =F22-F21 -> 3 | H22: 325131 | I22: =SUM(H22-H21) -> 282 | J22: =IF(G22>0,I22/G22,0) -> 94 | K22: 1615 | L22: =K22-K21 -> 5 | M22: 117578 | N22: =M22-M21 -> 400 | O22: =SUM(L22*$J$1) -> 383.33739 | P22: 1452 | Q22: 126239 | R22: =Q22-Q21 -> 0 | S22: =SUM(P22-P21) -> 0 | T22: =SUM(S22*$T$2) -> 0 | U22: =SUM(G22+L22+S22) -> 8 | V22: =R22+N22+I22:I22 -> 682 | X22: 2281 | Y22: =X22-X21 -> 2 | Z22: 128565.7 | AA22: =Z22-Z21 -> 134.6 | AB22: =SUM(Y22*$AB$2) -> 0 | AC22: 1688 | AD22: =AC22-AC21 -> 0 | AE22: 351848.7 | AF22: =AE22-AE21 -> 0 | AG22: =IF(AD22>0,AF22/AD22,0) -> 0 | AH22: =AF22+AA22 -> 134.6 | AI22: =SUM(AH22+V22) -> 816.6 | AJ22: =-tanks!AW23 -> 816.6 | AK22: =SUM(AJ22-AI22) -> 0 | AL22: =S22+L22+G22 -> 8 | AM22: =Y22+AD22 -> 2 | AN22: 65 | AO22: =(AN22/100)*3000 -> 1950 | AP22: 67 | AQ22: =(AP22/100)*3000 -> 2010 | AR22: 69 | AS22: =(AR22/100)*3000 -> 2070 | AT22: =SUM(AO22+AQ22+AS22) -> 6030 | AU22: =AT21-AT22+AV22 -> 270 | AX22: =IF(AV22>0,AW22,AX21) -> 0.7
A23: 43818 | B23: 222 | C23: 207 | D23: =C22-C23 -> 22 | E23: =D23*8.38 -> 184.36 | F23: 1248 | G23: =F23-F22 -> 10 | H23: 325886 | I23: =SUM(H23-H22) -> 755 | J23: =IF(G23>0,I23/G23,0) -> 75.5 | K23: 1615 | L23: =K23-K22 -> 0 | M23: 117578 | N23: =M23-M22 -> 0 | O23: =SUM(L23*$J$1) -> 0 | P23: 1452 | Q23: 126239 | R23: =Q23-Q22 -> 0 | S23: =SUM(P23-P22) -> 0 | T23: =SUM(S23*$T$2) -> 0 | U23: =SUM(G23+L23+S23) -> 10 | V23: =R23+N23+I23:I23 -> 755 | X23: 2289 | Y23: =X23-X22 -> 8 | Z23: 128954.4 | AA23: =Z23-Z22 -> 388.7 | AB23: =SUM(Y23*$AB$2) -> 0 | AC23: 1688 | AD23: =AC23-AC22 -> 0 | AE23: 351848.7 | AF23: =AE23-AE22 -> 0 | AG23: =IF(AD23>0,AF23/AD23,0) -> 0 | AH23: =AF23+AA23 -> 388.7 | AI23: =SUM(AH23+V23) -> 1143.7 | AJ23: =-tanks!AW24 -> 1143.7 | AK23: =SUM(AJ23-AI23) -> 0 | AL23: =S23+L23+G23 -> 10 | AM23: =Y23+AD23 -> 8 | AN23: 80 | AO23: =(AN23/100)*3000 -> 2400 | AP23: 81 | AQ23: =(AP23/100)*3000 -> 2430 | AR23: 79 | AS23: =(AR23/100)*3000 -> 2370 | AT23: =SUM(AO23+AQ23+AS23) -> 7200 | AU23: =AT22-AT23+AV23 -> 330 | AV23: 1500 | AW23: 0.7 | AX23: =IF(AV23>0,AW23,AX22) -> 0.7
A24: 43819 | B24: 219 | C24: 193 | D24: =C23-C24 -> 14 | E24: =D24*8.38 -> 117.32 | F24: 1256 | G24: =F24-F23 -> 8 | H24: 326591 | I24: =SUM(H24-H23) -> 705 | J24: =IF(G24>0,I24/G24,0) -> 88.125 | K24: 1615 | L24: =K24-K23 -> 0 | M24: 117578 | N24: =M24-M23 -> 0 | O24: =SUM(L24*$J$1) -> 0 | P24: 1452 | Q24: 126239 | R24: =Q24-Q23 -> 0 | S24: =SUM(P24-P23) -> 0 | T24: =SUM(S24*$T$2) -> 0 | U24: =SUM(G24+L24+S24) -> 8 | V24: =R24+N24+I24:I24 -> 705 | X24: 2289 | Y24: =X24-X23 -> 0 | Z24: 128954.4 | AA24: =Z24-Z23 -> 0 | AB24: =SUM(Y24*$AB$2) -> 0 | AC24: 1688 | AD24: =AC24-AC23 -> 0 | AE24: 351848.7 | AF24: =AE24-AE23 -> 0 | AG24: =IF(AD24>0,AF24/AD24,0) -> 0 | AH24: =AF24+AA24 -> 0 | AI24: =SUM(AH24+V24) -> 705 | AJ24: =-tanks!AW25 -> 705 | AK24: =SUM(AJ24-AI24) -> 0 | AL24: =S24+L24+G24 -> 8 | AM24: =Y24+AD24 -> 0 | AN24: 79 | AO24: =(AN24/100)*3000 -> 2370 | AP24: 80 | AQ24: =(AP24/100)*3000 -> 2400 | AR24: 78 | AS24: =(AR24/100)*3000 -> 2340 | AT24: =SUM(AO24+AQ24+AS24) -> 7110 | AU24: =AT23-AT24+AV24 -> 90 | AX24: =IF(AV24>0,AW24,AX23) -> 0.7
A25: 43820 | B25: 216 | C25: 179 | D25: =C24-C25 -> 14 | E25: =D25*8.38 -> 117.32 | F25: 1267 | G25: =F25-F24 -> 11 | H25: 327405 | I25: =SUM(H25-H24) -> 814 | J25: =IF(G25>0,I25/G25,0) -> 74 | K25: =K24 -> 1615 | L25: =K25-K24 -> 0 | M25: =M24 -> 117578 | N25: =M25-M24 -> 0 | O25: =SUM(L25*$J$1) -> 0 | P25: =P24 -> 1452 | Q25: =Q24 -> 126239 | R25: =Q25-Q24 -> 0 | S25: =SUM(P25-P24) -> 0 | T25: =SUM(S25*$T$2) -> 0 | U25: =SUM(G25+L25+S25) -> 11 | V25: =R25+N25+I25:I25 -> 814 | X25: =X24 -> 2289 | Y25: =X25-X24 -> 0 | Z25: =Z24 -> 128954.4 | AA25: =Z25-Z24 -> 0 | AB25: =SUM(Y25*$AB$2) -> 0 | AC25: =AC24 -> 1688 | AD25: =AC25-AC24 -> 0 | AE25: =AE24 -> 351848.7 | AF25: =AE25-AE24 -> 0 | AG25: =IF(AD25>0,AF25/AD25,0) -> 0 | AH25: =AF25+AA25 -> 0 | AI25: =SUM(AH25+V25) -> 814 | AJ25: =-tanks!AW26 -> 814 | AK25: =SUM(AJ25-AI25) -> 0 | AL25: =S25+L25+G25 -> 11 | AM25: =Y25+AD25 -> 0 | AN25: =AN24 -> 79 | AO25: =(AN25/100)*3000 -> 2370 | AP25: 78 | AQ25: =(AP25/100)*3000 -> 2340 | AR25: 76 | AS25: =(AR25/100)*3000 -> 2280 | AT25: =SUM(AO25+AQ25+AS25) -> 6990 | AU25: =AT24-AT25+AV25 -> 120 | AX25: =IF(AV25>0,AW25,AX24) -> 0.7
A26: 43821 | B26: 213 | C26: 166 | D26: =C25-C26 -> 13 | E26: =D26*8.38 -> 108.94 | F26: 1274 | G26: =F26-F25 -> 7 | H26: 328001 | I26: =SUM(H26-H25) -> 596 | J26: =IF(G26>0,I26/G26,0) -> 85.142857 | K26: 1615 | L26: =K26-K25 -> 0 | M26: 117578 | N26: =M26-M25 -> 0 | O26: =SUM(L26*$J$1) -> 0 | P26: 1452 | Q26: 126239 | R26: =Q26-Q25 -> 0 | S26: =SUM(P26-P25) -> 0 | T26: =SUM(S26*$T$2) -> 0 | U26: =SUM(G26+L26+S26) -> 7 | V26: =R26+N26+I26:I26 -> 596 | X26: 2292 | Y26: =X26-X25 -> 3 | Z26: 129117 | AA26: =Z26-Z25 -> 162.6 | AB26: =SUM(Y26*$AB$2) -> 0 | AC26: 1688 | AD26: =AC26-AC25 -> 0 | AE26: 351848.7 | AF26: =AE26-AE25 -> 0 | AG26: =IF(AD26>0,AF26/AD26,0) -> 0 | AH26: =AF26+AA26 -> 162.6 | AI26: =SUM(AH26+V26) -> 758.6 | AJ26: =-tanks!AW27 -> 758.6 | AK26: =SUM(AJ26-AI26) -> 0 | AL26: =S26+L26+G26 -> 7 | AM26: =Y26+AD26 -> 3 | AN26: 73 | AO26: =(AN26/100)*3000 -> 2190 | AP26: 74 | AQ26: =(AP26/100)*3000 -> 2220 | AR26: 73 | AS26: =(AR26/100)*3000 -> 2190 | AT26: =SUM(AO26+AQ26+AS26) -> 6600 | AU26: =AT25-AT26+AV26 -> 390 | AX26: =IF(AV26>0,AW26,AX25) -> 0.7
A27: 43822 | B27: 209 | C27: 145 | D27: =C26-C27 -> 21 | E27: =D27*8.38 -> 175.98 | F27: 1283 | G27: =F27-F26 -> 9 | H27: 328697 | I27: =SUM(H27-H26) -> 696 | J27: =IF(G27>0,I27/G27,0) -> 77.333333 | K27: 1615 | L27: =K27-K26 -> 0 | M27: 117578 | N27: =M27-M26 -> 0 | O27: =SUM(L27*$J$1) -> 0 | P27: 1452 | Q27: 126239 | R27: =Q27-Q26 -> 0 | S27: =SUM(P27-P26) -> 0 | T27: =SUM(S27*$T$2) -> 0 | U27: =SUM(G27+L27+S27) -> 9 | V27: =R27+N27+I27:I27 -> 696 | X27: 2300 | Y27: =X27-X26 -> 8 | Z27: 129516.3 | AA27: =Z27-Z26 -> 399.3 | AB27: =SUM(Y27*$AB$2) -> 0 | AC27: 1688 | AD27: =AC27-AC26 -> 0 | AE27: 351848.7 | AF27: =AE27-AE26 -> 0 | AG27: =IF(AD27>0,AF27/AD27,0) -> 0 | AH27: =AF27+AA27 -> 399.3 | AI27: =SUM(AH27+V27) -> 1095.3 | AJ27: =-tanks!AW28 -> 1095.3 | AK27: =SUM(AJ27-AI27) -> 0 | AL27: =S27+L27+G27 -> 9 | AM27: =Y27+AD27 -> 8 | AN27: 70 | AO27: =(AN27/100)*3000 -> 2100 | AP27: 71 | AQ27: =(AP27/100)*3000 -> 2130 | AR27: 71 | AS27: =(AR27/100)*3000 -> 2130 | AT27: =SUM(AO27+AQ27+AS27) -> 6360 | AU27: =AT26-AT27+AV27 -> 240 | AX27: =IF(AV27>0,AW27,AX26) -> 0.7
