Workbook

Sheet Total
A1: Site Name | B1: Day | C1: Month | D1: Year | E1: Total Electricity Kwh | F1: Electricity Tariff ($/Kwh) | G1: Total Fuel Oil (Liters) | H1: Fuel Oil $/Liter | I1: LPG (Kg) | J1: LPG $/Kg | K1: Water Utility Supply (m3) m3 | L1: Water Utility Supply (m3) $/m3 | M1: Irrigation Water (m3) m3 | N1: Irrigation water $/m3 | O1: Room Nights
A2: Beirut | B2: 1 | C2: 1 | D2: 2020 | E2: =ELEC!N3 -> 14239 | F2: =SUM('EDl log'!T4) -> 0.084804296 | G2: =-tanks!AW6 -> 1458 | H2: =SUM(tanks!AV6) -> 0.5634 | I2: =('B5'!AU5)*0.51 -> 91.8 | J2: ='B5'!AX5/0.51 -> 1.372549 | K2: =WATER!I6 -> 19 | L2: =SUM(WATER!J6) -> 12.733447 | M2: =WATER!Q6 -> 0 | N2: 0.6 | O2: =ELEC!B3 -> 97.98
A3: Beirut | B3: =B2+1 -> 2 | C3: 1 | D3: 2020 | E3: =ELEC!N4 -> 15103 | F3: =SUM('EDl log'!T5) -> 0.085324029 | G3: =-tanks!AW7 -> 1092.3 | H3: =SUM(tanks!AV7) -> 0.5634 | I3: =('B5'!AU6)*0.51 -> 265.2 | J3: ='B5'!AX6/0.51 -> 1.372549 | K3: =WATER!I7 -> 316 | L3: =SUM(WATER!J7) -> 1.1858718 | M3: =WATER!Q7 -> 0 | N3: 0.6 | O3: =ELEC!B4 -> 77.004
A4: Beirut | B4: =B3+1 -> 3 | C4: 1 | D4: 2020 | E4: =ELEC!N5 -> 15173 | F4: =SUM('EDl log'!T6) -> 0.098842411 | G4: =-tanks!AW8 -> 1325.9 | H4: =SUM(tanks!AV8) -> 0.5634 | I4: =('B5'!AU7)*0.51 -> 91.8 | J4: ='B5'!AX7/0.51 -> 1.372549 | K4: =WATER!I8 -> 0 | L4: =SUM(WATER!J8) -> 0 | M4: =WATER!Q8 -> 0 | N4: 0.6 | O4: =ELEC!B5 -> 63.986
A5: Beirut | B5: =B4+1 -> 4 | C5: 1 | D5: 2020 | E5: =ELEC!N6 -> 15817 | F5: =SUM('EDl log'!T7) -> 0.11620381 | G5: =-tanks!AW9 -> 944 | H5: =SUM(tanks!AV9) -> 0.5634 | I5: =('B5'!AU8)*0.51 -> 122.4 | J5: ='B5'!AX8/0.51 -> 1.372549 | K5: =WATER!I9 -> 288 | L5: =SUM(WATER!J9) -> 0.84005376 | M5: =WATER!Q9 -> 0 | N5: 0.6 | O5: =ELEC!B6 -> 48.99
A6: Beirut | B6: =B5+1 -> 5 | C6: 1 | D6: 2020 | E6: =ELEC!N7 -> 12909 | F6: =SUM('EDl log'!T8) -> 0.077101725 | G6: =-tanks!AW10 -> 1107.7 | H6: =SUM(tanks!AV10) -> 0.5634 | I6: =('B5'!AU9)*0.51 -> 137.7 | J6: ='B5'!AX9/0.51 -> 1.372549 | K6: =WATER!I10 -> 0 | L6: =SUM(WATER!J10) -> 0 | M6: =WATER!Q10 -> 0 | N6: 0.6 | O6: =ELEC!B7 -> 37.007
A7: Beirut | B7: =B6+1 -> 6 | C7: 1 | D7: 2020 | E7: =ELEC!N8 -> 13138 | F7: =SUM('EDl log'!T9) -> 0.1456359 | G7: =-tanks!AW11 -> 607 | H7: =SUM(tanks!AV11) -> 0.5634 | I7: =('B5'!AU10)*0.51 -> 91.8 | J7: ='B5'!AX10/0.51 -> 1.372549 | K7: =WATER!I11 -> 179 | L7: =SUM(WATER!J11) -> 1.3515949 | M7: =WATER!Q11 -> 0 | N7: 0.6 | O7: =ELEC!B8 -> 37.996
A8: Beirut | B8: =B7+1 -> 7 | C8: 1 | D8: 2020 | E8: =ELEC!N9 -> 12872 | F8: =SUM('EDl log'!T10) -> 0.085940773 | G8: =-tanks!AW12 -> 1019.3 | H8: =SUM(tanks!AV12) -> 0.5634 | I8: =('B5'!AU11)*0.51 -> 107.1 | J8: ='B5'!AX11/0.51 -> 1.372549 | K8: =WATER!I12 -> 79 | L8: =SUM(WATER!J12) -> 4.7224745 | M8: =WATER!Q12 -> 0 | N8: 0.6 | O8: =ELEC!B9 -> 54.004
A9: Beirut | B9: =B8+1 -> 8 | C9: 1 | D9: 2020 | E9: =ELEC!N10 -> 12536.4 | F9: =SUM('EDl log'!T11) -> 0.16900847 | G9: =-tanks!AW13 -> 816 | H9: =SUM(tanks!AV13) -> 0.5634 | I9: =('B5'!AU12)*0.51 -> 122.4 | J9: ='B5'!AX12/0.51 -> 1.372549 | K9: =WATER!I13 -> 182 | L9: =SUM(WATER!J13) -> 1.3293158 | M9: =WATER!Q13 -> 0 | N9: 0.6 | O9: =ELEC!B10 -> 53.82
A10: Beirut | B10: =B9+1 -> 9 | C10: 1 | D10: 2020 | E10: =ELEC!N11 -> 13631.6 | F10: =SUM('EDl log'!T12) -> 0.17783583 | G10: =-tanks!AW14 -> 853 | H10: =SUM(tanks!AV14) -> 0.5765 | I10: =('B5'!AU13)*0.51 -> 183.6 | J10: ='B5'!AX13/0.51 -> 1.372549 | K10: =WATER!I14 -> 80 | L10: =SUM(WATER!J14) -> 4.6841935 | M10: =WATER!Q14 -> 0 | N10: 0.6 | O10: =ELEC!B11 -> 48.001
A11: Beirut | B11: =B10+1 -> 10 | C11: 1 | D11: 2020 | E11: =ELEC!N12 -> 13062.8 | F11: =SUM('EDl log'!T13) -> 0.063701517 | G11: =-tanks!AW15 -> 1461.8 | H11: =SUM(tanks!AV15) -> 0.5765 | I11: =('B5'!AU14)*0.51 -> 61.2 | J11: ='B5'!AX14/0.51 -> 1.372549 | K11: =WATER!I15 -> 343 | L11: =SUM(WATER!J15) -> 0.70535126 | M11: =WATER!Q15 -> 0 | N11: 0.6 | O11: =ELEC!B12 -> 46
A12: Beirut | B12: =B11+1 -> 11 | C12: 1 | D12: 2020 | E12: =ELEC!N13 -> 14011.2 | F12: =SUM('EDl log'!T14) -> 0.098457917 | G12: =-tanks!AW16 -> 728 | H12: =SUM(tanks!AV16) -> 0.5765 | I12: =('B5'!AU15)*0.51 -> 45.9 | J12: ='B5'!AX15/0.51 -> 1.372549 | K12: =WATER!I16 -> 0 | L12: =SUM(WATER!J16) -> 0 | M12: =WATER!Q16 -> 0 | N12: 0.6 | O12: =ELEC!B13 -> 39.008
A13: Beirut | B13: =B12+1 -> 12 | C13: 1 | D13: 2020 | E13: =ELEC!N14 -> 14175 | F13: =SUM('EDl log'!T15) -> 0.074378763 | G13: =-tanks!AW17 -> 543 | H13: =SUM(tanks!AV17) -> 0.5765 | I13: =('B5'!AU16)*0.51 -> 122.4 | J13: ='B5'!AX16/0.51 -> 1.372549 | K13: =WATER!I17 -> 737 | L13: =SUM(WATER!J17) -> 0.32827067 | M13: =WATER!Q17 -> 0 | N13: 0.6 | O13: =ELEC!B14 -> 39.997
A14: Beirut | B14: =B13+1 -> 13 | C14: 1 | D14: 2020 | E14: =ELEC!N15 -> 12801 | F14: =SUM('EDl log'!T16) -> 0.093320379 | G14: =-tanks!AW18 -> 749 | H14: =SUM(tanks!AV18) -> 0.5765 | I14: =('B5'!AU17)*0.51 -> 122.4 | J14: ='B5'!AX17/0.51 -> 1.372549 | K14: =WATER!I18 -> 0 | L14: =SUM(WATER!J18) -> 0 | M14: =WATER!Q18 -> 0 | N14: 0.6 | O14: =ELEC!B15 -> 41.998
... A32: Beirut | B32: =B31+1 -> 31 | C32: 1 | D32: 2020 | E32: =ELEC!N33 -> 0 | F32: =SUM('EDl log'!T34) -> 0 | G32: =-tanks!AW36 -> 0 | H32: =SUM(tanks!AV36) -> 0.5835 | I32: =('B5'!AU35)*0.51 -> 0 | J32: ='B5'!AX35/0.51 -> 1.372549 | K32: =WATER!I36 -> 0 | L32: =SUM(WATER!J36) -> 0 | M32: =WATER!Q36 -> 0 | N32: 0.6 | O32: =ELEC!B33 -> 0

Sheet Submetering
A1: Site Name | B1: Day | C1: Month | D1: Year | E1: ATS1 Kwh | F1: ATS2 Kwh | G1: ATS3 Kwh | H1: ATS4 Kwh | I1: ATS5 Kwh | J1: Guest (m3) | K1: Kitchen & Laundry (m3) | L1: Room Nights
A2: Beirut | B2: 1 | C2: 1 | D2: 2020 | E2: =ELEC!M3 -> 4850 | F2: =ELEC!K3 -> 1588 | G2: =ELEC!I3 -> 2628 | H2: =ELEC!E3 -> 2900 | I2: =ELEC!G3 -> 2273 | J2: =WATER!Y6 -> 48 | K2: =WATER!AJ6 -> 81 | L2: =ELEC!B3 -> 97.98
A3: Beirut | B3: =B2+1 -> 2 | C3: 1 | D3: 2020 | E3: =ELEC!M4 -> 4714 | F3: =ELEC!K4 -> 1882 | G3: =ELEC!I4 -> 2598 | H3: =ELEC!E4 -> 3560 | I3: =ELEC!G4 -> 2349 | J3: =WATER!Y7 -> 88 | K3: =WATER!AJ7 -> 59 | L3: =ELEC!B4 -> 77.004
A4: Beirut | B4: =B3+1 -> 3 | C4: 1 | D4: 2020 | E4: =ELEC!M5 -> 4880 | F4: =ELEC!K5 -> 1846 | G4: =ELEC!I5 -> 2558 | H4: =ELEC!E5 -> 3438 | I4: =ELEC!G5 -> 2451 | J4: =WATER!Y8 -> 20 | K4: =WATER!AJ8 -> 27 | L4: =ELEC!B5 -> 63.986
A5: Beirut | B5: =B4+1 -> 4 | C5: 1 | D5: 2020 | E5: =ELEC!M6 -> 5028 | F5: =ELEC!K6 -> 2324 | G5: =ELEC!I6 -> 2522 | H5: =ELEC!E6 -> 3480 | I5: =ELEC!G6 -> 2463 | J5: =WATER!Y9 -> 98 | K5: =WATER!AJ9 -> 2 | L5: =ELEC!B6 -> 48.99
A6: Beirut | B6: =B5+1 -> 5 | C6: 1 | D6: 2020 | E6: =ELEC!M7 -> 4398 | F6: =ELEC!K7 -> 1702 | G6: =ELEC!I7 -> 2078 | H6: =ELEC!E7 -> 2736 | I6: =ELEC!G7 -> 1995 | J6: =WATER!Y10 -> 4 | K6: =WATER!AJ10 -> 53 | L6: =ELEC!B7 -> 37.007
A7: Beirut | B7: =B6+1 -> 6 | C7: 1 | D7: 2020 | E7: =ELEC!M8 -> 3870 | F7: =ELEC!K8 -> 1900 | G7: =ELEC!I8 -> 2188 | H7: =ELEC!E8 -> 3034 | I7: =ELEC!G8 -> 2146 | J7: =WATER!Y11 -> 54 | K7: =WATER!AJ11 -> 57 | L7: =ELEC!B8 -> 37.996
A8: Beirut | B8: =B7+1 -> 7 | C8: 1 | D8: 2020 | E8: =ELEC!M9 -> 3880 | F8: =ELEC!K9 -> 1810 | G8: =ELEC!I9 -> 2068 | H8: =ELEC!E9 -> 2972 | I8: =ELEC!G9 -> 2142 | J8: =WATER!Y12 -> 0 | K8: =WATER!AJ12 -> 31 | L8: =ELEC!B9 -> 54.004
A9: Beirut | B9: =B8+1 -> 8 | C9: 1 | D9: 2020 | E9: =ELEC!M10 -> 3650 | F9: =ELEC!K10 -> 1850 | G9: =ELEC!I10 -> 2170 | H9: =ELEC!E10 -> 2648 | I9: =ELEC!G10 -> 2218.4 | J9: =WATER!Y13 -> 68 | K9: =WATER!AJ13 -> 58 | L9: =ELEC!B10 -> 53.82
A10: Beirut | B10: =B9+1 -> 9 | C10: 1 | D10: 2020 | E10: =ELEC!M11 -> 4112 | F10: =ELEC!K11 -> 1578 | G10: =ELEC!I11 -> 2178 | H10: =ELEC!E11 -> 3440 | I10: =ELEC!G11 -> 2323.6 | J10: =WATER!Y14 -> 52 | K10: =WATER!AJ14 -> 4 | L10: =ELEC!B11 -> 48.001
A11: Beirut | B11: =B10+1 -> 10 | C11: 1 | D11: 2020 | E11: =ELEC!M12 -> 3938 | F11: =ELEC!K12 -> 1634 | G11: =ELEC!I12 -> 2182 | H11: =ELEC!E12 -> 3044 | I11: =ELEC!G12 -> 2264.8 | J11: =WATER!Y15 -> 140 | K11: =WATER!AJ15 -> 51 | L11: =ELEC!B12 -> 46
A12: Beirut | B12: =B11+1 -> 11 | C12: 1 | D12: 2020 | E12: =ELEC!M13 -> 4798 | F12: =ELEC!K13 -> 1598 | G12: =ELEC!I13 -> 2306 | H12: =ELEC!E13 -> 3078 | I12: =ELEC!G13 -> 2231.2 | J12: =WATER!Y16 -> 67 | K12: =WATER!AJ16 -> 35 | L12: =ELEC!B13 -> 39.008
A13: Beirut | B13: =B12+1 -> 12 | C13: 1 | D13: 2020 | E13: =ELEC!M14 -> 4462 | F13: =ELEC!K14 -> 1534 | G13: =ELEC!I14 -> 2480 | H13: =ELEC!E14 -> 3214 | I13: =ELEC!G14 -> 2485 | J13: =WATER!Y17 -> 101 | K13: =WATER!AJ17 -> 110 | L13: =ELEC!B14 -> 39.997
A14: Beirut | B14: =B13+1 -> 13 | C14: 1 | D14: 2020 | E14: =ELEC!M15 -> 3916 | F14: =ELEC!K15 -> 2088 | G14: =ELEC!I15 -> 2052 | H14: =ELEC!E15 -> 2560 | I14: =ELEC!G15 -> 2185 | J14: =WATER!Y18 -> 75 | K14: =WATER!AJ18 -> 0 | L14: =ELEC!B15 -> 41.998
... A32: Beirut | B32: =B31+1 -> 31 | C32: 1 | D32: 2020 | E32: =ELEC!M33 -> 0 | F32: =ELEC!K33 -> 0 | G32: =ELEC!I33 -> 0 | H32: =ELEC!E33 -> 0 | I32: =ELEC!G33 -> 0 | J32: =WATER!Y36 -> 0 | K32: =WATER!AJ36 -> 0 | L32: =ELEC!B33 -> 0

Sheet ELEC
A1: OOC | B1: Room OCC | D1: MDB3 | E1: MDB3/day | F1: EMDB2 | G1: EMDB2/day | H1: EMDB1 | I1: EMDB1/day | J1: MDB2 | K1: mdb2/day | L1: MDB1 | M1: MDB1/Day | N1: Total KWH | O1: KWH/Rooc | P1: Gen MHW | Q1: Gen/Day KWH | R1: EDL KWH | S1: CH1 RH | T1: RH | U1: C1h1 power | V1: CH1 Con KWH | W1: CH2 RH | X1: RH | Y1: Ch2 power | Z1: CH2 Con KWH | AA1: CH3 RH | AB1: RH | AC1: Ch3 power | AD1: CH3 Con KWH | AE1: RH total | AF1: KWH total | AG1: AVG chiller KW/Hr
A2: 0.1391 | B2: 0.1391 | C2: 31-12-2019 | D2: =[1]ELEC!D33 -> 31308238 | E2: =[1]ELEC!E33 -> 3678 | F2: =[1]ELEC!F33 -> 3431349 | G2: =[1]ELEC!G33 -> 2479 | H2: =[1]ELEC!H33 -> 17219918 | I2: =[1]ELEC!I33 -> 2804 | J2: =[1]ELEC!J33 -> 28230090 | K2: =[1]ELEC!K33 -> 3048 | ... AI2: =[1]ELEC!AI33 -> -49239434
A3: ='General information '!F6 -> 0.426 | B3: =SUM(230*A3) -> 97.98 | C3: 43831 | D3: 31311138 | E3: =D3-D2 -> 2900 | F3: 3433622 | G3: =F3-F2 -> 2273 | H3: 17222546 | I3: =H3-H2 -> 2628 | J3: 28231678 | K3: =J3-J2 -> 1588 | L3: 22527696 | M3: =L3-L2 -> 4850 | N3: =M3+K3+I3+G3+E3 -> 14239 | O3: =IF(B3>0,N3/B3,0) -> 145.32558 | P3: 15220.747 | Q3: =(P3-P2)*1000 -> 2547 | R3: =+N3-Q3 -> 11692 | S3: 8341 | T3: =S3-S2 -> 7 | U3: 1015726 | V3: =U3-U2 -> 1093 | W3: 31800 | X3: =W3-W2 -> 0 | Y3: 616769 | Z3: =Y3-Y2 -> 0 | AA3: 34851 | AB3: =AA3-AA2 -> 0 | AC3: 735699 | AD3: =AC3-AC2 -> 0 | AE3: =AB3+X3+T3 -> 7 | AF3: =V3+Z3+AD3 -> 1093 | AG3: =IF(AE3>0,AF3/AE3,0) -> 156.14286
A4: ='General information '!F7 -> 0.3348 | B4: =SUM(230*A4) -> 77.004 | C4: 43832 | D4: 31314698 | E4: =D4-D3 -> 3560 | F4: 3435971 | G4: =F4-F3 -> 2349 | H4: 17225144 | I4: =H4-H3 -> 2598 | J4: 28233560 | K4: =J4-J3 -> 1882 | L4: 22532410 | M4: =L4-L3 -> 4714 | N4: =M4+K4+I4+G4+E4 -> 15103 | O4: =IF(B4>0,N4/B4,0) -> 196.13267 | P4: 15225.369 | Q4: =(P4-P3)*1000 -> 4622 | R4: =N4-Q4 -> 10481 | S4: 8345 | T4: =S4-S3 -> 4 | U4: 1016381 | V4: =U4-U3 -> 655 | W4: 31802 | X4: =W4-W3 -> 2 | Y4: 617066 | Z4: =Y4-Y3 -> 297 | AA4: 34853 | AB4: =AA4-AA3 -> 2 | AC4: 736029 | AD4: =AC4-AC3 -> 330 | AE4: =AB4+X4+T4 -> 8 | AF4: =V4+Z4+AD4 -> 1282 | AG4: =IF(AE4>0,AF4/AE4,0) -> 160.25
A5: ='General information '!F8 -> 0.2782 | B5: =SUM(230*A5) -> 63.986 | C5: 43833 | D5: 31318136 | E5: =D5-D4 -> 3438 | F5: 3438422 | G5: =F5-F4 -> 2451 | H5: 17227702 | I5: =H5-H4 -> 2558 | J5: 28235406 | K5: =J5-J4 -> 1846 | L5: 22537290 | M5: =L5-L4 -> 4880 | N5: =M5+K5+I5+G5+E5 -> 15173 | O5: =IF(B5>0,N5/B5,0) -> 237.13 | P5: 15230 | Q5: =(P5-P4)*1000 -> 4631 | R5: =N5-Q5 -> 10542 | S5: 8350 | T5: =S5-S4 -> 5 | U5: 1017190 | V5: =U5-U4 -> 809 | W5: 31804 | X5: =W5-W4 -> 2 | Y5: 617292 | Z5: =Y5-Y4 -> 226 | AA5: 34855 | AB5: =AA5-AA4 -> 2 | AC5: 736416 | AD5: =AC5-AC4 -> 387 | AE5: =AB5+X5+T5 -> 9 | AF5: =V5+Z5+AD5 -> 1422 | AG5: =IF(AE5>0,AF5/AE5,0) -> 158 | AI5: =R5-'EDl log'!B3 -> -49262991
A6: ='General information '!F9 -> 0.213 | B6: =SUM(230*A6) -> 48.99 | C6: 43834 | D6: 31321616 | E6: =D6-D5 -> 3480 | F6: 3440885 | G6: =F6-F5 -> 2463 | H6: 17230224 | I6: =H6-H5 -> 2522 | J6: 28237730 | K6: =J6-J5 -> 2324 | L6: 22542318 | M6: =L6-L5 -> 5028 | N6: =M6+K6+I6+G6+E6 -> 15817 | O6: =IF(B6>0,N6/B6,0) -> 322.86181 | P6: 15234 | Q6: =(P6-P5)*1000 -> 4000 | R6: =N6-Q6 -> 11817 | S6: 8352 | T6: =S6-S5 -> 2 | U6: 1017672 | V6: =U6-U5 -> 482 | W6: 31807 | X6: =W6-W5 -> 3 | Y6: 617924 | Z6: =Y6-Y5 -> 632 | AA6: 34855 | AB6: =AA6-AA5 -> 0 | AC6: =AC5 -> 736416 | AD6: =AC6-AC5 -> 0 | AE6: =AB6+X6+T6 -> 5 | AF6: =V6+Z6+AD6 -> 1114 | AG6: =IF(AE6>0,AF6/AE6,0) -> 222.8 | AI6: =R6-'EDl log'!B4 -> -49267868
A7: ='General information '!F10 -> 0.1609 | B7: =SUM(230*A7) -> 37.007 | C7: 43835 | D7: 31324352 | E7: =D7-D6 -> 2736 | F7: 3442880 | G7: =F7-F6 -> 1995 | H7: 17232302 | I7: =H7-H6 -> 2078 | J7: 28239432 | K7: =J7-J6 -> 1702 | L7: 22546716 | M7: =L7-L6 -> 4398 | N7: =M7+K7+I7+G7+E7 -> 12909 | O7: =IF(B7>0,N7/B7,0) -> 348.8259 | P7: 15236.586 | Q7: =(P7-P6)*1000 -> 2586 | R7: =N7-Q24 -> 11403 | S7: 8355 | T7: =S7-S6 -> 3 | U7: 1018314 | V7: =U7-U6 -> 642 | W7: 31810 | X7: =W7-W6 -> 3 | Y7: 618493 | Z7: =Y7-Y6 -> 569 | AA7: 34856 | AB7: =AA7-AA6 -> 1 | AC7: 736573 | AD7: =AC7-AC6 -> 157 | AE7: =AB7+X7+T7 -> 7 | AF7: =V7+Z7+AD7 -> 1368 | AG7: =IF(AE7>0,AF7/AE7,0) -> 195.42857 | AI7: =R7-'EDl log'!B5 -> -49273702
A8: ='General information '!F11 -> 0.1652 | B8: =SUM(230*A8) -> 37.996 | C8: 43836 | D8: 31327386 | E8: =D8-D7 -> 3034 | F8: 3445026 | G8: =F8-F7 -> 2146 | H8: 17234490 | I8: =H8-H7 -> 2188 | J8: 28241332 | K8: =J8-J7 -> 1900 | L8: 22550586 | M8: =L8-L7 -> 3870 | N8: =M8+K8+I8+G8+E8 -> 13138 | O8: =IF(B8>0,N8/B8,0) -> 345.77324 | P8: 15241.82 | Q8: =(P8-P7)*1000 -> 5234 | R8: =N8-Q8 -> 7904 | S8: 8357 | T8: =S8-S7 -> 2 | U8: 1018561 | V8: =U8-U7 -> 247 | W8: 31813 | X8: =W8-W7 -> 3 | Y8: 619036 | Z8: =Y8-Y7 -> 543 | AA8: 34857 | AB8: =AA8-AA7 -> 1 | AC8: 736709 | AD8: =AC8-AC7 -> 136 | AE8: =AB8+X8+T8 -> 6 | AF8: =V8+Z8+AD8 -> 926 | AG8: =IF(AE8>0,AF8/AE8,0) -> 154.33333 | AI8: =R8-'EDl log'!B6 -> -49282366
A9: ='General information '!F12 -> 0.2348 | B9: =SUM(230*A9) -> 54.004 | C9: 43837 | D9: 31330358 | E9: =D9-D8 -> 2972 | F9: 3447168 | G9: =F9-F8 -> 2142 | H9: 17236558 | I9: =H9-H8 -> 2068 | J9: 28243142 | K9: =J9-J8 -> 1810 | L9: 22554466 | M9: =L9-L8 -> 3880 | N9: =M9+K9+I9+G9+E9 -> 12872 | O9: =IF(B9>0,N9/B9,0) -> 238.35271 | P9: 15246.699 | Q9: =(P9-P8)*1000 -> 4879 | R9: =N9-Q9 -> 7993 | S9: 8358 | T9: =S9-S8 -> 1 | U9: 1018775 | V9: =U9-U8 -> 214 | W9: 31816 | X9: =W9-W8 -> 3 | Y9: 619479 | Z9: =Y9-Y8 -> 443 | AA9: 34858 | AB9: =AA9-AA8 -> 1 | AC9: 736958 | AD9: =AC9-AC8 -> 249 | AE9: =AB9+X9+T9 -> 5 | AF9: =V9+Z9+AD9 -> 906 | AG9: =IF(AE9>0,AF9/AE9,0) -> 181.2 | AI9: =R9-'EDl log'!B7 -> -49288394
A10: ='General information '!F13 -> 0.234 | B10: =SUM(230*A10) -> 53.82 | C10: 43838 | D10: 31333006 | E10: =D10-D9 -> 2648 | F10: 3449386.4 | G10: =F10-F9 -> 2218.4 | H10: 17238728 | I10: =H10-H9 -> 2170 | J10: 28244992 | K10: =J10-J9 -> 1850 | L10: 22558116 | M10: =L10-L9 -> 3650 | N10: =M10+K10+I10+G10+E10 -> 12536.4 | O10: =IF(B10>0,N10/B10,0) -> 232.932 | P10: 15253.7 | Q10: =(P10-P9)*1000 -> 7001 | R10: =N10-Q10 -> 5535.4 | S10: =S9 -> 8358 | T10: =S10-S9 -> 0 | U10: =U9 -> 1018775 | V10: =U10-U9 -> 0 | W10: 31819 | X10: =W10-W9 -> 3 | Y10: 619891 | Z10: =Y10-Y9 -> 412 | AA10: 34858 | AB10: =AA10-AA9 -> 0 | AC10: =AC9 -> 736958 | AD10: =AC10-AC9 -> 0 | AE10: =AB10+X10+T10 -> 3 | AF10: =V10+Z10+AD10 -> 412 | AG10: =IF(AE10>0,AF10/AE10,0) -> 137.33333 | AI10: =R10-'EDl log'!B8 -> -49296483
A11: ='General information '!F14 -> 0.2087 | B11: =SUM(230*A11) -> 48.001 | C11: 43839 | D11: 31336446 | E11: =D11-D10 -> 3440 | F11: 3451710 | G11: =F11-F10 -> 2323.6 | H11: 17240906 | I11: =H11-H10 -> 2178 | J11: 28246570 | K11: =J11-J10 -> 1578 | L11: 22562228 | M11: =L11-L10 -> 4112 | N11: =M11+K11+I11+G11+E11 -> 13631.6 | O11: =IF(B11>0,N11/B11,0) -> 283.98575 | P11: 15258.586 | Q11: =(P11-P10)*1000 -> 4886 | R11: =N11-Q11 -> 8745.6 | S11: 8359 | T11: =S11-S10 -> 1 | U11: 1019129 | V11: =U11-U10 -> 354 | W11: 31819 | X11: =W11-W10 -> 0 | Y11: 619891 | Z11: =Y11-Y10 -> 0 | AA11: 34861 | AB11: =AA11-AA10 -> 3 | AC11: 737484 | AD11: =AC11-AC10 -> 526 | AE11: =AB11+X11+T11 -> 4 | AF11: =V11+Z11+AD11 -> 880 | AG11: =IF(AE11>0,AF11/AE11,0) -> 220 | AI11: =R11-'EDl log'!B9 -> -49297371
A12: ='General information '!F15 -> 0.2 | B12: =SUM(230*A12) -> 46 | C12: 43840 | D12: 31339490 | E12: =D12-D11 -> 3044 | F12: 3453974.8 | G12: =F12-F11 -> 2264.8 | H12: 17243088 | I12: =H12-H11 -> 2182 | J12: 28248204 | K12: =J12-J11 -> 1634 | L12: 22566166 | M12: =L12-L11 -> 3938 | N12: =M12+K12+I12+G12+E12 -> 13062.8 | O12: =IF(B12>0,N12/B12,0) -> 283.97391 | P12: 15261 | Q12: =(P12-P11)*1000 -> 2414 | R12: =N12-Q12 -> 10648.8 | S12: 8360 | T12: =S12-S11 -> 1 | U12: 1019198 | V12: =U12-U11 -> 69 | W12: 31820 | X12: =W12-W11 -> 1 | Y12: 620062 | Z12: =Y12-Y11 -> 171 | AA12: 34864 | AB12: =AA12-AA11 -> 3 | AC12: 737985 | AD12: =AC12-AC11 -> 501 | AE12: =AB12+X12+T12 -> 5 | AF12: =V12+Z12+AD12 -> 741 | AG12: =IF(AE12>0,AF12/AE12,0) -> 148.2 | AI12: =R12-'EDl log'!B10 -> -49299637
A13: ='General information '!F16 -> 0.1696 | B13: =SUM(230*A13) -> 39.008 | C13: 43841 | D13: 31342568 | E13: =D13-D12 -> 3078 | F13: 3456206 | G13: =F13-F12 -> 2231.2 | H13: 17245394 | I13: =H13-H12 -> 2306 | J13: 28249802 | K13: =J13-J12 -> 1598 | L13: 22570964 | M13: =L13-L12 -> 4798 | N13: =M13+K13+I13+G13+E13 -> 14011.2 | O13: =IF(B13>0,N13/B13,0) -> 359.18786 | P13: 15262.643 | Q13: =(P13-P12)*1000 -> 1643 | R13: =N13-Q13 -> 12368.2 | S13: 8362 | T13: =S13-S12 -> 2 | U13: 1019557 | V13: =U13-U12 -> 359 | W13: 31821 | X13: =W13-W12 -> 1 | Y13: 620205 | Z13: =Y13-Y12 -> 143 | AA13: 34865 | AB13: =AA13-AA12 -> 1 | AC13: 738305 | AD13: =AC13-AC12 -> 320 | AE13: =AB13+X13+T13 -> 4 | AF13: =V13+Z13+AD13 -> 822 | AG13: =IF(AE13>0,AF13/AE13,0) -> 205.5 | AI13: =R13-'EDl log'!B11 -> -49300715
A14: ='General information '!F17 -> 0.1739 | B14: =SUM(230*A14) -> 39.997 | C14: 43842 | D14: 31345782 | E14: =D14-D13 -> 3214 | F14: 3458691 | G14: =F14-F13 -> 2485 | H14: 17247874 | I14: =H14-H13 -> 2480 | J14: 28251336 | K14: =J14-J13 -> 1534 | L14: 22575426 | M14: =L14-L13 -> 4462 | N14: =M14+K14+I14+G14+E14 -> 14175 | O14: =IF(B14>0,N14/B14,0) -> 354.40158 | P14: 15264.76 | Q14: =(P14-P13)*1000 -> 2117 | R14: =N14-Q14 -> 12058 | S14: 8362 | T14: =S14-S13 -> 0 | U14: 1019557 | V14: =U14-U13 -> 0 | W14: 31821 | X14: =W14-W13 -> 0 | Y14: 620205 | Z14: =Y14-Y13 -> 0 | AA14: 34868 | AB14: =AA14-AA13 -> 3 | AC14: 738769 | AD14: =AC14-AC13 -> 464 | AE14: =AB14+X14+T14 -> 3 | AF14: =V14+Z14+AD14 -> 464 | AG14: =IF(AE14>0,AF14/AE14,0) -> 154.66667 | AI14: =R14-'EDl log'!B12 -> -49305644
A15: ='General information '!F18 -> 0.1826 | B15: =SUM(230*A15) -> 41.998 | C15: 43843 | D15: 31348342 | E15: =D15-D14 -> 2560 | F15: 3460876 | G15: =F15-F14 -> 2185 | H15: 17249926 | I15: =H15-H14 -> 2052 | J15: 28253424 | K15: =J15-J14 -> 2088 | L15: 22579342 | M15: =L15-L14 -> 3916 | N15: =M15+K15+I15+G15+E15 -> 12801 | O15: =IF(B15>0,N15/B15,0) -> 304.80023 | P15: 15267.071 | Q15: =(P15-P14)*1000 -> 2311 | R15: =N15-Q15 -> 10490 | S15: 8362 | T15: =S15-S14 -> 0 | U15: 1019557 | V15: =U15-U14 -> 0 | W15: 31825 | X15: =W15-W14 -> 4 | Y15: 620936 | Z15: =Y15-Y14 -> 731 | AA15: 34868 | AB15: =AA15-AA14 -> 0 | AC15: 738769 | AD15: =AC15-AC14 -> 0 | AE15: =AB15+X15+T15 -> 4 | AF15: =V15+Z15+AD15 -> 731 | AG15: =IF(AE15>0,AF15/AE15,0) -> 182.75 | AI15: =R15-'EDl log'!B13 -> -49312756
A16: ='General information '!F19 -> 0.2087 | B16: =SUM(230*A16) -> 48.001 | C16: 43844 | D16: 31350742 | E16: =D16-D15 -> 2400 | F16: 3462918 | G16: =F16-F15 -> 2042 | H16: 17252062 | I16: =H16-H15 -> 2136 | J16: 28255052 | K16: =J16-J15 -> 1628 | L16: 22583714 | M16: =L16-L15 -> 4372 | N16: =M16+K16+I16+G16+E16 -> 12578 | O16: =IF(B16>0,N16/B16,0) -> 262.03621 | P16: 15269.875 | Q16: =(P16-P15)*1000 -> 2804 | R16: =N16-Q16 -> 9774 | S16: 8363 | T16: =S16-S15 -> 1 | U16: 1019914 | V16: =U16-U15 -> 357 | W16: 31826 | X16: =W16-W15 -> 1 | Y16: 621137 | Z16: =Y16-Y15 -> 201 | AA16: 34868 | AB16: =AA16-AA15 -> 0 | AC16: 738769 | AD16: =AC16-AC15 -> 0 | AE16: =AB16+X16+T16 -> 2 | AF16: =V16+Z16+AD16 -> 558 | AG16: =IF(AE16>0,AF16/AE16,0) -> 279 | AI16: =R16-'EDl log'!B14 -> -49319823
A17: ='General information '!F20 -> 0.2261 | B17: =SUM(230*A17) -> 52.003 | C17: 43845 | D17: 31353438 | E17: =D17-D16 -> 2696 | F17: 3465049 | G17: =F17-F16 -> 2131 | H17: 17254166 | I17: =H17-H16 -> 2104 | J17: 28256730 | K17: =J17-J16 -> 1678 | L17: 22587984 | M17: =L17-L16 -> 4270 | N17: =M17+K17+I17+G17+E17 -> 12879 | O17: =IF(B17>0,N17/B17,0) -> 247.65879 | P17: 15272.521 | Q17: =(P17-P16)*1000 -> 2646 | R17: =N17-Q17 -> 10233 | S17: 8364 | T17: =S17-S16 -> 1 | U17: 1020115 | V17: =U17-U16 -> 201 | W17: 31827 | X17: =W17-W16 -> 1 | Y17: 621317 | Z17: =Y17-Y16 -> 180 | AA17: 34869 | AB17: =AA17-AA16 -> 1 | AC17: 739022 | AD17: =AC17-AC16 -> 253 | AE17: =AB17+X17+T17 -> 3 | AF17: =V17+Z17+AD17 -> 634 | AG17: =IF(AE17>0,AF17/AE17,0) -> 211.33333 | AI17: =R17-'EDl log'!B15 -> -49325513
A18: ='General information '!F21 -> 0.2261 | B18: =SUM(230*A18) -> 52.003 | C18: 43846 | D18: 31355626 | E18: =D18-D17 -> 2188 | F18: 3466916.4 | G18: =F18-F17 -> 1867.4 | H18: 17255862 | I18: =H18-H17 -> 1696 | J18: 28258666 | K18: =J18-J17 -> 1936 | L18: 22591666 | M18: =L18-L17 -> 3682 | N18: =M18+K18+I18+G18+E18 -> 11369.4 | O18: =IF(B18>0,N18/B18,0) -> 218.62969 | P18: 15277.001 | Q18: =(P18-P17)*1000 -> 4480 | R18: =N18-Q18 -> 6889.4 | S18: 8366 | T18: =S18-S17 -> 2 | U18: 1020406 | V18: =U18-U17 -> 291 | W18: 31831 | X18: =W18-W17 -> 4 | Y18: 622008 | Z18: =Y18-Y17 -> 691 | AA18: =AA17 -> 34869 | AB18: =AA18-AA17 -> 0 | AC18: =AC17 -> 739022 | AD18: =AC18-AC17 -> 0 | AE18: =AB18+X18+T18 -> 6 | AF18: =V18+Z18+AD18 -> 982 | AG18: =IF(AE18>0,AF18/AE18,0) -> 163.66667 | AI18: =R18-'EDl log'!B16 -> -49334319
A19: ='General information '!F22 -> 0.1739 | B19: =SUM(230*A19) -> 39.997 | C19: 43847 | D19: 31358932 | E19: =D19-D18 -> 3306 | F19: 3469290 | G19: =F19-F18 -> 2373.6 | H19: 17258222 | I19: =H19-H18 -> 2360 | J19: 28260246 | K19: =J19-J18 -> 1580 | L19: 22596296 | M19: =L19-L18 -> 4630 | N19: =M19+K19+I19+G19+E19 -> 14249.6 | O19: =IF(B19>0,N19/B19,0) -> 356.26672 | P19: 15279.015 | Q19: =(P19-P18)*1000 -> 2014 | R19: =N19-Q19 -> 12235.6 | S19: 8367 | T19: =S19-S18 -> 1 | U19: 1020832 | V19: =U19-U18 -> 426 | W19: =W18 -> 31831 | X19: =W19-W18 -> 0 | Y19: =Y18 -> 622008 | Z19: =Y19-Y18 -> 0 | AA19: 34871 | AB19: =AA19-AA18 -> 2 | AC19: 739336 | AD19: =AC19-AC18 -> 314 | AE19: =AB19+X19+T19 -> 3 | AF19: =V19+Z19+AD19 -> 740 | AG19: =IF(AE19>0,AF19/AE19,0) -> 246.66667 | AI19: =R19-'EDl log'!B17 -> -49333934
A20: ='General information '!F23 -> 0.0957 | B20: =SUM(230*A20) -> 22.011 | C20: 43848 | D20: 31361354 | E20: =D20-D19 -> 2422 | F20: 3471402 | G20: =F20-F19 -> 2112 | H20: 17260214 | I20: =H20-H19 -> 1992 | J20: 28261566 | K20: =J20-J19 -> 1320 | L20: 22599594 | M20: =L20-L19 -> 3298 | N20: =M20+K20+I20+G20+E20 -> 11144 | O20: =IF(B20>0,N20/B20,0) -> 506.29231 | P20: 15282 | Q20: =(P20-P19)*1000 -> 2985 | R20: =N20-Q20 -> 8159 | S20: =S19 -> 8367 | T20: =S20-S19 -> 0 | U20: =U19 -> 1020832 | V20: =U20-U19 -> 0 | W20: =W19 -> 31831 | X20: =W20-W19 -> 0 | Y20: =Y19 -> 622008 | Z20: =Y20-Y19 -> 0 | AA20: 34872 | AB20: =AA20-AA19 -> 1 | AC20: 739653 | AD20: =AC20-AC19 -> 317 | AE20: =AB20+X20+T20 -> 1 | AF20: =V20+Z20+AD20 -> 317 | AG20: =IF(AE20>0,AF20/AE20,0) -> 317 | AI20: =R20-'EDl log'!B18 -> -49343439
A21: ='General information '!F24 -> 0.0913 | B21: =SUM(230*A21) -> 20.999 | C21: 43849 | D21: 31362850 | E21: =D21-D20 -> 1496 | F21: 3473180 | G21: =F21-F20 -> 1778 | H21: 17261882 | I21: =H21-H20 -> 1668 | J21: 28262612 | K21: =J21-J20 -> 1046 | L21: 22602642 | M21: =L21-L20 -> 3048 | N21: =M21+K21+I21+G21+E21 -> 9036 | O21: =IF(B21>0,N21/B21,0) -> 430.30621 | P21: 15283.641 | Q21: =(P21-P20)*1000 -> 1641 | R21: =N21-Q21 -> 7395 | S21: 8367 | T21: =S21-S20 -> 0 | U21: 1020832 | V21: =U21-U20 -> 0 | W21: 31831 | X21: =W21-W20 -> 0 | Y21: 622008 | Z21: =Y21-Y20 -> 0 | AA21: 34872 | AB21: =AA21-AA20 -> 0 | AC21: 739653 | AD21: =AC21-AC20 -> 0 | AE21: =AB21+X21+T21 -> 0 | AF21: =V21+Z21+AD21 -> 0 | AG21: =IF(AE21>0,AF21/AE21,0) -> 0 | AI21: =R21-'EDl log'!B19 -> -49347825
A22: ='General information '!F25 -> 0.1087 | B22: =SUM(230*A22) -> 25.001 | C22: 43850 | D22: 31365678 | E22: =D22-D21 -> 2828 | F22: 3475174 | G22: =F22-F21 -> 1994 | H22: 17263862 | I22: =H22-H21 -> 1980 | J22: 28264114 | K22: =J22-J21 -> 1502 | L22: 22606238 | M22: =L22-L21 -> 3596 | N22: =M22+K22+I22+G22+E22 -> 11900 | O22: =IF(B22>0,N22/B22,0) -> 475.98096 | P22: 15285.763 | Q22: =(P22-P21)*1000 -> 2122 | R22: =N22-Q22 -> 9778 | S22: =S21 -> 8367 | T22: =S22-S21 -> 0 | U22: =U21 -> 1020832 | V22: =U22-U21 -> 0 | W22: 31833 | X22: =W22-W21 -> 2 | Y22: 622086 | Z22: =Y22-Y21 -> 78 | AA22: 34875 | AB22: =AA22-AA21 -> 3 | AC22: 740037 | AD22: =AC22-AC21 -> 384 | AE22: =AB22+X22+T22 -> 5 | AF22: =V22+Z22+AD22 -> 462 | AG22: =IF(AE22>0,AF22/AE22,0) -> 92.4 | AI22: =R22-'EDl log'!B20 -> -49351728
A23: ='General information '!F26 -> 0.1217 | B23: =SUM(230*A23) -> 27.991 | C23: 43851 | D23: 31367890 | E23: =D23-D22 -> 2212 | F23: 3477097.2 | G23: =F23-F22 -> 1923.2 | H23: 17265798 | I23: =H23-H22 -> 1936 | J23: 28265874 | K23: =J23-J22 -> 1760 | L23: 22609776 | M23: =L23-L22 -> 3538 | N23: =M23+K23+I23+G23+E23 -> 11369.2 | O23: =IF(B23>0,N23/B23,0) -> 406.17341 | P23: 15287.971 | Q23: =(P23-P22)*1000 -> 2208 | R23: =N23-Q23 -> 9161.2 | S23: =S22 -> 8367 | T23: =S23-S22 -> 0 | U23: =U22 -> 1020832 | V23: =U23-U22 -> 0 | W23: 31836 | X23: =W23-W22 -> 3 | Y23: 622669 | Z23: =Y23-Y22 -> 583 | AA23: =AA22 -> 34875 | AB23: =AA23-AA22 -> 0 | AC23: =AC22 -> 740037 | AD23: =AC23-AC22 -> 0 | AE23: =AB23+X23+T23 -> 3 | AF23: =V23+Z23+AD23 -> 583 | AG23: =IF(AE23>0,AF23/AE23,0) -> 194.33333 | AI23: =R23-'EDl log'!B21 -> -49356331
A24: ='General information '!F27 -> 0.13 | B24: =SUM(230*A24) -> 29.9 | C24: 43852 | D24: 31369798 | E24: =D24-D23 -> 1908 | F24: 3479115.2 | G24: =F24-F23 -> 2018 | H24: 17267778 | I24: =H24-H23 -> 1980 | J24: 28267176 | K24: =J24-J23 -> 1302 | L24: 22613538 | M24: =L24-L23 -> 3762 | N24: =M24+K24+I24+G24+E24 -> 10970 | O24: =IF(B24>0,N24/B24,0) -> 366.88963 | P24: 15289.477 | Q24: =(P24-P23)*1000 -> 1506 | R24: =N24-Q24 -> 9464 | S24: 8367 | T24: =S24-S23 -> 0 | U24: 1020832 | V24: =U24-U23 -> 0 | W24: 31836 | X24: =W24-W23 -> 0 | Y24: 622669 | Z24: =Y24-Y23 -> 0 | AA24: 34875 | AB24: =AA24-AA23 -> 0 | AC24: 740037 | AD24: =AC24-AC23 -> 0 | AE24: =AB24+X24+T24 -> 0 | AF24: =V24+Z24+AD24 -> 0 | AG24: =IF(AE24>0,AF24/AE24,0) -> 0 | AI24: =R24-'EDl log'!B22 -> -49360116
A25: ='General information '!F28 -> 0.1478 | B25: =SUM(230*A25) -> 33.994 | C25: 43853 | D25: 31371620 | E25: =D25-D24 -> 1822 | F25: 3481122 | G25: =F25-F24 -> 2006.8 | H25: 17269750 | I25: =H25-H24 -> 1972 | J25: 28268464 | K25: =J25-J24 -> 1288 | L25: 22617122 | M25: =L25-L24 -> 3584 | N25: =M25+K25+I25+G25+E25 -> 10672.8 | O25: =IF(B25>0,N25/B25,0) -> 313.96129 | P25: 15290.963 | Q25: =(P25-P24)*1000 -> 1486 | R25: =N25-Q25 -> 9186.8 | S25: =S24 -> 8367 | T25: =S25-S24 -> 0 | U25: =U24 -> 1020832 | V25: =U25-U24 -> 0 | W25: =W24 -> 31836 | X25: =W25-W24 -> 0 | Y25: =Y24 -> 622669 | Z25: =Y25-Y24 -> 0 | AA25: =AA24 -> 34875 | AB25: =AA25-AA24 -> 0 | AC25: =AC24 -> 740037 | AD25: =AC25-AC24 -> 0 | AE25: =AB25+X25+T25 -> 0 | AF25: =V25+Z25+AD25 -> 0 | AG25: =IF(AE25>0,AF25/AE25,0) -> 0 | AI25: =R25-'EDl log'!B23 -> -49365445
A26: ='General information '!F29 -> 0.113 | B26: =SUM(230*A26) -> 25.99 | C26: 43854 | D26: 31373586 | E26: =D26-D25 -> 1966 | F26: 3483034 | G26: =F26-F25 -> 1912 | H26: 17271710 | I26: =H26-H25 -> 1960 | J26: 28269814 | K26: =J26-J25 -> 1350 | L26: 22622055 | M26: =L26-L25 -> 4933 | N26: =M26+K26+I26+G26+E26 -> 12121 | O26: =IF(B26>0,N26/B26,0) -> 466.37168 | P26: 15292.985 | Q26: =(P26-P25)*1000 -> 2022 | R26: =N26-Q26 -> 10099 | S26: =S25 -> 8367 | T26: =S26-S25 -> 0 | U26: =U25 -> 1020832 | V26: =U26-U25 -> 0 | W26: =W25 -> 31836 | X26: =W26-W25 -> 0 | Y26: =Y25 -> 622669 | Z26: =Y26-Y25 -> 0 | AA26: =AA25 -> 34875 | AB26: =AA26-AA25 -> 0 | AC26: =AC25 -> 740037 | AD26: =AC26-AC25 -> 0 | AE26: =AB26+X26+T26 -> 0 | AF26: =V26+Z26+AD26 -> 0 | AG26: =IF(AE26>0,AF26/AE26,0) -> 0 | AI26: =R26-'EDl log'!B24 -> -49369299
A27: ='General information '!F30 -> 0.1 | B27: =SUM(230*A27) -> 23 | C27: 43855 | D27: 31375630 | E27: =D27-D26 -> 2044 | F27: 3484878 | G27: =F27-F26 -> 1844 | H27: 17273618 | I27: =H27-H26 -> 1908 | J27: 28271102 | K27: =J27-J26 -> 1288 | L27: 22623942 | M27: =L27-L26 -> 1887 | N27: =M27+K27+I27+G27+E27 -> 8971 | O27: =IF(B27>0,N27/B27,0) -> 390.04348 | P27: 15294.521 | Q27: =(P27-P26)*1000 -> 1536 | R27: =N27-Q27 -> 7435 | S27: 8368 | T27: =S27-S26 -> 1 | U27: 1021058 | V27: =U27-U26 -> 226 | W27: 31836 | X27: =W27-W26 -> 0 | Y27: =Y26 -> 622669 | Z27: =Y27-Y26 -> 0 | AA27: =AA26 -> 34875 | AB27: =AA27-AA26 -> 0 | AC27: =AC26 -> 740037 | AD27: =AC27-AC26 -> 0 | AE27: =AB27+X27+T27 -> 1 | AF27: =V27+Z27+AD27 -> 226 | AG27: =IF(AE27>0,AF27/AE27,0) -> 226 | AI27: =R27-'EDl log'!B25 -> -49376870
A28: ='General information '!F31 -> 0.0696 | B28: =SUM(230*A28) -> 16.008 | C28: 43856 | D28: 31377914 | E28: =D28-D27 -> 2284 | F28: 3486929.6 | G28: =F28-F27 -> 2051.6 | H28: 17275626 | I28: =H28-H27 -> 2008 | J28: 28272578 | K28: =J28-J27 -> 1476 | L28: 22627792 | M28: =L28-L27 -> 3850 | N28: =M28+K28+I28+G28+E28 -> 11669.6 | O28: =IF(B28>0,N28/B28,0) -> 728.98551 | P28: 15296.017 | Q28: =(P28-P27)*1000 -> 1496 | R28: =N28-Q28 -> 10173.6 | S28: 8369 | T28: =S28-S27 -> 1 | U28: 1021225 | V28: =U28-U27 -> 167 | W28: =W27 -> 31836 | X28: =W28-W27 -> 0 | Y28: =Y27 -> 622669 | Z28: =Y28-Y27 -> 0 | AA28: =AA27 -> 34875 | AB28: =AA28-AA27 -> 0 | AC28: 740119 | AD28: =AC28-AC27 -> 82 | AE28: =AB28+X28+T28 -> 1 | AF28: =V28+Z28+AD28 -> 249 | AG28: =IF(AE28>0,AF28/AE28,0) -> 249 | AI28: =R28-'EDl log'!B26 -> -49378921
A29: ='General information '!F32 -> 0 | B29: =SUM(230*A29) -> 0 | C29: 43857 | D29: =D28 -> 31377914 | E29: =D29-D28 -> 0 | F29: =F28 -> 3486929.6 | G29: =F29-F28 -> 0 | H29: =H28 -> 17275626 | I29: =H29-H28 -> 0 | J29: =J28 -> 28272578 | K29: =J29-J28 -> 0 | L29: =L28 -> 22627792 | M29: =L29-L28 -> 0 | N29: =M29+K29+I29+G29+E29 -> 0 | O29: =IF(B29>0,N29/B29,0) -> 0 | P29: =P28 -> 15296.017 | Q29: =(P29-P28)*1000 -> 0 | R29: =N29-Q29 -> 0 | S29: =S28 -> 8369 | T29: =S29-S28 -> 0 | U29: =U28 -> 1021225 | V29: =U29-U28 -> 0 | W29: =W28 -> 31836 | X29: =W29-W28 -> 0 | Y29: =Y28 -> 622669 | Z29: =Y29-Y28 -> 0 | AA29: =AA28 -> 34875 | AB29: =AA29-AA28 -> 0 | AC29: =AC28 -> 740119 | AD29: =AC29-AC28 -> 0 | AE29: =AB29+X29+T29 -> 0 | AF29: =V29+Z29+AD29 -> 0 | AG29: =IF(AE29>0,AF29/AE29,0) -> 0 | AI29: =R29-'EDl log'!B27 -> -49393543
A30: ='General information '!F33 -> 0 | B30: =SUM(230*A30) -> 0 | C30: 43858 | D30: =D29 -> 31377914 | E30: =D30-D29 -> 0 | F30: =F29 -> 3486929.6 | G30: =F30-F29 -> 0 | H30: =H29 -> 17275626 | I30: =H30-H29 -> 0 | J30: =J29 -> 28272578 | K30: =J30-J29 -> 0 | L30: =L29 -> 22627792 | M30: =L30-L29 -> 0 | N30: =M30+K30+I30+G30+E30 -> 0 | O30: =IF(B30>0,N30/B30,0) -> 0 | P30: =P29 -> 15296.017 | Q30: =(P30-P29)*1000 -> 0 | R30: =N30-Q30 -> 0 | S30: =S29 -> 8369 | T30: =S30-S29 -> 0 | U30: =U29 -> 1021225 | V30: =U30-U29 -> 0 | W30: =W29 -> 31836 | X30: =W30-W29 -> 0 | Y30: =Y29 -> 622669 | Z30: =Y30-Y29 -> 0 | AA30: =AA29 -> 34875 | AB30: =AA30-AA29 -> 0 | AC30: =AC29 -> 740119 | AD30: =AC30-AC29 -> 0 | AE30: =AB30+X30+T30 -> 0 | AF30: =V30+Z30+AD30 -> 0 | AG30: =IF(AE30>0,AF30/AE30,0) -> 0 | AI30: =R30-'EDl log'!B28 -> -49398189
A31: ='General information '!F34 -> 0 | B31: =SUM(230*A31) -> 0 | C31: 43859 | D31: =D30 -> 31377914 | E31: =D31-D30 -> 0 | F31: =F30 -> 3486929.6 | G31: =F31-F30 -> 0 | H31: =H30 -> 17275626 | I31: =H31-H30 -> 0 | J31: =J30 -> 28272578 | K31: =J31-J30 -> 0 | L31: =L30 -> 22627792 | M31: =L31-L30 -> 0 | N31: =M31+K31+I31+G31+E31 -> 0 | O31: =IF(B31>0,N31/B31,0) -> 0 | P31: =P30 -> 15296.017 | Q31: =(P31-P30)*1000 -> 0 | R31: =N31-Q31 -> 0 | S31: =S30 -> 8369 | T31: =S31-S30 -> 0 | U31: =U30 -> 1021225 | V31: =U31-U30 -> 0 | W31: =W30 -> 31836 | X31: =W31-W30 -> 0 | Y31: =Y30 -> 622669 | Z31: =Y31-Y30 -> 0 | AA31: =AA30 -> 34875 | AB31: =AA31-AA30 -> 0 | AC31: =AC30 -> 740119 | AD31: =AC31-AC30 -> 0 | AE31: =AB31+X31+T31 -> 0 | AF31: =V31+Z31+AD31 -> 0 | AG31: =IF(AE31>0,AF31/AE31,0) -> 0 | AI31: =R31-'EDl log'!B29 -> -49403452
A32: ='General information '!F35 -> 0 | B32: =SUM(230*A32) -> 0 | C32: 43860 | D32: =D31 -> 31377914 | E32: =D32-D31 -> 0 | F32: =F31 -> 3486929.6 | G32: =F32-F31 -> 0 | H32: =H31 -> 17275626 | I32: =H32-H31 -> 0 | J32: =J31 -> 28272578 | K32: =J32-J31 -> 0 | L32: =L31 -> 22627792 | M32: =L32-L31 -> 0 | N32: =M32+K32+I32+G32+E32 -> 0 | O32: =IF(B32>0,N32/B32,0) -> 0 | P32: =P31 -> 15296.017 | Q32: =(P32-P31)*1000 -> 0 | R32: =N32-Q32 -> 0 | S32: =S31 -> 8369 | T32: =S32-S31 -> 0 | U32: =U31 -> 1021225 | V32: =U32-U31 -> 0 | W32: =W31 -> 31836 | X32: =W32-W31 -> 0 | Y32: =Y31 -> 622669 | Z32: =Y32-Y31 -> 0 | AA32: =AA31 -> 34875 | AB32: =AA32-AA31 -> 0 | AC32: =AC31 -> 740119 | AD32: =AC32-AC31 -> 0 | AE32: =AB32+X32+T32 -> 0 | AF32: =V32+Z32+AD32 -> 0 | AG32: =IF(AE32>0,AF32/AE32,0) -> 0 | AI32: =R32-'EDl log'!B30 -> -49403452
A33: ='General information '!F36 -> 0 | B33: =SUM(230*A33) -> 0 | C33: 43861 | D33: =D32 -> 31377914 | E33: =D33-D32 -> 0 | F33: =F32 -> 3486929.6 | G33: =F33-F32 -> 0 | H33: =H32 -> 17275626 | I33: =H33-H32 -> 0 | J33: =J32 -> 28272578 | K33: =J33-J32 -> 0 | L33: =L32 -> 22627792 | M33: =L33-L32 -> 0 | N33: =M33+K33+I33+G33+E33 -> 0 | O33: =IF(B33>0,N33/B33,0) -> 0 | P33: =P32 -> 15296.017 | Q33: =(P33-P32)*1000 -> 0 | R33: =N33-Q33 -> 0 | S33: =S32 -> 8369 | T33: =S33-S32 -> 0 | U33: =U32 -> 1021225 | V33: =U33-U32 -> 0 | W33: =W32 -> 31836 | X33: =W33-W32 -> 0 | Y33: =Y32 -> 622669 | Z33: =Y33-Y32 -> 0 | AA33: =AA32 -> 34875 | AB33: =AA33-AA32 -> 0 | AC33: =AC32 -> 740119 | AD33: =AC33-AC32 -> 0 | AE33: =AB33+X33+T33 -> 0 | AF33: =V33+Z33+AD33 -> 0 | AG33: =IF(AE33>0,AF33/AE33,0) -> 0 | AI33: =R33-'EDl log'!B31 -> -49403452

Sheet B5
F1: Boiler A | J1: =J36 -> 77.635417 | K1: Boiler B | P1: Boiler C | V1: Boiler | X1: SteamA | AC1: SteamB | AH1: Steam | AI1: Boiler & steam | AL1: Total Boiler Runing H | AM1: Total Steam Runing H | AN1: GAS1 % | AO1: GAS1/L | AP1: GAS2% | AQ1: Gas2/L | AR1: GAS3% | AS1: GAS3/L | AU1: Gas Cons | AV1: Delivery | AW1: Cost/L
B2: Level Tank Gen | C2: Level tank Boiler | D2: Daily Cons Bo. | E2: Boiler litter | F2: Boiler A | G2: Run Hr a | H2: Boiler A fuel | I2: Daily consumption | J2: AVG | K2: index Run H | L2: Run Hrb | M2: Boiler B Fuel | O2: Daily consumption | P2: Boiler C | S2: Run C | U2: Total RH | V2: Total Fuel | X2: SteamA | Y2: Run SA | Z2: Steam A Conter | AA2: Liters | AC2: SteamB | AD2: Run SteamB | AE2: Steam B Conter | AF2: SB Litters | AG2: Avg | AH2: Total Fuel | AI2: Total Fuel
S3: 0
A4: 31-12-2019 | B4: =[1]B5!B35 -> 238 | C4: =[1]B5!C35 -> 98 | D4: =[1]B5!D35 -> 25 | E4: =[1]B5!E35 -> 209.5 | F4: =[1]B5!F35 -> 1303 | G4: =[1]B5!G35 -> 0 | H4: =[1]B5!H35 -> 330270 | I4: =[1]B5!I35 -> 0 | ... AX4: =[1]B5!AX35 -> 0.7
A5: 43831 | B5: 234 | C5: 78 | D5: =C4-C5 -> 20 | E5: =D5*8.38 -> 167.6 | F5: 1303 | G5: =F5-F4 -> 0 | H5: 330270 | I5: =SUM(H5-H4) -> 0 | J5: 1 | K5: 1693 | L5: =K5-K4 -> 14 | M5: 123329 | N5: =M5-M4 -> 1058 | O5: =SUM(L5*$J$1) -> 1086.8958 | P5: 1452 | Q5: 126239 | R5: =Q5-Q4 -> 0 | S5: =SUM(P5-P4) -> 0 | T5: =SUM(S5*$T$2) -> 0 | U5: =SUM(G5+L5+S5) -> 14 | V5: =R5+N5+I5:I5 -> 1058 | W5: =SUM(V5/U5) -> 75.571429 | X5: 2320 | Y5: =X5-X4 -> 0 | Z5: 130593 | AA5: =Z5-Z4 -> 0 | AB5: =SUM(Y5*$AB$2) -> 0 | AC5: 1712 | AD5: =AC5-AC4 -> 9 | AE5: 353100 | AF5: =AE5-AE4 -> 400 | AG5: =IF(AD5>0,AF5/AD5,0) -> 44.444444 | AH5: =AF5+AA5 -> 400 | AI5: =SUM(AH5+V5) -> 1458 | AJ5: =-tanks!AW6 -> 1458 | AK5: =SUM(AJ5-AI5) -> 0 | AL5: =S5+L5+G5 -> 14 | AM5: =Y5+AD5 -> 9 | AN5: 64 | AO5: =(AN5/100)*3000 -> 1920 | AP5: 65 | AQ5: =(AP5/100)*3000 -> 1950 | AR5: 65 | AS5: =(AR5/100)*3000 -> 1950 | AT5: =SUM(AO5+AQ5+AS5) -> 5820 | AU5: =AT4-AT5+AV5 -> 180 | AX5: =IF(AV5>0,AW5,AX4) -> 0.7
A6: 43832 | B6: 205 | C6: 143 | D6: =C5-C6 -> -65 | E6: =D6*8.38 -> -544.7 | F6: 1303 | G6: =F6-F5 -> 0 | H6: 330270 | I6: =SUM(H6-H5) -> 0 | J6: =IF(G6>0,I6/G6,0) -> 0 | K6: 1702 | L6: =K6-K5 -> 9 | M6: 123970 | N6: =M6-M5 -> 641 | O6: =SUM(L6*$J$1) -> 698.71875 | P6: 1456 | Q6: 126593 | R6: =Q6-Q5 -> 354 | S6: =SUM(P6-P5) -> 4 | T6: =SUM(S6*$T$2) -> 0 | U6: =SUM(G6+L6+S6) -> 13 | V6: =R6+N6+I6:I6 -> 995 | W6: =SUM(V6/U6) -> 76.538462 | X6: 2320 | Y6: =X6-X5 -> 0 | Z6: 130593 | AA6: =Z6-Z5 -> 0 | AB6: =SUM(Y6*$AB$2) -> 0 | AC6: 1714 | AD6: =AC6-AC5 -> 2 | AE6: 353197.3 | AF6: =AE6-AE5 -> 97.3 | AG6: =IF(AD6>0,AF6/AD6,0) -> 48.65 | AH6: =AF6+AA6 -> 97.3 | AI6: =SUM(AH6+V6) -> 1092.3 | AJ6: =-tanks!AW7 -> 1092.3 | AK6: =SUM(AJ6-AI6) -> 0 | AL6: =S6+L6+G6 -> 13 | AM6: =Y6+AD6 -> 2 | AN6: 80 | AO6: =(AN6/100)*3000 -> 2400 | AP6: 80 | AQ6: =(AP6/100)*3000 -> 2400 | AR6: 80 | AS6: =(AR6/100)*3000 -> 2400 | AT6: =SUM(AO6+AQ6+AS6) -> 7200 | AU6: =AT5-AT6+AV6 -> 520 | AV6: 1900 | AW6: 0.7 | AX6: =IF(AV6>0,AW6,AX5) -> 0.7
A7: 43833 | B7: 198 | C7: 127 | D7: =C6-C7 -> 16 | E7: =D7*8.38 -> 134.08 | F7: =F6 -> 1303 | G7: =F7-F6 -> 0 | H7: =H6 -> 330270 | I7: =SUM(H7-H6) -> 0 | J7: =IF(G7>0,I7/G7,0) -> 0 | K7: =K6 -> 1702 | L7: =K7-K6 -> 0 | M7: =M6 -> 123970 | N7: =M7-M6 -> 0 | O7: 1 | P7: 1467 | Q7: 127436 | R7: =Q7-Q6 -> 843 | S7: =SUM(P7-P6) -> 11 | T7: =SUM(S7*$T$2) -> 0 | U7: =SUM(G7+L7+S7) -> 11 | V7: =R7+N7+I7:I7 -> 843 | W7: =SUM(V7/U7) -> 76.636364 | X7: =X6 -> 2320 | Y7: =X7-X6 -> 0 | Z7: =Z6 -> 130593 | AA7: =Z7-Z6 -> 0 | AB7: =SUM(Y7*$AB$2) -> 0 | AC7: 1723 | AD7: =AC7-AC6 -> 9 | AE7: 353680.2 | AF7: =AE7-AE6 -> 482.9 | AG7: =IF(AD7>0,AF7/AD7,0) -> 53.655556 | AH7: =AF7+AA7 -> 482.9 | AI7: =SUM(AH7+V7) -> 1325.9 | AJ7: =-tanks!AW8 -> 1325.9 | AK7: =SUM(AJ7-AI7) -> 0 | AL7: =S7+L7+G7 -> 11 | AM7: =Y7+AD7 -> 9 | AN7: 78 | AO7: =(AN7/100)*3000 -> 2340 | AP7: 78 | AQ7: =(AP7/100)*3000 -> 2340 | AR7: 78 | AS7: =(AR7/100)*3000 -> 2340 | AT7: =SUM(AO7+AQ7+AS7) -> 7020 | AU7: =AT6-AT7+AV7 -> 180 | AX7: =IF(AV7>0,AW7,AX6) -> 0.7
A8: 43834 | B8: 193 | C8: 102 | D8: =C7-C8 -> 25 | E8: =D8*8.38 -> 209.5 | F8: =F7 -> 1303 | G8: =F8-F7 -> 0 | H8: =H7 -> 330270 | I8: =SUM(H8-H7) -> 0 | J8: =IF(G8>0,I8/G8,0) -> 0 | K8: =K7 -> 1702 | L8: =K8-K7 -> 0 | M8: =M7 -> 123970 | N8: =M8-M7 -> 0 | O8: 1479 | P8: 1479 | Q8: 128380 | R8: =Q8-Q7 -> 944 | S8: =SUM(P8-P7) -> 12 | T8: =SUM(S8*$T$2) -> 0 | U8: =SUM(G8+L8+S8) -> 12 | V8: =R8+N8+I8:I8 -> 944 | W8: =SUM(V8/U8) -> 78.666667 | X8: 2320 | Y8: =X8-X7 -> 0 | Z8: 130593 | AA8: =Z8-Z7 -> 0 | AB8: =SUM(Y8*$AB$2) -> 0 | AC8: 1723 | AD8: =AC8-AC7 -> 0 | AE8: =AE7 -> 353680.2 | AF8: =AE8-AE7 -> 0 | AG8: =IF(AD8>0,AF8/AD8,0) -> 0 | AH8: =AF8+AA8 -> 0 | AI8: =SUM(AH8+V8) -> 944 | AJ8: =-tanks!AW9 -> 944 | AK8: =SUM(AJ8-AI8) -> 0 | AL8: =S8+L8+G8 -> 12 | AM8: =Y8+AD8 -> 0 | AN8: 75 | AO8: =(AN8/100)*3000 -> 2250 | AP8: 76 | AQ8: =(AP8/100)*3000 -> 2280 | AR8: 75 | AS8: =(AR8/100)*3000 -> 2250 | AT8: =SUM(AO8+AQ8+AS8) -> 6780 | AU8: =AT7-AT8+AV8 -> 240 | AX8: =IF(AV8>0,AW8,AX7) -> 0.7
A9: 43835 | B9: 190 | C9: 88 | D9: =C8-C9 -> 14 | E9: =D9*8.38 -> 117.32 | F9: 1303 | G9: =F9-F8 -> 0 | H9: 330270 | I9: =SUM(H9-H8) -> 0 | J9: =IF(G9>0,I9/G9,0) -> 0 | K9: 1702 | L9: =K9-K8 -> 0 | M9: 123970 | N9: =M9-M8 -> 0 | O9: =SUM(L9*$J$1) -> 0 | P9: 1489 | Q9: 129086 | R9: =Q9-Q8 -> 706 | S9: =SUM(P9-P8) -> 10 | T9: =SUM(S9*$T$2) -> 0 | U9: =SUM(G9+L9+S9) -> 10 | V9: =R9+N9+I9:I9 -> 706 | W9: =SUM(V9/U9) -> 70.6 | X9: 2320 | Y9: =X9-X8 -> 0 | Z9: 130593 | AA9: =Z9-Z8 -> 0 | AB9: =SUM(Y9*$AB$2) -> 0 | AC9: 1732 | AD9: =AC9-AC8 -> 9 | AE9: 354081.9 | AF9: =AE9-AE8 -> 401.7 | AG9: =IF(AD9>0,AF9/AD9,0) -> 44.633333 | AH9: =AF9+AA9 -> 401.7 | AI9: =SUM(AH9+V9) -> 1107.7 | AJ9: =-tanks!AW10 -> 1107.7 | AK9: =SUM(AJ9-AI9) -> 0 | AL9: =S9+L9+G9 -> 10 | AM9: =Y9+AD9 -> 9 | AN9: 71 | AO9: =(AN9/100)*3000 -> 2130 | AP9: 73 | AQ9: =(AP9/100)*3000 -> 2190 | AR9: 73 | AS9: =(AR9/100)*3000 -> 2190 | AT9: =SUM(AO9+AQ9+AS9) -> 6510 | AU9: =AT8-AT9+AV9 -> 270 | AX9: =IF(AV9>0,AW9,AX8) -> 0.7
A10: 43836 | B10: 182 | C10: 70 | D10: =C9-C10 -> 18 | E10: =D10*8.38 -> 150.84 | F10: 1303 | G10: =F10-F9 -> 0 | H10: 330270 | I10: =SUM(H10-H9) -> 0 | J10: =IF(G10>0,I10/G10,0) -> 0 | K10: 1702 | L10: =K10-K9 -> 0 | M10: 123970 | N10: =M10-M9 -> 0 | O10: =SUM(L10*$J$1) -> 0 | P10: 1497 | Q10: 129693 | R10: =Q10-Q9 -> 607 | S10: =SUM(P10-P9) -> 8 | T10: =SUM(S10*$T$2) -> 0 | U10: =SUM(G10+L10+S10) -> 8 | V10: =R10+N10+I10:I10 -> 607 | W10: =SUM(V10/U10) -> 75.875 | X10: 2320 | Y10: =X10-X9 -> 0 | Z10: 130593 | AA10: =Z10-Z9 -> 0 | AB10: =SUM(Y10*$AB$2) -> 0 | AC10: 1732 | AD10: =AC10-AC9 -> 0 | AE10: 354081.9 | AF10: =AE10-AE9 -> 0 | AG10: =IF(AD10>0,AF10/AD10,0) -> 0 | AH10: =AF10+AA10 -> 0 | AI10: =SUM(AH10+V10) -> 607 | AJ10: =-tanks!AW11 -> 607 | AK10: =SUM(AJ10-AI10) -> 0 | AL10: =S10+L10+G10 -> 8 | AM10: =Y10+AD10 -> 0 | AN10: 69 | AO10: =(AN10/100)*3000 -> 2070 | AP10: 71 | AQ10: =(AP10/100)*3000 -> 2130 | AR10: 71 | AS10: =(AR10/100)*3000 -> 2130 | AT10: =SUM(AO10+AQ10+AS10) -> 6330 | AU10: =AT9-AT10+AV10 -> 180 | AX10: =IF(AV10>0,AW10,AX9) -> 0.7
A11: 43837 | B11: 164 | C11: 101 | D11: =C10-C11 -> -31 | E11: =D11*8.38 -> -259.78 | F11: 1303 | G11: =F11-F10 -> 0 | H11: 330270 | I11: =SUM(H11-H10) -> 0 | J11: =IF(G11>0,I11/G11,0) -> 0 | K11: 1702 | L11: =K11-K10 -> 0 | M11: 123970 | N11: =M11-M10 -> 0 | O11: =SUM(L11*$J$1) -> 0 | P11: 1505 | Q11: 130331 | R11: =Q11-Q10 -> 638 | S11: =SUM(P11-P10) -> 8 | T11: =SUM(S11*$T$2) -> 0 | U11: =SUM(G11+L11+S11) -> 8 | V11: =R11+N11+I11:I11 -> 638 | W11: =SUM(V11/U11) -> 79.75 | X11: 2320 | Y11: =X11-X10 -> 0 | Z11: 130593 | AA11: =Z11-Z10 -> 0 | AB11: =SUM(Y11*$AB$2) -> 0 | AC11: 1740 | AD11: =AC11-AC10 -> 8 | AE11: 354463.2 | AF11: =AE11-AE10 -> 381.3 | AG11: =IF(AD11>0,AF11/AD11,0) -> 47.6625 | AH11: =AF11+AA11 -> 381.3 | AI11: =SUM(AH11+V11) -> 1019.3 | AJ11: =-tanks!AW12 -> 1019.3 | AK11: =SUM(AJ11-AI11) -> 0 | AL11: =S11+L11+G11 -> 8 | AM11: =Y11+AD11 -> 8 | AN11: 67 | AO11: =(AN11/100)*3000 -> 2010 | AP11: 68 | AQ11: =(AP11/100)*3000 -> 2040 | AR11: 69 | AS11: =(AR11/100)*3000 -> 2070 | AT11: =SUM(AO11+AQ11+AS11) -> 6120 | AU11: =AT10-AT11+AV11 -> 210 | AX11: =IF(AV11>0,AW11,AX10) -> 0.7
A12: 43838 | B12: 154 | C12: 80 | D12: =C11-C12 -> 21 | E12: =D12*8.38 -> 175.98 | F12: =F11 -> 1303 | G12: =F12-F11 -> 0 | H12: =H11 -> 330270 | I12: =SUM(H12-H11) -> 0 | J12: =IF(G12>0,I12/G12,0) -> 0 | K12: =K11 -> 1702 | L12: =K12-K11 -> 0 | M12: =M11 -> 123970 | N12: =M12-M11 -> 0 | O12: =SUM(L12*$J$1) -> 0 | P12: 1516 | Q12: 131147 | R12: =Q12-Q11 -> 816 | S12: =SUM(P12-P11) -> 11 | T12: =SUM(S12*$T$2) -> 0 | U12: =SUM(G12+L12+S12) -> 11 | V12: =R12+N12+I12:I12 -> 816 | W12: =SUM(V12/U12) -> 74.181818 | X12: 2320 | Y12: =X12-X11 -> 0 | Z12: =Z11 -> 130593 | AA12: =Z12-Z11 -> 0 | AB12: =SUM(Y12*$AB$2) -> 0 | AC12: =AC11 -> 1740 | AD12: =AC12-AC11 -> 0 | AE12: =AE11 -> 354463.2 | AF12: =AE12-AE11 -> 0 | AG12: =IF(AD12>0,AF12/AD12,0) -> 0 | AH12: =AF12+AA12 -> 0 | AI12: =SUM(AH12+V12) -> 816 | AJ12: =-tanks!AW13 -> 816 | AK12: =SUM(AJ12-AI12) -> 0 | AL12: =S12+L12+G12 -> 11 | AM12: =Y12+AD12 -> 0 | AN12: 64 | AO12: =(AN12/100)*3000 -> 1920 | AP12: 66 | AQ12: =(AP12/100)*3000 -> 1980 | AR12: 66 | AS12: =(AR12/100)*3000 -> 1980 | AT12: =SUM(AO12+AQ12+AS12) -> 5880 | AU12: =AT11-AT12+AV12 -> 240 | AX12: =IF(AV12>0,AW12,AX11) -> 0.7
A13: 43839 | B13: 179 | C13: 162 | D13: =C12-C13 -> -82 | E13: =D13*8.38 -> -687.16 | F13: 1303 | G13: =F13-F12 -> 0 | H13: 330270 | I13: =SUM(H13-H12) -> 0 | J13: =IF(G13>0,I13/G13,0) -> 0 | K13: 1702 | L13: =K13-K12 -> 0 | M13: 123970 | N13: =M13-M12 -> 0 | O13: =SUM(L13*$J$1) -> 0 | P13: 1527 | Q13: 132000 | R13: =Q13-Q12 -> 853 | S13: =SUM(P13-P12) -> 11 | T13: =SUM(S13*$T$2) -> 0 | U13: =SUM(G13+L13+S13) -> 11 | V13: =R13+N13+I13:I13 -> 853 | W13: =SUM(V13/U13) -> 77.545455 | X13: 2320 | Y13: =X13-X12 -> 0 | Z13: 130593 | AA13: =Z13-Z12 -> 0 | AB13: =SUM(Y13*$AB$2) -> 0 | AC13: 1740 | AD13: =AC13-AC12 -> 0 | AE13: 354463.2 | AF13: =AE13-AE12 -> 0 | AG13: =IF(AD13>0,AF13/AD13,0) -> 0 | AH13: =AF13+AA13 -> 0 | AI13: =SUM(AH13+V13) -> 853 | AJ13: =-tanks!AW14 -> 853 | AK13: =SUM(AJ13-AI13) -> 0 | AL13: =S13+L13+G13 -> 11 | AM13: =Y13+AD13 -> 0 | AN13: 79 | AO13: =(AN13/100)*3000 -> 2370 | AP13: 79 | AQ13: =(AP13/100)*3000 -> 2370 | AR13: 81 | AS13: =(AR13/100)*3000 -> 2430 | AT13: =SUM(AO13+AQ13+AS13) -> 7170 | AU13: =AT12-AT13+AV13 -> 360 | AV13: 1650 | AW13: 0.7 | AX13: =IF(AV13>0,AW13,AX12) -> 0.7
A14: 43840 | B14: 168 | C14: 174 | D14: =C13-C14 -> -12 | E14: =D14*8.38 -> -100.56 | F14: 1309 | G14: =F14-F13 -> 6 | H14: 330804 | I14: =SUM(H14-H13) -> 534 | J14: =IF(G14>0,I14/G14,0) -> 89 | K14: =K13 -> 1702 | L14: =K14-K13 -> 0 | M14: =M13 -> 123970 | N14: =M14-M13 -> 0 | O14: =SUM(L14*$J$1) -> 0 | P14: 1534 | Q14: 132477 | R14: =Q14-Q13 -> 477 | S14: =SUM(P14-P13) -> 7 | T14: =SUM(S14*$T$2) -> 0 | U14: =SUM(G14+L14+S14) -> 13 | V14: =R14+N14+I14:I14 -> 1011 | W14: =SUM(V14/U14) -> 77.769231 | X14: 2320 | Y14: =X14-X13 -> 0 | Z14: =Z13 -> 130593 | AA14: =Z14-Z13 -> 0 | AB14: =SUM(Y14*$AB$2) -> 0 | AC14: 1749 | AD14: =AC14-AC13 -> 9 | AE14: 354914 | AF14: =AE14-AE13 -> 450.8 | AG14: =IF(AD14>0,AF14/AD14,0) -> 50.088889 | AH14: =AF14+AA14 -> 450.8 | AI14: =SUM(AH14+V14) -> 1461.8 | AJ14: =-tanks!AW15 -> 1461.8 | AK14: =SUM(AJ14-AI14) -> 0 | AL14: =S14+L14+G14 -> 13 | AM14: =Y14+AD14 -> 9 | AN14: 78 | AO14: =(AN14/100)*3000 -> 2340 | AP14: 77 | AQ14: =(AP14/100)*3000 -> 2310 | AR14: 80 | AS14: =(AR14/100)*3000 -> 2400 | AT14: =SUM(AO14+AQ14+AS14) -> 7050 | AU14: =AT13-AT14+AV14 -> 120 | AX14: =IF(AV14>0,AW14,AX13) -> 0.7
A15: 43841 | B15: 162 | C15: 168 | D15: =C14-C15 -> 6 | E15: =D15*8.38 -> 50.28 | F15: 1314 | G15: =F15-F14 -> 5 | H15: 331161 | I15: =SUM(H15-H14) -> 357 | J15: =IF(G15>0,I15/G15,0) -> 71.4 | K15: 1707 | L15: =K15-K14 -> 5 | M15: 124341 | N15: =M15-M14 -> 371 | O15: =SUM(L15*$J$1) -> 388.17708 | P15: =P14 -> 1534 | Q15: =Q14 -> 132477 | R15: =Q15-Q14 -> 0 | S15: =SUM(P15-P14) -> 0 | T15: =SUM(S15*$T$2) -> 0 | U15: =SUM(G15+L15+S15) -> 10 | V15: =R15+N15+I15:I15 -> 728 | W15: =SUM(V15/U15) -> 72.8 | X15: =X14 -> 2320 | Y15: =X15-X14 -> 0 | Z15: =Z14 -> 130593 | AA15: =Z15-Z14 -> 0 | AB15: =SUM(Y15*$AB$2) -> 0 | AC15: =AC14 -> 1749 | AD15: =AC15-AC14 -> 0 | AE15: =AE14 -> 354914 | AF15: =AE15-AE14 -> 0 | AG15: =IF(AD15>0,AF15/AD15,0) -> 0 | AH15: =AF15+AA15 -> 0 | AI15: =SUM(AH15+V15) -> 728 | AJ15: =-tanks!AW16 -> 728 | AK15: =SUM(AJ15-AI15) -> 0 | AL15: =S15+L15+G15 -> 10 | AM15: =Y15+AD15 -> 0 | AN15: 77 | AO15: =(AN15/100)*3000 -> 2310 | AP15: =AP14 -> 77 | AQ15: =(AP15/100)*3000 -> 2310 | AR15: 78 | AS15: =(AR15/100)*3000 -> 2340 | AT15: =SUM(AO15+AQ15+AS15) -> 6960 | AU15: =AT14-AT15+AV15 -> 90 | AX15: =IF(AV15>0,AW15,AX14) -> 0.7
A16: 43842 | B16: 158 | C16: 163 | D16: =C15-C16 -> 5 | E16: =D16*8.38 -> 41.9 | F16: =F15 -> 1314 | G16: =F16-F15 -> 0 | H16: 331161 | I16: =SUM(H16-H15) -> 0 | J16: =IF(G16>0,I16/G16,0) -> 0 | K16: 1711 | L16: =K16-K15 -> 4 | M16: 124632 | N16: =M16-M15 -> 291 | O16: =SUM(L16*$J$1) -> 310.54167 | P16: 1537 | Q16: 132729 | R16: =Q16-Q15 -> 252 | S16: =SUM(P16-P15) -> 3 | T16: =SUM(S16*$T$2) -> 0 | U16: =SUM(G16+L16+S16) -> 7 | V16: =R16+N16+I16:I16 -> 543 | W16: =SUM(V16/U16) -> 77.571429 | X16: 2320 | Y16: =X16-X15 -> 0 | Z16: 130593 | AA16: =Z16-Z15 -> 0 | AB16: =SUM(Y16*$AB$2) -> 0 | AC16: 1749 | AD16: =AC16-AC15 -> 0 | AE16: 354914 | AF16: =AE16-AE15 -> 0 | AG16: =IF(AD16>0,AF16/AD16,0) -> 0 | AH16: =AF16+AA16 -> 0 | AI16: =SUM(AH16+V16) -> 543 | AJ16: =-tanks!AW17 -> 543 | AK16: =SUM(AJ16-AI16) -> 0 | AL16: =S16+L16+G16 -> 7 | AM16: =Y16+AD16 -> 0 | AN16: 74 | AO16: =(AN16/100)*3000 -> 2220 | AP16: 74 | AQ16: =(AP16/100)*3000 -> 2220 | AR16: 76 | AS16: =(AR16/100)*3000 -> 2280 | AT16: =SUM(AO16+AQ16+AS16) -> 6720 | AU16: =AT15-AT16+AV16 -> 240 | AX16: =IF(AV16>0,AW16,AX15) -> 0.7
A17: 43843 | B17: 152 | C17: 159 | D17: =C16-C17 -> 4 | E17: =D17*8.38 -> 33.52 | F17: 1319 | G17: =F17-F16 -> 5 | H17: 331585 | I17: =SUM(H17-H16) -> 424 | J17: =IF(G17>0,I17/G17,0) -> 84.8 | K17: 1711 | L17: =K17-K16 -> 0 | M17: 124632 | N17: =M17-M16 -> 0 | O17: =SUM(L17*$J$1) -> 0 | P17: 1541 | Q17: 133054 | R17: =Q17-Q16 -> 325 | S17: =SUM(P17-P16) -> 4 | T17: =SUM(S17*$T$2) -> 0 | U17: =SUM(G17+L17+S17) -> 9 | V17: =R17+N17+I17:I17 -> 749 | X17: 2320 | Y17: =X17-X16 -> 0 | Z17: 130593 | AA17: =Z17-Z16 -> 0 | AB17: =SUM(Y17*$AB$2) -> 0 | AC17: 1749 | AD17: =AC17-AC16 -> 0 | AE17: 354914 | AF17: =AE17-AE16 -> 0 | AG17: =IF(AD17>0,AF17/AD17,0) -> 0 | AH17: =AF17+AA17 -> 0 | AI17: =SUM(AH17+V17) -> 749 | AJ17: =-tanks!AW18 -> 749 | AK17: =SUM(AJ17-AI17) -> 0 | AL17: =S17+L17+G17 -> 9 | AM17: =Y17+AD17 -> 0 | AN17: 71 | AO17: =(AN17/100)*3000 -> 2130 | AP17: 71 | AQ17: =(AP17/100)*3000 -> 2130 | AR17: 74 | AS17: =(AR17/100)*3000 -> 2220 | AT17: =SUM(AO17+AQ17+AS17) -> 6480 | AU17: =AT16-AT17+AV17 -> 240 | AX17: =IF(AV17>0,AW17,AX16) -> 0.7
A18: 43844 | B18: 208 | C18: 214 | D18: =C17-C18 -> -55 | E18: =D18*8.38 -> -460.9 | F18: 1323 | G18: =F18-F17 -> 4 | H18: 331908 | I18: =SUM(H18-H17) -> 323 | J18: =IF(G18>0,I18/G18,0) -> 80.75 | K18: 1712 | L18: =K18-K17 -> 1 | M18: 124752 | N18: =M18-M17 -> 120 | O18: =SUM(L18*$J$1) -> 77.635417 | P18: 1542 | Q18: 133071 | R18: =Q18-Q17 -> 17 | S18: =SUM(P18-P17) -> 1 | T18: =SUM(S18*$T$2) -> 0 | U18: =SUM(G18+L18+S18) -> 6 | V18: =R18+N18+I18:I18 -> 460 | X18: 2320 | Y18: =X18-X17 -> 0 | Z18: 130593 | AA18: =Z18-Z17 -> 0 | AB18: =SUM(Y18*$AB$2) -> 0 | AC18: 1759 | AD18: =AC18-AC17 -> 10 | AE18: 355340.6 | AF18: =AE18-AE17 -> 426.6 | AG18: =IF(AD18>0,AF18/AD18,0) -> 42.66 | AH18: =AF18+AA18 -> 426.6 | AI18: =SUM(AH18+V18) -> 886.6 | AJ18: =-tanks!AW19 -> 886.6 | AK18: =SUM(AJ18-AI18) -> 0 | AL18: =S18+L18+G18 -> 6 | AM18: =Y18+AD18 -> 10 | AN18: 69 | AO18: =(AN18/100)*3000 -> 2070 | AP18: 69 | AQ18: =(AP18/100)*3000 -> 2070 | AR18: 71 | AS18: =(AR18/100)*3000 -> 2130 | AT18: =SUM(AO18+AQ18+AS18) -> 6270 | AU18: =AT17-AT18+AV18 -> 210 | AX18: =IF(AV18>0,AW18,AX17) -> 0.7
A19: 43845 | B19: 201 | C19: 207 | D19: =C18-C19 -> 7 | E19: =D19*8.38 -> 58.66 | F19: 1324 | G19: =F19-F18 -> 1 | H19: 331958 | I19: =SUM(H19-H18) -> 50 | J19: =IF(G19>0,I19/G19,0) -> 50 | K19: 1715 | L19: =K19-K18 -> 3 | M19: 124996 | N19: =M19-M18 -> 244 | O19: =SUM(L19*$J$1) -> 232.90625 | P19: 1545 | Q19: 133365 | R19: =Q19-Q18 -> 294 | S19: =SUM(P19-P18) -> 3 | T19: =SUM(S19*$T$2) -> 0 | U19: =SUM(G19+L19+S19) -> 7 | V19: =R19+N19+I19:I19 -> 588 | X19: 2320 | Y19: =X19-X18 -> 0 | Z19: 130593 | AA19: =Z19-Z18 -> 0 | AB19: =SUM(Y19*$AB$2) -> 0 | AC19: 1762 | AD19: =AC19-AC18 -> 3 | AE19: 355515.2 | AF19: =AE19-AE18 -> 174.6 | AG19: =IF(AD19>0,AF19/AD19,0) -> 58.2 | AH19: =AF19+AA19 -> 174.6 | AI19: =SUM(AH19+V19) -> 762.6 | AJ19: =-tanks!AW20 -> 762.6 | AK19: =SUM(AJ19-AI19) -> 0 | AL19: =S19+L20+G19 -> 4 | AM19: =Y19+AD19 -> 3 | AN19: 67 | AO19: =(AN19/100)*3000 -> 2010 | AP19: 67 | AQ19: =(AP19/100)*3000 -> 2010 | AR19: 69 | AS19: =(AR19/100)*3000 -> 2070 | AT19: =SUM(AO19+AQ19+AS19) -> 6090 | AU19: =AT18-AT19+AV19 -> 180 | AX19: =IF(AV19>0,AW19,AX18) -> 0.7
A20: 43846 | B20: 223 | C20: 229 | D20: =C19-C20 -> -22 | E20: =D20*8.38 -> -184.36 | F20: 1327 | G20: =F20-F19 -> 3 | H20: 332212 | I20: =SUM(H20-H19) -> 254 | J20: =IF(G20>0,I20/G20,0) -> 84.666667 | K20: 1715 | L20: =K20-K19 -> 0 | M20: =M19 -> 124996 | N20: =M20-M19 -> 0 | O20: =SUM(L20*$J$1) -> 0 | P20: 1548 | Q20: 133595 | R20: =Q20-Q19 -> 230 | S20: =SUM(P20-P19) -> 3 | T20: =SUM(S20*$T$2) -> 0 | U20: =SUM(G20+L20+S20) -> 6 | V20: =R20+N20+I20:I20 -> 484 | X20: =X19 -> 2320 | Y20: =X20-X19 -> 0 | Z20: =Z19 -> 130593 | AA20: =Z20-Z19 -> 0 | AB20: =SUM(Y20*$AB$2) -> 0 | AC20: =AC19 -> 1762 | AD20: =AC20-AC19 -> 0 | AE20: =AE19 -> 355515.2 | AF20: =AE20-AE19 -> 0 | AG20: =IF(AD20>0,AF20/AD20,0) -> 0 | AH20: =AF20+AA20 -> 0 | AI20: =SUM(AH20+V20) -> 484 | AJ20: =-tanks!AW21 -> 484 | AK20: =SUM(AJ20-AI20) -> 0 | AL20: =S20+L21+G20 -> 10 | AM20: =Y20+AD20 -> 0 | AN20: 79 | AO20: =(AN20/100)*3000 -> 2370 | AP20: 79 | AQ20: =(AP20/100)*3000 -> 2370 | AR20: 82 | AS20: =(AR20/100)*3000 -> 2460 | AT20: =SUM(AO20+AQ20+AS20) -> 7200 | AU20: =AT19-AT20+AV20 -> 290 | AV20: 1400 | AW20: 0.7 | AX20: =IF(AV20>0,AW20,AX19) -> 0.7
A21: 43847 | B21: 219 | C21: 225 | D21: =C20-C21 -> 4 | E21: =D21*8.38 -> 33.52 | F21: 1330 | G21: =F21-F20 -> 3 | H21: 332480 | I21: =SUM(H21-H20) -> 268 | J21: =IF(G21>0,I21/G21,0) -> 89.333333 | K21: 1719 | L21: =K21-K20 -> 4 | M21: 125236 | N21: =M21-M20 -> 240 | O21: =SUM(L21*$J$1) -> 310.54167 | P21: 1549 | Q21: 133617 | R21: =Q21-Q20 -> 22 | S21: =SUM(P21-P20) -> 1 | T21: =SUM(S21*$T$2) -> 0 | U21: =SUM(G21+L21+S21) -> 8 | V21: =R21+N21+I21:I21 -> 530 | X21: =X20 -> 2320 | Y21: =X21-X20 -> 0 | Z21: =Z20 -> 130593 | AA21: =Z21-Z20 -> 0 | AB21: =SUM(Y21*$AB$2) -> 0 | AC21: 1771 | AD21: =AC21-AC20 -> 9 | AE21: 356012.3 | AF21: =AE21-AE20 -> 497.1 | AG21: =IF(AD21>0,AF21/AD21,0) -> 55.233333 | AH21: =AF21+AA21 -> 497.1 | AI21: =SUM(AH21+V21) -> 1027.1 | AJ21: =-tanks!AW22 -> 1027.1 | AK21: =SUM(AJ21-AI21) -> 0 | AL21: =S21+L21+G21 -> 8 | AM21: =Y21+AD21 -> 9 | AN21: 78 | AO21: =(AN21/100)*3000 -> 2340 | AP21: 78 | AQ21: =(AP21/100)*3000 -> 2340 | AR21: 81 | AS21: =(AR21/100)*3000 -> 2430 | AT21: =SUM(AO21+AQ21+AS21) -> 7110 | AU21: =AT20-AT21+AV21 -> 90 | AX21: =IF(AV21>0,AW21,AX20) -> 0.7
A22: 43848 | B22: 211 | C22: 218 | D22: =C21-C22 -> 7 | E22: =D22*8.38 -> 58.66 | F22: =F21 -> 1330 | G22: =F22-F21 -> 0 | H22: =H21 -> 332480 | I22: =SUM(H22-H21) -> 0 | J22: =IF(G22>0,I22/G22,0) -> 0 | K22: 1722 | L22: =K22-K21 -> 3 | M22: 125525 | N22: =M22-M21 -> 289 | O22: =SUM(L22*$J$1) -> 232.90625 | P22: 1552 | Q22: 133894 | R22: =Q22-Q21 -> 277 | S22: =SUM(P22-P21) -> 3 | T22: =SUM(S22*$T$2) -> 0 | U22: =SUM(G22+L22+S22) -> 6 | V22: =R22+N22+I22:I22 -> 566 | X22: 2320 | Y22: =X22-X21 -> 0 | Z22: =Z21 -> 130593 | AA22: =Z22-Z21 -> 0 | AB22: =SUM(Y22*$AB$2) -> 0 | AC22: =AC21 -> 1771 | AD22: =AC22-AC21 -> 0 | AE22: =AE21 -> 356012.3 | AF22: =AE22-AE21 -> 0 | AG22: =IF(AD22>0,AF22/AD22,0) -> 0 | AH22: =AF22+AA22 -> 0 | AI22: =SUM(AH22+V22) -> 566 | AJ22: =-tanks!AW23 -> 566 | AK22: =SUM(AJ22-AI22) -> 0 | AL22: =S22+L22+G22 -> 6 | AM22: =Y22+AD22 -> 0 | AN22: 76 | AO22: =(AN22/100)*3000 -> 2280 | AP22: 77 | AQ22: =(AP22/100)*3000 -> 2310 | AR22: 79 | AS22: =(AR22/100)*3000 -> 2370 | AT22: =SUM(AO22+AQ22+AS22) -> 6960 | AU22: =AT21-AT22+AV22 -> 150 | AX22: =IF(AV22>0,AW22,AX21) -> 0.7
A23: 43849 | B23: 208 | C23: 214 | D23: =C22-C23 -> 4 | E23: =D23*8.38 -> 33.52 | F23: 1332 | G23: =F23-F22 -> 2 | H23: 332630 | I23: =SUM(H23-H22) -> 150 | J23: =IF(G23>0,I23/G23,0) -> 75 | K23: 1722 | L23: =K23-K22 -> 0 | M23: 125525 | N23: =M23-M22 -> 0 | O23: =SUM(L23*$J$1) -> 0 | P23: 1557 | Q23: 134212 | R23: =Q23-Q22 -> 318 | S23: =SUM(P23-P22) -> 5 | T23: =SUM(S23*$T$2) -> 0 | U23: =SUM(G23+L23+S23) -> 7 | V23: =R23+N23+I23:I23 -> 468 | X23: 2320 | Y23: =X23-X22 -> 0 | Z23: 130593 | AA23: =Z23-Z22 -> 0 | AB23: =SUM(Y23*$AB$2) -> 0 | AC23: 1771 | AD23: =AC23-AC22 -> 0 | AE23: 356012.3 | AF23: =AE23-AE22 -> 0 | AG23: =IF(AD23>0,AF23/AD23,0) -> 0 | AH23: =AF23+AA23 -> 0 | AI23: =SUM(AH23+V23) -> 468 | AJ23: =-tanks!AW24 -> 468 | AK23: =SUM(AJ23-AI23) -> 0 | AL23: =S23+L23+G23 -> 7 | AM23: =Y23+AD23 -> 0 | AN23: 74 | AO23: =(AN23/100)*3000 -> 2220 | AP23: 75 | AQ23: =(AP23/100)*3000 -> 2250 | AR23: 78 | AS23: =(AR23/100)*3000 -> 2340 | AT23: =SUM(AO23+AQ23+AS23) -> 6810 | AU23: =AT22-AT23+AV23 -> 150 | AX23: =IF(AV23>0,AW23,AX22) -> 0.7
A24: 43850 | B24: 204 | C24: 210 | D24: =C23-C24 -> 4 | E24: =D24*8.38 -> 33.52 | F24: 1335 | G24: =F24-F23 -> 3 | H24: 332863 | I24: =SUM(H24-H23) -> 233 | J24: =IF(G24>0,I24/G24,0) -> 77.666667 | K24: 1727 | L24: =K24-K23 -> 5 | M24: 125847 | N24: =M24-M23 -> 322 | O24: =SUM(L24*$J$1) -> 388.17708 | P24: =P23 -> 1557 | Q24: =Q23 -> 134212 | R24: =Q24-Q23 -> 0 | S24: =SUM(P24-P23) -> 0 | T24: =SUM(S24*$T$2) -> 0 | U24: =SUM(G24+L24+S24) -> 8 | V24: =R24+N24+I24:I24 -> 555 | X24: =X23 -> 2320 | Y24: =X24-X23 -> 0 | Z24: =Z23 -> 130593 | AA24: =Z24-Z23 -> 0 | AB24: =SUM(Y24*$AB$2) -> 0 | AC24: =AC23 -> 1771 | AD24: =AC24-AC23 -> 0 | AE24: =AE23 -> 356012.3 | AF24: =AE24-AE23 -> 0 | AG24: =IF(AD24>0,AF24/AD24,0) -> 0 | AH24: =AF24+AA24 -> 0 | AI24: =SUM(AH24+V24) -> 555 | AJ24: =-tanks!AW25 -> 555 | AK24: =SUM(AJ24-AI24) -> 0 | AL24: =S24+L24+G24 -> 8 | AM24: =Y24+AD24 -> 0 | AN24: 71 | AO24: =(AN24/100)*3000 -> 2130 | AP24: 72 | AQ24: =(AP24/100)*3000 -> 2160 | AR24: 76 | AS24: =(AR24/100)*3000 -> 2280 | AT24: =SUM(AO24+AQ24+AS24) -> 6570 | AU24: =AT23-AT24+AV24 -> 240 | AX24: =IF(AV24>0,AW24,AX23) -> 0.7
A25: 43851 | B25: 198 | C25: 204 | D25: =C24-C25 -> 6 | E25: =D25*8.38 -> 50.28 | F25: 1336 | G25: =F25-F24 -> 1 | H25: 332987 | I25: =SUM(H25-H24) -> 124 | J25: =IF(G25>0,I25/G25,0) -> 124 | K25: 1732 | L25: =K25-K24 -> 5 | M25: 126286 | N25: =M25-M24 -> 439 | O25: =SUM(L25*$J$1) -> 388.17708 | P25: 1561 | Q25: 134546 | R25: =Q25-Q24 -> 334 | S25: =SUM(P25-P24) -> 4 | T25: =SUM(S25*$T$2) -> 0 | U25: =SUM(G25+L25+S25) -> 10 | V25: =R25+N25+I25:I25 -> 897 | X25: =X24 -> 2320 | Y25: =X25-X24 -> 0 | Z25: =Z24 -> 130593 | AA25: =Z25-Z24 -> 0 | AB25: =SUM(Y25*$AB$2) -> 0 | AC25: 1778 | AD25: =AC25-AC24 -> 7 | AE25: 356430 | AF25: =AE25-AE24 -> 417.7 | AG25: =IF(AD25>0,AF25/AD25,0) -> 59.671429 | AH25: =AF25+AA25 -> 417.7 | AI25: =SUM(AH25+V25) -> 1314.7 | AJ25: =-tanks!AW26 -> 1314.7 | AK25: =SUM(AJ25-AI25) -> 0 | AL25: =S25+L25+G25 -> 10 | AM25: =Y25+AD25 -> 7 | AN25: 70 | AO25: =(AN25/100)*3000 -> 2100 | AP25: 71 | AQ25: =(AP25/100)*3000 -> 2130 | AR25: 75 | AS25: =(AR25/100)*3000 -> 2250 | AT25: =SUM(AO25+AQ25+AS25) -> 6480 | AU25: =AT24-AT25+AV25 -> 90 | AX25: =IF(AV25>0,AW25,AX24) -> 0.7
A26: 43852 | B26: 249 | C26: 255 | D26: =C25-C26 -> -51 | E26: =D26*8.38 -> -427.38 | F26: 1340 | G26: =F26-F25 -> 4 | H26: 333257 | I26: =SUM(H26-H25) -> 270 | J26: =IF(G26>0,I26/G26,0) -> 67.5 | K26: 1732 | L26: =K26-K25 -> 0 | M26: 126286 | N26: =M26-M25 -> 0 | O26: =SUM(L26*$J$1) -> 0 | P26: 1565 | Q26: 134855 | R26: =Q26-Q25 -> 309 | S26: =SUM(P26-P25) -> 4 | T26: =SUM(S26*$T$2) -> 0 | U26: =SUM(G26+L26+S26) -> 8 | V26: =R26+N26+I26:I26 -> 579 | X26: 2320 | Y26: =X26-X25 -> 0 | Z26: 130593 | AA26: =Z26-Z25 -> 0 | AB26: =SUM(Y26*$AB$2) -> 0 | AC26: 1778 | AD26: =AC26-AC25 -> 0 | AE26: 356430 | AF26: =AE26-AE25 -> 0 | AG26: =IF(AD26>0,AF26/AD26,0) -> 0 | AH26: =AF26+AA26 -> 0 | AI26: =SUM(AH26+V26) -> 579 | AJ26: =-tanks!AW27 -> 579 | AK26: =SUM(AJ26-AI26) -> 0 | AL26: =S26+L26+G26 -> 8 | AM26: =Y26+AD26 -> 0 | AN26: 69 | AO26: =(AN26/100)*3000 -> 2070 | AP26: 70 | AQ26: =(AP26/100)*3000 -> 2100 | AR26: 72 | AS26: =(AR26/100)*3000 -> 2160 | AT26: =SUM(AO26+AQ26+AS26) -> 6330 | AU26: =AT25-AT26+AV26 -> 150 | AX26: =IF(AV26>0,AW26,AX25) -> 0.7
