Workbook

Sheet TOTAL
A1: Site Name | B1: Day | C1: Month | D1: Year | E1: Total Electricity Kwh | F1: Electricity Tariff ($/Kwh) | G1: Natual Gas (m3) | H1: Natural Gas $/m3 | I1: Water Utility Supply (m3) m3 | J1: Water Utility Supply (m3) $/m3 | K1: Room Nights
A2: Cairo at Nile Plaza | B2: 1 | C2: 5 | D2: 2019 | E2: =(((Submetering!O2+Submetering!P2)*0.842284+Submetering!Q2+(Submetering!M2+Submetering!N2+Submetering!Y2)*0.7362)+(Submetering!O2+Submetering!P2+Submetering!Q2)*0.1488+(Submetering!M2+Submetering!N2+Submetering!Y2)*0.1167+(Submetering!K2+Submetering!L2-Submetering!Z2-Submetering!AA2-Submetering!AB2-Submetering!AC2-Submetering!Q2)+(Submetering!M2+Submetering!N2+Submetering!Y2)*0.1139) -> 70385.209 | F2: 1.15 | G2: =Gas!C4*0.9147 -> 3227.9763 | H2: 2.25 | I2: =Submetering!AE2+Submetering!AD2+Submetering!H2 -> 296 | J2: 9.12 | K2: =ELECT.!B4 -> 237
A3: Cairo at Nile Plaza | B3: =B2+1 -> 2 | C3: 5 | D3: 2019 | E3: =(((Submetering!O3+Submetering!P3)*0.842284+Submetering!Q3+(Submetering!M3+Submetering!N3+Submetering!Y3)*0.7362)+(Submetering!O3+Submetering!P3+Submetering!Q3)*0.1488+(Submetering!M3+Submetering!N3+Submetering!Y3)*0.1167+(Submetering!K3+Submetering!L3-Submetering!Z3-Submetering!AA3-Submetering!AB3-Submetering!AC3-Submetering!Q3)+(Submetering!M3+Submetering!N3+Submetering!Y3)*0.1139) -> 38407.567 | F3: 1.15 | G3: =Gas!C5*0.9147 -> 2993.8131 | H3: 2.25 | I3: =Submetering!AE3+Submetering!AD3+Submetering!H3 -> 866 | J3: 9.12 | K3: =ELECT.!B5 -> 241
A4: Cairo at Nile Plaza | B4: =B3+1 -> 3 | C4: 5 | D4: 2019 | E4: =(((Submetering!O4+Submetering!P4)*0.842284+Submetering!Q4+(Submetering!M4+Submetering!N4+Submetering!Y4)*0.7362)+(Submetering!O4+Submetering!P4+Submetering!Q4)*0.1488+(Submetering!M4+Submetering!N4+Submetering!Y4)*0.1167+(Submetering!K4+Submetering!L4-Submetering!Z4-Submetering!AA4-Submetering!AB4-Submetering!AC4-Submetering!Q4)+(Submetering!M4+Submetering!N4+Submetering!Y4)*0.1139) -> 92437.526 | F4: 1.15 | G4: =Gas!C6*0.9147 -> 3056.0127 | H4: 2.25 | I4: =Submetering!AE4+Submetering!AD4+Submetering!H4 -> 1046 | J4: 9.12 | K4: =ELECT.!B6 -> 244
A5: Cairo at Nile Plaza | B5: =B4+1 -> 4 | C5: 5 | D5: 2019 | E5: =(((Submetering!O5+Submetering!P5)*0.842284+Submetering!Q5+(Submetering!M5+Submetering!N5+Submetering!Y5)*0.7362)+(Submetering!O5+Submetering!P5+Submetering!Q5)*0.1488+(Submetering!M5+Submetering!N5+Submetering!Y5)*0.1167+(Submetering!K5+Submetering!L5-Submetering!Z5-Submetering!AA5-Submetering!AB5-Submetering!AC5-Submetering!Q5)+(Submetering!M5+Submetering!N5+Submetering!Y5)*0.1139) -> 61742.206 | F5: 1.15 | G5: =Gas!C7*0.9147 -> 3157.5444 | H5: 2.25 | I5: =Submetering!AE5+Submetering!AD5+Submetering!H5 -> 776 | J5: 9.12 | K5: =ELECT.!B7 -> 204
A6: Cairo at Nile Plaza | B6: =B5+1 -> 5 | C6: 5 | D6: 2019 | E6: =(((Submetering!O6+Submetering!P6)*0.842284+Submetering!Q6+(Submetering!M6+Submetering!N6+Submetering!Y6)*0.7362)+(Submetering!O6+Submetering!P6+Submetering!Q6)*0.1488+(Submetering!M6+Submetering!N6+Submetering!Y6)*0.1167+(Submetering!K6+Submetering!L6-Submetering!Z6-Submetering!AA6-Submetering!AB6-Submetering!AC6-Submetering!Q6)+(Submetering!M6+Submetering!N6+Submetering!Y6)*0.1139) -> 69480.755 | F6: 1.15 | G6: =Gas!C8*0.9147 -> 3113.6388 | H6: 2.25 | I6: =Submetering!AE6+Submetering!AD6+Submetering!H6 -> 796 | J6: 9.12 | K6: =ELECT.!B8 -> 131
A7: Cairo at Nile Plaza | B7: =B6+1 -> 6 | C7: 5 | D7: 2019 | E7: =(((Submetering!O7+Submetering!P7)*0.842284+Submetering!Q7+(Submetering!M7+Submetering!N7+Submetering!Y7)*0.7362)+(Submetering!O7+Submetering!P7+Submetering!Q7)*0.1488+(Submetering!M7+Submetering!N7+Submetering!Y7)*0.1167+(Submetering!K7+Submetering!L7-Submetering!Z7-Submetering!AA7-Submetering!AB7-Submetering!AC7-Submetering!Q7)+(Submetering!M7+Submetering!N7+Submetering!Y7)*0.1139) -> 48160.786 | F7: 1.15 | G7: =Gas!C9*0.9147 -> 3044.1216 | H7: 2.25 | I7: =Submetering!AE7+Submetering!AD7+Submetering!H7 -> 816 | J7: 9.12 | K7: =ELECT.!B9 -> 115
A8: Cairo at Nile Plaza | B8: =B7+1 -> 7 | C8: 5 | D8: 2019 | E8: =(((Submetering!O8+Submetering!P8)*0.842284+Submetering!Q8+(Submetering!M8+Submetering!N8+Submetering!Y8)*0.7362)+(Submetering!O8+Submetering!P8+Submetering!Q8)*0.1488+(Submetering!M8+Submetering!N8+Submetering!Y8)*0.1167+(Submetering!K8+Submetering!L8-Submetering!Z8-Submetering!AA8-Submetering!AB8-Submetering!AC8-Submetering!Q8)+(Submetering!M8+Submetering!N8+Submetering!Y8)*0.1139) -> 86436.788 | F8: 1.15 | G8: =Gas!C10*0.9147 -> 2849.2905 | H8: 2.25 | I8: =Submetering!AE8+Submetering!AD8+Submetering!H8 -> 686 | J8: 9.12 | K8: =ELECT.!B10 -> 107
A9: Cairo at Nile Plaza | B9: =B8+1 -> 8 | C9: 5 | D9: 2019 | E9: =(((Submetering!O9+Submetering!P9)*0.842284+Submetering!Q9+(Submetering!M9+Submetering!N9+Submetering!Y9)*0.7362)+(Submetering!O9+Submetering!P9+Submetering!Q9)*0.1488+(Submetering!M9+Submetering!N9+Submetering!Y9)*0.1167+(Submetering!K9+Submetering!L9-Submetering!Z9-Submetering!AA9-Submetering!AB9-Submetering!AC9-Submetering!Q9)+(Submetering!M9+Submetering!N9+Submetering!Y9)*0.1139) -> 62834.343 | F9: 1.15 | G9: =Gas!C11*0.9147 -> 2941.6752 | H9: 2.25 | I9: =Submetering!AE9+Submetering!AD9+Submetering!H9 -> 636 | J9: 9.12 | K9: =ELECT.!B11 -> 85
A10: Cairo at Nile Plaza | B10: =B9+1 -> 9 | C10: 5 | D10: 2019 | E10: =(((Submetering!O10+Submetering!P10)*0.842284+Submetering!Q10+(Submetering!M10+Submetering!N10+Submetering!Y10)*0.7362)+(Submetering!O10+Submetering!P10+Submetering!Q10)*0.1488+(Submetering!M10+Submetering!N10+Submetering!Y10)*0.1167+(Submetering!K10+Submetering!L10-Submetering!Z10-Submetering!AA10-Submetering!AB10-Submetering!AC10-Submetering!Q10)+(Submetering!M10+Submetering!N10+Submetering!Y10)*0.1139) -> 40329.376 | F10: 1.15 | G10: =Gas!C12*0.9147 -> 2981.922 | H10: 2.25 | I10: =Submetering!AE10+Submetering!AD10+Submetering!H10 -> 686 | J10: 9.12 | K10: =ELECT.!B12 -> 76
A11: Cairo at Nile Plaza | B11: =B10+1 -> 10 | C11: 5 | D11: 2019 | E11: =(((Submetering!O11+Submetering!P11)*0.842284+Submetering!Q11+(Submetering!M11+Submetering!N11+Submetering!Y11)*0.7362)+(Submetering!O11+Submetering!P11+Submetering!Q11)*0.1488+(Submetering!M11+Submetering!N11+Submetering!Y11)*0.1167+(Submetering!K11+Submetering!L11-Submetering!Z11-Submetering!AA11-Submetering!AB11-Submetering!AC11-Submetering!Q11)+(Submetering!M11+Submetering!N11+Submetering!Y11)*0.1139) -> 76884.221 | F11: 1.15 | G11: =Gas!C13*0.9147 -> 2519.9985 | H11: 2.25 | I11: =Submetering!AE11+Submetering!AD11+Submetering!H11 -> 786 | J11: 9.12 | K11: =ELECT.!B13 -> 133
A12: Cairo at Nile Plaza | B12: =B11+1 -> 11 | C12: 5 | D12: 2019 | E12: =(((Submetering!O12+Submetering!P12)*0.842284+Submetering!Q12+(Submetering!M12+Submetering!N12+Submetering!Y12)*0.7362)+(Submetering!O12+Submetering!P12+Submetering!Q12)*0.1488+(Submetering!M12+Submetering!N12+Submetering!Y12)*0.1167+(Submetering!K12+Submetering!L12-Submetering!Z12-Submetering!AA12-Submetering!AB12-Submetering!AC12-Submetering!Q12)+(Submetering!M12+Submetering!N12+Submetering!Y12)*0.1139) -> 54710.651 | F12: 1.15 | G12: =Gas!C14*0.9147 -> 1068.3696 | H12: 2.25 | I12: =Submetering!AE12+Submetering!AD12+Submetering!H12 -> 626 | J12: 9.12 | K12: =ELECT.!B14 -> 142
A13: Cairo at Nile Plaza | B13: =B12+1 -> 12 | C13: 5 | D13: 2019 | E13: =(((Submetering!O13+Submetering!P13)*0.842284+Submetering!Q13+(Submetering!M13+Submetering!N13+Submetering!Y13)*0.7362)+(Submetering!O13+Submetering!P13+Submetering!Q13)*0.1488+(Submetering!M13+Submetering!N13+Submetering!Y13)*0.1167+(Submetering!K13+Submetering!L13-Submetering!Z13-Submetering!AA13-Submetering!AB13-Submetering!AC13-Submetering!Q13)+(Submetering!M13+Submetering!N13+Submetering!Y13)*0.1139) -> 68941.898 | F13: 1.15 | G13: =Gas!C15*0.9147 -> 2638.9095 | H13: 2.25 | I13: =Submetering!AE13+Submetering!AD13+Submetering!H13 -> 866 | J13: 9.12 | K13: =ELECT.!B15 -> 163
A14: Cairo at Nile Plaza | B14: =B13+1 -> 13 | C14: 5 | D14: 2019 | E14: =(((Submetering!O14+Submetering!P14)*0.842284+Submetering!Q14+(Submetering!M14+Submetering!N14+Submetering!Y14)*0.7362)+(Submetering!O14+Submetering!P14+Submetering!Q14)*0.1488+(Submetering!M14+Submetering!N14+Submetering!Y14)*0.1167+(Submetering!K14+Submetering!L14-Submetering!Z14-Submetering!AA14-Submetering!AB14-Submetering!AC14-Submetering!Q14)+(Submetering!M14+Submetering!N14+Submetering!Y14)*0.1139) -> 61017.646 | F14: 1.15 | G14: =Gas!C16*0.9147 -> 2584.0275 | H14: 2.25 | I14: =Submetering!AE14+Submetering!AD14+Submetering!H14 -> 896 | J14: 9.12 | K14: =ELECT.!B16 -> 138
... A31: Cairo at Nile Plaza | B31: =B30+1 -> 30 | C31: 5 | D31: 2019 | E31: =(((Submetering!O31+Submetering!P31)*0.842284+Submetering!Q31+(Submetering!M31+Submetering!N31+Submetering!Y31)*0.7362)+(Submetering!O31+Submetering!P31+Submetering!Q31)*0.1488+(Submetering!M31+Submetering!N31+Submetering!Y31)*0.1167+(Submetering!K31+Submetering!L31-Submetering!Z31-Submetering!AA31-Submetering!AB31-Submetering!AC31-Submetering!Q31)+(Submetering!M31+Submetering!N31+Submetering!Y31)*0.1139) -> 21831.559 | F31: 1.15 | G31: =Gas!C33*0.9147 -> 2462.3724 | H31: 2.25 | I31: =Submetering!AE31+Submetering!AD31+Submetering!H31 -> 716 | J31: 9.12 | K31: =ELECT.!B33 -> 89
A32: Cairo at Nile Plaza | C32: 5 | E32: =(((Submetering!O32+Submetering!P32)*0.842284+Submetering!Q32+(Submetering!M32+Submetering!N32+Submetering!Y32)*0.7362)+(Submetering!O32+Submetering!P32+Submetering!Q32)*0.1488+(Submetering!M32+Submetering!N32+Submetering!Y32)*0.1167+(Submetering!K32+Submetering!L32-Submetering!Z32-Submetering!AA32-Submetering!AB32-Submetering!AC32-Submetering!Q32)+(Submetering!M32+Submetering!N32+Submetering!Y32)*0.1139) -> 32024.769 | F32: 1.15 | G32: =Gas!C34*0.9147 -> 2937.1017 | H32: 2.25 | I32: =Submetering!AE32+Submetering!AD32+Submetering!H32 -> 616 | J32: 9.12 | K32: =ELECT.!B34 -> 82

Sheet Submetering
A1: Site Name | B1: Day | C1: Month | D1: Year | E1: Main (m3) | F1: Podium (m3) | G1: Hotel (m3) | H1: Large (m3) | I1: Feeder 1 (KWh) | J1: Feeder 2 (KWh) | K1: T1 (KWh) | L1: T2 (KWh) | M1: T3 (KWh) | N1: T4 (KWh) | O1: T5 (KWh) | P1: T7 (KWh) | Q1: New Chiller (KWh) | R1: Hotel (BTU) | S1: B.S (BTU) | T1: LS (BTU) | U1: Mall (BTU) | V1: AHU#25 (BTU) | W1: AHU#9 (BTU) | X1: Room Nights | Y1: Loss (KWH) | Z1: Mall (KWH) | AA1: Citadel (KWH) | AB1: Rotana (KWH) | AC1: CIB (KWH) | AD1: Plaza suits water consumption (M3) | AE1: Hotel water consumption (M3)
A2: Cairo at Nile Plaza | B2: 1 | C2: 5 | D2: 2019 | E2: =Water!C4 -> 490 | F2: =Water!E4 -> 513 | G2: =Water!G4 -> 299.7 | H2: =Water!I4 -> 1.809 | I2: =ELECT.!F4 -> 13534 | J2: =ELECT.!H4 -> 59705 | K2: =ELECT.!K4 -> 5404 | L2: =ELECT.!M4 -> 4808 | M2: =ELECT.!O4 -> 8524 | N2: =ELECT.!Q4 -> 15159 | O2: =ELECT.!S4 -> 11167 | P2: =ELECT.!W4*2 -> 26416 | Q2: =ELECT.!D4 -> 800 | R2: =BTU!C3 -> 12.039 | S2: =BTU!F3 -> 1.428 | T2: =BTU!I3 -> 0 | U2: =BTU!O3 -> 1.504 | V2: =BTU!L3 -> 1.29 | W2: =BTU!R3 -> 1.9 | X2: =ELECT.!B4 -> 237 | Y2: =I2+J2-(K2+L2+M2+N2+O2+P2) -> 1761 | Z2: ='Mall, Citadel, Rotana'!C4+'Mall, Citadel, Rotana'!E4+'Mall, Citadel, Rotana'!G4+'Mall, Citadel, Rotana'!I4 -> 1129 | AA2: ='Mall, Citadel, Rotana'!K4+'Mall, Citadel, Rotana'!M4 -> 480 | AB2: ='Mall, Citadel, Rotana'!O4 -> 4 | AC2: ='Mall, Citadel, Rotana'!Q4+'Mall, Citadel, Rotana'!S4 -> 180 | AD2: =(E2-H2-194)*0.1318 -> 38.774374 | AE2: =E2-H2-AD2-194 -> 255.41663
A3: Cairo at Nile Plaza | B3: =B2+1 -> 2 | C3: 5 | D3: 2019 | E3: =Water!C5 -> 1060 | F3: =Water!E5 -> 683.1 | G3: =Water!G5 -> 707.4 | H3: =Water!I5 -> 7.56 | I3: =ELECT.!F5 -> 7578 | J3: =ELECT.!H5 -> 33043 | K3: =ELECT.!K5 -> 2867 | L3: =ELECT.!M5 -> 2818 | M3: =ELECT.!O5 -> 4690 | N3: =ELECT.!Q5 -> 9055 | O3: =ELECT.!S5 -> 6254 | P3: =ELECT.!W5*2 -> 14262 | Q3: =ELECT.!D5 -> 640 | R3: =BTU!C4 -> 6.591 | S3: =BTU!F4 -> 1.977 | T3: =BTU!I4 -> 0 | U3: =BTU!O4 -> 1.077 | V3: =BTU!L4 -> 1.04 | W3: =BTU!R4 -> 1.6 | X3: =ELECT.!B5 -> 241 | Y3: =I3+J3-(K3+L3+M3+N3+O3+P3) -> 675 | Z3: ='Mall, Citadel, Rotana'!C5+'Mall, Citadel, Rotana'!E5+'Mall, Citadel, Rotana'!G5+'Mall, Citadel, Rotana'!I5 -> 765 | AA3: ='Mall, Citadel, Rotana'!K5+'Mall, Citadel, Rotana'!M5 -> 640 | AB3: ='Mall, Citadel, Rotana'!O5 -> 2 | AC3: ='Mall, Citadel, Rotana'!Q5+'Mall, Citadel, Rotana'!S5 -> 240 | AD3: =(E3-H3-194)*0.1318 -> 113.14239 | AE3: =E3-H3-AD3-194 -> 745.29761
A4: Cairo at Nile Plaza | B4: =B3+1 -> 3 | C4: 5 | D4: 2019 | E4: =Water!C6 -> 1240 | F4: =Water!E6 -> 402.3 | G4: =Water!G6 -> 364.5 | H4: =Water!I6 -> 2.511 | I4: =ELECT.!F6 -> 17548 | J4: =ELECT.!H6 -> 77926 | K4: =ELECT.!K6 -> 6232 | L4: =ELECT.!M6 -> 6689 | M4: =ELECT.!O6 -> 10652 | N4: =ELECT.!Q6 -> 18990 | O4: =ELECT.!S6 -> 14693 | P4: =ELECT.!W6*2 -> 36256 | Q4: =ELECT.!D6 -> 800 | R4: =BTU!C5 -> 11.457 | S4: =BTU!F5 -> 1.577 | T4: =BTU!I5 -> 0 | U4: =BTU!O5 -> 2.106 | V4: =BTU!L5 -> 0.89 | W4: =BTU!R5 -> 1.93 | X4: =ELECT.!B6 -> 244 | Y4: =I4+J4-(K4+L4+M4+N4+O4+P4) -> 1962 | Z4: ='Mall, Citadel, Rotana'!C6+'Mall, Citadel, Rotana'!E6+'Mall, Citadel, Rotana'!G6+'Mall, Citadel, Rotana'!I6 -> 977 | AA4: ='Mall, Citadel, Rotana'!K6+'Mall, Citadel, Rotana'!M6 -> 480 | AB4: ='Mall, Citadel, Rotana'!O6 -> 3 | AC4: ='Mall, Citadel, Rotana'!Q6+'Mall, Citadel, Rotana'!S6 -> 192 | AD4: =(E4-H4-194)*0.1318 -> 137.53185 | AE4: =E4-H4-AD4-194 -> 905.95715
A5: Cairo at Nile Plaza | B5: =B4+1 -> 4 | C5: 5 | D5: 2019 | E5: =Water!C7 -> 970 | F5: =Water!E7 -> 542.7 | G5: =Water!G7 -> 402.3 | H5: =Water!I7 -> 4.752 | I5: =ELECT.!F7 -> 11603 | J5: =ELECT.!H7 -> 52369 | K5: =ELECT.!K7 -> 4561 | L5: =ELECT.!M7 -> 4363 | M5: =ELECT.!O7 -> 7070 | N5: =ELECT.!Q7 -> 11172 | O5: =ELECT.!S7 -> 10525 | P5: =ELECT.!W7*2 -> 24938 | Q5: =ELECT.!D7 -> 320 | R5: =BTU!C6 -> 7.611 | S5: =BTU!F6 -> 1.359 | T5: =BTU!I6 -> 0 | U5: =BTU!O6 -> 1.578 | V5: =BTU!L6 -> 1.5 | W5: =BTU!R6 -> 1.66 | X5: =ELECT.!B7 -> 204 | Y5: =I5+J5-(K5+L5+M5+N5+O5+P5) -> 1343 | Z5: ='Mall, Citadel, Rotana'!C7+'Mall, Citadel, Rotana'!E7+'Mall, Citadel, Rotana'!G7+'Mall, Citadel, Rotana'!I7 -> 742 | AA5: ='Mall, Citadel, Rotana'!K7+'Mall, Citadel, Rotana'!M7 -> 320 | AB5: ='Mall, Citadel, Rotana'!O7 -> 1 | AC5: ='Mall, Citadel, Rotana'!Q7+'Mall, Citadel, Rotana'!S7 -> 248 | AD5: =(E5-H5-194)*0.1318 -> 101.65049 | AE5: =E5-H5-AD5-194 -> 669.59751
A6: Cairo at Nile Plaza | B6: =B5+1 -> 5 | C6: 5 | D6: 2019 | E6: =Water!C8 -> 990 | F6: =Water!E8 -> 550.8 | G6: =Water!G8 -> 396.9 | H6: =Water!I8 -> 4.86 | I6: =ELECT.!F8 -> 13288 | J6: =ELECT.!H8 -> 58403 | K6: =ELECT.!K8 -> 5820 | L6: =ELECT.!M8 -> 4949 | M6: =ELECT.!O8 -> 8138 | N6: =ELECT.!Q8 -> 13698 | O6: =ELECT.!S8 -> 10831 | P6: =ELECT.!W8*2 -> 26624 | Q6: =ELECT.!D8 -> 160 | R6: =BTU!C7 -> 7.897 | S6: =BTU!F7 -> 2.726 | T6: =BTU!I7 -> 0 | U6: =BTU!O7 -> 1.66 | V6: =BTU!L7 -> 1.37 | W6: =BTU!R7 -> 1.48 | X6: =ELECT.!B8 -> 131 | Y6: =I6+J6-(K6+L6+M6+N6+O6+P6) -> 1631 | Z6: ='Mall, Citadel, Rotana'!C8+'Mall, Citadel, Rotana'!E8+'Mall, Citadel, Rotana'!G8+'Mall, Citadel, Rotana'!I8 -> 622 | AA6: ='Mall, Citadel, Rotana'!K8+'Mall, Citadel, Rotana'!M8 -> 320 | AB6: ='Mall, Citadel, Rotana'!O8 -> 1 | AC6: ='Mall, Citadel, Rotana'!Q8+'Mall, Citadel, Rotana'!S8 -> 178 | AD6: =(E6-H6-194)*0.1318 -> 104.27225 | AE6: =E6-H6-AD6-194 -> 686.86775
A7: Cairo at Nile Plaza | B7: =B6+1 -> 6 | C7: 5 | D7: 2019 | E7: =Water!C9 -> 1010 | F7: =Water!E9 -> 531.9 | G7: =Water!G9 -> 469.8 | H7: =Water!I9 -> 4.779 | I7: =ELECT.!F9 -> 9484 | J7: =ELECT.!H9 -> 40501 | K7: =ELECT.!K9 -> 4875 | L7: =ELECT.!M9 -> 3169 | M7: =ELECT.!O9 -> 6224 | N7: =ELECT.!Q9 -> 8921 | O7: =ELECT.!S9 -> 7555 | P7: =ELECT.!W9*2 -> 18372 | Q7: =ELECT.!D9 -> 320 | R7: =BTU!C8 -> 7.918 | S7: =BTU!F8 -> 2.534 | T7: =BTU!I8 -> 0 | U7: =BTU!O8 -> 1.172 | V7: =BTU!L8 -> 1.32 | W7: =BTU!R8 -> 0.73 | X7: =ELECT.!B9 -> 115 | Y7: =I7+J7-(K7+L7+M7+N7+O7+P7) -> 869 | Z7: ='Mall, Citadel, Rotana'!C9+'Mall, Citadel, Rotana'!E9+'Mall, Citadel, Rotana'!G9+'Mall, Citadel, Rotana'!I9 -> 643 | AA7: ='Mall, Citadel, Rotana'!K9+'Mall, Citadel, Rotana'!M9 -> 320 | AB7: ='Mall, Citadel, Rotana'!O9 -> 3 | AC7: ='Mall, Citadel, Rotana'!Q9+'Mall, Citadel, Rotana'!S9 -> 143 | AD7: =(E7-H7-194)*0.1318 -> 106.91893 | AE7: =E7-H7-AD7-194 -> 704.30207
A8: Cairo at Nile Plaza | B8: =B7+1 -> 7 | C8: 5 | D8: 2019 | E8: =Water!C10 -> 880 | F8: =Water!E10 -> 475.2 | G8: =Water!G10 -> 372.6 | H8: =Water!I10 -> 4.941 | I8: =ELECT.!F10 -> 20162 | J8: =ELECT.!H10 -> 70944 | K8: =ELECT.!K10 -> 8675 | L8: =ELECT.!M10 -> 7368 | M8: =ELECT.!O10 -> 12570 | N8: =ELECT.!Q10 -> 14539 | O8: =ELECT.!S10 -> 13125 | P8: =ELECT.!W10*2 -> 33352 | Q8: =ELECT.!D10 -> 640 | R8: =BTU!C9 -> 6.051 | S8: =BTU!F9 -> 1.884 | T8: =BTU!I9 -> 0 | U8: =BTU!O9 -> 1.133 | V8: =BTU!L9 -> 1.23 | W8: =BTU!R9 -> 1.2 | X8: =ELECT.!B10 -> 107 | Y8: =I8+J8-(K8+L8+M8+N8+O8+P8) -> 1477 | Z8: ='Mall, Citadel, Rotana'!C10+'Mall, Citadel, Rotana'!E10+'Mall, Citadel, Rotana'!G10+'Mall, Citadel, Rotana'!I10 -> 2698 | AA8: ='Mall, Citadel, Rotana'!K10+'Mall, Citadel, Rotana'!M10 -> 480 | AB8: ='Mall, Citadel, Rotana'!O10 -> 3 | AC8: ='Mall, Citadel, Rotana'!Q10+'Mall, Citadel, Rotana'!S10 -> 220 | AD8: =(E8-H8-194)*0.1318 -> 89.763576 | AE8: =E8-H8-AD8-194 -> 591.29542
A9: Cairo at Nile Plaza | B9: =B8+1 -> 8 | C9: 5 | D9: 2019 | E9: =Water!C11 -> 830 | F9: =Water!E11 -> 469.8 | G9: =Water!G11 -> 332.1 | H9: =Water!I11 -> 5.535 | I9: =ELECT.!F11 -> 12506 | J9: =ELECT.!H11 -> 54386 | K9: =ELECT.!K11 -> 6485 | L9: =ELECT.!M11 -> 4484 | M9: =ELECT.!O11 -> 7852 | N9: =ELECT.!Q11 -> 10614 | O9: =ELECT.!S11 -> 10111 | P9: =ELECT.!W11*2 -> 26180 | Q9: =ELECT.!D11 -> 1920 | R9: =BTU!C10 -> 7.434 | S9: =BTU!F10 -> 2.184 | T9: =BTU!I10 -> 0 | U9: =BTU!O10 -> 1.176 | V9: =BTU!L10 -> 1.23 | W9: =BTU!R10 -> 2.77 | X9: =ELECT.!B11 -> 85 | Y9: =I9+J9-(K9+L9+M9+N9+O9+P9) -> 1166 | Z9: ='Mall, Citadel, Rotana'!C11+'Mall, Citadel, Rotana'!E11+'Mall, Citadel, Rotana'!G11+'Mall, Citadel, Rotana'!I11 -> 1101 | AA9: ='Mall, Citadel, Rotana'!K11+'Mall, Citadel, Rotana'!M11 -> 1920 | AB9: ='Mall, Citadel, Rotana'!O11 -> 10 | AC9: ='Mall, Citadel, Rotana'!Q11+'Mall, Citadel, Rotana'!S11 -> 337 | AD9: =(E9-H9-194)*0.1318 -> 83.095287 | AE9: =E9-H9-AD9-194 -> 547.36971
A10: Cairo at Nile Plaza | B10: =B9+1 -> 9 | C10: 5 | D10: 2019 | E10: =Water!C12 -> 880 | F10: =Water!E12 -> 510.3 | G10: =Water!G12 -> 297 | H10: =Water!I12 -> 5.778 | I10: =ELECT.!F12 -> 9353 | J10: =ELECT.!H12 -> 33373 | K10: =ELECT.!K12 -> 4558 | L10: =ELECT.!M12 -> 3054 | M10: =ELECT.!O12 -> 6180 | N10: =ELECT.!Q12 -> 2430 | O10: =ELECT.!S12 -> 7088 | P10: =ELECT.!W12*2 -> 18662 | Q10: =ELECT.!D12 -> 960 | R10: =BTU!C11 -> 7 | S10: =BTU!F11 -> 1.408 | T10: =BTU!I11 -> 0 | U10: =BTU!O11 -> 1.113 | V10: =BTU!L11 -> 1.06 | W10: =BTU!R11 -> 0.93 | X10: =ELECT.!B12 -> 76 | Y10: =I10+J10-(K10+L10+M10+N10+O10+P10) -> 754 | Z10: ='Mall, Citadel, Rotana'!C12+'Mall, Citadel, Rotana'!E12+'Mall, Citadel, Rotana'!G12+'Mall, Citadel, Rotana'!I12 -> 1183 | AA10: ='Mall, Citadel, Rotana'!K12+'Mall, Citadel, Rotana'!M12 -> 640 | AB10: ='Mall, Citadel, Rotana'!O12 -> 3 | AC10: ='Mall, Citadel, Rotana'!Q12+'Mall, Citadel, Rotana'!S12 -> 173 | AD10: =(E10-H10-194)*0.1318 -> 89.65326 | AE10: =E10-H10-AD10-194 -> 590.56874
A11: Cairo at Nile Plaza | B11: =B10+1 -> 10 | C11: 5 | D11: 2019 | E11: =Water!C13 -> 980 | F11: =Water!E13 -> 569.7 | G11: =Water!G13 -> 369.9 | H11: =Water!I13 -> 5.4 | I11: =ELECT.!F13 -> 17011 | J11: =ELECT.!H13 -> 62450 | K11: =ELECT.!K13 -> 8020 | L11: =ELECT.!M13 -> 5585 | M11: =ELECT.!O13 -> 11184 | N11: =ELECT.!Q13 -> 4384 | O11: =ELECT.!S13 -> 13440 | P11: =ELECT.!W13*2 -> 35292 | Q11: =ELECT.!D13 -> 640 | R11: =BTU!C12 -> 6.366 | S11: =BTU!F12 -> 0.977 | T11: =BTU!I12 -> 0 | U11: =BTU!O12 -> 1.216 | V11: =BTU!L12 -> 0.86 | W11: =BTU!R12 -> 0.8 | X11: =ELECT.!B13 -> 133 | Y11: =I11+J11-(K11+L11+M11+N11+O11+P11) -> 1556 | Z11: ='Mall, Citadel, Rotana'!C13+'Mall, Citadel, Rotana'!E13+'Mall, Citadel, Rotana'!G13+'Mall, Citadel, Rotana'!I13 -> 1042 | AA11: ='Mall, Citadel, Rotana'!K13+'Mall, Citadel, Rotana'!M13 -> 480 | AB11: ='Mall, Citadel, Rotana'!O13 -> 3 | AC11: ='Mall, Citadel, Rotana'!Q13+'Mall, Citadel, Rotana'!S13 -> 144 | AD11: =(E11-H11-194)*0.1318 -> 102.88308 | AE11: =E11-H11-AD11-194 -> 677.71692
A12: Cairo at Nile Plaza | B12: =B11+1 -> 11 | C12: 5 | D12: 2019 | E12: =Water!C14 -> 820 | F12: =Water!E14 -> 445.5 | G12: =Water!G14 -> 342.9 | H12: =Water!I14 -> 4.401 | I12: =ELECT.!F14 -> 11788 | J12: =ELECT.!H14 -> 45761 | K12: =ELECT.!K14 -> 5719 | L12: =ELECT.!M14 -> 3779 | M12: =ELECT.!O14 -> 7590 | N12: =ELECT.!Q14 -> 6648 | O12: =ELECT.!S14 -> 9080 | P12: =ELECT.!W14*2 -> 3962 | Q12: =ELECT.!D14 -> 640 | R12: =BTU!C13 -> 7.252 | S12: =BTU!F13 -> 1.555 | T12: =BTU!I13 -> 0.001 | U12: =BTU!O13 -> 1.144 | V12: =BTU!L13 -> 1.24 | W12: =BTU!R13 -> 1.98 | X12: =ELECT.!B14 -> 142 | Y12: =I12+J12-(K12+L12+M12+N12+O12+P12) -> 20771 | Z12: ='Mall, Citadel, Rotana'!C14+'Mall, Citadel, Rotana'!E14+'Mall, Citadel, Rotana'!G14+'Mall, Citadel, Rotana'!I14 -> 1025 | AA12: ='Mall, Citadel, Rotana'!K14+'Mall, Citadel, Rotana'!M14 -> 480 | AB12: ='Mall, Citadel, Rotana'!O14 -> 3 | AC12: ='Mall, Citadel, Rotana'!Q14+'Mall, Citadel, Rotana'!S14 -> 147 | AD12: =(E12-H12-194)*0.1318 -> 81.926748 | AE12: =E12-H12-AD12-194 -> 539.67225
A13: Cairo at Nile Plaza | B13: =B12+1 -> 12 | C13: 5 | D13: 2019 | E13: =Water!C15 -> 1060 | F13: =Water!E15 -> 604.8 | G13: =Water!G15 -> 415.8 | H13: =Water!I15 -> 6.993 | I13: =ELECT.!F15 -> 13077 | J13: =ELECT.!H15 -> 58216 | K13: =ELECT.!K15 -> 6166 | L13: =ELECT.!M15 -> 4661 | M13: =ELECT.!O15 -> 8220 | N13: =ELECT.!Q15 -> 12413 | O13: =ELECT.!S15 -> 10638 | P13: =ELECT.!W15*2 -> 47760 | Q13: =ELECT.!D15 -> 640 | R13: =BTU!C14 -> 7.891 | S13: =BTU!F14 -> 2.401 | T13: =BTU!I14 -> 0 | U13: =BTU!O14 -> 1.176 | V13: =BTU!L14 -> 1.3 | W13: =BTU!R14 -> 0 | X13: =ELECT.!B15 -> 163 | Y13: =I13+J13-(K13+L13+M13+N13+O13+P13) -> -18565 | Z13: ='Mall, Citadel, Rotana'!C15+'Mall, Citadel, Rotana'!E15+'Mall, Citadel, Rotana'!G15+'Mall, Citadel, Rotana'!I15 -> 862 | AA13: ='Mall, Citadel, Rotana'!K15+'Mall, Citadel, Rotana'!M15 -> 800 | AB13: ='Mall, Citadel, Rotana'!O15 -> 3 | AC13: ='Mall, Citadel, Rotana'!Q15+'Mall, Citadel, Rotana'!S15 -> 192 | AD13: =(E13-H13-194)*0.1318 -> 113.21712 | AE13: =E13-H13-AD13-194 -> 745.78988
A14: Cairo at Nile Plaza | B14: =B13+1 -> 13 | C14: 5 | D14: 2019 | E14: =Water!C16 -> 1090 | F14: =Water!E16 -> 564.3 | G14: =Water!G16 -> 423.9 | H14: =Water!I16 -> 5.184 | I14: =ELECT.!F16 -> 11593 | J14: =ELECT.!H16 -> 52244 | K14: =ELECT.!K16 -> 5918 | L14: =ELECT.!M16 -> 4075 | M14: =ELECT.!O16 -> 7410 | N14: =ELECT.!Q16 -> 11605 | O14: =ELECT.!S16 -> 9875 | P14: =ELECT.!W16*2 -> 23770 | Q14: =ELECT.!D16 -> 640 | R14: =BTU!C15 -> 9.031 | S14: =BTU!F15 -> 2.592 | T14: =BTU!I15 -> 0 | U14: =BTU!O15 -> 1.18 | V14: =BTU!L15 -> 1.27 | W14: =BTU!R15 -> 1.7 | X14: =ELECT.!B16 -> 138 | Y14: =I14+J14-(K14+L14+M14+N14+O14+P14) -> 1184 | Z14: ='Mall, Citadel, Rotana'!C16+'Mall, Citadel, Rotana'!E16+'Mall, Citadel, Rotana'!G16+'Mall, Citadel, Rotana'!I16 -> 1042 | AA14: ='Mall, Citadel, Rotana'!K16+'Mall, Citadel, Rotana'!M16 -> 640 | AB14: ='Mall, Citadel, Rotana'!O16 -> 3 | AC14: ='Mall, Citadel, Rotana'!Q16+'Mall, Citadel, Rotana'!S16 -> 259 | AD14: =(E14-H14-194)*0.1318 -> 117.40955 | AE14: =E14-H14-AD14-194 -> 773.40645
... A32: Cairo at Nile Plaza | B32: =B31+1 -> 31 | C32: 5 | D32: 2019 | E32: =Water!C34 -> 810 | F32: =Water!E34 -> 464.4 | G32: =Water!G34 -> 413.1 | H32: =Water!I34 -> 4.212 | I32: =ELECT.!F34 -> 13442 | J32: =ELECT.!H34 -> 18562 | K32: =ELECT.!K34 -> 10794 | L32: =ELECT.!M34 -> 2726 | M32: =ELECT.!O34 -> 8358 | N32: =ELECT.!Q34 -> 20634 | O32: =ELECT.!S34 -> 13863 | P32: =ELECT.!W34*2 -> 31172 | Q32: =ELECT.!D34 -> 160 | R32: =BTU!C33 -> 12.805 | S32: =BTU!F33 -> 2.192 | T32: =BTU!I33 -> 0.002 | U32: =BTU!O33 -> 1.7059667 | V32: =BTU!L33 -> 0.97 | W32: =BTU!R33 -> 0.3375 | X32: =ELECT.!B34 -> 82 | Y32: =I32+J32-(K32+L32+M32+N32+O32+P32) -> -55543 | Z32: ='Mall, Citadel, Rotana'!C34+'Mall, Citadel, Rotana'!E34+'Mall, Citadel, Rotana'!G34+'Mall, Citadel, Rotana'!I34 -> 301 | AA32: ='Mall, Citadel, Rotana'!K34+'Mall, Citadel, Rotana'!M34 -> 160 | AB32: ='Mall, Citadel, Rotana'!O34 -> 3 | AC32: ='Mall, Citadel, Rotana'!Q34+'Mall, Citadel, Rotana'!S34 -> 19 | AD32: =(E32-H32-194)*0.1318 -> 80.633658 | AE32: =E32-H32-AD32-194 -> 531.15434

Sheet Mall, Citadel, Rotana
A1: Mall, Citadel and Rotana readings and cons. MAY 2019
A2: Day | B2: R1 | C2: Cons | D2: R2 | E2: Cons | F2: R3 | G2: Cons | H2: R4 | I2: Cons | J2: RO1 | K2: Cons | L2: RO2 | M2: Cons | N2: ROE | O2: Cons | P2: CIB. 1 | Q2: Cons | R2: CIB. E | S2: Cons
A3: Last | B3: 41866 | D3: 37448 | F3: 17666 | H3: 214979 | J3: 303517 | L3: 22153 | N3: 168148 | P3: 983783 | R3: 55047
A4: 43586 | B4: 41869 | C4: =(B4-B3)*600/5 -> 360 | D4: 37452 | E4: =(D4-D3)*800/5 -> 640 | F4: 17671 | G4: =(F4-F3)*100/5 -> 100 | H4: 215008 | I4: =H4-H3 -> 29 | J4: 303517 | K4: =J4-J3 -> 0 | L4: 22156 | M4: =(L4-L3)*800/5 -> 480 | N4: 168152 | O4: =N4-N3 -> 4 | P4: 983963 | Q4: =P4-P3 -> 180 | R4: 55047 | S4: =R4-R3 -> 0
A5: 43587 | B5: 41872 | C5: =(B5-B4)*600/5 -> 360 | D5: 37454 | E5: =(D5-D4)*800/5 -> 320 | F5: 17674 | G5: =(F5-F4)*100/5 -> 60 | H5: 215033 | I5: =H5-H4 -> 25 | J5: 303517 | K5: =J5-J4 -> 0 | L5: 22160 | M5: =(L5-L4)*800/5 -> 640 | N5: 168154 | O5: =N5-N4 -> 2 | P5: 984203 | Q5: =P5-P4 -> 240 | R5: 55047 | S5: =R5-R4 -> 0
A6: 43588 | B6: 41874 | C6: =(B6-B5)*600/5 -> 240 | D6: 37458 | E6: =(D6-D5)*800/5 -> 640 | F6: 17678 | G6: =(F6-F5)*100/5 -> 80 | H6: 215050 | I6: =H6-H5 -> 17 | J6: 303517 | K6: =J6-J5 -> 0 | L6: 22163 | M6: =(L6-L5)*800/5 -> 480 | N6: 168157 | O6: =N6-N5 -> 3 | P6: 984395 | Q6: =P6-P5 -> 192 | R6: 55047 | S6: =R6-R5 -> 0
A7: 43589 | B7: 41876 | C7: =(B7-B6)*600/5 -> 240 | D7: 37461 | E7: =(D7-D6)*800/5 -> 480 | F7: 17679 | G7: =(F7-F6)*100/5 -> 20 | H7: 215052 | I7: =H7-H6 -> 2 | J7: 303517 | K7: =J7-J6 -> 0 | L7: 22165 | M7: =(L7-L6)*800/5 -> 320 | N7: 168158 | O7: =N7-N6 -> 1 | P7: 984643 | Q7: =P7-P6 -> 248 | R7: 55047 | S7: =R7-R6 -> 0
A8: 43590 | B8: 41878 | C8: =(B8-B7)*600/5 -> 240 | D8: 37463 | E8: =(D8-D7)*800/5 -> 320 | F8: 17682 | G8: =(F8-F7)*100/5 -> 60 | H8: 215054 | I8: =H8-H7 -> 2 | J8: 303517 | K8: =J8-J7 -> 0 | L8: 22167 | M8: =(L8-L7)*800/5 -> 320 | N8: 168159 | O8: =N8-N7 -> 1 | P8: 984821 | Q8: =P8-P7 -> 178 | R8: 55047 | S8: =R8-R7 -> 0
A9: 43591 | B9: 41879 | C9: =(B9-B8)*600/5 -> 120 | D9: 37466 | E9: =(D9-D8)*800/5 -> 480 | F9: 17684 | G9: =(F9-F8)*100/5 -> 40 | H9: 215057 | I9: =H9-H8 -> 3 | J9: 303517 | K9: =J9-J8 -> 0 | L9: 22169 | M9: =(L9-L8)*800/5 -> 320 | N9: 168162 | O9: =N9-N8 -> 3 | P9: 984964 | Q9: =P9-P8 -> 143 | R9: 55047 | S9: =R9-R8 -> 0
A10: 43592 | B10: 41894 | C10: =(B10-B9)*600/5 -> 1800 | D10: 37470 | E10: =(D10-D9)*800/5 -> 640 | F10: 17694 | G10: =(F10-F9)*100/5 -> 200 | H10: 215115 | I10: =H10-H9 -> 58 | J10: 303517 | K10: =J10-J9 -> 0 | L10: 22172 | M10: =(L10-L9)*800/5 -> 480 | N10: 168165 | O10: =N10-N9 -> 3 | P10: 985184 | Q10: =P10-P9 -> 220 | R10: 55047 | S10: =R10-R9 -> 0
A11: 43593 | B11: 41898 | C11: =(B11-B10)*600/5 -> 480 | D11: 37473 | E11: =(D11-D10)*800/5 -> 480 | F11: 17697 | G11: =(F11-F10)*100/5 -> 60 | H11: 215196 | I11: =H11-H10 -> 81 | J11: 303517 | K11: =J11-J10 -> 0 | L11: 22184 | M11: =(L11-L10)*800/5 -> 1920 | N11: 168175 | O11: =N11-N10 -> 10 | P11: 985521 | Q11: =P11-P10 -> 337 | R11: 55047 | S11: =R11-R10 -> 0
A12: 43594 | B12: 41903 | C12: =(B12-B11)*600/5 -> 600 | D12: 37476 | E12: =(D12-D11)*800/5 -> 480 | F12: 17702 | G12: =(F12-F11)*100/5 -> 100 | H12: 215199 | I12: =H12-H11 -> 3 | J12: 303517 | K12: =J12-J11 -> 0 | L12: 22188 | M12: =(L12-L11)*800/5 -> 640 | N12: 168178 | O12: =N12-N11 -> 3 | P12: 985694 | Q12: =P12-P11 -> 173 | R12: 55047 | S12: =R12-R11 -> 0
A13: 43595 | B13: 41907 | C13: =(B13-B12)*600/5 -> 480 | D13: 37479 | E13: =(D13-D12)*800/5 -> 480 | F13: 17706 | G13: =(F13-F12)*100/5 -> 80 | H13: 215201 | I13: =H13-H12 -> 2 | J13: 303517 | K13: =J13-J12 -> 0 | L13: 22191 | M13: =(L13-L12)*800/5 -> 480 | N13: 168181 | O13: =N13-N12 -> 3 | P13: 985838 | Q13: =P13-P12 -> 144 | R13: 55047 | S13: =R13-R12 -> 0
A14: 43596 | B14: 41911 | C14: =(B14-B13)*600/5 -> 480 | D14: 37482 | E14: =(D14-D13)*800/5 -> 480 | F14: 17709 | G14: =(F14-F13)*100/5 -> 60 | H14: 215206 | I14: =H14-H13 -> 5 | J14: 303517 | K14: =J14-J13 -> 0 | L14: 22194 | M14: =(L14-L13)*800/5 -> 480 | N14: 168184 | O14: =N14-N13 -> 3 | P14: 985985 | Q14: =P14-P13 -> 147 | R14: 55047 | S14: =R14-R13 -> 0
A15: 43597 | B15: 41915 | C15: =(B15-B14)*600/5 -> 480 | D15: 37484 | E15: =(D15-D14)*800/5 -> 320 | F15: 17712 | G15: =(F15-F14)*100/5 -> 60 | H15: 215208 | I15: =H15-H14 -> 2 | J15: 303517 | K15: =J15-J14 -> 0 | L15: 22199 | M15: =(L15-L14)*800/5 -> 800 | N15: 168187 | O15: =N15-N14 -> 3 | P15: 986177 | Q15: =P15-P14 -> 192 | R15: 55047 | S15: =R15-R14 -> 0
... A31: 43613 | B31: 41984 | C31: =(B31-B30)*600/5 -> 480 | D31: 37534 | E31: =(D31-D30)*800/5 -> 640 | F31: 17771 | G31: =(F31-F30)*100/5 -> 80 | H31: 215273 | I31: =H31-H30 -> 4 | J31: 303517 | K31: =J31-J30 -> 0 | L31: 22263 | M31: =(L31-L30)*800/5 -> 640 | N31: 168236 | O31: =N31-N30 -> 3 | P31: 989357 | Q31: =P31-P30 -> 127 | R31: 55047 | S31: =R31-R30 -> 0
A32: 43614 | B32: 41989 | C32: =(B32-B31)*600/5 -> 600 | D32: 37537 | E32: =(D32-D31)*800/5 -> 480 | F32: 17775 | G32: =(F32-F31)*100/5 -> 80 | H32: 215278 | I32: =H32-H31 -> 5 | J32: 303517 | K32: =J32-J31 -> 0 | L32: 22268 | M32: =(L32-L31)*800/5 -> 800 | N32: 168240 | O32: =N32-N31 -> 4 | P32: 989485 | Q32: 41 | R32: 55047 | S32: =R32-R31 -> 0
A33: 43615 | B33: 41990 | C33: =(B33-B32)*600/5 -> 120 | D33: 37538 | E33: =(D33-D32)*800/5 -> 160 | F33: 17777 | G33: =(F33-F32)*100/5 -> 40 | H33: 215278 | I33: =H33-H32 -> 0 | J33: 303517 | K33: =J33-J32 -> 0 | L33: 22269 | M33: =(L33-L32)*800/5 -> 160 | N33: 168240 | O33: =N33-N32 -> 0 | P33: 989485 | Q33: =P33-P32 -> 0 | R33: 55047 | S33: =R33-R32 -> 0
A34: 43616 | B34: 41991 | C34: =(B34-B33)*600/5 -> 120 | D34: 37539 | E34: =(D34-D33)*800/5 -> 160 | F34: 17778 | G34: =(F34-F33)*100/5 -> 20 | H34: 215279 | I34: =H34-H33 -> 1 | J34: 303517 | K34: =J34-J33 -> 0 | L34: 22270 | M34: =(L34-L33)*800/5 -> 160 | N34: 168243 | O34: =N34-N33 -> 3 | P34: 989504 | Q34: =P34-P33 -> 19 | R34: 55047 | S34: =R34-R33 -> 0
A35: Total | C35: =SUM(C4:C34) -> 15000 | E35: =SUM(E4:E34) -> 14560 | G35: =SUM(G4:G34) -> 2240 | I35: =SUM(I4:I34) -> 300 | K35: =SUM(K4:K34) -> 0 | M35: =SUM(M4:M34) -> 18720 | Q35: =SUM(Q4:Q34) -> 5634 | S35: =SUM(S4:S34) -> 0

Sheet Water
A1: Main Building, Podium, Hotel and Large cons. MAY 2019
A2: Day | B2: Main Reading | C2: Cons. | D2: Podium | E2: Cons. | F2: Hotel | G2: Cons. | H2: Large | I2: Cons. | J2: Total | K2: cost.LE
A3: Last | B3: 351660 | C3: 0 | D3: 93796800 | E3: 0 | F3: 93388700 | G3: 0 | H3: 609235 | I3: 0 | J3: =C3+E3+G3+I3 -> 0 | K3: =J3*5.86 -> 0
A4: 43586 | B4: 351709 | C4: =(IF((B4-B3)<0,"0",(B4-B3)))*10 -> 490 | D4: 93815800 | E4: =(IF((D4-D3)<0,"0",(D4-D3)))*0.027 -> 513 | F4: 93399800 | G4: =(IF((F4-F3)<0,"0",(F4-F3)))*0.027 -> 299.7 | H4: 609302 | I4: =(IF((H4-H3)<0,"0",(H4-H3)))*0.027 -> 1.809 | J4: =C4+E4+G4+I4 -> 1304.509 | K4: =J4*5.86 -> 7644.4227
A5: 43587 | B5: 351815 | C5: =(IF((B5-B4)<0,"0",(B5-B4)))*10 -> 1060 | D5: 93841100 | E5: =(IF((D5-D4)<0,"0",(D5-D4)))*0.027 -> 683.1 | F5: 93426000 | G5: =(IF((F5-F4)<0,"0",(F5-F4)))*0.027 -> 707.4 | H5: 609582 | I5: =(IF((H5-H4)<0,"0",(H5-H4)))*0.027 -> 7.56 | J5: =C5+E5+G5+I5 -> 2458.06 | K5: =J5*5.86 -> 14404.232
A6: 43588 | B6: 351939 | C6: =(IF((B6-B5)<0,"0",(B6-B5)))*10 -> 1240 | D6: 93856000 | E6: =(IF((D6-D5)<0,"0",(D6-D5)))*0.027 -> 402.3 | F6: 93439500 | G6: =(IF((F6-F5)<0,"0",(F6-F5)))*0.027 -> 364.5 | H6: 609675 | I6: =(IF((H6-H5)<0,"0",(H6-H5)))*0.027 -> 2.511 | J6: =C6+E6+G6+I6 -> 2009.311 | K6: =J6*5.86 -> 11774.562
A7: 43589 | B7: 352036 | C7: =(IF((B7-B6)<0,"0",(B7-B6)))*10 -> 970 | D7: 93876100 | E7: =(IF((D7-D6)<0,"0",(D7-D6)))*0.027 -> 542.7 | F7: 93454400 | G7: =(IF((F7-F6)<0,"0",(F7-F6)))*0.027 -> 402.3 | H7: 609851 | I7: =(IF((H7-H6)<0,"0",(H7-H6)))*0.027 -> 4.752 | J7: =C7+E7+G7+I7 -> 1919.752 | K7: =J7*5.86 -> 11249.747
A8: 43590 | B8: 352135 | C8: =(IF((B8-B7)<0,"0",(B8-B7)))*10 -> 990 | D8: 93896500 | E8: =(IF((D8-D7)<0,"0",(D8-D7)))*0.027 -> 550.8 | F8: 93469100 | G8: =(IF((F8-F7)<0,"0",(F8-F7)))*0.027 -> 396.9 | H8: 610031 | I8: =(IF((H8-H7)<0,"0",(H8-H7)))*0.027 -> 4.86 | J8: =C8+E8+G8+I8 -> 1942.56 | K8: =J8*5.86 -> 11383.402
A9: 43591 | B9: 352236 | C9: =(IF((B9-B8)<0,"0",(B9-B8)))*10 -> 1010 | D9: 93916200 | E9: =(IF((D9-D8)<0,"0",(D9-D8)))*0.027 -> 531.9 | F9: 93486500 | G9: =(IF((F9-F8)<0,"0",(F9-F8)))*0.027 -> 469.8 | H9: 610208 | I9: =(IF((H9-H8)<0,"0",(H9-H8)))*0.027 -> 4.779 | J9: =C9+E9+G9+I9 -> 2016.479 | K9: =J9*5.86 -> 11816.567
A10: 43592 | B10: 352324 | C10: =(IF((B10-B9)<0,"0",(B10-B9)))*10 -> 880 | D10: 93933800 | E10: =(IF((D10-D9)<0,"0",(D10-D9)))*0.027 -> 475.2 | F10: 93500300 | G10: =(IF((F10-F9)<0,"0",(F10-F9)))*0.027 -> 372.6 | H10: 610391 | I10: =(IF((H10-H9)<0,"0",(H10-H9)))*0.027 -> 4.941 | J10: =C10+E10+G10+I10 -> 1732.741 | K10: =J10*5.86 -> 10153.862
A11: 43593 | B11: 352407 | C11: =(IF((B11-B10)<0,"0",(B11-B10)))*10 -> 830 | D11: 93951200 | E11: =(IF((D11-D10)<0,"0",(D11-D10)))*0.027 -> 469.8 | F11: 93512600 | G11: =(IF((F11-F10)<0,"0",(F11-F10)))*0.027 -> 332.1 | H11: 610596 | I11: =(IF((H11-H10)<0,"0",(H11-H10)))*0.027 -> 5.535 | J11: =C11+E11+G11+I11 -> 1637.435 | K11: =J11*5.86 -> 9595.3691
A12: 43594 | B12: 352495 | C12: =(IF((B12-B11)<0,"0",(B12-B11)))*10 -> 880 | D12: 93970100 | E12: =(IF((D12-D11)<0,"0",(D12-D11)))*0.027 -> 510.3 | F12: 93523600 | G12: =(IF((F12-F11)<0,"0",(F12-F11)))*0.027 -> 297 | H12: 610810 | I12: =(IF((H12-H11)<0,"0",(H12-H11)))*0.027 -> 5.778 | J12: =C12+E12+G12+I12 -> 1693.078 | K12: =J12*5.86 -> 9921.4371
A13: 43595 | B13: 352593 | C13: =(IF((B13-B12)<0,"0",(B13-B12)))*10 -> 980 | D13: 93991200 | E13: =(IF((D13-D12)<0,"0",(D13-D12)))*0.027 -> 569.7 | F13: 93537300 | G13: =(IF((F13-F12)<0,"0",(F13-F12)))*0.027 -> 369.9 | H13: 611010 | I13: =(IF((H13-H12)<0,"0",(H13-H12)))*0.027 -> 5.4 | J13: =C13+E13+G13+I13 -> 1925 | K13: =J13*5.86 -> 11280.5
A14: 43596 | B14: 352675 | C14: =(IF((B14-B13)<0,"0",(B14-B13)))*10 -> 820 | D14: 94007700 | E14: =(IF((D14-D13)<0,"0",(D14-D13)))*0.027 -> 445.5 | F14: 93550000 | G14: =(IF((F14-F13)<0,"0",(F14-F13)))*0.027 -> 342.9 | H14: 611173 | I14: =(IF((H14-H13)<0,"0",(H14-H13)))*0.027 -> 4.401 | J14: =C14+E14+G14+I14 -> 1612.801 | K14: =J14*5.86 -> 9451.0139
A15: 43597 | B15: 352781 | C15: =(IF((B15-B14)<0,"0",(B15-B14)))*10 -> 1060 | D15: 94030100 | E15: =(IF((D15-D14)<0,"0",(D15-D14)))*0.027 -> 604.8 | F15: 93565400 | G15: =(IF((F15-F14)<0,"0",(F15-F14)))*0.027 -> 415.8 | H15: 611432 | I15: =(IF((H15-H14)<0,"0",(H15-H14)))*0.027 -> 6.993 | J15: =C15+E15+G15+I15 -> 2087.593 | K15: =J15*5.86 -> 12233.295
... A18: 43600 | B18: 353001 | C18: =(IF((B18-B17)<0,"0",(B18-B17)))*10 -> 110 | D18: 94092300 | E18: =(IF((D18-D17)<0,"0",(D18-D17)))*0.027 -> 486 | F18: 93614400 | G18: =(IF((F18-F17)<0,"0",(F18-F17)))*0.027 -> 388.8 | H18: 612047 | I18: =(IF((H18-H17)<0,"0",(H18-H17)))*0.027 -> 5.319 | J18: =C18+E18+G18+I18 -> 990.119 | K18: =J18*5.86 -> 5802.0973
A19: 43601 | B19: 353104 | C19: =(IF((B19-B18)<0,"0",(B19-B18)))*10 -> 1030 | D19: 94098600 | E19: =(IF((D19-D18)<0,"0",(D19-D18)))*0.027 -> 170.1 | F19: 93622400 | G19: =(IF((F19-F18)<0,"0",(F19-F18)))*0.027 -> 216 | H19: 612247 | I19: =(IF((H19-H18)<0,"0",(H19-H18)))*0.027 -> 5.4 | J19: =C19+E19+G19+I19 -> 1421.5 | K19: =J19*5.86 -> 8329.99 | Q19: `
A20: 43602 | B20: 353258 | C20: =(IF((B20-B19)<0,"0",(B20-B19)))*10 -> 1540 | D20: 94126700 | E20: =(IF((D20-D19)<0,"0",(D20-D19)))*0.027 -> 758.7 | F20: 93641800 | G20: =(IF((F20-F19)<0,"0",(F20-F19)))*0.027 -> 523.8 | H20: 612356 | I20: =(IF((H20-H19)<0,"0",(H20-H19)))*0.027 -> 2.943 | J20: =C20+E20+G20+I20 -> 2825.443 | K20: =J20*5.86 -> 16557.096
A21: 43603 | B21: 353363 | C21: =(IF((B21-B20)<0,"0",(B21-B20)))*10 -> 1050 | D21: 94145600 | E21: =(IF((D21-D20)<0,"0",(D21-D20)))*0.027 -> 510.3 | F21: 93655500 | G21: =(IF((F21-F20)<0,"0",(F21-F20)))*0.027 -> 369.9 | H21: 612537 | I21: =(IF((H21-H20)<0,"0",(H21-H20)))*0.027 -> 4.887 | J21: =C21+E21+G21+I21 -> 1935.087 | K21: =J21*5.86 -> 11339.61
A22: 43604 | B22: 353436 | C22: =(IF((B22-B21)<0,"0",(B22-B21)))*10 -> 730 | D22: 94163200 | E22: =(IF((D22-D21)<0,"0",(D22-D21)))*0.027 -> 475.2 | F22: 93668800 | G22: =(IF((F22-F21)<0,"0",(F22-F21)))*0.027 -> 359.1 | H22: 612706 | I22: =(IF((H22-H21)<0,"0",(H22-H21)))*0.027 -> 4.563 | J22: =C22+E22+G22+I22 -> 1568.863 | K22: =J22*5.86 -> 9193.5372
A23: 43605 | B23: 353533 | C23: =(IF((B23-B22)<0,"0",(B23-B22)))*10 -> 970 | D23: 94182900 | E23: =(IF((D23-D22)<0,"0",(D23-D22)))*0.027 -> 531.9 | F23: 93683800 | G23: =(IF((F23-F22)<0,"0",(F23-F22)))*0.027 -> 405 | H23: 612895 | I23: =(IF((H23-H22)<0,"0",(H23-H22)))*0.027 -> 5.103 | J23: =C23+E23+G23+I23 -> 1912.003 | K23: =J23*5.86 -> 11204.338
A24: 43606 | B24: 353637 | C24: =(IF((B24-B23)<0,"0",(B24-B23)))*10 -> 1040 | D24: 94203500 | E24: =(IF((D24-D23)<0,"0",(D24-D23)))*0.027 -> 556.2 | F24: 93701200 | G24: =(IF((F24-F23)<0,"0",(F24-F23)))*0.027 -> 469.8 | H24: 613093 | I24: =(IF((H24-H23)<0,"0",(H24-H23)))*0.027 -> 5.346 | J24: =C24+E24+G24+I24 -> 2071.346 | K24: =J24*5.86 -> 12138.088
A25: 43607 | B25: 353745 | C25: =(IF((B25-B24)<0,"0",(B25-B24)))*10 -> 1080 | D25: 94223100 | E25: =(IF((D25-D24)<0,"0",(D25-D24)))*0.027 -> 529.2 | F25: 93721200 | G25: =(IF((F25-F24)<0,"0",(F25-F24)))*0.027 -> 540 | H25: 613264 | I25: =(IF((H25-H24)<0,"0",(H25-H24)))*0.027 -> 4.617 | J25: =C25+E25+G25+I25 -> 2153.817 | K25: =J25*5.86 -> 12621.368
A26: 43608 | B26: 353842 | C26: =(IF((B26-B25)<0,"0",(B26-B25)))*10 -> 970 | D26: 94241000 | E26: =(IF((D26-D25)<0,"0",(D26-D25)))*0.027 -> 483.3 | F26: 93738500 | G26: =(IF((F26-F25)<0,"0",(F26-F25)))*0.027 -> 467.1 | H26: 613426 | I26: =(IF((H26-H25)<0,"0",(H26-H25)))*0.027 -> 4.374 | J26: =C26+E26+G26+I26 -> 1924.774 | K26: =J26*5.86 -> 11279.176
A27: 43609 | B27: 353949 | C27: =(IF((B27-B26)<0,"0",(B27-B26)))*10 -> 1070 | D27: 94262000 | E27: =(IF((D27-D26)<0,"0",(D27-D26)))*0.027 -> 567 | F27: 93756700 | G27: =(IF((F27-F26)<0,"0",(F27-F26)))*0.027 -> 491.4 | H27: 613591 | I27: =(IF((H27-H26)<0,"0",(H27-H26)))*0.027 -> 4.455 | J27: =C27+E27+G27+I27 -> 2132.855 | K27: =J27*5.86 -> 12498.53
A28: 43610 | B28: 354051 | C28: =(IF((B28-B27)<0,"0",(B28-B27)))*10 -> 1020 | D28: 94281800 | E28: =(IF((D28-D27)<0,"0",(D28-D27)))*0.027 -> 534.6 | F28: 93773000 | G28: =(IF((F28-F27)<0,"0",(F28-F27)))*0.027 -> 440.1 | H28: 613778 | I28: =(IF((H28-H27)<0,"0",(H28-H27)))*0.027 -> 5.049 | J28: =C28+E28+G28+I28 -> 1999.749 | K28: =J28*5.86 -> 11718.529
A29: 43611 | B29: 354165 | C29: =(IF((B29-B28)<0,"0",(B29-B28)))*10 -> 1140 | D29: 94305800 | E29: =(IF((D29-D28)<0,"0",(D29-D28)))*0.027 -> 648 | F29: 93790400 | G29: =(IF((F29-F28)<0,"0",(F29-F28)))*0.027 -> 469.8 | H29: 613955 | I29: =(IF((H29-H28)<0,"0",(H29-H28)))*0.027 -> 4.779 | J29: =C29+E29+G29+I29 -> 2262.579 | K29: =J29*5.86 -> 13258.713
A30: 43612 | B30: 354275 | C30: =(IF((B30-B29)<0,"0",(B30-B29)))*10 -> 1100 | D30: 94322400 | E30: =(IF((D30-D29)<0,"0",(D30-D29)))*0.027 -> 448.2 | F30: 93804000 | G30: =(IF((F30-F29)<0,"0",(F30-F29)))*0.027 -> 367.2 | H30: 614104 | I30: =(IF((H30-H29)<0,"0",(H30-H29)))*0.027 -> 4.023 | J30: =C30+E30+G30+I30 -> 1919.423 | K30: =J30*5.86 -> 11247.819
A31: 43613 | B31: 354388 | C31: =(IF((B31-B30)<0,"0",(B31-B30)))*10 -> 1130 | D31: 94340900 | E31: =(IF((D31-D30)<0,"0",(D31-D30)))*0.027 -> 499.5 | F31: 93820850 | G31: =(IF((F31-F30)<0,"0",(F31-F30)))*0.027 -> 454.95 | H31: 614215 | I31: =(IF((H31-H30)<0,"0",(H31-H30)))*0.027 -> 2.997 | J31: =C31+E31+G31+I31 -> 2087.447 | K31: =J31*5.86 -> 12232.439
... A33: 43615 | B33: 354549 | C33: =(IF((B33-B32)<0,"0",(B33-B32)))*10 -> 910 | D33: 94378300 | E33: =(IF((D33-D32)<0,"0",(D33-D32)))*0.027 -> 467.1 | F33: 93856700 | G33: =(IF((F33-F32)<0,"0",(F33-F32)))*0.027 -> 537.84 | H33: 614657 | I33: =(IF((H33-H32)<0,"0",(H33-H32)))*0.027 -> 4.779 | J33: =C33+E33+G33+I33 -> 1919.719 | K33: =J33*5.86 -> 11249.553
A34: 43616 | B34: 354630 | C34: =(IF((B34-B33)<0,"0",(B34-B33)))*10 -> 810 | D34: 94395500 | E34: =(IF((D34-D33)<0,"0",(D34-D33)))*0.027 -> 464.4 | F34: 93872000 | G34: =(IF((F34-F33)<0,"0",(F34-F33)))*0.027 -> 413.1 | H34: 614813 | I34: =(IF((H34-H33)<0,"0",(H34-H33)))*0.027 -> 4.212
A35: Total | C35: =SUM(C4:C34) -> 29700 | E35: =SUM(E4:E34) -> 16164.9 | G35: =SUM(G4:G34) -> 13049.1 | I35: =SUM(I4:I34) -> 150.606 | J35: =SUM(J4:J31) -> 53773.21 | K35: =SUM(K4:K31) -> 315111.01

Sheet ELECT.
A1: Feeders and transformers Electrity cons. MAY 2019
A2: Day | B2: Rooms Sold | C2: New Chillers | D2: Cons | E2: F-1 | F2: Cons. | G2: F-2 | H2: Cons. | I2: Total | J2: T-1 | K2: Cons. | L2: T-2 | M2: Cons. | N2: T-3 | O2: Cons. | P2: T-4 | Q2: Cons. | R2: T-5 | S2: Cons. | T2: T-6 | U2: Cons. | V2: T-7 | W2: Cons. | X2: Total | Y2: Diff | Z2: Daily Money Value | AA2: MTD Total Money
A3: Last | B3: 298 | C3: 15466 | E3: 16655010 | F3: 0 | G3: 45047485 | H3: 0 | I3: 0 | J3: 3869359 | K3: 0 | L3: 4076121 | M3: 0 | N3: 2537554 | O3: 0 | P3: 5174422 | Q3: 0 | R3: 10188644 | S3: 0 | T3: 0 | V3: 6731805 | W3: 0
A4: 43586 | B4: 237 | C4: 15471 | D4: =IF((C4-C3)<0,"0",(C4-C3))*160 -> 800 | E4: 16668544 | F4: =IF((E4-E3)<0,"0",(E4-E3)) -> 13534 | G4: 45107190 | H4: =IF((G4-G3)<0,"0",(G4-G3)) -> 59705 | I4: =F4+H4 -> 73239 | J4: 3874763 | K4: =IF((J4-J3)<0,"0",(J4-J3)) -> 5404 | L4: 4080929 | M4: =IF((L4-L3)<0,"0",(L4-L3)) -> 4808 | N4: 2541816 | O4: =(IF((N4-N3)<0,"0",(N4-N3)))*2 -> 8524 | P4: 5189581 | Q4: =IF((P4-P3)<0,"0",(P4-P3)) -> 15159 | R4: 10199811 | S4: =IF((R4-R3)<0,"0",(R4-R3)) -> 11167 | T4: 0 | V4: 6745013 | W4: =IF((V4-V3)<0,"0",(V4-V3)) -> 13208 | X4: =K4+M4+O4+Q4+S4+U4+W4 -> 58270 | Y4: =I4-X4 -> 14969 | Z4: =(0.93352*(W4+S4)+0.5568*(Q4+O4))*0.26 -> 9344.7235 | AA4: =SUM(Z1:Z4) -> 9344.7235
A5: 43587 | B5: 241 | C5: 15475 | D5: =IF((C5-C4)<0,"0",(C5-C4))*160 -> 640 | E5: 16676122 | F5: =IF((E5-E4)<0,"0",(E5-E4)) -> 7578 | G5: 45140233 | H5: =IF((G5-G4)<0,"0",(G5-G4)) -> 33043 | I5: =F5+H5 -> 40621 | J5: 3877630 | K5: =IF((J5-J4)<0,"0",(J5-J4)) -> 2867 | L5: 4083747 | M5: =IF((L5-L4)<0,"0",(L5-L4)) -> 2818 | N5: 2544161 | O5: =(IF((N5-N4)<0,"0",(N5-N4)))*2 -> 4690 | P5: 5198636 | Q5: =IF((P5-P4)<0,"0",(P5-P4)) -> 9055 | R5: 10206065 | S5: =IF((R5-R4)<0,"0",(R5-R4)) -> 6254 | T5: 0 | V5: 6752144 | W5: =IF((V5-V4)<0,"0",(V5-V4)) -> 7131 | X5: =K5+M5+O5+Q5+S5+U5+W5 -> 32815 | Y5: =I5-X5 -> 7806 | Z5: =(0.93352*(W5+S5)+0.5568*(Q5+O5))*0.26 -> 5238.5791 | AA5: =SUM(Z2:Z5) -> 14583.303
A6: 43588 | B6: 244 | C6: 15480 | D6: =IF((C6-C5)<0,"0",(C6-C5))*160 -> 800 | E6: 16693670 | F6: =IF((E6-E5)<0,"0",(E6-E5)) -> 17548 | G6: 45218159 | H6: =IF((G6-G5)<0,"0",(G6-G5)) -> 77926 | I6: =F6+H6 -> 95474 | J6: 3883862 | K6: =IF((J6-J5)<0,"0",(J6-J5)) -> 6232 | L6: 4090436 | M6: =IF((L6-L5)<0,"0",(L6-L5)) -> 6689 | N6: 2549487 | O6: =(IF((N6-N5)<0,"0",(N6-N5)))*2 -> 10652 | P6: 5217626 | Q6: =IF((P6-P5)<0,"0",(P6-P5)) -> 18990 | R6: 10220758 | S6: =IF((R6-R5)<0,"0",(R6-R5)) -> 14693 | T6: 0 | V6: 6770272 | W6: =IF((V6-V5)<0,"0",(V6-V5)) -> 18128 | X6: =K6+M6+O6+Q6+S6+U6+W6 -> 75384 | Y6: =I6-X6 -> 20090 | Z6: =(0.93352*(W6+S6)+0.5568*(Q6+O6))*0.26 -> 12257.369 | AA6: =SUM(Z3:Z6) -> 26840.671
A7: 43589 | B7: 204 | C7: 15482 | D7: =IF((C7-C6)<0,"0",(C7-C6))*160 -> 320 | E7: 16705273 | F7: =IF((E7-E6)<0,"0",(E7-E6)) -> 11603 | G7: 45270528 | H7: =IF((G7-G6)<0,"0",(G7-G6)) -> 52369 | I7: =F7+H7 -> 63972 | J7: 3888423 | K7: =IF((J7-J6)<0,"0",(J7-J6)) -> 4561 | L7: 4094799 | M7: =IF((L7-L6)<0,"0",(L7-L6)) -> 4363 | N7: 2553022 | O7: =(IF((N7-N6)<0,"0",(N7-N6)))*2 -> 7070 | P7: 5228798 | Q7: =IF((P7-P6)<0,"0",(P7-P6)) -> 11172 | R7: 10231283 | S7: =IF((R7-R6)<0,"0",(R7-R6)) -> 10525 | T7: 0 | V7: 6782741 | W7: =IF((V7-V6)<0,"0",(V7-V6)) -> 12469 | X7: =K7+M7+O7+Q7+S7+U7+W7 -> 50160 | Y7: =I7-X7 -> 13812 | Z7: =(0.93352*(W7+S7)+0.5568*(Q7+O7))*0.26 -> 8221.8512 | AA7: =SUM(Z4:Z7) -> 35062.522
A8: 43590 | B8: 131 | C8: 15483 | D8: =IF((C8-C7)<0,"0",(C8-C7))*160 -> 160 | E8: 16718561 | F8: =IF((E8-E7)<0,"0",(E8-E7)) -> 13288 | G8: 45328931 | H8: =IF((G8-G7)<0,"0",(G8-G7)) -> 58403 | I8: =F8+H8 -> 71691 | J8: 3894243 | K8: =IF((J8-J7)<0,"0",(J8-J7)) -> 5820 | L8: 4099748 | M8: =IF((L8-L7)<0,"0",(L8-L7)) -> 4949 | N8: 2557091 | O8: =(IF((N8-N7)<0,"0",(N8-N7)))*2 -> 8138 | P8: 5242496 | Q8: =IF((P8-P7)<0,"0",(P8-P7)) -> 13698 | R8: 10242114 | S8: =IF((R8-R7)<0,"0",(R8-R7)) -> 10831 | T8: 0 | V8: 6796053 | W8: =IF((V8-V7)<0,"0",(V8-V7)) -> 13312 | X8: =K8+M8+O8+Q8+S8+U8+W8 -> 56748 | Y8: =I8-X8 -> 14943 | Z8: =(0.93352*(W8+S8)+0.5568*(Q8+O8))*0.26 -> 9021.0271 | AA8: =SUM(Z5:Z8) -> 34738.826
A9: 43591 | B9: 115 | C9: 15485 | D9: =IF((C9-C8)<0,"0",(C9-C8))*160 -> 320 | E9: 16728045 | F9: =IF((E9-E8)<0,"0",(E9-E8)) -> 9484 | G9: 45369432 | H9: =IF((G9-G8)<0,"0",(G9-G8)) -> 40501 | I9: =F9+H9 -> 49985 | J9: 3899118 | K9: =IF((J9-J8)<0,"0",(J9-J8)) -> 4875 | L9: 4102917 | M9: =IF((L9-L8)<0,"0",(L9-L8)) -> 3169 | N9: 2560203 | O9: =(IF((N9-N8)<0,"0",(N9-N8)))*2 -> 6224 | P9: 5251417 | Q9: =IF((P9-P8)<0,"0",(P9-P8)) -> 8921 | R9: 10249669 | S9: =IF((R9-R8)<0,"0",(R9-R8)) -> 7555 | T9: 0 | V9: 6805239 | W9: =IF((V9-V8)<0,"0",(V9-V8)) -> 9186 | X9: =K9+M9+O9+Q9+S9+U9+W9 -> 39930 | Y9: =I9-X9 -> 10055 | Z9: =(0.93352*(W9+S9)+0.5568*(Q9+O9))*0.26 -> 6255.8065 | AA9: =SUM(Z6:Z9) -> 35756.053
A10: 43592 | B10: 107 | C10: 15489 | D10: =IF((C10-C9)<0,"0",(C10-C9))*160 -> 640 | E10: 16748207 | F10: =IF((E10-E9)<0,"0",(E10-E9)) -> 20162 | G10: 45440376 | H10: =IF((G10-G9)<0,"0",(G10-G9)) -> 70944 | I10: =F10+H10 -> 91106 | J10: 3907793 | K10: =IF((J10-J9)<0,"0",(J10-J9)) -> 8675 | L10: 4110285 | M10: =IF((L10-L9)<0,"0",(L10-L9)) -> 7368 | N10: 2566488 | O10: =(IF((N10-N9)<0,"0",(N10-N9)))*2 -> 12570 | P10: 5265956 | Q10: =IF((P10-P9)<0,"0",(P10-P9)) -> 14539 | R10: 10262794 | S10: =IF((R10-R9)<0,"0",(R10-R9)) -> 13125 | T10: 0 | V10: 6821915 | W10: =IF((V10-V9)<0,"0",(V10-V9)) -> 16676 | X10: =K10+M10+O10+Q10+S10+U10+W10 -> 72953 | Y10: =I10-X10 -> 18153 | Z10: =(0.93352*(W10+S10)+0.5568*(Q10+O10))*0.26 -> 11157.671 | AA10: =SUM(Z7:Z10) -> 34656.356
A11: 43593 | B11: 85 | C11: 15501 | D11: =IF((C11-C10)<0,"0",(C11-C10))*160 -> 1920 | E11: 16760713 | F11: =IF((E11-E10)<0,"0",(E11-E10)) -> 12506 | G11: 45494762 | H11: =IF((G11-G10)<0,"0",(G11-G10)) -> 54386 | I11: =F11+H11 -> 66892 | J11: 3914278 | K11: =IF((J11-J10)<0,"0",(J11-J10)) -> 6485 | L11: 4114769 | M11: =IF((L11-L10)<0,"0",(L11-L10)) -> 4484 | N11: 2570414 | O11: =(IF((N11-N10)<0,"0",(N11-N10)))*2 -> 7852 | P11: 5276570 | Q11: =IF((P11-P10)<0,"0",(P11-P10)) -> 10614 | R11: 10272905 | S11: =IF((R11-R10)<0,"0",(R11-R10)) -> 10111 | T11: 0 | V11: 6835005 | W11: =IF((V11-V10)<0,"0",(V11-V10)) -> 13090 | X11: =K11+M11+O11+Q11+S11+U11+W11 -> 52636 | Y11: =I11-X11 -> 14256 | Z11: =(0.93352*(W11+S11)+0.5568*(Q11+O11))*0.26 -> 8304.5212 | AA11: =SUM(Z8:Z11) -> 34739.026
A12: 43594 | B12: 76 | C12: 15507 | D12: =IF((C12-C11)<0,"0",(C12-C11))*160 -> 960 | E12: 16770066 | F12: =IF((E12-E11)<0,"0",(E12-E11)) -> 9353 | G12: 45528135 | H12: =IF((G12-G11)<0,"0",(G12-G11)) -> 33373 | I12: =F12+H12 -> 42726 | J12: 3918836 | K12: =IF((J12-J11)<0,"0",(J12-J11)) -> 4558 | L12: 4117823 | M12: =IF((L12-L11)<0,"0",(L12-L11)) -> 3054 | N12: 2573504 | O12: =(IF((N12-N11)<0,"0",(N12-N11)))*2 -> 6180 | P12: 5279000 | Q12: =IF((P12-P11)<0,"0",(P12-P11)) -> 2430 | R12: 10279993 | S12: =IF((R12-R11)<0,"0",(R12-R11)) -> 7088 | T12: 0 | V12: 6844336 | W12: =IF((V12-V11)<0,"0",(V12-V11)) -> 9331 | X12: =K12+M12+O12+Q12+S12+U12+W12 -> 32641 | Y12: =I12-X12 -> 10085 | Z12: =(0.93352*(W12+S12)+0.5568*(Q12+O12))*0.26 -> 5231.5933 | AA12: =SUM(Z9:Z12) -> 30949.593
A13: 43595 | B13: 133 | C13: 15511 | D13: =IF((C13-C12)<0,"0",(C13-C12))*160 -> 640 | E13: 16787077 | F13: =IF((E13-E12)<0,"0",(E13-E12)) -> 17011 | G13: 45590585 | H13: =IF((G13-G12)<0,"0",(G13-G12)) -> 62450 | I13: =F13+H13 -> 79461 | J13: 3926856 | K13: =IF((J13-J12)<0,"0",(J13-J12)) -> 8020 | L13: 4123408 | M13: =IF((L13-L12)<0,"0",(L13-L12)) -> 5585 | N13: 2579096 | O13: =(IF((N13-N12)<0,"0",(N13-N12)))*2 -> 11184 | P13: 5283384 | Q13: =IF((P13-P12)<0,"0",(P13-P12)) -> 4384 | R13: 10293433 | S13: =IF((R13-R12)<0,"0",(R13-R12)) -> 13440 | T13: 0 | V13: 6861982 | W13: =IF((V13-V12)<0,"0",(V13-V12)) -> 17646 | X13: =K13+M13+O13+Q13+S13+U13+W13 -> 60259 | Y13: =I13-X13 -> 19202 | Z13: =(0.93352*(W13+S13)+0.5568*(Q13+O13))*0.26 -> 9798.7929 | AA13: =SUM(Z10:Z13) -> 34492.579
A14: 43596 | B14: 142 | C14: 15515 | D14: =IF((C14-C13)<0,"0",(C14-C13))*160 -> 640 | E14: 16798865 | F14: =IF((E14-E13)<0,"0",(E14-E13)) -> 11788 | G14: 45636346 | H14: =IF((G14-G13)<0,"0",(G14-G13)) -> 45761 | I14: =F14+H14 -> 57549 | J14: 3932575 | K14: =IF((J14-J13)<0,"0",(J14-J13)) -> 5719 | L14: 4127187 | M14: =IF((L14-L13)<0,"0",(L14-L13)) -> 3779 | N14: 2582891 | O14: =(IF((N14-N13)<0,"0",(N14-N13)))*2 -> 7590 | P14: 5290032 | Q14: =IF((P14-P13)<0,"0",(P14-P13)) -> 6648 | R14: 10302513 | S14: =IF((R14-R13)<0,"0",(R14-R13)) -> 9080 | T14: 0 | V14: 6863963 | W14: =IF((V14-V13)<0,"0",(V14-V13)) -> 1981 | X14: =K14+M14+O14+Q14+S14+U14+W14 -> 34797 | Y14: =I14-X14 -> 22752 | Z14: =(0.93352*(W14+S14)+0.5568*(Q14+O14))*0.26 -> 4745.8796 | AA14: =SUM(Z11:Z14) -> 28080.787
A15: 43597 | B15: 163 | C15: 15519 | D15: =IF((C15-C14)<0,"0",(C15-C14))*160 -> 640 | E15: 16811942 | F15: =IF((E15-E14)<0,"0",(E15-E14)) -> 13077 | G15: 45694562 | H15: =IF((G15-G14)<0,"0",(G15-G14)) -> 58216 | I15: =F15+H15 -> 71293 | J15: 3938741 | K15: =IF((J15-J14)<0,"0",(J15-J14)) -> 6166 | L15: 4131848 | M15: =IF((L15-L14)<0,"0",(L15-L14)) -> 4661 | N15: 2587001 | O15: =(IF((N15-N14)<0,"0",(N15-N14)))*2 -> 8220 | P15: 5302445 | Q15: =IF((P15-P14)<0,"0",(P15-P14)) -> 12413 | R15: 10313151 | S15: =IF((R15-R14)<0,"0",(R15-R14)) -> 10638 | T15: 0 | V15: 6887843 | W15: =IF((V15-V14)<0,"0",(V15-V14)) -> 23880 | X15: =K15+M15+O15+Q15+S15+U15+W15 -> 65978 | Y15: =I15-X15 -> 5315 | Z15: =(0.93352*(W15+S15)+0.5568*(Q15+O15))*0.26 -> 11365.041 | AA15: =SUM(Z12:Z15) -> 31141.307
... A34: 43616 | B34: 82 | C34: 15608 | D34: =IF((C34-C33)<0,"0",(C34-C33))*160 -> 160 | E34: 17084485 | F34: =IF((E34-E33)<0,"0",(E34-E33)) -> 13442 | G34: 46768437 | H34: =IF((G34-G33)<0,"0",(G34-G33)) -> 18562 | I34: =F34+H34 -> 32004 | J34: 4057002 | K34: =IF((J34-J33)<0,"0",(J34-J33)) -> 10794 | L34: 4226976 | M34: =IF((L34-L33)<0,"0",(L34-L33)) -> 2726 | N34: 2674034 | O34: =(IF((N34-N33)<0,"0",(N34-N33)))*2 -> 8358 | P34: 5562756 | Q34: =IF((P34-P33)<0,"0",(P34-P33)) -> 20634 | R34: 10513383 | S34: =IF((R34-R33)<0,"0",(R34-R33)) -> 13863 | T34: 0 | V34: 7125204 | W34: =IF((V34-V33)<0,"0",(V34-V33)) -> 15586 | X34: =K34+M34+O34+Q34+S34+U34+W34 -> 71961 | Y34: =I34-X34 -> -39957 | Z34: =(0.93352*(W34+S34)+0.5568*(Q34+O34))*0.26 -> 11344.834 | AA34: =SUM(Z31:Z34) -> 32345.519
A35: Total | F35: =SUM(F3:F34) -> 429475 | H35: =SUM(H3:H34) -> 1720952 | I35: =F35+H35 -> 2150427 | K35: =SUM(K3:K34) -> 187643 | M35: =SUM(M3:M34) -> 150855 | O35: =SUM(O3:O34) -> 272960 | Q35: =SUM(Q3:Q34) -> 388334 | S35: =SUM(S3:T34) -> 324739 | W35: =SUM(W3:W34) -> 393399 | X35: =SUM(X4:X31) -> 1566063 | Y35: =SUM(Y4:Y31) -> 398321 | Z35: =SUM(Z5:Z31) -> 237645.77

Sheet Gas
A1: Gas Con. MAY 2019
A2: Day | B2: Main | C2: Cons.
A3: Last | B3: 15455257
A4: 43586 | B4: 15458786 | C4: =IF((B4-B3)<0,"0",(B4-B3)) -> 3529
A5: 43587 | B5: 15462059 | C5: =IF((B5-B4)<0,"0",(B5-B4)) -> 3273
A6: 43588 | B6: 15465400 | C6: =IF((B6-B5)<0,"0",(B6-B5)) -> 3341
A7: 43589 | B7: 15468852 | C7: =IF((B7-B6)<0,"0",(B7-B6)) -> 3452
A8: 43590 | B8: 15472256 | C8: =IF((B8-B7)<0,"0",(B8-B7)) -> 3404
A9: 43591 | B9: 15475584 | C9: =IF((B9-B8)<0,"0",(B9-B8)) -> 3328
A10: 43592 | B10: 15478699 | C10: =IF((B10-B9)<0,"0",(B10-B9)) -> 3115
A11: 43593 | B11: 15481915 | C11: =IF((B11-B10)<0,"0",(B11-B10)) -> 3216
A12: 43594 | B12: 15485175 | C12: =IF((B12-B11)<0,"0",(B12-B11)) -> 3260
A13: 43595 | B13: 15487930 | C13: =IF((B13-B12)<0,"0",(B13-B12)) -> 2755
A14: 43596 | B14: 15489098 | C14: =IF((B14-B13)<0,"0",(B14-B13)) -> 1168
A15: 43597 | B15: 15491983 | C15: =IF((B15-B14)<0,"0",(B15-B14)) -> 2885
... A34: 43616 | B34: 15543823 | C34: =IF((B34-B33)<0,"0",(B34-B33)) -> 3211
A35: Total | C35: =SUM(C4:C34) -> 88566

Sheet BTU
A1: Day | B1: Hotel | C1: Cons. Mwh | D1: Cost (LE) | E1: B.S | F1: Cons. Mwh | G1: Cost (LE) | H1: LS | I1: Cons.Mwh | J1: . | K1: AHU # 25 | L1: Cons.Mwh | M1: Cost (LE) | N1: Mall | O1: Cons.Mwh | P1: Cost (LE) | Q1: AHU # 9 | R1: Cons.Mwh | S1: Cost (LE) | T1: Total Cons. | U1: Total Cost (LE)
A2: Last | B2: 14254.981 | D2: =C2*1.9*1000 -> 0 | E2: 2151.183 | G2: =F2*1.9*1000 -> 0 | H2: 857.576 | J2: =I2*1.9*1000 -> 0 | K2: 12719.78 | M2: =L2*1.9*1000 -> 0 | N2: 1784.885 | P2: =O2*1.9*1000 -> 0 | Q2: 3862.89 | S2: 0 | T2: =C2+F2+I2+L2+O2+R2 -> 0
A3: 43586 | B3: 14267.02 | C3: =IF((B3-B2)<0,"0",(B3-B2)) -> 12.039 | D3: =C3*1.9*1000 -> 22874.1 | E3: 2152.611 | F3: =IF((E3-E2)<0,"0",(E3-E2)) -> 1.428 | G3: =F3*1.9*1000 -> 2713.2 | H3: 857.576 | I3: =IF((H3-H2)<0,"0",(H3-H2)) -> 0 | J3: =I3*1.9*1000 -> 0 | K3: 12721.07 | L3: =IF((K3-K2)<0,"0",(K3-K2)) -> 1.29 | M3: =L3*1.9*1000 -> 2451 | N3: 1786.389 | O3: =IF((N3-N2)<0,"0",(N3-N2)) -> 1.504 | P3: =O3*1.9*1000 -> 2857.6 | Q3: 3864.79 | R3: =IF((Q3-Q2)<0,"0",(Q3-Q2)) -> 1.9 | S3: =R3*1.9*1000 -> 3610 | T3: =C3+F3+I3+L3+O3+R3 -> 18.161 | U3: =T3*1.9*1000 -> 34505.9
A4: 43587 | B4: 14273.611 | C4: =IF((B4-B3)<0,"0",(B4-B3)) -> 6.591 | D4: =C4*1.9*1000 -> 12522.9 | E4: 2154.588 | F4: =IF((E4-E3)<0,"0",(E4-E3)) -> 1.977 | G4: =F4*1.9*1000 -> 3756.3 | H4: 857.576 | I4: =IF((H4-H3)<0,"0",(H4-H3)) -> 0 | J4: =I4*1.9*1000 -> 0 | K4: 12722.11 | L4: =IF((K4-K3)<0,"0",(K4-K3)) -> 1.04 | M4: =L4*1.9*1000 -> 1976 | N4: 1787.466 | O4: =IF((N4-N3)<0,"0",(N4-N3)) -> 1.077 | P4: =O4*1.9*1000 -> 2046.3 | Q4: 3866.39 | R4: =IF((Q4-Q3)<0,"0",(Q4-Q3)) -> 1.6 | S4: =R4*1.9*1000 -> 3040 | T4: =C4+F4+I4+L4+O4+R4 -> 12.285 | U4: =T4*1.9*1000 -> 23341.5
A5: 43588 | B5: 14285.068 | C5: =IF((B5-B4)<0,"0",(B5-B4)) -> 11.457 | D5: =C5*1.9*1000 -> 21768.3 | E5: 2156.165 | F5: =IF((E5-E4)<0,"0",(E5-E4)) -> 1.577 | G5: =F5*1.9*1000 -> 2996.3 | H5: 857.576 | I5: =IF((H5-H4)<0,"0",(H5-H4)) -> 0 | J5: =I5*1.9*1000 -> 0 | K5: 12723 | L5: =IF((K5-K4)<0,"0",(K5-K4)) -> 0.89 | M5: =L5*1.9*1000 -> 1691 | N5: 1789.572 | O5: =IF((N5-N4)<0,"0",(N5-N4)) -> 2.106 | P5: =O5*1.9*1000 -> 4001.4 | Q5: 3868.32 | R5: =IF((Q5-Q4)<0,"0",(Q5-Q4)) -> 1.93 | S5: =R5*1.9*1000 -> 3667 | T5: =C5+F5+I5+L5+O5+R5 -> 17.96 | U5: =T5*1.9*1000 -> 34124
A6: 43589 | B6: 14292.679 | C6: =IF((B6-B5)<0,"0",(B6-B5)) -> 7.611 | D6: =C6*1.9*1000 -> 14460.9 | E6: 2157.524 | F6: =IF((E6-E5)<0,"0",(E6-E5)) -> 1.359 | G6: =F6*1.9*1000 -> 2582.1 | H6: 857.576 | I6: =IF((H6-H5)<0,"0",(H6-H5)) -> 0 | J6: =I6*1.9*1000 -> 0 | K6: 12724.5 | L6: =IF((K6-K5)<0,"0",(K6-K5)) -> 1.5 | M6: =L6*1.9*1000 -> 2850 | N6: 1791.15 | O6: =IF((N6-N5)<0,"0",(N6-N5)) -> 1.578 | P6: =O6*1.9*1000 -> 2998.2 | Q6: 3869.98 | R6: =IF((Q6-Q5)<0,"0",(Q6-Q5)) -> 1.66 | S6: =R6*1.9*1000 -> 3154 | T6: =C6+F6+I6+L6+O6+R6 -> 13.708 | U6: =T6*1.9*1000 -> 26045.2
A7: 43590 | B7: 14300.576 | C7: =IF((B7-B6)<0,"0",(B7-B6)) -> 7.897 | D7: =C7*1.9*1000 -> 15004.3 | E7: 2160.25 | F7: =IF((E7-E6)<0,"0",(E7-E6)) -> 2.726 | G7: =F7*1.9*1000 -> 5179.4 | H7: 857.576 | I7: =IF((H7-H6)<0,"0",(H7-H6)) -> 0 | J7: =I7*1.9*1000 -> 0 | K7: 12725.87 | L7: =IF((K7-K6)<0,"0",(K7-K6)) -> 1.37 | M7: =L7*1.9*1000 -> 2603 | N7: 1792.81 | O7: =IF((N7-N6)<0,"0",(N7-N6)) -> 1.66 | P7: =O7*1.9*1000 -> 3154 | Q7: 3871.46 | R7: =IF((Q7-Q6)<0,"0",(Q7-Q6)) -> 1.48 | S7: =R7*1.9*1000 -> 2812 | T7: =C7+F7+I7+L7+O7+R7 -> 15.133 | U7: =T7*1.9*1000 -> 28752.7
A8: 43591 | B8: 14308.494 | C8: =IF((B8-B7)<0,"0",(B8-B7)) -> 7.918 | D8: =C8*1.9*1000 -> 15044.2 | E8: 2162.784 | F8: =IF((E8-E7)<0,"0",(E8-E7)) -> 2.534 | G8: =F8*1.9*1000 -> 4814.6 | H8: 857.576 | I8: =IF((H8-H7)<0,"0",(H8-H7)) -> 0 | J8: =I8*1.9*1000 -> 0 | K8: 12727.19 | L8: =IF((K8-K7)<0,"0",(K8-K7)) -> 1.32 | M8: =L8*1.9*1000 -> 2508 | N8: 1793.982 | O8: =IF((N8-N7)<0,"0",(N8-N7)) -> 1.172 | P8: =O8*1.9*1000 -> 2226.8 | Q8: 3872.19 | R8: =IF((Q8-Q7)<0,"0",(Q8-Q7)) -> 0.73 | S8: =R8*1.9*1000 -> 1387 | T8: =C8+F8+I8+L8+O8+R8 -> 13.674 | U8: =T8*1.9*1000 -> 25980.6
A9: 43592 | B9: 14314.545 | C9: =IF((B9-B8)<0,"0",(B9-B8)) -> 6.051 | D9: =C9*1.9*1000 -> 11496.9 | E9: 2164.668 | F9: =IF((E9-E8)<0,"0",(E9-E8)) -> 1.884 | G9: =F9*1.9*1000 -> 3579.6 | H9: 857.576 | I9: =IF((H9-H8)<0,"0",(H9-H8)) -> 0 | J9: =I9*1.9*1000 -> 0 | K9: 12728.42 | L9: =IF((K9-K8)<0,"0",(K9-K8)) -> 1.23 | M9: =L9*1.9*1000 -> 2337 | N9: 1795.115 | O9: =IF((N9-N8)<0,"0",(N9-N8)) -> 1.133 | P9: =O9*1.9*1000 -> 2152.7 | Q9: 3873.39 | R9: =IF((Q9-Q8)<0,"0",(Q9-Q8)) -> 1.2 | S9: =R9*1.9*1000 -> 2280 | T9: =C9+F9+I9+L9+O9+R9 -> 11.498 | U9: =T9*1.9*1000 -> 21846.2
A10: 43593 | B10: 14321.979 | C10: =IF((B10-B9)<0,"0",(B10-B9)) -> 7.434 | D10: =C10*1.9*1000 -> 14124.6 | E10: 2166.852 | F10: =IF((E10-E9)<0,"0",(E10-E9)) -> 2.184 | G10: =F10*1.9*1000 -> 4149.6 | H10: 857.576 | I10: =IF((H10-H9)<0,"0",(H10-H9)) -> 0 | J10: =I10*1.9*1000 -> 0 | K10: 12729.65 | L10: =IF((K10-K9)<0,"0",(K10-K9)) -> 1.23 | M10: =L10*1.9*1000 -> 2337 | N10: 1796.291 | O10: =IF((N10-N9)<0,"0",(N10-N9)) -> 1.176 | P10: =O10*1.9*1000 -> 2234.4 | Q10: 3876.16 | R10: =IF((Q10-Q9)<0,"0",(Q10-Q9)) -> 2.77 | S10: =R10*1.9*1000 -> 5263 | T10: =C10+F10+I10+L10+O10+R10 -> 14.794 | U10: =T10*1.9*1000 -> 28108.6
A11: 43594 | B11: 14328.979 | C11: =IF((B11-B10)<0,"0",(B11-B10)) -> 7 | D11: =C11*1.9*1000 -> 13300 | E11: 2168.26 | F11: =IF((E11-E10)<0,"0",(E11-E10)) -> 1.408 | G11: =F11*1.9*1000 -> 2675.2 | H11: 857.576 | I11: =IF((H11-H10)<0,"0",(H11-H10)) -> 0 | J11: =I11*1.9*1000 -> 0 | K11: 12730.71 | L11: =IF((K11-K10)<0,"0",(K11-K10)) -> 1.06 | M11: =L11*1.9*1000 -> 2014 | N11: 1797.404 | O11: =IF((N11-N10)<0,"0",(N11-N10)) -> 1.113 | P11: =O11*1.9*1000 -> 2114.7 | Q11: 3877.09 | R11: =IF((Q11-Q10)<0,"0",(Q11-Q10)) -> 0.93 | S11: =R11*1.9*1000 -> 1767 | T11: =C11+F11+I11+L11+O11+R11 -> 11.511 | U11: =T11*1.9*1000 -> 21870.9
A12: 43595 | B12: 14335.345 | C12: =IF((B12-B11)<0,"0",(B12-B11)) -> 6.366 | D12: =C12*1.9*1000 -> 12095.4 | E12: 2169.237 | F12: =IF((E12-E11)<0,"0",(E12-E11)) -> 0.977 | G12: =F12*1.9*1000 -> 1856.3 | H12: 857.576 | I12: =IF((H12-H11)<0,"0",(H12-H11)) -> 0 | J12: =I12*1.9*1000 -> 0 | K12: 12731.57 | L12: =IF((K12-K11)<0,"0",(K12-K11)) -> 0.86 | M12: =L12*1.9*1000 -> 1634 | N12: 1798.62 | O12: =IF((N12-N11)<0,"0",(N12-N11)) -> 1.216 | P12: =O12*1.9*1000 -> 2310.4 | Q12: 3877.89 | R12: =IF((Q12-Q11)<0,"0",(Q12-Q11)) -> 0.8 | S12: =R12*1.9*1000 -> 1520 | T12: =C12+F12+I12+L12+O12+R12 -> 10.219 | U12: =T12*1.9*1000 -> 19416.1
A13: 43596 | B13: 14342.597 | C13: =IF((B13-B12)<0,"0",(B13-B12)) -> 7.252 | D13: =C13*1.9*1000 -> 13778.8 | E13: 2170.792 | F13: =IF((E13-E12)<0,"0",(E13-E12)) -> 1.555 | G13: =F13*1.9*1000 -> 2954.5 | H13: 857.577 | I13: =IF((H13-H12)<0,"0",(H13-H12)) -> 0.001 | J13: =I13*1.9*1000 -> 1.9 | K13: 12732.81 | L13: =IF((K13-K12)<0,"0",(K13-K12)) -> 1.24 | M13: =L13*1.9*1000 -> 2356 | N13: 1799.764 | O13: =IF((N13-N12)<0,"0",(N13-N12)) -> 1.144 | P13: =O13*1.9*1000 -> 2173.6 | Q13: 3879.87 | R13: =IF((Q13-Q12)<0,"0",(Q13-Q12)) -> 1.98 | S13: =R13*1.9*1000 -> 3762 | T13: =C13+F13+I13+L13+O13+R13 -> 13.172 | U13: =T13*1.9*1000 -> 25026.8
