Workbook

Sheet TOTAL
A1: Site Name | B1: Day | C1: Month | D1: Year | E1: Total Electricity Kwh | F1: Electricity Tariff ($/Kwh) | G1: Natual Gas (m3) | H1: Natural Gas $/m3 | I1: Water Utility Supply (m3) m3 | J1: Water Utility Supply (m3) $/m3 | K1: Room Nights
A2: Cairo at Nile Plaza | B2: 1 | C2: 4 | D2: 2019 | E2: =(((Submetering!O2+Submetering!P2)*0.842284+Submetering!Q2+(Submetering!M2+Submetering!N2+Submetering!Y2)*0.7362)+(Submetering!O2+Submetering!P2+Submetering!Q2)*0.1488+(Submetering!M2+Submetering!N2+Submetering!Y2)*0.1167+(Submetering!K2+Submetering!L2-Submetering!Z2-Submetering!AA2-Submetering!AB2-Submetering!AC2-Submetering!Q2)+(Submetering!M2+Submetering!N2+Submetering!Y2)*0.1139) -> 53239.056 | F2: 1.15 | G2: =Gas!C4*0.9147 -> 3610.3209 | H2: 2.25 | I2: =Submetering!AE2+Submetering!AD2+Submetering!H2 -> 716 | J2: 9.12 | K2: =ELECT.!B4 -> 330
A3: Cairo at Nile Plaza | B3: =B2+1 -> 2 | C3: 4 | D3: 2019 | E3: =(((Submetering!O3+Submetering!P3)*0.842284+Submetering!Q3+(Submetering!M3+Submetering!N3+Submetering!Y3)*0.7362)+(Submetering!O3+Submetering!P3+Submetering!Q3)*0.1488+(Submetering!M3+Submetering!N3+Submetering!Y3)*0.1167+(Submetering!K3+Submetering!L3-Submetering!Z3-Submetering!AA3-Submetering!AB3-Submetering!AC3-Submetering!Q3)+(Submetering!M3+Submetering!N3+Submetering!Y3)*0.1139) -> 52142.872 | F3: 1.15 | G3: =Gas!C5*0.9147 -> 3808.8108 | H3: 2.25 | I3: =Submetering!AE3+Submetering!AD3+Submetering!H3 -> 856 | J3: 9.12 | K3: =ELECT.!B5 -> 341
A4: Cairo at Nile Plaza | B4: =B3+1 -> 3 | C4: 4 | D4: 2019 | E4: =(((Submetering!O4+Submetering!P4)*0.842284+Submetering!Q4+(Submetering!M4+Submetering!N4+Submetering!Y4)*0.7362)+(Submetering!O4+Submetering!P4+Submetering!Q4)*0.1488+(Submetering!M4+Submetering!N4+Submetering!Y4)*0.1167+(Submetering!K4+Submetering!L4-Submetering!Z4-Submetering!AA4-Submetering!AB4-Submetering!AC4-Submetering!Q4)+(Submetering!M4+Submetering!N4+Submetering!Y4)*0.1139) -> 53841.705 | F4: 1.15 | G4: =Gas!C6*0.9147 -> 3292.92 | H4: 2.25 | I4: =Submetering!AE4+Submetering!AD4+Submetering!H4 -> 906 | J4: 9.12 | K4: =ELECT.!B6 -> 338
A5: Cairo at Nile Plaza | B5: =B4+1 -> 4 | C5: 4 | D5: 2019 | E5: =(((Submetering!O5+Submetering!P5)*0.842284+Submetering!Q5+(Submetering!M5+Submetering!N5+Submetering!Y5)*0.7362)+(Submetering!O5+Submetering!P5+Submetering!Q5)*0.1488+(Submetering!M5+Submetering!N5+Submetering!Y5)*0.1167+(Submetering!K5+Submetering!L5-Submetering!Z5-Submetering!AA5-Submetering!AB5-Submetering!AC5-Submetering!Q5)+(Submetering!M5+Submetering!N5+Submetering!Y5)*0.1139) -> 38769.761 | F5: 1.15 | G5: =Gas!C7*0.9147 -> 3388.0488 | H5: 2.25 | I5: =Submetering!AE5+Submetering!AD5+Submetering!H5 -> 1096 | J5: 9.12 | K5: =ELECT.!B7 -> 344
A6: Cairo at Nile Plaza | B6: =B5+1 -> 5 | C6: 4 | D6: 2019 | E6: =(((Submetering!O6+Submetering!P6)*0.842284+Submetering!Q6+(Submetering!M6+Submetering!N6+Submetering!Y6)*0.7362)+(Submetering!O6+Submetering!P6+Submetering!Q6)*0.1488+(Submetering!M6+Submetering!N6+Submetering!Y6)*0.1167+(Submetering!K6+Submetering!L6-Submetering!Z6-Submetering!AA6-Submetering!AB6-Submetering!AC6-Submetering!Q6)+(Submetering!M6+Submetering!N6+Submetering!Y6)*0.1139) -> 79409.591 | F6: 1.15 | G6: =Gas!C8*0.9147 -> 3446.5896 | H6: 2.25 | I6: =Submetering!AE6+Submetering!AD6+Submetering!H6 -> 686 | J6: 9.12 | K6: =ELECT.!B8 -> 365
A7: Cairo at Nile Plaza | B7: =B6+1 -> 6 | C7: 4 | D7: 2019 | E7: =(((Submetering!O7+Submetering!P7)*0.842284+Submetering!Q7+(Submetering!M7+Submetering!N7+Submetering!Y7)*0.7362)+(Submetering!O7+Submetering!P7+Submetering!Q7)*0.1488+(Submetering!M7+Submetering!N7+Submetering!Y7)*0.1167+(Submetering!K7+Submetering!L7-Submetering!Z7-Submetering!AA7-Submetering!AB7-Submetering!AC7-Submetering!Q7)+(Submetering!M7+Submetering!N7+Submetering!Y7)*0.1139) -> 39990.706 | F7: 1.15 | G7: =Gas!C9*0.9147 -> 3452.0778 | H7: 2.25 | I7: =Submetering!AE7+Submetering!AD7+Submetering!H7 -> 526 | J7: 9.12 | K7: =ELECT.!B9 -> 332
A8: Cairo at Nile Plaza | B8: =B7+1 -> 7 | C8: 4 | D8: 2019 | E8: =(((Submetering!O8+Submetering!P8)*0.842284+Submetering!Q8+(Submetering!M8+Submetering!N8+Submetering!Y8)*0.7362)+(Submetering!O8+Submetering!P8+Submetering!Q8)*0.1488+(Submetering!M8+Submetering!N8+Submetering!Y8)*0.1167+(Submetering!K8+Submetering!L8-Submetering!Z8-Submetering!AA8-Submetering!AB8-Submetering!AC8-Submetering!Q8)+(Submetering!M8+Submetering!N8+Submetering!Y8)*0.1139) -> 60281.631 | F8: 1.15 | G8: =Gas!C10*0.9147 -> 3122.7858 | H8: 2.25 | I8: =Submetering!AE8+Submetering!AD8+Submetering!H8 -> 846 | J8: 9.12 | K8: =ELECT.!B10 -> 322
A9: Cairo at Nile Plaza | B9: =B8+1 -> 8 | C9: 4 | D9: 2019 | E9: =(((Submetering!O9+Submetering!P9)*0.842284+Submetering!Q9+(Submetering!M9+Submetering!N9+Submetering!Y9)*0.7362)+(Submetering!O9+Submetering!P9+Submetering!Q9)*0.1488+(Submetering!M9+Submetering!N9+Submetering!Y9)*0.1167+(Submetering!K9+Submetering!L9-Submetering!Z9-Submetering!AA9-Submetering!AB9-Submetering!AC9-Submetering!Q9)+(Submetering!M9+Submetering!N9+Submetering!Y9)*0.1139) -> 47376.188 | F9: 1.15 | G9: =Gas!C11*0.9147 -> 3024.9129 | H9: 2.25 | I9: =Submetering!AE9+Submetering!AD9+Submetering!H9 -> 976 | J9: 9.12 | K9: =ELECT.!B11 -> 330
A10: Cairo at Nile Plaza | B10: =B9+1 -> 9 | C10: 4 | D10: 2019 | E10: =(((Submetering!O10+Submetering!P10)*0.842284+Submetering!Q10+(Submetering!M10+Submetering!N10+Submetering!Y10)*0.7362)+(Submetering!O10+Submetering!P10+Submetering!Q10)*0.1488+(Submetering!M10+Submetering!N10+Submetering!Y10)*0.1167+(Submetering!K10+Submetering!L10-Submetering!Z10-Submetering!AA10-Submetering!AB10-Submetering!AC10-Submetering!Q10)+(Submetering!M10+Submetering!N10+Submetering!Y10)*0.1139) -> 60061.159 | F10: 1.15 | G10: =Gas!C12*0.9147 -> 3190.4736 | H10: 2.25 | I10: =Submetering!AE10+Submetering!AD10+Submetering!H10 -> 766 | J10: 9.12 | K10: =ELECT.!B12 -> 320
A11: Cairo at Nile Plaza | B11: =B10+1 -> 10 | C11: 4 | D11: 2019 | E11: =(((Submetering!O11+Submetering!P11)*0.842284+Submetering!Q11+(Submetering!M11+Submetering!N11+Submetering!Y11)*0.7362)+(Submetering!O11+Submetering!P11+Submetering!Q11)*0.1488+(Submetering!M11+Submetering!N11+Submetering!Y11)*0.1167+(Submetering!K11+Submetering!L11-Submetering!Z11-Submetering!AA11-Submetering!AB11-Submetering!AC11-Submetering!Q11)+(Submetering!M11+Submetering!N11+Submetering!Y11)*0.1139) -> 49482.864 | F11: 1.15 | G11: =Gas!C13*0.9147 -> 3396.2811 | H11: 2.25 | I11: =Submetering!AE11+Submetering!AD11+Submetering!H11 -> 766 | J11: 9.12 | K11: =ELECT.!B13 -> 344
A12: Cairo at Nile Plaza | B12: =B11+1 -> 11 | C12: 4 | D12: 2019 | E12: =(((Submetering!O12+Submetering!P12)*0.842284+Submetering!Q12+(Submetering!M12+Submetering!N12+Submetering!Y12)*0.7362)+(Submetering!O12+Submetering!P12+Submetering!Q12)*0.1488+(Submetering!M12+Submetering!N12+Submetering!Y12)*0.1167+(Submetering!K12+Submetering!L12-Submetering!Z12-Submetering!AA12-Submetering!AB12-Submetering!AC12-Submetering!Q12)+(Submetering!M12+Submetering!N12+Submetering!Y12)*0.1139) -> 64468.294 | F12: 1.15 | G12: =Gas!C14*0.9147 -> 3468.5424 | H12: 2.25 | I12: =Submetering!AE12+Submetering!AD12+Submetering!H12 -> 826 | J12: 9.12 | K12: =ELECT.!B14 -> 351
A13: Cairo at Nile Plaza | B13: =B12+1 -> 12 | C13: 4 | D13: 2019 | E13: =(((Submetering!O13+Submetering!P13)*0.842284+Submetering!Q13+(Submetering!M13+Submetering!N13+Submetering!Y13)*0.7362)+(Submetering!O13+Submetering!P13+Submetering!Q13)*0.1488+(Submetering!M13+Submetering!N13+Submetering!Y13)*0.1167+(Submetering!K13+Submetering!L13-Submetering!Z13-Submetering!AA13-Submetering!AB13-Submetering!AC13-Submetering!Q13)+(Submetering!M13+Submetering!N13+Submetering!Y13)*0.1139) -> 38742.06 | F13: 1.15 | G13: =Gas!C15*0.9147 -> 3392.6223 | H13: 2.25 | I13: =Submetering!AE13+Submetering!AD13+Submetering!H13 -> 866 | J13: 9.12 | K13: =ELECT.!B15 -> 358
A14: Cairo at Nile Plaza | B14: =B13+1 -> 13 | C14: 4 | D14: 2019 | E14: =(((Submetering!O14+Submetering!P14)*0.842284+Submetering!Q14+(Submetering!M14+Submetering!N14+Submetering!Y14)*0.7362)+(Submetering!O14+Submetering!P14+Submetering!Q14)*0.1488+(Submetering!M14+Submetering!N14+Submetering!Y14)*0.1167+(Submetering!K14+Submetering!L14-Submetering!Z14-Submetering!AA14-Submetering!AB14-Submetering!AC14-Submetering!Q14)+(Submetering!M14+Submetering!N14+Submetering!Y14)*0.1139) -> 66719.475 | F14: 1.15 | G14: =Gas!C16*0.9147 -> 3230.7204 | H14: 2.25 | I14: =Submetering!AE14+Submetering!AD14+Submetering!H14 -> 946 | J14: 9.12 | K14: =ELECT.!B16 -> 340
... A31: Cairo at Nile Plaza | B31: =B30+1 -> 30 | C31: 4 | D31: 2019 | E31: =(((Submetering!O31+Submetering!P31)*0.842284+Submetering!Q31+(Submetering!M31+Submetering!N31+Submetering!Y31)*0.7362)+(Submetering!O31+Submetering!P31+Submetering!Q31)*0.1488+(Submetering!M31+Submetering!N31+Submetering!Y31)*0.1167+(Submetering!K31+Submetering!L31-Submetering!Z31-Submetering!AA31-Submetering!AB31-Submetering!AC31-Submetering!Q31)+(Submetering!M31+Submetering!N31+Submetering!Y31)*0.1139) -> 65981.515 | F31: 1.15 | G31: =Gas!C33*0.9147 -> 2681.9004 | H31: 2.25 | I31: =Submetering!AE31+Submetering!AD31+Submetering!H31 -> 896 | J31: 9.12 | K31: =ELECT.!B33 -> 298

Sheet Submetering
A1: Site Name | B1: Day | C1: Month | D1: Year | E1: Main (m3) | F1: Podium (m3) | G1: Hotel (m3) | H1: Large (m3) | I1: Feeder 1 (KWh) | J1: Feeder 2 (KWh) | K1: T1 (KWh) | L1: T2 (KWh) | M1: T3 (KWh) | N1: T4 (KWh) | O1: T5 (KWh) | P1: T7 (KWh) | Q1: New Chiller (KWh) | R1: Hotel (BTU) | S1: B.S (BTU) | T1: LS (BTU) | U1: Mall (BTU) | V1: AHU#25 (BTU) | W1: AHU#9 (BTU) | X1: Room Nights | Y1: Loss (KWH) | Z1: Mall (KWH) | AA1: Citadel (KWH) | AB1: Rotana (KWH) | AC1: CIB (KWH) | AD1: Plaza suits water consumption (M3) | AE1: Hotel water consumption (M3)
A2: Cairo at Nile Plaza | B2: 1 | C2: 4 | D2: 2019 | E2: =Water!C4 -> 910 | F2: =Water!E4 -> 550.8 | G2: =Water!G4 -> 356.4 | H2: =Water!I4 -> 4.698 | I2: =ELECT.!F4 -> 6187 | J2: =ELECT.!H4 -> 49845 | K2: =ELECT.!K4 -> 4765 | L2: =ELECT.!M4 -> 4732 | M2: =ELECT.!O4 -> 1384 | N2: =ELECT.!Q4 -> 8852 | O2: =ELECT.!S4 -> 10918 | P2: =ELECT.!W4*2 -> 24356 | Q2: =ELECT.!D4 -> 480 | R2: =BTU!C3 -> 12.505 | S2: =BTU!F3 -> 0.802 | T2: =BTU!I3 -> 0.125 | U2: =BTU!O3 -> 2.771 | V2: =BTU!L3 -> 1.89 | W2: =BTU!R3 -> 0 | X2: =ELECT.!B4 -> 330 | Y2: =I2+J2-(K2+L2+M2+N2+O2+P2) -> 1025 | Z2: ='Mall, Citadel, Rotana'!C4+'Mall, Citadel, Rotana'!E4+'Mall, Citadel, Rotana'!G4+'Mall, Citadel, Rotana'!I4 -> 1334 | AA2: ='Mall, Citadel, Rotana'!K4+'Mall, Citadel, Rotana'!M4 -> 640 | AB2: ='Mall, Citadel, Rotana'!O4 -> 3 | AC2: ='Mall, Citadel, Rotana'!Q4+'Mall, Citadel, Rotana'!S4 -> 199 | AD2: =(E2-H2-194)*0.1318 -> 93.749604 | AE2: =E2-H2-AD2-194 -> 617.5524
A3: Cairo at Nile Plaza | B3: =B2+1 -> 2 | C3: 4 | D3: 2019 | E3: =Water!C5 -> 1050 | F3: =Water!E5 -> 421.2 | G3: =Water!G5 -> 321.3 | H3: =Water!I5 -> 2.673 | I3: =ELECT.!F5 -> 6211 | J3: =ELECT.!H5 -> 48810 | K3: =ELECT.!K5 -> 4587 | L3: =ELECT.!M5 -> 4633 | M3: =ELECT.!O5 -> 1426 | N3: =ELECT.!Q5 -> 8443 | O3: =ELECT.!S5 -> 10689 | P3: =ELECT.!W5*2 -> 24076 | Q3: =ELECT.!D5 -> 640 | R3: =BTU!C4 -> 4.891 | S3: =BTU!F4 -> 1.26 | T3: =BTU!I4 -> 0.245 | U3: =BTU!O4 -> 1.219 | V3: =BTU!L4 -> 1.06 | W3: =BTU!R4 -> 0 | X3: =ELECT.!B5 -> 341 | Y3: =I3+J3-(K3+L3+M3+N3+O3+P3) -> 1167 | Z3: ='Mall, Citadel, Rotana'!C5+'Mall, Citadel, Rotana'!E5+'Mall, Citadel, Rotana'!G5+'Mall, Citadel, Rotana'!I5 -> 1315 | AA3: ='Mall, Citadel, Rotana'!K5+'Mall, Citadel, Rotana'!M5 -> 800 | AB3: ='Mall, Citadel, Rotana'!O5 -> 3 | AC3: ='Mall, Citadel, Rotana'!Q5+'Mall, Citadel, Rotana'!S5 -> 179 | AD3: =(E3-H3-194)*0.1318 -> 112.4685 | AE3: =E3-H3-AD3-194 -> 740.8585
A4: Cairo at Nile Plaza | B4: =B3+1 -> 3 | C4: 4 | D4: 2019 | E4: =Water!C6 -> 1100 | F4: =Water!E6 -> 680.4 | G4: =Water!G6 -> 531.9 | H4: =Water!I6 -> 5.697 | I4: =ELECT.!F6 -> 6436 | J4: =ELECT.!H6 -> 50506 | K4: =ELECT.!K6 -> 4598 | L4: =ELECT.!M6 -> 4829 | M4: =ELECT.!O6 -> 1464 | N4: =ELECT.!Q6 -> 9750 | O4: =ELECT.!S6 -> 10598 | P4: =ELECT.!W6*2 -> 24370 | Q4: =ELECT.!D6 -> 800 | R4: =BTU!C5 -> 5.776 | S4: =BTU!F5 -> 1.398 | T4: =BTU!I5 -> 0.052 | U4: =BTU!O5 -> 1.258 | V4: =BTU!L5 -> 0.15 | W4: =BTU!R5 -> 0 | X4: =ELECT.!B6 -> 338 | Y4: =I4+J4-(K4+L4+M4+N4+O4+P4) -> 1333 | Z4: ='Mall, Citadel, Rotana'!C6+'Mall, Citadel, Rotana'!E6+'Mall, Citadel, Rotana'!G6+'Mall, Citadel, Rotana'!I6 -> 1320 | AA4: ='Mall, Citadel, Rotana'!K6+'Mall, Citadel, Rotana'!M6 -> 960 | AB4: ='Mall, Citadel, Rotana'!O6 -> 3 | AC4: ='Mall, Citadel, Rotana'!Q6+'Mall, Citadel, Rotana'!S6 -> 208 | AD4: =(E4-H4-194)*0.1318 -> 118.65994 | AE4: =E4-H4-AD4-194 -> 781.64306
A5: Cairo at Nile Plaza | B5: =B4+1 -> 4 | C5: 4 | D5: 2019 | E5: =Water!C7 -> 1290 | F5: =Water!E7 -> 486 | G5: =Water!G7 -> 278.1 | H5: =Water!I7 -> 3.294 | I5: =ELECT.!F7 -> 8231 | J5: =ELECT.!H7 -> 33694 | K5: =ELECT.!K7 -> 3478 | L5: =ELECT.!M7 -> 3546 | M5: =ELECT.!O7 -> 4632 | N5: =ELECT.!Q7 -> 2655 | O5: =ELECT.!S7 -> 8089 | P5: =ELECT.!W7*2 -> 17666 | Q5: =ELECT.!D7 -> 800 | R5: =BTU!C6 -> 6.777 | S5: =BTU!F6 -> 1.371 | T5: =BTU!I6 -> 0.043 | U5: =BTU!O6 -> 1.664 | V5: =BTU!L6 -> 2.16 | W5: =BTU!R6 -> 0 | X5: =ELECT.!B7 -> 344 | Y5: =I5+J5-(K5+L5+M5+N5+O5+P5) -> 1859 | Z5: ='Mall, Citadel, Rotana'!C7+'Mall, Citadel, Rotana'!E7+'Mall, Citadel, Rotana'!G7+'Mall, Citadel, Rotana'!I7 -> 1485 | AA5: ='Mall, Citadel, Rotana'!K7+'Mall, Citadel, Rotana'!M7 -> 1120 | AB5: ='Mall, Citadel, Rotana'!O7 -> 3 | AC5: ='Mall, Citadel, Rotana'!Q7+'Mall, Citadel, Rotana'!S7 -> 133 | AD5: =(E5-H5-194)*0.1318 -> 144.01865 | AE5: =E5-H5-AD5-194 -> 948.68735
A6: Cairo at Nile Plaza | B6: =B5+1 -> 5 | C6: 4 | D6: 2019 | E6: =Water!C8 -> 880 | F6: =Water!E8 -> 515.7 | G6: =Water!G8 -> 540 | H6: =Water!I8 -> 6.669 | I6: =ELECT.!F8 -> 17222 | J6: =ELECT.!H8 -> 65636 | K6: =ELECT.!K8 -> 6152 | L6: =ELECT.!M8 -> 6902 | M6: =ELECT.!O8 -> 10000 | N6: =ELECT.!Q8 -> 4104 | O6: =ELECT.!S8 -> 16784 | P6: =ELECT.!W8*2 -> 37904 | Q6: =ELECT.!D8 -> 800 | R6: =BTU!C7 -> 6.236 | S6: =BTU!F7 -> 0.602 | T6: =BTU!I7 -> 0.012 | U6: =BTU!O7 -> 1.593 | V6: =BTU!L7 -> 1.14 | W6: =BTU!R7 -> 0 | X6: =ELECT.!B8 -> 365 | Y6: =I6+J6-(K6+L6+M6+N6+O6+P6) -> 1012 | Z6: ='Mall, Citadel, Rotana'!C8+'Mall, Citadel, Rotana'!E8+'Mall, Citadel, Rotana'!G8+'Mall, Citadel, Rotana'!I8 -> 1684 | AA6: ='Mall, Citadel, Rotana'!K8+'Mall, Citadel, Rotana'!M8 -> 800 | AB6: ='Mall, Citadel, Rotana'!O8 -> 5 | AC6: ='Mall, Citadel, Rotana'!Q8+'Mall, Citadel, Rotana'!S8 -> 89 | AD6: =(E6-H6-194)*0.1318 -> 89.535826 | AE6: =E6-H6-AD6-194 -> 589.79517
A7: Cairo at Nile Plaza | B7: =B6+1 -> 6 | C7: 4 | D7: 2019 | E7: =Water!C9 -> 720 | F7: =Water!E9 -> 531.9 | G7: =Water!G9 -> 434.7 | H7: =Water!I9 -> 4.05 | I7: =ELECT.!F9 -> 8885 | J7: =ELECT.!H9 -> 32978 | K7: =ELECT.!K9 -> 3382 | L7: =ELECT.!M9 -> 3866 | M7: =ELECT.!O9 -> 4926 | N7: =ELECT.!Q9 -> 2014 | O7: =ELECT.!S9 -> 8465 | P7: =ELECT.!W9*2 -> 18536 | Q7: =ELECT.!D9 -> 640 | R7: =BTU!C8 -> 6.381 | S7: =BTU!F8 -> 0.668 | T7: =BTU!I8 -> 0.042 | U7: =BTU!O8 -> 1.8 | V7: =BTU!L8 -> 1.1 | W7: =BTU!R8 -> 0 | X7: =ELECT.!B9 -> 332 | Y7: =I7+J7-(K7+L7+M7+N7+O7+P7) -> 674 | Z7: ='Mall, Citadel, Rotana'!C9+'Mall, Citadel, Rotana'!E9+'Mall, Citadel, Rotana'!G9+'Mall, Citadel, Rotana'!I9 -> 783 | AA7: ='Mall, Citadel, Rotana'!K9+'Mall, Citadel, Rotana'!M9 -> 640 | AB7: ='Mall, Citadel, Rotana'!O9 -> 2 | AC7: ='Mall, Citadel, Rotana'!Q9+'Mall, Citadel, Rotana'!S9 -> 49 | AD7: =(E7-H7-194)*0.1318 -> 68.79301 | AE7: =E7-H7-AD7-194 -> 453.15699
A8: Cairo at Nile Plaza | B8: =B7+1 -> 7 | C8: 4 | D8: 2019 | E8: =Water!C10 -> 1040 | F8: =Water!E10 -> 564.3 | G8: =Water!G10 -> 456.3 | H8: =Water!I10 -> 4.968 | I8: =ELECT.!F10 -> 14463 | J8: =ELECT.!H10 -> 48697 | K8: =ELECT.!K10 -> 4963 | L8: =ELECT.!M10 -> 5599 | M8: =ELECT.!O10 -> 8670 | N8: =ELECT.!Q10 -> 3258 | O8: =ELECT.!S10 -> 12190 | P8: =ELECT.!W10*2 -> 26924 | Q8: =ELECT.!D10 -> 800 | R8: =BTU!C9 -> 8.481 | S8: =BTU!F9 -> 2.08 | T8: =BTU!I9 -> 0 | U8: =BTU!O9 -> 1.686 | V8: =BTU!L9 -> 1.2 | W8: =BTU!R9 -> 0 | X8: =ELECT.!B10 -> 322 | Y8: =I8+J8-(K8+L8+M8+N8+O8+P8) -> 1556 | Z8: ='Mall, Citadel, Rotana'!C10+'Mall, Citadel, Rotana'!E10+'Mall, Citadel, Rotana'!G10+'Mall, Citadel, Rotana'!I10 -> 1676 | AA8: ='Mall, Citadel, Rotana'!K10+'Mall, Citadel, Rotana'!M10 -> 0 | AB8: ='Mall, Citadel, Rotana'!O10 -> 2 | AC8: ='Mall, Citadel, Rotana'!Q10+'Mall, Citadel, Rotana'!S10 -> 523 | AD8: =(E8-H8-194)*0.1318 -> 110.84802 | AE8: =E8-H8-AD8-194 -> 730.18398
A9: Cairo at Nile Plaza | B9: =B8+1 -> 8 | C9: 4 | D9: 2019 | E9: =Water!C11 -> 1170 | F9: =Water!E11 -> 653.4 | G9: =Water!G11 -> 521.1 | H9: =Water!I11 -> 4.995 | I9: =ELECT.!F11 -> 11308 | J9: =ELECT.!H11 -> 38251 | K9: =ELECT.!K11 -> 4171 | L9: =ELECT.!M11 -> 4408 | M9: =ELECT.!O11 -> 7784 | N9: =ELECT.!Q11 -> 2806 | O9: =ELECT.!S11 -> 8827 | P9: =ELECT.!W11*2 -> 21468 | Q9: =ELECT.!D11 -> 800 | R9: =BTU!C10 -> 6.336 | S9: =BTU!F10 -> 1.645 | T9: =BTU!I10 -> 0.003 | U9: =BTU!O10 -> 1.245 | V9: =BTU!L10 -> 1 | W9: =BTU!R10 -> 2.02 | X9: =ELECT.!B11 -> 330 | Y9: =I9+J9-(K9+L9+M9+N9+O9+P9) -> 95 | Z9: ='Mall, Citadel, Rotana'!C11+'Mall, Citadel, Rotana'!E11+'Mall, Citadel, Rotana'!G11+'Mall, Citadel, Rotana'!I11 -> 1139 | AA9: ='Mall, Citadel, Rotana'!K11+'Mall, Citadel, Rotana'!M11 -> 480 | AB9: ='Mall, Citadel, Rotana'!O11 -> 3 | AC9: ='Mall, Citadel, Rotana'!Q11+'Mall, Citadel, Rotana'!S11 -> 55 | AD9: =(E9-H9-194)*0.1318 -> 127.97846 | AE9: =E9-H9-AD9-194 -> 843.02654
A10: Cairo at Nile Plaza | B10: =B9+1 -> 9 | C10: 4 | D10: 2019 | E10: =Water!C12 -> 960 | F10: =Water!E12 -> 526.5 | G10: =Water!G12 -> 410.4 | H10: =Water!I12 -> 5.481 | I10: =ELECT.!F12 -> 13871 | J10: =ELECT.!H12 -> 49322 | K10: =ELECT.!K12 -> 5279 | L10: =ELECT.!M12 -> 5346 | M10: =ELECT.!O12 -> 7372 | N10: =ELECT.!Q12 -> 2564 | O10: =ELECT.!S12 -> 11638 | P10: =ELECT.!W12*2 -> 27490 | Q10: =ELECT.!D12 -> 640 | R10: =BTU!C11 -> 7.306 | S10: =BTU!F11 -> 2.151 | T10: =BTU!I11 -> 0.001 | U10: =BTU!O11 -> 1.39 | V10: =BTU!L11 -> 1.11 | W10: =BTU!R11 -> 0.16 | X10: =ELECT.!B12 -> 320 | Y10: =I10+J10-(K10+L10+M10+N10+O10+P10) -> 3504 | Z10: ='Mall, Citadel, Rotana'!C12+'Mall, Citadel, Rotana'!E12+'Mall, Citadel, Rotana'!G12+'Mall, Citadel, Rotana'!I12 -> 1299 | AA10: ='Mall, Citadel, Rotana'!K12+'Mall, Citadel, Rotana'!M12 -> 800 | AB10: ='Mall, Citadel, Rotana'!O12 -> 3 | AC10: ='Mall, Citadel, Rotana'!Q12+'Mall, Citadel, Rotana'!S12 -> 330 | AD10: =(E10-H10-194)*0.1318 -> 100.2364 | AE10: =E10-H10-AD10-194 -> 660.2826
A11: Cairo at Nile Plaza | B11: =B10+1 -> 10 | C11: 4 | D11: 2019 | E11: =Water!C13 -> 960 | F11: =Water!E13 -> 556.2 | G11: =Water!G13 -> 372.6 | H11: =Water!I13 -> 5.589 | I11: =ELECT.!F13 -> 11164 | J11: =ELECT.!H13 -> 41113 | K11: =ELECT.!K13 -> 4706 | L11: =ELECT.!M13 -> 4339 | M11: =ELECT.!O13 -> 6674 | N11: =ELECT.!Q13 -> 3962 | O11: =ELECT.!S13 -> 9723 | P11: =ELECT.!W13*2 -> 22608 | Q11: =ELECT.!D13 -> 800 | R11: =BTU!C12 -> 7.154 | S11: =BTU!F12 -> 1.714 | T11: =BTU!I12 -> 0.003 | U11: =BTU!O12 -> 1.548 | V11: =BTU!L12 -> 1.1 | W11: =BTU!R12 -> 0.18 | X11: =ELECT.!B13 -> 344 | Y11: =I11+J11-(K11+L11+M11+N11+O11+P11) -> 265 | Z11: ='Mall, Citadel, Rotana'!C13+'Mall, Citadel, Rotana'!E13+'Mall, Citadel, Rotana'!G13+'Mall, Citadel, Rotana'!I13 -> 1179 | AA11: ='Mall, Citadel, Rotana'!K13+'Mall, Citadel, Rotana'!M13 -> 800 | AB11: ='Mall, Citadel, Rotana'!O13 -> 3 | AC11: ='Mall, Citadel, Rotana'!Q13+'Mall, Citadel, Rotana'!S13 -> 281 | AD11: =(E11-H11-194)*0.1318 -> 100.22217 | AE11: =E11-H11-AD11-194 -> 660.18883
A12: Cairo at Nile Plaza | B12: =B11+1 -> 11 | C12: 4 | D12: 2019 | E12: =Water!C14 -> 1020 | F12: =Water!E14 -> 615.6 | G12: =Water!G14 -> 467.1 | H12: =Water!I14 -> 4.59 | I12: =ELECT.!F14 -> 14177 | J12: =ELECT.!H14 -> 53215 | K12: =ELECT.!K14 -> 5926 | L12: =ELECT.!M14 -> 5297 | M12: =ELECT.!O14 -> 8674 | N12: =ELECT.!Q14 -> 3972 | O12: =ELECT.!S14 -> 13105 | P12: =ELECT.!W14*2 -> 28728 | Q12: =ELECT.!D14 -> 640 | R12: =BTU!C13 -> 7.252 | S12: =BTU!F13 -> 1.816 | T12: =BTU!I13 -> 0.017 | U12: =BTU!O13 -> 1.338 | V12: =BTU!L13 -> 1.19 | W12: =BTU!R13 -> 0.23 | X12: =ELECT.!B14 -> 351 | Y12: =I12+J12-(K12+L12+M12+N12+O12+P12) -> 1690 | Z12: ='Mall, Citadel, Rotana'!C14+'Mall, Citadel, Rotana'!E14+'Mall, Citadel, Rotana'!G14+'Mall, Citadel, Rotana'!I14 -> 1337 | AA12: ='Mall, Citadel, Rotana'!K14+'Mall, Citadel, Rotana'!M14 -> 640 | AB12: ='Mall, Citadel, Rotana'!O14 -> 2 | AC12: ='Mall, Citadel, Rotana'!Q14+'Mall, Citadel, Rotana'!S14 -> 191 | AD12: =(E12-H12-194)*0.1318 -> 108.26184 | AE12: =E12-H12-AD12-194 -> 713.14816
A13: Cairo at Nile Plaza | B13: =B12+1 -> 12 | C13: 4 | D13: 2019 | E13: =Water!C15 -> 1060 | F13: =Water!E15 -> 313.2 | G13: =Water!G15 -> 480.6 | H13: =Water!I15 -> 3.132 | I13: =ELECT.!F15 -> 8679 | J13: =ELECT.!H15 -> 32424 | K13: =ELECT.!K15 -> 3161 | L13: =ELECT.!M15 -> 3146 | M13: =ELECT.!O15 -> 5440 | N13: =ELECT.!Q15 -> 2437 | O13: =ELECT.!S15 -> 8068 | P13: =ELECT.!W15*2 -> 18042 | Q13: =ELECT.!D15 -> 640 | R13: =BTU!C14 -> 7.526 | S13: =BTU!F14 -> 0.97 | T13: =BTU!I14 -> 0.233 | U13: =BTU!O14 -> 1.479 | V13: =BTU!L14 -> 1.18 | W13: =BTU!R14 -> 0.12 | X13: =ELECT.!B15 -> 358 | Y13: =I13+J13-(K13+L13+M13+N13+O13+P13) -> 809 | Z13: ='Mall, Citadel, Rotana'!C15+'Mall, Citadel, Rotana'!E15+'Mall, Citadel, Rotana'!G15+'Mall, Citadel, Rotana'!I15 -> 1310 | AA13: ='Mall, Citadel, Rotana'!K15+'Mall, Citadel, Rotana'!M15 -> 480 | AB13: ='Mall, Citadel, Rotana'!O15 -> 3 | AC13: ='Mall, Citadel, Rotana'!Q15+'Mall, Citadel, Rotana'!S15 -> 142 | AD13: =(E13-H13-194)*0.1318 -> 113.726 | AE13: =E13-H13-AD13-194 -> 749.142
A14: Cairo at Nile Plaza | B14: =B13+1 -> 13 | C14: 4 | D14: 2019 | E14: =Water!C16 -> 1140 | F14: =Water!E16 -> 772.2 | G14: =Water!G16 -> 531.9 | H14: =Water!I16 -> 3.888 | I14: =ELECT.!F16 -> 13280 | J14: =ELECT.!H16 -> 55940 | K14: =ELECT.!K16 -> 5554 | L14: =ELECT.!M16 -> 5339 | M14: =ELECT.!O16 -> 7760 | N14: =ELECT.!Q16 -> 6183 | O14: =ELECT.!S16 -> 13477 | P14: =ELECT.!W16*2 -> 29296 | Q14: =ELECT.!D16 -> 640 | R14: =BTU!C15 -> 8.047 | S14: =BTU!F15 -> 0.743 | T14: =BTU!I15 -> 0.654 | U14: =BTU!O15 -> 1.351 | V14: =BTU!L15 -> 1.05 | W14: =BTU!R15 -> 0.3 | X14: =ELECT.!B16 -> 340 | Y14: =I14+J14-(K14+L14+M14+N14+O14+P14) -> 1611 | Z14: ='Mall, Citadel, Rotana'!C16+'Mall, Citadel, Rotana'!E16+'Mall, Citadel, Rotana'!G16+'Mall, Citadel, Rotana'!I16 -> 1052 | AA14: ='Mall, Citadel, Rotana'!K16+'Mall, Citadel, Rotana'!M16 -> 480 | AB14: ='Mall, Citadel, Rotana'!O16 -> 3 | AC14: ='Mall, Citadel, Rotana'!Q16+'Mall, Citadel, Rotana'!S16 -> 163 | AD14: =(E14-H14-194)*0.1318 -> 124.17036 | AE14: =E14-H14-AD14-194 -> 817.94164
... A31: Cairo at Nile Plaza | B31: =B30+1 -> 30 | C31: 4 | D31: 2019 | E31: =Water!C33 -> 1090 | F31: =Water!E33 -> 575.1 | G31: =Water!G33 -> 442.8 | H31: =Water!I33 -> 3.834 | I31: =ELECT.!F33 -> 12743 | J31: =ELECT.!H33 -> 56716 | K31: =ELECT.!K33 -> 6093 | L31: =ELECT.!M33 -> 4545 | M31: =ELECT.!O33 -> 8034 | N31: =ELECT.!Q33 -> 14811 | O31: =ELECT.!S33 -> 9870 | P31: =ELECT.!W33*2 -> 24652 | Q31: =ELECT.!D33 -> 800 | R31: =BTU!C32 -> 7.26 | S31: =BTU!F32 -> 2.421 | T31: =BTU!I32 -> 0 | U31: =BTU!O32 -> 1.43 | V31: =BTU!L32 -> 1.24 | W31: =BTU!R32 -> 3.78 | X31: =ELECT.!B33 -> 298 | Y31: =I31+J31-(K31+L31+M31+N31+O31+P31) -> 1454 | Z31: ='Mall, Citadel, Rotana'!C33+'Mall, Citadel, Rotana'!E33+'Mall, Citadel, Rotana'!G33+'Mall, Citadel, Rotana'!I33 -> 1436 | AA31: ='Mall, Citadel, Rotana'!K33+'Mall, Citadel, Rotana'!M33 -> 800 | AB31: ='Mall, Citadel, Rotana'!O33 -> 3 | AC31: ='Mall, Citadel, Rotana'!Q33+'Mall, Citadel, Rotana'!S33 -> 243 | AD31: =(E31-H31-194)*0.1318 -> 117.58748 | AE31: =E31-H31-AD31-194 -> 774.57852

Sheet Mall, Citadel, Rotana
A1: Mall, Citadel and Rotana readings and cons. Apr 2019
A2: Day | B2: R1 | C2: Cons | D2: R2 | E2: Cons | F2: R3 | G2: Cons | H2: R4 | I2: Cons | J2: RO1 | K2: Cons | L2: RO2 | M2: Cons | N2: ROE | O2: Cons | P2: CIB. 1 | Q2: Cons | R2: CIB. E | S2: Cons
A3: Last | B3: 41690 | D3: 37348 | F3: 17539 | H3: 214373 | J3: 303515 | L3: 22032 | N3: 168057 | P3: 977975 | R3: 55047
A4: 43556 | B4: 41695 | C4: =(B4-B3)*600/5 -> 600 | D4: 37352 | E4: =(D4-D3)*800/5 -> 640 | F4: 17543 | G4: =(F4-F3)*100/5 -> 80 | H4: 214387 | I4: =H4-H3 -> 14 | J4: 303515 | K4: =J4-J3 -> 0 | L4: 22036 | M4: =(L4-L3)*800/5 -> 640 | N4: 168060 | O4: =N4-N3 -> 3 | P4: 978174 | Q4: =P4-P3 -> 199 | R4: 55047 | S4: =R4-R3 -> 0
A5: 43557 | B5: 41701 | C5: =(B5-B4)*600/5 -> 720 | D5: 37355 | E5: =(D5-D4)*800/5 -> 480 | F5: 17548 | G5: =(F5-F4)*100/5 -> 100 | H5: 214402 | I5: =H5-H4 -> 15 | J5: 303515 | K5: =J5-J4 -> 0 | L5: 22041 | M5: =(L5-L4)*800/5 -> 800 | N5: 168063 | O5: =N5-N4 -> 3 | P5: 978353 | Q5: =P5-P4 -> 179 | R5: 55047 | S5: =R5-R4 -> 0
A6: 43558 | B6: 41707 | C6: =(B6-B5)*600/5 -> 720 | D6: 37358 | E6: =(D6-D5)*800/5 -> 480 | F6: 17553 | G6: =(F6-F5)*100/5 -> 100 | H6: 214422 | I6: =H6-H5 -> 20 | J6: 303515 | K6: =J6-J5 -> 0 | L6: 22047 | M6: =(L6-L5)*800/5 -> 960 | N6: 168066 | O6: =N6-N5 -> 3 | P6: 978561 | Q6: =P6-P5 -> 208 | R6: 55047 | S6: =R6-R5 -> 0
A7: 43559 | B7: 41713 | C7: =(B7-B6)*600/5 -> 720 | D7: 37362 | E7: =(D7-D6)*800/5 -> 640 | F7: 17559 | G7: =(F7-F6)*100/5 -> 120 | H7: 214427 | I7: =H7-H6 -> 5 | J7: 303515 | K7: =J7-J6 -> 0 | L7: 22054 | M7: =(L7-L6)*800/5 -> 1120 | N7: 168069 | O7: =N7-N6 -> 3 | P7: 978694 | Q7: =P7-P6 -> 133 | R7: 55047 | S7: =R7-R6 -> 0
A8: 43560 | B8: 41717 | C8: =(B8-B7)*600/5 -> 480 | D8: 37369 | E8: =(D8-D7)*800/5 -> 1120 | F8: 17563 | G8: =(F8-F7)*100/5 -> 80 | H8: 214431 | I8: =H8-H7 -> 4 | J8: 303515 | K8: =J8-J7 -> 0 | L8: 22059 | M8: =(L8-L7)*800/5 -> 800 | N8: 168074 | O8: =N8-N7 -> 5 | P8: 978783 | Q8: =P8-P7 -> 89 | R8: 55047 | S8: =R8-R7 -> 0
A9: 43561 | B9: 41719 | C9: =(B9-B8)*600/5 -> 240 | D9: 37372 | E9: =(D9-D8)*800/5 -> 480 | F9: 17566 | G9: =(F9-F8)*100/5 -> 60 | H9: 214434 | I9: =H9-H8 -> 3 | J9: 303515 | K9: =J9-J8 -> 0 | L9: 22063 | M9: =(L9-L8)*800/5 -> 640 | N9: 168076 | O9: =N9-N8 -> 2 | P9: 978832 | Q9: =P9-P8 -> 49 | R9: 55047 | S9: =R9-R8 -> 0
A10: 43562 | B10: 41729 | C10: =(B10-B9)*600/5 -> 1200 | D10: 37374 | E10: =(D10-D9)*800/5 -> 320 | F10: 17570 | G10: =(F10-F9)*100/5 -> 80 | H10: 214510 | I10: =H10-H9 -> 76 | J10: 303515 | K10: =J10-J9 -> 0 | L10: 22063 | M10: =(L10-L9)*800/5 -> 0 | N10: 168078 | O10: =N10-N9 -> 2 | P10: 979355 | Q10: =P10-P9 -> 523 | R10: 55047 | S10: =R10-R9 -> 0
A11: 43563 | B11: 41735 | C11: =(B11-B10)*600/5 -> 720 | D11: 37376 | E11: =(D11-D10)*800/5 -> 320 | F11: 17574 | G11: =(F11-F10)*100/5 -> 80 | H11: 214529 | I11: =H11-H10 -> 19 | J11: 303515 | K11: =J11-J10 -> 0 | L11: 22066 | M11: =(L11-L10)*800/5 -> 480 | N11: 168081 | O11: =N11-N10 -> 3 | P11: 979410 | Q11: =P11-P10 -> 55 | R11: 55047 | S11: =R11-R10 -> 0
A12: 43564 | B12: 41741 | C12: =(B12-B11)*600/5 -> 720 | D12: 37379 | E12: =(D12-D11)*800/5 -> 480 | F12: 17578 | G12: =(F12-F11)*100/5 -> 80 | H12: 214548 | I12: =H12-H11 -> 19 | J12: 303515 | K12: =J12-J11 -> 0 | L12: 22071 | M12: =(L12-L11)*800/5 -> 800 | N12: 168084 | O12: =N12-N11 -> 3 | P12: 979740 | Q12: =P12-P11 -> 330 | R12: 55047 | S12: =R12-R11 -> 0
A13: 43565 | B13: 41746 | C13: =(B13-B12)*600/5 -> 600 | D13: 37382 | E13: =(D13-D12)*800/5 -> 480 | F13: 17582 | G13: =(F13-F12)*100/5 -> 80 | H13: 214567 | I13: =H13-H12 -> 19 | J13: 303515 | K13: =J13-J12 -> 0 | L13: 22076 | M13: =(L13-L12)*800/5 -> 800 | N13: 168087 | O13: =N13-N12 -> 3 | P13: 980021 | Q13: =P13-P12 -> 281 | R13: 55047 | S13: =R13-R12 -> 0
A14: 43566 | B14: 41751 | C14: =(B14-B13)*600/5 -> 600 | D14: 37386 | E14: =(D14-D13)*800/5 -> 640 | F14: 17586 | G14: =(F14-F13)*100/5 -> 80 | H14: 214584 | I14: =H14-H13 -> 17 | J14: 303515 | K14: =J14-J13 -> 0 | L14: 22080 | M14: =(L14-L13)*800/5 -> 640 | N14: 168089 | O14: =N14-N13 -> 2 | P14: 980212 | Q14: =P14-P13 -> 191 | R14: 55047 | S14: =R14-R13 -> 0
A15: 43567 | B15: 41757 | C15: =(B15-B14)*600/5 -> 720 | D15: 37389 | E15: =(D15-D14)*800/5 -> 480 | F15: 17590 | G15: =(F15-F14)*100/5 -> 80 | H15: 214614 | I15: =H15-H14 -> 30 | J15: 303515 | K15: =J15-J14 -> 0 | L15: 22083 | M15: =(L15-L14)*800/5 -> 480 | N15: 168092 | O15: =N15-N14 -> 3 | P15: 980354 | Q15: =P15-P14 -> 142 | R15: 55047 | S15: =R15-R14 -> 0
... A31: 43583 | B31: 41845 | C31: =(B31-B30)*600/5 -> 600 | D31: 37442 | E31: =(D31-D30)*800/5 -> 480 | F31: 17658 | G31: =(F31-F30)*100/5 -> 80 | H31: 214938 | I31: =H31-H30 -> 27 | J31: 303517 | K31: =J31-J30 -> 0 | L31: 22145 | M31: =(L31-L30)*800/5 -> 320 | N31: 168142 | O31: =N31-N30 -> 2 | P31: 983353 | Q31: =P31-P30 -> 246 | R31: 55047 | S31: =R31-R30 -> 0
A32: 43584 | B32: 41858 | C32: =(B32-B31)*600/5 -> 1560 | D32: 37445 | E32: =(D32-D31)*800/5 -> 480 | F32: 17661 | G32: =(F32-F31)*100/5 -> 60 | H32: 214963 | I32: =H32-H31 -> 25 | J32: 303517 | K32: =J32-J31 -> 0 | L32: 22148 | M32: =(L32-L31)*800/5 -> 480 | N32: 168145 | O32: =N32-N31 -> 3 | P32: 983540 | Q32: 41 | R32: 55047 | S32: =R32-R31 -> 0
A33: 43585 | B33: 41865 | C33: =(B33-B32)*600/5 -> 840 | D33: 37448 | E33: =(D33-D32)*800/5 -> 480 | F33: 17666 | G33: =(F33-F32)*100/5 -> 100 | H33: 214979 | I33: =H33-H32 -> 16 | J33: 303517 | K33: =J33-J32 -> 0 | L33: 22153 | M33: =(L33-L32)*800/5 -> 800 | N33: 168148 | O33: =N33-N32 -> 3 | P33: 983783 | Q33: =P33-P32 -> 243 | R33: 55047 | S33: =R33-R32 -> 0
B34: 41865 | C34: =(B34-B33)*600/5 -> 0 | D34: 37448 | E34: =(D34-D33)*800/5 -> 0 | F34: 17666 | G34: =(F34-F33)*100/5 -> 0 | H34: 214979 | I34: =H34-H33 -> 0 | J34: 303517 | K34: =J34-J33 -> 0 | L34: 22153 | M34: =(L34-L33)*800/5 -> 0 | N34: 168148 | O34: =N34-N33 -> 0 | P34: 983783 | Q34: =P34-P33 -> 0 | R34: 55047 | S34: =R34-R33 -> 0
A35: Total | C35: =SUM(C4:C34) -> 21000 | E35: =SUM(E4:E34) -> 16000 | G35: =SUM(G4:G34) -> 2540 | I35: =SUM(I4:I34) -> 606 | K35: =SUM(K4:K34) -> 2 | M35: =SUM(M4:M34) -> 19360 | O35: =SUM(O4:O34) -> 91 | Q35: =SUM(Q4:Q34) -> 5662 | S35: =SUM(S4:S34) -> 0

Sheet Water
A1: Main Building, Podium, Hotel and Large cons. Apr 2019
A2: Day | B2: Main Reading | C2: Cons. | D2: Podium | E2: Cons. | F2: Hotel | G2: Cons. | H2: Large | I2: Cons. | J2: Total | K2: cost.LE
A3: Last | B3: 348554 | C3: 0 | D3: 93163800 | E3: 0 | F3: 92909900 | G3: 0 | H3: 604325 | I3: 0 | J3: =C3+E3+G3+I3 -> 0 | K3: =J3*5.86 -> 0
A4: 43556 | B4: 348645 | C4: =(IF((B4-B3)<0,"0",(B4-B3)))*10 -> 910 | D4: 93184200 | E4: =(IF((D4-D3)<0,"0",(D4-D3)))*0.027 -> 550.8 | F4: 92923100 | G4: =(IF((F4-F3)<0,"0",(F4-F3)))*0.027 -> 356.4 | H4: 604499 | I4: =(IF((H4-H3)<0,"0",(H4-H3)))*0.027 -> 4.698 | J4: =C4+E4+G4+I4 -> 1821.898 | K4: =J4*5.86 -> 10676.322
A5: 43557 | B5: 348750 | C5: =(IF((B5-B4)<0,"0",(B5-B4)))*10 -> 1050 | D5: 93199800 | E5: =(IF((D5-D4)<0,"0",(D5-D4)))*0.027 -> 421.2 | F5: 92935000 | G5: =(IF((F5-F4)<0,"0",(F5-F4)))*0.027 -> 321.3 | H5: 604598 | I5: =(IF((H5-H4)<0,"0",(H5-H4)))*0.027 -> 2.673 | J5: =C5+E5+G5+I5 -> 1795.173 | K5: =J5*5.86 -> 10519.714
A6: 43558 | B6: 348860 | C6: =(IF((B6-B5)<0,"0",(B6-B5)))*10 -> 1100 | D6: 93225000 | E6: =(IF((D6-D5)<0,"0",(D6-D5)))*0.027 -> 680.4 | F6: 92954700 | G6: =(IF((F6-F5)<0,"0",(F6-F5)))*0.027 -> 531.9 | H6: 604809 | I6: =(IF((H6-H5)<0,"0",(H6-H5)))*0.027 -> 5.697 | J6: =C6+E6+G6+I6 -> 2317.997 | K6: =J6*5.86 -> 13583.462
A7: 43559 | B7: 348989 | C7: =(IF((B7-B6)<0,"0",(B7-B6)))*10 -> 1290 | D7: 93243000 | E7: =(IF((D7-D6)<0,"0",(D7-D6)))*0.027 -> 486 | F7: 92965000 | G7: =(IF((F7-F6)<0,"0",(F7-F6)))*0.027 -> 278.1 | H7: 604931 | I7: =(IF((H7-H6)<0,"0",(H7-H6)))*0.027 -> 3.294 | J7: =C7+E7+G7+I7 -> 2057.394 | K7: =J7*5.86 -> 12056.329
A8: 43560 | B8: 349077 | C8: =(IF((B8-B7)<0,"0",(B8-B7)))*10 -> 880 | D8: 93262100 | E8: =(IF((D8-D7)<0,"0",(D8-D7)))*0.027 -> 515.7 | F8: 92985000 | G8: =(IF((F8-F7)<0,"0",(F8-F7)))*0.027 -> 540 | H8: 605178 | I8: =(IF((H8-H7)<0,"0",(H8-H7)))*0.027 -> 6.669 | J8: =C8+E8+G8+I8 -> 1942.369 | K8: =J8*5.86 -> 11382.282
A9: 43561 | B9: 349149 | C9: =(IF((B9-B8)<0,"0",(B9-B8)))*10 -> 720 | D9: 93281800 | E9: =(IF((D9-D8)<0,"0",(D9-D8)))*0.027 -> 531.9 | F9: 93001100 | G9: =(IF((F9-F8)<0,"0",(F9-F8)))*0.027 -> 434.7 | H9: 605328 | I9: =(IF((H9-H8)<0,"0",(H9-H8)))*0.027 -> 4.05 | J9: =C9+E9+G9+I9 -> 1690.65 | K9: =J9*5.86 -> 9907.209
A10: 43562 | B10: 349253 | C10: =(IF((B10-B9)<0,"0",(B10-B9)))*10 -> 1040 | D10: 93302700 | E10: =(IF((D10-D9)<0,"0",(D10-D9)))*0.027 -> 564.3 | F10: 93018000 | G10: =(IF((F10-F9)<0,"0",(F10-F9)))*0.027 -> 456.3 | H10: 605512 | I10: =(IF((H10-H9)<0,"0",(H10-H9)))*0.027 -> 4.968 | J10: =C10+E10+G10+I10 -> 2065.568 | K10: =J10*5.86 -> 12104.228
A11: 43563 | B11: 349370 | C11: =(IF((B11-B10)<0,"0",(B11-B10)))*10 -> 1170 | D11: 93326900 | E11: =(IF((D11-D10)<0,"0",(D11-D10)))*0.027 -> 653.4 | F11: 93037300 | G11: =(IF((F11-F10)<0,"0",(F11-F10)))*0.027 -> 521.1 | H11: 605697 | I11: =(IF((H11-H10)<0,"0",(H11-H10)))*0.027 -> 4.995 | J11: =C11+E11+G11+I11 -> 2349.495 | K11: =J11*5.86 -> 13768.041
A12: 43564 | B12: 349466 | C12: =(IF((B12-B11)<0,"0",(B12-B11)))*10 -> 960 | D12: 93346400 | E12: =(IF((D12-D11)<0,"0",(D12-D11)))*0.027 -> 526.5 | F12: 93052500 | G12: =(IF((F12-F11)<0,"0",(F12-F11)))*0.027 -> 410.4 | H12: 605900 | I12: =(IF((H12-H11)<0,"0",(H12-H11)))*0.027 -> 5.481 | J12: =C12+E12+G12+I12 -> 1902.381 | K12: =J12*5.86 -> 11147.953
A13: 43565 | B13: 349562 | C13: =(IF((B13-B12)<0,"0",(B13-B12)))*10 -> 960 | D13: 93367000 | E13: =(IF((D13-D12)<0,"0",(D13-D12)))*0.027 -> 556.2 | F13: 93066300 | G13: =(IF((F13-F12)<0,"0",(F13-F12)))*0.027 -> 372.6 | H13: 606107 | I13: =(IF((H13-H12)<0,"0",(H13-H12)))*0.027 -> 5.589 | J13: =C13+E13+G13+I13 -> 1894.389 | K13: =J13*5.86 -> 11101.12
A14: 43566 | B14: 349664 | C14: =(IF((B14-B13)<0,"0",(B14-B13)))*10 -> 1020 | D14: 93389800 | E14: =(IF((D14-D13)<0,"0",(D14-D13)))*0.027 -> 615.6 | F14: 93083600 | G14: =(IF((F14-F13)<0,"0",(F14-F13)))*0.027 -> 467.1 | H14: 606277 | I14: =(IF((H14-H13)<0,"0",(H14-H13)))*0.027 -> 4.59 | J14: =C14+E14+G14+I14 -> 2107.29 | K14: =J14*5.86 -> 12348.719
A15: 43567 | B15: 349770 | C15: =(IF((B15-B14)<0,"0",(B15-B14)))*10 -> 1060 | D15: 93401400 | E15: =(IF((D15-D14)<0,"0",(D15-D14)))*0.027 -> 313.2 | F15: 93101400 | G15: =(IF((F15-F14)<0,"0",(F15-F14)))*0.027 -> 480.6 | H15: 606393 | I15: =(IF((H15-H14)<0,"0",(H15-H14)))*0.027 -> 3.132 | J15: =C15+E15+G15+I15 -> 1856.932 | K15: =J15*5.86 -> 10881.622
... A18: 43570 | B18: 350091 | C18: =(IF((B18-B17)<0,"0",(B18-B17)))*10 -> 990 | D18: 93471000 | E18: =(IF((D18-D17)<0,"0",(D18-D17)))*0.027 -> 537.3 | F18: 93155200 | G18: =(IF((F18-F17)<0,"0",(F18-F17)))*0.027 -> 432 | H18: 606830 | I18: =(IF((H18-H17)<0,"0",(H18-H17)))*0.027 -> 3.834 | J18: =C18+E18+G18+I18 -> 1963.134 | K18: =J18*5.86 -> 11503.965
A19: 43571 | B19: 350195 | C19: =(IF((B19-B18)<0,"0",(B19-B18)))*10 -> 1040 | D19: 93498500 | E19: =(IF((D19-D18)<0,"0",(D19-D18)))*0.027 -> 742.5 | F19: 93178800 | G19: =(IF((F19-F18)<0,"0",(F19-F18)))*0.027 -> 637.2 | H19: 607083 | I19: =(IF((H19-H18)<0,"0",(H19-H18)))*0.027 -> 6.831 | J19: =C19+E19+G19+I19 -> 2426.531 | K19: =J19*5.86 -> 14219.472 | Q19: `
A20: 43572 | B20: 350293 | C20: =(IF((B20-B19)<0,"0",(B20-B19)))*10 -> 980 | D20: 93516700 | E20: =(IF((D20-D19)<0,"0",(D20-D19)))*0.027 -> 491.4 | F20: 93186100 | G20: =(IF((F20-F19)<0,"0",(F20-F19)))*0.027 -> 197.1 | H20: 607231 | I20: =(IF((H20-H19)<0,"0",(H20-H19)))*0.027 -> 3.996 | J20: =C20+E20+G20+I20 -> 1672.496 | K20: =J20*5.86 -> 9800.8266
A21: 43573 | B21: 350411 | C21: =(IF((B21-B20)<0,"0",(B21-B20)))*10 -> 1180 | D21: 93538900 | E21: =(IF((D21-D20)<0,"0",(D21-D20)))*0.027 -> 599.4 | F21: 93202100 | G21: =(IF((F21-F20)<0,"0",(F21-F20)))*0.027 -> 432 | H21: 607441 | I21: =(IF((H21-H20)<0,"0",(H21-H20)))*0.027 -> 5.67 | J21: =C21+E21+G21+I21 -> 2217.07 | K21: =J21*5.86 -> 12992.03
A22: 43574 | B22: 350540 | C22: =(IF((B22-B21)<0,"0",(B22-B21)))*10 -> 1290 | D22: 93560900 | E22: =(IF((D22-D21)<0,"0",(D22-D21)))*0.027 -> 594 | F22: 93218000 | G22: =(IF((F22-F21)<0,"0",(F22-F21)))*0.027 -> 429.3 | H22: 607628 | I22: =(IF((H22-H21)<0,"0",(H22-H21)))*0.027 -> 5.049 | J22: =C22+E22+G22+I22 -> 2318.349 | K22: =J22*5.86 -> 13585.525
A23: 43575 | B23: 350623 | C23: =(IF((B23-B22)<0,"0",(B23-B22)))*10 -> 830 | D23: 93582000 | E23: =(IF((D23-D22)<0,"0",(D23-D22)))*0.027 -> 569.7 | F23: 93232400 | G23: =(IF((F23-F22)<0,"0",(F23-F22)))*0.027 -> 388.8 | H23: 607805 | I23: =(IF((H23-H22)<0,"0",(H23-H22)))*0.027 -> 4.779 | J23: =C23+E23+G23+I23 -> 1793.279 | K23: =J23*5.86 -> 10508.615
A24: 43576 | B24: 350727 | C24: =(IF((B24-B23)<0,"0",(B24-B23)))*10 -> 1040 | D24: 93604300 | E24: =(IF((D24-D23)<0,"0",(D24-D23)))*0.027 -> 602.1 | F24: 93248400 | G24: =(IF((F24-F23)<0,"0",(F24-F23)))*0.027 -> 432 | H24: 607944 | I24: =(IF((H24-H23)<0,"0",(H24-H23)))*0.027 -> 3.753 | J24: =C24+E24+G24+I24 -> 2077.853 | K24: =J24*5.86 -> 12176.219
A25: 43577 | B25: 350848 | C25: =(IF((B25-B24)<0,"0",(B25-B24)))*10 -> 1210 | D25: 93627400 | E25: =(IF((D25-D24)<0,"0",(D25-D24)))*0.027 -> 623.7 | F25: 93262800 | G25: =(IF((F25-F24)<0,"0",(F25-F24)))*0.027 -> 388.8 | H25: 608134 | I25: =(IF((H25-H24)<0,"0",(H25-H24)))*0.027 -> 5.13 | J25: =C25+E25+G25+I25 -> 2227.63 | K25: =J25*5.86 -> 13053.912
A26: 43578 | B26: 350940 | C26: =(IF((B26-B25)<0,"0",(B26-B25)))*10 -> 920 | D26: 93651500 | E26: =(IF((D26-D25)<0,"0",(D26-D25)))*0.027 -> 650.7 | F26: 93277400 | G26: =(IF((F26-F25)<0,"0",(F26-F25)))*0.027 -> 394.2 | H26: 608333 | I26: =(IF((H26-H25)<0,"0",(H26-H25)))*0.027 -> 5.373 | J26: =C26+E26+G26+I26 -> 1970.273 | K26: =J26*5.86 -> 11545.8
A27: 43579 | B27: 351042 | C27: =(IF((B27-B26)<0,"0",(B27-B26)))*10 -> 1020 | D27: 93673400 | E27: =(IF((D27-D26)<0,"0",(D27-D26)))*0.027 -> 591.3 | F27: 93291700 | G27: =(IF((F27-F26)<0,"0",(F27-F26)))*0.027 -> 386.1 | H27: 608503 | I27: =(IF((H27-H26)<0,"0",(H27-H26)))*0.027 -> 4.59 | J27: =C27+E27+G27+I27 -> 2001.99 | K27: =J27*5.86 -> 11731.661
A28: 43580 | B28: 351138 | C28: =(IF((B28-B27)<0,"0",(B28-B27)))*10 -> 960 | D28: 93693400 | E28: =(IF((D28-D27)<0,"0",(D28-D27)))*0.027 -> 540 | F28: 93306700 | G28: =(IF((F28-F27)<0,"0",(F28-F27)))*0.027 -> 405 | H28: 608655 | I28: =(IF((H28-H27)<0,"0",(H28-H27)))*0.027 -> 4.104 | J28: =C28+E28+G28+I28 -> 1909.104 | K28: =J28*5.86 -> 11187.349
A29: 43581 | B29: 351240 | C29: =(IF((B29-B28)<0,"0",(B29-B28)))*10 -> 1020 | D29: 93714500 | E29: =(IF((D29-D28)<0,"0",(D29-D28)))*0.027 -> 569.7 | F29: 93323200 | G29: =(IF((F29-F28)<0,"0",(F29-F28)))*0.027 -> 445.5 | H29: 608778 | I29: =(IF((H29-H28)<0,"0",(H29-H28)))*0.027 -> 3.321 | J29: =C29+E29+G29+I29 -> 2038.521 | K29: =J29*5.86 -> 11945.733
A30: 43582 | B30: 351337 | C30: =(IF((B30-B29)<0,"0",(B30-B29)))*10 -> 970 | D30: 93735200 | E30: =(IF((D30-D29)<0,"0",(D30-D29)))*0.027 -> 558.9 | F30: 93338700 | G30: =(IF((F30-F29)<0,"0",(F30-F29)))*0.027 -> 418.5 | H30: 608887 | I30: =(IF((H30-H29)<0,"0",(H30-H29)))*0.027 -> 2.943 | J30: =C30+E30+G30+I30 -> 1950.343 | K30: =J30*5.86 -> 11429.01
A31: 43583 | B31: 351442 | C31: =(IF((B31-B30)<0,"0",(B31-B30)))*10 -> 1050 | D31: 93756200 | E31: =(IF((D31-D30)<0,"0",(D31-D30)))*0.027 -> 567 | F31: 93355400 | G31: =(IF((F31-F30)<0,"0",(F31-F30)))*0.027 -> 450.9 | H31: 609010 | I31: =(IF((H31-H30)<0,"0",(H31-H30)))*0.027 -> 3.321 | J31: =C31+E31+G31+I31 -> 2071.221 | K31: =J31*5.86 -> 12137.355
... A33: 43585 | B33: 351660 | C33: =(IF((B33-B32)<0,"0",(B33-B32)))*10 -> 1090 | D33: 93796800 | E33: =(IF((D33-D32)<0,"0",(D33-D32)))*0.027 -> 575.1 | F33: 93388700 | G33: =(IF((F33-F32)<0,"0",(F33-F32)))*0.027 -> 442.8 | H33: 609235 | I33: =(IF((H33-H32)<0,"0",(H33-H32)))*0.027 -> 3.834 | J33: =C33+E33+G33+I33 -> 2111.734 | K33: =J33*5.86 -> 12374.761
B34: 351660 | C34: =(IF((B34-B33)<0,"0",(B34-B33)))*10 -> 0 | D34: 93796800 | E34: =(IF((D34-D33)<0,"0",(D34-D33)))*0.027 -> 0 | F34: 93388700 | G34: =(IF((F34-F33)<0,"0",(F34-F33)))*0.027 -> 0 | H34: 609235 | I34: =(IF((H34-H33)<0,"0",(H34-H33)))*0.027 -> 0
A35: Total | C35: =SUM(C4:C34) -> 31060 | E35: =SUM(E4:E34) -> 17091 | G35: =SUM(G4:G34) -> 12927.6 | I35: =SUM(I4:I34) -> 132.57 | J35: =SUM(J4:J31) -> 57029.795 | K35: =SUM(K4:K31) -> 334194.6

Sheet ELECT.
A1: Feeders and transformers Electrity cons. Apr 2019
A2: Day | B2: Rooms Sold | C2: New Chillers | D2: Cons | E2: F-1 | F2: Cons. | G2: F-2 | H2: Cons. | I2: Total | J2: T-1 | K2: Cons. | L2: T-2 | M2: Cons. | N2: T-3 | O2: Cons. | P2: T-4 | Q2: Cons. | R2: T-5 | S2: Cons. | T2: T-6 | U2: Cons. | V2: T-7 | W2: Cons. | X2: Total | Y2: Diff | Z2: Daily Money Value | AA2: MTD Total Money
A3: Last | B3: 350 | C3: 15337 | E3: 16372454 | F3: 0 | G3: 43524507 | H3: 0 | I3: 0 | J3: 3720138 | K3: 0 | L3: 3930918 | M3: 0 | N3: 2470813 | O3: 0 | P3: 4919848 | Q3: 0 | R3: 9860830 | S3: 0 | T3: 0 | V3: 6353860 | W3: 0
A4: 43556 | B4: 330 | C4: 15340 | D4: =IF((C4-C3)<0,"0",(C4-C3))*160 -> 480 | E4: 16378641 | F4: =IF((E4-E3)<0,"0",(E4-E3)) -> 6187 | G4: 43574352 | H4: =IF((G4-G3)<0,"0",(G4-G3)) -> 49845 | I4: =F4+H4 -> 56032 | J4: 3724903 | K4: =IF((J4-J3)<0,"0",(J4-J3)) -> 4765 | L4: 3935650 | M4: =IF((L4-L3)<0,"0",(L4-L3)) -> 4732 | N4: 2471505 | O4: =(IF((N4-N3)<0,"0",(N4-N3)))*2 -> 1384 | P4: 4928700 | Q4: =IF((P4-P3)<0,"0",(P4-P3)) -> 8852 | R4: 9871748 | S4: =IF((R4-R3)<0,"0",(R4-R3)) -> 10918 | T4: 0 | V4: 6366038 | W4: =IF((V4-V3)<0,"0",(V4-V3)) -> 12178 | X4: =K4+M4+O4+Q4+S4+U4+W4 -> 42829 | Y4: =I4-X4 -> 13203 | Z4: =(0.93352*(W4+S4)+0.5568*(Q4+O4))*0.26 -> 7087.5955 | AA4: =SUM(Z1:Z4) -> 7087.5955
A5: 43557 | B5: 341 | C5: 15344 | D5: =IF((C5-C4)<0,"0",(C5-C4))*160 -> 640 | E5: 16384852 | F5: =IF((E5-E4)<0,"0",(E5-E4)) -> 6211 | G5: 43623162 | H5: =IF((G5-G4)<0,"0",(G5-G4)) -> 48810 | I5: =F5+H5 -> 55021 | J5: 3729490 | K5: =IF((J5-J4)<0,"0",(J5-J4)) -> 4587 | L5: 3940283 | M5: =IF((L5-L4)<0,"0",(L5-L4)) -> 4633 | N5: 2472218 | O5: =(IF((N5-N4)<0,"0",(N5-N4)))*2 -> 1426 | P5: 4937143 | Q5: =IF((P5-P4)<0,"0",(P5-P4)) -> 8443 | R5: 9882437 | S5: =IF((R5-R4)<0,"0",(R5-R4)) -> 10689 | T5: 0 | V5: 6378076 | W5: =IF((V5-V4)<0,"0",(V5-V4)) -> 12038 | X5: =K5+M5+O5+Q5+S5+U5+W5 -> 41816 | Y5: =I5-X5 -> 13205 | Z5: =(0.93352*(W5+S5)+0.5568*(Q5+O5))*0.26 -> 6944.9037 | AA5: =SUM(Z2:Z5) -> 14032.499
A6: 43558 | B6: 338 | C6: 15349 | D6: =IF((C6-C5)<0,"0",(C6-C5))*160 -> 800 | E6: 16391288 | F6: =IF((E6-E5)<0,"0",(E6-E5)) -> 6436 | G6: 43673668 | H6: =IF((G6-G5)<0,"0",(G6-G5)) -> 50506 | I6: =F6+H6 -> 56942 | J6: 3734088 | K6: =IF((J6-J5)<0,"0",(J6-J5)) -> 4598 | L6: 3945112 | M6: =IF((L6-L5)<0,"0",(L6-L5)) -> 4829 | N6: 2472950 | O6: =(IF((N6-N5)<0,"0",(N6-N5)))*2 -> 1464 | P6: 4946893 | Q6: =IF((P6-P5)<0,"0",(P6-P5)) -> 9750 | R6: 9893035 | S6: =IF((R6-R5)<0,"0",(R6-R5)) -> 10598 | T6: 0 | V6: 6390261 | W6: =IF((V6-V5)<0,"0",(V6-V5)) -> 12185 | X6: =K6+M6+O6+Q6+S6+U6+W6 -> 43424 | Y6: =I6-X6 -> 13518 | Z6: =(0.93352*(W6+S6)+0.5568*(Q6+O6))*0.26 -> 7153.2088 | AA6: =SUM(Z3:Z6) -> 21185.708
A7: 43559 | B7: 344 | C7: 15354 | D7: =IF((C7-C6)<0,"0",(C7-C6))*160 -> 800 | E7: 16399519 | F7: =IF((E7-E6)<0,"0",(E7-E6)) -> 8231 | G7: 43707362 | H7: =IF((G7-G6)<0,"0",(G7-G6)) -> 33694 | I7: =F7+H7 -> 41925 | J7: 3737566 | K7: =IF((J7-J6)<0,"0",(J7-J6)) -> 3478 | L7: 3948658 | M7: =IF((L7-L6)<0,"0",(L7-L6)) -> 3546 | N7: 2475266 | O7: =(IF((N7-N6)<0,"0",(N7-N6)))*2 -> 4632 | P7: 4949548 | Q7: =IF((P7-P6)<0,"0",(P7-P6)) -> 2655 | R7: 9901124 | S7: =IF((R7-R6)<0,"0",(R7-R6)) -> 8089 | T7: 0 | V7: 6399094 | W7: =IF((V7-V6)<0,"0",(V7-V6)) -> 8833 | X7: =K7+M7+O7+Q7+S7+U7+W7 -> 31233 | Y7: =I7-X7 -> 10692 | Z7: =(0.93352*(W7+S7)+0.5568*(Q7+O7))*0.26 -> 5162.151 | AA7: =SUM(Z4:Z7) -> 26347.859
A8: 43560 | B8: 365 | C8: 15359 | D8: =IF((C8-C7)<0,"0",(C8-C7))*160 -> 800 | E8: 16416741 | F8: =IF((E8-E7)<0,"0",(E8-E7)) -> 17222 | G8: 43772998 | H8: =IF((G8-G7)<0,"0",(G8-G7)) -> 65636 | I8: =F8+H8 -> 82858 | J8: 3743718 | K8: =IF((J8-J7)<0,"0",(J8-J7)) -> 6152 | L8: 3955560 | M8: =IF((L8-L7)<0,"0",(L8-L7)) -> 6902 | N8: 2480266 | O8: =(IF((N8-N7)<0,"0",(N8-N7)))*2 -> 10000 | P8: 4953652 | Q8: =IF((P8-P7)<0,"0",(P8-P7)) -> 4104 | R8: 9917908 | S8: =IF((R8-R7)<0,"0",(R8-R7)) -> 16784 | T8: 0 | V8: 6418046 | W8: =IF((V8-V7)<0,"0",(V8-V7)) -> 18952 | X8: =K8+M8+O8+Q8+S8+U8+W8 -> 62894 | Y8: =I8-X8 -> 19964 | Z8: =(0.93352*(W8+S8)+0.5568*(Q8+O8))*0.26 -> 10715.478 | AA8: =SUM(Z5:Z8) -> 29975.742
A9: 43561 | B9: 332 | C9: 15363 | D9: =IF((C9-C8)<0,"0",(C9-C8))*160 -> 640 | E9: 16425626 | F9: =IF((E9-E8)<0,"0",(E9-E8)) -> 8885 | G9: 43805976 | H9: =IF((G9-G8)<0,"0",(G9-G8)) -> 32978 | I9: =F9+H9 -> 41863 | J9: 3747100 | K9: =IF((J9-J8)<0,"0",(J9-J8)) -> 3382 | L9: 3959426 | M9: =IF((L9-L8)<0,"0",(L9-L8)) -> 3866 | N9: 2482729 | O9: =(IF((N9-N8)<0,"0",(N9-N8)))*2 -> 4926 | P9: 4955666 | Q9: =IF((P9-P8)<0,"0",(P9-P8)) -> 2014 | R9: 9926373 | S9: =IF((R9-R8)<0,"0",(R9-R8)) -> 8465 | T9: 0 | V9: 6427314 | W9: =IF((V9-V8)<0,"0",(V9-V8)) -> 9268 | X9: =K9+M9+O9+Q9+S9+U9+W9 -> 31921 | Y9: =I9-X9 -> 9942 | Z9: =(0.93352*(W9+S9)+0.5568*(Q9+O9))*0.26 -> 5308.7586 | AA9: =SUM(Z6:Z9) -> 28339.597
A10: 43562 | B10: 322 | C10: 15368 | D10: =IF((C10-C9)<0,"0",(C10-C9))*160 -> 800 | E10: 16440089 | F10: =IF((E10-E9)<0,"0",(E10-E9)) -> 14463 | G10: 43854673 | H10: =IF((G10-G9)<0,"0",(G10-G9)) -> 48697 | I10: =F10+H10 -> 63160 | J10: 3752063 | K10: =IF((J10-J9)<0,"0",(J10-J9)) -> 4963 | L10: 3965025 | M10: =IF((L10-L9)<0,"0",(L10-L9)) -> 5599 | N10: 2487064 | O10: =(IF((N10-N9)<0,"0",(N10-N9)))*2 -> 8670 | P10: 4958924 | Q10: =IF((P10-P9)<0,"0",(P10-P9)) -> 3258 | R10: 9938563 | S10: =IF((R10-R9)<0,"0",(R10-R9)) -> 12190 | T10: 0 | V10: 6440776 | W10: =IF((V10-V9)<0,"0",(V10-V9)) -> 13462 | X10: =K10+M10+O10+Q10+S10+U10+W10 -> 48142 | Y10: =I10-X10 -> 15018 | Z10: =(0.93352*(W10+S10)+0.5568*(Q10+O10))*0.26 -> 7952.923 | AA10: =SUM(Z7:Z10) -> 29139.311
A11: 43563 | B11: 330 | C11: 15373 | D11: =IF((C11-C10)<0,"0",(C11-C10))*160 -> 800 | E11: 16451397 | F11: =IF((E11-E10)<0,"0",(E11-E10)) -> 11308 | G11: 43892924 | H11: =IF((G11-G10)<0,"0",(G11-G10)) -> 38251 | I11: =F11+H11 -> 49559 | J11: 3756234 | K11: =IF((J11-J10)<0,"0",(J11-J10)) -> 4171 | L11: 3969433 | M11: =IF((L11-L10)<0,"0",(L11-L10)) -> 4408 | N11: 2490956 | O11: =(IF((N11-N10)<0,"0",(N11-N10)))*2 -> 7784 | P11: 4961730 | Q11: =IF((P11-P10)<0,"0",(P11-P10)) -> 2806 | R11: 9947390 | S11: =IF((R11-R10)<0,"0",(R11-R10)) -> 8827 | T11: 0 | V11: 6451510 | W11: =IF((V11-V10)<0,"0",(V11-V10)) -> 10734 | X11: =K11+M11+O11+Q11+S11+U11+W11 -> 38730 | Y11: =I11-X11 -> 10829 | Z11: =(0.93352*(W11+S11)+0.5568*(Q11+O11))*0.26 -> 6280.8451 | AA11: =SUM(Z8:Z11) -> 30258.005
A12: 43564 | B12: 320 | C12: 15377 | D12: =IF((C12-C11)<0,"0",(C12-C11))*160 -> 640 | E12: 16465268 | F12: =IF((E12-E11)<0,"0",(E12-E11)) -> 13871 | G12: 43942246 | H12: =IF((G12-G11)<0,"0",(G12-G11)) -> 49322 | I12: =F12+H12 -> 63193 | J12: 3761513 | K12: =IF((J12-J11)<0,"0",(J12-J11)) -> 5279 | L12: 3974779 | M12: =IF((L12-L11)<0,"0",(L12-L11)) -> 5346 | N12: 2494642 | O12: =(IF((N12-N11)<0,"0",(N12-N11)))*2 -> 7372 | P12: 4964294 | Q12: =IF((P12-P11)<0,"0",(P12-P11)) -> 2564 | R12: 9959028 | S12: =IF((R12-R11)<0,"0",(R12-R11)) -> 11638 | T12: 0 | V12: 6465255 | W12: =IF((V12-V11)<0,"0",(V12-V11)) -> 13745 | X12: =K12+M12+O12+Q12+S12+U12+W12 -> 45944 | Y12: =I12-X12 -> 17249 | Z12: =(0.93352*(W12+S12)+0.5568*(Q12+O12))*0.26 -> 7599.2548 | AA12: =SUM(Z9:Z12) -> 27141.781
A13: 43565 | B13: 344 | C13: 15382 | D13: =IF((C13-C12)<0,"0",(C13-C12))*160 -> 800 | E13: 16476432 | F13: =IF((E13-E12)<0,"0",(E13-E12)) -> 11164 | G13: 43983359 | H13: =IF((G13-G12)<0,"0",(G13-G12)) -> 41113 | I13: =F13+H13 -> 52277 | J13: 3766219 | K13: =IF((J13-J12)<0,"0",(J13-J12)) -> 4706 | L13: 3979118 | M13: =IF((L13-L12)<0,"0",(L13-L12)) -> 4339 | N13: 2497979 | O13: =(IF((N13-N12)<0,"0",(N13-N12)))*2 -> 6674 | P13: 4968256 | Q13: =IF((P13-P12)<0,"0",(P13-P12)) -> 3962 | R13: 9968751 | S13: =IF((R13-R12)<0,"0",(R13-R12)) -> 9723 | T13: 0 | V13: 6476559 | W13: =IF((V13-V12)<0,"0",(V13-V12)) -> 11304 | X13: =K13+M13+O13+Q13+S13+U13+W13 -> 40708 | Y13: =I13-X13 -> 11569 | Z13: =(0.93352*(W13+S13)+0.5568*(Q13+O13))*0.26 -> 6643.325 | AA13: =SUM(Z10:Z13) -> 28476.348
A14: 43566 | B14: 351 | C14: 15386 | D14: =IF((C14-C13)<0,"0",(C14-C13))*160 -> 640 | E14: 16490609 | F14: =IF((E14-E13)<0,"0",(E14-E13)) -> 14177 | G14: 44036574 | H14: =IF((G14-G13)<0,"0",(G14-G13)) -> 53215 | I14: =F14+H14 -> 67392 | J14: 3772145 | K14: =IF((J14-J13)<0,"0",(J14-J13)) -> 5926 | L14: 3984415 | M14: =IF((L14-L13)<0,"0",(L14-L13)) -> 5297 | N14: 2502316 | O14: =(IF((N14-N13)<0,"0",(N14-N13)))*2 -> 8674 | P14: 4972228 | Q14: =IF((P14-P13)<0,"0",(P14-P13)) -> 3972 | R14: 9981856 | S14: =IF((R14-R13)<0,"0",(R14-R13)) -> 13105 | T14: 0 | V14: 6490923 | W14: =IF((V14-V13)<0,"0",(V14-V13)) -> 14364 | X14: =K14+M14+O14+Q14+S14+U14+W14 -> 51338 | Y14: =I14-X14 -> 16054 | Z14: =(0.93352*(W14+S14)+0.5568*(Q14+O14))*0.26 -> 8497.88 | AA14: =SUM(Z11:Z14) -> 29021.305
A15: 43567 | B15: 358 | C15: 15390 | D15: =IF((C15-C14)<0,"0",(C15-C14))*160 -> 640 | E15: 16499288 | F15: =IF((E15-E14)<0,"0",(E15-E14)) -> 8679 | G15: 44068998 | H15: =IF((G15-G14)<0,"0",(G15-G14)) -> 32424 | I15: =F15+H15 -> 41103 | J15: 3775306 | K15: =IF((J15-J14)<0,"0",(J15-J14)) -> 3161 | L15: 3987561 | M15: =IF((L15-L14)<0,"0",(L15-L14)) -> 3146 | N15: 2505036 | O15: =(IF((N15-N14)<0,"0",(N15-N14)))*2 -> 5440 | P15: 4974665 | Q15: =IF((P15-P14)<0,"0",(P15-P14)) -> 2437 | R15: 9989924 | S15: =IF((R15-R14)<0,"0",(R15-R14)) -> 8068 | T15: 0 | V15: 6499944 | W15: =IF((V15-V14)<0,"0",(V15-V14)) -> 9021 | X15: =K15+M15+O15+Q15+S15+U15+W15 -> 31273 | Y15: =I15-X15 -> 9830 | Z15: =(0.93352*(W15+S15)+0.5568*(Q15+O15))*0.26 -> 5288.0976 | AA15: =SUM(Z12:Z15) -> 28028.557
... A33: 43585 | B33: 298 | C33: 15466 | D33: =IF((C33-C32)<0,"0",(C33-C32))*160 -> 800 | E33: 16655010 | F33: =IF((E33-E32)<0,"0",(E33-E32)) -> 12743 | G33: 45047485 | H33: =IF((G33-G32)<0,"0",(G33-G32)) -> 56716 | I33: =F33+H33 -> 69459 | J33: 3869359 | K33: =IF((J33-J32)<0,"0",(J33-J32)) -> 6093 | L33: 4076121 | M33: =IF((L33-L32)<0,"0",(L33-L32)) -> 4545 | N33: 2537554 | O33: =(IF((N33-N32)<0,"0",(N33-N32)))*2 -> 8034 | P33: 5174422 | Q33: =IF((P33-P32)<0,"0",(P33-P32)) -> 14811 | R33: 10188644 | S33: =IF((R33-R32)<0,"0",(R33-R32)) -> 9870 | T33: 0 | V33: 6731805 | W33: =IF((V33-V32)<0,"0",(V33-V32)) -> 12326 | X33: =K33+M33+O33+Q33+S33+U33+W33 -> 55679 | Y33: =I33-X33 -> 13780 | Z33: =(0.93352*(W33+S33)+0.5568*(Q33+O33))*0.26 -> 8694.5315 | AA33: =SUM(Z30:Z33) -> 33451.241
D34: =IF((C34-C33)<0,"0",(C34-C33))*160 -> 0 | E34: 16655010 | F34: =IF((E34-E33)<0,"0",(E34-E33)) -> 0 | G34: 45047485 | H34: =IF((G34-G33)<0,"0",(G34-G33)) -> 0 | I34: =F34+H34 -> 0 | J34: 3869359 | K34: =IF((J34-J33)<0,"0",(J34-J33)) -> 0 | L34: 4076121 | M34: =IF((L34-L33)<0,"0",(L34-L33)) -> 0 | N34: 2537554 | O34: =(IF((N34-N33)<0,"0",(N34-N33)))*2 -> 0 | P34: 5174422 | Q34: =IF((P34-P33)<0,"0",(P34-P33)) -> 0 | R34: 10188644 | S34: =IF((R34-R33)<0,"0",(R34-R33)) -> 0 | T34: 0 | V34: 6731805 | W34: =IF((V34-V33)<0,"0",(V34-V33)) -> 0 | X34: =K34+M34+O34+Q34+S34+U34+W34 -> 0 | Y34: =I34-X34 -> 0 | Z34: =(0.93352*(W34+S34)+0.5568*(Q34+O34))*0.26 -> 0 | AA34: =SUM(Z31:Z34) -> 26475.878
A35: Total | F35: =SUM(F3:F34) -> 282556 | H35: =SUM(H3:H34) -> 1522978 | I35: =F35+H35 -> 1805534 | K35: =SUM(K3:K34) -> 149221 | M35: =SUM(M3:M34) -> 145203 | O35: =SUM(O3:O34) -> 133482 | Q35: =SUM(Q3:Q34) -> 254574 | S35: =SUM(S3:T34) -> 327814 | W35: =SUM(W3:W34) -> 377945 | X35: =SUM(X4:X31) -> 1260047 | Y35: =SUM(Y4:Y31) -> 385376 | Z35: =SUM(Z5:Z31) -> 200338.77

Sheet Gas
A1: Gas Con. Apr 2019
A2: Day | B2: Main | C2: Cons.
A3: Last | B3: 15346378
A4: 43556 | B4: 15350325 | C4: =IF((B4-B3)<0,"0",(B4-B3)) -> 3947
A5: 43557 | B5: 15354489 | C5: =IF((B5-B4)<0,"0",(B5-B4)) -> 4164
A6: 43558 | B6: 15358089 | C6: =IF((B6-B5)<0,"0",(B6-B5)) -> 3600
A7: 43559 | B7: 15361793 | C7: =IF((B7-B6)<0,"0",(B7-B6)) -> 3704
A8: 43560 | B8: 15365561 | C8: =IF((B8-B7)<0,"0",(B8-B7)) -> 3768
A9: 43561 | B9: 15369335 | C9: =IF((B9-B8)<0,"0",(B9-B8)) -> 3774
A10: 43562 | B10: 15372749 | C10: =IF((B10-B9)<0,"0",(B10-B9)) -> 3414
A11: 43563 | B11: 15376056 | C11: =IF((B11-B10)<0,"0",(B11-B10)) -> 3307
A12: 43564 | B12: 15379544 | C12: =IF((B12-B11)<0,"0",(B12-B11)) -> 3488
A13: 43565 | B13: 15383257 | C13: =IF((B13-B12)<0,"0",(B13-B12)) -> 3713
A14: 43566 | B14: 15387049 | C14: =IF((B14-B13)<0,"0",(B14-B13)) -> 3792
A15: 43567 | B15: 15390758 | C15: =IF((B15-B14)<0,"0",(B15-B14)) -> 3709
... A33: 43585 | B33: 15455257 | C33: =IF((B33-B32)<0,"0",(B33-B32)) -> 2932
B34: 15455257 | C34: =IF((B34-B33)<0,"0",(B34-B33)) -> 0
A35: Total | C35: =SUM(C4:C34) -> 108879

Sheet BTU
A1: Day | B1: Hotel | C1: Cons. Mwh | D1: Cost (LE) | E1: B.S | F1: Cons. Mwh | G1: Cost (LE) | H1: LS | I1: Cons.Mwh | J1: . | K1: AHU # 25 | L1: Cons.Mwh | M1: Cost (LE) | N1: Mall | O1: Cons.Mwh | P1: Cost (LE) | Q1: AHU # 9 | R1: Cons.Mwh | S1: Cost (LE) | T1: Total Cons. | U1: Total Cost (LE)
A2: Last | B2: 14052.22 | D2: =C2*1.9*1000 -> 0 | E2: 2110.121 | G2: =F2*1.9*1000 -> 0 | H2: 855.773 | J2: =I2*1.9*1000 -> 0 | K2: 12689.35 | M2: =L2*1.9*1000 -> 0 | N2: 1740.251 | P2: =O2*1.9*1000 -> 0 | Q2: 3839.1 | S2: 0 | T2: =C2+F2+I2+L2+O2+R2 -> 0
A3: 43556 | B3: 14064.725 | C3: =IF((B3-B2)<0,"0",(B3-B2)) -> 12.505 | D3: =C3*1.9*1000 -> 23759.5 | E3: 2110.923 | F3: =IF((E3-E2)<0,"0",(E3-E2)) -> 0.802 | G3: =F3*1.9*1000 -> 1523.8 | H3: 855.898 | I3: =IF((H3-H2)<0,"0",(H3-H2)) -> 0.125 | J3: =I3*1.9*1000 -> 237.5 | K3: 12691.24 | L3: =IF((K3-K2)<0,"0",(K3-K2)) -> 1.89 | M3: =L3*1.9*1000 -> 3591 | N3: 1743.022 | O3: =IF((N3-N2)<0,"0",(N3-N2)) -> 2.771 | P3: =O3*1.9*1000 -> 5264.9 | Q3: 3839.1 | R3: =IF((Q3-Q2)<0,"0",(Q3-Q2)) -> 0 | S3: =R3*1.9*1000 -> 0 | T3: =C3+F3+I3+L3+O3+R3 -> 18.093 | U3: =T3*1.9*1000 -> 34376.7
A4: 43557 | B4: 14069.616 | C4: =IF((B4-B3)<0,"0",(B4-B3)) -> 4.891 | D4: =C4*1.9*1000 -> 9292.9 | E4: 2112.183 | F4: =IF((E4-E3)<0,"0",(E4-E3)) -> 1.26 | G4: =F4*1.9*1000 -> 2394 | H4: 856.143 | I4: =IF((H4-H3)<0,"0",(H4-H3)) -> 0.245 | J4: =I4*1.9*1000 -> 465.5 | K4: 12692.3 | L4: =IF((K4-K3)<0,"0",(K4-K3)) -> 1.06 | M4: =L4*1.9*1000 -> 2014 | N4: 1744.241 | O4: =IF((N4-N3)<0,"0",(N4-N3)) -> 1.219 | P4: =O4*1.9*1000 -> 2316.1 | Q4: 3839.1 | R4: =IF((Q4-Q3)<0,"0",(Q4-Q3)) -> 0 | S4: =R4*1.9*1000 -> 0 | T4: =C4+F4+I4+L4+O4+R4 -> 8.675 | U4: =T4*1.9*1000 -> 16482.5
A5: 43558 | B5: 14075.392 | C5: =IF((B5-B4)<0,"0",(B5-B4)) -> 5.776 | D5: =C5*1.9*1000 -> 10974.4 | E5: 2113.581 | F5: =IF((E5-E4)<0,"0",(E5-E4)) -> 1.398 | G5: =F5*1.9*1000 -> 2656.2 | H5: 856.195 | I5: =IF((H5-H4)<0,"0",(H5-H4)) -> 0.052 | J5: =I5*1.9*1000 -> 98.8 | K5: 12692.45 | L5: =IF((K5-K4)<0,"0",(K5-K4)) -> 0.15 | M5: =L5*1.9*1000 -> 285 | N5: 1745.499 | O5: =IF((N5-N4)<0,"0",(N5-N4)) -> 1.258 | P5: =O5*1.9*1000 -> 2390.2 | Q5: 3839.1 | R5: =IF((Q5-Q4)<0,"0",(Q5-Q4)) -> 0 | S5: =R5*1.9*1000 -> 0 | T5: =C5+F5+I5+L5+O5+R5 -> 8.634 | U5: =T5*1.9*1000 -> 16404.6
A6: 43559 | B6: 14082.169 | C6: =IF((B6-B5)<0,"0",(B6-B5)) -> 6.777 | D6: =C6*1.9*1000 -> 12876.3 | E6: 2114.952 | F6: =IF((E6-E5)<0,"0",(E6-E5)) -> 1.371 | G6: =F6*1.9*1000 -> 2604.9 | H6: 856.238 | I6: =IF((H6-H5)<0,"0",(H6-H5)) -> 0.043 | J6: =I6*1.9*1000 -> 81.7 | K6: 12694.61 | L6: =IF((K6-K5)<0,"0",(K6-K5)) -> 2.16 | M6: =L6*1.9*1000 -> 4104 | N6: 1747.163 | O6: =IF((N6-N5)<0,"0",(N6-N5)) -> 1.664 | P6: =O6*1.9*1000 -> 3161.6 | Q6: 3839.1 | R6: =IF((Q6-Q5)<0,"0",(Q6-Q5)) -> 0 | S6: =R6*1.9*1000 -> 0 | T6: =C6+F6+I6+L6+O6+R6 -> 12.015 | U6: =T6*1.9*1000 -> 22828.5
A7: 43560 | B7: 14088.405 | C7: =IF((B7-B6)<0,"0",(B7-B6)) -> 6.236 | D7: =C7*1.9*1000 -> 11848.4 | E7: 2115.554 | F7: =IF((E7-E6)<0,"0",(E7-E6)) -> 0.602 | G7: =F7*1.9*1000 -> 1143.8 | H7: 856.25 | I7: =IF((H7-H6)<0,"0",(H7-H6)) -> 0.012 | J7: =I7*1.9*1000 -> 22.8 | K7: 12695.75 | L7: =IF((K7-K6)<0,"0",(K7-K6)) -> 1.14 | M7: =L7*1.9*1000 -> 2166 | N7: 1748.756 | O7: =IF((N7-N6)<0,"0",(N7-N6)) -> 1.593 | P7: =O7*1.9*1000 -> 3026.7 | Q7: 3839.1 | R7: =IF((Q7-Q6)<0,"0",(Q7-Q6)) -> 0 | S7: =R7*1.9*1000 -> 0 | T7: =C7+F7+I7+L7+O7+R7 -> 9.583 | U7: =T7*1.9*1000 -> 18207.7
A8: 43561 | B8: 14094.786 | C8: =IF((B8-B7)<0,"0",(B8-B7)) -> 6.381 | D8: =C8*1.9*1000 -> 12123.9 | E8: 2116.222 | F8: =IF((E8-E7)<0,"0",(E8-E7)) -> 0.668 | G8: =F8*1.9*1000 -> 1269.2 | H8: 856.292 | I8: =IF((H8-H7)<0,"0",(H8-H7)) -> 0.042 | J8: =I8*1.9*1000 -> 79.8 | K8: 12696.85 | L8: =IF((K8-K7)<0,"0",(K8-K7)) -> 1.1 | M8: =L8*1.9*1000 -> 2090 | N8: 1750.556 | O8: =IF((N8-N7)<0,"0",(N8-N7)) -> 1.8 | P8: =O8*1.9*1000 -> 3420 | Q8: 3839.1 | R8: =IF((Q8-Q7)<0,"0",(Q8-Q7)) -> 0 | S8: =R8*1.9*1000 -> 0 | T8: =C8+F8+I8+L8+O8+R8 -> 9.991 | U8: =T8*1.9*1000 -> 18982.9
A9: 43562 | B9: 14103.267 | C9: =IF((B9-B8)<0,"0",(B9-B8)) -> 8.481 | D9: =C9*1.9*1000 -> 16113.9 | E9: 2118.302 | F9: =IF((E9-E8)<0,"0",(E9-E8)) -> 2.08 | G9: =F9*1.9*1000 -> 3952 | H9: 856.292 | I9: =IF((H9-H8)<0,"0",(H9-H8)) -> 0 | J9: =I9*1.9*1000 -> 0 | K9: 12698.05 | L9: =IF((K9-K8)<0,"0",(K9-K8)) -> 1.2 | M9: =L9*1.9*1000 -> 2280 | N9: 1752.242 | O9: =IF((N9-N8)<0,"0",(N9-N8)) -> 1.686 | P9: =O9*1.9*1000 -> 3203.4 | Q9: 3839.1 | R9: =IF((Q9-Q8)<0,"0",(Q9-Q8)) -> 0 | S9: =R9*1.9*1000 -> 0 | T9: =C9+F9+I9+L9+O9+R9 -> 13.447 | U9: =T9*1.9*1000 -> 25549.3
A10: 43563 | B10: 14109.603 | C10: =IF((B10-B9)<0,"0",(B10-B9)) -> 6.336 | D10: =C10*1.9*1000 -> 12038.4 | E10: 2119.947 | F10: =IF((E10-E9)<0,"0",(E10-E9)) -> 1.645 | G10: =F10*1.9*1000 -> 3125.5 | H10: 856.295 | I10: =IF((H10-H9)<0,"0",(H10-H9)) -> 0.003 | J10: =I10*1.9*1000 -> 5.7 | K10: 12699.05 | L10: =IF((K10-K9)<0,"0",(K10-K9)) -> 1 | M10: =L10*1.9*1000 -> 1900 | N10: 1753.487 | O10: =IF((N10-N9)<0,"0",(N10-N9)) -> 1.245 | P10: =O10*1.9*1000 -> 2365.5 | Q10: 3841.12 | R10: =IF((Q10-Q9)<0,"0",(Q10-Q9)) -> 2.02 | S10: =R10*1.9*1000 -> 3838 | T10: =C10+F10+I10+L10+O10+R10 -> 12.249 | U10: =T10*1.9*1000 -> 23273.1
A11: 43564 | B11: 14116.909 | C11: =IF((B11-B10)<0,"0",(B11-B10)) -> 7.306 | D11: =C11*1.9*1000 -> 13881.4 | E11: 2122.098 | F11: =IF((E11-E10)<0,"0",(E11-E10)) -> 2.151 | G11: =F11*1.9*1000 -> 4086.9 | H11: 856.296 | I11: =IF((H11-H10)<0,"0",(H11-H10)) -> 0.001 | J11: =I11*1.9*1000 -> 1.9 | K11: 12700.16 | L11: =IF((K11-K10)<0,"0",(K11-K10)) -> 1.11 | M11: =L11*1.9*1000 -> 2109 | N11: 1754.877 | O11: =IF((N11-N10)<0,"0",(N11-N10)) -> 1.39 | P11: =O11*1.9*1000 -> 2641 | Q11: 3841.28 | R11: =IF((Q11-Q10)<0,"0",(Q11-Q10)) -> 0.16 | S11: =R11*1.9*1000 -> 304 | T11: =C11+F11+I11+L11+O11+R11 -> 12.118 | U11: =T11*1.9*1000 -> 23024.2
A12: 43565 | B12: 14124.063 | C12: =IF((B12-B11)<0,"0",(B12-B11)) -> 7.154 | D12: =C12*1.9*1000 -> 13592.6 | E12: 2123.812 | F12: =IF((E12-E11)<0,"0",(E12-E11)) -> 1.714 | G12: =F12*1.9*1000 -> 3256.6 | H12: 856.299 | I12: =IF((H12-H11)<0,"0",(H12-H11)) -> 0.003 | J12: =I12*1.9*1000 -> 5.7 | K12: 12701.26 | L12: =IF((K12-K11)<0,"0",(K12-K11)) -> 1.1 | M12: =L12*1.9*1000 -> 2090 | N12: 1756.425 | O12: =IF((N12-N11)<0,"0",(N12-N11)) -> 1.548 | P12: =O12*1.9*1000 -> 2941.2 | Q12: 3841.46 | R12: =IF((Q12-Q11)<0,"0",(Q12-Q11)) -> 0.18 | S12: =R12*1.9*1000 -> 342 | T12: =C12+F12+I12+L12+O12+R12 -> 11.699 | U12: =T12*1.9*1000 -> 22228.1
A13: 43566 | B13: 14131.315 | C13: =IF((B13-B12)<0,"0",(B13-B12)) -> 7.252 | D13: =C13*1.9*1000 -> 13778.8 | E13: 2125.628 | F13: =IF((E13-E12)<0,"0",(E13-E12)) -> 1.816 | G13: =F13*1.9*1000 -> 3450.4 | H13: 856.316 | I13: =IF((H13-H12)<0,"0",(H13-H12)) -> 0.017 | J13: =I13*1.9*1000 -> 32.3 | K13: 12702.45 | L13: =IF((K13-K12)<0,"0",(K13-K12)) -> 1.19 | M13: =L13*1.9*1000 -> 2261 | N13: 1757.763 | O13: =IF((N13-N12)<0,"0",(N13-N12)) -> 1.338 | P13: =O13*1.9*1000 -> 2542.2 | Q13: 3841.69 | R13: =IF((Q13-Q12)<0,"0",(Q13-Q12)) -> 0.23 | S13: =R13*1.9*1000 -> 437 | T13: =C13+F13+I13+L13+O13+R13 -> 11.843 | U13: =T13*1.9*1000 -> 22501.7
