Workbook

Sheet TOTAL
A1: Site Name | B1: Day | C1: Month | D1: Year | E1: Total Electricity Kwh | F1: Electricity Tariff ($/Kwh) | G1: Natual Gas (m3) | H1: Natural Gas $/m3 | I1: Water Utility Supply (m3) m3 | J1: Water Utility Supply (m3) $/m3 | K1: Room Nights
A2: Cairo at Nile Plaza | B2: 1 | C2: 1 | D2: 2019 | E2: =(((Submetering!O2+Submetering!P2)*0.842284+Submetering!Q2+(Submetering!M2+Submetering!N2+Submetering!Y2)*0.7362)+(Submetering!O2+Submetering!P2+Submetering!Q2)*0.1488+(Submetering!M2+Submetering!N2+Submetering!Y2)*0.1167+(Submetering!K2+Submetering!L2-Submetering!Z2-Submetering!AA2-Submetering!AB2-Submetering!AC2-Submetering!Q2)+(Submetering!M2+Submetering!N2+Submetering!Y2)*0.1139) -> 71499.561 | F2: 1.15 | G2: =Gas!C4*0.9147 -> 5319.8952 | H2: 2.25 | I2: =Submetering!AE2+Submetering!AD2+Submetering!H2 -> 866 | J2: 9.12 | K2: =ELECT.!B4 -> 265
A3: Cairo at Nile Plaza | B3: =B2+1 -> 2 | C3: 1 | D3: 2019 | E3: =(((Submetering!O3+Submetering!P3)*0.842284+Submetering!Q3+(Submetering!M3+Submetering!N3+Submetering!Y3)*0.7362)+(Submetering!O3+Submetering!P3+Submetering!Q3)*0.1488+(Submetering!M3+Submetering!N3+Submetering!Y3)*0.1167+(Submetering!K3+Submetering!L3-Submetering!Z3-Submetering!AA3-Submetering!AB3-Submetering!AC3-Submetering!Q3)+(Submetering!M3+Submetering!N3+Submetering!Y3)*0.1139) -> 45441.901 | F3: 1.15 | G3: =Gas!C5*0.9147 -> 3332.2521 | H3: 2.25 | I3: =Submetering!AE3+Submetering!AD3+Submetering!H3 -> 456 | J3: 9.12 | K3: =ELECT.!B5 -> 284
A4: Cairo at Nile Plaza | B4: =B3+1 -> 3 | C4: 1 | D4: 2019 | E4: =(((Submetering!O4+Submetering!P4)*0.842284+Submetering!Q4+(Submetering!M4+Submetering!N4+Submetering!Y4)*0.7362)+(Submetering!O4+Submetering!P4+Submetering!Q4)*0.1488+(Submetering!M4+Submetering!N4+Submetering!Y4)*0.1167+(Submetering!K4+Submetering!L4-Submetering!Z4-Submetering!AA4-Submetering!AB4-Submetering!AC4-Submetering!Q4)+(Submetering!M4+Submetering!N4+Submetering!Y4)*0.1139) -> 74047.276 | F4: 1.15 | G4: =Gas!C6*0.9147 -> 2954.481 | H4: 2.25 | I4: =Submetering!AE4+Submetering!AD4+Submetering!H4 -> 656 | J4: 9.12 | K4: =ELECT.!B6 -> 316
A5: Cairo at Nile Plaza | B5: =B4+1 -> 4 | C5: 1 | D5: 2019 | E5: =(((Submetering!O5+Submetering!P5)*0.842284+Submetering!Q5+(Submetering!M5+Submetering!N5+Submetering!Y5)*0.7362)+(Submetering!O5+Submetering!P5+Submetering!Q5)*0.1488+(Submetering!M5+Submetering!N5+Submetering!Y5)*0.1167+(Submetering!K5+Submetering!L5-Submetering!Z5-Submetering!AA5-Submetering!AB5-Submetering!AC5-Submetering!Q5)+(Submetering!M5+Submetering!N5+Submetering!Y5)*0.1139) -> 60289.723 | F5: 1.15 | G5: =Gas!C7*0.9147 -> 3893.8779 | H5: 2.25 | I5: =Submetering!AE5+Submetering!AD5+Submetering!H5 -> 1186 | J5: 9.12 | K5: =ELECT.!B7 -> 316
A6: Cairo at Nile Plaza | B6: =B5+1 -> 5 | C6: 1 | D6: 2019 | E6: =(((Submetering!O6+Submetering!P6)*0.842284+Submetering!Q6+(Submetering!M6+Submetering!N6+Submetering!Y6)*0.7362)+(Submetering!O6+Submetering!P6+Submetering!Q6)*0.1488+(Submetering!M6+Submetering!N6+Submetering!Y6)*0.1167+(Submetering!K6+Submetering!L6-Submetering!Z6-Submetering!AA6-Submetering!AB6-Submetering!AC6-Submetering!Q6)+(Submetering!M6+Submetering!N6+Submetering!Y6)*0.1139) -> 49568.406 | F6: 1.15 | G6: =Gas!C8*0.9147 -> 3664.2882 | H6: 2.25 | I6: =Submetering!AE6+Submetering!AD6+Submetering!H6 -> 1016 | J6: 9.12 | K6: =ELECT.!B8 -> 318
A7: Cairo at Nile Plaza | B7: =B6+1 -> 6 | C7: 1 | D7: 2019 | E7: =(((Submetering!O7+Submetering!P7)*0.842284+Submetering!Q7+(Submetering!M7+Submetering!N7+Submetering!Y7)*0.7362)+(Submetering!O7+Submetering!P7+Submetering!Q7)*0.1488+(Submetering!M7+Submetering!N7+Submetering!Y7)*0.1167+(Submetering!K7+Submetering!L7-Submetering!Z7-Submetering!AA7-Submetering!AB7-Submetering!AC7-Submetering!Q7)+(Submetering!M7+Submetering!N7+Submetering!Y7)*0.1139) -> 45064.772 | F7: 1.15 | G7: =Gas!C9*0.9147 -> 3334.0815 | H7: 2.25 | I7: =Submetering!AE7+Submetering!AD7+Submetering!H7 -> 936 | J7: 9.12 | K7: =ELECT.!B9 -> 270
A8: Cairo at Nile Plaza | B8: =B7+1 -> 7 | C8: 1 | D8: 2019 | E8: =(((Submetering!O8+Submetering!P8)*0.842284+Submetering!Q8+(Submetering!M8+Submetering!N8+Submetering!Y8)*0.7362)+(Submetering!O8+Submetering!P8+Submetering!Q8)*0.1488+(Submetering!M8+Submetering!N8+Submetering!Y8)*0.1167+(Submetering!K8+Submetering!L8-Submetering!Z8-Submetering!AA8-Submetering!AB8-Submetering!AC8-Submetering!Q8)+(Submetering!M8+Submetering!N8+Submetering!Y8)*0.1139) -> 68307.425 | F8: 1.15 | G8: =Gas!C10*0.9147 -> 3273.7113 | H8: 2.25 | I8: =Submetering!AE8+Submetering!AD8+Submetering!H8 -> 976 | J8: 9.12 | K8: =ELECT.!B10 -> 258
A9: Cairo at Nile Plaza | B9: =B8+1 -> 8 | C9: 1 | D9: 2019 | E9: =(((Submetering!O9+Submetering!P9)*0.842284+Submetering!Q9+(Submetering!M9+Submetering!N9+Submetering!Y9)*0.7362)+(Submetering!O9+Submetering!P9+Submetering!Q9)*0.1488+(Submetering!M9+Submetering!N9+Submetering!Y9)*0.1167+(Submetering!K9+Submetering!L9-Submetering!Z9-Submetering!AA9-Submetering!AB9-Submetering!AC9-Submetering!Q9)+(Submetering!M9+Submetering!N9+Submetering!Y9)*0.1139) -> 52108.838 | F9: 1.15 | G9: =Gas!C11*0.9147 -> 5257.6956 | H9: 2.25 | I9: =Submetering!AE9+Submetering!AD9+Submetering!H9 -> 676 | J9: 9.12 | K9: =ELECT.!B11 -> 263
A10: Cairo at Nile Plaza | B10: =B9+1 -> 9 | C10: 1 | D10: 2019 | E10: =(((Submetering!O10+Submetering!P10)*0.842284+Submetering!Q10+(Submetering!M10+Submetering!N10+Submetering!Y10)*0.7362)+(Submetering!O10+Submetering!P10+Submetering!Q10)*0.1488+(Submetering!M10+Submetering!N10+Submetering!Y10)*0.1167+(Submetering!K10+Submetering!L10-Submetering!Z10-Submetering!AA10-Submetering!AB10-Submetering!AC10-Submetering!Q10)+(Submetering!M10+Submetering!N10+Submetering!Y10)*0.1139) -> 62433.179 | F10: 1.15 | G10: =Gas!C12*0.9147 -> 4696.9845 | H10: 2.25 | I10: =Submetering!AE10+Submetering!AD10+Submetering!H10 -> 1076 | J10: 9.12 | K10: =ELECT.!B12 -> 263
A11: Cairo at Nile Plaza | B11: =B10+1 -> 10 | C11: 1 | D11: 2019 | E11: =(((Submetering!O11+Submetering!P11)*0.842284+Submetering!Q11+(Submetering!M11+Submetering!N11+Submetering!Y11)*0.7362)+(Submetering!O11+Submetering!P11+Submetering!Q11)*0.1488+(Submetering!M11+Submetering!N11+Submetering!Y11)*0.1167+(Submetering!K11+Submetering!L11-Submetering!Z11-Submetering!AA11-Submetering!AB11-Submetering!AC11-Submetering!Q11)+(Submetering!M11+Submetering!N11+Submetering!Y11)*0.1139) -> 49205.374 | F11: 1.15 | G11: =Gas!C13*0.9147 -> 4306.4076 | H11: 2.25 | I11: =Submetering!AE11+Submetering!AD11+Submetering!H11 -> 876 | J11: 9.12 | K11: =ELECT.!B13 -> 268
A12: Cairo at Nile Plaza | B12: =B11+1 -> 11 | C12: 1 | D12: 2019 | E12: =(((Submetering!O12+Submetering!P12)*0.842284+Submetering!Q12+(Submetering!M12+Submetering!N12+Submetering!Y12)*0.7362)+(Submetering!O12+Submetering!P12+Submetering!Q12)*0.1488+(Submetering!M12+Submetering!N12+Submetering!Y12)*0.1167+(Submetering!K12+Submetering!L12-Submetering!Z12-Submetering!AA12-Submetering!AB12-Submetering!AC12-Submetering!Q12)+(Submetering!M12+Submetering!N12+Submetering!Y12)*0.1139) -> 81660.159 | F12: 1.15 | G12: =Gas!C14*0.9147 -> 5362.8861 | H12: 2.25 | I12: =Submetering!AE12+Submetering!AD12+Submetering!H12 -> 846 | J12: 9.12 | K12: =ELECT.!B14 -> 271
A13: Cairo at Nile Plaza | B13: =B12+1 -> 12 | C13: 1 | D13: 2019 | E13: =(((Submetering!O13+Submetering!P13)*0.842284+Submetering!Q13+(Submetering!M13+Submetering!N13+Submetering!Y13)*0.7362)+(Submetering!O13+Submetering!P13+Submetering!Q13)*0.1488+(Submetering!M13+Submetering!N13+Submetering!Y13)*0.1167+(Submetering!K13+Submetering!L13-Submetering!Z13-Submetering!AA13-Submetering!AB13-Submetering!AC13-Submetering!Q13)+(Submetering!M13+Submetering!N13+Submetering!Y13)*0.1139) -> 37318.519 | F13: 1.15 | G13: =Gas!C15*0.9147 -> 4030.1682 | H13: 2.25 | I13: =Submetering!AE13+Submetering!AD13+Submetering!H13 -> 916 | J13: 9.12 | K13: =ELECT.!B15 -> 298
A14: Cairo at Nile Plaza | B14: =B13+1 -> 13 | C14: 1 | D14: 2019 | E14: =(((Submetering!O14+Submetering!P14)*0.842284+Submetering!Q14+(Submetering!M14+Submetering!N14+Submetering!Y14)*0.7362)+(Submetering!O14+Submetering!P14+Submetering!Q14)*0.1488+(Submetering!M14+Submetering!N14+Submetering!Y14)*0.1167+(Submetering!K14+Submetering!L14-Submetering!Z14-Submetering!AA14-Submetering!AB14-Submetering!AC14-Submetering!Q14)+(Submetering!M14+Submetering!N14+Submetering!Y14)*0.1139) -> 67210.732 | F14: 1.15 | G14: =Gas!C16*0.9147 -> 3865.5222 | H14: 2.25 | I14: =Submetering!AE14+Submetering!AD14+Submetering!H14 -> 856 | J14: 9.12 | K14: =ELECT.!B16 -> 250
... A31: Cairo at Nile Plaza | B31: =B30+1 -> 30 | C31: 1 | D31: 2019 | E31: =(((Submetering!O31+Submetering!P31)*0.842284+Submetering!Q31+(Submetering!M31+Submetering!N31+Submetering!Y31)*0.7362)+(Submetering!O31+Submetering!P31+Submetering!Q31)*0.1488+(Submetering!M31+Submetering!N31+Submetering!Y31)*0.1167+(Submetering!K31+Submetering!L31-Submetering!Z31-Submetering!AA31-Submetering!AB31-Submetering!AC31-Submetering!Q31)+(Submetering!M31+Submetering!N31+Submetering!Y31)*0.1139) -> 75560.406 | F31: 1.15 | G31: =Gas!C33*0.9147 -> 5027.1912 | H31: 2.25 | I31: =Submetering!AE31+Submetering!AD31+Submetering!H31 -> 886 | J31: 9.12 | K31: =ELECT.!B33 -> 331
A32: Cairo at Nile Plaza | B32: 31 | C32: 1 | D32: 2019 | E32: =(((Submetering!O32+Submetering!P32)*0.842284+Submetering!Q32+(Submetering!M32+Submetering!N32+Submetering!Y32)*0.7362)+(Submetering!O32+Submetering!P32+Submetering!Q32)*0.1488+(Submetering!M32+Submetering!N32+Submetering!Y32)*0.1167+(Submetering!K32+Submetering!L32-Submetering!Z32-Submetering!AA32-Submetering!AB32-Submetering!AC32-Submetering!Q32)+(Submetering!M32+Submetering!N32+Submetering!Y32)*0.1139) -> 21398.546 | F32: 1.15 | G32: =Gas!C34*0.9147 -> 1984.899 | H32: 2.25 | I32: =Submetering!AE32+Submetering!AD32+Submetering!H32 -> 1006 | J32: 9.12 | K32: =ELECT.!B34 -> 358

Sheet Submetering
A1: Site Name | B1: Day | C1: Month | D1: Year | E1: Main (m3) | F1: Podium (m3) | G1: Hotel (m3) | H1: Large (m3) | I1: Feeder 1 (KWh) | J1: Feeder 2 (KWh) | K1: T1 (KWh) | L1: T2 (KWh) | M1: T3 (KWh) | N1: T4 (KWh) | O1: T5 (KWh) | P1: T7 (KWh) | Q1: New Chiller (KWh) | R1: Hotel (BTU) | S1: B.S (BTU) | T1: LS (BTU) | U1: Mall (BTU) | V1: AHU#25 (BTU) | W1: AHU#9 (BTU) | X1: Room Nights | Y1: Loss (KWH) | Z1: Mall (KWH) | AA1: Citadel (KWH) | AB1: Rotana (KWH) | AC1: CIB (KWH) | AD1: Plaza suits water consumption (M3) | AE1: Hotel water consumption (M3)
A2: Cairo at Nile Plaza | B2: 1 | C2: 1 | D2: 2019 | E2: =Water!C4 -> 1060 | F2: =Water!E4 -> 558.9 | G2: =Water!G4 -> 475.2 | H2: =Water!I4 -> 5.211 | I2: =ELECT.!F4 -> 17864 | J2: =ELECT.!H4 -> 55718 | K2: =ELECT.!K4 -> 7382 | L2: =ELECT.!M4 -> 8059 | M2: =ELECT.!O4 -> 9720 | N2: =ELECT.!Q4 -> 4854 | O2: =ELECT.!S4 -> 13613 | P2: =ELECT.!W4*2 -> 29888 | Q2: =ELECT.!D4 -> 1280 | R2: =BTU!C3 -> 3.912 | S2: =BTU!F3 -> 0.644 | T2: =BTU!I3 -> 0 | U2: =BTU!O3 -> 1.156 | V2: =BTU!L3 -> 0.4 | W2: =BTU!R3 -> 0.12 | X2: =ELECT.!B4 -> 265 | Y2: =I2+J2-(K2+L2+M2+N2+O2+P2) -> 66 | Z2: ='Mall, Citadel, Rotana'!C4+'Mall, Citadel, Rotana'!E4+'Mall, Citadel, Rotana'!G4+'Mall, Citadel, Rotana'!I4 -> 1173 | AA2: ='Mall, Citadel, Rotana'!K4+'Mall, Citadel, Rotana'!M4 -> 160 | AB2: ='Mall, Citadel, Rotana'!O4 -> 3 | AC2: ='Mall, Citadel, Rotana'!Q4+'Mall, Citadel, Rotana'!S4 -> 63 | AD2: =(E2-H2-194)*0.1318 -> 113.45199 | AE2: =E2-H2-AD2-194 -> 747.33701
A3: Cairo at Nile Plaza | B3: =B2+1 -> 2 | C3: 1 | D3: 2019 | E3: =Water!C5 -> 650 | F3: =Water!E5 -> 610.2 | G3: =Water!G5 -> 594 | H3: =Water!I5 -> 5.859 | I3: =ELECT.!F5 -> 11858 | J3: =ELECT.!H5 -> 36170 | K3: =ELECT.!K5 -> 3946 | L3: =ELECT.!M5 -> 5246 | M3: =ELECT.!O5 -> 6454 | N3: =ELECT.!Q5 -> 1773 | O3: =ELECT.!S5 -> 8939 | P3: =ELECT.!W5*2 -> 19878 | Q3: =ELECT.!D5 -> 1280 | R3: =BTU!C4 -> 3.771 | S3: =BTU!F4 -> 0.584 | T3: =BTU!I4 -> 0 | U3: =BTU!O4 -> 1.109 | V3: =BTU!L4 -> 0.28 | W3: =BTU!R4 -> 0 | X3: =ELECT.!B5 -> 284 | Y3: =I3+J3-(K3+L3+M3+N3+O3+P3) -> 1792 | Z3: ='Mall, Citadel, Rotana'!C5+'Mall, Citadel, Rotana'!E5+'Mall, Citadel, Rotana'!G5+'Mall, Citadel, Rotana'!I5 -> 1213 | AA3: ='Mall, Citadel, Rotana'!K5+'Mall, Citadel, Rotana'!M5 -> 960 | AB3: ='Mall, Citadel, Rotana'!O5 -> 3 | AC3: ='Mall, Citadel, Rotana'!Q5+'Mall, Citadel, Rotana'!S5 -> 11 | AD3: =(E3-H3-194)*0.1318 -> 59.328584 | AE3: =E3-H3-AD3-194 -> 390.81242
A4: Cairo at Nile Plaza | B4: =B3+1 -> 3 | C4: 1 | D4: 2019 | E4: =Water!C6 -> 850 | F4: =Water!E6 -> 680.4 | G4: =Water!G6 -> 437.4 | H4: =Water!I6 -> 6.156 | I4: =ELECT.!F6 -> 18769 | J4: =ELECT.!H6 -> 58620 | K4: =ELECT.!K6 -> 6404 | L4: =ELECT.!M6 -> 8034 | M4: =ELECT.!O6 -> 10540 | N4: =ELECT.!Q6 -> 4209 | O4: =ELECT.!S6 -> 15258 | P4: =ELECT.!W6*2 -> 31760 | Q4: =ELECT.!D6 -> 1280 | R4: =BTU!C5 -> 3.344 | S4: =BTU!F5 -> 0.599 | T4: =BTU!I5 -> 0 | U4: =BTU!O5 -> 0.653 | V4: =BTU!L5 -> 0.61 | W4: =BTU!R5 -> 0.05 | X4: =ELECT.!B6 -> 316 | Y4: =I4+J4-(K4+L4+M4+N4+O4+P4) -> 1184 | Z4: ='Mall, Citadel, Rotana'!C6+'Mall, Citadel, Rotana'!E6+'Mall, Citadel, Rotana'!G6+'Mall, Citadel, Rotana'!I6 -> 1437 | AA4: ='Mall, Citadel, Rotana'!K6+'Mall, Citadel, Rotana'!M6 -> 640 | AB4: ='Mall, Citadel, Rotana'!O6 -> 3 | AC4: ='Mall, Citadel, Rotana'!Q6+'Mall, Citadel, Rotana'!S6 -> 504 | AD4: =(E4-H4-194)*0.1318 -> 85.649439 | AE4: =E4-H4-AD4-194 -> 564.19456
A5: Cairo at Nile Plaza | B5: =B4+1 -> 4 | C5: 1 | D5: 2019 | E5: =Water!C7 -> 1380 | F5: =Water!E7 -> 488.7 | G5: =Water!G7 -> 237.6 | H5: =Water!I7 -> 4.266 | I5: =ELECT.!F7 -> 14786 | J5: =ELECT.!H7 -> 47759 | K5: =ELECT.!K7 -> 5284 | L5: =ELECT.!M7 -> 6069 | M5: =ELECT.!O7 -> 8492 | N5: =ELECT.!Q7 -> 3724 | O5: =ELECT.!S7 -> 12163 | P5: =ELECT.!W7*2 -> 25674 | Q5: =ELECT.!D7 -> 1280 | R5: =BTU!C6 -> 3.528 | S5: =BTU!F6 -> 0.414 | T5: =BTU!I6 -> 0 | U5: =BTU!O6 -> 0.95 | V5: =BTU!L6 -> 0.08 | W5: =BTU!R6 -> 0 | X5: =ELECT.!B7 -> 316 | Y5: =I5+J5-(K5+L5+M5+N5+O5+P5) -> 1139 | Z5: ='Mall, Citadel, Rotana'!C7+'Mall, Citadel, Rotana'!E7+'Mall, Citadel, Rotana'!G7+'Mall, Citadel, Rotana'!I7 -> 1010 | AA5: ='Mall, Citadel, Rotana'!K7+'Mall, Citadel, Rotana'!M7 -> 640 | AB5: ='Mall, Citadel, Rotana'!O7 -> 2 | AC5: ='Mall, Citadel, Rotana'!Q7+'Mall, Citadel, Rotana'!S7 -> 13 | AD5: =(E5-H5-194)*0.1318 -> 155.75254 | AE5: =E5-H5-AD5-194 -> 1025.9815
A6: Cairo at Nile Plaza | B6: =B5+1 -> 5 | C6: 1 | D6: 2019 | E6: =Water!C8 -> 1210 | F6: =Water!E8 -> 629.1 | G6: =Water!G8 -> 432 | H6: =Water!I8 -> 6.399 | I6: =ELECT.!F8 -> 12510 | J6: =ELECT.!H8 -> 39358 | K6: =ELECT.!K8 -> 5528 | L6: =ELECT.!M8 -> 5481 | M6: =ELECT.!O8 -> 6906 | N6: =ELECT.!Q8 -> 3549 | O6: =ELECT.!S8 -> 9541 | P6: =ELECT.!W8*2 -> 20786 | Q6: =ELECT.!D8 -> 1280 | R6: =BTU!C7 -> 3.863 | S6: =BTU!F7 -> 0.575 | T6: =BTU!I7 -> 0.013 | U6: =BTU!O7 -> 0.996 | V6: =BTU!L7 -> 0.19 | W6: =BTU!R7 -> 0 | X6: =ELECT.!B8 -> 318 | Y6: =I6+J6-(K6+L6+M6+N6+O6+P6) -> 77 | Z6: ='Mall, Citadel, Rotana'!C8+'Mall, Citadel, Rotana'!E8+'Mall, Citadel, Rotana'!G8+'Mall, Citadel, Rotana'!I8 -> 1339 | AA6: ='Mall, Citadel, Rotana'!K8+'Mall, Citadel, Rotana'!M8 -> 320 | AB6: ='Mall, Citadel, Rotana'!O8 -> 4 | AC6: ='Mall, Citadel, Rotana'!Q8+'Mall, Citadel, Rotana'!S8 -> 207 | AD6: =(E6-H6-194)*0.1318 -> 133.06541 | AE6: =E6-H6-AD6-194 -> 876.53559
A7: Cairo at Nile Plaza | B7: =B6+1 -> 6 | C7: 1 | D7: 2019 | E7: =Water!C9 -> 1130 | F7: =Water!E9 -> 631.8 | G7: =Water!G9 -> 324 | H7: =Water!I9 -> 6.534 | I7: =ELECT.!F9 -> 11373 | J7: =ELECT.!H9 -> 36395 | K7: =ELECT.!K9 -> 5211 | L7: =ELECT.!M9 -> 4915 | M7: =ELECT.!O9 -> 6320 | N7: =ELECT.!Q9 -> 2191 | O7: =ELECT.!S9 -> 8749 | P7: =ELECT.!W9*2 -> 19048 | Q7: =ELECT.!D9 -> 1280 | R7: =BTU!C8 -> 3.572 | S7: =BTU!F8 -> 0.529 | T7: =BTU!I8 -> 0 | U7: =BTU!O8 -> 1.002 | V7: =BTU!L8 -> 0 | W7: =BTU!R8 -> 0 | X7: =ELECT.!B9 -> 270 | Y7: =I7+J7-(K7+L7+M7+N7+O7+P7) -> 1334 | Z7: ='Mall, Citadel, Rotana'!C9+'Mall, Citadel, Rotana'!E9+'Mall, Citadel, Rotana'!G9+'Mall, Citadel, Rotana'!I9 -> 1316 | AA7: ='Mall, Citadel, Rotana'!K9+'Mall, Citadel, Rotana'!M9 -> 800 | AB7: ='Mall, Citadel, Rotana'!O9 -> 3 | AC7: ='Mall, Citadel, Rotana'!Q9+'Mall, Citadel, Rotana'!S9 -> 200 | AD7: =(E7-H7-194)*0.1318 -> 122.50362 | AE7: =E7-H7-AD7-194 -> 806.96238
A8: Cairo at Nile Plaza | B8: =B7+1 -> 7 | C8: 1 | D8: 2019 | E8: =Water!C10 -> 1170 | F8: =Water!E10 -> 669.6 | G8: =Water!G10 -> 321.3 | H8: =Water!I10 -> 6.21 | I8: =ELECT.!F10 -> 16709 | J8: =ELECT.!H10 -> 53966 | K8: =ELECT.!K10 -> 6062 | L8: =ELECT.!M10 -> 7272 | M8: =ELECT.!O10 -> 9244 | N8: =ELECT.!Q10 -> 4094 | O8: =ELECT.!S10 -> 13987 | P8: =ELECT.!W10*2 -> 28950 | Q8: =ELECT.!D10 -> 1280 | R8: =BTU!C9 -> 3.767 | S8: =BTU!F9 -> 0.427 | T8: =BTU!I9 -> 0 | U8: =BTU!O9 -> 0.698 | V8: =BTU!L9 -> 0.1 | W8: =BTU!R9 -> 0 | X8: =ELECT.!B10 -> 258 | Y8: =I8+J8-(K8+L8+M8+N8+O8+P8) -> 1066 | Z8: ='Mall, Citadel, Rotana'!C10+'Mall, Citadel, Rotana'!E10+'Mall, Citadel, Rotana'!G10+'Mall, Citadel, Rotana'!I10 -> 1011 | AA8: ='Mall, Citadel, Rotana'!K10+'Mall, Citadel, Rotana'!M10 -> 480 | AB8: ='Mall, Citadel, Rotana'!O10 -> 3 | AC8: ='Mall, Citadel, Rotana'!Q10+'Mall, Citadel, Rotana'!S10 -> 203 | AD8: =(E8-H8-194)*0.1318 -> 127.81832 | AE8: =E8-H8-AD8-194 -> 841.97168
A9: Cairo at Nile Plaza | B9: =B8+1 -> 8 | C9: 1 | D9: 2019 | E9: =Water!C11 -> 870 | F9: =Water!E11 -> 464.4 | G9: =Water!G11 -> 245.7 | H9: =Water!I11 -> 5.913 | I9: =ELECT.!F11 -> 13023 | J9: =ELECT.!H11 -> 41880 | K9: =ELECT.!K11 -> 4807 | L9: =ELECT.!M11 -> 5800 | M9: =ELECT.!O11 -> 7054 | N9: =ELECT.!Q11 -> 3705 | O9: =ELECT.!S11 -> 10755 | P9: =ELECT.!W11*2 -> 22518 | Q9: =ELECT.!D11 -> 1280 | R9: =BTU!C10 -> 3.315 | S9: =BTU!F10 -> 0.642 | T9: =BTU!I10 -> 0 | U9: =BTU!O10 -> 0.867 | V9: =BTU!L10 -> 0 | W9: =BTU!R10 -> 0 | X9: =ELECT.!B11 -> 263 | Y9: =I9+J9-(K9+L9+M9+N9+O9+P9) -> 264 | Z9: ='Mall, Citadel, Rotana'!C11+'Mall, Citadel, Rotana'!E11+'Mall, Citadel, Rotana'!G11+'Mall, Citadel, Rotana'!I11 -> 1474 | AA9: ='Mall, Citadel, Rotana'!K11+'Mall, Citadel, Rotana'!M11 -> 640 | AB9: ='Mall, Citadel, Rotana'!O11 -> 3 | AC9: ='Mall, Citadel, Rotana'!Q11+'Mall, Citadel, Rotana'!S11 -> 205 | AD9: =(E9-H9-194)*0.1318 -> 88.317467 | AE9: =E9-H9-AD9-194 -> 581.76953
A10: Cairo at Nile Plaza | B10: =B9+1 -> 9 | C10: 1 | D10: 2019 | E10: =Water!C12 -> 1270 | F10: =Water!E12 -> 604.8 | G10: =Water!G12 -> 391.5 | H10: =Water!I12 -> 6.507 | I10: =ELECT.!F12 -> 15086 | J10: =ELECT.!H12 -> 50331 | K10: =ELECT.!K12 -> 6176 | L10: =ELECT.!M12 -> 6658 | M10: =ELECT.!O12 -> 8266 | N10: =ELECT.!Q12 -> 2913 | O10: =ELECT.!S12 -> 13078 | P10: =ELECT.!W12*2 -> 27256 | Q10: =ELECT.!D12 -> 1280 | R10: =BTU!C11 -> 2.4 | S10: =BTU!F11 -> 0.525 | T10: =BTU!I11 -> 0.019 | U10: =BTU!O11 -> 0.693 | V10: =BTU!L11 -> 0.03 | W10: =BTU!R11 -> 0 | X10: =ELECT.!B12 -> 263 | Y10: =I10+J10-(K10+L10+M10+N10+O10+P10) -> 1070 | Z10: ='Mall, Citadel, Rotana'!C12+'Mall, Citadel, Rotana'!E12+'Mall, Citadel, Rotana'!G12+'Mall, Citadel, Rotana'!I12 -> 1352 | AA10: ='Mall, Citadel, Rotana'!K12+'Mall, Citadel, Rotana'!M12 -> 960 | AB10: ='Mall, Citadel, Rotana'!O12 -> 2 | AC10: ='Mall, Citadel, Rotana'!Q12+'Mall, Citadel, Rotana'!S12 -> 94 | AD10: =(E10-H10-194)*0.1318 -> 140.95918 | AE10: =E10-H10-AD10-194 -> 928.53382
A11: Cairo at Nile Plaza | B11: =B10+1 -> 10 | C11: 1 | D11: 2019 | E11: =Water!C13 -> 1070 | F11: =Water!E13 -> 577.8 | G11: =Water!G13 -> 472.5 | H11: =Water!I13 -> 4.914 | I11: =ELECT.!F13 -> 10136 | J11: =ELECT.!H13 -> 41739 | K11: =ELECT.!K13 -> 6014 | L11: =ELECT.!M13 -> 4592 | M11: =ELECT.!O13 -> 5420 | N11: =ELECT.!Q13 -> 3262 | O11: =ELECT.!S13 -> 9488 | P11: =ELECT.!W13*2 -> 21810 | Q11: =ELECT.!D13 -> 1280 | R11: =BTU!C12 -> 2.567 | S11: =BTU!F12 -> 0.719 | T11: =BTU!I12 -> 0 | U11: =BTU!O12 -> 0.47 | V11: =BTU!L12 -> 0.14 | W11: =BTU!R12 -> 0 | X11: =ELECT.!B13 -> 268 | Y11: =I11+J11-(K11+L11+M11+N11+O11+P11) -> 1289 | Z11: ='Mall, Citadel, Rotana'!C13+'Mall, Citadel, Rotana'!E13+'Mall, Citadel, Rotana'!G13+'Mall, Citadel, Rotana'!I13 -> 1189 | AA11: ='Mall, Citadel, Rotana'!K13+'Mall, Citadel, Rotana'!M13 -> 960 | AB11: ='Mall, Citadel, Rotana'!O13 -> 3 | AC11: ='Mall, Citadel, Rotana'!Q13+'Mall, Citadel, Rotana'!S13 -> 98 | AD11: =(E11-H11-194)*0.1318 -> 114.80913 | AE11: =E11-H11-AD11-194 -> 756.27687
A12: Cairo at Nile Plaza | B12: =B11+1 -> 11 | C12: 1 | D12: 2019 | E12: =Water!C14 -> 1040 | F12: =Water!E14 -> 545.4 | G12: =Water!G14 -> 364.5 | H12: =Water!I14 -> 3.159 | I12: =ELECT.!F14 -> 18316 | J12: =ELECT.!H14 -> 65659 | K12: =ELECT.!K14 -> 7547 | L12: =ELECT.!M14 -> 7763 | M12: =ELECT.!O14 -> 10294 | N12: =ELECT.!Q14 -> 4622 | O12: =ELECT.!S14 -> 16248 | P12: =ELECT.!W14*2 -> 36024 | Q12: =ELECT.!D14 -> 1280 | R12: =BTU!C13 -> 3.173 | S12: =BTU!F13 -> 0.506 | T12: =BTU!I13 -> 0.028 | U12: =BTU!O13 -> 1.006 | V12: =BTU!L13 -> 0.06 | W12: =BTU!R13 -> 0 | X12: =ELECT.!B14 -> 271 | Y12: =I12+J12-(K12+L12+M12+N12+O12+P12) -> 1477 | Z12: ='Mall, Citadel, Rotana'!C14+'Mall, Citadel, Rotana'!E14+'Mall, Citadel, Rotana'!G14+'Mall, Citadel, Rotana'!I14 -> 747 | AA12: ='Mall, Citadel, Rotana'!K14+'Mall, Citadel, Rotana'!M14 -> 640 | AB12: ='Mall, Citadel, Rotana'!O14 -> 6 | AC12: ='Mall, Citadel, Rotana'!Q14+'Mall, Citadel, Rotana'!S14 -> 102 | AD12: =(E12-H12-194)*0.1318 -> 111.08644 | AE12: =E12-H12-AD12-194 -> 731.75456
A13: Cairo at Nile Plaza | B13: =B12+1 -> 12 | C13: 1 | D13: 2019 | E13: =Water!C15 -> 1110 | F13: =Water!E15 -> 575.1 | G13: =Water!G15 -> 391.5 | H13: =Water!I15 -> 4.779 | I13: =ELECT.!F15 -> 9508 | J13: =ELECT.!H15 -> 29953 | K13: =ELECT.!K15 -> 3491 | L13: =ELECT.!M15 -> 4283 | M13: =ELECT.!O15 -> 5142 | N13: =ELECT.!Q15 -> 2078 | O13: =ELECT.!S15 -> 7613 | P13: =ELECT.!W15*2 -> 16356 | Q13: =ELECT.!D15 -> 1280 | R13: =BTU!C14 -> 2 | S13: =BTU!F14 -> 0.38 | T13: =BTU!I14 -> 0 | U13: =BTU!O14 -> 1.149 | V13: =BTU!L14 -> 0.06 | W13: =BTU!R14 -> 0 | X13: =ELECT.!B15 -> 298 | Y13: =I13+J13-(K13+L13+M13+N13+O13+P13) -> 498 | Z13: ='Mall, Citadel, Rotana'!C15+'Mall, Citadel, Rotana'!E15+'Mall, Citadel, Rotana'!G15+'Mall, Citadel, Rotana'!I15 -> 1767 | AA13: ='Mall, Citadel, Rotana'!K15+'Mall, Citadel, Rotana'!M15 -> 0 | AB13: ='Mall, Citadel, Rotana'!O15 -> 0 | AC13: ='Mall, Citadel, Rotana'!Q15+'Mall, Citadel, Rotana'!S15 -> 96 | AD13: =(E13-H13-194)*0.1318 -> 120.09893 | AE13: =E13-H13-AD13-194 -> 791.12207
A14: Cairo at Nile Plaza | B14: =B13+1 -> 13 | C14: 1 | D14: 2019 | E14: =Water!C16 -> 1050 | F14: =Water!E16 -> 564.3 | G14: =Water!G16 -> 356.4 | H14: =Water!I16 -> 4.563 | I14: =ELECT.!F16 -> 16685 | J14: =ELECT.!H16 -> 53531 | K14: =ELECT.!K16 -> 6074 | L14: =ELECT.!M16 -> 8193 | M14: =ELECT.!O16 -> 8874 | N14: =ELECT.!Q16 -> 3472 | O14: =ELECT.!S16 -> 13540 | P14: =ELECT.!W16*2 -> 29442 | Q14: =ELECT.!D16 -> 1280 | R14: =BTU!C15 -> 3.6 | S14: =BTU!F15 -> 0.4 | T14: =BTU!I15 -> 0 | U14: =BTU!O15 -> 0.8 | V14: =BTU!L15 -> 0.59 | W14: =BTU!R15 -> 0 | X14: =ELECT.!B16 -> 250 | Y14: =I14+J14-(K14+L14+M14+N14+O14+P14) -> 621 | Z14: ='Mall, Citadel, Rotana'!C16+'Mall, Citadel, Rotana'!E16+'Mall, Citadel, Rotana'!G16+'Mall, Citadel, Rotana'!I16 -> 1965 | AA14: ='Mall, Citadel, Rotana'!K16+'Mall, Citadel, Rotana'!M16 -> 320 | AB14: ='Mall, Citadel, Rotana'!O16 -> 0 | AC14: ='Mall, Citadel, Rotana'!Q16+'Mall, Citadel, Rotana'!S16 -> 97 | AD14: =(E14-H14-194)*0.1318 -> 112.2194 | AE14: =E14-H14-AD14-194 -> 739.2176
... A31: Cairo at Nile Plaza | B31: =B30+1 -> 30 | C31: 1 | D31: 2019 | E31: =Water!C33 -> 1080 | F31: =Water!E33 -> 510.3 | G31: =Water!G33 -> 413.1 | H31: =Water!I33 -> 3.996 | I31: =ELECT.!F33 -> 19432 | J31: =ELECT.!H33 -> 59082 | K31: =ELECT.!K33 -> 7979 | L31: =ELECT.!M33 -> 8733 | M31: =ELECT.!O33 -> 10494 | N31: =ELECT.!Q33 -> 3584 | O31: =ELECT.!S33 -> 14400 | P31: =ELECT.!W33*2 -> 32166 | Q31: =ELECT.!D33 -> 480 | R31: =BTU!C32 -> 0 | S31: =BTU!F32 -> 0 | T31: =BTU!I32 -> 0 | U31: =BTU!O32 -> 0 | V31: =BTU!L32 -> 0 | W31: =BTU!R32 -> 0 | X31: =ELECT.!B33 -> 331 | Y31: =I31+J31-(K31+L31+M31+N31+O31+P31) -> 1158 | Z31: ='Mall, Citadel, Rotana'!C33+'Mall, Citadel, Rotana'!E33+'Mall, Citadel, Rotana'!G33+'Mall, Citadel, Rotana'!I33 -> 1374 | AA31: ='Mall, Citadel, Rotana'!K33+'Mall, Citadel, Rotana'!M33 -> 640 | AB31: ='Mall, Citadel, Rotana'!O33 -> 2 | AC31: ='Mall, Citadel, Rotana'!Q33+'Mall, Citadel, Rotana'!S33 -> 88 | AD31: =(E31-H31-194)*0.1318 -> 116.24813 | AE31: =E31-H31-AD31-194 -> 765.75587
A32: Cairo at Nile Plaza | B32: 31 | C32: 1 | D32: 2019 | E32: =Water!C34 -> 1200 | F32: =Water!E34 -> 499.5 | G32: =Water!G34 -> 434.7 | H32: =Water!I34 -> 3.726 | I32: =ELECT.!F34 -> 5379 | J32: =ELECT.!H34 -> 17995 | K32: =ELECT.!K34 -> 1969 | L32: =ELECT.!M34 -> 2082 | M32: =ELECT.!O34 -> 3210 | N32: =ELECT.!Q34 -> 1115 | O32: =ELECT.!S34 -> 4462 | P32: =ELECT.!W34*2 -> 10150 | Q32: =ELECT.!D34 -> 640 | R32: =BTU!C33 -> 0 | S32: =BTU!F33 -> 0 | T32: =BTU!I33 -> 0 | U32: =BTU!O33 -> 0 | V32: =BTU!L33 -> 0 | W32: =BTU!R33 -> 0 | X32: =ELECT.!B34 -> 358 | Y32: =I32+J32-(K32+L32+M32+N32+O32+P32) -> 386 | Z32: ='Mall, Citadel, Rotana'!C34+'Mall, Citadel, Rotana'!E34+'Mall, Citadel, Rotana'!G34+'Mall, Citadel, Rotana'!I34 -> 1083 | AA32: ='Mall, Citadel, Rotana'!K34+'Mall, Citadel, Rotana'!M34 -> 640 | AB32: ='Mall, Citadel, Rotana'!O34 -> 2 | AC32: ='Mall, Citadel, Rotana'!Q34+'Mall, Citadel, Rotana'!S34 -> 59 | AD32: =(E32-H32-194)*0.1318 -> 132.09971 | AE32: =E32-H32-AD32-194 -> 870.17429

Sheet Mall, Citadel, Rotana
A1: Mall, Citadel and Rotana readings and cons. Jan 2019
A2: Day | B2: R1 | C2: Cons | D2: R2 | E2: Cons | F2: R3 | G2: Cons | H2: R4 | I2: Cons | J2: RO1 | K2: Cons | L2: RO2 | M2: Cons | N2: ROE | O2: Cons | P2: CIB. 1 | Q2: Cons | R2: CIB. E | S2: Cons
A3: Last | B3: 41222 | D3: 37066 | F3: 17159 | H3: 213152 | J3: 303515 | L3: 21668 | N3: 167792 | P3: 963408 | R3: 55047
A4: 43466 | B4: 41227 | C4: =(B4-B3)*600/5 -> 600 | D4: 37069 | E4: =(D4-D3)*800/5 -> 480 | F4: 17163 | G4: =(F4-F3)*100/5 -> 80 | H4: 213165 | I4: =H4-H3 -> 13 | J4: 303515 | K4: =J4-J3 -> 0 | L4: 21669 | M4: =(L4-L3)*800/5 -> 160 | N4: 167795 | O4: =N4-N3 -> 3 | P4: 963471 | Q4: =P4-P3 -> 63 | R4: 55047 | S4: =R4-R3 -> 0
A5: 43467 | B5: 41231 | C5: =(B5-B4)*600/5 -> 480 | D5: 37073 | E5: =(D5-D4)*800/5 -> 640 | F5: 17167 | G5: =(F5-F4)*100/5 -> 80 | H5: 213178 | I5: =H5-H4 -> 13 | J5: 303515 | K5: =J5-J4 -> 0 | L5: 21675 | M5: =(L5-L4)*800/5 -> 960 | N5: 167798 | O5: =N5-N4 -> 3 | P5: 963482 | Q5: =P5-P4 -> 11 | R5: 55047 | S5: =R5-R4 -> 0
A6: 43468 | B6: 41238 | C6: =(B6-B5)*600/5 -> 840 | D6: 37076 | E6: =(D6-D5)*800/5 -> 480 | F6: 17172 | G6: =(F6-F5)*100/5 -> 100 | H6: 213195 | I6: =H6-H5 -> 17 | J6: 303515 | K6: =J6-J5 -> 0 | L6: 21679 | M6: =(L6-L5)*800/5 -> 640 | N6: 167801 | O6: =N6-N5 -> 3 | P6: 963986 | Q6: =P6-P5 -> 504 | R6: 55047 | S6: =R6-R5 -> 0
A7: 43469 | B7: 41243 | C7: =(B7-B6)*600/5 -> 600 | D7: 37078 | E7: =(D7-D6)*800/5 -> 320 | F7: 17176 | G7: =(F7-F6)*100/5 -> 80 | H7: 213205 | I7: =H7-H6 -> 10 | J7: 303515 | K7: =J7-J6 -> 0 | L7: 21683 | M7: =(L7-L6)*800/5 -> 640 | N7: 167803 | O7: =N7-N6 -> 2 | P7: 963999 | Q7: =P7-P6 -> 13 | R7: 55047 | S7: =R7-R6 -> 0
A8: 43470 | B8: 41248 | C8: =(B8-B7)*600/5 -> 600 | D8: 37082 | E8: =(D8-D7)*800/5 -> 640 | F8: 17180 | G8: =(F8-F7)*100/5 -> 80 | H8: 213224 | I8: =H8-H7 -> 19 | J8: 303515 | K8: =J8-J7 -> 0 | L8: 21685 | M8: =(L8-L7)*800/5 -> 320 | N8: 167807 | O8: =N8-N7 -> 4 | P8: 964206 | Q8: =P8-P7 -> 207 | R8: 55047 | S8: =R8-R7 -> 0
A9: 43471 | B9: 41254 | C9: =(B9-B8)*600/5 -> 720 | D9: 37085 | E9: =(D9-D8)*800/5 -> 480 | F9: 17185 | G9: =(F9-F8)*100/5 -> 100 | H9: 213240 | I9: =H9-H8 -> 16 | J9: 303515 | K9: =J9-J8 -> 0 | L9: 21690 | M9: =(L9-L8)*800/5 -> 800 | N9: 167810 | O9: =N9-N8 -> 3 | P9: 964406 | Q9: =P9-P8 -> 200 | R9: 55047 | S9: =R9-R8 -> 0
A10: 43472 | B10: 41259 | C10: =(B10-B9)*600/5 -> 600 | D10: 37087 | E10: =(D10-D9)*800/5 -> 320 | F10: 17189 | G10: =(F10-F9)*100/5 -> 80 | H10: 213251 | I10: =H10-H9 -> 11 | J10: 303515 | K10: =J10-J9 -> 0 | L10: 21693 | M10: =(L10-L9)*800/5 -> 480 | N10: 167813 | O10: =N10-N9 -> 3 | P10: 964609 | Q10: =P10-P9 -> 203 | R10: 55047 | S10: =R10-R9 -> 0
A11: 43473 | B11: 41264 | C11: =(B11-B10)*600/5 -> 600 | D11: 37092 | E11: =(D11-D10)*800/5 -> 800 | F11: 17192 | G11: =(F11-F10)*100/5 -> 60 | H11: 213265 | I11: =H11-H10 -> 14 | J11: 303515 | K11: =J11-J10 -> 0 | L11: 21697 | M11: =(L11-L10)*800/5 -> 640 | N11: 167816 | O11: =N11-N10 -> 3 | P11: 964814 | Q11: =P11-P10 -> 205 | R11: 55047 | S11: =R11-R10 -> 0
A12: 43474 | B12: 41270 | C12: =(B12-B11)*600/5 -> 720 | D12: 37095 | E12: =(D12-D11)*800/5 -> 480 | F12: 17199 | G12: =(F12-F11)*100/5 -> 140 | H12: 213277 | I12: =H12-H11 -> 12 | J12: 303515 | K12: =J12-J11 -> 0 | L12: 21703 | M12: =(L12-L11)*800/5 -> 960 | N12: 167818 | O12: =N12-N11 -> 2 | P12: 964908 | Q12: =P12-P11 -> 94 | R12: 55047 | S12: =R12-R11 -> 0
A13: 43475 | B13: 41275 | C13: =(B13-B12)*600/5 -> 600 | D13: 37098 | E13: =(D13-D12)*800/5 -> 480 | F13: 17204 | G13: =(F13-F12)*100/5 -> 100 | H13: 213286 | I13: =H13-H12 -> 9 | J13: 303515 | K13: =J13-J12 -> 0 | L13: 21709 | M13: =(L13-L12)*800/5 -> 960 | N13: 167821 | O13: =N13-N12 -> 3 | P13: 965006 | Q13: =P13-P12 -> 98 | R13: 55047 | S13: =R13-R12 -> 0
A14: 43476 | B14: 41279 | C14: =(B14-B13)*600/5 -> 480 | D14: 37099 | E14: =(D14-D13)*800/5 -> 160 | F14: 17209 | G14: =(F14-F13)*100/5 -> 100 | H14: 213293 | I14: =H14-H13 -> 7 | J14: 303515 | K14: =J14-J13 -> 0 | L14: 21713 | M14: =(L14-L13)*800/5 -> 640 | N14: 167827 | O14: =N14-N13 -> 6 | P14: 965108 | Q14: =P14-P13 -> 102 | R14: 55047 | S14: =R14-R13 -> 0
A15: 43477 | B15: 41285 | C15: =(B15-B14)*600/5 -> 720 | D15: 37105 | E15: =(D15-D14)*800/5 -> 960 | F15: 17212 | G15: =(F15-F14)*100/5 -> 60 | H15: 213320 | I15: =H15-H14 -> 27 | J15: 303515 | K15: =J15-J14 -> 0 | L15: 21713 | M15: =(L15-L14)*800/5 -> 0 | N15: 167827 | O15: =N15-N14 -> 0 | P15: 965204 | Q15: =P15-P14 -> 96 | R15: 55047 | S15: =R15-R14 -> 0
... A34: 43496 | B34: 41381 | C34: =(B34-B33)*600/5 -> 360 | D34: 37167 | E34: =(D34-D33)*800/5 -> 640 | F34: 17292 | G34: =(F34-F33)*100/5 -> 80 | H34: 213570 | I34: =H34-H33 -> 3 | J34: 303515 | K34: =J34-J33 -> 0 | L34: 21793 | M34: =(L34-L33)*800/5 -> 640 | N34: 167881 | O34: =N34-N33 -> 2 | P34: 967830 | Q34: =P34-P33 -> 59 | R34: 55047 | S34: =R34-R33 -> 0
A35: Total | C35: =SUM(C4:C34) -> 19080 | E35: =SUM(E4:E34) -> 16160 | G35: =SUM(G4:G34) -> 2660 | I35: =SUM(I4:I34) -> 418 | K35: =SUM(K4:K34) -> 0 | M35: =SUM(M4:M34) -> 20000 | O35: =SUM(O4:O34) -> 89 | Q35: =SUM(Q4:Q34) -> 4422 | S35: =SUM(S4:S34) -> 0

Sheet Water
A1: Main Building, Podium, Hotel and Large cons. Jan 2019
A2: Day | B2: Main Reading | C2: Cons. | D2: Podium | E2: Cons. | F2: Hotel | G2: Cons. | H2: Large | I2: Cons. | J2: Total | K2: cost.LE
A3: Last | B3: 339105 | C3: 0 | D3: 91386700 | E3: 0 | F3: 91599400 | G3: 0 | H3: 590400 | I3: 0 | J3: =C3+E3+G3+I3 -> 0 | K3: =J3*5.86 -> 0
A4: 43466 | B4: 339211 | C4: =(IF((B4-B3)<0,"0",(B4-B3)))*10 -> 1060 | D4: 91407400 | E4: =(IF((D4-D3)<0,"0",(D4-D3)))*0.027 -> 558.9 | F4: 91617000 | G4: =(IF((F4-F3)<0,"0",(F4-F3)))*0.027 -> 475.2 | H4: 590593 | I4: =(IF((H4-H3)<0,"0",(H4-H3)))*0.027 -> 5.211 | J4: =C4+E4+G4+I4 -> 2099.311 | K4: =J4*5.86 -> 12301.962
A5: 43467 | B5: 339276 | C5: =(IF((B5-B4)<0,"0",(B5-B4)))*10 -> 650 | D5: 91430000 | E5: =(IF((D5-D4)<0,"0",(D5-D4)))*0.027 -> 610.2 | F5: 91639000 | G5: =(IF((F5-F4)<0,"0",(F5-F4)))*0.027 -> 594 | H5: 590810 | I5: =(IF((H5-H4)<0,"0",(H5-H4)))*0.027 -> 5.859 | J5: =C5+E5+G5+I5 -> 1860.059 | K5: =J5*5.86 -> 10899.946
A6: 43468 | B6: 339361 | C6: =(IF((B6-B5)<0,"0",(B6-B5)))*10 -> 850 | D6: 91455200 | E6: =(IF((D6-D5)<0,"0",(D6-D5)))*0.027 -> 680.4 | F6: 91655200 | G6: =(IF((F6-F5)<0,"0",(F6-F5)))*0.027 -> 437.4 | H6: 591038 | I6: =(IF((H6-H5)<0,"0",(H6-H5)))*0.027 -> 6.156 | J6: =C6+E6+G6+I6 -> 1973.956 | K6: =J6*5.86 -> 11567.382
A7: 43469 | B7: 339499 | C7: =(IF((B7-B6)<0,"0",(B7-B6)))*10 -> 1380 | D7: 91473300 | E7: =(IF((D7-D6)<0,"0",(D7-D6)))*0.027 -> 488.7 | F7: 91664000 | G7: =(IF((F7-F6)<0,"0",(F7-F6)))*0.027 -> 237.6 | H7: 591196 | I7: =(IF((H7-H6)<0,"0",(H7-H6)))*0.027 -> 4.266 | J7: =C7+E7+G7+I7 -> 2110.566 | K7: =J7*5.86 -> 12367.917
A8: 43470 | B8: 339620 | C8: =(IF((B8-B7)<0,"0",(B8-B7)))*10 -> 1210 | D8: 91496600 | E8: =(IF((D8-D7)<0,"0",(D8-D7)))*0.027 -> 629.1 | F8: 91680000 | G8: =(IF((F8-F7)<0,"0",(F8-F7)))*0.027 -> 432 | H8: 591433 | I8: =(IF((H8-H7)<0,"0",(H8-H7)))*0.027 -> 6.399 | J8: =C8+E8+G8+I8 -> 2277.499 | K8: =J8*5.86 -> 13346.144
A9: 43471 | B9: 339733 | C9: =(IF((B9-B8)<0,"0",(B9-B8)))*10 -> 1130 | D9: 91520000 | E9: =(IF((D9-D8)<0,"0",(D9-D8)))*0.027 -> 631.8 | F9: 91692000 | G9: =(IF((F9-F8)<0,"0",(F9-F8)))*0.027 -> 324 | H9: 591675 | I9: =(IF((H9-H8)<0,"0",(H9-H8)))*0.027 -> 6.534 | J9: =C9+E9+G9+I9 -> 2092.334 | K9: =J9*5.86 -> 12261.077
A10: 43472 | B10: 339850 | C10: =(IF((B10-B9)<0,"0",(B10-B9)))*10 -> 1170 | D10: 91544800 | E10: =(IF((D10-D9)<0,"0",(D10-D9)))*0.027 -> 669.6 | F10: 91703900 | G10: =(IF((F10-F9)<0,"0",(F10-F9)))*0.027 -> 321.3 | H10: 591905 | I10: =(IF((H10-H9)<0,"0",(H10-H9)))*0.027 -> 6.21 | J10: =C10+E10+G10+I10 -> 2167.11 | K10: =J10*5.86 -> 12699.265
A11: 43473 | B11: 339937 | C11: =(IF((B11-B10)<0,"0",(B11-B10)))*10 -> 870 | D11: 91562000 | E11: =(IF((D11-D10)<0,"0",(D11-D10)))*0.027 -> 464.4 | F11: 91713000 | G11: =(IF((F11-F10)<0,"0",(F11-F10)))*0.027 -> 245.7 | H11: 592124 | I11: =(IF((H11-H10)<0,"0",(H11-H10)))*0.027 -> 5.913 | J11: =C11+E11+G11+I11 -> 1586.013 | K11: =J11*5.86 -> 9294.0362
A12: 43474 | B12: 340064 | C12: =(IF((B12-B11)<0,"0",(B12-B11)))*10 -> 1270 | D12: 91584400 | E12: =(IF((D12-D11)<0,"0",(D12-D11)))*0.027 -> 604.8 | F12: 91727500 | G12: =(IF((F12-F11)<0,"0",(F12-F11)))*0.027 -> 391.5 | H12: 592365 | I12: =(IF((H12-H11)<0,"0",(H12-H11)))*0.027 -> 6.507 | J12: =C12+E12+G12+I12 -> 2272.807 | K12: =J12*5.86 -> 13318.649
A13: 43475 | B13: 340171 | C13: =(IF((B13-B12)<0,"0",(B13-B12)))*10 -> 1070 | D13: 91605800 | E13: =(IF((D13-D12)<0,"0",(D13-D12)))*0.027 -> 577.8 | F13: 91745000 | G13: =(IF((F13-F12)<0,"0",(F13-F12)))*0.027 -> 472.5 | H13: 592547 | I13: =(IF((H13-H12)<0,"0",(H13-H12)))*0.027 -> 4.914 | J13: =C13+E13+G13+I13 -> 2125.214 | K13: =J13*5.86 -> 12453.754
A14: 43476 | B14: 340275 | C14: =(IF((B14-B13)<0,"0",(B14-B13)))*10 -> 1040 | D14: 91626000 | E14: =(IF((D14-D13)<0,"0",(D14-D13)))*0.027 -> 545.4 | F14: 91758500 | G14: =(IF((F14-F13)<0,"0",(F14-F13)))*0.027 -> 364.5 | H14: 592664 | I14: =(IF((H14-H13)<0,"0",(H14-H13)))*0.027 -> 3.159 | J14: =C14+E14+G14+I14 -> 1953.059 | K14: =J14*5.86 -> 11444.926
A15: 43477 | B15: 340386 | C15: =(IF((B15-B14)<0,"0",(B15-B14)))*10 -> 1110 | D15: 91647300 | E15: =(IF((D15-D14)<0,"0",(D15-D14)))*0.027 -> 575.1 | F15: 91773000 | G15: =(IF((F15-F14)<0,"0",(F15-F14)))*0.027 -> 391.5 | H15: 592841 | I15: =(IF((H15-H14)<0,"0",(H15-H14)))*0.027 -> 4.779 | J15: =C15+E15+G15+I15 -> 2081.379 | K15: =J15*5.86 -> 12196.881
... A18: 43480 | B18: 340699 | C18: =(IF((B18-B17)<0,"0",(B18-B17)))*10 -> 1240 | D18: 91711000 | E18: =(IF((D18-D17)<0,"0",(D18-D17)))*0.027 -> 540 | F18: 91812400 | G18: =(IF((F18-F17)<0,"0",(F18-F17)))*0.027 -> 337.5 | H18: 593407 | I18: =(IF((H18-H17)<0,"0",(H18-H17)))*0.027 -> 5.535 | J18: =C18+E18+G18+I18 -> 2123.035 | K18: =J18*5.86 -> 12440.985
A19: 43481 | B19: 340789 | C19: =(IF((B19-B18)<0,"0",(B19-B18)))*10 -> 900 | D19: 91727500 | E19: =(IF((D19-D18)<0,"0",(D19-D18)))*0.027 -> 445.5 | F19: 91824200 | G19: =(IF((F19-F18)<0,"0",(F19-F18)))*0.027 -> 318.6 | H19: 593557 | I19: =(IF((H19-H18)<0,"0",(H19-H18)))*0.027 -> 4.05 | J19: =C19+E19+G19+I19 -> 1668.15 | K19: =J19*5.86 -> 9775.359 | Q19: `
A20: 43482 | B20: 340895 | C20: =(IF((B20-B19)<0,"0",(B20-B19)))*10 -> 1060 | D20: 91746100 | E20: =(IF((D20-D19)<0,"0",(D20-D19)))*0.027 -> 502.2 | F20: 91840700 | G20: =(IF((F20-F19)<0,"0",(F20-F19)))*0.027 -> 445.5 | H20: 593731 | I20: =(IF((H20-H19)<0,"0",(H20-H19)))*0.027 -> 4.698 | J20: =C20+E20+G20+I20 -> 2012.398 | K20: =J20*5.86 -> 11792.652
A21: 43483 | B21: 341016 | C21: =(IF((B21-B20)<0,"0",(B21-B20)))*10 -> 1210 | D21: 91763400 | E21: =(IF((D21-D20)<0,"0",(D21-D20)))*0.027 -> 467.1 | F21: 91853400 | G21: =(IF((F21-F20)<0,"0",(F21-F20)))*0.027 -> 342.9 | H21: 593866 | I21: =(IF((H21-H20)<0,"0",(H21-H20)))*0.027 -> 3.645 | J21: =C21+E21+G21+I21 -> 2023.645 | K21: =J21*5.86 -> 11858.56
A22: 43484 | B22: 341116 | C22: =(IF((B22-B21)<0,"0",(B22-B21)))*10 -> 1000 | D22: 91780500 | E22: =(IF((D22-D21)<0,"0",(D22-D21)))*0.027 -> 461.7 | F22: 91867600 | G22: =(IF((F22-F21)<0,"0",(F22-F21)))*0.027 -> 383.4 | H22: 594031 | I22: =(IF((H22-H21)<0,"0",(H22-H21)))*0.027 -> 4.455 | J22: =C22+E22+G22+I22 -> 1849.555 | K22: =J22*5.86 -> 10838.392
A23: 43485 | B23: 341223 | C23: =(IF((B23-B22)<0,"0",(B23-B22)))*10 -> 1070 | D23: 91799400 | E23: =(IF((D23-D22)<0,"0",(D23-D22)))*0.027 -> 510.3 | F23: 91881300 | G23: =(IF((F23-F22)<0,"0",(F23-F22)))*0.027 -> 369.9 | H23: 594234 | I23: =(IF((H23-H22)<0,"0",(H23-H22)))*0.027 -> 5.481 | J23: =C23+E23+G23+I23 -> 1955.681 | K23: =J23*5.86 -> 11460.291
A24: 43486 | B24: 341346 | C24: =(IF((B24-B23)<0,"0",(B24-B23)))*10 -> 1230 | D24: 91819400 | E24: =(IF((D24-D23)<0,"0",(D24-D23)))*0.027 -> 540 | F24: 91896000 | G24: =(IF((F24-F23)<0,"0",(F24-F23)))*0.027 -> 396.9 | H24: 594362 | I24: =(IF((H24-H23)<0,"0",(H24-H23)))*0.027 -> 3.456 | J24: =C24+E24+G24+I24 -> 2170.356 | K24: =J24*5.86 -> 12718.286
A25: 43487 | B25: 341440 | C25: =(IF((B25-B24)<0,"0",(B25-B24)))*10 -> 940 | D25: 91837100 | E25: =(IF((D25-D24)<0,"0",(D25-D24)))*0.027 -> 477.9 | F25: 91910200 | G25: =(IF((F25-F24)<0,"0",(F25-F24)))*0.027 -> 383.4 | H25: 594528 | I25: =(IF((H25-H24)<0,"0",(H25-H24)))*0.027 -> 4.482 | J25: =C25+E25+G25+I25 -> 1805.782 | K25: =J25*5.86 -> 10581.883
A26: 43488 | B26: 341530 | C26: =(IF((B26-B25)<0,"0",(B26-B25)))*10 -> 900 | D26: 91854700 | E26: =(IF((D26-D25)<0,"0",(D26-D25)))*0.027 -> 475.2 | F26: 91923200 | G26: =(IF((F26-F25)<0,"0",(F26-F25)))*0.027 -> 351 | H26: 594687 | I26: =(IF((H26-H25)<0,"0",(H26-H25)))*0.027 -> 4.293 | J26: =C26+E26+G26+I26 -> 1730.493 | K26: =J26*5.86 -> 10140.689
A27: 43489 | B27: 341620 | C27: =(IF((B27-B26)<0,"0",(B27-B26)))*10 -> 900 | D27: 91870400 | E27: =(IF((D27-D26)<0,"0",(D27-D26)))*0.027 -> 423.9 | F27: 91936000 | G27: =(IF((F27-F26)<0,"0",(F27-F26)))*0.027 -> 345.6 | H27: 594838 | I27: =(IF((H27-H26)<0,"0",(H27-H26)))*0.027 -> 4.077 | J27: =C27+E27+G27+I27 -> 1673.577 | K27: =J27*5.86 -> 9807.1612
A28: 43490 | B28: 341713 | C28: =(IF((B28-B27)<0,"0",(B28-B27)))*10 -> 930 | D28: 91886100 | E28: =(IF((D28-D27)<0,"0",(D28-D27)))*0.027 -> 423.9 | F28: 91949400 | G28: =(IF((F28-F27)<0,"0",(F28-F27)))*0.027 -> 361.8 | H28: 594958 | I28: =(IF((H28-H27)<0,"0",(H28-H27)))*0.027 -> 3.24 | J28: =C28+E28+G28+I28 -> 1718.94 | K28: =J28*5.86 -> 10072.988
A29: 43491 | B29: 341806 | C29: =(IF((B29-B28)<0,"0",(B29-B28)))*10 -> 930 | D29: 91901600 | E29: =(IF((D29-D28)<0,"0",(D29-D28)))*0.027 -> 418.5 | F29: 91963300 | G29: =(IF((F29-F28)<0,"0",(F29-F28)))*0.027 -> 375.3 | H29: 595113 | I29: =(IF((H29-H28)<0,"0",(H29-H28)))*0.027 -> 4.185 | J29: =C29+E29+G29+I29 -> 1727.985 | K29: =J29*5.86 -> 10125.992
A30: 43492 | B30: 341908 | C30: =(IF((B30-B29)<0,"0",(B30-B29)))*10 -> 1020 | D30: 91919600 | E30: =(IF((D30-D29)<0,"0",(D30-D29)))*0.027 -> 486 | F30: 91978200 | G30: =(IF((F30-F29)<0,"0",(F30-F29)))*0.027 -> 402.3 | H30: 595265 | I30: =(IF((H30-H29)<0,"0",(H30-H29)))*0.027 -> 4.104 | J30: =C30+E30+G30+I30 -> 1912.404 | K30: =J30*5.86 -> 11206.687
A31: 43493 | B31: 342024 | C31: =(IF((B31-B30)<0,"0",(B31-B30)))*10 -> 1160 | D31: 91939100 | E31: =(IF((D31-D30)<0,"0",(D31-D30)))*0.027 -> 526.5 | F31: 91997500 | G31: =(IF((F31-F30)<0,"0",(F31-F30)))*0.027 -> 521.1 | H31: 595433 | I31: =(IF((H31-H30)<0,"0",(H31-H30)))*0.027 -> 4.536 | J31: =C31+E31+G31+I31 -> 2212.136 | K31: =J31*5.86 -> 12963.117
... A33: 43495 | B33: 342227 | C33: =(IF((B33-B32)<0,"0",(B33-B32)))*10 -> 1080 | D33: 91973500 | E33: =(IF((D33-D32)<0,"0",(D33-D32)))*0.027 -> 510.3 | F33: 92026300 | G33: =(IF((F33-F32)<0,"0",(F33-F32)))*0.027 -> 413.1 | H33: 595730 | I33: =(IF((H33-H32)<0,"0",(H33-H32)))*0.027 -> 3.996 | J33: =C33+E33+G33+I33 -> 2007.396 | K33: =J33*5.86 -> 11763.341
A34: 43496 | B34: 342347 | C34: =(IF((B34-B33)<0,"0",(B34-B33)))*10 -> 1200 | D34: 91992000 | E34: =(IF((D34-D33)<0,"0",(D34-D33)))*0.027 -> 499.5 | F34: 92042400 | G34: =(IF((F34-F33)<0,"0",(F34-F33)))*0.027 -> 434.7 | H34: 595868 | I34: =(IF((H34-H33)<0,"0",(H34-H33)))*0.027 -> 3.726
A35: Total | C35: =SUM(C4:C34) -> 32420 | E35: =SUM(E4:E34) -> 16343.1 | G35: =SUM(G4:G34) -> 11961 | I35: =SUM(I4:I34) -> 147.636 | J35: =SUM(J4:J31) -> 54989.391 | K35: =SUM(K4:K31) -> 322237.83

Sheet ELECT.
A1: Feeders and transformers Electrity cons. Dec 2019
A2: Day | B2: Rooms Sold | C2: New Chillers | D2: Cons | E2: F-1 | F2: Cons. | G2: F-2 | H2: Cons. | I2: Total | J2: T-1 | K2: Cons. | L2: T-2 | M2: Cons. | N2: T-3 | O2: Cons. | P2: T-4 | Q2: Cons. | R2: T-5 | S2: Cons. | T2: T-6 | U2: Cons. | V2: T-7 | W2: Cons. | X2: Total | Y2: Diff | Z2: Daily Money Value | AA2: MTD Total Money
A3: Last | B3: 270 | C3: 14870 | D3: 0 | E3: 15259933 | F3: 0 | G3: 39367646 | H3: 0 | I3: 0 | J3: 3282768 | K3: 0 | L3: 3401304 | M3: 0 | N3: 2186588 | O3: 0 | P3: 4537644 | Q3: 0 | R3: 8859895 | S3: 0 | T3: 0 | V3: 5223635 | W3: 0
A4: 43466 | B4: 265 | C4: 14878 | D4: =IF((C4-C3)<0,"0",(C4-C3))*160 -> 1280 | E4: 15277797 | F4: =IF((E4-E3)<0,"0",(E4-E3)) -> 17864 | G4: 39423364 | H4: =IF((G4-G3)<0,"0",(G4-G3)) -> 55718 | I4: =F4+H4 -> 73582 | J4: 3290150 | K4: =IF((J4-J3)<0,"0",(J4-J3)) -> 7382 | L4: 3409363 | M4: =IF((L4-L3)<0,"0",(L4-L3)) -> 8059 | N4: 2191448 | O4: =(IF((N4-N3)<0,"0",(N4-N3)))*2 -> 9720 | P4: 4542498 | Q4: =IF((P4-P3)<0,"0",(P4-P3)) -> 4854 | R4: 8873508 | S4: =IF((R4-R3)<0,"0",(R4-R3)) -> 13613 | T4: 0 | V4: 5238579 | W4: =IF((V4-V3)<0,"0",(V4-V3)) -> 14944 | X4: =K4+M4+O4+Q4+S4+U4+W4 -> 58572 | Y4: =I4-X4 -> 15010 | Z4: =(0.93352*(W4+S4)+0.5568*(Q4+O4))*0.26 -> 9041.0668 | AA4: =SUM(Z1:Z4) -> 9041.0668
A5: 43467 | B5: 284 | C5: 14886 | D5: =IF((C5-C4)<0,"0",(C5-C4))*160 -> 1280 | E5: 15289655 | F5: =IF((E5-E4)<0,"0",(E5-E4)) -> 11858 | G5: 39459534 | H5: =IF((G5-G4)<0,"0",(G5-G4)) -> 36170 | I5: =F5+H5 -> 48028 | J5: 3294096 | K5: =IF((J5-J4)<0,"0",(J5-J4)) -> 3946 | L5: 3414609 | M5: =IF((L5-L4)<0,"0",(L5-L4)) -> 5246 | N5: 2194675 | O5: =(IF((N5-N4)<0,"0",(N5-N4)))*2 -> 6454 | P5: 4544271 | Q5: =IF((P5-P4)<0,"0",(P5-P4)) -> 1773 | R5: 8882447 | S5: =IF((R5-R4)<0,"0",(R5-R4)) -> 8939 | T5: 0 | V5: 5248518 | W5: =IF((V5-V4)<0,"0",(V5-V4)) -> 9939 | X5: =K5+M5+O5+Q5+S5+U5+W5 -> 36297 | Y5: =I5-X5 -> 11731 | Z5: =(0.93352*(W5+S5)+0.5568*(Q5+O5))*0.26 -> 5772.9839 | AA5: =SUM(Z2:Z5) -> 14814.051
A6: 43468 | B6: 316 | C6: 14894 | D6: =IF((C6-C5)<0,"0",(C6-C5))*160 -> 1280 | E6: 15308424 | F6: =IF((E6-E5)<0,"0",(E6-E5)) -> 18769 | G6: 39518154 | H6: =IF((G6-G5)<0,"0",(G6-G5)) -> 58620 | I6: =F6+H6 -> 77389 | J6: 3300500 | K6: =IF((J6-J5)<0,"0",(J6-J5)) -> 6404 | L6: 3422643 | M6: =IF((L6-L5)<0,"0",(L6-L5)) -> 8034 | N6: 2199945 | O6: =(IF((N6-N5)<0,"0",(N6-N5)))*2 -> 10540 | P6: 4548480 | Q6: =IF((P6-P5)<0,"0",(P6-P5)) -> 4209 | R6: 8897705 | S6: =IF((R6-R5)<0,"0",(R6-R5)) -> 15258 | T6: 0 | V6: 5264398 | W6: =IF((V6-V5)<0,"0",(V6-V5)) -> 15880 | X6: =K6+M6+O6+Q6+S6+U6+W6 -> 60325 | Y6: =I6-X6 -> 17064 | Z6: =(0.93352*(W6+S6)+0.5568*(Q6+O6))*0.26 -> 9692.8491 | AA6: =SUM(Z3:Z6) -> 24506.9
A7: 43469 | B7: 316 | C7: 14902 | D7: =IF((C7-C6)<0,"0",(C7-C6))*160 -> 1280 | E7: 15323210 | F7: =IF((E7-E6)<0,"0",(E7-E6)) -> 14786 | G7: 39565913 | H7: =IF((G7-G6)<0,"0",(G7-G6)) -> 47759 | I7: =F7+H7 -> 62545 | J7: 3305784 | K7: =IF((J7-J6)<0,"0",(J7-J6)) -> 5284 | L7: 3428712 | M7: =IF((L7-L6)<0,"0",(L7-L6)) -> 6069 | N7: 2204191 | O7: =(IF((N7-N6)<0,"0",(N7-N6)))*2 -> 8492 | P7: 4552204 | Q7: =IF((P7-P6)<0,"0",(P7-P6)) -> 3724 | R7: 8909868 | S7: =IF((R7-R6)<0,"0",(R7-R6)) -> 12163 | T7: 0 | V7: 5277235 | W7: =IF((V7-V6)<0,"0",(V7-V6)) -> 12837 | X7: =K7+M7+O7+Q7+S7+U7+W7 -> 48569 | Y7: =I7-X7 -> 13976 | Z7: =(0.93352*(W7+S7)+0.5568*(Q7+O7))*0.26 -> 7836.3659 | AA7: =SUM(Z4:Z7) -> 32343.266
A8: 43470 | B8: 318 | C8: 14910 | D8: =IF((C8-C7)<0,"0",(C8-C7))*160 -> 1280 | E8: 15335720 | F8: =IF((E8-E7)<0,"0",(E8-E7)) -> 12510 | G8: 39605271 | H8: =IF((G8-G7)<0,"0",(G8-G7)) -> 39358 | I8: =F8+H8 -> 51868 | J8: 3311312 | K8: =IF((J8-J7)<0,"0",(J8-J7)) -> 5528 | L8: 3434193 | M8: =IF((L8-L7)<0,"0",(L8-L7)) -> 5481 | N8: 2207644 | O8: =(IF((N8-N7)<0,"0",(N8-N7)))*2 -> 6906 | P8: 4555753 | Q8: =IF((P8-P7)<0,"0",(P8-P7)) -> 3549 | R8: 8919409 | S8: =IF((R8-R7)<0,"0",(R8-R7)) -> 9541 | T8: 0 | V8: 5287628 | W8: =IF((V8-V7)<0,"0",(V8-V7)) -> 10393 | X8: =K8+M8+O8+Q8+S8+U8+W8 -> 41398 | Y8: =I8-X8 -> 10470 | Z8: =(0.93352*(W8+S8)+0.5568*(Q8+O8))*0.26 -> 6351.8342 | AA8: =SUM(Z5:Z8) -> 29654.033
A9: 43471 | B9: 270 | C9: 14918 | D9: =IF((C9-C8)<0,"0",(C9-C8))*160 -> 1280 | E9: 15347093 | F9: =IF((E9-E8)<0,"0",(E9-E8)) -> 11373 | G9: 39641666 | H9: =IF((G9-G8)<0,"0",(G9-G8)) -> 36395 | I9: =F9+H9 -> 47768 | J9: 3316523 | K9: =IF((J9-J8)<0,"0",(J9-J8)) -> 5211 | L9: 3439108 | M9: =IF((L9-L8)<0,"0",(L9-L8)) -> 4915 | N9: 2210804 | O9: =(IF((N9-N8)<0,"0",(N9-N8)))*2 -> 6320 | P9: 4557944 | Q9: =IF((P9-P8)<0,"0",(P9-P8)) -> 2191 | R9: 8928158 | S9: =IF((R9-R8)<0,"0",(R9-R8)) -> 8749 | T9: 0 | V9: 5297152 | W9: =IF((V9-V8)<0,"0",(V9-V8)) -> 9524 | X9: =K9+M9+O9+Q9+S9+U9+W9 -> 36910 | Y9: =I9-X9 -> 10858 | Z9: =(0.93352*(W9+S9)+0.5568*(Q9+O9))*0.26 -> 5667.2553 | AA9: =SUM(Z6:Z9) -> 29548.305
A10: 43472 | B10: 258 | C10: 14926 | D10: =IF((C10-C9)<0,"0",(C10-C9))*160 -> 1280 | E10: 15363802 | F10: =IF((E10-E9)<0,"0",(E10-E9)) -> 16709 | G10: 39695632 | H10: =IF((G10-G9)<0,"0",(G10-G9)) -> 53966 | I10: =F10+H10 -> 70675 | J10: 3322585 | K10: =IF((J10-J9)<0,"0",(J10-J9)) -> 6062 | L10: 3446380 | M10: =IF((L10-L9)<0,"0",(L10-L9)) -> 7272 | N10: 2215426 | O10: =(IF((N10-N9)<0,"0",(N10-N9)))*2 -> 9244 | P10: 4562038 | Q10: =IF((P10-P9)<0,"0",(P10-P9)) -> 4094 | R10: 8942145 | S10: =IF((R10-R9)<0,"0",(R10-R9)) -> 13987 | T10: 0 | V10: 5311627 | W10: =IF((V10-V9)<0,"0",(V10-V9)) -> 14475 | X10: =K10+M10+O10+Q10+S10+U10+W10 -> 55134 | Y10: =I10-X10 -> 15541 | Z10: =(0.93352*(W10+S10)+0.5568*(Q10+O10))*0.26 -> 8839.0756 | AA10: =SUM(Z7:Z10) -> 28694.531
A11: 43473 | B11: 263 | C11: 14934 | D11: =IF((C11-C10)<0,"0",(C11-C10))*160 -> 1280 | E11: 15376825 | F11: =IF((E11-E10)<0,"0",(E11-E10)) -> 13023 | G11: 39737512 | H11: =IF((G11-G10)<0,"0",(G11-G10)) -> 41880 | I11: =F11+H11 -> 54903 | J11: 3327392 | K11: =IF((J11-J10)<0,"0",(J11-J10)) -> 4807 | L11: 3452180 | M11: =IF((L11-L10)<0,"0",(L11-L10)) -> 5800 | N11: 2218953 | O11: =(IF((N11-N10)<0,"0",(N11-N10)))*2 -> 7054 | P11: 4565743 | Q11: =IF((P11-P10)<0,"0",(P11-P10)) -> 3705 | R11: 8952900 | S11: =IF((R11-R10)<0,"0",(R11-R10)) -> 10755 | T11: 0 | V11: 5322886 | W11: =IF((V11-V10)<0,"0",(V11-V10)) -> 11259 | X11: =K11+M11+O11+Q11+S11+U11+W11 -> 43380 | Y11: =I11-X11 -> 11523 | Z11: =(0.93352*(W11+S11)+0.5568*(Q11+O11))*0.26 -> 6900.6913 | AA11: =SUM(Z8:Z11) -> 27758.856
A12: 43474 | B12: 263 | C12: 14942 | D12: =IF((C12-C11)<0,"0",(C12-C11))*160 -> 1280 | E12: 15391911 | F12: =IF((E12-E11)<0,"0",(E12-E11)) -> 15086 | G12: 39787843 | H12: =IF((G12-G11)<0,"0",(G12-G11)) -> 50331 | I12: =F12+H12 -> 65417 | J12: 3333568 | K12: =IF((J12-J11)<0,"0",(J12-J11)) -> 6176 | L12: 3458838 | M12: =IF((L12-L11)<0,"0",(L12-L11)) -> 6658 | N12: 2223086 | O12: =(IF((N12-N11)<0,"0",(N12-N11)))*2 -> 8266 | P12: 4568656 | Q12: =IF((P12-P11)<0,"0",(P12-P11)) -> 2913 | R12: 8965978 | S12: =IF((R12-R11)<0,"0",(R12-R11)) -> 13078 | T12: 0 | V12: 5336514 | W12: =IF((V12-V11)<0,"0",(V12-V11)) -> 13628 | X12: =K12+M12+O12+Q12+S12+U12+W12 -> 50719 | Y12: =I12-X12 -> 14698 | Z12: =(0.93352*(W12+S12)+0.5568*(Q12+O12))*0.26 -> 8100.3136 | AA12: =SUM(Z9:Z12) -> 29507.336
A13: 43475 | B13: 268 | C13: 14950 | D13: =IF((C13-C12)<0,"0",(C13-C12))*160 -> 1280 | E13: 15402047 | F13: =IF((E13-E12)<0,"0",(E13-E12)) -> 10136 | G13: 39829582 | H13: =IF((G13-G12)<0,"0",(G13-G12)) -> 41739 | I13: =F13+H13 -> 51875 | J13: 3339582 | K13: =IF((J13-J12)<0,"0",(J13-J12)) -> 6014 | L13: 3463430 | M13: =IF((L13-L12)<0,"0",(L13-L12)) -> 4592 | N13: 2225796 | O13: =(IF((N13-N12)<0,"0",(N13-N12)))*2 -> 5420 | P13: 4571918 | Q13: =IF((P13-P12)<0,"0",(P13-P12)) -> 3262 | R13: 8975466 | S13: =IF((R13-R12)<0,"0",(R13-R12)) -> 9488 | T13: 0 | V13: 5347419 | W13: =IF((V13-V12)<0,"0",(V13-V12)) -> 10905 | X13: =K13+M13+O13+Q13+S13+U13+W13 -> 39681 | Y13: =I13-X13 -> 12194 | Z13: =(0.93352*(W13+S13)+0.5568*(Q13+O13))*0.26 -> 6206.5668 | AA13: =SUM(Z10:Z13) -> 30046.647
A14: 43476 | B14: 271 | C14: 14958 | D14: =IF((C14-C13)<0,"0",(C14-C13))*160 -> 1280 | E14: 15420363 | F14: =IF((E14-E13)<0,"0",(E14-E13)) -> 18316 | G14: 39895241 | H14: =IF((G14-G13)<0,"0",(G14-G13)) -> 65659 | I14: =F14+H14 -> 83975 | J14: 3347129 | K14: =IF((J14-J13)<0,"0",(J14-J13)) -> 7547 | L14: 3471193 | M14: =IF((L14-L13)<0,"0",(L14-L13)) -> 7763 | N14: 2230943 | O14: =(IF((N14-N13)<0,"0",(N14-N13)))*2 -> 10294 | P14: 4576540 | Q14: =IF((P14-P13)<0,"0",(P14-P13)) -> 4622 | R14: 8991714 | S14: =IF((R14-R13)<0,"0",(R14-R13)) -> 16248 | T14: 0 | V14: 5365431 | W14: =IF((V14-V13)<0,"0",(V14-V13)) -> 18012 | X14: =K14+M14+O14+Q14+S14+U14+W14 -> 64486 | Y14: =I14-X14 -> 19489 | Z14: =(0.93352*(W14+S14)+0.5568*(Q14+O14))*0.26 -> 10474.782 | AA14: =SUM(Z11:Z14) -> 31682.354
A15: 43477 | B15: 298 | C15: 14966 | D15: =IF((C15-C14)<0,"0",(C15-C14))*160 -> 1280 | E15: 15429871 | F15: =IF((E15-E14)<0,"0",(E15-E14)) -> 9508 | G15: 39925194 | H15: =IF((G15-G14)<0,"0",(G15-G14)) -> 29953 | I15: =F15+H15 -> 39461 | J15: 3350620 | K15: =IF((J15-J14)<0,"0",(J15-J14)) -> 3491 | L15: 3475476 | M15: =IF((L15-L14)<0,"0",(L15-L14)) -> 4283 | N15: 2233514 | O15: =(IF((N15-N14)<0,"0",(N15-N14)))*2 -> 5142 | P15: 4578618 | Q15: =IF((P15-P14)<0,"0",(P15-P14)) -> 2078 | R15: 8999327 | S15: =IF((R15-R14)<0,"0",(R15-R14)) -> 7613 | T15: 0 | V15: 5373609 | W15: =IF((V15-V14)<0,"0",(V15-V14)) -> 8178 | X15: =K15+M15+O15+Q15+S15+U15+W15 -> 30785 | Y15: =I15-X15 -> 8676 | Z15: =(0.93352*(W15+S15)+0.5568*(Q15+O15))*0.26 -> 4877.9407 | AA15: =SUM(Z12:Z15) -> 29659.603
... A22: 43484 | B22: 299 | C22: 15022 | D22: =IF((C22-C21)<0,"0",(C22-C21))*160 -> 1280 | E22: 15530208 | F22: =IF((E22-E21)<0,"0",(E22-E21)) -> 17535 | G22: 40253747 | H22: =IF((G22-G21)<0,"0",(G22-G21)) -> 54320 | I22: =F22+H22 -> 71855 | J22: 3386835 | K22: =IF((J22-J21)<0,"0",(J22-J21)) -> 5749 | L22: 3520540 | M22: =IF((L22-L21)<0,"0",(L22-L21)) -> 7864 | N22: 2260549 | O22: =(IF((N22-N21)<0,"0",(N22-N21)))*2 -> 9466 | P22: 4598046 | Q22: =IF((P22-P21)<0,"0",(P22-P21)) -> 2908 | R22: 9081066 | S22: =IF((R22-R21)<0,"0",(R22-R21)) -> 13619 | T22: 0 | V22: 5466525 | W22: =IF((V22-V21)<0,"0",(V22-V21)) -> 15602 | X22: =K22+M22+O22+Q22+S22+U22+W22 -> 55208 | Y22: =I22-X22 -> 16647 | Z22: =(0.93352*(W22+S22)+0.5568*(Q22+O22))*0.26 -> 8883.7401 | AA22: =SUM(Z19:Z22) -> 29539.044
A23: 43485 | B23: =B22 -> 299 | C23: 15030 | D23: =IF((C23-C22)<0,"0",(C23-C22))*160 -> 1280 | E23: 15546434 | F23: =IF((E23-E22)<0,"0",(E23-E22)) -> 16226 | G23: 40302753 | H23: =IF((G23-G22)<0,"0",(G23-G22)) -> 49006 | I23: =F23+H23 -> 65232 | J23: 3391888 | K23: =IF((J23-J22)<0,"0",(J23-J22)) -> 5053 | L23: 3527677 | M23: =IF((L23-L22)<0,"0",(L23-L22)) -> 7137 | N23: 2265012 | O23: =(IF((N23-N22)<0,"0",(N23-N22)))*2 -> 8926 | P23: 4600858 | Q23: =IF((P23-P22)<0,"0",(P23-P22)) -> 2812 | R23: 9092586 | S23: =IF((R23-R22)<0,"0",(R23-R22)) -> 11520 | T23: 0 | V23: 5480962 | W23: =IF((V23-V22)<0,"0",(V23-V22)) -> 14437 | X23: =K23+M23+O23+Q23+S23+U23+W23 -> 49885 | Y23: =I23-X23 -> 15347 | Z23: =(0.93352*(W23+S23)+0.5568*(Q23+O23))*0.26 -> 7999.4452 | AA23: =SUM(Z20:Z23) -> 30654.088
A24: 43486 | B24: 278 | C24: 15038 | D24: =IF((C24-C23)<0,"0",(C24-C23))*160 -> 1280 | E24: 15565392 | F24: =IF((E24-E23)<0,"0",(E24-E23)) -> 18958 | G24: 40360230 | H24: =IF((G24-G23)<0,"0",(G24-G23)) -> 57477 | I24: =F24+H24 -> 76435 | J24: 3397939 | K24: =IF((J24-J23)<0,"0",(J24-J23)) -> 6051 | L24: 3535286 | M24: =IF((L24-L23)<0,"0",(L24-L23)) -> 7609 | N24: 2270562 | O24: =(IF((N24-N23)<0,"0",(N24-N23)))*2 -> 11100 | P24: 4603940 | Q24: =IF((P24-P23)<0,"0",(P24-P23)) -> 3082 | R24: 9106410 | S24: =IF((R24-R23)<0,"0",(R24-R23)) -> 13824 | T24: 0 | V24: 5497712 | W24: =IF((V24-V23)<0,"0",(V24-V23)) -> 16750 | X24: =K24+M24+O24+Q24+S24+U24+W24 -> 58416 | Y24: =I24-X24 -> 18019 | Z24: =(0.93352*(W24+S24)+0.5568*(Q24+O24))*0.26 -> 9473.8743 | AA24: =SUM(Z21:Z24) -> 31570.938
A25: 43487 | B25: =B24 -> 278 | C25: 15046 | D25: =IF((C25-C24)<0,"0",(C25-C24))*160 -> 1280 | E25: 15577566 | F25: =IF((E25-E24)<0,"0",(E25-E24)) -> 12174 | G25: 40393851 | H25: =IF((G25-G24)<0,"0",(G25-G24)) -> 33621 | I25: =F25+H25 -> 45795 | J25: 3402017 | K25: =IF((J25-J24)<0,"0",(J25-J24)) -> 4078 | L25: 3540962 | M25: =IF((L25-L24)<0,"0",(L25-L24)) -> 5676 | N25: 2273758 | O25: =(IF((N25-N24)<0,"0",(N25-N24)))*2 -> 6392 | P25: 4605730 | Q25: =IF((P25-P24)<0,"0",(P25-P24)) -> 1790 | R25: 9114138 | S25: =IF((R25-R24)<0,"0",(R25-R24)) -> 7728 | T25: 0 | V25: 5507506 | W25: =IF((V25-V24)<0,"0",(V25-V24)) -> 9794 | X25: =K25+M25+O25+Q25+S25+U25+W25 -> 35458 | Y25: =I25-X25 -> 10337 | Z25: =(0.93352*(W25+S25)+0.5568*(Q25+O25))*0.26 -> 5437.3475 | AA25: =SUM(Z22:Z25) -> 31794.407
A26: 43488 | B26: 318 | C26: 15054 | D26: =IF((C26-C25)<0,"0",(C26-C25))*160 -> 1280 | E26: 15592024 | F26: =IF((E26-E25)<0,"0",(E26-E25)) -> 14458 | G26: 40436468 | H26: =IF((G26-G25)<0,"0",(G26-G25)) -> 42617 | I26: =F26+H26 -> 57075 | J26: 3406715 | K26: =IF((J26-J25)<0,"0",(J26-J25)) -> 4698 | L26: 3547098 | M26: =IF((L26-L25)<0,"0",(L26-L25)) -> 6136 | N26: 2277842 | O26: =(IF((N26-N25)<0,"0",(N26-N25)))*2 -> 8168 | P26: 4608082 | Q26: =IF((P26-P25)<0,"0",(P26-P25)) -> 2352 | R26: 9123648 | S26: =IF((R26-R25)<0,"0",(R26-R25)) -> 9510 | T26: 0 | V26: 5520176 | W26: =IF((V26-V25)<0,"0",(V26-V25)) -> 12670 | X26: =K26+M26+O26+Q26+S26+U26+W26 -> 43534 | Y26: =I26-X26 -> 13541 | Z26: =(0.93352*(W26+S26)+0.5568*(Q26+O26))*0.26 -> 6906.3825 | AA26: =SUM(Z23:Z26) -> 29817.05
A27: 43489 | B27: =B26 -> 318 | C27: 15062 | D27: =IF((C27-C26)<0,"0",(C27-C26))*160 -> 1280 | E27: 15606116 | F27: =IF((E27-E26)<0,"0",(E27-E26)) -> 14092 | G27: 40476200 | H27: =IF((G27-G26)<0,"0",(G27-G26)) -> 39732 | I27: =F27+H27 -> 53824 | J27: 3410368 | K27: =IF((J27-J26)<0,"0",(J27-J26)) -> 3653 | L27: 3552727 | M27: =IF((L27-L26)<0,"0",(L27-L26)) -> 5629 | N27: 2281362 | O27: =(IF((N27-N26)<0,"0",(N27-N26)))*2 -> 7040 | P27: 4610413 | Q27: =IF((P27-P26)<0,"0",(P27-P26)) -> 2331 | R27: 9133532 | S27: =IF((R27-R26)<0,"0",(R27-R26)) -> 9884 | T27: 0 | V27: 5531577 | W27: =IF((V27-V26)<0,"0",(V27-V26)) -> 11401 | X27: =K27+M27+O27+Q27+S27+U27+W27 -> 39938 | Y27: =I27-X27 -> 13886 | Z27: =(0.93352*(W27+S27)+0.5568*(Q27+O27))*0.26 -> 6522.814 | AA27: =SUM(Z24:Z27) -> 28340.418
A28: 43490 | B28: 305 | C28: 15070 | D28: =IF((C28-C27)<0,"0",(C28-C27))*160 -> 1280 | E28: 15620090 | F28: =IF((E28-E27)<0,"0",(E28-E27)) -> 13974 | G28: 40521958 | H28: =IF((G28-G27)<0,"0",(G28-G27)) -> 45758 | I28: =F28+H28 -> 59732 | J28: 3415391 | K28: =IF((J28-J27)<0,"0",(J28-J27)) -> 5023 | L28: 3559048 | M28: =IF((L28-L27)<0,"0",(L28-L27)) -> 6321 | N28: 2285728 | O28: =(IF((N28-N27)<0,"0",(N28-N27)))*2 -> 8732 | P28: 4612747 | Q28: =IF((P28-P27)<0,"0",(P28-P27)) -> 2334 | R28: 9145508 | S28: =IF((R28-R27)<0,"0",(R28-R27)) -> 11976 | T28: 0 | V28: 5544608 | W28: =IF((V28-V27)<0,"0",(V28-V27)) -> 13031 | X28: =K28+M28+O28+Q28+S28+U28+W28 -> 47417 | Y28: =I28-X28 -> 12315 | Z28: =(0.93352*(W28+S28)+0.5568*(Q28+O28))*0.26 -> 7671.5817 | AA28: =SUM(Z25:Z28) -> 26538.126
A29: 43491 | B29: 337 | C29: 15078 | D29: =IF((C29-C28)<0,"0",(C29-C28))*160 -> 1280 | E29: 15635013 | F29: =IF((E29-E28)<0,"0",(E29-E28)) -> 14923 | G29: 40555449 | H29: =IF((G29-G28)<0,"0",(G29-G28)) -> 33491 | I29: =F29+H29 -> 48414 | J29: 3418910 | K29: =IF((J29-J28)<0,"0",(J29-J28)) -> 3519 | L29: 3563653 | M29: =IF((L29-L28)<0,"0",(L29-L28)) -> 4605 | N29: 2289059 | O29: =(IF((N29-N28)<0,"0",(N29-N28)))*2 -> 6662 | P29: 4614708 | Q29: =IF((P29-P28)<0,"0",(P29-P28)) -> 1961 | R29: 9153728 | S29: =IF((R29-R28)<0,"0",(R29-R28)) -> 8220 | T29: 0 | V29: 5554236 | W29: =IF((V29-V28)<0,"0",(V29-V28)) -> 9628 | X29: =K29+M29+O29+Q29+S29+U29+W29 -> 34595 | Y29: =I29-X29 -> 13819 | Z29: =(0.93352*(W29+S29)+0.5568*(Q29+O29))*0.26 -> 5580.3154 | AA29: =SUM(Z26:Z29) -> 26681.094
A30: 43492 | B30: 360 | C30: 15086 | D30: =IF((C30-C29)<0,"0",(C30-C29))*160 -> 1280 | E30: 15649358 | F30: =IF((E30-E29)<0,"0",(E30-E29)) -> 14345 | G30: 40605894 | H30: =IF((G30-G29)<0,"0",(G30-G29)) -> 50445 | I30: =F30+H30 -> 64790 | J30: 3424339 | K30: =IF((J30-J29)<0,"0",(J30-J29)) -> 5429 | L30: 3571349 | M30: =IF((L30-L29)<0,"0",(L30-L29)) -> 7696 | N30: 2294040 | O30: =(IF((N30-N29)<0,"0",(N30-N29)))*2 -> 9962 | P30: 4617828 | Q30: =IF((P30-P29)<0,"0",(P30-P29)) -> 3120 | R30: 9166618 | S30: =IF((R30-R29)<0,"0",(R30-R29)) -> 12890 | T30: 0 | V30: 5568324 | W30: =IF((V30-V29)<0,"0",(V30-V29)) -> 14088 | X30: =K30+M30+O30+Q30+S30+U30+W30 -> 53185 | Y30: =I30-X30 -> 11605 | Z30: =(0.93352*(W30+S30)+0.5568*(Q30+O30))*0.26 -> 8441.8256 | AA30: =SUM(Z27:Z30) -> 28216.537
A31: 43493 | B31: 365 | C31: 15094 | D31: =IF((C31-C30)<0,"0",(C31-C30))*160 -> 1280 | E31: 15663399 | F31: =IF((E31-E30)<0,"0",(E31-E30)) -> 14041 | G31: 40646278 | H31: =IF((G31-G30)<0,"0",(G31-G30)) -> 40384 | I31: =F31+H31 -> 54425 | J31: 3428732 | K31: =IF((J31-J30)<0,"0",(J31-J30)) -> 4393 | L31: 3577503 | M31: =IF((L31-L30)<0,"0",(L31-L30)) -> 6154 | N31: 2297898 | O31: =(IF((N31-N30)<0,"0",(N31-N30)))*2 -> 7716 | P31: 4620432 | Q31: =IF((P31-P30)<0,"0",(P31-P30)) -> 2604 | R31: 9176858 | S31: =IF((R31-R30)<0,"0",(R31-R30)) -> 10240 | T31: 0 | V31: 5579561 | W31: =IF((V31-V30)<0,"0",(V31-V30)) -> 11237 | X31: =K31+M31+O31+Q31+S31+U31+W31 -> 42344 | Y31: =I31-X31 -> 12081 | Z31: =(0.93352*(W31+S31)+0.5568*(Q31+O31))*0.26 -> 6706.8001 | AA31: =SUM(Z28:Z31) -> 28400.523
A32: 43494 | B32: 360 | C32: 15102 | D32: =IF((C32-C31)<0,"0",(C32-C31))*160 -> 1280 | E32: 15674357 | F32: =IF((E32-E31)<0,"0",(E32-E31)) -> 10958 | G32: 40678248 | H32: =IF((G32-G31)<0,"0",(G32-G31)) -> 31970 | I32: =F32+H32 -> 42928 | J32: 3432180 | K32: =IF((J32-J31)<0,"0",(J32-J31)) -> 3448 | L32: 3582197 | M32: =IF((L32-L31)<0,"0",(L32-L31)) -> 4694 | N32: 2300966 | O32: =(IF((N32-N31)<0,"0",(N32-N31)))*2 -> 6136 | P32: 4622388 | Q32: =IF((P32-P31)<0,"0",(P32-P31)) -> 1956 | R32: 9184973 | S32: =IF((R32-R31)<0,"0",(R32-R31)) -> 8115 | T32: 0 | V32: 5588526 | W32: =IF((V32-V31)<0,"0",(V32-V31)) -> 8965 | X32: =K32+M32+O32+Q32+S32+U32+W32 -> 33314 | Y32: =I32-X32 -> 9614 | Z32: =(0.93352*(W32+S32)+0.5568*(Q32+O32))*0.26 -> 5317.0383 | AA32: =SUM(Z29:Z32) -> 26045.979
A33: 43495 | B33: 331 | C33: 15105 | D33: =IF((C33-C32)<0,"0",(C33-C32))*160 -> 480 | E33: 15693789 | F33: =IF((E33-E32)<0,"0",(E33-E32)) -> 19432 | G33: 40737330 | H33: =IF((G33-G32)<0,"0",(G33-G32)) -> 59082 | I33: =F33+H33 -> 78514 | J33: 3440159 | K33: =IF((J33-J32)<0,"0",(J33-J32)) -> 7979 | L33: 3590930 | M33: =IF((L33-L32)<0,"0",(L33-L32)) -> 8733 | N33: 2306213 | O33: =(IF((N33-N32)<0,"0",(N33-N32)))*2 -> 10494 | P33: 4625972 | Q33: =IF((P33-P32)<0,"0",(P33-P32)) -> 3584 | R33: 9199373 | S33: =IF((R33-R32)<0,"0",(R33-R32)) -> 14400 | T33: 0 | V33: 5604609 | W33: =IF((V33-V32)<0,"0",(V33-V32)) -> 16083 | X33: =K33+M33+O33+Q33+S33+U33+W33 -> 61273 | Y33: =I33-X33 -> 17241 | Z33: =(0.93352*(W33+S33)+0.5568*(Q33+O33))*0.26 -> 9436.7313 | AA33: =SUM(Z30:Z33) -> 29902.395
