Workbook

Sheet TOTAL
A1: Site Name | B1: Day | C1: Month | D1: Year | E1: Total Electricity Kwh | F1: Electricity Tariff ($/Kwh) | G1: Natual Gas (m3) | H1: Natural Gas $/m3 | I1: Water Utility Supply (m3) m3 | J1: Water Utility Supply (m3) $/m3 | K1: Room Nights
A2: Cairo at Nile Plaza | B2: 1 | C2: 11 | D2: 2019 | E2: =(((Submetering!O2+Submetering!P2)*0.842284+Submetering!Q2+(Submetering!M2+Submetering!N2+Submetering!Y2)*0.7362)+(Submetering!O2+Submetering!P2+Submetering!Q2)*0.1488+(Submetering!M2+Submetering!N2+Submetering!Y2)*0.1167+(Submetering!K2+Submetering!L2-Submetering!Z2-Submetering!AA2-Submetering!AB2-Submetering!AC2-Submetering!Q2)+(Submetering!M2+Submetering!N2+Submetering!Y2)*0.1139) -> 54983.598 | F2: 1.27 | G2: =Gas!C4*0.9147 -> 2046.1839 | H2: 3.65 | I2: =Submetering!AE2+Submetering!AD2+Submetering!H2 -> 646 | J2: 10.03 | K2: =ELECT.!B4 -> 335
A3: Cairo at Nile Plaza | B3: =B2+1 -> 2 | C3: 11 | D3: 2019 | E3: =(((Submetering!O3+Submetering!P3)*0.842284+Submetering!Q3+(Submetering!M3+Submetering!N3+Submetering!Y3)*0.7362)+(Submetering!O3+Submetering!P3+Submetering!Q3)*0.1488+(Submetering!M3+Submetering!N3+Submetering!Y3)*0.1167+(Submetering!K3+Submetering!L3-Submetering!Z3-Submetering!AA3-Submetering!AB3-Submetering!AC3-Submetering!Q3)+(Submetering!M3+Submetering!N3+Submetering!Y3)*0.1139) -> 41428.728 | F3: 1.27 | G3: =Gas!C5*0.9147 -> 2652.63 | H3: 3.65 | I3: =Submetering!AE3+Submetering!AD3+Submetering!H3 -> 956 | J3: 10.03 | K3: =ELECT.!B5 -> 323
A4: Cairo at Nile Plaza | B4: =B3+1 -> 3 | C4: 11 | D4: 2019 | E4: =(((Submetering!O4+Submetering!P4)*0.842284+Submetering!Q4+(Submetering!M4+Submetering!N4+Submetering!Y4)*0.7362)+(Submetering!O4+Submetering!P4+Submetering!Q4)*0.1488+(Submetering!M4+Submetering!N4+Submetering!Y4)*0.1167+(Submetering!K4+Submetering!L4-Submetering!Z4-Submetering!AA4-Submetering!AB4-Submetering!AC4-Submetering!Q4)+(Submetering!M4+Submetering!N4+Submetering!Y4)*0.1139) -> 90057.331 | F4: 1.27 | G4: =Gas!C6*0.9147 -> 3206.0235 | H4: 3.65 | I4: =Submetering!AE4+Submetering!AD4+Submetering!H4 -> 916 | J4: 10.03 | K4: =ELECT.!B6 -> 345
A5: Cairo at Nile Plaza | B5: =B4+1 -> 4 | C5: 11 | D5: 2019 | E5: =(((Submetering!O5+Submetering!P5)*0.842284+Submetering!Q5+(Submetering!M5+Submetering!N5+Submetering!Y5)*0.7362)+(Submetering!O5+Submetering!P5+Submetering!Q5)*0.1488+(Submetering!M5+Submetering!N5+Submetering!Y5)*0.1167+(Submetering!K5+Submetering!L5-Submetering!Z5-Submetering!AA5-Submetering!AB5-Submetering!AC5-Submetering!Q5)+(Submetering!M5+Submetering!N5+Submetering!Y5)*0.1139) -> 59673.984 | F5: 1.27 | G5: =Gas!C7*0.9147 -> 3707.2791 | H5: 3.65 | I5: =Submetering!AE5+Submetering!AD5+Submetering!H5 -> 936 | J5: 10.03 | K5: =ELECT.!B7 -> 338
A6: Cairo at Nile Plaza | B6: =B5+1 -> 5 | C6: 11 | D6: 2019 | E6: =(((Submetering!O6+Submetering!P6)*0.842284+Submetering!Q6+(Submetering!M6+Submetering!N6+Submetering!Y6)*0.7362)+(Submetering!O6+Submetering!P6+Submetering!Q6)*0.1488+(Submetering!M6+Submetering!N6+Submetering!Y6)*0.1167+(Submetering!K6+Submetering!L6-Submetering!Z6-Submetering!AA6-Submetering!AB6-Submetering!AC6-Submetering!Q6)+(Submetering!M6+Submetering!N6+Submetering!Y6)*0.1139) -> 60207.437 | F6: 1.27 | G6: =Gas!C8*0.9147 -> 3096.2595 | H6: 3.65 | I6: =Submetering!AE6+Submetering!AD6+Submetering!H6 -> 926 | J6: 10.03 | K6: =ELECT.!B8 -> 345
A7: Cairo at Nile Plaza | B7: =B6+1 -> 6 | C7: 11 | D7: 2019 | E7: =(((Submetering!O7+Submetering!P7)*0.842284+Submetering!Q7+(Submetering!M7+Submetering!N7+Submetering!Y7)*0.7362)+(Submetering!O7+Submetering!P7+Submetering!Q7)*0.1488+(Submetering!M7+Submetering!N7+Submetering!Y7)*0.1167+(Submetering!K7+Submetering!L7-Submetering!Z7-Submetering!AA7-Submetering!AB7-Submetering!AC7-Submetering!Q7)+(Submetering!M7+Submetering!N7+Submetering!Y7)*0.1139) -> 60689.822 | F7: 1.27 | G7: =Gas!C9*0.9147 -> 2835.57 | H7: 3.65 | I7: =Submetering!AE7+Submetering!AD7+Submetering!H7 -> 996 | J7: 10.03 | K7: =ELECT.!B9 -> 358
A8: Cairo at Nile Plaza | B8: =B7+1 -> 7 | C8: 11 | D8: 2019 | E8: =(((Submetering!O8+Submetering!P8)*0.842284+Submetering!Q8+(Submetering!M8+Submetering!N8+Submetering!Y8)*0.7362)+(Submetering!O8+Submetering!P8+Submetering!Q8)*0.1488+(Submetering!M8+Submetering!N8+Submetering!Y8)*0.1167+(Submetering!K8+Submetering!L8-Submetering!Z8-Submetering!AA8-Submetering!AB8-Submetering!AC8-Submetering!Q8)+(Submetering!M8+Submetering!N8+Submetering!Y8)*0.1139) -> 85211.209 | F8: 1.27 | G8: =Gas!C10*0.9147 -> 3679.8381 | H8: 3.65 | I8: =Submetering!AE8+Submetering!AD8+Submetering!H8 -> 996 | J8: 10.03 | K8: =ELECT.!B10 -> 360
A9: Cairo at Nile Plaza | B9: =B8+1 -> 8 | C9: 11 | D9: 2019 | E9: =(((Submetering!O9+Submetering!P9)*0.842284+Submetering!Q9+(Submetering!M9+Submetering!N9+Submetering!Y9)*0.7362)+(Submetering!O9+Submetering!P9+Submetering!Q9)*0.1488+(Submetering!M9+Submetering!N9+Submetering!Y9)*0.1167+(Submetering!K9+Submetering!L9-Submetering!Z9-Submetering!AA9-Submetering!AB9-Submetering!AC9-Submetering!Q9)+(Submetering!M9+Submetering!N9+Submetering!Y9)*0.1139) -> 71363.167 | F9: 1.27 | G9: =Gas!C11*0.9147 -> 3776.7963 | H9: 3.65 | I9: =Submetering!AE9+Submetering!AD9+Submetering!H9 -> 836 | J9: 10.03 | K9: =ELECT.!B11 -> 317
A10: Cairo at Nile Plaza | B10: =B9+1 -> 9 | C10: 11 | D10: 2019 | E10: =(((Submetering!O10+Submetering!P10)*0.842284+Submetering!Q10+(Submetering!M10+Submetering!N10+Submetering!Y10)*0.7362)+(Submetering!O10+Submetering!P10+Submetering!Q10)*0.1488+(Submetering!M10+Submetering!N10+Submetering!Y10)*0.1167+(Submetering!K10+Submetering!L10-Submetering!Z10-Submetering!AA10-Submetering!AB10-Submetering!AC10-Submetering!Q10)+(Submetering!M10+Submetering!N10+Submetering!Y10)*0.1139) -> 59910.072 | F10: 1.27 | G10: =Gas!C12*0.9147 -> 3436.5279 | H10: 3.65 | I10: =Submetering!AE10+Submetering!AD10+Submetering!H10 -> 926 | J10: 10.03 | K10: =ELECT.!B12 -> 332
A11: Cairo at Nile Plaza | B11: =B10+1 -> 10 | C11: 11 | D11: 2019 | E11: =(((Submetering!O11+Submetering!P11)*0.842284+Submetering!Q11+(Submetering!M11+Submetering!N11+Submetering!Y11)*0.7362)+(Submetering!O11+Submetering!P11+Submetering!Q11)*0.1488+(Submetering!M11+Submetering!N11+Submetering!Y11)*0.1167+(Submetering!K11+Submetering!L11-Submetering!Z11-Submetering!AA11-Submetering!AB11-Submetering!AC11-Submetering!Q11)+(Submetering!M11+Submetering!N11+Submetering!Y11)*0.1139) -> 47826.611 | F11: 1.27 | G11: =Gas!C13*0.9147 -> 2771.541 | H11: 3.65 | I11: =Submetering!AE11+Submetering!AD11+Submetering!H11 -> 916 | J11: 10.03 | K11: =ELECT.!B13 -> 322
A12: Cairo at Nile Plaza | B12: =B11+1 -> 11 | C12: 11 | D12: 2019 | E12: =(((Submetering!O12+Submetering!P12)*0.842284+Submetering!Q12+(Submetering!M12+Submetering!N12+Submetering!Y12)*0.7362)+(Submetering!O12+Submetering!P12+Submetering!Q12)*0.1488+(Submetering!M12+Submetering!N12+Submetering!Y12)*0.1167+(Submetering!K12+Submetering!L12-Submetering!Z12-Submetering!AA12-Submetering!AB12-Submetering!AC12-Submetering!Q12)+(Submetering!M12+Submetering!N12+Submetering!Y12)*0.1139) -> 90402.907 | F12: 1.27 | G12: =Gas!C14*0.9147 -> 3776.7963 | H12: 3.65 | I12: =Submetering!AE12+Submetering!AD12+Submetering!H12 -> 706 | J12: 10.03 | K12: =ELECT.!B14 -> 292
A13: Cairo at Nile Plaza | B13: =B12+1 -> 12 | C13: 11 | D13: 2019 | E13: =(((Submetering!O13+Submetering!P13)*0.842284+Submetering!Q13+(Submetering!M13+Submetering!N13+Submetering!Y13)*0.7362)+(Submetering!O13+Submetering!P13+Submetering!Q13)*0.1488+(Submetering!M13+Submetering!N13+Submetering!Y13)*0.1167+(Submetering!K13+Submetering!L13-Submetering!Z13-Submetering!AA13-Submetering!AB13-Submetering!AC13-Submetering!Q13)+(Submetering!M13+Submetering!N13+Submetering!Y13)*0.1139) -> 58099.475 | F13: 1.27 | G13: =Gas!C15*0.9147 -> 3185.9001 | H13: 3.65 | I13: =Submetering!AE13+Submetering!AD13+Submetering!H13 -> 1036 | J13: 10.03 | K13: =ELECT.!B15 -> 325
A14: Cairo at Nile Plaza | B14: =B13+1 -> 13 | C14: 11 | D14: 2019 | E14: =(((Submetering!O14+Submetering!P14)*0.842284+Submetering!Q14+(Submetering!M14+Submetering!N14+Submetering!Y14)*0.7362)+(Submetering!O14+Submetering!P14+Submetering!Q14)*0.1488+(Submetering!M14+Submetering!N14+Submetering!Y14)*0.1167+(Submetering!K14+Submetering!L14-Submetering!Z14-Submetering!AA14-Submetering!AB14-Submetering!AC14-Submetering!Q14)+(Submetering!M14+Submetering!N14+Submetering!Y14)*0.1139) -> 68287.447 | F14: 1.27 | G14: =Gas!C16*0.9147 -> 3160.2885 | H14: 3.65 | I14: =Submetering!AE14+Submetering!AD14+Submetering!H14 -> 896 | J14: 10.03 | K14: =ELECT.!B16 -> 340
... A31: Cairo at Nile Plaza | B31: =B30+1 -> 30 | C31: 11 | D31: 2019 | E31: =(((Submetering!O31+Submetering!P31)*0.842284+Submetering!Q31+(Submetering!M31+Submetering!N31+Submetering!Y31)*0.7362)+(Submetering!O31+Submetering!P31+Submetering!Q31)*0.1488+(Submetering!M31+Submetering!N31+Submetering!Y31)*0.1167+(Submetering!K31+Submetering!L31-Submetering!Z31-Submetering!AA31-Submetering!AB31-Submetering!AC31-Submetering!Q31)+(Submetering!M31+Submetering!N31+Submetering!Y31)*0.1139) -> 62645.532 | F31: 1.27 | G31: =Gas!C33*0.9147 -> 1907.1495 | H31: 3.65 | I31: =Submetering!AE31+Submetering!AD31+Submetering!H31 -> 756 | J31: 10.03 | K31: =ELECT.!B33 -> 355

Sheet Submetering
A1: Site Name | B1: Day | C1: Month | D1: Year | E1: Main (m3) | F1: Podium (m3) | G1: Hotel (m3) | H1: Large (m3) | I1: Feeder 1 (KWh) | J1: Feeder 2 (KWh) | K1: T1 (KWh) | L1: T2 (KWh) | M1: T3 (KWh) | N1: T4 (KWh) | O1: T5 (KWh) | P1: T7 (KWh) | Q1: New Chiller (KWh) | R1: Hotel (BTU) | S1: B.S (BTU) | T1: LS (BTU) | U1: Mall (BTU) | V1: AHU#25 (BTU) | W1: AHU#9 (BTU) | X1: Room Nights | Y1: Loss (KWH) | Z1: Mall (KWH) | AA1: Citadel (KWH) | AB1: Rotana (KWH) | AC1: CIB (KWH) | AD1: Plaza suits water consumption (M3) | AE1: Hotel water consumption (M3)
A2: Cairo at Nile Plaza | B2: 1 | C2: 11 | D2: 2019 | E2: =Water!C4 -> 840 | F2: =Water!E4 -> 445.5 | G2: =Water!G4 -> 383.4 | H2: =Water!I4 -> 4.347 | I2: =ELECT.!F4 -> 10617 | J2: =ELECT.!H4 -> 46719 | K2: =ELECT.!K4 -> 4746 | L2: =ELECT.!M4 -> 4082 | M2: =ELECT.!O4 -> 6390 | N2: =ELECT.!Q4 -> 7794 | O2: =ELECT.!S4 -> 9847 | P2: =ELECT.!W4*2 -> 22266 | Q2: =ELECT.!D4 -> 640 | R2: =BTU!C3 -> 7.9 | S2: =BTU!F3 -> 1.8 | T2: =BTU!I3 -> 4 | U2: =BTU!O3 -> 2.4 | V2: =BTU!L3 -> 0.8 | W2: =BTU!R3 -> 2.1 | X2: =ELECT.!B4 -> 335 | Y2: =I2+J2-(K2+L2+M2+N2+O2+P2) -> 2211 | Z2: ='Mall, Citadel, Rotana'!C4+'Mall, Citadel, Rotana'!E4+'Mall, Citadel, Rotana'!G4+'Mall, Citadel, Rotana'!I4 -> 1028 | AA2: ='Mall, Citadel, Rotana'!K4+'Mall, Citadel, Rotana'!M4 -> 480 | AB2: ='Mall, Citadel, Rotana'!O4 -> 3 | AC2: ='Mall, Citadel, Rotana'!Q4+'Mall, Citadel, Rotana'!S4 -> 106 | AD2: =(E2-H2-194)*0.1318 -> 84.569865 | AE2: =E2-H2-AD2-194 -> 557.08313
A3: Cairo at Nile Plaza | B3: =B2+1 -> 2 | C3: 11 | D3: 2019 | E3: =Water!C5 -> 1150 | F3: =Water!E5 -> 594 | G3: =Water!G5 -> 510.3 | H3: =Water!I5 -> 5.562 | I3: =ELECT.!F5 -> 8330 | J3: =ELECT.!H5 -> 35697 | K3: =ELECT.!K5 -> 3898 | L3: =ELECT.!M5 -> 3300 | M3: =ELECT.!O5 -> 4914 | N3: =ELECT.!Q5 -> 7867 | O3: =ELECT.!S5 -> 7475 | P3: =ELECT.!W5*2 -> 16928 | Q3: =ELECT.!D5 -> 960 | R3: =BTU!C4 -> 7.3 | S3: =BTU!F4 -> 1 | T3: =BTU!I4 -> 3 | U3: =BTU!O4 -> 1.9 | V3: =BTU!L4 -> 0.42 | W3: =BTU!R4 -> 2.3 | X3: =ELECT.!B5 -> 323 | Y3: =I3+J3-(K3+L3+M3+N3+O3+P3) -> -355 | Z3: ='Mall, Citadel, Rotana'!C5+'Mall, Citadel, Rotana'!E5+'Mall, Citadel, Rotana'!G5+'Mall, Citadel, Rotana'!I5 -> 1335 | AA3: ='Mall, Citadel, Rotana'!K5+'Mall, Citadel, Rotana'!M5 -> 640 | AB3: ='Mall, Citadel, Rotana'!O5 -> 3 | AC3: ='Mall, Citadel, Rotana'!Q5+'Mall, Citadel, Rotana'!S5 -> 133 | AD3: =(E3-H3-194)*0.1318 -> 125.26773 | AE3: =E3-H3-AD3-194 -> 825.17027
A4: Cairo at Nile Plaza | B4: =B3+1 -> 3 | C4: 11 | D4: 2019 | E4: =Water!C6 -> 1110 | F4: =Water!E6 -> 583.2 | G4: =Water!G6 -> 450.9 | H4: =Water!I6 -> 5.535 | I4: =ELECT.!F6 -> 18395 | J4: =ELECT.!H6 -> 74819 | K4: =ELECT.!K6 -> 7991 | L4: =ELECT.!M6 -> 7409 | M4: =ELECT.!O6 -> 10620 | N4: =ELECT.!Q6 -> 14736 | O4: =ELECT.!S6 -> 15350 | P4: =ELECT.!W6*2 -> 35338 | Q4: =ELECT.!D6 -> 960 | R4: =BTU!C5 -> 6.8 | S4: =BTU!F5 -> 1.8 | T4: =BTU!I5 -> 3 | U4: =BTU!O5 -> 2.2 | V4: =BTU!L5 -> 0.38 | W4: =BTU!R5 -> 1.1 | X4: =ELECT.!B6 -> 345 | Y4: =I4+J4-(K4+L4+M4+N4+O4+P4) -> 1770 | Z4: ='Mall, Citadel, Rotana'!C6+'Mall, Citadel, Rotana'!E6+'Mall, Citadel, Rotana'!G6+'Mall, Citadel, Rotana'!I6 -> 1159 | AA4: ='Mall, Citadel, Rotana'!K6+'Mall, Citadel, Rotana'!M6 -> 640 | AB4: ='Mall, Citadel, Rotana'!O6 -> 3 | AC4: ='Mall, Citadel, Rotana'!Q6+'Mall, Citadel, Rotana'!S6 -> 145 | AD4: =(E4-H4-194)*0.1318 -> 119.99929 | AE4: =E4-H4-AD4-194 -> 790.46571
A5: Cairo at Nile Plaza | B5: =B4+1 -> 4 | C5: 11 | D5: 2019 | E5: =Water!C7 -> 1130 | F5: =Water!E7 -> 588.6 | G5: =Water!G7 -> 469.8 | H5: =Water!I7 -> 5.454 | I5: =ELECT.!F7 -> 12023 | J5: =ELECT.!H7 -> 50422 | K5: =ELECT.!K7 -> 5623 | L5: =ELECT.!M7 -> 4943 | M5: =ELECT.!O7 -> 7116 | N5: =ELECT.!Q7 -> 9931 | O5: =ELECT.!S7 -> 10058 | P5: =ELECT.!W7*2 -> 24052 | Q5: =ELECT.!D7 -> 800 | R5: =BTU!C6 -> 9.2 | S5: =BTU!F6 -> 2.4 | T5: =BTU!I6 -> 3 | U5: =BTU!O6 -> 2.5 | V5: =BTU!L6 -> 0.4 | W5: =BTU!R6 -> 1.5 | X5: =ELECT.!B7 -> 338 | Y5: =I5+J5-(K5+L5+M5+N5+O5+P5) -> 722 | Z5: ='Mall, Citadel, Rotana'!C7+'Mall, Citadel, Rotana'!E7+'Mall, Citadel, Rotana'!G7+'Mall, Citadel, Rotana'!I7 -> 1060 | AA5: ='Mall, Citadel, Rotana'!K7+'Mall, Citadel, Rotana'!M7 -> 800 | AB5: ='Mall, Citadel, Rotana'!O7 -> 3 | AC5: ='Mall, Citadel, Rotana'!Q7+'Mall, Citadel, Rotana'!S7 -> 133 | AD5: =(E5-H5-194)*0.1318 -> 122.64596 | AE5: =E5-H5-AD5-194 -> 807.90004
A6: Cairo at Nile Plaza | B6: =B5+1 -> 5 | C6: 11 | D6: 2019 | E6: =Water!C8 -> 1120 | F6: =Water!E8 -> 580.5 | G6: =Water!G8 -> 480.6 | H6: =Water!I8 -> 5.346 | I6: =ELECT.!F8 -> 12147 | J6: =ELECT.!H8 -> 51121 | K6: =ELECT.!K8 -> 5281 | L6: =ELECT.!M8 -> 4717 | M6: =ELECT.!O8 -> 7224 | N6: =ELECT.!Q8 -> 10166 | O6: =ELECT.!S8 -> 10006 | P6: =ELECT.!W8*2 -> 23940 | Q6: =ELECT.!D8 -> 1120 | R6: =BTU!C7 -> 8 | S6: =BTU!F7 -> 2.6 | T6: =BTU!I7 -> 4 | U6: =BTU!O7 -> 2.2 | V6: =BTU!L7 -> 0.6 | W6: =BTU!R7 -> 1.1 | X6: =ELECT.!B8 -> 345 | Y6: =I6+J6-(K6+L6+M6+N6+O6+P6) -> 1934 | Z6: ='Mall, Citadel, Rotana'!C8+'Mall, Citadel, Rotana'!E8+'Mall, Citadel, Rotana'!G8+'Mall, Citadel, Rotana'!I8 -> 1482 | AA6: ='Mall, Citadel, Rotana'!K8+'Mall, Citadel, Rotana'!M8 -> 640 | AB6: ='Mall, Citadel, Rotana'!O8 -> 3 | AC6: ='Mall, Citadel, Rotana'!Q8+'Mall, Citadel, Rotana'!S8 -> 158 | AD6: =(E6-H6-194)*0.1318 -> 121.3422 | AE6: =E6-H6-AD6-194 -> 799.3118
A7: Cairo at Nile Plaza | B7: =B6+1 -> 6 | C7: 11 | D7: 2019 | E7: =Water!C9 -> 1190 | F7: =Water!E9 -> 631.8 | G7: =Water!G9 -> 477.9 | H7: =Water!I9 -> 5.805 | I7: =ELECT.!F9 -> 12301 | J7: =ELECT.!H9 -> 50976 | K7: =ELECT.!K9 -> 5526 | L7: =ELECT.!M9 -> 4730 | M7: =ELECT.!O9 -> 7420 | N7: =ELECT.!Q9 -> 10518 | O7: =ELECT.!S9 -> 10293 | P7: =ELECT.!W9*2 -> 24548 | Q7: =ELECT.!D9 -> 800 | R7: =BTU!C8 -> 8.8 | S7: =BTU!F8 -> 2.1 | T7: =BTU!I8 -> 4 | U7: =BTU!O8 -> 2.2 | V7: =BTU!L8 -> 0.4 | W7: =BTU!R8 -> 1 | X7: =ELECT.!B9 -> 358 | Y7: =I7+J7-(K7+L7+M7+N7+O7+P7) -> 242 | Z7: ='Mall, Citadel, Rotana'!C9+'Mall, Citadel, Rotana'!E9+'Mall, Citadel, Rotana'!G9+'Mall, Citadel, Rotana'!I9 -> 1061 | AA7: ='Mall, Citadel, Rotana'!K9+'Mall, Citadel, Rotana'!M9 -> 640 | AB7: ='Mall, Citadel, Rotana'!O9 -> 3 | AC7: ='Mall, Citadel, Rotana'!Q9+'Mall, Citadel, Rotana'!S9 -> 88 | AD7: =(E7-H7-194)*0.1318 -> 130.5077 | AE7: =E7-H7-AD7-194 -> 859.6873
A8: Cairo at Nile Plaza | B8: =B7+1 -> 7 | C8: 11 | D8: 2019 | E8: =Water!C10 -> 1190 | F8: =Water!E10 -> 612.9 | G8: =Water!G10 -> 518.4 | H8: =Water!I10 -> 5.562 | I8: =ELECT.!F10 -> 17439 | J8: =ELECT.!H10 -> 71265 | K8: =ELECT.!K10 -> 7518 | L8: =ELECT.!M10 -> 6660 | M8: =ELECT.!O10 -> 10578 | N8: =ELECT.!Q10 -> 15018 | O8: =ELECT.!S10 -> 14560 | P8: =ELECT.!W10*2 -> 32822 | Q8: =ELECT.!D10 -> 960 | R8: =BTU!C9 -> 9.2 | S8: =BTU!F9 -> 2.6 | T8: =BTU!I9 -> 5 | U8: =BTU!O9 -> 2.5 | V8: =BTU!L9 -> 0.6 | W8: =BTU!R9 -> 1.6 | X8: =ELECT.!B10 -> 360 | Y8: =I8+J8-(K8+L8+M8+N8+O8+P8) -> 1548 | Z8: ='Mall, Citadel, Rotana'!C10+'Mall, Citadel, Rotana'!E10+'Mall, Citadel, Rotana'!G10+'Mall, Citadel, Rotana'!I10 -> 1304 | AA8: ='Mall, Citadel, Rotana'!K10+'Mall, Citadel, Rotana'!M10 -> 800 | AB8: ='Mall, Citadel, Rotana'!O10 -> 4 | AC8: ='Mall, Citadel, Rotana'!Q10+'Mall, Citadel, Rotana'!S10 -> 204 | AD8: =(E8-H8-194)*0.1318 -> 130.53973 | AE8: =E8-H8-AD8-194 -> 859.89827
A9: Cairo at Nile Plaza | B9: =B8+1 -> 8 | C9: 11 | D9: 2019 | E9: =Water!C11 -> 1030 | F9: =Water!E11 -> 521.1 | G9: =Water!G11 -> 453.6 | H9: =Water!I11 -> 4.779 | I9: =ELECT.!F11 -> 14513 | J9: =ELECT.!H11 -> 59498 | K9: =ELECT.!K11 -> 5915 | L9: =ELECT.!M11 -> 5157 | M9: =ELECT.!O11 -> 9132 | N9: =ELECT.!Q11 -> 12728 | O9: =ELECT.!S11 -> 12101 | P9: =ELECT.!W11*2 -> 27666 | Q9: =ELECT.!D11 -> 800 | R9: =BTU!C10 -> 8.8 | S9: =BTU!F10 -> 1.1 | T9: =BTU!I10 -> 4 | U9: =BTU!O10 -> 2.1 | V9: =BTU!L10 -> 0.4 | W9: =BTU!R10 -> 1.6 | X9: =ELECT.!B11 -> 317 | Y9: =I9+J9-(K9+L9+M9+N9+O9+P9) -> 1312 | Z9: ='Mall, Citadel, Rotana'!C11+'Mall, Citadel, Rotana'!E11+'Mall, Citadel, Rotana'!G11+'Mall, Citadel, Rotana'!I11 -> 1054 | AA9: ='Mall, Citadel, Rotana'!K11+'Mall, Citadel, Rotana'!M11 -> 480 | AB9: ='Mall, Citadel, Rotana'!O11 -> 2 | AC9: ='Mall, Citadel, Rotana'!Q11+'Mall, Citadel, Rotana'!S11 -> 107 | AD9: =(E9-H9-194)*0.1318 -> 109.55493 | AE9: =E9-H9-AD9-194 -> 721.66607
A10: Cairo at Nile Plaza | B10: =B9+1 -> 9 | C10: 11 | D10: 2019 | E10: =Water!C12 -> 1120 | F10: =Water!E12 -> 567 | G10: =Water!G12 -> 483.3 | H10: =Water!I12 -> 5.508 | I10: =ELECT.!F12 -> 12003 | J10: =ELECT.!H12 -> 50485 | K10: =ELECT.!K12 -> 5304 | L10: =ELECT.!M12 -> 4318 | M10: =ELECT.!O12 -> 7554 | N10: =ELECT.!Q12 -> 10564 | O10: =ELECT.!S12 -> 9869 | P10: =ELECT.!W12*2 -> 23988 | Q10: =ELECT.!D12 -> 800 | R10: =BTU!C11 -> 9.306 | S10: =BTU!F11 -> 1.307 | T10: =BTU!I11 -> 4 | U10: =BTU!O11 -> 2.164 | V10: =BTU!L11 -> 0.56 | W10: =BTU!R11 -> 1.55 | X10: =ELECT.!B12 -> 332 | Y10: =I10+J10-(K10+L10+M10+N10+O10+P10) -> 891 | Z10: ='Mall, Citadel, Rotana'!C12+'Mall, Citadel, Rotana'!E12+'Mall, Citadel, Rotana'!G12+'Mall, Citadel, Rotana'!I12 -> 1180 | AA10: ='Mall, Citadel, Rotana'!K12+'Mall, Citadel, Rotana'!M12 -> 480 | AB10: ='Mall, Citadel, Rotana'!O12 -> 4 | AC10: ='Mall, Citadel, Rotana'!Q12+'Mall, Citadel, Rotana'!S12 -> 100 | AD10: =(E10-H10-194)*0.1318 -> 121.32085 | AE10: =E10-H10-AD10-194 -> 799.17115
A11: Cairo at Nile Plaza | B11: =B10+1 -> 10 | C11: 11 | D11: 2019 | E11: =Water!C13 -> 1110 | F11: =Water!E13 -> 550.8 | G11: =Water!G13 -> 483.3 | H11: =Water!I13 -> 4.86 | I11: =ELECT.!F13 -> 9598 | J11: =ELECT.!H13 -> 40769 | K11: =ELECT.!K13 -> 4164 | L11: =ELECT.!M13 -> 3365 | M11: =ELECT.!O13 -> 6106 | N11: =ELECT.!Q13 -> 8047 | O11: =ELECT.!S13 -> 8022 | P11: =ELECT.!W13*2 -> 19444 | Q11: =ELECT.!D13 -> 960 | R11: =BTU!C12 -> 10.139 | S11: =BTU!F12 -> 1.305 | T11: =BTU!I12 -> 5 | U11: =BTU!O12 -> 2.248 | V11: =BTU!L12 -> 0.44 | W11: =BTU!R12 -> 0.5 | X11: =ELECT.!B13 -> 322 | Y11: =I11+J11-(K11+L11+M11+N11+O11+P11) -> 1219 | Z11: ='Mall, Citadel, Rotana'!C13+'Mall, Citadel, Rotana'!E13+'Mall, Citadel, Rotana'!G13+'Mall, Citadel, Rotana'!I13 -> 1340 | AA11: ='Mall, Citadel, Rotana'!K13+'Mall, Citadel, Rotana'!M13 -> 480 | AB11: ='Mall, Citadel, Rotana'!O13 -> 3 | AC11: ='Mall, Citadel, Rotana'!Q13+'Mall, Citadel, Rotana'!S13 -> 105 | AD11: =(E11-H11-194)*0.1318 -> 120.08825 | AE11: =E11-H11-AD11-194 -> 791.05175
A12: Cairo at Nile Plaza | B12: =B11+1 -> 11 | C12: 11 | D12: 2019 | E12: =Water!C14 -> 900 | F12: =Water!E14 -> 448.2 | G12: =Water!G14 -> 405 | H12: =Water!I14 -> 3.942 | I12: =ELECT.!F14 -> 18503 | J12: =ELECT.!H14 -> 74916 | K12: =ELECT.!K14 -> 7920 | L12: =ELECT.!M14 -> 7122 | M12: =ELECT.!O14 -> 11166 | N12: =ELECT.!Q14 -> 16076 | O12: =ELECT.!S14 -> 14895 | P12: =ELECT.!W14*2 -> 35104 | Q12: =ELECT.!D14 -> 960 | R12: =BTU!C13 -> 7.253 | S12: =BTU!F13 -> 2.102 | T12: =BTU!I13 -> 4 | U12: =BTU!O13 -> 2.109 | V12: =BTU!L13 -> 0.6 | W12: =BTU!R13 -> 2.9 | X12: =ELECT.!B14 -> 292 | Y12: =I12+J12-(K12+L12+M12+N12+O12+P12) -> 1136 | Z12: ='Mall, Citadel, Rotana'!C14+'Mall, Citadel, Rotana'!E14+'Mall, Citadel, Rotana'!G14+'Mall, Citadel, Rotana'!I14 -> 1179 | AA12: ='Mall, Citadel, Rotana'!K14+'Mall, Citadel, Rotana'!M14 -> 480 | AB12: ='Mall, Citadel, Rotana'!O14 -> 7 | AC12: ='Mall, Citadel, Rotana'!Q14+'Mall, Citadel, Rotana'!S14 -> 105 | AD12: =(E12-H12-194)*0.1318 -> 92.531244 | AE12: =E12-H12-AD12-194 -> 609.52676
A13: Cairo at Nile Plaza | B13: =B12+1 -> 12 | C13: 11 | D13: 2019 | E13: =Water!C15 -> 1230 | F13: =Water!E15 -> 680.4 | G13: =Water!G15 -> 448.2 | H13: =Water!I15 -> 6.696 | I13: =ELECT.!F15 -> 11613 | J13: =ELECT.!H15 -> 48792 | K13: =ELECT.!K15 -> 5182 | L13: =ELECT.!M15 -> 4437 | M13: =ELECT.!O15 -> 6972 | N13: =ELECT.!Q15 -> 9625 | O13: =ELECT.!S15 -> 12391 | P13: =ELECT.!W15*2 -> 23194 | Q13: =ELECT.!D15 -> 480 | R13: =BTU!C14 -> 7.267 | S13: =BTU!F14 -> 1.867 | T13: =BTU!I14 -> 3 | U13: =BTU!O14 -> 1.796 | V13: =BTU!L14 -> 0.45 | W13: =BTU!R14 -> 1.74 | X13: =ELECT.!B15 -> 325 | Y13: =I13+J13-(K13+L13+M13+N13+O13+P13) -> -1396 | Z13: ='Mall, Citadel, Rotana'!C15+'Mall, Citadel, Rotana'!E15+'Mall, Citadel, Rotana'!G15+'Mall, Citadel, Rotana'!I15 -> 1143 | AA13: ='Mall, Citadel, Rotana'!K15+'Mall, Citadel, Rotana'!M15 -> 320 | AB13: ='Mall, Citadel, Rotana'!O15 -> 4 | AC13: ='Mall, Citadel, Rotana'!Q15+'Mall, Citadel, Rotana'!S15 -> 88 | AD13: =(E13-H13-194)*0.1318 -> 135.66227 | AE13: =E13-H13-AD13-194 -> 893.64173
A14: Cairo at Nile Plaza | B14: =B13+1 -> 13 | C14: 11 | D14: 2019 | E14: =Water!C16 -> 1090 | F14: =Water!E16 -> 577.8 | G14: =Water!G16 -> 461.7 | H14: =Water!I16 -> 5.508 | I14: =ELECT.!F16 -> 13384 | J14: =ELECT.!H16 -> 58067 | K14: =ELECT.!K16 -> 6062 | L14: =ELECT.!M16 -> 5088 | M14: =ELECT.!O16 -> 8158 | N14: =ELECT.!Q16 -> 11281 | O14: =ELECT.!S16 -> 9186 | P14: =ELECT.!W16*2 -> 28082 | Q14: =ELECT.!D16 -> 480 | R14: =BTU!C15 -> 8.673 | S14: =BTU!F15 -> 2.26 | T14: =BTU!I15 -> 5 | U14: =BTU!O15 -> 2.289 | V14: =BTU!L15 -> 0.46 | W14: =BTU!R15 -> 1.72 | X14: =ELECT.!B16 -> 340 | Y14: =I14+J14-(K14+L14+M14+N14+O14+P14) -> 3594 | Z14: ='Mall, Citadel, Rotana'!C16+'Mall, Citadel, Rotana'!E16+'Mall, Citadel, Rotana'!G16+'Mall, Citadel, Rotana'!I16 -> 1364 | AA14: ='Mall, Citadel, Rotana'!K16+'Mall, Citadel, Rotana'!M16 -> 640 | AB14: ='Mall, Citadel, Rotana'!O16 -> 3 | AC14: ='Mall, Citadel, Rotana'!Q16+'Mall, Citadel, Rotana'!S16 -> 131 | AD14: =(E14-H14-194)*0.1318 -> 117.36685 | AE14: =E14-H14-AD14-194 -> 773.12515
... A31: Cairo at Nile Plaza | B31: =B30+1 -> 30 | C31: 11 | D31: 2019 | E31: =Water!C33 -> 950 | F31: =Water!E33 -> 496.8 | G31: =Water!G33 -> 421.2 | H31: =Water!I33 -> 7.56 | I31: =ELECT.!F33 -> 11941 | J31: =ELECT.!H33 -> 53742 | K31: =ELECT.!K33 -> 5396 | L31: =ELECT.!M33 -> 4662 | M31: =ELECT.!O33 -> 7168 | N31: =ELECT.!Q33 -> 9618 | O31: =ELECT.!S33 -> 11460 | P31: =ELECT.!W33*2 -> 26378 | Q31: =ELECT.!D33 -> 480 | R31: =BTU!C32 -> 6 | S31: =BTU!F32 -> 1.3 | T31: =BTU!I32 -> 4 | U31: =BTU!O32 -> 1.4 | V31: =BTU!L32 -> 0.06 | W31: =BTU!R32 -> 0.7 | X31: =ELECT.!B33 -> 355 | Y31: =I31+J31-(K31+L31+M31+N31+O31+P31) -> 1001 | Z31: ='Mall, Citadel, Rotana'!C33+'Mall, Citadel, Rotana'!E33+'Mall, Citadel, Rotana'!G33+'Mall, Citadel, Rotana'!I33 -> 1631 | AA31: ='Mall, Citadel, Rotana'!K33+'Mall, Citadel, Rotana'!M33 -> 480 | AB31: ='Mall, Citadel, Rotana'!O33 -> 0 | AC31: ='Mall, Citadel, Rotana'!Q33+'Mall, Citadel, Rotana'!S33 -> 70 | AD31: =(E31-H31-194)*0.1318 -> 98.644392 | AE31: =E31-H31-AD31-194 -> 649.79561

Sheet Mall, Citadel, Rotana
A1: Mall, Citadel and Rotana readings and cons. Nov. 2019
A2: Day | B2: R1 | C2: Cons | D2: R2 | E2: Cons | F2: R3 | G2: Cons | H2: R4 | I2: Cons | J2: RO1 | K2: Cons | L2: RO2 | M2: Cons | N2: ROE | O2: Cons | P2: CIB. 1 | Q2: Cons | R2: CIB. E | S2: Cons
A3: Last | B3: 42886 | D3: 38051 | F3: 18412 | H3: 221603 | J3: 303517 | L3: 22880 | N3: 168730 | P3: 20181 | R3: 55047
A4: 43770 | B4: 42891 | C4: =(B4-B3)*600/5 -> 600 | D4: 38053 | E4: =(D4-D3)*800/5 -> 320 | F4: 18416 | G4: =(F4-F3)*100/5 -> 80 | H4: 221631 | I4: =H4-H3 -> 28 | J4: 303517 | K4: =J4-J3 -> 0 | L4: 22883 | M4: =(L4-L3)*800/5 -> 480 | N4: 168733 | O4: =N4-N3 -> 3 | P4: 20287 | Q4: =P4-P3 -> 106 | R4: 55047 | S4: =R4-R3 -> 0
A5: 43771 | B5: 42897 | C5: =(B5-B4)*600/5 -> 720 | D5: 38056 | E5: =(D5-D4)*800/5 -> 480 | F5: 18420 | G5: =(F5-F4)*100/5 -> 80 | H5: 221686 | I5: =H5-H4 -> 55 | J5: 303517 | K5: =J5-J4 -> 0 | L5: 22887 | M5: =(L5-L4)*800/5 -> 640 | N5: 168736 | O5: =N5-N4 -> 3 | P5: 20420 | Q5: =P5-P4 -> 133 | R5: 55047 | S5: =R5-R4 -> 0
A6: 43772 | B6: 42902 | C6: =(B6-B5)*600/5 -> 600 | D6: 38059 | E6: =(D6-D5)*800/5 -> 480 | F6: 18423 | G6: =(F6-F5)*100/5 -> 60 | H6: 221705 | I6: =H6-H5 -> 19 | J6: 303517 | K6: =J6-J5 -> 0 | L6: 22891 | M6: =(L6-L5)*800/5 -> 640 | N6: 168739 | O6: =N6-N5 -> 3 | P6: 20565 | Q6: =P6-P5 -> 145 | R6: 55047 | S6: =R6-R5 -> 0
A7: 43773 | B7: 42906 | C7: =(B7-B6)*600/5 -> 480 | D7: 38062 | E7: =(D7-D6)*800/5 -> 480 | F7: 18427 | G7: =(F7-F6)*100/5 -> 80 | H7: 221725 | I7: =H7-H6 -> 20 | J7: 303517 | K7: =J7-J6 -> 0 | L7: 22896 | M7: =(L7-L6)*800/5 -> 800 | N7: 168742 | O7: =N7-N6 -> 3 | P7: 20698 | Q7: =P7-P6 -> 133 | R7: 55047 | S7: =R7-R6 -> 0
A8: 43774 | B8: 42912 | C8: =(B8-B7)*600/5 -> 720 | D8: 38066 | E8: =(D8-D7)*800/5 -> 640 | F8: 18431 | G8: =(F8-F7)*100/5 -> 80 | H8: 221767 | I8: =H8-H7 -> 42 | J8: 303517 | K8: =J8-J7 -> 0 | L8: 22900 | M8: =(L8-L7)*800/5 -> 640 | N8: 168745 | O8: =N8-N7 -> 3 | P8: 20856 | Q8: =P8-P7 -> 158 | R8: 55047 | S8: =R8-R7 -> 0
A9: 43775 | B9: 42916 | C9: =(B9-B8)*600/5 -> 480 | D9: 38069 | E9: =(D9-D8)*800/5 -> 480 | F9: 18434 | G9: =(F9-F8)*100/5 -> 60 | H9: 221808 | I9: =H9-H8 -> 41 | J9: 303517 | K9: =J9-J8 -> 0 | L9: 22904 | M9: =(L9-L8)*800/5 -> 640 | N9: 168748 | O9: =N9-N8 -> 3 | P9: 20944 | Q9: =P9-P8 -> 88 | R9: 55047 | S9: =R9-R8 -> 0
A10: 43776 | B10: 42922 | C10: =(B10-B9)*600/5 -> 720 | D10: 38072 | E10: =(D10-D9)*800/5 -> 480 | F10: 18438 | G10: =(F10-F9)*100/5 -> 80 | H10: 221832 | I10: =H10-H9 -> 24 | J10: 303517 | K10: =J10-J9 -> 0 | L10: 22909 | M10: =(L10-L9)*800/5 -> 800 | N10: 168752 | O10: =N10-N9 -> 4 | P10: 21148 | Q10: =P10-P9 -> 204 | R10: 55047 | S10: =R10-R9 -> 0
A11: 43777 | B11: 42926 | C11: =(B11-B10)*600/5 -> 480 | D11: 38075 | E11: =(D11-D10)*800/5 -> 480 | F11: 18441 | G11: =(F11-F10)*100/5 -> 60 | H11: 221866 | I11: =H11-H10 -> 34 | J11: 303517 | K11: =J11-J10 -> 0 | L11: 22912 | M11: =(L11-L10)*800/5 -> 480 | N11: 168754 | O11: =N11-N10 -> 2 | P11: 21255 | Q11: =P11-P10 -> 107 | R11: 55047 | S11: =R11-R10 -> 0
A12: 43778 | B12: 42931 | C12: =(B12-B11)*600/5 -> 600 | D12: 38078 | E12: =(D12-D11)*800/5 -> 480 | F12: 18445 | G12: =(F12-F11)*100/5 -> 80 | H12: 221886 | I12: =H12-H11 -> 20 | J12: 303517 | K12: =J12-J11 -> 0 | L12: 22915 | M12: =(L12-L11)*800/5 -> 480 | N12: 168758 | O12: =N12-N11 -> 4 | P12: 21355 | Q12: =P12-P11 -> 100 | R12: 55047 | S12: =R12-R11 -> 0
A13: 43779 | B13: 42936 | C13: =(B13-B12)*600/5 -> 600 | D13: 38082 | E13: =(D13-D12)*800/5 -> 640 | F13: 18449 | G13: =(F13-F12)*100/5 -> 80 | H13: 221906 | I13: =H13-H12 -> 20 | J13: 303517 | K13: =J13-J12 -> 0 | L13: 22918 | M13: =(L13-L12)*800/5 -> 480 | N13: 168761 | O13: =N13-N12 -> 3 | P13: 21460 | Q13: =P13-P12 -> 105 | R13: 55047 | S13: =R13-R12 -> 0
A14: 43780 | B14: 42941 | C14: =(B14-B13)*600/5 -> 600 | D14: 38085 | E14: =(D14-D13)*800/5 -> 480 | F14: 18453 | G14: =(F14-F13)*100/5 -> 80 | H14: 221925 | I14: =H14-H13 -> 19 | J14: 303517 | K14: =J14-J13 -> 0 | L14: 22921 | M14: =(L14-L13)*800/5 -> 480 | N14: 168768 | O14: =N14-N13 -> 7 | P14: 21565 | Q14: =P14-P13 -> 105 | R14: =R13 -> 55047 | S14: =R14-R13 -> 0
A15: 43781 | B15: 42945 | C15: =(B15-B14)*600/5 -> 480 | D15: 38089 | E15: =(D15-D14)*800/5 -> 640 | F15: 18454 | G15: =(F15-F14)*100/5 -> 20 | H15: 221928 | I15: =H15-H14 -> 3 | J15: 303517 | K15: =J15-J14 -> 0 | L15: 22923 | M15: =(L15-L14)*800/5 -> 320 | N15: 168772 | O15: =N15-N14 -> 4 | P15: 21653 | Q15: =P15-P14 -> 88 | R15: 55047 | S15: =R15-R14 -> 0
A16: 43782 | B16: 42949 | C16: =(B16-B15)*600/5 -> 480 | D16: 38094 | E16: =(D16-D15)*800/5 -> 800 | F16: 18458 | G16: =(F16-F15)*100/5 -> 80 | H16: 221932 | I16: =H16-H15 -> 4 | J16: 303517 | K16: =J16-J15 -> 0 | L16: 22927 | M16: =(L16-L15)*800/5 -> 640 | N16: 168775 | O16: =N16-N15 -> 3 | P16: 21784 | Q16: =P16-P15 -> 131 | R16: =R15 -> 55047 | S16: =R16-R15 -> 0
A17: 43783 | B17: 42954 | C17: =(B17-B16)*600/5 -> 600 | D17: 38097 | E17: =(D17-D16)*800/5 -> 480 | F17: 18463 | G17: =(F17-F16)*100/5 -> 100 | H17: 221936 | I17: =H17-H16 -> 4 | J17: 303517 | K17: =J17-J16 -> 0 | L17: 22929 | M17: =(L17-L16)*800/5 -> 320 | N17: 168776 | O17: =N17-N16 -> 1 | P17: 21934 | Q17: =P17-P16 -> 150 | R17: 55047 | S17: =R17-R16 -> 0
A18: 43784 | B18: 42961 | C18: =(B18-B17)*600/5 -> 840 | D18: 38099 | E18: =(D18-D17)*800/5 -> 320 | F18: 18468 | G18: =(F18-F17)*100/5 -> 100 | H18: 222011 | I18: =H18-H17 -> 75 | J18: 303517 | K18: =J18-J17 -> 0 | L18: 22933 | M18: =(L18-L17)*800/5 -> 640 | N18: 168777 | O18: =N18-N17 -> 1 | P18: 22134 | Q18: =P18-P17 -> 200 | R18: 55047 | S18: =R18-R17 -> 0
A19: 43785 | B19: 42966 | C19: =(B19-B18)*600/5 -> 600 | D19: 38101 | E19: =(D19-D18)*800/5 -> 320 | F19: 18472 | G19: =(F19-F18)*100/5 -> 80 | H19: 222077 | I19: =H19-H18 -> 66 | J19: 303517 | K19: =J19-J18 -> 0 | L19: 22939 | M19: =(L19-L18)*800/5 -> 960 | N19: 168779 | O19: =N19-N18 -> 2 | P19: 22321 | Q19: =P19-P18 -> 187 | R19: 55047 | S19: =R19-R18 -> 0
A20: 43786 | B20: 42971 | C20: =(B20-B19)*600/5 -> 600 | D20: 38104 | E20: =(D20-D19)*800/5 -> 480 | F20: 18475 | G20: =(F20-F19)*100/5 -> 60 | H20: 222094 | I20: =H20-H19 -> 17 | J20: 303517 | K20: =J20-J19 -> 0 | L20: 22944 | M20: =(L20-L19)*800/5 -> 800 | N20: 168783 | O20: =N20-N19 -> 4 | P20: 22501 | Q20: =P20-P19 -> 180 | R20: 55047 | S20: =R20-R19 -> 0
A21: 43787 | B21: 42977 | C21: =(B21-B20)*600/5 -> 720 | D21: 38108 | E21: =(D21-D20)*800/5 -> 640 | F21: 18479 | G21: =(F21-F20)*100/5 -> 80 | H21: 222130 | I21: =H21-H20 -> 36 | J21: 303517 | K21: =J21-J20 -> 0 | L21: 22948 | M21: =(L21-L20)*800/5 -> 640 | N21: 168786 | O21: =N21-N20 -> 3 | P21: 22700 | Q21: =P21-P20 -> 199 | R21: =R20 -> 55047 | S21: =R21-R20 -> 0
A22: 43788 | B22: 42982 | C22: =(B22-B21)*600/5 -> 600 | D22: 38111 | E22: =(D22-D21)*800/5 -> 480 | F22: 18483 | G22: =(F22-F21)*100/5 -> 80 | H22: 222156 | I22: =H22-H21 -> 26 | J22: =J21 -> 303517 | K22: =J22-J21 -> 0 | L22: 22953 | M22: =(L22-L21)*800/5 -> 800 | N22: 168789 | O22: =N22-N21 -> 3 | P22: 22895 | Q22: =P22-P21 -> 195 | R22: =R21 -> 55047 | S22: =R22-R21 -> 0
A23: 43789 | B23: 42986 | C23: =(B23-B22)*600/5 -> 480 | D23: 38113 | E23: =(D23-D22)*800/5 -> 320 | F23: 18486 | G23: =(F23-F22)*100/5 -> 60 | H23: 222175 | I23: =H23-H22 -> 19 | J23: =J22 -> 303517 | K23: =J23-J22 -> 0 | L23: 22956 | M23: =(L23-L22)*800/5 -> 480 | N23: 168791 | O23: =N23-N22 -> 2 | P23: 23096 | Q23: =P23-P22 -> 201 | R23: =R22 -> 55047 | S23: =R23-R22 -> 0
A24: 43790 | B24: 42992 | C24: =(B24-B23)*600/5 -> 720 | D24: 38117 | E24: =(D24-D23)*800/5 -> 640 | F24: 18489 | G24: =(F24-F23)*100/5 -> 60 | H24: 222193 | I24: =H24-H23 -> 18 | J24: =J23 -> 303517 | K24: =J24-J23 -> 0 | L24: 22961 | M24: =(L24-L23)*800/5 -> 800 | N24: 168794 | O24: =N24-N23 -> 3 | P24: 23297 | Q24: =P24-P23 -> 201 | R24: =R23 -> 55047 | S24: =R24-R23 -> 0
A25: 43791 | B25: 42996 | C25: =(B25-B24)*600/5 -> 480 | D25: 38120 | E25: =(D25-D24)*800/5 -> 480 | F25: 18493 | G25: =(F25-F24)*100/5 -> 80 | H25: 222210 | I25: =H25-H24 -> 17 | J25: =J24 -> 303517 | K25: =J25-J24 -> 0 | L25: 22963 | M25: =(L25-L24)*800/5 -> 320 | N25: 168797 | O25: =N25-N24 -> 3 | P25: 23499 | Q25: =P25-P24 -> 202 | R25: =R24 -> 55047 | S25: =R25-R24 -> 0
A26: 43792 | B26: 43001 | C26: =(B26-B25)*600/5 -> 600 | D26: 38124 | E26: =(D26-D25)*800/5 -> 640 | F26: 18497 | G26: =(F26-F25)*100/5 -> 80 | H26: 222230 | I26: =H26-H25 -> 20 | J26: 303517 | K26: =J26-J25 -> 0 | L26: 22966 | M26: =(L26-L25)*800/5 -> 480 | N26: 168801 | O26: =N26-N25 -> 4 | P26: 23700 | Q26: =P26-P25 -> 201 | R26: 55047 | S26: =R26-R25 -> 0
A27: 43793 | B27: 43007 | C27: =(B27-B26)*600/5 -> 720 | D27: 38127 | E27: =(D27-D26)*800/5 -> 480 | F27: 18501 | G27: =(F27-F26)*100/5 -> 80 | H27: 222243 | I27: =H27-H26 -> 13 | J27: 303517 | K27: =J27-J26 -> 0 | L27: 22971 | M27: =(L27-L26)*800/5 -> 800 | N27: 168804 | O27: =N27-N26 -> 3 | P27: 23901 | Q27: =P27-P26 -> 201 | R27: =R26 -> 55047 | S27: =R27-R26 -> 0
A28: 43794 | B28: 43011 | C28: =(B28-B27)*600/5 -> 480 | D28: 38129 | E28: =(D28-D27)*800/5 -> 320 | F28: 18504 | G28: =(F28-F27)*100/5 -> 60 | H28: 222247 | I28: =H28-H27 -> 4 | J28: 303517 | K28: =J28-J27 -> 0 | L28: 22975 | M28: =(L28-L27)*800/5 -> 640 | N28: 168808 | O28: =N28-N27 -> 4 | P28: 24009 | Q28: =P28-P27 -> 108 | R28: =R27 -> 55047 | S28: =R28-R27 -> 0
A29: 43795 | B29: 43016 | C29: =(B29-B28)*600/5 -> 600 | D29: 38134 | E29: =(D29-D28)*800/5 -> 800 | F29: 18507 | G29: =(F29-F28)*100/5 -> 60 | H29: 222252 | I29: =H29-H28 -> 5 | J29: =J28 -> 303517 | K29: =J29-J28 -> 0 | L29: 22979 | M29: =(L29-L28)*800/5 -> 640 | N29: 168812 | O29: =N29-N28 -> 4 | P29: 24207 | Q29: =P29-P28 -> 198 | R29: =R28 -> 55047 | S29: =R29-R28 -> 0
A30: 43796 | B30: 43019 | C30: =(B30-B29)*600/5 -> 360 | D30: 38137 | E30: =(D30-D29)*800/5 -> 480 | F30: 18511 | G30: =(F30-F29)*100/5 -> 80 | H30: 222256 | I30: =H30-H29 -> 4 | J30: =J29 -> 303517 | K30: =J30-J29 -> 0 | L30: 22984 | M30: =(L30-L29)*800/5 -> 800 | N30: 168816 | O30: =N30-N29 -> 4 | P30: 24314 | Q30: =P30-P29 -> 107 | R30: =R29 -> 55047 | S30: =R30-R29 -> 0
A31: 43797 | B31: 43023 | C31: =(B31-B30)*600/5 -> 480 | D31: 38139 | E31: =(D31-D30)*800/5 -> 320 | F31: 18514 | G31: =(F31-F30)*100/5 -> 60 | H31: 222259 | I31: =H31-H30 -> 3 | J31: =J30 -> 303517 | K31: =J31-J30 -> 0 | L31: 22990 | M31: =(L31-L30)*800/5 -> 960 | N31: 168818 | O31: =N31-N30 -> 2 | P31: 24408 | Q31: =P31-P30 -> 94 | R31: =R30 -> 55047 | S31: =R31-R30 -> 0
A32: 43798 | B32: 43029 | C32: =(B32-B31)*600/5 -> 720 | D32: 38144 | E32: =(D32-D31)*800/5 -> 800 | F32: 18521 | G32: =(F32-F31)*100/5 -> 140 | H32: 222361 | I32: =H32-H31 -> 102 | J32: =J31 -> 303517 | K32: =J32-J31 -> 0 | L32: 22992 | M32: =(L32-L31)*800/5 -> 320 | N32: 168820 | O32: =N32-N31 -> 2 | P32: 24502 | Q32: =P32-P31 -> 94 | R32: =R31 -> 55047 | S32: =R32-R31 -> 0
A33: 43799 | B33: 43038 | C33: =(B33-B32)*600/5 -> 1080 | D33: 38147 | E33: =(D33-D32)*800/5 -> 480 | F33: 18524 | G33: =(F33-F32)*100/5 -> 60 | H33: 222372 | I33: =H33-H32 -> 11 | J33: =J32 -> 303517 | K33: =J33-J32 -> 0 | L33: 22995 | M33: =(L33-L32)*800/5 -> 480 | N33: 168820 | O33: =N33-N32 -> 0 | P33: 24572 | Q33: =P33-P32 -> 70 | R33: =R32 -> 55047 | S33: =R33-R32 -> 0
B34: =B33 -> 43038 | C34: =(B34-B32)*600/5 -> 1080 | D34: =D33 -> 38147 | E34: =(D34-D32)*800/5 -> 480 | F34: =F33 -> 18524 | G34: =(F34-F32)*100/5 -> 60 | H34: =H33 -> 222372 | I34: =H34-H32 -> 11 | J34: =J33 -> 303517 | K34: =J34-J32 -> 0 | L34: =L33 -> 22995 | M34: =(L34-L32)*800/5 -> 480 | N34: =N33 -> 168820 | O34: =N34-N32 -> 0 | P34: =P33 -> 24572 | Q34: =P34-P32 -> 70 | R34: =R33 -> 55047 | S34: =R34-R32 -> 0
A35: Total | C35: =SUM(C4:C34) -> 19320 | E35: =SUM(E4:E34) -> 15840 | G35: =SUM(G4:G34) -> 2300 | I35: =SUM(I4:I34) -> 780 | K35: =SUM(K4:K34) -> 0 | M35: =SUM(M4:M34) -> 18880 | Q35: =SUM(Q4:Q34) -> 4461 | S35: =SUM(S4:S34) -> 0

Sheet Water
A1: Main Building, Podium, Hotel and Large cons. Nov. 2019
A2: Day | B2: Main Reading | C2: Cons. | D2: Podium | E2: Cons. | F2: Hotel | G2: Cons. | H2: Large | I2: Cons. | J2: Total | K2: cost.LE
A3: Last | B3: 371948 | D3: 97635200 | F3: 96955500 | H3: 642600 | J3: =C3+E3+G3+I3 -> 0 | K3: =J3*5.86 -> 0
A4: 43770 | B4: 372032 | C4: =(IF((B4-B3)<0,"0",(B4-B3)))*10 -> 840 | D4: 97651700 | E4: =(IF((D4-D3)<0,"0",(D4-D3)))*0.027 -> 445.5 | F4: 96969700 | G4: =(IF((F4-F3)<0,"0",(F4-F3)))*0.027 -> 383.4 | H4: 642761 | I4: =(IF((H4-H3)<0,"0",(H4-H3)))*0.027 -> 4.347 | J4: =C4+E4+G4+I4 -> 1673.247 | K4: =J4*5.86 -> 9805.2274
A5: 43771 | B5: 372147 | C5: =(IF((B5-B4)<0,"0",(B5-B4)))*10 -> 1150 | D5: 97673700 | E5: =(IF((D5-D4)<0,"0",(D5-D4)))*0.027 -> 594 | F5: 96988600 | G5: =(IF((F5-F4)<0,"0",(F5-F4)))*0.027 -> 510.3 | H5: 642967 | I5: =(IF((H5-H4)<0,"0",(H5-H4)))*0.027 -> 5.562 | J5: =C5+E5+G5+I5 -> 2259.862 | K5: =J5*5.86 -> 13242.791
A6: 43772 | B6: 372258 | C6: =(IF((B6-B5)<0,"0",(B6-B5)))*10 -> 1110 | D6: 97695300 | E6: =(IF((D6-D5)<0,"0",(D6-D5)))*0.027 -> 583.2 | F6: 97005300 | G6: =(IF((F6-F5)<0,"0",(F6-F5)))*0.027 -> 450.9 | H6: 643172 | I6: =(IF((H6-H5)<0,"0",(H6-H5)))*0.027 -> 5.535 | J6: =C6+E6+G6+I6 -> 2149.635 | K6: =J6*5.86 -> 12596.861
A7: 43773 | B7: 372371 | C7: =(IF((B7-B6)<0,"0",(B7-B6)))*10 -> 1130 | D7: 97717100 | E7: =(IF((D7-D6)<0,"0",(D7-D6)))*0.027 -> 588.6 | F7: 97022700 | G7: =(IF((F7-F6)<0,"0",(F7-F6)))*0.027 -> 469.8 | H7: 643374 | I7: =(IF((H7-H6)<0,"0",(H7-H6)))*0.027 -> 5.454 | J7: =C7+E7+G7+I7 -> 2193.854 | K7: =J7*5.86 -> 12855.984
A8: 43774 | B8: 372483 | C8: =(IF((B8-B7)<0,"0",(B8-B7)))*10 -> 1120 | D8: 97738600 | E8: =(IF((D8-D7)<0,"0",(D8-D7)))*0.027 -> 580.5 | F8: 97040500 | G8: =(IF((F8-F7)<0,"0",(F8-F7)))*0.027 -> 480.6 | H8: 643572 | I8: =(IF((H8-H7)<0,"0",(H8-H7)))*0.027 -> 5.346 | J8: =C8+E8+G8+I8 -> 2186.446 | K8: =J8*5.86 -> 12812.574
A9: 43775 | B9: 372602 | C9: =(IF((B9-B8)<0,"0",(B9-B8)))*10 -> 1190 | D9: 97762000 | E9: =(IF((D9-D8)<0,"0",(D9-D8)))*0.027 -> 631.8 | F9: 97058200 | G9: =(IF((F9-F8)<0,"0",(F9-F8)))*0.027 -> 477.9 | H9: 643787 | I9: =(IF((H9-H8)<0,"0",(H9-H8)))*0.027 -> 5.805 | J9: =C9+E9+G9+I9 -> 2305.505 | K9: =J9*5.86 -> 13510.259
A10: 43776 | B10: 372721 | C10: =(IF((B10-B9)<0,"0",(B10-B9)))*10 -> 1190 | D10: 97784700 | E10: =(IF((D10-D9)<0,"0",(D10-D9)))*0.027 -> 612.9 | F10: 97077400 | G10: =(IF((F10-F9)<0,"0",(F10-F9)))*0.027 -> 518.4 | H10: 643993 | I10: =(IF((H10-H9)<0,"0",(H10-H9)))*0.027 -> 5.562 | J10: =C10+E10+G10+I10 -> 2326.862 | K10: =J10*5.86 -> 13635.411
A11: 43777 | B11: 372824 | C11: =(IF((B11-B10)<0,"0",(B11-B10)))*10 -> 1030 | D11: 97804000 | E11: =(IF((D11-D10)<0,"0",(D11-D10)))*0.027 -> 521.1 | F11: 97094200 | G11: =(IF((F11-F10)<0,"0",(F11-F10)))*0.027 -> 453.6 | H11: 644170 | I11: =(IF((H11-H10)<0,"0",(H11-H10)))*0.027 -> 4.779 | J11: =C11+E11+G11+I11 -> 2009.479 | K11: =J11*5.86 -> 11775.547
A12: 43778 | B12: 372936 | C12: =(IF((B12-B11)<0,"0",(B12-B11)))*10 -> 1120 | D12: 97825000 | E12: =(IF((D12-D11)<0,"0",(D12-D11)))*0.027 -> 567 | F12: 97112100 | G12: =(IF((F12-F11)<0,"0",(F12-F11)))*0.027 -> 483.3 | H12: 644374 | I12: =(IF((H12-H11)<0,"0",(H12-H11)))*0.027 -> 5.508 | J12: =C12+E12+G12+I12 -> 2175.808 | K12: =J12*5.86 -> 12750.235
A13: 43779 | B13: 373047 | C13: =(IF((B13-B12)<0,"0",(B13-B12)))*10 -> 1110 | D13: 97845400 | E13: =(IF((D13-D12)<0,"0",(D13-D12)))*0.027 -> 550.8 | F13: 97130000 | G13: =(IF((F13-F12)<0,"0",(F13-F12)))*0.027 -> 483.3 | H13: 644554 | I13: =(IF((H13-H12)<0,"0",(H13-H12)))*0.027 -> 4.86 | J13: =C13+E13+G13+I13 -> 2148.96 | K13: =J13*5.86 -> 12592.906
A14: 43780 | B14: 373137 | C14: =(IF((B14-B13)<0,"0",(B14-B13)))*10 -> 900 | D14: 97862000 | E14: =(IF((D14-D13)<0,"0",(D14-D13)))*0.027 -> 448.2 | F14: 97145000 | G14: =(IF((F14-F13)<0,"0",(F14-F13)))*0.027 -> 405 | H14: 644700 | I14: =(IF((H14-H13)<0,"0",(H14-H13)))*0.027 -> 3.942 | J14: =C14+E14+G14+I14 -> 1757.142 | K14: =J14*5.86 -> 10296.852
A15: 43781 | B15: 373260 | C15: =(IF((B15-B14)<0,"0",(B15-B14)))*10 -> 1230 | D15: 97887200 | E15: =(IF((D15-D14)<0,"0",(D15-D14)))*0.027 -> 680.4 | F15: 97161600 | G15: =(IF((F15-F14)<0,"0",(F15-F14)))*0.027 -> 448.2 | H15: 644948 | I15: =(IF((H15-H14)<0,"0",(H15-H14)))*0.027 -> 6.696 | J15: =C15+E15+G15+I15 -> 2365.296 | K15: =J15*5.86 -> 13860.635
... A18: 43784 | B18: 373583 | C18: =(IF((B18-B17)<0,"0",(B18-B17)))*10 -> 1030 | D18: 97947300 | E18: =(IF((D18-D17)<0,"0",(D18-D17)))*0.027 -> 467.1 | F18: 97213700 | G18: =(IF((F18-F17)<0,"0",(F18-F17)))*0.027 -> 437.4 | H18: 645486 | I18: =(IF((H18-H17)<0,"0",(H18-H17)))*0.027 -> 3.375 | J18: =C18+E18+G18+I18 -> 1937.875 | K18: =J18*5.86 -> 11355.948
A19: 43785 | B19: 373690 | C19: =(IF((B19-B18)<0,"0",(B19-B18)))*10 -> 1070 | D19: 97967000 | E19: =(IF((D19-D18)<0,"0",(D19-D18)))*0.027 -> 531.9 | F19: 97231300 | G19: =(IF((F19-F18)<0,"0",(F19-F18)))*0.027 -> 475.2 | H19: 645681 | I19: =(IF((H19-H18)<0,"0",(H19-H18)))*0.027 -> 5.265 | J19: =C19+E19+G19+I19 -> 2082.365 | K19: =J19*5.86 -> 12202.659 | Q19: `
A20: 43786 | B20: 373811 | C20: =(IF((B20-B19)<0,"0",(B20-B19)))*10 -> 1210 | D20: 97988100 | E20: =(IF((D20-D19)<0,"0",(D20-D19)))*0.027 -> 569.7 | F20: 97249300 | G20: =(IF((F20-F19)<0,"0",(F20-F19)))*0.027 -> 486 | H20: 645871 | I20: =(IF((H20-H19)<0,"0",(H20-H19)))*0.027 -> 5.13 | J20: =C20+E20+G20+I20 -> 2270.83 | K20: =J20*5.86 -> 13307.064
A21: 43787 | B21: 373937 | C21: =(IF((B21-B20)<0,"0",(B21-B20)))*10 -> 1260 | D21: 98005300 | E21: =(IF((D21-D20)<0,"0",(D21-D20)))*0.027 -> 464.4 | F21: 97266100 | G21: =(IF((F21-F20)<0,"0",(F21-F20)))*0.027 -> 453.6 | H21: 646066 | I21: =(IF((H21-H20)<0,"0",(H21-H20)))*0.027 -> 5.265 | J21: =C21+E21+G21+I21 -> 2183.265 | K21: =J21*5.86 -> 12793.933
A22: 43788 | B22: 374031 | C22: =(IF((B22-B21)<0,"0",(B22-B21)))*10 -> 940 | D22: 98024600 | E22: =(IF((D22-D21)<0,"0",(D22-D21)))*0.027 -> 521.1 | F22: 97283300 | G22: =(IF((F22-F21)<0,"0",(F22-F21)))*0.027 -> 464.4 | H22: 646268 | I22: =(IF((H22-H21)<0,"0",(H22-H21)))*0.027 -> 5.454 | J22: =C22+E22+G22+I22 -> 1930.954 | K22: =J22*5.86 -> 11315.39
A23: 43789 | B23: 374135 | C23: =(IF((B23-B22)<0,"0",(B23-B22)))*10 -> 1040 | D23: 98046500 | E23: =(IF((D23-D22)<0,"0",(D23-D22)))*0.027 -> 591.3 | F23: 97299300 | G23: =(IF((F23-F22)<0,"0",(F23-F22)))*0.027 -> 432 | H23: 646484 | I23: =(IF((H23-H22)<0,"0",(H23-H22)))*0.027 -> 5.832 | J23: =C23+E23+G23+I23 -> 2069.132 | K23: =J23*5.86 -> 12125.114
A24: 43790 | B24: 374240 | C24: =(IF((B24-B23)<0,"0",(B24-B23)))*10 -> 1050 | D24: 98064500 | E24: =(IF((D24-D23)<0,"0",(D24-D23)))*0.027 -> 486 | F24: 97313800 | G24: =(IF((F24-F23)<0,"0",(F24-F23)))*0.027 -> 391.5 | H24: 646661 | I24: =(IF((H24-H23)<0,"0",(H24-H23)))*0.027 -> 4.779 | J24: =C24+E24+G24+I24 -> 1932.279 | K24: =J24*5.86 -> 11323.155
A25: 43791 | B25: 374343 | C25: =(IF((B25-B24)<0,"0",(B25-B24)))*10 -> 1030 | D25: 98082400 | E25: =(IF((D25-D24)<0,"0",(D25-D24)))*0.027 -> 483.3 | F25: 97330300 | G25: =(IF((F25-F24)<0,"0",(F25-F24)))*0.027 -> 445.5 | H25: 646828 | I25: =(IF((H25-H24)<0,"0",(H25-H24)))*0.027 -> 4.509 | J25: =C25+E25+G25+I25 -> 1963.309 | K25: =J25*5.86 -> 11504.991
A26: 43792 | B26: 374442 | C26: =(IF((B26-B25)<0,"0",(B26-B25)))*10 -> 990 | D26: 98100200 | E26: =(IF((D26-D25)<0,"0",(D26-D25)))*0.027 -> 480.6 | F26: 97346100 | G26: =(IF((F26-F25)<0,"0",(F26-F25)))*0.027 -> 426.6 | H26: 646994 | I26: =(IF((H26-H25)<0,"0",(H26-H25)))*0.027 -> 4.482 | J26: =C26+E26+G26+I26 -> 1901.682 | K26: =J26*5.86 -> 11143.857
A27: 43793 | B27: 374545 | C27: =(IF((B27-B26)<0,"0",(B27-B26)))*10 -> 1030 | D27: 98118800 | E27: =(IF((D27-D26)<0,"0",(D27-D26)))*0.027 -> 502.2 | F27: 97362400 | G27: =(IF((F27-F26)<0,"0",(F27-F26)))*0.027 -> 440.1 | H27: 647196 | I27: =(IF((H27-H26)<0,"0",(H27-H26)))*0.027 -> 5.454 | J27: =C27+E27+G27+I27 -> 1977.754 | K27: =J27*5.86 -> 11589.638
A28: 43794 | B28: 374652 | C28: =(IF((B28-B27)<0,"0",(B28-B27)))*10 -> 1070 | D28: 98131100 | E28: =(IF((D28-D27)<0,"0",(D28-D27)))*0.027 -> 332.1 | F28: 97380000 | G28: =(IF((F28-F27)<0,"0",(F28-F27)))*0.027 -> 475.2 | H28: 647320 | I28: =(IF((H28-H27)<0,"0",(H28-H27)))*0.027 -> 3.348 | J28: =C28+E28+G28+I28 -> 1880.648 | K28: =J28*5.86 -> 11020.597
A29: 43795 | B29: 374759 | C29: =(IF((B29-B28)<0,"0",(B29-B28)))*10 -> 1070 | D29: 98153000 | E29: =(IF((D29-D28)<0,"0",(D29-D28)))*0.027 -> 591.3 | F29: 97396000 | G29: =(IF((F29-F28)<0,"0",(F29-F28)))*0.027 -> 432 | H29: 647560 | I29: =(IF((H29-H28)<0,"0",(H29-H28)))*0.027 -> 6.48 | J29: =C29+E29+G29+I29 -> 2099.78 | K29: =J29*5.86 -> 12304.711
A30: 43796 | B30: 374869 | C30: =(IF((B30-B29)<0,"0",(B30-B29)))*10 -> 1100 | D30: 98159000 | E30: =(IF((D30-D29)<0,"0",(D30-D29)))*0.027 -> 162 | F30: 97409700 | G30: =(IF((F30-F29)<0,"0",(F30-F29)))*0.027 -> 369.9 | H30: 647689 | I30: =(IF((H30-H29)<0,"0",(H30-H29)))*0.027 -> 3.483 | J30: =C30+E30+G30+I30 -> 1635.383 | K30: =J30*5.86 -> 9583.3444
A31: 43797 | B31: 374980 | C31: =(IF((B31-B30)<0,"0",(B31-B30)))*10 -> 1110 | D31: 98193300 | E31: =(IF((D31-D30)<0,"0",(D31-D30)))*0.027 -> 926.1 | F31: 97430600 | G31: =(IF((F31-F30)<0,"0",(F31-F30)))*0.027 -> 564.3 | H31: 648184 | I31: =(IF((H31-H30)<0,"0",(H31-H30)))*0.027 -> 13.365 | J31: =C31+E31+G31+I31 -> 2613.765 | K31: =J31*5.86 -> 15316.663
... A33: 43799 | B33: 375138 | C33: =(IF((B33-B32)<0,"0",(B33-B32)))*10 -> 950 | D33: 98230400 | E33: =(IF((D33-D32)<0,"0",(D33-D32)))*0.027 -> 496.8 | F33: 97463800 | G33: =(IF((F33-F32)<0,"0",(F33-F32)))*0.027 -> 421.2 | H33: 648691 | I33: =(IF((H33-H32)<0,"0",(H33-H32)))*0.027 -> 7.56 | J33: =C33+E33+G33+I33 -> 1875.56 | K33: =J33*5.86 -> 10990.782
B34: =B33 -> 375138 | C34: =(IF((B34-B33)<0,"0",(B34-B33)))*10 -> 0 | D34: =D33 -> 98230400 | E34: =(IF((D34-D33)<0,"0",(D34-D33)))*0.027 -> 0 | F34: =F33 -> 97463800 | G34: =(IF((F34-F33)<0,"0",(F34-F33)))*0.027 -> 0 | H34: =H33 -> 648691 | I34: =(IF((H34-H33)<0,"0",(H34-H33)))*0.027 -> 0 | J34: =C34+E34+G34+I34 -> 0 | K34: =J34*5.86 -> 0
A35: Total | C35: =SUM(C4:C34) -> 31900 | E35: =SUM(E4:E34) -> 16070.4 | G35: =SUM(G4:G34) -> 13724.1 | I35: =SUM(I4:I34) -> 164.457 | J35: =SUM(J4:J31) -> 58367.168 | K35: =SUM(K4:K31) -> 342031.6

Sheet ELECT.
A1: Feeders and transformers Electrity cons. Nov 2019
A2: Day | B2: Rooms Sold | C2: New Chillers | D2: Cons | E2: F-1 | F2: Cons. | G2: F-2 | H2: Cons. | I2: Total | J2: T-1 | K2: Cons. | L2: T-2 | M2: Cons. | N2: T-3 | O2: Cons. | P2: T-4 | Q2: Cons. | R2: T-5 | S2: Cons. | T2: T-6 | U2: Cons. | V2: T-7 | W2: Cons. | X2: Total | Y2: Diff | Z2: Daily Money Value | AA2: MTD Total Money
A3: Last | C3: 16704 | D3: 0 | E3: 19737593 | F3: 0 | G3: 56370688 | H3: 0 | I3: =F3+H3 -> 0 | J3: 4991084 | K3: 0 | L3: 5316936 | M3: 0 | N3: 3440825 | O3: 0 | P3: 8134977 | Q3: 0 | R3: 12292323 | S3: 0 | T3: 0 | V3: 9183292 | X3: =K3+M3+O3+Q3+S3+U3+W3 -> 0 | Y3: =I3-X3 -> 0 | Z3: =(0.93352*(W3+S3)+0.5568*(Q3+O3))*0.26 -> 0 | AA3: =SUM(#REF!) -> #REF!
A4: 43770 | B4: 335 | C4: 16708 | D4: =IF((C4-C3)<0,"0",(C4-C3))*160 -> 640 | E4: 19748210 | F4: =IF((E4-E3)<0,"0",(E4-E3)) -> 10617 | G4: 56417407 | H4: =IF((G4-G3)<0,"0",(G4-G3)) -> 46719 | I4: =F4+H4 -> 57336 | J4: 4995830 | K4: =IF((J4-J3)<0,"0",(J4-J3)) -> 4746 | L4: 5321018 | M4: =IF((L4-L3)<0,"0",(L4-L3)) -> 4082 | N4: 3444020 | O4: =(IF((N4-N3)<0,"0",(N4-N3)))*2 -> 6390 | P4: 8142771 | Q4: =IF((P4-P3)<0,"0",(P4-P3)) -> 7794 | R4: 12302170 | S4: =IF((R4-R3)<0,"0",(R4-R3)) -> 9847 | T4: 0 | V4: 9194425 | W4: =IF((V4-V3)<0,"0",(V4-V3)) -> 11133 | X4: =K4+M4+O4+Q4+S4+U4+W4 -> 43992 | Y4: =I4-X4 -> 13344 | Z4: =(0.93352*(W4+S4)+0.5568*(Q4+O4))*0.26 -> 7145.5542 | AA4: =SUM(Z1:Z4) -> 7145.5542
A5: 43771 | B5: 323 | C5: 16714 | D5: =IF((C5-C4)<0,"0",(C5-C4))*160 -> 960 | E5: 19756540 | F5: =IF((E5-E4)<0,"0",(E5-E4)) -> 8330 | G5: 56453104 | H5: =IF((G5-G4)<0,"0",(G5-G4)) -> 35697 | I5: =F5+H5 -> 44027 | J5: 4999728 | K5: =IF((J5-J4)<0,"0",(J5-J4)) -> 3898 | L5: 5324318 | M5: =IF((L5-L4)<0,"0",(L5-L4)) -> 3300 | N5: 3446477 | O5: =(IF((N5-N4)<P100,"0",(N5-N4)))*2 -> 4914 | P5: 8150638 | Q5: =IF((P5-P4)<0,"0",(P5-P4)) -> 7867 | R5: 12309645 | S5: =IF((R5-R4)<0,"0",(R5-R4)) -> 7475 | T5: 0 | V5: 9202889 | W5: =IF((V5-V4)<0,"0",(V5-V4)) -> 8464 | X5: =K5+M5+O5+Q5+S5+U5+W5 -> 35918 | Y5: =I5-X5 -> 8109 | Z5: =(0.93352*(W5+S5)+0.5568*(Q5+O5))*0.26 -> 5718.9174 | AA5: =SUM(Z2:Z5) -> 12864.472
A6: 43772 | B6: 345 | C6: 16720 | D6: =IF((C6-C5)<0,"0",(C6-C5))*160 -> 960 | E6: 19774935 | F6: =IF((E6-E5)<0,"0",(E6-E5)) -> 18395 | G6: 56527923 | H6: =IF((G6-G5)<0,"0",(G6-G5)) -> 74819 | I6: =F6+H6 -> 93214 | J6: 5007719 | K6: =IF((J6-J5)<0,"0",(J6-J5)) -> 7991 | L6: 5331727 | M6: =IF((L6-L5)<0,"0",(L6-L5)) -> 7409 | N6: 3451787 | O6: =(IF((N6-N5)<0,"0",(N6-N5)))*2 -> 10620 | P6: 8165374 | Q6: =IF((P6-P5)<0,"0",(P6-P5)) -> 14736 | R6: 12324995 | S6: =IF((R6-R5)<0,"0",(R6-R5)) -> 15350 | T6: 0 | V6: 9220558 | W6: =IF((V6-V5)<0,"0",(V6-V5)) -> 17669 | X6: =K6+M6+O6+Q6+S6+U6+W6 -> 73775 | Y6: =I6-X6 -> 19439 | Z6: =(0.93352*(W6+S6)+0.5568*(Q6+O6))*0.26 -> 11684.951 | AA6: =SUM(Z3:Z6) -> 24549.422
A7: 43773 | B7: 338 | C7: 16725 | D7: =IF((C7-C6)<0,"0",(C7-C6))*160 -> 800 | E7: 19786958 | F7: =IF((E7-E6)<0,"0",(E7-E6)) -> 12023 | G7: 56578345 | H7: =IF((G7-G6)<0,"0",(G7-G6)) -> 50422 | I7: =F7+H7 -> 62445 | J7: 5013342 | K7: =IF((J7-J6)<0,"0",(J7-J6)) -> 5623 | L7: 5336670 | M7: =IF((L7-L6)<0,"0",(L7-L6)) -> 4943 | N7: 3455345 | O7: =(IF((N7-N6)<0,"0",(N7-N6)))*2 -> 7116 | P7: 8175305 | Q7: =IF((P7-P6)<0,"0",(P7-P6)) -> 9931 | R7: 12335053 | S7: =IF((R7-R6)<0,"0",(R7-R6)) -> 10058 | T7: 0 | V7: 9232584 | W7: =IF((V7-V6)<0,"0",(V7-V6)) -> 12026 | X7: =K7+M7+O7+Q7+S7+U7+W7 -> 49697 | Y7: =I7-X7 -> 12748 | Z7: =(0.93352*(W7+S7)+0.5568*(Q7+O7))*0.26 -> 7827.9826 | AA7: =SUM(Z4:Z7) -> 32377.405
A8: 43774 | B8: 345 | C8: 16732 | D8: =IF((C8-C7)<0,"0",(C8-C7))*160 -> 1120 | E8: 19799105 | F8: =IF((E8-E7)<0,"0",(E8-E7)) -> 12147 | G8: 56629466 | H8: =IF((G8-G7)<0,"0",(G8-G7)) -> 51121 | I8: =F8+H8 -> 63268 | J8: 5018623 | K8: =IF((J8-J7)<0,"0",(J8-J7)) -> 5281 | L8: 5341387 | M8: =IF((L8-L7)<0,"0",(L8-L7)) -> 4717 | N8: 3458957 | O8: =(IF((N8-N7)<0,"0",(N8-N7)))*2 -> 7224 | P8: 8185471 | Q8: =IF((P8-P7)<0,"0",(P8-P7)) -> 10166 | R8: 12345059 | S8: =IF((R8-R7)<0,"0",(R8-R7)) -> 10006 | T8: 0 | V8: 9244554 | W8: =IF((V8-V7)<0,"0",(V8-V7)) -> 11970 | X8: =K8+M8+O8+Q8+S8+U8+W8 -> 49364 | Y8: =I8-X8 -> 13904 | Z8: =(0.93352*(W8+S8)+0.5568*(Q8+O8))*0.26 -> 7851.4248 | AA8: =SUM(Z5:Z8) -> 33083.275
A9: 43775 | B9: 358 | C9: 16737 | D9: =IF((C9-C8)<0,"0",(C9-C8))*160 -> 800 | E9: 19811406 | F9: =IF((E9-E8)<0,"0",(E9-E8)) -> 12301 | G9: 56680442 | H9: =IF((G9-G8)<0,"0",(G9-G8)) -> 50976 | I9: =F9+H9 -> 63277 | J9: 5024149 | K9: =IF((J9-J8)<0,"0",(J9-J8)) -> 5526 | L9: 5346117 | M9: =IF((L9-L8)<0,"0",(L9-L8)) -> 4730 | N9: 3462667 | O9: =(IF((N9-N8)<0,"0",(N9-N8)))*2 -> 7420 | P9: 8195989 | Q9: =IF((P9-P8)<0,"0",(P9-P8)) -> 10518 | R9: 12355352 | S9: =IF((R9-R8)<0,"0",(R9-R8)) -> 10293 | T9: 0 | V9: 9256828 | W9: =IF((V9-V8)<0,"0",(V9-V8)) -> 12274 | X9: =K9+M9+O9+Q9+S9+U9+W9 -> 50761 | Y9: =I9-X9 -> 12516 | Z9: =(0.93352*(W9+S9)+0.5568*(Q9+O9))*0.26 -> 8074.2023 | AA9: =SUM(Z6:Z9) -> 35438.56
A10: 43776 | B10: 360 | C10: 16743 | D10: =IF((C10-C9)<0,"0",(C10-C9))*160 -> 960 | E10: 19828845 | F10: =IF((E10-E9)<0,"0",(E10-E9)) -> 17439 | G10: 56751707 | H10: =IF((G10-G9)<0,"0",(G10-G9)) -> 71265 | I10: =F10+H10 -> 88704 | J10: 5031667 | K10: =IF((J10-J9)<0,"0",(J10-J9)) -> 7518 | L10: 5352777 | M10: =IF((L10-L9)<0,"0",(L10-L9)) -> 6660 | N10: 3467956 | O10: =(IF((N10-N9)<0,"0",(N10-N9)))*2 -> 10578 | P10: 8211007 | Q10: =IF((P10-P9)<0,"0",(P10-P9)) -> 15018 | R10: 12369912 | S10: =IF((R10-R9)<0,"0",(R10-R9)) -> 14560 | T10: 0 | V10: 9273239 | W10: =IF((V10-V9)<0,"0",(V10-V9)) -> 16411 | X10: =K10+M10+O10+Q10+S10+U10+W10 -> 70745 | Y10: =I10-X10 -> 17959 | Z10: =(0.93352*(W10+S10)+0.5568*(Q10+O10))*0.26 -> 11222.614 | AA10: =SUM(Z7:Z10) -> 34976.224
A11: 43777 | B11: 317 | C11: 16748 | D11: =IF((C11-C10)<0,"0",(C11-C10))*160 -> 800 | E11: 19843358 | F11: =IF((E11-E10)<0,"0",(E11-E10)) -> 14513 | G11: 56811205 | H11: =IF((G11-G10)<0,"0",(G11-G10)) -> 59498 | I11: =F11+H11 -> 74011 | J11: 5037582 | K11: =IF((J11-J10)<0,"0",(J11-J10)) -> 5915 | L11: 5357934 | M11: =IF((L11-L10)<0,"0",(L11-L10)) -> 5157 | N11: 3472522 | O11: =(IF((N11-N10)<0,"0",(N11-N10)))*2 -> 9132 | P11: 8223735 | Q11: =IF((P11-P10)<0,"0",(P11-P10)) -> 12728 | R11: 12382013 | S11: =IF((R11-R10)<0,"0",(R11-R10)) -> 12101 | T11: 0 | V11: 9287072 | W11: =IF((V11-V10)<0,"0",(V11-V10)) -> 13833 | X11: =K11+M11+O11+Q11+S11+U11+W11 -> 58866 | Y11: =I11-X11 -> 15145 | Z11: =(0.93352*(W11+S11)+0.5568*(Q11+O11))*0.26 -> 9459.2045 | AA11: =SUM(Z8:Z11) -> 36607.446
A12: 43778 | B12: 332 | C12: 16753 | D12: =IF((C12-C11)<0,"0",(C12-C11))*160 -> 800 | E12: 19855361 | F12: =IF((E12-E11)<0,"0",(E12-E11)) -> 12003 | G12: 56861690 | H12: =IF((G12-G11)<0,"0",(G12-G11)) -> 50485 | I12: =F12+H12 -> 62488 | J12: 5042886 | K12: =IF((J12-J11)<0,"0",(J12-J11)) -> 5304 | L12: 5362252 | M12: =IF((L12-L11)<0,"0",(L12-L11)) -> 4318 | N12: 3476299 | O12: =(IF((N12-N11)<0,"0",(N12-N11)))*2 -> 7554 | P12: 8234299 | Q12: =IF((P12-P11)<0,"0",(P12-P11)) -> 10564 | R12: 12391882 | S12: =IF((R12-R11)<0,"0",(R12-R11)) -> 9869 | T12: 0 | V12: 9299066 | W12: =IF((V12-V11)<0,"0",(V12-V11)) -> 11994 | X12: =K12+M12+O12+Q12+S12+U12+W12 -> 49603 | Y12: =I12-X12 -> 12885 | Z12: =(0.93352*(W12+S12)+0.5568*(Q12+O12))*0.26 -> 7929.389 | AA12: =SUM(Z9:Z12) -> 36685.41
A13: 43779 | B13: 322 | C13: 16759 | D13: =IF((C13-C12)<0,"0",(C13-C12))*160 -> 960 | E13: 19864959 | F13: =IF((E13-E12)<0,"0",(E13-E12)) -> 9598 | G13: 56902459 | H13: =IF((G13-G12)<0,"0",(G13-G12)) -> 40769 | I13: =F13+H13 -> 50367 | J13: 5047050 | K13: =IF((J13-J12)<0,"0",(J13-J12)) -> 4164 | L13: 5365617 | M13: =IF((L13-L12)<0,"0",(L13-L12)) -> 3365 | N13: 3479352 | O13: =(IF((N13-N12)<0,"0",(N13-N12)))*2 -> 6106 | P13: 8242346 | Q13: =IF((P13-P12)<0,"0",(P13-P12)) -> 8047 | R13: 12399904 | S13: =IF((R13-R12)<0,"0",(R13-R12)) -> 8022 | T13: 0 | V13: 9308788 | W13: =IF((V13-V12)<0,"0",(V13-V12)) -> 9722 | X13: =K13+M13+O13+Q13+S13+U13+W13 -> 39426 | Y13: =I13-X13 -> 10941 | Z13: =(0.93352*(W13+S13)+0.5568*(Q13+O13))*0.26 -> 6355.64 | AA13: =SUM(Z10:Z13) -> 34966.848
A14: 43780 | B14: 292 | C14: 16765 | D14: =IF((C14-C13)<0,"0",(C14-C13))*160 -> 960 | E14: 19883462 | F14: =IF((E14-E13)<0,"0",(E14-E13)) -> 18503 | G14: 56977375 | H14: =IF((G14-G13)<0,"0",(G14-G13)) -> 74916 | I14: =F14+H14 -> 93419 | J14: 5054970 | K14: =IF((J14-J13)<0,"0",(J14-J13)) -> 7920 | L14: 5372739 | M14: =IF((L14-L13)<0,"0",(L14-L13)) -> 7122 | N14: 3484935 | O14: =(IF((N14-N13)<0,"0",(N14-N13)))*2 -> 11166 | P14: 8258422 | Q14: =IF((P14-P13)<0,"0",(P14-P13)) -> 16076 | R14: 12414799 | S14: =IF((R14-R13)<0,"0",(R14-R13)) -> 14895 | T14: 0 | V14: 9326340 | W14: =IF((V14-V13)<0,"0",(V14-V13)) -> 17552 | X14: =K14+M14+O14+Q14+S14+U14+W14 -> 74731 | Y14: =I14-X14 -> 18688 | Z14: =(0.93352*(W14+S14)+0.5568*(Q14+O14))*0.26 -> 11819.15 | AA14: =SUM(Z11:Z14) -> 35563.383
A15: 43781 | B15: 325 | C15: 16768 | D15: =IF((C15-C14)<0,"0",(C15-C14))*160 -> 480 | E15: 19895075 | F15: =IF((E15-E14)<0,"0",(E15-E14)) -> 11613 | G15: 57026167 | H15: =IF((G15-G14)<0,"0",(G15-G14)) -> 48792 | I15: =F15+H15 -> 60405 | J15: 5060152 | K15: =IF((J15-J14)<0,"0",(J15-J14)) -> 5182 | L15: 5377176 | M15: =IF((L15-L14)<0,"0",(L15-L14)) -> 4437 | N15: 3488421 | O15: =(IF((N15-N14)<0,"0",(N15-N14)))*2 -> 6972 | P15: 8268047 | Q15: =IF((P15-P14)<0,"0",(P15-P14)) -> 9625 | R15: 12427190 | S15: =IF((R15-R14)<0,"0",(R15-R14)) -> 12391 | T15: 0 | V15: 9337937 | W15: =IF((V15-V14)<0,"0",(V15-V14)) -> 11597 | X15: =K15+M15+O15+Q15+S15+U15+W15 -> 50204 | Y15: =I15-X15 -> 10201 | Z15: =(0.93352*(W15+S15)+0.5568*(Q15+O15))*0.26 -> 8224.9667 | AA15: =SUM(Z12:Z15) -> 34329.146
A16: 43782 | B16: 340 | C16: 16771 | D16: =IF((C16-C15)<0,"0",(C16-C15))*160 -> 480 | E16: 19908459 | F16: =IF((E16-E15)<0,"0",(E16-E15)) -> 13384 | G16: 57084234 | H16: =IF((G16-G15)<0,"0",(G16-G15)) -> 58067 | I16: =F16+H16 -> 71451 | J16: 5066214 | K16: =IF((J16-J15)<0,"0",(J16-J15)) -> 6062 | L16: 5382264 | M16: =IF((L16-L15)<0,"0",(L16-L15)) -> 5088 | N16: 3492500 | O16: =(IF((N16-N15)<0,"0",(N16-N15)))*2 -> 8158 | P16: 8279328 | Q16: =IF((P16-P15)<0,"0",(P16-P15)) -> 11281 | R16: 12436376 | S16: =IF((R16-R15)<0,"0",(R16-R15)) -> 9186 | T16: 0 | V16: 9351978 | W16: =IF((V16-V15)<0,"0",(V16-V15)) -> 14041 | X16: =K16+M16+O16+Q16+S16+U16+W16 -> 53816 | Y16: =I16-X16 -> 17635 | Z16: =(0.93352*(W16+S16)+0.5568*(Q16+O16))*0.26 -> 8451.6911 | AA16: =SUM(Z13:Z16) -> 34851.448
A17: 43783 | B17: 340 | C17: 16774 | D17: =IF((C17-C16)<0,"0",(C17-C16))*160 -> 480 | E17: 19923227 | F17: =IF((E17-E16)<0,"0",(E17-E16)) -> 14768 | G17: 57147799 | H17: =IF((G17-G16)<0,"0",(G17-G16)) -> 63565 | I17: =F17+H17 -> 78333 | J17: 5072800 | K17: =IF((J17-J16)<0,"0",(J17-J16)) -> 6586 | L17: 5387590 | M17: =IF((L17-L16)<0,"0",(L17-L16)) -> 5326 | N17: 3497114 | O17: =(IF((N17-N16)<0,"0",(N17-N16)))*2 -> 9228 | P17: 8291806 | Q17: =IF((P17-P16)<0,"0",(P17-P16)) -> 12478 | R17: 12449292 | S17: =IF((R17-R16)<0,"0",(R17-R16)) -> 12916 | T17: 0 | V17: 9367136 | W17: =IF((V17-V16)<0,"0",(V17-V16)) -> 15158 | X17: =K17+M17+O17+Q17+S17+U17+W17 -> 61692 | Y17: =I17-X17 -> 16641 | Z17: =(0.93352*(W17+S17)+0.5568*(Q17+O17))*0.26 -> 9956.3207 | AA17: =SUM(Z14:Z17) -> 38452.128
... A33: 43799 | B33: 355 | C33: 16837 | D33: =IF((C33-C32)<0,"0",(C33-C32))*160 -> 480 | E33: 20117285 | F33: =IF((E33-E32)<0,"0",(E33-E32)) -> 11941 | G33: 58009635 | H33: =IF((G33-G32)<0,"0",(G33-G32)) -> 53742 | I33: =F33+H33 -> 65683 | J33: 5164818 | K33: =IF((J33-J32)<0,"0",(J33-J32)) -> 5396 | L33: 5463312 | M33: =IF((L33-L32)<0,"0",(L33-L32)) -> 4662 | N33: 3554928 | O33: =(IF((N33-N32)<0,"0",(N33-N32)))*2 -> 7168 | P33: 8446105 | Q33: =IF((P33-P32)<0,"0",(P33-P32)) -> 9618 | R33: 12629844 | S33: =IF((R33-R32)<0,"0",(R33-R32)) -> 11460 | T33: 0 | V33: 9577366 | W33: =IF((V33-V32)<0,"0",(V33-V32)) -> 13189 | X33: =K33+M33+O33+Q33+S33+U33+W33 -> 51493 | Y33: =I33-X33 -> 14190 | Z33: =(0.93352*(W33+S33)+0.5568*(Q33+O33))*0.26 -> 8412.7626 | AA33: =SUM(Z30:Z33) -> 36444.026
C34: =C33 -> 16837 | D34: =IF((C34-C33)<0,"0",(C34-C33))*160 -> 0 | E34: =E33 -> 20117285 | F34: =IF((E34-E33)<0,"0",(E34-E33)) -> 0 | G34: =G33 -> 58009635 | H34: =IF((G34-G33)<0,"0",(G34-G33)) -> 0 | I34: =F34+H34 -> 0 | J34: =J33 -> 5164818 | K34: =IF((J34-J33)<0,"0",(J34-J33)) -> 0 | L34: =L33 -> 5463312 | M34: =IF((L34-L33)<0,"0",(L34-L33)) -> 0 | N34: =N33 -> 3554928 | O34: =(IF((N34-N33)<0,"0",(N34-N33)))*2 -> 0 | P34: =P33 -> 8446105 | Q34: =IF((P34-P33)<0,"0",(P34-P33)) -> 0 | R34: =R33 -> 12629844 | S34: =IF((R34-R33)<0,"0",(R34-R33)) -> 0 | T34: 0 | V34: =V33 -> 9577366 | W34: =IF((V34-V33)<0,"0",(V34-V33)) -> 0 | X34: =K34+M34+O34+Q34+S34+U34+W34 -> 0 | Y34: =I34-X34 -> 0 | Z34: =(0.93352*(W34+S34)+0.5568*(Q34+O34))*0.26 -> 0 | AA34: =SUM(Z31:Z34) -> 27252.722
A35: Total | D35: =SUM(D3:D34) -> 21280 | F35: =SUM(F3:F34) -> 379692 | H35: =SUM(H3:H34) -> 1638947 | I35: =F35+H35 -> 2018639 | K35: =SUM(K3:K34) -> 173734 | M35: =SUM(M3:M34) -> 146376 | O35: =SUM(O3:O34) -> 228206 | Q35: =SUM(Q3:Q34) -> 311128 | S35: =SUM(S3:T34) -> 337521 | W35: =SUM(W3:W34) -> 394074 | X35: =SUM(X4:X31) -> 1483848 | Y35: =SUM(Y4:Y31) -> 397280 | Z35: =SUM(Z5:Z31) -> 230892.43

Sheet Gas
A1: Gas Con. Nov 2019
A2: Day | B2: Main | C2: Cons.
A3: Last | B3: 16030756
A4: 43770 | B4: 16032993 | C4: =IF((B4-B3)<0,"0",(B4-B3)) -> 2237
A5: 43771 | B5: 16035893 | C5: =IF((B5-B4)<0,"0",(B5-B4)) -> 2900
A6: 43772 | B6: 16039398 | C6: =IF((B6-B5)<0,"0",(B6-B5)) -> 3505
A7: 43773 | B7: 16043451 | C7: =IF((B7-B6)<0,"0",(B7-B6)) -> 4053
A8: 43774 | B8: 16046836 | C8: =IF((B8-B7)<0,"0",(B8-B7)) -> 3385
A9: 43775 | B9: 16049936 | C9: =IF((B9-B8)<0,"0",(B9-B8)) -> 3100
A10: 43776 | B10: 16053959 | C10: =IF((B10-B9)<0,"0",(B10-B9)) -> 4023
A11: 43777 | B11: 16058088 | C11: =IF((B11-B10)<0,"0",(B11-B10)) -> 4129
A12: 43778 | B12: 16061845 | C12: =IF((B12-B11)<0,"0",(B12-B11)) -> 3757
A13: 43779 | B13: 16064875 | C13: =IF((B13-B12)<0,"0",(B13-B12)) -> 3030
A14: 43780 | B14: 16069004 | C14: =IF((B14-B13)<0,"0",(B14-B13)) -> 4129
A15: 43781 | B15: 16072487 | C15: =IF((B15-B14)<0,"0",(B15-B14)) -> 3483
... A33: 43799 | B33: 16134402 | C33: =IF((B33-B32)<0,"0",(B33-B32)) -> 2085
B34: =B33 -> 16134402 | C34: =IF((B34-B33)<0,"0",(B34-B33)) -> 0
