Workbook

Sheet TOTAL
A1: Site Name | B1: Day | C1: Month | D1: Year | E1: Total Electricity Kwh | F1: Electricity Tariff ($/Kwh) | G1: Natual Gas (m3) | H1: Natural Gas $/m3 | I1: Water Utility Supply (m3) m3 | J1: Water Utility Supply (m3) $/m3 | K1: Room Nights
A2: Cairo at Nile Plaza | B2: 1 | C2: 3 | D2: 2019 | E2: =(((Submetering!O2+Submetering!P2)*0.842284+Submetering!Q2+(Submetering!M2+Submetering!N2+Submetering!Y2)*0.7362)+(Submetering!O2+Submetering!P2+Submetering!Q2)*0.1488+(Submetering!M2+Submetering!N2+Submetering!Y2)*0.1167+(Submetering!K2+Submetering!L2-Submetering!Z2-Submetering!AA2-Submetering!AB2-Submetering!AC2-Submetering!Q2)+(Submetering!M2+Submetering!N2+Submetering!Y2)*0.1139) -> 91623.129 | F2: 1.15 | G2: =Gas!C4*0.9147 -> 3573.7329 | H2: 2.25 | I2: =Submetering!AE2+Submetering!AD2+Submetering!H2 -> 916 | J2: 9.12 | K2: =ELECT.!B4 -> 334
A3: Cairo at Nile Plaza | B3: =B2+1 -> 2 | C3: 3 | D3: 2019 | E3: =(((Submetering!O3+Submetering!P3)*0.842284+Submetering!Q3+(Submetering!M3+Submetering!N3+Submetering!Y3)*0.7362)+(Submetering!O3+Submetering!P3+Submetering!Q3)*0.1488+(Submetering!M3+Submetering!N3+Submetering!Y3)*0.1167+(Submetering!K3+Submetering!L3-Submetering!Z3-Submetering!AA3-Submetering!AB3-Submetering!AC3-Submetering!Q3)+(Submetering!M3+Submetering!N3+Submetering!Y3)*0.1139) -> 42570.008 | F3: 1.15 | G3: =Gas!C5*0.9147 -> 3561.8418 | H3: 2.25 | I3: =Submetering!AE3+Submetering!AD3+Submetering!H3 -> 786 | J3: 9.12 | K3: =ELECT.!B5 -> 323
A4: Cairo at Nile Plaza | B4: =B3+1 -> 3 | C4: 3 | D4: 2019 | E4: =(((Submetering!O4+Submetering!P4)*0.842284+Submetering!Q4+(Submetering!M4+Submetering!N4+Submetering!Y4)*0.7362)+(Submetering!O4+Submetering!P4+Submetering!Q4)*0.1488+(Submetering!M4+Submetering!N4+Submetering!Y4)*0.1167+(Submetering!K4+Submetering!L4-Submetering!Z4-Submetering!AA4-Submetering!AB4-Submetering!AC4-Submetering!Q4)+(Submetering!M4+Submetering!N4+Submetering!Y4)*0.1139) -> 59641.484 | F4: 1.15 | G4: =Gas!C6*0.9147 -> 3131.9328 | H4: 2.25 | I4: =Submetering!AE4+Submetering!AD4+Submetering!H4 -> 896 | J4: 9.12 | K4: =ELECT.!B6 -> 275
A5: Cairo at Nile Plaza | B5: =B4+1 -> 4 | C5: 3 | D5: 2019 | E5: =(((Submetering!O5+Submetering!P5)*0.842284+Submetering!Q5+(Submetering!M5+Submetering!N5+Submetering!Y5)*0.7362)+(Submetering!O5+Submetering!P5+Submetering!Q5)*0.1488+(Submetering!M5+Submetering!N5+Submetering!Y5)*0.1167+(Submetering!K5+Submetering!L5-Submetering!Z5-Submetering!AA5-Submetering!AB5-Submetering!AC5-Submetering!Q5)+(Submetering!M5+Submetering!N5+Submetering!Y5)*0.1139) -> 47807.624 | F5: 1.15 | G5: =Gas!C7*0.9147 -> 3356.949 | H5: 2.25 | I5: =Submetering!AE5+Submetering!AD5+Submetering!H5 -> 676 | J5: 9.12 | K5: =ELECT.!B7 -> 300
A6: Cairo at Nile Plaza | B6: =B5+1 -> 5 | C6: 3 | D6: 2019 | E6: =(((Submetering!O6+Submetering!P6)*0.842284+Submetering!Q6+(Submetering!M6+Submetering!N6+Submetering!Y6)*0.7362)+(Submetering!O6+Submetering!P6+Submetering!Q6)*0.1488+(Submetering!M6+Submetering!N6+Submetering!Y6)*0.1167+(Submetering!K6+Submetering!L6-Submetering!Z6-Submetering!AA6-Submetering!AB6-Submetering!AC6-Submetering!Q6)+(Submetering!M6+Submetering!N6+Submetering!Y6)*0.1139) -> 50256.047 | F6: 1.15 | G6: =Gas!C8*0.9147 -> 3647.8236 | H6: 2.25 | I6: =Submetering!AE6+Submetering!AD6+Submetering!H6 -> 796 | J6: 9.12 | K6: =ELECT.!B8 -> 375
A7: Cairo at Nile Plaza | B7: =B6+1 -> 6 | C7: 3 | D7: 2019 | E7: =(((Submetering!O7+Submetering!P7)*0.842284+Submetering!Q7+(Submetering!M7+Submetering!N7+Submetering!Y7)*0.7362)+(Submetering!O7+Submetering!P7+Submetering!Q7)*0.1488+(Submetering!M7+Submetering!N7+Submetering!Y7)*0.1167+(Submetering!K7+Submetering!L7-Submetering!Z7-Submetering!AA7-Submetering!AB7-Submetering!AC7-Submetering!Q7)+(Submetering!M7+Submetering!N7+Submetering!Y7)*0.1139) -> 38670.331 | F7: 1.15 | G7: =Gas!C9*0.9147 -> 3967.0539 | H7: 2.25 | I7: =Submetering!AE7+Submetering!AD7+Submetering!H7 -> 826 | J7: 9.12 | K7: =ELECT.!B9 -> 323
A8: Cairo at Nile Plaza | B8: =B7+1 -> 7 | C8: 3 | D8: 2019 | E8: =(((Submetering!O8+Submetering!P8)*0.842284+Submetering!Q8+(Submetering!M8+Submetering!N8+Submetering!Y8)*0.7362)+(Submetering!O8+Submetering!P8+Submetering!Q8)*0.1488+(Submetering!M8+Submetering!N8+Submetering!Y8)*0.1167+(Submetering!K8+Submetering!L8-Submetering!Z8-Submetering!AA8-Submetering!AB8-Submetering!AC8-Submetering!Q8)+(Submetering!M8+Submetering!N8+Submetering!Y8)*0.1139) -> 79724.61 | F8: 1.15 | G8: =Gas!C10*0.9147 -> 3544.4625 | H8: 2.25 | I8: =Submetering!AE8+Submetering!AD8+Submetering!H8 -> 896 | J8: 9.12 | K8: =ELECT.!B10 -> 357
A9: Cairo at Nile Plaza | B9: =B8+1 -> 8 | C9: 3 | D9: 2019 | E9: =(((Submetering!O9+Submetering!P9)*0.842284+Submetering!Q9+(Submetering!M9+Submetering!N9+Submetering!Y9)*0.7362)+(Submetering!O9+Submetering!P9+Submetering!Q9)*0.1488+(Submetering!M9+Submetering!N9+Submetering!Y9)*0.1167+(Submetering!K9+Submetering!L9-Submetering!Z9-Submetering!AA9-Submetering!AB9-Submetering!AC9-Submetering!Q9)+(Submetering!M9+Submetering!N9+Submetering!Y9)*0.1139) -> 54420.135 | F9: 1.15 | G9: =Gas!C11*0.9147 -> 3564.5859 | H9: 2.25 | I9: =Submetering!AE9+Submetering!AD9+Submetering!H9 -> 706 | J9: 9.12 | K9: =ELECT.!B11 -> 361
A10: Cairo at Nile Plaza | B10: =B9+1 -> 9 | C10: 3 | D10: 2019 | E10: =(((Submetering!O10+Submetering!P10)*0.842284+Submetering!Q10+(Submetering!M10+Submetering!N10+Submetering!Y10)*0.7362)+(Submetering!O10+Submetering!P10+Submetering!Q10)*0.1488+(Submetering!M10+Submetering!N10+Submetering!Y10)*0.1167+(Submetering!K10+Submetering!L10-Submetering!Z10-Submetering!AA10-Submetering!AB10-Submetering!AC10-Submetering!Q10)+(Submetering!M10+Submetering!N10+Submetering!Y10)*0.1139) -> 53536.984 | F10: 1.15 | G10: =Gas!C12*0.9147 -> 3530.742 | H10: 2.25 | I10: =Submetering!AE10+Submetering!AD10+Submetering!H10 -> 636 | J10: 9.12 | K10: =ELECT.!B12 -> 293
A11: Cairo at Nile Plaza | B11: =B10+1 -> 10 | C11: 3 | D11: 2019 | E11: =(((Submetering!O11+Submetering!P11)*0.842284+Submetering!Q11+(Submetering!M11+Submetering!N11+Submetering!Y11)*0.7362)+(Submetering!O11+Submetering!P11+Submetering!Q11)*0.1488+(Submetering!M11+Submetering!N11+Submetering!Y11)*0.1167+(Submetering!K11+Submetering!L11-Submetering!Z11-Submetering!AA11-Submetering!AB11-Submetering!AC11-Submetering!Q11)+(Submetering!M11+Submetering!N11+Submetering!Y11)*0.1139) -> 66899.421 | F11: 1.15 | G11: =Gas!C13*0.9147 -> 3162.1179 | H11: 2.25 | I11: =Submetering!AE11+Submetering!AD11+Submetering!H11 -> 636 | J11: 9.12 | K11: =ELECT.!B13 -> 302
A12: Cairo at Nile Plaza | B12: =B11+1 -> 11 | C12: 3 | D12: 2019 | E12: =(((Submetering!O12+Submetering!P12)*0.842284+Submetering!Q12+(Submetering!M12+Submetering!N12+Submetering!Y12)*0.7362)+(Submetering!O12+Submetering!P12+Submetering!Q12)*0.1488+(Submetering!M12+Submetering!N12+Submetering!Y12)*0.1167+(Submetering!K12+Submetering!L12-Submetering!Z12-Submetering!AA12-Submetering!AB12-Submetering!AC12-Submetering!Q12)+(Submetering!M12+Submetering!N12+Submetering!Y12)*0.1139) -> 29761.389 | F12: 1.15 | G12: =Gas!C14*0.9147 -> 3131.9328 | H12: 2.25 | I12: =Submetering!AE12+Submetering!AD12+Submetering!H12 -> 856 | J12: 9.12 | K12: =ELECT.!B14 -> 353
A13: Cairo at Nile Plaza | B13: =B12+1 -> 12 | C13: 3 | D13: 2019 | E13: =(((Submetering!O13+Submetering!P13)*0.842284+Submetering!Q13+(Submetering!M13+Submetering!N13+Submetering!Y13)*0.7362)+(Submetering!O13+Submetering!P13+Submetering!Q13)*0.1488+(Submetering!M13+Submetering!N13+Submetering!Y13)*0.1167+(Submetering!K13+Submetering!L13-Submetering!Z13-Submetering!AA13-Submetering!AB13-Submetering!AC13-Submetering!Q13)+(Submetering!M13+Submetering!N13+Submetering!Y13)*0.1139) -> 65967.795 | F13: 1.15 | G13: =Gas!C15*0.9147 -> 2991.069 | H13: 2.25 | I13: =Submetering!AE13+Submetering!AD13+Submetering!H13 -> 966 | J13: 9.12 | K13: =ELECT.!B15 -> 320
A14: Cairo at Nile Plaza | B14: =B13+1 -> 13 | C14: 3 | D14: 2019 | E14: =(((Submetering!O14+Submetering!P14)*0.842284+Submetering!Q14+(Submetering!M14+Submetering!N14+Submetering!Y14)*0.7362)+(Submetering!O14+Submetering!P14+Submetering!Q14)*0.1488+(Submetering!M14+Submetering!N14+Submetering!Y14)*0.1167+(Submetering!K14+Submetering!L14-Submetering!Z14-Submetering!AA14-Submetering!AB14-Submetering!AC14-Submetering!Q14)+(Submetering!M14+Submetering!N14+Submetering!Y14)*0.1139) -> 58239.272 | F14: 1.15 | G14: =Gas!C16*0.9147 -> 4471.0536 | H14: 2.25 | I14: =Submetering!AE14+Submetering!AD14+Submetering!H14 -> 1136 | J14: 9.12 | K14: =ELECT.!B16 -> 330.19231
... A32: Cairo at Nile Plaza | B32: =B31+1 -> 31 | C32: 3 | D32: 2019 | E32: =(((Submetering!O32+Submetering!P32)*0.842284+Submetering!Q32+(Submetering!M32+Submetering!N32+Submetering!Y32)*0.7362)+(Submetering!O32+Submetering!P32+Submetering!Q32)*0.1488+(Submetering!M32+Submetering!N32+Submetering!Y32)*0.1167+(Submetering!K32+Submetering!L32-Submetering!Z32-Submetering!AA32-Submetering!AB32-Submetering!AC32-Submetering!Q32)+(Submetering!M32+Submetering!N32+Submetering!Y32)*0.1139) -> 54831.823 | F32: 1.15 | G32: =Gas!C34*0.9147 -> 2977.3485 | H32: 2.25 | I32: =Submetering!AE32+Submetering!AD32+Submetering!H32 -> 806 | J32: 9.12 | K32: =ELECT.!B34 -> 350

Sheet Submetering
A1: Site Name | B1: Day | C1: Month | D1: Year | E1: Main (m3) | F1: Podium (m3) | G1: Hotel (m3) | H1: Large (m3) | I1: Feeder 1 (KWh) | J1: Feeder 2 (KWh) | K1: T1 (KWh) | L1: T2 (KWh) | M1: T3 (KWh) | N1: T4 (KWh) | O1: T5 (KWh) | P1: T7 (KWh) | Q1: New Chiller (KWh) | R1: Hotel (BTU) | S1: B.S (BTU) | T1: LS (BTU) | U1: Mall (BTU) | V1: AHU#25 (BTU) | W1: AHU#9 (BTU) | X1: Room Nights | Y1: Loss (KWH) | Z1: Mall (KWH) | AA1: Citadel (KWH) | AB1: Rotana (KWH) | AC1: CIB (KWH) | AD1: Plaza suits water consumption (M3) | AE1: Hotel water consumption (M3)
A2: Cairo at Nile Plaza | B2: 1 | C2: 3 | D2: 2019 | E2: =Water!C4 -> 1110 | F2: =Water!E4 -> 507.6 | G2: =Water!G4 -> 418.5 | H2: =Water!I4 -> 1.917 | I2: =ELECT.!F4 -> 17654 | J2: =ELECT.!H4 -> 76332 | K2: =ELECT.!K4 -> 7385 | L2: =ELECT.!M4 -> 7695 | M2: =ELECT.!O4 -> 9696 | N2: =ELECT.!Q4 -> 4428 | O2: =ELECT.!S4 -> 19748 | P2: =ELECT.!W4*2 -> 43098 | Q2: =ELECT.!D4 -> 1120 | R2: =BTU!C3 -> 3.899 | S2: =BTU!F3 -> 0.442 | T2: =BTU!I3 -> 0 | U2: =BTU!O3 -> 1.023 | V2: =BTU!L3 -> 0 | W2: =BTU!R3 -> 0.37 | X2: =ELECT.!B4 -> 334 | Y2: =I2+J2-(K2+L2+M2+N2+O2+P2) -> 1936 | Z2: ='Mall, Citadel, Rotana'!C4+'Mall, Citadel, Rotana'!E4+'Mall, Citadel, Rotana'!G4+'Mall, Citadel, Rotana'!I4 -> 724 | AA2: ='Mall, Citadel, Rotana'!K4+'Mall, Citadel, Rotana'!M4 -> 640 | AB2: ='Mall, Citadel, Rotana'!O4 -> 2 | AC2: ='Mall, Citadel, Rotana'!Q4+'Mall, Citadel, Rotana'!S4 -> 70 | AD2: =(E2-H2-194)*0.1318 -> 120.47614 | AE2: =E2-H2-AD2-194 -> 793.60686
A3: Cairo at Nile Plaza | B3: =B2+1 -> 2 | C3: 3 | D3: 2019 | E3: =Water!C5 -> 980 | F3: =Water!E5 -> 483.3 | G3: =Water!G5 -> 394.2 | H3: =Water!I5 -> 3.483 | I3: =ELECT.!F5 -> 8546 | J3: =ELECT.!H5 -> 35408 | K3: =ELECT.!K5 -> 3525 | L3: =ELECT.!M5 -> 3773 | M3: =ELECT.!O5 -> 4672 | N3: =ELECT.!Q5 -> 2084 | O3: =ELECT.!S5 -> 9179 | P3: =ELECT.!W5*2 -> 19958 | Q3: =ELECT.!D5 -> 480 | R3: =BTU!C4 -> 4.215 | S3: =BTU!F4 -> 0.641 | T3: =BTU!I4 -> 0 | U3: =BTU!O4 -> 0.999 | V3: =BTU!L4 -> 0 | W3: =BTU!R4 -> 0.83 | X3: =ELECT.!B5 -> 323 | Y3: =I3+J3-(K3+L3+M3+N3+O3+P3) -> 763 | Z3: ='Mall, Citadel, Rotana'!C5+'Mall, Citadel, Rotana'!E5+'Mall, Citadel, Rotana'!G5+'Mall, Citadel, Rotana'!I5 -> 605 | AA3: ='Mall, Citadel, Rotana'!K5+'Mall, Citadel, Rotana'!M5 -> 320 | AB3: ='Mall, Citadel, Rotana'!O5 -> 2 | AC3: ='Mall, Citadel, Rotana'!Q5+'Mall, Citadel, Rotana'!S5 -> 19 | AD3: =(E3-H3-194)*0.1318 -> 103.13574 | AE3: =E3-H3-AD3-194 -> 679.38126
A4: Cairo at Nile Plaza | B4: =B3+1 -> 3 | C4: 3 | D4: 2019 | E4: =Water!C6 -> 1090 | F4: =Water!E6 -> 510.3 | G4: =Water!G6 -> 364.5 | H4: =Water!I6 -> 3.267 | I4: =ELECT.!F6 -> 12190 | J4: =ELECT.!H6 -> 51903 | K4: =ELECT.!K6 -> 5191 | L4: =ELECT.!M6 -> 5153 | M4: =ELECT.!O6 -> 6840 | N4: =ELECT.!Q6 -> 3120 | O4: =ELECT.!S6 -> 13104 | P4: =ELECT.!W6*2 -> 29258 | Q4: =ELECT.!D6 -> 640 | R4: =BTU!C5 -> 4.547 | S4: =BTU!F5 -> 0.871 | T4: =BTU!I5 -> 0 | U4: =BTU!O5 -> 0.577 | V4: =BTU!L5 -> 0 | W4: =BTU!R5 -> 0.04 | X4: =ELECT.!B6 -> 275 | Y4: =I4+J4-(K4+L4+M4+N4+O4+P4) -> 1427 | Z4: ='Mall, Citadel, Rotana'!C6+'Mall, Citadel, Rotana'!E6+'Mall, Citadel, Rotana'!G6+'Mall, Citadel, Rotana'!I6 -> 2475 | AA4: ='Mall, Citadel, Rotana'!K6+'Mall, Citadel, Rotana'!M6 -> 960 | AB4: ='Mall, Citadel, Rotana'!O6 -> 3 | AC4: ='Mall, Citadel, Rotana'!Q6+'Mall, Citadel, Rotana'!S6 -> 353 | AD4: =(E4-H4-194)*0.1318 -> 117.66221 | AE4: =E4-H4-AD4-194 -> 775.07079
A5: Cairo at Nile Plaza | B5: =B4+1 -> 4 | C5: 3 | D5: 2019 | E5: =Water!C7 -> 870 | F5: =Water!E7 -> 283.5 | G5: =Water!G7 -> 332.1 | H5: =Water!I7 -> 3.996 | I5: =ELECT.!F7 -> 10066 | J5: =ELECT.!H7 -> 40529 | K5: =ELECT.!K7 -> 4012 | L5: =ELECT.!M7 -> 4436 | M5: =ELECT.!O7 -> 5524 | N5: =ELECT.!Q7 -> 2330 | O5: =ELECT.!S7 -> 10053 | P5: =ELECT.!W7*2 -> 23330 | Q5: =ELECT.!D7 -> 640 | R5: =BTU!C6 -> 5.144 | S5: =BTU!F6 -> 1.076 | T5: =BTU!I6 -> 0 | U5: =BTU!O6 -> 0.61 | V5: =BTU!L6 -> 0 | W5: =BTU!R6 -> 0.19 | X5: =ELECT.!B7 -> 300 | Y5: =I5+J5-(K5+L5+M5+N5+O5+P5) -> 910 | Z5: ='Mall, Citadel, Rotana'!C7+'Mall, Citadel, Rotana'!E7+'Mall, Citadel, Rotana'!G7+'Mall, Citadel, Rotana'!I7 -> 1173 | AA5: ='Mall, Citadel, Rotana'!K7+'Mall, Citadel, Rotana'!M7 -> 960 | AB5: ='Mall, Citadel, Rotana'!O7 -> 3 | AC5: ='Mall, Citadel, Rotana'!Q7+'Mall, Citadel, Rotana'!S7 -> 158 | AD5: =(E5-H5-194)*0.1318 -> 88.570127 | AE5: =E5-H5-AD5-194 -> 583.43387
A6: Cairo at Nile Plaza | B6: =B5+1 -> 5 | C6: 3 | D6: 2019 | E6: =Water!C8 -> 990 | F6: =Water!E8 -> 680.4 | G6: =Water!G8 -> 310.5 | H6: =Water!I8 -> 2.673 | I6: =ELECT.!F8 -> 9052 | J6: =ELECT.!H8 -> 43731 | K6: =ELECT.!K8 -> 4350 | L6: =ELECT.!M8 -> 4570 | M6: =ELECT.!O8 -> 4332 | N6: =ELECT.!Q8 -> 4338 | O6: =ELECT.!S8 -> 10390 | P6: =ELECT.!W8*2 -> 23874 | Q6: =ELECT.!D8 -> 640 | R6: =BTU!C7 -> 4.804 | S6: =BTU!F7 -> 0.89 | T6: =BTU!I7 -> 0.009 | U6: =BTU!O7 -> 0.7718 | V6: =BTU!L7 -> 0 | W6: =BTU!R7 -> 0 | X6: =ELECT.!B8 -> 375 | Y6: =I6+J6-(K6+L6+M6+N6+O6+P6) -> 929 | Z6: ='Mall, Citadel, Rotana'!C8+'Mall, Citadel, Rotana'!E8+'Mall, Citadel, Rotana'!G8+'Mall, Citadel, Rotana'!I8 -> 1152 | AA6: ='Mall, Citadel, Rotana'!K8+'Mall, Citadel, Rotana'!M8 -> 640 | AB6: ='Mall, Citadel, Rotana'!O8 -> 3 | AC6: ='Mall, Citadel, Rotana'!Q8+'Mall, Citadel, Rotana'!S8 -> 203 | AD6: =(E6-H6-194)*0.1318 -> 104.5605 | AE6: =E6-H6-AD6-194 -> 688.7665
A7: Cairo at Nile Plaza | B7: =B6+1 -> 6 | C7: 3 | D7: 2019 | E7: =Water!C9 -> 1020 | F7: =Water!E9 -> 558.9 | G7: =Water!G9 -> 340.2 | H7: =Water!I9 -> 4.05 | I7: =ELECT.!F9 -> 4879 | J7: =ELECT.!H9 -> 36044 | K7: =ELECT.!K9 -> 3289 | L7: =ELECT.!M9 -> 3387 | M7: =ELECT.!O9 -> 1392 | N7: =ELECT.!Q9 -> 5814 | O7: =ELECT.!S9 -> 8066 | P7: =ELECT.!W9*2 -> 18342 | Q7: =ELECT.!D9 -> 800 | R7: =BTU!C8 -> 4.081 | S7: =BTU!F8 -> 0.885 | T7: =BTU!I8 -> 0 | U7: =BTU!O8 -> 0.9352 | V7: =BTU!L8 -> 0 | W7: =BTU!R8 -> 0 | X7: =ELECT.!B9 -> 323 | Y7: =I7+J7-(K7+L7+M7+N7+O7+P7) -> 633 | Z7: ='Mall, Citadel, Rotana'!C9+'Mall, Citadel, Rotana'!E9+'Mall, Citadel, Rotana'!G9+'Mall, Citadel, Rotana'!I9 -> 1197 | AA7: ='Mall, Citadel, Rotana'!K9+'Mall, Citadel, Rotana'!M9 -> 480 | AB7: ='Mall, Citadel, Rotana'!O9 -> 3 | AC7: ='Mall, Citadel, Rotana'!Q9+'Mall, Citadel, Rotana'!S9 -> 196 | AD7: =(E7-H7-194)*0.1318 -> 108.33301 | AE7: =E7-H7-AD7-194 -> 713.61699
A8: Cairo at Nile Plaza | B8: =B7+1 -> 7 | C8: 3 | D8: 2019 | E8: =Water!C10 -> 1090 | F8: =Water!E10 -> 380.7 | G8: =Water!G10 -> 251.1 | H8: =Water!I10 -> 2.781 | I8: =ELECT.!F10 -> 15662 | J8: =ELECT.!H10 -> 66776 | K8: =ELECT.!K10 -> 6365 | L8: =ELECT.!M10 -> 8701 | M8: =ELECT.!O10 -> 6718 | N8: =ELECT.!Q10 -> 8084 | O8: =ELECT.!S10 -> 15595 | P8: =ELECT.!W10*2 -> 35506 | Q8: =ELECT.!D10 -> 480 | R8: =BTU!C9 -> 1.941 | S8: =BTU!F9 -> 0.779 | T8: =BTU!I9 -> 0.001 | U8: =BTU!O9 -> 0.969 | V8: =BTU!L9 -> 0 | W8: =BTU!R9 -> 0 | X8: =ELECT.!B10 -> 357 | Y8: =I8+J8-(K8+L8+M8+N8+O8+P8) -> 1469 | Z8: ='Mall, Citadel, Rotana'!C10+'Mall, Citadel, Rotana'!E10+'Mall, Citadel, Rotana'!G10+'Mall, Citadel, Rotana'!I10 -> 773 | AA8: ='Mall, Citadel, Rotana'!K10+'Mall, Citadel, Rotana'!M10 -> 800 | AB8: ='Mall, Citadel, Rotana'!O10 -> 3 | AC8: ='Mall, Citadel, Rotana'!Q10+'Mall, Citadel, Rotana'!S10 -> 213 | AD8: =(E8-H8-194)*0.1318 -> 117.72626 | AE8: =E8-H8-AD8-194 -> 775.49274
A9: Cairo at Nile Plaza | B9: =B8+1 -> 8 | C9: 3 | D9: 2019 | E9: =Water!C11 -> 900 | F9: =Water!E11 -> 761.4 | G9: =Water!G11 -> 499.5 | H9: =Water!I11 -> 4.455 | I9: =ELECT.!F11 -> 14850 | J9: =ELECT.!H11 -> 42460 | K9: =ELECT.!K11 -> 3119 | L9: =ELECT.!M11 -> 6033 | M9: =ELECT.!O11 -> 8652 | N9: =ELECT.!Q11 -> 2542 | O9: =ELECT.!S11 -> 11047 | P9: =ELECT.!W11*2 -> 24208 | Q9: =ELECT.!D11 -> 960 | R9: =BTU!C10 -> 6.519 | S9: =BTU!F10 -> 0.494 | T9: =BTU!I10 -> 0.005 | U9: =BTU!O10 -> 1.146 | V9: =BTU!L10 -> 0 | W9: =BTU!R10 -> 0.38 | X9: =ELECT.!B11 -> 361 | Y9: =I9+J9-(K9+L9+M9+N9+O9+P9) -> 1709 | Z9: ='Mall, Citadel, Rotana'!C11+'Mall, Citadel, Rotana'!E11+'Mall, Citadel, Rotana'!G11+'Mall, Citadel, Rotana'!I11 -> 1717 | AA9: ='Mall, Citadel, Rotana'!K11+'Mall, Citadel, Rotana'!M11 -> 480 | AB9: ='Mall, Citadel, Rotana'!O11 -> 3 | AC9: ='Mall, Citadel, Rotana'!Q11+'Mall, Citadel, Rotana'!S11 -> 90 | AD9: =(E9-H9-194)*0.1318 -> 92.463631 | AE9: =E9-H9-AD9-194 -> 609.08137
A10: Cairo at Nile Plaza | B10: =B9+1 -> 9 | C10: 3 | D10: 2019 | E10: =Water!C12 -> 830 | F10: =Water!E12 -> 378 | G10: =Water!G12 -> 283.5 | H10: =Water!I12 -> 3.807 | I10: =ELECT.!F12 -> 14810 | J10: =ELECT.!H12 -> 40800 | K10: =ELECT.!K12 -> 5035 | L10: =ELECT.!M12 -> 6229 | M10: =ELECT.!O12 -> 8446 | N10: =ELECT.!Q12 -> 2494 | O10: =ELECT.!S12 -> 10353 | P10: =ELECT.!W12*2 -> 22996 | Q10: =ELECT.!D12 -> 480 | R10: =BTU!C11 -> 4.957 | S10: =BTU!F11 -> 0.482 | T10: =BTU!I11 -> 0.054 | U10: =BTU!O11 -> 1.358 | V10: =BTU!L11 -> 0.72 | W10: =BTU!R11 -> 0.55 | X10: =ELECT.!B12 -> 293 | Y10: =I10+J10-(K10+L10+M10+N10+O10+P10) -> 57 | Z10: ='Mall, Citadel, Rotana'!C12+'Mall, Citadel, Rotana'!E12+'Mall, Citadel, Rotana'!G12+'Mall, Citadel, Rotana'!I12 -> 1067 | AA10: ='Mall, Citadel, Rotana'!K12+'Mall, Citadel, Rotana'!M12 -> 320 | AB10: ='Mall, Citadel, Rotana'!O12 -> 3 | AC10: ='Mall, Citadel, Rotana'!Q12+'Mall, Citadel, Rotana'!S12 -> 92 | AD10: =(E10-H10-194)*0.1318 -> 83.323037 | AE10: =E10-H10-AD10-194 -> 548.86996
A11: Cairo at Nile Plaza | B11: =B10+1 -> 10 | C11: 3 | D11: 2019 | E11: =Water!C13 -> 830 | F11: =Water!E13 -> 561.6 | G11: =Water!G13 -> 326.7 | H11: =Water!I13 -> 4.86 | I11: =ELECT.!F13 -> 17227 | J11: =ELECT.!H13 -> 52594 | K11: =ELECT.!K13 -> 5569 | L11: =ELECT.!M13 -> 7224 | M11: =ELECT.!O13 -> 9772 | N11: =ELECT.!Q13 -> 3262 | O11: =ELECT.!S13 -> 12872 | P11: =ELECT.!W13*2 -> 29770 | Q11: =ELECT.!D13 -> 640 | R11: =BTU!C12 -> 4.923 | S11: =BTU!F12 -> 1.218 | T11: =BTU!I12 -> 0.114 | U11: =BTU!O12 -> 1.198 | V11: =BTU!L12 -> 1.06 | W11: =BTU!R12 -> 0 | X11: =ELECT.!B13 -> 302 | Y11: =I11+J11-(K11+L11+M11+N11+O11+P11) -> 1352 | Z11: ='Mall, Citadel, Rotana'!C13+'Mall, Citadel, Rotana'!E13+'Mall, Citadel, Rotana'!G13+'Mall, Citadel, Rotana'!I13 -> 1186 | AA11: ='Mall, Citadel, Rotana'!K13+'Mall, Citadel, Rotana'!M13 -> 800 | AB11: ='Mall, Citadel, Rotana'!O13 -> 2 | AC11: ='Mall, Citadel, Rotana'!Q13+'Mall, Citadel, Rotana'!S13 -> 171 | AD11: =(E11-H11-194)*0.1318 -> 83.184252 | AE11: =E11-H11-AD11-194 -> 547.95575
A12: Cairo at Nile Plaza | B12: =B11+1 -> 11 | C12: 3 | D12: 2019 | E12: =Water!C14 -> 1050 | F12: =Water!E14 -> 540 | G12: =Water!G14 -> 356.4 | H12: =Water!I14 -> 4.023 | I12: =ELECT.!F14 -> 6996 | J12: =ELECT.!H14 -> 25238 | K12: =ELECT.!K14 -> 2509 | L12: =ELECT.!M14 -> 3728 | M12: =ELECT.!O14 -> 3216 | N12: =ELECT.!Q14 -> 2764 | O12: =ELECT.!S14 -> 5768 | P12: =ELECT.!W14*2 -> 13844 | Q12: =ELECT.!D14 -> 640 | R12: =BTU!C13 -> 4.732 | S12: =BTU!F13 -> 1.247 | T12: =BTU!I13 -> 0.056 | U12: =BTU!O13 -> 1.192 | V12: =BTU!L13 -> 0.59 | W12: =BTU!R13 -> 0 | X12: =ELECT.!B14 -> 353 | Y12: =I12+J12-(K12+L12+M12+N12+O12+P12) -> 405 | Z12: ='Mall, Citadel, Rotana'!C14+'Mall, Citadel, Rotana'!E14+'Mall, Citadel, Rotana'!G14+'Mall, Citadel, Rotana'!I14 -> 1186 | AA12: ='Mall, Citadel, Rotana'!K14+'Mall, Citadel, Rotana'!M14 -> 800 | AB12: ='Mall, Citadel, Rotana'!O14 -> 2 | AC12: ='Mall, Citadel, Rotana'!Q14+'Mall, Citadel, Rotana'!S14 -> 193 | AD12: =(E12-H12-194)*0.1318 -> 112.29057 | AE12: =E12-H12-AD12-194 -> 739.68643
A13: Cairo at Nile Plaza | B13: =B12+1 -> 12 | C13: 3 | D13: 2019 | E13: =Water!C15 -> 1160 | F13: =Water!E15 -> 591.3 | G13: =Water!G15 -> 434.7 | H13: =Water!I15 -> 3.429 | I13: =ELECT.!F15 -> 14676 | J13: =ELECT.!H15 -> 54255 | K13: =ELECT.!K15 -> 5870 | L13: =ELECT.!M15 -> 6044 | M13: =ELECT.!O15 -> 8456 | N13: =ELECT.!Q15 -> 3028 | O13: =ELECT.!S15 -> 12727 | P13: =ELECT.!W15*2 -> 31694 | Q13: =ELECT.!D15 -> 800 | R13: =BTU!C14 -> 4.862 | S13: =BTU!F14 -> 1.166 | T13: =BTU!I14 -> 0.001 | U13: =BTU!O14 -> 1.17 | V13: =BTU!L14 -> 1.04 | W13: =BTU!R14 -> 0 | X13: =ELECT.!B15 -> 320 | Y13: =I13+J13-(K13+L13+M13+N13+O13+P13) -> 1112 | Z13: ='Mall, Citadel, Rotana'!C15+'Mall, Citadel, Rotana'!E15+'Mall, Citadel, Rotana'!G15+'Mall, Citadel, Rotana'!I15 -> 1420 | AA13: ='Mall, Citadel, Rotana'!K15+'Mall, Citadel, Rotana'!M15 -> 640 | AB13: ='Mall, Citadel, Rotana'!O15 -> 4 | AC13: ='Mall, Citadel, Rotana'!Q15+'Mall, Citadel, Rotana'!S15 -> 204 | AD13: =(E13-H13-194)*0.1318 -> 126.86686 | AE13: =E13-H13-AD13-194 -> 835.70414
A14: Cairo at Nile Plaza | B14: =B13+1 -> 13 | C14: 3 | D14: 2019 | E14: =Water!C16 -> 1330 | F14: =Water!E16 -> 556.2 | G14: =Water!G16 -> 396.9 | H14: =Water!I16 -> 3.375 | I14: =ELECT.!F16 -> 15365 | J14: =ELECT.!H16 -> 45373 | K14: =ELECT.!K16 -> 4879 | L14: =ELECT.!M16 -> 6258 | M14: =ELECT.!O16 -> 8706 | N14: =ELECT.!Q16 -> 2663 | O14: =ELECT.!S16 -> 11216 | P14: =ELECT.!W16*2 -> 25886 | Q14: =ELECT.!D16 -> 800 | R14: =BTU!C15 -> 4.799 | S14: =BTU!F15 -> 0.985 | T14: =BTU!I15 -> 0 | U14: =BTU!O15 -> 1.403 | V14: =BTU!L15 -> 0.58 | W14: =BTU!R15 -> 0 | X14: =ELECT.!B16 -> 330.19231 | Y14: =I14+J14-(K14+L14+M14+N14+O14+P14) -> 1130 | Z14: ='Mall, Citadel, Rotana'!C16+'Mall, Citadel, Rotana'!E16+'Mall, Citadel, Rotana'!G16+'Mall, Citadel, Rotana'!I16 -> 1194 | AA14: ='Mall, Citadel, Rotana'!K16+'Mall, Citadel, Rotana'!M16 -> 480 | AB14: ='Mall, Citadel, Rotana'!O16 -> 4 | AC14: ='Mall, Citadel, Rotana'!Q16+'Mall, Citadel, Rotana'!S16 -> 194 | AD14: =(E14-H14-194)*0.1318 -> 149.27998 | AE14: =E14-H14-AD14-194 -> 983.34503
... A32: Cairo at Nile Plaza | B32: =B31+1 -> 31 | C32: 3 | D32: 2019 | E32: =Water!C34 -> 1000 | F32: =Water!E34 -> 556.2 | G32: =Water!G34 -> 402.3 | H32: =Water!I34 -> 3.807 | I32: =ELECT.!F34 -> 6125 | J32: =ELECT.!H34 -> 51160 | K32: =ELECT.!K34 -> 4814 | L32: =ELECT.!M34 -> 4324 | M32: =ELECT.!O34 -> 1654 | N32: =ELECT.!Q34 -> 9179 | O32: =ELECT.!S34 -> 11144 | P32: =ELECT.!W34*2 -> 24826 | Q32: =ELECT.!D34 -> 160 | R32: =BTU!C33 -> 0 | S32: =BTU!F33 -> 0 | T32: =BTU!I33 -> 0 | U32: =BTU!O33 -> 0 | V32: =BTU!L33 -> 0 | W32: =BTU!R33 -> 0 | X32: =ELECT.!B34 -> 350 | Y32: =I32+J32-(K32+L32+M32+N32+O32+P32) -> 1344 | Z32: ='Mall, Citadel, Rotana'!C34+'Mall, Citadel, Rotana'!E34+'Mall, Citadel, Rotana'!G34+'Mall, Citadel, Rotana'!I34 -> 1083 | AA32: ='Mall, Citadel, Rotana'!K34+'Mall, Citadel, Rotana'!M34 -> 480 | AB32: ='Mall, Citadel, Rotana'!O34 -> 1 | AC32: ='Mall, Citadel, Rotana'!Q34+'Mall, Citadel, Rotana'!S34 -> 188 | AD32: =(E32-H32-194)*0.1318 -> 105.72904 | AE32: =E32-H32-AD32-194 -> 696.46396

Sheet Mall, Citadel, Rotana
A1: Mall, Citadel and Rotana readings and cons. Mar 2019
A2: Day | B2: R1 | C2: Cons | D2: R2 | E2: Cons | F2: R3 | G2: Cons | H2: R4 | I2: Cons | J2: RO1 | K2: Cons | L2: RO2 | M2: Cons | N2: ROE | O2: Cons | P2: CIB. 1 | Q2: Cons | R2: CIB. E | S2: Cons
A3: Last | B3: 41524 | D3: 37249 | F3: 17407 | H3: 213908 | J3: 303515 | L3: 21909 | N3: 167967 | P3: 972518 | R3: 55047
A4: 43525 | B4: 41527 | C4: =(B4-B3)*600/5 -> 360 | D4: 37251 | E4: =(D4-D3)*800/5 -> 320 | F4: 17409 | G4: =(F4-F3)*100/5 -> 40 | H4: 213912 | I4: =H4-H3 -> 4 | J4: 303515 | K4: =J4-J3 -> 0 | L4: 21913 | M4: =(L4-L3)*800/5 -> 640 | N4: 167969 | O4: =N4-N3 -> 2 | P4: 972588 | Q4: =P4-P3 -> 70 | R4: 55047 | S4: =R4-R3 -> 0
A5: 43526 | B5: 41529 | C5: =(B5-B4)*600/5 -> 240 | D5: 37253 | E5: =(D5-D4)*800/5 -> 320 | F5: 17411 | G5: =(F5-F4)*100/5 -> 40 | H5: 213917 | I5: =H5-H4 -> 5 | J5: 303515 | K5: =J5-J4 -> 0 | L5: 21915 | M5: =(L5-L4)*800/5 -> 320 | N5: 167971 | O5: =N5-N4 -> 2 | P5: 972607 | Q5: =P5-P4 -> 19 | R5: 55047 | S5: =R5-R4 -> 0
A6: 43527 | B6: 41542 | C6: =(B6-B5)*600/5 -> 1560 | D6: 37257 | E6: =(D6-D5)*800/5 -> 640 | F6: 17422 | G6: =(F6-F5)*100/5 -> 220 | H6: 213972 | I6: =H6-H5 -> 55 | J6: 303515 | K6: =J6-J5 -> 0 | L6: 21921 | M6: =(L6-L5)*800/5 -> 960 | N6: 167974 | O6: =N6-N5 -> 3 | P6: 972960 | Q6: =P6-P5 -> 353 | R6: 55047 | S6: =R6-R5 -> 0
A7: 43528 | B7: 41547 | C7: =(B7-B6)*600/5 -> 600 | D7: 37260 | E7: =(D7-D6)*800/5 -> 480 | F7: 17426 | G7: =(F7-F6)*100/5 -> 80 | H7: 213985 | I7: =H7-H6 -> 13 | J7: 303515 | K7: =J7-J6 -> 0 | L7: 21927 | M7: =(L7-L6)*800/5 -> 960 | N7: 167977 | O7: =N7-N6 -> 3 | P7: 973118 | Q7: =P7-P6 -> 158 | R7: 55047 | S7: =R7-R6 -> 0
A8: 43529 | B8: 41552 | C8: =(B8-B7)*600/5 -> 600 | D8: 37263 | E8: =(D8-D7)*800/5 -> 480 | F8: 17429 | G8: =(F8-F7)*100/5 -> 60 | H8: 213997 | I8: =H8-H7 -> 12 | J8: 303515 | K8: =J8-J7 -> 0 | L8: 21931 | M8: =(L8-L7)*800/5 -> 640 | N8: 167980 | O8: =N8-N7 -> 3 | P8: 973321 | Q8: =P8-P7 -> 203 | R8: 55047 | S8: =R8-R7 -> 0
A9: 43530 | B9: 41557 | C9: =(B9-B8)*600/5 -> 600 | D9: 37266 | E9: =(D9-D8)*800/5 -> 480 | F9: 17434 | G9: =(F9-F8)*100/5 -> 100 | H9: 214014 | I9: =H9-H8 -> 17 | J9: 303515 | K9: =J9-J8 -> 0 | L9: 21934 | M9: =(L9-L8)*800/5 -> 480 | N9: 167983 | O9: =N9-N8 -> 3 | P9: 973517 | Q9: =P9-P8 -> 196 | R9: 55047 | S9: =R9-R8 -> 0
A10: 43531 | B10: 41560 | C10: =(B10-B9)*600/5 -> 360 | D10: 37268 | E10: =(D10-D9)*800/5 -> 320 | F10: 17438 | G10: =(F10-F9)*100/5 -> 80 | H10: 214027 | I10: =H10-H9 -> 13 | J10: 303515 | K10: =J10-J9 -> 0 | L10: 21939 | M10: =(L10-L9)*800/5 -> 800 | N10: 167986 | O10: =N10-N9 -> 3 | P10: 973730 | Q10: =P10-P9 -> 213 | R10: 55047 | S10: =R10-R9 -> 0
A11: 43532 | B11: 41567 | C11: =(B11-B10)*600/5 -> 840 | D11: 37273 | E11: =(D11-D10)*800/5 -> 800 | F11: 17441 | G11: =(F11-F10)*100/5 -> 60 | H11: 214044 | I11: =H11-H10 -> 17 | J11: 303515 | K11: =J11-J10 -> 0 | L11: 21942 | M11: =(L11-L10)*800/5 -> 480 | N11: 167989 | O11: =N11-N10 -> 3 | P11: 973820 | Q11: =P11-P10 -> 90 | R11: 55047 | S11: =R11-R10 -> 0
A12: 43533 | B12: 41571 | C12: =(B12-B11)*600/5 -> 480 | D12: 37276 | E12: =(D12-D11)*800/5 -> 480 | F12: 17446 | G12: =(F12-F11)*100/5 -> 100 | H12: 214051 | I12: =H12-H11 -> 7 | J12: 303515 | K12: =J12-J11 -> 0 | L12: 21944 | M12: =(L12-L11)*800/5 -> 320 | N12: 167992 | O12: =N12-N11 -> 3 | P12: 973912 | Q12: =P12-P11 -> 92 | R12: 55047 | S12: =R12-R11 -> 0
A13: 43534 | B13: 41576 | C13: =(B13-B12)*600/5 -> 600 | D13: 37279 | E13: =(D13-D12)*800/5 -> 480 | F13: 17451 | G13: =(F13-F12)*100/5 -> 100 | H13: 214057 | I13: =H13-H12 -> 6 | J13: 303515 | K13: =J13-J12 -> 0 | L13: 21949 | M13: =(L13-L12)*800/5 -> 800 | N13: 167994 | O13: =N13-N12 -> 2 | P13: 974083 | Q13: =P13-P12 -> 171 | R13: 55047 | S13: =R13-R12 -> 0
A14: 43535 | B14: 41581 | C14: =(B14-B13)*600/5 -> 600 | D14: 37282 | E14: =(D14-D13)*800/5 -> 480 | F14: 17456 | G14: =(F14-F13)*100/5 -> 100 | H14: 214063 | I14: =H14-H13 -> 6 | J14: 303515 | K14: =J14-J13 -> 0 | L14: 21954 | M14: =(L14-L13)*800/5 -> 800 | N14: 167996 | O14: =N14-N13 -> 2 | P14: 974276 | Q14: =P14-P13 -> 193 | R14: 55047 | S14: =R14-R13 -> 0
A15: 43536 | B15: 41587 | C15: =(B15-B14)*600/5 -> 720 | D15: 37286 | E15: =(D15-D14)*800/5 -> 640 | F15: 17458 | G15: =(F15-F14)*100/5 -> 40 | H15: 214083 | I15: =H15-H14 -> 20 | J15: 303515 | K15: =J15-J14 -> 0 | L15: 21958 | M15: =(L15-L14)*800/5 -> 640 | N15: 168000 | O15: =N15-N14 -> 4 | P15: 974480 | Q15: =P15-P14 -> 204 | R15: 55047 | S15: =R15-R14 -> 0
... A34: 43555 | B34: 41690 | C34: =(B34-B33)*600/5 -> 480 | D34: 37348 | E34: =(D34-D33)*800/5 -> 480 | F34: 17539 | G34: =(F34-F33)*100/5 -> 100 | H34: 214373 | I34: =H34-H33 -> 23 | J34: 303515 | K34: =J34-J33 -> 0 | L34: 22032 | M34: =(L34-L33)*800/5 -> 480 | N34: 168057 | O34: =N34-N33 -> 1 | P34: 977975 | Q34: =P34-P33 -> 188 | R34: 55047 | S34: =R34-R33 -> 0
A35: Total | C35: =SUM(C4:C34) -> 19920 | E35: =SUM(E4:E34) -> 15840 | G35: =SUM(G4:G34) -> 2640 | I35: =SUM(I4:I34) -> 465 | K35: =SUM(K4:K34) -> 0 | M35: =SUM(M4:M34) -> 19680 | Q35: =SUM(Q4:Q34) -> 5457 | S35: =SUM(S4:S34) -> 0

Sheet Water
A1: Main Building, Podium, Hotel and Large cons. Mar 2019
A2: Day | B2: Main Reading | C2: Cons. | D2: Podium | E2: Cons. | F2: Hotel | G2: Cons. | H2: Large | I2: Cons. | J2: Total | K2: cost.LE
A3: Last | B3: 345245 | C3: 0 | D3: 92514000 | E3: 0 | F3: 92469600 | G3: 0 | H3: 599930 | I3: 0 | J3: =C3+E3+G3+I3 -> 0 | K3: =J3*5.86 -> 0
A4: 43525 | B4: 345356 | C4: =(IF((B4-B3)<0,"0",(B4-B3)))*10 -> 1110 | D4: 92532800 | E4: =(IF((D4-D3)<0,"0",(D4-D3)))*0.027 -> 507.6 | F4: 92485100 | G4: =(IF((F4-F3)<0,"0",(F4-F3)))*0.027 -> 418.5 | H4: 600001 | I4: =(IF((H4-H3)<0,"0",(H4-H3)))*0.027 -> 1.917 | J4: =C4+E4+G4+I4 -> 2038.017 | K4: =J4*5.86 -> 11942.78
A5: 43526 | B5: 345454 | C5: =(IF((B5-B4)<0,"0",(B5-B4)))*10 -> 980 | D5: 92550700 | E5: =(IF((D5-D4)<0,"0",(D5-D4)))*0.027 -> 483.3 | F5: 92499700 | G5: =(IF((F5-F4)<0,"0",(F5-F4)))*0.027 -> 394.2 | H5: 600130 | I5: =(IF((H5-H4)<0,"0",(H5-H4)))*0.027 -> 3.483 | J5: =C5+E5+G5+I5 -> 1860.983 | K5: =J5*5.86 -> 10905.36
A6: 43527 | B6: 345563 | C6: =(IF((B6-B5)<0,"0",(B6-B5)))*10 -> 1090 | D6: 92569600 | E6: =(IF((D6-D5)<0,"0",(D6-D5)))*0.027 -> 510.3 | F6: 92513200 | G6: =(IF((F6-F5)<0,"0",(F6-F5)))*0.027 -> 364.5 | H6: 600251 | I6: =(IF((H6-H5)<0,"0",(H6-H5)))*0.027 -> 3.267 | J6: =C6+E6+G6+I6 -> 1968.067 | K6: =J6*5.86 -> 11532.873
A7: 43528 | B7: 345650 | C7: =(IF((B7-B6)<0,"0",(B7-B6)))*10 -> 870 | D7: 92580100 | E7: =(IF((D7-D6)<0,"0",(D7-D6)))*0.027 -> 283.5 | F7: 92525500 | G7: =(IF((F7-F6)<0,"0",(F7-F6)))*0.027 -> 332.1 | H7: 600399 | I7: =(IF((H7-H6)<0,"0",(H7-H6)))*0.027 -> 3.996 | J7: =C7+E7+G7+I7 -> 1489.596 | K7: =J7*5.86 -> 8729.0326
A8: 43529 | B8: 345749 | C8: =(IF((B8-B7)<0,"0",(B8-B7)))*10 -> 990 | D8: 92605300 | E8: =(IF((D8-D7)<0,"0",(D8-D7)))*0.027 -> 680.4 | F8: 92537000 | G8: =(IF((F8-F7)<0,"0",(F8-F7)))*0.027 -> 310.5 | H8: 600498 | I8: =(IF((H8-H7)<0,"0",(H8-H7)))*0.027 -> 2.673 | J8: =C8+E8+G8+I8 -> 1983.573 | K8: =J8*5.86 -> 11623.738
A9: 43530 | B9: 345851 | C9: =(IF((B9-B8)<0,"0",(B9-B8)))*10 -> 1020 | D9: 92626000 | E9: =(IF((D9-D8)<0,"0",(D9-D8)))*0.027 -> 558.9 | F9: 92549600 | G9: =(IF((F9-F8)<0,"0",(F9-F8)))*0.027 -> 340.2 | H9: 600648 | I9: =(IF((H9-H8)<0,"0",(H9-H8)))*0.027 -> 4.05 | J9: =C9+E9+G9+I9 -> 1923.15 | K9: =J9*5.86 -> 11269.659
A10: 43531 | B10: 345960 | C10: =(IF((B10-B9)<0,"0",(B10-B9)))*10 -> 1090 | D10: 92640100 | E10: =(IF((D10-D9)<0,"0",(D10-D9)))*0.027 -> 380.7 | F10: 92558900 | G10: =(IF((F10-F9)<0,"0",(F10-F9)))*0.027 -> 251.1 | H10: 600751 | I10: =(IF((H10-H9)<0,"0",(H10-H9)))*0.027 -> 2.781 | J10: =C10+E10+G10+I10 -> 1724.581 | K10: =J10*5.86 -> 10106.045
A11: 43532 | B11: 346050 | C11: =(IF((B11-B10)<0,"0",(B11-B10)))*10 -> 900 | D11: 92668300 | E11: =(IF((D11-D10)<0,"0",(D11-D10)))*0.027 -> 761.4 | F11: 92577400 | G11: =(IF((F11-F10)<0,"0",(F11-F10)))*0.027 -> 499.5 | H11: 600916 | I11: =(IF((H11-H10)<0,"0",(H11-H10)))*0.027 -> 4.455 | J11: =C11+E11+G11+I11 -> 2165.355 | K11: =J11*5.86 -> 12688.98
A12: 43533 | B12: 346133 | C12: =(IF((B12-B11)<0,"0",(B12-B11)))*10 -> 830 | D12: 92682300 | E12: =(IF((D12-D11)<0,"0",(D12-D11)))*0.027 -> 378 | F12: 92587900 | G12: =(IF((F12-F11)<0,"0",(F12-F11)))*0.027 -> 283.5 | H12: 601057 | I12: =(IF((H12-H11)<0,"0",(H12-H11)))*0.027 -> 3.807 | J12: =C12+E12+G12+I12 -> 1495.307 | K12: =J12*5.86 -> 8762.499
A13: 43534 | B13: 346216 | C13: =(IF((B13-B12)<0,"0",(B13-B12)))*10 -> 830 | D13: 92703100 | E13: =(IF((D13-D12)<0,"0",(D13-D12)))*0.027 -> 561.6 | F13: 92600000 | G13: =(IF((F13-F12)<0,"0",(F13-F12)))*0.027 -> 326.7 | H13: 601237 | I13: =(IF((H13-H12)<0,"0",(H13-H12)))*0.027 -> 4.86 | J13: =C13+E13+G13+I13 -> 1723.16 | K13: =J13*5.86 -> 10097.718
A14: 43535 | B14: 346321 | C14: =(IF((B14-B13)<0,"0",(B14-B13)))*10 -> 1050 | D14: 92723100 | E14: =(IF((D14-D13)<0,"0",(D14-D13)))*0.027 -> 540 | F14: 92613200 | G14: =(IF((F14-F13)<0,"0",(F14-F13)))*0.027 -> 356.4 | H14: 601386 | I14: =(IF((H14-H13)<0,"0",(H14-H13)))*0.027 -> 4.023 | J14: =C14+E14+G14+I14 -> 1950.423 | K14: =J14*5.86 -> 11429.479
A15: 43536 | B15: 346437 | C15: =(IF((B15-B14)<0,"0",(B15-B14)))*10 -> 1160 | D15: 92745000 | E15: =(IF((D15-D14)<0,"0",(D15-D14)))*0.027 -> 591.3 | F15: 92629300 | G15: =(IF((F15-F14)<0,"0",(F15-F14)))*0.027 -> 434.7 | H15: 601513 | I15: =(IF((H15-H14)<0,"0",(H15-H14)))*0.027 -> 3.429 | J15: =C15+E15+G15+I15 -> 2189.429 | K15: =J15*5.86 -> 12830.054
... A18: 43539 | B18: 346799 | C18: =(IF((B18-B17)<0,"0",(B18-B17)))*10 -> 1150 | D18: 92811300 | E18: =(IF((D18-D17)<0,"0",(D18-D17)))*0.027 -> 588.6 | F18: 92673000 | G18: =(IF((F18-F17)<0,"0",(F18-F17)))*0.027 -> 399.6 | H18: 601855 | I18: =(IF((H18-H17)<0,"0",(H18-H17)))*0.027 -> 2.484 | J18: =C18+E18+G18+I18 -> 2140.684 | K18: =J18*5.86 -> 12544.408
A19: 43540 | B19: 346901 | C19: =(IF((B19-B18)<0,"0",(B19-B18)))*10 -> 1020 | D19: 92835800 | E19: =(IF((D19-D18)<0,"0",(D19-D18)))*0.027 -> 661.5 | F19: 92688400 | G19: =(IF((F19-F18)<0,"0",(F19-F18)))*0.027 -> 415.8 | H19: 601993 | I19: =(IF((H19-H18)<0,"0",(H19-H18)))*0.027 -> 3.726 | J19: =C19+E19+G19+I19 -> 2101.026 | K19: =J19*5.86 -> 12312.012 | Q19: `
A20: 43541 | B20: 347039 | C20: =(IF((B20-B19)<0,"0",(B20-B19)))*10 -> 1380 | D20: 92858000 | E20: =(IF((D20-D19)<0,"0",(D20-D19)))*0.027 -> 599.4 | F20: 92702000 | G20: =(IF((F20-F19)<0,"0",(F20-F19)))*0.027 -> 367.2 | H20: 602118 | I20: =(IF((H20-H19)<0,"0",(H20-H19)))*0.027 -> 3.375 | J20: =C20+E20+G20+I20 -> 2349.975 | K20: =J20*5.86 -> 13770.854
A21: 43542 | B21: 347144 | C21: =(IF((B21-B20)<0,"0",(B21-B20)))*10 -> 1050 | D21: 92870100 | E21: =(IF((D21-D20)<0,"0",(D21-D20)))*0.027 -> 326.7 | F21: 92718000 | G21: =(IF((F21-F20)<0,"0",(F21-F20)))*0.027 -> 432 | H21: 602301 | I21: =(IF((H21-H20)<0,"0",(H21-H20)))*0.027 -> 4.941 | J21: =C21+E21+G21+I21 -> 1813.641 | K21: =J21*5.86 -> 10627.936
A22: 43543 | B22: 347250 | C22: =(IF((B22-B21)<0,"0",(B22-B21)))*10 -> 1060 | D22: 92902600 | E22: =(IF((D22-D21)<0,"0",(D22-D21)))*0.027 -> 877.5 | F22: 92729600 | G22: =(IF((F22-F21)<0,"0",(F22-F21)))*0.027 -> 313.2 | H22: 602380 | I22: =(IF((H22-H21)<0,"0",(H22-H21)))*0.027 -> 2.133 | J22: =C22+E22+G22+I22 -> 2252.833 | K22: =J22*5.86 -> 13201.601
A23: 43544 | B23: 347368 | C23: =(IF((B23-B22)<0,"0",(B23-B22)))*10 -> 1180 | D23: 92926200 | E23: =(IF((D23-D22)<0,"0",(D23-D22)))*0.027 -> 637.2 | F23: 92743200 | G23: =(IF((F23-F22)<0,"0",(F23-F22)))*0.027 -> 367.2 | H23: 602580 | I23: =(IF((H23-H22)<0,"0",(H23-H22)))*0.027 -> 5.4 | J23: =C23+E23+G23+I23 -> 2189.8 | K23: =J23*5.86 -> 12832.228
A24: 43545 | B24: 347480 | C24: =(IF((B24-B23)<0,"0",(B24-B23)))*10 -> 1120 | D24: 92948600 | E24: =(IF((D24-D23)<0,"0",(D24-D23)))*0.027 -> 604.8 | F24: 92758000 | G24: =(IF((F24-F23)<0,"0",(F24-F23)))*0.027 -> 399.6 | H24: 602770 | I24: =(IF((H24-H23)<0,"0",(H24-H23)))*0.027 -> 5.13 | J24: =C24+E24+G24+I24 -> 2129.53 | K24: =J24*5.86 -> 12479.046
A25: 43546 | B25: 347596 | C25: =(IF((B25-B24)<0,"0",(B25-B24)))*10 -> 1160 | D25: 92969400 | E25: =(IF((D25-D24)<0,"0",(D25-D24)))*0.027 -> 561.6 | F25: 92773400 | G25: =(IF((F25-F24)<0,"0",(F25-F24)))*0.027 -> 415.8 | H25: 602906 | I25: =(IF((H25-H24)<0,"0",(H25-H24)))*0.027 -> 3.672 | J25: =C25+E25+G25+I25 -> 2141.072 | K25: =J25*5.86 -> 12546.682
A26: 43547 | B26: 347719 | C26: =(IF((B26-B25)<0,"0",(B26-B25)))*10 -> 1230 | D26: 92994700 | E26: =(IF((D26-D25)<0,"0",(D26-D25)))*0.027 -> 683.1 | F26: 92792100 | G26: =(IF((F26-F25)<0,"0",(F26-F25)))*0.027 -> 504.9 | H26: 603129 | I26: =(IF((H26-H25)<0,"0",(H26-H25)))*0.027 -> 6.021 | J26: =C26+E26+G26+I26 -> 2424.021 | K26: =J26*5.86 -> 14204.763
A27: 43548 | B27: 347821 | C27: =(IF((B27-B26)<0,"0",(B27-B26)))*10 -> 1020 | D27: 93015300 | E27: =(IF((D27-D26)<0,"0",(D27-D26)))*0.027 -> 556.2 | F27: 92805200 | G27: =(IF((F27-F26)<0,"0",(F27-F26)))*0.027 -> 353.7 | H27: 603321 | I27: =(IF((H27-H26)<0,"0",(H27-H26)))*0.027 -> 5.184 | J27: =C27+E27+G27+I27 -> 1935.084 | K27: =J27*5.86 -> 11339.592
A28: 43549 | B28: 347932 | C28: =(IF((B28-B27)<0,"0",(B28-B27)))*10 -> 1110 | D28: 93037500 | E28: =(IF((D28-D27)<0,"0",(D28-D27)))*0.027 -> 599.4 | F28: 92818800 | G28: =(IF((F28-F27)<0,"0",(F28-F27)))*0.027 -> 367.2 | H28: 603453 | I28: =(IF((H28-H27)<0,"0",(H28-H27)))*0.027 -> 3.564 | J28: =C28+E28+G28+I28 -> 2080.164 | K28: =J28*5.86 -> 12189.761
A29: 43550 | B29: 348044 | C29: =(IF((B29-B28)<0,"0",(B29-B28)))*10 -> 1120 | D29: 93062200 | E29: =(IF((D29-D28)<0,"0",(D29-D28)))*0.027 -> 666.9 | F29: 92833100 | G29: =(IF((F29-F28)<0,"0",(F29-F28)))*0.027 -> 386.1 | H29: 603591 | I29: =(IF((H29-H28)<0,"0",(H29-H28)))*0.027 -> 3.726 | J29: =C29+E29+G29+I29 -> 2176.726 | K29: =J29*5.86 -> 12755.614
A30: 43551 | B30: 348155 | C30: =(IF((B30-B29)<0,"0",(B30-B29)))*10 -> 1110 | D30: 93085700 | E30: =(IF((D30-D29)<0,"0",(D30-D29)))*0.027 -> 634.5 | F30: 92847700 | G30: =(IF((F30-F29)<0,"0",(F30-F29)))*0.027 -> 394.2 | H30: 603738 | I30: =(IF((H30-H29)<0,"0",(H30-H29)))*0.027 -> 3.969 | J30: =C30+E30+G30+I30 -> 2142.669 | K30: =J30*5.86 -> 12556.04
A31: 43552 | B31: 348262 | C31: =(IF((B31-B30)<0,"0",(B31-B30)))*10 -> 1070 | D31: 93106700 | E31: =(IF((D31-D30)<0,"0",(D31-D30)))*0.027 -> 567 | F31: 92863800 | G31: =(IF((F31-F30)<0,"0",(F31-F30)))*0.027 -> 434.7 | H31: 603901 | I31: =(IF((H31-H30)<0,"0",(H31-H30)))*0.027 -> 4.401 | J31: =C31+E31+G31+I31 -> 2076.101 | K31: =J31*5.86 -> 12165.952
... A33: 43554 | B33: 348454 | C33: =(IF((B33-B32)<0,"0",(B33-B32)))*10 -> 1010 | D33: 93143200 | E33: =(IF((D33-D32)<0,"0",(D33-D32)))*0.027 -> 499.5 | F33: 92895000 | G33: =(IF((F33-F32)<0,"0",(F33-F32)))*0.027 -> 429.3 | H33: 604184 | I33: =(IF((H33-H32)<0,"0",(H33-H32)))*0.027 -> 4.401 | J33: =C33+E33+G33+I33 -> 1943.201 | K33: =J33*5.86 -> 11387.158
A34: 43555 | B34: 348554 | C34: =(IF((B34-B33)<0,"0",(B34-B33)))*10 -> 1000 | D34: 93163800 | E34: =(IF((D34-D33)<0,"0",(D34-D33)))*0.027 -> 556.2 | F34: 92909900 | G34: =(IF((F34-F33)<0,"0",(F34-F33)))*0.027 -> 402.3 | H34: 604325 | I34: =(IF((H34-H33)<0,"0",(H34-H33)))*0.027 -> 3.807
A35: Total | C35: =SUM(C4:C34) -> 33090 | E35: =SUM(E4:E34) -> 17544.6 | G35: =SUM(G4:G34) -> 11888.1 | I35: =SUM(I4:I34) -> 118.665 | J35: =SUM(J4:J31) -> 56923.517 | K35: =SUM(K4:K31) -> 333571.81

Sheet ELECT.
A1: Feeders and transformers Electrity cons. Mar 2019
A2: Day | B2: Rooms Sold | C2: New Chillers | D2: Cons | E2: F-1 | F2: Cons. | G2: F-2 | H2: Cons. | I2: Total | J2: T-1 | K2: Cons. | L2: T-2 | M2: Cons. | N2: T-3 | O2: Cons. | P2: T-4 | Q2: Cons. | R2: T-5 | S2: Cons. | T2: T-6 | U2: Cons. | V2: T-7 | W2: Cons. | X2: Total | Y2: Diff | Z2: Daily Money Value | AA2: MTD Total Money
A3: Last | B3: 334 | C3: 15211 | E3: 16039765 | F3: 0 | G3: 42038210 | H3: 0 | I3: 0 | J3: 3573765 | K3: 0 | L3: 3771306 | M3: 0 | N3: 2386621 | O3: 0 | P3: 4766838 | Q3: 0 | R3: 9510473 | S3: 0 | T3: 0 | V3: 5950752 | W3: 0
A4: 43525 | B4: 334 | C4: 15218 | D4: =IF((C4-C3)<0,"0",(C4-C3))*160 -> 1120 | E4: 16057419 | F4: =IF((E4-E3)<0,"0",(E4-E3)) -> 17654 | G4: 42114542 | H4: =IF((G4-G3)<0,"0",(G4-G3)) -> 76332 | I4: =F4+H4 -> 93986 | J4: 3581150 | K4: =IF((J4-J3)<0,"0",(J4-J3)) -> 7385 | L4: 3779001 | M4: =IF((L4-L3)<0,"0",(L4-L3)) -> 7695 | N4: 2391469 | O4: =(IF((N4-N3)<0,"0",(N4-N3)))*2 -> 9696 | P4: 4771266 | Q4: =IF((P4-P3)<0,"0",(P4-P3)) -> 4428 | R4: 9530221 | S4: =IF((R4-R3)<0,"0",(R4-R3)) -> 19748 | T4: 0 | V4: 5972301 | W4: =IF((V4-V3)<0,"0",(V4-V3)) -> 21549 | X4: =K4+M4+O4+Q4+S4+U4+W4 -> 70501 | Y4: =I4-X4 -> 23485 | Z4: =(0.93352*(W4+S4)+0.5568*(Q4+O4))*0.26 -> 12068.113 | AA4: =SUM(Z1:Z4) -> 12068.113
A5: 43526 | B5: 323 | C5: 15221 | D5: =IF((C5-C4)<0,"0",(C5-C4))*160 -> 480 | E5: 16065965 | F5: =IF((E5-E4)<0,"0",(E5-E4)) -> 8546 | G5: 42149950 | H5: =IF((G5-G4)<0,"0",(G5-G4)) -> 35408 | I5: =F5+H5 -> 43954 | J5: 3584675 | K5: =IF((J5-J4)<0,"0",(J5-J4)) -> 3525 | L5: 3782774 | M5: =IF((L5-L4)<0,"0",(L5-L4)) -> 3773 | N5: 2393805 | O5: =(IF((N5-N4)<0,"0",(N5-N4)))*2 -> 4672 | P5: 4773350 | Q5: =IF((P5-P4)<0,"0",(P5-P4)) -> 2084 | R5: 9539400 | S5: =IF((R5-R4)<0,"0",(R5-R4)) -> 9179 | T5: 0 | V5: 5982280 | W5: =IF((V5-V4)<0,"0",(V5-V4)) -> 9979 | X5: =K5+M5+O5+Q5+S5+U5+W5 -> 33212 | Y5: =I5-X5 -> 10742 | Z5: =(0.93352*(W5+S5)+0.5568*(Q5+O5))*0.26 -> 5627.9904 | AA5: =SUM(Z2:Z5) -> 17696.103
A6: 43527 | B6: 275 | C6: 15225 | D6: =IF((C6-C5)<0,"0",(C6-C5))*160 -> 640 | E6: 16078155 | F6: =IF((E6-E5)<0,"0",(E6-E5)) -> 12190 | G6: 42201853 | H6: =IF((G6-G5)<0,"0",(G6-G5)) -> 51903 | I6: =F6+H6 -> 64093 | J6: 3589866 | K6: =IF((J6-J5)<0,"0",(J6-J5)) -> 5191 | L6: 3787927 | M6: =IF((L6-L5)<0,"0",(L6-L5)) -> 5153 | N6: 2397225 | O6: =(IF((N6-N5)<0,"0",(N6-N5)))*2 -> 6840 | P6: 4776470 | Q6: =IF((P6-P5)<0,"0",(P6-P5)) -> 3120 | R6: 9552504 | S6: =IF((R6-R5)<0,"0",(R6-R5)) -> 13104 | T6: 0 | V6: 5996909 | W6: =IF((V6-V5)<0,"0",(V6-V5)) -> 14629 | X6: =K6+M6+O6+Q6+S6+U6+W6 -> 48037 | Y6: =I6-X6 -> 16056 | Z6: =(0.93352*(W6+S6)+0.5568*(Q6+O6))*0.26 -> 8173.1099 | AA6: =SUM(Z3:Z6) -> 25869.213
A7: 43528 | B7: 300 | C7: 15229 | D7: =IF((C7-C6)<0,"0",(C7-C6))*160 -> 640 | E7: 16088221 | F7: =IF((E7-E6)<0,"0",(E7-E6)) -> 10066 | G7: 42242382 | H7: =IF((G7-G6)<0,"0",(G7-G6)) -> 40529 | I7: =F7+H7 -> 50595 | J7: 3593878 | K7: =IF((J7-J6)<0,"0",(J7-J6)) -> 4012 | L7: 3792363 | M7: =IF((L7-L6)<0,"0",(L7-L6)) -> 4436 | N7: 2399987 | O7: =(IF((N7-N6)<0,"0",(N7-N6)))*2 -> 5524 | P7: 4778800 | Q7: =IF((P7-P6)<0,"0",(P7-P6)) -> 2330 | R7: 9562557 | S7: =IF((R7-R6)<0,"0",(R7-R6)) -> 10053 | T7: 0 | V7: 6008574 | W7: =IF((V7-V6)<0,"0",(V7-V6)) -> 11665 | X7: =K7+M7+O7+Q7+S7+U7+W7 -> 38020 | Y7: =I7-X7 -> 12575 | Z7: =(0.93352*(W7+S7)+0.5568*(Q7+O7))*0.26 -> 6408.2966 | AA7: =SUM(Z4:Z7) -> 32277.51
A8: 43529 | B8: 375 | C8: 15233 | D8: =IF((C8-C7)<0,"0",(C8-C7))*160 -> 640 | E8: 16097273 | F8: =IF((E8-E7)<0,"0",(E8-E7)) -> 9052 | G8: 42286113 | H8: =IF((G8-G7)<0,"0",(G8-G7)) -> 43731 | I8: =F8+H8 -> 52783 | J8: 3598228 | K8: =IF((J8-J7)<0,"0",(J8-J7)) -> 4350 | L8: 3796933 | M8: =IF((L8-L7)<0,"0",(L8-L7)) -> 4570 | N8: 2402153 | O8: =(IF((N8-N7)<0,"0",(N8-N7)))*2 -> 4332 | P8: 4783138 | Q8: =IF((P8-P7)<0,"0",(P8-P7)) -> 4338 | R8: 9572947 | S8: =IF((R8-R7)<0,"0",(R8-R7)) -> 10390 | T8: 0 | V8: 6020511 | W8: =IF((V8-V7)<0,"0",(V8-V7)) -> 11937 | X8: =K8+M8+O8+Q8+S8+U8+W8 -> 39917 | Y8: =I8-X8 -> 12866 | Z8: =(0.93352*(W8+S8)+0.5568*(Q8+O8))*0.26 -> 6674.2408 | AA8: =SUM(Z5:Z8) -> 26883.638
A9: 43530 | B9: 323 | C9: 15238 | D9: =IF((C9-C8)<0,"0",(C9-C8))*160 -> 800 | E9: 16102152 | F9: =IF((E9-E8)<0,"0",(E9-E8)) -> 4879 | G9: 42322157 | H9: =IF((G9-G8)<0,"0",(G9-G8)) -> 36044 | I9: =F9+H9 -> 40923 | J9: 3601517 | K9: =IF((J9-J8)<0,"0",(J9-J8)) -> 3289 | L9: 3800320 | M9: =IF((L9-L8)<0,"0",(L9-L8)) -> 3387 | N9: 2402849 | O9: =(IF((N9-N8)<0,"0",(N9-N8)))*2 -> 1392 | P9: 4788952 | Q9: =IF((P9-P8)<0,"0",(P9-P8)) -> 5814 | R9: 9581013 | S9: =IF((R9-R8)<0,"0",(R9-R8)) -> 8066 | T9: 0 | V9: 6029682 | W9: =IF((V9-V8)<0,"0",(V9-V8)) -> 9171 | X9: =K9+M9+O9+Q9+S9+U9+W9 -> 31119 | Y9: =I9-X9 -> 9804 | Z9: =(0.93352*(W9+S9)+0.5568*(Q9+O9))*0.26 -> 5226.8801 | AA9: =SUM(Z6:Z9) -> 26482.527
A10: 43531 | B10: 357 | C10: 15241 | D10: =IF((C10-C9)<0,"0",(C10-C9))*160 -> 480 | E10: 16117814 | F10: =IF((E10-E9)<0,"0",(E10-E9)) -> 15662 | G10: 42388933 | H10: =IF((G10-G9)<0,"0",(G10-G9)) -> 66776 | I10: =F10+H10 -> 82438 | J10: 3607882 | K10: =IF((J10-J9)<0,"0",(J10-J9)) -> 6365 | L10: 3809021 | M10: =IF((L10-L9)<0,"0",(L10-L9)) -> 8701 | N10: 2406208 | O10: =(IF((N10-N9)<0,"0",(N10-N9)))*2 -> 6718 | P10: 4797036 | Q10: =IF((P10-P9)<0,"0",(P10-P9)) -> 8084 | R10: 9596608 | S10: =IF((R10-R9)<0,"0",(R10-R9)) -> 15595 | T10: 0 | V10: 6047435 | W10: =IF((V10-V9)<0,"0",(V10-V9)) -> 17753 | X10: =K10+M10+O10+Q10+S10+U10+W10 -> 63216 | Y10: =I10-X10 -> 19222 | Z10: =(0.93352*(W10+S10)+0.5568*(Q10+O10))*0.26 -> 10236.922 | AA10: =SUM(Z7:Z10) -> 28546.34
A11: 43532 | B11: 361 | C11: 15247 | D11: =IF((C11-C10)<0,"0",(C11-C10))*160 -> 960 | E11: 16132664 | F11: =IF((E11-E10)<0,"0",(E11-E10)) -> 14850 | G11: 42431393 | H11: =IF((G11-G10)<0,"0",(G11-G10)) -> 42460 | I11: =F11+H11 -> 57310 | J11: 3611001 | K11: =IF((J11-J10)<0,"0",(J11-J10)) -> 3119 | L11: 3815054 | M11: =IF((L11-L10)<0,"0",(L11-L10)) -> 6033 | N11: 2410534 | O11: =(IF((N11-N10)<0,"0",(N11-N10)))*2 -> 8652 | P11: 4799578 | Q11: =IF((P11-P10)<0,"0",(P11-P10)) -> 2542 | R11: 9607655 | S11: =IF((R11-R10)<0,"0",(R11-R10)) -> 11047 | T11: 0 | V11: 6059539 | W11: =IF((V11-V10)<0,"0",(V11-V10)) -> 12104 | X11: =K11+M11+O11+Q11+S11+U11+W11 -> 43497 | Y11: =I11-X11 -> 13813 | Z11: =(0.93352*(W11+S11)+0.5568*(Q11+O11))*0.26 -> 7239.6326 | AA11: =SUM(Z8:Z11) -> 29377.676
A12: 43533 | B12: 293 | C12: 15250 | D12: =IF((C12-C11)<0,"0",(C12-C11))*160 -> 480 | E12: 16147474 | F12: =IF((E12-E11)<0,"0",(E12-E11)) -> 14810 | G12: 42472193 | H12: =IF((G12-G11)<0,"0",(G12-G11)) -> 40800 | I12: =F12+H12 -> 55610 | J12: 3616036 | K12: =IF((J12-J11)<0,"0",(J12-J11)) -> 5035 | L12: 3821283 | M12: =IF((L12-L11)<0,"0",(L12-L11)) -> 6229 | N12: 2414757 | O12: =(IF((N12-N11)<0,"0",(N12-N11)))*2 -> 8446 | P12: 4802072 | Q12: =IF((P12-P11)<0,"0",(P12-P11)) -> 2494 | R12: 9618008 | S12: =IF((R12-R11)<0,"0",(R12-R11)) -> 10353 | T12: 0 | V12: 6071037 | W12: =IF((V12-V11)<0,"0",(V12-V11)) -> 11498 | X12: =K12+M12+O12+Q12+S12+U12+W12 -> 44055 | Y12: =I12-X12 -> 11555 | Z12: =(0.93352*(W12+S12)+0.5568*(Q12+O12))*0.26 -> 6887.3318 | AA12: =SUM(Z9:Z12) -> 29590.767
A13: 43534 | B13: 302 | C13: 15254 | D13: =IF((C13-C12)<0,"0",(C13-C12))*160 -> 640 | E13: 16164701 | F13: =IF((E13-E12)<0,"0",(E13-E12)) -> 17227 | G13: 42524787 | H13: =IF((G13-G12)<0,"0",(G13-G12)) -> 52594 | I13: =F13+H13 -> 69821 | J13: 3621605 | K13: =IF((J13-J12)<0,"0",(J13-J12)) -> 5569 | L13: 3828507 | M13: =IF((L13-L12)<0,"0",(L13-L12)) -> 7224 | N13: 2419643 | O13: =(IF((N13-N12)<0,"0",(N13-N12)))*2 -> 9772 | P13: 4805334 | Q13: =IF((P13-P12)<0,"0",(P13-P12)) -> 3262 | R13: 9630880 | S13: =IF((R13-R12)<0,"0",(R13-R12)) -> 12872 | T13: 0 | V13: 6085922 | W13: =IF((V13-V12)<0,"0",(V13-V12)) -> 14885 | X13: =K13+M13+O13+Q13+S13+U13+W13 -> 53584 | Y13: =I13-X13 -> 16237 | Z13: =(0.93352*(W13+S13)+0.5568*(Q13+O13))*0.26 -> 8623.9519 | AA13: =SUM(Z10:Z13) -> 32987.839
A14: 43535 | B14: 353 | C14: 15258 | D14: =IF((C14-C13)<0,"0",(C14-C13))*160 -> 640 | E14: 16171697 | F14: =IF((E14-E13)<0,"0",(E14-E13)) -> 6996 | G14: 42550025 | H14: =IF((G14-G13)<0,"0",(G14-G13)) -> 25238 | I14: =F14+H14 -> 32234 | J14: 3624114 | K14: =IF((J14-J13)<0,"0",(J14-J13)) -> 2509 | L14: 3832235 | M14: =IF((L14-L13)<0,"0",(L14-L13)) -> 3728 | N14: 2421251 | O14: =(IF((N14-N13)<0,"0",(N14-N13)))*2 -> 3216 | P14: 4808098 | Q14: =IF((P14-P13)<0,"0",(P14-P13)) -> 2764 | R14: 9636648 | S14: =IF((R14-R13)<0,"0",(R14-R13)) -> 5768 | T14: 0 | V14: 6092844 | W14: =IF((V14-V13)<0,"0",(V14-V13)) -> 6922 | X14: =K14+M14+O14+Q14+S14+U14+W14 -> 24907 | Y14: =I14-X14 -> 7327 | Z14: =(0.93352*(W14+S14)+0.5568*(Q14+O14))*0.26 -> 3945.7685 | AA14: =SUM(Z11:Z14) -> 26696.685
A15: 43536 | B15: 320 | C15: 15263 | D15: =IF((C15-C14)<0,"0",(C15-C14))*160 -> 800 | E15: 16186373 | F15: =IF((E15-E14)<0,"0",(E15-E14)) -> 14676 | G15: 42604280 | H15: =IF((G15-G14)<0,"0",(G15-G14)) -> 54255 | I15: =F15+H15 -> 68931 | J15: 3629984 | K15: =IF((J15-J14)<0,"0",(J15-J14)) -> 5870 | L15: 3838279 | M15: =IF((L15-L14)<0,"0",(L15-L14)) -> 6044 | N15: 2425479 | O15: =(IF((N15-N14)<0,"0",(N15-N14)))*2 -> 8456 | P15: 4811126 | Q15: =IF((P15-P14)<0,"0",(P15-P14)) -> 3028 | R15: 9649375 | S15: =IF((R15-R14)<0,"0",(R15-R14)) -> 12727 | T15: 0 | V15: 6108691 | W15: =IF((V15-V14)<0,"0",(V15-V14)) -> 15847 | X15: =K15+M15+O15+Q15+S15+U15+W15 -> 51972 | Y15: =I15-X15 -> 16959 | Z15: =(0.93352*(W15+S15)+0.5568*(Q15+O15))*0.26 -> 8597.8598 | AA15: =SUM(Z12:Z15) -> 28054.912
... A34: 43555 | B34: 350 | C34: 15337 | D34: =IF((C34-C33)<0,"0",(C34-C33))*160 -> 160 | E34: 16372454 | F34: =IF((E34-E33)<0,"0",(E34-E33)) -> 6125 | G34: 43524507 | H34: =IF((G34-G33)<0,"0",(G34-G33)) -> 51160 | I34: =F34+H34 -> 57285 | J34: 3720138 | K34: =IF((J34-J33)<0,"0",(J34-J33)) -> 4814 | L34: 3930918 | M34: =IF((L34-L33)<0,"0",(L34-L33)) -> 4324 | N34: 2470813 | O34: =(IF((N34-N33)<0,"0",(N34-N33)))*2 -> 1654 | P34: 4919848 | Q34: =IF((P34-P33)<0,"0",(P34-P33)) -> 9179 | R34: 9860830 | S34: =IF((R34-R33)<0,"0",(R34-R33)) -> 11144 | T34: 0 | V34: 6353860 | W34: =IF((V34-V33)<0,"0",(V34-V33)) -> 12413 | X34: =K34+M34+O34+Q34+S34+U34+W34 -> 43528 | Y34: =I34-X34 -> 13757 | Z34: =(0.93352*(W34+S34)+0.5568*(Q34+O34))*0.26 -> 7285.9137 | AA34: =SUM(Z31:Z34) -> 30992.991
A35: Total | F35: =SUM(F3:F34) -> 332689 | H35: =SUM(H3:H34) -> 1486297 | I35: =F35+H35 -> 1818986 | K35: =SUM(K3:K34) -> 146373 | M35: =SUM(M3:M34) -> 159612 | O35: =SUM(O3:O34) -> 168384 | Q35: =SUM(Q3:Q34) -> 153010 | S35: =SUM(S3:T34) -> 350357 | W35: =SUM(W3:W34) -> 403108 | X35: =SUM(X4:X31) -> 1254052 | Y35: =SUM(Y4:Y31) -> 398312 | Z35: =SUM(Z5:Z31) -> 195952.9

Sheet Gas
A1: Gas Con. Mar 2019
A2: Day | B2: Main | C2: Cons.
A3: Last | B3: 15230695
A4: 43525 | B4: 15234602 | C4: =IF((B4-B3)<0,"0",(B4-B3)) -> 3907
A5: 43526 | B5: 15238496 | C5: =IF((B5-B4)<0,"0",(B5-B4)) -> 3894
A6: 43527 | B6: 15241920 | C6: =IF((B6-B5)<0,"0",(B6-B5)) -> 3424
A7: 43528 | B7: 15245590 | C7: =IF((B7-B6)<0,"0",(B7-B6)) -> 3670
A8: 43529 | B8: 15249578 | C8: =IF((B8-B7)<0,"0",(B8-B7)) -> 3988
A9: 43530 | B9: 15253915 | C9: =IF((B9-B8)<0,"0",(B9-B8)) -> 4337
A10: 43531 | B10: 15257790 | C10: =IF((B10-B9)<0,"0",(B10-B9)) -> 3875
A11: 43532 | B11: 15261687 | C11: =IF((B11-B10)<0,"0",(B11-B10)) -> 3897
A12: 43533 | B12: 15265547 | C12: =IF((B12-B11)<0,"0",(B12-B11)) -> 3860
A13: 43534 | B13: 15269004 | C13: =IF((B13-B12)<0,"0",(B13-B12)) -> 3457
A14: 43535 | B14: 15272428 | C14: =IF((B14-B13)<0,"0",(B14-B13)) -> 3424
A15: 43536 | B15: 15275698 | C15: =IF((B15-B14)<0,"0",(B15-B14)) -> 3270
... A34: 43555 | B34: 15346378 | C34: =IF((B34-B33)<0,"0",(B34-B33)) -> 3255
A35: Total | C35: =SUM(C4:C34) -> 115683

Sheet BTU
A1: Day | B1: Hotel | C1: Cons. Mwh | D1: Cost (LE) | E1: B.S | F1: Cons. Mwh | G1: Cost (LE) | H1: LS | I1: Cons.Mwh | J1: . | K1: AHU # 25 | L1: Cons.Mwh | M1: Cost (LE) | N1: Mall | O1: Cons.Mwh | P1: Cost (LE) | Q1: AHU # 9 | R1: Cons.Mwh | S1: Cost (LE) | T1: Total Cons. | U1: Total Cost (LE)
A2: Last | B2: 13904.919 | D2: =C2*1.9*1000 -> 0 | E2: 2079.709 | G2: =F2*1.9*1000 -> 0 | H2: 855.446 | J2: =I2*1.9*1000 -> 0 | K2: 12668.92 | M2: =L2*1.9*1000 -> 0 | N2: 1704.686 | P2: =O2*1.9*1000 -> 0 | Q2: 3836.26 | S2: 0 | T2: =C2+F2+I2+L2+O2+R2 -> 0
A3: 43525 | B3: 13908.818 | C3: =IF((B3-B2)<0,"0",(B3-B2)) -> 3.899 | D3: =C3*1.9*1000 -> 7408.1 | E3: 2080.151 | F3: =IF((E3-E2)<0,"0",(E3-E2)) -> 0.442 | G3: =F3*1.9*1000 -> 839.8 | H3: 855.446 | I3: =IF((H3-H2)<0,"0",(H3-H2)) -> 0 | J3: =I3*1.9*1000 -> 0 | K3: 12668.92 | L3: =IF((K3-K2)<0,"0",(K3-K2)) -> 0 | M3: =L3*1.9*1000 -> 0 | N3: 1705.709 | O3: =IF((N3-N2)<0,"0",(N3-N2)) -> 1.023 | P3: =O3*1.9*1000 -> 1943.7 | Q3: 3836.63 | R3: =IF((Q3-Q2)<0,"0",(Q3-Q2)) -> 0.37 | S3: =R3*1.9*1000 -> 703 | T3: =C3+F3+I3+L3+O3+R3 -> 5.734 | U3: =T3*1.9*1000 -> 10894.6
A4: 43526 | B4: 13913.033 | C4: =IF((B4-B3)<0,"0",(B4-B3)) -> 4.215 | D4: =C4*1.9*1000 -> 8008.5 | E4: 2080.792 | F4: =IF((E4-E3)<0,"0",(E4-E3)) -> 0.641 | G4: =F4*1.9*1000 -> 1217.9 | H4: 855.446 | I4: =IF((H4-H3)<0,"0",(H4-H3)) -> 0 | J4: =I4*1.9*1000 -> 0 | K4: 12668.92 | L4: =IF((K4-K3)<0,"0",(K4-K3)) -> 0 | M4: =L4*1.9*1000 -> 0 | N4: 1706.708 | O4: =IF((N4-N3)<0,"0",(N4-N3)) -> 0.999 | P4: =O4*1.9*1000 -> 1898.1 | Q4: 3837.46 | R4: =IF((Q4-Q3)<0,"0",(Q4-Q3)) -> 0.83 | S4: =R4*1.9*1000 -> 1577 | T4: =C4+F4+I4+L4+O4+R4 -> 6.685 | U4: =T4*1.9*1000 -> 12701.5
A5: 43527 | B5: 13917.58 | C5: =IF((B5-B4)<0,"0",(B5-B4)) -> 4.547 | D5: =C5*1.9*1000 -> 8639.3 | E5: 2081.663 | F5: =IF((E5-E4)<0,"0",(E5-E4)) -> 0.871 | G5: =F5*1.9*1000 -> 1654.9 | H5: 855.446 | I5: =IF((H5-H4)<0,"0",(H5-H4)) -> 0 | J5: =I5*1.9*1000 -> 0 | K5: 12668.92 | L5: =IF((K5-K4)<0,"0",(K5-K4)) -> 0 | M5: =L5*1.9*1000 -> 0 | N5: 1707.285 | O5: =IF((N5-N4)<0,"0",(N5-N4)) -> 0.577 | P5: =O5*1.9*1000 -> 1096.3 | Q5: 3837.5 | R5: =IF((Q5-Q4)<0,"0",(Q5-Q4)) -> 0.04 | S5: =R5*1.9*1000 -> 76 | T5: =C5+F5+I5+L5+O5+R5 -> 6.035 | U5: =T5*1.9*1000 -> 11466.5
A6: 43528 | B6: 13922.724 | C6: =IF((B6-B5)<0,"0",(B6-B5)) -> 5.144 | D6: =C6*1.9*1000 -> 9773.6 | E6: 2082.739 | F6: =IF((E6-E5)<0,"0",(E6-E5)) -> 1.076 | G6: =F6*1.9*1000 -> 2044.4 | H6: 855.446 | I6: =IF((H6-H5)<0,"0",(H6-H5)) -> 0 | J6: =I6*1.9*1000 -> 0 | K6: 12668.92 | L6: =IF((K6-K5)<0,"0",(K6-K5)) -> 0 | M6: =L6*1.9*1000 -> 0 | N6: 1707.895 | O6: =IF((N6-N5)<0,"0",(N6-N5)) -> 0.61 | P6: =O6*1.9*1000 -> 1159 | Q6: 3837.69 | R6: =IF((Q6-Q5)<0,"0",(Q6-Q5)) -> 0.19 | S6: =R6*1.9*1000 -> 361 | T6: =C6+F6+I6+L6+O6+R6 -> 7.02 | U6: =T6*1.9*1000 -> 13338
A7: 43529 | B7: 13927.528 | C7: =IF((B7-B6)<0,"0",(B7-B6)) -> 4.804 | D7: =C7*1.9*1000 -> 9127.6 | E7: 2083.629 | F7: =IF((E7-E6)<0,"0",(E7-E6)) -> 0.89 | G7: =F7*1.9*1000 -> 1691 | H7: 855.455 | I7: =IF((H7-H6)<0,"0",(H7-H6)) -> 0.009 | J7: =I7*1.9*1000 -> 17.1 | K7: 12668.92 | L7: =IF((K7-K6)<0,"0",(K7-K6)) -> 0 | M7: =L7*1.9*1000 -> 0 | N7: 1708.6668 | O7: =IF((N7-N6)<0,"0",(N7-N6)) -> 0.7718 | P7: =O7*1.9*1000 -> 1466.42 | Q7: 3837.69 | R7: =IF((Q7-Q6)<0,"0",(Q7-Q6)) -> 0 | S7: =R7*1.9*1000 -> 0 | T7: =C7+F7+I7+L7+O7+R7 -> 6.4748 | U7: =T7*1.9*1000 -> 12302.12
A8: 43530 | B8: 13931.609 | C8: =IF((B8-B7)<0,"0",(B8-B7)) -> 4.081 | D8: =C8*1.9*1000 -> 7753.9 | E8: 2084.514 | F8: =IF((E8-E7)<0,"0",(E8-E7)) -> 0.885 | G8: =F8*1.9*1000 -> 1681.5 | H8: 855.455 | I8: =IF((H8-H7)<0,"0",(H8-H7)) -> 0 | J8: =I8*1.9*1000 -> 0 | K8: 12668.92 | L8: =IF((K8-K7)<0,"0",(K8-K7)) -> 0 | M8: =L8*1.9*1000 -> 0 | N8: 1709.602 | O8: =IF((N8-N7)<0,"0",(N8-N7)) -> 0.9352 | P8: =O8*1.9*1000 -> 1776.88 | Q8: 3837.69 | R8: =IF((Q8-Q7)<0,"0",(Q8-Q7)) -> 0 | S8: =R8*1.9*1000 -> 0 | T8: =C8+F8+I8+L8+O8+R8 -> 5.9012 | U8: =T8*1.9*1000 -> 11212.28
A9: 43531 | B9: 13933.55 | C9: =IF((B9-B8)<0,"0",(B9-B8)) -> 1.941 | D9: =C9*1.9*1000 -> 3687.9 | E9: 2085.293 | F9: =IF((E9-E8)<0,"0",(E9-E8)) -> 0.779 | G9: =F9*1.9*1000 -> 1480.1 | H9: 855.456 | I9: =IF((H9-H8)<0,"0",(H9-H8)) -> 0.001 | J9: =I9*1.9*1000 -> 1.9 | K9: 12668.92 | L9: =IF((K9-K8)<0,"0",(K9-K8)) -> 0 | M9: =L9*1.9*1000 -> 0 | N9: 1710.571 | O9: =IF((N9-N8)<0,"0",(N9-N8)) -> 0.969 | P9: =O9*1.9*1000 -> 1841.1 | Q9: 3837.69 | R9: =IF((Q9-Q8)<0,"0",(Q9-Q8)) -> 0 | S9: =R9*1.9*1000 -> 0 | T9: =C9+F9+I9+L9+O9+R9 -> 3.69 | U9: =T9*1.9*1000 -> 7011
A10: 43532 | B10: 13940.069 | C10: =IF((B10-B9)<0,"0",(B10-B9)) -> 6.519 | D10: =C10*1.9*1000 -> 12386.1 | E10: 2085.787 | F10: =IF((E10-E9)<0,"0",(E10-E9)) -> 0.494 | G10: =F10*1.9*1000 -> 938.6 | H10: 855.461 | I10: =IF((H10-H9)<0,"0",(H10-H9)) -> 0.005 | J10: =I10*1.9*1000 -> 9.5 | K10: 12668.92 | L10: =IF((K10-K9)<0,"0",(K10-K9)) -> 0 | M10: =L10*1.9*1000 -> 0 | N10: 1711.717 | O10: =IF((N10-N9)<0,"0",(N10-N9)) -> 1.146 | P10: =O10*1.9*1000 -> 2177.4 | Q10: 3838.07 | R10: =IF((Q10-Q9)<0,"0",(Q10-Q9)) -> 0.38 | S10: =R10*1.9*1000 -> 722 | T10: =C10+F10+I10+L10+O10+R10 -> 8.544 | U10: =T10*1.9*1000 -> 16233.6
A11: 43533 | B11: 13945.026 | C11: =IF((B11-B10)<0,"0",(B11-B10)) -> 4.957 | D11: =C11*1.9*1000 -> 9418.3 | E11: 2086.269 | F11: =IF((E11-E10)<0,"0",(E11-E10)) -> 0.482 | G11: =F11*1.9*1000 -> 915.8 | H11: 855.515 | I11: =IF((H11-H10)<0,"0",(H11-H10)) -> 0.054 | J11: =I11*1.9*1000 -> 102.6 | K11: 12669.64 | L11: =IF((K11-K10)<0,"0",(K11-K10)) -> 0.72 | M11: =L11*1.9*1000 -> 1368 | N11: 1713.075 | O11: =IF((N11-N10)<0,"0",(N11-N10)) -> 1.358 | P11: =O11*1.9*1000 -> 2580.2 | Q11: 3838.62 | R11: =IF((Q11-Q10)<0,"0",(Q11-Q10)) -> 0.55 | S11: =R11*1.9*1000 -> 1045 | T11: =C11+F11+I11+L11+O11+R11 -> 8.121 | U11: =T11*1.9*1000 -> 15429.9
A12: 43534 | B12: 13949.949 | C12: =IF((B12-B11)<0,"0",(B12-B11)) -> 4.923 | D12: =C12*1.9*1000 -> 9353.7 | E12: 2087.487 | F12: =IF((E12-E11)<0,"0",(E12-E11)) -> 1.218 | G12: =F12*1.9*1000 -> 2314.2 | H12: 855.629 | I12: =IF((H12-H11)<0,"0",(H12-H11)) -> 0.114 | J12: =I12*1.9*1000 -> 216.6 | K12: 12670.7 | L12: =IF((K12-K11)<0,"0",(K12-K11)) -> 1.06 | M12: =L12*1.9*1000 -> 2014 | N12: 1714.273 | O12: =IF((N12-N11)<0,"0",(N12-N11)) -> 1.198 | P12: =O12*1.9*1000 -> 2276.2 | Q12: 3838.62 | R12: =IF((Q12-Q11)<0,"0",(Q12-Q11)) -> 0 | S12: =R12*1.9*1000 -> 0 | T12: =C12+F12+I12+L12+O12+R12 -> 8.513 | U12: =T12*1.9*1000 -> 16174.7
A13: 43535 | B13: 13954.681 | C13: =IF((B13-B12)<0,"0",(B13-B12)) -> 4.732 | D13: =C13*1.9*1000 -> 8990.8 | E13: 2088.734 | F13: =IF((E13-E12)<0,"0",(E13-E12)) -> 1.247 | G13: =F13*1.9*1000 -> 2369.3 | H13: 855.685 | I13: =IF((H13-H12)<0,"0",(H13-H12)) -> 0.056 | J13: =I13*1.9*1000 -> 106.4 | K13: 12671.29 | L13: =IF((K13-K12)<0,"0",(K13-K12)) -> 0.59 | M13: =L13*1.9*1000 -> 1121 | N13: 1715.465 | O13: =IF((N13-N12)<0,"0",(N13-N12)) -> 1.192 | P13: =O13*1.9*1000 -> 2264.8 | Q13: 3838.62 | R13: =IF((Q13-Q12)<0,"0",(Q13-Q12)) -> 0 | S13: =R13*1.9*1000 -> 0 | T13: =C13+F13+I13+L13+O13+R13 -> 7.817 | U13: =T13*1.9*1000 -> 14852.3
A14: 43536 | B14: 13959.543 | C14: =IF((B14-B13)<0,"0",(B14-B13)) -> 4.862 | D14: =C14*1.9*1000 -> 9237.8 | E14: 2089.9 | F14: =IF((E14-E13)<0,"0",(E14-E13)) -> 1.166 | G14: =F14*1.9*1000 -> 2215.4 | H14: 855.686 | I14: =IF((H14-H13)<0,"0",(H14-H13)) -> 0.001 | J14: =I14*1.9*1000 -> 1.9 | K14: 12672.33 | L14: =IF((K14-K13)<0,"0",(K14-K13)) -> 1.04 | M14: =L14*1.9*1000 -> 1976 | N14: 1716.635 | O14: =IF((N14-N13)<0,"0",(N14-N13)) -> 1.17 | P14: =O14*1.9*1000 -> 2223 | Q14: 3838.62 | R14: =IF((Q14-Q13)<0,"0",(Q14-Q13)) -> 0 | S14: =R14*1.9*1000 -> 0 | T14: =C14+F14+I14+L14+O14+R14 -> 8.239 | U14: =T14*1.9*1000 -> 15654.1
... A33: 43555 | B33: 14052.22 | C33: =IF((B33-B32)<0,"0",(B33-B32)) -> 0 | D33: =C33*1.9*1000 -> 0 | E33: 2110.121 | F33: =IF((E33-E32)<0,"0",(E33-E32)) -> 0 | G33: =F33*1.9*1000 -> 0 | H33: 855.773 | I33: =IF((H33-H32)<0,"0",(H33-H32)) -> 0 | J33: =I33*1.9*1000 -> 0 | K33: 12689.35 | L33: =IF((K33-K32)<0,"0",(K33-K32)) -> 0 | M33: =L33*1.9*1000 -> 0 | N33: 1740.251 | O33: =IF((N33-N32)<0,"0",(N33-N32)) -> 0 | P33: =O33*1.9*1000 -> 0 | Q33: 3839.1 | R33: =IF((Q33-Q32)<0,"0",(Q33-Q32)) -> 0 | S33: =R33*1.9*1000 -> 0 | T33: =C33+F33+I33+L33+O33+R33 -> 0 | U33: =T33*1.9*1000 -> 0
C34: =SUM(C3:C33) -> 147.301 | D34: =SUM(D3:D33) -> 279871.9 | F34: =SUM(F3:F33) -> 30.412 | G34: =SUM(G2:G33) -> 57782.8 | I34: =SUM(I3:I33) -> 0.327 | J34: =SUM(J2:J33) -> 621.3 | L34: =SUM(L3:L33) -> 20.43 | M34: =SUM(M2:M33) -> 38817 | O34: =SUM(O3:O33) -> 35.565 | P34: =SUM(P2:P33) -> 67573.5 | R34: =SUM(R3:R33) -> 2.84 | S34: =SUM(S2:S33) -> 5396 | T34: =SUM(T2:T33) -> 236.875 | U34: =SUM(U3:U33) -> 450062.5

Sheet Energy Monthly statment
A1: Energy Monthly Statement Mar . 2019
B2: Plant room | C2: =K8+K9+K14 -> 356428 | D2: =C2*1.15 -> 409892.2 | H2: Electric
H3: Feeder 1 | I3: =ELECT.!E3 -> 16039765 | J3: =ELECT.!E34 -> 16372454 | K3: =J3-I3 -> 332689
B4: With out Plant room | C4: Kwh | D4: LE | H4: Feeder 2 | I4: =ELECT.!G3 -> 42038210 | J4: =ELECT.!G34 -> 43524507 | K4: =J4-I4 -> 1486297
B5: Hotel | C5: =(K10+K12)*0.842284+K26 -> 1003122.9 | D5: =C5*1.15 -> 1153591.4 | H5: Total | K5: =K3+K4 -> 1818986
B6: Plaza | C6: =(K10+K12+K26)*0.1488 -> 176407.31 | D6: =C6*1.15 -> 202868.41 | H6: Tr1 | I6: =ELECT.!J3 -> 3573765 | J6: =ELECT.!J34 -> 3720138 | K6: =J6-I6 -> 146373
