Workbook

Sheet Total
A1: Site Name | B1: Day | C1: Month | D1: Year | E1: Total Electricity Kwh | F1: Electricity Tariff ($/Kwh) | G1: LPG (Kg) | H1: LPG $/Kg | I1: Water Utility Supply (m3) m3 | J1: Water Utility Supply (m3) $/m3 | K1: Room Nights | L1: Utilities day cost dh
A2: Serengeti | B2: 1 | C2: 2 | D2: 2020 | E2: ='UTILITY REPORT 1'!F3 -> 4580 | F2: =('UTILITY REPORT 1'!E3*'UTILITY REPORT 1'!D3)/'UTILITY REPORT 1'!F3 -> 0.39841703 | G2: =IF('Utility summery'!M6<0,"0",'Utility summery'!M6) -> 94.512 | H2: 0 | I2: =IF('UTILITY REPORT 1'!G3<0,"0",'UTILITY REPORT 1'!G3) -> 113 | J2: 0 | K2: ='UTILITY REPORT 1'!C3 -> 18 | L2: =E2*F2+G2*H2+#REF!*#REF!+I2*J2 -> #REF!
A3: Serengeti | B3: =B2+1 -> 2 | C3: 2 | D3: 2020 | E3: ='UTILITY REPORT 1'!F4 -> 4303 | F3: =('UTILITY REPORT 1'!E4*'UTILITY REPORT 1'!D4)/'UTILITY REPORT 1'!F4 -> 0.41897513 | G3: =IF('Utility summery'!M7<0,"0",'Utility summery'!M7) -> 104.632 | H3: 0 | I3: =IF('UTILITY REPORT 1'!G4<0,"0",'UTILITY REPORT 1'!G4) -> 97 | J3: 0 | K3: ='UTILITY REPORT 1'!C4 -> 18 | L3: =E3*F3+G3*H3+#REF!*#REF!+I3*J3 -> #REF!
A4: Serengeti | B4: =B3+1 -> 3 | C4: 2 | D4: 2020 | E4: ='UTILITY REPORT 1'!F5 -> 4514 | F4: =('UTILITY REPORT 1'!E5*'UTILITY REPORT 1'!D5)/'UTILITY REPORT 1'!F5 -> 0.42554719 | G4: =IF('Utility summery'!M8<0,"0",'Utility summery'!M8) -> 0 | H4: 0 | I4: =IF('UTILITY REPORT 1'!G5<0,"0",'UTILITY REPORT 1'!G5) -> 107 | J4: 0 | K4: ='UTILITY REPORT 1'!C5 -> 8 | L4: =E4*F4+G4*H4+#REF!*#REF!+I4*J4 -> #REF!
A5: Serengeti | B5: =B4+1 -> 4 | C5: 2 | D5: 2020 | E5: ='UTILITY REPORT 1'!F6 -> 5690 | F5: =('UTILITY REPORT 1'!E6*'UTILITY REPORT 1'!D6)/'UTILITY REPORT 1'!F6 -> 0.41460808 | G5: =IF('Utility summery'!M9<0,"0",'Utility summery'!M9) -> 112.728 | H5: 0 | I5: =IF('UTILITY REPORT 1'!G6<0,"0",'UTILITY REPORT 1'!G6) -> 139 | J5: 0 | K5: ='UTILITY REPORT 1'!C6 -> 77 | L5: =E5*F5+G5*H5+#REF!*#REF!+I5*J5 -> #REF!
A6: Serengeti | B6: =B5+1 -> 5 | C6: 2 | D6: 2020 | E6: ='UTILITY REPORT 1'!F7 -> 5866 | F6: =('UTILITY REPORT 1'!E7*'UTILITY REPORT 1'!D7)/'UTILITY REPORT 1'!F7 -> 0.3847136 | G6: =IF('Utility summery'!M10<0,"0",'Utility summery'!M10) -> 106.92 | H6: 0 | I6: =IF('UTILITY REPORT 1'!G7<0,"0",'UTILITY REPORT 1'!G7) -> 141 | J6: 0 | K6: ='UTILITY REPORT 1'!C7 -> 77 | L6: =E6*F6+G6*H6+#REF!*#REF!+I6*J6 -> #REF!
A7: Serengeti | B7: =B6+1 -> 6 | C7: 2 | D7: 2020 | E7: ='UTILITY REPORT 1'!F8 -> 5875 | F7: =('UTILITY REPORT 1'!E8*'UTILITY REPORT 1'!D8)/'UTILITY REPORT 1'!F8 -> 0.42408681 | G7: =IF('Utility summery'!M11<0,"0",'Utility summery'!M11) -> 102.124 | H7: 0 | I7: =IF('UTILITY REPORT 1'!G8<0,"0",'UTILITY REPORT 1'!G8) -> 129 | J7: 0 | K7: ='UTILITY REPORT 1'!C8 -> 77 | L7: =E7*F7+G7*H7+#REF!*#REF!+I7*J7 -> #REF!
A8: Serengeti | B8: =B7+1 -> 7 | C8: 2 | D8: 2020 | E8: ='UTILITY REPORT 1'!F9 -> 5952 | F8: =('UTILITY REPORT 1'!E9*'UTILITY REPORT 1'!D9)/'UTILITY REPORT 1'!F9 -> 0.37714046 | G8: =IF('Utility summery'!M12<0,"0",'Utility summery'!M12) -> 108.196 | H8: 0 | I8: =IF('UTILITY REPORT 1'!G9<0,"0",'UTILITY REPORT 1'!G9) -> 129 | J8: 0 | K8: ='UTILITY REPORT 1'!C9 -> 77 | L8: =E8*F8+G8*H8+#REF!*#REF!+I8*J8 -> #REF!
A9: Serengeti | B9: =B8+1 -> 8 | C9: 2 | D9: 2020 | E9: ='UTILITY REPORT 1'!F10 -> 5988 | F9: =('UTILITY REPORT 1'!E10*'UTILITY REPORT 1'!D10)/'UTILITY REPORT 1'!F10 -> 0.42909987 | G9: =IF('Utility summery'!M13<0,"0",'Utility summery'!M13) -> 112.156 | H9: 0 | I9: =IF('UTILITY REPORT 1'!G10<0,"0",'UTILITY REPORT 1'!G10) -> 128 | J9: 0 | K9: ='UTILITY REPORT 1'!C10 -> 13 | L9: =E9*F9+G9*H9+#REF!*#REF!+I9*J9 -> #REF!
A10: Serengeti | B10: =B9+1 -> 9 | C10: 2 | D10: 2020 | E10: ='UTILITY REPORT 1'!F11 -> 5209 | F10: =('UTILITY REPORT 1'!E11*'UTILITY REPORT 1'!D11)/'UTILITY REPORT 1'!F11 -> 0.39159532 | G10: =IF('Utility summery'!M14<0,"0",'Utility summery'!M14) -> 103.444 | H10: 0 | I10: =IF('UTILITY REPORT 1'!G11<0,"0",'UTILITY REPORT 1'!G11) -> 96 | J10: 0 | K10: ='UTILITY REPORT 1'!C11 -> 16 | L10: =E10*F10+G10*H10+#REF!*#REF!+I10*J10 -> #REF!
A11: Serengeti | B11: =B10+1 -> 10 | C11: 2 | D11: 2020 | E11: ='UTILITY REPORT 1'!F12 -> 0 | F11: =('UTILITY REPORT 1'!E12*'UTILITY REPORT 1'!D12)/'UTILITY REPORT 1'!F12 -> #DIV/0! | G11: =IF('Utility summery'!M15<0,"0",'Utility summery'!M15) -> 0 | H11: 0 | I11: =IF('UTILITY REPORT 1'!G12<0,"0",'UTILITY REPORT 1'!G12) -> 0 | J11: 0 | K11: ='UTILITY REPORT 1'!C12 -> 15 | L11: =E11*F11+G11*H11+#REF!*#REF!+I11*J11 -> #DIV/0!
A12: Serengeti | B12: =B11+1 -> 11 | C12: 2 | D12: 2020 | E12: ='UTILITY REPORT 1'!F13 -> 0 | F12: =('UTILITY REPORT 1'!E13*'UTILITY REPORT 1'!D13)/'UTILITY REPORT 1'!F13 -> #DIV/0! | G12: =IF('Utility summery'!M16<0,"0",'Utility summery'!M16) -> 0 | H12: 0 | I12: =IF('UTILITY REPORT 1'!G13<0,"0",'UTILITY REPORT 1'!G13) -> 0 | J12: 0 | K12: ='UTILITY REPORT 1'!C13 -> 0 | L12: =E12*F12+G12*H12+#REF!*#REF!+I12*J12 -> #DIV/0!
A13: Serengeti | B13: =B12+1 -> 12 | C13: 2 | D13: 2020 | E13: ='UTILITY REPORT 1'!F14 -> 0 | F13: =('UTILITY REPORT 1'!E14*'UTILITY REPORT 1'!D14)/'UTILITY REPORT 1'!F14 -> #DIV/0! | G13: =IF('Utility summery'!M17<0,"0",'Utility summery'!M17) -> 0 | H13: 0 | I13: =IF('UTILITY REPORT 1'!G14<0,"0",'UTILITY REPORT 1'!G14) -> 0 | J13: 0 | K13: ='UTILITY REPORT 1'!C14 -> 0 | L13: =E13*F13+G13*H13+#REF!*#REF!+I13*J13 -> #DIV/0!
A14: Serengeti | B14: =B13+1 -> 13 | C14: 2 | D14: 2020 | E14: ='UTILITY REPORT 1'!F15 -> 0 | F14: =('UTILITY REPORT 1'!E15*'UTILITY REPORT 1'!D15)/'UTILITY REPORT 1'!F15 -> #DIV/0! | G14: =IF('Utility summery'!M18<0,"0",'Utility summery'!M18) -> 0 | H14: 0 | I14: =IF('UTILITY REPORT 1'!G15<0,"0",'UTILITY REPORT 1'!G15) -> 0 | J14: 0 | K14: ='UTILITY REPORT 1'!C15 -> 0 | L14: =E14*F14+G14*H14+#REF!*#REF!+I14*J14 -> #DIV/0!
... A30: Serengeti | B30: =B29+1 -> 29 | C30: 2 | D30: 2020 | E30: ='UTILITY REPORT 1'!F31 -> 0 | F30: =('UTILITY REPORT 1'!E31*'UTILITY REPORT 1'!D31)/'UTILITY REPORT 1'!F31 -> #DIV/0! | G30: =IF('Utility summery'!M34<0,"0",'Utility summery'!M34) -> 0 | H30: 0 | I30: =IF('UTILITY REPORT 1'!G31<0,"0",'UTILITY REPORT 1'!G31) -> 0 | J30: 0 | K30: ='UTILITY REPORT 1'!C31 -> 0 | L30: =E30*F30+G30*H30+#REF!*#REF!+I30*J30 -> #DIV/0!
A31: Serengeti | B31: 1 | C31: 3 | D31: 2020 | E31: ='UTILITY REPORT 1'!F32 -> 0 | F31: =('UTILITY REPORT 1'!E32*'UTILITY REPORT 1'!D32)/'UTILITY REPORT 1'!F32 -> #DIV/0! | G31: =IF('Utility summery'!M35<0,"0",'Utility summery'!M35) -> 0 | H31: 0 | I31: =IF('UTILITY REPORT 1'!G32<0,"0",'UTILITY REPORT 1'!G32) -> 0 | J31: 0 | K31: ='UTILITY REPORT 1'!C32 -> 0 | L31: =E31*F31+G31*H31+#REF!*#REF!+I31*J31 -> #DIV/0!
A32: Serengeti | B32: 2 | C32: 3 | D32: 2020 | E32: ='UTILITY REPORT 1'!F33 -> 0 | F32: =('UTILITY REPORT 1'!E33*'UTILITY REPORT 1'!D33)/'UTILITY REPORT 1'!F33 -> #DIV/0! | G32: =IF('Utility summery'!M36<0,"0",'Utility summery'!M36) -> 0 | H32: 0 | I32: =IF('UTILITY REPORT 1'!G33<0,"0",'UTILITY REPORT 1'!G33) -> 0 | J32: 0 | K32: ='UTILITY REPORT 1'!C33 -> 0

Sheet Submetering
A1: Site Name | B1: Day | C1: Month | D1: Year | E1: Transport Consumption (LT) | F1: Generators Consumption (LT) | G1: Total Electricity Kwh | H1: Kitchen (KWh) | I1: Laundry (KWh) | J1: STP (M3) | K1: RO prodution (M3) | L1: Amani Restaurant (M3) | M1: Kitchen (M3) | N1: Laundry (M3) | O1: Laundry (M3) | P1: Total water Consumption (M3) | Q1: Borehole #1 (M3) | R1: Borehole #2 (M3) | S1: Borehole #3 (M3) | T1: Borehole #4 (M3) | U1: Borehole #5 (M3) | V1: Borehole #6 (M3) | W1: Total Bore holes production (M3) | X1: Room Nights
A2: Serengeti | B2: 1 | C2: 2 | D2: 2020 | E2: ='UTILITY REPORT 1'!I3 -> 83.21 | F2: ='UTILITY REPORT 1'!E3 -> 1824.75 | G2: ='UTILITY REPORT 1'!F3 -> 4580 | H2: =IF('Kit report'!F4<0,"0",'Kit report'!F4) -> 444 | I2: =IF('Kit report'!X4<0,"0",'Kit report'!X4) -> 700 | J2: =IF('Utility summery'!H6<0,"0",'Utility summery'!H6) -> 53 | K2: =IF('UTILITY REPORT 1'!H3<0,"0",'UTILITY REPORT 1'!H3) -> 115 | L2: ='Water-Meter'!K6 -> 3 | M2: ='Water-Meter'!H6 -> 0 | N2: ='Water-Meter'!Q6 -> 9 | O2: =K2*E2+H2*I2+#REF!*#REF!+J2*L2 -> #REF! | P2: ='Water-Meter'!E6 -> 113 | Q2: =IF('Water-Meter'!U6<0,"0",'Water-Meter'!U6) -> 49 | R2: =IF('Water-Meter'!X6<0,"0",'Water-Meter'!X6) -> 62 | S2: =IF('Water-Meter'!AA6<0,"0",'Water-Meter'!AA6) -> 50 | T2: =IF('Water-Meter'!AD6<0,"0",'Water-Meter'!AD6) -> 15 | U2: =IF('Water-Meter'!AG6<0,"0",'Water-Meter'!AG6) -> 24 | V2: =IF('Water-Meter'!AJ6<0,"0",'Water-Meter'!AJ6) -> 0 | W2: ='Water-Meter'!AN6 -> 200 | X2: =Total!K2 -> 18
A3: Serengeti | B3: =B2+1 -> 2 | C3: 2 | D3: 2020 | E3: ='UTILITY REPORT 1'!I4 -> 130.39 | F3: ='UTILITY REPORT 1'!E4 -> 1802.85 | G3: ='UTILITY REPORT 1'!F4 -> 4303 | H3: =IF('Kit report'!F5<0,"0",'Kit report'!F5) -> 468 | I3: =IF('Kit report'!X5<0,"0",'Kit report'!X5) -> 700 | J3: =IF('Utility summery'!H7<0,"0",'Utility summery'!H7) -> 63 | K3: =IF('UTILITY REPORT 1'!H4<0,"0",'UTILITY REPORT 1'!H4) -> 101 | L3: ='Water-Meter'!K7 -> 2 | M3: ='Water-Meter'!H7 -> 0 | N3: ='Water-Meter'!Q7 -> 8 | O3: =K3*E3+H3*I3+#REF!*#REF!+J3*L3 -> #REF! | P3: ='Water-Meter'!E7 -> 97 | Q3: =IF('Water-Meter'!U7<0,"0",'Water-Meter'!U7) -> 19 | R3: =IF('Water-Meter'!X7<0,"0",'Water-Meter'!X7) -> 30 | S3: =IF('Water-Meter'!AA7<0,"0",'Water-Meter'!AA7) -> 50 | T3: =IF('Water-Meter'!AD7<0,"0",'Water-Meter'!AD7) -> 16 | U3: =IF('Water-Meter'!AG7<0,"0",'Water-Meter'!AG7) -> 25 | V3: =IF('Water-Meter'!AJ7<0,"0",'Water-Meter'!AJ7) -> 0 | W3: ='Water-Meter'!AN7 -> 140 | X3: =Total!K3 -> 18
A4: Serengeti | B4: =B3+1 -> 3 | C4: 2 | D4: 2020 | E4: ='UTILITY REPORT 1'!I5 -> 178.75 | F4: ='UTILITY REPORT 1'!E5 -> 1920.92 | G4: ='UTILITY REPORT 1'!F5 -> 4514 | H4: =IF('Kit report'!F6<0,"0",'Kit report'!F6) -> 516 | I4: =IF('Kit report'!X6<0,"0",'Kit report'!X6) -> 960 | J4: =IF('Utility summery'!H8<0,"0",'Utility summery'!H8) -> 60 | K4: =IF('UTILITY REPORT 1'!H5<0,"0",'UTILITY REPORT 1'!H5) -> 81 | L4: ='Water-Meter'!K8 -> 3 | M4: ='Water-Meter'!H8 -> 0 | N4: ='Water-Meter'!Q8 -> 10 | O4: =K4*E4+H4*I4+#REF!*#REF!+J4*L4 -> #REF! | P4: ='Water-Meter'!E8 -> 107 | Q4: =IF('Water-Meter'!U8<0,"0",'Water-Meter'!U8) -> 0 | R4: =IF('Water-Meter'!X8<0,"0",'Water-Meter'!X8) -> 0 | S4: =IF('Water-Meter'!AA8<0,"0",'Water-Meter'!AA8) -> 50 | T4: =IF('Water-Meter'!AD8<0,"0",'Water-Meter'!AD8) -> 17 | U4: =IF('Water-Meter'!AG8<0,"0",'Water-Meter'!AG8) -> 26 | V4: =IF('Water-Meter'!AJ8<0,"0",'Water-Meter'!AJ8) -> 0 | W4: ='Water-Meter'!AN8 -> 93 | X4: =Total!K4 -> 8
A5: Serengeti | B5: =B4+1 -> 4 | C5: 2 | D5: 2020 | E5: ='UTILITY REPORT 1'!I6 -> 89.65 | F5: ='UTILITY REPORT 1'!E6 -> 2359.12 | G5: ='UTILITY REPORT 1'!F6 -> 5690 | H5: =IF('Kit report'!F7<0,"0",'Kit report'!F7) -> 492 | I5: =IF('Kit report'!X7<0,"0",'Kit report'!X7) -> 1060 | J5: =IF('Utility summery'!H9<0,"0",'Utility summery'!H9) -> 63 | K5: =IF('UTILITY REPORT 1'!H6<0,"0",'UTILITY REPORT 1'!H6) -> 100 | L5: ='Water-Meter'!K9 -> 4 | M5: ='Water-Meter'!H9 -> 0 | N5: ='Water-Meter'!Q9 -> 5 | O5: =K5*E5+H5*I5+#REF!*#REF!+J5*L5 -> #REF! | P5: ='Water-Meter'!E9 -> 139 | Q5: =IF('Water-Meter'!U9<0,"0",'Water-Meter'!U9) -> 0 | R5: =IF('Water-Meter'!X9<0,"0",'Water-Meter'!X9) -> 0 | S5: =IF('Water-Meter'!AA9<0,"0",'Water-Meter'!AA9) -> 52 | T5: =IF('Water-Meter'!AD9<0,"0",'Water-Meter'!AD9) -> 17 | U5: =IF('Water-Meter'!AG9<0,"0",'Water-Meter'!AG9) -> 25 | V5: =IF('Water-Meter'!AJ9<0,"0",'Water-Meter'!AJ9) -> 0 | W5: ='Water-Meter'!AN9 -> 94 | X5: =Total!K5 -> 77
A6: Serengeti | B6: =B5+1 -> 5 | C6: 2 | D6: 2020 | E6: ='UTILITY REPORT 1'!I7 -> 129.27 | F6: ='UTILITY REPORT 1'!E7 -> 2256.73 | G6: ='UTILITY REPORT 1'!F7 -> 5866 | H6: =IF('Kit report'!F8<0,"0",'Kit report'!F8) -> 552 | I6: =IF('Kit report'!X8<0,"0",'Kit report'!X8) -> 840 | J6: =IF('Utility summery'!H10<0,"0",'Utility summery'!H10) -> 63 | K6: =IF('UTILITY REPORT 1'!H7<0,"0",'UTILITY REPORT 1'!H7) -> 98 | L6: ='Water-Meter'!K10 -> 5 | M6: ='Water-Meter'!H10 -> 0 | N6: ='Water-Meter'!Q10 -> 4 | O6: =K6*E6+H6*I6+#REF!*#REF!+J6*L6 -> #REF! | P6: ='Water-Meter'!E10 -> 141 | Q6: =IF('Water-Meter'!U10<0,"0",'Water-Meter'!U10) -> 49 | R6: =IF('Water-Meter'!X10<0,"0",'Water-Meter'!X10) -> 55 | S6: =IF('Water-Meter'!AA10<0,"0",'Water-Meter'!AA10) -> 39 | T6: =IF('Water-Meter'!AD10<0,"0",'Water-Meter'!AD10) -> 12 | U6: =IF('Water-Meter'!AG10<0,"0",'Water-Meter'!AG10) -> 23 | V6: =IF('Water-Meter'!AJ10<0,"0",'Water-Meter'!AJ10) -> 0 | W6: ='Water-Meter'!AN10 -> 178 | X6: =Total!K6 -> 77
A7: Serengeti | B7: =B6+1 -> 6 | C7: 2 | D7: 2020 | E7: ='UTILITY REPORT 1'!I8 -> 187.64 | F7: ='UTILITY REPORT 1'!E8 -> 2491.51 | G7: ='UTILITY REPORT 1'!F8 -> 5875 | H7: =IF('Kit report'!F9<0,"0",'Kit report'!F9) -> 540 | I7: =IF('Kit report'!X9<0,"0",'Kit report'!X9) -> 1060 | J7: =IF('Utility summery'!H11<0,"0",'Utility summery'!H11) -> 56 | K7: =IF('UTILITY REPORT 1'!H8<0,"0",'UTILITY REPORT 1'!H8) -> 83 | L7: ='Water-Meter'!K11 -> 4 | M7: ='Water-Meter'!H11 -> 0 | N7: ='Water-Meter'!Q11 -> 15 | O7: =K7*E7+H7*I7+#REF!*#REF!+J7*L7 -> #REF! | P7: ='Water-Meter'!E11 -> 129 | Q7: =IF('Water-Meter'!U11<0,"0",'Water-Meter'!U11) -> 53 | R7: =IF('Water-Meter'!X11<0,"0",'Water-Meter'!X11) -> 65 | S7: =IF('Water-Meter'!AA11<0,"0",'Water-Meter'!AA11) -> 33 | T7: =IF('Water-Meter'!AD11<0,"0",'Water-Meter'!AD11) -> 13 | U7: =IF('Water-Meter'!AG11<0,"0",'Water-Meter'!AG11) -> 24 | V7: =IF('Water-Meter'!AJ11<0,"0",'Water-Meter'!AJ11) -> 0 | W7: ='Water-Meter'!AN11 -> 188 | X7: =Total!K7 -> 77
A8: Serengeti | B8: =B7+1 -> 7 | C8: 2 | D8: 2020 | E8: ='UTILITY REPORT 1'!I9 -> 203.15 | F8: ='UTILITY REPORT 1'!E9 -> 2244.74 | G8: ='UTILITY REPORT 1'!F9 -> 5952 | H8: =IF('Kit report'!F10<0,"0",'Kit report'!F10) -> 564 | I8: =IF('Kit report'!X10<0,"0",'Kit report'!X10) -> 1200 | J8: =IF('Utility summery'!H12<0,"0",'Utility summery'!H12) -> 0 | K8: =IF('UTILITY REPORT 1'!H9<0,"0",'UTILITY REPORT 1'!H9) -> 103 | L8: ='Water-Meter'!K12 -> 4 | M8: ='Water-Meter'!H12 -> 0 | N8: ='Water-Meter'!Q12 -> 11 | O8: =K8*E8+H8*I8+#REF!*#REF!+J8*L8 -> #REF! | P8: ='Water-Meter'!E12 -> 129 | Q8: =IF('Water-Meter'!U12<0,"0",'Water-Meter'!U12) -> 52 | R8: =IF('Water-Meter'!X12<0,"0",'Water-Meter'!X12) -> 60 | S8: =IF('Water-Meter'!AA12<0,"0",'Water-Meter'!AA12) -> 30 | T8: =IF('Water-Meter'!AD12<0,"0",'Water-Meter'!AD12) -> 13 | U8: =IF('Water-Meter'!AG12<0,"0",'Water-Meter'!AG12) -> 23 | V8: =IF('Water-Meter'!AJ12<0,"0",'Water-Meter'!AJ12) -> 0 | W8: ='Water-Meter'!AN12 -> 178 | X8: =Total!K8 -> 77
A9: Serengeti | B9: =B8+1 -> 8 | C9: 2 | D9: 2020 | E9: ='UTILITY REPORT 1'!I10 -> 56.74 | F9: ='UTILITY REPORT 1'!E10 -> 2569.45 | G9: ='UTILITY REPORT 1'!F10 -> 5988 | H9: =IF('Kit report'!F11<0,"0",'Kit report'!F11) -> 564 | I9: =IF('Kit report'!X11<0,"0",'Kit report'!X11) -> 1220 | J9: =IF('Utility summery'!H13<0,"0",'Utility summery'!H13) -> 0 | K9: =IF('UTILITY REPORT 1'!H10<0,"0",'UTILITY REPORT 1'!H10) -> 105 | L9: ='Water-Meter'!K13 -> 4 | M9: ='Water-Meter'!H13 -> 0 | N9: ='Water-Meter'!Q13 -> 13 | O9: =K9*E9+H9*I9+#REF!*#REF!+J9*L9 -> #REF! | P9: ='Water-Meter'!E13 -> 128 | Q9: =IF('Water-Meter'!U13<0,"0",'Water-Meter'!U13) -> 53 | R9: =IF('Water-Meter'!X13<0,"0",'Water-Meter'!X13) -> 55 | S9: =IF('Water-Meter'!AA13<0,"0",'Water-Meter'!AA13) -> 40 | T9: =IF('Water-Meter'!AD13<0,"0",'Water-Meter'!AD13) -> 14 | U9: =IF('Water-Meter'!AG13<0,"0",'Water-Meter'!AG13) -> 22 | V9: =IF('Water-Meter'!AJ13<0,"0",'Water-Meter'!AJ13) -> 0 | W9: ='Water-Meter'!AN13 -> 184 | X9: =Total!K9 -> 13
A10: Serengeti | B10: =B9+1 -> 9 | C10: 2 | D10: 2020 | E10: ='UTILITY REPORT 1'!I11 -> 162.68 | F10: ='UTILITY REPORT 1'!E11 -> 2039.82 | G10: ='UTILITY REPORT 1'!F11 -> 5209 | H10: =IF('Kit report'!F12<0,"0",'Kit report'!F12) -> 552 | I10: =IF('Kit report'!X12<0,"0",'Kit report'!X12) -> 1060 | J10: =IF('Utility summery'!H14<0,"0",'Utility summery'!H14) -> 0 | K10: =IF('UTILITY REPORT 1'!H11<0,"0",'UTILITY REPORT 1'!H11) -> 136 | L10: ='Water-Meter'!K14 -> 3 | M10: ='Water-Meter'!H14 -> 0 | N10: ='Water-Meter'!Q14 -> 14 | O10: =K10*E10+H10*I10+#REF!*#REF!+J10*L10 -> #REF! | P10: ='Water-Meter'!E14 -> 96 | Q10: =IF('Water-Meter'!U14<0,"0",'Water-Meter'!U14) -> 55 | R10: =IF('Water-Meter'!X14<0,"0",'Water-Meter'!X14) -> 62 | S10: =IF('Water-Meter'!AA14<0,"0",'Water-Meter'!AA14) -> 78 | T10: =IF('Water-Meter'!AD14<0,"0",'Water-Meter'!AD14) -> 22 | U10: =IF('Water-Meter'!AG14<0,"0",'Water-Meter'!AG14) -> 22 | V10: =IF('Water-Meter'!AJ14<0,"0",'Water-Meter'!AJ14) -> 0 | W10: ='Water-Meter'!AN14 -> 239 | X10: =Total!K10 -> 16
A11: Serengeti | B11: =B10+1 -> 10 | C11: 2 | D11: 2020 | E11: ='UTILITY REPORT 1'!I12 -> 0 | F11: ='UTILITY REPORT 1'!E12 -> 0 | G11: ='UTILITY REPORT 1'!F12 -> 0 | H11: =IF('Kit report'!F13<0,"0",'Kit report'!F13) -> 0 | I11: =IF('Kit report'!X13<0,"0",'Kit report'!X13) -> 0 | J11: =IF('Utility summery'!H15<0,"0",'Utility summery'!H15) -> 49 | K11: =IF('UTILITY REPORT 1'!H12<0,"0",'UTILITY REPORT 1'!H12) -> 121 | L11: ='Water-Meter'!K15 -> 0 | M11: ='Water-Meter'!H15 -> 0 | N11: ='Water-Meter'!Q15 -> 0 | O11: =K11*E11+H11*I11+#REF!*#REF!+J11*L11 -> #REF! | P11: ='Water-Meter'!E15 -> 0 | Q11: =IF('Water-Meter'!U15<0,"0",'Water-Meter'!U15) -> 0 | R11: =IF('Water-Meter'!X15<0,"0",'Water-Meter'!X15) -> 0 | S11: =IF('Water-Meter'!AA15<0,"0",'Water-Meter'!AA15) -> 0 | T11: =IF('Water-Meter'!AD15<0,"0",'Water-Meter'!AD15) -> 0 | U11: =IF('Water-Meter'!AG15<0,"0",'Water-Meter'!AG15) -> 0 | V11: =IF('Water-Meter'!AJ15<0,"0",'Water-Meter'!AJ15) -> 0 | W11: ='Water-Meter'!AN15 -> 0 | X11: =Total!K11 -> 15
A12: Serengeti | B12: =B11+1 -> 11 | C12: 2 | D12: 2020 | E12: ='UTILITY REPORT 1'!I13 -> 0 | F12: ='UTILITY REPORT 1'!E13 -> 0 | G12: ='UTILITY REPORT 1'!F13 -> 0 | H12: =IF('Kit report'!F14<0,"0",'Kit report'!F14) -> 0 | I12: =IF('Kit report'!X14<0,"0",'Kit report'!X14) -> 0 | J12: =IF('Utility summery'!H16<0,"0",'Utility summery'!H16) -> 0 | K12: =IF('UTILITY REPORT 1'!H13<0,"0",'UTILITY REPORT 1'!H13) -> 0 | L12: ='Water-Meter'!K16 -> 0 | M12: ='Water-Meter'!H16 -> 0 | N12: ='Water-Meter'!Q16 -> 0 | O12: =K12*E12+H12*I12+#REF!*#REF!+J12*L12 -> #REF! | P12: ='Water-Meter'!E16 -> 0 | Q12: =IF('Water-Meter'!U16<0,"0",'Water-Meter'!U16) -> 0 | R12: =IF('Water-Meter'!X16<0,"0",'Water-Meter'!X16) -> 0 | S12: =IF('Water-Meter'!AA16<0,"0",'Water-Meter'!AA16) -> 0 | T12: =IF('Water-Meter'!AD16<0,"0",'Water-Meter'!AD16) -> 0 | U12: =IF('Water-Meter'!AG16<0,"0",'Water-Meter'!AG16) -> 0 | V12: =IF('Water-Meter'!AJ16<0,"0",'Water-Meter'!AJ16) -> 0 | W12: ='Water-Meter'!AN16 -> 0 | X12: =Total!K12 -> 0
A13: Serengeti | B13: =B12+1 -> 12 | C13: 2 | D13: 2020 | E13: ='UTILITY REPORT 1'!I14 -> 0 | F13: ='UTILITY REPORT 1'!E14 -> 0 | G13: ='UTILITY REPORT 1'!F14 -> 0 | H13: =IF('Kit report'!F15<0,"0",'Kit report'!F15) -> 0 | I13: =IF('Kit report'!X15<0,"0",'Kit report'!X15) -> 0 | J13: =IF('Utility summery'!H17<0,"0",'Utility summery'!H17) -> 0 | K13: =IF('UTILITY REPORT 1'!H14<0,"0",'UTILITY REPORT 1'!H14) -> 0 | L13: ='Water-Meter'!K17 -> 0 | M13: ='Water-Meter'!H17 -> 0 | N13: ='Water-Meter'!Q17 -> 0 | O13: =K13*E13+H13*I13+#REF!*#REF!+J13*L13 -> #REF! | P13: ='Water-Meter'!E17 -> 0 | Q13: =IF('Water-Meter'!U17<0,"0",'Water-Meter'!U17) -> 0 | R13: =IF('Water-Meter'!X17<0,"0",'Water-Meter'!X17) -> 0 | S13: =IF('Water-Meter'!AA17<0,"0",'Water-Meter'!AA17) -> 0 | T13: =IF('Water-Meter'!AD17<0,"0",'Water-Meter'!AD17) -> 0 | U13: =IF('Water-Meter'!AG17<0,"0",'Water-Meter'!AG17) -> 0 | V13: =IF('Water-Meter'!AJ17<0,"0",'Water-Meter'!AJ17) -> 0 | W13: ='Water-Meter'!AN17 -> 0 | X13: =Total!K13 -> 0
A14: Serengeti | B14: =B13+1 -> 13 | C14: 2 | D14: 2020 | E14: ='UTILITY REPORT 1'!I15 -> 0 | F14: ='UTILITY REPORT 1'!E15 -> 0 | G14: ='UTILITY REPORT 1'!F15 -> 0 | H14: =IF('Kit report'!F16<0,"0",'Kit report'!F16) -> 0 | I14: =IF('Kit report'!X16<0,"0",'Kit report'!X16) -> 0 | J14: =IF('Utility summery'!H18<0,"0",'Utility summery'!H18) -> 0 | K14: =IF('UTILITY REPORT 1'!H15<0,"0",'UTILITY REPORT 1'!H15) -> 0 | L14: ='Water-Meter'!K18 -> 0 | M14: ='Water-Meter'!H18 -> 0 | N14: ='Water-Meter'!Q18 -> 0 | O14: =K14*E14+H14*I14+#REF!*#REF!+J14*L14 -> #REF! | P14: ='Water-Meter'!E18 -> 0 | Q14: =IF('Water-Meter'!U18<0,"0",'Water-Meter'!U18) -> 0 | R14: =IF('Water-Meter'!X18<0,"0",'Water-Meter'!X18) -> 0 | S14: =IF('Water-Meter'!AA18<0,"0",'Water-Meter'!AA18) -> 0 | T14: =IF('Water-Meter'!AD18<0,"0",'Water-Meter'!AD18) -> 0 | U14: =IF('Water-Meter'!AG18<0,"0",'Water-Meter'!AG18) -> 0 | V14: =IF('Water-Meter'!AJ18<0,"0",'Water-Meter'!AJ18) -> 0 | W14: ='Water-Meter'!AN18 -> 0 | X14: =Total!K14 -> 0
... A30: Serengeti | B30: =B29+1 -> 29 | C30: 2 | D30: 2020 | E30: ='UTILITY REPORT 1'!I31 -> 0 | F30: ='UTILITY REPORT 1'!E31 -> 0 | G30: ='UTILITY REPORT 1'!F31 -> 0 | H30: =IF('Kit report'!F32<0,"0",'Kit report'!F32) -> 0 | I30: =IF('Kit report'!X32<0,"0",'Kit report'!X32) -> 0 | J30: =IF('Utility summery'!H34<0,"0",'Utility summery'!H34) -> 0 | K30: =IF('UTILITY REPORT 1'!H31<0,"0",'UTILITY REPORT 1'!H31) -> 0 | L30: ='Water-Meter'!K34 -> 0 | M30: ='Water-Meter'!H34 -> 0 | N30: ='Water-Meter'!Q34 -> 0 | O30: =K30*E30+H30*I30+#REF!*#REF!+J30*L30 -> #REF! | P30: ='Water-Meter'!E34 -> 0 | Q30: =IF('Water-Meter'!U34<0,"0",'Water-Meter'!U34) -> 0 | R30: =IF('Water-Meter'!X34<0,"0",'Water-Meter'!X34) -> 0 | S30: =IF('Water-Meter'!AA34<0,"0",'Water-Meter'!AA34) -> 0 | T30: =IF('Water-Meter'!AD34<0,"0",'Water-Meter'!AD34) -> 0 | U30: =IF('Water-Meter'!AG34<0,"0",'Water-Meter'!AG34) -> 0 | V30: =IF('Water-Meter'!AJ34<0,"0",'Water-Meter'!AJ34) -> 0 | W30: ='Water-Meter'!AN34 -> 0 | X30: =Total!K30 -> 0
A31: Serengeti | B31: 1 | C31: 3 | D31: 2020 | E31: ='UTILITY REPORT 1'!I32 -> 0 | F31: ='UTILITY REPORT 1'!E32 -> 0 | G31: ='UTILITY REPORT 1'!F32 -> 0 | H31: =IF('Kit report'!F33<0,"0",'Kit report'!F33) -> 0 | I31: =IF('Kit report'!X33<0,"0",'Kit report'!X33) -> 0 | J31: =IF('Utility summery'!H35<0,"0",'Utility summery'!H35) -> 0 | K31: =IF('UTILITY REPORT 1'!H32<0,"0",'UTILITY REPORT 1'!H32) -> 0 | L31: ='Water-Meter'!K35 -> 0 | M31: ='Water-Meter'!H35 -> 0 | N31: ='Water-Meter'!Q35 -> 0 | O31: =K31*E31+H31*I31+#REF!*#REF!+J31*L31 -> #REF! | P31: ='Water-Meter'!E35 -> 0 | Q31: =IF('Water-Meter'!U35<0,"0",'Water-Meter'!U35) -> 0 | R31: =IF('Water-Meter'!X35<0,"0",'Water-Meter'!X35) -> 0 | S31: =IF('Water-Meter'!AA35<0,"0",'Water-Meter'!AA35) -> 0 | T31: =IF('Water-Meter'!AD35<0,"0",'Water-Meter'!AD35) -> 0 | U31: =IF('Water-Meter'!AG35<0,"0",'Water-Meter'!AG35) -> 0 | V31: =IF('Water-Meter'!AJ35<0,"0",'Water-Meter'!AJ35) -> 0 | W31: ='Water-Meter'!AN35 -> 0 | X31: =Total!K31 -> 0
A32: Serengeti | B32: 2 | C32: 3 | D32: 2020 | E32: ='UTILITY REPORT 1'!I33 -> 0 | F32: ='UTILITY REPORT 1'!E33 -> 0 | G32: ='UTILITY REPORT 1'!F33 -> 0 | H32: =IF('Kit report'!F34<0,"0",'Kit report'!F34) -> 0 | I32: =IF('Kit report'!X34<0,"0",'Kit report'!X34) -> 0 | J32: =IF('Utility summery'!H36<0,"0",'Utility summery'!H36) -> 0 | K32: =IF('UTILITY REPORT 1'!H33<0,"0",'UTILITY REPORT 1'!H33) -> 0 | L32: ='Water-Meter'!K36 -> 0 | M32: ='Water-Meter'!H36 -> 0 | N32: ='Water-Meter'!Q36 -> 0 | P32: ='Water-Meter'!E36 -> 0 | Q32: =IF('Water-Meter'!U36<0,"0",'Water-Meter'!U36) -> 0 | R32: =IF('Water-Meter'!X36<0,"0",'Water-Meter'!X36) -> 0 | S32: =IF('Water-Meter'!AA36<0,"0",'Water-Meter'!AA36) -> 0 | T32: =IF('Water-Meter'!AD36<0,"0",'Water-Meter'!AD36) -> 0 | U32: =IF('Water-Meter'!AG36<0,"0",'Water-Meter'!AG36) -> 0 | V32: =IF('Water-Meter'!AJ36<0,"0",'Water-Meter'!AJ36) -> 0 | W32: ='Water-Meter'!AN36 -> 0 | X32: =Total!K32 -> 0

Sheet UTILITY REPORT 1
A1: NOVEMBER UTILITY REPORT
A2: Date | B2: % | C2: Guest Rooms Occupied | D2: Diesel cost Per Liter ($) | E2: Diesel consumption (LT) | F2: Power production (KW) | G2: Water consumption (M3) | H2: RO prodution (M3) | I2: Transport Consupmtion (LT)
A3: 43862 | B3: =Gen!B11 -> 0.2338 | C3: ='Summery Report'!E5 -> 18 | D3: 1 | E3: =Gen!S11 -> 1824.75 | F3: =Gen!T11 -> 4580 | G3: ='Water-Meter'!E6 -> 113 | H3: ='Utility report '!AC6 -> 115 | I3: =Gen!AJ11 -> 83.21
A4: 43863 | B4: =Gen!B12 -> 0.234 | C4: ='Summery Report'!E6 -> 18 | D4: 1 | E4: =Gen!S12 -> 1802.85 | F4: =Gen!T12 -> 4303 | G4: ='Water-Meter'!E7 -> 97 | H4: ='Utility report '!AC7 -> 101 | I4: =Gen!AJ12 -> 130.39
A5: 43864 | B5: =Gen!B13 -> 0.104 | C5: ='Summery Report'!E7 -> 8 | D5: 1 | E5: =Gen!S13 -> 1920.92 | F5: =Gen!T13 -> 4514 | G5: ='Water-Meter'!E8 -> 107 | H5: ='Utility report '!AC8 -> 81 | I5: =Gen!AJ13 -> 178.75
A6: 43865 | B6: =Gen!B14 -> 1 | C6: ='Summery Report'!E8 -> 77 | D6: 1 | E6: =Gen!S14 -> 2359.12 | F6: =Gen!T14 -> 5690 | G6: ='Water-Meter'!E9 -> 139 | H6: ='Utility report '!AC9 -> 100 | I6: =Gen!AJ14 -> 89.65
A7: 43866 | B7: =Gen!B15 -> 1 | C7: ='Summery Report'!E9 -> 77 | D7: 1 | E7: =Gen!S15 -> 2256.73 | F7: =Gen!T15 -> 5866 | G7: ='Water-Meter'!E10 -> 141 | H7: ='Utility report '!AC10 -> 98 | I7: =Gen!AJ15 -> 129.27
A8: 43867 | B8: =Gen!B16 -> 1 | C8: ='Summery Report'!E10 -> 77 | D8: 1 | E8: =Gen!S16 -> 2491.51 | F8: =Gen!T16 -> 5875 | G8: ='Water-Meter'!E11 -> 129 | H8: ='Utility report '!AC11 -> 83 | I8: =Gen!AJ16 -> 187.64
A9: 43868 | B9: =Gen!B17 -> 1 | C9: ='Summery Report'!E11 -> 77 | D9: 1 | E9: =Gen!S17 -> 2244.74 | F9: =Gen!T17 -> 5952 | G9: ='Water-Meter'!E12 -> 129 | H9: ='Utility report '!AC12 -> 103 | I9: =Gen!AJ17 -> 203.15
A10: 43869 | B10: =Gen!B18 -> 0.1429 | C10: ='Summery Report'!E12 -> 13 | D10: 1 | E10: =Gen!S18 -> 2569.45 | F10: =Gen!T18 -> 5988 | G10: ='Water-Meter'!E13 -> 128 | H10: ='Utility report '!AC13 -> 105 | I10: =Gen!AJ18 -> 56.74
A11: 43870 | B11: =Gen!B19 -> 0.195 | C11: ='Summery Report'!E13 -> 16 | D11: 1 | E11: =Gen!S19 -> 2039.82 | F11: =Gen!T19 -> 5209 | G11: ='Water-Meter'!E14 -> 96 | H11: ='Utility report '!AC14 -> 136 | I11: =Gen!AJ19 -> 162.68
A12: 43871 | B12: =Gen!B20 -> 0.1818 | C12: ='Summery Report'!E14 -> 15 | D12: 1 | E12: =Gen!S20 -> 0 | F12: =Gen!T20 -> 0 | G12: ='Water-Meter'!E15 -> 0 | H12: ='Utility report '!AC15 -> 121 | I12: =Gen!AJ20 -> 0
A13: 43872 | B13: =Gen!B21 -> 0 | C13: ='Summery Report'!E15 -> 0 | D13: 1 | E13: =Gen!S21 -> 0 | F13: =Gen!T21 -> 0 | G13: ='Water-Meter'!E16 -> 0 | H13: ='Utility report '!AC16 -> -24878 | I13: =Gen!AJ21 -> 0
A14: 43873 | B14: =Gen!B22 -> 0 | C14: ='Summery Report'!E16 -> 0 | D14: 1 | E14: =Gen!S22 -> 0 | F14: =Gen!T22 -> 0 | G14: ='Water-Meter'!E17 -> 0 | H14: ='Utility report '!AC17 -> 0 | I14: =Gen!AJ22 -> 0
... A34: 43893 | B34: =Gen!B42 -> 0 | C34: ='Summery Report'!E36 -> 0 | D34: 2 | E34: =Gen!S42 -> 0 | F34: =Gen!T42 -> 0 | G34: ='Water-Meter'!E37 -> 0 | H34: ='Utility report '!AC37 -> 0 | I34: =Gen!AJ42 -> 0

Sheet Utility summery
A4: Date | B4: Room Occupied | C4: Electricity Units Generated KW | D4: Diseal | G4: Water | J4: Gas | N4: Cost of utilites
D5: Generator | E5: Transport | F5: Total | G5: RO | H5: STP | I5: Total Consumption | J5: 2 ton | K5: 1 Ton | L5: 1 Ton | M5: Total consumption | N5: Electricity /1.4$/liter | O5: Diseal for Transport | P5: Gas /2.38$/Kg | Q5: Total HLP Cost | R5: Electricity Cost/Room $ | S5: cost/Room $
A6: =Gen!A11 -> 43862 | B6: ='Summery Report'!E5 -> 18 | C6: =Gen!T11 -> 4580 | D6: =Gen!S11 -> 1824.75 | E6: =Gen!AJ11 -> 83.21 | F6: =Gen!AR11 -> 1907.96 | G6: ='Utility report '!AC6 -> 115 | H6: ='Utility report '!AE6 -> 53 | I6: ='Water-Meter'!E6 -> 113 | J6: ='Lpg (2)'!B10 -> 85 | K6: ='Lpg (2)'!C10 -> 85 | L6: ='Lpg (2)'!D10 -> 18 | M6: ='Lpg (2)'!G10 -> 94.512 | O6: =E6 -> 83.21 | P6: ='[1]Lpg (2)'!#REF! -> #REF! | Q6: ='[1]Summery Report'!#REF! -> #REF! | R6: =N6/B6 -> 0 | S6: =Q6/B6 -> #REF!
A7: =Gen!A12 -> 43863 | B7: ='Summery Report'!E6 -> 18 | C7: =Gen!T12 -> 4303 | D7: =Gen!S12 -> 1802.85 | E7: =Gen!AJ12 -> 130.39 | F7: =Gen!AR12 -> 1933.24 | G7: ='Utility report '!AC7 -> 101 | H7: ='Utility report '!AE7 -> 63 | I7: ='Water-Meter'!E7 -> 97 | J7: ='Lpg (2)'!B11 -> 85 | K7: ='Lpg (2)'!C11 -> 85 | L7: ='Lpg (2)'!D11 -> 10 | M7: ='Lpg (2)'!G11 -> 104.632 | N7: =D7*1.4 -> 2523.99 | O7: =E7*1.4 -> 182.546 | P7: ='[1]Lpg (2)'!#REF! -> #REF! | Q7: ='[1]Summery Report'!#REF! -> #REF! | R7: =N7/B7 -> 140.22167 | S7: =Q7/B7 -> #REF!
A8: =Gen!A13 -> 43864 | B8: ='Summery Report'!E7 -> 8 | C8: =Gen!T13 -> 4514 | D8: =Gen!S13 -> 1920.92 | E8: =Gen!AJ13 -> 178.75 | F8: =Gen!AR13 -> 2099.67 | G8: ='Utility report '!AC8 -> 81 | H8: ='Utility report '!AE8 -> 60 | I8: ='Water-Meter'!E8 -> 107 | J8: ='Lpg (2)'!B12 -> 85 | K8: ='Lpg (2)'!C12 -> 85 | L8: ='Lpg (2)'!D12 -> 7 | M8: ='Lpg (2)'!G12 -> -783.948 | N8: =D8*1.4 -> 2689.288 | O8: =E8*1.4 -> 250.25 | P8: ='[1]Lpg (2)'!#REF! -> #REF! | Q8: ='[1]Summery Report'!#REF! -> #REF! | R8: =N8/B8 -> 336.161 | S8: =Q8/B8 -> #REF!
A9: =Gen!A14 -> 43865 | B9: ='Summery Report'!E8 -> 77 | C9: =Gen!T14 -> 5690 | D9: =Gen!S14 -> 2359.12 | E9: =Gen!AJ14 -> 89.65 | F9: =Gen!AR14 -> 2448.77 | G9: ='Utility report '!AC9 -> 100 | H9: ='Utility report '!AE9 -> 63 | I9: ='Water-Meter'!E9 -> 139 | J9: ='Lpg (2)'!B13 -> 85 | K9: ='Lpg (2)'!C13 -> 85 | L9: ='Lpg (2)'!D13 -> 5 | M9: ='Lpg (2)'!G13 -> 112.728 | N9: =D9*1.4 -> 3302.768 | O9: =E9*1.4 -> 125.51 | P9: ='[1]Lpg (2)'!#REF! -> #REF! | Q9: ='[1]Summery Report'!#REF! -> #REF! | R9: =N9/B9 -> 42.893091 | S9: =Q9/B9 -> #REF!
A10: =Gen!A15 -> 43866 | B10: ='Summery Report'!E9 -> 77 | C10: =Gen!T15 -> 5866 | D10: =Gen!S15 -> 2256.73 | E10: =Gen!AJ15 -> 129.27 | F10: =Gen!AR15 -> 2386 | G10: ='Utility report '!AC10 -> 98 | H10: ='Utility report '!AE10 -> 63 | I10: ='Water-Meter'!E10 -> 141 | J10: ='Lpg (2)'!B14 -> 85 | K10: ='Lpg (2)'!C14 -> 76 | L10: ='Lpg (2)'!D14 -> 0 | M10: ='Lpg (2)'!G14 -> 106.92 | N10: =D10*1.4 -> 3159.422 | O10: =E10*1.4 -> 180.978 | P10: ='[1]Lpg (2)'!#REF! -> #REF! | Q10: ='[1]Summery Report'!#REF! -> #REF! | R10: =N10/B10 -> 41.031455 | S10: =Q10/B10 -> #REF!
A11: =Gen!A16 -> 43867 | B11: ='Summery Report'!E10 -> 77 | C11: =Gen!T16 -> 5875 | D11: =Gen!S16 -> 2491.51 | E11: =Gen!AJ16 -> 187.64 | F11: =Gen!AR16 -> 2679.15 | G11: ='Utility report '!AC11 -> 83 | H11: ='Utility report '!AE11 -> 56 | I11: ='Water-Meter'!E11 -> 129 | J11: ='Lpg (2)'!B15 -> 85 | K11: ='Lpg (2)'!C15 -> 70 | L11: ='Lpg (2)'!D15 -> 0 | M11: ='Lpg (2)'!G15 -> 102.124 | N11: =D11*1.4 -> 3488.114 | O11: =E11*1.4 -> 262.696 | P11: ='[1]Lpg (2)'!#REF! -> #REF! | Q11: ='[1]Summery Report'!#REF! -> #REF! | R11: =N11/B11 -> 45.300182 | S11: =Q11/B11 -> #REF!
A12: =Gen!A17 -> 43868 | B12: ='Summery Report'!E11 -> 77 | C12: =Gen!T17 -> 5952 | D12: =Gen!S17 -> 2244.74 | E12: =Gen!AJ17 -> 203.15 | F12: =Gen!AR17 -> 2447.89 | G12: ='Utility report '!AC12 -> 103 | H12: ='Utility report '!AE12 -> 0 | I12: ='Water-Meter'!E12 -> 129 | J12: ='Lpg (2)'!B16 -> 85 | K12: ='Lpg (2)'!C16 -> 60 | L12: ='Lpg (2)'!D16 -> 0 | M12: ='Lpg (2)'!G16 -> 108.196 | N12: =D12*1.4 -> 3142.636 | O12: =E12*1.4 -> 284.41 | P12: ='[1]Lpg (2)'!#REF! -> #REF! | Q12: ='[1]Summery Report'!#REF! -> #REF! | R12: =N12/B12 -> 40.813455 | S12: =Q12/B12 -> #REF!
A13: =Gen!A18 -> 43869 | B13: ='Summery Report'!E12 -> 13 | C13: =Gen!T18 -> 5988 | D13: =Gen!S18 -> 2569.45 | E13: =Gen!AJ18 -> 56.74 | F13: =Gen!AR18 -> 2626.19 | G13: ='Utility report '!AC13 -> 105 | H13: ='Utility report '!AE13 -> 0 | I13: ='Water-Meter'!E13 -> 128 | J13: ='Lpg (2)'!B17 -> 85 | K13: ='Lpg (2)'!C17 -> 55 | L13: ='Lpg (2)'!D17 -> 0 | M13: ='Lpg (2)'!G17 -> 112.156 | N13: =D13*1.4 -> 3597.23 | O13: =E13*1.4 -> 79.436 | P13: ='[1]Lpg (2)'!#REF! -> #REF! | Q13: ='[1]Summery Report'!#REF! -> #REF! | R13: =N13/B13 -> 276.71 | S13: =Q13/B13 -> #REF!
A14: =Gen!A19 -> 43870 | B14: ='Summery Report'!E13 -> 16 | C14: =Gen!T19 -> 5209 | D14: =Gen!S19 -> 2039.82 | E14: =Gen!AJ19 -> 162.68 | F14: =Gen!AR19 -> 2202.5 | G14: ='Utility report '!AC14 -> 136 | H14: ='Utility report '!AE14 -> 0 | I14: ='Water-Meter'!E14 -> 96 | J14: ='Lpg (2)'!B18 -> 85 | K14: ='Lpg (2)'!C18 -> 49 | L14: ='Lpg (2)'!D18 -> 0 | M14: ='Lpg (2)'!G18 -> 103.444 | N14: =D14*1.4 -> 2855.748 | O14: =E14*1.4 -> 227.752 | P14: ='[1]Lpg (2)'!#REF! -> #REF! | Q14: ='[1]Summery Report'!#REF! -> #REF! | R14: =N14/B14 -> 178.48425 | S14: =Q14/B14 -> #REF!
A15: =Gen!A20 -> 43871 | B15: ='Summery Report'!E14 -> 15 | C15: =Gen!T20 -> 0 | D15: =Gen!S20 -> 0 | E15: =Gen!AJ20 -> 0 | F15: =Gen!AR20 -> 0 | G15: ='Utility report '!AC15 -> 121 | H15: ='Utility report '!AE15 -> 49 | I15: ='Water-Meter'!E15 -> 0 | J15: ='Lpg (2)'!B19 -> 0 | K15: ='Lpg (2)'!C19 -> 0 | L15: ='Lpg (2)'!D19 -> 0 | M15: ='Lpg (2)'!G19 -> -307317.16 | N15: =D15*1.4 -> 0 | O15: =E15*1.4 -> 0 | P15: ='[1]Lpg (2)'!#REF! -> #REF! | Q15: ='[1]Summery Report'!#REF! -> #REF! | R15: =N15/B15 -> 0 | S15: =Q15/B15 -> #REF!
A16: =Gen!A21 -> 43872 | B16: ='Summery Report'!E15 -> 0 | C16: =Gen!T21 -> 0 | D16: =Gen!S21 -> 0 | E16: =Gen!AJ21 -> 0 | F16: =Gen!AR21 -> 0 | G16: ='Utility report '!AC16 -> -24878 | H16: ='Utility report '!AE16 -> -195532 | I16: ='Water-Meter'!E16 -> 0 | J16: ='Lpg (2)'!B20 -> 0 | K16: ='Lpg (2)'!C20 -> 0 | L16: ='Lpg (2)'!D20 -> 0 | M16: ='Lpg (2)'!G20 -> 0 | N16: =D16*1.4 -> 0 | O16: =E16*1.4 -> 0 | P16: ='[1]Lpg (2)'!#REF! -> #REF! | Q16: ='[1]Summery Report'!#REF! -> #REF! | R16: =N16/B16 -> #DIV/0! | S16: =Q16/B16 -> #REF!
A17: =Gen!A22 -> 43873 | B17: ='Summery Report'!E16 -> 0 | C17: =Gen!T22 -> 0 | D17: =Gen!S22 -> 0 | E17: =Gen!AJ22 -> 0 | F17: =Gen!AR22 -> 0 | G17: ='Utility report '!AC17 -> 0 | H17: ='Utility report '!AE17 -> 0 | I17: ='Water-Meter'!E17 -> 0 | J17: ='Lpg (2)'!B21 -> 0 | K17: ='Lpg (2)'!C21 -> 0 | L17: ='Lpg (2)'!D21 -> 0 | M17: ='Lpg (2)'!G21 -> 0 | N17: =D17*1.4 -> 0 | O17: =E17*1.4 -> 0 | P17: ='[1]Lpg (2)'!#REF! -> #REF! | Q17: ='[1]Summery Report'!#REF! -> #REF! | R17: =N17/B17 -> #DIV/0! | S17: =Q17/B17 -> #REF!
A18: =Gen!A23 -> 43874 | B18: ='Summery Report'!E17 -> 0 | C18: =Gen!T23 -> 0 | D18: =Gen!S23 -> 0 | E18: =Gen!AJ23 -> 0 | F18: =Gen!AR23 -> 0 | G18: ='Utility report '!AC18 -> 0 | H18: ='Utility report '!AE18 -> 0 | I18: ='Water-Meter'!E18 -> 0 | J18: ='Lpg (2)'!B22 -> 0 | K18: ='Lpg (2)'!C22 -> 0 | L18: ='Lpg (2)'!D22 -> 0 | M18: ='Lpg (2)'!G22 -> 0 | N18: =D18*1.4 -> 0 | O18: =E18*1.4 -> 0 | P18: ='[1]Lpg (2)'!#REF! -> #REF! | Q18: ='[1]Summery Report'!#REF! -> #REF! | R18: =N18/B18 -> #DIV/0! | S18: =Q18/B18 -> #REF!
... A32: =Gen!A37 -> 43888 | B32: ='Summery Report'!E31 -> 0 | C32: =Gen!T37 -> 0 | D32: =Gen!S37 -> 0 | E32: =Gen!AJ37 -> 0 | F32: =Gen!AR37 -> 0 | G32: ='Utility report '!AC32 -> 0 | H32: ='Utility report '!AE32 -> 0 | I32: ='Water-Meter'!E32 -> 0 | J32: ='Lpg (2)'!B36 -> 0 | K32: ='Lpg (2)'!C36 -> 0 | L32: ='Lpg (2)'!D36 -> 0 | M32: ='Lpg (2)'!G36 -> 0 | N32: =D32*1.4 -> 0 | O32: =E32*1.4 -> 0 | P32: ='[1]Lpg (2)'!#REF! -> #REF! | Q32: ='[1]Summery Report'!#REF! -> #REF! | R32: =N32/B32 -> #DIV/0! | S32: =Q32/B32 -> #REF!
A33: =Gen!A38 -> 43889 | B33: ='Summery Report'!E32 -> 0 | C33: =Gen!T38 -> 0 | D33: =Gen!S38 -> 0 | E33: =Gen!AJ38 -> 0 | F33: =Gen!AR38 -> 0 | G33: ='Utility report '!AC33 -> 0 | H33: ='Utility report '!AE33 -> 0 | I33: ='Water-Meter'!E33 -> 0 | J33: ='Lpg (2)'!B37 -> 0 | K33: ='Lpg (2)'!C37 -> 0 | L33: ='Lpg (2)'!D37 -> 0 | M33: ='Lpg (2)'!G37 -> 0 | N33: =D33*1.4 -> 0 | O33: =E33*1.4 -> 0 | P33: ='[1]Lpg (2)'!#REF! -> #REF! | Q33: ='[1]Summery Report'!#REF! -> #REF! | R33: =N33/B33 -> #DIV/0! | S33: =Q33/B33 -> #REF! | T33: =3124/13 -> 240.30769
A34: =Gen!A39 -> 43890 | B34: ='Summery Report'!E33 -> 0 | C34: =Gen!T39 -> 0 | D34: =Gen!S39 -> 0 | E34: =Gen!AJ39 -> 0 | F34: =Gen!AR39 -> 0 | G34: ='Utility report '!AC34 -> 0 | H34: ='Utility report '!AE34 -> 0 | I34: ='Water-Meter'!E34 -> 0 | J34: ='Lpg (2)'!B38 -> 0 | K34: ='Lpg (2)'!C38 -> 0 | L34: ='Lpg (2)'!D38 -> 0 | M34: ='Lpg (2)'!G38 -> 0 | N34: =D34*1.4 -> 0 | O34: =E34*1.4 -> 0 | P34: ='[1]Lpg (2)'!#REF! -> #REF! | Q34: ='[1]Summery Report'!#REF! -> #REF! | R34: =N34/B34 -> #DIV/0! | S34: =Q34/B34 -> #REF!
A35: =Gen!A40 -> 43891 | B35: ='Summery Report'!E34 -> 0 | C35: =Gen!T40 -> 0 | D35: =Gen!S40 -> 0 | E35: =Gen!AJ40 -> 0 | F35: =Gen!AR40 -> 0 | G35: ='Utility report '!AC35 -> 0 | H35: ='Utility report '!AE35 -> 0 | I35: ='Water-Meter'!E35 -> 0 | J35: ='Lpg (2)'!B39 -> 0 | K35: ='Lpg (2)'!C39 -> 0 | L35: ='Lpg (2)'!D39 -> 0 | M35: ='Lpg (2)'!G39 -> 0 | N35: =D35*1.4 -> 0 | O35: =E35*1.4 -> 0 | P35: ='[1]Lpg (2)'!#REF! -> #REF! | Q35: ='[1]Summery Report'!#REF! -> #REF! | R35: =N35/B35 -> #DIV/0! | S35: =Q35/B35 -> #REF!
A36: =Gen!A41 -> 43892 | B36: ='Summery Report'!E35 -> 0 | C36: =Gen!T41 -> 0 | D36: =Gen!S41 -> 0 | E36: =Gen!AJ41 -> 0 | F36: =Gen!AR41 -> 0 | G36: ='Utility report '!AC36 -> 0 | H36: ='Utility report '!AE36 -> 0 | I36: ='Water-Meter'!E36 -> 0 | J36: ='Lpg (2)'!B40 -> 0 | K36: ='Lpg (2)'!C40 -> 0 | L36: ='Lpg (2)'!D40 -> 0 | M36: ='Lpg (2)'!G40 -> 0 | N36: =D36*1.4 -> 0 | O36: =E36*1.4 -> 0 | P36: ='[1]Lpg (2)'!#REF! -> #REF! | Q36: ='[1]Summery Report'!#REF! -> #REF! | R36: =N36/B36 -> #DIV/0! | S36: =Q36/B36 -> #REF!
A37: =[1]Gen!A42 -> #REF! | B37: ='Summery Report'!E36 -> 0 | C37: =Gen!T42 -> 0 | D37: =Gen!S42 -> 0 | E37: =Gen!AJ42 -> 0 | F37: =Gen!AR42 -> 0 | G37: ='Utility report '!AC37 -> 0 | H37: ='Utility report '!AE37 -> 0 | I37: ='Water-Meter'!E37 -> 0 | J37: ='Lpg (2)'!B41 -> 0 | K37: ='Lpg (2)'!C41 -> 0 | L37: ='Lpg (2)'!D41 -> 0 | M37: ='Lpg (2)'!G41 -> 0 | Q37: ='[1]Summery Report'!#REF! -> #REF! | R37: =N37/B37 -> #DIV/0! | S37: =Q37/B37 -> #REF!
A39: Total | B39: =SUM(B7:B37) -> 378 | C39: =SUM(C7:C35) -> 43397 | D39: =SUM(D7:D35) -> 17685.14 | E39: =SUM(E7:E35) -> 1138.27 | F39: =SUM(F7:F35) -> 18823.41 | G39: =SUM(G7:G35) -> -23950 | H39: =SUM(H7:H35) -> -195178 | I39: =SUM(I7:I35) -> 966 | J39: =SUM(J7:J35) -> 680 | ... S39: =SUM(S7:S35) -> #REF!

Sheet Utility report 
A1: DAILY UTILITY REPORT FEBRUARY 2020
A2: Date | B2: Total occupancy | H2: Diesel balance LTS | I2: Diesel Deliveries | J2: Gen.Diesel consumption LTS | L2: Total Diesel consumption LTS | M2: Water Meter reading | N2: Water consumption m³ | O2: R.O WATER PRODUCTION LTRS + TIME | AA2: Total RO production | AB2: RO Meter reading | AD2: 0 | AF2: GAS TANK A | AG2: GAS TANK B | AH2: GAS TANK C | AI2: Total Gas Tanks | AJ2: Kg /day | AK2: TOTAL GAS cons.
A3: Rate Tsh /$ | B3: 1640 | C3: Diesel cost / lits | D3: 2175 | F3: =SUM(D3/B3) -> 1.3262195 | H3: =Gen!C11 -> 30982.31 | K3: Transport consumption | M3: Balance | O3: PLANT NO 1 | S3: PLANT NO 2 | W3: PLANT NO 3 | AA3: /day | AB3: Balance | AC3: Production | AD3: 0 | AE3: Production | AF3: Capacity | AG3: Capacity | AH3: Capacity | AI3: Kg | AJ3: /day | AK3: /day
B4: Rooms OCC | C4: % | D4: Guest Rooms Occ | F4: Electricity Production Cost /Room Occ by guest | G4: All Cost /Room Occ by guest | O4: Flow M3 | P4: Reading Hours Meter | Q4: Hrs | R4: total production M3 | S4: Flow M3 | T4: Reading Hours Meter | U4: Hrs | V4: total production M3 | W4: Flow M3 | X4: READING HOURS METER | Y4: Hrs | Z4: total production M3 | AA4: M3 | AC4: M3 | AE4: M3 | AF4: 2000 | AG4: 1000 | AH4: 1000 | AI4: =SUM([2]Sheet1!$AA$36) -> 950 | AJ4: Kg | AK4: M3
X5: 23125 | AB5: 23835 | AD5: 195125 | AF5: 0.85 | AG5: 0.85 | AH5: 0.85
A6: =Gen!A11 -> 43862 | B6: ='Summery Report'!E5 -> 18 | C6: =Gen!B11 -> 0.2338 | D6: ='Summery Report'!E5 -> 18 | E6: =SUM(F3) -> 1.3262195 | F6: =SUM(J6*E6)/D6 -> 134.4455 | G6: =SUM(L6*E6)/D6 -> 140.57632 | H6: =Gen!C11 -> 30982.31 | I6: =Gen!E11 -> 0 | J6: =Gen!S11 -> 1824.75 | K6: =Gen!AJ11 -> 83.21 | L6: =SUM(J6:K6) -> 1907.96 | M6: ='Water-Meter'!K46 -> 574.19311 | N6: ='Water-Meter'!E6 -> 113 | Q6: =SUM(P6-P5) -> 0 | R6: =SUM(Q6*O6) -> 0 | T6: 15719 | U6: =T6-T5 -> 15719 | V6: - | X6: 23143 | Y6: =X6-X5 -> 18 | Z6: =Y6-Y5 -> 18 | AA6: =Z6-Z5 -> 18 | AB6: 23950 | AC6: =AB6-AB5 -> 115 | AD6: 195178 | AE6: =AD6-AD5 -> 53 | AF6: ='Lpg (2)'!B10*2000/85 -> 2000 | AG6: ='Lpg (2)'!C10*1000/85 -> 1000 | AH6: ='Lpg (2)'!D10*1000/85 -> 211.76471 | AI6: =SUM(AF6*2000)+(AG6*1000)+(AH6*1000) -> 5211764.7 | AJ6: =SUM(AI5-AI6) -> -5211764.7
A7: =Gen!A12 -> 43863 | B7: ='Summery Report'!E6 -> 18 | C7: =Gen!B12 -> 0.234 | D7: ='Summery Report'!E6 -> 18 | E7: =SUM(E6) -> 1.3262195 | F7: =SUM(J7*E7)/D7 -> 132.83194 | G7: =SUM(L7*E7)/D7 -> 142.43892 | H7: =Gen!C12 -> 29074.35 | I7: =Gen!E12 -> 18000 | J7: =Gen!S12 -> 1802.85 | K7: =Gen!AJ12 -> 130.39 | L7: =SUM(J7:K7) -> 1933.24 | M7: ='Water-Meter'!K47 -> 533.64272 | N7: ='Water-Meter'!E7 -> 97 | P7: 18665 | Q7: =SUM(P7-P6) -> 18665 | R7: =SUM(Q7*O7) -> 0 | T7: 15719 | U7: =T7-T6 -> 0 | V7: =SUM(U7*S7) -> 0 | X7: 23167 | Y7: =X7-X6 -> 24 | Z7: =SUM(Y7*W7) -> 0 | AA7: =SUM(Z7*X9) -> 0 | AB7: 24051 | AC7: =AB7-AB6 -> 101 | AD7: 195241 | AE7: =AD7-AD6 -> 63 | AF7: ='Lpg (2)'!B11*2000/85 -> 2000 | AG7: ='Lpg (2)'!C11*1000/85 -> 1000 | AH7: ='Lpg (2)'!D11*1000/85 -> 117.64706 | AI7: =SUM(AF6*2000)+(AG7*1000)+(AH7*1000) -> 5117647.1 | AJ7: =SUM(AI6-AI7) -> 94117.647
A8: =Gen!A13 -> 43864 | B8: ='Summery Report'!E7 -> 8 | C8: =Gen!B13 -> 0.104 | D8: ='Summery Report'!E7 -> 8 | E8: =SUM(E7) -> 1.3262195 | F8: =SUM(J8*E8)/D8 -> 318.4452 | G8: =SUM(L8*E8)/D8 -> 348.07792 | H8: =Gen!C13 -> 27141.11 | I8: =Gen!E13 -> 0 | J8: =Gen!S13 -> 1920.92 | K8: =Gen!AJ13 -> 178.75 | L8: =SUM(J8:K8) -> 2099.67 | M8: ='Water-Meter'!K48 -> 440.34108 | N8: ='Water-Meter'!E8 -> 107 | P8: 18665 | Q8: =SUM(P8-P7) -> 0 | R8: =SUM(Q8*O8) -> 0 | T8: 15719 | U8: =T8-T7 -> 0 | V8: =SUM(U8*S8) -> 0 | X8: 23184.3 | Y8: =X8-X7 -> 17.3 | Z8: =SUM(Y8*W8) -> 0 | AA8: =SUM(Z8*X10) -> 0 | AB8: 24132 | AC8: =AB8-AB7 -> 81 | AD8: 195301 | AE8: =AD8-AD7 -> 60 | AF8: ='Lpg (2)'!B12*2000/85 -> 2000 | AG8: ='Lpg (2)'!C12*1000/85 -> 1000 | AH8: ='Lpg (2)'!D12*1000/85 -> 82.352941 | AI8: =SUM(AF7*2000)+(AG8*1000)+(AH8*1000) -> 5082352.9 | AJ8: =SUM(AI7-AI8) -> 35294.118
A9: =Gen!A14 -> 43865 | B9: ='Summery Report'!E8 -> 77 | C9: =Gen!B14 -> 1 | D9: ='Summery Report'!E8 -> 77 | E9: =SUM(E8) -> 1.3262195 | F9: =SUM(J9*E9)/D9 -> 40.63261 | G9: =SUM(L9*E9)/D9 -> 42.176709 | H9: =Gen!C14 -> 43041.44 | I9: =Gen!E14 -> 0 | J9: =Gen!S14 -> 2359.12 | K9: =Gen!AJ14 -> 89.65 | L9: =SUM(J9:K9) -> 2448.77 | M9: ='Water-Meter'!K49 -> 339.08585 | N9: ='Water-Meter'!E9 -> 139 | P9: 18665 | Q9: =SUM(P9-P8) -> 0 | R9: =SUM(Q9*O9) -> 0 | T9: 15719 | U9: =T9-T8 -> 0 | V9: =SUM(U9*S9) -> 0 | X9: 23208 | Y9: =X9-X8 -> 23.7 | Z9: =SUM(Y9*W9) -> 0 | AA9: =SUM(Z9*X11) -> 0 | AB9: 24232 | AC9: =AB9-AB8 -> 100 | AD9: 195364 | AE9: =AD9-AD8 -> 63 | AF9: ='Lpg (2)'!B13*2000/85 -> 2000 | AG9: ='Lpg (2)'!C13*1000/85 -> 1000 | AH9: ='Lpg (2)'!D13*1000/85 -> 58.823529 | AI9: =SUM(AF8*2000)+(AG9*1000)+(AH9*1000) -> 5058823.5 | AJ9: =SUM(AI8-AI9) -> 23529.412
A10: =Gen!A15 -> 43866 | B10: ='Summery Report'!E9 -> 77 | C10: =Gen!B15 -> 1 | D10: ='Summery Report'!E9 -> 77 | E10: =SUM(E9) -> 1.3262195 | F10: =SUM(J10*E10)/D10 -> 38.869083 | G10: =SUM(L10*E10)/D10 -> 41.095581 | H10: =Gen!C15 -> 40592.67 | I10: =Gen!E15 -> 0 | J10: =Gen!S15 -> 2256.73 | K10: =Gen!AJ15 -> 129.27 | L10: =SUM(J10:K10) -> 2386 | M10: ='Water-Meter'!K50 -> 383.76819 | N10: ='Water-Meter'!E10 -> 141 | P10: 18665 | Q10: =SUM(P10-P9) -> 0 | R10: =SUM(Q10*O10) -> 0 | T10: 15719 | U10: =T10-T9 -> 0 | V10: =SUM(U10*S10) -> 0 | W10: 4.8 | X10: 23251 | Y10: =X10-X9 -> 43 | Z10: =SUM(Y10*W10) -> 206.4 | AA10: =SUM(Z10*X12) -> 4807881.6 | AB10: 24330 | AC10: =AB10-AB9 -> 98 | AD10: 195427 | AE10: =AD10-AD9 -> 63 | AF10: ='Lpg (2)'!B14*2000/85 -> 2000 | AG10: ='Lpg (2)'!C14*1000/85 -> 894.11765 | AH10: ='Lpg (2)'!D14*1000/85 -> 0 | AI10: =SUM(AF9*2000)+(AG10*1000)+(AH10*1000) -> 4894117.6 | AJ10: =SUM(AI9-AI10) -> 164705.88
A11: =Gen!A16 -> 43867 | B11: ='Summery Report'!E10 -> 77 | C11: =Gen!B16 -> 1 | D11: ='Summery Report'!E10 -> 77 | E11: =SUM(E10) -> 1.3262195 | F11: =SUM(J11*E11)/D11 -> 42.912846 | G11: =SUM(L11*E11)/D11 -> 46.144688 | H11: =Gen!C16 -> 38206.67 | I11: =Gen!E16 -> 0 | J11: =Gen!S16 -> 2491.51 | K11: =Gen!AJ16 -> 187.64 | L11: =SUM(J11:K11) -> 2679.15 | M11: ='Water-Meter'!K51 -> 370.15578 | N11: ='Water-Meter'!E11 -> 129 | P11: 18665 | Q11: =SUM(P11-P10) -> 0 | R11: =SUM(Q11*O11) -> 0 | T11: 15719 | U11: =T11-T10 -> 0 | V11: =SUM(U11*S11) -> 0 | W11: 4.8 | X11: 23274 | Y11: =X11-X10 -> 23 | Z11: =SUM(Y11*W11) -> 110.4 | AA11: =SUM(Z11*X13) -> 2574196.8 | AB11: 24413 | AC11: =AB11-AB10 -> 83 | AD11: 195483 | AE11: =AD11-AD10 -> 56 | AF11: ='Lpg (2)'!B15*2000/85 -> 2000 | AG11: ='Lpg (2)'!C15*1000/85 -> 823.52941 | AH11: ='Lpg (2)'!D15*1000/85 -> 0 | AI11: =SUM(AF10*2000)+(AG11*1000)+(AH11*1000) -> 4823529.4 | AJ11: =SUM(AI10-AI11) -> 70588.235
A12: =Gen!A17 -> 43868 | B12: ='Summery Report'!E11 -> 77 | C12: =Gen!B17 -> 1 | D12: ='Summery Report'!E11 -> 77 | E12: =SUM(E11) -> 1.3262195 | F12: =SUM(J12*E12)/D12 -> 38.662571 | G12: =SUM(L12*E12)/D12 -> 42.161552 | H12: =Gen!C17 -> 35527.52 | I12: =Gen!E17 -> 0 | J12: =Gen!S17 -> 2244.74 | K12: =Gen!AJ17 -> 203.15 | L12: =SUM(J12:K12) -> 2447.89 | M12: ='Water-Meter'!K52 -> 390.1632 | N12: ='Water-Meter'!E12 -> 129 | O12: 2.5 | P12: 18674 | Q12: =SUM(P12-P11) -> 9 | R12: =SUM(Q12*O12) -> 22.5 | T12: 15719 | U12: =T12-T11 -> 0 | V12: =SUM(U12*S12) -> 0 | W12: 4.7 | X12: 23294 | Y12: =X12-X11 -> 20 | Z12: =SUM(Y12*W12) -> 94 | AA12: =SUM(Z12*X14) -> 2194054 | AB12: 24516 | AC12: =AB12-AB11 -> 103 | AD12: 195483 | AE12: =AD12-AD11 -> 0 | AF12: ='Lpg (2)'!B16*2000/85 -> 2000 | AG12: ='Lpg (2)'!C16*1000/85 -> 705.88235 | AH12: ='Lpg (2)'!D16*1000/85 -> 0 | AI12: =SUM(AF11*2000)+(AG12*1000)+(AH12*1000) -> 4705882.4 | AJ12: =SUM(AI11-AI12) -> 117647.06
A13: =Gen!A18 -> 43869 | B13: ='Summery Report'!E12 -> 13 | C13: =Gen!B18 -> 0.1429 | D13: ='Summery Report'!E12 -> 13 | E13: =SUM(E12) -> 1.3262195 | F13: =SUM(J13*E13)/D13 -> 262.12729 | G13: =SUM(L13*E13)/D13 -> 267.91572 | H13: =Gen!C18 -> 33079.63 | I13: =Gen!E18 -> 0 | J13: =Gen!S18 -> 2569.45 | K13: =Gen!AJ18 -> 56.74 | L13: =SUM(J13:K13) -> 2626.19 | M13: ='Water-Meter'!K53 -> 329.199 | N13: ='Water-Meter'!E13 -> 128 | O13: 2.5 | P13: 18687 | Q13: =SUM(P13-P12) -> 13 | R13: =SUM(Q13*O13) -> 32.5 | T13: 15719 | U13: =T13-T12 -> 0 | V13: =SUM(U13*S13) -> 0 | W13: 5 | X13: 23317 | Y13: =X13-X12 -> 23 | Z13: =SUM(Y13*W13) -> 115 | AA13: =SUM(Z13*X15) -> 0 | AB13: 24621 | AC13: =AB13-AB12 -> 105 | AD13: 195483 | AE13: =AD13-AD12 -> 0 | AF13: ='Lpg (2)'!B17*2000/85 -> 2000 | AG13: ='Lpg (2)'!C17*1000/85 -> 647.05882 | AH13: ='Lpg (2)'!D17*1000/85 -> 0 | AI13: =SUM(AF12*2000)+(AG13*1000)+(AH13*1000) -> 4647058.8 | AJ13: =SUM(AI12-AI13) -> 58823.529
A14: =Gen!A19 -> 43870 | B14: ='Summery Report'!E13 -> 16 | C14: =Gen!B19 -> 0.195 | D14: ='Summery Report'!E13 -> 16 | E14: =SUM(E13) -> 1.3262195 | F14: =SUM(J14*E14)/D14 -> 169.07807 | G14: =SUM(L14*E14)/D14 -> 182.5624 | H14: =Gen!C19 -> 45453.44 | I14: =Gen!E19 -> 15000 | J14: =Gen!S19 -> 2039.82 | K14: =Gen!AJ19 -> 162.68 | L14: =SUM(J14:K14) -> 2202.5 | M14: ='Water-Meter'!K54 -> 382.48232 | N14: ='Water-Meter'!E14 -> 96 | P14: 18687 | Q14: =SUM(P14-P13) -> 0 | R14: =SUM(Q14*O14) -> 0 | T14: 15719 | U14: =T14-T13 -> 0 | V14: =SUM(U14*S14) -> 0 | W14: 5.2 | X14: 23341 | Y14: =X14-X13 -> 24 | Z14: =SUM(Y14*W14) -> 124.8 | AA14: =SUM(Z14*X16) -> 0 | AB14: 24757 | AC14: =AB14-AB13 -> 136 | AD14: 195483 | AE14: =AD14-AD13 -> 0 | AF14: ='Lpg (2)'!B18*2000/85 -> 2000 | AG14: ='Lpg (2)'!C18*1000/85 -> 576.47059 | AH14: ='Lpg (2)'!D18*1000/85 -> 0 | AI14: =SUM(AF13*2000)+(AG14*1000)+(AH14*1000) -> 4576470.6 | AJ14: =SUM(AI13-AI14) -> 70588.235
A15: =Gen!A20 -> 43871 | B15: ='Summery Report'!E14 -> 15 | C15: =Gen!B20 -> 0.1818 | D15: ='Summery Report'!E14 -> 15 | E15: =SUM(E14) -> 1.3262195 | F15: =SUM(J15*E15)/D15 -> 0 | G15: =SUM(L15*E15)/D15 -> 0 | H15: =Gen!C20 -> 43250.94 | I15: =Gen!E20 -> 0 | J15: =Gen!S20 -> 0 | K15: =Gen!AJ20 -> 0 | L15: =SUM(J15:K15) -> 0 | M15: ='Water-Meter'!K55 -> 0 | N15: ='Water-Meter'!E15 -> 0 | Q15: =SUM(P15-P14) -> -18687 | R15: =SUM(Q15*O15) -> 0 | U15: =T15-T14 -> -15719 | V15: =SUM(U15*S15) -> 0 | Y15: =X15-X14 -> -23341 | Z15: =SUM(Y15*W15) -> 0 | AA15: =SUM(Z15*X17) -> 0 | AB15: 24878 | AC15: =AB15-AB14 -> 121 | AD15: 195532 | AE15: =AD15-AD14 -> 49 | AF15: ='Lpg (2)'!B19*2000/85 -> 0 | AG15: ='Lpg (2)'!C19*1000/85 -> 0 | AH15: ='Lpg (2)'!D19*1000/85 -> 0 | AI15: =SUM(AF15*2000)+(AG15*1000)+(AH15*1000) -> 0 | AJ15: =SUM(AI14-AI15) -> 4576470.6
A16: =Gen!A21 -> 43872 | B16: ='Summery Report'!E15 -> 0 | C16: =Gen!B21 -> 0 | D16: ='Summery Report'!E15 -> 0 | E16: =SUM(E15) -> 1.3262195 | F16: =SUM(J16*E16)/D16 -> #DIV/0! | G16: =SUM(L16*E16)/D16 -> #DIV/0! | H16: =Gen!C21 -> 43250.94 | I16: =Gen!E21 -> 0 | J16: =Gen!S21 -> 0 | K16: =Gen!AJ21 -> 0 | L16: =SUM(J16:K16) -> 0 | M16: ='Water-Meter'!K56 -> 0 | N16: ='Water-Meter'!E16 -> 0 | Q16: =SUM(P16-P15) -> 0 | R16: =SUM(Q16*O16) -> 0 | U16: =T16-T15 -> 0 | V16: =SUM(U16*S16) -> 0 | Y16: =X16-X15 -> 0 | Z16: =SUM(Y16*W16) -> 0 | AA16: =SUM(Z16*X18) -> 0 | AC16: =AB16-AB15 -> -24878 | AE16: =AD16-AD15 -> -195532 | AF16: ='Lpg (2)'!B20*2000/85 -> 0 | AG16: ='Lpg (2)'!C20*1000/85 -> 0 | AH16: ='Lpg (2)'!D20*1000/85 -> 0 | AI16: =SUM(AF16*2000)+(AG16*1000)+(AH16*1000) -> 0 | AJ16: =SUM(AI15-AI16) -> 0
A17: =Gen!A22 -> 43873 | B17: ='Summery Report'!E16 -> 0 | C17: =Gen!B22 -> 0 | D17: ='Summery Report'!E16 -> 0 | E17: =SUM(E16) -> 1.3262195 | F17: =SUM(J17*E17)/D17 -> #DIV/0! | G17: =SUM(L17*E17)/D17 -> #DIV/0! | H17: =Gen!C22 -> 43250.94 | I17: =Gen!E22 -> 0 | J17: =Gen!S22 -> 0 | K17: =Gen!AJ22 -> 0 | L17: =SUM(J17:K17) -> 0 | M17: ='Water-Meter'!K57 -> 0 | N17: ='Water-Meter'!E17 -> 0 | Q17: =SUM(P18-P16) -> 0 | R17: =SUM(Q17*O17) -> 0 | U17: =T17-T16 -> 0 | V17: =SUM(U17*S17) -> 0 | Y17: =X17-X16 -> 0 | Z17: =SUM(Y17*W17) -> 0 | AA17: =SUM(Z17*X19) -> 0 | AC17: =AB17-AB16 -> 0 | AE17: =AD17-AD16 -> 0 | AF17: ='Lpg (2)'!B21*2000/85 -> 0 | AG17: ='Lpg (2)'!C21*1000/85 -> 0 | AH17: ='Lpg (2)'!D21*1000/85 -> 0 | AI17: =SUM(AF17*2000)+(AG17*1000)+(AH17*1000) -> 0 | AJ17: =SUM(AI16-AI17) -> 0
A18: =Gen!A23 -> 43874 | B18: ='Summery Report'!E17 -> 0 | C18: =Gen!B23 -> 0 | D18: ='Summery Report'!E17 -> 0 | E18: =SUM(E17) -> 1.3262195 | F18: =SUM(J18*E18)/D18 -> #DIV/0! | G18: =SUM(L18*E18)/D18 -> #DIV/0! | H18: =Gen!C23 -> 43250.94 | I18: =Gen!E23 -> 0 | J18: =Gen!S23 -> 0 | K18: =Gen!AJ23 -> 0 | L18: =SUM(J18:K18) -> 0 | M18: ='Water-Meter'!K58 -> 0 | N18: ='Water-Meter'!E18 -> 0 | R18: =SUM(Q18*O18) -> 0 | U18: =T18-T17 -> 0 | V18: =SUM(U18*S18) -> 0 | Y18: =X18-X17 -> 0 | Z18: =SUM(Y18*W18) -> 0 | AA18: =SUM(Z18*X20) -> 0 | AC18: =AB18-AB17 -> 0 | AE18: =AD18-AD17 -> 0 | AF18: ='Lpg (2)'!B22*2000/85 -> 0 | AG18: ='Lpg (2)'!C22*1000/85 -> 0 | AH18: ='Lpg (2)'!D22*1000/85 -> 0 | AI18: =SUM(AF18*2000)+(AG18*1000)+(AH18*1000) -> 0 | AJ18: =SUM(AI17-AI18) -> 0
A19: =Gen!A24 -> 43875 | B19: ='Summery Report'!E18 -> 0 | C19: =Gen!B24 -> 0 | D19: ='Summery Report'!E18 -> 0 | E19: =SUM(E18) -> 1.3262195 | F19: =SUM(J19*E19)/D19 -> #DIV/0! | G19: =SUM(L19*E19)/D19 -> #DIV/0! | H19: =Gen!C24 -> 43250.94 | I19: =Gen!E24 -> 0 | J19: =Gen!S24 -> 0 | K19: =Gen!AJ24 -> 0 | L19: =SUM(J19:K19) -> 0 | M19: ='Water-Meter'!K59 -> 0 | N19: ='Water-Meter'!E19 -> 0 | R19: =SUM(Q19*O19) -> 0 | U19: =T19-T18 -> 0 | V19: =SUM(U19*S19) -> 0 | Y19: =X19-X18 -> 0 | Z19: =SUM(Y19*W19) -> 0 | AA19: =SUM(Z19*X21) -> 0 | AC19: =AB19-AB18 -> 0 | AE19: =AD19-AD18 -> 0 | AF19: ='Lpg (2)'!B23*2000/85 -> 0 | AG19: ='Lpg (2)'!C23*1000/85 -> 0 | AH19: ='Lpg (2)'!D23*1000/85 -> 0 | AI19: =SUM(AF19*2000)+(AG19*1000)+(AH19*1000) -> 0 | AJ19: =SUM(AI18-AI19) -> 0
A20: =Gen!A25 -> 43876 | B20: ='Summery Report'!E19 -> 0 | C20: =Gen!B25 -> 0 | D20: ='Summery Report'!E19 -> 0 | E20: =SUM(E19) -> 1.3262195 | F20: =SUM(J20*E20)/D20 -> #DIV/0! | G20: =SUM(L20*E20)/D20 -> #DIV/0! | H20: =Gen!C25 -> 43250.94 | I20: =Gen!E25 -> 0 | J20: =Gen!S25 -> 0 | K20: =Gen!AJ25 -> 0 | L20: =SUM(J20:K20) -> 0 | M20: ='Water-Meter'!K60 -> 0 | N20: ='Water-Meter'!E20 -> 0 | Q20: =SUM(P20-P19) -> 0 | R20: =SUM(Q20*O20) -> 0 | U20: =T20-T19 -> 0 | V20: =SUM(U20*S20) -> 0 | Y20: =X20-X19 -> 0 | Z20: =SUM(Y20*W20) -> 0 | AA20: =SUM(Z20*X22) -> 0 | AC20: =AB20-AB19 -> 0 | AE20: =AD20-AD19 -> 0 | AF20: ='Lpg (2)'!B24*2000/85 -> 0 | AG20: ='Lpg (2)'!C24*1000/85 -> 0 | AH20: ='Lpg (2)'!D24*1000/85 -> 0 | AI20: =SUM(AF20*2000)+(AG20*1000)+(AH20*1000) -> 0 | AJ20: =SUM(AI19-AI20) -> 0
A21: =Gen!A26 -> 43877 | B21: ='Summery Report'!E20 -> 0 | C21: =Gen!B26 -> 0 | D21: ='Summery Report'!E20 -> 0 | E21: =SUM(E20) -> 1.3262195 | F21: =SUM(J21*E21)/D21 -> #DIV/0! | G21: =SUM(L21*E21)/D21 -> #DIV/0! | H21: =Gen!C26 -> 43250.94 | I21: =Gen!E26 -> 18000 | J21: =Gen!S26 -> 0 | K21: =Gen!AJ26 -> 0 | L21: =SUM(J21:K21) -> 0 | M21: ='Water-Meter'!K61 -> 0 | N21: ='Water-Meter'!E21 -> 0 | Q21: =SUM(P21-P20) -> 0 | R21: =SUM(Q21*O21) -> 0 | U21: =T21-T20 -> 0 | V21: =SUM(U21*S21) -> 0 | Y21: =X21-X20 -> 0 | Z21: =SUM(Y21*W21) -> 0 | AA21: =SUM(Z21*X23) -> 0 | AC21: =AB21-AB20 -> 0 | AE21: =AD21-AD20 -> 0 | AF21: ='Lpg (2)'!B25*2000/85 -> 0 | AG21: ='Lpg (2)'!C25*1000/85 -> 0 | AH21: ='Lpg (2)'!D25*1000/85 -> 0 | AI21: =SUM(AF21*2000)+(AG21*1000)+(AH21*1000) -> 0 | AJ21: =SUM(AI20-AI21) -> 0
A22: =Gen!A27 -> 43878 | B22: ='Summery Report'!E21 -> 0 | C22: =Gen!B27 -> 0 | D22: ='Summery Report'!E21 -> 0 | E22: =SUM(E21) -> 1.3262195 | F22: =SUM(J22*E22)/D22 -> #DIV/0! | G22: =SUM(L22*E22)/D22 -> #DIV/0! | H22: =Gen!C27 -> 43250.94 | I22: =Gen!E27 -> 0 | J22: =Gen!S27 -> 0 | K22: =Gen!AJ27 -> 0 | L22: =SUM(J22:K22) -> 0 | M22: ='Water-Meter'!K62 -> 0 | N22: ='Water-Meter'!E22 -> 0 | Q22: =SUM(P22-P21) -> 0 | R22: =SUM(Q22*O22) -> 0 | U22: =T22-T21 -> 0 | V22: =SUM(U22*S22) -> 0 | Y22: =X22-X21 -> 0 | Z22: =SUM(Y22*W22) -> 0 | AA22: =SUM(Z22*X24) -> 0 | AC22: =AB22-AB21 -> 0 | AE22: =AD22-AD21 -> 0 | AF22: ='Lpg (2)'!B26*2000/85 -> 0 | AG22: ='Lpg (2)'!C26*1000/85 -> 0 | AH22: ='Lpg (2)'!D26*1000/85 -> 0 | AI22: =SUM(AF22*2000)+(AG22*1000)+(AH22*1000) -> 0 | AJ22: =SUM(AI21-AI22) -> 0
A23: =Gen!A28 -> 43879 | B23: ='Summery Report'!E22 -> 0 | C23: =Gen!B28 -> 0 | D23: ='Summery Report'!E22 -> 0 | E23: =SUM(E22) -> 1.3262195 | F23: =SUM(J23*E23)/D23 -> #DIV/0! | G23: =SUM(L23*E23)/D23 -> #DIV/0! | H23: =Gen!C28 -> 43250.94 | I23: =Gen!E28 -> 0 | J23: =Gen!S28 -> 0 | K23: =Gen!AJ28 -> 0 | L23: =SUM(J23:K23) -> 0 | M23: ='Water-Meter'!K63 -> 0 | N23: ='Water-Meter'!E23 -> 0 | Q23: =SUM(P23-P22) -> 0 | R23: =SUM(Q23*O23) -> 0 | U23: =T23-T22 -> 0 | V23: =SUM(U23*S23) -> 0 | Y23: =X23-X22 -> 0 | Z23: =SUM(Y23*W23) -> 0 | AA23: =SUM(Z23*X25) -> 0 | AC23: =AB23-AB22 -> 0 | AE23: =AD23-AD22 -> 0 | AF23: ='Lpg (2)'!B27*2000/85 -> 0 | AG23: ='Lpg (2)'!C27*1000/85 -> 0 | AH23: ='Lpg (2)'!D27*1000/85 -> 0 | AI23: =SUM(AF23*2000)+(AG23*1000)+(AH23*1000) -> 0 | AJ23: =SUM(AI22-AI23) -> 0
A24: =Gen!A29 -> 43880 | B24: ='Summery Report'!E23 -> 0 | C24: =Gen!B29 -> 0 | D24: ='Summery Report'!E23 -> 0 | E24: =SUM(E23) -> 1.3262195 | F24: =SUM(J24*E24)/D24 -> #DIV/0! | G24: =SUM(L24*E24)/D24 -> #DIV/0! | H24: =Gen!C29 -> 43250.94 | I24: =Gen!E29 -> 0 | J24: =Gen!S29 -> 0 | K24: =Gen!AJ29 -> 0 | L24: =SUM(J24:K24) -> 0 | M24: ='Water-Meter'!K64 -> 0 | N24: ='Water-Meter'!E24 -> 0 | Q24: =SUM(P24-P23) -> 0 | R24: =SUM(Q24*O24) -> 0 | U24: =T24-T23 -> 0 | V24: =SUM(U24*S24) -> 0 | Y24: =X24-X23 -> 0 | Z24: =SUM(Y24*W24) -> 0 | AA24: =SUM(Z24*X26) -> 0 | AC24: =AB24-AB23 -> 0 | AE24: =AD24-AD23 -> 0 | AF24: ='Lpg (2)'!B28*2000/85 -> 0 | AG24: ='Lpg (2)'!C28*1000/85 -> 0 | AH24: ='Lpg (2)'!D28*1000/85 -> 0 | AI24: =SUM(AF24*2000)+(AG24*1000)+(AH24*1000) -> 0 | AJ24: =SUM(AI23-AI24) -> 0
A25: =Gen!A30 -> 43881 | B25: ='Summery Report'!E24 -> 0 | C25: =Gen!B30 -> 0 | D25: ='Summery Report'!E24 -> 0 | E25: =SUM(E24) -> 1.3262195 | F25: =SUM(J25*E25)/D25 -> #DIV/0! | G25: =SUM(L25*E25)/D25 -> #DIV/0! | H25: =Gen!C30 -> 43250.94 | I25: =Gen!E30 -> 0 | J25: =Gen!S30 -> 0 | K25: =Gen!AJ30 -> 0 | L25: =SUM(J25:K25) -> 0 | M25: ='Water-Meter'!K65 -> 0 | N25: ='Water-Meter'!E25 -> 0 | Q25: =SUM(P25-P24) -> 0 | R25: =SUM(Q25*O25) -> 0 | U25: =T25-T24 -> 0 | V25: =SUM(U25*S25) -> 0 | Y25: =X25-X24 -> 0 | Z25: =SUM(Y25*W25) -> 0 | AA25: =SUM(Z25*X27) -> 0 | AC25: =AB25-AB24 -> 0 | AE25: =AD25-AD24 -> 0 | AF25: ='Lpg (2)'!B29*2000/85 -> 0 | AG25: ='Lpg (2)'!C29*1000/85 -> 0 | AH25: ='Lpg (2)'!D29*1000/85 -> 0 | AI25: =SUM(AF25*2000)+(AG25*1000)+(AH25*1000) -> 0 | AJ25: =SUM(AI24-AI25) -> 0
A26: =Gen!A31 -> 43882 | B26: ='Summery Report'!E25 -> 0 | C26: =Gen!B31 -> 0 | D26: ='Summery Report'!E25 -> 0 | E26: =SUM(E25) -> 1.3262195 | F26: =SUM(J26*E26)/D26 -> #DIV/0! | G26: =SUM(L26*E26)/D26 -> #DIV/0! | H26: =Gen!C31 -> 43250.94 | I26: =Gen!E31 -> 0 | J26: =Gen!S31 -> 0 | K26: =Gen!AJ31 -> 0 | L26: =SUM(J26:K26) -> 0 | M26: ='Water-Meter'!K66 -> 0 | N26: ='Water-Meter'!E26 -> 0 | Q26: =SUM(P26-P25) -> 0 | R26: =SUM(Q26*O26) -> 0 | U26: =T26-T25 -> 0 | V26: =SUM(U26*S26) -> 0 | Y26: =X26-X25 -> 0 | Z26: =SUM(Y26*W26) -> 0 | AA26: =SUM(Z26*X28) -> 0 | AC26: =AB26-AB25 -> 0 | AE26: =AD26-AD25 -> 0 | AF26: ='Lpg (2)'!B30*2000/85 -> 0 | AG26: ='Lpg (2)'!C30*1000/85 -> 0 | AH26: ='Lpg (2)'!D30*1000/85 -> 0 | AI26: =SUM(AF26*2000)+(AG26*1000)+(AH26*1000) -> 0 | AJ26: =SUM(AI25-AI26) -> 0
A27: =Gen!A32 -> 43883 | B27: ='Summery Report'!E26 -> 0 | C27: =Gen!B32 -> 0 | D27: ='Summery Report'!E26 -> 0 | E27: =SUM(E26) -> 1.3262195 | F27: =SUM(J27*E27)/D27 -> #DIV/0! | G27: =SUM(L27*E27)/D27 -> #DIV/0! | H27: =Gen!C32 -> 43250.94 | I27: =Gen!E32 -> 0 | J27: =Gen!S32 -> 0 | K27: =Gen!AJ32 -> 0 | L27: =SUM(J27:K27) -> 0 | M27: ='Water-Meter'!K67 -> 0 | N27: ='Water-Meter'!E27 -> 0 | Q27: =SUM(P27-P26) -> 0 | R27: =SUM(Q27*O27) -> 0 | U27: =T27-T26 -> 0 | V27: =SUM(U27*S27) -> 0 | Y27: =X27-X26 -> 0 | Z27: =SUM(Y27*W27) -> 0 | AA27: =SUM(Z27*X29) -> 0 | AC27: =AB27-AB26 -> 0 | AE27: =AD27-AD26 -> 0 | AF27: ='Lpg (2)'!B31*2000/85 -> 0 | AG27: ='Lpg (2)'!C31*1000/85 -> 0 | AH27: ='Lpg (2)'!D31*1000/85 -> 0 | AI27: =SUM(AF27*2000)+(AG27*1000)+(AH27*1000) -> 0 | AJ27: =SUM(AI26-AI27) -> 0
A28: =Gen!A33 -> 43884 | B28: ='Summery Report'!E27 -> 0 | C28: =Gen!B33 -> 0 | D28: ='Summery Report'!E27 -> 0 | E28: =SUM(E27) -> 1.3262195 | F28: =SUM(J28*E28)/D28 -> #DIV/0! | G28: =SUM(L28*E28)/D28 -> #DIV/0! | H28: =Gen!C33 -> 43250.94 | I28: =Gen!E33 -> 0 | J28: =Gen!S33 -> 0 | K28: =Gen!AJ33 -> 0 | L28: =SUM(J28:K28) -> 0 | M28: ='Water-Meter'!K68 -> 0 | N28: ='Water-Meter'!E28 -> 0 | Q28: =SUM(P28-P27) -> 0 | R28: =SUM(Q28*O28) -> 0 | U28: =T28-T27 -> 0 | V28: =SUM(U28*S28) -> 0 | Y28: =X28-X27 -> 0 | Z28: =SUM(Y28*W28) -> 0 | AA28: =SUM(Z28*X30) -> 0 | AC28: =SUM(AB28-AB27) -> 0 | AE28: =AD28-AD27 -> 0 | AF28: ='Lpg (2)'!B32*2000/85 -> 0 | AG28: ='Lpg (2)'!C32*1000/85 -> 0 | AH28: ='Lpg (2)'!D32*1000/85 -> 0 | AI28: =SUM(AF28*2000)+(AG28*1000)+(AH28*1000) -> 0 | AJ28: =SUM(AI27-AI28) -> 0
A29: =Gen!A34 -> 43885 | B29: ='Summery Report'!E28 -> 0 | C29: =Gen!B34 -> 0 | D29: ='Summery Report'!E28 -> 0 | E29: =SUM(E28) -> 1.3262195 | F29: =SUM(J29*E29)/D29 -> #DIV/0! | G29: =SUM(L29*E29)/D29 -> #DIV/0! | H29: =Gen!C34 -> 43250.94 | I29: =Gen!E34 -> 0 | J29: =Gen!S34 -> 0 | K29: =Gen!AJ34 -> 0 | L29: =SUM(J29:K29) -> 0 | M29: ='Water-Meter'!K69 -> 0 | N29: ='Water-Meter'!E29 -> 0 | Q29: =SUM(P29-P28) -> 0 | R29: =SUM(Q29*O29) -> 0 | U29: =T29-T28 -> 0 | V29: =SUM(U29*S29) -> 0 | Y29: =X29-X28 -> 0 | Z29: =SUM(Y29*W29) -> 0 | AA29: =SUM(Z29*X31) -> 0 | AC29: =SUM(AB29-AB28) -> 0 | AE29: =AD29-AD28 -> 0 | AF29: ='Lpg (2)'!B33*2000/85 -> 0 | AG29: ='Lpg (2)'!C33*1000/85 -> 0 | AH29: ='Lpg (2)'!D33*1000/85 -> 0 | AI29: =SUM(AF29*2000)+(AG29*1000)+(AH29*1000) -> 0 | AJ29: =SUM(AI28-AI29) -> 0
