Workbook

Sheet TOTAL
A1: Site Name | B1: Day | C1: Month | D1: Year | E1: Total Electricity Kwh | F1: Electricity Tariff ($/Kwh) | G1: LPG (Kg) | H1: LPG $/Kg | I1: District Energy Heating Kwh | J1: District Energy Heating $/Kwh | K1: Water Utility Supply (m3) m3 | L1: Water Utility Supply (m3) $/m3 | M1: Room Nights | N1: Total Guests | O1: Utilities day cost dh
A2: Marrakech | B2: 1 | C2: 1 | D2: 2019 | E2: ='Consommation du 01.01 au 31.01'!M10 -> 15890 | F2: 1.002 | G2: ='Consommation du 01.01 au 31.01'!U10 -> 853.3 | H2: 9.65 | I2: ='Consommation du 01.01 au 31.01'!Y10*1000 -> 8990 | J2: 0.53 | K2: ='Consommation du 01.01 au 31.01'!D10 -> 380 | L2: 12.67 | M2: ='Consommation du 01.01 au 31.01'!AC10 -> 122 | N2: 278 | O2: =E2*F2+G2*H2+I2*J2+K2*L2 -> 33735.425
A3: Marrakech | B3: =B2+1 -> 2 | C3: 1 | D3: 2019 | E3: ='Consommation du 01.01 au 31.01'!M11 -> 14449 | F3: 1.002 | G3: ='Consommation du 01.01 au 31.01'!U11 -> 853.3 | H3: 9.65 | I3: ='Consommation du 01.01 au 31.01'!Y11*1000 -> 10340 | J3: 0.53 | K3: ='Consommation du 01.01 au 31.01'!D11 -> 370 | L3: 12.67 | M3: ='Consommation du 01.01 au 31.01'!AC11 -> 111 | N3: 254 | O3: =E3*F3+G3*H3+I3*J3+K3*L3 -> 32880.343
A4: Marrakech | B4: =B3+1 -> 3 | C4: 1 | D4: 2019 | E4: ='Consommation du 01.01 au 31.01'!M12 -> 14300 | F4: 1.002 | G4: ='Consommation du 01.01 au 31.01'!U12 -> 1817.9 | H4: 9.65 | I4: ='Consommation du 01.01 au 31.01'!Y12*1000 -> 9590 | J4: 0.53 | K4: ='Consommation du 01.01 au 31.01'!D12 -> 350 | L4: 12.67 | M4: ='Consommation du 01.01 au 31.01'!AC12 -> 112 | N4: 252 | O4: =E4*F4+G4*H4+I4*J4+K4*L4 -> 41388.535
A5: Marrakech | B5: =B4+1 -> 4 | C5: 1 | D5: 2019 | E5: ='Consommation du 01.01 au 31.01'!M13 -> 13780 | F5: 1.002 | G5: ='Consommation du 01.01 au 31.01'!U13 -> 1669.5 | H5: 9.65 | I5: ='Consommation du 01.01 au 31.01'!Y13*1000 -> 11260 | J5: 0.53 | K5: ='Consommation du 01.01 au 31.01'!D13 -> 360 | L5: 12.67 | M5: ='Consommation du 01.01 au 31.01'!AC13 -> 89 | N5: 206 | O5: =E5*F5+G5*H5+I5*J5+K5*L5 -> 40447.235
A6: Marrakech | B6: =B5+1 -> 5 | C6: 1 | D6: 2019 | E6: ='Consommation du 01.01 au 31.01'!M14 -> 14067 | F6: 1.002 | G6: ='Consommation du 01.01 au 31.01'!U14 -> 1892.1 | H6: 9.65 | I6: ='Consommation du 01.01 au 31.01'!Y14*1000 -> 11450 | J6: 0.53 | K6: ='Consommation du 01.01 au 31.01'!D14 -> 410 | L6: 12.67 | M6: ='Consommation du 01.01 au 31.01'!AC14 -> 76 | N6: 177 | O6: =E6*F6+G6*H6+I6*J6+K6*L6 -> 43617.099
A7: Marrakech | B7: =B6+1 -> 6 | C7: 1 | D7: 2019 | E7: ='Consommation du 01.01 au 31.01'!M15 -> 13509 | F7: 1.002 | G7: ='Consommation du 01.01 au 31.01'!U15 -> 1335.6 | H7: 9.65 | I7: ='Consommation du 01.01 au 31.01'!Y15*1000 -> 10070 | J7: 0.53 | K7: ='Consommation du 01.01 au 31.01'!D15 -> 350 | L7: 12.67 | M7: ='Consommation du 01.01 au 31.01'!AC15 -> 52 | N7: 121 | O7: =E7*F7+G7*H7+I7*J7+K7*L7 -> 36196.158
A8: Marrakech | B8: =B7+1 -> 7 | C8: 1 | D8: 2019 | E8: ='Consommation du 01.01 au 31.01'!M16 -> 13217 | F8: 1.002 | G8: ='Consommation du 01.01 au 31.01'!U16 -> 1595.3 | H8: 9.65 | I8: ='Consommation du 01.01 au 31.01'!Y16*1000 -> 11370 | J8: 0.53 | K8: ='Consommation du 01.01 au 31.01'!D16 -> 330 | L8: 12.67 | M8: ='Consommation du 01.01 au 31.01'!AC16 -> 60 | N8: 113 | O8: =E8*F8+G8*H8+I8*J8+K8*L8 -> 38845.279
A9: Marrakech | B9: =B8+1 -> 8 | C9: 1 | D9: 2019 | E9: ='Consommation du 01.01 au 31.01'!M17 -> 13793 | F9: 1.002 | G9: ='Consommation du 01.01 au 31.01'!U17 -> 1298.5 | H9: 9.65 | I9: ='Consommation du 01.01 au 31.01'!Y17*1000 -> 9550 | J9: 0.53 | K9: ='Consommation du 01.01 au 31.01'!D17 -> 350 | L9: 12.67 | M9: ='Consommation du 01.01 au 31.01'!AC17 -> 54 | N9: 101 | O9: =E9*F9+G9*H9+I9*J9+K9*L9 -> 35847.111
A10: Marrakech | B10: =B9+1 -> 9 | C10: 1 | D10: 2019 | E10: ='Consommation du 01.01 au 31.01'!M18 -> 13753 | F10: 1.002 | G10: ='Consommation du 01.01 au 31.01'!U18 -> 1966.3 | H10: 9.65 | I10: ='Consommation du 01.01 au 31.01'!Y18*1000 -> 11430 | J10: 0.53 | K10: ='Consommation du 01.01 au 31.01'!D18 -> 310 | L10: 12.67 | M10: ='Consommation du 01.01 au 31.01'!AC18 -> 56 | N10: 103 | O10: =E10*F10+G10*H10+I10*J10+K10*L10 -> 42740.901
A11: Marrakech | B11: =B10+1 -> 10 | C11: 1 | D11: 2019 | E11: ='Consommation du 01.01 au 31.01'!M19 -> 13544 | F11: 1.002 | G11: ='Consommation du 01.01 au 31.01'!U19 -> 1409.8 | H11: 9.65 | I11: ='Consommation du 01.01 au 31.01'!Y19*1000 -> 10190 | J11: 0.53 | K11: ='Consommation du 01.01 au 31.01'!D19 -> 270 | L11: 12.67 | M11: ='Consommation du 01.01 au 31.01'!AC19 -> 59 | N11: 101 | O11: =E11*F11+G11*H11+I11*J11+K11*L11 -> 35997.258
A12: Marrakech | B12: =B11+1 -> 11 | C12: 1 | D12: 2019 | E12: ='Consommation du 01.01 au 31.01'!M20 -> 13643 | F12: 1.002 | G12: ='Consommation du 01.01 au 31.01'!U20 -> 2040.5 | H12: 9.65 | I12: ='Consommation du 01.01 au 31.01'!Y20*1000 -> 11160 | J12: 0.53 | K12: ='Consommation du 01.01 au 31.01'!D20 -> 300 | L12: 12.67 | M12: ='Consommation du 01.01 au 31.01'!AC20 -> 95 | N12: 154 | O12: =E12*F12+G12*H12+I12*J12+K12*L12 -> 43076.911
A13: Marrakech | B13: =B12+1 -> 12 | C13: 1 | D13: 2019 | E13: ='Consommation du 01.01 au 31.01'!M21 -> 13935 | F13: 1.002 | G13: ='Consommation du 01.01 au 31.01'!U21 -> 1558.2 | H13: 9.65 | I13: ='Consommation du 01.01 au 31.01'!Y21*1000 -> 12120 | J13: 0.53 | K13: ='Consommation du 01.01 au 31.01'!D21 -> 310 | L13: 12.67 | M13: ='Consommation du 01.01 au 31.01'!AC21 -> 62 | N13: 111 | O13: =E13*F13+G13*H13+I13*J13+K13*L13 -> 39350.8
A14: Marrakech | B14: =B13+1 -> 13 | C14: 1 | D14: 2019 | E14: ='Consommation du 01.01 au 31.01'!M22 -> 14254 | F14: 1.002 | G14: ='Consommation du 01.01 au 31.01'!U22 -> 1372.7 | H14: 9.65 | I14: ='Consommation du 01.01 au 31.01'!Y22*1000 -> 14590 | J14: 0.53 | K14: ='Consommation du 01.01 au 31.01'!D22 -> 320 | L14: 12.67 | M14: ='Consommation du 01.01 au 31.01'!AC22 -> 34 | N14: 58 | O14: =E14*F14+G14*H14+I14*J14+K14*L14 -> 39316.163
... A29: Marrakech | B29: =B28+1 -> 28 | C29: 1 | D29: 2019 | E29: ='Consommation du 01.01 au 31.01'!M37 -> 12683 | F29: 1.002 | G29: ='Consommation du 01.01 au 31.01'!U37 -> 890.4 | H29: 9.65 | I29: ='Consommation du 01.01 au 31.01'!Y37*1000 -> 15310 | J29: 0.53 | K29: ='Consommation du 01.01 au 31.01'!D37 -> 300 | L29: 12.67 | M29: ='Consommation du 01.01 au 31.01'!AC37 -> 55 | N29: 93 | O29: =E29*F29+G29*H29+I29*J29+K29*L29 -> 33216.026
A30: Marrakech | B30: =B29+1 -> 29 | C30: 1 | D30: 2019 | E30: ='Consommation du 01.01 au 31.01'!M38 -> 13320 | F30: 1.002 | G30: ='Consommation du 01.01 au 31.01'!U38 -> 890.4 | H30: 9.65 | I30: ='Consommation du 01.01 au 31.01'!Y38*1000 -> 13310 | J30: 0.53 | K30: ='Consommation du 01.01 au 31.01'!D38 -> 340 | L30: 12.67 | M30: ='Consommation du 01.01 au 31.01'!AC38 -> 56 | N30: 96
A31: Marrakech | B31: =B30+1 -> 30 | C31: 1 | D31: 2019 | E31: ='Consommation du 01.01 au 31.01'!M39 -> 12260 | F31: 1.002 | G31: ='Consommation du 01.01 au 31.01'!U39 -> 779.1 | H31: 9.65 | I31: ='Consommation du 01.01 au 31.01'!Y39*1000 -> 10990 | J31: 0.53 | K31: ='Consommation du 01.01 au 31.01'!D39 -> 300 | L31: 12.67 | M31: ='Consommation du 01.01 au 31.01'!AC39 -> 50 | N31: 89
A32: Marrakech | B32: =B31+1 -> 31 | C32: 1 | D32: 2019 | E32: ='Consommation du 01.01 au 31.01'!M40 -> 12227 | F32: 1 | G32: ='Consommation du 01.01 au 31.01'!U40 -> 890.4 | H32: 9.65 | I32: ='Consommation du 01.01 au 31.01'!Y40*1000 -> 16030 | J32: 0.53 | K32: ='Consommation du 01.01 au 31.01'!D40 -> 300 | L32: 12.67 | M32: ='Consommation du 01.01 au 31.01'!AC40 -> 54 | N32: 90

Sheet Consommation du 01.01 au 31.01
B8: Date | D8: Cons Eau/Hotel | F8: Consommation du jour en DH | J8: ELECTRICITE en KWH | M8: total | O8: Consommation du jour en DH | Q8: Cons Elec/Villa | S8: Cons Elec/RIAD | U8: GAZ en Kg | W8: Consommation du jour en DH | AB8: Temp moyenne du jour °C | AC8: Room Nights | AD8: % Occupation | AE8: Temp Piscine Adulte à 7h00 °C | AF8: Temp Piscine Adulte à 15h00 °C | AG8: Temp Piscine famille à 07h00 ° C | AH8: Temp Piscine famille à 15h00 ° C
J9: creuse 81 | K9: pleine 82 | L9: pointe 83 | X9: Compteur AVEO Mwh | Y9: consommation eau choud en Mwh | Z9: consommation du jour en DH
B10: 43800 | D10: ='Suivi EAU-ELEC'!C15 -> 380 | F10: =D10*12.67 -> 4814.6 | J10: ='Suivi EAU-ELEC'!E15 -> 5589 | K10: ='Suivi EAU-ELEC'!G15 -> 6916 | L10: ='Suivi EAU-ELEC'!I15 -> 3385 | M10: =L10+K10+J10 -> 15890 | O10: =M10*1.002 -> 15921.78 | U10: ='Suvi Gaz'!O11 -> 853.3 | W10: =U10*8.8038 -> 7512.2825 | X10: 12137.53 | Y10: =IF(X11<X10,0,X11-X10) -> 8.99 | Z10: =Y10*0.84*1000 -> 7551.6 | AB10: 18 | AC10: 122 | AD10: 0.8971 | AE10: 28.8 | AF10: 29 | AG10: 29.2 | AH10: 30
B11: =B10+1 -> 43801 | D11: ='Suivi EAU-ELEC'!C16 -> 370 | F11: =D11*12.67 -> 4687.9 | J11: ='Suivi EAU-ELEC'!E16 -> 4606 | K11: ='Suivi EAU-ELEC'!G16 -> 6701 | L11: ='Suivi EAU-ELEC'!I16 -> 3142 | M11: =L11+K11+J11 -> 14449 | O11: =M11*1.002 -> 14477.898 | U11: ='Suvi Gaz'!O11 -> 853.3 | W11: =U11*8.8038 -> 7512.2825 | X11: 12146.52 | Y11: =IF(X12<X11,0,X12-X11) -> 10.34 | Z11: =Y11*0.84*1000 -> 8685.6 | AB11: 17 | AC11: 111 | AD11: 0.8538 | AE11: 29 | AF11: 29.8 | AG11: 29.4 | AH11: 29.8
B12: =B11+1 -> 43802 | D12: ='Suivi EAU-ELEC'!C17 -> 350 | F12: =D12*12.67 -> 4434.5 | J12: ='Suivi EAU-ELEC'!E17 -> 4289 | K12: ='Suivi EAU-ELEC'!G17 -> 6866 | L12: ='Suivi EAU-ELEC'!I17 -> 3145 | M12: =L12+K12+J12 -> 14300 | O12: =M12*1.002 -> 14328.6 | U12: ='Suvi Gaz'!O12 -> 1817.9 | W12: =U12*8.8038 -> 16004.428 | X12: 12156.86 | Y12: =IF(X13<X12,0,X13-X12) -> 9.59 | Z12: =Y12*0.84*1000 -> 8055.6 | AB12: 17 | AC12: 112 | AD12: 0.855 | AE12: 29.4 | AF12: 30 | AG12: 29.4 | AH12: 29.8
B13: =B12+1 -> 43803 | D13: ='Suivi EAU-ELEC'!C18 -> 360 | F13: =D13*12.67 -> 4561.2 | J13: ='Suivi EAU-ELEC'!E18 -> 4218 | K13: ='Suivi EAU-ELEC'!G18 -> 6555 | L13: ='Suivi EAU-ELEC'!I18 -> 3007 | M13: =L13+K13+J13 -> 13780 | O13: =M13*1.002 -> 13807.56 | U13: ='Suvi Gaz'!O13 -> 1669.5 | W13: =U13*8.8038 -> 14697.944 | X13: 12166.45 | Y13: =IF(X14<X13,0,X14-X13) -> 11.26 | Z13: =Y13*0.84*1000 -> 9458.4 | AB13: 16 | AC13: 89 | AD13: 0.6742 | AE13: 29 | AF13: 30 | AG13: 29 | AH13: 30
B14: =B13+1 -> 43804 | D14: ='Suivi EAU-ELEC'!C19 -> 410 | F14: =D14*12.67 -> 5194.7 | J14: ='Suivi EAU-ELEC'!E19 -> 4290 | K14: ='Suivi EAU-ELEC'!G19 -> 6732 | L14: ='Suivi EAU-ELEC'!I19 -> 3045 | M14: =L14+K14+J14 -> 14067 | O14: =M14*1.002 -> 14095.134 | U14: ='Suvi Gaz'!O14 -> 1892.1 | W14: =U14*8.8038 -> 16657.67 | X14: 12177.71 | Y14: =IF(X15<X14,0,X15-X14) -> 11.45 | Z14: =Y14*0.84*1000 -> 9618 | AB14: 17 | AC14: 76 | AD14: 0.5984 | AE14: 29 | AF14: 28.5 | AG14: 29 | AH14: 28
B15: =B14+1 -> 43805 | D15: ='Suivi EAU-ELEC'!C20 -> 350 | F15: =D15*12.67 -> 4434.5 | J15: ='Suivi EAU-ELEC'!E20 -> 4138 | K15: ='Suivi EAU-ELEC'!G20 -> 6398 | L15: ='Suivi EAU-ELEC'!I20 -> 2973 | M15: =L15+K15+J15 -> 13509 | O15: =M15*1.002 -> 13536.018 | U15: ='Suvi Gaz'!O15 -> 1335.6 | W15: =U15*8.8038 -> 11758.355 | X15: 12189.16 | Y15: =IF(X16<X15,0,X16-X15) -> 10.07 | Z15: =Y15*0.84*1000 -> 8458.8 | AB15: 14 | AC15: 52 | AD15: 0.4194 | AE15: 28 | AF15: 28.5 | AG15: 29 | AH15: 29
B16: =B15+1 -> 43806 | D16: ='Suivi EAU-ELEC'!C21 -> 330 | F16: =D16*12.67 -> 4181.1 | J16: ='Suivi EAU-ELEC'!E21 -> 4186 | K16: ='Suivi EAU-ELEC'!G21 -> 6125 | L16: ='Suivi EAU-ELEC'!I21 -> 2906 | M16: =L16+K16+J16 -> 13217 | O16: =M16*1.002 -> 13243.434 | U16: ='Suvi Gaz'!O16 -> 1595.3 | W16: =U16*8.8038 -> 14044.702 | X16: 12199.23 | Y16: =IF(X17<X16,0,X17-X16) -> 11.37 | Z16: =Y16*0.84*1000 -> 9550.8 | AB16: 12 | AC16: 60 | AD16: 0.4444 | AE16: 28 | AF16: 28 | AG16: 29 | AH16: 28.5
B17: =B16+1 -> 43807 | D17: ='Suivi EAU-ELEC'!C22 -> 350 | F17: =D17*12.67 -> 4434.5 | J17: ='Suivi EAU-ELEC'!E22 -> 4317 | K17: ='Suivi EAU-ELEC'!G22 -> 6445 | L17: ='Suivi EAU-ELEC'!I22 -> 3031 | M17: =L17+K17+J17 -> 13793 | O17: =M17*1.002 -> 13820.586 | U17: ='Suvi Gaz'!O17 -> 1298.5 | W17: =U17*8.8038 -> 11431.734 | X17: 12210.6 | Y17: =IF(X18<X17,0,X18-X17) -> 9.55 | Z17: =Y17*0.84*1000 -> 8022 | AB17: 13 | AC17: 54 | AD17: 0.432 | AE17: 28 | AF17: 28.4 | AG17: 29 | AH17: 29
B18: =B17+1 -> 43808 | D18: ='Suivi EAU-ELEC'!C23 -> 310 | F18: =D18*12.67 -> 3927.7 | J18: ='Suivi EAU-ELEC'!E23 -> 4074 | K18: ='Suivi EAU-ELEC'!G23 -> 6756 | L18: ='Suivi EAU-ELEC'!I23 -> 2923 | M18: =L18+K18+J18 -> 13753 | O18: =M18*1.002 -> 13780.506 | U18: ='Suvi Gaz'!O18 -> 1966.3 | W18: =U18*8.8038 -> 17310.912 | X18: 12220.15 | Y18: =IF(X19<X18,0,X19-X18) -> 11.43 | Z18: =Y18*0.84*1000 -> 9601.2 | AB18: 14 | AC18: 56 | AD18: 0.4516 | AE18: 27.3 | AF18: 28 | AG18: 28 | AH18: 27
B19: =B18+1 -> 43809 | D19: ='Suivi EAU-ELEC'!C24 -> 270 | F19: =D19*12.67 -> 3420.9 | J19: ='Suivi EAU-ELEC'!E24 -> 4129 | K19: ='Suivi EAU-ELEC'!G24 -> 6480 | L19: ='Suivi EAU-ELEC'!I24 -> 2935 | M19: =L19+K19+J19 -> 13544 | O19: =M19*1.002 -> 13571.088 | U19: ='Suvi Gaz'!O19 -> 1409.8 | W19: =U19*8.8038 -> 12411.597 | X19: 12231.58 | Y19: =IF(X20<X19,0,X20-X19) -> 10.19 | Z19: =Y19*0.84*1000 -> 8559.6 | AB19: 13 | AC19: 59 | AD19: 0.472 | AE19: 27 | AF19: 28 | AG19: 27 | AH19: 28
B20: =B19+1 -> 43810 | D20: ='Suivi EAU-ELEC'!C25 -> 300 | F20: =D20*12.67 -> 3801 | J20: ='Suivi EAU-ELEC'!E25 -> 4099 | K20: ='Suivi EAU-ELEC'!G25 -> 6541 | L20: ='Suivi EAU-ELEC'!I25 -> 3003 | M20: =L20+K20+J20 -> 13643 | O20: =M20*1.002 -> 13670.286 | U20: ='Suvi Gaz'!O20 -> 2040.5 | W20: =U20*8.8038 -> 17964.154 | X20: 12241.77 | Y20: =IF(X21<X20,0,X21-X20) -> 11.16 | Z20: =Y20*0.84*1000 -> 9374.4 | AA20: 14 | AB20: 13 | AC20: 95 | AD20: 0.7724 | AE20: 28 | AF20: 28.5 | AG20: 28 | AH20: 25.5
B21: =B20+1 -> 43811 | D21: ='Suivi EAU-ELEC'!C26 -> 310 | F21: =D21*12.67 -> 3927.7 | J21: ='Suivi EAU-ELEC'!E26 -> 4222 | K21: ='Suivi EAU-ELEC'!G26 -> 6595 | L21: ='Suivi EAU-ELEC'!I26 -> 3118 | M21: =L21+K21+J21 -> 13935 | O21: =M21*1.002 -> 13962.87 | U21: ='Suvi Gaz'!O21 -> 1558.2 | W21: =U21*8.8038 -> 13718.081 | X21: 12252.93 | Y21: =IF(X22<X21,0,X22-X21) -> 12.12 | Z21: =Y21*0.84*1000 -> 10180.8 | AA21: 14 | AB21: 14 | AC21: 62 | AD21: 0.5124 | AE21: 28 | AF21: 28 | AG21: 28 | AH21: 28
B22: =B21+1 -> 43812 | D22: ='Suivi EAU-ELEC'!C27 -> 320 | F22: =D22*12.67 -> 4054.4 | J22: ='Suivi EAU-ELEC'!E27 -> 4314 | K22: ='Suivi EAU-ELEC'!G27 -> 6859 | L22: ='Suivi EAU-ELEC'!I27 -> 3081 | M22: =L22+K22+J22 -> 14254 | O22: =M22*1.002 -> 14282.508 | U22: ='Suvi Gaz'!O22 -> 1372.7 | W22: =U22*8.8038 -> 12084.976 | X22: 12265.05 | Y22: =IF(X23<X22,0,X23-X22) -> 14.59 | Z22: =Y22*0.84*1000 -> 12255.6 | AB22: 14 | AC22: 34 | AD22: 0.2742 | AE22: 28 | AF22: 28 | AG22: 28 | AH22: 28.5
B23: =B22+1 -> 43813 | D23: ='Suivi EAU-ELEC'!C28 -> 330 | F23: =D23*12.67 -> 4181.1 | J23: ='Suivi EAU-ELEC'!E28 -> 4563 | K23: ='Suivi EAU-ELEC'!G28 -> 6847 | L23: ='Suivi EAU-ELEC'!I28 -> 3367 | M23: =L23+K23+J23 -> 14777 | O23: =M23*1.002 -> 14806.554 | U23: ='Suvi Gaz'!O23 -> 1855 | W23: =U23*8.8038 -> 16331.049 | X23: 12279.64 | Y23: =IF(X24<X23,0,X24-X23) -> 14.39 | Z23: =Y23*0.84*1000 -> 12087.6 | AB23: 14 | AC23: 93 | AD23: 0.6788 | AE23: 28 | AF23: 28.5 | AG23: 28 | AH23: 28.5
B24: =B23+1 -> 43814 | D24: ='Suivi EAU-ELEC'!C29 -> 340 | F24: =D24*12.67 -> 4307.8 | J24: ='Suivi EAU-ELEC'!E29 -> 4961 | K24: ='Suivi EAU-ELEC'!G29 -> 7337 | L24: ='Suivi EAU-ELEC'!I29 -> 3320 | M24: =L24+K24+J24 -> 15618 | O24: =M24*1.002 -> 15649.236 | U24: ='Suvi Gaz'!O24 -> 1706.6 | W24: =U24*8.8038 -> 15024.565 | X24: 12294.03 | Y24: =IF(X25<X24,0,X25-X24) -> 18.44 | Z24: =Y24*0.84*1000 -> 15489.6 | AB24: 13 | AC24: 125 | AD24: 0.9124 | AE24: 28 | AF24: 29 | AG24: 28 | AH24: 29
B25: =B24+1 -> 43815 | D25: ='Suivi EAU-ELEC'!C30 -> 300 | F25: =D25*12.67 -> 3801 | J25: ='Suivi EAU-ELEC'!E30 -> 4990 | K25: ='Suivi EAU-ELEC'!G30 -> 7519 | L25: ='Suivi EAU-ELEC'!I30 -> 3433 | M25: =L25+K25+J25 -> 15942 | O25: =M25*1.002 -> 15973.884 | U25: ='Suvi Gaz'!O25 -> 1075.9 | W25: =U25*8.8038 -> 9472.0084 | X25: 12312.47 | Y25: =IF(X26<X25,0,X26-X25) -> 15.92 | Z25: =Y25*0.84*1000 -> 13372.8 | AB25: 12 | AC25: 130 | AD25: 0.9848 | AE25: 28 | AF25: 29 | AG25: 29 | AH25: 29
B26: =B25+1 -> 43816 | D26: ='Suivi EAU-ELEC'!C31 -> 300 | F26: =D26*12.67 -> 3801 | J26: ='Suivi EAU-ELEC'!E31 -> 4730 | K26: ='Suivi EAU-ELEC'!G31 -> 7447 | L26: ='Suivi EAU-ELEC'!I31 -> 3330 | M26: =L26+K26+J26 -> 15507 | O26: =M26*1.002 -> 15538.014 | U26: ='Suvi Gaz'!O26 -> 1484 | W26: =U26*8.8038 -> 13064.839 | X26: 12328.39 | Y26: =IF(X27<X26,0,X27-X26) -> 13.61 | Z26: =Y26*0.84*1000 -> 11432.4 | AB26: 13 | AC26: 110 | AD26: 0.8594 | AE26: 28 | AF26: 28.5 | AG26: 28.5 | AH26: 29
B27: =B26+1 -> 43817 | D27: ='Suivi EAU-ELEC'!C32 -> 330 | F27: =D27*12.67 -> 4181.1 | J27: ='Suivi EAU-ELEC'!E32 -> 4740 | K27: ='Suivi EAU-ELEC'!G32 -> 7543 | L27: ='Suivi EAU-ELEC'!I32 -> 3363 | M27: =L27+K27+J27 -> 15646 | O27: =M27*1.002 -> 15677.292 | U27: ='Suvi Gaz'!O27 -> 1632.4 | W27: =U27*8.8038 -> 14371.323 | X27: 12342 | Y27: =IF(X28<X27,0,X28-X27) -> 13.85 | Z27: =Y27*0.84*1000 -> 11634 | AB27: 12 | AC27: 118 | AD27: 0.8694 | AE27: 28.5 | AF27: 29 | AG27: 29 | AH27: 30
B28: =B27+1 -> 43818 | D28: ='Suivi EAU-ELEC'!C33 -> 350 | F28: =D28*12.67 -> 4434.5 | J28: ='Suivi EAU-ELEC'!E33 -> 4788 | K28: ='Suivi EAU-ELEC'!G33 -> 7043 | L28: ='Suivi EAU-ELEC'!I33 -> 3245 | M28: =L28+K28+J28 -> 15076 | O28: =M28*1.002 -> 15106.152 | U28: ='Suvi Gaz'!O28 -> 1521.1 | W28: =U28*8.8038 -> 13391.46 | X28: 12355.85 | Y28: =IF(X29<X28,0,X29-X28) -> 13.26 | Z28: =Y28*0.84*1000 -> 11138.4 | AB28: 14 | AC28: 129 | AD28: 0.9348 | AE28: 28.5 | AF28: 29 | AG28: 29 | AH28: 30
B29: =B28+1 -> 43819 | D29: ='Suivi EAU-ELEC'!C34 -> 360 | F29: =D29*12.67 -> 4561.2 | J29: ='Suivi EAU-ELEC'!E34 -> 4431 | K29: ='Suivi EAU-ELEC'!G34 -> 6886 | L29: ='Suivi EAU-ELEC'!I34 -> 3194 | M29: =L29+K29+J29 -> 14511 | O29: =M29*1.002 -> 14540.022 | U29: ='Suvi Gaz'!O29 -> 1075.9 | W29: =U29*8.8038 -> 9472.0084 | X29: 12369.11 | Y29: =IF(X30<X29,0,X30-X29) -> 11.77 | Z29: =Y29*0.84*1000 -> 9886.8 | AB29: 14 | AC29: 77 | AD29: 0.5923 | AE29: 29 | AF29: 29 | AG29: 29 | AH29: 30
B30: =B29+1 -> 43820 | D30: ='Suivi EAU-ELEC'!C35 -> 300 | F30: =D30*12.67 -> 3801 | J30: ='Suivi EAU-ELEC'!E35 -> 4393 | K30: ='Suivi EAU-ELEC'!G35 -> 6817 | L30: ='Suivi EAU-ELEC'!I35 -> 3029 | M30: =L30+K30+J30 -> 14239 | O30: =M30*1.002 -> 14267.478 | U30: ='Suvi Gaz'!O30 -> 1113 | W30: =U30*8.8038 -> 9798.6294 | X30: 12380.88 | Y30: =IF(X31<X30,0,X31-X30) -> 11.51 | Z30: =Y30*0.84*1000 -> 9668.4 | AB30: 12 | AC30: 115 | AD30: 0.8915 | AE30: 29.5 | AF30: 30 | AG30: 29 | AH30: 30
B31: =B30+1 -> 43821 | D31: ='Suivi EAU-ELEC'!C36 -> 310 | F31: =D31*12.67 -> 3927.7 | J31: ='Suivi EAU-ELEC'!E36 -> 4652 | K31: ='Suivi EAU-ELEC'!G36 -> 7061 | L31: ='Suivi EAU-ELEC'!I36 -> 3141 | M31: =L31+K31+J31 -> 14854 | O31: =M31*1.002 -> 14883.708 | U31: ='Suvi Gaz'!O31 -> 1001.7 | W31: =U31*8.8038 -> 8818.7665 | X31: 12392.39 | Y31: =IF(X32<X31,0,X32-X31) -> 15.94 | Z31: =Y31*0.84*1000 -> 13389.6 | AB31: 12 | AC31: 103 | AD31: 0.7803 | AE31: 28.8 | AF31: 30 | AG31: 28.8 | AH31: 30
B32: =B31+1 -> 43822 | D32: ='Suivi EAU-ELEC'!C37 -> 360 | F32: =D32*12.67 -> 4561.2 | J32: ='Suivi EAU-ELEC'!E37 -> 4637 | K32: ='Suivi EAU-ELEC'!G37 -> 7211 | L32: ='Suivi EAU-ELEC'!I37 -> 3187 | M32: =L32+K32+J32 -> 15035 | O32: =M32*1.002 -> 15065.07 | U32: ='Suvi Gaz'!O32 -> 742 | W32: =U32*8.8038 -> 6532.4196 | X32: 12408.33 | Y32: =IF(X33<X32,0,X33-X32) -> 18.35 | Z32: =Y32*0.84*1000 -> 15414 | AB32: 13 | AC32: 105 | AD32: 0.8077 | AE32: 28 | AF32: 29 | AG32: 28 | AH32: 29
B33: =B32+1 -> 43823 | D33: ='Suivi EAU-ELEC'!C38 -> 310 | F33: =D33*12.67 -> 3927.7 | J33: ='Suivi EAU-ELEC'!E38 -> 4450 | K33: ='Suivi EAU-ELEC'!G38 -> 7066 | L33: ='Suivi EAU-ELEC'!I38 -> 3216 | M33: =L33+K33+J33 -> 14732 | O33: =M33*1.002 -> 14761.464 | U33: ='Suvi Gaz'!O33 -> 1113 | W33: =U33*8.8038 -> 9798.6294 | X33: 12426.68 | Y33: =IF(X34<X33,0,X34-X33) -> 15.25 | Z33: =Y33*0.84*1000 -> 12810 | AB33: 15 | AC33: 92 | AD33: 0.7023 | AE33: 28.5 | AF33: 28 | AG33: 28 | AH33: 27
... B40: =B39+1 -> 43830 | D40: ='Suivi EAU-ELEC'!C45 -> 300 | F40: =D40*12.67 -> 3801 | J40: ='Suivi EAU-ELEC'!E45 -> 3365 | K40: ='Suivi EAU-ELEC'!G45 -> 6122 | L40: ='Suivi EAU-ELEC'!I45 -> 2740 | M40: =L40+K40+J40 -> 12227 | O40: =M40*1.002 -> 12251.454 | U40: ='Suvi Gaz'!O40 -> 890.4 | W40: =U40*8.8038 -> 7838.9035 | X40: 12517.57 | Y40: =IF(X41<X40,0,X41-X40) -> 16.03 | Z40: =Y40*0.84*1000 -> 13465.2 | AB40: 14 | AC40: 54 | AD40: 0.4355 | AE40: 28 | AF40: 28 | AG40: 29 | AH40: 29
D41: =SUM(D10:D39) -> 9900 | F41: =SUM(F10:H40) -> 129234 | J41: =SUM(J10:J40) -> 135468 | K41: =SUM(K10:K40) -> 208547 | L41: =SUM(L10:L40) -> 95080 | M41: =SUM(M10:M40) -> 439095 | O41: =SUM(O10:Q40) -> 439973.19 | S41: =SUM(S10:S40) -> 0 | U41: =SUM(U10:U40) -> 39659.9 | W41: =SUM(W10:W40) -> 349157.83 | X41: 12533.6 | Y41: =SUM(Y10:Y40) -> 396.07 | Z41: =SUM(Z10:Z40) -> 332698.8
A43: ELECTRICITE / Kw/h | D43: creuse 81 | F43: 1.002 | G43: =J41 -> 135468 | J43: =G43*F43 -> 135738.94 | L43: =J43+J44+J45 -> 439973.19
D44: pleine 82 | F44: 1.002 | G44: =K41 -> 208547 | J44: =G44*F44 -> 208964.09
D45: pointe 83 | F45: 1.002 | G45: =L41 -> 95080 | J45: =G45*F45 -> 95270.16
A46: EAU HOTEL M3 | F46: 12.67 | G46: =D41 -> 9900 | J46: =G46*F46 -> 125433 | L46: =J46 -> 125433
A47: GAZ Kg | F47: 9.65 | G47: =U41 -> 39659.9 | J47: =G47*F47 -> 382718.04 | L47: =J47 -> 382718.04

Sheet Suvi Gaz
D1: suivi Gaz
Q2: 803 | T2: 519 | W2: 800 | Z2: 802
B3: Relvé C1 | C3: cons C1 | D3: Relvé C2 | E3: cons C2 | F3: Relvé C3 | G3: cons C3 | H3: Relvé C4 | I3: cons C4 | J3: ∑ des relevés | K3: moyen general % | L3: con.j | M3: ∑ de volume en L | N3: cons./jen L | O3: cons./jen Kg | P3: cons./jen DH | Q3: livraison C1 | R3: %Avant | S3: % Après | T3: livraison C2 | U3: %Avant | V3: % Après | W3: livraison C3 | X3: %Avant | Y3: % Après | Z3: livraison C4 | AA3: %Avant | AB3: % Après | AC3: total livraison | AD3: moyen general % Avant L | AE3: moyen general % Aaprés L
A4: 43824 | B4: 39 | C4: =IF(AC4>0,((B4-R4)+(S4-B5)),IF(B5=0, ,(B4-B5))) -> 12 | D4: 40 | E4: =IF(AC4>0,((D4-U4)+(V4-D5)),IF(D5=0, ,(D4-D5))) -> 8 | F4: 35 | G4: =IF(AC4>0,((F4-X4)+(Y4-F5)),IF(F5=0, ,(F4-F5))) -> 13 | H4: 39 | I4: =IF(AC4>0,((H4-AA4)+(AB4-H5)),IF(H5=0, ,(H4-H5))) -> 12 | J4: =B4+D4+F4+H4 -> 153 | K4: =J4/4 -> 38.25 | L4: =IF(AC4>0,((K4-AD4)+(AE4-K5)),IF(K5=0, ,(K4-K5))) -> 11.25 | M4: =7000*4 -> 28000 | N4: =L4*M4/100 -> 3150 | O4: =N4*0.53 -> 1669.5 | P4: =O4*9.65 -> 16110.675 | Q4: 4181 | R4: 37 | S4: 85 | T4: 3938 | U4: 40 | V4: 85 | W4: 4495 | X4: 33 | Y4: 85 | Z4: 4101 | AA4: 38 | AB4: 85 | AC4: =Q4+T4+W4+Z4 -> 16715 | AD4: =(R4+U4+X4+AA4)/4 -> 37 | AE4: =(S4+V4+Y4+AB4)/4 -> 85
A5: =(A4+1) -> 43825 | B5: 75 | C5: =IF(AC5>0,((B5-R5)+(S5-B6)),IF(B6=0, ,(B5-B6))) -> 6 | D5: 77 | E5: =IF(AC5>0,((D5-U5)+(V5-D6)),IF(D6=0, ,(D5-D6))) -> 5 | F5: 74 | G5: =IF(AC5>0,((F5-X5)+(Y5-F6)),IF(F6=0, ,(F5-F6))) -> 8 | H5: 74 | I5: =IF(AC5>0,((H5-AA5)+(AB5-H6)),IF(H6=0, ,(H5-H6))) -> 6 | J5: =B5+D5+F5+H5 -> 300 | K5: =J5/4 -> 75 | L5: =IF(AC5>0,((K5-AD5)+(AE5-K6)),IF(K6=0, ,(K5-K6))) -> 6.25 | M5: =7000*4 -> 28000 | N5: =L5*M5/100 -> 1750 | O5: =N5*0.53 -> 927.5 | P5: =O5*9.65 -> 8950.375 | AC5: =Q5+T5+W5+Z5 -> 0 | AD5: =(R5+U5+X5+AA5)/4 -> 0 | AE5: =(S5+V5+Y5+AB5)/4 -> 0
A6: =(A5+1) -> 43826 | B6: 69 | C6: =IF(AC6>0,((B6-R6)+(S6-B7)),IF(B7=0, ,(B6-B7))) -> 10 | D6: 72 | E6: =IF(AC6>0,((D6-U6)+(V6-D7)),IF(D7=0, ,(D6-D7))) -> 11 | F6: 66 | G6: =IF(AC6>0,((F6-X6)+(Y6-F7)),IF(F7=0, ,(F6-F7))) -> 11 | H6: 68 | I6: =IF(AC6>0,((H6-AA6)+(AB6-H7)),IF(H7=0, ,(H6-H7))) -> 11 | J6: =B6+D6+F6+H6 -> 275 | K6: =J6/4 -> 68.75 | L6: =IF(AC6>0,((K6-AD6)+(AE6-K7)),IF(K7=0, ,(K6-K7))) -> 10.75 | M6: =7000*4 -> 28000 | N6: =L6*M6/100 -> 3010 | O6: =N6*0.53 -> 1595.3 | P6: =O6*9.65 -> 15394.645 | AC6: =Q6+T6+W6+Z6 -> 0 | AD6: =(R6+U6+X6+AA6)/4 -> 0 | AE6: =(S6+V6+Y6+AB6)/4 -> 0
A7: =(A6+1) -> 43827 | B7: 59 | C7: =IF(AC7>0,((B7-R7)+(S7-B8)),IF(B8=0, ,(B7-B8))) -> 12 | D7: 61 | E7: =IF(AC7>0,((D7-U7)+(V7-D8)),IF(D8=0, ,(D7-D8))) -> 12 | F7: 55 | G7: =IF(AC7>0,((F7-X7)+(Y7-F8)),IF(F8=0, ,(F7-F8))) -> 12 | H7: 57 | I7: =IF(AC7>0,((H7-AA7)+(AB7-H8)),IF(H8=0, ,(H7-H8))) -> 13 | J7: =B7+D7+F7+H7 -> 232 | K7: =J7/4 -> 58 | L7: =IF(AC7>0,((K7-AD7)+(AE7-K8)),IF(K8=0, ,(K7-K8))) -> 12.25 | M7: =7000*4 -> 28000 | N7: =L7*M7/100 -> 3430 | O7: =N7*0.53 -> 1817.9 | P7: =O7*9.65 -> 17542.735 | AC7: =Q7+T7+W7+Z7 -> 0 | AD7: =(R7+U7+X7+AA7)/4 -> 0 | AE7: =(S7+V7+Y7+AB7)/4 -> 0
A8: =(A7+1) -> 43828 | B8: 47 | C8: =IF(AC8>0,((B8-R8)+(S8-B9)),IF(B9=0, ,(B8-B9))) -> 7 | D8: 49 | E8: =IF(AC8>0,((D8-U8)+(V8-D9)),IF(D9=0, ,(D8-D9))) -> 3 | F8: 43 | G8: =IF(AC8>0,((F8-X8)+(Y8-F9)),IF(F9=0, ,(F8-F9))) -> 9 | H8: 44 | I8: =IF(AC8>0,((H8-AA8)+(AB8-H9)),IF(H9=0, ,(H8-H9))) -> 3 | J8: =B8+D8+F8+H8 -> 183 | K8: 45.75 | L8: =IF(AC8>0,((K8-AD8)+(AE8-K9)),IF(K9=0, ,(K8-K9))) -> 5.5 | M8: 28000 | N8: =L8*M8/100 -> 1540 | O8: =N8*0.53 -> 816.2 | P8: =O8*9.65 -> 7876.33 | Q8: 3207 | R8: 46 | S8: 86 | T8: 3023 | U8: 50 | V8: 86 | W8: 3410 | X8: 42 | Y8: 86 | Z8: 3415 | AA8: 45 | AB8: 87 | AC8: =Q8+T8+W8+Z8 -> 13055 | AD8: =(R8+U8+X8+AA8)/4 -> 45.75 | AE8: =(S8+V8+Y8+AB8)/4 -> 86.25
A9: =(A8+1) -> 43829 | B9: 80 | C9: =IF(AC9>0,((B9-R9)+(S9-B10)),IF(B10=0, ,(B9-B10))) -> 10 | D9: 82 | E9: =IF(AC9>0,((D9-U9)+(V9-D10)),IF(D10=0, ,(D9-D10))) -> 10 | F9: 78 | G9: =IF(AC9>0,((F9-X9)+(Y9-F10)),IF(F10=0, ,(F9-F10))) -> 13 | H9: 83 | I9: =IF(AC9>0,((H9-AA9)+(AB9-H10)),IF(H10=0, ,(H9-H10))) -> 15 | J9: =B9+D9+F9+H9 -> 323 | K9: 80.75 | L9: =IF(AC9>0,((K9-AD9)+(AE9-K10)),IF(K10=0, ,(K9-K10))) -> 12 | M9: 28000 | N9: =L9*M9/100 -> 3360 | O9: =N9*0.53 -> 1780.8 | P9: =O9*9.65 -> 17184.72 | AC9: =Q9+T9+W9+Z9 -> 0 | AD9: =(R9+U9+X9+AA9)/4 -> 0 | AE9: =(S9+V9+Y9+AB9)/4 -> 0
A10: =(A9+1) -> 43830 | B10: 70 | C10: =IF(AC10>0,((B10-R10)+(S10-B11)),IF(B11=0, ,(B10-B11))) -> 10 | D10: 72 | E10: =IF(AC10>0,((D10-U10)+(V10-D11)),IF(D11=0, ,(D10-D11))) -> 10 | F10: 65 | G10: =IF(AC10>0,((F10-X10)+(Y10-F11)),IF(F11=0, ,(F10-F11))) -> 9 | H10: 68 | I10: =IF(AC10>0,((H10-AA10)+(AB10-H11)),IF(H11=0, ,(H10-H11))) -> 13 | J10: =B10+D10+F10+H10 -> 275 | K10: 68.75 | L10: =IF(AC10>0,((K10-AD10)+(AE10-K11)),IF(K11=0, ,(K10-K11))) -> 10.5 | M10: 28000 | N10: =L10*M10/100 -> 2940 | O10: =N10*0.53 -> 1558.2 | P10: =O10*9.65 -> 15036.63 | AC10: =Q10+T10+W10+Z10 -> 0 | AD10: =(R10+U10+X10+AA10)/4 -> 0 | AE10: =(S10+V10+Y10+AB10)/4 -> 0
A11: =(A10+1) -> 43831 | B11: 60 | C11: =IF(AC11>0,((B11-R11)+(S11-B12)),IF(B12=0, ,(B11-B12))) -> 7 | D11: 62 | E11: =IF(AC11>0,((D11-U11)+(V11-D12)),IF(D12=0, ,(D11-D12))) -> 5 | F11: 56 | G11: =IF(AC11>0,((F11-X11)+(Y11-F12)),IF(F12=0, ,(F11-F12))) -> 10 | H11: 55 | I11: =IF(AC11>0,((H11-AA11)+(AB11-H12)),IF(H12=0, ,(H11-H12))) -> 1 | J11: =B11+D11+F11+H11 -> 233 | K11: =J11/4 -> 58.25 | L11: =IF(AC11>0,((K11-AD11)+(AE11-K12)),IF(K12=0, ,(K11-K12))) -> 5.75 | M11: =7000*4 -> 28000 | N11: =L11*M11/100 -> 1610 | O11: =N11*0.53 -> 853.3 | P11: =O11*9.65 -> 8234.345 | Q11: 2701 | R11: 55 | S11: 86 | T11: 2315 | U11: 58 | V11: 86 | W11: 2819 | X11: 50 | Y11: 85 | Z11: 2847 | AA11: 55 | AB11: 86 | AC11: =Q11+T11+W11+Z11 -> 10682 | AD11: =(R11+U11+X11+AA11)/4 -> 54.5 | AE11: =(S11+V11+Y11+AB11)/4 -> 85.75
A12: =(A11+1) -> 43832 | B12: 84 | C12: =IF(AC12>0,((B12-R12)+(S12-B13)),IF(B13=0, ,(B12-B13))) -> 12 | D12: 85 | E12: =IF(AC12>0,((D12-U12)+(V12-D13)),IF(D13=0, ,(D12-D13))) -> 10 | F12: 81 | G12: =IF(AC12>0,((F12-X12)+(Y12-F13)),IF(F13=0, ,(F12-F13))) -> 13 | H12: 85 | I12: =IF(AC12>0,((H12-AA12)+(AB12-H13)),IF(H13=0, ,(H12-H13))) -> 14 | J12: =B12+D12+F12+H12 -> 335 | K12: =J12/4 -> 83.75 | L12: =IF(AC12>0,((K12-AD12)+(AE12-K13)),IF(K13=0, ,(K12-K13))) -> 12.25 | M12: =7000*4 -> 28000 | N12: =L12*M12/100 -> 3430 | O12: =N12*0.53 -> 1817.9 | P12: =O12*9.65 -> 17542.735 | AC12: =Q12+T12+W12+Z12 -> 0 | AD12: =(R12+U12+X12+AA12)/4 -> 0 | AE12: =(S12+V12+Y12+AB12)/4 -> 0
A13: =(A12+1) -> 43833 | B13: 72 | C13: =IF(AC13>0,((B13-R13)+(S13-B14)),IF(B14=0, ,(B13-B14))) -> 12 | D13: 75 | E13: =IF(AC13>0,((D13-U13)+(V13-D14)),IF(D14=0, ,(D13-D14))) -> 11 | F13: 68 | G13: =IF(AC13>0,((F13-X13)+(Y13-F14)),IF(F14=0, ,(F13-F14))) -> 12 | H13: 71 | I13: =IF(AC13>0,((H13-AA13)+(AB13-H14)),IF(H14=0, ,(H13-H14))) -> 10 | J13: =B13+D13+F13+H13 -> 286 | K13: =J13/4 -> 71.5 | L13: =IF(AC13>0,((K13-AD13)+(AE13-K14)),IF(K14=0, ,(K13-K14))) -> 11.25 | M13: =7000*4 -> 28000 | N13: =L13*M13/100 -> 3150 | O13: =N13*0.53 -> 1669.5 | P13: =O13*9.65 -> 16110.675 | AC13: =Q13+T13+W13+Z13 -> 0 | AD13: =(R13+U13+X13+AA13)/4 -> 0 | AE13: =(S13+V13+Y13+AB13)/4 -> 0
A14: =(A13+1) -> 43834 | B14: 60 | C14: =IF(AC14>0,((B14-R14)+(S14-B15)),IF(B15=0, ,(B14-B15))) -> 12 | D14: 64 | E14: =IF(AC14>0,((D14-U14)+(V14-D15)),IF(D15=0, ,(D14-D15))) -> 14 | F14: 56 | G14: =IF(AC14>0,((F14-X14)+(Y14-F15)),IF(F15=0, ,(F14-F15))) -> 13 | H14: 61 | I14: =IF(AC14>0,((H14-AA14)+(AB14-H15)),IF(H15=0, ,(H14-H15))) -> 12 | J14: =B14+D14+F14+H14 -> 241 | K14: =J14/4 -> 60.25 | L14: =IF(AC14>0,((K14-AD14)+(AE14-K15)),IF(K15=0, ,(K14-K15))) -> 12.75 | M14: =7000*4 -> 28000 | N14: =L14*M14/100 -> 3570 | O14: =N14*0.53 -> 1892.1 | P14: =O14*9.65 -> 18258.765 | AC14: =Q14+T14+W14+Z14 -> 0 | AD14: =(R14+U14+X14+AA14)/4 -> 0 | AE14: =(S14+V14+Y14+AB14)/4 -> 0
A15: =(A14+1) -> 43835 | B15: 48 | C15: =IF(AC15>0,((B15-R15)+(S15-B16)),IF(B16=0, ,(B15-B16))) -> 8 | D15: 50 | E15: =IF(AC15>0,((D15-U15)+(V15-D16)),IF(D16=0, ,(D15-D16))) -> 7 | F15: 43 | G15: =IF(AC15>0,((F15-X15)+(Y15-F16)),IF(F16=0, ,(F15-F16))) -> 8 | H15: 49 | I15: =IF(AC15>0,((H15-AA15)+(AB15-H16)),IF(H16=0, ,(H15-H16))) -> 13 | J15: =B15+D15+F15+H15 -> 190 | K15: =J15/4 -> 47.5 | L15: =IF(AC15>0,((K15-AD15)+(AE15-K16)),IF(K16=0, ,(K15-K16))) -> 9 | M15: =7000*4 -> 28000 | N15: =L15*M15/100 -> 2520 | O15: =N15*0.53 -> 1335.6 | P15: =O15*9.65 -> 12888.54 | Q15: 1591 | R15: 45 | S15: 85 | T15: 1532 | U15: 48 | V15: 85 | W15: 1690 | X15: 42 | Y15: 85 | Z15: 1623 | AA15: 42 | AB15: 85 | AC15: =Q15+T15+W15+Z15 -> 6436 | AD15: =(R15+U15+X15+AA15)/4 -> 44.25 | AE15: =(S15+V15+Y15+AB15)/4 -> 85
A16: =(A15+1) -> 43836 | B16: 80 | C16: =IF(AC16>0,((B16-R16)+(S16-B17)),IF(B17=0, ,(B16-B17))) -> 10 | D16: 80 | E16: =IF(AC16>0,((D16-U16)+(V16-D17)),IF(D17=0, ,(D16-D17))) -> 10 | F16: 78 | G16: =IF(AC16>0,((F16-X16)+(Y16-F17)),IF(F17=0, ,(F16-F17))) -> 11 | H16: 79 | I16: =IF(AC16>0,((H16-AA16)+(AB16-H17)),IF(H17=0, ,(H16-H17))) -> 12 | J16: =B16+D16+F16+H16 -> 317 | K16: =J16/4 -> 79.25 | L16: =IF(AC16>0,((K16-AD16)+(AE16-K17)),IF(K17=0, ,(K16-K17))) -> 10.75 | M16: =7000*4 -> 28000 | N16: =L16*M16/100 -> 3010 | O16: =N16*0.53 -> 1595.3 | P16: =O16*9.65 -> 15394.645 | AC16: =Q16+T16+W16+Z16 -> 0 | AD16: =(R16+U16+X16+AA16)/4 -> 0 | AE16: =(S16+V16+Y16+AB16)/4 -> 0
A17: =(A16+1) -> 43837 | B17: 70 | C17: =IF(AC17>0,((B17-R17)+(S17-B18)),IF(B18=0, ,(B17-B18))) -> 10 | D17: 70 | E17: =IF(AC17>0,((D17-U17)+(V17-D18)),IF(D18=0, ,(D17-D18))) -> 8 | F17: 67 | G17: =IF(AC17>0,((F17-X17)+(Y17-F18)),IF(F18=0, ,(F17-F18))) -> 9 | H17: 67 | I17: =IF(AC17>0,((H17-AA17)+(AB17-H18)),IF(H18=0, ,(H17-H18))) -> 8 | J17: =B17+D17+F17+H17 -> 274 | K17: =J17/4 -> 68.5 | L17: =IF(AC17>0,((K17-AD17)+(AE17-K18)),IF(K18=0, ,(K17-K18))) -> 8.75 | M17: =7000*4 -> 28000 | N17: =L17*M17/100 -> 2450 | O17: =N17*0.53 -> 1298.5 | P17: =O17*9.65 -> 12530.525 | AC17: =Q17+T17+W17+Z17 -> 0 | AD17: =(R17+U17+X17+AA17)/4 -> 0 | AE17: =(S17+V17+Y17+AB17)/4 -> 0
A18: =(A17+1) -> 43838 | B18: 60 | C18: =IF(AC18>0,((B18-R18)+(S18-B19)),IF(B19=0, ,(B18-B19))) -> 11 | D18: 62 | E18: =IF(AC18>0,((D18-U18)+(V18-D19)),IF(D19=0, ,(D18-D19))) -> 12 | F18: 58 | G18: =IF(AC18>0,((F18-X18)+(Y18-F19)),IF(F19=0, ,(F18-F19))) -> 16 | H18: 59 | I18: =IF(AC18>0,((H18-AA18)+(AB18-H19)),IF(H19=0, ,(H18-H19))) -> 14 | J18: =B18+D18+F18+H18 -> 239 | K18: =J18/4 -> 59.75 | L18: =IF(AC18>0,((K18-AD18)+(AE18-K19)),IF(K19=0, ,(K18-K19))) -> 13.25 | M18: =7000*4 -> 28000 | N18: =L18*M18/100 -> 3710 | O18: =N18*0.53 -> 1966.3 | P18: =O18*9.65 -> 18974.795 | AC18: =Q18+T18+W18+Z18 -> 0 | AD18: =(R18+U18+X18+AA18)/4 -> 0 | AE18: =(S18+V18+Y18+AB18)/4 -> 0
A19: =(A18+1) -> 43839 | B19: 49 | C19: =IF(AC19>0,((B19-R19)+(S19-B20)),IF(B20=0, ,(B19-B20))) -> 11 | D19: 50 | E19: =IF(AC19>0,((D19-U19)+(V19-D20)),IF(D20=0, ,(D19-D20))) -> 11 | F19: 42 | G19: =IF(AC19>0,((F19-X19)+(Y19-F20)),IF(F20=0, ,(F19-F20))) -> 7 | H19: 45 | I19: =IF(AC19>0,((H19-AA19)+(AB19-H20)),IF(H20=0, ,(H19-H20))) -> 9 | J19: =B19+D19+F19+H19 -> 186 | K19: =J19/4 -> 46.5 | L19: =IF(AC19>0,((K19-AD19)+(AE19-K20)),IF(K20=0, ,(K19-K20))) -> 9.5 | M19: =7000*4 -> 28000 | N19: =L19*M19/100 -> 2660 | O19: =N19*0.53 -> 1409.8 | P19: =O19*9.65 -> 13604.57 | AC19: =Q19+T19+W19+Z19 -> 0 | AD19: =(R19+U19+X19+AA19)/4 -> 0 | AE19: =(S19+V19+Y19+AB19)/4 -> 0
A20: =(A19+1) -> 43840 | B20: 38 | C20: =IF(AC20>0,((B20-R20)+(S20-B21)),IF(B21=0, ,(B20-B21))) -> 13 | D20: 39 | E20: =IF(AC20>0,((D20-U20)+(V20-D21)),IF(D21=0, ,(D20-D21))) -> 12 | F20: 35 | G20: =IF(AC20>0,((F20-X20)+(Y20-F21)),IF(F21=0, ,(F20-F21))) -> 15 | H20: 36 | I20: =IF(AC20>0,((H20-AA20)+(AB20-H21)),IF(H21=0, ,(H20-H21))) -> 15 | J20: =B20+D20+F20+H20 -> 148 | K20: =J20/4 -> 37 | L20: =IF(AC20>0,((K20-AD20)+(AE20-K21)),IF(K21=0, ,(K20-K21))) -> 13.75 | M20: =7000*4 -> 28000 | N20: =L20*M20/100 -> 3850 | O20: =N20*0.53 -> 2040.5 | P20: =O20*9.65 -> 19690.825 | AC20: =Q20+T20+W20+Z20 -> 0 | AD20: =(R20+U20+X20+AA20)/4 -> 0 | AE20: =(S20+V20+Y20+AB20)/4 -> 0
A21: =(A20+1) -> 43841 | B21: 25 | C21: =IF(AC21>0,((B21-R21)+(S21-B22)),IF(B22=0, ,(B21-B22))) -> 17 | D21: 27 | E21: =IF(AC21>0,((D21-U21)+(V21-D22)),IF(D22=0, ,(D21-D22))) -> 16 | F21: 20 | G21: =IF(AC21>0,((F21-X21)+(Y21-F22)),IF(F22=0, ,(F21-F22))) -> 15 | H21: 21 | I21: =IF(AC21>0,((H21-AA21)+(AB21-H22)),IF(H22=0, ,(H21-H22))) -> -6 | J21: =B21+D21+F21+H21 -> 93 | K21: =J21/4 -> 23.25 | L21: =IF(AC21>0,((K21-AD21)+(AE21-K22)),IF(K22=0, ,(K21-K22))) -> 10.5 | M21: =7000*4 -> 28000 | N21: =L21*M21/100 -> 2940 | O21: =N21*0.53 -> 1558.2 | P21: =O21*9.65 -> 15036.63 | Q21: 2504 | R21: 23 | S21: 85 | T21: 2434 | U21: 25 | V21: 85 | W21: 2494 | X21: 22 | Y21: 85 | Z21: 1595 | AA21: 20 | AB21: 62 | AC21: =Q21+T21+W21+Z21 -> 9027 | AD21: =(R21+U21+X21+AA21)/4 -> 22.5 | AE21: =(S21+V21+Y21+AB21)/4 -> 79.25
A22: =(A21+1) -> 43842 | B22: 70 | C22: =IF(AC22>0,((B22-R22)+(S22-B23)),IF(B23=0, ,(B22-B23))) -> 10 | D22: 71 | E22: =IF(AC22>0,((D22-U22)+(V22-D23)),IF(D23=0, ,(D22-D23))) -> 9 | F22: 68 | G22: =IF(AC22>0,((F22-X22)+(Y22-F23)),IF(F23=0, ,(F22-F23))) -> 9 | H22: 69 | I22: =IF(AC22>0,((H22-AA22)+(AB22-H23)),IF(H23=0, ,(H22-H23))) -> 9 | J22: =B22+D22+F22+H22 -> 278 | K22: =J22/4 -> 69.5 | L22: =IF(AC22>0,((K22-AD22)+(AE22-K23)),IF(K23=0, ,(K22-K23))) -> 9.25 | M22: =7000*4 -> 28000 | N22: =L22*M22/100 -> 2590 | O22: =N22*0.53 -> 1372.7 | P22: =O22*9.65 -> 13246.555 | AC22: =Q22+T22+W22+Z22 -> 0 | AD22: =(R22+U22+X22+AA22)/4 -> 0 | AE22: =(S22+V22+Y22+AB22)/4 -> 0
A23: =(A22+1) -> 43843 | B23: 60 | C23: =IF(AC23>0,((B23-R23)+(S23-B24)),IF(B24=0, ,(B23-B24))) -> 13 | D23: 62 | E23: =IF(AC23>0,((D23-U23)+(V23-D24)),IF(D24=0, ,(D23-D24))) -> 10 | F23: 59 | G23: =IF(AC23>0,((F23-X23)+(Y23-F24)),IF(F24=0, ,(F23-F24))) -> 15 | H23: 60 | I23: =IF(AC23>0,((H23-AA23)+(AB23-H24)),IF(H24=0, ,(H23-H24))) -> 12 | J23: =B23+D23+F23+H23 -> 241 | K23: =J23/4 -> 60.25 | L23: =IF(AC23>0,((K23-AD23)+(AE23-K24)),IF(K24=0, ,(K23-K24))) -> 12.5 | M23: =7000*4 -> 28000 | N23: =L23*M23/100 -> 3500 | O23: =N23*0.53 -> 1855 | P23: =O23*9.65 -> 17900.75 | AC23: =Q23+T23+W23+Z23 -> 0 | AD23: =(R23+U23+X23+AA23)/4 -> 0 | AE23: =(S23+V23+Y23+AB23)/4 -> 0
A24: =(A23+1) -> 43844 | B24: 47 | C24: =IF(AC24>0,((B24-R24)+(S24-B25)),IF(B25=0, ,(B24-B25))) -> 11 | D24: 52 | E24: =IF(AC24>0,((D24-U24)+(V24-D25)),IF(D25=0, ,(D24-D25))) -> 14 | F24: 44 | G24: =IF(AC24>0,((F24-X24)+(Y24-F25)),IF(F25=0, ,(F24-F25))) -> 12 | H24: 48 | I24: =IF(AC24>0,((H24-AA24)+(AB24-H25)),IF(H25=0, ,(H24-H25))) -> 9 | J24: =B24+D24+F24+H24 -> 191 | K24: =J24/4 -> 47.75 | L24: =IF(AC24>0,((K24-AD24)+(AE24-K25)),IF(K25=0, ,(K24-K25))) -> 11.5 | M24: =7000*4 -> 28000 | N24: =L24*M24/100 -> 3220 | O24: =N24*0.53 -> 1706.6 | P24: =O24*9.65 -> 16468.69 | AC24: =Q24+T24+W24+Z24 -> 0 | AD24: =(R24+U24+X24+AA24)/4 -> 0 | AE24: =(S24+V24+Y24+AB24)/4 -> 0
A25: =(A24+1) -> 43845 | B25: 36 | C25: =IF(AC25>0,((B25-R25)+(S25-B26)),IF(B26=0, ,(B25-B26))) -> 7 | D25: 38 | E25: =IF(AC25>0,((D25-U25)+(V25-D26)),IF(D26=0, ,(D25-D26))) -> 8 | F25: 32 | G25: =IF(AC25>0,((F25-X25)+(Y25-F26)),IF(F26=0, ,(F25-F26))) -> 7 | H25: 39 | I25: =IF(AC25>0,((H25-AA25)+(AB25-H26)),IF(H26=0, ,(H25-H26))) -> 7 | J25: =B25+D25+F25+H25 -> 145 | K25: =J25/4 -> 36.25 | L25: =IF(AC25>0,((K25-AD25)+(AE25-K26)),IF(K26=0, ,(K25-K26))) -> 7.25 | M25: =7000*4 -> 28000 | N25: =L25*M25/100 -> 2030 | O25: =N25*0.53 -> 1075.9 | P25: =O25*9.65 -> 10382.435 | Q25: 3501 | R25: 35 | S25: 81 | T25: 3500 | U25: 38 | V25: 85 | W25: 3501 | X25: 32 | Y25: 80 | Z25: 3303 | AA25: 38 | AB25: 80 | AC25: =Q25+T25+W25+Z25 -> 13805 | AD25: =(R25+U25+X25+AA25)/4 -> 35.75 | AE25: =(S25+V25+Y25+AB25)/4 -> 81.5
A26: =(A25+1) -> 43846 | B26: 75 | C26: =IF(AC26>0,((B26-R26)+(S26-B27)),IF(B27=0, ,(B26-B27))) -> 10 | D26: 77 | E26: =IF(AC26>0,((D26-U26)+(V26-D27)),IF(D27=0, ,(D26-D27))) -> 10 | F26: 73 | G26: =IF(AC26>0,((F26-X26)+(Y26-F27)),IF(F27=0, ,(F26-F27))) -> 11 | H26: 74 | I26: =IF(AC26>0,((H26-AA26)+(AB26-H27)),IF(H27=0, ,(H26-H27))) -> 9 | J26: =B26+D26+F26+H26 -> 299 | K26: =J26/4 -> 74.75 | L26: =IF(AC26>0,((K26-AD26)+(AE26-K27)),IF(K27=0, ,(K26-K27))) -> 10 | M26: =7000*4 -> 28000 | N26: =L26*M26/100 -> 2800 | O26: =N26*0.53 -> 1484 | P26: =O26*9.65 -> 14320.6 | AC26: =Q26+T26+W26+Z26 -> 0 | AD26: =(R26+U26+X26+AA26)/4 -> 0 | AE26: =(S26+V26+Y26+AB26)/4 -> 0
A27: =(A26+1) -> 43847 | B27: 65 | C27: =IF(AC27>0,((B27-R27)+(S27-B28)),IF(B28=0, ,(B27-B28))) -> 11 | D27: 67 | E27: =IF(AC27>0,((D27-U27)+(V27-D28)),IF(D28=0, ,(D27-D28))) -> 10 | F27: 62 | G27: =IF(AC27>0,((F27-X27)+(Y27-F28)),IF(F28=0, ,(F27-F28))) -> 11 | H27: 65 | I27: =IF(AC27>0,((H27-AA27)+(AB27-H28)),IF(H28=0, ,(H27-H28))) -> 12 | J27: =B27+D27+F27+H27 -> 259 | K27: =J27/4 -> 64.75 | L27: =IF(AC27>0,((K27-AD27)+(AE27-K28)),IF(K28=0, ,(K27-K28))) -> 11 | M27: =7000*4 -> 28000 | N27: =L27*M27/100 -> 3080 | O27: =N27*0.53 -> 1632.4 | P27: =O27*9.65 -> 15752.66 | AC27: =Q27+T27+W27+Z27 -> 0 | AD27: =(R27+U27+X27+AA27)/4 -> 0 | AE27: =(S27+V27+Y27+AB27)/4 -> 0
A28: =(A27+1) -> 43848 | B28: 54 | C28: =IF(AC28>0,((B28-R28)+(S28-B29)),IF(B29=0, ,(B28-B29))) -> 11 | D28: 57 | E28: =IF(AC28>0,((D28-U28)+(V28-D29)),IF(D29=0, ,(D28-D29))) -> 10 | F28: 51 | G28: =IF(AC28>0,((F28-X28)+(Y28-F29)),IF(F29=0, ,(F28-F29))) -> 10 | H28: 53 | I28: =IF(AC28>0,((H28-AA28)+(AB28-H29)),IF(H29=0, ,(H28-H29))) -> 10 | J28: =B28+D28+F28+H28 -> 215 | K28: =J28/4 -> 53.75 | L28: =IF(AC28>0,((K28-AD28)+(AE28-K29)),IF(K29=0, ,(K28-K29))) -> 10.25 | M28: =7000*4 -> 28000 | N28: =L28*M28/100 -> 2870 | O28: =N28*0.53 -> 1521.1 | P28: =O28*9.65 -> 14678.615 | AC28: =Q28+T28+W28+Z28 -> 0 | AD28: =(R28+U28+X28+AA28)/4 -> 0 | AE28: =(S28+V28+Y28+AB28)/4 -> 0
A29: =(A28+1) -> 43849 | B29: 43 | C29: =IF(AC29>0,((B29-R29)+(S29-B30)),IF(B30=0, ,(B29-B30))) -> 9 | D29: 47 | E29: =IF(AC29>0,((D29-U29)+(V29-D30)),IF(D30=0, ,(D29-D30))) -> 8 | F29: 41 | G29: =IF(AC29>0,((F29-X29)+(Y29-F30)),IF(F30=0, ,(F29-F30))) -> 9 | H29: 43 | I29: =IF(AC29>0,((H29-AA29)+(AB29-H30)),IF(H30=0, ,(H29-H30))) -> 3 | J29: =B29+D29+F29+H29 -> 174 | K29: =J29/4 -> 43.5 | L29: =IF(AC29>0,((K29-AD29)+(AE29-K30)),IF(K30=0, ,(K29-K30))) -> 7.25 | M29: =7000*4 -> 28000 | N29: =L29*M29/100 -> 2030 | O29: =N29*0.53 -> 1075.9 | P29: =O29*9.65 -> 10382.435 | Q29: 2227 | R29: 39 | S29: 80 | T29: 1787 | U29: 45 | V29: 85 | W29: 1537 | X29: 42 | Y29: 83 | Z29: 1062 | AA29: 43 | AB29: 76 | AC29: =Q29+T29+W29+Z29 -> 6613 | AD29: =(R29+U29+X29+AA29)/4 -> 42.25 | AE29: =(S29+V29+Y29+AB29)/4 -> 81
A30: =(A29+1) -> 43850 | B30: 75 | C30: =IF(AC30>0,((B30-R30)+(S30-B31)),IF(B31=0, ,(B30-B31))) -> 7 | D30: 79 | E30: =IF(AC30>0,((D30-U30)+(V30-D31)),IF(D31=0, ,(D30-D31))) -> 9 | F30: 73 | G30: =IF(AC30>0,((F30-X30)+(Y30-F31)),IF(F31=0, ,(F30-F31))) -> 8 | H30: 73 | I30: =IF(AC30>0,((H30-AA30)+(AB30-H31)),IF(H31=0, ,(H30-H31))) -> 6 | J30: =B30+D30+F30+H30 -> 300 | K30: =J30/4 -> 75 | L30: =IF(AC30>0,((K30-AD30)+(AE30-K31)),IF(K31=0, ,(K30-K31))) -> 7.5 | M30: =7000*4 -> 28000 | N30: =L30*M30/100 -> 2100 | O30: =N30*0.53 -> 1113 | P30: =O30*9.65 -> 10740.45 | AC30: =Q30+T30+W30+Z30 -> 0 | AD30: =(R30+U30+X30+AA30)/4 -> 0 | AE30: =(S30+V30+Y30+AB30)/4 -> 0
A31: =(A30+1) -> 43851 | B31: 68 | C31: =IF(AC31>0,((B31-R31)+(S31-B32)),IF(B32=0, ,(B31-B32))) -> 7 | D31: 70 | E31: =IF(AC31>0,((D31-U31)+(V31-D32)),IF(D32=0, ,(D31-D32))) -> 7 | F31: 65 | G31: =IF(AC31>0,((F31-X31)+(Y31-F32)),IF(F32=0, ,(F31-F32))) -> 7 | H31: 67 | I31: =IF(AC31>0,((H31-AA31)+(AB31-H32)),IF(H32=0, ,(H31-H32))) -> 6 | J31: =B31+D31+F31+H31 -> 270 | K31: =J31/4 -> 67.5 | L31: =IF(AC31>0,((K31-AD31)+(AE31-K32)),IF(K32=0, ,(K31-K32))) -> 6.75 | M31: =7000*4 -> 28000 | N31: =L31*M31/100 -> 1890 | O31: =N31*0.53 -> 1001.7 | P31: =O31*9.65 -> 9666.405 | AC31: =Q31+T31+W31+Z31 -> 0 | AD31: =(R31+U31+X31+AA31)/4 -> 0 | AE31: =(S31+V31+Y31+AB31)/4 -> 0
A32: =(A31+1) -> 43852 | B32: 61 | C32: =IF(AC32>0,((B32-R32)+(S32-B33)),IF(B33=0, ,(B32-B33))) -> 4 | D32: 63 | E32: =IF(AC32>0,((D32-U32)+(V32-D33)),IF(D33=0, ,(D32-D33))) -> 3 | F32: 58 | G32: =IF(AC32>0,((F32-X32)+(Y32-F33)),IF(F33=0, ,(F32-F33))) -> 7 | H32: 61 | I32: =IF(AC32>0,((H32-AA32)+(AB32-H33)),IF(H33=0, ,(H32-H33))) -> 6 | J32: =B32+D32+F32+H32 -> 243 | K32: =J32/4 -> 60.75 | L32: =IF(AC32>0,((K32-AD32)+(AE32-K33)),IF(K33=0, ,(K32-K33))) -> 5 | M32: =7000*4 -> 28000 | N32: =L32*M32/100 -> 1400 | O32: =N32*0.53 -> 742 | P32: =O32*9.65 -> 7160.3 | AC32: =Q32+T32+W32+Z32 -> 0 | AD32: =(R32+U32+X32+AA32)/4 -> 0 | AE32: =(S32+V32+Y32+AB32)/4 -> 0
A33: =(A32+1) -> 43853 | B33: 57 | C33: =IF(AC33>0,((B33-R33)+(S33-B34)),IF(B34=0, ,(B33-B34))) -> 9 | D33: 60 | E33: =IF(AC33>0,((D33-U33)+(V33-D34)),IF(D34=0, ,(D33-D34))) -> 8 | F33: 51 | G33: =IF(AC33>0,((F33-X33)+(Y33-F34)),IF(F34=0, ,(F33-F34))) -> 5 | H33: 55 | I33: =IF(AC33>0,((H33-AA33)+(AB33-H34)),IF(H34=0, ,(H33-H34))) -> 8 | J33: =B33+D33+F33+H33 -> 223 | K33: =J33/4 -> 55.75 | L33: =IF(AC33>0,((K33-AD33)+(AE33-K34)),IF(K34=0, ,(K33-K34))) -> 7.5 | M33: =7000*4 -> 28000 | N33: =L33*M33/100 -> 2100 | O33: =N33*0.53 -> 1113 | P33: =O33*9.65 -> 10740.45 | AC33: =Q33+T33+W33+Z33 -> 0 | AD33: =(R33+U33+X33+AA33)/4 -> 0 | AE33: =(S33+V33+Y33+AB33)/4 -> 0
A34: =(A33+1) -> 43854 | B34: 48 | C34: =IF(AC34>0,((B34-R34)+(S34-B35)),IF(B35=0, ,(B34-B35))) -> 5 | D34: 52 | E34: =IF(AC34>0,((D34-U34)+(V34-D35)),IF(D35=0, ,(D34-D35))) -> 5 | F34: 46 | G34: =IF(AC34>0,((F34-X34)+(Y34-F35)),IF(F35=0, ,(F34-F35))) -> 5 | H34: 47 | I34: =IF(AC34>0,((H34-AA34)+(AB34-H35)),IF(H35=0, ,(H34-H35))) -> 5 | J34: =B34+D34+F34+H34 -> 193 | K34: =J34/4 -> 48.25 | L34: =IF(AC34>0,((K34-AD34)+(AE34-K35)),IF(K35=0, ,(K34-K35))) -> 5 | M34: =7000*4 -> 28000 | N34: =L34*M34/100 -> 1400 | O34: =N34*0.53 -> 742 | P34: =O34*9.65 -> 7160.3 | AC34: =Q34+T34+W34+Z34 -> 0 | AD34: =(R34+U34+X34+AA34)/4 -> 0 | AE34: =(S34+V34+Y34+AB34)/4 -> 0
A35: =(A34+1) -> 43855 | B35: 43 | C35: =IF(AC35>0,((B35-R35)+(S35-B36)),IF(B36=0, ,(B35-B36))) -> 6 | D35: 47 | E35: =IF(AC35>0,((D35-U35)+(V35-D36)),IF(D36=0, ,(D35-D36))) -> 7 | F35: 41 | G35: =IF(AC35>0,((F35-X35)+(Y35-F36)),IF(F36=0, ,(F35-F36))) -> 6 | H35: 42 | I35: =IF(AC35>0,((H35-AA35)+(AB35-H36)),IF(H36=0, ,(H35-H36))) -> 2 | J35: =B35+D35+F35+H35 -> 173 | K35: =J35/4 -> 43.25 | L35: =IF(AC35>0,((K35-AD35)+(AE35-K36)),IF(K36=0, ,(K35-K36))) -> 5.25 | M35: =7000*4 -> 28000 | N35: =L35*M35/100 -> 1470 | O35: =N35*0.53 -> 779.1 | P35: =O35*9.65 -> 7518.315 | AC35: =Q35+T35+W35+Z35 -> 0 | AD35: =(R35+U35+X35+AA35)/4 -> 0 | AE35: =(S35+V35+Y35+AB35)/4 -> 0
A36: =(A35+1) -> 43856 | B36: 37 | C36: =IF(AC36>0,((B36-R36)+(S36-B37)),IF(B37=0, ,(B36-B37))) -> 3 | D36: 40 | E36: =IF(AC36>0,((D36-U36)+(V36-D37)),IF(D37=0, ,(D36-D37))) -> 5 | F36: 35 | G36: =IF(AC36>0,((F36-X36)+(Y36-F37)),IF(F37=0, ,(F36-F37))) -> 3 | H36: 40 | I36: =IF(AC36>0,((H36-AA36)+(AB36-H37)),IF(H37=0, ,(H36-H37))) -> 8 | J36: =B36+D36+F36+H36 -> 152 | K36: =J36/4 -> 38 | L36: =IF(AC36>0,((K36-AD36)+(AE36-K37)),IF(K37=0, ,(K36-K37))) -> 4.75 | M36: =7000*4 -> 28000 | N36: =L36*M36/100 -> 1330 | O36: =N36*0.53 -> 704.9 | P36: =O36*9.65 -> 6802.285 | Q36: 2626 | R36: 34 | S36: 65 | T36: 2620 | U36: 33 | V36: 63 | W36: 2599 | X36: 38 | Y36: 68 | Z36: 2606 | AA36: 35 | AB36: 65 | AC36: =Q36+T36+W36+Z36 -> 10451 | AD36: =(R36+U36+X36+AA36)/4 -> 35 | AE36: =(S36+V36+Y36+AB36)/4 -> 65.25
A37: =(A36+1) -> 43857 | B37: 65 | C37: =IF(AC37>0,((B37-R37)+(S37-B38)),IF(B38=0, ,(B37-B38))) -> 7 | D37: 65 | E37: =IF(AC37>0,((D37-U37)+(V37-D38)),IF(D38=0, ,(D37-D38))) -> 4 | F37: 62 | G37: =IF(AC37>0,((F37-X37)+(Y37-F38)),IF(F38=0, ,(F37-F38))) -> 7 | H37: 62 | I37: =IF(AC37>0,((H37-AA37)+(AB37-H38)),IF(H38=0, ,(H37-H38))) -> 6 | J37: =B37+D37+F37+H37 -> 254 | K37: =J37/4 -> 63.5 | L37: =IF(AC37>0,((K37-AD37)+(AE37-K38)),IF(K38=0, ,(K37-K38))) -> 6 | M37: =7000*4 -> 28000 | N37: =L37*M37/100 -> 1680 | O37: =N37*0.53 -> 890.4 | P37: =O37*9.65 -> 8592.36 | AC37: =Q37+T37+W37+Z37 -> 0 | AD37: =(R37+U37+X37+AA37)/4 -> 0 | AE37: =(S37+V37+Y37+AB37)/4 -> 0
A38: =(A37+1) -> 43858 | B38: 58 | C38: =IF(AC38>0,((B38-R38)+(S38-B39)),IF(B39=0, ,(B38-B39))) -> 6 | D38: 61 | E38: =IF(AC38>0,((D38-U38)+(V38-D39)),IF(D39=0, ,(D38-D39))) -> 6 | F38: 55 | G38: =IF(AC38>0,((F38-X38)+(Y38-F39)),IF(F39=0, ,(F38-F39))) -> 6 | H38: 56 | I38: =IF(AC38>0,((H38-AA38)+(AB38-H39)),IF(H39=0, ,(H38-H39))) -> 6 | J38: =B38+D38+F38+H38 -> 230 | K38: =J38/4 -> 57.5 | L38: =IF(AC38>0,((K38-AD38)+(AE38-K39)),IF(K39=0, ,(K38-K39))) -> 6 | M38: =7000*4 -> 28000 | N38: =L38*M38/100 -> 1680 | O38: =N38*0.53 -> 890.4 | P38: =O38*9.65 -> 8592.36 | AC38: =Q38+T38+W38+Z38 -> 0 | AD38: =(R38+U38+X38+AA38)/4 -> 0 | AE38: =(S38+V38+Y38+AB38)/4 -> 0
A39: =(A38+1) -> 43859 | B39: 52 | C39: =IF(AC39>0,((B39-R39)+(S39-B40)),IF(B40=0, ,(B39-B40))) -> 6 | D39: 55 | E39: =IF(AC39>0,((D39-U39)+(V39-D40)),IF(D40=0, ,(D39-D40))) -> 5 | F39: 49 | G39: =IF(AC39>0,((F39-X39)+(Y39-F40)),IF(F40=0, ,(F39-F40))) -> 5 | H39: 50 | I39: =IF(AC39>0,((H39-AA39)+(AB39-H40)),IF(H40=0, ,(H39-H40))) -> 5 | J39: =B39+D39+F39+H39 -> 206 | K39: =J39/4 -> 51.5 | L39: =IF(AC39>0,((K39-AD39)+(AE39-K40)),IF(K40=0, ,(K39-K40))) -> 5.25 | M39: =7000*4 -> 28000 | N39: =L39*M39/100 -> 1470 | O39: =N39*0.53 -> 779.1 | P39: =O39*9.65 -> 7518.315 | AC39: =Q39+T39+W39+Z39 -> 0 | AD39: =(R39+U39+X39+AA39)/4 -> 0 | AE39: =(S39+V39+Y39+AB39)/4 -> 0
A40: =(A39+1) -> 43860 | B40: 46 | C40: =IF(AC40>0,((B40-R40)+(S40-B41)),IF(B41=0, ,(B40-B41))) -> 3 | D40: 50 | E40: =IF(AC40>0,((D40-U40)+(V40-D41)),IF(D41=0, ,(D40-D41))) -> 5 | F40: 44 | G40: =IF(AC40>0,((F40-X40)+(Y40-F41)),IF(F41=0, ,(F40-F41))) -> 9 | H40: 45 | I40: =IF(AC40>0,((H40-AA40)+(AB40-H41)),IF(H41=0, ,(H40-H41))) -> 7 | J40: =B40+D40+F40+H40 -> 185 | K40: =J40/4 -> 46.25 | L40: =IF(AC40>0,((K40-AD40)+(AE40-K41)),IF(K41=0, ,(K40-K41))) -> 6 | M40: =7000*4 -> 28000 | N40: =L40*M40/100 -> 1680 | O40: =N40*0.53 -> 890.4 | P40: =O40*9.65 -> 8592.36 | Q40: 3299 | R40: 45 | S40: 85 | T40: 3205 | U40: 45 | V40: 85 | W40: 3405 | X40: 40 | Y40: 85 | Z40: 3403 | AA40: 42 | AB40: 85 | AC40: =Q40+T40+W40+Z40 -> 13312 | AD40: =(R40+U40+X40+AA40)/4 -> 43 | AE40: =(S40+V40+Y40+AB40)/4 -> 85
...

Sheet Suivi EAU-ELEC
C1: Suivi Compteur d'Eau- électricité RADEEMA -
A7: Date | B7: Eau m3 | D7: Electricité Kw/h
B8: Compteur | C8: Consommation | D8: Compteur H.Creuse | E8: Consommation H.Creuse | F8: Compteur H.Pleine | G8: Consommation H.Pleine | H8: Compteur H.Pointe | I8: Consommation H.Pointe
A9: 43824 | B9: 100567 | C9: =IF(B10<B9,0,B10-B9)*10 -> 340 | D9: 15905064 | E9: =IF(D10<D9,0,D10-D9) -> 4393 | F9: 28752557 | G9: =IF(F10<F9,0,F10-F9) -> 6820 | H9: 12781536 | I9: =IF(H10<H9,0,H10-H9) -> 3745
A10: =A9+1 -> 43825 | B10: 100601 | C10: =IF(B11<B10,0,B11-B10)*10 -> 370 | D10: 15909457 | E10: =IF(D11<D10,0,D11-D10) -> 4070 | F10: 28759377 | G10: =IF(F11<F10,0,F11-F10) -> 6676 | H10: 12785281 | I10: =IF(H11<H10,0,H11-H10) -> 3146
A11: =A10+1 -> 43826 | B11: 100638 | C11: =IF(B12<B11,0,B12-B11)*10 -> 360 | D11: 15913527 | E11: =IF(D12<D11,0,D12-D11) -> 5510 | F11: 28766053 | G11: =IF(F12<F11,0,F12-F11) -> 6445 | H11: 12788427 | I11: =IF(H12<H11,0,H12-H11) -> 3175
A12: =A11+1 -> 43827 | B12: 100674 | C12: =IF(B13<B12,0,B13-B12)*10 -> 370 | D12: 15919037 | E12: =IF(D13<D12,0,D13-D12) -> 5495 | F12: 28772498 | G12: =IF(F13<F12,0,F13-F12) -> 7417 | H12: 12791602 | I12: =IF(H13<H12,0,H13-H12) -> 3561
A13: =A12+1 -> 43828 | B13: 100711 | C13: =IF(B14<B13,0,B14-B13)*10 -> 390 | D13: 15924532 | E13: =IF(D14<D13,0,D14-D13) -> 4276 | F13: 28779915 | G13: =IF(F14<F13,0,F14-F13) -> 8054 | H13: 12795163 | I13: =IF(H14<H13,0,H14-H13) -> 3419
A14: =A13+1 -> 43829 | B14: 100750 | C14: =IF(B15<B14,0,B15-B14)*10 -> 400 | D14: 15928808 | E14: =IF(D15<D14,0,D15-D14) -> 4107 | F14: 28787969 | G14: =IF(F15<F14,0,F15-F14) -> 6633 | H14: 12798582 | I14: =IF(H15<H14,0,H15-H14) -> 3347
A15: =A14+1 -> 43830 | B15: 100790 | C15: =IF(B16<B15,0,B16-B15)*10 -> 380 | D15: 15932915 | E15: =IF(D16<D15,0,D16-D15) -> 5589 | F15: 28794602 | G15: =IF(F16<F15,0,F16-F15) -> 6916 | H15: 12801929 | I15: =IF(H16<H15,0,H16-H15) -> 3385
A16: =A15+1 -> 43831 | B16: 100828 | C16: =IF(B17<B16,0,B17-B16)*10 -> 370 | D16: 15938504 | E16: =IF(D17<D16,0,D17-D16) -> 4606 | F16: 28801518 | G16: =IF(F17<F16,0,F17-F16) -> 6701 | H16: 12805314 | I16: =IF(H17<H16,0,H17-H16) -> 3142
A17: =A16+1 -> 43832 | B17: 100865 | C17: =IF(B18<B17,0,B18-B17)*10 -> 350 | D17: 15943110 | E17: =IF(D18<D17,0,D18-D17) -> 4289 | F17: 28808219 | G17: =IF(F18<F17,0,F18-F17) -> 6866 | H17: 12808456 | I17: =IF(H18<H17,0,H18-H17) -> 3145
A18: =A17+1 -> 43833 | B18: 100900 | C18: =IF(B19<B18,0,B19-B18)*10 -> 360 | D18: 15947399 | E18: =IF(D19<D18,0,D19-D18) -> 4218 | F18: 28815085 | G18: =IF(F19<F18,0,F19-F18) -> 6555 | H18: 12811601 | I18: =IF(H19<H18,0,H19-H18) -> 3007
A19: =A18+1 -> 43834 | B19: 100936 | C19: =IF(B20<B19,0,B20-B19)*10 -> 410 | D19: 15951617 | E19: =IF(D20<D19,0,D20-D19) -> 4290 | F19: 28821640 | G19: =IF(F20<F19,0,F20-F19) -> 6732 | H19: 12814608 | I19: =IF(H20<H19,0,H20-H19) -> 3045
A20: =A19+1 -> 43835 | B20: 100977 | C20: =IF(B21<B20,0,B21-B20)*10 -> 350 | D20: 15955907 | E20: =IF(D21<D20,0,D21-D20) -> 4138 | F20: 28828372 | G20: =IF(F21<F20,0,F21-F20) -> 6398 | H20: 12817653 | I20: =IF(H21<H20,0,H21-H20) -> 2973
A21: =A20+1 -> 43836 | B21: 101012 | C21: =IF(B22<B21,0,B22-B21)*10 -> 330 | D21: 15960045 | E21: =IF(D22<D21,0,D22-D21) -> 4186 | F21: 28834770 | G21: =IF(F22<F21,0,F22-F21) -> 6125 | H21: 12820626 | I21: =IF(H22<H21,0,H22-H21) -> 2906
... A47: =A46+1 -> 43862 | B47: 101841 | C47: =IF(B48<B47,0,B48-B47)*10 -> 0 | D47: 16072240 | E47: =IF(D48<D47,0,D48-D47) -> 0 | F47: 29009466 | G47: =IF(F48<F47,0,F48-F47) -> 0 | H47: 12899829 | I47: =IF(H48<H47,0,H48-H47) -> 0
C48: =SUM(C16:C46) -> 10130 | E48: =SUM(E16:E46) -> 133736 | G48: =SUM(G16:G46) -> 207948 | I48: =SUM(I16:I46) -> 94515
G58: =IF(F59<F58,0,F59-F58) -> 0

Sheet Feuil1
