Workbook

Sheet TOTAL
A1: Site Name | B1: Day | C1: Month | D1: Year | E1: Total Electricity Kwh | F1: Electricity Tariff ($/Kwh) | G1: LPG (Kg) | H1: LPG $/Kg | I1: District Energy Heating Kwh | J1: District Energy Heating $/Kwh | K1: Water Utility Supply (m3) m3 | L1: Water Utility Supply (m3) $/m3 | M1: Room Nights | N1: Total Guests | O1: Utilities day cost dh
A2: Marrakech | B2: 1 | C2: 2 | D2: 2019 | E2: ='Consommation du 01.02 au 28.02'!M10 -> 12994 | F2: 1.002 | G2: ='Consommation du 01.02 au 28.02'!U10 -> 742 | H2: 9.65 | I2: ='Consommation du 01.02 au 28.02'!Y10*1000 -> 15950 | J2: 0.53 | K2: ='Consommation du 01.02 au 28.02'!D10 -> 310 | L2: 12.67 | M2: ='Consommation du 01.02 au 28.02'!AC10 -> 56 | N2: 107 | O2: =E2*F2+G2*H2+I2*J2+K2*L2 -> 32561.488
A3: Marrakech | B3: =B2+1 -> 2 | C3: 2 | D3: 2019 | E3: ='Consommation du 01.02 au 28.02'!M11 -> 12797 | F3: 1.002 | G3: ='Consommation du 01.02 au 28.02'!U11 -> 742 | H3: 9.65 | I3: ='Consommation du 01.02 au 28.02'!Y11*1000 -> 16610 | J3: 0.53 | K3: ='Consommation du 01.02 au 28.02'!D11 -> 260 | L3: 12.67 | M3: ='Consommation du 01.02 au 28.02'!AC11 -> 72 | N3: 147 | O3: =E3*F3+G3*H3+I3*J3+K3*L3 -> 32080.394
A4: Marrakech | B4: =B3+1 -> 3 | C4: 2 | D4: 2019 | E4: ='Consommation du 01.02 au 28.02'!M12 -> 12695 | F4: 1.002 | G4: ='Consommation du 01.02 au 28.02'!U12 -> 593.6 | H4: 9.65 | I4: ='Consommation du 01.02 au 28.02'!Y12*1000 -> 16420 | J4: 0.53 | K4: ='Consommation du 01.02 au 28.02'!D12 -> 290 | L4: 12.67 | M4: ='Consommation du 01.02 au 28.02'!AC12 -> 71 | N4: 144 | O4: =E4*F4+G4*H4+I4*J4+K4*L4 -> 30825.53
A5: Marrakech | B5: =B4+1 -> 4 | C5: 2 | D5: 2019 | E5: ='Consommation du 01.02 au 28.02'!M13 -> 13972 | F5: 1.002 | G5: ='Consommation du 01.02 au 28.02'!U13 -> 482.3 | H5: 9.65 | I5: ='Consommation du 01.02 au 28.02'!Y13*1000 -> 14920 | J5: 0.53 | K5: ='Consommation du 01.02 au 28.02'!D13 -> 290 | L5: 12.67 | M5: ='Consommation du 01.02 au 28.02'!AC13 -> 58 | N5: 113 | O5: =E5*F5+G5*H5+I5*J5+K5*L5 -> 30236.039
A6: Marrakech | B6: =B5+1 -> 5 | C6: 2 | D6: 2019 | E6: ='Consommation du 01.02 au 28.02'!M14 -> 15346 | F6: 1.002 | G6: ='Consommation du 01.02 au 28.02'!U14 -> 742 | H6: 9.65 | I6: ='Consommation du 01.02 au 28.02'!Y14*1000 -> 11770 | J6: 0.53 | K6: ='Consommation du 01.02 au 28.02'!D14 -> 370 | L6: 12.67 | M6: ='Consommation du 01.02 au 28.02'!AC14 -> 74 | N6: 142 | O6: =E6*F6+G6*H6+I6*J6+K6*L6 -> 33462.992
A7: Marrakech | B7: =B6+1 -> 6 | C7: 2 | D7: 2019 | E7: ='Consommation du 01.02 au 28.02'!M15 -> 15098 | F7: 1.002 | G7: ='Consommation du 01.02 au 28.02'!U15 -> 927.5 | H7: 9.65 | I7: ='Consommation du 01.02 au 28.02'!Y15*1000 -> 11840 | J7: 0.53 | K7: ='Consommation du 01.02 au 28.02'!D15 -> 320 | L7: 12.67 | M7: ='Consommation du 01.02 au 28.02'!AC15 -> 101 | N7: 192 | O7: =E7*F7+G7*H7+I7*J7+K7*L7 -> 34408.171
A8: Marrakech | B8: =B7+1 -> 7 | C8: 2 | D8: 2019 | E8: ='Consommation du 01.02 au 28.02'!M16 -> 14981 | F8: 1.002 | G8: ='Consommation du 01.02 au 28.02'!U16 -> 1446.9 | H8: 9.65 | I8: ='Consommation du 01.02 au 28.02'!Y16*1000 -> 16840 | J8: 0.53 | K8: ='Consommation du 01.02 au 28.02'!D16 -> 330 | L8: 12.67 | M8: ='Consommation du 01.02 au 28.02'!AC16 -> 101 | N8: 190 | O8: =E8*F8+G8*H8+I8*J8+K8*L8 -> 42079.847
A9: Marrakech | B9: =B8+1 -> 8 | C9: 2 | D9: 2019 | E9: ='Consommation du 01.02 au 28.02'!M17 -> 14817 | F9: 1.002 | G9: ='Consommation du 01.02 au 28.02'!U17 -> 630.7 | H9: 9.65 | I9: ='Consommation du 01.02 au 28.02'!Y17*1000 -> 15090 | J9: 0.53 | K9: ='Consommation du 01.02 au 28.02'!D17 -> 350 | L9: 12.67 | M9: ='Consommation du 01.02 au 28.02'!AC17 -> 134 | N9: 249 | O9: =E9*F9+G9*H9+I9*J9+K9*L9 -> 33365.089
A10: Marrakech | B10: =B9+1 -> 9 | C10: 2 | D10: 2019 | E10: ='Consommation du 01.02 au 28.02'!M18 -> 13398 | F10: 1.002 | G10: ='Consommation du 01.02 au 28.02'!U18 -> 1150.1 | H10: 9.65 | I10: ='Consommation du 01.02 au 28.02'!Y18*1000 -> 16590 | J10: 0.53 | K10: ='Consommation du 01.02 au 28.02'!D18 -> 310 | L10: 12.67 | M10: ='Consommation du 01.02 au 28.02'!AC18 -> 131 | N10: 231 | O10: =E10*F10+G10*H10+I10*J10+K10*L10 -> 37243.661
A11: Marrakech | B11: =B10+1 -> 10 | C11: 2 | D11: 2019 | E11: ='Consommation du 01.02 au 28.02'!M19 -> 13383 | F11: 1.002 | G11: ='Consommation du 01.02 au 28.02'!U19 -> 556.5 | H11: 9.65 | I11: ='Consommation du 01.02 au 28.02'!Y19*1000 -> 18810 | J11: 0.53 | K11: ='Consommation du 01.02 au 28.02'!D19 -> 440 | L11: 12.67 | M11: ='Consommation du 01.02 au 28.02'!AC19 -> 101 | N11: 191 | O11: =E11*F11+G11*H11+I11*J11+K11*L11 -> 34324.091
A12: Marrakech | B12: =B11+1 -> 11 | C12: 2 | D12: 2019 | E12: ='Consommation du 01.02 au 28.02'!M20 -> 14045 | F12: 1.002 | G12: ='Consommation du 01.02 au 28.02'!U20 -> 742 | H12: 9.65 | I12: ='Consommation du 01.02 au 28.02'!Y20*1000 -> 16680 | J12: 0.53 | K12: ='Consommation du 01.02 au 28.02'!D20 -> 350 | L12: 12.67 | M12: ='Consommation du 01.02 au 28.02'!AC20 -> 91 | N12: 170 | O12: =E12*F12+G12*H12+I12*J12+K12*L12 -> 34508.29
A13: Marrakech | B13: =B12+1 -> 12 | C13: 2 | D13: 2019 | E13: ='Consommation du 01.02 au 28.02'!M21 -> 13658 | F13: 1.002 | G13: ='Consommation du 01.02 au 28.02'!U21 -> 667.8 | H13: 9.65 | I13: ='Consommation du 01.02 au 28.02'!Y21*1000 -> 16240 | J13: 0.53 | K13: ='Consommation du 01.02 au 28.02'!D21 -> 330 | L13: 12.67 | M13: ='Consommation du 01.02 au 28.02'!AC21 -> 74 | N13: 154 | O13: =E13*F13+G13*H13+I13*J13+K13*L13 -> 32917.886
A14: Marrakech | B14: =B13+1 -> 13 | C14: 2 | D14: 2019 | E14: ='Consommation du 01.02 au 28.02'!M22 -> 13275 | F14: 1.002 | G14: ='Consommation du 01.02 au 28.02'!U22 -> 853.3 | H14: 9.65 | I14: ='Consommation du 01.02 au 28.02'!Y22*1000 -> 17010 | J14: 0.53 | K14: ='Consommation du 01.02 au 28.02'!D22 -> 380 | L14: 12.67 | M14: ='Consommation du 01.02 au 28.02'!AC22 -> 85 | N14: 172 | O14: =E14*F14+G14*H14+I14*J14+K14*L14 -> 35365.795
... A29: Marrakech | B29: =B28+1 -> 28 | C29: 2 | D29: 2019 | E29: ='Consommation du 01.02 au 28.02'!M37 -> 18866 | F29: 1.002 | G29: ='Consommation du 01.02 au 28.02'!U37 -> 1038.8 | H29: 9.65 | I29: ='Consommation du 01.02 au 28.02'!Y37*1000 -> 9220 | J29: 0.53 | K29: ='Consommation du 01.02 au 28.02'!D37 -> 400 | L29: 12.67 | M29: ='Consommation du 01.02 au 28.02'!AC37 -> 137 | N29: 202 | O29: =E29*F29+G29*H29+I29*J29+K29*L29 -> 38882.752

Sheet Consommation du 01.02 au 28.02
B8: Date | D8: Cons Eau/Hotel | F8: Consommation du jour en DH | J8: ELECTRICITE en KWH | M8: total | O8: Consommation du jour en DH | Q8: Cons Elec/Villa | S8: Cons Elec/RIAD | U8: GAZ en Kg | W8: Consommation du jour en DH | AB8: Temp moyenne du jour °C | AC8: Room Nights | AD8: % Occupation | AE8: Temp Piscine Adulte à 7h00 °C | AF8: Temp Piscine Adulte à 15h00 °C | AG8: Temp Piscine famille à 07h00 ° C | AH8: Temp Piscine famille à 15h00 ° C
J9: creuse 81 | K9: pleine 82 | L9: pointe 83 | X9: Compteur AVEO Mwh | Y9: consommation eau choud en Mwh | Z9: consommation du jour en DH
B10: 43497 | D10: ='Suivi EAU-ELEC'!C15 -> 310 | F10: =D10*12.67 -> 3927.7 | J10: ='Suivi EAU-ELEC'!E15 -> 3857 | K10: ='Suivi EAU-ELEC'!G15 -> 6317 | L10: ='Suivi EAU-ELEC'!I15 -> 2820 | M10: =L10+K10+J10 -> 12994 | O10: =M10*1.002 -> 13019.988 | U10: ='Suvi Gaz'!O11 -> 742 | W10: =U10*9.65 -> 7160.3 | X10: 12533.6 | Y10: =IF(X11<X10,0,X11-X10) -> 15.95 | Z10: =Y10*0.84*1000 -> 13398 | AB10: 16 | AC10: 56 | AD10: 0.4706 | AE10: 28 | AF10: 28 | AG10: 29 | AH10: 29
B11: =B10+1 -> 43498 | D11: ='Suivi EAU-ELEC'!C16 -> 260 | F11: =D11*12.67 -> 3294.2 | J11: ='Suivi EAU-ELEC'!E16 -> 4091 | K11: ='Suivi EAU-ELEC'!G16 -> 5953 | L11: ='Suivi EAU-ELEC'!I16 -> 2753 | M11: =L11+K11+J11 -> 12797 | O11: =M11*1.002 -> 12822.594 | U11: ='Suvi Gaz'!O11 -> 742 | W11: =U11*9.65 -> 7160.3 | X11: 12549.55 | Y11: =IF(X12<X11,0,X12-X11) -> 16.61 | Z11: =Y11*0.84*1000 -> 13952.4 | AB11: 11 | AC11: 72 | AD11: 0.5581 | AE11: 28 | AF11: 28.5 | AG11: 29 | AH11: 29
B12: =B11+1 -> 43499 | D12: ='Suivi EAU-ELEC'!C17 -> 290 | F12: =D12*12.67 -> 3674.3 | J12: ='Suivi EAU-ELEC'!E17 -> 3913 | K12: ='Suivi EAU-ELEC'!G17 -> 5980 | L12: ='Suivi EAU-ELEC'!I17 -> 2802 | M12: =L12+K12+J12 -> 12695 | O12: =M12*1.002 -> 12720.39 | U12: ='Suvi Gaz'!O12 -> 593.6 | W12: =U12*9.65 -> 5728.24 | X12: 12566.16 | Y12: =IF(X13<X12,0,X13-X12) -> 16.42 | Z12: =Y12*0.84*1000 -> 13792.8 | AB12: 12 | AC12: 71 | AD12: 0.5726 | AE12: 28 | AF12: 28.5 | AG12: 29 | AH12: 29.5
B13: =B12+1 -> 43500 | D13: ='Suivi EAU-ELEC'!C18 -> 290 | F13: =D13*12.67 -> 3674.3 | J13: ='Suivi EAU-ELEC'!E18 -> 4337 | K13: ='Suivi EAU-ELEC'!G18 -> 6419 | L13: ='Suivi EAU-ELEC'!I18 -> 3216 | M13: =L13+K13+J13 -> 13972 | O13: =M13*1.002 -> 13999.944 | U13: ='Suvi Gaz'!O13 -> 482.3 | W13: =U13*9.65 -> 4654.195 | X13: 12582.58 | Y13: =IF(X14<X13,0,X14-X13) -> 14.92 | Z13: =Y13*0.84*1000 -> 12532.8 | AB13: 13 | AC13: 58 | AD13: 0.4833 | AE13: 28 | AF13: 29 | AG13: 28.5 | AH13: 29
B14: =B13+1 -> 43501 | D14: ='Suivi EAU-ELEC'!C19 -> 370 | F14: =D14*12.67 -> 4687.9 | J14: ='Suivi EAU-ELEC'!E19 -> 4771 | K14: ='Suivi EAU-ELEC'!G19 -> 7231 | L14: ='Suivi EAU-ELEC'!I19 -> 3344 | M14: =L14+K14+J14 -> 15346 | O14: =M14*1.002 -> 15376.692 | U14: ='Suvi Gaz'!O14 -> 742 | W14: =U14*9.65 -> 7160.3 | X14: 12597.5 | Y14: =IF(X15<X14,0,X15-X14) -> 11.77 | Z14: =Y14*0.84*1000 -> 9886.8 | AB14: 19 | AC14: 74 | AD14: 0.6016 | AE14: 28 | AF14: 28.4 | AG14: 29 | AH14: 29.6
B15: =B14+1 -> 43502 | D15: ='Suivi EAU-ELEC'!C20 -> 320 | F15: =D15*12.67 -> 4054.4 | J15: ='Suivi EAU-ELEC'!E20 -> 4760 | K15: ='Suivi EAU-ELEC'!G20 -> 7167 | L15: ='Suivi EAU-ELEC'!I20 -> 3171 | M15: =L15+K15+J15 -> 15098 | O15: =M15*1.002 -> 15128.196 | U15: ='Suvi Gaz'!O15 -> 927.5 | W15: =U15*9.65 -> 8950.375 | X15: 12609.27 | Y15: =IF(X16<X15,0,X16-X15) -> 11.84 | Z15: =Y15*0.84*1000 -> 9945.6 | AB15: 17 | AC15: 101 | AD15: 0.7829 | AE15: 28 | AF15: 29 | AG15: 28.8 | AH15: 29
B16: =B15+1 -> 43503 | D16: ='Suivi EAU-ELEC'!C21 -> 330 | F16: =D16*12.67 -> 4181.1 | J16: ='Suivi EAU-ELEC'!E21 -> 4610 | K16: ='Suivi EAU-ELEC'!G21 -> 7145 | L16: ='Suivi EAU-ELEC'!I21 -> 3226 | M16: =L16+K16+J16 -> 14981 | O16: =M16*1.002 -> 15010.962 | U16: ='Suvi Gaz'!O16 -> 1446.9 | W16: =U16*9.65 -> 13962.585 | X16: 12621.11 | Y16: =IF(X17<X16,0,X17-X16) -> 16.84 | Z16: =Y16*0.84*1000 -> 14145.6 | AB16: 19 | AC16: 101 | AD16: 0.7481 | AE16: 28.5 | AF16: 29 | AG16: 30 | AH16: 31
B17: =B16+1 -> 43504 | D17: ='Suivi EAU-ELEC'!C22 -> 350 | F17: =D17*12.67 -> 4434.5 | J17: ='Suivi EAU-ELEC'!E22 -> 4565 | K17: ='Suivi EAU-ELEC'!G22 -> 7035 | L17: ='Suivi EAU-ELEC'!I22 -> 3217 | M17: =L17+K17+J17 -> 14817 | O17: =M17*1.002 -> 14846.634 | U17: ='Suvi Gaz'!O17 -> 630.7 | W17: =U17*9.65 -> 6086.255 | X17: 12637.95 | Y17: =IF(X18<X17,0,X18-X17) -> 15.09 | Z17: =Y17*0.84*1000 -> 12675.6 | AB17: 19 | AC17: 134 | AD17: 0.9781 | AE17: 29 | AF17: 30 | AG17: 30 | AH17: 31
B18: =B17+1 -> 43505 | D18: ='Suivi EAU-ELEC'!C23 -> 310 | F18: =D18*12.67 -> 3927.7 | J18: ='Suivi EAU-ELEC'!E23 -> 4055 | K18: ='Suivi EAU-ELEC'!G23 -> 6392 | L18: ='Suivi EAU-ELEC'!I23 -> 2951 | M18: =L18+K18+J18 -> 13398 | O18: =M18*1.002 -> 13424.796 | U18: ='Suvi Gaz'!O18 -> 1150.1 | W18: =U18*9.65 -> 11098.465 | X18: 12653.04 | Y18: =IF(X19<X18,0,X19-X18) -> 16.59 | Z18: =Y18*0.84*1000 -> 13935.6 | AB18: 20 | AC18: 131 | AD18: 0.9704 | AE18: 29 | AF18: 30 | AG18: 29.8 | AH18: 31
B19: =B18+1 -> 43506 | D19: ='Suivi EAU-ELEC'!C24 -> 440 | F19: =D19*12.67 -> 5574.8 | J19: ='Suivi EAU-ELEC'!E24 -> 4251 | K19: ='Suivi EAU-ELEC'!G24 -> 6293 | L19: ='Suivi EAU-ELEC'!I24 -> 2839 | M19: =L19+K19+J19 -> 13383 | O19: =M19*1.002 -> 13409.766 | U19: ='Suvi Gaz'!O19 -> 556.5 | W19: =U19*9.65 -> 5370.225 | X19: 12669.63 | Y19: =IF(X20<X19,0,X20-X19) -> 18.81 | Z19: =Y19*0.84*1000 -> 15800.4 | AB19: 21 | AC19: 101 | AD19: 0.8016 | AE19: 29 | AF19: 30 | AG19: 29.5 | AH19: 30.5
B20: =B19+1 -> 43507 | D20: ='Suivi EAU-ELEC'!C25 -> 350 | F20: =D20*12.67 -> 4434.5 | J20: ='Suivi EAU-ELEC'!E25 -> 4729 | K20: ='Suivi EAU-ELEC'!G25 -> 6361 | L20: ='Suivi EAU-ELEC'!I25 -> 2955 | M20: =L20+K20+J20 -> 14045 | O20: =M20*1.002 -> 14073.09 | U20: ='Suvi Gaz'!O20 -> 742 | W20: =U20*9.65 -> 7160.3 | X20: 12688.44 | Y20: =IF(X21<X20,0,X21-X20) -> 16.68 | Z20: =Y20*0.84*1000 -> 14011.2 | AA20: 14 | AB20: 22 | AC20: 91 | AD20: 0.7165 | AE20: 29 | AF20: 30 | AG20: 29 | AH20: 30
B21: =B20+1 -> 43508 | D21: ='Suivi EAU-ELEC'!C26 -> 330 | F21: =D21*12.67 -> 4181.1 | J21: ='Suivi EAU-ELEC'!E26 -> 4149 | K21: ='Suivi EAU-ELEC'!G26 -> 6450 | L21: ='Suivi EAU-ELEC'!I26 -> 3059 | M21: =L21+K21+J21 -> 13658 | O21: =M21*1.002 -> 13685.316 | U21: ='Suvi Gaz'!O21 -> 667.8 | W21: =U21*9.65 -> 6444.27 | X21: 12705.12 | Y21: =IF(X22<X21,0,X22-X21) -> 16.24 | Z21: =Y21*0.84*1000 -> 13641.6 | AA21: 14 | AB21: 22 | AC21: 74 | AD21: 0.5968 | AE21: 29 | AF21: 29 | AG21: 29 | AH21: 30
B22: =B21+1 -> 43509 | D22: ='Suivi EAU-ELEC'!C27 -> 380 | F22: =D22*12.67 -> 4814.6 | J22: ='Suivi EAU-ELEC'!E27 -> 4147 | K22: ='Suivi EAU-ELEC'!G27 -> 6289 | L22: ='Suivi EAU-ELEC'!I27 -> 2839 | M22: =L22+K22+J22 -> 13275 | O22: =M22*1.002 -> 13301.55 | U22: ='Suvi Gaz'!O22 -> 853.3 | W22: =U22*9.65 -> 8234.345 | X22: 12721.36 | Y22: =IF(X23<X22,0,X23-X22) -> 17.01 | Z22: =Y22*0.84*1000 -> 14288.4 | AB22: 23 | AC22: 85 | AD22: 0.6538 | AE22: 29 | AF22: 29 | AG22: 29 | AH22: 30
B23: =B22+1 -> 43510 | D23: ='Suivi EAU-ELEC'!C28 -> 350 | F23: =D23*12.67 -> 4434.5 | J23: ='Suivi EAU-ELEC'!E28 -> 4054 | K23: ='Suivi EAU-ELEC'!G28 -> 6343 | L23: ='Suivi EAU-ELEC'!I28 -> 2844 | M23: =L23+K23+J23 -> 13241 | O23: =M23*1.002 -> 13267.482 | U23: ='Suvi Gaz'!O23 -> 667.8 | W23: =U23*9.65 -> 6444.27 | X23: 12738.37 | Y23: =IF(X24<X23,0,X24-X23) -> 14.34 | Z23: =Y23*0.84*1000 -> 12045.6 | AB23: 21 | AC23: 120 | AD23: 0.8824 | AE23: 28.5 | AF23: 29.5 | AG23: 28.5 | AH23: 30
B24: =B23+1 -> 43511 | D24: ='Suivi EAU-ELEC'!C29 -> 410 | F24: =D24*12.67 -> 5194.7 | J24: ='Suivi EAU-ELEC'!E29 -> 4802 | K24: ='Suivi EAU-ELEC'!G29 -> 6792 | L24: ='Suivi EAU-ELEC'!I29 -> 3081 | M24: =L24+K24+J24 -> 14675 | O24: =M24*1.002 -> 14704.35 | U24: ='Suvi Gaz'!O24 -> 371 | W24: =U24*9.65 -> 3580.15 | X24: 12752.71 | Y24: =IF(X25<X24,0,X25-X24) -> 17.34 | Z24: =Y24*0.84*1000 -> 14565.6 | AB24: 20 | AC24: 130 | AD24: 0.9489 | AE24: 29 | AF24: 30 | AG24: 29 | AH24: 30
B25: =B24+1 -> 43512 | D25: ='Suivi EAU-ELEC'!C30 -> 350 | F25: =D25*12.67 -> 4434.5 | J25: ='Suivi EAU-ELEC'!E30 -> 5332 | K25: ='Suivi EAU-ELEC'!G30 -> 7039 | L25: ='Suivi EAU-ELEC'!I30 -> 3529 | M25: =L25+K25+J25 -> 15900 | O25: =M25*1.002 -> 15931.8 | U25: ='Suvi Gaz'!O25 -> 630.7 | W25: =U25*9.65 -> 6086.255 | X25: 12770.05 | Y25: =IF(X26<X25,0,X26-X25) -> 16.35 | Z25: =Y25*0.84*1000 -> 13734 | AB25: 14 | AC25: 130 | AD25: 0.9489 | AE25: 28 | AF25: 29 | AG25: 28 | AH25: 29
B26: =B25+1 -> 43513 | D26: ='Suivi EAU-ELEC'!C31 -> 460 | F26: =D26*12.67 -> 5828.2 | J26: ='Suivi EAU-ELEC'!E31 -> 4389 | K26: ='Suivi EAU-ELEC'!G31 -> 6846 | L26: ='Suivi EAU-ELEC'!I31 -> 3277 | M26: =L26+K26+J26 -> 14512 | O26: =M26*1.002 -> 14541.024 | U26: ='Suvi Gaz'!O26 -> 779.1 | W26: =U26*9.65 -> 7518.315 | X26: 12786.4 | Y26: =IF(X27<X26,0,X27-X26) -> 14.53 | Z26: =Y26*0.84*1000 -> 12205.2 | AB26: 16 | AC26: 136 | AD26: 0.9855 | AE26: 28 | AF26: 29 | AG26: 28 | AH26: 28.5
B27: =B26+1 -> 43514 | D27: ='Suivi EAU-ELEC'!C32 -> 370 | F27: =D27*12.67 -> 4687.9 | J27: ='Suivi EAU-ELEC'!E32 -> 3923 | K27: ='Suivi EAU-ELEC'!G32 -> 6682 | L27: ='Suivi EAU-ELEC'!I32 -> 3136 | M27: =L27+K27+J27 -> 13741 | O27: =M27*1.002 -> 13768.482 | U27: ='Suvi Gaz'!O27 -> 890.4 | W27: =U27*9.65 -> 8592.36 | X27: 12800.93 | Y27: =IF(X28<X27,0,X28-X27) -> 2.85 | Z27: =Y27*0.84*1000 -> 2394 | AB27: 16 | AC27: 127 | AD27: 0.9137 | AE27: 28 | AF27: 28 | AG27: 27 | AH27: 27
B28: =B27+1 -> 43515 | D28: ='Suivi EAU-ELEC'!C33 -> 420 | F28: =D28*12.67 -> 5321.4 | J28: ='Suivi EAU-ELEC'!E33 -> 4681 | K28: ='Suivi EAU-ELEC'!G33 -> 6775 | L28: ='Suivi EAU-ELEC'!I33 -> 3145 | M28: =L28+K28+J28 -> 14601 | O28: =M28*1.002 -> 14630.202 | U28: ='Suvi Gaz'!O28 -> 2374.4 | W28: =U28*9.65 -> 22912.96 | X28: 12803.78 | Y28: =IF(X29<X28,0,X29-X28) -> 0 | Z28: =Y28*0.84*1000 -> 0 | AB28: 13 | AC28: 124 | AD28: 0.9323 | AE28: 27 | AF28: 27 | AG28: 27 | AH28: 27
B29: =B28+1 -> 43516 | D29: ='Suivi EAU-ELEC'!C34 -> 370 | F29: =D29*12.67 -> 4687.9 | J29: ='Suivi EAU-ELEC'!E34 -> 4399 | K29: ='Suivi EAU-ELEC'!G34 -> 6628 | L29: ='Suivi EAU-ELEC'!I34 -> 3347 | M29: =L29+K29+J29 -> 14374 | O29: =M29*1.002 -> 14402.748 | U29: ='Suvi Gaz'!O29 -> 2337.3 | W29: =U29*9.65 -> 22554.945 | X29: 12803.78 | Y29: =IF(X30<X29,0,X30-X29) -> 0 | Z29: =Y29*0.84*1000 -> 0 | AB29: 17 | AC29: 117 | AD29: 0.8478 | AE29: 27 | AF29: 28 | AG29: 28 | AH29: 28.5
B30: =B29+1 -> 43517 | D30: ='Suivi EAU-ELEC'!C35 -> 370 | F30: =D30*12.67 -> 4687.9 | J30: ='Suivi EAU-ELEC'!E35 -> 4277 | K30: ='Suivi EAU-ELEC'!G35 -> 6603 | L30: ='Suivi EAU-ELEC'!I35 -> 3487 | M30: =L30+K30+J30 -> 14367 | O30: =M30*1.002 -> 14395.734 | U30: ='Suvi Gaz'!O30 -> 2003.4 | W30: =U30*9.65 -> 19332.81 | X30: 12803.78 | Y30: =IF(X31<X30,0,X31-X30) -> 0 | Z30: =Y30*0.84*1000 -> 0 | AB30: 20 | AC30: 116 | AD30: 0.8593 | AE30: 28 | AF30: 29 | AG30: 29 | AH30: 30
B31: =B30+1 -> 43518 | D31: ='Suivi EAU-ELEC'!C36 -> 410 | F31: =D31*12.67 -> 5194.7 | J31: ='Suivi EAU-ELEC'!E36 -> 4387 | K31: ='Suivi EAU-ELEC'!G36 -> 7177 | L31: ='Suivi EAU-ELEC'!I36 -> 2901 | M31: =L31+K31+J31 -> 14465 | O31: =M31*1.002 -> 14493.93 | U31: ='Suvi Gaz'!O31 -> 2114.7 | W31: =U31*9.65 -> 20406.855 | X31: 12803.78 | Y31: =IF(X32<X31,0,X32-X31) -> 0 | Z31: =Y31*0.84*1000 -> 0 | AB31: 22 | AC31: 139 | AD31: 1 | AE31: 28 | AF31: 29 | AG31: 29 | AH31: 30
B32: =B31+1 -> 43519 | D32: ='Suivi EAU-ELEC'!C37 -> 340 | F32: =D32*12.67 -> 4307.8 | J32: ='Suivi EAU-ELEC'!E37 -> 4348 | K32: ='Suivi EAU-ELEC'!G37 -> 7183 | L32: ='Suivi EAU-ELEC'!I37 -> 3458 | M32: =L32+K32+J32 -> 14989 | O32: =M32*1.002 -> 15018.978 | U32: ='Suvi Gaz'!O32 -> 1409.8 | W32: =U32*9.65 -> 13604.57 | X32: 12803.78 | Y32: =IF(X33<X32,0,X33-X32) -> 0 | Z32: =Y32*0.84*1000 -> 0 | AB32: 24 | AC32: 127 | AD32: 0.9407 | AE32: 29 | AF32: 30 | AG32: 30 | AH32: 31
B33: =B32+1 -> 43520 | D33: ='Suivi EAU-ELEC'!C38 -> 450 | F33: =D33*12.67 -> 5701.5 | J33: ='Suivi EAU-ELEC'!E38 -> 4405 | K33: ='Suivi EAU-ELEC'!G38 -> 8245 | L33: ='Suivi EAU-ELEC'!I38 -> 3737 | M33: =L33+K33+J33 -> 16387 | O33: =M33*1.002 -> 16419.774 | U33: ='Suvi Gaz'!O33 -> 1929.2 | W33: =U33*9.65 -> 18616.78 | X33: 12803.78 | Y33: =IF(X34<X33,0,X34-X33) -> 0 | Z33: =Y33*0.84*1000 -> 0 | AB33: 23 | AC33: 116 | AD33: 0.8657 | AE33: 29 | AF33: 30 | AG33: 29.5 | AH33: 30
... B39: =B38+1 -> 43526 | D39: ='Suivi EAU-ELEC'!C44 -> 420 | F39: =D39*12.67 -> 5321.4 | J39: ='Suivi EAU-ELEC'!E44 -> 4947 | K39: ='Suivi EAU-ELEC'!G44 -> 7679 | L39: ='Suivi EAU-ELEC'!I44 -> 3829 | M39: =L39+K39+J39 -> 16455 | O39: =M39*1.002 -> 16487.91 | U39: ='Suvi Gaz'!O39 -> 1150.1 | W39: =U39*9.65 -> 11098.465 | X39: 12834.09 | Y39: =IF(X40<X39,0,X40-X39) -> 0 | Z39: =Y39*0.84*1000 -> 0 | AB39: 21 | AC39: 132 | AD39: 0.9706 | AE39: 29 | AF39: 30 | AG39: 26 | AH39: 27.5
B40: =B39+1 -> 43527 | D40: ='Suivi EAU-ELEC'!C45 -> 0 | F40: =D40*12.67 -> 0 | J40: ='Suivi EAU-ELEC'!E45 -> 0 | K40: ='Suivi EAU-ELEC'!G45 -> 0 | L40: ='Suivi EAU-ELEC'!I45 -> 0 | M40: =L40+K40+J40 -> 0 | O40: =M40*1.002 -> 0 | U40: ='Suvi Gaz'!O40 -> 0 | W40: =U40*9.65 -> 0 | Y40: =IF(X41<X40,0,X41-X40) -> 0 | Z40: =Y40*0.53*1000 -> 0
D41: =SUM(D10:D37) -> 10310 | F41: =SUM(F10:H37) -> 130627.7 | J41: =SUM(J10:J37) -> 125747 | K41: =SUM(K10:K37) -> 195629 | L41: =SUM(L10:L37) -> 90101 | M41: =SUM(M10:M37) -> 411477 | O41: 385768 | S41: =SUM(S10:S40) -> 0 | U41: =SUM(U10:U37) -> 32054.4 | W41: =SUM(W10:W37) -> 309324.96 | Y41: =SUM(Y10:Y37) -> 291.64 | Z41: =SUM(Z10:Z37) -> 244977.6
A43: ELECTRICITE / Kw/h | D43: creuse 81 | F43: 1.002 | G43: =J41 -> 125747 | J43: =G43*F43 -> 125998.49 | L43: =J43+J44+J45 -> 412299.95
D44: pleine 82 | F44: 1.002 | G44: =K41 -> 195629 | J44: =G44*F44 -> 196020.26
D45: pointe 83 | F45: 1.002 | G45: =L41 -> 90101 | J45: =G45*F45 -> 90281.202
A46: EAU HOTEL M3 | F46: 12.67 | G46: =D41 -> 10310 | J46: =G46*F46 -> 130627.7 | L46: =J46 -> 130627.7
A47: GAZ Kg | F47: 9.65 | G47: =U41 -> 32054.4 | J47: =G47*F47 -> 309324.96 | L47: =J47 -> 309324.96

Sheet Suvi Gaz
D1: suivi Gaz
Q2: 803 | T2: 519 | W2: 800 | Z2: 802
B3: Relvé C1 | C3: cons C1 | D3: Relvé C2 | E3: cons C2 | F3: Relvé C3 | G3: cons C3 | H3: Relvé C4 | I3: cons C4 | J3: ∑ des relevés | K3: moyen general % | L3: con.j | M3: ∑ de volume en L | N3: cons./jen L | O3: cons./jen Kg | P3: cons./jen DH | Q3: livraison C1 | R3: %Avant | S3: % Après | T3: livraison C2 | U3: %Avant | V3: % Après | W3: livraison C3 | X3: %Avant | Y3: % Après | Z3: livraison C4 | AA3: %Avant | AB3: % Après | AC3: total livraison | AD3: moyen general % Avant L | AE3: moyen general % Aaprés L
A4: 43490 | B4: 43 | C4: =IF(AC4>0,((B4-R4)+(S4-B5)),IF(B5=0, ,(B4-B5))) -> 6 | D4: 47 | E4: =IF(AC4>0,((D4-U4)+(V4-D5)),IF(D5=0, ,(D4-D5))) -> 7 | F4: 41 | G4: =IF(AC4>0,((F4-X4)+(Y4-F5)),IF(F5=0, ,(F4-F5))) -> 6 | H4: 42 | I4: =IF(AC4>0,((H4-AA4)+(AB4-H5)),IF(H5=0, ,(H4-H5))) -> 2 | J4: =B4+D4+F4+H4 -> 173 | K4: =J4/4 -> 43.25 | L4: =IF(AC4>0,((K4-AD4)+(AE4-K5)),IF(K5=0, ,(K4-K5))) -> 5.25 | M4: =7000*4 -> 28000 | N4: =L4*M4/100 -> 1470 | O4: =N4*0.53 -> 779.1 | P4: =O4*9.65 -> 7518.315 | AC4: =Q4+T4+W4+Z4 -> 0 | AD4: =(R4+U4+X4+AA4)/4 -> 0 | AE4: =(S4+V4+Y4+AB4)/4 -> 0
A5: 43491 | B5: 37 | C5: =IF(AC5>0,((B5-R5)+(S5-B6)),IF(B6=0, ,(B5-B6))) -> 3 | D5: 40 | E5: =IF(AC5>0,((D5-U5)+(V5-D6)),IF(D6=0, ,(D5-D6))) -> 5 | F5: 35 | G5: =IF(AC5>0,((F5-X5)+(Y5-F6)),IF(F6=0, ,(F5-F6))) -> 3 | H5: 40 | I5: =IF(AC5>0,((H5-AA5)+(AB5-H6)),IF(H6=0, ,(H5-H6))) -> 8 | J5: =B5+D5+F5+H5 -> 152 | K5: =J5/4 -> 38 | L5: =IF(AC5>0,((K5-AD5)+(AE5-K6)),IF(K6=0, ,(K5-K6))) -> 4.75 | M5: =7000*4 -> 28000 | N5: =L5*M5/100 -> 1330 | O5: =N5*0.53 -> 704.9 | P5: =O5*9.65 -> 6802.285 | Q5: 2626 | R5: 34 | S5: 65 | T5: 2620 | U5: 33 | V5: 63 | W5: 2599 | X5: 38 | Y5: 68 | Z5: 2606 | AA5: 35 | AB5: 65 | AC5: =Q5+T5+W5+Z5 -> 10451 | AD5: =(R5+U5+X5+AA5)/4 -> 35 | AE5: =(S5+V5+Y5+AB5)/4 -> 65.25
A6: 43492 | B6: 65 | C6: =IF(AC6>0,((B6-R6)+(S6-B7)),IF(B7=0, ,(B6-B7))) -> 7 | D6: 65 | E6: =IF(AC6>0,((D6-U6)+(V6-D7)),IF(D7=0, ,(D6-D7))) -> 4 | F6: 62 | G6: =IF(AC6>0,((F6-X6)+(Y6-F7)),IF(F7=0, ,(F6-F7))) -> 7 | H6: 62 | I6: =IF(AC6>0,((H6-AA6)+(AB6-H7)),IF(H7=0, ,(H6-H7))) -> 6 | J6: =B6+D6+F6+H6 -> 254 | K6: =J6/4 -> 63.5 | L6: =IF(AC6>0,((K6-AD6)+(AE6-K7)),IF(K7=0, ,(K6-K7))) -> 6 | M6: =7000*4 -> 28000 | N6: =L6*M6/100 -> 1680 | O6: =N6*0.53 -> 890.4 | P6: =O6*9.65 -> 8592.36 | AC6: =Q6+T6+W6+Z6 -> 0 | AD6: =(R6+U6+X6+AA6)/4 -> 0 | AE6: =(S6+V6+Y6+AB6)/4 -> 0
A7: 43493 | B7: 58 | C7: =IF(AC7>0,((B7-R7)+(S7-B8)),IF(B8=0, ,(B7-B8))) -> 6 | D7: 61 | E7: =IF(AC7>0,((D7-U7)+(V7-D8)),IF(D8=0, ,(D7-D8))) -> 6 | F7: 55 | G7: =IF(AC7>0,((F7-X7)+(Y7-F8)),IF(F8=0, ,(F7-F8))) -> 6 | H7: 56 | I7: =IF(AC7>0,((H7-AA7)+(AB7-H8)),IF(H8=0, ,(H7-H8))) -> 6 | J7: =B7+D7+F7+H7 -> 230 | K7: =J7/4 -> 57.5 | L7: =IF(AC7>0,((K7-AD7)+(AE7-K8)),IF(K8=0, ,(K7-K8))) -> 6 | M7: =7000*4 -> 28000 | N7: =L7*M7/100 -> 1680 | O7: =N7*0.53 -> 890.4 | P7: =O7*9.65 -> 8592.36 | AC7: =Q7+T7+W7+Z7 -> 0 | AD7: =(R7+U7+X7+AA7)/4 -> 0 | AE7: =(S7+V7+Y7+AB7)/4 -> 0
A8: 43494 | B8: 52 | C8: =IF(AC8>0,((B8-R8)+(S8-B9)),IF(B9=0, ,(B8-B9))) -> 6 | D8: 55 | E8: =IF(AC8>0,((D8-U8)+(V8-D9)),IF(D9=0, ,(D8-D9))) -> 5 | F8: 49 | G8: =IF(AC8>0,((F8-X8)+(Y8-F9)),IF(F9=0, ,(F8-F9))) -> 5 | H8: 50 | I8: =IF(AC8>0,((H8-AA8)+(AB8-H9)),IF(H9=0, ,(H8-H9))) -> 5 | J8: =B8+D8+F8+H8 -> 206 | K8: =J8/4 -> 51.5 | L8: =IF(AC8>0,((K8-AD8)+(AE8-K9)),IF(K9=0, ,(K8-K9))) -> 5.25 | M8: =7000*4 -> 28000 | N8: =L8*M8/100 -> 1470 | O8: =N8*0.53 -> 779.1 | P8: =O8*9.65 -> 7518.315 | AC8: =Q8+T8+W8+Z8 -> 0 | AD8: =(R8+U8+X8+AA8)/4 -> 0 | AE8: =(S8+V8+Y8+AB8)/4 -> 0
A9: 43495 | B9: 46 | C9: =IF(AC9>0,((B9-R9)+(S9-B10)),IF(B10=0, ,(B9-B10))) -> 3 | D9: 50 | E9: =IF(AC9>0,((D9-U9)+(V9-D10)),IF(D10=0, ,(D9-D10))) -> 5 | F9: 44 | G9: =IF(AC9>0,((F9-X9)+(Y9-F10)),IF(F10=0, ,(F9-F10))) -> 9 | H9: 45 | I9: =IF(AC9>0,((H9-AA9)+(AB9-H10)),IF(H10=0, ,(H9-H10))) -> 7 | J9: =B9+D9+F9+H9 -> 185 | K9: =J9/4 -> 46.25 | L9: =IF(AC9>0,((K9-AD9)+(AE9-K10)),IF(K10=0, ,(K9-K10))) -> 6 | M9: =7000*4 -> 28000 | N9: =L9*M9/100 -> 1680 | O9: =N9*0.53 -> 890.4 | P9: =O9*9.65 -> 8592.36 | Q9: 3299 | R9: 45 | S9: 85 | T9: 3205 | U9: 45 | V9: 85 | W9: 3405 | X9: 40 | Y9: 85 | Z9: 3403 | AA9: 42 | AB9: 85 | AC9: =Q9+T9+W9+Z9 -> 13312 | AD9: =(R9+U9+X9+AA9)/4 -> 43 | AE9: =(S9+V9+Y9+AB9)/4 -> 85
A10: 43496 | B10: 83 | C10: =IF(AC10>0,((B10-R10)+(S10-B11)),IF(B11=0, ,(B10-B11))) -> 3 | D10: 85 | E10: =IF(AC10>0,((D10-U10)+(V10-D11)),IF(D11=0, ,(D10-D11))) -> 5 | F10: 80 | G10: =IF(AC10>0,((F10-X10)+(Y10-F11)),IF(F11=0, ,(F10-F11))) -> 2 | H10: 81 | I10: =IF(AC10>0,((H10-AA10)+(AB10-H11)),IF(H11=0, ,(H10-H11))) -> 3 | J10: =B10+D10+F10+H10 -> 329 | K10: =J10/4 -> 82.25 | L10: =IF(AC10>0,((K10-AD10)+(AE10-K11)),IF(K11=0, ,(K10-K11))) -> 3.25 | M10: =7000*4 -> 28000 | N10: =L10*M10/100 -> 910 | O10: =N10*0.53 -> 482.3 | P10: =O10*9.65 -> 4654.195 | AC10: =Q10+T10+W10+Z10 -> 0 | AD10: =(R10+U10+X10+AA10)/4 -> 0 | AE10: =(S10+V10+Y10+AB10)/4 -> 0
A11: 43497 | B11: 80 | C11: =IF(AC11>0,((B11-R11)+(S11-B12)),IF(B12=0, ,(B11-B12))) -> 6 | D11: 80 | E11: =IF(AC11>0,((D11-U11)+(V11-D12)),IF(D12=0, ,(D11-D12))) -> 4 | F11: 78 | G11: =IF(AC11>0,((F11-X11)+(Y11-F12)),IF(F12=0, ,(F11-F12))) -> 4 | H11: 78 | I11: =IF(AC11>0,((H11-AA11)+(AB11-H12)),IF(H12=0, ,(H11-H12))) -> 6 | J11: =B11+D11+F11+H11 -> 316 | K11: =J11/4 -> 79 | L11: =IF(AC11>0,((K11-AD11)+(AE11-K12)),IF(K12=0, ,(K11-K12))) -> 5 | M11: =7000*4 -> 28000 | N11: =L11*M11/100 -> 1400 | O11: =N11*0.53 -> 742 | P11: =O11*9.65 -> 7160.3 | AC11: =Q11+T11+W11+Z11 -> 0 | AD11: =(R11+U11+X11+AA11)/4 -> 0 | AE11: =(S11+V11+Y11+AB11)/4 -> 0
A12: 43498 | B12: 74 | C12: =IF(AC12>0,((B12-R12)+(S12-B13)),IF(B13=0, ,(B12-B13))) -> 4 | D12: 76 | E12: =IF(AC12>0,((D12-U12)+(V12-D13)),IF(D13=0, ,(D12-D13))) -> 5 | F12: 74 | G12: =IF(AC12>0,((F12-X12)+(Y12-F13)),IF(F13=0, ,(F12-F13))) -> 5 | H12: 72 | I12: =IF(AC12>0,((H12-AA12)+(AB12-H13)),IF(H13=0, ,(H12-H13))) -> 2 | J12: =B12+D12+F12+H12 -> 296 | K12: =J12/4 -> 74 | L12: =IF(AC12>0,((K12-AD12)+(AE12-K13)),IF(K13=0, ,(K12-K13))) -> 4 | M12: =7000*4 -> 28000 | N12: =L12*M12/100 -> 1120 | O12: =N12*0.53 -> 593.6 | P12: =O12*9.65 -> 5728.24 | AC12: =Q12+T12+W12+Z12 -> 0 | AD12: =(R12+U12+X12+AA12)/4 -> 0 | AE12: =(S12+V12+Y12+AB12)/4 -> 0
A13: 43499 | B13: 70 | C13: =IF(AC13>0,((B13-R13)+(S13-B14)),IF(B14=0, ,(B13-B14))) -> 2 | D13: 71 | E13: =IF(AC13>0,((D13-U13)+(V13-D14)),IF(D14=0, ,(D13-D14))) -> 2 | F13: 69 | G13: =IF(AC13>0,((F13-X13)+(Y13-F14)),IF(F14=0, ,(F13-F14))) -> 5 | H13: 70 | I13: =IF(AC13>0,((H13-AA13)+(AB13-H14)),IF(H14=0, ,(H13-H14))) -> 4 | J13: =B13+D13+F13+H13 -> 280 | K13: =J13/4 -> 70 | L13: =IF(AC13>0,((K13-AD13)+(AE13-K14)),IF(K14=0, ,(K13-K14))) -> 3.25 | M13: =7000*4 -> 28000 | N13: =L13*M13/100 -> 910 | O13: =N13*0.53 -> 482.3 | P13: =O13*9.65 -> 4654.195 | AC13: =Q13+T13+W13+Z13 -> 0 | AD13: =(R13+U13+X13+AA13)/4 -> 0 | AE13: =(S13+V13+Y13+AB13)/4 -> 0
A14: 43500 | B14: 68 | C14: =IF(AC14>0,((B14-R14)+(S14-B15)),IF(B15=0, ,(B14-B15))) -> 6 | D14: 69 | E14: =IF(AC14>0,((D14-U14)+(V14-D15)),IF(D15=0, ,(D14-D15))) -> 5 | F14: 64 | G14: =IF(AC14>0,((F14-X14)+(Y14-F15)),IF(F15=0, ,(F14-F15))) -> 4 | H14: 66 | I14: =IF(AC14>0,((H14-AA14)+(AB14-H15)),IF(H15=0, ,(H14-H15))) -> 5 | J14: =B14+D14+F14+H14 -> 267 | K14: =J14/4 -> 66.75 | L14: =IF(AC14>0,((K14-AD14)+(AE14-K15)),IF(K15=0, ,(K14-K15))) -> 5 | M14: =7000*4 -> 28000 | N14: =L14*M14/100 -> 1400 | O14: =N14*0.53 -> 742 | P14: =O14*9.65 -> 7160.3 | AC14: =Q14+T14+W14+Z14 -> 0 | AD14: =(R14+U14+X14+AA14)/4 -> 0 | AE14: =(S14+V14+Y14+AB14)/4 -> 0
A15: 43501 | B15: 62 | C15: =IF(AC15>0,((B15-R15)+(S15-B16)),IF(B16=0, ,(B15-B16))) -> 5 | D15: 64 | E15: =IF(AC15>0,((D15-U15)+(V15-D16)),IF(D16=0, ,(D15-D16))) -> 4 | F15: 60 | G15: =IF(AC15>0,((F15-X15)+(Y15-F16)),IF(F16=0, ,(F15-F16))) -> 9 | H15: 61 | I15: =IF(AC15>0,((H15-AA15)+(AB15-H16)),IF(H16=0, ,(H15-H16))) -> 7 | J15: =B15+D15+F15+H15 -> 247 | K15: =J15/4 -> 61.75 | L15: =IF(AC15>0,((K15-AD15)+(AE15-K16)),IF(K16=0, ,(K15-K16))) -> 6.25 | M15: =7000*4 -> 28000 | N15: =L15*M15/100 -> 1750 | O15: =N15*0.53 -> 927.5 | P15: =O15*9.65 -> 8950.375 | AC15: =Q15+T15+W15+Z15 -> 0 | AD15: =(R15+U15+X15+AA15)/4 -> 0 | AE15: =(S15+V15+Y15+AB15)/4 -> 0
A16: 43502 | B16: 57 | C16: =IF(AC16>0,((B16-R16)+(S16-B17)),IF(B17=0, ,(B16-B17))) -> 11 | D16: 60 | E16: =IF(AC16>0,((D16-U16)+(V16-D17)),IF(D17=0, ,(D16-D17))) -> 10 | F16: 51 | G16: =IF(AC16>0,((F16-X16)+(Y16-F17)),IF(F17=0, ,(F16-F17))) -> 9 | H16: 54 | I16: =IF(AC16>0,((H16-AA16)+(AB16-H17)),IF(H17=0, ,(H16-H17))) -> 9 | J16: =B16+D16+F16+H16 -> 222 | K16: =J16/4 -> 55.5 | L16: =IF(AC16>0,((K16-AD16)+(AE16-K17)),IF(K17=0, ,(K16-K17))) -> 9.75 | M16: =7000*4 -> 28000 | N16: =L16*M16/100 -> 2730 | O16: =N16*0.53 -> 1446.9 | P16: =O16*9.65 -> 13962.585 | AC16: =Q16+T16+W16+Z16 -> 0 | AD16: =(R16+U16+X16+AA16)/4 -> 0 | AE16: =(S16+V16+Y16+AB16)/4 -> 0
A17: 43503 | B17: 46 | C17: =IF(AC17>0,((B17-R17)+(S17-B18)),IF(B18=0, ,(B17-B18))) -> 5 | D17: 50 | E17: =IF(AC17>0,((D17-U17)+(V17-D18)),IF(D18=0, ,(D17-D18))) -> 5 | F17: 42 | G17: =IF(AC17>0,((F17-X17)+(Y17-F18)),IF(F18=0, ,(F17-F18))) -> 2 | H17: 45 | I17: =IF(AC17>0,((H17-AA17)+(AB17-H18)),IF(H18=0, ,(H17-H18))) -> 5 | J17: =B17+D17+F17+H17 -> 183 | K17: =J17/4 -> 45.75 | L17: =IF(AC17>0,((K17-AD17)+(AE17-K18)),IF(K18=0, ,(K17-K18))) -> 4.25 | M17: =7000*4 -> 28000 | N17: =L17*M17/100 -> 1190 | O17: =N17*0.53 -> 630.7 | P17: =O17*9.65 -> 6086.255 | AC17: =Q17+T17+W17+Z17 -> 0 | AD17: =(R17+U17+X17+AA17)/4 -> 0 | AE17: =(S17+V17+Y17+AB17)/4 -> 0
A18: 43504 | B18: 41 | C18: =IF(AC18>0,((B18-R18)+(S18-B19)),IF(B19=0, ,(B18-B19))) -> 8 | D18: 45 | E18: =IF(AC18>0,((D18-U18)+(V18-D19)),IF(D19=0, ,(D18-D19))) -> 10 | F18: 40 | G18: =IF(AC18>0,((F18-X18)+(Y18-F19)),IF(F19=0, ,(F18-F19))) -> 10 | H18: 40 | I18: =IF(AC18>0,((H18-AA18)+(AB18-H19)),IF(H19=0, ,(H18-H19))) -> 3 | J18: =B18+D18+F18+H18 -> 166 | K18: =J18/4 -> 41.5 | L18: =IF(AC18>0,((K18-AD18)+(AE18-K19)),IF(K19=0, ,(K18-K19))) -> 7.75 | M18: =7000*4 -> 28000 | N18: =L18*M18/100 -> 2170 | O18: =N18*0.53 -> 1150.1 | P18: =O18*9.65 -> 11098.465 | Q18: 3501 | R18: 40 | S18: 85 | T18: 3514 | U18: 40 | V18: 85 | W18: 3499 | X18: 40 | Y18: 85 | Z18: 1752 | AA18: 37 | AB18: 70 | AC18: =Q18+T18+W18+Z18 -> 12266 | AD18: =(R18+U18+X18+AA18)/4 -> 39.25 | AE18: =(S18+V18+Y18+AB18)/4 -> 81.25
A19: 43505 | B19: 78 | C19: =IF(AC19>0,((B19-R19)+(S19-B20)),IF(B20=0, ,(B19-B20))) -> 5 | D19: 80 | E19: =IF(AC19>0,((D19-U19)+(V19-D20)),IF(D20=0, ,(D19-D20))) -> 5 | F19: 75 | G19: =IF(AC19>0,((F19-X19)+(Y19-F20)),IF(F20=0, ,(F19-F20))) -> 5 | H19: 70 | I19: =IF(AC19>0,((H19-AA19)+(AB19-H20)),IF(H20=0, ,(H19-H20))) -> 0 | J19: =B19+D19+F19+H19 -> 303 | K19: =J19/4 -> 75.75 | L19: =IF(AC19>0,((K19-AD19)+(AE19-K20)),IF(K20=0, ,(K19-K20))) -> 3.75 | M19: =7000*4 -> 28000 | N19: =L19*M19/100 -> 1050 | O19: =N19*0.53 -> 556.5 | P19: =O19*9.65 -> 5370.225 | AC19: =Q19+T19+W19+Z19 -> 0 | AD19: =(R19+U19+X19+AA19)/4 -> 0 | AE19: =(S19+V19+Y19+AB19)/4 -> 0
A20: 43506 | B20: 73 | C20: =IF(AC20>0,((B20-R20)+(S20-B21)),IF(B21=0, ,(B20-B21))) -> 6 | D20: 75 | E20: =IF(AC20>0,((D20-U20)+(V20-D21)),IF(D21=0, ,(D20-D21))) -> 5 | F20: 70 | G20: =IF(AC20>0,((F20-X20)+(Y20-F21)),IF(F21=0, ,(F20-F21))) -> 5 | H20: 70 | I20: =IF(AC20>0,((H20-AA20)+(AB20-H21)),IF(H21=0, ,(H20-H21))) -> 4 | J20: =B20+D20+F20+H20 -> 288 | K20: =J20/4 -> 72 | L20: =IF(AC20>0,((K20-AD20)+(AE20-K21)),IF(K21=0, ,(K20-K21))) -> 5 | M20: =7000*4 -> 28000 | N20: =L20*M20/100 -> 1400 | O20: =N20*0.53 -> 742 | P20: =O20*9.65 -> 7160.3 | AC20: =Q20+T20+W20+Z20 -> 0 | AD20: =(R20+U20+X20+AA20)/4 -> 0 | AE20: =(S20+V20+Y20+AB20)/4 -> 0
A21: 43507 | B21: 67 | C21: =IF(AC21>0,((B21-R21)+(S21-B22)),IF(B22=0, ,(B21-B22))) -> 4 | D21: 70 | E21: =IF(AC21>0,((D21-U21)+(V21-D22)),IF(D22=0, ,(D21-D22))) -> 5 | F21: 65 | G21: =IF(AC21>0,((F21-X21)+(Y21-F22)),IF(F22=0, ,(F21-F22))) -> 4 | H21: 66 | I21: =IF(AC21>0,((H21-AA21)+(AB21-H22)),IF(H22=0, ,(H21-H22))) -> 5 | J21: =B21+D21+F21+H21 -> 268 | K21: =J21/4 -> 67 | L21: =IF(AC21>0,((K21-AD21)+(AE21-K22)),IF(K22=0, ,(K21-K22))) -> 4.5 | M21: =7000*4 -> 28000 | N21: =L21*M21/100 -> 1260 | O21: =N21*0.53 -> 667.8 | P21: =O21*9.65 -> 6444.27 | AC21: =Q21+T21+W21+Z21 -> 0 | AD21: =(R21+U21+X21+AA21)/4 -> 0 | AE21: =(S21+V21+Y21+AB21)/4 -> 0
A22: 43508 | B22: 63 | C22: =IF(AC22>0,((B22-R22)+(S22-B23)),IF(B23=0, ,(B22-B23))) -> 6 | D22: 65 | E22: =IF(AC22>0,((D22-U22)+(V22-D23)),IF(D23=0, ,(D22-D23))) -> 5 | F22: 61 | G22: =IF(AC22>0,((F22-X22)+(Y22-F23)),IF(F23=0, ,(F22-F23))) -> 6 | H22: 61 | I22: =IF(AC22>0,((H22-AA22)+(AB22-H23)),IF(H23=0, ,(H22-H23))) -> 6 | J22: =B22+D22+F22+H22 -> 250 | K22: =J22/4 -> 62.5 | L22: =IF(AC22>0,((K22-AD22)+(AE22-K23)),IF(K23=0, ,(K22-K23))) -> 5.75 | M22: =7000*4 -> 28000 | N22: =L22*M22/100 -> 1610 | O22: =N22*0.53 -> 853.3 | P22: =O22*9.65 -> 8234.345 | AC22: =Q22+T22+W22+Z22 -> 0 | AD22: =(R22+U22+X22+AA22)/4 -> 0 | AE22: =(S22+V22+Y22+AB22)/4 -> 0
A23: 43509 | B23: 57 | C23: =IF(AC23>0,((B23-R23)+(S23-B24)),IF(B24=0, ,(B23-B24))) -> 4 | D23: 60 | E23: =IF(AC23>0,((D23-U23)+(V23-D24)),IF(D24=0, ,(D23-D24))) -> 4 | F23: 55 | G23: =IF(AC23>0,((F23-X23)+(Y23-F24)),IF(F24=0, ,(F23-F24))) -> 6 | H23: 55 | I23: =IF(AC23>0,((H23-AA23)+(AB23-H24)),IF(H24=0, ,(H23-H24))) -> 4 | J23: =B23+D23+F23+H23 -> 227 | K23: =J23/4 -> 56.75 | L23: =IF(AC23>0,((K23-AD23)+(AE23-K24)),IF(K24=0, ,(K23-K24))) -> 4.5 | M23: =7000*4 -> 28000 | N23: =L23*M23/100 -> 1260 | O23: =N23*0.53 -> 667.8 | P23: =O23*9.65 -> 6444.27 | AC23: =Q23+T23+W23+Z23 -> 0 | AD23: =(R23+U23+X23+AA23)/4 -> 0 | AE23: =(S23+V23+Y23+AB23)/4 -> 0
A24: 43510 | B24: 53 | C24: =IF(AC24>0,((B24-R24)+(S24-B25)),IF(B25=0, ,(B24-B25))) -> 3 | D24: 56 | E24: =IF(AC24>0,((D24-U24)+(V24-D25)),IF(D25=0, ,(D24-D25))) -> 2 | F24: 49 | G24: =IF(AC24>0,((F24-X24)+(Y24-F25)),IF(F25=0, ,(F24-F25))) -> 4 | H24: 51 | I24: =IF(AC24>0,((H24-AA24)+(AB24-H25)),IF(H25=0, ,(H24-H25))) -> 1 | J24: =B24+D24+F24+H24 -> 209 | K24: =J24/4 -> 52.25 | L24: =IF(AC24>0,((K24-AD24)+(AE24-K25)),IF(K25=0, ,(K24-K25))) -> 2.5 | M24: =7000*4 -> 28000 | N24: =L24*M24/100 -> 700 | O24: =N24*0.53 -> 371 | P24: =O24*9.65 -> 3580.15 | Q24: 3001 | R24: 50 | S24: 85 | T24: 2850 | U24: 55 | V24: 87 | W24: 3020 | X24: 48 | Y24: 87 | Z24: 2551 | AA24: 50 | AB24: 85 | AC24: =Q24+T24+W24+Z24 -> 11422 | AD24: =(R24+U24+X24+AA24)/4 -> 50.75 | AE24: =(S24+V24+Y24+AB24)/4 -> 86
A25: 43511 | B25: 85 | C25: =IF(AC25>0,((B25-R25)+(S25-B26)),IF(B26=0, ,(B25-B26))) -> 5 | D25: 86 | E25: =IF(AC25>0,((D25-U25)+(V25-D26)),IF(D26=0, ,(D25-D26))) -> 3 | F25: 84 | G25: =IF(AC25>0,((F25-X25)+(Y25-F26)),IF(F26=0, ,(F25-F26))) -> 4 | H25: 85 | I25: =IF(AC25>0,((H25-AA25)+(AB25-H26)),IF(H26=0, ,(H25-H26))) -> 5 | J25: =B25+D25+F25+H25 -> 340 | K25: =J25/4 -> 85 | L25: =IF(AC25>0,((K25-AD25)+(AE25-K26)),IF(K26=0, ,(K25-K26))) -> 4.25 | M25: =7000*4 -> 28000 | N25: =L25*M25/100 -> 1190 | O25: =N25*0.53 -> 630.7 | P25: =O25*9.65 -> 6086.255 | AC25: =Q25+T25+W25+Z25 -> 0 | AD25: =(R25+U25+X25+AA25)/4 -> 0 | AE25: =(S25+V25+Y25+AB25)/4 -> 0
A26: 43512 | B26: 80 | C26: =IF(AC26>0,((B26-R26)+(S26-B27)),IF(B27=0, ,(B26-B27))) -> 3 | D26: 83 | E26: =IF(AC26>0,((D26-U26)+(V26-D27)),IF(D27=0, ,(D26-D27))) -> 4 | F26: 80 | G26: =IF(AC26>0,((F26-X26)+(Y26-F27)),IF(F27=0, ,(F26-F27))) -> 7 | H26: 80 | I26: =IF(AC26>0,((H26-AA26)+(AB26-H27)),IF(H27=0, ,(H26-H27))) -> 7 | J26: =B26+D26+F26+H26 -> 323 | K26: =J26/4 -> 80.75 | L26: =IF(AC26>0,((K26-AD26)+(AE26-K27)),IF(K27=0, ,(K26-K27))) -> 5.25 | M26: =7000*4 -> 28000 | N26: =L26*M26/100 -> 1470 | O26: =N26*0.53 -> 779.1 | P26: =O26*9.65 -> 7518.315 | AC26: =Q26+T26+W26+Z26 -> 0 | AD26: =(R26+U26+X26+AA26)/4 -> 0 | AE26: =(S26+V26+Y26+AB26)/4 -> 0
A27: 43513 | B27: 77 | C27: =IF(AC27>0,((B27-R27)+(S27-B28)),IF(B28=0, ,(B27-B28))) -> 7 | D27: 79 | E27: =IF(AC27>0,((D27-U27)+(V27-D28)),IF(D28=0, ,(D27-D28))) -> 6 | F27: 73 | G27: =IF(AC27>0,((F27-X27)+(Y27-F28)),IF(F28=0, ,(F27-F28))) -> 7 | H27: 73 | I27: =IF(AC27>0,((H27-AA27)+(AB27-H28)),IF(H28=0, ,(H27-H28))) -> 4 | J27: =B27+D27+F27+H27 -> 302 | K27: =J27/4 -> 75.5 | L27: =IF(AC27>0,((K27-AD27)+(AE27-K28)),IF(K28=0, ,(K27-K28))) -> 6 | M27: =7000*4 -> 28000 | N27: =L27*M27/100 -> 1680 | O27: =N27*0.53 -> 890.4 | P27: =O27*9.65 -> 8592.36 | AC27: =Q27+T27+W27+Z27 -> 0 | AD27: =(R27+U27+X27+AA27)/4 -> 0 | AE27: =(S27+V27+Y27+AB27)/4 -> 0
A28: 43514 | B28: 70 | C28: =IF(AC28>0,((B28-R28)+(S28-B29)),IF(B29=0, ,(B28-B29))) -> 15 | D28: 73 | E28: =IF(AC28>0,((D28-U28)+(V28-D29)),IF(D29=0, ,(D28-D29))) -> 15 | F28: 66 | G28: =IF(AC28>0,((F28-X28)+(Y28-F29)),IF(F29=0, ,(F28-F29))) -> 16 | H28: 69 | I28: =IF(AC28>0,((H28-AA28)+(AB28-H29)),IF(H29=0, ,(H28-H29))) -> 18 | J28: =B28+D28+F28+H28 -> 278 | K28: =J28/4 -> 69.5 | L28: =IF(AC28>0,((K28-AD28)+(AE28-K29)),IF(K29=0, ,(K28-K29))) -> 16 | M28: =7000*4 -> 28000 | N28: =L28*M28/100 -> 4480 | O28: =N28*0.53 -> 2374.4 | P28: =O28*9.65 -> 22912.96 | AC28: =Q28+T28+W28+Z28 -> 0 | AD28: =(R28+U28+X28+AA28)/4 -> 0 | AE28: =(S28+V28+Y28+AB28)/4 -> 0
A29: 43515 | B29: 55 | C29: =IF(AC29>0,((B29-R29)+(S29-B30)),IF(B30=0, ,(B29-B30))) -> 17 | D29: 58 | E29: =IF(AC29>0,((D29-U29)+(V29-D30)),IF(D30=0, ,(D29-D30))) -> 18 | F29: 50 | G29: =IF(AC29>0,((F29-X29)+(Y29-F30)),IF(F30=0, ,(F29-F30))) -> 15 | H29: 51 | I29: =IF(AC29>0,((H29-AA29)+(AB29-H30)),IF(H30=0, ,(H29-H30))) -> 13 | J29: =B29+D29+F29+H29 -> 214 | K29: =J29/4 -> 53.5 | L29: =IF(AC29>0,((K29-AD29)+(AE29-K30)),IF(K30=0, ,(K29-K30))) -> 15.75 | M29: =7000*4 -> 28000 | N29: =L29*M29/100 -> 4410 | O29: =N29*0.53 -> 2337.3 | P29: =O29*9.65 -> 22554.945 | AC29: =Q29+T29+W29+Z29 -> 0 | AD29: =(R29+U29+X29+AA29)/4 -> 0 | AE29: =(S29+V29+Y29+AB29)/4 -> 0
A30: 43516 | B30: 38 | C30: =IF(AC30>0,((B30-R30)+(S30-B31)),IF(B31=0, ,(B30-B31))) -> 31 | D30: 40 | E30: =IF(AC30>0,((D30-U30)+(V30-D31)),IF(D31=0, ,(D30-D31))) -> 25 | F30: 35 | G30: =IF(AC30>0,((F30-X30)+(Y30-F31)),IF(F31=0, ,(F30-F31))) -> 1 | H30: 38 | I30: =IF(AC30>0,((H30-AA30)+(AB30-H31)),IF(H31=0, ,(H30-H31))) -> -3 | J30: =B30+D30+F30+H30 -> 151 | K30: =J30/4 -> 37.75 | L30: =IF(AC30>0,((K30-AD30)+(AE30-K31)),IF(K31=0, ,(K30-K31))) -> 13.5 | M30: =7000*4 -> 28000 | N30: =L30*M30/100 -> 3780 | O30: =N30*0.53 -> 2003.4 | P30: =O30*9.65 -> 19332.81 | Q30: 5100 | R30: 30 | S30: 85 | T30: 3920 | U30: 35 | V30: 85 | W30: 1997 | X30: 30 | Y30: 56 | AC30: =Q30+T30+W30+Z30 -> 11017 | AD30: =(R30+U30+X30+AA30)/4 -> 23.75 | AE30: =(S30+V30+Y30+AB30)/4 -> 56.5
A31: 43517 | B31: 62 | C31: =IF(AC31>0,((B31-R31)+(S31-B32)),IF(B32=0, ,(B31-B32))) -> 20 | D31: 65 | E31: =IF(AC31>0,((D31-U31)+(V31-D32)),IF(D32=0, ,(D31-D32))) -> 16 | F31: 60 | G31: =IF(AC31>0,((F31-X31)+(Y31-F32)),IF(F32=0, ,(F31-F32))) -> 20 | H31: 41 | I31: =IF(AC31>0,((H31-AA31)+(AB31-H32)),IF(H32=0, ,(H31-H32))) -> 1 | J31: =B31+D31+F31+H31 -> 228 | K31: =J31/4 -> 57 | L31: =IF(AC31>0,((K31-AD31)+(AE31-K32)),IF(K32=0, ,(K31-K32))) -> 14.25 | M31: =7000*4 -> 28000 | N31: =L31*M31/100 -> 3990 | O31: =N31*0.53 -> 2114.7 | P31: =O31*9.65 -> 20406.855 | AC31: =Q31+T31+W31+Z31 -> 0 | AD31: =(R31+U31+X31+AA31)/4 -> 0 | AE31: =(S31+V31+Y31+AB31)/4 -> 0
A32: 43518 | B32: 42 | C32: =IF(AC32>0,((B32-R32)+(S32-B33)),IF(B33=0, ,(B32-B33))) -> 11 | D32: 49 | E32: =IF(AC32>0,((D32-U32)+(V32-D33)),IF(D33=0, ,(D32-D33))) -> 16 | F32: 40 | G32: =IF(AC32>0,((F32-X32)+(Y32-F33)),IF(F33=0, ,(F32-F33))) -> 6 | H32: 40 | I32: =IF(AC32>0,((H32-AA32)+(AB32-H33)),IF(H33=0, ,(H32-H33))) -> 5 | J32: =B32+D32+F32+H32 -> 171 | K32: =J32/4 -> 42.75 | L32: =IF(AC32>0,((K32-AD32)+(AE32-K33)),IF(K33=0, ,(K32-K33))) -> 9.5 | M32: =7000*4 -> 28000 | N32: =L32*M32/100 -> 2660 | O32: =N32*0.53 -> 1409.8 | P32: =O32*9.65 -> 13604.57 | Q32: 2722 | R32: 47 | S32: 82 | T32: 2645 | U32: 50 | V32: 85 | W32: 2741 | X32: 37 | Y32: 65 | Z32: 2731 | AA32: 35 | AB32: 60 | AC32: =Q32+T32+W32+Z32 -> 10839 | AD32: =(R32+U32+X32+AA32)/4 -> 42.25 | AE32: =(S32+V32+Y32+AB32)/4 -> 73
A33: 43519 | B33: 66 | C33: =IF(AC33>0,((B33-R33)+(S33-B34)),IF(B34=0, ,(B33-B34))) -> 16 | D33: 68 | E33: =IF(AC33>0,((D33-U33)+(V33-D34)),IF(D34=0, ,(D33-D34))) -> 12 | F33: 62 | G33: =IF(AC33>0,((F33-X33)+(Y33-F34)),IF(F34=0, ,(F33-F34))) -> 13 | H33: 60 | I33: =IF(AC33>0,((H33-AA33)+(AB33-H34)),IF(H34=0, ,(H33-H34))) -> 11 | J33: =B33+D33+F33+H33 -> 256 | K33: =J33/4 -> 64 | L33: =IF(AC33>0,((K33-AD33)+(AE33-K34)),IF(K34=0, ,(K33-K34))) -> 13 | M33: =7000*4 -> 28000 | N33: =L33*M33/100 -> 3640 | O33: =N33*0.53 -> 1929.2 | P33: =O33*9.65 -> 18616.78 | AC33: =Q33+T33+W33+Z33 -> 0 | AD33: =(R33+U33+X33+AA33)/4 -> 0 | AE33: =(S33+V33+Y33+AB33)/4 -> 0
A34: 43520 | B34: 50 | C34: =IF(AC34>0,((B34-R34)+(S34-B35)),IF(B35=0, ,(B34-B35))) -> 16 | D34: 56 | E34: =IF(AC34>0,((D34-U34)+(V34-D35)),IF(D35=0, ,(D34-D35))) -> 17 | F34: 49 | G34: =IF(AC34>0,((F34-X34)+(Y34-F35)),IF(F35=0, ,(F34-F35))) -> 16 | H34: 49 | I34: =IF(AC34>0,((H34-AA34)+(AB34-H35)),IF(H35=0, ,(H34-H35))) -> 17 | J34: =B34+D34+F34+H34 -> 204 | K34: =J34/4 -> 51 | L34: =IF(AC34>0,((K34-AD34)+(AE34-K35)),IF(K35=0, ,(K34-K35))) -> 16.5 | M34: =7000*4 -> 28000 | N34: =L34*M34/100 -> 4620 | O34: =N34*0.53 -> 2448.6 | P34: =O34*9.65 -> 23628.99 | AC34: =Q34+T34+W34+Z34 -> 0 | AD34: =(R34+U34+X34+AA34)/4 -> 0 | AE34: =(S34+V34+Y34+AB34)/4 -> 0
A35: 43521 | B35: 34 | C35: =IF(AC35>0,((B35-R35)+(S35-B36)),IF(B36=0, ,(B35-B36))) -> 15 | D35: 39 | E35: =IF(AC35>0,((D35-U35)+(V35-D36)),IF(D36=0, ,(D35-D36))) -> 12 | F35: 33 | G35: =IF(AC35>0,((F35-X35)+(Y35-F36)),IF(F36=0, ,(F35-F36))) -> 12 | H35: 32 | I35: =IF(AC35>0,((H35-AA35)+(AB35-H36)),IF(H36=0, ,(H35-H36))) -> 10 | J35: =B35+D35+F35+H35 -> 138 | K35: =J35/4 -> 34.5 | L35: =IF(AC35>0,((K35-AD35)+(AE35-K36)),IF(K36=0, ,(K35-K36))) -> 12.25 | M35: =7000*4 -> 28000 | N35: =L35*M35/100 -> 3430 | O35: =N35*0.53 -> 1817.9 | P35: =O35*9.65 -> 17542.735 | Q35: 1302 | R35: 27 | S35: 45 | T35: 1300 | U35: 35 | V35: 50 | W35: 1300 | X35: 30 | Y35: 45 | Z35: 1301 | AA35: 27 | AB35: 40 | AC35: =Q35+T35+W35+Z35 -> 5203 | AD35: =(R35+U35+X35+AA35)/4 -> 29.75 | AE35: =(S35+V35+Y35+AB35)/4 -> 45
A36: 43522 | B36: 37 | C36: =IF(AC36>0,((B36-R36)+(S36-B37)),IF(B37=0, ,(B36-B37))) -> 7 | D36: 42 | E36: =IF(AC36>0,((D36-U36)+(V36-D37)),IF(D37=0, ,(D36-D37))) -> 7 | F36: 36 | G36: =IF(AC36>0,((F36-X36)+(Y36-F37)),IF(F37=0, ,(F36-F37))) -> 5 | H36: 35 | I36: =IF(AC36>0,((H36-AA36)+(AB36-H37)),IF(H37=0, ,(H36-H37))) -> 7 | J36: =B36+D36+F36+H36 -> 150 | K36: =J36/4 -> 37.5 | L36: =IF(AC36>0,((K36-AD36)+(AE36-K37)),IF(K37=0, ,(K36-K37))) -> 6.5 | M36: =7000*4 -> 28000 | N36: =L36*M36/100 -> 1820 | O36: =N36*0.53 -> 964.6 | P36: =O36*9.65 -> 9308.39 | Q36: 3620 | R36: 36 | S36: 83 | T36: 4616 | U36: 40 | V36: 85 | W36: 3270 | X36: 42 | Y36: 85 | Z36: 3564 | AA36: 39 | AB36: 85 | AC36: =Q36+T36+W36+Z36 -> 15070 | AD36: =(R36+U36+X36+AA36)/4 -> 39.25 | AE36: =(S36+V36+Y36+AB36)/4 -> 84.5
A37: 43523 | B37: 77 | C37: =IF(AC37>0,((B37-R37)+(S37-B38)),IF(B38=0, ,(B37-B38))) -> 7 | D37: 80 | E37: =IF(AC37>0,((D37-U37)+(V37-D38)),IF(D38=0, ,(D37-D38))) -> 8 | F37: 74 | G37: =IF(AC37>0,((F37-X37)+(Y37-F38)),IF(F38=0, ,(F37-F38))) -> 7 | H37: 74 | I37: =IF(AC37>0,((H37-AA37)+(AB37-H38)),IF(H38=0, ,(H37-H38))) -> 6 | J37: =B37+D37+F37+H37 -> 305 | K37: =J37/4 -> 76.25 | L37: =IF(AC37>0,((K37-AD37)+(AE37-K38)),IF(K38=0, ,(K37-K38))) -> 7 | M37: =7000*4 -> 28000 | N37: =L37*M37/100 -> 1960 | O37: =N37*0.53 -> 1038.8 | P37: =O37*9.65 -> 10024.42 | AC37: =Q37+T37+W37+Z37 -> 0 | AD37: =(R37+U37+X37+AA37)/4 -> 0 | AE37: =(S37+V37+Y37+AB37)/4 -> 0
A38: 43524 | B38: 70 | C38: =IF(AC38>0,((B38-R38)+(S38-B39)),IF(B39=0, ,(B38-B39))) -> 8 | D38: 72 | E38: =IF(AC38>0,((D38-U38)+(V38-D39)),IF(D39=0, ,(D38-D39))) -> 7 | F38: 67 | G38: =IF(AC38>0,((F38-X38)+(Y38-F39)),IF(F39=0, ,(F38-F39))) -> 8 | H38: 68 | I38: =IF(AC38>0,((H38-AA38)+(AB38-H39)),IF(H39=0, ,(H38-H39))) -> 7 | J38: =B38+D38+F38+H38 -> 277 | K38: =J38/4 -> 69.25 | L38: =IF(AC38>0,((K38-AD38)+(AE38-K39)),IF(K39=0, ,(K38-K39))) -> 7.5 | M38: =7000*4 -> 28000 | N38: =L38*M38/100 -> 2100 | O38: =N38*0.53 -> 1113 | P38: =O38*9.65 -> 10740.45 | AC38: =Q38+T38+W38+Z38 -> 0 | AD38: =(R38+U38+X38+AA38)/4 -> 0 | AE38: =(S38+V38+Y38+AB38)/4 -> 0
A39: 43525 | B39: 62 | C39: =IF(AC39>0,((B39-R39)+(S39-B40)),IF(B40=0, ,(B39-B40))) -> 8 | D39: 65 | E39: =IF(AC39>0,((D39-U39)+(V39-D40)),IF(D40=0, ,(D39-D40))) -> 6 | F39: 59 | G39: =IF(AC39>0,((F39-X39)+(Y39-F40)),IF(F40=0, ,(F39-F40))) -> 9 | H39: 61 | I39: =IF(AC39>0,((H39-AA39)+(AB39-H40)),IF(H40=0, ,(H39-H40))) -> 8 | J39: =B39+D39+F39+H39 -> 247 | K39: =J39/4 -> 61.75 | L39: =IF(AC39>0,((K39-AD39)+(AE39-K40)),IF(K40=0, ,(K39-K40))) -> 7.75 | M39: =7000*4 -> 28000 | N39: =L39*M39/100 -> 2170 | O39: =N39*0.53 -> 1150.1 | P39: =O39*9.65 -> 11098.465 | AC39: =Q39+T39+W39+Z39 -> 0 | AD39: =(R39+U39+X39+AA39)/4 -> 0 | AE39: =(S39+V39+Y39+AB39)/4 -> 0
A40: 43526 | B40: 54 | C40: =IF(AC40>0,((B40-R40)+(S40-B41)),IF(B41=0, ,(B40-B41))) -> 0 | D40: 59 | E40: =IF(AC40>0,((D40-U40)+(V40-D41)),IF(D41=0, ,(D40-D41))) -> 0 | F40: 50 | G40: =IF(AC40>0,((F40-X40)+(Y40-F41)),IF(F41=0, ,(F40-F41))) -> 0 | H40: 53 | I40: =IF(AC40>0,((H40-AA40)+(AB40-H41)),IF(H41=0, ,(H40-H41))) -> 0 | J40: =B40+D40+F40+H40 -> 216 | K40: =J40/4 -> 54 | L40: =IF(AC40>0,((K40-AD40)+(AE40-K41)),IF(K41=0, ,(K40-K41))) -> 0 | M40: =7000*4 -> 28000 | N40: =L40*M40/100 -> 0 | O40: =N40*0.53 -> 0 | P40: =O40*9.65 -> 0 | AC40: =Q40+T40+W40+Z40 -> 0 | AD40: =(R40+U40+X40+AA40)/4 -> 0 | AE40: =(S40+V40+Y40+AB40)/4 -> 0
...

Sheet Suivi EAU-ELEC
C1: Suivi Compteur d'Eau- électricité RADEEMA -
A7: Date | B7: Eau m3 | D7: Electricité Kw/h
B8: Compteur | C8: Consommation | D8: Compteur H.Creuse | E8: Consommation H.Creuse | F8: Compteur H.Pleine | G8: Consommation H.Pleine | H8: Compteur H.Pointe | I8: Consommation H.Pointe
A9: 43490 | B9: 101623 | C9: =IF(B10<B9,0,B10-B9)*10 -> 320 | D9: 16045022 | E9: =IF(D10<D9,0,D10-D9) -> 3786 | F9: 28966072 | G9: =IF(F10<F9,0,F10-F9) -> 6799 | H9: 12880553 | I9: =IF(H10<H9,0,H10-H9) -> 2912
A10: =A9+1 -> 43491 | B10: 101655 | C10: =IF(B11<B10,0,B11-B10)*10 -> 310 | D10: 16048808 | E10: =IF(D11<D10,0,D11-D10) -> 4098 | F10: 28972871 | G10: =IF(F11<F10,0,F11-F10) -> 6046 | H10: 12883465 | I10: =IF(H11<H10,0,H11-H10) -> 2763
A11: =A10+1 -> 43492 | B11: 101686 | C11: =IF(B12<B11,0,B12-B11)*10 -> 300 | D11: 16052906 | E11: =IF(D12<D11,0,D12-D11) -> 3972 | F11: 28978917 | G11: =IF(F12<F11,0,F12-F11) -> 6075 | H11: 12886228 | I11: =IF(H12<H11,0,H12-H11) -> 2636
A12: =A11+1 -> 43493 | B12: 101716 | C12: =IF(B13<B12,0,B13-B12)*10 -> 340 | D12: 16056878 | E12: =IF(D13<D12,0,D13-D12) -> 4606 | F12: 28984992 | G12: =IF(F13<F12,0,F13-F12) -> 6072 | H12: 12888864 | I12: =IF(H13<H12,0,H13-H12) -> 2642
A13: =A12+1 -> 43494 | B13: 101750 | C13: =IF(B14<B13,0,B14-B13)*10 -> 300 | D13: 16061484 | E13: =IF(D14<D13,0,D14-D13) -> 3534 | F13: 28991064 | G13: =IF(F14<F13,0,F14-F13) -> 5963 | H13: 12891506 | I13: =IF(H14<H13,0,H14-H13) -> 2763
A14: =A13+1 -> 43495 | B14: 101780 | C14: =IF(B15<B14,0,B15-B14)*10 -> 300 | D14: 16065018 | E14: =IF(D15<D14,0,D15-D14) -> 3365 | F14: 28997027 | G14: =IF(F15<F14,0,F15-F14) -> 6122 | H14: 12894269 | I14: =IF(H15<H14,0,H15-H14) -> 2740
A15: =A14+1 -> 43496 | B15: 101810 | C15: =IF(B16<B15,0,B16-B15)*10 -> 310 | D15: 16068383 | E15: =IF(D16<D15,0,D16-D15) -> 3857 | F15: 29003149 | G15: =IF(F16<F15,0,F16-F15) -> 6317 | H15: 12897009 | I15: =IF(H16<H15,0,H16-H15) -> 2820
A16: =A15+1 -> 43497 | B16: 101841 | C16: =IF(B17<B16,0,B17-B16)*10 -> 260 | D16: 16072240 | E16: =IF(D17<D16,0,D17-D16) -> 4091 | F16: 29009466 | G16: =IF(F17<F16,0,F17-F16) -> 5953 | H16: 12899829 | I16: =IF(H17<H16,0,H17-H16) -> 2753
A17: =A16+1 -> 43498 | B17: 101867 | C17: =IF(B18<B17,0,B18-B17)*10 -> 290 | D17: 16076331 | E17: =IF(D18<D17,0,D18-D17) -> 3913 | F17: 29015419 | G17: =IF(F18<F17,0,F18-F17) -> 5980 | H17: 12902582 | I17: =IF(H18<H17,0,H18-H17) -> 2802
A18: =A17+1 -> 43499 | B18: 101896 | C18: =IF(B19<B18,0,B19-B18)*10 -> 290 | D18: 16080244 | E18: =IF(D19<D18,0,D19-D18) -> 4337 | F18: 29021399 | G18: =IF(F19<F18,0,F19-F18) -> 6419 | H18: 12905384 | I18: =IF(H19<H18,0,H19-H18) -> 3216
A19: =A18+1 -> 43500 | B19: 101925 | C19: =IF(B20<B19,0,B20-B19)*10 -> 370 | D19: 16084581 | E19: =IF(D20<D19,0,D20-D19) -> 4771 | F19: 29027818 | G19: =IF(F20<F19,0,F20-F19) -> 7231 | H19: 12908600 | I19: =IF(H20<H19,0,H20-H19) -> 3344
A20: =A19+1 -> 43501 | B20: 101962 | C20: =IF(B21<B20,0,B21-B20)*10 -> 320 | D20: 16089352 | E20: =IF(D21<D20,0,D21-D20) -> 4760 | F20: 29035049 | G20: =IF(F21<F20,0,F21-F20) -> 7167 | H20: 12911944 | I20: =IF(H21<H20,0,H21-H20) -> 3171
A21: =A20+1 -> 43502 | B21: 101994 | C21: =IF(B22<B21,0,B22-B21)*10 -> 330 | D21: 16094112 | E21: =IF(D22<D21,0,D22-D21) -> 4610 | F21: 29042216 | G21: =IF(F22<F21,0,F22-F21) -> 7145 | H21: 12915115 | I21: =IF(H22<H21,0,H22-H21) -> 3226
... A45: =A44+1 -> 43526 | B45: 102921 | C45: =IF(B46<B45,0,B46-B45)*10 -> 0 | D45: 16204083 | E45: =IF(D46<D45,0,D46-D45) -> 0 | F45: 29216351 | G45: =IF(F46<F45,0,F46-F45) -> 0 | H45: 12994372 | I45: =IF(H46<H45,0,H46-H45) -> 0
A46: =A45+1 -> 43527 | C46: =IF(B47<B46,0,B47-B46)*10 -> 0 | E46: =IF(D47<D46,0,D47-D46) -> 0 | G46: =IF(F47<F46,0,F47-F46) -> 0 | I46: =IF(H47<H46,0,H47-H46) -> 0
A47: =A46+1 -> 43528 | C47: =IF(B48<B47,0,B48-B47)*10 -> 0 | E47: =IF(D48<D47,0,D48-D47) -> 0 | G47: =IF(F48<F47,0,F48-F47) -> 0 | I47: =IF(H48<H47,0,H48-H47) -> 0
C48: =SUM(C16:C43) -> 10380 | E48: =SUM(E16:E43) -> 126896 | G48: =SUM(G16:G43) -> 199206 | I48: =SUM(I16:I43) -> 90714
G58: =IF(F59<F58,0,F59-F58) -> 0

Sheet Feuil1
