Workbook

Sheet TOTAL
A1: Site Name | B1: Day | C1: Month | D1: Year | E1: Total Electricity Kwh | F1: Electricity Tariff ($/Kwh) | G1: LPG (Kg) | H1: LPG $/Kg | I1: District Energy Heating Kwh | J1: District Energy Heating $/Kwh | K1: Water Utility Supply (m3) m3 | L1: Water Utility Supply (m3) $/m3 | M1: Room Nights | N1: Total Guests | O1: Utilities day cost dh
A2: Marrakech | B2: 1 | C2: 2 | D2: 2020 | E2: ='Consommation du 01.02 au 29.02'!M10 -> 13061 | F2: 1.002 | G2: ='Consommation du 01.02 au 29.02'!U10 -> 1780.8 | H2: 9.3657 | I2: ='Consommation du 01.02 au 29.02'!Y10*1000 -> 1430 | J2: 0.53 | K2: ='Consommation du 01.02 au 29.02'!D10 -> 470 | L2: 12.67 | M2: ='Consommation du 01.02 au 29.02'!AC10 -> 128 | N2: 245 | O2: =E2*F2+G2*H2+I2*J2+K2*L2 -> 36478.361
A3: Marrakech | B3: =B2+1 -> 2 | C3: 2 | D3: 2020 | E3: ='Consommation du 01.02 au 29.02'!M11 -> 14391 | F3: 1.002 | G3: ='Consommation du 01.02 au 29.02'!U11 -> 1446.9 | H3: 9.3657 | I3: ='Consommation du 01.02 au 29.02'!Y11*1000 -> 11110 | J3: 0.53 | K3: ='Consommation du 01.02 au 29.02'!D11 -> 540 | L3: 12.67 | M3: ='Consommation du 01.02 au 29.02'!AC11 -> 126 | N3: 250 | O3: =E3*F3+G3*H3+I3*J3+K3*L3 -> 40701.113
A4: Marrakech | B4: =B3+1 -> 3 | C4: 2 | D4: 2020 | E4: ='Consommation du 01.02 au 29.02'!M12 -> 15693 | F4: 1.002 | G4: ='Consommation du 01.02 au 29.02'!U12 -> 1558.2 | H4: 9.3657 | I4: ='Consommation du 01.02 au 29.02'!Y12*1000 -> 14880 | J4: 0.53 | K4: ='Consommation du 01.02 au 29.02'!D12 -> 470 | L4: 12.67 | M4: ='Consommation du 01.02 au 29.02'!AC12 -> 129 | N4: 243 | O4: =E4*F4+G4*H4+I4*J4+K4*L4 -> 44159.32
A5: Marrakech | B5: =B4+1 -> 4 | C5: 2 | D5: 2020 | E5: ='Consommation du 01.02 au 29.02'!M13 -> 16210 | F5: 1.002 | G5: ='Consommation du 01.02 au 29.02'!U13 -> 556.5 | H5: 9.3657 | I5: ='Consommation du 01.02 au 29.02'!Y13*1000 -> 17570 | J5: 0.53 | K5: ='Consommation du 01.02 au 29.02'!D13 -> 500 | L5: 12.67 | M5: ='Consommation du 01.02 au 29.02'!AC13 -> 111 | N5: 210 | O5: =E5*F5+G5*H5+I5*J5+K5*L5 -> 37101.532
A6: Marrakech | B6: =B5+1 -> 5 | C6: 2 | D6: 2020 | E6: ='Consommation du 01.02 au 29.02'!M14 -> 16303 | F6: 1.002 | G6: ='Consommation du 01.02 au 29.02'!U14 -> 408.1 | H6: 9.3657 | I6: ='Consommation du 01.02 au 29.02'!Y14*1000 -> 17350 | J6: 0.53 | K6: ='Consommation du 01.02 au 29.02'!D14 -> 520 | L6: 12.67 | M6: ='Consommation du 01.02 au 29.02'!AC14 -> 111 | N6: 205 | O6: =E6*F6+G6*H6+I6*J6+K6*L6 -> 35941.648
A7: Marrakech | B7: =B6+1 -> 6 | C7: 2 | D7: 2020 | E7: ='Consommation du 01.02 au 29.02'!M15 -> 18306 | F7: 1.002 | G7: ='Consommation du 01.02 au 29.02'!U15 -> 519.4 | H7: 9.3657 | I7: ='Consommation du 01.02 au 29.02'!Y15*1000 -> 17500 | J7: 0.53 | K7: ='Consommation du 01.02 au 29.02'!D15 -> 510 | L7: 12.67 | M7: ='Consommation du 01.02 au 29.02'!AC15 -> 103 | N7: 201 | O7: =E7*F7+G7*H7+I7*J7+K7*L7 -> 38943.857
A8: Marrakech | B8: =B7+1 -> 7 | C8: 2 | D8: 2020 | E8: ='Consommation du 01.02 au 29.02'!M16 -> 15369 | F8: 1.002 | G8: ='Consommation du 01.02 au 29.02'!U16 -> 779.1 | H8: 9.3657 | I8: ='Consommation du 01.02 au 29.02'!Y16*1000 -> 14690 | J8: 0.53 | K8: ='Consommation du 01.02 au 29.02'!D16 -> 500 | L8: 12.67 | M8: ='Consommation du 01.02 au 29.02'!AC16 -> 114 | N8: 224 | O8: =E8*F8+G8*H8+I8*J8+K8*L8 -> 36817.255
A9: Marrakech | B9: =B8+1 -> 8 | C9: 2 | D9: 2020 | E9: ='Consommation du 01.02 au 29.02'!M17 -> 15877 | F9: 1.002 | G9: ='Consommation du 01.02 au 29.02'!U17 -> 704.9 | H9: 9.3657 | I9: ='Consommation du 01.02 au 29.02'!Y17*1000 -> 16400 | J9: 0.53 | K9: ='Consommation du 01.02 au 29.02'!D17 -> 560 | L9: 12.67 | M9: ='Consommation du 01.02 au 29.02'!AC17 -> 101 | N9: 196 | O9: =E9*F9+G9*H9+I9*J9+K9*L9 -> 38297.836
A10: Marrakech | B10: =B9+1 -> 9 | C10: 2 | D10: 2020 | E10: ='Consommation du 01.02 au 29.02'!M18 -> 13938 | F10: 1.002 | G10: ='Consommation du 01.02 au 29.02'!U18 -> 519.4 | H10: 9.3657 | I10: ='Consommation du 01.02 au 29.02'!Y18*1000 -> 17250 | J10: 0.53 | K10: ='Consommation du 01.02 au 29.02'!D18 -> 470 | L10: 12.67 | M10: ='Consommation du 01.02 au 29.02'!AC18 -> 91 | N10: 184 | O10: =E10*F10+G10*H10+I10*J10+K10*L10 -> 33927.821
A11: Marrakech | B11: =B10+1 -> 10 | C11: 2 | D11: 2020 | E11: ='Consommation du 01.02 au 29.02'!M19 -> 16253 | F11: 1.002 | G11: ='Consommation du 01.02 au 29.02'!U19 -> 519.4 | H11: 9.3657 | I11: ='Consommation du 01.02 au 29.02'!Y19*1000 -> 16710 | J11: 0.53 | K11: ='Consommation du 01.02 au 29.02'!D19 -> 480 | L11: 12.67 | M11: ='Consommation du 01.02 au 29.02'!AC19 -> 87 | N11: 178 | O11: =E11*F11+G11*H11+I11*J11+K11*L11 -> 36087.951
A12: Marrakech | B12: =B11+1 -> 11 | C12: 2 | D12: 2020 | E12: ='Consommation du 01.02 au 29.02'!M20 -> 16442 | F12: 1.002 | G12: ='Consommation du 01.02 au 29.02'!U20 -> 853.3 | H12: 9.3657 | I12: ='Consommation du 01.02 au 29.02'!Y20*1000 -> 14320 | J12: 0.53 | K12: ='Consommation du 01.02 au 29.02'!D20 -> 690 | L12: 12.67 | M12: ='Consommation du 01.02 au 29.02'!AC20 -> 76 | N12: 160 | O12: =E12*F12+G12*H12+I12*J12+K12*L12 -> 40798.536
A13: Marrakech | B13: =B12+1 -> 12 | C13: 2 | D13: 2020 | E13: ='Consommation du 01.02 au 29.02'!M21 -> 16429 | F13: 1.002 | G13: ='Consommation du 01.02 au 29.02'!U21 -> 1372.7 | H13: 9.3657 | I13: ='Consommation du 01.02 au 29.02'!Y21*1000 -> 13610 | J13: 0.53 | K13: ='Consommation du 01.02 au 29.02'!D21 -> 610 | L13: 12.67 | M13: ='Consommation du 01.02 au 29.02'!AC21 -> 83 | N13: 175 | O13: =E13*F13+G13*H13+I13*J13+K13*L13 -> 44260.154
A14: Marrakech | B14: =B13+1 -> 13 | C14: 2 | D14: 2020 | E14: ='Consommation du 01.02 au 29.02'!M22 -> 0 | F14: 1.002 | G14: ='Consommation du 01.02 au 29.02'!U22 -> 0 | H14: 9.3657 | I14: ='Consommation du 01.02 au 29.02'!Y22*1000 -> 0 | J14: 0.53 | K14: ='Consommation du 01.02 au 29.02'!D22 -> 0 | L14: 12.67 | M14: ='Consommation du 01.02 au 29.02'!AC22 -> 0 | O14: =E14*F14+G14*H14+I14*J14+K14*L14 -> 0
A15: Marrakech | B15: =B14+1 -> 14 | C15: 2 | D15: 2020 | E15: ='Consommation du 01.02 au 29.02'!M23 -> 0 | F15: 1.002 | G15: ='Consommation du 01.02 au 29.02'!U23 -> 0 | H15: 9.3657 | I15: ='Consommation du 01.02 au 29.02'!Y23*1000 -> 0 | J15: 0.53 | K15: ='Consommation du 01.02 au 29.02'!D23 -> 0 | L15: 12.67 | M15: ='Consommation du 01.02 au 29.02'!AC23 -> 0 | O15: =E15*F15+G15*H15+I15*J15+K15*L15 -> 0
A16: Marrakech | B16: =B15+1 -> 15 | C16: 2 | D16: 2020 | E16: ='Consommation du 01.02 au 29.02'!M24 -> 0 | F16: 1.002 | G16: ='Consommation du 01.02 au 29.02'!U24 -> 0 | H16: 9.3657 | I16: ='Consommation du 01.02 au 29.02'!Y24*1000 -> 0 | J16: 0.53 | K16: ='Consommation du 01.02 au 29.02'!D24 -> 0 | L16: 12.67 | M16: ='Consommation du 01.02 au 29.02'!AC24 -> 0 | O16: =E16*F16+G16*H16+I16*J16+K16*L16 -> 0
A17: Marrakech | B17: =B16+1 -> 16 | C17: 2 | D17: 2020 | E17: ='Consommation du 01.02 au 29.02'!M25 -> 0 | F17: 1.002 | G17: ='Consommation du 01.02 au 29.02'!U25 -> 0 | H17: 9.3657 | I17: ='Consommation du 01.02 au 29.02'!Y25*1000 -> 0 | J17: 0.53 | K17: ='Consommation du 01.02 au 29.02'!D25 -> 0 | L17: 12.67 | M17: ='Consommation du 01.02 au 29.02'!AC25 -> 0 | O17: =E17*F17+G17*H17+I17*J17+K17*L17 -> 0
A18: Marrakech | B18: =B17+1 -> 17 | C18: 2 | D18: 2020 | E18: ='Consommation du 01.02 au 29.02'!M26 -> 0 | F18: 1.002 | G18: ='Consommation du 01.02 au 29.02'!U26 -> 0 | H18: 9.3657 | I18: ='Consommation du 01.02 au 29.02'!Y26*1000 -> 0 | J18: 0.53 | K18: ='Consommation du 01.02 au 29.02'!D26 -> 0 | L18: 12.67 | M18: ='Consommation du 01.02 au 29.02'!AC26 -> 0 | O18: =E18*F18+G18*H18+I18*J18+K18*L18 -> 0
A19: Marrakech | B19: =B18+1 -> 18 | C19: 2 | D19: 2020 | E19: ='Consommation du 01.02 au 29.02'!M27 -> 0 | F19: 1.002 | G19: ='Consommation du 01.02 au 29.02'!U27 -> 0 | H19: 9.3657 | I19: ='Consommation du 01.02 au 29.02'!Y27*1000 -> 0 | J19: 0.53 | K19: ='Consommation du 01.02 au 29.02'!D27 -> 0 | L19: 12.67 | M19: ='Consommation du 01.02 au 29.02'!AC27 -> 0 | O19: =E19*F19+G19*H19+I19*J19+K19*L19 -> 0
A20: Marrakech | B20: =B19+1 -> 19 | C20: 2 | D20: 2020 | E20: ='Consommation du 01.02 au 29.02'!M28 -> 0 | F20: 1.002 | G20: ='Consommation du 01.02 au 29.02'!U28 -> 0 | H20: 9.3657 | I20: ='Consommation du 01.02 au 29.02'!Y28*1000 -> 0 | J20: 0.53 | K20: ='Consommation du 01.02 au 29.02'!D28 -> 0 | L20: 12.67 | M20: ='Consommation du 01.02 au 29.02'!AC28 -> 0 | O20: =E20*F20+G20*H20+I20*J20+K20*L20 -> 0
A21: Marrakech | B21: =B20+1 -> 20 | C21: 2 | D21: 2020 | E21: ='Consommation du 01.02 au 29.02'!M29 -> 0 | F21: 1.002 | G21: ='Consommation du 01.02 au 29.02'!U29 -> 0 | H21: 9.3657 | I21: ='Consommation du 01.02 au 29.02'!Y29*1000 -> 0 | J21: 0.53 | K21: ='Consommation du 01.02 au 29.02'!D29 -> 0 | L21: 12.67 | M21: ='Consommation du 01.02 au 29.02'!AC29 -> 0 | O21: =E21*F21+G21*H21+I21*J21+K21*L21 -> 0
A22: Marrakech | B22: =B21+1 -> 21 | C22: 2 | D22: 2020 | E22: ='Consommation du 01.02 au 29.02'!M30 -> 0 | F22: 1.002 | G22: ='Consommation du 01.02 au 29.02'!U30 -> 0 | H22: 9.3657 | I22: ='Consommation du 01.02 au 29.02'!Y30*1000 -> 0 | J22: 0.53 | K22: ='Consommation du 01.02 au 29.02'!D30 -> 0 | L22: 12.67 | M22: ='Consommation du 01.02 au 29.02'!AC30 -> 0 | O22: =E22*F22+G22*H22+I22*J22+K22*L22 -> 0
A23: Marrakech | B23: =B22+1 -> 22 | C23: 2 | D23: 2020 | E23: ='Consommation du 01.02 au 29.02'!M31 -> 0 | F23: 1.002 | G23: ='Consommation du 01.02 au 29.02'!U31 -> 0 | H23: 9.3657 | I23: ='Consommation du 01.02 au 29.02'!Y31*1000 -> 0 | J23: 0.53 | K23: ='Consommation du 01.02 au 29.02'!D31 -> 0 | L23: 12.67 | M23: ='Consommation du 01.02 au 29.02'!AC31 -> 0 | O23: =E23*F23+G23*H23+I23*J23+K23*L23 -> 0
A24: Marrakech | B24: =B23+1 -> 23 | C24: 2 | D24: 2020 | E24: ='Consommation du 01.02 au 29.02'!M32 -> 0 | F24: 1.002 | G24: ='Consommation du 01.02 au 29.02'!U32 -> 0 | H24: 9.3657 | I24: ='Consommation du 01.02 au 29.02'!Y32*1000 -> 0 | J24: 0.53 | K24: ='Consommation du 01.02 au 29.02'!D32 -> 0 | L24: 12.67 | M24: ='Consommation du 01.02 au 29.02'!AC32 -> 0 | O24: =E24*F24+G24*H24+I24*J24+K24*L24 -> 0
A25: Marrakech | B25: =B24+1 -> 24 | C25: 2 | D25: 2020 | E25: ='Consommation du 01.02 au 29.02'!M33 -> 0 | F25: 1.002 | G25: ='Consommation du 01.02 au 29.02'!U33 -> 0 | H25: 9.3657 | I25: ='Consommation du 01.02 au 29.02'!Y33*1000 -> 0 | J25: 0.53 | K25: ='Consommation du 01.02 au 29.02'!D33 -> 0 | L25: 12.67 | M25: ='Consommation du 01.02 au 29.02'!AC33 -> 0 | O25: =E25*F25+G25*H25+I25*J25+K25*L25 -> 0
... A29: Marrakech | B29: =B28+1 -> 28 | C29: 2 | D29: 2020 | E29: ='Consommation du 01.02 au 29.02'!M37 -> 0 | F29: 1.002 | G29: ='Consommation du 01.02 au 29.02'!U37 -> 0 | H29: 9.3657 | I29: ='Consommation du 01.02 au 29.02'!Y37*1000 -> 0 | J29: 0.53 | K29: ='Consommation du 01.02 au 29.02'!D37 -> 0 | L29: 12.67 | M29: ='Consommation du 01.02 au 29.02'!AC37 -> 0 | O29: =E29*F29+G29*H29+I29*J29+K29*L29 -> 0
A30: Marrakech | B30: =B29+1 -> 29 | C30: 2 | D30: 2020 | E30: ='Consommation du 01.02 au 29.02'!M38 -> 0 | F30: 1.002 | G30: ='Consommation du 01.02 au 29.02'!U38 -> 0 | H30: 9.3657 | I30: ='Consommation du 01.02 au 29.02'!Y38*1000 -> 0 | J30: 0.53 | K30: ='Consommation du 01.02 au 29.02'!D38 -> 0 | L30: 12.67 | M30: ='Consommation du 01.02 au 29.02'!AC38 -> 0

Sheet Consommation du 01.02 au 29.02
B8: Date | D8: Cons Eau/Hotel | F8: Consommation du jour en DH | J8: ELECTRICITE en KWH | M8: total | O8: Consommation du jour en DH | Q8: Cons Elec/Villa | S8: Cons Elec/RIAD | U8: GAZ en Kg | W8: Consommation du jour en DH | AB8: Temp moyenne du jour °C | AC8: Room Nights | AD8: % Occupation | AE8: Temp Piscine Adulte à 7h00 °C | AF8: Temp Piscine Adulte à 15h00 °C | AG8: Temp Piscine famille à 07h00 ° C | AH8: Temp Piscine famille à 15h00 ° C
J9: creuse 81 | K9: pleine 82 | L9: pointe 83 | X9: Compteur AVEO Mwh | Y9: consommation eau choud en Mwh | Z9: consommation du jour en DH
B10: 43862 | D10: ='Suivi EAU-ELEC'!C16 -> 470 | F10: =D10*12.67 -> 5954.9 | J10: ='Suivi EAU-ELEC'!E16 -> 4015 | K10: ='Suivi EAU-ELEC'!G16 -> 6238 | L10: ='Suivi EAU-ELEC'!I16 -> 2808 | M10: =L10+K10+J10 -> 13061 | O10: =M10*1.002 -> 13087.122 | U10: ='Suvi Gaz'!O11 -> 1780.8 | W10: =U10*9.3657 -> 16678.439 | X10: 16394.17 | Y10: =IF(X11<X10,0,X11-X10) -> 1.43 | Z10: =Y10*0.53*1000 -> 757.9 | AB10: 21 | AC10: 128 | AD10: 0.9343 | AE10: 29.4 | AF10: 30 | AG10: 27.8 | AH10: 28
B11: =B10+1 -> 43863 | D11: ='Suivi EAU-ELEC'!C17 -> 540 | F11: =D11*12.67 -> 6841.8 | J11: ='Suivi EAU-ELEC'!E17 -> 4712 | K11: ='Suivi EAU-ELEC'!G17 -> 6202 | L11: ='Suivi EAU-ELEC'!I17 -> 3477 | M11: =L11+K11+J11 -> 14391 | O11: =M11*1.002 -> 14419.782 | U11: ='Suvi Gaz'!O12 -> 1446.9 | W11: =U11*9.3657 -> 13551.231 | X11: 16395.6 | Y11: =IF(X12<X11,0,X12-X11) -> 11.11 | Z11: =Y11*0.53*1000 -> 5888.3 | AB11: 23 | AC11: 126 | AD11: 0.9545 | AE11: 29.2 | AF11: 30 | AG11: 28 | AH11: 29
B12: =B11+1 -> 43864 | D12: ='Suivi EAU-ELEC'!C18 -> 470 | F12: =D12*12.67 -> 5954.9 | J12: ='Suivi EAU-ELEC'!E18 -> 4776 | K12: ='Suivi EAU-ELEC'!G18 -> 7173 | L12: ='Suivi EAU-ELEC'!I18 -> 3744 | M12: =L12+K12+J12 -> 15693 | O12: =M12*1.002 -> 15724.386 | U12: ='Suvi Gaz'!O13 -> 1558.2 | W12: =U12*9.3657 -> 14593.634 | X12: 16406.71 | Y12: =IF(X13<X12,0,X13-X12) -> 14.88 | Z12: =Y12*0.53*1000 -> 7886.4 | AB12: 24 | AC12: 129 | AD12: 0.9699 | AE12: 28.6 | AF12: 30 | AG12: 27.5 | AH12: 29
B13: =B12+1 -> 43865 | D13: ='Suivi EAU-ELEC'!C19 -> 500 | F13: =D13*12.67 -> 6335 | J13: ='Suivi EAU-ELEC'!E19 -> 5000 | K13: ='Suivi EAU-ELEC'!G19 -> 7730 | L13: ='Suivi EAU-ELEC'!I19 -> 3480 | M13: =L13+K13+J13 -> 16210 | O13: =M13*1.002 -> 16242.42 | U13: ='Suvi Gaz'!O14 -> 556.5 | W13: =U13*9.3657 -> 5212.0121 | X13: 16421.59 | Y13: =IF(X14<X13,0,X14-X13) -> 17.57 | Z13: =Y13*0.53*1000 -> 9312.1 | AB13: 24 | AC13: 111 | AD13: 0.8409 | AE13: 28.8 | AF13: 30 | AG13: 27 | AH13: 28
B14: =B13+1 -> 43866 | D14: ='Suivi EAU-ELEC'!C20 -> 520 | F14: =D14*12.67 -> 6588.4 | J14: ='Suivi EAU-ELEC'!E20 -> 5560 | K14: ='Suivi EAU-ELEC'!G20 -> 7043 | L14: ='Suivi EAU-ELEC'!I20 -> 3700 | M14: =L14+K14+J14 -> 16303 | O14: =M14*1.002 -> 16335.606 | U14: ='Suvi Gaz'!O15 -> 408.1 | W14: =U14*9.3657 -> 3822.1422 | X14: 16439.16 | Y14: =IF(X15<X14,0,X15-X14) -> 17.35 | Z14: =Y14*0.53*1000 -> 9195.5 | AB14: 25 | AC14: 111 | AD14: 0.8284 | AE14: 28.6 | AF14: 30 | AG14: 27.6 | AH14: 28.6
B15: =B14+1 -> 43867 | D15: ='Suivi EAU-ELEC'!C21 -> 510 | F15: =D15*12.67 -> 6461.7 | J15: ='Suivi EAU-ELEC'!E21 -> 6172 | K15: ='Suivi EAU-ELEC'!G21 -> 8342 | L15: ='Suivi EAU-ELEC'!I21 -> 3792 | M15: =L15+K15+J15 -> 18306 | O15: =M15*1.002 -> 18342.612 | U15: ='Suvi Gaz'!O16 -> 519.4 | W15: =U15*9.3657 -> 4864.5446 | X15: 16456.51 | Y15: =IF(X16<X15,0,X16-X15) -> 17.5 | Z15: =Y15*0.53*1000 -> 9275 | AB15: 25 | AC15: 103 | AD15: 0.7863 | AE15: 28.6 | AF15: 29.6 | AG15: 27.4 | AH15: 28
B16: =B15+1 -> 43868 | D16: ='Suivi EAU-ELEC'!C22 -> 500 | F16: =D16*12.67 -> 6335 | J16: ='Suivi EAU-ELEC'!E22 -> 4971 | K16: ='Suivi EAU-ELEC'!G22 -> 6753 | L16: ='Suivi EAU-ELEC'!I22 -> 3645 | M16: =L16+K16+J16 -> 15369 | O16: =M16*1.002 -> 15399.738 | U16: ='Suvi Gaz'!O17 -> 779.1 | W16: =U16*9.3657 -> 7296.8169 | X16: 16474.01 | Y16: =IF(X17<X16,0,X17-X16) -> 14.69 | Z16: =Y16*0.53*1000 -> 7785.7 | AB16: 19 | AC16: 114 | AD16: 0.8906 | AE16: 29 | AF16: 29 | AG16: 27.6 | AH16: 28
B17: =B16+1 -> 43869 | D17: ='Suivi EAU-ELEC'!C23 -> 560 | F17: =D17*12.67 -> 7095.2 | J17: ='Suivi EAU-ELEC'!E23 -> 5056 | K17: ='Suivi EAU-ELEC'!G23 -> 7112 | L17: ='Suivi EAU-ELEC'!I23 -> 3709 | M17: =L17+K17+J17 -> 15877 | O17: =M17*1.002 -> 15908.754 | U17: ='Suvi Gaz'!O18 -> 704.9 | W17: =U17*9.3657 -> 6601.8819 | X17: 16488.7 | Y17: =IF(X18<X17,0,X18-X17) -> 16.4 | Z17: =Y17*0.53*1000 -> 8692 | AB17: 18 | AC17: 101 | AD17: 0.8016 | AE17: 28 | AF17: 28.5 | AG17: 27.5 | AH17: 28
B18: =B17+1 -> 43870 | D18: ='Suivi EAU-ELEC'!C24 -> 470 | F18: =D18*12.67 -> 5954.9 | J18: ='Suivi EAU-ELEC'!E24 -> 3627 | K18: ='Suivi EAU-ELEC'!G24 -> 6695 | L18: ='Suivi EAU-ELEC'!I24 -> 3616 | M18: =L18+K18+J18 -> 13938 | O18: =M18*1.002 -> 13965.876 | U18: ='Suvi Gaz'!O19 -> 519.4 | W18: =U18*9.3657 -> 4864.5446 | X18: 16505.1 | Y18: =IF(X19<X18,0,X19-X18) -> 17.25 | Z18: =Y18*0.53*1000 -> 9142.5 | AB18: 19 | AC18: 91 | AD18: 0.728 | AE18: 28 | AF18: 28.5 | AG18: 27 | AH18: 27.5
B19: =B18+1 -> 43871 | D19: ='Suivi EAU-ELEC'!C25 -> 480 | F19: =D19*12.67 -> 6081.6 | J19: ='Suivi EAU-ELEC'!E25 -> 5442 | K19: ='Suivi EAU-ELEC'!G25 -> 7290 | L19: ='Suivi EAU-ELEC'!I25 -> 3521 | M19: =L19+K19+J19 -> 16253 | O19: =M19*1.002 -> 16285.506 | U19: ='Suvi Gaz'!O20 -> 519.4 | W19: =U19*9.3657 -> 4864.5446 | X19: 16522.35 | Y19: =IF(X20<X19,0,X20-X19) -> 16.71 | Z19: =Y19*0.53*1000 -> 8856.3 | AB19: 21 | AC19: 87 | AD19: 0.685 | AE19: 28 | AF19: 29 | AG19: 27.6 | AH19: 27.5
B20: =B19+1 -> 43872 | D20: ='Suivi EAU-ELEC'!C26 -> 690 | F20: =D20*12.67 -> 8742.3 | J20: ='Suivi EAU-ELEC'!E26 -> 4611 | K20: ='Suivi EAU-ELEC'!G26 -> 7836 | L20: ='Suivi EAU-ELEC'!I26 -> 3995 | M20: =L20+K20+J20 -> 16442 | O20: =M20*1.002 -> 16474.884 | U20: ='Suvi Gaz'!O21 -> 853.3 | W20: =U20*9.3657 -> 7991.7518 | X20: 16539.06 | Y20: =IF(X21<X20,0,X21-X20) -> 14.32 | Z20: =Y20*0.53*1000 -> 7589.6 | AA20: 14 | AB20: 23 | AC20: 76 | AD20: 0.5846 | AE20: 27.5 | AF20: 28.5 | AG20: 27 | AH20: 28
B21: =B20+1 -> 43873 | D21: ='Suivi EAU-ELEC'!C27 -> 610 | F21: =D21*12.67 -> 7728.7 | J21: ='Suivi EAU-ELEC'!E27 -> 4837 | K21: ='Suivi EAU-ELEC'!G27 -> 8000 | L21: ='Suivi EAU-ELEC'!I27 -> 3592 | M21: =L21+K21+J21 -> 16429 | O21: =M21*1.002 -> 16461.858 | U21: ='Suvi Gaz'!O22 -> 1372.7 | W21: =U21*9.3657 -> 12856.296 | X21: 16553.38 | Y21: =IF(X22<X21,0,X22-X21) -> 13.61 | Z21: =Y21*0.53*1000 -> 7213.3 | AA21: 14 | AB21: 23 | AC21: 83 | AD21: 0.6385 | AE21: 28.5 | AF21: 29 | AG21: 28 | AH21: 28
B22: =B21+1 -> 43874 | D22: ='Suivi EAU-ELEC'!C28 -> 0 | F22: =D22*12.67 -> 0 | J22: ='Suivi EAU-ELEC'!E28 -> 0 | K22: ='Suivi EAU-ELEC'!G28 -> 0 | L22: ='Suivi EAU-ELEC'!I28 -> 0 | M22: =L22+K22+J22 -> 0 | O22: =M22*1.002 -> 0 | U22: ='Suvi Gaz'!O23 -> 0 | W22: =U22*9.3657 -> 0 | X22: 16566.99 | Y22: =IF(X23<X22,0,X23-X22) -> 0 | Z22: =Y22*0.53*1000 -> 0
B23: =B22+1 -> 43875 | D23: ='Suivi EAU-ELEC'!C29 -> 0 | F23: =D23*12.67 -> 0 | J23: ='Suivi EAU-ELEC'!E29 -> 0 | K23: ='Suivi EAU-ELEC'!G29 -> 0 | L23: ='Suivi EAU-ELEC'!I29 -> 0 | M23: =L23+K23+J23 -> 0 | O23: =M23*1.002 -> 0 | U23: ='Suvi Gaz'!O24 -> 0 | W23: =U23*9.3657 -> 0 | Y23: =IF(X24<X23,0,X24-X23) -> 0 | Z23: =Y23*0.53*1000 -> 0
B24: =B23+1 -> 43876 | D24: ='Suivi EAU-ELEC'!C30 -> 0 | F24: =D24*12.67 -> 0 | J24: ='Suivi EAU-ELEC'!E30 -> 0 | K24: ='Suivi EAU-ELEC'!G30 -> 0 | L24: ='Suivi EAU-ELEC'!I30 -> 0 | M24: =L24+K24+J24 -> 0 | O24: =M24*1.002 -> 0 | U24: ='Suvi Gaz'!O25 -> 0 | W24: =U24*9.3657 -> 0 | Y24: =IF(X25<X24,0,X25-X24) -> 0 | Z24: =Y24*0.53*1000 -> 0
B25: =B24+1 -> 43877 | D25: ='Suivi EAU-ELEC'!C31 -> 0 | F25: =D25*12.67 -> 0 | J25: ='Suivi EAU-ELEC'!E31 -> 0 | K25: ='Suivi EAU-ELEC'!G31 -> 0 | L25: ='Suivi EAU-ELEC'!I31 -> 0 | M25: =L25+K25+J25 -> 0 | O25: =M25*1.002 -> 0 | U25: ='Suvi Gaz'!O26 -> 0 | W25: =U25*9.3657 -> 0 | Y25: =IF(X26<X25,0,X26-X25) -> 0 | Z25: =Y25*0.53*1000 -> 0
B26: =B25+1 -> 43878 | D26: ='Suivi EAU-ELEC'!C32 -> 0 | F26: =D26*12.67 -> 0 | J26: ='Suivi EAU-ELEC'!E32 -> 0 | K26: ='Suivi EAU-ELEC'!G32 -> 0 | L26: ='Suivi EAU-ELEC'!I32 -> 0 | M26: =L26+K26+J26 -> 0 | O26: =M26*1.002 -> 0 | U26: ='Suvi Gaz'!O27 -> 0 | W26: =U26*9.3657 -> 0 | Y26: =IF(X27<X26,0,X27-X26) -> 0 | Z26: =Y26*0.53*1000 -> 0
B27: =B26+1 -> 43879 | D27: ='Suivi EAU-ELEC'!C33 -> 0 | F27: =D27*12.67 -> 0 | J27: ='Suivi EAU-ELEC'!E33 -> 0 | K27: ='Suivi EAU-ELEC'!G33 -> 0 | L27: ='Suivi EAU-ELEC'!I33 -> 0 | M27: =L27+K27+J27 -> 0 | O27: =M27*1.002 -> 0 | U27: ='Suvi Gaz'!O28 -> 0 | W27: =U27*9.3657 -> 0 | Y27: =IF(X28<X27,0,X28-X27) -> 0 | Z27: =Y27*0.53*1000 -> 0
B28: =B27+1 -> 43880 | D28: ='Suivi EAU-ELEC'!C34 -> 0 | F28: =D28*12.67 -> 0 | J28: ='Suivi EAU-ELEC'!E34 -> 0 | K28: ='Suivi EAU-ELEC'!G34 -> 0 | L28: ='Suivi EAU-ELEC'!I34 -> 0 | M28: =L28+K28+J28 -> 0 | O28: =M28*1.002 -> 0 | U28: ='Suvi Gaz'!O29 -> 0 | W28: =U28*9.3657 -> 0 | Y28: =IF(X29<X28,0,X29-X28) -> 0 | Z28: =Y28*0.53*1000 -> 0
B29: =B28+1 -> 43881 | D29: ='Suivi EAU-ELEC'!C35 -> 0 | F29: =D29*12.67 -> 0 | J29: ='Suivi EAU-ELEC'!E35 -> 0 | K29: ='Suivi EAU-ELEC'!G35 -> 0 | L29: ='Suivi EAU-ELEC'!I35 -> 0 | M29: =L29+K29+J29 -> 0 | O29: =M29*1.002 -> 0 | U29: ='Suvi Gaz'!O30 -> 0 | W29: =U29*9.3657 -> 0 | Y29: =IF(X30<X29,0,X30-X29) -> 0 | Z29: =Y29*0.53*1000 -> 0
B30: =B29+1 -> 43882 | D30: ='Suivi EAU-ELEC'!C36 -> 0 | F30: =D30*12.67 -> 0 | J30: ='Suivi EAU-ELEC'!E36 -> 0 | K30: ='Suivi EAU-ELEC'!G36 -> 0 | L30: ='Suivi EAU-ELEC'!I36 -> 0 | M30: =L30+K30+J30 -> 0 | O30: =M30*1.002 -> 0 | U30: ='Suvi Gaz'!O31 -> 0 | W30: =U30*9.3657 -> 0 | Y30: =IF(X31<X30,0,X31-X30) -> 0 | Z30: =Y30*0.53*1000 -> 0
B31: =B30+1 -> 43883 | D31: ='Suivi EAU-ELEC'!C37 -> 0 | F31: =D31*12.67 -> 0 | J31: ='Suivi EAU-ELEC'!E37 -> 0 | K31: ='Suivi EAU-ELEC'!G37 -> 0 | L31: ='Suivi EAU-ELEC'!I37 -> 0 | M31: =L31+K31+J31 -> 0 | O31: =M31*1.002 -> 0 | U31: ='Suvi Gaz'!O32 -> 0 | W31: =U31*9.3657 -> 0 | Y31: =IF(X32<X31,0,X32-X31) -> 0 | Z31: =Y31*0.53*1000 -> 0
B32: =B31+1 -> 43884 | D32: ='Suivi EAU-ELEC'!C38 -> 0 | F32: =D32*12.67 -> 0 | J32: ='Suivi EAU-ELEC'!E38 -> 0 | K32: ='Suivi EAU-ELEC'!G38 -> 0 | L32: ='Suivi EAU-ELEC'!I38 -> 0 | M32: =L32+K32+J32 -> 0 | O32: =M32*1.002 -> 0 | U32: ='Suvi Gaz'!O33 -> 0 | W32: =U32*9.3657 -> 0 | Y32: =IF(X33<X32,0,X33-X32) -> 0 | Z32: =Y32*0.53*1000 -> 0
B33: =B32+1 -> 43885 | D33: ='Suivi EAU-ELEC'!C39 -> 0 | F33: =D33*12.67 -> 0 | J33: ='Suivi EAU-ELEC'!E39 -> 0 | K33: ='Suivi EAU-ELEC'!G39 -> 0 | L33: ='Suivi EAU-ELEC'!I39 -> 0 | M33: =L33+K33+J33 -> 0 | O33: =M33*1.002 -> 0 | U33: ='Suvi Gaz'!O34 -> 0 | W33: =U33*9.3657 -> 0 | Y33: =IF(X34<X33,0,X34-X33) -> 0 | Z33: =Y33*0.53*1000 -> 0
B34: =B33+1 -> 43886 | D34: ='Suivi EAU-ELEC'!C40 -> 0 | F34: =D34*12.67 -> 0 | J34: ='Suivi EAU-ELEC'!E40 -> 0 | K34: ='Suivi EAU-ELEC'!G40 -> 0 | L34: ='Suivi EAU-ELEC'!I40 -> 0 | M34: =L34+K34+J34 -> 0 | O34: =M34*1.002 -> 0 | U34: ='Suvi Gaz'!O35 -> 0 | W34: =U34*9.3657 -> 0 | Y34: =IF(X35<X34,0,X35-X34) -> 0 | Z34: =Y34*0.53*1000 -> 0
... B40: =B39+1 -> 43892 | D40: ='Suivi EAU-ELEC'!C46 -> 0 | F40: =D40*12.67 -> 0 | J40: ='Suivi EAU-ELEC'!E46 -> 0 | K40: ='Suivi EAU-ELEC'!G46 -> 0 | L40: ='Suivi EAU-ELEC'!I46 -> 0 | M40: =L40+K40+J40 -> 0 | O40: =M40*1.002 -> 0 | U40: ='Suvi Gaz'!O41 -> 0 | W40: =U40*9.3657 -> 0 | Y40: =IF(X41<X40,0,X41-X40) -> 0 | Z40: =Y40*0.53*1000 -> 0
D41: =SUM(D10:D38) -> 6320 | F41: 470 | J41: =SUM(J10:J38) -> 58779 | K41: =SUM(K10:K38) -> 86414 | L41: =SUM(L10:L38) -> 43079 | M41: =SUM(M10:M38) -> 188272 | O41: =SUM(O10:O38) -> 188648.54 | S41: =SUM(S10:S40) -> 0 | U41: =SUM(U10:U38) -> 11018.7 | W41: =SUM(W10:W38) -> 103197.84 | Y41: =SUM(Y10:Y38) -> 172.82 | Z41: =SUM(Z10:Z38) -> 91594.6
A43: ELECTRICITE / Kw/h | D43: creuse 81 | F43: 1.002 | G43: =J41 -> 58779 | J43: =G43*F43 -> 58896.558 | L43: =J43+J44+J45 -> 188648.54
D44: pleine 82 | F44: 1.002 | G44: =K41 -> 86414 | J44: =G44*F44 -> 86586.828
D45: pointe 83 | F45: 1.002 | G45: =L41 -> 43079 | J45: =G45*F45 -> 43165.158
A46: EAU HOTEL M3 | F46: 12.67 | G46: =D41 -> 6320 | J46: =G46*F46 -> 80074.4 | L46: =J46 -> 80074.4
A47: GAZ Kg | F47: 9.3657 | G47: =U41 -> 11018.7 | J47: =G47*F47 -> 103197.84 | L47: =J47 -> 103197.84

Sheet Suvi Gaz
D1: suivi Gaz
Q2: 803 | T2: 519 | W2: 800 | Z2: 802
B3: Relvé C1 | C3: cons C1 | D3: Relvé C2 | E3: cons C2 | F3: Relvé C3 | G3: cons C3 | H3: Relvé C4 | I3: cons C4 | J3: ∑ des relevés | K3: moyen general % | L3: con.j | M3: ∑ de volume en L | N3: cons./jen L | O3: cons./jen Kg | P3: cons./jen DH | Q3: livraison C1 | R3: %Avant | S3: % Après | T3: livraison C2 | U3: %Avant | V3: % Après | W3: livraison C3 | X3: %Avant | Y3: % Après | Z3: livraison C4 | AA3: %Avant | AB3: % Après | AC3: total livraison | AD3: moyen general % Avant L | AE3: moyen general % Aaprés L
A4: 43855 | B4: 73 | C4: =IF(AC4>0,((B4-R4)+(S4-B5)),IF(B5=0, ,(B4-B5))) -> 11 | D4: 74 | E4: =IF(AC4>0,((D4-U4)+(V4-D5)),IF(D5=0, ,(D4-D5))) -> 10 | F4: 68 | G4: =IF(AC4>0,((F4-X4)+(Y4-F5)),IF(F5=0, ,(F4-F5))) -> 6 | H4: 64 | I4: =IF(AC4>0,((H4-AA4)+(AB4-H5)),IF(H5=0, ,(H4-H5))) -> 4 | J4: =B4+D4+F4+H4 -> 279 | K4: =J4/4 -> 69.75 | L4: =IF(AC4>0,((K4-AD4)+(AE4-K5)),IF(K5=0, ,(K4-K5))) -> 7.75 | M4: =7000*4 -> 28000 | N4: =L4*M4/100 -> 2170 | O4: =N4*0.53 -> 1150.1 | P4: =O4*8.8038 -> 10125.25 | AC4: =Q4+T4+W4+Z4 -> 0 | AD4: =(R4+U4+X4+AA4)/4 -> 0 | AE4: =(S4+V4+Y4+AB4)/4 -> 0
A5: =(A4+1) -> 43856 | B5: 62 | C5: =IF(AC5>0,((B5-R5)+(S5-B6)),IF(B6=0, ,(B5-B6))) -> 8 | D5: 64 | E5: =IF(AC5>0,((D5-U5)+(V5-D6)),IF(D6=0, ,(D5-D6))) -> 6 | F5: 62 | G5: =IF(AC5>0,((F5-X5)+(Y5-F6)),IF(F6=0, ,(F5-F6))) -> 11 | H5: 60 | I5: =IF(AC5>0,((H5-AA5)+(AB5-H6)),IF(H6=0, ,(H5-H6))) -> 8 | J5: =B5+D5+F5+H5 -> 248 | K5: =J5/4 -> 62 | L5: =IF(AC5>0,((K5-AD5)+(AE5-K6)),IF(K6=0, ,(K5-K6))) -> 8.25 | M5: =7000*4 -> 28000 | N5: =L5*M5/100 -> 2310 | O5: =N5*0.53 -> 1224.3 | P5: =O5*8.8038 -> 10778.492 | AC5: =Q5+T5+W5+Z5 -> 0 | AD5: =(R5+U5+X5+AA5)/4 -> 0 | AE5: =(S5+V5+Y5+AB5)/4 -> 0
A6: =(A5+1) -> 43857 | B6: 54 | C6: =IF(AC6>0,((B6-R6)+(S6-B7)),IF(B7=0, ,(B6-B7))) -> 5 | D6: 58 | E6: =IF(AC6>0,((D6-U6)+(V6-D7)),IF(D7=0, ,(D6-D7))) -> 8 | F6: 51 | G6: =IF(AC6>0,((F6-X6)+(Y6-F7)),IF(F7=0, ,(F6-F7))) -> 4 | H6: 52 | I6: =IF(AC6>0,((H6-AA6)+(AB6-H7)),IF(H7=0, ,(H6-H7))) -> 5 | J6: =B6+D6+F6+H6 -> 215 | K6: =J6/4 -> 53.75 | L6: =IF(AC6>0,((K6-AD6)+(AE6-K7)),IF(K7=0, ,(K6-K7))) -> 5.5 | M6: =7000*4 -> 28000 | N6: =L6*M6/100 -> 1540 | O6: =N6*0.53 -> 816.2 | P6: =O6*8.8038 -> 7185.6616 | Q6: 2999 | R6: 50 | S6: 86 | T6: 3005 | U6: 52 | V6: 87 | W6: 2999 | X6: 50 | Y6: 86 | Z6: 3001 | AA6: 50 | AB6: 86 | AC6: =Q6+T6+W6+Z6 -> 12004 | AD6: =(R6+U6+X6+AA6)/4 -> 50.5 | AE6: =(S6+V6+Y6+AB6)/4 -> 86.25
A7: =(A6+1) -> 43858 | B7: 85 | C7: =IF(AC7>0,((B7-R7)+(S7-B8)),IF(B8=0, ,(B7-B8))) -> 12 | D7: 85 | E7: =IF(AC7>0,((D7-U7)+(V7-D8)),IF(D8=0, ,(D7-D8))) -> 10 | F7: 83 | G7: =IF(AC7>0,((F7-X7)+(Y7-F8)),IF(F8=0, ,(F7-F8))) -> 13 | H7: 83 | I7: =IF(AC7>0,((H7-AA7)+(AB7-H8)),IF(H8=0, ,(H7-H8))) -> 13 | J7: =B7+D7+F7+H7 -> 336 | K7: =J7/4 -> 84 | L7: =IF(AC7>0,((K7-AD7)+(AE7-K8)),IF(K8=0, ,(K7-K8))) -> 12 | M7: =7000*4 -> 28000 | N7: =L7*M7/100 -> 3360 | O7: =N7*0.53 -> 1780.8 | P7: =O7*8.8038 -> 15677.807 | AC7: =Q7+T7+W7+Z7 -> 0 | AD7: =(R7+U7+X7+AA7)/4 -> 0 | AE7: =(S7+V7+Y7+AB7)/4 -> 0
A8: =(A7+1) -> 43859 | B8: 73 | C8: =IF(AC8>0,((B8-R8)+(S8-B9)),IF(B9=0, ,(B8-B9))) -> 8 | D8: 75 | E8: =IF(AC8>0,((D8-U8)+(V8-D9)),IF(D9=0, ,(D8-D9))) -> 7 | F8: 70 | G8: =IF(AC8>0,((F8-X8)+(Y8-F9)),IF(F9=0, ,(F8-F9))) -> 8 | H8: 70 | I8: =IF(AC8>0,((H8-AA8)+(AB8-H9)),IF(H9=0, ,(H8-H9))) -> 7 | J8: =B8+D8+F8+H8 -> 288 | K8: =J8/4 -> 72 | L8: =IF(AC8>0,((K8-AD8)+(AE8-K9)),IF(K9=0, ,(K8-K9))) -> 7.5 | M8: =7000*4 -> 28000 | N8: =L8*M8/100 -> 2100 | O8: =N8*0.53 -> 1113 | P8: =O8*8.8038 -> 9798.6294 | AC8: =Q8+T8+W8+Z8 -> 0 | AD8: =(R8+U8+X8+AA8)/4 -> 0 | AE8: =(S8+V8+Y8+AB8)/4 -> 0
A9: =(A8+1) -> 43860 | B9: 65 | C9: =IF(AC9>0,((B9-R9)+(S9-B10)),IF(B10=0, ,(B9-B10))) -> 7 | D9: 68 | E9: =IF(AC9>0,((D9-U9)+(V9-D10)),IF(D10=0, ,(D9-D10))) -> 8 | F9: 62 | G9: =IF(AC9>0,((F9-X9)+(Y9-F10)),IF(F10=0, ,(F9-F10))) -> 7 | H9: 63 | I9: =IF(AC9>0,((H9-AA9)+(AB9-H10)),IF(H10=0, ,(H9-H10))) -> 8 | J9: =B9+D9+F9+H9 -> 258 | K9: =J9/4 -> 64.5 | L9: =IF(AC9>0,((K9-AD9)+(AE9-K10)),IF(K10=0, ,(K9-K10))) -> 7.5 | M9: =7000*4 -> 28000 | N9: =L9*M9/100 -> 2100 | O9: =N9*0.53 -> 1113 | P9: =O9*8.8038 -> 9798.6294 | AC9: =Q9+T9+W9+Z9 -> 0 | AD9: =(R9+U9+X9+AA9)/4 -> 0 | AE9: =(S9+V9+Y9+AB9)/4 -> 0
A10: =(A9+1) -> 43861 | B10: 58 | C10: =IF(AC10>0,((B10-R10)+(S10-B11)),IF(B11=0, ,(B10-B11))) -> 14 | D10: 60 | E10: =IF(AC10>0,((D10-U10)+(V10-D11)),IF(D11=0, ,(D10-D11))) -> 9 | F10: 55 | G10: =IF(AC10>0,((F10-X10)+(Y10-F11)),IF(F11=0, ,(F10-F11))) -> 14 | H10: 55 | I10: =IF(AC10>0,((H10-AA10)+(AB10-H11)),IF(H11=0, ,(H10-H11))) -> 15 | J10: =B10+D10+F10+H10 -> 228 | K10: =J10/4 -> 57 | L10: =IF(AC10>0,((K10-AD10)+(AE10-K11)),IF(K11=0, ,(K10-K11))) -> 13 | M10: =7000*4 -> 28000 | N10: =L10*M10/100 -> 3640 | O10: =N10*0.53 -> 1929.2 | P10: =O10*8.8038 -> 16984.291 | Q10: 2200 | R10: 50 | S10: 80 | T10: 2200 | U10: 55 | V10: 82 | W10: 2301 | X10: 48 | Y10: 78 | Z10: 2360 | AA10: 48 | AB10: 78 | AC10: =Q10+T10+W10+Z10 -> 9061 | AD10: =(R10+U10+X10+AA10)/4 -> 50.25 | AE10: =(S10+V10+Y10+AB10)/4 -> 79.5
A11: =(A10+1) -> 43862 | B11: 74 | C11: =IF(AC11>0,((B11-R11)+(S11-B12)),IF(B12=0, ,(B11-B12))) -> 14 | D11: 78 | E11: =IF(AC11>0,((D11-U11)+(V11-D12)),IF(D12=0, ,(D11-D12))) -> 13 | F11: 71 | G11: =IF(AC11>0,((F11-X11)+(Y11-F12)),IF(F12=0, ,(F11-F12))) -> 11 | H11: 70 | I11: =IF(AC11>0,((H11-AA11)+(AB11-H12)),IF(H12=0, ,(H11-H12))) -> 10 | J11: =B11+D11+F11+H11 -> 293 | K11: =J11/4 -> 73.25 | L11: =IF(AC11>0,((K11-AD11)+(AE11-K12)),IF(K12=0, ,(K11-K12))) -> 12 | M11: =7000*4 -> 28000 | N11: =L11*M11/100 -> 3360 | O11: =N11*0.53 -> 1780.8 | P11: =O11*9.3657 -> 16678.439 | AC11: =Q11+T11+W11+Z11 -> 0 | AD11: =(R11+U11+X11+AA11)/4 -> 0 | AE11: =(S11+V11+Y11+AB11)/4 -> 0
A12: =(A11+1) -> 43863 | B12: 60 | C12: =IF(AC12>0,((B12-R12)+(S12-B13)),IF(B13=0, ,(B12-B13))) -> 10 | D12: 65 | E12: =IF(AC12>0,((D12-U12)+(V12-D13)),IF(D13=0, ,(D12-D13))) -> 9 | F12: 60 | G12: =IF(AC12>0,((F12-X12)+(Y12-F13)),IF(F13=0, ,(F12-F13))) -> 10 | H12: 60 | I12: =IF(AC12>0,((H12-AA12)+(AB12-H13)),IF(H13=0, ,(H12-H13))) -> 10 | J12: =B12+D12+F12+H12 -> 245 | K12: =J12/4 -> 61.25 | L12: =IF(AC12>0,((K12-AD12)+(AE12-K13)),IF(K13=0, ,(K12-K13))) -> 9.75 | M12: =7000*4 -> 28000 | N12: =L12*M12/100 -> 2730 | O12: =N12*0.53 -> 1446.9 | P12: =O12*9.3657 -> 13551.231 | AC12: =Q12+T12+W12+Z12 -> 0 | AD12: =(R12+U12+X12+AA12)/4 -> 0 | AE12: =(S12+V12+Y12+AB12)/4 -> 0
A13: =(A12+1) -> 43864 | B13: 50 | C13: =IF(AC13>0,((B13-R13)+(S13-B14)),IF(B14=0, ,(B13-B14))) -> 20 | D13: 56 | E13: =IF(AC13>0,((D13-U13)+(V13-D14)),IF(D14=0, ,(D13-D14))) -> -16 | F13: 50 | G13: =IF(AC13>0,((F13-X13)+(Y13-F14)),IF(F14=0, ,(F13-F14))) -> 20 | H13: 50 | I13: =IF(AC13>0,((H13-AA13)+(AB13-H14)),IF(H14=0, ,(H13-H14))) -> 18 | J13: =B13+D13+F13+H13 -> 206 | K13: =J13/4 -> 51.5 | L13: =IF(AC13>0,((K13-AD13)+(AE13-K14)),IF(K14=0, ,(K13-K14))) -> 10.5 | M13: =7000*4 -> 28000 | N13: =L13*M13/100 -> 2940 | O13: =N13*0.53 -> 1558.2 | P13: =O13*9.3657 -> 14593.634 | Q13: 4157 | R13: 43 | S13: 85 | W13: 3528 | X13: 45 | Y13: 85 | Z13: 2079 | AA13: 45 | AB13: 83 | AC13: =Q13+T13+W13+Z13 -> 9764 | AD13: =(R13+U13+X13+AA13)/4 -> 33.25 | AE13: =(S13+V13+Y13+AB13)/4 -> 63.25
A14: =(A13+1) -> 43865 | B14: 72 | C14: =IF(AC14>0,((B14-R14)+(S14-B15)),IF(B15=0, ,(B14-B15))) -> 4 | D14: 72 | E14: =IF(AC14>0,((D14-U14)+(V14-D15)),IF(D15=0, ,(D14-D15))) -> 3 | F14: 70 | G14: =IF(AC14>0,((F14-X14)+(Y14-F15)),IF(F15=0, ,(F14-F15))) -> 4 | H14: 70 | I14: =IF(AC14>0,((H14-AA14)+(AB14-H15)),IF(H15=0, ,(H14-H15))) -> 4 | J14: =B14+D14+F14+H14 -> 284 | K14: =J14/4 -> 71 | L14: =IF(AC14>0,((K14-AD14)+(AE14-K15)),IF(K15=0, ,(K14-K15))) -> 3.75 | M14: =7000*4 -> 28000 | N14: =L14*M14/100 -> 1050 | O14: =N14*0.53 -> 556.5 | P14: =O14*9.3657 -> 5212.0121 | AC14: =Q14+T14+W14+Z14 -> 0 | AD14: =(R14+U14+X14+AA14)/4 -> 0 | AE14: =(S14+V14+Y14+AB14)/4 -> 0
A15: =(A14+1) -> 43866 | B15: 68 | C15: =IF(AC15>0,((B15-R15)+(S15-B16)),IF(B16=0, ,(B15-B16))) -> 2 | D15: 69 | E15: =IF(AC15>0,((D15-U15)+(V15-D16)),IF(D16=0, ,(D15-D16))) -> 2 | F15: 66 | G15: =IF(AC15>0,((F15-X15)+(Y15-F16)),IF(F16=0, ,(F15-F16))) -> 4 | H15: 66 | I15: =IF(AC15>0,((H15-AA15)+(AB15-H16)),IF(H16=0, ,(H15-H16))) -> 3 | J15: =B15+D15+F15+H15 -> 269 | K15: =J15/4 -> 67.25 | L15: =IF(AC15>0,((K15-AD15)+(AE15-K16)),IF(K16=0, ,(K15-K16))) -> 2.75 | M15: =7000*4 -> 28000 | N15: =L15*M15/100 -> 770 | O15: =N15*0.53 -> 408.1 | P15: =O15*9.3657 -> 3822.1422 | Q15: 1500 | R15: 67 | S15: 85 | T15: 1500 | U15: 68 | V15: 85 | W15: 1630 | X15: 65 | Y15: 85 | Z15: 1600 | AA15: 66 | AB15: 85 | AC15: =Q15+T15+W15+Z15 -> 6230 | AD15: =(R15+U15+X15+AA15)/4 -> 66.5 | AE15: =(S15+V15+Y15+AB15)/4 -> 85
A16: =(A15+1) -> 43867 | B16: 84 | C16: =IF(AC16>0,((B16-R16)+(S16-B17)),IF(B17=0, ,(B16-B17))) -> 4 | D16: 84 | E16: =IF(AC16>0,((D16-U16)+(V16-D17)),IF(D17=0, ,(D16-D17))) -> 2 | F16: 82 | G16: =IF(AC16>0,((F16-X16)+(Y16-F17)),IF(F17=0, ,(F16-F17))) -> 4 | H16: 82 | I16: =IF(AC16>0,((H16-AA16)+(AB16-H17)),IF(H17=0, ,(H16-H17))) -> 4 | J16: =B16+D16+F16+H16 -> 332 | K16: =J16/4 -> 83 | L16: =IF(AC16>0,((K16-AD16)+(AE16-K17)),IF(K17=0, ,(K16-K17))) -> 3.5 | M16: =7000*4 -> 28000 | N16: =L16*M16/100 -> 980 | O16: =N16*0.53 -> 519.4 | P16: =O16*9.3657 -> 4864.5446 | AC16: =Q16+T16+W16+Z16 -> 0 | AD16: =(R16+U16+X16+AA16)/4 -> 0 | AE16: =(S16+V16+Y16+AB16)/4 -> 0
A17: =(A16+1) -> 43868 | B17: 80 | C17: =IF(AC17>0,((B17-R17)+(S17-B18)),IF(B18=0, ,(B17-B18))) -> 5 | D17: 82 | E17: =IF(AC17>0,((D17-U17)+(V17-D18)),IF(D18=0, ,(D17-D18))) -> 6 | F17: 78 | G17: =IF(AC17>0,((F17-X17)+(Y17-F18)),IF(F18=0, ,(F17-F18))) -> 6 | H17: 78 | I17: =IF(AC17>0,((H17-AA17)+(AB17-H18)),IF(H18=0, ,(H17-H18))) -> 4 | J17: =B17+D17+F17+H17 -> 318 | K17: =J17/4 -> 79.5 | L17: =IF(AC17>0,((K17-AD17)+(AE17-K18)),IF(K18=0, ,(K17-K18))) -> 5.25 | M17: =7000*4 -> 28000 | N17: =L17*M17/100 -> 1470 | O17: =N17*0.53 -> 779.1 | P17: =O17*9.3657 -> 7296.8169 | AC17: =Q17+T17+W17+Z17 -> 0 | AD17: =(R17+U17+X17+AA17)/4 -> 0 | AE17: =(S17+V17+Y17+AB17)/4 -> 0
A18: =(A17+1) -> 43869 | B18: 75 | C18: =IF(AC18>0,((B18-R18)+(S18-B19)),IF(B19=0, ,(B18-B19))) -> 5 | D18: 76 | E18: =IF(AC18>0,((D18-U18)+(V18-D19)),IF(D19=0, ,(D18-D19))) -> 4 | F18: 72 | G18: =IF(AC18>0,((F18-X18)+(Y18-F19)),IF(F19=0, ,(F18-F19))) -> 4 | H18: 74 | I18: =IF(AC18>0,((H18-AA18)+(AB18-H19)),IF(H19=0, ,(H18-H19))) -> 6 | J18: =B18+D18+F18+H18 -> 297 | K18: =J18/4 -> 74.25 | L18: =IF(AC18>0,((K18-AD18)+(AE18-K19)),IF(K19=0, ,(K18-K19))) -> 4.75 | M18: =7000*4 -> 28000 | N18: =L18*M18/100 -> 1330 | O18: =N18*0.53 -> 704.9 | P18: =O18*9.3657 -> 6601.8819 | AC18: =Q18+T18+W18+Z18 -> 0 | AD18: =(R18+U18+X18+AA18)/4 -> 0 | AE18: =(S18+V18+Y18+AB18)/4 -> 0
A19: =(A18+1) -> 43870 | B19: 70 | C19: =IF(AC19>0,((B19-R19)+(S19-B20)),IF(B20=0, ,(B19-B20))) -> 4 | D19: 72 | E19: =IF(AC19>0,((D19-U19)+(V19-D20)),IF(D20=0, ,(D19-D20))) -> 4 | F19: 68 | G19: =IF(AC19>0,((F19-X19)+(Y19-F20)),IF(F20=0, ,(F19-F20))) -> 3 | H19: 68 | I19: =IF(AC19>0,((H19-AA19)+(AB19-H20)),IF(H20=0, ,(H19-H20))) -> 3 | J19: =B19+D19+F19+H19 -> 278 | K19: =J19/4 -> 69.5 | L19: =IF(AC19>0,((K19-AD19)+(AE19-K20)),IF(K20=0, ,(K19-K20))) -> 3.5 | M19: =7000*4 -> 28000 | N19: =L19*M19/100 -> 980 | O19: =N19*0.53 -> 519.4 | P19: =O19*9.3657 -> 4864.5446 | AC19: =Q19+T19+W19+Z19 -> 0 | AD19: =(R19+U19+X19+AA19)/4 -> 0 | AE19: =(S19+V19+Y19+AB19)/4 -> 0
A20: =(A19+1) -> 43871 | B20: 66 | C20: =IF(AC20>0,((B20-R20)+(S20-B21)),IF(B21=0, ,(B20-B21))) -> 1 | D20: 68 | E20: =IF(AC20>0,((D20-U20)+(V20-D21)),IF(D21=0, ,(D20-D21))) -> 3 | F20: 65 | G20: =IF(AC20>0,((F20-X20)+(Y20-F21)),IF(F21=0, ,(F20-F21))) -> 5 | H20: 65 | I20: =IF(AC20>0,((H20-AA20)+(AB20-H21)),IF(H21=0, ,(H20-H21))) -> 5 | J20: =B20+D20+F20+H20 -> 264 | K20: =J20/4 -> 66 | L20: =IF(AC20>0,((K20-AD20)+(AE20-K21)),IF(K21=0, ,(K20-K21))) -> 3.5 | M20: =7000*4 -> 28000 | N20: =L20*M20/100 -> 980 | O20: =N20*0.53 -> 519.4 | P20: =O20*9.3657 -> 4864.5446 | AC20: =Q20+T20+W20+Z20 -> 0 | AD20: =(R20+U20+X20+AA20)/4 -> 0 | AE20: =(S20+V20+Y20+AB20)/4 -> 0
A21: =(A20+1) -> 43872 | B21: 65 | C21: =IF(AC21>0,((B21-R21)+(S21-B22)),IF(B22=0, ,(B21-B22))) -> 9 | D21: 65 | E21: =IF(AC21>0,((D21-U21)+(V21-D22)),IF(D22=0, ,(D21-D22))) -> 4 | F21: 60 | G21: =IF(AC21>0,((F21-X21)+(Y21-F22)),IF(F22=0, ,(F21-F22))) -> 5 | H21: 60 | I21: =IF(AC21>0,((H21-AA21)+(AB21-H22)),IF(H22=0, ,(H21-H22))) -> 5 | J21: =B21+D21+F21+H21 -> 250 | K21: =J21/4 -> 62.5 | L21: =IF(AC21>0,((K21-AD21)+(AE21-K22)),IF(K22=0, ,(K21-K22))) -> 5.75 | M21: =7000*4 -> 28000 | N21: =L21*M21/100 -> 1610 | O21: =N21*0.53 -> 853.3 | P21: =O21*9.3657 -> 7991.7518 | AC21: =Q21+T21+W21+Z21 -> 0 | AD21: =(R21+U21+X21+AA21)/4 -> 0 | AE21: =(S21+V21+Y21+AB21)/4 -> 0
A22: =(A21+1) -> 43873 | B22: 56 | C22: =IF(AC22>0,((B22-R22)+(S22-B23)),IF(B23=0, ,(B22-B23))) -> 10 | D22: 61 | E22: =IF(AC22>0,((D22-U22)+(V22-D23)),IF(D23=0, ,(D22-D23))) -> 7 | F22: 55 | G22: =IF(AC22>0,((F22-X22)+(Y22-F23)),IF(F23=0, ,(F22-F23))) -> 10 | H22: 55 | I22: =IF(AC22>0,((H22-AA22)+(AB22-H23)),IF(H23=0, ,(H22-H23))) -> 10 | J22: =B22+D22+F22+H22 -> 227 | K22: =J22/4 -> 56.75 | L22: =IF(AC22>0,((K22-AD22)+(AE22-K23)),IF(K23=0, ,(K22-K23))) -> 9.25 | M22: =7000*4 -> 28000 | N22: =L22*M22/100 -> 2590 | O22: =N22*0.53 -> 1372.7 | P22: =O22*9.3657 -> 12856.296 | Q22: 3001 | R22: 50 | S22: 86 | T22: 2870 | U22: 55 | V22: 86 | W22: 2900 | X22: 50 | Y22: 85 | Z22: 2830 | AA22: 50 | AB22: 85 | AC22: =Q22+T22+W22+Z22 -> 11601 | AD22: =(R22+U22+X22+AA22)/4 -> 51.25 | AE22: =(S22+V22+Y22+AB22)/4 -> 85.5
A23: =(A22+1) -> 43874 | B23: 82 | C23: =IF(AC23>0,((B23-R23)+(S23-B24)),IF(B24=0, ,(B23-B24))) -> 0 | D23: 85 | E23: =IF(AC23>0,((D23-U23)+(V23-D24)),IF(D24=0, ,(D23-D24))) -> 0 | F23: 80 | G23: =IF(AC23>0,((F23-X23)+(Y23-F24)),IF(F24=0, ,(F23-F24))) -> 0 | H23: 80 | I23: =IF(AC23>0,((H23-AA23)+(AB23-H24)),IF(H24=0, ,(H23-H24))) -> 0 | J23: =B23+D23+F23+H23 -> 327 | K23: =J23/4 -> 81.75 | L23: =IF(AC23>0,((K23-AD23)+(AE23-K24)),IF(K24=0, ,(K23-K24))) -> 0 | M23: =7000*4 -> 28000 | N23: =L23*M23/100 -> 0 | O23: =N23*0.53 -> 0 | P23: =O23*9.3657 -> 0 | AC23: =Q23+T23+W23+Z23 -> 0 | AD23: =(R23+U23+X23+AA23)/4 -> 0 | AE23: =(S23+V23+Y23+AB23)/4 -> 0
A24: =(A23+1) -> 43875 | C24: =IF(AC24>0,((B24-R24)+(S24-B25)),IF(B25=0, ,(B24-B25))) -> 0 | E24: =IF(AC24>0,((D24-U24)+(V24-D25)),IF(D25=0, ,(D24-D25))) -> 0 | G24: =IF(AC24>0,((F24-X24)+(Y24-F25)),IF(F25=0, ,(F24-F25))) -> 0 | I24: =IF(AC24>0,((H24-AA24)+(AB24-H25)),IF(H25=0, ,(H24-H25))) -> 0 | J24: =B24+D24+F24+H24 -> 0 | K24: =J24/4 -> 0 | L24: =IF(AC24>0,((K24-AD24)+(AE24-K25)),IF(K25=0, ,(K24-K25))) -> 0 | M24: =7000*4 -> 28000 | N24: =L24*M24/100 -> 0 | O24: =N24*0.53 -> 0 | P24: =O24*9.3657 -> 0 | AC24: =Q24+T24+W24+Z24 -> 0 | AD24: =(R24+U24+X24+AA24)/4 -> 0 | AE24: =(S24+V24+Y24+AB24)/4 -> 0
A25: =(A24+1) -> 43876 | C25: =IF(AC25>0,((B25-R25)+(S25-B26)),IF(B26=0, ,(B25-B26))) -> 0 | E25: =IF(AC25>0,((D25-U25)+(V25-D26)),IF(D26=0, ,(D25-D26))) -> 0 | G25: =IF(AC25>0,((F25-X25)+(Y25-F26)),IF(F26=0, ,(F25-F26))) -> 0 | I25: =IF(AC25>0,((H25-AA25)+(AB25-H26)),IF(H26=0, ,(H25-H26))) -> 0 | J25: =B25+D25+F25+H25 -> 0 | K25: =J25/4 -> 0 | L25: =IF(AC25>0,((K25-AD25)+(AE25-K26)),IF(K26=0, ,(K25-K26))) -> 0 | M25: =7000*4 -> 28000 | N25: =L25*M25/100 -> 0 | O25: =N25*0.53 -> 0 | P25: =O25*9.3657 -> 0 | AC25: =Q25+T25+W25+Z25 -> 0 | AD25: =(R25+U25+X25+AA25)/4 -> 0 | AE25: =(S25+V25+Y25+AB25)/4 -> 0
A26: =(A25+1) -> 43877 | C26: =IF(AC26>0,((B26-R26)+(S26-B27)),IF(B27=0, ,(B26-B27))) -> 0 | E26: =IF(AC26>0,((D26-U26)+(V26-D27)),IF(D27=0, ,(D26-D27))) -> 0 | G26: =IF(AC26>0,((F26-X26)+(Y26-F27)),IF(F27=0, ,(F26-F27))) -> 0 | I26: =IF(AC26>0,((H26-AA26)+(AB26-H27)),IF(H27=0, ,(H26-H27))) -> 0 | J26: =B26+D26+F26+H26 -> 0 | K26: =J26/4 -> 0 | L26: =IF(AC26>0,((K26-AD26)+(AE26-K27)),IF(K27=0, ,(K26-K27))) -> 0 | M26: =7000*4 -> 28000 | N26: =L26*M26/100 -> 0 | O26: =N26*0.53 -> 0 | P26: =O26*9.3657 -> 0 | AC26: =Q26+T26+W26+Z26 -> 0 | AD26: =(R26+U26+X26+AA26)/4 -> 0 | AE26: =(S26+V26+Y26+AB26)/4 -> 0
A27: =(A26+1) -> 43878 | C27: =IF(AC27>0,((B27-R27)+(S27-B28)),IF(B28=0, ,(B27-B28))) -> 0 | E27: =IF(AC27>0,((D27-U27)+(V27-D28)),IF(D28=0, ,(D27-D28))) -> 0 | G27: =IF(AC27>0,((F27-X27)+(Y27-F28)),IF(F28=0, ,(F27-F28))) -> 0 | I27: =IF(AC27>0,((H27-AA27)+(AB27-H28)),IF(H28=0, ,(H27-H28))) -> 0 | J27: =B27+D27+F27+H27 -> 0 | K27: =J27/4 -> 0 | L27: =IF(AC27>0,((K27-AD27)+(AE27-K28)),IF(K28=0, ,(K27-K28))) -> 0 | M27: =7000*4 -> 28000 | N27: =L27*M27/100 -> 0 | O27: =N27*0.53 -> 0 | P27: =O27*9.3657 -> 0 | AC27: =Q27+T27+W27+Z27 -> 0 | AD27: =(R27+U27+X27+AA27)/4 -> 0 | AE27: =(S27+V27+Y27+AB27)/4 -> 0
A28: =(A27+1) -> 43879 | C28: =IF(AC28>0,((B28-R28)+(S28-B29)),IF(B29=0, ,(B28-B29))) -> 0 | E28: =IF(AC28>0,((D28-U28)+(V28-D29)),IF(D29=0, ,(D28-D29))) -> 0 | G28: =IF(AC28>0,((F28-X28)+(Y28-F29)),IF(F29=0, ,(F28-F29))) -> 0 | I28: =IF(AC28>0,((H28-AA28)+(AB28-H29)),IF(H29=0, ,(H28-H29))) -> 0 | J28: =B28+D28+F28+H28 -> 0 | K28: =J28/4 -> 0 | L28: =IF(AC28>0,((K28-AD28)+(AE28-K29)),IF(K29=0, ,(K28-K29))) -> 0 | M28: =7000*4 -> 28000 | N28: =L28*M28/100 -> 0 | O28: =N28*0.53 -> 0 | P28: =O28*9.3657 -> 0 | AC28: =Q28+T28+W28+Z28 -> 0 | AD28: =(R28+U28+X28+AA28)/4 -> 0 | AE28: =(S28+V28+Y28+AB28)/4 -> 0
A29: =(A28+1) -> 43880 | C29: =IF(AC29>0,((B29-R29)+(S29-B30)),IF(B30=0, ,(B29-B30))) -> 0 | E29: =IF(AC29>0,((D29-U29)+(V29-D30)),IF(D30=0, ,(D29-D30))) -> 0 | G29: =IF(AC29>0,((F29-X29)+(Y29-F30)),IF(F30=0, ,(F29-F30))) -> 0 | I29: =IF(AC29>0,((H29-AA29)+(AB29-H30)),IF(H30=0, ,(H29-H30))) -> 0 | J29: =B29+D29+F29+H29 -> 0 | K29: =J29/4 -> 0 | L29: =IF(AC29>0,((K29-AD29)+(AE29-K30)),IF(K30=0, ,(K29-K30))) -> 0 | M29: =7000*4 -> 28000 | N29: =L29*M29/100 -> 0 | O29: =N29*0.53 -> 0 | P29: =O29*9.3657 -> 0 | AC29: =Q29+T29+W29+Z29 -> 0 | AD29: =(R29+U29+X29+AA29)/4 -> 0 | AE29: =(S29+V29+Y29+AB29)/4 -> 0
A30: =(A29+1) -> 43881 | C30: =IF(AC30>0,((B30-R30)+(S30-B31)),IF(B31=0, ,(B30-B31))) -> 0 | E30: =IF(AC30>0,((D30-U30)+(V30-D31)),IF(D31=0, ,(D30-D31))) -> 0 | G30: =IF(AC30>0,((F30-X30)+(Y30-F31)),IF(F31=0, ,(F30-F31))) -> 0 | I30: =IF(AC30>0,((H30-AA30)+(AB30-H31)),IF(H31=0, ,(H30-H31))) -> 0 | J30: =B30+D30+F30+H30 -> 0 | K30: =J30/4 -> 0 | L30: =IF(AC30>0,((K30-AD30)+(AE30-K31)),IF(K31=0, ,(K30-K31))) -> 0 | M30: =7000*4 -> 28000 | N30: =L30*M30/100 -> 0 | O30: =N30*0.53 -> 0 | P30: =O30*9.3657 -> 0 | AC30: =Q30+T30+W30+Z30 -> 0 | AD30: =(R30+U30+X30+AA30)/4 -> 0 | AE30: =(S30+V30+Y30+AB30)/4 -> 0
A31: =(A30+1) -> 43882 | C31: =IF(AC31>0,((B31-R31)+(S31-B32)),IF(B32=0, ,(B31-B32))) -> 0 | E31: =IF(AC31>0,((D31-U31)+(V31-D32)),IF(D32=0, ,(D31-D32))) -> 0 | G31: =IF(AC31>0,((F31-X31)+(Y31-F32)),IF(F32=0, ,(F31-F32))) -> 0 | I31: =IF(AC31>0,((H31-AA31)+(AB31-H32)),IF(H32=0, ,(H31-H32))) -> 0 | J31: =B31+D31+F31+H31 -> 0 | K31: =J31/4 -> 0 | L31: =IF(AC31>0,((K31-AD31)+(AE31-K32)),IF(K32=0, ,(K31-K32))) -> 0 | M31: =7000*4 -> 28000 | N31: =L31*M31/100 -> 0 | O31: =N31*0.53 -> 0 | P31: =O31*9.3657 -> 0 | AC31: =Q31+T31+W31+Z31 -> 0 | AD31: =(R31+U31+X31+AA31)/4 -> 0 | AE31: =(S31+V31+Y31+AB31)/4 -> 0
A32: =(A31+1) -> 43883 | C32: =IF(AC32>0,((B32-R32)+(S32-B33)),IF(B33=0, ,(B32-B33))) -> 0 | E32: =IF(AC32>0,((D32-U32)+(V32-D33)),IF(D33=0, ,(D32-D33))) -> 0 | G32: =IF(AC32>0,((F32-X32)+(Y32-F33)),IF(F33=0, ,(F32-F33))) -> 0 | I32: =IF(AC32>0,((H32-AA32)+(AB32-H33)),IF(H33=0, ,(H32-H33))) -> 0 | J32: =B32+D32+F32+H32 -> 0 | K32: =J32/4 -> 0 | L32: =IF(AC32>0,((K32-AD32)+(AE32-K33)),IF(K33=0, ,(K32-K33))) -> 0 | M32: =7000*4 -> 28000 | N32: =L32*M32/100 -> 0 | O32: =N32*0.53 -> 0 | P32: =O32*9.3657 -> 0 | AC32: =Q32+T32+W32+Z32 -> 0 | AD32: =(R32+U32+X32+AA32)/4 -> 0 | AE32: =(S32+V32+Y32+AB32)/4 -> 0
A33: =(A32+1) -> 43884 | C33: =IF(AC33>0,((B33-R33)+(S33-B34)),IF(B34=0, ,(B33-B34))) -> 0 | E33: =IF(AC33>0,((D33-U33)+(V33-D34)),IF(D34=0, ,(D33-D34))) -> 0 | G33: =IF(AC33>0,((F33-X33)+(Y33-F34)),IF(F34=0, ,(F33-F34))) -> 0 | I33: =IF(AC33>0,((H33-AA33)+(AB33-H34)),IF(H34=0, ,(H33-H34))) -> 0 | J33: =B33+D33+F33+H33 -> 0 | K33: =J33/4 -> 0 | L33: =IF(AC33>0,((K33-AD33)+(AE33-K34)),IF(K34=0, ,(K33-K34))) -> 0 | M33: =7000*4 -> 28000 | N33: =L33*M33/100 -> 0 | O33: =N33*0.53 -> 0 | P33: =O33*9.3657 -> 0 | AC33: =Q33+T33+W33+Z33 -> 0 | AD33: =(R33+U33+X33+AA33)/4 -> 0 | AE33: =(S33+V33+Y33+AB33)/4 -> 0
A34: =(A33+1) -> 43885 | C34: =IF(AC34>0,((B34-R34)+(S34-B35)),IF(B35=0, ,(B34-B35))) -> 0 | E34: =IF(AC34>0,((D34-U34)+(V34-D35)),IF(D35=0, ,(D34-D35))) -> 0 | G34: =IF(AC34>0,((F34-X34)+(Y34-F35)),IF(F35=0, ,(F34-F35))) -> 0 | I34: =IF(AC34>0,((H34-AA34)+(AB34-H35)),IF(H35=0, ,(H34-H35))) -> 0 | J34: =B34+D34+F34+H34 -> 0 | K34: =J34/4 -> 0 | L34: =IF(AC34>0,((K34-AD34)+(AE34-K35)),IF(K35=0, ,(K34-K35))) -> 0 | M34: =7000*4 -> 28000 | N34: =L34*M34/100 -> 0 | O34: =N34*0.53 -> 0 | P34: =O34*9.3657 -> 0 | AC34: =Q34+T34+W34+Z34 -> 0 | AD34: =(R34+U34+X34+AA34)/4 -> 0 | AE34: =(S34+V34+Y34+AB34)/4 -> 0
A35: =(A34+1) -> 43886 | C35: =IF(AC35>0,((B35-R35)+(S35-B36)),IF(B36=0, ,(B35-B36))) -> 0 | E35: =IF(AC35>0,((D35-U35)+(V35-D36)),IF(D36=0, ,(D35-D36))) -> 0 | G35: =IF(AC35>0,((F35-X35)+(Y35-F36)),IF(F36=0, ,(F35-F36))) -> 0 | I35: =IF(AC35>0,((H35-AA35)+(AB35-H36)),IF(H36=0, ,(H35-H36))) -> 0 | J35: =B35+D35+F35+H35 -> 0 | K35: =J35/4 -> 0 | L35: =IF(AC35>0,((K35-AD35)+(AE35-K36)),IF(K36=0, ,(K35-K36))) -> 0 | M35: =7000*4 -> 28000 | N35: =L35*M35/100 -> 0 | O35: =N35*0.53 -> 0 | P35: =O35*9.3657 -> 0 | AC35: =Q35+T35+W35+Z35 -> 0 | AD35: =(R35+U35+X35+AA35)/4 -> 0 | AE35: =(S35+V35+Y35+AB35)/4 -> 0
... A42: =(A41+1) -> 43893 | C42: =IF(AC42>0,((B42-R42)+(S42-B43)),IF(B43=0, ,(B42-B43))) -> 0 | E42: =IF(AC42>0,((D42-U42)+(V42-D43)),IF(D43=0, ,(D42-D43))) -> 0 | G42: =IF(AC42>0,((F42-X42)+(Y42-F43)),IF(F43=0, ,(F42-F43))) -> 0 | I42: =IF(AC42>0,((H42-AA42)+(AB42-H43)),IF(H43=0, ,(H42-H43))) -> 0 | J42: =B42+D42+F42+H42 -> 0 | K42: =J42/4 -> 0 | L42: =IF(AC42>0,((K42-AD42)+(AE42-K43)),IF(K43=0, ,(K42-K43))) -> 0 | M42: =7000*4 -> 28000 | N42: =L42*M42/100 -> 0 | O42: =N42*0.53 -> 0 | P42: =O42*9.3657 -> 0 | AC42: =Q42+T42+W42+Z42 -> 0 | AD42: =(R42+U42+X42+AA42)/4 -> 0 | AE42: =(S42+V42+Y42+AB42)/4 -> 0
C43: =SUM(C11:C39) -> 88 | E43: =SUM(E11:E39) -> 41 | G43: =SUM(G11:G39) -> 86 | I43: =SUM(I11:I39) -> 82 | N43: =SUM(N11:N39) -> 20790 | O43: =N43*0.53 -> 11018.7 | P43: =O43*9.3657 -> 103197.84 | Q43: =SUM(Q11:Q39) -> 8658 | T43: =SUM(T11:T39) -> 4370 | W43: =SUM(W11:W39) -> 8058 | Z43: =SUM(Z11:Z39) -> 6509 | AC43: =SUM(AC11:AC39) -> 27595
Q44: =Q43+T43+W43+Z43 -> 27595 | AC44: =Q43+T43+W43+Z43 -> 27595
K46: Litre | L46: Kg | M46: DH
H47: Consommation du mois | K47: =N43 -> 20790 | L47: =O43 -> 11018.7 | M47: =P43 -> 103197.84
...

Sheet Suivi EAU-ELEC
C1: Suivi Compteur d'Eau- électricité RADEEMA -
A7: Date | B7: Eau m3 | D7: Electricité Kw/h
B8: Compteur | C8: Consommation | D8: Compteur H.Creuse | E8: Consommation H.Creuse | F8: Compteur H.Pleine | G8: Consommation H.Pleine | H8: Compteur H.Pointe | I8: Consommation H.Pointe
A9: 43855 | B9: 119288 | C9: =IF(B10<B9,0,B10-B9)*10 -> 460 | D9: 18107218 | E9: =IF(D10<D9,0,D10-D9) -> 4237 | F9: 32645615 | G9: =IF(F10<F9,0,F10-F9) -> 6599 | H9: 14439283 | I9: =IF(H10<H9,0,H10-H9) -> 2997
A10: =A9+1 -> 43856 | B10: 119334 | C10: =IF(B11<B10,0,B11-B10)*10 -> 560 | D10: 18111455 | E10: =IF(D11<D10,0,D11-D10) -> 4274 | F10: 32652214 | G10: =IF(F11<F10,0,F11-F10) -> 6547 | H10: 14442280 | I10: =IF(H11<H10,0,H11-H10) -> 2970
A11: =A10+1 -> 43857 | B11: 119390 | C11: =IF(B12<B11,0,B12-B11)*10 -> 470 | D11: 18115729 | E11: =IF(D12<D11,0,D12-D11) -> 4336 | F11: 32658761 | G11: =IF(F12<F11,0,F12-F11) -> 6772 | H11: 14445250 | I11: =IF(H12<H11,0,H12-H11) -> 3041
A12: =A11+1 -> 43858 | B12: 119437 | C12: =IF(B13<B12,0,B13-B12)*10 -> 500 | D12: 18120065 | E12: =IF(D13<D12,0,D13-D12) -> 4342 | F12: 32665533 | G12: =IF(F13<F12,0,F13-F12) -> 6931 | H12: 14448291 | I12: =IF(H13<H12,0,H13-H12) -> 3007
A13: =A12+1 -> 43859 | B13: 119487 | C13: =IF(B14<B13,0,B14-B13)*10 -> 480 | D13: 18124407 | E13: =IF(D14<D13,0,D14-D13) -> 4225 | F13: 32672464 | G13: =IF(F14<F13,0,F14-F13) -> 6665 | H13: 14451298 | I13: =IF(H14<H13,0,H14-H13) -> 2896
A14: =A13+1 -> 43860 | B14: 119535 | C14: =IF(B15<B14,0,B15-B14)*10 -> 430 | D14: 18128632 | E14: =IF(D15<D14,0,D15-D14) -> 4163 | F14: 32679129 | G14: =IF(F15<F14,0,F15-F14) -> 6904 | H14: 14454194 | I14: =IF(H15<H14,0,H15-H14) -> 2884
A15: =A14+1 -> 43861 | B15: 119578 | C15: =IF(B16<B15,0,B16-B15)*10 -> 490 | D15: 18132795 | E15: =IF(D16<D15,0,D16-D15) -> 4335 | F15: 32686033 | G15: =IF(F16<F15,0,F16-F15) -> 6357 | H15: 14457078 | I15: =IF(H16<H15,0,H16-H15) -> 2896
A16: =A15+1 -> 43862 | B16: 119627 | C16: =IF(B17<B16,0,B17-B16)*10 -> 470 | D16: 18137130 | E16: =IF(D17<D16,0,D17-D16) -> 4015 | F16: 32692390 | G16: =IF(F17<F16,0,F17-F16) -> 6238 | H16: 14459974 | I16: =IF(H17<H16,0,H17-H16) -> 2808
A17: =A16+1 -> 43863 | B17: 119674 | C17: =IF(B18<B17,0,B18-B17)*10 -> 540 | D17: 18141145 | E17: =IF(D18<D17,0,D18-D17) -> 4712 | F17: 32698628 | G17: =IF(F18<F17,0,F18-F17) -> 6202 | H17: 14462782 | I17: =IF(H18<H17,0,H18-H17) -> 3477
A18: =A17+1 -> 43864 | B18: 119728 | C18: =IF(B19<B18,0,B19-B18)*10 -> 470 | D18: 18145857 | E18: =IF(D19<D18,0,D19-D18) -> 4776 | F18: 32704830 | G18: =IF(F19<F18,0,F19-F18) -> 7173 | H18: 14466259 | I18: =IF(H19<H18,0,H19-H18) -> 3744
A19: =A18+1 -> 43865 | B19: 119775 | C19: =IF(B20<B19,0,B20-B19)*10 -> 500 | D19: 18150633 | E19: =IF(D20<D19,0,D20-D19) -> 5000 | F19: 32712003 | G19: =IF(F20<F19,0,F20-F19) -> 7730 | H19: 14470003 | I19: =IF(H20<H19,0,H20-H19) -> 3480
A20: =A19+1 -> 43866 | B20: 119825 | C20: =IF(B21<B20,0,B21-B20)*10 -> 520 | D20: 18155633 | E20: =IF(D21<D20,0,D21-D20) -> 5560 | F20: 32719733 | G20: =IF(F21<F20,0,F21-F20) -> 7043 | H20: 14473483 | I20: =IF(H21<H20,0,H21-H20) -> 3700
A21: =A20+1 -> 43867 | B21: 119877 | C21: =IF(B22<B21,0,B22-B21)*10 -> 510 | D21: 18161193 | E21: =IF(D22<D21,0,D22-D21) -> 6172 | F21: 32726776 | G21: =IF(F22<F21,0,F22-F21) -> 8342 | H21: 14477183 | I21: =IF(H22<H21,0,H22-H21) -> 3792
... A28: =A27+1 -> 43874 | B28: 120259 | C28: =IF(B29<B28,0,B29-B28)*10 -> 0 | D28: 18195909 | E28: =IF(D29<D28,0,D29-D28) -> 0 | F28: 32778804 | G28: =IF(F29<F28,0,F29-F28) -> 0 | H28: 14503053 | I28: =IF(H29<H28,0,H29-H28) -> 0
A29: =A28+1 -> 43875 | C29: =IF(B30<B29,0,B30-B29)*10 -> 0 | E29: =IF(D30<D29,0,D30-D29) -> 0 | G29: =IF(F30<F29,0,F30-F29) -> 0 | I29: =IF(H30<H29,0,H30-H29) -> 0
A30: =A29+1 -> 43876 | C30: =IF(B31<B30,0,B31-B30)*10 -> 0 | E30: =IF(D31<D30,0,D31-D30) -> 0 | G30: =IF(F31<F30,0,F31-F30) -> 0 | I30: =IF(H31<H30,0,H31-H30) -> 0
A31: =A30+1 -> 43877 | C31: =IF(B32<B31,0,B32-B31)*10 -> 0 | E31: =IF(D32<D31,0,D32-D31) -> 0 | G31: =IF(F32<F31,0,F32-F31) -> 0 | I31: =IF(H32<H31,0,H32-H31) -> 0
A32: =A31+1 -> 43878 | C32: =IF(B33<B32,0,B33-B32)*10 -> 0 | E32: =IF(D33<D32,0,D33-D32) -> 0 | G32: =IF(F33<F32,0,F33-F32) -> 0 | I32: =IF(H33<H32,0,H33-H32) -> 0
A33: =A32+1 -> 43879 | C33: =IF(B34<B33,0,B34-B33)*10 -> 0 | E33: =IF(D34<D33,0,D34-D33) -> 0 | G33: =IF(F34<F33,0,F34-F33) -> 0 | I33: =IF(H34<H33,0,H34-H33) -> 0
A34: =A33+1 -> 43880 | C34: =IF(B35<B34,0,B35-B34)*10 -> 0 | E34: =IF(D35<D34,0,D35-D34) -> 0 | G34: =IF(F35<F34,0,F35-F34) -> 0 | I34: =IF(H35<H34,0,H35-H34) -> 0
A35: =A34+1 -> 43881 | C35: =IF(B36<B35,0,B36-B35)*10 -> 0 | E35: =IF(D36<D35,0,D36-D35) -> 0 | G35: =IF(F36<F35,0,F36-F35) -> 0 | I35: =IF(H36<H35,0,H36-H35) -> 0
A36: =A35+1 -> 43882 | C36: =IF(B37<B36,0,B37-B36)*10 -> 0 | E36: =IF(D37<D36,0,D37-D36) -> 0 | G36: =IF(F37<F36,0,F37-F36) -> 0 | I36: =IF(H37<H36,0,H37-H36) -> 0
A37: =A36+1 -> 43883 | C37: =IF(B38<B37,0,B38-B37)*10 -> 0 | E37: =IF(D38<D37,0,D38-D37) -> 0 | G37: =IF(F38<F37,0,F38-F37) -> 0 | I37: =IF(H38<H37,0,H38-H37) -> 0
A38: =A37+1 -> 43884 | C38: =IF(B39<B38,0,B39-B38)*10 -> 0 | E38: =IF(D39<D38,0,D39-D38) -> 0 | G38: =IF(F39<F38,0,F39-F38) -> 0 | I38: =IF(H39<H38,0,H39-H38) -> 0
A39: =A38+1 -> 43885 | C39: =IF(B40<B39,0,B40-B39)*10 -> 0 | E39: =IF(D40<D39,0,D40-D39) -> 0 | G39: =IF(F40<F39,0,F40-F39) -> 0 | I39: =IF(H40<H39,0,H40-H39) -> 0
A40: =A39+1 -> 43886 | C40: =IF(B41<B40,0,B41-B40)*10 -> 0 | E40: =IF(D41<D40,0,D41-D40) -> 0 | G40: =IF(F41<F40,0,F41-F40) -> 0 | I40: =IF(H41<H40,0,H41-H40) -> 0
... A47: =A46+1 -> 43893 | C47: =IF(B48<B47,0,B48-B47)*10 -> 0 | E47: =IF(D48<D47,0,D48-D47) -> 0 | G47: =IF(F48<F47,0,F48-F47) -> 0 | I47: =IF(H48<H47,0,H48-H47) -> 0
C48: =SUM(C16:C44) -> 6320 | E48: =SUM(E16:E44) -> 58779 | G48: =SUM(G16:G44) -> 86414 | I48: =SUM(I16:I44) -> 43079
G58: =IF(F59<F58,0,F59-F58) -> 0

Sheet Feuil1
