Workbook

Sheet TOTAL
A1: Site Name | B1: Day | C1: Month | D1: Year | E1: Total Electricity Kwh | F1: Electricity Tariff ($/Kwh) | G1: LPG (Kg) | H1: LPG $/Kg | I1: Water Utility Supply (m3) m3 | J1: Water Utility Supply (m3) $/m3 | K1: Room Nights | N1: Water Tanks | O1: Cost of Water Tanks Rs | P1: Water Utility Supply (m3) Rs/m3 | Q1: Electricity Tariff (Rs/Kwh) | R1: LPG Rs/Kg | S1: Exchange Rate | T1: Total LPG Cost | U1: Total Water Cost
A2: Mauritius at Anahita | B2: 1 | C2: 1 | D2: 2020 | E2: =HOTEL!E4 -> 27980 | F2: 6.21 | G2: =HOTEL!BY4 -> 1077.5 | H2: 50.05 | I2: =HOTEL!Q4+HOTEL!U4 -> 311 | J2: =P2 -> 60.418006 | K2: =HOTEL!DS4 -> 87 | N2: =HOTEL!S4 -> 5 | O2: =N2*2500 -> 12500 | P2: =(((HOTEL!Q4*34))+(N2*2500))/I2 -> 60.418006 | Q2: 5.83 | R2: 50.05 | S2: 33.88 | T2: =G2*H2 -> 53928.875 | U2: =I2*P2 -> 18790
A3: Mauritius at Anahita | B3: =B2+1 -> 2 | C3: 1 | D3: 2020 | E3: =HOTEL!E5 -> 28575 | F3: 6.21 | G3: =HOTEL!BY5 -> 969.75 | H3: 50.05 | I3: =HOTEL!Q5+HOTEL!U5 -> 212 | J3: =P3 -> 60.716981 | K3: =HOTEL!DS5 -> 74 | N3: =HOTEL!S5 -> 3 | O3: =N3*2500 -> 7500 | P3: =(((HOTEL!Q5*34))+(N3*2500))/I3 -> 60.716981 | Q3: 5.83 | R3: 50.05 | S3: 33.88 | T3: =G3*H3 -> 48535.987 | U3: =I3*P3 -> 12872
A4: Mauritius at Anahita | B4: =B3+1 -> 3 | C4: 1 | D4: 2020 | E4: =HOTEL!E6 -> 29882 | F4: 6.21 | G4: =HOTEL!BY6 -> 538.75 | H4: 50.05 | I4: =HOTEL!Q6+HOTEL!U6 -> 134 | J4: =P4 -> 27.910448 | K4: =HOTEL!DS6 -> 79 | N4: =HOTEL!S6 -> 0 | O4: =N4*2500 -> 0 | P4: =(((HOTEL!Q6*34))+(N4*2500))/I4 -> 27.910448 | Q4: 5.83 | R4: 50.05 | S4: 33.88 | T4: =G4*H4 -> 26964.438 | U4: =I4*P4 -> 3740
A5: Mauritius at Anahita | B5: =B4+1 -> 4 | C5: 1 | D5: 2020 | E5: =HOTEL!E7 -> 28520 | F5: 6.21 | G5: =HOTEL!BY7 -> 1077.5 | H5: 50.05 | I5: =HOTEL!Q7+HOTEL!U7 -> 338 | J5: =P5 -> 70.236686 | K5: =HOTEL!DS7 -> 85 | N5: =HOTEL!S7 -> 8 | O5: =N5*2500 -> 20000 | P5: =(((HOTEL!Q7*34))+(N5*2500))/I5 -> 70.236686 | Q5: 5.83 | R5: 50.05 | S5: 33.88 | T5: =G5*H5 -> 53928.875 | U5: =I5*P5 -> 23740
A6: Mauritius at Anahita | B6: =B5+1 -> 5 | C6: 1 | D6: 2020 | E6: =HOTEL!E8 -> 27431 | F6: 6.21 | G6: =HOTEL!BY8 -> 1077.5 | H6: 50.05 | I6: =HOTEL!Q8+HOTEL!U8 -> 289 | J6: =P6 -> 66.844291 | K6: =HOTEL!DS8 -> 77 | N6: =HOTEL!S8 -> 6 | O6: =N6*2500 -> 15000 | P6: =(((HOTEL!Q8*34))+(N6*2500))/I6 -> 66.844291 | Q6: 5.83 | R6: 50.05 | S6: 33.88 | T6: =G6*H6 -> 53928.875 | U6: =I6*P6 -> 19318
A7: Mauritius at Anahita | B7: =B6+1 -> 6 | C7: 1 | D7: 2020 | E7: =HOTEL!E9 -> 27753 | F7: 6.21 | G7: =HOTEL!BY9 -> 538.75 | H7: 50.05 | I7: =HOTEL!Q9+HOTEL!U9 -> 374 | J7: =P7 -> 74.572193 | K7: =HOTEL!DS9 -> 74 | N7: =HOTEL!S9 -> 10 | O7: =N7*2500 -> 25000 | P7: =(((HOTEL!Q9*34))+(N7*2500))/I7 -> 74.572193 | Q7: 5.83 | R7: 50.05 | S7: 33.88 | T7: =G7*H7 -> 26964.438 | U7: =I7*P7 -> 27890
A8: Mauritius at Anahita | B8: =B7+1 -> 7 | C8: 1 | D8: 2020 | E8: =HOTEL!E10 -> 26949 | F8: 6.21 | G8: =HOTEL!BY10 -> 1120 | H8: 50.05 | I8: =HOTEL!Q10+HOTEL!U10 -> 106 | J8: =P8 -> 34 | K8: =HOTEL!DS10 -> 74 | N8: =HOTEL!S10 -> 0 | O8: =N8*2500 -> 0 | P8: =(((HOTEL!Q10*34))+(N8*2500))/I8 -> 34 | Q8: 5.83 | R8: 50.05 | S8: 33.88 | T8: =G8*H8 -> 56056 | U8: =I8*P8 -> 3604
A9: Mauritius at Anahita | B9: =B8+1 -> 8 | C9: 1 | D9: 2020 | E9: =HOTEL!E11 -> 27034 | F9: 6.21 | G9: =HOTEL!BY11 -> 969.75 | H9: 50.05 | I9: =HOTEL!Q11+HOTEL!U11 -> 311 | J9: =P9 -> 58.996785 | K9: =HOTEL!DS11 -> 69 | N9: =HOTEL!S11 -> 5 | O9: =N9*2500 -> 12500 | P9: =(((HOTEL!Q11*34))+(N9*2500))/I9 -> 58.996785 | Q9: 5.83 | R9: 50.05 | S9: 33.88 | T9: =G9*H9 -> 48535.987 | U9: =I9*P9 -> 18348
A10: Mauritius at Anahita | B10: =B9+1 -> 9 | C10: 1 | D10: 2020 | E10: =HOTEL!E12 -> 24570 | F10: 6.21 | G10: =HOTEL!BY12 -> 646.5 | H10: 50.05 | I10: =HOTEL!Q12+HOTEL!U12 -> 312 | J10: =P10 -> 58.589744 | K10: =HOTEL!DS12 -> 68 | N10: =HOTEL!S12 -> 5 | O10: =N10*2500 -> 12500 | P10: =(((HOTEL!Q12*34))+(N10*2500))/I10 -> 58.589744 | Q10: 5.83 | R10: 50.05 | S10: 33.93 | T10: =G10*H10 -> 32357.325 | U10: =I10*P10 -> 18280
A11: Mauritius at Anahita | B11: =B10+1 -> 10 | C11: 1 | D11: 2020 | E11: =HOTEL!E13 -> 25702 | F11: 6.21 | G11: =HOTEL!BY13 -> 538.75 | H11: 62.95 | I11: =HOTEL!Q13+HOTEL!U13 -> 399 | J11: =P11 -> 72.285714 | K11: =HOTEL!DS13 -> 62 | N11: =HOTEL!S13 -> 10 | O11: =N11*2500 -> 25000 | P11: =(((HOTEL!Q13*34))+(N11*2500))/I11 -> 72.285714 | Q11: 5.83 | R11: 62.95 | S11: 33.93 | T11: =G11*H11 -> 33914.312 | U11: =I11*P11 -> 28842
A12: Mauritius at Anahita | B12: =B11+1 -> 11 | C12: 1 | D12: 2020 | E12: =HOTEL!E14 -> 25512 | F12: 6.21 | G12: =HOTEL!BY14 -> 538.75 | H12: 62.95 | I12: =HOTEL!Q14+HOTEL!U14 -> 251 | J12: =P12 -> 65.784861 | K12: =HOTEL!DS14 -> 63 | N12: =HOTEL!S14 -> 5 | O12: =N12*2500 -> 12500 | P12: =(((HOTEL!Q14*34))+(N12*2500))/I12 -> 65.784861 | Q12: 5.83 | R12: 62.95 | S12: 33.93 | T12: =G12*H12 -> 33914.312 | U12: =I12*P12 -> 16512
A13: Mauritius at Anahita | B13: =B12+1 -> 12 | C13: 1 | D13: 2020 | E13: =HOTEL!E15 -> 0 | F13: 6.21 | G13: =HOTEL!BY15 -> 0 | H13: 62.95 | I13: =HOTEL!Q15+HOTEL!U15 -> 0 | J13: =P13 -> #DIV/0! | K13: =HOTEL!DS15 -> 66 | N13: =HOTEL!S15 -> 0 | O13: =N13*2500 -> 0 | P13: =(((HOTEL!Q15*34))+(N13*2500))/I13 -> #DIV/0! | Q13: 5.83 | R13: 62.95 | S13: 33.93 | T13: =G13*H13 -> 0 | U13: =I13*P13 -> #DIV/0!
A14: Mauritius at Anahita | B14: =B13+1 -> 13 | C14: 1 | D14: 2020 | E14: =HOTEL!E16 -> 0 | F14: 6.21 | G14: =HOTEL!BY16 -> 0 | H14: 62.95 | I14: =HOTEL!Q16+HOTEL!U16 -> 0 | J14: =P14 -> #DIV/0! | K14: =HOTEL!DS16 -> 0 | N14: =HOTEL!S16 -> 0 | O14: =N14*2500 -> 0 | P14: =(((HOTEL!Q16*34))+(N14*2500))/I14 -> #DIV/0! | Q14: 5.83 | R14: 62.95 | S14: 33.93 | T14: =G14*H14 -> 0 | U14: =I14*P14 -> #DIV/0!
... A29: Mauritius at Anahita | B29: =B28+1 -> 28 | C29: 1 | D29: 2020 | E29: =HOTEL!E31 -> 0 | F29: 6.21 | G29: =HOTEL!BY31 -> 0 | H29: 62.95 | I29: =HOTEL!Q31+HOTEL!U31 -> 0 | J29: =P29 -> #DIV/0! | K29: =HOTEL!DS31 -> 0 | N29: =HOTEL!S31 -> 0 | O29: =N29*2500 -> 0 | P29: =(((HOTEL!Q31*34))+(N29*2500))/I29 -> #DIV/0! | Q29: 5.83 | R29: 62.95 | S29: 33.93 | T29: =G29*H29 -> 0 | U29: =I29*P29 -> #DIV/0!
A30: Mauritius at Anahita | B30: =B29+1 -> 29 | C30: 1 | D30: 2020 | E30: =HOTEL!E32 -> 0 | F30: 6.21 | G30: =HOTEL!BY32 -> 0 | H30: 62.95 | I30: =HOTEL!Q32+HOTEL!U32 -> 0 | J30: =P30 -> #DIV/0! | K30: =HOTEL!DS32 -> 0 | N30: =HOTEL!S32 -> 0 | O30: =N30*2500 -> 0 | P30: =(((HOTEL!Q32*34))+(N30*2500))/I30 -> #DIV/0! | Q30: 5.83 | R30: 62.95 | T30: =G30*H30 -> 0 | U30: =I30*P30 -> #DIV/0!
A31: Mauritius at Anahita | B31: =B30+1 -> 30 | C31: 1 | D31: 2020 | E31: =HOTEL!E33 -> 0 | F31: 6.21 | G31: =HOTEL!BY33 -> 0 | H31: 62.95 | I31: =HOTEL!Q33+HOTEL!U33 -> 0 | J31: =P31 -> #DIV/0! | K31: =HOTEL!DS33 -> 0 | N31: =HOTEL!S33 -> 0 | O31: =N31*2500 -> 0 | P31: =(((HOTEL!Q33*34))+(N31*2500))/I31 -> #DIV/0! | Q31: 5.83 | R31: 62.95 | T31: =G31*H31 -> 0 | U31: =I31*P31 -> #DIV/0!
A32: Mauritius at Anahita | B32: =B31+1 -> 31 | C32: 1 | D32: 2020 | E32: =HOTEL!E34 -> 0 | F32: 7.21 | G32: =HOTEL!BY34 -> 0 | H32: 62.95 | I32: =HOTEL!Q34+HOTEL!U34 -> 0 | J32: =P32 -> #DIV/0! | K32: =HOTEL!DS34 -> 0 | N32: =HOTEL!S34 -> 8 | O32: =N32*2500 -> 20000 | P32: =(((HOTEL!Q34*34))+(N32*2500))/I32 -> #DIV/0! | Q32: 5.83 | R32: 62.95 | T32: =G32*H32 -> 0 | U32: =I32*P32 -> #DIV/0!

Sheet Submetering
A1: Site Name | B1: Day | C1: Month | D1: Year | E1: Hotel (KWh) | F1: Vacoas (KWh) | G1: Laundry (KWh) | H1: Villa 145 (KWh) | I1: Villa 146 (KWh) | J1: Villa 111 (KWh) | K1: Villa 128 (KWh) | L1: Hotel (m3) | M1: Bamboo Pool (m3) | N1: Island (m3) | O1: Main Building (m3) | P1: Pantry A (m3) | Q1: Pantry B (m3) | R1: Pantry C (m3) | S1: Pantry D (m3) | T1: Pantry E (m3) | U1: Pantry F (m3) | V1: Pantry G (m3) | W1: North Parcel (m3) | X1: South Parcel (m3) | Y1: Beau champ (Kg) | Z1: Acquapazza (Kg) | AA1: Bamboo (Kg) | AB1: Steam Boiler (Kg) | AC1: Laundry (Kg) | AD1: Pantry A (Kg) | AE1: Pantry B (Kg) | AF1: Pantry C (Kg) | AG1: Pantry D (Kg) | AH1: Pantry E (Kg) | AI1: Pantry F (Kg) | AJ1: Pantry G (Kg) | AK1: Room Nights
A2: Mauritius at Anahita | B2: 1 | C2: 1 | D2: 2020 | E2: =TOTAL!E2 -> 27980 | F2: =HOTEL!M4 -> 704 | G2: =HOTEL!O4 -> 612 | H2: =HOTEL!DL4 -> 0 | I2: =HOTEL!DN4 -> 0 | J2: =HOTEL!DP4 -> 0 | K2: =HOTEL!DR4 -> 0 | L2: =N2+W2+X2 -> 270 | M2: =HOTEL!AA4 -> 11 | N2: =HOTEL!AE4 -> 130 | O2: =HOTEL!AG4 -> 14 | P2: =HOTEL!AI4 -> 2 | Q2: =HOTEL!AK4 -> 2 | R2: =HOTEL!AM4 -> 7 | S2: =HOTEL!AO4 -> 8 | T2: =HOTEL!AQ4 -> 2 | U2: =HOTEL!AS4 -> 4 | V2: =HOTEL!AU4 -> 4 | W2: =HOTEL!BG4 -> 110 | X2: =HOTEL!BJ4 -> 30 | Y2: =HOTEL!CC4 -> 343.75 | Z2: =HOTEL!CF3 -> 0 | AA2: =HOTEL!CI4 -> 106.25 | AB2: =HOTEL!CL4 -> 31.25 | AC2: =HOTEL!CO4 -> 31.25 | AD2: =HOTEL!CR4 -> 68.75 | AE2: =HOTEL!CU4 -> 31.25 | AF2: =HOTEL!CX4 -> 6.25 | AG2: =HOTEL!DA4 -> 37.5 | AH2: =HOTEL!DD4 -> 25 | AI2: =HOTEL!DG4 -> 43.75 | AJ2: =HOTEL!DJ4 -> 43.75 | AK2: =TOTAL!K2 -> 87
A3: Mauritius at Anahita | B3: =B2+1 -> 2 | C3: 1 | D3: 2020 | E3: =TOTAL!E3 -> 28575 | F3: =HOTEL!M5 -> 816 | G3: =HOTEL!O5 -> 617 | H3: =HOTEL!DL5 -> 0 | I3: =HOTEL!DN5 -> 0 | J3: =HOTEL!DP5 -> 0 | K3: =HOTEL!DR5 -> 0 | L3: =N3+W3+X3 -> 290 | M3: =HOTEL!AA5 -> 0 | N3: =HOTEL!AE5 -> 140 | O3: =HOTEL!AG5 -> 15 | P3: =HOTEL!AI5 -> 2 | Q3: =HOTEL!AK5 -> 3 | R3: =HOTEL!AM5 -> 4 | S3: =HOTEL!AO5 -> 5 | T3: =HOTEL!AQ5 -> 2 | U3: =HOTEL!AS5 -> 3 | V3: =HOTEL!AU5 -> 3 | W3: =HOTEL!BG5 -> 120 | X3: =HOTEL!BJ5 -> 30 | Y3: =HOTEL!CC5 -> 356.25 | Z3: =HOTEL!CF4 -> 106.25 | AA3: =HOTEL!CI5 -> 62.5 | AB3: =HOTEL!CL5 -> 25 | AC3: =HOTEL!CO5 -> 31.25 | AD3: =HOTEL!CR5 -> 50 | AE3: =HOTEL!CU5 -> 31.25 | AF3: =HOTEL!CX5 -> 6.25 | AG3: =HOTEL!DA5 -> 43.75 | AH3: =HOTEL!DD5 -> 31.25 | AI3: =HOTEL!DG5 -> 43.75 | AJ3: =HOTEL!DJ5 -> 50 | AK3: =TOTAL!K3 -> 74
A4: Mauritius at Anahita | B4: =B3+1 -> 3 | C4: 1 | D4: 2020 | E4: =TOTAL!E4 -> 29882 | F4: =HOTEL!M6 -> 2059 | G4: =HOTEL!O6 -> 661 | H4: =HOTEL!DL6 -> 0 | I4: =HOTEL!DN6 -> 0 | J4: =HOTEL!DP6 -> 0 | K4: =HOTEL!DR6 -> 0 | L4: =N4+W4+X4 -> 270 | M4: =HOTEL!AA6 -> 43 | N4: =HOTEL!AE6 -> 130 | O4: =HOTEL!AG6 -> 19 | P4: =HOTEL!AI6 -> 3 | Q4: =HOTEL!AK6 -> 3 | R4: =HOTEL!AM6 -> 1 | S4: =HOTEL!AO6 -> 5 | T4: =HOTEL!AQ6 -> 2 | U4: =HOTEL!AS6 -> 3 | V4: =HOTEL!AU6 -> 2 | W4: =HOTEL!BG6 -> 110 | X4: =HOTEL!BJ6 -> 30 | Y4: =HOTEL!CC6 -> 343.75 | Z4: =HOTEL!CF5 -> 50 | AA4: =HOTEL!CI6 -> 93.75 | AB4: =HOTEL!CL6 -> 25 | AC4: =HOTEL!CO6 -> 37.5 | AD4: =HOTEL!CR6 -> 56.25 | AE4: =HOTEL!CU6 -> 31.25 | AF4: =HOTEL!CX6 -> 5 | AG4: =HOTEL!DA6 -> 43.75 | AH4: =HOTEL!DD6 -> 31.25 | AI4: =HOTEL!DG6 -> 50 | AJ4: =HOTEL!DJ6 -> 43.75 | AK4: =TOTAL!K4 -> 79
A5: Mauritius at Anahita | B5: =B4+1 -> 4 | C5: 1 | D5: 2020 | E5: =TOTAL!E5 -> 28520 | F5: =HOTEL!M7 -> 1922 | G5: =HOTEL!O7 -> 606 | H5: =HOTEL!DL7 -> 0 | I5: =HOTEL!DN7 -> 0 | J5: =HOTEL!DP7 -> 6 | K5: =HOTEL!DR7 -> 0 | L5: =N5+W5+X5 -> 300 | M5: =HOTEL!AA7 -> 0 | N5: =HOTEL!AE7 -> 160 | O5: =HOTEL!AG7 -> 16 | P5: =HOTEL!AI7 -> 2 | Q5: =HOTEL!AK7 -> 4 | R5: =HOTEL!AM7 -> 3 | S5: =HOTEL!AO7 -> 7 | T5: =HOTEL!AQ7 -> 3 | U5: =HOTEL!AS7 -> 2 | V5: =HOTEL!AU7 -> 1 | W5: =HOTEL!BG7 -> 120 | X5: =HOTEL!BJ7 -> 20 | Y5: =HOTEL!CC7 -> 256.25 | Z5: =HOTEL!CF6 -> 0 | AA5: =HOTEL!CI7 -> 75 | AB5: =HOTEL!CL7 -> 25 | AC5: =HOTEL!CO7 -> 37.5 | AD5: =HOTEL!CR7 -> 56.25 | AE5: =HOTEL!CU7 -> 37.5 | AF5: =HOTEL!CX7 -> 6.25 | AG5: =HOTEL!DA7 -> 43.75 | AH5: =HOTEL!DD7 -> 25 | AI5: =HOTEL!DG7 -> 43.75 | AJ5: =HOTEL!DJ7 -> 37.5 | AK5: =TOTAL!K5 -> 85
A6: Mauritius at Anahita | B6: =B5+1 -> 5 | C6: 1 | D6: 2020 | E6: =TOTAL!E6 -> 27431 | F6: =HOTEL!M8 -> 2009 | G6: =HOTEL!O8 -> 583 | H6: =HOTEL!DL8 -> 0 | I6: =HOTEL!DN8 -> 0 | J6: =HOTEL!DP8 -> 0 | K6: =HOTEL!DR8 -> 171.9 | L6: =N6+W6+X6 -> 350 | M6: =HOTEL!AA8 -> 0 | N6: =HOTEL!AE8 -> 180 | O6: =HOTEL!AG8 -> 19 | P6: =HOTEL!AI8 -> 2 | Q6: =HOTEL!AK8 -> 5 | R6: =HOTEL!AM8 -> 5 | S6: =HOTEL!AO8 -> 6 | T6: =HOTEL!AQ8 -> 4 | U6: =HOTEL!AS8 -> 3 | V6: =HOTEL!AU8 -> 1 | W6: =HOTEL!BG8 -> 120 | X6: =HOTEL!BJ8 -> 50 | Y6: =HOTEL!CC8 -> 356.25 | Z6: =HOTEL!CF7 -> 50 | AA6: =HOTEL!CI8 -> 62.5 | AB6: =HOTEL!CL8 -> 25 | AC6: =HOTEL!CO8 -> 37.5 | AD6: =HOTEL!CR8 -> 50 | AE6: =HOTEL!CU8 -> 31.25 | AF6: =HOTEL!CX8 -> 5.625 | AG6: =HOTEL!DA8 -> 43.75 | AH6: =HOTEL!DD8 -> 37.5 | AI6: =HOTEL!DG8 -> 43.75 | AJ6: =HOTEL!DJ8 -> 43.75 | AK6: =TOTAL!K6 -> 77
A7: Mauritius at Anahita | B7: =B6+1 -> 6 | C7: 1 | D7: 2020 | E7: =TOTAL!E7 -> 27753 | F7: =HOTEL!M9 -> 587 | G7: =HOTEL!O9 -> 758 | H7: =HOTEL!DL9 -> 0 | I7: =HOTEL!DN9 -> 0 | J7: =HOTEL!DP9 -> 0 | K7: =HOTEL!DR9 -> 0 | L7: =N7+W7+X7 -> 310 | M7: =HOTEL!AA9 -> 0 | N7: =HOTEL!AE9 -> 160 | O7: =HOTEL!AG9 -> 15 | P7: =HOTEL!AI9 -> 2 | Q7: =HOTEL!AK9 -> 3 | R7: =HOTEL!AM9 -> 5 | S7: =HOTEL!AO9 -> 8 | T7: =HOTEL!AQ9 -> 3 | U7: =HOTEL!AS9 -> 2 | V7: =HOTEL!AU9 -> 0 | W7: =HOTEL!BG9 -> 110 | X7: =HOTEL!BJ9 -> 40 | Y7: =HOTEL!CC9 -> 325 | Z7: =HOTEL!CF8 -> 50 | AA7: =HOTEL!CI9 -> 125 | AB7: =HOTEL!CL9 -> 25 | AC7: =HOTEL!CO9 -> 43.75 | AD7: =HOTEL!CR9 -> 56.25 | AE7: =HOTEL!CU9 -> 37.5 | AF7: =HOTEL!CX9 -> 6.25 | AG7: =HOTEL!DA9 -> 43.75 | AH7: =HOTEL!DD9 -> 31.25 | AI7: =HOTEL!DG9 -> 43.75 | AJ7: =HOTEL!DJ9 -> 37.5 | AK7: =TOTAL!K7 -> 74
A8: Mauritius at Anahita | B8: =B7+1 -> 7 | C8: 1 | D8: 2020 | E8: =TOTAL!E8 -> 26949 | F8: =HOTEL!M10 -> 611 | G8: =HOTEL!O10 -> 631 | H8: =HOTEL!DL10 -> 0 | I8: =HOTEL!DN10 -> 0 | J8: =HOTEL!DP10 -> 0 | K8: =HOTEL!DR10 -> 0 | L8: =N8+W8+X8 -> 290 | M8: =HOTEL!AA10 -> 0 | N8: =HOTEL!AE10 -> 140 | O8: =HOTEL!AG10 -> 15 | P8: =HOTEL!AI10 -> 3 | Q8: =HOTEL!AK10 -> 4 | R8: =HOTEL!AM10 -> 5 | S8: =HOTEL!AO10 -> 6 | T8: =HOTEL!AQ10 -> 2 | U8: =HOTEL!AS10 -> 2 | V8: =HOTEL!AU10 -> 1 | W8: =HOTEL!BG10 -> 120 | X8: =HOTEL!BJ10 -> 30 | Y8: =HOTEL!CC10 -> 325 | Z8: =HOTEL!CF9 -> 50 | AA8: =HOTEL!CI10 -> 112.5 | AB8: =HOTEL!CL10 -> 31.25 | AC8: =HOTEL!CO10 -> 31.25 | AD8: =HOTEL!CR10 -> 56.25 | AE8: =HOTEL!CU10 -> 31.25 | AF8: =HOTEL!CX10 -> 7.5 | AG8: =HOTEL!DA10 -> 43.75 | AH8: =HOTEL!DD10 -> 31.25 | AI8: =HOTEL!DG10 -> 37.5 | AJ8: =HOTEL!DJ10 -> 37.5 | AK8: =TOTAL!K8 -> 74
A9: Mauritius at Anahita | B9: =B8+1 -> 8 | C9: 1 | D9: 2020 | E9: =TOTAL!E9 -> 27034 | F9: =HOTEL!M11 -> 635 | G9: =HOTEL!O11 -> 690 | H9: =HOTEL!DL11 -> 0 | I9: =HOTEL!DN11 -> 0 | J9: =HOTEL!DP11 -> 0 | K9: =HOTEL!DR11 -> 0 | L9: =N9+W9+X9 -> 320 | M9: =HOTEL!AA11 -> 65 | N9: =HOTEL!AE11 -> 120 | O9: =HOTEL!AG11 -> 15 | P9: =HOTEL!AI11 -> 2 | Q9: =HOTEL!AK11 -> 4 | R9: =HOTEL!AM11 -> 1 | S9: =HOTEL!AO11 -> 8 | T9: =HOTEL!AQ11 -> 3 | U9: =HOTEL!AS11 -> 1 | V9: =HOTEL!AU11 -> 1 | W9: =HOTEL!BG11 -> 170 | X9: =HOTEL!BJ11 -> 30 | Y9: =HOTEL!CC11 -> 362.5 | Z9: =HOTEL!CF10 -> 43.75 | AA9: =HOTEL!CI11 -> 106.25 | AB9: =HOTEL!CL11 -> 25 | AC9: =HOTEL!CO11 -> 37.5 | AD9: =HOTEL!CR11 -> 56.25 | AE9: =HOTEL!CU11 -> 31.25 | AF9: =HOTEL!CX11 -> 5 | AG9: =HOTEL!DA11 -> 31.25 | AH9: =HOTEL!DD11 -> 31.25 | AI9: =HOTEL!DG11 -> 31.25 | AJ9: =HOTEL!DJ11 -> 37.5 | AK9: =TOTAL!K9 -> 69
A10: Mauritius at Anahita | B10: =B9+1 -> 9 | C10: 1 | D10: 2020 | E10: =TOTAL!E10 -> 24570 | F10: =HOTEL!M12 -> 611 | G10: =HOTEL!O12 -> 568 | H10: =HOTEL!DL12 -> 0 | I10: =HOTEL!DN12 -> 0 | J10: =HOTEL!DP12 -> 0 | K10: =HOTEL!DR12 -> 0 | L10: =N10+W10+X10 -> 300 | M10: =HOTEL!AA12 -> 19 | N10: =HOTEL!AE12 -> 150 | O10: =HOTEL!AG12 -> 14 | P10: =HOTEL!AI12 -> 2 | Q10: =HOTEL!AK12 -> 3 | R10: =HOTEL!AM12 -> 5 | S10: =HOTEL!AO12 -> 7 | T10: =HOTEL!AQ12 -> 3 | U10: =HOTEL!AS12 -> 1 | V10: =HOTEL!AU12 -> 1 | W10: =HOTEL!BG12 -> 120 | X10: =HOTEL!BJ12 -> 30 | Y10: =HOTEL!CC12 -> 231.25 | Z10: =HOTEL!CF11 -> 0 | AA10: =HOTEL!CI12 -> 106.25 | AB10: =HOTEL!CL12 -> 31.25 | AC10: =HOTEL!CO12 -> 31.25 | AD10: =HOTEL!CR12 -> 56.25 | AE10: =HOTEL!CU12 -> 25 | AF10: =HOTEL!CX12 -> 4.375 | AG10: =HOTEL!DA12 -> 31.25 | AH10: =HOTEL!DD12 -> 31.25 | AI10: =HOTEL!DG12 -> 31.25 | AJ10: =HOTEL!DJ12 -> 31.25 | AK10: =TOTAL!K10 -> 68
A11: Mauritius at Anahita | B11: =B10+1 -> 10 | C11: 1 | D11: 2020 | E11: =TOTAL!E11 -> 25702 | F11: =HOTEL!M13 -> 508 | G11: =HOTEL!O13 -> 712 | H11: =HOTEL!DL13 -> 80 | I11: =HOTEL!DN13 -> 2531 | J11: =HOTEL!DP13 -> 0 | K11: =HOTEL!DR13 -> 0 | L11: =N11+W11+X11 -> 270 | M11: =HOTEL!AA13 -> 11 | N11: =HOTEL!AE13 -> 150 | O11: =HOTEL!AG13 -> 15 | P11: =HOTEL!AI13 -> 2 | Q11: =HOTEL!AK13 -> 2 | R11: =HOTEL!AM13 -> 3 | S11: =HOTEL!AO13 -> 6 | T11: =HOTEL!AQ13 -> 2 | U11: =HOTEL!AS13 -> 0 | V11: =HOTEL!AU13 -> 0 | W11: =HOTEL!BG13 -> 110 | X11: =HOTEL!BJ13 -> 10 | Y11: =HOTEL!CC13 -> 350 | Z11: =HOTEL!CF12 -> 50 | AA11: =HOTEL!CI13 -> 75 | AB11: =HOTEL!CL13 -> 25 | AC11: =HOTEL!CO13 -> 31.25 | AD11: =HOTEL!CR13 -> 50 | AE11: =HOTEL!CU13 -> 31.25 | AF11: =HOTEL!CX13 -> 7.5 | AG11: =HOTEL!DA13 -> 25 | AH11: =HOTEL!DD13 -> 31.25 | AI11: =HOTEL!DG13 -> 25 | AJ11: =HOTEL!DJ13 -> 31.25 | AK11: =TOTAL!K11 -> 62
A12: Mauritius at Anahita | B12: =B11+1 -> 11 | C12: 1 | D12: 2020 | E12: =TOTAL!E12 -> 25512 | F12: =HOTEL!M14 -> 722 | G12: =HOTEL!O14 -> 597 | H12: =HOTEL!DL14 -> 0 | I12: =HOTEL!DN14 -> 0 | J12: =HOTEL!DP14 -> 0 | K12: =HOTEL!DR14 -> 0 | L12: =N12+W12+X12 -> 300 | M12: =HOTEL!AA14 -> 11 | N12: =HOTEL!AE14 -> 150 | O12: =HOTEL!AG14 -> 16 | P12: =HOTEL!AI14 -> 2 | Q12: =HOTEL!AK14 -> 5 | R12: =HOTEL!AM14 -> 2 | S12: =HOTEL!AO14 -> 7 | T12: =HOTEL!AQ14 -> 2 | U12: =HOTEL!AS14 -> 1 | V12: =HOTEL!AU14 -> 1 | W12: =HOTEL!BG14 -> 120 | X12: =HOTEL!BJ14 -> 30 | Y12: =HOTEL!CC14 -> 350 | Z12: =HOTEL!CF13 -> 43.75 | AA12: =HOTEL!CI14 -> 131.25 | AB12: =HOTEL!CL14 -> 25 | AC12: =HOTEL!CO14 -> 37.5 | AD12: =HOTEL!CR14 -> 56.25 | AE12: =HOTEL!CU14 -> 25 | AF12: =HOTEL!CX14 -> 4.375 | AG12: =HOTEL!DA14 -> 56.25 | AH12: =HOTEL!DD14 -> 25 | AI12: =HOTEL!DG14 -> 0 | AJ12: =HOTEL!DJ14 -> 37.5 | AK12: =TOTAL!K12 -> 63
A13: Mauritius at Anahita | B13: =B12+1 -> 12 | C13: 1 | D13: 2020 | E13: =TOTAL!E13 -> 0 | F13: =HOTEL!M15 -> 0 | G13: =HOTEL!O15 -> 0 | H13: =HOTEL!DL15 -> 0 | I13: =HOTEL!DN15 -> 0 | J13: =HOTEL!DP15 -> 0 | K13: =HOTEL!DR15 -> 0 | L13: =N13+W13+X13 -> 0 | M13: =HOTEL!AA15 -> 0 | N13: =HOTEL!AE15 -> 0 | O13: =HOTEL!AG15 -> 0 | P13: =HOTEL!AI15 -> 0 | Q13: =HOTEL!AK15 -> 0 | R13: =HOTEL!AM15 -> 0 | S13: =HOTEL!AO15 -> 0 | T13: =HOTEL!AQ15 -> 0 | U13: =HOTEL!AS15 -> 0 | V13: =HOTEL!AU15 -> 0 | W13: =HOTEL!BG15 -> 0 | X13: =HOTEL!BJ15 -> 0 | Y13: =HOTEL!CC15 -> 0 | Z13: =HOTEL!CF14 -> 6.25 | AA13: =HOTEL!CI15 -> 0 | AB13: =HOTEL!CL15 -> 0 | AC13: =HOTEL!CO15 -> 0 | AD13: =HOTEL!CR15 -> 0 | AE13: =HOTEL!CU15 -> 0 | AF13: =HOTEL!CX15 -> 0 | AG13: =HOTEL!DA15 -> 0 | AH13: =HOTEL!DD15 -> 0 | AI13: =HOTEL!DG15 -> 0 | AJ13: =HOTEL!DJ15 -> 0 | AK13: =TOTAL!K13 -> 66
A14: Mauritius at Anahita | B14: =B13+1 -> 13 | C14: 1 | D14: 2020 | E14: =TOTAL!E14 -> 0 | F14: =HOTEL!M16 -> 0 | G14: =HOTEL!O16 -> 0 | H14: =HOTEL!DL16 -> 0 | I14: =HOTEL!DN16 -> 0 | J14: =HOTEL!DP16 -> 0 | K14: =HOTEL!DR16 -> 0 | L14: =N14+W14+X14 -> 0 | M14: =HOTEL!AA16 -> 0 | N14: =HOTEL!AE16 -> 0 | O14: =HOTEL!AG16 -> 0 | P14: =HOTEL!AI16 -> 0 | Q14: =HOTEL!AK16 -> 0 | R14: =HOTEL!AM16 -> 0 | S14: =HOTEL!AO16 -> 0 | T14: =HOTEL!AQ16 -> 0 | U14: =HOTEL!AS16 -> 0 | V14: =HOTEL!AU16 -> 0 | W14: =HOTEL!BG16 -> 0 | X14: =HOTEL!BJ16 -> 0 | Y14: =HOTEL!CC16 -> 0 | Z14: =HOTEL!CF15 -> 0 | AA14: =HOTEL!CI16 -> 0 | AB14: =HOTEL!CL16 -> 0 | AC14: =HOTEL!CO16 -> 0 | AD14: =HOTEL!CR16 -> 0 | AE14: =HOTEL!CU16 -> 0 | AF14: =HOTEL!CX16 -> 0 | AG14: =HOTEL!DA16 -> 0 | AH14: =HOTEL!DD16 -> 0 | AI14: =HOTEL!DG16 -> 0 | AJ14: =HOTEL!DJ16 -> 0 | AK14: =TOTAL!K14 -> 0
... A32: Mauritius at Anahita | B32: =B31+1 -> 31 | C32: 1 | D32: 2020 | E32: =TOTAL!E32 -> 0 | F32: =HOTEL!M34 -> 0 | G32: =HOTEL!O34 -> 0 | H32: =HOTEL!DL34 -> 0 | I32: =HOTEL!DN34 -> 0 | J32: =HOTEL!DP34 -> 0 | K32: =HOTEL!DR34 -> 0 | L32: =N32+W32+X32 -> 0 | M32: =HOTEL!AA34 -> 0 | N32: =HOTEL!AE34 -> 0 | O32: =HOTEL!AG34 -> 0 | P32: =HOTEL!AI34 -> 0 | Q32: =HOTEL!AK34 -> 0 | R32: =HOTEL!AM34 -> 0 | S32: =HOTEL!AO34 -> 0 | T32: =HOTEL!AQ34 -> 0 | U32: =HOTEL!AS34 -> 0 | V32: =HOTEL!AU34 -> 0 | W32: =HOTEL!BG34 -> 0 | X32: =HOTEL!BJ34 -> 0 | Y32: =HOTEL!CC34 -> 0 | Z32: =HOTEL!CF33 -> 0 | AA32: =HOTEL!CI34 -> 0 | AB32: =HOTEL!CL34 -> 0 | AC32: =HOTEL!CO34 -> 0 | AD32: =HOTEL!CR34 -> 0 | AE32: =HOTEL!CU34 -> 0 | AF32: =HOTEL!CX34 -> 0 | AG32: =HOTEL!DA34 -> 0 | AH32: =HOTEL!DD34 -> 0 | AI32: =HOTEL!DG34 -> 0 | AJ32: =HOTEL!DJ34 -> 0 | AK32: =TOTAL!K32 -> 0

Sheet HOTEL
B1: Hotel Electricity | H1: Gen 01 | J1: Gen 02 | L1: Vacoas KW | M1: CONS | N1: Laundry (KWh) | O1: CONS | P1: Hotel | R1: % Water Available | S1: water truck | V1: UV meter | X1: chiller | Z1: bamboo pool | AB1: laundry | AC1: CONS | AD1: Island | AF1: Main Building | AH1: Pantry A | AJ1: Pantry B | AL1: Pantry C | AN1: Pantry D | AP1: Pantry E | AR1: Pantry F | AT1: Pantry G | BF1: North | BH1: South | BK1: Diesel | BO1: Gas | CJ1: Steam Boiler | CM1: Main Building | CP1: Pantry A | CS1: Pantry B | CV1: Pantry C | CY1: Pantry D | DB1: Pantry E | DE1: Pantry F | DH1: Pantry G
A2: Date | B2: KVAH | C2: CONS | D2: KWH | E2: CONS | F2: PF | G2: KVA | P2: CWA23 | Q2: CONS | T2: Truck Meter | U2: Cons | V2: UV meter | W2: CONS | X2: chiller | Y2: CONS | AA2: CONS | AD2: island | AE2: cons | AF2: M.Buil | AG2: Cons | AH2: Pantry A | AI2: Cons | AJ2: Pantry B | AK2: Cons | AL2: Pantry C | AM2: cons | AN2: Pantry D | AO2: cons | AP2: Pantry E | AQ2: cons | AR2: Pantry F | AS2: Cons | AT2: Pantry G | AU2: Cons | AV2: Main Kitchen | AW2: Cons | AX2: Bamboo H | AY2: Cons | AZ2: Bamboo C | BA2: Cons | BB2: cyclon bridge | BC2: cons | BD2: Island - Hot | BE2: Island Cold | BF2: north | BG2: cons | BH2: south | BI2: cons | BJ2: south | BK2: DIESEL | BL2: stock | BM2: Del | BN2: CONS | BO2: Meter | BP2: cons | BQ2: Kg | BR2: LPG 1 | BS2: stock | BT2: LPG 2 | BU2: stock | BV2: LPG 3 | BW2: stock | BX2: total stock | BY2: cons | BZ2: del | CA2: Beau champ | CB2: cons(Litres) | CC2: Cons(Kg) | CD2: Acquapazza | CE2: cons(Litres) | CF2: Cons(Kg) | CG2: Bamboo | CH2: cons(Litres) | CI2: Cons(Kg) | CK2: cons(Litres) | CL2: Cons(Kg) | CN2: cons(Litres) | CO2: Cons(Kg) | CQ2: cons(Litres) | CR2: Cons(Kg) | CT2: cons(Litres) | CU2: Cons(Kg) | CW2: cons(Litres) | CX2: Cons(Kg) | CZ2: cons(Litres) | DA2: Cons(Kg) | DC2: cons(Litres) | DD2: Cons(Kg) | DF2: cons(Litres) | DG2: Cons(Kg) | DI2: cons(Litres) | DJ2: Cons(Kg) | DK2: 145 | DL2: CONS | DM2: 146 | DN2: CONS | DO2: Villa 111 | DP2: CONS | DQ2: Villa 128 | DR2: CONS | DS2: Room Nights | DT2: Bed Nights | DU2: % OCC
A3: 44227 | B3: 3309872 | C3: 29144 | D3: 2781572 | E3: 28273 | F3: 0.97011392 | G3: 1668 | H3: 749 | I3: 0 | J3: 965 | K3: 0 | L3: 2492958 | M3: 1136 | N3: 2155954 | O3: 662 | P3: 78197 | Q3: 166 | R3: 88 | S3: 8 | T3: 146127 | U3: 145 | V3: 32402 | W3: 90 | X3: 1018 | Y3: 1 | Z3: 3134 | AA3: 11 | AD3: 560540 | AE3: 120 | AF3: 51282 | AG3: 19 | AH3: 8721 | AI3: 3 | AJ3: 10330 | AK3: 2 | AL3: 14334 | AM3: 6 | AN3: 19110 | AO3: 7 | AP3: 19441 | AQ3: 0.1 | AR3: 13754 | AS3: 3 | AT3: 6107 | AU3: 3 | AV3: 25855 | AW3: 10 | AX3: 807 | AY3: 7 | AZ3: 3964 | BA3: 1 | BB3: 3636 | BC3: 0 | BD3: 9.1 | BE3: 110.9 | BF3: 585440 | BG3: 120 | BH3: 756080 | BI3: 150 | BJ3: 30 | BK3: 144 | BL3: 18518.168 | BN3: 0 | BO3: 198791 | BP3: 139 | BQ3: 868.75 | BR3: 74 | BS3: 7973.5 | BT3: 75 | BU3: 8081.25 | BV3: 75 | BW3: 8081.25 | BX3: 24136 | BY3: -6572.75 | CA3: 31672 | CB3: 52 | CC3: 325 | CD3: 34012 | CE3: 0 | CF3: 0 | CG3: 9487 | CH3: 11 | CI3: 68.75 | CJ3: 83028 | CK3: 5 | CL3: 31.25 | CM3: 5416 | CN3: 7 | CO3: 43.75 | CP3: 6488 | CQ3: 9 | CR3: 56.25 | CS3: 3182 | CT3: 5 | CU3: 31.25 | CV3: 1811.7 | CW3: 1 | CX3: 6.25 | CY3: 4674 | CZ3: 8 | DA3: 50 | DB3: 4219 | DC3: 5 | DD3: 31.25 | DE3: 4844 | DF3: 7 | DG3: 43.75 | DH3: 4106 | DI3: 7 | DJ3: 43.75 | DK3: 12382 | DL3: 0 | DM3: 52386 | DN3: 0 | DO3: 15518 | DP3: 0 | DQ3: 23468.4 | DR3: 0 | DS3: 74 | DT3: 195 | DU3: 0.65
A4: 44228 | B4: 3338798 | C4: =IF((B4-B3)<0,"0",(B4-B3)) -> 28926 | D4: 2809552 | E4: =IF((D4-D3)<0,"0",(D4-D3)) -> 27980 | F4: =E4/C4 -> 0.96729586 | G4: 1664 | H4: 749 | I4: 0 | J4: 965 | K4: 0 | L4: 2493662 | M4: =IF((L4-L3)<0,"0",(L4-L3)) -> 704 | N4: 2156566 | O4: =IF((N4-N3)<0,"0",(N4-N3)) -> 612 | P4: 78382 | Q4: =IF((P4-P3)<0,"0",(P4-P3)) -> 185 | R4: 88 | S4: 5 | T4: 146253 | U4: =IF((T4-T3)<0,"0",(T4-T3)) -> 126 | V4: 32489 | W4: =IF((V4-V3)<0,"0",(V4-V3)) -> 87 | X4: 1018 | Y4: =IF((X4-X3)<0,"0",(X4-X3)) -> 0 | Z4: 3145 | AA4: =IF((Z4-Z3)<0,"0",(Z4-Z3)) -> 11 | AD4: 560670 | AE4: =IF((AD4-AD3)<0,"0",(AD4-AD3)) -> 130 | AF4: 51296 | AG4: =IF((AF4-AF3)<0,"0",(AF4-AF3)) -> 14 | AH4: 8723 | AI4: =IF((AH4-AH3)<0,"0",(AH4-AH3)) -> 2 | AJ4: 10332 | AK4: =IF((AJ4-AJ3)<0,"0",(AJ4-AJ3)) -> 2 | AL4: 14341 | AM4: =IF((AL4-AL3)<0,"0",(AL4-AL3)) -> 7 | AN4: 19118 | AO4: =IF((AN4-AN3)<0,"0",(AN4-AN3)) -> 8 | AP4: 19443 | AQ4: =IF((AP4-AP3)<0,"0",(AP4-AP3)) -> 2 | AR4: 13758 | AS4: =IF((AR4-AR3)<0,"0",(AR4-AR3)) -> 4 | AT4: 6111 | AU4: =IF((AT4-AT3)<0,"0",(AT4-AT3)) -> 4 | AV4: 25865 | AW4: =IF((AV4-AV3)<0,"0",(AV4-AV3)) -> 10 | AX4: 812.9 | AY4: =IF((AX4-AX3)<0,"0",(AX4-AX3)) -> 5.9 | AZ4: 3976 | BA4: =IF((AZ4-AZ3)<0,"0",(AZ4-AZ3)) -> 12 | BB4: 3636 | BC4: =IF((BB4-BB3)<0,"0",(BB4-BB3)) -> 0 | BD4: =AS4+AQ4+AM4 -> 13 | BE4: =AE4-BD4 -> 117 | BF4: 585550 | BG4: =IF((BF4-BF3)<0,"0",(BF4-BF3)) -> 110 | BH4: 756240 | BI4: =IF((BH4-BH3)<0,"0",(BH4-BH3)) -> 160 | BJ4: =IF((BI4-AE4)<0,"0",(BI4-AE4)) -> 30 | BK4: 144 | BL4: =(IF(BK4<=116.4,((116.4*116.4*ACOS((116.4-BK4)/116.4))-((116.4-BK4)*SQRT(2*116.4*BK4-BK4*BK4)))*669.8,((3.1416*116.4*116.4)-((116.4*116.4*ACOS((116.4-(2*116.4-BK4))/116.4))-((116.4-(2*116.4-BK4))*SQRT(2*116.4*(2*116.4-BK4)-((2*116.4-BK4)*(2*116.4-BK4))))))*669.8))/1000 -> 18518.168 | BN4: =IF((BL3-BL4)<0,"0",(BL3-BL4)) -> 0 | BO4: 198947 | BP4: =IF((BO4-BO3)<0,"0",(BO4-BO3)) -> 156 | BQ4: =BP4*6.25 -> 975 | BR4: 70 | BS4: =(BR4*10775)/100 -> 7542.5 | BT4: 72 | BU4: =(BT4*10775)/100 -> 7758 | BV4: 72 | BW4: =(BV4*10775)/100 -> 7758 | BX4: =BS4+BU4+BW4 -> 23058.5 | BY4: =IF((BX3-BX4+BZ3)=BX3,"0",(BX3-BX4+BZ3)) -> 1077.5 | CA4: 31727 | CB4: =IF((CA4-CA3)<0,"0",(CA4-CA3)) -> 55 | CC4: =CB4*6.25 -> 343.75 | CD4: 34029 | CE4: =IF((CD4-CD3)<0,"0",(CD4-CD3)) -> 17 | CF4: =CE4*6.25 -> 106.25 | CG4: 9504 | CH4: =IF((CG4-CG3)<0,"0",(CG4-CG3)) -> 17 | CI4: =CH4*6.25 -> 106.25 | CJ4: 83033 | CK4: =IF((CJ4-CJ3)<0,"0",(CJ4-CJ3)) -> 5 | CL4: =CK4*6.25 -> 31.25 | CM4: 5421 | CN4: =IF((CM4-CM3)<0,"0",(CM4-CM3)) -> 5 | CO4: =CN4*6.25 -> 31.25 | CP4: 6499 | CQ4: =IF((CP4-CP3)<0,"0",(CP4-CP3)) -> 11 | CR4: =CQ4*6.25 -> 68.75 | CS4: 3187 | CT4: =IF((CS4-CS3)<0,"0",(CS4-CS3)) -> 5 | CU4: =CT4*6.25 -> 31.25 | CV4: 1812.7 | CW4: =IF((CV4-CV3)<0,"0",(CV4-CV3)) -> 1 | CX4: =CW4*6.25 -> 6.25 | CY4: 4680 | CZ4: =IF((CY4-CY3)<0,"0",(CY4-CY3)) -> 6 | DA4: =CZ4*6.25 -> 37.5 | DB4: 4223 | DC4: =IF((DB4-DB3)<0,"0",(DB4-DB3)) -> 4 | DD4: =DC4*6.25 -> 25 | DE4: 4851 | DF4: =IF((DE4-DE3)<0,"0",(DE4-DE3)) -> 7 | DG4: =DF4*6.25 -> 43.75 | DH4: 4113 | DI4: =IF((DH4-DH3)<0,"0",(DH4-DH3)) -> 7 | DJ4: =DI4*6.25 -> 43.75 | DK4: 12382 | DL4: =IF((DK4-DK3)<0,"0",(DK4-DK3)) -> 0 | DM4: 52386 | DN4: =IF((DM4-DM3)<0,"0",(DM4-DM3)) -> 0 | DO4: 15518 | DP4: =IF((DO4-DO3)<0,"0",(DO4-DO3)) -> 0 | DQ4: 23468.4 | DR4: =IF((DQ4-DQ3)<0,"0",(DQ4-DQ3)) -> 0 | DS4: 87 | DT4: 209 | DU4: 0.65
A5: 44229 | B5: 3368392 | C5: =IF((B5-B4)<0,"0",(B5-B4)) -> 29594 | D5: 2838127 | E5: =IF((D5-D4)<0,"0",(D5-D4)) -> 28575 | F5: =E5/C5 -> 0.96556734 | G5: 1664 | H5: 749 | I5: 0 | J5: 965 | K5: 0 | L5: 2494478 | M5: =IF((L5-L4)<0,"0",(L5-L4)) -> 816 | N5: 2157183 | O5: =IF((N5-N4)<0,"0",(N5-N4)) -> 617 | P5: 78540 | Q5: =IF((P5-P4)<0,"0",(P5-P4)) -> 158 | R5: 83 | S5: 3 | T5: 146307 | U5: =IF((T5-T4)<0,"0",(T5-T4)) -> 54 | V5: 32579 | W5: =IF((V5-V4)<0,"0",(V5-V4)) -> 90 | X5: 1018 | Y5: =IF((X5-X4)<0,"0",(X5-X4)) -> 0 | Z5: 3145 | AA5: =IF((Z5-Z4)<0,"0",(Z5-Z4)) -> 0 | AD5: 560810 | AE5: =IF((AD5-AD4)<0,"0",(AD5-AD4)) -> 140 | AF5: 51311 | AG5: =IF((AF5-AF4)<0,"0",(AF5-AF4)) -> 15 | AH5: 8725 | AI5: =IF((AH5-AH4)<0,"0",(AH5-AH4)) -> 2 | AJ5: 10335 | AK5: =IF((AJ5-AJ4)<0,"0",(AJ5-AJ4)) -> 3 | AL5: 14345 | AM5: =IF((AL5-AL4)<0,"0",(AL5-AL4)) -> 4 | AN5: 19123 | AO5: =IF((AN5-AN4)<0,"0",(AN5-AN4)) -> 5 | AP5: 19445 | AQ5: =IF((AP5-AP4)<0,"0",(AP5-AP4)) -> 2 | AR5: 13761 | AS5: =IF((AR5-AR4)<0,"0",(AR5-AR4)) -> 3 | AT5: 6114 | AU5: =IF((AT5-AT4)<0,"0",(AT5-AT4)) -> 3 | AV5: 25875 | AW5: =IF((AV5-AV4)<0,"0",(AV5-AV4)) -> 10 | AX5: 819.2 | AY5: =IF((AX5-AX4)<0,"0",(AX5-AX4)) -> 6.3 | AZ5: 3982 | BA5: =IF((AZ5-AZ4)<0,"0",(AZ5-AZ4)) -> 6 | BB5: 3636 | BC5: =IF((BB5-BB4)<0,"0",(BB5-BB4)) -> 0 | BD5: =AS5+AQ5+AM5 -> 9 | BE5: =AE5-BD5 -> 131 | BF5: 585670 | BG5: =IF((BF5-BF4)<0,"0",(BF5-BF4)) -> 120 | BH5: 756410 | BI5: =IF((BH5-BH4)<0,"0",(BH5-BH4)) -> 170 | BJ5: =IF((BI5-AE5)<0,"0",(BI5-AE5)) -> 30 | BK5: 144 | BL5: =(IF(BK5<=116.4,((116.4*116.4*ACOS((116.4-BK5)/116.4))-((116.4-BK5)*SQRT(2*116.4*BK5-BK5*BK5)))*669.8,((3.1416*116.4*116.4)-((116.4*116.4*ACOS((116.4-(2*116.4-BK5))/116.4))-((116.4-(2*116.4-BK5))*SQRT(2*116.4*(2*116.4-BK5)-((2*116.4-BK5)*(2*116.4-BK5))))))*669.8))/1000 -> 18518.168 | BN5: =IF((BL4-BL5)<0,"0",(BL4-BL5)) -> 0 | BO5: 199079 | BP5: =IF((BO5-BO4)<0,"0",(BO5-BO4)) -> 132 | BQ5: =BP5*6.25 -> 825 | BR5: 65 | BS5: =(BR5*10775)/100 -> 7003.75 | BT5: 70 | BU5: =(BT5*10775)/100 -> 7542.5 | BV5: 70 | BW5: =(BV5*10775)/100 -> 7542.5 | BX5: =BS5+BU5+BW5 -> 22088.75 | BY5: =IF((BX4-BX5+BZ4)=BX4,"0",(BX4-BX5+BZ4)) -> 969.75 | CA5: 31784 | CB5: =IF((CA5-CA4)<0,"0",(CA5-CA4)) -> 57 | CC5: =CB5*6.25 -> 356.25 | CD5: 34037 | CE5: =IF((CD5-CD4)<0,"0",(CD5-CD4)) -> 8 | CF5: =CE5*6.25 -> 50 | CG5: 9514 | CH5: =IF((CG5-CG4)<0,"0",(CG5-CG4)) -> 10 | CI5: =CH5*6.25 -> 62.5 | CJ5: 83037 | CK5: =IF((CJ5-CJ4)<0,"0",(CJ5-CJ4)) -> 4 | CL5: =CK5*6.25 -> 25 | CM5: 5426 | CN5: =IF((CM5-CM4)<0,"0",(CM5-CM4)) -> 5 | CO5: =CN5*6.25 -> 31.25 | CP5: 6507 | CQ5: =IF((CP5-CP4)<0,"0",(CP5-CP4)) -> 8 | CR5: =CQ5*6.25 -> 50 | CS5: 3192 | CT5: =IF((CS5-CS4)<0,"0",(CS5-CS4)) -> 5 | CU5: =CT5*6.25 -> 31.25 | CV5: 1813.7 | CW5: =IF((CV5-CV4)<0,"0",(CV5-CV4)) -> 1 | CX5: =CW5*6.25 -> 6.25 | CY5: 4687 | CZ5: =IF((CY5-CY4)<0,"0",(CY5-CY4)) -> 7 | DA5: =CZ5*6.25 -> 43.75 | DB5: 4228 | DC5: =IF((DB5-DB4)<0,"0",(DB5-DB4)) -> 5 | DD5: =DC5*6.25 -> 31.25 | DE5: 4858 | DF5: =IF((DE5-DE4)<0,"0",(DE5-DE4)) -> 7 | DG5: =DF5*6.25 -> 43.75 | DH5: 4121 | DI5: =IF((DH5-DH4)<0,"0",(DH5-DH4)) -> 8 | DJ5: =DI5*6.25 -> 50 | DK5: 12382 | DL5: =IF((DK5-DK4)<0,"0",(DK5-DK4)) -> 0 | DM5: 52386 | DN5: =IF((DM5-DM4)<0,"0",(DM5-DM4)) -> 0 | DO5: 15518 | DP5: =IF((DO5-DO4)<0,"0",(DO5-DO4)) -> 0 | DQ5: 23468.4 | DR5: =IF((DQ5-DQ4)<0,"0",(DQ5-DQ4)) -> 0 | DS5: 74 | DT5: 169 | DU5: 0.56
A6: 44230 | B6: 3399343 | C6: =IF((B6-B5)<0,"0",(B6-B5)) -> 30951 | D6: 2868009 | E6: =IF((D6-D5)<0,"0",(D6-D5)) -> 29882 | F6: =E6/C6 -> 0.96546154 | G6: 1664 | H6: 749 | I6: 0 | J6: 965 | K6: 0 | L6: 2496537 | M6: =IF((L6-L5)<0,"0",(L6-L5)) -> 2059 | N6: 2157844 | O6: =IF((N6-N5)<0,"0",(N6-N5)) -> 661 | P6: 78650 | Q6: =IF((P6-P5)<0,"0",(P6-P5)) -> 110 | R6: 66 | S6: 0 | T6: 146331 | U6: =IF((T6-T5)<0,"0",(T6-T5)) -> 24 | V6: 32670 | W6: =IF((V6-V5)<0,"0",(V6-V5)) -> 91 | X6: 1018 | Y6: =IF((X6-X5)<0,"0",(X6-X5)) -> 0 | Z6: 3188 | AA6: =IF((Z6-Z5)<0,"0",(Z6-Z5)) -> 43 | AD6: 560940 | AE6: =IF((AD6-AD5)<0,"0",(AD6-AD5)) -> 130 | AF6: 51330 | AG6: =IF((AF6-AF5)<0,"0",(AF6-AF5)) -> 19 | AH6: 8728 | AI6: =IF((AH6-AH5)<0,"0",(AH6-AH5)) -> 3 | AJ6: 10338 | AK6: =IF((AJ6-AJ5)<0,"0",(AJ6-AJ5)) -> 3 | AL6: 14346 | AM6: =IF((AL6-AL5)<0,"0",(AL6-AL5)) -> 1 | AN6: 19128 | AO6: =IF((AN6-AN5)<0,"0",(AN6-AN5)) -> 5 | AP6: 19447 | AQ6: =IF((AP6-AP5)<0,"0",(AP6-AP5)) -> 2 | AR6: 13764 | AS6: =IF((AR6-AR5)<0,"0",(AR6-AR5)) -> 3 | AT6: 6116 | AU6: =IF((AT6-AT5)<0,"0",(AT6-AT5)) -> 2 | AV6: 25888 | AW6: =IF((AV6-AV5)<0,"0",(AV6-AV5)) -> 13 | AX6: 825.7 | AY6: =IF((AX6-AX5)<0,"0",(AX6-AX5)) -> 6.5 | AZ6: 3990 | BA6: =IF((AZ6-AZ5)<0,"0",(AZ6-AZ5)) -> 8 | BB6: 3636 | BC6: =IF((BB6-BB5)<0,"0",(BB6-BB5)) -> 0 | BD6: =AS6+AQ6+AM6 -> 6 | BE6: =AE6-BD6 -> 124 | BF6: 585780 | BG6: =IF((BF6-BF5)<0,"0",(BF6-BF5)) -> 110 | BH6: 756570 | BI6: =IF((BH6-BH5)<0,"0",(BH6-BH5)) -> 160 | BJ6: =IF((BI6-AE6)<0,"0",(BI6-AE6)) -> 30 | BK6: 144 | BL6: =(IF(BK6<=116.4,((116.4*116.4*ACOS((116.4-BK6)/116.4))-((116.4-BK6)*SQRT(2*116.4*BK6-BK6*BK6)))*669.8,((3.1416*116.4*116.4)-((116.4*116.4*ACOS((116.4-(2*116.4-BK6))/116.4))-((116.4-(2*116.4-BK6))*SQRT(2*116.4*(2*116.4-BK6)-((2*116.4-BK6)*(2*116.4-BK6))))))*669.8))/1000 -> 18518.168 | BN6: =IF((BL5-BL6)<0,"0",(BL5-BL6)) -> 0 | BO6: 199205 | BP6: =IF((BO6-BO5)<0,"0",(BO6-BO5)) -> 126 | BQ6: =BP6*6.25 -> 787.5 | BR6: 65 | BS6: =(BR6*10775)/100 -> 7003.75 | BT6: 70 | BU6: =(BT6*10775)/100 -> 7542.5 | BV6: 65 | BW6: =(BV6*10775)/100 -> 7003.75 | BX6: =BS6+BU6+BW6 -> 21550 | BY6: =IF((BX5-BX6+BZ5)=BX5,"0",(BX5-BX6+BZ5)) -> 538.75 | CA6: 31839 | CB6: =IF((CA6-CA5)<0,"0",(CA6-CA5)) -> 55 | CC6: =CB6*6.25 -> 343.75 | CD6: 34037 | CE6: =IF((CD6-CD5)<0,"0",(CD6-CD5)) -> 0 | CF6: =CE6*6.25 -> 0 | CG6: 9529 | CH6: =IF((CG6-CG5)<0,"0",(CG6-CG5)) -> 15 | CI6: =CH6*6.25 -> 93.75 | CJ6: 83041 | CK6: =IF((CJ6-CJ5)<0,"0",(CJ6-CJ5)) -> 4 | CL6: =CK6*6.25 -> 25 | CM6: 5432 | CN6: =IF((CM6-CM5)<0,"0",(CM6-CM5)) -> 6 | CO6: =CN6*6.25 -> 37.5 | CP6: 6516 | CQ6: =IF((CP6-CP5)<0,"0",(CP6-CP5)) -> 9 | CR6: =CQ6*6.25 -> 56.25 | CS6: 3197 | CT6: =IF((CS6-CS5)<0,"0",(CS6-CS5)) -> 5 | CU6: =CT6*6.25 -> 31.25 | CV6: 1814.5 | CW6: =IF((CV6-CV5)<0,"0",(CV6-CV5)) -> 0.8 | CX6: =CW6*6.25 -> 5 | CY6: 4694 | CZ6: =IF((CY6-CY5)<0,"0",(CY6-CY5)) -> 7 | DA6: =CZ6*6.25 -> 43.75 | DB6: 4233 | DC6: =IF((DB6-DB5)<0,"0",(DB6-DB5)) -> 5 | DD6: =DC6*6.25 -> 31.25 | DE6: 4866 | DF6: =IF((DE6-DE5)<0,"0",(DE6-DE5)) -> 8 | DG6: =DF6*6.25 -> 50 | DH6: 4128 | DI6: =IF((DH6-DH5)<0,"0",(DH6-DH5)) -> 7 | DJ6: =DI6*6.25 -> 43.75 | DK6: 12382 | DL6: =IF((DK6-DK5)<0,"0",(DK6-DK5)) -> 0 | DM6: 52386 | DN6: =IF((DM6-DM5)<0,"0",(DM6-DM5)) -> 0 | DO6: 15518 | DP6: =IF((DO6-DO5)<0,"0",(DO6-DO5)) -> 0 | DQ6: 23468.4 | DR6: =IF((DQ6-DQ5)<0,"0",(DQ6-DQ5)) -> 0 | DS6: 79 | DT6: 181 | DU6: 0.59
A7: 44231 | B7: 3428739 | C7: =IF((B7-B6)<0,"0",(B7-B6)) -> 29396 | D7: 2896529 | E7: =IF((D7-D6)<0,"0",(D7-D6)) -> 28520 | F7: =E7/C7 -> 0.97020003 | G7: 1664 | H7: 749 | I7: 0 | J7: 965 | K7: 0 | L7: 2498459 | M7: =IF((L7-L6)<0,"0",(L7-L6)) -> 1922 | N7: 2158450 | O7: =IF((N7-N6)<0,"0",(N7-N6)) -> 606 | P7: 78760 | Q7: =IF((P7-P6)<0,"0",(P7-P6)) -> 110 | R7: 83 | S7: 8 | T7: 146559 | U7: =IF((T7-T6)<0,"0",(T7-T6)) -> 228 | V7: 32760 | W7: =IF((V7-V6)<0,"0",(V7-V6)) -> 90 | X7: 1018 | Y7: =IF((X7-X6)<0,"0",(X7-X6)) -> 0 | Z7: 3188 | AA7: =IF((Z7-Z6)<0,"0",(Z7-Z6)) -> 0 | AD7: 561100 | AE7: =IF((AD7-AD6)<0,"0",(AD7-AD6)) -> 160 | AF7: 51346 | AG7: =IF((AF7-AF6)<0,"0",(AF7-AF6)) -> 16 | AH7: 8730 | AI7: =IF((AH7-AH6)<0,"0",(AH7-AH6)) -> 2 | AJ7: 10342 | AK7: =IF((AJ7-AJ6)<0,"0",(AJ7-AJ6)) -> 4 | AL7: 14349 | AM7: =IF((AL7-AL6)<0,"0",(AL7-AL6)) -> 3 | AN7: 19135 | AO7: =IF((AN7-AN6)<0,"0",(AN7-AN6)) -> 7 | AP7: 19450 | AQ7: =IF((AP7-AP6)<0,"0",(AP7-AP6)) -> 3 | AR7: 13766 | AS7: =IF((AR7-AR6)<0,"0",(AR7-AR6)) -> 2 | AT7: 6117 | AU7: =IF((AT7-AT6)<0,"0",(AT7-AT6)) -> 1 | AV7: 25899 | AW7: =IF((AV7-AV6)<0,"0",(AV7-AV6)) -> 11 | AX7: 832.7 | AY7: =IF((AX7-AX6)<0,"0",(AX7-AX6)) -> 7 | AZ7: 4000 | BA7: =IF((AZ7-AZ6)<0,"0",(AZ7-AZ6)) -> 10 | BB7: 3636 | BC7: =IF((BB7-BB6)<0,"0",(BB7-BB6)) -> 0 | BD7: =AS7+AQ7+AM7 -> 8 | BE7: =AE7-BD7 -> 152 | BF7: 585900 | BG7: =IF((BF7-BF6)<0,"0",(BF7-BF6)) -> 120 | BH7: 756750 | BI7: =IF((BH7-BH6)<0,"0",(BH7-BH6)) -> 180 | BJ7: =IF((BI7-AE7)<0,"0",(BI7-AE7)) -> 20 | BK7: 144 | BL7: =(IF(BK7<=116.4,((116.4*116.4*ACOS((116.4-BK7)/116.4))-((116.4-BK7)*SQRT(2*116.4*BK7-BK7*BK7)))*669.8,((3.1416*116.4*116.4)-((116.4*116.4*ACOS((116.4-(2*116.4-BK7))/116.4))-((116.4-(2*116.4-BK7))*SQRT(2*116.4*(2*116.4-BK7)-((2*116.4-BK7)*(2*116.4-BK7))))))*669.8))/1000 -> 18518.168 | BN7: =IF((BL6-BL7)<0,"0",(BL6-BL7)) -> 0 | BO7: 199330 | BP7: =IF((BO7-BO6)<0,"0",(BO7-BO6)) -> 125 | BQ7: =BP7*6.25 -> 781.25 | BR7: 60 | BS7: =(BR7*10775)/100 -> 6465 | BT7: 65 | BU7: =(BT7*10775)/100 -> 7003.75 | BV7: 65 | BW7: =(BV7*10775)/100 -> 7003.75 | BX7: =BS7+BU7+BW7 -> 20472.5 | BY7: =IF((BX6-BX7+BZ6)=BX6,"0",(BX6-BX7+BZ6)) -> 1077.5 | CA7: 31880 | CB7: =IF((CA7-CA6)<0,"0",(CA7-CA6)) -> 41 | CC7: =CB7*6.25 -> 256.25 | CD7: 34045 | CE7: =IF((CD7-CD6)<0,"0",(CD7-CD6)) -> 8 | CF7: =CE7*6.25 -> 50 | CG7: 9541 | CH7: =IF((CG7-CG6)<0,"0",(CG7-CG6)) -> 12 | CI7: =CH7*6.25 -> 75 | CJ7: 83045 | CK7: =IF((CJ7-CJ6)<0,"0",(CJ7-CJ6)) -> 4 | CL7: =CK7*6.25 -> 25 | CM7: 5438 | CN7: =IF((CM7-CM6)<0,"0",(CM7-CM6)) -> 6 | CO7: =CN7*6.25 -> 37.5 | CP7: 6525 | CQ7: =IF((CP7-CP6)<0,"0",(CP7-CP6)) -> 9 | CR7: =CQ7*6.25 -> 56.25 | CS7: 3203 | CT7: =IF((CS7-CS6)<0,"0",(CS7-CS6)) -> 6 | CU7: =CT7*6.25 -> 37.5 | CV7: 1815.5 | CW7: =IF((CV7-CV6)<0,"0",(CV7-CV6)) -> 1 | CX7: =CW7*6.25 -> 6.25 | CY7: 4701 | CZ7: =IF((CY7-CY6)<0,"0",(CY7-CY6)) -> 7 | DA7: =CZ7*6.25 -> 43.75 | DB7: 4237 | DC7: =IF((DB7-DB6)<0,"0",(DB7-DB6)) -> 4 | DD7: =DC7*6.25 -> 25 | DE7: 4873 | DF7: =IF((DE7-DE6)<0,"0",(DE7-DE6)) -> 7 | DG7: =DF7*6.25 -> 43.75 | DH7: 4134 | DI7: =IF((DH7-DH6)<0,"0",(DH7-DH6)) -> 6 | DJ7: =DI7*6.25 -> 37.5 | DK7: 12382 | DL7: =IF((DK7-DK6)<0,"0",(DK7-DK6)) -> 0 | DM7: 52386 | DN7: =IF((DM7-DM6)<0,"0",(DM7-DM6)) -> 0 | DO7: 15524 | DP7: =IF((DO7-DO6)<0,"0",(DO7-DO6)) -> 6 | DQ7: 23468.4 | DR7: =IF((DQ7-DQ6)<0,"0",(DQ7-DQ6)) -> 0 | DS7: 85 | DT7: 199 | DU7: 0.64
A8: 44232 | B8: 3457027 | C8: =IF((B8-B7)<0,"0",(B8-B7)) -> 28288 | D8: 2923960 | E8: =IF((D8-D7)<0,"0",(D8-D7)) -> 27431 | F8: =E8/C8 -> 0.96970447 | G8: 1664 | H8: 749 | I8: 0 | J8: 965 | K8: 0 | L8: 2500468 | M8: =IF((L8-L7)<0,"0",(L8-L7)) -> 2009 | N8: 2159033 | O8: =IF((N8-N7)<0,"0",(N8-N7)) -> 583 | P8: 78887 | Q8: =IF((P8-P7)<0,"0",(P8-P7)) -> 127 | R8: 77 | S8: 6 | T8: 146721 | U8: =IF((T8-T7)<0,"0",(T8-T7)) -> 162 | V8: 32856 | W8: =IF((V8-V7)<0,"0",(V8-V7)) -> 96 | X8: 1018 | Y8: =IF((X8-X7)<0,"0",(X8-X7)) -> 0 | Z8: 3188 | AA8: =IF((Z8-Z7)<0,"0",(Z8-Z7)) -> 0 | AD8: 561280 | AE8: =IF((AD8-AD7)<0,"0",(AD8-AD7)) -> 180 | AF8: 51365 | AG8: =IF((AF8-AF7)<0,"0",(AF8-AF7)) -> 19 | AH8: 8732 | AI8: =IF((AH8-AH7)<0,"0",(AH8-AH7)) -> 2 | AJ8: 10347 | AK8: =IF((AJ8-AJ7)<0,"0",(AJ8-AJ7)) -> 5 | AL8: 14354 | AM8: =IF((AL8-AL7)<0,"0",(AL8-AL7)) -> 5 | AN8: 19141 | AO8: =IF((AN8-AN7)<0,"0",(AN8-AN7)) -> 6 | AP8: 19454 | AQ8: =IF((AP8-AP7)<0,"0",(AP8-AP7)) -> 4 | AR8: 13769 | AS8: =IF((AR8-AR7)<0,"0",(AR8-AR7)) -> 3 | AT8: 6118 | AU8: =IF((AT8-AT7)<0,"0",(AT8-AT7)) -> 1 | AV8: 25910 | AW8: =IF((AV8-AV7)<0,"0",(AV8-AV7)) -> 11 | AX8: 838.7 | AY8: =IF((AX8-AX7)<0,"0",(AX8-AX7)) -> 6 | AZ8: 4005 | BA8: =IF((AZ8-AZ7)<0,"0",(AZ8-AZ7)) -> 5 | BB8: 3636 | BC8: =IF((BB8-BB7)<0,"0",(BB8-BB7)) -> 0 | BD8: =AS8+AQ8+AM8 -> 12 | BE8: =AE8-BD8 -> 168 | BF8: 586020 | BG8: =IF((BF8-BF7)<0,"0",(BF8-BF7)) -> 120 | BH8: 756980 | BI8: =IF((BH8-BH7)<0,"0",(BH8-BH7)) -> 230 | BJ8: =IF((BI8-AE8)<0,"0",(BI8-AE8)) -> 50 | BK8: 144 | BL8: =(IF(BK8<=116.4,((116.4*116.4*ACOS((116.4-BK8)/116.4))-((116.4-BK8)*SQRT(2*116.4*BK8-BK8*BK8)))*669.8,((3.1416*116.4*116.4)-((116.4*116.4*ACOS((116.4-(2*116.4-BK8))/116.4))-((116.4-(2*116.4-BK8))*SQRT(2*116.4*(2*116.4-BK8)-((2*116.4-BK8)*(2*116.4-BK8))))))*669.8))/1000 -> 18518.168 | BN8: =IF((BL7-BL8)<0,"0",(BL7-BL8)) -> 0 | BO8: 199461 | BP8: =IF((BO8-BO7)<0,"0",(BO8-BO7)) -> 131 | BQ8: =BP8*6.25 -> 818.75 | BR8: 60 | BS8: =(BR8*10775)/100 -> 6465 | BT8: 60 | BU8: =(BT8*10775)/100 -> 6465 | BV8: 60 | BW8: =(BV8*10775)/100 -> 6465 | BX8: =BS8+BU8+BW8 -> 19395 | BY8: =IF((BX7-BX8+BZ7)=BX7,"0",(BX7-BX8+BZ7)) -> 1077.5 | CA8: 31937 | CB8: =IF((CA8-CA7)<0,"0",(CA8-CA7)) -> 57 | CC8: =CB8*6.25 -> 356.25 | CD8: 34053 | CE8: =IF((CD8-CD7)<0,"0",(CD8-CD7)) -> 8 | CF8: =CE8*6.25 -> 50 | CG8: 9551 | CH8: =IF((CG8-CG7)<0,"0",(CG8-CG7)) -> 10 | CI8: =CH8*6.25 -> 62.5 | CJ8: 83049 | CK8: =IF((CJ8-CJ7)<0,"0",(CJ8-CJ7)) -> 4 | CL8: =CK8*6.25 -> 25 | CM8: 5444 | CN8: =IF((CM8-CM7)<0,"0",(CM8-CM7)) -> 6 | CO8: =CN8*6.25 -> 37.5 | CP8: 6533 | CQ8: =IF((CP8-CP7)<0,"0",(CP8-CP7)) -> 8 | CR8: =CQ8*6.25 -> 50 | CS8: 3208 | CT8: =IF((CS8-CS7)<0,"0",(CS8-CS7)) -> 5 | CU8: =CT8*6.25 -> 31.25 | CV8: 1816.4 | CW8: =IF((CV8-CV7)<0,"0",(CV8-CV7)) -> 0.9 | CX8: =CW8*6.25 -> 5.625 | CY8: 4708 | CZ8: =IF((CY8-CY7)<0,"0",(CY8-CY7)) -> 7 | DA8: =CZ8*6.25 -> 43.75 | DB8: 4243 | DC8: =IF((DB8-DB7)<0,"0",(DB8-DB7)) -> 6 | DD8: =DC8*6.25 -> 37.5 | DE8: 4880 | DF8: =IF((DE8-DE7)<0,"0",(DE8-DE7)) -> 7 | DG8: =DF8*6.25 -> 43.75 | DH8: 4141 | DI8: =IF((DH8-DH7)<0,"0",(DH8-DH7)) -> 7 | DJ8: =DI8*6.25 -> 43.75 | DK8: 12382 | DL8: =IF((DK8-DK7)<0,"0",(DK8-DK7)) -> 0 | DM8: 52386 | DN8: =IF((DM8-DM7)<0,"0",(DM8-DM7)) -> 0 | DO8: 15524 | DP8: =IF((DO8-DO7)<0,"0",(DO8-DO7)) -> 0 | DQ8: 23640.3 | DR8: =IF((DQ8-DQ7)<0,"0",(DQ8-DQ7)) -> 171.9 | DS8: 77 | DT8: 182 | DU8: 0.58
A9: 44233 | B9: 3485667 | C9: =IF((B9-B8)<0,"0",(B9-B8)) -> 28640 | D9: 2951713 | E9: =IF((D9-D8)<0,"0",(D9-D8)) -> 27753 | F9: =E9/C10 -> 0.96902933 | G9: 1664 | H9: 749 | I9: 0 | J9: 965 | K9: 0 | L9: 2501055 | M9: =IF((L9-L8)<0,"0",(L9-L8)) -> 587 | N9: 2159791 | O9: =IF((N9-N8)<0,"0",(N9-N8)) -> 758 | P9: 78972 | Q9: =IF((P9-P8)<0,"0",(P9-P8)) -> 85 | R9: 88 | S9: 10 | T9: 147010 | U9: =IF((T9-T8)<0,"0",(T9-T8)) -> 289 | V9: 32950 | W9: =IF((V9-V8)<0,"0",(V9-V8)) -> 94 | X9: 1019 | Y9: =IF((X9-X8)<0,"0",(X9-X8)) -> 1 | Z9: 3188 | AA9: =IF((Z9-Z8)<0,"0",(Z9-Z8)) -> 0 | AD9: 561440 | AE9: =IF((AD9-AD8)<0,"0",(AD9-AD8)) -> 160 | AF9: 51380 | AG9: =IF((AF9-AF8)<0,"0",(AF9-AF8)) -> 15 | AH9: 8734 | AI9: =IF((AH9-AH8)<0,"0",(AH9-AH8)) -> 2 | AJ9: 10350 | AK9: =IF((AJ9-AJ8)<0,"0",(AJ9-AJ8)) -> 3 | AL9: 14359 | AM9: =IF((AL9-AL8)<0,"0",(AL9-AL8)) -> 5 | AN9: 19149 | AO9: =IF((AN9-AN8)<0,"0",(AN9-AN8)) -> 8 | AP9: 19457 | AQ9: =IF((AP9-AP8)<0,"0",(AP9-AP8)) -> 3 | AR9: 13771 | AS9: =IF((AR9-AR8)<0,"0",(AR9-AR8)) -> 2 | AT9: 6118 | AU9: =IF((AT9-AT8)<0,"0",(AT9-AT8)) -> 0 | AV9: 25921 | AW9: =IF((AV9-AV8)<0,"0",(AV9-AV8)) -> 11 | AX9: 844.8 | AY9: =IF((AX9-AX8)<0,"0",(AX9-AX8)) -> 6.1 | AZ9: 4014 | BA9: =IF((AZ9-AZ8)<0,"0",(AZ9-AZ8)) -> 9 | BB9: 3636 | BC9: =IF((BB9-BB8)<0,"0",(BB9-BB8)) -> 0 | BD9: =AS9+AQ9+AM9 -> 10 | BE9: =AE9-BD9 -> 150 | BF9: 586130 | BG9: =IF((BF9-BF8)<0,"0",(BF9-BF8)) -> 110 | BH9: 757180 | BI9: =IF((BH9-BH8)<0,"0",(BH9-BH8)) -> 200 | BJ9: =IF((BI9-AE9)<0,"0",(BI9-AE9)) -> 40 | BK9: 144 | BL9: =(IF(BK9<=116.4,((116.4*116.4*ACOS((116.4-BK9)/116.4))-((116.4-BK9)*SQRT(2*116.4*BK9-BK9*BK9)))*669.8,((3.1416*116.4*116.4)-((116.4*116.4*ACOS((116.4-(2*116.4-BK9))/116.4))-((116.4-(2*116.4-BK9))*SQRT(2*116.4*(2*116.4-BK9)-((2*116.4-BK9)*(2*116.4-BK9))))))*669.8))/1000 -> 18518.168 | BN9: =IF((BL8-BL9)<0,"0",(BL8-BL9)) -> 0 | BO9: 199598 | BP9: =IF((BO9-BO8)<0,"0",(BO9-BO8)) -> 137 | BQ9: =BP9*6.25 -> 856.25 | BR9: 55 | BS9: =(BR9*10775)/100 -> 5926.25 | BT9: 60 | BU9: =(BT9*10775)/100 -> 6465 | BV9: 60 | BW9: =(BV9*10775)/100 -> 6465 | BX9: =BS9+BU9+BW9 -> 18856.25 | BY9: =IF((BX8-BX9+BZ8)=BX8,"0",(BX8-BX9+BZ8)) -> 538.75 | BZ9: 9740 | CA9: 31989 | CB9: =IF((CA9-CA8)<0,"0",(CA9-CA8)) -> 52 | CC9: =CB9*6.25 -> 325 | CD9: 34061 | CE9: =IF((CD9-CD8)<0,"0",(CD9-CD8)) -> 8 | CF9: =CE9*6.25 -> 50 | CG9: 9571 | CH9: =IF((CG9-CG8)<0,"0",(CG9-CG8)) -> 20 | CI9: =CH9*6.25 -> 125 | CJ9: 83053 | CK9: =IF((CJ9-CJ8)<0,"0",(CJ9-CJ8)) -> 4 | CL9: =CK9*6.25 -> 25 | CM9: 5451 | CN9: =IF((CM9-CM8)<0,"0",(CM9-CM8)) -> 7 | CO9: =CN9*6.25 -> 43.75 | CP9: 6542 | CQ9: =IF((CP9-CP8)<0,"0",(CP9-CP8)) -> 9 | CR9: =CQ9*6.25 -> 56.25 | CS9: 3214 | CT9: =IF((CS9-CS8)<0,"0",(CS9-CS8)) -> 6 | CU9: =CT9*6.25 -> 37.5 | CV9: 1817.4 | CW9: =IF((CV9-CV8)<0,"0",(CV9-CV8)) -> 1 | CX9: =CW9*6.25 -> 6.25 | CY9: 4715 | CZ9: =IF((CY9-CY8)<0,"0",(CY9-CY8)) -> 7 | DA9: =CZ9*6.25 -> 43.75 | DB9: 4248 | DC9: =IF((DB9-DB8)<0,"0",(DB9-DB8)) -> 5 | DD9: =DC9*6.25 -> 31.25 | DE9: 4887 | DF9: =IF((DE9-DE8)<0,"0",(DE9-DE8)) -> 7 | DG9: =DF9*6.25 -> 43.75 | DH9: 4147 | DI9: =IF((DH9-DH8)<0,"0",(DH9-DH8)) -> 6 | DJ9: =DI9*6.25 -> 37.5 | DK9: 12382 | DL9: =IF((DK9-DK8)<0,"0",(DK9-DK8)) -> 0 | DM9: 52386 | DN9: =IF((DM9-DM8)<0,"0",(DM9-DM8)) -> 0 | DO9: 15524 | DP9: =IF((DO9-DO8)<0,"0",(DO9-DO8)) -> 0 | DQ9: 23640.3 | DR9: =IF((DQ9-DQ8)<0,"0",(DQ9-DQ8)) -> 0 | DS9: 74 | DT9: 189 | DU9: 0.59
A10: 44234 | B10: 3513624 | C10: =IF((B9-B8)<0,"0",(B9-B8)) -> 28640 | D10: 2978662 | E10: =IF((D10-D9)<0,"0",(D10-D9)) -> 26949 | F10: =E10/C11 -> 0.97131015 | G10: 1664 | H10: 749 | I10: 0 | J10: 965 | K10: 0 | L10: 2501666 | M10: =IF((L10-L9)<0,"0",(L10-L9)) -> 611 | N10: 2160422 | O10: =IF((N10-N9)<0,"0",(N10-N9)) -> 631 | P10: 79078 | Q10: =IF((P10-P9)<0,"0",(P10-P9)) -> 106 | R10: 66 | S10: 0 | T10: 147010 | U10: =IF((T10-T9)<0,"0",(T10-T9)) -> 0 | V10: 33039 | W10: =IF((V10-V9)<0,"0",(V10-V9)) -> 89 | X10: 1019 | Y10: =IF((X10-X9)<0,"0",(X10-X9)) -> 0 | Z10: 3188 | AA10: =IF((Z10-Z9)<0,"0",(Z10-Z9)) -> 0 | AD10: 561580 | AE10: =IF((AD10-AD9)<0,"0",(AD10-AD9)) -> 140 | AF10: 51395 | AG10: =IF((AF10-AF9)<0,"0",(AF10-AF9)) -> 15 | AH10: 8737 | AI10: =IF((AH10-AH9)<0,"0",(AH10-AH9)) -> 3 | AJ10: 10354 | AK10: =IF((AJ10-AJ9)<0,"0",(AJ10-AJ9)) -> 4 | AL10: 14364 | AM10: =IF((AL10-AL9)<0,"0",(AL10-AL9)) -> 5 | AN10: 19155 | AO10: =IF((AN10-AN9)<0,"0",(AN10-AN9)) -> 6 | AP10: 19459 | AQ10: =IF((AP10-AP9)<0,"0",(AP10-AP9)) -> 2 | AR10: 13773 | AS10: =IF((AR10-AR9)<0,"0",(AR10-AR9)) -> 2 | AT10: 6119 | AU10: =IF((AT10-AT9)<0,"0",(AT10-AT9)) -> 1 | AV10: 25931 | AW10: =IF((AV10-AV9)<0,"0",(AV10-AV9)) -> 10 | AX10: 851 | AY10: =IF((AX10-AX9)<0,"0",(AX10-AX9)) -> 6.2 | AZ10: 4023 | BA10: =IF((AZ10-AZ9)<0,"0",(AZ10-AZ9)) -> 9 | BB10: 3636 | BC10: =IF((BB10-BB9)<0,"0",(BB10-BB9)) -> 0 | BD10: =AS10+AQ10+AM10 -> 9 | BE10: =AE10-BD10 -> 131 | BF10: 586250 | BG10: =IF((BF10-BF9)<0,"0",(BF10-BF9)) -> 120 | BH10: 757350 | BI10: =IF((BH10-BH9)<0,"0",(BH10-BH9)) -> 170 | BJ10: =IF((BI10-AE10)<0,"0",(BI10-AE10)) -> 30 | BK10: 144 | BL10: =(IF(BK10<=116.4,((116.4*116.4*ACOS((116.4-BK10)/116.4))-((116.4-BK10)*SQRT(2*116.4*BK10-BK10*BK10)))*669.8,((3.1416*116.4*116.4)-((116.4*116.4*ACOS((116.4-(2*116.4-BK10))/116.4))-((116.4-(2*116.4-BK10))*SQRT(2*116.4*(2*116.4-BK10)-((2*116.4-BK10)*(2*116.4-BK10))))))*669.8))/1000 -> 18518.168 | BN10: =IF((BL9-BL10)<0,"0",(BL9-BL10)) -> 0 | BO10: 199741 | BP10: =IF((BO10-BO9)<0,"0",(BO10-BO9)) -> 143 | BQ10: =BP10*6.25 -> 893.75 | BR10: 85 | BS10: =(BR10*10775)/100 -> 9158.75 | BT10: 85 | BU10: =(BT10*10775)/100 -> 9158.75 | BV10: 85 | BW10: =(BV10*10775)/100 -> 9158.75 | BX10: =BS10+BU10+BW10 -> 27476.25 | BY10: =IF((BX9-BX10+BZ9)=BX9,"0",(BX9-BX10+BZ9)) -> 1120 | CA10: 32041 | CB10: =IF((CA10-CA9)<0,"0",(CA10-CA9)) -> 52 | CC10: =CB10*6.25 -> 325 | CD10: 34068 | CE10: =IF((CD10-CD9)<0,"0",(CD10-CD9)) -> 7 | CF10: =CE10*6.25 -> 43.75 | CG10: 9589 | CH10: =IF((CG10-CG9)<0,"0",(CG10-CG9)) -> 18 | CI10: =CH10*6.25 -> 112.5 | CJ10: 83058 | CK10: =IF((CJ10-CJ9)<0,"0",(CJ10-CJ9)) -> 5 | CL10: =CK10*6.25 -> 31.25 | CM10: 5456 | CN10: =IF((CM10-CM9)<0,"0",(CM10-CM9)) -> 5 | CO10: =CN10*6.25 -> 31.25 | CP10: 6551 | CQ10: =IF((CP10-CP9)<0,"0",(CP10-CP9)) -> 9 | CR10: =CQ10*6.25 -> 56.25 | CS10: 3219 | CT10: =IF((CS10-CS9)<0,"0",(CS10-CS9)) -> 5 | CU10: =CT10*6.25 -> 31.25 | CV10: 1818.6 | CW10: =IF((CV10-CV9)<0,"0",(CV10-CV9)) -> 1.2 | CX10: =CW10*6.25 -> 7.5 | CY10: 4722 | CZ10: =IF((CY10-CY9)<0,"0",(CY10-CY9)) -> 7 | DA10: =CZ10*6.25 -> 43.75 | DB10: 4253 | DC10: =IF((DB10-DB9)<0,"0",(DB10-DB9)) -> 5 | DD10: =DC10*6.25 -> 31.25 | DE10: 4893 | DF10: =IF((DE10-DE9)<0,"0",(DE10-DE9)) -> 6 | DG10: =DF10*6.25 -> 37.5 | DH10: 4153 | DI10: =IF((DH10-DH9)<0,"0",(DH10-DH9)) -> 6 | DJ10: =DI10*6.25 -> 37.5 | DK10: 12382 | DL10: =IF((DK10-DK9)<0,"0",(DK10-DK9)) -> 0 | DM10: 52386 | DN10: =IF((DM10-DM9)<0,"0",(DM10-DM9)) -> 0 | DO10: 15524 | DP10: =IF((DO10-DO9)<0,"0",(DO10-DO9)) -> 0 | DQ10: 23640.3 | DR10: =IF((DQ10-DQ9)<0,"0",(DQ10-DQ9)) -> 0 | DS10: 74 | DT10: 177 | DU10: 0.56
A11: 44235 | B11: 3541369 | C11: =IF((B11-B10)<0,"0",(B11-B10)) -> 27745 | D11: 3005696 | E11: =IF((D11-D10)<0,"0",(D11-D10)) -> 27034 | F11: =E11/C11 -> 0.97437376 | G11: 1664 | H11: 749 | I11: 0 | J11: 965 | K11: 0 | L11: 2502301 | M11: =IF((L11-L10)<0,"0",(L11-L10)) -> 635 | N11: 2161112 | O11: =IF((N11-N10)<0,"0",(N11-N10)) -> 690 | P11: 79250 | Q11: =IF((P11-P10)<0,"0",(P11-P10)) -> 172 | R11: 66 | S11: 5 | T11: 147149 | U11: =IF((T11-T10)<0,"0",(T11-T10)) -> 139 | V11: 33133 | W11: =IF((V11-V10)<0,"0",(V11-V10)) -> 94 | X11: 1020 | Y11: =IF((X11-X10)<0,"0",(X11-X10)) -> 1 | Z11: 3253 | AA11: =IF((Z11-Z10)<0,"0",(Z11-Z10)) -> 65 | AD11: 561700 | AE11: =IF((AD11-AD10)<0,"0",(AD11-AD10)) -> 120 | AF11: 51410 | AG11: =IF((AF11-AF10)<0,"0",(AF11-AF10)) -> 15 | AH11: 8739 | AI11: =IF((AH11-AH10)<0,"0",(AH11-AH10)) -> 2 | AJ11: 10358 | AK11: =IF((AJ11-AJ10)<0,"0",(AJ11-AJ10)) -> 4 | AL11: 14365 | AM11: =IF((AL11-AL10)<0,"0",(AL11-AL10)) -> 1 | AN11: 19163 | AO11: =IF((AN11-AN10)<0,"0",(AN11-AN10)) -> 8 | AP11: 19462 | AQ11: =IF((AP11-AP10)<0,"0",(AP11-AP10)) -> 3 | AR11: 13774 | AS11: =IF((AR11-AR10)<0,"0",(AR11-AR10)) -> 1 | AT11: 6120 | AU11: =IF((AT11-AT10)<0,"0",(AT11-AT10)) -> 1 | AV11: 25942 | AW11: =IF((AV11-AV10)<0,"0",(AV11-AV10)) -> 11 | AX11: 857 | AY11: =IF((AX11-AX10)<0,"0",(AX11-AX10)) -> 6 | AZ11: 4031 | BA11: =IF((AZ11-AZ10)<0,"0",(AZ11-AZ10)) -> 8 | BB11: 3636 | BC11: =IF((BB11-BB10)<0,"0",(BB11-BB10)) -> 0 | BD11: =AS11+AQ11+AM11 -> 5 | BE11: =AE11-BD11 -> 115 | BF11: 586420 | BG11: =IF((BF11-BF10)<0,"0",(BF11-BF10)) -> 170 | BH11: 757500 | BI11: =IF((BH11-BH10)<0,"0",(BH11-BH10)) -> 150 | BJ11: =IF((BI11-AE11)<0,"0",(BI11-AE11)) -> 30 | BK11: 144 | BL11: =(IF(BK11<=116.4,((116.4*116.4*ACOS((116.4-BK11)/116.4))-((116.4-BK11)*SQRT(2*116.4*BK11-BK11*BK11)))*669.8,((3.1416*116.4*116.4)-((116.4*116.4*ACOS((116.4-(2*116.4-BK11))/116.4))-((116.4-(2*116.4-BK11))*SQRT(2*116.4*(2*116.4-BK11)-((2*116.4-BK11)*(2*116.4-BK11))))))*669.8))/1000 -> 18518.168 | BN11: =IF((BL10-BL11)<0,"0",(BL10-BL11)) -> 0 | BO11: 199864 | BP11: =IF((BO11-BO10)<0,"0",(BO11-BO10)) -> 123 | BQ11: =BP11*6.25 -> 768.75 | BR11: 82 | BS11: =(BR11*10775)/100 -> 8835.5 | BT11: 82 | BU11: =(BT11*10775)/100 -> 8835.5 | BV11: 82 | BW11: =(BV11*10775)/100 -> 8835.5 | BX11: =BS11+BU11+BW11 -> 26506.5 | BY11: =IF((BX10-BX11+BZ10)=BX10,"0",(BX10-BX11+BZ10)) -> 969.75 | CA11: 32099 | CB11: =IF((CA11-CA10)<0,"0",(CA11-CA10)) -> 58 | CC11: =CB11*6.25 -> 362.5 | CD11: 34068 | CE11: =IF((CD11-CD10)<0,"0",(CD11-CD10)) -> 0 | CF11: =CE11*6.25 -> 0 | CG11: 9606 | CH11: =IF((CG11-CG10)<0,"0",(CG11-CG10)) -> 17 | CI11: =CH11*6.25 -> 106.25 | CJ11: 83062 | CK11: =IF((CJ11-CJ10)<0,"0",(CJ11-CJ10)) -> 4 | CL11: =CK11*6.25 -> 25 | CM11: 5462 | CN11: =IF((CM11-CM10)<0,"0",(CM11-CM10)) -> 6 | CO11: =CN11*6.25 -> 37.5 | CP11: 6560 | CQ11: =IF((CP11-CP10)<0,"0",(CP11-CP10)) -> 9 | CR11: =CQ11*6.25 -> 56.25 | CS11: 3224 | CT11: =IF((CS11-CS10)<0,"0",(CS11-CS10)) -> 5 | CU11: =CT11*6.25 -> 31.25 | CV11: 1819.4 | CW11: =IF((CV11-CV10)<0,"0",(CV11-CV10)) -> 0.8 | CX11: =CW11*6.25 -> 5 | CY11: 4727 | CZ11: =IF((CY11-CY10)<0,"0",(CY11-CY10)) -> 5 | DA11: =CZ11*6.25 -> 31.25 | DB11: 4258 | DC11: =IF((DB11-DB10)<0,"0",(DB11-DB10)) -> 5 | DD11: =DC11*6.25 -> 31.25 | DE11: 4898 | DF11: =IF((DE11-DE10)<0,"0",(DE11-DE10)) -> 5 | DG11: =DF11*6.25 -> 31.25 | DH11: 4159 | DI11: =IF((DH11-DH10)<0,"0",(DH11-DH10)) -> 6 | DJ11: =DI11*6.25 -> 37.5 | DK11: 12382 | DL11: =IF((DK11-DK10)<0,"0",(DK11-DK10)) -> 0 | DM11: 52386 | DN11: =IF((DM11-DM10)<0,"0",(DM11-DM10)) -> 0 | DO11: 15524 | DP11: =IF((DO11-DO10)<0,"0",(DO11-DO10)) -> 0 | DQ11: 23640.3 | DR11: =IF((DQ11-DQ10)<0,"0",(DQ11-DQ10)) -> 0 | DS11: 69 | DT11: 170 | DU11: 0.52
A12: 44236 | B12: 3566595 | C12: =IF((B12-B11)<0,"0",(B12-B11)) -> 25226 | D12: 3030266 | E12: =IF((D12-D11)<0,"0",(D12-D11)) -> 24570 | F12: =E12/C12 -> 0.97399508 | G12: 1664 | H12: 749 | I12: 0 | J12: 965 | K12: 0 | L12: 2502912 | M12: =IF((L12-L11)<0,"0",(L12-L11)) -> 611 | N12: 2161680 | O12: =IF((N12-N11)<0,"0",(N12-N11)) -> 568 | P12: 79420 | Q12: =IF((P12-P11)<0,"0",(P12-P11)) -> 170 | R12: 77 | S12: 5 | T12: 147291 | U12: =IF((T12-T11)<0,"0",(T12-T11)) -> 142 | V12: 33221 | W12: =IF((V12-V11)<0,"0",(V12-V11)) -> 88 | X12: 1020 | Y12: =IF((X12-X11)<0,"0",(X12-X11)) -> 0 | Z12: 3272 | AA12: =IF((Z12-Z11)<0,"0",(Z12-Z11)) -> 19 | AD12: 561850 | AE12: =IF((AD12-AD11)<0,"0",(AD12-AD11)) -> 150 | AF12: 51424 | AG12: =IF((AF12-AF11)<0,"0",(AF12-AF11)) -> 14 | AH12: 8741 | AI12: =IF((AH12-AH11)<0,"0",(AH12-AH11)) -> 2 | AJ12: 10361 | AK12: =IF((AJ12-AJ11)<0,"0",(AJ12-AJ11)) -> 3 | AL12: 14370 | AM12: =IF((AL12-AL11)<0,"0",(AL12-AL11)) -> 5 | AN12: 19170 | AO12: =IF((AN12-AN11)<0,"0",(AN12-AN11)) -> 7 | AP12: 19465 | AQ12: =IF((AP12-AP11)<0,"0",(AP12-AP11)) -> 3 | AR12: 13775 | AS12: =IF((AR12-AR11)<0,"0",(AR12-AR11)) -> 1 | AT12: 6121 | AU12: =IF((AT12-AT11)<0,"0",(AT12-AT11)) -> 1 | AV12: 25951 | AW12: =IF((AV12-AV11)<0,"0",(AV12-AV11)) -> 9 | AX12: 863 | AY12: =IF((AX12-AX11)<0,"0",(AX12-AX11)) -> 6 | AZ12: 4042 | BA12: =IF((AZ12-AZ11)<0,"0",(AZ12-AZ11)) -> 11 | BB12: 3636 | BC12: =IF((BB12-BB11)<0,"0",(BB12-BB11)) -> 0 | BD12: =AS12+AQ12+AM12 -> 9 | BE12: =AE12-BD12 -> 141 | BF12: 586540 | BG12: =IF((BF12-BF11)<0,"0",(BF12-BF11)) -> 120 | BH12: 757680 | BI12: =IF((BH12-BH11)<0,"0",(BH12-BH11)) -> 180 | BJ12: =IF((BI12-AE12)<0,"0",(BI12-AE12)) -> 30 | BK12: 144 | BL12: =(IF(BK12<=116.4,((116.4*116.4*ACOS((116.4-BK12)/116.4))-((116.4-BK12)*SQRT(2*116.4*BK12-BK12*BK12)))*669.8,((3.1416*116.4*116.4)-((116.4*116.4*ACOS((116.4-(2*116.4-BK12))/116.4))-((116.4-(2*116.4-BK12))*SQRT(2*116.4*(2*116.4-BK12)-((2*116.4-BK12)*(2*116.4-BK12))))))*669.8))/1000 -> 18518.168 | BN12: =IF((BL11-BL12)<0,"0",(BL11-BL12)) -> 0 | BO12: 199988 | BP12: =IF((BO12-BO11)<0,"0",(BO12-BO11)) -> 124 | BQ12: =BP12*6.25 -> 775 | BR12: 80 | BS12: =(BR12*10775)/100 -> 8620 | BT12: 80 | BU12: =(BT12*10775)/100 -> 8620 | BV12: 80 | BW12: =(BV12*10775)/100 -> 8620 | BX12: =BS12+BU12+BW12 -> 25860 | BY12: =IF((BX11-BX12+BZ11)=BX11,"0",(BX11-BX12+BZ11)) -> 646.5 | CA12: 32136 | CB12: =IF((CA12-CA11)<0,"0",(CA12-CA11)) -> 37 | CC12: =CB12*6.25 -> 231.25 | CD12: 34076 | CE12: =IF((CD12-CD11)<0,"0",(CD12-CD11)) -> 8 | CF12: =CE12*6.25 -> 50 | CG12: 9623 | CH12: =IF((CG12-CG11)<0,"0",(CG12-CG11)) -> 17 | CI12: =CH12*6.25 -> 106.25 | CJ12: 83067 | CK12: =IF((CJ12-CJ11)<0,"0",(CJ12-CJ11)) -> 5 | CL12: =CK12*6.25 -> 31.25 | CM12: 5467 | CN12: =IF((CM12-CM11)<0,"0",(CM12-CM11)) -> 5 | CO12: =CN12*6.25 -> 31.25 | CP12: 6569 | CQ12: =IF((CP12-CP11)<0,"0",(CP12-CP11)) -> 9 | CR12: =CQ12*6.25 -> 56.25 | CS12: 3228 | CT12: =IF((CS12-CS11)<0,"0",(CS12-CS11)) -> 4 | CU12: =CT12*6.25 -> 25 | CV12: 1820.1 | CW12: =IF((CV12-CV11)<0,"0",(CV12-CV11)) -> 0.7 | CX12: =CW12*6.25 -> 4.375 | CY12: 4732 | CZ12: =IF((CY12-CY11)<0,"0",(CY12-CY11)) -> 5 | DA12: =CZ12*6.25 -> 31.25 | DB12: 4263 | DC12: =IF((DB12-DB11)<0,"0",(DB12-DB11)) -> 5 | DD12: =DC12*6.25 -> 31.25 | DE12: 4903 | DF12: =IF((DE12-DE11)<0,"0",(DE12-DE11)) -> 5 | DG12: =DF12*6.25 -> 31.25 | DH12: 4164 | DI12: =IF((DH12-DH11)<0,"0",(DH12-DH11)) -> 5 | DJ12: =DI12*6.25 -> 31.25 | DK12: 12382 | DL12: =IF((DK12-DK11)<0,"0",(DK12-DK11)) -> 0 | DM12: 52386 | DN12: =IF((DM12-DM11)<0,"0",(DM12-DM11)) -> 0 | DO12: 15524 | DP12: =IF((DO12-DO11)<0,"0",(DO12-DO11)) -> 0 | DQ12: 23640.3 | DR12: =IF((DQ12-DQ11)<0,"0",(DQ12-DQ11)) -> 0 | DS12: 68 | DT12: 171 | DU12: 0.51
A13: 44237 | B13: 3592922 | C13: =IF((B13-B12)<0,"0",(B13-B12)) -> 26327 | D13: 3055968 | E13: =IF((D13-D12)<0,"0",(D13-D12)) -> 25702 | F13: =E13/C13 -> 0.97626011 | G13: 1664 | H13: 749 | I13: 0 | J13: 965 | K13: 0 | L13: 2503420 | M13: =IF((L13-L12)<0,"0",(L13-L12)) -> 508 | N13: 2162392 | O13: =IF((N13-N12)<0,"0",(N13-N12)) -> 712 | P13: 79533 | Q13: =IF((P13-P12)<0,"0",(P13-P12)) -> 113 | R13: 89 | S13: 10 | T13: 147577 | U13: =IF((T13-T12)<0,"0",(T13-T12)) -> 286 | V13: 33314 | W13: =IF((V13-V12)<0,"0",(V13-V12)) -> 93 | X13: 1020 | Y13: =IF((X13-X12)<0,"0",(X13-X12)) -> 0 | Z13: 3283 | AA13: =IF((Z13-Z12)<0,"0",(Z13-Z12)) -> 11 | AD13: 562000 | AE13: =IF((AD13-AD12)<0,"0",(AD13-AD12)) -> 150 | AF13: 51439 | AG13: =IF((AF13-AF12)<0,"0",(AF13-AF12)) -> 15 | AH13: 8743 | AI13: =IF((AH13-AH12)<0,"0",(AH13-AH12)) -> 2 | AJ13: 10363 | AK13: =IF((AJ13-AJ12)<0,"0",(AJ13-AJ12)) -> 2 | AL13: 14373 | AM13: =IF((AL13-AL12)<0,"0",(AL13-AL12)) -> 3 | AN13: 19176 | AO13: =IF((AN13-AN12)<0,"0",(AN13-AN12)) -> 6 | AP13: 19467 | AQ13: =IF((AP13-AP12)<0,"0",(AP13-AP12)) -> 2 | AR13: 13775 | AS13: =IF((AR13-AR12)<0,"0",(AR13-AR12)) -> 0 | AT13: 6121 | AU13: =IF((AT13-AT12)<0,"0",(AT13-AT12)) -> 0 | AV13: 25961 | AW13: =IF((AV13-AV12)<0,"0",(AV13-AV12)) -> 10 | AX13: 869 | AY13: =IF((AX13-AX12)<0,"0",(AX13-AX12)) -> 6 | AZ13: 4049 | BA13: =IF((AZ13-AZ12)<0,"0",(AZ13-AZ12)) -> 7 | BB13: 3636 | BC13: =IF((BB13-BB12)<0,"0",(BB13-BB12)) -> 0 | BD13: =AS13+AQ13+AM13 -> 5 | BE13: =AE13-BD13 -> 145 | BF13: 586650 | BG13: =IF((BF13-BF12)<0,"0",(BF13-BF12)) -> 110 | BH13: 757840 | BI13: =IF((BH13-BH12)<0,"0",(BH13-BH12)) -> 160 | BJ13: =IF((BI13-AE13)<0,"0",(BI13-AE13)) -> 10 | BK13: 144 | BL13: =(IF(BK13<=116.4,((116.4*116.4*ACOS((116.4-BK13)/116.4))-((116.4-BK13)*SQRT(2*116.4*BK13-BK13*BK13)))*669.8,((3.1416*116.4*116.4)-((116.4*116.4*ACOS((116.4-(2*116.4-BK13))/116.4))-((116.4-(2*116.4-BK13))*SQRT(2*116.4*(2*116.4-BK13)-((2*116.4-BK13)*(2*116.4-BK13))))))*669.8))/1000 -> 18518.168 | BN13: =IF((BL12-BL13)<0,"0",(BL12-BL13)) -> 0 | BO13: 200107 | BP13: =IF((BO13-BO12)<0,"0",(BO13-BO12)) -> 119 | BQ13: =BP13*6.25 -> 743.75 | BR13: 75 | BS13: =(BR13*10775)/100 -> 8081.25 | BT13: 80 | BU13: =(BT13*10775)/100 -> 8620 | BV13: 80 | BW13: =(BV13*10775)/100 -> 8620 | BX13: =BS13+BU13+BW13 -> 25321.25 | BY13: =IF((BX12-BX13+BZ12)=BX12,"0",(BX12-BX13+BZ12)) -> 538.75 | CA13: 32192 | CB13: =IF((CA13-CA12)<0,"0",(CA13-CA12)) -> 56 | CC13: =CB13*6.25 -> 350 | CD13: 34083 | CE13: =IF((CD13-CD12)<0,"0",(CD13-CD12)) -> 7 | CF13: =CE13*6.25 -> 43.75 | CG13: 9635 | CH13: =IF((CG13-CG12)<0,"0",(CG13-CG12)) -> 12 | CI13: =CH13*6.25 -> 75 | CJ13: 83071 | CK13: =IF((CJ13-CJ12)<0,"0",(CJ13-CJ12)) -> 4 | CL13: =CK13*6.25 -> 25 | CM13: 5472 | CN13: =IF((CM13-CM12)<0,"0",(CM13-CM12)) -> 5 | CO13: =CN13*6.25 -> 31.25 | CP13: 6577 | CQ13: =IF((CP13-CP12)<0,"0",(CP13-CP12)) -> 8 | CR13: =CQ13*6.25 -> 50 | CS13: 3233 | CT13: =IF((CS13-CS12)<0,"0",(CS13-CS12)) -> 5 | CU13: =CT13*6.25 -> 31.25 | CV13: 1821.3 | CW13: =IF((CV13-CV12)<0,"0",(CV13-CV12)) -> 1.2 | CX13: =CW13*6.25 -> 7.5 | CY13: 4736 | CZ13: =IF((CY13-CY12)<0,"0",(CY13-CY12)) -> 4 | DA13: =CZ13*6.25 -> 25 | DB13: 4268 | DC13: =IF((DB13-DB12)<0,"0",(DB13-DB12)) -> 5 | DD13: =DC13*6.25 -> 31.25 | DE13: 4907 | DF13: =IF((DE13-DE12)<0,"0",(DE13-DE12)) -> 4 | DG13: =DF13*6.25 -> 25 | DH13: 4169 | DI13: =IF((DH13-DH12)<0,"0",(DH13-DH12)) -> 5 | DJ13: =DI13*6.25 -> 31.25 | DK13: 12462 | DL13: =IF((DK13-DK12)<0,"0",(DK13-DK12)) -> 80 | DM13: 54917 | DN13: =IF((DM13-DM12)<0,"0",(DM13-DM12)) -> 2531 | DO13: 15524 | DP13: =IF((DO13-DO12)<0,"0",(DO13-DO12)) -> 0 | DQ13: 23640.3 | DR13: =IF((DQ13-DQ12)<0,"0",(DQ13-DQ12)) -> 0 | DS13: 62 | DT13: 150 | DU13: 0.47
