Workbook

Sheet TOTAL
A1: Site Name | B1: Day | C1: Month | D1: Year | E1: Total Electricity Kwh | F1: Electricity Tariff ($/Kwh) | G1: Natual Gas (m3) | H1: Natural Gas $/m3 | I1: District Energy Cooling Kwh | J1: District Energy Cooling $/Kwh | K1: Water Utility Supply (m3) m3 | L1: Water Utility Supply (m3) $/m3 | M1: Room Nights | N1: Total Guests
A2: Abu Dhabi | B2: 1 | C2: 2 | D2: 2020 | E2: =Submetering!E2+Submetering!F2+Submetering!G2+Submetering!H2+Submetering!I2+Submetering!J2+Submetering!K2 -> 33298 | F2: 0.2 | G2: =Submetering!P2 -> 428.5 | H2: 10.02 | I2: =Submetering!T2-Submetering!T2*15%-Submetering!X2 -> 25776.253 | J2: 0.21 | K2: ='FS-AD Daily '!T7 -> 151.964 | L2: 7.84 | M2: 161 | N2: 235
A3: Abu Dhabi | B3: =B2+1 -> 2 | C3: 2 | D3: 2020 | E3: =Submetering!E3+Submetering!F3+Submetering!G3+Submetering!H3+Submetering!I3+Submetering!J3+Submetering!K3 -> 33833 | F3: 0.2 | G3: =Submetering!P3 -> 397.4 | H3: 10.02 | I3: =Submetering!T3-Submetering!T3*15%-Submetering!X3 -> 27546.686 | J3: 0.21 | K3: ='FS-AD Daily '!T8 -> 312.318 | L3: 7.84 | M3: 161 | N3: 231
A4: Abu Dhabi | B4: =B3+1 -> 3 | C4: 2 | D4: 2020 | E4: =Submetering!E4+Submetering!F4+Submetering!G4+Submetering!H4+Submetering!I4+Submetering!J4+Submetering!K4 -> 35597 | F4: 0.2 | G4: =Submetering!P4 -> 406.7 | H4: 10.02 | I4: =Submetering!T4-Submetering!T4*15%-Submetering!X4 -> 26404.568 | J4: 0.21 | K4: ='FS-AD Daily '!T9 -> 206.533 | L4: 7.84 | M4: 176 | N4: 232
A5: Abu Dhabi | B5: =B4+1 -> 4 | C5: 2 | D5: 2020 | E5: =Submetering!E5+Submetering!F5+Submetering!G5+Submetering!H5+Submetering!I5+Submetering!J5+Submetering!K5 -> 35495 | F5: 0.2 | G5: =Submetering!P5 -> 403.8 | H5: 10.02 | I5: =Submetering!T5-Submetering!T5*15%-Submetering!X5 -> 26945.741 | J5: 0.21 | K5: ='FS-AD Daily '!T10 -> 219.216 | L5: 7.84 | M5: 177 | N5: 233
A6: Abu Dhabi | B6: =B5+1 -> 5 | C6: 2 | D6: 2020 | E6: =Submetering!E6+Submetering!F6+Submetering!G6+Submetering!H6+Submetering!I6+Submetering!J6+Submetering!K6 -> 32996 | F6: 0.2 | G6: =Submetering!P6 -> 399 | H6: 10.02 | I6: =Submetering!T6-Submetering!T6*15%-Submetering!X6 -> 27105.79 | J6: 0.21 | K6: ='FS-AD Daily '!T11 -> 203.068 | L6: 7.84 | M6: 171 | N6: 226
A7: Abu Dhabi | B7: =B6+1 -> 6 | C7: 2 | D7: 2020 | E7: =Submetering!E7+Submetering!F7+Submetering!G7+Submetering!H7+Submetering!I7+Submetering!J7+Submetering!K7 -> 32669 | F7: 0.2 | G7: =Submetering!P7 -> 406.1 | H7: 10.02 | I7: =Submetering!T7-Submetering!T7*15%-Submetering!X7 -> 28601.076 | J7: 0.21 | K7: ='FS-AD Daily '!T12 -> 220.182 | L7: 7.84 | M7: 124 | N7: 206
A8: Abu Dhabi | B8: =B7+1 -> 7 | C8: 2 | D8: 2020 | E8: =Submetering!E8+Submetering!F8+Submetering!G8+Submetering!H8+Submetering!I8+Submetering!J8+Submetering!K8 -> 32487 | F8: 0.2 | G8: =Submetering!P8 -> 420.7 | H8: 10.02 | I8: =Submetering!T8-Submetering!T8*15%-Submetering!X8 -> 29581.573 | J8: 0.21 | K8: ='FS-AD Daily '!T13 -> 198.992 | L8: 7.84 | M8: 141 | N8: 248
A9: Abu Dhabi | B9: =B8+1 -> 8 | C9: 2 | D9: 2020 | E9: =Submetering!E9+Submetering!F9+Submetering!G9+Submetering!H9+Submetering!I9+Submetering!J9+Submetering!K9 -> 31311 | F9: 0.2 | G9: =Submetering!P9 -> 400.8 | H9: 10.02 | I9: =Submetering!T9-Submetering!T9*15%-Submetering!X9 -> 29483.658 | J9: 0.21 | K9: ='FS-AD Daily '!T14 -> 214.131 | L9: 7.84 | M9: 163 | N9: 229
A10: Abu Dhabi | B10: =B9+1 -> 9 | C10: 2 | D10: 2020 | E10: =Submetering!E10+Submetering!F10+Submetering!G10+Submetering!H10+Submetering!I10+Submetering!J10+Submetering!K10 -> 33544 | F10: 0.2 | G10: =Submetering!P10 -> 402 | H10: 10.02 | I10: =Submetering!T10-Submetering!T10*15%-Submetering!X10 -> 32795.458 | J10: 0.21 | K10: ='FS-AD Daily '!T15 -> 216.329 | L10: 7.84 | M10: 173 | N10: 217
A11: Abu Dhabi | B11: =B10+1 -> 10 | C11: 2 | D11: 2020 | E11: =Submetering!E11+Submetering!F11+Submetering!G11+Submetering!H11+Submetering!I11+Submetering!J11+Submetering!K11 -> 33266 | F11: 0.2 | G11: =Submetering!P11 -> 443.4 | H11: 10.02 | I11: =Submetering!T11-Submetering!T11*15%-Submetering!X11 -> 33735.295 | J11: 0.21 | K11: ='FS-AD Daily '!T16 -> 222.331 | L11: 7.84 | M11: 190 | N11: 219
A12: Abu Dhabi | B12: =B11+1 -> 11 | C12: 2 | D12: 2020 | E12: =Submetering!E12+Submetering!F12+Submetering!G12+Submetering!H12+Submetering!I12+Submetering!J12+Submetering!K12 -> 32655 | F12: 0.2 | G12: =Submetering!P12 -> 396.1 | H12: 10.02 | I12: =Submetering!T12-Submetering!T12*15%-Submetering!X12 -> 27792.5 | J12: 0.21 | K12: ='FS-AD Daily '!T17 -> 226.034 | L12: 7.84 | M12: 195 | N12: 221
A13: Abu Dhabi | B13: =B12+1 -> 12 | C13: 2 | D13: 2020 | E13: =Submetering!E13+Submetering!F13+Submetering!G13+Submetering!H13+Submetering!I13+Submetering!J13+Submetering!K13 -> 34750 | F13: 0.2 | G13: =Submetering!P13 -> 371.1 | H13: 10.02 | I13: =Submetering!T13-Submetering!T13*15%-Submetering!X13 -> 23204.681 | J13: 0.21 | K13: ='FS-AD Daily '!T18 -> 233.177 | L13: 7.84 | M13: 190 | N13: 221
A14: Abu Dhabi | B14: =B13+1 -> 13 | C14: 2 | D14: 2020 | E14: =Submetering!E14+Submetering!F14+Submetering!G14+Submetering!H14+Submetering!I14+Submetering!J14+Submetering!K14 -> 35993 | F14: 0.2 | G14: =Submetering!P14 -> 442.5 | H14: 10.02 | I14: =Submetering!T14-Submetering!T14*15%-Submetering!X14 -> 25243.143 | J14: 0.21 | K14: ='FS-AD Daily '!T19 -> 230.478 | L14: 7.84 | M14: 167 | N14: 233
... A21: Abu Dhabi | B21: =B20+1 -> 20 | C21: 2 | D21: 2020 | E21: =Submetering!E21+Submetering!F21+Submetering!G21+Submetering!H21+Submetering!I21+Submetering!J21+Submetering!K21 -> 33079 | F21: 0.2 | G21: =Submetering!P21 -> 482 | H21: 10.02 | I21: =Submetering!T21-Submetering!T21*15%-Submetering!X21 -> 35979.734 | J21: 0.21 | K21: ='FS-AD Daily '!T26 -> 260.3 | L21: 7.84 | M21: 180 | N21: 291
A22: Abu Dhabi | B22: =B21+1 -> 21 | C22: 2 | D22: 2020 | E22: =Submetering!E22+Submetering!F22+Submetering!G22+Submetering!H22+Submetering!I22+Submetering!J22+Submetering!K22 -> 0 | F22: 0.2 | G22: =Submetering!P22 -> 0 | H22: 10.02 | I22: =Submetering!T22-Submetering!T22*15%-Submetering!X22 -> 0 | J22: 0.21 | K22: ='FS-AD Daily '!T27 -> 0 | L22: 7.84
A23: Abu Dhabi | B23: =B22+1 -> 22 | C23: 2 | D23: 2020 | E23: =Submetering!E23+Submetering!F23+Submetering!G23+Submetering!H23+Submetering!I23+Submetering!J23+Submetering!K23 -> 0 | F23: 0.2 | G23: =Submetering!P23 -> 0 | H23: 10.02 | I23: =Submetering!T23-Submetering!T23*15%-Submetering!X23 -> 0 | J23: 0.21 | K23: ='FS-AD Daily '!T28 -> 0 | L23: 7.84
A24: Abu Dhabi | B24: =B23+1 -> 23 | C24: 2 | D24: 2020 | E24: =Submetering!E24+Submetering!F24+Submetering!G24+Submetering!H24+Submetering!I24+Submetering!J24+Submetering!K24 -> 0 | F24: 0.2 | G24: =Submetering!P24 -> 0 | H24: 10.02 | I24: =Submetering!T24-Submetering!T24*15%-Submetering!X24 -> 0 | J24: 0.21 | K24: ='FS-AD Daily '!T29 -> 0 | L24: 7.84
A25: Abu Dhabi | B25: =B24+1 -> 24 | C25: 2 | D25: 2020 | E25: =Submetering!E25+Submetering!F25+Submetering!G25+Submetering!H25+Submetering!I25+Submetering!J25+Submetering!K25 -> 0 | F25: 0.2 | G25: =Submetering!P25 -> 0 | H25: 10.02 | I25: =Submetering!T25-Submetering!T25*15%-Submetering!X25 -> 0 | J25: 0.21 | K25: ='FS-AD Daily '!T30 -> 0 | L25: 7.84
A26: Abu Dhabi | B26: =B25+1 -> 25 | C26: 2 | D26: 2020 | E26: =Submetering!E26+Submetering!F26+Submetering!G26+Submetering!H26+Submetering!I26+Submetering!J26+Submetering!K26 -> 0 | F26: 0.2 | G26: =Submetering!P26 -> 0 | H26: 10.02 | I26: =Submetering!T26-Submetering!T26*15%-Submetering!X26 -> 0 | J26: 0.21 | K26: ='FS-AD Daily '!T31 -> 0 | L26: 7.84
A27: Abu Dhabi | B27: =B26+1 -> 26 | C27: 2 | D27: 2020 | E27: =Submetering!E27+Submetering!F27+Submetering!G27+Submetering!H27+Submetering!I27+Submetering!J27+Submetering!K27 -> 0 | F27: 0.2 | G27: =Submetering!P27 -> 0 | H27: 10.02 | I27: =Submetering!T27-Submetering!T27*15%-Submetering!X27 -> 0 | J27: 0.21 | K27: ='FS-AD Daily '!T32 -> 0 | L27: 7.84
A28: Abu Dhabi | B28: =B27+1 -> 27 | C28: 2 | D28: 2020 | E28: =Submetering!E28+Submetering!F28+Submetering!G28+Submetering!H28+Submetering!I28+Submetering!J28+Submetering!K28 -> 0 | F28: 0.2 | G28: =Submetering!P28 -> 0 | H28: 10.02 | I28: =Submetering!T28-Submetering!T28*15%-Submetering!X28 -> 0 | J28: 0.21 | K28: ='FS-AD Daily '!T33 -> 0 | L28: 7.84
A29: Abu Dhabi | B29: =B28+1 -> 28 | C29: 2 | D29: 2020 | E29: =Submetering!E29+Submetering!F29+Submetering!G29+Submetering!H29+Submetering!I29+Submetering!J29+Submetering!K29 -> 0 | F29: 0.2 | G29: =Submetering!P29 -> 0 | H29: 10.02 | I29: =Submetering!T29-Submetering!T29*15%-Submetering!X29 -> 0 | J29: 0.21 | K29: ='FS-AD Daily '!T34 -> 0 | L29: 7.84
A30: Abu Dhabi | B30: =B29+1 -> 29 | C30: 2 | D30: 2020 | E30: =Submetering!E30+Submetering!F30+Submetering!G30+Submetering!H30+Submetering!I30+Submetering!J30+Submetering!K30 -> 0 | F30: 0.2 | G30: =Submetering!P30 -> 0 | H30: 10.02 | I30: =Submetering!T30-Submetering!T30*15%-Submetering!X30 -> 0 | J30: 0.21 | K30: ='FS-AD Daily '!T35 -> 0 | L30: 7.84
A31: Abu Dhabi | D31: 2020 | E31: =Submetering!E31+Submetering!F31+Submetering!G31+Submetering!H31+Submetering!I31+Submetering!J31+Submetering!K31 -> #REF! | F31: 0.2 | G31: =Submetering!P31 -> #REF! | H31: 10.02 | I31: =Submetering!T31-Submetering!T31*15%-Submetering!X31 -> #REF! | J31: 0.21 | K31: ='FS-AD Daily '!#REF! -> #REF! | L31: 7.84
A32: Abu Dhabi | D32: 2020 | E32: =Submetering!E32+Submetering!F32+Submetering!G32+Submetering!H32+Submetering!I32+Submetering!J32+Submetering!K32 -> #REF! | F32: 0.2 | G32: =Submetering!P32 -> #REF! | H32: 10.02 | I32: =Submetering!T32-Submetering!T32*15%-Submetering!X32 -> #REF! | J32: 0.21 | K32: ='FS-AD Daily '!#REF! -> #REF! | L32: 7.84
M33: =SUM(M2:M32) -> 3262 | N33: =SUM(N2:N32) -> 4577

Sheet Submetering
A1: Site Name | B1: Day | C1: Month | D1: Year | E1: LVS-1 SECTION A - KWh | F1: LVS-1 SECTION B - KWh | G1: LVS-2 (CAFE MILANO)- KWh | H1: LVS-3 SECTION A- KWh | I1: LVS-3 SECTION B- KWh | J1: LVS-4 SECTION A- KWh | K1: LVS-4 SECTION B- KWh | L1: LVS-5 (FLOOR 15-32) KWh | M1: LVS-LRLV (RETAIL)KWh | N1: Total Water- m3 | O1: Galleria Water m3 | P1: Main Gas m3 | Q1: HW Boiler Gas - m3 | R1: Steam Boiler Gas- m3 | S1: Total Kitchen- m3 | T1: Main District Cooling- KWh | U1: Podium District Cooling- KWh | V1: Guest Rooms District Cooling- KWh | W1: Residence District Cooling- KWh | X1: Galleria District Cooling KWh | Y1: Room Nights | Z1: Total Guests
A2: Abu Dhabi | B2: 1 | C2: 1 | D2: 2020 | E2: ='FS-AD Daily '!B7 -> 6582 | F2: ='FS-AD Daily '!C7 -> 5752 | G2: ='FS-AD Daily '!D7 -> 894 | H2: ='FS-AD Daily '!E7 -> 7009 | I2: ='FS-AD Daily '!F7 -> 5915 | J2: ='FS-AD Daily '!G7 -> 3190 | K2: ='FS-AD Daily '!H7 -> 3956 | L2: ='FS-AD Daily '!I7 -> 2271 | M2: ='FS-AD Daily '!J7 -> 6935 | N2: ='FS-AD Daily '!T7 -> 151.964 | O2: ='FS-AD Daily '!R7 -> 74.783 | P2: ='FS-AD Daily '!Z7 -> 428.5 | Q2: ='FS-AD Daily '!V7 -> 155.1 | R2: ='FS-AD Daily '!W7 -> 97.42 | S2: =P2-Q2-R2 -> 175.98 | T2: ='FS-AD Daily '!AD7*3.516 -> 40325.004 | U2: =('FS-AD Daily '!AF7)*1000 -> 17800 | V2: =('FS-AD Daily '!AG7)*1000 -> 5500 | W2: ='FS-AD Daily '!AH7*1000 -> 5200 | X2: =('FS-AD Daily '!AK7)*1000 -> 8500 | Y2: 161 | Z2: 235
A3: Abu Dhabi | B3: =B2+1 -> 2 | C3: 1 | D3: 2020 | E3: ='FS-AD Daily '!B8 -> 7082 | F3: ='FS-AD Daily '!C8 -> 5851 | G3: ='FS-AD Daily '!D8 -> 897 | H3: ='FS-AD Daily '!E8 -> 7241 | I3: ='FS-AD Daily '!F8 -> 5694 | J3: ='FS-AD Daily '!G8 -> 3179 | K3: ='FS-AD Daily '!H8 -> 3889 | L3: ='FS-AD Daily '!I8 -> 2273 | M3: ='FS-AD Daily '!J8 -> 6755 | N3: ='FS-AD Daily '!T8 -> 312.318 | O3: ='FS-AD Daily '!R8 -> 79.006 | P3: ='FS-AD Daily '!Z8 -> 397.4 | Q3: ='FS-AD Daily '!V8 -> 135 | R3: ='FS-AD Daily '!W8 -> 90.5 | S3: =P3-Q3-R3 -> 171.9 | T3: ='FS-AD Daily '!AD8*3.516 -> 43584.336 | U3: =('FS-AD Daily '!AF8)*1000 -> 19500 | V3: =('FS-AD Daily '!AG8)*1000 -> 5700 | W3: ='FS-AD Daily '!AH8*1000 -> 6200 | X3: =('FS-AD Daily '!AK8)*1000 -> 9500 | Y3: 161 | Z3: 231
A4: Abu Dhabi | B4: =B3+1 -> 3 | C4: 1 | D4: 2020 | E4: ='FS-AD Daily '!B9 -> 8556 | F4: ='FS-AD Daily '!C9 -> 5895 | G4: ='FS-AD Daily '!D9 -> 896 | H4: ='FS-AD Daily '!E9 -> 7150 | I4: ='FS-AD Daily '!F9 -> 5910 | J4: ='FS-AD Daily '!G9 -> 3250 | K4: ='FS-AD Daily '!H9 -> 3940 | L4: ='FS-AD Daily '!I9 -> 2199 | M4: ='FS-AD Daily '!J9 -> 7078 | N4: ='FS-AD Daily '!T9 -> 206.533 | O4: ='FS-AD Daily '!R9 -> 62.709 | P4: ='FS-AD Daily '!Z9 -> 406.7 | Q4: ='FS-AD Daily '!V9 -> 139.7 | R4: ='FS-AD Daily '!W9 -> 90.09 | S4: =P4-Q4-R4 -> 176.91 | T4: ='FS-AD Daily '!AD9*3.516 -> 41770.08 | U4: =('FS-AD Daily '!AF9)*1000 -> 18900 | V4: =('FS-AD Daily '!AG9)*1000 -> 5500 | W4: ='FS-AD Daily '!AH9*1000 -> 6300 | X4: =('FS-AD Daily '!AK9)*1000 -> 9100 | Y4: 176 | Z4: 232
A5: Abu Dhabi | B5: =B4+1 -> 4 | C5: 1 | D5: 2020 | E5: ='FS-AD Daily '!B10 -> 9022 | F5: ='FS-AD Daily '!C10 -> 5598 | G5: ='FS-AD Daily '!D10 -> 874 | H5: ='FS-AD Daily '!E10 -> 7167 | I5: ='FS-AD Daily '!F10 -> 5970 | J5: ='FS-AD Daily '!G10 -> 3224 | K5: ='FS-AD Daily '!H10 -> 3640 | L5: ='FS-AD Daily '!I10 -> 2165 | M5: ='FS-AD Daily '!J10 -> 6981 | N5: ='FS-AD Daily '!T10 -> 219.216 | O5: ='FS-AD Daily '!R10 -> 68.418 | P5: ='FS-AD Daily '!Z10 -> 403.8 | Q5: ='FS-AD Daily '!V10 -> 136.9 | R5: ='FS-AD Daily '!W10 -> 89.36 | S5: =P5-Q5-R5 -> 177.54 | T5: ='FS-AD Daily '!AD10*3.516 -> 42642.048 | U5: =('FS-AD Daily '!AF10)*1000 -> 19200 | V5: =('FS-AD Daily '!AG10)*1000 -> 5600 | W5: ='FS-AD Daily '!AH10*1000 -> 6400 | X5: =('FS-AD Daily '!AK10)*1000 -> 9300 | Y5: 177 | Z5: 233
A6: Abu Dhabi | B6: =B5+1 -> 5 | C6: 1 | D6: 2020 | E6: ='FS-AD Daily '!B11 -> 6806 | F6: ='FS-AD Daily '!C11 -> 5276 | G6: ='FS-AD Daily '!D11 -> 897 | H6: ='FS-AD Daily '!E11 -> 7120 | I6: ='FS-AD Daily '!F11 -> 6070 | J6: ='FS-AD Daily '!G11 -> 3248 | K6: ='FS-AD Daily '!H11 -> 3579 | L6: ='FS-AD Daily '!I11 -> 2135 | M6: ='FS-AD Daily '!J11 -> 7016 | N6: ='FS-AD Daily '!T11 -> 203.068 | O6: ='FS-AD Daily '!R11 -> 81.387 | P6: ='FS-AD Daily '!Z11 -> 399 | Q6: ='FS-AD Daily '!V11 -> 135.4 | R6: ='FS-AD Daily '!W11 -> 92.7 | S6: =P6-Q6-R6 -> 170.9 | T6: ='FS-AD Daily '!AD11*3.516 -> 44477.4 | U6: =('FS-AD Daily '!AF11)*1000 -> 20400 | V6: =('FS-AD Daily '!AG11)*1000 -> 5700 | W6: ='FS-AD Daily '!AH11*1000 -> 6000 | X6: =('FS-AD Daily '!AK11)*1000 -> 10700 | Y6: 171 | Z6: 226
A7: Abu Dhabi | B7: =B6+1 -> 6 | C7: 1 | D7: 2020 | E7: ='FS-AD Daily '!B12 -> 6241 | F7: ='FS-AD Daily '!C12 -> 5372 | G7: ='FS-AD Daily '!D12 -> 958 | H7: ='FS-AD Daily '!E12 -> 7214 | I7: ='FS-AD Daily '!F12 -> 6022 | J7: ='FS-AD Daily '!G12 -> 3304 | K7: ='FS-AD Daily '!H12 -> 3558 | L7: ='FS-AD Daily '!I12 -> 2196 | M7: ='FS-AD Daily '!J12 -> 7301 | N7: ='FS-AD Daily '!T12 -> 220.182 | O7: ='FS-AD Daily '!R12 -> 71.47 | P7: ='FS-AD Daily '!Z12 -> 406.1 | Q7: ='FS-AD Daily '!V12 -> 137.6 | R7: ='FS-AD Daily '!W12 -> 91.48 | S7: =P7-Q7-R7 -> 177.02 | T7: ='FS-AD Daily '!AD12*3.516 -> 48707.148 | U7: =('FS-AD Daily '!AF12)*1000 -> 22700 | V7: =('FS-AD Daily '!AG12)*1000 -> 6200 | W7: ='FS-AD Daily '!AH12*1000 -> 7100 | X7: =('FS-AD Daily '!AK12)*1000 -> 12800 | Y7: 124 | Z7: 206
A8: Abu Dhabi | B8: =B7+1 -> 7 | C8: 1 | D8: 2020 | E8: ='FS-AD Daily '!B13 -> 5961 | F8: ='FS-AD Daily '!C13 -> 5964 | G8: ='FS-AD Daily '!D13 -> 869 | H8: ='FS-AD Daily '!E13 -> 6852 | I8: ='FS-AD Daily '!F13 -> 6095 | J8: ='FS-AD Daily '!G13 -> 3218 | K8: ='FS-AD Daily '!H13 -> 3528 | L8: ='FS-AD Daily '!I13 -> 2091 | M8: ='FS-AD Daily '!J13 -> 6894 | N8: ='FS-AD Daily '!T13 -> 198.992 | O8: ='FS-AD Daily '!R13 -> 76.932 | P8: ='FS-AD Daily '!Z13 -> 420.7 | Q8: ='FS-AD Daily '!V13 -> 140.3 | R8: ='FS-AD Daily '!W13 -> 85.81 | S8: =P8-Q8-R8 -> 194.59 | T8: ='FS-AD Daily '!AD13*3.516 -> 50095.968 | U8: =('FS-AD Daily '!AF13)*1000 -> 23200 | V8: =('FS-AD Daily '!AG13)*1000 -> 6800 | W8: ='FS-AD Daily '!AH13*1000 -> 7800 | X8: =('FS-AD Daily '!AK13)*1000 -> 13000 | Y8: 141 | Z8: 248
A9: Abu Dhabi | B9: =B8+1 -> 8 | C9: 1 | D9: 2020 | E9: ='FS-AD Daily '!B14 -> 5554 | F9: ='FS-AD Daily '!C14 -> 5160 | G9: ='FS-AD Daily '!D14 -> 907 | H9: ='FS-AD Daily '!E14 -> 6942 | I9: ='FS-AD Daily '!F14 -> 5893 | J9: ='FS-AD Daily '!G14 -> 3253 | K9: ='FS-AD Daily '!H14 -> 3602 | L9: ='FS-AD Daily '!I14 -> 2276 | M9: ='FS-AD Daily '!J14 -> 6891 | N9: ='FS-AD Daily '!T14 -> 214.131 | O9: ='FS-AD Daily '!R14 -> 4.9 | P9: ='FS-AD Daily '!Z14 -> 400.8 | Q9: ='FS-AD Daily '!V14 -> 140.6 | R9: ='FS-AD Daily '!W14 -> 83.15 | S9: =P9-Q9-R9 -> 177.05 | T9: ='FS-AD Daily '!AD14*3.516 -> 50686.656 | U9: =('FS-AD Daily '!AF14)*1000 -> 22700 | V9: =('FS-AD Daily '!AG14)*1000 -> 7200 | W9: ='FS-AD Daily '!AH14*1000 -> 8500 | X9: =('FS-AD Daily '!AK14)*1000 -> 13600 | Y9: 163 | Z9: 229
A10: Abu Dhabi | B10: =B9+1 -> 9 | C10: 1 | D10: 2020 | E10: ='FS-AD Daily '!B15 -> 7186 | F10: ='FS-AD Daily '!C15 -> 5593 | G10: ='FS-AD Daily '!D15 -> 887 | H10: ='FS-AD Daily '!E15 -> 7052 | I10: ='FS-AD Daily '!F15 -> 6108 | J10: ='FS-AD Daily '!G15 -> 3175 | K10: ='FS-AD Daily '!H15 -> 3543 | L10: ='FS-AD Daily '!I15 -> 2250 | M10: ='FS-AD Daily '!J15 -> 7039 | N10: ='FS-AD Daily '!T15 -> 216.329 | O10: ='FS-AD Daily '!R15 -> 65.848 | P10: ='FS-AD Daily '!Z15 -> 402 | Q10: ='FS-AD Daily '!V15 -> 148.3 | R10: ='FS-AD Daily '!W15 -> 86.6 | S10: =P10-Q10-R10 -> 167.1 | T10: ='FS-AD Daily '!AD15*3.516 -> 53524.068 | U10: =('FS-AD Daily '!AF15)*1000 -> 25400 | V10: =('FS-AD Daily '!AG15)*1000 -> 7500 | W10: ='FS-AD Daily '!AH15*1000 -> 7700 | X10: =('FS-AD Daily '!AK15)*1000 -> 12700 | Y10: 173 | Z10: 217
A11: Abu Dhabi | B11: =B10+1 -> 10 | C11: 1 | D11: 2020 | E11: ='FS-AD Daily '!B16 -> 6317 | F11: ='FS-AD Daily '!C16 -> 5797 | G11: ='FS-AD Daily '!D16 -> 891 | H11: ='FS-AD Daily '!E16 -> 7195 | I11: ='FS-AD Daily '!F16 -> 6216 | J11: ='FS-AD Daily '!G16 -> 3202 | K11: ='FS-AD Daily '!H16 -> 3648 | L11: ='FS-AD Daily '!I16 -> 2290 | M11: ='FS-AD Daily '!J16 -> 7236 | N11: ='FS-AD Daily '!T16 -> 222.331 | O11: ='FS-AD Daily '!R16 -> 63.233 | P11: ='FS-AD Daily '!Z16 -> 443.4 | Q11: ='FS-AD Daily '!V16 -> 162.3 | R11: ='FS-AD Daily '!W16 -> 92.74 | S11: =P11-Q11-R11 -> 188.36 | T11: ='FS-AD Daily '!AD16*3.516 -> 56041.524 | U11: =('FS-AD Daily '!AF16)*1000 -> 27300 | V11: =('FS-AD Daily '!AG16)*1000 -> 7500 | W11: ='FS-AD Daily '!AH16*1000 -> 7700 | X11: =('FS-AD Daily '!AK16)*1000 -> 13900 | Y11: 190 | Z11: 219
A12: Abu Dhabi | B12: =B11+1 -> 11 | C12: 1 | D12: 2020 | E12: ='FS-AD Daily '!B17 -> 6929 | F12: ='FS-AD Daily '!C17 -> 5298 | G12: ='FS-AD Daily '!D17 -> 873 | H12: ='FS-AD Daily '!E17 -> 6938 | I12: ='FS-AD Daily '!F17 -> 6074 | J12: ='FS-AD Daily '!G17 -> 2988 | K12: ='FS-AD Daily '!H17 -> 3555 | L12: ='FS-AD Daily '!I17 -> 2239 | M12: ='FS-AD Daily '!J17 -> 6847 | N12: ='FS-AD Daily '!T17 -> 226.034 | O12: ='FS-AD Daily '!R17 -> 65.784 | P12: ='FS-AD Daily '!Z17 -> 396.1 | Q12: ='FS-AD Daily '!V17 -> 138.5 | R12: ='FS-AD Daily '!W17 -> 92.58 | S12: =P12-Q12-R12 -> 165.02 | T12: ='FS-AD Daily '!AD17*3.516 -> 46108.824 | U12: =('FS-AD Daily '!AF17)*1000 -> 21700 | V12: =('FS-AD Daily '!AG17)*1000 -> 5800 | W12: ='FS-AD Daily '!AH17*1000 -> 6400 | X12: =('FS-AD Daily '!AK17)*1000 -> 11400 | Y12: 195 | Z12: 221
A13: Abu Dhabi | B13: =B12+1 -> 12 | C13: 1 | D13: 2020 | E13: ='FS-AD Daily '!B18 -> 8221 | F13: ='FS-AD Daily '!C18 -> 5978 | G13: ='FS-AD Daily '!D18 -> 759 | H13: ='FS-AD Daily '!E18 -> 7085 | I13: ='FS-AD Daily '!F18 -> 6114 | J13: ='FS-AD Daily '!G18 -> 3078 | K13: ='FS-AD Daily '!H18 -> 3515 | L13: ='FS-AD Daily '!I18 -> 2202 | M13: ='FS-AD Daily '!J18 -> 6908 | N13: ='FS-AD Daily '!T18 -> 233.177 | O13: ='FS-AD Daily '!R18 -> 76.481 | P13: ='FS-AD Daily '!Z18 -> 371.1 | Q13: ='FS-AD Daily '!V18 -> 128.9 | R13: ='FS-AD Daily '!W18 -> 89.84 | S13: =P13-Q13-R13 -> 152.36 | T13: ='FS-AD Daily '!AD18*3.516 -> 37417.272 | U13: =('FS-AD Daily '!AF18)*1000 -> 16400 | V13: =('FS-AD Daily '!AG18)*1000 -> 4400 | W13: ='FS-AD Daily '!AH18*1000 -> 5400 | X13: =('FS-AD Daily '!AK18)*1000 -> 8600 | Y13: 190 | Z13: 221
A14: Abu Dhabi | B14: =B13+1 -> 13 | C14: 1 | D14: 2020 | E14: ='FS-AD Daily '!B19 -> 8972 | F14: ='FS-AD Daily '!C19 -> 5799 | G14: ='FS-AD Daily '!D19 -> 930 | H14: ='FS-AD Daily '!E19 -> 7381 | I14: ='FS-AD Daily '!F19 -> 6118 | J14: ='FS-AD Daily '!G19 -> 3244 | K14: ='FS-AD Daily '!H19 -> 3549 | L14: ='FS-AD Daily '!I19 -> 2203 | M14: ='FS-AD Daily '!J19 -> 7358 | N14: ='FS-AD Daily '!T19 -> 230.478 | O14: ='FS-AD Daily '!R19 -> 75.246 | P14: ='FS-AD Daily '!Z19 -> 442.5 | Q14: ='FS-AD Daily '!V19 -> 150.4 | R14: ='FS-AD Daily '!W19 -> 88.61 | S14: =P14-Q14-R14 -> 203.49 | T14: ='FS-AD Daily '!AD19*3.516 -> 40050.756 | U14: =('FS-AD Daily '!AF19)*1000 -> 18100 | V14: =('FS-AD Daily '!AG19)*1000 -> 4900 | W14: ='FS-AD Daily '!AH19*1000 -> 5500 | X14: =('FS-AD Daily '!AK19)*1000 -> 8800 | Y14: 167 | Z14: 233
... A21: Abu Dhabi | B21: =B20+1 -> 20 | C21: 1 | D21: 2020 | E21: ='FS-AD Daily '!B26 -> 6573 | F21: ='FS-AD Daily '!C26 -> 5357 | G21: ='FS-AD Daily '!D26 -> 908 | H21: ='FS-AD Daily '!E26 -> 7472 | I21: ='FS-AD Daily '!F26 -> 5944 | J21: ='FS-AD Daily '!G26 -> 3181 | K21: ='FS-AD Daily '!H26 -> 3644 | L21: ='FS-AD Daily '!I26 -> 2363 | M21: ='FS-AD Daily '!J26 -> 7430 | N21: ='FS-AD Daily '!T26 -> 260.3 | O21: ='FS-AD Daily '!R26 -> 74.803 | P21: ='FS-AD Daily '!Z26 -> 482 | Q21: ='FS-AD Daily '!V26 -> 161.2 | R21: ='FS-AD Daily '!W26 -> 90.54 | S21: =P21-Q21-R21 -> 230.26 | T21: ='FS-AD Daily '!AD26*3.516 -> 58682.04 | U21: =('FS-AD Daily '!AF26)*1000 -> 29000 | V21: =('FS-AD Daily '!AG26)*1000 -> 7500 | W21: ='FS-AD Daily '!AH26*1000 -> 7800 | X21: =('FS-AD Daily '!AK26)*1000 -> 13900 | Y21: 180 | Z21: 291
A22: Abu Dhabi | B22: =B21+1 -> 21 | C22: 1 | D22: 2020 | E22: ='FS-AD Daily '!B27 -> 0 | F22: ='FS-AD Daily '!C27 -> 0 | G22: ='FS-AD Daily '!D27 -> 0 | H22: ='FS-AD Daily '!E27 -> 0 | I22: ='FS-AD Daily '!F27 -> 0 | J22: ='FS-AD Daily '!G27 -> 0 | K22: ='FS-AD Daily '!H27 -> 0 | L22: ='FS-AD Daily '!I27 -> 0 | M22: ='FS-AD Daily '!J27 -> 0 | N22: ='FS-AD Daily '!T27 -> 0 | O22: ='FS-AD Daily '!R27 -> 0 | P22: ='FS-AD Daily '!Z27 -> 0 | Q22: ='FS-AD Daily '!V27 -> 0 | R22: ='FS-AD Daily '!W27 -> 0 | S22: =P22-Q22-R22 -> 0 | T22: ='FS-AD Daily '!AD27*3.516 -> 0 | U22: =('FS-AD Daily '!AF27)*1000 -> 0 | V22: =('FS-AD Daily '!AG27)*1000 -> 0 | W22: ='FS-AD Daily '!AH27*1000 -> 0 | X22: =('FS-AD Daily '!AK27)*1000 -> 0
A23: Abu Dhabi | B23: =B22+1 -> 22 | C23: 1 | D23: 2020 | E23: ='FS-AD Daily '!B28 -> 0 | F23: ='FS-AD Daily '!C28 -> 0 | G23: ='FS-AD Daily '!D28 -> 0 | H23: ='FS-AD Daily '!E28 -> 0 | I23: ='FS-AD Daily '!F28 -> 0 | J23: ='FS-AD Daily '!G28 -> 0 | K23: ='FS-AD Daily '!H28 -> 0 | L23: ='FS-AD Daily '!I28 -> 0 | M23: ='FS-AD Daily '!J28 -> 0 | N23: ='FS-AD Daily '!T28 -> 0 | O23: ='FS-AD Daily '!R28 -> 0 | P23: ='FS-AD Daily '!Z28 -> 0 | Q23: ='FS-AD Daily '!V28 -> 0 | R23: ='FS-AD Daily '!W28 -> 0 | S23: =P23-Q23-R23 -> 0 | T23: ='FS-AD Daily '!AD28*3.516 -> 0 | U23: =('FS-AD Daily '!AF28)*1000 -> 0 | V23: =('FS-AD Daily '!AG28)*1000 -> 0 | W23: ='FS-AD Daily '!AH28*1000 -> 0 | X23: =('FS-AD Daily '!AK28)*1000 -> 0
A24: Abu Dhabi | B24: =B23+1 -> 23 | C24: 1 | D24: 2020 | E24: ='FS-AD Daily '!B29 -> 0 | F24: ='FS-AD Daily '!C29 -> 0 | G24: ='FS-AD Daily '!D29 -> 0 | H24: ='FS-AD Daily '!E29 -> 0 | I24: ='FS-AD Daily '!F29 -> 0 | J24: ='FS-AD Daily '!G29 -> 0 | K24: ='FS-AD Daily '!H29 -> 0 | L24: ='FS-AD Daily '!I29 -> 0 | M24: ='FS-AD Daily '!J29 -> 0 | N24: ='FS-AD Daily '!T29 -> 0 | O24: ='FS-AD Daily '!R29 -> 0 | P24: ='FS-AD Daily '!Z29 -> 0 | Q24: ='FS-AD Daily '!V29 -> 0 | R24: ='FS-AD Daily '!W29 -> 0 | S24: =P24-Q24-R24 -> 0 | T24: ='FS-AD Daily '!AD29*3.516 -> 0 | U24: =('FS-AD Daily '!AF29)*1000 -> 0 | V24: =('FS-AD Daily '!AG29)*1000 -> 0 | W24: ='FS-AD Daily '!AH29*1000 -> 0 | X24: =('FS-AD Daily '!AK29)*1000 -> 0
A25: Abu Dhabi | B25: =B24+1 -> 24 | C25: 1 | D25: 2020 | E25: ='FS-AD Daily '!B30 -> 0 | F25: ='FS-AD Daily '!C30 -> 0 | G25: ='FS-AD Daily '!D30 -> 0 | H25: ='FS-AD Daily '!E30 -> 0 | I25: ='FS-AD Daily '!F30 -> 0 | J25: ='FS-AD Daily '!G30 -> 0 | K25: ='FS-AD Daily '!H30 -> 0 | L25: ='FS-AD Daily '!I30 -> 0 | M25: ='FS-AD Daily '!J30 -> 0 | N25: ='FS-AD Daily '!T30 -> 0 | O25: ='FS-AD Daily '!R30 -> 0 | P25: ='FS-AD Daily '!Z30 -> 0 | Q25: ='FS-AD Daily '!V30 -> 0 | R25: ='FS-AD Daily '!W30 -> 0 | S25: =P25-Q25-R25 -> 0 | T25: ='FS-AD Daily '!AD30*3.516 -> 0 | U25: =('FS-AD Daily '!AF30)*1000 -> 0 | V25: =('FS-AD Daily '!AG30)*1000 -> 0 | W25: ='FS-AD Daily '!AH30*1000 -> 0 | X25: =('FS-AD Daily '!AK30)*1000 -> 0
A26: Abu Dhabi | B26: =B25+1 -> 25 | C26: 1 | D26: 2020 | E26: ='FS-AD Daily '!B31 -> 0 | F26: ='FS-AD Daily '!C31 -> 0 | G26: ='FS-AD Daily '!D31 -> 0 | H26: ='FS-AD Daily '!E31 -> 0 | I26: ='FS-AD Daily '!F31 -> 0 | J26: ='FS-AD Daily '!G31 -> 0 | K26: ='FS-AD Daily '!H31 -> 0 | L26: ='FS-AD Daily '!I31 -> 0 | M26: ='FS-AD Daily '!J31 -> 0 | N26: ='FS-AD Daily '!T31 -> 0 | O26: ='FS-AD Daily '!R31 -> 0 | P26: ='FS-AD Daily '!Z31 -> 0 | Q26: ='FS-AD Daily '!V31 -> 0 | R26: ='FS-AD Daily '!W31 -> 0 | S26: =P26-Q26-R26 -> 0 | T26: ='FS-AD Daily '!AD31*3.516 -> 0 | U26: =('FS-AD Daily '!AF31)*1000 -> 0 | V26: =('FS-AD Daily '!AG31)*1000 -> 0 | W26: ='FS-AD Daily '!AH31*1000 -> 0 | X26: =('FS-AD Daily '!AK31)*1000 -> 0
A27: Abu Dhabi | B27: =B26+1 -> 26 | C27: 1 | D27: 2020 | E27: ='FS-AD Daily '!B32 -> 0 | F27: ='FS-AD Daily '!C32 -> 0 | G27: ='FS-AD Daily '!D32 -> 0 | H27: ='FS-AD Daily '!E32 -> 0 | I27: ='FS-AD Daily '!F32 -> 0 | J27: ='FS-AD Daily '!G32 -> 0 | K27: ='FS-AD Daily '!H32 -> 0 | L27: ='FS-AD Daily '!I32 -> 0 | M27: ='FS-AD Daily '!J32 -> 0 | N27: ='FS-AD Daily '!T32 -> 0 | O27: ='FS-AD Daily '!R32 -> 0 | P27: ='FS-AD Daily '!Z32 -> 0 | Q27: ='FS-AD Daily '!V32 -> 0 | R27: ='FS-AD Daily '!W32 -> 0 | S27: =P27-Q27-R27 -> 0 | T27: ='FS-AD Daily '!AD32*3.516 -> 0 | U27: =('FS-AD Daily '!AF32)*1000 -> 0 | V27: =('FS-AD Daily '!AG32)*1000 -> 0 | W27: ='FS-AD Daily '!AH32*1000 -> 0 | X27: =('FS-AD Daily '!AK32)*1000 -> 0
A28: Abu Dhabi | B28: =B27+1 -> 27 | C28: 1 | D28: 2020 | E28: ='FS-AD Daily '!B33 -> 0 | F28: ='FS-AD Daily '!C33 -> 0 | G28: ='FS-AD Daily '!D33 -> 0 | H28: ='FS-AD Daily '!E33 -> 0 | I28: ='FS-AD Daily '!F33 -> 0 | J28: ='FS-AD Daily '!G33 -> 0 | K28: ='FS-AD Daily '!H33 -> 0 | L28: ='FS-AD Daily '!I33 -> 0 | M28: ='FS-AD Daily '!J33 -> 0 | N28: ='FS-AD Daily '!T33 -> 0 | O28: ='FS-AD Daily '!R33 -> 0 | P28: ='FS-AD Daily '!Z33 -> 0 | Q28: ='FS-AD Daily '!V33 -> 0 | R28: ='FS-AD Daily '!W33 -> 0 | S28: =P28-Q28-R28 -> 0 | T28: ='FS-AD Daily '!AD33*3.516 -> 0 | U28: =('FS-AD Daily '!AF33)*1000 -> 0 | V28: =('FS-AD Daily '!AG33)*1000 -> 0 | W28: ='FS-AD Daily '!AH33*1000 -> 0 | X28: =('FS-AD Daily '!AK33)*1000 -> 0
A29: Abu Dhabi | B29: =B28+1 -> 28 | C29: 1 | D29: 2020 | E29: ='FS-AD Daily '!B34 -> 0 | F29: ='FS-AD Daily '!C34 -> 0 | G29: ='FS-AD Daily '!D34 -> 0 | H29: ='FS-AD Daily '!E34 -> 0 | I29: ='FS-AD Daily '!F34 -> 0 | J29: ='FS-AD Daily '!G34 -> 0 | K29: ='FS-AD Daily '!H34 -> 0 | L29: ='FS-AD Daily '!I34 -> 0 | M29: ='FS-AD Daily '!J34 -> 0 | N29: ='FS-AD Daily '!T34 -> 0 | O29: ='FS-AD Daily '!R34 -> 0 | P29: ='FS-AD Daily '!Z34 -> 0 | Q29: ='FS-AD Daily '!V34 -> 0 | R29: ='FS-AD Daily '!W34 -> 0 | S29: =P29-Q29-R29 -> 0 | T29: ='FS-AD Daily '!AD34*3.516 -> 0 | U29: =('FS-AD Daily '!AF34)*1000 -> 0 | V29: =('FS-AD Daily '!AG34)*1000 -> 0 | W29: ='FS-AD Daily '!AH34*1000 -> 0 | X29: =('FS-AD Daily '!AK34)*1000 -> 0
A30: Abu Dhabi | B30: =B29+1 -> 29 | C30: 1 | D30: 2020 | E30: ='FS-AD Daily '!B35 -> 0 | F30: ='FS-AD Daily '!C35 -> 0 | G30: ='FS-AD Daily '!D35 -> 0 | H30: ='FS-AD Daily '!E35 -> 0 | I30: ='FS-AD Daily '!F35 -> 0 | J30: ='FS-AD Daily '!G35 -> 0 | K30: ='FS-AD Daily '!H35 -> 0 | L30: ='FS-AD Daily '!I35 -> 0 | M30: ='FS-AD Daily '!J35 -> 0 | N30: ='FS-AD Daily '!T35 -> 0 | O30: ='FS-AD Daily '!R35 -> 0 | P30: ='FS-AD Daily '!Z35 -> 0 | Q30: ='FS-AD Daily '!V35 -> 0 | R30: ='FS-AD Daily '!W35 -> 0 | S30: =P30-Q30-R30 -> 0 | T30: ='FS-AD Daily '!AD35*3.516 -> 0 | U30: =('FS-AD Daily '!AF35)*1000 -> 0 | V30: =('FS-AD Daily '!AG35)*1000 -> 0 | W30: ='FS-AD Daily '!AH35*1000 -> 0 | X30: =('FS-AD Daily '!AK35)*1000 -> 0
A31: Abu Dhabi | C31: 1 | D31: 2020 | E31: ='FS-AD Daily '!#REF! -> #REF! | F31: ='FS-AD Daily '!#REF! -> #REF! | G31: ='FS-AD Daily '!#REF! -> #REF! | H31: ='FS-AD Daily '!#REF! -> #REF! | I31: ='FS-AD Daily '!#REF! -> #REF! | J31: ='FS-AD Daily '!#REF! -> #REF! | K31: ='FS-AD Daily '!#REF! -> #REF! | L31: ='FS-AD Daily '!#REF! -> #REF! | ... R31: ='FS-AD Daily '!#REF! -> #REF! | S31: =P31-Q31-R31 -> #REF! | T31: ='FS-AD Daily '!#REF!*3.516 -> #REF! | U31: ='FS-AD Daily '!#REF!*3.516 -> #REF! | V31: =('FS-AD Daily '!#REF!)*1000 -> #REF! | W31: ='FS-AD Daily '!#REF!*1000 -> #REF! | X31: =('FS-AD Daily '!#REF!)*1000 -> #REF!
A32: Abu Dhabi | C32: 1 | D32: 2020 | E32: ='FS-AD Daily '!#REF! -> #REF! | F32: ='FS-AD Daily '!#REF! -> #REF! | G32: ='FS-AD Daily '!#REF! -> #REF! | H32: ='FS-AD Daily '!#REF! -> #REF! | I32: ='FS-AD Daily '!#REF! -> #REF! | J32: ='FS-AD Daily '!#REF! -> #REF! | K32: ='FS-AD Daily '!#REF! -> #REF! | L32: ='FS-AD Daily '!#REF! -> #REF! | ... R32: ='FS-AD Daily '!#REF! -> #REF! | S32: =P32-Q32-R32 -> #REF! | T32: ='FS-AD Daily '!#REF!*3.516 -> #REF! | U32: ='FS-AD Daily '!#REF!*3.516 -> #REF! | V32: =('FS-AD Daily '!#REF!)*1000 -> #REF! | W32: ='FS-AD Daily '!#REF!*1000 -> #REF! | X32: =('FS-AD Daily '!#REF!)*1000 -> #REF!
Y33: =SUM(Y2:Y32) -> 3262 | Z33: =SUM(Z2:Z32) -> 4577

Sheet FS-AD Daily 
A1: DATE | B1: ELECTRICAL METERS | K1: TOTAL CONSUMPTION (kWh) | L1: ELECTRICITY - TOTAL (AED) | M1: Concrete Tank Meter (Daily Consumption) | N1: Fiber tank Meter Cold Water Podium & Galleria Staff Toilet Section 2 | O1: Galleria Hot water Public Area | P1: Water Bulk 3 Meter Galleria (Daily Consumption) section 1 | Q1: Irrigation Tank Meter (Daily Consumption) | R1: Galleria Consumption m3 | S1: GALLERIA WATER TOTAL COST (AED) | T1: WATER METER (Daily Consumption) m3 | U1: FSH WATER (AED) | V1: Hot Water Boiler (Daily Gas Consumption m 3) | W1: Steam Boiler (Daily Gas Consumption m 3) | X1: GAS METERS (Daily Reading) | Z1: GAS (Daily Consumption m 3) | AA1: GAS (AED) | AB1: CHILLED WATER (Daily Reading) Present HT | AC1: CHILLED WATER (Daily Reading) Previous HT | AD1: CHILLED WATER (Daily Consumption) HT | AE1: CHILLED WATER (AED) | AF1: Podium Chilled Water - MWh | AG1: Guest Room Chilled Water MWh | AH1: Residence Chilled Water MWh | AI1: Galleria chilled water MWH Previous | AJ1: Galleria chilled water MWH Present | AK1: Galleria Chilled Water Total MWH | AL1: Galleria Chilled Water Total HT | AM1: CHILLED WATER (AED) | AN1: OCCUPANCY (Room Night) | AO1: TOTAL (AED) | AQ1: THR AED (0.334529) | AR1: MWH = H.TON (1 = 284.34)
A2: 2020 | B2: 1 | C2: 2 | D2: 3 | E2: 4 | F2: 5 | G2: 6 | H2: 7 | I2: 8 | J2: 9 | K2: TOTAL CONSUMPTION (KWH) | L2: TOTAL AMOUNT (AED) | X2: 1 | Y2: 2 | AA2: (AED. 10.02/m3 + AED. 0.50 Service) | AC2: (K21B2419000) | AE2: AED. 0.334569/Ton | AM2: AED. 0.334569/Ton
A3: Meter No. | B3: IT5T14D000335 | C3: IT5T14D000328 | D3: I1C13D005898 | E3: IT5T14D000315 | F3: IT5T14D000345 | G3: IT5T14D000318 | H3: IT5T14D000311 | I3: Residence apartments only | J3: I1C14D009051
A4: Acc. No. | B4: 4626096222-E | C4: 6572482789-E | D4: 3190048503-E | E4: 3732963488-E | F4: 4626096253-E | G4: 7651356710-E | H4: 5076351256-E | I4: 8990986529-E | J4: 6057081392-E
B5: LVS-1 SECTION A | C5: LVS-1 SECTION B | D5: LVS-2 (CAFÉ MILANO) | E5: LVS-3 SECTION A | F5: LVS-3 SECTION B | G5: LVS-4 SECTION A | H5: LVS-4 SECTION B | I5: LVS-5 (FLOOR 15-32) | J5: LVS-LRLV (RETAIL) | Y5: 627742.2 | AB5: 37070630 | AJ5: 33427.1
A6: TOTAL | E6: Hot water calorifiers L 14 feed 15 - 19 floor | G6: Residence Apartment chilled water pump share feeder | H6: Residence Public Area Electric DB share feeder | I6: Residence apartments Electric DB (individual apartment feeder) | X6: Galleria independent supply | AA6: =SUM(#REF!) -> #REF! | AE6: =SUM(#REF!) -> #REF! | AK6: =SUM(#REF!) -> #REF! | AO6: =SUM(#REF!) -> #REF!
A7: 43862 | B7: 6582 | C7: 5752 | D7: 894 | E7: 7009 | F7: 5915 | G7: 3190 | H7: 3956 | I7: 2271 | J7: 6935 | K7: =SUM(B7:H7) -> 33298 | L7: =K7*0.21 -> 6992.58 | M7: 142.125 | N7: 3.552 | O7: 5.309 | P7: 65.922 | Q7: 9.839 | R7: =N7+O7+P7 -> 74.783 | S7: =(N7+O7+P7)*7.84 -> 586.29872 | T7: =M7+Q7 -> 151.964 | U7: =T7*7.84 -> 1191.3978 | V7: 155.1 | W7: 97.42 | X7: 0001523.20 | Y7: 628170.7 | Z7: =IF((Y7-Y6<0), "0",Y7-Y5) -> 428.5 | AA7: =Z7*10.07 -> 4314.995 | AB7: 37082099 | AC7: 37070630 | AD7: =IF((AB7-AC7<0), "0",AB7-AC7) -> 11469 | AE7: =AD7*0.334569 -> 3837.1719 | AF7: 17.8 | AG7: 5.5 | AH7: 5.2 | AI7: 33427.1 | AJ7: 33435.6 | AK7: =IF((AJ7-AI7)<0, "0",AJ7-AI7) -> 8.5 | AL7: =AK7*(284.34513609) -> 2416.9337 | AM7: =AL7*0.334569 -> 808.63108 | AN7: 161 | AO7: =L7+U7+AA7+AE7 -> 16336.145
A8: 43863 | B8: 7082 | C8: 5851 | D8: 897 | E8: 7241 | F8: 5694 | G8: 3179 | H8: 3889 | I8: 2273 | J8: 6755 | K8: =SUM(B8:H8) -> 33833 | L8: =K8*0.21 -> 7104.93 | M8: 306.438 | N8: 3.61 | O8: 5.539 | P8: 69.857 | Q8: 5.88 | R8: =N8+O8+P8 -> 79.006 | S8: =(N8+O8+P8)*7.84 -> 619.40704 | T8: =M8+Q8 -> 312.318 | U8: =T8*7.84 -> 2448.5731 | V8: 135 | W8: 90.5 | X8: 0001523.20 | Y8: 628568.1 | Z8: =IF((Y8-Y7<0), "0",Y8-Y7) -> 397.4 | AA8: =Z8*10.07 -> 4001.818 | AB8: 37094495 | AC8: =AB7 -> 37082099 | AD8: =IF((AB8-AC8<0), "0",AB8-AC8) -> 12396 | AE8: =AD8*0.334569 -> 4147.3173 | AF8: 19.5 | AG8: 5.7 | AH8: 6.2 | AI8: =AJ7 -> 33435.6 | AJ8: 33445.1 | AK8: =IF((AJ8-AI8)<0, "0",AJ8-AI8) -> 9.5 | AL8: =AK8*(284.34513609) -> 2701.2788 | AM8: =AL8*0.334569 -> 903.76414 | AN8: 161 | AO8: =L8+U8+AA8+AE8 -> 17702.638
A9: 43864 | B9: 8556 | C9: 5895 | D9: 896 | E9: 7150 | F9: 5910 | G9: 3250 | H9: 3940 | I9: 2199 | J9: 7078 | K9: =SUM(B9:H9) -> 35597 | L9: =K9*0.21 -> 7475.37 | M9: 199.318 | N9: 2.439 | O9: 4.447 | P9: 55.823 | Q9: 7.215 | R9: =N9+O9+P9 -> 62.709 | S9: =(N9+O9+P9)*7.84 -> 491.63856 | T9: =M9+Q9 -> 206.533 | U9: =T9*7.84 -> 1619.2187 | V9: 139.7 | W9: =125281.53-125191.44 -> 90.09 | X9: 0001523.20 | Y9: 628974.8 | Z9: =IF((Y9-Y8<0), "0",Y9-Y8) -> 406.7 | AA9: =Z9*10.07 -> 4095.469 | AB9: 37106375 | AC9: =AB8 -> 37094495 | AD9: =IF((AB9-AC9<0), "0",AB9-AC9) -> 11880 | AE9: =AD9*0.334569 -> 3974.6797 | AF9: 18.9 | AG9: 5.5 | AH9: 6.3 | AI9: =AJ8 -> 33445.1 | AJ9: 33454.2 | AK9: =IF((AJ9-AI9)<0, "0",AJ9-AI9) -> 9.1 | AL9: =AK9*(284.34513609) -> 2587.5407 | AM9: =AL9*0.334569 -> 865.71092 | AN9: 176 | AO9: =L9+U9+AA9+AE9 -> 17164.737
A10: 43865 | B10: 9022 | C10: 5598 | D10: 874 | E10: 7167 | F10: 5970 | G10: 3224 | H10: 3640 | I10: 2165 | J10: 6981 | K10: =SUM(B10:H10) -> 35495 | L10: =K10*0.21 -> 7453.95 | M10: 213.443 | N10: 4.128 | O10: 5.599 | P10: 58.691 | Q10: 5.773 | R10: =N10+O10+P10 -> 68.418 | S10: =(N10+O10+P10)*7.84 -> 536.39712 | T10: =M10+Q10 -> 219.216 | U10: =T10*7.84 -> 1718.6534 | V10: 136.9 | W10: 89.36 | X10: 0001523.20 | Y10: 629378.6 | Z10: =IF((Y10-Y9<0), "0",Y10-Y9) -> 403.8 | AA10: =Z10*10.07 -> 4066.266 | AB10: 37118503 | AC10: =AB9 -> 37106375 | AD10: =IF((AB10-AC10<0), "0",AB10-AC10) -> 12128 | AE10: =AD10*0.334569 -> 4057.6528 | AF10: 19.2 | AG10: 5.6 | AH10: 6.4 | AI10: =AJ9 -> 33454.2 | AJ10: 33463.5 | AK10: =IF((AJ10-AI10)<0, "0",AJ10-AI10) -> 9.3 | AL10: =AK10*(284.34513609) -> 2644.4098 | AM10: =AL10*0.334569 -> 884.73753 | AN10: 177 | AO10: =L10+U10+AA10+AE10 -> 17296.522
A11: 43866 | B11: 6806 | C11: 5276 | D11: 897 | E11: 7120 | F11: 6070 | G11: 3248 | H11: 3579 | I11: 2135 | J11: 7016 | K11: =SUM(B11:H11) -> 32996 | L11: =K11*0.21 -> 6929.16 | M11: 196.534 | N11: 7.89 | O11: 5.536 | P11: 67.961 | Q11: 6.534 | R11: =N11+O11+P11 -> 81.387 | S11: =(N11+O11+P11)*7.84 -> 638.07408 | T11: =M11+Q11 -> 203.068 | U11: =T11*7.84 -> 1592.0531 | V11: 135.4 | W11: 92.7 | X11: 0001523.20 | Y11: 629777.6 | Z11: =IF((Y11-Y10<0), "0",Y11-Y10) -> 399 | AA11: =Z11*10.07 -> 4017.93 | AB11: 37131153 | AC11: =AB10 -> 37118503 | AD11: =IF((AB11-AC11<0), "0",AB11-AC11) -> 12650 | AE11: =AD11*0.334569 -> 4232.2978 | AF11: 20.4 | AG11: 5.7 | AH11: 6 | AI11: =AJ10 -> 33463.5 | AJ11: 33474.2 | AK11: =IF((AJ11-AI11)<0, "0",AJ11-AI11) -> 10.7 | AL11: =AK11*(284.34513609) -> 3042.493 | AM11: =AL11*0.334569 -> 1017.9238 | AN11: 171 | AO11: =L11+U11+AA11+AE11 -> 16771.441
A12: 43867 | B12: 6241 | C12: 5372 | D12: 958 | E12: 7214 | F12: 6022 | G12: 3304 | H12: 3558 | I12: 2196 | J12: 7301 | K12: =SUM(B12:H12) -> 32669 | L12: =K12*0.21 -> 6860.49 | M12: 211.703 | N12: 4.284 | O12: 3.696 | P12: 63.49 | Q12: 8.479 | R12: =N12+O12+P12 -> 71.47 | S12: =(N12+O12+P12)*7.84 -> 560.3248 | T12: =M12+Q12 -> 220.182 | U12: =T12*7.84 -> 1726.2269 | V12: 137.6 | W12: 91.48 | X12: 0001523.20 | Y12: 630183.7 | Z12: =IF((Y12-Y11<0), "0",Y12-Y11) -> 406.1 | AA12: =Z12*10.07 -> 4089.427 | AB12: 37145006 | AC12: =AB11 -> 37131153 | AD12: =IF((AB12-AC12<0), "0",AB12-AC12) -> 13853 | AE12: =AD12*0.334569 -> 4634.7844 | AF12: 22.7 | AG12: 6.2 | AH12: 7.1 | AI12: =AJ11 -> 33474.2 | AJ12: 33487 | AK12: =IF((AJ12-AI12)<0, "0",AJ12-AI12) -> 12.8 | AL12: =AK12*(284.34513609) -> 3639.6177 | AM12: =AL12*0.334569 -> 1217.7033 | AN12: 124 | AO12: =L12+U12+AA12+AE12 -> 17310.928
A13: 43868 | B13: 5961 | C13: 5964 | D13: 869 | E13: 6852 | F13: 6095 | G13: 3218 | H13: 3528 | I13: 2091 | J13: 6894 | K13: =SUM(B13:H13) -> 32487 | L13: =K13*0.21 -> 6822.27 | M13: 194.449 | N13: 2.844 | O13: 4.384 | P13: 69.704 | Q13: 4.543 | R13: =N13+O13+P13 -> 76.932 | S13: =(N13+O13+P13)*7.84 -> 603.14688 | T13: =M13+Q13 -> 198.992 | U13: =T13*7.84 -> 1560.0973 | V13: 140.3 | W13: 85.81 | X13: 0001523.20 | Y13: 630604.4 | Z13: =IF((Y13-Y12<0), "0",Y13-Y12) -> 420.7 | AA13: =Z13*10.07 -> 4236.449 | AB13: 37159254 | AC13: =AB12 -> 37145006 | AD13: =IF((AB13-AC13<0), "0",AB13-AC13) -> 14248 | AE13: =AD13*0.334569 -> 4766.9391 | AF13: 23.2 | AG13: 6.8 | AH13: 7.8 | AI13: =AJ12 -> 33487 | AJ13: 33500 | AK13: =IF((AJ13-AI13)<0, "0",AJ13-AI13) -> 13 | AL13: =AK13*(284.34513609) -> 3696.4868 | AM13: =AL13*0.334569 -> 1236.7299 | AN13: 141 | AO13: =L13+U13+AA13+AE13 -> 17385.755
A14: 43869 | B14: 5554 | C14: 5160 | D14: 907 | E14: 6942 | F14: 5893 | G14: 3253 | H14: 3602 | I14: 2276 | J14: 6891 | K14: =SUM(B14:H14) -> 31311 | L14: =K14*0.21 -> 6575.31 | M14: 209.152 | N14: 7.348 | O14: 5.152 | P14: 67.187 | Q14: 4.979 | R14: 4.9 | S14: =(N14+O14+P14)*7.84 -> 624.74608 | T14: =M14+Q14 -> 214.131 | U14: =T14*7.84 -> 1678.787 | V14: 140.6 | W14: 83.15 | X14: 0001523.20 | Y14: 631005.2 | Z14: =IF((Y14-Y13<0), "0",Y14-Y13) -> 400.8 | AA14: =Z14*10.07 -> 4036.056 | AB14: 37173670 | AC14: =AB13 -> 37159254 | AD14: =IF((AB14-AC14<0), "0",AB14-AC14) -> 14416 | AE14: =AD14*0.334569 -> 4823.1467 | AF14: 22.7 | AG14: 7.2 | AH14: 8.5 | AI14: =AJ13 -> 33500 | AJ14: 33513.6 | AK14: =IF((AJ14-AI14)<0, "0",AJ14-AI14) -> 13.6 | AL14: =AK14*(284.34513609) -> 3867.0939 | AM14: =AL14*0.334569 -> 1293.8097 | AN14: 163 | AO14: =L14+U14+AA14+AE14 -> 17113.3
A15: 43870 | B15: 7186 | C15: 5593 | D15: 887 | E15: 7052 | F15: 6108 | G15: 3175 | H15: 3543 | I15: 2250 | J15: 7039 | K15: =SUM(B15:H15) -> 33544 | L15: =K15*0.21 -> 7044.24 | M15: 204.362 | N15: 4.91 | O15: 4.89 | P15: 56.048 | Q15: 11.967 | R15: =N15+O15+P15 -> 65.848 | S15: =(N15+O15+P15)*7.84 -> 516.24832 | T15: =M15+Q15 -> 216.329 | U15: =T15*7.84 -> 1696.0194 | V15: 148.3 | W15: 86.6 | X15: 0001523.20 | Y15: 631407.2 | Z15: =IF((Y15-Y14<0), "0",Y15-Y14) -> 402 | AA15: =Z15*10.07 -> 4048.14 | AB15: 37188893 | AC15: =AB14 -> 37173670 | AD15: =IF((AB15-AC15<0), "0",AB15-AC15) -> 15223 | AE15: =AD15*0.334569 -> 5093.1439 | AF15: 25.4 | AG15: 7.5 | AH15: 7.7 | AI15: =AJ14 -> 33513.6 | AJ15: 33526.3 | AK15: =IF((AJ15-AI15)<0, "0",AJ15-AI15) -> 12.7 | AL15: =AK15*(284.34513609) -> 3611.1832 | AM15: =AL15*0.334569 -> 1208.19 | AN15: 173 | AO15: =L15+U15+AA15+AE15 -> 17881.543
A16: 43871 | B16: 6317 | C16: 5797 | D16: 891 | E16: 7195 | F16: 6216 | G16: 3202 | H16: 3648 | I16: 2290 | J16: 7236 | K16: =SUM(B16:H16) -> 33266 | L16: =K16*0.21 -> 6985.86 | M16: 217.251 | N16: 4.261 | O16: 5.56 | P16: 53.412 | Q16: 5.08 | R16: =N16+O16+P16 -> 63.233 | S16: =(N16+O16+P16)*7.84 -> 495.74672 | T16: =M16+Q16 -> 222.331 | U16: =T16*7.84 -> 1743.075 | V16: 162.3 | W16: 92.74 | X16: 0001523.20 | Y16: 631850.6 | Z16: =IF((Y16-Y15<0), "0",Y16-Y15) -> 443.4 | AA16: =Z16*10.07 -> 4465.038 | AB16: 37204832 | AC16: =AB15 -> 37188893 | AD16: =IF((AB16-AC16<0), "0",AB16-AC16) -> 15939 | AE16: =AD16*0.334569 -> 5332.6953 | AF16: 27.3 | AG16: 7.5 | AH16: 7.7 | AI16: =AJ15 -> 33526.3 | AJ16: 33540.2 | AK16: =IF((AJ16-AI16)<0, "0",AJ16-AI16) -> 13.9 | AL16: =AK16*(284.34513609) -> 3952.3974 | AM16: =AL16*0.334569 -> 1322.3496 | AN16: 190 | AO16: =L16+U16+AA16+AE16 -> 18526.668
A17: 43872 | B17: 6929 | C17: 5298 | D17: 873 | E17: 6938 | F17: 6074 | G17: 2988 | H17: 3555 | I17: 2239 | J17: 6847 | K17: =SUM(B17:H17) -> 32655 | L17: =K17*0.21 -> 6857.55 | M17: 218.441 | N17: 3.885 | O17: 5.313 | P17: 56.586 | Q17: 7.593 | R17: =N17+O17+P17 -> 65.784 | S17: =(N17+O17+P17)*7.84 -> 515.74656 | T17: =M17+Q17 -> 226.034 | U17: =T17*7.84 -> 1772.1066 | V17: 138.5 | W17: 92.58 | X17: 0001523.20 | Y17: 632246.7 | Z17: =IF((Y17-Y16<0), "0",Y17-Y16) -> 396.1 | AA17: =Z17*10.07 -> 3988.727 | AB17: 37217946 | AC17: =AB16 -> 37204832 | AD17: =IF((AB17-AC17<0), "0",AB17-AC17) -> 13114 | AE17: =AD17*0.334569 -> 4387.5379 | AF17: 21.7 | AG17: 5.8 | AH17: 6.4 | AI17: =AJ16 -> 33540.2 | AJ17: 33551.6 | AK17: =IF((AJ17-AI17)<0, "0",AJ17-AI17) -> 11.4 | AL17: =AK17*(284.34513609) -> 3241.5346 | AM17: =AL17*0.334569 -> 1084.517 | AN17: 195 | AO17: =L17+U17+AA17+AE17 -> 17005.921
A18: 43873 | B18: 8221 | C18: 5978 | D18: 759 | E18: 7085 | F18: 6114 | G18: 3078 | H18: 3515 | I18: 2202 | J18: 6908 | K18: =SUM(B18:H18) -> 34750 | L18: =K18*0.21 -> 7297.5 | M18: 216.198 | N18: 5.129 | O18: 5.017 | P18: 66.335 | Q18: 16.979 | R18: =N18+O18+P18 -> 76.481 | S18: =(N18+O18+P18)*7.84 -> 599.61104 | T18: =M18+Q18 -> 233.177 | U18: =T18*7.84 -> 1828.1077 | V18: 128.9 | W18: 89.84 | X18: 0001523.20 | Y18: 632617.8 | Z18: =IF((Y18-Y17<0), "0",Y18-Y17) -> 371.1 | AA18: =Z18*10.07 -> 3736.977 | AB18: 37228588 | AC18: =AB17 -> 37217946 | AD18: =IF((AB18-AC18<0), "0",AB18-AC18) -> 10642 | AE18: =AD18*0.334569 -> 3560.4833 | AF18: 16.4 | AG18: 4.4 | AH18: 5.4 | AI18: =AJ17 -> 33551.6 | AJ18: 33560.2 | AK18: =IF((AJ18-AI18)<0, "0",AJ18-AI18) -> 8.6 | AL18: =AK18*(284.34513609) -> 2445.3682 | AM18: =AL18*0.334569 -> 818.14438 | AN18: 190 | AO18: =L18+U18+AA18+AE18 -> 16423.068
A19: 43874 | B19: 8972 | C19: 5799 | D19: 930 | E19: 7381 | F19: 6118 | G19: 3244 | H19: 3549 | I19: 2203 | J19: 7358 | K19: =SUM(B19:H19) -> 35993 | L19: =K19*0.21 -> 7558.53 | M19: 222.22 | N19: 4.298 | O19: 5.191 | P19: 65.757 | Q19: 8.258 | R19: =N19+O19+P19 -> 75.246 | S19: =(N19+O19+P19)*7.84 -> 589.92864 | T19: =M19+Q19 -> 230.478 | U19: =T19*7.84 -> 1806.9475 | V19: 150.4 | W19: 88.61 | X19: 0001523.20 | Y19: 633060.3 | Z19: =IF((Y19-Y18<0), "0",Y19-Y18) -> 442.5 | AA19: =Z19*10.07 -> 4455.975 | AB19: 37239979 | AC19: =AB18 -> 37228588 | AD19: =IF((AB19-AC19<0), "0",AB19-AC19) -> 11391 | AE19: =AD19*0.334569 -> 3811.0755 | AF19: 18.1 | AG19: 4.9 | AH19: 5.5 | AI19: =AJ18 -> 33560.2 | AJ19: 33569 | AK19: =IF((AJ19-AI19)<0, "0",AJ19-AI19) -> 8.8 | AL19: =AK19*(284.34513609) -> 2502.2372 | AM19: =AL19*0.334569 -> 837.171 | AN19: 167 | AO19: =L19+U19+AA19+AE19 -> 17632.528
A20: 43875 | B20: 9260 | C20: 5635 | D20: 909 | E20: 7611 | F20: 6260 | G20: 3138 | H20: 3543 | I20: 2235 | J20: 7453 | K20: =SUM(B20:H20) -> 36356 | L20: =K20*0.21 -> 7634.76 | M20: 229.182 | N20: 5.277 | O20: 5.357 | P20: 70.739 | Q20: 4.74 | R20: =N20+O20+P20 -> 81.373 | S20: =(N20+O20+P20)*7.84 -> 637.96432 | T20: =M20+Q20 -> 233.922 | U20: =T20*7.84 -> 1833.9485 | V20: 155.8 | W20: 96.19 | X20: 0001523.20 | Y20: 633514 | Z20: =IF((Y20-Y19<0), "0",Y20-Y19) -> 453.7 | AA20: =Z20*10.07 -> 4568.759 | AB20: 37251750 | AC20: =AB19 -> 37239979 | AD20: =IF((AB20-AC20<0), "0",AB20-AC20) -> 11771 | AE20: =AD20*0.334569 -> 3938.2117 | AF20: 18.5 | AG20: 5.3 | AH20: 5.6 | AI20: =AJ19 -> 33569 | AJ20: 33578.8 | AK20: =IF((AJ20-AI20)<0, "0",AJ20-AI20) -> 9.8 | AL20: =AK20*(284.34513609) -> 2786.5823 | AM20: =AL20*0.334569 -> 932.30406 | AN20: 158 | AO20: =L20+U20+AA20+AE20 -> 17975.679
A21: 43876 | B21: 8002 | C21: 4552 | D21: 923 | E21: 7109 | F21: 5701 | G21: 3024 | H21: 3433 | I21: 2335 | J21: 7115 | K21: =SUM(B21:H21) -> 32744 | L21: =K21*0.21 -> 6876.24 | M21: 205.9 | N21: 6.6 | O21: 4.6 | P21: 71.4 | Q21: 9.4 | R21: =N21+O21+P21 -> 82.6 | S21: =(N21+O21+P21)*7.84 -> 647.584 | T21: =M21+Q21 -> 215.3 | U21: =T21*7.84 -> 1687.952 | V21: 126.2 | W21: 91.8 | X21: 0001523.20 | Y21: 633902.5 | Z21: =IF((Y21-Y20<0), "0",Y21-Y20) -> 388.5 | AA21: =Z21*10.07 -> 3912.195 | AB21: 37263731 | AC21: =AB20 -> 37251750 | AD21: =IF((AB21-AC21<0), "0",AB21-AC21) -> 11981 | AE21: =AD21*0.334569 -> 4008.4712 | AF21: 18.1 | AG21: 5.5 | AH21: 5.9 | AI21: =AJ20 -> 33578.8 | AJ21: 33589.9 | AK21: =IF((AJ21-AI21)<0, "0",AJ21-AI21) -> 11.1 | AL21: =AK21*(284.34513609) -> 3156.231 | AM21: =AL21*0.334569 -> 1055.9771 | AN21: 141 | AO21: =L21+U21+AA21+AE21 -> 16484.858
A22: 43877 | B22: 6263 | C22: 5278 | D22: 907 | E22: 7327 | F22: 5812 | G22: 3015 | H22: 3562 | I22: 2233 | J22: 7017 | K22: =SUM(B22:H22) -> 32164 | L22: =K22*0.21 -> 6754.44 | M22: 209.7 | N22: 4.4 | O22: 4.6 | P22: 60.5 | Q22: 3.5 | R22: =N22+O22+P22 -> 69.5 | S22: =(N22+O22+P22)*7.84 -> 544.88 | T22: =M22+Q22 -> 213.2 | U22: =T22*7.84 -> 1671.488 | V22: 138.6 | W22: 93.2 | X22: 0001523.20 | Y22: 634306 | Z22: =IF((Y22-Y21<0), "0",Y22-Y21) -> 403.5 | AA22: =Z22*10.07 -> 4063.245 | AB22: 37276585 | AC22: =AB21 -> 37263731 | AD22: =IF((AB22-AC22<0), "0",AB22-AC22) -> 12854 | AE22: =AD22*0.334569 -> 4300.5499 | AF22: 21.5 | AG22: 6 | AH22: 6.4 | AI22: =AJ21 -> 33589.9 | AJ22: 33602.5 | AK22: =IF((AJ22-AI22)<0, "0",AJ22-AI22) -> 12.6 | AL22: =AK22*(284.34513609) -> 3582.7487 | AM22: =AL22*0.334569 -> 1198.6767 | AN22: 139 | AO22: =L22+U22+AA22+AE22 -> 16789.723
A23: 43878 | B23: 5957 | C23: 5236 | D23: 922 | E23: 6990 | F23: 5713 | G23: 2918 | H23: 3567 | I23: 2211 | J23: 6929 | K23: =SUM(B23:H23) -> 31303 | L23: =K23*0.21 -> 6573.63 | M23: 188.8 | N23: 6.5 | O23: 4.8 | P23: 59.1 | Q23: 2.7 | R23: =N23+O23+P23 -> 70.4 | S23: =(N23+O23+P23)*7.84 -> 551.936 | T23: =M23+Q23 -> 191.5 | U23: =T23*7.84 -> 1501.36 | V23: 125.4 | W23: 85.4 | X23: 0001523.20 | Y23: 634706.9 | Z23: =IF((Y23-Y22<0), "0",Y23-Y22) -> 400.9 | AA23: =Z23*10.07 -> 4037.063 | AB23: 37290995 | AC23: =AB22 -> 37276585 | AD23: =IF((AB23-AC23<0), "0",AB23-AC23) -> 14410 | AE23: =AD23*0.334569 -> 4821.1393 | AF23: 23.2 | AG23: 6.9 | AH23: 6.7 | AI23: =AJ22 -> 33602.5 | AJ23: 33615.2 | AK23: =IF((AJ23-AI23)<0, "0",AJ23-AI23) -> 12.7 | AL23: =AK23*(284.34513609) -> 3611.1832 | AM23: =AL23*0.334569 -> 1208.19 | AN23: 137 | AO23: =L23+U23+AA23+AE23 -> 16933.192
A24: 43879 | B24: 6866 | C24: 5557 | D24: 886 | E24: 6990 | F24: 5691 | G24: 2915 | H24: 3540 | I24: 2299 | J24: 5911 | K24: =SUM(B24:H24) -> 32445 | L24: =K24*0.21 -> 6813.45 | M24: 206.2 | N24: 3.6 | O24: 4.6 | P24: 55.2 | Q24: 5.7 | R24: =N24+O24+P24 -> 63.4 | S24: =(N24+O24+P24)*7.84 -> 497.056 | T24: =M24+Q24 -> 211.9 | U24: =T24*7.84 -> 1661.296 | V24: 146.2 | W24: 100.7 | X24: 0001523.20 | Y24: 635103 | Z24: =IF((Y24-Y23<0), "0",Y24-Y23) -> 396.1 | AA24: =Z24*10.07 -> 3988.727 | AB24: 37305637 | AC24: =AB23 -> 37290995 | AD24: =IF((AB24-AC24<0), "0",AB24-AC24) -> 14642 | AE24: =AD24*0.334569 -> 4898.7593 | AF24: 24.5 | AG24: 6.9 | AH24: 6.7 | AI24: =AJ23 -> 33615.2 | AJ24: 33627 | AK24: =IF((AJ24-AI24)<0, "0",AJ24-AI24) -> 11.8 | AL24: =AK24*(284.34513609) -> 3355.2726 | AM24: =AL24*0.334569 -> 1122.5702 | AN24: 139 | AO24: =L24+U24+AA24+AE24 -> 17362.232
A25: 43880 | B25: 6809 | C25: 5270 | D25: 889 | E25: 7168 | F25: 5763 | G25: 3107 | H25: 3590 | I25: 2384 | J25: 8152 | K25: =SUM(B25:H25) -> 32596 | L25: =K25*0.21 -> 6845.16 | M25: 218.874 | N25: 2.91 | O25: 4.797 | P25: 61.052 | Q25: 9.417 | R25: =N25+O25+P25 -> 68.759 | S25: =(N25+O25+P25)*7.84 -> 539.07056 | T25: =M25+Q25 -> 228.291 | U25: =T25*7.84 -> 1789.8014 | V25: 145.9 | W25: 93.23 | X25: 0001523.20 | Y25: 635521.7 | Z25: =IF((Y25-Y24<0), "0",Y25-Y24) -> 418.7 | AA25: =Z25*10.07 -> 4216.309 | AB25: 37320954 | AC25: =AB24 -> 37305637 | AD25: =IF((AB25-AC25<0), "0",AB25-AC25) -> 15317 | AE25: =AD25*0.334569 -> 5124.5934 | AF25: 25.6 | AG25: 7.3 | AH25: 7.1 | AI25: =AJ24 -> 33627 | AJ25: 33639.5 | AK25: =IF((AJ25-AI25)<0, "0",AJ25-AI25) -> 12.5 | AL25: =AK25*(284.34513609) -> 3554.3142 | AM25: =AL25*0.334569 -> 1189.1633 | AN25: 180 | AO25: =L25+U25+AA25+AE25 -> 17975.864
A26: 43881 | B26: 6573 | C26: 5357 | D26: 908 | E26: 7472 | F26: 5944 | G26: 3181 | H26: 3644 | I26: 2363 | J26: 7430 | K26: =SUM(B26:H26) -> 33079 | L26: =K26*0.21 -> 6946.59 | M26: 252.541 | N26: 3.643 | O26: 4.792 | P26: 66.368 | Q26: 7.759 | R26: =N26+O26+P26 -> 74.803 | S26: =(N26+O26+P26)*7.84 -> 586.45552 | T26: =M26+Q26 -> 260.3 | U26: =T26*7.84 -> 2040.752 | V26: 161.2 | W26: 90.54 | X26: 0001523.20 | Y26: 636003.7 | Z26: =IF((Y26-Y25<0), "0",Y26-Y25) -> 482 | AA26: =Z26*10.07 -> 4853.74 | AB26: 37337644 | AC26: =AB25 -> 37320954 | AD26: =IF((AB26-AC26<0), "0",AB26-AC26) -> 16690 | AE26: =AD26*0.334569 -> 5583.9566 | AF26: 29 | AG26: 7.5 | AH26: 7.8 | AI26: =AJ25 -> 33639.5 | AJ26: 33653.4 | AK26: =IF((AJ26-AI26)<0, "0",AJ26-AI26) -> 13.9 | AL26: =AK26*(284.34513609) -> 3952.3974 | AM26: =AL26*0.334569 -> 1322.3496 | AN26: 169 | AO26: =L26+U26+AA26+AE26 -> 19425.039
A27: 43882 | K27: =SUM(B27:H27) -> 0 | L27: =K27*0.21 -> 0 | R27: =N27+O27+P27 -> 0 | S27: =(N27+O27+P27)*7.84 -> 0 | T27: =M27+Q27 -> 0 | U27: =T27*7.84 -> 0 | X27: 0001523.20 | Z27: =IF((Y27-Y26<0), "0",Y27-Y26) -> 0 | AA27: =Z27*10.07 -> 0 | AC27: =AB26 -> 37337644 | AD27: =IF((AB27-AC27<0), "0",AB27-AC27) -> 0 | AE27: =AD27*0.334569 -> 0 | AI27: =AJ26 -> 33653.4 | AK27: =IF((AJ27-AI27)<0, "0",AJ27-AI27) -> 0 | AL27: =AK27*(284.34513609) -> 0 | AM27: =AL27*0.334569 -> 0 | AO27: =L27+U27+AA27+AE27 -> 0
A28: 43883 | K28: =SUM(B28:H28) -> 0 | L28: =K28*0.21 -> 0 | R28: =N28+O28+P28 -> 0 | S28: =(N28+O28+P28)*7.84 -> 0 | T28: =M28+Q28 -> 0 | U28: =T28*7.84 -> 0 | X28: 0001523.20 | Z28: =IF((Y28-Y27<0), "0",Y28-Y27) -> 0 | AA28: =Z28*10.07 -> 0 | AC28: =AB27 -> 0 | AD28: =IF((AB28-AC28<0), "0",AB28-AC28) -> 0 | AE28: =AD28*0.334569 -> 0 | AI28: =AJ27 -> 0 | AK28: =IF((AJ28-AI28)<0, "0",AJ28-AI28) -> 0 | AL28: =AK28*(284.34513609) -> 0 | AM28: =AL28*0.334569 -> 0 | AO28: =L28+U28+AA28+AE28 -> 0
A29: 43884 | K29: =SUM(B29:H29) -> 0 | L29: =K29*0.21 -> 0 | R29: =N29+O29+P29 -> 0 | S29: =(N29+O29+P29)*7.84 -> 0 | T29: =M29+Q29 -> 0 | U29: =T29*7.84 -> 0 | X29: 0001523.20 | Z29: =IF((Y29-Y28<0), "0",Y29-Y28) -> 0 | AA29: =Z29*10.07 -> 0 | AC29: =AB28 -> 0 | AD29: =IF((AB29-AC29<0), "0",AB29-AC29) -> 0 | AE29: =AD29*0.334569 -> 0 | AI29: =AJ28 -> 0 | AK29: =IF((AJ29-AI29)<0, "0",AJ29-AI29) -> 0 | AL29: =AK29*(284.34513609) -> 0 | AM29: =AL29*0.334569 -> 0 | AO29: =L29+U29+AA29+AE29 -> 0
A30: 43885 | K30: =SUM(B30:H30) -> 0 | L30: =K30*0.21 -> 0 | R30: =N30+O30+P30 -> 0 | S30: =(N30+O30+P30)*7.84 -> 0 | T30: =M30+Q30 -> 0 | U30: =T30*7.84 -> 0 | X30: 0001523.20 | Z30: =IF((Y30-Y29<0), "0",Y30-Y29) -> 0 | AA30: =Z30*10.07 -> 0 | AC30: =AB29 -> 0 | AD30: =IF((AB30-AC30<0), "0",AB30-AC30) -> 0 | AE30: =AD30*0.334569 -> 0 | AI30: =AJ29 -> 0 | AK30: =IF((AJ30-AI30)<0, "0",AJ30-AI30) -> 0 | AL30: =AK30*(284.34513609) -> 0 | AM30: =AL30*0.334569 -> 0 | AO30: =L30+U30+AA30+AE30 -> 0
A31: 43886 | K31: =SUM(B31:H31) -> 0 | L31: =K31*0.21 -> 0 | R31: =N31+O31+P31 -> 0 | S31: =(N31+O31+P31)*7.84 -> 0 | T31: =M31+Q31 -> 0 | U31: =T31*7.84 -> 0 | X31: 0001523.20 | Z31: =IF((Y31-Y30<0), "0",Y31-Y30) -> 0 | AA31: =Z31*10.07 -> 0 | AC31: =AB30 -> 0 | AD31: =IF((AB31-AC31<0), "0",AB31-AC31) -> 0 | AE31: =AD31*0.334569 -> 0 | AI31: =AJ30 -> 0 | AK31: =IF((AJ31-AI31)<0, "0",AJ31-AI31) -> 0 | AL31: =AK31*(284.34513609) -> 0 | AM31: =AL31*0.334569 -> 0 | AO31: =L31+U31+AA31+AE31 -> 0
A32: 43887 | K32: =SUM(B32:H32) -> 0 | L32: =K32*0.21 -> 0 | R32: =N32+O32+P32 -> 0 | S32: =(N32+O32+P32)*7.84 -> 0 | T32: =M32+Q32 -> 0 | U32: =T32*7.84 -> 0 | X32: 0001523.20 | Z32: =IF((Y32-Y31<0), "0",Y32-Y31) -> 0 | AA32: =Z32*10.07 -> 0 | AC32: =AB31 -> 0 | AD32: =IF((AB32-AC32<0), "0",AB32-AC32) -> 0 | AE32: =AD32*0.334569 -> 0 | AI32: =AJ31 -> 0 | AK32: =IF((AJ32-AI32)<0, "0",AJ32-AI32) -> 0 | AL32: =AK32*(284.34513609) -> 0 | AM32: =AL32*0.334569 -> 0 | AO32: =L32+U32+AA32+AE32 -> 0
A33: 43888 | K33: =SUM(B33:H33) -> 0 | L33: =K33*0.21 -> 0 | R33: =N33+O33+P33 -> 0 | S33: =(N33+O33+P33)*7.84 -> 0 | T33: =M33+Q33 -> 0 | U33: =T33*7.84 -> 0 | X33: 0001523.20 | Z33: =IF((Y33-Y32<0), "0",Y33-Y32) -> 0 | AA33: =Z33*10.07 -> 0 | AC33: =AB32 -> 0 | AD33: =IF((AB33-AC33<0), "0",AB33-AC33) -> 0 | AE33: =AD33*0.334569 -> 0 | AI33: =AJ32 -> 0 | AK33: =IF((AJ33-AI33)<0, "0",AJ33-AI33) -> 0 | AL33: =AK33*(284.34513609) -> 0 | AM33: =AL33*0.334569 -> 0 | AO33: =L33+U33+AA33+AE33 -> 0
A34: 43889 | K34: =SUM(B34:H34) -> 0 | L34: =K34*0.21 -> 0 | R34: =N34+O34+P34 -> 0 | S34: =(N34+O34+P34)*7.84 -> 0 | T34: =M34+Q34 -> 0 | U34: =T34*7.84 -> 0 | X34: 0001523.20 | Z34: =IF((Y34-Y33<0), "0",Y34-Y33) -> 0 | AA34: =Z34*10.07 -> 0 | AC34: =AB33 -> 0 | AD34: =IF((AB34-AC34<0), "0",AB34-AC34) -> 0 | AE34: =AD34*0.334569 -> 0 | AI34: =AJ33 -> 0 | AK34: =IF((AJ34-AI34)<0, "0",AJ34-AI34) -> 0 | AL34: =AK34*(284.34513609) -> 0 | AM34: =AL34*0.334569 -> 0 | AO34: =L34+U34+AA34+AE34 -> 0
A35: 43890 | K35: =SUM(B35:H35) -> 0 | L35: =K35*0.21 -> 0 | R35: =N35+O35+P35 -> 0 | S35: =(N35+O35+P35)*7.84 -> 0 | T35: =M35+Q35 -> 0 | U35: =T35*7.84 -> 0 | X35: 0001523.20 | Z35: =IF((Y35-Y34<0), "0",Y35-Y34) -> 0 | AA35: =Z35*10.07 -> 0 | AC35: =AB34 -> 0 | AD35: =IF((AB35-AC35<0), "0",AB35-AC35) -> 0 | AE35: =AD35*0.334569 -> 0 | AI35: =AJ34 -> 0 | AK35: =IF((AJ35-AI35)<0, "0",AJ35-AI35) -> 0 | AL35: =AK35*(284.34513609) -> 0 | AM35: =AL35*0.334569 -> 0 | AO35: =L35+U35+AA35+AE35 -> 0
D36: =SUM(D7:D35) -> 17876 | E36: KW/H | G36: =SUM(G7:G35) -> 62851 | H36: =SUM(H7:H35) -> 72381 | I36: =SUM(I7:I35) -> 44850 | J36: =SUM(J7:J35) -> 141246 | K36: =SUM(K7:K35) -> 668581 | L36: =SUM(L7:L35) -> 140402.01 | R36: =SUM(R7:R35) -> 1377.032 | T36: =SUM(T7:T35) -> 4409.166 | U36: =T36*7.84 -> 34567.861 | Z36: =SUM(Z7:Z35) -> 8261.5 | AA36: =SUM(AA7:AA35) -> 83193.305 | AD36: =SUM(AD7:AD35) -> 267014 | AE36: =AD36*0.334569 -> 89334.607 | AF36: =SUM(AF7:AF35) -> 433.7 | AG36: =SUM(AG7:AG35) -> 123.7 | AH36: =SUM(AH7:AH35) -> 132.4 | AK36: =SUM(AK7:AK35) -> 226.3 | AL36: =SUM(AL7:AL35) -> 64347.304 | AM36: =SUM(AM7:AM35) -> 21528.613 | AN36: =SUM(AN7:AN35) -> 3252 | AO36: =SUM(AO7:AO35) -> 347497.78
D37: =#REF!*24 -> #REF! | E37: Day | R37: 7.84 | T37: Total / budget | U37: =U36-R38 -> 23771.931
D38: =D37*31 -> #REF! | E38: Month | F38: AED | G38: =D38*0.2 -> #REF! | R38: =R36*R37 -> 10795.931 | U38: =U37/R37 -> 3032.134
D39: =D38*0.2 -> #REF!
E40: 20KWH
...
