Workbook

Sheet Total
A1: Site Name | B1: Day | C1: Month | D1: Year | E1: Total Electricity Kwh | F1: Electricity Tariff ($/Kwh) | G1: Total Fuel Oil (Liters) | H1: Fuel Oil $/Liter | I1: LPG (Kg) | J1: LPG $/Kg | K1: Water Utility Supply (m3) m3 | L1: Water Utility Supply (m3) $/m3 | M1: Irrigation Water (m3) m3 | N1: Irrigation water $/m3 | O1: Room Nights
A2: Beirut | B2: 1 | C2: 2 | D2: 2020 | E2: =ELEC!N3 -> 11338 | F2: =SUM('EDl log'!T4) -> 0.10069059 | G2: =-tanks!AW6 -> 530 | H2: =SUM(tanks!AV6) -> 0.5835 | I2: =('B5'!AU5)*0.51 -> 45.9 | J2: ='B5'!AX5/0.51 -> 1.372549 | K2: =WATER!I6 -> 320 | L2: =SUM(WATER!J6) -> 0.80818966 | M2: =WATER!Q6 -> 0 | N2: 0.6 | O2: =ELEC!B3 -> 33.994
A3: Beirut | B3: =B2+1 -> 2 | C3: 2 | D3: 2020 | E3: =ELEC!N4 -> 13781 | F3: =SUM('EDl log'!T5) -> 0.08047306 | G3: =-tanks!AW7 -> 606 | H3: =SUM(tanks!AV7) -> 0.5835 | I3: =('B5'!AU6)*0.51 -> 107.1 | J3: ='B5'!AX6/0.51 -> 1.372549 | K3: =WATER!I7 -> 40 | L3: =SUM(WATER!J7) -> 6.4655172 | M3: =WATER!Q7 -> 0 | N3: 0.6 | O3: =ELEC!B4 -> 25.001
A4: Beirut | B4: =B3+1 -> 3 | C4: 2 | D4: 2020 | E4: =ELEC!N5 -> 10327 | F4: =SUM('EDl log'!T6) -> 0.099326823 | G4: =-tanks!AW8 -> 655 | H4: =SUM(tanks!AV8) -> 0.5835 | I4: =('B5'!AU7)*0.51 -> 45.9 | J4: ='B5'!AX7/0.51 -> 1.372549 | K4: =WATER!I8 -> 118 | L4: =SUM(WATER!J8) -> 2.1917008 | M4: =WATER!Q8 -> 0 | N4: 0.6 | O4: =ELEC!B5 -> 27.002
A5: Beirut | B5: =B4+1 -> 4 | C5: 2 | D5: 2020 | E5: =ELEC!N6 -> 12214 | F5: =SUM('EDl log'!T7) -> 0.080064763 | G5: =-tanks!AW9 -> 1137.7 | H5: =SUM(tanks!AV9) -> 0.5835 | I5: =('B5'!AU8)*0.51 -> 91.8 | J5: ='B5'!AX8/0.51 -> 1.372549 | K5: =WATER!I9 -> 0 | L5: =SUM(WATER!J9) -> 0 | M5: =WATER!Q9 -> 0 | N5: 0.6 | O5: =ELEC!B6 -> 27.002
A6: Beirut | B6: =B5+1 -> 5 | C6: 2 | D6: 2020 | E6: =ELEC!N7 -> 13334 | F6: =SUM('EDl log'!T8) -> 0.089794305 | G6: =-tanks!AW10 -> 617 | H6: =SUM(tanks!AV10) -> 0.5835 | I6: =('B5'!AU9)*0.51 -> 91.8 | J6: ='B5'!AX9/0.51 -> 1.372549 | K6: =WATER!I10 -> 311 | L6: =SUM(WATER!J10) -> 0.83157778 | M6: =WATER!Q10 -> 0 | N6: 0.6 | O6: =ELEC!B7 -> 33.994
A7: Beirut | B7: =B6+1 -> 6 | C7: 2 | D7: 2020 | E7: =ELEC!N8 -> 11008 | F7: =SUM('EDl log'!T9) -> 0.091261957 | G7: =-tanks!AW11 -> 453 | H7: =SUM(tanks!AV11) -> 0.5835 | I7: =('B5'!AU10)*0.51 -> 163.2 | J7: ='B5'!AX10/0.51 -> 1.372549 | K7: =WATER!I11 -> 0 | L7: =SUM(WATER!J11) -> 0 | M7: =WATER!Q11 -> 0 | N7: 0.6 | O7: =ELEC!B8 -> 46
A8: Beirut | B8: =B7+1 -> 7 | C8: 2 | D8: 2020 | E8: =ELEC!N9 -> 12629 | F8: =SUM('EDl log'!T10) -> 0.012386308 | G8: =-tanks!AW12 -> 906.9 | H8: =SUM(tanks!AV12) -> 0.54 | I8: =('B5'!AU11)*0.51 -> 61.2 | J8: ='B5'!AX11/0.51 -> 1.372549 | K8: =WATER!I12 -> 334 | L8: =SUM(WATER!J12) -> 0.77431344 | M8: =WATER!Q12 -> 0 | N8: 0.6 | O8: =ELEC!B9 -> 45.011
A9: Beirut | B9: =B8+1 -> 8 | C9: 2 | D9: 2020 | E9: =ELEC!N10 -> 12830 | F9: =SUM('EDl log'!T11) -> 0.082024837 | G9: =-tanks!AW13 -> 669.8 | H9: =SUM(tanks!AV13) -> 0.54 | I9: =('B5'!AU12)*0.51 -> 45.9 | J9: ='B5'!AX12/0.51 -> 1.372549 | K9: =WATER!I13 -> 0 | L9: =SUM(WATER!J13) -> 0 | M9: =WATER!Q13 -> 0 | N9: 0.6 | O9: =ELEC!B10 -> 31.97
A10: Beirut | B10: =B9+1 -> 9 | C10: 2 | D10: 2020 | E10: =ELEC!N11 -> 10890 | F10: =SUM('EDl log'!T12) -> 0.094138036 | G10: =-tanks!AW14 -> 828 | H10: =SUM(tanks!AV14) -> 0.54 | I10: =('B5'!AU13)*0.51 -> 137.7 | J10: ='B5'!AX13/0.51 -> 1.372549 | K10: =WATER!I14 -> 0 | L10: =SUM(WATER!J14) -> 0 | M10: =WATER!Q14 -> 0 | N10: 0.6 | O10: =ELEC!B11 -> 35.006
A11: Beirut | B11: =B10+1 -> 10 | C11: 2 | D11: 2020 | E11: =ELEC!N12 -> 10518 | F11: =SUM('EDl log'!T13) -> 0.093357235 | G11: =-tanks!AW15 -> 1098.6 | H11: =SUM(tanks!AV15) -> 0.54 | I11: =('B5'!AU14)*0.51 -> 137.7 | J11: ='B5'!AX14/0.51 -> 1.372549 | K11: =WATER!I15 -> 324 | L11: =SUM(WATER!J15) -> 0.79821201 | M11: =WATER!Q15 -> 0 | N11: 0.6 | O11: =ELEC!B12 -> 37.007
A12: Beirut | B12: =B11+1 -> 11 | C12: 2 | D12: 2020 | E12: =ELEC!N13 -> 10923 | F12: =SUM('EDl log'!T14) -> 0.072704071 | G12: =-tanks!AW16 -> 1468.1 | H12: =SUM(tanks!AV16) -> 0.54 | I12: =('B5'!AU15)*0.51 -> 45.9 | J12: ='B5'!AX15/0.51 -> 1.372549 | K12: =WATER!I16 -> 141 | L12: =SUM(WATER!J16) -> 1.8341893 | M12: =WATER!Q16 -> 0 | N12: 0.6 | O12: =ELEC!B13 -> 33.994
A13: Beirut | B13: =B12+1 -> 12 | C13: 2 | D13: 2020 | E13: =ELEC!N14 -> 11363.4 | F13: =SUM('EDl log'!T15) -> 0.10545805 | G13: =-tanks!AW17 -> 880 | H13: =SUM(tanks!AV17) -> 0.54 | I13: =('B5'!AU16)*0.51 -> 61.2 | J13: ='B5'!AX16/0.51 -> 1.372549 | K13: =WATER!I17 -> 0 | L13: =SUM(WATER!J17) -> 0 | M13: =WATER!Q17 -> 0 | N13: 0.6 | O13: =ELEC!B14 -> 46.989
A14: Beirut | B14: =B13+1 -> 13 | C14: 2 | D14: 2020 | E14: =ELEC!N15 -> 11590.6 | F14: =SUM('EDl log'!T16) -> 0.071227716 | G14: =-tanks!AW18 -> 735 | H14: =SUM(tanks!AV18) -> 0.54 | I14: =('B5'!AU17)*0.51 -> 193.8 | J14: ='B5'!AX17/0.51 -> 1.372549 | K14: =WATER!I18 -> 0 | L14: =SUM(WATER!J18) -> 0 | M14: =WATER!Q18 -> 0 | N14: 0.6 | O14: =ELEC!B15 -> 79.994
... A30: Beirut | B30: =B29+1 -> 29 | C30: 2 | D30: 2020 | E30: =ELEC!N31 -> 0 | F30: =SUM('EDl log'!T32) -> 0 | G30: =-tanks!AW34 -> 0 | H30: =SUM(tanks!AV34) -> 0.5165 | I30: =('B5'!AU33)*0.51 -> 0 | J30: ='B5'!AX33/0.51 -> 1.372549 | K30: =WATER!I34 -> 0 | L30: =SUM(WATER!J34) -> 0 | M30: =WATER!Q34 -> 0 | N30: 0.6 | O30: =ELEC!B31 -> 0
A31: Beirut | E31: =ELEC!N32 -> 0
A32: Beirut | E32: =ELEC!N33 -> 0

Sheet Submetering
A1: Site Name | B1: Day | C1: Month | D1: Year | E1: ATS1 Kwh | F1: ATS2 Kwh | G1: ATS3 Kwh | H1: ATS4 Kwh | I1: ATS5 Kwh | J1: Guest (m3) | K1: Kitchen & Laundry (m3) | L1: Room Nights
A2: Beirut | B2: 1 | C2: 2 | D2: 2020 | E2: =ELEC!M3 -> 3520 | F2: =ELEC!K3 -> 1372 | G2: =ELEC!I3 -> 1962 | H2: =ELEC!E3 -> 2503 | I2: =ELEC!G3 -> 1981 | J2: =WATER!Y6 -> 168 | K2: =WATER!AJ6 -> 58 | L2: =ELEC!B3 -> 33.994
A3: Beirut | B3: =B2+1 -> 2 | C3: 2 | D3: 2020 | E3: =ELEC!M4 -> 4766 | F3: =ELEC!K4 -> 1798 | G3: =ELEC!I4 -> 2192 | H3: =ELEC!E4 -> 2791 | I3: =ELEC!G4 -> 2234 | J3: =WATER!Y7 -> 0 | K3: =WATER!AJ7 -> 0 | L3: =ELEC!B4 -> 25.001
A4: Beirut | B4: =B3+1 -> 3 | C4: 2 | D4: 2020 | E4: =ELEC!M5 -> 3236 | F4: =ELEC!K5 -> 1446 | G4: =ELEC!I5 -> 1588 | H4: =ELEC!E5 -> 2364 | I4: =ELEC!G5 -> 1693 | J4: =WATER!Y8 -> 24 | K4: =WATER!AJ8 -> 43 | L4: =ELEC!B5 -> 27.002
A5: Beirut | B5: =B4+1 -> 4 | C5: 2 | D5: 2020 | E5: =ELEC!M6 -> 3902 | F5: =ELEC!K6 -> 1680 | G5: =ELEC!I6 -> 1948 | H5: =ELEC!E6 -> 2740 | I5: =ELEC!G6 -> 1944 | J5: =WATER!Y9 -> 2 | K5: =WATER!AJ9 -> 2 | L5: =ELEC!B6 -> 27.002
A6: Beirut | B6: =B5+1 -> 5 | C6: 2 | D6: 2020 | E6: =ELEC!M7 -> 4024 | F6: =ELEC!K7 -> 2528 | G6: =ELEC!I7 -> 1964 | H6: =ELEC!E7 -> 2836 | I6: =ELEC!G7 -> 1982 | J6: =WATER!Y10 -> 118 | K6: =WATER!AJ10 -> 79 | L6: =ELEC!B7 -> 33.994
A7: Beirut | B7: =B6+1 -> 6 | C7: 2 | D7: 2020 | E7: =ELEC!M8 -> 3578 | F7: =ELEC!K8 -> 1468 | G7: =ELEC!I8 -> 1744 | H7: =ELEC!E8 -> 2352 | I7: =ELEC!G8 -> 1866 | J7: =WATER!Y11 -> 101 | K7: =WATER!AJ11 -> 42 | L7: =ELEC!B8 -> 46
A8: Beirut | B8: =B7+1 -> 7 | C8: 2 | D8: 2020 | E8: =ELEC!M9 -> 4492 | F8: =ELEC!K9 -> 1532 | G8: =ELEC!I9 -> 1972 | H8: =ELEC!E9 -> 2488 | I8: =ELEC!G9 -> 2145 | J8: =WATER!Y12 -> 46 | K8: =WATER!AJ12 -> 67 | L8: =ELEC!B9 -> 45.011
A9: Beirut | B9: =B8+1 -> 8 | C9: 2 | D9: 2020 | E9: =ELEC!M10 -> 4476 | F9: =ELEC!K10 -> 1540 | G9: =ELEC!I10 -> 1836 | H9: =ELEC!E10 -> 2884 | I9: =ELEC!G10 -> 2094 | J9: =WATER!Y13 -> 0 | K9: =WATER!AJ13 -> 0 | L9: =ELEC!B10 -> 31.97
A10: Beirut | B10: =B9+1 -> 9 | C10: 2 | D10: 2020 | E10: =ELEC!M11 -> 3672 | F10: =ELEC!K11 -> 1226 | G10: =ELEC!I11 -> 1668 | H10: =ELEC!E11 -> 1838 | I10: =ELEC!G11 -> 2486 | J10: =WATER!Y14 -> 121 | K10: =WATER!AJ14 -> 99 | L10: =ELEC!B11 -> 35.006
A11: Beirut | B11: =B10+1 -> 10 | C11: 2 | D11: 2020 | E11: =ELEC!M12 -> 4204 | F11: =ELEC!K12 -> 1442 | G11: =ELEC!I12 -> 1990 | H11: =ELEC!E12 -> 1626 | I11: =ELEC!G12 -> 1256 | J11: =WATER!Y15 -> 0 | K11: =WATER!AJ15 -> 0 | L11: =ELEC!B12 -> 37.007
A12: Beirut | B12: =B11+1 -> 11 | C12: 2 | D12: 2020 | E12: =ELEC!M13 -> 3388 | F12: =ELEC!K13 -> 1748 | G12: =ELEC!I13 -> 2082 | H12: =ELEC!E13 -> 1812 | I12: =ELEC!G13 -> 1893 | J12: =WATER!Y16 -> 3 | K12: =WATER!AJ16 -> 1 | L12: =ELEC!B13 -> 33.994
A13: Beirut | B13: =B12+1 -> 12 | C13: 2 | D13: 2020 | E13: =ELEC!M14 -> 3704 | F13: =ELEC!K14 -> 1416 | G13: =ELEC!I14 -> 2220 | H13: =ELEC!E14 -> 2052 | I13: =ELEC!G14 -> 1971.4 | J13: =WATER!Y17 -> 0 | K13: =WATER!AJ17 -> 0 | L13: =ELEC!B14 -> 46.989
A14: Beirut | B14: =B13+1 -> 13 | C14: 2 | D14: 2020 | E14: =ELEC!M15 -> 3592 | F14: =ELEC!K15 -> 1374 | G14: =ELEC!I15 -> 2192 | H14: =ELEC!E15 -> 2308 | I14: =ELEC!G15 -> 2124.6 | J14: =WATER!Y18 -> 0 | K14: =WATER!AJ18 -> 0 | L14: =ELEC!B15 -> 79.994
... A30: Beirut | B30: =B29+1 -> 29 | C30: 2 | D30: 2020 | E30: =ELEC!M31 -> 0 | F30: =ELEC!K31 -> 0 | G30: =ELEC!I31 -> 0 | H30: =ELEC!E31 -> 0 | I30: =ELEC!G31 -> 0 | J30: =WATER!Y34 -> 0 | K30: =WATER!AJ34 -> 0 | L30: =ELEC!B31 -> 0
A31: Beirut
A32: Beirut

Sheet ELEC
A1: OOC | B1: Room OCC | D1: MDB3 | E1: MDB3/day | F1: EMDB2 | G1: EMDB2/day | H1: EMDB1 | I1: EMDB1/day | J1: MDB2 | K1: mdb2/day | L1: MDB1 | M1: MDB1/Day | N1: Total KWH | O1: KWH/Rooc | P1: Gen MHW | Q1: Gen/Day KWH | R1: EDL KWH | S1: CH1 RH | T1: RH | U1: C1h1 power | V1: CH1 Con KWH | W1: CH2 RH | X1: RH | Y1: Ch2 power | Z1: CH2 Con KWH | AA1: CH3 RH | AB1: RH | AC1: Ch3 power | AD1: CH3 Con KWH | AE1: RH total | AF1: KWH total | AG1: AVG chiller KW/Hr
A2: =[1]ELEC!$A$33 -> 0.1478 | B2: =[1]ELEC!$B$33 -> 33.994 | C2: 31-01-2020 | D2: 31388876 | E2: =[1]ELEC!E33 -> 1958 | F2: 3496407 | G2: =[1]ELEC!G33 -> 1865.8 | H2: 17285396 | I2: =[1]ELEC!I33 -> 1934 | J2: =[1]ELEC!J33 -> 28279902 | K2: =[1]ELEC!K33 -> 1240 | L2: =[1]ELEC!L33 -> 22645064 | M2: =[1]ELEC!M33 -> 3350 | N2: =[1]ELEC!N33 -> 10347.8 | O2: =[1]ELEC!O33 -> 304.40078 | P2: =[1]ELEC!P33 -> 15304.848 | ... AJ2: =[1]ELEC!AJ33 -> 0
A3: ='General information '!F6 -> 0.1478 | B3: =SUM(230*A3) -> 33.994 | C3: 43862 | D3: 31391379 | E3: =D3-D2 -> 2503 | F3: 3498388 | G3: =F3-F2 -> 1981 | H3: 17287358 | I3: =H3-H2 -> 1962 | J3: 28281274 | K3: =J3-J2 -> 1372 | L3: 22648584 | M3: =L3-L2 -> 3520 | N3: =M3+K3+I3+G3+E3 -> 11338 | O3: =IF(B3>0,N3/B3,0) -> 333.52945 | P3: 15307.274 | Q3: =(P3-P2)*1000 -> 2426 | R3: =+N3-Q3 -> 8912 | S3: 8373 | T3: =S3-S2 -> 2 | U3: 1022099 | V3: =U3-U2 -> 469 | W3: =W2 -> 31840 | X3: =W3-W2 -> 0 | Y3: =Y2 -> 623360 | Z3: =Y3-Y2 -> 0 | AA3: =AA2 -> 34877 | AB3: =AA3-AA2 -> 0 | AC3: =AC2 -> 740427 | AD3: =AC3-AC2 -> 0 | AE3: =AB3+X3+T3 -> 2 | AF3: =V3+Z3+AD3 -> 469 | AG3: =IF(AE3>0,AF3/AE3,0) -> 234.5
A4: ='General information '!F7 -> 0.1087 | B4: =SUM(230*A4) -> 25.001 | C4: 43863 | D4: 31394170 | E4: =D4-D3 -> 2791 | F4: 3500622 | G4: =F4-F3 -> 2234 | H4: 17289550 | I4: =H4-H3 -> 2192 | J4: 28283072 | K4: =J4-J3 -> 1798 | L4: 22653350 | M4: =L4-L3 -> 4766 | N4: =M4+K4+I4+G4+E4 -> 13781 | O4: =IF(B4>0,N4/B4,0) -> 551.21795 | P4: 15309.206 | Q4: =(P4-P3)*1000 -> 1932 | R4: =N4-Q4 -> 11849 | S4: 8378 | T4: =S4-S3 -> 5 | U4: 1023028 | V4: =U4-U3 -> 929 | W4: 31840 | X4: =W4-W3 -> 0 | Y4: =Y3 -> 623360 | Z4: =Y4-Y3 -> 0 | AA4: 34878 | AB4: =AA4-AA3 -> 1 | AC4: 740548 | AD4: =AC4-AC3 -> 121 | AE4: =AB4+X4+T4 -> 6 | AF4: =V4+Z4+AD4 -> 1050 | AG4: =IF(AE4>0,AF4/AE4,0) -> 175
A5: ='General information '!F8 -> 0.1174 | B5: =SUM(230*A5) -> 27.002 | C5: 43864 | D5: 31396534 | E5: =D5-D4 -> 2364 | F5: 3502315 | G5: =F5-F4 -> 1693 | H5: 17291138 | I5: =H5-H4 -> 1588 | J5: 28284518 | K5: =J5-J4 -> 1446 | L5: 22656586 | M5: =L5-L4 -> 3236 | N5: =M5+K5+I5+G5+E5 -> 10327 | O5: =IF(B5>0,N5/B5,0) -> 382.45315 | P5: 15312.064 | Q5: =(P5-P4)*1000 -> 2858 | R5: =N5-Q5 -> 7469 | S5: 8379 | T5: =S5-S4 -> 1 | U5: 1023092 | V5: =U5-U4 -> 64 | W5: 31841 | X5: =W5-W4 -> 1 | Y5: 623507 | Z5: =Y5-Y4 -> 147 | AA5: 34879 | AB5: =AA5-AA4 -> 1 | AC5: 740830 | AD5: =AC5-AC4 -> 282 | AE5: =AB5+X5+T5 -> 3 | AF5: =V5+Z5+AD5 -> 493 | AG5: =IF(AE5>0,AF5/AE5,0) -> 164.33333 | AI5: =R5-'EDl log'!B3 -> -49419805
A6: ='General information '!F9 -> 0.1174 | B6: =SUM(230*A6) -> 27.002 | C6: 43865 | D6: 31399274 | E6: =D6-D5 -> 2740 | F6: 3504259 | G6: =F6-F5 -> 1944 | H6: 17293086 | I6: =H6-H5 -> 1948 | J6: 28286198 | K6: =J6-J5 -> 1680 | L6: 22660488 | M6: =L6-L5 -> 3902 | N6: =M6+K6+I6+G6+E6 -> 12214 | O6: =IF(B6>0,N6/B6,0) -> 452.33686 | P6: 15314.842 | Q6: =(P6-P5)*1000 -> 2778 | R6: =N6-Q6 -> 9436 | S6: =S5 -> 8379 | T6: =S6-S5 -> 0 | U6: =U5 -> 1023092 | V6: =U6-U5 -> 0 | W6: =W5 -> 31841 | X6: =W6-W5 -> 0 | Y6: =Y5 -> 623507 | Z6: =Y6-Y5 -> 0 | AA6: 34882 | AB6: =AA6-AA5 -> 3 | AC6: 741247 | AD6: =AC6-AC5 -> 417 | AE6: =AB6+X6+T6 -> 3 | AF6: =V6+Z6+AD6 -> 417 | AG6: =IF(AE6>0,AF6/AE6,0) -> 139 | AI6: =R6-'EDl log'!B4 -> -49422471
A7: ='General information '!F10 -> 0.1478 | B7: =SUM(230*A7) -> 33.994 | C7: 43866 | D7: 31402110 | E7: =D7-D6 -> 2836 | F7: 3506241 | G7: =F7-F6 -> 1982 | H7: 17295050 | I7: =H7-H6 -> 1964 | J7: 28288726 | K7: =J7-J6 -> 2528 | L7: 22664512 | M7: =L7-L6 -> 4024 | N7: =M7+K7+I7+G7+E7 -> 13334 | O7: =IF(B7>0,N7/B7,0) -> 392.24569 | P7: 15317.023 | Q7: =(P7-P6)*1000 -> 2181 | R7: =N7-Q24 -> 10670 | S7: 8379 | T7: =S7-S6 -> 0 | U7: 1023092 | V7: =U7-U6 -> 0 | W7: 31843 | X7: =W7-W6 -> 2 | Y7: 624129 | Z7: =Y7-Y6 -> 622 | AA7: 34882 | AB7: =AA7-AA6 -> 0 | AC7: 741247 | AD7: =AC7-AC6 -> 0 | AE7: =AB7+X7+T7 -> 2 | AF7: =V7+Z7+AD7 -> 622 | AG7: =IF(AE7>0,AF7/AE7,0) -> 311 | AI7: =R7-'EDl log'!B5 -> -49427349
A8: ='General information '!F11 -> 0.2 | B8: =SUM(230*A8) -> 46 | C8: 43867 | D8: 31404462 | E8: =D8-D7 -> 2352 | F8: 3508107 | G8: =F8-F7 -> 1866 | H8: 17296794 | I8: =H8-H7 -> 1744 | J8: 28290194 | K8: =J8-J7 -> 1468 | L8: 22668090 | M8: =L8-L7 -> 3578 | N8: =M8+K8+I8+G8+E8 -> 11008 | O8: =IF(B8>0,N8/B8,0) -> 239.30435 | P8: 15318.894 | Q8: =(P8-P7)*1000 -> 1871 | R8: =N8-Q8 -> 9137 | S8: =S7 -> 8379 | T8: =S8-S7 -> 0 | U8: =U7 -> 1023092 | V8: =U8-U7 -> 0 | W8: 31845 | X8: =W8-W7 -> 2 | Y8: 624369 | Z8: =Y8-Y7 -> 240 | AA8: 34883 | AB8: =AA8-AA7 -> 1 | AC8: 741440 | AD8: =AC8-AC7 -> 193 | AE8: =AB8+X8+T8 -> 3 | AF8: =V8+Z8+AD8 -> 433 | AG8: =IF(AE8>0,AF8/AE8,0) -> 144.33333 | AI8: =R8-'EDl log'!B6 -> -49432747
A9: ='General information '!F12 -> 0.1957 | B9: =SUM(230*A9) -> 45.011 | C9: 43868 | D9: 31406950 | E9: =D9-D8 -> 2488 | F9: 3510252 | G9: =F9-F8 -> 2145 | H9: 17298766 | I9: =H9-H8 -> 1972 | J9: 28291726 | K9: =J9-J8 -> 1532 | L9: 22672582 | M9: =L9-L8 -> 4492 | N9: =M9+K9+I9+G9+E9 -> 12629 | O9: =IF(B9>0,N9/B9,0) -> 280.57586 | P9: 15321.643 | Q9: =(P9-P8)*1000 -> 2749 | R9: =N9-Q9 -> 9880 | S9: 8380 | T9: =S9-S8 -> 1 | U9: 1023424 | V9: =U9-U8 -> 332 | W9: =W8 -> 31845 | X9: =W9-W8 -> 0 | Y9: =Y8 -> 624369 | Z9: =Y9-Y8 -> 0 | AA9: =AA8 -> 34883 | AB9: =AA9-AA8 -> 0 | AC9: =AC8 -> 741440 | AD9: =AC9-AC8 -> 0 | AE9: =AB9+X9+T9 -> 1 | AF9: =V9+Z9+AD9 -> 332 | AG9: =IF(AE9>0,AF9/AE9,0) -> 332 | AI9: =R9-'EDl log'!B7 -> -49436888
A10: ='General information '!F13 -> 0.139 | B10: =SUM(230*A10) -> 31.97 | C10: 43869 | D10: 31409834 | E10: =D10-D9 -> 2884 | F10: 3512346 | G10: =F10-F9 -> 2094 | H10: 17300602 | I10: =H10-H9 -> 1836 | J10: 28293266 | K10: =J10-J9 -> 1540 | L10: 22677058 | M10: =L10-L9 -> 4476 | N10: =M10+K10+I10+G10+E10 -> 12830 | O10: =IF(B10>0,N10/B10,0) -> 401.31373 | P10: 15323.08 | Q10: =(P10-P9)*1000 -> 1437 | R10: =N10-Q10 -> 11393 | S10: 8382 | T10: =S10-S9 -> 2 | U10: 1023764 | V10: =U10-U9 -> 340 | W10: 31845 | X10: =W10-W9 -> 0 | Y10: 624440 | Z10: =Y10-Y9 -> 71 | AA10: 34883 | AB10: =AA10-AA9 -> 0 | AC10: 741441 | AD10: =AC10-AC9 -> 1 | AE10: =AB10+X10+T10 -> 2 | AF10: =V10+Z10+AD10 -> 412 | AG10: =IF(AE10>0,AF10/AE10,0) -> 206 | AI10: =R10-'EDl log'!B8 -> -49440422
A11: ='General information '!F14 -> 0.1522 | B11: =SUM(230*A11) -> 35.006 | C11: 43870 | D11: 31411672 | E11: =D11-D10 -> 1838 | F11: 3514832 | G11: =F11-F10 -> 2486 | H11: 17302270 | I11: =H11-H10 -> 1668 | J11: 28294492 | K11: =J11-J10 -> 1226 | L11: 22680730 | M11: =L11-L10 -> 3672 | N11: =M11+K11+I11+G11+E11 -> 10890 | O11: =IF(B11>0,N11/B11,0) -> 311.08953 | P11: 15325.17 | Q11: =(P11-P10)*1000 -> 2090 | R11: =N11-Q11 -> 8800 | S11: 8382 | T11: =S11-S10 -> 0 | U11: =U10 -> 1023764 | V11: =U11-U10 -> 0 | W11: =W10 -> 31845 | X11: =W11-W10 -> 0 | Y11: =Y10 -> 624440 | Z11: =Y11-Y10 -> 0 | AA11: 34887 | AB11: =AA11-AA10 -> 4 | AC11: 742049 | AD11: =AC11-AC10 -> 608 | AE11: =AB11+X11+T11 -> 4 | AF11: =V11+Z11+AD11 -> 608 | AG11: =IF(AE11>0,AF11/AE11,0) -> 152 | AI11: =R11-'EDl log'!B9 -> -49448459
A12: ='General information '!F15 -> 0.1609 | B12: =SUM(230*A12) -> 37.007 | C12: 43871 | D12: 31413298 | E12: =D12-D11 -> 1626 | F12: 3516088 | G12: =F12-F11 -> 1256 | H12: 17304260 | I12: =H12-H11 -> 1990 | J12: 28295934 | K12: =J12-J11 -> 1442 | L12: 22684934 | M12: =L12-L11 -> 4204 | N12: =M12+K12+I12+G12+E12 -> 10518 | O12: =IF(B12>0,N12/B12,0) -> 284.2165 | P12: 15326.76 | Q12: =(P12-P11)*1000 -> 1590 | R12: =N12-Q12 -> 8928 | S12: 8382 | T12: =S12-S11 -> 0 | U12: 1023764 | V12: =U12-U11 -> 0 | W12: 31845 | X12: =W12-W11 -> 0 | Y12: 624440 | Z12: =Y12-Y11 -> 0 | AA12: 34888 | AB12: =AA12-AA11 -> 1 | AC12: 742070 | AD12: =AC12-AC11 -> 21 | AE12: =AB12+X12+T12 -> 1 | AF12: =V12+Z12+AD12 -> 21 | AG12: =IF(AE12>0,AF12/AE12,0) -> 21 | AI12: =R12-'EDl log'!B10 -> -49453440
A13: ='General information '!F16 -> 0.1478 | B13: =SUM(230*A13) -> 33.994 | C13: 43872 | D13: 31415110 | E13: =D13-D12 -> 1812 | F13: 3517981 | G13: =F13-F12 -> 1893 | H13: 17306342 | I13: =H13-H12 -> 2082 | J13: 28297682 | K13: =J13-J12 -> 1748 | L13: 22688322 | M13: =L13-L12 -> 3388 | N13: =M13+K13+I13+G13+E13 -> 10923 | O13: =IF(B13>0,N13/B13,0) -> 321.32141 | P13: 15328.411 | Q13: =(P13-P12)*1000 -> 1651 | R13: =N13-Q13 -> 9272 | S13: 8382 | T13: =S13-S12 -> 0 | U13: 1023769 | V13: =U13-U12 -> 5 | W13: 31845 | X13: =W13-W12 -> 0 | Y13: 624440 | Z13: =Y13-Y12 -> 0 | AA13: 34888 | AB13: =AA13-AA12 -> 0 | AC13: 742070 | AD13: =AC13-AC12 -> 0 | AE13: =AB13+X13+T13 -> 0 | AF13: =V13+Z13+AD13 -> 5 | AG13: =IF(AE13>0,AF13/AE13,0) -> 0 | AI13: =R13-'EDl log'!B11 -> -49459020
A14: ='General information '!F17 -> 0.2043 | B14: =SUM(230*A14) -> 46.989 | C14: 43873 | D14: 31417162 | E14: =D14-D13 -> 2052 | F14: 3519952.4 | G14: =F14-F13 -> 1971.4 | H14: 17308562 | I14: =H14-H13 -> 2220 | J14: 28299098 | K14: =J14-J13 -> 1416 | L14: 22692026 | M14: =L14-L13 -> 3704 | N14: =M14+K14+I14+G14+E14 -> 11363.4 | O14: =IF(B14>0,N14/B14,0) -> 241.83107 | P14: 15330.121 | Q14: =(P14-P13)*1000 -> 1710 | R14: =N14-Q14 -> 9653.4 | S14: 8383 | T14: =S14-S13 -> 1 | U14: 1023979 | V14: =U14-U13 -> 210 | W14: =W13 -> 31845 | X14: =W14-W13 -> 0 | Y14: =Y13 -> 624440 | Z14: =Y14-Y13 -> 0 | AA14: =AA13 -> 34888 | AB14: =AA14-AA13 -> 0 | AC14: 742158 | AD14: =AC14-AC13 -> 88 | AE14: =AB14+X14+T14 -> 1 | AF14: =V14+Z14+AD14 -> 298 | AG14: =IF(AE14>0,AF14/AE14,0) -> 298 | AI14: =R14-'EDl log'!B12 -> -49462867
A15: ='General information '!F18 -> 0.3478 | B15: =SUM(230*A15) -> 79.994 | C15: 43874 | D15: 31419470 | E15: =D15-D14 -> 2308 | F15: 3522077 | G15: =F15-F14 -> 2124.6 | H15: 17310754 | I15: =H15-H14 -> 2192 | J15: 28300472 | K15: =J15-J14 -> 1374 | L15: 22695618 | M15: =L15-L14 -> 3592 | N15: =M15+K15+I15+G15+E15 -> 11590.6 | O15: =IF(B15>0,N15/B15,0) -> 144.89337 | P15: 15332.234 | Q15: =(P15-P14)*1000 -> 2113 | R15: =N15-Q15 -> 9477.6 | S15: 8383 | T15: =S15-S14 -> 0 | U15: 1023979 | V15: =U15-U14 -> 0 | W15: 31845 | X15: =W15-W14 -> 0 | Y15: 624440 | Z15: =Y15-Y14 -> 0 | AA15: 34890 | AB15: =AA15-AA14 -> 2 | AC15: 742464 | AD15: =AC15-AC14 -> 306 | AE15: =AB15+X15+T15 -> 2 | AF15: =V15+Z15+AD15 -> 306 | AG15: =IF(AE15>0,AF15/AE15,0) -> 153 | AI15: =R15-'EDl log'!B13 -> -49467996
A16: ='General information '!F19 -> 0.3826 | B16: =SUM(230*A16) -> 87.998 | C16: 43875 | D16: 31423330 | E16: =D16-D15 -> 3860 | F16: 3524322 | G16: =F16-F15 -> 2245 | H16: 17312988 | I16: =H16-H15 -> 2234 | J16: 28302050 | K16: =J16-J15 -> 1578 | L16: 22699674 | M16: =L16-L15 -> 4056 | N16: =M16+K16+I16+G16+E16 -> 13973 | O16: =IF(B16>0,N16/B16,0) -> 158.7877 | P16: 15334.331 | Q16: =(P16-P15)*1000 -> 2097 | R16: =N16-Q16 -> 11876 | S16: 8384 | T16: =S16-S15 -> 1 | U16: 1024343 | V16: =U16-U15 -> 364 | W16: =W15 -> 31845 | X16: =W16-W15 -> 0 | Y16: =Y15 -> 624440 | Z16: =Y16-Y15 -> 0 | AA16: 34895 | AB16: =AA16-AA15 -> 5 | AC16: 743301 | AD16: =AC16-AC15 -> 837 | AE16: =AB16+X16+T16 -> 6 | AF16: =V16+Z16+AD16 -> 1201 | AG16: =IF(AE16>0,AF16/AE16,0) -> 200.16667 | AI16: =R16-'EDl log'!B14 -> -49470408
A17: ='General information '!F20 -> 0.247 | B17: =SUM(230*A17) -> 56.81 | C17: 43876 | D17: 31426858 | E17: =D17-D16 -> 3528 | F17: 3526558.8 | G17: =F17-F16 -> 2236.8 | H17: 17315262 | I17: =H17-H16 -> 2274 | J17: 28303566 | K17: =J17-J16 -> 1516 | L17: 22703290 | M17: =L17-L16 -> 3616 | N17: =M17+K17+I17+G17+E17 -> 13170.8 | O17: =IF(B17>0,N17/B17,0) -> 231.83946 | P17: 15336.825 | Q17: =(P17-P16)*1000 -> 2494 | R17: =N17-Q17 -> 10676.8 | S17: =S16 -> 8384 | T17: =S17-S16 -> 0 | U17: =U16 -> 1024343 | V17: =U17-U16 -> 0 | W17: =W16 -> 31845 | X17: =W17-W16 -> 0 | Y17: =Y16 -> 624440 | Z17: =Y17-Y16 -> 0 | AA17: 34900 | AB17: =AA17-AA16 -> 5 | AC17: 744360 | AD17: =AC17-AC16 -> 1059 | AE17: =AB17+X17+T17 -> 5 | AF17: =V17+Z17+AD17 -> 1059 | AG17: =IF(AE17>0,AF17/AE17,0) -> 211.8 | AI17: =R17-'EDl log'!B15 -> -49476609
A18: ='General information '!F21 -> 0.1696 | B18: =SUM(230*A18) -> 39.008 | C18: 43877 | D18: 31430446 | E18: =D18-D17 -> 3588 | F18: 3528846 | G18: =F18-F17 -> 2287.2 | H18: 17317582 | I18: =H18-H17 -> 2320 | J18: 28305092 | K18: =J18-J17 -> 1526 | L18: 22707034 | M18: =L18-L17 -> 3744 | N18: =M18+K18+I18+G18+E18 -> 13465.2 | O18: =IF(B18>0,N18/B18,0) -> 345.19073 | P18: 15337.7 | Q18: =(P18-P17)*1000 -> 875 | R18: =N18-Q18 -> 12590.2 | S18: =S17 -> 8384 | T18: =S18-S17 -> 0 | U18: =U17 -> 1024343 | V18: =U18-U17 -> 0 | W18: =W17 -> 31845 | X18: =W18-W17 -> 0 | Y18: =Y17 -> 624440 | Z18: =Y18-Y17 -> 0 | AA18: 34903 | AB18: =AA18-AA17 -> 3 | AC18: 744994 | AD18: =AC18-AC17 -> 634 | AE18: =AB18+X18+T18 -> 3 | AF18: =V18+Z18+AD18 -> 634 | AG18: =IF(AE18>0,AF18/AE18,0) -> 211.33333 | AI18: =R18-'EDl log'!B16 -> -49479605
A19: ='General information '!F22 -> 0.2304 | B19: =SUM(230*A19) -> 52.992 | C19: 43878 | D19: 31434710 | E19: =D19-D18 -> 4264 | F19: 3530950 | G19: =F19-F18 -> 2104 | H19: 17319762 | I19: =H19-H18 -> 2180 | J19: 28306616 | K19: =J19-J18 -> 1524 | L19: 22710454 | M19: =L19-L18 -> 3420 | N19: =M19+K19+I19+G19+E19 -> 13492 | O19: =IF(B19>0,N19/B19,0) -> 254.60447 | P19: 15339.919 | Q19: =(P19-P18)*1000 -> 2219 | R19: =N19-Q19 -> 11273 | S19: 8384 | T19: =S19-S18 -> 0 | U19: 1024343 | V19: =U19-U18 -> 0 | W19: 31845 | X19: =W19-W18 -> 0 | Y19: 624440 | Z19: =Y19-Y18 -> 0 | AA19: 34907 | AB19: =AA19-AA18 -> 4 | AC19: 745923 | AD19: =AC19-AC18 -> 929 | AE19: =AB19+X19+T19 -> 4 | AF19: =V19+Z19+AD19 -> 929 | AG19: =IF(AE19>0,AF19/AE19,0) -> 232.25 | AI19: =R19-'EDl log'!B17 -> -49487057
A20: ='General information '!F23 -> 0.2348 | B20: =SUM(230*A20) -> 54.004 | C20: 43879 | D20: 31438132 | E20: =D20-D19 -> 3422 | F20: 3532897 | G20: =F20-F19 -> 1947 | H20: 17321730 | I20: =H20-H19 -> 1968 | J20: 28308028 | K20: =J20-J19 -> 1412 | L20: 22713590 | M20: =L20-L19 -> 3136 | N20: =M20+K20+I20+G20+E20 -> 11885 | O20: =IF(B20>0,N20/B20,0) -> 220.07629 | P20: 15342.182 | Q20: =(P20-P19)*1000 -> 2263 | R20: =N20-Q20 -> 9622 | S20: 8384 | T20: =S20-S19 -> 0 | U20: 1024343 | V20: =U20-U19 -> 0 | W20: 31845 | X20: =W20-W19 -> 0 | Y20: 624440 | Z20: =Y20-Y19 -> 0 | AA20: 34911 | AB20: =AA20-AA19 -> 4 | AC20: 746724 | AD20: =AC20-AC19 -> 801 | AE20: =AB20+X20+T20 -> 4 | AF20: =V20+Z20+AD20 -> 801 | AG20: =IF(AE20>0,AF20/AE20,0) -> 200.25 | AI20: =R20-'EDl log'!B18 -> -49494226
A21: ='General information '!F24 -> 0.2304 | B21: =SUM(230*A21) -> 52.992 | C21: 43880 | D21: 31441234 | E21: =D21-D20 -> 3102 | F21: 3534911 | G21: =F21-F20 -> 2014 | H21: 17323880 | I21: =H21-H20 -> 2150 | J21: 28309470 | K21: =J21-J20 -> 1442 | L21: 22716958 | M21: =L21-L20 -> 3368 | N21: =M21+K21+I21+G21+E21 -> 12076 | O21: =IF(B21>0,N21/B21,0) -> 227.88345 | P21: 15344.795 | Q21: =(P21-P20)*1000 -> 2613 | R21: =N21-Q21 -> 9463 | S21: 8384 | T21: =S21-S20 -> 0 | U21: 1024343 | V21: =U21-U20 -> 0 | W21: 31845 | X21: =W21-W20 -> 0 | Y21: 624440 | Z21: =Y21-Y20 -> 0 | AA21: 34913 | AB21: =AA21-AA20 -> 2 | AC21: 747174 | AD21: =AC21-AC20 -> 450 | AE21: =AB21+X21+T21 -> 2 | AF21: =V21+Z21+AD21 -> 450 | AG21: =IF(AE21>0,AF21/AE21,0) -> 225 | AI21: =R21-'EDl log'!B19 -> -49500889
A22: ='General information '!F25 -> 0.2261 | B22: =SUM(230*A22) -> 52.003 | C22: 43881 | D22: 31444914 | E22: =D22-D21 -> 3680 | F22: 3536916 | G22: =F22-F21 -> 2005 | H22: 17325874 | I22: =H22-H21 -> 1994 | J22: 28310926 | K22: =J22-J21 -> 1456 | L22: 22720206 | M22: =L22-L21 -> 3248 | N22: =M22+K22+I22+G22+E22 -> 12383 | O22: =IF(B22>0,N22/B22,0) -> 238.12088 | P22: 15346.83 | Q22: =(P22-P21)*1000 -> 2035 | R22: =N22-Q22 -> 10348 | S22: 8384 | T22: =S22-S21 -> 0 | U22: 1024343 | V22: =U22-U21 -> 0 | W22: 31845 | X22: =W22-W21 -> 0 | Y22: 624440 | Z22: =Y22-Y21 -> 0 | AA22: 34918 | AB22: =AA22-AA21 -> 5 | AC22: 748034 | AD22: =AC22-AC21 -> 860 | AE22: =AB22+X22+T22 -> 5 | AF22: =V22+Z22+AD22 -> 860 | AG22: =IF(AE22>0,AF22/AE22,0) -> 172 | AI22: =R22-'EDl log'!B20 -> -49505865
A23: ='General information '!F26 -> 0.2478 | B23: =SUM(230*A23) -> 56.994 | C23: 43882 | D23: 31449362 | E23: =D23-D22 -> 4448 | F23: 3538936 | G23: =F23-F22 -> 2020 | H23: 17327918 | I23: =H23-H22 -> 2044 | J23: 28312595 | K23: =J23-J22 -> 1669 | L23: 22723562 | M23: =L23-L22 -> 3356 | N23: =M23+K23+I23+G23+E23 -> 13537 | O23: =IF(B23>0,N23/B23,0) -> 237.51623 | P23: 15349.098 | Q23: =(P23-P22)*1000 -> 2268 | R23: =N23-Q23 -> 11269 | S23: 8384 | T23: =S23-S22 -> 0 | U23: =U22 -> 1024343 | V23: =U23-U22 -> 0 | W23: =W22 -> 31845 | X23: =W23-W22 -> 0 | Y23: =Y22 -> 624440 | Z23: =Y23-Y22 -> 0 | AA23: 34924 | AB23: =AA23-AA22 -> 6 | AC23: 749155 | AD23: =AC23-AC22 -> 1121 | AE23: =AB23+X23+T23 -> 6 | AF23: =V23+Z23+AD23 -> 1121 | AG23: =IF(AE23>0,AF23/AE23,0) -> 186.83333 | AI23: =R23-'EDl log'!B21 -> -49509924
A24: ='General information '!F27 -> 0.1826 | B24: =SUM(230*A24) -> 41.998 | C24: 43883 | D24: 31453650 | E24: =D24-D23 -> 4288 | F24: 3541037 | G24: =F24-F23 -> 2101 | H24: 17330058 | I24: =H24-H23 -> 2140 | J24: 28314274 | K24: =J24-J23 -> 1679 | L24: 22727126 | M24: =L24-L23 -> 3564 | N24: =M24+K24+I24+G24+E24 -> 13772 | O24: =IF(B24>0,N24/B24,0) -> 327.92038 | P24: 15351.762 | Q24: =(P24-P23)*1000 -> 2664 | R24: =N24-Q24 -> 11108 | S24: =S23 -> 8384 | T24: =S24-S23 -> 0 | U24: =U23 -> 1024343 | V24: =U24-U23 -> 0 | W24: =W23 -> 31845 | X24: =W24-W23 -> 0 | Y24: =Y23 -> 624440 | Z24: =Y24-Y23 -> 0 | AA24: 34929 | AB24: =AA24-AA23 -> 5 | AC24: 750150 | AD24: =AC24-AC23 -> 995 | AE24: =AB24+X24+T24 -> 5 | AF24: =V24+Z24+AD24 -> 995 | AG24: =IF(AE24>0,AF24/AE24,0) -> 199 | AI24: =R24-'EDl log'!B22 -> -49514934
A25: ='General information '!F28 -> 0.1391 | B25: =SUM(230*A25) -> 31.993 | C25: 43884 | D25: 31458170 | E25: =D25-D24 -> 4520 | F25: 3543226 | G25: =F25-F24 -> 2189 | H25: 17332322 | I25: =H25-H24 -> 2264 | J25: 28316014 | K25: =J25-J24 -> 1740 | L25: 22730712 | M25: =L25-L24 -> 3586 | N25: =M25+K25+I25+G25+E25 -> 14299 | O25: =IF(B25>0,N25/B25,0) -> 446.94152 | P25: 15355.608 | Q25: =(P25-P24)*1000 -> 3846 | R25: =N25-Q25 -> 10453 | S25: 8384 | T25: =S25-S24 -> 0 | U25: 1024343 | V25: =U25-U24 -> 0 | W25: 31845 | X25: =W25-W24 -> 0 | Y25: 624440 | Z25: =Y25-Y24 -> 0 | AA25: 34936 | AB25: =AA25-AA24 -> 7 | AC25: 751223 | AD25: =AC25-AC24 -> 1073 | AE25: =AB25+X25+T25 -> 7 | AF25: =V25+Z25+AD25 -> 1073 | AG25: =IF(AE25>0,AF25/AE25,0) -> 153.28571 | AI25: =R25-'EDl log'!B23 -> -49520999
A26: ='General information '!F29 -> 0 | B26: =SUM(230*A26) -> 0 | C26: 43885 | D26: =D25 -> 31458170 | E26: =D26-D25 -> 0 | F26: =F25 -> 3543226 | G26: =F26-F25 -> 0 | H26: =H25 -> 17332322 | I26: =H26-H25 -> 0 | J26: =J25 -> 28316014 | K26: =J26-J25 -> 0 | L26: =L25 -> 22730712 | M26: =L26-L25 -> 0 | N26: =M26+K26+I26+G26+E26 -> 0 | O26: =IF(B26>0,N26/B26,0) -> 0 | P26: =P25 -> 15355.608 | Q26: =(P26-P25)*1000 -> 0 | R26: =N26-Q26 -> 0 | S26: =S25 -> 8384 | T26: =S26-S25 -> 0 | U26: =U25 -> 1024343 | V26: =U26-U25 -> 0 | W26: =W25 -> 31845 | X26: =W26-W25 -> 0 | Y26: =Y25 -> 624440 | Z26: =Y26-Y25 -> 0 | AA26: =AA25 -> 34936 | AB26: =AA26-AA25 -> 0 | AC26: =AC25 -> 751223 | AD26: =AC26-AC25 -> 0 | AE26: =AB26+X26+T26 -> 0 | AF26: =V26+Z26+AD26 -> 0 | AG26: =IF(AE26>0,AF26/AE26,0) -> 0 | AI26: =R26-'EDl log'!B24 -> -49537279
A27: ='General information '!F30 -> 0 | B27: =SUM(230*A27) -> 0 | C27: 43886 | D27: =D26 -> 31458170 | E27: =D27-D26 -> 0 | F27: =F26 -> 3543226 | G27: =F27-F26 -> 0 | H27: =H26 -> 17332322 | I27: =H27-H26 -> 0 | J27: =J26 -> 28316014 | K27: =J27-J26 -> 0 | L27: =L26 -> 22730712 | M27: =L27-L26 -> 0 | N27: =M27+K27+I27+G27+E27 -> 0 | O27: =IF(B27>0,N27/B27,0) -> 0 | P27: =P26 -> 15355.608 | Q27: =(P27-P26)*1000 -> 0 | R27: =N27-Q27 -> 0 | S27: =S26 -> 8384 | T27: =S27-S26 -> 0 | U27: =U26 -> 1024343 | V27: =U27-U26 -> 0 | W27: =W26 -> 31845 | X27: =W27-W26 -> 0 | Y27: =Y26 -> 624440 | Z27: =Y27-Y26 -> 0 | AA27: =AA26 -> 34936 | AB27: =AA27-AA26 -> 0 | AC27: =AC26 -> 751223 | AD27: =AC27-AC26 -> 0 | AE27: =AB27+X27+T27 -> 0 | AF27: =V27+Z27+AD27 -> 0 | AG27: =IF(AE27>0,AF27/AE27,0) -> 0 | AI27: =R27-'EDl log'!B25 -> -49543046
A28: ='General information '!F31 -> 0 | B28: =SUM(230*A28) -> 0 | C28: 43887 | D28: =D27 -> 31458170 | E28: =D28-D27 -> 0 | F28: =F27 -> 3543226 | G28: =F28-F27 -> 0 | H28: =H27 -> 17332322 | I28: =H28-H27 -> 0 | J28: =J27 -> 28316014 | K28: =J28-J27 -> 0 | L28: =L27 -> 22730712 | M28: =L28-L27 -> 0 | N28: =M28+K28+I28+G28+E28 -> 0 | O28: =IF(B28>0,N28/B28,0) -> 0 | P28: =P27 -> 15355.608 | Q28: =(P28-P27)*1000 -> 0 | R28: =N28-Q28 -> 0 | S28: =S27 -> 8384 | T28: =S28-S27 -> 0 | U28: =U27 -> 1024343 | V28: =U28-U27 -> 0 | W28: =W27 -> 31845 | X28: =W28-W27 -> 0 | Y28: =Y27 -> 624440 | Z28: =Y28-Y27 -> 0 | AA28: =AA27 -> 34936 | AB28: =AA28-AA27 -> 0 | AC28: =AC27 -> 751223 | AD28: =AC28-AC27 -> 0 | AE28: =AB28+X28+T28 -> 0 | AF28: =V28+Z28+AD28 -> 0 | AG28: =IF(AE28>0,AF28/AE28,0) -> 0 | AI28: =R28-'EDl log'!B26 -> -49548451
A29: ='General information '!F32 -> 0 | B29: =SUM(230*A29) -> 0 | C29: 43888 | D29: =D28 -> 31458170 | E29: =D29-D28 -> 0 | F29: =F28 -> 3543226 | G29: =F29-F28 -> 0 | H29: =H28 -> 17332322 | I29: =H29-H28 -> 0 | J29: =J28 -> 28316014 | K29: =J29-J28 -> 0 | L29: =L28 -> 22730712 | M29: =L29-L28 -> 0 | N29: =M29+K29+I29+G29+E29 -> 0 | O29: =IF(B29>0,N29/B29,0) -> 0 | P29: =P28 -> 15355.608 | Q29: =(P29-P28)*1000 -> 0 | R29: =N29-Q29 -> 0 | S29: =S28 -> 8384 | T29: =S29-S28 -> 0 | U29: =U28 -> 1024343 | V29: =U29-U28 -> 0 | W29: =W28 -> 31845 | X29: =W29-W28 -> 0 | Y29: =Y28 -> 624440 | Z29: =Y29-Y28 -> 0 | AA29: =AA28 -> 34936 | AB29: =AA29-AA28 -> 0 | AC29: =AC28 -> 751223 | AD29: =AC29-AC28 -> 0 | AE29: =AB29+X29+T29 -> 0 | AF29: =V29+Z29+AD29 -> 0 | AG29: =IF(AE29>0,AF29/AE29,0) -> 0 | AI29: =R29-'EDl log'!B27 -> -49548451
A30: ='General information '!F33 -> 0 | B30: =SUM(230*A30) -> 0 | C30: 43889 | D30: =D29 -> 31458170 | E30: =D30-D29 -> 0 | F30: =F29 -> 3543226 | G30: =F30-F29 -> 0 | H30: =H29 -> 17332322 | I30: =H30-H29 -> 0 | J30: =J29 -> 28316014 | K30: =J30-J29 -> 0 | L30: =L29 -> 22730712 | M30: =L30-L29 -> 0 | N30: =M30+K30+I30+G30+E30 -> 0 | O30: =IF(B30>0,N30/B30,0) -> 0 | P30: =P29 -> 15355.608 | Q30: =(P30-P29)*1000 -> 0 | R30: =N30-Q30 -> 0 | S30: =S29 -> 8384 | T30: =S30-S29 -> 0 | U30: =U29 -> 1024343 | V30: =U30-U29 -> 0 | W30: =W29 -> 31845 | X30: =W30-W29 -> 0 | Y30: =Y29 -> 624440 | Z30: =Y30-Y29 -> 0 | AA30: =AA29 -> 34936 | AB30: =AA30-AA29 -> 0 | AC30: =AC29 -> 751223 | AD30: =AC30-AC29 -> 0 | AE30: =AB30+X30+T30 -> 0 | AF30: =V30+Z30+AD30 -> 0 | AG30: =IF(AE30>0,AF30/AE30,0) -> 0 | AI30: =R30-'EDl log'!B28 -> -49548451
A31: ='General information '!F34 -> 0 | B31: =SUM(230*A31) -> 0 | C31: 43890 | D31: =D30 -> 31458170 | E31: =D31-D30 -> 0 | F31: =F30 -> 3543226 | G31: =F31-F30 -> 0 | H31: =H30 -> 17332322 | I31: =H31-H30 -> 0 | J31: =J30 -> 28316014 | K31: =J31-J30 -> 0 | L31: =L30 -> 22730712 | M31: =L31-L30 -> 0 | N31: =M31+K31+I31+G31+E31 -> 0 | O31: =IF(B31>0,N31/B31,0) -> 0 | P31: =P30 -> 15355.608 | Q31: =(P31-P30)*1000 -> 0 | R31: =N31-Q31 -> 0 | S31: =S30 -> 8384 | T31: =S31-S30 -> 0 | U31: =U30 -> 1024343 | V31: =U31-U30 -> 0 | W31: =W30 -> 31845 | X31: =W31-W30 -> 0 | Y31: =Y30 -> 624440 | Z31: =Y31-Y30 -> 0 | AA31: =AA30 -> 34936 | AB31: =AA31-AA30 -> 0 | AC31: =AC30 -> 751223 | AD31: =AC31-AC30 -> 0 | AE31: =AB31+X31+T31 -> 0 | AF31: =V31+Z31+AD31 -> 0 | AG31: =IF(AE31>0,AF31/AE31,0) -> 0 | AI31: =R31-'EDl log'!B29 -> -49548451
A32: ='General information '!F35 -> 0 | B32: =SUM(230*A32) -> 0 | D32: =D31 -> 31458170 | E32: =D32-D31 -> 0 | F32: =F31 -> 3543226 | G32: =F32-F31 -> 0 | H32: =H31 -> 17332322 | I32: =H32-H31 -> 0 | J32: =J31 -> 28316014 | K32: =J32-J31 -> 0 | L32: =L31 -> 22730712 | M32: =L32-L31 -> 0 | N32: =M32+K32+I32+G32+E32 -> 0 | O32: =IF(B32>0,N32/B32,0) -> 0 | P32: =P31 -> 15355.608 | Q32: =(P32-P31)*1000 -> 0 | R32: =N32-Q32 -> 0 | S32: =S31 -> 8384 | T32: =S32-S31 -> 0 | U32: =U31 -> 1024343 | V32: =U32-U31 -> 0 | W32: =W31 -> 31845 | X32: =W32-W31 -> 0 | Y32: =Y31 -> 624440 | Z32: =Y32-Y31 -> 0 | AA32: =AA31 -> 34936 | AB32: =AA32-AA31 -> 0 | AC32: =AC31 -> 751223 | AD32: =AC32-AC31 -> 0 | AE32: =AB32+X32+T32 -> 0 | AF32: =V32+Z32+AD32 -> 0 | AG32: =IF(AE32>0,AF32/AE32,0) -> 0 | AI32: =R32-'EDl log'!B30 -> -49548451
A33: ='General information '!F36 -> 0 | B33: =SUM(230*A33) -> 0 | D33: =D32 -> 31458170 | E33: =D33-D32 -> 0 | F33: =F32 -> 3543226 | G33: =F33-F32 -> 0 | H33: =H32 -> 17332322 | I33: =H33-H32 -> 0 | J33: =J32 -> 28316014 | K33: =J33-J32 -> 0 | L33: =L32 -> 22730712 | M33: =L33-L32 -> 0 | N33: =M33+K33+I33+G33+E33 -> 0 | O33: =IF(B33>0,N33/B33,0) -> 0 | P33: =P32 -> 15355.608 | Q33: =(P33-P32)*1000 -> 0 | R33: =N33-Q33 -> 0 | S33: =S32 -> 8384 | T33: =S33-S32 -> 0 | U33: =U32 -> 1024343 | V33: =U33-U32 -> 0 | W33: =W32 -> 31845 | X33: =W33-W32 -> 0 | Y33: =Y32 -> 624440 | Z33: =Y33-Y32 -> 0 | AA33: =AA32 -> 34936 | AB33: =AA33-AA32 -> 0 | AC33: =AC32 -> 751223 | AD33: =AC33-AC32 -> 0 | AE33: =AB33+X33+T33 -> 0 | AF33: =V33+Z33+AD33 -> 0 | AG33: =IF(AE33>0,AF33/AE33,0) -> 0 | AI33: =R33-'EDl log'!B31 -> -49548451

Sheet B5
F1: Boiler A | J1: =J36 -> 76.638542 | K1: Boiler B | P1: Boiler C | V1: Boiler | X1: SteamA | AC1: SteamB | AH1: Steam | AI1: Boiler & steam | AL1: Total Boiler Runing H | AM1: Total Steam Runing H | AN1: GAS1 % | AO1: GAS1/L | AP1: GAS2% | AQ1: Gas2/L | AR1: GAS3% | AS1: GAS3/L | AU1: Gas Cons | AV1: Delivery | AW1: Cost/L
B2: Level Tank Gen | C2: Level tank Boiler | D2: Daily Cons Bo. | E2: Boiler litter | F2: Boiler A | G2: Run Hr a | H2: Boiler A fuel | I2: Daily consumption | J2: AVG | K2: index Run H | L2: Run Hrb | M2: Boiler B Fuel | O2: Daily consumption | P2: Boiler C | S2: Run C | U2: Total RH | V2: Total Fuel | X2: SteamA | Y2: Run SA | Z2: Steam A Conter | AA2: Liters | AC2: SteamB | AD2: Run SteamB | AE2: Steam B Conter | AF2: SB Litters | AG2: Avg | AH2: Total Fuel | AI2: Total Fuel
S3: 0
A4: =ELEC!C2 -> 31-01-2020 | B4: =[1]B5!B35 -> 242.4 | C4: =[1]B5!C35 -> 248 | D4: =[1]B5!D35 -> 5.1 | E4: =[1]B5!E35 -> 42.738 | F4: =[1]B5!F35 -> 1365 | G4: =[1]B5!G35 -> 4 | H4: =[1]B5!H35 -> 335279 | I4: =[1]B5!I35 -> 270 | ... AX4: =[1]B5!AX35 -> 0.7
A5: =ELEC!C3 -> 43862 | B5: 237 | C5: 242 | D5: =C4-C5 -> 6 | E5: =D5*8.38 -> 50.28 | F5: 1368 | G5: =F5-F4 -> 3 | H5: 335533 | I5: =SUM(H5-H4) -> 254 | J5: 1 | K5: 1760 | L5: =K5-K4 -> 4 | M5: 128367 | N5: =M5-M4 -> 276 | O5: =SUM(L5*$J$1) -> 306.55417 | P5: =P4 -> 1590 | Q5: =Q4 -> 136769 | R5: =Q5-Q4 -> 0 | S5: =SUM(P5-P4) -> 0 | T5: =SUM(S5*$T$2) -> 0 | U5: =SUM(G5+L5+S5) -> 7 | V5: =R5+N5+I5:I5 -> 530 | W5: =SUM(V5/U5) -> 75.714286 | X5: =X4 -> 2320 | Y5: =X5-X4 -> 0 | Z5: =Z4 -> 130593 | AA5: =Z5-Z4 -> 0 | AB5: =SUM(Y5*$AB$2) -> 0 | AC5: =AC4 -> 1800 | AD5: =AC5-AC4 -> 0 | AE5: =AE4 -> 357647.9 | AF5: =AE5-AE4 -> 0 | AG5: =IF(AD5>0,AF5/AD5,0) -> 0 | AH5: =AF5+AA5 -> 0 | AI5: =SUM(AH5+V5) -> 530 | AJ5: =-tanks!AW6 -> 530 | AK5: =SUM(AJ5-AI5) -> 0 | AL5: =S5+L5+G5 -> 7 | AM5: =Y5+AD5 -> 0 | AN5: 78 | AO5: =(AN5/100)*3000 -> 2340 | AP5: 78 | AQ5: =(AP5/100)*3000 -> 2340 | AR5: 78 | AS5: =(AR5/100)*3000 -> 2340 | AT5: =SUM(AO5+AQ5+AS5) -> 7020 | AU5: =AT4-AT5+AV5 -> 90 | AX5: =IF(AV5>0,AW5,AX4) -> 0.7
A6: =ELEC!C4 -> 43863 | B6: 232 | C6: 238 | D6: =C5-C6 -> 4 | E6: =D6*8.38 -> 33.52 | F6: 1368 | G6: =F6-F5 -> 0 | H6: 335533 | I6: =SUM(H6-H5) -> 0 | J6: =IF(G6>0,I6/G6,0) -> 0 | K6: 1763 | L6: =K6-K5 -> 3 | M6: 128639 | N6: =M6-M5 -> 272 | O6: =SUM(L6*$J$1) -> 229.91563 | P6: 1595 | Q6: 137103 | R6: =Q6-Q5 -> 334 | S6: =SUM(P6-P5) -> 5 | T6: =SUM(S6*$T$2) -> 0 | U6: =SUM(G6+L6+S6) -> 8 | V6: =R6+N6+I6:I6 -> 606 | W6: =SUM(V6/U6) -> 75.75 | X6: 2320 | Y6: =X6-X5 -> 0 | Z6: 130593 | AA6: =Z6-Z5 -> 0 | AB6: =SUM(Y6*$AB$2) -> 0 | AC6: 1800 | AD6: =AC6-AC5 -> 0 | AE6: 357647.9 | AF6: =AE6-AE5 -> 0 | AG6: =IF(AD6>0,AF6/AD6,0) -> 0 | AH6: =AF6+AA6 -> 0 | AI6: =SUM(AH6+V6) -> 606 | AJ6: =-tanks!AW7 -> 606 | AK6: =SUM(AJ6-AI6) -> 0 | AL6: =S6+L6+G6 -> 8 | AM6: =Y6+AD6 -> 0 | AN6: 77 | AO6: =(AN6/100)*3000 -> 2310 | AP6: 75 | AQ6: =(AP6/100)*3000 -> 2250 | AR6: 75 | AS6: =(AR6/100)*3000 -> 2250 | AT6: =SUM(AO6+AQ6+AS6) -> 6810 | AU6: =AT5-AT6+AV6 -> 210 | AX6: =IF(AV6>0,AW6,AX5) -> 0.7
A7: =ELEC!C5 -> 43864 | B7: 226.4 | C7: 232.2 | D7: =C6-C7 -> 5.8 | E7: =D7*8.38 -> 48.604 | F7: 1373 | G7: =F7-F6 -> 5 | H7: 335970 | I7: =SUM(H7-H6) -> 437 | J7: =IF(G7>0,I7/G7,0) -> 87.4 | K7: 1763 | L7: =K7-K6 -> 0 | M7: 128639 | N7: =M7-M6 -> 0 | O7: 1 | P7: 1597 | Q7: 137321 | R7: =Q7-Q6 -> 218 | S7: =SUM(P7-P6) -> 2 | T7: =SUM(S7*$T$2) -> 0 | U7: =SUM(G7+L7+S7) -> 7 | V7: =R7+N7+I7:I7 -> 655 | W7: =SUM(V7/U7) -> 93.571429 | X7: 2320 | Y7: =X7-X6 -> 0 | Z7: 130593 | AA7: =Z7-Z6 -> 0 | AB7: =SUM(Y7*$AB$2) -> 0 | AC7: 1800 | AD7: =AC7-AC6 -> 0 | AE7: 357647.9 | AF7: =AE7-AE6 -> 0 | AG7: =IF(AD7>0,AF7/AD7,0) -> 0 | AH7: =AF7+AA7 -> 0 | AI7: =SUM(AH7+V7) -> 655 | AJ7: =-tanks!AW8 -> 655 | AK7: =SUM(AJ7-AI7) -> 0 | AL7: =S7+L7+G7 -> 7 | AM7: =Y7+AD7 -> 0 | AN7: 76 | AO7: =(AN7/100)*3000 -> 2280 | AP7: 74 | AQ7: =(AP7/100)*3000 -> 2220 | AR7: 74 | AS7: =(AR7/100)*3000 -> 2220 | AT7: =SUM(AO7+AQ7+AS7) -> 6720 | AU7: =AT6-AT7+AV7 -> 90 | AX7: =IF(AV7>0,AW7,AX6) -> 0.7
A8: =ELEC!C6 -> 43865 | B8: 220 | C8: 226 | D8: =C7-C8 -> 6.2 | E8: =D8*8.38 -> 51.956 | F8: 1377 | G8: =F8-F7 -> 4 | H8: 336311 | I8: =SUM(H8-H7) -> 341 | J8: =IF(G8>0,I8/G8,0) -> 85.25 | K8: 1767 | L8: =K8-K7 -> 4 | M8: 128883 | N8: =M8-M7 -> 244 | O8: 1479 | P8: 1599 | Q8: 137447 | R8: =Q8-Q7 -> 126 | S8: =SUM(P8-P7) -> 2 | T8: =SUM(S8*$T$2) -> 0 | U8: =SUM(G8+L8+S8) -> 10 | V8: =R8+N8+I8:I8 -> 711 | W8: =SUM(V8/U8) -> 71.1 | X8: 2328 | Y8: =X8-X7 -> 8 | Z8: 131019.7 | AA8: =Z8-Z7 -> 426.7 | AB8: =SUM(Y8*$AB$2) -> 0 | AC8: =AC7 -> 1800 | AD8: =AC8-AC7 -> 0 | AE8: =AE7 -> 357647.9 | AF8: =AE8-AE7 -> 0 | AG8: =IF(AD8>0,AF8/AD8,0) -> 0 | AH8: =AF8+AA8 -> 426.7 | AI8: =SUM(AH8+V8) -> 1137.7 | AJ8: =-tanks!AW9 -> 1137.7 | AK8: =SUM(AJ8-AI8) -> 0 | AL8: =S8+L8+G8 -> 10 | AM8: =Y8+AD8 -> 8 | AN8: 74 | AO8: =(AN8/100)*3000 -> 2220 | AP8: 72 | AQ8: =(AP8/100)*3000 -> 2160 | AR8: 72 | AS8: =(AR8/100)*3000 -> 2160 | AT8: =SUM(AO8+AQ8+AS8) -> 6540 | AU8: =AT7-AT8+AV8 -> 180 | AX8: =IF(AV8>0,AW8,AX7) -> 0.7
A9: =ELEC!C7 -> 43866 | B9: 214.2 | C9: 220 | D9: =C8-C9 -> 6 | E9: =D9*8.38 -> 50.28 | F9: 1377 | G9: =F9-F8 -> 0 | H9: 336311 | I9: =SUM(H9-H8) -> 0 | J9: =IF(G9>0,I9/G9,0) -> 0 | K9: 1771 | L9: =K9-K8 -> 4 | M9: 129199 | N9: =M9-M8 -> 316 | O9: =SUM(L9*$J$1) -> 306.55417 | P9: 1603 | Q9: 137748 | R9: =Q9-Q8 -> 301 | S9: =SUM(P9-P8) -> 4 | T9: =SUM(S9*$T$2) -> 0 | U9: =SUM(G9+L9+S9) -> 8 | V9: =R9+N9+I9:I9 -> 617 | W9: =SUM(V9/U9) -> 77.125 | X9: 2328 | Y9: =X9-X8 -> 0 | Z9: 131019.7 | AA9: =Z9-Z8 -> 0 | AB9: =SUM(Y9*$AB$2) -> 0 | AC9: 1800 | AD9: =AC9-AC8 -> 0 | AE9: 357647.9 | AF9: =AE9-AE8 -> 0 | AG9: =IF(AD9>0,AF9/AD9,0) -> 0 | AH9: =AF9+AA9 -> 0 | AI9: =SUM(AH9+V9) -> 617 | AJ9: =-tanks!AW10 -> 617 | AK9: =SUM(AJ9-AI9) -> 0 | AL9: =S9+L9+G9 -> 8 | AM9: =Y9+AD9 -> 0 | AN9: 72 | AO9: =(AN9/100)*3000 -> 2160 | AP9: 70 | AQ9: =(AP9/100)*3000 -> 2100 | AR9: 70 | AS9: =(AR9/100)*3000 -> 2100 | AT9: =SUM(AO9+AQ9+AS9) -> 6360 | AU9: =AT8-AT9+AV9 -> 180 | AX9: =IF(AV9>0,AW9,AX8) -> 0.7
A10: =ELEC!C8 -> 43867 | B10: 210.3 | C10: 216.4 | D10: =C9-C10 -> 3.6 | E10: =D10*8.38 -> 30.168 | F10: 1380 | G10: =F10-F9 -> 3 | H10: 336523 | I10: =SUM(H10-H9) -> 212 | J10: =IF(G10>0,I10/G10,0) -> 70.666667 | K10: =K9 -> 1771 | L10: =K10-K9 -> 0 | M10: =M9 -> 129199 | N10: =M10-M9 -> 0 | O10: =SUM(L10*$J$1) -> 0 | P10: 1606 | Q10: 137989 | R10: =Q10-Q9 -> 241 | S10: =SUM(P10-P9) -> 3 | T10: =SUM(S10*$T$2) -> 0 | U10: =SUM(G10+L10+S10) -> 6 | V10: =R10+N10+I10:I10 -> 453 | W10: =SUM(V10/U10) -> 75.5 | X10: =X9 -> 2328 | Y10: =X10-X9 -> 0 | Z10: =Z9 -> 131019.7 | AA10: =Z10-Z9 -> 0 | AB10: =SUM(Y10*$AB$2) -> 0 | AC10: =AC9 -> 1800 | AD10: =AC10-AC9 -> 0 | AE10: =AE9 -> 357647.9 | AF10: =AE10-AE9 -> 0 | AG10: =IF(AD10>0,AF10/AD10,0) -> 0 | AH10: =AF10+AA10 -> 0 | AI10: =SUM(AH10+V10) -> 453 | AJ10: =-tanks!AW11 -> 453 | AK10: =SUM(AJ10-AI10) -> 0 | AL10: =S10+L10+G10 -> 6 | AM10: =Y10+AD10 -> 0 | AN10: 80 | AO10: =(AN10/100)*3000 -> 2400 | AP10: 79 | AQ10: =(AP10/100)*3000 -> 2370 | AR10: 79 | AS10: =(AR10/100)*3000 -> 2370 | AT10: =SUM(AO10+AQ10+AS10) -> 7140 | AU10: =AT9-AT10+AV10 -> 320 | AV10: 1100 | AW10: 0.7 | AX10: =IF(AV10>0,AW10,AX9) -> 0.7
A11: =ELEC!C9 -> 43868 | B11: 252 | C11: 259 | D11: =C10-C11 -> -42.6 | E11: =D11*8.38 -> -356.988 | F11: 1383 | G11: =F11-F10 -> 3 | H11: 336745 | I11: =SUM(H11-H10) -> 222 | J11: =IF(G11>0,I11/G11,0) -> 74 | K11: 1775 | L11: =K11-K10 -> 4 | M11: 129531 | N11: =M11-M10 -> 332 | O11: =SUM(L11*$J$1) -> 306.55417 | P11: =P10 -> 1606 | Q11: =Q10 -> 137989 | R11: =Q11-Q10 -> 0 | S11: =SUM(P11-P10) -> 0 | T11: =SUM(S11*$T$2) -> 0 | U11: =SUM(G11+L11+S11) -> 7 | V11: =R11+N11+I11:I11 -> 554 | W11: =SUM(V11/U11) -> 79.142857 | X11: 2335 | Y11: =X11-X10 -> 7 | Z11: 131372.6 | AA11: =Z11-Z10 -> 352.9 | AB11: =SUM(Y11*$AB$2) -> 0 | AC11: =AC10 -> 1800 | AD11: =AC11-AC10 -> 0 | AE11: =AE10 -> 357647.9 | AF11: =AE11-AE10 -> 0 | AG11: =IF(AD11>0,AF11/AD11,0) -> 0 | AH11: =AF11+AA11 -> 352.9 | AI11: =SUM(AH11+V11) -> 906.9 | AJ11: =-tanks!AW12 -> 906.9 | AK11: =SUM(AJ11-AI11) -> 0 | AL11: =S11+L11+G11 -> 7 | AM11: =Y11+AD11 -> 7 | AN11: 78 | AO11: =(AN11/100)*3000 -> 2340 | AP11: 78 | AQ11: =(AP11/100)*3000 -> 2340 | AR11: 78 | AS11: =(AR11/100)*3000 -> 2340 | AT11: =SUM(AO11+AQ11+AS11) -> 7020 | AU11: =AT10-AT11+AV11 -> 120 | AX11: =IF(AV11>0,AW11,AX10) -> 0.7
A12: =ELEC!C10 -> 43869 | B12: 248 | C12: 253.4 | D12: =C11-C12 -> 5.6 | E12: =D12*8.38 -> 46.928 | F12: =F11 -> 1383 | G12: =F12-F11 -> 0 | H12: =H11 -> 336745 | I12: =SUM(H12-H11) -> 0 | J12: =IF(G12>0,I12/G12,0) -> 0 | K12: 1779 | L12: =K12-K11 -> 4 | M12: 129837 | N12: =M12-M11 -> 306 | O12: =SUM(L12*$J$1) -> 306.55417 | P12: 1610 | Q12: 138263 | R12: =Q12-Q11 -> 274 | S12: =SUM(P12-P11) -> 4 | T12: =SUM(S12*$T$2) -> 0 | U12: =SUM(G12+L12+S12) -> 8 | V12: =R12+N12+I12:I12 -> 580 | W12: =SUM(V12/U12) -> 72.5 | X12: =X11 -> 2335 | Y12: =X12-X11 -> 0 | Z12: 131398.9 | AA12: =Z12-Z11 -> 26.3 | AB12: =SUM(Y12*$AB$2) -> 0 | AC12: 1801 | AD12: =AC12-AC11 -> 1 | AE12: 357711.4 | AF12: =AE12-AE11 -> 63.5 | AG12: =IF(AD12>0,AF12/AD12,0) -> 63.5 | AH12: =AF12+AA12 -> 89.8 | AI12: =SUM(AH12+V12) -> 669.8 | AJ12: =-tanks!AW13 -> 669.8 | AK12: =SUM(AJ12-AI12) -> 0 | AL12: =S12+L12+G12 -> 8 | AM12: =Y12+AD12 -> 1 | AN12: 77 | AO12: =(AN12/100)*3000 -> 2310 | AP12: 77 | AQ12: =(AP12/100)*3000 -> 2310 | AR12: 77 | AS12: =(AR12/100)*3000 -> 2310 | AT12: =SUM(AO12+AQ12+AS12) -> 6930 | AU12: =AT11-AT12+AV12 -> 90 | AX12: =IF(AV12>0,AW12,AX11) -> 0.7
A13: =ELEC!C11 -> 43870 | B13: 242 | C13: 248 | D13: =C12-C13 -> 5.4 | E13: =D13*8.38 -> 45.252 | F13: 1387 | G13: =F13-F12 -> 4 | H13: 337106 | I13: =SUM(H13-H12) -> 361 | J13: =IF(G13>0,I13/G13,0) -> 90.25 | K13: =K12 -> 1779 | L13: =K13-K12 -> 0 | M13: =M12 -> 129837 | N13: =M13-M12 -> 0 | O13: =SUM(L13*$J$1) -> 0 | P13: 1616 | Q13: 138730 | R13: =Q13-Q12 -> 467 | S13: =SUM(P13-P12) -> 6 | T13: =SUM(S13*$T$2) -> 0 | U13: =SUM(G13+L13+S13) -> 10 | V13: =R13+N13+I13:I13 -> 828 | W13: =SUM(V13/U13) -> 82.8 | X13: =X12 -> 2335 | Y13: =X13-X12 -> 0 | Z13: =Z12 -> 131398.9 | AA13: =Z13-Z12 -> 0 | AB13: =SUM(Y13*$AB$2) -> 0 | AC13: =AC12 -> 1801 | AD13: =AC13-AC12 -> 0 | AE13: =AE12 -> 357711.4 | AF13: =AE13-AE12 -> 0 | AG13: =IF(AD13>0,AF13/AD13,0) -> 0 | AH13: =AF13+AA13 -> 0 | AI13: =SUM(AH13+V13) -> 828 | AJ13: =-tanks!AW14 -> 828 | AK13: =SUM(AJ13-AI13) -> 0 | AL13: =S13+L13+G13 -> 10 | AM13: =Y13+AD13 -> 0 | AN13: 74 | AO13: =(AN13/100)*3000 -> 2220 | AP13: 74 | AQ13: =(AP13/100)*3000 -> 2220 | AR13: 74 | AS13: =(AR13/100)*3000 -> 2220 | AT13: =SUM(AO13+AQ13+AS13) -> 6660 | AU13: =AT12-AT13+AV13 -> 270 | AX13: =IF(AV13>0,AW13,AX12) -> 0.7
A14: =ELEC!C12 -> 43871 | B14: 236.1 | C14: 241.4 | D14: =C13-C14 -> 6.6 | E14: =D14*8.38 -> 55.308 | F14: 1394 | G14: =F14-F13 -> 7 | H14: 337680 | I14: =SUM(H14-H13) -> 574 | J14: =IF(G14>0,I14/G14,0) -> 82 | K14: 1784 | L14: =K14-K13 -> 5 | M14: 130244 | N14: =M14-M13 -> 407 | O14: =SUM(L14*$J$1) -> 383.19271 | P14: 1617 | Q14: 138848 | R14: =Q14-Q13 -> 118 | S14: =SUM(P14-P13) -> 1 | T14: =SUM(S14*$T$2) -> 0 | U14: =SUM(G14+L14+S14) -> 13 | V14: =R14+N14+I14:I14 -> 1099 | W14: =SUM(V14/U14) -> 84.538462 | X14: 2335 | Y14: =X14-X13 -> 0 | Z14: 131398.9 | AA14: =Z14-Z13 -> 0 | AB14: =SUM(Y14*$AB$2) -> 0 | AC14: 1801 | AD14: =AC14-AC13 -> 0 | AE14: 357711 | AF14: =AE14-AE13 -> -0.4 | AG14: =IF(AD14>0,AF14/AD14,0) -> 0 | AH14: =AF14+AA14 -> -0.4 | AI14: =SUM(AH14+V14) -> 1098.6 | AJ14: =-tanks!AW15 -> 1098.6 | AK14: =SUM(AJ14-AI14) -> 0 | AL14: =S14+L14+G14 -> 13 | AM14: =Y14+AD14 -> 0 | AN14: 71 | AO14: =(AN14/100)*3000 -> 2130 | AP14: 71 | AQ14: =(AP14/100)*3000 -> 2130 | AR14: 71 | AS14: =(AR14/100)*3000 -> 2130 | AT14: =SUM(AO14+AQ14+AS14) -> 6390 | AU14: =AT13-AT14+AV14 -> 270 | AX14: =IF(AV14>0,AW14,AX13) -> 0.7
A15: =ELEC!C13 -> 43872 | B15: 230 | C15: 235.4 | D15: =C14-C15 -> 6 | E15: =D15*8.38 -> 50.28 | F15: 1394 | G15: =F15-F14 -> 0 | H15: 337680 | I15: =SUM(H15-H14) -> 0 | J15: =IF(G15>0,I15/G15,0) -> 0 | K15: 1792 | L15: =K15-K14 -> 8 | M15: 130802 | N15: =M15-M14 -> 558 | O15: =SUM(L15*$J$1) -> 613.10833 | P15: 1623 | Q15: 139294 | R15: =Q15-Q14 -> 446 | S15: =SUM(P15-P14) -> 6 | T15: =SUM(S15*$T$2) -> 0 | U15: =SUM(G15+L15+S15) -> 14 | V15: =R15+N15+I15:I15 -> 1004 | W15: =SUM(V15/U15) -> 71.714286 | X15: 2344 | Y15: =X15-X14 -> 9 | Z15: 131862.6 | AA15: =Z15-Z14 -> 463.7 | AB15: =SUM(Y15*$AB$2) -> 0 | AC15: 1801 | AD15: =AC15-AC14 -> 0 | AE15: 357711.4 | AF15: =AE15-AE14 -> 0.4 | AG15: =IF(AD15>0,AF15/AD15,0) -> 0 | AH15: =AF15+AA15 -> 464.1 | AI15: =SUM(AH15+V15) -> 1468.1 | AJ15: =-tanks!AW16 -> 1468.1 | AK15: =SUM(AJ15-AI15) -> 0 | AL15: =S15+L15+G15 -> 14 | AM15: =Y15+AD15 -> 9 | AN15: 70 | AO15: =(AN15/100)*3000 -> 2100 | AP15: 70 | AQ15: =(AP15/100)*3000 -> 2100 | AR15: 70 | AS15: =(AR15/100)*3000 -> 2100 | AT15: =SUM(AO15+AQ15+AS15) -> 6300 | AU15: =AT14-AT15+AV15 -> 90 | AX15: =IF(AV15>0,AW15,AX14) -> 0.7
A16: =ELEC!C14 -> 43873 | B16: 223 | C16: 229.5 | D16: =C15-C16 -> 5.9 | E16: =D16*8.38 -> 49.442 | F16: 1399 | G16: =F16-F15 -> 5 | H16: 338058 | I16: =SUM(H16-H15) -> 378 | J16: =IF(G16>0,I16/G16,0) -> 75.6 | K16: =K15 -> 1792 | L16: =K16-K15 -> 0 | M16: =M15 -> 130802 | N16: =M16-M15 -> 0 | O16: =SUM(L16*$J$1) -> 0 | P16: 1630 | Q16: 139796 | R16: =Q16-Q15 -> 502 | S16: =SUM(P16-P15) -> 7 | T16: =SUM(S16*$T$2) -> 0 | U16: =SUM(G16+L16+S16) -> 12 | V16: =R16+N16+I16:I16 -> 880 | W16: =SUM(V16/U16) -> 73.333333 | X16: =X15 -> 2344 | Y16: =X16-X15 -> 0 | Z16: =Z15 -> 131862.6 | AA16: =Z16-Z15 -> 0 | AB16: =SUM(Y16*$AB$2) -> 0 | AC16: =AC15 -> 1801 | AD16: =AC16-AC15 -> 0 | AE16: =AE15 -> 357711.4 | AF16: =AE16-AE15 -> 0 | AG16: =IF(AD16>0,AF16/AD16,0) -> 0 | AH16: =AF16+AA16 -> 0 | AI16: =SUM(AH16+V16) -> 880 | AJ16: =-tanks!AW17 -> 880 | AK16: =SUM(AJ16-AI16) -> 0 | AL16: =S16+L16+G16 -> 12 | AM16: =Y16+AD16 -> 0 | AN16: 69 | AO16: =(AN16/100)*3000 -> 2070 | AP16: 69 | AQ16: =(AP16/100)*3000 -> 2070 | AR16: 68 | AS16: =(AR16/100)*3000 -> 2040 | AT16: =SUM(AO16+AQ16+AS16) -> 6180 | AU16: =AT15-AT16+AV16 -> 120 | AX16: =IF(AV16>0,AW16,AX15) -> 0.7
A17: =ELEC!C15 -> 43874 | B17: 219 | C17: 225 | D17: =C16-C17 -> 4.5 | E17: =D17*8.38 -> 37.71 | F17: 1403 | G17: =F17-F16 -> 4 | H17: 338387 | I17: =SUM(H17-H16) -> 329 | J17: =IF(G17>0,I17/G17,0) -> 82.25 | K17: 1793 | L17: =K17-K16 -> 1 | M17: 130929 | N17: =M17-M16 -> 127 | O17: =SUM(L17*$J$1) -> 76.638542 | P17: 1634 | Q17: 140075 | R17: =Q17-Q16 -> 279 | S17: =SUM(P17-P16) -> 4 | T17: =SUM(S17*$T$2) -> 0 | U17: =SUM(G17+L17+S17) -> 9 | V17: =R17+N17+I17:I17 -> 735 | X17: 2344 | Y17: =X17-X16 -> 0 | Z17: 131862.6 | AA17: =Z17-Z16 -> 0 | AB17: =SUM(Y17*$AB$2) -> 0 | AC17: 1801 | AD17: =AC17-AC16 -> 0 | AE17: 357711.4 | AF17: =AE17-AE16 -> 0 | AG17: =IF(AD17>0,AF17/AD17,0) -> 0 | AH17: =AF17+AA17 -> 0 | AI17: =SUM(AH17+V17) -> 735 | AJ17: =-tanks!AW18 -> 735 | AK17: =SUM(AJ17-AI17) -> 0 | AL17: =S17+L17+G17 -> 9 | AM17: =Y17+AD17 -> 0 | AN17: 80 | AO17: =(AN17/100)*3000 -> 2400 | AP17: 80 | AQ17: =(AP17/100)*3000 -> 2400 | AR17: 80 | AS17: =(AR17/100)*3000 -> 2400 | AT17: =SUM(AO17+AQ17+AS17) -> 7200 | AU17: =AT16-AT17+AV17 -> 380 | AV17: 1400 | AW17: 0.7 | AX17: =IF(AV17>0,AW17,AX16) -> 0.7
A18: =ELEC!C16 -> 43875 | B18: 213.2 | C18: 219 | D18: =C17-C18 -> 6 | E18: =D18*8.38 -> 50.28 | F18: =F17 -> 1403 | G18: =F18-F17 -> 0 | H18: =H17 -> 338387 | I18: =SUM(H18-H17) -> 0 | J18: =IF(G18>0,I18/G18,0) -> 0 | K18: =K17 -> 1793 | L18: =K18-K17 -> 0 | M18: =M17 -> 130929 | N18: =M18-M17 -> 0 | O18: =SUM(L18*$J$1) -> 0 | P18: 1643 | Q18: 140820 | R18: =Q18-Q17 -> 745 | S18: =SUM(P18-P17) -> 9 | T18: =SUM(S18*$T$2) -> 0 | U18: =SUM(G18+L18+S18) -> 9 | V18: =R18+N18+I18:I18 -> 745 | X18: 2353 | Y18: =X18-X17 -> 9 | Z18: 132298.7 | AA18: =Z18-Z17 -> 436.1 | AB18: =SUM(Y18*$AB$2) -> 0 | AC18: =AC17 -> 1801 | AD18: =AC18-AC17 -> 0 | AE18: 357717.4 | AF18: =AE18-AE17 -> 6 | AG18: =IF(AD18>0,AF18/AD18,0) -> 0 | AH18: =AF18+AA18 -> 442.1 | AI18: =SUM(AH18+V18) -> 1187.1 | AJ18: =-tanks!AW19 -> 1187.1 | AK18: =SUM(AJ18-AI18) -> 0 | AL18: =S18+L18+G18 -> 9 | AM18: =Y18+AD18 -> 9 | AN18: 78 | AO18: =(AN18/100)*3000 -> 2340 | AP18: 79 | AQ18: =(AP18/100)*3000 -> 2370 | AR18: 79 | AS18: =(AR18/100)*3000 -> 2370 | AT18: =SUM(AO18+AQ18+AS18) -> 7080 | AU18: =AT17-AT18+AV18 -> 120 | AX18: =IF(AV18>0,AW18,AX17) -> 0.7
A19: =ELEC!C17 -> 43876 | B19: 206.1 | C19: 212 | D19: =C18-C19 -> 7 | E19: =D19*8.38 -> 58.66 | F19: 1408 | G19: =F19-F18 -> 5 | H19: 338776 | I19: =SUM(H19-H18) -> 389 | J19: =IF(G19>0,I19/G19,0) -> 77.8 | K19: =K18 -> 1793 | L19: =K19-K18 -> 0 | M19: =M18 -> 130929 | N19: =M19-M18 -> 0 | O19: =SUM(L19*$J$1) -> 0 | P19: 1648 | Q19: 141150 | R19: =Q19-Q18 -> 330 | S19: =SUM(P19-P18) -> 5 | T19: =SUM(S19*$T$2) -> 0 | U19: =SUM(G19+L19+S19) -> 10 | V19: =R19+N19+I19:I19 -> 719 | X19: =X18 -> 2353 | Y19: =X19-X18 -> 0 | Z19: 132325.7 | AA19: =Z19-Z18 -> 27 | AB19: =SUM(Y19*$AB$2) -> 0 | AC19: =AC18 -> 1801 | AD19: =AC19-AC18 -> 0 | AE19: 357717.4 | AF19: =AE19-AE18 -> 0 | AG19: =IF(AD19>0,AF19/AD19,0) -> 0 | AH19: =AF19+AA19 -> 27 | AI19: =SUM(AH19+V19) -> 746 | AJ19: =-tanks!AW20 -> 746 | AK19: =SUM(AJ19-AI19) -> 0 | AL19: =S19+L20+G19 -> 15 | AM19: =Y19+AD19 -> 0 | AN19: 76 | AO19: =(AN19/100)*3000 -> 2280 | AP19: 78 | AQ19: =(AP19/100)*3000 -> 2340 | AR19: 78 | AS19: =(AR19/100)*3000 -> 2340 | AT19: =SUM(AO19+AQ19+AS19) -> 6960 | AU19: =AT18-AT19+AV19 -> 120 | AX19: =IF(AV19>0,AW19,AX18) -> 0.7
A20: =ELEC!C18 -> 43877 | B20: 202.3 | C20: 208.1 | D20: =C19-C20 -> 3.9 | E20: =D20*8.38 -> 32.682 | F20: 1411 | G20: =F20-F19 -> 3 | H20: 339042 | I20: =SUM(H20-H19) -> 266 | J20: =IF(G20>0,I20/G20,0) -> 88.666667 | K20: 1798 | L20: =K20-K19 -> 5 | M20: 131307 | N20: =M20-M19 -> 378 | O20: =SUM(L20*$J$1) -> 383.19271 | P20: =P19 -> 1648 | Q20: =Q19 -> 141150 | R20: =Q20-Q19 -> 0 | S20: =SUM(P20-P19) -> 0 | T20: =SUM(S20*$T$2) -> 0 | U20: =SUM(G20+L20+S20) -> 8 | V20: =R20+N20+I20:I20 -> 644 | X20: =X19 -> 2353 | Y20: =X20-X19 -> 0 | Z20: 132325.7 | AA20: =Z20-Z19 -> 0 | AB20: =SUM(Y20*$AB$2) -> 0 | AC20: =AC19 -> 1801 | AD20: =AC20-AC19 -> 0 | AE20: =AE19 -> 357717.4 | AF20: =AE20-AE19 -> 0 | AG20: =IF(AD20>0,AF20/AD20,0) -> 0 | AH20: =AF20+AA20 -> 0 | AI20: =SUM(AH20+V20) -> 644 | AJ20: =-tanks!AW21 -> 644 | AK20: =SUM(AJ20-AI20) -> 0 | AL20: =S20+L21+G20 -> 7 | AM20: =Y20+AD20 -> 0 | AN20: 74 | AO20: =(AN20/100)*3000 -> 2220 | AP20: 76 | AQ20: =(AP20/100)*3000 -> 2280 | AR20: 76 | AS20: =(AR20/100)*3000 -> 2280 | AT20: =SUM(AO20+AQ20+AS20) -> 6780 | AU20: =AT19-AT20+AV20 -> 180 | AX20: =IF(AV20>0,AW20,AX19) -> 0.7
A21: =ELEC!C19 -> 43878 | B21: 198 | C21: 203.3 | D21: =C20-C21 -> 4.8 | E21: =D21*8.38 -> 40.224 | F21: 1411 | G21: =F21-F20 -> 0 | H21: 339042 | I21: =SUM(H21-H20) -> 0 | J21: =IF(G21>0,I21/G21,0) -> 0 | K21: 1802 | L21: =K21-K20 -> 4 | M21: 131602 | N21: =M21-M20 -> 295 | O21: =SUM(L21*$J$1) -> 306.55417 | P21: 1652 | Q21: 141485 | R21: =Q21-Q20 -> 335 | S21: =SUM(P21-P20) -> 4 | T21: =SUM(S21*$T$2) -> 0 | U21: =SUM(G21+L21+S21) -> 8 | V21: =R21+N21+I21:I21 -> 630 | X21: 2353 | Y21: =X21-X20 -> 0 | Z21: 132325.7 | AA21: =Z21-Z20 -> 0 | AB21: =SUM(Y21*$AB$2) -> 0 | AC21: 1801 | AD21: =AC21-AC20 -> 0 | AE21: 357717.4 | AF21: =AE21-AE20 -> 0 | AG21: =IF(AD21>0,AF21/AD21,0) -> 0 | AH21: =AF21+AA21 -> 0 | AI21: =SUM(AH21+V21) -> 630 | AJ21: =-tanks!AW22 -> 630 | AK21: =SUM(AJ21-AI21) -> 0 | AL21: =S21+L21+G21 -> 8 | AM21: =Y21+AD21 -> 0 | AN21: 71 | AO21: =(AN21/100)*3000 -> 2130 | AP21: 73 | AQ21: =(AP21/100)*3000 -> 2190 | AR21: 73 | AS21: =(AR21/100)*3000 -> 2190 | AT21: =SUM(AO21+AQ21+AS21) -> 6510 | AU21: =AT20-AT21+AV21 -> 270 | AX21: =IF(AV21>0,AW21,AX20) -> 0.7
A22: =ELEC!C20 -> 43879 | B22: 251.2 | C22: 256.4 | D22: =C21-C22 -> -53.1 | E22: =D22*8.38 -> -444.978 | F22: 1415 | G22: =F22-F21 -> 4 | H22: 339352 | I22: =SUM(H22-H21) -> 310 | J22: =IF(G22>0,I22/G22,0) -> 77.5 | K22: 1802 | L22: =K22-K21 -> 0 | M22: 131602 | N22: =M22-M21 -> 0 | O22: =SUM(L22*$J$1) -> 0 | P22: 1656 | Q22: 141745 | R22: =Q22-Q21 -> 260 | S22: =SUM(P22-P21) -> 4 | T22: =SUM(S22*$T$2) -> 0 | U22: =SUM(G22+L22+S22) -> 8 | V22: =R22+N22+I22:I22 -> 570 | X22: 2363 | Y22: =X22-X21 -> 10 | Z22: 132877.7 | AA22: =Z22-Z21 -> 552 | AB22: =SUM(Y22*$AB$2) -> 0 | AC22: =AC21 -> 1801 | AD22: =AC22-AC21 -> 0 | AE22: =AE21 -> 357717.4 | AF22: =AE22-AE21 -> 0 | AG22: =IF(AD22>0,AF22/AD22,0) -> 0 | AH22: =AF22+AA22 -> 552 | AI22: =SUM(AH22+V22) -> 1122 | AJ22: =-tanks!AW23 -> 1122 | AK22: =SUM(AJ22-AI22) -> 0 | AL22: =S22+L22+G22 -> 8 | AM22: =Y22+AD22 -> 10 | AN22: 69 | AO22: =(AN22/100)*3000 -> 2070 | AP22: 71 | AQ22: =(AP22/100)*3000 -> 2130 | AR22: 72 | AS22: =(AR22/100)*3000 -> 2160 | AT22: =SUM(AO22+AQ22+AS22) -> 6360 | AU22: =AT21-AT22+AV22 -> 150 | AX22: =IF(AV22>0,AW22,AX21) -> 0.7
A23: =ELEC!C21 -> 43880 | B23: 245 | C23: 249.4 | D23: =C22-C23 -> 7 | E23: =D23*8.38 -> 58.66 | F23: 1418 | G23: =F23-F22 -> 3 | H23: 339608 | I23: =SUM(H23-H22) -> 256 | J23: =IF(G23>0,I23/G23,0) -> 85.333333 | K23: 1805 | L23: =K23-K22 -> 3 | M23: 131845 | N23: =M23-M22 -> 243 | O23: =SUM(L23*$J$1) -> 229.91563 | P23: 1656 | Q23: 141745 | R23: =Q23-Q22 -> 0 | S23: =SUM(P23-P22) -> 0 | T23: =SUM(S23*$T$2) -> 0 | U23: =SUM(G23+L23+S23) -> 6 | V23: =R23+N23+I23:I23 -> 499 | X23: 2363 | Y23: =X23-X22 -> 0 | Z23: 132877.7 | AA23: =Z23-Z22 -> 0 | AB23: =SUM(Y23*$AB$2) -> 0 | AC23: 1801 | AD23: =AC23-AC22 -> 0 | AE23: 357717.4 | AF23: =AE23-AE22 -> 0 | AG23: =IF(AD23>0,AF23/AD23,0) -> 0 | AH23: =AF23+AA23 -> 0 | AI23: =SUM(AH23+V23) -> 499 | AJ23: =-tanks!AW24 -> 499 | AK23: =SUM(AJ23-AI23) -> 0 | AL23: =S23+L23+G23 -> 6 | AM23: =Y23+AD23 -> 0 | AN23: 67 | AO23: =(AN23/100)*3000 -> 2010 | AP23: 69 | AQ23: =(AP23/100)*3000 -> 2070 | AR23: 70 | AS23: =(AR23/100)*3000 -> 2100 | AT23: =SUM(AO23+AQ23+AS23) -> 6180 | AU23: =AT22-AT23+AV23 -> 180 | AX23: =IF(AV23>0,AW23,AX22) -> 0.7
A24: =ELEC!C22 -> 43881 | B24: 241 | C24: 246.5 | D24: =C23-C24 -> 2.9 | E24: =D24*8.38 -> 24.302 | F24: 1418 | G24: =F24-F23 -> 0 | H24: 339608 | I24: =SUM(H24-H23) -> 0 | J24: =IF(G24>0,I24/G24,0) -> 0 | K24: 1809 | L24: =K24-K23 -> 4 | M24: 132120 | N24: =M24-M23 -> 275 | O24: =SUM(L24*$J$1) -> 306.55417 | P24: 1659 | Q24: 142011 | R24: =Q24-Q23 -> 266 | S24: =SUM(P24-P23) -> 3 | T24: =SUM(S24*$T$2) -> 0 | U24: =SUM(G24+L24+S24) -> 7 | V24: =R24+N24+I24:I24 -> 541 | X24: 2363 | Y24: =X24-X23 -> 0 | Z24: 132877.7 | AA24: =Z24-Z23 -> 0 | AB24: =SUM(Y24*$AB$2) -> 0 | AC24: 1801 | AD24: =AC24-AC23 -> 0 | AE24: 357717.4 | AF24: =AE24-AE23 -> 0 | AG24: =IF(AD24>0,AF24/AD24,0) -> 0 | AH24: =AF24+AA24 -> 0 | AI24: =SUM(AH24+V24) -> 541 | AJ24: =-tanks!AW25 -> 541 | AK24: =SUM(AJ24-AI24) -> 0 | AL24: =S24+L24+G24 -> 7 | AM24: =Y24+AD24 -> 0 | AN24: 79 | AO24: =(AN24/100)*3000 -> 2370 | AP24: 79 | AQ24: =(AP24/100)*3000 -> 2370 | AR24: 81 | AS24: =(AR24/100)*3000 -> 2430 | AT24: =SUM(AO24+AQ24+AS24) -> 7170 | AU24: =AT23-AT24+AV24 -> 410 | AV24: 1400 | AW24: 0.7 | AX24: =IF(AV24>0,AW24,AX23) -> 0.7
A25: =ELEC!C23 -> 43882 | B25: 237 | C25: 241 | D25: =C24-C25 -> 5.5 | E25: =D25*8.38 -> 46.09 | F25: 1422 | G25: =F25-F24 -> 4 | H25: 339923 | I25: =SUM(H25-H24) -> 315 | J25: =IF(G25>0,I25/G25,0) -> 78.75 | K25: =K24 -> 1809 | L25: =K25-K24 -> 0 | M25: =M24 -> 132120 | N25: =M25-M24 -> 0 | O25: =SUM(L25*$J$1) -> 0 | P25: 1662 | Q25: 142265 | R25: =Q25-Q24 -> 254 | S25: =SUM(P25-P24) -> 3 | T25: =SUM(S25*$T$2) -> 0 | U25: =SUM(G25+L25+S25) -> 7 | V25: =R25+N25+I25:I25 -> 569 | X25: 2372 | Y25: =X25-X24 -> 9 | Z25: 133353 | AA25: =Z25-Z24 -> 475.3 | AB25: =SUM(Y25*$AB$2) -> 0 | AC25: =AC24 -> 1801 | AD25: =AC25-AC24 -> 0 | AE25: =AE24 -> 357717.4 | AF25: =AE25-AE24 -> 0 | AG25: =IF(AD25>0,AF25/AD25,0) -> 0 | AH25: =AF25+AA25 -> 475.3 | AI25: =SUM(AH25+V25) -> 1044.3 | AJ25: =-tanks!AW26 -> 1044.3 | AK25: =SUM(AJ25-AI25) -> 0 | AL25: =S25+L25+G25 -> 7 | AM25: =Y25+AD25 -> 9 | AN25: =AN24 -> 79 | AO25: =(AN25/100)*3000 -> 2370 | AP25: =AP24 -> 79 | AQ25: =(AP25/100)*3000 -> 2370 | AR25: 80 | AS25: =(AR25/100)*3000 -> 2400 | AT25: =SUM(AO25+AQ25+AS25) -> 7140 | AU25: =AT24-AT25+AV25 -> 30 | AX25: =IF(AV25>0,AW25,AX24) -> 0.7
A26: =ELEC!C24 -> 43883 | B26: 229 | C26: 234.3 | D26: =C25-C26 -> 6.7 | E26: =D26*8.38 -> 56.146 | F26: 1426 | G26: =F26-F25 -> 4 | H26: 340262 | I26: =SUM(H26-H25) -> 339 | J26: =IF(G26>0,I26/G26,0) -> 84.75 | K26: 1814 | L26: =K26-K25 -> 5 | M26: 132475 | N26: =M26-M25 -> 355 | O26: =SUM(L26*$J$1) -> 383.19271 | P26: 1662 | Q26: 142270 | R26: =Q26-Q25 -> 5 | S26: =SUM(P26-P25) -> 0 | T26: =SUM(S26*$T$2) -> 0 | U26: =SUM(G26+L26+S26) -> 9 | V26: =R26+N26+I26:I26 -> 699 | X26: 2374 | Y26: =X26-X25 -> 2 | Z26: 133402 | AA26: =Z26-Z25 -> 49 | AB26: =SUM(Y26*$AB$2) -> 0 | AC26: =AC25 -> 1801 | AD26: =AC26-AC25 -> 0 | AE26: =AE25 -> 357717.4 | AF26: =AE26-AE25 -> 0 | AG26: =IF(AD26>0,AF26/AD26,0) -> 0 | AH26: =AF26+AA26 -> 49 | AI26: =SUM(AH26+V26) -> 748 | AJ26: =-tanks!AW27 -> 748 | AK26: =SUM(AJ26-AI26) -> 0 | AL26: =S26+L26+G26 -> 9 | AM26: =Y26+AD26 -> 2 | AN26: 77 | AO26: =(AN26/100)*3000 -> 2310 | AP26: 78 | AQ26: =(AP26/100)*3000 -> 2340 | AR26: 79 | AS26: =(AR26/100)*3000 -> 2370 | AT26: =SUM(AO26+AQ26+AS26) -> 7020 | AU26: =AT25-AT26+AV26 -> 120 | AX26: =IF(AV26>0,AW26,AX25) -> 0.7
