Workbook

Sheet TOTAL
A1: Site Name | B1: Day | C1: Month | D1: Year | E1: Total Electricity Kwh | F1: Electricity Tariff ($/Kwh) | G1: Natual Gas (m3) | H1: Natural Gas $/m3 | I1: Water Utility Supply (m3) m3 | J1: Water Utility Supply (m3) $/m3 | K1: Room Nights
A2: Cairo at Nile Plaza | B2: 1 | C2: 9 | D2: 2019 | E2: =( (Submetering!O2+Submetering!P2)*0.842284+Submetering!Q2+Submetering!M2+Submetering!N2)*1.02 -> 74529.43 | F2: 1.27 | G2: =Gas!C4 -> 2148 | H2: 3.65 | I2: =Submetering!F2+Submetering!G2 -> 1066.5 | J2: 10.03 | K2: =ELECT.!B4 -> 245
A3: Cairo at Nile Plaza | B3: =B2+1 -> 2 | C3: 9 | D3: 2019 | E3: =( (Submetering!O3+Submetering!P3)*0.842284+Submetering!Q3+Submetering!M3+Submetering!N3)*1.02 -> 50833.018 | F3: 1.27 | G3: =Gas!C5 -> 2960 | H3: 3.65 | I3: =Submetering!F3+Submetering!G3 -> 1044.9 | J3: 10.03 | K3: =ELECT.!B5 -> 240
A4: Cairo at Nile Plaza | B4: =B3+1 -> 3 | C4: 9 | D4: 2019 | E4: =( (Submetering!O4+Submetering!P4)*0.842284+Submetering!Q4+Submetering!M4+Submetering!N4)*1.02 -> 51678.678 | F4: 1.27 | G4: =Gas!C6 -> 2445 | H4: 3.65 | I4: =Submetering!F4+Submetering!G4 -> 1112.4 | J4: 10.03 | K4: =ELECT.!B6 -> 248
A5: Cairo at Nile Plaza | B5: =B4+1 -> 4 | C5: 9 | D5: 2019 | E5: =( (Submetering!O5+Submetering!P5)*0.842284+Submetering!Q5+Submetering!M5+Submetering!N5)*1.02 -> 64737.28 | F5: 1.27 | G5: =Gas!C7 -> 2101 | H5: 3.65 | I5: =Submetering!F5+Submetering!G5 -> 1139.4 | J5: 10.03 | K5: =ELECT.!B7 -> 242
A6: Cairo at Nile Plaza | B6: =B5+1 -> 5 | C6: 9 | D6: 2019 | E6: =( (Submetering!O6+Submetering!P6)*0.842284+Submetering!Q6+Submetering!M6+Submetering!N6)*1.02 -> 59716.359 | F6: 1.27 | G6: =Gas!C8 -> 4082 | H6: 3.65 | I6: =Submetering!F6+Submetering!G6 -> 1174.5 | J6: 10.03 | K6: =ELECT.!B8 -> 293
A7: Cairo at Nile Plaza | B7: =B6+1 -> 6 | C7: 9 | D7: 2019 | E7: =( (Submetering!O7+Submetering!P7)*0.842284+Submetering!Q7+Submetering!M7+Submetering!N7)*1.02 -> 65178.302 | F7: 1.27 | G7: =Gas!C9 -> 3955 | H7: 3.65 | I7: =Submetering!F7+Submetering!G7 -> 1026 | J7: 10.03 | K7: =ELECT.!B9 -> 277
A8: Cairo at Nile Plaza | B8: =B7+1 -> 7 | C8: 9 | D8: 2019 | E8: =( (Submetering!O8+Submetering!P8)*0.842284+Submetering!Q8+Submetering!M8+Submetering!N8)*1.02 -> 46624.216 | F8: 1.27 | G8: =Gas!C10 -> 2328 | H8: 3.65 | I8: =Submetering!F8+Submetering!G8 -> 1107 | J8: 10.03 | K8: =ELECT.!B10 -> 292
A9: Cairo at Nile Plaza | B9: =B8+1 -> 8 | C9: 9 | D9: 2019 | E9: =( (Submetering!O9+Submetering!P9)*0.842284+Submetering!Q9+Submetering!M9+Submetering!N9)*1.02 -> 74898.543 | F9: 1.27 | G9: =Gas!C11 -> 3602 | H9: 3.65 | I9: =Submetering!F9+Submetering!G9 -> 1107 | J9: 10.03 | K9: =ELECT.!B11 -> 269
A10: Cairo at Nile Plaza | B10: =B9+1 -> 9 | C10: 9 | D10: 2019 | E10: =( (Submetering!O10+Submetering!P10)*0.842284+Submetering!Q10+Submetering!M10+Submetering!N10)*1.02 -> 60041.209 | F10: 1.27 | G10: =Gas!C12 -> 3588 | H10: 3.65 | I10: =Submetering!F10+Submetering!G10 -> 950.4 | J10: 10.03 | K10: =ELECT.!B12 -> 280
A11: Cairo at Nile Plaza | B11: =B10+1 -> 10 | C11: 9 | D11: 2019 | E11: =( (Submetering!O11+Submetering!P11)*0.842284+Submetering!Q11+Submetering!M11+Submetering!N11)*1.02 -> 64055.235 | F11: 1.27 | G11: =Gas!C13 -> 2965 | H11: 3.65 | I11: =Submetering!F11+Submetering!G11 -> 1161 | J11: 10.03 | K11: =ELECT.!B13 -> 297
A12: Cairo at Nile Plaza | B12: =B11+1 -> 11 | C12: 9 | D12: 2019 | E12: =( (Submetering!O12+Submetering!P12)*0.842284+Submetering!Q12+Submetering!M12+Submetering!N12)*1.02 -> 45571.374 | F12: 1.27 | G12: =Gas!C14 -> 2819 | H12: 3.65 | I12: =Submetering!F12+Submetering!G12 -> 882.9 | J12: 10.03 | K12: =ELECT.!B14 -> 294
A13: Cairo at Nile Plaza | B13: =B12+1 -> 12 | C13: 9 | D13: 2019 | E13: =( (Submetering!O13+Submetering!P13)*0.842284+Submetering!Q13+Submetering!M13+Submetering!N13)*1.02 -> 78555.436 | F13: 1.27 | G13: =Gas!C15 -> 3611 | H13: 3.65 | I13: =Submetering!F13+Submetering!G13 -> 1182.6 | J13: 10.03 | K13: =ELECT.!B15 -> 304
A14: Cairo at Nile Plaza | B14: =B13+1 -> 13 | C14: 9 | D14: 2019 | E14: =( (Submetering!O14+Submetering!P14)*0.842284+Submetering!Q14+Submetering!M14+Submetering!N14)*1.02 -> 56312.294 | F14: 1.27 | G14: =Gas!C16 -> 2887 | H14: 3.65 | I14: =Submetering!F14+Submetering!G14 -> 831.6 | J14: 10.03 | K14: =ELECT.!B16 -> 323
... A31: Cairo at Nile Plaza | B31: =B30+1 -> 30 | C31: 9 | D31: 2019 | E31: =( (Submetering!O31+Submetering!P31)*0.842284+Submetering!Q31+Submetering!M31+Submetering!N31)*1.02 -> 63296.272 | F31: 1.27 | G31: =Gas!C33 -> 3144 | H31: 3.65 | I31: =Submetering!F31+Submetering!G31 -> 926.1 | J31: 10.03 | K31: =ELECT.!B33 -> 248

Sheet Submetering
A1: Site Name | B1: Day | C1: Month | D1: Year | E1: Main (m3) | F1: Podium (m3) | G1: Hotel (m3) | H1: Large (m3) | I1: Feeder 1 (KWh) | J1: Feeder 2 (KWh) | K1: T1 (KWh) | L1: T2 (KWh) | M1: T3 (KWh) | N1: T4 (KWh) | O1: T5 (KWh) | P1: T7 (KWh) | Q1: New Chiller (KWh) | R1: Hotel (BTU) | S1: B.S (BTU) | T1: LS (BTU) | U1: Mall (BTU) | V1: AHU#25 (BTU) | W1: AHU#9 (BTU) | X1: Room Nights
A2: Cairo at Nile Plaza | B2: 1 | C2: 9 | D2: 2019 | E2: =Water!C4 -> 1030 | F2: =Water!E4 -> 553.5 | G2: =Water!G4 -> 513 | H2: =Water!I4 -> 5.67 | I2: =ELECT.!F4 -> 24204 | J2: =ELECT.!H4 -> 58792 | K2: =ELECT.!K4 -> 6542 | L2: =ELECT.!M4 -> 8131 | M2: =ELECT.!O4 -> 27668 | N2: =ELECT.!Q4 -> 14004 | O2: =ELECT.!S4 -> 11489 | P2: =ELECT.!W4*2 -> 25406 | Q2: =ELECT.!D4 -> 320 | R2: =BTU!C3 -> 14.1516 | S2: =BTU!F3 -> 0.89733333 | T2: =BTU!I3 -> 0 | U2: =BTU!O3 -> 1.155 | V2: =BTU!L3 -> 0.1 | W2: =BTU!R3 -> 2.84 | X2: =ELECT.!B4 -> 245
A3: Cairo at Nile Plaza | B3: =B2+1 -> 2 | C3: 9 | D3: 2019 | E3: =Water!C5 -> 1060 | F3: =Water!E5 -> 534.6 | G3: =Water!G5 -> 510.3 | H3: =Water!I5 -> 5.67 | I3: =ELECT.!F5 -> 24350 | J3: =ELECT.!H5 -> 56902 | K3: =ELECT.!K5 -> 6210 | L3: =ELECT.!M5 -> 8586 | M3: =ELECT.!O5 -> 3572 | N3: =ELECT.!Q5 -> 13382 | O3: =ELECT.!S5 -> 11348 | P3: =ELECT.!W5*2 -> 25032 | Q3: =ELECT.!D5 -> 2240 | R3: =BTU!C4 -> 14.336 | S3: =BTU!F4 -> 0.395 | T3: =BTU!I4 -> 10 | U3: =BTU!O4 -> 2.745 | V3: =BTU!L4 -> 0.54 | W3: =BTU!R4 -> 5.8 | X3: =ELECT.!B5 -> 240
A4: Cairo at Nile Plaza | B4: =B3+1 -> 3 | C4: 9 | D4: 2019 | E4: =Water!C6 -> 1140 | F4: =Water!E6 -> 567 | G4: =Water!G6 -> 545.4 | H4: =Water!I6 -> 5.616 | I4: =ELECT.!F6 -> 17111 | J4: =ELECT.!H6 -> 49775 | K4: =ELECT.!K6 -> 5335 | L4: =ELECT.!M6 -> 5797 | M4: =ELECT.!O6 -> 11132 | N4: =ELECT.!Q6 -> 11371 | O4: =ELECT.!S6 -> 10030 | P4: =ELECT.!W6*2 -> 22076 | Q4: =ELECT.!D6 -> 1120 | R4: =BTU!C5 -> 32.181 | S4: =BTU!F5 -> 5.032 | T4: =BTU!I5 -> 5 | U4: =BTU!O5 -> 6.556 | V4: =BTU!L5 -> 1.59 | W4: =BTU!R5 -> 4 | X4: =ELECT.!B6 -> 248
A5: Cairo at Nile Plaza | B5: =B4+1 -> 4 | C5: 9 | D5: 2019 | E5: =Water!C7 -> 1160 | F5: =Water!E7 -> 577.8 | G5: =Water!G7 -> 561.6 | H5: =Water!I7 -> 5.373 | I5: =ELECT.!F7 -> 19396 | J5: =ELECT.!H7 -> 63636 | K5: =ELECT.!K7 -> 7284 | L5: =ELECT.!M7 -> 6399 | M5: =ELECT.!O7 -> 12790 | N5: =ELECT.!Q7 -> 14534 | O5: =ELECT.!S7 -> 13570 | P5: =ELECT.!W7*2 -> 28392 | Q5: =ELECT.!D7 -> 800 | R5: =BTU!C6 -> 14.98 | S5: =BTU!F6 -> 3.395 | T5: =BTU!I6 -> 0 | U5: =BTU!O6 -> 3.528 | V5: =BTU!L6 -> 0.76 | W5: =BTU!R6 -> 1.03 | X5: =ELECT.!B7 -> 242
A6: Cairo at Nile Plaza | B6: =B5+1 -> 5 | C6: 9 | D6: 2019 | E6: =Water!C8 -> 1210 | F6: =Water!E8 -> 591.3 | G6: =Water!G8 -> 583.2 | H6: =Water!I8 -> 6.642 | I6: =ELECT.!F8 -> 17320 | J6: =ELECT.!H8 -> 60375 | K6: =ELECT.!K8 -> 5897 | L6: =ELECT.!M8 -> 5604 | M6: =ELECT.!O8 -> 11526 | N6: =ELECT.!Q8 -> 13768 | O6: =ELECT.!S8 -> 11636 | P6: =ELECT.!W8*2 -> 26512 | Q6: =ELECT.!D8 -> 1120 | R6: =BTU!C7 -> 15.956 | S6: =BTU!F7 -> 3.309 | T6: =BTU!I7 -> 0 | U6: =BTU!O7 -> 3.23 | V6: =BTU!L7 -> 0.76 | W6: =BTU!R7 -> 0.97 | X6: =ELECT.!B8 -> 293
A7: Cairo at Nile Plaza | B7: =B6+1 -> 6 | C7: 9 | D7: 2019 | E7: =Water!C9 -> 1040 | F7: =Water!E9 -> 496.8 | G7: =Water!G9 -> 529.2 | H7: =Water!I9 -> 5.886 | I7: =ELECT.!F9 -> 18903 | J7: =ELECT.!H9 -> 64590 | K7: =ELECT.!K9 -> 6253 | L7: =ELECT.!M9 -> 5884 | M7: =ELECT.!O9 -> 12754 | N7: =ELECT.!Q9 -> 15469 | O7: =ELECT.!S9 -> 13040 | P7: =ELECT.!W9*2 -> 28368 | Q7: =ELECT.!D9 -> 800 | R7: =BTU!C8 -> 18.997 | S7: =BTU!F8 -> 2.07 | T7: =BTU!I8 -> 0 | U7: =BTU!O8 -> 3.484 | V7: =BTU!L8 -> 0.88 | W7: =BTU!R8 -> 5.09 | X7: =ELECT.!B9 -> 277
A8: Cairo at Nile Plaza | B8: =B7+1 -> 7 | C8: 9 | D8: 2019 | E8: =Water!C10 -> 1150 | F8: =Water!E10 -> 567 | G8: =Water!G10 -> 540 | H8: =Water!I10 -> 7.695 | I8: =ELECT.!F10 -> 15862 | J8: =ELECT.!H10 -> 43690 | K8: =ELECT.!K10 -> 4567 | L8: =ELECT.!M10 -> 5152 | M8: =ELECT.!O10 -> 10598 | N8: =ELECT.!Q10 -> 10355 | O8: =ELECT.!S10 -> 8817 | P8: =ELECT.!W10*2 -> 19246 | Q8: =ELECT.!D10 -> 1120 | R8: =BTU!C9 -> 15.052 | S8: =BTU!F9 -> 1.892 | T8: =BTU!I9 -> 0 | U8: =BTU!O9 -> 3.47 | V8: =BTU!L9 -> 0.71 | W8: =BTU!R9 -> 1.11 | X8: =ELECT.!B10 -> 292
A9: Cairo at Nile Plaza | B9: =B8+1 -> 8 | C9: 9 | D9: 2019 | E9: =Water!C11 -> 1160 | F9: =Water!E11 -> 604.8 | G9: =Water!G11 -> 502.2 | H9: =Water!I11 -> 7.182 | I9: =ELECT.!F11 -> 22997 | J9: =ELECT.!H11 -> 74394 | K9: =ELECT.!K11 -> 7808 | L9: =ELECT.!M11 -> 8163 | M9: =ELECT.!O11 -> 14642 | N9: =ELECT.!Q11 -> 17096 | O9: =ELECT.!S11 -> 14627 | P9: =ELECT.!W11*2 -> 33352 | Q9: =ELECT.!D11 -> 1280 | R9: =BTU!C10 -> 15.084 | S9: =BTU!F10 -> 3.886 | T9: =BTU!I10 -> 0 | U9: =BTU!O10 -> 3.339 | V9: =BTU!L10 -> 0.75 | W9: =BTU!R10 -> 0.8 | X9: =ELECT.!B11 -> 269
A10: Cairo at Nile Plaza | B10: =B9+1 -> 9 | C10: 9 | D10: 2019 | E10: =Water!C12 -> 990 | F10: =Water!E12 -> 507.6 | G10: =Water!G12 -> 442.8 | H10: =Water!I12 -> 5.697 | I10: =ELECT.!F12 -> 19492 | J10: =ELECT.!H12 -> 58354 | K10: =ELECT.!K12 -> 6029 | L10: =ELECT.!M12 -> 6787 | M10: =ELECT.!O12 -> 12464 | N10: =ELECT.!Q12 -> 12959 | O10: =ELECT.!S12 -> 11211 | P10: =ELECT.!W12*2 -> 26972 | Q10: =ELECT.!D12 -> 1280 | R10: =BTU!C11 -> 14.28 | S10: =BTU!F11 -> 3.748 | T10: =BTU!I11 -> 0 | U10: =BTU!O11 -> 3.252 | V10: =BTU!L11 -> 0.71 | W10: =BTU!R11 -> 3 | X10: =ELECT.!B12 -> 280
A11: Cairo at Nile Plaza | B11: =B10+1 -> 10 | C11: 9 | D11: 2019 | E11: =Water!C13 -> 1210 | F11: =Water!E13 -> 631.8 | G11: =Water!G13 -> 529.2 | H11: =Water!I13 -> 5.535 | I11: =ELECT.!F13 -> 18385 | J11: =ELECT.!H13 -> 64587 | K11: =ELECT.!K13 -> 6782 | L11: =ELECT.!M13 -> 6021 | M11: =ELECT.!O13 -> 12132 | N11: =ELECT.!Q13 -> 14301 | O11: =ELECT.!S13 -> 12538 | P11: =ELECT.!W13*2 -> 29498 | Q11: =ELECT.!D13 -> 960 | R11: =BTU!C12 -> 14.4 | S11: =BTU!F12 -> 3.6 | T11: =BTU!I12 -> 0 | U11: =BTU!O12 -> 3.5 | V11: =BTU!L12 -> 0.8 | W11: =BTU!R12 -> 2.7 | X11: =ELECT.!B13 -> 297
A12: Cairo at Nile Plaza | B12: =B11+1 -> 11 | C12: 9 | D12: 2019 | E12: =Water!C14 -> 910 | F12: =Water!E14 -> 467.1 | G12: =Water!G14 -> 415.8 | H12: =Water!I14 -> 4.428 | I12: =ELECT.!F14 -> 15387 | J12: =ELECT.!H14 -> 45138 | K12: =ELECT.!K14 -> 4767 | L12: =ELECT.!M14 -> 4604 | M12: =ELECT.!O14 -> 8478 | N12: =ELECT.!Q14 -> 9984 | O12: =ELECT.!S14 -> 8761 | P12: =ELECT.!W14*2 -> 20844 | Q12: =ELECT.!D14 -> 1280 | R12: =BTU!C13 -> 14.26 | S12: =BTU!F13 -> 3.437 | T12: =BTU!I13 -> 0 | U12: =BTU!O13 -> 3.07 | V12: =BTU!L13 -> 0.66 | W12: =BTU!R13 -> 1.2 | X12: =ELECT.!B14 -> 294
A13: Cairo at Nile Plaza | B13: =B12+1 -> 12 | C13: 9 | D13: 2019 | E13: =Water!C15 -> 1190 | F13: =Water!E15 -> 612.9 | G13: =Water!G15 -> 569.7 | H13: =Water!I15 -> 4.671 | I13: =ELECT.!F15 -> 21070 | J13: =ELECT.!H15 -> 78985 | K13: =ELECT.!K15 -> 8151 | L13: =ELECT.!M15 -> 8219 | M13: =ELECT.!O15 -> 14762 | N13: =ELECT.!Q15 -> 17438 | O13: =ELECT.!S15 -> 15329 | P13: =ELECT.!W15*2 -> 36358 | Q13: =ELECT.!D15 -> 1280 | R13: =BTU!C14 -> 13.991 | S13: =BTU!F14 -> 3.384 | T13: =BTU!I14 -> 0 | U13: =BTU!O14 -> 2.632 | V13: =BTU!L14 -> 0.67 | W13: =BTU!R14 -> 1.26 | X13: =ELECT.!B15 -> 304
A14: Cairo at Nile Plaza | B14: =B13+1 -> 13 | C14: 9 | D14: 2019 | E14: =Water!C16 -> 1000 | F14: =Water!E16 -> 359.1 | G14: =Water!G16 -> 472.5 | H14: =Water!I16 -> 3.726 | I14: =ELECT.!F16 -> 16140 | J14: =ELECT.!H16 -> 55456 | K14: =ELECT.!K16 -> 5492 | L14: =ELECT.!M16 -> 5409 | M14: =ELECT.!O16 -> 10594 | N14: =ELECT.!Q16 -> 12296 | O14: =ELECT.!S16 -> 11230 | P14: =ELECT.!W16*2 -> 25430 | Q14: =ELECT.!D16 -> 1440 | R14: =BTU!C15 -> 15.215 | S14: =BTU!F15 -> 2.405 | T14: =BTU!I15 -> 0 | U14: =BTU!O15 -> 3.168 | V14: =BTU!L15 -> 0.77 | W14: =BTU!R15 -> 5.62 | X14: =ELECT.!B16 -> 323
... A31: Cairo at Nile Plaza | B31: =B30+1 -> 30 | C31: 9 | D31: 2019 | E31: =Water!C33 -> 980 | F31: =Water!E33 -> 499.5 | G31: =Water!G33 -> 426.6 | H31: =Water!I33 -> 5.805 | I31: =ELECT.!F33 -> 17179 | J31: =ELECT.!H33 -> 64613 | K31: =ELECT.!K33 -> 6797 | L31: =ELECT.!M33 -> 6359 | M31: =ELECT.!O33 -> 11648 | N31: =ELECT.!Q33 -> 13666 | O31: =ELECT.!S33 -> 13241 | P31: =ELECT.!W33*2 -> 29810 | Q31: =ELECT.!D33 -> 480 | R31: =BTU!C32 -> 10.775 | S31: =BTU!F32 -> 2.689 | T31: =BTU!I32 -> 0 | U31: =BTU!O32 -> 2.539 | V31: =BTU!L32 -> 0.43 | W31: =BTU!R32 -> 2.08 | X31: =ELECT.!B33 -> 248
A32: Cairo at Nile Plaza | E32: =Water!C34 -> 0 | F32: =Water!E34 -> 0 | G32: =Water!G34 -> 0 | H32: =Water!I34 -> 0 | I32: =ELECT.!F34 -> 0 | J32: =ELECT.!H34 -> 0 | K32: =ELECT.!K34 -> 0 | L32: =ELECT.!M34 -> 0 | M32: =ELECT.!O34 -> 0 | N32: =ELECT.!Q34 -> 0 | O32: =ELECT.!S34 -> 0 | P32: =ELECT.!W34*2 -> 0 | Q32: =ELECT.!D34 -> 0 | R32: =BTU!C33 -> 0 | S32: =BTU!F33 -> 0 | T32: =BTU!I33 -> 0 | U32: =BTU!O33 -> 0 | V32: =BTU!L33 -> 0 | W32: =BTU!R33 -> 0 | X32: =ELECT.!B34 -> 0

Sheet Mall, Citadel, Rotana
A1: Mall, Citadel and Rotana readings and cons. Sep. 2019
A2: Day | B2: R1 | C2: Cons | D2: R2 | E2: Cons | F2: R3 | G2: Cons | H2: R4 | I2: Cons | J2: RO1 | K2: Cons | L2: RO2 | M2: Cons | N2: ROE | O2: Cons | P2: CIB. 1 | Q2: Cons | R2: CIB. E | S2: Cons
A3: Last | B3: 42547 | C3: 360 | D3: 37843 | E3: 320 | F3: 18177 | G3: 80 | H3: 219364 | I3: 4 | J3: 303517 | K3: 0 | L3: 22637 | M3: 320 | N3: 168532 | O3: 2 | P3: 9997 | Q3: 24 | R3: 55047
A4: 43709 | B4: 42549 | C4: =(B4-B3)*600/5 -> 240 | D4: 37845 | E4: =(D4-D3)*800/5 -> 320 | F4: 18180 | G4: =(F4-F3)*100/5 -> 60 | H4: 219366 | I4: =H4-H3 -> 2 | J4: 303517 | K4: =J4-J3 -> 0 | L4: 22639 | M4: =(L4-L3)*800/5 -> 320 | N4: 168534 | O4: =N4-N3 -> 2 | P4: 9999 | Q4: =P4-P3 -> 2 | R4: 55047 | S4: =R4-R3 -> 0
A5: 43710 | B5: 42561 | C5: =(B5-B4)*600/5 -> 1440 | D5: 37850 | E5: =(D5-D4)*800/5 -> 800 | F5: 18185 | G5: =(F5-F4)*100/5 -> 100 | H5: 219367 | I5: =H5-H4 -> 1 | J5: 303517 | K5: =J5-J4 -> 0 | L5: 22647 | M5: =(L5-L4)*800/5 -> 1280 | N5: 168540 | O5: =N5-N4 -> 6 | P5: 10818 | Q5: =P5-P4 -> 819 | R5: 55047 | S5: =R5-R4 -> 0
A6: 43711 | B6: 42567 | C6: =(B6-B5)*600/5 -> 720 | D6: 37854 | E6: =(D6-D5)*800/5 -> 640 | F6: 18189 | G6: =(F6-F5)*100/5 -> 80 | H6: 219401 | I6: =H6-H5 -> 34 | J6: 303517 | K6: =J6-J5 -> 0 | L6: 22652 | M6: =(L6-L5)*800/5 -> 800 | N6: 168543 | O6: =N6-N5 -> 3 | P6: 11023 | Q6: =P6-P5 -> 205 | R6: 55047 | S6: =R6-R5 -> 0
A7: 43712 | B7: 42572 | C7: =(B7-B6)*600/5 -> 600 | D7: 37857 | E7: =(D7-D6)*800/5 -> 480 | F7: 18193 | G7: =(F7-F6)*100/5 -> 80 | H7: 219429 | I7: =H7-H6 -> 28 | J7: 303517 | K7: =J7-J6 -> 0 | L7: 22655 | M7: =(L7-L6)*800/5 -> 480 | N7: 168546 | O7: =N7-N6 -> 3 | P7: 11199 | Q7: =P7-P6 -> 176 | R7: 55047 | S7: =R7-R6 -> 0
A8: 43713 | B8: 42578 | C8: =(B8-B7)*600/5 -> 720 | D8: 37860 | E8: =(D8-D7)*800/5 -> 480 | F8: 18197 | G8: =(F8-F7)*100/5 -> 80 | H8: 219461 | I8: =H8-H7 -> 32 | J8: 303517 | K8: =J8-J7 -> 0 | L8: 22659 | M8: =(L8-L7)*800/5 -> 640 | N8: 168549 | O8: =N8-N7 -> 3 | P8: 11378 | Q8: =P8-P7 -> 179 | R8: 55047 | S8: =R8-R7 -> 0
A9: 43714 | B9: 42583 | C9: =(B9-B8)*600/5 -> 600 | D9: 37865 | E9: =(D9-D8)*800/5 -> 800 | F9: 18200 | G9: =(F9-F8)*100/5 -> 60 | H9: 219489 | I9: =H9-H8 -> 28 | J9: 303517 | K9: =J9-J8 -> 0 | L9: 22661 | M9: =(L9-L8)*800/5 -> 320 | N9: 168552 | O9: =N9-N8 -> 3 | P9: 11482 | Q9: =P9-P8 -> 104 | R9: 55047 | S9: =R9-R8 -> 0
A10: 43715 | B10: 42589 | C10: =(B10-B9)*600/5 -> 720 | D10: 37867 | E10: =(D10-D9)*800/5 -> 320 | F10: 18204 | G10: =(F10-F9)*100/5 -> 80 | H10: 219523 | I10: =H10-H9 -> 34 | J10: 303517 | K10: =J10-J9 -> 0 | L10: 22665 | M10: =(L10-L9)*800/5 -> 640 | N10: 168555 | O10: =N10-N9 -> 3 | P10: 11646 | Q10: =P10-P9 -> 164 | R10: 55047 | S10: =R10-R9 -> 0
A11: 43716 | B11: 42595 | C11: =(B11-B10)*600/5 -> 720 | D11: 37870 | E11: =(D11-D10)*800/5 -> 480 | F11: 18209 | G11: =(F11-F10)*100/5 -> 100 | H11: 219594 | I11: =H11-H10 -> 71 | J11: 303517 | K11: =J11-J10 -> 0 | L11: 22669 | M11: =(L11-L10)*800/5 -> 640 | N11: 168559 | O11: =N11-N10 -> 4 | P11: 11684 | Q11: =P11-P10 -> 38 | R11: 55047 | S11: =R11-R10 -> 0
A12: 43717 | B12: 42601 | C12: =(B12-B11)*600/5 -> 720 | D12: 37874 | E12: =(D12-D11)*800/5 -> 640 | F12: 18213 | G12: =(F12-F11)*100/5 -> 80 | H12: 219617 | I12: =H12-H11 -> 23 | J12: 303517 | K12: =J12-J11 -> 0 | L12: 22674 | M12: =(L12-L11)*800/5 -> 800 | N12: 168562 | O12: =N12-N11 -> 3 | P12: 11692 | Q12: =P12-P11 -> 8 | R12: 55047 | S12: =R12-R11 -> 0
A13: 43718 | B13: 42607 | C13: =(B13-B12)*600/5 -> 720 | D13: 37877 | E13: =(D13-D12)*800/5 -> 480 | F13: 18218 | G13: =(F13-F12)*100/5 -> 100 | H13: 219651 | I13: =H13-H12 -> 34 | J13: 303517 | K13: =J13-J12 -> 0 | L13: 22678 | M13: =(L13-L12)*800/5 -> 640 | N13: 168565 | O13: =N13-N12 -> 3 | P13: 11720 | Q13: =P13-P12 -> 28 | R13: 55047 | S13: =R13-R12 -> 0
A14: 43719 | B14: 42613 | C14: =(B14-B13)*600/5 -> 720 | D14: 37881 | E14: =(D14-D13)*800/5 -> 640 | F14: 18221 | G14: =(F14-F13)*100/5 -> 60 | H14: 219687 | I14: =H14-H13 -> 36 | J14: 303517 | K14: =J14-J13 -> 0 | L14: 22682 | M14: =(L14-L13)*800/5 -> 640 | N14: 168569 | O14: =N14-N13 -> 4 | P14: 12349 | Q14: =P14-P13 -> 629 | R14: 55047 | S14: =R14-R13 -> 0
A15: 43720 | B15: 42619 | C15: =(B15-B14)*600/5 -> 720 | D15: 37884 | E15: =(D15-D14)*800/5 -> 480 | F15: 18227 | G15: =(F15-F14)*100/5 -> 120 | H15: 219713 | I15: =H15-H14 -> 26 | J15: 303517 | K15: =J15-J14 -> 0 | L15: 22686 | M15: =(L15-L14)*800/5 -> 640 | N15: 168572 | O15: =N15-N14 -> 3 | P15: 12444 | Q15: =P15-P14 -> 95 | R15: 55047 | S15: =R15-R14 -> 0
... A33: 43738 | B33: 42722 | C33: =(B33-B32)*600/5 -> 1560 | D33: 37947 | E33: =(D33-D32)*800/5 -> 1120 | F33: 18295 | G33: =(F33-F32)*100/5 -> 40 | H33: 220261 | I33: =H33-H32 -> 4 | J33: 303517 | K33: =J33-J32 -> 0 | L33: 22756 | M33: =(L33-L32)*800/5 -> 1120 | N33: 168629 | O33: =N33-N32 -> 8 | P33: 14998 | Q33: =P33-P32 -> 104 | R33: 55047 | S33: =R33-R32 -> 0
B34: 42722 | C34: =(B34-B32)*600/5 -> 1560 | D34: 37947 | E34: =(D34-D32)*800/5 -> 1120 | F34: 18295 | G34: =(F34-F32)*100/5 -> 40 | H34: 220261 | I34: =H34-H32 -> 4 | J34: 303517 | K34: =J34-J32 -> 0 | L34: 22756 | M34: =(L34-L32)*800/5 -> 1120 | N34: 168629 | O34: =N34-N32 -> 8 | P34: 14998 | Q34: =P34-P32 -> 104 | R34: 55047 | S34: =R34-R32 -> 0
A35: Total | C35: =SUM(C4:C34) -> 22560 | E35: =SUM(E4:E34) -> 17760 | G35: =SUM(G4:G34) -> 2400 | I35: =SUM(I4:I34) -> 901 | K35: =SUM(K4:K34) -> 0 | M35: =SUM(M4:M34) -> 20160 | Q35: =SUM(Q4:Q34) -> 5105 | S35: =SUM(S4:S34) -> 0

Sheet Water
A1: Main Building, Podium, Hotel and Large cons. Sep. 2019
A2: Day | B2: Main Reading | C2: Cons. | D2: Podium | E2: Cons. | F2: Hotel | G2: Cons. | H2: Large | I2: Cons. | J2: Total | K2: cost.LE
A3: Last | B3: 365069 | C3: 1120 | D3: 96358800 | E3: 534.6 | F3: 95833300 | G3: 475.2 | H3: 628900 | I3: 5.103 | J3: 2134.903 | K3: 12510.532
A4: 43709 | B4: 365172 | C4: =(IF((B4-B3)<0,"0",(B4-B3)))*10 -> 1030 | D4: 96379300 | E4: =(IF((D4-D3)<0,"0",(D4-D3)))*0.027 -> 553.5 | F4: 95852300 | G4: =(IF((F4-F3)<0,"0",(F4-F3)))*0.027 -> 513 | H4: 629110 | I4: =(IF((H4-H3)<0,"0",(H4-H3)))*0.027 -> 5.67 | J4: =C4+E4+G4+I4 -> 2102.17 | K4: =J4*5.86 -> 12318.716
A5: 43710 | B5: 365278 | C5: =(IF((B5-B4)<0,"0",(B5-B4)))*10 -> 1060 | D5: 96399100 | E5: =(IF((D5-D4)<0,"0",(D5-D4)))*0.027 -> 534.6 | F5: 95871200 | G5: =(IF((F5-F4)<0,"0",(F5-F4)))*0.027 -> 510.3 | H5: 629320 | I5: =(IF((H5-H4)<0,"0",(H5-H4)))*0.027 -> 5.67 | J5: =C5+E5+G5+I5 -> 2110.57 | K5: =J5*5.86 -> 12367.94
A6: 43711 | B6: 365392 | C6: =(IF((B6-B5)<0,"0",(B6-B5)))*10 -> 1140 | D6: 96420100 | E6: =(IF((D6-D5)<0,"0",(D6-D5)))*0.027 -> 567 | F6: 95891400 | G6: =(IF((F6-F5)<0,"0",(F6-F5)))*0.027 -> 545.4 | H6: 629528 | I6: =(IF((H6-H5)<0,"0",(H6-H5)))*0.027 -> 5.616 | J6: =C6+E6+G6+I6 -> 2258.016 | K6: =J6*5.86 -> 13231.974
A7: 43712 | B7: 365508 | C7: =(IF((B7-B6)<0,"0",(B7-B6)))*10 -> 1160 | D7: 96441500 | E7: =(IF((D7-D6)<0,"0",(D7-D6)))*0.027 -> 577.8 | F7: 95912200 | G7: =(IF((F7-F6)<0,"0",(F7-F6)))*0.027 -> 561.6 | H7: 629727 | I7: =(IF((H7-H6)<0,"0",(H7-H6)))*0.027 -> 5.373 | J7: =C7+E7+G7+I7 -> 2304.773 | K7: =J7*5.86 -> 13505.97
A8: 43713 | B8: 365629 | C8: =(IF((B8-B7)<0,"0",(B8-B7)))*10 -> 1210 | D8: 96463400 | E8: =(IF((D8-D7)<0,"0",(D8-D7)))*0.027 -> 591.3 | F8: 95933800 | G8: =(IF((F8-F7)<0,"0",(F8-F7)))*0.027 -> 583.2 | H8: 629973 | I8: =(IF((H8-H7)<0,"0",(H8-H7)))*0.027 -> 6.642 | J8: =C8+E8+G8+I8 -> 2391.142 | K8: =J8*5.86 -> 14012.092
A9: 43714 | B9: 365733 | C9: =(IF((B9-B8)<0,"0",(B9-B8)))*10 -> 1040 | D9: 96481800 | E9: =(IF((D9-D8)<0,"0",(D9-D8)))*0.027 -> 496.8 | F9: 95953400 | G9: =(IF((F9-F8)<0,"0",(F9-F8)))*0.027 -> 529.2 | H9: 630191 | I9: =(IF((H9-H8)<0,"0",(H9-H8)))*0.027 -> 5.886 | J9: =C9+E9+G9+I9 -> 2071.886 | K9: =J9*5.86 -> 12141.252
A10: 43715 | B10: 365848 | C10: =(IF((B10-B9)<0,"0",(B10-B9)))*10 -> 1150 | D10: 96502800 | E10: =(IF((D10-D9)<0,"0",(D10-D9)))*0.027 -> 567 | F10: 95973400 | G10: =(IF((F10-F9)<0,"0",(F10-F9)))*0.027 -> 540 | H10: 630476 | I10: =(IF((H10-H9)<0,"0",(H10-H9)))*0.027 -> 7.695 | J10: =C10+E10+G10+I10 -> 2264.695 | K10: =J10*5.86 -> 13271.113
A11: 43716 | B11: 365964 | C11: =(IF((B11-B10)<0,"0",(B11-B10)))*10 -> 1160 | D11: 96525200 | E11: =(IF((D11-D10)<0,"0",(D11-D10)))*0.027 -> 604.8 | F11: 95992000 | G11: =(IF((F11-F10)<0,"0",(F11-F10)))*0.027 -> 502.2 | H11: 630742 | I11: =(IF((H11-H10)<0,"0",(H11-H10)))*0.027 -> 7.182 | J11: =C11+E11+G11+I11 -> 2274.182 | K11: =J11*5.86 -> 13326.707
A12: 43717 | B12: 366063 | C12: =(IF((B12-B11)<0,"0",(B12-B11)))*10 -> 990 | D12: 96544000 | E12: =(IF((D12-D11)<0,"0",(D12-D11)))*0.027 -> 507.6 | F12: 96008400 | G12: =(IF((F12-F11)<0,"0",(F12-F11)))*0.027 -> 442.8 | H12: 630953 | I12: =(IF((H12-H11)<0,"0",(H12-H11)))*0.027 -> 5.697 | J12: =C12+E12+G12+I12 -> 1946.097 | K12: =J12*5.86 -> 11404.128
A13: 43718 | B13: 366184 | C13: =(IF((B13-B12)<0,"0",(B13-B12)))*10 -> 1210 | D13: 96567400 | E13: =(IF((D13-D12)<0,"0",(D13-D12)))*0.027 -> 631.8 | F13: 96028000 | G13: =(IF((F13-F12)<0,"0",(F13-F12)))*0.027 -> 529.2 | H13: 631158 | I13: =(IF((H13-H12)<0,"0",(H13-H12)))*0.027 -> 5.535 | J13: =C13+E13+G13+I13 -> 2376.535 | K13: =J13*5.86 -> 13926.495
A14: 43719 | B14: 366275 | C14: =(IF((B14-B13)<0,"0",(B14-B13)))*10 -> 910 | D14: 96584700 | E14: =(IF((D14-D13)<0,"0",(D14-D13)))*0.027 -> 467.1 | F14: 96043400 | G14: =(IF((F14-F13)<0,"0",(F14-F13)))*0.027 -> 415.8 | H14: 631322 | I14: =(IF((H14-H13)<0,"0",(H14-H13)))*0.027 -> 4.428 | J14: =C14+E14+G14+I14 -> 1797.328 | K14: =J14*5.86 -> 10532.342
A15: 43720 | B15: 366394 | C15: =(IF((B15-B14)<0,"0",(B15-B14)))*10 -> 1190 | D15: 96607400 | E15: =(IF((D15-D14)<0,"0",(D15-D14)))*0.027 -> 612.9 | F15: 96064500 | G15: =(IF((F15-F14)<0,"0",(F15-F14)))*0.027 -> 569.7 | H15: 631495 | I15: =(IF((H15-H14)<0,"0",(H15-H14)))*0.027 -> 4.671 | J15: =C15+E15+G15+I15 -> 2377.271 | K15: =J15*5.86 -> 13930.808
... A18: 43723 | B18: 366711 | C18: =(IF((B18-B17)<0,"0",(B18-B17)))*10 -> 1090 | D18: 96669800 | E18: =(IF((D18-D17)<0,"0",(D18-D17)))*0.027 -> 604.8 | F18: 96121800 | G18: =(IF((F18-F17)<0,"0",(F18-F17)))*0.027 -> 567 | H18: 632036 | I18: =(IF((H18-H17)<0,"0",(H18-H17)))*0.027 -> 5.697 | J18: =C18+E18+G18+I18 -> 2267.497 | K18: =J18*5.86 -> 13287.532
A19: 43724 | B19: 366810 | C19: =(IF((B19-B18)<0,"0",(B19-B18)))*10 -> 990 | D19: 96689100 | E19: =(IF((D19-D18)<0,"0",(D19-D18)))*0.027 -> 521.1 | F19: 96141400 | G19: =(IF((F19-F18)<0,"0",(F19-F18)))*0.027 -> 529.2 | H19: 632221 | I19: =(IF((H19-H18)<0,"0",(H19-H18)))*0.027 -> 4.995 | J19: =C19+E19+G19+I19 -> 2045.295 | K19: =J19*5.86 -> 11985.429 | Q19: `
A20: 43725 | B20: 366931 | C20: =(IF((B20-B19)<0,"0",(B20-B19)))*10 -> 1210 | D20: 96711200 | E20: =(IF((D20-D19)<0,"0",(D20-D19)))*0.027 -> 596.7 | F20: 96161700 | G20: =(IF((F20-F19)<0,"0",(F20-F19)))*0.027 -> 548.1 | H20: 632392 | I20: =(IF((H20-H19)<0,"0",(H20-H19)))*0.027 -> 4.617 | J20: =C20+E20+G20+I20 -> 2359.417 | K20: =J20*5.86 -> 13826.184
A21: 43726 | B21: 367060 | C21: =(IF((B21-B20)<0,"0",(B21-B20)))*10 -> 1290 | D21: 96735700 | E21: =(IF((D21-D20)<0,"0",(D21-D20)))*0.027 -> 661.5 | F21: 96183300 | G21: =(IF((F21-F20)<0,"0",(F21-F20)))*0.027 -> 583.2 | H21: 632600 | I21: =(IF((H21-H20)<0,"0",(H21-H20)))*0.027 -> 5.616 | J21: =C21+E21+G21+I21 -> 2540.316 | K21: =J21*5.86 -> 14886.252
A22: 43727 | B22: 367169 | C22: =(IF((B22-B21)<0,"0",(B22-B21)))*10 -> 1090 | D22: 96756900 | E22: =(IF((D22-D21)<0,"0",(D22-D21)))*0.027 -> 572.4 | F22: 96190000 | G22: =(IF((F22-F21)<0,"0",(F22-F21)))*0.027 -> 180.9 | H22: 632612 | I22: =(IF((H22-H21)<0,"0",(H22-H21)))*0.027 -> 0.324 | J22: =C22+E22+G22+I22 -> 1843.624 | K22: =J22*5.86 -> 10803.637
A23: 43728 | B23: 367255 | C23: =(IF((B23-B22)<0,"0",(B23-B22)))*10 -> 860 | D23: 96775500 | E23: =(IF((D23-D22)<0,"0",(D23-D22)))*0.027 -> 502.2 | F23: 96211000 | G23: =(IF((F23-F22)<0,"0",(F23-F22)))*0.027 -> 567 | H23: 632822 | I23: =(IF((H23-H22)<0,"0",(H23-H22)))*0.027 -> 5.67 | J23: =C23+E23+G23+I23 -> 1934.87 | K23: =J23*5.86 -> 11338.338
A24: 43729 | B24: 367380 | C24: =(IF((B24-B23)<0,"0",(B24-B23)))*10 -> 1250 | D24: 96790600 | E24: =(IF((D24-D23)<0,"0",(D24-D23)))*0.027 -> 407.7 | F24: 96233100 | G24: =(IF((F24-F23)<0,"0",(F24-F23)))*0.027 -> 596.7 | H24: 632932 | I24: =(IF((H24-H23)<0,"0",(H24-H23)))*0.027 -> 2.97 | J24: =C24+E24+G24+I24 -> 2257.37 | K24: =J24*5.86 -> 13228.188
A25: 43730 | B25: 367474 | C25: =(IF((B25-B24)<0,"0",(B25-B24)))*10 -> 940 | D25: 96810300 | E25: =(IF((D25-D24)<0,"0",(D25-D24)))*0.027 -> 531.9 | F25: 96258200 | G25: =(IF((F25-F24)<0,"0",(F25-F24)))*0.027 -> 677.7 | H25: 633328 | I25: =(IF((H25-H24)<0,"0",(H25-H24)))*0.027 -> 10.692 | J25: =C25+E25+G25+I25 -> 2160.292 | K25: =J25*5.86 -> 12659.311
A26: 43731 | B26: 367592 | C26: =(IF((B26-B25)<0,"0",(B26-B25)))*10 -> 1180 | D26: 96831400 | E26: =(IF((D26-D25)<0,"0",(D26-D25)))*0.027 -> 569.7 | F26: 96280000 | G26: =(IF((F26-F25)<0,"0",(F26-F25)))*0.027 -> 588.6 | H26: 633577 | I26: =(IF((H26-H25)<0,"0",(H26-H25)))*0.027 -> 6.723 | J26: =C26+E26+G26+I26 -> 2345.023 | K26: =J26*5.86 -> 13741.835
A27: 43732 | B27: 367688 | C27: =(IF((B27-B26)<0,"0",(B27-B26)))*10 -> 960 | D27: 96849400 | E27: =(IF((D27-D26)<0,"0",(D27-D26)))*0.027 -> 486 | F27: 96896100 | G27: =(IF((F27-F26)<0,"0",(F27-F26)))*0.027 -> 16634.7 | H27: 633792 | I27: =(IF((H27-H26)<0,"0",(H27-H26)))*0.027 -> 5.805 | J27: =C27+E27+G27+I27 -> 18086.505 | K27: =J27*5.86 -> 105986.92
A28: 43733 | B28: 367798 | C28: =(IF((B28-B27)<0,"0",(B28-B27)))*10 -> 1100 | D28: 96871100 | E28: =(IF((D28-D27)<0,"0",(D28-D27)))*0.027 -> 585.9 | F28: 96314100 | G28: =(IF((F28-F27)<0,"0",(F28-F27)))*0.027 -> 0 | H28: 634067 | I28: =(IF((H28-H27)<0,"0",(H28-H27)))*0.027 -> 7.425 | J28: =C28+E28+G28+I28 -> 1693.325 | K28: =J28*5.86 -> 9922.8845
A29: 43734 | B29: 367895 | C29: =(IF((B29-B28)<0,"0",(B29-B28)))*10 -> 970 | D29: 96888800 | E29: =(IF((D29-D28)<0,"0",(D29-D28)))*0.027 -> 477.9 | F29: 96331800 | G29: =(IF((F29-F28)<0,"0",(F29-F28)))*0.027 -> 477.9 | H29: 634302 | I29: =(IF((H29-H28)<0,"0",(H29-H28)))*0.027 -> 6.345 | J29: =C29+E29+G29+I29 -> 1932.145 | K29: =J29*5.86 -> 11322.37
A30: 43735 | B30: 367998 | C30: =(IF((B30-B29)<0,"0",(B30-B29)))*10 -> 1030 | D30: 96908500 | E30: =(IF((D30-D29)<0,"0",(D30-D29)))*0.027 -> 531.9 | F30: 96350300 | G30: =(IF((F30-F29)<0,"0",(F30-F29)))*0.027 -> 499.5 | H30: 634517 | I30: =(IF((H30-H29)<0,"0",(H30-H29)))*0.027 -> 5.805 | J30: =C30+E30+G30+I30 -> 2067.205 | K30: =J30*5.86 -> 12113.821
A31: 43736 | B31: 368106 | C31: =(IF((B31-B30)<0,"0",(B31-B30)))*10 -> 1080 | D31: 96928300 | E31: =(IF((D31-D30)<0,"0",(D31-D30)))*0.027 -> 534.6 | F31: 96368200 | G31: =(IF((F31-F30)<0,"0",(F31-F30)))*0.027 -> 483.3 | H31: 634754 | I31: =(IF((H31-H30)<0,"0",(H31-H30)))*0.027 -> 6.399 | J31: =C31+E31+G31+I31 -> 2104.299 | K31: =J31*5.86 -> 12331.192
... A33: 43738 | B33: 368310 | C33: =(IF((B33-B32)<0,"0",(B33-B32)))*10 -> 980 | D33: 96967700 | E33: =(IF((D33-D32)<0,"0",(D33-D32)))*0.027 -> 499.5 | F33: 96401000 | G33: =(IF((F33-F32)<0,"0",(F33-F32)))*0.027 -> 426.6 | H33: 635215 | I33: =(IF((H33-H32)<0,"0",(H33-H32)))*0.027 -> 5.805 | J33: =C33+E33+G33+I33 -> 1911.905 | K33: =J33*5.86 -> 11203.763
B34: 368310 | C34: =(IF((B34-B33)<0,"0",(B34-B33)))*10 -> 0 | D34: 96967700 | E34: =(IF((D34-D33)<0,"0",(D34-D33)))*0.027 -> 0 | F34: 96401000 | G34: =(IF((F34-F33)<0,"0",(F34-F33)))*0.027 -> 0 | H34: 635215 | I34: =(IF((H34-H33)<0,"0",(H34-H33)))*0.027 -> 0 | J34: =C34+E34+G34+I34 -> 0 | K34: =J34*5.86 -> 0
A35: Total | C35: =SUM(C4:C34) -> 32410 | E35: =SUM(E4:E34) -> 16440.3 | G35: =SUM(G4:G34) -> 31041.9 | I35: =SUM(I4:I34) -> 170.505 | J35: =SUM(J4:J31) -> 76060.858 | K35: =SUM(K4:K31) -> 445716.63

Sheet ELECT.
A1: Feeders and transformers Electrity cons. Sep. 2019
A2: Day | B2: Rooms Sold | C2: New Chillers | D2: Cons | E2: F-1 | F2: Cons. | G2: F-2 | H2: Cons. | I2: Total | J2: T-1 | K2: Cons. | L2: T-2 | M2: Cons. | N2: T-3 | O2: Cons. | P2: T-4 | Q2: Cons. | R2: T-5 | S2: Cons. | T2: T-6 | U2: Cons. | V2: T-7 | W2: Cons. | X2: Total | Y2: Diff | Z2: Daily Money Value | AA2: MTD Total Money
A3: Last | B3: 245 | C3: 16297 | D3: 480 | E3: 18643308 | F3: 0 | G3: 52775188 | H3: 60069 | I3: 60069 | J3: 4613370 | K3: 6297 | L3: 4926113 | M3: 8405 | N3: 3095086 | O3: 16568 | P3: 7372585 | Q3: 14280 | R3: 11582143 | S3: 11726 | T3: 0 | V3: 8349237 | W3: 13364 | X3: 70640 | Y3: -10571 | Z3: 10555.528 | AA3: 43309.561
A4: 43709 | B4: 245 | C4: 16299 | D4: =IF((C4-C3)<0,"0",(C4-C3))*160 -> 320 | E4: 18667512 | F4: =IF((E4-E3)<0,"0",(E4-E3)) -> 24204 | G4: 52833980 | H4: =IF((G4-G3)<0,"0",(G4-G3)) -> 58792 | I4: =F4+H4 -> 82996 | J4: 4619912 | K4: =IF((J4-J3)<0,"0",(J4-J3)) -> 6542 | L4: 4934244 | M4: =IF((L4-L3)<0,"0",(L4-L3)) -> 8131 | N4: 3108920 | O4: =(IF((N4-N3)<0,"0",(N4-N3)))*2 -> 27668 | P4: 7386589 | Q4: =IF((P4-P3)<0,"0",(P4-P3)) -> 14004 | R4: 11593632 | S4: =IF((R4-R3)<0,"0",(R4-R3)) -> 11489 | T4: 0 | V4: 8361940 | W4: =IF((V4-V3)<0,"0",(V4-V3)) -> 12703 | X4: =K4+M4+O4+Q4+S4+U4+W4 -> 80537 | Y4: =I4-X4 -> 2459 | Z4: =(0.93352*(W4+S4)+0.5568*(Q4+O4))*0.26 -> 11904.538 | AA4: =SUM(Z1:Z4) -> 22460.066
A5: 43710 | B5: 240 | C5: 16313 | D5: =IF((C5-C4)<0,"0",(C5-C4))*160 -> 2240 | E5: 18691862 | F5: =IF((E5-E4)<0,"0",(E5-E4)) -> 24350 | G5: 52890882 | H5: =IF((G5-G4)<0,"0",(G5-G4)) -> 56902 | I5: =F5+H5 -> 81252 | J5: 4626122 | K5: =IF((J5-J4)<0,"0",(J5-J4)) -> 6210 | L5: 4942830 | M5: =IF((L5-L4)<0,"0",(L5-L4)) -> 8586 | N5: 3110706 | O5: =(IF((N5-N4)<P100,"0",(N5-N4)))*2 -> 3572 | P5: 7399971 | Q5: =IF((P5-P4)<0,"0",(P5-P4)) -> 13382 | R5: 11604980 | S5: =IF((R5-R4)<0,"0",(R5-R4)) -> 11348 | T5: 0 | V5: 8374456 | W5: =IF((V5-V4)<0,"0",(V5-V4)) -> 12516 | X5: =K5+M5+O5+Q5+S5+U5+W5 -> 55614 | Y5: =I5-X5 -> 25638 | Z5: =(0.93352*(W5+S5)+0.5568*(Q5+O5))*0.26 -> 8246.5522 | AA5: =SUM(Z2:Z5) -> 30706.618
A6: 43711 | B6: 248 | C6: 16320 | D6: =IF((C6-C5)<0,"0",(C6-C5))*160 -> 1120 | E6: 18708973 | F6: =IF((E6-E5)<0,"0",(E6-E5)) -> 17111 | G6: 52940657 | H6: =IF((G6-G5)<0,"0",(G6-G5)) -> 49775 | I6: =F6+H6 -> 66886 | J6: 4631457 | K6: =IF((J6-J5)<0,"0",(J6-J5)) -> 5335 | L6: 4948627 | M6: =IF((L6-L5)<0,"0",(L6-L5)) -> 5797 | N6: 3116272 | O6: =(IF((N6-N5)<0,"0",(N6-N5)))*2 -> 11132 | P6: 7411342 | Q6: =IF((P6-P5)<0,"0",(P6-P5)) -> 11371 | R6: 11615010 | S6: =IF((R6-R5)<0,"0",(R6-R5)) -> 10030 | T6: 0 | V6: 8385494 | W6: =IF((V6-V5)<0,"0",(V6-V5)) -> 11038 | X6: =K6+M6+O6+Q6+S6+U6+W6 -> 54703 | Y6: =I6-X6 -> 12183 | Z6: =(0.93352*(W6+S6)+0.5568*(Q6+O6))*0.26 -> 8371.2381 | AA6: =SUM(Z3:Z6) -> 39077.856
A7: 43712 | B7: 242 | C7: 16325 | D7: =IF((C7-C6)<0,"0",(C7-C6))*160 -> 800 | E7: 18728369 | F7: =IF((E7-E6)<0,"0",(E7-E6)) -> 19396 | G7: 53004293 | H7: =IF((G7-G6)<0,"0",(G7-G6)) -> 63636 | I7: =F7+H7 -> 83032 | J7: 4638741 | K7: =IF((J7-J6)<0,"0",(J7-J6)) -> 7284 | L7: 4955026 | M7: =IF((L7-L6)<0,"0",(L7-L6)) -> 6399 | N7: 3122667 | O7: =(IF((N7-N6)<0,"0",(N7-N6)))*2 -> 12790 | P7: 7425876 | Q7: =IF((P7-P6)<0,"0",(P7-P6)) -> 14534 | R7: 11628580 | S7: =IF((R7-R6)<0,"0",(R7-R6)) -> 13570 | T7: 0 | V7: 8399690 | W7: =IF((V7-V6)<0,"0",(V7-V6)) -> 14196 | X7: =K7+M7+O7+Q7+S7+U7+W7 -> 68773 | Y7: =I7-X7 -> 14259 | Z7: =(0.93352*(W7+S7)+0.5568*(Q7+O7))*0.26 -> 10694.871 | AA7: =SUM(Z4:Z7) -> 39217.2
A8: 43713 | B8: 293 | C8: 16332 | D8: =IF((C8-C7)<0,"0",(C8-C7))*160 -> 1120 | E8: 18745689 | F8: =IF((E8-E7)<0,"0",(E8-E7)) -> 17320 | G8: 53064668 | H8: =IF((G8-G7)<0,"0",(G8-G7)) -> 60375 | I8: =F8+H8 -> 77695 | J8: 4644638 | K8: =IF((J8-J7)<0,"0",(J8-J7)) -> 5897 | L8: 4960630 | M8: =IF((L8-L7)<0,"0",(L8-L7)) -> 5604 | N8: 3128430 | O8: =(IF((N8-N7)<0,"0",(N8-N7)))*2 -> 11526 | P8: 7439644 | Q8: =IF((P8-P7)<0,"0",(P8-P7)) -> 13768 | R8: 11640216 | S8: =IF((R8-R7)<0,"0",(R8-R7)) -> 11636 | T8: 0 | V8: 8412946 | W8: =IF((V8-V7)<0,"0",(V8-V7)) -> 13256 | X8: =K8+M8+O8+Q8+S8+U8+W8 -> 61687 | Y8: =I8-X8 -> 16008 | Z8: =(0.93352*(W8+S8)+0.5568*(Q8+O8))*0.26 -> 9703.4286 | AA8: =SUM(Z5:Z8) -> 37016.09
A9: 43714 | B9: 277 | C9: 16337 | D9: =IF((C9-C8)<0,"0",(C9-C8))*160 -> 800 | E9: 18764592 | F9: =IF((E9-E8)<0,"0",(E9-E8)) -> 18903 | G9: 53129258 | H9: =IF((G9-G8)<0,"0",(G9-G8)) -> 64590 | I9: =F9+H9 -> 83493 | J9: 4650891 | K9: =IF((J9-J8)<0,"0",(J9-J8)) -> 6253 | L9: 4966514 | M9: =IF((L9-L8)<0,"0",(L9-L8)) -> 5884 | N9: 3134807 | O9: =(IF((N9-N8)<0,"0",(N9-N8)))*2 -> 12754 | P9: 7455113 | Q9: =IF((P9-P8)<0,"0",(P9-P8)) -> 15469 | R9: 11653256 | S9: =IF((R9-R8)<0,"0",(R9-R8)) -> 13040 | T9: 0 | V9: 8427130 | W9: =IF((V9-V8)<0,"0",(V9-V8)) -> 14184 | X9: =K9+M9+O9+Q9+S9+U9+W9 -> 67584 | Y9: =I9-X9 -> 15909 | Z9: =(0.93352*(W9+S9)+0.5568*(Q9+O9))*0.26 -> 10693.466 | AA9: =SUM(Z6:Z9) -> 39463.004
A10: 43715 | B10: 292 | C10: 16344 | D10: =IF((C10-C9)<0,"0",(C10-C9))*160 -> 1120 | E10: 18780454 | F10: =IF((E10-E9)<0,"0",(E10-E9)) -> 15862 | G10: 53172948 | H10: =IF((G10-G9)<0,"0",(G10-G9)) -> 43690 | I10: =F10+H10 -> 59552 | J10: 4655458 | K10: =IF((J10-J9)<0,"0",(J10-J9)) -> 4567 | L10: 4971666 | M10: =IF((L10-L9)<0,"0",(L10-L9)) -> 5152 | N10: 3140106 | O10: =(IF((N10-N9)<0,"0",(N10-N9)))*2 -> 10598 | P10: 7465468 | Q10: =IF((P10-P9)<0,"0",(P10-P9)) -> 10355 | R10: 11662073 | S10: =IF((R10-R9)<0,"0",(R10-R9)) -> 8817 | T10: 0 | V10: 8436753 | W10: =IF((V10-V9)<0,"0",(V10-V9)) -> 9623 | X10: =K10+M10+O10+Q10+S10+U10+W10 -> 49112 | Y10: =I10-X10 -> 10440 | Z10: =(0.93352*(W10+S10)+0.5568*(Q10+O10))*0.26 -> 7508.9922 | AA10: =SUM(Z7:Z10) -> 38600.758
A11: 43716 | B11: 269 | C11: 16352 | D11: =IF((C11-C10)<0,"0",(C11-C10))*160 -> 1280 | E11: 18803451 | F11: =IF((E11-E10)<0,"0",(E11-E10)) -> 22997 | G11: 53247342 | H11: =IF((G11-G10)<0,"0",(G11-G10)) -> 74394 | I11: =F11+H11 -> 97391 | J11: 4663266 | K11: =IF((J11-J10)<0,"0",(J11-J10)) -> 7808 | L11: 4979829 | M11: =IF((L11-L10)<0,"0",(L11-L10)) -> 8163 | N11: 3147427 | O11: =(IF((N11-N10)<0,"0",(N11-N10)))*2 -> 14642 | P11: 7482564 | Q11: =IF((P11-P10)<0,"0",(P11-P10)) -> 17096 | R11: 11676700 | S11: =IF((R11-R10)<0,"0",(R11-R10)) -> 14627 | T11: 0 | V11: 8453429 | W11: =IF((V11-V10)<0,"0",(V11-V10)) -> 16676 | X11: =K11+M11+O11+Q11+S11+U11+W11 -> 79012 | Y11: =I11-X11 -> 18379 | Z11: =(0.93352*(W11+S11)+0.5568*(Q11+O11))*0.26 -> 12192.361 | AA11: =SUM(Z8:Z11) -> 40098.247
A12: 43717 | B12: 280 | C12: 16360 | D12: =IF((C12-C11)<0,"0",(C12-C11))*160 -> 1280 | E12: 18822943 | F12: =IF((E12-E11)<0,"0",(E12-E11)) -> 19492 | G12: 53305696 | H12: =IF((G12-G11)<0,"0",(G12-G11)) -> 58354 | I12: =F12+H12 -> 77846 | J12: 4669295 | K12: =IF((J12-J11)<0,"0",(J12-J11)) -> 6029 | L12: 4986616 | M12: =IF((L12-L11)<0,"0",(L12-L11)) -> 6787 | N12: 3153659 | O12: =(IF((N12-N11)<0,"0",(N12-N11)))*2 -> 12464 | P12: 7495523 | Q12: =IF((P12-P11)<0,"0",(P12-P11)) -> 12959 | R12: 11687911 | S12: =IF((R12-R11)<0,"0",(R12-R11)) -> 11211 | T12: 0 | V12: 8466915 | W12: =IF((V12-V11)<0,"0",(V12-V11)) -> 13486 | X12: =K12+M12+O12+Q12+S12+U12+W12 -> 62936 | Y12: =I12-X12 -> 14910 | Z12: =(0.93352*(W12+S12)+0.5568*(Q12+O12))*0.26 -> 9674.7742 | AA12: =SUM(Z9:Z12) -> 40069.593
A13: 43718 | B13: 297 | C13: 16366 | D13: =IF((C13-C12)<0,"0",(C13-C12))*160 -> 960 | E13: 18841328 | F13: =IF((E13-E12)<0,"0",(E13-E12)) -> 18385 | G13: 53370283 | H13: =IF((G13-G12)<0,"0",(G13-G12)) -> 64587 | I13: =F13+H13 -> 82972 | J13: 4676077 | K13: =IF((J13-J12)<0,"0",(J13-J12)) -> 6782 | L13: 4992637 | M13: =IF((L13-L12)<0,"0",(L13-L12)) -> 6021 | N13: 3159725 | O13: =(IF((N13-N12)<0,"0",(N13-N12)))*2 -> 12132 | P13: 7509824 | Q13: =IF((P13-P12)<0,"0",(P13-P12)) -> 14301 | R13: 11700449 | S13: =IF((R13-R12)<0,"0",(R13-R12)) -> 12538 | T13: 0 | V13: 8481664 | W13: =IF((V13-V12)<0,"0",(V13-V12)) -> 14749 | X13: =K13+M13+O13+Q13+S13+U13+W13 -> 66523 | Y13: =I13-X13 -> 16449 | Z13: =(0.93352*(W13+S13)+0.5568*(Q13+O13))*0.26 -> 10449.622 | AA13: =SUM(Z10:Z13) -> 39825.749
A14: 43719 | B14: 294 | C14: 16374 | D14: =IF((C14-C13)<0,"0",(C14-C13))*160 -> 1280 | E14: 18856715 | F14: =IF((E14-E13)<0,"0",(E14-E13)) -> 15387 | G14: 53415421 | H14: =IF((G14-G13)<0,"0",(G14-G13)) -> 45138 | I14: =F14+H14 -> 60525 | J14: 4680844 | K14: =IF((J14-J13)<0,"0",(J14-J13)) -> 4767 | L14: 4997241 | M14: =IF((L14-L13)<0,"0",(L14-L13)) -> 4604 | N14: 3163964 | O14: =(IF((N14-N13)<0,"0",(N14-N13)))*2 -> 8478 | P14: 7519808 | Q14: =IF((P14-P13)<0,"0",(P14-P13)) -> 9984 | R14: 11709210 | S14: =IF((R14-R13)<0,"0",(R14-R13)) -> 8761 | T14: 0 | V14: 8492086 | W14: =IF((V14-V13)<0,"0",(V14-V13)) -> 10422 | X14: =K14+M14+O14+Q14+S14+U14+W14 -> 47016 | Y14: =I14-X14 -> 13509 | Z14: =(0.93352*(W14+S14)+0.5568*(Q14+O14))*0.26 -> 7328.7125 | AA14: =SUM(Z11:Z14) -> 39645.47
A15: 43720 | B15: 304 | C15: 16382 | D15: =IF((C15-C14)<0,"0",(C15-C14))*160 -> 1280 | E15: 18877785 | F15: =IF((E15-E14)<0,"0",(E15-E14)) -> 21070 | G15: 53494406 | H15: =IF((G15-G14)<0,"0",(G15-G14)) -> 78985 | I15: =F15+H15 -> 100055 | J15: 4688995 | K15: =IF((J15-J14)<0,"0",(J15-J14)) -> 8151 | L15: 5005460 | M15: =IF((L15-L14)<0,"0",(L15-L14)) -> 8219 | N15: 3171345 | O15: =(IF((N15-N14)<0,"0",(N15-N14)))*2 -> 14762 | P15: 7537246 | Q15: =IF((P15-P14)<0,"0",(P15-P14)) -> 17438 | R15: 11724539 | S15: =IF((R15-R14)<0,"0",(R15-R14)) -> 15329 | T15: 0 | V15: 8510265 | W15: =IF((V15-V14)<0,"0",(V15-V14)) -> 18179 | X15: =K15+M15+O15+Q15+S15+U15+W15 -> 82078 | Y15: =I15-X15 -> 17977 | Z15: =(0.93352*(W15+S15)+0.5568*(Q15+O15))*0.26 -> 12794.431 | AA15: =SUM(Z12:Z15) -> 40247.539
A16: 43721 | B16: 323 | C16: 16391 | D16: =IF((C16-C15)<0,"0",(C16-C15))*160 -> 1440 | E16: 18893925 | F16: =IF((E16-E15)<0,"0",(E16-E15)) -> 16140 | G16: 53549862 | H16: =IF((G16-G15)<0,"0",(G16-G15)) -> 55456 | I16: =F16+H16 -> 71596 | J16: 4694487 | K16: =IF((J16-J15)<0,"0",(J16-J15)) -> 5492 | L16: 5010869 | M16: =IF((L16-L15)<0,"0",(L16-L15)) -> 5409 | N16: 3176642 | O16: =(IF((N16-N15)<0,"0",(N16-N15)))*2 -> 10594 | P16: 7549542 | Q16: =IF((P16-P15)<0,"0",(P16-P15)) -> 12296 | R16: 11735769 | S16: =IF((R16-R15)<0,"0",(R16-R15)) -> 11230 | T16: 0 | V16: 8522980 | W16: =IF((V16-V15)<0,"0",(V16-V15)) -> 12715 | X16: =K16+M16+O16+Q16+S16+U16+W16 -> 57736 | Y16: =I16-X16 -> 13860 | Z16: =(0.93352*(W16+S16)+0.5568*(Q16+O16))*0.26 -> 9125.555 | AA16: =SUM(Z13:Z16) -> 39698.32
A17: 43722 | B17: 350 | C17: 16395 | D17: =IF((C17-C16)<0,"0",(C17-C16))*160 -> 640 | E17: 18911485 | F17: =IF((E17-E16)<0,"0",(E17-E16)) -> 17560 | G17: 53611577 | H17: =IF((G17-G16)<0,"0",(G17-G16)) -> 61715 | I17: =F17+H17 -> 79275 | J17: 4700597 | K17: =IF((J17-J16)<0,"0",(J17-J16)) -> 6110 | L17: 5016862 | M17: =IF((L17-L16)<0,"0",(L17-L16)) -> 5993 | N17: 3182319 | O17: =(IF((N17-N16)<0,"0",(N17-N16)))*2 -> 11354 | P17: 7562535 | Q17: =IF((P17-P16)<0,"0",(P17-P16)) -> 12993 | R17: 11748149 | S17: =IF((R17-R16)<0,"0",(R17-R16)) -> 12380 | T17: 0 | V17: 8537713 | W17: =IF((V17-V16)<0,"0",(V17-V16)) -> 14733 | X17: =K17+M17+O17+Q17+S17+U17+W17 -> 63563 | Y17: =I17-X17 -> 15712 | Z17: =(0.93352*(W17+S17)+0.5568*(Q17+O17))*0.26 -> 10105.404 | AA17: =SUM(Z14:Z17) -> 39354.102
... A33: 43738 | B33: 248 | C33: 16502 | D33: =IF((C33-C32)<0,"0",(C33-C32))*160 -> 480 | E33: 19193711 | F33: =IF((E33-E32)<0,"0",(E33-E32)) -> 17179 | G33: 54582537 | H33: =IF((G33-G32)<0,"0",(G33-G32)) -> 64613 | I33: =F33+H33 -> 81792 | J33: 4800570 | K33: =IF((J33-J32)<0,"0",(J33-J32)) -> 6797 | L33: 5116576 | M33: =IF((L33-L32)<0,"0",(L33-L32)) -> 6359 | N33: 3272510 | O33: =(IF((N33-N32)<0,"0",(N33-N32)))*2 -> 11648 | P33: 7772441 | Q33: =IF((P33-P32)<0,"0",(P33-P32)) -> 13666 | R33: 11930963 | S33: =IF((R33-R32)<0,"0",(R33-R32)) -> 13241 | T33: 0 | V33: 8765395 | W33: =IF((V33-V32)<0,"0",(V33-V32)) -> 14905 | X33: =K33+M33+O33+Q33+S33+U33+W33 -> 66616 | Y33: =I33-X33 -> 15176 | Z33: =(0.93352*(W33+S33)+0.5568*(Q33+O33))*0.26 -> 10496.119 | AA33: =SUM(Z30:Z33) -> 41742.305
C34: 16502 | D34: =IF((C34-C33)<0,"0",(C34-C33))*160 -> 0 | E34: 19193711 | F34: =IF((E34-E33)<0,"0",(E34-E33)) -> 0 | G34: 54582537 | H34: =IF((G34-G33)<0,"0",(G34-G33)) -> 0 | I34: =F34+H34 -> 0 | J34: 4800570 | K34: =IF((J34-J33)<0,"0",(J34-J33)) -> 0 | L34: 5116576 | M34: =IF((L34-L33)<0,"0",(L34-L33)) -> 0 | N34: 3272510 | O34: =(IF((N34-N33)<0,"0",(N34-N33)))*2 -> 0 | P34: 7772441 | Q34: =IF((P34-P33)<0,"0",(P34-P33)) -> 0 | R34: 11930963 | S34: =IF((R34-R33)<0,"0",(R34-R33)) -> 0 | T34: 0 | V34: 8765395 | W34: =IF((V34-V33)<0,"0",(V34-V33)) -> 0 | X34: =K34+M34+O34+Q34+S34+U34+W34 -> 0 | Y34: =I34-X34 -> 0 | Z34: =(0.93352*(W34+S34)+0.5568*(Q34+O34))*0.26 -> 0 | AA34: =SUM(Z31:Z34) -> 29001.459
A35: Total | F35: =SUM(F3:F34) -> 550403 | H35: =SUM(H3:H34) -> 1867418 | I35: =F35+H35 -> 2417821 | K35: =SUM(K3:K34) -> 193497 | M35: =SUM(M3:M34) -> 198868 | O35: =SUM(O3:O34) -> 371416 | Q35: =SUM(Q3:Q34) -> 414136 | S35: =SUM(S3:T34) -> 360546 | W35: =SUM(W3:W34) -> 429522 | X35: =SUM(X4:X31) -> 1759714 | Y35: =SUM(Y4:Y31) -> 426129 | Z35: =SUM(Z5:Z31) -> 261488.24

Sheet Gas
A1: Gas Con. Sep 2019
A2: Day | B2: Main | C2: Cons.
A3: Last | B3: 15830854
A4: 43709 | B4: 15833002 | C4: =IF((B4-B3)<0,"0",(B4-B3)) -> 2148
A5: 43710 | B5: 15835962 | C5: =IF((B5-B4)<0,"0",(B5-B4)) -> 2960
A6: 43711 | B6: 15838407 | C6: =IF((B6-B5)<0,"0",(B6-B5)) -> 2445
A7: 43712 | B7: 15840508 | C7: =IF((B7-B6)<0,"0",(B7-B6)) -> 2101
A8: 43713 | B8: 15844590 | C8: =IF((B8-B7)<0,"0",(B8-B7)) -> 4082
A9: 43714 | B9: 15848545 | C9: =IF((B9-B8)<0,"0",(B9-B8)) -> 3955
A10: 43715 | B10: 15850873 | C10: =IF((B10-B9)<0,"0",(B10-B9)) -> 2328
A11: 43716 | B11: 15854475 | C11: =IF((B11-B10)<0,"0",(B11-B10)) -> 3602
A12: 43717 | B12: 15858063 | C12: =IF((B12-B11)<0,"0",(B12-B11)) -> 3588
A13: 43718 | B13: 15861028 | C13: =IF((B13-B12)<0,"0",(B13-B12)) -> 2965
A14: 43719 | B14: 15863847 | C14: =IF((B14-B13)<0,"0",(B14-B13)) -> 2819
A15: 43720 | B15: 15867458 | C15: =IF((B15-B14)<0,"0",(B15-B14)) -> 3611
... A33: 43738 | B33: 15925989 | C33: =IF((B33-B32)<0,"0",(B33-B32)) -> 3144
B34: 15925989 | C34: =IF((B34-B33)<0,"0",(B34-B33)) -> 0
A35: Total | C35: =SUM(C4:C34) -> 95135

Sheet BTU
A1: Day | B1: Hotel | C1: Cons. Mwh | D1: Cost (LE) | E1: B.S | F1: Cons. Mwh | G1: Cost (LE) | H1: LS | I1: Cons.Mwh | J1: . | K1: AHU # 25 | L1: Cons.Mwh | M1: Cost (LE) | N1: Mall | O1: Cons.Mwh | P1: Cost (LE) | Q1: AHU # 9 | R1: Cons.Mwh | S1: Cost (LE) | T1: Total Cons. | U1: Total Cost (LE)
A2: Last | B2: 16049.882 | C2: 0 | D2: 0 | E2: 2511.5757 | F2: 4.098 | G2: 7786.2 | H2: 1003.3333 | I2: 1.5 | J2: 2850 | K2: 12839.8 | L2: 0.84 | M2: 1596 | N2: 2090.241 | O2: 3.2535 | P2: 6181.65 | Q2: 4151.36 | R2: 2.561 | S2: 4865.9 | T2: 12.2525 | U2: 23279.75
A3: 43709 | B3: 16064.034 | C3: =IF((B3-B2)<0,"0",(B3-B2)) -> 14.1516 | D3: =C3*1.9*1000 -> 26888.04 | E3: 2512.473 | F3: =IF((E3-E2)<0,"0",(E3-E2)) -> 0.89733333 | G3: =F3*1.9*1000 -> 1704.9333 | H3: 58 | I3: =IF((H3-H2)<0,"0",(H3-H2)) -> 0 | J3: =I3*1.9*1000 -> 0 | K3: 12839.9 | L3: =IF((K3-K2)<0,"0",(K3-K2)) -> 0.1 | M3: =L3*1.9*1000 -> 190 | N3: 2091.396 | O3: =IF((N3-N2)<0,"0",(N3-N2)) -> 1.155 | P3: =O3*1.9*1000 -> 2194.5 | Q3: 4154.2 | R3: =IF((Q3-Q2)<0,"0",(Q3-Q2)) -> 2.84 | S3: =R3*1.9*1000 -> 5396 | T3: =C3+F3+I3+L3+O3+R3 -> 19.143933 | U3: =T3*1.9*1000 -> 36373.473
A4: 43710 | B4: 16078.37 | C4: =IF((B4-B3)<0,"0",(B4-B3)) -> 14.336 | D4: =C4*1.9*1000 -> 27238.4 | E4: 2512.868 | F4: =IF((E4-E3)<0,"0",(E4-E3)) -> 0.395 | G4: =F4*1.9*1000 -> 750.5 | H4: 68 | I4: =IF((H4-H3)<0,"0",(H4-H3)) -> 10 | J4: =I4*1.9*1000 -> 19000 | K4: 12840.44 | L4: =IF((K4-K3)<0,"0",(K4-K3)) -> 0.54 | M4: =L4*1.9*1000 -> 1026 | N4: 2094.141 | O4: =IF((N4-N3)<0,"0",(N4-N3)) -> 2.745 | P4: =O4*1.9*1000 -> 5215.5 | Q4: 4160 | R4: =IF((Q4-Q3)<0,"0",(Q4-Q3)) -> 5.8 | S4: =R4*1.9*1000 -> 11020 | T4: =C4+F4+I4+L4+O4+R4 -> 33.816 | U4: =T4*1.9*1000 -> 64250.4
A5: 43711 | B5: 16110.551 | C5: =IF((B5-B4)<0,"0",(B5-B4)) -> 32.181 | D5: =C5*1.9*1000 -> 61143.9 | E5: 2517.9 | F5: =IF((E5-E4)<0,"0",(E5-E4)) -> 5.032 | G5: =F5*1.9*1000 -> 9560.8 | H5: 73 | I5: =IF((H5-H4)<0,"0",(H5-H4)) -> 5 | J5: =I5*1.9*1000 -> 9500 | K5: 12842.03 | L5: =IF((K5-K4)<0,"0",(K5-K4)) -> 1.59 | M5: =L5*1.9*1000 -> 3021 | N5: 2100.697 | O5: =IF((N5-N4)<0,"0",(N5-N4)) -> 6.556 | P5: =O5*1.9*1000 -> 12456.4 | Q5: 4164 | R5: =IF((Q5-Q4)<0,"0",(Q5-Q4)) -> 4 | S5: =R5*1.9*1000 -> 7600 | T5: =C5+F5+I5+L5+O5+R5 -> 54.359 | U5: =T5*1.9*1000 -> 103282.1
A6: 43712 | B6: 16125.531 | C6: =IF((B6-B5)<0,"0",(B6-B5)) -> 14.98 | D6: =C6*1.9*1000 -> 28462 | E6: 2521.295 | F6: =IF((E6-E5)<0,"0",(E6-E5)) -> 3.395 | G6: =F6*1.9*1000 -> 6450.5 | H6: 73 | I6: =IF((H6-H5)<0,"0",(H6-H5)) -> 0 | J6: =I6*1.9*1000 -> 0 | K6: 12842.79 | L6: =IF((K6-K5)<0,"0",(K6-K5)) -> 0.76 | M6: =L6*1.9*1000 -> 1444 | N6: 2104.225 | O6: =IF((N6-N5)<0,"0",(N6-N5)) -> 3.528 | P6: =O6*1.9*1000 -> 6703.2 | Q6: 4165.03 | R6: =IF((Q6-Q5)<0,"0",(Q6-Q5)) -> 1.03 | S6: =R6*1.9*1000 -> 1957 | T6: =C6+F6+I6+L6+O6+R6 -> 23.693 | U6: =T6*1.9*1000 -> 45016.7
A7: 43713 | B7: 16141.487 | C7: =IF((B7-B6)<0,"0",(B7-B6)) -> 15.956 | D7: =C7*1.9*1000 -> 30316.4 | E7: 2524.604 | F7: =IF((E7-E6)<0,"0",(E7-E6)) -> 3.309 | G7: =F7*1.9*1000 -> 6287.1 | H7: 73 | I7: =IF((H7-H6)<0,"0",(H7-H6)) -> 0 | J7: =I7*1.9*1000 -> 0 | K7: 12843.55 | L7: =IF((K7-K6)<0,"0",(K7-K6)) -> 0.76 | M7: =L7*1.9*1000 -> 1444 | N7: 2107.455 | O7: =IF((N7-N6)<0,"0",(N7-N6)) -> 3.23 | P7: =O7*1.9*1000 -> 6137 | Q7: 4166 | R7: =IF((Q7-Q6)<0,"0",(Q7-Q6)) -> 0.97 | S7: =R7*1.9*1000 -> 1843 | T7: =C7+F7+I7+L7+O7+R7 -> 24.225 | U7: =T7*1.9*1000 -> 46027.5
A8: 43714 | B8: 16160.484 | C8: =IF((B8-B7)<0,"0",(B8-B7)) -> 18.997 | D8: =C8*1.9*1000 -> 36094.3 | E8: 2526.674 | F8: =IF((E8-E7)<0,"0",(E8-E7)) -> 2.07 | G8: =F8*1.9*1000 -> 3933 | H8: 73 | I8: =IF((H8-H7)<0,"0",(H8-H7)) -> 0 | J8: =I8*1.9*1000 -> 0 | K8: 12844.43 | L8: =IF((K8-K7)<0,"0",(K8-K7)) -> 0.88 | M8: =L8*1.9*1000 -> 1672 | N8: 2110.939 | O8: =IF((N8-N7)<0,"0",(N8-N7)) -> 3.484 | P8: =O8*1.9*1000 -> 6619.6 | Q8: 4171.09 | R8: =IF((Q8-Q7)<0,"0",(Q8-Q7)) -> 5.09 | S8: =R8*1.9*1000 -> 9671 | T8: =C8+F8+I8+L8+O8+R8 -> 30.521 | U8: =T8*1.9*1000 -> 57989.9
A9: 43715 | B9: 16175.536 | C9: =IF((B9-B8)<0,"0",(B9-B8)) -> 15.052 | D9: =C9*1.9*1000 -> 28598.8 | E9: 2528.566 | F9: =IF((E9-E8)<0,"0",(E9-E8)) -> 1.892 | G9: =F9*1.9*1000 -> 3594.8 | H9: 73 | I9: =IF((H9-H8)<0,"0",(H9-H8)) -> 0 | J9: =I9*1.9*1000 -> 0 | K9: 12845.14 | L9: =IF((K9-K8)<0,"0",(K9-K8)) -> 0.71 | M9: =L9*1.9*1000 -> 1349 | N9: 2114.409 | O9: =IF((N9-N8)<0,"0",(N9-N8)) -> 3.47 | P9: =O9*1.9*1000 -> 6593 | Q9: 4172.2 | R9: =IF((Q9-Q8)<0,"0",(Q9-Q8)) -> 1.11 | S9: =R9*1.9*1000 -> 2109 | T9: =C9+F9+I9+L9+O9+R9 -> 22.234 | U9: =T9*1.9*1000 -> 42244.6
A10: 43716 | B10: 16190.62 | C10: =IF((B10-B9)<0,"0",(B10-B9)) -> 15.084 | D10: =C10*1.9*1000 -> 28659.6 | E10: 2532.452 | F10: =IF((E10-E9)<0,"0",(E10-E9)) -> 3.886 | G10: =F10*1.9*1000 -> 7383.4 | H10: 73 | I10: =IF((H10-H9)<0,"0",(H10-H9)) -> 0 | J10: =I10*1.9*1000 -> 0 | K10: 12845.89 | L10: =IF((K10-K9)<0,"0",(K10-K9)) -> 0.75 | M10: =L10*1.9*1000 -> 1425 | N10: 2117.748 | O10: =IF((N10-N9)<0,"0",(N10-N9)) -> 3.339 | P10: =O10*1.9*1000 -> 6344.1 | Q10: 4173 | R10: =IF((Q10-Q9)<0,"0",(Q10-Q9)) -> 0.8 | S10: =R10*1.9*1000 -> 1520 | T10: =C10+F10+I10+L10+O10+R10 -> 23.859 | U10: =T10*1.9*1000 -> 45332.1
A11: 43717 | B11: 16204.9 | C11: =IF((B11-B10)<0,"0",(B11-B10)) -> 14.28 | D11: =C11*1.9*1000 -> 27132 | E11: 2536.2 | F11: =IF((E11-E10)<0,"0",(E11-E10)) -> 3.748 | G11: =F11*1.9*1000 -> 7121.2 | H11: 73 | I11: =IF((H11-H10)<0,"0",(H11-H10)) -> 0 | J11: =I11*1.9*1000 -> 0 | K11: 12846.6 | L11: =IF((K11-K10)<0,"0",(K11-K10)) -> 0.71 | M11: =L11*1.9*1000 -> 1349 | N11: 2121 | O11: =IF((N11-N10)<0,"0",(N11-N10)) -> 3.252 | P11: =O11*1.9*1000 -> 6178.8 | Q11: 4176 | R11: =IF((Q11-Q10)<0,"0",(Q11-Q10)) -> 3 | S11: =R11*1.9*1000 -> 5700 | T11: =C11+F11+I11+L11+O11+R11 -> 24.99 | U11: =T11*1.9*1000 -> 47481
A12: 43718 | B12: 16219.3 | C12: =IF((B12-B11)<0,"0",(B12-B11)) -> 14.4 | D12: =C12*1.9*1000 -> 27360 | E12: 2539.8 | F12: =IF((E12-E11)<0,"0",(E12-E11)) -> 3.6 | G12: =F12*1.9*1000 -> 6840 | H12: 73 | I12: =IF((H12-H11)<0,"0",(H12-H11)) -> 0 | J12: =I12*1.9*1000 -> 0 | K12: 12847.4 | L12: =IF((K12-K11)<0,"0",(K12-K11)) -> 0.8 | M12: =L12*1.9*1000 -> 1520 | N12: 2124.5 | O12: =IF((N12-N11)<0,"0",(N12-N11)) -> 3.5 | P12: =O12*1.9*1000 -> 6650 | Q12: 4178.7 | R12: =IF((Q12-Q11)<0,"0",(Q12-Q11)) -> 2.7 | S12: =R12*1.9*1000 -> 5130 | T12: =C12+F12+I12+L12+O12+R12 -> 25 | U12: =T12*1.9*1000 -> 47500
A13: 43719 | B13: 16233.56 | C13: =IF((B13-B12)<0,"0",(B13-B12)) -> 14.26 | D13: =C13*1.9*1000 -> 27094 | E13: 2543.237 | F13: =IF((E13-E12)<0,"0",(E13-E12)) -> 3.437 | G13: =F13*1.9*1000 -> 6530.3 | H13: 73 | I13: =IF((H13-H12)<0,"0",(H13-H12)) -> 0 | J13: =I13*1.9*1000 -> 0 | K13: 12848.06 | L13: =IF((K13-K12)<0,"0",(K13-K12)) -> 0.66 | M13: =L13*1.9*1000 -> 1254 | N13: 2127.57 | O13: =IF((N13-N12)<0,"0",(N13-N12)) -> 3.07 | P13: =O13*1.9*1000 -> 5833 | Q13: 4179.9 | R13: =IF((Q13-Q12)<0,"0",(Q13-Q12)) -> 1.2 | S13: =R13*1.9*1000 -> 2280 | T13: =C13+F13+I13+L13+O13+R13 -> 22.627 | U13: =T13*1.9*1000 -> 42991.3
A14: 43720 | B14: 16247.551 | C14: =IF((B14-B13)<0,"0",(B14-B13)) -> 13.991 | D14: =C14*1.9*1000 -> 26582.9 | E14: 2546.621 | F14: =IF((E14-E13)<0,"0",(E14-E13)) -> 3.384 | G14: =F14*1.9*1000 -> 6429.6 | H14: 73 | I14: =IF((H14-H13)<0,"0",(H14-H13)) -> 0 | J14: =I14*1.9*1000 -> 0 | K14: 12848.73 | L14: =IF((K14-K13)<0,"0",(K14-K13)) -> 0.67 | M14: =L14*1.9*1000 -> 1273 | N14: 2130.202 | O14: =IF((N14-N13)<0,"0",(N14-N13)) -> 2.632 | P14: =O14*1.9*1000 -> 5000.8 | Q14: 4181.16 | R14: =IF((Q14-Q13)<0,"0",(Q14-Q13)) -> 1.26 | S14: =R14*1.9*1000 -> 2394 | T14: =C14+F14+I14+L14+O14+R14 -> 21.937 | U14: =T14*1.9*1000 -> 41680.3
... A32: 43738 | B32: 16476.022 | C32: =IF((B32-B31)<0,"0",(B32-B31)) -> 10.775 | D32: =C32*1.9*1000 -> 20472.5 | E32: 2596.918 | F32: =IF((E32-E31)<0,"0",(E32-E31)) -> 2.689 | G32: =F32*1.9*1000 -> 5109.1 | H32: 74 | I32: =IF((H32-H31)<0,"0",(H32-H31)) -> 0 | J32: =I32*1.9*1000 -> 0 | K32: 12859.44 | L32: =IF((K32-K31)<0,"0",(K32-K31)) -> 0.43 | M32: =L32*1.9*1000 -> 817 | N32: 2180.972 | O32: =IF((N32-N31)<0,"0",(N32-N31)) -> 2.539 | P32: =O32*1.9*1000 -> 4824.1 | Q32: 4229.28 | R32: =IF((Q32-Q31)<0,"0",(Q32-Q31)) -> 2.08 | S32: =R32*1.9*1000 -> 3952 | T32: =C32+F32+I32+L32+O32+R32 -> 18.513 | U32: =T32*1.9*1000 -> 35174.7
B33: 16476.022 | C33: =IF((B33-B32)<0,"0",(B33-B32)) -> 0 | D33: =C33*1.9*1000 -> 0 | E33: 2596.918 | F33: =IF((E33-E32)<0,"0",(E33-E32)) -> 0 | G33: =F33*1.9*1000 -> 0 | H33: 74 | I33: =IF((H33-H32)<0,"0",(H33-H32)) -> 0 | J33: =I33*1.9*1000 -> 0 | K33: 12859.44 | L33: =IF((K33-K32)<0,"0",(K33-K32)) -> 0 | M33: =L33*1.9*1000 -> 0 | N33: 2180.972 | O33: =IF((N33-N32)<0,"0",(N33-N32)) -> 0 | P33: =O33*1.9*1000 -> 0 | Q33: 4229.28 | R33: =IF((Q33-Q32)<0,"0",(Q33-Q32)) -> 0 | S33: =R33*1.9*1000 -> 0 | T33: =C33+F33+I33+L33+O33+R33 -> 0 | U33: =T33*1.9*1000 -> 0
C34: =SUM(C3:C33) -> 426.1396 | D34: =SUM(D3:D33) -> 809665.24 | F34: =SUM(F3:F33) -> 85.342333 | G34: =SUM(G2:G33) -> 169936.63 | I34: =SUM(I3:I33) -> 16 | J34: =SUM(J2:J33) -> 33250 | L34: =SUM(L3:L33) -> 19.64 | M34: =SUM(M2:M33) -> 38912 | O34: =SUM(O3:O33) -> 90.731 | P34: =SUM(P2:P33) -> 178570.55 | R34: =SUM(R3:R33) -> 77.92 | S34: =SUM(S2:S33) -> 152913.9 | T34: =SUM(T2:T33) -> 728.02543 | U34: =SUM(U3:U33) -> 1359968.6

Sheet Plaza and residential
C1: Four Season Nile Plaza | J1: Four Season Nile Plaza
C2: Floor | D2: Type | E2: Acutal till july 2019 | F2: Acutal till August 2019 | G2: Consumption | H2: Note | J2: Floor | K2: Type | L2: Acutal till August 2019 | M2: Acutal till Sept. 2019 | N2: Consumption | O2: Note
C3: 6 | D3: Jade | E3: 254427 | F3: 255218 | G3: =F3-E3 -> 791 | J3: 6 | K3: Jade | L3: 255218 | M3: 256068 | N3: =M3-L3 -> 850
D4: Pearl | E4: 216518 | F4: 216913 | G4: =F4-E4 -> 395 | K4: Pearl | L4: 216913 | M4: 218128 | N4: =M4-L4 -> 1215
D5: Topaz | E5: 171971 | F5: 172378 | G5: =F5-E5 -> 407 | K5: Topaz | L5: 172378 | M5: 173224 | N5: =M5-L5 -> 846
C6: 7 | D6: Jade | E6: 210864 | F6: 212252 | G6: =F6-E6 -> 1388 | J6: 7 | K6: Jade | L6: 212252 | M6: 213444 | N6: =M6-L6 -> 1192
D7: Pearl | E7: 147112 | F7: 147799 | G7: =F7-E7 -> 687 | K7: Pearl | L7: 147799 | M7: 148292 | N7: =M7-L7 -> 493
D8: Topaz | E8: 106082 | F8: 106289 | G8: =F8-E8 -> 207 | K8: Topaz | L8: 106289 | M8: 106817 | N8: =M8-L8 -> 528
C9: 8 | D9: Jade | E9: 68958 | F9: 69141 | G9: =F9-E9 -> 183 | J9: 8 | K9: Jade | L9: 69141 | M9: 69333 | N9: =M9-L9 -> 192
D10: Pearl | E10: 158 | F10: 158 | G10: =F10-E10 -> 0 | K10: Pearl | L10: 158 | M10: 158 | N10: =M10-L10 -> 0
D11: Topaz | E11: 80836 | F11: 81969 | G11: =F11-E11 -> 1133 | K11: Topaz | L11: 81969 | M11: 82891 | N11: =M11-L11 -> 922
C12: 9 | D12: Jade | E12: 33656 | F12: 33672 | G12: =F12-E12 -> 16 | J12: 9 | K12: Jade | L12: 33672 | M12: 33737 | N12: =M12-L12 -> 65
D13: Pearl | E13: 0 | F13: 0 | G13: =F13-E13 -> 0 | K13: Pearl | L13: 0 | M13: 0 | N13: =M13-L13 -> 0
D14: Topaz | E14: 26903 | F14: 36984 | G14: =F14-E14 -> 10081 | K14: Topaz | L14: 36984 | M14: 37062 | N14: =M14-L14 -> 78
C15: 10 | D15: Jade | E15: 151919 | F15: 153526 | G15: =F15-E15 -> 1607 | J15: 10 | K15: Jade | L15: 153526 | M15: 155173 | N15: =M15-L15 -> 1647
D16: Pearl | E16: 7603 | F16: 7703 | G16: =F16-E16 -> 100 | K16: Pearl | L16: 7703 | M16: 7703 | N16: =M16-L16 -> 0
D17: Topaz | E17: 144877 | F17: 147546 | G17: =F17-E17 -> 2669 | K17: Topaz | L17: 147546 | M17: 150171 | N17: =M17-L17 -> 2625
C18: 11 | D18: Jade | E18: 61207 | F18: 61269 | G18: =F18-E18 -> 62 | J18: 11 | K18: Jade | L18: 61269 | M18: 61321 | N18: =M18-L18 -> 52
D19: Pearl | E19: 185440 | F19: 186134 | G19: =F19-E19 -> 694 | K19: Pearl | L19: 186134 | M19: 186812 | N19: =M19-L19 -> 678
D20: Topaz | E20: 26127 | F20: 29534 | G20: =F20-E20 -> 3407 | H20: There was mistake in the reading last month | K20: Topaz | L20: 29534 | M20: 29584 | N20: =M20-L20 -> 50
C21: 12 | D21: Jade | E21: 143713 | F21: 143713 | G21: =F21-E21 -> 0 | J21: 12 | K21: Jade | L21: 143713 | M21: 143806 | N21: =M21-L21 -> 93
D22: Pearl | E22: 18385 | F22: 18801 | G22: =F22-E22 -> 416 | K22: Pearl | L22: 18801 | M22: 19992 | N22: =M22-L22 -> 1191
D23: Topaz | E23: 206127 | F23: 206891 | G23: =F23-E23 -> 764 | K23: Topaz | L23: 206891 | M23: 208088 | N23: =M23-L23 -> 1197
C24: 14 | D24: Jade | E24: 110784 | F24: 111048 | G24: =F24-E24 -> 264 | J24: 14 | K24: Jade | L24: 111048 | M24: 111309 | N24: =M24-L24 -> 261
D25: Pearl | E25: 21842 | F25: 23136 | G25: =F25-E25 -> 1294 | K25: Pearl | L25: 23136 | M25: 23136 | N25: =M25-L25 -> 0
D26: Topaz | E26: 1062 | F26: 1071 | G26: =F26-E26 -> 9 | K26: Topaz | L26: 1071 | M26: 1098 | N26: =M26-L26 -> 27
C27: 15 | D27: Jade | E27: 39008 | F27: 39008 | G27: =F27-E27 -> 0 | J27: 15 | K27: Jade | L27: 39008 | M27: 39008 | N27: =M27-L27 -> 0
D28: Pearl | E28: 71323 | F28: 71843 | G28: =F28-E28 -> 520 | K28: Pearl | L28: 71843 | M28: 72273 | N28: =M28-L28 -> 430
D29: Topaz | E29: 134465 | F29: 135395 | G29: =F29-E29 -> 930 | K29: Topaz | L29: 135395 | M29: 136221 | N29: =M29-L29 -> 826
C30: 16 | D30: Jade | E30: 94962 | F30: 95569 | G30: =F30-E30 -> 607 | J30: 16 | K30: Jade | L30: 95569 | M30: 95569 | N30: =M30-L30 -> 0
D31: Pearl | E31: 52511 | F31: 52831 | G31: =F31-E31 -> 320 | K31: Pearl | L31: 52831 | M31: 53313 | N31: =M31-L31 -> 482
D32: Topaz | E32: 67444 | F32: 67444 | G32: =F32-E32 -> 0 | K32: Topaz | L32: 67444 | M32: 67672 | N32: =M32-L32 -> 228
C33: 17 | D33: Jade | E33: 22368 | F33: 23220 | G33: =F33-E33 -> 852 | J33: 17 | K33: Jade | L33: 23220 | M33: 23623 | N33: =M33-L33 -> 403
D34: Pearl | E34: 63576 | F34: 63627 | G34: =F34-E34 -> 51 | K34: Pearl | L34: 63627 | M34: 63673 | N34: =M34-L34 -> 46
D35: Topaz | E35: 11163 | F35: 11163 | G35: =F35-E35 -> 0 | K35: Topaz | L35: 11163 | M35: 11164 | N35: =M35-L35 -> 1
C36: 18 | D36: Jade | E36: 209368 | F36: 210533 | G36: =F36-E36 -> 1165 | J36: 18 | K36: Jade | L36: 210533 | M36: 211282 | N36: =M36-L36 -> 749
D37: Pearl | E37: 15712 | F37: 15712 | G37: =F37-E37 -> 0 | K37: Pearl | L37: 15712 | M37: 15712 | N37: =M37-L37 -> 0
D38: Topaz | E38: 62066 | F38: 62105 | G38: =F38-E38 -> 39 | K38: Topaz | L38: 62105 | M38: 62108 | N38: =M38-L38 -> 3
C39: 19 | D39: Jade | E39: 16400 | F39: 16670 | G39: =F39-E39 -> 270 | J39: 19 | K39: Jade | L39: 16670 | M39: 16951 | N39: =M39-L39 -> 281
D40: Pearl | E40: 77963 | F40: 78218 | G40: =F40-E40 -> 255 | K40: Pearl | L40: 78218 | M40: 78415 | N40: =M40-L40 -> 197
...

Sheet Energy Monthly Statement
A1: Energy Monthly Statement Sep . 2019
B2: Plant room | C2: =K8+K9+K14 -> 798953 | D2: =C2*1.15 -> 918795.95 | H2: Electric
H3: Feeder 1 | I3: =ELECT.!E3 -> 18643308 | J3: =ELECT.!E34 -> 19193711 | K3: =J3-I3 -> 550403
B4: With out Plant room | C4: Kwh | D4: LE | H4: Feeder 2 | I4: =ELECT.!G3 -> 52775188 | J4: =ELECT.!G34 -> 54582537 | K4: =J4-I4 -> 1807349
B5: Hotel | C5: =(K10+K12)*0.842284+K26 -> 1027652 | D5: =C5*1.27 -> 1305118 | H5: Total | K5: =K3+K4 -> 2357752
B6: Plaza | C6: =(K10+K12+K26)*0.1488 -> 180633.68 | D6: =C6*1.27 -> 229404.77 | H6: Tr1 | I6: =ELECT.!J3 -> 4613370 | J6: =ELECT.!J34 -> 4800570 | K6: =J6-I6 -> 187200
B7: Large s. | C7: =(K6+K7)-(C8+C9+C10+C11+K26) -> 302909 | D7: =C7*1.27 -> 384694.43 | H7: Tr2 | I7: =ELECT.!L3 -> 4926113 | J7: =ELECT.!L34 -> 5116576 | K7: =J7-I7 -> 190463
B8: Mall | C8: =K21+K22+K23+K24 -> 36737 | D8: =C8*1.27 -> 46655.99 | H8: Tr3 | I8: =ELECT.!N3 -> 3095086 | J8: =ELECT.!N34 -> 3272510 | K8: =(J8-I8)*2 -> 354848
B9: Rotana | C9: =K25 -> 97 | D9: =C9*1.27 -> 123.19 | H9: Tr4 | I9: =ELECT.!P3 -> 7372585 | J9: =ELECT.!P34 -> 7772441 | K9: =J9-I9 -> 399856
B10: Citadle | C10: =K17+K18 -> 119 | D10: =C10*1.27 -> 151.13 | H10: Tr5 | I10: =ELECT.!R3 -> 11582143 | J10: =ELECT.!R34 -> 11930963 | K10: =J10-I10 -> 348820
B11: CIB Bank | C11: =K19+K20 -> 5001 | D11: =C11*1.27 -> 6351.27 | H11: Tr6 | I11: 0 | J11: 0 | K11: =J11-I11 -> 0
H12: Tr7 | I12: =ELECT.!V3 -> 8349237 | J12: =ELECT.!V34 -> 8765395 | K12: =(J12-I12)*2 -> 832316
B13: Water | C13: M3 | D13: LE | H13: Total | K13: =SUM(K6:K12) -> 2313503
B14: Main | C14: =K29 -> 32410 | D14: =C14*10.03 -> 325072.3 | H14: loss | K14: =K5-K13 -> 44249
B15: Large suite | C15: =K30 -> 170.505 | D15: =C15*10.03 -> 1710.1651
B16: Plaza | C16: =(C14-C15-C18-C19-C20-C21)*0.1318 -> 3669.2454 | D16: =C16*10.03 -> 36802.532
B17: Mall | C17: 1420 | D17: =C17*10.03 -> 14242.6 | H17: RO1 | I17: ='Mall, Citadel, Rotana'!J3 -> 303517 | J17: ='Mall, Citadel, Rotana'!J34 -> 303517 | K17: =J17-I17 -> 0
B18: CIB Bank | C18: 200 | D18: =C18*10.03 -> 2006 | H18: RO2 | I18: ='Mall, Citadel, Rotana'!L3 -> 22637 | J18: ='Mall, Citadel, Rotana'!L34 -> 22756 | K18: =J18-I18 -> 119
