Workbook

Sheet TOTAL
A1: Site Name | B1: Day | C1: Month | D1: Year | E1: Total Electricity Kwh | F1: Electricity Tariff ($/Kwh) | G1: Natual Gas (m3) | H1: Natural Gas $/m3 | I1: Water Utility Supply (m3) m3 | J1: Water Utility Supply (m3) $/m3 | K1: Room Nights | L1: Total Guests
A2: London at Park Lane | B2: 1 | C2: 2 | D2: 2020 | E2: =Submetering!E2+Submetering!F2+Submetering!G2 -> 17693 | F2: 0.10888583 | G2: =Submetering!AC2-Submetering!AD2 -> 968 | H2: 0.255129 | I2: =Submetering!Y2+Submetering!Z2 -> 4447 | J2: 2.3196173 | K2: =Submetering!AE2 -> 11 | L2: =Submetering!AF2 -> 152
A3: London at Park Lane | B3: =B2+1 -> 2 | C3: 2 | D3: 2020 | E3: =Submetering!E3+Submetering!F3+Submetering!G3 -> 16915 | F3: 0.10888583 | G3: =Submetering!AC3-Submetering!AD3 -> 984 | H3: 0.255129 | I3: =Submetering!Y3+Submetering!Z3 -> 0 | J3: 2.3196173 | K3: =Submetering!AE3 -> 123 | L3: =Submetering!AF3 -> 154
A4: London at Park Lane | B4: =B3+1 -> 3 | C4: 2 | D4: 2020 | E4: =Submetering!E4+Submetering!F4+Submetering!G4 -> 16211 | F4: 0.10888583 | G4: =Submetering!AC4-Submetering!AD4 -> 950 | H4: 0.255129 | I4: =Submetering!Y4+Submetering!Z4 -> 0 | J4: 2.3196173 | K4: =Submetering!AE4 -> 134 | L4: =Submetering!AF4 -> 170
A5: London at Park Lane | B5: =B4+1 -> 4 | C5: 2 | D5: 2020 | E5: =Submetering!E5+Submetering!F5+Submetering!G5 -> 17684 | F5: 0.10888583 | G5: =Submetering!AC5-Submetering!AD5 -> 1166 | H5: 0.255129 | I5: =Submetering!Y5+Submetering!Z5 -> 0 | J5: 2.3196173 | K5: =Submetering!AE5 -> 145 | L5: =Submetering!AF5 -> 192
A6: London at Park Lane | B6: =B5+1 -> 5 | C6: 2 | D6: 2020 | E6: =Submetering!E6+Submetering!F6+Submetering!G6 -> 17630 | F6: 0.10888583 | G6: =Submetering!AC6-Submetering!AD6 -> 1122 | H6: 0.255129 | I6: =Submetering!Y6+Submetering!Z6 -> 0 | J6: 2.3196173 | K6: =Submetering!AE6 -> 138 | L6: =Submetering!AF6 -> 187
A7: London at Park Lane | B7: =B6+1 -> 6 | C7: 2 | D7: 2020 | E7: =Submetering!E7+Submetering!F7+Submetering!G7 -> 17285 | F7: 0.10888583 | G7: =Submetering!AC7-Submetering!AD7 -> 1511 | H7: 0.255129 | I7: =Submetering!Y7+Submetering!Z7 -> 0 | J7: 2.3196173 | K7: =Submetering!AE7 -> 131 | L7: =Submetering!AF7 -> 175
A8: London at Park Lane | B8: =B7+1 -> 7 | C8: 2 | D8: 2020 | E8: =Submetering!E8+Submetering!F8+Submetering!G8 -> 17438 | F8: 0.10888583 | G8: =Submetering!AC8-Submetering!AD8 -> 1309 | H8: 0.255129 | I8: =Submetering!Y8+Submetering!Z8 -> 0 | J8: 2.3196173 | K8: =Submetering!AE8 -> 114 | L8: =Submetering!AF8 -> 160
A9: London at Park Lane | B9: =B8+1 -> 8 | C9: 2 | D9: 2020 | E9: =Submetering!E9+Submetering!F9+Submetering!G9 -> 16757 | F9: 0.10888583 | G9: =Submetering!AC9-Submetering!AD9 -> 1191 | H9: 0.255129 | I9: =Submetering!Y9+Submetering!Z9 -> 0 | J9: 2.3196173 | K9: =Submetering!AE9 -> 123 | L9: =Submetering!AF9 -> 173
A10: London at Park Lane | B10: =B9+1 -> 9 | C10: 2 | D10: 2020 | E10: =Submetering!E10+Submetering!F10+Submetering!G10 -> 16611 | F10: 0.10888583 | G10: =Submetering!AC10-Submetering!AD10 -> 1124 | H10: 0.255129 | I10: =Submetering!Y10+Submetering!Z10 -> 0 | J10: 2.3196173 | K10: =Submetering!AE10 -> 102 | L10: =Submetering!AF10 -> 137
A11: London at Park Lane | B11: =B10+1 -> 10 | C11: 2 | D11: 2020 | E11: =Submetering!E11+Submetering!F11+Submetering!G11 -> 16970 | F11: 0.10888583 | G11: =Submetering!AC11-Submetering!AD11 -> 1049 | H11: 0.255129 | I11: =Submetering!Y11+Submetering!Z11 -> 739 | J11: 2.3196173 | K11: =Submetering!AE11 -> 110 | L11: =Submetering!AF11 -> 139
A12: London at Park Lane | B12: =B11+1 -> 11 | C12: 2 | D12: 2020 | E12: =Submetering!E12+Submetering!F12+Submetering!G12 -> 16036 | F12: 0.10888583 | G12: =Submetering!AC12-Submetering!AD12 -> 1132 | H12: 0.255129 | I12: =Submetering!Y12+Submetering!Z12 -> 0 | J12: 2.3196173 | K12: =Submetering!AE12 -> 129 | L12: =Submetering!AF12 -> 163
A13: London at Park Lane | B13: =B12+1 -> 12 | C13: 2 | D13: 2020 | E13: =Submetering!E13+Submetering!F13+Submetering!G13 -> 16154 | F13: 0.10888583 | G13: =Submetering!AC13-Submetering!AD13 -> 1153 | H13: 0.255129 | I13: =Submetering!Y13+Submetering!Z13 -> 0 | J13: 2.3196173 | K13: =Submetering!AE13 -> 136 | L13: =Submetering!AF13 -> 174
A14: London at Park Lane | B14: =B13+1 -> 13 | C14: 2 | D14: 2020 | E14: =Submetering!E14+Submetering!F14+Submetering!G14 -> 16666 | F14: 0.10888583 | G14: =Submetering!AC14-Submetering!AD14 -> 1159 | H14: 0.255129 | I14: =Submetering!Y14+Submetering!Z14 -> 0 | J14: 2.3196173 | K14: =Submetering!AE14 -> 121 | L14: =Submetering!AF14 -> 166
... A30: London at Park Lane | B30: =B29+1 -> 29 | C30: 2 | D30: 2020 | E30: =Submetering!E30+Submetering!F30+Submetering!G30 -> 0 | F30: 0.10888583 | G30: =Submetering!AC30-Submetering!AD30 -> 0 | H30: 0.255129 | I30: =Submetering!Y30+Submetering!Z30 -> 0 | J30: 2.3196173 | K30: =Submetering!AE30 -> 0 | L30: =Submetering!AF30 -> 0
A31: London at Park Lane | D31: 2020 | E31: =Submetering!E31+Submetering!F31+Submetering!G31 -> 0 | F31: 0.10888583 | G31: =Submetering!AC31-Submetering!AD31 -> 0 | H31: 0.255129 | I31: =Submetering!Y31+Submetering!Z31 -> 0 | J31: 2.3196173 | K31: =Submetering!AE31 -> 0 | L31: =Submetering!AF31 -> 0
A32: London at Park Lane | D32: 2020 | E32: =Submetering!E32+Submetering!F32+Submetering!G32 -> 0 | F32: 0.10888583 | G32: =Submetering!AC32-Submetering!AD32 -> 0 | H32: 0.255129 | I32: =Submetering!Y32+Submetering!Z32 -> 0 | J32: 2.3196173 | K32: =Submetering!AE32 -> 0 | L32: =Submetering!AF32 -> 0

Sheet Submetering
A1: Site Name | B1: Day | C1: Month | D1: Year | E1: LV Panel 1 KWh | F1: LV Panel 2 KWh | G1: CHP KWh | H1: MCC9 KWh | I1: GF Panel KWh | J1: Kitchen Switch. KWh | K1: Kitchen Panel KWh | L1: MCC3 (AHU) KWh | M1: MCC8 KWh | N1: 1st Floor Plan (KWh) | O1: MCC6(1st floor AHU) KWh | P1: Chiller 1 KWh | Q1: Chiller 2 KWh | R1: MCC 10 (Mechanical Services) KWh | S1: MCC2 CHW KWh | T1: MCC7 (Kitchen) KWh | U1: MCC 5 (Mechanical services) KWh | V1: MCC 4 (Water Services) KWh | W1: MCC1 (KWh) | X1: Laundry db KWh | Y1: City Water 1 m3 | Z1: City Water 2 m3 | AA1: Laundry CW m3 | AB1: Laundry HW m3 | AC1: Natural Gas m3 | AD1: CHP Natural Gas m3 | AE1: Room Nights | AF1: Total Guests
A2: London at Park Lane | B2: 1 | C2: 2 | D2: 2020 | E2: =IF(('FSLPL Daily '!C4-'FSLPL Daily '!C3<0), "0",'FSLPL Daily '!C4-'FSLPL Daily '!C3) -> 7921 | F2: =IF(('FSLPL Daily '!E4-'FSLPL Daily '!E3<0), "0",'FSLPL Daily '!E4-'FSLPL Daily '!E3) -> 5781 | G2: =IF(('FSLPL Daily '!G4-'FSLPL Daily '!G3<0), "0",'FSLPL Daily '!G4-'FSLPL Daily '!G3) -> 3991 | H2: =IF(('FSLPL Daily '!I4-'FSLPL Daily '!I3<0), "0",'FSLPL Daily '!I4-'FSLPL Daily '!I3) -> 474 | I2: =IF(('FSLPL Daily '!K4-'FSLPL Daily '!K3<0), "0",'FSLPL Daily '!K4-'FSLPL Daily '!K3) -> 842 | J2: =IF(('FSLPL Daily '!M4-'FSLPL Daily '!M3<0), "0",'FSLPL Daily '!M4-'FSLPL Daily '!M3) -> 1310 | K2: =IF(('FSLPL Daily '!O4-'FSLPL Daily '!O3<0), "0",'FSLPL Daily '!O4-'FSLPL Daily '!O3) -> 586 | L2: =IF(('FSLPL Daily '!Q4-'FSLPL Daily '!Q3<0), "0",'FSLPL Daily '!Q4-'FSLPL Daily '!Q3) -> 364 | M2: =IF(('FSLPL Daily '!S4-'FSLPL Daily '!S3<0), "0",'FSLPL Daily '!S4-'FSLPL Daily '!S3) -> 87 | N2: =IF(('FSLPL Daily '!U4-'FSLPL Daily '!U3<0), "0",'FSLPL Daily '!U4-'FSLPL Daily '!U3) -> 995 | O2: =IF(('FSLPL Daily '!W4-'FSLPL Daily '!W3<0), "0",'FSLPL Daily '!W4-'FSLPL Daily '!W3) -> 153 | P2: =IF(('FSLPL Daily '!Y4-'FSLPL Daily '!Y3<0), "0",'FSLPL Daily '!Y4-'FSLPL Daily '!Y3) -> 1250 | Q2: =IF(('FSLPL Daily '!AA4-'FSLPL Daily '!AA3<0), "0",'FSLPL Daily '!AA4-'FSLPL Daily '!AA3) -> 2 | R2: =IF(('FSLPL Daily '!AC4-'FSLPL Daily '!AC3<0), "0",'FSLPL Daily '!AC4-'FSLPL Daily '!AC3) -> 1447 | S2: =IF(('FSLPL Daily '!AE4-'FSLPL Daily '!AE3<0), "0",'FSLPL Daily '!AE4-'FSLPL Daily '!AE3) -> 1954 | T2: =IF(('FSLPL Daily '!AG4-'FSLPL Daily '!AG3<0), "0",'FSLPL Daily '!AG4-'FSLPL Daily '!AG3) -> 263 | U2: =IF(('FSLPL Daily '!AI4-'FSLPL Daily '!AI3<0), "0",'FSLPL Daily '!AI4-'FSLPL Daily '!AI3) -> 76 | V2: =IF(('FSLPL Daily '!AK4-'FSLPL Daily '!AK3<0), "0",'FSLPL Daily '!AK4-'FSLPL Daily '!AK3) -> 353 | W2: =IF(('FSLPL Daily '!AM4-'FSLPL Daily '!AM3<0), "0",'FSLPL Daily '!AM4-'FSLPL Daily '!AM3) -> 576 | X2: =IF(('FSLPL Daily '!AO4-'FSLPL Daily '!AO3<0), "0",'FSLPL Daily '!AO4-'FSLPL Daily '!AO3) -> 827 | Y2: ='FSLPL Daily '!AS4 -> 3419 | Z2: ='FSLPL Daily '!AU4 -> 1028 | AA2: =IF(('FSLPL Daily '!AV4-'FSLPL Daily '!AV3<0), "0",'FSLPL Daily '!AV4-'FSLPL Daily '!AV3) -> 23 | AB2: =IF(('FSLPL Daily '!AX4-'FSLPL Daily '!AX3<0), "0",'FSLPL Daily '!AX4-'FSLPL Daily '!AX3) -> 3 | AC2: =IF(('FSLPL Daily '!AZ4-'FSLPL Daily '!AZ3<0), "0",'FSLPL Daily '!AZ4-'FSLPL Daily '!AZ3) -> 2117 | AD2: =IF(('FSLPL Daily '!BB4-'FSLPL Daily '!BB3<0), "0",'FSLPL Daily '!BB4-'FSLPL Daily '!BB3) -> 1149 | AE2: ='FSLPL Daily '!BD4 -> 11 | AF2: ='FSLPL Daily '!BE4 -> 152
A3: London at Park Lane | B3: =B2+1 -> 2 | C3: 2 | D3: 2020 | E3: =IF(('FSLPL Daily '!C5-'FSLPL Daily '!C4<0), "0",'FSLPL Daily '!C5-'FSLPL Daily '!C4) -> 7565 | F3: =IF(('FSLPL Daily '!E5-'FSLPL Daily '!E4<0), "0",'FSLPL Daily '!E5-'FSLPL Daily '!E4) -> 5486 | G3: =IF(('FSLPL Daily '!G5-'FSLPL Daily '!G4<0), "0",'FSLPL Daily '!G5-'FSLPL Daily '!G4) -> 3864 | H3: =IF(('FSLPL Daily '!I5-'FSLPL Daily '!I4<0), "0",'FSLPL Daily '!I5-'FSLPL Daily '!I4) -> 489 | I3: =IF(('FSLPL Daily '!K5-'FSLPL Daily '!K4<0), "0",'FSLPL Daily '!K5-'FSLPL Daily '!K4) -> 790 | J3: =IF(('FSLPL Daily '!M5-'FSLPL Daily '!M4<0), "0",'FSLPL Daily '!M5-'FSLPL Daily '!M4) -> 1366 | K3: =IF(('FSLPL Daily '!O5-'FSLPL Daily '!O4<0), "0",'FSLPL Daily '!O5-'FSLPL Daily '!O4) -> 606 | L3: =IF(('FSLPL Daily '!Q5-'FSLPL Daily '!Q4<0), "0",'FSLPL Daily '!Q5-'FSLPL Daily '!Q4) -> 347 | M3: =IF(('FSLPL Daily '!S5-'FSLPL Daily '!S4<0), "0",'FSLPL Daily '!S5-'FSLPL Daily '!S4) -> 84 | N3: =IF(('FSLPL Daily '!U5-'FSLPL Daily '!U4<0), "0",'FSLPL Daily '!U5-'FSLPL Daily '!U4) -> 935 | O3: =IF(('FSLPL Daily '!W5-'FSLPL Daily '!W4<0), "0",'FSLPL Daily '!W5-'FSLPL Daily '!W4) -> 195 | P3: =IF(('FSLPL Daily '!Y5-'FSLPL Daily '!Y4<0), "0",'FSLPL Daily '!Y5-'FSLPL Daily '!Y4) -> 990 | Q3: =IF(('FSLPL Daily '!AA5-'FSLPL Daily '!AA4<0), "0",'FSLPL Daily '!AA5-'FSLPL Daily '!AA4) -> 3 | R3: =IF(('FSLPL Daily '!AC5-'FSLPL Daily '!AC4<0), "0",'FSLPL Daily '!AC5-'FSLPL Daily '!AC4) -> 1410 | S3: =IF(('FSLPL Daily '!AE5-'FSLPL Daily '!AE4<0), "0",'FSLPL Daily '!AE5-'FSLPL Daily '!AE4) -> 1835 | T3: =IF(('FSLPL Daily '!AG5-'FSLPL Daily '!AG4<0), "0",'FSLPL Daily '!AG5-'FSLPL Daily '!AG4) -> 231 | U3: =IF(('FSLPL Daily '!AI5-'FSLPL Daily '!AI4<0), "0",'FSLPL Daily '!AI5-'FSLPL Daily '!AI4) -> 74 | V3: =IF(('FSLPL Daily '!AK5-'FSLPL Daily '!AK4<0), "0",'FSLPL Daily '!AK5-'FSLPL Daily '!AK4) -> 327 | W3: =IF(('FSLPL Daily '!AM5-'FSLPL Daily '!AM4<0), "0",'FSLPL Daily '!AM5-'FSLPL Daily '!AM4) -> 578 | X3: =IF(('FSLPL Daily '!AO5-'FSLPL Daily '!AO4<0), "0",'FSLPL Daily '!AO5-'FSLPL Daily '!AO4) -> 847 | Y3: ='FSLPL Daily '!AS5 -> 0 | Z3: ='FSLPL Daily '!AU5 -> 0 | AA3: =IF(('FSLPL Daily '!AV5-'FSLPL Daily '!AV4<0), "0",'FSLPL Daily '!AV5-'FSLPL Daily '!AV4) -> 23 | AB3: =IF(('FSLPL Daily '!AX5-'FSLPL Daily '!AX4<0), "0",'FSLPL Daily '!AX5-'FSLPL Daily '!AX4) -> 2 | AC3: =IF(('FSLPL Daily '!AZ5-'FSLPL Daily '!AZ4<0), "0",'FSLPL Daily '!AZ5-'FSLPL Daily '!AZ4) -> 2095 | AD3: =IF(('FSLPL Daily '!BB5-'FSLPL Daily '!BB4<0), "0",'FSLPL Daily '!BB5-'FSLPL Daily '!BB4) -> 1111 | AE3: ='FSLPL Daily '!BD5 -> 123 | AF3: ='FSLPL Daily '!BE5 -> 154
A4: London at Park Lane | B4: =B3+1 -> 3 | C4: 2 | D4: 2020 | E4: =IF(('FSLPL Daily '!C6-'FSLPL Daily '!C5<0), "0",'FSLPL Daily '!C6-'FSLPL Daily '!C5) -> 7087 | F4: =IF(('FSLPL Daily '!E6-'FSLPL Daily '!E5<0), "0",'FSLPL Daily '!E6-'FSLPL Daily '!E5) -> 5324 | G4: =IF(('FSLPL Daily '!G6-'FSLPL Daily '!G5<0), "0",'FSLPL Daily '!G6-'FSLPL Daily '!G5) -> 3800 | H4: =IF(('FSLPL Daily '!I6-'FSLPL Daily '!I5<0), "0",'FSLPL Daily '!I6-'FSLPL Daily '!I5) -> 476 | I4: =IF(('FSLPL Daily '!K6-'FSLPL Daily '!K5<0), "0",'FSLPL Daily '!K6-'FSLPL Daily '!K5) -> 777 | J4: =IF(('FSLPL Daily '!M6-'FSLPL Daily '!M5<0), "0",'FSLPL Daily '!M6-'FSLPL Daily '!M5) -> 1216 | K4: =IF(('FSLPL Daily '!O6-'FSLPL Daily '!O5<0), "0",'FSLPL Daily '!O6-'FSLPL Daily '!O5) -> 562 | L4: =IF(('FSLPL Daily '!Q6-'FSLPL Daily '!Q5<0), "0",'FSLPL Daily '!Q6-'FSLPL Daily '!Q5) -> 339 | M4: =IF(('FSLPL Daily '!S6-'FSLPL Daily '!S5<0), "0",'FSLPL Daily '!S6-'FSLPL Daily '!S5) -> 82 | N4: =IF(('FSLPL Daily '!U6-'FSLPL Daily '!U5<0), "0",'FSLPL Daily '!U6-'FSLPL Daily '!U5) -> 770 | O4: =IF(('FSLPL Daily '!W6-'FSLPL Daily '!W5<0), "0",'FSLPL Daily '!W6-'FSLPL Daily '!W5) -> 100 | P4: =IF(('FSLPL Daily '!Y6-'FSLPL Daily '!Y5<0), "0",'FSLPL Daily '!Y6-'FSLPL Daily '!Y5) -> 1067 | Q4: =IF(('FSLPL Daily '!AA6-'FSLPL Daily '!AA5<0), "0",'FSLPL Daily '!AA6-'FSLPL Daily '!AA5) -> 2 | R4: =IF(('FSLPL Daily '!AC6-'FSLPL Daily '!AC5<0), "0",'FSLPL Daily '!AC6-'FSLPL Daily '!AC5) -> 1384 | S4: =IF(('FSLPL Daily '!AE6-'FSLPL Daily '!AE5<0), "0",'FSLPL Daily '!AE6-'FSLPL Daily '!AE5) -> 1781 | T4: =IF(('FSLPL Daily '!AG6-'FSLPL Daily '!AG5<0), "0",'FSLPL Daily '!AG6-'FSLPL Daily '!AG5) -> 230 | U4: =IF(('FSLPL Daily '!AI6-'FSLPL Daily '!AI5<0), "0",'FSLPL Daily '!AI6-'FSLPL Daily '!AI5) -> 73 | V4: =IF(('FSLPL Daily '!AK6-'FSLPL Daily '!AK5<0), "0",'FSLPL Daily '!AK6-'FSLPL Daily '!AK5) -> 329 | W4: =IF(('FSLPL Daily '!AM6-'FSLPL Daily '!AM5<0), "0",'FSLPL Daily '!AM6-'FSLPL Daily '!AM5) -> 562 | X4: =IF(('FSLPL Daily '!AO6-'FSLPL Daily '!AO5<0), "0",'FSLPL Daily '!AO6-'FSLPL Daily '!AO5) -> 755 | Y4: ='FSLPL Daily '!AS6 -> 0 | Z4: ='FSLPL Daily '!AU6 -> 0 | AA4: =IF(('FSLPL Daily '!AV6-'FSLPL Daily '!AV5<0), "0",'FSLPL Daily '!AV6-'FSLPL Daily '!AV5) -> 18 | AB4: =IF(('FSLPL Daily '!AX6-'FSLPL Daily '!AX5<0), "0",'FSLPL Daily '!AX6-'FSLPL Daily '!AX5) -> 2 | AC4: =IF(('FSLPL Daily '!AZ6-'FSLPL Daily '!AZ5<0), "0",'FSLPL Daily '!AZ6-'FSLPL Daily '!AZ5) -> 2041 | AD4: =IF(('FSLPL Daily '!BB6-'FSLPL Daily '!BB5<0), "0",'FSLPL Daily '!BB6-'FSLPL Daily '!BB5) -> 1091 | AE4: ='FSLPL Daily '!BD6 -> 134 | AF4: ='FSLPL Daily '!BE6 -> 170
A5: London at Park Lane | B5: =B4+1 -> 4 | C5: 2 | D5: 2020 | E5: =IF(('FSLPL Daily '!C7-'FSLPL Daily '!C6<0), "0",'FSLPL Daily '!C7-'FSLPL Daily '!C6) -> 8056 | F5: =IF(('FSLPL Daily '!E7-'FSLPL Daily '!E6<0), "0",'FSLPL Daily '!E7-'FSLPL Daily '!E6) -> 5605 | G5: =IF(('FSLPL Daily '!G7-'FSLPL Daily '!G6<0), "0",'FSLPL Daily '!G7-'FSLPL Daily '!G6) -> 4023 | H5: =IF(('FSLPL Daily '!I7-'FSLPL Daily '!I6<0), "0",'FSLPL Daily '!I7-'FSLPL Daily '!I6) -> 606 | I5: =IF(('FSLPL Daily '!K7-'FSLPL Daily '!K6<0), "0",'FSLPL Daily '!K7-'FSLPL Daily '!K6) -> 831 | J5: =IF(('FSLPL Daily '!M7-'FSLPL Daily '!M6<0), "0",'FSLPL Daily '!M7-'FSLPL Daily '!M6) -> 1367 | K5: =IF(('FSLPL Daily '!O7-'FSLPL Daily '!O6<0), "0",'FSLPL Daily '!O7-'FSLPL Daily '!O6) -> 613 | L5: =IF(('FSLPL Daily '!Q7-'FSLPL Daily '!Q6<0), "0",'FSLPL Daily '!Q7-'FSLPL Daily '!Q6) -> 355 | M5: =IF(('FSLPL Daily '!S7-'FSLPL Daily '!S6<0), "0",'FSLPL Daily '!S7-'FSLPL Daily '!S6) -> 87 | N5: =IF(('FSLPL Daily '!U7-'FSLPL Daily '!U6<0), "0",'FSLPL Daily '!U7-'FSLPL Daily '!U6) -> 1122 | O5: =IF(('FSLPL Daily '!W7-'FSLPL Daily '!W6<0), "0",'FSLPL Daily '!W7-'FSLPL Daily '!W6) -> 254 | P5: =IF(('FSLPL Daily '!Y7-'FSLPL Daily '!Y6<0), "0",'FSLPL Daily '!Y7-'FSLPL Daily '!Y6) -> 1071 | Q5: =IF(('FSLPL Daily '!AA7-'FSLPL Daily '!AA6<0), "0",'FSLPL Daily '!AA7-'FSLPL Daily '!AA6) -> 2 | R5: =IF(('FSLPL Daily '!AC7-'FSLPL Daily '!AC6<0), "0",'FSLPL Daily '!AC7-'FSLPL Daily '!AC6) -> 1468 | S5: =IF(('FSLPL Daily '!AE7-'FSLPL Daily '!AE6<0), "0",'FSLPL Daily '!AE7-'FSLPL Daily '!AE6) -> 1878 | T5: =IF(('FSLPL Daily '!AG7-'FSLPL Daily '!AG6<0), "0",'FSLPL Daily '!AG7-'FSLPL Daily '!AG6) -> 253 | U5: =IF(('FSLPL Daily '!AI7-'FSLPL Daily '!AI6<0), "0",'FSLPL Daily '!AI7-'FSLPL Daily '!AI6) -> 76 | V5: =IF(('FSLPL Daily '!AK7-'FSLPL Daily '!AK6<0), "0",'FSLPL Daily '!AK7-'FSLPL Daily '!AK6) -> 376 | W5: =IF(('FSLPL Daily '!AM7-'FSLPL Daily '!AM6<0), "0",'FSLPL Daily '!AM7-'FSLPL Daily '!AM6) -> 592 | X5: =IF(('FSLPL Daily '!AO7-'FSLPL Daily '!AO6<0), "0",'FSLPL Daily '!AO7-'FSLPL Daily '!AO6) -> 688 | Y5: ='FSLPL Daily '!AS7 -> 0 | Z5: ='FSLPL Daily '!AU7 -> 0 | AA5: =IF(('FSLPL Daily '!AV7-'FSLPL Daily '!AV6<0), "0",'FSLPL Daily '!AV7-'FSLPL Daily '!AV6) -> 19 | AB5: =IF(('FSLPL Daily '!AX7-'FSLPL Daily '!AX6<0), "0",'FSLPL Daily '!AX7-'FSLPL Daily '!AX6) -> 5 | AC5: =IF(('FSLPL Daily '!AZ7-'FSLPL Daily '!AZ6<0), "0",'FSLPL Daily '!AZ7-'FSLPL Daily '!AZ6) -> 2310 | AD5: =IF(('FSLPL Daily '!BB7-'FSLPL Daily '!BB6<0), "0",'FSLPL Daily '!BB7-'FSLPL Daily '!BB6) -> 1144 | AE5: ='FSLPL Daily '!BD7 -> 145 | AF5: ='FSLPL Daily '!BE7 -> 192
A6: London at Park Lane | B6: =B5+1 -> 5 | C6: 2 | D6: 2020 | E6: =IF(('FSLPL Daily '!C8-'FSLPL Daily '!C7<0), "0",'FSLPL Daily '!C8-'FSLPL Daily '!C7) -> 7910 | F6: =IF(('FSLPL Daily '!E8-'FSLPL Daily '!E7<0), "0",'FSLPL Daily '!E8-'FSLPL Daily '!E7) -> 5670 | G6: =IF(('FSLPL Daily '!G8-'FSLPL Daily '!G7<0), "0",'FSLPL Daily '!G8-'FSLPL Daily '!G7) -> 4050 | H6: =IF(('FSLPL Daily '!I8-'FSLPL Daily '!I7<0), "0",'FSLPL Daily '!I8-'FSLPL Daily '!I7) -> 362 | I6: =IF(('FSLPL Daily '!K8-'FSLPL Daily '!K7<0), "0",'FSLPL Daily '!K8-'FSLPL Daily '!K7) -> 811 | J6: =IF(('FSLPL Daily '!M8-'FSLPL Daily '!M7<0), "0",'FSLPL Daily '!M8-'FSLPL Daily '!M7) -> 1408 | K6: =IF(('FSLPL Daily '!O8-'FSLPL Daily '!O7<0), "0",'FSLPL Daily '!O8-'FSLPL Daily '!O7) -> 661 | L6: =IF(('FSLPL Daily '!Q8-'FSLPL Daily '!Q7<0), "0",'FSLPL Daily '!Q8-'FSLPL Daily '!Q7) -> 381 | M6: =IF(('FSLPL Daily '!S8-'FSLPL Daily '!S7<0), "0",'FSLPL Daily '!S8-'FSLPL Daily '!S7) -> 118 | N6: =IF(('FSLPL Daily '!U8-'FSLPL Daily '!U7<0), "0",'FSLPL Daily '!U8-'FSLPL Daily '!U7) -> 1073 | O6: =IF(('FSLPL Daily '!W8-'FSLPL Daily '!W7<0), "0",'FSLPL Daily '!W8-'FSLPL Daily '!W7) -> 210 | P6: =IF(('FSLPL Daily '!Y8-'FSLPL Daily '!Y7<0), "0",'FSLPL Daily '!Y8-'FSLPL Daily '!Y7) -> 1041 | Q6: =IF(('FSLPL Daily '!AA8-'FSLPL Daily '!AA7<0), "0",'FSLPL Daily '!AA8-'FSLPL Daily '!AA7) -> 2 | R6: =IF(('FSLPL Daily '!AC8-'FSLPL Daily '!AC7<0), "0",'FSLPL Daily '!AC8-'FSLPL Daily '!AC7) -> 1453 | S6: =IF(('FSLPL Daily '!AE8-'FSLPL Daily '!AE7<0), "0",'FSLPL Daily '!AE8-'FSLPL Daily '!AE7) -> 1914 | T6: =IF(('FSLPL Daily '!AG8-'FSLPL Daily '!AG7<0), "0",'FSLPL Daily '!AG8-'FSLPL Daily '!AG7) -> 236 | U6: =IF(('FSLPL Daily '!AI8-'FSLPL Daily '!AI7<0), "0",'FSLPL Daily '!AI8-'FSLPL Daily '!AI7) -> 76 | V6: =IF(('FSLPL Daily '!AK8-'FSLPL Daily '!AK7<0), "0",'FSLPL Daily '!AK8-'FSLPL Daily '!AK7) -> 369 | W6: =IF(('FSLPL Daily '!AM8-'FSLPL Daily '!AM7<0), "0",'FSLPL Daily '!AM8-'FSLPL Daily '!AM7) -> 576 | X6: =IF(('FSLPL Daily '!AO8-'FSLPL Daily '!AO7<0), "0",'FSLPL Daily '!AO8-'FSLPL Daily '!AO7) -> 660 | Y6: ='FSLPL Daily '!AS8 -> 0 | Z6: ='FSLPL Daily '!AU8 -> 0 | AA6: =IF(('FSLPL Daily '!AV8-'FSLPL Daily '!AV7<0), "0",'FSLPL Daily '!AV8-'FSLPL Daily '!AV7) -> 20 | AB6: =IF(('FSLPL Daily '!AX8-'FSLPL Daily '!AX7<0), "0",'FSLPL Daily '!AX8-'FSLPL Daily '!AX7) -> 1 | AC6: =IF(('FSLPL Daily '!AZ8-'FSLPL Daily '!AZ7<0), "0",'FSLPL Daily '!AZ8-'FSLPL Daily '!AZ7) -> 2222 | AD6: =IF(('FSLPL Daily '!BB8-'FSLPL Daily '!BB7<0), "0",'FSLPL Daily '!BB8-'FSLPL Daily '!BB7) -> 1100 | AE6: ='FSLPL Daily '!BD8 -> 138 | AF6: ='FSLPL Daily '!BE8 -> 187
A7: London at Park Lane | B7: =B6+1 -> 6 | C7: 2 | D7: 2020 | E7: =IF(('FSLPL Daily '!C9-'FSLPL Daily '!C8<0), "0",'FSLPL Daily '!C9-'FSLPL Daily '!C8) -> 7911 | F7: =IF(('FSLPL Daily '!E9-'FSLPL Daily '!E8<0), "0",'FSLPL Daily '!E9-'FSLPL Daily '!E8) -> 5546 | G7: =IF(('FSLPL Daily '!G9-'FSLPL Daily '!G8<0), "0",'FSLPL Daily '!G9-'FSLPL Daily '!G8) -> 3828 | H7: =IF(('FSLPL Daily '!I9-'FSLPL Daily '!I8<0), "0",'FSLPL Daily '!I9-'FSLPL Daily '!I8) -> 472 | I7: =IF(('FSLPL Daily '!K9-'FSLPL Daily '!K8<0), "0",'FSLPL Daily '!K9-'FSLPL Daily '!K8) -> 832 | J7: =IF(('FSLPL Daily '!M9-'FSLPL Daily '!M8<0), "0",'FSLPL Daily '!M9-'FSLPL Daily '!M8) -> 1314 | K7: =IF(('FSLPL Daily '!O9-'FSLPL Daily '!O8<0), "0",'FSLPL Daily '!O9-'FSLPL Daily '!O8) -> 624 | L7: =IF(('FSLPL Daily '!Q9-'FSLPL Daily '!Q8<0), "0",'FSLPL Daily '!Q9-'FSLPL Daily '!Q8) -> 355 | M7: =IF(('FSLPL Daily '!S9-'FSLPL Daily '!S8<0), "0",'FSLPL Daily '!S9-'FSLPL Daily '!S8) -> 53 | N7: =IF(('FSLPL Daily '!U9-'FSLPL Daily '!U8<0), "0",'FSLPL Daily '!U9-'FSLPL Daily '!U8) -> 1128 | O7: =IF(('FSLPL Daily '!W9-'FSLPL Daily '!W8<0), "0",'FSLPL Daily '!W9-'FSLPL Daily '!W8) -> 226 | P7: =IF(('FSLPL Daily '!Y9-'FSLPL Daily '!Y8<0), "0",'FSLPL Daily '!Y9-'FSLPL Daily '!Y8) -> 1088 | Q7: =IF(('FSLPL Daily '!AA9-'FSLPL Daily '!AA8<0), "0",'FSLPL Daily '!AA9-'FSLPL Daily '!AA8) -> 3 | R7: =IF(('FSLPL Daily '!AC9-'FSLPL Daily '!AC8<0), "0",'FSLPL Daily '!AC9-'FSLPL Daily '!AC8) -> 1409 | S7: =IF(('FSLPL Daily '!AE9-'FSLPL Daily '!AE8<0), "0",'FSLPL Daily '!AE9-'FSLPL Daily '!AE8) -> 1943 | T7: =IF(('FSLPL Daily '!AG9-'FSLPL Daily '!AG8<0), "0",'FSLPL Daily '!AG9-'FSLPL Daily '!AG8) -> 236 | U7: =IF(('FSLPL Daily '!AI9-'FSLPL Daily '!AI8<0), "0",'FSLPL Daily '!AI9-'FSLPL Daily '!AI8) -> 77 | V7: =IF(('FSLPL Daily '!AK9-'FSLPL Daily '!AK8<0), "0",'FSLPL Daily '!AK9-'FSLPL Daily '!AK8) -> 359 | W7: =IF(('FSLPL Daily '!AM9-'FSLPL Daily '!AM8<0), "0",'FSLPL Daily '!AM9-'FSLPL Daily '!AM8) -> 583 | X7: =IF(('FSLPL Daily '!AO9-'FSLPL Daily '!AO8<0), "0",'FSLPL Daily '!AO9-'FSLPL Daily '!AO8) -> 672 | Y7: ='FSLPL Daily '!AS9 -> 0 | Z7: ='FSLPL Daily '!AU9 -> 0 | AA7: =IF(('FSLPL Daily '!AV9-'FSLPL Daily '!AV8<0), "0",'FSLPL Daily '!AV9-'FSLPL Daily '!AV8) -> 19 | AB7: =IF(('FSLPL Daily '!AX9-'FSLPL Daily '!AX8<0), "0",'FSLPL Daily '!AX9-'FSLPL Daily '!AX8) -> 1 | AC7: =IF(('FSLPL Daily '!AZ9-'FSLPL Daily '!AZ8<0), "0",'FSLPL Daily '!AZ9-'FSLPL Daily '!AZ8) -> 2607 | AD7: =IF(('FSLPL Daily '!BB9-'FSLPL Daily '!BB8<0), "0",'FSLPL Daily '!BB9-'FSLPL Daily '!BB8) -> 1096 | AE7: ='FSLPL Daily '!BD9 -> 131 | AF7: ='FSLPL Daily '!BE9 -> 175
A8: London at Park Lane | B8: =B7+1 -> 7 | C8: 2 | D8: 2020 | E8: =IF(('FSLPL Daily '!C10-'FSLPL Daily '!C9<0), "0",'FSLPL Daily '!C10-'FSLPL Daily '!C9) -> 8030 | F8: =IF(('FSLPL Daily '!E10-'FSLPL Daily '!E9<0), "0",'FSLPL Daily '!E10-'FSLPL Daily '!E9) -> 5479 | G8: =IF(('FSLPL Daily '!G10-'FSLPL Daily '!G9<0), "0",'FSLPL Daily '!G10-'FSLPL Daily '!G9) -> 3929 | H8: =IF(('FSLPL Daily '!I10-'FSLPL Daily '!I9<0), "0",'FSLPL Daily '!I10-'FSLPL Daily '!I9) -> 491 | I8: =IF(('FSLPL Daily '!K10-'FSLPL Daily '!K9<0), "0",'FSLPL Daily '!K10-'FSLPL Daily '!K9) -> 824 | J8: =IF(('FSLPL Daily '!M10-'FSLPL Daily '!M9<0), "0",'FSLPL Daily '!M10-'FSLPL Daily '!M9) -> 1437 | K8: =IF(('FSLPL Daily '!O10-'FSLPL Daily '!O9<0), "0",'FSLPL Daily '!O10-'FSLPL Daily '!O9) -> 666 | L8: =IF(('FSLPL Daily '!Q10-'FSLPL Daily '!Q9<0), "0",'FSLPL Daily '!Q10-'FSLPL Daily '!Q9) -> 353 | M8: =IF(('FSLPL Daily '!S10-'FSLPL Daily '!S9<0), "0",'FSLPL Daily '!S10-'FSLPL Daily '!S9) -> 85 | N8: =IF(('FSLPL Daily '!U10-'FSLPL Daily '!U9<0), "0",'FSLPL Daily '!U10-'FSLPL Daily '!U9) -> 1093 | O8: =IF(('FSLPL Daily '!W10-'FSLPL Daily '!W9<0), "0",'FSLPL Daily '!W10-'FSLPL Daily '!W9) -> 253 | P8: =IF(('FSLPL Daily '!Y10-'FSLPL Daily '!Y9<0), "0",'FSLPL Daily '!Y10-'FSLPL Daily '!Y9) -> 1058 | Q8: =IF(('FSLPL Daily '!AA10-'FSLPL Daily '!AA9<0), "0",'FSLPL Daily '!AA10-'FSLPL Daily '!AA9) -> 2 | R8: =IF(('FSLPL Daily '!AC10-'FSLPL Daily '!AC9<0), "0",'FSLPL Daily '!AC10-'FSLPL Daily '!AC9) -> 1461 | S8: =IF(('FSLPL Daily '!AE10-'FSLPL Daily '!AE9<0), "0",'FSLPL Daily '!AE10-'FSLPL Daily '!AE9) -> 1838 | T8: =IF(('FSLPL Daily '!AG10-'FSLPL Daily '!AG9<0), "0",'FSLPL Daily '!AG10-'FSLPL Daily '!AG9) -> 233 | U8: =IF(('FSLPL Daily '!AI10-'FSLPL Daily '!AI9<0), "0",'FSLPL Daily '!AI10-'FSLPL Daily '!AI9) -> 76 | V8: =IF(('FSLPL Daily '!AK10-'FSLPL Daily '!AK9<0), "0",'FSLPL Daily '!AK10-'FSLPL Daily '!AK9) -> 339 | W8: =IF(('FSLPL Daily '!AM10-'FSLPL Daily '!AM9<0), "0",'FSLPL Daily '!AM10-'FSLPL Daily '!AM9) -> 582 | X8: =IF(('FSLPL Daily '!AO10-'FSLPL Daily '!AO9<0), "0",'FSLPL Daily '!AO10-'FSLPL Daily '!AO9) -> 640 | Y8: ='FSLPL Daily '!AS10 -> 0 | Z8: ='FSLPL Daily '!AU10 -> 0 | AA8: =IF(('FSLPL Daily '!AV10-'FSLPL Daily '!AV9<0), "0",'FSLPL Daily '!AV10-'FSLPL Daily '!AV9) -> 19 | AB8: =IF(('FSLPL Daily '!AX10-'FSLPL Daily '!AX9<0), "0",'FSLPL Daily '!AX10-'FSLPL Daily '!AX9) -> 2 | AC8: =IF(('FSLPL Daily '!AZ10-'FSLPL Daily '!AZ9<0), "0",'FSLPL Daily '!AZ10-'FSLPL Daily '!AZ9) -> 2403 | AD8: =IF(('FSLPL Daily '!BB10-'FSLPL Daily '!BB9<0), "0",'FSLPL Daily '!BB10-'FSLPL Daily '!BB9) -> 1094 | AE8: ='FSLPL Daily '!BD10 -> 114 | AF8: ='FSLPL Daily '!BE10 -> 160
A9: London at Park Lane | B9: =B8+1 -> 8 | C9: 2 | D9: 2020 | E9: =IF(('FSLPL Daily '!C11-'FSLPL Daily '!C10<0), "0",'FSLPL Daily '!C11-'FSLPL Daily '!C10) -> 7545 | F9: =IF(('FSLPL Daily '!E11-'FSLPL Daily '!E10<0), "0",'FSLPL Daily '!E11-'FSLPL Daily '!E10) -> 5363 | G9: =IF(('FSLPL Daily '!G11-'FSLPL Daily '!G10<0), "0",'FSLPL Daily '!G11-'FSLPL Daily '!G10) -> 3849 | H9: =IF(('FSLPL Daily '!I11-'FSLPL Daily '!I10<0), "0",'FSLPL Daily '!I11-'FSLPL Daily '!I10) -> 483 | I9: =IF(('FSLPL Daily '!K11-'FSLPL Daily '!K10<0), "0",'FSLPL Daily '!K11-'FSLPL Daily '!K10) -> 811 | J9: =IF(('FSLPL Daily '!M11-'FSLPL Daily '!M10<0), "0",'FSLPL Daily '!M11-'FSLPL Daily '!M10) -> 1260 | K9: =IF(('FSLPL Daily '!O11-'FSLPL Daily '!O10<0), "0",'FSLPL Daily '!O11-'FSLPL Daily '!O10) -> 664 | L9: =IF(('FSLPL Daily '!Q11-'FSLPL Daily '!Q10<0), "0",'FSLPL Daily '!Q11-'FSLPL Daily '!Q10) -> 355 | M9: =IF(('FSLPL Daily '!S11-'FSLPL Daily '!S10<0), "0",'FSLPL Daily '!S11-'FSLPL Daily '!S10) -> 84 | N9: =IF(('FSLPL Daily '!U11-'FSLPL Daily '!U10<0), "0",'FSLPL Daily '!U11-'FSLPL Daily '!U10) -> 929 | O9: =IF(('FSLPL Daily '!W11-'FSLPL Daily '!W10<0), "0",'FSLPL Daily '!W11-'FSLPL Daily '!W10) -> 133 | P9: =IF(('FSLPL Daily '!Y11-'FSLPL Daily '!Y10<0), "0",'FSLPL Daily '!Y11-'FSLPL Daily '!Y10) -> 1073 | Q9: =IF(('FSLPL Daily '!AA11-'FSLPL Daily '!AA10<0), "0",'FSLPL Daily '!AA11-'FSLPL Daily '!AA10) -> 2 | R9: =IF(('FSLPL Daily '!AC11-'FSLPL Daily '!AC10<0), "0",'FSLPL Daily '!AC11-'FSLPL Daily '!AC10) -> 1422 | S9: =IF(('FSLPL Daily '!AE11-'FSLPL Daily '!AE10<0), "0",'FSLPL Daily '!AE11-'FSLPL Daily '!AE10) -> 1708 | T9: =IF(('FSLPL Daily '!AG11-'FSLPL Daily '!AG10<0), "0",'FSLPL Daily '!AG11-'FSLPL Daily '!AG10) -> 228 | U9: =IF(('FSLPL Daily '!AI11-'FSLPL Daily '!AI10<0), "0",'FSLPL Daily '!AI11-'FSLPL Daily '!AI10) -> 74 | V9: =IF(('FSLPL Daily '!AK11-'FSLPL Daily '!AK10<0), "0",'FSLPL Daily '!AK11-'FSLPL Daily '!AK10) -> 343 | W9: =IF(('FSLPL Daily '!AM11-'FSLPL Daily '!AM10<0), "0",'FSLPL Daily '!AM11-'FSLPL Daily '!AM10) -> 577 | X9: =IF(('FSLPL Daily '!AO11-'FSLPL Daily '!AO10<0), "0",'FSLPL Daily '!AO11-'FSLPL Daily '!AO10) -> 719 | Y9: ='FSLPL Daily '!AS11 -> 0 | Z9: ='FSLPL Daily '!AU11 -> 0 | AA9: =IF(('FSLPL Daily '!AV11-'FSLPL Daily '!AV10<0), "0",'FSLPL Daily '!AV11-'FSLPL Daily '!AV10) -> 26 | AB9: =IF(('FSLPL Daily '!AX11-'FSLPL Daily '!AX10<0), "0",'FSLPL Daily '!AX11-'FSLPL Daily '!AX10) -> 6 | AC9: =IF(('FSLPL Daily '!AZ11-'FSLPL Daily '!AZ10<0), "0",'FSLPL Daily '!AZ11-'FSLPL Daily '!AZ10) -> 2271 | AD9: =IF(('FSLPL Daily '!BB11-'FSLPL Daily '!BB10<0), "0",'FSLPL Daily '!BB11-'FSLPL Daily '!BB10) -> 1080 | AE9: ='FSLPL Daily '!BD11 -> 123 | AF9: ='FSLPL Daily '!BE11 -> 173
A10: London at Park Lane | B10: =B9+1 -> 9 | C10: 2 | D10: 2020 | E10: =IF(('FSLPL Daily '!C12-'FSLPL Daily '!C11<0), "0",'FSLPL Daily '!C12-'FSLPL Daily '!C11) -> 7422 | F10: =IF(('FSLPL Daily '!E12-'FSLPL Daily '!E11<0), "0",'FSLPL Daily '!E12-'FSLPL Daily '!E11) -> 5239 | G10: =IF(('FSLPL Daily '!G12-'FSLPL Daily '!G11<0), "0",'FSLPL Daily '!G12-'FSLPL Daily '!G11) -> 3950 | H10: =IF(('FSLPL Daily '!I12-'FSLPL Daily '!I11<0), "0",'FSLPL Daily '!I12-'FSLPL Daily '!I11) -> 446 | I10: =IF(('FSLPL Daily '!K12-'FSLPL Daily '!K11<0), "0",'FSLPL Daily '!K12-'FSLPL Daily '!K11) -> 812 | J10: =IF(('FSLPL Daily '!M12-'FSLPL Daily '!M11<0), "0",'FSLPL Daily '!M12-'FSLPL Daily '!M11) -> 1272 | K10: =IF(('FSLPL Daily '!O12-'FSLPL Daily '!O11<0), "0",'FSLPL Daily '!O12-'FSLPL Daily '!O11) -> 644 | L10: =IF(('FSLPL Daily '!Q12-'FSLPL Daily '!Q11<0), "0",'FSLPL Daily '!Q12-'FSLPL Daily '!Q11) -> 351 | M10: =IF(('FSLPL Daily '!S12-'FSLPL Daily '!S11<0), "0",'FSLPL Daily '!S12-'FSLPL Daily '!S11) -> 85 | N10: =IF(('FSLPL Daily '!U12-'FSLPL Daily '!U11<0), "0",'FSLPL Daily '!U12-'FSLPL Daily '!U11) -> 860 | O10: =IF(('FSLPL Daily '!W12-'FSLPL Daily '!W11<0), "0",'FSLPL Daily '!W12-'FSLPL Daily '!W11) -> 137 | P10: =IF(('FSLPL Daily '!Y12-'FSLPL Daily '!Y11<0), "0",'FSLPL Daily '!Y12-'FSLPL Daily '!Y11) -> 1074 | Q10: =IF(('FSLPL Daily '!AA12-'FSLPL Daily '!AA11<0), "0",'FSLPL Daily '!AA12-'FSLPL Daily '!AA11) -> 2 | R10: =IF(('FSLPL Daily '!AC12-'FSLPL Daily '!AC11<0), "0",'FSLPL Daily '!AC12-'FSLPL Daily '!AC11) -> 1448 | S10: =IF(('FSLPL Daily '!AE12-'FSLPL Daily '!AE11<0), "0",'FSLPL Daily '!AE12-'FSLPL Daily '!AE11) -> 1766 | T10: =IF(('FSLPL Daily '!AG12-'FSLPL Daily '!AG11<0), "0",'FSLPL Daily '!AG12-'FSLPL Daily '!AG11) -> 236 | U10: =IF(('FSLPL Daily '!AI12-'FSLPL Daily '!AI11<0), "0",'FSLPL Daily '!AI12-'FSLPL Daily '!AI11) -> 76 | V10: =IF(('FSLPL Daily '!AK12-'FSLPL Daily '!AK11<0), "0",'FSLPL Daily '!AK12-'FSLPL Daily '!AK11) -> 337 | W10: =IF(('FSLPL Daily '!AM12-'FSLPL Daily '!AM11<0), "0",'FSLPL Daily '!AM12-'FSLPL Daily '!AM11) -> 589 | X10: =IF(('FSLPL Daily '!AO12-'FSLPL Daily '!AO11<0), "0",'FSLPL Daily '!AO12-'FSLPL Daily '!AO11) -> 642 | Y10: ='FSLPL Daily '!AS12 -> 0 | Z10: ='FSLPL Daily '!AU12 -> 0 | AA10: =IF(('FSLPL Daily '!AV12-'FSLPL Daily '!AV11<0), "0",'FSLPL Daily '!AV12-'FSLPL Daily '!AV11) -> 26 | AB10: =IF(('FSLPL Daily '!AX12-'FSLPL Daily '!AX11<0), "0",'FSLPL Daily '!AX12-'FSLPL Daily '!AX11) -> 4 | AC10: =IF(('FSLPL Daily '!AZ12-'FSLPL Daily '!AZ11<0), "0",'FSLPL Daily '!AZ12-'FSLPL Daily '!AZ11) -> 2249 | AD10: =IF(('FSLPL Daily '!BB12-'FSLPL Daily '!BB11<0), "0",'FSLPL Daily '!BB12-'FSLPL Daily '!BB11) -> 1125 | AE10: ='FSLPL Daily '!BD12 -> 102 | AF10: ='FSLPL Daily '!BE12 -> 137
A11: London at Park Lane | B11: =B10+1 -> 10 | C11: 2 | D11: 2020 | E11: =IF(('FSLPL Daily '!C13-'FSLPL Daily '!C12<0), "0",'FSLPL Daily '!C13-'FSLPL Daily '!C12) -> 7664 | F11: =IF(('FSLPL Daily '!E13-'FSLPL Daily '!E12<0), "0",'FSLPL Daily '!E13-'FSLPL Daily '!E12) -> 5332 | G11: =IF(('FSLPL Daily '!G13-'FSLPL Daily '!G12<0), "0",'FSLPL Daily '!G13-'FSLPL Daily '!G12) -> 3974 | H11: =IF(('FSLPL Daily '!I13-'FSLPL Daily '!I12<0), "0",'FSLPL Daily '!I13-'FSLPL Daily '!I12) -> 483 | I11: =IF(('FSLPL Daily '!K13-'FSLPL Daily '!K12<0), "0",'FSLPL Daily '!K13-'FSLPL Daily '!K12) -> 840 | J11: =IF(('FSLPL Daily '!M13-'FSLPL Daily '!M12<0), "0",'FSLPL Daily '!M13-'FSLPL Daily '!M12) -> 1373 | K11: =IF(('FSLPL Daily '!O13-'FSLPL Daily '!O12<0), "0",'FSLPL Daily '!O13-'FSLPL Daily '!O12) -> 627 | L11: =IF(('FSLPL Daily '!Q13-'FSLPL Daily '!Q12<0), "0",'FSLPL Daily '!Q13-'FSLPL Daily '!Q12) -> 351 | M11: =IF(('FSLPL Daily '!S13-'FSLPL Daily '!S12<0), "0",'FSLPL Daily '!S13-'FSLPL Daily '!S12) -> 85 | N11: =IF(('FSLPL Daily '!U13-'FSLPL Daily '!U12<0), "0",'FSLPL Daily '!U13-'FSLPL Daily '!U12) -> 993 | O11: =IF(('FSLPL Daily '!W13-'FSLPL Daily '!W12<0), "0",'FSLPL Daily '!W13-'FSLPL Daily '!W12) -> 141 | P11: =IF(('FSLPL Daily '!Y13-'FSLPL Daily '!Y12<0), "0",'FSLPL Daily '!Y13-'FSLPL Daily '!Y12) -> 1011 | Q11: =IF(('FSLPL Daily '!AA13-'FSLPL Daily '!AA12<0), "0",'FSLPL Daily '!AA13-'FSLPL Daily '!AA12) -> 3 | R11: =IF(('FSLPL Daily '!AC13-'FSLPL Daily '!AC12<0), "0",'FSLPL Daily '!AC13-'FSLPL Daily '!AC12) -> 1431 | S11: =IF(('FSLPL Daily '!AE13-'FSLPL Daily '!AE12<0), "0",'FSLPL Daily '!AE13-'FSLPL Daily '!AE12) -> 1877 | T11: =IF(('FSLPL Daily '!AG13-'FSLPL Daily '!AG12<0), "0",'FSLPL Daily '!AG13-'FSLPL Daily '!AG12) -> 235 | U11: =IF(('FSLPL Daily '!AI13-'FSLPL Daily '!AI12<0), "0",'FSLPL Daily '!AI13-'FSLPL Daily '!AI12) -> 75 | V11: =IF(('FSLPL Daily '!AK13-'FSLPL Daily '!AK12<0), "0",'FSLPL Daily '!AK13-'FSLPL Daily '!AK12) -> 337 | W11: =IF(('FSLPL Daily '!AM13-'FSLPL Daily '!AM12<0), "0",'FSLPL Daily '!AM13-'FSLPL Daily '!AM12) -> 595 | X11: =IF(('FSLPL Daily '!AO13-'FSLPL Daily '!AO12<0), "0",'FSLPL Daily '!AO13-'FSLPL Daily '!AO12) -> 687 | Y11: ='FSLPL Daily '!AS13 -> 220 | Z11: ='FSLPL Daily '!AU13 -> 519 | AA11: =IF(('FSLPL Daily '!AV13-'FSLPL Daily '!AV12<0), "0",'FSLPL Daily '!AV13-'FSLPL Daily '!AV12) -> 21 | AB11: =IF(('FSLPL Daily '!AX13-'FSLPL Daily '!AX12<0), "0",'FSLPL Daily '!AX13-'FSLPL Daily '!AX12) -> 2 | AC11: =IF(('FSLPL Daily '!AZ13-'FSLPL Daily '!AZ12<0), "0",'FSLPL Daily '!AZ13-'FSLPL Daily '!AZ12) -> 2202 | AD11: =IF(('FSLPL Daily '!BB13-'FSLPL Daily '!BB12<0), "0",'FSLPL Daily '!BB13-'FSLPL Daily '!BB12) -> 1153 | AE11: ='FSLPL Daily '!BD13 -> 110 | AF11: ='FSLPL Daily '!BE13 -> 139
A12: London at Park Lane | B12: =B11+1 -> 11 | C12: 2 | D12: 2020 | E12: =IF(('FSLPL Daily '!C14-'FSLPL Daily '!C13<0), "0",'FSLPL Daily '!C14-'FSLPL Daily '!C13) -> 7241 | F12: =IF(('FSLPL Daily '!E14-'FSLPL Daily '!E13<0), "0",'FSLPL Daily '!E14-'FSLPL Daily '!E13) -> 4938 | G12: =IF(('FSLPL Daily '!G14-'FSLPL Daily '!G13<0), "0",'FSLPL Daily '!G14-'FSLPL Daily '!G13) -> 3857 | H12: =IF(('FSLPL Daily '!I14-'FSLPL Daily '!I13<0), "0",'FSLPL Daily '!I14-'FSLPL Daily '!I13) -> 454 | I12: =IF(('FSLPL Daily '!K14-'FSLPL Daily '!K13<0), "0",'FSLPL Daily '!K14-'FSLPL Daily '!K13) -> 825 | J12: =IF(('FSLPL Daily '!M14-'FSLPL Daily '!M13<0), "0",'FSLPL Daily '!M14-'FSLPL Daily '!M13) -> 1120 | K12: =IF(('FSLPL Daily '!O14-'FSLPL Daily '!O13<0), "0",'FSLPL Daily '!O14-'FSLPL Daily '!O13) -> 574 | L12: =IF(('FSLPL Daily '!Q14-'FSLPL Daily '!Q13<0), "0",'FSLPL Daily '!Q14-'FSLPL Daily '!Q13) -> 328 | M12: =IF(('FSLPL Daily '!S14-'FSLPL Daily '!S13<0), "0",'FSLPL Daily '!S14-'FSLPL Daily '!S13) -> 85 | N12: =IF(('FSLPL Daily '!U14-'FSLPL Daily '!U13<0), "0",'FSLPL Daily '!U14-'FSLPL Daily '!U13) -> 977 | O12: =IF(('FSLPL Daily '!W14-'FSLPL Daily '!W13<0), "0",'FSLPL Daily '!W14-'FSLPL Daily '!W13) -> 120 | P12: =IF(('FSLPL Daily '!Y14-'FSLPL Daily '!Y13<0), "0",'FSLPL Daily '!Y14-'FSLPL Daily '!Y13) -> 870 | Q12: =IF(('FSLPL Daily '!AA14-'FSLPL Daily '!AA13<0), "0",'FSLPL Daily '!AA14-'FSLPL Daily '!AA13) -> 2 | R12: =IF(('FSLPL Daily '!AC14-'FSLPL Daily '!AC13<0), "0",'FSLPL Daily '!AC14-'FSLPL Daily '!AC13) -> 1122 | S12: =IF(('FSLPL Daily '!AE14-'FSLPL Daily '!AE13<0), "0",'FSLPL Daily '!AE14-'FSLPL Daily '!AE13) -> 1895 | T12: =IF(('FSLPL Daily '!AG14-'FSLPL Daily '!AG13<0), "0",'FSLPL Daily '!AG14-'FSLPL Daily '!AG13) -> 153 | U12: =IF(('FSLPL Daily '!AI14-'FSLPL Daily '!AI13<0), "0",'FSLPL Daily '!AI14-'FSLPL Daily '!AI13) -> 67 | V12: =IF(('FSLPL Daily '!AK14-'FSLPL Daily '!AK13<0), "0",'FSLPL Daily '!AK14-'FSLPL Daily '!AK13) -> 345 | W12: =IF(('FSLPL Daily '!AM14-'FSLPL Daily '!AM13<0), "0",'FSLPL Daily '!AM14-'FSLPL Daily '!AM13) -> 599 | X12: =IF(('FSLPL Daily '!AO14-'FSLPL Daily '!AO13<0), "0",'FSLPL Daily '!AO14-'FSLPL Daily '!AO13) -> 581 | Y12: ='FSLPL Daily '!AS14 -> 0 | Z12: ='FSLPL Daily '!AU14 -> 0 | AA12: =IF(('FSLPL Daily '!AV14-'FSLPL Daily '!AV13<0), "0",'FSLPL Daily '!AV14-'FSLPL Daily '!AV13) -> 20 | AB12: =IF(('FSLPL Daily '!AX14-'FSLPL Daily '!AX13<0), "0",'FSLPL Daily '!AX14-'FSLPL Daily '!AX13) -> 4 | AC12: =IF(('FSLPL Daily '!AZ14-'FSLPL Daily '!AZ13<0), "0",'FSLPL Daily '!AZ14-'FSLPL Daily '!AZ13) -> 2233 | AD12: =IF(('FSLPL Daily '!BB14-'FSLPL Daily '!BB13<0), "0",'FSLPL Daily '!BB14-'FSLPL Daily '!BB13) -> 1101 | AE12: ='FSLPL Daily '!BD14 -> 129 | AF12: ='FSLPL Daily '!BE14 -> 163
A13: London at Park Lane | B13: =B12+1 -> 12 | C13: 2 | D13: 2020 | E13: =IF(('FSLPL Daily '!C15-'FSLPL Daily '!C14<0), "0",'FSLPL Daily '!C15-'FSLPL Daily '!C14) -> 7484 | F13: =IF(('FSLPL Daily '!E15-'FSLPL Daily '!E14<0), "0",'FSLPL Daily '!E15-'FSLPL Daily '!E14) -> 4732 | G13: =IF(('FSLPL Daily '!G15-'FSLPL Daily '!G14<0), "0",'FSLPL Daily '!G15-'FSLPL Daily '!G14) -> 3938 | H13: =IF(('FSLPL Daily '!I15-'FSLPL Daily '!I14<0), "0",'FSLPL Daily '!I15-'FSLPL Daily '!I14) -> 472 | I13: =IF(('FSLPL Daily '!K15-'FSLPL Daily '!K14<0), "0",'FSLPL Daily '!K15-'FSLPL Daily '!K14) -> 816 | J13: =IF(('FSLPL Daily '!M15-'FSLPL Daily '!M14<0), "0",'FSLPL Daily '!M15-'FSLPL Daily '!M14) -> 1147 | K13: =IF(('FSLPL Daily '!O15-'FSLPL Daily '!O14<0), "0",'FSLPL Daily '!O15-'FSLPL Daily '!O14) -> 585 | L13: =IF(('FSLPL Daily '!Q15-'FSLPL Daily '!Q14<0), "0",'FSLPL Daily '!Q15-'FSLPL Daily '!Q14) -> 377 | M13: =IF(('FSLPL Daily '!S15-'FSLPL Daily '!S14<0), "0",'FSLPL Daily '!S15-'FSLPL Daily '!S14) -> 84 | N13: =IF(('FSLPL Daily '!U15-'FSLPL Daily '!U14<0), "0",'FSLPL Daily '!U15-'FSLPL Daily '!U14) -> 1142 | O13: =IF(('FSLPL Daily '!W15-'FSLPL Daily '!W14<0), "0",'FSLPL Daily '!W15-'FSLPL Daily '!W14) -> 155 | P13: =IF(('FSLPL Daily '!Y15-'FSLPL Daily '!Y14<0), "0",'FSLPL Daily '!Y15-'FSLPL Daily '!Y14) -> 847 | Q13: =IF(('FSLPL Daily '!AA15-'FSLPL Daily '!AA14<0), "0",'FSLPL Daily '!AA15-'FSLPL Daily '!AA14) -> 2 | R13: =IF(('FSLPL Daily '!AC15-'FSLPL Daily '!AC14<0), "0",'FSLPL Daily '!AC15-'FSLPL Daily '!AC14) -> 882 | S13: =IF(('FSLPL Daily '!AE15-'FSLPL Daily '!AE14<0), "0",'FSLPL Daily '!AE15-'FSLPL Daily '!AE14) -> 1899 | T13: =IF(('FSLPL Daily '!AG15-'FSLPL Daily '!AG14<0), "0",'FSLPL Daily '!AG15-'FSLPL Daily '!AG14) -> 78 | U13: =IF(('FSLPL Daily '!AI15-'FSLPL Daily '!AI14<0), "0",'FSLPL Daily '!AI15-'FSLPL Daily '!AI14) -> 76 | V13: =IF(('FSLPL Daily '!AK15-'FSLPL Daily '!AK14<0), "0",'FSLPL Daily '!AK15-'FSLPL Daily '!AK14) -> 327 | W13: =IF(('FSLPL Daily '!AM15-'FSLPL Daily '!AM14<0), "0",'FSLPL Daily '!AM15-'FSLPL Daily '!AM14) -> 612 | X13: =IF(('FSLPL Daily '!AO15-'FSLPL Daily '!AO14<0), "0",'FSLPL Daily '!AO15-'FSLPL Daily '!AO14) -> 638 | Y13: ='FSLPL Daily '!AS15 -> 0 | Z13: ='FSLPL Daily '!AU15 -> 0 | AA13: =IF(('FSLPL Daily '!AV15-'FSLPL Daily '!AV14<0), "0",'FSLPL Daily '!AV15-'FSLPL Daily '!AV14) -> 21 | AB13: =IF(('FSLPL Daily '!AX15-'FSLPL Daily '!AX14<0), "0",'FSLPL Daily '!AX15-'FSLPL Daily '!AX14) -> 1 | AC13: =IF(('FSLPL Daily '!AZ15-'FSLPL Daily '!AZ14<0), "0",'FSLPL Daily '!AZ15-'FSLPL Daily '!AZ14) -> 2267 | AD13: =IF(('FSLPL Daily '!BB15-'FSLPL Daily '!BB14<0), "0",'FSLPL Daily '!BB15-'FSLPL Daily '!BB14) -> 1114 | AE13: ='FSLPL Daily '!BD15 -> 136 | AF13: ='FSLPL Daily '!BE15 -> 174
A14: London at Park Lane | B14: =B13+1 -> 13 | C14: 2 | D14: 2020 | E14: =IF(('FSLPL Daily '!C16-'FSLPL Daily '!C15<0), "0",'FSLPL Daily '!C16-'FSLPL Daily '!C15) -> 7484 | F14: =IF(('FSLPL Daily '!E16-'FSLPL Daily '!E15<0), "0",'FSLPL Daily '!E16-'FSLPL Daily '!E15) -> 5308 | G14: =IF(('FSLPL Daily '!G16-'FSLPL Daily '!G15<0), "0",'FSLPL Daily '!G16-'FSLPL Daily '!G15) -> 3874 | H14: =IF(('FSLPL Daily '!I16-'FSLPL Daily '!I15<0), "0",'FSLPL Daily '!I16-'FSLPL Daily '!I15) -> 441 | I14: =IF(('FSLPL Daily '!K16-'FSLPL Daily '!K15<0), "0",'FSLPL Daily '!K16-'FSLPL Daily '!K15) -> 828 | J14: =IF(('FSLPL Daily '!M16-'FSLPL Daily '!M15<0), "0",'FSLPL Daily '!M16-'FSLPL Daily '!M15) -> 1187 | K14: =IF(('FSLPL Daily '!O16-'FSLPL Daily '!O15<0), "0",'FSLPL Daily '!O16-'FSLPL Daily '!O15) -> 590 | L14: =IF(('FSLPL Daily '!Q16-'FSLPL Daily '!Q15<0), "0",'FSLPL Daily '!Q16-'FSLPL Daily '!Q15) -> 344 | M14: =IF(('FSLPL Daily '!S16-'FSLPL Daily '!S15<0), "0",'FSLPL Daily '!S16-'FSLPL Daily '!S15) -> 84 | N14: =IF(('FSLPL Daily '!U16-'FSLPL Daily '!U15<0), "0",'FSLPL Daily '!U16-'FSLPL Daily '!U15) -> 1052 | O14: =IF(('FSLPL Daily '!W16-'FSLPL Daily '!W15<0), "0",'FSLPL Daily '!W16-'FSLPL Daily '!W15) -> 195 | P14: =IF(('FSLPL Daily '!Y16-'FSLPL Daily '!Y15<0), "0",'FSLPL Daily '!Y16-'FSLPL Daily '!Y15) -> 960 | Q14: =IF(('FSLPL Daily '!AA16-'FSLPL Daily '!AA15<0), "0",'FSLPL Daily '!AA16-'FSLPL Daily '!AA15) -> 2 | R14: =IF(('FSLPL Daily '!AC16-'FSLPL Daily '!AC15<0), "0",'FSLPL Daily '!AC16-'FSLPL Daily '!AC15) -> 1248 | S14: =IF(('FSLPL Daily '!AE16-'FSLPL Daily '!AE15<0), "0",'FSLPL Daily '!AE16-'FSLPL Daily '!AE15) -> 1952 | T14: =IF(('FSLPL Daily '!AG16-'FSLPL Daily '!AG15<0), "0",'FSLPL Daily '!AG16-'FSLPL Daily '!AG15) -> 167 | U14: =IF(('FSLPL Daily '!AI16-'FSLPL Daily '!AI15<0), "0",'FSLPL Daily '!AI16-'FSLPL Daily '!AI15) -> 75 | V14: =IF(('FSLPL Daily '!AK16-'FSLPL Daily '!AK15<0), "0",'FSLPL Daily '!AK16-'FSLPL Daily '!AK15) -> 345 | W14: =IF(('FSLPL Daily '!AM16-'FSLPL Daily '!AM15<0), "0",'FSLPL Daily '!AM16-'FSLPL Daily '!AM15) -> 602 | X14: =IF(('FSLPL Daily '!AO16-'FSLPL Daily '!AO15<0), "0",'FSLPL Daily '!AO16-'FSLPL Daily '!AO15) -> 614 | Y14: ='FSLPL Daily '!AS16 -> 0 | Z14: ='FSLPL Daily '!AU16 -> 0 | AA14: =IF(('FSLPL Daily '!AV16-'FSLPL Daily '!AV15<0), "0",'FSLPL Daily '!AV16-'FSLPL Daily '!AV15) -> 20 | AB14: =IF(('FSLPL Daily '!AX16-'FSLPL Daily '!AX15<0), "0",'FSLPL Daily '!AX16-'FSLPL Daily '!AX15) -> 3 | AC14: =IF(('FSLPL Daily '!AZ16-'FSLPL Daily '!AZ15<0), "0",'FSLPL Daily '!AZ16-'FSLPL Daily '!AZ15) -> 2257 | AD14: =IF(('FSLPL Daily '!BB16-'FSLPL Daily '!BB15<0), "0",'FSLPL Daily '!BB16-'FSLPL Daily '!BB15) -> 1098 | AE14: ='FSLPL Daily '!BD16 -> 121 | AF14: ='FSLPL Daily '!BE16 -> 166
... A30: London at Park Lane | B30: =B29+1 -> 29 | C30: 2 | D30: 2020 | E30: =IF(('FSLPL Daily '!C32-'FSLPL Daily '!C31<0), "0",'FSLPL Daily '!C32-'FSLPL Daily '!C31) -> 0 | F30: =IF(('FSLPL Daily '!E32-'FSLPL Daily '!E31<0), "0",'FSLPL Daily '!E32-'FSLPL Daily '!E31) -> 0 | G30: =IF(('FSLPL Daily '!G32-'FSLPL Daily '!G31<0), "0",'FSLPL Daily '!G32-'FSLPL Daily '!G31) -> 0 | H30: =IF(('FSLPL Daily '!I32-'FSLPL Daily '!I31<0), "0",'FSLPL Daily '!I32-'FSLPL Daily '!I31) -> 0 | I30: =IF(('FSLPL Daily '!K32-'FSLPL Daily '!K31<0), "0",'FSLPL Daily '!K32-'FSLPL Daily '!K31) -> 0 | J30: =IF(('FSLPL Daily '!M32-'FSLPL Daily '!M31<0), "0",'FSLPL Daily '!M32-'FSLPL Daily '!M31) -> 0 | K30: =IF(('FSLPL Daily '!O32-'FSLPL Daily '!O31<0), "0",'FSLPL Daily '!O32-'FSLPL Daily '!O31) -> 0 | L30: =IF(('FSLPL Daily '!Q32-'FSLPL Daily '!Q31<0), "0",'FSLPL Daily '!Q32-'FSLPL Daily '!Q31) -> 0 | M30: =IF(('FSLPL Daily '!S32-'FSLPL Daily '!S31<0), "0",'FSLPL Daily '!S32-'FSLPL Daily '!S31) -> 0 | N30: =IF(('FSLPL Daily '!U32-'FSLPL Daily '!U31<0), "0",'FSLPL Daily '!U32-'FSLPL Daily '!U31) -> 0 | O30: =IF(('FSLPL Daily '!W32-'FSLPL Daily '!W31<0), "0",'FSLPL Daily '!W32-'FSLPL Daily '!W31) -> 0 | P30: =IF(('FSLPL Daily '!Y32-'FSLPL Daily '!Y31<0), "0",'FSLPL Daily '!Y32-'FSLPL Daily '!Y31) -> 0 | Q30: =IF(('FSLPL Daily '!AA32-'FSLPL Daily '!AA31<0), "0",'FSLPL Daily '!AA32-'FSLPL Daily '!AA31) -> 0 | R30: =IF(('FSLPL Daily '!AC32-'FSLPL Daily '!AC31<0), "0",'FSLPL Daily '!AC32-'FSLPL Daily '!AC31) -> 0 | S30: =IF(('FSLPL Daily '!AE32-'FSLPL Daily '!AE31<0), "0",'FSLPL Daily '!AE32-'FSLPL Daily '!AE31) -> 0 | T30: =IF(('FSLPL Daily '!AG32-'FSLPL Daily '!AG31<0), "0",'FSLPL Daily '!AG32-'FSLPL Daily '!AG31) -> 0 | U30: =IF(('FSLPL Daily '!AI32-'FSLPL Daily '!AI31<0), "0",'FSLPL Daily '!AI32-'FSLPL Daily '!AI31) -> 0 | V30: =IF(('FSLPL Daily '!AK32-'FSLPL Daily '!AK31<0), "0",'FSLPL Daily '!AK32-'FSLPL Daily '!AK31) -> 0 | W30: =IF(('FSLPL Daily '!AM32-'FSLPL Daily '!AM31<0), "0",'FSLPL Daily '!AM32-'FSLPL Daily '!AM31) -> 0 | X30: =IF(('FSLPL Daily '!AO32-'FSLPL Daily '!AO31<0), "0",'FSLPL Daily '!AO32-'FSLPL Daily '!AO31) -> 0 | Y30: ='FSLPL Daily '!AS32 -> 0 | Z30: ='FSLPL Daily '!AU32 -> 0 | AA30: =IF(('FSLPL Daily '!AV32-'FSLPL Daily '!AV31<0), "0",'FSLPL Daily '!AV32-'FSLPL Daily '!AV31) -> 0 | AB30: =IF(('FSLPL Daily '!AX32-'FSLPL Daily '!AX31<0), "0",'FSLPL Daily '!AX32-'FSLPL Daily '!AX31) -> 0 | AC30: =IF(('FSLPL Daily '!AZ32-'FSLPL Daily '!AZ31<0), "0",'FSLPL Daily '!AZ32-'FSLPL Daily '!AZ31) -> 0 | AD30: =IF(('FSLPL Daily '!BB32-'FSLPL Daily '!BB31<0), "0",'FSLPL Daily '!BB32-'FSLPL Daily '!BB31) -> 0 | AE30: ='FSLPL Daily '!BD32 -> 0 | AF30: ='FSLPL Daily '!BE32 -> 0
A31: London at Park Lane | C31: 2 | D31: 2020 | E31: =IF(('FSLPL Daily '!C33-'FSLPL Daily '!C32<0), "0",'FSLPL Daily '!C33-'FSLPL Daily '!C32) -> 0 | F31: =IF(('FSLPL Daily '!E33-'FSLPL Daily '!E32<0), "0",'FSLPL Daily '!E33-'FSLPL Daily '!E32) -> 0 | G31: =IF(('FSLPL Daily '!G33-'FSLPL Daily '!G32<0), "0",'FSLPL Daily '!G33-'FSLPL Daily '!G32) -> 0 | H31: =IF(('FSLPL Daily '!I33-'FSLPL Daily '!I32<0), "0",'FSLPL Daily '!I33-'FSLPL Daily '!I32) -> 0 | I31: =IF(('FSLPL Daily '!K33-'FSLPL Daily '!K32<0), "0",'FSLPL Daily '!K33-'FSLPL Daily '!K32) -> 0 | J31: =IF(('FSLPL Daily '!M33-'FSLPL Daily '!M32<0), "0",'FSLPL Daily '!M33-'FSLPL Daily '!M32) -> 0 | K31: =IF(('FSLPL Daily '!O33-'FSLPL Daily '!O32<0), "0",'FSLPL Daily '!O33-'FSLPL Daily '!O32) -> 0 | L31: =IF(('FSLPL Daily '!Q33-'FSLPL Daily '!Q32<0), "0",'FSLPL Daily '!Q33-'FSLPL Daily '!Q32) -> 0 | M31: =IF(('FSLPL Daily '!S33-'FSLPL Daily '!S32<0), "0",'FSLPL Daily '!S33-'FSLPL Daily '!S32) -> 0 | N31: =IF(('FSLPL Daily '!U33-'FSLPL Daily '!U32<0), "0",'FSLPL Daily '!U33-'FSLPL Daily '!U32) -> 0 | O31: =IF(('FSLPL Daily '!W33-'FSLPL Daily '!W32<0), "0",'FSLPL Daily '!W33-'FSLPL Daily '!W32) -> 0 | P31: =IF(('FSLPL Daily '!Y33-'FSLPL Daily '!Y32<0), "0",'FSLPL Daily '!Y33-'FSLPL Daily '!Y32) -> 0 | Q31: =IF(('FSLPL Daily '!AA33-'FSLPL Daily '!AA32<0), "0",'FSLPL Daily '!AA33-'FSLPL Daily '!AA32) -> 0 | R31: =IF(('FSLPL Daily '!AC33-'FSLPL Daily '!AC32<0), "0",'FSLPL Daily '!AC33-'FSLPL Daily '!AC32) -> 0 | S31: =IF(('FSLPL Daily '!AE33-'FSLPL Daily '!AE32<0), "0",'FSLPL Daily '!AE33-'FSLPL Daily '!AE32) -> 0 | T31: =IF(('FSLPL Daily '!AG33-'FSLPL Daily '!AG32<0), "0",'FSLPL Daily '!AG33-'FSLPL Daily '!AG32) -> 0 | U31: =IF(('FSLPL Daily '!AI33-'FSLPL Daily '!AI32<0), "0",'FSLPL Daily '!AI33-'FSLPL Daily '!AI32) -> 0 | V31: =IF(('FSLPL Daily '!AK33-'FSLPL Daily '!AK32<0), "0",'FSLPL Daily '!AK33-'FSLPL Daily '!AK32) -> 0 | W31: =IF(('FSLPL Daily '!AM33-'FSLPL Daily '!AM32<0), "0",'FSLPL Daily '!AM33-'FSLPL Daily '!AM32) -> 0 | X31: =IF(('FSLPL Daily '!AO33-'FSLPL Daily '!AO32<0), "0",'FSLPL Daily '!AO33-'FSLPL Daily '!AO32) -> 0 | Y31: ='FSLPL Daily '!AS33 -> 0 | Z31: ='FSLPL Daily '!AU33 -> 0 | AA31: =IF(('FSLPL Daily '!AV33-'FSLPL Daily '!AV32<0), "0",'FSLPL Daily '!AV33-'FSLPL Daily '!AV32) -> 0 | AB31: =IF(('FSLPL Daily '!AX33-'FSLPL Daily '!AX32<0), "0",'FSLPL Daily '!AX33-'FSLPL Daily '!AX32) -> 0 | AC31: =IF(('FSLPL Daily '!AZ33-'FSLPL Daily '!AZ32<0), "0",'FSLPL Daily '!AZ33-'FSLPL Daily '!AZ32) -> 0 | AD31: =IF(('FSLPL Daily '!BB33-'FSLPL Daily '!BB32<0), "0",'FSLPL Daily '!BB33-'FSLPL Daily '!BB32) -> 0 | AE31: ='FSLPL Daily '!BD33 -> 0 | AF31: ='FSLPL Daily '!BE33 -> 0
A32: London at Park Lane | C32: 2 | D32: 2020 | E32: =IF(('FSLPL Daily '!C34-'FSLPL Daily '!C33<0), "0",'FSLPL Daily '!C34-'FSLPL Daily '!C33) -> 0 | F32: =IF(('FSLPL Daily '!E34-'FSLPL Daily '!E33<0), "0",'FSLPL Daily '!E34-'FSLPL Daily '!E33) -> 0 | G32: =IF(('FSLPL Daily '!G34-'FSLPL Daily '!G33<0), "0",'FSLPL Daily '!G34-'FSLPL Daily '!G33) -> 0 | H32: =IF(('FSLPL Daily '!I34-'FSLPL Daily '!I33<0), "0",'FSLPL Daily '!I34-'FSLPL Daily '!I33) -> 0 | I32: =IF(('FSLPL Daily '!K34-'FSLPL Daily '!K33<0), "0",'FSLPL Daily '!K34-'FSLPL Daily '!K33) -> 0 | J32: =IF(('FSLPL Daily '!M34-'FSLPL Daily '!M33<0), "0",'FSLPL Daily '!M34-'FSLPL Daily '!M33) -> 0 | K32: =IF(('FSLPL Daily '!O34-'FSLPL Daily '!O33<0), "0",'FSLPL Daily '!O34-'FSLPL Daily '!O33) -> 0 | L32: =IF(('FSLPL Daily '!Q34-'FSLPL Daily '!Q33<0), "0",'FSLPL Daily '!Q34-'FSLPL Daily '!Q33) -> 0 | M32: =IF(('FSLPL Daily '!S34-'FSLPL Daily '!S33<0), "0",'FSLPL Daily '!S34-'FSLPL Daily '!S33) -> 0 | N32: =IF(('FSLPL Daily '!U34-'FSLPL Daily '!U33<0), "0",'FSLPL Daily '!U34-'FSLPL Daily '!U33) -> 0 | O32: =IF(('FSLPL Daily '!W34-'FSLPL Daily '!W33<0), "0",'FSLPL Daily '!W34-'FSLPL Daily '!W33) -> 0 | P32: =IF(('FSLPL Daily '!Y34-'FSLPL Daily '!Y33<0), "0",'FSLPL Daily '!Y34-'FSLPL Daily '!Y33) -> 0 | Q32: =IF(('FSLPL Daily '!AA34-'FSLPL Daily '!AA33<0), "0",'FSLPL Daily '!AA34-'FSLPL Daily '!AA33) -> 0 | R32: =IF(('FSLPL Daily '!AC34-'FSLPL Daily '!AC33<0), "0",'FSLPL Daily '!AC34-'FSLPL Daily '!AC33) -> 0 | S32: =IF(('FSLPL Daily '!AE34-'FSLPL Daily '!AE33<0), "0",'FSLPL Daily '!AE34-'FSLPL Daily '!AE33) -> 0 | T32: =IF(('FSLPL Daily '!AG34-'FSLPL Daily '!AG33<0), "0",'FSLPL Daily '!AG34-'FSLPL Daily '!AG33) -> 0 | U32: =IF(('FSLPL Daily '!AI34-'FSLPL Daily '!AI33<0), "0",'FSLPL Daily '!AI34-'FSLPL Daily '!AI33) -> 0 | V32: =IF(('FSLPL Daily '!AK34-'FSLPL Daily '!AK33<0), "0",'FSLPL Daily '!AK34-'FSLPL Daily '!AK33) -> 0 | W32: =IF(('FSLPL Daily '!AM34-'FSLPL Daily '!AM33<0), "0",'FSLPL Daily '!AM34-'FSLPL Daily '!AM33) -> 0 | X32: =IF(('FSLPL Daily '!AO34-'FSLPL Daily '!AO33<0), "0",'FSLPL Daily '!AO34-'FSLPL Daily '!AO33) -> 0 | Y32: ='FSLPL Daily '!AS34 -> 0 | Z32: ='FSLPL Daily '!AU34 -> 0 | AA32: =IF(('FSLPL Daily '!AV34-'FSLPL Daily '!AV33<0), "0",'FSLPL Daily '!AV34-'FSLPL Daily '!AV33) -> 0 | AB32: =IF(('FSLPL Daily '!AX34-'FSLPL Daily '!AX33<0), "0",'FSLPL Daily '!AX34-'FSLPL Daily '!AX33) -> 0 | AC32: =IF(('FSLPL Daily '!AZ34-'FSLPL Daily '!AZ33<0), "0",'FSLPL Daily '!AZ34-'FSLPL Daily '!AZ33) -> 0 | AD32: =IF(('FSLPL Daily '!BB34-'FSLPL Daily '!BB33<0), "0",'FSLPL Daily '!BB34-'FSLPL Daily '!BB33) -> 0 | AE32: ='FSLPL Daily '!BD34 -> 0 | AF32: ='FSLPL Daily '!BE34 -> 0

Sheet FSLPL Daily 
A1: Days | C1: LV Panel 1 KWh | E1: LV Panel 2 KWh | G1: CHP KWh | I1: MCC9 KWh | K1: GF Panel KWh | M1: Kitchen Switchboard | O1: Kitchen Panel | Q1: MCC3 (AHU) KWh | S1: MCC8 KWh | U1: 1st Floor Panel (KWh) | W1: MCC6(1st floor AHU) KWh | Y1: Chiller 1 KWh | AA1: Chiller 2 KWh | AC1: MCC 10 (Mechanical Services) KWh | AE1: MCC2 CHW KWh | AG1: MCC7 (Kitchen) KWh | AI1: MCC 5 (Mechanical services) KWh | AK1: MCC 4 (Water Services) KWh | AM1: MCC1 (KWh) | AO1: Laundry db KWh | AR1: Hamilton Place Water 1 m3 | AT1: Old Parklane Water 2 m3 | AV1: Laundry CW m3 | AX1: Laundry HW m3 | AZ1: Natural Gas m3 | BB1: CHP Natural Gas m3
A2: Date | C2: Reading KWH | D2: Difference KWH | E2: Reading KWH | F2: Difference KWH | G2: Reading KWH | H2: Difference KWH | I2: Reading KWH | J2: Difference KWH | K2: Reading KWH | L2: Difference KWH | M2: Reading KWH | N2: Difference KWH | O2: Reading KWH | P2: Difference KWH | Q2: Reading KWH | R2: Difference KWH | S2: Reading KWH | T2: Difference KWH | U2: Reading KWH | V2: Difference KWH | W2: Reading KWH | X2: Difference KWH | Y2: Reading KWH | Z2: Difference KWH | AA2: Reading KWH | AB2: Difference KWH | AC2: Reading KWH | AD2: Difference KWH | AE2: Reading KWH | AF2: Difference KWH | AG2: Reading KWH | AH2: Difference KWH | AI2: Reading KWH | AJ2: Difference KWH | AK2: Reading KWH | AL2: Difference KWH | AM2: Reading KWH | AN2: Difference KWH | AO2: Reading KWH | AP2: Difference KWH | AR2: Reading m³ | AS2: Daily Consumption m³ | AT2: Reading m³ | AU2: Daily Consumption m³ | AV2: Reading m³ | AW2: Daily Consumption m³ | AX2: Reading m³ | AY2: Daily Consumption m³ | AZ2: Reading Liters | BA2: Daily Consumption L | BB2: Reading Liters | BC2: Daily Consumption L | BD2: ROOM NIGHTS | BE2: TOTAL GUESTS
A3: 43861 | C3: 25301330 | D3: =IF((C4-C3<0), "0",C4-C3) -> 7921 | E3: 26078962 | F3: =IF((E4-E3<0), "",E4-E3) -> 5781 | G3: 11035314 | H3: =IF((G4-G3<0), "",G4-G3) -> 3991 | I3: 1551591 | J3: =IF((I4-I3<0), "",I4-I3) -> 474 | K3: 3131200 | L3: =IF((K4-K3<0), "",K4-K3) -> 842 | M3: 4550863 | N3: =IF((M4-M3<0), "",M4-M3) -> 1310 | O3: 2180224 | P3: =IF((O4-O3<0), "",O4-O3) -> 586 | Q3: 1220767 | R3: =IF((Q4-Q3<0), "",Q4-Q3) -> 364 | S3: 393519 | T3: =IF((S4-S3<0), "",S4-S3) -> 87 | U3: 4098110 | V3: =IF((U4-U3<0), "",U4-U3) -> 995 | W3: 944250 | X3: =IF((W4-W3<0), "",W4-W3) -> 153 | Y3: 3749104 | Z3: =IF((Y4-Y3<0), "",Y4-Y3) -> 1250 | AA3: 1966697 | AB3: =IF((AA4-AA3<0), "",AA4-AA3) -> 2 | AC3: 5042012 | AD3: =IF((AC4-AC3<0), "",AC4-AC3) -> 1447 | AE3: 7179359 | AF3: =IF((AE4-AE3<0), "",AE4-AE3) -> 1954 | AG3: 1269342 | AH3: =IF((AG4-AG3<0), "",AG4-AG3) -> 263 | AI3: 249627 | AJ3: =IF((AI4-AI3<0), "",AI4-AI3) -> 76 | AK3: 926199 | AL3: =IF((AK4-AK3<0), "",AK4-AK3) -> 353 | AM3: 1718347 | AN3: =IF((AM4-AM3<0), "",AM4-AM3) -> 576 | AO3: 1838735 | AP3: =IF((AO4-AO3<0), "",AO4-AO3) -> 827 | AV3: 86535 | AW3: =IF((AV4-AV3<0), "",AV4-AV3) -> 23 | AX3: 10961 | AY3: =IF((AX4-AX3<0), "",AX4-AX3) -> 3 | AZ3: 6754051 | BA3: =IF((AZ4-AZ3<0), "",AZ4-AZ3) -> 2117 | BB3: 1160816 | BC3: =IF((BB4-BB3<0), "",BB4-BB3) -> 1149 | BD3: 121 | BE3: 161
A4: 43862 | C4: 25309251 | E4: 26084743 | G4: 11039305 | I4: 1552065 | K4: 3132042 | M4: 4552173 | O4: 2180810 | Q4: 1221131 | S4: 393606 | U4: 4099105 | W4: 944403 | Y4: 3750354 | AA4: 1966699 | AC4: 5043459 | AE4: 7181313 | AG4: 1269605 | AI4: 249703 | AK4: 926552 | AM4: 1718923 | AO4: 1839562 | AR4: 0 | AS4: 3419 | AU4: 1028 | AV4: 86558 | AX4: 10964 | AZ4: 6756168 | BB4: 1161965 | BD4: 11 | BE4: 152
A5: 43863 | C5: 25316816 | D5: =IF((C5-C4<0), "0",C5-C4) -> 7565 | E5: 26090229 | F5: =IF((E5-E4<0), "0",E5-E4) -> 5486 | G5: 11043169 | H5: =IF((G5-G4<0), "0",G5-G4) -> 3864 | I5: 1552554 | J5: =IF((I5-I4<0), "0",I5-I4) -> 489 | K5: 3132832 | L5: =IF((K5-K4<0), "0",K5-K4) -> 790 | M5: 4553539 | N5: =IF((M5-M4<0), "0",M5-M4) -> 1366 | O5: 2181416 | P5: =IF((O5-O4<0), "0",O5-O4) -> 606 | Q5: 1221478 | R5: =IF((Q5-Q4<0), "0",Q5-Q4) -> 347 | S5: 393690 | T5: =IF((S5-S4<0), "0",S5-S4) -> 84 | U5: 4100040 | V5: =IF((U5-U4<0), "",U5-U4) -> 935 | W5: 944598 | X5: =IF((W5-W4<0), "",W5-W4) -> 195 | Y5: 3751344 | Z5: =IF((Y5-Y4<0), "",Y5-Y4) -> 990 | AA5: 1966702 | AB5: =IF((AA5-AA4<0), "",AA5-AA4) -> 3 | AC5: 5044869 | AD5: =IF((AC5-AC4<0), "",AC5-AC4) -> 1410 | AE5: 7183148 | AF5: =IF((AE5-AE4<0), "",AE5-AE4) -> 1835 | AG5: 1269836 | AH5: =IF((AG5-AG4<0), "",AG5-AG4) -> 231 | AI5: 249777 | AJ5: =IF((AI5-AI4<0), "",AI5-AI4) -> 74 | AK5: 926879 | AL5: =IF((AK5-AK4<0), "",AK5-AK4) -> 327 | AM5: 1719501 | AN5: =IF((AM5-AM4<0), "",AM5-AM4) -> 578 | AO5: 1840409 | AP5: =IF((AO5-AO4<0), "",AO5-AO4) -> 847 | AR5: 0 | AS5: 0 | AT5: 0 | AU5: 0 | AV5: 86581 | AW5: =IF((AV5-AV4<0), "",AV5-AV4) -> 23 | AX5: 10966 | AY5: =IF((AX5-AX4<0), "",AX5-AX4) -> 2 | AZ5: 6758263 | BA5: =IF((AZ5-AZ4<0), "",AZ5-AZ4) -> 2095 | BB5: 1163076 | BC5: =IF((BB5-BB4<0), "",BB5-BB4) -> 1111 | BD5: 123 | BE5: 154
A6: 43864 | C6: 25323903 | D6: =IF((C6-C5<0), "0",C6-C5) -> 7087 | E6: 26095553 | F6: =IF((E6-E5<0), "0",E6-E5) -> 5324 | G6: 11046969 | H6: =IF((G6-G5<0), "0",G6-G5) -> 3800 | I6: 1553030 | J6: =IF((I6-I5<0), "0",I6-I5) -> 476 | K6: 3133609 | L6: =IF((K6-K5<0), "0",K6-K5) -> 777 | M6: 4554755 | N6: =IF((M6-M5<0), "0",M6-M5) -> 1216 | O6: 2181978 | P6: =IF((O6-O5<0), "0",O6-O5) -> 562 | Q6: 1221817 | R6: =IF((Q6-Q5<0), "0",Q6-Q5) -> 339 | S6: 393772 | T6: =IF((S6-S5<0), "0",S6-S5) -> 82 | U6: 4100810 | V6: =IF((U6-U5<0), "",U6-U5) -> 770 | W6: 944698 | X6: =IF((W6-W5<0), "",W6-W5) -> 100 | Y6: 3752411 | Z6: =IF((Y6-Y5<0), "",Y6-Y5) -> 1067 | AA6: 1966704 | AB6: =IF((AA6-AA5<0), "",AA6-AA5) -> 2 | AC6: 5046253 | AD6: =IF((AC6-AC5<0), "",AC6-AC5) -> 1384 | AE6: 7184929 | AF6: =IF((AE6-AE5<0), "",AE6-AE5) -> 1781 | AG6: 1270066 | AH6: =IF((AG6-AG5<0), "",AG6-AG5) -> 230 | AI6: 249850 | AJ6: =IF((AI6-AI5<0), "",AI6-AI5) -> 73 | AK6: 927208 | AL6: =IF((AK6-AK5<0), "",AK6-AK5) -> 329 | AM6: 1720063 | AN6: =IF((AM6-AM5<0), "",AM6-AM5) -> 562 | AO6: 1841164 | AP6: =IF((AO6-AO5<0), "",AO6-AO5) -> 755 | AR6: 0 | AS6: 0 | AT6: 0 | AU6: 0 | AV6: 86599 | AW6: =IF((AV6-AV5<0), "",AV6-AV5) -> 18 | AX6: 10968 | AY6: =IF((AX6-AX5<0), "",AX6-AX5) -> 2 | AZ6: 6760304 | BA6: =IF((AZ6-AZ5<0), "",AZ6-AZ5) -> 2041 | BB6: 1164167 | BC6: =IF((BB6-BB5<0), "",BB6-BB5) -> 1091 | BD6: 134 | BE6: 170
A7: 43865 | C7: 25331959 | D7: =IF((C7-C6<0), "0",C7-C6) -> 8056 | E7: 26101158 | F7: =IF((E7-E6<0), "0",E7-E6) -> 5605 | G7: 11050992 | H7: =IF((G7-G6<0), "0",G7-G6) -> 4023 | I7: 1553636 | J7: =IF((I7-I6<0), "0",I7-I6) -> 606 | K7: 3134440 | L7: =IF((K7-K6<0), "0",K7-K6) -> 831 | M7: 4556122 | N7: =IF((M7-M6<0), "0",M7-M6) -> 1367 | O7: 2182591 | P7: =IF((O7-O6<0), "0",O7-O6) -> 613 | Q7: 1222172 | R7: =IF((Q7-Q6<0), "0",Q7-Q6) -> 355 | S7: 393859 | T7: =IF((S7-S6<0), "0",S7-S6) -> 87 | U7: 4101932 | V7: =IF((U7-U6<0), "",U7-U6) -> 1122 | W7: 944952 | X7: =IF((W7-W6<0), "",W7-W6) -> 254 | Y7: 3753482 | Z7: =IF((Y7-Y6<0), "",Y7-Y6) -> 1071 | AA7: 1966706 | AB7: =IF((AA7-AA6<0), "",AA7-AA6) -> 2 | AC7: 5047721 | AD7: =IF((AC7-AC6<0), "",AC7-AC6) -> 1468 | AE7: 7186807 | AF7: =IF((AE7-AE6<0), "",AE7-AE6) -> 1878 | AG7: 1270319 | AH7: =IF((AG7-AG6<0), "",AG7-AG6) -> 253 | AI7: 249926 | AJ7: =IF((AI7-AI6<0), "",AI7-AI6) -> 76 | AK7: 927584 | AL7: =IF((AK7-AK6<0), "",AK7-AK6) -> 376 | AM7: 1720655 | AN7: =IF((AM7-AM6<0), "",AM7-AM6) -> 592 | AO7: 1841852 | AP7: =IF((AO7-AO6<0), "",AO7-AO6) -> 688 | AR7: 0 | AS7: 0 | AT7: 0 | AU7: 0 | AV7: 86618 | AW7: =IF((AV7-AV6<0), "",AV7-AV6) -> 19 | AX7: 10973 | AY7: =IF((AX7-AX6<0), "",AX7-AX6) -> 5 | AZ7: 6762614 | BA7: =IF((AZ7-AZ6<0), "",AZ7-AZ6) -> 2310 | BB7: 1165311 | BC7: =IF((BB7-BB6<0), "",BB7-BB6) -> 1144 | BD7: 145 | BE7: 192
A8: 43866 | C8: 25339869 | D8: =IF((C8-C7<0), "0",C8-C7) -> 7910 | E8: 26106828 | F8: =IF((E8-E7<0), "0",E8-E7) -> 5670 | G8: 11055042 | H8: =IF((G8-G7<0), "0",G8-G7) -> 4050 | I8: 1553998 | J8: =IF((I8-I7<0), "0",I8-I7) -> 362 | K8: 3135251 | L8: =IF((K8-K7<0), "0",K8-K7) -> 811 | M8: 4557530 | N8: =IF((M8-M7<0), "0",M8-M7) -> 1408 | O8: 2183252 | P8: =IF((O8-O7<0), "0",O8-O7) -> 661 | Q8: 1222553 | R8: =IF((Q8-Q7<0), "0",Q8-Q7) -> 381 | S8: 393977 | T8: =IF((S8-S7<0), "0",S8-S7) -> 118 | U8: 4103005 | V8: =IF((U8-U7<0), "",U8-U7) -> 1073 | W8: 945162 | X8: =IF((W8-W7<0), "",W8-W7) -> 210 | Y8: 3754523 | Z8: =IF((Y8-Y7<0), "",Y8-Y7) -> 1041 | AA8: 1966708 | AB8: =IF((AA8-AA7<0), "",AA8-AA7) -> 2 | AC8: 5049174 | AD8: =IF((AC8-AC7<0), "",AC8-AC7) -> 1453 | AE8: 7188721 | AF8: =IF((AE8-AE7<0), "",AE8-AE7) -> 1914 | AG8: 1270555 | AH8: =IF((AG8-AG7<0), "",AG8-AG7) -> 236 | AI8: 250002 | AJ8: =IF((AI8-AI7<0), "",AI8-AI7) -> 76 | AK8: 927953 | AL8: =IF((AK8-AK7<0), "",AK8-AK7) -> 369 | AM8: 1721231 | AN8: =IF((AM8-AM7<0), "",AM8-AM7) -> 576 | AO8: 1842512 | AP8: =IF((AO8-AO7<0), "",AO8-AO7) -> 660 | AR8: 0 | AS8: 0 | AT8: 0 | AU8: 0 | AV8: 86638 | AW8: =IF((AV8-AV7<0), "",AV8-AV7) -> 20 | AX8: 10974 | AY8: =IF((AX8-AX7<0), "",AX8-AX7) -> 1 | AZ8: 6764836 | BA8: =IF((AZ8-AZ7<0), "",AZ8-AZ7) -> 2222 | BB8: 1166411 | BC8: =IF((BB8-BB7<0), "",BB8-BB7) -> 1100 | BD8: 138 | BE8: 187
A9: 43867 | C9: 25347780 | D9: =IF((C9-C8<0), "0",C9-C8) -> 7911 | E9: 26112374 | F9: =IF((E9-E8<0), "0",E9-E8) -> 5546 | G9: 11058870 | H9: =IF((G9-G8<0), "0",G9-G8) -> 3828 | I9: 1554470 | J9: =IF((I9-I8<0), "0",I9-I8) -> 472 | K9: 3136083 | L9: =IF((K9-K8<0), "0",K9-K8) -> 832 | M9: 4558844 | N9: =IF((M9-M8<0), "0",M9-M8) -> 1314 | O9: 2183876 | P9: =IF((O9-O8<0), "0",O9-O8) -> 624 | Q9: 1222908 | R9: =IF((Q9-Q8<0), "0",Q9-Q8) -> 355 | S9: 394030 | T9: =IF((S9-S8<0), "0",S9-S8) -> 53 | U9: 4104133 | V9: =IF((U9-U8<0), "",U9-U8) -> 1128 | W9: 945388 | X9: =IF((W9-W8<0), "",W9-W8) -> 226 | Y9: 3755611 | Z9: =IF((Y9-Y8<0), "",Y9-Y8) -> 1088 | AA9: 1966711 | AB9: =IF((AA9-AA8<0), "",AA9-AA8) -> 3 | AC9: 5050583 | AD9: =IF((AC9-AC8<0), "",AC9-AC8) -> 1409 | AE9: 7190664 | AF9: =IF((AE9-AE8<0), "",AE9-AE8) -> 1943 | AG9: 1270791 | AH9: =IF((AG9-AG8<0), "",AG9-AG8) -> 236 | AI9: 250079 | AJ9: =IF((AI9-AI8<0), "",AI9-AI8) -> 77 | AK9: 928312 | AL9: =IF((AK9-AK8<0), "",AK9-AK8) -> 359 | AM9: 1721814 | AN9: =IF((AM9-AM8<0), "",AM9-AM8) -> 583 | AO9: 1843184 | AP9: =IF((AO9-AO8<0), "",AO9-AO8) -> 672 | AR9: 0 | AS9: 0 | AT9: 0 | AU9: 0 | AV9: 86657 | AW9: =IF((AV9-AV8<0), "",AV9-AV8) -> 19 | AX9: 10975 | AY9: =IF((AX9-AX8<0), "",AX9-AX8) -> 1 | AZ9: 6767443 | BA9: =IF((AZ9-AZ8<0), "",AZ9-AZ8) -> 2607 | BB9: 1167507 | BC9: =IF((BB9-BB8<0), "",BB9-BB8) -> 1096 | BD9: 131 | BE9: 175
