Workbook

Sheet TOTAL
A1: Site Name | B1: Day | C1: Month | D1: Year | E1: Total Electricity Kwh | F1: Electricity Tariff ($/Kwh) | G1: Natual Gas (m3) | H1: Natural Gas $/m3 | I1: Water Utility Supply (m3) m3 | J1: Water Utility Supply (m3) $/m3 | K1: Room Nights | L1: Total Guests
A2: London at Park Lane | B2: 1 | C2: 2 | D2: 2020 | E2: =Submetering!E2+Submetering!F2+Submetering!G2 -> 18074 | F2: 0.10888583 | G2: =Submetering!AC2-Submetering!AD2 -> 2132 | H2: 0.255129 | I2: =Submetering!Y2+Submetering!Z2 -> 0 | J2: 2.3196173 | K2: =Submetering!AE2 -> 123 | L2: =Submetering!AF2 -> 193
A3: London at Park Lane | B3: =B2+1 -> 2 | C3: 2 | D3: 2020 | E3: =Submetering!E3+Submetering!F3+Submetering!G3 -> 17948 | F3: 0.10888583 | G3: =Submetering!AC3 -> 3132 | H3: 0.255129 | I3: =Submetering!F3+Submetering!G3 -> 10003 | J3: 2.3196173 | K3: =Submetering!AE3 -> 133 | L3: =Submetering!AF3 -> 173
A4: London at Park Lane | B4: =B3+1 -> 3 | C4: 2 | D4: 2020 | E4: =Submetering!E4+Submetering!F4+Submetering!G4 -> 17768 | F4: 0.10888583 | G4: =Submetering!AC4 -> 3107 | H4: 0.255129 | I4: =Submetering!F4+Submetering!G4 -> 9850 | J4: 2.3196173 | K4: =Submetering!AE4 -> 138 | L4: =Submetering!AF4 -> 200
A5: London at Park Lane | B5: =B4+1 -> 4 | C5: 2 | D5: 2020 | E5: =Submetering!E5+Submetering!F5+Submetering!G5 -> 18009 | F5: 0.10888583 | G5: =Submetering!AC5 -> 2908 | H5: 0.255129 | I5: =Submetering!F5+Submetering!G5 -> 10088 | J5: 2.3196173 | K5: =Submetering!AE5 -> 130 | L5: =Submetering!AF5 -> 151
A6: London at Park Lane | B6: =B5+1 -> 5 | C6: 2 | D6: 2020 | E6: =Submetering!E6+Submetering!F6+Submetering!G6 -> 18103 | F6: 0.10888583 | G6: =Submetering!AC6 -> 2465 | H6: 0.255129 | I6: =Submetering!F6+Submetering!G6 -> 9885 | J6: 2.3196173 | K6: =Submetering!AE6 -> 138 | L6: =Submetering!AF6 -> 200
A7: London at Park Lane | B7: =B6+1 -> 6 | C7: 2 | D7: 2020 | E7: =Submetering!E7+Submetering!F7+Submetering!G7 -> 18155 | F7: 0.10888583 | G7: =Submetering!AC7 -> 2491 | H7: 0.255129 | I7: =Submetering!F7+Submetering!G7 -> 9824 | J7: 2.3196173 | K7: =Submetering!AE7 -> 134 | L7: =Submetering!AF7 -> 180
A8: London at Park Lane | B8: =B7+1 -> 7 | C8: 2 | D8: 2020 | E8: =Submetering!E8+Submetering!F8+Submetering!G8 -> 19086 | F8: 0.10888583 | G8: =Submetering!AC8 -> 2627 | H8: 0.255129 | I8: =Submetering!F8+Submetering!G8 -> 10349 | J8: 2.3196173 | K8: =Submetering!AE8 -> 158 | L8: =Submetering!AF8 -> 224
A9: London at Park Lane | B9: =B8+1 -> 8 | C9: 2 | D9: 2020 | E9: =Submetering!E9+Submetering!F9+Submetering!G9 -> 17928 | F9: 0.10888583 | G9: =Submetering!AC9 -> 2282 | H9: 0.255129 | I9: =Submetering!F9+Submetering!G9 -> 9505 | J9: 2.3196173 | K9: =Submetering!AE9 -> 151 | L9: =Submetering!AF9 -> 238
A10: London at Park Lane | B10: =B9+1 -> 9 | C10: 2 | D10: 2020 | E10: =Submetering!E10+Submetering!F10+Submetering!G10 -> 18061 | F10: 0.10888583 | G10: =Submetering!AC10 -> 2501 | H10: 0.255129 | I10: =Submetering!F10+Submetering!G10 -> 10048 | J10: 2.3196173 | K10: =Submetering!AE10 -> 151 | L10: =Submetering!AF10 -> 248
A11: London at Park Lane | B11: =B10+1 -> 10 | C11: 2 | D11: 2020 | E11: =Submetering!E11+Submetering!F11+Submetering!G11 -> 17780 | F11: 0.10888583 | G11: =Submetering!AC11 -> 2549 | H11: 0.255129 | I11: =Submetering!F11+Submetering!G11 -> 9932 | J11: 2.3196173 | K11: =Submetering!AE11 -> 142 | L11: =Submetering!AF11 -> 228
A12: London at Park Lane | B12: =B11+1 -> 11 | C12: 2 | D12: 2020 | E12: =Submetering!E12+Submetering!F12+Submetering!G12 -> 17721 | F12: 0.10888583 | G12: =Submetering!AC12 -> 2722 | H12: 0.255129 | I12: =Submetering!F12+Submetering!G12 -> 9919 | J12: 2.3196173 | K12: =Submetering!AE12 -> 141 | L12: =Submetering!AF12 -> 209
A13: London at Park Lane | B13: =B12+1 -> 12 | C13: 2 | D13: 2020 | E13: =Submetering!E13+Submetering!F13+Submetering!G13 -> 18267 | F13: 0.10888583 | G13: =Submetering!AC13 -> 2400 | H13: 0.255129 | I13: =Submetering!F13+Submetering!G13 -> 9938 | J13: 2.3196173 | K13: =Submetering!AE13 -> 142 | L13: =Submetering!AF13 -> 202
A14: London at Park Lane | B14: =B13+1 -> 13 | C14: 2 | D14: 2020 | E14: =Submetering!E14+Submetering!F14+Submetering!G14 -> 19408 | F14: 0.10888583 | G14: =Submetering!AC14 -> 2332 | H14: 0.255129 | I14: =Submetering!F14+Submetering!G14 -> 10462 | J14: 2.3196173 | K14: =Submetering!AE14 -> 130 | L14: =Submetering!AF14 -> 169
... A29: London at Park Lane | B29: =B28+1 -> 28 | C29: 2 | D29: 2020 | E29: =Submetering!E29+Submetering!F29+Submetering!G29 -> 27106 | F29: 0.10888583 | G29: =Submetering!AC29 -> 2053 | H29: 0.255129 | I29: =Submetering!F29+Submetering!G29 -> 9758 | J29: 2.3196173 | K29: =Submetering!AE29 -> 134 | L29: =Submetering!AF29 -> 193

Sheet Submetering
A1: Site Name | B1: Day | C1: Month | D1: Year | E1: LV Panel 1 KWh | F1: LV Panel 2 KWh | G1: CHP KWh | H1: MCC9 KWh | I1: GF Panel KWh | J1: Kitchen Switch. KWh | K1: Kitchen Panel KWh | L1: MCC3 (AHU) KWh | M1: MCC8 KWh | N1: 1st Floor Plan (KWh) | O1: MCC6(1st floor AHU) KWh | P1: Chiller 1 KWh | Q1: Chiller 2 KWh | R1: MCC 10 (Mechanical Services) KWh | S1: MCC2 CHW KWh | T1: MCC7 (Kitchen) KWh | U1: MCC 5 (Mechanical services) KWh | V1: MCC 4 (Water Services) KWh | W1: MCC1 (KWh) | X1: Laundry db KWh | Y1: City Water 1 m3 | Z1: City Water 2 m3 | AA1: Laundry CW m3 | AB1: Laundry HW m3 | AC1: Natural Gas m3 | AD1: CHP Natural Gas m3 | AE1: Room Nights | AF1: Total Guests
A2: London at Park Lane | B2: 1 | C2: 2 | D2: 2020 | E2: =IF(('FSLPL Daily '!C4-'FSLPL Daily '!C3<0), "0",'FSLPL Daily '!C4-'FSLPL Daily '!C3) -> 8036 | F2: =IF(('FSLPL Daily '!E4-'FSLPL Daily '!E3<0), "0",'FSLPL Daily '!E4-'FSLPL Daily '!E3) -> 6127 | G2: =IF(('FSLPL Daily '!G4-'FSLPL Daily '!G3<0), "0",'FSLPL Daily '!G4-'FSLPL Daily '!G3) -> 3911 | H2: =IF(('FSLPL Daily '!I4-'FSLPL Daily '!I3<0), "",'FSLPL Daily '!I4-'FSLPL Daily '!I3) -> 423 | I2: =IF(('FSLPL Daily '!K4-'FSLPL Daily '!K3<0), "",'FSLPL Daily '!K4-'FSLPL Daily '!K3) -> 862 | J2: =IF(('FSLPL Daily '!M4-'FSLPL Daily '!M3<0), "",'FSLPL Daily '!M4-'FSLPL Daily '!M3) -> 1524 | K2: =IF(('FSLPL Daily '!O4-'FSLPL Daily '!O3<0), "",'FSLPL Daily '!O4-'FSLPL Daily '!O3) -> 671 | L2: =IF(('FSLPL Daily '!Q4-'FSLPL Daily '!Q3<0), "",'FSLPL Daily '!Q4-'FSLPL Daily '!Q3) -> 351 | M2: =IF(('FSLPL Daily '!S4-'FSLPL Daily '!S3<0), "",'FSLPL Daily '!S4-'FSLPL Daily '!S3) -> 10 | N2: =IF(('FSLPL Daily '!U4-'FSLPL Daily '!U3<0), "",'FSLPL Daily '!U4-'FSLPL Daily '!U3) -> 1120 | O2: =IF(('FSLPL Daily '!W4-'FSLPL Daily '!W3<0), "",'FSLPL Daily '!W4-'FSLPL Daily '!W3) -> 152 | P2: =IF(('FSLPL Daily '!Y4-'FSLPL Daily '!Y3<0), "",'FSLPL Daily '!Y4-'FSLPL Daily '!Y3) -> 1102 | Q2: =IF(('FSLPL Daily '!AA4-'FSLPL Daily '!AA3<0), "",'FSLPL Daily '!AA4-'FSLPL Daily '!AA3) -> 3 | R2: =IF(('FSLPL Daily '!AC4-'FSLPL Daily '!AC3<0), "",'FSLPL Daily '!AC4-'FSLPL Daily '!AC3) -> 1443 | S2: =IF(('FSLPL Daily '!AE4-'FSLPL Daily '!AE3<0), "",'FSLPL Daily '!AE4-'FSLPL Daily '!AE3) -> 2076 | T2: =IF(('FSLPL Daily '!AG4-'FSLPL Daily '!AG3<0), "",'FSLPL Daily '!AG4-'FSLPL Daily '!AG3) -> 374 | U2: =IF(('FSLPL Daily '!AI4-'FSLPL Daily '!AI3<0), "",'FSLPL Daily '!AI4-'FSLPL Daily '!AI3) -> 20 | V2: =IF(('FSLPL Daily '!AK4-'FSLPL Daily '!AK3<0), "",'FSLPL Daily '!AK4-'FSLPL Daily '!AK3) -> 400 | W2: =IF(('FSLPL Daily '!AM4-'FSLPL Daily '!AM3<0), "",'FSLPL Daily '!AM4-'FSLPL Daily '!AM3) -> 669 | X2: =IF(('FSLPL Daily '!AO4-'FSLPL Daily '!AO3<0), "",'FSLPL Daily '!AO4-'FSLPL Daily '!AO3) -> 720 | Y2: =IF(('FSLPL Daily '!AR4-'FSLPL Daily '!AR3<0), "0",'FSLPL Daily '!AR4-'FSLPL Daily '!AR3) -> 0 | Z2: =IF(('FSLPL Daily '!AT4-'FSLPL Daily '!AT3<0), "0",'FSLPL Daily '!AT4-'FSLPL Daily '!AT3) -> 0 | AA2: =IF(('FSLPL Daily '!AV4-'FSLPL Daily '!AV3<0), "0",'FSLPL Daily '!AV4-'FSLPL Daily '!AV3) -> 28 | AB2: =IF(('FSLPL Daily '!AX4-'FSLPL Daily '!AX3<0), "",'FSLPL Daily '!AX4-'FSLPL Daily '!AX3) -> 13 | AC2: =IF(('FSLPL Daily '!AZ4-'FSLPL Daily '!AZ3<0), "0",'FSLPL Daily '!AZ4-'FSLPL Daily '!AZ3) -> 3258 | AD2: =IF(('FSLPL Daily '!BB4-'FSLPL Daily '!BB3<0), "0",'FSLPL Daily '!BB4-'FSLPL Daily '!BB3) -> 1126 | AE2: ='FSLPL Daily '!BD4 -> 123 | AF2: ='FSLPL Daily '!BE4 -> 193
A3: London at Park Lane | B3: =B2+1 -> 2 | C3: 2 | D3: 2020 | E3: =IF(('FSLPL Daily '!C5-'FSLPL Daily '!C4<0), "0",'FSLPL Daily '!C5-'FSLPL Daily '!C4) -> 7945 | F3: =IF(('FSLPL Daily '!E5-'FSLPL Daily '!E4<0), "0",'FSLPL Daily '!E5-'FSLPL Daily '!E4) -> 6167 | G3: =IF(('FSLPL Daily '!G5-'FSLPL Daily '!G4<0), "0",'FSLPL Daily '!G5-'FSLPL Daily '!G4) -> 3836 | H3: =IF(('FSLPL Daily '!I5-'FSLPL Daily '!I4<0), "",'FSLPL Daily '!I5-'FSLPL Daily '!I4) -> 424 | I3: =IF(('FSLPL Daily '!K5-'FSLPL Daily '!K4<0), "",'FSLPL Daily '!K5-'FSLPL Daily '!K4) -> 845 | J3: =IF(('FSLPL Daily '!M5-'FSLPL Daily '!M4<0), "",'FSLPL Daily '!M5-'FSLPL Daily '!M4) -> 1534 | K3: =IF(('FSLPL Daily '!O5-'FSLPL Daily '!O4<0), "",'FSLPL Daily '!O5-'FSLPL Daily '!O4) -> 703 | L3: =IF(('FSLPL Daily '!Q5-'FSLPL Daily '!Q4<0), "",'FSLPL Daily '!Q5-'FSLPL Daily '!Q4) -> 347 | M3: =IF(('FSLPL Daily '!S5-'FSLPL Daily '!S4<0), "",'FSLPL Daily '!S5-'FSLPL Daily '!S4) -> 15 | N3: =IF(('FSLPL Daily '!U5-'FSLPL Daily '!U4<0), "",'FSLPL Daily '!U5-'FSLPL Daily '!U4) -> 1017 | O3: =IF(('FSLPL Daily '!W5-'FSLPL Daily '!W4<0), "",'FSLPL Daily '!W5-'FSLPL Daily '!W4) -> 56 | P3: =IF(('FSLPL Daily '!Y5-'FSLPL Daily '!Y4<0), "",'FSLPL Daily '!Y5-'FSLPL Daily '!Y4) -> 1167 | Q3: =IF(('FSLPL Daily '!AA5-'FSLPL Daily '!AA4<0), "",'FSLPL Daily '!AA5-'FSLPL Daily '!AA4) -> 2 | R3: =IF(('FSLPL Daily '!AC5-'FSLPL Daily '!AC4<0), "",'FSLPL Daily '!AC5-'FSLPL Daily '!AC4) -> 1439 | S3: =IF(('FSLPL Daily '!AE5-'FSLPL Daily '!AE4<0), "",'FSLPL Daily '!AE5-'FSLPL Daily '!AE4) -> 2069 | T3: =IF(('FSLPL Daily '!AG5-'FSLPL Daily '!AG4<0), "",'FSLPL Daily '!AG5-'FSLPL Daily '!AG4) -> 375 | U3: =IF(('FSLPL Daily '!AI5-'FSLPL Daily '!AI4<0), "",'FSLPL Daily '!AI5-'FSLPL Daily '!AI4) -> 20 | V3: =IF(('FSLPL Daily '!AK5-'FSLPL Daily '!AK4<0), "",'FSLPL Daily '!AK5-'FSLPL Daily '!AK4) -> 389 | W3: =IF(('FSLPL Daily '!AM5-'FSLPL Daily '!AM4<0), "",'FSLPL Daily '!AM5-'FSLPL Daily '!AM4) -> 664 | X3: =IF(('FSLPL Daily '!AO5-'FSLPL Daily '!AO4<0), "",'FSLPL Daily '!AO5-'FSLPL Daily '!AO4) -> 706 | Y3: =IF(('FSLPL Daily '!AR5-'FSLPL Daily '!AR4<0), "",'FSLPL Daily '!AR5-'FSLPL Daily '!AR4) -> 0 | Z3: =IF(('FSLPL Daily '!AT5-'FSLPL Daily '!AT4<0), "",'FSLPL Daily '!AT5-'FSLPL Daily '!AT4) -> 0 | AA3: =IF(('FSLPL Daily '!AV5-'FSLPL Daily '!AV4<0), "",'FSLPL Daily '!AV5-'FSLPL Daily '!AV4) -> 39 | AB3: =IF(('FSLPL Daily '!AX5-'FSLPL Daily '!AX4<0), "",'FSLPL Daily '!AX5-'FSLPL Daily '!AX4) -> 8 | AC3: =IF(('FSLPL Daily '!AZ5-'FSLPL Daily '!AZ4<0), "",'FSLPL Daily '!AZ5-'FSLPL Daily '!AZ4) -> 3132 | AD3: =IF(('FSLPL Daily '!BB5-'FSLPL Daily '!BB4<0), "",'FSLPL Daily '!BB5-'FSLPL Daily '!BB4) -> 1099 | AE3: ='FSLPL Daily '!BD5 -> 133 | AF3: ='FSLPL Daily '!BE5 -> 173
A4: London at Park Lane | B4: =B3+1 -> 3 | C4: 2 | D4: 2020 | E4: =IF(('FSLPL Daily '!C6-'FSLPL Daily '!C5<0), "0",'FSLPL Daily '!C6-'FSLPL Daily '!C5) -> 7918 | F4: =IF(('FSLPL Daily '!E6-'FSLPL Daily '!E5<0), "0",'FSLPL Daily '!E6-'FSLPL Daily '!E5) -> 6047 | G4: =IF(('FSLPL Daily '!G6-'FSLPL Daily '!G5<0), "0",'FSLPL Daily '!G6-'FSLPL Daily '!G5) -> 3803 | H4: =IF(('FSLPL Daily '!I6-'FSLPL Daily '!I5<0), "",'FSLPL Daily '!I6-'FSLPL Daily '!I5) -> 446 | I4: =IF(('FSLPL Daily '!K6-'FSLPL Daily '!K5<0), "",'FSLPL Daily '!K6-'FSLPL Daily '!K5) -> 835 | J4: =IF(('FSLPL Daily '!M6-'FSLPL Daily '!M5<0), "",'FSLPL Daily '!M6-'FSLPL Daily '!M5) -> 1408 | K4: =IF(('FSLPL Daily '!O6-'FSLPL Daily '!O5<0), "",'FSLPL Daily '!O6-'FSLPL Daily '!O5) -> 699 | L4: =IF(('FSLPL Daily '!Q6-'FSLPL Daily '!Q5<0), "",'FSLPL Daily '!Q6-'FSLPL Daily '!Q5) -> 350 | M4: =IF(('FSLPL Daily '!S6-'FSLPL Daily '!S5<0), "",'FSLPL Daily '!S6-'FSLPL Daily '!S5) -> 19 | N4: =IF(('FSLPL Daily '!U6-'FSLPL Daily '!U5<0), "",'FSLPL Daily '!U6-'FSLPL Daily '!U5) -> 1074 | O4: =IF(('FSLPL Daily '!W6-'FSLPL Daily '!W5<0), "",'FSLPL Daily '!W6-'FSLPL Daily '!W5) -> 194 | P4: =IF(('FSLPL Daily '!Y6-'FSLPL Daily '!Y5<0), "",'FSLPL Daily '!Y6-'FSLPL Daily '!Y5) -> 1202 | Q4: =IF(('FSLPL Daily '!AA6-'FSLPL Daily '!AA5<0), "",'FSLPL Daily '!AA6-'FSLPL Daily '!AA5) -> 2 | R4: =IF(('FSLPL Daily '!AC6-'FSLPL Daily '!AC5<0), "",'FSLPL Daily '!AC6-'FSLPL Daily '!AC5) -> 1457 | S4: =IF(('FSLPL Daily '!AE6-'FSLPL Daily '!AE5<0), "",'FSLPL Daily '!AE6-'FSLPL Daily '!AE5) -> 2058 | T4: =IF(('FSLPL Daily '!AG6-'FSLPL Daily '!AG5<0), "",'FSLPL Daily '!AG6-'FSLPL Daily '!AG5) -> 373 | U4: =IF(('FSLPL Daily '!AI6-'FSLPL Daily '!AI5<0), "",'FSLPL Daily '!AI6-'FSLPL Daily '!AI5) -> 20 | V4: =IF(('FSLPL Daily '!AK6-'FSLPL Daily '!AK5<0), "",'FSLPL Daily '!AK6-'FSLPL Daily '!AK5) -> 392 | W4: =IF(('FSLPL Daily '!AM6-'FSLPL Daily '!AM5<0), "",'FSLPL Daily '!AM6-'FSLPL Daily '!AM5) -> 662 | X4: =IF(('FSLPL Daily '!AO6-'FSLPL Daily '!AO5<0), "",'FSLPL Daily '!AO6-'FSLPL Daily '!AO5) -> 720 | Y4: =IF(('FSLPL Daily '!AR6-'FSLPL Daily '!AR5<0), "",'FSLPL Daily '!AR6-'FSLPL Daily '!AR5) -> 0 | Z4: =IF(('FSLPL Daily '!AT6-'FSLPL Daily '!AT5<0), "",'FSLPL Daily '!AT6-'FSLPL Daily '!AT5) -> 0 | AA4: =IF(('FSLPL Daily '!AV6-'FSLPL Daily '!AV5<0), "",'FSLPL Daily '!AV6-'FSLPL Daily '!AV5) -> 40 | AB4: =IF(('FSLPL Daily '!AX6-'FSLPL Daily '!AX5<0), "",'FSLPL Daily '!AX6-'FSLPL Daily '!AX5) -> 11 | AC4: =IF(('FSLPL Daily '!AZ6-'FSLPL Daily '!AZ5<0), "",'FSLPL Daily '!AZ6-'FSLPL Daily '!AZ5) -> 3107 | AD4: =IF(('FSLPL Daily '!BB6-'FSLPL Daily '!BB5<0), "",'FSLPL Daily '!BB6-'FSLPL Daily '!BB5) -> 1073 | AE4: ='FSLPL Daily '!BD6 -> 138 | AF4: ='FSLPL Daily '!BE6 -> 200
A5: London at Park Lane | B5: =B4+1 -> 4 | C5: 2 | D5: 2020 | E5: =IF(('FSLPL Daily '!C7-'FSLPL Daily '!C6<0), "0",'FSLPL Daily '!C7-'FSLPL Daily '!C6) -> 7921 | F5: =IF(('FSLPL Daily '!E7-'FSLPL Daily '!E6<0), "0",'FSLPL Daily '!E7-'FSLPL Daily '!E6) -> 6128 | G5: =IF(('FSLPL Daily '!G7-'FSLPL Daily '!G6<0), "0",'FSLPL Daily '!G7-'FSLPL Daily '!G6) -> 3960 | H5: =IF(('FSLPL Daily '!I7-'FSLPL Daily '!I6<0), "",'FSLPL Daily '!I7-'FSLPL Daily '!I6) -> 467 | I5: =IF(('FSLPL Daily '!K7-'FSLPL Daily '!K6<0), "",'FSLPL Daily '!K7-'FSLPL Daily '!K6) -> 840 | J5: =IF(('FSLPL Daily '!M7-'FSLPL Daily '!M6<0), "",'FSLPL Daily '!M7-'FSLPL Daily '!M6) -> 1375 | K5: =IF(('FSLPL Daily '!O7-'FSLPL Daily '!O6<0), "",'FSLPL Daily '!O7-'FSLPL Daily '!O6) -> 728 | L5: =IF(('FSLPL Daily '!Q7-'FSLPL Daily '!Q6<0), "",'FSLPL Daily '!Q7-'FSLPL Daily '!Q6) -> 354 | M5: =IF(('FSLPL Daily '!S7-'FSLPL Daily '!S6<0), "",'FSLPL Daily '!S7-'FSLPL Daily '!S6) -> 20 | N5: =IF(('FSLPL Daily '!U7-'FSLPL Daily '!U6<0), "",'FSLPL Daily '!U7-'FSLPL Daily '!U6) -> 1025 | O5: =IF(('FSLPL Daily '!W7-'FSLPL Daily '!W6<0), "",'FSLPL Daily '!W7-'FSLPL Daily '!W6) -> 119 | P5: =IF(('FSLPL Daily '!Y7-'FSLPL Daily '!Y6<0), "",'FSLPL Daily '!Y7-'FSLPL Daily '!Y6) -> 1250 | Q5: =IF(('FSLPL Daily '!AA7-'FSLPL Daily '!AA6<0), "",'FSLPL Daily '!AA7-'FSLPL Daily '!AA6) -> 2 | R5: =IF(('FSLPL Daily '!AC7-'FSLPL Daily '!AC6<0), "",'FSLPL Daily '!AC7-'FSLPL Daily '!AC6) -> 1480 | S5: =IF(('FSLPL Daily '!AE7-'FSLPL Daily '!AE6<0), "",'FSLPL Daily '!AE7-'FSLPL Daily '!AE6) -> 2084 | T5: =IF(('FSLPL Daily '!AG7-'FSLPL Daily '!AG6<0), "",'FSLPL Daily '!AG7-'FSLPL Daily '!AG6) -> 381 | U5: =IF(('FSLPL Daily '!AI7-'FSLPL Daily '!AI6<0), "",'FSLPL Daily '!AI7-'FSLPL Daily '!AI6) -> 21 | V5: =IF(('FSLPL Daily '!AK7-'FSLPL Daily '!AK6<0), "",'FSLPL Daily '!AK7-'FSLPL Daily '!AK6) -> 378 | W5: =IF(('FSLPL Daily '!AM7-'FSLPL Daily '!AM6<0), "",'FSLPL Daily '!AM7-'FSLPL Daily '!AM6) -> 656 | X5: =IF(('FSLPL Daily '!AO7-'FSLPL Daily '!AO6<0), "",'FSLPL Daily '!AO7-'FSLPL Daily '!AO6) -> 698 | Y5: =IF(('FSLPL Daily '!AR7-'FSLPL Daily '!AR6<0), "",'FSLPL Daily '!AR7-'FSLPL Daily '!AR6) -> 0 | Z5: =IF(('FSLPL Daily '!AT7-'FSLPL Daily '!AT6<0), "",'FSLPL Daily '!AT7-'FSLPL Daily '!AT6) -> 0 | AA5: =IF(('FSLPL Daily '!AV7-'FSLPL Daily '!AV6<0), "",'FSLPL Daily '!AV7-'FSLPL Daily '!AV6) -> 30 | AB5: =IF(('FSLPL Daily '!AX7-'FSLPL Daily '!AX6<0), "",'FSLPL Daily '!AX7-'FSLPL Daily '!AX6) -> 7 | AC5: =IF(('FSLPL Daily '!AZ7-'FSLPL Daily '!AZ6<0), "",'FSLPL Daily '!AZ7-'FSLPL Daily '!AZ6) -> 2908 | AD5: =IF(('FSLPL Daily '!BB7-'FSLPL Daily '!BB6<0), "",'FSLPL Daily '!BB7-'FSLPL Daily '!BB6) -> 1109 | AE5: ='FSLPL Daily '!BD7 -> 130 | AF5: ='FSLPL Daily '!BE7 -> 151
A6: London at Park Lane | B6: =B5+1 -> 5 | C6: 2 | D6: 2020 | E6: =IF(('FSLPL Daily '!C8-'FSLPL Daily '!C7<0), "0",'FSLPL Daily '!C8-'FSLPL Daily '!C7) -> 8218 | F6: =IF(('FSLPL Daily '!E8-'FSLPL Daily '!E7<0), "0",'FSLPL Daily '!E8-'FSLPL Daily '!E7) -> 6058 | G6: =IF(('FSLPL Daily '!G8-'FSLPL Daily '!G7<0), "0",'FSLPL Daily '!G8-'FSLPL Daily '!G7) -> 3827 | H6: =IF(('FSLPL Daily '!I8-'FSLPL Daily '!I7<0), "",'FSLPL Daily '!I8-'FSLPL Daily '!I7) -> 411 | I6: =IF(('FSLPL Daily '!K8-'FSLPL Daily '!K7<0), "",'FSLPL Daily '!K8-'FSLPL Daily '!K7) -> 859 | J6: =IF(('FSLPL Daily '!M8-'FSLPL Daily '!M7<0), "",'FSLPL Daily '!M8-'FSLPL Daily '!M7) -> 1424 | K6: =IF(('FSLPL Daily '!O8-'FSLPL Daily '!O7<0), "",'FSLPL Daily '!O8-'FSLPL Daily '!O7) -> 703 | L6: =IF(('FSLPL Daily '!Q8-'FSLPL Daily '!Q7<0), "",'FSLPL Daily '!Q8-'FSLPL Daily '!Q7) -> 344 | M6: =IF(('FSLPL Daily '!S8-'FSLPL Daily '!S7<0), "",'FSLPL Daily '!S8-'FSLPL Daily '!S7) -> 23 | N6: =IF(('FSLPL Daily '!U8-'FSLPL Daily '!U7<0), "",'FSLPL Daily '!U8-'FSLPL Daily '!U7) -> 1170 | O6: =IF(('FSLPL Daily '!W8-'FSLPL Daily '!W7<0), "",'FSLPL Daily '!W8-'FSLPL Daily '!W7) -> 165 | P6: =IF(('FSLPL Daily '!Y8-'FSLPL Daily '!Y7<0), "",'FSLPL Daily '!Y8-'FSLPL Daily '!Y7) -> 1286 | Q6: =IF(('FSLPL Daily '!AA8-'FSLPL Daily '!AA7<0), "",'FSLPL Daily '!AA8-'FSLPL Daily '!AA7) -> 3 | R6: =IF(('FSLPL Daily '!AC8-'FSLPL Daily '!AC7<0), "",'FSLPL Daily '!AC8-'FSLPL Daily '!AC7) -> 1444 | S6: =IF(('FSLPL Daily '!AE8-'FSLPL Daily '!AE7<0), "",'FSLPL Daily '!AE8-'FSLPL Daily '!AE7) -> 2045 | T6: =IF(('FSLPL Daily '!AG8-'FSLPL Daily '!AG7<0), "",'FSLPL Daily '!AG8-'FSLPL Daily '!AG7) -> 374 | U6: =IF(('FSLPL Daily '!AI8-'FSLPL Daily '!AI7<0), "",'FSLPL Daily '!AI8-'FSLPL Daily '!AI7) -> 20 | V6: =IF(('FSLPL Daily '!AK8-'FSLPL Daily '!AK7<0), "",'FSLPL Daily '!AK8-'FSLPL Daily '!AK7) -> 375 | W6: =IF(('FSLPL Daily '!AM8-'FSLPL Daily '!AM7<0), "",'FSLPL Daily '!AM8-'FSLPL Daily '!AM7) -> 616 | X6: =IF(('FSLPL Daily '!AO8-'FSLPL Daily '!AO7<0), "",'FSLPL Daily '!AO8-'FSLPL Daily '!AO7) -> 614 | Y6: =IF(('FSLPL Daily '!AR8-'FSLPL Daily '!AR7<0), "",'FSLPL Daily '!AR8-'FSLPL Daily '!AR7) -> 0 | Z6: =IF(('FSLPL Daily '!AT8-'FSLPL Daily '!AT7<0), "",'FSLPL Daily '!AT8-'FSLPL Daily '!AT7) -> 0 | AA6: =IF(('FSLPL Daily '!AV8-'FSLPL Daily '!AV7<0), "",'FSLPL Daily '!AV8-'FSLPL Daily '!AV7) -> 30 | AB6: =IF(('FSLPL Daily '!AX8-'FSLPL Daily '!AX7<0), "",'FSLPL Daily '!AX8-'FSLPL Daily '!AX7) -> 7 | AC6: =IF(('FSLPL Daily '!AZ8-'FSLPL Daily '!AZ7<0), "",'FSLPL Daily '!AZ8-'FSLPL Daily '!AZ7) -> 2465 | AD6: =IF(('FSLPL Daily '!BB8-'FSLPL Daily '!BB7<0), "",'FSLPL Daily '!BB8-'FSLPL Daily '!BB7) -> 1081 | AE6: ='FSLPL Daily '!BD8 -> 138 | AF6: ='FSLPL Daily '!BE8 -> 200
A7: London at Park Lane | B7: =B6+1 -> 6 | C7: 2 | D7: 2020 | E7: =IF(('FSLPL Daily '!C9-'FSLPL Daily '!C8<0), "0",'FSLPL Daily '!C9-'FSLPL Daily '!C8) -> 8331 | F7: =IF(('FSLPL Daily '!E9-'FSLPL Daily '!E8<0), "0",'FSLPL Daily '!E9-'FSLPL Daily '!E8) -> 5968 | G7: =IF(('FSLPL Daily '!G9-'FSLPL Daily '!G8<0), "0",'FSLPL Daily '!G9-'FSLPL Daily '!G8) -> 3856 | H7: =IF(('FSLPL Daily '!I9-'FSLPL Daily '!I8<0), "",'FSLPL Daily '!I9-'FSLPL Daily '!I8) -> 403 | I7: =IF(('FSLPL Daily '!K9-'FSLPL Daily '!K8<0), "",'FSLPL Daily '!K9-'FSLPL Daily '!K8) -> 857 | J7: =IF(('FSLPL Daily '!M9-'FSLPL Daily '!M8<0), "",'FSLPL Daily '!M9-'FSLPL Daily '!M8) -> 1459 | K7: =IF(('FSLPL Daily '!O9-'FSLPL Daily '!O8<0), "",'FSLPL Daily '!O9-'FSLPL Daily '!O8) -> 681 | L7: =IF(('FSLPL Daily '!Q9-'FSLPL Daily '!Q8<0), "",'FSLPL Daily '!Q9-'FSLPL Daily '!Q8) -> 349 | M7: =IF(('FSLPL Daily '!S9-'FSLPL Daily '!S8<0), "",'FSLPL Daily '!S9-'FSLPL Daily '!S8) -> 25 | N7: =IF(('FSLPL Daily '!U9-'FSLPL Daily '!U8<0), "",'FSLPL Daily '!U9-'FSLPL Daily '!U8) -> 1172 | O7: =IF(('FSLPL Daily '!W9-'FSLPL Daily '!W8<0), "",'FSLPL Daily '!W9-'FSLPL Daily '!W8) -> 177 | P7: =IF(('FSLPL Daily '!Y9-'FSLPL Daily '!Y8<0), "",'FSLPL Daily '!Y9-'FSLPL Daily '!Y8) -> 1301 | Q7: =IF(('FSLPL Daily '!AA9-'FSLPL Daily '!AA8<0), "",'FSLPL Daily '!AA9-'FSLPL Daily '!AA8) -> 2 | R7: =IF(('FSLPL Daily '!AC9-'FSLPL Daily '!AC8<0), "",'FSLPL Daily '!AC9-'FSLPL Daily '!AC8) -> 1394 | S7: =IF(('FSLPL Daily '!AE9-'FSLPL Daily '!AE8<0), "",'FSLPL Daily '!AE9-'FSLPL Daily '!AE8) -> 2056 | T7: =IF(('FSLPL Daily '!AG9-'FSLPL Daily '!AG8<0), "",'FSLPL Daily '!AG9-'FSLPL Daily '!AG8) -> 341 | U7: =IF(('FSLPL Daily '!AI9-'FSLPL Daily '!AI8<0), "",'FSLPL Daily '!AI9-'FSLPL Daily '!AI8) -> 21 | V7: =IF(('FSLPL Daily '!AK9-'FSLPL Daily '!AK8<0), "",'FSLPL Daily '!AK9-'FSLPL Daily '!AK8) -> 379 | W7: =IF(('FSLPL Daily '!AM9-'FSLPL Daily '!AM8<0), "",'FSLPL Daily '!AM9-'FSLPL Daily '!AM8) -> 621 | X7: =IF(('FSLPL Daily '!AO9-'FSLPL Daily '!AO8<0), "",'FSLPL Daily '!AO9-'FSLPL Daily '!AO8) -> 689 | Y7: =IF(('FSLPL Daily '!AR9-'FSLPL Daily '!AR8<0), "",'FSLPL Daily '!AR9-'FSLPL Daily '!AR8) -> 0 | Z7: =IF(('FSLPL Daily '!AT9-'FSLPL Daily '!AT8<0), "",'FSLPL Daily '!AT9-'FSLPL Daily '!AT8) -> 0 | AA7: =IF(('FSLPL Daily '!AV9-'FSLPL Daily '!AV8<0), "",'FSLPL Daily '!AV9-'FSLPL Daily '!AV8) -> 20 | AB7: =IF(('FSLPL Daily '!AX9-'FSLPL Daily '!AX8<0), "",'FSLPL Daily '!AX9-'FSLPL Daily '!AX8) -> 8 | AC7: =IF(('FSLPL Daily '!AZ9-'FSLPL Daily '!AZ8<0), "",'FSLPL Daily '!AZ9-'FSLPL Daily '!AZ8) -> 2491 | AD7: =IF(('FSLPL Daily '!BB9-'FSLPL Daily '!BB8<0), "",'FSLPL Daily '!BB9-'FSLPL Daily '!BB8) -> 1086 | AE7: ='FSLPL Daily '!BD9 -> 134 | AF7: ='FSLPL Daily '!BE9 -> 180
A8: London at Park Lane | B8: =B7+1 -> 7 | C8: 2 | D8: 2020 | E8: =IF(('FSLPL Daily '!C10-'FSLPL Daily '!C9<0), "0",'FSLPL Daily '!C10-'FSLPL Daily '!C9) -> 8737 | F8: =IF(('FSLPL Daily '!E10-'FSLPL Daily '!E9<0), "0",'FSLPL Daily '!E10-'FSLPL Daily '!E9) -> 6114 | G8: =IF(('FSLPL Daily '!G10-'FSLPL Daily '!G9<0), "0",'FSLPL Daily '!G10-'FSLPL Daily '!G9) -> 4235 | H8: =IF(('FSLPL Daily '!I10-'FSLPL Daily '!I9<0), "",'FSLPL Daily '!I10-'FSLPL Daily '!I9) -> 431 | I8: =IF(('FSLPL Daily '!K10-'FSLPL Daily '!K9<0), "",'FSLPL Daily '!K10-'FSLPL Daily '!K9) -> 898 | J8: =IF(('FSLPL Daily '!M10-'FSLPL Daily '!M9<0), "",'FSLPL Daily '!M10-'FSLPL Daily '!M9) -> 1578 | K8: =IF(('FSLPL Daily '!O10-'FSLPL Daily '!O9<0), "",'FSLPL Daily '!O10-'FSLPL Daily '!O9) -> 719 | L8: =IF(('FSLPL Daily '!Q10-'FSLPL Daily '!Q9<0), "",'FSLPL Daily '!Q10-'FSLPL Daily '!Q9) -> 363 | M8: =IF(('FSLPL Daily '!S10-'FSLPL Daily '!S9<0), "",'FSLPL Daily '!S10-'FSLPL Daily '!S9) -> 24 | N8: =IF(('FSLPL Daily '!U10-'FSLPL Daily '!U9<0), "",'FSLPL Daily '!U10-'FSLPL Daily '!U9) -> 1188 | O8: =IF(('FSLPL Daily '!W10-'FSLPL Daily '!W9<0), "",'FSLPL Daily '!W10-'FSLPL Daily '!W9) -> 196 | P8: =IF(('FSLPL Daily '!Y10-'FSLPL Daily '!Y9<0), "",'FSLPL Daily '!Y10-'FSLPL Daily '!Y9) -> 1320 | Q8: =IF(('FSLPL Daily '!AA10-'FSLPL Daily '!AA9<0), "",'FSLPL Daily '!AA10-'FSLPL Daily '!AA9) -> 2 | R8: =IF(('FSLPL Daily '!AC10-'FSLPL Daily '!AC9<0), "",'FSLPL Daily '!AC10-'FSLPL Daily '!AC9) -> 1406 | S8: =IF(('FSLPL Daily '!AE10-'FSLPL Daily '!AE9<0), "",'FSLPL Daily '!AE10-'FSLPL Daily '!AE9) -> 2074 | T8: =IF(('FSLPL Daily '!AG10-'FSLPL Daily '!AG9<0), "",'FSLPL Daily '!AG10-'FSLPL Daily '!AG9) -> 343 | U8: =IF(('FSLPL Daily '!AI10-'FSLPL Daily '!AI9<0), "",'FSLPL Daily '!AI10-'FSLPL Daily '!AI9) -> 21 | V8: =IF(('FSLPL Daily '!AK10-'FSLPL Daily '!AK9<0), "",'FSLPL Daily '!AK10-'FSLPL Daily '!AK9) -> 407 | W8: =IF(('FSLPL Daily '!AM10-'FSLPL Daily '!AM9<0), "",'FSLPL Daily '!AM10-'FSLPL Daily '!AM9) -> 632 | X8: =IF(('FSLPL Daily '!AO10-'FSLPL Daily '!AO9<0), "",'FSLPL Daily '!AO10-'FSLPL Daily '!AO9) -> 773 | Y8: =IF(('FSLPL Daily '!AR10-'FSLPL Daily '!AR9<0), "",'FSLPL Daily '!AR10-'FSLPL Daily '!AR9) -> 0 | Z8: =IF(('FSLPL Daily '!AT10-'FSLPL Daily '!AT9<0), "",'FSLPL Daily '!AT10-'FSLPL Daily '!AT9) -> 0 | AA8: =IF(('FSLPL Daily '!AV10-'FSLPL Daily '!AV9<0), "",'FSLPL Daily '!AV10-'FSLPL Daily '!AV9) -> 43 | AB8: =IF(('FSLPL Daily '!AX10-'FSLPL Daily '!AX9<0), "",'FSLPL Daily '!AX10-'FSLPL Daily '!AX9) -> 16 | AC8: =IF(('FSLPL Daily '!AZ10-'FSLPL Daily '!AZ9<0), "",'FSLPL Daily '!AZ10-'FSLPL Daily '!AZ9) -> 2627 | AD8: =IF(('FSLPL Daily '!BB10-'FSLPL Daily '!BB9<0), "",'FSLPL Daily '!BB10-'FSLPL Daily '!BB9) -> 1215 | AE8: ='FSLPL Daily '!BD10 -> 158 | AF8: ='FSLPL Daily '!BE10 -> 224
A9: London at Park Lane | B9: =B8+1 -> 8 | C9: 2 | D9: 2020 | E9: =IF(('FSLPL Daily '!C11-'FSLPL Daily '!C10<0), "0",'FSLPL Daily '!C11-'FSLPL Daily '!C10) -> 8423 | F9: =IF(('FSLPL Daily '!E11-'FSLPL Daily '!E10<0), "0",'FSLPL Daily '!E11-'FSLPL Daily '!E10) -> 6003 | G9: =IF(('FSLPL Daily '!G11-'FSLPL Daily '!G10<0), "0",'FSLPL Daily '!G11-'FSLPL Daily '!G10) -> 3502 | H9: =IF(('FSLPL Daily '!I11-'FSLPL Daily '!I10<0), "",'FSLPL Daily '!I11-'FSLPL Daily '!I10) -> 427 | I9: =IF(('FSLPL Daily '!K11-'FSLPL Daily '!K10<0), "",'FSLPL Daily '!K11-'FSLPL Daily '!K10) -> 856 | J9: =IF(('FSLPL Daily '!M11-'FSLPL Daily '!M10<0), "",'FSLPL Daily '!M11-'FSLPL Daily '!M10) -> 1524 | K9: =IF(('FSLPL Daily '!O11-'FSLPL Daily '!O10<0), "",'FSLPL Daily '!O11-'FSLPL Daily '!O10) -> 731 | L9: =IF(('FSLPL Daily '!Q11-'FSLPL Daily '!Q10<0), "",'FSLPL Daily '!Q11-'FSLPL Daily '!Q10) -> 335 | M9: =IF(('FSLPL Daily '!S11-'FSLPL Daily '!S10<0), "",'FSLPL Daily '!S11-'FSLPL Daily '!S10) -> 20 | N9: =IF(('FSLPL Daily '!U11-'FSLPL Daily '!U10<0), "",'FSLPL Daily '!U11-'FSLPL Daily '!U10) -> 1183 | O9: =IF(('FSLPL Daily '!W11-'FSLPL Daily '!W10<0), "",'FSLPL Daily '!W11-'FSLPL Daily '!W10) -> 242 | P9: =IF(('FSLPL Daily '!Y11-'FSLPL Daily '!Y10<0), "",'FSLPL Daily '!Y11-'FSLPL Daily '!Y10) -> 1259 | Q9: =IF(('FSLPL Daily '!AA11-'FSLPL Daily '!AA10<0), "",'FSLPL Daily '!AA11-'FSLPL Daily '!AA10) -> 2 | R9: =IF(('FSLPL Daily '!AC11-'FSLPL Daily '!AC10<0), "",'FSLPL Daily '!AC11-'FSLPL Daily '!AC10) -> 1441 | S9: =IF(('FSLPL Daily '!AE11-'FSLPL Daily '!AE10<0), "",'FSLPL Daily '!AE11-'FSLPL Daily '!AE10) -> 1962 | T9: =IF(('FSLPL Daily '!AG11-'FSLPL Daily '!AG10<0), "",'FSLPL Daily '!AG11-'FSLPL Daily '!AG10) -> 385 | U9: =IF(('FSLPL Daily '!AI11-'FSLPL Daily '!AI10<0), "",'FSLPL Daily '!AI11-'FSLPL Daily '!AI10) -> 19 | V9: =IF(('FSLPL Daily '!AK11-'FSLPL Daily '!AK10<0), "",'FSLPL Daily '!AK11-'FSLPL Daily '!AK10) -> 373 | W9: =IF(('FSLPL Daily '!AM11-'FSLPL Daily '!AM10<0), "",'FSLPL Daily '!AM11-'FSLPL Daily '!AM10) -> 603 | X9: =IF(('FSLPL Daily '!AO11-'FSLPL Daily '!AO10<0), "",'FSLPL Daily '!AO11-'FSLPL Daily '!AO10) -> 648 | Y9: =IF(('FSLPL Daily '!AR11-'FSLPL Daily '!AR10<0), "",'FSLPL Daily '!AR11-'FSLPL Daily '!AR10) -> 0 | Z9: =IF(('FSLPL Daily '!AT11-'FSLPL Daily '!AT10<0), "",'FSLPL Daily '!AT11-'FSLPL Daily '!AT10) -> 0 | AA9: =IF(('FSLPL Daily '!AV11-'FSLPL Daily '!AV10<0), "",'FSLPL Daily '!AV11-'FSLPL Daily '!AV10) -> 26 | AB9: =IF(('FSLPL Daily '!AX11-'FSLPL Daily '!AX10<0), "",'FSLPL Daily '!AX11-'FSLPL Daily '!AX10) -> 11 | AC9: =IF(('FSLPL Daily '!AZ11-'FSLPL Daily '!AZ10<0), "",'FSLPL Daily '!AZ11-'FSLPL Daily '!AZ10) -> 2282 | AD9: =IF(('FSLPL Daily '!BB11-'FSLPL Daily '!BB10<0), "",'FSLPL Daily '!BB11-'FSLPL Daily '!BB10) -> 1001 | AE9: ='FSLPL Daily '!BD11 -> 151 | AF9: ='FSLPL Daily '!BE11 -> 238
A10: London at Park Lane | B10: =B9+1 -> 9 | C10: 2 | D10: 2020 | E10: =IF(('FSLPL Daily '!C12-'FSLPL Daily '!C11<0), "0",'FSLPL Daily '!C12-'FSLPL Daily '!C11) -> 8013 | F10: =IF(('FSLPL Daily '!E12-'FSLPL Daily '!E11<0), "0",'FSLPL Daily '!E12-'FSLPL Daily '!E11) -> 6179 | G10: =IF(('FSLPL Daily '!G12-'FSLPL Daily '!G11<0), "0",'FSLPL Daily '!G12-'FSLPL Daily '!G11) -> 3869 | H10: =IF(('FSLPL Daily '!I12-'FSLPL Daily '!I11<0), "",'FSLPL Daily '!I12-'FSLPL Daily '!I11) -> 419 | I10: =IF(('FSLPL Daily '!K12-'FSLPL Daily '!K11<0), "",'FSLPL Daily '!K12-'FSLPL Daily '!K11) -> 863 | J10: =IF(('FSLPL Daily '!M12-'FSLPL Daily '!M11<0), "",'FSLPL Daily '!M12-'FSLPL Daily '!M11) -> 1381 | K10: =IF(('FSLPL Daily '!O12-'FSLPL Daily '!O11<0), "",'FSLPL Daily '!O12-'FSLPL Daily '!O11) -> 668 | L10: =IF(('FSLPL Daily '!Q12-'FSLPL Daily '!Q11<0), "",'FSLPL Daily '!Q12-'FSLPL Daily '!Q11) -> 336 | M10: =IF(('FSLPL Daily '!S12-'FSLPL Daily '!S11<0), "",'FSLPL Daily '!S12-'FSLPL Daily '!S11) -> 15 | N10: =IF(('FSLPL Daily '!U12-'FSLPL Daily '!U11<0), "",'FSLPL Daily '!U12-'FSLPL Daily '!U11) -> 998 | O10: =IF(('FSLPL Daily '!W12-'FSLPL Daily '!W11<0), "",'FSLPL Daily '!W12-'FSLPL Daily '!W11) -> 100 | P10: =IF(('FSLPL Daily '!Y12-'FSLPL Daily '!Y11<0), "",'FSLPL Daily '!Y12-'FSLPL Daily '!Y11) -> 1279 | Q10: =IF(('FSLPL Daily '!AA12-'FSLPL Daily '!AA11<0), "",'FSLPL Daily '!AA12-'FSLPL Daily '!AA11) -> 2 | R10: =IF(('FSLPL Daily '!AC12-'FSLPL Daily '!AC11<0), "",'FSLPL Daily '!AC12-'FSLPL Daily '!AC11) -> 1458 | S10: =IF(('FSLPL Daily '!AE12-'FSLPL Daily '!AE11<0), "",'FSLPL Daily '!AE12-'FSLPL Daily '!AE11) -> 2020 | T10: =IF(('FSLPL Daily '!AG12-'FSLPL Daily '!AG11<0), "",'FSLPL Daily '!AG12-'FSLPL Daily '!AG11) -> 385 | U10: =IF(('FSLPL Daily '!AI12-'FSLPL Daily '!AI11<0), "",'FSLPL Daily '!AI12-'FSLPL Daily '!AI11) -> 21 | V10: =IF(('FSLPL Daily '!AK12-'FSLPL Daily '!AK11<0), "",'FSLPL Daily '!AK12-'FSLPL Daily '!AK11) -> 401 | W10: =IF(('FSLPL Daily '!AM12-'FSLPL Daily '!AM11<0), "",'FSLPL Daily '!AM12-'FSLPL Daily '!AM11) -> 618 | X10: =IF(('FSLPL Daily '!AO12-'FSLPL Daily '!AO11<0), "",'FSLPL Daily '!AO12-'FSLPL Daily '!AO11) -> 755 | Y10: =IF(('FSLPL Daily '!AR12-'FSLPL Daily '!AR11<0), "",'FSLPL Daily '!AR12-'FSLPL Daily '!AR11) -> 0 | Z10: =IF(('FSLPL Daily '!AT12-'FSLPL Daily '!AT11<0), "",'FSLPL Daily '!AT12-'FSLPL Daily '!AT11) -> 0 | AA10: =IF(('FSLPL Daily '!AV12-'FSLPL Daily '!AV11<0), "",'FSLPL Daily '!AV12-'FSLPL Daily '!AV11) -> 47 | AB10: =IF(('FSLPL Daily '!AX12-'FSLPL Daily '!AX11<0), "",'FSLPL Daily '!AX12-'FSLPL Daily '!AX11) -> 12 | AC10: =IF(('FSLPL Daily '!AZ12-'FSLPL Daily '!AZ11<0), "",'FSLPL Daily '!AZ12-'FSLPL Daily '!AZ11) -> 2501 | AD10: =IF(('FSLPL Daily '!BB12-'FSLPL Daily '!BB11<0), "",'FSLPL Daily '!BB12-'FSLPL Daily '!BB11) -> 1123 | AE10: ='FSLPL Daily '!BD12 -> 151 | AF10: ='FSLPL Daily '!BE12 -> 248
A11: London at Park Lane | B11: =B10+1 -> 10 | C11: 2 | D11: 2020 | E11: =IF(('FSLPL Daily '!C13-'FSLPL Daily '!C12<0), "0",'FSLPL Daily '!C13-'FSLPL Daily '!C12) -> 7848 | F11: =IF(('FSLPL Daily '!E13-'FSLPL Daily '!E12<0), "0",'FSLPL Daily '!E13-'FSLPL Daily '!E12) -> 6010 | G11: =IF(('FSLPL Daily '!G13-'FSLPL Daily '!G12<0), "0",'FSLPL Daily '!G13-'FSLPL Daily '!G12) -> 3922 | H11: =IF(('FSLPL Daily '!I13-'FSLPL Daily '!I12<0), "",'FSLPL Daily '!I13-'FSLPL Daily '!I12) -> 450 | I11: =IF(('FSLPL Daily '!K13-'FSLPL Daily '!K12<0), "",'FSLPL Daily '!K13-'FSLPL Daily '!K12) -> 869 | J11: =IF(('FSLPL Daily '!M13-'FSLPL Daily '!M12<0), "",'FSLPL Daily '!M13-'FSLPL Daily '!M12) -> 1426 | K11: =IF(('FSLPL Daily '!O13-'FSLPL Daily '!O12<0), "",'FSLPL Daily '!O13-'FSLPL Daily '!O12) -> 709 | L11: =IF(('FSLPL Daily '!Q13-'FSLPL Daily '!Q12<0), "",'FSLPL Daily '!Q13-'FSLPL Daily '!Q12) -> 352 | M11: =IF(('FSLPL Daily '!S13-'FSLPL Daily '!S12<0), "",'FSLPL Daily '!S13-'FSLPL Daily '!S12) -> 20 | N11: =IF(('FSLPL Daily '!U13-'FSLPL Daily '!U12<0), "",'FSLPL Daily '!U13-'FSLPL Daily '!U12) -> 957 | O11: =IF(('FSLPL Daily '!W13-'FSLPL Daily '!W12<0), "",'FSLPL Daily '!W13-'FSLPL Daily '!W12) -> 34 | P11: =IF(('FSLPL Daily '!Y13-'FSLPL Daily '!Y12<0), "",'FSLPL Daily '!Y13-'FSLPL Daily '!Y12) -> 1221 | Q11: =IF(('FSLPL Daily '!AA13-'FSLPL Daily '!AA12<0), "",'FSLPL Daily '!AA13-'FSLPL Daily '!AA12) -> 3 | R11: =IF(('FSLPL Daily '!AC13-'FSLPL Daily '!AC12<0), "",'FSLPL Daily '!AC13-'FSLPL Daily '!AC12) -> 1448 | S11: =IF(('FSLPL Daily '!AE13-'FSLPL Daily '!AE12<0), "",'FSLPL Daily '!AE13-'FSLPL Daily '!AE12) -> 2015 | T11: =IF(('FSLPL Daily '!AG13-'FSLPL Daily '!AG12<0), "",'FSLPL Daily '!AG13-'FSLPL Daily '!AG12) -> 379 | U11: =IF(('FSLPL Daily '!AI13-'FSLPL Daily '!AI12<0), "",'FSLPL Daily '!AI13-'FSLPL Daily '!AI12) -> 20 | V11: =IF(('FSLPL Daily '!AK13-'FSLPL Daily '!AK12<0), "",'FSLPL Daily '!AK13-'FSLPL Daily '!AK12) -> 394 | W11: =IF(('FSLPL Daily '!AM13-'FSLPL Daily '!AM12<0), "",'FSLPL Daily '!AM13-'FSLPL Daily '!AM12) -> 620 | X11: =IF(('FSLPL Daily '!AO13-'FSLPL Daily '!AO12<0), "",'FSLPL Daily '!AO13-'FSLPL Daily '!AO12) -> 709 | Y11: =IF(('FSLPL Daily '!AR13-'FSLPL Daily '!AR12<0), "",'FSLPL Daily '!AR13-'FSLPL Daily '!AR12) -> 0 | Z11: =IF(('FSLPL Daily '!AT13-'FSLPL Daily '!AT12<0), "",'FSLPL Daily '!AT13-'FSLPL Daily '!AT12) -> 0 | AA11: =IF(('FSLPL Daily '!AV13-'FSLPL Daily '!AV12<0), "",'FSLPL Daily '!AV13-'FSLPL Daily '!AV12) -> 40 | AB11: =IF(('FSLPL Daily '!AX13-'FSLPL Daily '!AX12<0), "",'FSLPL Daily '!AX13-'FSLPL Daily '!AX12) -> 10 | AC11: =IF(('FSLPL Daily '!AZ13-'FSLPL Daily '!AZ12<0), "",'FSLPL Daily '!AZ13-'FSLPL Daily '!AZ12) -> 2549 | AD11: =IF(('FSLPL Daily '!BB13-'FSLPL Daily '!BB12<0), "",'FSLPL Daily '!BB13-'FSLPL Daily '!BB12) -> 1127 | AE11: ='FSLPL Daily '!BD13 -> 142 | AF11: ='FSLPL Daily '!BE13 -> 228
A12: London at Park Lane | B12: =B11+1 -> 11 | C12: 2 | D12: 2020 | E12: =IF(('FSLPL Daily '!C14-'FSLPL Daily '!C13<0), "0",'FSLPL Daily '!C14-'FSLPL Daily '!C13) -> 7802 | F12: =IF(('FSLPL Daily '!E14-'FSLPL Daily '!E13<0), "0",'FSLPL Daily '!E14-'FSLPL Daily '!E13) -> 6141 | G12: =IF(('FSLPL Daily '!G14-'FSLPL Daily '!G13<0), "0",'FSLPL Daily '!G14-'FSLPL Daily '!G13) -> 3778 | H12: =IF(('FSLPL Daily '!I14-'FSLPL Daily '!I13<0), "",'FSLPL Daily '!I14-'FSLPL Daily '!I13) -> 439 | I12: =IF(('FSLPL Daily '!K14-'FSLPL Daily '!K13<0), "",'FSLPL Daily '!K14-'FSLPL Daily '!K13) -> 845 | J12: =IF(('FSLPL Daily '!M14-'FSLPL Daily '!M13<0), "",'FSLPL Daily '!M14-'FSLPL Daily '!M13) -> 1405 | K12: =IF(('FSLPL Daily '!O14-'FSLPL Daily '!O13<0), "",'FSLPL Daily '!O14-'FSLPL Daily '!O13) -> 767 | L12: =IF(('FSLPL Daily '!Q14-'FSLPL Daily '!Q13<0), "",'FSLPL Daily '!Q14-'FSLPL Daily '!Q13) -> 347 | M12: =IF(('FSLPL Daily '!S14-'FSLPL Daily '!S13<0), "",'FSLPL Daily '!S14-'FSLPL Daily '!S13) -> 14 | N12: =IF(('FSLPL Daily '!U14-'FSLPL Daily '!U13<0), "",'FSLPL Daily '!U14-'FSLPL Daily '!U13) -> 1002 | O12: =IF(('FSLPL Daily '!W14-'FSLPL Daily '!W13<0), "",'FSLPL Daily '!W14-'FSLPL Daily '!W13) -> 41 | P12: =IF(('FSLPL Daily '!Y14-'FSLPL Daily '!Y13<0), "",'FSLPL Daily '!Y14-'FSLPL Daily '!Y13) -> 1188 | Q12: =IF(('FSLPL Daily '!AA14-'FSLPL Daily '!AA13<0), "",'FSLPL Daily '!AA14-'FSLPL Daily '!AA13) -> 2 | R12: =IF(('FSLPL Daily '!AC14-'FSLPL Daily '!AC13<0), "",'FSLPL Daily '!AC14-'FSLPL Daily '!AC13) -> 1424 | S12: =IF(('FSLPL Daily '!AE14-'FSLPL Daily '!AE13<0), "",'FSLPL Daily '!AE14-'FSLPL Daily '!AE13) -> 1984 | T12: =IF(('FSLPL Daily '!AG14-'FSLPL Daily '!AG13<0), "",'FSLPL Daily '!AG14-'FSLPL Daily '!AG13) -> 371 | U12: =IF(('FSLPL Daily '!AI14-'FSLPL Daily '!AI13<0), "",'FSLPL Daily '!AI14-'FSLPL Daily '!AI13) -> 20 | V12: =IF(('FSLPL Daily '!AK14-'FSLPL Daily '!AK13<0), "",'FSLPL Daily '!AK14-'FSLPL Daily '!AK13) -> 389 | W12: =IF(('FSLPL Daily '!AM14-'FSLPL Daily '!AM13<0), "",'FSLPL Daily '!AM14-'FSLPL Daily '!AM13) -> 626 | X12: =IF(('FSLPL Daily '!AO14-'FSLPL Daily '!AO13<0), "",'FSLPL Daily '!AO14-'FSLPL Daily '!AO13) -> 777 | Y12: =IF(('FSLPL Daily '!AR14-'FSLPL Daily '!AR13<0), "",'FSLPL Daily '!AR14-'FSLPL Daily '!AR13) -> 0 | Z12: =IF(('FSLPL Daily '!AT14-'FSLPL Daily '!AT13<0), "",'FSLPL Daily '!AT14-'FSLPL Daily '!AT13) -> 0 | AA12: =IF(('FSLPL Daily '!AV14-'FSLPL Daily '!AV13<0), "",'FSLPL Daily '!AV14-'FSLPL Daily '!AV13) -> 34 | AB12: =IF(('FSLPL Daily '!AX14-'FSLPL Daily '!AX13<0), "",'FSLPL Daily '!AX14-'FSLPL Daily '!AX13) -> 22 | AC12: =IF(('FSLPL Daily '!AZ14-'FSLPL Daily '!AZ13<0), "",'FSLPL Daily '!AZ14-'FSLPL Daily '!AZ13) -> 2722 | AD12: =IF(('FSLPL Daily '!BB14-'FSLPL Daily '!BB13<0), "",'FSLPL Daily '!BB14-'FSLPL Daily '!BB13) -> 1085 | AE12: ='FSLPL Daily '!BD14 -> 141 | AF12: ='FSLPL Daily '!BE14 -> 209
A13: London at Park Lane | B13: =B12+1 -> 12 | C13: 2 | D13: 2020 | E13: =IF(('FSLPL Daily '!C15-'FSLPL Daily '!C14<0), "0",'FSLPL Daily '!C15-'FSLPL Daily '!C14) -> 8329 | F13: =IF(('FSLPL Daily '!E15-'FSLPL Daily '!E14<0), "0",'FSLPL Daily '!E15-'FSLPL Daily '!E14) -> 7139 | G13: =IF(('FSLPL Daily '!G15-'FSLPL Daily '!G14<0), "0",'FSLPL Daily '!G15-'FSLPL Daily '!G14) -> 2799 | H13: =IF(('FSLPL Daily '!I15-'FSLPL Daily '!I14<0), "",'FSLPL Daily '!I15-'FSLPL Daily '!I14) -> 420 | I13: =IF(('FSLPL Daily '!K15-'FSLPL Daily '!K14<0), "",'FSLPL Daily '!K15-'FSLPL Daily '!K14) -> 848 | J13: =IF(('FSLPL Daily '!M15-'FSLPL Daily '!M14<0), "",'FSLPL Daily '!M15-'FSLPL Daily '!M14) -> 1457 | K13: =IF(('FSLPL Daily '!O15-'FSLPL Daily '!O14<0), "",'FSLPL Daily '!O15-'FSLPL Daily '!O14) -> 697 | L13: =IF(('FSLPL Daily '!Q15-'FSLPL Daily '!Q14<0), "",'FSLPL Daily '!Q15-'FSLPL Daily '!Q14) -> 356 | M13: =IF(('FSLPL Daily '!S15-'FSLPL Daily '!S14<0), "",'FSLPL Daily '!S15-'FSLPL Daily '!S14) -> 24 | N13: =IF(('FSLPL Daily '!U15-'FSLPL Daily '!U14<0), "",'FSLPL Daily '!U15-'FSLPL Daily '!U14) -> 1146 | O13: =IF(('FSLPL Daily '!W15-'FSLPL Daily '!W14<0), "",'FSLPL Daily '!W15-'FSLPL Daily '!W14) -> 144 | P13: =IF(('FSLPL Daily '!Y15-'FSLPL Daily '!Y14<0), "",'FSLPL Daily '!Y15-'FSLPL Daily '!Y14) -> 1336 | Q13: =IF(('FSLPL Daily '!AA15-'FSLPL Daily '!AA14<0), "",'FSLPL Daily '!AA15-'FSLPL Daily '!AA14) -> 2 | R13: =IF(('FSLPL Daily '!AC15-'FSLPL Daily '!AC14<0), "",'FSLPL Daily '!AC15-'FSLPL Daily '!AC14) -> 1481 | S13: =IF(('FSLPL Daily '!AE15-'FSLPL Daily '!AE14<0), "",'FSLPL Daily '!AE15-'FSLPL Daily '!AE14) -> 2023 | T13: =IF(('FSLPL Daily '!AG15-'FSLPL Daily '!AG14<0), "",'FSLPL Daily '!AG15-'FSLPL Daily '!AG14) -> 387 | U13: =IF(('FSLPL Daily '!AI15-'FSLPL Daily '!AI14<0), "",'FSLPL Daily '!AI15-'FSLPL Daily '!AI14) -> 30 | V13: =IF(('FSLPL Daily '!AK15-'FSLPL Daily '!AK14<0), "",'FSLPL Daily '!AK15-'FSLPL Daily '!AK14) -> 378 | W13: =IF(('FSLPL Daily '!AM15-'FSLPL Daily '!AM14<0), "",'FSLPL Daily '!AM15-'FSLPL Daily '!AM14) -> 632 | X13: =IF(('FSLPL Daily '!AO15-'FSLPL Daily '!AO14<0), "",'FSLPL Daily '!AO15-'FSLPL Daily '!AO14) -> 692 | Y13: =IF(('FSLPL Daily '!AR15-'FSLPL Daily '!AR14<0), "",'FSLPL Daily '!AR15-'FSLPL Daily '!AR14) -> 0 | Z13: =IF(('FSLPL Daily '!AT15-'FSLPL Daily '!AT14<0), "",'FSLPL Daily '!AT15-'FSLPL Daily '!AT14) -> 0 | AA13: =IF(('FSLPL Daily '!AV15-'FSLPL Daily '!AV14<0), "",'FSLPL Daily '!AV15-'FSLPL Daily '!AV14) -> 35 | AB13: =IF(('FSLPL Daily '!AX15-'FSLPL Daily '!AX14<0), "",'FSLPL Daily '!AX15-'FSLPL Daily '!AX14) -> 8 | AC13: =IF(('FSLPL Daily '!AZ15-'FSLPL Daily '!AZ14<0), "",'FSLPL Daily '!AZ15-'FSLPL Daily '!AZ14) -> 2400 | AD13: =IF(('FSLPL Daily '!BB15-'FSLPL Daily '!BB14<0), "",'FSLPL Daily '!BB15-'FSLPL Daily '!BB14) -> 861 | AE13: ='FSLPL Daily '!BD15 -> 142 | AF13: ='FSLPL Daily '!BE15 -> 202
A14: London at Park Lane | B14: =B13+1 -> 13 | C14: 2 | D14: 2020 | E14: =IF(('FSLPL Daily '!C16-'FSLPL Daily '!C15<0), "0",'FSLPL Daily '!C16-'FSLPL Daily '!C15) -> 8946 | F14: =IF(('FSLPL Daily '!E16-'FSLPL Daily '!E15<0), "0",'FSLPL Daily '!E16-'FSLPL Daily '!E15) -> 6736 | G14: =IF(('FSLPL Daily '!G16-'FSLPL Daily '!G15<0), "0",'FSLPL Daily '!G16-'FSLPL Daily '!G15) -> 3726 | H14: =IF(('FSLPL Daily '!I16-'FSLPL Daily '!I15<0), "",'FSLPL Daily '!I16-'FSLPL Daily '!I15) -> 442 | I14: =IF(('FSLPL Daily '!K16-'FSLPL Daily '!K15<0), "",'FSLPL Daily '!K16-'FSLPL Daily '!K15) -> 915 | J14: =IF(('FSLPL Daily '!M16-'FSLPL Daily '!M15<0), "",'FSLPL Daily '!M16-'FSLPL Daily '!M15) -> 1686 | K14: =IF(('FSLPL Daily '!O16-'FSLPL Daily '!O15<0), "",'FSLPL Daily '!O16-'FSLPL Daily '!O15) -> 680 | L14: =IF(('FSLPL Daily '!Q16-'FSLPL Daily '!Q15<0), "",'FSLPL Daily '!Q16-'FSLPL Daily '!Q15) -> 373 | M14: =IF(('FSLPL Daily '!S16-'FSLPL Daily '!S15<0), "",'FSLPL Daily '!S16-'FSLPL Daily '!S15) -> 29 | N14: =IF(('FSLPL Daily '!U16-'FSLPL Daily '!U15<0), "",'FSLPL Daily '!U16-'FSLPL Daily '!U15) -> 1161 | O14: =IF(('FSLPL Daily '!W16-'FSLPL Daily '!W15<0), "",'FSLPL Daily '!W16-'FSLPL Daily '!W15) -> 198 | P14: =IF(('FSLPL Daily '!Y16-'FSLPL Daily '!Y15<0), "",'FSLPL Daily '!Y16-'FSLPL Daily '!Y15) -> 1434 | Q14: =IF(('FSLPL Daily '!AA16-'FSLPL Daily '!AA15<0), "",'FSLPL Daily '!AA16-'FSLPL Daily '!AA15) -> 2 | R14: =IF(('FSLPL Daily '!AC16-'FSLPL Daily '!AC15<0), "",'FSLPL Daily '!AC16-'FSLPL Daily '!AC15) -> 1561 | S14: =IF(('FSLPL Daily '!AE16-'FSLPL Daily '!AE15<0), "",'FSLPL Daily '!AE16-'FSLPL Daily '!AE15) -> 2128 | T14: =IF(('FSLPL Daily '!AG16-'FSLPL Daily '!AG15<0), "",'FSLPL Daily '!AG16-'FSLPL Daily '!AG15) -> 410 | U14: =IF(('FSLPL Daily '!AI16-'FSLPL Daily '!AI15<0), "",'FSLPL Daily '!AI16-'FSLPL Daily '!AI15) -> 12 | V14: =IF(('FSLPL Daily '!AK16-'FSLPL Daily '!AK15<0), "",'FSLPL Daily '!AK16-'FSLPL Daily '!AK15) -> 395 | W14: =IF(('FSLPL Daily '!AM16-'FSLPL Daily '!AM15<0), "",'FSLPL Daily '!AM16-'FSLPL Daily '!AM15) -> 637 | X14: =IF(('FSLPL Daily '!AO16-'FSLPL Daily '!AO15<0), "",'FSLPL Daily '!AO16-'FSLPL Daily '!AO15) -> 735 | Y14: =IF(('FSLPL Daily '!AR16-'FSLPL Daily '!AR15<0), "",'FSLPL Daily '!AR16-'FSLPL Daily '!AR15) -> 0 | Z14: =IF(('FSLPL Daily '!AT16-'FSLPL Daily '!AT15<0), "",'FSLPL Daily '!AT16-'FSLPL Daily '!AT15) -> 0 | AA14: =IF(('FSLPL Daily '!AV16-'FSLPL Daily '!AV15<0), "",'FSLPL Daily '!AV16-'FSLPL Daily '!AV15) -> 34 | AB14: =IF(('FSLPL Daily '!AX16-'FSLPL Daily '!AX15<0), "",'FSLPL Daily '!AX16-'FSLPL Daily '!AX15) -> 8 | AC14: =IF(('FSLPL Daily '!AZ16-'FSLPL Daily '!AZ15<0), "",'FSLPL Daily '!AZ16-'FSLPL Daily '!AZ15) -> 2332 | AD14: =IF(('FSLPL Daily '!BB16-'FSLPL Daily '!BB15<0), "",'FSLPL Daily '!BB16-'FSLPL Daily '!BB15) -> 960 | AE14: ='FSLPL Daily '!BD16 -> 130 | AF14: ='FSLPL Daily '!BE16 -> 169
... A29: London at Park Lane | B29: =B28+1 -> 28 | C29: 2 | D29: 2020 | E29: =IF(('FSLPL Daily '!C31-'FSLPL Daily '!C30<0), "0",'FSLPL Daily '!C31-'FSLPL Daily '!C30) -> 17348 | F29: =IF(('FSLPL Daily '!E31-'FSLPL Daily '!E30<0), "0",'FSLPL Daily '!E31-'FSLPL Daily '!E30) -> 5799 | G29: =IF(('FSLPL Daily '!G31-'FSLPL Daily '!G30<0), "0",'FSLPL Daily '!G31-'FSLPL Daily '!G30) -> 3959 | H29: =IF(('FSLPL Daily '!I31-'FSLPL Daily '!I30<0), "",'FSLPL Daily '!I31-'FSLPL Daily '!I30) -> 440 | I29: =IF(('FSLPL Daily '!K31-'FSLPL Daily '!K30<0), "",'FSLPL Daily '!K31-'FSLPL Daily '!K30) -> 864 | J29: =IF(('FSLPL Daily '!M31-'FSLPL Daily '!M30<0), "",'FSLPL Daily '!M31-'FSLPL Daily '!M30) -> 1628 | K29: =IF(('FSLPL Daily '!O31-'FSLPL Daily '!O30<0), "",'FSLPL Daily '!O31-'FSLPL Daily '!O30) -> 719 | L29: =IF(('FSLPL Daily '!Q31-'FSLPL Daily '!Q30<0), "",'FSLPL Daily '!Q31-'FSLPL Daily '!Q30) -> 370 | M29: =IF(('FSLPL Daily '!S31-'FSLPL Daily '!S30<0), "",'FSLPL Daily '!S31-'FSLPL Daily '!S30) -> 51 | N29: =IF(('FSLPL Daily '!U31-'FSLPL Daily '!U30<0), "",'FSLPL Daily '!U31-'FSLPL Daily '!U30) -> 1387 | O29: =IF(('FSLPL Daily '!W31-'FSLPL Daily '!W30<0), "",'FSLPL Daily '!W31-'FSLPL Daily '!W30) -> 210 | P29: =IF(('FSLPL Daily '!Y31-'FSLPL Daily '!Y30<0), "",'FSLPL Daily '!Y31-'FSLPL Daily '!Y30) -> 1846 | Q29: =IF(('FSLPL Daily '!AA31-'FSLPL Daily '!AA30<0), "",'FSLPL Daily '!AA31-'FSLPL Daily '!AA30) -> 3 | R29: =IF(('FSLPL Daily '!AC31-'FSLPL Daily '!AC30<0), "",'FSLPL Daily '!AC31-'FSLPL Daily '!AC30) -> 1492 | S29: =IF(('FSLPL Daily '!AE31-'FSLPL Daily '!AE30<0), "",'FSLPL Daily '!AE31-'FSLPL Daily '!AE30) -> 2112 | T29: =IF(('FSLPL Daily '!AG31-'FSLPL Daily '!AG30<0), "",'FSLPL Daily '!AG31-'FSLPL Daily '!AG30) -> 386 | U29: =IF(('FSLPL Daily '!AI31-'FSLPL Daily '!AI30<0), "",'FSLPL Daily '!AI31-'FSLPL Daily '!AI30) -> 21 | V29: =IF(('FSLPL Daily '!AK31-'FSLPL Daily '!AK30<0), "",'FSLPL Daily '!AK31-'FSLPL Daily '!AK30) -> 398 | W29: =IF(('FSLPL Daily '!AM31-'FSLPL Daily '!AM30<0), "",'FSLPL Daily '!AM31-'FSLPL Daily '!AM30) -> 626 | X29: =IF(('FSLPL Daily '!AO31-'FSLPL Daily '!AO30<0), "",'FSLPL Daily '!AO31-'FSLPL Daily '!AO30) -> 699 | Y29: =IF(('FSLPL Daily '!AR31-'FSLPL Daily '!AR30<0), "",'FSLPL Daily '!AR31-'FSLPL Daily '!AR30) -> 0 | Z29: =IF(('FSLPL Daily '!AT31-'FSLPL Daily '!AT30<0), "",'FSLPL Daily '!AT31-'FSLPL Daily '!AT30) -> 0 | AA29: =IF(('FSLPL Daily '!AV31-'FSLPL Daily '!AV30<0), "",'FSLPL Daily '!AV31-'FSLPL Daily '!AV30) -> 39 | AB29: =IF(('FSLPL Daily '!AX31-'FSLPL Daily '!AX30<0), "",'FSLPL Daily '!AX31-'FSLPL Daily '!AX30) -> 10 | AC29: =IF(('FSLPL Daily '!AZ31-'FSLPL Daily '!AZ30<0), "",'FSLPL Daily '!AZ31-'FSLPL Daily '!AZ30) -> 2053 | AD29: =IF(('FSLPL Daily '!BB31-'FSLPL Daily '!BB30<0), "",'FSLPL Daily '!BB31-'FSLPL Daily '!BB30) -> 1136 | AE29: ='FSLPL Daily '!BD31 -> 134 | AF29: ='FSLPL Daily '!BE31 -> 193
AB30: =IF(('FSLPL Daily '!BA121-'FSLPL Daily '!BA120<0), "",'FSLPL Daily '!BA121-'FSLPL Daily '!BA120) -> 0
AB31: =IF(('FSLPL Daily '!BA122-'FSLPL Daily '!BA121<0), "",'FSLPL Daily '!BA122-'FSLPL Daily '!BA121) -> 0
AB32: =IF(('FSLPL Daily '!BA123-'FSLPL Daily '!BA122<0), "",'FSLPL Daily '!BA123-'FSLPL Daily '!BA122) -> 0
AB33: =IF(('FSLPL Daily '!BA124-'FSLPL Daily '!BA123<0), "",'FSLPL Daily '!BA124-'FSLPL Daily '!BA123) -> 0
AB34: =IF(('FSLPL Daily '!BA125-'FSLPL Daily '!BA124<0), "",'FSLPL Daily '!BA125-'FSLPL Daily '!BA124) -> 0
AB35: =IF(('FSLPL Daily '!BA126-'FSLPL Daily '!BA125<0), "",'FSLPL Daily '!BA126-'FSLPL Daily '!BA125) -> 0
AB36: =IF(('FSLPL Daily '!BA127-'FSLPL Daily '!BA126<0), "",'FSLPL Daily '!BA127-'FSLPL Daily '!BA126) -> 0
AB37: =IF(('FSLPL Daily '!BA128-'FSLPL Daily '!BA127<0), "",'FSLPL Daily '!BA128-'FSLPL Daily '!BA127) -> 0
AB38: =IF(('FSLPL Daily '!BA129-'FSLPL Daily '!BA128<0), "",'FSLPL Daily '!BA129-'FSLPL Daily '!BA128) -> 0
AB39: =IF(('FSLPL Daily '!BA130-'FSLPL Daily '!BA129<0), "",'FSLPL Daily '!BA130-'FSLPL Daily '!BA129) -> 0
AB40: =IF(('FSLPL Daily '!BA131-'FSLPL Daily '!BA130<0), "",'FSLPL Daily '!BA131-'FSLPL Daily '!BA130) -> 0
AB41: =IF(('FSLPL Daily '!BA132-'FSLPL Daily '!BA131<0), "",'FSLPL Daily '!BA132-'FSLPL Daily '!BA131) -> 0
... AB65440: =IF(('FSLPL Daily '!BA65531-'FSLPL Daily '!BA65530<0), "",'FSLPL Daily '!BA65531-'FSLPL Daily '!BA65530) -> 0

Sheet FSLPL Daily 
A1: Days | C1: LV Panel 1 KWh | E1: LV Panel 2 KWh | G1: CHP KWh | I1: MCC9 KWh | K1: GF Panel KWh | M1: Kitchen Switch. KWh | O1: Kitchen Panel | Q1: MCC3 (AHU) KWh | S1: MCC8 KWh | U1: 1st Floor Plan (KWh) | W1: MCC6(1st floor AHU) KWh | Y1: Chiller 1 KWh | AA1: Chiller 2 KWh | AC1: MCC 10 (Mechanical Services) KWh | AE1: MCC2 CHW KWh | AG1: MCC7 (Kitchen) KWh | AI1: MCC 5 (Mechanical services) KWh | AK1: MCC 4 (Water Services) KWh | AM1: MCC1 (KWh) | AO1: Laundry db KWh | AR1: Hamilton City Water 1 m3 | AT1: Old Park Lane City Water 2 m3 | AV1: Laundry CW m3 | AX1: Laundry HW m3 | AZ1: Natural Gas m3 | BB1: CHP Natural Gas m3
A2: Date | C2: Reading KWH | D2: Difference KWH | E2: Reading KWH | F2: Difference KWH | G2: Reading KWH | H2: Difference KWH | I2: Reading KWH | J2: Difference KWH | K2: Reading KWH | L2: Difference KWH | M2: Reading KWH | N2: Difference KWH | O2: Reading KWH | P2: Difference KWH | Q2: Reading KWH | R2: Difference KWH | S2: Reading KWH | T2: Difference KWH | U2: Reading KWH | V2: Difference KWH | W2: Reading KWH | X2: Difference KWH | Y2: Reading KWH | Z2: Difference KWH | AA2: Reading KWH | AB2: Difference KWH | AC2: Reading KWH | AD2: Difference KWH | AE2: Reading KWH | AF2: Difference KWH | AG2: Reading KWH | AH2: Difference KWH | AI2: Reading KWH | AJ2: Difference KWH | AK2: Reading KWH | AL2: Difference KWH | AM2: Reading KWH | AN2: Difference KWH | AO2: Reading KWH | AP2: Difference KWH | AR2: Reading m³ | AS2: Daily Consumption m³ | AT2: Reading m³ | AU2: Daily Consumption m³ | AV2: Reading m³ | AW2: Daily Consumption m³ | AX2: Reading m³ | AY2: Daily Consumption m³ | AZ2: Reading Liters | BA2: Daily Consumption L | BB2: Reading Liters | BC2: Daily Consumption L | BD2: ROOM NIGHTS | BE2: TOTAL GUESTS
A3: 31/1/2019 | C3: 22109736 | D3: =IF((C4-C3<0), "",C4-C3) -> 8036 | E3: 23667167 | F3: =IF((E4-E3<0), "",E4-E3) -> 6127 | G3: 9869983 | H3: =IF((G4-G3<0), "",G4-G3) -> 3911 | I3: 1389668 | J3: =IF((I4-I3<0), "",I4-I3) -> 423 | K3: 2818567 | L3: =IF((K4-K3<0), "",K4-K3) -> 862 | M3: 4034230 | N3: =IF((M4-M3<0), "",M4-M3) -> 1524 | O3: 1940351 | P3: =IF((O4-O3<0), "",O4-O3) -> 671 | Q3: 1093823 | R3: =IF((Q4-Q3<0), "",Q4-Q3) -> 351 | S3: 339784 | T3: =IF((S4-S3<0), "",S4-S3) -> 10 | U3: 3700553 | V3: =IF((U4-U3<0), "",U4-U3) -> 1120 | W3: 885586 | X3: =IF((W4-W3<0), "",W4-W3) -> 152 | Y3: 3072680 | Z3: =IF((Y4-Y3<0), "",Y4-Y3) -> 1102 | AA3: 1921699 | AB3: =IF((AA4-AA3<0), "",AA4-AA3) -> 3 | AC3: 4521570 | AD3: =IF((AC4-AC3<0), "",AC4-AC3) -> 1443 | AE3: 6455348 | AF3: =IF((AE4-AE3<0), "",AE4-AE3) -> 2076 | AG3: 1156656 | AH3: =IF((AG4-AG3<0), "",AG4-AG3) -> 374 | AI3: 228079 | AJ3: =IF((AI4-AI3<0), "",AI4-AI3) -> 20 | AK3: 787390 | AL3: =IF((AK4-AK3<0), "",AK4-AK3) -> 400 | AM3: 1522247 | AN3: =IF((AM4-AM3<0), "",AM4-AM3) -> 669 | AO3: 1610485 | AP3: =IF((AO4-AO3<0), "",AO4-AO3) -> 720 | AR3: 0 | AS3: 1592 | AT3: 0 | AU3: 2494 | AV3: 74853 | AW3: =IF((AV4-AV3<0), "",AV4-AV3) -> 28 | AX3: 8398 | AY3: =IF((AX4-AX3<0), "",AX4-AX3) -> 13 | AZ3: 6048629 | BA3: =IF((AZ4-AZ3<0), "",AZ4-AZ3) -> 3258 | BB3: 826800 | BC3: =IF((BB4-BB3<0), "",BB4-BB3) -> 1126 | BD3: 148 | BE3: 207
A4: 43497 | C4: 22117772 | E4: 23673294 | G4: 9873894 | I4: 1390091 | K4: 2819429 | M4: 4035754 | O4: 1941022 | Q4: 1094174 | S4: 339794 | U4: 3701673 | W4: 885738 | Y4: 3073782 | AA4: 1921702 | AC4: 4523013 | AE4: 6457424 | AG4: 1157030 | AI4: 228099 | AK4: 787790 | AM4: 1522916 | AO4: 1611205 | AR4: 0 | AT4: 0 | AV4: 74881 | AX4: 8411 | AZ4: 6051887 | BB4: 827926 | BD4: 123 | BE4: 193
A5: 43498 | C5: 22125717 | D5: =IF((C5-C4<0), "",C5-C4) -> 7945 | E5: 23679461 | F5: =IF((E5-E4<0), "",E5-E4) -> 6167 | G5: 9877730 | H5: =IF((G5-G4<0), "",G5-G4) -> 3836 | I5: 1390515 | J5: =IF((I5-I4<0), "",I5-I4) -> 424 | K5: 2820274 | L5: =IF((K5-K4<0), "",K5-K4) -> 845 | M5: 4037288 | N5: =IF((M5-M4<0), "",M5-M4) -> 1534 | O5: 1941725 | P5: =IF((O5-O4<0), "",O5-O4) -> 703 | Q5: 1094521 | R5: =IF((Q5-Q4<0), "",Q5-Q4) -> 347 | S5: 339809 | T5: =IF((S5-S4<0), "",S5-S4) -> 15 | U5: 3702690 | V5: =IF((U5-U4<0), "",U5-U4) -> 1017 | W5: 885794 | X5: =IF((W5-W4<0), "",W5-W4) -> 56 | Y5: 3074949 | Z5: =IF((Y5-Y4<0), "",Y5-Y4) -> 1167 | AA5: 1921704 | AB5: =IF((AA5-AA4<0), "",AA5-AA4) -> 2 | AC5: 4524452 | AD5: =IF((AC5-AC4<0), "",AC5-AC4) -> 1439 | AE5: 6459493 | AF5: =IF((AE5-AE4<0), "",AE5-AE4) -> 2069 | AG5: 1157405 | AH5: =IF((AG5-AG4<0), "",AG5-AG4) -> 375 | AI5: 228119 | AJ5: =IF((AI5-AI4<0), "",AI5-AI4) -> 20 | AK5: 788179 | AL5: =IF((AK5-AK4<0), "",AK5-AK4) -> 389 | AM5: 1523580 | AN5: =IF((AM5-AM4<0), "",AM5-AM4) -> 664 | AO5: 1611911 | AP5: =IF((AO5-AO4<0), "",AO5-AO4) -> 706 | AR5: 0 | AS5: =IF((AR5-AR4<0), "",AR5-AR4) -> 0 | AT5: 0 | AU5: =IF((AT5-AT4<0), "",AT5-AT4) -> 0 | AV5: 74920 | AW5: =IF((AV5-AV4<0), "",AV5-AV4) -> 39 | AX5: 8419 | AY5: =IF((AX5-AX4<0), "",AX5-AX4) -> 8 | AZ5: 6055019 | BA5: =IF((AZ5-AZ4<0), "",AZ5-AZ4) -> 3132 | BB5: 829025 | BC5: =IF((BB5-BB4<0), "9",BB5-BB4) -> 1099 | BD5: 133 | BE5: 173
A6: 43499 | C6: 22133635 | D6: =IF((C6-C5<0), "",C6-C5) -> 7918 | E6: 23685508 | F6: =IF((E6-E5<0), "",E6-E5) -> 6047 | G6: 9881533 | H6: =IF((G6-G5<0), "",G6-G5) -> 3803 | I6: 1390961 | J6: =IF((I6-I5<0), "",I6-I5) -> 446 | K6: 2821109 | L6: =IF((K6-K5<0), "",K6-K5) -> 835 | M6: 4038696 | N6: =IF((M6-M5<0), "",M6-M5) -> 1408 | O6: 1942424 | P6: =IF((O6-O5<0), "",O6-O5) -> 699 | Q6: 1094871 | R6: =IF((Q6-Q5<0), "",Q6-Q5) -> 350 | S6: 339828 | T6: =IF((S6-S5<0), "",S6-S5) -> 19 | U6: 3703764 | V6: =IF((U6-U5<0), "",U6-U5) -> 1074 | W6: 885988 | X6: =IF((W6-W5<0), "",W6-W5) -> 194 | Y6: 3076151 | Z6: =IF((Y6-Y5<0), "",Y6-Y5) -> 1202 | AA6: 1921706 | AB6: =IF((AA6-AA5<0), "",AA6-AA5) -> 2 | AC6: 4525909 | AD6: =IF((AC6-AC5<0), "",AC6-AC5) -> 1457 | AE6: 6461551 | AF6: =IF((AE6-AE5<0), "",AE6-AE5) -> 2058 | AG6: 1157778 | AH6: =IF((AG6-AG5<0), "",AG6-AG5) -> 373 | AI6: 228139 | AJ6: =IF((AI6-AI5<0), "",AI6-AI5) -> 20 | AK6: 788571 | AL6: =IF((AK6-AK5<0), "",AK6-AK5) -> 392 | AM6: 1524242 | AN6: =IF((AM6-AM5<0), "",AM6-AM5) -> 662 | AO6: 1612631 | AP6: =IF((AO6-AO5<0), "",AO6-AO5) -> 720 | AR6: 0 | AS6: =IF((AR6-AR5<0), "",AR6-AR5) -> 0 | AT6: 0 | AU6: =IF((AT6-AT5<0), "",AT6-AT5) -> 0 | AV6: 74960 | AW6: =IF((AV6-AV5<0), "",AV6-AV5) -> 40 | AX6: 8430 | AY6: =IF((AX6-AX5<0), "",AX6-AX5) -> 11 | AZ6: 6058126 | BA6: =IF((AZ6-AZ5<0), "",AZ6-AZ5) -> 3107 | BB6: 830098 | BC6: =IF((BB6-BB5<0), "9",BB6-BB5) -> 1073 | BD6: 138 | BE6: 200
A7: 43500 | C7: 22141556 | D7: =IF((C7-C6<0), "",C7-C6) -> 7921 | E7: 23691636 | F7: =IF((E7-E6<0), "",E7-E6) -> 6128 | G7: 9885493 | H7: =IF((G7-G6<0), "",G7-G6) -> 3960 | I7: 1391428 | J7: =IF((I7-I6<0), "",I7-I6) -> 467 | K7: 2821949 | L7: =IF((K7-K6<0), "",K7-K6) -> 840 | M7: 4040071 | N7: =IF((M7-M6<0), "",M7-M6) -> 1375 | O7: 1943152 | P7: =IF((O7-O6<0), "",O7-O6) -> 728 | Q7: 1095225 | R7: =IF((Q7-Q6<0), "",Q7-Q6) -> 354 | S7: 339848 | T7: =IF((S7-S6<0), "",S7-S6) -> 20 | U7: 3704789 | V7: =IF((U7-U6<0), "",U7-U6) -> 1025 | W7: 886107 | X7: =IF((W7-W6<0), "",W7-W6) -> 119 | Y7: 3077401 | Z7: =IF((Y7-Y6<0), "",Y7-Y6) -> 1250 | AA7: 1921708 | AB7: =IF((AA7-AA6<0), "",AA7-AA6) -> 2 | AC7: 4527389 | AD7: =IF((AC7-AC6<0), "",AC7-AC6) -> 1480 | AE7: 6463635 | AF7: =IF((AE7-AE6<0), "",AE7-AE6) -> 2084 | AG7: 1158159 | AH7: =IF((AG7-AG6<0), "",AG7-AG6) -> 381 | AI7: 228160 | AJ7: =IF((AI7-AI6<0), "",AI7-AI6) -> 21 | AK7: 788949 | AL7: =IF((AK7-AK6<0), "",AK7-AK6) -> 378 | AM7: 1524898 | AN7: =IF((AM7-AM6<0), "",AM7-AM6) -> 656 | AO7: 1613329 | AP7: =IF((AO7-AO6<0), "",AO7-AO6) -> 698 | AR7: 0 | AS7: =IF((AR7-AR6<0), "",AR7-AR6) -> 0 | AT7: 0 | AU7: =IF((AT7-AT6<0), "",AT7-AT6) -> 0 | AV7: 74990 | AW7: =IF((AV7-AV6<0), "",AV7-AV6) -> 30 | AX7: 8437 | AY7: =IF((AX7-AX6<0), "",AX7-AX6) -> 7 | AZ7: 6061034 | BA7: =IF((AZ7-AZ6<0), "",AZ7-AZ6) -> 2908 | BB7: 831207 | BC7: =IF((BB7-BB6<0), "9",BB7-BB6) -> 1109 | BD7: 130 | BE7: 151
A8: 43501 | C8: 22149774 | D8: =IF((C8-C7<0), "",C8-C7) -> 8218 | E8: 23697694 | F8: =IF((E8-E7<0), "",E8-E7) -> 6058 | G8: 9889320 | H8: =IF((G8-G7<0), "",G8-G7) -> 3827 | I8: 1391839 | J8: =IF((I8-I7<0), "",I8-I7) -> 411 | K8: 2822808 | L8: =IF((K8-K7<0), "",K8-K7) -> 859 | M8: 4041495 | N8: =IF((M8-M7<0), "",M8-M7) -> 1424 | O8: 1943855 | P8: =IF((O8-O7<0), "",O8-O7) -> 703 | Q8: 1095569 | R8: =IF((Q8-Q7<0), "",Q8-Q7) -> 344 | S8: 339871 | T8: =IF((S8-S7<0), "",S8-S7) -> 23 | U8: 3705959 | V8: =IF((U8-U7<0), "",U8-U7) -> 1170 | W8: 886272 | X8: =IF((W8-W7<0), "",W8-W7) -> 165 | Y8: 3078687 | Z8: =IF((Y8-Y7<0), "",Y8-Y7) -> 1286 | AA8: 1921711 | AB8: =IF((AA8-AA7<0), "",AA8-AA7) -> 3 | AC8: 4528833 | AD8: =IF((AC8-AC7<0), "",AC8-AC7) -> 1444 | AE8: 6465680 | AF8: =IF((AE8-AE7<0), "",AE8-AE7) -> 2045 | AG8: 1158533 | AH8: =IF((AG8-AG7<0), "",AG8-AG7) -> 374 | AI8: 228180 | AJ8: =IF((AI8-AI7<0), "",AI8-AI7) -> 20 | AK8: 789324 | AL8: =IF((AK8-AK7<0), "",AK8-AK7) -> 375 | AM8: 1525514 | AN8: =IF((AM8-AM7<0), "",AM8-AM7) -> 616 | AO8: 1613943 | AP8: =IF((AO8-AO7<0), "",AO8-AO7) -> 614 | AR8: 0 | AS8: =IF((AR8-AR7<0), "",AR8-AR7) -> 0 | AT8: 0 | AU8: =IF((AT8-AT7<0), "",AT8-AT7) -> 0 | AV8: 75020 | AW8: =IF((AV8-AV7<0), "",AV8-AV7) -> 30 | AX8: 8444 | AY8: =IF((AX8-AX7<0), "",AX8-AX7) -> 7 | AZ8: 6063499 | BA8: =IF((AZ8-AZ7<0), "",AZ8-AZ7) -> 2465 | BB8: 832288 | BC8: =IF((BB8-BB7<0), "9",BB8-BB7) -> 1081 | BD8: 138 | BE8: 200
A9: 43502 | C9: 22158105 | D9: =IF((C9-C8<0), "",C9-C8) -> 8331 | E9: 23703662 | F9: =IF((E9-E8<0), "",E9-E8) -> 5968 | G9: 9893176 | H9: =IF((G9-G8<0), "",G9-G8) -> 3856 | I9: 1392242 | J9: =IF((I9-I8<0), "",I9-I8) -> 403 | K9: 2823665 | L9: =IF((K9-K8<0), "",K9-K8) -> 857 | M9: 4042954 | N9: =IF((M9-M8<0), "",M9-M8) -> 1459 | O9: 1944536 | P9: =IF((O9-O8<0), "",O9-O8) -> 681 | Q9: 1095918 | R9: =IF((Q9-Q8<0), "",Q9-Q8) -> 349 | S9: 339896 | T9: =IF((S9-S8<0), "",S9-S8) -> 25 | U9: 3707131 | V9: =IF((U9-U8<0), "",U9-U8) -> 1172 | W9: 886449 | X9: =IF((W9-W8<0), "",W9-W8) -> 177 | Y9: 3079988 | Z9: =IF((Y9-Y8<0), "",Y9-Y8) -> 1301 | AA9: 1921713 | AB9: =IF((AA9-AA8<0), "",AA9-AA8) -> 2 | AC9: 4530227 | AD9: =IF((AC9-AC8<0), "",AC9-AC8) -> 1394 | AE9: 6467736 | AF9: =IF((AE9-AE8<0), "",AE9-AE8) -> 2056 | AG9: 1158874 | AH9: =IF((AG9-AG8<0), "",AG9-AG8) -> 341 | AI9: 228201 | AJ9: =IF((AI9-AI8<0), "",AI9-AI8) -> 21 | AK9: 789703 | AL9: =IF((AK9-AK8<0), "",AK9-AK8) -> 379 | AM9: 1526135 | AN9: =IF((AM9-AM8<0), "",AM9-AM8) -> 621 | AO9: 1614632 | AP9: =IF((AO9-AO8<0), "",AO9-AO8) -> 689 | AR9: 0 | AS9: =IF((AR9-AR8<0), "",AR9-AR8) -> 0 | AT9: 0 | AU9: =IF((AT9-AT8<0), "",AT9-AT8) -> 0 | AV9: 75040 | AW9: =IF((AV9-AV8<0), "",AV9-AV8) -> 20 | AX9: 8452 | AY9: =IF((AX9-AX8<0), "",AX9-AX8) -> 8 | AZ9: 6065990 | BA9: =IF((AZ9-AZ8<0), "",AZ9-AZ8) -> 2491 | BB9: 833374 | BC9: =IF((BB9-BB8<0), "9",BB9-BB8) -> 1086 | BD9: 134 | BE9: 180
A10: 43503 | C10: 22166842 | D10: =IF((C10-C9<0), "",C10-C9) -> 8737 | E10: 23709776 | F10: =IF((E10-E9<0), "",E10-E9) -> 6114 | G10: 9897411 | H10: =IF((G10-G9<0), "",G10-G9) -> 4235 | I10: 1392673 | J10: =IF((I10-I9<0), "",I10-I9) -> 431 | K10: 2824563 | L10: =IF((K10-K9<0), "",K10-K9) -> 898 | M10: 4044532 | N10: =IF((M10-M9<0), "",M10-M9) -> 1578 | O10: 1945255 | P10: =IF((O10-O9<0), "",O10-O9) -> 719 | Q10: 1096281 | R10: =IF((Q10-Q9<0), "",Q10-Q9) -> 363 | S10: 339920 | T10: =IF((S10-S9<0), "",S10-S9) -> 24 | U10: 3708319 | V10: =IF((U10-U9<0), "",U10-U9) -> 1188 | W10: 886645 | X10: =IF((W10-W9<0), "",W10-W9) -> 196 | Y10: 3081308 | Z10: =IF((Y10-Y9<0), "",Y10-Y9) -> 1320 | AA10: 1921715 | AB10: =IF((AA10-AA9<0), "",AA10-AA9) -> 2 | AC10: 4531633 | AD10: =IF((AC10-AC9<0), "",AC10-AC9) -> 1406 | AE10: 6469810 | AF10: =IF((AE10-AE9<0), "",AE10-AE9) -> 2074 | AG10: 1159217 | AH10: =IF((AG10-AG9<0), "",AG10-AG9) -> 343 | AI10: 228222 | AJ10: =IF((AI10-AI9<0), "",AI10-AI9) -> 21 | AK10: 790110 | AL10: =IF((AK10-AK9<0), "",AK10-AK9) -> 407 | AM10: 1526767 | AN10: =IF((AM10-AM9<0), "",AM10-AM9) -> 632 | AO10: 1615405 | AP10: =IF((AO10-AO9<0), "",AO10-AO9) -> 773 | AR10: 0 | AS10: =IF((AR10-AR9<0), "",AR10-AR9) -> 0 | AT10: 0 | AU10: =IF((AT10-AT9<0), "",AT10-AT9) -> 0 | AV10: 75083 | AW10: =IF((AV10-AV9<0), "",AV10-AV9) -> 43 | AX10: 8468 | AY10: =IF((AX10-AX9<0), "",AX10-AX9) -> 16 | AZ10: 6068617 | BA10: =IF((AZ10-AZ9<0), "",AZ10-AZ9) -> 2627 | BB10: 834589 | BC10: =IF((BB10-BB9<0), "9",BB10-BB9) -> 1215 | BD10: 158 | BE10: 224
