Workbook

Sheet Total
A1: Site Name | B1: Day | C1: Month | D1: Year | E1: Total Electricity Kwh | F1: Electricity Tariff ($/Kwh) | G1: LPG (Kg) | H1: LPG $/Kg | I1: Water Utility Supply (m3) m3 | J1: Water Utility Supply (m3) $/m3 | K1: Room Nights | L1: Utilities day cost dh
A2: Serengeti | B2: 1 | C2: 3 | D2: 2020 | E2: ='UTILITY REPORT 1'!F3 -> 5649 | F2: =('UTILITY REPORT 1'!E3*'UTILITY REPORT 1'!D3)/'UTILITY REPORT 1'!F3 -> 0.39771464 | G2: =IF('Utility summery'!M6<0,"0",'Utility summery'!M6) -> 123.068 | H2: 0 | I2: =IF('UTILITY REPORT 1'!G3<0,"0",'UTILITY REPORT 1'!G3) -> 146 | J2: 0 | K2: ='UTILITY REPORT 1'!C3 -> 46 | L2: =E2*F2+G2*H2+#REF!*#REF!+I2*J2 -> #REF!
A3: Serengeti | B3: =B2+1 -> 2 | C3: 3 | D3: 2020 | E3: ='UTILITY REPORT 1'!F4 -> 5543 | F3: =('UTILITY REPORT 1'!E4*'UTILITY REPORT 1'!D4)/'UTILITY REPORT 1'!F4 -> 0.383453 | G3: =IF('Utility summery'!M7<0,"0",'Utility summery'!M7) -> 166.276 | H3: 0 | I3: =IF('UTILITY REPORT 1'!G4<0,"0",'UTILITY REPORT 1'!G4) -> 164 | J3: 0 | K3: ='UTILITY REPORT 1'!C4 -> 17 | L3: =E3*F3+G3*H3+#REF!*#REF!+I3*J3 -> #REF!
A4: Serengeti | B4: =B3+1 -> 3 | C4: 3 | D4: 2020 | E4: ='UTILITY REPORT 1'!F5 -> 4636 | F4: =('UTILITY REPORT 1'!E5*'UTILITY REPORT 1'!D5)/'UTILITY REPORT 1'!F5 -> 0.44893874 | G4: =IF('Utility summery'!M8<0,"0",'Utility summery'!M8) -> 108.592 | H4: 0 | I4: =IF('UTILITY REPORT 1'!G5<0,"0",'UTILITY REPORT 1'!G5) -> 164 | J4: 0 | K4: ='UTILITY REPORT 1'!C5 -> 12 | L4: =E4*F4+G4*H4+#REF!*#REF!+I4*J4 -> #REF!
A5: Serengeti | B5: =B4+1 -> 4 | C5: 3 | D5: 2020 | E5: ='UTILITY REPORT 1'!F6 -> 6200 | F5: =('UTILITY REPORT 1'!E6*'UTILITY REPORT 1'!D6)/'UTILITY REPORT 1'!F6 -> 0.39053065 | G5: =IF('Utility summery'!M9<0,"0",'Utility summery'!M9) -> 105.6 | H5: 0 | I5: =IF('UTILITY REPORT 1'!G6<0,"0",'UTILITY REPORT 1'!G6) -> 163 | J5: 0 | K5: ='UTILITY REPORT 1'!C6 -> 77 | L5: =E5*F5+G5*H5+#REF!*#REF!+I5*J5 -> #REF!
A6: Serengeti | B6: =B5+1 -> 5 | C6: 3 | D6: 2020 | E6: ='UTILITY REPORT 1'!F7 -> 0 | F6: =('UTILITY REPORT 1'!E7*'UTILITY REPORT 1'!D7)/'UTILITY REPORT 1'!F7 -> #DIV/0! | G6: =IF('Utility summery'!M10<0,"0",'Utility summery'!M10) -> 103.84 | H6: 0 | I6: =IF('UTILITY REPORT 1'!G7<0,"0",'UTILITY REPORT 1'!G7) -> 0 | J6: 0 | K6: ='UTILITY REPORT 1'!C7 -> 77 | L6: =E6*F6+G6*H6+#REF!*#REF!+I6*J6 -> #DIV/0!
A7: Serengeti | B7: =B6+1 -> 6 | C7: 3 | D7: 2020 | E7: ='UTILITY REPORT 1'!F8 -> 0 | F7: =('UTILITY REPORT 1'!E8*'UTILITY REPORT 1'!D8)/'UTILITY REPORT 1'!F8 -> #DIV/0! | G7: =IF('Utility summery'!M11<0,"0",'Utility summery'!M11) -> 0 | H7: 0 | I7: =IF('UTILITY REPORT 1'!G8<0,"0",'UTILITY REPORT 1'!G8) -> 0 | J7: 0 | K7: ='UTILITY REPORT 1'!C8 -> 77 | L7: =E7*F7+G7*H7+#REF!*#REF!+I7*J7 -> #DIV/0!
A8: Serengeti | B8: =B7+1 -> 7 | C8: 3 | D8: 2020 | E8: ='UTILITY REPORT 1'!F9 -> 0 | F8: =('UTILITY REPORT 1'!E9*'UTILITY REPORT 1'!D9)/'UTILITY REPORT 1'!F9 -> #DIV/0! | G8: =IF('Utility summery'!M12<0,"0",'Utility summery'!M12) -> 0 | H8: 0 | I8: =IF('UTILITY REPORT 1'!G9<0,"0",'UTILITY REPORT 1'!G9) -> 0 | J8: 0 | K8: ='UTILITY REPORT 1'!C9 -> 0 | L8: =E8*F8+G8*H8+#REF!*#REF!+I8*J8 -> #DIV/0!
A9: Serengeti | B9: =B8+1 -> 8 | C9: 3 | D9: 2020 | E9: ='UTILITY REPORT 1'!F10 -> 0 | F9: =('UTILITY REPORT 1'!E10*'UTILITY REPORT 1'!D10)/'UTILITY REPORT 1'!F10 -> #DIV/0! | G9: =IF('Utility summery'!M13<0,"0",'Utility summery'!M13) -> 0 | H9: 0 | I9: =IF('UTILITY REPORT 1'!G10<0,"0",'UTILITY REPORT 1'!G10) -> 0 | J9: 0 | K9: ='UTILITY REPORT 1'!C10 -> 0 | L9: =E9*F9+G9*H9+#REF!*#REF!+I9*J9 -> #DIV/0!
A10: Serengeti | B10: =B9+1 -> 9 | C10: 3 | D10: 2020 | E10: ='UTILITY REPORT 1'!F11 -> 0 | F10: =('UTILITY REPORT 1'!E11*'UTILITY REPORT 1'!D11)/'UTILITY REPORT 1'!F11 -> #DIV/0! | G10: =IF('Utility summery'!M14<0,"0",'Utility summery'!M14) -> 0 | H10: 0 | I10: =IF('UTILITY REPORT 1'!G11<0,"0",'UTILITY REPORT 1'!G11) -> 0 | J10: 0 | K10: ='UTILITY REPORT 1'!C11 -> 0 | L10: =E10*F10+G10*H10+#REF!*#REF!+I10*J10 -> #DIV/0!
A11: Serengeti | B11: =B10+1 -> 10 | C11: 3 | D11: 2020 | E11: ='UTILITY REPORT 1'!F12 -> 0 | F11: =('UTILITY REPORT 1'!E12*'UTILITY REPORT 1'!D12)/'UTILITY REPORT 1'!F12 -> #DIV/0! | G11: =IF('Utility summery'!M15<0,"0",'Utility summery'!M15) -> 0 | H11: 0 | I11: =IF('UTILITY REPORT 1'!G12<0,"0",'UTILITY REPORT 1'!G12) -> 0 | J11: 0 | K11: ='UTILITY REPORT 1'!C12 -> 0 | L11: =E11*F11+G11*H11+#REF!*#REF!+I11*J11 -> #DIV/0!
A12: Serengeti | B12: =B11+1 -> 11 | C12: 3 | D12: 2020 | E12: ='UTILITY REPORT 1'!F13 -> 0 | F12: =('UTILITY REPORT 1'!E13*'UTILITY REPORT 1'!D13)/'UTILITY REPORT 1'!F13 -> #DIV/0! | G12: =IF('Utility summery'!M16<0,"0",'Utility summery'!M16) -> 0 | H12: 0 | I12: =IF('UTILITY REPORT 1'!G13<0,"0",'UTILITY REPORT 1'!G13) -> 0 | J12: 0 | K12: ='UTILITY REPORT 1'!C13 -> 0 | L12: =E12*F12+G12*H12+#REF!*#REF!+I12*J12 -> #DIV/0!
A13: Serengeti | B13: =B12+1 -> 12 | C13: 3 | D13: 2020 | E13: ='UTILITY REPORT 1'!F14 -> 0 | F13: =('UTILITY REPORT 1'!E14*'UTILITY REPORT 1'!D14)/'UTILITY REPORT 1'!F14 -> #DIV/0! | G13: =IF('Utility summery'!M17<0,"0",'Utility summery'!M17) -> 0 | H13: 0 | I13: =IF('UTILITY REPORT 1'!G14<0,"0",'UTILITY REPORT 1'!G14) -> 0 | J13: 0 | K13: ='UTILITY REPORT 1'!C14 -> 0 | L13: =E13*F13+G13*H13+#REF!*#REF!+I13*J13 -> #DIV/0!
A14: Serengeti | B14: =B13+1 -> 13 | C14: 3 | D14: 2020 | E14: ='UTILITY REPORT 1'!F15 -> 0 | F14: =('UTILITY REPORT 1'!E15*'UTILITY REPORT 1'!D15)/'UTILITY REPORT 1'!F15 -> #DIV/0! | G14: =IF('Utility summery'!M18<0,"0",'Utility summery'!M18) -> 0 | H14: 0 | I14: =IF('UTILITY REPORT 1'!G15<0,"0",'UTILITY REPORT 1'!G15) -> 0 | J14: 0 | K14: ='UTILITY REPORT 1'!C15 -> 0 | L14: =E14*F14+G14*H14+#REF!*#REF!+I14*J14 -> #DIV/0!
... A30: Serengeti | B30: =B29+1 -> 29 | C30: 3 | D30: 2020 | E30: ='UTILITY REPORT 1'!F31 -> 0 | F30: =('UTILITY REPORT 1'!E31*'UTILITY REPORT 1'!D31)/'UTILITY REPORT 1'!F31 -> #DIV/0! | G30: =IF('Utility summery'!M34<0,"0",'Utility summery'!M34) -> 0 | H30: 0 | I30: =IF('UTILITY REPORT 1'!G31<0,"0",'UTILITY REPORT 1'!G31) -> 0 | J30: 0 | K30: ='UTILITY REPORT 1'!C31 -> 0 | L30: =E30*F30+G30*H30+#REF!*#REF!+I30*J30 -> #DIV/0!
A31: Serengeti | B31: 30 | C31: 3 | D31: 2020 | E31: ='UTILITY REPORT 1'!F32 -> 0 | F31: =('UTILITY REPORT 1'!E32*'UTILITY REPORT 1'!D32)/'UTILITY REPORT 1'!F32 -> #DIV/0! | G31: =IF('Utility summery'!M35<0,"0",'Utility summery'!M35) -> 0 | H31: 0 | I31: =IF('UTILITY REPORT 1'!G32<0,"0",'UTILITY REPORT 1'!G32) -> 0 | J31: 0 | K31: ='UTILITY REPORT 1'!C32 -> 0 | L31: =E31*F31+G31*H31+#REF!*#REF!+I31*J31 -> #DIV/0!
A32: Serengeti | B32: 31 | C32: 3 | D32: 2020 | E32: ='UTILITY REPORT 1'!F33 -> 0 | F32: =('UTILITY REPORT 1'!E33*'UTILITY REPORT 1'!D33)/'UTILITY REPORT 1'!F33 -> #DIV/0! | G32: =IF('Utility summery'!M36<0,"0",'Utility summery'!M36) -> 0 | H32: 0 | I32: =IF('UTILITY REPORT 1'!G33<0,"0",'UTILITY REPORT 1'!G33) -> 0 | J32: 0 | K32: ='UTILITY REPORT 1'!C33 -> 0

Sheet Submetering
A1: Site Name | B1: Day | C1: Month | D1: Year | E1: Transport Consumption (LT) | F1: Generators Consumption (LT) | G1: Total Electricity Kwh | H1: Kitchen (KWh) | I1: Laundry (KWh) | J1: STP (M3) | K1: RO prodution (M3) | L1: Amani Restaurant (M3) | M1: Kitchen (M3) | N1: Laundry (M3) | O1: Laundry (M3) | P1: Total water Consumption (M3) | Q1: Borehole #1 (M3) | R1: Borehole #2 (M3) | S1: Borehole #3 (M3) | T1: Borehole #4 (M3) | U1: Borehole #5 (M3) | V1: Borehole #6 (M3) | W1: Total Bore holes production (M3) | X1: Room Nights
A2: Serengeti | B2: 1 | C2: 3 | D2: 2020 | E2: ='UTILITY REPORT 1'!I3 -> 321.77 | F2: ='UTILITY REPORT 1'!E3 -> 2246.69 | G2: ='UTILITY REPORT 1'!F3 -> 5649 | H2: =IF('Kit report'!F4<0,"0",'Kit report'!F4) -> 552 | I2: =IF('Kit report'!X4<0,"0",'Kit report'!X4) -> 980 | J2: =IF('Utility summery'!H6<0,"0",'Utility summery'!H6) -> 100 | K2: =IF('UTILITY REPORT 1'!H3<0,"0",'UTILITY REPORT 1'!H3) -> 182 | L2: ='Water-Meter'!K6 -> 3 | M2: ='Water-Meter'!H6 -> 0 | N2: ='Water-Meter'!Q6 -> 11 | O2: =K2*E2+H2*I2+#REF!*#REF!+J2*L2 -> #REF! | P2: ='Water-Meter'!E6 -> 146 | Q2: =IF('Water-Meter'!U6<0,"0",'Water-Meter'!U6) -> 58 | R2: =IF('Water-Meter'!X6<0,"0",'Water-Meter'!X6) -> 42 | S2: =IF('Water-Meter'!AA6<0,"0",'Water-Meter'!AA6) -> 68 | T2: =IF('Water-Meter'!AD6<0,"0",'Water-Meter'!AD6) -> 14 | U2: =IF('Water-Meter'!AG6<0,"0",'Water-Meter'!AG6) -> 24 | V2: =IF('Water-Meter'!AJ6<0,"0",'Water-Meter'!AJ6) -> 0 | W2: ='Water-Meter'!AN6 -> 206 | X2: =Total!K2 -> 46
A3: Serengeti | B3: =B2+1 -> 2 | C3: 3 | D3: 2020 | E3: ='UTILITY REPORT 1'!I4 -> 281.34 | F3: ='UTILITY REPORT 1'!E4 -> 2125.48 | G3: ='UTILITY REPORT 1'!F4 -> 5543 | H3: =IF('Kit report'!F5<0,"0",'Kit report'!F5) -> 528 | I3: =IF('Kit report'!X5<0,"0",'Kit report'!X5) -> 940 | J3: =IF('Utility summery'!H7<0,"0",'Utility summery'!H7) -> 105 | K3: =IF('UTILITY REPORT 1'!H4<0,"0",'UTILITY REPORT 1'!H4) -> 184 | L3: ='Water-Meter'!K7 -> 3 | M3: ='Water-Meter'!H7 -> 0 | N3: ='Water-Meter'!Q7 -> 9 | O3: =K3*E3+H3*I3+#REF!*#REF!+J3*L3 -> #REF! | P3: ='Water-Meter'!E7 -> 164 | Q3: =IF('Water-Meter'!U7<0,"0",'Water-Meter'!U7) -> 59 | R3: =IF('Water-Meter'!X7<0,"0",'Water-Meter'!X7) -> 52 | S3: =IF('Water-Meter'!AA7<0,"0",'Water-Meter'!AA7) -> 46 | T3: =IF('Water-Meter'!AD7<0,"0",'Water-Meter'!AD7) -> 8 | U3: =IF('Water-Meter'!AG7<0,"0",'Water-Meter'!AG7) -> 26 | V3: =IF('Water-Meter'!AJ7<0,"0",'Water-Meter'!AJ7) -> 0 | W3: ='Water-Meter'!AN7 -> 191 | X3: =Total!K3 -> 17
A4: Serengeti | B4: =B3+1 -> 3 | C4: 3 | D4: 2020 | E4: ='UTILITY REPORT 1'!I5 -> 55.1 | F4: ='UTILITY REPORT 1'!E5 -> 2081.28 | G4: ='UTILITY REPORT 1'!F5 -> 4636 | H4: =IF('Kit report'!F6<0,"0",'Kit report'!F6) -> 480 | I4: =IF('Kit report'!X6<0,"0",'Kit report'!X6) -> 640 | J4: =IF('Utility summery'!H8<0,"0",'Utility summery'!H8) -> 79 | K4: =IF('UTILITY REPORT 1'!H5<0,"0",'UTILITY REPORT 1'!H5) -> 151 | L4: ='Water-Meter'!K8 -> 2 | M4: ='Water-Meter'!H8 -> 0 | N4: ='Water-Meter'!Q8 -> 10 | O4: =K4*E4+H4*I4+#REF!*#REF!+J4*L4 -> #REF! | P4: ='Water-Meter'!E8 -> 164 | Q4: =IF('Water-Meter'!U8<0,"0",'Water-Meter'!U8) -> 57 | R4: =IF('Water-Meter'!X8<0,"0",'Water-Meter'!X8) -> 66 | S4: =IF('Water-Meter'!AA8<0,"0",'Water-Meter'!AA8) -> 59 | T4: =IF('Water-Meter'!AD8<0,"0",'Water-Meter'!AD8) -> 14 | U4: =IF('Water-Meter'!AG8<0,"0",'Water-Meter'!AG8) -> 25 | V4: =IF('Water-Meter'!AJ8<0,"0",'Water-Meter'!AJ8) -> 0 | W4: ='Water-Meter'!AN8 -> 221 | X4: =Total!K4 -> 12
A5: Serengeti | B5: =B4+1 -> 4 | C5: 3 | D5: 2020 | E5: ='UTILITY REPORT 1'!I6 -> 149.94 | F5: ='UTILITY REPORT 1'!E6 -> 2421.29 | G5: ='UTILITY REPORT 1'!F6 -> 6200 | H5: =IF('Kit report'!F7<0,"0",'Kit report'!F7) -> 552 | I5: =IF('Kit report'!X7<0,"0",'Kit report'!X7) -> 1660 | J5: =IF('Utility summery'!H9<0,"0",'Utility summery'!H9) -> 81 | K5: =IF('UTILITY REPORT 1'!H6<0,"0",'UTILITY REPORT 1'!H6) -> 153 | L5: ='Water-Meter'!K9 -> 4 | M5: ='Water-Meter'!H9 -> 0 | N5: ='Water-Meter'!Q9 -> 11 | O5: =K5*E5+H5*I5+#REF!*#REF!+J5*L5 -> #REF! | P5: ='Water-Meter'!E9 -> 163 | Q5: =IF('Water-Meter'!U9<0,"0",'Water-Meter'!U9) -> 58 | R5: =IF('Water-Meter'!X9<0,"0",'Water-Meter'!X9) -> 61 | S5: =IF('Water-Meter'!AA9<0,"0",'Water-Meter'!AA9) -> 47 | T5: =IF('Water-Meter'!AD9<0,"0",'Water-Meter'!AD9) -> 11 | U5: =IF('Water-Meter'!AG9<0,"0",'Water-Meter'!AG9) -> 26 | V5: =IF('Water-Meter'!AJ9<0,"0",'Water-Meter'!AJ9) -> 0 | W5: ='Water-Meter'!AN9 -> 203 | X5: =Total!K5 -> 77
A6: Serengeti | B6: =B5+1 -> 5 | C6: 3 | D6: 2020 | E6: ='UTILITY REPORT 1'!I7 -> 0 | F6: ='UTILITY REPORT 1'!E7 -> 0 | G6: ='UTILITY REPORT 1'!F7 -> 0 | H6: =IF('Kit report'!F8<0,"0",'Kit report'!F8) -> 0 | I6: =IF('Kit report'!X8<0,"0",'Kit report'!X8) -> 0 | J6: =IF('Utility summery'!H10<0,"0",'Utility summery'!H10) -> 0 | K6: =IF('UTILITY REPORT 1'!H7<0,"0",'UTILITY REPORT 1'!H7) -> 0 | L6: ='Water-Meter'!K10 -> 0 | M6: ='Water-Meter'!H10 -> 0 | N6: ='Water-Meter'!Q10 -> 0 | O6: =K6*E6+H6*I6+#REF!*#REF!+J6*L6 -> #REF! | P6: ='Water-Meter'!E10 -> 0 | Q6: =IF('Water-Meter'!U10<0,"0",'Water-Meter'!U10) -> 0 | R6: =IF('Water-Meter'!X10<0,"0",'Water-Meter'!X10) -> 0 | S6: =IF('Water-Meter'!AA10<0,"0",'Water-Meter'!AA10) -> 0 | T6: =IF('Water-Meter'!AD10<0,"0",'Water-Meter'!AD10) -> 0 | U6: =IF('Water-Meter'!AG10<0,"0",'Water-Meter'!AG10) -> 0 | V6: =IF('Water-Meter'!AJ10<0,"0",'Water-Meter'!AJ10) -> 0 | W6: ='Water-Meter'!AN10 -> 0 | X6: =Total!K6 -> 77
A7: Serengeti | B7: =B6+1 -> 6 | C7: 3 | D7: 2020 | E7: ='UTILITY REPORT 1'!I8 -> 0 | F7: ='UTILITY REPORT 1'!E8 -> 0 | G7: ='UTILITY REPORT 1'!F8 -> 0 | H7: =IF('Kit report'!F9<0,"0",'Kit report'!F9) -> 0 | I7: =IF('Kit report'!X9<0,"0",'Kit report'!X9) -> 0 | J7: =IF('Utility summery'!H11<0,"0",'Utility summery'!H11) -> 0 | K7: =IF('UTILITY REPORT 1'!H8<0,"0",'UTILITY REPORT 1'!H8) -> 0 | L7: ='Water-Meter'!K11 -> 0 | M7: ='Water-Meter'!H11 -> 0 | N7: ='Water-Meter'!Q11 -> 0 | O7: =K7*E7+H7*I7+#REF!*#REF!+J7*L7 -> #REF! | P7: ='Water-Meter'!E11 -> 0 | Q7: =IF('Water-Meter'!U11<0,"0",'Water-Meter'!U11) -> 0 | R7: =IF('Water-Meter'!X11<0,"0",'Water-Meter'!X11) -> 0 | S7: =IF('Water-Meter'!AA11<0,"0",'Water-Meter'!AA11) -> 0 | T7: =IF('Water-Meter'!AD11<0,"0",'Water-Meter'!AD11) -> 0 | U7: =IF('Water-Meter'!AG11<0,"0",'Water-Meter'!AG11) -> 0 | V7: =IF('Water-Meter'!AJ11<0,"0",'Water-Meter'!AJ11) -> 0 | W7: ='Water-Meter'!AN11 -> 0 | X7: =Total!K7 -> 77
A8: Serengeti | B8: =B7+1 -> 7 | C8: 3 | D8: 2020 | E8: ='UTILITY REPORT 1'!I9 -> 0 | F8: ='UTILITY REPORT 1'!E9 -> 0 | G8: ='UTILITY REPORT 1'!F9 -> 0 | H8: =IF('Kit report'!F10<0,"0",'Kit report'!F10) -> 0 | I8: =IF('Kit report'!X10<0,"0",'Kit report'!X10) -> 0 | J8: =IF('Utility summery'!H12<0,"0",'Utility summery'!H12) -> 0 | K8: =IF('UTILITY REPORT 1'!H9<0,"0",'UTILITY REPORT 1'!H9) -> 0 | L8: ='Water-Meter'!K12 -> 0 | M8: ='Water-Meter'!H12 -> 0 | N8: ='Water-Meter'!Q12 -> 0 | O8: =K8*E8+H8*I8+#REF!*#REF!+J8*L8 -> #REF! | P8: ='Water-Meter'!E12 -> 0 | Q8: =IF('Water-Meter'!U12<0,"0",'Water-Meter'!U12) -> 0 | R8: =IF('Water-Meter'!X12<0,"0",'Water-Meter'!X12) -> 0 | S8: =IF('Water-Meter'!AA12<0,"0",'Water-Meter'!AA12) -> 0 | T8: =IF('Water-Meter'!AD12<0,"0",'Water-Meter'!AD12) -> 0 | U8: =IF('Water-Meter'!AG12<0,"0",'Water-Meter'!AG12) -> 0 | V8: =IF('Water-Meter'!AJ12<0,"0",'Water-Meter'!AJ12) -> 0 | W8: ='Water-Meter'!AN12 -> 0 | X8: =Total!K8 -> 0
A9: Serengeti | B9: =B8+1 -> 8 | C9: 3 | D9: 2020 | E9: ='UTILITY REPORT 1'!I10 -> 0 | F9: ='UTILITY REPORT 1'!E10 -> 0 | G9: ='UTILITY REPORT 1'!F10 -> 0 | H9: =IF('Kit report'!F11<0,"0",'Kit report'!F11) -> 0 | I9: =IF('Kit report'!X11<0,"0",'Kit report'!X11) -> 0 | J9: =IF('Utility summery'!H13<0,"0",'Utility summery'!H13) -> 0 | K9: =IF('UTILITY REPORT 1'!H10<0,"0",'UTILITY REPORT 1'!H10) -> 0 | L9: ='Water-Meter'!K13 -> 0 | M9: ='Water-Meter'!H13 -> 0 | N9: ='Water-Meter'!Q13 -> 0 | O9: =K9*E9+H9*I9+#REF!*#REF!+J9*L9 -> #REF! | P9: ='Water-Meter'!E13 -> 0 | Q9: =IF('Water-Meter'!U13<0,"0",'Water-Meter'!U13) -> 0 | R9: =IF('Water-Meter'!X13<0,"0",'Water-Meter'!X13) -> 0 | S9: =IF('Water-Meter'!AA13<0,"0",'Water-Meter'!AA13) -> 0 | T9: =IF('Water-Meter'!AD13<0,"0",'Water-Meter'!AD13) -> 0 | U9: =IF('Water-Meter'!AG13<0,"0",'Water-Meter'!AG13) -> 0 | V9: =IF('Water-Meter'!AJ13<0,"0",'Water-Meter'!AJ13) -> 0 | W9: ='Water-Meter'!AN13 -> 0 | X9: =Total!K9 -> 0
A10: Serengeti | B10: =B9+1 -> 9 | C10: 3 | D10: 2020 | E10: ='UTILITY REPORT 1'!I11 -> 0 | F10: ='UTILITY REPORT 1'!E11 -> 0 | G10: ='UTILITY REPORT 1'!F11 -> 0 | H10: =IF('Kit report'!F12<0,"0",'Kit report'!F12) -> 0 | I10: =IF('Kit report'!X12<0,"0",'Kit report'!X12) -> 0 | J10: =IF('Utility summery'!H14<0,"0",'Utility summery'!H14) -> 0 | K10: =IF('UTILITY REPORT 1'!H11<0,"0",'UTILITY REPORT 1'!H11) -> 0 | L10: ='Water-Meter'!K14 -> 0 | M10: ='Water-Meter'!H14 -> 0 | N10: ='Water-Meter'!Q14 -> 0 | O10: =K10*E10+H10*I10+#REF!*#REF!+J10*L10 -> #REF! | P10: ='Water-Meter'!E14 -> 0 | Q10: =IF('Water-Meter'!U14<0,"0",'Water-Meter'!U14) -> 0 | R10: =IF('Water-Meter'!X14<0,"0",'Water-Meter'!X14) -> 0 | S10: =IF('Water-Meter'!AA14<0,"0",'Water-Meter'!AA14) -> 0 | T10: =IF('Water-Meter'!AD14<0,"0",'Water-Meter'!AD14) -> 0 | U10: =IF('Water-Meter'!AG14<0,"0",'Water-Meter'!AG14) -> 0 | V10: =IF('Water-Meter'!AJ14<0,"0",'Water-Meter'!AJ14) -> 0 | W10: ='Water-Meter'!AN14 -> 0 | X10: =Total!K10 -> 0
A11: Serengeti | B11: =B10+1 -> 10 | C11: 3 | D11: 2020 | E11: ='UTILITY REPORT 1'!I12 -> 0 | F11: ='UTILITY REPORT 1'!E12 -> 0 | G11: ='UTILITY REPORT 1'!F12 -> 0 | H11: =IF('Kit report'!F13<0,"0",'Kit report'!F13) -> 0 | I11: =IF('Kit report'!X13<0,"0",'Kit report'!X13) -> 0 | J11: =IF('Utility summery'!H15<0,"0",'Utility summery'!H15) -> 0 | K11: =IF('UTILITY REPORT 1'!H12<0,"0",'UTILITY REPORT 1'!H12) -> 0 | L11: ='Water-Meter'!K15 -> 0 | M11: ='Water-Meter'!H15 -> 0 | N11: ='Water-Meter'!Q15 -> 0 | O11: =K11*E11+H11*I11+#REF!*#REF!+J11*L11 -> #REF! | P11: ='Water-Meter'!E15 -> 0 | Q11: =IF('Water-Meter'!U15<0,"0",'Water-Meter'!U15) -> 0 | R11: =IF('Water-Meter'!X15<0,"0",'Water-Meter'!X15) -> 0 | S11: =IF('Water-Meter'!AA15<0,"0",'Water-Meter'!AA15) -> 0 | T11: =IF('Water-Meter'!AD15<0,"0",'Water-Meter'!AD15) -> 0 | U11: =IF('Water-Meter'!AG15<0,"0",'Water-Meter'!AG15) -> 0 | V11: =IF('Water-Meter'!AJ15<0,"0",'Water-Meter'!AJ15) -> 0 | W11: ='Water-Meter'!AN15 -> 0 | X11: =Total!K11 -> 0
A12: Serengeti | B12: =B11+1 -> 11 | C12: 3 | D12: 2020 | E12: ='UTILITY REPORT 1'!I13 -> 0 | F12: ='UTILITY REPORT 1'!E13 -> 0 | G12: ='UTILITY REPORT 1'!F13 -> 0 | H12: =IF('Kit report'!F14<0,"0",'Kit report'!F14) -> 0 | I12: =IF('Kit report'!X14<0,"0",'Kit report'!X14) -> 0 | J12: =IF('Utility summery'!H16<0,"0",'Utility summery'!H16) -> 0 | K12: =IF('UTILITY REPORT 1'!H13<0,"0",'UTILITY REPORT 1'!H13) -> 0 | L12: ='Water-Meter'!K16 -> 0 | M12: ='Water-Meter'!H16 -> 0 | N12: ='Water-Meter'!Q16 -> 0 | O12: =K12*E12+H12*I12+#REF!*#REF!+J12*L12 -> #REF! | P12: ='Water-Meter'!E16 -> 0 | Q12: =IF('Water-Meter'!U16<0,"0",'Water-Meter'!U16) -> 0 | R12: =IF('Water-Meter'!X16<0,"0",'Water-Meter'!X16) -> 0 | S12: =IF('Water-Meter'!AA16<0,"0",'Water-Meter'!AA16) -> 0 | T12: =IF('Water-Meter'!AD16<0,"0",'Water-Meter'!AD16) -> 0 | U12: =IF('Water-Meter'!AG16<0,"0",'Water-Meter'!AG16) -> 0 | V12: =IF('Water-Meter'!AJ16<0,"0",'Water-Meter'!AJ16) -> 0 | W12: ='Water-Meter'!AN16 -> 0 | X12: =Total!K12 -> 0
A13: Serengeti | B13: =B12+1 -> 12 | C13: 3 | D13: 2020 | E13: ='UTILITY REPORT 1'!I14 -> 0 | F13: ='UTILITY REPORT 1'!E14 -> 0 | G13: ='UTILITY REPORT 1'!F14 -> 0 | H13: =IF('Kit report'!F15<0,"0",'Kit report'!F15) -> 0 | I13: =IF('Kit report'!X15<0,"0",'Kit report'!X15) -> 0 | J13: =IF('Utility summery'!H17<0,"0",'Utility summery'!H17) -> 0 | K13: =IF('UTILITY REPORT 1'!H14<0,"0",'UTILITY REPORT 1'!H14) -> 0 | L13: ='Water-Meter'!K17 -> 0 | M13: ='Water-Meter'!H17 -> 0 | N13: ='Water-Meter'!Q17 -> 0 | O13: =K13*E13+H13*I13+#REF!*#REF!+J13*L13 -> #REF! | P13: ='Water-Meter'!E17 -> 0 | Q13: =IF('Water-Meter'!U17<0,"0",'Water-Meter'!U17) -> 0 | R13: =IF('Water-Meter'!X17<0,"0",'Water-Meter'!X17) -> 0 | S13: =IF('Water-Meter'!AA17<0,"0",'Water-Meter'!AA17) -> 0 | T13: =IF('Water-Meter'!AD17<0,"0",'Water-Meter'!AD17) -> 0 | U13: =IF('Water-Meter'!AG17<0,"0",'Water-Meter'!AG17) -> 0 | V13: =IF('Water-Meter'!AJ17<0,"0",'Water-Meter'!AJ17) -> 0 | W13: ='Water-Meter'!AN17 -> 0 | X13: =Total!K13 -> 0
A14: Serengeti | B14: =B13+1 -> 13 | C14: 3 | D14: 2020 | E14: ='UTILITY REPORT 1'!I15 -> 0 | F14: ='UTILITY REPORT 1'!E15 -> 0 | G14: ='UTILITY REPORT 1'!F15 -> 0 | H14: =IF('Kit report'!F16<0,"0",'Kit report'!F16) -> 0 | I14: =IF('Kit report'!X16<0,"0",'Kit report'!X16) -> 0 | J14: =IF('Utility summery'!H18<0,"0",'Utility summery'!H18) -> 0 | K14: =IF('UTILITY REPORT 1'!H15<0,"0",'UTILITY REPORT 1'!H15) -> 0 | L14: ='Water-Meter'!K18 -> 0 | M14: ='Water-Meter'!H18 -> 0 | N14: ='Water-Meter'!Q18 -> 0 | O14: =K14*E14+H14*I14+#REF!*#REF!+J14*L14 -> #REF! | P14: ='Water-Meter'!E18 -> 0 | Q14: =IF('Water-Meter'!U18<0,"0",'Water-Meter'!U18) -> 0 | R14: =IF('Water-Meter'!X18<0,"0",'Water-Meter'!X18) -> 0 | S14: =IF('Water-Meter'!AA18<0,"0",'Water-Meter'!AA18) -> 0 | T14: =IF('Water-Meter'!AD18<0,"0",'Water-Meter'!AD18) -> 0 | U14: =IF('Water-Meter'!AG18<0,"0",'Water-Meter'!AG18) -> 0 | V14: =IF('Water-Meter'!AJ18<0,"0",'Water-Meter'!AJ18) -> 0 | W14: ='Water-Meter'!AN18 -> 0 | X14: =Total!K14 -> 0
... A30: Serengeti | B30: =B29+1 -> 29 | C30: 3 | D30: 2020 | E30: ='UTILITY REPORT 1'!I31 -> 0 | F30: ='UTILITY REPORT 1'!E31 -> 0 | G30: ='UTILITY REPORT 1'!F31 -> 0 | H30: =IF('Kit report'!F32<0,"0",'Kit report'!F32) -> 0 | I30: =IF('Kit report'!X32<0,"0",'Kit report'!X32) -> 0 | J30: =IF('Utility summery'!H34<0,"0",'Utility summery'!H34) -> 0 | K30: =IF('UTILITY REPORT 1'!H31<0,"0",'UTILITY REPORT 1'!H31) -> 0 | L30: ='Water-Meter'!K34 -> 0 | M30: ='Water-Meter'!H34 -> 0 | N30: ='Water-Meter'!Q34 -> 0 | O30: =K30*E30+H30*I30+#REF!*#REF!+J30*L30 -> #REF! | P30: ='Water-Meter'!E34 -> 0 | Q30: =IF('Water-Meter'!U34<0,"0",'Water-Meter'!U34) -> 0 | R30: =IF('Water-Meter'!X34<0,"0",'Water-Meter'!X34) -> 0 | S30: =IF('Water-Meter'!AA34<0,"0",'Water-Meter'!AA34) -> 0 | T30: =IF('Water-Meter'!AD34<0,"0",'Water-Meter'!AD34) -> 0 | U30: =IF('Water-Meter'!AG34<0,"0",'Water-Meter'!AG34) -> 0 | V30: =IF('Water-Meter'!AJ34<0,"0",'Water-Meter'!AJ34) -> 0 | W30: ='Water-Meter'!AN34 -> 0 | X30: =Total!K30 -> 0
A31: Serengeti | B31: 30 | C31: 3 | D31: 2020 | E31: ='UTILITY REPORT 1'!I32 -> 0 | F31: ='UTILITY REPORT 1'!E32 -> 0 | G31: ='UTILITY REPORT 1'!F32 -> 0 | H31: =IF('Kit report'!F33<0,"0",'Kit report'!F33) -> 0 | I31: =IF('Kit report'!X33<0,"0",'Kit report'!X33) -> 0 | J31: =IF('Utility summery'!H35<0,"0",'Utility summery'!H35) -> 0 | K31: =IF('UTILITY REPORT 1'!H32<0,"0",'UTILITY REPORT 1'!H32) -> 0 | L31: ='Water-Meter'!K35 -> 0 | M31: ='Water-Meter'!H35 -> 0 | N31: ='Water-Meter'!Q35 -> 0 | O31: =K31*E31+H31*I31+#REF!*#REF!+J31*L31 -> #REF! | P31: ='Water-Meter'!E35 -> 0 | Q31: =IF('Water-Meter'!U35<0,"0",'Water-Meter'!U35) -> 0 | R31: =IF('Water-Meter'!X35<0,"0",'Water-Meter'!X35) -> 0 | S31: =IF('Water-Meter'!AA35<0,"0",'Water-Meter'!AA35) -> 0 | T31: =IF('Water-Meter'!AD35<0,"0",'Water-Meter'!AD35) -> 0 | U31: =IF('Water-Meter'!AG35<0,"0",'Water-Meter'!AG35) -> 0 | V31: =IF('Water-Meter'!AJ35<0,"0",'Water-Meter'!AJ35) -> 0 | W31: ='Water-Meter'!AN35 -> 0 | X31: =Total!K31 -> 0
A32: Serengeti | B32: 31 | C32: 3 | D32: 2020 | E32: ='UTILITY REPORT 1'!I33 -> 0 | F32: ='UTILITY REPORT 1'!E33 -> 0 | G32: ='UTILITY REPORT 1'!F33 -> 0 | H32: =IF('Kit report'!F34<0,"0",'Kit report'!F34) -> 0 | I32: =IF('Kit report'!X34<0,"0",'Kit report'!X34) -> 0 | J32: =IF('Utility summery'!H36<0,"0",'Utility summery'!H36) -> 0 | K32: =IF('UTILITY REPORT 1'!H33<0,"0",'UTILITY REPORT 1'!H33) -> 0 | L32: ='Water-Meter'!K36 -> 0 | M32: ='Water-Meter'!H36 -> 0 | N32: ='Water-Meter'!Q36 -> 0 | P32: ='Water-Meter'!E36 -> 0 | Q32: =IF('Water-Meter'!U36<0,"0",'Water-Meter'!U36) -> 0 | R32: =IF('Water-Meter'!X36<0,"0",'Water-Meter'!X36) -> 0 | S32: =IF('Water-Meter'!AA36<0,"0",'Water-Meter'!AA36) -> 0 | T32: =IF('Water-Meter'!AD36<0,"0",'Water-Meter'!AD36) -> 0 | U32: =IF('Water-Meter'!AG36<0,"0",'Water-Meter'!AG36) -> 0 | V32: =IF('Water-Meter'!AJ36<0,"0",'Water-Meter'!AJ36) -> 0 | W32: ='Water-Meter'!AN36 -> 0 | X32: =Total!K32 -> 0

Sheet UTILITY REPORT 1
A1: NOVEMBER UTILITY REPORT
A2: Date | B2: % | C2: Guest Rooms Occupied | D2: Diesel cost Per Liter ($) | E2: Diesel consumption (LT) | F2: Power production (KW) | G2: Water consumption (M3) | H2: RO prodution (M3) | I2: Transport Consupmtion (LT)
A3: 43862 | B3: =Gen!C11 -> 0.5714 | C3: ='Summery Report'!E5 -> 46 | D3: 1 | E3: =Gen!T11 -> 2246.69 | F3: =Gen!U11 -> 5649 | G3: ='Water-Meter'!E6 -> 146 | H3: ='Utility report '!AC6 -> 182 | I3: =Gen!AK11 -> 321.77
A4: 43863 | B4: =Gen!C12 -> 0.2208 | C4: ='Summery Report'!E6 -> 17 | D4: 1 | E4: =Gen!T12 -> 2125.48 | F4: =Gen!U12 -> 5543 | G4: ='Water-Meter'!E7 -> 164 | H4: ='Utility report '!AC7 -> 184 | I4: =Gen!AK12 -> 281.34
A5: 43864 | B5: =Gen!C13 -> 0.1429 | C5: ='Summery Report'!E7 -> 12 | D5: 1 | E5: =Gen!T13 -> 2081.28 | F5: =Gen!U13 -> 4636 | G5: ='Water-Meter'!E8 -> 164 | H5: ='Utility report '!AC8 -> 151 | I5: =Gen!AK13 -> 55.1
A6: 43865 | B6: =Gen!C14 -> 1 | C6: ='Summery Report'!E8 -> 77 | D6: 1 | E6: =Gen!T14 -> 2421.29 | F6: =Gen!U14 -> 6200 | G6: ='Water-Meter'!E9 -> 163 | H6: ='Utility report '!AC9 -> 153 | I6: =Gen!AK14 -> 149.94
A7: 43866 | B7: =Gen!C15 -> 1 | C7: ='Summery Report'!E9 -> 77 | D7: 1 | E7: =Gen!T15 -> 0 | F7: =Gen!U15 -> 0 | G7: ='Water-Meter'!E10 -> 0 | H7: ='Utility report '!AC10 -> -27663 | I7: =Gen!AK15 -> 0
A8: 43867 | B8: =Gen!C16 -> 0 | C8: ='Summery Report'!E10 -> 77 | D8: 1 | E8: =Gen!T16 -> 0 | F8: =Gen!U16 -> 0 | G8: ='Water-Meter'!E11 -> 0 | H8: ='Utility report '!AC11 -> 0 | I8: =Gen!AK16 -> 0
A9: 43868 | B9: =Gen!C17 -> 0 | C9: ='Summery Report'!E11 -> 0 | D9: 1 | E9: =Gen!T17 -> 0 | F9: =Gen!U17 -> 0 | G9: ='Water-Meter'!E12 -> 0 | H9: ='Utility report '!AC12 -> 0 | I9: =Gen!AK17 -> 0
A10: 43869 | B10: =Gen!C18 -> 0 | C10: ='Summery Report'!E12 -> 0 | D10: 1 | E10: =Gen!T18 -> 0 | F10: =Gen!U18 -> 0 | G10: ='Water-Meter'!E13 -> 0 | H10: ='Utility report '!AC13 -> 0 | I10: =Gen!AK18 -> 0
A11: 43870 | B11: =Gen!C19 -> 0 | C11: ='Summery Report'!E13 -> 0 | D11: 1 | E11: =Gen!T19 -> 0 | F11: =Gen!U19 -> 0 | G11: ='Water-Meter'!E14 -> 0 | H11: ='Utility report '!AC14 -> 0 | I11: =Gen!AK19 -> 0
A12: 43871 | B12: =Gen!C20 -> 0 | C12: ='Summery Report'!E14 -> 0 | D12: 1 | E12: =Gen!T20 -> 0 | F12: =Gen!U20 -> 0 | G12: ='Water-Meter'!E15 -> 0 | H12: ='Utility report '!AC15 -> 0 | I12: =Gen!AK20 -> 0
A13: 43872 | B13: =Gen!C21 -> 0 | C13: ='Summery Report'!E15 -> 0 | D13: 1 | E13: =Gen!T21 -> 0 | F13: =Gen!U21 -> 0 | G13: ='Water-Meter'!E16 -> 0 | H13: ='Utility report '!AC16 -> 0 | I13: =Gen!AK21 -> 0
A14: 43873 | B14: =Gen!C22 -> 0 | C14: ='Summery Report'!E16 -> 0 | D14: 1 | E14: =Gen!T22 -> 0 | F14: =Gen!U22 -> 0 | G14: ='Water-Meter'!E17 -> 0 | H14: ='Utility report '!AC17 -> 0 | I14: =Gen!AK22 -> 0
... A34: 43893 | B34: =Gen!C42 -> 0 | C34: ='Summery Report'!E36 -> 0 | D34: 2 | E34: =Gen!T42 -> 0 | F34: =Gen!U42 -> 0 | G34: ='Water-Meter'!E37 -> 0 | H34: ='Utility report '!AC37 -> 0 | I34: =Gen!AK42 -> 0

Sheet Utility summery
A4: Date | B4: Room Occupied | C4: Electricity Units Generated KW | D4: Diseal | G4: Water | J4: Gas | N4: Cost of utilites
D5: Generator | E5: Transport | F5: Total | G5: RO | H5: STP | I5: Total Consumption | J5: 2 ton | K5: 1 Ton | L5: 1 Ton | M5: Total consumption | N5: Electricity /1.4$/liter | O5: Diseal for Transport | P5: Gas /2.38$/Kg | Q5: Total HLP Cost | R5: Electricity Cost/Room $ | S5: cost/Room $
A6: =Gen!B11 -> 43891 | B6: ='Summery Report'!E5 -> 46 | C6: =Gen!U11 -> 5649 | D6: =Gen!T11 -> 2246.69 | E6: =Gen!AK11 -> 321.77 | F6: =Gen!AS11 -> 2568.46 | G6: ='Utility report '!AC6 -> 182 | H6: ='Utility report '!AE6 -> 100 | I6: ='Water-Meter'!E6 -> 146 | J6: ='Lpg (2)'!B10 -> 62 | K6: ='Lpg (2)'!C10 -> 0 | L6: ='Lpg (2)'!D10 -> 0 | M6: ='Lpg (2)'!G10 -> 123.068 | O6: =E6 -> 321.77 | P6: ='[1]Lpg (2)'!#REF! -> #REF! | Q6: ='[1]Summery Report'!#REF! -> #REF! | R6: =N6/B6 -> 0 | S6: =Q6/B6 -> #REF!
A7: =Gen!B12 -> 43892 | B7: ='Summery Report'!E6 -> 17 | C7: =Gen!U12 -> 5543 | D7: =Gen!T12 -> 2125.48 | E7: =Gen!AK12 -> 281.34 | F7: =Gen!AS12 -> 2406.82 | G7: ='Utility report '!AC7 -> 184 | H7: ='Utility report '!AE7 -> 105 | I7: ='Water-Meter'!E7 -> 164 | J7: ='Lpg (2)'!B11 -> 59 | K7: ='Lpg (2)'!C11 -> 0 | L7: ='Lpg (2)'!D11 -> 0 | M7: ='Lpg (2)'!G11 -> 166.276 | N7: =D7*1.4 -> 2975.672 | O7: =E7*1.4 -> 393.876 | P7: ='[1]Lpg (2)'!#REF! -> #REF! | Q7: ='[1]Summery Report'!#REF! -> #REF! | R7: =N7/B7 -> 175.03953 | S7: =Q7/B7 -> #REF!
A8: =Gen!B13 -> 43893 | B8: ='Summery Report'!E7 -> 12 | C8: =Gen!U13 -> 4636 | D8: =Gen!T13 -> 2081.28 | E8: =Gen!AK13 -> 55.1 | F8: =Gen!AS13 -> 2136.38 | G8: ='Utility report '!AC8 -> 151 | H8: ='Utility report '!AE8 -> 79 | I8: ='Water-Meter'!E8 -> 164 | J8: ='Lpg (2)'!B12 -> 55 | K8: ='Lpg (2)'!C12 -> 85 | L8: ='Lpg (2)'!D12 -> 85 | M8: ='Lpg (2)'!G12 -> 108.592 | N8: =D8*1.4 -> 2913.792 | O8: =E8*1.4 -> 77.14 | P8: ='[1]Lpg (2)'!#REF! -> #REF! | Q8: ='[1]Summery Report'!#REF! -> #REF! | R8: =N8/B8 -> 242.816 | S8: =Q8/B8 -> #REF!
A9: =Gen!B14 -> 43894 | B9: ='Summery Report'!E8 -> 77 | C9: =Gen!U14 -> 6200 | D9: =Gen!T14 -> 2421.29 | E9: =Gen!AK14 -> 149.94 | F9: =Gen!AS14 -> 2571.23 | G9: ='Utility report '!AC9 -> 153 | H9: ='Utility report '!AE9 -> 81 | I9: ='Water-Meter'!E9 -> 163 | J9: ='Lpg (2)'!B13 -> 51 | K9: ='Lpg (2)'!C13 -> 85 | L9: ='Lpg (2)'!D13 -> 85 | M9: ='Lpg (2)'!G13 -> 105.6 | N9: =D9*1.4 -> 3389.806 | O9: =E9*1.4 -> 209.916 | P9: ='[1]Lpg (2)'!#REF! -> #REF! | Q9: ='[1]Summery Report'!#REF! -> #REF! | R9: =N9/B9 -> 44.023455 | S9: =Q9/B9 -> #REF!
A10: =Gen!B15 -> 43895 | B10: ='Summery Report'!E9 -> 77 | C10: =Gen!U15 -> 0 | D10: =Gen!T15 -> 0 | E10: =Gen!AK15 -> 0 | F10: =Gen!AS15 -> 0 | G10: ='Utility report '!AC10 -> -27663 | H10: ='Utility report '!AE10 -> -197789 | I10: ='Water-Meter'!E10 -> 0 | J10: ='Lpg (2)'!B14 -> 47 | K10: ='Lpg (2)'!C14 -> 85 | L10: ='Lpg (2)'!D14 -> 85 | M10: ='Lpg (2)'!G14 -> 103.84 | N10: =D10*1.4 -> 0 | O10: =E10*1.4 -> 0 | P10: ='[1]Lpg (2)'!#REF! -> #REF! | Q10: ='[1]Summery Report'!#REF! -> #REF! | R10: =N10/B10 -> 0 | S10: =Q10/B10 -> #REF!
A11: =Gen!B16 -> 43896 | B11: ='Summery Report'!E10 -> 77 | C11: =Gen!U16 -> 0 | D11: =Gen!T16 -> 0 | E11: =Gen!AK16 -> 0 | F11: =Gen!AS16 -> 0 | G11: ='Utility report '!AC11 -> 0 | H11: ='Utility report '!AE11 -> 0 | I11: ='Water-Meter'!E11 -> 0 | J11: ='Lpg (2)'!B15 -> 0 | K11: ='Lpg (2)'!C15 -> 0 | L11: ='Lpg (2)'!D15 -> 0 | M11: ='Lpg (2)'!G15 -> -310244.18 | N11: =D11*1.4 -> 0 | O11: =E11*1.4 -> 0 | P11: ='[1]Lpg (2)'!#REF! -> #REF! | Q11: ='[1]Summery Report'!#REF! -> #REF! | R11: =N11/B11 -> 0 | S11: =Q11/B11 -> #REF!
A12: =Gen!B17 -> 43897 | B12: ='Summery Report'!E11 -> 0 | C12: =Gen!U17 -> 0 | D12: =Gen!T17 -> 0 | E12: =Gen!AK17 -> 0 | F12: =Gen!AS17 -> 0 | G12: ='Utility report '!AC12 -> 0 | H12: ='Utility report '!AE12 -> 0 | I12: ='Water-Meter'!E12 -> 0 | J12: ='Lpg (2)'!B16 -> 0 | K12: ='Lpg (2)'!C16 -> 0 | L12: ='Lpg (2)'!D16 -> 0 | M12: ='Lpg (2)'!G16 -> 0 | N12: =D12*1.4 -> 0 | O12: =E12*1.4 -> 0 | P12: ='[1]Lpg (2)'!#REF! -> #REF! | Q12: ='[1]Summery Report'!#REF! -> #REF! | R12: =N12/B12 -> #DIV/0! | S12: =Q12/B12 -> #REF!
A13: =Gen!B18 -> 43898 | B13: ='Summery Report'!E12 -> 0 | C13: =Gen!U18 -> 0 | D13: =Gen!T18 -> 0 | E13: =Gen!AK18 -> 0 | F13: =Gen!AS18 -> 0 | G13: ='Utility report '!AC13 -> 0 | H13: ='Utility report '!AE13 -> 0 | I13: ='Water-Meter'!E13 -> 0 | J13: ='Lpg (2)'!B17 -> 0 | K13: ='Lpg (2)'!C17 -> 0 | L13: ='Lpg (2)'!D17 -> 0 | M13: ='Lpg (2)'!G17 -> 0 | N13: =D13*1.4 -> 0 | O13: =E13*1.4 -> 0 | P13: ='[1]Lpg (2)'!#REF! -> #REF! | Q13: ='[1]Summery Report'!#REF! -> #REF! | R13: =N13/B13 -> #DIV/0! | S13: =Q13/B13 -> #REF!
A14: =Gen!B19 -> 43899 | B14: ='Summery Report'!E13 -> 0 | C14: =Gen!U19 -> 0 | D14: =Gen!T19 -> 0 | E14: =Gen!AK19 -> 0 | F14: =Gen!AS19 -> 0 | G14: ='Utility report '!AC14 -> 0 | H14: ='Utility report '!AE14 -> 0 | I14: ='Water-Meter'!E14 -> 0 | J14: ='Lpg (2)'!B18 -> 0 | K14: ='Lpg (2)'!C18 -> 0 | L14: ='Lpg (2)'!D18 -> 0 | M14: ='Lpg (2)'!G18 -> 0 | N14: =D14*1.4 -> 0 | O14: =E14*1.4 -> 0 | P14: ='[1]Lpg (2)'!#REF! -> #REF! | Q14: ='[1]Summery Report'!#REF! -> #REF! | R14: =N14/B14 -> #DIV/0! | S14: =Q14/B14 -> #REF!
A15: =Gen!B20 -> 43900 | B15: ='Summery Report'!E14 -> 0 | C15: =Gen!U20 -> 0 | D15: =Gen!T20 -> 0 | E15: =Gen!AK20 -> 0 | F15: =Gen!AS20 -> 0 | G15: ='Utility report '!AC15 -> 0 | H15: ='Utility report '!AE15 -> 0 | I15: ='Water-Meter'!E15 -> 0 | J15: ='Lpg (2)'!B19 -> 0 | K15: ='Lpg (2)'!C19 -> 0 | L15: ='Lpg (2)'!D19 -> 0 | M15: ='Lpg (2)'!G19 -> 0 | N15: =D15*1.4 -> 0 | O15: =E15*1.4 -> 0 | P15: ='[1]Lpg (2)'!#REF! -> #REF! | Q15: ='[1]Summery Report'!#REF! -> #REF! | R15: =N15/B15 -> #DIV/0! | S15: =Q15/B15 -> #REF!
A16: =Gen!B21 -> 43901 | B16: ='Summery Report'!E15 -> 0 | C16: =Gen!U21 -> 0 | D16: =Gen!T21 -> 0 | E16: =Gen!AK21 -> 0 | F16: =Gen!AS21 -> 0 | G16: ='Utility report '!AC16 -> 0 | H16: ='Utility report '!AE16 -> 0 | I16: ='Water-Meter'!E16 -> 0 | J16: ='Lpg (2)'!B20 -> 0 | K16: ='Lpg (2)'!C20 -> 0 | L16: ='Lpg (2)'!D20 -> 0 | M16: ='Lpg (2)'!G20 -> 0 | N16: =D16*1.4 -> 0 | O16: =E16*1.4 -> 0 | P16: ='[1]Lpg (2)'!#REF! -> #REF! | Q16: ='[1]Summery Report'!#REF! -> #REF! | R16: =N16/B16 -> #DIV/0! | S16: =Q16/B16 -> #REF!
A17: =Gen!B22 -> 43902 | B17: ='Summery Report'!E16 -> 0 | C17: =Gen!U22 -> 0 | D17: =Gen!T22 -> 0 | E17: =Gen!AK22 -> 0 | F17: =Gen!AS22 -> 0 | G17: ='Utility report '!AC17 -> 0 | H17: ='Utility report '!AE17 -> 0 | I17: ='Water-Meter'!E17 -> 0 | J17: ='Lpg (2)'!B21 -> 0 | K17: ='Lpg (2)'!C21 -> 0 | L17: ='Lpg (2)'!D21 -> 0 | M17: ='Lpg (2)'!G21 -> 0 | N17: =D17*1.4 -> 0 | O17: =E17*1.4 -> 0 | P17: ='[1]Lpg (2)'!#REF! -> #REF! | Q17: ='[1]Summery Report'!#REF! -> #REF! | R17: =N17/B17 -> #DIV/0! | S17: =Q17/B17 -> #REF!
A18: =Gen!B23 -> 43903 | B18: ='Summery Report'!E17 -> 0 | C18: =Gen!U23 -> 0 | D18: =Gen!T23 -> 0 | E18: =Gen!AK23 -> 0 | F18: =Gen!AS23 -> 0 | G18: ='Utility report '!AC18 -> 0 | H18: ='Utility report '!AE18 -> 0 | I18: ='Water-Meter'!E18 -> 0 | J18: ='Lpg (2)'!B22 -> 0 | K18: ='Lpg (2)'!C22 -> 0 | L18: ='Lpg (2)'!D22 -> 0 | M18: ='Lpg (2)'!G22 -> 0 | N18: =D18*1.4 -> 0 | O18: =E18*1.4 -> 0 | P18: ='[1]Lpg (2)'!#REF! -> #REF! | Q18: ='[1]Summery Report'!#REF! -> #REF! | R18: =N18/B18 -> #DIV/0! | S18: =Q18/B18 -> #REF!
... A32: =Gen!B37 -> 43917 | B32: ='Summery Report'!E31 -> 0 | C32: =Gen!U37 -> 0 | D32: =Gen!T37 -> 0 | E32: =Gen!AK37 -> 0 | F32: =Gen!AS37 -> 0 | G32: ='Utility report '!AC32 -> 0 | H32: ='Utility report '!AE32 -> 0 | I32: ='Water-Meter'!E32 -> 0 | J32: ='Lpg (2)'!B36 -> 0 | K32: ='Lpg (2)'!C36 -> 0 | L32: ='Lpg (2)'!D36 -> 0 | M32: ='Lpg (2)'!G36 -> 0 | N32: =D32*1.4 -> 0 | O32: =E32*1.4 -> 0 | P32: ='[1]Lpg (2)'!#REF! -> #REF! | Q32: ='[1]Summery Report'!#REF! -> #REF! | R32: =N32/B32 -> #DIV/0! | S32: =Q32/B32 -> #REF!
A33: =Gen!B38 -> 43918 | B33: ='Summery Report'!E32 -> 0 | C33: =Gen!U38 -> 0 | D33: =Gen!T38 -> 0 | E33: =Gen!AK38 -> 0 | F33: =Gen!AS38 -> 0 | G33: ='Utility report '!AC33 -> 0 | H33: ='Utility report '!AE33 -> 0 | I33: ='Water-Meter'!E33 -> 0 | J33: ='Lpg (2)'!B37 -> 0 | K33: ='Lpg (2)'!C37 -> 0 | L33: ='Lpg (2)'!D37 -> 0 | M33: ='Lpg (2)'!G37 -> 0 | N33: =D33*1.4 -> 0 | O33: =E33*1.4 -> 0 | P33: ='[1]Lpg (2)'!#REF! -> #REF! | Q33: ='[1]Summery Report'!#REF! -> #REF! | R33: =N33/B33 -> #DIV/0! | S33: =Q33/B33 -> #REF! | T33: =3124/13 -> 240.30769
A34: =Gen!B39 -> 43919 | B34: ='Summery Report'!E33 -> 0 | C34: =Gen!U39 -> 0 | D34: =Gen!T39 -> 0 | E34: =Gen!AK39 -> 0 | F34: =Gen!AS39 -> 0 | G34: ='Utility report '!AC34 -> 0 | H34: ='Utility report '!AE34 -> 0 | I34: ='Water-Meter'!E34 -> 0 | J34: ='Lpg (2)'!B38 -> 0 | K34: ='Lpg (2)'!C38 -> 0 | L34: ='Lpg (2)'!D38 -> 0 | M34: ='Lpg (2)'!G38 -> 0 | N34: =D34*1.4 -> 0 | O34: =E34*1.4 -> 0 | P34: ='[1]Lpg (2)'!#REF! -> #REF! | Q34: ='[1]Summery Report'!#REF! -> #REF! | R34: =N34/B34 -> #DIV/0! | S34: =Q34/B34 -> #REF!
A35: =Gen!B40 -> 43920 | B35: ='Summery Report'!E34 -> 0 | C35: =Gen!U40 -> 0 | D35: =Gen!T40 -> 0 | E35: =Gen!AK40 -> 0 | F35: =Gen!AS40 -> 0 | G35: ='Utility report '!AC35 -> 0 | H35: ='Utility report '!AE35 -> 0 | I35: ='Water-Meter'!E35 -> 0 | J35: ='Lpg (2)'!B39 -> 0 | K35: ='Lpg (2)'!C39 -> 0 | L35: ='Lpg (2)'!D39 -> 0 | M35: ='Lpg (2)'!G39 -> 0 | N35: =D35*1.4 -> 0 | O35: =E35*1.4 -> 0 | P35: ='[1]Lpg (2)'!#REF! -> #REF! | Q35: ='[1]Summery Report'!#REF! -> #REF! | R35: =N35/B35 -> #DIV/0! | S35: =Q35/B35 -> #REF!
A36: =Gen!B41 -> 43921 | B36: ='Summery Report'!E35 -> 0 | C36: =Gen!U41 -> 0 | D36: =Gen!T41 -> 0 | E36: =Gen!AK41 -> 0 | F36: =Gen!AS41 -> 0 | G36: ='Utility report '!AC36 -> 0 | H36: ='Utility report '!AE36 -> 0 | I36: ='Water-Meter'!E36 -> 0 | J36: ='Lpg (2)'!B40 -> 0 | K36: ='Lpg (2)'!C40 -> 0 | L36: ='Lpg (2)'!D40 -> 0 | M36: ='Lpg (2)'!G40 -> 0 | N36: =D36*1.4 -> 0 | O36: =E36*1.4 -> 0 | P36: ='[1]Lpg (2)'!#REF! -> #REF! | Q36: ='[1]Summery Report'!#REF! -> #REF! | R36: =N36/B36 -> #DIV/0! | S36: =Q36/B36 -> #REF!
A37: =Gen!B42 -> 43922 | B37: ='Summery Report'!E36 -> 0 | C37: =Gen!U42 -> 0 | D37: =Gen!T42 -> 0 | E37: =Gen!AK42 -> 0 | F37: =Gen!AS42 -> 0 | G37: ='Utility report '!AC37 -> 0 | H37: ='Utility report '!AE37 -> 0 | I37: ='Water-Meter'!E37 -> 0 | J37: ='Lpg (2)'!B41 -> 0 | K37: ='Lpg (2)'!C41 -> 0 | L37: ='Lpg (2)'!D41 -> 0 | M37: ='Lpg (2)'!G41 -> 0 | Q37: ='[1]Summery Report'!#REF! -> #REF! | R37: =N37/B37 -> #DIV/0! | S37: =Q37/B37 -> #REF!
A39: Total | B39: =SUM(B7:B37) -> 260 | C39: =SUM(C7:C35) -> 16379 | D39: =SUM(D7:D35) -> 6628.05 | E39: =SUM(E7:E35) -> 486.38 | F39: =SUM(F7:F35) -> 7114.43 | G39: =SUM(G7:G35) -> -27175 | H39: =SUM(H7:H35) -> -197524 | I39: =SUM(I7:I35) -> 491 | J39: =SUM(J7:J35) -> 212 | ... S39: =SUM(S7:S35) -> #REF!

Sheet Utility report 
A1: DAILY UTILITY REPORT March 2020
A2: Date | B2: Total occupancy | H2: Diesel balance LTS | I2: Diesel Deliveries | J2: Gen.Diesel consumption LTS | L2: Total Diesel consumption LTS | M2: Water Meter reading | N2: Water consumption m³ | O2: R.O WATER PRODUCTION LTRS + TIME | AA2: Total RO production | AB2: RO Meter reading | AD2: 0 | AF2: GAS TANK A | AG2: GAS TANK B | AH2: GAS TANK C | AI2: Total Gas Tanks | AJ2: Kg /day | AK2: TOTAL GAS cons.
A3: Rate Tsh /$ | B3: 1640 | C3: Diesel cost / lits | D3: 2175 | F3: =SUM(D3/B3) -> 1.3262195 | H3: =Gen!D11 -> 32302.73 | K3: Transport consumption | M3: Balance | O3: PLANT NO 1 | S3: PLANT NO 2 | W3: PLANT NO 3 | AA3: /day | AB3: Balance | AC3: Production | AD3: 0 | AE3: Production | AF3: Capacity | AG3: Capacity | AH3: Capacity | AI3: Kg | AJ3: /day | AK3: /day
B4: Rooms OCC | C4: % | D4: Guest Rooms Occ | F4: Electricity Production Cost /Room Occ by guest | G4: All Cost /Room Occ by guest | O4: Flow M3 | P4: Reading Hours Meter | Q4: Hrs | R4: total production M3 | S4: Flow M3 | T4: Reading Hours Meter | U4: Hrs | V4: total production M3 | W4: Flow M3 | X4: READING HOURS METER | Y4: Hrs | Z4: total production M3 | AA4: M3 | AC4: M3 | AE4: M3 | AF4: 2000 | AG4: 1000 | AH4: 1000 | AI4: =SUM([2]Sheet1!$AA$36) -> 950 | AJ4: Kg | AK4: M3
P5: 19015 | T5: 15720 | X5: 23794 | AB5: 26993 | AD5: 197424 | AF5: 0.85 | AG5: 0.85 | AH5: 0.85
A6: =Gen!B11 -> 43891 | B6: ='Summery Report'!E5 -> 46 | C6: =Gen!C11 -> 0.5714 | D6: ='Summery Report'!E5 -> 46 | E6: =SUM(F3) -> 1.3262195 | F6: =SUM(J6*E6)/D6 -> 64.774003 | G6: =SUM(L6*E6)/D6 -> 74.050908 | H6: =Gen!D11 -> 32302.73 | I6: =Gen!F11 -> 0 | J6: =Gen!T11 -> 2246.69 | K6: =Gen!AK11 -> 321.77 | L6: =SUM(J6:K6) -> 2568.46 | M6: ='Water-Meter'!K46 -> 398.83513 | N6: ='Water-Meter'!E6 -> 146 | P6: 19015 | Q6: =SUM(P6-P5) -> 0 | R6: =SUM(Q6*O6) -> 0 | S6: 6 | T6: 15742 | U6: =T6-T5 -> 22 | V6: - | X6: 23818 | Y6: =X6-X5 -> 24 | Z6: =Y6-Y5 -> 24 | AA6: =Z6-Z5 -> 24 | AB6: 27175 | AC6: =AB6-AB5 -> 182 | AD6: 197524 | AE6: =AD6-AD5 -> 100 | AF6: ='Lpg (2)'!B10*2000/85 -> 1458.8235 | AG6: ='Lpg (2)'!C10*1000/85 -> 0 | AH6: ='Lpg (2)'!D10*1000/85 -> 0 | AI6: =SUM(AF6*2000)+(AG6*1000)+(AH6*1000) -> 2917647.1 | AJ6: =SUM(AI5-AI6) -> -2917647.1
A7: =Gen!B12 -> 43892 | B7: ='Summery Report'!E6 -> 17 | C7: =Gen!C12 -> 0.2208 | D7: ='Summery Report'!E6 -> 17 | E7: =SUM(E6) -> 1.3262195 | F7: =SUM(J7*E7)/D7 -> 165.81489 | G7: =SUM(L7*E7)/D7 -> 187.76304 | H7: =Gen!D12 -> 47734.27 | I7: =Gen!F12 -> 18000 | J7: =Gen!T12 -> 2125.48 | K7: =Gen!AK12 -> 281.34 | L7: =SUM(J7:K7) -> 2406.82 | M7: ='Water-Meter'!K47 -> 319.5363 | N7: ='Water-Meter'!E7 -> 164 | P7: 19015 | Q7: =SUM(P7-P6) -> 0 | R7: =SUM(Q7*O7) -> 0 | T7: 15766 | U7: =T7-T6 -> 24 | V7: =SUM(U7*S7) -> 0 | X7: 23842 | Y7: =X7-X6 -> 24 | Z7: =SUM(Y7*W7) -> 0 | AA7: =SUM(Z7*X9) -> 0 | AB7: 27359 | AC7: =AB7-AB6 -> 184 | AD7: 197629 | AE7: =AD7-AD6 -> 105 | AF7: ='Lpg (2)'!B11*2000/85 -> 1388.2353 | AG7: ='Lpg (2)'!C11*1000/85 -> 0 | AH7: ='Lpg (2)'!D11*1000/85 -> 0 | AI7: =SUM(AF6*2000)+(AG7*1000)+(AH7*1000) -> 2917647.1 | AJ7: =SUM(AI6-AI7) -> 0
A8: =Gen!B13 -> 43893 | B8: ='Summery Report'!E7 -> 12 | C8: =Gen!C13 -> 0.1429 | D8: ='Summery Report'!E7 -> 12 | E8: =SUM(E7) -> 1.3262195 | F8: =SUM(J8*E8)/D8 -> 230.01951 | G8: =SUM(L8*E8)/D8 -> 236.10907 | H8: =Gen!D13 -> 45327.45 | I8: =Gen!F13 -> 0 | J8: =Gen!T13 -> 2081.28 | K8: =Gen!AK13 -> 55.1 | L8: =SUM(J8:K8) -> 2136.38 | M8: ='Water-Meter'!K48 -> 285.71003 | N8: ='Water-Meter'!E8 -> 164 | P8: 19015 | Q8: =SUM(P8-P7) -> 0 | R8: =SUM(Q8*O8) -> 0 | T8: 15790 | U8: =T8-T7 -> 24 | V8: =SUM(U8*S8) -> 0 | X8: 23843 | Y8: =X8-X7 -> 1 | Z8: =SUM(Y8*W8) -> 0 | AA8: =SUM(Z8*X10) -> 0 | AB8: 27510 | AC8: =AB8-AB7 -> 151 | AD8: 197708 | AE8: =AD8-AD7 -> 79 | AF8: ='Lpg (2)'!B12*2000/85 -> 1294.1176 | AG8: ='Lpg (2)'!C12*1000/85 -> 1000 | AH8: ='Lpg (2)'!D12*1000/85 -> 1000 | AI8: =SUM(AF7*2000)+(AG8*1000)+(AH8*1000) -> 4776470.6 | AJ8: =SUM(AI7-AI8) -> -1858823.5
A9: =Gen!B14 -> 43894 | B9: ='Summery Report'!E8 -> 77 | C9: =Gen!C14 -> 1 | D9: ='Summery Report'!E8 -> 77 | E9: =SUM(E8) -> 1.3262195 | F9: =SUM(J9*E9)/D9 -> 41.703403 | G9: =SUM(L9*E9)/D9 -> 44.285914 | H9: =Gen!D14 -> 43191.07 | I9: =Gen!F14 -> 0 | J9: =Gen!T14 -> 2421.29 | K9: =Gen!AK14 -> 149.94 | L9: =SUM(J9:K9) -> 2571.23 | M9: ='Water-Meter'!K49 -> 303.55711 | N9: ='Water-Meter'!E9 -> 163 | P9: 19015 | Q9: =SUM(P9-P8) -> 0 | R9: =SUM(Q9*O9) -> 0 | S9: 4.2 | T9: 15815 | U9: =T9-T8 -> 25 | V9: =SUM(U9*S9) -> 105 | X9: 23843 | Y9: =X9-X8 -> 0 | Z9: =SUM(Y9*W9) -> 0 | AA9: =SUM(Z9*X11) -> 0 | AB9: 27663 | AC9: =AB9-AB8 -> 153 | AD9: 197789 | AE9: =AD9-AD8 -> 81 | AF9: ='Lpg (2)'!B13*2000/85 -> 1200 | AG9: ='Lpg (2)'!C13*1000/85 -> 1000 | AH9: ='Lpg (2)'!D13*1000/85 -> 1000 | AI9: =SUM(AF8*2000)+(AG9*1000)+(AH9*1000) -> 4588235.3 | AJ9: =SUM(AI8-AI9) -> 188235.29
A10: =Gen!B15 -> 43895 | B10: ='Summery Report'!E9 -> 77 | C10: =Gen!C15 -> 1 | D10: ='Summery Report'!E9 -> 77 | E10: =SUM(E9) -> 1.3262195 | F10: =SUM(J10*E10)/D10 -> 0 | G10: =SUM(L10*E10)/D10 -> 0 | H10: =Gen!D15 -> 40619.84 | I10: =Gen!F15 -> 0 | J10: =Gen!T15 -> 0 | K10: =Gen!AK15 -> 0 | L10: =SUM(J10:K10) -> 0 | M10: ='Water-Meter'!K50 -> 0 | N10: ='Water-Meter'!E10 -> 0 | Q10: =SUM(P10-P9) -> -19015 | R10: =SUM(Q10*O10) -> 0 | U10: =T10-T9 -> -15815 | V10: =SUM(U10*S10) -> 0 | Y10: =X10-X9 -> -23843 | Z10: =SUM(Y10*W10) -> 0 | AA10: =SUM(Z10*X12) -> 0 | AC10: =AB10-AB9 -> -27663 | AE10: =AD10-AD9 -> -197789 | AF10: ='Lpg (2)'!B14*2000/85 -> 1105.8824 | AG10: ='Lpg (2)'!C14*1000/85 -> 1000 | AH10: ='Lpg (2)'!D14*1000/85 -> 1000 | AI10: =SUM(AF9*2000)+(AG10*1000)+(AH10*1000) -> 4400000 | AJ10: =SUM(AI9-AI10) -> 188235.29
A11: =Gen!B16 -> 43896 | B11: ='Summery Report'!E10 -> 77 | C11: =Gen!C16 -> 0 | D11: ='Summery Report'!E10 -> 77 | E11: =SUM(E10) -> 1.3262195 | F11: =SUM(J11*E11)/D11 -> 0 | G11: =SUM(L11*E11)/D11 -> 0 | H11: =Gen!D16 -> 40619.84 | I11: =Gen!F16 -> 0 | J11: =Gen!T16 -> 0 | K11: =Gen!AK16 -> 0 | L11: =SUM(J11:K11) -> 0 | M11: ='Water-Meter'!K51 -> 0 | N11: ='Water-Meter'!E11 -> 0 | Q11: =SUM(P11-P10) -> 0 | R11: =SUM(Q11*O11) -> 0 | U11: =T11-T10 -> 0 | V11: =SUM(U11*S11) -> 0 | Y11: =X11-X10 -> 0 | Z11: =SUM(Y11*W11) -> 0 | AA11: =SUM(Z11*X13) -> 0 | AC11: =AB11-AB10 -> 0 | AE11: =AD11-AD10 -> 0 | AF11: ='Lpg (2)'!B15*2000/85 -> 0 | AG11: ='Lpg (2)'!C15*1000/85 -> 0 | AH11: ='Lpg (2)'!D15*1000/85 -> 0 | AI11: =SUM(AF10*2000)+(AG11*1000)+(AH11*1000) -> 2211764.7 | AJ11: =SUM(AI10-AI11) -> 2188235.3
A12: =Gen!B17 -> 43897 | B12: ='Summery Report'!E11 -> 0 | C12: =Gen!C17 -> 0 | D12: ='Summery Report'!E11 -> 0 | E12: =SUM(E11) -> 1.3262195 | F12: =SUM(J12*E12)/D12 -> #DIV/0! | G12: =SUM(L12*E12)/D12 -> #DIV/0! | H12: =Gen!D17 -> 40619.84 | I12: =Gen!F17 -> 0 | J12: =Gen!T17 -> 0 | K12: =Gen!AK17 -> 0 | L12: =SUM(J12:K12) -> 0 | M12: ='Water-Meter'!K52 -> 0 | N12: ='Water-Meter'!E12 -> 0 | Q12: =SUM(P12-P11) -> 0 | R12: =SUM(Q12*O12) -> 0 | U12: =T12-T11 -> 0 | V12: =SUM(U12*S12) -> 0 | Y12: =X12-X11 -> 0 | Z12: =SUM(Y12*W12) -> 0 | AA12: =SUM(Z12*X14) -> 0 | AC12: =AB12-AB11 -> 0 | AE12: =AD12-AD11 -> 0 | AF12: ='Lpg (2)'!B16*2000/85 -> 0 | AG12: ='Lpg (2)'!C16*1000/85 -> 0 | AH12: ='Lpg (2)'!D16*1000/85 -> 0 | AI12: =SUM(AF11*2000)+(AG12*1000)+(AH12*1000) -> 0 | AJ12: =SUM(AI11-AI12) -> 2211764.7
A13: =Gen!B18 -> 43898 | B13: ='Summery Report'!E12 -> 0 | C13: =Gen!C18 -> 0 | D13: ='Summery Report'!E12 -> 0 | E13: =SUM(E12) -> 1.3262195 | F13: =SUM(J13*E13)/D13 -> #DIV/0! | G13: =SUM(L13*E13)/D13 -> #DIV/0! | H13: =Gen!D18 -> 40619.84 | I13: =Gen!F18 -> 15000 | J13: =Gen!T18 -> 0 | K13: =Gen!AK18 -> 0 | L13: =SUM(J13:K13) -> 0 | M13: ='Water-Meter'!K53 -> 0 | N13: ='Water-Meter'!E13 -> 0 | Q13: =SUM(P13-P12) -> 0 | R13: =SUM(Q13*O13) -> 0 | U13: =T13-T12 -> 0 | V13: =SUM(U13*S13) -> 0 | Y13: =X13-X12 -> 0 | Z13: =SUM(Y13*W13) -> 0 | AA13: =SUM(Z13*X15) -> 0 | AC13: =AB13-AB12 -> 0 | AE13: =AD13-AD12 -> 0 | AF13: ='Lpg (2)'!B17*2000/85 -> 0 | AG13: ='Lpg (2)'!C17*1000/85 -> 0 | AH13: ='Lpg (2)'!D17*1000/85 -> 0 | AI13: =SUM(AF12*2000)+(AG13*1000)+(AH13*1000) -> 0 | AJ13: =SUM(AI12-AI13) -> 0
A14: =Gen!B19 -> 43899 | B14: ='Summery Report'!E13 -> 0 | C14: =Gen!C19 -> 0 | D14: ='Summery Report'!E13 -> 0 | E14: =SUM(E13) -> 1.3262195 | F14: =SUM(J14*E14)/D14 -> #DIV/0! | G14: =SUM(L14*E14)/D14 -> #DIV/0! | H14: =Gen!D19 -> 40619.84 | I14: =Gen!F19 -> 0 | J14: =Gen!T19 -> 0 | K14: =Gen!AK19 -> 0 | L14: =SUM(J14:K14) -> 0 | M14: ='Water-Meter'!K54 -> 0 | N14: ='Water-Meter'!E14 -> 0 | Q14: =SUM(P14-P13) -> 0 | R14: =SUM(Q14*O14) -> 0 | U14: =T14-T13 -> 0 | V14: =SUM(U14*S14) -> 0 | Y14: =X14-X13 -> 0 | Z14: =SUM(Y14*W14) -> 0 | AA14: =SUM(Z14*X16) -> 0 | AC14: =AB14-AB13 -> 0 | AE14: =AD14-AD13 -> 0 | AF14: ='Lpg (2)'!B18*2000/85 -> 0 | AG14: ='Lpg (2)'!C18*1000/85 -> 0 | AH14: ='Lpg (2)'!D18*1000/85 -> 0 | AI14: =SUM(AF13*2000)+(AG14*1000)+(AH14*1000) -> 0 | AJ14: =SUM(AI13-AI14) -> 0
A15: =Gen!B20 -> 43900 | B15: ='Summery Report'!E14 -> 0 | C15: =Gen!C20 -> 0 | D15: ='Summery Report'!E14 -> 0 | E15: =SUM(E14) -> 1.3262195 | F15: =SUM(J15*E15)/D15 -> #DIV/0! | G15: =SUM(L15*E15)/D15 -> #DIV/0! | H15: =Gen!D20 -> 40619.84 | I15: =Gen!F20 -> 0 | J15: =Gen!T20 -> 0 | K15: =Gen!AK20 -> 0 | L15: =SUM(J15:K15) -> 0 | M15: ='Water-Meter'!K55 -> 0 | N15: ='Water-Meter'!E15 -> 0 | Q15: =SUM(P15-P14) -> 0 | R15: =SUM(Q15*O15) -> 0 | U15: =T15-T14 -> 0 | V15: =SUM(U15*S15) -> 0 | Y15: =X15-X14 -> 0 | Z15: =SUM(Y15*W15) -> 0 | AA15: =SUM(Z15*X17) -> 0 | AC15: =AB15-AB14 -> 0 | AE15: =AD15-AD14 -> 0 | AF15: ='Lpg (2)'!B19*2000/85 -> 0 | AG15: ='Lpg (2)'!C19*1000/85 -> 0 | AH15: ='Lpg (2)'!D19*1000/85 -> 0 | AI15: =SUM(AF15*2000)+(AG15*1000)+(AH15*1000) -> 0 | AJ15: =SUM(AI14-AI15) -> 0
A16: =Gen!B21 -> 43901 | B16: ='Summery Report'!E15 -> 0 | C16: =Gen!C21 -> 0 | D16: ='Summery Report'!E15 -> 0 | E16: =SUM(E15) -> 1.3262195 | F16: =SUM(J16*E16)/D16 -> #DIV/0! | G16: =SUM(L16*E16)/D16 -> #DIV/0! | H16: =Gen!D21 -> 40619.84 | I16: =Gen!F21 -> 0 | J16: =Gen!T21 -> 0 | K16: =Gen!AK21 -> 0 | L16: =SUM(J16:K16) -> 0 | M16: ='Water-Meter'!K56 -> 0 | N16: ='Water-Meter'!E16 -> 0 | Q16: =SUM(P16-P15) -> 0 | R16: =SUM(Q16*O16) -> 0 | U16: =T16-T15 -> 0 | V16: =SUM(U16*S16) -> 0 | Y16: =X16-X15 -> 0 | Z16: =SUM(Y16*W16) -> 0 | AA16: =SUM(Z16*X18) -> 0 | AC16: =AB16-AB15 -> 0 | AE16: =AD16-AD15 -> 0 | AF16: ='Lpg (2)'!B20*2000/85 -> 0 | AG16: ='Lpg (2)'!C20*1000/85 -> 0 | AH16: ='Lpg (2)'!D20*1000/85 -> 0 | AI16: =SUM(AF16*2000)+(AG16*1000)+(AH16*1000) -> 0 | AJ16: =SUM(AI15-AI16) -> 0
A17: =Gen!B22 -> 43902 | B17: ='Summery Report'!E16 -> 0 | C17: =Gen!C22 -> 0 | D17: ='Summery Report'!E16 -> 0 | E17: =SUM(E16) -> 1.3262195 | F17: =SUM(J17*E17)/D17 -> #DIV/0! | G17: =SUM(L17*E17)/D17 -> #DIV/0! | H17: =Gen!D22 -> 40619.84 | I17: =Gen!F22 -> 0 | J17: =Gen!T22 -> 0 | K17: =Gen!AK22 -> 0 | L17: =SUM(J17:K17) -> 0 | M17: ='Water-Meter'!K57 -> 0 | N17: ='Water-Meter'!E17 -> 0 | Q17: =SUM(P18-P16) -> 0 | R17: =SUM(Q17*O17) -> 0 | U17: =T17-T16 -> 0 | V17: =SUM(U17*S17) -> 0 | Y17: =X17-X16 -> 0 | Z17: =SUM(Y17*W17) -> 0 | AA17: =SUM(Z17*X19) -> 0 | AC17: =AB17-AB16 -> 0 | AE17: =AD17-AD16 -> 0 | AF17: ='Lpg (2)'!B21*2000/85 -> 0 | AG17: ='Lpg (2)'!C21*1000/85 -> 0 | AH17: ='Lpg (2)'!D21*1000/85 -> 0 | AI17: =SUM(AF17*2000)+(AG17*1000)+(AH17*1000) -> 0 | AJ17: =SUM(AI16-AI17) -> 0
A18: =Gen!B23 -> 43903 | B18: ='Summery Report'!E17 -> 0 | C18: =Gen!C23 -> 0 | D18: ='Summery Report'!E17 -> 0 | E18: =SUM(E17) -> 1.3262195 | F18: =SUM(J18*E18)/D18 -> #DIV/0! | G18: =SUM(L18*E18)/D18 -> #DIV/0! | H18: =Gen!D23 -> 40619.84 | I18: =Gen!F23 -> 0 | J18: =Gen!T23 -> 0 | K18: =Gen!AK23 -> 0 | L18: =SUM(J18:K18) -> 0 | M18: ='Water-Meter'!K58 -> 0 | N18: ='Water-Meter'!E18 -> 0 | R18: =SUM(Q18*O18) -> 0 | U18: =T18-T17 -> 0 | V18: =SUM(U18*S18) -> 0 | Y18: =X18-X17 -> 0 | Z18: =SUM(Y18*W18) -> 0 | AA18: =SUM(Z18*X20) -> 0 | AC18: =AB18-AB17 -> 0 | AE18: =AD18-AD17 -> 0 | AF18: ='Lpg (2)'!B22*2000/85 -> 0 | AG18: ='Lpg (2)'!C22*1000/85 -> 0 | AH18: ='Lpg (2)'!D22*1000/85 -> 0 | AI18: =SUM(AF18*2000)+(AG18*1000)+(AH18*1000) -> 0 | AJ18: =SUM(AI17-AI18) -> 0
A19: =Gen!B24 -> 43904 | B19: ='Summery Report'!E18 -> 0 | C19: =Gen!C24 -> 0 | D19: ='Summery Report'!E18 -> 0 | E19: =SUM(E18) -> 1.3262195 | F19: =SUM(J19*E19)/D19 -> #DIV/0! | G19: =SUM(L19*E19)/D19 -> #DIV/0! | H19: =Gen!D24 -> 40619.84 | I19: =Gen!F24 -> 18000 | J19: =Gen!T24 -> 0 | K19: =Gen!AK24 -> 0 | L19: =SUM(J19:K19) -> 0 | M19: ='Water-Meter'!K59 -> 0 | N19: ='Water-Meter'!E19 -> 0 | R19: =SUM(Q19*O19) -> 0 | U19: =T19-T18 -> 0 | V19: =SUM(U19*S19) -> 0 | Y19: =X19-X18 -> 0 | Z19: =SUM(Y19*W19) -> 0 | AA19: =SUM(Z19*X21) -> 0 | AC19: =AB19-AB18 -> 0 | AE19: =AD19-AD18 -> 0 | AF19: ='Lpg (2)'!B23*2000/85 -> 0 | AG19: ='Lpg (2)'!C23*1000/85 -> 0 | AH19: ='Lpg (2)'!D23*1000/85 -> 0 | AI19: =SUM(AF19*2000)+(AG19*1000)+(AH19*1000) -> 0 | AJ19: =SUM(AI18-AI19) -> 0
A20: =Gen!B25 -> 43905 | B20: ='Summery Report'!E19 -> 0 | C20: =Gen!C25 -> 0 | D20: ='Summery Report'!E19 -> 0 | E20: =SUM(E19) -> 1.3262195 | F20: =SUM(J20*E20)/D20 -> #DIV/0! | G20: =SUM(L20*E20)/D20 -> #DIV/0! | H20: =Gen!D25 -> 40619.84 | I20: =Gen!F25 -> 0 | J20: =Gen!T25 -> 0 | K20: =Gen!AK25 -> 0 | L20: =SUM(J20:K20) -> 0 | M20: ='Water-Meter'!K60 -> 0 | N20: ='Water-Meter'!E20 -> 0 | Q20: =SUM(P20-P19) -> 0 | R20: =SUM(Q20*O20) -> 0 | U20: =T20-T19 -> 0 | V20: =SUM(U20*S20) -> 0 | Y20: =X20-X19 -> 0 | Z20: =SUM(Y20*W20) -> 0 | AA20: =SUM(Z20*X22) -> 0 | AC20: =AB20-AB19 -> 0 | AE20: =AD20-AD19 -> 0 | AF20: ='Lpg (2)'!B24*2000/85 -> 0 | AG20: ='Lpg (2)'!C24*1000/85 -> 0 | AH20: ='Lpg (2)'!D24*1000/85 -> 0 | AI20: =SUM(AF20*2000)+(AG20*1000)+(AH20*1000) -> 0 | AJ20: =SUM(AI19-AI20) -> 0
A21: =Gen!B26 -> 43906 | B21: ='Summery Report'!E20 -> 0 | C21: =Gen!C26 -> 0 | D21: ='Summery Report'!E20 -> 0 | E21: =SUM(E20) -> 1.3262195 | F21: =SUM(J21*E21)/D21 -> #DIV/0! | G21: =SUM(L21*E21)/D21 -> #DIV/0! | H21: =Gen!D26 -> 40619.84 | I21: =Gen!F26 -> 0 | J21: =Gen!T26 -> 0 | K21: =Gen!AK26 -> 0 | L21: =SUM(J21:K21) -> 0 | M21: ='Water-Meter'!K61 -> 0 | N21: ='Water-Meter'!E21 -> 0 | Q21: =SUM(P21-P20) -> 0 | R21: =SUM(Q21*O21) -> 0 | U21: =T22-T20 -> 0 | V21: =SUM(U21*S21) -> 0 | Y21: =X21-X20 -> 0 | Z21: =SUM(Y21*W21) -> 0 | AA21: =SUM(Z21*X23) -> 0 | AC21: =AB21-AB20 -> 0 | AE21: =AD21-AD20 -> 0 | AF21: ='Lpg (2)'!B25*2000/85 -> 0 | AG21: ='Lpg (2)'!C25*1000/85 -> 0 | AH21: ='Lpg (2)'!D25*1000/85 -> 0 | AI21: =SUM(AF21*2000)+(AG21*1000)+(AH21*1000) -> 0 | AJ21: =SUM(AI20-AI21) -> 0
A22: =Gen!B27 -> 43907 | B22: ='Summery Report'!E21 -> 0 | C22: =Gen!C27 -> 0 | D22: ='Summery Report'!E21 -> 0 | E22: =SUM(E21) -> 1.3262195 | F22: =SUM(J22*E22)/D22 -> #DIV/0! | G22: =SUM(L22*E22)/D22 -> #DIV/0! | H22: =Gen!D27 -> 40619.84 | I22: =Gen!F27 -> 0 | J22: =Gen!T27 -> 0 | K22: =Gen!AK27 -> 0 | L22: =SUM(J22:K22) -> 0 | M22: ='Water-Meter'!K62 -> 0 | N22: ='Water-Meter'!E22 -> 0 | Q22: =SUM(P22-P21) -> 0 | R22: =SUM(Q22*O22) -> 0 | U22: =#REF!-T22 -> #REF! | V22: =SUM(U22*S22) -> #REF! | Y22: =X22-X21 -> 0 | Z22: =SUM(Y22*W22) -> 0 | AA22: =SUM(Z22*X24) -> 0 | AC22: =AB22-AB21 -> 0 | AE22: =AD22-AD21 -> 0 | AF22: ='Lpg (2)'!B26*2000/85 -> 0 | AG22: ='Lpg (2)'!C26*1000/85 -> 0 | AH22: ='Lpg (2)'!D26*1000/85 -> 0 | AI22: =SUM(AF22*2000)+(AG22*1000)+(AH22*1000) -> 0 | AJ22: =SUM(AI21-AI22) -> 0
A23: =Gen!B28 -> 43908 | B23: ='Summery Report'!E22 -> 0 | C23: =Gen!C28 -> 0 | D23: ='Summery Report'!E22 -> 0 | E23: =SUM(E22) -> 1.3262195 | F23: =SUM(J23*E23)/D23 -> #DIV/0! | G23: =SUM(L23*E23)/D23 -> #DIV/0! | H23: =Gen!D28 -> 40619.84 | I23: =Gen!F28 -> 0 | J23: =Gen!T28 -> 0 | K23: =Gen!AK28 -> 0 | L23: =SUM(J23:K23) -> 0 | M23: ='Water-Meter'!K63 -> 0 | N23: ='Water-Meter'!E23 -> 0 | Q23: =SUM(P23-P22) -> 0 | R23: =SUM(Q23*O23) -> 0 | U23: =T23-#REF! -> #REF! | V23: =SUM(U23*S23) -> #REF! | Y23: =X23-X22 -> 0 | Z23: =SUM(Y23*W23) -> 0 | AA23: =SUM(Z23*X25) -> 0 | AC23: =AB23-AB22 -> 0 | AE23: =AD23-AD22 -> 0 | AF23: ='Lpg (2)'!B27*2000/85 -> 0 | AG23: ='Lpg (2)'!C27*1000/85 -> 0 | AH23: ='Lpg (2)'!D27*1000/85 -> 0 | AI23: =SUM(AF23*2000)+(AG23*1000)+(AH23*1000) -> 0 | AJ23: =SUM(AI22-AI23) -> 0
A24: =Gen!B29 -> 43909 | B24: ='Summery Report'!E23 -> 0 | C24: =Gen!C29 -> 0 | D24: ='Summery Report'!E23 -> 0 | E24: =SUM(E23) -> 1.3262195 | F24: =SUM(J24*E24)/D24 -> #DIV/0! | G24: =SUM(L24*E24)/D24 -> #DIV/0! | H24: =Gen!D29 -> 40619.84 | I24: =Gen!F29 -> 0 | J24: =Gen!T29 -> 0 | K24: =Gen!AK29 -> 0 | L24: =SUM(J24:K24) -> 0 | M24: ='Water-Meter'!K64 -> 0 | N24: ='Water-Meter'!E24 -> 0 | Q24: =SUM(P24-P23) -> 0 | R24: =SUM(Q24*O24) -> 0 | U24: =T24-T23 -> 0 | V24: =SUM(U24*S24) -> 0 | Y24: =X24-X23 -> 0 | Z24: =SUM(Y24*W24) -> 0 | AA24: =SUM(Z24*X26) -> 0 | AC24: =AB24-AB23 -> 0 | AE24: =AD24-AD23 -> 0 | AF24: ='Lpg (2)'!B28*2000/85 -> 0 | AG24: ='Lpg (2)'!C28*1000/85 -> 0 | AH24: ='Lpg (2)'!D28*1000/85 -> 0 | AI24: =SUM(AF24*2000)+(AG24*1000)+(AH24*1000) -> 0 | AJ24: =SUM(AI23-AI24) -> 0
A25: =Gen!B30 -> 43910 | B25: ='Summery Report'!E24 -> 0 | C25: =Gen!C30 -> 0 | D25: ='Summery Report'!E24 -> 0 | E25: =SUM(E24) -> 1.3262195 | F25: =SUM(J25*E25)/D25 -> #DIV/0! | G25: =SUM(L25*E25)/D25 -> #DIV/0! | H25: =Gen!D30 -> 40619.84 | I25: =Gen!F30 -> 0 | J25: =Gen!T30 -> 0 | K25: =Gen!AK30 -> 0 | L25: =SUM(J25:K25) -> 0 | M25: ='Water-Meter'!K65 -> 0 | N25: ='Water-Meter'!E25 -> 0 | Q25: =SUM(P25-P24) -> 0 | R25: =SUM(Q25*O25) -> 0 | U25: =T25-T24 -> 0 | V25: =SUM(U25*S25) -> 0 | Y25: =X25-X24 -> 0 | Z25: =SUM(Y25*W25) -> 0 | AA25: =SUM(Z25*X27) -> 0 | AC25: =AB25-AB24 -> 0 | AE25: =AD25-AD24 -> 0 | AF25: ='Lpg (2)'!B29*2000/85 -> 0 | AG25: ='Lpg (2)'!C29*1000/85 -> 0 | AH25: ='Lpg (2)'!D29*1000/85 -> 0 | AI25: =SUM(AF25*2000)+(AG25*1000)+(AH25*1000) -> 0 | AJ25: =SUM(AI24-AI25) -> 0
A26: =Gen!B31 -> 43911 | B26: ='Summery Report'!E25 -> 0 | C26: =Gen!C31 -> 0 | D26: ='Summery Report'!E25 -> 0 | E26: =SUM(E25) -> 1.3262195 | F26: =SUM(J26*E26)/D26 -> #DIV/0! | G26: =SUM(L26*E26)/D26 -> #DIV/0! | H26: =Gen!D31 -> 40619.84 | I26: =Gen!F31 -> 18000 | J26: =Gen!T31 -> 0 | K26: =Gen!AK31 -> 0 | L26: =SUM(J26:K26) -> 0 | M26: ='Water-Meter'!K66 -> 0 | N26: ='Water-Meter'!E26 -> 0 | Q26: =SUM(P26-P25) -> 0 | R26: =SUM(Q26*O26) -> 0 | U26: =T26-T25 -> 0 | V26: =SUM(U26*S26) -> 0 | Y26: =X26-X25 -> 0 | Z26: =SUM(Y26*W26) -> 0 | AA26: =SUM(Z26*X28) -> 0 | AC26: =AB26-AB25 -> 0 | AE26: =AD26-AD25 -> 0 | AF26: ='Lpg (2)'!B30*2000/85 -> 0 | AG26: ='Lpg (2)'!C30*1000/85 -> 0 | AH26: ='Lpg (2)'!D30*1000/85 -> 0 | AI26: =SUM(AF26*2000)+(AG26*1000)+(AH26*1000) -> 0 | AJ26: =SUM(AI25-AI26) -> 0
A27: =Gen!B32 -> 43912 | B27: ='Summery Report'!E26 -> 0 | C27: =Gen!C32 -> 0 | D27: ='Summery Report'!E26 -> 0 | E27: =SUM(E26) -> 1.3262195 | F27: =SUM(J27*E27)/D27 -> #DIV/0! | G27: =SUM(L27*E27)/D27 -> #DIV/0! | H27: =Gen!D32 -> 40619.84 | I27: =Gen!F32 -> 0 | J27: =Gen!T32 -> 0 | K27: =Gen!AK32 -> 0 | L27: =SUM(J27:K27) -> 0 | M27: ='Water-Meter'!K67 -> 0 | N27: ='Water-Meter'!E27 -> 0 | Q27: =SUM(P27-P26) -> 0 | R27: =SUM(Q27*O27) -> 0 | U27: =T27-T26 -> 0 | V27: =SUM(U27*S27) -> 0 | Y27: =X27-X26 -> 0 | Z27: =SUM(Y27*W27) -> 0 | AA27: =SUM(Z27*X29) -> 0 | AC27: =AB27-AB26 -> 0 | AE27: =AD27-AD26 -> 0 | AF27: ='Lpg (2)'!B31*2000/85 -> 0 | AG27: ='Lpg (2)'!C31*1000/85 -> 0 | AH27: ='Lpg (2)'!D31*1000/85 -> 0 | AI27: =SUM(AF27*2000)+(AG27*1000)+(AH27*1000) -> 0 | AJ27: =SUM(AI26-AI27) -> 0
A28: =Gen!B33 -> 43913 | B28: ='Summery Report'!E27 -> 0 | C28: =Gen!C33 -> 0 | D28: ='Summery Report'!E27 -> 0 | E28: =SUM(E27) -> 1.3262195 | F28: =SUM(J28*E28)/D28 -> #DIV/0! | G28: =SUM(L28*E28)/D28 -> #DIV/0! | H28: =Gen!D33 -> 40619.84 | I28: =Gen!F33 -> 0 | J28: =Gen!T33 -> 0 | K28: =Gen!AK33 -> 0 | L28: =SUM(J28:K28) -> 0 | M28: ='Water-Meter'!K68 -> 0 | N28: ='Water-Meter'!E28 -> 0 | Q28: =SUM(P28-P27) -> 0 | R28: =SUM(Q28*O28) -> 0 | U28: =T28-T27 -> 0 | V28: =SUM(U28*S28) -> 0 | Y28: =X28-X27 -> 0 | Z28: =SUM(Y28*W28) -> 0 | AA28: =SUM(Z28*X30) -> 0 | AC28: =SUM(AB28-AB27) -> 0 | AE28: =AD28-AD27 -> 0 | AF28: ='Lpg (2)'!B32*2000/85 -> 0 | AG28: ='Lpg (2)'!C32*1000/85 -> 0 | AH28: ='Lpg (2)'!D32*1000/85 -> 0 | AI28: =SUM(AF28*2000)+(AG28*1000)+(AH28*1000) -> 0 | AJ28: =SUM(AI27-AI28) -> 0
A29: =Gen!B34 -> 43914 | B29: ='Summery Report'!E28 -> 0 | C29: =Gen!C34 -> 0 | D29: ='Summery Report'!E28 -> 0 | E29: =SUM(E28) -> 1.3262195 | F29: =SUM(J29*E29)/D29 -> #DIV/0! | G29: =SUM(L29*E29)/D29 -> #DIV/0! | H29: =Gen!D34 -> 40619.84 | I29: =Gen!F34 -> 0 | J29: =Gen!T34 -> 0 | K29: =Gen!AK34 -> 0 | L29: =SUM(J29:K29) -> 0 | M29: ='Water-Meter'!K69 -> 0 | N29: ='Water-Meter'!E29 -> 0 | Q29: =SUM(P29-P28) -> 0 | R29: =SUM(Q29*O29) -> 0 | U29: =T29-T28 -> 0 | V29: =SUM(U29*S29) -> 0 | Y29: =X29-X28 -> 0 | Z29: =SUM(Y29*W29) -> 0 | AA29: =SUM(Z29*X31) -> 0 | AC29: =SUM(AB29-AB28) -> 0 | AE29: =AD29-AD28 -> 0 | AF29: ='Lpg (2)'!B33*2000/85 -> 0 | AG29: ='Lpg (2)'!C33*1000/85 -> 0 | AH29: ='Lpg (2)'!D33*1000/85 -> 0 | AI29: =SUM(AF29*2000)+(AG29*1000)+(AH29*1000) -> 0 | AJ29: =SUM(AI28-AI29) -> 0
A30: =Gen!B35 -> 43915 | B30: ='Summery Report'!E29 -> 0 | C30: =Gen!C35 -> 0 | D30: ='Summery Report'!E29 -> 0 | E30: =SUM(E29) -> 1.3262195 | F30: =SUM(J30*E30)/D30 -> #DIV/0! | G30: =SUM(L30*E30)/D30 -> #DIV/0! | H30: =Gen!D35 -> 40619.84 | I30: =Gen!F35 -> 0 | J30: =Gen!T35 -> 0 | K30: =Gen!AK35 -> 0 | L30: =SUM(J30:K30) -> 0 | M30: ='Water-Meter'!K70 -> 0 | N30: ='Water-Meter'!E30 -> 0 | Q30: =SUM(P30-P29) -> 0 | R30: =SUM(Q30*O30) -> 0 | U30: =T30-T29 -> 0 | V30: =SUM(U30*S30) -> 0 | Y30: =X30-X29 -> 0 | Z30: =SUM(Y30*W30) -> 0 | AA30: =SUM(Z30*X32) -> 0 | AC30: =SUM(AB30-AB29) -> 0 | AE30: =AD30-AD29 -> 0 | AF30: ='Lpg (2)'!B34*2000/85 -> 0 | AG30: ='Lpg (2)'!C34*1000/85 -> 0 | AH30: ='Lpg (2)'!D34*1000/85 -> 0 | AI30: =SUM(AF30*2000)+(AG30*1000)+(AH30*1000) -> 0 | AJ30: =SUM(AI29-AI30) -> 0
A31: =Gen!B36 -> 43916 | B31: ='Summery Report'!E30 -> 0 | C31: =Gen!C36 -> 0 | D31: ='Summery Report'!E30 -> 0 | E31: =SUM(E30) -> 1.3262195 | F31: =SUM(J31*E31)/D31 -> #DIV/0! | G31: =SUM(L31*E31)/D31 -> #DIV/0! | H31: =Gen!D36 -> 40619.84 | I31: =Gen!F36 -> 0 | J31: =Gen!T36 -> 0 | K31: =Gen!AK36 -> 0 | L31: =SUM(J31:K31) -> 0 | M31: ='Water-Meter'!K71 -> 0 | N31: ='Water-Meter'!E31 -> 0 | Q31: =SUM(P31-P30) -> 0 | R31: =SUM(Q31*O31) -> 0 | U31: =T31-T30 -> 0 | V31: =SUM(U31*S31) -> 0 | Y31: =X31-X30 -> 0 | Z31: =SUM(Y31*W31) -> 0 | AA31: =SUM(Z31*X33) -> 0 | AC31: =SUM(AB31-AB30) -> 0 | AE31: =AD31-AD30 -> 0 | AF31: ='Lpg (2)'!B35*2000/85 -> 0 | AG31: ='Lpg (2)'!C35*1000/85 -> 0 | AH31: ='Lpg (2)'!D35*1000/85 -> 0 | AI31: =SUM(AF31*2000)+(AG31*1000)+(AH31*1000) -> 0 | AJ31: =SUM(AI30-AI31) -> 0
