Workbook

Sheet Total
A1: Site Name | B1: Day | C1: Month | D1: Year | E1: Total Electricity Kwh | F1: Electricity Tariff ($/Kwh) | G1: Total Fuel Oil (Liters) | H1: Fuel Oil $/Liter | I1: LPG (Kg) | J1: LPG $/Kg | K1: Water Utility Supply (m3) m3 | L1: Water Utility Supply (m3) $/m3 | M1: Irrigation Water (m3) m3 | N1: Irrigation water $/m3 | O1: Room Nights
A2: Beirut | B2: 1 | C2: 3 | D2: 2020 | E2: =ELEC!N3 -> 10658 | F2: =SUM('EDl log'!T4) -> 0.048038828 | G2: =-tanks!AW6 -> 580 | H2: =SUM(tanks!AV6) -> 0.1 | I2: =('B5'!AU5)*0.51 -> 122.451 | J2: ='B5'!AX5/0.51 -> 0.19607843 | K2: =WATER!I6 -> 0 | L2: =SUM(WATER!J6) -> 0 | M2: =WATER!Q6 -> 0 | N2: 0.6 | O2: =ELEC!B3 -> 35.006
A3: Beirut | B3: =B2+1 -> 2 | C3: 3 | D3: 2020 | E3: =ELEC!N4 -> 12173 | F3: =SUM('EDl log'!T5) -> 0.048140417 | G3: =-tanks!AW7 -> 567 | H3: =SUM(tanks!AV7) -> 0.1 | I3: =('B5'!AU6)*0.51 -> 30.6 | J3: ='B5'!AX6/0.51 -> 0.19607843 | K3: =WATER!I7 -> 454 | L3: =SUM(WATER!J7) -> 0.53289754 | M3: =WATER!Q7 -> 0 | N3: 0.6 | O3: =ELEC!B4 -> 25.99
A4: Beirut | B4: =B3+1 -> 3 | C4: 3 | D4: 2020 | E4: =ELEC!N5 -> 11827.6 | F4: =SUM('EDl log'!T6) -> 0.044792755 | G4: =-tanks!AW8 -> 1061.4 | H4: =SUM(tanks!AV8) -> 0.1 | I4: =('B5'!AU7)*0.51 -> 45.9 | J4: ='B5'!AX7/0.51 -> 0.19607843 | K4: =WATER!I8 -> 0 | L4: =SUM(WATER!J8) -> 0 | M4: =WATER!Q8 -> 0 | N4: 0.6 | O4: =ELEC!B5 -> 27.991
A5: Beirut | B5: =B4+1 -> 4 | C5: 3 | D5: 2020 | E5: =ELEC!N6 -> 12688.8 | F5: =SUM('EDl log'!T7) -> 0.05022043 | G5: =-tanks!AW9 -> 276.7 | H5: =SUM(tanks!AV9) -> 0.1 | I5: =('B5'!AU8)*0.51 -> 107.1 | J5: ='B5'!AX8/0.51 -> 0.19607843 | K5: =WATER!I9 -> 341 | L5: =SUM(WATER!J9) -> 0.70948822 | M5: =WATER!Q9 -> 0 | N5: 0.6 | O5: =ELEC!B6 -> 29.003
A6: Beirut | B6: =B5+1 -> 5 | C6: 3 | D6: 2020 | E6: =ELEC!N7 -> 0 | F6: =SUM('EDl log'!T8) -> 0 | G6: =-tanks!AW10 -> 0 | H6: =SUM(tanks!AV10) -> 0.1 | I6: =('B5'!AU9)*0.51 -> 0 | J6: ='B5'!AX9/0.51 -> 0.19607843 | K6: =WATER!I10 -> 0 | L6: =SUM(WATER!J10) -> 0 | M6: =WATER!Q10 -> 0 | N6: 0.6 | O6: =ELEC!B7 -> 0
A7: Beirut | B7: =B6+1 -> 6 | C7: 3 | D7: 2020 | E7: =ELEC!N8 -> 0 | F7: =SUM('EDl log'!T9) -> 0 | G7: =-tanks!AW11 -> 0 | H7: =SUM(tanks!AV11) -> 0.1 | I7: =('B5'!AU10)*0.51 -> 0 | J7: ='B5'!AX10/0.51 -> 0.19607843 | K7: =WATER!I11 -> 0 | L7: =SUM(WATER!J11) -> 0 | M7: =WATER!Q11 -> 0 | N7: 0.6 | O7: =ELEC!B8 -> 0
A8: Beirut | B8: =B7+1 -> 7 | C8: 3 | D8: 2020 | E8: =ELEC!N9 -> 0 | F8: =SUM('EDl log'!T10) -> 0 | G8: =-tanks!AW12 -> 0 | H8: =SUM(tanks!AV12) -> 0.1 | I8: =('B5'!AU11)*0.51 -> 0 | J8: ='B5'!AX11/0.51 -> 0.19607843 | K8: =WATER!I12 -> 0 | L8: =SUM(WATER!J12) -> 0 | M8: =WATER!Q12 -> 0 | N8: 0.6 | O8: =ELEC!B9 -> 0
A9: Beirut | B9: =B8+1 -> 8 | C9: 3 | D9: 2020 | E9: =ELEC!N10 -> 0 | F9: =SUM('EDl log'!T11) -> 0 | G9: =-tanks!AW13 -> 0 | H9: =SUM(tanks!AV13) -> 0.1 | I9: =('B5'!AU12)*0.51 -> 0 | J9: ='B5'!AX12/0.51 -> 0.19607843 | K9: =WATER!I13 -> 0 | L9: =SUM(WATER!J13) -> 0 | M9: =WATER!Q13 -> 0 | N9: 0.6 | O9: =ELEC!B10 -> 0
A10: Beirut | B10: =B9+1 -> 9 | C10: 3 | D10: 2020 | E10: =ELEC!N11 -> 0 | F10: =SUM('EDl log'!T12) -> 0 | G10: =-tanks!AW14 -> 0 | H10: =SUM(tanks!AV14) -> 0.1 | I10: =('B5'!AU13)*0.51 -> 0 | J10: ='B5'!AX13/0.51 -> 0.19607843 | K10: =WATER!I14 -> 0 | L10: =SUM(WATER!J14) -> 0 | M10: =WATER!Q14 -> 0 | N10: 0.6 | O10: =ELEC!B11 -> 0
A11: Beirut | B11: =B10+1 -> 10 | C11: 3 | D11: 2020 | E11: =ELEC!N12 -> 0 | F11: =SUM('EDl log'!T13) -> 0 | G11: =-tanks!AW15 -> 0 | H11: =SUM(tanks!AV15) -> 0.1 | I11: =('B5'!AU14)*0.51 -> 0 | J11: ='B5'!AX14/0.51 -> 0.19607843 | K11: =WATER!I15 -> 0 | L11: =SUM(WATER!J15) -> 0 | M11: =WATER!Q15 -> 0 | N11: 0.6 | O11: =ELEC!B12 -> 0
A12: Beirut | B12: =B11+1 -> 11 | C12: 3 | D12: 2020 | E12: =ELEC!N13 -> 0 | F12: =SUM('EDl log'!T14) -> 0 | G12: =-tanks!AW16 -> 0 | H12: =SUM(tanks!AV16) -> 0.1 | I12: =('B5'!AU15)*0.51 -> 0 | J12: ='B5'!AX15/0.51 -> 0.19607843 | K12: =WATER!I16 -> 0 | L12: =SUM(WATER!J16) -> 0 | M12: =WATER!Q16 -> 0 | N12: 0.6 | O12: =ELEC!B13 -> 0
A13: Beirut | B13: =B12+1 -> 12 | C13: 3 | D13: 2020 | E13: =ELEC!N14 -> 0 | F13: =SUM('EDl log'!T15) -> 0 | G13: =-tanks!AW17 -> 0 | H13: =SUM(tanks!AV17) -> 0.1 | I13: =('B5'!AU16)*0.51 -> 0 | J13: ='B5'!AX16/0.51 -> 0.19607843 | K13: =WATER!I17 -> 0 | L13: =SUM(WATER!J17) -> 0 | M13: =WATER!Q17 -> 0 | N13: 0.6 | O13: =ELEC!B14 -> 0
A14: Beirut | B14: =B13+1 -> 13 | C14: 3 | D14: 2020 | E14: =ELEC!N15 -> 0 | F14: =SUM('EDl log'!T16) -> 0 | G14: =-tanks!AW18 -> 0 | H14: =SUM(tanks!AV18) -> 0.1 | I14: =('B5'!AU17)*0.51 -> 0 | J14: ='B5'!AX17/0.51 -> 0.19607843 | K14: =WATER!I18 -> 0 | L14: =SUM(WATER!J18) -> 0 | M14: =WATER!Q18 -> 0 | N14: 0.6 | O14: =ELEC!B15 -> 0
... A32: Beirut | B32: =B31+1 -> 31 | C32: 3 | D32: 2020 | E32: =ELEC!N33 -> 0 | F32: =SUM('EDl log'!T34) -> 0 | G32: =-tanks!AW36 -> 0 | H32: =SUM(tanks!AV36) -> 0.1 | I32: =('B5'!AU35)*0.51 -> 0 | J32: ='B5'!AX35/0.51 -> 0.19607843 | K32: =WATER!I36 -> 0 | L32: =SUM(WATER!J36) -> 0 | M32: =WATER!Q36 -> 0 | N32: 0.6 | O32: =ELEC!B33 -> 0

Sheet Submetering
A1: Site Name | B1: Day | C1: Month | D1: Year | E1: ATS1 Kwh | F1: ATS2 Kwh | G1: ATS3 Kwh | H1: ATS4 Kwh | I1: ATS5 Kwh | J1: Guest (m3) | K1: Kitchen & Laundry (m3) | L1: Room Nights
A2: Beirut | B2: 1 | C2: 3 | D2: 2020 | E2: =ELEC!M3 -> 3180 | F2: =ELEC!K3 -> 1116 | G2: =ELEC!I3 -> 1704 | H2: =ELEC!E3 -> 2808 | I2: =ELEC!G3 -> 1850 | J2: =WATER!Y6 -> 26 | K2: =WATER!AJ6 -> 11 | L2: =ELEC!B3 -> 35.006
A3: Beirut | B3: =B2+1 -> 2 | C3: 3 | D3: 2020 | E3: =ELEC!M4 -> 3284 | F3: =ELEC!K4 -> 1684 | G3: =ELEC!I4 -> 1910 | H3: =ELEC!E4 -> 3246 | I3: =ELEC!G4 -> 2049 | J3: =WATER!Y7 -> 152 | K3: =WATER!AJ7 -> 66 | L3: =ELEC!B4 -> 25.99
A4: Beirut | B4: =B3+1 -> 3 | C4: 3 | D4: 2020 | E4: =ELEC!M5 -> 3232 | F4: =ELEC!K5 -> 1468 | G4: =ELEC!I5 -> 1798 | H4: =ELEC!E5 -> 3364 | I4: =ELEC!G5 -> 1965.6 | J4: =WATER!Y8 -> 0 | K4: =WATER!AJ8 -> 0 | L4: =ELEC!B5 -> 27.991
A5: Beirut | B5: =B4+1 -> 4 | C5: 3 | D5: 2020 | E5: =ELEC!M6 -> 3424 | F5: =ELEC!K6 -> 1488 | G5: =ELEC!I6 -> 2038 | H5: =ELEC!E6 -> 3630 | I5: =ELEC!G6 -> 2108.8 | J5: =WATER!Y9 -> 93 | K5: =WATER!AJ9 -> 90 | L5: =ELEC!B6 -> 29.003
A6: Beirut | B6: =B5+1 -> 5 | C6: 3 | D6: 2020 | E6: =ELEC!M7 -> 0 | F6: =ELEC!K7 -> 0 | G6: =ELEC!I7 -> 0 | H6: =ELEC!E7 -> 0 | I6: =ELEC!G7 -> 0 | J6: =WATER!Y10 -> 0 | K6: =WATER!AJ10 -> 0 | L6: =ELEC!B7 -> 0
A7: Beirut | B7: =B6+1 -> 6 | C7: 3 | D7: 2020 | E7: =ELEC!M8 -> 0 | F7: =ELEC!K8 -> 0 | G7: =ELEC!I8 -> 0 | H7: =ELEC!E8 -> 0 | I7: =ELEC!G8 -> 0 | J7: =WATER!Y11 -> 0 | K7: =WATER!AJ11 -> 0 | L7: =ELEC!B8 -> 0
A8: Beirut | B8: =B7+1 -> 7 | C8: 3 | D8: 2020 | E8: =ELEC!M9 -> 0 | F8: =ELEC!K9 -> 0 | G8: =ELEC!I9 -> 0 | H8: =ELEC!E9 -> 0 | I8: =ELEC!G9 -> 0 | J8: =WATER!Y12 -> 0 | K8: =WATER!AJ12 -> 0 | L8: =ELEC!B9 -> 0
A9: Beirut | B9: =B8+1 -> 8 | C9: 3 | D9: 2020 | E9: =ELEC!M10 -> 0 | F9: =ELEC!K10 -> 0 | G9: =ELEC!I10 -> 0 | H9: =ELEC!E10 -> 0 | I9: =ELEC!G10 -> 0 | J9: =WATER!Y13 -> 0 | K9: =WATER!AJ13 -> 0 | L9: =ELEC!B10 -> 0
A10: Beirut | B10: =B9+1 -> 9 | C10: 3 | D10: 2020 | E10: =ELEC!M11 -> 0 | F10: =ELEC!K11 -> 0 | G10: =ELEC!I11 -> 0 | H10: =ELEC!E11 -> 0 | I10: =ELEC!G11 -> 0 | J10: =WATER!Y14 -> 0 | K10: =WATER!AJ14 -> 0 | L10: =ELEC!B11 -> 0
A11: Beirut | B11: =B10+1 -> 10 | C11: 3 | D11: 2020 | E11: =ELEC!M12 -> 0 | F11: =ELEC!K12 -> 0 | G11: =ELEC!I12 -> 0 | H11: =ELEC!E12 -> 0 | I11: =ELEC!G12 -> 0 | J11: =WATER!Y15 -> 0 | K11: =WATER!AJ15 -> 0 | L11: =ELEC!B12 -> 0
A12: Beirut | B12: =B11+1 -> 11 | C12: 3 | D12: 2020 | E12: =ELEC!M13 -> 0 | F12: =ELEC!K13 -> 0 | G12: =ELEC!I13 -> 0 | H12: =ELEC!E13 -> 0 | I12: =ELEC!G13 -> 0 | J12: =WATER!Y16 -> 0 | K12: =WATER!AJ16 -> 0 | L12: =ELEC!B13 -> 0
A13: Beirut | B13: =B12+1 -> 12 | C13: 3 | D13: 2020 | E13: =ELEC!M14 -> 0 | F13: =ELEC!K14 -> 0 | G13: =ELEC!I14 -> 0 | H13: =ELEC!E14 -> 0 | I13: =ELEC!G14 -> 0 | J13: =WATER!Y17 -> 0 | K13: =WATER!AJ17 -> 0 | L13: =ELEC!B14 -> 0
A14: Beirut | B14: =B13+1 -> 13 | C14: 3 | D14: 2020 | E14: =ELEC!M15 -> 0 | F14: =ELEC!K15 -> 0 | G14: =ELEC!I15 -> 0 | H14: =ELEC!E15 -> 0 | I14: =ELEC!G15 -> 0 | J14: =WATER!Y18 -> 0 | K14: =WATER!AJ18 -> 0 | L14: =ELEC!B15 -> 0
... A32: Beirut | B32: =B31+1 -> 31 | C32: 3 | D32: 2020 | E32: =ELEC!M33 -> 0 | F32: =ELEC!K33 -> 0 | G32: =ELEC!I33 -> 0 | H32: =ELEC!E33 -> 0 | I32: =ELEC!G33 -> 0 | J32: =WATER!Y36 -> 0 | K32: =WATER!AJ36 -> 0 | L32: =ELEC!B33 -> 0

Sheet ELEC
A1: OOC | B1: Room OCC | D1: MDB3 | E1: MDB3/day | F1: EMDB2 | G1: EMDB2/day | H1: EMDB1 | I1: EMDB1/day | J1: MDB2 | K1: mdb2/day | L1: MDB1 | M1: MDB1/Day | N1: Total KWH | O1: KWH/Rooc | P1: Gen MHW | Q1: Gen/Day KWH | R1: EDL KWH | S1: CH1 RH | T1: RH | U1: C1h1 power | V1: CH1 Con KWH | W1: CH2 RH | X1: RH | Y1: Ch2 power | Z1: CH2 Con KWH | AA1: CH3 RH | AB1: RH | AC1: Ch3 power | AD1: CH3 Con KWH | AE1: RH total | AF1: KWH total | AG1: AVG chiller KW/Hr
A2: 0.1391 | B2: 0.1391 | C2: 43890 | D2: =[1]ELEC!D31 -> 31482720 | E2: =[1]ELEC!E31 -> 3634 | F2: =[1]ELEC!F31 -> 3556171 | G2: =[1]ELEC!G31 -> 2226 | H2: =[1]ELEC!H31 -> 17345006 | I2: =[1]ELEC!I31 -> 2064 | J2: =[1]ELEC!J31 -> 28330034 | K2: =[1]ELEC!K31 -> 2096 | ... AI2: =[1]ELEC!AI31 -> -49556526
A3: ='General information '!F6 -> 0.1522 | B3: =SUM(230*A3) -> 35.006 | C3: 43891 | D3: 31485528 | E3: =D3-D2 -> 2808 | F3: 3558021 | G3: =F3-F2 -> 1850 | H3: 17346710 | I3: =H3-H2 -> 1704 | J3: 28331150 | K3: =J3-J2 -> 1116 | L3: 22755778 | M3: =L3-L2 -> 3180 | N3: =M3+K3+I3+G3+E3 -> 10658 | O3: =IF(B3>0,N3/B3,0) -> 304.46209 | P3: 15381 | Q3: =(P3-P2)*1000 -> 4100 | R3: =+N3-Q3 -> 6558 | S3: 8384 | T3: =S3-S2 -> 0 | U3: 1024343 | V3: =U3-U2 -> 0 | W3: 31845 | X3: =W3-W2 -> 0 | Y3: 624440 | Z3: =Y3-Y2 -> 0 | AA3: 34971 | AB3: =AA3-AA2 -> 4 | AC3: 757660 | AD3: =AC3-AC2 -> 681 | AE3: =AB3+X3+T3 -> 4 | AF3: =V3+Z3+AD3 -> 681 | AG3: =IF(AE3>0,AF3/AE3,0) -> 170.25
A4: ='General information '!F7 -> 0.113 | B4: =SUM(230*A4) -> 25.99 | C4: 43892 | D4: 31488774 | E4: =D4-D3 -> 3246 | F4: 3560070 | G4: =F4-F3 -> 2049 | H4: 17348620 | I4: =H4-H3 -> 1910 | J4: 28332834 | K4: =J4-J3 -> 1684 | L4: 22759062 | M4: =L4-L3 -> 3284 | N4: =M4+K4+I4+G4+E4 -> 12173 | O4: =IF(B4>0,N4/B4,0) -> 468.37245 | P4: 15381.849 | Q4: =(P4-P3)*1000 -> 849 | R4: =N4-Q4 -> 11324 | S4: =S3 -> 8384 | T4: =S4-S3 -> 0 | U4: =U3 -> 1024343 | V4: =U4-U3 -> 0 | W4: =W3 -> 31845 | X4: =W4-W3 -> 0 | Y4: =Y3 -> 624440 | Z4: =Y4-Y3 -> 0 | AA4: 34974 | AB4: =AA4-AA3 -> 3 | AC4: 758247 | AD4: =AC4-AC3 -> 587 | AE4: =AB4+X4+T4 -> 3 | AF4: =V4+Z4+AD4 -> 587 | AG4: =IF(AE4>0,AF4/AE4,0) -> 195.66667
A5: ='General information '!F8 -> 0.1217 | B5: =SUM(230*A5) -> 27.991 | C5: 43893 | D5: 31492138 | E5: =D5-D4 -> 3364 | F5: 3562035.6 | G5: =F5-F4 -> 1965.6 | H5: 17350418 | I5: =H5-H4 -> 1798 | J5: 28334302 | K5: =J5-J4 -> 1468 | L5: 22762294 | M5: =L5-L4 -> 3232 | N5: =M5+K5+I5+G5+E5 -> 11827.6 | O5: =IF(B5>0,N5/B5,0) -> 422.55011 | P5: 15383.715 | Q5: =(P5-P4)*1000 -> 1866 | R5: =N5-Q5 -> 9961.6 | S5: 8384 | T5: =S5-S4 -> 0 | U5: 1024343 | V5: =U5-U4 -> 0 | W5: 31845 | X5: =W5-W4 -> 0 | Y5: 624440 | Z5: =Y5-Y4 -> 0 | AA5: 34978 | AB5: =AA5-AA4 -> 4 | AC5: 759035 | AD5: =AC5-AC4 -> 788 | AE5: =AB5+X5+T5 -> 4 | AF5: =V5+Z5+AD5 -> 788 | AG5: =IF(AE5>0,AF5/AE5,0) -> 197 | AI5: =R5-'EDl log'!B3 -> -49572080
A6: ='General information '!F9 -> 0.1261 | B6: =SUM(230*A6) -> 29.003 | C6: 43894 | D6: 31495768 | E6: =D6-D5 -> 3630 | F6: 3564144.4 | G6: =F6-F5 -> 2108.8 | H6: 17352456 | I6: =H6-H5 -> 2038 | J6: 28335790 | K6: =J6-J5 -> 1488 | L6: 22765718 | M6: =L6-L5 -> 3424 | N6: =M6+K6+I6+G6+E6 -> 12688.8 | O6: =IF(B6>0,N6/B6,0) -> 437.49957 | P6: 15386.126 | Q6: =(P6-P5)*1000 -> 2411 | R6: =N6-Q6 -> 10277.8 | S6: 8384 | T6: =S6-S5 -> 0 | U6: 1024343 | V6: =U6-U5 -> 0 | W6: 31845 | X6: =W6-W5 -> 0 | Y6: 624440 | Z6: =Y6-Y5 -> 0 | AA6: 34982 | AB6: =AA6-AA5 -> 4 | AC6: 759837 | AD6: =AC6-AC5 -> 802 | AE6: =AB6+X6+T6 -> 4 | AF6: =V6+Z6+AD6 -> 802 | AG6: =IF(AE6>0,AF6/AE6,0) -> 200.5 | AI6: =R6-'EDl log'!B4 -> -49576134
A7: ='General information '!F10 -> 0 | B7: =SUM(230*A7) -> 0 | C7: 43895 | D7: =D6 -> 31495768 | E7: =D7-D6 -> 0 | F7: =F6 -> 3564144.4 | G7: =F7-F6 -> 0 | H7: =H6 -> 17352456 | I7: =H7-H6 -> 0 | J7: =J6 -> 28335790 | K7: =J7-J6 -> 0 | L7: =L6 -> 22765718 | M7: =L7-L6 -> 0 | N7: =M7+K7+I7+G7+E7 -> 0 | O7: =IF(B7>0,N7/B7,0) -> 0 | P7: =P6 -> 15386.126 | Q7: =(P7-P6)*1000 -> 0 | R7: =N7-Q7 -> 0 | S7: =S6 -> 8384 | T7: =S7-S6 -> 0 | U7: =U6 -> 1024343 | V7: =U7-U6 -> 0 | W7: =W6 -> 31845 | X7: =W7-W6 -> 0 | Y7: =Y6 -> 624440 | Z7: =Y7-Y6 -> 0 | AA7: =AA6 -> 34982 | AB7: =AA7-AA6 -> 0 | AC7: =AC6 -> 759837 | AD7: =AC7-AC6 -> 0 | AE7: =AB7+X7+T7 -> 0 | AF7: =V7+Z7+AD7 -> 0 | AG7: =IF(AE7>0,AF7/AE7,0) -> 0 | AI7: =R7-'EDl log'!B5 -> -49591340
A8: ='General information '!F11 -> 0 | B8: =SUM(230*A8) -> 0 | C8: 43896 | D8: =D7 -> 31495768 | E8: =D8-D7 -> 0 | F8: =F7 -> 3564144.4 | G8: =F8-F7 -> 0 | H8: =H7 -> 17352456 | I8: =H8-H7 -> 0 | J8: =J7 -> 28335790 | K8: =J8-J7 -> 0 | L8: =L7 -> 22765718 | M8: =L8-L7 -> 0 | N8: =M8+K8+I8+G8+E8 -> 0 | O8: =IF(B8>0,N8/B8,0) -> 0 | P8: =P7 -> 15386.126 | Q8: =(P8-P7)*1000 -> 0 | R8: =N8-Q8 -> 0 | S8: =S7 -> 8384 | T8: =S8-S7 -> 0 | U8: =U7 -> 1024343 | V8: =U8-U7 -> 0 | W8: =W7 -> 31845 | X8: =W8-W7 -> 0 | Y8: =Y7 -> 624440 | Z8: =Y8-Y7 -> 0 | AA8: =AA7 -> 34982 | AB8: =AA8-AA7 -> 0 | AC8: =AC7 -> 759837 | AD8: =AC8-AC7 -> 0 | AE8: =AB8+X8+T8 -> 0 | AF8: =V8+Z8+AD8 -> 0 | AG8: =IF(AE8>0,AF8/AE8,0) -> 0 | AI8: =R8-'EDl log'!B6 -> -49596500
A9: ='General information '!F12 -> 0 | B9: =SUM(230*A9) -> 0 | C9: 43897 | D9: =D8 -> 31495768 | E9: =D9-D8 -> 0 | F9: =F8 -> 3564144.4 | G9: =F9-F8 -> 0 | H9: =H8 -> 17352456 | I9: =H9-H8 -> 0 | J9: =J8 -> 28335790 | K9: =J9-J8 -> 0 | L9: =L8 -> 22765718 | M9: =L9-L8 -> 0 | N9: =M9+K9+I9+G9+E9 -> 0 | O9: =IF(B9>0,N9/B9,0) -> 0 | P9: =P8 -> 15386.126 | Q9: =(P9-P8)*1000 -> 0 | R9: =N9-Q9 -> 0 | S9: =S8 -> 8384 | T9: =S9-S8 -> 0 | U9: =U8 -> 1024343 | V9: =U9-U8 -> 0 | W9: =W8 -> 31845 | X9: =W9-W8 -> 0 | Y9: =Y8 -> 624440 | Z9: =Y9-Y8 -> 0 | AA9: =AA8 -> 34982 | AB9: =AA9-AA8 -> 0 | AC9: =AC8 -> 759837 | AD9: =AC9-AC8 -> 0 | AE9: =AB9+X9+T9 -> 0 | AF9: =V9+Z9+AD9 -> 0 | AG9: =IF(AE9>0,AF9/AE9,0) -> 0 | AI9: =R9-'EDl log'!B7 -> -49601831
A10: ='General information '!F13 -> 0 | B10: =SUM(230*A10) -> 0 | C10: 43898 | D10: =D9 -> 31495768 | E10: =D10-D9 -> 0 | F10: =F9 -> 3564144.4 | G10: =F10-F9 -> 0 | H10: =H9 -> 17352456 | I10: =H10-H9 -> 0 | J10: =J9 -> 28335790 | K10: =J10-J9 -> 0 | L10: =L9 -> 22765718 | M10: =L10-L9 -> 0 | N10: =M10+K10+I10+G10+E10 -> 0 | O10: =IF(B10>0,N10/B10,0) -> 0 | P10: =P9 -> 15386.126 | Q10: =(P10-P9)*1000 -> 0 | R10: =N10-Q10 -> 0 | S10: =S9 -> 8384 | T10: =S10-S9 -> 0 | U10: =U9 -> 1024343 | V10: =U10-U9 -> 0 | W10: =W9 -> 31845 | X10: =W10-W9 -> 0 | Y10: =Y9 -> 624440 | Z10: =Y10-Y9 -> 0 | AA10: =AA9 -> 34982 | AB10: =AA10-AA9 -> 0 | AC10: =AC9 -> 759837 | AD10: =AC10-AC9 -> 0 | AE10: =AB10+X10+T10 -> 0 | AF10: =V10+Z10+AD10 -> 0 | AG10: =IF(AE10>0,AF10/AE10,0) -> 0 | AI10: =R10-'EDl log'!B8 -> -49601831
A11: ='General information '!F14 -> 0 | B11: =SUM(230*A11) -> 0 | C11: 43899 | D11: =D10 -> 31495768 | E11: =D11-D10 -> 0 | F11: =F10 -> 3564144.4 | G11: =F11-F10 -> 0 | H11: =H10 -> 17352456 | I11: =H11-H10 -> 0 | J11: =J10 -> 28335790 | K11: =J11-J10 -> 0 | L11: =L10 -> 22765718 | M11: =L11-L10 -> 0 | N11: =M11+K11+I11+G11+E11 -> 0 | O11: =IF(B11>0,N11/B11,0) -> 0 | P11: =P10 -> 15386.126 | Q11: =(P11-P10)*1000 -> 0 | R11: =N11-Q11 -> 0 | S11: =S10 -> 8384 | T11: =S11-S10 -> 0 | U11: =U10 -> 1024343 | V11: =U11-U10 -> 0 | W11: =W10 -> 31845 | X11: =W11-W10 -> 0 | Y11: =Y10 -> 624440 | Z11: =Y11-Y10 -> 0 | AA11: =AA10 -> 34982 | AB11: =AA11-AA10 -> 0 | AC11: =AC10 -> 759837 | AD11: =AC11-AC10 -> 0 | AE11: =AB11+X11+T11 -> 0 | AF11: =V11+Z11+AD11 -> 0 | AG11: =IF(AE11>0,AF11/AE11,0) -> 0 | AI11: =R11-'EDl log'!B9 -> -49601831
A12: ='General information '!F15 -> 0 | B12: =SUM(230*A12) -> 0 | C12: 43900 | D12: =D11 -> 31495768 | E12: =D12-D11 -> 0 | F12: =F11 -> 3564144.4 | G12: =F12-F11 -> 0 | H12: =H11 -> 17352456 | I12: =H12-H11 -> 0 | J12: =J11 -> 28335790 | K12: =J12-J11 -> 0 | L12: =L11 -> 22765718 | M12: =L12-L11 -> 0 | N12: =M12+K12+I12+G12+E12 -> 0 | O12: =IF(B12>0,N12/B12,0) -> 0 | P12: =P11 -> 15386.126 | Q12: =(P12-P11)*1000 -> 0 | R12: =N12-Q12 -> 0 | S12: =S11 -> 8384 | T12: =S12-S11 -> 0 | U12: =U11 -> 1024343 | V12: =U12-U11 -> 0 | W12: =W11 -> 31845 | X12: =W12-W11 -> 0 | Y12: =Y11 -> 624440 | Z12: =Y12-Y11 -> 0 | AA12: =AA11 -> 34982 | AB12: =AA12-AA11 -> 0 | AC12: =AC11 -> 759837 | AD12: =AC12-AC11 -> 0 | AE12: =AB12+X12+T12 -> 0 | AF12: =V12+Z12+AD12 -> 0 | AG12: =IF(AE12>0,AF12/AE12,0) -> 0 | AI12: =R12-'EDl log'!B10 -> -49601831
A13: ='General information '!F16 -> 0 | B13: =SUM(230*A13) -> 0 | C13: 43901 | D13: =D12 -> 31495768 | E13: =D13-D12 -> 0 | F13: =F12 -> 3564144.4 | G13: =F13-F12 -> 0 | H13: =H12 -> 17352456 | I13: =H13-H12 -> 0 | J13: =J12 -> 28335790 | K13: =J13-J12 -> 0 | L13: =L12 -> 22765718 | M13: =L13-L12 -> 0 | N13: =M13+K13+I13+G13+E13 -> 0 | O13: =IF(B13>0,N13/B13,0) -> 0 | P13: =P12 -> 15386.126 | Q13: =(P13-P12)*1000 -> 0 | R13: =N13-Q13 -> 0 | S13: =S12 -> 8384 | T13: =S13-S12 -> 0 | U13: =U12 -> 1024343 | V13: =U13-U12 -> 0 | W13: =W12 -> 31845 | X13: =W13-W12 -> 0 | Y13: =Y12 -> 624440 | Z13: =Y13-Y12 -> 0 | AA13: =AA12 -> 34982 | AB13: =AA13-AA12 -> 0 | AC13: =AC12 -> 759837 | AD13: =AC13-AC12 -> 0 | AE13: =AB13+X13+T13 -> 0 | AF13: =V13+Z13+AD13 -> 0 | AG13: =IF(AE13>0,AF13/AE13,0) -> 0 | AI13: =R13-'EDl log'!B11 -> -49601831
A14: ='General information '!F17 -> 0 | B14: =SUM(230*A14) -> 0 | C14: 43902 | D14: =D13 -> 31495768 | E14: =D14-D13 -> 0 | F14: =F13 -> 3564144.4 | G14: =F14-F13 -> 0 | H14: =H13 -> 17352456 | I14: =H14-H13 -> 0 | J14: =J13 -> 28335790 | K14: =J14-J13 -> 0 | L14: =L13 -> 22765718 | M14: =L14-L13 -> 0 | N14: =M14+K14+I14+G14+E14 -> 0 | O14: =IF(B14>0,N14/B14,0) -> 0 | P14: =P13 -> 15386.126 | Q14: =(P14-P13)*1000 -> 0 | R14: =N14-Q14 -> 0 | S14: =S13 -> 8384 | T14: =S14-S13 -> 0 | U14: =U13 -> 1024343 | V14: =U14-U13 -> 0 | W14: =W13 -> 31845 | X14: =W14-W13 -> 0 | Y14: =Y13 -> 624440 | Z14: =Y14-Y13 -> 0 | AA14: =AA13 -> 34982 | AB14: =AA14-AA13 -> 0 | AC14: =AC13 -> 759837 | AD14: =AC14-AC13 -> 0 | AE14: =AB14+X14+T14 -> 0 | AF14: =V14+Z14+AD14 -> 0 | AG14: =IF(AE14>0,AF14/AE14,0) -> 0 | AI14: =R14-'EDl log'!B12 -> -49601831
A15: ='General information '!F18 -> 0 | B15: =SUM(230*A15) -> 0 | C15: 43903 | D15: =D14 -> 31495768 | E15: =D15-D14 -> 0 | F15: =F14 -> 3564144.4 | G15: =F15-F14 -> 0 | H15: =H14 -> 17352456 | I15: =H15-H14 -> 0 | J15: =J14 -> 28335790 | K15: =J15-J14 -> 0 | L15: =L14 -> 22765718 | M15: =L15-L14 -> 0 | N15: =M15+K15+I15+G15+E15 -> 0 | O15: =IF(B15>0,N15/B15,0) -> 0 | P15: =P14 -> 15386.126 | Q15: =(P15-P14)*1000 -> 0 | R15: =N15-Q15 -> 0 | S15: =S14 -> 8384 | T15: =S15-S14 -> 0 | U15: =U14 -> 1024343 | V15: =U15-U14 -> 0 | W15: =W14 -> 31845 | X15: =W15-W14 -> 0 | Y15: =Y14 -> 624440 | Z15: =Y15-Y14 -> 0 | AA15: =AA14 -> 34982 | AB15: =AA15-AA14 -> 0 | AC15: =AC14 -> 759837 | AD15: =AC15-AC14 -> 0 | AE15: =AB15+X15+T15 -> 0 | AF15: =V15+Z15+AD15 -> 0 | AG15: =IF(AE15>0,AF15/AE15,0) -> 0 | AI15: =R15-'EDl log'!B13 -> -49601831
A16: ='General information '!F19 -> 0 | B16: =SUM(230*A16) -> 0 | C16: 43904 | D16: =D15 -> 31495768 | E16: =D16-D15 -> 0 | F16: =F15 -> 3564144.4 | G16: =F16-F15 -> 0 | H16: =H15 -> 17352456 | I16: =H16-H15 -> 0 | J16: =J15 -> 28335790 | K16: =J16-J15 -> 0 | L16: =L15 -> 22765718 | M16: =L16-L15 -> 0 | N16: =M16+K16+I16+G16+E16 -> 0 | O16: =IF(B16>0,N16/B16,0) -> 0 | P16: =P15 -> 15386.126 | Q16: =(P16-P15)*1000 -> 0 | R16: =N16-Q16 -> 0 | S16: =S15 -> 8384 | T16: =S16-S15 -> 0 | U16: =U15 -> 1024343 | V16: =U16-U15 -> 0 | W16: =W15 -> 31845 | X16: =W16-W15 -> 0 | Y16: =Y15 -> 624440 | Z16: =Y16-Y15 -> 0 | AA16: =AA15 -> 34982 | AB16: =AA16-AA15 -> 0 | AC16: =AC15 -> 759837 | AD16: =AC16-AC15 -> 0 | AE16: =AB16+X16+T16 -> 0 | AF16: =V16+Z16+AD16 -> 0 | AG16: =IF(AE16>0,AF16/AE16,0) -> 0 | AI16: =R16-'EDl log'!B14 -> -49601831
A17: ='General information '!F20 -> 0 | B17: =SUM(230*A17) -> 0 | C17: 43905 | D17: =D16 -> 31495768 | E17: =D17-D16 -> 0 | F17: =F16 -> 3564144.4 | G17: =F17-F16 -> 0 | H17: =H16 -> 17352456 | I17: =H17-H16 -> 0 | J17: =J16 -> 28335790 | K17: =J17-J16 -> 0 | L17: =L16 -> 22765718 | M17: =L17-L16 -> 0 | N17: =M17+K17+I17+G17+E17 -> 0 | O17: =IF(B17>0,N17/B17,0) -> 0 | P17: =P16 -> 15386.126 | Q17: =(P17-P16)*1000 -> 0 | R17: =N17-Q17 -> 0 | S17: =S16 -> 8384 | T17: =S17-S16 -> 0 | U17: =U16 -> 1024343 | V17: =U17-U16 -> 0 | W17: =W16 -> 31845 | X17: =W17-W16 -> 0 | Y17: =Y16 -> 624440 | Z17: =Y17-Y16 -> 0 | AA17: =AA16 -> 34982 | AB17: =AA17-AA16 -> 0 | AC17: =AC16 -> 759837 | AD17: =AC17-AC16 -> 0 | AE17: =AB17+X17+T17 -> 0 | AF17: =V17+Z17+AD17 -> 0 | AG17: =IF(AE17>0,AF17/AE17,0) -> 0 | AI17: =R17-'EDl log'!B15 -> -49601831
A18: ='General information '!F21 -> 0 | B18: =SUM(230*A18) -> 0 | C18: 43906 | D18: =D17 -> 31495768 | E18: =D18-D17 -> 0 | F18: =F17 -> 3564144.4 | G18: =F18-F17 -> 0 | H18: =H17 -> 17352456 | I18: =H18-H17 -> 0 | J18: =J17 -> 28335790 | K18: =J18-J17 -> 0 | L18: =L17 -> 22765718 | M18: =L18-L17 -> 0 | N18: =M18+K18+I18+G18+E18 -> 0 | O18: =IF(B18>0,N18/B18,0) -> 0 | P18: =P17 -> 15386.126 | Q18: =(P18-P17)*1000 -> 0 | R18: =N18-Q18 -> 0 | S18: =S17 -> 8384 | T18: =S18-S17 -> 0 | U18: =U17 -> 1024343 | V18: =U18-U17 -> 0 | W18: =W17 -> 31845 | X18: =W18-W17 -> 0 | Y18: =Y17 -> 624440 | Z18: =Y18-Y17 -> 0 | AA18: =AA17 -> 34982 | AB18: =AA18-AA17 -> 0 | AC18: =AC17 -> 759837 | AD18: =AC18-AC17 -> 0 | AE18: =AB18+X18+T18 -> 0 | AF18: =V18+Z18+AD18 -> 0 | AG18: =IF(AE18>0,AF18/AE18,0) -> 0 | AI18: =R18-'EDl log'!B16 -> -49601831
... A33: ='General information '!F36 -> 0 | B33: =SUM(230*A33) -> 0 | C33: 43921 | D33: =D32 -> 31495768 | E33: =D33-D32 -> 0 | F33: =F32 -> 3564144.4 | G33: =F33-F32 -> 0 | H33: =H32 -> 17352456 | I33: =H33-H32 -> 0 | J33: =J32 -> 28335790 | K33: =J33-J32 -> 0 | L33: =L32 -> 22765718 | M33: =L33-L32 -> 0 | N33: =M33+K33+I33+G33+E33 -> 0 | O33: =IF(B33>0,N33/B33,0) -> 0 | P33: =P32 -> 15386.126 | Q33: =(P33-P32)*1000 -> 0 | R33: =N33-Q33 -> 0 | S33: =S32 -> 8384 | T33: =S33-S32 -> 0 | U33: =U32 -> 1024343 | V33: =U33-U32 -> 0 | W33: =W32 -> 31845 | X33: =W33-W32 -> 0 | Y33: =Y32 -> 624440 | Z33: =Y33-Y32 -> 0 | AA33: =AA32 -> 34982 | AB33: =AA33-AA32 -> 0 | AC33: =AC32 -> 759837 | AD33: =AC33-AC32 -> 0 | AE33: =AB33+X33+T33 -> 0 | AF33: =V33+Z33+AD33 -> 0 | AG33: =IF(AE33>0,AF33/AE33,0) -> 0 | AI33: =R33-'EDl log'!B31 -> -49601831

Sheet B5
F1: Boiler A | J1: =J36 -> 51.888889 | K1: Boiler B | P1: Boiler C | V1: Boiler | X1: SteamA | AC1: SteamB | AH1: Steam | AI1: Boiler & steam | AL1: Total Boiler Runing H | AM1: Total Steam Runing H | AN1: GAS1 % | AO1: GAS1/L | AP1: GAS2% | AQ1: Gas2/L | AR1: GAS3% | AS1: GAS3/L | AU1: Gas Cons | AV1: Delivery | AW1: Cost/L
B2: Level Tank Gen | C2: Level tank Boiler | D2: Daily Cons Bo. | E2: Boiler litter | F2: Boiler A | G2: Run Hr a | H2: Boiler A fuel | I2: Daily consumption | J2: AVG | K2: index Run H | L2: Run Hrb | M2: Boiler B Fuel | O2: Daily consumption | P2: Boiler C | S2: Run C | U2: Total RH | V2: Total Fuel | X2: SteamA | Y2: Run SA | Z2: Steam A Conter | AA2: Liters | AC2: SteamB | AD2: Run SteamB | AE2: Steam B Conter | AF2: SB Litters | AG2: Avg | AH2: Total Fuel | AI2: Total Fuel
S3: 0
A4: =ELEC!C2 -> 43890 | B4: =[1]B5!B33 -> 233.3 | C4: =[1]B5!C33 -> 239.1 | D4: =[1]B5!D33 -> 8.9 | E4: =[1]B5!E33 -> 74.582 | F4: =[1]B5!F33 -> 1448 | G4: =[1]B5!G33 -> 1 | H4: =[1]B5!H33 -> 342051 | I4: =[1]B5!I33 -> 93 | ... AX4: =[1]B5!AX33 -> 0.7
A5: =ELEC!C3 -> 43891 | B5: 229 | C5: 234.4 | D5: =C4-C5 -> 4.7 | E5: =D5*8.38 -> 39.386 | F5: 1452 | G5: =F5-F4 -> 4 | H5: 342342 | I5: =SUM(H5-H4) -> 291 | J5: 1 | K5: 1836 | L5: =K5-K4 -> 0 | M5: 134157 | N5: =M5-M4 -> 0 | O5: =SUM(L5*$J$1) -> 0 | P5: 1680 | Q5: 143596 | R5: =Q5-Q4 -> 289 | S5: =SUM(P5-P4) -> 4 | T5: =SUM(S5*$T$2) -> 0 | U5: =SUM(G5+L5+S5) -> 8 | V5: =R5+N5+I5:I5 -> 580 | W5: =SUM(V5/U5) -> 72.5 | X5: 2392 | Y5: =X5-X4 -> 0 | Z5: 134406.8 | AA5: =Z5-Z4 -> 0 | AB5: =SUM(Y5*$AB$2) -> 0 | AC5: 1801 | AD5: =AC5-AC4 -> 0 | AE5: 357717.5 | AF5: =AE5-AE4 -> 0 | AG5: =IF(AD5>0,AF5/AD5,0) -> 0 | AH5: =AF5+AA5 -> 0 | AI5: =SUM(AH5+V5) -> 580 | AJ5: =-tanks!AW6 -> 580 | AK5: =SUM(AJ5-AI5) -> 0 | AL5: =S5+L5+G5 -> 8 | AM5: =Y5+AD5 -> 0 | AN5: 75 | AO5: =(AN5/100)*3000 -> 2250 | AP5: 75 | AQ5: =(AP5/100)*3000 -> 2250 | AR5: 76 | AS5: =(AR5/100)*3000 -> 2280 | AT5: =SUM(AO5+AQ5+AS5) -> 6780 | AU5: =AT4-AT5+AV5 -> 240.1 | AV5: 0.1 | AW5: 0.1 | AX5: =IF(AV5>0,AW5,AX4) -> 0.1
A6: =ELEC!C4 -> 43892 | B6: 224 | C6: 230 | D6: =C5-C6 -> 4.4 | E6: =D6*8.38 -> 36.872 | F6: 1456 | G6: =F6-F5 -> 4 | H6: 342630 | I6: =SUM(H6-H5) -> 288 | J6: =IF(G6>0,I6/G6,0) -> 72 | K6: 1839 | L6: =K6-K5 -> 3 | M6: 134436 | N6: =M6-M5 -> 279 | O6: =SUM(L6*$J$1) -> 155.66667 | P6: =P5 -> 1680 | Q6: =Q5 -> 143596 | R6: =Q6-Q5 -> 0 | S6: =SUM(P6-P5) -> 0 | T6: =SUM(S6*$T$2) -> 0 | U6: =SUM(G6+L6+S6) -> 7 | V6: =R6+N6+I6:I6 -> 567 | W6: =SUM(V6/U6) -> 81 | X6: =X5 -> 2392 | Y6: =X6-X5 -> 0 | Z6: =Z5 -> 134406.8 | AA6: =Z6-Z5 -> 0 | AB6: =SUM(Y6*$AB$2) -> 0 | AC6: =AC5 -> 1801 | AD6: =AC6-AC5 -> 0 | AE6: =AE5 -> 357717.5 | AF6: =AE6-AE5 -> 0 | AG6: =IF(AD6>0,AF6/AD6,0) -> 0 | AH6: =AF6+AA6 -> 0 | AI6: =SUM(AH6+V6) -> 567 | AJ6: =-tanks!AW7 -> 567 | AK6: =SUM(AJ6-AI6) -> 0 | AL6: =S6+L6+G6 -> 7 | AM6: =Y6+AD6 -> 0 | AN6: =AN5 -> 75 | AO6: =(AN6/100)*3000 -> 2250 | AP6: 74 | AQ6: =(AP6/100)*3000 -> 2220 | AR6: 75 | AS6: =(AR6/100)*3000 -> 2250 | AT6: =SUM(AO6+AQ6+AS6) -> 6720 | AU6: =AT5-AT6+AV6 -> 60 | AX6: =IF(AV6>0,AW6,AX5) -> 0.1
A7: =ELEC!C5 -> 43893 | B7: 220 | C7: 225.4 | D7: =C6-C7 -> 4.6 | E7: =D7*8.38 -> 38.548 | F7: 1459 | G7: =F7-F6 -> 3 | H7: 342878 | I7: =SUM(H7-H6) -> 248 | J7: =IF(G7>0,I7/G7,0) -> 82.666667 | K7: 1843 | L7: =K7-K6 -> 4 | M7: 134733 | N7: =M7-M6 -> 297 | O7: 1 | P7: 1680 | Q7: 143604 | R7: =Q7-Q6 -> 8 | S7: =SUM(P7-P6) -> 0 | T7: =SUM(S7*$T$2) -> 0 | U7: =SUM(G7+L7+S7) -> 7 | V7: =R7+N7+I7:I7 -> 553 | W7: =SUM(V7/U7) -> 79 | X7: 2400 | Y7: =X7-X6 -> 8 | Z7: 134915.2 | AA7: =Z7-Z6 -> 508.4 | AB7: =SUM(Y7*$AB$2) -> 0 | AC7: 1801 | AD7: =AC7-AC6 -> 0 | AE7: 357717.5 | AF7: =AE7-AE6 -> 0 | AG7: =IF(AD7>0,AF7/AD7,0) -> 0 | AH7: =AF7+AA7 -> 508.4 | AI7: =SUM(AH7+V7) -> 1061.4 | AJ7: =-tanks!AW8 -> 1061.4 | AK7: =SUM(AJ7-AI7) -> 0 | AL7: =S7+L7+G7 -> 7 | AM7: =Y7+AD7 -> 8 | AN7: 72 | AO7: =(AN7/100)*3000 -> 2160 | AP7: 74 | AQ7: =(AP7/100)*3000 -> 2220 | AR7: =AR6 -> 75 | AS7: =(AR7/100)*3000 -> 2250 | AT7: =SUM(AO7+AQ7+AS7) -> 6630 | AU7: =AT6-AT7+AV7 -> 90 | AX7: =IF(AV7>0,AW7,AX6) -> 0.1
A8: =ELEC!C6 -> 43894 | B8: 213.3 | C8: 219.2 | D8: =C7-C8 -> 6.2 | E8: =D8*8.38 -> 51.956 | F8: 1459 | G8: =F8-F7 -> 0 | H8: 342878 | I8: =SUM(H8-H7) -> 0 | J8: =IF(G8>0,I8/G8,0) -> 0 | K8: 1846 | L8: =K8-K7 -> 3 | M8: 134906 | N8: =M8-M7 -> 173 | O8: 1479 | P8: 1681 | Q8: 143671 | R8: =Q8-Q7 -> 67 | S8: =SUM(P8-P7) -> 1 | T8: =SUM(S8*$T$2) -> 0 | U8: =SUM(G8+L8+S8) -> 4 | V8: =R8+N8+I8:I8 -> 240 | W8: =SUM(V8/U8) -> 60 | X8: 2401 | Y8: =X8-X7 -> 1 | Z8: 134951.9 | AA8: =Z8-Z7 -> 36.7 | AB8: =SUM(Y8*$AB$2) -> 0 | AC8: 1801 | AD8: =AC8-AC7 -> 0 | AE8: 357717.5 | AF8: =AE8-AE7 -> 0 | AG8: =IF(AD8>0,AF8/AD8,0) -> 0 | AH8: =AF8+AA8 -> 36.7 | AI8: =SUM(AH8+V8) -> 276.7 | AJ8: =-tanks!AW9 -> 276.7 | AK8: =SUM(AJ8-AI8) -> 0 | AL8: =S8+L8+G8 -> 4 | AM8: =Y8+AD8 -> 1 | AN8: 71 | AO8: =(AN8/100)*3000 -> 2130 | AP8: 71 | AQ8: =(AP8/100)*3000 -> 2130 | AR8: 72 | AS8: =(AR8/100)*3000 -> 2160 | AT8: =SUM(AO8+AQ8+AS8) -> 6420 | AU8: =AT7-AT8+AV8 -> 210 | AX8: =IF(AV8>0,AW8,AX7) -> 0.1
A9: =ELEC!C7 -> 43895 | B9: =B8 -> 213.3 | C9: =C8 -> 219.2 | D9: =C8-C9 -> 0 | E9: =D9*8.38 -> 0 | F9: =F8 -> 1459 | G9: =F9-F8 -> 0 | H9: =H8 -> 342878 | I9: =SUM(H9-H8) -> 0 | J9: =IF(G9>0,I9/G9,0) -> 0 | K9: =K8 -> 1846 | L9: =K9-K8 -> 0 | M9: =M8 -> 134906 | N9: =M9-M8 -> 0 | O9: =SUM(L9*$J$1) -> 0 | P9: =P8 -> 1681 | Q9: =Q8 -> 143671 | R9: =Q9-Q8 -> 0 | S9: =SUM(P9-P8) -> 0 | T9: =SUM(S9*$T$2) -> 0 | U9: =SUM(G9+L9+S9) -> 0 | V9: =R9+N9+I9:I9 -> 0 | W9: =SUM(V9/U9) -> #DIV/0! | X9: =X8 -> 2401 | Y9: =X9-X8 -> 0 | Z9: =Z8 -> 134951.9 | AA9: =Z9-Z8 -> 0 | AB9: =SUM(Y9*$AB$2) -> 0 | AC9: =AC8 -> 1801 | AD9: =AC9-AC8 -> 0 | AE9: =AE8 -> 357717.5 | AF9: =AE9-AE8 -> 0 | AG9: =IF(AD9>0,AF9/AD9,0) -> 0 | AH9: =AF9+AA9 -> 0 | AI9: =SUM(AH9+V9) -> 0 | AJ9: =-tanks!AW10 -> 0 | AK9: =SUM(AJ9-AI9) -> 0 | AL9: =S9+L9+G9 -> 0 | AM9: =Y9+AD9 -> 0 | AN9: =AN8 -> 71 | AO9: =(AN9/100)*3000 -> 2130 | AP9: =AP8 -> 71 | AQ9: =(AP9/100)*3000 -> 2130 | AR9: =AR8 -> 72 | AS9: =(AR9/100)*3000 -> 2160 | AT9: =SUM(AO9+AQ9+AS9) -> 6420 | AU9: =AT8-AT9+AV9 -> 0 | AX9: =IF(AV9>0,AW9,AX8) -> 0.1
A10: =ELEC!C8 -> 43896 | B10: =B9 -> 213.3 | C10: =C9 -> 219.2 | D10: =C9-C10 -> 0 | E10: =D10*8.38 -> 0 | F10: =F9 -> 1459 | G10: =F10-F9 -> 0 | H10: =H9 -> 342878 | I10: =SUM(H10-H9) -> 0 | J10: =IF(G10>0,I10/G10,0) -> 0 | K10: =K9 -> 1846 | L10: =K10-K9 -> 0 | M10: =M9 -> 134906 | N10: =M10-M9 -> 0 | O10: =SUM(L10*$J$1) -> 0 | P10: =P9 -> 1681 | Q10: =Q9 -> 143671 | R10: =Q10-Q9 -> 0 | S10: =SUM(P10-P9) -> 0 | T10: =SUM(S10*$T$2) -> 0 | U10: =SUM(G10+L10+S10) -> 0 | V10: =R10+N10+I10:I10 -> 0 | W10: =SUM(V10/U10) -> #DIV/0! | X10: =X9 -> 2401 | Y10: =X10-X9 -> 0 | Z10: =Z9 -> 134951.9 | AA10: =Z10-Z9 -> 0 | AB10: =SUM(Y10*$AB$2) -> 0 | AC10: =AC9 -> 1801 | AD10: =AC10-AC9 -> 0 | AE10: =AE9 -> 357717.5 | AF10: =AE10-AE9 -> 0 | AG10: =IF(AD10>0,AF10/AD10,0) -> 0 | AH10: =AF10+AA10 -> 0 | AI10: =SUM(AH10+V10) -> 0 | AJ10: =-tanks!AW11 -> 0 | AK10: =SUM(AJ10-AI10) -> 0 | AL10: =S10+L10+G10 -> 0 | AM10: =Y10+AD10 -> 0 | AN10: =AN9 -> 71 | AO10: =(AN10/100)*3000 -> 2130 | AP10: =AP9 -> 71 | AQ10: =(AP10/100)*3000 -> 2130 | AR10: =AR9 -> 72 | AS10: =(AR10/100)*3000 -> 2160 | AT10: =SUM(AO10+AQ10+AS10) -> 6420 | AU10: =AT9-AT10+AV10 -> 0 | AX10: =IF(AV10>0,AW10,AX9) -> 0.1
A11: =ELEC!C9 -> 43897 | B11: =B10 -> 213.3 | C11: =C10 -> 219.2 | D11: =C10-C11 -> 0 | E11: =D11*8.38 -> 0 | F11: =F10 -> 1459 | G11: =F11-F10 -> 0 | H11: =H10 -> 342878 | I11: =SUM(H11-H10) -> 0 | J11: =IF(G11>0,I11/G11,0) -> 0 | K11: =K10 -> 1846 | L11: =K11-K10 -> 0 | M11: =M10 -> 134906 | N11: =M11-M10 -> 0 | O11: =SUM(L11*$J$1) -> 0 | P11: =P10 -> 1681 | Q11: =Q10 -> 143671 | R11: =Q11-Q10 -> 0 | S11: =SUM(P11-P10) -> 0 | T11: =SUM(S11*$T$2) -> 0 | U11: =SUM(G11+L11+S11) -> 0 | V11: =R11+N11+I11:I11 -> 0 | W11: =SUM(V11/U11) -> #DIV/0! | X11: =X10 -> 2401 | Y11: =X11-X10 -> 0 | Z11: =Z10 -> 134951.9 | AA11: =Z11-Z10 -> 0 | AB11: =SUM(Y11*$AB$2) -> 0 | AC11: =AC10 -> 1801 | AD11: =AC11-AC10 -> 0 | AE11: =AE10 -> 357717.5 | AF11: =AE11-AE10 -> 0 | AG11: =IF(AD11>0,AF11/AD11,0) -> 0 | AH11: =AF11+AA11 -> 0 | AI11: =SUM(AH11+V11) -> 0 | AJ11: =-tanks!AW12 -> 0 | AK11: =SUM(AJ11-AI11) -> 0 | AL11: =S11+L11+G11 -> 0 | AM11: =Y11+AD11 -> 0 | AN11: =AN10 -> 71 | AO11: =(AN11/100)*3000 -> 2130 | AP11: =AP10 -> 71 | AQ11: =(AP11/100)*3000 -> 2130 | AR11: =AR10 -> 72 | AS11: =(AR11/100)*3000 -> 2160 | AT11: =SUM(AO11+AQ11+AS11) -> 6420 | AU11: =AT10-AT11+AV11 -> 0 | AX11: =IF(AV11>0,AW11,AX10) -> 0.1
A12: =ELEC!C10 -> 43898 | B12: =B11 -> 213.3 | C12: =C11 -> 219.2 | D12: =C11-C12 -> 0 | E12: =D12*8.38 -> 0 | F12: =F11 -> 1459 | G12: =F12-F11 -> 0 | H12: =H11 -> 342878 | I12: =SUM(H12-H11) -> 0 | J12: =IF(G12>0,I12/G12,0) -> 0 | K12: =K11 -> 1846 | L12: =K12-K11 -> 0 | M12: =M11 -> 134906 | N12: =M12-M11 -> 0 | O12: =SUM(L12*$J$1) -> 0 | P12: =P11 -> 1681 | Q12: =Q11 -> 143671 | R12: =Q12-Q11 -> 0 | S12: =SUM(P12-P11) -> 0 | T12: =SUM(S12*$T$2) -> 0 | U12: =SUM(G12+L12+S12) -> 0 | V12: =R12+N12+I12:I12 -> 0 | W12: =SUM(V12/U12) -> #DIV/0! | X12: =X11 -> 2401 | Y12: =X12-X11 -> 0 | Z12: =Z11 -> 134951.9 | AA12: =Z12-Z11 -> 0 | AB12: =SUM(Y12*$AB$2) -> 0 | AC12: =AC11 -> 1801 | AD12: =AC12-AC11 -> 0 | AE12: =AE11 -> 357717.5 | AF12: =AE12-AE11 -> 0 | AG12: =IF(AD12>0,AF12/AD12,0) -> 0 | AH12: =AF12+AA12 -> 0 | AI12: =SUM(AH12+V12) -> 0 | AJ12: =-tanks!AW13 -> 0 | AK12: =SUM(AJ12-AI12) -> 0 | AL12: =S12+L12+G12 -> 0 | AM12: =Y12+AD12 -> 0 | AN12: =AN11 -> 71 | AO12: =(AN12/100)*3000 -> 2130 | AP12: =AP11 -> 71 | AQ12: =(AP12/100)*3000 -> 2130 | AR12: =AR11 -> 72 | AS12: =(AR12/100)*3000 -> 2160 | AT12: =SUM(AO12+AQ12+AS12) -> 6420 | AU12: =AT11-AT12+AV12 -> 0 | AX12: =IF(AV12>0,AW12,AX11) -> 0.1
A13: =ELEC!C11 -> 43899 | B13: =B12 -> 213.3 | C13: =C12 -> 219.2 | D13: =C12-C13 -> 0 | E13: =D13*8.38 -> 0 | F13: =F12 -> 1459 | G13: =F13-F12 -> 0 | H13: =H12 -> 342878 | I13: =SUM(H13-H12) -> 0 | J13: =IF(G13>0,I13/G13,0) -> 0 | K13: =K12 -> 1846 | L13: =K13-K12 -> 0 | M13: =M12 -> 134906 | N13: =M13-M12 -> 0 | O13: =SUM(L13*$J$1) -> 0 | P13: =P12 -> 1681 | Q13: =Q12 -> 143671 | R13: =Q13-Q12 -> 0 | S13: =SUM(P13-P12) -> 0 | T13: =SUM(S13*$T$2) -> 0 | U13: =SUM(G13+L13+S13) -> 0 | V13: =R13+N13+I13:I13 -> 0 | W13: =SUM(V13/U13) -> #DIV/0! | X13: =X12 -> 2401 | Y13: =X13-X12 -> 0 | Z13: =Z12 -> 134951.9 | AA13: =Z13-Z12 -> 0 | AB13: =SUM(Y13*$AB$2) -> 0 | AC13: =AC12 -> 1801 | AD13: =AC13-AC12 -> 0 | AE13: =AE12 -> 357717.5 | AF13: =AE13-AE12 -> 0 | AG13: =IF(AD13>0,AF13/AD13,0) -> 0 | AH13: =AF13+AA13 -> 0 | AI13: =SUM(AH13+V13) -> 0 | AJ13: =-tanks!AW14 -> 0 | AK13: =SUM(AJ13-AI13) -> 0 | AL13: =S13+L13+G13 -> 0 | AM13: =Y13+AD13 -> 0 | AN13: =AN12 -> 71 | AO13: =(AN13/100)*3000 -> 2130 | AP13: =AP12 -> 71 | AQ13: =(AP13/100)*3000 -> 2130 | AR13: =AR12 -> 72 | AS13: =(AR13/100)*3000 -> 2160 | AT13: =SUM(AO13+AQ13+AS13) -> 6420 | AU13: =AT12-AT13+AV13 -> 0 | AX13: =IF(AV13>0,AW13,AX12) -> 0.1
A14: =ELEC!C12 -> 43900 | B14: =B13 -> 213.3 | C14: =C13 -> 219.2 | D14: =C13-C14 -> 0 | E14: =D14*8.38 -> 0 | F14: =F13 -> 1459 | G14: =F14-F13 -> 0 | H14: =H13 -> 342878 | I14: =SUM(H14-H13) -> 0 | J14: =IF(G14>0,I14/G14,0) -> 0 | K14: =K13 -> 1846 | L14: =K14-K13 -> 0 | M14: =M13 -> 134906 | N14: =M14-M13 -> 0 | O14: =SUM(L14*$J$1) -> 0 | P14: =P13 -> 1681 | Q14: =Q13 -> 143671 | R14: =Q14-Q13 -> 0 | S14: =SUM(P14-P13) -> 0 | T14: =SUM(S14*$T$2) -> 0 | U14: =SUM(G14+L14+S14) -> 0 | V14: =R14+N14+I14:I14 -> 0 | W14: =SUM(V14/U14) -> #DIV/0! | X14: =X13 -> 2401 | Y14: =X14-X13 -> 0 | Z14: =Z13 -> 134951.9 | AA14: =Z14-Z13 -> 0 | AB14: =SUM(Y14*$AB$2) -> 0 | AC14: =AC13 -> 1801 | AD14: =AC14-AC13 -> 0 | AE14: =AE13 -> 357717.5 | AF14: =AE14-AE13 -> 0 | AG14: =IF(AD14>0,AF14/AD14,0) -> 0 | AH14: =AF14+AA14 -> 0 | AI14: =SUM(AH14+V14) -> 0 | AJ14: =-tanks!AW15 -> 0 | AK14: =SUM(AJ14-AI14) -> 0 | AL14: =S14+L14+G14 -> 0 | AM14: =Y14+AD14 -> 0 | AN14: =AN13 -> 71 | AO14: =(AN14/100)*3000 -> 2130 | AP14: =AP13 -> 71 | AQ14: =(AP14/100)*3000 -> 2130 | AR14: =AR13 -> 72 | AS14: =(AR14/100)*3000 -> 2160 | AT14: =SUM(AO14+AQ14+AS14) -> 6420 | AU14: =AT13-AT14+AV14 -> 0 | AX14: =IF(AV14>0,AW14,AX13) -> 0.1
A15: =ELEC!C13 -> 43901 | B15: =B14 -> 213.3 | C15: =C14 -> 219.2 | D15: =C14-C15 -> 0 | E15: =D15*8.38 -> 0 | F15: =F14 -> 1459 | G15: =F15-F14 -> 0 | H15: =H14 -> 342878 | I15: =SUM(H15-H14) -> 0 | J15: =IF(G15>0,I15/G15,0) -> 0 | K15: =K14 -> 1846 | L15: =K15-K14 -> 0 | M15: =M14 -> 134906 | N15: =M15-M14 -> 0 | O15: =SUM(L15*$J$1) -> 0 | P15: =P14 -> 1681 | Q15: =Q14 -> 143671 | R15: =Q15-Q14 -> 0 | S15: =SUM(P15-P14) -> 0 | T15: =SUM(S15*$T$2) -> 0 | U15: =SUM(G15+L15+S15) -> 0 | V15: =R15+N15+I15:I15 -> 0 | W15: =SUM(V15/U15) -> #DIV/0! | X15: =X14 -> 2401 | Y15: =X15-X14 -> 0 | Z15: =Z14 -> 134951.9 | AA15: =Z15-Z14 -> 0 | AB15: =SUM(Y15*$AB$2) -> 0 | AC15: =AC14 -> 1801 | AD15: =AC15-AC14 -> 0 | AE15: =AE14 -> 357717.5 | AF15: =AE15-AE14 -> 0 | AG15: =IF(AD15>0,AF15/AD15,0) -> 0 | AH15: =AF15+AA15 -> 0 | AI15: =SUM(AH15+V15) -> 0 | AJ15: =-tanks!AW16 -> 0 | AK15: =SUM(AJ15-AI15) -> 0 | AL15: =S15+L15+G15 -> 0 | AM15: =Y15+AD15 -> 0 | AN15: =AN14 -> 71 | AO15: =(AN15/100)*3000 -> 2130 | AP15: =AP14 -> 71 | AQ15: =(AP15/100)*3000 -> 2130 | AR15: =AR14 -> 72 | AS15: =(AR15/100)*3000 -> 2160 | AT15: =SUM(AO15+AQ15+AS15) -> 6420 | AU15: =AT14-AT15+AV15 -> 0 | AX15: =IF(AV15>0,AW15,AX14) -> 0.1
A16: =ELEC!C14 -> 43902 | B16: =B15 -> 213.3 | C16: =C15 -> 219.2 | D16: =C15-C16 -> 0 | E16: =D16*8.38 -> 0 | F16: =F15 -> 1459 | G16: =F16-F15 -> 0 | H16: =H15 -> 342878 | I16: =SUM(H16-H15) -> 0 | J16: =IF(G16>0,I16/G16,0) -> 0 | K16: =K15 -> 1846 | L16: =K16-K15 -> 0 | M16: =M15 -> 134906 | N16: =M16-M15 -> 0 | O16: =SUM(L16*$J$1) -> 0 | P16: =P15 -> 1681 | Q16: =Q15 -> 143671 | R16: =Q16-Q15 -> 0 | S16: =SUM(P16-P15) -> 0 | T16: =SUM(S16*$T$2) -> 0 | U16: =SUM(G16+L16+S16) -> 0 | V16: =R16+N16+I16:I16 -> 0 | W16: =SUM(V16/U16) -> #DIV/0! | X16: =X15 -> 2401 | Y16: =X16-X15 -> 0 | Z16: =Z15 -> 134951.9 | AA16: =Z16-Z15 -> 0 | AB16: =SUM(Y16*$AB$2) -> 0 | AC16: =AC15 -> 1801 | AD16: =AC16-AC15 -> 0 | AE16: =AE15 -> 357717.5 | AF16: =AE16-AE15 -> 0 | AG16: =IF(AD16>0,AF16/AD16,0) -> 0 | AH16: =AF16+AA16 -> 0 | AI16: =SUM(AH16+V16) -> 0 | AJ16: =-tanks!AW17 -> 0 | AK16: =SUM(AJ16-AI16) -> 0 | AL16: =S16+L16+G16 -> 0 | AM16: =Y16+AD16 -> 0 | AN16: =AN15 -> 71 | AO16: =(AN16/100)*3000 -> 2130 | AP16: =AP15 -> 71 | AQ16: =(AP16/100)*3000 -> 2130 | AR16: =AR15 -> 72 | AS16: =(AR16/100)*3000 -> 2160 | AT16: =SUM(AO16+AQ16+AS16) -> 6420 | AU16: =AT15-AT16+AV16 -> 0 | AX16: =IF(AV16>0,AW16,AX15) -> 0.1
A17: =ELEC!C15 -> 43903 | B17: =B16 -> 213.3 | C17: =C16 -> 219.2 | D17: =C16-C17 -> 0 | E17: =D17*8.38 -> 0 | F17: =F16 -> 1459 | G17: =F17-F16 -> 0 | H17: =H16 -> 342878 | I17: =SUM(H17-H16) -> 0 | J17: =IF(G17>0,I17/G17,0) -> 0 | K17: =K16 -> 1846 | L17: =K17-K16 -> 0 | M17: =M16 -> 134906 | N17: =M17-M16 -> 0 | O17: =SUM(L17*$J$1) -> 0 | P17: =P16 -> 1681 | Q17: =Q16 -> 143671 | R17: =Q17-Q16 -> 0 | S17: =SUM(P17-P16) -> 0 | T17: =SUM(S17*$T$2) -> 0 | U17: =SUM(G17+L17+S17) -> 0 | V17: =R17+N17+I17:I17 -> 0 | X17: =X16 -> 2401 | Y17: =X17-X16 -> 0 | Z17: =Z16 -> 134951.9 | AA17: =Z17-Z16 -> 0 | AB17: =SUM(Y17*$AB$2) -> 0 | AC17: =AC16 -> 1801 | AD17: =AC17-AC16 -> 0 | AE17: =AE16 -> 357717.5 | AF17: =AE17-AE16 -> 0 | AG17: =IF(AD17>0,AF17/AD17,0) -> 0 | AH17: =AF17+AA17 -> 0 | AI17: =SUM(AH17+V17) -> 0 | AJ17: =-tanks!AW18 -> 0 | AK17: =SUM(AJ17-AI17) -> 0 | AL17: =S17+L17+G17 -> 0 | AM17: =Y17+AD17 -> 0 | AN17: =AN16 -> 71 | AO17: =(AN17/100)*3000 -> 2130 | AP17: =AP16 -> 71 | AQ17: =(AP17/100)*3000 -> 2130 | AR17: =AR16 -> 72 | AS17: =(AR17/100)*3000 -> 2160 | AT17: =SUM(AO17+AQ17+AS17) -> 6420 | AU17: =AT16-AT17+AV17 -> 0 | AX17: =IF(AV17>0,AW17,AX16) -> 0.1
A18: =ELEC!C16 -> 43904 | B18: =B17 -> 213.3 | C18: =C17 -> 219.2 | D18: =C17-C18 -> 0 | E18: =D18*8.38 -> 0 | F18: =F17 -> 1459 | G18: =F18-F17 -> 0 | H18: =H17 -> 342878 | I18: =SUM(H18-H17) -> 0 | J18: =IF(G18>0,I18/G18,0) -> 0 | K18: =K17 -> 1846 | L18: =K18-K17 -> 0 | M18: =M17 -> 134906 | N18: =M18-M17 -> 0 | O18: =SUM(L18*$J$1) -> 0 | P18: =P17 -> 1681 | Q18: =Q17 -> 143671 | R18: =Q18-Q17 -> 0 | S18: =SUM(P18-P17) -> 0 | T18: =SUM(S18*$T$2) -> 0 | U18: =SUM(G18+L18+S18) -> 0 | V18: =R18+N18+I18:I18 -> 0 | X18: =X17 -> 2401 | Y18: =X18-X17 -> 0 | Z18: =Z17 -> 134951.9 | AA18: =Z18-Z17 -> 0 | AB18: =SUM(Y18*$AB$2) -> 0 | AC18: =AC17 -> 1801 | AD18: =AC18-AC17 -> 0 | AE18: =AE17 -> 357717.5 | AF18: =AE18-AE17 -> 0 | AG18: =IF(AD18>0,AF18/AD18,0) -> 0 | AH18: =AF18+AA18 -> 0 | AI18: =SUM(AH18+V18) -> 0 | AJ18: =-tanks!AW19 -> 0 | AK18: =SUM(AJ18-AI18) -> 0 | AL18: =S18+L18+G18 -> 0 | AM18: =Y18+AD18 -> 0 | AN18: =AN17 -> 71 | AO18: =(AN18/100)*3000 -> 2130 | AP18: =AP17 -> 71 | AQ18: =(AP18/100)*3000 -> 2130 | AR18: =AR17 -> 72 | AS18: =(AR18/100)*3000 -> 2160 | AT18: =SUM(AO18+AQ18+AS18) -> 6420 | AU18: =AT17-AT18+AV18 -> 0 | AX18: =IF(AV18>0,AW18,AX17) -> 0.1
A19: =ELEC!C17 -> 43905 | B19: =B18 -> 213.3 | C19: =C18 -> 219.2 | D19: =C18-C19 -> 0 | E19: =D19*8.38 -> 0 | F19: =F18 -> 1459 | G19: =F19-F18 -> 0 | H19: =H18 -> 342878 | I19: =SUM(H19-H18) -> 0 | J19: =IF(G19>0,I19/G19,0) -> 0 | K19: =K18 -> 1846 | L19: =K19-K18 -> 0 | M19: =M18 -> 134906 | N19: =M19-M18 -> 0 | O19: =SUM(L19*$J$1) -> 0 | P19: =P18 -> 1681 | Q19: =Q18 -> 143671 | R19: =Q19-Q18 -> 0 | S19: =SUM(P19-P18) -> 0 | T19: =SUM(S19*$T$2) -> 0 | U19: =SUM(G19+L19+S19) -> 0 | V19: =R19+N19+I19:I19 -> 0 | X19: =X18 -> 2401 | Y19: =X19-X18 -> 0 | Z19: =Z18 -> 134951.9 | AA19: =Z19-Z18 -> 0 | AB19: =SUM(Y19*$AB$2) -> 0 | AC19: =AC18 -> 1801 | AD19: =AC19-AC18 -> 0 | AE19: =AE18 -> 357717.5 | AF19: =AE19-AE18 -> 0 | AG19: =IF(AD19>0,AF19/AD19,0) -> 0 | AH19: =AF19+AA19 -> 0 | AI19: =SUM(AH19+V19) -> 0 | AJ19: =-tanks!AW20 -> 0 | AK19: =SUM(AJ19-AI19) -> 0 | AL19: =S19+L20+G19 -> 0 | AM19: =Y19+AD19 -> 0 | AN19: =AN18 -> 71 | AO19: =(AN19/100)*3000 -> 2130 | AP19: =AP18 -> 71 | AQ19: =(AP19/100)*3000 -> 2130 | AR19: =AR18 -> 72 | AS19: =(AR19/100)*3000 -> 2160 | AT19: =SUM(AO19+AQ19+AS19) -> 6420 | AU19: =AT18-AT19+AV19 -> 0 | AX19: =IF(AV19>0,AW19,AX18) -> 0.1
A20: =ELEC!C18 -> 43906 | B20: =B19 -> 213.3 | C20: =C19 -> 219.2 | D20: =C19-C20 -> 0 | E20: =D20*8.38 -> 0 | F20: =F19 -> 1459 | G20: =F20-F19 -> 0 | H20: =H19 -> 342878 | I20: =SUM(H20-H19) -> 0 | J20: =IF(G20>0,I20/G20,0) -> 0 | K20: =K19 -> 1846 | L20: =K20-K19 -> 0 | M20: =M19 -> 134906 | N20: =M20-M19 -> 0 | O20: =SUM(L20*$J$1) -> 0 | P20: =P19 -> 1681 | Q20: =Q19 -> 143671 | R20: =Q20-Q19 -> 0 | S20: =SUM(P20-P19) -> 0 | T20: =SUM(S20*$T$2) -> 0 | U20: =SUM(G20+L20+S20) -> 0 | V20: =R20+N20+I20:I20 -> 0 | X20: =X19 -> 2401 | Y20: =X20-X19 -> 0 | Z20: =Z19 -> 134951.9 | AA20: =Z20-Z19 -> 0 | AB20: =SUM(Y20*$AB$2) -> 0 | AC20: =AC19 -> 1801 | AD20: =AC20-AC19 -> 0 | AE20: =AE19 -> 357717.5 | AF20: =AE20-AE19 -> 0 | AG20: =IF(AD20>0,AF20/AD20,0) -> 0 | AH20: =AF20+AA20 -> 0 | AI20: =SUM(AH20+V20) -> 0 | AJ20: =-tanks!AW21 -> 0 | AK20: =SUM(AJ20-AI20) -> 0 | AL20: =S20+L21+G20 -> 0 | AM20: =Y20+AD20 -> 0 | AN20: =AN19 -> 71 | AO20: =(AN20/100)*3000 -> 2130 | AP20: =AP19 -> 71 | AQ20: =(AP20/100)*3000 -> 2130 | AR20: =AR19 -> 72 | AS20: =(AR20/100)*3000 -> 2160 | AT20: =SUM(AO20+AQ20+AS20) -> 6420 | AU20: =AT19-AT20+AV20 -> 0 | AX20: =IF(AV20>0,AW20,AX19) -> 0.1
A21: =ELEC!C19 -> 43907 | B21: =B20 -> 213.3 | C21: =C20 -> 219.2 | D21: =C20-C21 -> 0 | E21: =D21*8.38 -> 0 | F21: =F20 -> 1459 | G21: =F21-F20 -> 0 | H21: =H20 -> 342878 | I21: =SUM(H21-H20) -> 0 | J21: =IF(G21>0,I21/G21,0) -> 0 | K21: =K20 -> 1846 | L21: =K21-K20 -> 0 | M21: =M20 -> 134906 | N21: =M21-M20 -> 0 | O21: =SUM(L21*$J$1) -> 0 | P21: =P20 -> 1681 | Q21: =Q20 -> 143671 | R21: =Q21-Q20 -> 0 | S21: =SUM(P21-P20) -> 0 | T21: =SUM(S21*$T$2) -> 0 | U21: =SUM(G21+L21+S21) -> 0 | V21: =R21+N21+I21:I21 -> 0 | X21: =X20 -> 2401 | Y21: =X21-X20 -> 0 | Z21: =Z20 -> 134951.9 | AA21: =Z21-Z20 -> 0 | AB21: =SUM(Y21*$AB$2) -> 0 | AC21: =AC20 -> 1801 | AD21: =AC21-AC20 -> 0 | AE21: =AE20 -> 357717.5 | AF21: =AE21-AE20 -> 0 | AG21: =IF(AD21>0,AF21/AD21,0) -> 0 | AH21: =AF21+AA21 -> 0 | AI21: =SUM(AH21+V21) -> 0 | AJ21: =-tanks!AW22 -> 0 | AK21: =SUM(AJ21-AI21) -> 0 | AL21: =S21+L21+G21 -> 0 | AM21: =Y21+AD21 -> 0 | AN21: =AN20 -> 71 | AO21: =(AN21/100)*3000 -> 2130 | AP21: =AP20 -> 71 | AQ21: =(AP21/100)*3000 -> 2130 | AR21: =AR20 -> 72 | AS21: =(AR21/100)*3000 -> 2160 | AT21: =SUM(AO21+AQ21+AS21) -> 6420 | AU21: =AT20-AT21+AV21 -> 0 | AX21: =IF(AV21>0,AW21,AX20) -> 0.1
A22: =ELEC!C20 -> 43908 | B22: =B21 -> 213.3 | C22: =C21 -> 219.2 | D22: =C21-C22 -> 0 | E22: =D22*8.38 -> 0 | F22: =F21 -> 1459 | G22: =F22-F21 -> 0 | H22: =H21 -> 342878 | I22: =SUM(H22-H21) -> 0 | J22: =IF(G22>0,I22/G22,0) -> 0 | K22: =K21 -> 1846 | L22: =K22-K21 -> 0 | M22: =M21 -> 134906 | N22: =M22-M21 -> 0 | O22: =SUM(L22*$J$1) -> 0 | P22: =P21 -> 1681 | Q22: =Q21 -> 143671 | R22: =Q22-Q21 -> 0 | S22: =SUM(P22-P21) -> 0 | T22: =SUM(S22*$T$2) -> 0 | U22: =SUM(G22+L22+S22) -> 0 | V22: =R22+N22+I22:I22 -> 0 | X22: =X21 -> 2401 | Y22: =X22-X21 -> 0 | Z22: =Z21 -> 134951.9 | AA22: =Z22-Z21 -> 0 | AB22: =SUM(Y22*$AB$2) -> 0 | AC22: =AC21 -> 1801 | AD22: =AC22-AC21 -> 0 | AE22: =AE21 -> 357717.5 | AF22: =AE22-AE21 -> 0 | AG22: =IF(AD22>0,AF22/AD22,0) -> 0 | AH22: =AF22+AA22 -> 0 | AI22: =SUM(AH22+V22) -> 0 | AJ22: =-tanks!AW23 -> 0 | AK22: =SUM(AJ22-AI22) -> 0 | AL22: =S22+L22+G22 -> 0 | AM22: =Y22+AD22 -> 0 | AN22: =AN21 -> 71 | AO22: =(AN22/100)*3000 -> 2130 | AP22: =AP21 -> 71 | AQ22: =(AP22/100)*3000 -> 2130 | AR22: =AR21 -> 72 | AS22: =(AR22/100)*3000 -> 2160 | AT22: =SUM(AO22+AQ22+AS22) -> 6420 | AU22: =AT21-AT22+AV22 -> 0 | AX22: =IF(AV22>0,AW22,AX21) -> 0.1
A23: =ELEC!C21 -> 43909 | B23: =B22 -> 213.3 | C23: =C22 -> 219.2 | D23: =C22-C23 -> 0 | E23: =D23*8.38 -> 0 | F23: =F22 -> 1459 | G23: =F23-F22 -> 0 | H23: =H22 -> 342878 | I23: =SUM(H23-H22) -> 0 | J23: =IF(G23>0,I23/G23,0) -> 0 | K23: =K22 -> 1846 | L23: =K23-K22 -> 0 | M23: =M22 -> 134906 | N23: =M23-M22 -> 0 | O23: =SUM(L23*$J$1) -> 0 | P23: =P22 -> 1681 | Q23: =Q22 -> 143671 | R23: =Q23-Q22 -> 0 | S23: =SUM(P23-P22) -> 0 | T23: =SUM(S23*$T$2) -> 0 | U23: =SUM(G23+L23+S23) -> 0 | V23: =R23+N23+I23:I23 -> 0 | X23: =X22 -> 2401 | Y23: =X23-X22 -> 0 | Z23: =Z22 -> 134951.9 | AA23: =Z23-Z22 -> 0 | AB23: =SUM(Y23*$AB$2) -> 0 | AC23: =AC22 -> 1801 | AD23: =AC23-AC22 -> 0 | AE23: =AE22 -> 357717.5 | AF23: =AE23-AE22 -> 0 | AG23: =IF(AD23>0,AF23/AD23,0) -> 0 | AH23: =AF23+AA23 -> 0 | AI23: =SUM(AH23+V23) -> 0 | AJ23: =-tanks!AW24 -> 0 | AK23: =SUM(AJ23-AI23) -> 0 | AL23: =S23+L23+G23 -> 0 | AM23: =Y23+AD23 -> 0 | AN23: =AN22 -> 71 | AO23: =(AN23/100)*3000 -> 2130 | AP23: =AP22 -> 71 | AQ23: =(AP23/100)*3000 -> 2130 | AR23: =AR22 -> 72 | AS23: =(AR23/100)*3000 -> 2160 | AT23: =SUM(AO23+AQ23+AS23) -> 6420 | AU23: =AT22-AT23+AV23 -> 0 | AX23: =IF(AV23>0,AW23,AX22) -> 0.1
A24: =ELEC!C22 -> 43910 | B24: =B23 -> 213.3 | C24: =C23 -> 219.2 | D24: =C23-C24 -> 0 | E24: =D24*8.38 -> 0 | F24: =F23 -> 1459 | G24: =F24-F23 -> 0 | H24: =H23 -> 342878 | I24: =SUM(H24-H23) -> 0 | J24: =IF(G24>0,I24/G24,0) -> 0 | K24: =K23 -> 1846 | L24: =K24-K23 -> 0 | M24: =M23 -> 134906 | N24: =M24-M23 -> 0 | O24: =SUM(L24*$J$1) -> 0 | P24: =P23 -> 1681 | Q24: =Q23 -> 143671 | R24: =Q24-Q23 -> 0 | S24: =SUM(P24-P23) -> 0 | T24: =SUM(S24*$T$2) -> 0 | U24: =SUM(G24+L24+S24) -> 0 | V24: =R24+N24+I24:I24 -> 0 | X24: =X23 -> 2401 | Y24: =X24-X23 -> 0 | Z24: =Z23 -> 134951.9 | AA24: =Z24-Z23 -> 0 | AB24: =SUM(Y24*$AB$2) -> 0 | AC24: =AC23 -> 1801 | AD24: =AC24-AC23 -> 0 | AE24: =AE23 -> 357717.5 | AF24: =AE24-AE23 -> 0 | AG24: =IF(AD24>0,AF24/AD24,0) -> 0 | AH24: =AF24+AA24 -> 0 | AI24: =SUM(AH24+V24) -> 0 | AJ24: =-tanks!AW25 -> 0 | AK24: =SUM(AJ24-AI24) -> 0 | AL24: =S24+L24+G24 -> 0 | AM24: =Y24+AD24 -> 0 | AN24: =AN23 -> 71 | AO24: =(AN24/100)*3000 -> 2130 | AP24: =AP23 -> 71 | AQ24: =(AP24/100)*3000 -> 2130 | AR24: =AR23 -> 72 | AS24: =(AR24/100)*3000 -> 2160 | AT24: =SUM(AO24+AQ24+AS24) -> 6420 | AU24: =AT23-AT24+AV24 -> 0 | AX24: =IF(AV24>0,AW24,AX23) -> 0.1
A25: =ELEC!C23 -> 43911 | B25: =B24 -> 213.3 | C25: =C24 -> 219.2 | D25: =C24-C25 -> 0 | E25: =D25*8.38 -> 0 | F25: =F24 -> 1459 | G25: =F25-F24 -> 0 | H25: =H24 -> 342878 | I25: =SUM(H25-H24) -> 0 | J25: =IF(G25>0,I25/G25,0) -> 0 | K25: =K24 -> 1846 | L25: =K25-K24 -> 0 | M25: =M24 -> 134906 | N25: =M25-M24 -> 0 | O25: =SUM(L25*$J$1) -> 0 | P25: =P24 -> 1681 | Q25: =Q24 -> 143671 | R25: =Q25-Q24 -> 0 | S25: =SUM(P25-P24) -> 0 | T25: =SUM(S25*$T$2) -> 0 | U25: =SUM(G25+L25+S25) -> 0 | V25: =R25+N25+I25:I25 -> 0 | X25: =X24 -> 2401 | Y25: =X25-X24 -> 0 | Z25: =Z24 -> 134951.9 | AA25: =Z25-Z24 -> 0 | AB25: =SUM(Y25*$AB$2) -> 0 | AC25: =AC24 -> 1801 | AD25: =AC25-AC24 -> 0 | AE25: =AE24 -> 357717.5 | AF25: =AE25-AE24 -> 0 | AG25: =IF(AD25>0,AF25/AD25,0) -> 0 | AH25: =AF25+AA25 -> 0 | AI25: =SUM(AH25+V25) -> 0 | AJ25: =-tanks!AW26 -> 0 | AK25: =SUM(AJ25-AI25) -> 0 | AL25: =S25+L25+G25 -> 0 | AM25: =Y25+AD25 -> 0 | AN25: =AN24 -> 71 | AO25: =(AN25/100)*3000 -> 2130 | AP25: =AP24 -> 71 | AQ25: =(AP25/100)*3000 -> 2130 | AR25: =AR24 -> 72 | AS25: =(AR25/100)*3000 -> 2160 | AT25: =SUM(AO25+AQ25+AS25) -> 6420 | AU25: =AT24-AT25+AV25 -> 0 | AX25: =IF(AV25>0,AW25,AX24) -> 0.1
A26: =ELEC!C24 -> 43912 | B26: =B25 -> 213.3 | C26: =C25 -> 219.2 | D26: =C25-C26 -> 0 | E26: =D26*8.38 -> 0 | F26: =F25 -> 1459 | G26: =F26-F25 -> 0 | H26: =H25 -> 342878 | I26: =SUM(H26-H25) -> 0 | J26: =IF(G26>0,I26/G26,0) -> 0 | K26: =K25 -> 1846 | L26: =K26-K25 -> 0 | M26: =M25 -> 134906 | N26: =M26-M25 -> 0 | O26: =SUM(L26*$J$1) -> 0 | P26: =P25 -> 1681 | Q26: =Q25 -> 143671 | R26: =Q26-Q25 -> 0 | S26: =SUM(P26-P25) -> 0 | T26: =SUM(S26*$T$2) -> 0 | U26: =SUM(G26+L26+S26) -> 0 | V26: =R26+N26+I26:I26 -> 0 | X26: =X25 -> 2401 | Y26: =X26-X25 -> 0 | Z26: =Z25 -> 134951.9 | AA26: =Z26-Z25 -> 0 | AB26: =SUM(Y26*$AB$2) -> 0 | AC26: =AC25 -> 1801 | AD26: =AC26-AC25 -> 0 | AE26: =AE25 -> 357717.5 | AF26: =AE26-AE25 -> 0 | AG26: =IF(AD26>0,AF26/AD26,0) -> 0 | AH26: =AF26+AA26 -> 0 | AI26: =SUM(AH26+V26) -> 0 | AJ26: =-tanks!AW27 -> 0 | AK26: =SUM(AJ26-AI26) -> 0 | AL26: =S26+L26+G26 -> 0 | AM26: =Y26+AD26 -> 0 | AN26: =AN25 -> 71 | AO26: =(AN26/100)*3000 -> 2130 | AP26: =AP25 -> 71 | AQ26: =(AP26/100)*3000 -> 2130 | AR26: =AR25 -> 72 | AS26: =(AR26/100)*3000 -> 2160 | AT26: =SUM(AO26+AQ26+AS26) -> 6420 | AU26: =AT25-AT26+AV26 -> 0 | AX26: =IF(AV26>0,AW26,AX25) -> 0.1
A27: =ELEC!C25 -> 43913 | B27: =B26 -> 213.3 | C27: =C26 -> 219.2 | D27: =C26-C27 -> 0 | E27: =D27*8.38 -> 0 | F27: =F26 -> 1459 | G27: =F27-F26 -> 0 | H27: =H26 -> 342878 | I27: =SUM(H27-H26) -> 0 | J27: =IF(G27>0,I27/G27,0) -> 0 | K27: =K26 -> 1846 | L27: =K27-K26 -> 0 | M27: =M26 -> 134906 | N27: =M27-M26 -> 0 | O27: =SUM(L27*$J$1) -> 0 | P27: =P26 -> 1681 | Q27: =Q26 -> 143671 | R27: =Q27-Q26 -> 0 | S27: =SUM(P27-P26) -> 0 | T27: =SUM(S27*$T$2) -> 0 | U27: =SUM(G27+L27+S27) -> 0 | V27: =R27+N27+I27:I27 -> 0 | X27: =X26 -> 2401 | Y27: =X27-X26 -> 0 | Z27: =Z26 -> 134951.9 | AA27: =Z27-Z26 -> 0 | AB27: =SUM(Y27*$AB$2) -> 0 | AC27: =AC26 -> 1801 | AD27: =AC27-AC26 -> 0 | AE27: =AE26 -> 357717.5 | AF27: =AE27-AE26 -> 0 | AG27: =IF(AD27>0,AF27/AD27,0) -> 0 | AH27: =AF27+AA27 -> 0 | AI27: =SUM(AH27+V27) -> 0 | AJ27: =-tanks!AW28 -> 0 | AK27: =SUM(AJ27-AI27) -> 0 | AL27: =S27+L27+G27 -> 0 | AM27: =Y27+AD27 -> 0 | AN27: =AN26 -> 71 | AO27: =(AN27/100)*3000 -> 2130 | AP27: =AP26 -> 71 | AQ27: =(AP27/100)*3000 -> 2130 | AR27: =AR26 -> 72 | AS27: =(AR27/100)*3000 -> 2160 | AT27: =SUM(AO27+AQ27+AS27) -> 6420 | AU27: =AT26-AT27+AV27 -> 0 | AX27: =IF(AV27>0,AW27,AX26) -> 0.1
A28: =ELEC!C26 -> 43914 | B28: =B27 -> 213.3 | C28: =C27 -> 219.2 | D28: =C27-C28 -> 0 | E28: =D28*8.38 -> 0 | F28: =F27 -> 1459 | G28: =F28-F27 -> 0 | H28: =H27 -> 342878 | I28: =SUM(H28-H27) -> 0 | J28: =IF(G28>0,I28/G28,0) -> 0 | K28: =K27 -> 1846 | L28: =K28-K27 -> 0 | M28: =M27 -> 134906 | N28: =M28-M27 -> 0 | O28: =SUM(L28*$J$1) -> 0 | P28: =P27 -> 1681 | Q28: =Q27 -> 143671 | R28: =Q28-Q27 -> 0 | S28: =SUM(P28-P27) -> 0 | T28: =SUM(S28*$T$2) -> 0 | U28: =SUM(G28+L28+S28) -> 0 | V28: =R28+N28+I28:I28 -> 0 | X28: =X27 -> 2401 | Y28: =X28-X27 -> 0 | Z28: =Z27 -> 134951.9 | AA28: =Z28-Z27 -> 0 | AB28: =SUM(Y28*$AB$2) -> 0 | AC28: =AC27 -> 1801 | AD28: =AC28-AC27 -> 0 | AE28: =AE27 -> 357717.5 | AF28: =AE28-AE27 -> 0 | AG28: =IF(AD28>0,AF28/AD28,0) -> 0 | AH28: =AF28+AA28 -> 0 | AI28: =SUM(AH28+V28) -> 0 | AJ28: =-tanks!AW29 -> 0 | AK28: =SUM(AJ28-AI28) -> 0 | AL28: =S28+L28+G28 -> 0 | AM28: =Y28+AD28 -> 0 | AN28: =AN27 -> 71 | AO28: =(AN28/100)*3000 -> 2130 | AP28: =AP27 -> 71 | AQ28: =(AP28/100)*3000 -> 2130 | AR28: =AR27 -> 72 | AS28: =(AR28/100)*3000 -> 2160 | AT28: =SUM(AO28+AQ28+AS28) -> 6420 | AU28: =AT27-AT28+AV28 -> 0 | AX28: =IF(AV28>0,AW28,AX27) -> 0.1
A29: =ELEC!C27 -> 43915 | B29: =B28 -> 213.3 | C29: =C28 -> 219.2 | D29: =C28-C29 -> 0 | E29: =D29*8.38 -> 0 | F29: =F28 -> 1459 | G29: =F29-F28 -> 0 | H29: =H28 -> 342878 | I29: =SUM(H29-H28) -> 0 | J29: =IF(G29>0,I29/G29,0) -> 0 | K29: =K28 -> 1846 | L29: =K29-K28 -> 0 | M29: =M28 -> 134906 | N29: =M29-M28 -> 0 | O29: =SUM(L29*$J$1) -> 0 | P29: =P28 -> 1681 | Q29: =Q28 -> 143671 | R29: =Q29-Q28 -> 0 | S29: =SUM(P29-P28) -> 0 | T29: =SUM(S29*$T$2) -> 0 | U29: =SUM(G29+L29+S29) -> 0 | V29: =R29+N29+I29:I29 -> 0 | X29: =X28 -> 2401 | Y29: =X29-X28 -> 0 | Z29: =Z28 -> 134951.9 | AA29: =Z29-Z28 -> 0 | AB29: =SUM(Y29*$AB$2) -> 0 | AC29: =AC28 -> 1801 | AD29: =AC29-AC28 -> 0 | AE29: =AE28 -> 357717.5 | AF29: =AE29-AE28 -> 0 | AG29: =IF(AD29>0,AF29/AD29,0) -> 0 | AH29: =AF29+AA29 -> 0 | AI29: =SUM(AH29+V29) -> 0 | AJ29: =-tanks!AW30 -> 0 | AK29: =SUM(AJ29-AI29) -> 0 | AL29: =S29+L29+G29 -> 0 | AM29: =Y29+AD29 -> 0 | AN29: =AN28 -> 71 | AO29: =(AN29/100)*3000 -> 2130 | AP29: =AP28 -> 71 | AQ29: =(AP29/100)*3000 -> 2130 | AR29: =AR28 -> 72 | AS29: =(AR29/100)*3000 -> 2160 | AT29: =SUM(AO29+AQ29+AS29) -> 6420 | AU29: =AT28-AT29+AV29 -> 0 | AX29: =IF(AV29>0,AW29,AX28) -> 0.1
A30: =ELEC!C28 -> 43916 | B30: =B29 -> 213.3 | C30: =C29 -> 219.2 | D30: =C29-C30 -> 0 | E30: =D30*8.38 -> 0 | F30: =F29 -> 1459 | G30: =F30-F29 -> 0 | H30: =H29 -> 342878 | I30: =SUM(H30-H29) -> 0 | J30: =IF(G30>0,I30/G30,0) -> 0 | K30: =K29 -> 1846 | L30: =K30-K29 -> 0 | M30: =M29 -> 134906 | N30: =M30-M29 -> 0 | O30: =SUM(L30*$J$1) -> 0 | P30: =P29 -> 1681 | Q30: =Q29 -> 143671 | R30: =Q30-Q29 -> 0 | S30: =SUM(P30-P29) -> 0 | T30: =SUM(S30*$T$2) -> 0 | U30: =SUM(G30+L30+S30) -> 0 | V30: =R30+N30+I30:I30 -> 0 | X30: =X29 -> 2401 | Y30: =X30-X29 -> 0 | Z30: =Z29 -> 134951.9 | AA30: =Z30-Z29 -> 0 | AB30: =SUM(Y30*$AB$2) -> 0 | AC30: =AC29 -> 1801 | AD30: =AC30-AC29 -> 0 | AE30: =AE29 -> 357717.5 | AF30: =AE30-AE29 -> 0 | AG30: =IF(AD30>0,AF30/AD30,0) -> 0 | AH30: =AF30+AA30 -> 0 | AI30: =SUM(AH30+V30) -> 0 | AJ30: =-tanks!AW31 -> 0 | AK30: =SUM(AJ30-AI30) -> 0 | AL30: =S30+L30+G30 -> 0 | AM30: =Y30+AD30 -> 0 | AN30: =AN29 -> 71 | AO30: =(AN30/100)*3000 -> 2130 | AP30: =AP29 -> 71 | AQ30: =(AP30/100)*3000 -> 2130 | AR30: =AR29 -> 72 | AS30: =(AR30/100)*3000 -> 2160 | AT30: =SUM(AO30+AQ30+AS30) -> 6420 | AU30: =AT29-AT30+AV30 -> 0 | AX30: =IF(AV30>0,AW30,AX29) -> 0.1
A31: =ELEC!C29 -> 43917 | B31: =B30 -> 213.3 | C31: =C30 -> 219.2 | D31: =C30-C31 -> 0 | E31: =D31*8.38 -> 0 | F31: =F30 -> 1459 | G31: =F31-F30 -> 0 | H31: =H30 -> 342878 | I31: =SUM(H31-H30) -> 0 | J31: =IF(G31>0,I31/G31,0) -> 0 | K31: =K30 -> 1846 | L31: =K31-K30 -> 0 | M31: =M30 -> 134906 | N31: =M31-M30 -> 0 | O31: =SUM(L31*$J$1) -> 0 | P31: =P30 -> 1681 | Q31: =Q30 -> 143671 | R31: =Q31-Q30 -> 0 | S31: =SUM(P31-P30) -> 0 | T31: =SUM(S31*$T$2) -> 0 | U31: =SUM(G31+L31+S31) -> 0 | V31: =R31+N31+I31:I31 -> 0 | X31: =X30 -> 2401 | Y31: =X31-X30 -> 0 | Z31: =Z30 -> 134951.9 | AA31: =Z31-Z30 -> 0 | AB31: =SUM(Y31*$AB$2) -> 0 | AC31: =AC30 -> 1801 | AD31: =AC31-AC30 -> 0 | AE31: =AE30 -> 357717.5 | AF31: =AE31-AE30 -> 0 | AG31: =IF(AD31>0,AF31/AD31,0) -> 0 | AH31: =AF31+AA31 -> 0 | AI31: =SUM(AH31+V31) -> 0 | AJ31: =-tanks!AW32 -> 0 | AK31: =SUM(AJ31-AI31) -> 0 | AL31: =S31+L31+G31 -> 0 | AM31: =Y31+AD31 -> 0 | AN31: =AN30 -> 71 | AO31: =(AN31/100)*3000 -> 2130 | AP31: =AP30 -> 71 | AQ31: =(AP31/100)*3000 -> 2130 | AR31: =AR30 -> 72 | AS31: =(AR31/100)*3000 -> 2160 | AT31: =SUM(AO31+AQ31+AS31) -> 6420 | AU31: =AT30-AT31+AV31 -> 0 | AX31: =IF(AV31>0,AW31,AX30) -> 0.1
A32: =ELEC!C30 -> 43918 | B32: =B31 -> 213.3 | C32: =C31 -> 219.2 | D32: =C31-C32 -> 0 | E32: =D32*8.38 -> 0 | F32: =F31 -> 1459 | G32: =F32-F31 -> 0 | H32: =H31 -> 342878 | I32: =SUM(H32-H31) -> 0 | J32: =IF(G32>0,I32/G32,0) -> 0 | K32: =K31 -> 1846 | L32: =K32-K31 -> 0 | M32: =M31 -> 134906 | N32: =M32-M31 -> 0 | O32: =SUM(L32*$J$1) -> 0 | P32: =P31 -> 1681 | Q32: =Q31 -> 143671 | R32: =Q32-Q31 -> 0 | S32: =SUM(P32-P31) -> 0 | T32: =SUM(S32*$T$2) -> 0 | U32: =SUM(G32+L32+S32) -> 0 | V32: =R32+N32+I32:I32 -> 0 | X32: =X31 -> 2401 | Y32: =X32-X31 -> 0 | Z32: =Z31 -> 134951.9 | AA32: =Z32-Z31 -> 0 | AB32: =SUM(Y32*$AB$2) -> 0 | AC32: =AC31 -> 1801 | AD32: =AC32-AC31 -> 0 | AE32: =AE31 -> 357717.5 | AF32: =AE32-AE31 -> 0 | AG32: =IF(AD32>0,AF32/AD32,0) -> 0 | AH32: =AF32+AA32 -> 0 | AI32: =SUM(AH32+V32) -> 0 | AJ32: =-tanks!AW33 -> 0 | AK32: =SUM(AJ32-AI32) -> 0 | AL32: =S32+L32+G32 -> 0 | AM32: =Y32+AD32 -> 0 | AN32: =AN31 -> 71 | AO32: =(AN32/100)*3000 -> 2130 | AP32: =AP31 -> 71 | AQ32: =(AP32/100)*3000 -> 2130 | AR32: =AR31 -> 72 | AS32: =(AR32/100)*3000 -> 2160 | AT32: =SUM(AO32+AQ32+AS32) -> 6420 | AU32: =AT31-AT32+AV32 -> 0 | AX32: =IF(AV32>0,AW32,AX31) -> 0.1
... A35: =ELEC!C33 -> 43921 | B35: =B34 -> 213.3 | C35: =C34 -> 219.2 | D35: =C34-C35 -> 0 | E35: =D35*8.38 -> 0 | F35: =F34 -> 1459 | G35: =F35-F34 -> 0 | H35: =H34 -> 342878 | I35: =SUM(H35-H34) -> 0 | J35: =IF(G35>0,I35/G35,0) -> 0 | K35: =K34 -> 1846 | L35: =K35-K34 -> 0 | M35: =M34 -> 134906 | N35: =M35-M34 -> 0 | O35: =SUM(L35*$J$1) -> 0 | P35: =P34 -> 1681 | Q35: =Q34 -> 143671 | R35: =Q35-Q34 -> 0 | S35: =SUM(P35-P34) -> 0 | T35: =SUM(S35*$T$2) -> 0 | U35: =SUM(G35+L35+S35) -> 0 | V35: =R35+N35+I35:I35 -> 0 | X35: =X34 -> 2401 | Y35: =X35-X34 -> 0 | Z35: =Z34 -> 134951.9 | AA35: =Z35-Z34 -> 0 | AB35: =SUM(Y35*$AB$2) -> 0 | AC35: =AC34 -> 1801 | AD35: =AC35-AC34 -> 0 | AE35: =AE34 -> 357717.5 | AF35: =AE35-AE34 -> 0 | AG35: =IF(AD35>0,AF35/AD35,0) -> 0 | AH35: =AF35+AA35 -> 0 | AI35: =SUM(AH35+V35) -> 0 | AJ35: =-tanks!AW36 -> 0 | AK35: =SUM(AJ35-AI35) -> 0 | AL35: =S35+L35+G35 -> 0 | AM35: =Y35+AD35 -> 0 | AN35: =AN34 -> 71 | AO35: =(AN35/100)*3000 -> 2130 | AP35: =AP34 -> 71 | AQ35: =(AP35/100)*3000 -> 2130 | AR35: =AR34 -> 72 | AS35: =(AR35/100)*3000 -> 2160 | AT35: =SUM(AO35+AQ35+AS35) -> 6420 | AU35: =AT34-AT35+AV35 -> 0 | AX35: =IF(AV35>0,AW35,AX34) -> 0.1
J36: =SUM(J5:J34)/(COUNT(J5:J34)-COUNTIF(J5:J34,0)) -> 51.888889 | AE36: . | AR36: Nb Delivery | AS36: =COUNT(AW5:AW35) -> 1 | AU36: =SUM(AU5:AU35) -> 600.1 | AV36: =SUM(AV5:AV35) -> 0.1 | AW36: =SUM(AW5:AW35)/AS36 -> 0.1
AH37: =AF37+AA37 -> 0 | AI37: =SUM(AI5:AI35) -> 2485.1
AH38: =AF38+AA38 -> 0 | AU38: =AU36*0.51 -> 306.051 | AV38: =AV36/0.51 -> 0.19607843 | AW38: =SUM(AW5:AW35)/AS36 -> 0.1
AV39: =AV36*0.51 -> 0.051

Sheet WATER
D1: =SUM(G21:G35) -> 8895720 | AR1: Entrance | AT1: Tank 1 | AV1: Tank 2
AR2: Level | AW2: Quantity CM3 | AZ2: Var
A3: Date | B3: Truck | C3: Truck M3/day | D3: N0. Trucks | F3: REQ. # of trucks | G3: City | H3: City/day | I3: Total water delivery | K3: SW | L3: Cosum SW/day | M3: RO Guest/ Liter | O3: RO K&L/ Liter | Q3: TOTAL RO Production | R3: RO 1 RH | S3: RO 2 RH | T3: RO water counter | U3: RO Cons m3 | V3: Steam Boiler | W3: Steam Boiler/day | X3: Softener Guest | Y3: Guest Sotf/day | Z3: Softener K&L | AA3: K&L Soft/Day | AB3: Fire Tank Level | AC3: Fire Tank Counter | AE3: Laundry Hot Water Counter | AF3: Hot Water Cons/day | AG3: Laundry Cold Water Counter | AH3: Cold Water Cons/day | AI3: Laundry Water Total Cons | AJ3: K&L Sotf/day | AK3: Guest / day | AL3: K&L /day | AM3: Avg Outside Temp | AN3: Banquet Activity | AR3: Date | AT3: MainI | AV3: Kitchen and Laundry | AX3: Guest | AY3: Main Tank | AZ3: Kitchen and Laundry | BA3: Guest | BB3: Kitchen and Laundry | BC3: Main | BD3: Guest | BE3: Total VAR | BF3: Hotel Consumption
E4: 1.66 | AN4: Ball R | AO4: Meeting | AP4: outlet | AT4: 180 | AV4: 220 | AX4: 580 | AY4: =SUM(AT4) -> 180 | AZ4: =SUM(AV4) -> 220 | BA4: =SUM(AX4) -> 580
A5: 43890 | B5: =[1]WATER!B34 -> 108473 | C5: =[1]WATER!C34 -> 0 | D5: =[1]WATER!D34 -> 0 | E5: =[1]WATER!E34 -> 258.62069 | F5: =[1]WATER!F34 -> 0 | G5: =[1]WATER!G34 -> 592253 | H5: =[1]WATER!H34 -> 160 | I5: =[1]WATER!I34 -> 160 | ... AQ5: =[1]WATER!AQ34 -> 0 | AR5: =A5 -> 43890 | AS5: =[1]WATER!AS34 -> 0.9 | AT5: =[1]WATER!AT34 -> 93 | AU5: =[1]WATER!AU34 -> 1.1 | AV5: =[1]WATER!AV34 -> 95 | AW5: =[1]WATER!AW34 -> 2.9 | AX5: =[1]WATER!AX34 -> 68 | AY5: =[1]WATER!AY34 -> 83.7 | AZ5: =[1]WATER!AZ34 -> 104.5 | ... BG5: =[1]WATER!BG34 -> 68.8
