Workbook

Sheet TOTAL
A1: Site Name | B1: Day | C1: Month | D1: Year | E1: Total Electricity Kwh | F1: Electricity Tariff ($/Kwh) | G1: Natual Gas (m3) | H1: Natural Gas $/m3 | I1: Water Utility Supply (m3) m3 | J1: Water Utility Supply (m3) $/m3 | K1: Room Nights | L1: Total Guests
A2: London at Park Lane | B2: 1 | C2: 3 | D2: 2020 | E2: =Submetering!E2+Submetering!F2+Submetering!G2 -> 16631 | F2: =((Submetering!F2+Submetering!E2)*0.1088+Submetering!G2*0.0302)/(Submetering!E2+Submetering!F2+Submetering!G2) -> 0.089956984 | G2: =Submetering!AC2 -> 2437 | H2: 0.255129 | I2: =Submetering!Y2+Submetering!Z2 -> 1264 | J2: 2.3196173 | K2: =Submetering!AE2 -> 113 | L2: =Submetering!AF2 -> 149
A3: London at Park Lane | B3: =B2+1 -> 2 | C3: 3 | D3: 2020 | E3: =Submetering!E3+Submetering!F3+Submetering!G3 -> 16375 | F3: =((Submetering!F3+Submetering!E3)*0.1088+Submetering!G3*0.0302)/(Submetering!E3+Submetering!F3+Submetering!G3) -> 0.0905312 | G3: =Submetering!AC3 -> 2193 | H3: 0.255129 | I3: =Submetering!Y3+Submetering!Z3 -> 0 | J3: 2.3196173 | K3: =Submetering!AE3 -> 127 | L3: =Submetering!AF3 -> 155
A4: London at Park Lane | B4: =B3+1 -> 3 | C4: 3 | D4: 2020 | E4: =Submetering!E4+Submetering!F4+Submetering!G4 -> 17238 | F4: =((Submetering!F4+Submetering!E4)*0.1088+Submetering!G4*0.0302)/(Submetering!E4+Submetering!F4+Submetering!G4) -> 0.090661538 | G4: =Submetering!AC4 -> 2432 | H4: 0.255129 | I4: =Submetering!Y4+Submetering!Z4 -> 0 | J4: 2.3196173 | K4: =Submetering!AE4 -> 122 | L4: =Submetering!AF4 -> 152
A5: London at Park Lane | B5: =B4+1 -> 4 | C5: 3 | D5: 2020 | E5: =Submetering!E5+Submetering!F5+Submetering!G5 -> 17491 | F5: =((Submetering!F5+Submetering!E5)*0.1088+Submetering!G5*0.0302)/(Submetering!E5+Submetering!F5+Submetering!G5) -> 0.091054222 | G5: =Submetering!AC5 -> 2414 | H5: 0.255129 | I5: =Submetering!Y5+Submetering!Z5 -> 0 | J5: 2.3196173 | K5: =Submetering!AE5 -> 90 | L5: =Submetering!AF5 -> 121
A6: London at Park Lane | B6: =B5+1 -> 5 | C6: 3 | D6: 2020 | E6: =Submetering!E6+Submetering!F6+Submetering!G6 -> 17121 | F6: =((Submetering!F6+Submetering!E6)*0.1088+Submetering!G6*0.0302)/(Submetering!E6+Submetering!F6+Submetering!G6) -> 0.090739583 | G6: =Submetering!AC6 -> 2383 | H6: 0.255129 | I6: =Submetering!Y6+Submetering!Z6 -> 0 | J6: 2.3196173 | K6: =Submetering!AE6 -> 70 | L6: =Submetering!AF6 -> 97
A7: London at Park Lane | B7: =B6+1 -> 6 | C7: 3 | D7: 2020 | E7: =Submetering!E7+Submetering!F7+Submetering!G7 -> 16626 | F7: =((Submetering!F7+Submetering!E7)*0.1088+Submetering!G7*0.0302)/(Submetering!E7+Submetering!F7+Submetering!G7) -> 0.08998441 | G7: =Submetering!AC7 -> 2504 | H7: 0.255129 | I7: =Submetering!Y7+Submetering!Z7 -> 0 | J7: 2.3196173 | K7: =Submetering!AE7 -> 71 | L7: =Submetering!AF7 -> 104
A8: London at Park Lane | B8: =B7+1 -> 7 | C8: 3 | D8: 2020 | E8: =Submetering!E8+Submetering!F8+Submetering!G8 -> 16635 | F8: =((Submetering!F8+Submetering!E8)*0.1088+Submetering!G8*0.0302)/(Submetering!E8+Submetering!F8+Submetering!G8) -> 0.090136339 | G8: =Submetering!AC8 -> 2500 | H8: 0.255129 | I8: =Submetering!Y8+Submetering!Z8 -> 0 | J8: 2.3196173 | K8: =Submetering!AE8 -> 79 | L8: =Submetering!AF8 -> 120
A9: London at Park Lane | B9: =B8+1 -> 8 | C9: 3 | D9: 2020 | E9: =Submetering!E9+Submetering!F9+Submetering!G9 -> 16239 | F9: =((Submetering!F9+Submetering!E9)*0.1088+Submetering!G9*0.0302)/(Submetering!E9+Submetering!F9+Submetering!G9) -> 0.089531166 | G9: =Submetering!AC9 -> 2346 | H9: 0.255129 | I9: =Submetering!Y9+Submetering!Z9 -> 0 | J9: 2.3196173 | K9: =Submetering!AE9 -> 56 | L9: =Submetering!AF9 -> 87
A10: London at Park Lane | B10: =B9+1 -> 9 | C10: 3 | D10: 2020 | E10: =Submetering!E10+Submetering!F10+Submetering!G10 -> 16401 | F10: =((Submetering!F10+Submetering!E10)*0.1088+Submetering!G10*0.0302)/(Submetering!E10+Submetering!F10+Submetering!G10) -> 0.090282202 | G10: =Submetering!AC10 -> 1861 | H10: 0.255129 | I10: =Submetering!Y10+Submetering!Z10 -> 0 | J10: 2.3196173 | K10: =Submetering!AE10 -> 69 | L10: =Submetering!AF10 -> 105
A11: London at Park Lane | B11: =B10+1 -> 10 | C11: 3 | D11: 2020 | E11: =Submetering!E11+Submetering!F11+Submetering!G11 -> 16992 | F11: =((Submetering!F11+Submetering!E11)*0.1088+Submetering!G11*0.0302)/(Submetering!E11+Submetering!F11+Submetering!G11) -> 0.090468326 | G11: =Submetering!AC11 -> 2193 | H11: 0.255129 | I11: =Submetering!Y11+Submetering!Z11 -> 0 | J11: 2.3196173 | K11: =Submetering!AE11 -> 59 | L11: =Submetering!AF11 -> 91
A12: London at Park Lane | B12: =B11+1 -> 11 | C12: 3 | D12: 2020 | E12: =Submetering!E12+Submetering!F12+Submetering!G12 -> 17254 | F12: =((Submetering!F12+Submetering!E12)*0.1088+Submetering!G12*0.0302)/(Submetering!E12+Submetering!F12+Submetering!G12) -> 0.09103824 | G12: =Submetering!AC12 -> 2052 | H12: 0.255129 | I12: =Submetering!Y12+Submetering!Z12 -> 0 | J12: 2.3196173 | K12: =Submetering!AE12 -> 37 | L12: =Submetering!AF12 -> 58
A13: London at Park Lane | B13: =B12+1 -> 12 | C13: 3 | D13: 2020 | E13: =Submetering!E13+Submetering!F13+Submetering!G13 -> 16481 | F13: =((Submetering!F13+Submetering!E13)*0.1088+Submetering!G13*0.0302)/(Submetering!E13+Submetering!F13+Submetering!G13) -> 0.090119325 | G13: =Submetering!AC13 -> 2068 | H13: 0.255129 | I13: =Submetering!Y13+Submetering!Z13 -> 0 | J13: 2.3196173 | K13: =Submetering!AE13 -> 44 | L13: =Submetering!AF13 -> 71
A14: London at Park Lane | B14: =B13+1 -> 13 | C14: 3 | D14: 2020 | E14: =Submetering!E14+Submetering!F14+Submetering!G14 -> 15864 | F14: =((Submetering!F14+Submetering!E14)*0.1088+Submetering!G14*0.0302)/(Submetering!E14+Submetering!F14+Submetering!G14) -> 0.089422504 | G14: =Submetering!AC14 -> 2175 | H14: 0.255129 | I14: =Submetering!Y14+Submetering!Z14 -> 913 | J14: 2.3196173 | K14: =Submetering!AE14 -> 40 | L14: =Submetering!AF14 -> 61
... A32: London at Park Lane | B32: =B31+1 -> 31 | C32: 3 | D32: 2020 | E32: =Submetering!E32+Submetering!F32+Submetering!G32 -> 0 | F32: =((Submetering!F32+Submetering!E32)*0.1088+Submetering!G32*0.0302)/(Submetering!E32+Submetering!F32+Submetering!G32) -> #DIV/0! | G32: =Submetering!AC32 -> 0 | H32: 0.255129 | I32: =Submetering!Y32+Submetering!Z32 -> 0 | J32: 2.3196173 | K32: =Submetering!AE32 -> 0 | L32: =Submetering!AF32 -> 0

Sheet Submetering
A1: Site Name | B1: Day | C1: Month | D1: Year | E1: LV Panel 1 KWh | F1: LV Panel 2 KWh | G1: CHP KWh | H1: MCC9 KWh | I1: GF Panel KWh | J1: Kitchen Switch. KWh | K1: Kitchen Panel KWh | L1: MCC3 (AHU) KWh | M1: MCC8 KWh | N1: 1st Floor Plan (KWh) | O1: MCC6(1st floor AHU) KWh | P1: Chiller 1 KWh | Q1: Chiller 2 KWh | R1: MCC 10 (Mechanical Services) KWh | S1: MCC2 CHW KWh | T1: MCC7 (Kitchen) KWh | U1: MCC 5 (Mechanical services) KWh | V1: MCC 4 (Water Services) KWh | W1: MCC1 (KWh) | X1: Laundry db KWh | Y1: City Water 1 m3 | Z1: City Water 2 m3 | AA1: Laundry CW m3 | AB1: Laundry HW m3 | AC1: Natural Gas m3 | AD1: CHP Natural Gas m3 | AE1: Room Nights | AF1: Total Guests
A2: London at Park Lane | B2: 1 | C2: 3 | D2: 2020 | E2: =IF(('FSLPL Daily '!C4-'FSLPL Daily '!C3<0), "0",'FSLPL Daily '!C4-'FSLPL Daily '!C3) -> 6271 | F2: =IF(('FSLPL Daily '!E4-'FSLPL Daily '!E3<0), "0",'FSLPL Daily '!E4-'FSLPL Daily '!E3) -> 6373 | G2: =IF(('FSLPL Daily '!G4-'FSLPL Daily '!G3<0), "0",'FSLPL Daily '!G4-'FSLPL Daily '!G3) -> 3987 | H2: =IF(('FSLPL Daily '!I4-'FSLPL Daily '!I3<0), "0",'FSLPL Daily '!I4-'FSLPL Daily '!I3) -> 485 | I2: =IF(('FSLPL Daily '!K4-'FSLPL Daily '!K3<0), "0",'FSLPL Daily '!K4-'FSLPL Daily '!K3) -> 788 | J2: =IF(('FSLPL Daily '!M4-'FSLPL Daily '!M3<0), "0",'FSLPL Daily '!M4-'FSLPL Daily '!M3) -> 1182 | K2: =IF(('FSLPL Daily '!O4-'FSLPL Daily '!O3<0), "0",'FSLPL Daily '!O4-'FSLPL Daily '!O3) -> 559 | L2: =IF(('FSLPL Daily '!Q4-'FSLPL Daily '!Q3<0), "0",'FSLPL Daily '!Q4-'FSLPL Daily '!Q3) -> 323 | M2: =IF(('FSLPL Daily '!S4-'FSLPL Daily '!S3<0), "0",'FSLPL Daily '!S4-'FSLPL Daily '!S3) -> 74 | N2: =IF(('FSLPL Daily '!U4-'FSLPL Daily '!U3<0), "0",'FSLPL Daily '!U4-'FSLPL Daily '!U3) -> 869 | O2: =IF(('FSLPL Daily '!W4-'FSLPL Daily '!W3<0), "0",'FSLPL Daily '!W4-'FSLPL Daily '!W3) -> 100 | P2: =IF(('FSLPL Daily '!Y4-'FSLPL Daily '!Y3<0), "0",'FSLPL Daily '!Y4-'FSLPL Daily '!Y3) -> 4 | Q2: =IF(('FSLPL Daily '!AA4-'FSLPL Daily '!AA3<0), "0",'FSLPL Daily '!AA4-'FSLPL Daily '!AA3) -> 756 | R2: =IF(('FSLPL Daily '!AC4-'FSLPL Daily '!AC3<0), "0",'FSLPL Daily '!AC4-'FSLPL Daily '!AC3) -> 1378 | S2: =IF(('FSLPL Daily '!AE4-'FSLPL Daily '!AE3<0), "0",'FSLPL Daily '!AE4-'FSLPL Daily '!AE3) -> 1931 | T2: =IF(('FSLPL Daily '!AG4-'FSLPL Daily '!AG3<0), "0",'FSLPL Daily '!AG4-'FSLPL Daily '!AG3) -> 231 | U2: =IF(('FSLPL Daily '!AI4-'FSLPL Daily '!AI3<0), "0",'FSLPL Daily '!AI4-'FSLPL Daily '!AI3) -> 68 | V2: =IF(('FSLPL Daily '!AK4-'FSLPL Daily '!AK3<0), "0",'FSLPL Daily '!AK4-'FSLPL Daily '!AK3) -> 332 | W2: =IF(('FSLPL Daily '!AM4-'FSLPL Daily '!AM3<0), "0",'FSLPL Daily '!AM4-'FSLPL Daily '!AM3) -> 585 | X2: =IF(('FSLPL Daily '!AO4-'FSLPL Daily '!AO3<0), "0",'FSLPL Daily '!AO4-'FSLPL Daily '!AO3) -> 662 | Y2: ='FSLPL Daily '!AS4 -> 359 | Z2: ='FSLPL Daily '!AU4 -> 905 | AA2: =IF(('FSLPL Daily '!AV4-'FSLPL Daily '!AV3<0), "0",'FSLPL Daily '!AV4-'FSLPL Daily '!AV3) -> 20 | AB2: =IF(('FSLPL Daily '!AX4-'FSLPL Daily '!AX3<0), "0",'FSLPL Daily '!AX4-'FSLPL Daily '!AX3) -> 3 | AC2: =IF(('FSLPL Daily '!AZ4-'FSLPL Daily '!AZ3<0), "0",'FSLPL Daily '!AZ4-'FSLPL Daily '!AZ3) -> 2437 | AD2: =IF(('FSLPL Daily '!BB4-'FSLPL Daily '!BB3<0), "0",'FSLPL Daily '!BB4-'FSLPL Daily '!BB3) -> 1160 | AE2: ='FSLPL Daily '!BD4 -> 113 | AF2: ='FSLPL Daily '!BE4 -> 149
A3: London at Park Lane | B3: =B2+1 -> 2 | C3: 3 | D3: 2020 | E3: =IF(('FSLPL Daily '!C5-'FSLPL Daily '!C4<0), "0",'FSLPL Daily '!C5-'FSLPL Daily '!C4) -> 6479 | F3: =IF(('FSLPL Daily '!E5-'FSLPL Daily '!E4<0), "0",'FSLPL Daily '!E5-'FSLPL Daily '!E4) -> 6090 | G3: =IF(('FSLPL Daily '!G5-'FSLPL Daily '!G4<0), "0",'FSLPL Daily '!G5-'FSLPL Daily '!G4) -> 3806 | H3: =IF(('FSLPL Daily '!I5-'FSLPL Daily '!I4<0), "0",'FSLPL Daily '!I5-'FSLPL Daily '!I4) -> 506 | I3: =IF(('FSLPL Daily '!K5-'FSLPL Daily '!K4<0), "0",'FSLPL Daily '!K5-'FSLPL Daily '!K4) -> 783 | J3: =IF(('FSLPL Daily '!M5-'FSLPL Daily '!M4<0), "0",'FSLPL Daily '!M5-'FSLPL Daily '!M4) -> 1319 | K3: =IF(('FSLPL Daily '!O5-'FSLPL Daily '!O4<0), "0",'FSLPL Daily '!O5-'FSLPL Daily '!O4) -> 594 | L3: =IF(('FSLPL Daily '!Q5-'FSLPL Daily '!Q4<0), "0",'FSLPL Daily '!Q5-'FSLPL Daily '!Q4) -> 294 | M3: =IF(('FSLPL Daily '!S5-'FSLPL Daily '!S4<0), "0",'FSLPL Daily '!S5-'FSLPL Daily '!S4) -> 39 | N3: =IF(('FSLPL Daily '!U5-'FSLPL Daily '!U4<0), "0",'FSLPL Daily '!U5-'FSLPL Daily '!U4) -> 879 | O3: =IF(('FSLPL Daily '!W5-'FSLPL Daily '!W4<0), "0",'FSLPL Daily '!W5-'FSLPL Daily '!W4) -> 12 | P3: =IF(('FSLPL Daily '!Y5-'FSLPL Daily '!Y4<0), "0",'FSLPL Daily '!Y5-'FSLPL Daily '!Y4) -> 133 | Q3: =IF(('FSLPL Daily '!AA5-'FSLPL Daily '!AA4<0), "0",'FSLPL Daily '!AA5-'FSLPL Daily '!AA4) -> 1094 | R3: =IF(('FSLPL Daily '!AC5-'FSLPL Daily '!AC4<0), "0",'FSLPL Daily '!AC5-'FSLPL Daily '!AC4) -> 1377 | S3: =IF(('FSLPL Daily '!AE5-'FSLPL Daily '!AE4<0), "0",'FSLPL Daily '!AE5-'FSLPL Daily '!AE4) -> 1432 | T3: =IF(('FSLPL Daily '!AG5-'FSLPL Daily '!AG4<0), "0",'FSLPL Daily '!AG5-'FSLPL Daily '!AG4) -> 223 | U3: =IF(('FSLPL Daily '!AI5-'FSLPL Daily '!AI4<0), "0",'FSLPL Daily '!AI5-'FSLPL Daily '!AI4) -> 19 | V3: =IF(('FSLPL Daily '!AK5-'FSLPL Daily '!AK4<0), "0",'FSLPL Daily '!AK5-'FSLPL Daily '!AK4) -> 339 | W3: =IF(('FSLPL Daily '!AM5-'FSLPL Daily '!AM4<0), "0",'FSLPL Daily '!AM5-'FSLPL Daily '!AM4) -> 585 | X3: =IF(('FSLPL Daily '!AO5-'FSLPL Daily '!AO4<0), "0",'FSLPL Daily '!AO5-'FSLPL Daily '!AO4) -> 583 | Y3: ='FSLPL Daily '!AS5 -> 0 | Z3: ='FSLPL Daily '!AU5 -> 0 | AA3: =IF(('FSLPL Daily '!AV5-'FSLPL Daily '!AV4<0), "0",'FSLPL Daily '!AV5-'FSLPL Daily '!AV4) -> 17 | AB3: =IF(('FSLPL Daily '!AX5-'FSLPL Daily '!AX4<0), "0",'FSLPL Daily '!AX5-'FSLPL Daily '!AX4) -> 2 | AC3: =IF(('FSLPL Daily '!AZ5-'FSLPL Daily '!AZ4<0), "0",'FSLPL Daily '!AZ5-'FSLPL Daily '!AZ4) -> 2193 | AD3: =IF(('FSLPL Daily '!BB5-'FSLPL Daily '!BB4<0), "0",'FSLPL Daily '!BB5-'FSLPL Daily '!BB4) -> 1103 | AE3: ='FSLPL Daily '!BD5 -> 127 | AF3: ='FSLPL Daily '!BE5 -> 155
A4: London at Park Lane | B4: =B3+1 -> 3 | C4: 3 | D4: 2020 | E4: =IF(('FSLPL Daily '!C6-'FSLPL Daily '!C5<0), "0",'FSLPL Daily '!C6-'FSLPL Daily '!C5) -> 8137 | F4: =IF(('FSLPL Daily '!E6-'FSLPL Daily '!E5<0), "0",'FSLPL Daily '!E6-'FSLPL Daily '!E5) -> 5123 | G4: =IF(('FSLPL Daily '!G6-'FSLPL Daily '!G5<0), "0",'FSLPL Daily '!G6-'FSLPL Daily '!G5) -> 3978 | H4: =IF(('FSLPL Daily '!I6-'FSLPL Daily '!I5<0), "0",'FSLPL Daily '!I6-'FSLPL Daily '!I5) -> 483 | I4: =IF(('FSLPL Daily '!K6-'FSLPL Daily '!K5<0), "0",'FSLPL Daily '!K6-'FSLPL Daily '!K5) -> 832 | J4: =IF(('FSLPL Daily '!M6-'FSLPL Daily '!M5<0), "0",'FSLPL Daily '!M6-'FSLPL Daily '!M5) -> 1427 | K4: =IF(('FSLPL Daily '!O6-'FSLPL Daily '!O5<0), "0",'FSLPL Daily '!O6-'FSLPL Daily '!O5) -> 613 | L4: =IF(('FSLPL Daily '!Q6-'FSLPL Daily '!Q5<0), "0",'FSLPL Daily '!Q6-'FSLPL Daily '!Q5) -> 314 | M4: =IF(('FSLPL Daily '!S6-'FSLPL Daily '!S5<0), "0",'FSLPL Daily '!S6-'FSLPL Daily '!S5) -> 59 | N4: =IF(('FSLPL Daily '!U6-'FSLPL Daily '!U5<0), "0",'FSLPL Daily '!U6-'FSLPL Daily '!U5) -> 1266 | O4: =IF(('FSLPL Daily '!W6-'FSLPL Daily '!W5<0), "0",'FSLPL Daily '!W6-'FSLPL Daily '!W5) -> 295 | P4: =IF(('FSLPL Daily '!Y6-'FSLPL Daily '!Y5<0), "0",'FSLPL Daily '!Y6-'FSLPL Daily '!Y5) -> 845 | Q4: =IF(('FSLPL Daily '!AA6-'FSLPL Daily '!AA5<0), "0",'FSLPL Daily '!AA6-'FSLPL Daily '!AA5) -> 87 | R4: =IF(('FSLPL Daily '!AC6-'FSLPL Daily '!AC5<0), "0",'FSLPL Daily '!AC6-'FSLPL Daily '!AC5) -> 1420 | S4: =IF(('FSLPL Daily '!AE6-'FSLPL Daily '!AE5<0), "0",'FSLPL Daily '!AE6-'FSLPL Daily '!AE5) -> 1760 | T4: =IF(('FSLPL Daily '!AG6-'FSLPL Daily '!AG5<0), "0",'FSLPL Daily '!AG6-'FSLPL Daily '!AG5) -> 228 | U4: =IF(('FSLPL Daily '!AI6-'FSLPL Daily '!AI5<0), "0",'FSLPL Daily '!AI6-'FSLPL Daily '!AI5) -> 20 | V4: =IF(('FSLPL Daily '!AK6-'FSLPL Daily '!AK5<0), "0",'FSLPL Daily '!AK6-'FSLPL Daily '!AK5) -> 351 | W4: =IF(('FSLPL Daily '!AM6-'FSLPL Daily '!AM5<0), "0",'FSLPL Daily '!AM6-'FSLPL Daily '!AM5) -> 578 | X4: =IF(('FSLPL Daily '!AO6-'FSLPL Daily '!AO5<0), "0",'FSLPL Daily '!AO6-'FSLPL Daily '!AO5) -> 630 | Y4: ='FSLPL Daily '!AS6 -> 0 | Z4: ='FSLPL Daily '!AU6 -> 0 | AA4: =IF(('FSLPL Daily '!AV6-'FSLPL Daily '!AV5<0), "0",'FSLPL Daily '!AV6-'FSLPL Daily '!AV5) -> 22 | AB4: =IF(('FSLPL Daily '!AX6-'FSLPL Daily '!AX5<0), "0",'FSLPL Daily '!AX6-'FSLPL Daily '!AX5) -> 3 | AC4: =IF(('FSLPL Daily '!AZ6-'FSLPL Daily '!AZ5<0), "0",'FSLPL Daily '!AZ6-'FSLPL Daily '!AZ5) -> 2432 | AD4: =IF(('FSLPL Daily '!BB6-'FSLPL Daily '!BB5<0), "0",'FSLPL Daily '!BB6-'FSLPL Daily '!BB5) -> 1148 | AE4: ='FSLPL Daily '!BD6 -> 122 | AF4: ='FSLPL Daily '!BE6 -> 152
A5: London at Park Lane | B5: =B4+1 -> 4 | C5: 3 | D5: 2020 | E5: =IF(('FSLPL Daily '!C7-'FSLPL Daily '!C6<0), "0",'FSLPL Daily '!C7-'FSLPL Daily '!C6) -> 8223 | F5: =IF(('FSLPL Daily '!E7-'FSLPL Daily '!E6<0), "0",'FSLPL Daily '!E7-'FSLPL Daily '!E6) -> 5319 | G5: =IF(('FSLPL Daily '!G7-'FSLPL Daily '!G6<0), "0",'FSLPL Daily '!G7-'FSLPL Daily '!G6) -> 3949 | H5: =IF(('FSLPL Daily '!I7-'FSLPL Daily '!I6<0), "0",'FSLPL Daily '!I7-'FSLPL Daily '!I6) -> 500 | I5: =IF(('FSLPL Daily '!K7-'FSLPL Daily '!K6<0), "0",'FSLPL Daily '!K7-'FSLPL Daily '!K6) -> 848 | J5: =IF(('FSLPL Daily '!M7-'FSLPL Daily '!M6<0), "0",'FSLPL Daily '!M7-'FSLPL Daily '!M6) -> 1399 | K5: =IF(('FSLPL Daily '!O7-'FSLPL Daily '!O6<0), "0",'FSLPL Daily '!O7-'FSLPL Daily '!O6) -> 620 | L5: =IF(('FSLPL Daily '!Q7-'FSLPL Daily '!Q6<0), "0",'FSLPL Daily '!Q7-'FSLPL Daily '!Q6) -> 355 | M5: =IF(('FSLPL Daily '!S7-'FSLPL Daily '!S6<0), "0",'FSLPL Daily '!S7-'FSLPL Daily '!S6) -> 85 | N5: =IF(('FSLPL Daily '!U7-'FSLPL Daily '!U6<0), "0",'FSLPL Daily '!U7-'FSLPL Daily '!U6) -> 1129 | O5: =IF(('FSLPL Daily '!W7-'FSLPL Daily '!W6<0), "0",'FSLPL Daily '!W7-'FSLPL Daily '!W6) -> 256 | P5: =IF(('FSLPL Daily '!Y7-'FSLPL Daily '!Y6<0), "0",'FSLPL Daily '!Y7-'FSLPL Daily '!Y6) -> 1039 | Q5: =IF(('FSLPL Daily '!AA7-'FSLPL Daily '!AA6<0), "0",'FSLPL Daily '!AA7-'FSLPL Daily '!AA6) -> 2 | R5: =IF(('FSLPL Daily '!AC7-'FSLPL Daily '!AC6<0), "0",'FSLPL Daily '!AC7-'FSLPL Daily '!AC6) -> 1391 | S5: =IF(('FSLPL Daily '!AE7-'FSLPL Daily '!AE6<0), "0",'FSLPL Daily '!AE7-'FSLPL Daily '!AE6) -> 1992 | T5: =IF(('FSLPL Daily '!AG7-'FSLPL Daily '!AG6<0), "0",'FSLPL Daily '!AG7-'FSLPL Daily '!AG6) -> 229 | U5: =IF(('FSLPL Daily '!AI7-'FSLPL Daily '!AI6<0), "0",'FSLPL Daily '!AI7-'FSLPL Daily '!AI6) -> 20 | V5: =IF(('FSLPL Daily '!AK7-'FSLPL Daily '!AK6<0), "0",'FSLPL Daily '!AK7-'FSLPL Daily '!AK6) -> 361 | W5: =IF(('FSLPL Daily '!AM7-'FSLPL Daily '!AM6<0), "0",'FSLPL Daily '!AM7-'FSLPL Daily '!AM6) -> 612 | X5: =IF(('FSLPL Daily '!AO7-'FSLPL Daily '!AO6<0), "0",'FSLPL Daily '!AO7-'FSLPL Daily '!AO6) -> 644 | Y5: ='FSLPL Daily '!AS7 -> 0 | Z5: ='FSLPL Daily '!AU7 -> 0 | AA5: =IF(('FSLPL Daily '!AV7-'FSLPL Daily '!AV6<0), "0",'FSLPL Daily '!AV7-'FSLPL Daily '!AV6) -> 20 | AB5: =IF(('FSLPL Daily '!AX7-'FSLPL Daily '!AX6<0), "0",'FSLPL Daily '!AX7-'FSLPL Daily '!AX6) -> 2 | AC5: =IF(('FSLPL Daily '!AZ7-'FSLPL Daily '!AZ6<0), "0",'FSLPL Daily '!AZ7-'FSLPL Daily '!AZ6) -> 2414 | AD5: =IF(('FSLPL Daily '!BB7-'FSLPL Daily '!BB6<0), "0",'FSLPL Daily '!BB7-'FSLPL Daily '!BB6) -> 1130 | AE5: ='FSLPL Daily '!BD7 -> 90 | AF5: ='FSLPL Daily '!BE7 -> 121
A6: London at Park Lane | B6: =B5+1 -> 5 | C6: 3 | D6: 2020 | E6: =IF(('FSLPL Daily '!C8-'FSLPL Daily '!C7<0), "0",'FSLPL Daily '!C8-'FSLPL Daily '!C7) -> 7947 | F6: =IF(('FSLPL Daily '!E8-'FSLPL Daily '!E7<0), "0",'FSLPL Daily '!E8-'FSLPL Daily '!E7) -> 5240 | G6: =IF(('FSLPL Daily '!G8-'FSLPL Daily '!G7<0), "0",'FSLPL Daily '!G8-'FSLPL Daily '!G7) -> 3934 | H6: =IF(('FSLPL Daily '!I8-'FSLPL Daily '!I7<0), "0",'FSLPL Daily '!I8-'FSLPL Daily '!I7) -> 500 | I6: =IF(('FSLPL Daily '!K8-'FSLPL Daily '!K7<0), "0",'FSLPL Daily '!K8-'FSLPL Daily '!K7) -> 819 | J6: =IF(('FSLPL Daily '!M8-'FSLPL Daily '!M7<0), "0",'FSLPL Daily '!M8-'FSLPL Daily '!M7) -> 1278 | K6: =IF(('FSLPL Daily '!O8-'FSLPL Daily '!O7<0), "0",'FSLPL Daily '!O8-'FSLPL Daily '!O7) -> 633 | L6: =IF(('FSLPL Daily '!Q8-'FSLPL Daily '!Q7<0), "0",'FSLPL Daily '!Q8-'FSLPL Daily '!Q7) -> 323 | M6: =IF(('FSLPL Daily '!S8-'FSLPL Daily '!S7<0), "0",'FSLPL Daily '!S8-'FSLPL Daily '!S7) -> 85 | N6: =IF(('FSLPL Daily '!U8-'FSLPL Daily '!U7<0), "0",'FSLPL Daily '!U8-'FSLPL Daily '!U7) -> 1079 | O6: =IF(('FSLPL Daily '!W8-'FSLPL Daily '!W7<0), "0",'FSLPL Daily '!W8-'FSLPL Daily '!W7) -> 244 | P6: =IF(('FSLPL Daily '!Y8-'FSLPL Daily '!Y7<0), "0",'FSLPL Daily '!Y8-'FSLPL Daily '!Y7) -> 1051 | Q6: =IF(('FSLPL Daily '!AA8-'FSLPL Daily '!AA7<0), "0",'FSLPL Daily '!AA8-'FSLPL Daily '!AA7) -> 2 | R6: =IF(('FSLPL Daily '!AC8-'FSLPL Daily '!AC7<0), "0",'FSLPL Daily '!AC8-'FSLPL Daily '!AC7) -> 1395 | S6: =IF(('FSLPL Daily '!AE8-'FSLPL Daily '!AE7<0), "0",'FSLPL Daily '!AE8-'FSLPL Daily '!AE7) -> 1983 | T6: =IF(('FSLPL Daily '!AG8-'FSLPL Daily '!AG7<0), "0",'FSLPL Daily '!AG8-'FSLPL Daily '!AG7) -> 226 | U6: =IF(('FSLPL Daily '!AI8-'FSLPL Daily '!AI7<0), "0",'FSLPL Daily '!AI8-'FSLPL Daily '!AI7) -> 20 | V6: =IF(('FSLPL Daily '!AK8-'FSLPL Daily '!AK7<0), "0",'FSLPL Daily '!AK8-'FSLPL Daily '!AK7) -> 329 | W6: =IF(('FSLPL Daily '!AM8-'FSLPL Daily '!AM7<0), "0",'FSLPL Daily '!AM8-'FSLPL Daily '!AM7) -> 607 | X6: =IF(('FSLPL Daily '!AO8-'FSLPL Daily '!AO7<0), "0",'FSLPL Daily '!AO8-'FSLPL Daily '!AO7) -> 587 | Y6: ='FSLPL Daily '!AS8 -> 0 | Z6: ='FSLPL Daily '!AU8 -> 0 | AA6: =IF(('FSLPL Daily '!AV8-'FSLPL Daily '!AV7<0), "0",'FSLPL Daily '!AV8-'FSLPL Daily '!AV7) -> 18 | AB6: =IF(('FSLPL Daily '!AX8-'FSLPL Daily '!AX7<0), "0",'FSLPL Daily '!AX8-'FSLPL Daily '!AX7) -> 3 | AC6: =IF(('FSLPL Daily '!AZ8-'FSLPL Daily '!AZ7<0), "0",'FSLPL Daily '!AZ8-'FSLPL Daily '!AZ7) -> 2383 | AD6: =IF(('FSLPL Daily '!BB8-'FSLPL Daily '!BB7<0), "0",'FSLPL Daily '!BB8-'FSLPL Daily '!BB7) -> 1124 | AE6: ='FSLPL Daily '!BD8 -> 70 | AF6: ='FSLPL Daily '!BE8 -> 97
A7: London at Park Lane | B7: =B6+1 -> 6 | C7: 3 | D7: 2020 | E7: =IF(('FSLPL Daily '!C9-'FSLPL Daily '!C8<0), "0",'FSLPL Daily '!C9-'FSLPL Daily '!C8) -> 7428 | F7: =IF(('FSLPL Daily '!E9-'FSLPL Daily '!E8<0), "0",'FSLPL Daily '!E9-'FSLPL Daily '!E8) -> 5218 | G7: =IF(('FSLPL Daily '!G9-'FSLPL Daily '!G8<0), "0",'FSLPL Daily '!G9-'FSLPL Daily '!G8) -> 3980 | H7: =IF(('FSLPL Daily '!I9-'FSLPL Daily '!I8<0), "0",'FSLPL Daily '!I9-'FSLPL Daily '!I8) -> 494 | I7: =IF(('FSLPL Daily '!K9-'FSLPL Daily '!K8<0), "0",'FSLPL Daily '!K9-'FSLPL Daily '!K8) -> 811 | J7: =IF(('FSLPL Daily '!M9-'FSLPL Daily '!M8<0), "0",'FSLPL Daily '!M9-'FSLPL Daily '!M8) -> 1239 | K7: =IF(('FSLPL Daily '!O9-'FSLPL Daily '!O8<0), "0",'FSLPL Daily '!O9-'FSLPL Daily '!O8) -> 538 | L7: =IF(('FSLPL Daily '!Q9-'FSLPL Daily '!Q8<0), "0",'FSLPL Daily '!Q9-'FSLPL Daily '!Q8) -> 318 | M7: =IF(('FSLPL Daily '!S9-'FSLPL Daily '!S8<0), "0",'FSLPL Daily '!S9-'FSLPL Daily '!S8) -> 85 | N7: =IF(('FSLPL Daily '!U9-'FSLPL Daily '!U8<0), "0",'FSLPL Daily '!U9-'FSLPL Daily '!U8) -> 979 | O7: =IF(('FSLPL Daily '!W9-'FSLPL Daily '!W8<0), "0",'FSLPL Daily '!W9-'FSLPL Daily '!W8) -> 123 | P7: =IF(('FSLPL Daily '!Y9-'FSLPL Daily '!Y8<0), "0",'FSLPL Daily '!Y9-'FSLPL Daily '!Y8) -> 973 | Q7: =IF(('FSLPL Daily '!AA9-'FSLPL Daily '!AA8<0), "0",'FSLPL Daily '!AA9-'FSLPL Daily '!AA8) -> 3 | R7: =IF(('FSLPL Daily '!AC9-'FSLPL Daily '!AC8<0), "0",'FSLPL Daily '!AC9-'FSLPL Daily '!AC8) -> 1420 | S7: =IF(('FSLPL Daily '!AE9-'FSLPL Daily '!AE8<0), "0",'FSLPL Daily '!AE9-'FSLPL Daily '!AE8) -> 1983 | T7: =IF(('FSLPL Daily '!AG9-'FSLPL Daily '!AG8<0), "0",'FSLPL Daily '!AG9-'FSLPL Daily '!AG8) -> 224 | U7: =IF(('FSLPL Daily '!AI9-'FSLPL Daily '!AI8<0), "0",'FSLPL Daily '!AI9-'FSLPL Daily '!AI8) -> 20 | V7: =IF(('FSLPL Daily '!AK9-'FSLPL Daily '!AK8<0), "0",'FSLPL Daily '!AK9-'FSLPL Daily '!AK8) -> 316 | W7: =IF(('FSLPL Daily '!AM9-'FSLPL Daily '!AM8<0), "0",'FSLPL Daily '!AM9-'FSLPL Daily '!AM8) -> 608 | X7: =IF(('FSLPL Daily '!AO9-'FSLPL Daily '!AO8<0), "0",'FSLPL Daily '!AO9-'FSLPL Daily '!AO8) -> 618 | Y7: ='FSLPL Daily '!AS9 -> 0 | Z7: ='FSLPL Daily '!AU9 -> 0 | AA7: =IF(('FSLPL Daily '!AV9-'FSLPL Daily '!AV8<0), "0",'FSLPL Daily '!AV9-'FSLPL Daily '!AV8) -> 17 | AB7: =IF(('FSLPL Daily '!AX9-'FSLPL Daily '!AX8<0), "0",'FSLPL Daily '!AX9-'FSLPL Daily '!AX8) -> 2 | AC7: =IF(('FSLPL Daily '!AZ9-'FSLPL Daily '!AZ8<0), "0",'FSLPL Daily '!AZ9-'FSLPL Daily '!AZ8) -> 2504 | AD7: =IF(('FSLPL Daily '!BB9-'FSLPL Daily '!BB8<0), "0",'FSLPL Daily '!BB9-'FSLPL Daily '!BB8) -> 1143 | AE7: ='FSLPL Daily '!BD9 -> 71 | AF7: ='FSLPL Daily '!BE9 -> 104
A8: London at Park Lane | B8: =B7+1 -> 7 | C8: 3 | D8: 2020 | E8: =IF(('FSLPL Daily '!C10-'FSLPL Daily '!C9<0), "0",'FSLPL Daily '!C10-'FSLPL Daily '!C9) -> 7531 | F8: =IF(('FSLPL Daily '!E10-'FSLPL Daily '!E9<0), "0",'FSLPL Daily '!E10-'FSLPL Daily '!E9) -> 5154 | G8: =IF(('FSLPL Daily '!G10-'FSLPL Daily '!G9<0), "0",'FSLPL Daily '!G10-'FSLPL Daily '!G9) -> 3950 | H8: =IF(('FSLPL Daily '!I10-'FSLPL Daily '!I9<0), "0",'FSLPL Daily '!I10-'FSLPL Daily '!I9) -> 499 | I8: =IF(('FSLPL Daily '!K10-'FSLPL Daily '!K9<0), "0",'FSLPL Daily '!K10-'FSLPL Daily '!K9) -> 822 | J8: =IF(('FSLPL Daily '!M10-'FSLPL Daily '!M9<0), "0",'FSLPL Daily '!M10-'FSLPL Daily '!M9) -> 1153 | K8: =IF(('FSLPL Daily '!O10-'FSLPL Daily '!O9<0), "0",'FSLPL Daily '!O10-'FSLPL Daily '!O9) -> 559 | L8: =IF(('FSLPL Daily '!Q10-'FSLPL Daily '!Q9<0), "0",'FSLPL Daily '!Q10-'FSLPL Daily '!Q9) -> 328 | M8: =IF(('FSLPL Daily '!S10-'FSLPL Daily '!S9<0), "0",'FSLPL Daily '!S10-'FSLPL Daily '!S9) -> 86 | N8: =IF(('FSLPL Daily '!U10-'FSLPL Daily '!U9<0), "0",'FSLPL Daily '!U10-'FSLPL Daily '!U9) -> 1015 | O8: =IF(('FSLPL Daily '!W10-'FSLPL Daily '!W9<0), "0",'FSLPL Daily '!W10-'FSLPL Daily '!W9) -> 132 | P8: =IF(('FSLPL Daily '!Y10-'FSLPL Daily '!Y9<0), "0",'FSLPL Daily '!Y10-'FSLPL Daily '!Y9) -> 1111 | Q8: =IF(('FSLPL Daily '!AA10-'FSLPL Daily '!AA9<0), "0",'FSLPL Daily '!AA10-'FSLPL Daily '!AA9) -> 2 | R8: =IF(('FSLPL Daily '!AC10-'FSLPL Daily '!AC9<0), "0",'FSLPL Daily '!AC10-'FSLPL Daily '!AC9) -> 1452 | S8: =IF(('FSLPL Daily '!AE10-'FSLPL Daily '!AE9<0), "0",'FSLPL Daily '!AE10-'FSLPL Daily '!AE9) -> 2055 | T8: =IF(('FSLPL Daily '!AG10-'FSLPL Daily '!AG9<0), "0",'FSLPL Daily '!AG10-'FSLPL Daily '!AG9) -> 234 | U8: =IF(('FSLPL Daily '!AI10-'FSLPL Daily '!AI9<0), "0",'FSLPL Daily '!AI10-'FSLPL Daily '!AI9) -> 21 | V8: =IF(('FSLPL Daily '!AK10-'FSLPL Daily '!AK9<0), "0",'FSLPL Daily '!AK10-'FSLPL Daily '!AK9) -> 327 | W8: =IF(('FSLPL Daily '!AM10-'FSLPL Daily '!AM9<0), "0",'FSLPL Daily '!AM10-'FSLPL Daily '!AM9) -> 613 | X8: =IF(('FSLPL Daily '!AO10-'FSLPL Daily '!AO9<0), "0",'FSLPL Daily '!AO10-'FSLPL Daily '!AO9) -> 589 | Y8: ='FSLPL Daily '!AS10 -> 0 | Z8: ='FSLPL Daily '!AU10 -> 0 | AA8: =IF(('FSLPL Daily '!AV10-'FSLPL Daily '!AV9<0), "0",'FSLPL Daily '!AV10-'FSLPL Daily '!AV9) -> 20 | AB8: =IF(('FSLPL Daily '!AX10-'FSLPL Daily '!AX9<0), "0",'FSLPL Daily '!AX10-'FSLPL Daily '!AX9) -> 2 | AC8: =IF(('FSLPL Daily '!AZ10-'FSLPL Daily '!AZ9<0), "0",'FSLPL Daily '!AZ10-'FSLPL Daily '!AZ9) -> 2500 | AD8: =IF(('FSLPL Daily '!BB10-'FSLPL Daily '!BB9<0), "0",'FSLPL Daily '!BB10-'FSLPL Daily '!BB9) -> 1110 | AE8: ='FSLPL Daily '!BD10 -> 79 | AF8: ='FSLPL Daily '!BE10 -> 120
A9: London at Park Lane | B9: =B8+1 -> 8 | C9: 3 | D9: 2020 | E9: =IF(('FSLPL Daily '!C11-'FSLPL Daily '!C10<0), "0",'FSLPL Daily '!C11-'FSLPL Daily '!C10) -> 7406 | F9: =IF(('FSLPL Daily '!E11-'FSLPL Daily '!E10<0), "0",'FSLPL Daily '!E11-'FSLPL Daily '!E10) -> 4852 | G9: =IF(('FSLPL Daily '!G11-'FSLPL Daily '!G10<0), "0",'FSLPL Daily '!G11-'FSLPL Daily '!G10) -> 3981 | H9: =IF(('FSLPL Daily '!I11-'FSLPL Daily '!I10<0), "0",'FSLPL Daily '!I11-'FSLPL Daily '!I10) -> 502 | I9: =IF(('FSLPL Daily '!K11-'FSLPL Daily '!K10<0), "0",'FSLPL Daily '!K11-'FSLPL Daily '!K10) -> 774 | J9: =IF(('FSLPL Daily '!M11-'FSLPL Daily '!M10<0), "0",'FSLPL Daily '!M11-'FSLPL Daily '!M10) -> 1675 | K9: =IF(('FSLPL Daily '!O11-'FSLPL Daily '!O10<0), "0",'FSLPL Daily '!O11-'FSLPL Daily '!O10) -> 519 | L9: =IF(('FSLPL Daily '!Q11-'FSLPL Daily '!Q10<0), "0",'FSLPL Daily '!Q11-'FSLPL Daily '!Q10) -> 302 | M9: =IF(('FSLPL Daily '!S11-'FSLPL Daily '!S10<0), "0",'FSLPL Daily '!S11-'FSLPL Daily '!S10) -> 84 | N9: =IF(('FSLPL Daily '!U11-'FSLPL Daily '!U10<0), "0",'FSLPL Daily '!U11-'FSLPL Daily '!U10) -> 968 | O9: =IF(('FSLPL Daily '!W11-'FSLPL Daily '!W10<0), "0",'FSLPL Daily '!W11-'FSLPL Daily '!W10) -> 225 | P9: =IF(('FSLPL Daily '!Y11-'FSLPL Daily '!Y10<0), "0",'FSLPL Daily '!Y11-'FSLPL Daily '!Y10) -> 1134 | Q9: =IF(('FSLPL Daily '!AA11-'FSLPL Daily '!AA10<0), "0",'FSLPL Daily '!AA11-'FSLPL Daily '!AA10) -> 2 | R9: =IF(('FSLPL Daily '!AC11-'FSLPL Daily '!AC10<0), "0",'FSLPL Daily '!AC11-'FSLPL Daily '!AC10) -> 1388 | S9: =IF(('FSLPL Daily '!AE11-'FSLPL Daily '!AE10<0), "0",'FSLPL Daily '!AE11-'FSLPL Daily '!AE10) -> 1959 | T9: =IF(('FSLPL Daily '!AG11-'FSLPL Daily '!AG10<0), "0",'FSLPL Daily '!AG11-'FSLPL Daily '!AG10) -> 220 | U9: =IF(('FSLPL Daily '!AI11-'FSLPL Daily '!AI10<0), "0",'FSLPL Daily '!AI11-'FSLPL Daily '!AI10) -> 20 | V9: =IF(('FSLPL Daily '!AK11-'FSLPL Daily '!AK10<0), "0",'FSLPL Daily '!AK11-'FSLPL Daily '!AK10) -> 307 | W9: =IF(('FSLPL Daily '!AM11-'FSLPL Daily '!AM10<0), "0",'FSLPL Daily '!AM11-'FSLPL Daily '!AM10) -> 580 | X9: =IF(('FSLPL Daily '!AO11-'FSLPL Daily '!AO10<0), "0",'FSLPL Daily '!AO11-'FSLPL Daily '!AO10) -> 558 | Y9: ='FSLPL Daily '!AS11 -> 0 | Z9: ='FSLPL Daily '!AU11 -> 0 | AA9: =IF(('FSLPL Daily '!AV11-'FSLPL Daily '!AV10<0), "0",'FSLPL Daily '!AV11-'FSLPL Daily '!AV10) -> 11 | AB9: =IF(('FSLPL Daily '!AX11-'FSLPL Daily '!AX10<0), "0",'FSLPL Daily '!AX11-'FSLPL Daily '!AX10) -> 3 | AC9: =IF(('FSLPL Daily '!AZ11-'FSLPL Daily '!AZ10<0), "0",'FSLPL Daily '!AZ11-'FSLPL Daily '!AZ10) -> 2346 | AD9: =IF(('FSLPL Daily '!BB11-'FSLPL Daily '!BB10<0), "0",'FSLPL Daily '!BB11-'FSLPL Daily '!BB10) -> 1000 | AE9: ='FSLPL Daily '!BD11 -> 56 | AF9: ='FSLPL Daily '!BE11 -> 87
A10: London at Park Lane | B10: =B9+1 -> 9 | C10: 3 | D10: 2020 | E10: =IF(('FSLPL Daily '!C12-'FSLPL Daily '!C11<0), "0",'FSLPL Daily '!C12-'FSLPL Daily '!C11) -> 7801 | F10: =IF(('FSLPL Daily '!E12-'FSLPL Daily '!E11<0), "0",'FSLPL Daily '!E12-'FSLPL Daily '!E11) -> 4736 | G10: =IF(('FSLPL Daily '!G12-'FSLPL Daily '!G11<0), "0",'FSLPL Daily '!G12-'FSLPL Daily '!G11) -> 3864 | H10: =IF(('FSLPL Daily '!I12-'FSLPL Daily '!I11<0), "0",'FSLPL Daily '!I12-'FSLPL Daily '!I11) -> 508 | I10: =IF(('FSLPL Daily '!K12-'FSLPL Daily '!K11<0), "0",'FSLPL Daily '!K12-'FSLPL Daily '!K11) -> 800 | J10: =IF(('FSLPL Daily '!M12-'FSLPL Daily '!M11<0), "0",'FSLPL Daily '!M12-'FSLPL Daily '!M11) -> 694 | K10: =IF(('FSLPL Daily '!O12-'FSLPL Daily '!O11<0), "0",'FSLPL Daily '!O12-'FSLPL Daily '!O11) -> 560 | L10: =IF(('FSLPL Daily '!Q12-'FSLPL Daily '!Q11<0), "0",'FSLPL Daily '!Q12-'FSLPL Daily '!Q11) -> 308 | M10: =IF(('FSLPL Daily '!S12-'FSLPL Daily '!S11<0), "0",'FSLPL Daily '!S12-'FSLPL Daily '!S11) -> 84 | N10: =IF(('FSLPL Daily '!U12-'FSLPL Daily '!U11<0), "0",'FSLPL Daily '!U12-'FSLPL Daily '!U11) -> 1001 | O10: =IF(('FSLPL Daily '!W12-'FSLPL Daily '!W11<0), "0",'FSLPL Daily '!W12-'FSLPL Daily '!W11) -> 263 | P10: =IF(('FSLPL Daily '!Y12-'FSLPL Daily '!Y11<0), "0",'FSLPL Daily '!Y12-'FSLPL Daily '!Y11) -> 1192 | Q10: =IF(('FSLPL Daily '!AA12-'FSLPL Daily '!AA11<0), "0",'FSLPL Daily '!AA12-'FSLPL Daily '!AA11) -> 2 | R10: =IF(('FSLPL Daily '!AC12-'FSLPL Daily '!AC11<0), "0",'FSLPL Daily '!AC12-'FSLPL Daily '!AC11) -> 1403 | S10: =IF(('FSLPL Daily '!AE12-'FSLPL Daily '!AE11<0), "0",'FSLPL Daily '!AE12-'FSLPL Daily '!AE11) -> 1973 | T10: =IF(('FSLPL Daily '!AG12-'FSLPL Daily '!AG11<0), "0",'FSLPL Daily '!AG12-'FSLPL Daily '!AG11) -> 221 | U10: =IF(('FSLPL Daily '!AI12-'FSLPL Daily '!AI11<0), "0",'FSLPL Daily '!AI12-'FSLPL Daily '!AI11) -> 20 | V10: =IF(('FSLPL Daily '!AK12-'FSLPL Daily '!AK11<0), "0",'FSLPL Daily '!AK12-'FSLPL Daily '!AK11) -> 319 | W10: =IF(('FSLPL Daily '!AM12-'FSLPL Daily '!AM11<0), "0",'FSLPL Daily '!AM12-'FSLPL Daily '!AM11) -> 586 | X10: =IF(('FSLPL Daily '!AO12-'FSLPL Daily '!AO11<0), "0",'FSLPL Daily '!AO12-'FSLPL Daily '!AO11) -> 580 | Y10: ='FSLPL Daily '!AS12 -> 0 | Z10: ='FSLPL Daily '!AU12 -> 0 | AA10: =IF(('FSLPL Daily '!AV12-'FSLPL Daily '!AV11<0), "0",'FSLPL Daily '!AV12-'FSLPL Daily '!AV11) -> 14 | AB10: =IF(('FSLPL Daily '!AX12-'FSLPL Daily '!AX11<0), "0",'FSLPL Daily '!AX12-'FSLPL Daily '!AX11) -> 1 | AC10: =IF(('FSLPL Daily '!AZ12-'FSLPL Daily '!AZ11<0), "0",'FSLPL Daily '!AZ12-'FSLPL Daily '!AZ11) -> 1861 | AD10: =IF(('FSLPL Daily '!BB12-'FSLPL Daily '!BB11<0), "0",'FSLPL Daily '!BB12-'FSLPL Daily '!BB11) -> 1242 | AE10: ='FSLPL Daily '!BD12 -> 69 | AF10: ='FSLPL Daily '!BE12 -> 105
A11: London at Park Lane | B11: =B10+1 -> 10 | C11: 3 | D11: 2020 | E11: =IF(('FSLPL Daily '!C13-'FSLPL Daily '!C12<0), "0",'FSLPL Daily '!C13-'FSLPL Daily '!C12) -> 7980 | F11: =IF(('FSLPL Daily '!E13-'FSLPL Daily '!E12<0), "0",'FSLPL Daily '!E13-'FSLPL Daily '!E12) -> 5049 | G11: =IF(('FSLPL Daily '!G13-'FSLPL Daily '!G12<0), "0",'FSLPL Daily '!G13-'FSLPL Daily '!G12) -> 3963 | H11: =IF(('FSLPL Daily '!I13-'FSLPL Daily '!I12<0), "0",'FSLPL Daily '!I13-'FSLPL Daily '!I12) -> 490 | I11: =IF(('FSLPL Daily '!K13-'FSLPL Daily '!K12<0), "0",'FSLPL Daily '!K13-'FSLPL Daily '!K12) -> 830 | J11: =IF(('FSLPL Daily '!M13-'FSLPL Daily '!M12<0), "0",'FSLPL Daily '!M13-'FSLPL Daily '!M12) -> 1139 | K11: =IF(('FSLPL Daily '!O13-'FSLPL Daily '!O12<0), "0",'FSLPL Daily '!O13-'FSLPL Daily '!O12) -> 532 | L11: =IF(('FSLPL Daily '!Q13-'FSLPL Daily '!Q12<0), "0",'FSLPL Daily '!Q13-'FSLPL Daily '!Q12) -> 316 | M11: =IF(('FSLPL Daily '!S13-'FSLPL Daily '!S12<0), "0",'FSLPL Daily '!S13-'FSLPL Daily '!S12) -> 87 | N11: =IF(('FSLPL Daily '!U13-'FSLPL Daily '!U12<0), "0",'FSLPL Daily '!U13-'FSLPL Daily '!U12) -> 1316 | O11: =IF(('FSLPL Daily '!W13-'FSLPL Daily '!W12<0), "0",'FSLPL Daily '!W13-'FSLPL Daily '!W12) -> 300 | P11: =IF(('FSLPL Daily '!Y13-'FSLPL Daily '!Y12<0), "0",'FSLPL Daily '!Y13-'FSLPL Daily '!Y12) -> 1193 | Q11: =IF(('FSLPL Daily '!AA13-'FSLPL Daily '!AA12<0), "0",'FSLPL Daily '!AA13-'FSLPL Daily '!AA12) -> 3 | R11: =IF(('FSLPL Daily '!AC13-'FSLPL Daily '!AC12<0), "0",'FSLPL Daily '!AC13-'FSLPL Daily '!AC12) -> 1417 | S11: =IF(('FSLPL Daily '!AE13-'FSLPL Daily '!AE12<0), "0",'FSLPL Daily '!AE13-'FSLPL Daily '!AE12) -> 1989 | T11: =IF(('FSLPL Daily '!AG13-'FSLPL Daily '!AG12<0), "0",'FSLPL Daily '!AG13-'FSLPL Daily '!AG12) -> 263 | U11: =IF(('FSLPL Daily '!AI13-'FSLPL Daily '!AI12<0), "0",'FSLPL Daily '!AI13-'FSLPL Daily '!AI12) -> 21 | V11: =IF(('FSLPL Daily '!AK13-'FSLPL Daily '!AK12<0), "0",'FSLPL Daily '!AK13-'FSLPL Daily '!AK12) -> 318 | W11: =IF(('FSLPL Daily '!AM13-'FSLPL Daily '!AM12<0), "0",'FSLPL Daily '!AM13-'FSLPL Daily '!AM12) -> 595 | X11: =IF(('FSLPL Daily '!AO13-'FSLPL Daily '!AO12<0), "0",'FSLPL Daily '!AO13-'FSLPL Daily '!AO12) -> 566 | Y11: ='FSLPL Daily '!AS13 -> 0 | Z11: ='FSLPL Daily '!AU13 -> 0 | AA11: =IF(('FSLPL Daily '!AV13-'FSLPL Daily '!AV12<0), "0",'FSLPL Daily '!AV13-'FSLPL Daily '!AV12) -> 19 | AB11: =IF(('FSLPL Daily '!AX13-'FSLPL Daily '!AX12<0), "0",'FSLPL Daily '!AX13-'FSLPL Daily '!AX12) -> 2 | AC11: =IF(('FSLPL Daily '!AZ13-'FSLPL Daily '!AZ12<0), "0",'FSLPL Daily '!AZ13-'FSLPL Daily '!AZ12) -> 2193 | AD11: =IF(('FSLPL Daily '!BB13-'FSLPL Daily '!BB12<0), "0",'FSLPL Daily '!BB13-'FSLPL Daily '!BB12) -> 1129 | AE11: ='FSLPL Daily '!BD13 -> 59 | AF11: ='FSLPL Daily '!BE13 -> 91
A12: London at Park Lane | B12: =B11+1 -> 11 | C12: 3 | D12: 2020 | E12: =IF(('FSLPL Daily '!C14-'FSLPL Daily '!C13<0), "0",'FSLPL Daily '!C14-'FSLPL Daily '!C13) -> 8280 | F12: =IF(('FSLPL Daily '!E14-'FSLPL Daily '!E13<0), "0",'FSLPL Daily '!E14-'FSLPL Daily '!E13) -> 5075 | G12: =IF(('FSLPL Daily '!G14-'FSLPL Daily '!G13<0), "0",'FSLPL Daily '!G14-'FSLPL Daily '!G13) -> 3899 | H12: =IF(('FSLPL Daily '!I14-'FSLPL Daily '!I13<0), "0",'FSLPL Daily '!I14-'FSLPL Daily '!I13) -> 459 | I12: =IF(('FSLPL Daily '!K14-'FSLPL Daily '!K13<0), "0",'FSLPL Daily '!K14-'FSLPL Daily '!K13) -> 801 | J12: =IF(('FSLPL Daily '!M14-'FSLPL Daily '!M13<0), "0",'FSLPL Daily '!M14-'FSLPL Daily '!M13) -> 1314 | K12: =IF(('FSLPL Daily '!O14-'FSLPL Daily '!O13<0), "0",'FSLPL Daily '!O14-'FSLPL Daily '!O13) -> 609 | L12: =IF(('FSLPL Daily '!Q14-'FSLPL Daily '!Q13<0), "0",'FSLPL Daily '!Q14-'FSLPL Daily '!Q13) -> 339 | M12: =IF(('FSLPL Daily '!S14-'FSLPL Daily '!S13<0), "0",'FSLPL Daily '!S14-'FSLPL Daily '!S13) -> 82 | N12: =IF(('FSLPL Daily '!U14-'FSLPL Daily '!U13<0), "0",'FSLPL Daily '!U14-'FSLPL Daily '!U13) -> 1142 | O12: =IF(('FSLPL Daily '!W14-'FSLPL Daily '!W13<0), "0",'FSLPL Daily '!W14-'FSLPL Daily '!W13) -> 334 | P12: =IF(('FSLPL Daily '!Y14-'FSLPL Daily '!Y13<0), "0",'FSLPL Daily '!Y14-'FSLPL Daily '!Y13) -> 1347 | Q12: =IF(('FSLPL Daily '!AA14-'FSLPL Daily '!AA13<0), "0",'FSLPL Daily '!AA14-'FSLPL Daily '!AA13) -> 2 | R12: =IF(('FSLPL Daily '!AC14-'FSLPL Daily '!AC13<0), "0",'FSLPL Daily '!AC14-'FSLPL Daily '!AC13) -> 1388 | S12: =IF(('FSLPL Daily '!AE14-'FSLPL Daily '!AE13<0), "0",'FSLPL Daily '!AE14-'FSLPL Daily '!AE13) -> 1951 | T12: =IF(('FSLPL Daily '!AG14-'FSLPL Daily '!AG13<0), "0",'FSLPL Daily '!AG14-'FSLPL Daily '!AG13) -> 262 | U12: =IF(('FSLPL Daily '!AI14-'FSLPL Daily '!AI13<0), "0",'FSLPL Daily '!AI14-'FSLPL Daily '!AI13) -> 20 | V12: =IF(('FSLPL Daily '!AK14-'FSLPL Daily '!AK13<0), "0",'FSLPL Daily '!AK14-'FSLPL Daily '!AK13) -> 328 | W12: =IF(('FSLPL Daily '!AM14-'FSLPL Daily '!AM13<0), "0",'FSLPL Daily '!AM14-'FSLPL Daily '!AM13) -> 581 | X12: =IF(('FSLPL Daily '!AO14-'FSLPL Daily '!AO13<0), "0",'FSLPL Daily '!AO14-'FSLPL Daily '!AO13) -> 530 | Y12: ='FSLPL Daily '!AS14 -> 0 | Z12: ='FSLPL Daily '!AU14 -> 0 | AA12: =IF(('FSLPL Daily '!AV14-'FSLPL Daily '!AV13<0), "0",'FSLPL Daily '!AV14-'FSLPL Daily '!AV13) -> 15 | AB12: =IF(('FSLPL Daily '!AX14-'FSLPL Daily '!AX13<0), "0",'FSLPL Daily '!AX14-'FSLPL Daily '!AX13) -> 2 | AC12: =IF(('FSLPL Daily '!AZ14-'FSLPL Daily '!AZ13<0), "0",'FSLPL Daily '!AZ14-'FSLPL Daily '!AZ13) -> 2052 | AD12: =IF(('FSLPL Daily '!BB14-'FSLPL Daily '!BB13<0), "0",'FSLPL Daily '!BB14-'FSLPL Daily '!BB13) -> 1122 | AE12: ='FSLPL Daily '!BD14 -> 37 | AF12: ='FSLPL Daily '!BE14 -> 58
A13: London at Park Lane | B13: =B12+1 -> 12 | C13: 3 | D13: 2020 | E13: =IF(('FSLPL Daily '!C15-'FSLPL Daily '!C14<0), "0",'FSLPL Daily '!C15-'FSLPL Daily '!C14) -> 7694 | F13: =IF(('FSLPL Daily '!E15-'FSLPL Daily '!E14<0), "0",'FSLPL Daily '!E15-'FSLPL Daily '!E14) -> 4870 | G13: =IF(('FSLPL Daily '!G15-'FSLPL Daily '!G14<0), "0",'FSLPL Daily '!G15-'FSLPL Daily '!G14) -> 3917 | H13: =IF(('FSLPL Daily '!I15-'FSLPL Daily '!I14<0), "0",'FSLPL Daily '!I15-'FSLPL Daily '!I14) -> 464 | I13: =IF(('FSLPL Daily '!K15-'FSLPL Daily '!K14<0), "0",'FSLPL Daily '!K15-'FSLPL Daily '!K14) -> 804 | J13: =IF(('FSLPL Daily '!M15-'FSLPL Daily '!M14<0), "0",'FSLPL Daily '!M15-'FSLPL Daily '!M14) -> 1131 | K13: =IF(('FSLPL Daily '!O15-'FSLPL Daily '!O14<0), "0",'FSLPL Daily '!O15-'FSLPL Daily '!O14) -> 552 | L13: =IF(('FSLPL Daily '!Q15-'FSLPL Daily '!Q14<0), "0",'FSLPL Daily '!Q15-'FSLPL Daily '!Q14) -> 308 | M13: =IF(('FSLPL Daily '!S15-'FSLPL Daily '!S14<0), "0",'FSLPL Daily '!S15-'FSLPL Daily '!S14) -> 84 | N13: =IF(('FSLPL Daily '!U15-'FSLPL Daily '!U14<0), "0",'FSLPL Daily '!U15-'FSLPL Daily '!U14) -> 1147 | O13: =IF(('FSLPL Daily '!W15-'FSLPL Daily '!W14<0), "0",'FSLPL Daily '!W15-'FSLPL Daily '!W14) -> 180 | P13: =IF(('FSLPL Daily '!Y15-'FSLPL Daily '!Y14<0), "0",'FSLPL Daily '!Y15-'FSLPL Daily '!Y14) -> 1219 | Q13: =IF(('FSLPL Daily '!AA15-'FSLPL Daily '!AA14<0), "0",'FSLPL Daily '!AA15-'FSLPL Daily '!AA14) -> 2 | R13: =IF(('FSLPL Daily '!AC15-'FSLPL Daily '!AC14<0), "0",'FSLPL Daily '!AC15-'FSLPL Daily '!AC14) -> 1406 | S13: =IF(('FSLPL Daily '!AE15-'FSLPL Daily '!AE14<0), "0",'FSLPL Daily '!AE15-'FSLPL Daily '!AE14) -> 1979 | T13: =IF(('FSLPL Daily '!AG15-'FSLPL Daily '!AG14<0), "0",'FSLPL Daily '!AG15-'FSLPL Daily '!AG14) -> 228 | U13: =IF(('FSLPL Daily '!AI15-'FSLPL Daily '!AI14<0), "0",'FSLPL Daily '!AI15-'FSLPL Daily '!AI14) -> 20 | V13: =IF(('FSLPL Daily '!AK15-'FSLPL Daily '!AK14<0), "0",'FSLPL Daily '!AK15-'FSLPL Daily '!AK14) -> 307 | W13: =IF(('FSLPL Daily '!AM15-'FSLPL Daily '!AM14<0), "0",'FSLPL Daily '!AM15-'FSLPL Daily '!AM14) -> 594 | X13: =IF(('FSLPL Daily '!AO15-'FSLPL Daily '!AO14<0), "0",'FSLPL Daily '!AO15-'FSLPL Daily '!AO14) -> 527 | Y13: ='FSLPL Daily '!AS15 -> 0 | Z13: ='FSLPL Daily '!AU15 -> 0 | AA13: =IF(('FSLPL Daily '!AV15-'FSLPL Daily '!AV14<0), "0",'FSLPL Daily '!AV15-'FSLPL Daily '!AV14) -> 13 | AB13: =IF(('FSLPL Daily '!AX15-'FSLPL Daily '!AX14<0), "0",'FSLPL Daily '!AX15-'FSLPL Daily '!AX14) -> 2 | AC13: =IF(('FSLPL Daily '!AZ15-'FSLPL Daily '!AZ14<0), "0",'FSLPL Daily '!AZ15-'FSLPL Daily '!AZ14) -> 2068 | AD13: =IF(('FSLPL Daily '!BB15-'FSLPL Daily '!BB14<0), "0",'FSLPL Daily '!BB15-'FSLPL Daily '!BB14) -> 1126 | AE13: ='FSLPL Daily '!BD15 -> 44 | AF13: ='FSLPL Daily '!BE15 -> 71
A14: London at Park Lane | B14: =B13+1 -> 13 | C14: 3 | D14: 2020 | E14: =IF(('FSLPL Daily '!C16-'FSLPL Daily '!C15<0), "0",'FSLPL Daily '!C16-'FSLPL Daily '!C15) -> 7143 | F14: =IF(('FSLPL Daily '!E16-'FSLPL Daily '!E15<0), "0",'FSLPL Daily '!E16-'FSLPL Daily '!E15) -> 4810 | G14: =IF(('FSLPL Daily '!G16-'FSLPL Daily '!G15<0), "0",'FSLPL Daily '!G16-'FSLPL Daily '!G15) -> 3911 | H14: =IF(('FSLPL Daily '!I16-'FSLPL Daily '!I15<0), "0",'FSLPL Daily '!I16-'FSLPL Daily '!I15) -> 473 | I14: =IF(('FSLPL Daily '!K16-'FSLPL Daily '!K15<0), "0",'FSLPL Daily '!K16-'FSLPL Daily '!K15) -> 812 | J14: =IF(('FSLPL Daily '!M16-'FSLPL Daily '!M15<0), "0",'FSLPL Daily '!M16-'FSLPL Daily '!M15) -> 1048 | K14: =IF(('FSLPL Daily '!O16-'FSLPL Daily '!O15<0), "0",'FSLPL Daily '!O16-'FSLPL Daily '!O15) -> 567 | L14: =IF(('FSLPL Daily '!Q16-'FSLPL Daily '!Q15<0), "0",'FSLPL Daily '!Q16-'FSLPL Daily '!Q15) -> 312 | M14: =IF(('FSLPL Daily '!S16-'FSLPL Daily '!S15<0), "0",'FSLPL Daily '!S16-'FSLPL Daily '!S15) -> 80 | N14: =IF(('FSLPL Daily '!U16-'FSLPL Daily '!U15<0), "0",'FSLPL Daily '!U16-'FSLPL Daily '!U15) -> 969 | O14: =IF(('FSLPL Daily '!W16-'FSLPL Daily '!W15<0), "0",'FSLPL Daily '!W16-'FSLPL Daily '!W15) -> 80 | P14: =IF(('FSLPL Daily '!Y16-'FSLPL Daily '!Y15<0), "0",'FSLPL Daily '!Y16-'FSLPL Daily '!Y15) -> 994 | Q14: =IF(('FSLPL Daily '!AA16-'FSLPL Daily '!AA15<0), "0",'FSLPL Daily '!AA16-'FSLPL Daily '!AA15) -> 3 | R14: =IF(('FSLPL Daily '!AC16-'FSLPL Daily '!AC15<0), "0",'FSLPL Daily '!AC16-'FSLPL Daily '!AC15) -> 1450 | S14: =IF(('FSLPL Daily '!AE16-'FSLPL Daily '!AE15<0), "0",'FSLPL Daily '!AE16-'FSLPL Daily '!AE15) -> 1909 | T14: =IF(('FSLPL Daily '!AG16-'FSLPL Daily '!AG15<0), "0",'FSLPL Daily '!AG16-'FSLPL Daily '!AG15) -> 237 | U14: =IF(('FSLPL Daily '!AI16-'FSLPL Daily '!AI15<0), "0",'FSLPL Daily '!AI16-'FSLPL Daily '!AI15) -> 20 | V14: =IF(('FSLPL Daily '!AK16-'FSLPL Daily '!AK15<0), "0",'FSLPL Daily '!AK16-'FSLPL Daily '!AK15) -> 313 | W14: =IF(('FSLPL Daily '!AM16-'FSLPL Daily '!AM15<0), "0",'FSLPL Daily '!AM16-'FSLPL Daily '!AM15) -> 597 | X14: =IF(('FSLPL Daily '!AO16-'FSLPL Daily '!AO15<0), "0",'FSLPL Daily '!AO16-'FSLPL Daily '!AO15) -> 479 | Y14: ='FSLPL Daily '!AS16 -> 246 | Z14: ='FSLPL Daily '!AU16 -> 667 | AA14: =IF(('FSLPL Daily '!AV16-'FSLPL Daily '!AV15<0), "0",'FSLPL Daily '!AV16-'FSLPL Daily '!AV15) -> 11 | AB14: =IF(('FSLPL Daily '!AX16-'FSLPL Daily '!AX15<0), "0",'FSLPL Daily '!AX16-'FSLPL Daily '!AX15) -> 1 | AC14: =IF(('FSLPL Daily '!AZ16-'FSLPL Daily '!AZ15<0), "0",'FSLPL Daily '!AZ16-'FSLPL Daily '!AZ15) -> 2175 | AD14: =IF(('FSLPL Daily '!BB16-'FSLPL Daily '!BB15<0), "0",'FSLPL Daily '!BB16-'FSLPL Daily '!BB15) -> 1115 | AE14: ='FSLPL Daily '!BD16 -> 40 | AF14: ='FSLPL Daily '!BE16 -> 61
... A32: London at Park Lane | B32: =B31+1 -> 31 | C32: 3 | D32: 2020 | E32: =IF(('FSLPL Daily '!C34-'FSLPL Daily '!C33<0), "0",'FSLPL Daily '!C34-'FSLPL Daily '!C33) -> 0 | F32: =IF(('FSLPL Daily '!E34-'FSLPL Daily '!E33<0), "0",'FSLPL Daily '!E34-'FSLPL Daily '!E33) -> 0 | G32: =IF(('FSLPL Daily '!G34-'FSLPL Daily '!G33<0), "0",'FSLPL Daily '!G34-'FSLPL Daily '!G33) -> 0 | H32: =IF(('FSLPL Daily '!I34-'FSLPL Daily '!I33<0), "0",'FSLPL Daily '!I34-'FSLPL Daily '!I33) -> 0 | I32: =IF(('FSLPL Daily '!K34-'FSLPL Daily '!K33<0), "0",'FSLPL Daily '!K34-'FSLPL Daily '!K33) -> 0 | J32: =IF(('FSLPL Daily '!M34-'FSLPL Daily '!M33<0), "0",'FSLPL Daily '!M34-'FSLPL Daily '!M33) -> 0 | K32: =IF(('FSLPL Daily '!O34-'FSLPL Daily '!O33<0), "0",'FSLPL Daily '!O34-'FSLPL Daily '!O33) -> 0 | L32: =IF(('FSLPL Daily '!Q34-'FSLPL Daily '!Q33<0), "0",'FSLPL Daily '!Q34-'FSLPL Daily '!Q33) -> 0 | M32: =IF(('FSLPL Daily '!S34-'FSLPL Daily '!S33<0), "0",'FSLPL Daily '!S34-'FSLPL Daily '!S33) -> 0 | N32: =IF(('FSLPL Daily '!U34-'FSLPL Daily '!U33<0), "0",'FSLPL Daily '!U34-'FSLPL Daily '!U33) -> 0 | O32: =IF(('FSLPL Daily '!W34-'FSLPL Daily '!W33<0), "0",'FSLPL Daily '!W34-'FSLPL Daily '!W33) -> 0 | P32: =IF(('FSLPL Daily '!Y34-'FSLPL Daily '!Y33<0), "0",'FSLPL Daily '!Y34-'FSLPL Daily '!Y33) -> 0 | Q32: =IF(('FSLPL Daily '!AA34-'FSLPL Daily '!AA33<0), "0",'FSLPL Daily '!AA34-'FSLPL Daily '!AA33) -> 0 | R32: =IF(('FSLPL Daily '!AC34-'FSLPL Daily '!AC33<0), "0",'FSLPL Daily '!AC34-'FSLPL Daily '!AC33) -> 0 | S32: =IF(('FSLPL Daily '!AE34-'FSLPL Daily '!AE33<0), "0",'FSLPL Daily '!AE34-'FSLPL Daily '!AE33) -> 0 | T32: =IF(('FSLPL Daily '!AG34-'FSLPL Daily '!AG33<0), "0",'FSLPL Daily '!AG34-'FSLPL Daily '!AG33) -> 0 | U32: =IF(('FSLPL Daily '!AI34-'FSLPL Daily '!AI33<0), "0",'FSLPL Daily '!AI34-'FSLPL Daily '!AI33) -> 0 | V32: =IF(('FSLPL Daily '!AK34-'FSLPL Daily '!AK33<0), "0",'FSLPL Daily '!AK34-'FSLPL Daily '!AK33) -> 0 | W32: =IF(('FSLPL Daily '!AM34-'FSLPL Daily '!AM33<0), "0",'FSLPL Daily '!AM34-'FSLPL Daily '!AM33) -> 0 | X32: =IF(('FSLPL Daily '!AO34-'FSLPL Daily '!AO33<0), "0",'FSLPL Daily '!AO34-'FSLPL Daily '!AO33) -> 0 | Y32: ='FSLPL Daily '!AS34 -> 0 | Z32: ='FSLPL Daily '!AU34 -> 0 | AA32: =IF(('FSLPL Daily '!AV34-'FSLPL Daily '!AV33<0), "0",'FSLPL Daily '!AV34-'FSLPL Daily '!AV33) -> 0 | AB32: =IF(('FSLPL Daily '!AX34-'FSLPL Daily '!AX33<0), "0",'FSLPL Daily '!AX34-'FSLPL Daily '!AX33) -> 0 | AC32: =IF(('FSLPL Daily '!AZ34-'FSLPL Daily '!AZ33<0), "0",'FSLPL Daily '!AZ34-'FSLPL Daily '!AZ33) -> 0 | AD32: =IF(('FSLPL Daily '!BB34-'FSLPL Daily '!BB33<0), "0",'FSLPL Daily '!BB34-'FSLPL Daily '!BB33) -> 0 | AE32: ='FSLPL Daily '!BD34 -> 0 | AF32: ='FSLPL Daily '!BE34 -> 0

Sheet FSLPL Daily 
A1: Days | C1: LV Panel 1 KWh | E1: LV Panel 2 KWh | G1: CHP KWh | I1: MCC9 KWh | K1: GF Panel KWh | M1: Kitchen Switchboard | O1: Kitchen Panel | Q1: MCC3 (AHU) KWh | S1: MCC8 KWh | U1: 1st Floor Panel (KWh) | W1: MCC6(1st floor AHU) KWh | Y1: Chiller 1 KWh | AA1: Chiller 2 KWh | AC1: MCC 10 (Mechanical Services) KWh | AE1: MCC2 CHW KWh | AG1: MCC7 (Kitchen) KWh | AI1: MCC 5 (Mechanical services) KWh | AK1: MCC 4 (Water Services) KWh | AM1: MCC1 (KWh) | AO1: Laundry db KWh | AR1: Hamilton Place Water 1 m3 | AT1: Old Parklane Water 2 m3 | AV1: Laundry CW m3 | AX1: Laundry HW m3 | AZ1: Natural Gas m3 | BB1: CHP Natural Gas m3
A2: Date | C2: Reading KWH | D2: Difference KWH | E2: Reading KWH | F2: Difference KWH | G2: Reading KWH | H2: Difference KWH | I2: Reading KWH | J2: Difference KWH | K2: Reading KWH | L2: Difference KWH | M2: Reading KWH | N2: Difference KWH | O2: Reading KWH | P2: Difference KWH | Q2: Reading KWH | R2: Difference KWH | S2: Reading KWH | T2: Difference KWH | U2: Reading KWH | V2: Difference KWH | W2: Reading KWH | X2: Difference KWH | Y2: Reading KWH | Z2: Difference KWH | AA2: Reading KWH | AB2: Difference KWH | AC2: Reading KWH | AD2: Difference KWH | AE2: Reading KWH | AF2: Difference KWH | AG2: Reading KWH | AH2: Difference KWH | AI2: Reading KWH | AJ2: Difference KWH | AK2: Reading KWH | AL2: Difference KWH | AM2: Reading KWH | AN2: Difference KWH | AO2: Reading KWH | AP2: Difference KWH | AR2: Reading m³ | AS2: Daily Consumption m³ | AT2: Reading m³ | AU2: Daily Consumption m³ | AV2: Reading m³ | AW2: Daily Consumption m³ | AX2: Reading m³ | AY2: Daily Consumption m³ | AZ2: Reading Liters | BA2: Daily Consumption L | BB2: Reading Liters | BC2: Daily Consumption L | BD2: ROOM NIGHTS | BE2: TOTAL GUESTS
A3: 43890 | C3: 25518682 | D3: =IF((C4-C3<0), "0",C4-C3) -> 6271 | E3: 26238936 | F3: =IF((E4-E3<0), "",E4-E3) -> 6373 | G3: 11148968 | H3: =IF((G4-G3<0), "",G4-G3) -> 3987 | I3: 1565376 | J3: =IF((I4-I3<0), "",I4-I3) -> 485 | K3: 3154732 | L3: =IF((K4-K3<0), "",K4-K3) -> 788 | M3: 4587286 | N3: =IF((M4-M3<0), "",M4-M3) -> 1182 | O3: 2197583 | P3: =IF((O4-O3<0), "",O4-O3) -> 559 | Q3: 1230989 | R3: =IF((Q4-Q3<0), "",Q4-Q3) -> 323 | S3: 395980 | T3: =IF((S4-S3<0), "",S4-S3) -> 74 | U3: 4127691 | V3: =IF((U4-U3<0), "",U4-U3) -> 869 | W3: 949000 | X3: =IF((W4-W3<0), "",W4-W3) -> 100 | Y3: 3774908 | Z3: =IF((Y4-Y3<0), "",Y4-Y3) -> 4 | AA3: 1969658 | AB3: =IF((AA4-AA3<0), "",AA4-AA3) -> 756 | AC3: 5082568 | AD3: =IF((AC4-AC3<0), "",AC4-AC3) -> 1378 | AE3: 7235312 | AF3: =IF((AE4-AE3<0), "",AE4-AE3) -> 1931 | AG3: 1275841 | AH3: =IF((AG4-AG3<0), "",AG4-AG3) -> 231 | AI3: 251800 | AJ3: =IF((AI4-AI3<0), "",AI4-AI3) -> 68 | AK3: 936083 | AL3: =IF((AK4-AK3<0), "",AK4-AK3) -> 332 | AM3: 1735512 | AN3: =IF((AM4-AM3<0), "",AM4-AM3) -> 585 | AO3: 1857936 | AP3: =IF((AO4-AO3<0), "",AO4-AO3) -> 662 | AV3: 87113 | AW3: =IF((AV4-AV3<0), "",AV4-AV3) -> 20 | AX3: 40 | AY3: =IF((AX4-AX3<0), "",AX4-AX3) -> 3 | AZ3: 6819507 | BA3: =IF((AZ4-AZ3<0), "",AZ4-AZ3) -> 2437 | BB3: 1193121 | BC3: =IF((BB4-BB3<0), "",BB4-BB3) -> 1160 | BD3: 111 | BE3: 167
A4: 43891 | C4: 25524953 | E4: 26245309 | G4: 11152955 | I4: 1565861 | K4: 3155520 | M4: 4588468 | O4: 2198142 | Q4: 1231312 | S4: 396054 | U4: 4128560 | W4: 949100 | Y4: 3774912 | AA4: 1970414 | AC4: 5083946 | AE4: 7237243 | AG4: 1276072 | AI4: 251868 | AK4: 936415 | AM4: 1736097 | AO4: 1858598 | AR4: 0 | AS4: 359 | AU4: 905 | AV4: 87133 | AX4: 43 | AZ4: 6821944 | BB4: 1194281 | BD4: 113 | BE4: 149
A5: 43892 | C5: 25531432 | D5: =IF((C5-C4<0), "0",C5-C4) -> 6479 | E5: 26251399 | F5: =IF((E5-E4<0), "0",E5-E4) -> 6090 | G5: 11156761 | H5: =IF((G5-G4<0), "0",G5-G4) -> 3806 | I5: 1566367 | J5: =IF((I5-I4<0), "0",I5-I4) -> 506 | K5: 3156303 | L5: =IF((K5-K4<0), "0",K5-K4) -> 783 | M5: 4589787 | N5: =IF((M5-M4<0), "0",M5-M4) -> 1319 | O5: 2198736 | P5: =IF((O5-O4<0), "0",O5-O4) -> 594 | Q5: 1231606 | R5: =IF((Q5-Q4<0), "0",Q5-Q4) -> 294 | S5: 396093 | T5: =IF((S5-S4<0), "0",S5-S4) -> 39 | U5: 4129439 | V5: =IF((U5-U4<0), "",U5-U4) -> 879 | W5: 949112 | X5: =IF((W5-W4<0), "",W5-W4) -> 12 | Y5: 3775045 | Z5: =IF((Y5-Y4<0), "",Y5-Y4) -> 133 | AA5: 1971508 | AB5: =IF((AA5-AA4<0), "",AA5-AA4) -> 1094 | AC5: 5085323 | AD5: =IF((AC5-AC4<0), "",AC5-AC4) -> 1377 | AE5: 7238675 | AF5: =IF((AE5-AE4<0), "",AE5-AE4) -> 1432 | AG5: 1276295 | AH5: =IF((AG5-AG4<0), "",AG5-AG4) -> 223 | AI5: 251887 | AJ5: =IF((AI5-AI4<0), "",AI5-AI4) -> 19 | AK5: 936754 | AL5: =IF((AK5-AK4<0), "",AK5-AK4) -> 339 | AM5: 1736682 | AN5: =IF((AM5-AM4<0), "",AM5-AM4) -> 585 | AO5: 1859181 | AP5: =IF((AO5-AO4<0), "",AO5-AO4) -> 583 | AR5: 0 | AS5: 0 | AT5: 0 | AU5: 0 | AV5: 87150 | AW5: =IF((AV5-AV4<0), "",AV5-AV4) -> 17 | AX5: 45 | AY5: =IF((AX5-AX4<0), "",AX5-AX4) -> 2 | AZ5: 6824137 | BA5: =IF((AZ5-AZ4<0), "",AZ5-AZ4) -> 2193 | BB5: 1195384 | BC5: =IF((BB5-BB4<0), "",BB5-BB4) -> 1103 | BD5: 127 | BE5: 155
A6: 43893 | C6: 25539569 | D6: =IF((C6-C5<0), "0",C6-C5) -> 8137 | E6: 26256522 | F6: =IF((E6-E5<0), "0",E6-E5) -> 5123 | G6: 11160739 | H6: =IF((G6-G5<0), "0",G6-G5) -> 3978 | I6: 1566850 | J6: =IF((I6-I5<0), "0",I6-I5) -> 483 | K6: 3157135 | L6: =IF((K6-K5<0), "0",K6-K5) -> 832 | M6: 4591214 | N6: =IF((M6-M5<0), "0",M6-M5) -> 1427 | O6: 2199349 | P6: =IF((O6-O5<0), "0",O6-O5) -> 613 | Q6: 1231920 | R6: =IF((Q6-Q5<0), "0",Q6-Q5) -> 314 | S6: 396152 | T6: =IF((S6-S5<0), "0",S6-S5) -> 59 | U6: 4130705 | V6: =IF((U6-U5<0), "",U6-U5) -> 1266 | W6: 949407 | X6: =IF((W6-W5<0), "",W6-W5) -> 295 | Y6: 3775890 | Z6: =IF((Y6-Y5<0), "",Y6-Y5) -> 845 | AA6: 1971595 | AB6: =IF((AA6-AA5<0), "",AA6-AA5) -> 87 | AC6: 5086743 | AD6: =IF((AC6-AC5<0), "",AC6-AC5) -> 1420 | AE6: 7240435 | AF6: =IF((AE6-AE5<0), "",AE6-AE5) -> 1760 | AG6: 1276523 | AH6: =IF((AG6-AG5<0), "",AG6-AG5) -> 228 | AI6: 251907 | AJ6: =IF((AI6-AI5<0), "",AI6-AI5) -> 20 | AK6: 937105 | AL6: =IF((AK6-AK5<0), "",AK6-AK5) -> 351 | AM6: 1737260 | AN6: =IF((AM6-AM5<0), "",AM6-AM5) -> 578 | AO6: 1859811 | AP6: =IF((AO6-AO5<0), "",AO6-AO5) -> 630 | AR6: 0 | AS6: 0 | AT6: 0 | AU6: 0 | AV6: 87172 | AW6: =IF((AV6-AV5<0), "",AV6-AV5) -> 22 | AX6: 48 | AY6: =IF((AX6-AX5<0), "",AX6-AX5) -> 3 | AZ6: 6826569 | BA6: =IF((AZ6-AZ5<0), "",AZ6-AZ5) -> 2432 | BB6: 1196532 | BC6: =IF((BB6-BB5<0), "",BB6-BB5) -> 1148 | BD6: 122 | BE6: 152
A7: 43894 | C7: 25547792 | D7: =IF((C7-C6<0), "0",C7-C6) -> 8223 | E7: 26261841 | F7: =IF((E7-E6<0), "0",E7-E6) -> 5319 | G7: 11164688 | H7: =IF((G7-G6<0), "0",G7-G6) -> 3949 | I7: 1567350 | J7: =IF((I7-I6<0), "0",I7-I6) -> 500 | K7: 3157983 | L7: =IF((K7-K6<0), "0",K7-K6) -> 848 | M7: 4592613 | N7: =IF((M7-M6<0), "0",M7-M6) -> 1399 | O7: 2199969 | P7: =IF((O7-O6<0), "0",O7-O6) -> 620 | Q7: 1232275 | R7: =IF((Q7-Q6<0), "0",Q7-Q6) -> 355 | S7: 396237 | T7: =IF((S7-S6<0), "0",S7-S6) -> 85 | U7: 4131834 | V7: =IF((U7-U6<0), "",U7-U6) -> 1129 | W7: 949663 | X7: =IF((W7-W6<0), "",W7-W6) -> 256 | Y7: 3776929 | Z7: =IF((Y7-Y6<0), "",Y7-Y6) -> 1039 | AA7: 1971597 | AB7: =IF((AA7-AA6<0), "",AA7-AA6) -> 2 | AC7: 5088134 | AD7: =IF((AC7-AC6<0), "",AC7-AC6) -> 1391 | AE7: 7242427 | AF7: =IF((AE7-AE6<0), "",AE7-AE6) -> 1992 | AG7: 1276752 | AH7: =IF((AG7-AG6<0), "",AG7-AG6) -> 229 | AI7: 251927 | AJ7: =IF((AI7-AI6<0), "",AI7-AI6) -> 20 | AK7: 937466 | AL7: =IF((AK7-AK6<0), "",AK7-AK6) -> 361 | AM7: 1737872 | AN7: =IF((AM7-AM6<0), "",AM7-AM6) -> 612 | AO7: 1860455 | AP7: =IF((AO7-AO6<0), "",AO7-AO6) -> 644 | AR7: 0 | AS7: 0 | AT7: 0 | AU7: 0 | AV7: 87192 | AW7: =IF((AV7-AV6<0), "",AV7-AV6) -> 20 | AX7: 50 | AY7: =IF((AX7-AX6<0), "",AX7-AX6) -> 2 | AZ7: 6828983 | BA7: =IF((AZ7-AZ6<0), "",AZ7-AZ6) -> 2414 | BB7: 1197662 | BC7: =IF((BB7-BB6<0), "",BB7-BB6) -> 1130 | BD7: 90 | BE7: 121
A8: 43895 | C8: 25555739 | D8: =IF((C8-C7<0), "0",C8-C7) -> 7947 | E8: 26267081 | F8: =IF((E8-E7<0), "0",E8-E7) -> 5240 | G8: 11168622 | H8: =IF((G8-G7<0), "0",G8-G7) -> 3934 | I8: 1567850 | J8: =IF((I8-I7<0), "0",I8-I7) -> 500 | K8: 3158802 | L8: =IF((K8-K7<0), "0",K8-K7) -> 819 | M8: 4593891 | N8: =IF((M8-M7<0), "0",M8-M7) -> 1278 | O8: 2200602 | P8: =IF((O8-O7<0), "0",O8-O7) -> 633 | Q8: 1232598 | R8: =IF((Q8-Q7<0), "0",Q8-Q7) -> 323 | S8: 396322 | T8: =IF((S8-S7<0), "0",S8-S7) -> 85 | U8: 4132913 | V8: =IF((U8-U7<0), "",U8-U7) -> 1079 | W8: 949907 | X8: =IF((W8-W7<0), "",W8-W7) -> 244 | Y8: 3777980 | Z8: =IF((Y8-Y7<0), "",Y8-Y7) -> 1051 | AA8: 1971599 | AB8: =IF((AA8-AA7<0), "",AA8-AA7) -> 2 | AC8: 5089529 | AD8: =IF((AC8-AC7<0), "",AC8-AC7) -> 1395 | AE8: 7244410 | AF8: =IF((AE8-AE7<0), "",AE8-AE7) -> 1983 | AG8: 1276978 | AH8: =IF((AG8-AG7<0), "",AG8-AG7) -> 226 | AI8: 251947 | AJ8: =IF((AI8-AI7<0), "",AI8-AI7) -> 20 | AK8: 937795 | AL8: =IF((AK8-AK7<0), "",AK8-AK7) -> 329 | AM8: 1738479 | AN8: =IF((AM8-AM7<0), "",AM8-AM7) -> 607 | AO8: 1861042 | AP8: =IF((AO8-AO7<0), "",AO8-AO7) -> 587 | AR8: 0 | AS8: 0 | AT8: 0 | AU8: 0 | AV8: 87210 | AW8: =IF((AV8-AV7<0), "",AV8-AV7) -> 18 | AX8: 53 | AY8: =IF((AX8-AX7<0), "",AX8-AX7) -> 3 | AZ8: 6831366 | BA8: =IF((AZ8-AZ7<0), "",AZ8-AZ7) -> 2383 | BB8: 1198786 | BC8: =IF((BB8-BB7<0), "",BB8-BB7) -> 1124 | BD8: 70 | BE8: 97
A9: 43896 | C9: 25563167 | D9: =IF((C9-C8<0), "0",C9-C8) -> 7428 | E9: 26272299 | F9: =IF((E9-E8<0), "0",E9-E8) -> 5218 | G9: 11172602 | H9: =IF((G9-G8<0), "0",G9-G8) -> 3980 | I9: 1568344 | J9: =IF((I9-I8<0), "0",I9-I8) -> 494 | K9: 3159613 | L9: =IF((K9-K8<0), "0",K9-K8) -> 811 | M9: 4595130 | N9: =IF((M9-M8<0), "0",M9-M8) -> 1239 | O9: 2201140 | P9: =IF((O9-O8<0), "0",O9-O8) -> 538 | Q9: 1232916 | R9: =IF((Q9-Q8<0), "0",Q9-Q8) -> 318 | S9: 396407 | T9: =IF((S9-S8<0), "0",S9-S8) -> 85 | U9: 4133892 | V9: =IF((U9-U8<0), "",U9-U8) -> 979 | W9: 950030 | X9: =IF((W9-W8<0), "",W9-W8) -> 123 | Y9: 3778953 | Z9: =IF((Y9-Y8<0), "",Y9-Y8) -> 973 | AA9: 1971602 | AB9: =IF((AA9-AA8<0), "",AA9-AA8) -> 3 | AC9: 5090949 | AD9: =IF((AC9-AC8<0), "",AC9-AC8) -> 1420 | AE9: 7246393 | AF9: =IF((AE9-AE8<0), "",AE9-AE8) -> 1983 | AG9: 1277202 | AH9: =IF((AG9-AG8<0), "",AG9-AG8) -> 224 | AI9: 251967 | AJ9: =IF((AI9-AI8<0), "",AI9-AI8) -> 20 | AK9: 938111 | AL9: =IF((AK9-AK8<0), "",AK9-AK8) -> 316 | AM9: 1739087 | AN9: =IF((AM9-AM8<0), "",AM9-AM8) -> 608 | AO9: 1861660 | AP9: =IF((AO9-AO8<0), "",AO9-AO8) -> 618 | AR9: 0 | AS9: 0 | AT9: 0 | AU9: 0 | AV9: 87227 | AW9: =IF((AV9-AV8<0), "",AV9-AV8) -> 17 | AX9: 55 | AY9: =IF((AX9-AX8<0), "",AX9-AX8) -> 2 | AZ9: 6833870 | BA9: =IF((AZ9-AZ8<0), "",AZ9-AZ8) -> 2504 | BB9: 1199929 | BC9: =IF((BB9-BB8<0), "",BB9-BB8) -> 1143 | BD9: 71 | BE9: 104
A10: 43897 | C10: 25570698 | D10: =IF((C10-C9<0), "0",C10-C9) -> 7531 | E10: 26277453 | F10: =IF((E10-E9<0), "0",E10-E9) -> 5154 | G10: 11176552 | H10: =IF((G10-G9<0), "0",G10-G9) -> 3950 | I10: 1568843 | J10: =IF((I10-I9<0), "0",I10-I9) -> 499 | K10: 3160435 | L10: =IF((K10-K9<0), "0",K10-K9) -> 822 | M10: 4596283 | N10: =IF((M10-M9<0), "0",M10-M9) -> 1153 | O10: 2201699 | P10: =IF((O10-O9<0), "0",O10-O9) -> 559 | Q10: 1233244 | R10: =IF((Q10-Q9<0), "0",Q10-Q9) -> 328 | S10: 396493 | T10: =IF((S10-S9<0), "0",S10-S9) -> 86 | U10: 4134907 | V10: =IF((U10-U9<0), "",U10-U9) -> 1015 | W10: 950162 | X10: =IF((W10-W9<0), "",W10-W9) -> 132 | Y10: 3780064 | Z10: =IF((Y10-Y9<0), "",Y10-Y9) -> 1111 | AA10: 1971604 | AB10: =IF((AA10-AA9<0), "",AA10-AA9) -> 2 | AC10: 5092401 | AD10: =IF((AC10-AC9<0), "",AC10-AC9) -> 1452 | AE10: 7248448 | AF10: =IF((AE10-AE9<0), "",AE10-AE9) -> 2055 | AG10: 1277436 | AH10: =IF((AG10-AG9<0), "",AG10-AG9) -> 234 | AI10: 251988 | AJ10: =IF((AI10-AI9<0), "",AI10-AI9) -> 21 | AK10: 938438 | AL10: =IF((AK10-AK9<0), "",AK10-AK9) -> 327 | AM10: 1739700 | AN10: =IF((AM10-AM9<0), "",AM10-AM9) -> 613 | AO10: 1862249 | AP10: =IF((AO10-AO9<0), "",AO10-AO9) -> 589 | AR10: 0 | AS10: 0 | AT10: 0 | AU10: 0 | AV10: 87247 | AW10: =IF((AV10-AV9<0), "",AV10-AV9) -> 20 | AX10: 57 | AY10: =IF((AX10-AX9<0), "",AX10-AX9) -> 2 | AZ10: 6836370 | BA10: =IF((AZ10-AZ9<0), "",AZ10-AZ9) -> 2500 | BB10: 1201039 | BC10: =IF((BB10-BB9<0), "",BB10-BB9) -> 1110 | BD10: 79 | BE10: 120
A11: 43898 | C11: 25578104 | D11: =IF((C11-C10<0), "0",C11-C10) -> 7406 | E11: 26282305 | F11: =IF((E11-E10<0), "0",E11-E10) -> 4852 | G11: 11180533 | H11: =IF((G11-G10<0), "0",G11-G10) -> 3981 | I11: 1569345 | J11: =IF((I11-I10<0), "0",I11-I10) -> 502 | K11: 3161209 | L11: =IF((K11-K10<0), "0",K11-K10) -> 774 | M11: 4597958 | N11: =IF((M11-M10<0), "0",M11-M10) -> 1675 | O11: 2202218 | P11: =IF((O11-O10<0), "0",O11-O10) -> 519 | Q11: 1233546 | R11: =IF((Q11-Q10<0), "0",Q11-Q10) -> 302 | S11: 396577 | T11: =IF((S11-S10<0), "0",S11-S10) -> 84 | U11: 4135875 | V11: =IF((U11-U10<0), "",U11-U10) -> 968 | W11: 950387 | X11: =IF((W11-W10<0), "",W11-W10) -> 225 | Y11: 3781198 | Z11: =IF((Y11-Y10<0), "",Y11-Y10) -> 1134 | AA11: 1971606 | AB11: =IF((AA11-AA10<0), "",AA11-AA10) -> 2 | AC11: 5093789 | AD11: =IF((AC11-AC10<0), "",AC11-AC10) -> 1388 | AE11: 7250407 | AF11: =IF((AE11-AE10<0), "",AE11-AE10) -> 1959 | AG11: 1277656 | AH11: =IF((AG11-AG10<0), "",AG11-AG10) -> 220 | AI11: 252008 | AJ11: =IF((AI11-AI10<0), "",AI11-AI10) -> 20 | AK11: 938745 | AL11: =IF((AK11-AK10<0), "",AK11-AK10) -> 307 | AM11: 1740280 | AN11: =IF((AM11-AM10<0), "",AM11-AM10) -> 580 | AO11: 1862807 | AP11: =IF((AO11-AO10<0), "",AO11-AO10) -> 558 | AR11: 0 | AS11: 0 | AT11: 0 | AU11: 0 | AV11: 87258 | AW11: =IF((AV11-AV10<0), "",AV11-AV10) -> 11 | AX11: 60 | AY11: =IF((AX11-AX10<0), "",AX11-AX10) -> 3 | AZ11: 6838716 | BA11: =IF((AZ11-AZ10<0), "",AZ11-AZ10) -> 2346 | BB11: 1202039 | BC11: =IF((BB11-BB10<0), "",BB11-BB10) -> 1000 | BD11: 56 | BE11: 87
A12: 43899 | C12: 25585905 | D12: =IF((C12-C11<0), "0",C12-C11) -> 7801 | E12: 26287041 | F12: =IF((E12-E11<0), "0",E12-E11) -> 4736 | G12: 11184397 | H12: =IF((G12-G11<0), "0",G12-G11) -> 3864 | I12: 1569853 | J12: =IF((I12-I11<0), "0",I12-I11) -> 508 | K12: 3162009 | L12: =IF((K12-K11<0), "0",K12-K11) -> 800 | M12: 4598652 | N12: =IF((M12-M11<0), "0",M12-M11) -> 694 | O12: 2202778 | P12: =IF((O12-O11<0), "0",O12-O11) -> 560 | Q12: 1233854 | R12: =IF((Q12-Q11<0), "0",Q12-Q11) -> 308 | S12: 396661 | T12: =IF((S12-S11<0), "0",S12-S11) -> 84 | U12: 4136876 | V12: =IF((U12-U11<0), "",U12-U11) -> 1001 | W12: 950650 | X12: =IF((W12-W11<0), "",W12-W11) -> 263 | Y12: 3782390 | Z12: =IF((Y12-Y11<0), "",Y12-Y11) -> 1192 | AA12: 1971608 | AB12: =IF((AA12-AA11<0), "",AA12-AA11) -> 2 | AC12: 5095192 | AD12: =IF((AC12-AC11<0), "",AC12-AC11) -> 1403 | AE12: 7252380 | AF12: =IF((AE12-AE11<0), "",AE12-AE11) -> 1973 | AG12: 1277877 | AH12: =IF((AG12-AG11<0), "",AG12-AG11) -> 221 | AI12: 252028 | AJ12: =IF((AI12-AI11<0), "",AI12-AI11) -> 20 | AK12: 939064 | AL12: =IF((AK12-AK11<0), "",AK12-AK11) -> 319 | AM12: 1740866 | AN12: =IF((AM12-AM11<0), "",AM12-AM11) -> 586 | AO12: 1863387 | AP12: =IF((AO12-AO11<0), "",AO12-AO11) -> 580 | AR12: 0 | AV12: 87272 | AW12: =IF((AV12-AV11<0), "",AV12-AV11) -> 14 | AX12: 61 | AY12: =IF((AX12-AX11<0), "",AX12-AX11) -> 1 | AZ12: 6840577 | BA12: =IF((AZ12-AZ11<0), "",AZ12-AZ11) -> 1861 | BB12: 1203281 | BC12: =IF((BB12-BB11<0), "",BB12-BB11) -> 1242 | BD12: 69 | BE12: 105
