Workbook

Sheet TOTAL
A1: Site Name | B1: Day | C1: Month | D1: Year | E1: Total Electricity Kwh | F1: Electricity Tariff ($/Kwh) | G1: Water Utility Supply (m3) m3 | H1: Water Utility Supply (m3) $/m3 | I1: Room Nights
A2: Kuwait | B2: 1 | C2: 4 | D2: 2020 | E2: =Submetering!E2+Submetering!F2+Submetering!G2+Submetering!H2+Submetering!I2+Submetering!J2+Submetering!K2+Submetering!L2+Submetering!M2+Submetering!N2+Submetering!O2+Submetering!P2+Submetering!Q2 -> 24870 | F2: 0.005 | G2: =Submetering!R2 -> 412.23115 | H2: 0.528 | I2: =Hotel!B7 -> 80
A3: Kuwait | B3: =B2+1 -> 2 | C3: 4 | D3: 2020 | E3: =Submetering!E3+Submetering!F3+Submetering!G3+Submetering!H3+Submetering!I3+Submetering!J3+Submetering!K3+Submetering!L3+Submetering!M3+Submetering!N3+Submetering!O3+Submetering!P3+Submetering!Q3 -> 29670 | F3: 0.005 | G3: =Submetering!R3 -> 596.58062 | H3: 0.528 | I3: =Hotel!B8 -> 80
A4: Kuwait | B4: =B3+1 -> 3 | C4: 4 | D4: 2020 | E4: =Submetering!E4+Submetering!F4+Submetering!G4+Submetering!H4+Submetering!I4+Submetering!J4+Submetering!K4+Submetering!L4+Submetering!M4+Submetering!N4+Submetering!O4+Submetering!P4+Submetering!Q4 -> 26930 | F4: 0.005 | G4: =Submetering!R4 -> 403.52471 | H4: 0.528 | I4: =Hotel!B9 -> 79
A5: Kuwait | B5: =B4+1 -> 4 | C5: 4 | D5: 2020 | E5: =Submetering!E5+Submetering!F5+Submetering!G5+Submetering!H5+Submetering!I5+Submetering!J5+Submetering!K5+Submetering!L5+Submetering!M5+Submetering!N5+Submetering!O5+Submetering!P5+Submetering!Q5 -> 27540 | F5: 0.005 | G5: =Submetering!R5 -> 397.46805 | H5: 0.528 | I5: =Hotel!B10 -> 6
A6: Kuwait | B6: =B5+1 -> 5 | C6: 4 | D6: 2020 | E6: =Submetering!E6+Submetering!F6+Submetering!G6+Submetering!H6+Submetering!I6+Submetering!J6+Submetering!K6+Submetering!L6+Submetering!M6+Submetering!N6+Submetering!O6+Submetering!P6+Submetering!Q6 -> 29280 | F6: 0.005 | G6: =Submetering!R6 -> 46.560543 | H6: 0.528 | I6: =Hotel!B11 -> 6
A7: Kuwait | B7: =B6+1 -> 6 | C7: 4 | D7: 2020 | E7: =Submetering!E7+Submetering!F7+Submetering!G7+Submetering!H7+Submetering!I7+Submetering!J7+Submetering!K7+Submetering!L7+Submetering!M7+Submetering!N7+Submetering!O7+Submetering!P7+Submetering!Q7 -> 27540 | F7: 0.005 | G7: =Submetering!R7 -> 52.99574 | H7: 0.528 | I7: =Hotel!B12 -> 7
A8: Kuwait | B8: =B7+1 -> 7 | C8: 4 | D8: 2020 | E8: =Submetering!E8+Submetering!F8+Submetering!G8+Submetering!H8+Submetering!I8+Submetering!J8+Submetering!K8+Submetering!L8+Submetering!M8+Submetering!N8+Submetering!O8+Submetering!P8+Submetering!Q8 -> 32190 | F8: 0.005 | G8: =Submetering!R8 -> 1501.6721 | H8: 0.528 | I8: =Hotel!B13 -> 4
A9: Kuwait | B9: =B8+1 -> 8 | C9: 4 | D9: 2020 | E9: =Submetering!E9+Submetering!F9+Submetering!G9+Submetering!H9+Submetering!I9+Submetering!J9+Submetering!K9+Submetering!L9+Submetering!M9+Submetering!N9+Submetering!O9+Submetering!P9+Submetering!Q9 -> 29170 | F9: 0.005 | G9: =Submetering!R9 -> 155.58035 | H9: 0.528 | I9: =Hotel!B14 -> 8
A10: Kuwait | B10: =B9+1 -> 9 | C10: 4 | D10: 2020 | E10: =Submetering!E10+Submetering!F10+Submetering!G10+Submetering!H10+Submetering!I10+Submetering!J10+Submetering!K10+Submetering!L10+Submetering!M10+Submetering!N10+Submetering!O10+Submetering!P10+Submetering!Q10 -> 31160 | F10: 0.005 | G10: =Submetering!R10 -> 566.29734 | H10: 0.528 | I10: =Hotel!B15 -> 14
A11: Kuwait | B11: =B10+1 -> 10 | C11: 4 | D11: 2020 | E11: =Submetering!E11+Submetering!F11+Submetering!G11+Submetering!H11+Submetering!I11+Submetering!J11+Submetering!K11+Submetering!L11+Submetering!M11+Submetering!N11+Submetering!O11+Submetering!P11+Submetering!Q11 -> 31726 | F11: 0.005 | G11: =Submetering!R11 -> 418.66635 | H11: 0.528 | I11: =Hotel!B16 -> 13
A12: Kuwait | B12: =B11+1 -> 11 | C12: 4 | D12: 2020 | E12: =Submetering!E12+Submetering!F12+Submetering!G12+Submetering!H12+Submetering!I12+Submetering!J12+Submetering!K12+Submetering!L12+Submetering!M12+Submetering!N12+Submetering!O12+Submetering!P12+Submetering!Q12 -> 32754 | F12: 0.005 | G12: =Submetering!R12 -> 540.93509 | H12: 0.528 | I12: =Hotel!B17 -> 5
A13: Kuwait | B13: =B12+1 -> 12 | C13: 4 | D13: 2020 | E13: =Submetering!E13+Submetering!F13+Submetering!G13+Submetering!H13+Submetering!I13+Submetering!J13+Submetering!K13+Submetering!L13+Submetering!M13+Submetering!N13+Submetering!O13+Submetering!P13+Submetering!Q13 -> 32180 | F13: 0.005 | G13: =Submetering!R13 -> 164.66533 | H13: 0.528 | I13: =Hotel!B18 -> 5
A14: Kuwait | B14: =B13+1 -> 13 | C14: 4 | D14: 2020 | E14: =Submetering!E14+Submetering!F14+Submetering!G14+Submetering!H14+Submetering!I14+Submetering!J14+Submetering!K14+Submetering!L14+Submetering!M14+Submetering!N14+Submetering!O14+Submetering!P14+Submetering!Q14 -> 32170 | F14: 0.005 | G14: =Submetering!R14 -> 393.3041 | H14: 0.528 | I14: =Hotel!B19 -> 4
... A32: Kuwait | B32: =B31+1 -> 31 | C32: 4 | D32: 2020 | E32: =Submetering!E32+Submetering!F32+Submetering!G32+Submetering!H32+Submetering!I32+Submetering!J32+Submetering!K32+Submetering!L32+Submetering!M32+Submetering!N32+Submetering!O32+Submetering!P32+Submetering!Q32 -> 0 | F32: 0.005 | G32: =Submetering!R32 -> 0 | H32: 0.528 | I32: =Hotel!B37 -> 0

Sheet Submetering
A1: Site Name | B1: Day | C1: Month | D1: Year | E1: HT.02.02 - KWh | F1: HT.02.04 - KWh | G1: HT.02.07 - KWh | H1: HT.02.03 - KWh | I1: HT.02.06 - KWh | J1: HT.03.03 - KWh | K1: HT.03.07 - KWh | L1: HT.03.05 - KWh | M1: HT.03.08 - KWh | N1: HT.03.04 - KWh | O1: HT.03.06 - KWh | P1: HT.03.01 - KWh | Q1: HT.03.02 - KWh | R1: Water - m3 | S1: Room Nights
A2: Kuwait | B2: 1 | C2: 4 | D2: 2020 | E2: =Hotel!Q7 -> 580 | F2: =Hotel!R7 -> 0 | G2: =Hotel!S7 -> 2510 | H2: =Hotel!T7 -> 1420 | I2: =Hotel!U7 -> 2640 | J2: =Hotel!V7 -> 2490 | K2: =Hotel!W7 -> 2090 | L2: =Hotel!X7 -> 940 | ... Q2: =Hotel!AC7 -> 3070 | R2: =Hotel!AV7*0.00378541*100 -> 412.23115 | S2: =Hotel!B7 -> 80
A3: Kuwait | B3: =B2+1 -> 2 | C3: 4 | D3: 2020 | E3: =Hotel!Q8 -> 570 | F3: =Hotel!R8 -> 3860 | G3: =Hotel!S8 -> 2720 | H3: =Hotel!T8 -> 1420 | I3: =Hotel!U8 -> 2780 | J3: =Hotel!V8 -> 2280 | K3: =Hotel!W8 -> 2120 | L3: =Hotel!X8 -> 950 | ... Q3: =Hotel!AC8 -> 3310 | R3: =Hotel!AV8*0.00378541*100 -> 596.58062 | S3: =Hotel!B8 -> 80
A4: Kuwait | B4: =B3+1 -> 3 | C4: 4 | D4: 2020 | E4: =Hotel!Q9 -> 540 | F4: =Hotel!R9 -> 1800 | G4: =Hotel!S9 -> 2570 | H4: =Hotel!T9 -> 1340 | I4: =Hotel!U9 -> 2540 | J4: =Hotel!V9 -> 2040 | K4: =Hotel!W9 -> 2010 | L4: =Hotel!X9 -> 950 | ... Q4: =Hotel!AC9 -> 3530 | R4: =Hotel!AV9*0.00378541*100 -> 403.52471 | S4: =Hotel!B9 -> 79
A5: Kuwait | B5: =B4+1 -> 4 | C5: 4 | D5: 2020 | E5: =Hotel!Q10 -> 560 | F5: =Hotel!R10 -> 1870 | G5: =Hotel!S10 -> 2660 | H5: =Hotel!T10 -> 1380 | I5: =Hotel!U10 -> 2730 | J5: =Hotel!V10 -> 2160 | K5: =Hotel!W10 -> 2080 | L5: =Hotel!X10 -> 990 | ... Q5: =Hotel!AC10 -> 3380 | R5: =Hotel!AV10*0.00378541*100 -> 397.46805 | S5: =Hotel!B10 -> 6
A6: Kuwait | B6: =B5+1 -> 5 | C6: 4 | D6: 2020 | E6: =Hotel!Q11 -> 560 | F6: =Hotel!R11 -> 1920 | G6: =Hotel!S11 -> 2930 | H6: =Hotel!T11 -> 1430 | I6: =Hotel!U11 -> 3010 | J6: =Hotel!V11 -> 2370 | K6: =Hotel!W11 -> 2140 | L6: =Hotel!X11 -> 1180 | ... Q6: =Hotel!AC11 -> 3560 | R6: =Hotel!AV11*0.00378541*100 -> 46.560543 | S6: =Hotel!B11 -> 6
A7: Kuwait | B7: =B6+1 -> 6 | C7: 4 | D7: 2020 | E7: =Hotel!Q12 -> 560 | F7: =Hotel!R12 -> 1800 | G7: =Hotel!S12 -> 2500 | H7: =Hotel!T12 -> 1400 | I7: =Hotel!U12 -> 3000 | J7: =Hotel!V12 -> 2030 | K7: =Hotel!W12 -> 2090 | L7: =Hotel!X12 -> 1000 | ... Q7: =Hotel!AC12 -> 3500 | R7: =Hotel!AV12*0.00378541*100 -> 52.99574 | S7: =Hotel!B12 -> 7
A8: Kuwait | B8: =B7+1 -> 7 | C8: 4 | D8: 2020 | E8: =Hotel!Q13 -> 580 | F8: =Hotel!R13 -> 2010 | G8: =Hotel!S13 -> 3460 | H8: =Hotel!T13 -> 1430 | I8: =Hotel!U13 -> 2610 | J8: =Hotel!V13 -> 2760 | K8: =Hotel!W13 -> 2100 | L8: =Hotel!X13 -> 1890 | ... Q8: =Hotel!AC13 -> 3970 | R8: =Hotel!AV13*0.00378541*100 -> 1501.6721 | S8: =Hotel!B13 -> 4
A9: Kuwait | B9: =B8+1 -> 8 | C9: 4 | D9: 2020 | E9: =Hotel!Q14 -> 530 | F9: =Hotel!R14 -> 1800 | G9: =Hotel!S14 -> 3080 | H9: =Hotel!T14 -> 1350 | I9: =Hotel!U14 -> 2690 | J9: =Hotel!V14 -> 2060 | K9: =Hotel!W14 -> 2000 | L9: =Hotel!X14 -> 1400 | ... Q9: =Hotel!AC14 -> 4080 | R9: =Hotel!AV14*0.00378541*100 -> 155.58035 | S9: =Hotel!B14 -> 8
A10: Kuwait | B10: =B9+1 -> 9 | C10: 4 | D10: 2020 | E10: =Hotel!Q15 -> 560 | F10: =Hotel!R15 -> 1910 | G10: =Hotel!S15 -> 3330 | H10: =Hotel!T15 -> 1380 | I10: =Hotel!U15 -> 2940 | J10: =Hotel!V15 -> 2270 | K10: =Hotel!W15 -> 2130 | L10: =Hotel!X15 -> 1480 | ... Q10: =Hotel!AC15 -> 4370 | R10: =Hotel!AV15*0.00378541*100 -> 566.29734 | S10: =Hotel!B15 -> 14
A11: Kuwait | B11: =B10+1 -> 10 | C11: 4 | D11: 2020 | E11: =Hotel!Q16 -> 570 | F11: =Hotel!R16 -> 1906 | G11: =Hotel!S16 -> 3510 | H11: =Hotel!T16 -> 1340 | I11: =Hotel!U16 -> 3040 | J11: =Hotel!V16 -> 2190 | K11: =Hotel!W16 -> 2100 | L11: =Hotel!X16 -> 1340 | ... Q11: =Hotel!AC16 -> 4540 | R11: =Hotel!AV16*0.00378541*100 -> 418.66635 | S11: =Hotel!B16 -> 13
A12: Kuwait | B12: =B11+1 -> 11 | C12: 4 | D12: 2020 | E12: =Hotel!Q17 -> 560 | F12: =Hotel!R17 -> 1914 | G12: =Hotel!S17 -> 3290 | H12: =Hotel!T17 -> 1440 | I12: =Hotel!U17 -> 3290 | J12: =Hotel!V17 -> 2380 | K12: =Hotel!W17 -> 2150 | L12: =Hotel!X17 -> 1400 | ... Q12: =Hotel!AC17 -> 4730 | R12: =Hotel!AV17*0.00378541*100 -> 540.93509 | S12: =Hotel!B17 -> 5
A13: Kuwait | B13: =B12+1 -> 12 | C13: 4 | D13: 2020 | E13: =Hotel!Q18 -> 570 | F13: =Hotel!R18 -> 1910 | G13: =Hotel!S18 -> 2910 | H13: =Hotel!T18 -> 1330 | I13: =Hotel!U18 -> 3070 | J13: =Hotel!V18 -> 2380 | K13: =Hotel!W18 -> 2130 | L13: =Hotel!X18 -> 1440 | ... Q13: =Hotel!AC18 -> 4970 | R13: =Hotel!AV18*0.00378541*100 -> 164.66533 | S13: =Hotel!B18 -> 5
A14: Kuwait | B14: =B13+1 -> 13 | C14: 4 | D14: 2020 | E14: =Hotel!Q19 -> 550 | F14: =Hotel!R19 -> 1850 | G14: =Hotel!S19 -> 2790 | H14: =Hotel!T19 -> 1470 | I14: =Hotel!U19 -> 2810 | J14: =Hotel!V19 -> 2320 | K14: =Hotel!W19 -> 2040 | L14: =Hotel!X19 -> 1290 | ... Q14: =Hotel!AC19 -> 5640 | R14: =Hotel!AV19*0.00378541*100 -> 393.3041 | S14: =Hotel!B19 -> 4
A15: Kuwait | B15: =B14+1 -> 14 | C15: 4 | D15: 2020 | E15: =Hotel!Q20 -> 0 | F15: =Hotel!R20 -> 0 | G15: =Hotel!S20 -> 0 | H15: =Hotel!T20 -> 0 | I15: =Hotel!U20 -> 0 | J15: =Hotel!V20 -> 0 | K15: =Hotel!W20 -> 0 | L15: =Hotel!X20 -> 0 | ... Q15: =Hotel!AC20 -> 0 | R15: =Hotel!AV20*0.00378541*100 -> 0 | S15: =Hotel!B20 -> 0
A16: Kuwait | B16: =B15+1 -> 15 | C16: 4 | D16: 2020 | E16: =Hotel!Q21 -> 0 | F16: =Hotel!R21 -> 0 | G16: =Hotel!S21 -> 0 | H16: =Hotel!T21 -> 0 | I16: =Hotel!U21 -> 0 | J16: =Hotel!V21 -> 0 | K16: =Hotel!W21 -> 0 | L16: =Hotel!X21 -> 0 | ... Q16: =Hotel!AC21 -> 0 | R16: =Hotel!AV21*0.00378541*100 -> 0 | S16: 38
A17: Kuwait | B17: =B16+1 -> 16 | C17: 4 | D17: 2020 | E17: =Hotel!Q22 -> 0 | F17: =Hotel!R22 -> 0 | G17: =Hotel!S22 -> 0 | H17: =Hotel!T22 -> 0 | I17: =Hotel!U22 -> 0 | J17: =Hotel!V22 -> 0 | K17: =Hotel!W22 -> 0 | L17: =Hotel!X22 -> 0 | ... Q17: =Hotel!AC22 -> 0 | R17: =Hotel!AV22*0.00378541*100 -> 0 | S17: 41
A18: Kuwait | B18: =B17+1 -> 17 | C18: 4 | D18: 2020 | E18: =Hotel!Q23 -> 0 | F18: =Hotel!R23 -> 0 | G18: =Hotel!S23 -> 0 | H18: =Hotel!T23 -> 0 | I18: =Hotel!U23 -> 0 | J18: =Hotel!V23 -> 0 | K18: =Hotel!W23 -> 0 | L18: =Hotel!X23 -> 0 | ... Q18: =Hotel!AC23 -> 0 | R18: =Hotel!AV23*0.00378541*100 -> 0 | S18: =Hotel!B23 -> 0
A19: Kuwait | B19: =B18+1 -> 18 | C19: 4 | D19: 2020 | E19: =Hotel!Q24 -> 0 | F19: =Hotel!R24 -> 0 | G19: =Hotel!S24 -> 0 | H19: =Hotel!T24 -> 0 | I19: =Hotel!U24 -> 0 | J19: =Hotel!V24 -> 0 | K19: =Hotel!W24 -> 0 | L19: =Hotel!X24 -> 0 | ... Q19: =Hotel!AC24 -> 0 | R19: =Hotel!AV24*0.00378541*100 -> 0 | S19: =Hotel!B24 -> 0
A20: Kuwait | B20: =B19+1 -> 19 | C20: 4 | D20: 2020 | E20: =Hotel!Q25 -> 0 | F20: =Hotel!R25 -> 0 | G20: =Hotel!S25 -> 0 | H20: =Hotel!T25 -> 0 | I20: =Hotel!U25 -> 0 | J20: =Hotel!V25 -> 0 | K20: =Hotel!W25 -> 0 | L20: =Hotel!X25 -> 0 | ... Q20: =Hotel!AC25 -> 0 | R20: =Hotel!AV25*0.00378541*100 -> 0 | S20: =Hotel!B25 -> 0
A21: Kuwait | B21: =B20+1 -> 20 | C21: 4 | D21: 2020 | E21: =Hotel!Q26 -> 0 | F21: =Hotel!R26 -> 0 | G21: =Hotel!S26 -> 0 | H21: =Hotel!T26 -> 0 | I21: =Hotel!U26 -> 0 | J21: =Hotel!V26 -> 0 | K21: =Hotel!W26 -> 0 | L21: =Hotel!X26 -> 0 | ... Q21: =Hotel!AC26 -> 0 | R21: =Hotel!AV26*0.00378541*100 -> 0 | S21: =Hotel!B26 -> 0
A22: Kuwait | B22: =B21+1 -> 21 | C22: 4 | D22: 2020 | E22: =Hotel!Q27 -> 0 | F22: =Hotel!R27 -> 0 | G22: =Hotel!S27 -> 0 | H22: =Hotel!T27 -> 0 | I22: =Hotel!U27 -> 0 | J22: =Hotel!V27 -> 0 | K22: =Hotel!W27 -> 0 | L22: =Hotel!X27 -> 0 | ... Q22: =Hotel!AC27 -> 0 | R22: =Hotel!AV27*0.00378541*100 -> 0 | S22: =Hotel!B27 -> 0
A23: Kuwait | B23: =B22+1 -> 22 | C23: 4 | D23: 2020 | E23: =Hotel!Q28 -> 0 | F23: =Hotel!R28 -> 0 | G23: =Hotel!S28 -> 0 | H23: =Hotel!T28 -> 0 | I23: =Hotel!U28 -> 0 | J23: =Hotel!V28 -> 0 | K23: =Hotel!W28 -> 0 | L23: =Hotel!X28 -> 0 | ... Q23: =Hotel!AC28 -> 0 | R23: =Hotel!AV28*0.00378541*100 -> 0 | S23: =Hotel!B28 -> 0
A24: Kuwait | B24: =B23+1 -> 23 | C24: 4 | D24: 2020 | E24: =Hotel!Q29 -> 0 | F24: =Hotel!R29 -> 0 | G24: =Hotel!S29 -> 0 | H24: =Hotel!T29 -> 0 | I24: =Hotel!U29 -> 0 | J24: =Hotel!V29 -> 0 | K24: =Hotel!W29 -> 0 | L24: =Hotel!X29 -> 0 | ... Q24: =Hotel!AC29 -> 0 | R24: =Hotel!AV29*0.00378541*100 -> 0 | S24: =Hotel!B29 -> 0
A25: Kuwait | B25: =B24+1 -> 24 | C25: 4 | D25: 2020 | E25: =Hotel!Q30 -> 0 | F25: =Hotel!R30 -> 0 | G25: =Hotel!S30 -> 0 | H25: =Hotel!T30 -> 0 | I25: =Hotel!U30 -> 0 | J25: =Hotel!V30 -> 0 | K25: =Hotel!W30 -> 0 | L25: =Hotel!X30 -> 0 | ... Q25: =Hotel!AC30 -> 0 | R25: =Hotel!AV30*0.00378541*100 -> 0 | S25: =Hotel!B30 -> 0
A26: Kuwait | B26: =B25+1 -> 25 | C26: 4 | D26: 2020 | E26: =Hotel!Q31 -> 0 | F26: =Hotel!R31 -> 0 | G26: =Hotel!S31 -> 0 | H26: =Hotel!T31 -> 0 | I26: =Hotel!U31 -> 0 | J26: =Hotel!V31 -> 0 | K26: =Hotel!W31 -> 0 | L26: =Hotel!X31 -> 0 | ... Q26: =Hotel!AC31 -> 0 | R26: =Hotel!AV31*0.00378541*100 -> 0 | S26: =Hotel!B31 -> 0
A27: Kuwait | B27: =B26+1 -> 26 | C27: 4 | D27: 2020 | E27: =Hotel!Q32 -> 0 | F27: =Hotel!R32 -> 0 | G27: =Hotel!S32 -> 0 | H27: =Hotel!T32 -> 0 | I27: =Hotel!U32 -> 0 | J27: =Hotel!V32 -> 0 | K27: =Hotel!W32 -> 0 | L27: =Hotel!X32 -> 0 | ... Q27: =Hotel!AC32 -> 0 | R27: =Hotel!AV32*0.00378541*100 -> 0 | S27: =Hotel!B32 -> 0
A28: Kuwait | B28: =B27+1 -> 27 | C28: 4 | D28: 2020 | E28: =Hotel!Q33 -> 0 | F28: =Hotel!R33 -> 0 | G28: =Hotel!S33 -> 0 | H28: =Hotel!T33 -> 0 | I28: =Hotel!U33 -> 0 | J28: =Hotel!V33 -> 0 | K28: =Hotel!W33 -> 0 | L28: =Hotel!X33 -> 0 | ... Q28: =Hotel!AC33 -> 0 | R28: =Hotel!AV33*0.00378541*100 -> 0 | S28: =Hotel!B33 -> 0
A29: Kuwait | B29: =B28+1 -> 28 | C29: 4 | D29: 2020 | E29: =Hotel!Q34 -> 0 | F29: =Hotel!R34 -> 0 | G29: =Hotel!S34 -> 0 | H29: =Hotel!T34 -> 0 | I29: =Hotel!U34 -> 0 | J29: =Hotel!V34 -> 0 | K29: =Hotel!W34 -> 0 | L29: =Hotel!X34 -> 0 | ... Q29: =Hotel!AC34 -> 0 | R29: =Hotel!AV34*0.00378541*100 -> 0 | S29: =Hotel!B34 -> 0
... A32: Kuwait | B32: =B31+1 -> 31 | C32: 4 | D32: 2020 | E32: =Hotel!Q37 -> 0 | F32: =Hotel!R37 -> 0 | G32: =Hotel!S37 -> 0 | H32: =Hotel!T37 -> 0 | I32: =Hotel!U37 -> 0 | J32: =Hotel!V37 -> 0 | K32: =Hotel!W37 -> 0 | L32: =Hotel!X37 -> 0 | ... Q32: =Hotel!AC37 -> 0 | R32: =Hotel!AV37*0.00378541*100 -> 0 | S32: =Hotel!B37 -> 0

Sheet Hotel
C1: 1 | D1: 2 | E1: 3 | F1: 4 | G1: 5 | H1: 6 | I1: 7 | J1: 8 | K1: 9 | L1: 10 | M1: 11 | N1: 12 | O1: 13 | Q1: 1 | R1: 2 | S1: 3 | T1: 4 | U1: 5 | V1: 6 | W1: 7 | X1: 8 | Y1: 9 | Z1: 10 | AA1: 11 | AB1: 12 | AC1: 13
A2: 43921 | B2: 10 | C2: 5972110 | D2: 12917870 | E2: 1603830 | F2: 2774540 | G2: 8633410 | H2: 4267620 | I2: 4099910 | J2: 4698530 | K2: 7408570 | L2: 2755500 | M2: 6699730 | N2: 9438740 | O2: 12901680 | Q2: HT.02.02 | R2: HT.02.04 | S2: HT.02.07 | T2: HT.02.03 | U2: HT.02.06 | V2: HT.03.03 | W2: HT.03.07 | X2: HT.03.05 | Y2: HT.03.08 | Z2: HT.03.04 | AA2: HT.03.06 | AB2: HT.03.01 | AC2: HT.03.02 | AU2: 873470
A4: Date | B4: Room Night | C4: April | D4: Electricity - Meter No | Q4: Electricity Consumption -KWh | AD4: Total KWh | AF4: Electricity Consumption - Amount | AS4: Total Kd | AU4: Water Meter Reading | AV4: Consumption Gallons | AW4: Total KD
A5: 2020 | C5: HT.02.02 | D5: HT.02.04 | E5: HT.02.07 | F5: HT.02.03 | G5: HT.02.06 | H5: HT.03.03 | I5: HT.03.07 | J5: HT.03.05 | K5: HT.03.08 | L5: HT.03.04 | M5: HT.03.06 | N5: HT.03.01 | O5: HT.03.02 | Q5: 8483196 | R5: 8483193 | S5: 8483178 | T5: 8483176 | U5: 8483206 | V5: 8483170 | W5: 8483168 | X5: 8483169 | Y5: 8483194 | Z5: 8483199 | AA5: 8483187 | AB5: 8483188 | AC5: 8483174 | AF5: 1 | AG5: 2 | AH5: 3 | AI5: 4 | AJ5: 5 | AK5: 6 | AL5: 7 | AM5: 8 | AN5: 9 | AO5: 10 | AP5: 11 | AQ5: 12 | AR5: 13
C6: 8483196 | D6: 8483193 | E6: 8483178 | F6: 8483176 | G6: 8483206 | H6: 8483170 | I6: 8483168 | J6: 8483169 | K6: 8483194 | L6: 8483199 | M6: 8483187 | N6: 8483188 | O6: 8483174 | AU6: 873470
A7: 43922 | B7: 80 | C7: 5972690 | D7: 12917870 | E7: 1606340 | F7: 2775960 | G7: 8636050 | H7: 4270110 | I7: 4102000 | J7: 4699470 | K7: 7410690 | L7: 2757400 | M7: 6700750 | N7: 9442830 | O7: 12904750 | Q7: =IF((C7-C2<0), "0",C7-C2) -> 580 | R7: =IF((D7-D2<0), "0",D7-D2) -> 0 | S7: =IF((E7-E2<0), "0",E7-E2) -> 2510 | T7: =IF((F7-F2<0), "0",F7-F2) -> 1420 | U7: =IF((G7-G2<0), "0",G7-G2) -> 2640 | V7: =IF((H7-H2<0), "0",H7-H2) -> 2490 | W7: =IF((I7-I2<0), "0",I7-I2) -> 2090 | X7: =IF((J7-J2<0), "0",J7-J2) -> 940 | ... AC7: =IF((O7-O2<0), "0",O7-O2) -> 3070 | AD7: =SUM(Q7:AC7) -> 24870 | AF7: =Q7*$D$39 -> 2.9 | AG7: =R7*$D$39 -> 0 | AH7: =S7*$D$39 -> 12.55 | AI7: =T7*$D$39 -> 7.1 | AJ7: =U7*$D$39 -> 13.2 | AK7: =V7*$D$39 -> 12.45 | AL7: =W7*$D$39 -> 10.45 | AM7: =X7*$D$39 -> 4.7 | ... AR7: =AC7*$D$39 -> 15.35 | AS7: =SUM(AF7:AR7) -> 124.35 | AU7: 874559 | AV7: =IF((AU7-AU6<0),"0",AU7-AU6) -> 1089 | AW7: 0
A8: 43923 | B8: 80 | C8: 5973260 | D8: 12921730 | E8: 1609060 | F8: 2777380 | G8: 8638830 | H8: 4272390 | I8: 4104120 | J8: 4700420 | K8: 7412810 | L8: 2759640 | M8: 6701980 | N8: 9446900 | O8: 12908060 | Q8: =IF((C8-C7<0), "0",C8-C7) -> 570 | R8: =IF((D8-D7<0), "0",D8-D7) -> 3860 | S8: =IF((E8-E7<0), "0",E8-E7) -> 2720 | T8: =IF((F8-F7<0), "0",F8-F7) -> 1420 | U8: =IF((G8-G7<0), "0",G8-G7) -> 2780 | V8: =IF((H8-H7<0), "0",H8-H7) -> 2280 | W8: =IF((I8-I7<0), "0",I8-I7) -> 2120 | X8: =IF((J8-J7<0), "0",J8-J7) -> 950 | ... AC8: =IF((O8-O7<0), "0",O8-O7) -> 3310 | AD8: =SUM(Q8:AC8) -> 29670 | AF8: =Q8*$D$39 -> 2.85 | AG8: =R8*$D$39 -> 19.3 | AH8: =S8*$D$39 -> 13.6 | AI8: =T8*$D$39 -> 7.1 | AJ8: =U8*$D$39 -> 13.9 | AK8: =V8*$D$39 -> 11.4 | AL8: =W8*$D$39 -> 10.6 | AM8: =X8*$D$39 -> 4.75 | ... AR8: =AC8*$D$39 -> 16.55 | AS8: =SUM(AF8:AR8) -> 148.35 | AU8: 876135 | AV8: =IF((AU8-AU7<0),"0",AU8-AU7) -> 1576 | AW8: 0
A9: 43924 | B9: 79 | C9: 5973800 | D9: 12923530 | E9: 1611630 | F9: 2778720 | G9: 8641370 | H9: 4274430 | I9: 4106130 | J9: 4701370 | K9: 7414790 | L9: 2761700 | M9: 6703490 | N9: 9450960 | O9: 12911590 | Q9: =IF((C9-C8<0), "0",C9-C8) -> 540 | R9: =IF((D9-D8<0), "0",D9-D8) -> 1800 | S9: =IF((E9-E8<0), "0",E9-E8) -> 2570 | T9: =IF((F9-F8<0), "0",F9-F8) -> 1340 | U9: =IF((G9-G8<0), "0",G9-G8) -> 2540 | V9: =IF((H9-H8<0), "0",H9-H8) -> 2040 | W9: =IF((I9-I8<0), "0",I9-I8) -> 2010 | X9: =IF((J9-J8<0), "0",J9-J8) -> 950 | ... AC9: =IF((O9-O8<0), "0",O9-O8) -> 3530 | AD9: =SUM(Q9:AC9) -> 26930 | AF9: =Q9*$D$39 -> 2.7 | AG9: =R9*$D$39 -> 9 | AH9: =S9*$D$39 -> 12.85 | AI9: =T9*$D$39 -> 6.7 | AJ9: =U9*$D$39 -> 12.7 | AK9: =V9*$D$39 -> 10.2 | AL9: =W9*$D$39 -> 10.05 | AM9: =X9*$D$39 -> 4.75 | ... AR9: =AC9*$D$39 -> 17.65 | AS9: =SUM(AF9:AR9) -> 134.65 | AU9: 877201 | AV9: =IF((AU9-AU8<0),"0",AU9-AU8) -> 1066 | AW9: =AV9*$D$40 -> 2.132
A10: 43925 | B10: 6 | C10: 5974360 | D10: 12925400 | E10: 1614290 | F10: 2780100 | G10: 8644100 | H10: 4276590 | I10: 4108210 | J10: 4702360 | K10: 7416930 | L10: 2763730 | M10: 6704950 | N10: 9455060 | O10: 12914970 | Q10: =IF((C10-C9<0), "0",C10-C9) -> 560 | R10: =IF((D10-D9<0), "0",D10-D9) -> 1870 | S10: =IF((E10-E9<0), "0",E10-E9) -> 2660 | T10: =IF((F10-F9<0), "0",F10-F9) -> 1380 | U10: =IF((G10-G9<0), "0",G10-G9) -> 2730 | V10: =IF((H10-H9<0), "0",H10-H9) -> 2160 | W10: =IF((I10-I9<0), "0",I10-I9) -> 2080 | X10: =IF((J10-J9<0), "0",J10-J9) -> 990 | ... AC10: =IF((O10-O9<0), "0",O10-O9) -> 3380 | AD10: =SUM(Q10:AC10) -> 27540 | AF10: =Q10*$D$39 -> 2.8 | AG10: =R10*$D$39 -> 9.35 | AH10: =S10*$D$39 -> 13.3 | AI10: =T10*$D$39 -> 6.9 | AJ10: =U10*$D$39 -> 13.65 | AK10: =V10*$D$39 -> 10.8 | AL10: =W10*$D$39 -> 10.4 | AM10: =X10*$D$39 -> 4.95 | ... AR10: =AC10*$D$39 -> 16.9 | AS10: =SUM(AF10:AR10) -> 137.7 | AU10: 878251 | AV10: =IF((AU10-AU9<0),"0",AU10-AU9) -> 1050 | AW10: =AV10*$D$40 -> 2.1
A11: 43926 | B11: 6 | C11: 5974920 | D11: 12927320 | E11: 1617220 | F11: 2781530 | G11: 8647110 | H11: 4278960 | I11: 4110350 | J11: 4703540 | K11: 7419120 | L11: 2765790 | M11: 6706520 | N11: 9459420 | O11: 12918530 | Q11: =IF((C11-C10<0), "0",C11-C10) -> 560 | R11: =IF((D11-D10<0), "0",D11-D10) -> 1920 | S11: =IF((E11-E10<0), "0",E11-E10) -> 2930 | T11: =IF((F11-F10<0), "0",F11-F10) -> 1430 | U11: =IF((G11-G10<0), "0",G11-G10) -> 3010 | V11: =IF((H11-H10<0), "0",H11-H10) -> 2370 | W11: =IF((I11-I10<0), "0",I11-I10) -> 2140 | X11: =IF((J11-J10<0), "0",J11-J10) -> 1180 | ... AC11: =IF((O11-O10<0), "0",O11-O10) -> 3560 | AD11: =SUM(Q11:AC11) -> 29280 | AF11: =Q11*$D$39 -> 2.8 | AG11: =R11*$D$39 -> 9.6 | AH11: =S11*$D$39 -> 14.65 | AI11: =T11*$D$39 -> 7.15 | AJ11: =U11*$D$39 -> 15.05 | AK11: =V11*$D$39 -> 11.85 | AL11: =W11*$D$39 -> 10.7 | AM11: =X11*$D$39 -> 5.9 | ... AR11: =AC11*$D$39 -> 17.8 | AS11: =SUM(AF11:AR11) -> 146.4 | AU11: 878374 | AV11: =IF((AU11-AU10<0),"0",AU11-AU10) -> 123 | AW11: =AV11*$D$40 -> 0.246
A12: 43927 | B12: 7 | C12: 5975480 | D12: 12929120 | E12: 1619720 | F12: 2782930 | G12: 8650110 | H12: 4280990 | I12: 4112440 | J12: 4704540 | K12: 7421120 | L12: 2767850 | M12: 6708020 | N12: 9463520 | O12: 12922030 | Q12: =IF((C12-C11<0), "0",C12-C11) -> 560 | R12: =IF((D12-D11<0), "0",D12-D11) -> 1800 | S12: =IF((E12-E11<0), "0",E12-E11) -> 2500 | T12: =IF((F12-F11<0), "0",F12-F11) -> 1400 | U12: =IF((G12-G11<0), "0",G12-G11) -> 3000 | V12: =IF((H12-H11<0), "0",H12-H11) -> 2030 | W12: =IF((I12-I11<0), "0",I12-I11) -> 2090 | X12: =IF((J12-J11<0), "0",J12-J11) -> 1000 | ... AC12: =IF((O12-O11<0), "0",O12-O11) -> 3500 | AD12: =SUM(Q12:AC12) -> 27540 | AF12: =Q12*$D$39 -> 2.8 | AG12: =R12*$D$39 -> 9 | AH12: =S12*$D$39 -> 12.5 | AI12: =T12*$D$39 -> 7 | AJ12: =U12*$D$39 -> 15 | AK12: =V12*$D$39 -> 10.15 | AL12: =W12*$D$39 -> 10.45 | AM12: =X12*$D$39 -> 5 | ... AR12: =AC12*$D$39 -> 17.5 | AS12: =SUM(AF12:AR12) -> 137.7 | AU12: 878514 | AV12: =IF((AU12-AU11<0),"0",AU12-AU11) -> 140 | AW12: =AV12*$D$40 -> 0.28
A13: 43928 | B13: 4 | C13: 5976060 | D13: 12931130 | E13: 1623180 | F13: 2784360 | G13: 8652720 | H13: 4283750 | I13: 4114540 | J13: 4706430 | K13: 7423290 | L13: 2770190 | M13: 6710750 | N13: 9467660 | O13: 12926000 | Q13: =IF((C13-C12<0), "0",C13-C12) -> 580 | R13: =IF((D13-D12<0), "0",D13-D12) -> 2010 | S13: =IF((E13-E12<0), "0",E13-E12) -> 3460 | T13: =IF((F13-F12<0), "0",F13-F12) -> 1430 | U13: =IF((G13-G12<0), "0",G13-G12) -> 2610 | V13: =IF((H13-H12<0), "0",H13-H12) -> 2760 | W13: =IF((I13-I12<0), "0",I13-I12) -> 2100 | X13: =IF((J13-J12<0), "0",J13-J12) -> 1890 | ... AC13: =IF((O13-O12<0), "0",O13-O12) -> 3970 | AD13: =SUM(Q13:AC13) -> 32190 | AF13: =Q13*$D$39 -> 2.9 | AG13: =R13*$D$39 -> 10.05 | AH13: =S13*$D$39 -> 17.3 | AI13: =T13*$D$39 -> 7.15 | AJ13: =U13*$D$39 -> 13.05 | AK13: =V13*$D$39 -> 13.8 | AL13: =W13*$D$39 -> 10.5 | AM13: =X13*$D$39 -> 9.45 | ... AR13: =AC13*$D$39 -> 19.85 | AS13: =SUM(AF13:AR13) -> 160.95 | AU13: 882481 | AV13: =IF((AU13-AU12<0),"0",AU13-AU12) -> 3967 | AW13: =AV13*$D$40 -> 7.934
A14: 43929 | B14: 8 | C14: 5976590 | D14: 12932930 | E14: 1626260 | F14: 2785710 | G14: 8655410 | H14: 4285810 | I14: 4116540 | J14: 4707830 | K14: 7425410 | L14: 2772250 | M14: 6712750 | N14: 9471660 | O14: 12930080 | Q14: =IF((C14-C13<0), "0",C14-C13) -> 530 | R14: =IF((D14-D13<0), "0",D14-D13) -> 1800 | S14: =IF((E14-E13<0), "0",E14-E13) -> 3080 | T14: =IF((F14-F13<0), "0",F14-F13) -> 1350 | U14: =IF((G14-G13<0), "0",G14-G13) -> 2690 | V14: =IF((H14-H13<0), "0",H14-H13) -> 2060 | W14: =IF((I14-I13<0), "0",I14-I13) -> 2000 | X14: =IF((J14-J13<0), "0",J14-J13) -> 1400 | ... AC14: =IF((O14-O13<0), "0",O14-O13) -> 4080 | AD14: =SUM(Q14:AC14) -> 29170 | AF14: =Q14*$D$39 -> 2.65 | AG14: =R14*$D$39 -> 9 | AH14: =S14*$D$39 -> 15.4 | AI14: =T14*$D$39 -> 6.75 | AJ14: =U14*$D$39 -> 13.45 | AK14: =V14*$D$39 -> 10.3 | AL14: =W14*$D$39 -> 10 | AM14: =X14*$D$39 -> 7 | ... AR14: =AC14*$D$39 -> 20.4 | AS14: =SUM(AF14:AR14) -> 145.85 | AU14: 882892 | AV14: =IF((AU14-AU13<0),"0",AU14-AU13) -> 411 | AW14: =AV14*$D$40 -> 0.822
A15: 43930 | B15: 14 | C15: 5977150 | D15: 12934840 | E15: 1629590 | F15: 2787090 | G15: 8658350 | H15: 4288080 | I15: 4118670 | J15: 4709310 | K15: 7427690 | L15: 2774610 | M15: 6714670 | N15: 9475890 | O15: 12934450 | Q15: =IF((C15-C14<0), "0",C15-C14) -> 560 | R15: =IF((D15-D14<0), "0",D15-D14) -> 1910 | S15: =IF((E15-E14<0), "0",E15-E14) -> 3330 | T15: =IF((F15-F14<0), "0",F15-F14) -> 1380 | U15: =IF((G15-G14<0), "0",G15-G14) -> 2940 | V15: =IF((H15-H14<0), "0",H15-H14) -> 2270 | W15: =IF((I15-I14<0), "0",I15-I14) -> 2130 | X15: =IF((J15-J14<0), "0",J15-J14) -> 1480 | ... AC15: =IF((O15-O14<0), "0",O15-O14) -> 4370 | AD15: =SUM(Q15:AC15) -> 31160 | AF15: =Q15*$D$39 -> 2.8 | AG15: =R15*$D$39 -> 9.55 | AH15: =S15*$D$39 -> 16.65 | AI15: =T15*$D$39 -> 6.9 | AJ15: =U15*$D$39 -> 14.7 | AK15: =V15*$D$39 -> 11.35 | AL15: =W15*$D$39 -> 10.65 | AM15: =X15*$D$39 -> 7.4 | ... AR15: =AC15*$D$39 -> 21.85 | AS15: =SUM(AF15:AR15) -> 155.8 | AU15: 884388 | AV15: =IF((AU15-AU14<0),"0",AU15-AU14) -> 1496 | AW15: =AV15*$D$40 -> 2.992
A16: 43931 | B16: 13 | C16: 5977720 | D16: 12936746 | E16: 1633100 | F16: 2788430 | G16: 8661390 | H16: 4290270 | I16: 4120770 | J16: 4710650 | K16: 7430240 | L16: 2776930 | M16: 6716790 | N16: 9480090 | O16: 12938990 | Q16: =IF((C16-C15<0), "0",C16-C15) -> 570 | R16: =IF((D16-D15<0), "0",D16-D15) -> 1906 | S16: =IF((E16-E15<0), "0",E16-E15) -> 3510 | T16: =IF((F16-F15<0), "0",F16-F15) -> 1340 | U16: =IF((G16-G15<0), "0",G16-G15) -> 3040 | V16: =IF((H16-H15<0), "0",H16-H15) -> 2190 | W16: =IF((I16-I15<0), "0",I16-I15) -> 2100 | X16: =IF((J16-J15<0), "0",J16-J15) -> 1340 | ... AC16: =IF((O16-O15<0), "0",O16-O15) -> 4540 | AD16: =SUM(Q16:AC16) -> 31726 | AF16: =Q16*$D$39 -> 2.85 | AG16: =R16*$D$39 -> 9.53 | AH16: =S16*$D$39 -> 17.55 | AI16: =T16*$D$39 -> 6.7 | AJ16: =U16*$D$39 -> 15.2 | AK16: =V16*$D$39 -> 10.95 | AL16: =W16*$D$39 -> 10.5 | AM16: =X16*$D$39 -> 6.7 | ... AR16: =AC16*$D$39 -> 22.7 | AS16: =SUM(AF16:AR16) -> 158.63 | AU16: 885494 | AV16: =IF((AU16-AU15<0),"0",AU16-AU15) -> 1106 | AW16: =AV16*$D$40 -> 2.212
A17: 43932 | B17: 5 | C17: 5978280 | D17: 12938660 | E17: 1636390 | F17: 2789870 | G17: 8664680 | H17: 4292650 | I17: 4122920 | J17: 4712050 | K17: 7433070 | L17: 2779230 | M17: 6719200 | N17: 9484150 | O17: 12943720 | Q17: =IF((C17-C16<0), "0",C17-C16) -> 560 | R17: =IF((D17-D16<0), "0",D17-D16) -> 1914 | S17: =IF((E17-E16<0), "0",E17-E16) -> 3290 | T17: =IF((F17-F16<0), "0",F17-F16) -> 1440 | U17: =IF((G17-G16<0), "0",G17-G16) -> 3290 | V17: =IF((H17-H16<0), "0",H17-H16) -> 2380 | W17: =IF((I17-I16<0), "0",I17-I16) -> 2150 | X17: =IF((J17-J16<0), "0",J17-J16) -> 1400 | ... AC17: =IF((O17-O16<0), "0",O17-O16) -> 4730 | AD17: =SUM(Q17:AC17) -> 32754 | AF17: =Q17*$D$39 -> 2.8 | AG17: =R17*$D$39 -> 9.57 | AH17: =S17*$D$39 -> 16.45 | AI17: =T17*$D$39 -> 7.2 | AJ17: =U17*$D$39 -> 16.45 | AK17: =V17*$D$39 -> 11.9 | AL17: =W17*$D$39 -> 10.75 | AM17: =X17*$D$39 -> 7 | ... AR17: =AC17*$D$39 -> 23.65 | AS17: =SUM(AF17:AR17) -> 163.77 | AU17: 886923 | AV17: =IF((AU17-AU16<0),"0",AU17-AU16) -> 1429 | AW17: =AV17*$D$40 -> 2.858
A18: 43933 | B18: 5 | C18: 5978850 | D18: 12940570 | E18: 1639300 | F18: 2791200 | G18: 8667750 | H18: 4295030 | I18: 4125050 | J18: 4713490 | K18: 7436050 | L18: 2781490 | M18: 6721500 | N18: 9488080 | O18: 12948690 | Q18: =IF((C18-C17<0), "0",C18-C17) -> 570 | R18: =IF((D18-D17<0), "0",D18-D17) -> 1910 | S18: =IF((E18-E17<0), "0",E18-E17) -> 2910 | T18: =IF((F18-F17<0), "0",F18-F17) -> 1330 | U18: =IF((G18-G17<0), "0",G18-G17) -> 3070 | V18: =IF((H18-H17<0), "0",H18-H17) -> 2380 | W18: =IF((I18-I17<0), "0",I18-I17) -> 2130 | X18: =IF((J18-J17<0), "0",J18-J17) -> 1440 | ... AC18: =IF((O18-O17<0), "0",O18-O17) -> 4970 | AD18: =SUM(Q18:AC18) -> 32180 | AF18: =Q18*$D$39 -> 2.85 | AG18: =R18*$D$39 -> 9.55 | AH18: =S18*$D$39 -> 14.55 | AI18: =T18*$D$39 -> 6.65 | AJ18: =U18*$D$39 -> 15.35 | AK18: =V18*$D$39 -> 11.9 | AL18: =W18*$D$39 -> 10.65 | AM18: =X18*$D$39 -> 7.2 | ... AR18: =AC18*$D$39 -> 24.85 | AS18: =SUM(AF18:AR18) -> 160.9 | AU18: 887358 | AV18: =IF((AU18-AU17<0),"0",AU18-AU17) -> 435 | AW18: =AV18*$D$40 -> 0.87
A19: 43934 | B19: 4 | C19: 5979400 | D19: 12942420 | E19: 1642090 | F19: 2792670 | G19: 8670560 | H19: 4297350 | I19: 4127090 | J19: 4714780 | K19: 7439030 | L19: 2783700 | M19: 6723630 | N19: 9492170 | O19: 12954330 | Q19: =IF((C19-C18<0), "0",C19-C18) -> 550 | R19: =IF((D19-D18<0), "0",D19-D18) -> 1850 | S19: =IF((E19-E18<0), "0",E19-E18) -> 2790 | T19: =IF((F19-F18<0), "0",F19-F18) -> 1470 | U19: =IF((G19-G18<0), "0",G19-G18) -> 2810 | V19: =IF((H19-H18<0), "0",H19-H18) -> 2320 | W19: =IF((I19-I18<0), "0",I19-I18) -> 2040 | X19: =IF((J19-J18<0), "0",J19-J18) -> 1290 | ... AC19: =IF((O19-O18<0), "0",O19-O18) -> 5640 | AD19: =SUM(Q19:AC19) -> 32170 | AF19: =Q19*$D$39 -> 2.75 | AG19: =R19*$D$39 -> 9.25 | AH19: =S19*$D$39 -> 13.95 | AI19: =T19*$D$39 -> 7.35 | AJ19: =U19*$D$39 -> 14.05 | AK19: =V19*$D$39 -> 11.6 | AL19: =W19*$D$39 -> 10.2 | AM19: =X19*$D$39 -> 6.45 | ... AR19: =AC19*$D$39 -> 28.2 | AS19: =SUM(AF19:AR19) -> 160.85 | AU19: 888397 | AV19: =IF((AU19-AU18<0),"0",AU19-AU18) -> 1039 | AW19: =AV19*$D$40 -> 2.078
A20: 43935 | Q20: =IF((C20-C19<0), "0",C20-C19) -> 0 | R20: =IF((D20-D19<0), "0",D20-D19) -> 0 | S20: =IF((E20-E19<0), "0",E20-E19) -> 0 | T20: =IF((F20-F19<0), "0",F20-F19) -> 0 | U20: =IF((G20-G19<0), "0",G20-G19) -> 0 | V20: =IF((H20-H19<0), "0",H20-H19) -> 0 | W20: =IF((I20-I19<0), "0",I20-I19) -> 0 | X20: =IF((J20-J19<0), "0",J20-J19) -> 0 | ... AC20: =IF((O20-O19<0), "0",O20-O19) -> 0 | AD20: =SUM(Q20:AC20) -> 0 | AF20: =Q20*$D$39 -> 0 | AG20: =R20*$D$39 -> 0 | AH20: =S20*$D$39 -> 0 | AI20: =T20*$D$39 -> 0 | AJ20: =U20*$D$39 -> 0 | AK20: =V20*$D$39 -> 0 | AL20: =W20*$D$39 -> 0 | AM20: =X20*$D$39 -> 0 | ... AR20: =AC20*$D$39 -> 0 | AS20: =SUM(AF20:AR20) -> 0 | AV20: =IF((AU20-AU19<0),"0",AU20-AU19) -> 0 | AW20: =AV20*$D$40 -> 0
A21: 43936 | Q21: =IF((C21-C20<0), "0",C21-C20) -> 0 | R21: =IF((D21-D20<0), "0",D21-D20) -> 0 | S21: =IF((E21-E20<0), "0",E21-E20) -> 0 | T21: =IF((F21-F20<0), "0",F21-F20) -> 0 | U21: =IF((G21-G20<0), "0",G21-G20) -> 0 | V21: =IF((H21-H20<0), "0",H21-H20) -> 0 | W21: =IF((I21-I20<0), "0",I21-I20) -> 0 | X21: =IF((J21-J20<0), "0",J21-J20) -> 0 | ... AC21: =IF((O21-O20<0), "0",O21-O20) -> 0 | AD21: =SUM(Q21:AC21) -> 0 | AF21: =Q21*$D$39 -> 0 | AG21: =R21*$D$39 -> 0 | AH21: =S21*$D$39 -> 0 | AI21: =T21*$D$39 -> 0 | AJ21: =U21*$D$39 -> 0 | AK21: =V21*$D$39 -> 0 | AL21: =W21*$D$39 -> 0 | AM21: =X21*$D$39 -> 0 | ... AR21: =AC21*$D$39 -> 0 | AS21: =SUM(AF21:AR21) -> 0 | AV21: =IF((AU21-AU20<0),"0",AU21-AU20) -> 0 | AW21: =AV21*$D$40 -> 0
A22: 43937 | Q22: =IF((C22-C21<0), "0",C22-C21) -> 0 | R22: =IF((D22-D21<0), "0",D22-D21) -> 0 | S22: =IF((E22-E21<0), "0",E22-E21) -> 0 | T22: =IF((F22-F21<0), "0",F22-F21) -> 0 | U22: =IF((G22-G21<0), "0",G22-G21) -> 0 | V22: =IF((H22-H21<0), "0",H22-H21) -> 0 | W22: =IF((I22-I21<0), "0",I22-I21) -> 0 | X22: =IF((J22-J21<0), "0",J22-J21) -> 0 | ... AC22: =IF((O22-O21<0), "0",O22-O21) -> 0 | AD22: =SUM(Q22:AC22) -> 0 | AF22: =Q22*$D$39 -> 0 | AG22: =R22*$D$39 -> 0 | AH22: =S22*$D$39 -> 0 | AI22: =T22*$D$39 -> 0 | AJ22: =U22*$D$39 -> 0 | AK22: =V22*$D$39 -> 0 | AL22: =W22*$D$39 -> 0 | AM22: =X22*$D$39 -> 0 | ... AR22: =AC22*$D$39 -> 0 | AS22: =SUM(AF22:AR22) -> 0 | AV22: =IF((AU22-AU21<0),"0",AU22-AU21) -> 0 | AW22: =AV22*$D$40 -> 0
A23: 43938 | Q23: =IF((C23-C22<0), "0",C23-C22) -> 0 | R23: =IF((D23-D22<0), "0",D23-D22) -> 0 | S23: =IF((E23-E22<0), "0",E23-E22) -> 0 | T23: =IF((F23-F22<0), "0",F23-F22) -> 0 | U23: =IF((G23-G22<0), "0",G23-G22) -> 0 | V23: =IF((H23-H22<0), "0",H23-H22) -> 0 | W23: =IF((I23-I22<0), "0",I23-I22) -> 0 | X23: =IF((J23-J22<0), "0",J23-J22) -> 0 | ... AC23: =IF((O23-O22<0), "0",O23-O22) -> 0 | AD23: =SUM(Q23:AC23) -> 0 | AF23: =Q23*$D$39 -> 0 | AG23: =R23*$D$39 -> 0 | AH23: =S23*$D$39 -> 0 | AI23: =T23*$D$39 -> 0 | AJ23: =U23*$D$39 -> 0 | AK23: =V23*$D$39 -> 0 | AL23: =W23*$D$39 -> 0 | AM23: =X23*$D$39 -> 0 | ... AR23: =AC23*$D$39 -> 0 | AS23: =SUM(AF23:AR23) -> 0 | AV23: =IF((AU23-AU22<0),"0",AU23-AU22) -> 0 | AW23: =AV23*$D$40 -> 0
A24: 43939 | Q24: =IF((C24-C23<0), "0",C24-C23) -> 0 | R24: =IF((D24-D23<0), "0",D24-D23) -> 0 | S24: =IF((E24-E23<0), "0",E24-E23) -> 0 | T24: =IF((F24-F23<0), "0",F24-F23) -> 0 | U24: =IF((G24-G23<0), "0",G24-G23) -> 0 | V24: =IF((H24-H23<0), "0",H24-H23) -> 0 | W24: =IF((I24-I23<0), "0",I24-I23) -> 0 | X24: =IF((J24-J23<0), "0",J24-J23) -> 0 | ... AC24: =IF((O24-O23<0), "0",O24-O23) -> 0 | AD24: =SUM(Q24:AC24) -> 0 | AF24: =Q24*$D$39 -> 0 | AG24: =R24*$D$39 -> 0 | AH24: =S24*$D$39 -> 0 | AI24: =T24*$D$39 -> 0 | AJ24: =U24*$D$39 -> 0 | AK24: =V24*$D$39 -> 0 | AL24: =W24*$D$39 -> 0 | AM24: =X24*$D$39 -> 0 | ... AR24: =AC24*$D$39 -> 0 | AS24: =SUM(AF24:AR24) -> 0 | AV24: =IF((AU24-AU23<0),"0",AU24-AU23) -> 0 | AW24: =AV24*$D$40 -> 0
A25: 43940 | Q25: =IF((C25-C24<0), "0",C25-C24) -> 0 | R25: =IF((D25-D24<0), "0",D25-D24) -> 0 | S25: =IF((E25-E24<0), "0",E25-E24) -> 0 | T25: =IF((F25-F24<0), "0",F25-F24) -> 0 | U25: =IF((G25-G24<0), "0",G25-G24) -> 0 | V25: =IF((H25-H24<0), "0",H25-H24) -> 0 | W25: =IF((I25-I24<0), "0",I25-I24) -> 0 | X25: =IF((J25-J24<0), "0",J25-J24) -> 0 | ... AC25: =IF((O25-O24<0), "0",O25-O24) -> 0 | AD25: =SUM(Q25:AC25) -> 0 | AF25: =Q25*$D$39 -> 0 | AG25: =R25*$D$39 -> 0 | AH25: =S25*$D$39 -> 0 | AI25: =T25*$D$39 -> 0 | AJ25: =U25*$D$39 -> 0 | AK25: =V25*$D$39 -> 0 | AL25: =W25*$D$39 -> 0 | AM25: =X25*$D$39 -> 0 | ... AR25: =AC25*$D$39 -> 0 | AS25: =SUM(AF25:AR25) -> 0 | AV25: =IF((AU25-AU24<0),"0",AU25-AU24) -> 0 | AW25: =AV25*$D$40 -> 0
A26: 43941 | Q26: =IF((C26-C25<0), "0",C26-C25) -> 0 | R26: =IF((D26-D25<0), "0",D26-D25) -> 0 | S26: =IF((E26-E25<0), "0",E26-E25) -> 0 | T26: =IF((F26-F25<0), "0",F26-F25) -> 0 | U26: =IF((G26-G25<0), "0",G26-G25) -> 0 | V26: =IF((H26-H25<0), "0",H26-H25) -> 0 | W26: =IF((I26-I25<0), "0",I26-I25) -> 0 | X26: =IF((J26-J25<0), "0",J26-J25) -> 0 | ... AC26: =IF((O26-O25<0), "0",O26-O25) -> 0 | AD26: =SUM(Q26:AC26) -> 0 | AF26: =Q26*$D$39 -> 0 | AG26: =R26*$D$39 -> 0 | AH26: =S26*$D$39 -> 0 | AI26: =T26*$D$39 -> 0 | AJ26: =U26*$D$39 -> 0 | AK26: =V26*$D$39 -> 0 | AL26: =W26*$D$39 -> 0 | AM26: =X26*$D$39 -> 0 | ... AR26: =AC26*$D$39 -> 0 | AS26: =SUM(AF26:AR26) -> 0 | AV26: =IF((AU26-AU25<0),"0",AU26-AU25) -> 0 | AW26: =AV26*$D$40 -> 0
A27: 43942 | Q27: =IF((C27-C26<0), "0",C27-C26) -> 0 | R27: =IF((D27-D26<0), "0",D27-D26) -> 0 | S27: =IF((E27-E26<0), "0",E27-E26) -> 0 | T27: =IF((F27-F26<0), "0",F27-F26) -> 0 | U27: =IF((G27-G26<0), "0",G27-G26) -> 0 | V27: =IF((H27-H26<0), "0",H27-H26) -> 0 | W27: =IF((I27-I26<0), "0",I27-I26) -> 0 | X27: =IF((J27-J26<0), "0",J27-J26) -> 0 | ... AC27: =IF((O27-O26<0), "0",O27-O26) -> 0 | AD27: =SUM(Q27:AC27) -> 0 | AF27: =Q27*$D$39 -> 0 | AG27: =R27*$D$39 -> 0 | AH27: =S27*$D$39 -> 0 | AI27: =T27*$D$39 -> 0 | AJ27: =U27*$D$39 -> 0 | AK27: =V27*$D$39 -> 0 | AL27: =W27*$D$39 -> 0 | AM27: =X27*$D$39 -> 0 | ... AR27: =AC27*$D$39 -> 0 | AS27: =SUM(AF27:AR27) -> 0 | AV27: =IF((AU27-AU26<0),"0",AU27-AU26) -> 0 | AW27: =AV27*$D$40 -> 0
A28: 43943 | Q28: =IF((C28-C27<0), "0",C28-C27) -> 0 | R28: =IF((D28-D27<0), "0",D28-D27) -> 0 | S28: =IF((E28-E27<0), "0",E28-E27) -> 0 | T28: =IF((F28-F27<0), "0",F28-F27) -> 0 | U28: =IF((G28-G27<0), "0",G28-G27) -> 0 | V28: =IF((H28-H27<0), "0",H28-H27) -> 0 | W28: =IF((I28-I27<0), "0",I28-I27) -> 0 | X28: =IF((J28-J27<0), "0",J28-J27) -> 0 | ... AC28: =IF((O28-O27<0), "0",O28-O27) -> 0 | AD28: =SUM(Q28:AC28) -> 0 | AF28: =Q28*$D$39 -> 0 | AG28: =R28*$D$39 -> 0 | AH28: =S28*$D$39 -> 0 | AI28: =T28*$D$39 -> 0 | AJ28: =U28*$D$39 -> 0 | AK28: =V28*$D$39 -> 0 | AL28: =W28*$D$39 -> 0 | AM28: =X28*$D$39 -> 0 | ... AR28: =AC28*$D$39 -> 0 | AS28: =SUM(AF28:AR28) -> 0 | AV28: =IF((AU28-AU27<0),"0",AU28-AU27) -> 0 | AW28: =AV28*$D$40 -> 0
A29: 43944 | Q29: =IF((C29-C28<0), "0",C29-C28) -> 0 | R29: =IF((D29-D28<0), "0",D29-D28) -> 0 | S29: =IF((E29-E28<0), "0",E29-E28) -> 0 | T29: =IF((F29-F28<0), "0",F29-F28) -> 0 | U29: =IF((G29-G28<0), "0",G29-G28) -> 0 | V29: =IF((H29-H28<0), "0",H29-H28) -> 0 | W29: =IF((I29-I28<0), "0",I29-I28) -> 0 | X29: =IF((J29-J28<0), "0",J29-J28) -> 0 | ... AC29: =IF((O29-O28<0), "0",O29-O28) -> 0 | AD29: =SUM(Q29:AC29) -> 0 | AF29: =Q29*$D$39 -> 0 | AG29: =R29*$D$39 -> 0 | AH29: =S29*$D$39 -> 0 | AI29: =T29*$D$39 -> 0 | AJ29: =U29*$D$39 -> 0 | AK29: =V29*$D$39 -> 0 | AL29: =W29*$D$39 -> 0 | AM29: =X29*$D$39 -> 0 | ... AR29: =AC29*$D$39 -> 0 | AS29: =SUM(AF29:AR29) -> 0 | AV29: =IF((AU29-AU28<0),"0",AU29-AU28) -> 0 | AW29: =AV29*$D$40 -> 0
A30: 43945 | Q30: =IF((C30-C29<0), "0",C30-C29) -> 0 | R30: =IF((D30-D29<0), "0",D30-D29) -> 0 | S30: =IF((E30-E29<0), "0",E30-E29) -> 0 | T30: =IF((F30-F29<0), "0",F30-F29) -> 0 | U30: =IF((G30-G29<0), "0",G30-G29) -> 0 | V30: =IF((H30-H29<0), "0",H30-H29) -> 0 | W30: =IF((I30-I29<0), "0",I30-I29) -> 0 | X30: =IF((J30-J29<0), "0",J30-J29) -> 0 | ... AC30: =IF((O30-O29<0), "0",O30-O29) -> 0 | AD30: =SUM(Q30:AC30) -> 0 | AF30: =Q30*$D$39 -> 0 | AG30: =R30*$D$39 -> 0 | AH30: =S30*$D$39 -> 0 | AI30: =T30*$D$39 -> 0 | AJ30: =U30*$D$39 -> 0 | AK30: =V30*$D$39 -> 0 | AL30: =W30*$D$39 -> 0 | AM30: =X30*$D$39 -> 0 | ... AR30: =AC30*$D$39 -> 0 | AS30: =SUM(AF30:AR30) -> 0 | AV30: =IF((AU30-AU29<0),"0",AU30-AU29) -> 0 | AW30: =AV30*$D$40 -> 0
A31: 43946 | Q31: =IF((C31-C30<0), "0",C31-C30) -> 0 | R31: =IF((D31-D30<0), "0",D31-D30) -> 0 | S31: =IF((E31-E30<0), "0",E31-E30) -> 0 | T31: =IF((F31-F30<0), "0",F31-F30) -> 0 | U31: =IF((G31-G30<0), "0",G31-G30) -> 0 | V31: =IF((H31-H30<0), "0",H31-H30) -> 0 | W31: =IF((I31-I30<0), "0",I31-I30) -> 0 | X31: =IF((J31-J30<0), "0",J31-J30) -> 0 | ... AC31: =IF((O31-O30<0), "0",O31-O30) -> 0 | AD31: =SUM(Q31:AC31) -> 0 | AF31: =Q31*$D$39 -> 0 | AG31: =R31*$D$39 -> 0 | AH31: =S31*$D$39 -> 0 | AI31: =T31*$D$39 -> 0 | AJ31: =U31*$D$39 -> 0 | AK31: =V31*$D$39 -> 0 | AL31: =W31*$D$39 -> 0 | AM31: =X31*$D$39 -> 0 | ... AR31: =AC31*$D$39 -> 0 | AS31: =SUM(AF31:AR31) -> 0 | AV31: =IF((AU31-AU30<0),"0",AU31-AU30) -> 0 | AW31: =AV31*$D$40 -> 0
... A33: 43948 | Q33: =IF((C33-C32<0), "0",C33-C32) -> 0 | R33: =IF((D33-D32<0), "0",D33-D32) -> 0 | S33: =IF((E33-E32<0), "0",E33-E32) -> 0 | T33: =IF((F33-F32<0), "0",F33-F32) -> 0 | U33: =IF((G33-G32<0), "0",G33-G32) -> 0 | V33: =IF((H33-H32<0), "0",H33-H32) -> 0 | W33: =IF((I33-I32<0), "0",I33-I32) -> 0 | X33: =IF((J33-J32<0), "0",J33-J32) -> 0 | ... AC33: =IF((O33-O32<0), "0",O33-O32) -> 0 | AD33: =SUM(Q33:AC33) -> 0 | AF33: =Q33*$D$39 -> 0 | AG33: =R33*$D$39 -> 0 | AH33: =S33*$D$39 -> 0 | AI33: =T33*$D$39 -> 0 | AJ33: =U33*$D$39 -> 0 | AK33: =V33*$D$39 -> 0 | AL33: =W33*$D$39 -> 0 | AM33: =X33*$D$39 -> 0 | ... AR33: =AC33*$D$39 -> 0 | AS33: =SUM(AF33:AR33) -> 0 | AV33: =IF((AU33-AU32<0),"0",AU33-AU32) -> 0 | AW33: =AV33*$D$40 -> 0
A34: 43949 | Q34: =IF((C34-C33<0), "0",C34-C33) -> 0 | R34: =IF((D34-D33<0), "0",D34-D33) -> 0 | S34: =IF((E34-E33<0), "0",E34-E33) -> 0 | T34: =IF((F34-F33<0), "0",F34-F33) -> 0 | U34: =IF((G34-G33<0), "0",G34-G33) -> 0 | V34: =IF((H34-H33<0), "0",H34-H33) -> 0 | W34: =IF((I34-I33<0), "0",I34-I33) -> 0 | X34: =IF((J34-J33<0), "0",J34-J33) -> 0 | ... AA34: =IF((M34-M33<0), "0",M34-M33) -> 0 | AB34: 0 | AC34: =IF((O34-O33<0), "0",O34-O33) -> 0 | AD34: =SUM(Q34:AC34) -> 0 | AF34: =Q34*$D$39 -> 0 | AG34: =R34*$D$39 -> 0 | AH34: =S34*$D$39 -> 0 | AI34: =T34*$D$39 -> 0 | AJ34: =U34*$D$39 -> 0 | AK34: =V34*$D$39 -> 0 | AL34: =W34*$D$39 -> 0 | AM34: =X34*$D$39 -> 0 | ... AR34: =AC34*$D$39 -> 0 | AS34: =SUM(AF34:AR34) -> 0 | AV34: =IF((AU34-AU33<0),"0",AU34-AU33) -> 0 | AW34: =AV34*$D$40 -> 0
A35: 43950 | Q35: =IF((C35-C34<0), "0",C35-C34) -> 0 | R35: =IF((D35-D34<0), "0",D35-D34) -> 0 | S35: =IF((E35-E34<0), "0",E35-E34) -> 0 | T35: =IF((F35-F34<0), "0",F35-F34) -> 0 | U35: =IF((G35-G34<0), "0",G35-G34) -> 0 | V35: =IF((H35-H34<0), "0",H35-H34) -> 0 | W35: =IF((I35-I34<0), "0",I35-I34) -> 0 | X35: =IF((J35-J34<0), "0",J35-J34) -> 0 | ... AA35: =IF((M35-M34<0), "0",M35-M34) -> 0 | AB35: 0 | AC35: =IF((O35-O34<0), "0",O35-O34) -> 0 | AD35: =SUM(Q35:AC35) -> 0 | AF35: =Q35*$D$39 -> 0 | AG35: =R35*$D$39 -> 0 | AH35: =S35*$D$39 -> 0 | AI35: =T35*$D$39 -> 0 | AJ35: =U35*$D$39 -> 0 | AK35: =V35*$D$39 -> 0 | AL35: =W35*$D$39 -> 0 | AM35: =X35*$D$39 -> 0 | ... AR35: =AC35*$D$39 -> 0 | AS35: =SUM(AF35:AR35) -> 0 | AV35: =IF((AU35-AU34<0),"0",AU35-AU34) -> 0 | AW35: =AV35*$D$40 -> 0
A36: 43951 | Q36: =IF((C36-C35<0), "0",C36-C35) -> 0 | R36: =IF((D36-D35<0), "0",D36-D35) -> 0 | S36: =IF((E36-E35<0), "0",E36-E35) -> 0 | T36: =IF((F36-F35<0), "0",F36-F35) -> 0 | U36: =IF((G36-G35<0), "0",G36-G35) -> 0 | V36: =IF((H36-H35<0), "0",H36-H35) -> 0 | W36: =IF((I36-I35<0), "0",I36-I35) -> 0 | X36: =IF((J36-J35<0), "0",J36-J35) -> 0 | ... AC36: =IF((O36-O35<0), "0",O36-O35) -> 0 | AD36: =SUM(Q36:AC36) -> 0 | AF36: =Q36*$D$39 -> 0 | AG36: =R36*$D$39 -> 0 | AH36: =S36*$D$39 -> 0 | AI36: =T36*$D$39 -> 0 | AJ36: =U36*$D$39 -> 0 | AK36: =V36*$D$39 -> 0 | AL36: =W36*$D$39 -> 0 | AM36: =X36*$D$39 -> 0 | ... AR36: =AC36*$D$39 -> 0 | AS36: =SUM(AF36:AR36) -> 0 | AV36: =IF((AU36-AU35<0),"0",AU36-AU35) -> 0 | AW36: =AV36*$D$40 -> 0
Q37: =IF((C37-C36<0), "0",C37-C36) -> 0 | R37: =IF((D37-D36<0), "0",D37-D36) -> 0 | S37: =IF((E37-E36<0), "0",E37-E36) -> 0 | T37: =IF((F37-F36<0), "0",F37-F36) -> 0 | U37: =IF((G37-G36<0), "0",G37-G36) -> 0 | V37: =IF((H37-H36<0), "0",H37-H36) -> 0 | W37: =IF((I37-I36<0), "0",I37-I36) -> 0 | X37: =IF((J37-J36<0), "0",J37-J36) -> 0 | ... AC37: =IF((O37-O36<0), "0",O37-O36) -> 0 | AD37: =SUM(Q37:AC37) -> 0 | AF37: =Q37*$D$39 -> 0 | AG37: =R37*$D$39 -> 0 | AH37: =S37*$D$39 -> 0 | AI37: =T37*$D$39 -> 0 | AJ37: =U37*$D$39 -> 0 | AK37: =V37*$D$39 -> 0 | AL37: =W37*$D$39 -> 0 | AM37: =X37*$D$39 -> 0 | ... AR37: =AC37*$D$39 -> 0 | AS37: =SUM(AF37:AR37) -> 0 | AV37: =IF((AU37-AU36<0),"0",AU37-AU36) -> 0 | AW37: =AV37*$D$40 -> 0
Q38: =SUM(Q7:Q34) -> 7290 | R38: =SUM(R7:R34) -> 24550 | S38: =SUM(S7:S34) -> 38260 | T38: =SUM(T7:T34) -> 18130 | U38: =SUM(U7:U34) -> 37150 | V38: =SUM(V7:V34) -> 29730 | W38: =SUM(W7:W34) -> 27180 | X38: =SUM(X7:X34) -> 16250 | ... AD38: =SUM(AD7:AD34) -> 387180 | AF38: =SUM(AF7:AF34) -> 36.45 | AG38: =SUM(AG7:AG34) -> 122.75 | AH38: =SUM(AH7:AH34) -> 191.3 | AI38: =SUM(AI7:AI34) -> 90.65 | AJ38: =SUM(AJ7:AJ34) -> 185.75 | AK38: =SUM(AK7:AK34) -> 148.65 | AL38: =SUM(AL7:AL34) -> 135.9 | AM38: =SUM(AM7:AM34) -> 81.25 | ... AS38: =SUM(AS7:AS34) -> 1935.9 | AV38: =SUM(AV7:AV34) -> 14927 | AW38: =SUM(AW7:AW34) -> 24.524
D39: 0.005 | AV39: =AV38*0.00378541*1000 -> 56504.815
D40: 0.002 | AV40: =AV39/31 -> 1822.736
AV41: =AV38*0.00378541 -> 56.504815
AU44: =0.002 -> 0.002 | AV44: 0.00378541
...
