Workbook

Sheet Total
A1: Site Name | B1: Day | C1: Month | D1: Year | E1: Total Electricity Kwh | F1: Electricity Tariff ($/Kwh) | G1: LPG (Kg) | H1: LPG $/Kg | I1: Water Utility Supply (m3) m3 | J1: Water Utility Supply (m3) $/m3 | K1: Room Nights | L1: Utilities day cost dh
A2: Serengeti | B2: 1 | C2: 4 | D2: 2020 | E2: ='UTILITY REPORT 1'!F3 -> 2051 | F2: =('UTILITY REPORT 1'!E3*'UTILITY REPORT 1'!D3)/'UTILITY REPORT 1'!F3 -> 0.41490005 | G2: =IF('Utility summery'!M6<0,"0",'Utility summery'!M6) -> 61.6 | H2: 0 | I2: =IF('UTILITY REPORT 1'!G3<0,"0",'UTILITY REPORT 1'!G3) -> 38 | J2: 0 | K2: ='UTILITY REPORT 1'!C3 -> 0 | L2: =E2*F2+G2*H2+#REF!*#REF!+I2*J2 -> #REF!
A3: Serengeti | B3: =B2+1 -> 2 | C3: 4 | D3: 2020 | E3: ='UTILITY REPORT 1'!F4 -> 2088 | F3: =('UTILITY REPORT 1'!E4*'UTILITY REPORT 1'!D4)/'UTILITY REPORT 1'!F4 -> 0.41487069 | G3: =IF('Utility summery'!M7<0,"0",'Utility summery'!M7) -> 66 | H3: 0 | I3: =IF('UTILITY REPORT 1'!G4<0,"0",'UTILITY REPORT 1'!G4) -> 52 | J3: 0 | K3: ='UTILITY REPORT 1'!C4 -> 0 | L3: =E3*F3+G3*H3+#REF!*#REF!+I3*J3 -> #REF!
A4: Serengeti | B4: =B3+1 -> 3 | C4: 4 | D4: 2020 | E4: ='UTILITY REPORT 1'!F5 -> 1898 | F4: =('UTILITY REPORT 1'!E5*'UTILITY REPORT 1'!D5)/'UTILITY REPORT 1'!F5 -> 0.43884089 | G4: =IF('Utility summery'!M8<0,"0",'Utility summery'!M8) -> 37.532 | H4: 0 | I4: =IF('UTILITY REPORT 1'!G5<0,"0",'UTILITY REPORT 1'!G5) -> 26 | J4: 0 | K4: ='UTILITY REPORT 1'!C5 -> 0 | L4: =E4*F4+G4*H4+#REF!*#REF!+I4*J4 -> #REF!
A5: Serengeti | B5: =B4+1 -> 4 | C5: 4 | D5: 2020 | E5: ='UTILITY REPORT 1'!F6 -> 1815 | F5: =('UTILITY REPORT 1'!E6*'UTILITY REPORT 1'!D6)/'UTILITY REPORT 1'!F6 -> 0.43501377 | G5: =IF('Utility summery'!M9<0,"0",'Utility summery'!M9) -> 31.46 | H5: 0 | I5: =IF('UTILITY REPORT 1'!G6<0,"0",'UTILITY REPORT 1'!G6) -> 34 | J5: 0 | K5: ='UTILITY REPORT 1'!C6 -> 0 | L5: =E5*F5+G5*H5+#REF!*#REF!+I5*J5 -> #REF!
A6: Serengeti | B6: =B5+1 -> 5 | C6: 4 | D6: 2020 | E6: ='UTILITY REPORT 1'!F7 -> 1841 | F6: =('UTILITY REPORT 1'!E7*'UTILITY REPORT 1'!D7)/'UTILITY REPORT 1'!F7 -> 0.4417925 | G6: =IF('Utility summery'!M10<0,"0",'Utility summery'!M10) -> 27.808 | H6: 0 | I6: =IF('UTILITY REPORT 1'!G7<0,"0",'UTILITY REPORT 1'!G7) -> 42 | J6: 0 | K6: ='UTILITY REPORT 1'!C7 -> 0 | L6: =E6*F6+G6*H6+#REF!*#REF!+I6*J6 -> #REF!
A7: Serengeti | B7: =B6+1 -> 6 | C7: 4 | D7: 2020 | E7: ='UTILITY REPORT 1'!F8 -> 1789 | F7: =('UTILITY REPORT 1'!E8*'UTILITY REPORT 1'!D8)/'UTILITY REPORT 1'!F8 -> 0.42343767 | G7: =IF('Utility summery'!M11<0,"0",'Utility summery'!M11) -> 14.608 | H7: 0 | I7: =IF('UTILITY REPORT 1'!G8<0,"0",'UTILITY REPORT 1'!G8) -> 41 | J7: 0 | K7: ='UTILITY REPORT 1'!C8 -> 0 | L7: =E7*F7+G7*H7+#REF!*#REF!+I7*J7 -> #REF!
A8: Serengeti | B8: =B7+1 -> 7 | C8: 4 | D8: 2020 | E8: ='UTILITY REPORT 1'!F9 -> 1867 | F8: =('UTILITY REPORT 1'!E9*'UTILITY REPORT 1'!D9)/'UTILITY REPORT 1'!F9 -> 0.41968399 | G8: =IF('Utility summery'!M12<0,"0",'Utility summery'!M12) -> 25.212 | H8: 0 | I8: =IF('UTILITY REPORT 1'!G9<0,"0",'UTILITY REPORT 1'!G9) -> 47 | J8: 0 | K8: ='UTILITY REPORT 1'!C9 -> 0 | L8: =E8*F8+G8*H8+#REF!*#REF!+I8*J8 -> #REF!
A9: Serengeti | B9: =B8+1 -> 8 | C9: 4 | D9: 2020 | E9: ='UTILITY REPORT 1'!F10 -> 1940 | F9: =('UTILITY REPORT 1'!E10*'UTILITY REPORT 1'!D10)/'UTILITY REPORT 1'!F10 -> 0.42848969 | G9: =IF('Utility summery'!M13<0,"0",'Utility summery'!M13) -> 36.3 | H9: 0 | I9: =IF('UTILITY REPORT 1'!G10<0,"0",'UTILITY REPORT 1'!G10) -> 36 | J9: 0 | K9: ='UTILITY REPORT 1'!C10 -> 0 | L9: =E9*F9+G9*H9+#REF!*#REF!+I9*J9 -> #REF!
A10: Serengeti | B10: =B9+1 -> 9 | C10: 4 | D10: 2020 | E10: ='UTILITY REPORT 1'!F11 -> 1882 | F10: =('UTILITY REPORT 1'!E11*'UTILITY REPORT 1'!D11)/'UTILITY REPORT 1'!F11 -> 0.42843783 | G10: =IF('Utility summery'!M14<0,"0",'Utility summery'!M14) -> 25.916 | H10: 0 | I10: =IF('UTILITY REPORT 1'!G11<0,"0",'UTILITY REPORT 1'!G11) -> 33 | J10: 0 | K10: ='UTILITY REPORT 1'!C11 -> 0 | L10: =E10*F10+G10*H10+#REF!*#REF!+I10*J10 -> #REF!
A11: Serengeti | B11: =B10+1 -> 10 | C11: 4 | D11: 2020 | E11: ='UTILITY REPORT 1'!F12 -> 1935 | F11: =('UTILITY REPORT 1'!E12*'UTILITY REPORT 1'!D12)/'UTILITY REPORT 1'!F12 -> 0.42571059 | G11: =IF('Utility summery'!M15<0,"0",'Utility summery'!M15) -> 34.54 | H11: 0 | I11: =IF('UTILITY REPORT 1'!G12<0,"0",'UTILITY REPORT 1'!G12) -> 55 | J11: 0 | K11: ='UTILITY REPORT 1'!C12 -> 0 | L11: =E11*F11+G11*H11+#REF!*#REF!+I11*J11 -> #REF!
A12: Serengeti | B12: =B11+1 -> 11 | C12: 4 | D12: 2020 | E12: ='UTILITY REPORT 1'!F13 -> 1883 | F12: =('UTILITY REPORT 1'!E13*'UTILITY REPORT 1'!D13)/'UTILITY REPORT 1'!F13 -> 0.41565056 | G12: =IF('Utility summery'!M16<0,"0",'Utility summery'!M16) -> 38.412 | H12: 0 | I12: =IF('UTILITY REPORT 1'!G13<0,"0",'UTILITY REPORT 1'!G13) -> 56 | J12: 0 | K12: ='UTILITY REPORT 1'!C13 -> 0 | L12: =E12*F12+G12*H12+#REF!*#REF!+I12*J12 -> #REF!
A13: Serengeti | B13: =B12+1 -> 12 | C13: 4 | D13: 2020 | E13: ='UTILITY REPORT 1'!F14 -> 1877 | F13: =('UTILITY REPORT 1'!E14*'UTILITY REPORT 1'!D14)/'UTILITY REPORT 1'!F14 -> 0.41385189 | G13: =IF('Utility summery'!M17<0,"0",'Utility summery'!M17) -> 35.2 | H13: 0 | I13: =IF('UTILITY REPORT 1'!G14<0,"0",'UTILITY REPORT 1'!G14) -> 41 | J13: 0 | K13: ='UTILITY REPORT 1'!C14 -> 0 | L13: =E13*F13+G13*H13+#REF!*#REF!+I13*J13 -> #REF!
A14: Serengeti | B14: =B13+1 -> 13 | C14: 4 | D14: 2020 | E14: ='UTILITY REPORT 1'!F15 -> 1796 | F14: =('UTILITY REPORT 1'!E15*'UTILITY REPORT 1'!D15)/'UTILITY REPORT 1'!F15 -> 0.4296882 | G14: =IF('Utility summery'!M18<0,"0",'Utility summery'!M18) -> 36.036 | H14: 0 | I14: =IF('UTILITY REPORT 1'!G15<0,"0",'UTILITY REPORT 1'!G15) -> 45 | J14: 0 | K14: ='UTILITY REPORT 1'!C15 -> 0 | L14: =E14*F14+G14*H14+#REF!*#REF!+I14*J14 -> #REF!
... A30: Serengeti | B30: =B29+1 -> 29 | C30: 4 | D30: 2020 | E30: ='UTILITY REPORT 1'!F31 -> 1644 | F30: =('UTILITY REPORT 1'!E31*'UTILITY REPORT 1'!D31)/'UTILITY REPORT 1'!F31 -> 0.42037105 | G30: =IF('Utility summery'!M34<0,"0",'Utility summery'!M34) -> 40.92 | H30: 0 | I30: =IF('UTILITY REPORT 1'!G31<0,"0",'UTILITY REPORT 1'!G31) -> 29 | J30: 0 | K30: ='UTILITY REPORT 1'!C31 -> 0 | L30: =E30*F30+G30*H30+#REF!*#REF!+I30*J30 -> #REF!
A31: Serengeti | B31: 30 | C31: 4 | D31: 2020 | E31: ='UTILITY REPORT 1'!F32 -> 1564 | F31: =('UTILITY REPORT 1'!E32*'UTILITY REPORT 1'!D32)/'UTILITY REPORT 1'!F32 -> 0.42248082 | G31: =IF('Utility summery'!M35<0,"0",'Utility summery'!M35) -> 17.424 | H31: 0 | I31: =IF('UTILITY REPORT 1'!G32<0,"0",'UTILITY REPORT 1'!G32) -> 29 | J31: 0 | K31: ='UTILITY REPORT 1'!C32 -> 0 | L31: =E31*F31+G31*H31+#REF!*#REF!+I31*J31 -> #REF!
A32: Serengeti | B32: 31 | C32: 4 | D32: 2020 | E32: ='UTILITY REPORT 1'!F33 -> 0 | F32: =('UTILITY REPORT 1'!E33*'UTILITY REPORT 1'!D33)/'UTILITY REPORT 1'!F33 -> #DIV/0! | G32: =IF('Utility summery'!M36<0,"0",'Utility summery'!M36) -> 27.852 | H32: 0 | I32: =IF('UTILITY REPORT 1'!G33<0,"0",'UTILITY REPORT 1'!G33) -> 0 | J32: 0 | K32: ='UTILITY REPORT 1'!C33 -> 0

Sheet Submetering
A1: Site Name | B1: Day | C1: Month | D1: Year | E1: Transport Consumption (LT) | F1: Generators Consumption (LT) | G1: Total Electricity Kwh | H1: Kitchen (KWh) | I1: Laundry (KWh) | J1: STP (M3) | K1: RO prodution (M3) | L1: Amani Restaurant (M3) | M1: Kitchen (M3) | N1: Laundry (M3) | O1: Laundry (M3) | P1: Total water Consumption (M3) | Q1: Borehole #1 (M3) | R1: Borehole #2 (M3) | S1: Borehole #3 (M3) | T1: Borehole #4 (M3) | U1: Borehole #5 (M3) | V1: Borehole #6 (M3) | W1: Total Bore holes production (M3) | X1: Room Nights
A2: Serengeti | B2: 1 | C2: 4 | D2: 2020 | E2: ='UTILITY REPORT 1'!I3 -> 49.37 | F2: ='UTILITY REPORT 1'!E3 -> 850.96 | G2: ='UTILITY REPORT 1'!F3 -> 2051 | H2: =IF('Kit report'!F4<0,"0",'Kit report'!F4) -> 156 | I2: =IF('Kit report'!X4<0,"0",'Kit report'!X4) -> 20 | J2: =IF('Utility summery'!H6<0,"0",'Utility summery'!H6) -> 28 | K2: =IF('UTILITY REPORT 1'!H3<0,"0",'UTILITY REPORT 1'!H3) -> 0 | L2: ='Water-Meter'!K6 -> 1 | M2: ='Water-Meter'!H6 -> 0 | N2: ='Water-Meter'!Q6 -> 1 | O2: =K2*E2+H2*I2+#REF!*#REF!+J2*L2 -> #REF! | P2: ='Water-Meter'!E6 -> 38 | Q2: =IF('Water-Meter'!U6<0,"0",'Water-Meter'!U6) -> 75 | R2: =IF('Water-Meter'!X6<0,"0",'Water-Meter'!X6) -> 0 | S2: =IF('Water-Meter'!AA6<0,"0",'Water-Meter'!AA6) -> 0 | T2: =IF('Water-Meter'!AD6<0,"0",'Water-Meter'!AD6) -> 0 | U2: =IF('Water-Meter'!AG6<0,"0",'Water-Meter'!AG6) -> 24 | V2: =IF('Water-Meter'!AJ6<0,"0",'Water-Meter'!AJ6) -> 0 | W2: ='Water-Meter'!AN6 -> 99 | X2: =Total!K2 -> 0
A3: Serengeti | B3: =B2+1 -> 2 | C3: 4 | D3: 2020 | E3: ='UTILITY REPORT 1'!I4 -> 9.39 | F3: ='UTILITY REPORT 1'!E4 -> 866.25 | G3: ='UTILITY REPORT 1'!F4 -> 2088 | H3: =IF('Kit report'!F5<0,"0",'Kit report'!F5) -> 132 | I3: =IF('Kit report'!X5<0,"0",'Kit report'!X5) -> 20 | J3: =IF('Utility summery'!H7<0,"0",'Utility summery'!H7) -> 29 | K3: =IF('UTILITY REPORT 1'!H4<0,"0",'UTILITY REPORT 1'!H4) -> 48 | L3: ='Water-Meter'!K7 -> 1 | M3: ='Water-Meter'!H7 -> 0 | N3: ='Water-Meter'!Q7 -> 2 | O3: =K3*E3+H3*I3+#REF!*#REF!+J3*L3 -> #REF! | P3: ='Water-Meter'!E7 -> 52 | Q3: =IF('Water-Meter'!U7<0,"0",'Water-Meter'!U7) -> 65 | R3: =IF('Water-Meter'!X7<0,"0",'Water-Meter'!X7) -> 0 | S3: =IF('Water-Meter'!AA7<0,"0",'Water-Meter'!AA7) -> 0 | T3: =IF('Water-Meter'!AD7<0,"0",'Water-Meter'!AD7) -> 0 | U3: =IF('Water-Meter'!AG7<0,"0",'Water-Meter'!AG7) -> 24 | V3: =IF('Water-Meter'!AJ7<0,"0",'Water-Meter'!AJ7) -> 0 | W3: ='Water-Meter'!AN7 -> 89 | X3: =Total!K3 -> 0
A4: Serengeti | B4: =B3+1 -> 3 | C4: 4 | D4: 2020 | E4: ='UTILITY REPORT 1'!I5 -> 18.02 | F4: ='UTILITY REPORT 1'!E5 -> 832.92 | G4: ='UTILITY REPORT 1'!F5 -> 1898 | H4: =IF('Kit report'!F6<0,"0",'Kit report'!F6) -> 144 | I4: =IF('Kit report'!X6<0,"0",'Kit report'!X6) -> 40 | J4: =IF('Utility summery'!H8<0,"0",'Utility summery'!H8) -> 19 | K4: =IF('UTILITY REPORT 1'!H5<0,"0",'UTILITY REPORT 1'!H5) -> 59 | L4: ='Water-Meter'!K8 -> 1 | M4: ='Water-Meter'!H8 -> 0 | N4: ='Water-Meter'!Q8 -> 1 | O4: =K4*E4+H4*I4+#REF!*#REF!+J4*L4 -> #REF! | P4: ='Water-Meter'!E8 -> 26 | Q4: =IF('Water-Meter'!U8<0,"0",'Water-Meter'!U8) -> 60 | R4: =IF('Water-Meter'!X8<0,"0",'Water-Meter'!X8) -> 0 | S4: =IF('Water-Meter'!AA8<0,"0",'Water-Meter'!AA8) -> 0 | T4: =IF('Water-Meter'!AD8<0,"0",'Water-Meter'!AD8) -> 0 | U4: =IF('Water-Meter'!AG8<0,"0",'Water-Meter'!AG8) -> 24 | V4: =IF('Water-Meter'!AJ8<0,"0",'Water-Meter'!AJ8) -> 0 | W4: ='Water-Meter'!AN8 -> 84 | X4: =Total!K4 -> 0
A5: Serengeti | B5: =B4+1 -> 4 | C5: 4 | D5: 2020 | E5: ='UTILITY REPORT 1'!I6 -> 660.37 | F5: ='UTILITY REPORT 1'!E6 -> 789.55 | G5: ='UTILITY REPORT 1'!F6 -> 1815 | H5: =IF('Kit report'!F7<0,"0",'Kit report'!F7) -> 132 | I5: =IF('Kit report'!X7<0,"0",'Kit report'!X7) -> 40 | J5: =IF('Utility summery'!H9<0,"0",'Utility summery'!H9) -> 0 | K5: =IF('UTILITY REPORT 1'!H6<0,"0",'UTILITY REPORT 1'!H6) -> 57 | L5: ='Water-Meter'!K9 -> 1 | M5: ='Water-Meter'!H9 -> 0 | N5: ='Water-Meter'!Q9 -> 2 | O5: =K5*E5+H5*I5+#REF!*#REF!+J5*L5 -> #REF! | P5: ='Water-Meter'!E9 -> 34 | Q5: =IF('Water-Meter'!U9<0,"0",'Water-Meter'!U9) -> 52 | R5: =IF('Water-Meter'!X9<0,"0",'Water-Meter'!X9) -> 0 | S5: =IF('Water-Meter'!AA9<0,"0",'Water-Meter'!AA9) -> 0 | T5: =IF('Water-Meter'!AD9<0,"0",'Water-Meter'!AD9) -> 0 | U5: =IF('Water-Meter'!AG9<0,"0",'Water-Meter'!AG9) -> 24 | V5: =IF('Water-Meter'!AJ9<0,"0",'Water-Meter'!AJ9) -> 0 | W5: ='Water-Meter'!AN9 -> 76 | X5: =Total!K5 -> 0
A6: Serengeti | B6: =B5+1 -> 5 | C6: 4 | D6: 2020 | E6: ='UTILITY REPORT 1'!I7 -> 34.28 | F6: ='UTILITY REPORT 1'!E7 -> 813.34 | G6: ='UTILITY REPORT 1'!F7 -> 1841 | H6: =IF('Kit report'!F8<0,"0",'Kit report'!F8) -> 108 | I6: =IF('Kit report'!X8<0,"0",'Kit report'!X8) -> 40 | J6: =IF('Utility summery'!H10<0,"0",'Utility summery'!H10) -> 48 | K6: =IF('UTILITY REPORT 1'!H7<0,"0",'UTILITY REPORT 1'!H7) -> 57 | L6: ='Water-Meter'!K10 -> 0 | M6: ='Water-Meter'!H10 -> 0 | N6: ='Water-Meter'!Q10 -> 1 | O6: =K6*E6+H6*I6+#REF!*#REF!+J6*L6 -> #REF! | P6: ='Water-Meter'!E10 -> 42 | Q6: =IF('Water-Meter'!U10<0,"0",'Water-Meter'!U10) -> 82 | R6: =IF('Water-Meter'!X10<0,"0",'Water-Meter'!X10) -> 0 | S6: =IF('Water-Meter'!AA10<0,"0",'Water-Meter'!AA10) -> 0 | T6: =IF('Water-Meter'!AD10<0,"0",'Water-Meter'!AD10) -> 11 | U6: =IF('Water-Meter'!AG10<0,"0",'Water-Meter'!AG10) -> 0 | V6: =IF('Water-Meter'!AJ10<0,"0",'Water-Meter'!AJ10) -> 0 | W6: ='Water-Meter'!AN10 -> 93 | X6: =Total!K6 -> 0
A7: Serengeti | B7: =B6+1 -> 6 | C7: 4 | D7: 2020 | E7: ='UTILITY REPORT 1'!I8 -> 0 | F7: ='UTILITY REPORT 1'!E8 -> 757.53 | G7: ='UTILITY REPORT 1'!F8 -> 1789 | H7: =IF('Kit report'!F9<0,"0",'Kit report'!F9) -> 132 | I7: =IF('Kit report'!X9<0,"0",'Kit report'!X9) -> 40 | J7: =IF('Utility summery'!H11<0,"0",'Utility summery'!H11) -> 18 | K7: =IF('UTILITY REPORT 1'!H8<0,"0",'UTILITY REPORT 1'!H8) -> 38 | L7: ='Water-Meter'!K11 -> 0 | M7: ='Water-Meter'!H11 -> 0 | N7: ='Water-Meter'!Q11 -> 1 | O7: =K7*E7+H7*I7+#REF!*#REF!+J7*L7 -> #REF! | P7: ='Water-Meter'!E11 -> 41 | Q7: =IF('Water-Meter'!U11<0,"0",'Water-Meter'!U11) -> 65 | R7: =IF('Water-Meter'!X11<0,"0",'Water-Meter'!X11) -> 0 | S7: =IF('Water-Meter'!AA11<0,"0",'Water-Meter'!AA11) -> 0 | T7: =IF('Water-Meter'!AD11<0,"0",'Water-Meter'!AD11) -> 11 | U7: =IF('Water-Meter'!AG11<0,"0",'Water-Meter'!AG11) -> 0 | V7: =IF('Water-Meter'!AJ11<0,"0",'Water-Meter'!AJ11) -> 0 | W7: ='Water-Meter'!AN11 -> 76 | X7: =Total!K7 -> 0
A8: Serengeti | B8: =B7+1 -> 7 | C8: 4 | D8: 2020 | E8: ='UTILITY REPORT 1'!I9 -> 108.2 | F8: ='UTILITY REPORT 1'!E9 -> 783.55 | G8: ='UTILITY REPORT 1'!F9 -> 1867 | H8: =IF('Kit report'!F10<0,"0",'Kit report'!F10) -> 108 | I8: =IF('Kit report'!X10<0,"0",'Kit report'!X10) -> 40 | J8: =IF('Utility summery'!H12<0,"0",'Utility summery'!H12) -> 32 | K8: =IF('UTILITY REPORT 1'!H9<0,"0",'UTILITY REPORT 1'!H9) -> 53 | L8: ='Water-Meter'!K12 -> 0 | M8: ='Water-Meter'!H12 -> 0 | N8: ='Water-Meter'!Q12 -> 2 | O8: =K8*E8+H8*I8+#REF!*#REF!+J8*L8 -> #REF! | P8: ='Water-Meter'!E12 -> 47 | Q8: =IF('Water-Meter'!U12<0,"0",'Water-Meter'!U12) -> 49 | R8: =IF('Water-Meter'!X12<0,"0",'Water-Meter'!X12) -> 0 | S8: =IF('Water-Meter'!AA12<0,"0",'Water-Meter'!AA12) -> 44 | T8: =IF('Water-Meter'!AD12<0,"0",'Water-Meter'!AD12) -> 10 | U8: =IF('Water-Meter'!AG12<0,"0",'Water-Meter'!AG12) -> 0 | V8: =IF('Water-Meter'!AJ12<0,"0",'Water-Meter'!AJ12) -> 0 | W8: ='Water-Meter'!AN12 -> 103 | X8: =Total!K8 -> 0
A9: Serengeti | B9: =B8+1 -> 8 | C9: 4 | D9: 2020 | E9: ='UTILITY REPORT 1'!I10 -> 0 | F9: ='UTILITY REPORT 1'!E10 -> 831.27 | G9: ='UTILITY REPORT 1'!F10 -> 1940 | H9: =IF('Kit report'!F11<0,"0",'Kit report'!F11) -> 120 | I9: =IF('Kit report'!X11<0,"0",'Kit report'!X11) -> 40 | J9: =IF('Utility summery'!H13<0,"0",'Utility summery'!H13) -> 28 | K9: =IF('UTILITY REPORT 1'!H10<0,"0",'UTILITY REPORT 1'!H10) -> 50 | L9: ='Water-Meter'!K13 -> 0 | M9: ='Water-Meter'!H13 -> 0 | N9: ='Water-Meter'!Q13 -> 1 | O9: =K9*E9+H9*I9+#REF!*#REF!+J9*L9 -> #REF! | P9: ='Water-Meter'!E13 -> 36 | Q9: =IF('Water-Meter'!U13<0,"0",'Water-Meter'!U13) -> 66 | R9: =IF('Water-Meter'!X13<0,"0",'Water-Meter'!X13) -> 0 | S9: =IF('Water-Meter'!AA13<0,"0",'Water-Meter'!AA13) -> 52 | T9: =IF('Water-Meter'!AD13<0,"0",'Water-Meter'!AD13) -> 11 | U9: =IF('Water-Meter'!AG13<0,"0",'Water-Meter'!AG13) -> 0 | V9: =IF('Water-Meter'!AJ13<0,"0",'Water-Meter'!AJ13) -> 0 | W9: ='Water-Meter'!AN13 -> 129 | X9: =Total!K9 -> 0
A10: Serengeti | B10: =B9+1 -> 9 | C10: 4 | D10: 2020 | E10: ='UTILITY REPORT 1'!I11 -> 0 | F10: ='UTILITY REPORT 1'!E11 -> 806.32 | G10: ='UTILITY REPORT 1'!F11 -> 1882 | H10: =IF('Kit report'!F12<0,"0",'Kit report'!F12) -> 120 | I10: =IF('Kit report'!X12<0,"0",'Kit report'!X12) -> 20 | J10: =IF('Utility summery'!H14<0,"0",'Utility summery'!H14) -> 26 | K10: =IF('UTILITY REPORT 1'!H11<0,"0",'UTILITY REPORT 1'!H11) -> 7 | L10: ='Water-Meter'!K14 -> 0 | M10: ='Water-Meter'!H14 -> 0 | N10: ='Water-Meter'!Q14 -> 1 | O10: =K10*E10+H10*I10+#REF!*#REF!+J10*L10 -> #REF! | P10: ='Water-Meter'!E14 -> 33 | Q10: =IF('Water-Meter'!U14<0,"0",'Water-Meter'!U14) -> 65 | R10: =IF('Water-Meter'!X14<0,"0",'Water-Meter'!X14) -> 0 | S10: =IF('Water-Meter'!AA14<0,"0",'Water-Meter'!AA14) -> 53 | T10: =IF('Water-Meter'!AD14<0,"0",'Water-Meter'!AD14) -> 17 | U10: =IF('Water-Meter'!AG14<0,"0",'Water-Meter'!AG14) -> 0 | V10: =IF('Water-Meter'!AJ14<0,"0",'Water-Meter'!AJ14) -> 0 | W10: ='Water-Meter'!AN14 -> 135 | X10: =Total!K10 -> 0
A11: Serengeti | B11: =B10+1 -> 10 | C11: 4 | D11: 2020 | E11: ='UTILITY REPORT 1'!I12 -> 0 | F11: ='UTILITY REPORT 1'!E12 -> 823.75 | G11: ='UTILITY REPORT 1'!F12 -> 1935 | H11: =IF('Kit report'!F13<0,"0",'Kit report'!F13) -> 108 | I11: =IF('Kit report'!X13<0,"0",'Kit report'!X13) -> 60 | J11: =IF('Utility summery'!H15<0,"0",'Utility summery'!H15) -> 26 | K11: =IF('UTILITY REPORT 1'!H12<0,"0",'UTILITY REPORT 1'!H12) -> 44 | L11: ='Water-Meter'!K15 -> 0 | M11: ='Water-Meter'!H15 -> 0 | N11: ='Water-Meter'!Q15 -> 2 | O11: =K11*E11+H11*I11+#REF!*#REF!+J11*L11 -> #REF! | P11: ='Water-Meter'!E15 -> 55 | Q11: =IF('Water-Meter'!U15<0,"0",'Water-Meter'!U15) -> 1 | R11: =IF('Water-Meter'!X15<0,"0",'Water-Meter'!X15) -> 0 | S11: =IF('Water-Meter'!AA15<0,"0",'Water-Meter'!AA15) -> 53 | T11: =IF('Water-Meter'!AD15<0,"0",'Water-Meter'!AD15) -> 17 | U11: =IF('Water-Meter'!AG15<0,"0",'Water-Meter'!AG15) -> 20 | V11: =IF('Water-Meter'!AJ15<0,"0",'Water-Meter'!AJ15) -> 0 | W11: ='Water-Meter'!AN15 -> 91 | X11: =Total!K11 -> 0
A12: Serengeti | B12: =B11+1 -> 11 | C12: 4 | D12: 2020 | E12: ='UTILITY REPORT 1'!I13 -> 0 | F12: ='UTILITY REPORT 1'!E13 -> 782.67 | G12: ='UTILITY REPORT 1'!F13 -> 1883 | H12: =IF('Kit report'!F14<0,"0",'Kit report'!F14) -> 132 | I12: =IF('Kit report'!X14<0,"0",'Kit report'!X14) -> 20 | J12: =IF('Utility summery'!H16<0,"0",'Utility summery'!H16) -> 28 | K12: =IF('UTILITY REPORT 1'!H13<0,"0",'UTILITY REPORT 1'!H13) -> 75 | L12: ='Water-Meter'!K16 -> 0 | M12: ='Water-Meter'!H16 -> 0 | N12: ='Water-Meter'!Q16 -> 1 | O12: =K12*E12+H12*I12+#REF!*#REF!+J12*L12 -> #REF! | P12: ='Water-Meter'!E16 -> 56 | Q12: =IF('Water-Meter'!U16<0,"0",'Water-Meter'!U16) -> 0 | R12: =IF('Water-Meter'!X16<0,"0",'Water-Meter'!X16) -> 0 | S12: =IF('Water-Meter'!AA16<0,"0",'Water-Meter'!AA16) -> 4 | T12: =IF('Water-Meter'!AD16<0,"0",'Water-Meter'!AD16) -> 17 | U12: =IF('Water-Meter'!AG16<0,"0",'Water-Meter'!AG16) -> 25 | V12: =IF('Water-Meter'!AJ16<0,"0",'Water-Meter'!AJ16) -> 0 | W12: ='Water-Meter'!AN16 -> 46 | X12: =Total!K12 -> 0
A13: Serengeti | B13: =B12+1 -> 12 | C13: 4 | D13: 2020 | E13: ='UTILITY REPORT 1'!I14 -> 0 | F13: ='UTILITY REPORT 1'!E14 -> 776.8 | G13: ='UTILITY REPORT 1'!F14 -> 1877 | H13: =IF('Kit report'!F15<0,"0",'Kit report'!F15) -> 132 | I13: =IF('Kit report'!X15<0,"0",'Kit report'!X15) -> 20 | J13: =IF('Utility summery'!H17<0,"0",'Utility summery'!H17) -> 24 | K13: =IF('UTILITY REPORT 1'!H14<0,"0",'UTILITY REPORT 1'!H14) -> 49 | L13: ='Water-Meter'!K17 -> 1 | M13: ='Water-Meter'!H17 -> 0 | N13: ='Water-Meter'!Q17 -> 1 | O13: =K13*E13+H13*I13+#REF!*#REF!+J13*L13 -> #REF! | P13: ='Water-Meter'!E17 -> 41 | Q13: =IF('Water-Meter'!U17<0,"0",'Water-Meter'!U17) -> 0 | R13: =IF('Water-Meter'!X17<0,"0",'Water-Meter'!X17) -> 0 | S13: =IF('Water-Meter'!AA17<0,"0",'Water-Meter'!AA17) -> 0 | T13: =IF('Water-Meter'!AD17<0,"0",'Water-Meter'!AD17) -> 16 | U13: =IF('Water-Meter'!AG17<0,"0",'Water-Meter'!AG17) -> 25 | V13: =IF('Water-Meter'!AJ17<0,"0",'Water-Meter'!AJ17) -> 0 | W13: ='Water-Meter'!AN17 -> 41 | X13: =Total!K13 -> 0
A14: Serengeti | B14: =B13+1 -> 13 | C14: 4 | D14: 2020 | E14: ='UTILITY REPORT 1'!I15 -> 19.86 | F14: ='UTILITY REPORT 1'!E15 -> 771.72 | G14: ='UTILITY REPORT 1'!F15 -> 1796 | H14: =IF('Kit report'!F16<0,"0",'Kit report'!F16) -> 132 | I14: =IF('Kit report'!X16<0,"0",'Kit report'!X16) -> 20 | J14: =IF('Utility summery'!H18<0,"0",'Utility summery'!H18) -> 31 | K14: =IF('UTILITY REPORT 1'!H15<0,"0",'UTILITY REPORT 1'!H15) -> 50 | L14: ='Water-Meter'!K18 -> 0 | M14: ='Water-Meter'!H18 -> 0 | N14: ='Water-Meter'!Q18 -> 1 | O14: =K14*E14+H14*I14+#REF!*#REF!+J14*L14 -> #REF! | P14: ='Water-Meter'!E18 -> 45 | Q14: =IF('Water-Meter'!U18<0,"0",'Water-Meter'!U18) -> 0 | R14: =IF('Water-Meter'!X18<0,"0",'Water-Meter'!X18) -> 0 | S14: =IF('Water-Meter'!AA18<0,"0",'Water-Meter'!AA18) -> 0 | T14: =IF('Water-Meter'!AD18<0,"0",'Water-Meter'!AD18) -> 16 | U14: =IF('Water-Meter'!AG18<0,"0",'Water-Meter'!AG18) -> 25 | V14: =IF('Water-Meter'!AJ18<0,"0",'Water-Meter'!AJ18) -> 0 | W14: ='Water-Meter'!AN18 -> 41 | X14: =Total!K14 -> 0
... A30: Serengeti | B30: =B29+1 -> 29 | C30: 4 | D30: 2020 | E30: ='UTILITY REPORT 1'!I31 -> 38.11 | F30: ='UTILITY REPORT 1'!E31 -> 691.09 | G30: ='UTILITY REPORT 1'!F31 -> 1644 | H30: =IF('Kit report'!F32<0,"0",'Kit report'!F32) -> 108 | I30: =IF('Kit report'!X32<0,"0",'Kit report'!X32) -> 0 | J30: =IF('Utility summery'!H34<0,"0",'Utility summery'!H34) -> 42 | K30: =IF('UTILITY REPORT 1'!H31<0,"0",'UTILITY REPORT 1'!H31) -> 83 | L30: ='Water-Meter'!K34 -> 1 | M30: ='Water-Meter'!H34 -> 0 | N30: ='Water-Meter'!Q34 -> 1 | O30: =K30*E30+H30*I30+#REF!*#REF!+J30*L30 -> #REF! | P30: ='Water-Meter'!E34 -> 29 | Q30: =IF('Water-Meter'!U34<0,"0",'Water-Meter'!U34) -> 0 | R30: =IF('Water-Meter'!X34<0,"0",'Water-Meter'!X34) -> 0 | S30: =IF('Water-Meter'!AA34<0,"0",'Water-Meter'!AA34) -> 0 | T30: =IF('Water-Meter'!AD34<0,"0",'Water-Meter'!AD34) -> 20 | U30: =IF('Water-Meter'!AG34<0,"0",'Water-Meter'!AG34) -> 25 | V30: =IF('Water-Meter'!AJ34<0,"0",'Water-Meter'!AJ34) -> 0 | W30: ='Water-Meter'!AN34 -> 45 | X30: =Total!K30 -> 0
A31: Serengeti | B31: 30 | C31: 4 | D31: 2020 | E31: ='UTILITY REPORT 1'!I32 -> 0 | F31: ='UTILITY REPORT 1'!E32 -> 660.76 | G31: ='UTILITY REPORT 1'!F32 -> 1564 | H31: =IF('Kit report'!F33<0,"0",'Kit report'!F33) -> 96 | I31: =IF('Kit report'!X33<0,"0",'Kit report'!X33) -> 20 | J31: =IF('Utility summery'!H35<0,"0",'Utility summery'!H35) -> 70 | K31: =IF('UTILITY REPORT 1'!H32<0,"0",'UTILITY REPORT 1'!H32) -> 0 | L31: ='Water-Meter'!K35 -> 0 | M31: ='Water-Meter'!H35 -> 0 | N31: ='Water-Meter'!Q35 -> 1 | O31: =K31*E31+H31*I31+#REF!*#REF!+J31*L31 -> #REF! | P31: ='Water-Meter'!E35 -> 29 | Q31: =IF('Water-Meter'!U35<0,"0",'Water-Meter'!U35) -> 0 | R31: =IF('Water-Meter'!X35<0,"0",'Water-Meter'!X35) -> 0 | S31: =IF('Water-Meter'!AA35<0,"0",'Water-Meter'!AA35) -> 0 | T31: =IF('Water-Meter'!AD35<0,"0",'Water-Meter'!AD35) -> 21 | U31: =IF('Water-Meter'!AG35<0,"0",'Water-Meter'!AG35) -> 25 | V31: =IF('Water-Meter'!AJ35<0,"0",'Water-Meter'!AJ35) -> 0 | W31: ='Water-Meter'!AN35 -> 46 | X31: =Total!K31 -> 0
A32: Serengeti | B32: 31 | C32: 4 | D32: 2020 | E32: ='UTILITY REPORT 1'!I33 -> 0 | F32: ='UTILITY REPORT 1'!E33 -> 0 | G32: ='UTILITY REPORT 1'!F33 -> 0 | H32: =IF('Kit report'!F34<0,"0",'Kit report'!F34) -> 0 | I32: =IF('Kit report'!X34<0,"0",'Kit report'!X34) -> 0 | J32: =IF('Utility summery'!H36<0,"0",'Utility summery'!H36) -> 0 | K32: =IF('UTILITY REPORT 1'!H33<0,"0",'UTILITY REPORT 1'!H33) -> 0 | L32: ='Water-Meter'!K36 -> 0 | M32: ='Water-Meter'!H36 -> 0 | N32: ='Water-Meter'!Q36 -> 0 | P32: ='Water-Meter'!E36 -> 0 | Q32: =IF('Water-Meter'!U36<0,"0",'Water-Meter'!U36) -> 0 | R32: =IF('Water-Meter'!X36<0,"0",'Water-Meter'!X36) -> 0 | S32: =IF('Water-Meter'!AA36<0,"0",'Water-Meter'!AA36) -> 0 | T32: =IF('Water-Meter'!AD36<0,"0",'Water-Meter'!AD36) -> 0 | U32: =IF('Water-Meter'!AG36<0,"0",'Water-Meter'!AG36) -> 0 | V32: =IF('Water-Meter'!AJ36<0,"0",'Water-Meter'!AJ36) -> 0 | W32: ='Water-Meter'!AN36 -> 0 | X32: =Total!K32 -> 0

Sheet UTILITY REPORT 1
A1: APRIL UTILITY REPORT
A2: Date | B2: % | C2: Guest Rooms Occupied | D2: Diesel cost Per Liter ($) | E2: Diesel consumption (LT) | F2: Power production (KW) | G2: Water consumption (M3) | H2: RO prodution (M3) | I2: Transport Consupmtion (LT)
A3: =Gen!B11 -> 43922 | B3: =Gen!C11 -> 0 | C3: ='Summery Report'!E5 -> 0 | D3: 1 | E3: =Gen!T11 -> 850.96 | F3: =Gen!U11 -> 2051 | G3: ='Water-Meter'!E6 -> 38 | H3: ='Utility report '!AC6 -> 0 | I3: =Gen!AK11 -> 49.37
A4: =Gen!B12 -> 43923 | B4: =Gen!C12 -> 0 | C4: ='Summery Report'!E6 -> 0 | D4: 1 | E4: =Gen!T12 -> 866.25 | F4: =Gen!U12 -> 2088 | G4: ='Water-Meter'!E7 -> 52 | H4: ='Utility report '!AC7 -> 48 | I4: =Gen!AK12 -> 9.39
A5: =Gen!B13 -> 43924 | B5: =Gen!C13 -> 0 | C5: ='Summery Report'!E7 -> 0 | D5: 1 | E5: =Gen!T13 -> 832.92 | F5: =Gen!U13 -> 1898 | G5: ='Water-Meter'!E8 -> 26 | H5: ='Utility report '!AC8 -> 59 | I5: =Gen!AK13 -> 18.02
A6: =Gen!B14 -> 43925 | B6: =Gen!C14 -> 0 | C6: ='Summery Report'!E8 -> 0 | D6: 1 | E6: =Gen!T14 -> 789.55 | F6: =Gen!U14 -> 1815 | G6: ='Water-Meter'!E9 -> 34 | H6: ='Utility report '!AC9 -> 57 | I6: =Gen!AK14 -> 660.37
A7: =Gen!B15 -> 43926 | B7: =Gen!C15 -> 0 | C7: ='Summery Report'!E9 -> 0 | D7: 1 | E7: =Gen!T15 -> 813.34 | F7: =Gen!U15 -> 1841 | G7: ='Water-Meter'!E10 -> 42 | H7: ='Utility report '!AC10 -> 57 | I7: =Gen!AK15 -> 34.28
A8: =Gen!B16 -> 43927 | B8: =Gen!C16 -> 0 | C8: ='Summery Report'!E10 -> 0 | D8: 1 | E8: =Gen!T16 -> 757.53 | F8: =Gen!U16 -> 1789 | G8: ='Water-Meter'!E11 -> 41 | H8: ='Utility report '!AC11 -> 38 | I8: =Gen!AK16 -> 0
A9: =Gen!B17 -> 43928 | B9: =Gen!C17 -> 0 | C9: ='Summery Report'!E11 -> 0 | D9: 1 | E9: =Gen!T17 -> 783.55 | F9: =Gen!U17 -> 1867 | G9: ='Water-Meter'!E12 -> 47 | H9: ='Utility report '!AC12 -> 53 | I9: =Gen!AK17 -> 108.2
A10: =Gen!B18 -> 43929 | B10: =Gen!C18 -> 0 | C10: ='Summery Report'!E12 -> 0 | D10: 1 | E10: =Gen!T18 -> 831.27 | F10: =Gen!U18 -> 1940 | G10: ='Water-Meter'!E13 -> 36 | H10: ='Utility report '!AC13 -> 50 | I10: =Gen!AK18 -> 0
A11: =Gen!B19 -> 43930 | B11: =Gen!C19 -> 0 | C11: ='Summery Report'!E13 -> 0 | D11: 1 | E11: =Gen!T19 -> 806.32 | F11: =Gen!U19 -> 1882 | G11: ='Water-Meter'!E14 -> 33 | H11: ='Utility report '!AC14 -> 7 | I11: =Gen!AK19 -> 0
A12: =Gen!B20 -> 43931 | B12: =Gen!C20 -> 0 | C12: ='Summery Report'!E14 -> 0 | D12: 1 | E12: =Gen!T20 -> 823.75 | F12: =Gen!U20 -> 1935 | G12: ='Water-Meter'!E15 -> 55 | H12: ='Utility report '!AC15 -> 44 | I12: =Gen!AK20 -> 0
A13: =Gen!B21 -> 43932 | B13: =Gen!C21 -> 0 | C13: ='Summery Report'!E15 -> 0 | D13: 1 | E13: =Gen!T21 -> 782.67 | F13: =Gen!U21 -> 1883 | G13: ='Water-Meter'!E16 -> 56 | H13: ='Utility report '!AC16 -> 75 | I13: =Gen!AK21 -> 0
A14: =Gen!B22 -> 43933 | B14: =Gen!C22 -> 0 | C14: ='Summery Report'!E16 -> 0 | D14: 1 | E14: =Gen!T22 -> 776.8 | F14: =Gen!U22 -> 1877 | G14: ='Water-Meter'!E17 -> 41 | H14: ='Utility report '!AC17 -> 49 | I14: =Gen!AK22 -> 0
... A34: =Gen!B42 -> 0 | B34: =Gen!C42 -> 0 | C34: ='Summery Report'!E36 -> 0 | D34: 2 | E34: =Gen!T42 -> 0 | F34: =Gen!U42 -> 0 | G34: ='Water-Meter'!E37 -> 0 | H34: ='Utility report '!AC37 -> 0 | I34: =Gen!AK42 -> 0

Sheet Utility summery
A4: Date | B4: Room Occupied | C4: Electricity Units Generated KW | D4: Diseal | G4: Water | J4: Gas | N4: Cost of utilites
D5: Generator | E5: Transport | F5: Total | G5: RO | H5: STP | I5: Total Consumption | J5: 2 ton | K5: 1 Ton | L5: 1 Ton | M5: Total consumption | N5: Electricity /1.4$/liter | O5: Diseal for Transport | P5: Gas /2.38$/Kg | Q5: Total HLP Cost | R5: Electricity Cost/Room $ | S5: cost/Room $
A6: =Gen!B11 -> 43922 | B6: ='Summery Report'!E5 -> 0 | C6: =Gen!U11 -> 2051 | D6: =Gen!T11 -> 850.96 | E6: =Gen!AK11 -> 49.37 | F6: =Gen!AS11 -> 900.33 | G6: ='Utility report '!AC6 -> 0 | H6: ='Utility report '!AE6 -> 28 | I6: ='Water-Meter'!E6 -> 38 | J6: ='Lpg (2)'!B10 -> 16 | K6: ='Lpg (2)'!C10 -> 85 | L6: ='Lpg (2)'!D10 -> 66 | M6: ='Lpg (2)'!G10 -> 61.6 | O6: =E6 -> 49.37 | P6: ='[1]Lpg (2)'!#REF! -> #REF! | Q6: ='[1]Summery Report'!#REF! -> #REF! | R6: =N6/B6 -> #DIV/0! | S6: =Q6/B6 -> #REF!
A7: =Gen!B12 -> 43923 | B7: ='Summery Report'!E6 -> 0 | C7: =Gen!U12 -> 2088 | D7: =Gen!T12 -> 866.25 | E7: =Gen!AK12 -> 9.39 | F7: =Gen!AS12 -> 875.64 | G7: ='Utility report '!AC7 -> 48 | H7: ='Utility report '!AE7 -> 29 | I7: ='Water-Meter'!E7 -> 52 | J7: ='Lpg (2)'!B11 -> 16 | K7: ='Lpg (2)'!C11 -> 85 | L7: ='Lpg (2)'!D11 -> 66 | M7: ='Lpg (2)'!G11 -> 66 | N7: =D7*1.4 -> 1212.75 | O7: =E7*1.4 -> 13.146 | P7: ='[1]Lpg (2)'!#REF! -> #REF! | Q7: ='[1]Summery Report'!#REF! -> #REF! | R7: =N7/B7 -> #DIV/0! | S7: =Q7/B7 -> #REF!
A8: =Gen!B13 -> 43924 | B8: ='Summery Report'!E7 -> 0 | C8: =Gen!U13 -> 1898 | D8: =Gen!T13 -> 832.92 | E8: =Gen!AK13 -> 18.02 | F8: =Gen!AS13 -> 850.94 | G8: ='Utility report '!AC8 -> 59 | H8: ='Utility report '!AE8 -> 19 | I8: ='Water-Meter'!E8 -> 26 | J8: ='Lpg (2)'!B12 -> 15 | K8: ='Lpg (2)'!C12 -> 85 | L8: ='Lpg (2)'!D12 -> 66 | M8: ='Lpg (2)'!G12 -> 37.532 | N8: =D8*1.4 -> 1166.088 | O8: =E8*1.4 -> 25.228 | P8: ='[1]Lpg (2)'!#REF! -> #REF! | Q8: ='[1]Summery Report'!#REF! -> #REF! | R8: =N8/B8 -> #DIV/0! | S8: =Q8/B8 -> #REF!
A9: =Gen!B14 -> 43925 | B9: ='Summery Report'!E8 -> 0 | C9: =Gen!U14 -> 1815 | D9: =Gen!T14 -> 789.55 | E9: =Gen!AK14 -> 660.37 | F9: =Gen!AS14 -> 1449.92 | G9: ='Utility report '!AC9 -> 57 | H9: ='Utility report '!AE9 -> 0 | I9: ='Water-Meter'!E9 -> 34 | J9: ='Lpg (2)'!B13 -> 14 | K9: ='Lpg (2)'!C13 -> 85 | L9: ='Lpg (2)'!D13 -> 66 | M9: ='Lpg (2)'!G13 -> 31.46 | N9: =D9*1.4 -> 1105.37 | O9: =E9*1.4 -> 924.518 | P9: ='[1]Lpg (2)'!#REF! -> #REF! | Q9: ='[1]Summery Report'!#REF! -> #REF! | R9: =N9/B9 -> #DIV/0! | S9: =Q9/B9 -> #REF!
A10: =Gen!B15 -> 43926 | B10: ='Summery Report'!E9 -> 0 | C10: =Gen!U15 -> 1841 | D10: =Gen!T15 -> 813.34 | E10: =Gen!AK15 -> 34.28 | F10: =Gen!AS15 -> 847.62 | G10: ='Utility report '!AC10 -> 57 | H10: ='Utility report '!AE10 -> 48 | I10: ='Water-Meter'!E10 -> 42 | J10: ='Lpg (2)'!B14 -> 13 | K10: ='Lpg (2)'!C14 -> 85 | L10: ='Lpg (2)'!D14 -> 66 | M10: ='Lpg (2)'!G14 -> 27.808 | N10: =D10*1.4 -> 1138.676 | O10: =E10*1.4 -> 47.992 | P10: ='[1]Lpg (2)'!#REF! -> #REF! | Q10: ='[1]Summery Report'!#REF! -> #REF! | R10: =N10/B10 -> #DIV/0! | S10: =Q10/B10 -> #REF!
A11: =Gen!B16 -> 43927 | B11: ='Summery Report'!E10 -> 0 | C11: =Gen!U16 -> 1789 | D11: =Gen!T16 -> 757.53 | E11: =Gen!AK16 -> 0 | F11: =Gen!AS16 -> 757.53 | G11: ='Utility report '!AC11 -> 38 | H11: ='Utility report '!AE11 -> 18 | I11: ='Water-Meter'!E11 -> 41 | J11: ='Lpg (2)'!B15 -> 13 | K11: ='Lpg (2)'!C15 -> 85 | L11: ='Lpg (2)'!D15 -> 66 | M11: ='Lpg (2)'!G15 -> 14.608 | N11: =D11*1.4 -> 1060.542 | O11: =E11*1.4 -> 0 | P11: ='[1]Lpg (2)'!#REF! -> #REF! | Q11: ='[1]Summery Report'!#REF! -> #REF! | R11: =N11/B11 -> #DIV/0! | S11: =Q11/B11 -> #REF!
A12: =Gen!B17 -> 43928 | B12: ='Summery Report'!E11 -> 0 | C12: =Gen!U17 -> 1867 | D12: =Gen!T17 -> 783.55 | E12: =Gen!AK17 -> 108.2 | F12: =Gen!AS17 -> 891.75 | G12: ='Utility report '!AC12 -> 53 | H12: ='Utility report '!AE12 -> 32 | I12: ='Water-Meter'!E12 -> 47 | J12: ='Lpg (2)'!B16 -> 13 | K12: ='Lpg (2)'!C16 -> 85 | L12: ='Lpg (2)'!D16 -> 66 | M12: ='Lpg (2)'!G16 -> 25.212 | N12: =D12*1.4 -> 1096.97 | O12: =E12*1.4 -> 151.48 | P12: ='[1]Lpg (2)'!#REF! -> #REF! | Q12: ='[1]Summery Report'!#REF! -> #REF! | R12: =N12/B12 -> #DIV/0! | S12: =Q12/B12 -> #REF!
A13: =Gen!B18 -> 43929 | B13: ='Summery Report'!E12 -> 0 | C13: =Gen!U18 -> 1940 | D13: =Gen!T18 -> 831.27 | E13: =Gen!AK18 -> 0 | F13: =Gen!AS18 -> 831.27 | G13: ='Utility report '!AC13 -> 50 | H13: ='Utility report '!AE13 -> 28 | I13: ='Water-Meter'!E13 -> 36 | J13: ='Lpg (2)'!B17 -> 13 | K13: ='Lpg (2)'!C17 -> 85 | L13: ='Lpg (2)'!D17 -> 66 | M13: ='Lpg (2)'!G17 -> 36.3 | N13: =D13*1.4 -> 1163.778 | O13: =E13*1.4 -> 0 | P13: ='[1]Lpg (2)'!#REF! -> #REF! | Q13: ='[1]Summery Report'!#REF! -> #REF! | R13: =N13/B13 -> #DIV/0! | S13: =Q13/B13 -> #REF!
A14: =Gen!B19 -> 43930 | B14: ='Summery Report'!E13 -> 0 | C14: =Gen!U19 -> 1882 | D14: =Gen!T19 -> 806.32 | E14: =Gen!AK19 -> 0 | F14: =Gen!AS19 -> 806.32 | G14: ='Utility report '!AC14 -> 7 | H14: ='Utility report '!AE14 -> 26 | I14: ='Water-Meter'!E14 -> 33 | J14: ='Lpg (2)'!B18 -> 13 | K14: ='Lpg (2)'!C18 -> 85 | L14: ='Lpg (2)'!D18 -> 66 | M14: ='Lpg (2)'!G18 -> 25.916 | N14: =D14*1.4 -> 1128.848 | O14: =E14*1.4 -> 0 | P14: ='[1]Lpg (2)'!#REF! -> #REF! | Q14: ='[1]Summery Report'!#REF! -> #REF! | R14: =N14/B14 -> #DIV/0! | S14: =Q14/B14 -> #REF!
A15: =Gen!B20 -> 43931 | B15: ='Summery Report'!E14 -> 0 | C15: =Gen!U20 -> 1935 | D15: =Gen!T20 -> 823.75 | E15: =Gen!AK20 -> 0 | F15: =Gen!AS20 -> 823.75 | G15: ='Utility report '!AC15 -> 44 | H15: ='Utility report '!AE15 -> 26 | I15: ='Water-Meter'!E15 -> 55 | J15: ='Lpg (2)'!B19 -> 12 | K15: ='Lpg (2)'!C19 -> 85 | L15: ='Lpg (2)'!D19 -> 66 | M15: ='Lpg (2)'!G19 -> 34.54 | N15: =D15*1.4 -> 1153.25 | O15: =E15*1.4 -> 0 | P15: ='[1]Lpg (2)'!#REF! -> #REF! | Q15: ='[1]Summery Report'!#REF! -> #REF! | R15: =N15/B15 -> #DIV/0! | S15: =Q15/B15 -> #REF!
A16: =Gen!B21 -> 43932 | B16: ='Summery Report'!E15 -> 0 | C16: =Gen!U21 -> 1883 | D16: =Gen!T21 -> 782.67 | E16: =Gen!AK21 -> 0 | F16: =Gen!AS21 -> 782.67 | G16: ='Utility report '!AC16 -> 75 | H16: ='Utility report '!AE16 -> 28 | I16: ='Water-Meter'!E16 -> 56 | J16: ='Lpg (2)'!B20 -> 12 | K16: ='Lpg (2)'!C20 -> 85 | L16: ='Lpg (2)'!D20 -> 66 | M16: ='Lpg (2)'!G20 -> 38.412 | N16: =D16*1.4 -> 1095.738 | O16: =E16*1.4 -> 0 | P16: ='[1]Lpg (2)'!#REF! -> #REF! | Q16: ='[1]Summery Report'!#REF! -> #REF! | R16: =N16/B16 -> #DIV/0! | S16: =Q16/B16 -> #REF!
A17: =Gen!B22 -> 43933 | B17: ='Summery Report'!E16 -> 0 | C17: =Gen!U22 -> 1877 | D17: =Gen!T22 -> 776.8 | E17: =Gen!AK22 -> 0 | F17: =Gen!AS22 -> 776.8 | G17: ='Utility report '!AC17 -> 49 | H17: ='Utility report '!AE17 -> 24 | I17: ='Water-Meter'!E17 -> 41 | J17: ='Lpg (2)'!B21 -> 8 | K17: ='Lpg (2)'!C21 -> 85 | L17: ='Lpg (2)'!D21 -> 66 | M17: ='Lpg (2)'!G21 -> 35.2 | N17: =D17*1.4 -> 1087.52 | O17: =E17*1.4 -> 0 | P17: ='[1]Lpg (2)'!#REF! -> #REF! | Q17: ='[1]Summery Report'!#REF! -> #REF! | R17: =N17/B17 -> #DIV/0! | S17: =Q17/B17 -> #REF!
A18: =Gen!B23 -> 43934 | B18: ='Summery Report'!E17 -> 0 | C18: =Gen!U23 -> 1796 | D18: =Gen!T23 -> 771.72 | E18: =Gen!AK23 -> 19.86 | F18: =Gen!AS23 -> 791.58 | G18: ='Utility report '!AC18 -> 50 | H18: ='Utility report '!AE18 -> 31 | I18: ='Water-Meter'!E18 -> 45 | J18: ='Lpg (2)'!B22 -> 8 | K18: ='Lpg (2)'!C22 -> 85 | L18: ='Lpg (2)'!D22 -> 66 | M18: ='Lpg (2)'!G22 -> 36.036 | N18: =D18*1.4 -> 1080.408 | O18: =E18*1.4 -> 27.804 | P18: ='[1]Lpg (2)'!#REF! -> #REF! | Q18: ='[1]Summery Report'!#REF! -> #REF! | R18: =N18/B18 -> #DIV/0! | S18: =Q18/B18 -> #REF!
... A32: =Gen!B37 -> 43948 | B32: ='Summery Report'!E31 -> 0 | C32: =Gen!U37 -> 1721 | D32: =Gen!T37 -> 716.78 | E32: =Gen!AK37 -> 7.38 | F32: =Gen!AS37 -> 724.16 | G32: ='Utility report '!AC32 -> 58 | H32: ='Utility report '!AE32 -> 52 | I32: ='Water-Meter'!E32 -> 30 | J32: ='Lpg (2)'!B36 -> 85 | K32: ='Lpg (2)'!C36 -> 85 | L32: ='Lpg (2)'!D36 -> 55 | M32: ='Lpg (2)'!G36 -> 28.6 | N32: =D32*1.4 -> 1003.492 | O32: =E32*1.4 -> 10.332 | P32: ='[1]Lpg (2)'!#REF! -> #REF! | Q32: ='[1]Summery Report'!#REF! -> #REF! | R32: =N32/B32 -> #DIV/0! | S32: =Q32/B32 -> #REF!
A33: =Gen!B38 -> 43949 | B33: ='Summery Report'!E32 -> 0 | C33: =Gen!U38 -> 1637 | D33: =Gen!T38 -> 690.55 | E33: =Gen!AK38 -> 100 | F33: =Gen!AS38 -> 790.55 | G33: ='Utility report '!AC33 -> 0 | H33: ='Utility report '!AE33 -> 47 | I33: ='Water-Meter'!E33 -> 31 | J33: ='Lpg (2)'!B37 -> 85 | K33: ='Lpg (2)'!C37 -> 85 | L33: ='Lpg (2)'!D37 -> 53 | M33: ='Lpg (2)'!G37 -> 31.24 | N33: =D33*1.4 -> 966.77 | O33: =E33*1.4 -> 140 | P33: ='[1]Lpg (2)'!#REF! -> #REF! | Q33: ='[1]Summery Report'!#REF! -> #REF! | R33: =N33/B33 -> #DIV/0! | S33: =Q33/B33 -> #REF! | T33: =3124/13 -> 240.30769
A34: =Gen!B39 -> 43950 | B34: ='Summery Report'!E33 -> 0 | C34: =Gen!U39 -> 1644 | D34: =Gen!T39 -> 691.09 | E34: =Gen!AK39 -> 38.11 | F34: =Gen!AS39 -> 729.2 | G34: ='Utility report '!AC34 -> 83 | H34: ='Utility report '!AE34 -> 42 | I34: ='Water-Meter'!E34 -> 29 | J34: ='Lpg (2)'!B38 -> 85 | K34: ='Lpg (2)'!C38 -> 85 | L34: ='Lpg (2)'!D38 -> 50 | M34: ='Lpg (2)'!G38 -> 40.92 | N34: =D34*1.4 -> 967.526 | O34: =E34*1.4 -> 53.354 | P34: ='[1]Lpg (2)'!#REF! -> #REF! | Q34: ='[1]Summery Report'!#REF! -> #REF! | R34: =N34/B34 -> #DIV/0! | S34: =Q34/B34 -> #REF!
A35: =Gen!B40 -> 43951 | B35: ='Summery Report'!E34 -> 0 | C35: =Gen!U40 -> 1564 | D35: =Gen!T40 -> 660.76 | E35: =Gen!AK40 -> 0 | F35: =Gen!AS40 -> 660.76 | G35: ='Utility report '!AC35 -> 0 | H35: ='Utility report '!AE35 -> 70 | I35: ='Water-Meter'!E35 -> 29 | J35: ='Lpg (2)'!B39 -> 85 | K35: ='Lpg (2)'!C39 -> 85 | L35: ='Lpg (2)'!D39 -> 48 | M35: ='Lpg (2)'!G39 -> 17.424 | N35: =D35*1.4 -> 925.064 | O35: =E35*1.4 -> 0 | P35: ='[1]Lpg (2)'!#REF! -> #REF! | Q35: ='[1]Summery Report'!#REF! -> #REF! | R35: =N35/B35 -> #DIV/0! | S35: =Q35/B35 -> #REF!
A36: =Gen!B41 -> 0 | B36: ='Summery Report'!E35 -> 0 | C36: =Gen!U41 -> 0 | D36: =Gen!T41 -> 0 | E36: =Gen!AK41 -> 0 | F36: =Gen!AS41 -> 0 | G36: ='Utility report '!AC36 -> -31534 | H36: ='Utility report '!AE36 -> -200738 | I36: ='Water-Meter'!E36 -> 0 | J36: ='Lpg (2)'!B40 -> 85 | K36: ='Lpg (2)'!C40 -> 85 | L36: ='Lpg (2)'!D40 -> 45 | M36: ='Lpg (2)'!G40 -> 27.852 | N36: =D36*1.4 -> 0 | O36: =E36*1.4 -> 0 | P36: ='[1]Lpg (2)'!#REF! -> #REF! | Q36: ='[1]Summery Report'!#REF! -> #REF! | R36: =N36/B36 -> #DIV/0! | S36: =Q36/B36 -> #REF!
A37: =Gen!B42 -> 0 | B37: ='Summery Report'!E36 -> 0 | C37: =Gen!U42 -> 0 | D37: =Gen!T42 -> 0 | E37: =Gen!AK42 -> 0 | F37: =Gen!AS42 -> 0 | G37: ='Utility report '!AC37 -> 0 | H37: ='Utility report '!AE37 -> 0 | I37: ='Water-Meter'!E37 -> 0 | J37: ='Lpg (2)'!B41 -> 0 | K37: ='Lpg (2)'!C41 -> 0 | L37: ='Lpg (2)'!D41 -> 0 | M37: ='Lpg (2)'!G41 -> 0 | Q37: ='[1]Summery Report'!#REF! -> #REF! | R37: =N37/B37 -> #DIV/0! | S37: =Q37/B37 -> #REF!
A39: Total | B39: =SUM(B7:B37) -> 0 | C39: =SUM(C7:C35) -> 51720 | D39: =SUM(D7:D35) -> 21971.81 | E39: =SUM(E7:E35) -> 1809.04 | F39: =SUM(F7:F35) -> 23780.85 | G39: =SUM(G7:G35) -> 1285 | H39: =SUM(H7:H35) -> 1245 | I39: =SUM(I7:I35) -> 1122 | J39: =SUM(J7:J35) -> 946 | ... S39: =SUM(S7:S35) -> #REF!

Sheet Utility report 
A1: DAILY UTILITY REPORT March 2020
A2: Date | B2: Total occupancy | H2: Diesel balance LTS | I2: Diesel Deliveries | J2: Gen.Diesel consumption LTS | L2: Total Diesel consumption LTS | M2: Water Meter reading | N2: Water consumption m³ | O2: R.O WATER PRODUCTION LTRS + TIME | AA2: Total RO production | AB2: RO Meter reading | AD2: 0 | AE2: STP | AF2: GAS TANK A | AG2: GAS TANK B | AH2: GAS TANK C | AI2: Total Gas Tanks | AJ2: Kg /day | AK2: TOTAL GAS cons.
A3: Rate Tsh /$ | B3: 1640 | C3: Diesel cost / lits | D3: 2175 | F3: =SUM(D3/B3) -> 1.3262195 | H3: =Gen!D11 -> 41048.87 | K3: Transport consumption | M3: Balance | O3: PLANT NO 1 | S3: PLANT NO 2 | W3: PLANT NO 3 | AA3: /day | AB3: Balance | AC3: Production | AD3: 0 | AE3: Production | AF3: Capacity | AG3: Capacity | AH3: Capacity | AI3: Kg | AJ3: /day | AK3: /day
B4: Rooms OCC | C4: % | D4: Guest Rooms Occ | F4: Electricity Production Cost /Room Occ by guest | G4: All Cost /Room Occ by guest | O4: Flow M3 | P4: Reading Hours Meter | Q4: Hrs | R4: total production M3 | S4: Flow M3 | T4: Reading Hours Meter | U4: Hrs | V4: total production M3 | W4: Flow M3 | X4: READING HOURS METER | Y4: Hrs | Z4: total production M3 | AA4: M3 | AC4: M3 | AE4: M3 | AF4: 2000 | AG4: 1000 | AH4: 1000 | AI4: =SUM([2]Sheet1!$AA$36) -> 950 | AJ4: Kg | AK4: M3
P5: 19027 | T5: 16086 | X5: 24240 | AB5: 30249 | AD5: 199465 | AF5: 0.85 | AG5: 0.85 | AH5: 0.85
A6: =Gen!B11 -> 43922 | B6: ='Summery Report'!E5 -> 0 | C6: =Gen!C11 -> 0 | D6: ='Summery Report'!E5 -> 0 | E6: =SUM(F3) -> 1.3262195 | F6: =SUM(J6*E6)/D6 -> #DIV/0! | G6: =SUM(L6*E6)/D6 -> #DIV/0! | H6: =Gen!D11 -> 41048.87 | I6: =Gen!F11 -> 0 | J6: =Gen!T11 -> 850.96 | K6: =Gen!AK11 -> 49.37 | L6: =SUM(J6:K6) -> 900.33 | M6: ='Water-Meter'!K46 -> 434.92781 | N6: ='Water-Meter'!E6 -> 38 | P6: 19027 | Q6: =SUM(P6-P5) -> 0 | R6: =SUM(Q6*O6) -> 0 | T6: 16086 | U6: =T6-T5 -> 0 | V6: - | X6: 24240 | Y6: =X6-X5 -> 0 | Z6: =Y6-Y5 -> 0 | AA6: =Z6-Z5 -> 0 | AB6: 30249 | AC6: =AB6-AB5 -> 0 | AD6: 199493 | AE6: =AD6-AD5 -> 28 | AF6: ='Lpg (2)'!B10*2000/85 -> 376.47059 | AG6: ='Lpg (2)'!C10*1000/85 -> 1000 | AH6: ='Lpg (2)'!D10*1000/85 -> 776.47059 | AI6: =SUM(AF6*2000)+(AG6*1000)+(AH6*1000) -> 2529411.8 | AJ6: =SUM(AI5-AI6) -> -2529411.8
A7: =Gen!B12 -> 43923 | B7: ='Summery Report'!E6 -> 0 | C7: =Gen!C12 -> 0 | D7: ='Summery Report'!E6 -> 0 | E7: =SUM(E6) -> 1.3262195 | F7: =SUM(J7*E7)/D7 -> #DIV/0! | G7: =SUM(L7*E7)/D7 -> #DIV/0! | H7: =Gen!D12 -> 40148.54 | I7: =Gen!F12 -> 0 | J7: =Gen!T12 -> 866.25 | K7: =Gen!AK12 -> 9.39 | L7: =SUM(J7:K7) -> 875.64 | M7: ='Water-Meter'!K47 -> 503.07762 | N7: ='Water-Meter'!E7 -> 52 | O7: 2.3 | P7: 19029 | Q7: =SUM(P7-P6) -> 2 | R7: =SUM(Q7*O7) -> 4.6 | T7: 16086 | U7: =T7-T6 -> 0 | V7: =SUM(U7*S7) -> 0 | W7: 2.4 | X7: 24259 | Y7: =X7-X6 -> 19 | Z7: =SUM(Y7*W7) -> 45.6 | AA7: =SUM(Z7*X9) -> 1108399.2 | AB7: 30297 | AC7: =AB7-AB6 -> 48 | AD7: 199522 | AE7: =AD7-AD6 -> 29 | AF7: ='Lpg (2)'!B11*2000/85 -> 376.47059 | AG7: ='Lpg (2)'!C11*1000/85 -> 1000 | AH7: ='Lpg (2)'!D11*1000/85 -> 776.47059 | AI7: =SUM(AF6*2000)+(AG7*1000)+(AH7*1000) -> 2529411.8 | AJ7: =SUM(AI6-AI7) -> 0
A8: =Gen!B13 -> 43924 | B8: ='Summery Report'!E7 -> 0 | C8: =Gen!C13 -> 0 | D8: ='Summery Report'!E7 -> 0 | E8: =SUM(E7) -> 1.3262195 | F8: =SUM(J8*E8)/D8 -> #DIV/0! | G8: =SUM(L8*E8)/D8 -> #DIV/0! | H8: =Gen!D13 -> 39272.9 | I8: =Gen!F13 -> 0 | J8: =Gen!T13 -> 832.92 | K8: =Gen!AK13 -> 18.02 | L8: =SUM(J8:K8) -> 850.94 | M8: ='Water-Meter'!K48 -> 507.01618 | N8: ='Water-Meter'!E8 -> 26 | P8: 19029 | Q8: =SUM(P8-P7) -> 0 | R8: =SUM(Q8*O8) -> 0 | T8: 16086 | U8: =T8-T7 -> 0 | V8: =SUM(U8*S8) -> 0 | W8: 2.5 | X8: 24283 | Y8: =X8-X7 -> 24 | Z8: =SUM(Y8*W8) -> 60 | AA8: =SUM(Z8*X10) -> 1459860 | AB8: 30356 | AC8: =AB8-AB7 -> 59 | AD8: 199541 | AE8: =AD8-AD7 -> 19 | AF8: ='Lpg (2)'!B12*2000/85 -> 352.94118 | AG8: ='Lpg (2)'!C12*1000/85 -> 1000 | AH8: ='Lpg (2)'!D12*1000/85 -> 776.47059 | AI8: =SUM(AF7*2000)+(AG8*1000)+(AH8*1000) -> 2529411.8 | AJ8: =SUM(AI7-AI8) -> 0
A9: =Gen!B14 -> 43925 | B9: ='Summery Report'!E8 -> 0 | C9: =Gen!C14 -> 0 | D9: ='Summery Report'!E8 -> 0 | E9: =SUM(E8) -> 1.3262195 | F9: =SUM(J9*E9)/D9 -> #DIV/0! | G9: =SUM(L9*E9)/D9 -> #DIV/0! | H9: =Gen!D14 -> 38421.96 | I9: =Gen!F14 -> 0 | J9: =Gen!T14 -> 789.55 | K9: =Gen!AK14 -> 660.37 | L9: =SUM(J9:K9) -> 1449.92 | M9: ='Water-Meter'!K49 -> 518.72347 | N9: ='Water-Meter'!E9 -> 34 | P9: 19029 | Q9: =SUM(P9-P8) -> 0 | R9: =SUM(Q9*O9) -> 0 | T9: 16086 | U9: =T9-T8 -> 0 | V9: =SUM(U9*S9) -> 0 | W9: 2.6 | X9: 24307 | Y9: =X9-X8 -> 24 | Z9: =SUM(Y9*W9) -> 62.4 | AA9: =SUM(Z9*X11) -> 1519315.2 | AB9: 30413 | AC9: =AB9-AB8 -> 57 | AD9: 199541 | AE9: =AD9-AD8 -> 0 | AF9: ='Lpg (2)'!B13*2000/85 -> 329.41176 | AG9: ='Lpg (2)'!C13*1000/85 -> 1000 | AH9: ='Lpg (2)'!D13*1000/85 -> 776.47059 | AI9: =SUM(AF8*2000)+(AG9*1000)+(AH9*1000) -> 2482352.9 | AJ9: =SUM(AI8-AI9) -> 47058.824
A10: =Gen!B15 -> 43926 | B10: ='Summery Report'!E9 -> 0 | C10: =Gen!C15 -> 0 | D10: ='Summery Report'!E9 -> 0 | E10: =SUM(E9) -> 1.3262195 | F10: =SUM(J10*E10)/D10 -> #DIV/0! | G10: =SUM(L10*E10)/D10 -> #DIV/0! | H10: =Gen!D15 -> 36972.04 | I10: =Gen!F15 -> 0 | J10: =Gen!T15 -> 813.34 | K10: =Gen!AK15 -> 34.28 | L10: =SUM(J10:K10) -> 847.62 | M10: ='Water-Meter'!K50 -> 497.30897 | N10: ='Water-Meter'!E10 -> 42 | P10: 19029 | Q10: =SUM(P10-P9) -> 0 | R10: =SUM(Q10*O10) -> 0 | T10: 16086 | U10: =T10-T9 -> 0 | V10: =SUM(U10*S10) -> 0 | W10: 2.6 | X10: 24331 | Y10: =X10-X9 -> 24 | Z10: =SUM(Y10*W10) -> 62.4 | AA10: =SUM(Z10*X12) -> 1520812.8 | AB10: 30470 | AC10: =AB10-AB9 -> 57 | AD10: 199589 | AE10: =AD10-AD9 -> 48 | AF10: ='Lpg (2)'!B14*2000/85 -> 305.88235 | AG10: ='Lpg (2)'!C14*1000/85 -> 1000 | AH10: ='Lpg (2)'!D14*1000/85 -> 776.47059 | AI10: =SUM(AF9*2000)+(AG10*1000)+(AH10*1000) -> 2435294.1 | AJ10: =SUM(AI9-AI10) -> 47058.824
A11: =Gen!B16 -> 43927 | B11: ='Summery Report'!E10 -> 0 | C11: =Gen!C16 -> 0 | D11: ='Summery Report'!E10 -> 0 | E11: =SUM(E10) -> 1.3262195 | F11: =SUM(J11*E11)/D11 -> #DIV/0! | G11: =SUM(L11*E11)/D11 -> #DIV/0! | H11: =Gen!D16 -> 36124.42 | I11: =Gen!F16 -> 15000 | J11: =Gen!T16 -> 757.53 | K11: =Gen!AK16 -> 0 | L11: =SUM(J11:K11) -> 757.53 | M11: ='Water-Meter'!K51 -> 469.85871 | N11: ='Water-Meter'!E11 -> 41 | P11: 19029 | Q11: =SUM(P11-P10) -> 0 | R11: =SUM(Q11*O11) -> 0 | T11: 16086 | U11: =T11-T10 -> 0 | V11: =SUM(U11*S11) -> 0 | W11: 2.7 | X11: 24348 | Y11: =X11-X10 -> 17 | Z11: =SUM(Y11*W11) -> 45.9 | AA11: =SUM(Z11*X13) -> 1119730.5 | AB11: 30508 | AC11: =AB11-AB10 -> 38 | AD11: 199607 | AE11: =AD11-AD10 -> 18 | AF11: ='Lpg (2)'!B15*2000/85 -> 305.88235 | AG11: ='Lpg (2)'!C15*1000/85 -> 1000 | AH11: ='Lpg (2)'!D15*1000/85 -> 776.47059 | AI11: =SUM(AF10*2000)+(AG11*1000)+(AH11*1000) -> 2388235.3 | AJ11: =SUM(AI10-AI11) -> 47058.824
A12: =Gen!B17 -> 43928 | B12: ='Summery Report'!E11 -> 0 | C12: =Gen!C17 -> 0 | D12: ='Summery Report'!E11 -> 0 | E12: =SUM(E11) -> 1.3262195 | F12: =SUM(J12*E12)/D12 -> #DIV/0! | G12: =SUM(L12*E12)/D12 -> #DIV/0! | H12: =Gen!D17 -> 50366.89 | I12: =Gen!F17 -> 0 | J12: =Gen!T17 -> 783.55 | K12: =Gen!AK17 -> 108.2 | L12: =SUM(J12:K12) -> 891.75 | M12: ='Water-Meter'!K52 -> 471.68466 | N12: ='Water-Meter'!E12 -> 47 | P12: 19029 | Q12: =SUM(P12-P11) -> 0 | R12: =SUM(Q12*O12) -> 0 | T12: 16086 | U12: =T12-T11 -> 0 | V12: =SUM(U12*S12) -> 0 | W12: 2.2 | X12: 24372 | Y12: =X12-X11 -> 24 | Z12: =SUM(Y12*W12) -> 52.8 | AA12: =SUM(Z12*X14) -> 1288267.2 | AB12: 30561 | AC12: =AB12-AB11 -> 53 | AD12: 199639 | AE12: =AD12-AD11 -> 32 | AF12: ='Lpg (2)'!B16*2000/85 -> 305.88235 | AG12: ='Lpg (2)'!C16*1000/85 -> 1000 | AH12: ='Lpg (2)'!D16*1000/85 -> 776.47059 | AI12: =SUM(AF11*2000)+(AG12*1000)+(AH12*1000) -> 2388235.3 | AJ12: =SUM(AI11-AI12) -> 0
A13: =Gen!B18 -> 43929 | B13: ='Summery Report'!E12 -> 0 | C13: =Gen!C18 -> 0 | D13: ='Summery Report'!E12 -> 0 | E13: =SUM(E12) -> 1.3262195 | F13: =SUM(J13*E13)/D13 -> #DIV/0! | G13: =SUM(L13*E13)/D13 -> #DIV/0! | H13: =Gen!D18 -> 49475.14 | I13: =Gen!F18 -> 0 | J13: =Gen!T18 -> 831.27 | K13: =Gen!AK18 -> 0 | L13: =SUM(J13:K13) -> 831.27 | M13: ='Water-Meter'!K53 -> 483.60145 | N13: ='Water-Meter'!E13 -> 36 | O13: 2.4 | P13: 19030 | Q13: =SUM(P13-P12) -> 1 | R13: =SUM(Q13*O13) -> 2.4 | T13: 16086 | U13: =T13-T12 -> 0 | V13: =SUM(U13*S13) -> 0 | W13: 2.3 | X13: 24395 | Y13: =X13-X12 -> 23 | Z13: =SUM(Y13*W13) -> 52.9 | AA13: =SUM(Z13*X15) -> 1291818 | AB13: 30611 | AC13: =AB13-AB12 -> 50 | AD13: 199667 | AE13: =AD13-AD12 -> 28 | AF13: ='Lpg (2)'!B17*2000/85 -> 305.88235 | AG13: ='Lpg (2)'!C17*1000/85 -> 1000 | AH13: ='Lpg (2)'!D17*1000/85 -> 776.47059 | AI13: =SUM(AF12*2000)+(AG13*1000)+(AH13*1000) -> 2388235.3 | AJ13: =SUM(AI12-AI13) -> 0
A14: =Gen!B19 -> 43930 | B14: ='Summery Report'!E13 -> 0 | C14: =Gen!C19 -> 0 | D14: ='Summery Report'!E13 -> 0 | E14: =SUM(E13) -> 1.3262195 | F14: =SUM(J14*E14)/D14 -> #DIV/0! | G14: =SUM(L14*E14)/D14 -> #DIV/0! | H14: =Gen!D19 -> 48643.87 | I14: =Gen!F19 -> 0 | J14: =Gen!T19 -> 806.32 | K14: =Gen!AK19 -> 0 | L14: =SUM(J14:K14) -> 806.32 | M14: ='Water-Meter'!K54 -> 541.48315 | N14: ='Water-Meter'!E14 -> 33 | P14: 19030 | Q14: =SUM(P14-P13) -> 0 | R14: =SUM(Q14*O14) -> 0 | T14: 16086 | U14: =T14-T13 -> 0 | V14: =SUM(U14*S14) -> 0 | W14: 2.3 | X14: 24399 | Y14: =X14-X13 -> 4 | Z14: =SUM(Y14*W14) -> 9.2 | AA14: =SUM(Z14*X16) -> 224664 | AB14: 30618 | AC14: =AB14-AB13 -> 7 | AD14: 199693 | AE14: =AD14-AD13 -> 26 | AF14: ='Lpg (2)'!B18*2000/85 -> 305.88235 | AG14: ='Lpg (2)'!C18*1000/85 -> 1000 | AH14: ='Lpg (2)'!D18*1000/85 -> 776.47059 | AI14: =SUM(AF13*2000)+(AG14*1000)+(AH14*1000) -> 2388235.3 | AJ14: =SUM(AI13-AI14) -> 0
A15: =Gen!B20 -> 43931 | B15: ='Summery Report'!E14 -> 0 | C15: =Gen!C20 -> 0 | D15: ='Summery Report'!E14 -> 0 | E15: =SUM(E14) -> 1.3262195 | F15: =SUM(J15*E15)/D15 -> #DIV/0! | G15: =SUM(L15*E15)/D15 -> #DIV/0! | H15: =Gen!D20 -> 47837.55 | I15: =Gen!F20 -> 0 | J15: =Gen!T20 -> 823.75 | K15: =Gen!AK20 -> 0 | L15: =SUM(J15:K15) -> 823.75 | M15: ='Water-Meter'!K55 -> 600.59466 | N15: ='Water-Meter'!E15 -> 55 | P15: 19030 | Q15: =SUM(P15-P14) -> 0 | R15: =SUM(Q15*O15) -> 0 | T15: 16086 | U15: =T15-T14 -> 0 | V15: =SUM(U15*S15) -> 0 | W15: 2.3 | X15: 24420 | Y15: =X15-X14 -> 21 | Z15: =SUM(Y15*W15) -> 48.3 | AA15: =SUM(Z15*X17) -> 1179727.5 | AB15: 30662 | AC15: =AB15-AB14 -> 44 | AD15: 199719 | AE15: =AD15-AD14 -> 26 | AF15: ='Lpg (2)'!B19*2000/85 -> 282.35294 | AG15: ='Lpg (2)'!C19*1000/85 -> 1000 | AH15: ='Lpg (2)'!D19*1000/85 -> 776.47059 | AI15: =SUM(AF15*2000)+(AG15*1000)+(AH15*1000) -> 2341176.5 | AJ15: =SUM(AI14-AI15) -> 47058.824
A16: =Gen!B21 -> 43932 | B16: ='Summery Report'!E15 -> 0 | C16: =Gen!C21 -> 0 | D16: ='Summery Report'!E15 -> 0 | E16: =SUM(E15) -> 1.3262195 | F16: =SUM(J16*E16)/D16 -> #DIV/0! | G16: =SUM(L16*E16)/D16 -> #DIV/0! | H16: =Gen!D21 -> 47013.8 | I16: =Gen!F21 -> 0 | J16: =Gen!T21 -> 782.67 | K16: =Gen!AK21 -> 0 | L16: =SUM(J16:K16) -> 782.67 | M16: ='Water-Meter'!K56 -> 588.54041 | N16: ='Water-Meter'!E16 -> 56 | P16: 19030 | Q16: =SUM(P16-P15) -> 0 | R16: =SUM(Q16*O16) -> 0 | S16: 8.1 | T16: 16095 | U16: =T16-T15 -> 9 | V16: =SUM(U16*S16) -> 72.9 | X16: 24420 | Y16: =X16-X15 -> 0 | Z16: =SUM(Y16*W16) -> 0 | AA16: =SUM(Z16*X18) -> 0 | AB16: 30737 | AC16: =AB16-AB15 -> 75 | AD16: 199747 | AE16: =AD16-AD15 -> 28 | AF16: ='Lpg (2)'!B20*2000/85 -> 282.35294 | AG16: ='Lpg (2)'!C20*1000/85 -> 1000 | AH16: ='Lpg (2)'!D20*1000/85 -> 776.47059 | AI16: =SUM(AF16*2000)+(AG16*1000)+(AH16*1000) -> 2341176.5 | AJ16: =SUM(AI15-AI16) -> 0
A17: =Gen!B22 -> 43933 | B17: ='Summery Report'!E16 -> 0 | C17: =Gen!C22 -> 0 | D17: ='Summery Report'!E16 -> 0 | E17: =SUM(E16) -> 1.3262195 | F17: =SUM(J17*E17)/D17 -> #DIV/0! | G17: =SUM(L17*E17)/D17 -> #DIV/0! | H17: =Gen!D22 -> 46231.13 | I17: =Gen!F22 -> 0 | J17: =Gen!T22 -> 776.8 | K17: =Gen!AK22 -> 0 | L17: =SUM(J17:K17) -> 776.8 | M17: ='Water-Meter'!K57 -> 557.22322 | N17: ='Water-Meter'!E17 -> 41 | P17: 19030 | Q17: =SUM(P18-P16) -> 0 | R17: =SUM(Q17*O17) -> 0 | S17: 8.2 | T17: 16101 | U17: =T17-T16 -> 6 | V17: =SUM(U17*S17) -> 49.2 | X17: 24425 | Y17: =X17-X16 -> 5 | Z17: =SUM(Y17*W17) -> 0 | AA17: =SUM(Z17*X19) -> 0 | AB17: 30786 | AC17: =AB17-AB16 -> 49 | AD17: 199771 | AE17: =AD17-AD16 -> 24 | AF17: ='Lpg (2)'!B21*2000/85 -> 188.23529 | AG17: ='Lpg (2)'!C21*1000/85 -> 1000 | AH17: ='Lpg (2)'!D21*1000/85 -> 776.47059 | AI17: =SUM(AF17*2000)+(AG17*1000)+(AH17*1000) -> 2152941.2 | AJ17: =SUM(AI16-AI17) -> 188235.29
A18: =Gen!B23 -> 43934 | B18: ='Summery Report'!E17 -> 0 | C18: =Gen!C23 -> 0 | D18: ='Summery Report'!E17 -> 0 | E18: =SUM(E17) -> 1.3262195 | F18: =SUM(J18*E18)/D18 -> #DIV/0! | G18: =SUM(L18*E18)/D18 -> #DIV/0! | H18: =Gen!D23 -> 45454.33 | I18: =Gen!F23 -> 0 | J18: =Gen!T23 -> 771.72 | K18: =Gen!AK23 -> 19.86 | L18: =SUM(J18:K18) -> 791.58 | M18: ='Water-Meter'!K58 -> 543.27387 | N18: ='Water-Meter'!E18 -> 45 | P18: 19030 | R18: =SUM(Q18*O18) -> 0 | S18: 7.9 | T18: 16107 | U18: =T18-T17 -> 6 | V18: =SUM(U18*S18) -> 47.4 | X18: 24425 | Y18: =X18-X17 -> 0 | Z18: =SUM(Y18*W18) -> 0 | AA18: =SUM(Z18*X20) -> 0 | AB18: 30836 | AC18: =AB18-AB17 -> 50 | AD18: 199802 | AE18: =AD18-AD17 -> 31 | AF18: ='Lpg (2)'!B22*2000/85 -> 188.23529 | AG18: ='Lpg (2)'!C22*1000/85 -> 1000 | AH18: ='Lpg (2)'!D22*1000/85 -> 776.47059 | AI18: =SUM(AF18*2000)+(AG18*1000)+(AH18*1000) -> 2152941.2 | AJ18: =SUM(AI17-AI18) -> 0
A19: =Gen!B24 -> 43935 | B19: ='Summery Report'!E18 -> 0 | C19: =Gen!C24 -> 0 | D19: ='Summery Report'!E18 -> 0 | E19: =SUM(E18) -> 1.3262195 | F19: =SUM(J19*E19)/D19 -> #DIV/0! | G19: =SUM(L19*E19)/D19 -> #DIV/0! | H19: =Gen!D24 -> 44662.75 | I19: =Gen!F24 -> 0 | J19: =Gen!T24 -> 760.62 | K19: =Gen!AK24 -> 0 | L19: =SUM(J19:K19) -> 760.62 | M19: ='Water-Meter'!K59 -> 543.43274 | N19: ='Water-Meter'!E19 -> 51 | P19: 19030 | R19: =SUM(Q19*O19) -> 0 | S19: 8.2 | T19: 16112 | U19: =T19-T18 -> 5 | V19: =SUM(U19*S19) -> 41 | X19: 24425 | Y19: =X19-X18 -> 0 | Z19: =SUM(Y19*W19) -> 0 | AA19: =SUM(Z19*X21) -> 0 | AB19: 30871 | AC19: =AB19-AB18 -> 35 | AD19: 199828 | AE19: =AD19-AD18 -> 26 | AF19: ='Lpg (2)'!B23*2000/85 -> 141.17647 | AG19: ='Lpg (2)'!C23*1000/85 -> 1000 | AH19: ='Lpg (2)'!D23*1000/85 -> 776.47059 | AI19: =SUM(AF19*2000)+(AG19*1000)+(AH19*1000) -> 2058823.5 | AJ19: =SUM(AI18-AI19) -> 94117.647
A20: =Gen!B25 -> 43936 | B20: ='Summery Report'!E19 -> 0 | C20: =Gen!C25 -> 0 | D20: ='Summery Report'!E19 -> 0 | E20: =SUM(E19) -> 1.3262195 | F20: =SUM(J20*E20)/D20 -> #DIV/0! | G20: =SUM(L20*E20)/D20 -> #DIV/0! | H20: =Gen!D25 -> 43902.13 | I20: =Gen!F25 -> 0 | J20: =Gen!T25 -> 786.19 | K20: =Gen!AK25 -> 0 | L20: =SUM(J20:K20) -> 786.19 | M20: ='Water-Meter'!K60 -> 536.76736 | N20: ='Water-Meter'!E20 -> 54 | P20: 19030 | Q20: =SUM(P20-P19) -> 0 | R20: =SUM(Q20*O20) -> 0 | S20: 8.4 | T20: 16118 | U20: =T20-T19 -> 6 | V20: =SUM(U20*S20) -> 50.4 | X20: 24425 | Y20: =X20-X19 -> 0 | Z20: =SUM(Y20*W20) -> 0 | AA20: =SUM(Z20*X22) -> 0 | AB20: 30928 | AC20: =AB20-AB19 -> 57 | AD20: 199872 | AE20: =AD20-AD19 -> 44 | AF20: ='Lpg (2)'!B24*2000/85 -> 117.64706 | AG20: ='Lpg (2)'!C24*1000/85 -> 1000 | AH20: ='Lpg (2)'!D24*1000/85 -> 776.47059 | AI20: =SUM(AF20*2000)+(AG20*1000)+(AH20*1000) -> 2011764.7 | AJ20: =SUM(AI19-AI20) -> 47058.824
A21: =Gen!B26 -> 43937 | B21: ='Summery Report'!E20 -> 0 | C21: =Gen!C26 -> 0 | D21: ='Summery Report'!E20 -> 0 | E21: =SUM(E20) -> 1.3262195 | F21: =SUM(J21*E21)/D21 -> #DIV/0! | G21: =SUM(L21*E21)/D21 -> #DIV/0! | H21: =Gen!D26 -> 43115.94 | I21: =Gen!F26 -> 0 | J21: =Gen!T26 -> 754.27 | K21: =Gen!AK26 -> 0 | L21: =SUM(J21:K21) -> 754.27 | M21: ='Water-Meter'!K61 -> 513.8488 | N21: ='Water-Meter'!E21 -> 54 | P21: 19030 | Q21: =SUM(P21-P20) -> 0 | R21: =SUM(Q21*O21) -> 0 | S21: 8.2 | T21: 16124 | U21: =T21-T20 -> 6 | V21: =SUM(U21*S21) -> 49.2 | X21: 24425 | Y21: =X21-X20 -> 0 | Z21: =SUM(Y21*W21) -> 0 | AA21: =SUM(Z21*X23) -> 0 | AB21: 30972 | AC21: =AB21-AB20 -> 44 | AD21: 199900 | AE21: =AD21-AD20 -> 28 | AF21: ='Lpg (2)'!B25*2000/85 -> 117.64706 | AG21: ='Lpg (2)'!C25*1000/85 -> 1000 | AH21: ='Lpg (2)'!D25*1000/85 -> 776.47059 | AI21: =SUM(AF21*2000)+(AG21*1000)+(AH21*1000) -> 2011764.7 | AJ21: =SUM(AI20-AI21) -> 0
A22: =Gen!B27 -> 43938 | B22: ='Summery Report'!E21 -> 0 | C22: =Gen!C27 -> 0 | D22: ='Summery Report'!E21 -> 0 | E22: =SUM(E21) -> 1.3262195 | F22: =SUM(J22*E22)/D22 -> #DIV/0! | G22: =SUM(L22*E22)/D22 -> #DIV/0! | H22: =Gen!D27 -> 42361.67 | I22: =Gen!F27 -> 0 | J22: =Gen!T27 -> 781.93 | K22: =Gen!AK27 -> 18.45 | L22: =SUM(J22:K22) -> 800.38 | M22: ='Water-Meter'!K62 -> 494.06905 | N22: ='Water-Meter'!E22 -> 42 | P22: 19030 | Q22: =SUM(P22-P21) -> 0 | R22: =SUM(Q22*O22) -> 0 | S22: 8.1 | T22: 16133 | U22: =T22-T21 -> 9 | V22: =SUM(U22*S22) -> 72.9 | X22: 24425 | Y22: =X22-X21 -> 0 | Z22: =SUM(Y22*W22) -> 0 | AA22: =SUM(Z22*X24) -> 0 | AB22: 31040 | AC22: =AB22-AB21 -> 68 | AD22: 199939 | AE22: =AD22-AD21 -> 39 | AF22: ='Lpg (2)'!B26*2000/85 -> 117.64706 | AG22: ='Lpg (2)'!C26*1000/85 -> 1000 | AH22: ='Lpg (2)'!D26*1000/85 -> 776.47059 | AI22: =SUM(AF22*2000)+(AG22*1000)+(AH22*1000) -> 2011764.7 | AJ22: =SUM(AI21-AI22) -> 0
A23: =Gen!B28 -> 43939 | B23: ='Summery Report'!E22 -> 0 | C23: =Gen!C28 -> 0 | D23: ='Summery Report'!E22 -> 0 | E23: =SUM(E22) -> 1.3262195 | F23: =SUM(J23*E23)/D23 -> #DIV/0! | G23: =SUM(L23*E23)/D23 -> #DIV/0! | H23: =Gen!D28 -> 41561.29 | I23: =Gen!F28 -> 0 | J23: =Gen!T28 -> 744.22 | K23: =Gen!AK28 -> 0 | L23: =SUM(J23:K23) -> 744.22 | M23: ='Water-Meter'!K63 -> 481.0404 | N23: ='Water-Meter'!E23 -> 30 | P23: 19030 | Q23: =SUM(P23-P22) -> 0 | R23: =SUM(Q23*O23) -> 0 | S23: 8.3 | T23: 16139 | U23: =T23-T22 -> 6 | V23: =SUM(U23*S23) -> 49.8 | X23: 24425 | Y23: =X23-X22 -> 0 | Z23: =SUM(Y23*W23) -> 0 | AA23: =SUM(Z23*X25) -> 0 | AB23: 31087 | AC23: =AB23-AB22 -> 47 | AD23: 200001 | AE23: =AD23-AD22 -> 62 | AF23: ='Lpg (2)'!B27*2000/85 -> 94.117647 | AG23: ='Lpg (2)'!C27*1000/85 -> 1000 | AH23: ='Lpg (2)'!D27*1000/85 -> 776.47059 | AI23: =SUM(AF23*2000)+(AG23*1000)+(AH23*1000) -> 1964705.9 | AJ23: =SUM(AI22-AI23) -> 47058.824
A24: =Gen!B29 -> 43940 | B24: ='Summery Report'!E23 -> 0 | C24: =Gen!C29 -> 0 | D24: ='Summery Report'!E23 -> 0 | E24: =SUM(E23) -> 1.3262195 | F24: =SUM(J24*E24)/D24 -> #DIV/0! | G24: =SUM(L24*E24)/D24 -> #DIV/0! | H24: =Gen!D29 -> 40817.07 | I24: =Gen!F29 -> 0 | J24: =Gen!T29 -> 740.05 | K24: =Gen!AK29 -> 52.04 | L24: =SUM(J24:K24) -> 792.09 | M24: ='Water-Meter'!K64 -> 493.97483 | N24: ='Water-Meter'!E24 -> 51 | P24: 19030 | Q24: =SUM(P24-P23) -> 0 | R24: =SUM(Q24*O24) -> 0 | T24: 16139 | U24: =T24-T23 -> 0 | V24: =SUM(U24*S24) -> 0 | X24: 24425 | Y24: =X24-X23 -> 0 | Z24: =SUM(Y24*W24) -> 0 | AA24: =SUM(Z24*X26) -> 0 | AB24: 31087 | AC24: =AB24-AB23 -> 0 | AD24: 200070 | AE24: =AD24-AD23 -> 69 | AF24: ='Lpg (2)'!B28*2000/85 -> 47.058824 | AG24: ='Lpg (2)'!C28*1000/85 -> 1000 | AH24: ='Lpg (2)'!D28*1000/85 -> 776.47059 | AI24: =SUM(AF24*2000)+(AG24*1000)+(AH24*1000) -> 1870588.2 | AJ24: =SUM(AI23-AI24) -> 94117.647
A25: =Gen!B30 -> 43941 | B25: ='Summery Report'!E24 -> 0 | C25: =Gen!C30 -> 0 | D25: ='Summery Report'!E24 -> 0 | E25: =SUM(E24) -> 1.3262195 | F25: =SUM(J25*E25)/D25 -> #DIV/0! | G25: =SUM(L25*E25)/D25 -> #DIV/0! | H25: =Gen!D30 -> 40024.98 | I25: =Gen!F30 -> 0 | J25: =Gen!T30 -> 731.47 | K25: =Gen!AK30 -> 0 | L25: =SUM(J25:K25) -> 731.47 | M25: ='Water-Meter'!K65 -> 506.27127 | N25: ='Water-Meter'!E25 -> 35 | P25: 19030 | Q25: =SUM(P25-P24) -> 0 | R25: =SUM(Q25*O25) -> 0 | T25: 16139 | U25: =T25-T24 -> 0 | V25: =SUM(U25*S25) -> 0 | W25: 2.2 | X25: 24445 | Y25: =X25-X24 -> 20 | Z25: =SUM(Y25*W25) -> 44 | AA25: =SUM(Z25*X27) -> 1076944 | AB25: 31133 | AC25: =AB25-AB24 -> 46 | AD25: 200121 | AE25: =AD25-AD24 -> 51 | AF25: ='Lpg (2)'!B29*2000/85 -> 47.058824 | AG25: ='Lpg (2)'!C29*1000/85 -> 1000 | AH25: ='Lpg (2)'!D29*1000/85 -> 776.47059 | AI25: =SUM(AF25*2000)+(AG25*1000)+(AH25*1000) -> 1870588.2 | AJ25: =SUM(AI24-AI25) -> 0
A26: =Gen!B31 -> 43942 | B26: ='Summery Report'!E25 -> 0 | C26: =Gen!C31 -> 0 | D26: ='Summery Report'!E25 -> 0 | E26: =SUM(E25) -> 1.3262195 | F26: =SUM(J26*E26)/D26 -> #DIV/0! | G26: =SUM(L26*E26)/D26 -> #DIV/0! | H26: =Gen!D31 -> 39293.51 | I26: =Gen!F31 -> 0 | J26: =Gen!T31 -> 747.27 | K26: =Gen!AK31 -> 180 | L26: =SUM(J26:K26) -> 927.27 | M26: ='Water-Meter'!K66 -> 484.18481 | N26: ='Water-Meter'!E26 -> 27 | P26: 19030 | Q26: =SUM(P26-P25) -> 0 | R26: =SUM(Q26*O26) -> 0 | T26: 16139 | U26: =T26-T25 -> 0 | V26: =SUM(U26*S26) -> 0 | W26: 2.3 | X26: 24469 | Y26: =X26-X25 -> 24 | Z26: =SUM(Y26*W26) -> 55.2 | AA26: =SUM(Z26*X28) -> 1351075.2 | AB26: 31182 | AC26: =AB26-AB25 -> 49 | AD26: 200162 | AE26: =AD26-AD25 -> 41 | AF26: ='Lpg (2)'!B30*2000/85 -> 47.058824 | AG26: ='Lpg (2)'!C30*1000/85 -> 1000 | AH26: ='Lpg (2)'!D30*1000/85 -> 776.47059 | AI26: =SUM(AF26*2000)+(AG26*1000)+(AH26*1000) -> 1870588.2 | AJ26: =SUM(AI25-AI26) -> 0
A27: =Gen!B32 -> 43943 | B27: ='Summery Report'!E26 -> 0 | C27: =Gen!C32 -> 0 | D27: ='Summery Report'!E26 -> 0 | E27: =SUM(E26) -> 1.3262195 | F27: =SUM(J27*E27)/D27 -> #DIV/0! | G27: =SUM(L27*E27)/D27 -> #DIV/0! | H27: =Gen!D32 -> 38366.24 | I27: =Gen!F32 -> 0 | J27: =Gen!T32 -> 709.13 | K27: =Gen!AK32 -> 123.51 | L27: =SUM(J27:K27) -> 832.64 | M27: ='Water-Meter'!K67 -> 460.25989 | N27: ='Water-Meter'!E27 -> 28 | P27: 19030 | Q27: =SUM(P27-P26) -> 0 | R27: =SUM(Q27*O27) -> 0 | S27: 8.2 | T27: 16145 | U27: =T27-T26 -> 6 | V27: =SUM(U27*S27) -> 49.2 | W27: 2.3 | X27: 24476 | Y27: =X27-X26 -> 7 | Z27: =SUM(Y27*W27) -> 16.1 | AA27: =SUM(Z27*X29) -> 394063.6 | AB27: 31247 | AC27: =AB27-AB26 -> 65 | AD27: 200203 | AE27: =AD27-AD26 -> 41 | AF27: ='Lpg (2)'!B31*2000/85 -> 2000 | AG27: ='Lpg (2)'!C31*1000/85 -> 1000 | AH27: ='Lpg (2)'!D31*1000/85 -> 752.94118 | AI27: =SUM(AF27*2000)+(AG27*1000)+(AH27*1000) -> 5752941.2 | AJ27: =SUM(AI26-AI27) -> -3882352.9
