Workbook

Sheet Total
A1: Site Name | B1: Day | C1: Month | D1: Year | E1: Total Electricity Kwh | F1: Electricity Tariff ($/Kwh) | G1: Total Fuel Oil (Liters) | H1: Fuel Oil $/Liter | I1: LPG (Kg) | J1: LPG $/Kg | K1: Water Utility Supply (m3) m3 | L1: Water Utility Supply (m3) $/m3 | M1: Irrigation Water (m3) m3 | N1: Irrigation water $/m3 | O1: Room Nights
A2: Beirut | B2: 1 | C2: 4 | D2: 2020 | E2: =ELEC!N3 -> 7662.2 | F2: =SUM('EDl log'!T4) -> 0.10830399 | G2: =-tanks!AW6 -> 267 | H2: =SUM(tanks!AV6) -> 0.3845 | I2: =('B5'!AU5)*0.51 -> 30.6 | J2: ='B5'!AX5/0.51 -> 1.372549 | K2: =WATER!I6 -> 107 | L2: =SUM(WATER!J6) -> 2.3364486 | M2: =WATER!Q6 -> 0 | N2: 0.6 | O2: =ELEC!B3 -> 4.002
A3: Beirut | B3: =B2+1 -> 2 | C3: 4 | D3: 2020 | E3: =ELEC!N4 -> 7437.6 | F3: =SUM('EDl log'!T5) -> 0.093088556 | G3: =-tanks!AW7 -> 307 | H3: =SUM(tanks!AV7) -> 0.3845 | I3: =('B5'!AU6)*0.51 -> 91.8 | J3: ='B5'!AX6/0.51 -> 1.372549 | K3: =WATER!I7 -> 0 | L3: =SUM(WATER!J7) -> 0 | M3: =WATER!Q7 -> 0 | N3: 0.6 | O3: =ELEC!B4 -> 2.001
A4: Beirut | B4: =B3+1 -> 3 | C4: 4 | D4: 2020 | E4: =ELEC!N5 -> 8665.2 | F4: =SUM('EDl log'!T6) -> 0.069733051 | G4: =-tanks!AW8 -> 351 | H4: =SUM(tanks!AV8) -> 0.3845 | I4: =('B5'!AU7)*0.51 -> 30.6 | J4: ='B5'!AX7/0.51 -> 1.372549 | K4: =WATER!I8 -> 300 | L4: =SUM(WATER!J8) -> 0.83333333 | M4: =WATER!Q8 -> 0 | N4: 0.6 | O4: =ELEC!B5 -> 2.001
A5: Beirut | B5: =B4+1 -> 4 | C5: 4 | D5: 2020 | E5: =ELEC!N6 -> 7670.4 | F5: =SUM('EDl log'!T7) -> 0.071592309 | G5: =-tanks!AW9 -> 271 | H5: =SUM(tanks!AV9) -> 0.3845 | I5: =('B5'!AU8)*0.51 -> 61.2 | J5: ='B5'!AX8/0.51 -> 1.372549 | K5: =WATER!I9 -> 0 | L5: =SUM(WATER!J9) -> 0 | M5: =WATER!Q9 -> 0 | N5: 0.6 | O5: =ELEC!B6 -> 2.99
A6: Beirut | B6: =B5+1 -> 5 | C6: 4 | D6: 2020 | E6: =ELEC!N7 -> 8538.8 | F6: =SUM('EDl log'!T8) -> 0.086834101 | G6: =-tanks!AW10 -> 252 | H6: =SUM(tanks!AV10) -> 0.3845 | I6: =('B5'!AU9)*0.51 -> 15.3 | J6: ='B5'!AX9/0.51 -> 1.372549 | K6: =WATER!I10 -> 166 | L6: =SUM(WATER!J10) -> 1.5060241 | M6: =WATER!Q10 -> 0 | N6: 0.6 | O6: =ELEC!B7 -> 6.992
A7: Beirut | B7: =B6+1 -> 6 | C7: 4 | D7: 2020 | E7: =ELEC!N8 -> 10057.8 | F7: =SUM('EDl log'!T9) -> 0.057249517 | G7: =-tanks!AW11 -> 444 | H7: =SUM(tanks!AV11) -> 0.3845 | I7: =('B5'!AU10)*0.51 -> 30.6 | J7: ='B5'!AX10/0.51 -> 1.372549 | K7: =WATER!I11 -> 19 | L7: =SUM(WATER!J11) -> 13.157895 | M7: =WATER!Q11 -> 0 | N7: 0.6 | O7: =ELEC!B8 -> 2.001
A8: Beirut | B8: =B7+1 -> 7 | C8: 4 | D8: 2020 | E8: =ELEC!N9 -> 7909.4 | F8: =SUM('EDl log'!T10) -> 0.063332284 | G8: =-tanks!AW12 -> 164 | H8: =SUM(tanks!AV12) -> 0.3845 | I8: =('B5'!AU11)*0.51 -> 15.3 | J8: ='B5'!AX11/0.51 -> 1.372549 | K8: =WATER!I12 -> 0 | L8: =SUM(WATER!J12) -> 0 | M8: =WATER!Q12 -> 0 | N8: 0.6 | O8: =ELEC!B9 -> 2.001
A9: Beirut | B9: =B8+1 -> 8 | C9: 4 | D9: 2020 | E9: =ELEC!N10 -> 10815.6 | F9: =SUM('EDl log'!T11) -> 0.068925058 | G9: =-tanks!AW13 -> 305 | H9: =SUM(tanks!AV13) -> 0.3845 | I9: =('B5'!AU12)*0.51 -> 61.2 | J9: ='B5'!AX12/0.51 -> 1.372549 | K9: =WATER!I13 -> 29 | L9: =SUM(WATER!J13) -> 8.6206897 | M9: =WATER!Q13 -> 0 | N9: 0.6 | O9: =ELEC!B10 -> 10.994
A10: Beirut | B10: =B9+1 -> 9 | C10: 4 | D10: 2020 | E10: =ELEC!N11 -> 9103 | F10: =SUM('EDl log'!T12) -> 0.073464034 | G10: =-tanks!AW14 -> 615.7 | H10: =SUM(tanks!AV14) -> 0.3845 | I10: =('B5'!AU13)*0.51 -> 158.1 | J10: ='B5'!AX13/0.51 -> 1.372549 | K10: =WATER!I14 -> 287 | L10: =SUM(WATER!J14) -> 0.87108014 | M10: =WATER!Q14 -> 0 | N10: 0.6 | O10: =ELEC!B11 -> 4.991
A11: Beirut | B11: =B10+1 -> 10 | C11: 4 | D11: 2020 | E11: =ELEC!N12 -> 8022.6 | F11: =SUM('EDl log'!T13) -> 0.082986374 | G11: =-tanks!AW15 -> 426 | H11: =SUM(tanks!AV15) -> 0.3845 | I11: =('B5'!AU14)*0.51 -> 45.9 | J11: ='B5'!AX14/0.51 -> 1.372549 | K11: =WATER!I15 -> 0 | L11: =SUM(WATER!J15) -> 0 | M11: =WATER!Q15 -> 0 | N11: 0.6 | O11: =ELEC!B12 -> 2.001
A12: Beirut | B12: =B11+1 -> 11 | C12: 4 | D12: 2020 | E12: =ELEC!N13 -> 8603.4 | F12: =SUM('EDl log'!T14) -> 0.067763691 | G12: =-tanks!AW16 -> 194 | H12: =SUM(tanks!AV16) -> 0.3845 | I12: =('B5'!AU15)*0.51 -> 30.6 | J12: ='B5'!AX15/0.51 -> 1.372549 | K12: =WATER!I16 -> 0 | L12: =SUM(WATER!J16) -> 0 | M12: =WATER!Q16 -> 0 | N12: 0.6 | O12: =ELEC!B13 -> 4.002
A13: Beirut | B13: =B12+1 -> 12 | C13: 4 | D13: 2020 | E13: =ELEC!N14 -> 8743 | F13: =SUM('EDl log'!T15) -> 0.079652111 | G13: =-tanks!AW17 -> 308 | H13: =SUM(tanks!AV17) -> 0.3845 | I13: =('B5'!AU16)*0.51 -> 61.2 | J13: ='B5'!AX16/0.51 -> 1.372549 | K13: =WATER!I17 -> 0 | L13: =SUM(WATER!J17) -> 0 | M13: =WATER!Q17 -> 0 | N13: 0.6 | O13: =ELEC!B14 -> 2.99
A14: Beirut | B14: =B13+1 -> 13 | C14: 4 | D14: 2020 | E14: =ELEC!N15 -> 8764 | F14: =SUM('EDl log'!T16) -> 0.083829721 | G14: =-tanks!AW18 -> 411 | H14: =SUM(tanks!AV18) -> 0.3845 | I14: =('B5'!AU17)*0.51 -> 30.6 | J14: ='B5'!AX17/0.51 -> 1.372549 | K14: =WATER!I18 -> 45 | L14: =SUM(WATER!J18) -> 5.5555556 | M14: =WATER!Q18 -> 0 | N14: 0.6 | O14: =ELEC!B15 -> 8.004
... A31: Beirut | B31: =B30+1 -> 30 | C31: 4 | D31: 2020 | E31: =ELEC!N32 -> 10173.2 | F31: =SUM('EDl log'!T33) -> 0.066615024 | G31: =-tanks!AW35 -> 281 | H31: =SUM(tanks!AV35) -> 0.284 | I31: =('B5'!AU34)*0.51 -> 224.4 | J31: ='B5'!AX34/0.51 -> 1.372549 | K31: =WATER!I35 -> 0 | L31: =SUM(WATER!J35) -> 0 | M31: =WATER!Q35 -> 0 | N31: 0.6 | O31: =ELEC!B32 -> 2.99

Sheet Submetering
A1: Site Name | B1: Day | C1: Month | D1: Year | E1: ATS1 Kwh | F1: ATS2 Kwh | G1: ATS3 Kwh | H1: ATS4 Kwh | I1: ATS5 Kwh | J1: Guest (m3) | K1: Kitchen & Laundry (m3) | L1: Room Nights
A2: Beirut | B2: 1 | C2: 4 | D2: 2020 | E2: =ELEC!M3 -> 2880 | F2: =ELEC!K3 -> 740 | G2: =ELEC!I3 -> 1112 | H2: =ELEC!E3 -> 1668 | I2: =ELEC!G3 -> 1262.2 | J2: =WATER!Y6 -> 99 | K2: =WATER!AJ6 -> 0 | L2: =ELEC!B3 -> 4.002
A3: Beirut | B3: =B2+1 -> 2 | C3: 4 | D3: 2020 | E3: =ELEC!M4 -> 2800 | F3: =ELEC!K4 -> 776 | G3: =ELEC!I4 -> 1056 | H3: =ELEC!E4 -> 1572 | I3: =ELEC!G4 -> 1233.6 | J3: =WATER!Y7 -> 72 | K3: =WATER!AJ7 -> 20 | L3: =ELEC!B4 -> 2.001
A4: Beirut | B4: =B3+1 -> 3 | C4: 4 | D4: 2020 | E4: =ELEC!M5 -> 3270 | F4: =ELEC!K5 -> 918 | G4: =ELEC!I5 -> 1130 | H4: =ELEC!E5 -> 2056 | I4: =ELEC!G5 -> 1291.2 | J4: =WATER!Y8 -> 60 | K4: =WATER!AJ8 -> 34 | L4: =ELEC!B5 -> 2.001
A5: Beirut | B5: =B4+1 -> 4 | C5: 4 | D5: 2020 | E5: =ELEC!M6 -> 2810 | F5: =ELEC!K6 -> 774 | G5: =ELEC!I6 -> 1112 | H5: =ELEC!E6 -> 1784 | I5: =ELEC!G6 -> 1190.4 | J5: =WATER!Y9 -> 10 | K5: =WATER!AJ9 -> 0 | L5: =ELEC!B6 -> 2.99
A6: Beirut | B6: =B5+1 -> 5 | C6: 4 | D6: 2020 | E6: =ELEC!M7 -> 2492 | F6: =ELEC!K7 -> 888 | G6: =ELEC!I7 -> 1086 | H6: =ELEC!E7 -> 2924 | I6: =ELEC!G7 -> 1148.8 | J6: =WATER!Y10 -> 0 | K6: =WATER!AJ10 -> 70 | L6: =ELEC!B7 -> 6.992
A7: Beirut | B7: =B6+1 -> 6 | C7: 4 | D7: 2020 | E7: =ELEC!M8 -> 3192 | F7: =ELEC!K8 -> 1022 | G7: =ELEC!I8 -> 1192 | H7: =ELEC!E8 -> 3300 | I7: =ELEC!G8 -> 1351.8 | J7: =WATER!Y11 -> 4 | K7: =WATER!AJ11 -> 0 | L7: =ELEC!B8 -> 2.001
A8: Beirut | B8: =B7+1 -> 7 | C8: 4 | D8: 2020 | E8: =ELEC!M9 -> 2542 | F8: =ELEC!K9 -> 832 | G8: =ELEC!I9 -> 1086 | H8: =ELEC!E9 -> 2178 | I8: =ELEC!G9 -> 1271.4 | J8: =WATER!Y12 -> 0 | K8: =WATER!AJ12 -> 37 | L8: =ELEC!B9 -> 2.001
A9: Beirut | B9: =B8+1 -> 8 | C9: 4 | D9: 2020 | E9: =ELEC!M10 -> 2910 | F9: =ELEC!K10 -> 1174 | G9: =ELEC!I10 -> 1352 | H9: =ELEC!E10 -> 3866 | I9: =ELEC!G10 -> 1513.6 | J9: =WATER!Y13 -> 81 | K9: =WATER!AJ13 -> 0 | L9: =ELEC!B10 -> 10.994
A10: Beirut | B10: =B9+1 -> 9 | C10: 4 | D10: 2020 | E10: =ELEC!M11 -> 2356 | F10: =ELEC!K11 -> 972 | G10: =ELEC!I11 -> 1158 | H10: =ELEC!E11 -> 3330 | I10: =ELEC!G11 -> 1287 | J10: =WATER!Y14 -> 78 | K10: =WATER!AJ14 -> 24 | L10: =ELEC!B11 -> 4.991
A11: Beirut | B11: =B10+1 -> 10 | C11: 4 | D11: 2020 | E11: =ELEC!M12 -> 2392 | F11: =ELEC!K12 -> 954 | G11: =ELEC!I12 -> 1200 | H11: =ELEC!E12 -> 2186 | I11: =ELEC!G12 -> 1290.6 | J11: =WATER!Y15 -> 0 | K11: =WATER!AJ15 -> 0 | L11: =ELEC!B12 -> 2.001
A12: Beirut | B12: =B11+1 -> 11 | C12: 4 | D12: 2020 | E12: =ELEC!M13 -> 2612 | F12: =ELEC!K13 -> 978 | G12: =ELEC!I13 -> 1300 | H12: =ELEC!E13 -> 2336 | I12: =ELEC!G13 -> 1377.4 | J12: =WATER!Y16 -> 0 | K12: =WATER!AJ16 -> 5 | L12: =ELEC!B13 -> 4.002
A13: Beirut | B13: =B12+1 -> 12 | C13: 4 | D13: 2020 | E13: =ELEC!M14 -> 2468 | F13: =ELEC!K14 -> 958 | G13: =ELEC!I14 -> 1268 | H13: =ELEC!E14 -> 2796 | I13: =ELEC!G14 -> 1253 | J13: =WATER!Y17 -> 0 | K13: =WATER!AJ17 -> 0 | L13: =ELEC!B14 -> 2.99
A14: Beirut | B14: =B13+1 -> 13 | C14: 4 | D14: 2020 | E14: =ELEC!M15 -> 2532 | F14: =ELEC!K15 -> 924 | G14: =ELEC!I15 -> 1316 | H14: =ELEC!E15 -> 2660 | I14: =ELEC!G15 -> 1332 | J14: =WATER!Y18 -> 3 | K14: =WATER!AJ18 -> 0 | L14: =ELEC!B15 -> 8.004
... A31: Beirut | B31: =B30+1 -> 30 | C31: 4 | D31: 2020 | E31: =ELEC!M32 -> 3506 | F31: =ELEC!K32 -> 1094 | G31: =ELEC!I32 -> 1518 | H31: =ELEC!E32 -> 2376 | I31: =ELEC!G32 -> 1679.2 | J31: =WATER!Y35 -> 0 | K31: =WATER!AJ35 -> 0 | L31: =ELEC!B32 -> 2.99

Sheet ELEC
A1: OOC | B1: Room OCC | D1: MDB3 | E1: MDB3/day | F1: EMDB2 | G1: EMDB2/day | H1: EMDB1 | I1: EMDB1/day | J1: MDB2 | K1: mdb2/day | L1: MDB1 | M1: MDB1/Day | N1: Total KWH | O1: KWH/Rooc | P1: Gen MHW | Q1: Gen/Day KWH | R1: EDL KWH | S1: CH1 RH | T1: RH | U1: C1h1 power | V1: CH1 Con KWH | W1: CH2 RH | X1: RH | Y1: Ch2 power | Z1: CH2 Con KWH | AA1: CH3 RH | AB1: RH | AC1: Ch3 power | AD1: CH3 Con KWH | AE1: RH total | AF1: KWH total | AG1: AVG chiller KW/Hr
A2: =[1]ELEC!$A$33 -> 0.0087 | B2: =[1]ELEC!$B$33 -> 2.001 | C2: 43921 | D2: =[1]ELEC!D33 -> 31561298 | E2: =[1]ELEC!E33 -> 2012 | F2: =[1]ELEC!F33 -> 3605675 | G2: =[1]ELEC!G33 -> 1309 | H2: =[1]ELEC!H33 -> 17390434 | I2: =[1]ELEC!I33 -> 1104 | J2: =[1]ELEC!J33 -> 28361182 | K2: =[1]ELEC!K33 -> 772 | ... T2: =[1]ELEC!T33 -> 2 | U2: 29956 | V2: =[1]ELEC!V33 -> 319 | W2: =[1]ELEC!W33 -> 31845 | X2: =[1]ELEC!X33 -> 0 | Y2: =[1]ELEC!Y33 -> 624440 | Z2: =[1]ELEC!Z33 -> 0 | AA2: =[1]ELEC!AA33 -> 35018 | AB2: =[1]ELEC!AB33 -> 1 | AC2: =[1]ELEC!AC33 -> 767207 | ... AI2: =[1]ELEC!AI33 -> -49692041
A3: ='General information '!F6 -> 0.0174 | B3: =SUM(230*A3) -> 4.002 | C3: 43922 | D3: 31562966 | E3: =D3-D2 -> 1668 | F3: 3606937.2 | G3: =F3-F2 -> 1262.2 | H3: 17391546 | I3: =H3-H2 -> 1112 | J3: 28361922 | K3: =J3-J2 -> 740 | L3: 22854318 | M3: =L3-L2 -> 2880 | N3: =M3+K3+I3+G3+E3 -> 7662.2 | O3: =IF(B3>0,N3/B3,0) -> 1914.5927 | P3: 15437.157 | Q3: =(P3-P2)*1000 -> 2431 | R3: =+N3-Q3 -> 5231.2 | S3: 8410 | T3: =S3-S2 -> 1 | U3: 30202 | V3: =U3-U2 -> 246 | W3: 31845 | X3: =W3-W2 -> 0 | Y3: 624440 | Z3: =Y3-Y2 -> 0 | AA3: =AA2 -> 35018 | AB3: =AA3-AA2 -> 0 | AC3: =AC2 -> 767207 | AD3: =AC3-AC2 -> 0 | AE3: =AB3+X3+T3 -> 1 | AF3: =V3+Z3+AD3 -> 246 | AG3: =IF(AE3>0,AF3/AE3,0) -> 246
A4: ='General information '!F7 -> 0.0087 | B4: =SUM(230*A4) -> 2.001 | C4: 43923 | D4: 31564538 | E4: =D4-D3 -> 1572 | F4: 3608170.8 | G4: =F4-F3 -> 1233.6 | H4: 17392602 | I4: =H4-H3 -> 1056 | J4: 28362698 | K4: =J4-J3 -> 776 | L4: 22857118 | M4: =L4-L3 -> 2800 | N4: =M4+K4+I4+G4+E4 -> 7437.6 | O4: =IF(B4>0,N4/B4,0) -> 3716.9415 | P4: 15438.738 | Q4: =(P4-P3)*1000 -> 1581 | R4: =N4-Q4 -> 5856.6 | S4: 8411 | T4: =S4-S3 -> 1 | U4: 30510 | V4: =U4-U3 -> 308 | W4: =W3 -> 31845 | X4: =W4-W3 -> 0 | Y4: =Y3 -> 624440 | Z4: =Y4-Y3 -> 0 | AA4: =AA3 -> 35018 | AB4: =AA4-AA3 -> 0 | AC4: =AC3 -> 767207 | AD4: =AC4-AC3 -> 0 | AE4: =AB4+X4+T4 -> 1 | AF4: =V4+Z4+AD4 -> 308 | AG4: =IF(AE4>0,AF4/AE4,0) -> 308
A5: ='General information '!F8 -> 0.0087 | B5: =SUM(230*A5) -> 2.001 | C5: 43924 | D5: 31566594 | E5: =D5-D4 -> 2056 | F5: 3609462 | G5: =F5-F4 -> 1291.2 | H5: 17393732 | I5: =H5-H4 -> 1130 | J5: 28363616 | K5: =J5-J4 -> 918 | L5: 22860388 | M5: =L5-L4 -> 3270 | N5: =M5+K5+I5+G5+E5 -> 8665.2 | O5: =IF(B5>0,N5/B5,0) -> 4330.4348 | P5: 15440 | Q5: =(P5-P4)*1000 -> 1262 | R5: =N5-Q5 -> 7403.2 | S5: 8413 | T5: =S5-S4 -> 2 | U5: 31029 | V5: =U5-U4 -> 519 | W5: =W4 -> 31845 | X5: =W5-W4 -> 0 | Y5: =Y4 -> 624440 | Z5: =Y5-Y4 -> 0 | AA5: =AA4 -> 35018 | AB5: =AA5-AA4 -> 0 | AC5: =AC4 -> 767207 | AD5: =AC5-AC4 -> 0 | AE5: =AB5+X5+T5 -> 2 | AF5: =V5+Z5+AD5 -> 519 | AG5: =IF(AE5>0,AF5/AE5,0) -> 259.5 | AI5: =R5-'EDl log'!B3 -> -49702331
A6: ='General information '!F9 -> 0.013 | B6: =SUM(230*A6) -> 2.99 | C6: 43925 | D6: 31568378 | E6: =D6-D5 -> 1784 | F6: 3610652.4 | G6: =F6-F5 -> 1190.4 | H6: 17394844 | I6: =H6-H5 -> 1112 | J6: 28364390 | K6: =J6-J5 -> 774 | L6: 22863198 | M6: =L6-L5 -> 2810 | N6: =M6+K6+I6+G6+E6 -> 7670.4 | O6: =IF(B6>0,N6/B6,0) -> 2565.3512 | P6: 15441.642 | Q6: =(P6-P5)*1000 -> 1642 | R6: =N6-Q6 -> 6028.4 | S6: 8414 | T6: =S6-S5 -> 1 | U6: 31272 | V6: =U6-U5 -> 243 | W6: =W5 -> 31845 | X6: =W6-W5 -> 0 | Y6: =Y5 -> 624440 | Z6: =Y6-Y5 -> 0 | AA6: =AA5 -> 35018 | AB6: =AA6-AA5 -> 0 | AC6: =AC5 -> 767207 | AD6: =AC6-AC5 -> 0 | AE6: =AB6+X6+T6 -> 1 | AF6: =V6+Z6+AD6 -> 243 | AG6: =IF(AE6>0,AF6/AE6,0) -> 243 | AI6: =R6-'EDl log'!B4 -> -49706937
A7: ='General information '!F10 -> 0.0304 | B7: =SUM(230*A7) -> 6.992 | C7: 43926 | D7: 31571302 | E7: =D7-D6 -> 2924 | F7: 3611801.2 | G7: =F7-F6 -> 1148.8 | H7: 17395930 | I7: =H7-H6 -> 1086 | J7: 28365278 | K7: =J7-J6 -> 888 | L7: 22865690 | M7: =L7-L6 -> 2492 | N7: =M7+K7+I7+G7+E7 -> 8538.8 | O7: =IF(B7>0,N7/B7,0) -> 1221.2243 | P7: 15443.333 | Q7: =(P7-P6)*1000 -> 1691 | R7: =N7-Q7 -> 6847.8 | S7: 8416 | T7: =S7-S6 -> 2 | U7: 31598 | V7: =U7-U6 -> 326 | W7: 31845 | X7: =W7-W6 -> 0 | Y7: 624440 | Z7: =Y7-Y6 -> 0 | AA7: 35025 | AB7: =AA7-AA6 -> 7 | AC7: 768802 | AD7: =AC7-AC6 -> 1595 | AE7: =AB7+X7+T7 -> 9 | AF7: =V7+Z7+AD7 -> 1921 | AG7: =IF(AE7>0,AF7/AE7,0) -> 213.44444 | AI7: =R7-'EDl log'!B5 -> -49709193
A8: ='General information '!F11 -> 0.0087 | B8: =SUM(230*A8) -> 2.001 | C8: 43927 | D8: 31574602 | E8: =D8-D7 -> 3300 | F8: 3613153 | G8: =F8-F7 -> 1351.8 | H8: 17397122 | I8: =H8-H7 -> 1192 | J8: 28366300 | K8: =J8-J7 -> 1022 | L8: 22868882 | M8: =L8-L7 -> 3192 | N8: =M8+K8+I8+G8+E8 -> 10057.8 | O8: =IF(B8>0,N8/B8,0) -> 5026.3868 | P8: 15445.123 | Q8: =(P8-P7)*1000 -> 1790 | R8: =N8-Q8 -> 8267.8 | S8: 8416 | T8: =S8-S7 -> 0 | U8: 31598 | V8: =U8-U7 -> 0 | W8: 31845 | X8: =W8-W7 -> 0 | Y8: 624440 | Z8: =Y8-Y7 -> 0 | AA8: 35025 | AB8: =AA8-AA7 -> 0 | AC8: 768802 | AD8: =AC8-AC7 -> 0 | AE8: =AB8+X8+T8 -> 0 | AF8: =V8+Z8+AD8 -> 0 | AG8: =IF(AE8>0,AF8/AE8,0) -> 0 | AI8: =R8-'EDl log'!B6 -> -49711486
A9: ='General information '!F12 -> 0.0087 | B9: =SUM(230*A9) -> 2.001 | C9: 43928 | D9: 31576780 | E9: =D9-D8 -> 2178 | F9: 3614424.4 | G9: =F9-F8 -> 1271.4 | H9: 17398208 | I9: =H9-H8 -> 1086 | J9: 28367132 | K9: =J9-J8 -> 832 | L9: 22871424 | M9: =L9-L8 -> 2542 | N9: =M9+K9+I9+G9+E9 -> 7909.4 | O9: =IF(B9>0,N9/B9,0) -> 3952.7236 | P9: 15446.522 | Q9: =(P9-P8)*1000 -> 1399 | R9: =N9-Q9 -> 6510.4 | S9: 8416 | T9: =S9-S8 -> 0 | U9: 31598 | V9: =U9-U8 -> 0 | W9: 31845 | X9: =W9-W8 -> 0 | Y9: 624440 | Z9: =Y9-Y8 -> 0 | AA9: 35026 | AB9: =AA9-AA8 -> 1 | AC9: 769112 | AD9: =AC9-AC8 -> 310 | AE9: =AB9+X9+T9 -> 1 | AF9: =V9+Z9+AD9 -> 310 | AG9: =IF(AE9>0,AF9/AE9,0) -> 310 | AI9: =R9-'EDl log'!B7 -> -49716573
A10: ='General information '!F13 -> 0.0478 | B10: =SUM(230*A10) -> 10.994 | C10: 43929 | D10: 31580646 | E10: =D10-D9 -> 3866 | F10: 3615938 | G10: =F10-F9 -> 1513.6 | H10: 17399560 | I10: =H10-H9 -> 1352 | J10: 28368306 | K10: =J10-J9 -> 1174 | L10: 22874334 | M10: =L10-L9 -> 2910 | N10: =M10+K10+I10+G10+E10 -> 10815.6 | O10: =IF(B10>0,N10/B10,0) -> 983.77297 | P10: 15448.133 | Q10: =(P10-P9)*1000 -> 1611 | R10: =N10-Q10 -> 9204.6 | S10: 8416 | T10: =S10-S9 -> 0 | U10: 31598 | V10: =U10-U9 -> 0 | W10: 31845 | X10: =W10-W9 -> 0 | Y10: 624440 | Z10: =Y10-Y9 -> 0 | AA10: 35030 | AB10: =AA10-AA9 -> 4 | AC10: 770135 | AD10: =AC10-AC9 -> 1023 | AE10: =AB10+X10+T10 -> 4 | AF10: =V10+Z10+AD10 -> 1023 | AG10: =IF(AE10>0,AF10/AE10,0) -> 255.75 | AI10: =R10-'EDl log'!B8 -> -49717461
A11: ='General information '!F14 -> 0.0217 | B11: =SUM(230*A11) -> 4.991 | C11: 43930 | D11: 31583976 | E11: =D11-D10 -> 3330 | F11: 3617225 | G11: =F11-F10 -> 1287 | H11: 17400718 | I11: =H11-H10 -> 1158 | J11: 28369278 | K11: =J11-J10 -> 972 | L11: 22876690 | M11: =L11-L10 -> 2356 | N11: =M11+K11+I11+G11+E11 -> 9103 | O11: =IF(B11>0,N11/B11,0) -> 1823.883 | P11: 15450 | Q11: =(P11-P10)*1000 -> 1867 | R11: =N11-Q11 -> 7236 | S11: =S10 -> 8416 | T11: =S11-S10 -> 0 | U11: =U10 -> 31598 | V11: =U11-U10 -> 0 | W11: =W10 -> 31845 | X11: =W11-W10 -> 0 | Y11: =Y10 -> 624440 | Z11: =Y11-Y10 -> 0 | AA11: 35032 | AB11: =AA11-AA10 -> 2 | AC11: 770886 | AD11: =AC11-AC10 -> 751 | AE11: =AB11+X11+T11 -> 2 | AF11: =V11+Z11+AD11 -> 751 | AG11: =IF(AE11>0,AF11/AE11,0) -> 375.5 | AI11: =R11-'EDl log'!B9 -> -49723744
A12: ='General information '!F15 -> 0.0087 | B12: =SUM(230*A12) -> 2.001 | C12: 43931 | D12: 31586162 | E12: =D12-D11 -> 2186 | F12: 3618515.6 | G12: =F12-F11 -> 1290.6 | H12: 17401918 | I12: =H12-H11 -> 1200 | J12: 28370232 | K12: =J12-J11 -> 954 | L12: 22879082 | M12: =L12-L11 -> 2392 | N12: =M12+K12+I12+G12+E12 -> 8022.6 | O12: =IF(B12>0,N12/B12,0) -> 4009.2954 | P12: 15451 | Q12: =(P12-P11)*1000 -> 1000 | R12: =N12-Q12 -> 7022.6 | S12: =S11 -> 8416 | T12: =S12-S11 -> 0 | U12: =U11 -> 31598 | V12: =U12-U11 -> 0 | W12: =W11 -> 31845 | X12: =W12-W11 -> 0 | Y12: =Y11 -> 624440 | Z12: =Y12-Y11 -> 0 | AA12: 35034 | AB12: =AA12-AA11 -> 2 | AC12: 771312 | AD12: =AC12-AC11 -> 426 | AE12: =AB12+X12+T12 -> 2 | AF12: =V12+Z12+AD12 -> 426 | AG12: =IF(AE12>0,AF12/AE12,0) -> 213 | AI12: =R12-'EDl log'!B10 -> -49727414
A13: ='General information '!F16 -> 0.0174 | B13: =SUM(230*A13) -> 4.002 | C13: 43932 | D13: 31588498 | E13: =D13-D12 -> 2336 | F13: 3619893 | G13: =F13-F12 -> 1377.4 | H13: 17403218 | I13: =H13-H12 -> 1300 | J13: 28371210 | K13: =J13-J12 -> 978 | L13: 22881694 | M13: =L13-L12 -> 2612 | N13: =M13+K13+I13+G13+E13 -> 8603.4 | O13: =IF(B13>0,N13/B13,0) -> 2149.7751 | P13: 15453 | Q13: =(P13-P12)*1000 -> 2000 | R13: =N13-Q13 -> 6603.4 | S13: =S12 -> 8416 | T13: =S13-S12 -> 0 | U13: =U12 -> 31598 | V13: =U13-U12 -> 0 | W13: =W12 -> 31845 | X13: =W13-W12 -> 0 | Y13: =Y12 -> 624440 | Z13: =Y13-Y12 -> 0 | AA13: 35035 | AB13: =AA13-AA12 -> 1 | AC13: 771620 | AD13: =AC13-AC12 -> 308 | AE13: =AB13+X13+T13 -> 1 | AF13: =V13+Z13+AD13 -> 308 | AG13: =IF(AE13>0,AF13/AE13,0) -> 308 | AI13: =R13-'EDl log'!B11 -> -49732572
A14: ='General information '!F17 -> 0.013 | B14: =SUM(230*A14) -> 2.99 | C14: 43933 | D14: 31591294 | E14: =D14-D13 -> 2796 | F14: 3621146 | G14: =F14-F13 -> 1253 | H14: 17404486 | I14: =H14-H13 -> 1268 | J14: 28372168 | K14: =J14-J13 -> 958 | L14: 22884162 | M14: =L14-L13 -> 2468 | N14: =M14+K14+I14+G14+E14 -> 8743 | O14: =IF(B14>0,N14/B14,0) -> 2924.0803 | P14: 15454 | Q14: =(P14-P13)*1000 -> 1000 | R14: =N14-Q14 -> 7743 | S14: =S13 -> 8416 | T14: =S14-S13 -> 0 | U14: =U13 -> 31598 | V14: =U14-U13 -> 0 | W14: =W13 -> 31845 | X14: =W14-W13 -> 0 | Y14: =Y13 -> 624440 | Z14: =Y14-Y13 -> 0 | AA14: 35037 | AB14: =AA14-AA13 -> 2 | AC14: 772092 | AD14: =AC14-AC13 -> 472 | AE14: =AB14+X14+T14 -> 2 | AF14: =V14+Z14+AD14 -> 472 | AG14: =IF(AE14>0,AF14/AE14,0) -> 236 | AI14: =R14-'EDl log'!B12 -> -49735109
A15: ='General information '!F18 -> 0.0348 | B15: =SUM(230*A15) -> 8.004 | C15: 43934 | D15: 31593954 | E15: =D15-D14 -> 2660 | F15: 3622478 | G15: =F15-F14 -> 1332 | H15: 17405802 | I15: =H15-H14 -> 1316 | J15: 28373092 | K15: =J15-J14 -> 924 | L15: 22886694 | M15: =L15-L14 -> 2532 | N15: =M15+K15+I15+G15+E15 -> 8764 | O15: =IF(B15>0,N15/B15,0) -> 1094.9525 | P15: 15455 | Q15: =(P15-P14)*1000 -> 1000 | R15: =N15-Q15 -> 7764 | S15: =S14 -> 8416 | T15: =S15-S14 -> 0 | U15: =U14 -> 31598 | V15: =U15-U14 -> 0 | W15: =W14 -> 31845 | X15: =W15-W14 -> 0 | Y15: =Y14 -> 624440 | Z15: =Y15-Y14 -> 0 | AA15: =AA14 -> 35037 | AB15: =AA15-AA14 -> 0 | AC15: 772288 | AD15: =AC15-AC14 -> 196 | AE15: =AB15+X15+T15 -> 0 | AF15: =V15+Z15+AD15 -> 196 | AG15: =IF(AE15>0,AF15/AE15,0) -> 0 | AI15: =R15-'EDl log'!B13 -> -49738477
A16: ='General information '!F19 -> 0.0217 | B16: =SUM(230*A16) -> 4.991 | C16: 43935 | D16: 31596054 | E16: =D16-D15 -> 2100 | F16: 3623964.4 | G16: =F16-F15 -> 1486.4 | H16: 17407190 | I16: =H16-H15 -> 1388 | J16: 28374102 | K16: =J16-J15 -> 1010 | L16: 22889398 | M16: =L16-L15 -> 2704 | N16: =M16+K16+I16+G16+E16 -> 8688.4 | O16: =IF(B16>0,N16/B16,0) -> 1740.8135 | P16: 15457.114 | Q16: =(P16-P15)*1000 -> 2114 | R16: =N16-Q16 -> 6574.4 | S16: 8416 | T16: =S16-S15 -> 0 | U16: 31598 | V16: =U16-U15 -> 0 | W16: 31845 | X16: =W16-W15 -> 0 | Y16: 624440 | Z16: =Y16-Y15 -> 0 | AA16: 35038 | AB16: =AA16-AA15 -> 1 | AC16: 772525 | AD16: =AC16-AC15 -> 237 | AE16: =AB16+X16+T16 -> 1 | AF16: =V16+Z16+AD16 -> 237 | AG16: =IF(AE16>0,AF16/AE16,0) -> 237 | AI16: =R16-'EDl log'!B14 -> -49743158
A17: ='General information '!F20 -> 0.013 | B17: =SUM(230*A17) -> 2.99 | C17: 43936 | D17: 31598968 | E17: =D17-D16 -> 2914 | F17: 3625348.4 | G17: =F17-F16 -> 1384 | H17: 17408506 | I17: =H17-H16 -> 1316 | J17: 28375126 | K17: =J17-J16 -> 1024 | L17: 22892042 | M17: =L17-L16 -> 2644 | N17: =M17+K17+I17+G17+E17 -> 9282 | O17: =IF(B17>0,N17/B17,0) -> 3104.3478 | P17: 15458.864 | Q17: =(P17-P16)*1000 -> 1750 | R17: =N17-Q17 -> 7532 | S17: 8416 | T17: =S17-S16 -> 0 | U17: 31598 | V17: =U17-U16 -> 0 | W17: 31845 | X17: =W17-W16 -> 0 | Y17: 624440 | Z17: =Y17-Y16 -> 0 | AA17: 35041 | AB17: =AA17-AA16 -> 3 | AC17: 773141 | AD17: =AC17-AC16 -> 616 | AE17: =AB17+X17+T17 -> 3 | AF17: =V17+Z17+AD17 -> 616 | AG17: =IF(AE17>0,AF17/AE17,0) -> 205.33333 | AI17: =R17-'EDl log'!B15 -> -49746497
A18: ='General information '!F21 -> 0.01 | B18: =SUM(230*A18) -> 2.3 | C18: 43937 | D18: 31601698 | E18: =D18-D17 -> 2730 | F18: 3627030 | G18: =F18-F17 -> 1681.6 | H18: 17410024 | I18: =H18-H17 -> 1518 | J18: 28376340 | K18: =J18-J17 -> 1214 | L18: 22895670 | M18: =L18-L17 -> 3628 | N18: =M18+K18+I18+G18+E18 -> 10771.6 | O18: =IF(B18>0,N18/B18,0) -> 4683.3043 | P18: 15459.5 | Q18: =(P18-P17)*1000 -> 636 | R18: =N18-Q18 -> 10135.6 | S18: 8418 | T18: =S18-S17 -> 2 | U18: 32172 | V18: =U18-U17 -> 574 | W18: 31845 | X18: =W18-W17 -> 0 | Y18: =Y17 -> 624440 | Z18: =Y18-Y17 -> 0 | AA18: 35042 | AB18: =AA18-AA17 -> 1 | AC18: 773343 | AD18: =AC18-AC17 -> 202 | AE18: =AB18+X18+T18 -> 3 | AF18: =V18+Z18+AD18 -> 776 | AG18: =IF(AE18>0,AF18/AE18,0) -> 258.66667 | AI18: =R18-'EDl log'!B16 -> -49747767
A19: ='General information '!F22 -> 0.0087 | B19: =SUM(230*A19) -> 2.001 | C19: 43938 | D19: 31603542 | E19: =D19-D18 -> 1844 | F19: 3628364 | G19: =F19-F18 -> 1334 | H19: 17411118 | I19: =H19-H18 -> 1094 | J19: 28377274 | K19: =J19-J18 -> 934 | L19: 22898710 | M19: =L19-L18 -> 3040 | N19: =M19+K19+I19+G19+E19 -> 8246 | O19: =IF(B19>0,N19/B19,0) -> 4120.9395 | P19: 15461.289 | Q19: =(P19-P18)*1000 -> 1789 | R19: =N19-Q19 -> 6457 | S19: 8420 | T19: =S19-S18 -> 2 | U19: 32720 | V19: =U19-U18 -> 548 | W19: 31845 | X19: =W19-W18 -> 0 | Y19: =Y18 -> 624440 | Z19: =Y19-Y18 -> 0 | AA19: =AA18 -> 35042 | AB19: =AA19-AA18 -> 0 | AC19: =AC18 -> 773343 | AD19: =AC19-AC18 -> 0 | AE19: =AB19+X19+T19 -> 2 | AF19: =V19+Z19+AD19 -> 548 | AG19: =IF(AE19>0,AF19/AE19,0) -> 274 | AI19: =R19-'EDl log'!B17 -> -49755146
A20: ='General information '!F23 -> 0.013 | B20: =SUM(230*A20) -> 2.99 | C20: 43939 | D20: 31605926 | E20: =D20-D19 -> 2384 | F20: 3629837 | G20: =F20-F19 -> 1473 | H20: 17412422 | I20: =H20-H19 -> 1304 | J20: 28378316 | K20: =J20-J19 -> 1042 | L20: 22902130 | M20: =L20-L19 -> 3420 | N20: =M20+K20+I20+G20+E20 -> 9623 | O20: =IF(B20>0,N20/B20,0) -> 3218.3946 | P20: 15462.976 | Q20: =(P20-P19)*1000 -> 1687 | R20: =N20-Q20 -> 7936 | S20: 8423 | T20: =S20-S19 -> 3 | U20: 33208 | V20: =U20-U19 -> 488 | W20: =W19 -> 31845 | X20: =W20-W19 -> 0 | Y20: =Y19 -> 624440 | Z20: =Y20-Y19 -> 0 | AA20: =AA19 -> 35042 | AB20: =AA20-AA19 -> 0 | AC20: =AC19 -> 773343 | AD20: =AC20-AC19 -> 0 | AE20: =AB20+X20+T20 -> 3 | AF20: =V20+Z20+AD20 -> 488 | AG20: =IF(AE20>0,AF20/AE20,0) -> 162.66667 | AI20: =R20-'EDl log'!B18 -> -49757589
A21: ='General information '!F24 -> 0.0217 | B21: =SUM(230*A21) -> 4.991 | C21: 43940 | D21: 31608186 | E21: =D21-D20 -> 2260 | F21: 3631079 | G21: =F21-F20 -> 1242 | H21: 17413568 | I21: =H21-H20 -> 1146 | J21: 28379406 | K21: =J21-J20 -> 1090 | L21: 22905442 | M21: =L21-L20 -> 3312 | N21: =M21+K21+I21+G21+E21 -> 9050 | O21: =IF(B21>0,N21/B21,0) -> 1813.2639 | P21: 15463.334 | Q21: =(P21-P20)*1000 -> 358 | R21: =N21-Q21 -> 8692 | S21: 8425 | T21: =S21-S20 -> 2 | U21: 33943 | V21: =U21-U20 -> 735 | W21: =W20 -> 31845 | X21: =W21-W20 -> 0 | Y21: =Y20 -> 624440 | Z21: =Y21-Y20 -> 0 | AA21: =AA20 -> 35042 | AB21: =AA21-AA20 -> 0 | AC21: =AC20 -> 773343 | AD21: =AC21-AC20 -> 0 | AE21: =AB21+X21+T21 -> 2 | AF21: =V21+Z21+AD21 -> 735 | AG21: =IF(AE21>0,AF21/AE21,0) -> 367.5 | AI21: =R21-'EDl log'!B19 -> -49762137
A22: ='General information '!F25 -> 0.0087 | B22: =SUM(230*A22) -> 2.001 | C22: 43941 | D22: 31610498 | E22: =D22-D21 -> 2312 | F22: 3632435 | G22: =F22-F21 -> 1356 | H22: 17414834 | I22: =H22-H21 -> 1266 | J22: 28380474 | K22: =J22-J21 -> 1068 | L22: 22909138 | M22: =L22-L21 -> 3696 | N22: =M22+K22+I22+G22+E22 -> 9698 | O22: =IF(B22>0,N22/B22,0) -> 4846.5767 | P22: 15463.334 | Q22: =(P22-P21)*1000 -> 0 | R22: =N22-Q22 -> 9698 | S22: 8429 | T22: =S22-S21 -> 4 | U22: 34834 | V22: =U22-U21 -> 891 | W22: =W21 -> 31845 | X22: =W22-W21 -> 0 | Y22: =Y21 -> 624440 | Z22: =Y22-Y21 -> 0 | AA22: =AA21 -> 35042 | AB22: =AA22-AA21 -> 0 | AC22: =AC21 -> 773343 | AD22: =AC22-AC21 -> 0 | AE22: =AB22+X22+T22 -> 4 | AF22: =V22+Z22+AD22 -> 891 | AG22: =IF(AE22>0,AF22/AE22,0) -> 222.75 | AI22: =R22-'EDl log'!B20 -> -49764486
A23: ='General information '!F26 -> 0.0087 | B23: =SUM(230*A23) -> 2.001 | C23: 43942 | D23: 31612378 | E23: =D23-D22 -> 1880 | F23: 3633753 | G23: =F23-F22 -> 1318 | H23: 17415986 | I23: =H23-H22 -> 1152 | J23: 28381450 | K23: =J23-J22 -> 976 | L23: 22912266 | M23: =L23-L22 -> 3128 | N23: =M23+K23+I23+G23+E23 -> 8454 | O23: =IF(B23>0,N23/B23,0) -> 4224.8876 | P23: 15464.986 | Q23: =(P23-P22)*1000 -> 1652 | R23: =N23-Q23 -> 6802 | S23: 8432 | T23: =S23-S22 -> 3 | U23: 35423 | V23: =U23-U22 -> 589 | W23: 31845 | X23: =W23-W22 -> 0 | Y23: 624440 | Z23: =Y23-Y22 -> 0 | AA23: 35042 | AB23: =AA23-AA22 -> 0 | AC23: 773343 | AD23: =AC23-AC22 -> 0 | AE23: =AB23+X23+T23 -> 3 | AF23: =V23+Z23+AD23 -> 589 | AG23: =IF(AE23>0,AF23/AE23,0) -> 196.33333 | AI23: =R23-'EDl log'!B21 -> -49771537
A24: ='General information '!F27 -> 0.0087 | B24: =SUM(230*A24) -> 2.001 | C24: 43943 | D24: 31614590 | E24: =D24-D23 -> 2212 | F24: 3635325 | G24: =F24-F23 -> 1572 | H24: 17417342 | I24: =H24-H23 -> 1356 | J24: 28382546 | K24: =J24-J23 -> 1096 | L24: 22915870 | M24: =L24-L23 -> 3604 | N24: =M24+K24+I24+G24+E24 -> 9840 | O24: =IF(B24>0,N24/B24,0) -> 4917.5412 | P24: 15467.004 | Q24: =(P24-P23)*1000 -> 2018 | R24: =N24-Q24 -> 7822 | S24: 8434 | T24: =S24-S23 -> 2 | U24: 35999 | V24: =U24-U23 -> 576 | W24: 31845 | X24: =W24-W23 -> 0 | Y24: 624440 | Z24: =Y24-Y23 -> 0 | AA24: 35042 | AB24: =AA24-AA23 -> 0 | AC24: 773343 | AD24: =AC24-AC23 -> 0 | AE24: =AB24+X24+T24 -> 2 | AF24: =V24+Z24+AD24 -> 576 | AG24: =IF(AE24>0,AF24/AE24,0) -> 288 | AI24: =R24-'EDl log'!B22 -> -49775041
A25: ='General information '!F28 -> 0.0087 | B25: =SUM(230*A25) -> 2.001 | C25: 43944 | D25: 31616650 | E25: =D25-D24 -> 2060 | F25: 3636670 | G25: =F25-F24 -> 1345 | H25: 17418468 | I25: =H25-H24 -> 1126 | J25: 28383382 | K25: =J25-J24 -> 836 | L25: 22918890 | M25: =L25-L24 -> 3020 | N25: =M25+K25+I25+G25+E25 -> 8387 | O25: =IF(B25>0,N25/B25,0) -> 4191.4043 | P25: 15468 | Q25: =(P25-P24)*1000 -> 996 | R25: =N25-Q25 -> 7391 | S25: 8437 | T25: =S25-S24 -> 3 | U25: 36455 | V25: =U25-U24 -> 456 | W25: =W24 -> 31845 | X25: =W25-W24 -> 0 | Y25: =Y24 -> 624440 | Z25: =Y25-Y24 -> 0 | AA25: =AA24 -> 35042 | AB25: =AA25-AA24 -> 0 | AC25: =AC24 -> 773343 | AD25: =AC25-AC24 -> 0 | AE25: =AB25+X25+T25 -> 3 | AF25: =V25+Z25+AD25 -> 456 | AG25: =IF(AE25>0,AF25/AE25,0) -> 152 | AI25: =R25-'EDl log'!B23 -> -49780505
A26: ='General information '!F29 -> 0.0087 | B26: =SUM(230*A26) -> 2.001 | C26: 43945 | D26: 31619370 | E26: =D26-D25 -> 2720 | F26: 3638044.4 | G26: =F26-F25 -> 1374.4 | H26: 17419674 | I26: =H26-H25 -> 1206 | J26: 28384482 | K26: =J26-J25 -> 1100 | L26: 22922712 | M26: =L26-L25 -> 3822 | N26: =M26+K26+I26+G26+E26 -> 10222.4 | O26: =IF(B26>0,N26/B26,0) -> 5108.6457 | P26: 15469.98 | Q26: =(P26-P25)*1000 -> 1980 | R26: =N26-Q26 -> 8242.4 | S26: 8441 | T26: =S26-S25 -> 4 | U26: 37459 | V26: =U26-U25 -> 1004 | W26: =W25 -> 31845 | X26: =W26-W25 -> 0 | Y26: =Y25 -> 624440 | Z26: =Y26-Y25 -> 0 | AA26: =AA25 -> 35042 | AB26: =AA26-AA25 -> 0 | AC26: =AC25 -> 773343 | AD26: =AC26-AC25 -> 0 | AE26: =AB26+X26+T26 -> 4 | AF26: =V26+Z26+AD26 -> 1004 | AG26: =IF(AE26>0,AF26/AE26,0) -> 251 | AI26: =R26-'EDl log'!B24 -> -49783217
A27: ='General information '!F30 -> 0.0174 | B27: =SUM(230*A27) -> 4.002 | C27: 43946 | D27: 31621706 | E27: =D27-D26 -> 2336 | F27: 3639346 | G27: =F27-F26 -> 1301.6 | H27: 17420866 | I27: =H27-H26 -> 1192 | J27: 28385472 | K27: =J27-J26 -> 990 | L27: 22926062 | M27: =L27-L26 -> 3350 | N27: =M27+K27+I27+G27+E27 -> 9169.6 | O27: =IF(B27>0,N27/B27,0) -> 2291.2544 | P27: 15471.5 | Q27: =(P27-P26)*1000 -> 1520 | R27: =N27-Q27 -> 7649.6 | S27: 8444 | T27: =S27-S26 -> 3 | U27: 38088 | V27: =U27-U26 -> 629 | W27: =W26 -> 31845 | X27: =W27-W26 -> 0 | Y27: =Y26 -> 624440 | Z27: =Y27-Y26 -> 0 | AA27: =AA26 -> 35042 | AB27: =AA27-AA26 -> 0 | AC27: =AC26 -> 773343 | AD27: =AC27-AC26 -> 0 | AE27: =AB27+X27+T27 -> 3 | AF27: =V27+Z27+AD27 -> 629 | AG27: =IF(AE27>0,AF27/AE27,0) -> 209.66667 | AI27: =R27-'EDl log'!B25 -> -49787896
A28: ='General information '!F31 -> 0.0348 | B28: =SUM(230*A28) -> 8.004 | C28: 43947 | D28: 31623718 | E28: =D28-D27 -> 2012 | F28: 3640592 | G28: =F28-F27 -> 1246 | H28: 17422066 | I28: =H28-H27 -> 1200 | J28: 28386398 | K28: =J28-J27 -> 926 | L28: 22929078 | M28: =L28-L27 -> 3016 | N28: =M28+K28+I28+G28+E28 -> 8400 | O28: =IF(B28>0,N28/B28,0) -> 1049.4753 | P28: 15473 | Q28: =(P28-P27)*1000 -> 1500 | R28: =N28-Q28 -> 6900 | S28: 8446 | T28: =S28-S27 -> 2 | U28: 38539 | V28: =U28-U27 -> 451 | W28: =W27 -> 31845 | X28: =W28-W27 -> 0 | Y28: =Y27 -> 624440 | Z28: =Y28-Y27 -> 0 | AA28: =AA27 -> 35042 | AB28: =AA28-AA27 -> 0 | AC28: =AC27 -> 773343 | AD28: =AC28-AC27 -> 0 | AE28: =AB28+X28+T28 -> 2 | AF28: =V28+Z28+AD28 -> 451 | AG28: =IF(AE28>0,AF28/AE28,0) -> 225.5 | AI28: =R28-'EDl log'!B26 -> -49792018
A29: ='General information '!F32 -> 0.0087 | B29: =SUM(230*A29) -> 2.001 | C29: 43948 | D29: 31625998 | E29: =D29-D28 -> 2280 | F29: 3642080 | G29: =F29-F28 -> 1488 | H29: 17423448 | I29: =H29-H28 -> 1382 | J29: 28387428 | K29: =J29-J28 -> 1030 | L29: 22932548 | M29: =L29-L28 -> 3470 | N29: =M29+K29+I29+G29+E29 -> 9650 | O29: =IF(B29>0,N29/B29,0) -> 4822.5887 | P29: 15475.513 | Q29: =(P29-P28)*1000 -> 2513 | R29: =N29-Q29 -> 7137 | S29: 8449 | T29: =S29-S28 -> 3 | U29: 39033 | V29: =U29-U28 -> 494 | W29: 31845 | X29: =W29-W28 -> 0 | Y29: 624440 | Z29: =Y29-Y28 -> 0 | AA29: 35042 | AB29: =AA29-AA28 -> 0 | AC29: 773343 | AD29: =AC29-AC28 -> 0 | AE29: =AB29+X29+T29 -> 3 | AF29: =V29+Z29+AD29 -> 494 | AG29: =IF(AE29>0,AF29/AE29,0) -> 164.66667 | AI29: =R29-'EDl log'!B27 -> -49796566
A30: ='General information '!F33 -> 0.0174 | B30: =SUM(230*A30) -> 4.002 | C30: 43949 | D30: 31628282 | E30: =D30-D29 -> 2284 | F30: 3643444 | G30: =F30-F29 -> 1364 | H30: 17424726 | I30: =H30-H29 -> 1278 | J30: 28388330 | K30: =J30-J29 -> 902 | L30: 22935484 | M30: =L30-L29 -> 2936 | N30: =M30+K30+I30+G30+E30 -> 8764 | O30: =IF(B30>0,N30/B30,0) -> 2189.905 | P30: 15476.532 | Q30: =(P30-P29)*1000 -> 1019 | R30: =N30-Q30 -> 7745 | S30: 8450 | T30: =S30-S29 -> 1 | U30: 39179 | V30: =U30-U29 -> 146 | W30: 31845 | X30: =W30-W29 -> 0 | Y30: 624440 | Z30: =Y30-Y29 -> 0 | AA30: 35042 | AB30: =AA30-AA29 -> 0 | AC30: 773343 | AD30: =AC30-AC29 -> 0 | AE30: =AB30+X30+T30 -> 1 | AF30: =V30+Z30+AD30 -> 146 | AG30: =IF(AE30>0,AF30/AE30,0) -> 146 | AI30: =R30-'EDl log'!B28 -> -49799895
A31: ='General information '!F34 -> 0.0174 | B31: =SUM(230*A31) -> 4.002 | C31: 43950 | D31: 31630714 | E31: =D31-D30 -> 2432 | F31: 3644716.4 | G31: =F31-F30 -> 1272.4 | H31: 17425898 | I31: =H31-H30 -> 1172 | J31: 28389326 | K31: =J31-J30 -> 996 | L31: 22938680 | M31: =L31-L30 -> 3196 | N31: =M31+K31+I31+G31+E31 -> 9068.4 | O31: =IF(B31>0,N31/B31,0) -> 2265.967 | P31: 15477.83 | Q31: =(P31-P30)*1000 -> 1298 | R31: =N31-Q31 -> 7770.4 | S31: 8452 | T31: =S31-S30 -> 2 | U31: 39860 | V31: =U31-U30 -> 681 | W31: 31845 | X31: =W31-W30 -> 0 | Y31: 624440 | Z31: =Y31-Y30 -> 0 | AA31: 35042 | AB31: =AA31-AA30 -> 0 | AC31: 773343 | AD31: =AC31-AC30 -> 0 | AE31: =AB31+X31+T31 -> 2 | AF31: =V31+Z31+AD31 -> 681 | AG31: =IF(AE31>0,AF31/AE31,0) -> 340.5 | AI31: =R31-'EDl log'!B29 -> -49803311
A32: ='General information '!F35 -> 0.013 | B32: =SUM(230*A32) -> 2.99 | C32: 43951 | D32: 31633090 | E32: =D32-D31 -> 2376 | F32: 3646395.6 | G32: =F32-F31 -> 1679.2 | H32: 17427416 | I32: =H32-H31 -> 1518 | J32: 28390420 | K32: =J32-J31 -> 1094 | L32: 22942186 | M32: =L32-L31 -> 3506 | N32: =M32+K32+I32+G32+E32 -> 10173.2 | O32: =IF(B32>0,N32/B32,0) -> 3402.408 | P32: 15479.6 | Q32: =(P32-P31)*1000 -> 1770 | R32: =N32-Q32 -> 8403.2 | S32: 8454 | T32: =S32-S31 -> 2 | U32: 40221 | V32: =U32-U31 -> 361 | W32: =W31 -> 31845 | X32: =W32-W31 -> 0 | Y32: =Y31 -> 624440 | Z32: =Y32-Y31 -> 0 | AA32: =AA31 -> 35042 | AB32: =AA32-AA31 -> 0 | AC32: =AC31 -> 773343 | AD32: =AC32-AC31 -> 0 | AE32: =AB32+X32+T32 -> 2 | AF32: =V32+Z32+AD32 -> 361 | AG32: =IF(AE32>0,AF32/AE32,0) -> 180.5 | AI32: =R32-'EDl log'!B30 -> -49806640

Sheet B5
F1: Boiler A | J1: =J35 -> 82.769841 | K1: Boiler B | P1: Boiler C | V1: Boiler | X1: SteamA | AC1: SteamB | AH1: Steam | AI1: Boiler & steam | AL1: Total Boiler Runing H | AM1: Total Steam Runing H | AN1: GAS1 % | AO1: GAS1/L | AP1: GAS2% | AQ1: Gas2/L | AR1: GAS3% | AS1: GAS3/L | AU1: Gas Cons | AV1: Delivery | AW1: Cost/L
B2: Level Tank Gen | C2: Level tank Boiler | D2: Daily Cons Bo. | E2: Boiler litter | F2: Boiler A | G2: Run Hr a | H2: Boiler A fuel | I2: Daily consumption | J2: AVG | K2: index Run H | L2: Run Hrb | M2: Boiler B Fuel | O2: Daily consumption | P2: Boiler C | S2: Run C | U2: Total RH | V2: Total Fuel | X2: SteamA | Y2: Run SA | Z2: Steam A Conter | AA2: Liters | AC2: SteamB | AD2: Run SteamB | AE2: Steam B Conter | AF2: SB Litters | AG2: Avg | AH2: Total Fuel | AI2: Total Fuel
S3: 0
A4: =ELEC!C2 -> 43921 | B4: =[1]B5!B35 -> 252 | C4: =[1]B5!C35 -> 258 | D4: =[1]B5!D35 -> -34 | E4: =[1]B5!E35 -> -284.92 | F4: =[1]B5!F35 -> 1498 | G4: =[1]B5!G35 -> 1 | H4: =[1]B5!H35 -> 346077 | I4: =[1]B5!I35 -> 84 | ... AX4: =[1]B5!AX35 -> 0.7
A5: =ELEC!C3 -> 43922 | B5: 247 | C5: 253 | D5: =C4-C5 -> 5 | E5: =D5*8.38 -> 41.9 | F5: 1499 | G5: =F5-F4 -> 1 | H5: 346155 | I5: =SUM(H5-H4) -> 78 | J5: 1 | K5: 1883 | L5: =K5-K4 -> 4 | M5: 137637 | N5: =M5-M4 -> 189 | O5: =SUM(L5*$J$1) -> 331.07937 | P5: =P4 -> 1727 | Q5: =Q4 -> 147146 | R5: =Q5-Q4 -> 0 | S5: =SUM(P5-P4) -> 0 | T5: =SUM(S5*$T$2) -> 0 | U5: =SUM(G5+L5+S5) -> 5 | V5: =R5+N5+I5:I5 -> 267 | W5: =SUM(V5/U5) -> 53.4 | X5: =X4 -> 2404 | Y5: =X5-X4 -> 0 | Z5: =Z4 -> 135129.3 | AA5: =Z5-Z4 -> 0 | AB5: =SUM(Y5*$AB$2) -> 0 | AC5: =AC4 -> 1824 | AD5: =AC5-AC4 -> 0 | AE5: =AE4 -> 358857.5 | AF5: =AE5-AE4 -> 0 | AG5: =IF(AD5>0,AF5/AD5,0) -> 0 | AH5: =AF5+AA5 -> 0 | AI5: =SUM(AH5+V5) -> 267 | AJ5: =-tanks!AW6 -> 267 | AK5: =SUM(AJ5-AI5) -> 0 | AL5: =S5+L5+G5 -> 5 | AM5: =Y5+AD5 -> 0 | AN5: 71 | AO5: =(AN5/100)*3000 -> 2130 | AP5: 68 | AQ5: =(AP5/100)*3000 -> 2040 | AR5: 65 | AS5: =(AR5/100)*3000 -> 1950 | AT5: =SUM(AO5+AQ5+AS5) -> 6120 | AU5: =AT4-AT5+AV5 -> 60 | AX5: =IF(AV5>0,AW5,AX4) -> 0.7
A6: =ELEC!C4 -> 43923 | B6: 243 | C6: 249 | D6: =C5-C6 -> 4 | E6: =D6*8.38 -> 33.52 | F6: 1499 | G6: =F6-F5 -> 0 | H6: =H5 -> 346155 | I6: =SUM(H6-H5) -> 0 | J6: =IF(G6>0,I6/G6,0) -> 0 | K6: 1883 | L6: =K6-K5 -> 0 | M6: 137775 | N6: =M6-M5 -> 138 | O6: =SUM(L6*$J$1) -> 0 | P6: 1729 | Q6: 147315 | R6: =Q6-Q5 -> 169 | S6: =SUM(P6-P5) -> 2 | T6: =SUM(S6*$T$2) -> 0 | U6: =SUM(G6+L6+S6) -> 2 | V6: =R6+N6+I6:I6 -> 307 | W6: =SUM(V6/U6) -> 153.5 | X6: =X5 -> 2404 | Y6: =X6-X5 -> 0 | Z6: =Z5 -> 135129.3 | AA6: =Z6-Z5 -> 0 | AB6: =SUM(Y6*$AB$2) -> 0 | AC6: =AC5 -> 1824 | AD6: =AC6-AC5 -> 0 | AE6: =AE5 -> 358857.5 | AF6: =AE6-AE5 -> 0 | AG6: =IF(AD6>0,AF6/AD6,0) -> 0 | AH6: =AF6+AA6 -> 0 | AI6: =SUM(AH6+V6) -> 307 | AJ6: =-tanks!AW7 -> 307 | AK6: =SUM(AJ6-AI6) -> 0 | AL6: =S6+L6+G6 -> 2 | AM6: =Y6+AD6 -> 0 | AN6: 68 | AO6: =(AN6/100)*3000 -> 2040 | AP6: 66 | AQ6: =(AP6/100)*3000 -> 1980 | AR6: 64 | AS6: =(AR6/100)*3000 -> 1920 | AT6: =SUM(AO6+AQ6+AS6) -> 5940 | AU6: =AT5-AT6+AV6 -> 180 | AX6: =IF(AV6>0,AW6,AX5) -> 0.7
A7: =ELEC!C5 -> 43924 | B7: 241 | C7: 246 | D7: =C6-C7 -> 3 | E7: =D7*8.38 -> 25.14 | F7: 1502 | G7: =F7-F6 -> 3 | H7: 346351 | I7: =SUM(H7-H6) -> 196 | J7: =IF(G7>0,I7/G7,0) -> 65.333333 | K7: =K6 -> 1883 | L7: =K7-K6 -> 0 | M7: =M6 -> 137775 | N7: =M7-M6 -> 0 | O7: 1 | P7: 1731 | Q7: 147470 | R7: =Q7-Q6 -> 155 | S7: =SUM(P7-P6) -> 2 | T7: =SUM(S7*$T$2) -> 0 | U7: =SUM(G7+L7+S7) -> 5 | V7: =R7+N7+I7:I7 -> 351 | W7: =SUM(V7/U7) -> 70.2 | X7: =X6 -> 2404 | Y7: =X7-X6 -> 0 | Z7: =Z6 -> 135129.3 | AA7: =Z7-Z6 -> 0 | AB7: =SUM(Y7*$AB$2) -> 0 | AC7: =AC6 -> 1824 | AD7: =AC7-AC6 -> 0 | AE7: =AE6 -> 358857.5 | AF7: =AE7-AE6 -> 0 | AG7: =IF(AD7>0,AF7/AD7,0) -> 0 | AH7: =AF7+AA7 -> 0 | AI7: =SUM(AH7+V7) -> 351 | AJ7: =-tanks!AW8 -> 351 | AK7: =SUM(AJ7-AI7) -> 0 | AL7: =S7+L7+G7 -> 5 | AM7: =Y7+AD7 -> 0 | AN7: =AN6 -> 68 | AO7: =(AN7/100)*3000 -> 2040 | AP7: =AP6 -> 66 | AQ7: =(AP7/100)*3000 -> 1980 | AR7: 62 | AS7: =(AR7/100)*3000 -> 1860 | AT7: =SUM(AO7+AQ7+AS7) -> 5880 | AU7: =AT6-AT7+AV7 -> 60 | AX7: =IF(AV7>0,AW7,AX6) -> 0.7
A8: =ELEC!C6 -> 43925 | B8: 239 | C8: 244 | D8: =C7-C8 -> 2 | E8: =D8*8.38 -> 16.76 | F8: 1503 | G8: =F8-F7 -> 1 | H8: 346462 | I8: =SUM(H8-H7) -> 111 | J8: =IF(G8>0,I8/G8,0) -> 111 | K8: 1884 | L8: =K8-K7 -> 1 | M8: 137882 | N8: =M8-M7 -> 107 | O8: 1479 | P8: 1732 | Q8: 147523 | R8: =Q8-Q7 -> 53 | S8: =SUM(P8-P7) -> 1 | T8: =SUM(S8*$T$2) -> 0 | U8: =SUM(G8+L8+S8) -> 3 | V8: =R8+N8+I8:I8 -> 271 | W8: =SUM(V8/U8) -> 90.333333 | X8: 2404 | Y8: =X8-X7 -> 0 | Z8: =Z7 -> 135129.3 | AA8: =Z8-Z7 -> 0 | AB8: =SUM(Y8*$AB$2) -> 0 | AC8: =AC7 -> 1824 | AD8: =AC8-AC7 -> 0 | AE8: =AE7 -> 358857.5 | AF8: =AE8-AE7 -> 0 | AG8: =IF(AD8>0,AF8/AD8,0) -> 0 | AH8: =AF8+AA8 -> 0 | AI8: =SUM(AH8+V8) -> 271 | AJ8: =-tanks!AW9 -> 271 | AK8: =SUM(AJ8-AI8) -> 0 | AL8: =S8+L8+G8 -> 3 | AM8: =Y8+AD8 -> 0 | AN8: 66 | AO8: =(AN8/100)*3000 -> 1980 | AP8: 65 | AQ8: =(AP8/100)*3000 -> 1950 | AR8: 61 | AS8: =(AR8/100)*3000 -> 1830 | AT8: =SUM(AO8+AQ8+AS8) -> 5760 | AU8: =AT7-AT8+AV8 -> 120 | AX8: =IF(AV8>0,AW8,AX7) -> 0.7
A9: =ELEC!C7 -> 43926 | B9: 235 | C9: 241 | D9: =C8-C9 -> 3 | E9: =D9*8.38 -> 25.14 | F9: =F8 -> 1503 | G9: =F9-F8 -> 0 | H9: =H8 -> 346462 | I9: =SUM(H9-H8) -> 0 | J9: =IF(G9>0,I9/G9,0) -> 0 | K9: =K8 -> 1884 | L9: =K9-K8 -> 0 | M9: =M8 -> 137882 | N9: =M9-M8 -> 0 | O9: =SUM(L9*$J$1) -> 0 | P9: 1734 | Q9: 147775 | R9: =Q9-Q8 -> 252 | S9: =SUM(P9-P8) -> 2 | T9: =SUM(S9*$T$2) -> 0 | U9: =SUM(G9+L9+S9) -> 2 | V9: =R9+N9+I9:I9 -> 252 | W9: =SUM(V9/U9) -> 126 | X9: =X8 -> 2404 | Y9: =X9-X8 -> 0 | Z9: =Z8 -> 135129.3 | AA9: =Z9-Z8 -> 0 | AB9: =SUM(Y9*$AB$2) -> 0 | AC9: =AC8 -> 1824 | AD9: =AC9-AC8 -> 0 | AE9: =AE8 -> 358857.5 | AF9: =AE9-AE8 -> 0 | AG9: =IF(AD9>0,AF9/AD9,0) -> 0 | AH9: =AF9+AA9 -> 0 | AI9: =SUM(AH9+V9) -> 252 | AJ9: =-tanks!AW10 -> 252 | AK9: =SUM(AJ9-AI9) -> 0 | AL9: =S9+L9+G9 -> 2 | AM9: =Y9+AD9 -> 0 | AN9: 66 | AO9: =(AN9/100)*3000 -> 1980 | AP9: 65 | AQ9: =(AP9/100)*3000 -> 1950 | AR9: 60 | AS9: =(AR9/100)*3000 -> 1800 | AT9: =SUM(AO9+AQ9+AS9) -> 5730 | AU9: =AT8-AT9+AV9 -> 30 | AX9: =IF(AV9>0,AW9,AX8) -> 0.7
A10: =ELEC!C8 -> 43927 | B10: 233 | C10: 239 | D10: =C9-C10 -> 2 | E10: =D10*8.38 -> 16.76 | F10: 1507 | G10: =F10-F9 -> 4 | H10: 346758 | I10: =SUM(H10-H9) -> 296 | J10: =IF(G10>0,I10/G10,0) -> 74 | K10: 1884 | L10: =K10-K9 -> 0 | M10: 137884 | N10: =M10-M9 -> 2 | O10: =SUM(L10*$J$1) -> 0 | P10: 1737 | Q10: 147921 | R10: =Q10-Q9 -> 146 | S10: =SUM(P10-P9) -> 3 | T10: =SUM(S10*$T$2) -> 0 | U10: =SUM(G10+L10+S10) -> 7 | V10: =R10+N10+I10:I10 -> 444 | W10: =SUM(V10/U10) -> 63.428571 | X10: 2404 | Y10: =X10-X9 -> 0 | Z10: 135129.3 | AA10: =Z10-Z9 -> 0 | AB10: =SUM(Y10*$AB$2) -> 0 | AC10: 1824 | AD10: =AC10-AC9 -> 0 | AE10: 358857.5 | AF10: =AE10-AE9 -> 0 | AG10: =IF(AD10>0,AF10/AD10,0) -> 0 | AH10: =AF10+AA10 -> 0 | AI10: =SUM(AH10+V10) -> 444 | AJ10: =-tanks!AW11 -> 444 | AK10: =SUM(AJ10-AI10) -> 0 | AL10: =S10+L10+G10 -> 7 | AM10: =Y10+AD10 -> 0 | AN10: 65 | AO10: =(AN10/100)*3000 -> 1950 | AP10: 64 | AQ10: =(AP10/100)*3000 -> 1920 | AR10: 60 | AS10: =(AR10/100)*3000 -> 1800 | AT10: =SUM(AO10+AQ10+AS10) -> 5670 | AU10: =AT9-AT10+AV10 -> 60 | AX10: =IF(AV10>0,AW10,AX9) -> 0.7
A11: =ELEC!C9 -> 43928 | B11: 232 | C11: 238 | D11: =C10-C11 -> 1 | E11: =D11*8.38 -> 8.38 | F11: 1507 | G11: =F11-F10 -> 0 | H11: 346759 | I11: =SUM(H11-H10) -> 1 | J11: =IF(G11>0,I11/G11,0) -> 0 | K11: 1886 | L11: =K11-K10 -> 2 | M11: 138047 | N11: =M11-M10 -> 163 | O11: =SUM(L11*$J$1) -> 165.53968 | P11: 1737 | Q11: 147921 | R11: =Q11-Q10 -> 0 | S11: =SUM(P11-P10) -> 0 | T11: =SUM(S11*$T$2) -> 0 | U11: =SUM(G11+L11+S11) -> 2 | V11: =R11+N11+I11:I11 -> 164 | W11: =SUM(V11/U11) -> 82 | X11: 2404 | Y11: =X11-X10 -> 0 | Z11: 135129.3 | AA11: =Z11-Z10 -> 0 | AB11: =SUM(Y11*$AB$2) -> 0 | AC11: 1824 | AD11: =AC11-AC10 -> 0 | AE11: 358857.5 | AF11: =AE11-AE10 -> 0 | AG11: =IF(AD11>0,AF11/AD11,0) -> 0 | AH11: =AF11+AA11 -> 0 | AI11: =SUM(AH11+V11) -> 164 | AJ11: =-tanks!AW12 -> 164 | AK11: =SUM(AJ11-AI11) -> 0 | AL11: =S11+L11+G11 -> 2 | AM11: =Y11+AD11 -> 0 | AN11: =AN10 -> 65 | AO11: =(AN11/100)*3000 -> 1950 | AP11: =AP10 -> 64 | AQ11: =(AP11/100)*3000 -> 1920 | AR11: 59 | AS11: =(AR11/100)*3000 -> 1770 | AT11: =SUM(AO11+AQ11+AS11) -> 5640 | AU11: =AT10-AT11+AV11 -> 30 | AX11: =IF(AV11>0,AW11,AX10) -> 0.7
A12: =ELEC!C10 -> 43929 | B12: 229 | C12: 235 | D12: =C11-C12 -> 3 | E12: =D12*8.38 -> 25.14 | F12: 1507 | G12: =F12-F11 -> 0 | H12: 346759 | I12: =SUM(H12-H11) -> 0 | J12: =IF(G12>0,I12/G12,0) -> 0 | K12: 1888 | L12: =K12-K11 -> 2 | M12: 138172 | N12: =M12-M11 -> 125 | O12: =SUM(L12*$J$1) -> 165.53968 | P12: 1739 | Q12: 148101 | R12: =Q12-Q11 -> 180 | S12: =SUM(P12-P11) -> 2 | T12: =SUM(S12*$T$2) -> 0 | U12: =SUM(G12+L12+S12) -> 4 | V12: =R12+N12+I12:I12 -> 305 | W12: =SUM(V12/U12) -> 76.25 | X12: 2404 | Y12: =X12-X11 -> 0 | Z12: 135129.3 | AA12: =Z12-Z11 -> 0 | AB12: =SUM(Y12*$AB$2) -> 0 | AC12: 1824 | AD12: =AC12-AC11 -> 0 | AE12: 358857.5 | AF12: =AE12-AE11 -> 0 | AG12: =IF(AD12>0,AF12/AD12,0) -> 0 | AH12: =AF12+AA12 -> 0 | AI12: =SUM(AH12+V12) -> 305 | AJ12: =-tanks!AW13 -> 305 | AK12: =SUM(AJ12-AI12) -> 0 | AL12: =S12+L12+G12 -> 4 | AM12: =Y12+AD12 -> 0 | AN12: 64 | AO12: =(AN12/100)*3000 -> 1920 | AP12: 62 | AQ12: =(AP12/100)*3000 -> 1860 | AR12: 58 | AS12: =(AR12/100)*3000 -> 1740 | AT12: =SUM(AO12+AQ12+AS12) -> 5520 | AU12: =AT11-AT12+AV12 -> 120 | AX12: =IF(AV12>0,AW12,AX11) -> 0.7
A13: =ELEC!C11 -> 43930 | B13: 225 | C13: 231 | D13: =C12-C13 -> 4 | E13: =D13*8.38 -> 33.52 | F13: 1509 | G13: =F13-F12 -> 2 | H13: 346954 | I13: =SUM(H13-H12) -> 195 | J13: =IF(G13>0,I13/G13,0) -> 97.5 | K13: =K12 -> 1888 | L13: =K13-K12 -> 0 | M13: =M12 -> 138172 | N13: =M13-M12 -> 0 | O13: =SUM(L13*$J$1) -> 0 | P13: 1742 | Q13: 148290 | R13: =Q13-Q12 -> 189 | S13: =SUM(P13-P12) -> 3 | T13: =SUM(S13*$T$2) -> 0 | U13: =SUM(G13+L13+S13) -> 5 | V13: =R13+N13+I13:I13 -> 384 | W13: =SUM(V13/U13) -> 76.8 | X13: 2408 | Y13: =X13-X12 -> 4 | Z13: 135361 | AA13: =Z13-Z12 -> 231.7 | AB13: =SUM(Y13*$AB$2) -> 0 | AC13: =AC12 -> 1824 | AD13: =AC13-AC12 -> 0 | AE13: =AE12 -> 358857.5 | AF13: =AE13-AE12 -> 0 | AG13: =IF(AD13>0,AF13/AD13,0) -> 0 | AH13: =AF13+AA13 -> 231.7 | AI13: =SUM(AH13+V13) -> 615.7 | AJ13: =-tanks!AW14 -> 615.7 | AK13: =SUM(AJ13-AI13) -> 0 | AL13: =S13+L13+G13 -> 5 | AM13: =Y13+AD13 -> 4 | AN13: 80 | AO13: =(AN13/100)*3000 -> 2400 | AP13: 68 | AQ13: =(AP13/100)*3000 -> 2040 | AR13: 59 | AS13: =(AR13/100)*3000 -> 1770 | AT13: =SUM(AO13+AQ13+AS13) -> 6210 | AU13: =AT12-AT13+AV13 -> 310 | AV13: 1000 | AW13: 0.7 | AX13: =IF(AV13>0,AW13,AX12) -> 0.7
A14: =ELEC!C12 -> 43931 | B14: 221 | C14: 228 | D14: =C13-C14 -> 3 | E14: =D14*8.38 -> 25.14 | F14: 1511 | G14: =F14-F13 -> 2 | H14: 347085 | I14: =SUM(H14-H13) -> 131 | J14: =IF(G14>0,I14/G14,0) -> 65.5 | K14: 1892 | L14: =K14-K13 -> 4 | M14: 138467 | N14: =M14-M13 -> 295 | O14: =SUM(L14*$J$1) -> 331.07937 | P14: =P13 -> 1742 | Q14: =Q13 -> 148290 | R14: =Q14-Q13 -> 0 | S14: =SUM(P14-P13) -> 0 | T14: =SUM(S14*$T$2) -> 0 | U14: =SUM(G14+L14+S14) -> 6 | V14: =R14+N14+I14:I14 -> 426 | W14: =SUM(V14/U14) -> 71 | X14: =X13 -> 2408 | Y14: =X14-X13 -> 0 | Z14: =Z13 -> 135361 | AA14: =Z14-Z13 -> 0 | AB14: =SUM(Y14*$AB$2) -> 0 | AC14: =AC13 -> 1824 | AD14: =AC14-AC13 -> 0 | AE14: =AE13 -> 358857.5 | AF14: =AE14-AE13 -> 0 | AG14: =IF(AD14>0,AF14/AD14,0) -> 0 | AH14: =AF14+AA14 -> 0 | AI14: =SUM(AH14+V14) -> 426 | AJ14: =-tanks!AW15 -> 426 | AK14: =SUM(AJ14-AI14) -> 0 | AL14: =S14+L14+G14 -> 6 | AM14: =Y14+AD14 -> 0 | AN14: 79 | AO14: =(AN14/100)*3000 -> 2370 | AP14: 67 | AQ14: =(AP14/100)*3000 -> 2010 | AR14: 58 | AS14: =(AR14/100)*3000 -> 1740 | AT14: =SUM(AO14+AQ14+AS14) -> 6120 | AU14: =AT13-AT14+AV14 -> 90 | AX14: =IF(AV14>0,AW14,AX13) -> 0.7
A15: =ELEC!C13 -> 43932 | B15: 219 | C15: 225 | D15: =C14-C15 -> 3 | E15: =D15*8.38 -> 25.14 | F15: =F14 -> 1511 | G15: =F15-F14 -> 0 | H15: =H14 -> 347085 | I15: =SUM(H15-H14) -> 0 | J15: =IF(G15>0,I15/G15,0) -> 0 | K15: 1893 | L15: =K15-K14 -> 1 | M15: 138552 | N15: =M15-M14 -> 85 | O15: =SUM(L15*$J$1) -> 82.769841 | P15: 1743 | Q15: 148399 | R15: =Q15-Q14 -> 109 | S15: =SUM(P15-P14) -> 1 | T15: =SUM(S15*$T$2) -> 0 | U15: =SUM(G15+L15+S15) -> 2 | V15: =R15+N15+I15:I15 -> 194 | W15: =SUM(V15/U15) -> 97 | X15: =X14 -> 2408 | Y15: =X15-X14 -> 0 | Z15: =Z14 -> 135361 | AA15: =Z15-Z14 -> 0 | AB15: =SUM(Y15*$AB$2) -> 0 | AC15: =AC14 -> 1824 | AD15: =AC15-AC14 -> 0 | AE15: =AE14 -> 358857.5 | AF15: =AE15-AE14 -> 0 | AG15: =IF(AD15>0,AF15/AD15,0) -> 0 | AH15: =AF15+AA15 -> 0 | AI15: =SUM(AH15+V15) -> 194 | AJ15: =-tanks!AW16 -> 194 | AK15: =SUM(AJ15-AI15) -> 0 | AL15: =S15+L15+G15 -> 2 | AM15: =Y15+AD15 -> 0 | AN15: 79 | AO15: =(AN15/100)*3000 -> 2370 | AP15: 66 | AQ15: =(AP15/100)*3000 -> 1980 | AR15: 57 | AS15: =(AR15/100)*3000 -> 1710 | AT15: =SUM(AO15+AQ15+AS15) -> 6060 | AU15: =AT14-AT15+AV15 -> 60 | AX15: =IF(AV15>0,AW15,AX14) -> 0.7
A16: =ELEC!C14 -> 43933 | B16: 216 | C16: 223 | D16: =C15-C16 -> 2 | E16: =D16*8.38 -> 16.76 | F16: 1512 | G16: =F16-F15 -> 1 | H16: 347211 | I16: =SUM(H16-H15) -> 126 | J16: =IF(G16>0,I16/G16,0) -> 126 | K16: =K15 -> 1893 | L16: =K16-K15 -> 0 | M16: =M15 -> 138552 | N16: =M16-M15 -> 0 | O16: =SUM(L16*$J$1) -> 0 | P16: 1745 | Q16: 148581 | R16: =Q16-Q15 -> 182 | S16: =SUM(P16-P15) -> 2 | T16: =SUM(S16*$T$2) -> 0 | U16: =SUM(G16+L16+S16) -> 3 | V16: =R16+N16+I16:I16 -> 308 | W16: =SUM(V16/U16) -> 102.66667 | X16: =X15 -> 2408 | Y16: =X16-X15 -> 0 | Z16: =Z15 -> 135361 | AA16: =Z16-Z15 -> 0 | AB16: =SUM(Y16*$AB$2) -> 0 | AC16: =AC15 -> 1824 | AD16: =AC16-AC15 -> 0 | AE16: =AE15 -> 358857.5 | AF16: =AE16-AE15 -> 0 | AG16: =IF(AD16>0,AF16/AD16,0) -> 0 | AH16: =AF16+AA16 -> 0 | AI16: =SUM(AH16+V16) -> 308 | AJ16: =-tanks!AW17 -> 308 | AK16: =SUM(AJ16-AI16) -> 0 | AL16: =S16+L16+G16 -> 3 | AM16: =Y16+AD16 -> 0 | AN16: 78 | AO16: =(AN16/100)*3000 -> 2340 | AP16: 65 | AQ16: =(AP16/100)*3000 -> 1950 | AR16: 55 | AS16: =(AR16/100)*3000 -> 1650 | AT16: =SUM(AO16+AQ16+AS16) -> 5940 | AU16: =AT15-AT16+AV16 -> 120 | AX16: =IF(AV16>0,AW16,AX15) -> 0.7
A17: =ELEC!C15 -> 43934 | B17: 212 | C17: 219 | D17: =C16-C17 -> 4 | E17: =D17*8.38 -> 33.52 | F17: 1515 | G17: =F17-F16 -> 3 | H17: 347403 | I17: =SUM(H17-H16) -> 192 | J17: =IF(G17>0,I17/G17,0) -> 64 | K17: 1896 | L17: =K17-K16 -> 3 | M17: 138771 | N17: =M17-M16 -> 219 | O17: =SUM(L17*$J$1) -> 248.30952 | P17: =P16 -> 1745 | Q17: =Q16 -> 148581 | R17: =Q17-Q16 -> 0 | S17: =SUM(P17-P16) -> 0 | T17: =SUM(S17*$T$2) -> 0 | U17: =SUM(G17+L17+S17) -> 6 | V17: =R17+N17+I17:I17 -> 411 | X17: =X16 -> 2408 | Y17: =X17-X16 -> 0 | Z17: =Z16 -> 135361 | AA17: =Z17-Z16 -> 0 | AB17: =SUM(Y17*$AB$2) -> 0 | AC17: =AC16 -> 1824 | AD17: =AC17-AC16 -> 0 | AE17: =AE16 -> 358857.5 | AF17: =AE17-AE16 -> 0 | AG17: =IF(AD17>0,AF17/AD17,0) -> 0 | AH17: =AF17+AA17 -> 0 | AI17: =SUM(AH17+V17) -> 411 | AJ17: =-tanks!AW18 -> 411 | AK17: =SUM(AJ17-AI17) -> 0 | AL17: =S17+L17+G17 -> 6 | AM17: =Y17+AD17 -> 0 | AN17: 76 | AO17: =(AN17/100)*3000 -> 2280 | AP17: =AP16 -> 65 | AQ17: =(AP17/100)*3000 -> 1950 | AR17: =AR16 -> 55 | AS17: =(AR17/100)*3000 -> 1650 | AT17: =SUM(AO17+AQ17+AS17) -> 5880 | AU17: =AT16-AT17+AV17 -> 60 | AX17: =IF(AV17>0,AW17,AX16) -> 0.7
A18: =ELEC!C16 -> 43935 | B18: 210 | C18: 216.4 | D18: =C17-C18 -> 2.6 | E18: =D18*8.38 -> 21.788 | F18: 1517 | G18: =F18-F17 -> 2 | H18: 347551 | I18: =SUM(H18-H17) -> 148 | J18: =IF(G18>0,I18/G18,0) -> 74 | K18: 1897 | L18: =K18-K17 -> 1 | M18: 138858 | N18: =M18-M17 -> 87 | O18: =SUM(L18*$J$1) -> 82.769841 | P18: 1745 | Q18: 148581 | R18: =Q18-Q17 -> 0 | S18: =SUM(P18-P17) -> 0 | T18: =SUM(S18*$T$2) -> 0 | U18: =SUM(G18+L18+S18) -> 3 | V18: =R18+N18+I18:I18 -> 235 | X18: 2408 | Y18: =X18-X17 -> 0 | Z18: 135361 | AA18: =Z18-Z17 -> 0 | AB18: =SUM(Y18*$AB$2) -> 0 | AC18: 1824 | AD18: =AC18-AC17 -> 0 | AE18: 358857.5 | AF18: =AE18-AE17 -> 0 | AG18: =IF(AD18>0,AF18/AD18,0) -> 0 | AH18: =AF18+AA18 -> 0 | AI18: =SUM(AH18+V18) -> 235 | AJ18: =-tanks!AW19 -> 235 | AK18: =SUM(AJ18-AI18) -> 0 | AL18: =S18+L18+G18 -> 3 | AM18: =Y18+AD18 -> 0 | AN18: 74 | AO18: =(AN18/100)*3000 -> 2220 | AP18: 65 | AQ18: =(AP18/100)*3000 -> 1950 | AR18: 55 | AS18: =(AR18/100)*3000 -> 1650 | AT18: =SUM(AO18+AQ18+AS18) -> 5820 | AU18: =AT17-AT18+AV18 -> 60 | AX18: =IF(AV18>0,AW18,AX17) -> 0.7
A19: =ELEC!C17 -> 43936 | B19: 243 | C19: 249 | D19: =C18-C19 -> -32.6 | E19: =D19*8.38 -> -273.188 | F19: 1518 | G19: =F19-F18 -> 1 | H19: 347688 | I19: =SUM(H19-H18) -> 137 | J19: =IF(G19>0,I19/G19,0) -> 137 | K19: 1899 | L19: =K19-K18 -> 2 | M19: 139036 | N19: =M19-M18 -> 178 | O19: =SUM(L19*$J$1) -> 165.53968 | P19: 1745 | Q19: 148581 | R19: =Q19-Q18 -> 0 | S19: =SUM(P19-P18) -> 0 | T19: =SUM(S19*$T$2) -> 0 | U19: =SUM(G19+L19+S19) -> 3 | V19: =R19+N19+I19:I19 -> 315 | X19: 2412 | Y19: =X19-X18 -> 4 | Z19: 135583 | AA19: =Z19-Z18 -> 222 | AB19: =SUM(Y19*$AB$2) -> 0 | AC19: 1824 | AD19: =AC19-AC18 -> 0 | AE19: 358857.5 | AF19: =AE19-AE18 -> 0 | AG19: =IF(AD19>0,AF19/AD19,0) -> 0 | AH19: =AF19+AA19 -> 222 | AI19: =SUM(AH19+V19) -> 537 | AJ19: =-tanks!AW20 -> 537 | AK19: =SUM(AJ19-AI19) -> 0 | AL19: =S19+L20+G19 -> 3 | AM19: =Y19+AD19 -> 4 | AN19: 72 | AO19: =(AN19/100)*3000 -> 2160 | AP19: 64 | AQ19: =(AP19/100)*3000 -> 1920 | AR19: 55 | AS19: =(AR19/100)*3000 -> 1650 | AT19: =SUM(AO19+AQ19+AS19) -> 5730 | AU19: =AT18-AT19+AV19 -> 90 | AX19: =IF(AV19>0,AW19,AX18) -> 0.7
A20: =ELEC!C18 -> 43937 | B20: 241 | C20: 247 | D20: =C19-C20 -> 2 | E20: =D20*8.38 -> 16.76 | F20: 1518 | G20: =F20-F19 -> 0 | H20: =H19 -> 347688 | I20: =SUM(H20-H19) -> 0 | J20: =IF(G20>0,I20/G20,0) -> 0 | K20: 1901 | L20: =K20-K19 -> 2 | M20: 139183 | N20: =M20-M19 -> 147 | O20: =SUM(L20*$J$1) -> 165.53968 | P20: 1748 | Q20: 148774 | R20: =Q20-Q19 -> 193 | S20: =SUM(P20-P19) -> 3 | T20: =SUM(S20*$T$2) -> 0 | U20: =SUM(G20+L20+S20) -> 5 | V20: =R20+N20+I20:I20 -> 340 | X20: =X19 -> 2412 | Y20: =X20-X19 -> 0 | Z20: =Z19 -> 135583 | AA20: =Z20-Z19 -> 0 | AB20: =SUM(Y20*$AB$2) -> 0 | AC20: =AC19 -> 1824 | AD20: =AC20-AC19 -> 0 | AE20: =AE19 -> 358857.5 | AF20: =AE20-AE19 -> 0 | AG20: =IF(AD20>0,AF20/AD20,0) -> 0 | AH20: =AF20+AA20 -> 0 | AI20: =SUM(AH20+V20) -> 340 | AJ20: =-tanks!AW21 -> 340 | AK20: =SUM(AJ20-AI20) -> 0 | AL20: =S20+L21+G20 -> 3 | AM20: =Y20+AD20 -> 0 | AN20: 81 | AO20: =(AN20/100)*3000 -> 2430 | AP20: 65 | AQ20: =(AP20/100)*3000 -> 1950 | AR20: 71 | AS20: =(AR20/100)*3000 -> 2130 | AT20: =SUM(AO20+AQ20+AS20) -> 6510 | AU20: =AT19-AT20+AV20 -> 220 | AV20: 1000 | AW20: 0.7 | AX20: =IF(AV20>0,AW20,AX19) -> 0.7
A21: =ELEC!C19 -> 43938 | B21: 238 | C21: 244 | D21: =C20-C21 -> 3 | E21: =D21*8.38 -> 25.14 | F21: 1520 | G21: =F21-F20 -> 2 | H21: 347826 | I21: =SUM(H21-H20) -> 138 | J21: =IF(G21>0,I21/G21,0) -> 69 | K21: =K20 -> 1901 | L21: =K21-K20 -> 0 | M21: =M20 -> 139183 | N21: =M21-M20 -> 0 | O21: =SUM(L21*$J$1) -> 0 | P21: 1749 | Q21: 148883 | R21: =Q21-Q20 -> 109 | S21: =SUM(P21-P20) -> 1 | T21: =SUM(S21*$T$2) -> 0 | U21: =SUM(G21+L21+S21) -> 3 | V21: =R21+N21+I21:I21 -> 247 | X21: =X20 -> 2412 | Y21: =X21-X20 -> 0 | Z21: =Z20 -> 135583 | AA21: =Z21-Z20 -> 0 | AB21: =SUM(Y21*$AB$2) -> 0 | AC21: =AC20 -> 1824 | AD21: =AC21-AC20 -> 0 | AE21: =AE20 -> 358857.5 | AF21: =AE21-AE20 -> 0 | AG21: =IF(AD21>0,AF21/AD21,0) -> 0 | AH21: =AF21+AA21 -> 0 | AI21: =SUM(AH21+V21) -> 247 | AJ21: =-tanks!AW22 -> 247 | AK21: =SUM(AJ21-AI21) -> 0 | AL21: =S21+L21+G21 -> 3 | AM21: =Y21+AD21 -> 0 | AN21: 80 | AO21: =(AN21/100)*3000 -> 2400 | AP21: 65 | AQ21: =(AP21/100)*3000 -> 1950 | AR21: 70 | AS21: =(AR21/100)*3000 -> 2100 | AT21: =SUM(AO21+AQ21+AS21) -> 6450 | AU21: =AT20-AT21+AV21 -> 60 | AX21: =IF(AV21>0,AW21,AX20) -> 0.7
A22: =ELEC!C20 -> 43939 | B22: 235 | C22: 241 | D22: =C21-C22 -> 3 | E22: =D22*8.38 -> 25.14 | F22: 1522 | G22: =F22-F21 -> 2 | H22: 347921 | I22: =SUM(H22-H21) -> 95 | J22: =IF(G22>0,I22/G22,0) -> 47.5 | K22: 1904 | L22: =K22-K21 -> 3 | M22: 139383 | N22: =M22-M21 -> 200 | O22: =SUM(L22*$J$1) -> 248.30952 | P22: 1749 | Q22: =Q21 -> 148883 | R22: =Q22-Q21 -> 0 | S22: =SUM(P22-P21) -> 0 | T22: =SUM(S22*$T$2) -> 0 | U22: =SUM(G22+L22+S22) -> 5 | V22: =R22+N22+I22:I22 -> 295 | X22: =X21 -> 2412 | Y22: =X22-X21 -> 0 | Z22: =Z21 -> 135583 | AA22: =Z22-Z21 -> 0 | AB22: =SUM(Y22*$AB$2) -> 0 | AC22: =AC21 -> 1824 | AD22: =AC22-AC21 -> 0 | AE22: =AE21 -> 358857.5 | AF22: =AE22-AE21 -> 0 | AG22: =IF(AD22>0,AF22/AD22,0) -> 0 | AH22: =AF22+AA22 -> 0 | AI22: =SUM(AH22+V22) -> 295 | AJ22: =-tanks!AW23 -> 295 | AK22: =SUM(AJ22-AI22) -> 0 | AL22: =S22+L22+G22 -> 5 | AM22: =Y22+AD22 -> 0 | AN22: 78 | AO22: =(AN22/100)*3000 -> 2340 | AP22: 64 | AQ22: =(AP22/100)*3000 -> 1920 | AR22: 69 | AS22: =(AR22/100)*3000 -> 2070 | AT22: =SUM(AO22+AQ22+AS22) -> 6330 | AU22: =AT21-AT22+AV22 -> 120 | AX22: =IF(AV22>0,AW22,AX21) -> 0.7
A23: =ELEC!C21 -> 43940 | B23: 233 | C23: 239 | D23: =C22-C23 -> 2 | E23: =D23*8.38 -> 16.76 | F23: 1523 | G23: =F23-F22 -> 1 | H23: 348083 | I23: =SUM(H23-H22) -> 162 | J23: =IF(G23>0,I23/G23,0) -> 162 | K23: 1905 | L23: =K23-K22 -> 1 | M23: 139447 | N23: =M23-M22 -> 64 | O23: =SUM(L23*$J$1) -> 82.769841 | P23: 1751 | Q23: 148980 | R23: =Q23-Q22 -> 97 | S23: =SUM(P23-P22) -> 2 | T23: =SUM(S23*$T$2) -> 0 | U23: =SUM(G23+L23+S23) -> 4 | V23: =R23+N23+I23:I23 -> 323 | X23: =X22 -> 2412 | Y23: =X23-X22 -> 0 | Z23: =Z22 -> 135583 | AA23: =Z23-Z22 -> 0 | AB23: =SUM(Y23*$AB$2) -> 0 | AC23: =AC22 -> 1824 | AD23: =AC23-AC22 -> 0 | AE23: =AE22 -> 358857.5 | AF23: =AE23-AE22 -> 0 | AG23: =IF(AD23>0,AF23/AD23,0) -> 0 | AH23: =AF23+AA23 -> 0 | AI23: =SUM(AH23+V23) -> 323 | AJ23: =-tanks!AW24 -> 323 | AK23: =SUM(AJ23-AI23) -> 0 | AL23: =S23+L23+G23 -> 4 | AM23: =Y23+AD23 -> 0 | AN23: 77 | AO23: =(AN23/100)*3000 -> 2310 | AP23: 63 | AQ23: =(AP23/100)*3000 -> 1890 | AR23: 68 | AS23: =(AR23/100)*3000 -> 2040 | AT23: =SUM(AO23+AQ23+AS23) -> 6240 | AU23: =AT22-AT23+AV23 -> 90 | AX23: =IF(AV23>0,AW23,AX22) -> 0.7
A24: =ELEC!C22 -> 43941 | B24: 231 | C24: 238 | D24: =C23-C24 -> 1 | E24: =D24*8.38 -> 8.38 | F24: 1526 | G24: =F24-F23 -> 3 | H24: 348336 | I24: =SUM(H24-H23) -> 253 | J24: =IF(G24>0,I24/G24,0) -> 84.333333 | K24: 1905 | L24: =K24-K23 -> 0 | M24: =M23 -> 139447 | N24: =M24-M23 -> 0 | O24: =SUM(L24*$J$1) -> 0 | P24: 1752 | Q24: 149093 | R24: =Q24-Q23 -> 113 | S24: =SUM(P24-P23) -> 1 | T24: =SUM(S24*$T$2) -> 0 | U24: =SUM(G24+L24+S24) -> 4 | V24: =R24+N24+I24:I24 -> 366 | X24: 2412 | Y24: =X24-X23 -> 0 | Z24: =Z23 -> 135583 | AA24: =Z24-Z23 -> 0 | AB24: =SUM(Y24*$AB$2) -> 0 | AC24: =AC23 -> 1824 | AD24: =AC24-AC23 -> 0 | AE24: =AE23 -> 358857.5 | AF24: =AE24-AE23 -> 0 | AG24: =IF(AD24>0,AF24/AD24,0) -> 0 | AH24: =AF24+AA24 -> 0 | AI24: =SUM(AH24+V24) -> 366 | AJ24: =-tanks!AW25 -> 366 | AK24: =SUM(AJ24-AI24) -> 0 | AL24: =S24+L24+G24 -> 4 | AM24: =Y24+AD24 -> 0 | AN24: 75 | AO24: =(AN24/100)*3000 -> 2250 | AP24: =AP23 -> 63 | AQ24: =(AP24/100)*3000 -> 1890 | AR24: =AR23 -> 68 | AS24: =(AR24/100)*3000 -> 2040 | AT24: =SUM(AO24+AQ24+AS24) -> 6180 | AU24: =AT23-AT24+AV24 -> 60 | AX24: =IF(AV24>0,AW24,AX23) -> 0.7
A25: =ELEC!C23 -> 43942 | B25: 229 | C25: 235 | D25: =C24-C25 -> 3 | E25: =D25*8.38 -> 25.14 | F25: 1527 | G25: =F25-F24 -> 1 | H25: 348382 | I25: =SUM(H25-H24) -> 46 | J25: =IF(G25>0,I25/G25,0) -> 46 | K25: 1907 | L25: =K25-K24 -> 2 | M25: 139626 | N25: =M25-M24 -> 179 | O25: =SUM(L25*$J$1) -> 165.53968 | P25: =P24 -> 1752 | Q25: 149093 | R25: =Q25-Q24 -> 0 | S25: =SUM(P25-P24) -> 0 | T25: =SUM(S25*$T$2) -> 0 | U25: =SUM(G25+L25+S25) -> 3 | V25: =R25+N25+I25:I25 -> 225 | X25: 2412 | Y25: =X25-X24 -> 0 | Z25: 135583 | AA25: =Z25-Z24 -> 0 | AB25: =SUM(Y25*$AB$2) -> 0 | AC25: 1824 | AD25: =AC25-AC24 -> 0 | AE25: =AE24 -> 358857.5 | AF25: =AE25-AE24 -> 0 | AG25: =IF(AD25>0,AF25/AD25,0) -> 0 | AH25: =AF25+AA25 -> 0 | AI25: =SUM(AH25+V25) -> 225 | AJ25: =-tanks!AW26 -> 225 | AK25: =SUM(AJ25-AI25) -> 0 | AL25: =S25+L25+G25 -> 3 | AM25: =Y25+AD25 -> 0 | AN25: 74 | AO25: =(AN25/100)*3000 -> 2220 | AP25: 63 | AQ25: =(AP25/100)*3000 -> 1890 | AR25: 68 | AS25: =(AR25/100)*3000 -> 2040 | AT25: =SUM(AO25+AQ25+AS25) -> 6150 | AU25: =AT24-AT25+AV25 -> 30 | AX25: =IF(AV25>0,AW25,AX24) -> 0.7
A26: =ELEC!C24 -> 43943 | B26: 226 | C26: 232 | D26: =C25-C26 -> 3 | E26: =D26*8.38 -> 25.14 | F26: 1527 | G26: =F26-F25 -> 0 | H26: 348382 | I26: =SUM(H26-H25) -> 0 | J26: =IF(G26>0,I26/G26,0) -> 0 | K26: 1909 | L26: =K26-K25 -> 2 | M26: 139745 | N26: =M26-M25 -> 119 | O26: =SUM(L26*$J$1) -> 165.53968 | P26: 1755 | Q26: 149319 | R26: =Q26-Q25 -> 226 | S26: =SUM(P26-P25) -> 3 | T26: =SUM(S26*$T$2) -> 0 | U26: =SUM(G26+L26+S26) -> 5 | V26: =R26+N26+I26:I26 -> 345 | X26: 2412 | Y26: =X26-X25 -> 0 | Z26: 135583 | AA26: =Z26-Z25 -> 0 | AB26: =SUM(Y26*$AB$2) -> 0 | AC26: 1824 | AD26: =AC26-AC25 -> 0 | AE26: 358857.5 | AF26: =AE26-AE25 -> 0 | AG26: =IF(AD26>0,AF26/AD26,0) -> 0 | AH26: =AF26+AA26 -> 0 | AI26: =SUM(AH26+V26) -> 345 | AJ26: =-tanks!AW27 -> 345 | AK26: =SUM(AJ26-AI26) -> 0 | AL26: =S26+L26+G26 -> 5 | AM26: =Y26+AD26 -> 0 | AN26: 71 | AO26: =(AN26/100)*3000 -> 2130 | AP26: 62 | AQ26: =(AP26/100)*3000 -> 1860 | AR26: 67 | AS26: =(AR26/100)*3000 -> 2010 | AT26: =SUM(AO26+AQ26+AS26) -> 6000 | AU26: =AT25-AT26+AV26 -> 150 | AX26: =IF(AV26>0,AW26,AX25) -> 0.7
A27: =ELEC!C25 -> 43944 | B27: 221 | C27: 227 | D27: =C26-C27 -> 5 | E27: =D27*8.38 -> 41.9 | F27: 1529 | G27: =F27-F26 -> 2 | H27: 348527 | I27: =SUM(H27-H26) -> 145 | J27: =IF(G27>0,I27/G27,0) -> 72.5 | K27: =K26 -> 1909 | L27: =K27-K26 -> 0 | M27: =M26 -> 139745 | N27: =M27-M26 -> 0 | O27: =SUM(L27*$J$1) -> 0 | P27: 1756 | Q27: 149373 | R27: =Q27-Q26 -> 54 | S27: =SUM(P27-P26) -> 1 | T27: =SUM(S27*$T$2) -> 0 | U27: =SUM(G27+L27+S27) -> 3 | V27: =R27+N27+I27:I27 -> 199 | X27: 2417 | Y27: =X27-X26 -> 5 | Z27: 135840 | AA27: =Z27-Z26 -> 257 | AB27: =SUM(Y27*$AB$2) -> 0 | AC27: =AC26 -> 1824 | AD27: =AC27-AC26 -> 0 | AE27: =AE26 -> 358857.5 | AF27: =AE27-AE26 -> 0 | AG27: =IF(AD27>0,AF27/AD27,0) -> 0 | AH27: =AF27+AA27 -> 257 | AI27: =SUM(AH27+V27) -> 456 | AJ27: =-tanks!AW28 -> 456 | AK27: =SUM(AJ27-AI27) -> 0 | AL27: =S27+L27+G27 -> 3 | AM27: =Y27+AD27 -> 5 | AN27: 68 | AO27: =(AN27/100)*3000 -> 2040 | AP27: 61 | AQ27: =(AP27/100)*3000 -> 1830 | AR27: 65 | AS27: =(AR27/100)*3000 -> 1950 | AT27: =SUM(AO27+AQ27+AS27) -> 5820 | AU27: =AT26-AT27+AV27 -> 180 | AX27: =IF(AV27>0,AW27,AX26) -> 0.7
