Workbook

Sheet Total
A1: Site Name | B1: Day | C1: Month | D1: Year | E1: Total Electricity Kwh | F1: Electricity Tariff ($/Kwh) | G1: Total Fuel Oil (Liters) | H1: Fuel Oil $/Liter | I1: LPG (Kg) | J1: LPG $/Kg | K1: Water Utility Supply (m3) m3 | L1: Water Utility Supply (m3) $/m3 | M1: Irrigation Water (m3) m3 | N1: Irrigation water $/m3 | O1: Room Nights
A2: Beirut | B2: 1 | C2: 5 | D2: 2020 | E2: =ELEC!N3 -> 8802.4 | F2: =SUM('EDl log'!T4) -> 0.042144973 | G2: =-tanks!AW6 -> 349 | H2: =SUM(tanks!AV6) -> 0 | I2: =('B5'!AU5)*0.51 -> 30.6 | J2: ='B5'!AX5/0.51 -> 1.372549 | K2: =WATER!I6 -> 0 | L2: =SUM(WATER!J6) -> 0 | M2: =WATER!Q6 -> 0 | N2: 0.6 | O2: =ELEC!B3 -> 10.005
A3: Beirut | B3: =B2+1 -> 2 | C3: 5 | D3: 2020 | E3: =ELEC!N4 -> 8701.6 | F3: =SUM('EDl log'!T5) -> 0.042124556 | G3: =-tanks!AW7 -> 249 | H3: =SUM(tanks!AV7) -> 0 | I3: =('B5'!AU6)*0.51 -> 0 | J3: ='B5'!AX6/0.51 -> 1.372549 | K3: =WATER!I7 -> 0 | L3: =SUM(WATER!J7) -> 0 | M3: =WATER!Q7 -> 0 | N3: 0.6 | O3: =ELEC!B4 -> 8.97
A4: Beirut | B4: =B3+1 -> 3 | C4: 5 | D4: 2020 | E4: =ELEC!N5 -> 11338.4 | F4: =SUM('EDl log'!T6) -> 0.040860614 | G4: =-tanks!AW8 -> 288.5 | H4: =SUM(tanks!AV8) -> 0 | I4: =('B5'!AU7)*0.51 -> 76.5 | J4: ='B5'!AX7/0.51 -> 1.372549 | K4: =WATER!I8 -> 340 | L4: =SUM(WATER!J8) -> 0.71157495 | M4: =WATER!Q8 -> 0 | N4: 0.6 | O4: =ELEC!B5 -> 6.003
A5: Beirut | B5: =B4+1 -> 4 | C5: 5 | D5: 2020 | E5: =ELEC!N6 -> 10592 | F5: =SUM('EDl log'!T7) -> 0.038565461 | G5: =-tanks!AW9 -> 657.9 | H5: =SUM(tanks!AV9) -> 0 | I5: =('B5'!AU8)*0.51 -> 122.4 | J5: ='B5'!AX8/0.51 -> 1.372549 | K5: =WATER!I9 -> 0 | L5: =SUM(WATER!J9) -> 0 | M5: =WATER!Q9 -> 0 | N5: 0.6 | O5: =ELEC!B6 -> 2.001
A6: Beirut | B6: =B5+1 -> 5 | C6: 5 | D6: 2020 | E6: =ELEC!N7 -> 0 | F6: =SUM('EDl log'!T8) -> 0 | G6: =-tanks!AW10 -> 0 | H6: =SUM(tanks!AV10) -> 0 | I6: =('B5'!AU9)*0.51 -> 0 | J6: ='B5'!AX9/0.51 -> 1.372549 | K6: =WATER!I10 -> 0 | L6: =SUM(WATER!J10) -> 0 | M6: =WATER!Q10 -> 0 | N6: 0.6 | O6: =ELEC!B7 -> 0
A7: Beirut | B7: =B6+1 -> 6 | C7: 5 | D7: 2020 | E7: =ELEC!N8 -> 0 | F7: =SUM('EDl log'!T9) -> 0 | G7: =-tanks!AW11 -> 0 | H7: =SUM(tanks!AV11) -> 0 | I7: =('B5'!AU10)*0.51 -> 0 | J7: ='B5'!AX10/0.51 -> 1.372549 | K7: =WATER!I11 -> 0 | L7: =SUM(WATER!J11) -> 0 | M7: =WATER!Q11 -> 0 | N7: 0.6 | O7: =ELEC!B8 -> 0
A8: Beirut | B8: =B7+1 -> 7 | C8: 5 | D8: 2020 | E8: =ELEC!N9 -> 0 | F8: =SUM('EDl log'!T10) -> 0 | G8: =-tanks!AW12 -> 0 | H8: =SUM(tanks!AV12) -> 0 | I8: =('B5'!AU11)*0.51 -> 0 | J8: ='B5'!AX11/0.51 -> 1.372549 | K8: =WATER!I12 -> 0 | L8: =SUM(WATER!J12) -> 0 | M8: =WATER!Q12 -> 0 | N8: 0.6 | O8: =ELEC!B9 -> 0
A9: Beirut | B9: =B8+1 -> 8 | C9: 5 | D9: 2020 | E9: =ELEC!N10 -> 0 | F9: =SUM('EDl log'!T11) -> 0 | G9: =-tanks!AW13 -> 0 | H9: =SUM(tanks!AV13) -> 0 | I9: =('B5'!AU12)*0.51 -> 0 | J9: ='B5'!AX12/0.51 -> 1.372549 | K9: =WATER!I13 -> 0 | L9: =SUM(WATER!J13) -> 0 | M9: =WATER!Q13 -> 0 | N9: 0.6 | O9: =ELEC!B10 -> 0
A10: Beirut | B10: =B9+1 -> 9 | C10: 5 | D10: 2020 | E10: =ELEC!N11 -> 0 | F10: =SUM('EDl log'!T12) -> 0 | G10: =-tanks!AW14 -> 0 | H10: =SUM(tanks!AV14) -> 0 | I10: =('B5'!AU13)*0.51 -> 0 | J10: ='B5'!AX13/0.51 -> 1.372549 | K10: =WATER!I14 -> 0 | L10: =SUM(WATER!J14) -> 0 | M10: =WATER!Q14 -> 0 | N10: 0.6 | O10: =ELEC!B11 -> 0
A11: Beirut | B11: =B10+1 -> 10 | C11: 5 | D11: 2020 | E11: =ELEC!N12 -> 0 | F11: =SUM('EDl log'!T13) -> 0 | G11: =-tanks!AW15 -> 0 | H11: =SUM(tanks!AV15) -> 0 | I11: =('B5'!AU14)*0.51 -> 0 | J11: ='B5'!AX14/0.51 -> 1.372549 | K11: =WATER!I15 -> 0 | L11: =SUM(WATER!J15) -> 0 | M11: =WATER!Q15 -> 0 | N11: 0.6 | O11: =ELEC!B12 -> 0
A12: Beirut | B12: =B11+1 -> 11 | C12: 5 | D12: 2020 | E12: =ELEC!N13 -> 0 | F12: =SUM('EDl log'!T14) -> 0 | G12: =-tanks!AW16 -> 0 | H12: =SUM(tanks!AV16) -> 0 | I12: =('B5'!AU15)*0.51 -> 0 | J12: ='B5'!AX15/0.51 -> 1.372549 | K12: =WATER!I16 -> 0 | L12: =SUM(WATER!J16) -> 0 | M12: =WATER!Q16 -> 0 | N12: 0.6 | O12: =ELEC!B13 -> 0
A13: Beirut | B13: =B12+1 -> 12 | C13: 5 | D13: 2020 | E13: =ELEC!N14 -> 0 | F13: =SUM('EDl log'!T15) -> 0 | G13: =-tanks!AW17 -> 0 | H13: =SUM(tanks!AV17) -> 0 | I13: =('B5'!AU16)*0.51 -> 0 | J13: ='B5'!AX16/0.51 -> 1.372549 | K13: =WATER!I17 -> 0 | L13: =SUM(WATER!J17) -> 0 | M13: =WATER!Q17 -> 0 | N13: 0.6 | O13: =ELEC!B14 -> 0
A14: Beirut | B14: =B13+1 -> 13 | C14: 5 | D14: 2020 | E14: =ELEC!N15 -> 0 | F14: =SUM('EDl log'!T16) -> 0 | G14: =-tanks!AW18 -> 0 | H14: =SUM(tanks!AV18) -> 0 | I14: =('B5'!AU17)*0.51 -> 0 | J14: ='B5'!AX17/0.51 -> 1.372549 | K14: =WATER!I18 -> 0 | L14: =SUM(WATER!J18) -> 0 | M14: =WATER!Q18 -> 0 | N14: 0.6 | O14: =ELEC!B15 -> 0
... A32: Beirut | B32: =B31+1 -> 31 | C32: 5 | D32: 2020 | E32: =ELEC!N33 -> 0 | F32: =SUM('EDl log'!T34) -> 0 | G32: =-tanks!AW36 -> 0 | H32: =SUM(tanks!AV36) -> 0 | I32: =('B5'!AU35)*0.51 -> 0 | J32: ='B5'!AX35/0.51 -> 1.372549 | K32: =WATER!I36 -> 0 | L32: =SUM(WATER!J36) -> 0 | M32: =WATER!Q36 -> 0 | N32: 0.6 | O32: =ELEC!B33 -> 0

Sheet Submetering
A1: Site Name | B1: Day | C1: Month | D1: Year | E1: ATS1 Kwh | F1: ATS2 Kwh | G1: ATS3 Kwh | H1: ATS4 Kwh | I1: ATS5 Kwh | J1: Guest (m3) | K1: Kitchen & Laundry (m3) | L1: Room Nights
A2: Beirut | B2: 1 | C2: 5 | D2: 2020 | E2: =ELEC!M3 -> 2580 | F2: =ELEC!K3 -> 996 | G2: =ELEC!I3 -> 1146 | H2: =ELEC!E3 -> 2824 | I2: =ELEC!G3 -> 1256.4 | J2: =WATER!Y6 -> 2 | K2: =WATER!AJ6 -> 1 | L2: =ELEC!B3 -> 10.005
A3: Beirut | B3: =B2+1 -> 2 | C3: 5 | D3: 2020 | E3: =ELEC!M4 -> 2628 | F3: =ELEC!K4 -> 930 | G3: =ELEC!I4 -> 1188 | H3: =ELEC!E4 -> 2628 | I3: =ELEC!G4 -> 1327.6 | J3: =WATER!Y7 -> 66 | K3: =WATER!AJ7 -> 45 | L3: =ELEC!B4 -> 8.97
A4: Beirut | B4: =B3+1 -> 3 | C4: 5 | D4: 2020 | E4: =ELEC!M5 -> 2892 | F4: =ELEC!K5 -> 940 | G4: =ELEC!I5 -> 1376 | H4: =ELEC!E5 -> 4672 | I4: =ELEC!G5 -> 1458.4 | J4: =WATER!Y8 -> 82 | K4: =WATER!AJ8 -> 13 | L4: =ELEC!B5 -> 6.003
A5: Beirut | B5: =B4+1 -> 4 | C5: 5 | D5: 2020 | E5: =ELEC!M6 -> 2872 | F5: =ELEC!K6 -> 1572 | G5: =ELEC!I6 -> 1320 | H5: =ELEC!E6 -> 3434 | I5: =ELEC!G6 -> 1394 | J5: =WATER!Y9 -> 2 | K5: =WATER!AJ9 -> 21 | L5: =ELEC!B6 -> 2.001
A6: Beirut | B6: =B5+1 -> 5 | C6: 5 | D6: 2020 | E6: =ELEC!M7 -> 0 | F6: =ELEC!K7 -> 0 | G6: =ELEC!I7 -> 0 | H6: =ELEC!E7 -> 0 | I6: =ELEC!G7 -> 0 | J6: =WATER!Y10 -> 0 | K6: =WATER!AJ10 -> 0 | L6: =ELEC!B7 -> 0
A7: Beirut | B7: =B6+1 -> 6 | C7: 5 | D7: 2020 | E7: =ELEC!M8 -> 0 | F7: =ELEC!K8 -> 0 | G7: =ELEC!I8 -> 0 | H7: =ELEC!E8 -> 0 | I7: =ELEC!G8 -> 0 | J7: =WATER!Y11 -> 0 | K7: =WATER!AJ11 -> 0 | L7: =ELEC!B8 -> 0
A8: Beirut | B8: =B7+1 -> 7 | C8: 5 | D8: 2020 | E8: =ELEC!M9 -> 0 | F8: =ELEC!K9 -> 0 | G8: =ELEC!I9 -> 0 | H8: =ELEC!E9 -> 0 | I8: =ELEC!G9 -> 0 | J8: =WATER!Y12 -> 0 | K8: =WATER!AJ12 -> 0 | L8: =ELEC!B9 -> 0
A9: Beirut | B9: =B8+1 -> 8 | C9: 5 | D9: 2020 | E9: =ELEC!M10 -> 0 | F9: =ELEC!K10 -> 0 | G9: =ELEC!I10 -> 0 | H9: =ELEC!E10 -> 0 | I9: =ELEC!G10 -> 0 | J9: =WATER!Y13 -> 0 | K9: =WATER!AJ13 -> 0 | L9: =ELEC!B10 -> 0
A10: Beirut | B10: =B9+1 -> 9 | C10: 5 | D10: 2020 | E10: =ELEC!M11 -> 0 | F10: =ELEC!K11 -> 0 | G10: =ELEC!I11 -> 0 | H10: =ELEC!E11 -> 0 | I10: =ELEC!G11 -> 0 | J10: =WATER!Y14 -> 0 | K10: =WATER!AJ14 -> 0 | L10: =ELEC!B11 -> 0
A11: Beirut | B11: =B10+1 -> 10 | C11: 5 | D11: 2020 | E11: =ELEC!M12 -> 0 | F11: =ELEC!K12 -> 0 | G11: =ELEC!I12 -> 0 | H11: =ELEC!E12 -> 0 | I11: =ELEC!G12 -> 0 | J11: =WATER!Y15 -> 0 | K11: =WATER!AJ15 -> 0 | L11: =ELEC!B12 -> 0
A12: Beirut | B12: =B11+1 -> 11 | C12: 5 | D12: 2020 | E12: =ELEC!M13 -> 0 | F12: =ELEC!K13 -> 0 | G12: =ELEC!I13 -> 0 | H12: =ELEC!E13 -> 0 | I12: =ELEC!G13 -> 0 | J12: =WATER!Y16 -> 0 | K12: =WATER!AJ16 -> 0 | L12: =ELEC!B13 -> 0
A13: Beirut | B13: =B12+1 -> 12 | C13: 5 | D13: 2020 | E13: =ELEC!M14 -> 0 | F13: =ELEC!K14 -> 0 | G13: =ELEC!I14 -> 0 | H13: =ELEC!E14 -> 0 | I13: =ELEC!G14 -> 0 | J13: =WATER!Y17 -> 0 | K13: =WATER!AJ17 -> 0 | L13: =ELEC!B14 -> 0
A14: Beirut | B14: =B13+1 -> 13 | C14: 5 | D14: 2020 | E14: =ELEC!M15 -> 0 | F14: =ELEC!K15 -> 0 | G14: =ELEC!I15 -> 0 | H14: =ELEC!E15 -> 0 | I14: =ELEC!G15 -> 0 | J14: =WATER!Y18 -> 0 | K14: =WATER!AJ18 -> 0 | L14: =ELEC!B15 -> 0
... A32: Beirut | B32: =B31+1 -> 31 | C32: 5 | D32: 2020 | E32: =ELEC!M33 -> 0 | F32: =ELEC!K33 -> 0 | G32: =ELEC!I33 -> 0 | H32: =ELEC!E33 -> 0 | I32: =ELEC!G33 -> 0 | J32: =WATER!Y36 -> 0 | K32: =WATER!AJ36 -> 0 | L32: =ELEC!B33 -> 0

Sheet ELEC
A1: OOC | B1: Room OCC | D1: MDB3 | E1: MDB3/day | F1: EMDB2 | G1: EMDB2/day | H1: EMDB1 | I1: EMDB1/day | J1: MDB2 | K1: mdb2/day | L1: MDB1 | M1: MDB1/Day | N1: Total KWH | O1: KWH/Rooc | P1: Gen MHW | Q1: Gen/Day KWH | R1: EDL KWH | S1: CH1 RH | T1: RH | U1: C1h1 power | V1: CH1 Con KWH | W1: CH2 RH | X1: RH | Y1: Ch2 power | Z1: CH2 Con KWH | AA1: CH3 RH | AB1: RH | AC1: Ch3 power | AD1: CH3 Con KWH | AE1: RH total | AF1: KWH total | AG1: AVG chiller KW/Hr
A2: =[1]ELEC!A32 -> 0.013 | B2: 0.0299 | C2: 43951 | D2: =[1]ELEC!D32 -> 31633090 | E2: =[1]ELEC!E32 -> 2376 | F2: =[1]ELEC!F32 -> 3646395.6 | G2: =[1]ELEC!G32 -> 1679.2 | H2: =[1]ELEC!H32 -> 17427416 | I2: =[1]ELEC!I32 -> 1518 | J2: =[1]ELEC!J32 -> 28390420 | K2: =[1]ELEC!K32 -> 1094 | ... AI2: =[1]ELEC!AI32 -> -49806640
A3: ='General information '!F6 -> 0.0435 | B3: =SUM(230*A3) -> 10.005 | C3: 43952 | D3: 31635914 | E3: =D3-D2 -> 2824 | F3: 3647652 | G3: =F3-F2 -> 1256.4 | H3: 17428562 | I3: =H3-H2 -> 1146 | J3: 28391416 | K3: =J3-J2 -> 996 | L3: 22944766 | M3: =L3-L2 -> 2580 | N3: =M3+K3+I3+G3+E3 -> 8802.4 | O3: =IF(B3>0,N3/B3,0) -> 879.8001 | P3: 15481 | Q3: =(P3-P2)*1000 -> 1400 | R3: =+N3-Q3 -> 7402.4 | S3: =S2 -> 8454 | T3: =S3-S2 -> 0 | U3: =U2 -> 40221 | V3: =U3-U2 -> 0 | W3: 31845 | X3: =W3-W2 -> 0 | Y3: 624440 | Z3: =Y3-Y2 -> 0 | AA3: 35046 | AB3: =AA3-AA2 -> 4 | AC3: 774178 | AD3: =AC3-AC2 -> 835 | AE3: =AB3+X3+T3 -> 4 | AF3: =V3+Z3+AD3 -> 835 | AG3: =IF(AE3>0,AF3/AE3,0) -> 208.75
A4: ='General information '!F7 -> 0.039 | B4: =SUM(230*A4) -> 8.97 | C4: 43953 | D4: 31638542 | E4: =D4-D3 -> 2628 | F4: 3648979.6 | G4: =F4-F3 -> 1327.6 | H4: 17429750 | I4: =H4-H3 -> 1188 | J4: 28392346 | K4: =J4-J3 -> 930 | L4: 22947394 | M4: =L4-L3 -> 2628 | N4: =M4+K4+I4+G4+E4 -> 8701.6 | O4: =IF(B4>0,N4/B4,0) -> 970.07804 | P4: 15482.534 | Q4: =(P4-P3)*1000 -> 1534 | R4: =N4-Q4 -> 7167.6 | S4: =S3 -> 8454 | T4: =S4-S3 -> 0 | U4: =U3 -> 40221 | V4: =U4-U3 -> 0 | W4: =W3 -> 31845 | X4: =W4-W3 -> 0 | Y4: =Y3 -> 624440 | Z4: =Y4-Y3 -> 0 | AA4: 35049 | AB4: =AA4-AA3 -> 3 | AC4: 774785 | AD4: =AC4-AC3 -> 607 | AE4: =AB4+X4+T4 -> 3 | AF4: =V4+Z4+AD4 -> 607 | AG4: =IF(AE4>0,AF4/AE4,0) -> 202.33333
A5: ='General information '!F8 -> 0.0261 | B5: =SUM(230*A5) -> 6.003 | C5: 43954 | D5: 31643214 | E5: =D5-D4 -> 4672 | F5: 3650438 | G5: =F5-F4 -> 1458.4 | H5: 17431126 | I5: =H5-H4 -> 1376 | J5: 28393286 | K5: =J5-J4 -> 940 | L5: 22950286 | M5: =L5-L4 -> 2892 | N5: =M5+K5+I5+G5+E5 -> 11338.4 | O5: =IF(B5>0,N5/B5,0) -> 1888.7889 | P5: 15484 | Q5: =(P5-P4)*1000 -> 1466 | R5: =N5-Q5 -> 9872.4 | S5: =S4 -> 8454 | T5: =S5-S4 -> 0 | U5: =U4 -> 40221 | V5: =U5-U4 -> 0 | W5: 31845 | X5: =W5-W4 -> 0 | Y5: 624440 | Z5: =Y5-Y4 -> 0 | AA5: 35057 | AB5: =AA5-AA4 -> 8 | AC5: 776180 | AD5: =AC5-AC4 -> 1395 | AE5: =AB5+X5+T5 -> 8 | AF5: =V5+Z5+AD5 -> 1395 | AG5: =IF(AE5>0,AF5/AE5,0) -> 174.375 | AI5: =R5-'EDl log'!B3 -> -49817698
A6: ='General information '!F9 -> 0.0087 | B6: =SUM(230*A6) -> 2.001 | C6: 43955 | D6: 31646648 | E6: =D6-D5 -> 3434 | F6: 3651832 | G6: =F6-F5 -> 1394 | H6: 17432446 | I6: =H6-H5 -> 1320 | J6: 28394858 | K6: =J6-J5 -> 1572 | L6: 22953158 | M6: =L6-L5 -> 2872 | N6: =M6+K6+I6+G6+E6 -> 10592 | O6: =IF(B6>0,N6/B6,0) -> 5293.3533 | P6: 15485 | Q6: =(P6-P5)*1000 -> 1000 | R6: =N6-Q6 -> 9592 | S6: =S5 -> 8454 | T6: =S6-S5 -> 0 | U6: =U5 -> 40221 | V6: =U6-U5 -> 0 | W6: 31845 | X6: =W6-W5 -> 0 | Y6: 624440 | Z6: =Y6-Y5 -> 0 | AA6: 35061 | AB6: =AA6-AA5 -> 4 | AC6: 777210 | AD6: =AC6-AC5 -> 1030 | AE6: =AB6+X6+T6 -> 4 | AF6: =V6+Z6+AD6 -> 1030 | AG6: =IF(AE6>0,AF6/AE6,0) -> 257.5 | AI6: =R6-'EDl log'!B4 -> -49821551
A7: ='General information '!F10 -> 0 | B7: =SUM(230*A7) -> 0 | C7: 43956 | D7: =D6 -> 31646648 | E7: =D7-D6 -> 0 | F7: =F6 -> 3651832 | G7: =F7-F6 -> 0 | H7: =H6 -> 17432446 | I7: =H7-H6 -> 0 | J7: =J6 -> 28394858 | K7: =J7-J6 -> 0 | L7: =L6 -> 22953158 | M7: =L7-L6 -> 0 | N7: =M7+K7+I7+G7+E7 -> 0 | O7: =IF(B7>0,N7/B7,0) -> 0 | P7: =P6 -> 15485 | Q7: =(P7-P6)*1000 -> 0 | R7: =N7-Q7 -> 0 | S7: =S6 -> 8454 | T7: =S7-S6 -> 0 | U7: =U6 -> 40221 | V7: =U7-U6 -> 0 | W7: =W6 -> 31845 | X7: =W7-W6 -> 0 | Y7: =Y6 -> 624440 | Z7: =Y7-Y6 -> 0 | AA7: =AA6 -> 35061 | AB7: 6 | AC7: =AC6 -> 777210 | AD7: =AC7-AC6 -> 0 | AE7: =AB7+X7+T7 -> 6 | AF7: =V7+Z7+AD7 -> 0 | AG7: =IF(AE7>0,AF7/AE7,0) -> 0 | AI7: =R7-'EDl log'!B5 -> -49835173
A8: ='General information '!F11 -> 0 | B8: =SUM(230*A8) -> 0 | C8: 43957 | D8: =D7 -> 31646648 | E8: =D8-D7 -> 0 | F8: =F7 -> 3651832 | G8: =F8-F7 -> 0 | H8: =H7 -> 17432446 | I8: =H8-H7 -> 0 | J8: =J7 -> 28394858 | K8: =J8-J7 -> 0 | L8: =L7 -> 22953158 | M8: =L8-L7 -> 0 | N8: =M8+K8+I8+G8+E8 -> 0 | O8: =IF(B8>0,N8/B8,0) -> 0 | P8: =P7 -> 15485 | Q8: =(P8-P7)*1000 -> 0 | R8: =N8-Q8 -> 0 | S8: =S7 -> 8454 | T8: =S8-S7 -> 0 | U8: =U7 -> 40221 | V8: =U8-U7 -> 0 | W8: 31845 | X8: =W8-W7 -> 0 | Y8: 624440 | Z8: =Y8-Y7 -> 0 | AA8: =AA7 -> 35061 | AB8: =AA8-AA7 -> 0 | AC8: =AC7 -> 777210 | AD8: =AC8-AC7 -> 0 | AE8: =AB8+X8+T8 -> 0 | AF8: =V8+Z8+AD8 -> 0 | AG8: =IF(AE8>0,AF8/AE8,0) -> 0 | AI8: =R8-'EDl log'!B6 -> -49840476
A9: ='General information '!F12 -> 0 | B9: =SUM(230*A9) -> 0 | C9: 43958 | D9: =D8 -> 31646648 | E9: =D9-D8 -> 0 | F9: =F8 -> 3651832 | G9: =F9-F8 -> 0 | H9: =H8 -> 17432446 | I9: =H9-H8 -> 0 | J9: =J8 -> 28394858 | K9: =J9-J8 -> 0 | L9: =L8 -> 22953158 | M9: =L9-L8 -> 0 | N9: =M9+K9+I9+G9+E9 -> 0 | O9: =IF(B9>0,N9/B9,0) -> 0 | P9: =P8 -> 15485 | Q9: =(P9-P8)*1000 -> 0 | R9: =N9-Q9 -> 0 | S9: =S8 -> 8454 | T9: =S9-S8 -> 0 | U9: =U8 -> 40221 | V9: =U9-U8 -> 0 | W9: =W8 -> 31845 | X9: =W9-W8 -> 0 | Y9: =Y8 -> 624440 | Z9: =Y9-Y8 -> 0 | AA9: =AA8 -> 35061 | AB9: =AA9-AA8 -> 0 | AC9: =AC8 -> 777210 | AD9: =AC9-AC8 -> 0 | AE9: =AB9+X9+T9 -> 0 | AF9: =V9+Z9+AD9 -> 0 | AG9: =IF(AE9>0,AF9/AE9,0) -> 0 | AI9: =R9-'EDl log'!B7 -> -49844850
A10: ='General information '!F13 -> 0 | B10: =SUM(230*A10) -> 0 | C10: 43959 | D10: =D9 -> 31646648 | E10: =D10-D9 -> 0 | F10: =F9 -> 3651832 | G10: =F10-F9 -> 0 | H10: =H9 -> 17432446 | I10: =H10-H9 -> 0 | J10: =J9 -> 28394858 | K10: =J10-J9 -> 0 | L10: =L9 -> 22953158 | M10: =L10-L9 -> 0 | N10: =M10+K10+I10+G10+E10 -> 0 | O10: =IF(B10>0,N10/B10,0) -> 0 | P10: =P9 -> 15485 | Q10: =(P10-P9)*1000 -> 0 | R10: =N10-Q10 -> 0 | S10: =S9 -> 8454 | T10: =S10-S9 -> 0 | U10: =U9 -> 40221 | V10: =U10-U9 -> 0 | W10: 31845 | X10: =W10-W9 -> 0 | Y10: 624440 | Z10: =Y10-Y9 -> 0 | AA10: =AA9 -> 35061 | AB10: =AA10-AA9 -> 0 | AC10: =AC9 -> 777210 | AD10: =AC10-AC9 -> 0 | AE10: =AB10+X10+T10 -> 0 | AF10: =V10+Z10+AD10 -> 0 | AG10: =IF(AE10>0,AF10/AE10,0) -> 0 | AI10: =R10-'EDl log'!B8 -> -49844850
A11: ='General information '!F14 -> 0 | B11: =SUM(230*A11) -> 0 | C11: 43960 | D11: =D10 -> 31646648 | E11: =D11-D10 -> 0 | F11: =F10 -> 3651832 | G11: =F11-F10 -> 0 | H11: =H10 -> 17432446 | I11: =H11-H10 -> 0 | J11: =J10 -> 28394858 | K11: =J11-J10 -> 0 | L11: =L10 -> 22953158 | M11: =L11-L10 -> 0 | N11: =M11+K11+I11+G11+E11 -> 0 | O11: =IF(B11>0,N11/B11,0) -> 0 | P11: =P10 -> 15485 | Q11: =(P11-P10)*1000 -> 0 | R11: =N11-Q11 -> 0 | S11: =S10 -> 8454 | T11: =S11-S10 -> 0 | U11: =U10 -> 40221 | V11: =U11-U10 -> 0 | W11: =W10 -> 31845 | X11: =W11-W10 -> 0 | Y11: =Y10 -> 624440 | Z11: =Y11-Y10 -> 0 | AA11: =AA10 -> 35061 | AB11: =AA11-AA10 -> 0 | AC11: =AC10 -> 777210 | AD11: =AC11-AC10 -> 0 | AE11: =AB11+X11+T11 -> 0 | AF11: =V11+Z11+AD11 -> 0 | AG11: =IF(AE11>0,AF11/AE11,0) -> 0 | AI11: =R11-'EDl log'!B9 -> -49844850
A12: ='General information '!F15 -> 0 | B12: =SUM(230*A12) -> 0 | C12: 43961 | D12: =D11 -> 31646648 | E12: =D12-D11 -> 0 | F12: =F11 -> 3651832 | G12: =F12-F11 -> 0 | H12: =H11 -> 17432446 | I12: =H12-H11 -> 0 | J12: =J11 -> 28394858 | K12: =J12-J11 -> 0 | L12: =L11 -> 22953158 | M12: =L12-L11 -> 0 | N12: =M12+K12+I12+G12+E12 -> 0 | O12: =IF(B12>0,N12/B12,0) -> 0 | P12: =P11 -> 15485 | Q12: =(P12-P11)*1000 -> 0 | R12: =N12-Q12 -> 0 | S12: =S11 -> 8454 | T12: =S12-S11 -> 0 | U12: =U11 -> 40221 | V12: =U12-U11 -> 0 | W12: 31845 | X12: =W12-W11 -> 0 | Y12: 624440 | Z12: =Y12-Y11 -> 0 | AA12: =AA11 -> 35061 | AB12: =AA12-AA11 -> 0 | AC12: =AC11 -> 777210 | AD12: =AC12-AC11 -> 0 | AE12: =AB12+X12+T12 -> 0 | AF12: =V12+Z12+AD12 -> 0 | AG12: =IF(AE12>0,AF12/AE12,0) -> 0 | AI12: =R12-'EDl log'!B10 -> -49844850
A13: ='General information '!F16 -> 0 | B13: =SUM(230*A13) -> 0 | C13: 43962 | D13: =D12 -> 31646648 | E13: =D13-D12 -> 0 | F13: =F12 -> 3651832 | G13: =F13-F12 -> 0 | H13: =H12 -> 17432446 | I13: =H13-H12 -> 0 | J13: =J12 -> 28394858 | K13: =J13-J12 -> 0 | L13: =L12 -> 22953158 | M13: =L13-L12 -> 0 | N13: =M13+K13+I13+G13+E13 -> 0 | O13: =IF(B13>0,N13/B13,0) -> 0 | P13: =P12 -> 15485 | Q13: =(P13-P12)*1000 -> 0 | R13: =N13-Q13 -> 0 | S13: =S12 -> 8454 | T13: =S13-S12 -> 0 | U13: =U12 -> 40221 | V13: =U13-U12 -> 0 | W13: 31845 | X13: =W13-W12 -> 0 | Y13: 624440 | Z13: =Y13-Y12 -> 0 | AA13: =AA12 -> 35061 | AB13: =AA13-AA12 -> 0 | AC13: =AC12 -> 777210 | AD13: =AC13-AC12 -> 0 | AE13: =AB13+X13+T13 -> 0 | AF13: =V13+Z13+AD13 -> 0 | AG13: =IF(AE13>0,AF13/AE13,0) -> 0 | AI13: =R13-'EDl log'!B11 -> -49844850
A14: ='General information '!F17 -> 0 | B14: =SUM(230*A14) -> 0 | C14: 43963 | D14: =D13 -> 31646648 | E14: =D14-D13 -> 0 | F14: =F13 -> 3651832 | G14: =F14-F13 -> 0 | H14: =H13 -> 17432446 | I14: =H14-H13 -> 0 | J14: =J13 -> 28394858 | K14: =J14-J13 -> 0 | L14: =L13 -> 22953158 | M14: =L14-L13 -> 0 | N14: =M14+K14+I14+G14+E14 -> 0 | O14: =IF(B14>0,N14/B14,0) -> 0 | P14: =P13 -> 15485 | Q14: =(P14-P13)*1000 -> 0 | R14: =N14-Q14 -> 0 | S14: =S13 -> 8454 | T14: =S14-S13 -> 0 | U14: =U13 -> 40221 | V14: =U14-U13 -> 0 | W14: 31845 | X14: =W14-W13 -> 0 | Y14: 624440 | Z14: =Y14-Y13 -> 0 | AA14: =AA13 -> 35061 | AB14: =AA14-AA13 -> 0 | AC14: =AC13 -> 777210 | AD14: =AC14-AC13 -> 0 | AE14: =AB14+X14+T14 -> 0 | AF14: =V14+Z14+AD14 -> 0 | AG14: =IF(AE14>0,AF14/AE14,0) -> 0 | AI14: =R14-'EDl log'!B12 -> -49844850
A15: ='General information '!F18 -> 0 | B15: =SUM(230*A15) -> 0 | C15: 43964 | D15: =D14 -> 31646648 | E15: =D15-D14 -> 0 | F15: =F14 -> 3651832 | G15: =F15-F14 -> 0 | H15: =H14 -> 17432446 | I15: =H15-H14 -> 0 | J15: =J14 -> 28394858 | K15: =J15-J14 -> 0 | L15: =L14 -> 22953158 | M15: =L15-L14 -> 0 | N15: =M15+K15+I15+G15+E15 -> 0 | O15: =IF(B15>0,N15/B15,0) -> 0 | P15: =P14 -> 15485 | Q15: =(P15-P14)*1000 -> 0 | R15: =N15-Q15 -> 0 | S15: =S14 -> 8454 | T15: =S15-S14 -> 0 | U15: =U14 -> 40221 | V15: =U15-U14 -> 0 | W15: =W14 -> 31845 | X15: =W15-W14 -> 0 | Y15: =Y14 -> 624440 | Z15: =Y15-Y14 -> 0 | AA15: =AA14 -> 35061 | AB15: =AA15-AA14 -> 0 | AC15: =AC14 -> 777210 | AD15: =AC15-AC14 -> 0 | AE15: =AB15+X15+T15 -> 0 | AF15: =V15+Z15+AD15 -> 0 | AG15: =IF(AE15>0,AF15/AE15,0) -> 0 | AI15: =R15-'EDl log'!B13 -> -49844850
A16: ='General information '!F19 -> 0 | B16: =SUM(230*A16) -> 0 | C16: 43965 | D16: =D15 -> 31646648 | E16: =D16-D15 -> 0 | F16: =F15 -> 3651832 | G16: =F16-F15 -> 0 | H16: =H15 -> 17432446 | I16: =H16-H15 -> 0 | J16: =J15 -> 28394858 | K16: =J16-J15 -> 0 | L16: =L15 -> 22953158 | M16: =L16-L15 -> 0 | N16: =M16+K16+I16+G16+E16 -> 0 | O16: =IF(B16>0,N16/B16,0) -> 0 | P16: =P15 -> 15485 | Q16: =(P16-P15)*1000 -> 0 | R16: =N16-Q16 -> 0 | S16: =S15 -> 8454 | T16: =S16-S15 -> 0 | U16: =U15 -> 40221 | V16: =U16-U15 -> 0 | W16: =W15 -> 31845 | X16: =W16-W15 -> 0 | Y16: =Y15 -> 624440 | Z16: =Y16-Y15 -> 0 | AA16: =AA15 -> 35061 | AB16: =AA16-AA15 -> 0 | AC16: =AC15 -> 777210 | AD16: =AC16-AC15 -> 0 | AE16: =AB16+X16+T16 -> 0 | AF16: =V16+Z16+AD16 -> 0 | AG16: =IF(AE16>0,AF16/AE16,0) -> 0 | AI16: =R16-'EDl log'!B14 -> -49844850
A17: ='General information '!F20 -> 0 | B17: =SUM(230*A17) -> 0 | C17: 43966 | D17: =D16 -> 31646648 | E17: =D17-D16 -> 0 | F17: =F16 -> 3651832 | G17: =F17-F16 -> 0 | H17: =H16 -> 17432446 | I17: =H17-H16 -> 0 | J17: =J16 -> 28394858 | K17: =J17-J16 -> 0 | L17: =L16 -> 22953158 | M17: =L17-L16 -> 0 | N17: =M17+K17+I17+G17+E17 -> 0 | O17: =IF(B17>0,N17/B17,0) -> 0 | P17: =P16 -> 15485 | Q17: =(P17-P16)*1000 -> 0 | R17: =N17-Q17 -> 0 | S17: =S16 -> 8454 | T17: =S17-S16 -> 0 | U17: =U16 -> 40221 | V17: =U17-U16 -> 0 | W17: =W16 -> 31845 | X17: =W17-W16 -> 0 | Y17: =Y16 -> 624440 | Z17: =Y17-Y16 -> 0 | AA17: =AA16 -> 35061 | AB17: =AA17-AA16 -> 0 | AC17: =AC16 -> 777210 | AD17: =AC17-AC16 -> 0 | AE17: =AB17+X17+T17 -> 0 | AF17: =V17+Z17+AD17 -> 0 | AG17: =IF(AE17>0,AF17/AE17,0) -> 0 | AI17: =R17-'EDl log'!B15 -> -49844850
A18: ='General information '!F21 -> 0 | B18: =SUM(230*A18) -> 0 | C18: 43967 | D18: =D17 -> 31646648 | E18: =D18-D17 -> 0 | F18: =F17 -> 3651832 | G18: =F18-F17 -> 0 | H18: =H17 -> 17432446 | I18: =H18-H17 -> 0 | J18: =J17 -> 28394858 | K18: =J18-J17 -> 0 | L18: =L17 -> 22953158 | M18: =L18-L17 -> 0 | N18: =M18+K18+I18+G18+E18 -> 0 | O18: =IF(B18>0,N18/B18,0) -> 0 | P18: =P17 -> 15485 | Q18: =(P18-P17)*1000 -> 0 | R18: =N18-Q18 -> 0 | S18: =S17 -> 8454 | T18: =S18-S17 -> 0 | U18: =U17 -> 40221 | V18: =U18-U17 -> 0 | W18: =[2]ELEC!K18 -> 31845 | X18: =W18-W17 -> 0 | Y18: =[2]ELEC!L18 -> 624440 | Z18: =Y18-Y17 -> 0 | AA18: =AA17 -> 35061 | AB18: =AA18-AA17 -> 0 | AC18: =AC17 -> 777210 | AD18: =AC18-AC17 -> 0 | AE18: =AB18+X18+T18 -> 0 | AF18: =V18+Z18+AD18 -> 0 | AG18: =IF(AE18>0,AF18/AE18,0) -> 0 | AI18: =R18-'EDl log'!B16 -> -49844850
A19: ='General information '!F22 -> 0 | B19: =SUM(230*A19) -> 0 | C19: 43968 | D19: =D18 -> 31646648 | E19: =D19-D18 -> 0 | F19: =F18 -> 3651832 | G19: =F19-F18 -> 0 | H19: =H18 -> 17432446 | I19: =H19-H18 -> 0 | J19: =J18 -> 28394858 | K19: =J19-J18 -> 0 | L19: =L18 -> 22953158 | M19: =L19-L18 -> 0 | N19: =M19+K19+I19+G19+E19 -> 0 | O19: =IF(B19>0,N19/B19,0) -> 0 | P19: =P18 -> 15485 | Q19: =(P19-P18)*1000 -> 0 | R19: =N19-Q19 -> 0 | S19: =S18 -> 8454 | T19: =S19-S18 -> 0 | U19: =U18 -> 40221 | V19: =U19-U18 -> 0 | W19: =[2]ELEC!K19 -> 31845 | X19: =W19-W18 -> 0 | Y19: =[2]ELEC!L19 -> 624440 | Z19: =Y19-Y18 -> 0 | AA19: =AA18 -> 35061 | AB19: =AA19-AA18 -> 0 | AC19: =AC18 -> 777210 | AD19: =AC19-AC18 -> 0 | AE19: =AB19+X19+T19 -> 0 | AF19: =V19+Z19+AD19 -> 0 | AG19: =IF(AE19>0,AF19/AE19,0) -> 0 | AI19: =R19-'EDl log'!B17 -> -49844850
A20: ='General information '!F23 -> 0 | B20: =SUM(230*A20) -> 0 | C20: 43969 | D20: =D19 -> 31646648 | E20: =D20-D19 -> 0 | F20: =F19 -> 3651832 | G20: =F20-F19 -> 0 | H20: =H19 -> 17432446 | I20: =H20-H19 -> 0 | J20: =J19 -> 28394858 | K20: =J20-J19 -> 0 | L20: =L19 -> 22953158 | M20: =L20-L19 -> 0 | N20: =M20+K20+I20+G20+E20 -> 0 | O20: =IF(B20>0,N20/B20,0) -> 0 | P20: =P19 -> 15485 | Q20: =(P20-P19)*1000 -> 0 | R20: =N20-Q20 -> 0 | S20: =S19 -> 8454 | T20: =S20-S19 -> 0 | U20: =U19 -> 40221 | V20: =U20-U19 -> 0 | W20: 31845 | X20: =W20-W19 -> 0 | Y20: 624440 | Z20: =Y20-Y19 -> 0 | AA20: =AA19 -> 35061 | AB20: =AA20-AA19 -> 0 | AC20: =AC19 -> 777210 | AD20: =AC20-AC19 -> 0 | AE20: =AB20+X20+T20 -> 0 | AF20: =V20+Z20+AD20 -> 0 | AG20: =IF(AE20>0,AF20/AE20,0) -> 0 | AI20: =R20-'EDl log'!B18 -> -49844850
A21: ='General information '!F24 -> 0 | B21: =SUM(230*A21) -> 0 | C21: 43970 | D21: =D20 -> 31646648 | E21: =D21-D20 -> 0 | F21: =F20 -> 3651832 | G21: =F21-F20 -> 0 | H21: =H20 -> 17432446 | I21: =H21-H20 -> 0 | J21: =J20 -> 28394858 | K21: =J21-J20 -> 0 | L21: =L20 -> 22953158 | M21: =L21-L20 -> 0 | N21: =M21+K21+I21+G21+E21 -> 0 | O21: =IF(B21>0,N21/B21,0) -> 0 | P21: =P20 -> 15485 | Q21: =(P21-P20)*1000 -> 0 | R21: =N21-Q21 -> 0 | S21: =S20 -> 8454 | T21: =S21-S20 -> 0 | U21: =U20 -> 40221 | V21: =U21-U20 -> 0 | W21: =W20 -> 31845 | X21: =W21-W20 -> 0 | Y21: =Y20 -> 624440 | Z21: =Y21-Y20 -> 0 | AA21: =AA20 -> 35061 | AB21: =AA21-AA20 -> 0 | AC21: =AC20 -> 777210 | AD21: =AC21-AC20 -> 0 | AE21: =AB21+X21+T21 -> 0 | AF21: =V21+Z21+AD21 -> 0 | AG21: =IF(AE21>0,AF21/AE21,0) -> 0 | AI21: =R21-'EDl log'!B19 -> -49844850
A22: ='General information '!F25 -> 0 | B22: =SUM(230*A22) -> 0 | C22: 43971 | D22: =D21 -> 31646648 | E22: =D22-D21 -> 0 | F22: =F21 -> 3651832 | G22: =F22-F21 -> 0 | H22: =H21 -> 17432446 | I22: =H22-H21 -> 0 | J22: =J21 -> 28394858 | K22: =J22-J21 -> 0 | L22: =L21 -> 22953158 | M22: =L22-L21 -> 0 | N22: =M22+K22+I22+G22+E22 -> 0 | O22: =IF(B22>0,N22/B22,0) -> 0 | P22: =P21 -> 15485 | Q22: =(P22-P21)*1000 -> 0 | R22: =N22-Q22 -> 0 | S22: =S21 -> 8454 | T22: =S22-S21 -> 0 | U22: =U21 -> 40221 | V22: =U22-U21 -> 0 | W22: =W21 -> 31845 | X22: =W22-W21 -> 0 | Y22: =Y21 -> 624440 | Z22: =Y22-Y21 -> 0 | AA22: =AA21 -> 35061 | AB22: =AA22-AA21 -> 0 | AC22: =AC21 -> 777210 | AD22: =AC22-AC21 -> 0 | AE22: =AB22+X22+T22 -> 0 | AF22: =V22+Z22+AD22 -> 0 | AG22: =IF(AE22>0,AF22/AE22,0) -> 0 | AI22: =R22-'EDl log'!B20 -> -49844850
A23: ='General information '!F26 -> 0 | B23: =SUM(230*A23) -> 0 | C23: 43972 | D23: =D22 -> 31646648 | E23: =D23-D22 -> 0 | F23: =F22 -> 3651832 | G23: =F23-F22 -> 0 | H23: =H22 -> 17432446 | I23: =H23-H22 -> 0 | J23: =J22 -> 28394858 | K23: =J23-J22 -> 0 | L23: =L22 -> 22953158 | M23: =L23-L22 -> 0 | N23: =M23+K23+I23+G23+E23 -> 0 | O23: =IF(B23>0,N23/B23,0) -> 0 | P23: =P22 -> 15485 | Q23: =(P23-P22)*1000 -> 0 | R23: =N23-Q23 -> 0 | S23: =S22 -> 8454 | T23: =S23-S22 -> 0 | U23: =U22 -> 40221 | V23: =U23-U22 -> 0 | W23: =W22 -> 31845 | X23: =W23-W22 -> 0 | Y23: =Y22 -> 624440 | Z23: =Y23-Y22 -> 0 | AA23: =AA22 -> 35061 | AB23: =AA23-AA22 -> 0 | AC23: =AC22 -> 777210 | AD23: =AC23-AC22 -> 0 | AE23: =AB23+X23+T23 -> 0 | AF23: =V23+Z23+AD23 -> 0 | AG23: =IF(AE23>0,AF23/AE23,0) -> 0 | AI23: =R23-'EDl log'!B21 -> -49844850
A24: ='General information '!F27 -> 0 | B24: =SUM(230*A24) -> 0 | C24: 43973 | D24: =D23 -> 31646648 | E24: =D24-D23 -> 0 | F24: =F23 -> 3651832 | G24: =F24-F23 -> 0 | H24: =H23 -> 17432446 | I24: =H24-H23 -> 0 | J24: =J23 -> 28394858 | K24: =J24-J23 -> 0 | L24: =L23 -> 22953158 | M24: =L24-L23 -> 0 | N24: =M24+K24+I24+G24+E24 -> 0 | O24: =IF(B24>0,N24/B24,0) -> 0 | P24: =P23 -> 15485 | Q24: =(P24-P23)*1000 -> 0 | R24: =N24-Q24 -> 0 | S24: =S23 -> 8454 | T24: =S24-S23 -> 0 | U24: =U23 -> 40221 | V24: =U24-U23 -> 0 | W24: =W23 -> 31845 | X24: =W24-W23 -> 0 | Y24: =Y23 -> 624440 | Z24: =Y24-Y23 -> 0 | AA24: =AA23 -> 35061 | AB24: =AA24-AA23 -> 0 | AC24: =AC23 -> 777210 | AD24: =AC24-AC23 -> 0 | AE24: =AB24+X24+T24 -> 0 | AF24: =V24+Z24+AD24 -> 0 | AG24: =IF(AE24>0,AF24/AE24,0) -> 0 | AI24: =R24-'EDl log'!B22 -> -49844850
A25: ='General information '!F28 -> 0 | B25: =SUM(230*A25) -> 0 | C25: 43974 | D25: =D24 -> 31646648 | E25: =D25-D24 -> 0 | F25: =F24 -> 3651832 | G25: =F25-F24 -> 0 | H25: =H24 -> 17432446 | I25: =H25-H24 -> 0 | J25: =J24 -> 28394858 | K25: =J25-J24 -> 0 | L25: =L24 -> 22953158 | M25: =L25-L24 -> 0 | N25: =M25+K25+I25+G25+E25 -> 0 | O25: =IF(B25>0,N25/B25,0) -> 0 | P25: =P24 -> 15485 | Q25: =(P25-P24)*1000 -> 0 | R25: =N25-Q25 -> 0 | S25: =S24 -> 8454 | T25: =S25-S24 -> 0 | U25: =U24 -> 40221 | V25: =U25-U24 -> 0 | W25: =W24 -> 31845 | X25: =W25-W24 -> 0 | Y25: =Y24 -> 624440 | Z25: =Y25-Y24 -> 0 | AA25: =AA24 -> 35061 | AB25: =AA25-AA24 -> 0 | AC25: =AC24 -> 777210 | AD25: =AC25-AC24 -> 0 | AE25: =AB25+X25+T25 -> 0 | AF25: =V25+Z25+AD25 -> 0 | AG25: =IF(AE25>0,AF25/AE25,0) -> 0 | AI25: =R25-'EDl log'!B23 -> -49844850
A26: ='General information '!F29 -> 0 | B26: =SUM(230*A26) -> 0 | C26: 43975 | D26: =D25 -> 31646648 | E26: =D26-D25 -> 0 | F26: =F25 -> 3651832 | G26: =F26-F25 -> 0 | H26: =H25 -> 17432446 | I26: =H26-H25 -> 0 | J26: =J25 -> 28394858 | K26: =J26-J25 -> 0 | L26: =L25 -> 22953158 | M26: =L26-L25 -> 0 | N26: =M26+K26+I26+G26+E26 -> 0 | O26: =IF(B26>0,N26/B26,0) -> 0 | P26: =P25 -> 15485 | Q26: =(P26-P25)*1000 -> 0 | R26: =N26-Q26 -> 0 | S26: =S25 -> 8454 | T26: =S26-S25 -> 0 | U26: =U25 -> 40221 | V26: =U26-U25 -> 0 | W26: =W25 -> 31845 | X26: =W26-W25 -> 0 | Y26: =Y25 -> 624440 | Z26: =Y26-Y25 -> 0 | AA26: =AA25 -> 35061 | AB26: =AA26-AA25 -> 0 | AC26: =AC25 -> 777210 | AD26: =AC26-AC25 -> 0 | AE26: =AB26+X26+T26 -> 0 | AF26: =V26+Z26+AD26 -> 0 | AG26: =IF(AE26>0,AF26/AE26,0) -> 0 | AI26: =R26-'EDl log'!B24 -> -49844850
A27: ='General information '!F30 -> 0 | B27: =SUM(230*A27) -> 0 | C27: 43976 | D27: =D26 -> 31646648 | E27: =D27-D26 -> 0 | F27: =F26 -> 3651832 | G27: =F27-F26 -> 0 | H27: =H26 -> 17432446 | I27: =H27-H26 -> 0 | J27: =J26 -> 28394858 | K27: =J27-J26 -> 0 | L27: =L26 -> 22953158 | M27: =L27-L26 -> 0 | N27: =M27+K27+I27+G27+E27 -> 0 | O27: =IF(B27>0,N27/B27,0) -> 0 | P27: =P26 -> 15485 | Q27: =(P27-P26)*1000 -> 0 | R27: =N27-Q27 -> 0 | S27: =S26 -> 8454 | T27: =S27-S26 -> 0 | U27: =U26 -> 40221 | V27: =U27-U26 -> 0 | W27: 31845 | X27: =W27-W26 -> 0 | Y27: 624440 | Z27: =Y27-Y26 -> 0 | AA27: =AA26 -> 35061 | AB27: =AA27-AA26 -> 0 | AC27: =AC26 -> 777210 | AD27: =AC27-AC26 -> 0 | AE27: =AB27+X27+T27 -> 0 | AF27: =V27+Z27+AD27 -> 0 | AG27: =IF(AE27>0,AF27/AE27,0) -> 0 | AI27: =R27-'EDl log'!B25 -> -49844850
A28: ='General information '!F31 -> 0 | B28: =SUM(230*A28) -> 0 | C28: 43977 | D28: =D27 -> 31646648 | E28: =D28-D27 -> 0 | F28: =F27 -> 3651832 | G28: =F28-F27 -> 0 | H28: =H27 -> 17432446 | I28: =H28-H27 -> 0 | J28: =J27 -> 28394858 | K28: =J28-J27 -> 0 | L28: =L27 -> 22953158 | M28: =L28-L27 -> 0 | N28: =M28+K28+I28+G28+E28 -> 0 | O28: =IF(B28>0,N28/B28,0) -> 0 | P28: =P27 -> 15485 | Q28: =(P28-P27)*1000 -> 0 | R28: =N28-Q28 -> 0 | S28: =S27 -> 8454 | T28: =S28-S27 -> 0 | U28: =U27 -> 40221 | V28: =U28-U27 -> 0 | W28: =W27 -> 31845 | X28: =W28-W27 -> 0 | Y28: =Y27 -> 624440 | Z28: =Y28-Y27 -> 0 | AA28: =AA27 -> 35061 | AB28: =AA28-AA27 -> 0 | AC28: =AC27 -> 777210 | AD28: =AC28-AC27 -> 0 | AE28: =AB28+X28+T28 -> 0 | AF28: =V28+Z28+AD28 -> 0 | AG28: =IF(AE28>0,AF28/AE28,0) -> 0 | AI28: =R28-'EDl log'!B26 -> -49844850
A29: ='General information '!F32 -> 0 | B29: =SUM(230*A29) -> 0 | C29: 43978 | D29: =D28 -> 31646648 | E29: =D29-D28 -> 0 | F29: =F28 -> 3651832 | G29: =F29-F28 -> 0 | H29: =H28 -> 17432446 | I29: =H29-H28 -> 0 | J29: =J28 -> 28394858 | K29: =J29-J28 -> 0 | L29: =L28 -> 22953158 | M29: =L29-L28 -> 0 | N29: =M29+K29+I29+G29+E29 -> 0 | O29: =IF(B29>0,N29/B29,0) -> 0 | P29: =P28 -> 15485 | Q29: =(P29-P28)*1000 -> 0 | R29: =N29-Q29 -> 0 | S29: =S28 -> 8454 | T29: =S29-S28 -> 0 | U29: =U28 -> 40221 | V29: =U29-U28 -> 0 | W29: 31845 | X29: =W29-W28 -> 0 | Y29: =Y28 -> 624440 | Z29: =Y29-Y28 -> 0 | AA29: =AA28 -> 35061 | AB29: =AA29-AA28 -> 0 | AC29: =AC28 -> 777210 | AD29: =AC29-AC28 -> 0 | AE29: =AB29+X29+T29 -> 0 | AF29: =V29+Z29+AD29 -> 0 | AG29: =IF(AE29>0,AF29/AE29,0) -> 0 | AI29: =R29-'EDl log'!B27 -> -49844850
A30: ='General information '!F33 -> 0 | B30: =SUM(230*A30) -> 0 | C30: 43979 | D30: =D29 -> 31646648 | E30: =D30-D29 -> 0 | F30: =F29 -> 3651832 | G30: =F30-F29 -> 0 | H30: =H29 -> 17432446 | I30: =H30-H29 -> 0 | J30: =J29 -> 28394858 | K30: =J30-J29 -> 0 | L30: =L29 -> 22953158 | M30: =L30-L29 -> 0 | N30: =M30+K30+I30+G30+E30 -> 0 | O30: =IF(B30>0,N30/B30,0) -> 0 | P30: =P29 -> 15485 | Q30: =(P30-P29)*1000 -> 0 | R30: =N30-Q30 -> 0 | S30: =S29 -> 8454 | T30: =S30-S29 -> 0 | U30: =U29 -> 40221 | V30: =U30-U29 -> 0 | W30: =W29 -> 31845 | X30: =W30-W29 -> 0 | Y30: =Y29 -> 624440 | Z30: =Y30-Y29 -> 0 | AA30: =AA29 -> 35061 | AB30: =AA30-AA29 -> 0 | AC30: =AC29 -> 777210 | AD30: =AC30-AC29 -> 0 | AE30: =AB30+X30+T30 -> 0 | AF30: =V30+Z30+AD30 -> 0 | AG30: =IF(AE30>0,AF30/AE30,0) -> 0 | AI30: =R30-'EDl log'!B28 -> -49844850
A31: ='General information '!F34 -> 0 | B31: =SUM(230*A31) -> 0 | C31: 43980 | D31: =D30 -> 31646648 | E31: =D31-D30 -> 0 | F31: =F30 -> 3651832 | G31: =F31-F30 -> 0 | H31: =H30 -> 17432446 | I31: =H31-H30 -> 0 | J31: =J30 -> 28394858 | K31: =J31-J30 -> 0 | L31: =L30 -> 22953158 | M31: =L31-L30 -> 0 | N31: =M31+K31+I31+G31+E31 -> 0 | O31: =IF(B31>0,N31/B31,0) -> 0 | P31: =P30 -> 15485 | Q31: =(P31-P30)*1000 -> 0 | R31: =N31-Q31 -> 0 | S31: =S30 -> 8454 | T31: =S31-S30 -> 0 | U31: =U30 -> 40221 | V31: =U31-U30 -> 0 | W31: 31845 | X31: =W31-W30 -> 0 | Y31: 624440 | Z31: =Y31-Y30 -> 0 | AA31: =AA30 -> 35061 | AB31: =AA31-AA30 -> 0 | AC31: =AC30 -> 777210 | AD31: =AC31-AC30 -> 0 | AE31: =AB31+X31+T31 -> 0 | AF31: =V31+Z31+AD31 -> 0 | AG31: =IF(AE31>0,AF31/AE31,0) -> 0 | AI31: =R31-'EDl log'!B29 -> -49844850
A32: ='General information '!F35 -> 0 | B32: =SUM(230*A32) -> 0 | C32: 43981 | D32: =D31 -> 31646648 | E32: =D32-D31 -> 0 | F32: =F31 -> 3651832 | G32: =F32-F31 -> 0 | H32: =H31 -> 17432446 | I32: =H32-H31 -> 0 | J32: =J31 -> 28394858 | K32: =J32-J31 -> 0 | L32: =L31 -> 22953158 | M32: =L32-L31 -> 0 | N32: =M32+K32+I32+G32+E32 -> 0 | O32: =IF(B32>0,N32/B32,0) -> 0 | P32: =P31 -> 15485 | Q32: =(P32-P31)*1000 -> 0 | R32: =N32-Q32 -> 0 | S32: =S31 -> 8454 | T32: =S32-S31 -> 0 | U32: =U31 -> 40221 | V32: =U32-U31 -> 0 | W32: =W31 -> 31845 | X32: =W32-W31 -> 0 | Y32: =Y31 -> 624440 | Z32: =Y32-Y31 -> 0 | AA32: =AA31 -> 35061 | AB32: =AA32-AA31 -> 0 | AC32: =AC31 -> 777210 | AD32: =AC32-AC31 -> 0 | AE32: =AB32+X32+T32 -> 0 | AF32: =V32+Z32+AD32 -> 0 | AG32: =IF(AE32>0,AF32/AE32,0) -> 0 | AI32: =R32-'EDl log'!B30 -> -49844850
A33: ='General information '!F36 -> 0 | B33: =SUM(230*A33) -> 0 | C33: 43982 | D33: =D32 -> 31646648 | E33: =D33-D32 -> 0 | F33: =F32 -> 3651832 | G33: =F33-F32 -> 0 | H33: =H32 -> 17432446 | I33: =H33-H32 -> 0 | J33: =J32 -> 28394858 | K33: =J33-J32 -> 0 | L33: =L32 -> 22953158 | M33: =L33-L32 -> 0 | N33: =M33+K33+I33+G33+E33 -> 0 | O33: =IF(B33>0,N33/B33,0) -> 0 | P33: =P32 -> 15485 | Q33: =(P33-P32)*1000 -> 0 | R33: =N33-Q33 -> 0 | S33: =S32 -> 8454 | T33: =S33-S32 -> 0 | U33: =U32 -> 40221 | V33: =U33-U32 -> 0 | W33: =W32 -> 31845 | X33: =W33-W32 -> 0 | Y33: =Y32 -> 624440 | Z33: =Y33-Y32 -> 0 | AA33: =AA32 -> 35061 | AB33: =AA33-AA32 -> 0 | AC33: =AC32 -> 777210 | AD33: =AC33-AC32 -> 0 | AE33: =AB33+X33+T33 -> 0 | AF33: =V33+Z33+AD33 -> 0 | AG33: =IF(AE33>0,AF33/AE33,0) -> 0 | AI33: =R33-'EDl log'!B31 -> -49844850

Sheet B5
F1: Boiler A | J1: =J36 -> 48.666667 | K1: Boiler B | P1: Boiler C | V1: Boiler | X1: SteamA | AC1: SteamB | AH1: Steam | AI1: Boiler & steam | AL1: Total Boiler Runing H | AM1: Total Steam Runing H | AN1: GAS1 % | AO1: GAS1/L | AP1: GAS2% | AQ1: Gas2/L | AR1: GAS3% | AS1: GAS3/L | AU1: Gas Cons | AV1: Delivery | AW1: Cost/L
B2: Level Tank Gen | C2: Level tank Boiler | D2: Daily Cons Bo. | E2: Boiler litter | F2: Boiler A | G2: Run Hr a | H2: Boiler A fuel | I2: Daily consumption | J2: AVG | K2: index Run H | L2: Run Hrb | M2: Boiler B Fuel | O2: Daily consumption | P2: Boiler C | S2: Run C | U2: Total RH | V2: Total Fuel | X2: SteamA | Y2: Run SA | Z2: Steam A Conter | AA2: Liters | AC2: SteamB | AD2: Run SteamB | AE2: Steam B Conter | AF2: SB Litters | AG2: Avg | AH2: Total Fuel | AI2: Total Fuel
S3: 0
A4: =ELEC!C2 -> 43951 | B4: =[1]B5!B34 -> 245.5 | C4: =[1]B5!C34 -> 251 | D4: =[1]B5!D34 -> 3 | E4: =[1]B5!E34 -> 25.14 | F4: =[1]B5!F34 -> 1537 | G4: =[1]B5!G34 -> 1 | H4: =[1]B5!H34 -> 349198 | I4: =[1]B5!I34 -> 108 | ... AX4: =[1]B5!AX34 -> 0.7
A5: =ELEC!C3 -> 43952 | B5: 242 | C5: 248 | D5: =C4-C5 -> 3 | E5: =D5*8.38 -> 25.14 | F5: 1537 | G5: =F5-F4 -> 0 | H5: 349198 | I5: =SUM(H5-H4) -> 0 | J5: 1 | K5: 1921 | L5: =K5-K4 -> 2 | M5: 140667 | N5: =M5-M4 -> 104 | O5: =SUM(L5*$J$1) -> 97.333333 | P5: 1767 | Q5: 150185 | R5: =Q5-Q4 -> 245 | S5: =SUM(P5-P4) -> 4 | T5: =SUM(S5*$T$2) -> 0 | U5: =SUM(G5+L5+S5) -> 6 | V5: =R5+N5+I5:I5 -> 349 | W5: =SUM(V5/U5) -> 58.166667 | X5: =X4 -> 2417 | Y5: =X5-X4 -> 0 | Z5: =Z4 -> 135845.1 | AA5: =Z5-Z4 -> 0 | AB5: =SUM(Y5*$AB$2) -> 0 | AC5: =AC4 -> 1824 | AD5: =AC5-AC4 -> 0 | AE5: =AE4 -> 358865.2 | AF5: =AE5-AE4 -> 0 | AG5: =IF(AD5>0,AF5/AD5,0) -> 0 | AH5: =AF5+AA5 -> 0 | AI5: =SUM(AH5+V5) -> 349 | AJ5: =-tanks!AW6 -> 349 | AK5: =SUM(AJ5-AI5) -> 0 | AL5: =S5+L5+G5 -> 6 | AM5: =Y5+AD5 -> 0 | AN5: 80 | AO5: =(AN5/100)*3000 -> 2400 | AP5: 80 | AQ5: =(AP5/100)*3000 -> 2400 | AR5: 60 | AS5: =(AR5/100)*3000 -> 1800 | AT5: =SUM(AO5+AQ5+AS5) -> 6600 | AU5: =AT4-AT5+AV5 -> 60 | AX5: =IF(AV5>0,AW5,AX4) -> 0.7
A6: =ELEC!C4 -> 43953 | B6: 240 | C6: 246 | D6: =C5-C6 -> 2 | E6: =D6*8.38 -> 16.76 | F6: 1539 | G6: =F6-F5 -> 2 | H6: 349357 | I6: =SUM(H6-H5) -> 159 | J6: =IF(G6>0,I6/G6,0) -> 79.5 | K6: =K5 -> 1921 | L6: =K6-K5 -> 0 | M6: =M5 -> 140667 | N6: =M6-M5 -> 0 | O6: =SUM(L6*$J$1) -> 0 | P6: 1768 | Q6: 150275 | R6: =Q6-Q5 -> 90 | S6: =SUM(P6-P5) -> 1 | T6: =SUM(S6*$T$2) -> 0 | U6: =SUM(G6+L6+S6) -> 3 | V6: =R6+N6+I6:I6 -> 249 | W6: =SUM(V6/U6) -> 83 | X6: =X5 -> 2417 | Y6: =X6-X5 -> 0 | Z6: =Z5 -> 135845.1 | AA6: =Z6-Z5 -> 0 | AB6: =SUM(Y6*$AB$2) -> 0 | AC6: =AC5 -> 1824 | AD6: =AC6-AC5 -> 0 | AE6: =AE5 -> 358865.2 | AF6: =AE6-AE5 -> 0 | AG6: =IF(AD6>0,AF6/AD6,0) -> 0 | AH6: =AF6+AA6 -> 0 | AI6: =SUM(AH6+V6) -> 249 | AJ6: =-tanks!AW7 -> 249 | AK6: =SUM(AJ6-AI6) -> 0 | AL6: =S6+L6+G6 -> 3 | AM6: =Y6+AD6 -> 0 | AN6: 79 | AO6: =(AN6/100)*3000 -> 2370 | AP6: 79 | AQ6: =(AP6/100)*3000 -> 2370 | AR6: 62 | AS6: =(AR6/100)*3000 -> 1860 | AT6: =SUM(AO6+AQ6+AS6) -> 6600 | AU6: =AT5-AT6+AV6 -> 0 | AX6: =IF(AV6>0,AW6,AX5) -> 0.7
A7: =ELEC!C5 -> 43954 | B7: 237 | C7: 243 | D7: =C6-C7 -> 3 | E7: =D7*8.38 -> 25.14 | F7: 1541 | G7: =F7-F6 -> 2 | H7: 349488 | I7: =SUM(H7-H6) -> 131 | J7: =IF(G7>0,I7/G7,0) -> 65.5 | K7: 1923 | L7: =K7-K6 -> 2 | M7: 140824 | N7: =M7-M6 -> 157 | O7: 1 | P7: 1768 | Q7: 150275 | R7: =Q7-Q6 -> 0 | S7: =SUM(P7-P6) -> 0 | T7: =SUM(S7*$T$2) -> 0 | U7: =SUM(G7+L7+S7) -> 4 | V7: =R7+N7+I7:I7 -> 288 | W7: =SUM(V7/U7) -> 72 | X7: =X6 -> 2417 | Y7: =X7-X6 -> 0 | Z7: 135845.1 | AA7: =Z7-Z6 -> 0 | AB7: =SUM(Y7*$AB$2) -> 0 | AC7: 1824 | AD7: =AC7-AC6 -> 0 | AE7: 358865.7 | AF7: =AE7-AE6 -> 0.5 | AG7: =IF(AD7>0,AF7/AD7,0) -> 0 | AH7: =AF7+AA7 -> 0.5 | AI7: =SUM(AH7+V7) -> 288.5 | AJ7: =-tanks!AW8 -> 288.5 | AK7: =SUM(AJ7-AI7) -> 0 | AL7: =S7+L7+G7 -> 4 | AM7: =Y7+AD7 -> 0 | AN7: 77 | AO7: =(AN7/100)*3000 -> 2310 | AP7: 78 | AQ7: =(AP7/100)*3000 -> 2340 | AR7: 60 | AS7: =(AR7/100)*3000 -> 1800 | AT7: =SUM(AO7+AQ7+AS7) -> 6450 | AU7: =AT6-AT7+AV7 -> 150 | AX7: =IF(AV7>0,AW7,AX6) -> 0.7
A8: =ELEC!C6 -> 43955 | B8: 232 | C8: 239 | D8: =C7-C8 -> 4 | E8: =D8*8.38 -> 33.52 | F8: 1541 | G8: =F8-F7 -> 0 | H8: 349488 | I8: =SUM(H8-H7) -> 0 | J8: =IF(G8>0,I8/G8,0) -> 0 | K8: 1925 | L8: =K8-K7 -> 2 | M8: 140981 | N8: =M8-M7 -> 157 | O8: 1479 | P8: 1770 | Q8: 150466 | R8: =Q8-Q7 -> 191 | S8: =SUM(P8-P7) -> 2 | T8: =SUM(S8*$T$2) -> 0 | U8: =SUM(G8+L8+S8) -> 4 | V8: =R8+N8+I8:I8 -> 348 | W8: =SUM(V8/U8) -> 87 | X8: =X7 -> 2417 | Y8: =X8-X7 -> 0 | Z8: 135871 | AA8: =Z8-Z7 -> 25.9 | AB8: =SUM(Y8*$AB$2) -> 0 | AC8: 1829 | AD8: =AC8-AC7 -> 5 | AE8: 359149.7 | AF8: =AE8-AE7 -> 284 | AG8: =IF(AD8>0,AF8/AD8,0) -> 56.8 | AH8: =AF8+AA8 -> 309.9 | AI8: =SUM(AH8+V8) -> 657.9 | AJ8: =-tanks!AW9 -> 657.9 | AK8: =SUM(AJ8-AI8) -> 0 | AL8: =S8+L8+G8 -> 4 | AM8: =Y8+AD8 -> 5 | AN8: 72 | AO8: =(AN8/100)*3000 -> 2160 | AP8: 75 | AQ8: =(AP8/100)*3000 -> 2250 | AR8: 60 | AS8: =(AR8/100)*3000 -> 1800 | AT8: =SUM(AO8+AQ8+AS8) -> 6210 | AU8: =AT7-AT8+AV8 -> 240 | AX8: =IF(AV8>0,AW8,AX7) -> 0.7
A9: =ELEC!C7 -> 43956 | B9: =B8 -> 232 | C9: =C8 -> 239 | D9: =C8-C9 -> 0 | E9: =D9*8.38 -> 0 | F9: =F8 -> 1541 | G9: =F9-F8 -> 0 | H9: =H8 -> 349488 | I9: =SUM(H9-H8) -> 0 | J9: =IF(G9>0,I9/G9,0) -> 0 | K9: =K8 -> 1925 | L9: =K9-K8 -> 0 | M9: =M8 -> 140981 | N9: =M9-M8 -> 0 | O9: =SUM(L9*$J$1) -> 0 | P9: =P8 -> 1770 | Q9: =Q8 -> 150466 | R9: =Q9-Q8 -> 0 | S9: =SUM(P9-P8) -> 0 | T9: =SUM(S9*$T$2) -> 0 | U9: =SUM(G9+L9+S9) -> 0 | V9: =R9+N9+I9:I9 -> 0 | W9: =SUM(V9/U9) -> #DIV/0! | X9: =X8 -> 2417 | Y9: =X9-X8 -> 0 | Z9: =Z8 -> 135871 | AA9: =Z9-Z8 -> 0 | AB9: =SUM(Y9*$AB$2) -> 0 | AC9: =AC8 -> 1829 | AD9: =AC9-AC8 -> 0 | AE9: =AE8 -> 359149.7 | AF9: =AE9-AE8 -> 0 | AG9: =IF(AD9>0,AF9/AD9,0) -> 0 | AH9: =AF9+AA9 -> 0 | AI9: =SUM(AH9+V9) -> 0 | AJ9: =-tanks!AW10 -> 0 | AK9: =SUM(AJ9-AI9) -> 0 | AL9: =S9+L9+G9 -> 0 | AM9: =Y9+AD9 -> 0 | AN9: =AN8 -> 72 | AO9: =(AN9/100)*3000 -> 2160 | AP9: =AP8 -> 75 | AQ9: =(AP9/100)*3000 -> 2250 | AR9: =AR8 -> 60 | AS9: =(AR9/100)*3000 -> 1800 | AT9: =SUM(AO9+AQ9+AS9) -> 6210 | AU9: =AT8-AT9+AV9 -> 0 | AX9: =IF(AV9>0,AW9,AX8) -> 0.7
A10: =ELEC!C8 -> 43957 | B10: =B9 -> 232 | C10: =C9 -> 239 | D10: =C9-C10 -> 0 | E10: =D10*8.38 -> 0 | F10: =F9 -> 1541 | G10: =F10-F9 -> 0 | H10: =H9 -> 349488 | I10: =SUM(H10-H9) -> 0 | J10: =IF(G10>0,I10/G10,0) -> 0 | K10: =K9 -> 1925 | L10: =K10-K9 -> 0 | M10: =M9 -> 140981 | N10: =M10-M9 -> 0 | O10: =SUM(L10*$J$1) -> 0 | P10: =P9 -> 1770 | Q10: =Q9 -> 150466 | R10: =Q10-Q9 -> 0 | S10: =SUM(P10-P9) -> 0 | T10: =SUM(S10*$T$2) -> 0 | U10: =SUM(G10+L10+S10) -> 0 | V10: =R10+N10+I10:I10 -> 0 | W10: =SUM(V10/U10) -> #DIV/0! | X10: =X9 -> 2417 | Y10: =X10-X9 -> 0 | Z10: =Z9 -> 135871 | AA10: =Z10-Z9 -> 0 | AB10: =SUM(Y10*$AB$2) -> 0 | AC10: =AC9 -> 1829 | AD10: =AC10-AC9 -> 0 | AE10: =AE9 -> 359149.7 | AF10: =AE10-AE9 -> 0 | AG10: =IF(AD10>0,AF10/AD10,0) -> 0 | AH10: =AF10+AA10 -> 0 | AI10: =SUM(AH10+V10) -> 0 | AJ10: =-tanks!AW11 -> 0 | AK10: =SUM(AJ10-AI10) -> 0 | AL10: =S10+L10+G10 -> 0 | AM10: =Y10+AD10 -> 0 | AN10: =AN9 -> 72 | AO10: =(AN10/100)*3000 -> 2160 | AP10: =AP9 -> 75 | AQ10: =(AP10/100)*3000 -> 2250 | AR10: =AR9 -> 60 | AS10: =(AR10/100)*3000 -> 1800 | AT10: =SUM(AO10+AQ10+AS10) -> 6210 | AU10: =AT9-AT10+AV10 -> 0 | AX10: =IF(AV10>0,AW10,AX9) -> 0.7
A11: =ELEC!C9 -> 43958 | B11: =B10 -> 232 | C11: =C10 -> 239 | D11: =C10-C11 -> 0 | E11: =D11*8.38 -> 0 | F11: =F10 -> 1541 | G11: =F11-F10 -> 0 | H11: =H10 -> 349488 | I11: =SUM(H11-H10) -> 0 | J11: =IF(G11>0,I11/G11,0) -> 0 | K11: =K10 -> 1925 | L11: =K11-K10 -> 0 | M11: =M10 -> 140981 | N11: =M11-M10 -> 0 | O11: =SUM(L11*$J$1) -> 0 | P11: =P10 -> 1770 | Q11: =Q10 -> 150466 | R11: =Q11-Q10 -> 0 | S11: =SUM(P11-P10) -> 0 | T11: =SUM(S11*$T$2) -> 0 | U11: =SUM(G11+L11+S11) -> 0 | V11: =R11+N11+I11:I11 -> 0 | W11: =SUM(V11/U11) -> #DIV/0! | X11: =X10 -> 2417 | Y11: =X11-X10 -> 0 | Z11: =Z10 -> 135871 | AA11: =Z11-Z10 -> 0 | AB11: =SUM(Y11*$AB$2) -> 0 | AC11: =AC10 -> 1829 | AD11: =AC11-AC10 -> 0 | AE11: =AE10 -> 359149.7 | AF11: =AE11-AE10 -> 0 | AG11: =IF(AD11>0,AF11/AD11,0) -> 0 | AH11: =AF11+AA11 -> 0 | AI11: =SUM(AH11+V11) -> 0 | AJ11: =-tanks!AW12 -> 0 | AK11: =SUM(AJ11-AI11) -> 0 | AL11: =S11+L11+G11 -> 0 | AM11: =Y11+AD11 -> 0 | AN11: =AN10 -> 72 | AO11: =(AN11/100)*3000 -> 2160 | AP11: =AP10 -> 75 | AQ11: =(AP11/100)*3000 -> 2250 | AR11: =AR10 -> 60 | AS11: =(AR11/100)*3000 -> 1800 | AT11: =SUM(AO11+AQ11+AS11) -> 6210 | AU11: =AT10-AT11+AV11 -> 0 | AX11: =IF(AV11>0,AW11,AX10) -> 0.7
A12: =ELEC!C10 -> 43959 | B12: =B11 -> 232 | C12: =C11 -> 239 | D12: =C11-C12 -> 0 | E12: =D12*8.38 -> 0 | F12: =F11 -> 1541 | G12: =F12-F11 -> 0 | H12: =H11 -> 349488 | I12: =SUM(H12-H11) -> 0 | J12: =IF(G12>0,I12/G12,0) -> 0 | K12: =K11 -> 1925 | L12: =K12-K11 -> 0 | M12: =M11 -> 140981 | N12: =M12-M11 -> 0 | O12: =SUM(L12*$J$1) -> 0 | P12: =P11 -> 1770 | Q12: =Q11 -> 150466 | R12: =Q12-Q11 -> 0 | S12: =SUM(P12-P11) -> 0 | T12: =SUM(S12*$T$2) -> 0 | U12: =SUM(G12+L12+S12) -> 0 | V12: =R12+N12+I12:I12 -> 0 | W12: =SUM(V12/U12) -> #DIV/0! | X12: =X11 -> 2417 | Y12: =X12-X11 -> 0 | Z12: =Z11 -> 135871 | AA12: =Z12-Z11 -> 0 | AB12: =SUM(Y12*$AB$2) -> 0 | AC12: =AC11 -> 1829 | AD12: =AC12-AC11 -> 0 | AE12: =AE11 -> 359149.7 | AF12: =AE12-AE11 -> 0 | AG12: =IF(AD12>0,AF12/AD12,0) -> 0 | AH12: =AF12+AA12 -> 0 | AI12: =SUM(AH12+V12) -> 0 | AJ12: =-tanks!AW13 -> 0 | AK12: =SUM(AJ12-AI12) -> 0 | AL12: =S12+L12+G12 -> 0 | AM12: =Y12+AD12 -> 0 | AN12: =AN11 -> 72 | AO12: =(AN12/100)*3000 -> 2160 | AP12: =AP11 -> 75 | AQ12: =(AP12/100)*3000 -> 2250 | AR12: =AR11 -> 60 | AS12: =(AR12/100)*3000 -> 1800 | AT12: =SUM(AO12+AQ12+AS12) -> 6210 | AU12: =AT11-AT12+AV12 -> 0 | AX12: =IF(AV12>0,AW12,AX11) -> 0.7
A13: =ELEC!C11 -> 43960 | B13: =B12 -> 232 | C13: =C12 -> 239 | D13: =C12-C13 -> 0 | E13: =D13*8.38 -> 0 | F13: =F12 -> 1541 | G13: =F13-F12 -> 0 | H13: =H12 -> 349488 | I13: =SUM(H13-H12) -> 0 | J13: =IF(G13>0,I13/G13,0) -> 0 | K13: =K12 -> 1925 | L13: =K13-K12 -> 0 | M13: =M12 -> 140981 | N13: =M13-M12 -> 0 | O13: =SUM(L13*$J$1) -> 0 | P13: =P12 -> 1770 | Q13: =Q12 -> 150466 | R13: =Q13-Q12 -> 0 | S13: =SUM(P13-P12) -> 0 | T13: =SUM(S13*$T$2) -> 0 | U13: =SUM(G13+L13+S13) -> 0 | V13: =R13+N13+I13:I13 -> 0 | W13: =SUM(V13/U13) -> #DIV/0! | X13: =X12 -> 2417 | Y13: =X13-X12 -> 0 | Z13: =Z12 -> 135871 | AA13: =Z13-Z12 -> 0 | AB13: =SUM(Y13*$AB$2) -> 0 | AC13: =AC12 -> 1829 | AD13: =AC13-AC12 -> 0 | AE13: =AE12 -> 359149.7 | AF13: =AE13-AE12 -> 0 | AG13: =IF(AD13>0,AF13/AD13,0) -> 0 | AH13: =AF13+AA13 -> 0 | AI13: =SUM(AH13+V13) -> 0 | AJ13: =-tanks!AW14 -> 0 | AK13: =SUM(AJ13-AI13) -> 0 | AL13: =S13+L13+G13 -> 0 | AM13: =Y13+AD13 -> 0 | AN13: =AN12 -> 72 | AO13: =(AN13/100)*3000 -> 2160 | AP13: =AP12 -> 75 | AQ13: =(AP13/100)*3000 -> 2250 | AR13: =AR12 -> 60 | AS13: =(AR13/100)*3000 -> 1800 | AT13: =SUM(AO13+AQ13+AS13) -> 6210 | AU13: =AT12-AT13+AV13 -> 0 | AX13: =IF(AV13>0,AW13,AX12) -> 0.7
A14: =ELEC!C12 -> 43961 | B14: =B13 -> 232 | C14: =C13 -> 239 | D14: =C13-C14 -> 0 | E14: =D14*8.38 -> 0 | F14: =F13 -> 1541 | G14: =F14-F13 -> 0 | H14: =H13 -> 349488 | I14: =SUM(H14-H13) -> 0 | J14: =IF(G14>0,I14/G14,0) -> 0 | K14: =K13 -> 1925 | L14: =K14-K13 -> 0 | M14: =M13 -> 140981 | N14: =M14-M13 -> 0 | O14: =SUM(L14*$J$1) -> 0 | P14: =P13 -> 1770 | Q14: =Q13 -> 150466 | R14: =Q14-Q13 -> 0 | S14: =SUM(P14-P13) -> 0 | T14: =SUM(S14*$T$2) -> 0 | U14: =SUM(G14+L14+S14) -> 0 | V14: =R14+N14+I14:I14 -> 0 | W14: =SUM(V14/U14) -> #DIV/0! | X14: =X13 -> 2417 | Y14: =X14-X13 -> 0 | Z14: =Z13 -> 135871 | AA14: =Z14-Z13 -> 0 | AB14: =SUM(Y14*$AB$2) -> 0 | AC14: =AC13 -> 1829 | AD14: =AC14-AC13 -> 0 | AE14: =AE13 -> 359149.7 | AF14: =AE14-AE13 -> 0 | AG14: =IF(AD14>0,AF14/AD14,0) -> 0 | AH14: =AF14+AA14 -> 0 | AI14: =SUM(AH14+V14) -> 0 | AJ14: =-tanks!AW15 -> 0 | AK14: =SUM(AJ14-AI14) -> 0 | AL14: =S14+L14+G14 -> 0 | AM14: =Y14+AD14 -> 0 | AN14: =AN13 -> 72 | AO14: =(AN14/100)*3000 -> 2160 | AP14: =AP13 -> 75 | AQ14: =(AP14/100)*3000 -> 2250 | AR14: =AR13 -> 60 | AS14: =(AR14/100)*3000 -> 1800 | AT14: =SUM(AO14+AQ14+AS14) -> 6210 | AU14: =AT13-AT14+AV14 -> 0 | AX14: =IF(AV14>0,AW14,AX13) -> 0.7
A15: =ELEC!C13 -> 43962 | B15: =B14 -> 232 | C15: =C14 -> 239 | D15: =C14-C15 -> 0 | E15: =D15*8.38 -> 0 | F15: =F14 -> 1541 | G15: =F15-F14 -> 0 | H15: =H14 -> 349488 | I15: =SUM(H15-H14) -> 0 | J15: =IF(G15>0,I15/G15,0) -> 0 | K15: =K14 -> 1925 | L15: =K15-K14 -> 0 | M15: =M14 -> 140981 | N15: =M15-M14 -> 0 | O15: =SUM(L15*$J$1) -> 0 | P15: =P14 -> 1770 | Q15: =Q14 -> 150466 | R15: =Q15-Q14 -> 0 | S15: =SUM(P15-P14) -> 0 | T15: =SUM(S15*$T$2) -> 0 | U15: =SUM(G15+L15+S15) -> 0 | V15: =R15+N15+I15:I15 -> 0 | W15: =SUM(V15/U15) -> #DIV/0! | X15: =X14 -> 2417 | Y15: =X15-X14 -> 0 | Z15: =Z14 -> 135871 | AA15: =Z15-Z14 -> 0 | AB15: =SUM(Y15*$AB$2) -> 0 | AC15: =AC14 -> 1829 | AD15: =AC15-AC14 -> 0 | AE15: =AE14 -> 359149.7 | AF15: =AE15-AE14 -> 0 | AG15: =IF(AD15>0,AF15/AD15,0) -> 0 | AH15: =AF15+AA15 -> 0 | AI15: =SUM(AH15+V15) -> 0 | AJ15: =-tanks!AW16 -> 0 | AK15: =SUM(AJ15-AI15) -> 0 | AL15: =S15+L15+G15 -> 0 | AM15: =Y15+AD15 -> 0 | AN15: =AN14 -> 72 | AO15: =(AN15/100)*3000 -> 2160 | AP15: =AP14 -> 75 | AQ15: =(AP15/100)*3000 -> 2250 | AR15: =AR14 -> 60 | AS15: =(AR15/100)*3000 -> 1800 | AT15: =SUM(AO15+AQ15+AS15) -> 6210 | AU15: =AT14-AT15+AV15 -> 0 | AX15: =IF(AV15>0,AW15,AX14) -> 0.7
A16: =ELEC!C14 -> 43963 | B16: =B15 -> 232 | C16: =C15 -> 239 | D16: =C15-C16 -> 0 | E16: =D16*8.38 -> 0 | F16: =F15 -> 1541 | G16: =F16-F15 -> 0 | H16: =H15 -> 349488 | I16: =SUM(H16-H15) -> 0 | J16: =IF(G16>0,I16/G16,0) -> 0 | K16: =K15 -> 1925 | L16: =K16-K15 -> 0 | M16: =M15 -> 140981 | N16: =M16-M15 -> 0 | O16: =SUM(L16*$J$1) -> 0 | P16: =P15 -> 1770 | Q16: =Q15 -> 150466 | R16: =Q16-Q15 -> 0 | S16: =SUM(P16-P15) -> 0 | T16: =SUM(S16*$T$2) -> 0 | U16: =SUM(G16+L16+S16) -> 0 | V16: =R16+N16+I16:I16 -> 0 | W16: =SUM(V16/U16) -> #DIV/0! | X16: =X15 -> 2417 | Y16: =X16-X15 -> 0 | Z16: =Z15 -> 135871 | AA16: =Z16-Z15 -> 0 | AB16: =SUM(Y16*$AB$2) -> 0 | AC16: =AC15 -> 1829 | AD16: =AC16-AC15 -> 0 | AE16: =AE15 -> 359149.7 | AF16: =AE16-AE15 -> 0 | AG16: =IF(AD16>0,AF16/AD16,0) -> 0 | AH16: =AF16+AA16 -> 0 | AI16: =SUM(AH16+V16) -> 0 | AJ16: =-tanks!AW17 -> 0 | AK16: =SUM(AJ16-AI16) -> 0 | AL16: =S16+L16+G16 -> 0 | AM16: =Y16+AD16 -> 0 | AN16: =AN15 -> 72 | AO16: =(AN16/100)*3000 -> 2160 | AP16: =AP15 -> 75 | AQ16: =(AP16/100)*3000 -> 2250 | AR16: =AR15 -> 60 | AS16: =(AR16/100)*3000 -> 1800 | AT16: =SUM(AO16+AQ16+AS16) -> 6210 | AU16: =AT15-AT16+AV16 -> 0 | AX16: =IF(AV16>0,AW16,AX15) -> 0.7
A17: =ELEC!C15 -> 43964 | B17: =B16 -> 232 | C17: =C16 -> 239 | D17: =C16-C17 -> 0 | E17: =D17*8.38 -> 0 | F17: =F16 -> 1541 | G17: =F17-F16 -> 0 | H17: =H16 -> 349488 | I17: =SUM(H17-H16) -> 0 | J17: =IF(G17>0,I17/G17,0) -> 0 | K17: =K16 -> 1925 | L17: =K17-K16 -> 0 | M17: =M16 -> 140981 | N17: =M17-M16 -> 0 | O17: =SUM(L17*$J$1) -> 0 | P17: =P16 -> 1770 | Q17: =Q16 -> 150466 | R17: =Q17-Q16 -> 0 | S17: =SUM(P17-P16) -> 0 | T17: =SUM(S17*$T$2) -> 0 | U17: =SUM(G17+L17+S17) -> 0 | V17: =R17+N17+I17:I17 -> 0 | X17: =X16 -> 2417 | Y17: =X17-X16 -> 0 | Z17: =Z16 -> 135871 | AA17: =Z17-Z16 -> 0 | AB17: =SUM(Y17*$AB$2) -> 0 | AC17: =AC16 -> 1829 | AD17: =AC17-AC16 -> 0 | AE17: =AE16 -> 359149.7 | AF17: =AE17-AE16 -> 0 | AG17: =IF(AD17>0,AF17/AD17,0) -> 0 | AH17: =AF17+AA17 -> 0 | AI17: =SUM(AH17+V17) -> 0 | AJ17: =-tanks!AW18 -> 0 | AK17: =SUM(AJ17-AI17) -> 0 | AL17: =S17+L17+G17 -> 0 | AM17: =Y17+AD17 -> 0 | AN17: =AN16 -> 72 | AO17: =(AN17/100)*3000 -> 2160 | AP17: =AP16 -> 75 | AQ17: =(AP17/100)*3000 -> 2250 | AR17: =AR16 -> 60 | AS17: =(AR17/100)*3000 -> 1800 | AT17: =SUM(AO17+AQ17+AS17) -> 6210 | AU17: =AT16-AT17+AV17 -> 0 | AX17: =IF(AV17>0,AW17,AX16) -> 0.7
A18: =ELEC!C16 -> 43965 | B18: =B17 -> 232 | C18: =C17 -> 239 | D18: =C17-C18 -> 0 | E18: =D18*8.38 -> 0 | F18: =F17 -> 1541 | G18: =F18-F17 -> 0 | H18: =H17 -> 349488 | I18: =SUM(H18-H17) -> 0 | J18: =IF(G18>0,I18/G18,0) -> 0 | K18: =K17 -> 1925 | L18: =K18-K17 -> 0 | M18: =M17 -> 140981 | N18: =M18-M17 -> 0 | O18: =SUM(L18*$J$1) -> 0 | P18: =P17 -> 1770 | Q18: =Q17 -> 150466 | R18: =Q18-Q17 -> 0 | S18: =SUM(P18-P17) -> 0 | T18: =SUM(S18*$T$2) -> 0 | U18: =SUM(G18+L18+S18) -> 0 | V18: =R18+N18+I18:I18 -> 0 | X18: =X17 -> 2417 | Y18: =X18-X17 -> 0 | Z18: =Z17 -> 135871 | AA18: =Z18-Z17 -> 0 | AB18: =SUM(Y18*$AB$2) -> 0 | AC18: =AC17 -> 1829 | AD18: =AC18-AC17 -> 0 | AE18: =AE17 -> 359149.7 | AF18: =AE18-AE17 -> 0 | AG18: =IF(AD18>0,AF18/AD18,0) -> 0 | AH18: =AF18+AA18 -> 0 | AI18: =SUM(AH18+V18) -> 0 | AJ18: =-tanks!AW19 -> 0 | AK18: =SUM(AJ18-AI18) -> 0 | AL18: =S18+L18+G18 -> 0 | AM18: =Y18+AD18 -> 0 | AN18: =AN17 -> 72 | AO18: =(AN18/100)*3000 -> 2160 | AP18: =AP17 -> 75 | AQ18: =(AP18/100)*3000 -> 2250 | AR18: =AR17 -> 60 | AS18: =(AR18/100)*3000 -> 1800 | AT18: =SUM(AO18+AQ18+AS18) -> 6210 | AU18: =AT17-AT18+AV18 -> 0 | AX18: =IF(AV18>0,AW18,AX17) -> 0.7
A19: =ELEC!C17 -> 43966 | B19: =B18 -> 232 | C19: =C18 -> 239 | D19: =C18-C19 -> 0 | E19: =D19*8.38 -> 0 | F19: =F18 -> 1541 | G19: =F19-F18 -> 0 | H19: =H18 -> 349488 | I19: =SUM(H19-H18) -> 0 | J19: =IF(G19>0,I19/G19,0) -> 0 | K19: =K18 -> 1925 | L19: =K19-K18 -> 0 | M19: =M18 -> 140981 | N19: =M19-M18 -> 0 | O19: =SUM(L19*$J$1) -> 0 | P19: =P18 -> 1770 | Q19: =Q18 -> 150466 | R19: =Q19-Q18 -> 0 | S19: =SUM(P19-P18) -> 0 | T19: =SUM(S19*$T$2) -> 0 | U19: =SUM(G19+L19+S19) -> 0 | V19: =R19+N19+I19:I19 -> 0 | X19: =X18 -> 2417 | Y19: =X19-X18 -> 0 | Z19: =Z18 -> 135871 | AA19: =Z19-Z18 -> 0 | AB19: =SUM(Y19*$AB$2) -> 0 | AC19: =AC18 -> 1829 | AD19: =AC19-AC18 -> 0 | AE19: =AE18 -> 359149.7 | AF19: =AE19-AE18 -> 0 | AG19: =IF(AD19>0,AF19/AD19,0) -> 0 | AH19: =AF19+AA19 -> 0 | AI19: =SUM(AH19+V19) -> 0 | AJ19: =-tanks!AW20 -> 0 | AK19: =SUM(AJ19-AI19) -> 0 | AL19: =S19+L20+G19 -> 0 | AM19: =Y19+AD19 -> 0 | AN19: =AN18 -> 72 | AO19: =(AN19/100)*3000 -> 2160 | AP19: =AP18 -> 75 | AQ19: =(AP19/100)*3000 -> 2250 | AR19: =AR18 -> 60 | AS19: =(AR19/100)*3000 -> 1800 | AT19: =SUM(AO19+AQ19+AS19) -> 6210 | AU19: =AT18-AT19+AV19 -> 0 | AX19: =IF(AV19>0,AW19,AX18) -> 0.7
A20: =ELEC!C18 -> 43967 | B20: =B19 -> 232 | C20: =C19 -> 239 | D20: =C19-C20 -> 0 | E20: =D20*8.38 -> 0 | F20: =F19 -> 1541 | G20: =F20-F19 -> 0 | H20: =H19 -> 349488 | I20: =SUM(H20-H19) -> 0 | J20: =IF(G20>0,I20/G20,0) -> 0 | K20: =K19 -> 1925 | L20: =K20-K19 -> 0 | M20: =M19 -> 140981 | N20: =M20-M19 -> 0 | O20: =SUM(L20*$J$1) -> 0 | P20: =P19 -> 1770 | Q20: =Q19 -> 150466 | R20: =Q20-Q19 -> 0 | S20: =SUM(P20-P19) -> 0 | T20: =SUM(S20*$T$2) -> 0 | U20: =SUM(G20+L20+S20) -> 0 | V20: =R20+N20+I20:I20 -> 0 | X20: =X19 -> 2417 | Y20: =X20-X19 -> 0 | Z20: =Z19 -> 135871 | AA20: =Z20-Z19 -> 0 | AB20: =SUM(Y20*$AB$2) -> 0 | AC20: =AC19 -> 1829 | AD20: =AC20-AC19 -> 0 | AE20: =AE19 -> 359149.7 | AF20: =AE20-AE19 -> 0 | AG20: =IF(AD20>0,AF20/AD20,0) -> 0 | AH20: =AF20+AA20 -> 0 | AI20: =SUM(AH20+V20) -> 0 | AJ20: =-tanks!AW21 -> 0 | AK20: =SUM(AJ20-AI20) -> 0 | AL20: =S20+L21+G20 -> 0 | AM20: =Y20+AD20 -> 0 | AN20: =AN19 -> 72 | AO20: =(AN20/100)*3000 -> 2160 | AP20: =AP19 -> 75 | AQ20: =(AP20/100)*3000 -> 2250 | AR20: =AR19 -> 60 | AS20: =(AR20/100)*3000 -> 1800 | AT20: =SUM(AO20+AQ20+AS20) -> 6210 | AU20: =AT19-AT20+AV20 -> 0 | AX20: =IF(AV20>0,AW20,AX19) -> 0.7
A21: =ELEC!C19 -> 43968 | B21: =B20 -> 232 | C21: =C20 -> 239 | D21: =C20-C21 -> 0 | E21: =D21*8.38 -> 0 | F21: =F20 -> 1541 | G21: =F21-F20 -> 0 | H21: =H20 -> 349488 | I21: =SUM(H21-H20) -> 0 | J21: =IF(G21>0,I21/G21,0) -> 0 | K21: =K20 -> 1925 | L21: =K21-K20 -> 0 | M21: =M20 -> 140981 | N21: =M21-M20 -> 0 | O21: =SUM(L21*$J$1) -> 0 | P21: =P20 -> 1770 | Q21: =Q20 -> 150466 | R21: =Q21-Q20 -> 0 | S21: =SUM(P21-P20) -> 0 | T21: =SUM(S21*$T$2) -> 0 | U21: =SUM(G21+L21+S21) -> 0 | V21: =R21+N21+I21:I21 -> 0 | X21: =X20 -> 2417 | Y21: =X21-X20 -> 0 | Z21: =Z20 -> 135871 | AA21: =Z21-Z20 -> 0 | AB21: =SUM(Y21*$AB$2) -> 0 | AC21: =AC20 -> 1829 | AD21: =AC21-AC20 -> 0 | AE21: =AE20 -> 359149.7 | AF21: =AE21-AE20 -> 0 | AG21: =IF(AD21>0,AF21/AD21,0) -> 0 | AH21: =AF21+AA21 -> 0 | AI21: =SUM(AH21+V21) -> 0 | AJ21: =-tanks!AW22 -> 0 | AK21: =SUM(AJ21-AI21) -> 0 | AL21: =S21+L21+G21 -> 0 | AM21: =Y21+AD21 -> 0 | AN21: =AN20 -> 72 | AO21: =(AN21/100)*3000 -> 2160 | AP21: =AP20 -> 75 | AQ21: =(AP21/100)*3000 -> 2250 | AR21: =AR20 -> 60 | AS21: =(AR21/100)*3000 -> 1800 | AT21: =SUM(AO21+AQ21+AS21) -> 6210 | AU21: =AT20-AT21+AV21 -> 0 | AX21: =IF(AV21>0,AW21,AX20) -> 0.7
A22: =ELEC!C20 -> 43969 | B22: =B21 -> 232 | C22: =C21 -> 239 | D22: =C21-C22 -> 0 | E22: =D22*8.38 -> 0 | F22: =F21 -> 1541 | G22: =F22-F21 -> 0 | H22: =H21 -> 349488 | I22: =SUM(H22-H21) -> 0 | J22: =IF(G22>0,I22/G22,0) -> 0 | K22: =K21 -> 1925 | L22: =K22-K21 -> 0 | M22: =M21 -> 140981 | N22: =M22-M21 -> 0 | O22: =SUM(L22*$J$1) -> 0 | P22: =P21 -> 1770 | Q22: =Q21 -> 150466 | R22: =Q22-Q21 -> 0 | S22: =SUM(P22-P21) -> 0 | T22: =SUM(S22*$T$2) -> 0 | U22: =SUM(G22+L22+S22) -> 0 | V22: =R22+N22+I22:I22 -> 0 | X22: =X21 -> 2417 | Y22: =X22-X21 -> 0 | Z22: =Z21 -> 135871 | AA22: =Z22-Z21 -> 0 | AB22: =SUM(Y22*$AB$2) -> 0 | AC22: =AC21 -> 1829 | AD22: =AC22-AC21 -> 0 | AE22: =AE21 -> 359149.7 | AF22: =AE22-AE21 -> 0 | AG22: =IF(AD22>0,AF22/AD22,0) -> 0 | AH22: =AF22+AA22 -> 0 | AI22: =SUM(AH22+V22) -> 0 | AJ22: =-tanks!AW23 -> 0 | AK22: =SUM(AJ22-AI22) -> 0 | AL22: =S22+L22+G22 -> 0 | AM22: =Y22+AD22 -> 0 | AN22: =AN21 -> 72 | AO22: =(AN22/100)*3000 -> 2160 | AP22: =AP21 -> 75 | AQ22: =(AP22/100)*3000 -> 2250 | AR22: =AR21 -> 60 | AS22: =(AR22/100)*3000 -> 1800 | AT22: =SUM(AO22+AQ22+AS22) -> 6210 | AU22: =AT21-AT22+AV22 -> 0 | AX22: =IF(AV22>0,AW22,AX21) -> 0.7
A23: =ELEC!C21 -> 43970 | B23: =B22 -> 232 | C23: =C22 -> 239 | D23: =C22-C23 -> 0 | E23: =D23*8.38 -> 0 | F23: =F22 -> 1541 | G23: =F23-F22 -> 0 | H23: =H22 -> 349488 | I23: =SUM(H23-H22) -> 0 | J23: =IF(G23>0,I23/G23,0) -> 0 | K23: =K22 -> 1925 | L23: =K23-K22 -> 0 | M23: =M22 -> 140981 | N23: =M23-M22 -> 0 | O23: =SUM(L23*$J$1) -> 0 | P23: =P22 -> 1770 | Q23: =Q22 -> 150466 | R23: =Q23-Q22 -> 0 | S23: =SUM(P23-P22) -> 0 | T23: =SUM(S23*$T$2) -> 0 | U23: =SUM(G23+L23+S23) -> 0 | V23: =R23+N23+I23:I23 -> 0 | X23: =X22 -> 2417 | Y23: =X23-X22 -> 0 | Z23: =Z22 -> 135871 | AA23: =Z23-Z22 -> 0 | AB23: =SUM(Y23*$AB$2) -> 0 | AC23: =AC22 -> 1829 | AD23: =AC23-AC22 -> 0 | AE23: =AE22 -> 359149.7 | AF23: =AE23-AE22 -> 0 | AG23: =IF(AD23>0,AF23/AD23,0) -> 0 | AH23: =AF23+AA23 -> 0 | AI23: =SUM(AH23+V23) -> 0 | AJ23: =-tanks!AW24 -> 0 | AK23: =SUM(AJ23-AI23) -> 0 | AL23: =S23+L23+G23 -> 0 | AM23: =Y23+AD23 -> 0 | AN23: =AN22 -> 72 | AO23: =(AN23/100)*3000 -> 2160 | AP23: =AP22 -> 75 | AQ23: =(AP23/100)*3000 -> 2250 | AR23: =AR22 -> 60 | AS23: =(AR23/100)*3000 -> 1800 | AT23: =SUM(AO23+AQ23+AS23) -> 6210 | AU23: =AT22-AT23+AV23 -> 0 | AX23: =IF(AV23>0,AW23,AX22) -> 0.7
A24: =ELEC!C22 -> 43971 | B24: =B23 -> 232 | C24: =C23 -> 239 | D24: =C23-C24 -> 0 | E24: =D24*8.38 -> 0 | F24: =F23 -> 1541 | G24: =F24-F23 -> 0 | H24: =H23 -> 349488 | I24: =SUM(H24-H23) -> 0 | J24: =IF(G24>0,I24/G24,0) -> 0 | K24: =K23 -> 1925 | L24: =K24-K23 -> 0 | M24: =M23 -> 140981 | N24: =M24-M23 -> 0 | O24: =SUM(L24*$J$1) -> 0 | P24: =P23 -> 1770 | Q24: =Q23 -> 150466 | R24: =Q24-Q23 -> 0 | S24: =SUM(P24-P23) -> 0 | T24: =SUM(S24*$T$2) -> 0 | U24: =SUM(G24+L24+S24) -> 0 | V24: =R24+N24+I24:I24 -> 0 | X24: =X23 -> 2417 | Y24: =X24-X23 -> 0 | Z24: =Z23 -> 135871 | AA24: =Z24-Z23 -> 0 | AB24: =SUM(Y24*$AB$2) -> 0 | AC24: =AC23 -> 1829 | AD24: =AC24-AC23 -> 0 | AE24: =AE23 -> 359149.7 | AF24: =AE24-AE23 -> 0 | AG24: =IF(AD24>0,AF24/AD24,0) -> 0 | AH24: =AF24+AA24 -> 0 | AI24: =SUM(AH24+V24) -> 0 | AJ24: =-tanks!AW25 -> 0 | AK24: =SUM(AJ24-AI24) -> 0 | AL24: =S24+L24+G24 -> 0 | AM24: =Y24+AD24 -> 0 | AN24: =AN23 -> 72 | AO24: =(AN24/100)*3000 -> 2160 | AP24: =AP23 -> 75 | AQ24: =(AP24/100)*3000 -> 2250 | AR24: =AR23 -> 60 | AS24: =(AR24/100)*3000 -> 1800 | AT24: =SUM(AO24+AQ24+AS24) -> 6210 | AU24: =AT23-AT24+AV24 -> 0 | AX24: =IF(AV24>0,AW24,AX23) -> 0.7
A25: =ELEC!C23 -> 43972 | B25: =B24 -> 232 | C25: =C24 -> 239 | D25: =C24-C25 -> 0 | E25: =D25*8.38 -> 0 | F25: =F24 -> 1541 | G25: =F25-F24 -> 0 | H25: =H24 -> 349488 | I25: =SUM(H25-H24) -> 0 | J25: =IF(G25>0,I25/G25,0) -> 0 | K25: =K24 -> 1925 | L25: =K25-K24 -> 0 | M25: =M24 -> 140981 | N25: =M25-M24 -> 0 | O25: =SUM(L25*$J$1) -> 0 | P25: =P24 -> 1770 | Q25: =Q24 -> 150466 | R25: =Q25-Q24 -> 0 | S25: =SUM(P25-P24) -> 0 | T25: =SUM(S25*$T$2) -> 0 | U25: =SUM(G25+L25+S25) -> 0 | V25: =R25+N25+I25:I25 -> 0 | X25: =X24 -> 2417 | Y25: =X25-X24 -> 0 | Z25: =Z24 -> 135871 | AA25: =Z25-Z24 -> 0 | AB25: =SUM(Y25*$AB$2) -> 0 | AC25: =AC24 -> 1829 | AD25: =AC25-AC24 -> 0 | AE25: =AE24 -> 359149.7 | AF25: =AE25-AE24 -> 0 | AG25: =IF(AD25>0,AF25/AD25,0) -> 0 | AH25: =AF25+AA25 -> 0 | AI25: =SUM(AH25+V25) -> 0 | AJ25: =-tanks!AW26 -> 0 | AK25: =SUM(AJ25-AI25) -> 0 | AL25: =S25+L25+G25 -> 0 | AM25: =Y25+AD25 -> 0 | AN25: =AN24 -> 72 | AO25: =(AN25/100)*3000 -> 2160 | AP25: =AP24 -> 75 | AQ25: =(AP25/100)*3000 -> 2250 | AR25: =AR24 -> 60 | AS25: =(AR25/100)*3000 -> 1800 | AT25: =SUM(AO25+AQ25+AS25) -> 6210 | AU25: =AT24-AT25+AV25 -> 0 | AX25: =IF(AV25>0,AW25,AX24) -> 0.7
