Workbook

Sheet TOTAL
A1: Site Name | B1: Day | C1: Month | D1: Year | E1: Total Electricity Kwh | F1: Electricity Tariff ($/Kwh) | G1: LPG (Kg) | H1: LPG $/Kg | I1: Water Utility Supply (m3) m3 | J1: Water Utility Supply (m3) $/m3 | K1: Room Nights
A2: Seychelles at Desroches Island | B2: 1 | C2: 5 | D2: 2020 | E2: =Submetering!E2+Submetering!F2+Submetering!G2+Submetering!H2-Submetering!AV2 -> 4860 | F2: 0.5876503 | G2: =(Submetering!AX2+Submetering!AY2+Submetering!AZ2+Submetering!BA2+Submetering!BB2) -> 14.652 | H2: 0.99 | I2: ='FS Desroches Daily'!CM4 -> 29 | J2: 10.487298 | K2: ='FS Desroches Daily'!CN4 -> 0
A3: Seychelles at Desroches Island | B3: =B2+1 -> 2 | C3: 5 | D3: 2020 | E3: =Submetering!E3+Submetering!F3+Submetering!G3+Submetering!H3-Submetering!AV3 -> 5190 | F3: =F2 -> 0.5876503 | G3: =(Submetering!AX3+Submetering!AY3+Submetering!AZ3+Submetering!BA3+Submetering!BB3) -> 7.326 | H3: =H2 -> 0.99 | I3: ='FS Desroches Daily'!CM5 -> 29 | J3: =J2 -> 10.487298 | K3: ='FS Desroches Daily'!CN5 -> 0
A4: Seychelles at Desroches Island | B4: =B3+1 -> 3 | C4: 5 | D4: 2020 | E4: =Submetering!E4+Submetering!F4+Submetering!G4+Submetering!H4-Submetering!AV4 -> 4940 | F4: =F3 -> 0.5876503 | G4: =(Submetering!AX4+Submetering!AY4+Submetering!AZ4+Submetering!BA4+Submetering!BB4) -> 7.326 | H4: =H3 -> 0.99 | I4: ='FS Desroches Daily'!CM6 -> 19 | J4: =J3 -> 10.487298 | K4: ='FS Desroches Daily'!CN6 -> 0
A5: Seychelles at Desroches Island | B5: =B4+1 -> 4 | C5: 5 | D5: 2020 | E5: =Submetering!E5+Submetering!F5+Submetering!G5+Submetering!H5-Submetering!AV5 -> 5450 | F5: =F4 -> 0.5876503 | G5: =(Submetering!AX5+Submetering!AY5+Submetering!AZ5+Submetering!BA5+Submetering!BB5) -> 507.3255 | H5: =H4 -> 0.99 | I5: ='FS Desroches Daily'!CM7 -> 25.7 | J5: =J4 -> 10.487298 | K5: ='FS Desroches Daily'!CN7 -> 0
A6: Seychelles at Desroches Island | B6: =B5+1 -> 5 | C6: 5 | D6: 2020 | E6: =Submetering!E6+Submetering!F6+Submetering!G6+Submetering!H6-Submetering!AV6 -> 5590 | F6: =F5 -> 0.5876503 | G6: =(Submetering!AX6+Submetering!AY6+Submetering!AZ6+Submetering!BA6+Submetering!BB6) -> #REF! | H6: =H5 -> 0.99 | I6: ='FS Desroches Daily'!CM8 -> 30.3 | J6: =J5 -> 10.487298 | K6: ='FS Desroches Daily'!CN8 -> 0
A7: Seychelles at Desroches Island | B7: =B6+1 -> 6 | C7: 5 | D7: 2020 | E7: =Submetering!E7+Submetering!F7+Submetering!G7+Submetering!H7-Submetering!AV7 -> 0 | F7: =F6 -> 0.5876503 | G7: =(Submetering!AX7+Submetering!AY7+Submetering!AZ7+Submetering!BA7+Submetering!BB7) -> #REF! | H7: =H6 -> 0.99 | I7: ='FS Desroches Daily'!CM9 -> 0 | J7: =J6 -> 10.487298 | K7: ='FS Desroches Daily'!CN9 -> 0
A8: Seychelles at Desroches Island | B8: =B7+1 -> 7 | C8: 5 | D8: 2020 | E8: =Submetering!E8+Submetering!F8+Submetering!G8+Submetering!H8-Submetering!AV8 -> 0 | F8: =F7 -> 0.5876503 | G8: =(Submetering!AX8+Submetering!AY8+Submetering!AZ8+Submetering!BA8+Submetering!BB8) -> 0 | H8: =H7 -> 0.99 | I8: ='FS Desroches Daily'!CM10 -> 0 | J8: =J7 -> 10.487298 | K8: ='FS Desroches Daily'!CN10 -> 0
A9: Seychelles at Desroches Island | B9: =B8+1 -> 8 | C9: 5 | D9: 2020 | E9: =Submetering!E9+Submetering!F9+Submetering!G9+Submetering!H9-Submetering!AV9 -> 0 | F9: =F8 -> 0.5876503 | G9: =(Submetering!AX9+Submetering!AY9+Submetering!AZ9+Submetering!BA9+Submetering!BB9) -> 0 | H9: =H8 -> 0.99 | I9: ='FS Desroches Daily'!CM11 -> 0 | J9: =J8 -> 10.487298 | K9: ='FS Desroches Daily'!CN11 -> 0
A10: Seychelles at Desroches Island | B10: =B9+1 -> 9 | C10: 5 | D10: 2020 | E10: =Submetering!E10+Submetering!F10+Submetering!G10+Submetering!H10-Submetering!AV10 -> 0 | F10: =F9 -> 0.5876503 | G10: =(Submetering!AX10+Submetering!AY10+Submetering!AZ10+Submetering!BA10+Submetering!BB10) -> 0 | H10: =H9 -> 0.99 | I10: ='FS Desroches Daily'!CM12 -> 0 | J10: =J9 -> 10.487298 | K10: ='FS Desroches Daily'!CN12 -> 0
A11: Seychelles at Desroches Island | B11: =B10+1 -> 10 | C11: 5 | D11: 2020 | E11: =Submetering!E11+Submetering!F11+Submetering!G11+Submetering!H11-Submetering!AV11 -> 0 | F11: =F10 -> 0.5876503 | G11: =(Submetering!AX11+Submetering!AY11+Submetering!AZ11+Submetering!BA11+Submetering!BB11) -> 0 | H11: =H10 -> 0.99 | I11: ='FS Desroches Daily'!CM13 -> 0 | J11: =J10 -> 10.487298 | K11: ='FS Desroches Daily'!CN13 -> 0
A12: Seychelles at Desroches Island | B12: =B11+1 -> 11 | C12: 5 | D12: 2020 | E12: =Submetering!E12+Submetering!F12+Submetering!G12+Submetering!H12-Submetering!AV12 -> 0 | F12: =F11 -> 0.5876503 | G12: =(Submetering!AX12+Submetering!AY12+Submetering!AZ12+Submetering!BA12+Submetering!BB12) -> 0 | H12: =H11 -> 0.99 | I12: ='FS Desroches Daily'!CM14 -> 0 | J12: =J11 -> 10.487298 | K12: ='FS Desroches Daily'!CN14 -> 0
A13: Seychelles at Desroches Island | B13: =B12+1 -> 12 | C13: 5 | D13: 2020 | E13: =Submetering!E13+Submetering!F13+Submetering!G13+Submetering!H13-Submetering!AV13 -> 0 | F13: =F12 -> 0.5876503 | G13: =(Submetering!AX13+Submetering!AY13+Submetering!AZ13+Submetering!BA13+Submetering!BB13) -> 0 | H13: =H12 -> 0.99 | I13: ='FS Desroches Daily'!CM15 -> 0 | J13: =J12 -> 10.487298 | K13: ='FS Desroches Daily'!CN15 -> 0
A14: Seychelles at Desroches Island | B14: =B13+1 -> 13 | C14: 5 | D14: 2020 | E14: =Submetering!E14+Submetering!F14+Submetering!G14+Submetering!H14-Submetering!AV14 -> 0 | F14: =F13 -> 0.5876503 | G14: =(Submetering!AX14+Submetering!AY14+Submetering!AZ14+Submetering!BA14+Submetering!BB14) -> 0 | H14: =H13 -> 0.99 | I14: ='FS Desroches Daily'!CM16 -> 0 | J14: =J13 -> 10.487298 | K14: ='FS Desroches Daily'!CN16 -> 0
... A32: Seychelles at Desroches Island | B32: =B31+1 -> 31 | C32: 5 | D32: 2020 | E32: =Submetering!E32+Submetering!F32+Submetering!G32+Submetering!H32-Submetering!AV32 -> 0 | F32: =F31 -> 0.5876503 | G32: =(Submetering!AX32+Submetering!AY32+Submetering!AZ32+Submetering!BA32+Submetering!BB32) -> 0 | H32: =H31 -> 0.99 | I32: ='FS Desroches Daily'!CM34 -> 0 | J32: =J31 -> 10.487298 | K32: ='FS Desroches Daily'!CN34 -> 0

Sheet Submetering
A1: Site Name | B1: Day | C1: Month | D1: Year | E1: TRF CQ6 -KWh | F1: TRF FQ7 -KWh | G1: MSB BOH Q8 -KWh | H1: EX MAIN Q3 -KWh | I1: TRF DQ2 -KWh | J1: TRF B Q1 -KWh | K1: CANCAN shop -KWh | L1: CANCAN store -KWh | M1: Laundry EQU P D.B -KWh | N1: Laundry lighting -KWh | O1: PANTRY 1 -KWh | P1: PANTRY 2 -KWh | Q1: SPA LIGHT HOUSE -KWh | R1: PANTRY 3 -KWh | S1: PANTRY 4 -KWh | T1: VMC -KWh | U1: VILLA 100/157 -KWh | V1: VILLA 101/158 -KWh | W1: VILLA 102/159 -KWh | X1: VILLA 103/160 -KWh | Y1: VILLA 104/161 -KWh | Z1: VILLA 105/162 -KWh | AA1: VILLA 106/163 -KWh | AB1: VILLA 107/164 -KWh | AC1: VILLA 108/165 -KWh | AD1: VILLA 109/166 -KWh | AE1: VILLA 110 -KWh | AF1: KUMAR&KUMAR -KWh | AG1: BLOCK 15 -KWh | AH1: BLOCK 16 -KWh | AI1: BLOCK 17 -KWh | AJ1: BLOCK 18 -KWh | AK1: BLOCK 19 -KWh | AL1: BLOCK 20 -KWh | AM1: BLOCK 21 -KWh | AN1: BLOCK 22 -KWh | AO1: BLOCK 23 -KWh | AP1: BLOCK 24 -KWh | AQ1: Exhaust Kitchen (Main) -KWh | AR1: Exhaust Kitchen (Breakfast) -KWh | AS1: Exhaust Lighthouse -KWh | AT1: Exhaust Canteen -KWh | AU1: Cold Store -KWh | AV1: RO Plant -KWh | AW1: Water (m3) | AX1: Main kitchen M1 (9598630) - Kg | AY1: Main kitchen M2 (9598611) -Kg | AZ1: Main kitchen M3 (9249533) -Kg | BA1: Lighthouse -Kg | BB1: Canteen -Kg | BC1: Room Nights
A2: Seychelles at Desroches Island | B2: 1 | C2: 5 | D2: 2020 | E2: ='FS Desroches Daily'!D4 -> 1400 | F2: ='FS Desroches Daily'!F4 -> 900 | G2: ='FS Desroches Daily'!H4 -> 1800 | H2: ='FS Desroches Daily'!J4 -> 1200 | I2: ='FS Desroches Daily'!L4 -> 2100 | J2: ='FS Desroches Daily'!N4 -> 1000 | K2: ='FS Desroches Daily'!P4 -> 0 | L2: ='FS Desroches Daily'!R4 -> 4 | M2: ='FS Desroches Daily'!T4 -> 261 | N2: ='FS Desroches Daily'!V4 -> 115 | O2: ='FS Desroches Daily'!X4 -> 180 | P2: ='FS Desroches Daily'!Z4 -> 600 | Q2: ='FS Desroches Daily'!AB4 -> 80 | R2: ='FS Desroches Daily'!AD4 -> 280 | S2: ='FS Desroches Daily'!AF4 -> 500 | T2: ='FS Desroches Daily'!AH4 -> 0.9 | U2: ='FS Desroches Daily'!AJ4 -> 320 | V2: ='FS Desroches Daily'!AL4 -> 0.13 | W2: ='FS Desroches Daily'!AN4 -> 0.1 | X2: ='FS Desroches Daily'!AP4 -> 0.09 | Y2: ='FS Desroches Daily'!AR4 -> 70 | Z2: ='FS Desroches Daily'!AT4 -> 90 | AA2: ='FS Desroches Daily'!AT4 -> 90 | AB2: ='FS Desroches Daily'!AV4 -> 80 | AC2: ='FS Desroches Daily'!AZ4 -> 80 | AD2: ='FS Desroches Daily'!BB4 -> 70 | AE2: ='FS Desroches Daily'!BD4 -> 10 | AF2: ='FS Desroches Daily'!BF4 -> 32 | AG2: ='FS Desroches Daily'!BH4 -> 40 | AH2: ='FS Desroches Daily'!BJ4 -> 30 | AI2: ='FS Desroches Daily'!BL4 -> 30 | AJ2: ='FS Desroches Daily'!BN4 -> 40 | AK2: ='FS Desroches Daily'!BP4 -> 40 | AL2: ='FS Desroches Daily'!BR4 -> 24 | AM2: ='FS Desroches Daily'!BT4 -> 30 | AN2: ='FS Desroches Daily'!BV4 -> 21 | AO2: ='FS Desroches Daily'!BX4 -> 40 | AP2: ='FS Desroches Daily'!BZ4 -> 35 | AQ2: ='FS Desroches Daily'!CB4 -> 0 | AR2: ='FS Desroches Daily'!CD4 -> 0 | AS2: ='FS Desroches Daily'!CF4 -> 0 | AT2: ='FS Desroches Daily'!CH4 -> 61.9 | AU2: ='FS Desroches Daily'!CJ4 -> 197 | AV2: ='FS Desroches Daily'!CL4 -> 440 | AW2: ='FS Desroches Daily'!CM4 -> 29 | AX2: =IF(LPG!F9-LPG!F8<0,"0",(LPG!F9-LPG!F8)*1.8315) -> 0 | AY2: =IF(LPG!H9-LPG!H8<0,"0",(LPG!H9-LPG!H8)*1.8315) -> 0 | AZ2: =IF(LPG!J9-LPG!J8<0,"0",(LPG!J9-LPG!J8)*1.8315) -> 0 | BA2: =IF(LPG!M9-LPG!M8<0,"0",(LPG!M9-LPG!M8)*1.8315) -> 0 | BB2: =IF(LPG!Q9-LPG!Q8<0,"0",(LPG!Q9-LPG!Q8)*1.8315) -> 14.652 | BC2: ='FS Desroches Daily'!CN4 -> 0
A3: Seychelles at Desroches Island | B3: =B2+1 -> 2 | C3: 5 | D3: 2020 | E3: ='FS Desroches Daily'!D5 -> 1600 | F3: ='FS Desroches Daily'!F5 -> 1000 | G3: ='FS Desroches Daily'!H5 -> 1800 | H3: ='FS Desroches Daily'!J5 -> 1200 | I3: ='FS Desroches Daily'!L5 -> 2300 | J3: ='FS Desroches Daily'!N5 -> 1000 | K3: ='FS Desroches Daily'!P5 -> 0 | L3: ='FS Desroches Daily'!R5 -> 7 | M3: ='FS Desroches Daily'!T5 -> 145.4 | N3: ='FS Desroches Daily'!V5 -> 154.7 | O3: ='FS Desroches Daily'!X6 -> 210 | P3: ='FS Desroches Daily'!Z5 -> 600 | Q3: ='FS Desroches Daily'!AB5 -> 100 | R3: ='FS Desroches Daily'!AD5 -> 310 | S3: ='FS Desroches Daily'!AF5 -> 540 | T3: ='FS Desroches Daily'!AH5 -> 0.8 | U3: ='FS Desroches Daily'!AJ5 -> 350 | V3: ='FS Desroches Daily'!AL5 -> 0.17 | W3: ='FS Desroches Daily'!AN5 -> 0.12 | X3: ='FS Desroches Daily'!AP5 -> 0.13 | Y3: ='FS Desroches Daily'!AR5 -> 100 | Z3: ='FS Desroches Daily'!AT5 -> 110 | AA3: ='FS Desroches Daily'!AT5 -> 110 | AB3: ='FS Desroches Daily'!AV5 -> 110 | AC3: ='FS Desroches Daily'!AZ5 -> 90 | AD3: ='FS Desroches Daily'!BB5 -> 80 | AE3: ='FS Desroches Daily'!BD5 -> 10 | AF3: ='FS Desroches Daily'!BF5 -> 36 | AG3: ='FS Desroches Daily'!BH5 -> 30 | AH3: ='FS Desroches Daily'!BJ5 -> 50 | AI3: ='FS Desroches Daily'!BL5 -> 40 | AJ3: ='FS Desroches Daily'!BN5 -> 50 | AK3: ='FS Desroches Daily'!BP5 -> 50 | AL3: ='FS Desroches Daily'!BR5 -> 25 | AM3: ='FS Desroches Daily'!BT5 -> 20 | AN3: ='FS Desroches Daily'!BV5 -> 24 | AO3: ='FS Desroches Daily'!BX5 -> 30 | AP3: ='FS Desroches Daily'!BZ5 -> 39 | AQ3: ='FS Desroches Daily'!CB5 -> 0 | AR3: ='FS Desroches Daily'!CD5 -> 0 | AS3: ='FS Desroches Daily'!CF5 -> 0 | AT3: ='FS Desroches Daily'!CH5 -> 65.8 | AU3: ='FS Desroches Daily'!CJ5 -> 216 | AV3: ='FS Desroches Daily'!CL5 -> 410 | AW3: ='FS Desroches Daily'!CM5 -> 29 | AX3: =IF(LPG!F10-LPG!F9<0,"0",(LPG!F10-LPG!F9)*1.8315) -> 0 | AY3: =IF(LPG!H10-LPG!H9<0,"0",(LPG!H10-LPG!H9)*1.8315) -> 0 | AZ3: =IF(LPG!J10-LPG!J9<0,"0",(LPG!J10-LPG!J9)*1.8315) -> 0 | BA3: =IF(LPG!M10-LPG!M9<0,"0",(LPG!M10-LPG!M9)*1.8315) -> 0 | BB3: =IF(LPG!Q10-LPG!Q9<0,"0",(LPG!Q10-LPG!Q9)*1.8315) -> 7.326 | BC3: ='FS Desroches Daily'!CN5 -> 0
A4: Seychelles at Desroches Island | B4: =B3+1 -> 3 | C4: 5 | D4: 2020 | E4: ='FS Desroches Daily'!D6 -> 1600 | F4: ='FS Desroches Daily'!F6 -> 900 | G4: ='FS Desroches Daily'!H6 -> 1600 | H4: ='FS Desroches Daily'!J6 -> 1200 | I4: ='FS Desroches Daily'!L6 -> 2100 | J4: ='FS Desroches Daily'!N6 -> 1100 | K4: ='FS Desroches Daily'!P6 -> 0 | L4: ='FS Desroches Daily'!R6 -> 6 | M4: ='FS Desroches Daily'!T6 -> 56.6 | N4: ='FS Desroches Daily'!V6 -> 37.3 | O4: ='FS Desroches Daily'!X7 -> 220 | P4: ='FS Desroches Daily'!Z6 -> 600 | Q4: ='FS Desroches Daily'!AB6 -> 100 | R4: ='FS Desroches Daily'!AD6 -> 330 | S4: ='FS Desroches Daily'!AF6 -> 540 | T4: ='FS Desroches Daily'!AH6 -> 0.8 | U4: ='FS Desroches Daily'!AJ6 -> 270 | V4: ='FS Desroches Daily'!AL6 -> 0.18 | W4: ='FS Desroches Daily'!AN6 -> 0.12 | X4: ='FS Desroches Daily'!AP6 -> 0.14 | Y4: ='FS Desroches Daily'!AR6 -> 100 | Z4: ='FS Desroches Daily'!AT6 -> 110 | AA4: ='FS Desroches Daily'!AT6 -> 110 | AB4: ='FS Desroches Daily'!AV6 -> 90 | AC4: ='FS Desroches Daily'!AZ6 -> 100 | AD4: ='FS Desroches Daily'!BB6 -> 80 | AE4: ='FS Desroches Daily'!BD6 -> 10 | AF4: ='FS Desroches Daily'!BF6 -> 30 | AG4: ='FS Desroches Daily'!BH6 -> 30 | AH4: ='FS Desroches Daily'!BJ6 -> 40 | AI4: ='FS Desroches Daily'!BL6 -> 30 | AJ4: ='FS Desroches Daily'!BN6 -> 50 | AK4: ='FS Desroches Daily'!BP6 -> 60 | AL4: ='FS Desroches Daily'!BR6 -> 27 | AM4: ='FS Desroches Daily'!BT6 -> 20 | AN4: ='FS Desroches Daily'!BV6 -> 25 | AO4: ='FS Desroches Daily'!BX6 -> 30 | AP4: ='FS Desroches Daily'!BZ6 -> 39 | AQ4: ='FS Desroches Daily'!CB6 -> 0 | AR4: ='FS Desroches Daily'!CD6 -> 0 | AS4: ='FS Desroches Daily'!CF6 -> 0 | AT4: ='FS Desroches Daily'!CH6 -> 70.2 | AU4: ='FS Desroches Daily'!CJ6 -> 199 | AV4: ='FS Desroches Daily'!CL6 -> 360 | AW4: ='FS Desroches Daily'!CM6 -> 19 | AX4: =IF(LPG!F11-LPG!F10<0,"0",(LPG!F11-LPG!F10)*1.8315) -> 0 | AY4: =IF(LPG!H11-LPG!H10<0,"0",(LPG!H11-LPG!H10)*1.8315) -> 0 | AZ4: =IF(LPG!J13-LPG!J10<0,"0",(LPG!J13-LPG!J10)*1.8315) -> 0 | BA4: =IF(LPG!M11-LPG!M10<0,"0",(LPG!M11-LPG!M10)*1.8315) -> 0 | BB4: =IF(LPG!Q11-LPG!Q10<0,"0",(LPG!Q11-LPG!Q10)*1.8315) -> 7.326 | BC4: ='FS Desroches Daily'!CN6 -> 0
A5: Seychelles at Desroches Island | B5: =B4+1 -> 4 | C5: 5 | D5: 2020 | E5: ='FS Desroches Daily'!D7 -> 1700 | F5: ='FS Desroches Daily'!F7 -> 1000 | G5: ='FS Desroches Daily'!H7 -> 1800 | H5: ='FS Desroches Daily'!J7 -> 1300 | I5: ='FS Desroches Daily'!L7 -> 2500 | J5: ='FS Desroches Daily'!N7 -> 1200 | K5: ='FS Desroches Daily'!P7 -> 0 | L5: ='FS Desroches Daily'!R7 -> 7 | M5: ='FS Desroches Daily'!T7 -> 292.1 | N5: ='FS Desroches Daily'!V7 -> 171.6 | O5: ='FS Desroches Daily'!X8 -> 230 | P5: ='FS Desroches Daily'!Z7 -> 700 | Q5: ='FS Desroches Daily'!AB7 -> 120 | R5: ='FS Desroches Daily'!AD7 -> 360 | S5: ='FS Desroches Daily'!AF7 -> 610 | T5: ='FS Desroches Daily'!AH7 -> 1.3 | U5: ='FS Desroches Daily'!AJ7 -> 280 | V5: ='FS Desroches Daily'!AL7 -> 0.2 | W5: ='FS Desroches Daily'!AN7 -> 0.14 | X5: ='FS Desroches Daily'!AP7 -> 0.11 | Y5: ='FS Desroches Daily'!AR7 -> 110 | Z5: ='FS Desroches Daily'!AT7 -> 130 | AA5: ='FS Desroches Daily'!AT7 -> 130 | AB5: ='FS Desroches Daily'!AV7 -> 120 | AC5: ='FS Desroches Daily'!AZ7 -> 120 | AD5: ='FS Desroches Daily'!BB7 -> 100 | AE5: ='FS Desroches Daily'!BD7 -> 10 | AF5: ='FS Desroches Daily'!BF7 -> 31 | AG5: ='FS Desroches Daily'!BH7 -> 40 | AH5: ='FS Desroches Daily'!BJ7 -> 30 | AI5: ='FS Desroches Daily'!BL7 -> 40 | AJ5: ='FS Desroches Daily'!BN7 -> 40 | AK5: ='FS Desroches Daily'!BP7 -> 50 | AL5: ='FS Desroches Daily'!BR7 -> 27 | AM5: ='FS Desroches Daily'!BT7 -> 30 | AN5: ='FS Desroches Daily'!BV7 -> 28 | AO5: ='FS Desroches Daily'!BX7 -> 40 | AP5: ='FS Desroches Daily'!BZ7 -> 35 | AQ5: ='FS Desroches Daily'!CB7 -> 0 | AR5: ='FS Desroches Daily'!CD7 -> 0 | AS5: ='FS Desroches Daily'!CF7 -> 0 | AT5: ='FS Desroches Daily'!CH7 -> 66.5 | AU5: ='FS Desroches Daily'!CJ7 -> 269 | AV5: ='FS Desroches Daily'!CL7 -> 350 | AW5: ='FS Desroches Daily'!CM7 -> 25.7 | AX5: =IF(LPG!F12-LPG!F11<0,"0",(LPG!F12-LPG!F11)*1.8315) -> 0 | AY5: =IF(LPG!H12-LPG!H11<0,"0",(LPG!H12-LPG!H11)*1.8315) -> 0 | AZ5: =IF(LPG!J12-LPG!J13<0,"0",(LPG!J12-LPG!J13)*1.8315) -> 499.9995 | BA5: =IF(LPG!M12-LPG!M11<0,"0",(LPG!M12-LPG!M11)*1.8315) -> 0 | BB5: =IF(LPG!Q12-LPG!Q11<0,"0",(LPG!Q12-LPG!Q11)*1.8315) -> 7.326 | BC5: ='FS Desroches Daily'!CN7 -> 0
A6: Seychelles at Desroches Island | B6: =B5+1 -> 5 | C6: 5 | D6: 2020 | E6: ='FS Desroches Daily'!D8 -> 1700 | F6: ='FS Desroches Daily'!F8 -> 1000 | G6: ='FS Desroches Daily'!H8 -> 1900 | H6: ='FS Desroches Daily'!J8 -> 1400 | I6: ='FS Desroches Daily'!L8 -> 2400 | J6: ='FS Desroches Daily'!N8 -> 1100 | K6: ='FS Desroches Daily'!P8 -> 0 | L6: ='FS Desroches Daily'!R8 -> 6 | M6: ='FS Desroches Daily'!T8 -> 193.5 | N6: ='FS Desroches Daily'!V8 -> 126.7 | O6: ='FS Desroches Daily'!X8 -> 230 | P6: ='FS Desroches Daily'!Z8 -> 600 | Q6: ='FS Desroches Daily'!AB8 -> 110 | R6: ='FS Desroches Daily'!AD8 -> 350 | S6: ='FS Desroches Daily'!AF8 -> 590 | T6: ='FS Desroches Daily'!AH8 -> 1.1 | U6: ='FS Desroches Daily'!AJ8 -> 290 | V6: ='FS Desroches Daily'!AL8 -> 0.2 | W6: ='FS Desroches Daily'!AN8 -> 0.15 | X6: ='FS Desroches Daily'!AP8 -> 0.13 | Y6: ='FS Desroches Daily'!AR8 -> 100 | Z6: ='FS Desroches Daily'!AT8 -> 110 | AA6: ='FS Desroches Daily'!AT8 -> 110 | AB6: ='FS Desroches Daily'!AV8 -> 110 | AC6: ='FS Desroches Daily'!AZ8 -> 110 | AD6: ='FS Desroches Daily'!BB8 -> 90 | AE6: ='FS Desroches Daily'!BD8 -> 10 | AF6: ='FS Desroches Daily'!BF8 -> 40 | AG6: ='FS Desroches Daily'!BH8 -> 30 | AH6: ='FS Desroches Daily'!BJ8 -> 50 | AI6: ='FS Desroches Daily'!BL8 -> 30 | AJ6: ='FS Desroches Daily'!BN8 -> 30 | AK6: ='FS Desroches Daily'!BP8 -> 50 | AL6: ='FS Desroches Daily'!BR8 -> 26 | AM6: ='FS Desroches Daily'!BT8 -> 30 | AN6: ='FS Desroches Daily'!BV8 -> 26 | AO6: ='FS Desroches Daily'!BX8 -> 30 | AP6: ='FS Desroches Daily'!BZ8 -> 38 | AQ6: ='FS Desroches Daily'!CB8 -> 0 | AR6: ='FS Desroches Daily'!CD8 -> 0 | AS6: ='FS Desroches Daily'!CF8 -> 0 | AT6: ='FS Desroches Daily'!CH8 -> 55.3 | AU6: ='FS Desroches Daily'!CJ8 -> 264 | AV6: ='FS Desroches Daily'!CL8 -> 410 | AW6: ='FS Desroches Daily'!CM8 -> 30.3 | AX6: =IF(LPG!F13-LPG!F12<0,"0",(LPG!F13-LPG!F12)*1.8315) -> 0 | AY6: =IF(LPG!H13-LPG!H12<0,"0",(LPG!H13-LPG!H12)*1.8315) -> 0 | AZ6: =IF(LPG!#REF!-LPG!J12<0,"0",(LPG!#REF!-LPG!J12)*1.8315) -> #REF! | BA6: =IF(LPG!M13-LPG!M12<0,"0",(LPG!M13-LPG!M12)*1.8315) -> 0 | BB6: =IF(LPG!Q13-LPG!Q12<0,"0",(LPG!Q13-LPG!Q12)*1.8315) -> 0 | BC6: ='FS Desroches Daily'!CN8 -> 0
A7: Seychelles at Desroches Island | B7: =B6+1 -> 6 | C7: 5 | D7: 2020 | E7: ='FS Desroches Daily'!D9 -> 0 | F7: ='FS Desroches Daily'!F9 -> 0 | G7: ='FS Desroches Daily'!H9 -> 0 | H7: ='FS Desroches Daily'!J9 -> 0 | I7: ='FS Desroches Daily'!L9 -> 0 | J7: ='FS Desroches Daily'!N9 -> 0 | K7: ='FS Desroches Daily'!P9 -> 0 | L7: ='FS Desroches Daily'!R9 -> 0 | M7: ='FS Desroches Daily'!T9 -> 0 | N7: ='FS Desroches Daily'!V9 -> 0 | O7: ='FS Desroches Daily'!X9 | P7: ='FS Desroches Daily'!Z9 | Q7: ='FS Desroches Daily'!AB9 | R7: ='FS Desroches Daily'!AD9 | S7: ='FS Desroches Daily'!AF9 | T7: ='FS Desroches Daily'!AH9 -> 0 | U7: ='FS Desroches Daily'!AJ9 | V7: ='FS Desroches Daily'!AL9 -> 0 | W7: ='FS Desroches Daily'!AN9 -> 0 | X7: ='FS Desroches Daily'!AP9 | Y7: ='FS Desroches Daily'!AR9 | Z7: ='FS Desroches Daily'!AT9 | AA7: ='FS Desroches Daily'!AT9 | AB7: ='FS Desroches Daily'!AV9 | AC7: ='FS Desroches Daily'!AZ9 | AD7: ='FS Desroches Daily'!BB9 | AE7: ='FS Desroches Daily'!BD9 | AF7: ='FS Desroches Daily'!BF9 | AG7: ='FS Desroches Daily'!BH9 | AH7: ='FS Desroches Daily'!BJ9 | AI7: ='FS Desroches Daily'!BL9 | AJ7: ='FS Desroches Daily'!BN9 | AK7: ='FS Desroches Daily'!BP9 | AL7: ='FS Desroches Daily'!BR9 | AM7: ='FS Desroches Daily'!BT9 | AN7: ='FS Desroches Daily'!BV9 | AO7: ='FS Desroches Daily'!BX9 | AP7: ='FS Desroches Daily'!BZ9 | AQ7: ='FS Desroches Daily'!CB9 | AR7: ='FS Desroches Daily'!CD9 | AS7: ='FS Desroches Daily'!CF9 | AT7: ='FS Desroches Daily'!CH9 | AU7: ='FS Desroches Daily'!CJ9 | AV7: ='FS Desroches Daily'!CL9 -> 0 | AW7: ='FS Desroches Daily'!CM9 -> 0 | AX7: =IF(LPG!F14-LPG!F13<0,"0",(LPG!F14-LPG!F13)*1.8315) -> 0 | AY7: =IF(LPG!H14-LPG!H13<0,"0",(LPG!H14-LPG!H13)*1.8315) -> 0 | AZ7: =IF(LPG!J14-LPG!#REF!<0,"0",(LPG!J14-LPG!#REF!)*1.8315) -> #REF! | BA7: =IF(LPG!M14-LPG!M13<0,"0",(LPG!M14-LPG!M13)*1.8315) -> 0 | BB7: =IF(LPG!Q14-LPG!Q13<0,"0",(LPG!Q14-LPG!Q13)*1.8315) -> 0 | BC7: ='FS Desroches Daily'!CN9 -> 0
A8: Seychelles at Desroches Island | B8: =B7+1 -> 7 | C8: 5 | D8: 2020 | E8: ='FS Desroches Daily'!D10 -> 0 | F8: ='FS Desroches Daily'!F10 -> 0 | G8: ='FS Desroches Daily'!H10 -> 0 | H8: ='FS Desroches Daily'!J10 -> 0 | I8: ='FS Desroches Daily'!L10 -> 0 | J8: ='FS Desroches Daily'!N10 -> 0 | K8: ='FS Desroches Daily'!P10 -> 0 | L8: ='FS Desroches Daily'!R10 -> 0 | M8: ='FS Desroches Daily'!T10 -> 0 | N8: ='FS Desroches Daily'!V10 -> 0 | O8: ='FS Desroches Daily'!X10 -> 0 | P8: ='FS Desroches Daily'!Z10 -> 0 | Q8: ='FS Desroches Daily'!AB10 -> 0 | R8: ='FS Desroches Daily'!AD10 -> 0 | S8: ='FS Desroches Daily'!AF10 -> 0 | T8: ='FS Desroches Daily'!AH10 -> 0 | U8: ='FS Desroches Daily'!AJ10 -> 0 | V8: ='FS Desroches Daily'!AL10 -> 0 | W8: ='FS Desroches Daily'!AN10 -> 0 | X8: ='FS Desroches Daily'!AP10 -> 0 | Y8: ='FS Desroches Daily'!AR10 -> 0 | Z8: ='FS Desroches Daily'!AT10 -> 0 | AA8: ='FS Desroches Daily'!AT10 -> 0 | AB8: ='FS Desroches Daily'!AV10 -> 0 | AC8: ='FS Desroches Daily'!AZ10 -> 0 | AD8: ='FS Desroches Daily'!BB10 -> 0 | AE8: ='FS Desroches Daily'!BD10 -> 0 | AF8: ='FS Desroches Daily'!BF10 -> 0 | AG8: ='FS Desroches Daily'!BH10 -> 0 | AH8: ='FS Desroches Daily'!BJ10 -> 0 | AI8: ='FS Desroches Daily'!BL10 -> 0 | AJ8: ='FS Desroches Daily'!BN10 -> 0 | AK8: ='FS Desroches Daily'!BP10 -> 0 | AL8: ='FS Desroches Daily'!BR10 -> 0 | AM8: ='FS Desroches Daily'!BT10 -> 0 | AN8: ='FS Desroches Daily'!BV10 -> 0 | AO8: ='FS Desroches Daily'!BX10 -> 0 | AP8: ='FS Desroches Daily'!BZ10 -> 0 | AQ8: ='FS Desroches Daily'!CB10 -> 0 | AR8: ='FS Desroches Daily'!CD10 -> 0 | AS8: ='FS Desroches Daily'!CF10 -> 0 | AT8: ='FS Desroches Daily'!CH10 -> 0 | AU8: ='FS Desroches Daily'!CJ10 -> 0 | AV8: ='FS Desroches Daily'!CL10 -> 0 | AW8: ='FS Desroches Daily'!CM10 -> 0 | AX8: =IF(LPG!F15-LPG!F14<0,"0",(LPG!F15-LPG!F14)*1.8315) -> 0 | AY8: =IF(LPG!H15-LPG!H14<0,"0",(LPG!H15-LPG!H14)*1.8315) -> 0 | AZ8: =IF(LPG!J15-LPG!J14<0,"0",(LPG!J15-LPG!J14)*1.8315) -> 0 | BA8: =IF(LPG!M15-LPG!M14<0,"0",(LPG!M15-LPG!M14)*1.8315) -> 0 | BB8: =IF(LPG!Q15-LPG!Q14<0,"0",(LPG!Q15-LPG!Q14)*1.8315) -> 0 | BC8: ='FS Desroches Daily'!CN10 -> 0
A9: Seychelles at Desroches Island | B9: =B8+1 -> 8 | C9: 5 | D9: 2020 | E9: ='FS Desroches Daily'!D11 -> 0 | F9: ='FS Desroches Daily'!F11 -> 0 | G9: ='FS Desroches Daily'!H11 -> 0 | H9: ='FS Desroches Daily'!J11 -> 0 | I9: ='FS Desroches Daily'!L11 -> 0 | J9: ='FS Desroches Daily'!N11 -> 0 | K9: ='FS Desroches Daily'!P11 -> 0 | L9: ='FS Desroches Daily'!R11 -> 0 | M9: ='FS Desroches Daily'!T11 -> 0 | N9: ='FS Desroches Daily'!V11 -> 0 | O9: ='FS Desroches Daily'!X11 -> 0 | P9: ='FS Desroches Daily'!Z11 -> 0 | Q9: ='FS Desroches Daily'!AB11 -> 0 | R9: ='FS Desroches Daily'!AD11 -> 0 | S9: ='FS Desroches Daily'!AF11 -> 0 | T9: ='FS Desroches Daily'!AH11 -> 0 | U9: ='FS Desroches Daily'!AJ11 -> 0 | V9: ='FS Desroches Daily'!AL11 -> 0 | W9: ='FS Desroches Daily'!AN11 -> 0 | X9: ='FS Desroches Daily'!AP11 -> 0 | Y9: ='FS Desroches Daily'!AR11 -> 0 | Z9: ='FS Desroches Daily'!AT11 -> 0 | AA9: ='FS Desroches Daily'!AT11 -> 0 | AB9: ='FS Desroches Daily'!AV11 -> 0 | AC9: ='FS Desroches Daily'!AZ11 -> 0 | AD9: ='FS Desroches Daily'!BB11 -> 0 | AE9: ='FS Desroches Daily'!BD11 -> 0 | AF9: ='FS Desroches Daily'!BF11 -> 0 | AG9: ='FS Desroches Daily'!BH11 -> 0 | AH9: ='FS Desroches Daily'!BJ11 -> 0 | AI9: ='FS Desroches Daily'!BL11 -> 0 | AJ9: ='FS Desroches Daily'!BN11 -> 0 | AK9: ='FS Desroches Daily'!BP11 -> 0 | AL9: ='FS Desroches Daily'!BR11 -> 0 | AM9: ='FS Desroches Daily'!BT11 -> 0 | AN9: ='FS Desroches Daily'!BV11 -> 0 | AO9: ='FS Desroches Daily'!BX11 -> 0 | AP9: ='FS Desroches Daily'!BZ11 -> 0 | AQ9: ='FS Desroches Daily'!CB11 -> 0 | AR9: ='FS Desroches Daily'!CD11 -> 0 | AS9: ='FS Desroches Daily'!CF11 -> 0 | AT9: ='FS Desroches Daily'!CH11 -> 0 | AU9: ='FS Desroches Daily'!CJ11 -> 0 | AV9: ='FS Desroches Daily'!CL11 -> 0 | AW9: ='FS Desroches Daily'!CM11 -> 0 | AX9: =IF(LPG!F16-LPG!F15<0,"0",(LPG!F16-LPG!F15)*1.8315) -> 0 | AY9: =IF(LPG!H16-LPG!H15<0,"0",(LPG!H16-LPG!H15)*1.8315) -> 0 | AZ9: =IF(LPG!J16-LPG!J15<0,"0",(LPG!J16-LPG!J15)*1.8315) -> 0 | BA9: =IF(LPG!M16-LPG!M15<0,"0",(LPG!M16-LPG!M15)*1.8315) -> 0 | BB9: =IF(LPG!Q16-LPG!Q15<0,"0",(LPG!Q16-LPG!Q15)*1.8315) -> 0 | BC9: ='FS Desroches Daily'!CN11 -> 0
A10: Seychelles at Desroches Island | B10: =B9+1 -> 9 | C10: 5 | D10: 2020 | E10: ='FS Desroches Daily'!D12 -> 0 | F10: ='FS Desroches Daily'!F12 -> 0 | G10: ='FS Desroches Daily'!H12 -> 0 | H10: ='FS Desroches Daily'!J12 -> 0 | I10: ='FS Desroches Daily'!L12 -> 0 | J10: ='FS Desroches Daily'!N12 -> 0 | K10: ='FS Desroches Daily'!P12 -> 0 | L10: ='FS Desroches Daily'!R12 -> 0 | M10: ='FS Desroches Daily'!T12 -> 0 | N10: ='FS Desroches Daily'!V12 -> 0 | O10: ='FS Desroches Daily'!X12 -> 0 | P10: ='FS Desroches Daily'!Z12 -> 0 | Q10: ='FS Desroches Daily'!AB12 -> 0 | R10: ='FS Desroches Daily'!AD12 -> 0 | S10: ='FS Desroches Daily'!AF12 -> 0 | T10: ='FS Desroches Daily'!AH12 -> 0 | U10: ='FS Desroches Daily'!AJ12 -> 0 | V10: ='FS Desroches Daily'!AL12 -> 0 | W10: ='FS Desroches Daily'!AN12 -> 0 | X10: ='FS Desroches Daily'!AP12 -> 0 | Y10: ='FS Desroches Daily'!AR12 -> 0 | Z10: ='FS Desroches Daily'!AT12 -> 0 | AA10: ='FS Desroches Daily'!AT12 -> 0 | AB10: ='FS Desroches Daily'!AV12 -> 0 | AC10: ='FS Desroches Daily'!AZ12 -> 0 | AD10: ='FS Desroches Daily'!BB12 -> 0 | AE10: ='FS Desroches Daily'!BD12 -> 0 | AF10: ='FS Desroches Daily'!BF12 -> 0 | AG10: ='FS Desroches Daily'!BH12 -> 0 | AH10: ='FS Desroches Daily'!BJ12 -> 0 | AI10: ='FS Desroches Daily'!BL12 -> 0 | AJ10: ='FS Desroches Daily'!BN12 -> 0 | AK10: ='FS Desroches Daily'!BP12 -> 0 | AL10: ='FS Desroches Daily'!BR12 -> 0 | AM10: ='FS Desroches Daily'!BT12 -> 0 | AN10: ='FS Desroches Daily'!BV12 -> 0 | AO10: ='FS Desroches Daily'!BX12 -> 0 | AP10: ='FS Desroches Daily'!BZ12 -> 0 | AQ10: ='FS Desroches Daily'!CB12 -> 0 | AR10: ='FS Desroches Daily'!CD12 -> 0 | AS10: ='FS Desroches Daily'!CF12 -> 0 | AT10: ='FS Desroches Daily'!CH12 -> 0 | AU10: ='FS Desroches Daily'!CJ12 -> 0 | AV10: ='FS Desroches Daily'!CL12 -> 0 | AW10: ='FS Desroches Daily'!CM12 -> 0 | AX10: =IF(LPG!F17-LPG!F16<0,"0",(LPG!F17-LPG!F16)*1.8315) -> 0 | AY10: =IF(LPG!H17-LPG!H16<0,"0",(LPG!H17-LPG!H16)*1.8315) -> 0 | AZ10: =IF(LPG!J17-LPG!J16<0,"0",(LPG!J17-LPG!J16)*1.8315) -> 0 | BA10: =IF(LPG!M17-LPG!M16<0,"0",(LPG!M17-LPG!M16)*1.8315) -> 0 | BB10: =IF(LPG!Q17-LPG!Q16<0,"0",(LPG!Q17-LPG!Q16)*1.8315) -> 0 | BC10: ='FS Desroches Daily'!CN12 -> 0
A11: Seychelles at Desroches Island | B11: =B10+1 -> 10 | C11: 5 | D11: 2020 | E11: ='FS Desroches Daily'!D13 -> 0 | F11: ='FS Desroches Daily'!F13 -> 0 | G11: ='FS Desroches Daily'!H13 -> 0 | H11: ='FS Desroches Daily'!J13 -> 0 | I11: ='FS Desroches Daily'!L13 -> 0 | J11: ='FS Desroches Daily'!N13 -> 0 | K11: ='FS Desroches Daily'!P13 -> 0 | L11: ='FS Desroches Daily'!R13 -> 0 | M11: ='FS Desroches Daily'!T13 -> 0 | N11: ='FS Desroches Daily'!V13 -> 0 | O11: ='FS Desroches Daily'!X13 -> 0 | P11: ='FS Desroches Daily'!Z13 -> 0 | Q11: ='FS Desroches Daily'!AB13 -> 0 | R11: ='FS Desroches Daily'!AD13 -> 0 | S11: ='FS Desroches Daily'!AF13 -> 0 | T11: ='FS Desroches Daily'!AH13 -> 0 | U11: ='FS Desroches Daily'!AJ13 -> 0 | V11: ='FS Desroches Daily'!AL13 -> 0 | W11: ='FS Desroches Daily'!AN13 -> 0 | X11: ='FS Desroches Daily'!AP13 -> 0 | Y11: ='FS Desroches Daily'!AR13 -> 0 | Z11: ='FS Desroches Daily'!AT13 -> 0 | AA11: ='FS Desroches Daily'!AT13 -> 0 | AB11: ='FS Desroches Daily'!AV13 -> 0 | AC11: ='FS Desroches Daily'!AZ13 -> 0 | AD11: ='FS Desroches Daily'!BB13 -> 0 | AE11: ='FS Desroches Daily'!BD13 -> 0 | AF11: ='FS Desroches Daily'!BF13 -> 0 | AG11: ='FS Desroches Daily'!BH13 -> 0 | AH11: ='FS Desroches Daily'!BJ13 -> 0 | AI11: ='FS Desroches Daily'!BL13 -> 0 | AJ11: ='FS Desroches Daily'!BN13 -> 0 | AK11: ='FS Desroches Daily'!BP13 -> 0 | AL11: ='FS Desroches Daily'!BR13 -> 0 | AM11: ='FS Desroches Daily'!BT13 -> 0 | AN11: ='FS Desroches Daily'!BV13 -> 0 | AO11: ='FS Desroches Daily'!BX13 -> 0 | AP11: ='FS Desroches Daily'!BZ13 -> 0 | AQ11: ='FS Desroches Daily'!CB13 -> 0 | AR11: ='FS Desroches Daily'!CD13 -> 0 | AS11: ='FS Desroches Daily'!CF13 -> 0 | AT11: ='FS Desroches Daily'!CH13 -> 0 | AU11: ='FS Desroches Daily'!CJ13 -> 0 | AV11: ='FS Desroches Daily'!CL13 -> 0 | AW11: ='FS Desroches Daily'!CM13 -> 0 | AX11: =IF(LPG!F18-LPG!F17<0,"0",(LPG!F18-LPG!F17)*1.8315) -> 0 | AY11: =IF(LPG!H18-LPG!H17<0,"0",(LPG!H18-LPG!H17)*1.8315) -> 0 | AZ11: =IF(LPG!J18-LPG!J17<0,"0",(LPG!J18-LPG!J17)*1.8315) -> 0 | BA11: =IF(LPG!M18-LPG!M17<0,"0",(LPG!M18-LPG!M17)*1.8315) -> 0 | BB11: =IF(LPG!Q18-LPG!Q17<0,"0",(LPG!Q18-LPG!Q17)*1.8315) -> 0 | BC11: ='FS Desroches Daily'!CN13 -> 0
A12: Seychelles at Desroches Island | B12: =B11+1 -> 11 | C12: 5 | D12: 2020 | E12: ='FS Desroches Daily'!D14 -> 0 | F12: ='FS Desroches Daily'!F14 -> 0 | G12: ='FS Desroches Daily'!H14 -> 0 | H12: ='FS Desroches Daily'!J14 -> 0 | I12: ='FS Desroches Daily'!L14 -> 0 | J12: ='FS Desroches Daily'!N14 -> 0 | K12: ='FS Desroches Daily'!P14 -> 0 | L12: ='FS Desroches Daily'!R14 -> 0 | M12: ='FS Desroches Daily'!T14 -> 0 | N12: ='FS Desroches Daily'!V14 -> 0 | O12: ='FS Desroches Daily'!X14 -> 0 | P12: ='FS Desroches Daily'!Z14 -> 0 | Q12: ='FS Desroches Daily'!AB14 -> 0 | R12: ='FS Desroches Daily'!AD14 -> 0 | S12: ='FS Desroches Daily'!AF14 -> 0 | T12: ='FS Desroches Daily'!AH14 -> 0 | U12: ='FS Desroches Daily'!AJ14 -> 0 | V12: ='FS Desroches Daily'!AL14 -> 0 | W12: ='FS Desroches Daily'!AN14 -> 0 | X12: ='FS Desroches Daily'!AP14 -> 0 | Y12: ='FS Desroches Daily'!AR14 -> 0 | Z12: ='FS Desroches Daily'!AT14 -> 0 | AA12: ='FS Desroches Daily'!AT14 -> 0 | AB12: ='FS Desroches Daily'!AV14 -> 0 | AC12: ='FS Desroches Daily'!AZ14 -> 0 | AD12: ='FS Desroches Daily'!BB14 -> 0 | AE12: ='FS Desroches Daily'!BD14 -> 0 | AF12: ='FS Desroches Daily'!BF14 -> 0 | AG12: ='FS Desroches Daily'!BH14 -> 0 | AH12: ='FS Desroches Daily'!BJ14 -> 0 | AI12: ='FS Desroches Daily'!BL14 -> 0 | AJ12: ='FS Desroches Daily'!BN14 -> 0 | AK12: ='FS Desroches Daily'!BP14 -> 0 | AL12: ='FS Desroches Daily'!BR14 -> 0 | AM12: ='FS Desroches Daily'!BT14 -> 0 | AN12: ='FS Desroches Daily'!BV14 -> 0 | AO12: ='FS Desroches Daily'!BX14 -> 0 | AP12: ='FS Desroches Daily'!BZ14 -> 0 | AQ12: ='FS Desroches Daily'!CB14 -> 0 | AR12: ='FS Desroches Daily'!CD14 -> 0 | AS12: ='FS Desroches Daily'!CF14 -> 0 | AT12: ='FS Desroches Daily'!CH14 -> 0 | AU12: ='FS Desroches Daily'!CJ14 -> 0 | AV12: ='FS Desroches Daily'!CL14 -> 0 | AW12: ='FS Desroches Daily'!CM14 -> 0 | AX12: =IF(LPG!F19-LPG!F18<0,"0",(LPG!F19-LPG!F18)*1.8315) -> 0 | AY12: =IF(LPG!H19-LPG!H18<0,"0",(LPG!H19-LPG!H18)*1.8315) -> 0 | AZ12: =IF(LPG!J19-LPG!J18<0,"0",(LPG!J19-LPG!J18)*1.8315) -> 0 | BA12: =IF(LPG!M19-LPG!M18<0,"0",(LPG!M19-LPG!M18)*1.8315) -> 0 | BB12: =IF(LPG!Q19-LPG!Q18<0,"0",(LPG!Q19-LPG!Q18)*1.8315) -> 0 | BC12: ='FS Desroches Daily'!CN14 -> 0
A13: Seychelles at Desroches Island | B13: =B12+1 -> 12 | C13: 5 | D13: 2020 | E13: ='FS Desroches Daily'!D15 -> 0 | F13: ='FS Desroches Daily'!F15 -> 0 | G13: ='FS Desroches Daily'!H15 -> 0 | H13: ='FS Desroches Daily'!J15 -> 0 | I13: ='FS Desroches Daily'!L15 -> 0 | J13: ='FS Desroches Daily'!N15 -> 0 | K13: ='FS Desroches Daily'!P15 -> 0 | L13: ='FS Desroches Daily'!R15 -> 0 | M13: ='FS Desroches Daily'!T15 -> 0 | N13: ='FS Desroches Daily'!V15 -> 0 | O13: ='FS Desroches Daily'!X15 -> 0 | P13: ='FS Desroches Daily'!Z15 -> 0 | Q13: ='FS Desroches Daily'!AB15 -> 0 | R13: ='FS Desroches Daily'!AD15 -> 0 | S13: ='FS Desroches Daily'!AF15 -> 0 | T13: ='FS Desroches Daily'!AH15 -> 0 | U13: ='FS Desroches Daily'!AJ15 -> 0 | V13: ='FS Desroches Daily'!AL15 -> 0 | W13: ='FS Desroches Daily'!AN15 -> 0 | X13: ='FS Desroches Daily'!AP15 -> 0 | Y13: ='FS Desroches Daily'!AR15 -> 0 | Z13: ='FS Desroches Daily'!AT15 -> 0 | AA13: ='FS Desroches Daily'!AT15 -> 0 | AB13: ='FS Desroches Daily'!AV15 -> 0 | AC13: ='FS Desroches Daily'!AZ15 -> 0 | AD13: ='FS Desroches Daily'!BB15 -> 0 | AE13: ='FS Desroches Daily'!BD15 -> 0 | AF13: ='FS Desroches Daily'!BF15 -> 0 | AG13: ='FS Desroches Daily'!BH15 -> 0 | AH13: ='FS Desroches Daily'!BJ15 -> 0 | AI13: ='FS Desroches Daily'!BL15 -> 0 | AJ13: ='FS Desroches Daily'!BN15 -> 0 | AK13: ='FS Desroches Daily'!BP15 -> 0 | AL13: ='FS Desroches Daily'!BR15 -> 0 | AM13: ='FS Desroches Daily'!BT15 -> 0 | AN13: ='FS Desroches Daily'!BV15 -> 0 | AO13: ='FS Desroches Daily'!BX15 -> 0 | AP13: ='FS Desroches Daily'!BZ15 -> 0 | AQ13: ='FS Desroches Daily'!CB15 -> 0 | AR13: ='FS Desroches Daily'!CD15 -> 0 | AS13: ='FS Desroches Daily'!CF15 -> 0 | AT13: ='FS Desroches Daily'!CH15 -> 0 | AU13: ='FS Desroches Daily'!CJ15 -> 0 | AV13: ='FS Desroches Daily'!CL15 -> 0 | AW13: ='FS Desroches Daily'!CM15 -> 0 | AX13: =IF(LPG!F20-LPG!F19<0,"0",(LPG!F20-LPG!F19)*1.8315) -> 0 | AY13: =IF(LPG!H20-LPG!H19<0,"0",(LPG!H20-LPG!H19)*1.8315) -> 0 | AZ13: =IF(LPG!J20-LPG!J19<0,"0",(LPG!J20-LPG!J19)*1.8315) -> 0 | BA13: =IF(LPG!M20-LPG!M19<0,"0",(LPG!M20-LPG!M19)*1.8315) -> 0 | BB13: =IF(LPG!Q20-LPG!Q19<0,"0",(LPG!Q20-LPG!Q19)*1.8315) -> 0 | BC13: ='FS Desroches Daily'!CN15 -> 0
A14: Seychelles at Desroches Island | B14: =B13+1 -> 13 | C14: 5 | D14: 2020 | E14: ='FS Desroches Daily'!D16 -> 0 | F14: ='FS Desroches Daily'!F16 -> 0 | G14: ='FS Desroches Daily'!H16 -> 0 | H14: ='FS Desroches Daily'!J16 -> 0 | I14: ='FS Desroches Daily'!L16 -> 0 | J14: ='FS Desroches Daily'!N16 -> 0 | K14: ='FS Desroches Daily'!P16 -> 0 | L14: ='FS Desroches Daily'!R16 -> 0 | M14: ='FS Desroches Daily'!T16 -> 0 | N14: ='FS Desroches Daily'!V16 -> 0 | O14: ='FS Desroches Daily'!X16 -> 0 | P14: ='FS Desroches Daily'!Z16 -> 0 | Q14: ='FS Desroches Daily'!AB16 -> 0 | R14: ='FS Desroches Daily'!AD16 -> 0 | S14: ='FS Desroches Daily'!AF16 -> 0 | T14: ='FS Desroches Daily'!AH16 -> 0 | U14: ='FS Desroches Daily'!AJ16 -> 0 | V14: ='FS Desroches Daily'!AL16 -> 0 | W14: ='FS Desroches Daily'!AN16 -> 0 | X14: ='FS Desroches Daily'!AP16 -> 0 | Y14: ='FS Desroches Daily'!AR16 -> 0 | Z14: ='FS Desroches Daily'!AT16 -> 0 | AA14: ='FS Desroches Daily'!AT16 -> 0 | AB14: ='FS Desroches Daily'!AV16 -> 0 | AC14: ='FS Desroches Daily'!AZ16 -> 0 | AD14: ='FS Desroches Daily'!BB16 -> 0 | AE14: ='FS Desroches Daily'!BD16 -> 0 | AF14: ='FS Desroches Daily'!BF16 -> 0 | AG14: ='FS Desroches Daily'!BH16 -> 0 | AH14: ='FS Desroches Daily'!BJ16 -> 0 | AI14: ='FS Desroches Daily'!BL16 -> 0 | AJ14: ='FS Desroches Daily'!BN16 -> 0 | AK14: ='FS Desroches Daily'!BP16 -> 0 | AL14: ='FS Desroches Daily'!BR16 -> 0 | AM14: ='FS Desroches Daily'!BT16 -> 0 | AN14: ='FS Desroches Daily'!BV16 -> 0 | AO14: ='FS Desroches Daily'!BX16 -> 0 | AP14: ='FS Desroches Daily'!BZ16 -> 0 | AQ14: ='FS Desroches Daily'!CB16 -> 0 | AR14: ='FS Desroches Daily'!CD16 -> 0 | AS14: ='FS Desroches Daily'!CF16 -> 0 | AT14: ='FS Desroches Daily'!CH16 -> 0 | AU14: ='FS Desroches Daily'!CJ16 -> 0 | AV14: ='FS Desroches Daily'!CL16 -> 0 | AW14: ='FS Desroches Daily'!CM16 -> 0 | AX14: =IF(LPG!F21-LPG!F20<0,"0",(LPG!F21-LPG!F20)*1.8315) -> 0 | AY14: =IF(LPG!H21-LPG!H20<0,"0",(LPG!H21-LPG!H20)*1.8315) -> 0 | AZ14: =IF(LPG!J21-LPG!J20<0,"0",(LPG!J21-LPG!J20)*1.8315) -> 0 | BA14: =IF(LPG!M21-LPG!M20<0,"0",(LPG!M21-LPG!M20)*1.8315) -> 0 | BB14: =IF(LPG!Q21-LPG!Q20<0,"0",(LPG!Q21-LPG!Q20)*1.8315) -> 0 | BC14: ='FS Desroches Daily'!CN16 -> 0
A15: Seychelles at Desroches Island | B15: =B14+1 -> 14 | C15: 5 | D15: 2020 | E15: ='FS Desroches Daily'!D17 -> 0 | F15: ='FS Desroches Daily'!F17 -> 0 | G15: ='FS Desroches Daily'!H17 -> 0 | H15: ='FS Desroches Daily'!J17 -> 0 | I15: ='FS Desroches Daily'!L17 -> 0 | J15: ='FS Desroches Daily'!N17 -> 0 | K15: ='FS Desroches Daily'!P17 -> 0 | L15: ='FS Desroches Daily'!R17 -> 0 | M15: ='FS Desroches Daily'!T17 -> 0 | N15: ='FS Desroches Daily'!V17 -> 0 | O15: ='FS Desroches Daily'!X17 -> 0 | P15: ='FS Desroches Daily'!Z17 -> 0 | Q15: ='FS Desroches Daily'!AB17 -> 0 | R15: ='FS Desroches Daily'!AD17 -> 0 | S15: ='FS Desroches Daily'!AF17 -> 0 | T15: ='FS Desroches Daily'!AH17 -> 0 | U15: ='FS Desroches Daily'!AJ17 -> 0 | V15: ='FS Desroches Daily'!AL17 -> 0 | W15: ='FS Desroches Daily'!AN17 -> 0 | X15: ='FS Desroches Daily'!AP17 -> 0 | Y15: ='FS Desroches Daily'!AR17 -> 0 | Z15: ='FS Desroches Daily'!AT17 -> 0 | AA15: ='FS Desroches Daily'!AT17 -> 0 | AB15: ='FS Desroches Daily'!AV17 -> 0 | AC15: ='FS Desroches Daily'!AZ17 -> 0 | AD15: ='FS Desroches Daily'!BB17 -> 0 | AE15: ='FS Desroches Daily'!BD17 -> 0 | AF15: ='FS Desroches Daily'!BF17 -> 0 | AG15: ='FS Desroches Daily'!BH17 -> 0 | AH15: ='FS Desroches Daily'!BJ17 -> 0 | AI15: ='FS Desroches Daily'!BL17 -> 0 | AJ15: ='FS Desroches Daily'!BN17 -> 0 | AK15: ='FS Desroches Daily'!BP17 -> 0 | AL15: ='FS Desroches Daily'!BR17 -> 0 | AM15: ='FS Desroches Daily'!BT17 -> 0 | AN15: ='FS Desroches Daily'!BV17 -> 0 | AO15: ='FS Desroches Daily'!BX17 -> 0 | AP15: ='FS Desroches Daily'!BZ17 -> 0 | AQ15: ='FS Desroches Daily'!CB17 -> 0 | AR15: ='FS Desroches Daily'!CD17 -> 0 | AS15: ='FS Desroches Daily'!CF17 -> 0 | AT15: ='FS Desroches Daily'!CH17 -> 0 | AU15: ='FS Desroches Daily'!CJ17 -> 0 | AV15: ='FS Desroches Daily'!CL17 -> 0 | AW15: ='FS Desroches Daily'!CM17 -> 0 | AX15: =IF(LPG!F22-LPG!F21<0,"0",(LPG!F22-LPG!F21)*1.8315) -> 0 | AY15: =IF(LPG!H22-LPG!H21<0,"0",(LPG!H22-LPG!H21)*1.8315) -> 0 | AZ15: =IF(LPG!J22-LPG!J21<0,"0",(LPG!J22-LPG!J21)*1.8315) -> 0 | BA15: =IF(LPG!M22-LPG!M21<0,"0",(LPG!M22-LPG!M21)*1.8315) -> 0 | BB15: =IF(LPG!Q22-LPG!Q21<0,"0",(LPG!Q22-LPG!Q21)*1.8315) -> 0 | BC15: ='FS Desroches Daily'!CN17 -> 0
A16: Seychelles at Desroches Island | B16: =B15+1 -> 15 | C16: 5 | D16: 2020 | E16: ='FS Desroches Daily'!D18 -> 0 | F16: ='FS Desroches Daily'!F18 -> 0 | G16: ='FS Desroches Daily'!H18 -> 0 | H16: ='FS Desroches Daily'!J18 -> 0 | I16: ='FS Desroches Daily'!L18 -> 0 | J16: ='FS Desroches Daily'!N18 -> 0 | K16: ='FS Desroches Daily'!P18 -> 0 | L16: ='FS Desroches Daily'!R18 -> 0 | M16: ='FS Desroches Daily'!T18 -> 0 | N16: ='FS Desroches Daily'!V18 -> 0 | O16: ='FS Desroches Daily'!X18 -> 0 | P16: ='FS Desroches Daily'!Z18 -> 0 | Q16: ='FS Desroches Daily'!AB18 -> 0 | R16: ='FS Desroches Daily'!AD18 -> 0 | S16: ='FS Desroches Daily'!AF18 -> 0 | T16: ='FS Desroches Daily'!AH18 -> 0 | U16: ='FS Desroches Daily'!AJ18 -> 0 | V16: ='FS Desroches Daily'!AL18 -> 0 | W16: ='FS Desroches Daily'!AN18 -> 0 | X16: ='FS Desroches Daily'!AP18 -> 0 | Y16: ='FS Desroches Daily'!AR18 -> 0 | Z16: ='FS Desroches Daily'!AT18 -> 0 | AA16: ='FS Desroches Daily'!AT18 -> 0 | AB16: ='FS Desroches Daily'!AV18 -> 0 | AC16: ='FS Desroches Daily'!AZ18 -> 0 | AD16: ='FS Desroches Daily'!BB18 -> 0 | AE16: ='FS Desroches Daily'!BD18 -> 0 | AF16: ='FS Desroches Daily'!BF18 -> 0 | AG16: ='FS Desroches Daily'!BH18 -> 0 | AH16: ='FS Desroches Daily'!BJ18 -> 0 | AI16: ='FS Desroches Daily'!BL18 -> 0 | AJ16: ='FS Desroches Daily'!BN18 -> 0 | AK16: ='FS Desroches Daily'!BP18 -> 0 | AL16: ='FS Desroches Daily'!BR18 -> 0 | AM16: ='FS Desroches Daily'!BT18 -> 0 | AN16: ='FS Desroches Daily'!BV18 -> 0 | AO16: ='FS Desroches Daily'!BX18 -> 0 | AP16: ='FS Desroches Daily'!BZ18 -> 0 | AQ16: ='FS Desroches Daily'!CB18 -> 0 | AR16: ='FS Desroches Daily'!CD18 -> 0 | AS16: ='FS Desroches Daily'!CF18 -> 0 | AT16: ='FS Desroches Daily'!CH18 -> 0 | AU16: ='FS Desroches Daily'!CJ18 -> 0 | AV16: ='FS Desroches Daily'!CL18 -> 0 | AW16: ='FS Desroches Daily'!CM18 -> 0 | AX16: =IF(LPG!F23-LPG!F22<0,"0",(LPG!F23-LPG!F22)*1.8315) -> 0 | AY16: =IF(LPG!H23-LPG!H22<0,"0",(LPG!H23-LPG!H22)*1.8315) -> 0 | AZ16: =IF(LPG!J23-LPG!J22<0,"0",(LPG!J23-LPG!J22)*1.8315) -> 0 | BA16: =IF(LPG!M23-LPG!M22<0,"0",(LPG!M23-LPG!M22)*1.8315) -> 0 | BB16: =IF(LPG!Q23-LPG!Q22<0,"0",(LPG!Q23-LPG!Q22)*1.8315) -> 0 | BC16: ='FS Desroches Daily'!CN18 -> 0
A17: Seychelles at Desroches Island | B17: =B16+1 -> 16 | C17: 5 | D17: 2020 | E17: ='FS Desroches Daily'!D19 -> 0 | F17: ='FS Desroches Daily'!F19 -> 0 | G17: ='FS Desroches Daily'!H19 -> 0 | H17: ='FS Desroches Daily'!J19 -> 0 | I17: ='FS Desroches Daily'!L19 -> 0 | J17: ='FS Desroches Daily'!N19 -> 0 | K17: ='FS Desroches Daily'!P19 -> 0 | L17: ='FS Desroches Daily'!R19 -> 0 | M17: ='FS Desroches Daily'!T19 -> 0 | N17: ='FS Desroches Daily'!V19 -> 0 | O17: ='FS Desroches Daily'!X19 -> 0 | P17: ='FS Desroches Daily'!Z19 -> 0 | Q17: ='FS Desroches Daily'!AB19 -> 0 | R17: ='FS Desroches Daily'!AD19 -> 0 | S17: ='FS Desroches Daily'!AF19 -> 0 | T17: ='FS Desroches Daily'!AH19 -> 0 | U17: ='FS Desroches Daily'!AJ19 -> 0 | V17: ='FS Desroches Daily'!AL19 -> 0 | W17: ='FS Desroches Daily'!AN19 -> 0 | X17: ='FS Desroches Daily'!AP19 -> 0 | Y17: ='FS Desroches Daily'!AR19 -> 0 | Z17: ='FS Desroches Daily'!AU20 -> 0 | AA17: ='FS Desroches Daily'!AU20 -> 0 | AB17: ='FS Desroches Daily'!AV19 -> 0 | AC17: ='FS Desroches Daily'!AZ19 -> 0 | AD17: ='FS Desroches Daily'!BB19 -> 0 | AE17: ='FS Desroches Daily'!BD19 -> 0 | AF17: ='FS Desroches Daily'!BF19 -> 0 | AG17: ='FS Desroches Daily'!BH19 -> 0 | AH17: ='FS Desroches Daily'!BJ19 -> 0 | AI17: ='FS Desroches Daily'!BL19 -> 0 | AJ17: ='FS Desroches Daily'!BN19 -> 0 | AK17: ='FS Desroches Daily'!BP19 -> 0 | AL17: ='FS Desroches Daily'!BR19 -> 0 | AM17: ='FS Desroches Daily'!BT19 -> 0 | AN17: ='FS Desroches Daily'!BV19 -> 0 | AO17: ='FS Desroches Daily'!BX19 -> 0 | AP17: ='FS Desroches Daily'!BZ19 -> 0 | AQ17: ='FS Desroches Daily'!CB19 -> 0 | AR17: ='FS Desroches Daily'!CD19 -> 0 | AS17: ='FS Desroches Daily'!CF19 -> 0 | AT17: ='FS Desroches Daily'!CH19 -> 0 | AU17: ='FS Desroches Daily'!CJ19 -> 0 | AV17: ='FS Desroches Daily'!CL19 -> 0 | AW17: ='FS Desroches Daily'!CM19 -> 0 | AX17: =IF(LPG!F24-LPG!F23<0,"0",(LPG!F24-LPG!F23)*1.8315) -> 0 | AY17: =IF(LPG!H24-LPG!H23<0,"0",(LPG!H24-LPG!H23)*1.8315) -> 0 | AZ17: =IF(LPG!J24-LPG!J23<0,"0",(LPG!J24-LPG!J23)*1.8315) -> 0 | BA17: =IF(LPG!M24-LPG!M23<0,"0",(LPG!M24-LPG!M23)*1.8315) -> 0 | BB17: =IF(LPG!Q24-LPG!Q23<0,"0",(LPG!Q24-LPG!Q23)*1.8315) -> 0 | BC17: ='FS Desroches Daily'!CN19 -> 0
A18: Seychelles at Desroches Island | B18: =B17+1 -> 17 | C18: 5 | D18: 2020 | E18: ='FS Desroches Daily'!D20 -> 0 | F18: ='FS Desroches Daily'!F20 -> 0 | G18: ='FS Desroches Daily'!H20 -> 0 | H18: ='FS Desroches Daily'!J20 -> 0 | I18: ='FS Desroches Daily'!L20 -> 0 | J18: ='FS Desroches Daily'!N20 -> 0 | K18: ='FS Desroches Daily'!P20 -> 0 | L18: ='FS Desroches Daily'!R20 -> 0 | M18: ='FS Desroches Daily'!T20 -> 0 | N18: ='FS Desroches Daily'!V20 -> 0 | O18: ='FS Desroches Daily'!X20 -> 0 | P18: ='FS Desroches Daily'!Z20 -> 0 | Q18: ='FS Desroches Daily'!AB20 -> 0 | R18: ='FS Desroches Daily'!AD20 -> 0 | S18: ='FS Desroches Daily'!AF20 -> 0 | T18: ='FS Desroches Daily'!AH20 -> 0 | U18: ='FS Desroches Daily'!AJ20 -> 0 | V18: ='FS Desroches Daily'!AL20 -> 0 | W18: ='FS Desroches Daily'!AN20 -> 0 | X18: ='FS Desroches Daily'!AP20 -> 0 | Y18: ='FS Desroches Daily'!AR20 -> 0 | Z18: ='FS Desroches Daily'!AT20 -> 0 | AA18: ='FS Desroches Daily'!AT20 -> 0 | AB18: ='FS Desroches Daily'!AV20 -> 0 | AC18: ='FS Desroches Daily'!AZ20 -> 0 | AD18: ='FS Desroches Daily'!BB20 -> 0 | AE18: ='FS Desroches Daily'!BD20 -> 0 | AF18: ='FS Desroches Daily'!BF20 -> 0 | AG18: ='FS Desroches Daily'!BH20 -> 0 | AH18: ='FS Desroches Daily'!BJ20 -> 0 | AI18: ='FS Desroches Daily'!BL20 -> 0 | AJ18: ='FS Desroches Daily'!BN20 -> 0 | AK18: ='FS Desroches Daily'!BP20 -> 0 | AL18: ='FS Desroches Daily'!BR20 -> 0 | AM18: ='FS Desroches Daily'!BT20 -> 0 | AN18: ='FS Desroches Daily'!BV20 -> 0 | AO18: ='FS Desroches Daily'!BX20 -> 0 | AP18: ='FS Desroches Daily'!BZ20 -> 0 | AQ18: ='FS Desroches Daily'!CB20 -> 0 | AR18: ='FS Desroches Daily'!CD20 -> 0 | AS18: ='FS Desroches Daily'!CF20 -> 0 | AT18: ='FS Desroches Daily'!CH20 -> 0 | AU18: ='FS Desroches Daily'!CJ20 -> 0 | AV18: ='FS Desroches Daily'!CL20 -> 0 | AW18: ='FS Desroches Daily'!CM20 -> 0 | AX18: =IF(LPG!F25-LPG!F24<0,"0",(LPG!F25-LPG!F24)*1.8315) -> 0 | AY18: =IF(LPG!H25-LPG!H24<0,"0",(LPG!H25-LPG!H24)*1.8315) -> 0 | AZ18: =IF(LPG!J25-LPG!J24<0,"0",(LPG!J25-LPG!J24)*1.8315) -> 0 | BA18: =IF(LPG!M25-LPG!M24<0,"0",(LPG!M25-LPG!M24)*1.8315) -> 0 | BB18: =IF(LPG!Q25-LPG!Q24<0,"0",(LPG!Q25-LPG!Q24)*1.8315) -> 0 | BC18: ='FS Desroches Daily'!CN20 -> 0
A19: Seychelles at Desroches Island | B19: =B18+1 -> 18 | C19: 5 | D19: 2020 | E19: ='FS Desroches Daily'!D21 -> 0 | F19: ='FS Desroches Daily'!F21 -> 0 | G19: ='FS Desroches Daily'!H21 -> 0 | H19: ='FS Desroches Daily'!J21 -> 0 | I19: ='FS Desroches Daily'!L21 -> 0 | J19: ='FS Desroches Daily'!N21 -> 0 | K19: ='FS Desroches Daily'!P21 -> 0 | L19: ='FS Desroches Daily'!R21 -> 0 | M19: ='FS Desroches Daily'!T21 -> 0 | N19: ='FS Desroches Daily'!V21 -> 0 | O19: ='FS Desroches Daily'!X21 -> 0 | P19: ='FS Desroches Daily'!Z21 -> 0 | Q19: ='FS Desroches Daily'!AB21 -> 0 | R19: ='FS Desroches Daily'!AD21 -> 0 | S19: ='FS Desroches Daily'!AF21 -> 0 | T19: ='FS Desroches Daily'!AH21 -> 0 | U19: ='FS Desroches Daily'!AJ21 -> 0 | V19: ='FS Desroches Daily'!AL21 -> 0 | W19: ='FS Desroches Daily'!AN21 -> 0 | X19: ='FS Desroches Daily'!AP21 -> 0 | Y19: ='FS Desroches Daily'!AR21 -> 0 | Z19: ='FS Desroches Daily'!AT21 -> 0 | AA19: ='FS Desroches Daily'!AT21 -> 0 | AB19: ='FS Desroches Daily'!AV21 -> 0 | AC19: ='FS Desroches Daily'!AZ21 -> 0 | AD19: ='FS Desroches Daily'!BB21 -> 0 | AE19: ='FS Desroches Daily'!BD21 -> 0 | AF19: ='FS Desroches Daily'!BF21 -> 0 | AG19: ='FS Desroches Daily'!BH21 -> 0 | AH19: ='FS Desroches Daily'!BJ21 -> 0 | AI19: ='FS Desroches Daily'!BL21 -> 0 | AJ19: ='FS Desroches Daily'!BN21 -> 0 | AK19: ='FS Desroches Daily'!BP21 -> 0 | AL19: ='FS Desroches Daily'!BR21 -> 0 | AM19: ='FS Desroches Daily'!BT21 -> 0 | AN19: ='FS Desroches Daily'!BV21 -> 0 | AO19: ='FS Desroches Daily'!BX21 -> 0 | AP19: ='FS Desroches Daily'!BZ21 -> 0 | AQ19: ='FS Desroches Daily'!CB21 -> 0 | AR19: ='FS Desroches Daily'!CD21 -> 0 | AS19: ='FS Desroches Daily'!CF21 -> 0 | AT19: ='FS Desroches Daily'!CH21 -> 0 | AU19: ='FS Desroches Daily'!CJ21 -> 0 | AV19: ='FS Desroches Daily'!CL21 -> 0 | AW19: ='FS Desroches Daily'!CM21 -> 0 | AX19: =IF(LPG!F26-LPG!F25<0,"0",(LPG!F26-LPG!F25)*1.8315) -> 0 | AY19: =IF(LPG!H26-LPG!H25<0,"0",(LPG!H26-LPG!H25)*1.8315) -> 0 | AZ19: =IF(LPG!J26-LPG!J25<0,"0",(LPG!J26-LPG!J25)*1.8315) -> 0 | BA19: =IF(LPG!M26-LPG!M25<0,"0",(LPG!M26-LPG!M25)*1.8315) -> 0 | BB19: =IF(LPG!Q26-LPG!Q25<0,"0",(LPG!Q26-LPG!Q25)*1.8315) -> 0 | BC19: ='FS Desroches Daily'!CN21 -> 0
A20: Seychelles at Desroches Island | B20: =B19+1 -> 19 | C20: 5 | D20: 2020 | E20: ='FS Desroches Daily'!D22 -> 0 | F20: ='FS Desroches Daily'!F22 -> 0 | G20: ='FS Desroches Daily'!H22 -> 0 | H20: ='FS Desroches Daily'!J22 -> 0 | I20: ='FS Desroches Daily'!L22 -> 0 | J20: ='FS Desroches Daily'!N22 -> 0 | K20: ='FS Desroches Daily'!P22 -> 0 | L20: ='FS Desroches Daily'!R22 -> 0 | M20: ='FS Desroches Daily'!T22 -> 0 | N20: ='FS Desroches Daily'!V22 -> 0 | O20: ='FS Desroches Daily'!X22 -> 0 | P20: ='FS Desroches Daily'!Z22 -> 0 | Q20: ='FS Desroches Daily'!AB22 -> 0 | R20: ='FS Desroches Daily'!AD22 -> 0 | S20: ='FS Desroches Daily'!AF22 -> 0 | T20: ='FS Desroches Daily'!AH22 -> 0 | U20: ='FS Desroches Daily'!AJ22 -> 0 | V20: ='FS Desroches Daily'!AL22 -> 0 | W20: ='FS Desroches Daily'!AN22 -> 0 | X20: ='FS Desroches Daily'!AP22 -> 0 | Y20: ='FS Desroches Daily'!AR22 -> 0 | Z20: ='FS Desroches Daily'!AT22 -> 0 | AA20: ='FS Desroches Daily'!AT22 -> 0 | AB20: ='FS Desroches Daily'!AV22 -> 0 | AC20: ='FS Desroches Daily'!AZ22 -> 0 | AD20: ='FS Desroches Daily'!BB22 -> 0 | AE20: ='FS Desroches Daily'!BD22 -> 0 | AF20: ='FS Desroches Daily'!BF22 -> 0 | AG20: ='FS Desroches Daily'!BH22 -> 0 | AH20: ='FS Desroches Daily'!BJ22 -> 0 | AI20: ='FS Desroches Daily'!BL22 -> 0 | AJ20: ='FS Desroches Daily'!BN22 -> 0 | AK20: ='FS Desroches Daily'!BP22 -> 0 | AL20: ='FS Desroches Daily'!BR22 -> 0 | AM20: ='FS Desroches Daily'!BT22 -> 0 | AN20: ='FS Desroches Daily'!BV22 -> 0 | AO20: ='FS Desroches Daily'!BX22 -> 0 | AP20: ='FS Desroches Daily'!BZ22 -> 0 | AQ20: ='FS Desroches Daily'!CB22 -> 0 | AR20: ='FS Desroches Daily'!CD22 -> 0 | AS20: ='FS Desroches Daily'!CF22 -> 0 | AT20: ='FS Desroches Daily'!CH22 -> 0 | AU20: ='FS Desroches Daily'!CJ22 -> 0 | AV20: ='FS Desroches Daily'!CL22 -> 0 | AW20: ='FS Desroches Daily'!CM22 -> 0 | AX20: =IF(LPG!F27-LPG!F26<0,"0",(LPG!F27-LPG!F26)*1.8315) -> 0 | AY20: =IF(LPG!H27-LPG!H26<0,"0",(LPG!H27-LPG!H26)*1.8315) -> 0 | AZ20: =IF(LPG!J27-LPG!J26<0,"0",(LPG!J27-LPG!J26)*1.8315) -> 0 | BA20: =IF(LPG!M27-LPG!M26<0,"0",(LPG!M27-LPG!M26)*1.8315) -> 0 | BB20: =IF(LPG!Q27-LPG!Q26<0,"0",(LPG!Q27-LPG!Q26)*1.8315) -> 0 | BC20: ='FS Desroches Daily'!CN22 -> 0
A21: Seychelles at Desroches Island | B21: =B20+1 -> 20 | C21: 5 | D21: 2020 | E21: ='FS Desroches Daily'!D23 -> 0 | F21: ='FS Desroches Daily'!F23 -> 0 | G21: ='FS Desroches Daily'!H23 -> 0 | H21: ='FS Desroches Daily'!J23 -> 0 | I21: ='FS Desroches Daily'!L23 -> 0 | J21: ='FS Desroches Daily'!N23 -> 0 | K21: ='FS Desroches Daily'!P23 -> 0 | L21: ='FS Desroches Daily'!R23 -> 0 | M21: ='FS Desroches Daily'!T23 -> 0 | N21: ='FS Desroches Daily'!V23 -> 0 | O21: ='FS Desroches Daily'!X23 -> 0 | P21: ='FS Desroches Daily'!Z23 -> 0 | Q21: ='FS Desroches Daily'!AB23 -> 0 | R21: ='FS Desroches Daily'!AD23 -> 0 | S21: ='FS Desroches Daily'!AF23 -> 0 | T21: ='FS Desroches Daily'!AH23 -> 0 | U21: ='FS Desroches Daily'!AJ23 -> 0 | V21: ='FS Desroches Daily'!AL23 -> 0 | W21: ='FS Desroches Daily'!AN23 -> 0 | X21: ='FS Desroches Daily'!AP23 -> 0 | Y21: ='FS Desroches Daily'!AR23 -> 0 | Z21: ='FS Desroches Daily'!AT23 -> 0 | AA21: ='FS Desroches Daily'!AT23 -> 0 | AB21: ='FS Desroches Daily'!AV23 -> 0 | AC21: ='FS Desroches Daily'!AZ23 -> 0 | AD21: ='FS Desroches Daily'!BB23 -> 0 | AE21: ='FS Desroches Daily'!BD23 -> 0 | AF21: ='FS Desroches Daily'!BF23 -> 0 | AG21: ='FS Desroches Daily'!BH23 -> 0 | AH21: ='FS Desroches Daily'!BJ23 -> 0 | AI21: ='FS Desroches Daily'!BL23 -> 0 | AJ21: ='FS Desroches Daily'!BN23 -> 0 | AK21: ='FS Desroches Daily'!BP23 -> 0 | AL21: ='FS Desroches Daily'!BR23 -> 0 | AM21: ='FS Desroches Daily'!BT23 -> 0 | AN21: ='FS Desroches Daily'!BV23 -> 0 | AO21: ='FS Desroches Daily'!BX23 -> 0 | AP21: ='FS Desroches Daily'!BZ23 -> 0 | AQ21: ='FS Desroches Daily'!CB23 -> 0 | AR21: ='FS Desroches Daily'!CD23 -> 0 | AS21: ='FS Desroches Daily'!CF23 -> 0 | AT21: ='FS Desroches Daily'!CH23 -> 0 | AU21: ='FS Desroches Daily'!CJ23 -> 0 | AV21: ='FS Desroches Daily'!CL23 -> 0 | AW21: ='FS Desroches Daily'!CM23 -> 0 | AX21: =IF(LPG!F28-LPG!F27<0,"0",(LPG!F28-LPG!F27)*1.8315) -> 0 | AY21: =IF(LPG!H28-LPG!H27<0,"0",(LPG!H28-LPG!H27)*1.8315) -> 0 | AZ21: =IF(LPG!J28-LPG!J27<0,"0",(LPG!J28-LPG!J27)*1.8315) -> 0 | BA21: =IF(LPG!M28-LPG!M27<0,"0",(LPG!M28-LPG!M27)*1.8315) -> 0 | BB21: =IF(LPG!Q28-LPG!Q27<0,"0",(LPG!Q28-LPG!Q27)*1.8315) -> 0 | BC21: ='FS Desroches Daily'!CN23 -> 0
A22: Seychelles at Desroches Island | B22: =B21+1 -> 21 | C22: 5 | D22: 2020 | E22: ='FS Desroches Daily'!D24 -> 0 | F22: ='FS Desroches Daily'!F24 -> 0 | G22: ='FS Desroches Daily'!H24 -> 0 | H22: ='FS Desroches Daily'!J24 -> 0 | I22: ='FS Desroches Daily'!L24 -> 0 | J22: ='FS Desroches Daily'!N24 -> 0 | K22: ='FS Desroches Daily'!P24 -> 0 | L22: ='FS Desroches Daily'!R24 -> 0 | M22: ='FS Desroches Daily'!T24 -> 0 | N22: ='FS Desroches Daily'!V24 -> 0 | O22: ='FS Desroches Daily'!X24 -> 0 | P22: ='FS Desroches Daily'!Z24 -> 0 | Q22: ='FS Desroches Daily'!AB24 -> 0 | R22: ='FS Desroches Daily'!AD24 -> 0 | S22: ='FS Desroches Daily'!AF24 -> 0 | T22: ='FS Desroches Daily'!AH24 -> 0 | U22: ='FS Desroches Daily'!AJ24 -> 0 | V22: ='FS Desroches Daily'!AL24 -> 0 | W22: ='FS Desroches Daily'!AN24 -> 0 | X22: ='FS Desroches Daily'!AP24 -> 0 | Y22: ='FS Desroches Daily'!AR24 -> 0 | Z22: ='FS Desroches Daily'!AT24 -> 0 | AA22: ='FS Desroches Daily'!AT24 -> 0 | AB22: ='FS Desroches Daily'!AV24 -> 0 | AC22: ='FS Desroches Daily'!AZ24 -> 0 | AD22: ='FS Desroches Daily'!BB24 -> 0 | AE22: ='FS Desroches Daily'!BD24 -> 0 | AF22: ='FS Desroches Daily'!BF24 -> 0 | AG22: ='FS Desroches Daily'!BH24 -> 0 | AH22: ='FS Desroches Daily'!BJ24 -> 0 | AI22: ='FS Desroches Daily'!BL24 -> 0 | AJ22: ='FS Desroches Daily'!BN24 -> 0 | AK22: ='FS Desroches Daily'!BP24 -> 0 | AL22: ='FS Desroches Daily'!BR24 -> 0 | AM22: ='FS Desroches Daily'!BT24 -> 0 | AN22: ='FS Desroches Daily'!BV24 -> 0 | AO22: ='FS Desroches Daily'!BX24 -> 0 | AP22: ='FS Desroches Daily'!BZ24 -> 0 | AQ22: ='FS Desroches Daily'!CB24 -> 0 | AR22: ='FS Desroches Daily'!CD24 -> 0 | AS22: ='FS Desroches Daily'!CF24 -> 0 | AT22: ='FS Desroches Daily'!CH24 -> 0 | AU22: ='FS Desroches Daily'!CJ24 -> 0 | AV22: ='FS Desroches Daily'!CL24 -> 0 | AW22: ='FS Desroches Daily'!CM24 -> 0 | AX22: =IF(LPG!F29-LPG!F28<0,"0",(LPG!F29-LPG!F28)*1.8315) -> 0 | AY22: =IF(LPG!H29-LPG!H28<0,"0",(LPG!H29-LPG!H28)*1.8315) -> 0 | AZ22: =IF(LPG!J29-LPG!J28<0,"0",(LPG!J29-LPG!J28)*1.8315) -> 0 | BA22: =IF(LPG!M29-LPG!M28<0,"0",(LPG!M29-LPG!M28)*1.8315) -> 0 | BB22: =IF(LPG!Q29-LPG!Q28<0,"0",(LPG!Q29-LPG!Q28)*1.8315) -> 0 | BC22: ='FS Desroches Daily'!CN24 -> 0
A23: Seychelles at Desroches Island | B23: =B22+1 -> 22 | C23: 5 | D23: 2020 | E23: ='FS Desroches Daily'!D25 -> 0 | F23: ='FS Desroches Daily'!F25 -> 0 | G23: ='FS Desroches Daily'!H25 -> 0 | H23: ='FS Desroches Daily'!J25 -> 0 | I23: ='FS Desroches Daily'!L25 -> 0 | J23: ='FS Desroches Daily'!N25 -> 0 | K23: ='FS Desroches Daily'!P25 -> 0 | L23: ='FS Desroches Daily'!R25 -> 0 | M23: ='FS Desroches Daily'!T25 -> 0 | N23: ='FS Desroches Daily'!V25 -> 0 | O23: ='FS Desroches Daily'!X25 -> 0 | P23: ='FS Desroches Daily'!Z25 -> 0 | Q23: ='FS Desroches Daily'!AB25 -> 0 | R23: ='FS Desroches Daily'!AD25 -> 0 | S23: ='FS Desroches Daily'!AF25 -> 0 | T23: ='FS Desroches Daily'!AH25 -> 0 | U23: ='FS Desroches Daily'!AJ25 -> 0 | V23: ='FS Desroches Daily'!AL25 -> 0 | W23: ='FS Desroches Daily'!AN25 -> 0 | X23: ='FS Desroches Daily'!AP25 -> 0 | Y23: ='FS Desroches Daily'!AR25 -> 0 | Z23: ='FS Desroches Daily'!AT25 -> 0 | AA23: ='FS Desroches Daily'!AT25 -> 0 | AB23: ='FS Desroches Daily'!AV25 -> 0 | AC23: ='FS Desroches Daily'!AZ25 -> 0 | AD23: ='FS Desroches Daily'!BB25 -> 0 | AE23: ='FS Desroches Daily'!BD25 -> 0 | AF23: ='FS Desroches Daily'!BF25 -> 0 | AG23: ='FS Desroches Daily'!BH25 -> 0 | AH23: ='FS Desroches Daily'!BJ25 -> 0 | AI23: ='FS Desroches Daily'!BL25 -> 0 | AJ23: ='FS Desroches Daily'!BN25 -> 0 | AK23: ='FS Desroches Daily'!BP25 -> 0 | AL23: ='FS Desroches Daily'!BR25 -> 0 | AM23: ='FS Desroches Daily'!BT25 -> 0 | AN23: ='FS Desroches Daily'!BV25 -> 0 | AO23: ='FS Desroches Daily'!BX25 -> 0 | AP23: ='FS Desroches Daily'!BZ25 -> 0 | AQ23: ='FS Desroches Daily'!CB25 -> 0 | AR23: ='FS Desroches Daily'!CD25 -> 0 | AS23: ='FS Desroches Daily'!CF25 -> 0 | AT23: ='FS Desroches Daily'!CH25 -> 0 | AU23: ='FS Desroches Daily'!CJ25 -> 0 | AV23: ='FS Desroches Daily'!CL25 -> 0 | AW23: ='FS Desroches Daily'!CM25 -> 0 | AX23: =IF(LPG!F30-LPG!F29<0,"0",(LPG!F30-LPG!F29)*1.8315) -> 0 | AY23: =IF(LPG!H30-LPG!H29<0,"0",(LPG!H30-LPG!H29)*1.8315) -> 0 | AZ23: =IF(LPG!J30-LPG!J29<0,"0",(LPG!J30-LPG!J29)*1.8315) -> 0 | BA23: =IF(LPG!M30-LPG!M29<0,"0",(LPG!M30-LPG!M29)*1.8315) -> 0 | BB23: =IF(LPG!Q30-LPG!Q29<0,"0",(LPG!Q30-LPG!Q29)*1.8315) -> 0 | BC23: ='FS Desroches Daily'!CN25 -> 0
A24: Seychelles at Desroches Island | B24: =B23+1 -> 23 | C24: 5 | D24: 2020 | E24: ='FS Desroches Daily'!D26 -> 0 | F24: ='FS Desroches Daily'!F26 -> 0 | G24: ='FS Desroches Daily'!H26 -> 0 | H24: ='FS Desroches Daily'!J26 -> 0 | I24: ='FS Desroches Daily'!L26 -> 0 | J24: ='FS Desroches Daily'!N26 -> 0 | K24: ='FS Desroches Daily'!P26 -> 0 | L24: ='FS Desroches Daily'!R26 -> 0 | M24: ='FS Desroches Daily'!T26 -> 0 | N24: ='FS Desroches Daily'!V26 -> 0 | O24: ='FS Desroches Daily'!X26 -> 0 | P24: ='FS Desroches Daily'!Z26 -> 0 | Q24: ='FS Desroches Daily'!AB26 -> 0 | R24: ='FS Desroches Daily'!AD26 -> 0 | S24: ='FS Desroches Daily'!AF26 -> 0 | T24: ='FS Desroches Daily'!AH26 -> 0 | U24: ='FS Desroches Daily'!AJ26 -> 0 | V24: ='FS Desroches Daily'!AL26 -> 0 | W24: ='FS Desroches Daily'!AN26 -> 0 | X24: ='FS Desroches Daily'!AP26 -> 0 | Y24: ='FS Desroches Daily'!AR26 -> 0 | Z24: ='FS Desroches Daily'!AT26 -> 0 | AA24: ='FS Desroches Daily'!AT26 -> 0 | AB24: ='FS Desroches Daily'!AV26 -> 0 | AC24: ='FS Desroches Daily'!AZ26 -> 0 | AD24: ='FS Desroches Daily'!BB26 -> 0 | AE24: ='FS Desroches Daily'!BD26 -> 0 | AF24: ='FS Desroches Daily'!BF26 -> 0 | AG24: ='FS Desroches Daily'!BH26 -> 0 | AH24: ='FS Desroches Daily'!BJ26 -> 0 | AI24: ='FS Desroches Daily'!BL26 -> 0 | AJ24: ='FS Desroches Daily'!BN26 -> 0 | AK24: ='FS Desroches Daily'!BP26 -> 0 | AL24: ='FS Desroches Daily'!BR26 -> 0 | AM24: ='FS Desroches Daily'!BT26 -> 0 | AN24: ='FS Desroches Daily'!BV26 -> 0 | AO24: ='FS Desroches Daily'!BX26 -> 0 | AP24: ='FS Desroches Daily'!BZ26 -> 0 | AQ24: ='FS Desroches Daily'!CB26 -> 0 | AR24: ='FS Desroches Daily'!CD26 -> 0 | AS24: ='FS Desroches Daily'!CF26 -> 0 | AT24: ='FS Desroches Daily'!CH26 -> 0 | AU24: ='FS Desroches Daily'!CJ26 -> 0 | AV24: ='FS Desroches Daily'!CL26 -> 0 | AW24: ='FS Desroches Daily'!CM26 -> 0 | AX24: =IF(LPG!F31-LPG!F30<0,"0",(LPG!F31-LPG!F30)*1.8315) -> 0 | AY24: =IF(LPG!H31-LPG!H30<0,"0",(LPG!H31-LPG!H30)*1.8315) -> 0 | AZ24: =IF(LPG!J31-LPG!J30<0,"0",(LPG!J31-LPG!J30)*1.8315) -> 0 | BA24: =IF(LPG!M31-LPG!M30<0,"0",(LPG!M31-LPG!M30)*1.8315) -> 0 | BB24: =IF(LPG!Q31-LPG!Q30<0,"0",(LPG!Q31-LPG!Q30)*1.8315) -> 0 | BC24: ='FS Desroches Daily'!CN26 -> 0
A25: Seychelles at Desroches Island | B25: =B24+1 -> 24 | C25: 5 | D25: 2020 | E25: ='FS Desroches Daily'!D27 -> 0 | F25: ='FS Desroches Daily'!F27 -> 0 | G25: ='FS Desroches Daily'!H27 -> 0 | H25: ='FS Desroches Daily'!J27 -> 0 | I25: ='FS Desroches Daily'!L27 -> 0 | J25: ='FS Desroches Daily'!N27 -> 0 | K25: ='FS Desroches Daily'!P27 -> 0 | L25: ='FS Desroches Daily'!R27 -> 0 | M25: ='FS Desroches Daily'!T27 -> 0 | N25: ='FS Desroches Daily'!V27 -> 0 | O25: ='FS Desroches Daily'!X27 -> 0 | P25: ='FS Desroches Daily'!Z27 -> 0 | Q25: ='FS Desroches Daily'!AB27 -> 0 | R25: ='FS Desroches Daily'!AD27 -> 0 | S25: ='FS Desroches Daily'!AF27 -> 0 | T25: ='FS Desroches Daily'!AH27 -> 0 | U25: ='FS Desroches Daily'!AJ27 -> 0 | V25: ='FS Desroches Daily'!AL27 -> 0 | W25: ='FS Desroches Daily'!AN27 -> 0 | X25: ='FS Desroches Daily'!AP27 -> 0 | Y25: ='FS Desroches Daily'!AR27 -> 0 | Z25: ='FS Desroches Daily'!AT27 -> 0 | AA25: ='FS Desroches Daily'!AT27 -> 0 | AB25: ='FS Desroches Daily'!AV27 -> 0 | AC25: ='FS Desroches Daily'!AZ27 -> 0 | AD25: ='FS Desroches Daily'!BB27 -> 0 | AE25: ='FS Desroches Daily'!BD27 -> 0 | AF25: ='FS Desroches Daily'!BF27 -> 0 | AG25: ='FS Desroches Daily'!BH27 -> 0 | AH25: ='FS Desroches Daily'!BJ27 -> 0 | AI25: ='FS Desroches Daily'!BL27 -> 0 | AJ25: ='FS Desroches Daily'!BN27 -> 0 | AK25: ='FS Desroches Daily'!BP27 -> 0 | AL25: ='FS Desroches Daily'!BR27 -> 0 | AM25: ='FS Desroches Daily'!BT27 -> 0 | AN25: ='FS Desroches Daily'!BV27 -> 0 | AO25: ='FS Desroches Daily'!BX27 -> 0 | AP25: ='FS Desroches Daily'!BZ27 -> 0 | AQ25: ='FS Desroches Daily'!CB27 -> 0 | AR25: ='FS Desroches Daily'!CD27 -> 0 | AS25: ='FS Desroches Daily'!CF27 -> 0 | AT25: ='FS Desroches Daily'!CH27 -> 0 | AU25: ='FS Desroches Daily'!CJ27 -> 0 | AV25: ='FS Desroches Daily'!CL27 -> 0 | AW25: ='FS Desroches Daily'!CM27 -> 0 | AX25: =IF(LPG!F32-LPG!F31<0,"0",(LPG!F32-LPG!F31)*1.8315) -> 0 | AY25: =IF(LPG!H32-LPG!H31<0,"0",(LPG!H32-LPG!H31)*1.8315) -> 0 | AZ25: =IF(LPG!J32-LPG!J31<0,"0",(LPG!J32-LPG!J31)*1.8315) -> 0 | BA25: =IF(LPG!M32-LPG!M31<0,"0",(LPG!M32-LPG!M31)*1.8315) -> 0 | BB25: =IF(LPG!Q32-LPG!Q31<0,"0",(LPG!Q32-LPG!Q31)*1.8315) -> 0 | BC25: ='FS Desroches Daily'!CN27 -> 0
