Workbook

Sheet Total
A1: Site Name | B1: Day | C1: Month | D1: Year | E1: Total Electricity Kwh | F1: Electricity Tariff ($/Kwh) | G1: LPG (Kg) | H1: LPG $/Kg | I1: Water Utility Supply (m3) m3 | J1: Water Utility Supply (m3) $/m3 | K1: Room Nights | L1: Utilities day cost dh
A2: Serengeti | B2: 1 | C2: 5 | D2: 2020 | E2: ='UTILITY REPORT 1'!F3 -> 1620 | F2: =('UTILITY REPORT 1'!E3*'UTILITY REPORT 1'!D3)/'UTILITY REPORT 1'!F3 -> 0.41856173 | G2: =IF('Utility summery'!M6<0,"0",'Utility summery'!M6) -> 34.98 | H2: 0 | I2: =IF('UTILITY REPORT 1'!G3<0,"0",'UTILITY REPORT 1'!G3) -> 31 | J2: 0 | K2: ='UTILITY REPORT 1'!C3 -> 0 | L2: =E2*F2+G2*H2+#REF!*#REF!+I2*J2 -> #REF!
A3: Serengeti | B3: =B2+1 -> 2 | C3: 5 | D3: 2020 | E3: ='UTILITY REPORT 1'!F4 -> 1580 | F3: =('UTILITY REPORT 1'!E4*'UTILITY REPORT 1'!D4)/'UTILITY REPORT 1'!F4 -> 0.41750633 | G3: =IF('Utility summery'!M7<0,"0",'Utility summery'!M7) -> 19.756 | H3: 0 | I3: =IF('UTILITY REPORT 1'!G4<0,"0",'UTILITY REPORT 1'!G4) -> 31 | J3: 0 | K3: ='UTILITY REPORT 1'!C4 -> 0 | L3: =E3*F3+G3*H3+#REF!*#REF!+I3*J3 -> #REF!
A4: Serengeti | B4: =B3+1 -> 3 | C4: 5 | D4: 2020 | E4: ='UTILITY REPORT 1'!F5 -> 1625 | F4: =('UTILITY REPORT 1'!E5*'UTILITY REPORT 1'!D5)/'UTILITY REPORT 1'!F5 -> 0.40571692 | G4: =IF('Utility summery'!M8<0,"0",'Utility summery'!M8) -> 26.972 | H4: 0 | I4: =IF('UTILITY REPORT 1'!G5<0,"0",'UTILITY REPORT 1'!G5) -> 47 | J4: 0 | K4: ='UTILITY REPORT 1'!C5 -> 0 | L4: =E4*F4+G4*H4+#REF!*#REF!+I4*J4 -> #REF!
A5: Serengeti | B5: =B4+1 -> 4 | C5: 5 | D5: 2020 | E5: ='UTILITY REPORT 1'!F6 -> 1460 | F5: =('UTILITY REPORT 1'!E6*'UTILITY REPORT 1'!D6)/'UTILITY REPORT 1'!F6 -> 0.43419863 | G5: =IF('Utility summery'!M9<0,"0",'Utility summery'!M9) -> 26.4 | H5: 0 | I5: =IF('UTILITY REPORT 1'!G6<0,"0",'UTILITY REPORT 1'!G6) -> 31 | J5: 0 | K5: ='UTILITY REPORT 1'!C6 -> 0 | L5: =E5*F5+G5*H5+#REF!*#REF!+I5*J5 -> #REF!
A6: Serengeti | B6: =B5+1 -> 5 | C6: 5 | D6: 2020 | E6: ='UTILITY REPORT 1'!F7 -> 1531 | F6: =('UTILITY REPORT 1'!E7*'UTILITY REPORT 1'!D7)/'UTILITY REPORT 1'!F7 -> 0.4221032 | G6: =IF('Utility summery'!M10<0,"0",'Utility summery'!M10) -> 22.44 | H6: 0 | I6: =IF('UTILITY REPORT 1'!G7<0,"0",'UTILITY REPORT 1'!G7) -> 30 | J6: 0 | K6: ='UTILITY REPORT 1'!C7 -> 0 | L6: =E6*F6+G6*H6+#REF!*#REF!+I6*J6 -> #REF!
A7: Serengeti | B7: =B6+1 -> 6 | C7: 5 | D7: 2020 | E7: ='UTILITY REPORT 1'!F8 -> 0 | F7: =('UTILITY REPORT 1'!E8*'UTILITY REPORT 1'!D8)/'UTILITY REPORT 1'!F8 -> #DIV/0! | G7: =IF('Utility summery'!M11<0,"0",'Utility summery'!M11) -> 14.608 | H7: 0 | I7: =IF('UTILITY REPORT 1'!G8<0,"0",'UTILITY REPORT 1'!G8) -> 33 | J7: 0 | K7: ='UTILITY REPORT 1'!C8 -> 0 | L7: =E7*F7+G7*H7+#REF!*#REF!+I7*J7 -> #DIV/0!
A8: Serengeti | B8: =B7+1 -> 7 | C8: 5 | D8: 2020 | E8: ='UTILITY REPORT 1'!F9 -> 1434 | F8: =('UTILITY REPORT 1'!E9*'UTILITY REPORT 1'!D9)/'UTILITY REPORT 1'!F9 -> 0.44457462 | G8: =IF('Utility summery'!M12<0,"0",'Utility summery'!M12) -> 32.252 | H8: 0 | I8: =IF('UTILITY REPORT 1'!G9<0,"0",'UTILITY REPORT 1'!G9) -> 41 | J8: 0 | K8: ='UTILITY REPORT 1'!C9 -> 0 | L8: =E8*F8+G8*H8+#REF!*#REF!+I8*J8 -> #REF!
A9: Serengeti | B9: =B8+1 -> 8 | C9: 5 | D9: 2020 | E9: ='UTILITY REPORT 1'!F10 -> 1432 | F9: =('UTILITY REPORT 1'!E10*'UTILITY REPORT 1'!D10)/'UTILITY REPORT 1'!F10 -> 0.48381983 | G9: =IF('Utility summery'!M13<0,"0",'Utility summery'!M13) -> 35.552 | H9: 0 | I9: =IF('UTILITY REPORT 1'!G10<0,"0",'UTILITY REPORT 1'!G10) -> 37 | J9: 0 | K9: ='UTILITY REPORT 1'!C10 -> 0 | L9: =E9*F9+G9*H9+#REF!*#REF!+I9*J9 -> #REF!
A10: Serengeti | B10: =B9+1 -> 9 | C10: 5 | D10: 2020 | E10: ='UTILITY REPORT 1'!F11 -> 1527 | F10: =('UTILITY REPORT 1'!E11*'UTILITY REPORT 1'!D11)/'UTILITY REPORT 1'!F11 -> 0.43359528 | G10: =IF('Utility summery'!M14<0,"0",'Utility summery'!M14) -> 28.908 | H10: 0 | I10: =IF('UTILITY REPORT 1'!G11<0,"0",'UTILITY REPORT 1'!G11) -> 51 | J10: 0 | K10: ='UTILITY REPORT 1'!C11 -> 0 | L10: =E10*F10+G10*H10+#REF!*#REF!+I10*J10 -> #REF!
A11: Serengeti | B11: =B10+1 -> 10 | C11: 5 | D11: 2020 | E11: ='UTILITY REPORT 1'!F12 -> 1451 | F11: =('UTILITY REPORT 1'!E12*'UTILITY REPORT 1'!D12)/'UTILITY REPORT 1'!F12 -> 0.44957271 | G11: =IF('Utility summery'!M15<0,"0",'Utility summery'!M15) -> 45.144 | H11: 0 | I11: =IF('UTILITY REPORT 1'!G12<0,"0",'UTILITY REPORT 1'!G12) -> 51 | J11: 0 | K11: ='UTILITY REPORT 1'!C12 -> 0 | L11: =E11*F11+G11*H11+#REF!*#REF!+I11*J11 -> #REF!
A12: Serengeti | B12: =B11+1 -> 11 | C12: 5 | D12: 2020 | E12: ='UTILITY REPORT 1'!F13 -> 1449 | F12: =('UTILITY REPORT 1'!E13*'UTILITY REPORT 1'!D13)/'UTILITY REPORT 1'!F13 -> 0.46610766 | G12: =IF('Utility summery'!M16<0,"0",'Utility summery'!M16) -> 38.896 | H12: 0 | I12: =IF('UTILITY REPORT 1'!G13<0,"0",'UTILITY REPORT 1'!G13) -> 56 | J12: 0 | K12: ='UTILITY REPORT 1'!C13 -> 0 | L12: =E12*F12+G12*H12+#REF!*#REF!+I12*J12 -> #REF!
A13: Serengeti | B13: =B12+1 -> 12 | C13: 5 | D13: 2020 | E13: ='UTILITY REPORT 1'!F14 -> 1623 | F13: =('UTILITY REPORT 1'!E14*'UTILITY REPORT 1'!D14)/'UTILITY REPORT 1'!F14 -> 0.44301294 | G13: =IF('Utility summery'!M17<0,"0",'Utility summery'!M17) -> 27.016 | H13: 0 | I13: =IF('UTILITY REPORT 1'!G14<0,"0",'UTILITY REPORT 1'!G14) -> 58 | J13: 0 | K13: ='UTILITY REPORT 1'!C14 -> 0 | L13: =E13*F13+G13*H13+#REF!*#REF!+I13*J13 -> #REF!
A14: Serengeti | B14: =B13+1 -> 13 | C14: 5 | D14: 2020 | E14: ='UTILITY REPORT 1'!F15 -> 1552 | F14: =('UTILITY REPORT 1'!E15*'UTILITY REPORT 1'!D15)/'UTILITY REPORT 1'!F15 -> 0.42280284 | G14: =IF('Utility summery'!M18<0,"0",'Utility summery'!M18) -> 29.216 | H14: 0 | I14: =IF('UTILITY REPORT 1'!G15<0,"0",'UTILITY REPORT 1'!G15) -> 41 | J14: 0 | K14: ='UTILITY REPORT 1'!C15 -> 0 | L14: =E14*F14+G14*H14+#REF!*#REF!+I14*J14 -> #REF!
... A30: Serengeti | B30: =B29+1 -> 29 | C30: 5 | D30: 2020 | E30: ='UTILITY REPORT 1'!F31 -> 0 | F30: =('UTILITY REPORT 1'!E31*'UTILITY REPORT 1'!D31)/'UTILITY REPORT 1'!F31 -> #DIV/0! | G30: =IF('Utility summery'!M34<0,"0",'Utility summery'!M34) -> 0 | H30: 0 | I30: =IF('UTILITY REPORT 1'!G31<0,"0",'UTILITY REPORT 1'!G31) -> 0 | J30: 0 | K30: ='UTILITY REPORT 1'!C31 -> 0 | L30: =E30*F30+G30*H30+#REF!*#REF!+I30*J30 -> #DIV/0!
A31: Serengeti | B31: 30 | C31: 5 | D31: 2020 | E31: ='UTILITY REPORT 1'!F32 -> 0 | F31: =('UTILITY REPORT 1'!E32*'UTILITY REPORT 1'!D32)/'UTILITY REPORT 1'!F32 -> #DIV/0! | G31: =IF('Utility summery'!M35<0,"0",'Utility summery'!M35) -> 0 | H31: 0 | I31: =IF('UTILITY REPORT 1'!G32<0,"0",'UTILITY REPORT 1'!G32) -> 0 | J31: 0 | K31: ='UTILITY REPORT 1'!C32 -> 0 | L31: =E31*F31+G31*H31+#REF!*#REF!+I31*J31 -> #DIV/0!
A32: Serengeti | B32: 31 | C32: 5 | D32: 2020 | E32: ='UTILITY REPORT 1'!F33 -> 0 | F32: =('UTILITY REPORT 1'!E33*'UTILITY REPORT 1'!D33)/'UTILITY REPORT 1'!F33 -> #DIV/0! | G32: =IF('Utility summery'!M36<0,"0",'Utility summery'!M36) -> 0 | H32: 0 | I32: =IF('UTILITY REPORT 1'!G33<0,"0",'UTILITY REPORT 1'!G33) -> 0 | J32: 0 | K32: ='UTILITY REPORT 1'!C33 -> 0

Sheet Submetering
A1: Site Name | B1: Day | C1: Month | D1: Year | E1: Transport Consumption (LT) | F1: Generators Consumption (LT) | G1: Total Electricity Kwh | H1: Kitchen (KWh) | I1: Laundry (KWh) | J1: STP (M3) | K1: RO prodution (M3) | L1: Amani Restaurant (M3) | M1: Kitchen (M3) | N1: Laundry (M3) | O1: Laundry (M3) | P1: Total water Consumption (M3) | Q1: Borehole #1 (M3) | R1: Borehole #2 (M3) | S1: Borehole #3 (M3) | T1: Borehole #4 (M3) | U1: Borehole #5 (M3) | V1: Borehole #6 (M3) | W1: Total Bore holes production (M3) | X1: Room Nights
A2: Serengeti | B2: 1 | C2: 5 | D2: 2020 | E2: ='UTILITY REPORT 1'!I3 -> 0 | F2: ='UTILITY REPORT 1'!E3 -> 678.07 | G2: ='UTILITY REPORT 1'!F3 -> 1620 | H2: =IF('Kit report'!F4<0,"0",'Kit report'!F4) -> 108 | I2: =IF('Kit report'!X4<0,"0",'Kit report'!X4) -> 0 | J2: =IF('Utility summery'!H6<0,"0",'Utility summery'!H6) -> 65 | K2: =IF('UTILITY REPORT 1'!H3<0,"0",'UTILITY REPORT 1'!H3) -> 40 | L2: ='Water-Meter'!K6 -> 1 | M2: ='Water-Meter'!H6 -> 0 | N2: ='Water-Meter'!Q6 -> 1 | O2: =K2*E2+H2*I2+#REF!*#REF!+J2*L2 -> #REF! | P2: ='Water-Meter'!E6 -> 31 | Q2: =IF('Water-Meter'!U6<0,"0",'Water-Meter'!U6) -> 0 | R2: =IF('Water-Meter'!X6<0,"0",'Water-Meter'!X6) -> 0 | S2: =IF('Water-Meter'!AA6<0,"0",'Water-Meter'!AA6) -> 0 | T2: =IF('Water-Meter'!AD6<0,"0",'Water-Meter'!AD6) -> 21 | U2: =IF('Water-Meter'!AG6<0,"0",'Water-Meter'!AG6) -> 25 | V2: =IF('Water-Meter'!AJ6<0,"0",'Water-Meter'!AJ6) -> 0 | W2: ='Water-Meter'!AN6 -> 46 | X2: =Total!K2 -> 0
A3: Serengeti | B3: =B2+1 -> 2 | C3: 5 | D3: 2020 | E3: ='UTILITY REPORT 1'!I4 -> 0 | F3: ='UTILITY REPORT 1'!E4 -> 659.66 | G3: ='UTILITY REPORT 1'!F4 -> 1580 | H3: =IF('Kit report'!F5<0,"0",'Kit report'!F5) -> 108 | I3: =IF('Kit report'!X5<0,"0",'Kit report'!X5) -> 20 | J3: =IF('Utility summery'!H7<0,"0",'Utility summery'!H7) -> 51 | K3: =IF('UTILITY REPORT 1'!H4<0,"0",'UTILITY REPORT 1'!H4) -> 12 | L3: ='Water-Meter'!K7 -> 0 | M3: ='Water-Meter'!H7 -> 0 | N3: ='Water-Meter'!Q7 -> 1 | O3: =K3*E3+H3*I3+#REF!*#REF!+J3*L3 -> #REF! | P3: ='Water-Meter'!E7 -> 31 | Q3: =IF('Water-Meter'!U7<0,"0",'Water-Meter'!U7) -> 0 | R3: =IF('Water-Meter'!X7<0,"0",'Water-Meter'!X7) -> 0 | S3: =IF('Water-Meter'!AA7<0,"0",'Water-Meter'!AA7) -> 0 | T3: =IF('Water-Meter'!AD7<0,"0",'Water-Meter'!AD7) -> 20 | U3: =IF('Water-Meter'!AG7<0,"0",'Water-Meter'!AG7) -> 26 | V3: =IF('Water-Meter'!AJ7<0,"0",'Water-Meter'!AJ7) -> 0 | W3: ='Water-Meter'!AN7 -> 46 | X3: =Total!K3 -> 0
A4: Serengeti | B4: =B3+1 -> 3 | C4: 5 | D4: 2020 | E4: ='UTILITY REPORT 1'!I5 -> 0 | F4: ='UTILITY REPORT 1'!E5 -> 659.29 | G4: ='UTILITY REPORT 1'!F5 -> 1625 | H4: =IF('Kit report'!F6<0,"0",'Kit report'!F6) -> 96 | I4: =IF('Kit report'!X6<0,"0",'Kit report'!X6) -> 0 | J4: =IF('Utility summery'!H8<0,"0",'Utility summery'!H8) -> 53 | K4: =IF('UTILITY REPORT 1'!H5<0,"0",'UTILITY REPORT 1'!H5) -> 77 | L4: ='Water-Meter'!K8 -> 1 | M4: ='Water-Meter'!H8 -> 0 | N4: ='Water-Meter'!Q8 -> 0 | O4: =K4*E4+H4*I4+#REF!*#REF!+J4*L4 -> #REF! | P4: ='Water-Meter'!E8 -> 47 | Q4: =IF('Water-Meter'!U8<0,"0",'Water-Meter'!U8) -> 0 | R4: =IF('Water-Meter'!X8<0,"0",'Water-Meter'!X8) -> 0 | S4: =IF('Water-Meter'!AA8<0,"0",'Water-Meter'!AA8) -> 0 | T4: =IF('Water-Meter'!AD8<0,"0",'Water-Meter'!AD8) -> 24 | U4: =IF('Water-Meter'!AG8<0,"0",'Water-Meter'!AG8) -> 25 | V4: =IF('Water-Meter'!AJ8<0,"0",'Water-Meter'!AJ8) -> 0 | W4: ='Water-Meter'!AN8 -> 49 | X4: =Total!K4 -> 0
A5: Serengeti | B5: =B4+1 -> 4 | C5: 5 | D5: 2020 | E5: ='UTILITY REPORT 1'!I6 -> 2.33 | F5: ='UTILITY REPORT 1'!E6 -> 633.93 | G5: ='UTILITY REPORT 1'!F6 -> 1460 | H5: =IF('Kit report'!F7<0,"0",'Kit report'!F7) -> 108 | I5: =IF('Kit report'!X7<0,"0",'Kit report'!X7) -> 20 | J5: =IF('Utility summery'!H9<0,"0",'Utility summery'!H9) -> 56 | K5: =IF('UTILITY REPORT 1'!H6<0,"0",'UTILITY REPORT 1'!H6) -> 0 | L5: ='Water-Meter'!K9 -> 0 | M5: ='Water-Meter'!H9 -> 0 | N5: ='Water-Meter'!Q9 -> 1 | O5: =K5*E5+H5*I5+#REF!*#REF!+J5*L5 -> #REF! | P5: ='Water-Meter'!E9 -> 31 | Q5: =IF('Water-Meter'!U9<0,"0",'Water-Meter'!U9) -> 0 | R5: =IF('Water-Meter'!X9<0,"0",'Water-Meter'!X9) -> 0 | S5: =IF('Water-Meter'!AA9<0,"0",'Water-Meter'!AA9) -> 0 | T5: =IF('Water-Meter'!AD9<0,"0",'Water-Meter'!AD9) -> 22 | U5: =IF('Water-Meter'!AG9<0,"0",'Water-Meter'!AG9) -> 20 | V5: =IF('Water-Meter'!AJ9<0,"0",'Water-Meter'!AJ9) -> 0 | W5: ='Water-Meter'!AN9 -> 42 | X5: =Total!K5 -> 0
A6: Serengeti | B6: =B5+1 -> 5 | C6: 5 | D6: 2020 | E6: ='UTILITY REPORT 1'!I7 -> 0 | F6: ='UTILITY REPORT 1'!E7 -> 646.24 | G6: ='UTILITY REPORT 1'!F7 -> 1531 | H6: =IF('Kit report'!F8<0,"0",'Kit report'!F8) -> 96 | I6: =IF('Kit report'!X8<0,"0",'Kit report'!X8) -> 0 | J6: =IF('Utility summery'!H10<0,"0",'Utility summery'!H10) -> 54 | K6: =IF('UTILITY REPORT 1'!H7<0,"0",'UTILITY REPORT 1'!H7) -> 68 | L6: ='Water-Meter'!K10 -> 1 | M6: ='Water-Meter'!H10 -> 0 | N6: ='Water-Meter'!Q10 -> 0 | O6: =K6*E6+H6*I6+#REF!*#REF!+J6*L6 -> #REF! | P6: ='Water-Meter'!E10 -> 30 | Q6: =IF('Water-Meter'!U10<0,"0",'Water-Meter'!U10) -> 70 | R6: =IF('Water-Meter'!X10<0,"0",'Water-Meter'!X10) -> 0 | S6: =IF('Water-Meter'!AA10<0,"0",'Water-Meter'!AA10) -> 0 | T6: =IF('Water-Meter'!AD10<0,"0",'Water-Meter'!AD10) -> 21 | U6: =IF('Water-Meter'!AG10<0,"0",'Water-Meter'!AG10) -> 0 | V6: =IF('Water-Meter'!AJ10<0,"0",'Water-Meter'!AJ10) -> 0 | W6: ='Water-Meter'!AN10 -> 91 | X6: =Total!K6 -> 0
A7: Serengeti | B7: =B6+1 -> 6 | C7: 5 | D7: 2020 | E7: ='UTILITY REPORT 1'!I8 -> 31.11 | F7: ='UTILITY REPORT 1'!E8 -> 627.88 | G7: ='UTILITY REPORT 1'!F8 -> 0 | H7: =IF('Kit report'!F9<0,"0",'Kit report'!F9) -> 84 | I7: =IF('Kit report'!X9<0,"0",'Kit report'!X9) -> 20 | J7: =IF('Utility summery'!H11<0,"0",'Utility summery'!H11) -> 27 | K7: =IF('UTILITY REPORT 1'!H8<0,"0",'UTILITY REPORT 1'!H8) -> 36 | L7: ='Water-Meter'!K11 -> 0 | M7: ='Water-Meter'!H11 -> 0 | N7: ='Water-Meter'!Q11 -> 1 | O7: =K7*E7+H7*I7+#REF!*#REF!+J7*L7 -> #REF! | P7: ='Water-Meter'!E11 -> 33 | Q7: =IF('Water-Meter'!U11<0,"0",'Water-Meter'!U11) -> 37 | R7: =IF('Water-Meter'!X11<0,"0",'Water-Meter'!X11) -> 0 | S7: =IF('Water-Meter'!AA11<0,"0",'Water-Meter'!AA11) -> 0 | T7: =IF('Water-Meter'!AD11<0,"0",'Water-Meter'!AD11) -> 22 | U7: =IF('Water-Meter'!AG11<0,"0",'Water-Meter'!AG11) -> 0 | V7: =IF('Water-Meter'!AJ11<0,"0",'Water-Meter'!AJ11) -> 0 | W7: ='Water-Meter'!AN11 -> 59 | X7: =Total!K7 -> 0
A8: Serengeti | B8: =B7+1 -> 7 | C8: 5 | D8: 2020 | E8: ='UTILITY REPORT 1'!I9 -> 22.97 | F8: ='UTILITY REPORT 1'!E9 -> 637.52 | G8: ='UTILITY REPORT 1'!F9 -> 1434 | H8: =IF('Kit report'!F10<0,"0",'Kit report'!F10) -> 96 | I8: =IF('Kit report'!X10<0,"0",'Kit report'!X10) -> 20 | J8: =IF('Utility summery'!H12<0,"0",'Utility summery'!H12) -> 38 | K8: =IF('UTILITY REPORT 1'!H9<0,"0",'UTILITY REPORT 1'!H9) -> 0 | L8: ='Water-Meter'!K12 -> 0 | M8: ='Water-Meter'!H12 -> 0 | N8: ='Water-Meter'!Q12 -> 0 | O8: =K8*E8+H8*I8+#REF!*#REF!+J8*L8 -> #REF! | P8: ='Water-Meter'!E12 -> 41 | Q8: =IF('Water-Meter'!U12<0,"0",'Water-Meter'!U12) -> 17 | R8: =IF('Water-Meter'!X12<0,"0",'Water-Meter'!X12) -> 0 | S8: =IF('Water-Meter'!AA12<0,"0",'Water-Meter'!AA12) -> 0 | T8: =IF('Water-Meter'!AD12<0,"0",'Water-Meter'!AD12) -> 21 | U8: =IF('Water-Meter'!AG12<0,"0",'Water-Meter'!AG12) -> 0 | V8: =IF('Water-Meter'!AJ12<0,"0",'Water-Meter'!AJ12) -> 0 | W8: ='Water-Meter'!AN12 -> 38 | X8: =Total!K8 -> 0
A9: Serengeti | B9: =B8+1 -> 8 | C9: 5 | D9: 2020 | E9: ='UTILITY REPORT 1'!I10 -> 80.1 | F9: ='UTILITY REPORT 1'!E10 -> 692.83 | G9: ='UTILITY REPORT 1'!F10 -> 1432 | H9: =IF('Kit report'!F11<0,"0",'Kit report'!F11) -> 108 | I9: =IF('Kit report'!X11<0,"0",'Kit report'!X11) -> 40 | J9: =IF('Utility summery'!H13<0,"0",'Utility summery'!H13) -> 41 | K9: =IF('UTILITY REPORT 1'!H10<0,"0",'UTILITY REPORT 1'!H10) -> 70 | L9: ='Water-Meter'!K13 -> 1 | M9: ='Water-Meter'!H13 -> 0 | N9: ='Water-Meter'!Q13 -> 1 | O9: =K9*E9+H9*I9+#REF!*#REF!+J9*L9 -> #REF! | P9: ='Water-Meter'!E13 -> 37 | Q9: =IF('Water-Meter'!U13<0,"0",'Water-Meter'!U13) -> 0 | R9: =IF('Water-Meter'!X13<0,"0",'Water-Meter'!X13) -> 0 | S9: =IF('Water-Meter'!AA13<0,"0",'Water-Meter'!AA13) -> 0 | T9: =IF('Water-Meter'!AD13<0,"0",'Water-Meter'!AD13) -> 22 | U9: =IF('Water-Meter'!AG13<0,"0",'Water-Meter'!AG13) -> 0 | V9: =IF('Water-Meter'!AJ13<0,"0",'Water-Meter'!AJ13) -> 0 | W9: ='Water-Meter'!AN13 -> 22 | X9: =Total!K9 -> 0
A10: Serengeti | B10: =B9+1 -> 9 | C10: 5 | D10: 2020 | E10: ='UTILITY REPORT 1'!I11 -> 0 | F10: ='UTILITY REPORT 1'!E11 -> 662.1 | G10: ='UTILITY REPORT 1'!F11 -> 1527 | H10: =IF('Kit report'!F12<0,"0",'Kit report'!F12) -> 96 | I10: =IF('Kit report'!X12<0,"0",'Kit report'!X12) -> 0 | J10: =IF('Utility summery'!H14<0,"0",'Utility summery'!H14) -> 40 | K10: =IF('UTILITY REPORT 1'!H11<0,"0",'UTILITY REPORT 1'!H11) -> 110 | L10: ='Water-Meter'!K14 -> 0 | M10: ='Water-Meter'!H14 -> 0 | N10: ='Water-Meter'!Q14 -> 1 | O10: =K10*E10+H10*I10+#REF!*#REF!+J10*L10 -> #REF! | P10: ='Water-Meter'!E14 -> 51 | Q10: =IF('Water-Meter'!U14<0,"0",'Water-Meter'!U14) -> 0 | R10: =IF('Water-Meter'!X14<0,"0",'Water-Meter'!X14) -> 0 | S10: =IF('Water-Meter'!AA14<0,"0",'Water-Meter'!AA14) -> 0 | T10: =IF('Water-Meter'!AD14<0,"0",'Water-Meter'!AD14) -> 22 | U10: =IF('Water-Meter'!AG14<0,"0",'Water-Meter'!AG14) -> 0 | V10: =IF('Water-Meter'!AJ14<0,"0",'Water-Meter'!AJ14) -> 0 | W10: ='Water-Meter'!AN14 -> 22 | X10: =Total!K10 -> 0
A11: Serengeti | B11: =B10+1 -> 10 | C11: 5 | D11: 2020 | E11: ='UTILITY REPORT 1'!I12 -> 0 | F11: ='UTILITY REPORT 1'!E12 -> 652.33 | G11: ='UTILITY REPORT 1'!F12 -> 1451 | H11: =IF('Kit report'!F13<0,"0",'Kit report'!F13) -> 96 | I11: =IF('Kit report'!X13<0,"0",'Kit report'!X13) -> 0 | J11: =IF('Utility summery'!H15<0,"0",'Utility summery'!H15) -> 35 | K11: =IF('UTILITY REPORT 1'!H12<0,"0",'UTILITY REPORT 1'!H12) -> 0 | L11: ='Water-Meter'!K15 -> 1 | M11: ='Water-Meter'!H15 -> 0 | N11: ='Water-Meter'!Q15 -> 0 | O11: =K11*E11+H11*I11+#REF!*#REF!+J11*L11 -> #REF! | P11: ='Water-Meter'!E15 -> 51 | Q11: =IF('Water-Meter'!U15<0,"0",'Water-Meter'!U15) -> 24 | R11: =IF('Water-Meter'!X15<0,"0",'Water-Meter'!X15) -> 0 | S11: =IF('Water-Meter'!AA15<0,"0",'Water-Meter'!AA15) -> 0 | T11: =IF('Water-Meter'!AD15<0,"0",'Water-Meter'!AD15) -> 22 | U11: =IF('Water-Meter'!AG15<0,"0",'Water-Meter'!AG15) -> 0 | V11: =IF('Water-Meter'!AJ15<0,"0",'Water-Meter'!AJ15) -> 0 | W11: ='Water-Meter'!AN15 -> 46 | X11: =Total!K11 -> 0
A12: Serengeti | B12: =B11+1 -> 11 | C12: 5 | D12: 2020 | E12: ='UTILITY REPORT 1'!I13 -> 0 | F12: ='UTILITY REPORT 1'!E13 -> 675.39 | G12: ='UTILITY REPORT 1'!F13 -> 1449 | H12: =IF('Kit report'!F14<0,"0",'Kit report'!F14) -> 108 | I12: =IF('Kit report'!X14<0,"0",'Kit report'!X14) -> 0 | J12: =IF('Utility summery'!H16<0,"0",'Utility summery'!H16) -> 38 | K12: =IF('UTILITY REPORT 1'!H13<0,"0",'UTILITY REPORT 1'!H13) -> 0 | L12: ='Water-Meter'!K16 -> 0 | M12: ='Water-Meter'!H16 -> 0 | N12: ='Water-Meter'!Q16 -> 0 | O12: =K12*E12+H12*I12+#REF!*#REF!+J12*L12 -> #REF! | P12: ='Water-Meter'!E16 -> 56 | Q12: =IF('Water-Meter'!U16<0,"0",'Water-Meter'!U16) -> 37 | R12: =IF('Water-Meter'!X16<0,"0",'Water-Meter'!X16) -> 0 | S12: =IF('Water-Meter'!AA16<0,"0",'Water-Meter'!AA16) -> 0 | T12: =IF('Water-Meter'!AD16<0,"0",'Water-Meter'!AD16) -> 22 | U12: =IF('Water-Meter'!AG16<0,"0",'Water-Meter'!AG16) -> 0 | V12: =IF('Water-Meter'!AJ16<0,"0",'Water-Meter'!AJ16) -> 0 | W12: ='Water-Meter'!AN16 -> 59 | X12: =Total!K12 -> 0
A13: Serengeti | B13: =B12+1 -> 12 | C13: 5 | D13: 2020 | E13: ='UTILITY REPORT 1'!I14 -> 106.89 | F13: ='UTILITY REPORT 1'!E14 -> 719.01 | G13: ='UTILITY REPORT 1'!F14 -> 1623 | H13: =IF('Kit report'!F15<0,"0",'Kit report'!F15) -> 96 | I13: =IF('Kit report'!X15<0,"0",'Kit report'!X15) -> 20 | J13: =IF('Utility summery'!H17<0,"0",'Utility summery'!H17) -> 43 | K13: =IF('UTILITY REPORT 1'!H14<0,"0",'UTILITY REPORT 1'!H14) -> 71 | L13: ='Water-Meter'!K17 -> 0 | M13: ='Water-Meter'!H17 -> 0 | N13: ='Water-Meter'!Q17 -> 1 | O13: =K13*E13+H13*I13+#REF!*#REF!+J13*L13 -> #REF! | P13: ='Water-Meter'!E17 -> 58 | Q13: =IF('Water-Meter'!U17<0,"0",'Water-Meter'!U17) -> 23 | R13: =IF('Water-Meter'!X17<0,"0",'Water-Meter'!X17) -> 0 | S13: =IF('Water-Meter'!AA17<0,"0",'Water-Meter'!AA17) -> 43 | T13: =IF('Water-Meter'!AD17<0,"0",'Water-Meter'!AD17) -> 22 | U13: =IF('Water-Meter'!AG17<0,"0",'Water-Meter'!AG17) -> 0 | V13: =IF('Water-Meter'!AJ17<0,"0",'Water-Meter'!AJ17) -> 0 | W13: ='Water-Meter'!AN17 -> 88 | X13: =Total!K13 -> 0
A14: Serengeti | B14: =B13+1 -> 13 | C14: 5 | D14: 2020 | E14: ='UTILITY REPORT 1'!I15 -> 0 | F14: ='UTILITY REPORT 1'!E15 -> 656.19 | G14: ='UTILITY REPORT 1'!F15 -> 1552 | H14: =IF('Kit report'!F16<0,"0",'Kit report'!F16) -> 108 | I14: =IF('Kit report'!X16<0,"0",'Kit report'!X16) -> 0 | J14: =IF('Utility summery'!H18<0,"0",'Utility summery'!H18) -> 32 | K14: =IF('UTILITY REPORT 1'!H15<0,"0",'UTILITY REPORT 1'!H15) -> 0 | L14: ='Water-Meter'!K18 -> 1 | M14: ='Water-Meter'!H18 -> 0 | N14: ='Water-Meter'!Q18 -> 0 | O14: =K14*E14+H14*I14+#REF!*#REF!+J14*L14 -> #REF! | P14: ='Water-Meter'!E18 -> 41 | Q14: =IF('Water-Meter'!U18<0,"0",'Water-Meter'!U18) -> 10 | R14: =IF('Water-Meter'!X18<0,"0",'Water-Meter'!X18) -> 0 | S14: =IF('Water-Meter'!AA18<0,"0",'Water-Meter'!AA18) -> 10 | T14: =IF('Water-Meter'!AD18<0,"0",'Water-Meter'!AD18) -> 4 | U14: =IF('Water-Meter'!AG18<0,"0",'Water-Meter'!AG18) -> 0 | V14: =IF('Water-Meter'!AJ18<0,"0",'Water-Meter'!AJ18) -> 0 | W14: ='Water-Meter'!AN18 -> 24 | X14: =Total!K14 -> 0
... A30: Serengeti | B30: =B29+1 -> 29 | C30: 5 | D30: 2020 | E30: ='UTILITY REPORT 1'!I31 -> 0 | F30: ='UTILITY REPORT 1'!E31 -> 0 | G30: ='UTILITY REPORT 1'!F31 -> 0 | H30: =IF('Kit report'!F32<0,"0",'Kit report'!F32) -> 0 | I30: =IF('Kit report'!X32<0,"0",'Kit report'!X32) -> 0 | J30: =IF('Utility summery'!H34<0,"0",'Utility summery'!H34) -> 0 | K30: =IF('UTILITY REPORT 1'!H31<0,"0",'UTILITY REPORT 1'!H31) -> 0 | L30: ='Water-Meter'!K34 -> 0 | M30: ='Water-Meter'!H34 -> 0 | N30: ='Water-Meter'!Q34 -> 0 | O30: =K30*E30+H30*I30+#REF!*#REF!+J30*L30 -> #REF! | P30: ='Water-Meter'!E34 -> 0 | Q30: =IF('Water-Meter'!U34<0,"0",'Water-Meter'!U34) -> 0 | R30: =IF('Water-Meter'!X34<0,"0",'Water-Meter'!X34) -> 0 | S30: =IF('Water-Meter'!AA34<0,"0",'Water-Meter'!AA34) -> 0 | T30: =IF('Water-Meter'!AD34<0,"0",'Water-Meter'!AD34) -> 0 | U30: =IF('Water-Meter'!AG34<0,"0",'Water-Meter'!AG34) -> 0 | V30: =IF('Water-Meter'!AJ34<0,"0",'Water-Meter'!AJ34) -> 0 | W30: ='Water-Meter'!AN34 -> 0 | X30: =Total!K30 -> 0
A31: Serengeti | B31: 30 | C31: 5 | D31: 2020 | E31: ='UTILITY REPORT 1'!I32 -> 0 | F31: ='UTILITY REPORT 1'!E32 -> 0 | G31: ='UTILITY REPORT 1'!F32 -> 0 | H31: =IF('Kit report'!F33<0,"0",'Kit report'!F33) -> 0 | I31: =IF('Kit report'!X33<0,"0",'Kit report'!X33) -> 0 | J31: =IF('Utility summery'!H35<0,"0",'Utility summery'!H35) -> 0 | K31: =IF('UTILITY REPORT 1'!H32<0,"0",'UTILITY REPORT 1'!H32) -> 0 | L31: ='Water-Meter'!K35 -> 0 | M31: ='Water-Meter'!H35 -> 0 | N31: ='Water-Meter'!Q35 -> 0 | O31: =K31*E31+H31*I31+#REF!*#REF!+J31*L31 -> #REF! | P31: ='Water-Meter'!E35 -> 0 | Q31: =IF('Water-Meter'!U35<0,"0",'Water-Meter'!U35) -> 0 | R31: =IF('Water-Meter'!X35<0,"0",'Water-Meter'!X35) -> 0 | S31: =IF('Water-Meter'!AA35<0,"0",'Water-Meter'!AA35) -> 0 | T31: =IF('Water-Meter'!AD35<0,"0",'Water-Meter'!AD35) -> 0 | U31: =IF('Water-Meter'!AG35<0,"0",'Water-Meter'!AG35) -> 0 | V31: =IF('Water-Meter'!AJ35<0,"0",'Water-Meter'!AJ35) -> 0 | W31: ='Water-Meter'!AN35 -> 0 | X31: =Total!K31 -> 0
A32: Serengeti | B32: 31 | C32: 5 | D32: 2020 | E32: ='UTILITY REPORT 1'!I33 -> 0 | F32: ='UTILITY REPORT 1'!E33 -> 0 | G32: ='UTILITY REPORT 1'!F33 -> 0 | H32: =IF('Kit report'!F34<0,"0",'Kit report'!F34) -> 0 | I32: =IF('Kit report'!X34<0,"0",'Kit report'!X34) -> 0 | J32: =IF('Utility summery'!H36<0,"0",'Utility summery'!H36) -> 0 | K32: =IF('UTILITY REPORT 1'!H33<0,"0",'UTILITY REPORT 1'!H33) -> 0 | L32: ='Water-Meter'!K36 -> 0 | M32: ='Water-Meter'!H36 -> 0 | N32: ='Water-Meter'!Q36 -> 0 | P32: ='Water-Meter'!E36 -> 0 | Q32: =IF('Water-Meter'!U36<0,"0",'Water-Meter'!U36) -> 0 | R32: =IF('Water-Meter'!X36<0,"0",'Water-Meter'!X36) -> 0 | S32: =IF('Water-Meter'!AA36<0,"0",'Water-Meter'!AA36) -> 0 | T32: =IF('Water-Meter'!AD36<0,"0",'Water-Meter'!AD36) -> 0 | U32: =IF('Water-Meter'!AG36<0,"0",'Water-Meter'!AG36) -> 0 | V32: =IF('Water-Meter'!AJ36<0,"0",'Water-Meter'!AJ36) -> 0 | W32: ='Water-Meter'!AN36 -> 0 | X32: =Total!K32 -> 0

Sheet UTILITY REPORT 1
A1: NOVEMBER UTILITY REPORT
A2: Date | B2: % | C2: Guest Rooms Occupied | D2: Diesel cost Per Liter ($) | E2: Diesel consumption (LT) | F2: Power production (KW) | G2: Water consumption (M3) | H2: RO prodution (M3) | I2: Transport Consupmtion (LT)
A3: 43862 | B3: =Gen!C11 -> 0 | C3: ='Summery Report'!E5 -> 0 | D3: 1 | E3: =Gen!T11 -> 678.07 | F3: =Gen!U11 -> 1620 | G3: ='Water-Meter'!E6 -> 31 | H3: ='Utility report '!AC6 -> 40 | I3: =Gen!AK11 -> 0
A4: 43863 | B4: =Gen!C12 -> 0 | C4: ='Summery Report'!E6 -> 0 | D4: 1 | E4: =Gen!T12 -> 659.66 | F4: =Gen!U12 -> 1580 | G4: ='Water-Meter'!E7 -> 31 | H4: ='Utility report '!AC7 -> 12 | I4: =Gen!AK12 -> 0
A5: 43864 | B5: =Gen!C13 -> 0 | C5: ='Summery Report'!E7 -> 0 | D5: 1 | E5: =Gen!T13 -> 659.29 | F5: =Gen!U13 -> 1625 | G5: ='Water-Meter'!E8 -> 47 | H5: ='Utility report '!AC8 -> 77 | I5: =Gen!AK13 -> 0
A6: 43865 | B6: =Gen!C14 -> 0 | C6: ='Summery Report'!E8 -> 0 | D6: 1 | E6: =Gen!T14 -> 633.93 | F6: =Gen!U14 -> 1460 | G6: ='Water-Meter'!E9 -> 31 | H6: ='Utility report '!AC9 -> 0 | I6: =Gen!AK14 -> 2.33
A7: 43866 | B7: =Gen!C15 -> 0 | C7: ='Summery Report'!E9 -> 0 | D7: 1 | E7: =Gen!T15 -> 646.24 | F7: =Gen!U15 -> 1531 | G7: ='Water-Meter'!E10 -> 30 | H7: ='Utility report '!AC10 -> 68 | I7: =Gen!AK15 -> 0
A8: 43867 | B8: =Gen!C16 -> 0 | C8: ='Summery Report'!E10 -> 0 | D8: 1 | E8: =Gen!T16 -> 627.88 | F8: =Gen!U16 -> 0 | G8: ='Water-Meter'!E11 -> 33 | H8: ='Utility report '!AC11 -> 36 | I8: =Gen!AK16 -> 31.11
A9: 43868 | B9: =Gen!C17 -> 0 | C9: ='Summery Report'!E11 -> 0 | D9: 1 | E9: =Gen!T17 -> 637.52 | F9: =Gen!U17 -> 1434 | G9: ='Water-Meter'!E12 -> 41 | H9: ='Utility report '!AC12 -> 0 | I9: =Gen!AK17 -> 22.97
A10: 43869 | B10: =Gen!C18 -> 0 | C10: ='Summery Report'!E12 -> 0 | D10: 1 | E10: =Gen!T18 -> 692.83 | F10: =Gen!U18 -> 1432 | G10: ='Water-Meter'!E13 -> 37 | H10: ='Utility report '!AC13 -> 70 | I10: =Gen!AK18 -> 80.1
A11: 43870 | B11: =Gen!C19 -> 0 | C11: ='Summery Report'!E13 -> 0 | D11: 1 | E11: =Gen!T19 -> 662.1 | F11: =Gen!U19 -> 1527 | G11: ='Water-Meter'!E14 -> 51 | H11: ='Utility report '!AC14 -> 110 | I11: =Gen!AK19 -> 0
A12: 43871 | B12: =Gen!C20 -> 0 | C12: ='Summery Report'!E14 -> 0 | D12: 1 | E12: =Gen!T20 -> 652.33 | F12: =Gen!U20 -> 1451 | G12: ='Water-Meter'!E15 -> 51 | H12: ='Utility report '!AC15 -> 0 | I12: =Gen!AK20 -> 0
A13: 43872 | B13: =Gen!C21 -> 0 | C13: ='Summery Report'!E15 -> 0 | D13: 1 | E13: =Gen!T21 -> 675.39 | F13: =Gen!U21 -> 1449 | G13: ='Water-Meter'!E16 -> 56 | H13: ='Utility report '!AC16 -> 0 | I13: =Gen!AK21 -> 0
A14: 43873 | B14: =Gen!C22 -> 0 | C14: ='Summery Report'!E16 -> 0 | D14: 1 | E14: =Gen!T22 -> 719.01 | F14: =Gen!U22 -> 1623 | G14: ='Water-Meter'!E17 -> 58 | H14: ='Utility report '!AC17 -> 71 | I14: =Gen!AK22 -> 106.89
... A34: 43893 | B34: =Gen!C42 -> 0 | C34: ='Summery Report'!E36 -> 0 | D34: 2 | E34: =Gen!T42 -> 0 | F34: =Gen!U42 -> 0 | G34: ='Water-Meter'!E37 -> 0 | H34: ='Utility report '!AC37 -> 0 | I34: =Gen!AK42 -> 0

Sheet Utility summery
A4: Date | B4: Room Occupied | C4: Electricity Units Generated KW | D4: Diseal | G4: Water | J4: Gas | N4: Cost of utilites
D5: Generator | E5: Transport | F5: Total | G5: RO | H5: STP | I5: Total Consumption | J5: 2 ton | K5: 1 Ton | L5: 1 Ton | M5: Total consumption | N5: Electricity /1.4$/liter | O5: Diseal for Transport | P5: Gas /2.38$/Kg | Q5: Total HLP Cost | R5: Electricity Cost/Room $ | S5: cost/Room $
A6: =Gen!B11 -> 43952 | B6: ='Summery Report'!E5 -> 0 | C6: =Gen!U11 -> 1620 | D6: =Gen!T11 -> 678.07 | E6: =Gen!AK11 -> 0 | F6: =Gen!AS11 -> 678.07 | G6: ='Utility report '!AC6 -> 40 | H6: ='Utility report '!AE6 -> 65 | I6: ='Water-Meter'!E6 -> 31 | J6: ='Lpg (2)'!B10 -> 85 | K6: ='Lpg (2)'!C10 -> 83 | L6: ='Lpg (2)'!D10 -> 41 | M6: ='Lpg (2)'!G10 -> 34.98 | O6: =E6 -> 0 | P6: ='[1]Lpg (2)'!#REF! -> #REF! | Q6: ='[1]Summery Report'!#REF! -> #REF! | R6: =N6/B6 -> #DIV/0! | S6: =Q6/B6 -> #REF!
A7: =Gen!B12 -> 43953 | B7: ='Summery Report'!E6 -> 0 | C7: =Gen!U12 -> 1580 | D7: =Gen!T12 -> 659.66 | E7: =Gen!AK12 -> 0 | F7: =Gen!AS12 -> 659.66 | G7: ='Utility report '!AC7 -> 12 | H7: ='Utility report '!AE7 -> 51 | I7: ='Water-Meter'!E7 -> 31 | J7: ='Lpg (2)'!B11 -> 85 | K7: ='Lpg (2)'!C11 -> 83 | L7: ='Lpg (2)'!D11 -> 39 | M7: ='Lpg (2)'!G11 -> 19.756 | N7: =D7*1.4 -> 923.524 | O7: =E7*1.4 -> 0 | P7: ='[1]Lpg (2)'!#REF! -> #REF! | Q7: ='[1]Summery Report'!#REF! -> #REF! | R7: =N7/B7 -> #DIV/0! | S7: =Q7/B7 -> #REF!
A8: =Gen!B13 -> 43954 | B8: ='Summery Report'!E7 -> 0 | C8: =Gen!U13 -> 1625 | D8: =Gen!T13 -> 659.29 | E8: =Gen!AK13 -> 0 | F8: =Gen!AS13 -> 659.29 | G8: ='Utility report '!AC8 -> 77 | H8: ='Utility report '!AE8 -> 53 | I8: ='Water-Meter'!E8 -> 47 | J8: ='Lpg (2)'!B12 -> 85 | K8: ='Lpg (2)'!C12 -> 83 | L8: ='Lpg (2)'!D12 -> 37 | M8: ='Lpg (2)'!G12 -> 26.972 | N8: =D8*1.4 -> 923.006 | O8: =E8*1.4 -> 0 | P8: ='[1]Lpg (2)'!#REF! -> #REF! | Q8: ='[1]Summery Report'!#REF! -> #REF! | R8: =N8/B8 -> #DIV/0! | S8: =Q8/B8 -> #REF!
A9: =Gen!B14 -> 43955 | B9: ='Summery Report'!E8 -> 0 | C9: =Gen!U14 -> 1460 | D9: =Gen!T14 -> 633.93 | E9: =Gen!AK14 -> 2.33 | F9: =Gen!AS14 -> 636.26 | G9: ='Utility report '!AC9 -> 0 | H9: ='Utility report '!AE9 -> 56 | I9: ='Water-Meter'!E9 -> 31 | J9: ='Lpg (2)'!B13 -> 85 | K9: ='Lpg (2)'!C13 -> 83 | L9: ='Lpg (2)'!D13 -> 36 | M9: ='Lpg (2)'!G13 -> 26.4 | N9: =D9*1.4 -> 887.502 | O9: =E9*1.4 -> 3.262 | P9: ='[1]Lpg (2)'!#REF! -> #REF! | Q9: ='[1]Summery Report'!#REF! -> #REF! | R9: =N9/B9 -> #DIV/0! | S9: =Q9/B9 -> #REF!
A10: =Gen!B15 -> 43956 | B10: ='Summery Report'!E9 -> 0 | C10: =Gen!U15 -> 1531 | D10: =Gen!T15 -> 646.24 | E10: =Gen!AK15 -> 0 | F10: =Gen!AS15 -> 646.24 | G10: ='Utility report '!AC10 -> 68 | H10: ='Utility report '!AE10 -> 54 | I10: ='Water-Meter'!E10 -> 30 | J10: ='Lpg (2)'!B14 -> 85 | K10: ='Lpg (2)'!C14 -> 83 | L10: ='Lpg (2)'!D14 -> 35 | M10: ='Lpg (2)'!G14 -> 22.44 | N10: =D10*1.4 -> 904.736 | O10: =E10*1.4 -> 0 | P10: ='[1]Lpg (2)'!#REF! -> #REF! | Q10: ='[1]Summery Report'!#REF! -> #REF! | R10: =N10/B10 -> #DIV/0! | S10: =Q10/B10 -> #REF!
A11: =Gen!B16 -> 43957 | B11: ='Summery Report'!E10 -> 0 | C11: =Gen!U16 -> 0 | D11: =Gen!T16 -> 627.88 | E11: =Gen!AK16 -> 31.11 | F11: =Gen!AS16 -> 658.99 | G11: ='Utility report '!AC11 -> 36 | H11: ='Utility report '!AE11 -> 27 | I11: ='Water-Meter'!E11 -> 33 | J11: ='Lpg (2)'!B15 -> 85 | K11: ='Lpg (2)'!C15 -> 83 | L11: ='Lpg (2)'!D15 -> 34 | M11: ='Lpg (2)'!G15 -> 14.608 | N11: =D11*1.4 -> 879.032 | O11: =E11*1.4 -> 43.554 | P11: ='[1]Lpg (2)'!#REF! -> #REF! | Q11: ='[1]Summery Report'!#REF! -> #REF! | R11: =N11/B11 -> #DIV/0! | S11: =Q11/B11 -> #REF!
A12: =Gen!B17 -> 43958 | B12: ='Summery Report'!E11 -> 0 | C12: =Gen!U17 -> 1434 | D12: =Gen!T17 -> 637.52 | E12: =Gen!AK17 -> 22.97 | F12: =Gen!AS17 -> 660.49 | G12: ='Utility report '!AC12 -> 0 | H12: ='Utility report '!AE12 -> 38 | I12: ='Water-Meter'!E12 -> 41 | J12: ='Lpg (2)'!B16 -> 85 | K12: ='Lpg (2)'!C16 -> 83 | L12: ='Lpg (2)'!D16 -> 32 | M12: ='Lpg (2)'!G16 -> 32.252 | N12: =D12*1.4 -> 892.528 | O12: =E12*1.4 -> 32.158 | P12: ='[1]Lpg (2)'!#REF! -> #REF! | Q12: ='[1]Summery Report'!#REF! -> #REF! | R12: =N12/B12 -> #DIV/0! | S12: =Q12/B12 -> #REF!
A13: =Gen!B18 -> 43959 | B13: ='Summery Report'!E12 -> 0 | C13: =Gen!U18 -> 1432 | D13: =Gen!T18 -> 692.83 | E13: =Gen!AK18 -> 80.1 | F13: =Gen!AS18 -> 772.93 | G13: ='Utility report '!AC13 -> 70 | H13: ='Utility report '!AE13 -> 41 | I13: ='Water-Meter'!E13 -> 37 | J13: ='Lpg (2)'!B17 -> 85 | K13: ='Lpg (2)'!C17 -> 83 | L13: ='Lpg (2)'!D17 -> 30 | M13: ='Lpg (2)'!G17 -> 35.552 | N13: =D13*1.4 -> 969.962 | O13: =E13*1.4 -> 112.14 | P13: ='[1]Lpg (2)'!#REF! -> #REF! | Q13: ='[1]Summery Report'!#REF! -> #REF! | R13: =N13/B13 -> #DIV/0! | S13: =Q13/B13 -> #REF!
A14: =Gen!B19 -> 43960 | B14: ='Summery Report'!E13 -> 0 | C14: =Gen!U19 -> 1527 | D14: =Gen!T19 -> 662.1 | E14: =Gen!AK19 -> 0 | F14: =Gen!AS19 -> 662.1 | G14: ='Utility report '!AC14 -> 110 | H14: ='Utility report '!AE14 -> 40 | I14: ='Water-Meter'!E14 -> 51 | J14: ='Lpg (2)'!B18 -> 85 | K14: ='Lpg (2)'!C18 -> 83 | L14: ='Lpg (2)'!D18 -> 28 | M14: ='Lpg (2)'!G18 -> 28.908 | N14: =D14*1.4 -> 926.94 | O14: =E14*1.4 -> 0 | P14: ='[1]Lpg (2)'!#REF! -> #REF! | Q14: ='[1]Summery Report'!#REF! -> #REF! | R14: =N14/B14 -> #DIV/0! | S14: =Q14/B14 -> #REF!
A15: =Gen!B20 -> 43961 | B15: ='Summery Report'!E14 -> 0 | C15: =Gen!U20 -> 1451 | D15: =Gen!T20 -> 652.33 | E15: =Gen!AK20 -> 0 | F15: =Gen!AS20 -> 652.33 | G15: ='Utility report '!AC15 -> 0 | H15: ='Utility report '!AE15 -> 35 | I15: ='Water-Meter'!E15 -> 51 | J15: ='Lpg (2)'!B19 -> 85 | K15: ='Lpg (2)'!C19 -> 83 | L15: ='Lpg (2)'!D19 -> 25 | M15: ='Lpg (2)'!G19 -> 45.144 | N15: =D15*1.4 -> 913.262 | O15: =E15*1.4 -> 0 | P15: ='[1]Lpg (2)'!#REF! -> #REF! | Q15: ='[1]Summery Report'!#REF! -> #REF! | R15: =N15/B15 -> #DIV/0! | S15: =Q15/B15 -> #REF!
A16: =Gen!B21 -> 43962 | B16: ='Summery Report'!E15 -> 0 | C16: =Gen!U21 -> 1449 | D16: =Gen!T21 -> 675.39 | E16: =Gen!AK21 -> 0 | F16: =Gen!AS21 -> 675.39 | G16: ='Utility report '!AC16 -> 0 | H16: ='Utility report '!AE16 -> 38 | I16: ='Water-Meter'!E16 -> 56 | J16: ='Lpg (2)'!B20 -> 85 | K16: ='Lpg (2)'!C20 -> 83 | L16: ='Lpg (2)'!D20 -> 21 | M16: ='Lpg (2)'!G20 -> 38.896 | N16: =D16*1.4 -> 945.546 | O16: =E16*1.4 -> 0 | P16: ='[1]Lpg (2)'!#REF! -> #REF! | Q16: ='[1]Summery Report'!#REF! -> #REF! | R16: =N16/B16 -> #DIV/0! | S16: =Q16/B16 -> #REF!
A17: =Gen!B22 -> 43963 | B17: ='Summery Report'!E16 -> 0 | C17: =Gen!U22 -> 1623 | D17: =Gen!T22 -> 719.01 | E17: =Gen!AK22 -> 106.89 | F17: =Gen!AS22 -> 825.9 | G17: ='Utility report '!AC17 -> 71 | H17: ='Utility report '!AE17 -> 43 | I17: ='Water-Meter'!E17 -> 58 | J17: ='Lpg (2)'!B21 -> 85 | K17: ='Lpg (2)'!C22 -> 83 | L17: ='Lpg (2)'!D21 -> 20 | M17: ='Lpg (2)'!G21 -> 27.016 | N17: =D17*1.4 -> 1006.614 | O17: =E17*1.4 -> 149.646 | P17: ='[1]Lpg (2)'!#REF! -> #REF! | Q17: ='[1]Summery Report'!#REF! -> #REF! | R17: =N17/B17 -> #DIV/0! | S17: =Q17/B17 -> #REF!
A18: =Gen!B23 -> 43964 | B18: ='Summery Report'!E17 -> 0 | C18: =Gen!U23 -> 1552 | D18: =Gen!T23 -> 656.19 | E18: =Gen!AK23 -> 0 | F18: =Gen!AS23 -> 656.19 | G18: ='Utility report '!AC18 -> 0 | H18: ='Utility report '!AE18 -> 32 | I18: ='Water-Meter'!E18 -> 41 | J18: ='Lpg (2)'!B22 -> 85 | K18: ='Lpg (2)'!C23 -> 83 | L18: ='Lpg (2)'!D22 -> 18 | M18: ='Lpg (2)'!G22 -> 29.216 | N18: =D18*1.4 -> 918.666 | O18: =E18*1.4 -> 0 | P18: ='[1]Lpg (2)'!#REF! -> #REF! | Q18: ='[1]Summery Report'!#REF! -> #REF! | R18: =N18/B18 -> #DIV/0! | S18: =Q18/B18 -> #REF!
A19: =Gen!B24 -> 43965 | B19: ='Summery Report'!E18 -> 0 | C19: =Gen!U24 -> 1480 | D19: =Gen!T24 -> 633.08 | E19: =Gen!AK24 -> 0 | F19: =Gen!AS24 -> 633.08 | G19: ='Utility report '!AC19 -> 0 | H19: ='Utility report '!AE19 -> 36 | I19: ='Water-Meter'!E19 -> 33 | J19: ='Lpg (2)'!B23 -> 85 | K19: ='Lpg (2)'!C24 -> 83 | L19: ='Lpg (2)'!D23 -> 16 | M19: ='Lpg (2)'!G23 -> 37.18 | N19: =D19*1.4 -> 886.312 | O19: =E19*1.4 -> 0 | P19: ='[1]Lpg (2)'!#REF! -> #REF! | Q19: ='[1]Summery Report'!#REF! -> #REF! | R19: =N19/B19 -> #DIV/0! | S19: =Q19/B19 -> #REF!
A20: =Gen!B25 -> 43966 | B20: ='Summery Report'!E19 -> 0 | C20: =Gen!U25 -> 1322 | D20: =Gen!T25 -> 603.86 | E20: =Gen!AK25 -> 3.78 | F20: =Gen!AS25 -> 607.64 | G20: ='Utility report '!AC20 -> 0 | H20: ='Utility report '!AE20 -> 35 | I20: ='Water-Meter'!E20 -> 38 | J20: ='Lpg (2)'!B24 -> 85 | K20: ='Lpg (2)'!C25 -> 83 | L20: ='Lpg (2)'!D24 -> 15 | M20: ='Lpg (2)'!G24 -> 22.176 | N20: =D20*1.4 -> 845.404 | O20: =E20*1.4 -> 5.292 | P20: ='[1]Lpg (2)'!#REF! -> #REF! | Q20: ='[1]Summery Report'!#REF! -> #REF! | R20: =N20/B20 -> #DIV/0! | S20: =Q20/B20 -> #REF!
A21: =Gen!B26 -> 43967 | B21: ='Summery Report'!E20 -> 0 | C21: =Gen!U26 -> 1674 | D21: =Gen!T26 -> 635.49 | E21: =Gen!AK26 -> 0 | F21: =Gen!AS26 -> 635.49 | G21: ='Utility report '!AC21 -> 69 | H21: ='Utility report '!AE21 -> 43 | I21: ='Water-Meter'!E21 -> 44 | J21: ='Lpg (2)'!B25 -> 85 | K21: ='Lpg (2)'!C25 -> 83 | L21: ='Lpg (2)'!D25 -> 13 | M21: ='Lpg (2)'!G25 -> 34.848 | N21: =D21*1.4 -> 889.686 | O21: =E21*1.4 -> 0 | P21: ='[1]Lpg (2)'!#REF! -> #REF! | Q21: ='[1]Summery Report'!#REF! -> #REF! | R21: =N21/B21 -> #DIV/0! | S21: =Q21/B21 -> #REF!
A22: =Gen!B27 -> 43968 | B22: ='Summery Report'!E21 -> 0 | C22: =Gen!U27 -> 0 | D22: =Gen!T27 -> 0 | E22: =Gen!AK27 -> 0 | F22: =Gen!AS27 -> 0 | G22: ='Utility report '!AC22 -> -32087 | H22: ='Utility report '!AE22 -> -201425 | I22: ='Water-Meter'!E22 -> 0 | J22: ='Lpg (2)'!B26 -> 0 | K22: ='Lpg (2)'!C26 -> 0 | L22: ='Lpg (2)'!D26 -> 0 | M22: ='Lpg (2)'!G26 -> -313606.88 | N22: =D22*1.4 -> 0 | O22: =E22*1.4 -> 0 | P22: ='[1]Lpg (2)'!#REF! -> #REF! | Q22: ='[1]Summery Report'!#REF! -> #REF! | R22: =N22/B22 -> #DIV/0! | S22: =Q22/B22 -> #REF!
A23: =Gen!B28 -> 43969 | B23: ='Summery Report'!E22 -> 0 | C23: =Gen!U28 -> 0 | D23: =Gen!T28 -> 0 | E23: =Gen!AK28 -> 0 | F23: =Gen!AS28 -> 0 | G23: ='Utility report '!AC23 -> 0 | H23: ='Utility report '!AE23 -> 0 | I23: ='Water-Meter'!E23 -> 0 | J23: ='Lpg (2)'!B27 -> 0 | K23: ='Lpg (2)'!C27 -> 0 | L23: ='Lpg (2)'!D27 -> 0 | M23: ='Lpg (2)'!G27 -> 0 | N23: =D23*1.4 -> 0 | O23: =E23*1.4 -> 0 | P23: ='[1]Lpg (2)'!#REF! -> #REF! | Q23: ='[1]Summery Report'!#REF! -> #REF! | R23: =N23/B23 -> #DIV/0! | S23: =Q23/B23 -> #REF!
A24: =Gen!B29 -> 43970 | B24: ='Summery Report'!E23 -> 0 | C24: =Gen!U29 -> 0 | D24: =Gen!T29 -> 0 | E24: =Gen!AK29 -> 0 | F24: =Gen!AS29 -> 0 | G24: ='Utility report '!AC24 -> 0 | H24: ='Utility report '!AE24 -> 0 | I24: ='Water-Meter'!E24 -> 0 | J24: ='Lpg (2)'!B28 -> 0 | K24: ='Lpg (2)'!C28 -> 0 | L24: ='Lpg (2)'!D28 -> 0 | M24: ='Lpg (2)'!G28 -> 0 | N24: =D24*1.4 -> 0 | O24: =E24*1.4 -> 0 | P24: ='[1]Lpg (2)'!#REF! -> #REF! | Q24: ='[1]Summery Report'!#REF! -> #REF! | R24: =N24/B24 -> #DIV/0! | S24: =Q24/B24 -> #REF!
A25: =Gen!B30 -> 43971 | B25: ='Summery Report'!E24 -> 0 | C25: =Gen!U30 -> 0 | D25: =Gen!T30 -> 0 | E25: =Gen!AK30 -> 0 | F25: =Gen!AS30 -> 0 | G25: ='Utility report '!AC25 -> 0 | H25: ='Utility report '!AE25 -> 0 | I25: ='Water-Meter'!E25 -> 0 | J25: ='Lpg (2)'!B29 -> 0 | K25: ='Lpg (2)'!C29 -> 0 | L25: ='Lpg (2)'!D29 -> 0 | M25: ='Lpg (2)'!G29 -> 0 | N25: =D25*1.4 -> 0 | O25: =E25*1.4 -> 0 | P25: ='[1]Lpg (2)'!#REF! -> #REF! | Q25: ='[1]Summery Report'!#REF! -> #REF! | R25: =N25/B25 -> #DIV/0! | S25: =Q25/B25 -> #REF!
A26: =Gen!B31 -> 43972 | B26: ='Summery Report'!E25 -> 0 | C26: =Gen!U31 -> 0 | D26: =Gen!T31 -> 0 | E26: =Gen!AK31 -> 0 | F26: =Gen!AS31 -> 0 | G26: ='Utility report '!AC26 -> 0 | H26: ='Utility report '!AE26 -> 0 | I26: ='Water-Meter'!E26 -> 0 | J26: ='Lpg (2)'!B30 -> 0 | K26: ='Lpg (2)'!C30 -> 0 | L26: ='Lpg (2)'!D30 -> 0 | M26: ='Lpg (2)'!G30 -> 0 | N26: =D26*1.4 -> 0 | O26: =E26*1.4 -> 0 | P26: ='[1]Lpg (2)'!#REF! -> #REF! | Q26: ='[1]Summery Report'!#REF! -> #REF! | R26: =N26/B26 -> #DIV/0! | S26: =Q26/B26 -> #REF!
A27: =Gen!B32 -> 43973 | B27: ='Summery Report'!E26 -> 0 | C27: =Gen!U32 -> 0 | D27: =Gen!T32 -> 0 | E27: =Gen!AK32 -> 0 | F27: =Gen!AS32 -> 0 | G27: ='Utility report '!AC27 -> 0 | H27: ='Utility report '!AE27 -> 0 | I27: ='Water-Meter'!E27 -> 0 | J27: ='Lpg (2)'!B31 -> 0 | K27: ='Lpg (2)'!C31 -> 0 | L27: ='Lpg (2)'!D31 -> 0 | M27: ='Lpg (2)'!G31 -> 0 | N27: =D27*1.4 -> 0 | O27: =E27*1.4 -> 0 | P27: ='[1]Lpg (2)'!#REF! -> #REF! | Q27: ='[1]Summery Report'!#REF! -> #REF! | R27: =N27/B27 -> #DIV/0! | S27: =Q27/B27 -> #REF!
A28: =Gen!B33 -> 43974 | B28: ='Summery Report'!E27 -> 0 | C28: =Gen!U33 -> 0 | D28: =Gen!T33 -> 0 | E28: =Gen!AK33 -> 0 | F28: =Gen!AS33 -> 0 | G28: ='Utility report '!AC28 -> 0 | H28: ='Utility report '!AE28 -> 0 | I28: ='Water-Meter'!E28 -> 0 | J28: ='Lpg (2)'!B32 -> 0 | K28: ='Lpg (2)'!C32 -> 0 | L28: ='Lpg (2)'!D32 -> 0 | M28: ='Lpg (2)'!G32 -> 0 | N28: =D28*1.4 -> 0 | O28: =E28*1.4 -> 0 | P28: ='[1]Lpg (2)'!#REF! -> #REF! | Q28: ='[1]Summery Report'!#REF! -> #REF! | R28: =N28/B28 -> #DIV/0! | S28: =Q28/B28 -> #REF!
A29: =Gen!B34 -> 43975 | B29: ='Summery Report'!E28 -> 0 | C29: =Gen!U34 -> 0 | D29: =Gen!T34 -> 0 | E29: =Gen!AK34 -> 0 | F29: =Gen!AS34 -> 0 | G29: ='Utility report '!AC29 -> 0 | H29: ='Utility report '!AE29 -> 0 | I29: ='Water-Meter'!E29 -> 0 | J29: ='Lpg (2)'!B33 -> 0 | K29: ='Lpg (2)'!C33 -> 0 | L29: ='Lpg (2)'!D33 -> 0 | M29: ='Lpg (2)'!G33 -> 0 | N29: =D29*1.4 -> 0 | O29: =E29*1.4 -> 0 | P29: ='[1]Lpg (2)'!#REF! -> #REF! | Q29: ='[1]Summery Report'!#REF! -> #REF! | R29: =N29/B29 -> #DIV/0! | S29: =Q29/B29 -> #REF!
A30: =Gen!B35 -> 43976 | B30: ='Summery Report'!E29 -> 0 | C30: =Gen!U35 -> 0 | D30: =Gen!T35 -> 0 | E30: =Gen!AK35 -> 0 | F30: =Gen!AS35 -> 0 | G30: ='Utility report '!AC30 -> 0 | H30: ='Utility report '!AE30 -> 0 | I30: ='Water-Meter'!E30 -> 0 | J30: ='Lpg (2)'!B34 -> 0 | K30: ='Lpg (2)'!C34 -> 0 | L30: ='Lpg (2)'!D34 -> 0 | M30: ='Lpg (2)'!G34 -> 0 | N30: =D30*1.4 -> 0 | O30: =E30*1.4 -> 0 | P30: ='[1]Lpg (2)'!#REF! -> #REF! | Q30: ='[1]Summery Report'!#REF! -> #REF! | R30: =N30/B30 -> #DIV/0! | S30: =Q30/B30 -> #REF!
A31: =Gen!B36 -> 43977 | B31: ='Summery Report'!E30 -> 0 | C31: =Gen!U36 -> 0 | D31: =Gen!T36 -> 0 | E31: =Gen!AK36 -> 0 | F31: =Gen!AS36 -> 0 | G31: ='Utility report '!AC31 -> 0 | H31: ='Utility report '!AE31 -> 0 | I31: ='Water-Meter'!E31 -> 0 | J31: ='Lpg (2)'!B35 -> 0 | K31: ='Lpg (2)'!C35 -> 0 | L31: ='Lpg (2)'!D35 -> 0 | M31: ='Lpg (2)'!G35 -> 0 | N31: =D31*1.4 -> 0 | O31: =E31*1.4 -> 0 | P31: ='[1]Lpg (2)'!#REF! -> #REF! | Q31: ='[1]Summery Report'!#REF! -> #REF! | R31: =N31/B31 -> #DIV/0! | S31: =Q31/B31 -> #REF!
A32: =Gen!B37 -> 43978 | B32: ='Summery Report'!E31 -> 0 | C32: =Gen!U37 -> 0 | D32: =Gen!T37 -> 0 | E32: =Gen!AK37 -> 0 | F32: =Gen!AS37 -> 0 | G32: ='Utility report '!AC32 -> 0 | H32: ='Utility report '!AE32 -> 0 | I32: ='Water-Meter'!E32 -> 0 | J32: ='Lpg (2)'!B36 -> 0 | K32: ='Lpg (2)'!C36 -> 0 | L32: ='Lpg (2)'!D36 -> 0 | M32: ='Lpg (2)'!G36 -> 0 | N32: =D32*1.4 -> 0 | O32: =E32*1.4 -> 0 | P32: ='[1]Lpg (2)'!#REF! -> #REF! | Q32: ='[1]Summery Report'!#REF! -> #REF! | R32: =N32/B32 -> #DIV/0! | S32: =Q32/B32 -> #REF!
A33: =Gen!B38 -> 43979 | B33: ='Summery Report'!E32 -> 0 | C33: =Gen!U38 -> 0 | D33: =Gen!T38 -> 0 | E33: =Gen!AK38 -> 0 | F33: =Gen!AS38 -> 0 | G33: ='Utility report '!AC33 -> 0 | H33: ='Utility report '!AE33 -> 0 | I33: ='Water-Meter'!E33 -> 0 | J33: ='Lpg (2)'!B37 -> 0 | K33: ='Lpg (2)'!C37 -> 0 | L33: ='Lpg (2)'!D37 -> 0 | M33: ='Lpg (2)'!G37 -> 0 | N33: =D33*1.4 -> 0 | O33: =E33*1.4 -> 0 | P33: ='[1]Lpg (2)'!#REF! -> #REF! | Q33: ='[1]Summery Report'!#REF! -> #REF! | R33: =N33/B33 -> #DIV/0! | S33: =Q33/B33 -> #REF! | T33: =3124/13 -> 240.30769
A34: =Gen!B39 -> 43980 | B34: ='Summery Report'!E33 -> 0 | C34: =Gen!U39 -> 0 | D34: =Gen!T39 -> 0 | E34: =Gen!AK39 -> 0 | F34: =Gen!AS39 -> 0 | G34: ='Utility report '!AC34 -> 0 | H34: ='Utility report '!AE34 -> 0 | I34: ='Water-Meter'!E34 -> 0 | J34: ='Lpg (2)'!B38 -> 0 | K34: ='Lpg (2)'!C38 -> 0 | L34: ='Lpg (2)'!D38 -> 0 | M34: ='Lpg (2)'!G38 -> 0 | N34: =D34*1.4 -> 0 | O34: =E34*1.4 -> 0 | P34: ='[1]Lpg (2)'!#REF! -> #REF! | Q34: ='[1]Summery Report'!#REF! -> #REF! | R34: =N34/B34 -> #DIV/0! | S34: =Q34/B34 -> #REF!
A35: =Gen!B40 -> 43981 | B35: ='Summery Report'!E34 -> 0 | C35: =Gen!U40 -> 0 | D35: =Gen!T40 -> 0 | E35: =Gen!AK40 -> 0 | F35: =Gen!AS40 -> 0 | G35: ='Utility report '!AC35 -> 0 | H35: ='Utility report '!AE35 -> 0 | I35: ='Water-Meter'!E35 -> 0 | J35: ='Lpg (2)'!B39 -> 0 | K35: ='Lpg (2)'!C39 -> 0 | L35: ='Lpg (2)'!D39 -> 0 | M35: ='Lpg (2)'!G39 -> 0 | N35: =D35*1.4 -> 0 | O35: =E35*1.4 -> 0 | P35: ='[1]Lpg (2)'!#REF! -> #REF! | Q35: ='[1]Summery Report'!#REF! -> #REF! | R35: =N35/B35 -> #DIV/0! | S35: =Q35/B35 -> #REF!
A36: =Gen!B41 -> 43982 | B36: ='Summery Report'!E35 -> 0 | C36: =Gen!U41 -> 0 | D36: =Gen!T41 -> 0 | E36: =Gen!AK41 -> 0 | F36: =Gen!AS41 -> 0 | G36: ='Utility report '!AC36 -> 0 | H36: ='Utility report '!AE36 -> 0 | I36: ='Water-Meter'!E36 -> 0 | J36: ='Lpg (2)'!B40 -> 0 | K36: ='Lpg (2)'!C40 -> 0 | L36: ='Lpg (2)'!D40 -> 0 | M36: ='Lpg (2)'!G40 -> 0 | N36: =D36*1.4 -> 0 | O36: =E36*1.4 -> 0 | P36: ='[1]Lpg (2)'!#REF! -> #REF! | Q36: ='[1]Summery Report'!#REF! -> #REF! | R36: =N36/B36 -> #DIV/0! | S36: =Q36/B36 -> #REF!
A37: =Gen!B42 -> 43983 | B37: ='Summery Report'!E36 -> 0 | C37: =Gen!U42 -> 0 | D37: =Gen!T42 -> 0 | E37: =Gen!AK42 -> 0 | F37: =Gen!AS42 -> 0 | G37: ='Utility report '!AC37 -> 0 | H37: ='Utility report '!AE37 -> 0 | I37: ='Water-Meter'!E37 -> 0 | J37: ='Lpg (2)'!B41 -> 0 | K37: ='Lpg (2)'!C41 -> 0 | L37: ='Lpg (2)'!D41 -> 0 | M37: ='Lpg (2)'!G41 -> 0 | Q37: ='[1]Summery Report'!#REF! -> #REF! | R37: =N37/B37 -> #DIV/0! | S37: =Q37/B37 -> #REF!
A39: Total | B39: =SUM(B7:B37) -> 0 | C39: =SUM(C7:C35) -> 21140 | D39: =SUM(D7:D35) -> 9794.8 | E39: =SUM(E7:E35) -> 247.18 | F39: =SUM(F7:F35) -> 10041.98 | G39: =SUM(G7:G35) -> -31574 | H39: =SUM(H7:H35) -> -200803 | I39: =SUM(I7:I35) -> 622 | J39: =SUM(J7:J35) -> 1275 | ... S39: =SUM(S7:S35) -> #REF!

Sheet Utility report 
A1: DAILY UTILITY REPORT MAY 2020
A2: Date | B2: Total occupancy | H2: Diesel balance LTS | I2: Diesel Deliveries | J2: Gen.Diesel consumption LTS | L2: Total Diesel consumption LTS | M2: Water Meter reading | N2: Water consumption m³ | O2: R.O WATER PRODUCTION LTRS + TIME | AA2: Total RO production | AB2: RO Meter reading | AD2: 0 | AE2: STP | AF2: GAS TANK A | AG2: GAS TANK B | AH2: GAS TANK C | AI2: Total Gas Tanks | AJ2: Kg /day | AK2: TOTAL GAS cons.
A3: Rate Tsh /$ | B3: 1640 | C3: Diesel cost / lits | D3: 2175 | F3: =SUM(D3/B3) -> 1.3262195 | H3: =Gen!D11 -> 43367.69 | K3: Transport consumption | M3: Balance | O3: PLANT NO 1 | S3: PLANT NO 2 | W3: PLANT NO 3 | AA3: /day | AB3: Balance | AC3: Production | AD3: 0 | AE3: Production | AF3: Capacity | AG3: Capacity | AH3: Capacity | AI3: Kg | AJ3: /day | AK3: /day
B4: Rooms OCC | C4: % | D4: Guest Rooms Occ | F4: Electricity Production Cost /Room Occ by guest | G4: All Cost /Room Occ by guest | O4: Flow M3 | P4: Reading Hours Meter | Q4: Hrs | R4: total production M3 | S4: Flow M3 | T4: Reading Hours Meter | U4: Hrs | V4: total production M3 | W4: Flow M3 | X4: READING HOURS METER | Y4: Hrs | Z4: total production M3 | AA4: M3 | AC4: M3 | AE4: M3 | AF4: 2000 | AG4: 1000 | AH4: 1000 | AI4: =SUM([2]Sheet1!$AA$36) -> 950 | AJ4: Kg | AK4: M3
P5: 19030 | T5: 24476 | X5: 16177 | AB5: 31534 | AD5: 200738 | AF5: 0.85 | AG5: 0.85 | AH5: 0.85
A6: =Gen!B11 -> 43952 | B6: ='Summery Report'!E5 -> 0 | C6: =Gen!C11 -> 0 | D6: ='Summery Report'!E5 -> 0 | E6: =SUM(F3) -> 1.3262195 | F6: =SUM(J6*E6)/D6 -> #DIV/0! | G6: =SUM(L6*E6)/D6 -> #DIV/0! | H6: =Gen!D11 -> 43367.69 | I6: =Gen!F11 -> 0 | J6: =Gen!T11 -> 678.07 | K6: =Gen!AK11 -> 0 | L6: =SUM(J6:K6) -> 678.07 | M6: ='Water-Meter'!K46 -> 573.91481 | N6: ='Water-Meter'!E6 -> 31 | P6: 19030 | Q6: =SUM(P6-P5) -> 0 | R6: =SUM(Q6*O6) -> 0 | S6: 2.4 | T6: 24494 | U6: =T6-T5 -> 18 | V6: - | X6: 16177 | Y6: =X6-X5 -> 0 | Z6: =Y6-Y5 -> 0 | AA6: =Z6-Z5 -> 0 | AB6: 31574 | AC6: =AB6-AB5 -> 40 | AD6: 200803 | AE6: =AD6-AD5 -> 65 | AF6: ='Lpg (2)'!B10*2000/85 -> 2000 | AG6: ='Lpg (2)'!C10*1000/85 -> 976.47059 | AH6: ='Lpg (2)'!D10*1000/85 -> 482.35294 | AI6: =SUM(AF6*2000)+(AG6*1000)+(AH6*1000) -> 5458823.5 | AJ6: =SUM(AI5-AI6) -> -5458823.5
A7: =Gen!B12 -> 43953 | B7: ='Summery Report'!E6 -> 0 | C7: =Gen!C12 -> 0 | D7: ='Summery Report'!E6 -> 0 | E7: =SUM(E6) -> 1.3262195 | F7: =SUM(J7*E7)/D7 -> #DIV/0! | G7: =SUM(L7*E7)/D7 -> #DIV/0! | H7: =Gen!D12 -> 42689.62 | I7: =Gen!F12 -> 0 | J7: =Gen!T12 -> 659.66 | K7: =Gen!AK12 -> 0 | L7: =SUM(J7:K7) -> 659.66 | M7: ='Water-Meter'!K47 -> 575.50604 | N7: ='Water-Meter'!E7 -> 31 | P7: 19030 | Q7: =SUM(P7-P6) -> 0 | R7: =SUM(Q7*O7) -> 0 | S7: 2.3 | T7: 24499 | U7: =T7-T6 -> 5 | V7: =SUM(U7*S7) -> 11.5 | X7: 16177 | Y7: =X7-X6 -> 0 | Z7: =SUM(Y7*W7) -> 0 | AA7: =SUM(Z7*X9) -> 0 | AB7: 31586 | AC7: =AB7-AB6 -> 12 | AD7: 200854 | AE7: =AD7-AD6 -> 51 | AF7: ='Lpg (2)'!B11*2000/85 -> 2000 | AG7: ='Lpg (2)'!C11*1000/85 -> 976.47059 | AH7: ='Lpg (2)'!D11*1000/85 -> 458.82353 | AI7: =SUM(AF6*2000)+(AG7*1000)+(AH7*1000) -> 5435294.1 | AJ7: =SUM(AI6-AI7) -> 23529.412
A8: =Gen!B13 -> 43954 | B8: ='Summery Report'!E7 -> 0 | C8: =Gen!C13 -> 0 | D8: ='Summery Report'!E7 -> 0 | E8: =SUM(E7) -> 1.3262195 | F8: =SUM(J8*E8)/D8 -> #DIV/0! | G8: =SUM(L8*E8)/D8 -> #DIV/0! | H8: =Gen!D13 -> 42029.96 | I8: =Gen!F13 -> 0 | J8: =Gen!T13 -> 659.29 | K8: =Gen!AK13 -> 0 | L8: =SUM(J8:K8) -> 659.29 | M8: ='Water-Meter'!K48 -> 580.47195 | N8: ='Water-Meter'!E8 -> 47 | P8: 19030 | Q8: =SUM(P8-P7) -> 0 | R8: =SUM(Q8*O8) -> 0 | T8: 24499 | U8: =T8-T7 -> 0 | V8: =SUM(U8*S8) -> 0 | W8: 8.2 | X8: 16186 | Y8: =X8-X7 -> 9 | Z8: =SUM(Y8*W8) -> 73.8 | AA8: =SUM(Z8*X10) -> 1195117.2 | AB8: 31663 | AC8: =AB8-AB7 -> 77 | AD8: 200907 | AE8: =AD8-AD7 -> 53 | AF8: ='Lpg (2)'!B12*2000/85 -> 2000 | AG8: ='Lpg (2)'!C12*1000/85 -> 976.47059 | AH8: ='Lpg (2)'!D12*1000/85 -> 435.29412 | AI8: =SUM(AF7*2000)+(AG8*1000)+(AH8*1000) -> 5411764.7 | AJ8: =SUM(AI7-AI8) -> 23529.412
A9: =Gen!B14 -> 43955 | B9: ='Summery Report'!E8 -> 0 | C9: =Gen!C14 -> 0 | D9: ='Summery Report'!E8 -> 0 | E9: =SUM(E8) -> 1.3262195 | F9: =SUM(J9*E9)/D9 -> #DIV/0! | G9: =SUM(L9*E9)/D9 -> #DIV/0! | H9: =Gen!D14 -> 41370.67 | I9: =Gen!F14 -> 0 | J9: =Gen!T14 -> 633.93 | K9: =Gen!AK14 -> 2.33 | L9: =SUM(J9:K9) -> 636.26 | M9: ='Water-Meter'!K49 -> 625.62926 | N9: ='Water-Meter'!E9 -> 31 | P9: 19030 | Q9: =SUM(P9-P8) -> 0 | R9: =SUM(Q9*O9) -> 0 | T9: 24499 | U9: =T9-T8 -> 0 | V9: =SUM(U9*S9) -> 0 | X9: 16186 | Y9: =X9-X8 -> 0 | Z9: =SUM(Y9*W9) -> 0 | AA9: =SUM(Z9*X11) -> 0 | AB9: 31663 | AC9: =AB9-AB8 -> 0 | AD9: 200963 | AE9: =AD9-AD8 -> 56 | AF9: ='Lpg (2)'!B13*2000/85 -> 2000 | AG9: ='Lpg (2)'!C13*1000/85 -> 976.47059 | AH9: ='Lpg (2)'!D13*1000/85 -> 423.52941 | AI9: =SUM(AF8*2000)+(AG9*1000)+(AH9*1000) -> 5400000 | AJ9: =SUM(AI8-AI9) -> 11764.706
A10: =Gen!B15 -> 43956 | B10: ='Summery Report'!E9 -> 0 | C10: =Gen!C15 -> 0 | D10: ='Summery Report'!E9 -> 0 | E10: =SUM(E9) -> 1.3262195 | F10: =SUM(J10*E10)/D10 -> #DIV/0! | G10: =SUM(L10*E10)/D10 -> #DIV/0! | H10: =Gen!D15 -> 40734.41 | I10: =Gen!F15 -> 0 | J10: =Gen!T15 -> 646.24 | K10: =Gen!AK15 -> 0 | L10: =SUM(J10:K10) -> 646.24 | M10: ='Water-Meter'!K50 -> 536.43442 | N10: ='Water-Meter'!E10 -> 30 | P10: 19030 | Q10: =SUM(P10-P9) -> 0 | R10: =SUM(Q10*O10) -> 0 | T10: 24499 | U10: =T10-T9 -> 0 | V10: =SUM(U10*S10) -> 0 | X10: 16194 | Y10: =X10-X9 -> 8 | Z10: =SUM(Y10*W10) -> 0 | AA10: =SUM(Z10*X12) -> 0 | AB10: 31731 | AC10: =AB10-AB9 -> 68 | AD10: 201017 | AE10: =AD10-AD9 -> 54 | AF10: ='Lpg (2)'!B14*2000/85 -> 2000 | AG10: ='Lpg (2)'!C14*1000/85 -> 976.47059 | AH10: ='Lpg (2)'!D14*1000/85 -> 411.76471 | AI10: =SUM(AF9*2000)+(AG10*1000)+(AH10*1000) -> 5388235.3 | AJ10: =SUM(AI9-AI10) -> 11764.706
A11: =Gen!B16 -> 43957 | B11: ='Summery Report'!E10 -> 0 | C11: =Gen!C16 -> 0 | D11: ='Summery Report'!E10 -> 0 | E11: =SUM(E10) -> 1.3262195 | F11: =SUM(J11*E11)/D11 -> #DIV/0! | G11: =SUM(L11*E11)/D11 -> #DIV/0! | H11: =Gen!D16 -> 40088.17 | I11: =Gen!F16 -> 0 | J11: =Gen!T16 -> 627.88 | K11: =Gen!AK16 -> 31.11 | L11: =SUM(J11:K11) -> 658.99 | M11: ='Water-Meter'!K51 -> 558.95227 | N11: ='Water-Meter'!E11 -> 33 | P11: 19030 | Q11: =SUM(P11-P10) -> 0 | R11: =SUM(Q11*O11) -> 0 | T11: 24499 | U11: =T11-T10 -> 0 | V11: =SUM(U11*S11) -> 0 | X11: 16198 | Y11: =X11-X10 -> 4 | Z11: =SUM(Y11*W11) -> 0 | AA11: =SUM(Z11*X13) -> 0 | AB11: 31767 | AC11: =AB11-AB10 -> 36 | AD11: 201044 | AE11: =AD11-AD10 -> 27 | AF11: ='Lpg (2)'!B15*2000/85 -> 2000 | AG11: ='Lpg (2)'!C15*1000/85 -> 976.47059 | AH11: ='Lpg (2)'!D15*1000/85 -> 400 | AI11: =SUM(AF10*2000)+(AG11*1000)+(AH11*1000) -> 5376470.6 | AJ11: =SUM(AI10-AI11) -> 11764.706
A12: =Gen!B17 -> 43958 | B12: ='Summery Report'!E11 -> 0 | C12: =Gen!C17 -> 0 | D12: ='Summery Report'!E11 -> 0 | E12: =SUM(E11) -> 1.3262195 | F12: =SUM(J12*E12)/D12 -> #DIV/0! | G12: =SUM(L12*E12)/D12 -> #DIV/0! | H12: =Gen!D17 -> 39429.18 | I12: =Gen!F17 -> 0 | J12: =Gen!T17 -> 637.52 | K12: =Gen!AK17 -> 22.97 | L12: =SUM(J12:K12) -> 660.49 | M12: ='Water-Meter'!K52 -> 534.9191 | N12: ='Water-Meter'!E12 -> 41 | P12: 19030 | Q12: =SUM(P12-P11) -> 0 | R12: =SUM(Q12*O12) -> 0 | T12: 24499 | U12: =T12-T11 -> 0 | V12: =SUM(U12*S12) -> 0 | X12: 16198 | Y12: =X12-X11 -> 0 | Z12: =SUM(Y12*W12) -> 0 | AA12: =SUM(Z12*X14) -> 0 | AB12: 31767 | AC12: =AB12-AB11 -> 0 | AD12: 201082 | AE12: =AD12-AD11 -> 38 | AF12: ='Lpg (2)'!B16*2000/85 -> 2000 | AG12: ='Lpg (2)'!C16*1000/85 -> 976.47059 | AH12: ='Lpg (2)'!D16*1000/85 -> 376.47059 | AI12: =SUM(AF11*2000)+(AG12*1000)+(AH12*1000) -> 5352941.2 | AJ12: =SUM(AI11-AI12) -> 23529.412
A13: =Gen!B18 -> 43959 | B13: ='Summery Report'!E12 -> 0 | C13: =Gen!C18 -> 0 | D13: ='Summery Report'!E12 -> 0 | E13: =SUM(E12) -> 1.3262195 | F13: =SUM(J13*E13)/D13 -> #DIV/0! | G13: =SUM(L13*E13)/D13 -> #DIV/0! | H13: =Gen!D18 -> 38768.69 | I13: =Gen!F18 -> 0 | J13: =Gen!T18 -> 692.83 | K13: =Gen!AK18 -> 80.1 | L13: =SUM(J13:K13) -> 772.93 | M13: ='Water-Meter'!K53 -> 530.86816 | N13: ='Water-Meter'!E13 -> 37 | P13: 19030 | Q13: =SUM(P13-P12) -> 0 | R13: =SUM(Q13*O13) -> 0 | T13: 24499 | U13: =T13-T12 -> 0 | V13: =SUM(U13*S13) -> 0 | X13: 16206 | Y13: =X13-X12 -> 8 | Z13: =SUM(Y13*W13) -> 0 | AA13: =SUM(Z13*X15) -> 0 | AB13: 31837 | AC13: =AB13-AB12 -> 70 | AD13: 201123 | AE13: =AD13-AD12 -> 41 | AF13: ='Lpg (2)'!B17*2000/85 -> 2000 | AG13: ='Lpg (2)'!C17*1000/85 -> 976.47059 | AH13: ='Lpg (2)'!D17*1000/85 -> 352.94118 | AI13: =SUM(AF12*2000)+(AG13*1000)+(AH13*1000) -> 5329411.8 | AJ13: =SUM(AI12-AI13) -> 23529.412
A14: =Gen!B19 -> 43960 | B14: ='Summery Report'!E13 -> 0 | C14: =Gen!C19 -> 0 | D14: ='Summery Report'!E13 -> 0 | E14: =SUM(E13) -> 1.3262195 | F14: =SUM(J14*E14)/D14 -> #DIV/0! | G14: =SUM(L14*E14)/D14 -> #DIV/0! | H14: =Gen!D19 -> 37995.76 | I14: =Gen!F19 -> 0 | J14: =Gen!T19 -> 662.1 | K14: =Gen!AK19 -> 0 | L14: =SUM(J14:K14) -> 662.1 | M14: ='Water-Meter'!K54 -> 520.96975 | N14: ='Water-Meter'!E14 -> 51 | P14: 19030 | Q14: =SUM(P14-P13) -> 0 | R14: =SUM(Q14*O14) -> 0 | T14: 24499 | U14: =T14-T13 -> 0 | V14: =SUM(U14*S14) -> 0 | X14: 16219 | Y14: =X14-X13 -> 13 | Z14: =SUM(Y14*W14) -> 0 | AA14: =SUM(Z14*X16) -> 0 | AB14: 31947 | AC14: =AB14-AB13 -> 110 | AD14: 201163 | AE14: =AD14-AD13 -> 40 | AF14: ='Lpg (2)'!B18*2000/85 -> 2000 | AG14: ='Lpg (2)'!C18*1000/85 -> 976.47059 | AH14: ='Lpg (2)'!D18*1000/85 -> 329.41176 | AI14: =SUM(AF13*2000)+(AG14*1000)+(AH14*1000) -> 5305882.4 | AJ14: =SUM(AI13-AI14) -> 23529.412
A15: =Gen!B20 -> 43961 | B15: ='Summery Report'!E14 -> 0 | C15: =Gen!C20 -> 0 | D15: ='Summery Report'!E14 -> 0 | E15: =SUM(E14) -> 1.3262195 | F15: =SUM(J15*E15)/D15 -> #DIV/0! | G15: =SUM(L15*E15)/D15 -> #DIV/0! | H15: =Gen!D20 -> 37333.66 | I15: =Gen!F20 -> 0 | J15: =Gen!T20 -> 652.33 | K15: =Gen!AK20 -> 0 | L15: =SUM(J15:K15) -> 652.33 | M15: ='Water-Meter'!K55 -> 451.94849 | N15: ='Water-Meter'!E15 -> 51 | P15: 19030 | Q15: =SUM(P15-P14) -> 0 | R15: =SUM(Q15*O15) -> 0 | T15: 24499 | U15: =T15-T14 -> 0 | V15: =SUM(U15*S15) -> 0 | X15: 16219 | Y15: =X15-X14 -> 0 | Z15: =SUM(Y15*W15) -> 0 | AA15: =SUM(Z15*X17) -> 0 | AB15: 31947 | AC15: =AB15-AB14 -> 0 | AD15: 201198 | AE15: =AD15-AD14 -> 35 | AF15: ='Lpg (2)'!B19*2000/85 -> 2000 | AG15: ='Lpg (2)'!C19*1000/85 -> 976.47059 | AH15: ='Lpg (2)'!D19*1000/85 -> 294.11765 | AI15: =SUM(AF15*2000)+(AG15*1000)+(AH15*1000) -> 5270588.2 | AJ15: =SUM(AI14-AI15) -> 35294.118
A16: =Gen!B21 -> 43962 | B16: ='Summery Report'!E15 -> 0 | C16: =Gen!C21 -> 0 | D16: ='Summery Report'!E15 -> 0 | E16: =SUM(E15) -> 1.3262195 | F16: =SUM(J16*E16)/D16 -> #DIV/0! | G16: =SUM(L16*E16)/D16 -> #DIV/0! | H16: =Gen!D21 -> 36681.33 | I16: =Gen!F21 -> 0 | J16: =Gen!T21 -> 675.39 | K16: =Gen!AK21 -> 0 | L16: =SUM(J16:K16) -> 675.39 | M16: ='Water-Meter'!K56 -> 434.37855 | N16: ='Water-Meter'!E16 -> 56 | P16: 19030 | Q16: =SUM(P16-P15) -> 0 | R16: =SUM(Q16*O16) -> 0 | T16: 24499 | U16: =T16-T15 -> 0 | V16: =SUM(U16*S16) -> 0 | X16: 16219 | Y16: =X16-X15 -> 0 | Z16: =SUM(Y16*W16) -> 0 | AA16: =SUM(Z16*X18) -> 0 | AB16: 31947 | AC16: =AB16-AB15 -> 0 | AD16: 201236 | AE16: =AD16-AD15 -> 38 | AF16: ='Lpg (2)'!B20*2000/85 -> 2000 | AG16: ='Lpg (2)'!C20*1000/85 -> 976.47059 | AH16: ='Lpg (2)'!D20*1000/85 -> 247.05882 | AI16: =SUM(AF16*2000)+(AG16*1000)+(AH16*1000) -> 5223529.4 | AJ16: =SUM(AI15-AI16) -> 47058.824
A17: =Gen!B22 -> 43963 | B17: ='Summery Report'!E16 -> 0 | C17: =Gen!C22 -> 0 | D17: ='Summery Report'!E16 -> 0 | E17: =SUM(E16) -> 1.3262195 | F17: =SUM(J17*E17)/D17 -> #DIV/0! | G17: =SUM(L17*E17)/D17 -> #DIV/0! | H17: =Gen!D22 -> 46005.94 | I17: =Gen!F22 -> 10000 | J17: =Gen!T22 -> 719.01 | K17: =Gen!AK22 -> 106.89 | L17: =SUM(J17:K17) -> 825.9 | M17: ='Water-Meter'!K57 -> 473.35907 | N17: ='Water-Meter'!E17 -> 58 | P17: 19030 | Q17: =SUM(P18-P16) -> 0 | R17: =SUM(Q17*O17) -> 0 | T17: 24506 | U17: =T17-T16 -> 7 | V17: =SUM(U17*S17) -> 0 | X17: 16225 | Y17: =X17-X16 -> 6 | Z17: =SUM(Y17*W17) -> 0 | AA17: =SUM(Z17*X19) -> 0 | AB17: 32018 | AC17: =AB17-AB16 -> 71 | AD17: 201279 | AE17: =AD17-AD16 -> 43 | AF17: ='Lpg (2)'!B21*2000/85 -> 2000 | AG17: ='Lpg (2)'!C22*1000/85 -> 976.47059 | AH17: ='Lpg (2)'!D21*1000/85 -> 235.29412 | AI17: =SUM(AF17*2000)+(AG17*1000)+(AH17*1000) -> 5211764.7 | AJ17: =SUM(AI16-AI17) -> 11764.706
A18: =Gen!B23 -> 43964 | B18: ='Summery Report'!E17 -> 0 | C18: =Gen!C23 -> 0 | D18: ='Summery Report'!E17 -> 0 | E18: =SUM(E17) -> 1.3262195 | F18: =SUM(J18*E18)/D18 -> #DIV/0! | G18: =SUM(L18*E18)/D18 -> #DIV/0! | H18: =Gen!D23 -> 45180.04 | I18: =Gen!F23 -> 0 | J18: =Gen!T23 -> 656.19 | K18: =Gen!AK23 -> 0 | L18: =SUM(J18:K18) -> 656.19 | M18: ='Water-Meter'!K58 -> 521.36044 | N18: ='Water-Meter'!E18 -> 41 | P18: 19030 | R18: =SUM(Q18*O18) -> 0 | T18: 24506 | U18: =T18-T17 -> 0 | V18: =SUM(U18*S18) -> 0 | X18: 16225 | Y18: =X18-X17 -> 0 | Z18: =SUM(Y18*W18) -> 0 | AA18: =SUM(Z18*X20) -> 0 | AB18: 32018 | AC18: =AB18-AB17 -> 0 | AD18: 201311 | AE18: =AD18-AD17 -> 32 | AF18: ='Lpg (2)'!B22*2000/85 -> 2000 | AG18: ='Lpg (2)'!#REF!*1000/85 -> #REF! | AH18: ='Lpg (2)'!D22*1000/85 -> 211.76471 | AI18: =SUM(AF18*2000)+(AG18*1000)+(AH18*1000) -> #REF! | AJ18: =SUM(AI17-AI18) -> #REF!
A19: =Gen!B24 -> 43965 | B19: ='Summery Report'!E18 -> 0 | C19: =Gen!C24 -> 0 | D19: ='Summery Report'!E18 -> 0 | E19: =SUM(E18) -> 1.3262195 | F19: =SUM(J19*E19)/D19 -> #DIV/0! | G19: =SUM(L19*E19)/D19 -> #DIV/0! | H19: =Gen!D24 -> 44523.85 | I19: =Gen!F24 -> 0 | J19: =Gen!T24 -> 633.08 | K19: =Gen!AK24 -> 0 | L19: =SUM(J19:K19) -> 633.08 | M19: ='Water-Meter'!K59 -> 486.76278 | N19: ='Water-Meter'!E19 -> 33 | P19: 19030 | R19: =SUM(Q19*O19) -> 0 | T19: 24506 | U19: =T19-T18 -> 0 | V19: =SUM(U19*S19) -> 0 | X19: 16225 | Y19: =X19-X18 -> 0 | Z19: =SUM(Y19*W19) -> 0 | AA19: =SUM(Z19*X21) -> 0 | AB19: 32018 | AC19: =AB19-AB18 -> 0 | AD19: 201347 | AE19: =AD19-AD18 -> 36 | AF19: ='Lpg (2)'!B23*2000/85 -> 2000 | AG19: ='Lpg (2)'!C23*1000/85 -> 976.47059 | AH19: ='Lpg (2)'!D23*1000/85 -> 188.23529 | AI19: =SUM(AF19*2000)+(AG19*1000)+(AH19*1000) -> 5164705.9 | AJ19: =SUM(AI18-AI19) -> #REF!
A20: =Gen!B25 -> 43966 | B20: ='Summery Report'!E19 -> 0 | C20: =Gen!C25 -> 0 | D20: ='Summery Report'!E19 -> 0 | E20: =SUM(E19) -> 1.3262195 | F20: =SUM(J20*E20)/D20 -> #DIV/0! | G20: =SUM(L20*E20)/D20 -> #DIV/0! | H20: =Gen!D25 -> 43890.77 | I20: =Gen!F25 -> 0 | J20: =Gen!T25 -> 603.86 | K20: =Gen!AK25 -> 3.78 | L20: =SUM(J20:K20) -> 607.64 | M20: ='Water-Meter'!K60 -> 523.93295 | N20: ='Water-Meter'!E20 -> 38 | P20: 19030 | Q20: =SUM(P20-P19) -> 0 | R20: =SUM(Q20*O20) -> 0 | T20: 24506 | U20: =T20-T19 -> 0 | V20: =SUM(U20*S20) -> 0 | X20: 16225 | Y20: =X20-X19 -> 0 | Z20: =SUM(Y20*W20) -> 0 | AA20: =SUM(Z20*X22) -> 0 | AB20: 32018 | AD20: 201382 | AE20: =AD20-AD19 -> 35 | AF20: ='Lpg (2)'!B24*2000/85 -> 2000 | AG20: ='Lpg (2)'!C24*1000/85 -> 976.47059 | AH20: ='Lpg (2)'!D24*1000/85 -> 176.47059 | AI20: =SUM(AF20*2000)+(AG20*1000)+(AH20*1000) -> 5152941.2 | AJ20: =SUM(AI19-AI20) -> 11764.706
