Workbook
Name _IV99999: [1]Water!$IB$30257

Sheet Total
A1: Site Name | B1: Day | C1: Month | D1: Year | E1: Total Electricity Kwh | F1: Electricity Tariff ($/Kwh) | G1: Natual Gas (m3) | H1: Natural Gas $/m3 | I1: Water Utility Supply (m3) m3 | J1: Water Utility Supply (m3) $/m3 | K1: Room Nights
A2: Cairo at The First Residence | B2: 1 | C2: 3 | D2: 2020 | E2: =Elect!BL6 -> 9275.7 | F2: ='Utility Consnsumption'!K13/'Utility Consnsumption'!J13 -> 1.637964 | G2: =Gas!K7 -> 191.86 | H2: 3.8 | I2: =Water!H7 -> 52.2 | J2: 10 | K2: =Elect!BM6 -> 0
A3: Cairo at The First Residence | B3: =B2+1 -> 2 | C3: 3 | D3: 2020 | E3: =Elect!BL7 -> 16199.26 | F3: =F2 -> 1.637964 | G3: =Gas!K8 -> 170.66 | H3: 3.8 | I3: =Water!H8 -> 139.2 | J3: 10 | K3: =Elect!BM7 -> 0
A4: Cairo at The First Residence | B4: =B3+1 -> 3 | C4: 3 | D4: 2020 | E4: =Elect!BL8 -> 6850.27 | F4: =F3 -> 1.637964 | G4: =Gas!K9 -> 170.66 | H4: 3.8 | I4: =Water!H9 -> 133.4 | J4: 10 | K4: =Elect!BM8 -> 0
A5: Cairo at The First Residence | B5: =B4+1 -> 4 | C5: 3 | D5: 2020 | E5: =Elect!BL9 -> 12233.13 | F5: =F4 -> 1.637964 | G5: =Gas!K10 -> 170.66 | H5: 3.8 | I5: =Water!H10 -> 243.6 | J5: 10 | K5: =Elect!BM9 -> 0
A6: Cairo at The First Residence | B6: =B5+1 -> 5 | C6: 3 | D6: 2020 | E6: =Elect!BL10 -> 15742.95 | F6: =F5 -> 1.637964 | G6: =Gas!K11 -> 280.21212 | H6: 3.8 | I6: =Water!H11 -> 145 | J6: 10 | K6: =Elect!BM10 -> 0
A7: Cairo at The First Residence | B7: =B6+1 -> 6 | C7: 3 | D7: 2020 | E7: =Elect!BL11 -> 6712.55 | F7: =F6 -> 1.637964 | G7: =Gas!K12 -> 319.86606 | H7: 3.8 | I7: =Water!H12 -> 92.8 | J7: 10 | K7: =Elect!BM11 -> 0
A8: Cairo at The First Residence | B8: =B7+1 -> 7 | C8: 3 | D8: 2020 | E8: =Elect!BL12 -> 15222.27 | F8: =F7 -> 1.637964 | G8: =Gas!K13 -> 319.86606 | H8: 3.8 | I8: =Water!H13 -> 98.6 | J8: 10 | K8: =Elect!BM12 -> 0
A9: Cairo at The First Residence | B9: =B8+1 -> 8 | C9: 3 | D9: 2020 | E9: =Elect!BL13 -> 13930.72 | F9: =F8 -> 1.637964 | G9: =Gas!K14 -> 319.86606 | H9: 3.8 | I9: =Water!H14 -> 116 | J9: 10 | K9: =Elect!BM13 -> 0
A10: Cairo at The First Residence | B10: =B9+1 -> 9 | C10: 3 | D10: 2020 | E10: =Elect!BL14 -> 8231.14 | F10: =F9 -> 1.637964 | G10: =Gas!K15 -> 319.86606 | H10: 3.8 | I10: =Water!H15 -> 133.4 | J10: 10 | K10: =Elect!BM14 -> 0
A11: Cairo at The First Residence | B11: =B10+1 -> 10 | C11: 3 | D11: 2020 | E11: =Elect!BL15 -> 13092.23 | F11: =F10 -> 1.637964 | G11: =Gas!K16 -> 319.86606 | H11: 3.8 | I11: =Water!H16 -> 54.52 | J11: 10 | K11: =Elect!BM15 -> 0
A12: Cairo at The First Residence | B12: =B11+1 -> 11 | C12: 3 | D12: 2020 | E12: =Elect!BL16 -> 9014.3 | F12: =F11 -> 1.637964 | G12: =Gas!K17 -> 319.86606 | H12: 3.8 | I12: =Water!H17 -> 80.62 | J12: 10 | K12: =Elect!BM16 -> 0
A13: Cairo at The First Residence | B13: =B12+1 -> 12 | C13: 3 | D13: 2020 | E13: =Elect!BL17 -> 10233.37 | F13: =F12 -> 1.637964 | G13: =Gas!K18 -> 319.86606 | H13: 3.8 | I13: =Water!H18 -> 77.14 | J13: 10 | K13: =Elect!BM17 -> 0
A14: Cairo at The First Residence | B14: =B13+1 -> 13 | C14: 3 | D14: 2020 | E14: =Elect!BL18 -> 10826.08 | F14: =F13 -> 1.637964 | G14: =Gas!K19 -> 319.86606 | H14: 3.8 | I14: =Water!H19 -> 117.16 | J14: 10 | K14: =Elect!BM18 -> 0
... A32: Cairo at The First Residence | B32: =B31+1 -> 31 | C32: 3 | D32: 2020 | E32: =Elect!BL36 -> 0 | F32: =F31 -> 1.637964 | G32: =Gas!K37 -> 0 | H32: 3.8 | I32: =Water!H37 -> 0 | J32: 10 | K32: =Elect!BM36 -> 0

Sheet Submetering
A1: Site Name | B1: Day | C1: Month | D1: Year | E1: Electricity | F1: Main Feeder -KWh | G1: T2+T8 -KWh | H1: La Gourmandize -KWh | I1: Casino 3rd floor EM -KWh | J1: Casino 3rd floor Normal -KWh | K1: Chiller 1 -KWh | L1: Chiller 2 -KWh | M1: Chiller 3 -KWh | N1: Chiller 4 -KWh | O1: Cooling towers -KWh | P1: Chiller Pumps -KWh | Q1: LG Bakery -KWh | R1: Mall Ceiling light -KWh | S1: New chiller for Second floor -KWh | T1: LG Bakery light ( Old lockers ) -KWh | U1: MCCR1 -KWh | V1: Children Swimming pool -KWh | W1: DPH1 -KWh | X1: Main G2 -KWh | Y1: Casino Emergency -KWh | Z1: L / A -KWh | AA1: L / B -KWh | AB1: L / C -KWh | AC1: Water | AD1: Main water meter 1 -m3 | AE1: Main water meter 2 -m3 | AF1: Main water meter 3 -m3 | AG1: Gas | AH1: Main Gas Flow Meter -m3 | AI1: Laundry Gas Flow Meter -m3 | AJ1: Gourmandize Gas Flow Meter -m3 | AK1: Room Nights
A2: Cairo at The First Residence | B2: 1 | C2: 3 | D2: 2020 | F2: =Elect!J6 -> 1534 | G2: =Elect!K6 -> 1084 | H2: =Elect!Q6 -> 0 | I2: =Elect!W6 -> 120 | J2: =Elect!Y6 -> 98 | K2: =Elect!AA6 -> 0 | L2: =Elect!AC6 -> 314.29 | M2: =Elect!AE6 -> 465.34 | N2: =Elect!AG6 -> 326.48 | O2: =Elect!AI6 -> 288.85 | P2: =Elect!AK6 -> 1751.65 | Q2: =Elect!AN6 -> 23 | R2: =Elect!AP6 -> 3 | S2: =Elect!AR6 -> 3.19 | T2: =Elect!AT6 -> 27 | U2: =Elect!AV6 -> 273 | V2: =Elect!AX6 -> 39 | W2: =Elect!AZ6 -> 1473 | X2: =Elect!BB6 -> 2753.9 | Y2: =Elect!BE6 -> 0 | Z2: =Elect!BG6 -> 756 | AA2: =Elect!BI6 -> 67 | AB2: =Elect!BK6 -> 154 | AD2: =Water!C7 -> 40.6 | AE2: =Water!E7 -> 11.6 | AF2: =Water!G7 -> 0 | AH2: =Gas!C7 -> 191.86 | AI2: =Gas!E7 -> 0 | AJ2: =Gas!G7 -> 3 | AK2: =Elect!BM6 -> 0
A3: Cairo at The First Residence | B3: =B2+1 -> 2 | C3: 3 | D3: 2020 | F3: =Elect!J7 -> 1896 | G3: =Elect!K7 -> 1790 | H3: =Elect!Q7 -> 90 | I3: =Elect!W7 -> 150 | J3: =Elect!Y7 -> 96 | K3: =Elect!AA7 -> 0 | L3: =Elect!AC7 -> 531.59 | M3: =Elect!AE7 -> 1767.55 | N3: =Elect!AG7 -> 105.47 | O3: =Elect!AI7 -> 647.13 | P3: =Elect!AK7 -> 3112.16 | Q3: =Elect!AN7 -> 27 | R3: =Elect!AP7 -> 2 | S3: =Elect!AR7 -> 6.16 | T3: =Elect!AT7 -> 45 | U3: =Elect!AV7 -> 453 | V3: =Elect!AX7 -> 38 | W3: =Elect!AZ7 -> 2358 | X3: =Elect!BB7 -> 5120.2 | Y3: =Elect!BE7 -> 0 | Z3: =Elect!BG7 -> 1328 | AA3: =Elect!BI7 -> 114 | AB3: =Elect!BK7 -> 289 | AD3: =Water!C8 -> 133.4 | AE3: =Water!E8 -> 5.8 | AF3: =Water!G8 -> 0 | AH3: =Gas!C8 -> 170.66 | AI3: =Gas!E8 -> 0 | AJ3: =Gas!G8 -> 2 | AK3: =Elect!BM7 -> 0
A4: Cairo at The First Residence | B4: =B3+1 -> 3 | C4: 3 | D4: 2020 | F4: =Elect!J8 -> 1702 | G4: =Elect!K8 -> 776 | H4: =Elect!Q8 -> 30 | I4: =Elect!W8 -> 87 | J4: =Elect!Y8 -> 297 | K4: =Elect!AA8 -> 0 | L4: =Elect!AC8 -> 320.12 | M4: =Elect!AE8 -> 178.08 | N4: =Elect!AG8 -> 0 | O4: =Elect!AI8 -> 229.49 | P4: =Elect!AK8 -> 1278.89 | Q4: =Elect!AN8 -> 4 | R4: =Elect!AP8 -> 2 | S4: =Elect!AR8 -> 2.09 | T4: =Elect!AT8 -> 24 | U4: =Elect!AV8 -> 221 | V4: =Elect!AX8 -> 32 | W4: =Elect!AZ8 -> 966 | X4: =Elect!BB8 -> 1860.6 | Y4: =Elect!BE8 -> 0 | Z4: =Elect!BG8 -> 594 | AA4: =Elect!BI8 -> 46 | AB4: =Elect!BK8 -> 108 | AD4: =Water!C9 -> 92.8 | AE4: =Water!E9 -> 40.6 | AF4: =Water!G9 -> 0 | AH4: =Gas!C9 -> 170.66 | AI4: =Gas!E9 -> 0 | AJ4: =Gas!G9 -> 0 | AK4: =Elect!BM8 -> 0
A5: Cairo at The First Residence | B5: =B4+1 -> 4 | C5: 3 | D5: 2020 | F5: =Elect!J9 -> 1993 | G5: =Elect!K9 -> 1226 | H5: =Elect!Q9 -> 90 | I5: =Elect!W9 -> 135 | J5: =Elect!Y9 -> 228 | K5: =Elect!AA9 -> 0 | L5: =Elect!AC9 -> 1511.03 | M5: =Elect!AE9 -> 0 | N5: =Elect!AG9 -> 0 | O5: =Elect!AI9 -> 396.97 | P5: =Elect!AK9 -> 2288.54 | Q5: =Elect!AN9 -> 12 | R5: =Elect!AP9 -> 2 | S5: =Elect!AR9 -> 4.29 | T5: =Elect!AT9 -> 32 | U5: =Elect!AV9 -> 361 | V5: =Elect!AX9 -> 37 | W5: =Elect!AZ9 -> 1838 | X5: =Elect!BB9 -> 3667.3 | Y5: =Elect!BE9 -> 0 | Z5: =Elect!BG9 -> 917 | AA5: =Elect!BI9 -> 85 | AB5: =Elect!BK9 -> 202 | AD5: =Water!C10 -> 232 | AE5: =Water!E10 -> 11.6 | AF5: =Water!G10 -> 0 | AH5: =Gas!C10 -> 170.66 | AI5: =Gas!E10 -> 0 | AJ5: =Gas!G10 -> 2 | AK5: =Elect!BM9 -> 0
A6: Cairo at The First Residence | B6: =B5+1 -> 5 | C6: 3 | D6: 2020 | F6: =Elect!J10 -> 1723 | G6: =Elect!K10 -> 1590 | H6: =Elect!Q10 -> 60 | I6: =Elect!W10 -> 114 | J6: =Elect!Y10 -> 191 | K6: =Elect!AA10 -> 0 | L6: =Elect!AC10 -> 2708.3 | M6: =Elect!AE10 -> 0 | N6: =Elect!AG10 -> 0 | O6: =Elect!AI10 -> 508.8 | P6: =Elect!AK10 -> 2934.61 | Q6: =Elect!AN10 -> 29 | R6: =Elect!AP10 -> 2 | S6: =Elect!AR10 -> 5.94 | T6: =Elect!AT10 -> 41 | U6: =Elect!AV10 -> 485 | V6: =Elect!AX10 -> 39 | W6: =Elect!AZ10 -> 2436 | X6: =Elect!BB10 -> 4770.3 | Y6: =Elect!BE10 -> 0 | Z6: =Elect!BG10 -> 1282 | AA6: =Elect!BI10 -> 107 | AB6: =Elect!BK10 -> 262 | AD6: =Water!C11 -> 81.2 | AE6: =Water!E11 -> 63.8 | AF6: =Water!G11 -> 0 | AH6: =Gas!C11 -> 170.66 | AI6: =Gas!E11 -> 109.55212 | AJ6: =Gas!G11 -> 2 | AK6: =Elect!BM10 -> 0
A7: Cairo at The First Residence | B7: =B6+1 -> 6 | C7: 3 | D7: 2020 | F7: =Elect!J11 -> 1827 | G7: =Elect!K11 -> 1427 | H7: =Elect!Q11 -> 60 | I7: =Elect!W11 -> 113 | J7: =Elect!Y11 -> 189 | K7: =Elect!AA11 -> 0 | L7: =Elect!AC11 -> 992.16 | M7: =Elect!AE11 -> 0 | N7: =Elect!AG11 -> 0 | O7: =Elect!AI11 -> 179.14 | P7: =Elect!AK11 -> 909.48 | Q7: =Elect!AN11 -> 47 | R7: =Elect!AP11 -> 2 | S7: =Elect!AR11 -> 1.87 | T7: =Elect!AT11 -> 18 | U7: =Elect!AV11 -> 197 | V7: =Elect!AX11 -> 33 | W7: =Elect!AZ11 -> 867 | X7: =Elect!BB11 -> 1578.9 | Y7: =Elect!BE11 -> 0 | Z7: =Elect!BG11 -> 471 | AA7: =Elect!BI11 -> 35 | AB7: =Elect!BK11 -> 84 | AD7: =Water!C12 -> 46.4 | AE7: =Water!E12 -> 46.4 | AF7: =Water!G12 -> 0 | AH7: =Gas!C12 -> 170.66 | AI7: =Gas!E12 -> 149.20606 | AJ7: =Gas!G12 -> 1 | AK7: =Elect!BM11 -> 0
A8: Cairo at The First Residence | B8: =B7+1 -> 7 | C8: 3 | D8: 2020 | F8: =Elect!J12 -> 2458 | G8: =Elect!K12 -> 1967 | H8: =Elect!Q12 -> 120 | I8: =Elect!W12 -> 160 | J8: =Elect!Y12 -> 263 | K8: =Elect!AA12 -> 0 | L8: =Elect!AC12 -> 507.21 | M8: =Elect!AE12 -> 1939.27 | N8: =Elect!AG12 -> 0 | O8: =Elect!AI12 -> 437.78 | P8: =Elect!AK12 -> 2415.74 | Q8: =Elect!AN12 -> 15 | R8: =Elect!AP12 -> 2 | S8: =Elect!AR12 -> 5.17 | T8: =Elect!AT12 -> 36 | U8: =Elect!AV12 -> 371 | V8: =Elect!AX12 -> 44 | W8: =Elect!AZ12 -> 2571 | X8: =Elect!BB12 -> 4300.1 | Y8: =Elect!BE12 -> 0 | Z8: =Elect!BG12 -> 1339 | AA8: =Elect!BI12 -> 95 | AB8: =Elect!BK12 -> 232 | AD8: =Water!C13 -> 69.6 | AE8: =Water!E13 -> 29 | AF8: =Water!G13 -> 0 | AH8: =Gas!C13 -> 170.66 | AI8: =Gas!E13 -> 149.20606 | AJ8: =Gas!G13 -> 1 | AK8: =Elect!BM12 -> 0
A9: Cairo at The First Residence | B9: =B8+1 -> 8 | C9: 3 | D9: 2020 | F9: =Elect!J13 -> 2104 | G9: =Elect!K13 -> 1316 | H9: =Elect!Q13 -> 90 | I9: =Elect!W13 -> 148 | J9: =Elect!Y13 -> 237 | K9: =Elect!AA13 -> 0 | L9: =Elect!AC13 -> 0 | M9: =Elect!AE13 -> 2327.23 | N9: =Elect!AG13 -> 0 | O9: =Elect!AI13 -> 444.14 | P9: =Elect!AK13 -> 2433.23 | Q9: =Elect!AN13 -> 12 | R9: =Elect!AP13 -> 3 | S9: =Elect!AR13 -> 4.62 | T9: =Elect!AT13 -> 31 | U9: =Elect!AV13 -> 332 | V9: =Elect!AX13 -> 38 | W9: =Elect!AZ13 -> 2215 | X9: =Elect!BB13 -> 3896.5 | Y9: =Elect!BE13 -> 0 | Z9: =Elect!BG13 -> 1175 | AA9: =Elect!BI13 -> 89 | AB9: =Elect!BK13 -> 217 | AD9: =Water!C14 -> 75.4 | AE9: =Water!E14 -> 40.6 | AF9: =Water!G14 -> 0 | AH9: =Gas!C14 -> 170.66 | AI9: =Gas!E14 -> 149.20606 | AJ9: =Gas!G14 -> 1 | AK9: =Elect!BM13 -> 0
A10: Cairo at The First Residence | B10: =B9+1 -> 9 | C10: 3 | D10: 2020 | F10: =Elect!J14 -> 962 | G10: =Elect!K14 -> 981 | H10: =Elect!Q14 -> 30 | I10: =Elect!W14 -> 73 | J10: =Elect!Y14 -> 117 | K10: =Elect!AA14 -> 0 | L10: =Elect!AC14 -> 0 | M10: =Elect!AE14 -> 1698.65 | N10: =Elect!AG14 -> 0 | O10: =Elect!AI14 -> 333.9 | P10: =Elect!AK14 -> 1850.76 | Q10: =Elect!AN14 -> 6 | R10: =Elect!AP14 -> 1 | S10: =Elect!AR14 -> 2.53 | T10: =Elect!AT14 -> 27 | U10: =Elect!AV14 -> 251 | V10: =Elect!AX14 -> 19 | W10: =Elect!AZ14 -> 943 | X10: =Elect!BB14 -> 2106.3 | Y10: =Elect!BE14 -> 0 | Z10: =Elect!BG14 -> 627 | AA10: =Elect!BI14 -> 49 | AB10: =Elect!BK14 -> 117 | AD10: =Water!C15 -> 98.6 | AE10: =Water!E15 -> 34.8 | AF10: =Water!G15 -> 0 | AH10: =Gas!C15 -> 170.66 | AI10: =Gas!E15 -> 149.20606 | AJ10: =Gas!G15 -> 0 | AK10: =Elect!BM14 -> 0
A11: Cairo at The First Residence | B11: =B10+1 -> 10 | C11: 3 | D11: 2020 | F11: =Elect!J15 -> 2501 | G11: =Elect!K15 -> 1330 | H11: =Elect!Q15 -> 90 | I11: =Elect!W15 -> 189 | J11: =Elect!Y15 -> 168 | K11: =Elect!AA15 -> 0 | L11: =Elect!AC15 -> 0 | M11: =Elect!AE15 -> 360.4 | N11: =Elect!AG15 -> 527.35 | O11: =Elect!AI15 -> 149.46 | P11: =Elect!AK15 -> 1974.25 | Q11: =Elect!AN15 -> 15 | R11: =Elect!AP15 -> 3 | S11: =Elect!AR15 -> 6.27 | T11: =Elect!AT15 -> 41 | U11: =Elect!AV15 -> 343 | V11: =Elect!AX15 -> 43 | W11: =Elect!AZ15 -> 2196 | X11: =Elect!BB15 -> 4842.5 | Y11: =Elect!BE15 -> 0 | Z11: =Elect!BG15 -> 1375 | AA11: =Elect!BI15 -> 111 | AB11: =Elect!BK15 -> 274 | AD11: =Water!C16 -> 29 | AE11: =Water!E16 -> 17.4 | AF11: =Water!G16 -> 8.12 | AH11: =Gas!C16 -> 170.66 | AI11: =Gas!E16 -> 149.20606 | AJ11: =Gas!G16 -> 2 | AK11: =Elect!BM15 -> 0
A12: Cairo at The First Residence | B12: =B11+1 -> 11 | C12: 3 | D12: 2020 | F12: =Elect!J16 -> 1367 | G12: =Elect!K16 -> 911 | H12: =Elect!Q16 -> 60 | I12: =Elect!W16 -> 99 | J12: =Elect!Y16 -> 292 | K12: =Elect!AA16 -> 0 | L12: =Elect!AC16 -> 601.55 | M12: =Elect!AE16 -> 991.1 | N12: =Elect!AG16 -> 0 | O12: =Elect!AI16 -> 234.79 | P12: =Elect!AK16 -> 1706.07 | Q12: =Elect!AN16 -> 8 | R12: =Elect!AP16 -> 2 | S12: =Elect!AR16 -> 3.19 | T12: =Elect!AT16 -> 31 | U12: =Elect!AV16 -> 221 | V12: =Elect!AX16 -> 21 | W12: =Elect!AZ16 -> 1197 | X12: =Elect!BB16 -> 2570.6 | Y12: =Elect!BE16 -> 0 | Z12: =Elect!BG16 -> 789 | AA12: =Elect!BI16 -> 62 | AB12: =Elect!BK16 -> 150 | AD12: =Water!C17 -> 46.4 | AE12: =Water!E17 -> 29 | AF12: =Water!G17 -> 5.22 | AH12: =Gas!C17 -> 170.66 | AI12: =Gas!E17 -> 149.20606 | AJ12: =Gas!G17 -> 4 | AK12: =Elect!BM16 -> 0
A13: Cairo at The First Residence | B13: =B12+1 -> 12 | C13: 3 | D13: 2020 | F13: =Elect!J17 -> 1552 | G13: =Elect!K17 -> 1122 | H13: =Elect!Q17 -> 60 | I13: =Elect!W17 -> 99 | J13: =Elect!Y17 -> 158 | K13: =Elect!AA17 -> 0 | L13: =Elect!AC17 -> 0 | M13: =Elect!AE17 -> 2015.06 | N13: =Elect!AG17 -> 0 | O13: =Elect!AI17 -> 383.72 | P13: =Elect!AK17 -> 2061.7 | Q13: =Elect!AN17 -> 8 | R13: =Elect!AP17 -> 1 | S13: =Elect!AR17 -> 3.19 | T13: =Elect!AT17 -> 22 | U13: =Elect!AV17 -> 283 | V13: =Elect!AX17 -> 15 | W13: =Elect!AZ17 -> 1187 | X13: =Elect!BB17 -> 2641.7 | Y13: =Elect!BE17 -> 0 | Z13: =Elect!BG17 -> 733 | AA13: =Elect!BI17 -> 63 | AB13: =Elect!BK17 -> 157 | AD13: =Water!C18 -> 40.6 | AE13: =Water!E18 -> 29 | AF13: =Water!G18 -> 7.54 | AH13: =Gas!C18 -> 170.66 | AI13: =Gas!E18 -> 149.20606 | AJ13: =Gas!G18 -> 1 | AK13: =Elect!BM17 -> 0
A14: Cairo at The First Residence | B14: =B13+1 -> 13 | C14: 3 | D14: 2020 | F14: =Elect!J18 -> 1989 | G14: =Elect!K18 -> 1336 | H14: =Elect!Q18 -> 30 | I14: =Elect!W18 -> 136 | J14: =Elect!Y18 -> 217 | K14: =Elect!AA18 -> 0 | L14: =Elect!AC18 -> 0 | M14: =Elect!AE18 -> 555.97 | N14: =Elect!AG18 -> 914.25 | O14: =Elect!AI18 -> 227.9 | P14: =Elect!AK18 -> 1314.93 | Q14: =Elect!AN18 -> 11 | R14: =Elect!AP18 -> 2 | S14: =Elect!AR18 -> 3.63 | T14: =Elect!AT18 -> 29 | U14: =Elect!AV18 -> 298 | V14: =Elect!AX18 -> 0 | W14: =Elect!AZ18 -> 2023 | X14: =Elect!BB18 -> 3427.4 | Y14: =Elect!BE18 -> 0 | Z14: =Elect!BG18 -> 816 | AA14: =Elect!BI18 -> 90 | AB14: =Elect!BK18 -> 212 | AD14: =Water!C19 -> 63.8 | AE14: =Water!E19 -> 46.4 | AF14: =Water!G19 -> 6.96 | AH14: =Gas!C19 -> 170.66 | AI14: =Gas!E19 -> 149.20606 | AJ14: =Gas!G19 -> 1 | AK14: =Elect!BM18 -> 0
... A32: Cairo at The First Residence | B32: =B31+1 -> 31 | C32: 3 | D32: 2020 | F32: =Elect!J36 -> 0 | G32: =Elect!K36 -> 0 | H32: =Elect!Q36 -> 0 | I32: =Elect!W36 -> 0 | J32: =Elect!Y36 -> 0 | K32: =Elect!AA36 -> 0 | L32: =Elect!AC36 -> 0 | M32: =Elect!AE36 -> 0 | N32: =Elect!AG36 -> 0 | O32: =Elect!AI36 -> 0 | P32: =Elect!AK36 -> 0 | Q32: =Elect!AN36 -> 0 | R32: =Elect!AP36 -> 0 | S32: =Elect!AR36 -> 0 | T32: =Elect!AT36 -> 0 | U32: =Elect!AV36 -> 0 | V32: =Elect!AX36 -> 0 | W32: =Elect!AZ36 -> 0 | X32: =Elect!BB36 -> 0 | Y32: =Elect!BE36 -> 0 | Z32: =Elect!BG36 -> 0 | AA32: =Elect!BI36 -> 0 | AB32: =Elect!BK36 -> 0 | AD32: =Water!C37 -> 0 | AE32: =Water!E37 -> 0 | AF32: =Water!G37 -> 0 | AH32: =Gas!C37 -> 0 | AI32: =Gas!E37 -> 0 | AJ32: =Gas!G37 -> 0 | AK32: =Elect!BM36 -> 0

Sheet Elect
A1: April | M1: Electricity | BL1: Power Taxes | BM1: 0.0006 | BN1: Max Demand | BP1: 500 | BQ1: Electricity UP | BS1: 0.46
BL2: Light Taxes | BM2: 0.03 | BN2: PF Penalty | BQ2: Max. Demand UP | BS2: 30
A3: Date | B3: COUNTER (1) | D3: MD | F3: KVAR | H3: n | I3: Guest Rooms Consumption | R3: Casino Consumption | AD3: Plant Room Shared Loads | AW3: To Be Charged By First Arabian | BG3: From Main Panel G2 | BL3: Total Consumption. | BM3: No. Of | BN3: KWH/ | BO3: No. Of | BP3: KWH/ | BQ3: Total Cost | BR3: L.E\ | BS3: L.E\
B4: Reading | C4: Consp. F: *800 | D4: Reading | E4: Consp F: 80 | F4: Reading | G4: Consp. F:*10 | I4: Main Feeder | J4: Consp | K4: T2+T8 | L4: Trans T2 | M4: Consp | N4: Trans T8 | O4: Consp | P4: La Gourmandize | Q4: Consp *30 | R4: Casino 1 | S4: Consp | T4: Casino 2 | U4: Consp | V4: Casino 3rd floor EM | W4: Consp | X4: Casino 3rd floor Normal | Y4: Consp | Z4: Chiller 1 | AA4: Consp 53% | AB4: Chiller 2 | AC4: Consp 53% | AD4: Chiller 3 | AE4: Consp 53% | AF4: Chiller 4 | AG4: Consp 53% | AH4: Cooling towers | AI4: Consp 53% | AJ4: Chiller Pumps | AK4: Consp 53% | AL4: Total Plant Room Consp | AM4: LG Bakery | AN4: Consp | AO4: Mall Ceiling light | AP4: Consp | AQ4: New chiller for Second floor | AR4: Consp | AS4: LG Bakery light ( Old lockers ) | AT4: Consp | AU4: MCCR1 | AV4: Consp | AW4: Children Swimming pool | AX4: Consp | AY4: DPH1 | AZ4: Consp | BA4: Main G2 | BB4: Consp | BC4: Total Consp From First Arabian | BD4: Casino Emergency | BE4: Consp | BF4: L / A | BG4: Consp | BH4: L / B | BI4: Consp | BJ4: L / C | BK4: Consp | BM4: Rooms | BN4: room | BO4: guest | BP4: guest | BR4: Room | BS4: Guest
A5: Last Month Reading | I5: 20903264 | J5: =IF(I5>=I4,I5-I4,0) -> 0 | K5: =M5+O5 -> 0 | L5: 639087 | M5: =IF(L5>=L4,L5-L4,0) -> 0 | N5: 625772 | O5: =IF(N5>=N4,N5-N4,0) -> 0 | P5: 210667 | Q5: =IF(P5>=P4,P5-P4,0)*30 -> 0 | R5: 702925 | S5: =IF(R5>=R4,R5-R4,0) -> 0 | T5: 344001 | U5: =IF(T5>=T4,T5-T4,0) -> 0 | V5: 89901 | W5: =IF(V5>=V4,V5-V4,0) -> 0 | X5: 167667 | Y5: =IF(X5>=X4,X5-X4,0) -> 0 | Z5: 315108 | AA5: =IF(Z5>=Z4,Z5-Z4,0)*0.53 -> 0 | AB5: 657605 | AC5: =IF(AB5>=AB4,AB5-AB4,0)*0.53 -> 0 | AD5: 728396 | AE5: =IF(AD5>=AD4,AD5-AD4,0)*0.53 -> 0 | AF5: 704806 | AG5: =IF(AF5>=AF4,AF5-AF4,0)*0.53 -> 0 | AH5: 196777 | AI5: =IF(AH5>=AH4,AH5-AH4,0)*0.53 -> 0 | AJ5: 230037 | AK5: =IF(AJ5>=AJ4,AJ5-AJ4,0)*0.53 -> 0 | AL5: =AA5+AC5+AE5+AG5+AI5+AK5 -> 0 | AM5: 6884066 | AN5: =IF(AM5>=AM4,AM5-AM4,0) -> 0 | AO5: 536155 | AP5: =IF(AO5>=AO4,AO5-AO4,0) -> 0 | AQ5: 880427 | AR5: =IF(AQ5>=AQ4,AQ5-AQ4,0)*0.11 -> 0 | AS5: 781476 | AT5: =IF(AS5>=AS4,AS5-AS4,0) -> 0 | AU5: 2151442 | AV5: =IF(AU5>=AU4,AU5-AU4,0) -> 0 | AW5: 194717 | AX5: 0 | AY5: 16702581 | AZ5: =IF(AY5>=AY4,AY5-AY4,0) -> 0 | BA5: 20196681 | BB5: =IF(BA5>=BA4,BA5-BA4,0)-(0.6*BG5)-(0.5*BI5)-BK5-BE5 -> 0 | BC5: =AN5+AP5+AR5+AT5+AV5+AX5+AZ5+BB5 -> 0 | BD5: 1323286 | BE5: =IF(BD5>=BD4,BD5-BD4,0) -> 0 | BF5: 3122359 | BG5: =IF(BF5>=BF4,BF5-BF4,0) -> 0 | BH5: 346792 | BI5: =IF(BH5>=BH4,BH5-BH4,0) -> 0 | BJ5: 394126 | BK5: =IF(BJ5>=BJ4,BJ5-BJ4,0) -> 0
A6: 1 | C6: =IF(+B6-B5>0,B6-B5,(B6-B5)>0)*800 -> 0 | E6: =IF(+D6-D5>0,D6-D5,(D6-D5)>0)*80 -> 0 | G6: =IF(+F6-F5>0,F6-F5,(F6-F5)>0)*10 -> 0 | H6: 56 | I6: 20904798 | J6: =IF(I6>=I5,I6-I5,0) -> 1534 | K6: =M6+O6 -> 1084 | L6: 639631 | M6: =IF(L6>=L5,L6-L5,0) -> 544 | N6: 626312 | O6: =IF(N6>=N5,N6-N5,0) -> 540 | P6: 210667 | Q6: =IF(P6>=P5,P6-P5,0)*30 -> 0 | R6: 702925 | S6: =IF(R6>=R5,R6-R5,0) -> 0 | T6: 344001 | U6: =IF(T6>=T5,T6-T5,0) -> 0 | V6: 90021 | W6: =IF(V6>=V5,V6-V5,0) -> 120 | X6: 167765 | Y6: =IF(X6>=X5,X6-X5,0) -> 98 | Z6: 315108 | AA6: =IF(Z6>=Z5,Z6-Z5,0)*0.53 -> 0 | AB6: 658198 | AC6: =IF(AB6>=AB5,AB6-AB5,0)*0.53 -> 314.29 | AD6: 729274 | AE6: =IF(AD6>=AD5,AD6-AD5,0)*0.53 -> 465.34 | AF6: 705422 | AG6: =IF(AF6>=AF5,AF6-AF5,0)*0.53 -> 326.48 | AH6: 197322 | AI6: =IF(AH6>=AH5,AH6-AH5,0)*0.53 -> 288.85 | AJ6: 233342 | AK6: =IF(AJ6>=AJ5,AJ6-AJ5,0)*0.53 -> 1751.65 | AL6: =AA6+AC6+AE6+AG6+AI6+AK6 -> 3146.61 | AM6: 6884089 | AN6: =IF(AM6>=AM5,AM6-AM5,0) -> 23 | AO6: 536158 | AP6: =IF(AO6>=AO5,AO6-AO5,0) -> 3 | AQ6: 880456 | AR6: =IF(AQ6>=AQ5,AQ6-AQ5,0)*0.11 -> 3.19 | AS6: 781503 | AT6: =IF(AS6>=AS5,AS6-AS5,0) -> 27 | AU6: 2151715 | AV6: =IF(AU6>=AU5,AU6-AU5,0) -> 273 | AW6: 194756 | AX6: =IF(AW6>=AW5,AW6-AW5,0) -> 39 | AY6: 16704054 | AZ6: =IF(AY6>=AY5,AY6-AY5,0) -> 1473 | BA6: 20200076 | BB6: =IF(BA6>=BA5,BA6-BA5,0)-(0.6*BG6)-(0.5*BI6)-BK6-BE6 -> 2753.9 | BC6: =AN6+AP6+AR6+AT6+AV6+AX6+AZ6+BB6 -> 4595.09 | BD6: 1323286 | BE6: =IF(BD6>=BD5,BD6-BD5,0) -> 0 | BF6: 3123115 | BG6: =IF(BF6>=BF5,BF6-BF5,0) -> 756 | BH6: 346859 | BI6: =IF(BH6>=BH5,BH6-BH5,0) -> 67 | BJ6: 394280 | BK6: =IF(BJ6>=BJ5,BJ6-BJ5,0) -> 154 | BL6: =J6+Q6+AL6+BC6 -> 9275.7 | BN6: =IF(BL6>0,BL6/#REF!,0) -> #REF! | BP6: =IF(BL6>0,BL6/BO6,0) -> #DIV/0! | BQ6: =BL6*BS1 -> 4266.822 | BR6: =IF(BQ6>0,BQ6/#REF!,0) -> #REF! | BS6: =IF(BQ6>0,BQ6/BO6,0) -> #DIV/0!
A7: 2 | I7: 20906694 | J7: =IF(I7>=I6,I7-I6,0) -> 1896 | K7: =M7+O7 -> 1790 | L7: 640561 | M7: =IF(L7>=L6,L7-L6,0) -> 930 | N7: 627172 | O7: =IF(N7>=N6,N7-N6,0) -> 860 | P7: 210670 | Q7: =IF(P7>=P6,P7-P6,0)*30 -> 90 | R7: 702925 | S7: =IF(R7>=R6,R7-R6,0) -> 0 | T7: 344001 | U7: =IF(T7>=T6,T7-T6,0) -> 0 | V7: 90171 | W7: =IF(V7>=V6,V7-V6,0) -> 150 | X7: 167861 | Y7: =IF(X7>=X6,X7-X6,0) -> 96 | Z7: 315108 | AA7: =IF(Z7>=Z6,Z7-Z6,0)*0.53 -> 0 | AB7: 659201 | AC7: =IF(AB7>=AB6,AB7-AB6,0)*0.53 -> 531.59 | AD7: 732609 | AE7: =IF(AD7>=AD6,AD7-AD6,0)*0.53 -> 1767.55 | AF7: 705621 | AG7: =IF(AF7>=AF6,AF7-AF6,0)*0.53 -> 105.47 | AH7: 198543 | AI7: =IF(AH7>=AH6,AH7-AH6,0)*0.53 -> 647.13 | AJ7: 239214 | AK7: =IF(AJ7>=AJ6,AJ7-AJ6,0)*0.53 -> 3112.16 | AL7: =AA7+AC7+AE7+AG7+AI7+AK7 -> 6163.9 | AM7: 6884116 | AN7: =IF(AM7>=AM6,AM7-AM6,0) -> 27 | AO7: 536160 | AP7: =IF(AO7>=AO6,AO7-AO6,0) -> 2 | AQ7: 880512 | AR7: =IF(AQ7>=AQ6,AQ7-AQ6,0)*0.11 -> 6.16 | AS7: 781548 | AT7: =IF(AS7>=AS6,AS7-AS6,0) -> 45 | AU7: 2152168 | AV7: =IF(AU7>=AU6,AU7-AU6,0) -> 453 | AW7: 194794 | AX7: =IF(AW7>=AW6,AW7-AW6,0) -> 38 | AY7: 16706412 | AZ7: =IF(AY7>=AY6,AY7-AY6,0) -> 2358 | BA7: 20206339 | BB7: =IF(BA7>=BA6,BA7-BA6,0)-(0.6*BG7)-(0.5*BI7)-BK7-BE7 -> 5120.2 | BC7: =AN7+AP7+AR7+AT7+AV7+AX7+AZ7+BB7 -> 8049.36 | BD7: 1323286 | BE7: =IF(BD7>=BD6,BD7-BD6,0) -> 0 | BF7: 3124443 | BG7: =IF(BF7>=BF6,BF7-BF6,0) -> 1328 | BH7: 346973 | BI7: =IF(BH7>=BH6,BH7-BH6,0) -> 114 | BJ7: 394569 | BK7: =IF(BJ7>=BJ6,BJ7-BJ6,0) -> 289 | BL7: =J7+Q7+AL7+BC7 -> 16199.26 | BN7: =IF(BL7>0,BL7/BM6,0) -> #DIV/0! | BP7: =IF(BL7>0,BL7/BO7,0) -> #DIV/0! | BQ7: =BL7*BS1 -> 7451.6596 | BR7: =IF(BQ7>0,BQ7/BM6,0) -> #DIV/0! | BS7: =IF(BQ7>0,BQ7/BO7,0) -> #DIV/0!
A8: 3 | C8: =IF(+B8-B7>0,B8-B7,(B8-B7)>0)*800 -> 0 | E8: =IF(+D8-D7>0,D8-D7,(D8-D7)>0)*80 -> 0 | G8: =IF(+F8-F7>0,F8-F7,(F8-F7)>0)*10 -> 0 | H8: 57 | I8: 20908396 | J8: =IF(I8>=I7,I8-I7,0) -> 1702 | K8: =M8+O8 -> 776 | L8: 640963 | M8: =IF(L8>=L7,L8-L7,0) -> 402 | N8: 627546 | O8: =IF(N8>=N7,N8-N7,0) -> 374 | P8: 210671 | Q8: =IF(P8>=P7,P8-P7,0)*30 -> 30 | R8: 702925 | S8: =IF(R8>=R7,R8-R7,0) -> 0 | T8: 344001 | U8: =IF(T8>=T7,T8-T7,0) -> 0 | V8: 90258 | W8: =IF(V8>=V7,V8-V7,0) -> 87 | X8: 168158 | Y8: =IF(X8>=X7,X8-X7,0) -> 297 | Z8: 315108 | AA8: =IF(Z8>=Z7,Z8-Z7,0)*0.53 -> 0 | AB8: 659805 | AC8: =IF(AB8>=AB7,AB8-AB7,0)*0.53 -> 320.12 | AD8: 732945 | AE8: =IF(AD8>=AD7,AD8-AD7,0)*0.53 -> 178.08 | AF8: 705621 | AG8: =IF(AF8>=AF7,AF8-AF7,0)*0.53 -> 0 | AH8: 198976 | AI8: =IF(AH8>=AH7,AH8-AH7,0)*0.53 -> 229.49 | AJ8: 241627 | AK8: =IF(AJ8>=AJ7,AJ8-AJ7,0)*0.53 -> 1278.89 | AL8: =AA8+AC8+AE8+AG8+AI8+AK8 -> 2006.58 | AM8: 6884120 | AN8: =IF(AM8>=AM7,AM8-AM7,0) -> 4 | AO8: 536162 | AP8: =IF(AO8>=AO7,AO8-AO7,0) -> 2 | AQ8: 880531 | AR8: =IF(AQ8>=AQ7,AQ8-AQ7,0)*0.11 -> 2.09 | AS8: 781572 | AT8: =IF(AS8>=AS7,AS8-AS7,0) -> 24 | AU8: 2152389 | AV8: =IF(AU8>=AU7,AU8-AU7,0) -> 221 | AW8: 194826 | AX8: =IF(AW8>=AW7,AW8-AW7,0) -> 32 | AY8: 16707378 | AZ8: =IF(AY8>=AY7,AY8-AY7,0) -> 966 | BA8: 20208687 | BB8: =IF(BA8>=BA7,BA8-BA7,0)-(0.6*BG8)-(0.5*BI8)-BK8-BE8 -> 1860.6 | BC8: =AN8+AP8+AR8+AT8+AV8+AX8+AZ8+BB8 -> 3111.69 | BD8: 1323286 | BE8: =IF(BD8>=BD7,BD8-BD7,0) -> 0 | BF8: 3125037 | BG8: =IF(BF8>=BF7,BF8-BF7,0) -> 594 | BH8: 347019 | BI8: =IF(BH8>=BH7,BH8-BH7,0) -> 46 | BJ8: 394677 | BK8: =IF(BJ8>=BJ7,BJ8-BJ7,0) -> 108 | BL8: =J8+Q8+AL8+BC8 -> 6850.27 | BN8: =IF(BL8>0,BL8/BM7,0) -> #DIV/0! | BP8: =IF(BL8>0,BL8/BO8,0) -> #DIV/0! | BQ8: =BL8*BS1 -> 3151.1242 | BR8: =IF(BQ8>0,BQ8/BM7,0) -> #DIV/0! | BS8: =IF(BQ8>0,BQ8/BO8,0) -> #DIV/0!
A9: 4 | C9: =IF(+B9-B8>0,B9-B8,(B9-B8)>0)*800 -> 0 | E9: =IF(+D9-D8>0,D9-D8,(D9-D8)>0)*80 -> 0 | G9: =IF(+F9-F8>0,F9-F8,(F9-F8)>0)*10 -> 0 | I9: 20910389 | J9: =IF(I9>=I8,I9-I8,0) -> 1993 | K9: =M9+O9 -> 1226 | L9: 641597 | M9: =IF(L9>=L8,L9-L8,0) -> 634 | N9: 628138 | O9: =IF(N9>=N8,N9-N8,0) -> 592 | P9: 210674 | Q9: =IF(P9>=P8,P9-P8,0)*30 -> 90 | R9: 702925 | S9: =IF(R9>=R8,R9-R8,0) -> 0 | T9: 344001 | U9: =IF(T9>=T8,T9-T8,0) -> 0 | V9: 90393 | W9: =IF(V9>=V8,V9-V8,0) -> 135 | X9: 168386 | Y9: =IF(X9>=X8,X9-X8,0) -> 228 | Z9: 315108 | AA9: =IF(Z9>=Z8,Z9-Z8,0)*0.53 -> 0 | AB9: 662656 | AC9: =IF(AB9>=AB8,AB9-AB8,0)*0.53 -> 1511.03 | AD9: 732945 | AE9: =IF(AD9>=AD8,AD9-AD8,0)*0.53 -> 0 | AF9: 705621 | AG9: =IF(AF9>=AF8,AF9-AF8,0)*0.53 -> 0 | AH9: 199725 | AI9: =IF(AH9>=AH8,AH9-AH8,0)*0.53 -> 396.97 | AJ9: 245945 | AK9: =IF(AJ9>=AJ8,AJ9-AJ8,0)*0.53 -> 2288.54 | AL9: =AA9+AC9+AE9+AG9+AI9+AK9 -> 4196.54 | AM9: 6884132 | AN9: =IF(AM9>=AM8,AM9-AM8,0) -> 12 | AO9: 536164 | AP9: =IF(AO9>=AO8,AO9-AO8,0) -> 2 | AQ9: 880570 | AR9: =IF(AQ9>=AQ8,AQ9-AQ8,0)*0.11 -> 4.29 | AS9: 781604 | AT9: =IF(AS9>=AS8,AS9-AS8,0) -> 32 | AU9: 2152750 | AV9: =IF(AU9>=AU8,AU9-AU8,0) -> 361 | AW9: 194863 | AX9: =IF(AW9>=AW8,AW9-AW8,0) -> 37 | AY9: 16709216 | AZ9: =IF(AY9>=AY8,AY9-AY8,0) -> 1838 | BA9: 20213149 | BB9: =IF(BA9>=BA8,BA9-BA8,0)-(0.6*BG9)-(0.5*BI9)-BK9-BE9 -> 3667.3 | BC9: =AN9+AP9+AR9+AT9+AV9+AX9+AZ9+BB9 -> 5953.59 | BD9: 1323286 | BE9: =IF(BD9>=BD8,BD9-BD8,0) -> 0 | BF9: 3125954 | BG9: =IF(BF9>=BF8,BF9-BF8,0) -> 917 | BH9: 347104 | BI9: =IF(BH9>=BH8,BH9-BH8,0) -> 85 | BJ9: 394879 | BK9: =IF(BJ9>=BJ8,BJ9-BJ8,0) -> 202 | BL9: =J9+Q9+AL9+BC9 -> 12233.13 | BN9: =IF(BL9>0,BL9/BM8,0) -> #DIV/0! | BP9: =IF(BL9>0,BL9/BO9,0) -> #DIV/0! | BQ9: =BL9*BS1 -> 5627.2398 | BR9: =IF(BQ9>0,BQ9/BM8,0) -> #DIV/0! | BS9: =IF(BQ9>0,BQ9/BO9,0) -> #DIV/0!
A10: 5 | C10: =IF(+B10-B9>0,B10-B9,(B10-B9)>0)*800 -> 0 | E10: =IF(+D10-D9>0,D10-D9,(D10-D9)>0)*80 -> 0 | G10: =IF(+F10-F9>0,F10-F9,(F10-F9)>0)*10 -> 0 | H10: 58 | I10: 20912112 | J10: =IF(I10>=I9,I10-I9,0) -> 1723 | K10: =M10+O10 -> 1590 | L10: 642226 | M10: =IF(L10>=L9,L10-L9,0) -> 629 | N10: 629099 | O10: =IF(N10>=N9,N10-N9,0) -> 961 | P10: 210676 | Q10: =IF(P10>=P9,P10-P9,0)*30 -> 60 | R10: 702925 | S10: =IF(R10>=R9,R10-R9,0) -> 0 | T10: 344001 | U10: =IF(T10>=T9,T10-T9,0) -> 0 | V10: 90507 | W10: =IF(V10>=V9,V10-V9,0) -> 114 | X10: 168577 | Y10: =IF(X10>=X9,X10-X9,0) -> 191 | Z10: 315108 | AA10: =IF(Z10>=Z9,Z10-Z9,0)*0.53 -> 0 | AB10: 667766 | AC10: =IF(AB10>=AB9,AB10-AB9,0)*0.53 -> 2708.3 | AD10: 732945 | AE10: =IF(AD10>=AD9,AD10-AD9,0)*0.53 -> 0 | AF10: 705621 | AG10: =IF(AF10>=AF9,AF10-AF9,0)*0.53 -> 0 | AH10: 200685 | AI10: =IF(AH10>=AH9,AH10-AH9,0)*0.53 -> 508.8 | AJ10: 251482 | AK10: =IF(AJ10>=AJ9,AJ10-AJ9,0)*0.53 -> 2934.61 | AL10: =AA10+AC10+AE10+AG10+AI10+AK10 -> 6151.71 | AM10: 6884161 | AN10: =IF(AM10>=AM9,AM10-AM9,0) -> 29 | AO10: 536166 | AP10: =IF(AO10>=AO9,AO10-AO9,0) -> 2 | AQ10: 880624 | AR10: =IF(AQ10>=AQ9,AQ10-AQ9,0)*0.11 -> 5.94 | AS10: 781645 | AT10: =IF(AS10>=AS9,AS10-AS9,0) -> 41 | AU10: 2153235 | AV10: =IF(AU10>=AU9,AU10-AU9,0) -> 485 | AW10: 194902 | AX10: =IF(AW10>=AW9,AW10-AW9,0) -> 39 | AY10: 16711652 | AZ10: =IF(AY10>=AY9,AY10-AY9,0) -> 2436 | BA10: 20219004 | BB10: =IF(BA10>=BA9,BA10-BA9,0)-(0.6*BG10)-(0.5*BI10)-BK10-BE10 -> 4770.3 | BC10: =AN10+AP10+AR10+AT10+AV10+AX10+AZ10+BB10 -> 7808.24 | BD10: 1323286 | BE10: =IF(BD10>=BD9,BD10-BD9,0) -> 0 | BF10: 3127236 | BG10: =IF(BF10>=BF9,BF10-BF9,0) -> 1282 | BH10: 347211 | BI10: =IF(BH10>=BH9,BH10-BH9,0) -> 107 | BJ10: 395141 | BK10: =IF(BJ10>=BJ9,BJ10-BJ9,0) -> 262 | BL10: =J10+Q10+AL10+BC10 -> 15742.95 | BN10: =IF(BL10>0,BL10/BM9,0) -> #DIV/0! | BP10: =IF(BL10>0,BL10/BO10,0) -> #DIV/0! | BQ10: =BL10*BS1 -> 7241.757 | BR10: =IF(BQ10>0,BQ10/BM9,0) -> #DIV/0! | BS10: =IF(BQ10>0,BQ10/BO10,0) -> #DIV/0!
A11: 6 | C11: =IF(+B11-B10>0,B11-B10,(B11-B10)>0)*800 -> 0 | E11: =IF(+D11-D10>0,D11-D10,(D11-D10)>0)*80 -> 0 | G11: =IF(+F11-F10>0,F11-F10,(F11-F10)>0)*10 -> 0 | I11: 20913939 | J11: =IF(I11>=I10,I11-I10,0) -> 1827 | K11: =M11+O11 -> 1427 | L11: 642761 | M11: =IF(L11>=L10,L11-L10,0) -> 535 | N11: 629991 | O11: =IF(N11>=N10,N11-N10,0) -> 892 | P11: 210678 | Q11: =IF(P11>=P10,P11-P10,0)*30 -> 60 | R11: 702925 | S11: =IF(R11>=R10,R11-R10,0) -> 0 | T11: 344001 | U11: =IF(T11>=T10,T11-T10,0) -> 0 | V11: 90620 | W11: =IF(V11>=V10,V11-V10,0) -> 113 | X11: 168766 | Y11: =IF(X11>=X10,X11-X10,0) -> 189 | Z11: 315108 | AA11: =IF(Z11>=Z10,Z11-Z10,0)*0.53 -> 0 | AB11: 669638 | AC11: =IF(AB11>=AB10,AB11-AB10,0)*0.53 -> 992.16 | AD11: 732945 | AE11: =IF(AD11>=AD10,AD11-AD10,0)*0.53 -> 0 | AF11: 705621 | AG11: =IF(AF11>=AF10,AF11-AF10,0)*0.53 -> 0 | AH11: 201023 | AI11: =IF(AH11>=AH10,AH11-AH10,0)*0.53 -> 179.14 | AJ11: 253198 | AK11: =IF(AJ11>=AJ10,AJ11-AJ10,0)*0.53 -> 909.48 | AL11: =AA11+AC11+AE11+AG11+AI11+AK11 -> 2080.78 | AM11: 6884208 | AN11: =IF(AM11>=AM10,AM11-AM10,0) -> 47 | AO11: 536168 | AP11: =IF(AO11>=AO10,AO11-AO10,0) -> 2 | AQ11: 880641 | AR11: =IF(AQ11>=AQ10,AQ11-AQ10,0)*0.11 -> 1.87 | AS11: 781663 | AT11: =IF(AS11>=AS10,AS11-AS10,0) -> 18 | AU11: 2153432 | AV11: =IF(AU11>=AU10,AU11-AU10,0) -> 197 | AW11: 194935 | AX11: =IF(AW11>=AW10,AW11-AW10,0) -> 33 | AY11: 16712519 | AZ11: =IF(AY11>=AY10,AY11-AY10,0) -> 867 | BA11: 20220967 | BB11: =IF(BA11>=BA10,BA11-BA10,0)-(0.6*BG11)-(0.5*BI11)-BK11-BE11 -> 1578.9 | BC11: =AN11+AP11+AR11+AT11+AV11+AX11+AZ11+BB11 -> 2744.77 | BD11: 1323286 | BE11: =IF(BD11>=BD10,BD11-BD10,0) -> 0 | BF11: 3127707 | BG11: =IF(BF11>=BF10,BF11-BF10,0) -> 471 | BH11: 347246 | BI11: =IF(BH11>=BH10,BH11-BH10,0) -> 35 | BJ11: 395225 | BK11: =IF(BJ11>=BJ10,BJ11-BJ10,0) -> 84 | BL11: =J11+Q11+AL11+BC11 -> 6712.55 | BN11: =IF(BL11>0,BL11/BM10,0) -> #DIV/0! | BP11: =IF(BL11>0,BL11/BO11,0) -> #DIV/0! | BQ11: =BL11*BS1 -> 3087.773 | BR11: =IF(BQ11>0,BQ11/BM10,0) -> #DIV/0! | BS11: =IF(BQ11>0,BQ11/BO11,0) -> #DIV/0!
A12: 7 | C12: =IF(+B12-B11>0,B12-B11,(B12-B11)>0)*800 -> 0 | E12: =IF(+D12-D11>0,D12-D11,(D12-D11)>0)*80 -> 0 | G12: =IF(+F12-F11>0,F12-F11,(F12-F11)>0)*10 -> 0 | H12: 59 | I12: 20916397 | J12: =IF(I12>=I11,I12-I11,0) -> 2458 | K12: =M12+O12 -> 1967 | L12: 643637 | M12: =IF(L12>=L11,L12-L11,0) -> 876 | N12: 631082 | O12: =IF(N12>=N11,N12-N11,0) -> 1091 | P12: 210682 | Q12: =IF(P12>=P11,P12-P11,0)*30 -> 120 | R12: 702925 | S12: =IF(R12>=R11,R12-R11,0) -> 0 | T12: 344001 | U12: =IF(T12>=T11,T12-T11,0) -> 0 | V12: 90780 | W12: =IF(V12>=V11,V12-V11,0) -> 160 | X12: 169029 | Y12: =IF(X12>=X11,X12-X11,0) -> 263 | Z12: 315108 | AA12: =IF(Z12>=Z11,Z12-Z11,0)*0.53 -> 0 | AB12: 670595 | AC12: =IF(AB12>=AB11,AB12-AB11,0)*0.53 -> 507.21 | AD12: 736604 | AE12: =IF(AD12>=AD11,AD12-AD11,0)*0.53 -> 1939.27 | AF12: 705621 | AG12: =IF(AF12>=AF11,AF12-AF11,0)*0.53 -> 0 | AH12: 201849 | AI12: =IF(AH12>=AH11,AH12-AH11,0)*0.53 -> 437.78 | AJ12: 257756 | AK12: =IF(AJ12>=AJ11,AJ12-AJ11,0)*0.53 -> 2415.74 | AL12: =AA12+AC12+AE12+AG12+AI12+AK12 -> 5300 | AM12: 6884223 | AN12: =IF(AM12>=AM11,AM12-AM11,0) -> 15 | AO12: 536170 | AP12: =IF(AO12>=AO11,AO12-AO11,0) -> 2 | AQ12: 880688 | AR12: =IF(AQ12>=AQ11,AQ12-AQ11,0)*0.11 -> 5.17 | AS12: 781699 | AT12: =IF(AS12>=AS11,AS12-AS11,0) -> 36 | AU12: 2153803 | AV12: =IF(AU12>=AU11,AU12-AU11,0) -> 371 | AW12: 194979 | AX12: =IF(AW12>=AW11,AW12-AW11,0) -> 44 | AY12: 16715090 | AZ12: =IF(AY12>=AY11,AY12-AY11,0) -> 2571 | BA12: 20226350 | BB12: =IF(BA12>=BA11,BA12-BA11,0)-(0.6*BG12)-(0.5*BI12)-BK12-BE12 -> 4300.1 | BC12: =AN12+AP12+AR12+AT12+AV12+AX12+AZ12+BB12 -> 7344.27 | BD12: 1323286 | BE12: =IF(BD12>=BD11,BD12-BD11,0) -> 0 | BF12: 3129046 | BG12: =IF(BF12>=BF11,BF12-BF11,0) -> 1339 | BH12: 347341 | BI12: =IF(BH12>=BH11,BH12-BH11,0) -> 95 | BJ12: 395457 | BK12: =IF(BJ12>=BJ11,BJ12-BJ11,0) -> 232 | BL12: =J12+Q12+AL12+BC12 -> 15222.27 | BN12: =IF(BL12>0,BL12/BM11,0) -> #DIV/0! | BP12: =IF(BL12>0,BL12/BO12,0) -> #DIV/0! | BQ12: =BL12*BS1 -> 7002.2442 | BR12: =IF(BQ12>0,BQ12/BM11,0) -> #DIV/0! | BS12: =IF(BQ12>0,BQ12/BO12,0) -> #DIV/0!
A13: 8 | C13: =IF(+B13-B12>0,B13-B12,(B13-B12)>0)*800 -> 0 | E13: =IF(+D13-D12>0,D13-D12,(D13-D12)>0)*80 -> 0 | G13: =IF(+F13-F12>0,F13-F12,(F13-F12)>0)*10 -> 0 | I13: 20918501 | J13: =IF(I13>=I12,I13-I12,0) -> 2104 | K13: =M13+O13 -> 1316 | L13: 644414 | M13: =IF(L13>=L12,L13-L12,0) -> 777 | N13: 631621 | O13: =IF(N13>=N12,N13-N12,0) -> 539 | P13: 210685 | Q13: =IF(P13>=P12,P13-P12,0)*30 -> 90 | R13: 702925 | S13: =IF(R13>=R12,R13-R12,0) -> 0 | T13: 344001 | U13: =IF(T13>=T12,T13-T12,0) -> 0 | V13: 90928 | W13: =IF(V13>=V12,V13-V12,0) -> 148 | X13: 169266 | Y13: =IF(X13>=X12,X13-X12,0) -> 237 | Z13: 315108 | AA13: =IF(Z13>=Z12,Z13-Z12,0)*0.53 -> 0 | AB13: 670595 | AC13: =IF(AB13>=AB12,AB13-AB12,0)*0.53 -> 0 | AD13: 740995 | AE13: =IF(AD13>=AD12,AD13-AD12,0)*0.53 -> 2327.23 | AF13: 705621 | AG13: =IF(AF13>=AF12,AF13-AF12,0)*0.53 -> 0 | AH13: 202687 | AI13: =IF(AH13>=AH12,AH13-AH12,0)*0.53 -> 444.14 | AJ13: 262347 | AK13: =IF(AJ13>=AJ12,AJ13-AJ12,0)*0.53 -> 2433.23 | AL13: =AA13+AC13+AE13+AG13+AI13+AK13 -> 5204.6 | AM13: 6884235 | AN13: =IF(AM13>=AM12,AM13-AM12,0) -> 12 | AO13: 536173 | AP13: =IF(AO13>=AO12,AO13-AO12,0) -> 3 | AQ13: 880730 | AR13: =IF(AQ13>=AQ12,AQ13-AQ12,0)*0.11 -> 4.62 | AS13: 781730 | AT13: =IF(AS13>=AS12,AS13-AS12,0) -> 31 | AU13: 2154135 | AV13: =IF(AU13>=AU12,AU13-AU12,0) -> 332 | AW13: 195017 | AX13: =IF(AW13>=AW12,AW13-AW12,0) -> 38 | AY13: 16717305 | AZ13: =IF(AY13>=AY12,AY13-AY12,0) -> 2215 | BA13: 20231213 | BB13: =IF(BA13>=BA12,BA13-BA12,0)-(0.6*BG13)-(0.5*BI13)-BK13-BE13 -> 3896.5 | BC13: =AN13+AP13+AR13+AT13+AV13+AX13+AZ13+BB13 -> 6532.12 | BD13: 1323286 | BE13: =IF(BD13>=BD12,BD13-BD12,0) -> 0 | BF13: 3130221 | BG13: =IF(BF13>=BF12,BF13-BF12,0) -> 1175 | BH13: 347430 | BI13: =IF(BH13>=BH12,BH13-BH12,0) -> 89 | BJ13: 395674 | BK13: =IF(BJ13>=BJ12,BJ13-BJ12,0) -> 217 | BL13: =J13+Q13+AL13+BC13 -> 13930.72 | BN13: =IF(BL13>0,BL13/BM12,0) -> #DIV/0! | BP13: =IF(BL13>0,BL13/BO13,0) -> #DIV/0! | BQ13: =BL13*BS1 -> 6408.1312 | BR13: =IF(BQ13>0,BQ13/BM12,0) -> #DIV/0! | BS13: =IF(BQ13>0,BQ13/BO13,0) -> #DIV/0!
A14: 9 | C14: =IF(+B14-B13>0,B14-B13,(B14-B13)>0)*800 -> 0 | E14: =IF(+D14-D13>0,D14-D13,(D14-D13)>0)*80 -> 0 | G14: =IF(+F14-F13>0,F14-F13,(F14-F13)>0)*10 -> 0 | H14: 60 | I14: 20919463 | J14: =IF(I14>=I13,I14-I13,0) -> 962 | K14: =M14+O14 -> 981 | L14: 644997 | M14: =IF(L14>=L13,L14-L13,0) -> 583 | N14: 632019 | O14: =IF(N14>=N13,N14-N13,0) -> 398 | P14: 210686 | Q14: =IF(P14>=P13,P14-P13,0)*30 -> 30 | R14: 702925 | S14: =IF(R14>=R13,R14-R13,0) -> 0 | T14: 344001 | U14: =IF(T14>=T13,T14-T13,0) -> 0 | V14: 91001 | W14: =IF(V14>=V13,V14-V13,0) -> 73 | X14: 169383 | Y14: =IF(X14>=X13,X14-X13,0) -> 117 | Z14: 315108 | AA14: =IF(Z14>=Z13,Z14-Z13,0)*0.53 -> 0 | AB14: 670595 | AC14: =IF(AB14>=AB13,AB14-AB13,0)*0.53 -> 0 | AD14: 744200 | AE14: =IF(AD14>=AD13,AD14-AD13,0)*0.53 -> 1698.65 | AF14: 705621 | AG14: =IF(AF14>=AF13,AF14-AF13,0)*0.53 -> 0 | AH14: 203317 | AI14: =IF(AH14>=AH13,AH14-AH13,0)*0.53 -> 333.9 | AJ14: 265839 | AK14: =IF(AJ14>=AJ13,AJ14-AJ13,0)*0.53 -> 1850.76 | AL14: =AA14+AC14+AE14+AG14+AI14+AK14 -> 3883.31 | AM14: 6884241 | AN14: =IF(AM14>=AM13,AM14-AM13,0) -> 6 | AO14: 536174 | AP14: =IF(AO14>=AO13,AO14-AO13,0) -> 1 | AQ14: 880753 | AR14: =IF(AQ14>=AQ13,AQ14-AQ13,0)*0.11 -> 2.53 | AS14: 781757 | AT14: =IF(AS14>=AS13,AS14-AS13,0) -> 27 | AU14: 2154386 | AV14: =IF(AU14>=AU13,AU14-AU13,0) -> 251 | AW14: 195036 | AX14: =IF(AW14>=AW13,AW14-AW13,0) -> 19 | AY14: 16718248 | AZ14: =IF(AY14>=AY13,AY14-AY13,0) -> 943 | BA14: 20233837 | BB14: =IF(BA14>=BA13,BA14-BA13,0)-(0.6*BG14)-(0.5*BI14)-BK14-BE14 -> 2106.3 | BC14: =AN14+AP14+AR14+AT14+AV14+AX14+AZ14+BB14 -> 3355.83 | BD14: 1323286 | BE14: =IF(BD14>=BD13,BD14-BD13,0) -> 0 | BF14: 3130848 | BG14: =IF(BF14>=BF13,BF14-BF13,0) -> 627 | BH14: 347479 | BI14: =IF(BH14>=BH13,BH14-BH13,0) -> 49 | BJ14: 395791 | BK14: =IF(BJ14>=BJ13,BJ14-BJ13,0) -> 117 | BL14: =J14+Q14+AL14+BC14 -> 8231.14 | BN14: =IF(BL14>0,BL14/BM13,0) -> #DIV/0! | BP14: =IF(BL14>0,BL14/BO14,0) -> #DIV/0! | BQ14: =BL14*BS1 -> 3786.3244 | BR14: =IF(BQ14>0,BQ14/BM13,0) -> #DIV/0! | BS14: =IF(BQ14>0,BQ14/BO14,0) -> #DIV/0!
A15: 10 | C15: =IF(+B15-B14>0,B15-B14,(B15-B14)>0)*800 -> 0 | E15: =IF(+D15-D14>0,D15-D14,(D15-D14)>0)*80 -> 0 | G15: =IF(+F15-F14>0,F15-F14,(F15-F14)>0)*10 -> 0 | I15: 20921964 | J15: =IF(I15>=I14,I15-I14,0) -> 2501 | K15: =M15+O15 -> 1330 | L15: 645807 | M15: =IF(L15>=L14,L15-L14,0) -> 810 | N15: 632539 | O15: =IF(N15>=N14,N15-N14,0) -> 520 | P15: 210689 | Q15: =IF(P15>=P14,P15-P14,0)*30 -> 90 | R15: 702925 | S15: =IF(R15>=R14,R15-R14,0) -> 0 | T15: 344001 | U15: =IF(T15>=T14,T15-T14,0) -> 0 | V15: 91190 | W15: =IF(V15>=V14,V15-V14,0) -> 189 | X15: 169551 | Y15: =IF(X15>=X14,X15-X14,0) -> 168 | Z15: 315108 | AA15: =IF(Z15>=Z14,Z15-Z14,0)*0.53 -> 0 | AB15: 670595 | AC15: =IF(AB15>=AB14,AB15-AB14,0)*0.53 -> 0 | AD15: 744880 | AE15: =IF(AD15>=AD14,AD15-AD14,0)*0.53 -> 360.4 | AF15: 706616 | AG15: =IF(AF15>=AF14,AF15-AF14,0)*0.53 -> 527.35 | AH15: 203599 | AI15: =IF(AH15>=AH14,AH15-AH14,0)*0.53 -> 149.46 | AJ15: 269564 | AK15: =IF(AJ15>=AJ14,AJ15-AJ14,0)*0.53 -> 1974.25 | AL15: =AA15+AC15+AE15+AG15+AI15+AK15 -> 3011.46 | AM15: 6884256 | AN15: =IF(AM15>=AM14,AM15-AM14,0) -> 15 | AO15: 536177 | AP15: =IF(AO15>=AO14,AO15-AO14,0) -> 3 | AQ15: 880810 | AR15: =IF(AQ15>=AQ14,AQ15-AQ14,0)*0.11 -> 6.27 | AS15: 781798 | AT15: =IF(AS15>=AS14,AS15-AS14,0) -> 41 | AU15: 2154729 | AV15: =IF(AU15>=AU14,AU15-AU14,0) -> 343 | AW15: 195079 | AX15: =IF(AW15>=AW14,AW15-AW14,0) -> 43 | AY15: 16720444 | AZ15: =IF(AY15>=AY14,AY15-AY14,0) -> 2196 | BA15: 20239834 | BB15: =IF(BA15>=BA14,BA15-BA14,0)-(0.6*BG15)-(0.5*BI15)-BK15-BE15 -> 4842.5 | BC15: =AN15+AP15+AR15+AT15+AV15+AX15+AZ15+BB15 -> 7489.77 | BD15: 1323286 | BE15: =IF(BD15>=BD14,BD15-BD14,0) -> 0 | BF15: 3132223 | BG15: =IF(BF15>=BF14,BF15-BF14,0) -> 1375 | BH15: 347590 | BI15: =IF(BH15>=BH14,BH15-BH14,0) -> 111 | BJ15: 396065 | BK15: =IF(BJ15>=BJ14,BJ15-BJ14,0) -> 274 | BL15: =J15+Q15+AL15+BC15 -> 13092.23 | BN15: =IF(BL15>0,BL15/BM14,0) -> #DIV/0! | BP15: =IF(BL15>0,BL15/BO15,0) -> #DIV/0! | BQ15: =BL15*BS1 -> 6022.4258 | BR15: =IF(BQ15>0,BQ15/BM14,0) -> #DIV/0! | BS15: =IF(BQ15>0,BQ15/BO15,0) -> #DIV/0!
A16: 11 | C16: =IF(+B16-B15>0,B16-B15,(B16-B15)>0)*800 -> 0 | E16: =IF(+D16-D15>0,D16-D15,(D16-D15)>0)*80 -> 0 | G16: =IF(+F16-F15>0,F16-F15,(F16-F15)>0)*10 -> 0 | H16: 61 | I16: 20923331 | J16: =IF(I16>=I15,I16-I15,0) -> 1367 | K16: =M16+O16 -> 911 | L16: 646356 | M16: =IF(L16>=L15,L16-L15,0) -> 549 | N16: 632901 | O16: =IF(N16>=N15,N16-N15,0) -> 362 | P16: 210691 | Q16: =IF(P16>=P15,P16-P15,0)*30 -> 60 | R16: 702925 | S16: =IF(R16>=R15,R16-R15,0) -> 0 | T16: 344001 | U16: =IF(T20>=T15,T20-T15,0) -> 0 | V16: 91289 | W16: =IF(V16>=V15,V16-V15,0) -> 99 | X16: 169843 | Y16: =IF(X16>=X15,X16-X15,0) -> 292 | Z16: 315108 | AA16: =IF(Z16>=Z15,Z16-Z15,0)*0.53 -> 0 | AB16: 671730 | AC16: =IF(AB16>=AB15,AB16-AB15,0)*0.53 -> 601.55 | AD16: 746750 | AE16: =IF(AD16>=AD15,AD16-AD15,0)*0.53 -> 991.1 | AF16: 706616 | AG16: =IF(AF16>=AF15,AF16-AF15,0)*0.53 -> 0 | AH16: 204042 | AI16: =IF(AH16>=AH15,AH16-AH15,0)*0.53 -> 234.79 | AJ16: 272783 | AK16: =IF(AJ16>=AJ15,AJ16-AJ15,0)*0.53 -> 1706.07 | AL16: =AA16+AC16+AE16+AG16+AI16+AK16 -> 3533.51 | AM16: 6884264 | AN16: =IF(AM16>=AM15,AM16-AM15,0) -> 8 | AO16: 536179 | AP16: =IF(AO16>=AO15,AO16-AO15,0) -> 2 | AQ16: 880839 | AR16: =IF(AQ16>=AQ15,AQ16-AQ15,0)*0.11 -> 3.19 | AS16: 781829 | AT16: =IF(AS16>=AS15,AS16-AS15,0) -> 31 | AU16: 2154950 | AV16: =IF(AU16>=AU15,AU16-AU15,0) -> 221 | AW16: 195100 | AX16: =IF(AW16>=AW15,AW16-AW15,0) -> 21 | AY16: 16721641 | AZ16: =IF(AY16>=AY15,AY16-AY15,0) -> 1197 | BA16: 20243059 | BB16: =IF(BA16>=BA15,BA16-BA15,0)-(0.6*BG16)-(0.5*BI16)-BK16-BE16 -> 2570.6 | BC16: =AN16+AP16+AR16+AT16+AV16+AX16+AZ16+BB16 -> 4053.79 | BD16: 1323286 | BE16: =IF(BD16>=BD15,BD16-BD15,0) -> 0 | BF16: 3133012 | BG16: =IF(BF16>=BF15,BF16-BF15,0) -> 789 | BH16: 347652 | BI16: =IF(BH16>=BH15,BH16-BH15,0) -> 62 | BJ16: 396215 | BK16: =IF(BJ16>=BJ15,BJ16-BJ15,0) -> 150 | BL16: =J16+Q16+AL16+BC16 -> 9014.3 | BN16: =IF(BL16>0,BL16/BM15,0) -> #DIV/0! | BP16: =IF(BL16>0,BL16/BO16,0) -> #DIV/0! | BQ16: =BL16*BS1 -> 4146.578 | BR16: =IF(BQ16>0,BQ16/BM15,0) -> #DIV/0! | BS16: =IF(BQ16>0,BQ16/BO16,0) -> #DIV/0!
A17: 12 | C17: =IF(+B17-B16>0,B17-B16,(B17-B16)>0)*800 -> 0 | E17: =IF(+D17-D16>0,D17-D16,(D17-D16)>0)*80 -> 0 | G17: =IF(+F17-F16>0,F17-F16,(F17-F16)>0)*10 -> 0 | I17: 20924883 | J17: =IF(I17>=I16,I17-I16,0) -> 1552 | K17: =M17+O17 -> 1122 | L17: 647009 | M17: =IF(L17>=L16,L17-L16,0) -> 653 | N17: 633370 | O17: =IF(N17>=N16,N17-N16,0) -> 469 | P17: 210693 | Q17: =IF(P17>=P16,P17-P16,0)*30 -> 60 | R17: 702925 | S17: =IF(R17>=R16,R17-R16,0) -> 0 | T17: 344001 | U17: =IF(T17>=T20,T17-T20,0) -> 0 | V17: 91388 | W17: =IF(V17>=V16,V17-V16,0) -> 99 | X17: 170001 | Y17: =IF(X17>=X16,X17-X16,0) -> 158 | Z17: 315108 | AA17: =IF(Z17>=Z16,Z17-Z16,0)*0.53 -> 0 | AB17: 671730 | AC17: =IF(AB17>=AB16,AB17-AB16,0)*0.53 -> 0 | AD17: 750552 | AE17: =IF(AD17>=AD16,AD17-AD16,0)*0.53 -> 2015.06 | AF17: 706616 | AG17: =IF(AF17>=AF16,AF17-AF16,0)*0.53 -> 0 | AH17: 204766 | AI17: =IF(AH17>=AH16,AH17-AH16,0)*0.53 -> 383.72 | AJ17: 276673 | AK17: =IF(AJ17>=AJ16,AJ17-AJ16,0)*0.53 -> 2061.7 | AL17: =AA17+AC17+AE17+AG17+AI17+AK17 -> 4460.48 | AM17: 6884272 | AN17: =IF(AM17>=AM16,AM17-AM16,0) -> 8 | AO17: 536180 | AP17: =IF(AO17>=AO16,AO17-AO16,0) -> 1 | AQ17: 880868 | AR17: =IF(AQ17>=AQ16,AQ17-AQ16,0)*0.11 -> 3.19 | AS17: 781851 | AT17: =IF(AS17>=AS16,AS17-AS16,0) -> 22 | AU17: 2155233 | AV17: =IF(AU17>=AU16,AU17-AU16,0) -> 283 | AW17: 195115 | AX17: =IF(AW17>=AW16,AW17-AW16,0) -> 15 | AY17: 16722828 | AZ17: =IF(AY17>=AY16,AY17-AY16,0) -> 1187 | BA17: 20246329 | BB17: =IF(BA17>=BA16,BA17-BA16,0)-(0.6*BG17)-(0.5*BI17)-BK17-BE17 -> 2641.7 | BC17: =AN17+AP17+AR17+AT17+AV17+AX17+AZ17+BB17 -> 4160.89 | BD17: 1323286 | BE17: =IF(BD17>=BF16,BD17-BF16,0) -> 0 | BF17: 3133745 | BG17: =IF(BF17>=BF16,BF17-BF16,0) -> 733 | BH17: 347715 | BI17: =IF(BH17>=BH16,BH17-BH16,0) -> 63 | BJ17: 396372 | BK17: =IF(BJ17>=BJ16,BJ17-BJ16,0) -> 157 | BL17: =J17+Q17+AL17+BC17 -> 10233.37 | BN17: =IF(BL17>0,BL17/BM16,0) -> #DIV/0! | BP17: =IF(BL17>0,BL17/BO17,0) -> #DIV/0! | BQ17: =BL17*BS1 -> 4707.3502 | BR17: =IF(BQ17>0,BQ17/BM16,0) -> #DIV/0! | BS17: =IF(BQ17>0,BQ17/BO17,0) -> #DIV/0!
A18: 13 | C18: =IF(+B18-B17>0,B18-B17,(B18-B17)>0)*800 -> 0 | E18: =IF(+D18-D17>0,D18-D17,(D18-D17)>0)*80 -> 0 | G18: =IF(+F18-F17>0,F18-F17,(F18-F17)>0)*10 -> 0 | H18: 62 | I18: 20926872 | J18: =IF(I18>=I17,I18-I17,0) -> 1989 | K18: =M18+O18 -> 1336 | L18: 647634 | M18: =IF(L18>=L17,L18-L17,0) -> 625 | N18: 634081 | O18: =IF(N18>=N17,N18-N17,0) -> 711 | P18: 210694 | Q18: =IF(P18>=P17,P18-P17,0)*30 -> 30 | R18: 702925 | S18: =IF(R18>=R17,R18-R17,0) -> 0 | T18: 344001 | U18: =IF(T18>=T17,T18-T17,0) -> 0 | V18: 91524 | W18: =IF(V18>=V17,V18-V17,0) -> 136 | X18: 170218 | Y18: =IF(X18>=X17,X18-X17,0) -> 217 | Z18: 315108 | AA18: =IF(Z18>=Z17,Z18-Z17,0)*0.53 -> 0 | AB18: 671730 | AC18: =IF(AB18>=AB17,AB18-AB17,0)*0.53 -> 0 | AD18: 751601 | AE18: =IF(AD18>=AD17,AD18-AD17,0)*0.53 -> 555.97 | AF18: 708341 | AG18: =IF(AF18>=AF17,AF18-AF17,0)*0.53 -> 914.25 | AH18: 205196 | AI18: =IF(AH18>=AH17,AH18-AH17,0)*0.53 -> 227.9 | AJ18: 279154 | AK18: =IF(AJ18>=AJ17,AJ18-AJ17,0)*0.53 -> 1314.93 | AL18: =AA18+AC18+AE18+AG18+AI18+AK18 -> 3013.05 | AM18: 6884283 | AN18: =IF(AM18>=AM17,AM18-AM17,0) -> 11 | AO18: 536182 | AP18: =IF(AO18>=AO17,AO18-AO17,0) -> 2 | AQ18: 880901 | AR18: =IF(AQ18>=AQ17,AQ18-AQ17,0)*0.11 -> 3.63 | AS18: 781880 | AT18: =IF(AS18>=AS17,AS18-AS17,0) -> 29 | AU18: 2155531 | AV18: =IF(AU18>=AU17,AU18-AU17,0) -> 298 | AW18: 195115 | AX18: =IF(AW18>=AW17,AW18-AW17,0) -> 0 | AY18: 16724851 | AZ18: =IF(AY18>=AY17,AY18-AY17,0) -> 2023 | BA18: 20250503 | BB18: =IF(BA18>=BA17,BA18-BA17,0)-(0.6*BG18)-(0.5*BI18)-BK18-BE18 -> 3427.4 | BC18: =AN18+AP18+AR18+AT18+AV18+AX18+AZ18+BB18 -> 5794.03 | BD18: 1323286 | BE18: =IF(BD18>=BD17,BD18-BD17,0) -> 0 | BF18: 3134561 | BG18: =IF(BF18>=BF17,BF18-BF17,0) -> 816 | BH18: 347805 | BI18: =IF(BH18>=BH17,BH18-BH17,0) -> 90 | BJ18: 396584 | BK18: =IF(BJ18>=BJ17,BJ18-BJ17,0) -> 212 | BL18: =J18+Q18+AL18+BC18 -> 10826.08 | BN18: =IF(BL18>0,BL18/BM17,0) -> #DIV/0! | BP18: =IF(BL18>0,BL18/BO18,0) -> #DIV/0! | BQ18: =BL18*BS1 -> 4979.9968 | BR18: =IF(BQ18>0,BQ18/BM17,0) -> #DIV/0! | BS18: =IF(BQ18>0,BQ18/BO18,0) -> #DIV/0!
A19: 14 | C19: =IF(+B19-B18>0,B19-B18,(B19-B18)>0)*800 -> 0 | E19: =IF(+D19-D18>0,D19-D18,(D19-D18)>0)*80 -> 0 | G19: =IF(+F19-F18>0,F19-F18,(F19-F18)>0)*10 -> 0 | I19: 20928953 | J19: =IF(I19>=I18,I19-I18,0) -> 2081 | K19: =M19+O19 -> 1361 | L19: 648360 | M19: =IF(L19>=L18,L19-L18,0) -> 726 | N19: 634716 | O19: =IF(N19>=N18,N19-N18,0) -> 635 | P19: 210695 | Q19: =IF(P19>=P18,P19-P18,0)*30 -> 30 | R19: 702925 | S19: =IF(R19>=R18,R19-R18,0) -> 0 | T19: 344001 | U19: =IF(T19>=T18,T19-T18,0) -> 0 | V19: 91661 | W19: =IF(V19>=V18,V19-V18,0) -> 137 | X19: 170439 | Y19: =IF(X19>=X18,X19-X18,0) -> 221 | Z19: 315108 | AA19: =IF(Z19>=Z18,Z19-Z18,0)*0.53 -> 0 | AB19: 671730 | AC19: =IF(AB19>=AB18,AB19-AB18,0)*0.53 -> 0 | AD19: 752723 | AE19: =IF(AD19>=AD18,AD19-AD18,0)*0.53 -> 594.66 | AF19: 710269 | AG19: =IF(AF19>=AF18,AF19-AF18,0)*0.53 -> 1021.84 | AH19: 205548 | AI19: =IF(AH19>=AH18,AH19-AH18,0)*0.53 -> 186.56 | AJ19: 283464 | AK19: =IF(AJ19>=AJ18,AJ19-AJ18,0)*0.53 -> 2284.3 | AL19: =AA19+AC19+AE19+AG19+AI19+AK19 -> 4087.36 | AM19: 6884293 | AN19: =IF(AM19>=AM18,AM19-AM18,0) -> 10 | AO19: 536183 | AP19: =IF(AO19>=AO18,AO19-AO18,0) -> 1 | AQ19: 880948 | AR19: =IF(AQ19>=AQ18,AQ19-AQ18,0)*0.11 -> 5.17 | AS19: 781916 | AT19: =IF(AS19>=AS18,AS19-AS18,0) -> 36 | AU19: 2155832 | AV19: =IF(AU19>=AU18,AU19-AU18,0) -> 301 | AW19: 195116 | AX19: =IF(AW19>=AW18,AW19-AW18,0) -> 1 | AY19: 16726874 | AZ19: =IF(AY19>=AY18,AY19-AY18,0) -> 2023 | BA19: 20254893 | BB19: =IF(BA19>=BA18,BA19-BA18,0)-(0.6*BG19)-(0.5*BI19)-BK19-BE19 -> 3524.3 | BC19: =AN19+AP19+AR19+AT19+AV19+AX19+AZ19+BB19 -> 5901.47 | BD19: 1323286 | BE19: =IF(BD19>=BD18,BD19-BD18,0) -> 0 | BF19: 3135623 | BG19: =IF(BF19>=BF18,BF19-BF18,0) -> 1062 | BH19: 347882 | BI19: =IF(BH19>=BH18,BH19-BH18,0) -> 77 | BJ19: 396774 | BK19: =IF(BJ19>=BJ18,BJ19-BJ18,0) -> 190 | BL19: =J19+Q19+AL19+BC19 -> 12099.83 | BN19: =IF(BL19>0,BL19/BM18,0) -> #DIV/0! | BP19: =IF(BL19>0,BL19/BO19,0) -> #DIV/0! | BQ19: =BL19*BS1 -> 5565.9218 | BR19: =IF(BQ19>0,BQ19/BM18,0) -> #DIV/0! | BS19: =IF(BQ19>0,BQ19/BO19,0) -> #DIV/0!
A20: 15 | C20: =IF(+B20-B19>0,B20-B19,(B20-B19)>0)*800 -> 0 | E20: =IF(+D20-D19>0,D20-D19,(D20-D19)>0)*80 -> 0 | G20: =IF(+F20-F19>0,F20-F19,(F20-F19)>0)*10 -> 0 | H20: 63 | I20: 20930749 | J20: =IF(I20>=I19,I20-I19,0) -> 1796 | K20: =M20+O20 -> 1328 | L20: 648989 | M20: =IF(L20>=L19,L20-L19,0) -> 629 | N20: 635415 | O20: =IF(N20>=N19,N20-N19,0) -> 699 | P20: 210697 | Q20: =IF(P20>=P19,P20-P19,0)*30 -> 60 | R20: 702925 | S20: =IF(R20>=R19,R20-R19,0) -> 0 | T20: 344001 | U20: =IF(T20>=T19,T20-T19,0) -> 0 | V20: 91776 | W20: =IF(V20>=V19,V20-V19,0) -> 115 | X20: 170637 | Y20: =IF(X20>=X19,X20-X19,0) -> 198 | Z20: 315108 | AA20: =IF(Z20>=Z19,Z20-Z19,0)*0.53 -> 0 | AB20: 671730 | AC20: =IF(AB20>=AB19,AB20-AB19,0)*0.53 -> 0 | AD20: 752791 | AE20: =IF(AD20>=AD19,AD20-AD19,0)*0.53 -> 36.04 | AF20: 713327 | AG20: =IF(AF20>=AF19,AF20-AF19,0)*0.53 -> 1620.74 | AH20: 205989 | AI20: =IF(AH20>=AH19,AH20-AH19,0)*0.53 -> 233.73 | AJ20: 286921 | AK20: =IF(AJ20>=AJ19,AJ20-AJ19,0)*0.53 -> 1832.21 | AL20: =AA20+AC20+AE20+AG20+AI20+AK20 -> 3722.72 | AM20: 6884303 | AN20: =IF(AM20>=AM19,AM20-AM19,0) -> 10 | AO20: 536185 | AP20: =IF(AO20>=AO19,AO20-AO19,0) -> 2 | AQ20: 880981 | AR20: =IF(AQ20>=AQ19,AQ20-AQ19,0)*0.11 -> 3.63 | AS20: 781945 | AT20: =IF(AS20>=AS19,AS20-AS19,0) -> 29 | AU20: 2156132 | AV20: =IF(AU20>=AU19,AU20-AU19,0) -> 300 | AW20: 195116 | AX20: =IF(AW20>=AW19,AW20-AW19,0) -> 0 | AY20: 16728500 | AZ20: =IF(AY20>=AY19,AY20-AY19,0) -> 1626 | BA20: 20258705 | BB20: =IF(BA20>=BA19,BA20-BA19,0)-(0.6*BG20)-(0.5*BI20)-BK20-BE20 -> 3008.6 | BC20: =AN20+AP20+AR20+AT20+AV20+AX20+AZ20+BB20 -> 4979.23 | BD20: 1323286 | BE20: =IF(BD20>=BD19,BD20-BD19,0) -> 0 | BF20: 3136612 | BG20: =IF(BF20>=BF19,BF20-BF19,0) -> 989 | BH20: 347956 | BI20: =IF(BH20>=BH19,BH20-BH19,0) -> 74 | BJ20: 396947 | BK20: =IF(BJ20>=BJ19,BJ20-BJ19,0) -> 173 | BL20: =J20+Q20+AL20+BC20 -> 10557.95 | BN20: =IF(BL20>0,BL20/BM20,0) -> #DIV/0! | BP20: =IF(BL20>0,BL20/BO20,0) -> #DIV/0! | BQ20: =BL20*BS1 -> 4856.657 | BR20: =IF(BQ20>0,BQ20/BM20,0) -> #DIV/0! | BS20: =IF(BQ20>0,BQ20/BO20,0) -> #DIV/0!
A21: 16 | C21: =IF(+B21-B20>0,B21-B20,(B21-B20)>0)*800 -> 0 | E21: =IF(+D21-D20>0,D21-D20,(D21-D20)>0)*80 -> 0 | G21: =IF(+F21-F20>0,F21-F20,(F21-F20)>0)*10 -> 0 | I21: 20932550 | J21: =IF(I21>=I20,I21-I20,0) -> 1801 | K21: =M21+O21 -> 1379 | L21: 649619 | M21: =IF(L21>=L20,L21-L20,0) -> 630 | N21: 636164 | O21: =IF(N21>=N20,N21-N20,0) -> 749 | P21: 210700 | Q21: =IF(P21>=P20,P21-P20,0)*30 -> 90 | R21: 702925 | S21: =IF(R21>=R20,R21-R20,0) -> 0 | T21: 344001 | U21: =IF(T21>=T20,T21-T20,0) -> 0 | V21: 91884 | W21: =IF(V21>=V20,V21-V20,0) -> 108 | X21: 170825 | Y21: =IF(X21>=X20,X21-X20,0) -> 188 | Z21: 315108 | AA21: =IF(Z21>=Z20,Z21-Z20,0)*0.53 -> 0 | AB21: 671730 | AC21: =IF(AB21>=AB20,AB21-AB20,0)*0.53 -> 0 | AD21: 757497 | AE21: =IF(AD21>=AD20,AD21-AD20,0)*0.53 -> 2494.18 | AF21: 713327 | AG21: =IF(AF21>=AF20,AF21-AF20,0)*0.53 -> 0 | AH21: 206711 | AI21: =IF(AH21>=AH20,AH21-AH20,0)*0.53 -> 382.66 | AJ21: 291110 | AK21: =IF(AJ21>=AJ20,AJ21-AJ20,0)*0.53 -> 2220.17 | AL21: =AA21+AC21+AE21+AG21+AI21+AK21 -> 5097.01 | AM21: 6884318 | AN21: =IF(AM21>=AM20,AM21-AM20,0) -> 15 | AO21: 536187 | AP21: =IF(AO21>=AO20,AO21-AO20,0) -> 2 | AQ21: 881016 | AR21: =IF(AQ21>=AQ20,AQ21-AQ20,0)*0.11 -> 3.85 | AS21: 781973 | AT21: =IF(AS21>=AS20,AS21-AS20,0) -> 28 | AU21: 2156460 | AV21: =IF(AU21>=AU20,AU21-AU20,0) -> 328 | AW21: 195116 | AX21: =IF(AW21>=AW20,AW21-AW20,0) -> 0 | AY21: 16730236 | AZ21: =IF(AY21>=AY20,AY21-AY20,0) -> 1736 | BA21: 20262750 | BB21: =IF(BA21>=BA20,BA21-BA20,0)-(0.6*BG21)-(0.5*BI21)-BK21-BE21 -> 3192.1 | BC21: =AN21+AP21+AR21+AT21+AV21+AX21+AZ21+BB21 -> 5304.95 | BD21: 1323286 | BE21: =IF(BD21>=BD20,BD21-BD20,0) -> 0 | BF21: 3137666 | BG21: =IF(BF21>=BF20,BF21-BF20,0) -> 1054 | BH21: 348029 | BI21: =IF(BH21>=BH20,BH21-BH20,0) -> 73 | BJ21: 397131 | BK21: =IF(BJ21>=BJ20,BJ21-BJ20,0) -> 184 | BL21: =J21+Q21+AL21+BC21 -> 12292.96 | BN21: =IF(BL21>0,BL21/BM21,0) -> #DIV/0! | BP21: =IF(BL21>0,BL21/BO21,0) -> #DIV/0! | BQ21: =BL21*BS1 -> 5654.7616 | BR21: =IF(BQ21>0,BQ21/BM21,0) -> #DIV/0! | BS21: =IF(BQ21>0,BQ21/BO21,0) -> #DIV/0!
A22: 17 | C22: =IF(+B22-B21>0,B22-B21,(B22-B21)>0)*800 -> 0 | E22: =IF(+D22-D21>0,D22-D21,(D22-D21)>0)*80 -> 0 | G22: =IF(+F22-F21>0,F22-F21,(F22-F21)>0)*10 -> 0 | H22: 64 | I22: 20935088 | J22: =IF(I22>=I21,I22-I21,0) -> 2538 | K22: =M22+O22 -> 967 | L22: 650171 | M22: =IF(L22>=L21,L22-L21,0) -> 552 | N22: 636579 | O22: =IF(N22>=N21,N22-N21,0) -> 415 | P22: 210704 | Q22: =IF(P22>=P21,P22-P21,0)*30 -> 120 | R22: 702925 | S22: =IF(R22>=R21,R22-R21,0) -> 0 | T22: 344001 | U22: =IF(T22>=T21,T22-T21,0) -> 0 | V22: 92015 | W22: =IF(V22>=V21,V22-V21,0) -> 131 | X22: 171046 | Y22: =IF(X22>=X21,X22-X21,0) -> 221 | Z22: 315108 | AA22: =IF(Z22>=Z21,Z22-Z21,0)*0.53 -> 0 | AB22: 671730 | AC22: =IF(AB22>=AB21,AB22-AB21,0)*0.53 -> 0 | AD22: 762245 | AE22: =IF(AD22>=AD21,AD22-AD21,0)*0.53 -> 2516.44 | AF22: 714945 | AG22: =IF(AF22>=AF21,AF22-AF21,0)*0.53 -> 857.54 | AH22: 207229 | AI22: =IF(AH22>=AH21,AH22-AH21,0)*0.53 -> 274.54 | AJ22: 295198 | AK22: =IF(AJ22>=AJ21,AJ22-AJ21,0)*0.53 -> 2166.64 | AL22: =AA22+AC22+AE22+AG22+AI22+AK22 -> 5815.16 | AM22: 6884330 | AN22: =IF(AM22>=AM21,AM22-AM21,0) -> 12 | AO22: 536189 | AP22: =IF(AO22>=AO21,AO22-AO21,0) -> 2 | AQ22: 881040 | AR22: =IF(AQ22>=AQ21,AQ22-AQ21,0)*0.11 -> 2.64 | AS22: 782007 | AT22: =IF(AS22>=AS21,AS22-AS21,0) -> 34 | AU22: 2156808 | AV22: =IF(AU22>=AU21,AU22-AU21,0) -> 348 | AW22: 195116 | AX22: =IF(AW22>=AW21,AW22-AW21,0) -> 0 | AY22: 16732117 | AZ22: =IF(AY22>=AY21,AY22-AY21,0) -> 1881 | BA22: 20268022 | BB22: =IF(BA22>=BA21,BA22-BA21,0)-(0.6*BG22)-(0.5*BI22)-BK22-BE22 -> 4227.5 | BC22: =AN22+AP22+AR22+AT22+AV22+AX22+AZ22+BB22 -> 6507.14 | BD22: 1323286 | BE22: =IF(BD22>=BD21,BD22-BD21,0) -> 0 | BF22: 3139046 | BG22: =IF(BF22>=BF21,BF22-BF21,0) -> 1380 | BH22: 348112 | BI22: =IF(BH22>=BH21,BH22-BH21,0) -> 83 | BJ22: 397306 | BK22: =IF(BJ22>=BJ21,BJ22-BJ21,0) -> 175 | BL22: =J22+Q22+AL22+BC22 -> 14980.3 | BN22: =IF(BL22>0,BL22/BM22,0) -> #DIV/0! | BP22: =IF(BL22>0,BL22/BO22,0) -> #DIV/0! | BQ22: =BL22*BS1 -> 6890.938 | BR22: =IF(BQ22>0,BQ22/BM22,0) -> #DIV/0! | BS22: =IF(BQ22>0,BQ22/BO22,0) -> #DIV/0!
A23: 18 | C23: =IF(+B23-B22>0,B23-B22,(B23-B22)>0)*800 -> 0 | E23: =IF(+D23-D22>0,D23-D22,(D23-D22)>0)*80 -> 0 | G23: =IF(+F23-F22>0,F23-F22,(F23-F22)>0)*10 -> 0 | I23: 20936488 | J23: =IF(I23>=I22,I23-I22,0) -> 1400 | K23: =M23+O23 -> 1300 | L23: 650871 | M23: =IF(L23>=L22,L23-L22,0) -> 700 | N23: 637179 | O23: =IF(N23>=N22,N23-N22,0) -> 600 | P23: 210707 | Q23: =IF(P23>=P22,P23-P22,0)*30 -> 90 | R23: 702925 | S23: =IF(R23>=R22,R23-R22,0) -> 0 | T23: 344001 | U23: =IF(T23>=T22,T23-T22,0) -> 0 | V23: 92148 | W23: =IF(V23>=V22,V23-V22,0) -> 133 | X23: 171246 | Y23: =IF(X23>=X22,X23-X22,0) -> 200 | Z23: 315108 | AA23: =IF(Z23>=Z22,Z23-Z22,0)*0.53 -> 0 | AB23: 671730 | AC23: =IF(AB23>=AB22,AB23-AB22,0)*0.53 -> 0 | AD23: 762245 | AE23: =IF(AD23>=AD22,AD23-AD22,0)*0.53 -> 0 | AF23: 714945 | AG23: =IF(AF23>=AF22,AF23-AF22,0)*0.53 -> 0 | AH23: 207829 | AI23: =IF(AH23>=AH22,AH23-AH22,0)*0.53 -> 318 | AJ23: 298598 | AK23: =IF(AJ23>=AJ22,AJ23-AJ22,0)*0.53 -> 1802 | AL23: =AA23+AC23+AE23+AG23+AI23+AK23 -> 2120 | AM23: 6884338 | AN23: =IF(AM23>=AM22,AM23-AM22,0) -> 8 | AO23: 536191 | AP23: =IF(AO23>=AO22,AO23-AO22,0) -> 2 | AQ23: 881091 | AR23: =IF(AQ23>=AQ22,AQ23-AQ22,0)*0.11 -> 5.61 | AS23: 782037 | AT23: =IF(AS23>=AS22,AS23-AS22,0) -> 30 | AU23: 2157068 | AV23: =IF(AU23>=AU22,AU23-AU22,0) -> 260 | AW23: 195116 | AX23: =IF(AW23>=AW22,AW23-AW22,0) -> 0 | AY23: 16733717 | AZ23: =IF(AY23>=AY22,AY23-AY22,0) -> 1600 | BA23: 20271022 | BB23: =IF(BA23>=BA22,BA23-BA22,0)-(0.6*BG23)-(0.5*BI23)-BK23-BE23 -> 2285 | BC23: =AN23+AP23+AR23+AT23+AV23+AX23+AZ23+BB23 -> 4190.61 | BD23: 1323286 | BE23: =IF(BD23>=BD22,BD23-BD22,0) -> 0 | BF23: 3139846 | BG23: =IF(BF23>=BF22,BF23-BF22,0) -> 800 | BH23: 348182 | BI23: =IF(BH23>=BH22,BH23-BH22,0) -> 70 | BJ23: 397506 | BK23: =IF(BJ23>=BJ22,BJ23-BJ22,0) -> 200 | BL23: =J23+Q23+AL23+BC23 -> 7800.61 | BN23: =IF(BL23>0,BL23/BM23,0) -> #DIV/0! | BP23: =IF(BL23>0,BL23/BO23,0) -> #DIV/0! | BQ23: =BL23*BS1 -> 3588.2806 | BR23: =IF(BQ23>0,BQ23/BM23,0) -> #DIV/0! | BS23: =IF(BQ23>0,BQ23/BO23,0) -> #DIV/0!
A24: 19 | C24: =IF(+B24-B23>0,B24-B23,(B24-B23)>0)*800 -> 0 | E24: =IF(+D24-D23>0,D24-D23,(D24-D23)>0)*80 -> 0 | G24: =IF(+F24-F23>0,F24-F23,(F24-F23)>0)*10 -> 0 | H24: 65 | I24: 20938357 | J24: =IF(I24>=I23,I24-I23,0) -> 1869 | K24: =M24+O24 -> 1475 | L24: 651613 | M24: =IF(L24>=L23,L24-L23,0) -> 742 | N24: 637912 | O24: =IF(N24>=N23,N24-N23,0) -> 733 | P24: 210710 | Q24: =IF(P24>=P23,P24-P23,0)*30 -> 90 | R24: 702925 | S24: =IF(R24>=R23,R24-R23,0) -> 0 | T24: 344001 | U24: =IF(T24>=T23,T24-T23,0) -> 0 | V24: 92270 | W24: =IF(V24>=V23,V24-V23,0) -> 122 | X24: 171447 | Y24: =IF(X24>=X23,X24-X23,0) -> 201 | Z24: 315108 | AA24: =IF(Z24>=Z23,Z24-Z23,0)*0.53 -> 0 | AB24: 671730 | AC24: =IF(AB24>=AB23,AB24-AB23,0)*0.53 -> 0 | AD24: 767090 | AE24: =IF(AD24>=AD23,AD24-AD23,0)*0.53 -> 2567.85 | AF24: 714945 | AG24: =IF(AF24>=AF23,AF24-AF23,0)*0.53 -> 0 | AH24: 208707 | AI24: =IF(AH24>=AH23,AH24-AH23,0)*0.53 -> 465.34 | AJ24: 303488 | AK24: =IF(AJ24>=AJ23,AJ24-AJ23,0)*0.53 -> 2591.7 | AL24: =AA24+AC24+AE24+AG24+AI24+AK24 -> 5624.89 | AM24: 6884359 | AN24: =IF(AM24>=AM23,AM24-AM23,0) -> 21 | AO24: 536194 | AP24: =IF(AO24>=AO23,AO24-AO23,0) -> 3 | AQ24: 881128 | AR24: =IF(AQ24>=AQ23,AQ24-AQ23,0)*0.11 -> 4.07 | AS24: 782069 | AT24: =IF(AS24>=AS23,AS24-AS23,0) -> 32 | AU24: 2157447 | AV24: =IF(AU24>=AU23,AU24-AU23,0) -> 379 | AW24: 195116 | AX24: =IF(AW24>=AW23,AW24-AW23,0) -> 0 | AY24: 16735590 | AZ24: =IF(AY24>=AY23,AY24-AY23,0) -> 1873 | BA24: 20275231 | BB24: =IF(BA24>=BA23,BA24-BA23,0)-(0.6*BG24)-(0.5*BI24)-BK24-BE24 -> 3299.8 | BC24: =AN24+AP24+AR24+AT24+AV24+AX24+AZ24+BB24 -> 5611.87 | BD24: 1323286 | BE24: =IF(BD24>=BD23,BD24-BD23,0) -> 0 | BF24: 3140983 | BG24: =IF(BF24>=BF23,BF24-BF23,0) -> 1137 | BH24: 348256 | BI24: =IF(BH24>=BH23,BH24-BH23,0) -> 74 | BJ24: 397696 | BK24: =IF(BJ24>=BJ23,BJ24-BJ23,0) -> 190 | BL24: =J24+Q24+AL24+BC24 -> 13195.76 | BN24: =IF(BL24>0,BL24/BM24,0) -> #DIV/0! | BP24: =IF(BL24>0,BL24/BO24,0) -> #DIV/0! | BQ24: =BL24*BS1 -> 6070.0496 | BR24: =IF(BQ24>0,BQ24/BM24,0) -> #DIV/0! | BS24: =IF(BQ24>0,BQ24/BO24,0) -> #DIV/0!
A25: 20 | C25: =IF(+B25-B24>0,B25-B24,(B25-B24)>0)*800 -> 0 | E25: =IF(+D25-D24>0,D25-D24,(D25-D24)>0)*80 -> 0 | G25: =IF(+F25-F24>0,F25-F24,(F25-F24)>0)*10 -> 0 | I25: 20940346 | J25: =IF(I25>=I24,I25-I24,0) -> 1989 | K25: =M25+O25 -> 1026 | L25: 652121 | M25: =IF(L25>=L24,L25-L24,0) -> 508 | N25: 638430 | O25: =IF(N25>=N24,N25-N24,0) -> 518 | P25: 210713 | Q25: =IF(P25>=P24,P25-P24,0)*30 -> 90 | R25: 702925 | S25: =IF(R25>=R24,R25-R24,0) -> 0 | T25: 344001 | U25: =IF(T25>=T24,T25-T24,0) -> 0 | V25: 92414 | W25: =IF(V25>=V24,V25-V24,0) -> 144 | X25: 171682 | Y25: =IF(X25>=X24,X25-X24,0) -> 235 | Z25: 315108 | AA25: =IF(Z25>=Z24,Z25-Z24,0)*0.53 -> 0 | AB25: 671730 | AC25: =IF(AB25>=AB24,AB25-AB24,0)*0.53 -> 0 | AD25: 769991 | AE25: =IF(AD25>=AD24,AD25-AD24,0)*0.53 -> 1537.53 | AF25: 714945 | AG25: =IF(AF25>=AF24,AF25-AF24,0)*0.53 -> 0 | AH25: 209138 | AI25: =IF(AH25>=AH24,AH25-AH24,0)*0.53 -> 228.43 | AJ25: 306312 | AK25: =IF(AJ25>=AJ24,AJ25-AJ24,0)*0.53 -> 1496.72 | AL25: =AA25+AC25+AE25+AG25+AI25+AK25 -> 3262.68 | AM25: 6884369 | AN25: =IF(AM25>=AM24,AM25-AM24,0) -> 10 | AO25: 536195 | AP25: =IF(AO25>=AO24,AO25-AO24,0) -> 1 | AQ25: 881169 | AR25: =IF(AQ25>=AQ24,AQ25-AQ24,0)*0.11 -> 4.51 | AS25: 782093 | AT25: =IF(AS25>=AS24,AS25-AS24,0) -> 24 | AU25: 2157709 | AV25: =IF(AU25>=AU24,AU25-AU24,0) -> 262 | AW25: 195116 | AX25: =IF(AW25>=AW24,AW25-AW24,0) -> 0 | AY25: 16736982 | AZ25: =IF(AY25>=AY24,AY25-AY24,0) -> 1392 | BA25: 20279667 | BB25: =IF(BA25>=BA24,BA25-BA24,0)-(0.6*BG25)-(0.5*BI25)-BK25-BE25 -> 3465.4 | BC25: =AN25+AP25+AR25+AT25+AV25+AX25+AZ25+BB25 -> 5158.91 | BD25: 1323286 | BE25: =IF(BD25>=BD24,BD25-BD24,0) -> 0 | BF25: 3142189 | BG25: =IF(BF25>=BF24,BF25-BF24,0) -> 1206 | BH25: 348340 | BI25: =IF(BH25>=BH24,BH25-BH24,0) -> 84 | BJ25: 397901 | BK25: =IF(BJ25>=BJ24,BJ25-BJ24,0) -> 205 | BL25: =J25+Q25+AL25+BC25 -> 10500.59 | BN25: =IF(BL25>0,BL25/BM25,0) -> #DIV/0! | BP25: =IF(BL25>0,BL25/BO25,0) -> #DIV/0! | BQ25: =BL25*BS1 -> 4830.2714 | BR25: =IF(BQ25>0,BQ25/BM25,0) -> #DIV/0! | BS25: =IF(BQ25>0,BQ25/BO25,0) -> #DIV/0!
