Workbook

Sheet Total
A1: Site Name | B1: Day | C1: Month | D1: Year | E1: Total Electricity Kwh | F1: Electricity Tariff ($/Kwh) | G1: Total Fuel Oil (Liters) | H1: Fuel Oil $/Liter | I1: LPG (Kg) | J1: LPG $/Kg | K1: Water Utility Supply (m3) m3 | L1: Water Utility Supply (m3) $/m3 | M1: Irrigation Water (m3) m3 | N1: Irrigation water $/m3 | O1: Room Nights
A2: Beirut | B2: 1 | C2: 6 | D2: 2020 | E2: =ELEC!N3 -> 14293 | F2: =SUM('EDl log'!T4) -> 0.054260995 | G2: =-tanks!AW6 -> 452 | H2: =SUM(tanks!AV6) -> 0.1 | I2: =('B5'!AU5)*0.51 -> 91.8 | J2: ='B5'!AX5/0.51 -> 1.372549 | K2: =WATER!I6 -> 11 | L2: =SUM(WATER!J6) -> 22.727273 | M2: =WATER!Q6 -> 0 | N2: 0.6 | O2: =ELEC!B3 -> 4.991
A3: Beirut | B3: =B2+1 -> 2 | C3: 6 | D3: 2020 | E3: =ELEC!N4 -> 13728 | F3: =SUM('EDl log'!T5) -> 0.049559789 | G3: =-tanks!AW7 -> 296 | H3: =SUM(tanks!AV7) -> 0.1 | I3: =('B5'!AU6)*0.51 -> 45.9 | J3: ='B5'!AX6/0.51 -> 1.372549 | K3: =WATER!I7 -> 0 | L3: =SUM(WATER!J7) -> 0 | M3: =WATER!Q7 -> 0 | N3: 0.6 | O3: =ELEC!B4 -> 2.001
A4: Beirut | B4: =B3+1 -> 3 | C4: 6 | D4: 2020 | E4: =ELEC!N5 -> 14416 | F4: =SUM('EDl log'!T6) -> 0.062091019 | G4: =-tanks!AW8 -> 370.6 | H4: =SUM(tanks!AV8) -> 0.1 | I4: =('B5'!AU7)*0.51 -> 61.2 | J4: ='B5'!AX7/0.51 -> 1.372549 | K4: =WATER!I8 -> 0 | L4: =SUM(WATER!J8) -> 0 | M4: =WATER!Q8 -> 0 | N4: 0.6 | O4: =ELEC!B5 -> 6.003
A5: Beirut | B5: =B4+1 -> 4 | C5: 6 | D5: 2020 | E5: =ELEC!N6 -> 12453 | F5: =SUM('EDl log'!T7) -> 0.023042264 | G5: =-tanks!AW9 -> 628 | H5: =SUM(tanks!AV9) -> 0.34 | I5: =('B5'!AU8)*0.51 -> 178.5 | J5: ='B5'!AX8/0.51 -> 1.372549 | K5: =WATER!I9 -> 172 | L5: =SUM(WATER!J9) -> 1.4534884 | M5: =WATER!Q9 -> 0 | N5: 0.6 | O5: =ELEC!B6 -> 4.991
A6: Beirut | B6: =B5+1 -> 5 | C6: 6 | D6: 2020 | E6: =ELEC!N7 -> 13633 | F6: =SUM('EDl log'!T8) -> 0.056452537 | G6: =-tanks!AW10 -> 334 | H6: =SUM(tanks!AV10) -> 0.34 | I6: =('B5'!AU9)*0.51 -> 45.9 | J6: ='B5'!AX9/0.51 -> 1.372549 | K6: =WATER!I10 -> 0 | L6: =SUM(WATER!J10) -> 0 | M6: =WATER!Q10 -> 0 | N6: 0.6 | O6: =ELEC!B7 -> 2.99
A7: Beirut | B7: =B6+1 -> 6 | C7: 6 | D7: 2020 | E7: =ELEC!N8 -> 13778 | F7: =SUM('EDl log'!T9) -> 0.052170616 | G7: =-tanks!AW11 -> 391 | H7: =SUM(tanks!AV11) -> 0.34 | I7: =('B5'!AU10)*0.51 -> 30.6 | J7: ='B5'!AX10/0.51 -> 1.372549 | K7: =WATER!I11 -> 0 | L7: =SUM(WATER!J11) -> 0 | M7: =WATER!Q11 -> 0 | N7: 0.6 | O7: =ELEC!B8 -> 4.991
A8: Beirut | B8: =B7+1 -> 7 | C8: 6 | D8: 2020 | E8: =ELEC!N9 -> 16205 | F8: =SUM('EDl log'!T10) -> 0.057106013 | G8: =-tanks!AW12 -> 363 | H8: =SUM(tanks!AV12) -> 0.34 | I8: =('B5'!AU11)*0.51 -> 30.6 | J8: ='B5'!AX11/0.51 -> 1.372549 | K8: =WATER!I12 -> 0 | L8: =SUM(WATER!J12) -> 0 | M8: =WATER!Q12 -> 0 | N8: 0.6 | O8: =ELEC!B9 -> 4.002
A9: Beirut | B9: =B8+1 -> 8 | C9: 6 | D9: 2020 | E9: =ELEC!N10 -> 15745 | F9: =SUM('EDl log'!T11) -> 0.051575925 | G9: =-tanks!AW13 -> 360 | H9: =SUM(tanks!AV13) -> 0.34 | I9: =('B5'!AU12)*0.51 -> 45.9 | J9: ='B5'!AX12/0.51 -> 1.372549 | K9: =WATER!I13 -> 72 | L9: =SUM(WATER!J13) -> 3.4722222 | M9: =WATER!Q13 -> 0 | N9: 0.6 | O9: =ELEC!B10 -> 2.99
A10: Beirut | B10: =B9+1 -> 9 | C10: 6 | D10: 2020 | E10: =ELEC!N11 -> 15283 | F10: =SUM('EDl log'!T12) -> 0.055774284 | G10: =-tanks!AW14 -> 282 | H10: =SUM(tanks!AV14) -> 0.34 | I10: =('B5'!AU13)*0.51 -> 76.5 | J10: ='B5'!AX13/0.51 -> 1.372549 | K10: =WATER!I14 -> 0 | L10: =SUM(WATER!J14) -> 0 | M10: =WATER!Q14 -> 0 | N10: 0.6 | O10: =ELEC!B11 -> 4.002
A11: Beirut | B11: =B10+1 -> 10 | C11: 6 | D11: 2020 | E11: =ELEC!N12 -> 16634 | F11: =SUM('EDl log'!T13) -> 0.053380422 | G11: =-tanks!AW15 -> 600.4 | H11: =SUM(tanks!AV15) -> 0.34 | I11: =('B5'!AU14)*0.51 -> 76.5 | J11: ='B5'!AX14/0.51 -> 1.372549 | K11: =WATER!I15 -> 400 | L11: =SUM(WATER!J15) -> 0.625 | M11: =WATER!Q15 -> 0 | N11: 0.6 | O11: =ELEC!B12 -> 4.002
A12: Beirut | B12: =B11+1 -> 11 | C12: 6 | D12: 2020 | E12: =ELEC!N13 -> 14437 | F12: =SUM('EDl log'!T14) -> 0.070254456 | G12: =-tanks!AW16 -> 368.1 | H12: =SUM(tanks!AV16) -> 0.34 | I12: =('B5'!AU15)*0.51 -> 91.8 | J12: ='B5'!AX15/0.51 -> 1.372549 | K12: =WATER!I16 -> 0 | L12: =SUM(WATER!J16) -> 0 | M12: =WATER!Q16 -> 0 | N12: 0.6 | O12: =ELEC!B13 -> 2.99
A13: Beirut | B13: =B12+1 -> 12 | C13: 6 | D13: 2020 | E13: =ELEC!N14 -> 0 | F13: =SUM('EDl log'!T15) -> 0 | G13: =-tanks!AW17 -> 0 | H13: =SUM(tanks!AV17) -> 0.34 | I13: =('B5'!AU16)*0.51 -> 0 | J13: ='B5'!AX16/0.51 -> 1.372549 | K13: =WATER!I17 -> 0 | L13: =SUM(WATER!J17) -> 0 | M13: =WATER!Q17 -> 0 | N13: 0.6 | O13: =ELEC!B14 -> 0
A14: Beirut | B14: =B13+1 -> 13 | C14: 6 | D14: 2020 | E14: =ELEC!N15 -> 0 | F14: =SUM('EDl log'!T16) -> 0 | G14: =-tanks!AW18 -> 0 | H14: =SUM(tanks!AV18) -> 0.34 | I14: =('B5'!AU17)*0.51 -> 0 | J14: ='B5'!AX17/0.51 -> 1.372549 | K14: =WATER!I18 -> 0 | L14: =SUM(WATER!J18) -> 0 | M14: =WATER!Q18 -> 0 | N14: 0.6 | O14: =ELEC!B15 -> 0
... A31: Beirut | B31: =B30+1 -> 30 | C31: 6 | D31: 2020 | E31: =ELEC!N32 -> 0 | F31: =SUM('EDl log'!T33) -> 0 | G31: =-tanks!AW35 -> 0 | H31: =SUM(tanks!AV35) -> 0.34 | I31: =('B5'!AU34)*0.51 -> 0 | J31: ='B5'!AX34/0.51 -> 1.372549 | K31: =WATER!I35 -> 0 | L31: =SUM(WATER!J35) -> 0 | M31: =WATER!Q35 -> 0 | N31: 0.6 | O31: =ELEC!B32 -> 0

Sheet Submetering
A1: Site Name | B1: Day | C1: Month | D1: Year | E1: ATS1 Kwh | F1: ATS2 Kwh | G1: ATS3 Kwh | H1: ATS4 Kwh | I1: ATS5 Kwh | J1: Guest (m3) | K1: Kitchen & Laundry (m3) | L1: Room Nights
A2: Beirut | B2: 1 | C2: 6 | D2: 2020 | E2: =ELEC!M3 -> 5278 | F2: =ELEC!K3 -> 2192 | G2: =ELEC!I3 -> 1830 | H2: =ELEC!E3 -> 3460 | I2: =ELEC!G3 -> 1533 | J2: =WATER!Y6 -> 0 | K2: =WATER!AJ6 -> 0 | L2: =ELEC!B3 -> 4.991
A3: Beirut | B3: =B2+1 -> 2 | C3: 6 | D3: 2020 | E3: =ELEC!M4 -> 5374 | F3: =ELEC!K4 -> 2326 | G3: =ELEC!I4 -> 1596 | H3: =ELEC!E4 -> 3082 | I3: =ELEC!G4 -> 1350 | J3: =WATER!Y7 -> 0 | K3: =WATER!AJ7 -> 0 | L3: =ELEC!B4 -> 2.001
A4: Beirut | B4: =B3+1 -> 3 | C4: 6 | D4: 2020 | E4: =ELEC!M5 -> 3912 | F4: =ELEC!K5 -> 2394 | G4: =ELEC!I5 -> 1642 | H4: =ELEC!E5 -> 5024 | I4: =ELEC!G5 -> 1444 | J4: =WATER!Y8 -> 0 | K4: =WATER!AJ8 -> 0 | L4: =ELEC!B5 -> 6.003
A5: Beirut | B5: =B4+1 -> 4 | C5: 6 | D5: 2020 | E5: =ELEC!M6 -> 4642 | F5: =ELEC!K6 -> 2140 | G5: =ELEC!I6 -> 1582 | H5: =ELEC!E6 -> 2568 | I5: =ELEC!G6 -> 1521 | J5: =WATER!Y9 -> 30 | K5: =WATER!AJ9 -> 44 | L5: =ELEC!B6 -> 4.991
A6: Beirut | B6: =B5+1 -> 5 | C6: 6 | D6: 2020 | E6: =ELEC!M7 -> 5086 | F6: =ELEC!K7 -> 2000 | G6: =ELEC!I7 -> 1906 | H6: =ELEC!E7 -> 2948 | I6: =ELEC!G7 -> 1693 | J6: =WATER!Y10 -> 0 | K6: =WATER!AJ10 -> 33 | L6: =ELEC!B7 -> 2.99
A7: Beirut | B7: =B6+1 -> 6 | C7: 6 | D7: 2020 | E7: =ELEC!M8 -> 4466 | F7: =ELEC!K8 -> 2156 | G7: =ELEC!I8 -> 1690 | H7: =ELEC!E8 -> 3890 | I7: =ELEC!G8 -> 1576 | J7: =WATER!Y11 -> 0 | K7: =WATER!AJ11 -> 0 | L7: =ELEC!B8 -> 4.991
A8: Beirut | B8: =B7+1 -> 7 | C8: 6 | D8: 2020 | E8: =ELEC!M9 -> 4834 | F8: =ELEC!K9 -> 2572 | G8: =ELEC!I9 -> 1810 | H8: =ELEC!E9 -> 5210 | I8: =ELEC!G9 -> 1779 | J8: =WATER!Y12 -> 0 | K8: =WATER!AJ12 -> 0 | L8: =ELEC!B9 -> 4.002
A9: Beirut | B9: =B8+1 -> 8 | C9: 6 | D9: 2020 | E9: =ELEC!M10 -> 6270 | F9: =ELEC!K10 -> 2636 | G9: =ELEC!I10 -> 1756 | H9: =ELEC!E10 -> 3342 | I9: =ELEC!G10 -> 1741 | J9: =WATER!Y13 -> 3 | K9: =WATER!AJ13 -> 0 | L9: =ELEC!B10 -> 2.99
A10: Beirut | B10: =B9+1 -> 9 | C10: 6 | D10: 2020 | E10: =ELEC!M11 -> 4206 | F10: =ELEC!K11 -> 2540 | G10: =ELEC!I11 -> 1692 | H10: =ELEC!E11 -> 5186 | I10: =ELEC!G11 -> 1659 | J10: =WATER!Y14 -> 77 | K10: =WATER!AJ14 -> 46 | L10: =ELEC!B11 -> 4.002
A11: Beirut | B11: =B10+1 -> 10 | C11: 6 | D11: 2020 | E11: =ELEC!M12 -> 6604 | F11: =ELEC!K12 -> 2836 | G11: =ELEC!I12 -> 1750 | H11: =ELEC!E12 -> 3796 | I11: =ELEC!G12 -> 1648 | J11: =WATER!Y15 -> 46 | K11: =WATER!AJ15 -> 71 | L11: =ELEC!B12 -> 4.002
A12: Beirut | B12: =B11+1 -> 11 | C12: 6 | D12: 2020 | E12: =ELEC!M13 -> 5816 | F12: =ELEC!K13 -> 2328 | G12: =ELEC!I13 -> 1632 | H12: =ELEC!E13 -> 2998 | I12: =ELEC!G13 -> 1663 | J12: =WATER!Y16 -> 44 | K12: =WATER!AJ16 -> 19 | L12: =ELEC!B13 -> 2.99
A13: Beirut | B13: =B12+1 -> 12 | C13: 6 | D13: 2020 | E13: =ELEC!M14 -> 0 | F13: =ELEC!K14 -> 0 | G13: =ELEC!I14 -> 0 | H13: =ELEC!E14 -> 0 | I13: =ELEC!G14 -> 0 | J13: =WATER!Y17 -> 0 | K13: =WATER!AJ17 -> 0 | L13: =ELEC!B14 -> 0
A14: Beirut | B14: =B13+1 -> 13 | C14: 6 | D14: 2020 | E14: =ELEC!M15 -> 0 | F14: =ELEC!K15 -> 0 | G14: =ELEC!I15 -> 0 | H14: =ELEC!E15 -> 0 | I14: =ELEC!G15 -> 0 | J14: =WATER!Y18 -> 0 | K14: =WATER!AJ18 -> 0 | L14: =ELEC!B15 -> 0
... A31: Beirut | B31: =B30+1 -> 30 | C31: 6 | D31: 2020 | E31: =ELEC!M32 -> 0 | F31: =ELEC!K32 -> 0 | G31: =ELEC!I32 -> 0 | H31: =ELEC!E32 -> 0 | I31: =ELEC!G32 -> 0 | J31: =WATER!Y35 -> 0 | K31: =WATER!AJ35 -> 0 | L31: =ELEC!B32 -> 0

Sheet ELEC
A1: OOC | B1: Room OCC | D1: MDB3 | E1: MDB3/day | F1: EMDB2 | G1: EMDB2/day | H1: EMDB1 | I1: EMDB1/day | J1: MDB2 | K1: mdb2/day | L1: MDB1 | M1: MDB1/Day | N1: Total KWH | O1: KWH/Rooc | P1: Gen MHW | Q1: Gen/Day KWH | R1: EDL KWH | S1: CH1 RH | T1: RH | U1: C1h1 power | V1: CH1 Con KWH | W1: CH2 RH | X1: RH | Y1: Ch2 power | Z1: CH2 Con KWH | AA1: CH3 RH | AB1: RH | AC1: Ch3 power | AD1: CH3 Con KWH | AE1: RH total | AF1: KWH total | AG1: AVG chiller KW/Hr
A2: =[1]ELEC!A32 -> 0.013 | B2: 0.0299 | C2: 43982 | D2: =[2]ELEC!D33 -> 31738156 | E2: =[2]ELEC!E33 -> 3210 | F2: =[2]ELEC!F33 -> 3692449 | G2: =[2]ELEC!G33 -> 1387 | H2: =[2]ELEC!H33 -> 17470270 | I2: =[2]ELEC!I33 -> 1740 | J2: =[2]ELEC!J33 -> 28449698 | K2: =[2]ELEC!K33 -> 2176 | ... AI2: =[2]ELEC!AI33 -> -49957087
A3: ='General information '!F6 -> 0.0217 | B3: =SUM(230*A3) -> 4.991 | C3: 43983 | D3: 31741616 | E3: =D3-D2 -> 3460 | F3: 3693982 | G3: =F3-F2 -> 1533 | H3: 17472100 | I3: =H3-H2 -> 1830 | J3: 28451890 | K3: =J3-J2 -> 2192 | L3: 23072552 | M3: =L3-L2 -> 5278 | N3: =M3+K3+I3+G3+E3 -> 14293 | O3: =IF(B3>0,N3/B3,0) -> 2863.7548 | P3: 15549 | Q3: =(P3-P2)*1000 -> 2000 | R3: =+N3-Q3 -> 12293 | S3: 8609 | T3: =S3-S2 -> 20 | U3: 75398 | V3: =U3-U2 -> 2206 | W3: 31853 | X3: =W3-W2 -> 0 | Y3: 625865 | Z3: =Y3-Y2 -> 0 | AA3: 35119 | AB3: =AA3-AA2 -> 0 | AC3: 790452 | AD3: =AC3-AC2 -> 0 | AE3: =AB3+X3+T3 -> 20 | AF3: =V3+Z3+AD3 -> 2206 | AG3: =IF(AE3>0,AF3/AE3,0) -> 110.3
A4: ='General information '!F7 -> 0.0087 | B4: =SUM(230*A4) -> 2.001 | C4: 43984 | D4: 31744698 | E4: =D4-D3 -> 3082 | F4: 3695332 | G4: =F4-F3 -> 1350 | H4: 17473696 | I4: =H4-H3 -> 1596 | J4: 28454216 | K4: =J4-J3 -> 2326 | L4: 23077926 | M4: =L4-L3 -> 5374 | N4: =M4+K4+I4+G4+E4 -> 13728 | O4: =IF(B4>0,N4/B4,0) -> 6860.5697 | P4: 15551 | Q4: =(P4-P3)*1000 -> 2000 | R4: =N4-Q4 -> 11728 | S4: 8620 | T4: =S4-S3 -> 11 | U4: 77802 | V4: =U4-U3 -> 2404 | W4: =W3 -> 31853 | X4: =W4-W3 -> 0 | Y4: =Y3 -> 625865 | Z4: =Y4-Y3 -> 0 | AA4: =AA3 -> 35119 | AB4: =AA4-AA3 -> 0 | AC4: =AC3 -> 790452 | AD4: =AC4-AC3 -> 0 | AE4: =AB4+X4+T4 -> 11 | AF4: =V4+Z4+AD4 -> 2404 | AG4: =IF(AE4>0,AF4/AE4,0) -> 218.54545
A5: ='General information '!F8 -> 0.0261 | B5: =SUM(230*A5) -> 6.003 | C5: 43985 | D5: 31749722 | E5: =D5-D4 -> 5024 | F5: 3696776 | G5: =F5-F4 -> 1444 | H5: 17475338 | I5: =H5-H4 -> 1642 | J5: 28456610 | K5: =J5-J4 -> 2394 | L5: 23081838 | M5: =L5-L4 -> 3912 | N5: =M5+K5+I5+G5+E5 -> 14416 | O5: =IF(B5>0,N5/B5,0) -> 2401.4659 | P5: 15553 | Q5: =(P5-P4)*1000 -> 2000 | R5: =N5-Q5 -> 12416 | S5: 8625 | T5: =S5-S4 -> 5 | U5: 78590 | V5: =U5-U4 -> 788 | W5: =W4 -> 31853 | X5: =W5-W4 -> 0 | Y5: =Y4 -> 625865 | Z5: =Y5-Y4 -> 0 | AA5: 35126 | AB5: =AA5-AA4 -> 7 | AC5: 791862 | AD5: =AC5-AC4 -> 1410 | AE5: =AB5+X5+T5 -> 12 | AF5: =V5+Z5+AD5 -> 2198 | AG5: =IF(AE5>0,AF5/AE5,0) -> 183.16667 | AI5: =R5-'EDl log'!B3 -> -49976236
A6: ='General information '!F9 -> 0.0217 | B6: =SUM(230*A6) -> 4.991 | C6: 43986 | D6: 31752290 | E6: =D6-D5 -> 2568 | F6: 3698297 | G6: =F6-F5 -> 1521 | H6: 17476920 | I6: =H6-H5 -> 1582 | J6: 28458750 | K6: =J6-J5 -> 2140 | L6: 23086480 | M6: =L6-L5 -> 4642 | N6: =M6+K6+I6+G6+E6 -> 12453 | O6: =IF(B6>0,N6/B6,0) -> 2495.0912 | P6: 15555 | Q6: =(P6-P5)*1000 -> 2000 | R6: =N6-Q6 -> 10453 | S6: 8632 | T6: =S6-S5 -> 7 | U6: 80356 | V6: =U6-U5 -> 1766 | W6: =W5 -> 31853 | X6: =W6-W5 -> 0 | Y6: =Y5 -> 625865 | Z6: =Y6-Y5 -> 0 | AA6: 35127 | AB6: =AA6-AA5 -> 1 | AC6: 792067 | AD6: =AC6-AC5 -> 205 | AE6: =AB6+X6+T6 -> 8 | AF6: =V6+Z6+AD6 -> 1971 | AG6: =IF(AE6>0,AF6/AE6,0) -> 246.375 | AI6: =R6-'EDl log'!B4 -> -49984599
A7: ='General information '!F10 -> 0.013 | B7: =SUM(230*A7) -> 2.99 | C7: 43987 | D7: 31755238 | E7: =D7-D6 -> 2948 | F7: 3699990 | G7: =F7-F6 -> 1693 | H7: 17478826 | I7: =H7-H6 -> 1906 | J7: 28460750 | K7: =J7-J6 -> 2000 | L7: 23091566 | M7: =L7-L6 -> 5086 | N7: =M7+K7+I7+G7+E7 -> 13633 | O7: =IF(B7>0,N7/B7,0) -> 4559.5318 | P7: 15557 | Q7: =(P7-P6)*1000 -> 2000 | R7: =N7-Q7 -> 11633 | S7: 8639 | T7: =S7-S6 -> 7 | U7: 81962 | V7: =U7-U6 -> 1606 | W7: =W6 -> 31853 | X7: =W7-W6 -> 0 | Y7: =Y6 -> 625865 | Z7: =Y7-Y6 -> 0 | AA7: =AA6 -> 35127 | AB7: 0 | AC7: =AC6 -> 792067 | AD7: =AC7-AC6 -> 0 | AE7: =AB7+X7+T7 -> 7 | AF7: =V7+Z7+AD7 -> 1606 | AG7: =IF(AE7>0,AF7/AE7,0) -> 229.42857 | AI7: =R7-'EDl log'!B5 -> -49989529
A8: ='General information '!F11 -> 0.0217 | B8: =SUM(230*A8) -> 4.991 | C8: 43988 | D8: 31759128 | E8: =D8-D7 -> 3890 | F8: 3701566 | G8: =F8-F7 -> 1576 | H8: 17480516 | I8: =H8-H7 -> 1690 | J8: 28462906 | K8: =J8-J7 -> 2156 | L8: 23096032 | M8: =L8-L7 -> 4466 | N8: =M8+K8+I8+G8+E8 -> 13778 | O8: =IF(B8>0,N8/B8,0) -> 2760.569 | P8: 15559 | Q8: =(P8-P7)*1000 -> 2000 | R8: =N8-Q8 -> 11778 | S8: 8644 | T8: =S8-S7 -> 5 | U8: 83336 | V8: =U8-U7 -> 1374 | W8: =W7 -> 31853 | X8: =W8-W7 -> 0 | Y8: =Y7 -> 625865 | Z8: =Y8-Y7 -> 0 | AA8: 35130 | AB8: =AA8-AA7 -> 3 | AC8: 792883 | AD8: =AC8-AC7 -> 816 | AE8: =AB8+X8+T8 -> 8 | AF8: =V8+Z8+AD8 -> 2190 | AG8: =IF(AE8>0,AF8/AE8,0) -> 273.75 | AI8: =R8-'EDl log'!B6 -> -49995898
A9: ='General information '!F12 -> 0.0174 | B9: =SUM(230*A9) -> 4.002 | C9: 43989 | D9: 31764338 | E9: =D9-D8 -> 5210 | F9: 3703345 | G9: =F9-F8 -> 1779 | H9: 17482326 | I9: =H9-H8 -> 1810 | J9: 28465478 | K9: =J9-J8 -> 2572 | L9: 23100866 | M9: =L9-L8 -> 4834 | N9: =M9+K9+I9+G9+E9 -> 16205 | O9: =IF(B9>0,N9/B9,0) -> 4049.2254 | P9: 15561 | Q9: =(P9-P8)*1000 -> 2000 | R9: =N9-Q9 -> 14205 | S9: 8650 | T9: =S9-S8 -> 6 | U9: 84790 | V9: =U9-U8 -> 1454 | W9: 31853 | X9: =W9-W8 -> 0 | Y9: =Y8 -> 625865 | Z9: =Y9-Y8 -> 0 | AA9: 35137 | AB9: =AA9-AA8 -> 7 | AC9: 794338 | AD9: =AC9-AC8 -> 1455 | AE9: =AB9+X9+T9 -> 13 | AF9: =V9+Z9+AD9 -> 2909 | AG9: =IF(AE9>0,AF9/AE9,0) -> 223.76923 | AI9: =R9-'EDl log'!B7 -> -49999035
A10: ='General information '!F13 -> 0.013 | B10: =SUM(230*A10) -> 2.99 | C10: 43990 | D10: 31767680 | E10: =D10-D9 -> 3342 | F10: 3705086 | G10: =F10-F9 -> 1741 | H10: 17484082 | I10: =H10-H9 -> 1756 | J10: 28468114 | K10: =J10-J9 -> 2636 | L10: 23107136 | M10: =L10-L9 -> 6270 | N10: =M10+K10+I10+G10+E10 -> 15745 | O10: =IF(B10>0,N10/B10,0) -> 5265.8863 | P10: 15563 | Q10: =(P10-P9)*1000 -> 2000 | R10: =N10-Q10 -> 13745 | S10: 8662 | T10: =S10-S9 -> 12 | U10: 87625 | V10: =U10-U9 -> 2835 | W10: =W9 -> 31853 | X10: =W10-W9 -> 0 | Y10: =Y9 -> 625865 | Z10: =Y10-Y9 -> 0 | AA10: =AA9 -> 35137 | AB10: =AA10-AA9 -> 0 | AC10: =AC9 -> 794338 | AD10: =AC10-AC9 -> 0 | AE10: =AB10+X10+T10 -> 12 | AF10: =V10+Z10+AD10 -> 2835 | AG10: =IF(AE10>0,AF10/AE10,0) -> 236.25 | AI10: =R10-'EDl log'!B8 -> -50005354
A11: ='General information '!F14 -> 0.0174 | B11: =SUM(230*A11) -> 4.002 | C11: 43991 | D11: 31772866 | E11: =D11-D10 -> 5186 | F11: 3706745 | G11: =F11-F10 -> 1659 | H11: 17485774 | I11: =H11-H10 -> 1692 | J11: 28470654 | K11: =J11-J10 -> 2540 | L11: 23111342 | M11: =L11-L10 -> 4206 | N11: =M11+K11+I11+G11+E11 -> 15283 | O11: =IF(B11>0,N11/B11,0) -> 3818.8406 | P11: 15565 | Q11: =(P11-P10)*1000 -> 2000 | R11: =N11-Q11 -> 13283 | S11: 8665 | T11: =S11-S10 -> 3 | U11: 88326 | V11: =U11-U10 -> 701 | W11: 31853 | X11: =W11-W10 -> 0 | Y11: =Y10 -> 625865 | Z11: =Y11-Y10 -> 0 | AA11: 35145 | AB11: =AA11-AA10 -> 8 | AC11: 796009 | AD11: =AC11-AC10 -> 1671 | AE11: =AB11+X11+T11 -> 11 | AF11: =V11+Z11+AD11 -> 2372 | AG11: =IF(AE11>0,AF11/AE11,0) -> 215.63636 | AI11: =R11-'EDl log'!B9 -> -50011933
A12: ='General information '!F15 -> 0.0174 | B12: =SUM(230*A12) -> 4.002 | C12: 43992 | D12: 31776662 | E12: =D12-D11 -> 3796 | F12: 3708393 | G12: =F12-F11 -> 1648 | H12: 17487524 | I12: =H12-H11 -> 1750 | J12: 28473490 | K12: =J12-J11 -> 2836 | L12: 23117946 | M12: =L12-L11 -> 6604 | N12: =M12+K12+I12+G12+E12 -> 16634 | O12: =IF(B12>0,N12/B12,0) -> 4156.4218 | P12: 15571 | Q12: =(P12-P11)*1000 -> 6000 | R12: =N12-Q12 -> 10634 | S12: 8679 | T12: =S12-S11 -> 14 | U12: 91701 | V12: =U12-U11 -> 3375 | W12: 31853 | X12: =W12-W11 -> 0 | Y12: =Y11 -> 625865 | Z12: =Y12-Y11 -> 0 | AA12: 35145 | AB12: =AA12-AA11 -> 0 | AC12: 796009 | AD12: =AC12-AC11 -> 0 | AE12: =AB12+X12+T12 -> 14 | AF12: =V12+Z12+AD12 -> 3375 | AG12: =IF(AE12>0,AF12/AE12,0) -> 241.07143 | AI12: =R12-'EDl log'!B10 -> -50021868
A13: ='General information '!F16 -> 0.013 | B13: =SUM(230*A13) -> 2.99 | C13: 43993 | D13: 31779660 | E13: =D13-D12 -> 2998 | F13: 3710056 | G13: =F13-F12 -> 1663 | H13: 17489156 | I13: =H13-H12 -> 1632 | J13: 28475818 | K13: =J13-J12 -> 2328 | L13: 23123762 | M13: =L13-L12 -> 5816 | N13: =M13+K13+I13+G13+E13 -> 14437 | O13: =IF(B13>0,N13/B13,0) -> 4828.4281 | P13: 15576 | Q13: =(P13-P12)*1000 -> 5000 | R13: =N13-Q13 -> 9437 | S13: 8689 | T13: =S13-S12 -> 10 | U13: 94466 | V13: =U13-U12 -> 2765 | W13: 31853 | X13: =W13-W12 -> 0 | Y13: 625865 | Z13: =Y13-Y12 -> 0 | AA13: 35145 | AB13: =AA13-AA12 -> 0 | AC13: 796020 | AD13: =AC13-AC12 -> 11 | AE13: =AB13+X13+T13 -> 10 | AF13: =V13+Z13+AD13 -> 2776 | AG13: =IF(AE13>0,AF13/AE13,0) -> 277.6 | AI13: =R13-'EDl log'!B11 -> -50030059
A14: ='General information '!F17 -> 0 | B14: =SUM(230*A14) -> 0 | C14: 43994 | D14: =D13 -> 31779660 | E14: =D14-D13 -> 0 | F14: =F13 -> 3710056 | G14: =F14-F13 -> 0 | H14: =H13 -> 17489156 | I14: =H14-H13 -> 0 | J14: =J13 -> 28475818 | K14: =J14-J13 -> 0 | L14: =L13 -> 23123762 | M14: =L14-L13 -> 0 | N14: =M14+K14+I14+G14+E14 -> 0 | O14: =IF(B14>0,N14/B14,0) -> 0 | P14: =P13 -> 15576 | Q14: =(P14-P13)*1000 -> 0 | R14: =N14-Q14 -> 0 | S14: =S13 -> 8689 | T14: =S14-S13 -> 0 | U14: =U13 -> 94466 | V14: =U14-U13 -> 0 | W14: =W13 -> 31853 | X14: =W14-W13 -> 0 | Y14: =Y13 -> 625865 | Z14: =Y14-Y13 -> 0 | AA14: =AA13 -> 35145 | AB14: =AA14-AA13 -> 0 | AC14: =AC13 -> 796020 | AD14: =AC14-AC13 -> 0 | AE14: =AB14+X14+T14 -> 0 | AF14: =V14+Z14+AD14 -> 0 | AG14: =IF(AE14>0,AF14/AE14,0) -> 0 | AI14: =R14-'EDl log'!B12 -> -50046427
A15: ='General information '!F18 -> 0 | B15: =SUM(230*A15) -> 0 | C15: 43995 | D15: =D14 -> 31779660 | E15: =D15-D14 -> 0 | F15: =F14 -> 3710056 | G15: =F15-F14 -> 0 | H15: =H14 -> 17489156 | I15: =H15-H14 -> 0 | J15: =J14 -> 28475818 | K15: =J15-J14 -> 0 | L15: =L14 -> 23123762 | M15: =L15-L14 -> 0 | N15: =M15+K15+I15+G15+E15 -> 0 | O15: =IF(B15>0,N15/B15,0) -> 0 | P15: =P14 -> 15576 | Q15: =(P15-P14)*1000 -> 0 | R15: =N15-Q15 -> 0 | S15: =S14 -> 8689 | T15: =S15-S14 -> 0 | U15: =U14 -> 94466 | V15: =U15-U14 -> 0 | W15: =W14 -> 31853 | X15: =W15-W14 -> 0 | Y15: =Y14 -> 625865 | Z15: =Y15-Y14 -> 0 | AA15: =AA14 -> 35145 | AB15: =AA15-AA14 -> 0 | AC15: =AC14 -> 796020 | AD15: =AC15-AC14 -> 0 | AE15: =AB15+X15+T15 -> 0 | AF15: =V15+Z15+AD15 -> 0 | AG15: =IF(AE15>0,AF15/AE15,0) -> 0 | AI15: =R15-'EDl log'!B13 -> -50052150
A16: ='General information '!F19 -> 0 | B16: =SUM(230*A16) -> 0 | C16: 43996 | D16: =D15 -> 31779660 | E16: =D16-D15 -> 0 | F16: =F15 -> 3710056 | G16: =F16-F15 -> 0 | H16: =H15 -> 17489156 | I16: =H16-H15 -> 0 | J16: =J15 -> 28475818 | K16: =J16-J15 -> 0 | L16: =L15 -> 23123762 | M16: =L16-L15 -> 0 | N16: =M16+K16+I16+G16+E16 -> 0 | O16: =IF(B16>0,N16/B16,0) -> 0 | P16: =P15 -> 15576 | Q16: =(P16-P15)*1000 -> 0 | R16: =N16-Q16 -> 0 | S16: =S15 -> 8689 | T16: =S16-S15 -> 0 | U16: =U15 -> 94466 | V16: =U16-U15 -> 0 | W16: =W15 -> 31853 | X16: =W16-W15 -> 0 | Y16: =Y15 -> 625865 | Z16: =Y16-Y15 -> 0 | AA16: =AA15 -> 35145 | AB16: =AA16-AA15 -> 0 | AC16: =AC15 -> 796020 | AD16: =AC16-AC15 -> 0 | AE16: =AB16+X16+T16 -> 0 | AF16: =V16+Z16+AD16 -> 0 | AG16: =IF(AE16>0,AF16/AE16,0) -> 0 | AI16: =R16-'EDl log'!B14 -> -4163
A17: ='General information '!F20 -> 0 | B17: =SUM(230*A17) -> 0 | C17: 43997 | D17: =D16 -> 31779660 | E17: =D17-D16 -> 0 | F17: =F16 -> 3710056 | G17: =F17-F16 -> 0 | H17: =H16 -> 17489156 | I17: =H17-H16 -> 0 | J17: =J16 -> 28475818 | K17: =J17-J16 -> 0 | L17: =L16 -> 23123762 | M17: =L17-L16 -> 0 | N17: =M17+K17+I17+G17+E17 -> 0 | O17: =IF(B17>0,N17/B17,0) -> 0 | P17: =P16 -> 15576 | Q17: =(P17-P16)*1000 -> 0 | R17: =N17-Q17 -> 0 | S17: =S16 -> 8689 | T17: =S17-S16 -> 0 | U17: =U16 -> 94466 | V17: =U17-U16 -> 0 | W17: =W16 -> 31853 | X17: =W17-W16 -> 0 | Y17: =Y16 -> 625865 | Z17: =Y17-Y16 -> 0 | AA17: =AA16 -> 35145 | AB17: =AA17-AA16 -> 0 | AC17: =AC16 -> 796020 | AD17: =AC17-AC16 -> 0 | AE17: =AB17+X17+T17 -> 0 | AF17: =V17+Z17+AD17 -> 0 | AG17: =IF(AE17>0,AF17/AE17,0) -> 0 | AI17: =R17-'EDl log'!B15 -> -4163
A18: ='General information '!F21 -> 0 | B18: =SUM(230*A18) -> 0 | C18: 43998 | D18: =D17 -> 31779660 | E18: =D18-D17 -> 0 | F18: =F17 -> 3710056 | G18: =F18-F17 -> 0 | H18: =H17 -> 17489156 | I18: =H18-H17 -> 0 | J18: =J17 -> 28475818 | K18: =J18-J17 -> 0 | L18: =L17 -> 23123762 | M18: =L18-L17 -> 0 | N18: =M18+K18+I18+G18+E18 -> 0 | O18: =IF(B18>0,N18/B18,0) -> 0 | P18: =P17 -> 15576 | Q18: =(P18-P17)*1000 -> 0 | R18: =N18-Q18 -> 0 | S18: =S17 -> 8689 | T18: =S18-S17 -> 0 | U18: =U17 -> 94466 | V18: =U18-U17 -> 0 | W18: =W17 -> 31853 | X18: =W18-W17 -> 0 | Y18: =Y17 -> 625865 | Z18: =Y18-Y17 -> 0 | AA18: =AA17 -> 35145 | AB18: =AA18-AA17 -> 0 | AC18: =AC17 -> 796020 | AD18: =AC18-AC17 -> 0 | AE18: =AB18+X18+T18 -> 0 | AF18: =V18+Z18+AD18 -> 0 | AG18: =IF(AE18>0,AF18/AE18,0) -> 0 | AI18: =R18-'EDl log'!B16 -> -4163
A19: ='General information '!F22 -> 0 | B19: =SUM(230*A19) -> 0 | C19: 43999 | D19: =D18 -> 31779660 | E19: =D19-D18 -> 0 | F19: =F18 -> 3710056 | G19: =F19-F18 -> 0 | H19: =H18 -> 17489156 | I19: =H19-H18 -> 0 | J19: =J18 -> 28475818 | K19: =J19-J18 -> 0 | L19: =L18 -> 23123762 | M19: =L19-L18 -> 0 | N19: =M19+K19+I19+G19+E19 -> 0 | O19: =IF(B19>0,N19/B19,0) -> 0 | P19: =P18 -> 15576 | Q19: =(P19-P18)*1000 -> 0 | R19: =N19-Q19 -> 0 | S19: =S18 -> 8689 | T19: =S19-S18 -> 0 | U19: =U18 -> 94466 | V19: =U19-U18 -> 0 | W19: =W18 -> 31853 | X19: =W19-W18 -> 0 | Y19: =Y18 -> 625865 | Z19: =Y19-Y18 -> 0 | AA19: =AA18 -> 35145 | AB19: =AA19-AA18 -> 0 | AC19: =AC18 -> 796020 | AD19: =AC19-AC18 -> 0 | AE19: =AB19+X19+T19 -> 0 | AF19: =V19+Z19+AD19 -> 0 | AG19: =IF(AE19>0,AF19/AE19,0) -> 0 | AI19: =R19-'EDl log'!B17 -> -4163
A20: ='General information '!F23 -> 0 | B20: =SUM(230*A20) -> 0 | C20: 44000 | D20: =D19 -> 31779660 | E20: =D20-D19 -> 0 | F20: =F19 -> 3710056 | G20: =F20-F19 -> 0 | H20: =H19 -> 17489156 | I20: =H20-H19 -> 0 | J20: =J19 -> 28475818 | K20: =J20-J19 -> 0 | L20: =L19 -> 23123762 | M20: =L20-L19 -> 0 | N20: =M20+K20+I20+G20+E20 -> 0 | O20: =IF(B20>0,N20/B20,0) -> 0 | P20: =P19 -> 15576 | Q20: =(P20-P19)*1000 -> 0 | R20: =N20-Q20 -> 0 | S20: =S19 -> 8689 | T20: =S20-S19 -> 0 | U20: =U19 -> 94466 | V20: =U20-U19 -> 0 | W20: =W19 -> 31853 | X20: =W20-W19 -> 0 | Y20: =Y19 -> 625865 | Z20: =Y20-Y19 -> 0 | AA20: =AA19 -> 35145 | AB20: =AA20-AA19 -> 0 | AC20: =AC19 -> 796020 | AD20: =AC20-AC19 -> 0 | AE20: =AB20+X20+T20 -> 0 | AF20: =V20+Z20+AD20 -> 0 | AG20: =IF(AE20>0,AF20/AE20,0) -> 0 | AI20: =R20-'EDl log'!B18 -> -4163
A21: ='General information '!F24 -> 0 | B21: =SUM(230*A21) -> 0 | C21: 44001 | D21: =D20 -> 31779660 | E21: =D21-D20 -> 0 | F21: =F20 -> 3710056 | G21: =F21-F20 -> 0 | H21: =H20 -> 17489156 | I21: =H21-H20 -> 0 | J21: =J20 -> 28475818 | K21: =J21-J20 -> 0 | L21: =L20 -> 23123762 | M21: =L21-L20 -> 0 | N21: =M21+K21+I21+G21+E21 -> 0 | O21: =IF(B21>0,N21/B21,0) -> 0 | P21: =P20 -> 15576 | Q21: =(P21-P20)*1000 -> 0 | R21: =N21-Q21 -> 0 | S21: =S20 -> 8689 | T21: =S21-S20 -> 0 | U21: =U20 -> 94466 | V21: =U21-U20 -> 0 | W21: =W20 -> 31853 | X21: =W21-W20 -> 0 | Y21: =Y20 -> 625865 | Z21: =Y21-Y20 -> 0 | AA21: =AA20 -> 35145 | AB21: =AA21-AA20 -> 0 | AC21: =AC20 -> 796020 | AD21: =AC21-AC20 -> 0 | AE21: =AB21+X21+T21 -> 0 | AF21: =V21+Z21+AD21 -> 0 | AG21: =IF(AE21>0,AF21/AE21,0) -> 0 | AI21: =R21-'EDl log'!B19 -> -4163
A22: ='General information '!F25 -> 0 | B22: =SUM(230*A22) -> 0 | C22: 44002 | D22: =D21 -> 31779660 | E22: =D22-D21 -> 0 | F22: =F21 -> 3710056 | G22: =F22-F21 -> 0 | H22: =H21 -> 17489156 | I22: =H22-H21 -> 0 | J22: =J21 -> 28475818 | K22: =J22-J21 -> 0 | L22: =L21 -> 23123762 | M22: =L22-L21 -> 0 | N22: =M22+K22+I22+G22+E22 -> 0 | O22: =IF(B22>0,N22/B22,0) -> 0 | P22: =P21 -> 15576 | Q22: =(P22-P21)*1000 -> 0 | R22: =N22-Q22 -> 0 | S22: =S21 -> 8689 | T22: =S22-S21 -> 0 | U22: =U21 -> 94466 | V22: =U22-U21 -> 0 | W22: =W21 -> 31853 | X22: =W22-W21 -> 0 | Y22: =Y21 -> 625865 | Z22: =Y22-Y21 -> 0 | AA22: =AA21 -> 35145 | AB22: =AA22-AA21 -> 0 | AC22: =AC21 -> 796020 | AD22: =AC22-AC21 -> 0 | AE22: =AB22+X22+T22 -> 0 | AF22: =V22+Z22+AD22 -> 0 | AG22: =IF(AE22>0,AF22/AE22,0) -> 0 | AI22: =R22-'EDl log'!B20 -> -4163
A23: ='General information '!F26 -> 0 | B23: =SUM(230*A23) -> 0 | C23: 44003 | D23: =D22 -> 31779660 | E23: =D23-D22 -> 0 | F23: =F22 -> 3710056 | G23: =F23-F22 -> 0 | H23: =H22 -> 17489156 | I23: =H23-H22 -> 0 | J23: =J22 -> 28475818 | K23: =J23-J22 -> 0 | L23: =L22 -> 23123762 | M23: =L23-L22 -> 0 | N23: =M23+K23+I23+G23+E23 -> 0 | O23: =IF(B23>0,N23/B23,0) -> 0 | P23: =P22 -> 15576 | Q23: =(P23-P22)*1000 -> 0 | R23: =N23-Q23 -> 0 | S23: =S22 -> 8689 | T23: =S23-S22 -> 0 | U23: =U22 -> 94466 | V23: =U23-U22 -> 0 | W23: =W22 -> 31853 | X23: =W23-W22 -> 0 | Y23: =Y22 -> 625865 | Z23: =Y23-Y22 -> 0 | AA23: =AA22 -> 35145 | AB23: =AA23-AA22 -> 0 | AC23: =AC22 -> 796020 | AD23: =AC23-AC22 -> 0 | AE23: =AB23+X23+T23 -> 0 | AF23: =V23+Z23+AD23 -> 0 | AG23: =IF(AE23>0,AF23/AE23,0) -> 0 | AI23: =R23-'EDl log'!B21 -> -4163
A24: ='General information '!F27 -> 0 | B24: =SUM(230*A24) -> 0 | C24: 44004 | D24: =D23 -> 31779660 | E24: =D24-D23 -> 0 | F24: =F23 -> 3710056 | G24: =F24-F23 -> 0 | H24: =H23 -> 17489156 | I24: =H24-H23 -> 0 | J24: =J23 -> 28475818 | K24: =J24-J23 -> 0 | L24: =L23 -> 23123762 | M24: =L24-L23 -> 0 | N24: =M24+K24+I24+G24+E24 -> 0 | O24: =IF(B24>0,N24/B24,0) -> 0 | P24: =P23 -> 15576 | Q24: =(P24-P23)*1000 -> 0 | R24: =N24-Q24 -> 0 | S24: =S23 -> 8689 | T24: =S24-S23 -> 0 | U24: =U23 -> 94466 | V24: =U24-U23 -> 0 | W24: =W23 -> 31853 | X24: =W24-W23 -> 0 | Y24: =Y23 -> 625865 | Z24: =Y24-Y23 -> 0 | AA24: =AA23 -> 35145 | AB24: =AA24-AA23 -> 0 | AC24: =AC23 -> 796020 | AD24: =AC24-AC23 -> 0 | AE24: =AB24+X24+T24 -> 0 | AF24: =V24+Z24+AD24 -> 0 | AG24: =IF(AE24>0,AF24/AE24,0) -> 0 | AI24: =R24-'EDl log'!B22 -> -4163
A25: ='General information '!F28 -> 0 | B25: =SUM(230*A25) -> 0 | C25: 44005 | D25: =D24 -> 31779660 | E25: =D25-D24 -> 0 | F25: =F24 -> 3710056 | G25: =F25-F24 -> 0 | H25: =H24 -> 17489156 | I25: =H25-H24 -> 0 | J25: =J24 -> 28475818 | K25: =J25-J24 -> 0 | L25: =L24 -> 23123762 | M25: =L25-L24 -> 0 | N25: =M25+K25+I25+G25+E25 -> 0 | O25: =IF(B25>0,N25/B25,0) -> 0 | P25: =P24 -> 15576 | Q25: =(P25-P24)*1000 -> 0 | R25: =N25-Q25 -> 0 | S25: =S24 -> 8689 | T25: =S25-S24 -> 0 | U25: =U24 -> 94466 | V25: =U25-U24 -> 0 | W25: =W24 -> 31853 | X25: =W25-W24 -> 0 | Y25: =Y24 -> 625865 | Z25: =Y25-Y24 -> 0 | AA25: =AA24 -> 35145 | AB25: =AA25-AA24 -> 0 | AC25: =AC24 -> 796020 | AD25: =AC25-AC24 -> 0 | AE25: =AB25+X25+T25 -> 0 | AF25: =V25+Z25+AD25 -> 0 | AG25: =IF(AE25>0,AF25/AE25,0) -> 0 | AI25: =R25-'EDl log'!B23 -> -4163
... A32: ='General information '!F35 -> 0 | B32: =SUM(230*A32) -> 0 | C32: 44012 | D32: =D31 -> 31779660 | E32: =D32-D31 -> 0 | F32: =F31 -> 3710056 | G32: =F32-F31 -> 0 | H32: =H31 -> 17489156 | I32: =H32-H31 -> 0 | J32: =J31 -> 28475818 | K32: =J32-J31 -> 0 | L32: =L31 -> 23123762 | M32: =L32-L31 -> 0 | N32: =M32+K32+I32+G32+E32 -> 0 | O32: =IF(B32>0,N32/B32,0) -> 0 | P32: =P31 -> 15576 | Q32: =(P32-P31)*1000 -> 0 | R32: =N32-Q32 -> 0 | S32: =S31 -> 8689 | T32: =S32-S31 -> 0 | U32: =U31 -> 94466 | V32: =U32-U31 -> 0 | W32: =W31 -> 31853 | X32: =W32-W31 -> 0 | Y32: =Y31 -> 625865 | Z32: =Y32-Y31 -> 0 | AA32: =AA31 -> 35145 | AB32: =AA32-AA31 -> 0 | AC32: =AC31 -> 796020 | AD32: =AC32-AC31 -> 0 | AE32: =AB32+X32+T32 -> 0 | AF32: =V32+Z32+AD32 -> 0 | AG32: =IF(AE32>0,AF32/AE32,0) -> 0 | AI32: =R32-'EDl log'!B30 -> -4163

Sheet B5
F1: Boiler A | J1: =J35 -> 70.440476 | K1: Boiler B | P1: Boiler C | V1: Boiler | X1: SteamA | AC1: SteamB | AH1: Steam | AI1: Boiler & steam | AL1: Total Boiler Runing H | AM1: Total Steam Runing H | AN1: GAS1 % | AO1: GAS1/L | AP1: GAS2% | AQ1: Gas2/L | AR1: GAS3% | AS1: GAS3/L | AU1: Gas Cons | AV1: Delivery | AW1: Cost/L
B2: Level Tank Gen | C2: Level tank Boiler | D2: Daily Cons Bo. | E2: Boiler litter | F2: Boiler A | G2: Run Hr a | H2: Boiler A fuel | I2: Daily consumption | J2: AVG | K2: index Run H | L2: Run Hrb | M2: Boiler B Fuel | O2: Daily consumption | P2: Boiler C | S2: Run C | U2: Total RH | V2: Total Fuel | X2: SteamA | Y2: Run SA | Z2: Steam A Conter | AA2: Liters | AC2: SteamB | AD2: Run SteamB | AE2: Steam B Conter | AF2: SB Litters | AG2: Avg | AH2: Total Fuel | AI2: Total Fuel
S3: 0
A4: =ELEC!C2 -> 43982 | B4: =[2]B5!B35 -> 179 | C4: =[2]B5!C35 -> 186 | D4: =[2]B5!D35 -> 3.2 | E4: =[2]B5!E35 -> 26.816 | F4: =[2]B5!F35 -> 1578 | G4: =[2]B5!G35 -> 0 | H4: =[2]B5!H35 -> 352431 | I4: =[2]B5!I35 -> 0 | ... AW4: =[2]B5!AW35 -> 0 | AX4: =[1]B5!AX34 -> 0.7
A5: =ELEC!C3 -> 43983 | B5: 175 | C5: 182 | D5: =C4-C5 -> 4 | E5: =D5*8.38 -> 33.52 | F5: 1581 | G5: =F5-F4 -> 3 | H5: 352662 | I5: =SUM(H5-H4) -> 231 | J5: 1 | K5: =K4 -> 1962 | L5: =K5-K4 -> 0 | M5: =M4 -> 143825 | N5: =M5-M4 -> 0 | O5: =SUM(L5*$J$1) -> 0 | P5: 1797 | Q5: 152534 | R5: =Q5-Q4 -> 221 | S5: =SUM(P5-P4) -> 3 | T5: =SUM(S5*$T$2) -> 0 | U5: =SUM(G5+L5+S5) -> 6 | V5: =R5+N5+I5:I5 -> 452 | W5: =SUM(V5/U5) -> 75.333333 | X5: =X4 -> 2418 | Y5: =X5-X4 -> 0 | Z5: =Z4 -> 135904 | AA5: =Z5-Z4 -> 0 | AB5: =SUM(Y5*$AB$2) -> 0 | AC5: =AC4 -> 1841 | AD5: =AC5-AC4 -> 0 | AE5: =AE4 -> 359849.4 | AF5: =AE5-AE4 -> 0 | AG5: =IF(AD5>0,AF5/AD5,0) -> 0 | AH5: =AF5+AA5 -> 0 | AI5: =SUM(AH5+V5) -> 452 | AJ5: =-tanks!AW6 -> 452 | AK5: =SUM(AJ5-AI5) -> 0 | AL5: =S5+L5+G5 -> 6 | AM5: =Y5+AD5 -> 0 | AN5: 67 | AO5: =(AN5/100)*3000 -> 2010 | AP5: 78 | AQ5: =(AP5/100)*3000 -> 2340 | AR5: 69 | AS5: =(AR5/100)*3000 -> 2070 | AT5: =SUM(AO5+AQ5+AS5) -> 6420 | AU5: =AT4-AT5+AV5 -> 180 | AX5: =IF(AV5>0,AW5,AX4) -> 0.7
A6: =ELEC!C4 -> 43984 | B6: 173 | C6: 179 | D6: =C5-C6 -> 3 | E6: =D6*8.38 -> 25.14 | F6: 1582 | G6: =F6-F5 -> 1 | H6: 352783 | I6: =SUM(H6-H5) -> 121 | J6: =IF(G6>0,I6/G6,0) -> 121 | K6: 1965 | L6: =K6-K5 -> 3 | M6: 144000 | N6: =M6-M5 -> 175 | O6: =SUM(L6*$J$1) -> 211.32143 | P6: =P5 -> 1797 | Q6: 152534 | R6: =Q6-Q5 -> 0 | S6: =SUM(P6-P5) -> 0 | T6: =SUM(S6*$T$2) -> 0 | U6: =SUM(G6+L6+S6) -> 4 | V6: =R6+N6+I6:I6 -> 296 | W6: =SUM(V6/U6) -> 74 | X6: =X5 -> 2418 | Y6: =X6-X5 -> 0 | Z6: =Z5 -> 135904 | AA6: =Z6-Z5 -> 0 | AB6: =SUM(Y6*$AB$2) -> 0 | AC6: =AC5 -> 1841 | AD6: =AC6-AC5 -> 0 | AE6: =AE5 -> 359849.4 | AF6: =AE6-AE5 -> 0 | AG6: =IF(AD6>0,AF6/AD6,0) -> 0 | AH6: =AF6+AA6 -> 0 | AI6: =SUM(AH6+V6) -> 296 | AJ6: =-tanks!AW7 -> 296 | AK6: =SUM(AJ6-AI6) -> 0 | AL6: =S6+L6+G6 -> 4 | AM6: =Y6+AD6 -> 0 | AN6: 65 | AO6: =(AN6/100)*3000 -> 1950 | AP6: 75 | AQ6: =(AP6/100)*3000 -> 2250 | AR6: 71 | AS6: =(AR6/100)*3000 -> 2130 | AT6: =SUM(AO6+AQ6+AS6) -> 6330 | AU6: =AT5-AT6+AV6 -> 90 | AX6: =IF(AV6>0,AW6,AX5) -> 0.7
A7: =ELEC!C5 -> 43985 | B7: 168 | C7: 173 | D7: =C6-C7 -> 6 | E7: =D7*8.38 -> 50.28 | F7: 1582 | G7: =F7-F6 -> 0 | H7: 352783 | I7: =SUM(H7-H6) -> 0 | J7: =IF(G7>0,I7/G7,0) -> 0 | K7: 1967 | L7: =K7-K6 -> 2 | M7: 144145 | N7: =M7-M6 -> 145 | O7: 1 | P7: 1799 | Q7: 152706 | R7: =Q7-Q6 -> 172 | S7: =SUM(P7-P6) -> 2 | T7: =SUM(S7*$T$2) -> 0 | U7: =SUM(G7+L7+S7) -> 4 | V7: =R7+N7+I7:I7 -> 317 | W7: =SUM(V7/U7) -> 79.25 | X7: 2418 | Y7: =X7-X6 -> 0 | Z7: 135958 | AA7: =Z7-Z6 -> 54 | AB7: =SUM(Y7*$AB$2) -> 0 | AC7: 1841 | AD7: =AC7-AC6 -> 0 | AE7: 359849 | AF7: =AE7-AE6 -> -0.4 | AG7: =IF(AD7>0,AF7/AD7,0) -> 0 | AH7: =AF7+AA7 -> 53.6 | AI7: =SUM(AH7+V7) -> 370.6 | AJ7: =-tanks!AW8 -> 370.6 | AK7: =SUM(AJ7-AI7) -> 0 | AL7: =S7+L7+G7 -> 4 | AM7: =Y7+AD7 -> 0 | AN7: 70 | AO7: =(AN7/100)*3000 -> 2100 | AP7: 73 | AQ7: =(AP7/100)*3000 -> 2190 | AR7: 64 | AS7: =(AR7/100)*3000 -> 1920 | AT7: =SUM(AO7+AQ7+AS7) -> 6210 | AU7: =AT6-AT7+AV7 -> 120 | AX7: =IF(AV7>0,AW7,AX6) -> 0.7
A8: =ELEC!C6 -> 43986 | B8: 203 | C8: 210 | D8: =C7-C8 -> -37 | E8: =D8*8.38 -> -310.06 | F8: 1585 | G8: =F8-F7 -> 3 | H8: 352951 | I8: =SUM(H8-H7) -> 168 | J8: =IF(G8>0,I8/G8,0) -> 56 | K8: =K7 -> 1967 | L8: =K8-K7 -> 0 | M8: =M7 -> 144145 | N8: =M8-M7 -> 0 | O8: 1479 | P8: 1803 | Q8: 152938 | R8: =Q8-Q7 -> 232 | S8: =SUM(P8-P7) -> 4 | T8: =SUM(S8*$T$2) -> 0 | U8: =SUM(G8+L8+S8) -> 7 | V8: =R8+N8+I8:I8 -> 400 | W8: =SUM(V8/U8) -> 57.142857 | X8: =X7 -> 2418 | Y8: =X8-X7 -> 0 | Z8: =Z7 -> 135958 | AA8: =Z8-Z7 -> 0 | AB8: =SUM(Y8*$AB$2) -> 0 | AC8: 1845 | AD8: =AC8-AC7 -> 4 | AE8: 360077 | AF8: =AE8-AE7 -> 228 | AG8: =IF(AD8>0,AF8/AD8,0) -> 57 | AH8: =AF8+AA8 -> 228 | AI8: =SUM(AH8+V8) -> 628 | AJ8: =-tanks!AW9 -> 628 | AK8: =SUM(AJ8-AI8) -> 0 | AL8: =S8+L8+G8 -> 7 | AM8: =Y8+AD8 -> 4 | AN8: 79 | AO8: =(AN8/100)*3000 -> 2370 | AP8: 83 | AQ8: =(AP8/100)*3000 -> 2490 | AR8: 70 | AS8: =(AR8/100)*3000 -> 2100 | AT8: =SUM(AO8+AQ8+AS8) -> 6960 | AU8: =AT7-AT8+AV8 -> 350 | AV8: 1100 | AW8: 0.7 | AX8: =IF(AV8>0,AW8,AX7) -> 0.7
A9: =ELEC!C7 -> 43987 | B9: 199 | C9: 205 | D9: =C8-C9 -> 5 | E9: =D9*8.38 -> 41.9 | F9: 1587 | G9: =F9-F8 -> 2 | H9: 353130 | I9: =SUM(H9-H8) -> 179 | J9: =IF(G9>0,I9/G9,0) -> 89.5 | K9: 1968 | L9: =K9-K8 -> 1 | M9: 144264 | N9: =M9-M8 -> 119 | O9: =SUM(L9*$J$1) -> 70.440476 | P9: =P8 -> 1803 | Q9: 152974 | R9: =Q9-Q8 -> 36 | S9: =SUM(P9-P8) -> 0 | T9: =SUM(S9*$T$2) -> 0 | U9: =SUM(G9+L9+S9) -> 3 | V9: =R9+N9+I9:I9 -> 334 | W9: =SUM(V9/U9) -> 111.33333 | X9: =X8 -> 2418 | Y9: =X9-X8 -> 0 | Z9: =Z8 -> 135958 | AA9: =Z9-Z8 -> 0 | AB9: =SUM(Y9*$AB$2) -> 0 | AC9: =AC8 -> 1845 | AD9: =AC9-AC8 -> 0 | AE9: =AE8 -> 360077 | AF9: =AE9-AE8 -> 0 | AG9: =IF(AD9>0,AF9/AD9,0) -> 0 | AH9: =AF9+AA9 -> 0 | AI9: =SUM(AH9+V9) -> 334 | AJ9: =-tanks!AW10 -> 334 | AK9: =SUM(AJ9-AI9) -> 0 | AL9: =S9+L9+G9 -> 3 | AM9: =Y9+AD9 -> 0 | AN9: =AN8 -> 79 | AO9: =(AN9/100)*3000 -> 2370 | AP9: =AP8 -> 83 | AQ9: =(AP9/100)*3000 -> 2490 | AR9: 67 | AS9: =(AR9/100)*3000 -> 2010 | AT9: =SUM(AO9+AQ9+AS9) -> 6870 | AU9: =AT8-AT9+AV9 -> 90 | AX9: =IF(AV9>0,AW9,AX8) -> 0.7
A10: =ELEC!C8 -> 43988 | B10: 196 | C10: 202 | D10: =C9-C10 -> 3 | E10: =D10*8.38 -> 25.14 | F10: 1589 | G10: =F10-F9 -> 2 | H10: 353275 | I10: =SUM(H10-H9) -> 145 | J10: =IF(G10>0,I10/G10,0) -> 72.5 | K10: 1972 | L10: =K10-K9 -> 4 | M10: 144510 | N10: =M10-M9 -> 246 | O10: =SUM(L10*$J$1) -> 281.7619 | P10: =P9 -> 1803 | Q10: 152974 | R10: =Q10-Q9 -> 0 | S10: =SUM(P10-P9) -> 0 | T10: =SUM(S10*$T$2) -> 0 | U10: =SUM(G10+L10+S10) -> 6 | V10: =R10+N10+I10:I10 -> 391 | W10: =SUM(V10/U10) -> 65.166667 | X10: =X9 -> 2418 | Y10: =X10-X9 -> 0 | Z10: =Z9 -> 135958 | AA10: =Z10-Z9 -> 0 | AB10: =SUM(Y10*$AB$2) -> 0 | AC10: =AC9 -> 1845 | AD10: =AC10-AC9 -> 0 | AE10: =AE9 -> 360077 | AF10: =AE10-AE9 -> 0 | AG10: =IF(AD10>0,AF10/AD10,0) -> 0 | AH10: =AF10+AA10 -> 0 | AI10: =SUM(AH10+V10) -> 391 | AJ10: =-tanks!AW11 -> 391 | AK10: =SUM(AJ10-AI10) -> 0 | AL10: =S10+L10+G10 -> 6 | AM10: =Y10+AD10 -> 0 | AN10: 78 | AO10: =(AN10/100)*3000 -> 2340 | AP10: 81 | AQ10: =(AP10/100)*3000 -> 2430 | AR10: 68 | AS10: =(AR10/100)*3000 -> 2040 | AT10: =SUM(AO10+AQ10+AS10) -> 6810 | AU10: =AT9-AT10+AV10 -> 60 | AX10: =IF(AV10>0,AW10,AX9) -> 0.7
A11: =ELEC!C9 -> 43989 | B11: 192 | C11: 198 | D11: =C10-C11 -> 4 | E11: =D11*8.38 -> 33.52 | F11: 1593 | G11: =F11-F10 -> 4 | H11: 353638 | I11: =SUM(H11-H10) -> 363 | J11: =IF(G11>0,I11/G11,0) -> 90.75 | K11: =K10 -> 1972 | L11: =K11-K10 -> 0 | M11: =M10 -> 144510 | N11: =M11-M10 -> 0 | O11: 1803 | P11: =P10 -> 1803 | Q11: 152974 | R11: =Q11-Q10 -> 0 | S11: =SUM(P11-P10) -> 0 | T11: =SUM(S11*$T$2) -> 0 | U11: =SUM(G11+L11+S11) -> 4 | V11: =R11+N11+I11:I11 -> 363 | W11: =SUM(V11/U11) -> 90.75 | X11: =X10 -> 2418 | Y11: =X11-X10 -> 0 | Z11: =Z10 -> 135958 | AA11: =Z11-Z10 -> 0 | AB11: =SUM(Y11*$AB$2) -> 0 | AC11: =AC10 -> 1845 | AD11: =AC11-AC10 -> 0 | AE11: =AE10 -> 360077 | AF11: =AE11-AE10 -> 0 | AG11: =IF(AD11>0,AF11/AD11,0) -> 0 | AH11: =AF11+AA11 -> 0 | AI11: =SUM(AH11+V11) -> 363 | AJ11: =-tanks!AW12 -> 363 | AK11: =SUM(AJ11-AI11) -> 0 | AL11: =S11+L11+G11 -> 4 | AM11: =Y11+AD11 -> 0 | AN11: 77 | AO11: =(AN11/100)*3000 -> 2310 | AP11: 80 | AQ11: =(AP11/100)*3000 -> 2400 | AR11: =AR10 -> 68 | AS11: =(AR11/100)*3000 -> 2040 | AT11: =SUM(AO11+AQ11+AS11) -> 6750 | AU11: =AT10-AT11+AV11 -> 60 | AX11: =IF(AV11>0,AW11,AX10) -> 0.7
A12: =ELEC!C10 -> 43990 | B12: 188 | C12: 196 | D12: =C11-C12 -> 2 | E12: =D12*8.38 -> 16.76 | F12: 1596 | G12: =F12-F11 -> 3 | H12: 353825 | I12: =SUM(H12-H11) -> 187 | J12: =IF(G12>0,I12/G12,0) -> 62.333333 | K12: 1974 | L12: =K12-K11 -> 2 | M12: 144683 | N12: =M12-M11 -> 173 | O12: =SUM(L12*$J$1) -> 140.88095 | P12: =P11 -> 1803 | Q12: 152974 | R12: =Q12-Q11 -> 0 | S12: =SUM(P12-P11) -> 0 | T12: =SUM(S12*$T$2) -> 0 | U12: =SUM(G12+L12+S12) -> 5 | V12: =R12+N12+I12:I12 -> 360 | W12: =SUM(V12/U12) -> 72 | X12: =X11 -> 2418 | Y12: =X12-X11 -> 0 | Z12: =Z11 -> 135958 | AA12: =Z12-Z11 -> 0 | AB12: =SUM(Y12*$AB$2) -> 0 | AC12: =AC11 -> 1845 | AD12: =AC12-AC11 -> 0 | AE12: =AE11 -> 360077 | AF12: =AE12-AE11 -> 0 | AG12: =IF(AD12>0,AF12/AD12,0) -> 0 | AH12: =AF12+AA12 -> 0 | AI12: =SUM(AH12+V12) -> 360 | AJ12: =-tanks!AW13 -> 360 | AK12: =SUM(AJ12-AI12) -> 0 | AL12: =S12+L12+G12 -> 5 | AM12: =Y12+AD12 -> 0 | AN12: 76 | AO12: =(AN12/100)*3000 -> 2280 | AP12: 80 | AQ12: =(AP12/100)*3000 -> 2400 | AR12: 66 | AS12: =(AR12/100)*3000 -> 1980 | AT12: =SUM(AO12+AQ12+AS12) -> 6660 | AU12: =AT11-AT12+AV12 -> 90 | AX12: =IF(AV12>0,AW12,AX11) -> 0.7
A13: =ELEC!C11 -> 43991 | B13: 185.2 | C13: 191.3 | D13: =C12-C13 -> 4.7 | E13: =D13*8.38 -> 39.386 | F13: 1596 | G13: =F13-F12 -> 0 | H13: 353837 | I13: =SUM(H13-H12) -> 12 | J13: =IF(G13>0,I13/G13,0) -> 0 | K13: 1977 | L13: =K13-K12 -> 3 | M13: 144953 | N13: =M13-M12 -> 270 | O13: =SUM(L13*$J$1) -> 211.32143 | P13: 1803 | Q13: 152974 | R13: =Q13-Q12 -> 0 | S13: =SUM(P13-P12) -> 0 | T13: =SUM(S13*$T$2) -> 0 | U13: =SUM(G13+L13+S13) -> 3 | V13: =R13+N13+I13:I13 -> 282 | W13: =SUM(V13/U13) -> 94 | X13: 2418 | Y13: =X13-X12 -> 0 | Z13: 135958 | AA13: =Z13-Z12 -> 0 | AB13: =SUM(Y13*$AB$2) -> 0 | AC13: 1845 | AD13: =AC13-AC12 -> 0 | AE13: 360077 | AF13: =AE13-AE12 -> 0 | AG13: =IF(AD13>0,AF13/AD13,0) -> 0 | AH13: =AF13+AA13 -> 0 | AI13: =SUM(AH13+V13) -> 282 | AJ13: =-tanks!AW14 -> 282 | AK13: =SUM(AJ13-AI13) -> 0 | AL13: =S13+L13+G13 -> 3 | AM13: =Y13+AD13 -> 0 | AN13: 75 | AO13: =(AN13/100)*3000 -> 2250 | AP13: 77 | AQ13: =(AP13/100)*3000 -> 2310 | AR13: 65 | AS13: =(AR13/100)*3000 -> 1950 | AT13: =SUM(AO13+AQ13+AS13) -> 6510 | AU13: =AT12-AT13+AV13 -> 150 | AX13: =IF(AV13>0,AW13,AX12) -> 0.7
A14: =ELEC!C12 -> 43992 | B14: 177.2 | C14: 183.5 | D14: =C13-C14 -> 7.8 | E14: =D14*8.38 -> 65.364 | F14: 1596 | G14: =F14-F13 -> 0 | H14: 353837 | I14: =SUM(H14-H13) -> 0 | J14: =IF(G14>0,I14/G14,0) -> 0 | K14: 1983 | L14: =K14-K13 -> 6 | M14: 145331 | N14: =M14-M13 -> 378 | O14: =SUM(L14*$J$1) -> 422.64286 | P14: 1803 | Q14: 152974 | R14: =Q14-Q13 -> 0 | S14: =SUM(P14-P13) -> 0 | T14: =SUM(S14*$T$2) -> 0 | U14: =SUM(G14+L14+S14) -> 6 | V14: =R14+N14+I14:I14 -> 378 | W14: =SUM(V14/U14) -> 63 | X14: 2418 | Y14: =X14-X13 -> 0 | Z14: 135958 | AA14: =Z14-Z13 -> 0 | AB14: =SUM(Y14*$AB$2) -> 0 | AC14: 1848 | AD14: =AC14-AC13 -> 3 | AE14: 360299.4 | AF14: =AE14-AE13 -> 222.4 | AG14: =IF(AD14>0,AF14/AD14,0) -> 74.133333 | AH14: =AF14+AA14 -> 222.4 | AI14: =SUM(AH14+V14) -> 600.4 | AJ14: =-tanks!AW15 -> 600.4 | AK14: =SUM(AJ14-AI14) -> 0 | AL14: =S14+L14+G14 -> 6 | AM14: =Y14+AD14 -> 3 | AN14: 73 | AO14: =(AN14/100)*3000 -> 2190 | AP14: 75 | AQ14: =(AP14/100)*3000 -> 2250 | AR14: 64 | AS14: =(AR14/100)*3000 -> 1920 | AT14: =SUM(AO14+AQ14+AS14) -> 6360 | AU14: =AT13-AT14+AV14 -> 150 | AX14: =IF(AV14>0,AW14,AX13) -> 0.7
A15: =ELEC!C13 -> 43993 | B15: 169 | C15: 175 | D15: =C14-C15 -> 8.5 | E15: =D15*8.38 -> 71.23 | F15: 1596 | G15: =F15-F14 -> 0 | H15: 353837 | I15: =SUM(H15-H14) -> 0 | J15: =IF(G15>0,I15/G15,0) -> 0 | K15: 1987 | L15: =K15-K14 -> 4 | M15: 145693 | N15: =M15-M14 -> 362 | O15: =SUM(L15*$J$1) -> 281.7619 | P15: 1803 | Q15: 152974 | R15: =Q15-Q14 -> 0 | S15: =SUM(P15-P14) -> 0 | T15: =SUM(S15*$T$2) -> 0 | U15: =SUM(G15+L15+S15) -> 4 | V15: =R15+N15+I15:I15 -> 362 | W15: =SUM(V15/U15) -> 90.5 | X15: 2418 | Y15: =X15-X14 -> 0 | Z15: 135964.1 | AA15: =Z15-Z14 -> 6.1 | AB15: =SUM(Y15*$AB$2) -> 0 | AC15: 1848 | AD15: =AC15-AC14 -> 0 | AE15: =AE14 -> 360299.4 | AF15: =AE15-AE14 -> 0 | AG15: =IF(AD15>0,AF15/AD15,0) -> 0 | AH15: =AF15+AA15 -> 6.1 | AI15: =SUM(AH15+V15) -> 368.1 | AJ15: =-tanks!AW16 -> 368.1 | AK15: =SUM(AJ15-AI15) -> 0 | AL15: =S15+L15+G15 -> 4 | AM15: =Y15+AD15 -> 0 | AN15: 72 | AO15: =(AN15/100)*3000 -> 2160 | AP15: 73 | AQ15: =(AP15/100)*3000 -> 2190 | AR15: 61 | AS15: =(AR15/100)*3000 -> 1830 | AT15: =SUM(AO15+AQ15+AS15) -> 6180 | AU15: =AT14-AT15+AV15 -> 180 | AX15: =IF(AV15>0,AW15,AX14) -> 0.7
A16: =ELEC!C14 -> 43994 | B16: =B15 -> 169 | C16: =C15 -> 175 | D16: =C15-C16 -> 0 | E16: =D16*8.38 -> 0 | F16: =F15 -> 1596 | G16: =F16-F15 -> 0 | H16: =H15 -> 353837 | I16: =SUM(H16-H15) -> 0 | J16: =IF(G16>0,I16/G16,0) -> 0 | K16: =K15 -> 1987 | L16: =K16-K15 -> 0 | M16: =M15 -> 145693 | N16: =M16-M15 -> 0 | O16: =SUM(L16*$J$1) -> 0 | P16: =P15 -> 1803 | Q16: =Q15 -> 152974 | R16: =Q16-Q15 -> 0 | S16: =SUM(P16-P15) -> 0 | T16: =SUM(S16*$T$2) -> 0 | U16: =SUM(G16+L16+S16) -> 0 | V16: =R16+N16+I16:I16 -> 0 | W16: =SUM(V16/U16) -> #DIV/0! | X16: =X15 -> 2418 | Y16: =X16-X15 -> 0 | Z16: =Z15 -> 135964.1 | AA16: =Z16-Z15 -> 0 | AB16: =SUM(Y16*$AB$2) -> 0 | AC16: =AC15 -> 1848 | AD16: =AC16-AC15 -> 0 | AE16: =AE15 -> 360299.4 | AF16: =AE16-AE15 -> 0 | AG16: =IF(AD16>0,AF16/AD16,0) -> 0 | AH16: =AF16+AA16 -> 0 | AI16: =SUM(AH16+V16) -> 0 | AJ16: =-tanks!AW17 -> 0 | AK16: =SUM(AJ16-AI16) -> 0 | AL16: =S16+L16+G16 -> 0 | AM16: =Y16+AD16 -> 0 | AN16: =AN15 -> 72 | AO16: =(AN16/100)*3000 -> 2160 | AP16: =AP15 -> 73 | AQ16: =(AP16/100)*3000 -> 2190 | AR16: =AR15 -> 61 | AS16: =(AR16/100)*3000 -> 1830 | AT16: =SUM(AO16+AQ16+AS16) -> 6180 | AU16: =AT15-AT16+AV16 -> 0 | AX16: =IF(AV16>0,AW16,AX15) -> 0.7
A17: =ELEC!C15 -> 43995 | B17: =B16 -> 169 | C17: =C16 -> 175 | D17: =C16-C17 -> 0 | E17: =D17*8.38 -> 0 | F17: =F16 -> 1596 | G17: =F17-F16 -> 0 | H17: =H16 -> 353837 | I17: =SUM(H17-H16) -> 0 | J17: =IF(G17>0,I17/G17,0) -> 0 | K17: =K16 -> 1987 | L17: =K17-K16 -> 0 | M17: =M16 -> 145693 | N17: =M17-M16 -> 0 | O17: =SUM(L17*$J$1) -> 0 | P17: =P16 -> 1803 | Q17: =Q16 -> 152974 | R17: =Q17-Q16 -> 0 | S17: =SUM(P17-P16) -> 0 | T17: =SUM(S17*$T$2) -> 0 | U17: =SUM(G17+L17+S17) -> 0 | V17: =R17+N17+I17:I17 -> 0 | X17: =X16 -> 2418 | Y17: =X17-X16 -> 0 | Z17: =Z16 -> 135964.1 | AA17: =Z17-Z16 -> 0 | AB17: =SUM(Y17*$AB$2) -> 0 | AC17: =AC16 -> 1848 | AD17: =AC17-AC16 -> 0 | AE17: =AE16 -> 360299.4 | AF17: =AE17-AE16 -> 0 | AG17: =IF(AD17>0,AF17/AD17,0) -> 0 | AH17: =AF17+AA17 -> 0 | AI17: =SUM(AH17+V17) -> 0 | AJ17: =-tanks!AW18 -> 0 | AK17: =SUM(AJ17-AI17) -> 0 | AL17: =S17+L17+G17 -> 0 | AM17: =Y17+AD17 -> 0 | AN17: =AN16 -> 72 | AO17: =(AN17/100)*3000 -> 2160 | AP17: =AP16 -> 73 | AQ17: =(AP17/100)*3000 -> 2190 | AR17: =AR16 -> 61 | AS17: =(AR17/100)*3000 -> 1830 | AT17: =SUM(AO17+AQ17+AS17) -> 6180 | AU17: =AT16-AT17+AV17 -> 0 | AX17: =IF(AV17>0,AW17,AX16) -> 0.7
A18: =ELEC!C16 -> 43996 | B18: =B17 -> 169 | C18: =C17 -> 175 | D18: =C17-C18 -> 0 | E18: =D18*8.38 -> 0 | F18: =F17 -> 1596 | G18: =F18-F17 -> 0 | H18: =H17 -> 353837 | I18: =SUM(H18-H17) -> 0 | J18: =IF(G18>0,I18/G18,0) -> 0 | K18: =K17 -> 1987 | L18: =K18-K17 -> 0 | M18: =M17 -> 145693 | N18: =M18-M17 -> 0 | O18: =SUM(L18*$J$1) -> 0 | P18: =P17 -> 1803 | Q18: =Q17 -> 152974 | R18: =Q18-Q17 -> 0 | S18: =SUM(P18-P17) -> 0 | T18: =SUM(S18*$T$2) -> 0 | U18: =SUM(G18+L18+S18) -> 0 | V18: =R18+N18+I18:I18 -> 0 | X18: =X17 -> 2418 | Y18: =X18-X17 -> 0 | Z18: =Z17 -> 135964.1 | AA18: =Z18-Z17 -> 0 | AB18: =SUM(Y18*$AB$2) -> 0 | AC18: =AC17 -> 1848 | AD18: =AC18-AC17 -> 0 | AE18: =AE17 -> 360299.4 | AF18: =AE18-AE17 -> 0 | AG18: =IF(AD18>0,AF18/AD18,0) -> 0 | AH18: =AF18+AA18 -> 0 | AI18: =SUM(AH18+V18) -> 0 | AJ18: =-tanks!AW19 -> 0 | AK18: =SUM(AJ18-AI18) -> 0 | AL18: =S18+L18+G18 -> 0 | AM18: =Y18+AD18 -> 0 | AN18: =AN17 -> 72 | AO18: =(AN18/100)*3000 -> 2160 | AP18: =AP17 -> 73 | AQ18: =(AP18/100)*3000 -> 2190 | AR18: =AR17 -> 61 | AS18: =(AR18/100)*3000 -> 1830 | AT18: =SUM(AO18+AQ18+AS18) -> 6180 | AU18: =AT17-AT18+AV18 -> 0 | AX18: =IF(AV18>0,AW18,AX17) -> 0.7
A19: =ELEC!C17 -> 43997 | B19: =B18 -> 169 | C19: =C18 -> 175 | D19: =C18-C19 -> 0 | E19: =D19*8.38 -> 0 | F19: =F18 -> 1596 | G19: =F19-F18 -> 0 | H19: =H18 -> 353837 | I19: =SUM(H19-H18) -> 0 | J19: =IF(G19>0,I19/G19,0) -> 0 | K19: =K18 -> 1987 | L19: =K19-K18 -> 0 | M19: =M18 -> 145693 | N19: =M19-M18 -> 0 | O19: =SUM(L19*$J$1) -> 0 | P19: =P18 -> 1803 | Q19: =Q18 -> 152974 | R19: =Q19-Q18 -> 0 | S19: =SUM(P19-P18) -> 0 | T19: =SUM(S19*$T$2) -> 0 | U19: =SUM(G19+L19+S19) -> 0 | V19: =R19+N19+I19:I19 -> 0 | X19: =X18 -> 2418 | Y19: =X19-X18 -> 0 | Z19: =Z18 -> 135964.1 | AA19: =Z19-Z18 -> 0 | AB19: =SUM(Y19*$AB$2) -> 0 | AC19: =AC18 -> 1848 | AD19: =AC19-AC18 -> 0 | AE19: =AE18 -> 360299.4 | AF19: =AE19-AE18 -> 0 | AG19: =IF(AD19>0,AF19/AD19,0) -> 0 | AH19: =AF19+AA19 -> 0 | AI19: =SUM(AH19+V19) -> 0 | AJ19: =-tanks!AW20 -> 0 | AK19: =SUM(AJ19-AI19) -> 0 | AL19: =S19+L20+G19 -> 0 | AM19: =Y19+AD19 -> 0 | AN19: =AN18 -> 72 | AO19: =(AN19/100)*3000 -> 2160 | AP19: =AP18 -> 73 | AQ19: =(AP19/100)*3000 -> 2190 | AR19: =AR18 -> 61 | AS19: =(AR19/100)*3000 -> 1830 | AT19: =SUM(AO19+AQ19+AS19) -> 6180 | AU19: =AT18-AT19+AV19 -> 0 | AX19: =IF(AV19>0,AW19,AX18) -> 0.7
A20: =ELEC!C18 -> 43998 | B20: =B19 -> 169 | C20: =C19 -> 175 | D20: =C19-C20 -> 0 | E20: =D20*8.38 -> 0 | F20: =F19 -> 1596 | G20: =F20-F19 -> 0 | H20: =H19 -> 353837 | I20: =SUM(H20-H19) -> 0 | J20: =IF(G20>0,I20/G20,0) -> 0 | K20: =K19 -> 1987 | L20: =K20-K19 -> 0 | M20: =M19 -> 145693 | N20: =M20-M19 -> 0 | O20: =SUM(L20*$J$1) -> 0 | P20: =P19 -> 1803 | Q20: =Q19 -> 152974 | R20: =Q20-Q19 -> 0 | S20: =SUM(P20-P19) -> 0 | T20: =SUM(S20*$T$2) -> 0 | U20: =SUM(G20+L20+S20) -> 0 | V20: =R20+N20+I20:I20 -> 0 | X20: =X19 -> 2418 | Y20: =X20-X19 -> 0 | Z20: =Z19 -> 135964.1 | AA20: =Z20-Z19 -> 0 | AB20: =SUM(Y20*$AB$2) -> 0 | AC20: =AC19 -> 1848 | AD20: =AC20-AC19 -> 0 | AE20: =AE19 -> 360299.4 | AF20: =AE20-AE19 -> 0 | AG20: =IF(AD20>0,AF20/AD20,0) -> 0 | AH20: =AF20+AA20 -> 0 | AI20: =SUM(AH20+V20) -> 0 | AJ20: =-tanks!AW21 -> 0 | AK20: =SUM(AJ20-AI20) -> 0 | AL20: =S20+L21+G20 -> 0 | AM20: =Y20+AD20 -> 0 | AN20: =AN19 -> 72 | AO20: =(AN20/100)*3000 -> 2160 | AP20: =AP19 -> 73 | AQ20: =(AP20/100)*3000 -> 2190 | AR20: =AR19 -> 61 | AS20: =(AR20/100)*3000 -> 1830 | AT20: =SUM(AO20+AQ20+AS20) -> 6180 | AU20: =AT19-AT20+AV20 -> 0 | AX20: =IF(AV20>0,AW20,AX19) -> 0.7
A21: =ELEC!C19 -> 43999 | B21: =B20 -> 169 | C21: =C20 -> 175 | D21: =C20-C21 -> 0 | E21: =D21*8.38 -> 0 | F21: =F20 -> 1596 | G21: =F21-F20 -> 0 | H21: =H20 -> 353837 | I21: =SUM(H21-H20) -> 0 | J21: =IF(G21>0,I21/G21,0) -> 0 | K21: =K20 -> 1987 | L21: =K21-K20 -> 0 | M21: =M20 -> 145693 | N21: =M21-M20 -> 0 | O21: =SUM(L21*$J$1) -> 0 | P21: =P20 -> 1803 | Q21: =Q20 -> 152974 | R21: =Q21-Q20 -> 0 | S21: =SUM(P21-P20) -> 0 | T21: =SUM(S21*$T$2) -> 0 | U21: =SUM(G21+L21+S21) -> 0 | V21: =R21+N21+I21:I21 -> 0 | X21: =X20 -> 2418 | Y21: =X21-X20 -> 0 | Z21: =Z20 -> 135964.1 | AA21: =Z21-Z20 -> 0 | AB21: =SUM(Y21*$AB$2) -> 0 | AC21: =AC20 -> 1848 | AD21: =AC21-AC20 -> 0 | AE21: =AE20 -> 360299.4 | AF21: =AE21-AE20 -> 0 | AG21: =IF(AD21>0,AF21/AD21,0) -> 0 | AH21: =AF21+AA21 -> 0 | AI21: =SUM(AH21+V21) -> 0 | AJ21: =-tanks!AW22 -> 0 | AK21: =SUM(AJ21-AI21) -> 0 | AL21: =S21+L21+G21 -> 0 | AM21: =Y21+AD21 -> 0 | AN21: =AN20 -> 72 | AO21: =(AN21/100)*3000 -> 2160 | AP21: =AP20 -> 73 | AQ21: =(AP21/100)*3000 -> 2190 | AR21: =AR20 -> 61 | AS21: =(AR21/100)*3000 -> 1830 | AT21: =SUM(AO21+AQ21+AS21) -> 6180 | AU21: =AT20-AT21+AV21 -> 0 | AX21: =IF(AV21>0,AW21,AX20) -> 0.7
A22: =ELEC!C20 -> 44000 | B22: =B21 -> 169 | C22: =C21 -> 175 | D22: =C21-C22 -> 0 | E22: =D22*8.38 -> 0 | F22: =F21 -> 1596 | G22: =F22-F21 -> 0 | H22: =H21 -> 353837 | I22: =SUM(H22-H21) -> 0 | J22: =IF(G22>0,I22/G22,0) -> 0 | K22: =K21 -> 1987 | L22: =K22-K21 -> 0 | M22: =M21 -> 145693 | N22: =M22-M21 -> 0 | O22: =SUM(L22*$J$1) -> 0 | P22: =P21 -> 1803 | Q22: =Q21 -> 152974 | R22: =Q22-Q21 -> 0 | S22: =SUM(P22-P21) -> 0 | T22: =SUM(S22*$T$2) -> 0 | U22: =SUM(G22+L22+S22) -> 0 | V22: =R22+N22+I22:I22 -> 0 | X22: =X21 -> 2418 | Y22: =X22-X21 -> 0 | Z22: =Z21 -> 135964.1 | AA22: =Z22-Z21 -> 0 | AB22: =SUM(Y22*$AB$2) -> 0 | AC22: =AC21 -> 1848 | AD22: =AC22-AC21 -> 0 | AE22: =AE21 -> 360299.4 | AF22: =AE22-AE21 -> 0 | AG22: =IF(AD22>0,AF22/AD22,0) -> 0 | AH22: =AF22+AA22 -> 0 | AI22: =SUM(AH22+V22) -> 0 | AJ22: =-tanks!AW23 -> 0 | AK22: =SUM(AJ22-AI22) -> 0 | AL22: =S22+L22+G22 -> 0 | AM22: =Y22+AD22 -> 0 | AN22: =AN21 -> 72 | AO22: =(AN22/100)*3000 -> 2160 | AP22: =AP21 -> 73 | AQ22: =(AP22/100)*3000 -> 2190 | AR22: =AR21 -> 61 | AS22: =(AR22/100)*3000 -> 1830 | AT22: =SUM(AO22+AQ22+AS22) -> 6180 | AU22: =AT21-AT22+AV22 -> 0 | AX22: =IF(AV22>0,AW22,AX21) -> 0.7
A23: =ELEC!C21 -> 44001 | B23: =B22 -> 169 | C23: =C22 -> 175 | D23: =C22-C23 -> 0 | E23: =D23*8.38 -> 0 | F23: =F22 -> 1596 | G23: =F23-F22 -> 0 | H23: =H22 -> 353837 | I23: =SUM(H23-H22) -> 0 | J23: =IF(G23>0,I23/G23,0) -> 0 | K23: =K22 -> 1987 | L23: =K23-K22 -> 0 | M23: =M22 -> 145693 | N23: =M23-M22 -> 0 | O23: =SUM(L23*$J$1) -> 0 | P23: =P22 -> 1803 | Q23: =Q22 -> 152974 | R23: =Q23-Q22 -> 0 | S23: =SUM(P23-P22) -> 0 | T23: =SUM(S23*$T$2) -> 0 | U23: =SUM(G23+L23+S23) -> 0 | V23: =R23+N23+I23:I23 -> 0 | X23: =X22 -> 2418 | Y23: =X23-X22 -> 0 | Z23: =Z22 -> 135964.1 | AA23: =Z23-Z22 -> 0 | AB23: =SUM(Y23*$AB$2) -> 0 | AC23: =AC22 -> 1848 | AD23: =AC23-AC22 -> 0 | AE23: =AE22 -> 360299.4 | AF23: =AE23-AE22 -> 0 | AG23: =IF(AD23>0,AF23/AD23,0) -> 0 | AH23: =AF23+AA23 -> 0 | AI23: =SUM(AH23+V23) -> 0 | AJ23: =-tanks!AW24 -> 0 | AK23: =SUM(AJ23-AI23) -> 0 | AL23: =S23+L23+G23 -> 0 | AM23: =Y23+AD23 -> 0 | AN23: =AN22 -> 72 | AO23: =(AN23/100)*3000 -> 2160 | AP23: =AP22 -> 73 | AQ23: =(AP23/100)*3000 -> 2190 | AR23: =AR22 -> 61 | AS23: =(AR23/100)*3000 -> 1830 | AT23: =SUM(AO23+AQ23+AS23) -> 6180 | AU23: =AT22-AT23+AV23 -> 0 | AX23: =IF(AV23>0,AW23,AX22) -> 0.7
A24: =ELEC!C22 -> 44002 | B24: =B23 -> 169 | C24: =C23 -> 175 | D24: =C23-C24 -> 0 | E24: =D24*8.38 -> 0 | F24: =F23 -> 1596 | G24: =F24-F23 -> 0 | H24: =H23 -> 353837 | I24: =SUM(H24-H23) -> 0 | J24: =IF(G24>0,I24/G24,0) -> 0 | K24: =K23 -> 1987 | L24: =K24-K23 -> 0 | M24: =M23 -> 145693 | N24: =M24-M23 -> 0 | O24: =SUM(L24*$J$1) -> 0 | P24: =P23 -> 1803 | Q24: =Q23 -> 152974 | R24: =Q24-Q23 -> 0 | S24: =SUM(P24-P23) -> 0 | T24: =SUM(S24*$T$2) -> 0 | U24: =SUM(G24+L24+S24) -> 0 | V24: =R24+N24+I24:I24 -> 0 | X24: =X23 -> 2418 | Y24: =X24-X23 -> 0 | Z24: =Z23 -> 135964.1 | AA24: =Z24-Z23 -> 0 | AB24: =SUM(Y24*$AB$2) -> 0 | AC24: =AC23 -> 1848 | AD24: =AC24-AC23 -> 0 | AE24: =AE23 -> 360299.4 | AF24: =AE24-AE23 -> 0 | AG24: =IF(AD24>0,AF24/AD24,0) -> 0 | AH24: =AF24+AA24 -> 0 | AI24: =SUM(AH24+V24) -> 0 | AJ24: =-tanks!AW25 -> 0 | AK24: =SUM(AJ24-AI24) -> 0 | AL24: =S24+L24+G24 -> 0 | AM24: =Y24+AD24 -> 0 | AN24: =AN23 -> 72 | AO24: =(AN24/100)*3000 -> 2160 | AP24: =AP23 -> 73 | AQ24: =(AP24/100)*3000 -> 2190 | AR24: =AR23 -> 61 | AS24: =(AR24/100)*3000 -> 1830 | AT24: =SUM(AO24+AQ24+AS24) -> 6180 | AU24: =AT23-AT24+AV24 -> 0 | AX24: =IF(AV24>0,AW24,AX23) -> 0.7
A25: =ELEC!C23 -> 44003 | B25: =B24 -> 169 | C25: =C24 -> 175 | D25: =C24-C25 -> 0 | E25: =D25*8.38 -> 0 | F25: =F24 -> 1596 | G25: =F25-F24 -> 0 | H25: =H24 -> 353837 | I25: =SUM(H25-H24) -> 0 | J25: =IF(G25>0,I25/G25,0) -> 0 | K25: =K24 -> 1987 | L25: =K25-K24 -> 0 | M25: =M24 -> 145693 | N25: =M25-M24 -> 0 | O25: =SUM(L25*$J$1) -> 0 | P25: =P24 -> 1803 | Q25: =Q24 -> 152974 | R25: =Q25-Q24 -> 0 | S25: =SUM(P25-P24) -> 0 | T25: =SUM(S25*$T$2) -> 0 | U25: =SUM(G25+L25+S25) -> 0 | V25: =R25+N25+I25:I25 -> 0 | X25: =X24 -> 2418 | Y25: =X25-X24 -> 0 | Z25: =Z24 -> 135964.1 | AA25: =Z25-Z24 -> 0 | AB25: =SUM(Y25*$AB$2) -> 0 | AC25: =AC24 -> 1848 | AD25: =AC25-AC24 -> 0 | AE25: =AE24 -> 360299.4 | AF25: =AE25-AE24 -> 0 | AG25: =IF(AD25>0,AF25/AD25,0) -> 0 | AH25: =AF25+AA25 -> 0 | AI25: =SUM(AH25+V25) -> 0 | AJ25: =-tanks!AW26 -> 0 | AK25: =SUM(AJ25-AI25) -> 0 | AL25: =S25+L25+G25 -> 0 | AM25: =Y25+AD25 -> 0 | AN25: =AN24 -> 72 | AO25: =(AN25/100)*3000 -> 2160 | AP25: =AP24 -> 73 | AQ25: =(AP25/100)*3000 -> 2190 | AR25: =AR24 -> 61 | AS25: =(AR25/100)*3000 -> 1830 | AT25: =SUM(AO25+AQ25+AS25) -> 6180 | AU25: =AT24-AT25+AV25 -> 0 | AX25: =IF(AV25>0,AW25,AX24) -> 0.7
A26: =ELEC!C24 -> 44004 | B26: =B25 -> 169 | C26: =C25 -> 175 | D26: =C25-C26 -> 0 | E26: =D26*8.38 -> 0 | F26: =F25 -> 1596 | G26: =F26-F25 -> 0 | H26: =H25 -> 353837 | I26: =SUM(H26-H25) -> 0 | J26: =IF(G26>0,I26/G26,0) -> 0 | K26: =K25 -> 1987 | L26: =K26-K25 -> 0 | M26: =M25 -> 145693 | N26: =M26-M25 -> 0 | O26: =SUM(L26*$J$1) -> 0 | P26: =P25 -> 1803 | Q26: =Q25 -> 152974 | R26: =Q26-Q25 -> 0 | S26: =SUM(P26-P25) -> 0 | T26: =SUM(S26*$T$2) -> 0 | U26: =SUM(G26+L26+S26) -> 0 | V26: =R26+N26+I26:I26 -> 0 | X26: =X25 -> 2418 | Y26: =X26-X25 -> 0 | Z26: =Z25 -> 135964.1 | AA26: =Z26-Z25 -> 0 | AB26: =SUM(Y26*$AB$2) -> 0 | AC26: =AC25 -> 1848 | AD26: =AC26-AC25 -> 0 | AE26: =AE25 -> 360299.4 | AF26: =AE26-AE25 -> 0 | AG26: =IF(AD26>0,AF26/AD26,0) -> 0 | AH26: =AF26+AA26 -> 0 | AI26: =SUM(AH26+V26) -> 0 | AJ26: =-tanks!AW27 -> 0 | AK26: =SUM(AJ26-AI26) -> 0 | AL26: =S26+L26+G26 -> 0 | AM26: =Y26+AD26 -> 0 | AN26: =AN25 -> 72 | AO26: =(AN26/100)*3000 -> 2160 | AP26: =AP25 -> 73 | AQ26: =(AP26/100)*3000 -> 2190 | AR26: =AR25 -> 61 | AS26: =(AR26/100)*3000 -> 1830 | AT26: =SUM(AO26+AQ26+AS26) -> 6180 | AU26: =AT25-AT26+AV26 -> 0 | AX26: =IF(AV26>0,AW26,AX25) -> 0.7
A27: =ELEC!C25 -> 44005 | B27: =B26 -> 169 | C27: =C26 -> 175 | D27: =C26-C27 -> 0 | E27: =D27*8.38 -> 0 | F27: =F26 -> 1596 | G27: =F27-F26 -> 0 | H27: =H26 -> 353837 | I27: =SUM(H27-H26) -> 0 | J27: =IF(G27>0,I27/G27,0) -> 0 | K27: =K26 -> 1987 | L27: =K27-K26 -> 0 | M27: =M26 -> 145693 | N27: =M27-M26 -> 0 | O27: =SUM(L27*$J$1) -> 0 | P27: =P26 -> 1803 | Q27: =Q26 -> 152974 | R27: =Q27-Q26 -> 0 | S27: =SUM(P27-P26) -> 0 | T27: =SUM(S27*$T$2) -> 0 | U27: =SUM(G27+L27+S27) -> 0 | V27: =R27+N27+I27:I27 -> 0 | X27: =X26 -> 2418 | Y27: =X27-X26 -> 0 | Z27: =Z26 -> 135964.1 | AA27: =Z27-Z26 -> 0 | AB27: =SUM(Y27*$AB$2) -> 0 | AC27: =AC26 -> 1848 | AD27: =AC27-AC26 -> 0 | AE27: =AE26 -> 360299.4 | AF27: =AE27-AE26 -> 0 | AG27: =IF(AD27>0,AF27/AD27,0) -> 0 | AH27: =AF27+AA27 -> 0 | AI27: =SUM(AH27+V27) -> 0 | AJ27: =-tanks!AW28 -> 0 | AK27: =SUM(AJ27-AI27) -> 0 | AL27: =S27+L27+G27 -> 0 | AM27: =Y27+AD27 -> 0 | AN27: =AN26 -> 72 | AO27: =(AN27/100)*3000 -> 2160 | AP27: =AP26 -> 73 | AQ27: =(AP27/100)*3000 -> 2190 | AR27: =AR26 -> 61 | AS27: =(AR27/100)*3000 -> 1830 | AT27: =SUM(AO27+AQ27+AS27) -> 6180 | AU27: =AT26-AT27+AV27 -> 0 | AX27: =IF(AV27>0,AW27,AX26) -> 0.7
A28: =ELEC!C26 -> 44006 | B28: =B27 -> 169 | C28: =C27 -> 175 | D28: =C27-C28 -> 0 | E28: =D28*8.38 -> 0 | F28: =F27 -> 1596 | G28: =F28-F27 -> 0 | H28: =H27 -> 353837 | I28: =SUM(H28-H27) -> 0 | J28: =IF(G28>0,I28/G28,0) -> 0 | K28: =K27 -> 1987 | L28: =K28-K27 -> 0 | M28: =M27 -> 145693 | N28: =M28-M27 -> 0 | O28: =SUM(L28*$J$1) -> 0 | P28: =P27 -> 1803 | Q28: =Q27 -> 152974 | R28: =Q28-Q27 -> 0 | S28: =SUM(P28-P27) -> 0 | T28: =SUM(S28*$T$2) -> 0 | U28: =SUM(G28+L28+S28) -> 0 | V28: =R28+N28+I28:I28 -> 0 | X28: =X27 -> 2418 | Y28: =X28-X27 -> 0 | Z28: =Z27 -> 135964.1 | AA28: =Z28-Z27 -> 0 | AB28: =SUM(Y28*$AB$2) -> 0 | AC28: =AC27 -> 1848 | AD28: =AC28-AC27 -> 0 | AE28: =AE27 -> 360299.4 | AF28: =AE28-AE27 -> 0 | AG28: =IF(AD28>0,AF28/AD28,0) -> 0 | AH28: =AF28+AA28 -> 0 | AI28: =SUM(AH28+V28) -> 0 | AJ28: =-tanks!AW29 -> 0 | AK28: =SUM(AJ28-AI28) -> 0 | AL28: =S28+L28+G28 -> 0 | AM28: =Y28+AD28 -> 0 | AN28: =AN27 -> 72 | AO28: =(AN28/100)*3000 -> 2160 | AP28: =AP27 -> 73 | AQ28: =(AP28/100)*3000 -> 2190 | AR28: =AR27 -> 61 | AS28: =(AR28/100)*3000 -> 1830 | AT28: =SUM(AO28+AQ28+AS28) -> 6180 | AU28: =AT27-AT28+AV28 -> 0 | AX28: =IF(AV28>0,AW28,AX27) -> 0.7
A29: =ELEC!C27 -> 44007 | B29: =B28 -> 169 | C29: =C28 -> 175 | D29: =C28-C29 -> 0 | E29: =D29*8.38 -> 0 | F29: =F28 -> 1596 | G29: =F29-F28 -> 0 | H29: =H28 -> 353837 | I29: =SUM(H29-H28) -> 0 | J29: =IF(G29>0,I29/G29,0) -> 0 | K29: =K28 -> 1987 | L29: =K29-K28 -> 0 | M29: =M28 -> 145693 | N29: =M29-M28 -> 0 | O29: =SUM(L29*$J$1) -> 0 | P29: =P28 -> 1803 | Q29: =Q28 -> 152974 | R29: =Q29-Q28 -> 0 | S29: =SUM(P29-P28) -> 0 | T29: =SUM(S29*$T$2) -> 0 | U29: =SUM(G29+L29+S29) -> 0 | V29: =R29+N29+I29:I29 -> 0 | X29: =X28 -> 2418 | Y29: =X29-X28 -> 0 | Z29: =Z28 -> 135964.1 | AA29: =Z29-Z28 -> 0 | AB29: =SUM(Y29*$AB$2) -> 0 | AC29: =AC28 -> 1848 | AD29: =AC29-AC28 -> 0 | AE29: =AE28 -> 360299.4 | AF29: =AE29-AE28 -> 0 | AG29: =IF(AD29>0,AF29/AD29,0) -> 0 | AH29: =AF29+AA29 -> 0 | AI29: =SUM(AH29+V29) -> 0 | AJ29: =-tanks!AW30 -> 0 | AK29: =SUM(AJ29-AI29) -> 0 | AL29: =S29+L29+G29 -> 0 | AM29: =Y29+AD29 -> 0 | AN29: =AN28 -> 72 | AO29: =(AN29/100)*3000 -> 2160 | AP29: =AP28 -> 73 | AQ29: =(AP29/100)*3000 -> 2190 | AR29: =AR28 -> 61 | AS29: =(AR29/100)*3000 -> 1830 | AT29: =SUM(AO29+AQ29+AS29) -> 6180 | AU29: =AT28-AT29+AV29 -> 0 | AX29: =IF(AV29>0,AW29,AX28) -> 0.7
A30: =ELEC!C28 -> 44008 | B30: =B29 -> 169 | C30: =C29 -> 175 | D30: =C29-C30 -> 0 | E30: =D30*8.38 -> 0 | F30: =F29 -> 1596 | G30: =F30-F29 -> 0 | H30: =H29 -> 353837 | I30: =SUM(H30-H29) -> 0 | J30: =IF(G30>0,I30/G30,0) -> 0 | K30: =K29 -> 1987 | L30: =K30-K29 -> 0 | M30: =M29 -> 145693 | N30: =M30-M29 -> 0 | O30: =SUM(L30*$J$1) -> 0 | P30: =P29 -> 1803 | Q30: =Q29 -> 152974 | R30: =Q30-Q29 -> 0 | S30: =SUM(P30-P29) -> 0 | T30: =SUM(S30*$T$2) -> 0 | U30: =SUM(G30+L30+S30) -> 0 | V30: =R30+N30+I30:I30 -> 0 | X30: =X29 -> 2418 | Y30: =X30-X29 -> 0 | Z30: =Z29 -> 135964.1 | AA30: =Z30-Z29 -> 0 | AB30: =SUM(Y30*$AB$2) -> 0 | AC30: =AC29 -> 1848 | AD30: =AC30-AC29 -> 0 | AE30: =AE29 -> 360299.4 | AF30: =AE30-AE29 -> 0 | AG30: =IF(AD30>0,AF30/AD30,0) -> 0 | AH30: =AF30+AA30 -> 0 | AI30: =SUM(AH30+V30) -> 0 | AJ30: =-tanks!AW31 -> 0 | AK30: =SUM(AJ30-AI30) -> 0 | AL30: =S30+L30+G30 -> 0 | AM30: =Y30+AD30 -> 0 | AN30: =AN29 -> 72 | AO30: =(AN30/100)*3000 -> 2160 | AP30: =AP29 -> 73 | AQ30: =(AP30/100)*3000 -> 2190 | AR30: =AR29 -> 61 | AS30: =(AR30/100)*3000 -> 1830 | AT30: =SUM(AO30+AQ30+AS30) -> 6180 | AU30: =AT29-AT30+AV30 -> 0 | AX30: =IF(AV30>0,AW30,AX29) -> 0.7
