Workbook

Sheet Total
A1: Site Name | B1: Day | C1: Month | D1: Year | E1: Total Electricity Kwh | F1: Electricity Tariff ($/Kwh) | G1: Total Fuel Oil (Liters) | H1: Fuel Oil $/Liter | I1: LPG (Kg) | J1: LPG $/Kg | K1: Water Utility Supply (m3) m3 | L1: Water Utility Supply (m3) $/m3 | M1: Irrigation Water (m3) m3 | N1: Irrigation water $/m3 | O1: Room Nights
A2: Beirut | B2: 1 | C2: 7 | D2: 2020 | E2: =ELEC!N3 -> 18028 | F2: =SUM('EDl log'!T4) -> 0.080257859 | G2: =-tanks!AW6 -> 417 | H2: =SUM(tanks!AV6) -> 0.4624 | I2: =('B5'!AU5)*0.51 -> 45.9 | J2: ='B5'!AX5/0.51 -> 1.372549 | K2: =WATER!I6 -> 0 | L2: =SUM(WATER!J6) -> 0 | M2: =WATER!Q6 -> 0 | N2: 0.6 | O2: =ELEC!B3 -> 12.995
A3: Beirut | B3: =B2+1 -> 2 | C3: 7 | D3: 2020 | E3: =ELEC!N4 -> 18859 | F3: =SUM('EDl log'!T5) -> 0.14885239 | G3: =-tanks!AW7 -> 735 | H3: =SUM(tanks!AV7) -> 0.4624 | I3: =('B5'!AU6)*0.51 -> 204 | J3: ='B5'!AX6/0.51 -> 1.372549 | K3: =WATER!I7 -> 393 | L3: =SUM(WATER!J7) -> 0.61561192 | M3: =WATER!Q7 -> 0 | N3: 0.6 | O3: =ELEC!B4 -> 8.97
A4: Beirut | B4: =B3+1 -> 3 | C4: 7 | D4: 2020 | E4: =ELEC!N5 -> 20891 | F4: =SUM('EDl log'!T6) -> 0.13047965 | G4: =-tanks!AW8 -> 388 | H4: =SUM(tanks!AV8) -> 0.4624 | I4: =('B5'!AU7)*0.51 -> 91.8 | J4: ='B5'!AX7/0.51 -> 1.372549 | K4: =WATER!I8 -> 0 | L4: =SUM(WATER!J8) -> 0 | M4: =WATER!Q8 -> 0 | N4: 0.6 | O4: =ELEC!B5 -> 20.01
A5: Beirut | B5: =B4+1 -> 4 | C5: 7 | D5: 2020 | E5: =ELEC!N6 -> 18152 | F5: =SUM('EDl log'!T7) -> 0.14974971 | G5: =-tanks!AW9 -> 534 | H5: =SUM(tanks!AV9) -> 0.4624 | I5: =('B5'!AU8)*0.51 -> 15.3 | J5: ='B5'!AX8/0.51 -> 1.372549 | K5: =WATER!I9 -> 563 | L5: =SUM(WATER!J9) -> 0.42972555 | M5: =WATER!Q9 -> 0 | N5: 0.6 | O5: =ELEC!B6 -> 20.01
A6: Beirut | B6: =B5+1 -> 5 | C6: 7 | D6: 2020 | E6: =ELEC!N7 -> 18161 | F6: =SUM('EDl log'!T8) -> 0.15382108 | G6: =-tanks!AW10 -> 338 | H6: =SUM(tanks!AV10) -> 0.4624 | I6: =('B5'!AU9)*0.51 -> 61.2 | J6: ='B5'!AX9/0.51 -> 1.372549 | K6: =WATER!I10 -> 45 | L6: =SUM(WATER!J10) -> 5.3763441 | M6: =WATER!Q10 -> 0 | N6: 0.6 | O6: =ELEC!B7 -> 18.009
A7: Beirut | B7: =B6+1 -> 6 | C7: 7 | D7: 2020 | E7: =ELEC!N8 -> 20764 | F7: =SUM('EDl log'!T9) -> 0.12134878 | G7: =-tanks!AW11 -> 430 | H7: =SUM(tanks!AV11) -> 0.4624 | I7: =('B5'!AU10)*0.51 -> 76.5 | J7: ='B5'!AX10/0.51 -> 1.372549 | K7: =WATER!I11 -> 227 | L7: =SUM(WATER!J11) -> 1.0657951 | M7: =WATER!Q11 -> 0 | N7: 0.6 | O7: =ELEC!B8 -> 18.998
A8: Beirut | B8: =B7+1 -> 7 | C8: 7 | D8: 2020 | E8: =ELEC!N9 -> 20479 | F8: =SUM('EDl log'!T10) -> 0.1280995 | G8: =-tanks!AW12 -> 657 | H8: =SUM(tanks!AV12) -> 0.4624 | I8: =('B5'!AU11)*0.51 -> 76.5 | J8: ='B5'!AX11/0.51 -> 1.372549 | K8: =WATER!I12 -> 201 | L8: =SUM(WATER!J12) -> 1.2036591 | M8: =WATER!Q12 -> 0 | N8: 0.6 | O8: =ELEC!B9 -> 18.009
A9: Beirut | B9: =B8+1 -> 8 | C9: 7 | D9: 2020 | E9: =ELEC!N10 -> 23543 | F9: =SUM('EDl log'!T11) -> 0.10603817 | G9: =-tanks!AW13 -> 512 | H9: =SUM(tanks!AV13) -> 0.5284 | I9: =('B5'!AU12)*0.51 -> 107.1 | J9: ='B5'!AX12/0.51 -> 1.372549 | K9: =WATER!I13 -> 0 | L9: =SUM(WATER!J13) -> 0 | M9: =WATER!Q13 -> 0 | N9: 0.6 | O9: =ELEC!B10 -> 20.01
A10: Beirut | B10: =B9+1 -> 9 | C10: 7 | D10: 2020 | E10: =ELEC!N11 -> 18109 | F10: =SUM('EDl log'!T12) -> 0.19086406 | G10: =-tanks!AW14 -> 256 | H10: =SUM(tanks!AV14) -> 0.5284 | I10: =('B5'!AU13)*0.51 -> 198.9 | J10: ='B5'!AX13/0.51 -> 1.372549 | K10: =WATER!I14 -> 0 | L10: =SUM(WATER!J14) -> 0 | M10: =WATER!Q14 -> 0 | N10: 0.6 | O10: =ELEC!B11 -> 25.001
A11: Beirut | B11: =B10+1 -> 10 | C11: 7 | D11: 2020 | E11: =ELEC!N12 -> 20053 | F11: =SUM('EDl log'!T13) -> 0.05741841 | G11: =-tanks!AW15 -> 342.8 | H11: =SUM(tanks!AV15) -> 0.5284 | I11: =('B5'!AU14)*0.51 -> 91.8 | J11: ='B5'!AX14/0.51 -> 1.372549 | K11: =WATER!I15 -> 112 | L11: =SUM(WATER!J15) -> 2.1601382 | M11: =WATER!Q15 -> 0 | N11: 0.6 | O11: =ELEC!B12 -> 25.99
A12: Beirut | B12: =B11+1 -> 11 | C12: 7 | D12: 2020 | E12: =ELEC!N13 -> 21073 | F12: =SUM('EDl log'!T14) -> 0.15243522 | G12: =-tanks!AW16 -> 335 | H12: =SUM(tanks!AV16) -> 0.5284 | I12: =('B5'!AU15)*0.51 -> 61.2 | J12: ='B5'!AX15/0.51 -> 1.372549 | K12: =WATER!I16 -> 0 | L12: =SUM(WATER!J16) -> 0 | M12: =WATER!Q16 -> 0 | N12: 0.6 | O12: =ELEC!B13 -> 37.95
A13: Beirut | B13: =B12+1 -> 12 | C13: 7 | D13: 2020 | E13: =ELEC!N14 -> 20084 | F13: =SUM('EDl log'!T15) -> 0.15988382 | G13: =-tanks!AW17 -> 220 | H13: =SUM(tanks!AV17) -> 0.5284 | I13: =('B5'!AU16)*0.51 -> 15.3 | J13: ='B5'!AX16/0.51 -> 1.372549 | K13: =WATER!I17 -> 271 | L13: =SUM(WATER!J17) -> 0.89275086 | M13: =WATER!Q17 -> 0 | N13: 0.6 | O13: =ELEC!B14 -> 23
A14: Beirut | B14: =B13+1 -> 13 | C14: 7 | D14: 2020 | E14: =ELEC!N15 -> 19864 | F14: =SUM('EDl log'!T16) -> 0.13639207 | G14: =-tanks!AW18 -> 165 | H14: =SUM(tanks!AV18) -> 0.5284 | I14: =('B5'!AU17)*0.51 -> 30.6 | J14: ='B5'!AX17/0.51 -> 1.372549 | K14: =WATER!I18 -> 0 | L14: =SUM(WATER!J18) -> 0 | M14: =WATER!Q18 -> 0 | N14: 0.6 | O14: =ELEC!B15 -> 27.991
... A31: Beirut | B31: =B30+1 -> 30 | C31: 7 | D31: 2020 | E31: =ELEC!N32 -> 0 | F31: =SUM('EDl log'!T33) -> 0 | G31: =-tanks!AW35 -> 0 | H31: =SUM(tanks!AV35) -> 0.535 | I31: =('B5'!AU34)*0.51 -> 0 | J31: ='B5'!AX34/0.51 -> 1.372549 | K31: =WATER!I35 -> 0 | L31: =SUM(WATER!J35) -> 0 | M31: =WATER!Q35 -> 0 | N31: 0.6 | O31: =ELEC!B32 -> 0
A32: Beirut | B32: =B31+1 -> 31 | C32: 7 | D32: 2020 | E32: =ELEC!N33 -> 0 | F32: =SUM('EDl log'!T35) -> 0 | G32: =-tanks!AW37 -> 0 | H32: =SUM(tanks!AV37) -> 0 | I32: =('B5'!AU36)*0.51 -> 2279.7 | J32: ='B5'!AX36/0.51 -> 0 | K32: =WATER!I37 -> 3403 | L32: =SUM(WATER!J37) -> 0 | M32: =WATER!Q37 -> 0 | N32: 0.6 | O32: =ELEC!B33 -> 32.52936

Sheet Submetering
A1: Site Name | B1: Day | C1: Month | D1: Year | E1: ATS1 Kwh | F1: ATS2 Kwh | G1: ATS3 Kwh | H1: ATS4 Kwh | I1: ATS5 Kwh | J1: Guest (m3) | K1: Kitchen & Laundry (m3) | L1: Room Nights
A2: Beirut | B2: 1 | C2: 7 | D2: 2020 | E2: =ELEC!M3 -> 7896 | F2: =ELEC!K3 -> 2847 | G2: =ELEC!I3 -> 1774 | H2: =ELEC!E3 -> 3656 | I2: =ELEC!G3 -> 1855 | J2: =WATER!Y6 -> 115 | K2: =WATER!AJ6 -> 10 | L2: =ELEC!B3 -> 12.995
A3: Beirut | B3: =B2+1 -> 2 | C3: 7 | D3: 2020 | E3: =ELEC!M4 -> 8320 | F3: =ELEC!K4 -> 3057 | G3: =ELEC!I4 -> 1778 | H3: =ELEC!E4 -> 3856 | I3: =ELEC!G4 -> 1848 | J3: =WATER!Y7 -> 69 | K3: =WATER!AJ7 -> 48 | L3: =ELEC!B4 -> 8.97
A4: Beirut | B4: =B3+1 -> 3 | C4: 7 | D4: 2020 | E4: =ELEC!M5 -> 9244 | F4: =ELEC!K5 -> 3108 | G4: =ELEC!I5 -> 2010 | H4: =ELEC!E5 -> 4478 | I4: =ELEC!G5 -> 2051 | J4: =WATER!Y8 -> 48 | K4: =WATER!AJ8 -> 52 | L4: =ELEC!B5 -> 20.01
A5: Beirut | B5: =B4+1 -> 4 | C5: 7 | D5: 2020 | E5: =ELEC!M6 -> 8346 | F5: =ELEC!K6 -> 2220 | G5: =ELEC!I6 -> 1890 | H5: =ELEC!E6 -> 3772 | I5: =ELEC!G6 -> 1924 | J5: =WATER!Y9 -> 180 | K5: =WATER!AJ9 -> 73 | L5: =ELEC!B6 -> 20.01
A6: Beirut | B6: =B5+1 -> 5 | C6: 7 | D6: 2020 | E6: =ELEC!M7 -> 6172 | F6: =ELEC!K7 -> 2178 | G6: =ELEC!I7 -> 1996 | H6: =ELEC!E7 -> 5838 | I6: =ELEC!G7 -> 1977 | J6: =WATER!Y10 -> 2 | K6: =WATER!AJ10 -> 1 | L6: =ELEC!B7 -> 18.009
A7: Beirut | B7: =B6+1 -> 6 | C7: 7 | D7: 2020 | E7: =ELEC!M8 -> 8976 | F7: =ELEC!K8 -> 2448 | G7: =ELEC!I8 -> 2216 | H7: =ELEC!E8 -> 5028 | I7: =ELEC!G8 -> 2096 | J7: =WATER!Y11 -> 110 | K7: =WATER!AJ11 -> 43 | L7: =ELEC!B8 -> 18.998
A8: Beirut | B8: =B7+1 -> 7 | C8: 7 | D8: 2020 | E8: =ELEC!M9 -> 6248 | F8: =ELEC!K9 -> 2470 | G8: =ELEC!I9 -> 2320 | H8: =ELEC!E9 -> 7468 | I8: =ELEC!G9 -> 1973 | J8: =WATER!Y12 -> 111 | K8: =WATER!AJ12 -> 53 | L8: =ELEC!B9 -> 18.009
A9: Beirut | B9: =B8+1 -> 8 | C9: 7 | D9: 2020 | E9: =ELEC!M10 -> 10244 | F9: =ELEC!K10 -> 3566 | G9: =ELEC!I10 -> 2396 | H9: =ELEC!E10 -> 5190 | I9: =ELEC!G10 -> 2147 | J9: =WATER!Y13 -> 0 | K9: =WATER!AJ13 -> 0 | L9: =ELEC!B10 -> 20.01
A10: Beirut | B10: =B9+1 -> 9 | C10: 7 | D10: 2020 | E10: =ELEC!M11 -> 7658 | F10: =ELEC!K11 -> 2358 | G10: =ELEC!I11 -> 2000 | H10: =ELEC!E11 -> 4328 | I10: =ELEC!G11 -> 1765 | J10: =WATER!Y14 -> 0 | K10: =WATER!AJ14 -> 0 | L10: =ELEC!B11 -> 25.001
A11: Beirut | B11: =B10+1 -> 10 | C11: 7 | D11: 2020 | E11: =ELEC!M12 -> 3718 | F11: =ELEC!K12 -> 2532 | G11: =ELEC!I12 -> 2376 | H11: =ELEC!E12 -> 9500 | I11: =ELEC!G12 -> 1927 | J11: =WATER!Y15 -> 91 | K11: =WATER!AJ15 -> 24 | L11: =ELEC!B12 -> 25.99
A12: Beirut | B12: =B11+1 -> 11 | C12: 7 | D12: 2020 | E12: =ELEC!M13 -> 6858 | F12: =ELEC!K13 -> 3036 | G12: =ELEC!I13 -> 2372 | H12: =ELEC!E13 -> 6870 | I12: =ELEC!G13 -> 1937 | J12: =WATER!Y16 -> 0 | K12: =WATER!AJ16 -> 0 | L12: =ELEC!B13 -> 37.95
A13: Beirut | B13: =B12+1 -> 12 | C13: 7 | D13: 2020 | E13: =ELEC!M14 -> 8808 | F13: =ELEC!K14 -> 2836 | G13: =ELEC!I14 -> 2350 | H13: =ELEC!E14 -> 4100 | I13: =ELEC!G14 -> 1990 | J13: =WATER!Y17 -> 42 | K13: =WATER!AJ17 -> 66 | L13: =ELEC!B14 -> 23
A14: Beirut | B14: =B13+1 -> 13 | C14: 7 | D14: 2020 | E14: =ELEC!M15 -> 8276 | F14: =ELEC!K15 -> 2050 | G14: =ELEC!I15 -> 2418 | H14: =ELEC!E15 -> 4884 | I14: =ELEC!G15 -> 2236 | J14: =WATER!Y18 -> 3 | K14: =WATER!AJ18 -> 0 | L14: =ELEC!B15 -> 27.991
... A31: Beirut | B31: =B30+1 -> 30 | C31: 7 | D31: 2020 | E31: =ELEC!M32 -> 0 | F31: =ELEC!K32 -> 0 | G31: =ELEC!I32 -> 0 | H31: =ELEC!E32 -> 0 | I31: =ELEC!G32 -> 0 | J31: =WATER!Y35 -> 0 | K31: =WATER!AJ35 -> 0 | L31: =ELEC!B32 -> 0
A32: Beirut | B32: =B31+1 -> 31 | C32: 7 | D32: 2020 | E32: =ELEC!M33 -> 0 | F32: =ELEC!K33 -> 0 | G32: =ELEC!I33 -> 0 | H32: =ELEC!E33 -> 0 | I32: =ELEC!G33 -> 0 | J32: =WATER!Y36 -> 0 | K32: =WATER!AJ37 -> 702 | L32: =ELEC!B33 -> 32.52936

Sheet ELEC
A1: OOC | B1: Room OCC | D1: MDB3 | E1: MDB3/day | F1: EMDB2 | G1: EMDB2/day | H1: EMDB1 | I1: EMDB1/day | J1: MDB2 | K1: mdb2/day | L1: MDB1 | M1: MDB1/Day | N1: Total KWH | O1: KWH/Rooc | P1: Gen MHW | Q1: Gen/Day KWH | R1: EDL KWH | S1: CH1 RH | T1: RH | U1: C1h1 power | V1: CH1 Con KWH | W1: CH2 RH | X1: RH | Y1: Ch2 power | Z1: CH2 Con KWH | AA1: CH3 RH | AB1: RH | AC1: Ch3 power | AD1: CH3 Con KWH | AE1: RH total | AF1: KWH total | AG1: AVG chiller KW/Hr
A2: =[1]ELEC!A32 -> 0.0478 | B2: =[1]ELEC!B32 -> 10.994 | C2: 44012 | D2: =[1]ELEC!D32 -> 31865522 | E2: =[1]ELEC!E32 -> 4902 | F2: =[1]ELEC!F32 -> 3741866 | G2: =[1]ELEC!G32 -> 1782 | H2: =[1]ELEC!H32 -> 17521942 | I2: =[1]ELEC!I32 -> 1668 | J2: =[1]ELEC!J32 -> 28525590 | K2: =[1]ELEC!K32 -> 2504 | ... AI2: =[1]ELEC!AI32 -> -94226
A3: ='General information '!F6 -> 0.0565 | B3: =SUM(230*A3) -> 12.995 | C3: 44013 | D3: 31869178 | E3: =D3-D2 -> 3656 | F3: 3743721 | G3: =F3-F2 -> 1855 | H3: 17523716 | I3: =H3-H2 -> 1774 | J3: 28528437 | K3: =J3-J2 -> 2847 | L3: 23241532 | M3: =L3-L2 -> 7896 | N3: =M3+K3+I3+G3+E3 -> 18028 | O3: =IF(B3>0,N3/B3,0) -> 1387.3028 | P3: 15689 | Q3: =(P3-P2)*1000 -> 14000 | R3: =+N3-Q3 -> 4028 | S3: 8899 | T3: =S3-S2 -> 16 | U3: 141258 | V3: =U3-U2 -> 3740 | W3: 31853 | X3: =W3-W2 -> 0 | Y3: =Y2 -> 625865 | Z3: =Y3-Y2 -> 0 | AA3: 35228 | AB3: =AA3-AA2 -> 0 | AC3: =AC2 -> 814514 | AD3: =AC3-AC2 -> 0 | AE3: =AB3+X3+T3 -> 16 | AF3: =V3+Z3+AD3 -> 3740 | AG3: =IF(AE3>0,AF3/AE3,0) -> 233.75
A4: ='General information '!F7 -> 0.039 | B4: =SUM(230*A4) -> 8.97 | C4: 44014 | D4: 31873034 | E4: =D4-D3 -> 3856 | F4: 3745569 | G4: =F4-F3 -> 1848 | H4: 17525494 | I4: =H4-H3 -> 1778 | J4: 28531494 | K4: =J4-J3 -> 3057 | L4: 23249852 | M4: =L4-L3 -> 8320 | N4: =M4+K4+I4+G4+E4 -> 18859 | O4: =IF(B4>0,N4/B4,0) -> 2102.4526 | P4: 15702 | Q4: =(P4-P3)*1000 -> 13000 | R4: =N4-Q4 -> 5859 | S4: 8921 | T4: =S4-S3 -> 22 | U4: 146286 | V4: =U4-U3 -> 5028 | W4: =W3 -> 31853 | X4: =W4-W3 -> 0 | Y4: =Y3 -> 625865 | Z4: =Y4-Y3 -> 0 | AA4: =AA3 -> 35228 | AB4: =AA4-AA3 -> 0 | AC4: =AC3 -> 814514 | AD4: =AC4-AC3 -> 0 | AE4: =AB4+X4+T4 -> 22 | AF4: =V4+Z4+AD4 -> 5028 | AG4: =IF(AE4>0,AF4/AE4,0) -> 228.54545
A5: ='General information '!F8 -> 0.087 | B5: =SUM(230*A5) -> 20.01 | C5: 44015 | D5: 31877512 | E5: =D5-D4 -> 4478 | F5: 3747620 | G5: =F5-F4 -> 2051 | H5: 17527504 | I5: =H5-H4 -> 2010 | J5: 28534602 | K5: =J5-J4 -> 3108 | L5: 23259096 | M5: =L5-L4 -> 9244 | N5: =M5+K5+I5+G5+E5 -> 20891 | O5: =IF(B5>0,N5/B5,0) -> 1044.028 | P5: 15716 | Q5: =(P5-P4)*1000 -> 14000 | R5: =N5-Q5 -> 6891 | S5: 8939 | T5: =S5-S4 -> 18 | U5: 150883 | V5: =U5-U4 -> 4597 | W5: =W4 -> 31853 | X5: =W5-W4 -> 0 | Y5: =Y4 -> 625865 | Z5: =Y5-Y4 -> 0 | AA5: 35229 | AB5: =AA5-AA4 -> 1 | AC5: 814845 | AD5: =AC5-AC4 -> 331 | AE5: =AB5+X5+T5 -> 19 | AF5: =V5+Z5+AD5 -> 4928 | AG5: =IF(AE5>0,AF5/AE5,0) -> 259.36842 | AI5: =R5-'EDl log'!B3 -> -105299
A6: ='General information '!F9 -> 0.087 | B6: =SUM(230*A6) -> 20.01 | C6: 44016 | D6: 31881284 | E6: =D6-D5 -> 3772 | F6: 3749544 | G6: =F6-F5 -> 1924 | H6: 17529394 | I6: =H6-H5 -> 1890 | J6: 28536822 | K6: =J6-J5 -> 2220 | L6: 23267442 | M6: =L6-L5 -> 8346 | N6: =M6+K6+I6+G6+E6 -> 18152 | O6: =IF(B6>0,N6/B6,0) -> 907.14643 | P6: 15732 | Q6: =(P6-P5)*1000 -> 16000 | R6: =N6-Q6 -> 2152 | S6: 8959 | T6: =S6-S5 -> 20 | U6: 155326 | V6: =U6-U5 -> 4443 | W6: =W5 -> 31853 | X6: =W6-W5 -> 0 | Y6: =Y5 -> 625865 | Z6: =Y6-Y5 -> 0 | AA6: 35229 | AB6: =AA6-AA5 -> 0 | AC6: =AC5 -> 814845 | AD6: =AC6-AC5 -> 0 | AE6: =AB6+X6+T6 -> 20 | AF6: =V6+Z6+AD6 -> 4443 | AG6: =IF(AE6>0,AF6/AE6,0) -> 222.15 | AI6: =R6-'EDl log'!B4 -> -111978
A7: ='General information '!F10 -> 0.0783 | B7: =SUM(230*A7) -> 18.009 | C7: 44017 | D7: 31887122 | E7: =D7-D6 -> 5838 | F7: 3751521 | G7: =F7-F6 -> 1977 | H7: 17531390 | I7: =H7-H6 -> 1996 | J7: 28539000 | K7: =J7-J6 -> 2178 | L7: 23273614 | M7: =L7-L6 -> 6172 | N7: =M7+K7+I7+G7+E7 -> 18161 | O7: =IF(B7>0,N7/B7,0) -> 1008.4402 | P7: 15747 | Q7: =(P7-P6)*1000 -> 15000 | R7: =N7-Q7 -> 3161 | S7: 8971 | T7: =S7-S6 -> 12 | U7: 158305 | V7: =U7-U6 -> 2979 | W7: 31853 | X7: =W7-W6 -> 0 | Y7: =Y6 -> 625865 | Z7: =Y7-Y6 -> 0 | AA7: 35238 | AB7: =AA7-AA6 -> 9 | AC7: 816851 | AD7: =AC7-AC6 -> 2006 | AE7: =AB7+X7+T7 -> 21 | AF7: =V7+Z7+AD7 -> 4985 | AG7: =IF(AE7>0,AF7/AE7,0) -> 237.38095 | AI7: =R7-'EDl log'!B5 -> -114241
A8: ='General information '!F11 -> 0.0826 | B8: =SUM(230*A8) -> 18.998 | C8: 44018 | D8: 31892150 | E8: =D8-D7 -> 5028 | F8: 3753617 | G8: =F8-F7 -> 2096 | H8: 17533606 | I8: =H8-H7 -> 2216 | J8: 28541448 | K8: =J8-J7 -> 2448 | L8: 23282590 | M8: =L8-L7 -> 8976 | N8: =M8+K8+I8+G8+E8 -> 20764 | O8: =IF(B8>0,N8/B8,0) -> 1092.9572 | P8: 15765 | Q8: =(P8-P7)*1000 -> 18000 | R8: =N8-Q8 -> 2764 | S8: 8991 | T8: =S8-S7 -> 20 | U8: 162800 | V8: =U8-U7 -> 4495 | W8: =W7 -> 31853 | X8: =W8-W7 -> 0 | Y8: =Y7 -> 625865 | Z8: =Y8-Y7 -> 0 | AA8: 35240 | AB8: =AA8-AA7 -> 2 | AC8: 817378 | AD8: =AC8-AC7 -> 527 | AE8: =AB8+X8+T8 -> 22 | AF8: =V8+Z8+AD8 -> 5022 | AG8: =IF(AE8>0,AF8/AE8,0) -> 228.27273 | AI8: =R8-'EDl log'!B6 -> -118318
A9: ='General information '!F12 -> 0.0783 | B9: =SUM(230*A9) -> 18.009 | C9: 44019 | D9: 31899618 | E9: =D9-D8 -> 7468 | F9: 3755590 | G9: =F9-F8 -> 1973 | H9: 17535926 | I9: =H9-H8 -> 2320 | J9: 28543918 | K9: =J9-J8 -> 2470 | L9: 23288838 | M9: =L9-L8 -> 6248 | N9: =M9+K9+I9+G9+E9 -> 20479 | O9: =IF(B9>0,N9/B9,0) -> 1137.1536 | P9: 15780 | Q9: =(P9-P8)*1000 -> 15000 | R9: =N9-Q9 -> 5479 | S9: 9001 | T9: =S9-S8 -> 10 | U9: 165542 | V9: =U9-U8 -> 2742 | W9: 31853 | X9: =W9-W8 -> 0 | Y9: =Y8 -> 625865 | Z9: =Y9-Y8 -> 0 | AA9: 35253 | AB9: =AA9-AA8 -> 13 | AC9: 820446 | AD9: =AC9-AC8 -> 3068 | AE9: =AB9+X9+T9 -> 23 | AF9: =V9+Z9+AD9 -> 5810 | AG9: =IF(AE9>0,AF9/AE9,0) -> 252.6087 | AI9: =R9-'EDl log'!B7 -> -116573
A10: ='General information '!F13 -> 0.087 | B10: =SUM(230*A10) -> 20.01 | C10: 44020 | D10: 31904808 | E10: =D10-D9 -> 5190 | F10: 3757737 | G10: =F10-F9 -> 2147 | H10: 17538322 | I10: =H10-H9 -> 2396 | J10: 28547484 | K10: =J10-J9 -> 3566 | L10: 23299082 | M10: =L10-L9 -> 10244 | N10: =M10+K10+I10+G10+E10 -> 23543 | O10: =IF(B10>0,N10/B10,0) -> 1176.5617 | P10: 15795 | Q10: =(P10-P9)*1000 -> 15000 | R10: =N10-Q10 -> 8543 | S10: 9025 | T10: =S10-S9 -> 24 | U10: 171163 | V10: =U10-U9 -> 5621 | W10: 31853 | X10: =W10-W9 -> 0 | Y10: 625865 | Z10: =Y10-Y9 -> 0 | AA10: 35253 | AB10: =AA10-AA9 -> 0 | AC10: 820459 | AD10: =AC10-AC9 -> 13 | AE10: =AB10+X10+T10 -> 24 | AF10: =V10+Z10+AD10 -> 5634 | AG10: =IF(AE10>0,AF10/AE10,0) -> 234.75 | AI10: =R10-'EDl log'!B8 -> -115625
A11: ='General information '!F14 -> 0.1087 | B11: =SUM(230*A11) -> 25.001 | C11: 44021 | D11: 31909136 | E11: =D11-D10 -> 4328 | F11: 3759502 | G11: =F11-F10 -> 1765 | H11: 17540322 | I11: =H11-H10 -> 2000 | J11: 28549842 | K11: =J11-J10 -> 2358 | L11: 23306740 | M11: =L11-L10 -> 7658 | N11: =M11+K11+I11+G11+E11 -> 18109 | O11: =IF(B11>0,N11/B11,0) -> 724.33103 | P11: 15815 | Q11: =(P11-P10)*1000 -> 20000 | R11: =N11-Q11 -> -1891 | S11: 9046 | T11: =S11-S10 -> 21 | U11: 175732 | V11: =U11-U10 -> 4569 | W11: 31853 | X11: =W11-W10 -> 0 | Y11: =Y10 -> 625865 | Z11: =Y11-Y10 -> 0 | AA11: 35254 | AB11: =AA11-AA10 -> 1 | AC11: 820817 | AD11: =AC11-AC10 -> 358 | AE11: =AB11+X11+T11 -> 22 | AF11: =V11+Z11+AD11 -> 4927 | AG11: =IF(AE11>0,AF11/AE11,0) -> 223.95455 | AI11: =R11-'EDl log'!B9 -> -127584
A12: ='General information '!F15 -> 0.113 | B12: =SUM(230*A12) -> 25.99 | C12: 44022 | D12: 31918636 | E12: =D12-D11 -> 9500 | F12: 3761429 | G12: =F12-F11 -> 1927 | H12: 17542698 | I12: =H12-H11 -> 2376 | J12: 28552374 | K12: =J12-J11 -> 2532 | L12: 23310458 | M12: =L12-L11 -> 3718 | N12: =M12+K12+I12+G12+E12 -> 20053 | O12: =IF(B12>0,N12/B12,0) -> 771.56599 | P12: 15832 | Q12: =(P12-P11)*1000 -> 17000 | R12: =N12-Q12 -> 3053 | S12: 9046 | T12: =S12-S11 -> 0 | U12: =U11 -> 175732 | V12: =U12-U11 -> 0 | W12: 31853 | X12: =W12-W11 -> 0 | Y12: =Y11 -> 625865 | Z12: =Y12-Y11 -> 0 | AA12: 35277 | AB12: =AA12-AA11 -> 23 | AC12: 825666 | AD12: =AC12-AC11 -> 4849 | AE12: =AB12+X12+T12 -> 23 | AF12: =V12+Z12+AD12 -> 4849 | AG12: =IF(AE12>0,AF12/AE12,0) -> 210.82609 | AI12: =R12-'EDl log'!B10 -> -122641
A13: ='General information '!F16 -> 0.165 | B13: =SUM(230*A13) -> 37.95 | C13: 44023 | D13: 31925506 | E13: =D13-D12 -> 6870 | F13: 3763366 | G13: =F13-F12 -> 1937 | H13: 17545070 | I13: =H13-H12 -> 2372 | J13: 28555410 | K13: =J13-J12 -> 3036 | L13: 23317316 | M13: =L13-L12 -> 6858 | N13: =M13+K13+I13+G13+E13 -> 21073 | O13: =IF(B13>0,N13/B13,0) -> 555.28327 | P13: 15850 | Q13: =(P13-P12)*1000 -> 18000 | R13: =N13-Q13 -> 3073 | S13: 9058 | T13: =S13-S12 -> 12 | U13: 178830 | V13: =U13-U12 -> 3098 | W13: 31853 | X13: =W13-W12 -> 0 | Y13: =Y12 -> 625865 | Z13: =Y13-Y12 -> 0 | AA13: 35288 | AB13: =AA13-AA12 -> 11 | AC13: 827959 | AD13: =AC13-AC12 -> 2293 | AE13: =AB13+X13+T13 -> 23 | AF13: =V13+Z13+AD13 -> 5391 | AG13: =IF(AE13>0,AF13/AE13,0) -> 234.3913 | AI13: =R13-'EDl log'!B11 -> -122622
A14: ='General information '!F17 -> 0.1 | B14: =SUM(230*A14) -> 23 | C14: 44024 | D14: 31929606 | E14: =D14-D13 -> 4100 | F14: 3765356 | G14: =F14-F13 -> 1990 | H14: 17547420 | I14: =H14-H13 -> 2350 | J14: 28558246 | K14: =J14-J13 -> 2836 | L14: 23326124 | M14: =L14-L13 -> 8808 | N14: =M14+K14+I14+G14+E14 -> 20084 | O14: =IF(B14>0,N14/B14,0) -> 873.21739 | P14: 15869 | Q14: =(P14-P13)*1000 -> 19000 | R14: =N14-Q14 -> 1084 | S14: 9081 | T14: =S14-S13 -> 23 | U14: 183861 | V14: =U14-U13 -> 5031 | W14: 31853 | X14: =W14-W13 -> 0 | Y14: =Y13 -> 625865 | Z14: =Y14-Y13 -> 0 | AA14: 35288 | AB14: =AA14-AA13 -> 0 | AC14: 827989 | AD14: =AC14-AC13 -> 30 | AE14: =AB14+X14+T14 -> 23 | AF14: =V14+Z14+AD14 -> 5061 | AG14: =IF(AE14>0,AF14/AE14,0) -> 220.04348 | AI14: =R14-'EDl log'!B12 -> -132180
A15: ='General information '!F18 -> 0.1217 | B15: =SUM(230*A15) -> 27.991 | C15: 44025 | D15: 31934490 | E15: =D15-D14 -> 4884 | F15: 3767592 | G15: =F15-F14 -> 2236 | H15: 17549838 | I15: =H15-H14 -> 2418 | J15: 28560296 | K15: =J15-J14 -> 2050 | L15: 23334400 | M15: =L15-L14 -> 8276 | N15: =M15+K15+I15+G15+E15 -> 19864 | O15: =IF(B15>0,N15/B15,0) -> 709.65668 | P15: 15883 | Q15: =(P15-P14)*1000 -> 14000 | R15: =N15-Q15 -> 5864 | S15: 9101 | T15: =S15-S14 -> 20 | U15: 188212 | V15: =U15-U14 -> 4351 | W15: 31853 | X15: =W15-W14 -> 0 | Y15: 625865 | Z15: =Y15-Y14 -> 0 | AA15: 35290 | AB15: =AA15-AA14 -> 2 | AC15: 828442 | AD15: =AC15-AC14 -> 453 | AE15: =AB15+X15+T15 -> 22 | AF15: =V15+Z15+AD15 -> 4804 | AG15: =IF(AE15>0,AF15/AE15,0) -> 218.36364 | AI15: =R15-'EDl log'!B13 -> -127800
A16: ='General information '!F19 -> 0.1271 | B16: =SUM(230*A16) -> 29.233 | C16: 44026 | D16: 31944038 | E16: =D16-D15 -> 9548 | F16: 3769558 | G16: =F16-F15 -> 1966 | H16: 17552096 | I16: =H16-H15 -> 2258 | J16: 28562678 | K16: =J16-J15 -> 2382 | L16: 23337998 | M16: =L16-L15 -> 3598 | N16: =M16+K16+I16+G16+E16 -> 19752 | O16: =IF(B16>0,N16/B16,0) -> 675.67475 | P16: 15901 | Q16: =(P16-P15)*1000 -> 18000 | R16: =N16-Q16 -> 1752 | S16: 9101 | T16: =S16-S15 -> 0 | U16: 188213 | V16: =U16-U15 -> 1 | W16: =W15 -> 31853 | X16: =W16-W15 -> 0 | Y16: 625865 | Z16: =Y16-Y15 -> 0 | AA16: 35314 | AB16: =AA16-AA15 -> 24 | AC16: 833458 | AD16: =AC16-AC15 -> 5016 | AE16: =AB16+X16+T16 -> 24 | AF16: =V16+Z16+AD16 -> 5017 | AG16: =IF(AE16>0,AF16/AE16,0) -> 209.04167 | AI16: =R16-'EDl log'!B14 -> -134253
A17: ='General information '!F20 -> 0.1348 | B17: =SUM(230*A17) -> 31.004 | C17: 44027 | D17: 31949588 | E17: =D17-D16 -> 5550 | F17: 3771812 | G17: =F17-F16 -> 2254 | H17: 17554498 | I17: =H17-H16 -> 2402 | J17: 28565690 | K17: =J17-J16 -> 3012 | L17: 23347120 | M17: =L17-L16 -> 9122 | N17: =M17+K17+I17+G17+E17 -> 22340 | O17: =IF(B17>0,N17/B17,0) -> 720.55219 | P17: 15918 | Q17: =(P17-P16)*1000 -> 17000 | R17: =N17-Q17 -> 5340 | S17: 9120 | T17: =S17-S16 -> 19 | U17: 192930 | V17: =U17-U16 -> 4717 | W17: =W16 -> 31853 | X17: =W17-W16 -> 0 | Y17: =Y16 -> 625865 | Z17: =Y17-Y16 -> 0 | AA17: 35316 | AB17: =AA17-AA16 -> 2 | AC17: 834137 | AD17: =AC17-AC16 -> 679 | AE17: =AB17+X17+T17 -> 21 | AF17: =V17+Z17+AD17 -> 5396 | AG17: =IF(AE17>0,AF17/AE17,0) -> 256.95238 | AI17: =R17-'EDl log'!B15 -> -131110
A18: ='General information '!F21 -> 0.2 | B18: =SUM(230*A18) -> 46 | C18: 44028 | D18: 31955118 | E18: =D18-D17 -> 5530 | F18: 3773880 | G18: =F18-F17 -> 2068 | H18: 17556730 | I18: =H18-H17 -> 2232 | J18: 28570926 | K18: =J18-J17 -> 5236 | L18: 23352798 | M18: =L18-L17 -> 5678 | N18: =M18+K18+I18+G18+E18 -> 20744 | O18: =IF(B18>0,N18/B18,0) -> 450.95652 | P18: 15937 | Q18: =(P18-P17)*1000 -> 19000 | R18: =N18-Q18 -> 1744 | S18: 9130 | T18: =S18-S17 -> 10 | U18: 195258 | V18: =U18-U17 -> 2328 | W18: 31862 | X18: =W18-W17 -> 9 | Y18: 628067 | Z18: =Y18-Y17 -> 2202 | AA18: 35320 | AB18: =AA18-AA17 -> 4 | AC18: 834917 | AD18: =AC18-AC17 -> 780 | AE18: =AB18+X18+T18 -> 23 | AF18: =V18+Z18+AD18 -> 5310 | AG18: =IF(AE18>0,AF18/AE18,0) -> 230.86957 | AI18: =R18-'EDl log'!B16 -> -134707
A19: ='General information '!F22 -> 0.2 | B19: =SUM(230*A19) -> 46 | C19: 44029 | D19: 31959822 | E19: =D19-D18 -> 4704 | F19: 3776089 | G19: =F19-F18 -> 2209 | H19: 17559110 | I19: =H19-H18 -> 2380 | J19: 28578470 | K19: =J19-J18 -> 7544 | L19: 23356554 | M19: =L19-L18 -> 3756 | N19: =M19+K19+I19+G19+E19 -> 20593 | O19: =IF(B19>0,N19/B19,0) -> 447.67391 | P19: 15954 | Q19: =(P19-P18)*1000 -> 17000 | R19: =N19-Q19 -> 3593 | S19: 9130 | T19: =S19-S18 -> 0 | U19: 195258 | V19: =U19-U18 -> 0 | W19: 31885 | X19: =W19-W18 -> 23 | Y19: 632170 | Z19: =Y19-Y18 -> 4103 | AA19: 35320 | AB19: =AA19-AA18 -> 0 | AC19: 834917 | AD19: =AC19-AC18 -> 0 | AE19: =AB19+X19+T19 -> 23 | AF19: =V19+Z19+AD19 -> 4103 | AG19: =IF(AE19>0,AF19/AE19,0) -> 178.3913 | AI19: =R19-'EDl log'!B17 -> -136866
A20: ='General information '!F23 -> 0.2261 | B20: =SUM(230*A20) -> 52.003 | C20: 44030 | D20: 31964766 | E20: =D20-D19 -> 4944 | F20: 3778280 | G20: =F20-F19 -> 2191 | H20: 17561646 | I20: =H20-H19 -> 2536 | J20: 28585998 | K20: =J20-J19 -> 7528 | L20: 23360374 | M20: =L20-L19 -> 3820 | N20: =M20+K20+I20+G20+E20 -> 21019 | O20: =IF(B20>0,N20/B20,0) -> 404.18822 | P20: 15972 | Q20: =(P20-P19)*1000 -> 18000 | R20: =N20-Q20 -> 3019 | S20: =S19 -> 9130 | T20: =S20-S19 -> 0 | U20: =U19 -> 195258 | V20: =U20-U19 -> 0 | W20: 31907 | X20: =W20-W19 -> 22 | Y20: 638187 | Z20: =Y20-Y19 -> 6017 | AA20: =AA19 -> 35320 | AB20: =AA20-AA19 -> 0 | AC20: =AC19 -> 834917 | AD20: =AC20-AC19 -> 0 | AE20: =AB20+X20+T20 -> 22 | AF20: =V20+Z20+AD20 -> 6017 | AG20: =IF(AE20>0,AF20/AE20,0) -> 273.5 | AI20: =R20-'EDl log'!B18 -> -140124
A21: ='General information '!F24 -> 0.1913 | B21: =SUM(230*A21) -> 43.999 | C21: 44031 | D21: 31969010 | E21: =D21-D20 -> 4244 | F21: 3780487 | G21: =F21-F20 -> 2207 | H21: 17564140 | I21: =H21-H20 -> 2494 | J21: 28593642 | K21: =J21-J20 -> 7644 | L21: 23364212 | M21: =L21-L20 -> 3838 | N21: =M21+K21+I21+G21+E21 -> 20427 | O21: =IF(B21>0,N21/B21,0) -> 464.26055 | P21: 15987 | Q21: =(P21-P20)*1000 -> 15000 | R21: =N21-Q21 -> 5427 | S21: 9130 | T21: =S21-S20 -> 0 | U21: 195258 | V21: =U21-U20 -> 0 | W21: 31931 | X21: =W21-W20 -> 24 | Y21: 643391 | Z21: =Y21-Y20 -> 5204 | AA21: 35320 | AB21: =AA21-AA20 -> 0 | AC21: 834917 | AD21: =AC21-AC20 -> 0 | AE21: =AB21+X21+T21 -> 24 | AF21: =V21+Z21+AD21 -> 5204 | AG21: =IF(AE21>0,AF21/AE21,0) -> 216.83333 | AI21: =R21-'EDl log'!B19 -> -139053
A22: ='General information '!F25 -> 0.1739 | B22: =SUM(230*A22) -> 39.997 | C22: 44032 | D22: 31973062 | E22: =D22-D21 -> 4052 | F22: 3782513 | G22: =F22-F21 -> 2026 | H22: 17566494 | I22: =H22-H21 -> 2354 | J22: 28599922 | K22: =J22-J21 -> 6280 | L22: 23369044 | M22: =L22-L21 -> 4832 | N22: =M22+K22+I22+G22+E22 -> 19544 | O22: =IF(B22>0,N22/B22,0) -> 488.63665 | P22: 16004 | Q22: =(P22-P21)*1000 -> 17000 | R22: =N22-Q22 -> 2544 | S22: 9133 | T22: =S22-S21 -> 3 | U22: 196148 | V22: =U22-U21 -> 890 | W22: 31948 | X22: =W22-W21 -> 17 | Y22: 647533 | Z22: =Y22-Y21 -> 4142 | AA22: 35320 | AB22: =AA22-AA21 -> 0 | AC22: 834917 | AD22: =AC22-AC21 -> 0 | AE22: =AB22+X22+T22 -> 20 | AF22: =V22+Z22+AD22 -> 5032 | AG22: =IF(AE22>0,AF22/AE22,0) -> 251.6 | AI22: =R22-'EDl log'!B20 -> -143811
A23: ='General information '!F26 -> 0.1609 | B23: =SUM(230*A23) -> 37.007 | C23: 44033 | D23: 31980958 | E23: =D23-D22 -> 7896 | F23: 3784650 | G23: =F23-F22 -> 2137 | H23: 17569038 | I23: =H23-H22 -> 2544 | J23: 28602858 | K23: =J23-J22 -> 2936 | L23: 23375968 | M23: =L23-L22 -> 6924 | N23: =M23+K23+I23+G23+E23 -> 22437 | O23: =IF(B23>0,N23/B23,0) -> 606.2907 | P23: 16014 | Q23: =(P23-P22)*1000 -> 10000 | R23: =N23-Q23 -> 12437 | S23: 9146 | T23: =S23-S22 -> 13 | U23: 199238 | V23: =U23-U22 -> 3090 | W23: 31948 | X23: =W23-W22 -> 0 | Y23: 647533 | Z23: =Y23-Y22 -> 0 | AA23: 35331 | AB23: =AA23-AA22 -> 11 | AC23: 837792 | AD23: =AC23-AC22 -> 2875 | AE23: =AB23+X23+T23 -> 24 | AF23: =V23+Z23+AD23 -> 5965 | AG23: =IF(AE23>0,AF23/AE23,0) -> 248.54167 | AI23: =R23-'EDl log'!B21 -> -135632
A24: ='General information '!F27 -> 0.1622 | B24: =SUM(230*A24) -> 37.306 | C24: 44034 | D24: 31986374 | E24: =D24-D23 -> 5416 | F24: 3786901 | G24: =F24-F23 -> 2251 | H24: 17571542 | I24: =H24-H23 -> 2504 | J24: 28609818 | K24: =J24-J23 -> 6960 | L24: 23380378 | M24: =L24-L23 -> 4410 | N24: =M24+K24+I24+G24+E24 -> 21541 | O24: =IF(B24>0,N24/B24,0) -> 577.41382 | P24: 16030 | Q24: =(P24-P23)*1000 -> 16000 | R24: =N24-Q24 -> 5541 | S24: 9146 | T24: =S24-S23 -> 0 | U24: 199238 | V24: =U24-U23 -> 0 | W24: 31965 | X24: =W24-W23 -> 17 | Y24: 651920 | Z24: =Y24-Y23 -> 4387 | AA24: 35334 | AB24: =AA24-AA23 -> 3 | AC24: 838614 | AD24: =AC24-AC23 -> 822 | AE24: =AB24+X24+T24 -> 20 | AF24: =V24+Z24+AD24 -> 5209 | AG24: =IF(AE24>0,AF24/AE24,0) -> 260.45 | AI24: =R24-'EDl log'!B22 -> -142529
A25: ='General information '!F28 -> 0.2304 | B25: =SUM(230*A25) -> 52.992 | C25: 44035 | D25: 31995162 | E25: =D25-D24 -> 8788 | F25: 3789241 | G25: =F25-F24 -> 2340 | H25: 17574106 | I25: =H25-H24 -> 2564 | J25: 28612266 | K25: =J25-J24 -> 2448 | L25: 23387034 | M25: =L25-L24 -> 6656 | N25: =M25+K25+I25+G25+E25 -> 22796 | O25: =IF(B25>0,N25/B25,0) -> 430.17814 | P25: 16041 | Q25: =(P25-P24)*1000 -> 11000 | R25: =N25-Q25 -> 11796 | S25: 9156 | T25: =S25-S24 -> 10 | U25: 201513 | V25: =U25-U24 -> 2275 | W25: 31966 | X25: =W25-W24 -> 1 | Y25: 651986 | Z25: =Y25-Y24 -> 66 | AA25: 35346 | AB25: =AA25-AA24 -> 12 | AC25: 842032 | AD25: =AC25-AC24 -> 3418 | AE25: =AB25+X25+T25 -> 23 | AF25: =V25+Z25+AD25 -> 5759 | AG25: =IF(AE25>0,AF25/AE25,0) -> 250.3913 | AI25: =R25-'EDl log'!B23 -> -141602
A26: ='General information '!F29 -> 0.256 | B26: =SUM(230*A26) -> 58.88 | C26: 44036 | D26: 31999918 | E26: =D26-D25 -> 4756 | F26: 3791517 | G26: =F26-F25 -> 2276 | H26: 17576578 | I26: =H26-H25 -> 2472 | J26: 28618322 | K26: =J26-J25 -> 6056 | L26: 23393610 | M26: =L26-L25 -> 6576 | N26: =M26+K26+I26+G26+E26 -> 22136 | O26: =IF(B26>0,N26/B26,0) -> 375.95109 | P26: 16056 | Q26: =(P26-P25)*1000 -> 15000 | R26: =N26-Q26 -> 7136 | S26: 9165 | T26: =S26-S25 -> 9 | U26: 204005 | V26: =U26-U25 -> 2492 | W26: 31978 | X26: =W26-W25 -> 12 | Y26: 655238 | Z26: =Y26-Y25 -> 3252 | AA26: 35349 | AB26: =AA26-AA25 -> 3 | AC26: 842777 | AD26: =AC26-AC25 -> 745 | AE26: =AB26+X26+T26 -> 24 | AF26: =V26+Z26+AD26 -> 6489 | AG26: =IF(AE26>0,AF26/AE26,0) -> 270.375 | AI26: =R26-'EDl log'!B24 -> -146262
A27: ='General information '!F30 -> 0.269 | B27: =SUM(230*A27) -> 61.87 | C27: 44037 | D27: 32006116 | E27: =D27-D26 -> 6198 | F27: 3794144 | G27: =F27-F26 -> 2627 | H27: 17579320 | I27: =H27-H26 -> 2742 | J27: 28621058 | K27: =J27-J26 -> 2736 | L27: 23402658 | M27: =L27-L26 -> 9048 | N27: =M27+K27+I27+G27+E27 -> 23351 | O27: =IF(B27>0,N27/B27,0) -> 377.4204 | P27: 16065 | Q27: =(P27-P26)*1000 -> 9000 | R27: =N27-Q27 -> 14351 | S27: 9182 | T27: =S27-S26 -> 17 | U27: 208472 | V27: =U27-U26 -> 4467 | W27: =W26 -> 31978 | X27: =W27-W26 -> 0 | Y27: =Y26 -> 655238 | Z27: =Y27-Y26 -> 0 | AA27: 35355 | AB27: =AA27-AA26 -> 6 | AC27: 844436 | AD27: =AC27-AC26 -> 1659 | AE27: =AB27+X27+T27 -> 23 | AF27: =V27+Z27+AD27 -> 6126 | AG27: =IF(AE27>0,AF27/AE27,0) -> 266.34783 | AI27: =R27-'EDl log'!B25 -> -146237
A28: ='General information '!F31 -> 0 | B28: =SUM(230*A28) -> 0 | C28: 44038 | D28: =D27 -> 32006116 | E28: =D28-D27 -> 0 | F28: =F27 -> 3794144 | G28: =F28-F27 -> 0 | H28: =H27 -> 17579320 | I28: =H28-H27 -> 0 | J28: =J27 -> 28621058 | K28: =J28-J27 -> 0 | L28: =L27 -> 23402658 | M28: =L28-L27 -> 0 | N28: =M28+K28+I28+G28+E28 -> 0 | O28: =IF(B28>0,N28/B28,0) -> 0 | P28: =P27 -> 16065 | Q28: =(P28-P27)*1000 -> 0 | R28: =N28-Q28 -> 0 | S28: =S27 -> 9182 | T28: =S28-S27 -> 0 | U28: =U27 -> 208472 | V28: =U28-U27 -> 0 | W28: =W27 -> 31978 | X28: =W28-W27 -> 0 | Y28: =Y27 -> 655238 | Z28: =Y28-Y27 -> 0 | AA28: =AA27 -> 35355 | AB28: =AA28-AA27 -> 0 | AC28: =AC27 -> 844436 | AD28: =AC28-AC27 -> 0 | AE28: =AB28+X28+T28 -> 0 | AF28: =V28+Z28+AD28 -> 0 | AG28: =IF(AE28>0,AF28/AE28,0) -> 0 | AI28: =R28-'EDl log'!B26 -> -168116
A29: ='General information '!F32 -> 0 | B29: =SUM(230*A29) -> 0 | C29: 44039 | D29: =D28 -> 32006116 | E29: =D29-D28 -> 0 | F29: =F28 -> 3794144 | G29: =F29-F28 -> 0 | H29: =H28 -> 17579320 | I29: =H29-H28 -> 0 | J29: =J28 -> 28621058 | K29: =J29-J28 -> 0 | L29: =L28 -> 23402658 | M29: =L29-L28 -> 0 | N29: =M29+K29+I29+G29+E29 -> 0 | O29: =IF(B29>0,N29/B29,0) -> 0 | P29: =P28 -> 16065 | Q29: =(P29-P28)*1000 -> 0 | R29: =N29-Q29 -> 0 | S29: =S28 -> 9182 | T29: =S29-S28 -> 0 | U29: =U28 -> 208472 | V29: =U29-U28 -> 0 | W29: =W28 -> 31978 | X29: =W29-W28 -> 0 | Y29: =Y28 -> 655238 | Z29: =Y29-Y28 -> 0 | AA29: =AA28 -> 35355 | AB29: =AA29-AA28 -> 0 | AC29: =AC28 -> 844436 | AD29: =AC29-AC28 -> 0 | AE29: =AB29+X29+T29 -> 0 | AF29: =V29+Z29+AD29 -> 0 | AG29: =IF(AE29>0,AF29/AE29,0) -> 0 | AI29: =R29-'EDl log'!B27 -> -172611
A30: ='General information '!F33 -> 0 | B30: =SUM(230*A30) -> 0 | C30: 44040 | D30: =D29 -> 32006116 | E30: =D30-D29 -> 0 | F30: =F29 -> 3794144 | G30: =F30-F29 -> 0 | H30: =H29 -> 17579320 | I30: =H30-H29 -> 0 | J30: =J29 -> 28621058 | K30: =J30-J29 -> 0 | L30: =L29 -> 23402658 | M30: =L30-L29 -> 0 | N30: =M30+K30+I30+G30+E30 -> 0 | O30: =IF(B30>0,N30/B30,0) -> 0 | P30: =P29 -> 16065 | Q30: =(P30-P29)*1000 -> 0 | R30: =N30-Q30 -> 0 | S30: =S29 -> 9182 | T30: =S30-S29 -> 0 | U30: =U29 -> 208472 | V30: =U30-U29 -> 0 | W30: =W29 -> 31978 | X30: =W30-W29 -> 0 | Y30: =Y29 -> 655238 | Z30: =Y30-Y29 -> 0 | AA30: =AA29 -> 35355 | AB30: =AA30-AA29 -> 0 | AC30: =AC29 -> 844436 | AD30: =AC30-AC29 -> 0 | AE30: =AB30+X30+T30 -> 0 | AF30: =V30+Z30+AD30 -> 0 | AG30: =IF(AE30>0,AF30/AE30,0) -> 0 | AI30: =R30-'EDl log'!B28 -> -172611
A31: ='General information '!F34 -> 0 | B31: =SUM(230*A31) -> 0 | C31: 44041 | D31: =D30 -> 32006116 | E31: =D31-D30 -> 0 | F31: =F30 -> 3794144 | G31: =F31-F30 -> 0 | H31: =H30 -> 17579320 | I31: =H31-H30 -> 0 | J31: =J30 -> 28621058 | K31: =J31-J30 -> 0 | L31: =L30 -> 23402658 | M31: =L31-L30 -> 0 | N31: =M31+K31+I31+G31+E31 -> 0 | O31: =IF(B31>0,N31/B31,0) -> 0 | P31: =P30 -> 16065 | Q31: =(P31-P30)*1000 -> 0 | R31: =N31-Q31 -> 0 | S31: =S30 -> 9182 | T31: =S31-S30 -> 0 | U31: =U30 -> 208472 | V31: =U31-U30 -> 0 | W31: =W30 -> 31978 | X31: =W31-W30 -> 0 | Y31: =Y30 -> 655238 | Z31: =Y31-Y30 -> 0 | AA31: =AA30 -> 35355 | AB31: =AA31-AA30 -> 0 | AC31: =AC30 -> 844436 | AD31: =AC31-AC30 -> 0 | AE31: =AB31+X31+T31 -> 0 | AF31: =V31+Z31+AD31 -> 0 | AG31: =IF(AE31>0,AF31/AE31,0) -> 0 | AI31: =R31-'EDl log'!B29 -> -172611
A32: ='General information '!F35 -> 0 | B32: =SUM(230*A32) -> 0 | C32: 44042 | D32: =D31 -> 32006116 | E32: =D32-D31 -> 0 | F32: =F31 -> 3794144 | G32: =F32-F31 -> 0 | H32: =H31 -> 17579320 | I32: =H32-H31 -> 0 | J32: =J31 -> 28621058 | K32: =J32-J31 -> 0 | L32: =L31 -> 23402658 | M32: =L32-L31 -> 0 | N32: =M32+K32+I32+G32+E32 -> 0 | O32: =IF(B32>0,N32/B32,0) -> 0 | P32: =P31 -> 16065 | Q32: =(P32-P31)*1000 -> 0 | R32: =N32-Q32 -> 0 | S32: =S31 -> 9182 | T32: =S32-S31 -> 0 | U32: =U31 -> 208472 | V32: =U32-U31 -> 0 | W32: =W31 -> 31978 | X32: =W32-W31 -> 0 | Y32: =Y31 -> 655238 | Z32: =Y32-Y31 -> 0 | AA32: =AA31 -> 35355 | AB32: =AA32-AA31 -> 0 | AC32: =AC31 -> 844436 | AD32: =AC32-AC31 -> 0 | AE32: =AB32+X32+T32 -> 0 | AF32: =V32+Z32+AD32 -> 0 | AG32: =IF(AE32>0,AF32/AE32,0) -> 0 | AI32: =R32-'EDl log'!B30 -> -172611
A33: ='General information '!F37 -> 0.141432 | B33: =SUM(230*A33) -> 32.52936 | C33: 44043 | D33: =D32 -> 32006116 | E33: =D33-D32 -> 0 | F33: =F32 -> 3794144 | G33: =F33-F32 -> 0 | H33: =H32 -> 17579320 | I33: =H33-H32 -> 0 | J33: =J32 -> 28621058 | K33: =J33-J32 -> 0 | L33: =L32 -> 23402658 | M33: =L33-L32 -> 0 | N33: =M33+K33+I33+G33+E33 -> 0 | O33: =IF(B33>0,N33/B33,0) -> 0 | P33: =P32 -> 16065 | Q33: =(P33-P32)*1000 -> 0 | R33: =N33-Q33 -> 0 | S33: =S32 -> 9182 | T33: =S33-S32 -> 0 | U33: =U32 -> 208472 | V33: =U33-U32 -> 0 | W33: =W32 -> 31978 | X33: =W33-W32 -> 0 | Y33: =Y32 -> 655238 | Z33: =Y33-Y32 -> 0 | AA33: =AA32 -> 35355 | AB33: =AA33-AA32 -> 0 | AC33: =AC32 -> 844436 | AD33: =AC33-AC32 -> 0 | AE33: =AB33+X33+T33 -> 0 | AF33: =V33+Z33+AD33 -> 0 | AG33: =IF(AE33>0,AF33/AE33,0) -> 0 | AI33: =R33-'EDl log'!B31 -> -172611

Sheet B5
F1: Boiler A | J1: =J36 -> 74.894737 | K1: Boiler B | P1: Boiler C | V1: Boiler | X1: SteamA | AC1: SteamB | AH1: Steam | AI1: Boiler & steam | AL1: Total Boiler Runing H | AM1: Total Steam Runing H | AN1: GAS1 % | AO1: GAS1/L | AP1: GAS2% | AQ1: Gas2/L | AR1: GAS3% | AS1: GAS3/L | AU1: Gas Cons | AV1: Delivery | AW1: Cost/L
B2: Level Tank Gen | C2: Level tank Boiler | D2: Daily Cons Bo. | E2: Boiler litter | F2: Boiler A | G2: Run Hr a | H2: Boiler A fuel | I2: Daily consumption | J2: AVG | K2: index Run H | L2: Run Hrb | M2: Boiler B Fuel | O2: Daily consumption | P2: Boiler C | S2: Run C | U2: Total RH | V2: Total Fuel | X2: SteamA | Y2: Run SA | Z2: Steam A Conter | AA2: Liters | AC2: SteamB | AD2: Run SteamB | AE2: Steam B Conter | AF2: SB Litters | AG2: Avg | AH2: Total Fuel | AI2: Total Fuel
S3: 0
A4: =ELEC!C2 -> 44012 | B4: =[1]B5!B34 -> 140 | C4: =[1]B5!C34 -> 147 | D4: =[1]B5!D34 -> 11 | E4: =[1]B5!E34 -> 92.18 | F4: =[1]B5!F34 -> 1602 | G4: =[1]B5!G34 -> 1 | H4: =[1]B5!H34 -> 354323 | I4: =[1]B5!I34 -> 50 | ... AX4: =[1]B5!AX34 -> 0.7
A5: =ELEC!C3 -> 44013 | B5: 183 | C5: 190 | D5: =C4-C5 -> -43 | E5: =D5*8.38 -> -360.34 | F5: 1605 | G5: =F5-F4 -> 3 | H5: 354564 | I5: =SUM(H5-H4) -> 241 | J5: 1 | K5: =K4 -> 2069 | L5: =K5-K4 -> 0 | M5: =M4 -> 151781 | N5: =M5-M4 -> 0 | O5: =O4 -> 211.875 | P5: 1809 | Q5: 153475 | R5: =Q5-Q4 -> 176 | S5: =SUM(P5-P4) -> 2 | T5: =SUM(S5*$T$2) -> 0 | U5: =SUM(G5+L5+S5) -> 5 | V5: =R5+N5+I5:I5 -> 417 | W5: =SUM(V5/U5) -> 83.4 | X5: 2418 | Y5: =X5-X4 -> 0 | Z5: =Z4 -> 135964.1 | AA5: =Z5-Z4 -> 0 | AB5: =SUM(Y5*$AB$2) -> 0 | AC5: =AC4 -> 1857 | AD5: =AC5-AC4 -> 0 | AE5: =AE4 -> 360818 | AF5: =AE5-AE4 -> 0 | AG5: =IF(AD5>0,AF5/AD5,0) -> 0 | AH5: =AF5+AA5 -> 0 | AI5: =SUM(AH5+V5) -> 417 | AJ5: =-tanks!AW6 -> 417 | AK5: =SUM(AJ5-AI5) -> 0 | AL5: =S5+L5+G5 -> 5 | AM5: =Y5+AD5 -> 0 | AN5: 69 | AO5: =(AN5/100)*3000 -> 2070 | AP5: 76 | AQ5: =(AP5/100)*3000 -> 2280 | AR5: 76 | AS5: =(AR5/100)*3000 -> 2280 | AT5: =SUM(AO5+AQ5+AS5) -> 6630 | AU5: =AT4-AT5+AV5 -> 90 | AX5: =IF(AV5>0,AW5,AX4) -> 0.7
A6: =ELEC!C4 -> 44014 | B6: 165 | C6: 172 | D6: =C5-C6 -> 18 | E6: =D6*8.38 -> 150.84 | F6: =F5 -> 1605 | G6: =F6-F5 -> 0 | H6: =H5 -> 354564 | I6: =SUM(H6-H5) -> 0 | J6: =IF(G6>0,I6/G6,0) -> 0 | K6: =K5 -> 2069 | L6: =K6-K5 -> 0 | M6: =M5 -> 151781 | N6: =M6-M5 -> 0 | O6: =O5 -> 211.875 | P6: 1815 | Q6: 153940 | R6: =Q6-Q5 -> 465 | S6: =SUM(P6-P5) -> 6 | T6: =SUM(S6*$T$2) -> 0 | U6: =SUM(G6+L6+S6) -> 6 | V6: =R6+N6+I6:I6 -> 465 | W6: =SUM(V6/U6) -> 77.5 | X6: =X5 -> 2418 | Y6: =X6-X5 -> 0 | Z6: =Z5 -> 135964.1 | AA6: =Z6-Z5 -> 0 | AB6: =SUM(Y6*$AB$2) -> 0 | AC6: 1862 | AD6: =AC6-AC5 -> 5 | AE6: 361088 | AF6: =AE6-AE5 -> 270 | AG6: =IF(AD6>0,AF6/AD6,0) -> 54 | AH6: =AF6+AA6 -> 270 | AI6: =SUM(AH6+V6) -> 735 | AJ6: =-tanks!AW7 -> 735 | AK6: =SUM(AJ6-AI6) -> 0 | AL6: =S6+L6+G6 -> 6 | AM6: =Y6+AD6 -> 5 | AN6: 80 | AO6: =(AN6/100)*3000 -> 2400 | AP6: 80 | AQ6: =(AP6/100)*3000 -> 2400 | AR6: 81 | AS6: =(AR6/100)*3000 -> 2430 | AT6: =SUM(AO6+AQ6+AS6) -> 7230 | AU6: =AT5-AT6+AV6 -> 400 | AV6: 1000 | AW6: 0.7 | AX6: =IF(AV6>0,AW6,AX5) -> 0.7
A7: =ELEC!C5 -> 44015 | B7: 149 | C7: 158 | D7: =C6-C7 -> 14 | E7: =D7*8.38 -> 117.32 | F7: 1608 | G7: =F7-F6 -> 3 | H7: 354815 | I7: =SUM(H7-H6) -> 251 | J7: =IF(G7>0,I7/G7,0) -> 83.666667 | K7: =K6 -> 2069 | L7: =K7-K6 -> 0 | M7: =M6 -> 151781 | N7: =M7-M6 -> 0 | O7: =O6 -> 211.875 | P7: 1817 | Q7: 154077 | R7: =Q7-Q6 -> 137 | S7: =SUM(P7-P6) -> 2 | T7: =SUM(S7*$T$2) -> 0 | U7: =SUM(G7+L7+S7) -> 5 | V7: =R7+N7+I7:I7 -> 388 | W7: =SUM(V7/U7) -> 77.6 | X7: =X6 -> 2418 | Y7: =X7-X6 -> 0 | Z7: =Z6 -> 135964.1 | AA7: =Z7-Z6 -> 0 | AB7: =SUM(Y7*$AB$2) -> 0 | AC7: =AC6 -> 1862 | AD7: =AC7-AC6 -> 0 | AE7: =AE6 -> 361088 | AF7: =AE7-AE6 -> 0 | AG7: =IF(AD7>0,AF7/AD7,0) -> 0 | AH7: =AF7+AA7 -> 0 | AI7: =SUM(AH7+V7) -> 388 | AJ7: =-tanks!AW8 -> 388 | AK7: =SUM(AJ7-AI7) -> 0 | AL7: =S7+L7+G7 -> 5 | AM7: =Y7+AD7 -> 0 | AN7: 78 | AO7: =(AN7/100)*3000 -> 2340 | AP7: 79 | AQ7: =(AP7/100)*3000 -> 2370 | AR7: 78 | AS7: =(AR7/100)*3000 -> 2340 | AT7: =SUM(AO7+AQ7+AS7) -> 7050 | AU7: =AT6-AT7+AV7 -> 180 | AX7: =IF(AV7>0,AW7,AX6) -> 0.7
A8: =ELEC!C6 -> 44016 | B8: 131 | C8: 141.5 | D8: =C7-C8 -> 16.5 | E8: =D8*8.38 -> 138.27 | F8: 1611 | G8: =F8-F7 -> 3 | H8: 355017 | I8: =SUM(H8-H7) -> 202 | J8: =IF(G8>0,I8/G8,0) -> 67.333333 | K8: 2070 | L8: =K8-K7 -> 1 | M8: 151864 | N8: =M8-M7 -> 83 | O8: =O7 -> 211.875 | P8: 1819 | Q8: 154326 | R8: =Q8-Q7 -> 249 | S8: =SUM(P8-P7) -> 2 | T8: =SUM(S8*$T$2) -> 0 | U8: =SUM(G8+L8+S8) -> 6 | V8: =R8+N8+I8:I8 -> 534 | W8: =SUM(V8/U8) -> 89 | X8: =X7 -> 2418 | Y8: =X8-X7 -> 0 | Z8: =Z7 -> 135964.1 | AA8: =Z8-Z7 -> 0 | AB8: =SUM(Y8*$AB$2) -> 0 | AC8: =AC7 -> 1862 | AD8: =AC8-AC7 -> 0 | AE8: =AE7 -> 361088 | AF8: =AE8-AE7 -> 0 | AG8: =IF(AD8>0,AF8/AD8,0) -> 0 | AH8: =AF8+AA8 -> 0 | AI8: =SUM(AH8+V8) -> 534 | AJ8: =-tanks!AW9 -> 534 | AK8: =SUM(AJ8-AI8) -> 0 | AL8: =S8+L8+G8 -> 6 | AM8: =Y8+AD8 -> 0 | AN8: 78 | AO8: =(AN8/100)*3000 -> 2340 | AP8: 79 | AQ8: =(AP8/100)*3000 -> 2370 | AR8: 77 | AS8: =(AR8/100)*3000 -> 2310 | AT8: =SUM(AO8+AQ8+AS8) -> 7020 | AU8: =AT7-AT8+AV8 -> 30 | AX8: =IF(AV8>0,AW8,AX7) -> 0.7
A9: =ELEC!C7 -> 44017 | B9: 113 | C9: 125 | D9: =C8-C9 -> 16.5 | E9: =D9*8.38 -> 138.27 | F9: 1611 | G9: =F9-F8 -> 0 | H9: 355017 | I9: =SUM(H9-H8) -> 0 | J9: =IF(G9>0,I9/G9,0) -> 0 | K9: 2071 | L9: =K9-K8 -> 1 | M9: 151957 | N9: =M9-M8 -> 93 | O9: =O8 -> 211.875 | P9: 1823 | Q9: 154571 | R9: =Q9-Q8 -> 245 | S9: =SUM(P9-P8) -> 4 | T9: =SUM(S9*$T$2) -> 0 | U9: =SUM(G9+L9+S9) -> 5 | V9: =R9+N9+I9:I9 -> 338 | W9: =SUM(V9/U9) -> 67.6 | X9: 2418 | Y9: =X9-X8 -> 0 | Z9: =Z8 -> 135964.1 | AA9: =Z9-Z8 -> 0 | AB9: =SUM(Y9*$AB$2) -> 0 | AC9: 1862 | AD9: =AC9-AC8 -> 0 | AE9: 361088 | AF9: =AE9-AE8 -> 0 | AG9: =IF(AD9>0,AF9/AD9,0) -> 0 | AH9: =AF9+AA9 -> 0 | AI9: =SUM(AH9+V9) -> 338 | AJ9: =-tanks!AW10 -> 338 | AK9: =SUM(AJ9-AI9) -> 0 | AL9: =S9+L9+G9 -> 5 | AM9: =Y9+AD9 -> 0 | AN9: 77 | AO9: =(AN9/100)*3000 -> 2310 | AP9: 78 | AQ9: =(AP9/100)*3000 -> 2340 | AR9: 75 | AS9: =(AR9/100)*3000 -> 2250 | AT9: =SUM(AO9+AQ9+AS9) -> 6900 | AU9: =AT8-AT9+AV9 -> 120 | AX9: =IF(AV9>0,AW9,AX8) -> 0.7
A10: =ELEC!C8 -> 44018 | B10: 136 | C10: 143 | D10: =C9-C10 -> -18 | E10: =D10*8.38 -> -150.84 | F10: =F9 -> 1611 | G10: =F10-F9 -> 0 | H10: 355017 | I10: =SUM(H10-H9) -> 0 | J10: =IF(G10>0,I10/G10,0) -> 0 | K10: 2072 | L10: =K10-K9 -> 1 | M10: 152028 | N10: =M10-M9 -> 71 | O10: =O9 -> 211.875 | P10: 1825 | Q10: 154746 | R10: =Q10-Q9 -> 175 | S10: =SUM(P10-P9) -> 2 | T10: =SUM(S10*$T$2) -> 0 | U10: =SUM(G10+L10+S10) -> 3 | V10: =R10+N10+I10:I10 -> 246 | W10: =SUM(V10/U10) -> 82 | X10: 2418 | Y10: =X10-X9 -> 0 | Z10: 135964.1 | AA10: =Z10-Z9 -> 0 | AB10: =SUM(Y10*$AB$2) -> 0 | AC10: 1865 | AD10: =AC10-AC9 -> 3 | AE10: 361272 | AF10: =AE10-AE9 -> 184 | AG10: =IF(AD10>0,AF10/AD10,0) -> 61.333333 | AH10: =AF10+AA10 -> 184 | AI10: =SUM(AH10+V10) -> 430 | AJ10: =-tanks!AW11 -> 430 | AK10: =SUM(AJ10-AI10) -> 0 | AL10: =S10+L10+G10 -> 3 | AM10: =Y10+AD10 -> 3 | AN10: 75 | AO10: =(AN10/100)*3000 -> 2250 | AP10: 76 | AQ10: =(AP10/100)*3000 -> 2280 | AR10: 74 | AS10: =(AR10/100)*3000 -> 2220 | AT10: =SUM(AO10+AQ10+AS10) -> 6750 | AU10: =AT9-AT10+AV10 -> 150 | AX10: =IF(AV10>0,AW10,AX9) -> 0.7
A11: =ELEC!C9 -> 44019 | B11: 118 | C11: 125.4 | D11: =C10-C11 -> 17.6 | E11: =D11*8.38 -> 147.488 | F11: 1614 | G11: =F11-F10 -> 3 | H11: 355214 | I11: =SUM(H11-H10) -> 197 | J11: =IF(G11>0,I11/G11,0) -> 65.666667 | K11: 2075 | L11: =K11-K10 -> 3 | M11: 152253 | N11: =M11-M10 -> 225 | O11: =O10 -> 211.875 | P11: 1827 | Q11: 154981 | R11: =Q11-Q10 -> 235 | S11: =SUM(P11-P10) -> 2 | T11: =SUM(S11*$T$2) -> 0 | U11: =SUM(G11+L11+S11) -> 8 | V11: =R11+N11+I11:I11 -> 657 | W11: =SUM(V11/U11) -> 82.125 | X11: 2418 | Y11: =X11-X10 -> 0 | Z11: =Z10 -> 135964.1 | AA11: =Z11-Z10 -> 0 | AB11: =SUM(Y11*$AB$2) -> 0 | AC11: 1865 | AD11: =AC11-AC10 -> 0 | AE11: 361272 | AF11: =AE11-AE10 -> 0 | AG11: =IF(AD11>0,AF11/AD11,0) -> 0 | AH11: =AF11+AA11 -> 0 | AI11: =SUM(AH11+V11) -> 657 | AJ11: =-tanks!AW12 -> 657 | AK11: =SUM(AJ11-AI11) -> 0 | AL11: =S11+L11+G11 -> 8 | AM11: =Y11+AD11 -> 0 | AN11: 73 | AO11: =(AN11/100)*3000 -> 2190 | AP11: 75 | AQ11: =(AP11/100)*3000 -> 2250 | AR11: 72 | AS11: =(AR11/100)*3000 -> 2160 | AT11: =SUM(AO11+AQ11+AS11) -> 6600 | AU11: =AT10-AT11+AV11 -> 150 | AX11: =IF(AV11>0,AW11,AX10) -> 0.7
A12: =ELEC!C10 -> 44020 | B12: 138.2 | C12: 145.3 | D12: =C11-C12 -> -19.9 | E12: =D12*8.38 -> -166.762 | F12: 1615 | G12: =F12-F11 -> 1 | H12: 355291 | I12: =SUM(H12-H11) -> 77 | J12: =IF(G12>0,I12/G12,0) -> 77 | K12: 2075 | L12: =K12-K11 -> 0 | M12: 152253 | N12: =M12-M11 -> 0 | O12: =O11 -> 211.875 | P12: 1829 | Q12: 155136 | R12: =Q12-Q11 -> 155 | S12: =SUM(P12-P11) -> 2 | T12: =SUM(S12*$T$2) -> 0 | U12: =SUM(G12+L12+S12) -> 3 | V12: =R12+N12+I12:I12 -> 232 | W12: =SUM(V12/U12) -> 77.333333 | X12: 2418 | Y12: =X12-X11 -> 0 | Z12: =Z11 -> 135964.1 | AA12: =Z12-Z11 -> 0 | AB12: =SUM(Y12*$AB$2) -> 0 | AC12: 1869 | AD12: =AC12-AC11 -> 4 | AE12: 361552 | AF12: =AE12-AE11 -> 280 | AG12: =IF(AD12>0,AF12/AD12,0) -> 70 | AH12: =AF12+AA12 -> 280 | AI12: =SUM(AH12+V12) -> 512 | AJ12: =-tanks!AW13 -> 512 | AK12: =SUM(AJ12-AI12) -> 0 | AL12: =S12+L12+G12 -> 3 | AM12: =Y12+AD12 -> 4 | AN12: 70 | AO12: =(AN12/100)*3000 -> 2100 | AP12: 73 | AQ12: =(AP12/100)*3000 -> 2190 | AR12: 70 | AS12: =(AR12/100)*3000 -> 2100 | AT12: =SUM(AO12+AQ12+AS12) -> 6390 | AU12: =AT11-AT12+AV12 -> 210 | AX12: =IF(AV12>0,AW12,AX11) -> 0.7
A13: =ELEC!C11 -> 44021 | B13: 120.3 | C13: 127.2 | D13: =C12-C13 -> 18.1 | E13: =D13*8.38 -> 151.678 | F13: 1618 | G13: =F13-F12 -> 3 | H13: 355545 | I13: =SUM(H13-H12) -> 254 | J13: =IF(G13>0,I13/G13,0) -> 84.666667 | K13: 2075 | L13: =K13-K12 -> 0 | M13: 152253 | N13: =M13-M12 -> 0 | O13: =O12 -> 211.875 | P13: 1829 | Q13: 155136 | R13: =Q13-Q12 -> 0 | S13: =SUM(P13-P12) -> 0 | T13: =SUM(S13*$T$2) -> 0 | U13: =SUM(G13+L13+S13) -> 3 | V13: =R13+N13+I13:I13 -> 254 | W13: =SUM(V13/U13) -> 84.666667 | X13: 2418 | Y13: =X13-X12 -> 0 | Z13: 135964 | AA13: =Z13-Z12 -> -0.1 | AB13: =SUM(Y13*$AB$2) -> 0 | AC13: 1869 | AD13: =AC13-AC12 -> 0 | AE13: 361554.1 | AF13: =AE13-AE12 -> 2.1 | AG13: =IF(AD13>0,AF13/AD13,0) -> 0 | AH13: =AF13+AA13 -> 2 | AI13: =SUM(AH13+V13) -> 256 | AJ13: =-tanks!AW14 -> 256 | AK13: =SUM(AJ13-AI13) -> 0 | AL13: =S13+L13+G13 -> 3 | AM13: =Y13+AD13 -> 0 | AN13: 79 | AO13: =(AN13/100)*3000 -> 2370 | AP13: 80 | AQ13: =(AP13/100)*3000 -> 2400 | AR13: 81 | AS13: =(AR13/100)*3000 -> 2430 | AT13: =SUM(AO13+AQ13+AS13) -> 7200 | AU13: =AT12-AT13+AV13 -> 390 | AV13: 1200 | AW13: 0.7 | AX13: =IF(AV13>0,AW13,AX12) -> 0.7
A14: =ELEC!C12 -> 44022 | B14: 178.2 | C14: 185 | D14: =C13-C14 -> -57.8 | E14: =D14*8.38 -> -484.364 | F14: 1621 | G14: =F14-F13 -> 3 | H14: 355804 | I14: =SUM(H14-H13) -> 259 | J14: =IF(G14>0,I14/G14,0) -> 86.333333 | K14: 2075 | L14: =K14-K13 -> 0 | M14: 152253 | N14: =M14-M13 -> 0 | O14: =O13 -> 211.875 | P14: 1829 | Q14: 155219 | R14: =Q14-Q13 -> 83 | S14: =SUM(P14-P13) -> 0 | T14: =SUM(S14*$T$2) -> 0 | U14: =SUM(G14+L14+S14) -> 3 | V14: =R14+N14+I14:I14 -> 342 | W14: =SUM(V14/U14) -> 114 | X14: 2418 | Y14: =X14-X13 -> 0 | Z14: 135964 | AA14: =Z14-Z13 -> 0 | AB14: =SUM(Y14*$AB$2) -> 0 | AC14: 1869 | AD14: =AC14-AC13 -> 0 | AE14: 361554.9 | AF14: =AE14-AE13 -> 0.8 | AG14: =IF(AD14>0,AF14/AD14,0) -> 0 | AH14: =AF14+AA14 -> 0.8 | AI14: =SUM(AH14+V14) -> 342.8 | AJ14: =-tanks!AW15 -> 342.8 | AK14: =SUM(AJ14-AI14) -> 0 | AL14: =S14+L14+G14 -> 3 | AM14: =Y14+AD14 -> 0 | AN14: 77 | AO14: =(AN14/100)*3000 -> 2310 | AP14: 79 | AQ14: =(AP14/100)*3000 -> 2370 | AR14: 78 | AS14: =(AR14/100)*3000 -> 2340 | AT14: =SUM(AO14+AQ14+AS14) -> 7020 | AU14: =AT13-AT14+AV14 -> 180 | AX14: =IF(AV14>0,AW14,AX13) -> 0.7
A15: =ELEC!C13 -> 44023 | B15: 159 | C15: 166 | D15: =C14-C15 -> 19 | E15: =D15*8.38 -> 159.22 | F15: =F14 -> 1621 | G15: =F15-F14 -> 0 | H15: =H14 -> 355804 | I15: =SUM(H15-H14) -> 0 | J15: =IF(G15>0,I15/G15,0) -> 0 | K15: =K14 -> 2075 | L15: =K15-K14 -> 0 | M15: =M14 -> 152253 | N15: =M15-M14 -> 0 | O15: =O14 -> 211.875 | P15: 1830 | Q15: 155334 | R15: =Q15-Q14 -> 115 | S15: =SUM(P15-P14) -> 1 | T15: =SUM(S15*$T$2) -> 0 | U15: =SUM(G15+L15+S15) -> 1 | V15: =R15+N15+I15:I15 -> 115 | W15: =SUM(V15/U15) -> 115 | X15: =X14 -> 2418 | Y15: =X15-X14 -> 0 | Z15: =Z14 -> 135964 | AA15: =Z15-Z14 -> 0 | AB15: =SUM(Y15*$AB$2) -> 0 | AC15: 1873 | AD15: =AC15-AC14 -> 4 | AE15: 361774.9 | AF15: =AE15-AE14 -> 220 | AG15: =IF(AD15>0,AF15/AD15,0) -> 55 | AH15: =AF15+AA15 -> 220 | AI15: =SUM(AH15+V15) -> 335 | AJ15: =-tanks!AW16 -> 335 | AK15: =SUM(AJ15-AI15) -> 0 | AL15: =S15+L15+G15 -> 1 | AM15: =Y15+AD15 -> 4 | AN15: 76 | AO15: =(AN15/100)*3000 -> 2280 | AP15: 78 | AQ15: =(AP15/100)*3000 -> 2340 | AR15: 76 | AS15: =(AR15/100)*3000 -> 2280 | AT15: =SUM(AO15+AQ15+AS15) -> 6900 | AU15: =AT14-AT15+AV15 -> 120 | AX15: =IF(AV15>0,AW15,AX14) -> 0.7
A16: =ELEC!C14 -> 44024 | B16: 139 | C16: 146 | D16: =C15-C16 -> 20 | E16: =D16*8.38 -> 167.6 | F16: 1623 | G16: =F16-F15 -> 2 | H16: 355940 | I16: =SUM(H16-H15) -> 136 | J16: =IF(G16>0,I16/G16,0) -> 68 | K16: 2076 | L16: =K16-K15 -> 1 | M16: 152337 | N16: =M16-M15 -> 84 | O16: =O15 -> 211.875 | P16: 1830 | Q16: 155334 | R16: =Q16-Q15 -> 0 | S16: =SUM(P16-P15) -> 0 | T16: =SUM(S16*$T$2) -> 0 | U16: =SUM(G16+L16+S16) -> 3 | V16: =R16+N16+I16:I16 -> 220 | W16: =SUM(V16/U16) -> 73.333333 | X16: 2418 | Y16: =X16-X15 -> 0 | Z16: 135964 | AA16: =Z16-Z15 -> 0 | AB16: =SUM(Y16*$AB$2) -> 0 | AC16: 1873 | AD16: =AC16-AC15 -> 0 | AE16: =AE15 -> 361774.9 | AF16: =AE16-AE15 -> 0 | AG16: =IF(AD16>0,AF16/AD16,0) -> 0 | AH16: =AF16+AA16 -> 0 | AI16: =SUM(AH16+V16) -> 220 | AJ16: =-tanks!AW17 -> 220 | AK16: =SUM(AJ16-AI16) -> 0 | AL16: =S16+L16+G16 -> 3 | AM16: =Y16+AD16 -> 0 | AN16: 75 | AO16: =(AN16/100)*3000 -> 2250 | AP16: 78 | AQ16: =(AP16/100)*3000 -> 2340 | AR16: 76 | AS16: =(AR16/100)*3000 -> 2280 | AT16: =SUM(AO16+AQ16+AS16) -> 6870 | AU16: =AT15-AT16+AV16 -> 30 | AX16: =IF(AV16>0,AW16,AX15) -> 0.7
A17: =ELEC!C15 -> 44025 | B17: 122.2 | C17: 129 | D17: =C16-C17 -> 17 | E17: =D17*8.38 -> 142.46 | F17: 1624 | G17: =F17-F16 -> 1 | H17: 356052 | I17: =SUM(H17-H16) -> 112 | J17: =IF(G17>0,I17/G17,0) -> 112 | K17: 2077 | L17: =K17-K16 -> 1 | M17: 152390 | N17: =M17-M16 -> 53 | O17: =O16 -> 211.875 | P17: 1830 | Q17: 155334 | R17: =Q17-Q16 -> 0 | S17: =SUM(P17-P16) -> 0 | T17: =SUM(S17*$T$2) -> 0 | U17: =SUM(G17+L17+S17) -> 2 | V17: =R17+N17+I17:I17 -> 165 | X17: 2418 | Y17: =X17-X16 -> 0 | Z17: 135964 | AA17: =Z17-Z16 -> 0 | AB17: =SUM(Y17*$AB$2) -> 0 | AC17: 1873 | AD17: =AC17-AC16 -> 0 | AE17: =AE16 -> 361774.9 | AF17: =AE17-AE16 -> 0 | AG17: =IF(AD17>0,AF17/AD17,0) -> 0 | AH17: =AF17+AA17 -> 0 | AI17: =SUM(AH17+V17) -> 165 | AJ17: =-tanks!AW18 -> 165 | AK17: =SUM(AJ17-AI17) -> 0 | AL17: =S17+L17+G17 -> 2 | AM17: =Y17+AD17 -> 0 | AN17: 73 | AO17: =(AN17/100)*3000 -> 2190 | AP17: 78 | AQ17: =(AP17/100)*3000 -> 2340 | AR17: 76 | AS17: =(AR17/100)*3000 -> 2280 | AT17: =SUM(AO17+AQ17+AS17) -> 6810 | AU17: =AT16-AT17+AV17 -> 60 | AX17: =IF(AV17>0,AW17,AX16) -> 0.7
A18: =ELEC!C16 -> 44026 | B18: 137 | C18: 144 | D18: =C17-C18 -> -15 | E18: =D18*8.38 -> -125.7 | F18: 1628 | G18: =F18-F17 -> 4 | H18: 356324 | I18: =SUM(H18-H17) -> 272 | J18: =IF(G18>0,I18/G18,0) -> 68 | K18: 2077 | L18: =K18-K17 -> 0 | M18: 152390 | N18: =M18-M17 -> 0 | O18: =O17 -> 211.875 | P18: 1830 | Q18: 155334 | R18: =Q18-Q17 -> 0 | S18: =SUM(P18-P17) -> 0 | T18: =SUM(S18*$T$2) -> 0 | U18: =SUM(G18+L18+S18) -> 4 | V18: =R18+N18+I18:I18 -> 272 | X18: 2418 | Y18: =X18-X17 -> 0 | Z18: 135964 | AA18: =Z18-Z17 -> 0 | AB18: =SUM(Y18*$AB$2) -> 0 | AC18: 1875 | AD18: =AC18-AC17 -> 2 | AE18: 361937 | AF18: =AE18-AE17 -> 162.1 | AG18: =IF(AD18>0,AF18/AD18,0) -> 81.05 | AH18: =AF18+AA18 -> 162.1 | AI18: =SUM(AH18+V18) -> 434.1 | AJ18: =-tanks!AW19 -> 434.1 | AK18: =SUM(AJ18-AI18) -> 0 | AL18: =S18+L18+G18 -> 4 | AM18: =Y18+AD18 -> 2 | AN18: 71 | AO18: =(AN18/100)*3000 -> 2130 | AP18: 76 | AQ18: =(AP18/100)*3000 -> 2280 | AR18: 75 | AS18: =(AR18/100)*3000 -> 2250 | AT18: =SUM(AO18+AQ18+AS18) -> 6660 | AU18: =AT17-AT18+AV18 -> 150 | AX18: =IF(AV18>0,AW18,AX17) -> 0.7
A19: =ELEC!C17 -> 44027 | B19: 118.2 | C19: 125.2 | D19: =C18-C19 -> 18.8 | E19: =D19*8.38 -> 157.544 | F19: 1630 | G19: =F19-F18 -> 2 | H19: 356492 | I19: =SUM(H19-H18) -> 168 | J19: =IF(G19>0,I19/G19,0) -> 84 | K19: 2077 | L19: =K19-K18 -> 0 | M19: 152390 | N19: =M19-M18 -> 0 | O19: =O18 -> 211.875 | P19: 1830 | Q19: 155334 | R19: =Q19-Q18 -> 0 | S19: =SUM(P19-P18) -> 0 | T19: =SUM(S19*$T$2) -> 0 | U19: =SUM(G19+L19+S19) -> 2 | V19: =R19+N19+I19:I19 -> 168 | X19: 2418 | Y19: =X19-X18 -> 0 | Z19: 135964 | AA19: =Z19-Z18 -> 0 | AB19: =SUM(Y19*$AB$2) -> 0 | AC19: 1880 | AD19: =AC19-AC18 -> 5 | AE19: 362221 | AF19: =AE19-AE18 -> 284 | AG19: =IF(AD19>0,AF19/AD19,0) -> 56.8 | AH19: =AF19+AA19 -> 284 | AI19: =SUM(AH19+V19) -> 452 | AJ19: =-tanks!AW20 -> 452 | AK19: =SUM(AJ19-AI19) -> 0 | AL19: =S19+L20+G19 -> 2 | AM19: =Y19+AD19 -> 5 | AN19: 69 | AO19: =(AN19/100)*3000 -> 2070 | AP19: 73 | AQ19: =(AP19/100)*3000 -> 2190 | AR19: 73 | AS19: =(AR19/100)*3000 -> 2190 | AT19: =SUM(AO19+AQ19+AS19) -> 6450 | AU19: =AT18-AT19+AV19 -> 210 | AX19: =IF(AV19>0,AW19,AX18) -> 0.7
A20: =ELEC!C18 -> 44028 | B20: 171.3 | C20: 178 | D20: =C19-C20 -> -52.8 | E20: =D20*8.38 -> -442.464 | F20: 1633 | G20: =F20-F19 -> 3 | H20: 356674 | I20: =SUM(H20-H19) -> 182 | J20: =IF(G20>0,I20/G20,0) -> 60.666667 | K20: 2077 | L20: =K20-K19 -> 0 | M20: 152390 | N20: =M20-M19 -> 0 | O20: =O19 -> 211.875 | P20: 1830 | Q20: 155334 | R20: =Q20-Q19 -> 0 | S20: =SUM(P20-P19) -> 0 | T20: =SUM(S20*$T$2) -> 0 | U20: =SUM(G20+L20+S20) -> 3 | V20: =R20+N20+I20:I20 -> 182 | X20: 2418 | Y20: =X20-X19 -> 0 | Z20: 135964 | AA20: =Z20-Z19 -> 0 | AB20: =SUM(Y20*$AB$2) -> 0 | AC20: 1881 | AD20: =AC20-AC19 -> 1 | AE20: 362296 | AF20: =AE20-AE19 -> 75 | AG20: =IF(AD20>0,AF20/AD20,0) -> 75 | AH20: =AF20+AA20 -> 75 | AI20: =SUM(AH20+V20) -> 257 | AJ20: =-tanks!AW21 -> 257 | AK20: =SUM(AJ20-AI20) -> 0 | AL20: =S20+L21+G20 -> 3 | AM20: =Y20+AD20 -> 1 | AN20: 83 | AO20: =(AN20/100)*3000 -> 2490 | AP20: 83 | AQ20: =(AP20/100)*3000 -> 2490 | AR20: 82 | AS20: =(AR20/100)*3000 -> 2460 | AT20: =SUM(AO20+AQ20+AS20) -> 7440 | AU20: =AT19-AT20+AV20 -> 310 | AV20: 1300 | AW20: 0.7 | AX20: =IF(AV20>0,AW20,AX19) -> 0.7
A21: =ELEC!C19 -> 44029 | B21: 183 | C21: 189 | D21: =C20-C21 -> -11 | E21: =D21*8.38 -> -92.18 | F21: 1635 | G21: =F21-F20 -> 2 | H21: 356862 | I21: =SUM(H21-H20) -> 188 | J21: =IF(G21>0,I21/G21,0) -> 94 | K21: 2077 | L21: =K21-K20 -> 0 | M21: 152390 | N21: =M21-M20 -> 0 | O21: =O20 -> 211.875 | P21: 1830 | Q21: 155334 | R21: =Q21-Q20 -> 0 | S21: =SUM(P21-P20) -> 0 | T21: =SUM(S21*$T$2) -> 0 | U21: =SUM(G21+L21+S21) -> 2 | V21: =R21+N21+I21:I21 -> 188 | X21: 2418 | Y21: =X21-X20 -> 0 | Z21: 135964 | AA21: =Z21-Z20 -> 0 | AB21: =SUM(Y21*$AB$2) -> 0 | AC21: 1881 | AD21: =AC21-AC20 -> 0 | AE21: 362296 | AF21: =AE21-AE20 -> 0 | AG21: =IF(AD21>0,AF21/AD21,0) -> 0 | AH21: =AF21+AA21 -> 0 | AI21: =SUM(AH21+V21) -> 188 | AJ21: =-tanks!AW22 -> 188 | AK21: =SUM(AJ21-AI21) -> 0 | AL21: =S21+L21+G21 -> 2 | AM21: =Y21+AD21 -> 0 | AN21: 80 | AO21: =(AN21/100)*3000 -> 2400 | AP21: 83 | AQ21: =(AP21/100)*3000 -> 2490 | AR21: 80 | AS21: =(AR21/100)*3000 -> 2400 | AT21: =SUM(AO21+AQ21+AS21) -> 7290 | AU21: =AT20-AT21+AV21 -> 150 | AX21: =IF(AV21>0,AW21,AX20) -> 0.7
A22: =ELEC!C20 -> 44030 | B22: 163 | C22: 170 | D22: =C21-C22 -> 19 | E22: =D22*8.38 -> 159.22 | F22: 1637 | G22: =F22-F21 -> 2 | H22: 357042 | I22: =SUM(H22-H21) -> 180 | J22: =IF(G22>0,I22/G22,0) -> 90 | K22: =K21 -> 2077 | L22: =K22-K21 -> 0 | M22: =M21 -> 152390 | N22: =M22-M21 -> 0 | O22: =O21 -> 211.875 | P22: =P21 -> 1830 | Q22: =Q21 -> 155334 | R22: =Q22-Q21 -> 0 | S22: =SUM(P22-P21) -> 0 | T22: =SUM(S22*$T$2) -> 0 | U22: =SUM(G22+L22+S22) -> 2 | V22: =R22+N22+I22:I22 -> 180 | X22: =X21 -> 2418 | Y22: =X22-X21 -> 0 | Z22: =Z21 -> 135964 | AA22: =Z22-Z21 -> 0 | AB22: =SUM(Y22*$AB$2) -> 0 | AC22: 1883 | AD22: =AC22-AC21 -> 2 | AE22: 362443 | AF22: =AE22-AE21 -> 147 | AG22: =IF(AD22>0,AF22/AD22,0) -> 73.5 | AH22: =AF22+AA22 -> 147 | AI22: =SUM(AH22+V22) -> 327 | AJ22: =-tanks!AW23 -> 327 | AK22: =SUM(AJ22-AI22) -> 0 | AL22: =S22+L22+G22 -> 2 | AM22: =Y22+AD22 -> 2 | AN22: 78 | AO22: =(AN22/100)*3000 -> 2340 | AP22: 82 | AQ22: =(AP22/100)*3000 -> 2460 | AR22: 80 | AS22: =(AR22/100)*3000 -> 2400 | AT22: =SUM(AO22+AQ22+AS22) -> 7200 | AU22: =AT21-AT22+AV22 -> 90 | AX22: =IF(AV22>0,AW22,AX21) -> 0.7
A23: =ELEC!C21 -> 44031 | B23: 148 | C23: 155 | D23: =C22-C23 -> 15 | E23: =D23*8.38 -> 125.7 | F23: 1639 | G23: =F23-F22 -> 2 | H23: 357185 | I23: =SUM(H23-H22) -> 143 | J23: =IF(G23>0,I23/G23,0) -> 71.5 | K23: 2077 | L23: =K23-K22 -> 0 | M23: 152390 | N23: =M23-M22 -> 0 | O23: =O22 -> 211.875 | P23: 1830 | Q23: =Q22 -> 155334 | R23: =Q23-Q22 -> 0 | S23: =SUM(P23-P22) -> 0 | T23: =SUM(S23*$T$2) -> 0 | U23: =SUM(G23+L23+S23) -> 2 | V23: =R23+N23+I23:I23 -> 143 | X23: 2418 | Y23: =X23-X22 -> 0 | Z23: 135964 | AA23: =Z23-Z22 -> 0 | AB23: =SUM(Y23*$AB$2) -> 0 | AC23: 1883 | AD23: =AC23-AC22 -> 0 | AE23: 362443 | AF23: =AE23-AE22 -> 0 | AG23: =IF(AD23>0,AF23/AD23,0) -> 0 | AH23: =AF23+AA23 -> 0 | AI23: =SUM(AH23+V23) -> 143 | AJ23: =-tanks!AW24 -> 143 | AK23: =SUM(AJ23-AI23) -> 0 | AL23: =S23+L23+G23 -> 2 | AM23: =Y23+AD23 -> 0 | AN23: 78 | AO23: =(AN23/100)*3000 -> 2340 | AP23: 80 | AQ23: =(AP23/100)*3000 -> 2400 | AR23: 79 | AS23: =(AR23/100)*3000 -> 2370 | AT23: =SUM(AO23+AQ23+AS23) -> 7110 | AU23: =AT22-AT23+AV23 -> 90 | AX23: =IF(AV23>0,AW23,AX22) -> 0.7
A24: =ELEC!C22 -> 44032 | B24: 130 | C24: 137 | D24: =C23-C24 -> 18 | E24: =D24*8.38 -> 150.84 | F24: 1640 | G24: =F24-F23 -> 1 | H24: 357257 | I24: =SUM(H24-H23) -> 72 | J24: =IF(G24>0,I24/G24,0) -> 72 | K24: 2077 | L24: =K24-K23 -> 0 | M24: 152390 | N24: =M24-M23 -> 0 | O24: =O23 -> 211.875 | P24: 1830 | Q24: 155334 | R24: =Q24-Q23 -> 0 | S24: =SUM(P24-P23) -> 0 | T24: =SUM(S24*$T$2) -> 0 | U24: =SUM(G24+L24+S24) -> 1 | V24: =R24+N24+I24:I24 -> 72 | X24: 2418 | Y24: =X24-X23 -> 0 | Z24: 135964 | AA24: =Z24-Z23 -> 0 | AB24: =SUM(Y24*$AB$2) -> 0 | AC24: 1886 | AD24: =AC24-AC23 -> 3 | AE24: 362582 | AF24: =AE24-AE23 -> 139 | AG24: =IF(AD24>0,AF24/AD24,0) -> 46.333333 | AH24: =AF24+AA24 -> 139 | AI24: =SUM(AH24+V24) -> 211 | AJ24: =-tanks!AW25 -> 211 | AK24: =SUM(AJ24-AI24) -> 0 | AL24: =S24+L24+G24 -> 1 | AM24: =Y24+AD24 -> 3 | AN24: 76 | AO24: =(AN24/100)*3000 -> 2280 | AP24: 79 | AQ24: =(AP24/100)*3000 -> 2370 | AR24: 79 | AS24: =(AR24/100)*3000 -> 2370 | AT24: =SUM(AO24+AQ24+AS24) -> 7020 | AU24: =AT23-AT24+AV24 -> 90 | AX24: =IF(AV24>0,AW24,AX23) -> 0.7
A25: =ELEC!C23 -> 44033 | B25: 193.4 | C25: 199 | D25: =C24-C25 -> -62 | E25: =D25*8.38 -> -519.56 | F25: 1644 | G25: =F25-F24 -> 4 | H25: 357591 | I25: =SUM(H25-H24) -> 334 | J25: =IF(G25>0,I25/G25,0) -> 83.5 | K25: 2077 | L25: =K25-K24 -> 0 | M25: 152390 | N25: =M25-M24 -> 0 | O25: =O24 -> 211.875 | P25: 1830 | Q25: 155381 | R25: =Q25-Q24 -> 47 | S25: =SUM(P25-P24) -> 0 | T25: =SUM(S25*$T$2) -> 0 | U25: =SUM(G25+L25+S25) -> 4 | V25: =R25+N25+I25:I25 -> 381 | X25: 2418 | Y25: =X25-X24 -> 0 | Z25: 135964 | AA25: =Z25-Z24 -> 0 | AB25: =SUM(Y25*$AB$2) -> 0 | AC25: 1889 | AD25: =AC25-AC24 -> 3 | AE25: 362787 | AF25: =AE25-AE24 -> 205 | AG25: =IF(AD25>0,AF25/AD25,0) -> 68.333333 | AH25: =AF25+AA25 -> 205 | AI25: =SUM(AH25+V25) -> 586 | AJ25: =-tanks!AW26 -> 586 | AK25: =SUM(AJ25-AI25) -> 0 | AL25: =S25+L25+G25 -> 4 | AM25: =Y25+AD25 -> 3 | AN25: 68 | AO25: =(AN25/100)*3000 -> 2040 | AP25: 75 | AQ25: =(AP25/100)*3000 -> 2250 | AR25: 75 | AS25: =(AR25/100)*3000 -> 2250 | AT25: =SUM(AO25+AQ25+AS25) -> 6540 | AU25: =AT24-AT25+AV25 -> 480 | AX25: =IF(AV25>0,AW25,AX24) -> 0.7
A26: =ELEC!C24 -> 44034 | B26: 174 | C26: 181 | D26: =C25-C26 -> 18 | E26: =D26*8.38 -> 150.84 | F26: 1644 | G26: =F26-F25 -> 0 | H26: 357591 | I26: =SUM(H26-H25) -> 0 | J26: =IF(G26>0,I26/G26,0) -> 0 | K26: 2079 | L26: =K26-K25 -> 2 | M26: 152498 | N26: =M26-M25 -> 108 | O26: =O25 -> 211.875 | P26: 1831 | Q26: 155463 | R26: =Q26-Q25 -> 82 | S26: =SUM(P26-P25) -> 1 | T26: =SUM(S26*$T$2) -> 0 | U26: =SUM(G26+L26+S26) -> 3 | V26: =R26+N26+I26:I26 -> 190 | X26: 2418 | Y26: =X26-X25 -> 0 | Z26: 135964 | AA26: =Z26-Z25 -> 0 | AB26: =SUM(Y26*$AB$2) -> 0 | AC26: 1894 | AD26: =AC26-AC25 -> 5 | AE26: 363048 | AF26: =AE26-AE25 -> 261 | AG26: =IF(AD26>0,AF26/AD26,0) -> 52.2 | AH26: =AF26+AA26 -> 261 | AI26: =SUM(AH26+V26) -> 451 | AJ26: =-tanks!AW27 -> 451 | AK26: =SUM(AJ26-AI26) -> 0 | AL26: =S26+L26+G26 -> 3 | AM26: =Y26+AD26 -> 5 | AN26: 68 | AO26: =(AN26/100)*3000 -> 2040 | AP26: 73 | AQ26: =(AP26/100)*3000 -> 2190 | AR26: 72 | AS26: =(AR26/100)*3000 -> 2160 | AT26: =SUM(AO26+AQ26+AS26) -> 6390 | AU26: =AT25-AT26+AV26 -> 150 | AX26: =IF(AV26>0,AW26,AX25) -> 0.7
