Workbook

Sheet TOTAL
A1: Site Name | B1: Day | C1: Month | D1: Year | E1: Total Electricity Kwh | F1: Electricity Tariff ($/Kwh) | G1: LPG (Kg) | H1: LPG $/Kg | I1: Water Utility Supply (m3) m3 | J1: Water Utility Supply (m3) $/m3 | K1: Room Nights | N1: Water Tanks | O1: Cost of Water Tanks Rs | P1: Water Utility Supply (m3) Rs/m3 | Q1: Electricity Tariff (Rs/Kwh) | R1: LPG Rs/Kg | S1: Exchange Rate | T1: Total LPG Cost | U1: Total Water Cost
A2: Mauritius at Anahita | B2: 1 | C2: 7 | D2: 2020 | E2: =HOTEL!E4 -> 3297 | F2: 6.21 | G2: =HOTEL!CL4 -> 107.75 | H2: 57.45 | I2: =HOTEL!V4+HOTEL!Z4 -> 59 | J2: =P2 -> 34 | K2: =HOTEL!EF4 -> 3 | N2: =HOTEL!X4 -> 0 | O2: =N2*2500 -> 0 | P2: =IFERROR(((((HOTEL!V4*34))+(N2*2500))/(I2+N2*25)),0) -> 34 | Q2: 6.21 | R2: =H2 -> 57.45 | S2: 33.88 | T2: =G2*H2 -> 6190.2375 | U2: =I2*P2 -> 2006
A3: Mauritius at Anahita | B3: =B2+1 -> 2 | C3: 7 | D3: 2020 | E3: =HOTEL!E5 -> 3279 | F3: 6.21 | G3: =HOTEL!CL5 -> 0 | H3: 57.45 | I3: =HOTEL!V5+HOTEL!Z5 -> 75 | J3: =P3 -> 34 | K3: =HOTEL!EF5 -> 3 | N3: =HOTEL!X5 -> 0 | O3: =N3*2500 -> 0 | P3: =IFERROR(((((HOTEL!V5*34))+(N3*2500))/(I3+N3*25)),0) -> 34 | Q3: 6.21 | R3: =H3 -> 57.45 | S3: 33.88 | T3: =G3*H3 -> 0 | U3: =I3*P3 -> 2550
A4: Mauritius at Anahita | B4: =B3+1 -> 3 | C4: 7 | D4: 2020 | E4: =HOTEL!E6 -> 3144 | F4: 6.21 | G4: =HOTEL!CL6 -> 107.75 | H4: 57.45 | I4: =HOTEL!V6+HOTEL!Z6 -> 59 | J4: =P4 -> 34 | K4: =HOTEL!EF6 -> 3 | N4: =HOTEL!X6 -> 0 | O4: =N4*2500 -> 0 | P4: =IFERROR(((((HOTEL!V6*34))+(N4*2500))/(I4+N4*25)),0) -> 34 | Q4: 6.21 | R4: =H4 -> 57.45 | S4: 33.88 | T4: =G4*H4 -> 6190.2375 | U4: =I4*P4 -> 2006
A5: Mauritius at Anahita | B5: =B4+1 -> 4 | C5: 7 | D5: 2020 | E5: =HOTEL!E7 -> 3415 | F5: 6.21 | G5: =HOTEL!CL7 -> 0 | H5: 57.45 | I5: =HOTEL!V7+HOTEL!Z7 -> 68 | J5: =P5 -> 34 | K5: =HOTEL!EF7 -> 3 | N5: =HOTEL!X7 -> 0 | O5: =N5*2500 -> 0 | P5: =IFERROR(((((HOTEL!V7*34))+(N5*2500))/(I5+N5*25)),0) -> 34 | Q5: 6.21 | R5: =H5 -> 57.45 | S5: 33.88 | T5: =G5*H5 -> 0 | U5: =I5*P5 -> 2312
A6: Mauritius at Anahita | B6: =B5+1 -> 5 | C6: 7 | D6: 2020 | E6: =HOTEL!E8 -> 3148 | F6: 6.21 | G6: =HOTEL!CL8 -> 107.75 | H6: 57.45 | I6: =HOTEL!V8+HOTEL!Z8 -> 67 | J6: =P6 -> 34 | K6: =HOTEL!EF8 -> 2 | N6: =HOTEL!X8 -> 0 | O6: =N6*2500 -> 0 | P6: =IFERROR(((((HOTEL!V8*34))+(N6*2500))/(I6+N6*25)),0) -> 34 | Q6: 6.21 | R6: =H6 -> 57.45 | S6: 33.88 | T6: =G6*H6 -> 6190.2375 | U6: =I6*P6 -> 2278
A7: Mauritius at Anahita | B7: =B6+1 -> 6 | C7: 7 | D7: 2020 | E7: =HOTEL!E9 -> 3464 | F7: 6.21 | G7: =HOTEL!CL9 -> 0 | H7: 57.45 | I7: =HOTEL!V9+HOTEL!Z9 -> 68 | J7: =P7 -> 34 | K7: =HOTEL!EF9 -> 2 | N7: =HOTEL!X9 -> 0 | O7: =N7*2500 -> 0 | P7: =IFERROR(((((HOTEL!V9*34))+(N7*2500))/(I7+N7*25)),0) -> 34 | Q7: 6.21 | R7: =H7 -> 57.45 | S7: 33.88 | T7: =G7*H7 -> 0 | U7: =I7*P7 -> 2312
A8: Mauritius at Anahita | B8: =B7+1 -> 7 | C8: 7 | D8: 2020 | E8: =HOTEL!E10 -> 3430 | F8: 6.21 | G8: =HOTEL!CL10 -> 107.75 | H8: 57.45 | I8: =HOTEL!V10+HOTEL!Z10 -> 89 | J8: =P8 -> 34 | K8: =HOTEL!EF10 -> 2 | N8: =HOTEL!X10 -> 0 | O8: =N8*2500 -> 0 | P8: =IFERROR(((((HOTEL!V10*34))+(N8*2500))/(I8+N8*25)),0) -> 34 | Q8: 6.21 | R8: =H8 -> 57.45 | S8: 33.88 | T8: =G8*H8 -> 6190.2375 | U8: =I8*P8 -> 3026
A9: Mauritius at Anahita | B9: =B8+1 -> 8 | C9: 7 | D9: 2020 | E9: =HOTEL!E11 -> 3379 | F9: 6.21 | G9: =HOTEL!CL11 -> 0 | H9: 57.45 | I9: =HOTEL!V11+HOTEL!Z11 -> 73 | J9: =P9 -> 34 | K9: =HOTEL!EF11 -> 2 | N9: =HOTEL!X11 -> 0 | O9: =N9*2500 -> 0 | P9: =IFERROR(((((HOTEL!V11*34))+(N9*2500))/(I9+N9*25)),0) -> 34 | Q9: 6.21 | R9: =H9 -> 57.45 | S9: 33.88 | T9: =G9*H9 -> 0 | U9: =I9*P9 -> 2482
A10: Mauritius at Anahita | B10: =B9+1 -> 9 | C10: 7 | D10: 2020 | E10: =HOTEL!E12 -> 3546 | F10: 6.21 | G10: =HOTEL!CL12 -> 215.5 | H10: 57.45 | I10: =HOTEL!V12+HOTEL!Z12 -> 63 | J10: =P10 -> 34 | K10: =HOTEL!EF12 -> 2 | N10: =HOTEL!X12 -> 0 | O10: =N10*2500 -> 0 | P10: =IFERROR(((((HOTEL!V12*34))+(N10*2500))/(I10+N10*25)),0) -> 34 | Q10: 6.21 | R10: =H10 -> 57.45 | S10: 33.93 | T10: =G10*H10 -> 12380.475 | U10: =I10*P10 -> 2142
A11: Mauritius at Anahita | B11: =B10+1 -> 10 | C11: 7 | D11: 2020 | E11: =HOTEL!E13 -> 3325 | F11: 6.21 | G11: =HOTEL!CL13 -> 0 | H11: 57.45 | I11: =HOTEL!V13+HOTEL!Z13 -> 69 | J11: =P11 -> 34 | K11: =HOTEL!EF13 -> 2 | N11: =HOTEL!X13 -> 0 | O11: =N11*2500 -> 0 | P11: =IFERROR(((((HOTEL!V13*34))+(N11*2500))/(I11+N11*25)),0) -> 34 | Q11: 6.21 | R11: =H11 -> 57.45 | S11: 33.93 | T11: =G11*H11 -> 0 | U11: =I11*P11 -> 2346
A12: Mauritius at Anahita | B12: =B11+1 -> 11 | C12: 7 | D12: 2020 | E12: =HOTEL!E14 -> 3640 | F12: 6.21 | G12: =HOTEL!CL14 -> 0 | H12: 57.45 | I12: =HOTEL!V14+HOTEL!Z14 -> 68 | J12: =P12 -> 34 | K12: =HOTEL!EF14 -> 2 | N12: =HOTEL!X14 -> 0 | O12: =N12*2500 -> 0 | P12: =IFERROR(((((HOTEL!V14*34))+(N12*2500))/(I12+N12*25)),0) -> 34 | Q12: 6.21 | R12: =H12 -> 57.45 | S12: 33.93 | T12: =G12*H12 -> 0 | U12: =I12*P12 -> 2312
A13: Mauritius at Anahita | B13: =B12+1 -> 12 | C13: 7 | D13: 2020 | E13: =HOTEL!E15 -> 3338 | F13: 6.21 | G13: =HOTEL!CL15 -> 107.75 | H13: 57.45 | I13: =HOTEL!V15+HOTEL!Z15 -> 66 | J13: =P13 -> 34 | K13: =HOTEL!EF15 -> 2 | N13: =HOTEL!X15 -> 0 | O13: =N13*2500 -> 0 | P13: =IFERROR(((((HOTEL!V15*34))+(N13*2500))/(I13+N13*25)),0) -> 34 | Q13: 6.21 | R13: =H13 -> 57.45 | S13: 33.93 | T13: =G13*H13 -> 6190.2375 | U13: =I13*P13 -> 2244
A14: Mauritius at Anahita | B14: =B13+1 -> 13 | C14: 7 | D14: 2020 | E14: =HOTEL!E16 -> 3953 | F14: 6.21 | G14: =HOTEL!CL16 -> 215.5 | H14: 57.45 | I14: =HOTEL!V16+HOTEL!Z16 -> 85 | J14: =P14 -> 34 | K14: =HOTEL!EF16 -> 2 | N14: =HOTEL!X16 -> 0 | O14: =N14*2500 -> 0 | P14: =IFERROR(((((HOTEL!V16*34))+(N14*2500))/(I14+N14*25)),0) -> 34 | Q14: 6.21 | R14: =H14 -> 57.45 | S14: 33.93 | T14: =G14*H14 -> 12380.475 | U14: =I14*P14 -> 2890
... A29: Mauritius at Anahita | B29: =B28+1 -> 28 | C29: 7 | D29: 2020 | E29: =HOTEL!E31 -> 3618 | F29: 6.21 | G29: =HOTEL!CL31 -> 0 | H29: 57.45 | I29: =HOTEL!V31+HOTEL!Z31 -> 70 | J29: =P29 -> 34 | K29: =HOTEL!EF31 -> 1 | N29: =HOTEL!X31 -> 0 | O29: =N29*2500 -> 0 | P29: =IFERROR(((((HOTEL!V31*34))+(N29*2500))/(I29+N29*25)),0) -> 34 | Q29: 6.21 | R29: =H29 -> 57.45 | S29: 33.93 | T29: =G29*H29 -> 0 | U29: =I29*P29 -> 2380
A30: Mauritius at Anahita | B30: =B29+1 -> 29 | C30: 7 | D30: 2020 | E30: =HOTEL!E32 -> 3438 | F30: 6.21 | G30: =HOTEL!CL32 -> 107.75 | H30: 57.45 | I30: =HOTEL!V32+HOTEL!Z32 -> 68 | J30: =P30 -> 34 | K30: =HOTEL!EF32 -> 1 | N30: =HOTEL!X32 -> 0 | O30: =N30*2500 -> 0 | P30: =IFERROR(((((HOTEL!V32*34))+(N30*2500))/(I30+N30*25)),0) -> 34 | Q30: 6.21 | R30: =H30 -> 57.45 | T30: =G30*H30 -> 6190.2375 | U30: =I30*P30 -> 2312
A31: Mauritius at Anahita | B31: =B30+1 -> 30 | C31: 7 | D31: 2020 | E31: =HOTEL!E33 -> 3627 | F31: 6.21 | G31: =HOTEL!CL33 -> 0 | H31: 57.45 | I31: =HOTEL!V33+HOTEL!Z33 -> 71 | J31: =P31 -> 34 | K31: =HOTEL!EF33 -> 1 | N31: =HOTEL!X33 -> 0 | O31: =N31*2500 -> 0 | P31: =IFERROR(((((HOTEL!V33*34))+(N31*2500))/(I31+N31*25)),0) -> 34 | Q31: 6.21 | R31: =H31 -> 57.45 | T31: =G31*H31 -> 0 | U31: =I31*P31 -> 2414
A32: Mauritius at Anahita | B32: =B31+1 -> 31 | C32: 7 | D32: 2020 | E32: =HOTEL!E34 -> 3386 | F32: 6.21 | G32: =HOTEL!CL34 -> 107.75 | H32: 57.45 | I32: =HOTEL!V34+HOTEL!Z34 -> 63 | J32: =P32 -> 34 | K32: =HOTEL!EF34 -> 1 | N32: =HOTEL!X34 -> 0 | O32: =N32*2500 -> 0 | P32: =IFERROR(((((HOTEL!V34*34))+(N32*2500))/(I32+N32*25)),0) -> 34 | Q32: 6.21 | R32: =H32 -> 57.45 | T32: =G32*H32 -> 6190.2375 | U32: =I32*P32 -> 2142

Sheet Submetering
A1: Site Name | B1: Day | C1: Month | D1: Year | E1: Hotel (KWh) | F1: Vacoas (KWh) | G1: Laundry (KWh) | H1: Villa 145 (KWh) | I1: Villa 146 (KWh) | J1: Villa 111 (KWh) | K1: Villa 128 (KWh) | L1: Hotel (m3) | M1: Bamboo Pool (m3) | N1: Island (m3) | O1: Main Building (m3) | P1: Pantry A (m3) | Q1: Pantry B (m3) | R1: Pantry C (m3) | S1: Pantry D (m3) | T1: Pantry E (m3) | U1: Pantry F (m3) | V1: Pantry G (m3) | W1: North Parcel (m3) | X1: South Parcel (m3) | Y1: Beau champ (Kg) | Z1: Acquapazza (Kg) | AA1: Bamboo (Kg) | AB1: Steam Boiler (Kg) | AC1: Laundry (Kg) | AD1: Pantry A (Kg) | AE1: Pantry B (Kg) | AF1: Pantry C (Kg) | AG1: Pantry D (Kg) | AH1: Pantry E (Kg) | AI1: Pantry F (Kg) | AJ1: Pantry G (Kg) | AK1: Room Nights
A2: Mauritius at Anahita | B2: 1 | C2: 6 | D2: 2020 | E2: =TOTAL!E2 -> 3297 | F2: =HOTEL!R4 -> 0 | G2: =HOTEL!T4 -> 7 | H2: =HOTEL!DY4 -> 0 | I2: =HOTEL!EA4 -> 0 | J2: =HOTEL!EC4 -> 0 | K2: =HOTEL!EE4 -> 0 | L2: =N2+W2+X2 -> 50 | M2: =HOTEL!AF4 -> 0 | N2: =HOTEL!AJ4 -> 20 | O2: =HOTEL!AN4 -> 1 | P2: =HOTEL!AP4 -> 0 | Q2: =HOTEL!AR4 -> 0 | R2: =HOTEL!AT4 -> 0 | S2: =HOTEL!AV4 -> 0 | T2: =HOTEL!AX4 -> 0 | U2: =HOTEL!AZ4 -> 0 | V2: =HOTEL!BB4 -> 0 | W2: =HOTEL!BN4 -> 20 | X2: =HOTEL!BU4 -> 10 | Y2: =HOTEL!CP4 -> 4.148 | Z2: =HOTEL!CS3 -> 0 | AA2: =HOTEL!CV4 -> 0 | AB2: =HOTEL!CY4 -> 0 | AC2: =HOTEL!DB4 -> 0 | AD2: =HOTEL!DE4 -> 0 | AE2: =HOTEL!DH4 -> 3.824 | AF2: =HOTEL!DK4 -> 0.0478 | AG2: =HOTEL!DN4 -> 0 | AH2: =HOTEL!DQ4 -> 0 | AI2: =HOTEL!DT4 -> 0 | AJ2: =HOTEL!DW4 -> 0 | AK2: =TOTAL!K2 -> 3
A3: Mauritius at Anahita | B3: =B2+1 -> 2 | C3: 6 | D3: 2020 | E3: =TOTAL!E3 -> 3279 | F3: =HOTEL!R5 -> 87 | G3: =HOTEL!T5 -> 4 | H3: =HOTEL!DY5 -> 0 | I3: =HOTEL!EA5 -> 0 | J3: =HOTEL!EC5 -> 0 | K3: =HOTEL!EE5 -> 0 | L3: =N3+W3+X3 -> 70 | M3: =HOTEL!AF5 -> 0 | N3: =HOTEL!AJ5 -> 60 | O3: =HOTEL!AN5 -> 1 | P3: =HOTEL!AP5 -> 2 | Q3: =HOTEL!AR5 -> 0 | R3: =HOTEL!AT5 -> 0 | S3: =HOTEL!AV5 -> 0 | T3: =HOTEL!AX5 -> 0 | U3: =HOTEL!AZ5 -> 0 | V3: =HOTEL!BB5 -> 0 | W3: =HOTEL!BN5 -> 10 | X3: =HOTEL!BU5 -> 0 | Y3: =HOTEL!CP5 -> 3.172 | Z3: =HOTEL!CS4 -> 0 | AA3: =HOTEL!CV5 -> 0 | AB3: =HOTEL!CY5 -> 0 | AC3: =HOTEL!DB5 -> 0 | AD3: =HOTEL!DE5 -> 0 | AE3: =HOTEL!DH5 -> 13.862 | AF3: =HOTEL!DK5 -> 0 | AG3: =HOTEL!DN5 -> 0 | AH3: =HOTEL!DQ5 -> 0 | AI3: =HOTEL!DT5 -> 0 | AJ3: =HOTEL!DW5 -> 0 | AK3: =TOTAL!K3 -> 3
A4: Mauritius at Anahita | B4: =B3+1 -> 3 | C4: 6 | D4: 2020 | E4: =TOTAL!E4 -> 3144 | F4: =HOTEL!R6 -> 34 | G4: =HOTEL!T6 -> 1 | H4: =HOTEL!DY6 -> 0 | I4: =HOTEL!EA6 -> 0 | J4: =HOTEL!EC6 -> 0 | K4: =HOTEL!EE6 -> 0 | L4: =N4+W4+X4 -> 50 | M4: =HOTEL!AF6 -> 0 | N4: =HOTEL!AJ6 -> 30 | O4: =HOTEL!AN6 -> 0 | P4: =HOTEL!AP6 -> 0 | Q4: =HOTEL!AR6 -> 1 | R4: =HOTEL!AT6 -> 0 | S4: =HOTEL!AV6 -> 0 | T4: =HOTEL!AX6 -> 0 | U4: =HOTEL!AZ6 -> 0 | V4: =HOTEL!BB6 -> 1 | W4: =HOTEL!BN6 -> 20 | X4: =HOTEL!BU6 -> 0 | Y4: =HOTEL!CP6 -> 1.708 | Z4: =HOTEL!CS5 -> 0 | AA4: =HOTEL!CV6 -> 0 | AB4: =HOTEL!CY6 -> 0 | AC4: =HOTEL!DB6 -> 0 | AD4: =HOTEL!DE6 -> 0 | AE4: =HOTEL!DH6 -> 4.78 | AF4: =HOTEL!DK6 -> 0 | AG4: =HOTEL!DN6 -> 0 | AH4: =HOTEL!DQ6 -> 0 | AI4: =HOTEL!DT6 -> 0 | AJ4: =HOTEL!DW6 -> 0 | AK4: =TOTAL!K4 -> 3
A5: Mauritius at Anahita | B5: =B4+1 -> 4 | C5: 6 | D5: 2020 | E5: =TOTAL!E5 -> 3415 | F5: =HOTEL!R7 -> 47 | G5: =HOTEL!T7 -> 1 | H5: =HOTEL!DY7 -> 0 | I5: =HOTEL!EA7 -> 0 | J5: =HOTEL!EC7 -> 0 | K5: =HOTEL!EE7 -> 0 | L5: =N5+W5+X5 -> 80 | M5: =HOTEL!AF7 -> 0 | N5: =HOTEL!AJ7 -> 40 | O5: =HOTEL!AN7 -> 1 | P5: =HOTEL!AP7 -> 0 | Q5: =HOTEL!AR7 -> 0 | R5: =HOTEL!AT7 -> 0 | S5: =HOTEL!AV7 -> 0 | T5: =HOTEL!AX7 -> 0 | U5: =HOTEL!AZ7 -> 0 | V5: =HOTEL!BB7 -> 0 | W5: =HOTEL!BN7 -> 40 | X5: =HOTEL!BU7 -> 0 | Y5: =HOTEL!CP7 -> 2.44 | Z5: =HOTEL!CS6 -> 0 | AA5: =HOTEL!CV7 -> 0 | AB5: =HOTEL!CY7 -> 0 | AC5: =HOTEL!DB7 -> 0 | AD5: =HOTEL!DE7 -> 0 | AE5: =HOTEL!DH7 -> 7.648 | AF5: =HOTEL!DK7 -> 0 | AG5: =HOTEL!DN7 -> 0 | AH5: =HOTEL!DQ7 -> 0 | AI5: =HOTEL!DT7 -> 0 | AJ5: =HOTEL!DW7 -> 0 | AK5: =TOTAL!K5 -> 3
A6: Mauritius at Anahita | B6: =B5+1 -> 5 | C6: 6 | D6: 2020 | E6: =TOTAL!E6 -> 3148 | F6: =HOTEL!R8 -> 82 | G6: =HOTEL!T8 -> 0 | H6: =HOTEL!DY8 -> 0 | I6: =HOTEL!EA8 -> 0 | J6: =HOTEL!EC8 -> 0 | K6: =HOTEL!EE8 -> 0 | L6: =N6+W6+X6 -> 100 | M6: =HOTEL!AF8 -> 0 | N6: =HOTEL!AJ8 -> 70 | O6: =HOTEL!AN8 -> 0 | P6: =HOTEL!AP8 -> 0 | Q6: =HOTEL!AR8 -> 0 | R6: =HOTEL!AT8 -> 0 | S6: =HOTEL!AV8 -> 0 | T6: =HOTEL!AX8 -> 0 | U6: =HOTEL!AZ8 -> 0 | V6: =HOTEL!BB8 -> 0 | W6: =HOTEL!BN8 -> 30 | X6: =HOTEL!BU8 -> 0 | Y6: =HOTEL!CP8 -> 1.22 | Z6: =HOTEL!CS7 -> 0 | AA6: =HOTEL!CV8 -> 0 | AB6: =HOTEL!CY8 -> 0 | AC6: =HOTEL!DB8 -> 5.975 | AD6: =HOTEL!DE8 -> 0 | AE6: =HOTEL!DH8 -> 13.862 | AF6: =HOTEL!DK8 -> 0 | AG6: =HOTEL!DN8 -> 0 | AH6: =HOTEL!DQ8 -> 0 | AI6: =HOTEL!DT8 -> 0 | AJ6: =HOTEL!DW8 -> 0 | AK6: =TOTAL!K6 -> 2
A7: Mauritius at Anahita | B7: =B6+1 -> 6 | C7: 6 | D7: 2020 | E7: =TOTAL!E7 -> 3464 | F7: =HOTEL!R9 -> 40 | G7: =HOTEL!T9 -> 4 | H7: =HOTEL!DY9 -> 0 | I7: =HOTEL!EA9 -> 0 | J7: =HOTEL!EC9 -> 0 | K7: =HOTEL!EE9 -> 0 | L7: =N7+W7+X7 -> 40 | M7: =HOTEL!AF9 -> 0 | N7: =HOTEL!AJ9 -> 20 | O7: =HOTEL!AN9 -> 1 | P7: =HOTEL!AP9 -> 0 | Q7: =HOTEL!AR9 -> 0 | R7: =HOTEL!AT9 -> 0 | S7: =HOTEL!AV9 -> 0 | T7: =HOTEL!AX9 -> 0 | U7: =HOTEL!AZ9 -> 0 | V7: =HOTEL!BB9 -> 0 | W7: =HOTEL!BN9 -> 20 | X7: =HOTEL!BU9 -> 0 | Y7: =HOTEL!CP9 -> 2.44 | Z7: =HOTEL!CS8 -> 0 | AA7: =HOTEL!CV9 -> 0 | AB7: =HOTEL!CY9 -> 0 | AC7: =HOTEL!DB9 -> 1.912 | AD7: =HOTEL!DE9 -> 0 | AE7: =HOTEL!DH9 -> 3.824 | AF7: =HOTEL!DK9 -> 0 | AG7: =HOTEL!DN9 -> 0 | AH7: =HOTEL!DQ9 -> 0 | AI7: =HOTEL!DT9 -> 0 | AJ7: =HOTEL!DW9 -> 0 | AK7: =TOTAL!K7 -> 2
A8: Mauritius at Anahita | B8: =B7+1 -> 7 | C8: 6 | D8: 2020 | E8: =TOTAL!E8 -> 3430 | F8: =HOTEL!R10 -> 67 | G8: =HOTEL!T10 -> 3 | H8: =HOTEL!DY10 -> 0 | I8: =HOTEL!EA10 -> 0 | J8: =HOTEL!EC10 -> 0 | K8: =HOTEL!EE10 -> 0 | L8: =N8+W8+X8 -> 90 | M8: =HOTEL!AF10 -> 0 | N8: =HOTEL!AJ10 -> 70 | O8: =HOTEL!AN10 -> 1 | P8: =HOTEL!AP10 -> 0 | Q8: =HOTEL!AR10 -> 0 | R8: =HOTEL!AT10 -> 0 | S8: =HOTEL!AV10 -> 0 | T8: =HOTEL!AX10 -> 0 | U8: =HOTEL!AZ10 -> 0 | V8: =HOTEL!BB10 -> 0 | W8: =HOTEL!BN10 -> 20 | X8: =HOTEL!BU10 -> 0 | Y8: =HOTEL!CP10 -> 3.904 | Z8: =HOTEL!CS9 -> 0 | AA8: =HOTEL!CV10 -> 0 | AB8: =HOTEL!CY10 -> 0 | AC8: =HOTEL!DB10 -> 2.39 | AD8: =HOTEL!DE10 -> 0 | AE8: =HOTEL!DH10 -> 8.365 | AF8: =HOTEL!DK10 -> 0 | AG8: =HOTEL!DN10 -> 0 | AH8: =HOTEL!DQ10 -> 0 | AI8: =HOTEL!DT10 -> 0 | AJ8: =HOTEL!DW10 -> 0 | AK8: =TOTAL!K8 -> 2
A9: Mauritius at Anahita | B9: =B8+1 -> 8 | C9: 6 | D9: 2020 | E9: =TOTAL!E9 -> 3379 | F9: =HOTEL!R11 -> 87 | G9: =HOTEL!T11 -> 3 | H9: =HOTEL!DY11 -> 0 | I9: =HOTEL!EA11 -> 0 | J9: =HOTEL!EC11 -> 0 | K9: =HOTEL!EE11 -> 0 | L9: =N9+W9+X9 -> 40 | M9: =HOTEL!AF11 -> 0 | N9: =HOTEL!AJ11 -> 20 | O9: =HOTEL!AN11 -> 0 | P9: =HOTEL!AP11 -> 0 | Q9: =HOTEL!AR11 -> 0 | R9: =HOTEL!AT11 -> 0 | S9: =HOTEL!AV11 -> 0 | T9: =HOTEL!AX11 -> 0 | U9: =HOTEL!AZ11 -> 0 | V9: =HOTEL!BB11 -> 0 | W9: =HOTEL!BN11 -> 20 | X9: =HOTEL!BU11 -> 0 | Y9: =HOTEL!CP11 -> 1.708 | Z9: =HOTEL!CS10 -> 0 | AA9: =HOTEL!CV11 -> 0 | AB9: =HOTEL!CY11 -> 0 | AC9: =HOTEL!DB11 -> 0.478 | AD9: =HOTEL!DE11 -> 0 | AE9: =HOTEL!DH11 -> 9.321 | AF9: =HOTEL!DK11 -> 0 | AG9: =HOTEL!DN11 -> 0 | AH9: =HOTEL!DQ11 -> 0 | AI9: =HOTEL!DT11 -> 0 | AJ9: =HOTEL!DW11 -> 0 | AK9: =TOTAL!K9 -> 2
A10: Mauritius at Anahita | B10: =B9+1 -> 9 | C10: 6 | D10: 2020 | E10: =TOTAL!E10 -> 3546 | F10: =HOTEL!R12 -> 95 | G10: =HOTEL!T12 -> 0 | H10: =HOTEL!DY12 -> 0 | I10: =HOTEL!EA12 -> 0 | J10: =HOTEL!EC12 -> 0 | K10: =HOTEL!EE12 -> 0 | L10: =N10+W10+X10 -> 90 | M10: =HOTEL!AF12 -> 0 | N10: =HOTEL!AJ12 -> 70 | O10: =HOTEL!AN12 -> 0 | P10: =HOTEL!AP12 -> 3 | Q10: =HOTEL!AR12 -> 1 | R10: =HOTEL!AT12 -> 0 | S10: =HOTEL!AV12 -> 0 | T10: =HOTEL!AX12 -> 0 | U10: =HOTEL!AZ12 -> 0 | V10: =HOTEL!BB12 -> 0 | W10: =HOTEL!BN12 -> 20 | X10: =HOTEL!BU12 -> 0 | Y10: =HOTEL!CP12 -> 1.4396 | Z10: =HOTEL!CS11 -> 0 | AA10: =HOTEL!CV12 -> 0 | AB10: =HOTEL!CY12 -> 0 | AC10: =HOTEL!DB12 -> 1.434 | AD10: =HOTEL!DE12 -> 0 | AE10: =HOTEL!DH12 -> 13.384 | AF10: =HOTEL!DK12 -> 0 | AG10: =HOTEL!DN12 -> 0 | AH10: =HOTEL!DQ12 -> 0 | AI10: =HOTEL!DT12 -> 0 | AJ10: =HOTEL!DW12 -> 0 | AK10: =TOTAL!K10 -> 2
A11: Mauritius at Anahita | B11: =B10+1 -> 10 | C11: 6 | D11: 2020 | E11: =TOTAL!E11 -> 3325 | F11: =HOTEL!R13 -> 23 | G11: =HOTEL!T13 -> 44 | H11: =HOTEL!DY13 -> 0 | I11: =HOTEL!EA13 -> 0 | J11: =HOTEL!EC13 -> 0 | K11: =HOTEL!EE13 -> 0 | L11: =N11+W11+X11 -> 40 | M11: =HOTEL!AF13 -> 0 | N11: =HOTEL!AJ13 -> 10 | O11: =HOTEL!AN13 -> 1 | P11: =HOTEL!AP13 -> 0 | Q11: =HOTEL!AR13 -> 0 | R11: =HOTEL!AT13 -> 0 | S11: =HOTEL!AV13 -> 0 | T11: =HOTEL!AX13 -> 0 | U11: =HOTEL!AZ13 -> 0 | V11: =HOTEL!BB13 -> 0 | W11: =HOTEL!BN13 -> 30 | X11: =HOTEL!BU13 -> 0 | Y11: =HOTEL!CP13 -> 0 | Z11: =HOTEL!CS12 -> 0 | AA11: =HOTEL!CV13 -> 0 | AB11: =HOTEL!CY13 -> 0 | AC11: =HOTEL!DB13 -> 0 | AD11: =HOTEL!DE13 -> 0 | AE11: =HOTEL!DH13 -> 3.107 | AF11: =HOTEL!DK13 -> 0 | AG11: =HOTEL!DN13 -> 0 | AH11: =HOTEL!DQ13 -> 0 | AI11: =HOTEL!DT13 -> 0 | AJ11: =HOTEL!DW13 -> 0 | AK11: =TOTAL!K11 -> 2
A12: Mauritius at Anahita | B12: =B11+1 -> 11 | C12: 6 | D12: 2020 | E12: =TOTAL!E12 -> 3640 | F12: =HOTEL!R14 -> 48 | G12: =HOTEL!T14 -> 23 | H12: =HOTEL!DY14 -> 0 | I12: =HOTEL!EA14 -> 0 | J12: =HOTEL!EC14 -> 0 | K12: =HOTEL!EE14 -> 0 | L12: =N12+W12+X12 -> 100 | M12: =HOTEL!AF14 -> 0 | N12: =HOTEL!AJ14 -> 70 | O12: =HOTEL!AN14 -> 1 | P12: =HOTEL!AP14 -> 0 | Q12: =HOTEL!AR14 -> 0 | R12: =HOTEL!AT14 -> 0 | S12: =HOTEL!AV14 -> 1 | T12: =HOTEL!AX14 -> 0 | U12: =HOTEL!AZ14 -> 0 | V12: =HOTEL!BB14 -> 0 | W12: =HOTEL!BN14 -> 30 | X12: =HOTEL!BU14 -> 0 | Y12: =HOTEL!CP14 -> 2.9524 | Z12: =HOTEL!CS13 -> 0 | AA12: =HOTEL!CV14 -> 0 | AB12: =HOTEL!CY14 -> 0 | AC12: =HOTEL!DB14 -> 2.629 | AD12: =HOTEL!DE14 -> 0 | AE12: =HOTEL!DH14 -> 10.038 | AF12: =HOTEL!DK14 -> 0 | AG12: =HOTEL!DN14 -> 0 | AH12: =HOTEL!DQ14 -> 0 | AI12: =HOTEL!DT14 -> 0 | AJ12: =HOTEL!DW14 -> 0 | AK12: =TOTAL!K12 -> 2
A13: Mauritius at Anahita | B13: =B12+1 -> 12 | C13: 6 | D13: 2020 | E13: =TOTAL!E13 -> 3338 | F13: =HOTEL!R15 -> 51 | G13: =HOTEL!T15 -> 0 | H13: =HOTEL!DY15 -> 0 | I13: =HOTEL!EA15 -> 0 | J13: =HOTEL!EC15 -> 0 | K13: =HOTEL!EE15 -> 0 | L13: =N13+W13+X13 -> 60 | M13: =HOTEL!AF15 -> 11 | N13: =HOTEL!AJ15 -> 20 | O13: =HOTEL!AN15 -> 0 | P13: =HOTEL!AP15 -> 0 | Q13: =HOTEL!AR15 -> 0 | R13: =HOTEL!AT15 -> 0 | S13: =HOTEL!AV15 -> 0 | T13: =HOTEL!AX15 -> 0 | U13: =HOTEL!AZ15 -> 0 | V13: =HOTEL!BB15 -> 0 | W13: =HOTEL!BN15 -> 20 | X13: =HOTEL!BU15 -> 20 | Y13: =HOTEL!CP15 -> 1.464 | Z13: =HOTEL!CS14 -> 0 | AA13: =HOTEL!CV15 -> 0 | AB13: =HOTEL!CY15 -> 0 | AC13: =HOTEL!DB15 -> 0.956 | AD13: =HOTEL!DE15 -> 0 | AE13: =HOTEL!DH15 -> 11.95 | AF13: =HOTEL!DK15 -> 0 | AG13: =HOTEL!DN15 -> 0 | AH13: =HOTEL!DQ15 -> 0 | AI13: =HOTEL!DT15 -> 0 | AJ13: =HOTEL!DW15 -> 0 | AK13: =TOTAL!K13 -> 2
A14: Mauritius at Anahita | B14: =B13+1 -> 13 | C14: 6 | D14: 2020 | E14: =TOTAL!E14 -> 3953 | F14: =HOTEL!R16 -> 86 | G14: =HOTEL!T16 -> 143 | H14: =HOTEL!DY16 -> 0 | I14: =HOTEL!EA16 -> 0 | J14: =HOTEL!EC16 -> 0 | K14: =HOTEL!EE16 -> 0 | L14: =N14+W14+X14 -> 130 | M14: =HOTEL!AF16 -> 0 | N14: =HOTEL!AJ16 -> 80 | O14: =HOTEL!AN16 -> 2 | P14: =HOTEL!AP16 -> 0 | Q14: =HOTEL!AR16 -> 0 | R14: =HOTEL!AT16 -> 0 | S14: =HOTEL!AV16 -> 0 | T14: =HOTEL!AX16 -> 0 | U14: =HOTEL!AZ16 -> 0 | V14: =HOTEL!BB16 -> 0 | W14: =HOTEL!BN16 -> 50 | X14: =HOTEL!BU16 -> 0 | Y14: =HOTEL!CP16 -> 1.22 | Z14: =HOTEL!CS15 -> 0 | AA14: =HOTEL!CV16 -> 0 | AB14: =HOTEL!CY16 -> 179.8 | AC14: =HOTEL!DB16 -> 2.39 | AD14: =HOTEL!DE16 -> 0 | AE14: =HOTEL!DH16 -> 5.736 | AF14: =HOTEL!DK16 -> 0 | AG14: =HOTEL!DN16 -> 0 | AH14: =HOTEL!DQ16 -> 0 | AI14: =HOTEL!DT16 -> 0 | AJ14: =HOTEL!DW16 -> 0 | AK14: =TOTAL!K14 -> 2
... A32: Mauritius at Anahita | B32: =B31+1 -> 31 | C32: 6 | D32: 2020 | E32: =TOTAL!E32 -> 3386 | F32: =HOTEL!R34 -> 297 | G32: =HOTEL!T34 -> 74 | H32: =HOTEL!DY34 -> 0 | I32: =HOTEL!EA34 -> 0 | J32: =HOTEL!EC34 -> 0 | K32: =HOTEL!EE34 -> 0 | L32: =N32+W32+X32 -> 60 | M32: =HOTEL!AF34 -> 0 | N32: =HOTEL!AJ34 -> 40 | O32: =HOTEL!AN34 -> 2 | P32: =HOTEL!AP34 -> 0 | Q32: =HOTEL!AR34 -> 0 | R32: =HOTEL!AT34 -> 0 | S32: =HOTEL!AV34 -> 0 | T32: =HOTEL!AX34 -> 0 | U32: =HOTEL!AZ34 -> 0 | V32: =HOTEL!BB34 -> 0 | W32: =HOTEL!BN34 -> 20 | X32: =HOTEL!BU34 -> 0 | Y32: =HOTEL!CP34 -> 4.88 | Z32: =HOTEL!CS33 -> 0 | AA32: =HOTEL!CV34 -> 0 | AB32: =HOTEL!CY34 -> 0 | AC32: =HOTEL!DB34 -> 2.629 | AD32: =HOTEL!DE34 -> 0 | AE32: =HOTEL!DH34 -> 0 | AF32: =HOTEL!DK34 -> 0 | AG32: =HOTEL!DN34 -> 0 | AH32: =HOTEL!DQ34 -> 0 | AI32: =HOTEL!DT34 -> 0 | AJ32: =HOTEL!DW34 -> 0 | AK32: =TOTAL!K32 -> 1

Sheet HOTEL
B1: Hotel Electricity | I1: Gen 01 | M1: Gen 02 | Q1: Vacoas KW | R1: CONS | S1: Laundry (KWh) | T1: CONS | U1: Hotel | W1: % Water Available | X1: water truck | AC1: Water Softener | AE1: bamboo pool | AG1: laundry | AH1: CONS | AI1: Island | AK1: Island Sub | AM1: Main Building | AO1: Pantry A | AQ1: Pantry B | AS1: Pantry C | AU1: Pantry D | AW1: Pantry E | AY1: Pantry F | BA1: Pantry G | BM1: North | BO1: North Sub | BQ1: South | BS1: South Sub | BX1: Diesel | CB1: Gas | CW1: Steam Boiler | CZ1: Main Building | DC1: Pantry A | DF1: Pantry B | DI1: Pantry C | DL1: Pantry D | DO1: Pantry E | DR1: Pantry F | DU1: Pantry G | EI1: Pool Temperature
A2: Date | B2: KVAH | C2: CONS | D2: KWH | E2: CONS | F2: PF | G2: KVA | H2: KVA max | U2: CWA23 | V2: CONS | Y2: Truck Meter | Z2: Cons | AA2: UV reading | AC2: chiller | AD2: CONS | AF2: CONS | AI2: island | AJ2: cons | AM2: M.Buil | AN2: Cons | AO2: Pantry A | AP2: Cons | AQ2: Pantry B | AR2: Cons | AS2: Pantry C | AT2: cons | AU2: Pantry D | AV2: cons | AW2: Pantry E | AX2: cons | AY2: Pantry F | AZ2: Cons | BA2: Pantry G | BB2: Cons | BC2: Main Kitchen | BD2: Cons | BE2: Bamboo H | BF2: Cons | BG2: Bamboo C | BH2: Cons | BI2: cyclon bridge | BJ2: cons | BK2: Island - Hot | BL2: Island Cold | BM2: north | BN2: cons | BQ2: south | BR2: cons | BU2: south | BV2: Total water consump | BW2: Total HW consump | BX2: DIESEL | BY2: stock | BZ2: Del | CA2: CONS | CB2: Meter | CC2: cons | CD2: Kg | CE2: LPG 1 | CF2: stock | CG2: LPG 2 | CH2: stock | CI2: LPG 3 | CJ2: stock | CK2: total stock | CL2: cons | CM2: del | CN2: Beau champ | CO2: cons(Litres) | CP2: Cons(Kg) | CQ2: Acquapazza | CR2: cons(Litres) | CS2: Cons(Kg) | CT2: Bamboo | CU2: cons(Litres) | CV2: Cons(Kg) | CX2: cons(Litres) | CY2: Cons(Kg) | DA2: cons(Litres) | DB2: Cons(Kg) | DD2: cons(Litres) | DE2: Cons(Kg) | DG2: cons(Litres) | DH2: Cons(Kg) | DJ2: cons(Litres) | DK2: Cons(Kg) | DM2: cons(Litres) | DN2: Cons(Kg) | DP2: cons(Litres) | DQ2: Cons(Kg) | DS2: cons(Litres) | DT2: Cons(Kg) | DV2: cons(Litres) | DW2: Cons(Kg) | DX2: 145 | DY2: CONS | DZ2: 146 | EA2: CONS | EB2: Villa 111 | EC2: CONS | ED2: Villa 128 | EE2: CONS | EF2: Room Nights | EG2: Bed Nights | EH2: % OCC | EI2: California | EJ2: Infiniti | EK2: Fitness
A3: 44012 | B3: 5212270 | C3: 3502 | D3: 4563827 | E3: 3154 | F3: 0.90062821 | G3: 286 | H3: 430 | I3: 285707 | J3: 0 | K3: 750 | L3: 0 | M3: 629908 | N3: 0 | O3: 967 | P3: 0 | Q3: 2530500 | R3: 0 | S3: 2187519 | T3: 0 | U3: 92200 | V3: 63 | W3: 100 | X3: 0 | Y3: 152258 | Z3: 0 | AA3: 37827 | AB3: 5 | AC3: 1058 | AD3: 0 | AE3: 3689 | AF3: 0 | AI3: 570640 | AJ3: 70 | AM3: 52016 | AN3: 0 | AO3: 8864 | AP3: 0 | AQ3: 10548 | AR3: 0 | AS3: 14481 | AT3: 0 | AU3: 19349 | AV3: 0 | AW3: 20660 | AX3: 0 | AY3: 13831 | AZ3: 0 | BA3: 6152 | BB3: 0 | BC3: 26342 | BD3: 0 | BE3: 1112 | BF3: 0 | BG3: 4303 | BH3: 0 | BI3: 3636 | BJ3: 0 | BK3: 0 | BL3: 70 | BM3: 594960 | BN3: 10 | BO3: 581 | BP3: 0 | BQ3: 767670 | BR3: 70 | BS3: 5866 | BT3: 0 | BU3: 0 | BV3: 80 | BW3: 0 | BX3: 142.3 | BY3: 18260.186 | CA3: 45.592307 | CB3: 205885.9 | CC3: 1.4 | CD3: 7.994 | CE3: 40 | CF3: 4310 | CG3: 41 | CH3: 4417.75 | CI3: 44 | CJ3: 4741 | CK3: 13468.75 | CL3: 107.75 | CN3: 34091.2 | CO3: 1.8 | CP3: 4.392 | CQ3: 34300 | CR3: 0 | CS3: 0 | CT3: 10234 | CU3: 0 | CV3: 0 | CW3: 831923 | CX3: 0 | CY3: 0 | CZ3: 5719.1 | DA3: 0.6 | DB3: 1.434 | DC3: 7415 | DD3: 0 | DE3: 0 | DF3: 3777.7 | DG3: 4 | DH3: 9.56 | DI3: 1855.78 | DJ3: 0 | DK3: 0 | DL3: 5078.4 | DM3: 0 | DN3: 0 | DO3: 4451.7 | DP3: 0 | DQ3: 0 | DR3: 5086.1 | DS3: 0 | DT3: 0 | DU3: 4320.7 | DV3: 0 | DW3: 0 | DX3: 12732 | DY3: 0 | DZ3: 61889 | EA3: 0 | EB3: 15599 | EC3: 0 | ED3: 24594 | EE3: 0 | EF3: 3 | EG3: 11 | EH3: 0.015
A4: 44013 | B4: 5216107 | C4: =IF((B4-B3)<0,"0",(B4-B3)) -> 3837 | D4: 4567124 | E4: =IF((D4-D3)<0,"0",(D4-D3)) -> 3297 | F4: =E4/C4 -> 0.85926505 | G4: 286 | H4: 430 | I4: 285707 | J4: 0 | K4: 750 | L4: 0 | M4: 629908 | N4: 0 | O4: 967 | P4: 0 | Q4: 2530500 | R4: =IF((Q4-Q3)<0,"0",(Q4-Q3)) -> 0 | S4: 2187526 | T4: =IF((S4-S3)<0,"0",(S4-S3)) -> 7 | U4: 92259 | V4: =IF((U4-U3)<0,"0",(U4-U3)) -> 59 | W4: 100 | X4: 0 | Y4: 152258 | Z4: =IF((Y4-Y3)<0,"0",(Y4-Y3)) -> 0 | AA4: 37834 | AB4: =IF((AA4-AA3)<0,"0",(AA4-AA3)) -> 7 | AC4: 1058 | AD4: =IF((AC4-AC3)<0,"0",(AC4-AC3)) -> 0 | AE4: 3689 | AF4: =IF((AE4-AE3)<0,"0",(AE4-AE3)) -> 0 | AI4: 570660 | AJ4: =IF((AI4-AI3)<0,"0",(AI4-AI3)) -> 20 | AM4: 52017 | AN4: =IF((AM4-AM3)<0,"0",(AM4-AM3)) -> 1 | AO4: 8864 | AP4: =IF((AO4-AO3)<0,"0",(AO4-AO3)) -> 0 | AQ4: 10548 | AR4: =IF((AQ4-AQ3)<0,"0",(AQ4-AQ3)) -> 0 | AS4: 14481 | AT4: =IF((AS4-AS3)<0,"0",(AS4-AS3)) -> 0 | AU4: 19349 | AV4: =IF((AU4-AU3)<0,"0",(AU4-AU3)) -> 0 | AW4: 20660 | AX4: =IF((AW4-AW3)<0,"0",(AW4-AW3)) -> 0 | AY4: 13831 | AZ4: =IF((AY4-AY3)<0,"0",(AY4-AY3)) -> 0 | BA4: 6152 | BB4: =IF((BA4-BA3)<0,"0",(BA4-BA3)) -> 0 | BC4: 26342 | BD4: =IF((BC4-BC3)<0,"0",(BC4-BC3)) -> 0 | BE4: 1112 | BF4: =IF((BE4-BE3)<0,"0",(BE4-BE3)) -> 0 | BG4: 4303 | BH4: =IF((BG4-BG3)<0,"0",(BG4-BG3)) -> 0 | BI4: 3636 | BJ4: =IF((BI4-BI3)<0,"0",(BI4-BI3)) -> 0 | BK4: =AZ4+AX4+AT4 -> 0 | BL4: =AJ4-BK4 -> 20 | BM4: 594980 | BN4: =IF((BM4-BM3)<0,"0",(BM4-BM3)) -> 20 | BO4: 581 | BP4: =IF((BO4-BO3)<0,"0",(BO4-BO3)) -> 0 | BQ4: 767700 | BR4: =IF((BQ4-BQ3)<0,"0",(BQ4-BQ3)) -> 30 | BS4: 5866 | BT4: =IF((BS4-BS3)<0,"0",(BS4-BS3)) -> 0 | BU4: =(BR4-AJ4) -> 10 | BV4: =SUM(BN4, BR4) -> 50 | BW4: =SUM(AN4,AP4,AR4,AT4,AV4,AX4,AZ4,BB4,BF4) -> 1 | BX4: 142.3 | BY4: =(IF(BX4<=116.4,((116.4*116.4*ACOS((116.4-BX4)/116.4))-((116.4-BX4)*SQRT(2*116.4*BX4-BX4*BX4)))*669.8,((3.1416*116.4*116.4)-((116.4*116.4*ACOS((116.4-(2*116.4-BX4))/116.4))-((116.4-(2*116.4-BX4))*SQRT(2*116.4*(2*116.4-BX4)-((2*116.4-BX4)*(2*116.4-BX4))))))*669.8))/1000 -> 18260.186 | CA4: =IF((BY3-BY4)<0,"0",(BY3-BY4)) -> 0 | CB4: 205886 | CC4: =IF((CB4-CB3)<0,"0",(CB4-CB3)) -> 0.1 | CD4: =CC4*5.71 -> 0.571 | CE4: 40 | CF4: =(CE4*10775)/100 -> 4310 | CG4: 40 | CH4: =(CG4*10775)/100 -> 4310 | CI4: 44 | CJ4: =(CI4*10775)/100 -> 4741 | CK4: =CF4+CH4+CJ4 -> 13361 | CL4: =IF((CK3-CK4+CM3)=CK3,"0",(CK3-CK4+CM3)) -> 107.75 | CN4: 34092.9 | CO4: =IF((CN4-CN3)<0,"0",(CN4-CN3)) -> 1.7 | CP4: =CO4*2.44 -> 4.148 | CQ4: 34300 | CR4: =IF((CQ4-CQ3)<0,"0",(CQ4-CQ3)) -> 0 | CS4: =CR4*2.44 -> 0 | CT4: 10234 | CU4: =IF((CT4-CT3)<0,"0",(CT4-CT3)) -> 0 | CV4: =CU4*6.25 -> 0 | CW4: 831923 | CX4: =IF((CW4-CW3)<0,"0",(CW4-CW3)) -> 0 | CY4: =CX4*3.1 -> 0 | CZ4: 5719.1 | DA4: =IF((CZ4-CZ3)<0,"0",(CZ4-CZ3)) -> 0 | DB4: =DA4*2.39 -> 0 | DC4: 7415 | DD4: =IF((DC4-DC3)<0,"0",(DC4-DC3)) -> 0 | DE4: =DD4*2.39 -> 0 | DF4: 3779.3 | DG4: =IF((DF4-DF3)<0,"0",(DF4-DF3)) -> 1.6 | DH4: =DG4*2.39 -> 3.824 | DI4: 1855.8 | DJ4: =IF((DI4-DI3)<0,"0",(DI4-DI3)) -> 0.02 | DK4: =DJ4*2.39 -> 0.0478 | DL4: 5078.4 | DM4: =IF((DL4-DL3)<0,"0",(DL4-DL3)) -> 0 | DN4: =DM4*2.39 -> 0 | DO4: 4451.7 | DP4: =IF((DO4-DO3)<0,"0",(DO4-DO3)) -> 0 | DQ4: =DP4*2.39 -> 0 | DR4: 5086.1 | DS4: =IF((DR4-DR3)<0,"0",(DR4-DR3)) -> 0 | DT4: =DS4*2.39 -> 0 | DU4: 4320.7 | DV4: =IF((DU4-DU3)<0,"0",(DU4-DU3)) -> 0 | DW4: =DV4*2.39 -> 0 | DX4: 12732 | DY4: 0 | DZ4: 61889 | EA4: 0 | EB4: 15599 | EC4: 0 | ED4: 24594 | EE4: =IF((ED4-ED3)<0,"0",(ED4-ED3)) -> 0 | EF4: 3 | EG4: 11 | EH4: 0.015
A5: 44014 | B5: 5219716 | C5: =IF((B5-B4)<0,"0",(B5-B4)) -> 3609 | D5: 4570403 | E5: =IF((D5-D4)<0,"0",(D5-D4)) -> 3279 | F5: =E5/C5 -> 0.90856193 | G5: 286 | H5: 430 | I5: 285707 | J5: 0 | K5: 750 | L5: 0 | M5: 629908 | N5: 0 | O5: 967 | P5: 0 | Q5: 2530587 | R5: =IF((Q5-Q4)<0,"0",(Q5-Q4)) -> 87 | S5: 2187530 | T5: =IF((S5-S4)<0,"0",(S5-S4)) -> 4 | U5: 92334 | V5: =IF((U5-U4)<0,"0",(U5-U4)) -> 75 | W5: 100 | X5: 0 | Y5: 152258 | Z5: =IF((Y5-Y4)<0,"0",(Y5-Y4)) -> 0 | AA5: 37839 | AB5: =IF((AA5-AA4)<0,"0",(AA5-AA4)) -> 5 | AC5: 1058 | AD5: =IF((AC5-AC4)<0,"0",(AC5-AC4)) -> 0 | AE5: 3689 | AF5: =IF((AE5-AE4)<0,"0",(AE5-AE4)) -> 0 | AI5: 570720 | AJ5: =IF((AI5-AI4)<0,"0",(AI5-AI4)) -> 60 | AM5: 52018 | AN5: =IF((AM5-AM4)<0,"0",(AM5-AM4)) -> 1 | AO5: 8866 | AP5: =IF((AO5-AO4)<0,"0",(AO5-AO4)) -> 2 | AQ5: 10548 | AR5: =IF((AQ5-AQ4)<0,"0",(AQ5-AQ4)) -> 0 | AS5: 14481 | AT5: =IF((AS5-AS4)<0,"0",(AS5-AS4)) -> 0 | AU5: 19349 | AV5: =IF((AU5-AU4)<0,"0",(AU5-AU4)) -> 0 | AW5: 20660 | AX5: =IF((AW5-AW4)<0,"0",(AW5-AW4)) -> 0 | AY5: 13831 | AZ5: =IF((AY5-AY4)<0,"0",(AY5-AY4)) -> 0 | BA5: 6152 | BB5: =IF((BA5-BA4)<0,"0",(BA5-BA4)) -> 0 | BC5: 26342 | BD5: =IF((BC5-BC4)<0,"0",(BC5-BC4)) -> 0 | BE5: 1112 | BF5: =IF((BE5-BE4)<0,"0",(BE5-BE4)) -> 0 | BG5: 4303 | BH5: =IF((BG5-BG4)<0,"0",(BG5-BG4)) -> 0 | BI5: 3636 | BJ5: =IF((BI5-BI4)<0,"0",(BI5-BI4)) -> 0 | BK5: =AZ5+AX5+AT5 -> 0 | BL5: =AJ5-BK5 -> 60 | BM5: 594990 | BN5: =IF((BM5-BM4)<0,"0",(BM5-BM4)) -> 10 | BO5: 581 | BP5: =IF((BO5-BO4)<0,"0",(BO5-BO4)) -> 0 | BQ5: 767760 | BR5: =IF((BQ5-BQ4)<0,"0",(BQ5-BQ4)) -> 60 | BS5: 5866 | BT5: =IF((BS5-BS4)<0,"0",(BS5-BS4)) -> 0 | BU5: =(BR5-AJ5) -> 0 | BV5: =SUM(BN5, BR5) -> 70 | BW5: =SUM(AN5,AP5,AR5,AT5,AV5,AX5,AZ5,BB5,BF5) -> 3 | BX5: 142.3 | BY5: =(IF(BX5<=116.4,((116.4*116.4*ACOS((116.4-BX5)/116.4))-((116.4-BX5)*SQRT(2*116.4*BX5-BX5*BX5)))*669.8,((3.1416*116.4*116.4)-((116.4*116.4*ACOS((116.4-(2*116.4-BX5))/116.4))-((116.4-(2*116.4-BX5))*SQRT(2*116.4*(2*116.4-BX5)-((2*116.4-BX5)*(2*116.4-BX5))))))*669.8))/1000 -> 18260.186 | CA5: =IF((BY4-BY5)<0,"0",(BY4-BY5)) -> 0 | CB5: 205886 | CC5: =IF((CB5-CB4)<0,"0",(CB5-CB4)) -> 0 | CD5: =CC5*5.71 -> 0 | CE5: 40 | CF5: =(CE5*10775)/100 -> 4310 | CG5: 40 | CH5: =(CG5*10775)/100 -> 4310 | CI5: 44 | CJ5: =(CI5*10775)/100 -> 4741 | CK5: =CF5+CH5+CJ5 -> 13361 | CL5: =IF((CK4-CK5+CM4)=CK4,"0",(CK4-CK5+CM4)) -> 0 | CN5: 34094.2 | CO5: =IF((CN5-CN4)<0,"0",(CN5-CN4)) -> 1.3 | CP5: =CO5*2.44 -> 3.172 | CQ5: 34300 | CR5: =IF((CQ5-CQ4)<0,"0",(CQ5-CQ4)) -> 0 | CS5: =CR5*2.44 -> 0 | CT5: 10234 | CU5: =IF((CT5-CT4)<0,"0",(CT5-CT4)) -> 0 | CV5: =CU5*6.25 -> 0 | CW5: 831923 | CX5: =IF((CW5-CW4)<0,"0",(CW5-CW4)) -> 0 | CY5: =CX5*3.1 -> 0 | CZ5: 5719.1 | DA5: =IF((CZ5-CZ4)<0,"0",(CZ5-CZ4)) -> 0 | DB5: =DA5*2.39 -> 0 | DC5: 7415 | DD5: =IF((DC5-DC4)<0,"0",(DC5-DC4)) -> 0 | DE5: =DD5*2.39 -> 0 | DF5: 3785.1 | DG5: =IF((DF5-DF4)<0,"0",(DF5-DF4)) -> 5.8 | DH5: =DG5*2.39 -> 13.862 | DI5: 1855.8 | DJ5: =IF((DI5-DI4)<0,"0",(DI5-DI4)) -> 0 | DK5: =DJ5*2.39 -> 0 | DL5: 5078.4 | DM5: =IF((DL5-DL4)<0,"0",(DL5-DL4)) -> 0 | DN5: =DM5*2.39 -> 0 | DO5: 4451.7 | DP5: =IF((DO5-DO4)<0,"0",(DO5-DO4)) -> 0 | DQ5: =DP5*2.39 -> 0 | DR5: 5086.1 | DS5: =IF((DR5-DR4)<0,"0",(DR5-DR4)) -> 0 | DT5: =DS5*2.39 -> 0 | DU5: 4320.7 | DV5: =IF((DU5-DU4)<0,"0",(DU5-DU4)) -> 0 | DW5: =DV5*2.39 -> 0 | DX5: 12732 | DY5: 0 | DZ5: 61889 | EA5: 0 | EB5: 15599 | EC5: =IF((EB5-EB4)<0,"0",(EB5-EB4)) -> 0 | ED5: 24594 | EE5: =IF((ED5-ED4)<0,"0",(ED5-ED4)) -> 0 | EF5: 3 | EG5: 11 | EH5: 0.015
A6: 44015 | B6: 5223209 | C6: =IF((B6-B5)<0,"0",(B6-B5)) -> 3493 | D6: 4573547 | E6: =IF((D6-D5)<0,"0",(D6-D5)) -> 3144 | F6: =E6/C6 -> 0.90008589 | G6: 286 | H6: 430 | I6: 285707 | J6: 0 | K6: 750 | L6: 0 | M6: 629908 | N6: 0 | O6: 967 | P6: 0 | Q6: 2530621 | R6: =IF((Q6-Q5)<0,"0",(Q6-Q5)) -> 34 | S6: 2187531 | T6: =IF((S6-S5)<0,"0",(S6-S5)) -> 1 | U6: 92393 | V6: =IF((U6-U5)<0,"0",(U6-U5)) -> 59 | W6: 100 | X6: 0 | Y6: 152258 | Z6: =IF((Y6-Y5)<0,"0",(Y6-Y5)) -> 0 | AA6: 37848 | AB6: =IF((AA6-AA5)<0,"0",(AA6-AA5)) -> 9 | AC6: 1058 | AD6: =IF((AC6-AC5)<0,"0",(AC6-AC5)) -> 0 | AE6: 3689 | AF6: =IF((AE6-AE5)<0,"0",(AE6-AE5)) -> 0 | AI6: 570750 | AJ6: =IF((AI6-AI5)<0,"0",(AI6-AI5)) -> 30 | AM6: 52018 | AN6: =IF((AM6-AM5)<0,"0",(AM6-AM5)) -> 0 | AO6: 8866 | AP6: =IF((AO6-AO5)<0,"0",(AO6-AO5)) -> 0 | AQ6: 10549 | AR6: =IF((AQ6-AQ5)<0,"0",(AQ6-AQ5)) -> 1 | AS6: 14481 | AT6: =IF((AS6-AS5)<0,"0",(AS6-AS5)) -> 0 | AU6: 19349 | AV6: =IF((AU6-AU5)<0,"0",(AU6-AU5)) -> 0 | AW6: 20660 | AX6: =IF((AW6-AW5)<0,"0",(AW6-AW5)) -> 0 | AY6: 13831 | AZ6: =IF((AY6-AY5)<0,"0",(AY6-AY5)) -> 0 | BA6: 6153 | BB6: =IF((BA6-BA5)<0,"0",(BA6-BA5)) -> 1 | BC6: 26342 | BD6: =IF((BC6-BC5)<0,"0",(BC6-BC5)) -> 0 | BE6: 1112 | BF6: =IF((BE6-BE5)<0,"0",(BE6-BE5)) -> 0 | BG6: 4303 | BH6: =IF((BG6-BG5)<0,"0",(BG6-BG5)) -> 0 | BI6: 3636 | BJ6: =IF((BI6-BI5)<0,"0",(BI6-BI5)) -> 0 | BK6: =AZ6+AX6+AT6 -> 0 | BL6: =AJ6-BK6 -> 30 | BM6: 595010 | BN6: =IF((BM6-BM5)<0,"0",(BM6-BM5)) -> 20 | BO6: 581 | BP6: =IF((BO6-BO5)<0,"0",(BO6-BO5)) -> 0 | BQ6: 767790 | BR6: =IF((BQ6-BQ5)<0,"0",(BQ6-BQ5)) -> 30 | BS6: 5866 | BT6: =IF((BS6-BS5)<0,"0",(BS6-BS5)) -> 0 | BU6: =(BR6-AJ6) -> 0 | BV6: =SUM(BN6, BR6) -> 50 | BW6: =SUM(AN6,AP6,AR6,AT6,AV6,AX6,AZ6,BB6,BF6) -> 2 | BX6: 142.3 | BY6: =(IF(BX6<=116.4,((116.4*116.4*ACOS((116.4-BX6)/116.4))-((116.4-BX6)*SQRT(2*116.4*BX6-BX6*BX6)))*669.8,((3.1416*116.4*116.4)-((116.4*116.4*ACOS((116.4-(2*116.4-BX6))/116.4))-((116.4-(2*116.4-BX6))*SQRT(2*116.4*(2*116.4-BX6)-((2*116.4-BX6)*(2*116.4-BX6))))))*669.8))/1000 -> 18260.186 | CA6: =IF((BY5-BY6)<0,"0",(BY5-BY6)) -> 0 | CB6: 205886 | CC6: =IF((CB6-CB5)<0,"0",(CB6-CB5)) -> 0 | CD6: =CC6*5.71 -> 0 | CE6: 40 | CF6: =(CE6*10775)/100 -> 4310 | CG6: 40 | CH6: =(CG6*10775)/100 -> 4310 | CI6: 43 | CJ6: =(CI6*10775)/100 -> 4633.25 | CK6: =CF6+CH6+CJ6 -> 13253.25 | CL6: =IF((CK5-CK6+CM5)=CK5,"0",(CK5-CK6+CM5)) -> 107.75 | CN6: 34094.9 | CO6: =IF((CN6-CN5)<0,"0",(CN6-CN5)) -> 0.7 | CP6: =CO6*2.44 -> 1.708 | CQ6: 34300 | CR6: =IF((CQ6-CQ5)<0,"0",(CQ6-CQ5)) -> 0 | CS6: =CR6*2.44 -> 0 | CT6: 10234 | CU6: =IF((CT6-CT5)<0,"0",(CT6-CT5)) -> 0 | CV6: =CU6*6.25 -> 0 | CW6: 831923 | CX6: =IF((CW6-CW5)<0,"0",(CW6-CW5)) -> 0 | CY6: =CX6*3.1 -> 0 | CZ6: 5719.1 | DA6: =IF((CZ6-CZ5)<0,"0",(CZ6-CZ5)) -> 0 | DB6: =DA6*2.39 -> 0 | DC6: 7415 | DD6: =IF((DC6-DC5)<0,"0",(DC6-DC5)) -> 0 | DE6: =DD6*2.39 -> 0 | DF6: 3787.1 | DG6: =IF((DF6-DF5)<0,"0",(DF6-DF5)) -> 2 | DH6: =DG6*2.39 -> 4.78 | DI6: 1855.8 | DJ6: =IF((DI6-DI5)<0,"0",(DI6-DI5)) -> 0 | DK6: =DJ6*2.39 -> 0 | DL6: 5078.4 | DM6: =IF((DL6-DL5)<0,"0",(DL6-DL5)) -> 0 | DN6: =DM6*2.39 -> 0 | DO6: 4451.7 | DP6: =IF((DO6-DO5)<0,"0",(DO6-DO5)) -> 0 | DQ6: =DP6*2.39 -> 0 | DR6: 5086.1 | DS6: =IF((DR6-DR5)<0,"0",(DR6-DR5)) -> 0 | DT6: =DS6*2.39 -> 0 | DU6: 4320.7 | DV6: =IF((DU6-DU5)<0,"0",(DU6-DU5)) -> 0 | DW6: =DV6*2.39 -> 0 | DX6: 12732 | DY6: =IF((DX6-DX5)<0,"0",(DX6-DX5)) -> 0 | DZ6: 61889 | EA6: 0 | EB6: 15599 | EC6: =IF((EB6-EB5)<0,"0",(EB6-EB5)) -> 0 | ED6: 24594 | EE6: =IF((ED6-ED5)<0,"0",(ED6-ED5)) -> 0 | EF6: 3 | EG6: 11 | EH6: 0.015
A7: 44016 | B7: 5226972 | C7: =IF((B7-B6)<0,"0",(B7-B6)) -> 3763 | D7: 4576962 | E7: =IF((D7-D6)<0,"0",(D7-D6)) -> 3415 | F7: =E7/C7 -> 0.9075206 | G7: 286 | H7: 430 | I7: 285707 | J7: 0 | K7: 750 | L7: 0 | M7: 629908 | N7: 0 | O7: 967 | P7: 0 | Q7: 2530668 | R7: =IF((Q7-Q6)<0,"0",(Q7-Q6)) -> 47 | S7: 2187532 | T7: =IF((S7-S6)<0,"0",(S7-S6)) -> 1 | U7: 92461 | V7: =IF((U7-U6)<0,"0",(U7-U6)) -> 68 | W7: 100 | X7: 0 | Y7: 152258 | Z7: =IF((Y7-Y6)<0,"0",(Y7-Y6)) -> 0 | AA7: 37855 | AB7: =IF((AA7-AA6)<0,"0",(AA7-AA6)) -> 7 | AC7: 1058 | AD7: =IF((AC7-AC6)<0,"0",(AC7-AC6)) -> 0 | AE7: 3689 | AF7: =IF((AE7-AE6)<0,"0",(AE7-AE6)) -> 0 | AI7: 570790 | AJ7: =IF((AI7-AI6)<0,"0",(AI7-AI6)) -> 40 | AM7: 52019 | AN7: =IF((AM7-AM6)<0,"0",(AM7-AM6)) -> 1 | AO7: 8866 | AP7: =IF((AO7-AO6)<0,"0",(AO7-AO6)) -> 0 | AQ7: 10549 | AR7: =IF((AQ7-AQ6)<0,"0",(AQ7-AQ6)) -> 0 | AS7: 14481 | AT7: =IF((AS7-AS6)<0,"0",(AS7-AS6)) -> 0 | AU7: 19349 | AV7: =IF((AU7-AU6)<0,"0",(AU7-AU6)) -> 0 | AW7: 20660 | AX7: =IF((AW7-AW6)<0,"0",(AW7-AW6)) -> 0 | AY7: 13831 | AZ7: =IF((AY7-AY6)<0,"0",(AY7-AY6)) -> 0 | BA7: 6153 | BB7: =IF((BA7-BA6)<0,"0",(BA7-BA6)) -> 0 | BC7: 26343 | BD7: =IF((BC7-BC6)<0,"0",(BC7-BC6)) -> 1 | BE7: 1112 | BF7: =IF((BE7-BE6)<0,"0",(BE7-BE6)) -> 0 | BG7: 4303 | BH7: =IF((BG7-BG6)<0,"0",(BG7-BG6)) -> 0 | BI7: 3636 | BJ7: =IF((BI7-BI6)<0,"0",(BI7-BI6)) -> 0 | BK7: =AZ7+AX7+AT7 -> 0 | BL7: =AJ7-BK7 -> 40 | BM7: 595050 | BN7: =IF((BM7-BM6)<0,"0",(BM7-BM6)) -> 40 | BO7: 581 | BP7: =IF((BO7-BO6)<0,"0",(BO7-BO6)) -> 0 | BQ7: 767830 | BR7: =IF((BQ7-BQ6)<0,"0",(BQ7-BQ6)) -> 40 | BS7: 5866 | BT7: =IF((BS7-BS6)<0,"0",(BS7-BS6)) -> 0 | BU7: =(BR7-AJ7) -> 0 | BV7: =SUM(BN7, BR7) -> 80 | BW7: =SUM(AN7,AP7,AR7,AT7,AV7,AX7,AZ7,BB7,BF7) -> 1 | BX7: 142.3 | BY7: =(IF(BX7<=116.4,((116.4*116.4*ACOS((116.4-BX7)/116.4))-((116.4-BX7)*SQRT(2*116.4*BX7-BX7*BX7)))*669.8,((3.1416*116.4*116.4)-((116.4*116.4*ACOS((116.4-(2*116.4-BX7))/116.4))-((116.4-(2*116.4-BX7))*SQRT(2*116.4*(2*116.4-BX7)-((2*116.4-BX7)*(2*116.4-BX7))))))*669.8))/1000 -> 18260.186 | CA7: =IF((BY6-BY7)<0,"0",(BY6-BY7)) -> 0 | CB7: 205886 | CC7: =IF((CB7-CB6)<0,"0",(CB7-CB6)) -> 0 | CD7: =CC7*5.71 -> 0 | CE7: 40 | CF7: =(CE7*10775)/100 -> 4310 | CG7: 40 | CH7: =(CG7*10775)/100 -> 4310 | CI7: 43 | CJ7: =(CI7*10775)/100 -> 4633.25 | CK7: =CF7+CH7+CJ7 -> 13253.25 | CL7: =IF((CK6-CK7+CM6)=CK6,"0",(CK6-CK7+CM6)) -> 0 | CN7: 34095.9 | CO7: =IF((CN7-CN6)<0,"0",(CN7-CN6)) -> 1 | CP7: =CO7*2.44 -> 2.44 | CQ7: 34300 | CR7: =IF((CQ7-CQ6)<0,"0",(CQ7-CQ6)) -> 0 | CS7: =CR7*2.44 -> 0 | CT7: 10234 | CU7: =IF((CT7-CT6)<0,"0",(CT7-CT6)) -> 0 | CV7: =CU7*6.25 -> 0 | CW7: 831923 | CX7: =IF((CW7-CW6)<0,"0",(CW7-CW6)) -> 0 | CY7: =CX7*3.1 -> 0 | CZ7: 5719.1 | DA7: =IF((CZ7-CZ6)<0,"0",(CZ7-CZ6)) -> 0 | DB7: =DA7*2.39 -> 0 | DC7: 7415 | DD7: =IF((DC7-DC6)<0,"0",(DC7-DC6)) -> 0 | DE7: =DD7*2.39 -> 0 | DF7: 3790.3 | DG7: =IF((DF7-DF6)<0,"0",(DF7-DF6)) -> 3.2 | DH7: =DG7*2.39 -> 7.648 | DI7: 1855.8 | DJ7: =IF((DI7-DI6)<0,"0",(DI7-DI6)) -> 0 | DK7: =DJ7*2.39 -> 0 | DL7: 5078.4 | DM7: =IF((DL7-DL6)<0,"0",(DL7-DL6)) -> 0 | DN7: =DM7*2.39 -> 0 | DO7: 4451.7 | DP7: =IF((DO7-DO6)<0,"0",(DO7-DO6)) -> 0 | DQ7: =DP7*2.39 -> 0 | DR7: 5086.1 | DS7: =IF((DR7-DR6)<0,"0",(DR7-DR6)) -> 0 | DT7: =DS7*2.39 -> 0 | DU7: 4320.7 | DV7: =IF((DU7-DU6)<0,"0",(DU7-DU6)) -> 0 | DW7: =DV7*2.39 -> 0 | DX7: 12732 | DY7: =IF((DX7-DX6)<0,"0",(DX7-DX6)) -> 0 | DZ7: 61889 | EA7: 0 | EB7: 15599 | EC7: =IF((EB7-EB6)<0,"0",(EB7-EB6)) -> 0 | ED7: 24594 | EE7: =IF((ED7-ED6)<0,"0",(ED7-ED6)) -> 0 | EF7: 3 | EG7: 11 | EH7: 0.015
A8: 44017 | B8: 5230446 | C8: =IF((B8-B7)<0,"0",(B8-B7)) -> 3474 | D8: 4580110 | E8: =IF((D8-D7)<0,"0",(D8-D7)) -> 3148 | F8: =E8/C8 -> 0.90616005 | G8: 196 | H8: 286 | I8: 285707 | J8: =IF((I8-I7)<0,"0",(I8-I7)) -> 0 | K8: 750 | L8: =IF((K8-K7)<0,"0",(K8-K7)) -> 0 | M8: 629908 | N8: =IF((M8-M7)<0,"0",(M8-M7)) -> 0 | O8: 967 | P8: =IF((O8-O7)<0,"0",(O8-O7)) -> 0 | Q8: 2530750 | R8: =IF((Q8-Q7)<0,"0",(Q8-Q7)) -> 82 | S8: 2187532 | T8: =IF((S8-S7)<0,"0",(S8-S7)) -> 0 | U8: 92528 | V8: =IF((U8-U7)<0,"0",(U8-U7)) -> 67 | W8: 100 | X8: 0 | Y8: 152258 | Z8: =IF((Y8-Y7)<0,"0",(Y8-Y7)) -> 0 | AA8: 37865 | AB8: =IF((AA8-AA7)<0,"0",(AA8-AA7)) -> 10 | AC8: 1058 | AD8: =IF((AC8-AC7)<0,"0",(AC8-AC7)) -> 0 | AE8: 3689 | AF8: =IF((AE8-AE7)<0,"0",(AE8-AE7)) -> 0 | AI8: 570860 | AJ8: =IF((AI8-AI7)<0,"0",(AI8-AI7)) -> 70 | AM8: 52019 | AN8: =IF((AM8-AM7)<0,"0",(AM8-AM7)) -> 0 | AO8: 8866 | AP8: =IF((AO8-AO7)<0,"0",(AO8-AO7)) -> 0 | AQ8: 10549 | AR8: =IF((AQ8-AQ7)<0,"0",(AQ8-AQ7)) -> 0 | AS8: 14481 | AT8: =IF((AS8-AS7)<0,"0",(AS8-AS7)) -> 0 | AU8: 19349 | AV8: =IF((AU8-AU7)<0,"0",(AU8-AU7)) -> 0 | AW8: 20660 | AX8: =IF((AW8-AW7)<0,"0",(AW8-AW7)) -> 0 | AY8: 13831 | AZ8: =IF((AY8-AY7)<0,"0",(AY8-AY7)) -> 0 | BA8: 6153 | BB8: =IF((BA8-BA7)<0,"0",(BA8-BA7)) -> 0 | BC8: 26343 | BD8: =IF((BC8-BC7)<0,"0",(BC8-BC7)) -> 0 | BE8: 1112 | BF8: =IF((BE8-BE7)<0,"0",(BE8-BE7)) -> 0 | BG8: 4303 | BH8: =IF((BG8-BG7)<0,"0",(BG8-BG7)) -> 0 | BI8: 3636 | BJ8: =IF((BI8-BI7)<0,"0",(BI8-BI7)) -> 0 | BK8: =AZ8+AX8+AT8 -> 0 | BL8: =AJ8-BK8 -> 70 | BM8: 595080 | BN8: =IF((BM8-BM7)<0,"0",(BM8-BM7)) -> 30 | BO8: 581 | BP8: =IF((BO8-BO7)<0,"0",(BO8-BO7)) -> 0 | BQ8: 767900 | BR8: =IF((BQ8-BQ7)<0,"0",(BQ8-BQ7)) -> 70 | BS8: 5866 | BT8: =IF((BS8-BS7)<0,"0",(BS8-BS7)) -> 0 | BU8: =(BR8-AJ8) -> 0 | BV8: =SUM(BN8, BR8) -> 100 | BW8: =SUM(AN8,AP8,AR8,AT8,AV8,AX8,AZ8,BB8,BF8) -> 0 | BX8: 142.3 | BY8: =(IF(BX8<=116.4,((116.4*116.4*ACOS((116.4-BX8)/116.4))-((116.4-BX8)*SQRT(2*116.4*BX8-BX8*BX8)))*669.8,((3.1416*116.4*116.4)-((116.4*116.4*ACOS((116.4-(2*116.4-BX8))/116.4))-((116.4-(2*116.4-BX8))*SQRT(2*116.4*(2*116.4-BX8)-((2*116.4-BX8)*(2*116.4-BX8))))))*669.8))/1000 -> 18260.186 | CA8: =IF((BY7-BY8)<0,"0",(BY7-BY8)) -> 0 | CB8: 205886 | CC8: =IF((CB8-CB7)<0,"0",(CB8-CB7)) -> 0 | CD8: =CC8*5.71 -> 0 | CE8: 40 | CF8: =(CE8*10775)/100 -> 4310 | CG8: 40 | CH8: =(CG8*10775)/100 -> 4310 | CI8: 42 | CJ8: =(CI8*10775)/100 -> 4525.5 | CK8: =CF8+CH8+CJ8 -> 13145.5 | CL8: =IF((CK7-CK8+CM7)=CK7,"0",(CK7-CK8+CM7)) -> 107.75 | CN8: 34096.4 | CO8: =IF((CN8-CN7)<0,"0",(CN8-CN7)) -> 0.5 | CP8: =CO8*2.44 -> 1.22 | CQ8: 34300 | CR8: =IF((CQ8-CQ7)<0,"0",(CQ8-CQ7)) -> 0 | CS8: =CR8*2.44 -> 0 | CT8: 10234 | CU8: =IF((CT8-CT7)<0,"0",(CT8-CT7)) -> 0 | CV8: =CU8*6.25 -> 0 | CW8: 831923 | CX8: =IF((CW8-CW7)<0,"0",(CW8-CW7)) -> 0 | CY8: =CX8*3.1 -> 0 | CZ8: 5721.6 | DA8: =IF((CZ8-CZ7)<0,"0",(CZ8-CZ7)) -> 2.5 | DB8: =DA8*2.39 -> 5.975 | DC8: 7415 | DD8: =IF((DC8-DC7)<0,"0",(DC8-DC7)) -> 0 | DE8: =DD8*2.39 -> 0 | DF8: 3796.1 | DG8: =IF((DF8-DF7)<0,"0",(DF8-DF7)) -> 5.8 | DH8: =DG8*2.39 -> 13.862 | DI8: 1855.8 | DJ8: =IF((DI8-DI7)<0,"0",(DI8-DI7)) -> 0 | DK8: =DJ8*2.39 -> 0 | DL8: 5078.4 | DM8: =IF((DL8-DL7)<0,"0",(DL8-DL7)) -> 0 | DN8: =DM8*2.39 -> 0 | DO8: 4451.7 | DP8: =IF((DO8-DO7)<0,"0",(DO8-DO7)) -> 0 | DQ8: =DP8*2.39 -> 0 | DR8: 5086.1 | DS8: =IF((DR8-DR7)<0,"0",(DR8-DR7)) -> 0 | DT8: =DS8*2.39 -> 0 | DU8: 4320.7 | DV8: =IF((DU8-DU7)<0,"0",(DU8-DU7)) -> 0 | DW8: =DV8*2.39 -> 0 | DX8: 12732 | DY8: =IF((DX8-DX7)<0,"0",(DX8-DX7)) -> 0 | DZ8: 61889 | EA8: 0 | EB8: 15599 | EC8: =IF((EB8-EB7)<0,"0",(EB8-EB7)) -> 0 | ED8: 24594 | EE8: =IF((ED8-ED7)<0,"0",(ED8-ED7)) -> 0 | EF8: 2 | EG8: 11 | EH8: 0.015
A9: 44018 | B9: 5234249 | C9: =IF((B9-B8)<0,"0",(B9-B8)) -> 3803 | D9: 4583574 | E9: =IF((D9-D8)<0,"0",(D9-D8)) -> 3464 | F9: =E9/C9 -> 0.91085985 | G9: 196 | H9: 286 | I9: 285707 | J9: =IF((I9-I8)<0,"0",(I9-I8)) -> 0 | K9: 750 | L9: =IF((K9-K8)<0,"0",(K9-K8)) -> 0 | M9: 629908 | N9: =IF((M9-M8)<0,"0",(M9-M8)) -> 0 | O9: 967 | P9: =IF((O9-O8)<0,"0",(O9-O8)) -> 0 | Q9: 2530790 | R9: =IF((Q9-Q8)<0,"0",(Q9-Q8)) -> 40 | S9: 2187536 | T9: =IF((S9-S8)<0,"0",(S9-S8)) -> 4 | U9: 92596 | V9: =IF((U9-U8)<0,"0",(U9-U8)) -> 68 | W9: 100 | X9: 0 | Y9: 152258 | Z9: =IF((Y9-Y8)<0,"0",(Y9-Y8)) -> 0 | AA9: 37869 | AB9: =IF((AA9-AA8)<0,"0",(AA9-AA8)) -> 4 | AC9: 1058 | AD9: =IF((AC9-AC8)<0,"0",(AC9-AC8)) -> 0 | AE9: 3689 | AF9: =IF((AE9-AE8)<0,"0",(AE9-AE8)) -> 0 | AI9: 570880 | AJ9: =IF((AI9-AI8)<0,"0",(AI9-AI8)) -> 20 | AM9: 52020 | AN9: =IF((AM9-AM8)<0,"0",(AM9-AM8)) -> 1 | AO9: 8863 | AP9: =IF((AO9-AO8)<0,"0",(AO9-AO8)) -> 0 | AQ9: 10549 | AR9: =IF((AQ9-AQ8)<0,"0",(AQ9-AQ8)) -> 0 | AS9: 14481 | AT9: =IF((AS9-AS8)<0,"0",(AS9-AS8)) -> 0 | AU9: 19349 | AV9: =IF((AU9-AU8)<0,"0",(AU9-AU8)) -> 0 | AW9: 20660 | AX9: =IF((AW9-AW8)<0,"0",(AW9-AW8)) -> 0 | AY9: 13831 | AZ9: =IF((AY9-AY8)<0,"0",(AY9-AY8)) -> 0 | BA9: 6153 | BB9: =IF((BA9-BA8)<0,"0",(BA9-BA8)) -> 0 | BC9: 26343 | BD9: =IF((BC9-BC8)<0,"0",(BC9-BC8)) -> 0 | BE9: 1112 | BF9: =IF((BE9-BE8)<0,"0",(BE9-BE8)) -> 0 | BG9: 4303 | BH9: =IF((BG9-BG8)<0,"0",(BG9-BG8)) -> 0 | BI9: 3636 | BJ9: =IF((BI9-BI8)<0,"0",(BI9-BI8)) -> 0 | BK9: =AZ9+AX9+AT9 -> 0 | BL9: =AJ9-BK9 -> 20 | BM9: 595100 | BN9: =IF((BM9-BM8)<0,"0",(BM9-BM8)) -> 20 | BO9: 581 | BP9: =IF((BO9-BO8)<0,"0",(BO9-BO8)) -> 0 | BQ9: 767920 | BR9: =IF((BQ9-BQ8)<0,"0",(BQ9-BQ8)) -> 20 | BS9: 5866 | BT9: =IF((BS9-BS8)<0,"0",(BS9-BS8)) -> 0 | BU9: =(BR9-AJ9) -> 0 | BV9: =SUM(BN9, BR9) -> 40 | BW9: =SUM(AN9,AP9,AR9,AT9,AV9,AX9,AZ9,BB9,BF9) -> 1 | BX9: 142.3 | BY9: =(IF(BX9<=116.4,((116.4*116.4*ACOS((116.4-BX9)/116.4))-((116.4-BX9)*SQRT(2*116.4*BX9-BX9*BX9)))*669.8,((3.1416*116.4*116.4)-((116.4*116.4*ACOS((116.4-(2*116.4-BX9))/116.4))-((116.4-(2*116.4-BX9))*SQRT(2*116.4*(2*116.4-BX9)-((2*116.4-BX9)*(2*116.4-BX9))))))*669.8))/1000 -> 18260.186 | CA9: =IF((BY8-BY9)<0,"0",(BY8-BY9)) -> 0 | CB9: 205886 | CC9: =IF((CB9-CB8)<0,"0",(CB9-CB8)) -> 0 | CD9: =CC9*5.71 -> 0 | CE9: 40 | CF9: =(CE9*10775)/100 -> 4310 | CG9: 40 | CH9: =(CG9*10775)/100 -> 4310 | CI9: 42 | CJ9: =(CI9*10775)/100 -> 4525.5 | CK9: =CF9+CH9+CJ9 -> 13145.5 | CL9: =IF((CK8-CK9+CM8)=CK8,"0",(CK8-CK9+CM8)) -> 0 | CN9: 34097.4 | CO9: =IF((CN9-CN8)<0,"0",(CN9-CN8)) -> 1 | CP9: =CO9*2.44 -> 2.44 | CQ9: 34300 | CR9: =IF((CQ9-CQ8)<0,"0",(CQ9-CQ8)) -> 0 | CS9: =CR9*2.44 -> 0 | CT9: 10234 | CU9: =IF((CT9-CT8)<0,"0",(CT9-CT8)) -> 0 | CV9: =CU9*6.25 -> 0 | CW9: 831923 | CX9: =IF((CW9-CW8)<0,"0",(CW9-CW8)) -> 0 | CY9: =CX9*3.1 -> 0 | CZ9: 5722.4 | DA9: =IF((CZ9-CZ8)<0,"0",(CZ9-CZ8)) -> 0.8 | DB9: =DA9*2.39 -> 1.912 | DC9: 7415 | DD9: =IF((DC9-DC8)<0,"0",(DC9-DC8)) -> 0 | DE9: =DD9*2.39 -> 0 | DF9: 3797.7 | DG9: =IF((DF9-DF8)<0,"0",(DF9-DF8)) -> 1.6 | DH9: =DG9*2.39 -> 3.824 | DI9: 1855.8 | DK9: =DJ9*2.39 -> 0 | DL9: 5078.4 | DM9: =IF((DL9-DL8)<0,"0",(DL9-DL8)) -> 0 | DN9: =DM9*2.39 -> 0 | DO9: 4451.7 | DP9: =IF((DO9-DO8)<0,"0",(DO9-DO8)) -> 0 | DQ9: =DP9*2.39 -> 0 | DR9: 5086.1 | DS9: =IF((DR9-DR8)<0,"0",(DR9-DR8)) -> 0 | DT9: =DS9*2.39 -> 0 | DU9: 4320.7 | DV9: =IF((DU9-DU8)<0,"0",(DU9-DU8)) -> 0 | DW9: =DV9*2.39 -> 0 | DX9: 12732 | DY9: =IF((DX9-DX8)<0,"0",(DX9-DX8)) -> 0 | DZ9: 61889 | EA9: 0 | EB9: 15599 | EC9: =IF((EB9-EB8)<0,"0",(EB9-EB8)) -> 0 | ED9: 24594 | EE9: =IF((ED9-ED8)<0,"0",(ED9-ED8)) -> 0 | EF9: 2 | EG9: 11 | EH9: 0.015
A10: 44019 | B10: 5238027 | C10: =IF((B10-B9)<0,"0",(B10-B9)) -> 3778 | D10: 4587004 | E10: =IF((D10-D9)<0,"0",(D10-D9)) -> 3430 | F10: =E10/C10 -> 0.90788777 | G10: 196 | H10: 286 | I10: 285707 | J10: =IF((I10-I9)<0,"0",(I10-I9)) -> 0 | K10: 750 | L10: =IF((K10-K9)<0,"0",(K10-K9)) -> 0 | M10: 629908 | N10: =IF((M10-M9)<0,"0",(M10-M9)) -> 0 | O10: 967 | P10: =IF((O10-O9)<0,"0",(O10-O9)) -> 0 | Q10: 2530857 | R10: =IF((Q10-Q9)<0,"0",(Q10-Q9)) -> 67 | S10: 2187539 | T10: =IF((S10-S9)<0,"0",(S10-S9)) -> 3 | U10: 92664 | V10: 89 | W10: 100 | X10: 0 | Y10: 152258 | Z10: =IF((Y10-Y9)<0,"0",(Y10-Y9)) -> 0 | AA10: 37877 | AB10: =IF((AA10-AA9)<0,"0",(AA10-AA9)) -> 8 | AC10: 1060 | AD10: =IF((AC10-AC9)<0,"0",(AC10-AC9)) -> 2 | AE10: 3689 | AF10: =IF((AE10-AE9)<0,"0",(AE10-AE9)) -> 0 | AI10: 570950 | AJ10: =IF((AI10-AI9)<0,"0",(AI10-AI9)) -> 70 | AM10: 52021 | AN10: =IF((AM10-AM9)<0,"0",(AM10-AM9)) -> 1 | AO10: 8863 | AP10: =IF((AO10-AO9)<0,"0",(AO10-AO9)) -> 0 | AQ10: 10549 | AR10: =IF((AQ10-AQ9)<0,"0",(AQ10-AQ9)) -> 0 | AS10: 14481 | AT10: =IF((AS10-AS9)<0,"0",(AS10-AS9)) -> 0 | AU10: 19349 | AV10: =IF((AU10-AU9)<0,"0",(AU10-AU9)) -> 0 | AW10: 20660 | AX10: =IF((AW10-AW9)<0,"0",(AW10-AW9)) -> 0 | AY10: 13831 | AZ10: =IF((AY10-AY9)<0,"0",(AY10-AY9)) -> 0 | BA10: 6153 | BB10: =IF((BA10-BA9)<0,"0",(BA10-BA9)) -> 0 | BC10: 26343 | BD10: =IF((BC10-BC9)<0,"0",(BC10-BC9)) -> 0 | BE10: 1112 | BF10: =IF((BE10-BE9)<0,"0",(BE10-BE9)) -> 0 | BG10: 4303 | BH10: =IF((BG10-BG9)<0,"0",(BG10-BG9)) -> 0 | BI10: 3636 | BJ10: =IF((BI10-BI9)<0,"0",(BI10-BI9)) -> 0 | BK10: =AZ10+AX10+AT10 -> 0 | BL10: =AJ10-BK10 -> 70 | BM10: 595120 | BN10: =IF((BM10-BM9)<0,"0",(BM10-BM9)) -> 20 | BO10: 581 | BP10: =IF((BO10-BO9)<0,"0",(BO10-BO9)) -> 0 | BQ10: 767990 | BR10: =IF((BQ10-BQ9)<0,"0",(BQ10-BQ9)) -> 70 | BS10: 5866 | BT10: =IF((BS10-BS9)<0,"0",(BS10-BS9)) -> 0 | BU10: =(BR10-AJ10) -> 0 | BV10: =SUM(BN10, BR10) -> 90 | BW10: =SUM(AN10,AP10,AR10,AT10,AV10,AX10,AZ10,BB10,BF10) -> 1 | BX10: 142.3 | BY10: =(IF(BX10<=116.4,((116.4*116.4*ACOS((116.4-BX10)/116.4))-((116.4-BX10)*SQRT(2*116.4*BX10-BX10*BX10)))*669.8,((3.1416*116.4*116.4)-((116.4*116.4*ACOS((116.4-(2*116.4-BX10))/116.4))-((116.4-(2*116.4-BX10))*SQRT(2*116.4*(2*116.4-BX10)-((2*116.4-BX10)*(2*116.4-BX10))))))*669.8))/1000 -> 18260.186 | CA10: =IF((BY9-BY10)<0,"0",(BY9-BY10)) -> 0 | CB10: 205886 | CC10: =IF((CB10-CB9)<0,"0",(CB10-CB9)) -> 0 | CD10: =CC10*5.71 -> 0 | CE10: 40 | CF10: =(CE10*10775)/100 -> 4310 | CG10: 39 | CH10: =(CG10*10775)/100 -> 4202.25 | CI10: 42 | CJ10: =(CI10*10775)/100 -> 4525.5 | CK10: =CF10+CH10+CJ10 -> 13037.75 | CL10: =IF((CK9-CK10+CM9)=CK9,"0",(CK9-CK10+CM9)) -> 107.75 | CN10: 34099 | CO10: =IF((CN10-CN9)<0,"0",(CN10-CN9)) -> 1.6 | CP10: =CO10*2.44 -> 3.904 | CQ10: 34300 | CR10: =IF((CQ10-CQ9)<0,"0",(CQ10-CQ9)) -> 0 | CS10: =CR10*2.44 -> 0 | CT10: 10234 | CU10: =IF((CT10-CT9)<0,"0",(CT10-CT9)) -> 0 | CV10: =CU10*6.25 -> 0 | CW10: 831923 | CX10: =IF((CW10-CW9)<0,"0",(CW10-CW9)) -> 0 | CY10: =CX10*3.1 -> 0 | CZ10: 5723.4 | DA10: =IF((CZ10-CZ9)<0,"0",(CZ10-CZ9)) -> 1 | DB10: =DA10*2.39 -> 2.39 | DC10: 7415 | DD10: =IF((DC10-DC9)<0,"0",(DC10-DC9)) -> 0 | DE10: =DD10*2.39 -> 0 | DF10: 3801.2 | DG10: =IF((DF10-DF9)<0,"0",(DF10-DF9)) -> 3.5 | DH10: =DG10*2.39 -> 8.365 | DI10: 1855.8 | DJ10: =IF((DI10-DI9)<0,"0",(DI10-DI9)) -> 0 | DK10: =DJ10*2.39 -> 0 | DL10: 5078.4 | DM10: =IF((DL10-DL9)<0,"0",(DL10-DL9)) -> 0 | DN10: =DM10*2.39 -> 0 | DO10: 4451.7 | DP10: =IF((DO10-DO9)<0,"0",(DO10-DO9)) -> 0 | DQ10: =DP10*2.39 -> 0 | DR10: 5086.1 | DS10: =IF((DR10-DR9)<0,"0",(DR10-DR9)) -> 0 | DT10: =DS10*2.39 -> 0 | DU10: 4320.7 | DV10: =IF((DU10-DU9)<0,"0",(DU10-DU9)) -> 0 | DW10: =DV10*2.39 -> 0 | DX10: 12732 | DY10: =IF((DX10-DX9)<0,"0",(DX10-DX9)) -> 0 | DZ10: 61889 | EA10: 0 | EB10: 15599 | EC10: =IF((EB10-EB9)<0,"0",(EB10-EB9)) -> 0 | ED10: 24594 | EE10: =IF((ED10-ED9)<0,"0",(ED10-ED9)) -> 0 | EF10: 2 | EG10: 11 | EH10: 0.015
A11: 44020 | B11: 5241665 | C11: =IF((B11-B10)<0,"0",(B11-B10)) -> 3638 | D11: 4590383 | E11: =IF((D11-D10)<0,"0",(D11-D10)) -> 3379 | F11: =E11/C11 -> 0.92880704 | G11: 196 | H11: 286 | I11: 285707 | J11: =IF((I11-I10)<0,"0",(I11-I10)) -> 0 | K11: 750 | L11: =IF((K11-K10)<0,"0",(K11-K10)) -> 0 | M11: 629908 | N11: =IF((M11-M10)<0,"0",(M11-M10)) -> 0 | O11: 967 | P11: =IF((O11-O10)<0,"0",(O11-O10)) -> 0 | Q11: 2530944 | R11: =IF((Q11-Q10)<0,"0",(Q11-Q10)) -> 87 | S11: 2187542 | T11: =IF((S11-S10)<0,"0",(S11-S10)) -> 3 | U11: 92737 | V11: =IF((U11-U10)<0,"0",(U11-U10)) -> 73 | W11: 100 | X11: 0 | Y11: 152258 | Z11: =IF((Y11-Y10)<0,"0",(Y11-Y10)) -> 0 | AA11: 37883 | AB11: =IF((AA11-AA10)<0,"0",(AA11-AA10)) -> 6 | AC11: 1060 | AD11: =IF((AC11-AC10)<0,"0",(AC11-AC10)) -> 0 | AE11: 3689 | AF11: =IF((AE11-AE10)<0,"0",(AE11-AE10)) -> 0 | AI11: 570970 | AJ11: =IF((AI11-AI10)<0,"0",(AI11-AI10)) -> 20 | AM11: 52021 | AN11: =IF((AM11-AM10)<0,"0",(AM11-AM10)) -> 0 | AO11: 8863 | AP11: =IF((AO11-AO10)<0,"0",(AO11-AO10)) -> 0 | AQ11: 10549 | AR11: =IF((AQ11-AQ10)<0,"0",(AQ11-AQ10)) -> 0 | AS11: 14481 | AT11: =IF((AS11-AS10)<0,"0",(AS11-AS10)) -> 0 | AU11: 19349 | AV11: =IF((AU11-AU10)<0,"0",(AU11-AU10)) -> 0 | AW11: 20660 | AX11: =IF((AW11-AW10)<0,"0",(AW11-AW10)) -> 0 | AY11: 13831 | AZ11: =IF((AY11-AY10)<0,"0",(AY11-AY10)) -> 0 | BA11: 6153 | BB11: =IF((BA11-BA10)<0,"0",(BA11-BA10)) -> 0 | BC11: 26343 | BD11: =IF((BC11-BC10)<0,"0",(BC11-BC10)) -> 0 | BE11: 1112 | BF11: =IF((BE11-BE10)<0,"0",(BE11-BE10)) -> 0 | BG11: 4303 | BH11: =IF((BG11-BG10)<0,"0",(BG11-BG10)) -> 0 | BI11: 3636 | BJ11: =IF((BI11-BI10)<0,"0",(BI11-BI10)) -> 0 | BK11: =AZ11+AX11+AT11 -> 0 | BL11: =AJ11-BK11 -> 20 | BM11: 595140 | BN11: =IF((BM11-BM10)<0,"0",(BM11-BM10)) -> 20 | BO11: 581 | BP11: =IF((BO11-BO10)<0,"0",(BO11-BO10)) -> 0 | BQ11: 768010 | BR11: =IF((BQ11-BQ10)<0,"0",(BQ11-BQ10)) -> 20 | BS11: 5866 | BT11: =IF((BS11-BS10)<0,"0",(BS11-BS10)) -> 0 | BU11: =(BR11-AJ11) -> 0 | BV11: =SUM(BN11, BR11) -> 40 | BW11: =SUM(AN11,AP11,AR11,AT11,AV11,AX11,AZ11,BB11,BF11) -> 0 | BX11: 142.3 | BY11: =(IF(BX11<=116.4,((116.4*116.4*ACOS((116.4-BX11)/116.4))-((116.4-BX11)*SQRT(2*116.4*BX11-BX11*BX11)))*669.8,((3.1416*116.4*116.4)-((116.4*116.4*ACOS((116.4-(2*116.4-BX11))/116.4))-((116.4-(2*116.4-BX11))*SQRT(2*116.4*(2*116.4-BX11)-((2*116.4-BX11)*(2*116.4-BX11))))))*669.8))/1000 -> 18260.186 | CA11: =IF((BY10-BY11)<0,"0",(BY10-BY11)) -> 0 | CB11: 205886 | CC11: =IF((CB11-CB10)<0,"0",(CB11-CB10)) -> 0 | CD11: =CC11*5.71 -> 0 | CE11: 40 | CF11: =(CE11*10775)/100 -> 4310 | CG11: 39 | CH11: =(CG11*10775)/100 -> 4202.25 | CI11: 42 | CJ11: =(CI11*10775)/100 -> 4525.5 | CK11: =CF11+CH11+CJ11 -> 13037.75 | CL11: =IF((CK10-CK11+CM10)=CK10,"0",(CK10-CK11+CM10)) -> 0 | CN11: 34099.7 | CO11: =IF((CN11-CN10)<0,"0",(CN11-CN10)) -> 0.7 | CP11: =CO11*2.44 -> 1.708 | CQ11: 34300 | CR11: =IF((CQ11-CQ10)<0,"0",(CQ11-CQ10)) -> 0 | CS11: =CR11*2.44 -> 0 | CT11: 10234 | CU11: =IF((CT11-CT10)<0,"0",(CT11-CT10)) -> 0 | CV11: =CU11*6.25 -> 0 | CW11: 831923 | CX11: =IF((CW11-CW10)<0,"0",(CW11-CW10)) -> 0 | CY11: =CX11*3.1 -> 0 | CZ11: 5723.6 | DA11: =IF((CZ11-CZ10)<0,"0",(CZ11-CZ10)) -> 0.2 | DB11: =DA11*2.39 -> 0.478 | DC11: 7415 | DD11: =IF((DC11-DC10)<0,"0",(DC11-DC10)) -> 0 | DE11: =DD11*2.39 -> 0 | DF11: 3805.1 | DG11: =IF((DF11-DF10)<0,"0",(DF11-DF10)) -> 3.9 | DH11: =DG11*2.39 -> 9.321 | DI11: 1855.8 | DJ11: =IF((DI11-DI10)<0,"0",(DI11-DI10)) -> 0 | DK11: =DJ11*2.39 -> 0 | DL11: 5078.4 | DM11: =IF((DL11-DL10)<0,"0",(DL11-DL10)) -> 0 | DN11: =DM11*2.39 -> 0 | DO11: 4451.7 | DP11: =IF((DO11-DO10)<0,"0",(DO11-DO10)) -> 0 | DQ11: =DP11*2.39 -> 0 | DR11: 5086.1 | DS11: =IF((DR11-DR10)<0,"0",(DR11-DR10)) -> 0 | DT11: =DS11*2.39 -> 0 | DU11: 4320.7 | DV11: =IF((DU11-DU10)<0,"0",(DU11-DU10)) -> 0 | DW11: =DV11*2.39 -> 0 | DX11: 12732 | DY11: =IF((DX11-DX10)<0,"0",(DX11-DX10)) -> 0 | DZ11: 61889 | EA11: 0 | EB11: 15599 | EC11: =IF((EB11-EB10)<0,"0",(EB11-EB10)) -> 0 | ED11: 24594 | EE11: =IF((ED11-ED10)<0,"0",(ED11-ED10)) -> 0 | EF11: 2 | EG11: 11 | EH11: 0.015
A12: 44021 | B12: 5245556 | C12: =IF((B12-B11)<0,"0",(B12-B11)) -> 3891 | D12: 4593929 | E12: =IF((D12-D11)<0,"0",(D12-D11)) -> 3546 | F12: =E12/C12 -> 0.91133385 | G12: 200 | H12: 286 | I12: 285707 | J12: =IF((I12-I11)<0,"0",(I12-I11)) -> 0 | K12: 750 | L12: =IF((K12-K11)<0,"0",(K12-K11)) -> 0 | M12: 629908 | N12: =IF((M12-M11)<0,"0",(M12-M11)) -> 0 | O12: 967 | P12: =IF((O12-O11)<0,"0",(O12-O11)) -> 0 | Q12: 2531039 | R12: =IF((Q12-Q11)<0,"0",(Q12-Q11)) -> 95 | S12: 2187542 | T12: =IF((S12-S11)<0,"0",(S12-S11)) -> 0 | U12: 92800 | V12: =IF((U12-U11)<0,"0",(U12-U11)) -> 63 | W12: 100 | X12: 0 | Y12: 152258 | Z12: =IF((Y12-Y11)<0,"0",(Y12-Y11)) -> 0 | AA12: 37893 | AB12: =IF((AA12-AA11)<0,"0",(AA12-AA11)) -> 10 | AC12: 1060 | AD12: =IF((AC12-AC11)<0,"0",(AC12-AC11)) -> 0 | AE12: 3689 | AF12: =IF((AE12-AE11)<0,"0",(AE12-AE11)) -> 0 | AI12: 571040 | AJ12: =IF((AI12-AI11)<0,"0",(AI12-AI11)) -> 70 | AM12: 52021 | AN12: =IF((AM12-AM11)<0,"0",(AM12-AM11)) -> 0 | AO12: 8866 | AP12: =IF((AO12-AO11)<0,"0",(AO12-AO11)) -> 3 | AQ12: 10550 | AR12: =IF((AQ12-AQ11)<0,"0",(AQ12-AQ11)) -> 1 | AS12: 14481 | AT12: =IF((AS12-AS11)<0,"0",(AS12-AS11)) -> 0 | AU12: 19349 | AV12: =IF((AU12-AU11)<0,"0",(AU12-AU11)) -> 0 | AW12: 20660 | AX12: =IF((AW12-AW11)<0,"0",(AW12-AW11)) -> 0 | AY12: 13831 | AZ12: =IF((AY12-AY11)<0,"0",(AY12-AY11)) -> 0 | BA12: 6153 | BB12: =IF((BA12-BA11)<0,"0",(BA12-BA11)) -> 0 | BC12: 26343 | BD12: =IF((BC12-BC11)<0,"0",(BC12-BC11)) -> 0 | BE12: 1112 | BF12: =IF((BE12-BE11)<0,"0",(BE12-BE11)) -> 0 | BG12: 4303 | BH12: =IF((BG12-BG11)<0,"0",(BG12-BG11)) -> 0 | BI12: 3636 | BJ12: =IF((BI12-BI11)<0,"0",(BI12-BI11)) -> 0 | BK12: =AZ12+AX12+AT12 -> 0 | BL12: =AJ12-BK12 -> 70 | BM12: 595160 | BN12: =IF((BM12-BM11)<0,"0",(BM12-BM11)) -> 20 | BO12: 581 | BP12: =IF((BO12-BO11)<0,"0",(BO12-BO11)) -> 0 | BQ12: 768080 | BR12: =IF((BQ12-BQ11)<0,"0",(BQ12-BQ11)) -> 70 | BS12: 5866 | BT12: 0 | BU12: =(BR12-AJ12) -> 0 | BV12: =SUM(BN12, BR12) -> 90 | BW12: =SUM(AN12,AP12,AR12,AT12,AV12,AX12,AZ12,BB12,BF12) -> 4 | BX12: 142.3 | BY12: =(IF(BX12<=116.4,((116.4*116.4*ACOS((116.4-BX12)/116.4))-((116.4-BX12)*SQRT(2*116.4*BX12-BX12*BX12)))*669.8,((3.1416*116.4*116.4)-((116.4*116.4*ACOS((116.4-(2*116.4-BX12))/116.4))-((116.4-(2*116.4-BX12))*SQRT(2*116.4*(2*116.4-BX12)-((2*116.4-BX12)*(2*116.4-BX12))))))*669.8))/1000 -> 18260.186 | CA12: =IF((BY11-BY12)<0,"0",(BY11-BY12)) -> 0 | CB12: 205898 | CC12: =IF((CB12-CB11)<0,"0",(CB12-CB11)) -> 12 | CD12: =CC12*5.71 -> 68.52 | CE12: 40 | CF12: =(CE12*10775)/100 -> 4310 | CG12: 39 | CH12: =(CG12*10775)/100 -> 4202.25 | CI12: 40 | CJ12: =(CI12*10775)/100 -> 4310 | CK12: =CF12+CH12+CJ12 -> 12822.25 | CL12: =IF((CK11-CK12+CM11)=CK11,"0",(CK11-CK12+CM11)) -> 215.5 | CN12: 34100.29 | CO12: =IF((CN12-CN11)<0,"0",(CN12-CN11)) -> 0.59 | CP12: =CO12*2.44 -> 1.4396 | CQ12: 34300 | CR12: =IF((CQ12-CQ11)<0,"0",(CQ12-CQ11)) -> 0 | CS12: =CR12*2.44 -> 0 | CT12: 10234 | CU12: =IF((CT12-CT11)<0,"0",(CT12-CT11)) -> 0 | CV12: =CU12*6.25 -> 0 | CW12: 831935 | CX12: =IF((CW12-CW11)<0,"0",(CW12-CW11)) -> 12 | CZ12: 5724.2 | DA12: =IF((CZ12-CZ11)<0,"0",(CZ12-CZ11)) -> 0.6 | DB12: =DA12*2.39 -> 1.434 | DC12: 7415 | DD12: =IF((DC12-DC11)<0,"0",(DC12-DC11)) -> 0 | DE12: =DD12*2.39 -> 0 | DF12: 3810.7 | DG12: =IF((DF12-DF11)<0,"0",(DF12-DF11)) -> 5.6 | DH12: =DG12*2.39 -> 13.384 | DI12: 1855.7 | DJ12: =IF((DI12-DI11)<0,"0",(DI12-DI11)) -> 0 | DK12: =DJ12*2.39 -> 0 | DL12: 5078.4 | DM12: =IF((DL12-DL11)<0,"0",(DL12-DL11)) -> 0 | DN12: =DM12*2.39 -> 0 | DO12: 4451.7 | DP12: =IF((DO12-DO11)<0,"0",(DO12-DO11)) -> 0 | DQ12: =DP12*2.39 -> 0 | DR12: 5086.1 | DS12: =IF((DR12-DR11)<0,"0",(DR12-DR11)) -> 0 | DT12: =DS12*2.39 -> 0 | DU12: 4320.7 | DV12: =IF((DU12-DU11)<0,"0",(DU12-DU11)) -> 0 | DW12: =DV12*2.39 -> 0 | DX12: 12732 | DY12: =IF((DX12-DX11)<0,"0",(DX12-DX11)) -> 0 | DZ12: 61889 | EA12: 0 | EB12: 15599 | EC12: =IF((EB12-EB11)<0,"0",(EB12-EB11)) -> 0 | ED12: 24594 | EE12: =IF((ED12-ED11)<0,"0",(ED12-ED11)) -> 0 | EF12: 2 | EG12: 11 | EH12: 0.015
