Workbook

Sheet Total
A1: Site Name | B1: Day | C1: Month | D1: Year | E1: Total Electricity Kwh | F1: Electricity Tariff ($/Kwh) | G1: LPG (Kg) | H1: LPG $/Kg | I1: Water Utility Supply (m3) m3 | J1: Water Utility Supply (m3) $/m3 | K1: Room Nights | L1: Utilities day cost dh
A2: Serengeti | B2: 1 | C2: 8 | D2: 2020 | E2: ='UTILITY REPORT 1'!F3 -> 1872 | F2: =('UTILITY REPORT 1'!E3*'UTILITY REPORT 1'!D3)/'UTILITY REPORT 1'!F3 -> 0.39605769 | G2: =IF('Utility summery'!M6<0,"0",'Utility summery'!M6) -> 315873.14 | H2: 0 | I2: =IF('UTILITY REPORT 1'!G3<0,"0",'UTILITY REPORT 1'!G3) -> 51 | J2: 0 | K2: ='UTILITY REPORT 1'!C3 -> 0 | L2: =E2*F2+G2*H2+#REF!*#REF!+I2*J2 -> #REF!
A3: Serengeti | B3: =B2+1 -> 2 | C3: 8 | D3: 2020 | E3: ='UTILITY REPORT 1'!F4 -> 2030 | F3: =('UTILITY REPORT 1'!E4*'UTILITY REPORT 1'!D4)/'UTILITY REPORT 1'!F4 -> 0.38525123 | G3: =IF('Utility summery'!M7<0,"0",'Utility summery'!M7) -> 25.784 | H3: 0 | I3: =IF('UTILITY REPORT 1'!G4<0,"0",'UTILITY REPORT 1'!G4) -> 53 | J3: 0 | K3: ='UTILITY REPORT 1'!C4 -> 0 | L3: =E3*F3+G3*H3+#REF!*#REF!+I3*J3 -> #REF!
A4: Serengeti | B4: =B3+1 -> 3 | C4: 8 | D4: 2020 | E4: ='UTILITY REPORT 1'!F5 -> 1818 | F4: =('UTILITY REPORT 1'!E5*'UTILITY REPORT 1'!D5)/'UTILITY REPORT 1'!F5 -> 0.43366887 | G4: =IF('Utility summery'!M8<0,"0",'Utility summery'!M8) -> 65.648 | H4: 0 | I4: =IF('UTILITY REPORT 1'!G5<0,"0",'UTILITY REPORT 1'!G5) -> 42 | J4: 0 | K4: ='UTILITY REPORT 1'!C5 -> 0 | L4: =E4*F4+G4*H4+#REF!*#REF!+I4*J4 -> #REF!
A5: Serengeti | B5: =B4+1 -> 4 | C5: 8 | D5: 2020 | E5: ='UTILITY REPORT 1'!F6 -> 1980 | F5: =('UTILITY REPORT 1'!E6*'UTILITY REPORT 1'!D6)/'UTILITY REPORT 1'!F6 -> 0.40081313 | G5: =IF('Utility summery'!M9<0,"0",'Utility summery'!M9) -> 22.704 | H5: 0 | I5: =IF('UTILITY REPORT 1'!G6<0,"0",'UTILITY REPORT 1'!G6) -> 67 | J5: 0 | K5: ='UTILITY REPORT 1'!C6 -> 0 | L5: =E5*F5+G5*H5+#REF!*#REF!+I5*J5 -> #REF!
A6: Serengeti | B6: =B5+1 -> 5 | C6: 8 | D6: 2020 | E6: ='UTILITY REPORT 1'!F7 -> 1724 | F6: =('UTILITY REPORT 1'!E7*'UTILITY REPORT 1'!D7)/'UTILITY REPORT 1'!F7 -> 0.45012761 | G6: =IF('Utility summery'!M10<0,"0",'Utility summery'!M10) -> 31.24 | H6: 0 | I6: =IF('UTILITY REPORT 1'!G7<0,"0",'UTILITY REPORT 1'!G7) -> 49 | J6: 0 | K6: ='UTILITY REPORT 1'!C7 -> 0 | L6: =E6*F6+G6*H6+#REF!*#REF!+I6*J6 -> #REF!
A7: Serengeti | B7: =B6+1 -> 6 | C7: 8 | D7: 2020 | E7: ='UTILITY REPORT 1'!F8 -> 1892 | F7: =('UTILITY REPORT 1'!E8*'UTILITY REPORT 1'!D8)/'UTILITY REPORT 1'!F8 -> 0.4112685 | G7: =IF('Utility summery'!M11<0,"0",'Utility summery'!M11) -> 8.448 | H7: 0 | I7: =IF('UTILITY REPORT 1'!G8<0,"0",'UTILITY REPORT 1'!G8) -> 66 | J7: 0 | K7: ='UTILITY REPORT 1'!C8 -> 0 | L7: =E7*F7+G7*H7+#REF!*#REF!+I7*J7 -> #REF!
A8: Serengeti | B8: =B7+1 -> 7 | C8: 8 | D8: 2020 | E8: ='UTILITY REPORT 1'!F9 -> 1882 | F8: =('UTILITY REPORT 1'!E9*'UTILITY REPORT 1'!D9)/'UTILITY REPORT 1'!F9 -> 0.41004251 | G8: =IF('Utility summery'!M12<0,"0",'Utility summery'!M12) -> 0 | H8: 0 | I8: =IF('UTILITY REPORT 1'!G9<0,"0",'UTILITY REPORT 1'!G9) -> 51 | J8: 0 | K8: ='UTILITY REPORT 1'!C9 -> 0 | L8: =E8*F8+G8*H8+#REF!*#REF!+I8*J8 -> #REF!
A9: Serengeti | B9: =B8+1 -> 8 | C9: 8 | D9: 2020 | E9: ='UTILITY REPORT 1'!F10 -> 0 | F9: =('UTILITY REPORT 1'!E10*'UTILITY REPORT 1'!D10)/'UTILITY REPORT 1'!F10 -> #DIV/0! | G9: =IF('Utility summery'!M13<0,"0",'Utility summery'!M13) -> 0 | H9: 0 | I9: =IF('UTILITY REPORT 1'!G10<0,"0",'UTILITY REPORT 1'!G10) -> 0 | J9: 0 | K9: ='UTILITY REPORT 1'!C10 -> 0 | L9: =E9*F9+G9*H9+#REF!*#REF!+I9*J9 -> #DIV/0!
A10: Serengeti | B10: =B9+1 -> 9 | C10: 8 | D10: 2020 | E10: ='UTILITY REPORT 1'!F11 -> 0 | F10: =('UTILITY REPORT 1'!E11*'UTILITY REPORT 1'!D11)/'UTILITY REPORT 1'!F11 -> #DIV/0! | G10: =IF('Utility summery'!M14<0,"0",'Utility summery'!M14) -> 0 | H10: 0 | I10: =IF('UTILITY REPORT 1'!G11<0,"0",'UTILITY REPORT 1'!G11) -> 0 | J10: 0 | K10: ='UTILITY REPORT 1'!C11 -> 0 | L10: =E10*F10+G10*H10+#REF!*#REF!+I10*J10 -> #DIV/0!
A11: Serengeti | B11: =B10+1 -> 10 | C11: 8 | D11: 2020 | E11: ='UTILITY REPORT 1'!F12 -> 0 | F11: =('UTILITY REPORT 1'!E12*'UTILITY REPORT 1'!D12)/'UTILITY REPORT 1'!F12 -> #DIV/0! | G11: =IF('Utility summery'!M15<0,"0",'Utility summery'!M15) -> 0 | H11: 0 | I11: =IF('UTILITY REPORT 1'!G12<0,"0",'UTILITY REPORT 1'!G12) -> 0 | J11: 0 | K11: ='UTILITY REPORT 1'!C12 -> 0 | L11: =E11*F11+G11*H11+#REF!*#REF!+I11*J11 -> #DIV/0!
A12: Serengeti | B12: =B11+1 -> 11 | C12: 8 | D12: 2020 | E12: ='UTILITY REPORT 1'!F13 -> 0 | F12: =('UTILITY REPORT 1'!E13*'UTILITY REPORT 1'!D13)/'UTILITY REPORT 1'!F13 -> #DIV/0! | G12: =IF('Utility summery'!M16<0,"0",'Utility summery'!M16) -> 0 | H12: 0 | I12: =IF('UTILITY REPORT 1'!G13<0,"0",'UTILITY REPORT 1'!G13) -> 0 | J12: 0 | K12: ='UTILITY REPORT 1'!C13 -> 0 | L12: =E12*F12+G12*H12+#REF!*#REF!+I12*J12 -> #DIV/0!
A13: Serengeti | B13: =B12+1 -> 12 | C13: 8 | D13: 2020 | E13: ='UTILITY REPORT 1'!F14 -> 0 | F13: =('UTILITY REPORT 1'!E14*'UTILITY REPORT 1'!D14)/'UTILITY REPORT 1'!F14 -> #DIV/0! | G13: =IF('Utility summery'!M17<0,"0",'Utility summery'!M17) -> 0 | H13: 0 | I13: =IF('UTILITY REPORT 1'!G14<0,"0",'UTILITY REPORT 1'!G14) -> 0 | J13: 0 | K13: ='UTILITY REPORT 1'!C14 -> 0 | L13: =E13*F13+G13*H13+#REF!*#REF!+I13*J13 -> #DIV/0!
A14: Serengeti | B14: =B13+1 -> 13 | C14: 8 | D14: 2020 | E14: ='UTILITY REPORT 1'!F15 -> 0 | F14: =('UTILITY REPORT 1'!E15*'UTILITY REPORT 1'!D15)/'UTILITY REPORT 1'!F15 -> #DIV/0! | G14: =IF('Utility summery'!M18<0,"0",'Utility summery'!M18) -> 0 | H14: 0 | I14: =IF('UTILITY REPORT 1'!G15<0,"0",'UTILITY REPORT 1'!G15) -> 0 | J14: 0 | K14: ='UTILITY REPORT 1'!C15 -> 0 | L14: =E14*F14+G14*H14+#REF!*#REF!+I14*J14 -> #DIV/0!
... A30: Serengeti | B30: =B29+1 -> 29 | C30: 8 | D30: 2020 | E30: ='UTILITY REPORT 1'!F31 -> 0 | F30: =('UTILITY REPORT 1'!E31*'UTILITY REPORT 1'!D31)/'UTILITY REPORT 1'!F31 -> #DIV/0! | G30: =IF('Utility summery'!M34<0,"0",'Utility summery'!M34) -> 0 | H30: 0 | I30: =IF('UTILITY REPORT 1'!G31<0,"0",'UTILITY REPORT 1'!G31) -> 0 | J30: 0 | K30: ='UTILITY REPORT 1'!C31 -> 0 | L30: =E30*F30+G30*H30+#REF!*#REF!+I30*J30 -> #DIV/0!
A31: Serengeti | B31: 30 | C31: 8 | D31: 2020 | E31: ='UTILITY REPORT 1'!F32 -> 0 | F31: =('UTILITY REPORT 1'!E32*'UTILITY REPORT 1'!D32)/'UTILITY REPORT 1'!F32 -> #DIV/0! | G31: =IF('Utility summery'!M35<0,"0",'Utility summery'!M35) -> 0 | H31: 0 | I31: =IF('UTILITY REPORT 1'!G32<0,"0",'UTILITY REPORT 1'!G32) -> 0 | J31: 0 | K31: ='UTILITY REPORT 1'!C32 -> 0 | L31: =E31*F31+G31*H31+#REF!*#REF!+I31*J31 -> #DIV/0!
A32: Serengeti | B32: =B31+1 -> 31 | C32: 8 | D32: 2020 | E32: ='UTILITY REPORT 1'!F33 -> 0 | F32: =('UTILITY REPORT 1'!E33*'UTILITY REPORT 1'!D33)/'UTILITY REPORT 1'!F33 -> #DIV/0! | G32: =IF('Utility summery'!M36<0,"0",'Utility summery'!M36) -> 0 | H32: 0 | I32: =IF('UTILITY REPORT 1'!G33<0,"0",'UTILITY REPORT 1'!G33) -> 0 | J32: 0 | K32: ='UTILITY REPORT 1'!C33 -> 0

Sheet Submetering
A1: Site Name | B1: Day | C1: Month | D1: Year | E1: Transport Consumption (LT) | F1: Generators Consumption (LT) | G1: Total Electricity Kwh | H1: Kitchen (KWh) | I1: Laundry (KWh) | J1: STP (M3) | K1: RO prodution (M3) | L1: Amani Restaurant (M3) | M1: Kitchen (M3) | N1: Laundry (M3) | O1: Laundry (M3) | P1: Total water Consumption (M3) | Q1: Borehole #1 (M3) | R1: Borehole #2 (M3) | S1: Borehole #3 (M3) | T1: Borehole #4 (M3) | U1: Borehole #5 (M3) | V1: Borehole #6 (M3) | W1: Total Bore holes production (M3) | X1: Room Nights
A2: Serengeti | B2: 1 | C2: 8 | D2: 2020 | E2: ='UTILITY REPORT 1'!I3 -> 16.85 | F2: ='UTILITY REPORT 1'!E3 -> 741.42 | G2: ='UTILITY REPORT 1'!F3 -> 1872 | H2: =IF('Kit report'!F4<0,"0",'Kit report'!F4) -> 144 | I2: =IF('Kit report'!X4<0,"0",'Kit report'!X4) -> 20 | J2: =IF('Utility summery'!H6<0,"0",'Utility summery'!H6) -> 48 | K2: =IF('UTILITY REPORT 1'!H3<0,"0",'UTILITY REPORT 1'!H3) -> 78 | L2: ='Water-Meter'!K6 -> 1 | M2: ='Water-Meter'!H6 -> 0 | N2: ='Water-Meter'!Q6 -> 1 | O2: =K2*E2+H2*I2+#REF!*#REF!+J2*L2 -> #REF! | P2: ='Water-Meter'!E6 -> 51 | Q2: =IF('Water-Meter'!U6<0,"0",'Water-Meter'!U6) -> 80 | R2: =IF('Water-Meter'!X6<0,"0",'Water-Meter'!X6) -> 0 | S2: =IF('Water-Meter'!AA6<0,"0",'Water-Meter'!AA6) -> 35 | T2: =IF('Water-Meter'!AD6<0,"0",'Water-Meter'!AD6) -> 12 | U2: =IF('Water-Meter'!AG6<0,"0",'Water-Meter'!AG6) -> 0 | V2: =IF('Water-Meter'!AJ6<0,"0",'Water-Meter'!AJ6) -> 43 | W2: ='Water-Meter'!AN6 -> 170 | X2: =Total!K2 -> 0
A3: Serengeti | B3: =B2+1 -> 2 | C3: 8 | D3: 2020 | E3: ='UTILITY REPORT 1'!I4 -> 0 | F3: ='UTILITY REPORT 1'!E4 -> 782.06 | G3: ='UTILITY REPORT 1'!F4 -> 2030 | H3: =IF('Kit report'!F5<0,"0",'Kit report'!F5) -> 168 | I3: =IF('Kit report'!X5<0,"0",'Kit report'!X5) -> 40 | J3: =IF('Utility summery'!H7<0,"0",'Utility summery'!H7) -> 31 | K3: =IF('UTILITY REPORT 1'!H4<0,"0",'UTILITY REPORT 1'!H4) -> 156 | L3: ='Water-Meter'!K7 -> 1 | M3: ='Water-Meter'!H7 -> 0 | N3: ='Water-Meter'!Q7 -> 1 | O3: =K3*E3+H3*I3+#REF!*#REF!+J3*L3 -> #REF! | P3: ='Water-Meter'!E7 -> 53 | Q3: =IF('Water-Meter'!U7<0,"0",'Water-Meter'!U7) -> 97 | R3: =IF('Water-Meter'!X7<0,"0",'Water-Meter'!X7) -> 0 | S3: =IF('Water-Meter'!AA7<0,"0",'Water-Meter'!AA7) -> 38 | T3: =IF('Water-Meter'!AD7<0,"0",'Water-Meter'!AD7) -> 17 | U3: =IF('Water-Meter'!AG7<0,"0",'Water-Meter'!AG7) -> 0 | V3: =IF('Water-Meter'!AJ7<0,"0",'Water-Meter'!AJ7) -> 33 | W3: ='Water-Meter'!AN7 -> 185 | X3: =Total!K3 -> 0
A4: Serengeti | B4: =B3+1 -> 3 | C4: 8 | D4: 2020 | E4: ='UTILITY REPORT 1'!I5 -> 25.31 | F4: ='UTILITY REPORT 1'!E5 -> 788.41 | G4: ='UTILITY REPORT 1'!F5 -> 1818 | H4: =IF('Kit report'!F6<0,"0",'Kit report'!F6) -> 132 | I4: =IF('Kit report'!X6<0,"0",'Kit report'!X6) -> 20 | J4: =IF('Utility summery'!H8<0,"0",'Utility summery'!H8) -> 70 | K4: =IF('UTILITY REPORT 1'!H5<0,"0",'UTILITY REPORT 1'!H5) -> 0 | L4: ='Water-Meter'!K8 -> 1 | M4: ='Water-Meter'!H8 -> 0 | N4: ='Water-Meter'!Q8 -> 1 | O4: =K4*E4+H4*I4+#REF!*#REF!+J4*L4 -> #REF! | P4: ='Water-Meter'!E8 -> 42 | Q4: =IF('Water-Meter'!U8<0,"0",'Water-Meter'!U8) -> 83 | R4: =IF('Water-Meter'!X8<0,"0",'Water-Meter'!X8) -> 0 | S4: =IF('Water-Meter'!AA8<0,"0",'Water-Meter'!AA8) -> 40 | T4: =IF('Water-Meter'!AD8<0,"0",'Water-Meter'!AD8) -> 20 | U4: =IF('Water-Meter'!AG8<0,"0",'Water-Meter'!AG8) -> 0 | V4: =IF('Water-Meter'!AJ8<0,"0",'Water-Meter'!AJ8) -> 12 | W4: ='Water-Meter'!AN8 -> 155 | X4: =Total!K4 -> 0
A5: Serengeti | B5: =B4+1 -> 4 | C5: 8 | D5: 2020 | E5: ='UTILITY REPORT 1'!I6 -> 149.86 | F5: ='UTILITY REPORT 1'!E6 -> 793.61 | G5: ='UTILITY REPORT 1'!F6 -> 1980 | H5: =IF('Kit report'!F7<0,"0",'Kit report'!F7) -> 180 | I5: =IF('Kit report'!X7<0,"0",'Kit report'!X7) -> 20 | J5: =IF('Utility summery'!H9<0,"0",'Utility summery'!H9) -> 36 | K5: =IF('UTILITY REPORT 1'!H6<0,"0",'UTILITY REPORT 1'!H6) -> 55 | L5: ='Water-Meter'!K9 -> 0 | M5: ='Water-Meter'!H9 -> 0 | N5: ='Water-Meter'!Q9 -> 1 | O5: =K5*E5+H5*I5+#REF!*#REF!+J5*L5 -> #REF! | P5: ='Water-Meter'!E9 -> 67 | Q5: =IF('Water-Meter'!U9<0,"0",'Water-Meter'!U9) -> 87 | R5: =IF('Water-Meter'!X9<0,"0",'Water-Meter'!X9) -> 0 | S5: =IF('Water-Meter'!AA9<0,"0",'Water-Meter'!AA9) -> 37 | T5: =IF('Water-Meter'!AD9<0,"0",'Water-Meter'!AD9) -> 16 | U5: =IF('Water-Meter'!AG9<0,"0",'Water-Meter'!AG9) -> 0 | V5: =IF('Water-Meter'!AJ9<0,"0",'Water-Meter'!AJ9) -> 2 | W5: ='Water-Meter'!AN9 -> 142 | X5: =Total!K5 -> 0
A6: Serengeti | B6: =B5+1 -> 5 | C6: 8 | D6: 2020 | E6: ='UTILITY REPORT 1'!I7 -> 87.31 | F6: ='UTILITY REPORT 1'!E7 -> 776.02 | G6: ='UTILITY REPORT 1'!F7 -> 1724 | H6: =IF('Kit report'!F8<0,"0",'Kit report'!F8) -> 168 | I6: =IF('Kit report'!X8<0,"0",'Kit report'!X8) -> 20 | J6: =IF('Utility summery'!H10<0,"0",'Utility summery'!H10) -> 21 | K6: =IF('UTILITY REPORT 1'!H7<0,"0",'UTILITY REPORT 1'!H7) -> 56 | L6: ='Water-Meter'!K10 -> 1 | M6: ='Water-Meter'!H10 -> 0 | N6: ='Water-Meter'!Q10 -> 1 | O6: =K6*E6+H6*I6+#REF!*#REF!+J6*L6 -> #REF! | P6: ='Water-Meter'!E10 -> 49 | Q6: =IF('Water-Meter'!U10<0,"0",'Water-Meter'!U10) -> 89 | R6: =IF('Water-Meter'!X10<0,"0",'Water-Meter'!X10) -> 0 | S6: =IF('Water-Meter'!AA10<0,"0",'Water-Meter'!AA10) -> 38 | T6: =IF('Water-Meter'!AD10<0,"0",'Water-Meter'!AD10) -> 16 | U6: =IF('Water-Meter'!AG10<0,"0",'Water-Meter'!AG10) -> 0 | V6: =IF('Water-Meter'!AJ10<0,"0",'Water-Meter'!AJ10) -> 0 | W6: ='Water-Meter'!AN10 -> 143 | X6: =Total!K6 -> 0
A7: Serengeti | B7: =B6+1 -> 6 | C7: 8 | D7: 2020 | E7: ='UTILITY REPORT 1'!I8 -> 52.6 | F7: ='UTILITY REPORT 1'!E8 -> 778.12 | G7: ='UTILITY REPORT 1'!F8 -> 1892 | H7: =IF('Kit report'!F9<0,"0",'Kit report'!F9) -> 156 | I7: =IF('Kit report'!X9<0,"0",'Kit report'!X9) -> 40 | J7: =IF('Utility summery'!H11<0,"0",'Utility summery'!H11) -> 40 | K7: =IF('UTILITY REPORT 1'!H8<0,"0",'UTILITY REPORT 1'!H8) -> 50 | L7: ='Water-Meter'!K11 -> 1 | M7: ='Water-Meter'!H11 -> 0 | N7: ='Water-Meter'!Q11 -> 3 | O7: =K7*E7+H7*I7+#REF!*#REF!+J7*L7 -> #REF! | P7: ='Water-Meter'!E11 -> 66 | Q7: =IF('Water-Meter'!U11<0,"0",'Water-Meter'!U11) -> 87 | R7: =IF('Water-Meter'!X11<0,"0",'Water-Meter'!X11) -> 0 | S7: =IF('Water-Meter'!AA11<0,"0",'Water-Meter'!AA11) -> 37 | T7: =IF('Water-Meter'!AD11<0,"0",'Water-Meter'!AD11) -> 16 | U7: =IF('Water-Meter'!AG11<0,"0",'Water-Meter'!AG11) -> 0 | V7: =IF('Water-Meter'!AJ11<0,"0",'Water-Meter'!AJ11) -> 5 | W7: ='Water-Meter'!AN11 -> 145 | X7: =Total!K7 -> 0
A8: Serengeti | B8: =B7+1 -> 7 | C8: 8 | D8: 2020 | E8: ='UTILITY REPORT 1'!I9 -> 0 | F8: ='UTILITY REPORT 1'!E9 -> 771.7 | G8: ='UTILITY REPORT 1'!F9 -> 1882 | H8: =IF('Kit report'!F10<0,"0",'Kit report'!F10) -> 156 | I8: =IF('Kit report'!X10<0,"0",'Kit report'!X10) -> 40 | J8: =IF('Utility summery'!H12<0,"0",'Utility summery'!H12) -> 38 | K8: =IF('UTILITY REPORT 1'!H9<0,"0",'UTILITY REPORT 1'!H9) -> 55 | L8: ='Water-Meter'!K12 -> 1 | M8: ='Water-Meter'!H12 -> 0 | N8: ='Water-Meter'!Q12 -> 1 | O8: =K8*E8+H8*I8+#REF!*#REF!+J8*L8 -> #REF! | P8: ='Water-Meter'!E12 -> 51 | Q8: =IF('Water-Meter'!U12<0,"0",'Water-Meter'!U12) -> 87 | R8: =IF('Water-Meter'!X12<0,"0",'Water-Meter'!X12) -> 0 | S8: =IF('Water-Meter'!AA12<0,"0",'Water-Meter'!AA12) -> 38 | T8: =IF('Water-Meter'!AD12<0,"0",'Water-Meter'!AD12) -> 15 | U8: =IF('Water-Meter'!AG12<0,"0",'Water-Meter'!AG12) -> 0 | V8: =IF('Water-Meter'!AJ12<0,"0",'Water-Meter'!AJ12) -> 0 | W8: ='Water-Meter'!AN12 -> 140 | X8: =Total!K8 -> 0
A9: Serengeti | B9: =B8+1 -> 8 | C9: 8 | D9: 2020 | E9: ='UTILITY REPORT 1'!I10 -> 0 | F9: ='UTILITY REPORT 1'!E10 -> 0 | G9: ='UTILITY REPORT 1'!F10 -> 0 | H9: =IF('Kit report'!F11<0,"0",'Kit report'!F11) -> 0 | I9: =IF('Kit report'!X11<0,"0",'Kit report'!X11) -> 0 | J9: =IF('Utility summery'!H13<0,"0",'Utility summery'!H13) -> 0 | K9: =IF('UTILITY REPORT 1'!H10<0,"0",'UTILITY REPORT 1'!H10) -> 0 | L9: ='Water-Meter'!K13 -> 0 | M9: ='Water-Meter'!H13 -> 0 | N9: ='Water-Meter'!Q13 -> 0 | O9: =K9*E9+H9*I9+#REF!*#REF!+J9*L9 -> #REF! | P9: ='Water-Meter'!E13 -> 0 | Q9: =IF('Water-Meter'!U13<0,"0",'Water-Meter'!U13) -> 0 | R9: =IF('Water-Meter'!X13<0,"0",'Water-Meter'!X13) -> 0 | S9: =IF('Water-Meter'!AA13<0,"0",'Water-Meter'!AA13) -> 0 | T9: =IF('Water-Meter'!AD13<0,"0",'Water-Meter'!AD13) -> 0 | U9: =IF('Water-Meter'!AG13<0,"0",'Water-Meter'!AG13) -> 0 | V9: =IF('Water-Meter'!AJ13<0,"0",'Water-Meter'!AJ13) -> 0 | W9: ='Water-Meter'!AN13 -> -14679 | X9: =Total!K9 -> 0
A10: Serengeti | B10: =B9+1 -> 9 | C10: 8 | D10: 2020 | E10: ='UTILITY REPORT 1'!I11 -> 0 | F10: ='UTILITY REPORT 1'!E11 -> 0 | G10: ='UTILITY REPORT 1'!F11 -> 0 | H10: =IF('Kit report'!F12<0,"0",'Kit report'!F12) -> 0 | I10: =IF('Kit report'!X12<0,"0",'Kit report'!X12) -> 0 | J10: =IF('Utility summery'!H14<0,"0",'Utility summery'!H14) -> 0 | K10: =IF('UTILITY REPORT 1'!H11<0,"0",'UTILITY REPORT 1'!H11) -> 0 | L10: ='Water-Meter'!K14 -> 0 | M10: ='Water-Meter'!H14 -> 0 | N10: ='Water-Meter'!Q14 -> 0 | O10: =K10*E10+H10*I10+#REF!*#REF!+J10*L10 -> #REF! | P10: ='Water-Meter'!E14 -> 0 | Q10: =IF('Water-Meter'!U14<0,"0",'Water-Meter'!U14) -> 0 | R10: =IF('Water-Meter'!X14<0,"0",'Water-Meter'!X14) -> 0 | S10: =IF('Water-Meter'!AA14<0,"0",'Water-Meter'!AA14) -> 0 | T10: =IF('Water-Meter'!AD14<0,"0",'Water-Meter'!AD14) -> 0 | U10: =IF('Water-Meter'!AG14<0,"0",'Water-Meter'!AG14) -> 0 | V10: =IF('Water-Meter'!AJ14<0,"0",'Water-Meter'!AJ14) -> 0 | W10: ='Water-Meter'!AN14 -> 0 | X10: =Total!K10 -> 0
A11: Serengeti | B11: =B10+1 -> 10 | C11: 8 | D11: 2020 | E11: ='UTILITY REPORT 1'!I12 -> 0 | F11: ='UTILITY REPORT 1'!E12 -> 0 | G11: ='UTILITY REPORT 1'!F12 -> 0 | H11: =IF('Kit report'!F13<0,"0",'Kit report'!F13) -> 0 | I11: =IF('Kit report'!X13<0,"0",'Kit report'!X13) -> 0 | J11: =IF('Utility summery'!H15<0,"0",'Utility summery'!H15) -> 0 | K11: =IF('UTILITY REPORT 1'!H12<0,"0",'UTILITY REPORT 1'!H12) -> 0 | L11: ='Water-Meter'!K15 -> 0 | M11: ='Water-Meter'!H15 -> 0 | N11: ='Water-Meter'!Q15 -> 0 | O11: =K11*E11+H11*I11+#REF!*#REF!+J11*L11 -> #REF! | P11: ='Water-Meter'!E15 -> 0 | Q11: =IF('Water-Meter'!U15<0,"0",'Water-Meter'!U15) -> 0 | R11: =IF('Water-Meter'!X15<0,"0",'Water-Meter'!X15) -> 0 | S11: =IF('Water-Meter'!AA15<0,"0",'Water-Meter'!AA15) -> 0 | T11: =IF('Water-Meter'!AD15<0,"0",'Water-Meter'!AD15) -> 0 | U11: =IF('Water-Meter'!AG15<0,"0",'Water-Meter'!AG15) -> 0 | V11: =IF('Water-Meter'!AJ15<0,"0",'Water-Meter'!AJ15) -> 0 | W11: ='Water-Meter'!AN15 -> 0 | X11: =Total!K11 -> 0
A12: Serengeti | B12: =B11+1 -> 11 | C12: 8 | D12: 2020 | E12: ='UTILITY REPORT 1'!I13 -> 0 | F12: ='UTILITY REPORT 1'!E13 -> 0 | G12: ='UTILITY REPORT 1'!F13 -> 0 | H12: =IF('Kit report'!F14<0,"0",'Kit report'!F14) -> 0 | I12: =IF('Kit report'!X14<0,"0",'Kit report'!X14) -> 0 | J12: =IF('Utility summery'!H16<0,"0",'Utility summery'!H16) -> 0 | K12: =IF('UTILITY REPORT 1'!H13<0,"0",'UTILITY REPORT 1'!H13) -> 0 | L12: ='Water-Meter'!K16 -> 0 | M12: ='Water-Meter'!H16 -> 0 | N12: ='Water-Meter'!Q16 -> 0 | O12: =K12*E12+H12*I12+#REF!*#REF!+J12*L12 -> #REF! | P12: ='Water-Meter'!E16 -> 0 | Q12: =IF('Water-Meter'!U16<0,"0",'Water-Meter'!U16) -> 0 | R12: =IF('Water-Meter'!X16<0,"0",'Water-Meter'!X16) -> 0 | S12: =IF('Water-Meter'!AA16<0,"0",'Water-Meter'!AA16) -> 0 | T12: =IF('Water-Meter'!AD16<0,"0",'Water-Meter'!AD16) -> 0 | U12: =IF('Water-Meter'!AG16<0,"0",'Water-Meter'!AG16) -> 0 | V12: =IF('Water-Meter'!AJ16<0,"0",'Water-Meter'!AJ16) -> 0 | W12: ='Water-Meter'!AN16 -> 0 | X12: =Total!K12 -> 0
A13: Serengeti | B13: =B12+1 -> 12 | C13: 8 | D13: 2020 | E13: ='UTILITY REPORT 1'!I14 -> 0 | F13: ='UTILITY REPORT 1'!E14 -> 0 | G13: ='UTILITY REPORT 1'!F14 -> 0 | H13: =IF('Kit report'!F15<0,"0",'Kit report'!F15) -> 0 | I13: =IF('Kit report'!X15<0,"0",'Kit report'!X15) -> 0 | J13: =IF('Utility summery'!H17<0,"0",'Utility summery'!H17) -> 0 | K13: =IF('UTILITY REPORT 1'!H14<0,"0",'UTILITY REPORT 1'!H14) -> 0 | L13: ='Water-Meter'!K17 -> 0 | M13: ='Water-Meter'!H17 -> 0 | N13: ='Water-Meter'!Q17 -> 0 | O13: =K13*E13+H13*I13+#REF!*#REF!+J13*L13 -> #REF! | P13: ='Water-Meter'!E17 -> 0 | Q13: =IF('Water-Meter'!U17<0,"0",'Water-Meter'!U17) -> 0 | R13: =IF('Water-Meter'!X17<0,"0",'Water-Meter'!X17) -> 0 | S13: =IF('Water-Meter'!AA17<0,"0",'Water-Meter'!AA17) -> 0 | T13: =IF('Water-Meter'!AD17<0,"0",'Water-Meter'!AD17) -> 0 | U13: =IF('Water-Meter'!AG17<0,"0",'Water-Meter'!AG17) -> 0 | V13: =IF('Water-Meter'!AJ17<0,"0",'Water-Meter'!AJ17) -> 0 | W13: ='Water-Meter'!AN17 -> 0 | X13: =Total!K13 -> 0
A14: Serengeti | B14: =B13+1 -> 13 | C14: 8 | D14: 2020 | E14: ='UTILITY REPORT 1'!I15 -> 0 | F14: ='UTILITY REPORT 1'!E15 -> 0 | G14: ='UTILITY REPORT 1'!F15 -> 0 | H14: =IF('Kit report'!F16<0,"0",'Kit report'!F16) -> 0 | I14: =IF('Kit report'!X16<0,"0",'Kit report'!X16) -> 0 | J14: =IF('Utility summery'!H18<0,"0",'Utility summery'!H18) -> 0 | K14: =IF('UTILITY REPORT 1'!H15<0,"0",'UTILITY REPORT 1'!H15) -> 0 | L14: ='Water-Meter'!K18 -> 0 | M14: ='Water-Meter'!H18 -> 0 | N14: ='Water-Meter'!Q18 -> 0 | O14: =K14*E14+H14*I14+#REF!*#REF!+J14*L14 -> #REF! | P14: ='Water-Meter'!E18 -> 0 | Q14: =IF('Water-Meter'!U18<0,"0",'Water-Meter'!U18) -> 0 | R14: =IF('Water-Meter'!X18<0,"0",'Water-Meter'!X18) -> 0 | S14: =IF('Water-Meter'!AA18<0,"0",'Water-Meter'!AA18) -> 0 | T14: =IF('Water-Meter'!AD18<0,"0",'Water-Meter'!AD18) -> 0 | U14: =IF('Water-Meter'!AG18<0,"0",'Water-Meter'!AG18) -> 0 | V14: =IF('Water-Meter'!AJ18<0,"0",'Water-Meter'!AJ18) -> 0 | W14: ='Water-Meter'!AN18 -> 0 | X14: =Total!K14 -> 0
... A30: Serengeti | B30: =B29+1 -> 29 | C30: 8 | D30: 2020 | E30: ='UTILITY REPORT 1'!I31 -> 0 | F30: ='UTILITY REPORT 1'!E31 -> 0 | G30: ='UTILITY REPORT 1'!F31 -> 0 | H30: =IF('Kit report'!F32<0,"0",'Kit report'!F32) -> 0 | I30: =IF('Kit report'!X32<0,"0",'Kit report'!X32) -> 0 | J30: =IF('Utility summery'!H34<0,"0",'Utility summery'!H34) -> 0 | K30: =IF('UTILITY REPORT 1'!H31<0,"0",'UTILITY REPORT 1'!H31) -> 0 | L30: ='Water-Meter'!K34 -> 0 | M30: ='Water-Meter'!H34 -> 0 | N30: ='Water-Meter'!Q34 -> 0 | O30: =K30*E30+H30*I30+#REF!*#REF!+J30*L30 -> #REF! | P30: ='Water-Meter'!E34 -> 0 | Q30: =IF('Water-Meter'!U34<0,"0",'Water-Meter'!U34) -> 0 | R30: =IF('Water-Meter'!X34<0,"0",'Water-Meter'!X34) -> 0 | S30: =IF('Water-Meter'!AA34<0,"0",'Water-Meter'!AA34) -> 0 | T30: =IF('Water-Meter'!AD34<0,"0",'Water-Meter'!AD34) -> 0 | U30: =IF('Water-Meter'!AG34<0,"0",'Water-Meter'!AG34) -> 0 | V30: =IF('Water-Meter'!AJ34<0,"0",'Water-Meter'!AJ34) -> 0 | W30: ='Water-Meter'!AN34 -> 0 | X30: =Total!K30 -> 0
A31: Serengeti | B31: 30 | C31: 8 | D31: 2020 | E31: ='UTILITY REPORT 1'!I32 -> 0 | F31: ='UTILITY REPORT 1'!E32 -> 0 | G31: ='UTILITY REPORT 1'!F32 -> 0 | H31: =IF('Kit report'!F33<0,"0",'Kit report'!F33) -> 0 | I31: =IF('Kit report'!X33<0,"0",'Kit report'!X33) -> 0 | J31: =IF('Utility summery'!H35<0,"0",'Utility summery'!H35) -> 0 | K31: =IF('UTILITY REPORT 1'!H32<0,"0",'UTILITY REPORT 1'!H32) -> 0 | L31: ='Water-Meter'!K35 -> 0 | M31: ='Water-Meter'!H35 -> 0 | N31: ='Water-Meter'!Q35 -> 0 | O31: =K31*E31+H31*I31+#REF!*#REF!+J31*L31 -> #REF! | P31: ='Water-Meter'!E35 -> 0 | Q31: =IF('Water-Meter'!U35<0,"0",'Water-Meter'!U35) -> 0 | R31: =IF('Water-Meter'!X35<0,"0",'Water-Meter'!X35) -> 0 | S31: =IF('Water-Meter'!AA35<0,"0",'Water-Meter'!AA35) -> 0 | T31: =IF('Water-Meter'!AD35<0,"0",'Water-Meter'!AD35) -> 0 | U31: =IF('Water-Meter'!AG35<0,"0",'Water-Meter'!AG35) -> 0 | V31: =IF('Water-Meter'!AJ35<0,"0",'Water-Meter'!AJ35) -> 0 | W31: ='Water-Meter'!AN35 -> 0 | X31: =Total!K31 -> 0
A32: Serengeti | B32: =B31+1 -> 31 | C32: 8 | E32: ='UTILITY REPORT 1'!I33 -> 0 | F32: ='UTILITY REPORT 1'!E33 -> 0 | G32: ='UTILITY REPORT 1'!F33 -> 0 | H32: =IF('Kit report'!F34<0,"0",'Kit report'!F34) -> 0 | I32: =IF('Kit report'!X34<0,"0",'Kit report'!X34) -> 0 | J32: =IF('Utility summery'!H36<0,"0",'Utility summery'!H36) -> 0 | K32: =IF('UTILITY REPORT 1'!H33<0,"0",'UTILITY REPORT 1'!H33) -> 0 | L32: ='Water-Meter'!K36 -> 0 | M32: ='Water-Meter'!H36 -> 0 | N32: ='Water-Meter'!Q36 -> 0 | P32: ='Water-Meter'!E36 -> 0 | Q32: =IF('Water-Meter'!U36<0,"0",'Water-Meter'!U36) -> 0 | R32: =IF('Water-Meter'!X36<0,"0",'Water-Meter'!X36) -> 0 | S32: =IF('Water-Meter'!AA36<0,"0",'Water-Meter'!AA36) -> 0 | T32: =IF('Water-Meter'!AD36<0,"0",'Water-Meter'!AD36) -> 0 | U32: =IF('Water-Meter'!AG36<0,"0",'Water-Meter'!AG36) -> 0 | V32: =IF('Water-Meter'!AJ36<0,"0",'Water-Meter'!AJ36) -> 0 | W32: ='Water-Meter'!AN36 -> 0 | X32: =Total!K32 -> 0

Sheet UTILITY REPORT 1
A1: UTILITY REPORT
A2: Date | B2: % | C2: Guest Rooms Occupied | D2: Diesel cost Per Liter ($) | E2: Diesel consumption (LT) | F2: Power production (KW) | G2: Water consumption (M3) | H2: RO prodution (M3) | I2: Transport Consupmtion (LT)
A3: =Gen!B11 -> 44044 | B3: =Gen!C11 -> 0 | C3: ='Summery Report'!E5 -> 0 | D3: 1 | E3: =Gen!T11 -> 741.42 | F3: =Gen!U11 -> 1872 | G3: ='Water-Meter'!E6 -> 51 | H3: ='Utility report '!AC6 -> 78 | I3: =Gen!AK11 -> 16.85
A4: =Gen!B12 -> 44045 | B4: =Gen!C12 -> 0 | C4: ='Summery Report'!E6 -> 0 | D4: 1 | E4: =Gen!T12 -> 782.06 | F4: =Gen!U12 -> 2030 | G4: ='Water-Meter'!E7 -> 53 | H4: ='Utility report '!AC7 -> 156 | I4: =Gen!AK12 -> 0
A5: =Gen!B13 -> 44046 | B5: =Gen!C13 -> 0 | C5: ='Summery Report'!E7 -> 0 | D5: 1 | E5: =Gen!T13 -> 788.41 | F5: =Gen!U13 -> 1818 | G5: ='Water-Meter'!E8 -> 42 | H5: ='Utility report '!AC8 -> 0 | I5: =Gen!AK13 -> 25.31
A6: =Gen!B14 -> 44047 | B6: =Gen!C14 -> 0 | C6: ='Summery Report'!E8 -> 0 | D6: 1 | E6: =Gen!T14 -> 793.61 | F6: =Gen!U14 -> 1980 | G6: ='Water-Meter'!E9 -> 67 | H6: ='Utility report '!AC9 -> 55 | I6: =Gen!AK14 -> 149.86
A7: =Gen!B15 -> 44048 | B7: =Gen!C15 -> 0 | C7: ='Summery Report'!E9 -> 0 | D7: 1 | E7: =Gen!T15 -> 776.02 | F7: =Gen!U15 -> 1724 | G7: ='Water-Meter'!E10 -> 49 | H7: ='Utility report '!AC10 -> 56 | I7: =Gen!AK15 -> 87.31
A8: =Gen!B16 -> 44049 | B8: =Gen!C16 -> 0 | C8: ='Summery Report'!E10 -> 0 | D8: 1 | E8: =Gen!T16 -> 778.12 | F8: =Gen!U16 -> 1892 | G8: ='Water-Meter'!E11 -> 66 | H8: ='Utility report '!AC11 -> 50 | I8: =Gen!AK16 -> 52.6
A9: =Gen!B17 -> 44050 | B9: =Gen!C17 -> 0 | C9: ='Summery Report'!E11 -> 0 | D9: 1 | E9: =Gen!T17 -> 771.7 | F9: =Gen!U17 -> 1882 | G9: ='Water-Meter'!E12 -> 51 | H9: ='Utility report '!AC12 -> 55 | I9: =Gen!AK17 -> 0
A10: =Gen!B18 -> 44051 | B10: =Gen!C18 -> 0 | C10: ='Summery Report'!E12 -> 0 | D10: 1 | E10: =Gen!T18 -> 0 | F10: =Gen!U18 -> 0 | G10: ='Water-Meter'!E13 -> 0 | H10: ='Utility report '!AC13 -> -36392 | I10: =Gen!AK18 -> 0
A11: =Gen!B19 -> 44052 | B11: =Gen!C19 -> 0 | C11: ='Summery Report'!E13 -> 0 | D11: 1 | E11: =Gen!T19 -> 0 | F11: =Gen!U19 -> 0 | G11: ='Water-Meter'!E14 -> 0 | H11: ='Utility report '!AC14 -> 0 | I11: =Gen!AK19 -> 0
A12: =Gen!B20 -> 44053 | B12: =Gen!C20 -> 0 | C12: ='Summery Report'!E14 -> 0 | D12: 1 | E12: =Gen!T20 -> 0 | F12: =Gen!U20 -> 0 | G12: ='Water-Meter'!E15 -> 0 | H12: ='Utility report '!AC15 -> 0 | I12: =Gen!AK20 -> 0
A13: =Gen!B21 -> 44054 | B13: =Gen!C21 -> 0 | C13: ='Summery Report'!E15 -> 0 | D13: 1 | E13: =Gen!T21 -> 0 | F13: =Gen!U21 -> 0 | G13: ='Water-Meter'!E16 -> 0 | H13: ='Utility report '!AC16 -> 0 | I13: =Gen!AK21 -> 0
A14: =Gen!B22 -> 44055 | B14: =Gen!C22 -> 0 | C14: ='Summery Report'!E16 -> 0 | D14: 1 | E14: =Gen!T22 -> 0 | F14: =Gen!U22 -> 0 | G14: ='Water-Meter'!E17 -> 0 | H14: ='Utility report '!AC17 -> 0 | I14: =Gen!AK22 -> 0
... A33: =Gen!B41 -> 44074 | B33: =Gen!C41 -> 0 | C33: ='Summery Report'!E35 -> 0 | D33: 1 | E33: =Gen!T41 -> 0 | F33: =Gen!U41 -> 0 | G33: ='Water-Meter'!E36 -> 0 | H33: ='Utility report '!AC36 -> 0 | I33: =Gen!AK41 -> 0
B34: =Gen!C42 -> 0 | C34: ='Summery Report'!E36 -> 0 | D34: 2 | E34: =Gen!T42 -> 0 | F34: =Gen!U42 -> 0 | G34: ='Water-Meter'!E37 -> 0 | H34: ='Utility report '!AC37 -> 0 | I34: =Gen!AK42 -> 0

Sheet Utility summery
A4: Date | B4: Room Occupied | C4: Electricity Units Generated KW | D4: Diseal | G4: Water | J4: Gas | N4: Cost of utilites
D5: Generator | E5: Transport | F5: Total | G5: RO | H5: STP | I5: Total Consumption | J5: 2 ton | K5: 1 Ton | L5: 1 Ton | M5: Total consumption | N5: Electricity /1.4$/liter | O5: Diseal for Transport | P5: Gas /2.38$/Kg | Q5: Total HLP Cost | R5: Electricity Cost/Room $ | S5: cost/Room $
A6: =Gen!B11 -> 44044 | B6: ='Summery Report'!E5 -> 0 | C6: =Gen!U11 -> 1872 | D6: =Gen!T11 -> 741.42 | E6: =Gen!AK11 -> 16.85 | F6: =Gen!AS11 -> 758.27 | G6: ='Utility report '!AC6 -> 78 | H6: ='Utility report '!AE6 -> 48 | I6: ='Water-Meter'!E6 -> 51 | J6: ='Lpg (2)'!B10 -> 85 | K6: ='Lpg (2)'!C10 -> 85 | L6: ='Lpg (2)'!D10 -> 85 | M6: ='Lpg (2)'!G10 -> 315873.14 | O6: =E6 -> 16.85 | P6: ='[1]Lpg (2)'!#REF! -> #REF! | Q6: ='[1]Summery Report'!#REF! -> #REF! | R6: =N6/B6 -> #DIV/0! | S6: =Q6/B6 -> #REF!
A7: =Gen!B12 -> 44045 | B7: ='Summery Report'!E6 -> 0 | C7: =Gen!U12 -> 2030 | D7: =Gen!T12 -> 782.06 | E7: =Gen!AK12 -> 0 | F7: =Gen!AS12 -> 782.06 | G7: ='Utility report '!AC7 -> 156 | H7: ='Utility report '!AE7 -> 31 | I7: ='Water-Meter'!E7 -> 53 | J7: ='Lpg (2)'!B11 -> 85 | K7: ='Lpg (2)'!C11 -> 85 | L7: ='Lpg (2)'!D11 -> 85 | M7: ='Lpg (2)'!G11 -> 25.784 | N7: =D7*1.4 -> 1094.884 | O7: =E7*1.4 -> 0 | P7: ='[1]Lpg (2)'!#REF! -> #REF! | Q7: ='[1]Summery Report'!#REF! -> #REF! | R7: =N7/B7 -> #DIV/0! | S7: =Q7/B7 -> #REF!
A8: =Gen!B13 -> 44046 | B8: ='Summery Report'!E7 -> 0 | C8: =Gen!U13 -> 1818 | D8: =Gen!T13 -> 788.41 | E8: =Gen!AK13 -> 25.31 | F8: =Gen!AS13 -> 813.72 | G8: ='Utility report '!AC8 -> 0 | H8: ='Utility report '!AE8 -> 70 | I8: ='Water-Meter'!E8 -> 42 | J8: ='Lpg (2)'!B12 -> 85 | K8: ='Lpg (2)'!C12 -> 85 | L8: ='Lpg (2)'!D12 -> 84 | M8: ='Lpg (2)'!G12 -> 65.648 | N8: =D8*1.4 -> 1103.774 | O8: =E8*1.4 -> 35.434 | P8: ='[1]Lpg (2)'!#REF! -> #REF! | Q8: ='[1]Summery Report'!#REF! -> #REF! | R8: =N8/B8 -> #DIV/0! | S8: =Q8/B8 -> #REF!
A9: =Gen!B14 -> 44047 | B9: ='Summery Report'!E8 -> 0 | C9: =Gen!U14 -> 1980 | D9: =Gen!T14 -> 793.61 | E9: =Gen!AK14 -> 149.86 | F9: =Gen!AS14 -> 943.47 | G9: ='Utility report '!AC9 -> 55 | H9: ='Utility report '!AE9 -> 36 | I9: ='Water-Meter'!E9 -> 67 | J9: ='Lpg (2)'!B13 -> 85 | K9: ='Lpg (2)'!C13 -> 85 | L9: ='Lpg (2)'!D13 -> 84 | M9: ='Lpg (2)'!G13 -> 22.704 | N9: =D9*1.4 -> 1111.054 | O9: =E9*1.4 -> 209.804 | P9: ='[1]Lpg (2)'!#REF! -> #REF! | Q9: ='[1]Summery Report'!#REF! -> #REF! | R9: =N9/B9 -> #DIV/0! | S9: =Q9/B9 -> #REF!
A10: =Gen!B15 -> 44048 | B10: ='Summery Report'!E9 -> 0 | C10: =Gen!U15 -> 1724 | D10: =Gen!T15 -> 776.02 | E10: =Gen!AK15 -> 87.31 | F10: =Gen!AS15 -> 863.33 | G10: ='Utility report '!AC10 -> 56 | H10: ='Utility report '!AE10 -> 21 | I10: ='Water-Meter'!E10 -> 49 | J10: ='Lpg (2)'!B14 -> 85 | K10: ='Lpg (2)'!C14 -> 85 | L10: ='Lpg (2)'!D14 -> 84 | M10: ='Lpg (2)'!G14 -> 31.24 | N10: =D10*1.4 -> 1086.428 | O10: =E10*1.4 -> 122.234 | P10: ='[1]Lpg (2)'!#REF! -> #REF! | Q10: ='[1]Summery Report'!#REF! -> #REF! | R10: =N10/B10 -> #DIV/0! | S10: =Q10/B10 -> #REF!
A11: =Gen!B16 -> 44049 | B11: ='Summery Report'!E10 -> 0 | C11: =Gen!U16 -> 1892 | D11: =Gen!T16 -> 778.12 | E11: =Gen!AK16 -> 52.6 | F11: =Gen!AS16 -> 830.72 | G11: ='Utility report '!AC11 -> 50 | H11: ='Utility report '!AE11 -> 40 | I11: ='Water-Meter'!E11 -> 66 | J11: ='Lpg (2)'!B15 -> 85 | K11: ='Lpg (2)'!C15 -> 85 | L11: ='Lpg (2)'!D15 -> 83 | M11: ='Lpg (2)'!G15 -> 8.448 | N11: =D11*1.4 -> 1089.368 | O11: =E11*1.4 -> 73.64 | P11: ='[1]Lpg (2)'!#REF! -> #REF! | Q11: ='[1]Summery Report'!#REF! -> #REF! | R11: =N11/B11 -> #DIV/0! | S11: =Q11/B11 -> #REF!
A12: =Gen!B17 -> 44050 | B12: ='Summery Report'!E11 -> 0 | C12: =Gen!U17 -> 1882 | D12: =Gen!T17 -> 771.7 | E12: =Gen!AK17 -> 0 | F12: =Gen!AS17 -> 771.7 | G12: ='Utility report '!AC12 -> 55 | H12: ='Utility report '!AE12 -> 38 | I12: ='Water-Meter'!E12 -> 51 | J12: ='Lpg (2)'!B16 -> 85 | K12: ='Lpg (2)'!C16 -> 85 | L12: ='Lpg (2)'!D16 -> 0 | M12: ='Lpg (2)'!G16 -> -316026.96 | N12: =D12*1.4 -> 1080.38 | O12: =E12*1.4 -> 0 | P12: ='[1]Lpg (2)'!#REF! -> #REF! | Q12: ='[1]Summery Report'!#REF! -> #REF! | R12: =N12/B12 -> #DIV/0! | S12: =Q12/B12 -> #REF!
A13: =Gen!B18 -> 44051 | B13: ='Summery Report'!E12 -> 0 | C13: =Gen!U18 -> 0 | D13: =Gen!T18 -> 0 | E13: =Gen!AK18 -> 0 | F13: =Gen!AS18 -> 0 | G13: ='Utility report '!AC13 -> -36392 | H13: ='Utility report '!AE13 -> -203604 | I13: ='Water-Meter'!E13 -> 0 | J13: ='Lpg (2)'!B17 -> 0 | K13: ='Lpg (2)'!C17 -> 0 | L13: ='Lpg (2)'!D17 -> 0 | M13: ='Lpg (2)'!G17 -> 0 | N13: =D13*1.4 -> 0 | O13: =E13*1.4 -> 0 | P13: ='[1]Lpg (2)'!#REF! -> #REF! | Q13: ='[1]Summery Report'!#REF! -> #REF! | R13: =N13/B13 -> #DIV/0! | S13: =Q13/B13 -> #REF!
A14: =Gen!B19 -> 44052 | B14: ='Summery Report'!E13 -> 0 | C14: =Gen!U19 -> 0 | D14: =Gen!T19 -> 0 | E14: =Gen!AK19 -> 0 | F14: =Gen!AS19 -> 0 | G14: ='Utility report '!AC14 -> 0 | H14: ='Utility report '!AE14 -> 0 | I14: ='Water-Meter'!E14 -> 0 | J14: ='Lpg (2)'!B18 -> 0 | K14: ='Lpg (2)'!C18 -> 0 | L14: ='Lpg (2)'!D18 -> 0 | M14: ='Lpg (2)'!G18 -> 0 | N14: =D14*1.4 -> 0 | O14: =E14*1.4 -> 0 | P14: ='[1]Lpg (2)'!#REF! -> #REF! | Q14: ='[1]Summery Report'!#REF! -> #REF! | R14: =N14/B14 -> #DIV/0! | S14: =Q14/B14 -> #REF!
A15: =Gen!B20 -> 44053 | B15: ='Summery Report'!E14 -> 0 | C15: =Gen!U20 -> 0 | D15: =Gen!T20 -> 0 | E15: =Gen!AK20 -> 0 | F15: =Gen!AS20 -> 0 | G15: ='Utility report '!AC15 -> 0 | H15: ='Utility report '!AE15 -> 0 | I15: ='Water-Meter'!E15 -> 0 | J15: ='Lpg (2)'!B19 -> 0 | K15: ='Lpg (2)'!C19 -> 0 | L15: ='Lpg (2)'!D19 -> 0 | M15: ='Lpg (2)'!G19 -> 0 | N15: =D15*1.4 -> 0 | O15: =E15*1.4 -> 0 | P15: ='[1]Lpg (2)'!#REF! -> #REF! | Q15: ='[1]Summery Report'!#REF! -> #REF! | R15: =N15/B15 -> #DIV/0! | S15: =Q15/B15 -> #REF!
A16: =Gen!B21 -> 44054 | B16: ='Summery Report'!E15 -> 0 | C16: =Gen!U21 -> 0 | D16: =Gen!T21 -> 0 | E16: =Gen!AK21 -> 0 | F16: =Gen!AS21 -> 0 | G16: ='Utility report '!AC16 -> 0 | H16: ='Utility report '!AE16 -> 0 | I16: ='Water-Meter'!E16 -> 0 | J16: ='Lpg (2)'!B20 -> 0 | K16: ='Lpg (2)'!C20 -> 0 | L16: ='Lpg (2)'!D20 -> 0 | M16: ='Lpg (2)'!G20 -> 0 | N16: =D16*1.4 -> 0 | O16: =E16*1.4 -> 0 | P16: ='[1]Lpg (2)'!#REF! -> #REF! | Q16: ='[1]Summery Report'!#REF! -> #REF! | R16: =N16/B16 -> #DIV/0! | S16: =Q16/B16 -> #REF!
A17: =Gen!B22 -> 44055 | B17: ='Summery Report'!E16 -> 0 | C17: =Gen!U22 -> 0 | D17: =Gen!T22 -> 0 | E17: =Gen!AK22 -> 0 | F17: =Gen!AS22 -> 0 | G17: ='Utility report '!AC17 -> 0 | H17: ='Utility report '!AE17 -> 0 | I17: ='Water-Meter'!E17 -> 0 | J17: ='Lpg (2)'!B21 -> 0 | K17: ='Lpg (2)'!C22 -> 0 | L17: ='Lpg (2)'!D21 -> 0 | M17: ='Lpg (2)'!G21 -> 0 | N17: =D17*1.4 -> 0 | O17: =E17*1.4 -> 0 | P17: ='[1]Lpg (2)'!#REF! -> #REF! | Q17: ='[1]Summery Report'!#REF! -> #REF! | R17: =N17/B17 -> #DIV/0! | S17: =Q17/B17 -> #REF!
A18: =Gen!B23 -> 44056 | B18: ='Summery Report'!E17 -> 0 | C18: =Gen!U23 -> 0 | D18: =Gen!T23 -> 0 | E18: =Gen!AK23 -> 0 | F18: =Gen!AS23 -> 0 | G18: ='Utility report '!AC18 -> 0 | H18: ='Utility report '!AE18 -> 0 | I18: ='Water-Meter'!E18 -> 0 | J18: ='Lpg (2)'!B22 -> 0 | K18: ='Lpg (2)'!C23 -> 0 | L18: ='Lpg (2)'!D22 -> 0 | M18: ='Lpg (2)'!G22 -> 0 | N18: =D18*1.4 -> 0 | O18: =E18*1.4 -> 0 | P18: ='[1]Lpg (2)'!#REF! -> #REF! | Q18: ='[1]Summery Report'!#REF! -> #REF! | R18: =N18/B18 -> #DIV/0! | S18: =Q18/B18 -> #REF!
A19: =Gen!B24 -> 44057 | B19: ='Summery Report'!E18 -> 0 | C19: =Gen!U24 -> 0 | D19: =Gen!T24 -> 0 | E19: =Gen!AK24 -> 0 | F19: =Gen!AS24 -> 0 | G19: ='Utility report '!AC19 -> 0 | H19: ='Utility report '!AE19 -> 0 | I19: ='Water-Meter'!E19 -> 0 | J19: ='Lpg (2)'!B23 -> 0 | K19: ='Lpg (2)'!C24 -> 0 | L19: ='Lpg (2)'!D23 -> 0 | M19: ='Lpg (2)'!G23 -> 0 | N19: =D19*1.4 -> 0 | O19: =E19*1.4 -> 0 | P19: ='[1]Lpg (2)'!#REF! -> #REF! | Q19: ='[1]Summery Report'!#REF! -> #REF! | R19: =N19/B19 -> #DIV/0! | S19: =Q19/B19 -> #REF!
A20: =Gen!B25 -> 44058 | B20: ='Summery Report'!E19 -> 0 | C20: =Gen!U25 -> 0 | D20: =Gen!T25 -> 0 | E20: =Gen!AK25 -> 0 | F20: =Gen!AS25 -> 0 | G20: ='Utility report '!AC20 -> 0 | H20: ='Utility report '!AE20 -> 0 | I20: ='Water-Meter'!E20 -> 0 | J20: ='Lpg (2)'!B24 -> 0 | K20: ='Lpg (2)'!C25 -> 0 | L20: ='Lpg (2)'!D24 -> 0 | M20: ='Lpg (2)'!G24 -> 0 | N20: =D20*1.4 -> 0 | O20: =E20*1.4 -> 0 | P20: ='[1]Lpg (2)'!#REF! -> #REF! | Q20: ='[1]Summery Report'!#REF! -> #REF! | R20: =N20/B20 -> #DIV/0! | S20: =Q20/B20 -> #REF!
A21: =Gen!B26 -> 44059 | B21: ='Summery Report'!E20 -> 0 | C21: =Gen!U26 -> 0 | D21: =Gen!T26 -> 0 | E21: =Gen!AK26 -> 0 | F21: =Gen!AS26 -> 0 | G21: ='Utility report '!AC21 -> 0 | H21: ='Utility report '!AE21 -> 0 | I21: ='Water-Meter'!E21 -> 0 | J21: ='Lpg (2)'!B25 -> 0 | K21: ='Lpg (2)'!C25 -> 0 | L21: ='Lpg (2)'!D25 -> 0 | M21: ='Lpg (2)'!G25 -> 0 | N21: =D21*1.4 -> 0 | O21: =E21*1.4 -> 0 | P21: ='[1]Lpg (2)'!#REF! -> #REF! | Q21: ='[1]Summery Report'!#REF! -> #REF! | R21: =N21/B21 -> #DIV/0! | S21: =Q21/B21 -> #REF!
A22: =Gen!B27 -> 44060 | B22: ='Summery Report'!E21 -> 0 | C22: =Gen!U27 -> 0 | D22: =Gen!T27 -> 0 | E22: =Gen!AK27 -> 0 | F22: =Gen!AS27 -> 0 | G22: ='Utility report '!AC22 -> 0 | H22: ='Utility report '!AE22 -> 0 | I22: ='Water-Meter'!E22 -> 0 | J22: ='Lpg (2)'!B26 -> 0 | K22: ='Lpg (2)'!C26 -> 0 | L22: ='Lpg (2)'!D26 -> 0 | M22: ='Lpg (2)'!G26 -> 0 | N22: =D22*1.4 -> 0 | O22: =E22*1.4 -> 0 | P22: ='[1]Lpg (2)'!#REF! -> #REF! | Q22: ='[1]Summery Report'!#REF! -> #REF! | R22: =N22/B22 -> #DIV/0! | S22: =Q22/B22 -> #REF!
A23: =Gen!B28 -> 44061 | B23: ='Summery Report'!E22 -> 0 | C23: =Gen!U28 -> 0 | D23: =Gen!T28 -> 0 | E23: =Gen!AK28 -> 0 | F23: =Gen!AS28 -> 0 | G23: ='Utility report '!AC23 -> 0 | H23: ='Utility report '!AE23 -> 0 | I23: ='Water-Meter'!E23 -> 0 | J23: ='Lpg (2)'!B27 -> 0 | K23: ='Lpg (2)'!C27 -> 0 | L23: ='Lpg (2)'!D27 -> 0 | M23: ='Lpg (2)'!G27 -> 0 | N23: =D23*1.4 -> 0 | O23: =E23*1.4 -> 0 | P23: ='[1]Lpg (2)'!#REF! -> #REF! | Q23: ='[1]Summery Report'!#REF! -> #REF! | R23: =N23/B23 -> #DIV/0! | S23: =Q23/B23 -> #REF!
A24: =Gen!B29 -> 44062 | B24: ='Summery Report'!E23 -> 0 | C24: =Gen!U29 -> 0 | D24: =Gen!T29 -> 0 | E24: =Gen!AK29 -> 0 | F24: =Gen!AS29 -> 0 | G24: ='Utility report '!AC24 -> 0 | H24: ='Utility report '!AE24 -> 0 | I24: ='Water-Meter'!E24 -> 0 | J24: ='Lpg (2)'!B28 -> 0 | K24: ='Lpg (2)'!C28 -> 0 | L24: ='Lpg (2)'!D28 -> 0 | M24: ='Lpg (2)'!G28 -> 0 | N24: =D24*1.4 -> 0 | O24: =E24*1.4 -> 0 | P24: ='[1]Lpg (2)'!#REF! -> #REF! | Q24: ='[1]Summery Report'!#REF! -> #REF! | R24: =N24/B24 -> #DIV/0! | S24: =Q24/B24 -> #REF!
A25: =Gen!B30 -> 44063 | B25: ='Summery Report'!E24 -> 0 | C25: =Gen!U30 -> 0 | D25: =Gen!T30 -> 0 | E25: =Gen!AK30 -> 0 | F25: =Gen!AS30 -> 0 | G25: ='Utility report '!AC25 -> 0 | H25: ='Utility report '!AE25 -> 0 | I25: ='Water-Meter'!E25 -> 0 | J25: ='Lpg (2)'!B29 -> 0 | K25: ='Lpg (2)'!C29 -> 0 | L25: ='Lpg (2)'!D29 -> 0 | M25: ='Lpg (2)'!G29 -> 0 | N25: =D25*1.4 -> 0 | O25: =E25*1.4 -> 0 | P25: ='[1]Lpg (2)'!#REF! -> #REF! | Q25: ='[1]Summery Report'!#REF! -> #REF! | R25: =N25/B25 -> #DIV/0! | S25: =Q25/B25 -> #REF!
A26: =Gen!B31 -> 44064 | B26: ='Summery Report'!E25 -> 0 | C26: =Gen!U31 -> 0 | D26: =Gen!T31 -> 0 | E26: =Gen!AK31 -> 0 | F26: =Gen!AS31 -> 0 | G26: ='Utility report '!AC26 -> 0 | H26: ='Utility report '!AE26 -> 0 | I26: ='Water-Meter'!E26 -> 0 | J26: ='Lpg (2)'!B30 -> 0 | K26: ='Lpg (2)'!C30 -> 0 | L26: ='Lpg (2)'!D30 -> 0 | M26: ='Lpg (2)'!G30 -> 0 | N26: =D26*1.4 -> 0 | O26: =E26*1.4 -> 0 | P26: ='[1]Lpg (2)'!#REF! -> #REF! | Q26: ='[1]Summery Report'!#REF! -> #REF! | R26: =N26/B26 -> #DIV/0! | S26: =Q26/B26 -> #REF!
A27: =Gen!B32 -> 44065 | B27: ='Summery Report'!E26 -> 0 | C27: =Gen!U32 -> 0 | D27: =Gen!T32 -> 0 | E27: =Gen!AK32 -> 0 | F27: =Gen!AS32 -> 0 | G27: ='Utility report '!AC27 -> 0 | H27: ='Utility report '!AE27 -> 0 | I27: ='Water-Meter'!E27 -> 0 | J27: ='Lpg (2)'!B31 -> 0 | K27: ='Lpg (2)'!C31 -> 0 | L27: ='Lpg (2)'!D31 -> 0 | M27: ='Lpg (2)'!G31 -> 0 | N27: =D27*1.4 -> 0 | O27: =E27*1.4 -> 0 | P27: ='[1]Lpg (2)'!#REF! -> #REF! | Q27: ='[1]Summery Report'!#REF! -> #REF! | R27: =N27/B27 -> #DIV/0! | S27: =Q27/B27 -> #REF!
A28: =Gen!B33 -> 44066 | B28: ='Summery Report'!E27 -> 0 | C28: =Gen!U33 -> 0 | D28: =Gen!T33 -> 0 | E28: =Gen!AK33 -> 0 | F28: =Gen!AS33 -> 0 | G28: ='Utility report '!AC28 -> 0 | H28: ='Utility report '!AE28 -> 0 | I28: ='Water-Meter'!E28 -> 0 | J28: ='Lpg (2)'!B32 -> 0 | K28: ='Lpg (2)'!C32 -> 0 | L28: ='Lpg (2)'!D32 -> 0 | M28: ='Lpg (2)'!G32 -> 0 | N28: =D28*1.4 -> 0 | O28: =E28*1.4 -> 0 | P28: ='[1]Lpg (2)'!#REF! -> #REF! | Q28: ='[1]Summery Report'!#REF! -> #REF! | R28: =N28/B28 -> #DIV/0! | S28: =Q28/B28 -> #REF!
A29: =Gen!B34 -> 44067 | B29: ='Summery Report'!E28 -> 0 | C29: =Gen!U34 -> 0 | D29: =Gen!T34 -> 0 | E29: =Gen!AK34 -> 0 | F29: =Gen!AS34 -> 0 | G29: ='Utility report '!AC29 -> 0 | H29: ='Utility report '!AE29 -> 0 | I29: ='Water-Meter'!E29 -> 0 | J29: ='Lpg (2)'!B33 -> 0 | K29: ='Lpg (2)'!C33 -> 0 | L29: ='Lpg (2)'!D33 -> 0 | M29: ='Lpg (2)'!G33 -> 0 | N29: =D29*1.4 -> 0 | O29: =E29*1.4 -> 0 | P29: ='[1]Lpg (2)'!#REF! -> #REF! | Q29: ='[1]Summery Report'!#REF! -> #REF! | R29: =N29/B29 -> #DIV/0! | S29: =Q29/B29 -> #REF!
A30: =Gen!B35 -> 44068 | B30: ='Summery Report'!E29 -> 0 | C30: =Gen!U35 -> 0 | D30: =Gen!T35 -> 0 | E30: =Gen!AK35 -> 0 | F30: =Gen!AS35 -> 0 | G30: ='Utility report '!AC30 -> 0 | H30: ='Utility report '!AE30 -> 0 | I30: ='Water-Meter'!E30 -> 0 | J30: ='Lpg (2)'!B34 -> 0 | K30: ='Lpg (2)'!C34 -> 0 | L30: ='Lpg (2)'!D34 -> 0 | M30: ='Lpg (2)'!G34 -> 0 | N30: =D30*1.4 -> 0 | O30: =E30*1.4 -> 0 | P30: ='[1]Lpg (2)'!#REF! -> #REF! | Q30: ='[1]Summery Report'!#REF! -> #REF! | R30: =N30/B30 -> #DIV/0! | S30: =Q30/B30 -> #REF!
A31: =Gen!B36 -> 44069 | B31: ='Summery Report'!E30 -> 0 | C31: =Gen!U36 -> 0 | D31: =Gen!T36 -> 0 | E31: =Gen!AK36 -> 0 | F31: =Gen!AS36 -> 0 | G31: ='Utility report '!AC31 -> 0 | H31: ='Utility report '!AE31 -> 0 | I31: ='Water-Meter'!E31 -> 0 | J31: ='Lpg (2)'!B35 -> 0 | K31: ='Lpg (2)'!C35 -> 0 | L31: ='Lpg (2)'!D35 -> 0 | M31: ='Lpg (2)'!G35 -> 0 | N31: =D31*1.4 -> 0 | O31: =E31*1.4 -> 0 | P31: ='[1]Lpg (2)'!#REF! -> #REF! | Q31: ='[1]Summery Report'!#REF! -> #REF! | R31: =N31/B31 -> #DIV/0! | S31: =Q31/B31 -> #REF!
A32: =Gen!B37 -> 44070 | B32: ='Summery Report'!E31 -> 0 | C32: =Gen!U37 -> 0 | D32: =Gen!T37 -> 0 | E32: =Gen!AK37 -> 0 | F32: =Gen!AS37 -> 0 | G32: ='Utility report '!AC32 -> 0 | H32: ='Utility report '!AE32 -> 0 | I32: ='Water-Meter'!E32 -> 0 | J32: ='Lpg (2)'!B36 -> 0 | K32: ='Lpg (2)'!C36 -> 0 | L32: ='Lpg (2)'!D36 -> 0 | M32: ='Lpg (2)'!G36 -> 0 | N32: =D32*1.4 -> 0 | O32: =E32*1.4 -> 0 | P32: ='[1]Lpg (2)'!#REF! -> #REF! | Q32: ='[1]Summery Report'!#REF! -> #REF! | R32: =N32/B32 -> #DIV/0! | S32: =Q32/B32 -> #REF!
A33: =Gen!B38 -> 44071 | B33: ='Summery Report'!E32 -> 0 | C33: =Gen!U38 -> 0 | D33: =Gen!T38 -> 0 | E33: =Gen!AK38 -> 0 | F33: =Gen!AS38 -> 0 | G33: ='Utility report '!AC33 -> 0 | H33: ='Utility report '!AE33 -> 0 | I33: ='Water-Meter'!E33 -> 0 | J33: ='Lpg (2)'!B37 -> 0 | K33: ='Lpg (2)'!C37 -> 0 | L33: ='Lpg (2)'!D37 -> 0 | M33: ='Lpg (2)'!G37 -> 0 | N33: =D33*1.4 -> 0 | O33: =E33*1.4 -> 0 | P33: ='[1]Lpg (2)'!#REF! -> #REF! | Q33: ='[1]Summery Report'!#REF! -> #REF! | R33: =N33/B33 -> #DIV/0! | S33: =Q33/B33 -> #REF! | T33: =3124/13 -> 240.30769
A34: =Gen!B39 -> 44072 | B34: ='Summery Report'!E33 -> 0 | C34: =Gen!U39 -> 0 | D34: =Gen!T39 -> 0 | E34: =Gen!AK39 -> 0 | F34: =Gen!AS39 -> 0 | G34: ='Utility report '!AC34 -> 0 | H34: ='Utility report '!AE34 -> 0 | I34: ='Water-Meter'!E34 -> 0 | J34: ='Lpg (2)'!B38 -> 0 | K34: ='Lpg (2)'!C38 -> 0 | L34: ='Lpg (2)'!D38 -> 0 | M34: ='Lpg (2)'!G38 -> 0 | N34: =D34*1.4 -> 0 | O34: =E34*1.4 -> 0 | P34: ='[1]Lpg (2)'!#REF! -> #REF! | Q34: ='[1]Summery Report'!#REF! -> #REF! | R34: =N34/B34 -> #DIV/0! | S34: =Q34/B34 -> #REF!
A35: =Gen!B40 -> 44073 | B35: ='Summery Report'!E34 -> 0 | C35: =Gen!U40 -> 0 | D35: =Gen!T40 -> 0 | E35: =Gen!AK40 -> 0 | F35: =Gen!AS40 -> 0 | G35: ='Utility report '!AC35 -> 0 | H35: ='Utility report '!AE35 -> 0 | I35: ='Water-Meter'!E35 -> 0 | J35: ='Lpg (2)'!B39 -> 0 | K35: ='Lpg (2)'!C39 -> 0 | L35: ='Lpg (2)'!D39 -> 0 | M35: ='Lpg (2)'!G39 -> 0 | N35: =D35*1.4 -> 0 | O35: =E35*1.4 -> 0 | P35: ='[1]Lpg (2)'!#REF! -> #REF! | Q35: ='[1]Summery Report'!#REF! -> #REF! | R35: =N35/B35 -> #DIV/0! | S35: =Q35/B35 -> #REF!
A36: =Gen!B41 -> 44074 | B36: ='Summery Report'!E35 -> 0 | C36: =Gen!U41 -> 0 | D36: =Gen!T41 -> 0 | E36: =Gen!AK41 -> 0 | F36: =Gen!AS41 -> 0 | G36: ='Utility report '!AC36 -> 0 | H36: ='Utility report '!AE36 -> 0 | I36: ='Water-Meter'!E36 -> 0 | J36: ='Lpg (2)'!B40 -> 0 | K36: ='Lpg (2)'!C40 -> 0 | L36: ='Lpg (2)'!D40 -> 0 | M36: ='Lpg (2)'!G40 -> 0 | N36: =D36*1.4 -> 0 | O36: =E36*1.4 -> 0 | P36: ='[1]Lpg (2)'!#REF! -> #REF! | Q36: ='[1]Summery Report'!#REF! -> #REF! | R36: =N36/B36 -> #DIV/0! | S36: =Q36/B36 -> #REF!
A37: =Gen!B42 -> 0 | B37: ='Summery Report'!E36 -> 0 | C37: =Gen!U42 -> 0 | D37: =Gen!T42 -> 0 | E37: =Gen!AK42 -> 0 | F37: =Gen!AS42 -> 0 | G37: ='Utility report '!AC37 -> 0 | H37: ='Utility report '!AE37 -> 0 | I37: ='Water-Meter'!E37 -> 0 | J37: ='Lpg (2)'!B41 -> 0 | K37: ='Lpg (2)'!C41 -> 0 | L37: ='Lpg (2)'!D41 -> 0 | M37: ='Lpg (2)'!G41 -> 0 | Q37: ='[1]Summery Report'!#REF! -> #REF! | R37: =N37/B37 -> #DIV/0! | S37: =Q37/B37 -> #REF!
A39: Total | B39: =SUM(B7:B37) -> 0 | C39: =SUM(C7:C35) -> 11326 | D39: =SUM(D7:D35) -> 4689.92 | E39: =SUM(E7:E35) -> 315.08 | F39: =SUM(F7:F35) -> 5005 | G39: =SUM(G7:G35) -> -36020 | H39: =SUM(H7:H35) -> -203368 | I39: =SUM(I7:I35) -> 328 | J39: =SUM(J7:J35) -> 510 | ... S39: =SUM(S7:S35) -> #REF!

Sheet Utility report 
A1: DAILY UTILITY REPORT AUGUST 2020
A2: Date | B2: Total occupancy | H2: Diesel balance LTS | I2: Diesel Deliveries | J2: Gen.Diesel consumption LTS | L2: Total Diesel consumption LTS | M2: Water Meter reading | N2: Water consumption m³ | O2: R.O WATER PRODUCTION LTRS + TIME | AA2: Total RO production | AB2: RO Meter reading | AD2: 0 | AE2: STP | AF2: GAS TANK A | AG2: GAS TANK B | AH2: GAS TANK C | AI2: Total Gas Tanks | AJ2: Kg /day | AK2: TOTAL GAS cons.
A3: Rate Tsh /$ | B3: 1640 | C3: Diesel cost / lits | D3: 2175 | F3: =SUM(D3/B3) -> 1.3262195 | H3: =Gen!D11 -> 41431.87 | K3: Transport consumption | M3: Balance | O3: PLANT NO 1 | S3: PLANT NO 2 | W3: PLANT NO 3 | AA3: /day | AB3: Balance | AC3: Production | AD3: 0 | AE3: Production | AF3: Capacity | AG3: Capacity | AH3: Capacity | AI3: Kg | AJ3: /day | AK3: /day
B4: Rooms OCC | C4: % | D4: Guest Rooms Occ | F4: Electricity Production Cost /Room Occ by guest | G4: All Cost /Room Occ by guest | O4: Flow M3 | P4: Reading Hours Meter | Q4: Hrs | R4: total production M3 | S4: Flow M3 | T4: Reading Hours Meter | U4: Hrs | V4: total production M3 | W4: Flow M3 | X4: READING HOURS METER | Y4: Hrs | Z4: total production M3 | AA4: M3 | AC4: M3 | AE4: M3 | AF4: 2000 | AG4: 1000 | AH4: 1000 | AI4: =SUM([2]Sheet1!$AA$36) -> 950 | AJ4: Kg | AK4: M3
T5: 16713 | AB5: 35942 | AD5: 203320 | AF5: 0.85 | AG5: 0.85 | AH5: 0.85
A6: =Gen!B11 -> 44044 | B6: ='Summery Report'!E5 -> 0 | C6: =Gen!C11 -> 0 | D6: ='Summery Report'!E5 -> 0 | E6: =SUM(F3) -> 1.3262195 | F6: =SUM(J6*E6)/D6 -> #DIV/0! | G6: =SUM(L6*E6)/D6 -> #DIV/0! | H6: =Gen!D11 -> 41431.87 | I6: =Gen!F11 -> 0 | J6: =Gen!T11 -> 741.42 | K6: =Gen!AK11 -> 16.85 | L6: =SUM(J6:K6) -> 758.27 | M6: ='Water-Meter'!K46 -> 349.48762 | N6: ='Water-Meter'!E6 -> 51 | Q6: =SUM(P6-P5) -> 0 | R6: =SUM(Q6*O6) -> 0 | S6: 7.5 | T6: 16725 | U6: =T6-T5 -> 12 | V6: - | Y6: =X6-X5 -> 0 | Z6: =Y6-Y5 -> 0 | AA6: =Z6-Z5 -> 0 | AB6: 36020 | AC6: =AB6-AB5 -> 78 | AD6: 203368 | AE6: =AD6-AD5 -> 48 | AF6: ='Lpg (2)'!B10*2000/85 -> 2000 | AG6: ='Lpg (2)'!C10*1000/85 -> 1000 | AH6: ='Lpg (2)'!D10*1000/85 -> 1000 | AI6: =SUM(AF6*2000)+(AG6*1000)+(AH6*1000) -> 6000000 | AJ6: =SUM(AI5-AI6) -> -6000000
A7: =Gen!B12 -> 44045 | B7: ='Summery Report'!E6 -> 0 | C7: =Gen!C12 -> 0 | D7: ='Summery Report'!E6 -> 0 | E7: =SUM(E6) -> 1.3262195 | F7: =SUM(J7*E7)/D7 -> #DIV/0! | G7: =SUM(L7*E7)/D7 -> #DIV/0! | H7: =Gen!D12 -> 40673.6 | I7: =Gen!F12 -> 0 | J7: =Gen!T12 -> 782.06 | K7: =Gen!AK12 -> 0 | L7: =SUM(J7:K7) -> 782.06 | M7: ='Water-Meter'!K47 -> 388.24985 | N7: ='Water-Meter'!E7 -> 53 | Q7: =SUM(P7-P6) -> 0 | R7: =SUM(Q7*O7) -> 0 | S7: 7.5 | T7: 16749 | U7: =T7-T6 -> 24 | V7: =SUM(U7*S7) -> 180 | Y7: =X7-X6 -> 0 | Z7: =SUM(Y7*W7) -> 0 | AA7: =SUM(Z7*X9) -> 0 | AB7: 36176 | AC7: =AB7-AB6 -> 156 | AD7: 203399 | AE7: =AD7-AD6 -> 31 | AF7: ='Lpg (2)'!B11*2000/85 -> 2000 | AG7: ='Lpg (2)'!C11*1000/85 -> 1000 | AH7: ='Lpg (2)'!D11*1000/85 -> 1000 | AI7: =SUM(AF6*2000)+(AG7*1000)+(AH7*1000) -> 6000000 | AJ7: =SUM(AI6-AI7) -> 0
A8: =Gen!B13 -> 44046 | B8: ='Summery Report'!E7 -> 0 | C8: =Gen!C13 -> 0 | D8: ='Summery Report'!E7 -> 0 | E8: =SUM(E7) -> 1.3262195 | F8: =SUM(J8*E8)/D8 -> #DIV/0! | G8: =SUM(L8*E8)/D8 -> #DIV/0! | H8: =Gen!D13 -> 39891.54 | I8: =Gen!F13 -> 0 | J8: =Gen!T13 -> 788.41 | K8: =Gen!AK13 -> 25.31 | L8: =SUM(J8:K8) -> 813.72 | M8: ='Water-Meter'!K48 -> 442.42456 | N8: ='Water-Meter'!E8 -> 42 | Q8: =SUM(P8-P7) -> 0 | R8: =SUM(Q8*O8) -> 0 | S8: 7.5 | T8: 16749 | U8: =T8-T7 -> 0 | V8: =SUM(U8*S8) -> 0 | Y8: =X8-X7 -> 0 | Z8: =SUM(Y8*W8) -> 0 | AA8: =SUM(Z8*X10) -> 0 | AB8: 36176 | AC8: =AB8-AB7 -> 0 | AD8: 203469 | AE8: =AD8-AD7 -> 70 | AF8: ='Lpg (2)'!B12*2000/85 -> 2000 | AG8: ='Lpg (2)'!C12*1000/85 -> 1000 | AH8: ='Lpg (2)'!D12*1000/85 -> 988.23529 | AI8: =SUM(AF7*2000)+(AG8*1000)+(AH8*1000) -> 5988235.3 | AJ8: =SUM(AI7-AI8) -> 11764.706
A9: =Gen!B14 -> 44047 | B9: ='Summery Report'!E8 -> 0 | C9: =Gen!C14 -> 0 | D9: ='Summery Report'!E8 -> 0 | E9: =SUM(E8) -> 1.3262195 | F9: =SUM(J9*E9)/D9 -> #DIV/0! | G9: =SUM(L9*E9)/D9 -> #DIV/0! | H9: =Gen!D14 -> 39077.82 | I9: =Gen!F14 -> 0 | J9: =Gen!T14 -> 793.61 | K9: =Gen!AK14 -> 149.86 | L9: =SUM(J9:K9) -> 943.47 | M9: ='Water-Meter'!K49 -> 518.61523 | N9: ='Water-Meter'!E9 -> 67 | Q9: =SUM(P9-P8) -> 0 | R9: =SUM(Q9*O9) -> 0 | S9: 7.5 | T9: 16749 | U9: =T9-T8 -> 0 | V9: =SUM(U9*S9) -> 0 | W9: 2.7 | X9: 24606 | Y9: =X9-X8 -> 24606 | Z9: =SUM(Y9*W9) -> 66436.2 | AA9: =SUM(Z9*X11) -> 1.6377852e+09 | AB9: 36231 | AC9: =AB9-AB8 -> 55 | AD9: 203505 | AE9: =AD9-AD8 -> 36 | AF9: ='Lpg (2)'!B13*2000/85 -> 2000 | AG9: ='Lpg (2)'!C13*1000/85 -> 1000 | AH9: ='Lpg (2)'!D13*1000/85 -> 988.23529 | AI9: =SUM(AF8*2000)+(AG9*1000)+(AH9*1000) -> 5988235.3 | AJ9: =SUM(AI8-AI9) -> 0
A10: =Gen!B15 -> 44048 | B10: ='Summery Report'!E9 -> 0 | C10: =Gen!C15 -> 0 | D10: ='Summery Report'!E9 -> 0 | E10: =SUM(E9) -> 1.3262195 | F10: =SUM(J10*E10)/D10 -> #DIV/0! | G10: =SUM(L10*E10)/D10 -> #DIV/0! | H10: =Gen!D15 -> 38134.35 | I10: =Gen!F15 -> 0 | J10: =Gen!T15 -> 776.02 | K10: =Gen!AK15 -> 87.31 | L10: =SUM(J10:K10) -> 863.33 | M10: ='Water-Meter'!K50 -> 579.19289 | N10: ='Water-Meter'!E10 -> 49 | Q10: =SUM(P10-P9) -> 0 | R10: =SUM(Q10*O10) -> 0 | S10: 7.5 | T10: 16749 | U10: =T10-T9 -> 0 | V10: =SUM(U10*S10) -> 0 | W10: 2.7 | X10: 24630 | Y10: =X10-X9 -> 24 | Z10: =SUM(Y10*W10) -> 64.8 | AA10: =SUM(Z10*X12) -> 1599004.8 | AB10: 36287 | AC10: =AB10-AB9 -> 56 | AD10: 203526 | AE10: =AD10-AD9 -> 21 | AF10: ='Lpg (2)'!B14*2000/85 -> 2000 | AG10: ='Lpg (2)'!C14*1000/85 -> 1000 | AH10: ='Lpg (2)'!D14*1000/85 -> 988.23529 | AI10: =SUM(AF9*2000)+(AG10*1000)+(AH10*1000) -> 5988235.3 | AJ10: =SUM(AI9-AI10) -> 0
A11: =Gen!B16 -> 44049 | B11: ='Summery Report'!E10 -> 0 | C11: =Gen!C16 -> 0 | D11: ='Summery Report'!E10 -> 0 | E11: =SUM(E10) -> 1.3262195 | F11: =SUM(J11*E11)/D11 -> #DIV/0! | G11: =SUM(L11*E11)/D11 -> #DIV/0! | H11: =Gen!D16 -> 37271.02 | I11: =Gen!F16 -> 0 | J11: =Gen!T16 -> 778.12 | K11: =Gen!AK16 -> 52.6 | L11: =SUM(J11:K11) -> 830.72 | M11: ='Water-Meter'!K51 -> 588.89159 | N11: ='Water-Meter'!E11 -> 66 | Q11: =SUM(P11-P10) -> 0 | R11: =SUM(Q11*O11) -> 0 | S11: 7.5 | T11: 16749 | U11: =T11-T10 -> 0 | V11: =SUM(U11*S11) -> 0 | W11: 2.7 | X11: 24652 | Y11: =X11-X10 -> 22 | Z11: =SUM(Y11*W11) -> 59.4 | AA11: =SUM(Z11*X13) -> 0 | AB11: 36337 | AC11: =AB11-AB10 -> 50 | AD11: 203566 | AE11: =AD11-AD10 -> 40 | AF11: ='Lpg (2)'!B15*2000/85 -> 2000 | AG11: ='Lpg (2)'!C15*1000/85 -> 1000 | AH11: ='Lpg (2)'!D15*1000/85 -> 976.47059 | AI11: =SUM(AF10*2000)+(AG11*1000)+(AH11*1000) -> 5976470.6 | AJ11: =SUM(AI10-AI11) -> 11764.706
A12: =Gen!B17 -> 44050 | B12: ='Summery Report'!E11 -> 0 | C12: =Gen!C17 -> 0 | D12: ='Summery Report'!E11 -> 0 | E12: =SUM(E11) -> 1.3262195 | F12: =SUM(J12*E12)/D12 -> #DIV/0! | G12: =SUM(L12*E12)/D12 -> #DIV/0! | H12: =Gen!D17 -> 36440.3 | I12: =Gen!F17 -> 0 | J12: =Gen!T17 -> 771.7 | K12: =Gen!AK17 -> 0 | L12: =SUM(J12:K12) -> 771.7 | M12: ='Water-Meter'!K52 -> 571.60065 | N12: ='Water-Meter'!E12 -> 51 | Q12: =SUM(P12-P11) -> 0 | R12: =SUM(Q12*O12) -> 0 | S12: 7.5 | T12: 16749 | U12: =T12-T11 -> 0 | V12: =SUM(U12*S12) -> 0 | W12: 2.7 | X12: 24676 | Y12: =X12-X11 -> 24 | Z12: =SUM(Y12*W12) -> 64.8 | AA12: =SUM(Z12*X14) -> 0 | AB12: 36392 | AC12: =AB12-AB11 -> 55 | AD12: 203604 | AE12: =AD12-AD11 -> 38 | AF12: ='Lpg (2)'!B16*2000/85 -> 2000 | AG12: ='Lpg (2)'!C16*1000/85 -> 1000 | AH12: ='Lpg (2)'!D16*1000/85 -> 0 | AI12: =SUM(AF11*2000)+(AG12*1000)+(AH12*1000) -> 5000000 | AJ12: =SUM(AI11-AI12) -> 976470.59
A13: =Gen!B18 -> 44051 | B13: ='Summery Report'!E12 -> 0 | C13: =Gen!C18 -> 0 | D13: ='Summery Report'!E12 -> 0 | E13: =SUM(E12) -> 1.3262195 | F13: =SUM(J13*E13)/D13 -> #DIV/0! | G13: =SUM(L13*E13)/D13 -> #DIV/0! | H13: =Gen!D18 -> 35668.6 | I13: =Gen!F18 -> 0 | J13: =Gen!T18 -> 0 | K13: =Gen!AK18 -> 0 | L13: =SUM(J13:K13) -> 0 | M13: ='Water-Meter'!K53 -> 574.56424 | N13: ='Water-Meter'!E13 -> 0 | Q13: =SUM(P13-P12) -> 0 | R13: =SUM(Q13*O13) -> 0 | U13: =T13-T12 -> -16749 | V13: =SUM(U13*S13) -> 0 | Y13: =X13-X12 -> -24676 | Z13: =SUM(Y13*W13) -> 0 | AA13: =SUM(Z13*X15) -> 0 | AC13: =AB13-AB12 -> -36392 | AE13: =AD13-AD12 -> -203604 | AF13: ='Lpg (2)'!B17*2000/85 -> 0 | AG13: ='Lpg (2)'!C17*1000/85 -> 0 | AH13: ='Lpg (2)'!D17*1000/85 -> 0 | AI13: =SUM(AF12*2000)+(AG13*1000)+(AH13*1000) -> 4000000 | AJ13: =SUM(AI12-AI13) -> 1000000
A14: =Gen!B19 -> 44052 | B14: ='Summery Report'!E13 -> 0 | C14: =Gen!C19 -> 0 | D14: ='Summery Report'!E13 -> 0 | E14: =SUM(E13) -> 1.3262195 | F14: =SUM(J14*E14)/D14 -> #DIV/0! | G14: =SUM(L14*E14)/D14 -> #DIV/0! | H14: =Gen!D19 -> 35668.6 | I14: =Gen!F19 -> 0 | J14: =Gen!T19 -> 0 | K14: =Gen!AK19 -> 0 | L14: =SUM(J14:K14) -> 0 | M14: ='Water-Meter'!K54 -> 0 | N14: ='Water-Meter'!E14 -> 0 | Q14: =SUM(P14-P13) -> 0 | R14: =SUM(Q14*O14) -> 0 | U14: =T14-T13 -> 0 | V14: =SUM(U14*S14) -> 0 | Y14: =X14-X13 -> 0 | Z14: =SUM(Y14*W14) -> 0 | AA14: =SUM(Z14*X16) -> 0 | AC14: =AB14-AB13 -> 0 | AE14: =AD14-AD13 -> 0 | AF14: ='Lpg (2)'!B18*2000/85 -> 0 | AG14: ='Lpg (2)'!C18*1000/85 -> 0 | AH14: ='Lpg (2)'!D18*1000/85 -> 0 | AI14: =SUM(AF13*2000)+(AG14*1000)+(AH14*1000) -> 0 | AJ14: =SUM(AI13-AI14) -> 4000000
A15: =Gen!B20 -> 44053 | B15: ='Summery Report'!E14 -> 0 | C15: =Gen!C20 -> 0 | D15: ='Summery Report'!E14 -> 0 | E15: =SUM(E14) -> 1.3262195 | F15: =SUM(J15*E15)/D15 -> #DIV/0! | G15: =SUM(L15*E15)/D15 -> #DIV/0! | H15: =Gen!D20 -> 35668.6 | I15: =Gen!F20 -> 0 | J15: =Gen!T20 -> 0 | K15: =Gen!AK20 -> 0 | L15: =SUM(J15:K15) -> 0 | M15: ='Water-Meter'!K55 -> 0 | N15: ='Water-Meter'!E15 -> 0 | Q15: =SUM(P15-P14) -> 0 | R15: =SUM(Q15*O15) -> 0 | U15: =T15-T14 -> 0 | V15: =SUM(U15*S15) -> 0 | Y15: =X15-X14 -> 0 | Z15: =SUM(Y15*W15) -> 0 | AA15: =SUM(Z15*X17) -> 0 | AC15: =AB15-AB14 -> 0 | AE15: =AD15-AD14 -> 0 | AF15: ='Lpg (2)'!B19*2000/85 -> 0 | AG15: ='Lpg (2)'!C19*1000/85 -> 0 | AH15: ='Lpg (2)'!D19*1000/85 -> 0 | AI15: =SUM(AF15*2000)+(AG15*1000)+(AH15*1000) -> 0 | AJ15: =SUM(AI14-AI15) -> 0
A16: =Gen!B21 -> 44054 | B16: ='Summery Report'!E15 -> 0 | C16: =Gen!C21 -> 0 | D16: ='Summery Report'!E15 -> 0 | E16: =SUM(E15) -> 1.3262195 | F16: =SUM(J16*E16)/D16 -> #DIV/0! | G16: =SUM(L16*E16)/D16 -> #DIV/0! | H16: =Gen!D21 -> 35668.6 | I16: =Gen!F21 -> 0 | J16: =Gen!T21 -> 0 | K16: =Gen!AK21 -> 0 | L16: =SUM(J16:K16) -> 0 | M16: ='Water-Meter'!K56 -> 0 | N16: ='Water-Meter'!E16 -> 0 | Q16: =SUM(P16-P15) -> 0 | R16: =SUM(Q16*O16) -> 0 | U16: =T16-T15 -> 0 | V16: =SUM(U16*S16) -> 0 | Y16: =X16-X15 -> 0 | Z16: =SUM(Y16*W16) -> 0 | AA16: =SUM(Z16*X18) -> 0 | AC16: =AB16-AB15 -> 0 | AE16: =AD16-AD15 -> 0 | AF16: ='Lpg (2)'!B20*2000/85 -> 0 | AG16: ='Lpg (2)'!C20*1000/85 -> 0 | AH16: ='Lpg (2)'!D20*1000/85 -> 0 | AI16: =SUM(AF16*2000)+(AG16*1000)+(AH16*1000) -> 0 | AJ16: =SUM(AI15-AI16) -> 0
A17: =Gen!B22 -> 44055 | B17: ='Summery Report'!E16 -> 0 | C17: =Gen!C22 -> 0 | D17: ='Summery Report'!E16 -> 0 | E17: =SUM(E16) -> 1.3262195 | F17: =SUM(J17*E17)/D17 -> #DIV/0! | G17: =SUM(L17*E17)/D17 -> #DIV/0! | H17: =Gen!D22 -> 35668.6 | I17: =Gen!F22 -> 0 | J17: =Gen!T22 -> 0 | K17: =Gen!AK22 -> 0 | L17: =SUM(J17:K17) -> 0 | M17: ='Water-Meter'!K57 -> 0 | N17: ='Water-Meter'!E17 -> 0 | Q17: =SUM(P18-P16) -> 0 | R17: =SUM(Q17*O17) -> 0 | U17: =T17-T16 -> 0 | V17: =SUM(U17*S17) -> 0 | Y17: =X17-X16 -> 0 | Z17: =SUM(Y17*W17) -> 0 | AA17: =SUM(Z17*X19) -> 0 | AC17: =AB17-AB16 -> 0 | AE17: =AD17-AD16 -> 0 | AF17: ='Lpg (2)'!B21*2000/85 -> 0 | AG17: ='Lpg (2)'!C21*1000/85 -> 0 | AH17: ='Lpg (2)'!D21*1000/85 -> 0 | AI17: =SUM(AF17*2000)+(AG17*1000)+(AH17*1000) -> 0 | AJ17: =SUM(AI16-AI17) -> 0
A18: =Gen!B23 -> 44056 | B18: ='Summery Report'!E17 -> 0 | C18: =Gen!C23 -> 0 | D18: ='Summery Report'!E17 -> 0 | E18: =SUM(E17) -> 1.3262195 | F18: =SUM(J18*E18)/D18 -> #DIV/0! | G18: =SUM(L18*E18)/D18 -> #DIV/0! | H18: =Gen!D23 -> 35668.6 | I18: =Gen!F23 -> 0 | J18: =Gen!T23 -> 0 | K18: =Gen!AK23 -> 0 | L18: =SUM(J18:K18) -> 0 | M18: ='Water-Meter'!K58 -> 0 | N18: ='Water-Meter'!E18 -> 0 | R18: =SUM(Q18*O18) -> 0 | U18: =T18-T17 -> 0 | V18: =SUM(U18*S18) -> 0 | Y18: =X18-X17 -> 0 | Z18: =SUM(Y18*W18) -> 0 | AA18: =SUM(Z18*X20) -> 0 | AC18: =AB18-AB17 -> 0 | AE18: =AD18-AD17 -> 0 | AF18: ='Lpg (2)'!B22*2000/85 -> 0 | AG18: ='Lpg (2)'!C22*1000/85 -> 0 | AH18: ='Lpg (2)'!D22*1000/85 -> 0 | AI18: =SUM(AF18*2000)+(AG18*1000)+(AH18*1000) -> 0 | AJ18: =SUM(AI17-AI18) -> 0
A19: =Gen!B24 -> 44057 | B19: ='Summery Report'!E18 -> 0 | C19: =Gen!C24 -> 0 | D19: ='Summery Report'!E18 -> 0 | E19: =SUM(E18) -> 1.3262195 | F19: =SUM(J19*E19)/D19 -> #DIV/0! | G19: =SUM(L19*E19)/D19 -> #DIV/0! | H19: =Gen!D24 -> 35668.6 | I19: =Gen!F24 -> 18000 | J19: =Gen!T24 -> 0 | K19: =Gen!AK24 -> 0 | L19: =SUM(J19:K19) -> 0 | M19: ='Water-Meter'!K59 -> 0 | N19: ='Water-Meter'!E19 -> 0 | R19: =SUM(Q19*O19) -> 0 | U19: =T19-T18 -> 0 | V19: =SUM(U19*S19) -> 0 | Y19: =X19-X18 -> 0 | Z19: =SUM(Y19*W19) -> 0 | AA19: =SUM(Z19*X21) -> 0 | AE19: =AD19-AD18 -> 0 | AF19: ='Lpg (2)'!B23*2000/85 -> 0 | AG19: ='Lpg (2)'!C23*1000/85 -> 0 | AH19: ='Lpg (2)'!D23*1000/85 -> 0 | AI19: =SUM(AF19*2000)+(AG19*1000)+(AH19*1000) -> 0 | AJ19: =SUM(AI18-AI19) -> 0
A20: =Gen!B25 -> 44058 | B20: ='Summery Report'!E19 -> 0 | C20: =Gen!C25 -> 0 | D20: ='Summery Report'!E19 -> 0 | E20: =SUM(E19) -> 1.3262195 | F20: =SUM(J20*E20)/D20 -> #DIV/0! | G20: =SUM(L20*E20)/D20 -> #DIV/0! | H20: =Gen!D25 -> 35668.6 | I20: =Gen!F25 -> 0 | J20: =Gen!T25 -> 0 | K20: =Gen!AK25 -> 0 | L20: =SUM(J20:K20) -> 0 | M20: ='Water-Meter'!K60 -> 0 | N20: ='Water-Meter'!E20 -> 0 | Q20: =SUM(P20-P19) -> 0 | R20: =SUM(Q20*O20) -> 0 | U20: =T20-T19 -> 0 | V20: =SUM(U20*S20) -> 0 | Y20: =X20-X19 -> 0 | Z20: =SUM(Y20*W20) -> 0 | AA20: =SUM(Z20*X22) -> 0 | AC20: =AB20-AB19 -> 0 | AE20: =AD20-AD19 -> 0 | AF20: ='Lpg (2)'!B24*2000/85 -> 0 | AG20: ='Lpg (2)'!C24*1000/85 -> 0 | AH20: ='Lpg (2)'!D24*1000/85 -> 0 | AI20: =SUM(AF20*2000)+(AG20*1000)+(AH20*1000) -> 0 | AJ20: =SUM(AI19-AI20) -> 0
A21: =Gen!B26 -> 44059 | B21: ='Summery Report'!E20 -> 0 | C21: =Gen!C26 -> 0 | D21: ='Summery Report'!E20 -> 0 | E21: =SUM(E20) -> 1.3262195 | F21: =SUM(J21*E21)/D21 -> #DIV/0! | G21: =SUM(L21*E21)/D21 -> #DIV/0! | H21: =Gen!D26 -> 35668.6 | I21: =Gen!F26 -> 0 | J21: =Gen!T26 -> 0 | K21: =Gen!AK26 -> 0 | L21: =SUM(J21:K21) -> 0 | M21: ='Water-Meter'!K61 -> 0 | N21: ='Water-Meter'!E21 -> 0 | Q21: =SUM(P21-P20) -> 0 | R21: =SUM(Q21*O21) -> 0 | U21: =T22-T20 -> 0 | V21: =SUM(U21*S21) -> 0 | Y21: =X21-X20 -> 0 | Z21: =SUM(Y21*W21) -> 0 | AA21: =SUM(Z21*X23) -> 0 | AC21: =AB21-AB20 -> 0 | AE21: =AD21-AD20 -> 0 | AF21: ='Lpg (2)'!B25*2000/85 -> 0 | AG21: ='Lpg (2)'!C25*1000/85 -> 0 | AH21: ='Lpg (2)'!D25*1000/85 -> 0 | AI21: =SUM(AF21*2000)+(AG21*1000)+(AH21*1000) -> 0 | AJ21: =SUM(AI20-AI21) -> 0
A22: =Gen!B27 -> 44060 | B22: ='Summery Report'!E21 -> 0 | C22: =Gen!C27 -> 0 | D22: ='Summery Report'!E21 -> 0 | E22: =SUM(E21) -> 1.3262195 | F22: =SUM(J22*E22)/D22 -> #DIV/0! | G22: =SUM(L22*E22)/D22 -> #DIV/0! | H22: =Gen!D27 -> 35668.6 | I22: =Gen!F27 -> 0 | J22: =Gen!T27 -> 0 | K22: =Gen!AK27 -> 0 | L22: =SUM(J22:K22) -> 0 | M22: ='Water-Meter'!K62 -> 0 | N22: ='Water-Meter'!E22 -> 0 | Q22: =SUM(P22-P21) -> 0 | R22: =SUM(Q22*O22) -> 0 | U22: =T23-T21 -> 0 | V22: =SUM(U22*S22) -> 0 | Y22: =X22-X21 -> 0 | Z22: =SUM(Y22*W22) -> 0 | AA22: =SUM(Z22*X24) -> 0 | AC22: =AB22-AB21 -> 0 | AE22: =AD22-AD21 -> 0 | AF22: ='Lpg (2)'!B26*2000/85 -> 0 | AG22: ='Lpg (2)'!C26*1000/85 -> 0 | AH22: ='Lpg (2)'!D26*1000/85 -> 0 | AI22: =SUM(AF22*2000)+(AG22*1000)+(AH22*1000) -> 0 | AJ22: =SUM(AI21-AI22) -> 0
