Workbook

Sheet Total
A1: Site Name | B1: Day | C1: Month | D1: Year | E1: Total Electricity Kwh | F1: Electricity Tariff ($/Kwh) | G1: Total Fuel Oil (Liters) | H1: Fuel Oil $/Liter | I1: LPG (Kg) | J1: LPG $/Kg | K1: Water Utility Supply (m3) m3 | L1: Water Utility Supply (m3) $/m3 | M1: Irrigation Water (m3) m3 | N1: Irrigation water $/m3 | O1: Room Nights
A2: Beirut | B2: 1 | C2: 8 | D2: 2020 | E2: =ELEC!N3 -> 25351 | F2: =SUM('EDl log'!T4) -> 0.14031446 | G2: =-tanks!AW6 -> 380 | H2: =SUM(tanks!AV6) -> 0.5383 | I2: =('B5'!AU5)*0.51 -> 76.5 | J2: ='B5'!AX5/0.51 -> 1.5686275 | K2: =WATER!I6 -> 494 | L2: =SUM(WATER!J6) -> 0.69808802 | M2: =WATER!Q6 -> 0 | N2: 0.6 | O2: =ELEC!B3 -> 89.01
A3: Beirut | B3: =B2+1 -> 2 | C3: 8 | D3: 2020 | E3: =ELEC!N4 -> 24732 | F3: =SUM('EDl log'!T5) -> 0.092087922 | G3: =-tanks!AW7 -> 229 | H3: =SUM(tanks!AV7) -> 0.5383 | I3: =('B5'!AU6)*0.51 -> 183.6 | J3: ='B5'!AX6/0.51 -> 1.5686275 | K3: =WATER!I7 -> 0 | L3: =SUM(WATER!J7) -> 0 | M3: =WATER!Q7 -> 0 | N3: 0.6 | O3: =ELEC!B4 -> 77.993
A4: Beirut | B4: =B3+1 -> 3 | C4: 8 | D4: 2020 | E4: =ELEC!N5 -> 23757 | F4: =SUM('EDl log'!T6) -> 0.097640186 | G4: =-tanks!AW8 -> 680 | H4: =SUM(tanks!AV8) -> 0.54 | I4: =('B5'!AU7)*0.51 -> 183.6 | J4: ='B5'!AX7/0.51 -> 1.5686275 | K4: =WATER!I8 -> 366 | L4: =SUM(WATER!J8) -> 0.66102591 | M4: =WATER!Q8 -> 0 | N4: 0.6 | O4: =ELEC!B5 -> 69
A5: Beirut | B5: =B4+1 -> 4 | C5: 8 | D5: 2020 | E5: =ELEC!N6 -> 25244 | F5: =SUM('EDl log'!T7) -> 0.05481389 | G5: =-tanks!AW9 -> 0 | H5: =SUM(tanks!AV9) -> 0.54 | I5: =('B5'!AU8)*0.51 -> 0 | J5: ='B5'!AX8/0.51 -> 1.5686275 | K5: =WATER!I9 -> 0 | L5: =SUM(WATER!J9) -> 0 | M5: =WATER!Q9 -> 0 | N5: 0.6 | O5: =ELEC!B6 -> 0
A6: Beirut | B6: =B5+1 -> 5 | C6: 8 | D6: 2020 | E6: =ELEC!N7 -> 10988 | F6: =SUM('EDl log'!T8) -> 0.25447665 | G6: =-tanks!AW10 -> 144 | H6: =SUM(tanks!AV10) -> 0.54 | I6: =('B5'!AU9)*0.51 -> 0 | J6: ='B5'!AX9/0.51 -> 1.5686275 | K6: =WATER!I10 -> 172 | L6: =SUM(WATER!J10) -> 2.0049737 | M6: =WATER!Q10 -> 0 | N6: 0.6 | O6: =ELEC!B7 -> 0
A7: Beirut | B7: =B6+1 -> 6 | C7: 8 | D7: 2020 | E7: =ELEC!N8 -> 10699 | F7: =SUM('EDl log'!T9) -> 0.05068698 | G7: =-tanks!AW11 -> 0 | H7: =SUM(tanks!AV11) -> 0.54 | I7: =('B5'!AU10)*0.51 -> 0 | J7: ='B5'!AX10/0.51 -> 1.5686275 | K7: =WATER!I11 -> 0 | L7: =SUM(WATER!J11) -> 0 | M7: =WATER!Q11 -> 0 | N7: 0.6 | O7: =ELEC!B8 -> 0
A8: Beirut | B8: =B7+1 -> 7 | C8: 8 | D8: 2020 | E8: =ELEC!N9 -> 9781 | F8: =SUM('EDl log'!T10) -> -0.054155968 | G8: =-tanks!AW12 -> 0 | H8: =SUM(tanks!AV12) -> 0.535 | I8: =('B5'!AU11)*0.51 -> 0 | J8: ='B5'!AX11/0.51 -> 1.5686275 | K8: =WATER!I12 -> 0 | L8: =SUM(WATER!J12) -> 0 | M8: =WATER!Q12 -> 0 | N8: 0.6 | O8: =ELEC!B9 -> 0
A9: Beirut | B9: =B8+1 -> 8 | C9: 8 | D9: 2020 | E9: =ELEC!N10 -> 10647 | F9: =SUM('EDl log'!T11) -> 0.10342312 | G9: =-tanks!AW13 -> 0 | H9: =SUM(tanks!AV13) -> 0.535 | I9: =('B5'!AU12)*0.51 -> 0 | J9: ='B5'!AX12/0.51 -> 1.5686275 | K9: =WATER!I13 -> 0 | L9: =SUM(WATER!J13) -> 0 | M9: =WATER!Q13 -> 0 | N9: 0.6 | O9: =ELEC!B10 -> 0
A10: Beirut | B10: =B9+1 -> 9 | C10: 8 | D10: 2020 | E10: =ELEC!N11 -> 8400 | F10: =SUM('EDl log'!T12) -> 0.086638155 | G10: =-tanks!AW14 -> 0 | H10: =SUM(tanks!AV14) -> 0.535 | I10: =('B5'!AU13)*0.51 -> 0 | J10: ='B5'!AX13/0.51 -> 1.5686275 | K10: =WATER!I14 -> 0 | L10: =SUM(WATER!J14) -> 0 | M10: =WATER!Q14 -> 0 | N10: 0.6 | O10: =ELEC!B11 -> 0
A11: Beirut | B11: =B10+1 -> 10 | C11: 8 | D11: 2020 | E11: =ELEC!N12 -> 10457 | F11: =SUM('EDl log'!T13) -> 0.072990145 | G11: =-tanks!AW15 -> 0 | H11: =SUM(tanks!AV15) -> 0.535 | I11: =('B5'!AU14)*0.51 -> 0 | J11: ='B5'!AX14/0.51 -> 1.5686275 | K11: =WATER!I15 -> 0 | L11: =SUM(WATER!J15) -> 0 | M11: =WATER!Q15 -> 0 | N11: 0.6 | O11: =ELEC!B12 -> 0
A12: Beirut | B12: =B11+1 -> 11 | C12: 8 | D12: 2020 | E12: =ELEC!N13 -> 10265 | F12: =SUM('EDl log'!T14) -> 0.074713175 | G12: =-tanks!AW16 -> 115.2 | H12: =SUM(tanks!AV16) -> 0.535 | I12: =('B5'!AU15)*0.51 -> 0 | J12: ='B5'!AX15/0.51 -> 1.5686275 | K12: =WATER!I16 -> 0 | L12: =SUM(WATER!J16) -> 0 | M12: =WATER!Q16 -> 0 | N12: 0.6 | O12: =ELEC!B13 -> 0
A13: Beirut | B13: =B12+1 -> 12 | C13: 8 | D13: 2020 | E13: =ELEC!N14 -> 10779 | F13: =SUM('EDl log'!T15) -> 0.13059941 | G13: =-tanks!AW17 -> 0 | H13: =SUM(tanks!AV17) -> 0.535 | I13: =('B5'!AU16)*0.51 -> 0 | J13: ='B5'!AX16/0.51 -> 1.5686275 | K13: =WATER!I17 -> 0 | L13: =SUM(WATER!J17) -> 0 | M13: =WATER!Q17 -> 0 | N13: 0.6 | O13: =ELEC!B14 -> 0
A14: Beirut | B14: =B13+1 -> 13 | C14: 8 | D14: 2020 | E14: =ELEC!N15 -> 11455 | F14: =SUM('EDl log'!T16) -> 0.039500481 | G14: =-tanks!AW18 -> 0 | H14: =SUM(tanks!AV18) -> 0.535 | I14: =('B5'!AU17)*0.51 -> 0 | J14: ='B5'!AX17/0.51 -> 1.5686275 | K14: =WATER!I18 -> 0 | L14: =SUM(WATER!J18) -> 0 | M14: =WATER!Q18 -> 0 | N14: 0.6 | O14: =ELEC!B15 -> 0
... A32: Beirut | B32: =B31+1 -> 31 | C32: 8 | D32: 2020 | E32: =ELEC!N33 -> 0 | F32: =SUM('EDl log'!T34) -> 0 | G32: =-tanks!AW36 -> 0 | H32: =SUM(tanks!AV36) -> 0.535 | I32: =('B5'!AU35)*0.51 -> 0 | J32: ='B5'!AX35/0.51 -> 1.5686275 | K32: =WATER!I36 -> 0 | L32: =SUM(WATER!J36) -> 0 | M32: =WATER!Q36 -> 0 | N32: 0.6 | O32: =ELEC!B33 -> 0

Sheet Submetering
A1: Site Name | B1: Day | C1: Month | D1: Year | E1: ATS1 Kwh | F1: ATS2 Kwh | G1: ATS3 Kwh | H1: ATS4 Kwh | I1: ATS5 Kwh | J1: Guest (m3) | K1: Kitchen & Laundry (m3) | L1: Room Nights
A2: Beirut | B2: 1 | C2: 8 | D2: 2020 | E2: =ELEC!M3 -> 6992 | F2: =ELEC!K3 -> 7022 | G2: =ELEC!I3 -> 3104 | H2: =ELEC!E3 -> 5596 | I2: =ELEC!G3 -> 2637 | J2: =WATER!Y6 -> 73 | K2: =WATER!AJ6 -> 30 | L2: =ELEC!B3 -> 89.01
A3: Beirut | B3: =B2+1 -> 2 | C3: 8 | D3: 2020 | E3: =ELEC!M4 -> 10480 | F3: =ELEC!K4 -> 3280 | G3: =ELEC!I4 -> 3214 | H3: =ELEC!E4 -> 5232 | I3: =ELEC!G4 -> 2526 | J3: =WATER!Y7 -> 53 | K3: =WATER!AJ7 -> 32 | L3: =ELEC!B4 -> 77.993
A4: Beirut | B4: =B3+1 -> 3 | C4: 8 | D4: 2020 | E4: =ELEC!M5 -> 6864 | F4: =ELEC!K5 -> 2790 | G4: =ELEC!I5 -> 2934 | H4: =ELEC!E5 -> 8820 | I4: =ELEC!G5 -> 2349 | J4: =WATER!Y8 -> 104 | K4: =WATER!AJ8 -> 81 | L4: =ELEC!B5 -> 69
A5: Beirut | B5: =B4+1 -> 4 | C5: 8 | D5: 2020 | E5: =ELEC!M6 -> 7014 | F5: =ELEC!K6 -> 2520 | G5: =ELEC!I6 -> 3692 | H5: =ELEC!E6 -> 9186 | I5: =ELEC!G6 -> 2832 | J5: =WATER!Y9 -> 0 | K5: =WATER!AJ9 -> 0 | L5: =ELEC!B6 -> 0
A6: Beirut | B6: =B5+1 -> 5 | C6: 8 | D6: 2020 | E6: =ELEC!M7 -> 3062 | F6: =ELEC!K7 -> 3352 | G6: =ELEC!I7 -> 1178 | H6: =ELEC!E7 -> 2654 | I6: =ELEC!G7 -> 742 | J6: =WATER!Y10 -> 13 | K6: =WATER!AJ10 -> 22 | L6: =ELEC!B7 -> 0
A7: Beirut | B7: =B6+1 -> 6 | C7: 8 | D7: 2020 | E7: =ELEC!M8 -> 4204 | F7: =ELEC!K8 -> 1578 | G7: =ELEC!I8 -> 1120 | H7: =ELEC!E8 -> 2690 | I7: =ELEC!G8 -> 1107 | J7: =WATER!Y11 -> 0 | K7: =WATER!AJ11 -> 0 | L7: =ELEC!B8 -> 0
A8: Beirut | B8: =B7+1 -> 7 | C8: 8 | D8: 2020 | E8: =ELEC!M9 -> 4188 | F8: =ELEC!K9 -> 734 | G8: =ELEC!I9 -> 1028 | H8: =ELEC!E9 -> 2926 | I8: =ELEC!G9 -> 905 | J8: =WATER!Y12 -> 70 | K8: =WATER!AJ12 -> 40 | L8: =ELEC!B9 -> 0
A9: Beirut | B9: =B8+1 -> 8 | C9: 8 | D9: 2020 | E9: =ELEC!M10 -> 1858 | F9: =ELEC!K10 -> 1112 | G9: =ELEC!I10 -> 1114 | H9: =ELEC!E10 -> 5800 | I9: =ELEC!G10 -> 763 | J9: =WATER!Y13 -> 76 | K9: =WATER!AJ13 -> 32 | L9: =ELEC!B10 -> 0
A10: Beirut | B10: =B9+1 -> 9 | C10: 8 | D10: 2020 | E10: =ELEC!M11 -> 3154 | F10: =ELEC!K11 -> 800 | G10: =ELEC!I11 -> 1070 | H10: =ELEC!E11 -> 2524 | I10: =ELEC!G11 -> 852 | J10: =WATER!Y14 -> 125 | K10: =WATER!AJ14 -> 1 | L10: =ELEC!B11 -> 0
A11: Beirut | B11: =B10+1 -> 10 | C11: 8 | D11: 2020 | E11: =ELEC!M12 -> 2050 | F11: =ELEC!K12 -> 1056 | G11: =ELEC!I12 -> 1090 | H11: =ELEC!E12 -> 5508 | I11: =ELEC!G12 -> 753 | J11: =WATER!Y15 -> 100 | K11: =WATER!AJ15 -> 51 | L11: =ELEC!B12 -> 0
A12: Beirut | B12: =B11+1 -> 11 | C12: 8 | D12: 2020 | E12: =ELEC!M13 -> 3870 | F12: =ELEC!K13 -> 1468 | G12: =ELEC!I13 -> 1200 | H12: =ELEC!E13 -> 2784 | I12: =ELEC!G13 -> 943 | J12: =WATER!Y16 -> 29 | K12: =WATER!AJ16 -> 11 | L12: =ELEC!B13 -> 0
A13: Beirut | B13: =B12+1 -> 12 | C13: 8 | D13: 2020 | E13: =ELEC!M14 -> 4004 | F13: =ELEC!K14 -> 852 | G13: =ELEC!I14 -> 1468 | H13: =ELEC!E14 -> 3252 | I13: =ELEC!G14 -> 1203 | J13: =WATER!Y17 -> 0 | K13: =WATER!AJ17 -> 31 | L13: =ELEC!B14 -> 0
A14: Beirut | B14: =B13+1 -> 13 | C14: 8 | D14: 2020 | E14: =ELEC!M15 -> 3420 | F14: =ELEC!K15 -> 1020 | G14: =ELEC!I15 -> 1468 | H14: =ELEC!E15 -> 4400 | I14: =ELEC!G15 -> 1147 | J14: =WATER!Y18 -> 0 | K14: =WATER!AJ18 -> 0 | L14: =ELEC!B15 -> 0
... A32: Beirut | B32: =B31+1 -> 31 | C32: 8 | D32: 2020 | E32: =ELEC!M33 -> 0 | F32: =ELEC!K33 -> 0 | G32: =ELEC!I33 -> 0 | H32: =ELEC!E33 -> 0 | I32: =ELEC!G33 -> 0 | J32: =WATER!Y36 -> 0 | K32: =WATER!AJ36 -> 0 | L32: =ELEC!B33 -> 0

Sheet ELEC
A1: OOC | B1: Room OCC | D1: MDB3 | E1: MDB3/day | F1: EMDB2 | G1: EMDB2/day | H1: EMDB1 | I1: EMDB1/day | J1: MDB2 | K1: mdb2/day | L1: MDB1 | M1: MDB1/Day | N1: Total KWH | O1: KWH/Rooc | P1: Gen MHW | Q1: Gen/Day KWH | R1: EDL KWH | S1: CH1 RH | T1: RH | U1: C1h1 power | V1: CH1 Con KWH | W1: CH2 RH | X1: RH | Y1: Ch2 power | Z1: CH2 Con KWH | AA1: CH3 RH | AB1: RH | AC1: Ch3 power | AD1: CH3 Con KWH | AE1: RH total | AF1: KWH total | AG1: AVG chiller KW/Hr
A2: =[1]ELEC!$A$33 -> 0.3609 | B2: =[1]ELEC!$B$33 -> 83.007 | C2: 44043 | D2: =[1]ELEC!D33 -> 32042098 | E2: =[1]ELEC!E33 -> 6288 | F2: =[1]ELEC!F33 -> 3808714 | G2: =[1]ELEC!G33 -> 2565 | H2: =[1]ELEC!H33 -> 17595910 | I2: =[1]ELEC!I33 -> 2998 | J2: =[1]ELEC!J33 -> 28649166 | K2: =[1]ELEC!K33 -> 6152 | ... AI2: =[1]ELEC!AI33 -> -166787
A3: ='General information '!F6 -> 0.387 | B3: =SUM(230*A3) -> 89.01 | C3: 44044 | D3: 32047694 | E3: =D3-D2 -> 5596 | F3: 3811351 | G3: =F3-F2 -> 2637 | H3: 17599014 | I3: =H3-H2 -> 3104 | J3: 28656188 | K3: =J3-J2 -> 7022 | L3: 23457686 | M3: =L3-L2 -> 6992 | N3: =M3+K3+I3+G3+E3 -> 25351 | O3: =IF(B3>0,N3/B3,0) -> 284.8107 | P3: 16174 | Q3: =(P3-P2)*1000 -> 17000 | R3: =+N3-Q3 -> 8351 | S3: 9275 | T3: =S3-S2 -> 11 | U3: 233995 | V3: =U3-U2 -> 2707 | W3: 32033 | X3: =W3-W2 -> 15 | Y3: 669511 | Z3: =Y3-Y2 -> 4041 | AA3: 35377 | AB3: =AA3-AA2 -> 0 | AC3: =AC2 -> 849402 | AD3: =AC3-AC2 -> 0 | AE3: =AB3+X3+T3 -> 26 | AF3: =V3+Z3+AD3 -> 6748 | AG3: =IF(AE3>0,AF3/AE3,0) -> 259.53846
A4: ='General information '!F7 -> 0.3391 | B4: =SUM(230*A4) -> 77.993 | C4: 44045 | D4: 32052926 | E4: =D4-D3 -> 5232 | F4: 3813877 | G4: =F4-F3 -> 2526 | H4: 17602228 | I4: =H4-H3 -> 3214 | J4: 28659468 | K4: =J4-J3 -> 3280 | L4: 23468166 | M4: =L4-L3 -> 10480 | N4: =M4+K4+I4+G4+E4 -> 24732 | O4: =IF(B4>0,N4/B4,0) -> 317.10538 | P4: 16184 | Q4: =(P4-P3)*1000 -> 10000 | R4: =N4-Q4 -> 14732 | S4: 9298 | T4: =S4-S3 -> 23 | U4: 239777 | V4: =U4-U3 -> 5782 | W4: 32036 | X4: =W4-W3 -> 3 | Y4: 669993 | Z4: =Y4-Y3 -> 482 | AA4: 35377 | AB4: =AA4-AA3 -> 0 | AC4: 849402 | AD4: =AC4-AC3 -> 0 | AE4: =AB4+X4+T4 -> 26 | AF4: =V4+Z4+AD4 -> 6264 | AG4: =IF(AE4>0,AF4/AE4,0) -> 240.92308
A5: ='General information '!F8 -> 0.3 | B5: =SUM(230*A5) -> 69 | C5: 44046 | D5: 32061746 | E5: =D5-D4 -> 8820 | F5: 3816226 | G5: =F5-F4 -> 2349 | H5: 17605162 | I5: =H5-H4 -> 2934 | J5: 28662258 | K5: =J5-J4 -> 2790 | L5: 23475030 | M5: =L5-L4 -> 6864 | N5: =M5+K5+I5+G5+E5 -> 23757 | O5: =IF(B5>0,N5/B5,0) -> 344.30435 | P5: 16199 | Q5: =(P5-P4)*1000 -> 15000 | R5: =N5-Q5 -> 8757 | S5: 9309 | T5: =S5-S4 -> 11 | U5: 242688 | V5: =U5-U4 -> 2911 | W5: 32036 | X5: =W5-W4 -> 0 | Y5: =Y4 -> 669993 | Z5: =Y5-Y4 -> 0 | AA5: 35390 | AB5: =AA5-AA4 -> 13 | AC5: 852906 | AD5: =AC5-AC4 -> 3504 | AE5: =AB5+X5+T5 -> 24 | AF5: =V5+Z5+AD5 -> 6415 | AG5: =IF(AE5>0,AF5/AE5,0) -> 267.29167 | AI5: =R5-'EDl log'!B3 -> -197253
A6: ='General information '!F9 -> 0 | B6: =SUM(230*A6) -> 0 | C6: 44047 | D6: 32070932 | E6: =D6-D5 -> 9186 | F6: 3819058 | G6: =F6-F5 -> 2832 | H6: 17608854 | I6: =H6-H5 -> 3692 | J6: 28664778 | K6: =J6-J5 -> 2520 | L6: 23482044 | M6: =L6-L5 -> 7014 | N6: =M6+K6+I6+G6+E6 -> 25244 | O6: =IF(B6>0,N6/B6,0) -> 0 | P6: =P5 -> 16199 | Q6: =(P6-P5)*1000 -> 0 | R6: =N6-Q6 -> 25244 | S6: =S5 -> 9309 | T6: =S6-S5 -> 0 | U6: =U5 -> 242688 | V6: =U6-U5 -> 0 | W6: =W5 -> 32036 | X6: =W6-W5 -> 0 | Y6: =Y5 -> 669993 | Z6: =Y6-Y5 -> 0 | AA6: =AA5 -> 35390 | AB6: =AA6-AA5 -> 0 | AC6: =AC5 -> 852906 | AD6: =AC6-AC5 -> 0 | AE6: =AB6+X6+T6 -> 0 | AF6: =V6+Z6+AD6 -> 0 | AG6: =IF(AE6>0,AF6/AE6,0) -> 0 | AI6: =R6-'EDl log'!B4 -> -185451
A7: ='General information '!F10 -> 0 | B7: =SUM(230*A7) -> 0 | C7: 44048 | D7: 32073586 | E7: =D7-D6 -> 2654 | F7: 3819800 | G7: =F7-F6 -> 742 | H7: 17610032 | I7: =H7-H6 -> 1178 | J7: 28668130 | K7: =J7-J6 -> 3352 | L7: 23485106 | M7: =L7-L6 -> 3062 | N7: =M7+K7+I7+G7+E7 -> 10988 | O7: =IF(B7>0,N7/B7,0) -> 0 | P7: 16213 | Q7: =(P7-P6)*1000 -> 14000 | R7: =N7-Q7 -> -3012 | S7: 9319 | T7: =S7-S6 -> 10 | U7: 245384 | V7: =U7-U6 -> 2696 | W7: 32044 | X7: =W7-W6 -> 8 | Y7: 671974 | Z7: =Y7-Y6 -> 1981 | AA7: 35405 | AB7: =AA7-AA6 -> 15 | AC7: 856413 | AD7: =AC7-AC6 -> 3507 | AE7: =AB7+X7+T7 -> 33 | AF7: =V7+Z7+AD7 -> 8184 | AG7: =IF(AE7>0,AF7/AE7,0) -> 248 | AI7: =R7-'EDl log'!B5 -> -221667
A8: ='General information '!F11 -> 0 | B8: =SUM(230*A8) -> 0 | C8: 44049 | D8: 32076276 | E8: =D8-D7 -> 2690 | F8: 3820907 | G8: =F8-F7 -> 1107 | H8: 17611152 | I8: =H8-H7 -> 1120 | J8: 28669708 | K8: =J8-J7 -> 1578 | L8: 23489310 | M8: =L8-L7 -> 4204 | N8: =M8+K8+I8+G8+E8 -> 10699 | O8: =IF(B8>0,N8/B8,0) -> 0 | P8: 16218 | Q8: =(P8-P7)*1000 -> 5000 | R8: =N8-Q8 -> 5699 | S8: 9327 | T8: =S8-S7 -> 8 | U8: 246875 | V8: =U8-U7 -> 1491 | W8: 32046 | X8: =W8-W7 -> 2 | Y8: 672604 | Z8: =Y8-Y7 -> 630 | AA8: 35405 | AB8: =AA8-AA7 -> 0 | AC8: =AC7 -> 856413 | AD8: =AC8-AC7 -> 0 | AE8: =AB8+X8+T8 -> 10 | AF8: =V8+Z8+AD8 -> 2121 | AG8: =IF(AE8>0,AF8/AE8,0) -> 212.1 | AI8: =R8-'EDl log'!B6 -> -217453
A9: ='General information '!F12 -> 0 | B9: =SUM(230*A9) -> 0 | C9: 44050 | D9: 32079202 | E9: =D9-D8 -> 2926 | F9: 3821812 | G9: =F9-F8 -> 905 | H9: 17612180 | I9: =H9-H8 -> 1028 | J9: 28670442 | K9: =J9-J8 -> 734 | L9: 23493498 | M9: =L9-L8 -> 4188 | N9: =M9+K9+I9+G9+E9 -> 9781 | O9: =IF(B9>0,N9/B9,0) -> 0 | P9: 16219 | Q9: =(P9-P8)*1000 -> 1000 | R9: =N9-Q9 -> 8781 | S9: 9336 | T9: =S9-S8 -> 9 | U9: 248851 | V9: =U9-U8 -> 1976 | W9: 32046 | X9: =W9-W8 -> 0 | Y9: 672606 | Z9: =Y9-Y8 -> 2 | AA9: 35407 | AB9: =AA9-AA8 -> 2 | AC9: 856808 | AD9: =AC9-AC8 -> 395 | AE9: =AB9+X9+T9 -> 11 | AF9: =V9+Z9+AD9 -> 2373 | AG9: =IF(AE9>0,AF9/AE9,0) -> 215.72727 | AI9: =R9-'EDl log'!B7 -> -221782
A10: ='General information '!F13 -> 0 | B10: =SUM(230*A10) -> 0 | C10: 44051 | D10: 32085002 | E10: =D10-D9 -> 5800 | F10: 3822575 | G10: =F10-F9 -> 763 | H10: 17613294 | I10: =H10-H9 -> 1114 | J10: 28671554 | K10: =J10-J9 -> 1112 | L10: 23495356 | M10: =L10-L9 -> 1858 | N10: =M10+K10+I10+G10+E10 -> 10647 | O10: =IF(B10>0,N10/B10,0) -> 0 | P10: 16221 | Q10: =(P10-P9)*1000 -> 2000 | R10: =N10-Q10 -> 8647 | S10: 9337 | T10: =S10-S9 -> 1 | U10: 249122 | V10: =U10-U9 -> 271 | W10: 32046 | X10: =W10-W9 -> 0 | Y10: 672607 | Z10: =Y10-Y9 -> 1 | AA10: 35420 | AB10: =AA10-AA9 -> 13 | AC10: 859223 | AD10: =AC10-AC9 -> 2415 | AE10: =AB10+X10+T10 -> 14 | AF10: =V10+Z10+AD10 -> 2687 | AG10: =IF(AE10>0,AF10/AE10,0) -> 191.92857 | AI10: =R10-'EDl log'!B8 -> -224496
A11: ='General information '!F14 -> 0 | B11: =SUM(230*A11) -> 0 | C11: 44052 | D11: 32087526 | E11: =D11-D10 -> 2524 | F11: 3823427 | G11: =F11-F10 -> 852 | H11: 17614364 | I11: =H11-H10 -> 1070 | J11: 28672354 | K11: =J11-J10 -> 800 | L11: 23498510 | M11: =L11-L10 -> 3154 | N11: =M11+K11+I11+G11+E11 -> 8400 | O11: =IF(B11>0,N11/B11,0) -> 0 | P11: 16223 | Q11: =(P11-P10)*1000 -> 2000 | R11: =N11-Q11 -> 6400 | S11: 9346 | T11: =S11-S10 -> 9 | U11: 250635 | V11: =U11-U10 -> 1513 | W11: =W10 -> 32046 | X11: =W11-W10 -> 0 | Y11: =Y10 -> 672607 | Z11: =Y11-Y10 -> 0 | AA11: 35422 | AB11: =AA11-AA10 -> 2 | AC11: 859491 | AD11: =AC11-AC10 -> 268 | AE11: =AB11+X11+T11 -> 11 | AF11: =V11+Z11+AD11 -> 1781 | AG11: =IF(AE11>0,AF11/AE11,0) -> 161.90909 | AI11: =R11-'EDl log'!B9 -> -231591
A12: ='General information '!F15 -> 0 | B12: =SUM(230*A12) -> 0 | C12: 44053 | D12: 32093034 | E12: =D12-D11 -> 5508 | F12: 3824180 | G12: =F12-F11 -> 753 | H12: 17615454 | I12: =H12-H11 -> 1090 | J12: 28673410 | K12: =J12-J11 -> 1056 | L12: 23500560 | M12: =L12-L11 -> 2050 | N12: =M12+K12+I12+G12+E12 -> 10457 | O12: =IF(B12>0,N12/B12,0) -> 0 | P12: 16224 | Q12: =(P12-P11)*1000 -> 1000 | R12: =N12-Q12 -> 9457 | S12: 9348 | T12: =S12-S11 -> 2 | U12: 250968 | V12: =U12-U11 -> 333 | W12: 32046 | X12: =W12-W11 -> 0 | Y12: 672607 | Z12: =Y12-Y11 -> 0 | AA12: 35434 | AB12: =AA12-AA11 -> 12 | AC12: 861734 | AD12: =AC12-AC11 -> 2243 | AE12: =AB12+X12+T12 -> 14 | AF12: =V12+Z12+AD12 -> 2576 | AG12: =IF(AE12>0,AF12/AE12,0) -> 184 | AI12: =R12-'EDl log'!B10 -> -232684
A13: ='General information '!F16 -> 0 | B13: =SUM(230*A13) -> 0 | C13: 44054 | D13: 32095818 | E13: =D13-D12 -> 2784 | F13: 3825123 | G13: =F13-F12 -> 943 | H13: 17616654 | I13: =H13-H12 -> 1200 | J13: 28674878 | K13: =J13-J12 -> 1468 | L13: 23504430 | M13: =L13-L12 -> 3870 | N13: =M13+K13+I13+G13+E13 -> 10265 | O13: =IF(B13>0,N13/B13,0) -> 0 | P13: 16226 | Q13: =(P13-P12)*1000 -> 2000 | R13: =N13-Q13 -> 8265 | S13: 9356 | T13: =S13-S12 -> 8 | U13: 252595 | V13: =U13-U12 -> 1627 | W13: 32046 | X13: =W13-W12 -> 0 | Y13: 672607 | Z13: =Y13-Y12 -> 0 | AA13: 35434 | AB13: =AA13-AA12 -> 0 | AC13: 861734 | AD13: =AC13-AC12 -> 0 | AE13: =AB13+X13+T13 -> 8 | AF13: =V13+Z13+AD13 -> 1627 | AG13: =IF(AE13>0,AF13/AE13,0) -> 203.375 | AI13: =R13-'EDl log'!B11 -> -238500
A14: ='General information '!F17 -> 0 | B14: =SUM(230*A14) -> 0 | C14: 44055 | D14: 32099070 | E14: =D14-D13 -> 3252 | F14: 3826326 | G14: =F14-F13 -> 1203 | H14: 17618122 | I14: =H14-H13 -> 1468 | J14: 28675730 | K14: =J14-J13 -> 852 | L14: 23508434 | M14: =L14-L13 -> 4004 | N14: =M14+K14+I14+G14+E14 -> 10779 | O14: =IF(B14>0,N14/B14,0) -> 0 | P14: 16228 | Q14: =(P14-P13)*1000 -> 2000 | R14: =N14-Q14 -> 8779 | S14: 9363 | T14: =S14-S13 -> 7 | U14: 254289 | V14: =U14-U13 -> 1694 | W14: 32049 | X14: =W14-W13 -> 3 | Y14: 673052 | Z14: =Y14-Y13 -> 445 | AA14: 35437 | AB14: =AA14-AA13 -> 3 | AC14: 862371 | AD14: =AC14-AC13 -> 637 | AE14: =AB14+X14+T14 -> 13 | AF14: =V14+Z14+AD14 -> 2776 | AG14: =IF(AE14>0,AF14/AE14,0) -> 213.53846 | AI14: =R14-'EDl log'!B12 -> -241502
A15: ='General information '!F18 -> 0 | B15: =SUM(230*A15) -> 0 | C15: 44056 | D15: 32103470 | E15: =D15-D14 -> 4400 | F15: 3827473 | G15: =F15-F14 -> 1147 | H15: 17619590 | I15: =H15-H14 -> 1468 | J15: 28676750 | K15: =J15-J14 -> 1020 | L15: 23511854 | M15: =L15-L14 -> 3420 | N15: =M15+K15+I15+G15+E15 -> 11455 | O15: =IF(B15>0,N15/B15,0) -> 0 | P15: 16230 | Q15: =(P15-P14)*1000 -> 2000 | R15: =N15-Q15 -> 9455 | S15: 9368 | T15: =S15-S14 -> 5 | U15: 255509 | V15: =U15-U14 -> 1220 | W15: 32049 | X15: =W15-W14 -> 0 | Y15: 673052 | Z15: =Y15-Y14 -> 0 | AA15: 35444 | AB15: =AA15-AA14 -> 7 | AC15: 863877 | AD15: =AC15-AC14 -> 1506 | AE15: =AB15+X15+T15 -> 12 | AF15: =V15+Z15+AD15 -> 2726 | AG15: =IF(AE15>0,AF15/AE15,0) -> 227.16667 | AI15: =R15-'EDl log'!B13 -> -245532
A16: ='General information '!F19 -> 0 | B16: =SUM(230*A16) -> 0 | C16: 44057 | D16: 32108176 | E16: =D16-D15 -> 4706 | F16: 3828616 | G16: =F16-F15 -> 1143 | H16: 17621124 | I16: =H16-H15 -> 1534 | J16: 28677648 | K16: =J16-J15 -> 898 | L16: 23514782 | M16: =L16-L15 -> 2928 | N16: =M16+K16+I16+G16+E16 -> 11209 | O16: =IF(B16>0,N16/B16,0) -> 0 | P16: 16234 | Q16: =(P16-P15)*1000 -> 4000 | R16: =N16-Q16 -> 7209 | S16: =S15 -> 9368 | T16: =S16-S15 -> 0 | U16: =U15 -> 255509 | V16: =U16-U15 -> 0 | W16: =W15 -> 32049 | X16: =W16-W15 -> 0 | Y16: =Y15 -> 673052 | Z16: =Y16-Y15 -> 0 | AA16: 35454 | AB16: =AA16-AA15 -> 10 | AC16: 866059 | AD16: =AC16-AC15 -> 2182 | AE16: =AB16+X16+T16 -> 10 | AF16: =V16+Z16+AD16 -> 2182 | AG16: =IF(AE16>0,AF16/AE16,0) -> 218.2 | AI16: =R16-'EDl log'!B14 -> -252392
A17: ='General information '!F20 -> 0 | B17: =SUM(230*A17) -> 0 | C17: 44058 | D17: 32112390 | E17: =D17-D16 -> 4214 | F17: 3829736 | G17: =F17-F16 -> 1120 | H17: 17622674 | I17: =H17-H16 -> 1550 | J17: 28678218 | K17: =J17-J16 -> 570 | L17: 23517032 | M17: =L17-L16 -> 2250 | N17: =M17+K17+I17+G17+E17 -> 9704 | O17: =IF(B17>0,N17/B17,0) -> 0 | P17: 16236 | Q17: =(P17-P16)*1000 -> 2000 | R17: =N17-Q17 -> 7704 | S17: 9371 | T17: =S17-S16 -> 3 | U17: 256194 | V17: =U17-U16 -> 685 | W17: =W16 -> 32049 | X17: =W17-W16 -> 0 | Y17: =Y16 -> 673052 | Z17: =Y17-Y16 -> 0 | AA17: 35461 | AB17: =AA17-AA16 -> 7 | AC17: 867187 | AD17: =AC17-AC16 -> 1128 | AE17: =AB17+X17+T17 -> 10 | AF17: =V17+Z17+AD17 -> 1813 | AG17: =IF(AE17>0,AF17/AE17,0) -> 181.3 | AI17: =R17-'EDl log'!B15 -> -256520
A18: ='General information '!F21 -> 0 | B18: =SUM(230*A18) -> 0 | C18: 44059 | D18: 32115318 | E18: =D18-D17 -> 2928 | F18: 3830785 | G18: =F18-F17 -> 1049 | H18: 17624060 | I18: =H18-H17 -> 1386 | J18: 28678922 | K18: =J18-J17 -> 704 | L18: 23520330 | M18: =L18-L17 -> 3298 | N18: =M18+K18+I18+G18+E18 -> 9365 | O18: =IF(B18>0,N18/B18,0) -> 0 | P18: 16238 | Q18: =(P18-P17)*1000 -> 2000 | R18: =N18-Q18 -> 7365 | S18: 9377 | T18: =S18-S17 -> 6 | U18: 257494 | V18: =U18-U17 -> 1300 | W18: 32049 | X18: =W18-W17 -> 0 | Y18: =Y17 -> 673052 | Z18: =Y18-Y17 -> 0 | AA18: 35463 | AB18: =AA18-AA17 -> 2 | AC18: 867699 | AD18: =AC18-AC17 -> 512 | AE18: =AB18+X18+T18 -> 8 | AF18: =V18+Z18+AD18 -> 1812 | AG18: =IF(AE18>0,AF18/AE18,0) -> 226.5 | AI18: =R18-'EDl log'!B16 -> -261463
A19: ='General information '!F22 -> 0 | B19: =SUM(230*A19) -> 0 | C19: 44060 | D19: 32120150 | E19: =D19-D18 -> 4832 | F19: 3831819 | G19: =F19-F18 -> 1034 | H19: 17625264 | I19: =H19-H18 -> 1204 | J19: 28679954 | K19: =J19-J18 -> 1032 | L19: 23523954 | M19: =L19-L18 -> 3624 | N19: =M19+K19+I19+G19+E19 -> 11726 | O19: =IF(B19>0,N19/B19,0) -> 0 | P19: 16239 | Q19: =(P19-P18)*1000 -> 1000 | R19: =N19-Q19 -> 10726 | S19: 9384 | T19: =S19-S18 -> 7 | U19: 258864 | V19: =U19-U18 -> 1370 | W19: 32049 | X19: =W19-W18 -> 0 | Y19: 673052 | Z19: =Y19-Y18 -> 0 | AA19: =AA18 -> 35463 | AB19: =AA19-AA18 -> 0 | AC19: =AC18 -> 867699 | AD19: =AC19-AC18 -> 0 | AE19: =AB19+X19+T19 -> 7 | AF19: =V19+Z19+AD19 -> 1370 | AG19: =IF(AE19>0,AF19/AE19,0) -> 195.71429 | AI19: =R19-'EDl log'!B17 -> -261989
A20: ='General information '!F23 -> 0 | B20: =SUM(230*A20) -> 0 | C20: 44061 | D20: 32126336 | E20: =D20-D19 -> 6186 | F20: 3832913 | G20: =F20-F19 -> 1094 | H20: 17626674 | I20: =H20-H19 -> 1410 | J20: 28680930 | K20: =J20-J19 -> 976 | L20: 23526392 | M20: =L20-L19 -> 2438 | N20: =M20+K20+I20+G20+E20 -> 12104 | O20: =IF(B20>0,N20/B20,0) -> 0 | P20: 16240 | Q20: =(P20-P19)*1000 -> 1000 | R20: =N20-Q20 -> 11104 | S20: 9384 | T20: =S20-S19 -> 0 | U20: 258864 | V20: =U20-U19 -> 0 | W20: 32049 | X20: =W20-W19 -> 0 | Y20: =Y19 -> 673052 | Z20: =Y20-Y19 -> 0 | AA20: 35482 | AB20: =AA20-AA19 -> 19 | AC20: 871793 | AD20: =AC20-AC19 -> 4094 | AE20: =AB20+X20+T20 -> 19 | AF20: =V20+Z20+AD20 -> 4094 | AG20: =IF(AE20>0,AF20/AE20,0) -> 215.47368 | AI20: =R20-'EDl log'!B18 -> -265711
A21: ='General information '!F24 -> 0 | B21: =SUM(230*A21) -> 0 | C21: 44062 | D21: =D20 -> 32126336 | E21: =D21-D20 -> 0 | F21: =F20 -> 3832913 | G21: =F21-F20 -> 0 | H21: =H20 -> 17626674 | I21: =H21-H20 -> 0 | J21: =J20 -> 28680930 | K21: =J21-J20 -> 0 | L21: =L20 -> 23526392 | M21: =L21-L20 -> 0 | N21: =M21+K21+I21+G21+E21 -> 0 | O21: =IF(B21>0,N21/B21,0) -> 0 | P21: =P20 -> 16240 | Q21: =(P21-P20)*1000 -> 0 | R21: =N21-Q21 -> 0 | S21: =S20 -> 9384 | T21: =S21-S20 -> 0 | U21: =U20 -> 258864 | V21: =U21-U20 -> 0 | W21: =W20 -> 32049 | X21: =W21-W20 -> 0 | Y21: =Y20 -> 673052 | Z21: =Y21-Y20 -> 0 | AA21: =AA20 -> 35482 | AB21: =AA21-AA20 -> 0 | AC21: =AC20 -> 871793 | AD21: =AC21-AC20 -> 0 | AE21: =AB21+X21+T21 -> 0 | AF21: =V21+Z21+AD21 -> 0 | AG21: =IF(AE21>0,AF21/AE21,0) -> 0 | AI21: =R21-'EDl log'!B19 -> -280938
A22: ='General information '!F25 -> 0 | B22: =SUM(230*A22) -> 0 | C22: 44063 | D22: =D21 -> 32126336 | E22: =D22-D21 -> 0 | F22: =F21 -> 3832913 | G22: =F22-F21 -> 0 | H22: =H21 -> 17626674 | I22: =H22-H21 -> 0 | J22: =J21 -> 28680930 | K22: =J22-J21 -> 0 | L22: =L21 -> 23526392 | M22: =L22-L21 -> 0 | N22: =M22+K22+I22+G22+E22 -> 0 | O22: =IF(B22>0,N22/B22,0) -> 0 | P22: =P21 -> 16240 | Q22: =(P22-P21)*1000 -> 0 | R22: =N22-Q22 -> 0 | S22: =S21 -> 9384 | T22: =S22-S21 -> 0 | U22: =U21 -> 258864 | V22: =U22-U21 -> 0 | W22: =W21 -> 32049 | X22: =W22-W21 -> 0 | Y22: =Y21 -> 673052 | Z22: =Y22-Y21 -> 0 | AA22: =AA21 -> 35482 | AB22: =AA22-AA21 -> 0 | AC22: =AC21 -> 871793 | AD22: =AC22-AC21 -> 0 | AE22: =AB22+X22+T22 -> 0 | AF22: =V22+Z22+AD22 -> 0 | AG22: =IF(AE22>0,AF22/AE22,0) -> 0 | AI22: =R22-'EDl log'!B20 -> -286074
A23: ='General information '!F26 -> 0 | B23: =SUM(230*A23) -> 0 | C23: 44064 | D23: =D22 -> 32126336 | E23: =D23-D22 -> 0 | F23: =F22 -> 3832913 | G23: =F23-F22 -> 0 | H23: =H22 -> 17626674 | I23: =H23-H22 -> 0 | J23: =J22 -> 28680930 | K23: =J23-J22 -> 0 | L23: =L22 -> 23526392 | M23: =L23-L22 -> 0 | N23: =M23+K23+I23+G23+E23 -> 0 | O23: =IF(B23>0,N23/B23,0) -> 0 | P23: =P22 -> 16240 | Q23: =(P23-P22)*1000 -> 0 | R23: =N23-Q23 -> 0 | S23: =S22 -> 9384 | T23: =S23-S22 -> 0 | U23: =U22 -> 258864 | V23: =U23-U22 -> 0 | W23: =W22 -> 32049 | X23: =W23-W22 -> 0 | Y23: =Y22 -> 673052 | Z23: =Y23-Y22 -> 0 | AA23: =AA22 -> 35482 | AB23: =AA23-AA22 -> 0 | AC23: =AC22 -> 871793 | AD23: =AC23-AC22 -> 0 | AE23: =AB23+X23+T23 -> 0 | AF23: =V23+Z23+AD23 -> 0 | AG23: =IF(AE23>0,AF23/AE23,0) -> 0 | AI23: =R23-'EDl log'!B21 -> -291983
A24: ='General information '!F27 -> 0 | B24: =SUM(230*A24) -> 0 | C24: 44065 | D24: =D23 -> 32126336 | E24: =D24-D23 -> 0 | F24: =F23 -> 3832913 | G24: =F24-F23 -> 0 | H24: =H23 -> 17626674 | I24: =H24-H23 -> 0 | J24: =J23 -> 28680930 | K24: =J24-J23 -> 0 | L24: =L23 -> 23526392 | M24: =L24-L23 -> 0 | N24: =M24+K24+I24+G24+E24 -> 0 | O24: =IF(B24>0,N24/B24,0) -> 0 | P24: =P23 -> 16240 | Q24: =(P24-P23)*1000 -> 0 | R24: =N24-Q24 -> 0 | S24: =S23 -> 9384 | T24: =S24-S23 -> 0 | U24: =U23 -> 258864 | V24: =U24-U23 -> 0 | W24: =W23 -> 32049 | X24: =W24-W23 -> 0 | Y24: =Y23 -> 673052 | Z24: =Y24-Y23 -> 0 | AA24: =AA23 -> 35482 | AB24: =AA24-AA23 -> 0 | AC24: =AC23 -> 871793 | AD24: =AC24-AC23 -> 0 | AE24: =AB24+X24+T24 -> 0 | AF24: =V24+Z24+AD24 -> 0 | AG24: =IF(AE24>0,AF24/AE24,0) -> 0 | AI24: =R24-'EDl log'!B22 -> -291983
A25: ='General information '!F28 -> 0 | B25: =SUM(230*A25) -> 0 | C25: 44066 | D25: =D24 -> 32126336 | E25: =D25-D24 -> 0 | F25: =F24 -> 3832913 | G25: =F25-F24 -> 0 | H25: =H24 -> 17626674 | I25: =H25-H24 -> 0 | J25: =J24 -> 28680930 | K25: =J25-J24 -> 0 | L25: =L24 -> 23526392 | M25: =L25-L24 -> 0 | N25: =M25+K25+I25+G25+E25 -> 0 | O25: =IF(B25>0,N25/B25,0) -> 0 | P25: =P24 -> 16240 | Q25: =(P25-P24)*1000 -> 0 | R25: =N25-Q25 -> 0 | S25: =S24 -> 9384 | T25: =S25-S24 -> 0 | U25: =U24 -> 258864 | V25: =U25-U24 -> 0 | W25: =W24 -> 32049 | X25: =W25-W24 -> 0 | Y25: =Y24 -> 673052 | Z25: =Y25-Y24 -> 0 | AA25: =AA24 -> 35482 | AB25: =AA25-AA24 -> 0 | AC25: =AC24 -> 871793 | AD25: =AC25-AC24 -> 0 | AE25: =AB25+X25+T25 -> 0 | AF25: =V25+Z25+AD25 -> 0 | AG25: =IF(AE25>0,AF25/AE25,0) -> 0 | AI25: =R25-'EDl log'!B23 -> -291983
A26: ='General information '!F29 -> 0 | B26: =SUM(230*A26) -> 0 | C26: 44067 | D26: =D25 -> 32126336 | E26: =D26-D25 -> 0 | F26: =F25 -> 3832913 | G26: =F26-F25 -> 0 | H26: =H25 -> 17626674 | I26: =H26-H25 -> 0 | J26: =J25 -> 28680930 | K26: =J26-J25 -> 0 | L26: =L25 -> 23526392 | M26: =L26-L25 -> 0 | N26: =M26+K26+I26+G26+E26 -> 0 | O26: =IF(B26>0,N26/B26,0) -> 0 | P26: =P25 -> 16240 | Q26: =(P26-P25)*1000 -> 0 | R26: =N26-Q26 -> 0 | S26: =S25 -> 9384 | T26: =S26-S25 -> 0 | U26: =U25 -> 258864 | V26: =U26-U25 -> 0 | W26: =W25 -> 32049 | X26: =W26-W25 -> 0 | Y26: =Y25 -> 673052 | Z26: =Y26-Y25 -> 0 | AA26: =AA25 -> 35482 | AB26: =AA26-AA25 -> 0 | AC26: =AC25 -> 871793 | AD26: =AC26-AC25 -> 0 | AE26: =AB26+X26+T26 -> 0 | AF26: =V26+Z26+AD26 -> 0 | AG26: =IF(AE26>0,AF26/AE26,0) -> 0 | AI26: =R26-'EDl log'!B24 -> -291983
A27: ='General information '!F30 -> 0 | B27: =SUM(230*A27) -> 0 | C27: 44068 | D27: =D26 -> 32126336 | E27: =D27-D26 -> 0 | F27: =F26 -> 3832913 | G27: =F27-F26 -> 0 | H27: =H26 -> 17626674 | I27: =H27-H26 -> 0 | J27: =J26 -> 28680930 | K27: =J27-J26 -> 0 | L27: =L26 -> 23526392 | M27: =L27-L26 -> 0 | N27: =M27+K27+I27+G27+E27 -> 0 | O27: =IF(B27>0,N27/B27,0) -> 0 | P27: =P26 -> 16240 | Q27: =(P27-P26)*1000 -> 0 | R27: =N27-Q27 -> 0 | S27: =S26 -> 9384 | T27: =S27-S26 -> 0 | U27: =U26 -> 258864 | V27: =U27-U26 -> 0 | W27: =W26 -> 32049 | X27: =W27-W26 -> 0 | Y27: =Y26 -> 673052 | Z27: =Y27-Y26 -> 0 | AA27: =AA26 -> 35482 | AB27: =AA27-AA26 -> 0 | AC27: =AC26 -> 871793 | AD27: =AC27-AC26 -> 0 | AE27: =AB27+X27+T27 -> 0 | AF27: =V27+Z27+AD27 -> 0 | AG27: =IF(AE27>0,AF27/AE27,0) -> 0 | AI27: =R27-'EDl log'!B25 -> -291983
A28: ='General information '!F31 -> 0 | B28: =SUM(230*A28) -> 0 | C28: 44069 | D28: =D27 -> 32126336 | E28: =D28-D27 -> 0 | F28: =F27 -> 3832913 | G28: =F28-F27 -> 0 | H28: =H27 -> 17626674 | I28: =H28-H27 -> 0 | J28: =J27 -> 28680930 | K28: =J28-J27 -> 0 | L28: =L27 -> 23526392 | M28: =L28-L27 -> 0 | N28: =M28+K28+I28+G28+E28 -> 0 | O28: =IF(B28>0,N28/B28,0) -> 0 | P28: =P27 -> 16240 | Q28: =(P28-P27)*1000 -> 0 | R28: =N28-Q28 -> 0 | S28: =S27 -> 9384 | T28: =S28-S27 -> 0 | U28: =U27 -> 258864 | V28: =U28-U27 -> 0 | W28: =W27 -> 32049 | X28: =W28-W27 -> 0 | Y28: =Y27 -> 673052 | Z28: =Y28-Y27 -> 0 | AA28: =AA27 -> 35482 | AB28: =AA28-AA27 -> 0 | AC28: =AC27 -> 871793 | AD28: =AC28-AC27 -> 0 | AE28: =AB28+X28+T28 -> 0 | AF28: =V28+Z28+AD28 -> 0 | AG28: =IF(AE28>0,AF28/AE28,0) -> 0 | AI28: =R28-'EDl log'!B26 -> -291983
A29: ='General information '!F32 -> 0 | B29: =SUM(230*A29) -> 0 | C29: 44070 | D29: =D28 -> 32126336 | E29: =D29-D28 -> 0 | F29: =F28 -> 3832913 | G29: =F29-F28 -> 0 | H29: =H28 -> 17626674 | I29: =H29-H28 -> 0 | J29: =J28 -> 28680930 | K29: =J29-J28 -> 0 | L29: =L28 -> 23526392 | M29: =L29-L28 -> 0 | N29: =M29+K29+I29+G29+E29 -> 0 | O29: =IF(B29>0,N29/B29,0) -> 0 | P29: =P28 -> 16240 | Q29: =(P29-P28)*1000 -> 0 | R29: =N29-Q29 -> 0 | S29: =S28 -> 9384 | T29: =S29-S28 -> 0 | U29: =U28 -> 258864 | V29: =U29-U28 -> 0 | W29: =W28 -> 32049 | X29: =W29-W28 -> 0 | Y29: =Y28 -> 673052 | Z29: =Y29-Y28 -> 0 | AA29: =AA28 -> 35482 | AB29: =AA29-AA28 -> 0 | AC29: =AC28 -> 871793 | AD29: =AC29-AC28 -> 0 | AE29: =AB29+X29+T29 -> 0 | AF29: =V29+Z29+AD29 -> 0 | AG29: =IF(AE29>0,AF29/AE29,0) -> 0 | AI29: =R29-'EDl log'!B27 -> -291983
A30: ='General information '!F33 -> 0 | B30: =SUM(230*A30) -> 0 | C30: 44071 | D30: =D29 -> 32126336 | E30: =D30-D29 -> 0 | F30: =F29 -> 3832913 | G30: =F30-F29 -> 0 | H30: =H29 -> 17626674 | I30: =H30-H29 -> 0 | J30: =J29 -> 28680930 | K30: =J30-J29 -> 0 | L30: =L29 -> 23526392 | M30: =L30-L29 -> 0 | N30: =M30+K30+I30+G30+E30 -> 0 | O30: =IF(B30>0,N30/B30,0) -> 0 | P30: =P29 -> 16240 | Q30: =(P30-P29)*1000 -> 0 | R30: =N30-Q30 -> 0 | S30: =S29 -> 9384 | T30: =S30-S29 -> 0 | U30: =U29 -> 258864 | V30: =U30-U29 -> 0 | W30: =W29 -> 32049 | X30: =W30-W29 -> 0 | Y30: =Y29 -> 673052 | Z30: =Y30-Y29 -> 0 | AA30: =AA29 -> 35482 | AB30: =AA30-AA29 -> 0 | AC30: =AC29 -> 871793 | AD30: =AC30-AC29 -> 0 | AE30: =AB30+X30+T30 -> 0 | AF30: =V30+Z30+AD30 -> 0 | AG30: =IF(AE30>0,AF30/AE30,0) -> 0 | AI30: =R30-'EDl log'!B28 -> -291983
A31: ='General information '!F34 -> 0 | B31: =SUM(230*A31) -> 0 | C31: 44072 | D31: =D30 -> 32126336 | E31: =D31-D30 -> 0 | F31: =F30 -> 3832913 | G31: =F31-F30 -> 0 | H31: =H30 -> 17626674 | I31: =H31-H30 -> 0 | J31: =J30 -> 28680930 | K31: =J31-J30 -> 0 | L31: =L30 -> 23526392 | M31: =L31-L30 -> 0 | N31: =M31+K31+I31+G31+E31 -> 0 | O31: =IF(B31>0,N31/B31,0) -> 0 | P31: =P30 -> 16240 | Q31: =(P31-P30)*1000 -> 0 | R31: =N31-Q31 -> 0 | S31: =S30 -> 9384 | T31: =S31-S30 -> 0 | U31: =U30 -> 258864 | V31: =U31-U30 -> 0 | W31: =W30 -> 32049 | X31: =W31-W30 -> 0 | Y31: =Y30 -> 673052 | Z31: =Y31-Y30 -> 0 | AA31: =AA30 -> 35482 | AB31: =AA31-AA30 -> 0 | AC31: =AC30 -> 871793 | AD31: =AC31-AC30 -> 0 | AE31: =AB31+X31+T31 -> 0 | AF31: =V31+Z31+AD31 -> 0 | AG31: =IF(AE31>0,AF31/AE31,0) -> 0 | AI31: =R31-'EDl log'!B29 -> -291983
A32: ='General information '!F35 -> 0 | B32: =SUM(230*A32) -> 0 | C32: 44073 | D32: =D31 -> 32126336 | E32: =D32-D31 -> 0 | F32: =F31 -> 3832913 | G32: =F32-F31 -> 0 | H32: =H31 -> 17626674 | I32: =H32-H31 -> 0 | J32: =J31 -> 28680930 | K32: =J32-J31 -> 0 | L32: =L31 -> 23526392 | M32: =L32-L31 -> 0 | N32: =M32+K32+I32+G32+E32 -> 0 | O32: =IF(B32>0,N32/B32,0) -> 0 | P32: =P31 -> 16240 | Q32: =(P32-P31)*1000 -> 0 | R32: =N32-Q32 -> 0 | S32: =S31 -> 9384 | T32: =S32-S31 -> 0 | U32: =U31 -> 258864 | V32: =U32-U31 -> 0 | W32: =W31 -> 32049 | X32: =W32-W31 -> 0 | Y32: =Y31 -> 673052 | Z32: =Y32-Y31 -> 0 | AA32: =AA31 -> 35482 | AB32: =AA32-AA31 -> 0 | AC32: =AC31 -> 871793 | AD32: =AC32-AC31 -> 0 | AE32: =AB32+X32+T32 -> 0 | AF32: =V32+Z32+AD32 -> 0 | AG32: =IF(AE32>0,AF32/AE32,0) -> 0 | AI32: =R32-'EDl log'!B30 -> -291983
A33: ='General information '!F36 -> 0 | B33: =SUM(230*A33) -> 0 | C33: 44074 | D33: =D32 -> 32126336 | E33: =D33-D32 -> 0 | F33: =F32 -> 3832913 | G33: =F33-F32 -> 0 | H33: =H32 -> 17626674 | I33: =H33-H32 -> 0 | J33: =J32 -> 28680930 | K33: =J33-J32 -> 0 | L33: =L32 -> 23526392 | M33: =L33-L32 -> 0 | N33: =M33+K33+I33+G33+E33 -> 0 | O33: =IF(B33>0,N33/B33,0) -> 0 | P33: =P32 -> 16240 | Q33: =(P33-P32)*1000 -> 0 | R33: =N33-Q33 -> 0 | S33: =S32 -> 9384 | T33: =S33-S32 -> 0 | U33: =U32 -> 258864 | V33: =U33-U32 -> 0 | W33: =W32 -> 32049 | X33: =W33-W32 -> 0 | Y33: =Y32 -> 673052 | Z33: =Y33-Y32 -> 0 | AA33: =AA32 -> 35482 | AB33: =AA33-AA32 -> 0 | AC33: =AC32 -> 871793 | AD33: =AC33-AC32 -> 0 | AE33: =AB33+X33+T33 -> 0 | AF33: =V33+Z33+AD33 -> 0 | AG33: =IF(AE33>0,AF33/AE33,0) -> 0 | AI33: =R33-'EDl log'!B31 -> -291983

Sheet B5
F1: Boiler A | J1: =J36 -> 1 | K1: Boiler B | P1: Boiler C | V1: Boiler | X1: SteamA | AC1: SteamB | AH1: Steam | AI1: Boiler & steam | AL1: Total Boiler Runing H | AM1: Total Steam Runing H | AN1: GAS1 % | AO1: GAS1/L | AP1: GAS2% | AQ1: Gas2/L | AR1: GAS3% | AS1: GAS3/L | AU1: Gas Cons | AV1: Delivery | AW1: Cost/L
B2: Level Tank Gen | C2: Level tank Boiler | D2: Daily Cons Bo. | E2: Boiler litter | F2: Boiler A | G2: Run Hr a | H2: Boiler A fuel | I2: Daily consumption | J2: AVG | K2: index Run H | L2: Run Hrb | M2: Boiler B Fuel | O2: Daily consumption | P2: Boiler C | S2: Run C | U2: Total RH | V2: Total Fuel | X2: SteamA | Y2: Run SA | Z2: Steam A Conter | AA2: Liters | AC2: SteamB | AD2: Run SteamB | AE2: Steam B Conter | AF2: SB Litters | AG2: Avg | AH2: Total Fuel | AI2: Total Fuel
S3: 0
A4: =ELEC!C2 -> 44043 | B4: =[1]B5!B35 -> 218 | C4: =[1]B5!C35 -> 223 | D4: =[1]B5!D35 -> -22 | E4: =[1]B5!E35 -> -184.36 | F4: =[1]B5!F35 -> 1648 | G4: =[1]B5!G35 -> 0 | H4: =[1]B5!H35 -> 357868 | I4: =[1]B5!I35 -> 0 | ... AX4: =[1]B5!AX35 -> 0.8
A5: =ELEC!C3 -> 44044 | B5: 197.3 | C5: 204 | D5: =C4-C5 -> 19 | E5: =D5*8.38 -> 159.22 | F5: =F4 -> 1648 | G5: =F5-F4 -> 0 | H5: =H4 -> 357868 | I5: =SUM(H5-H4) -> 0 | J5: 1 | K5: 2098 | L5: =K5-K4 -> 2 | M5: 153977 | N5: =M5-M4 -> 197 | O5: =O4 -> 211.875 | P5: 1835 | Q5: 155805 | R5: =Q5-Q4 -> 53 | S5: =SUM(P5-P4) -> 1 | T5: =SUM(S5*$T$2) -> 0 | U5: =SUM(G5+L5+S5) -> 3 | V5: =R5+N5+I5:I5 -> 250 | W5: =SUM(V5/U5) -> 83.333333 | X5: =X4 -> 2418 | Y5: =X5-X4 -> 0 | Z5: 135983 | AA5: =Z5-Z4 -> 19 | AB5: =SUM(Y5*$AB$2) -> 0 | AC5: 1923 | AD5: =AC5-AC4 -> 2 | AE5: 364710 | AF5: =AE5-AE4 -> 111 | AG5: =IF(AD5>0,AF5/AD5,0) -> 55.5 | AH5: =AF5+AA5 -> 130 | AI5: =SUM(AH5+V5) -> 380 | AJ5: =-tanks!AW6 -> 380 | AK5: =SUM(AJ5-AI5) -> 0 | AL5: =S5+L5+G5 -> 3 | AM5: =Y5+AD5 -> 2 | AN5: 75 | AO5: =(AN5/100)*3000 -> 2250 | AP5: 78 | AQ5: =(AP5/100)*3000 -> 2340 | AR5: 78 | AS5: =(AR5/100)*3000 -> 2340 | AT5: =SUM(AO5+AQ5+AS5) -> 6930 | AU5: =AT4-AT5+AV5 -> 150 | AX5: =IF(AV5>0,AW5,AX4) -> 0.8
A6: =ELEC!C4 -> 44045 | B6: 188 | C6: 194 | D6: =C5-C6 -> 10 | E6: =D6*8.38 -> 83.8 | F6: 1648 | G6: =F6-F5 -> 0 | H6: 357868 | I6: =SUM(H6-H5) -> 0 | J6: =IF(G6>0,I6/G6,0) -> 0 | K6: 2101 | L6: =K6-K5 -> 3 | M6: 154206 | N6: =M6-M5 -> 229 | O6: =O5 -> 211.875 | P6: 1835 | Q6: 155805 | R6: =Q6-Q5 -> 0 | S6: =SUM(P6-P5) -> 0 | T6: =SUM(S6*$T$2) -> 0 | U6: =SUM(G6+L6+S6) -> 3 | V6: =R6+N6+I6:I6 -> 229 | W6: =SUM(V6/U6) -> 76.333333 | X6: 2418 | Y6: =X6-X5 -> 0 | Z6: 135983 | AA6: =Z6-Z5 -> 0 | AB6: =SUM(Y6*$AB$2) -> 0 | AC6: 1923 | AD6: =AC6-AC5 -> 0 | AE6: 364710 | AF6: =AE6-AE5 -> 0 | AG6: =IF(AD6>0,AF6/AD6,0) -> 0 | AH6: =AF6+AA6 -> 0 | AI6: =SUM(AH6+V6) -> 229 | AJ6: =-tanks!AW7 -> 229 | AK6: =SUM(AJ6-AI6) -> 0 | AL6: =S6+L6+G6 -> 3 | AM6: =Y6+AD6 -> 0 | AN6: 70 | AO6: =(AN6/100)*3000 -> 2100 | AP6: 74 | AQ6: =(AP6/100)*3000 -> 2220 | AR6: 75 | AS6: =(AR6/100)*3000 -> 2250 | AT6: =SUM(AO6+AQ6+AS6) -> 6570 | AU6: =AT5-AT6+AV6 -> 360 | AX6: =IF(AV6>0,AW6,AX5) -> 0.8
A7: =ELEC!C5 -> 44046 | B7: 207 | C7: 213 | D7: =C6-C7 -> -19 | E7: =D7*8.38 -> -159.22 | F7: 1648 | G7: =F7-F6 -> 0 | H7: 357868 | I7: =SUM(H7-H6) -> 0 | J7: =IF(G7>0,I7/G7,0) -> 0 | K7: 2105 | L7: =K7-K6 -> 4 | M7: 154439 | N7: =M7-M6 -> 233 | O7: =O6 -> 211.875 | P7: 1835 | Q7: 155805 | R7: =Q7-Q6 -> 0 | S7: =SUM(P7-P6) -> 0 | T7: =SUM(S7*$T$2) -> 0 | U7: =SUM(G7+L7+S7) -> 4 | V7: =R7+N7+I7:I7 -> 233 | W7: =SUM(V7/U7) -> 58.25 | X7: 2418 | Y7: =X7-X6 -> 0 | Z7: 135983 | AA7: =Z7-Z6 -> 0 | AB7: =SUM(Y7*$AB$2) -> 0 | AC7: 1932 | AD7: =AC7-AC6 -> 9 | AE7: 365157 | AF7: =AE7-AE6 -> 447 | AG7: =IF(AD7>0,AF7/AD7,0) -> 49.666667 | AH7: =AF7+AA7 -> 447 | AI7: =SUM(AH7+V7) -> 680 | AJ7: =-tanks!AW8 -> 680 | AK7: =SUM(AJ7-AI7) -> 0 | AL7: =S7+L7+G7 -> 4 | AM7: =Y7+AD7 -> 9 | AN7: 67 | AO7: =(AN7/100)*3000 -> 2010 | AP7: 70 | AQ7: =(AP7/100)*3000 -> 2100 | AR7: 70 | AS7: =(AR7/100)*3000 -> 2100 | AT7: =SUM(AO7+AQ7+AS7) -> 6210 | AU7: =AT6-AT7+AV7 -> 360 | AX7: =IF(AV7>0,AW7,AX6) -> 0.8
A8: =ELEC!C6 -> 44047 | B8: 207 | C8: 194 | D8: =C7-C8 -> 19 | E8: =D8*8.38 -> 159.22 | F8: =F7 -> 1648 | G8: =F8-F7 -> 0 | H8: =H7 -> 357868 | I8: =SUM(H8-H7) -> 0 | J8: =IF(G8>0,I8/G8,0) -> 0 | K8: 2106 | L8: =K8-K7 -> 1 | M8: =M7 -> 154439 | N8: =M8-M7 -> 0 | O8: =O7 -> 211.875 | P8: =P7 -> 1835 | Q8: =Q7 -> 155805 | R8: =Q8-Q7 -> 0 | S8: =SUM(P8-P7) -> 0 | T8: =SUM(S8*$T$2) -> 0 | U8: =SUM(G8+L8+S8) -> 1 | V8: =R8+N8+I8:I8 -> 0 | W8: =SUM(V8/U8) -> 0 | X8: =X7 -> 2418 | Y8: =X8-X7 -> 0 | Z8: =Z7 -> 135983 | AA8: =Z8-Z7 -> 0 | AB8: =SUM(Y8*$AB$2) -> 0 | AC8: =AC7 -> 1932 | AD8: =AC8-AC7 -> 0 | AE8: =AE7 -> 365157 | AF8: =AE8-AE7 -> 0 | AG8: =IF(AD8>0,AF8/AD8,0) -> 0 | AH8: =AF8+AA8 -> 0 | AI8: =SUM(AH8+V8) -> 0 | AJ8: =-tanks!AW9 -> 0 | AK8: =SUM(AJ8-AI8) -> 0 | AL8: =S8+L8+G8 -> 1 | AM8: =Y8+AD8 -> 0 | AN8: =AN7 -> 67 | AO8: =(AN8/100)*3000 -> 2010 | AP8: =AP7 -> 70 | AQ8: =(AP8/100)*3000 -> 2100 | AR8: =AR7 -> 70 | AS8: =(AR8/100)*3000 -> 2100 | AT8: =SUM(AO8+AQ8+AS8) -> 6210 | AU8: =AT7-AT8+AV8 -> 0 | AX8: =IF(AV8>0,AW8,AX7) -> 0.8
A9: =ELEC!C7 -> 44048 | B9: 187 | C9: 194 | D9: =C8-C9 -> 0 | E9: =D9*8.38 -> 0 | F9: 1648 | G9: =F9-F8 -> 0 | H9: 357868 | I9: =SUM(H9-H8) -> 0 | J9: =IF(G9>0,I9/G9,0) -> 0 | K9: 2106 | L9: =K9-K8 -> 0 | M9: 154583 | N9: =M9-M8 -> 144 | O9: =O8 -> 211.875 | P9: 1835 | Q9: 155805 | R9: =Q9-Q8 -> 0 | S9: =SUM(P9-P8) -> 0 | T9: =SUM(S9*$T$2) -> 0 | U9: =SUM(G9+L9+S9) -> 0 | V9: =R9+N9+I9:I9 -> 144 | W9: =SUM(V9/U9) -> #DIV/0! | X9: 2418 | Y9: =X9-X8 -> 0 | Z9: 135983 | AA9: =Z9-Z8 -> 0 | AB9: =SUM(Y9*$AB$2) -> 0 | AC9: 1932 | AD9: =AC9-AC8 -> 0 | AE9: 365157 | AF9: =AE9-AE8 -> 0 | AG9: =IF(AD9>0,AF9/AD9,0) -> 0 | AH9: =AF9+AA9 -> 0 | AI9: =SUM(AH9+V9) -> 144 | AJ9: =-tanks!AW10 -> 144 | AK9: =SUM(AJ9-AI9) -> 0 | AL9: =S9+L9+G9 -> 0 | AM9: =Y9+AD9 -> 0 | AN9: =AN8 -> 67 | AO9: =(AN9/100)*3000 -> 2010 | AP9: =AP8 -> 70 | AQ9: =(AP9/100)*3000 -> 2100 | AR9: =AR8 -> 70 | AS9: =(AR9/100)*3000 -> 2100 | AT9: =SUM(AO9+AQ9+AS9) -> 6210 | AU9: =AT8-AT9+AV9 -> 0 | AX9: =IF(AV9>0,AW9,AX8) -> 0.8
A10: =ELEC!C8 -> 44049 | B10: 186 | C10: 192 | D10: =C9-C10 -> 2 | E10: =D10*8.38 -> 16.76 | F10: =F9 -> 1648 | G10: =F10-F9 -> 0 | H10: =H9 -> 357868 | I10: =SUM(H10-H9) -> 0 | J10: =IF(G10>0,I10/G10,0) -> 0 | K10: 2106 | L10: =K10-K9 -> 0 | M10: =M9 -> 154583 | N10: =M10-M9 -> 0 | O10: =O9 -> 211.875 | P10: =P9 -> 1835 | Q10: =Q9 -> 155805 | R10: =Q10-Q9 -> 0 | S10: =SUM(P10-P9) -> 0 | T10: =SUM(S10*$T$2) -> 0 | U10: =SUM(G10+L10+S10) -> 0 | V10: =R10+N10+I10:I10 -> 0 | W10: =SUM(V10/U10) -> #DIV/0! | X10: =X9 -> 2418 | Y10: =X10-X9 -> 0 | Z10: =Z9 -> 135983 | AA10: =Z10-Z9 -> 0 | AB10: =SUM(Y10*$AB$2) -> 0 | AC10: =AC9 -> 1932 | AD10: =AC10-AC9 -> 0 | AE10: =AE9 -> 365157 | AF10: =AE10-AE9 -> 0 | AG10: =IF(AD10>0,AF10/AD10,0) -> 0 | AH10: =AF10+AA10 -> 0 | AI10: =SUM(AH10+V10) -> 0 | AJ10: =-tanks!AW11 -> 0 | AK10: =SUM(AJ10-AI10) -> 0 | AL10: =S10+L10+G10 -> 0 | AM10: =Y10+AD10 -> 0 | AN10: =AN9 -> 67 | AO10: =(AN10/100)*3000 -> 2010 | AP10: =AP9 -> 70 | AQ10: =(AP10/100)*3000 -> 2100 | AR10: =AR9 -> 70 | AS10: =(AR10/100)*3000 -> 2100 | AT10: =SUM(AO10+AQ10+AS10) -> 6210 | AU10: =AT9-AT10+AV10 -> 0 | AX10: =IF(AV10>0,AW10,AX9) -> 0.8
A11: =ELEC!C9 -> 44050 | B11: 268 | C11: 226 | D11: =C10-C11 -> -34 | E11: =D11*8.38 -> -284.92 | F11: 1648 | G11: =F11-F10 -> 0 | H11: 357868 | I11: =SUM(H11-H10) -> 0 | J11: =IF(G11>0,I11/G11,0) -> 0 | K11: 2106 | L11: =K11-K10 -> 0 | M11: 154583 | N11: =M11-M10 -> 0 | O11: =O10 -> 211.875 | P11: 1835 | Q11: 155805 | R11: =Q11-Q10 -> 0 | S11: =SUM(P11-P10) -> 0 | T11: =SUM(S11*$T$2) -> 0 | U11: =SUM(G11+L11+S11) -> 0 | V11: =R11+N11+I11:I11 -> 0 | W11: =SUM(V11/U11) -> #DIV/0! | X11: =X10 -> 2418 | Y11: =X11-X10 -> 0 | Z11: 135983 | AA11: =Z11-Z10 -> 0 | AB11: =SUM(Y11*$AB$2) -> 0 | AC11: 1932 | AD11: =AC11-AC10 -> 0 | AE11: 365157 | AF11: =AE11-AE10 -> 0 | AG11: =IF(AD11>0,AF11/AD11,0) -> 0 | AH11: =AF11+AA11 -> 0 | AI11: =SUM(AH11+V11) -> 0 | AJ11: =-tanks!AW12 -> 0 | AK11: =SUM(AJ11-AI11) -> 0 | AL11: =S11+L11+G11 -> 0 | AM11: =Y11+AD11 -> 0 | AN11: =AN10 -> 67 | AO11: =(AN11/100)*3000 -> 2010 | AP11: =AP10 -> 70 | AQ11: =(AP11/100)*3000 -> 2100 | AR11: =AR10 -> 70 | AS11: =(AR11/100)*3000 -> 2100 | AT11: =SUM(AO11+AQ11+AS11) -> 6210 | AU11: =AT10-AT11+AV11 -> 0 | AX11: =IF(AV11>0,AW11,AX10) -> 0.8
A12: =ELEC!C10 -> 44051 | B12: 253.3 | C12: 259.5 | D12: =C11-C12 -> -33.5 | E12: =D12*8.38 -> -280.73 | F12: 1648 | G12: =F12-F11 -> 0 | H12: =H11 -> 357868 | I12: =SUM(H12-H11) -> 0 | J12: =IF(G12>0,I12/G12,0) -> 0 | K12: =K11 -> 2106 | L12: =K12-K11 -> 0 | M12: =M11 -> 154583 | N12: =M12-M11 -> 0 | O12: =O11 -> 211.875 | P12: =P11 -> 1835 | Q12: =Q11 -> 155805 | R12: =Q12-Q11 -> 0 | S12: =SUM(P12-P11) -> 0 | T12: =SUM(S12*$T$2) -> 0 | U12: =SUM(G12+L12+S12) -> 0 | V12: =R12+N12+I12:I12 -> 0 | W12: =SUM(V12/U12) -> #DIV/0! | X12: =X11 -> 2418 | Y12: =X12-X11 -> 0 | Z12: =Z11 -> 135983 | AA12: =Z12-Z11 -> 0 | AB12: =SUM(Y12*$AB$2) -> 0 | AC12: =AC11 -> 1932 | AD12: =AC12-AC11 -> 0 | AE12: =AE11 -> 365157 | AF12: =AE12-AE11 -> 0 | AG12: =IF(AD12>0,AF12/AD12,0) -> 0 | AH12: =AF12+AA12 -> 0 | AI12: =SUM(AH12+V12) -> 0 | AJ12: =-tanks!AW13 -> 0 | AK12: =SUM(AJ12-AI12) -> 0 | AL12: =S12+L12+G12 -> 0 | AM12: =Y12+AD12 -> 0 | AN12: =AN11 -> 67 | AO12: =(AN12/100)*3000 -> 2010 | AP12: =AP11 -> 70 | AQ12: =(AP12/100)*3000 -> 2100 | AR12: =AR11 -> 70 | AS12: =(AR12/100)*3000 -> 2100 | AT12: =SUM(AO12+AQ12+AS12) -> 6210 | AU12: =AT11-AT12+AV12 -> 0 | AX12: =IF(AV12>0,AW12,AX11) -> 0.8
A13: =ELEC!C11 -> 44052 | B13: 251.4 | C13: 257.4 | D13: =C12-C13 -> 2.1 | E13: =D13*8.38 -> 17.598 | F13: =F12 -> 1648 | G13: =F13-F12 -> 0 | H13: =H12 -> 357868 | I13: =SUM(H13-H12) -> 0 | J13: =IF(G13>0,I13/G13,0) -> 0 | K13: =K12 -> 2106 | L13: =K13-K12 -> 0 | M13: =M12 -> 154583 | N13: =M13-M12 -> 0 | O13: =O12 -> 211.875 | P13: =P12 -> 1835 | Q13: =Q12 -> 155805 | R13: =Q13-Q12 -> 0 | S13: =SUM(P13-P12) -> 0 | T13: =SUM(S13*$T$2) -> 0 | U13: =SUM(G13+L13+S13) -> 0 | V13: =R13+N13+I13:I13 -> 0 | W13: =SUM(V13/U13) -> #DIV/0! | X13: =X12 -> 2418 | Y13: =X13-X12 -> 0 | Z13: =Z12 -> 135983 | AA13: =Z13-Z12 -> 0 | AB13: =SUM(Y13*$AB$2) -> 0 | AC13: =AC12 -> 1932 | AD13: =AC13-AC12 -> 0 | AE13: =AE12 -> 365157 | AF13: =AE13-AE12 -> 0 | AG13: =IF(AD13>0,AF13/AD13,0) -> 0 | AH13: =AF13+AA13 -> 0 | AI13: =SUM(AH13+V13) -> 0 | AJ13: =-tanks!AW14 -> 0 | AK13: =SUM(AJ13-AI13) -> 0 | AL13: =S13+L13+G13 -> 0 | AM13: =Y13+AD13 -> 0 | AN13: =AN12 -> 67 | AO13: =(AN13/100)*3000 -> 2010 | AP13: =AP12 -> 70 | AQ13: =(AP13/100)*3000 -> 2100 | AR13: =AR12 -> 70 | AS13: =(AR13/100)*3000 -> 2100 | AT13: =SUM(AO13+AQ13+AS13) -> 6210 | AU13: =AT12-AT13+AV13 -> 0 | AX13: =IF(AV13>0,AW13,AX12) -> 0.8
A14: =ELEC!C12 -> 44053 | B14: 250 | C14: 255.4 | D14: =C13-C14 -> 2 | E14: =D14*8.38 -> 16.76 | F14: 1648 | G14: =F14-F13 -> 0 | H14: 357868 | I14: =SUM(H14-H13) -> 0 | J14: =IF(G14>0,I14/G14,0) -> 0 | K14: =K13 -> 2106 | L14: =K14-K13 -> 0 | M14: =M13 -> 154583 | N14: =M14-M13 -> 0 | O14: =O13 -> 211.875 | P14: =P13 -> 1835 | Q14: =Q13 -> 155805 | R14: =Q14-Q13 -> 0 | S14: =SUM(P14-P13) -> 0 | T14: =SUM(S14*$T$2) -> 0 | U14: =SUM(G14+L14+S14) -> 0 | V14: =R14+N14+I14:I14 -> 0 | W14: =SUM(V14/U14) -> #DIV/0! | X14: =X13 -> 2418 | Y14: =X14-X13 -> 0 | Z14: =Z13 -> 135983 | AA14: =Z14-Z13 -> 0 | AB14: =SUM(Y14*$AB$2) -> 0 | AC14: =AC13 -> 1932 | AD14: =AC14-AC13 -> 0 | AE14: =AE13 -> 365157 | AF14: =AE14-AE13 -> 0 | AG14: =IF(AD14>0,AF14/AD14,0) -> 0 | AH14: =AF14+AA14 -> 0 | AI14: =SUM(AH14+V14) -> 0 | AJ14: =-tanks!AW15 -> 0 | AK14: =SUM(AJ14-AI14) -> 0 | AL14: =S14+L14+G14 -> 0 | AM14: =Y14+AD14 -> 0 | AN14: =AN13 -> 67 | AO14: =(AN14/100)*3000 -> 2010 | AP14: =AP13 -> 70 | AQ14: =(AP14/100)*3000 -> 2100 | AR14: =AR13 -> 70 | AS14: =(AR14/100)*3000 -> 2100 | AT14: =SUM(AO14+AQ14+AS14) -> 6210 | AU14: =AT13-AT14+AV14 -> 0 | AX14: =IF(AV14>0,AW14,AX13) -> 0.8
A15: =ELEC!C13 -> 44054 | B15: 248 | C15: 253.3 | D15: =C14-C15 -> 2.1 | E15: =D15*8.38 -> 17.598 | F15: 1648 | G15: =F15-F14 -> 0 | H15: =H14 -> 357868 | I15: =SUM(H15-H14) -> 0 | J15: =IF(G15>0,I15/G15,0) -> 0 | K15: 2107 | L15: =K15-K14 -> 1 | M15: 154592 | N15: =M15-M14 -> 9 | O15: =O14 -> 211.875 | P15: 1835 | Q15: =Q14 -> 155805 | R15: =Q15-Q14 -> 0 | S15: =SUM(P15-P14) -> 0 | T15: =SUM(S15*$T$2) -> 0 | U15: =SUM(G15+L15+S15) -> 1 | V15: =R15+N15+I15:I15 -> 9 | W15: =SUM(V15/U15) -> 9 | X15: 2419 | Y15: =X15-X14 -> 1 | Z15: 136036 | AA15: =Z15-Z14 -> 53 | AB15: =SUM(Y15*$AB$2) -> 0 | AC15: 1933 | AD15: =AC15-AC14 -> 1 | AE15: 365210.2 | AF15: =AE15-AE14 -> 53.2 | AG15: =IF(AD15>0,AF15/AD15,0) -> 53.2 | AH15: =AF15+AA15 -> 106.2 | AI15: =SUM(AH15+V15) -> 115.2 | AJ15: =-tanks!AW16 -> 115.2 | AK15: =SUM(AJ15-AI15) -> 0 | AL15: =S15+L15+G15 -> 1 | AM15: =Y15+AD15 -> 2 | AN15: =AN14 -> 67 | AO15: =(AN15/100)*3000 -> 2010 | AP15: =AP14 -> 70 | AQ15: =(AP15/100)*3000 -> 2100 | AR15: =AR14 -> 70 | AS15: =(AR15/100)*3000 -> 2100 | AT15: =SUM(AO15+AQ15+AS15) -> 6210 | AU15: =AT14-AT15+AV15 -> 0 | AX15: =IF(AV15>0,AW15,AX14) -> 0.8
A16: =ELEC!C14 -> 44055 | B16: 242.4 | C16: 248 | D16: =C15-C16 -> 5.3 | E16: =D16*8.38 -> 44.414 | F16: 1648 | G16: =F16-F15 -> 0 | H16: =H15 -> 357868 | I16: =SUM(H16-H15) -> 0 | J16: =IF(G16>0,I16/G16,0) -> 0 | K16: =K15 -> 2107 | L16: =K16-K15 -> 0 | M16: =M15 -> 154592 | N16: =M16-M15 -> 0 | O16: =O15 -> 211.875 | P16: =P15 -> 1835 | Q16: =Q15 -> 155805 | R16: =Q16-Q15 -> 0 | S16: =SUM(P16-P15) -> 0 | T16: =SUM(S16*$T$2) -> 0 | U16: =SUM(G16+L16+S16) -> 0 | V16: =R16+N16+I16:I16 -> 0 | W16: =SUM(V16/U16) -> #DIV/0! | X16: =X15 -> 2419 | Y16: =X16-X15 -> 0 | Z16: =Z15 -> 136036 | AA16: =Z16-Z15 -> 0 | AB16: =SUM(Y16*$AB$2) -> 0 | AC16: =AC15 -> 1933 | AD16: =AC16-AC15 -> 0 | AE16: =AE15 -> 365210.2 | AF16: =AE16-AE15 -> 0 | AG16: =IF(AD16>0,AF16/AD16,0) -> 0 | AH16: =AF16+AA16 -> 0 | AI16: =SUM(AH16+V16) -> 0 | AJ16: =-tanks!AW17 -> 0 | AK16: =SUM(AJ16-AI16) -> 0 | AL16: =S16+L16+G16 -> 0 | AM16: =Y16+AD16 -> 0 | AN16: =AN15 -> 67 | AO16: =(AN16/100)*3000 -> 2010 | AP16: =AP15 -> 70 | AQ16: =(AP16/100)*3000 -> 2100 | AR16: =AR15 -> 70 | AS16: =(AR16/100)*3000 -> 2100 | AT16: =SUM(AO16+AQ16+AS16) -> 6210 | AU16: =AT15-AT16+AV16 -> 0 | AX16: =IF(AV16>0,AW16,AX15) -> 0.8
A17: =ELEC!C15 -> 44056 | B17: =B16 -> 242.4 | C17: =C16 -> 248 | D17: =C16-C17 -> 0 | E17: =D17*8.38 -> 0 | F17: =F16 -> 1648 | G17: =F17-F16 -> 0 | H17: =H16 -> 357868 | I17: =SUM(H17-H16) -> 0 | J17: =IF(G17>0,I17/G17,0) -> 0 | K17: =K16 -> 2107 | L17: =K17-K16 -> 0 | M17: =M16 -> 154592 | N17: =M17-M16 -> 0 | O17: =O16 -> 211.875 | P17: =P16 -> 1835 | Q17: =Q16 -> 155805 | R17: =Q17-Q16 -> 0 | S17: =SUM(P17-P16) -> 0 | T17: =SUM(S17*$T$2) -> 0 | U17: =SUM(G17+L17+S17) -> 0 | V17: =R17+N17+I17:I17 -> 0 | X17: =X16 -> 2419 | Y17: =X17-X16 -> 0 | Z17: =Z16 -> 136036 | AA17: =Z17-Z16 -> 0 | AB17: =SUM(Y17*$AB$2) -> 0 | AC17: =AC16 -> 1933 | AD17: =AC17-AC16 -> 0 | AE17: =AE16 -> 365210.2 | AF17: =AE17-AE16 -> 0 | AG17: =IF(AD17>0,AF17/AD17,0) -> 0 | AH17: =AF17+AA17 -> 0 | AI17: =SUM(AH17+V17) -> 0 | AJ17: =-tanks!AW18 -> 0 | AK17: =SUM(AJ17-AI17) -> 0 | AL17: =S17+L17+G17 -> 0 | AM17: =Y17+AD17 -> 0 | AN17: =AN16 -> 67 | AO17: =(AN17/100)*3000 -> 2010 | AP17: =AP16 -> 70 | AQ17: =(AP17/100)*3000 -> 2100 | AR17: =AR16 -> 70 | AS17: =(AR17/100)*3000 -> 2100 | AT17: =SUM(AO17+AQ17+AS17) -> 6210 | AU17: =AT16-AT17+AV17 -> 0 | AX17: =IF(AV17>0,AW17,AX16) -> 0.8
A18: =ELEC!C16 -> 44057 | B18: 238 | C18: 244.5 | D18: =C17-C18 -> 3.5 | E18: =D18*8.38 -> 29.33 | F18: =F17 -> 1648 | G18: =F18-F17 -> 0 | H18: =H17 -> 357868 | I18: =SUM(H18-H17) -> 0 | J18: =IF(G18>0,I18/G18,0) -> 0 | K18: =K17 -> 2107 | L18: =K18-K17 -> 0 | M18: =M17 -> 154592 | N18: =M18-M17 -> 0 | O18: =O17 -> 211.875 | P18: =P17 -> 1835 | Q18: =Q17 -> 155805 | R18: =Q18-Q17 -> 0 | S18: =SUM(P18-P17) -> 0 | T18: =SUM(S18*$T$2) -> 0 | U18: =SUM(G18+L18+S18) -> 0 | V18: =R18+N18+I18:I18 -> 0 | X18: =X17 -> 2419 | Y18: =X18-X17 -> 0 | Z18: =Z17 -> 136036 | AA18: =Z18-Z17 -> 0 | AB18: =SUM(Y18*$AB$2) -> 0 | AC18: =AC17 -> 1933 | AD18: =AC18-AC17 -> 0 | AE18: =AE17 -> 365210.2 | AF18: =AE18-AE17 -> 0 | AG18: =IF(AD18>0,AF18/AD18,0) -> 0 | AH18: =AF18+AA18 -> 0 | AI18: =SUM(AH18+V18) -> 0 | AJ18: =-tanks!AW19 -> 0 | AK18: =SUM(AJ18-AI18) -> 0 | AL18: =S18+L18+G18 -> 0 | AM18: =Y18+AD18 -> 0 | AN18: =AN17 -> 67 | AO18: =(AN18/100)*3000 -> 2010 | AP18: =AP17 -> 70 | AQ18: =(AP18/100)*3000 -> 2100 | AR18: =AR17 -> 70 | AS18: =(AR18/100)*3000 -> 2100 | AT18: =SUM(AO18+AQ18+AS18) -> 6210 | AU18: =AT17-AT18+AV18 -> 0 | AX18: =IF(AV18>0,AW18,AX17) -> 0.8
A19: =ELEC!C17 -> 44058 | B19: 235 | C19: 241.2 | D19: =C18-C19 -> 3.3 | E19: =D19*8.38 -> 27.654 | F19: =F18 -> 1648 | G19: =F19-F18 -> 0 | H19: =H18 -> 357868 | I19: =SUM(H19-H18) -> 0 | J19: =IF(G19>0,I19/G19,0) -> 0 | K19: =K18 -> 2107 | L19: =K19-K18 -> 0 | M19: =M18 -> 154592 | N19: =M19-M18 -> 0 | O19: =O18 -> 211.875 | P19: =P18 -> 1835 | Q19: =Q18 -> 155805 | R19: =Q19-Q18 -> 0 | S19: =SUM(P19-P18) -> 0 | T19: =SUM(S19*$T$2) -> 0 | U19: =SUM(G19+L19+S19) -> 0 | V19: =R19+N19+I19:I19 -> 0 | X19: =X18 -> 2419 | Y19: =X19-X18 -> 0 | Z19: =Z18 -> 136036 | AA19: =Z19-Z18 -> 0 | AB19: =SUM(Y19*$AB$2) -> 0 | AC19: =AC18 -> 1933 | AD19: =AC19-AC18 -> 0 | AE19: =AE18 -> 365210.2 | AF19: =AE19-AE18 -> 0 | AG19: =IF(AD19>0,AF19/AD19,0) -> 0 | AH19: =AF19+AA19 -> 0 | AI19: =SUM(AH19+V19) -> 0 | AJ19: =-tanks!AW20 -> 0 | AK19: =SUM(AJ19-AI19) -> 0 | AL19: =S19+L20+G19 -> 0 | AM19: =Y19+AD19 -> 0 | AN19: =AN18 -> 67 | AO19: =(AN19/100)*3000 -> 2010 | AP19: =AP18 -> 70 | AQ19: =(AP19/100)*3000 -> 2100 | AR19: =AR18 -> 70 | AS19: =(AR19/100)*3000 -> 2100 | AT19: =SUM(AO19+AQ19+AS19) -> 6210 | AU19: =AT18-AT19+AV19 -> 0 | AX19: =IF(AV19>0,AW19,AX18) -> 0.8
A20: =ELEC!C18 -> 44059 | B20: 234.4 | C20: 240.1 | D20: =C19-C20 -> 1.1 | E20: =D20*8.38 -> 9.218 | F20: =F19 -> 1648 | G20: =F20-F19 -> 0 | H20: =H19 -> 357868 | I20: =SUM(H20-H19) -> 0 | J20: =IF(G20>0,I20/G20,0) -> 0 | K20: =K19 -> 2107 | L20: =K20-K19 -> 0 | M20: =M19 -> 154592 | N20: =M20-M19 -> 0 | O20: =O19 -> 211.875 | P20: =P19 -> 1835 | Q20: =Q19 -> 155805 | R20: =Q20-Q19 -> 0 | S20: =SUM(P20-P19) -> 0 | T20: =SUM(S20*$T$2) -> 0 | U20: =SUM(G20+L20+S20) -> 0 | V20: =R20+N20+I20:I20 -> 0 | X20: =X19 -> 2419 | Y20: =X20-X19 -> 0 | Z20: =Z19 -> 136036 | AA20: =Z20-Z19 -> 0 | AB20: =SUM(Y20*$AB$2) -> 0 | AC20: =AC19 -> 1933 | AD20: =AC20-AC19 -> 0 | AE20: =AE19 -> 365210.2 | AF20: =AE20-AE19 -> 0 | AG20: =IF(AD20>0,AF20/AD20,0) -> 0 | AH20: =AF20+AA20 -> 0 | AI20: =SUM(AH20+V20) -> 0 | AJ20: =-tanks!AW21 -> 0 | AK20: =SUM(AJ20-AI20) -> 0 | AL20: =S20+L21+G20 -> 0 | AM20: =Y20+AD20 -> 0 | AN20: =AN19 -> 67 | AO20: =(AN20/100)*3000 -> 2010 | AP20: =AP19 -> 70 | AQ20: =(AP20/100)*3000 -> 2100 | AR20: =AR19 -> 70 | AS20: =(AR20/100)*3000 -> 2100 | AT20: =SUM(AO20+AQ20+AS20) -> 6210 | AU20: =AT19-AT20+AV20 -> 0 | AX20: =IF(AV20>0,AW20,AX19) -> 0.8
A21: 232 | B21: 232 | C21: 238.1 | D21: =C20-C21 -> 2 | E21: =D21*8.38 -> 16.76 | F21: =F20 -> 1648 | G21: =F21-F20 -> 0 | H21: =H20 -> 357868 | I21: =SUM(H21-H20) -> 0 | J21: =IF(G21>0,I21/G21,0) -> 0 | K21: =K20 -> 2107 | L21: =K21-K20 -> 0 | M21: =M20 -> 154592 | N21: =M21-M20 -> 0 | O21: =O20 -> 211.875 | P21: =P20 -> 1835 | Q21: =Q20 -> 155805 | R21: =Q21-Q20 -> 0 | S21: =SUM(P21-P20) -> 0 | T21: =SUM(S21*$T$2) -> 0 | U21: =SUM(G21+L21+S21) -> 0 | V21: =R21+N21+I21:I21 -> 0 | X21: =X20 -> 2419 | Y21: =X21-X20 -> 0 | Z21: =Z20 -> 136036 | AA21: =Z21-Z20 -> 0 | AB21: =SUM(Y21*$AB$2) -> 0 | AC21: =AC20 -> 1933 | AD21: =AC21-AC20 -> 0 | AE21: =AE20 -> 365210.2 | AF21: =AE21-AE20 -> 0 | AG21: =IF(AD21>0,AF21/AD21,0) -> 0 | AH21: =AF21+AA21 -> 0 | AI21: =SUM(AH21+V21) -> 0 | AJ21: =-tanks!AW22 -> 0 | AK21: =SUM(AJ21-AI21) -> 0 | AL21: =S21+L21+G21 -> 0 | AM21: =Y21+AD21 -> 0 | AN21: =AN20 -> 67 | AO21: =(AN21/100)*3000 -> 2010 | AP21: =AP20 -> 70 | AQ21: =(AP21/100)*3000 -> 2100 | AR21: =AR20 -> 70 | AS21: =(AR21/100)*3000 -> 2100 | AT21: =SUM(AO21+AQ21+AS21) -> 6210 | AU21: =AT20-AT21+AV21 -> 0 | AX21: =IF(AV21>0,AW21,AX20) -> 0.8
A22: =ELEC!C20 -> 44061 | B22: 230 | C22: 236 | D22: =C21-C22 -> 2.1 | E22: =D22*8.38 -> 17.598 | F22: =F21 -> 1648 | G22: =F22-F21 -> 0 | H22: =H21 -> 357868 | I22: =SUM(H22-H21) -> 0 | J22: =IF(G22>0,I22/G22,0) -> 0 | K22: 2108 | L22: =K22-K21 -> 1 | M22: 154682 | N22: =M22-M21 -> 90 | O22: =O21 -> 211.875 | P22: 1837 | Q22: 155926 | R22: =Q22-Q21 -> 121 | S22: =SUM(P22-P21) -> 2 | T22: =SUM(S22*$T$2) -> 0 | U22: =SUM(G22+L22+S22) -> 3 | V22: =R22+N22+I22:I22 -> 211 | X22: 2424 | Y22: =X22-X21 -> 5 | Z22: 136280 | AA22: =Z22-Z21 -> 244 | AB22: =SUM(Y22*$AB$2) -> 0 | AC22: =AC21 -> 1933 | AD22: =AC22-AC21 -> 0 | AE22: =AE21 -> 365210.2 | AF22: =AE22-AE21 -> 0 | AG22: =IF(AD22>0,AF22/AD22,0) -> 0 | AH22: =AF22+AA22 -> 244 | AI22: =SUM(AH22+V22) -> 455 | AJ22: =-tanks!AW23 -> 455 | AK22: =SUM(AJ22-AI22) -> 0 | AL22: =S22+L22+G22 -> 3 | AM22: =Y22+AD22 -> 5 | AN22: =AN21 -> 67 | AO22: =(AN22/100)*3000 -> 2010 | AP22: =AP21 -> 70 | AQ22: =(AP22/100)*3000 -> 2100 | AR22: =AR21 -> 70 | AS22: =(AR22/100)*3000 -> 2100 | AT22: =SUM(AO22+AQ22+AS22) -> 6210 | AU22: =AT21-AT22+AV22 -> 0 | AX22: =IF(AV22>0,AW22,AX21) -> 0.8
A23: =ELEC!C21 -> 44062 | B23: =B22 -> 230 | C23: =C22 -> 236 | D23: =C22-C23 -> 0 | E23: =D23*8.38 -> 0 | F23: =F22 -> 1648 | G23: =F23-F22 -> 0 | H23: =H22 -> 357868 | I23: =SUM(H23-H22) -> 0 | J23: =IF(G23>0,I23/G23,0) -> 0 | K23: =K22 -> 2108 | L23: =K23-K22 -> 0 | M23: =M22 -> 154682 | N23: =M23-M22 -> 0 | O23: =O22 -> 211.875 | P23: =P22 -> 1837 | Q23: =Q22 -> 155926 | R23: =Q23-Q22 -> 0 | S23: =SUM(P23-P22) -> 0 | T23: =SUM(S23*$T$2) -> 0 | U23: =SUM(G23+L23+S23) -> 0 | V23: =R23+N23+I23:I23 -> 0 | X23: =X22 -> 2424 | Y23: =X23-X22 -> 0 | Z23: =Z22 -> 136280 | AA23: =Z23-Z22 -> 0 | AB23: =SUM(Y23*$AB$2) -> 0 | AC23: =AC22 -> 1933 | AD23: =AC23-AC22 -> 0 | AE23: =AE22 -> 365210.2 | AF23: =AE23-AE22 -> 0 | AG23: =IF(AD23>0,AF23/AD23,0) -> 0 | AH23: =AF23+AA23 -> 0 | AI23: =SUM(AH23+V23) -> 0 | AJ23: =-tanks!AW24 -> 0 | AK23: =SUM(AJ23-AI23) -> 0 | AL23: =S23+L23+G23 -> 0 | AM23: =Y23+AD23 -> 0 | AN23: =AN22 -> 67 | AO23: =(AN23/100)*3000 -> 2010 | AP23: =AP22 -> 70 | AQ23: =(AP23/100)*3000 -> 2100 | AR23: =AR22 -> 70 | AS23: =(AR23/100)*3000 -> 2100 | AT23: =SUM(AO23+AQ23+AS23) -> 6210 | AU23: =AT22-AT23+AV23 -> 0 | AX23: =IF(AV23>0,AW23,AX22) -> 0.8
A24: =ELEC!C22 -> 44063 | B24: =B23 -> 230 | C24: =C23 -> 236 | D24: =C23-C24 -> 0 | E24: =D24*8.38 -> 0 | F24: =F23 -> 1648 | G24: =F24-F23 -> 0 | H24: =H23 -> 357868 | I24: =SUM(H24-H23) -> 0 | J24: =IF(G24>0,I24/G24,0) -> 0 | K24: =K23 -> 2108 | L24: =K24-K23 -> 0 | M24: =M23 -> 154682 | N24: =M24-M23 -> 0 | O24: =O23 -> 211.875 | P24: =P23 -> 1837 | Q24: =Q23 -> 155926 | R24: =Q24-Q23 -> 0 | S24: =SUM(P24-P23) -> 0 | T24: =SUM(S24*$T$2) -> 0 | U24: =SUM(G24+L24+S24) -> 0 | V24: =R24+N24+I24:I24 -> 0 | X24: =X23 -> 2424 | Y24: =X24-X23 -> 0 | Z24: =Z23 -> 136280 | AA24: =Z24-Z23 -> 0 | AB24: =SUM(Y24*$AB$2) -> 0 | AC24: =AC23 -> 1933 | AD24: =AC24-AC23 -> 0 | AE24: =AE23 -> 365210.2 | AF24: =AE24-AE23 -> 0 | AG24: =IF(AD24>0,AF24/AD24,0) -> 0 | AH24: =AF24+AA24 -> 0 | AI24: =SUM(AH24+V24) -> 0 | AJ24: =-tanks!AW25 -> 0 | AK24: =SUM(AJ24-AI24) -> 0 | AL24: =S24+L24+G24 -> 0 | AM24: =Y24+AD24 -> 0 | AN24: =AN23 -> 67 | AO24: =(AN24/100)*3000 -> 2010 | AP24: =AP23 -> 70 | AQ24: =(AP24/100)*3000 -> 2100 | AR24: =AR23 -> 70 | AS24: =(AR24/100)*3000 -> 2100 | AT24: =SUM(AO24+AQ24+AS24) -> 6210 | AU24: =AT23-AT24+AV24 -> 0 | AX24: =IF(AV24>0,AW24,AX23) -> 0.8
A25: =ELEC!C23 -> 44064 | B25: =B24 -> 230 | C25: =C24 -> 236 | D25: =C24-C25 -> 0 | E25: =D25*8.38 -> 0 | F25: =F24 -> 1648 | G25: =F25-F24 -> 0 | H25: =H24 -> 357868 | I25: =SUM(H25-H24) -> 0 | J25: =IF(G25>0,I25/G25,0) -> 0 | K25: =K24 -> 2108 | L25: =K25-K24 -> 0 | M25: =M24 -> 154682 | N25: =M25-M24 -> 0 | O25: =O24 -> 211.875 | P25: =P24 -> 1837 | Q25: =Q24 -> 155926 | R25: =Q25-Q24 -> 0 | S25: =SUM(P25-P24) -> 0 | T25: =SUM(S25*$T$2) -> 0 | U25: =SUM(G25+L25+S25) -> 0 | V25: =R25+N25+I25:I25 -> 0 | X25: =X24 -> 2424 | Y25: =X25-X24 -> 0 | Z25: =Z24 -> 136280 | AA25: =Z25-Z24 -> 0 | AB25: =SUM(Y25*$AB$2) -> 0 | AC25: =AC24 -> 1933 | AD25: =AC25-AC24 -> 0 | AE25: =AE24 -> 365210.2 | AF25: =AE25-AE24 -> 0 | AG25: =IF(AD25>0,AF25/AD25,0) -> 0 | AH25: =AF25+AA25 -> 0 | AI25: =SUM(AH25+V25) -> 0 | AJ25: =-tanks!AW26 -> 0 | AK25: =SUM(AJ25-AI25) -> 0 | AL25: =S25+L25+G25 -> 0 | AM25: =Y25+AD25 -> 0 | AN25: =AN24 -> 67 | AO25: =(AN25/100)*3000 -> 2010 | AP25: =AP24 -> 70 | AQ25: =(AP25/100)*3000 -> 2100 | AR25: =AR24 -> 70 | AS25: =(AR25/100)*3000 -> 2100 | AT25: =SUM(AO25+AQ25+AS25) -> 6210 | AU25: =AT24-AT25+AV25 -> 0 | AX25: =IF(AV25>0,AW25,AX24) -> 0.8
A26: =ELEC!C24 -> 44065 | B26: =B25 -> 230 | C26: =C25 -> 236 | D26: =C25-C26 -> 0 | E26: =D26*8.38 -> 0 | F26: =F25 -> 1648 | G26: =F26-F25 -> 0 | H26: =H25 -> 357868 | I26: =SUM(H26-H25) -> 0 | J26: =IF(G26>0,I26/G26,0) -> 0 | K26: =K25 -> 2108 | L26: =K26-K25 -> 0 | M26: =M25 -> 154682 | N26: =M26-M25 -> 0 | O26: =O25 -> 211.875 | P26: =P25 -> 1837 | Q26: =Q25 -> 155926 | R26: =Q26-Q25 -> 0 | S26: =SUM(P26-P25) -> 0 | T26: =SUM(S26*$T$2) -> 0 | U26: =SUM(G26+L26+S26) -> 0 | V26: =R26+N26+I26:I26 -> 0 | X26: =X25 -> 2424 | Y26: =X26-X25 -> 0 | Z26: =Z25 -> 136280 | AA26: =Z26-Z25 -> 0 | AB26: =SUM(Y26*$AB$2) -> 0 | AC26: =AC25 -> 1933 | AD26: =AC26-AC25 -> 0 | AE26: =AE25 -> 365210.2 | AF26: =AE26-AE25 -> 0 | AG26: =IF(AD26>0,AF26/AD26,0) -> 0 | AH26: =AF26+AA26 -> 0 | AI26: =SUM(AH26+V26) -> 0 | AJ26: =-tanks!AW27 -> 0 | AK26: =SUM(AJ26-AI26) -> 0 | AL26: =S26+L26+G26 -> 0 | AM26: =Y26+AD26 -> 0 | AN26: =AN25 -> 67 | AO26: =(AN26/100)*3000 -> 2010 | AP26: =AP25 -> 70 | AQ26: =(AP26/100)*3000 -> 2100 | AR26: =AR25 -> 70 | AS26: =(AR26/100)*3000 -> 2100 | AT26: =SUM(AO26+AQ26+AS26) -> 6210 | AU26: =AT25-AT26+AV26 -> 0 | AX26: =IF(AV26>0,AW26,AX25) -> 0.8
