Workbook

Sheet TOTAL
A1: Site Name | B1: Day | C1: Month | D1: Year | E1: Total Electricity Kwh | F1: Electricity Tariff ($/Kwh) | G1: Natural Gas (m3) | H1: Natural Gas $/m3 | I1: Water Utility Supply (m3) m3 | J1: Water Utility Supply (m3) $/m3 | K1: Room Nights | L1: Total Guests
A2: Singapore | B2: 1 | C2: 8 | D2: 2020 | E2: =Submetering!G2+Submetering!H2+Submetering!I2+Submetering!J2 -> 20464 | G2: =Submetering!AI2+Submetering!AJ2+Submetering!AK2+Submetering!AL2+Submetering!AM2+Submetering!AN2 -> 3027.375 | I2: =Submetering!AO2+Submetering!AP2+Submetering!AR2+Submetering!AS2 -> 166 | K2: =Submetering!E2 -> 158.1 | L2: =Submetering!F2 -> 0
A3: Singapore | B3: =B2+1 -> 2 | C3: 8 | D3: 2020 | E3: =Submetering!G3+Submetering!H3+Submetering!I3+Submetering!J3 -> 21508 | G3: =Submetering!AI3+Submetering!AJ3+Submetering!AK3+Submetering!AL3+Submetering!AM3+Submetering!AN3 -> 2794.5 | I3: =Submetering!AO3+Submetering!AP3+Submetering!AR3+Submetering!AS3 -> 167 | K3: =Submetering!E3 -> 121.125 | L3: =Submetering!F3 -> 0
A4: Singapore | B4: =B3+1 -> 3 | C4: 8 | D4: 2020 | E4: =Submetering!G4+Submetering!H4+Submetering!I4+Submetering!J4 -> 21705 | G4: =Submetering!AI4+Submetering!AJ4+Submetering!AK4+Submetering!AL4+Submetering!AM4+Submetering!AN4 -> 1743.975 | I4: =Submetering!AO4+Submetering!AP4+Submetering!AR4+Submetering!AS4 -> 157 | K4: =Submetering!E4 -> 121.125 | L4: =Submetering!F4 -> 0
A5: Singapore | B5: =B4+1 -> 4 | C5: 8 | D5: 2020 | E5: =Submetering!G5+Submetering!H5+Submetering!I5+Submetering!J5 -> 21268 | G5: =Submetering!AI5+Submetering!AJ5+Submetering!AK5+Submetering!AL5+Submetering!AM5+Submetering!AN5 -> 1883.7 | I5: =Submetering!AO5+Submetering!AP5+Submetering!AR5+Submetering!AS5 -> 146 | K5: =Submetering!E5 -> 121.125 | L5: =Submetering!F5 -> 0
A6: Singapore | B6: =B5+1 -> 5 | C6: 8 | D6: 2020 | E6: =Submetering!G6+Submetering!H6+Submetering!I6+Submetering!J6 -> 21967 | G6: =Submetering!AI6+Submetering!AJ6+Submetering!AK6+Submetering!AL6+Submetering!AM6+Submetering!AN6 -> 3482.775 | I6: =Submetering!AO6+Submetering!AP6+Submetering!AR6+Submetering!AS6 -> 184 | K6: =Submetering!E6 -> 118.83 | L6: =Submetering!F6 -> 0
A7: Singapore | B7: =B6+1 -> 6 | C7: 8 | D7: 2020 | E7: =Submetering!G7+Submetering!H7+Submetering!I7+Submetering!J7 -> 23217 | G7: =Submetering!AI7+Submetering!AJ7+Submetering!AK7+Submetering!AL7+Submetering!AM7+Submetering!AN7 -> 3115.35 | I7: =Submetering!AO7+Submetering!AP7+Submetering!AR7+Submetering!AS7 -> 211 | K7: =Submetering!E7 -> 128.01 | L7: =Submetering!F7 -> 0
A8: Singapore | B8: =B7+1 -> 7 | C8: 8 | D8: 2020 | E8: =Submetering!G8+Submetering!H8+Submetering!I8+Submetering!J8 -> 23781 | G8: =Submetering!AI8+Submetering!AJ8+Submetering!AK8+Submetering!AL8+Submetering!AM8+Submetering!AN8 -> 3275.775 | I8: =Submetering!AO8+Submetering!AP8+Submetering!AR8+Submetering!AS8 -> 196 | K8: =Submetering!E8 -> 132.09 | L8: =Submetering!F8 -> 0
A9: Singapore | B9: =B8+1 -> 8 | C9: 8 | D9: 2020 | E9: =Submetering!G9+Submetering!H9+Submetering!I9+Submetering!J9 -> 23968 | G9: =Submetering!AI9+Submetering!AJ9+Submetering!AK9+Submetering!AL9+Submetering!AM9+Submetering!AN9 -> 3529.35 | I9: =Submetering!AO9+Submetering!AP9+Submetering!AR9+Submetering!AS9 -> 221 | K9: =Submetering!E9 -> 154.02 | L9: =Submetering!F9 -> 0
A10: Singapore | B10: =B9+1 -> 9 | C10: 8 | D10: 2020 | E10: =Submetering!G10+Submetering!H10+Submetering!I10+Submetering!J10 -> 24416 | G10: =Submetering!AI10+Submetering!AJ10+Submetering!AK10+Submetering!AL10+Submetering!AM10+Submetering!AN10 -> 3301.65 | I10: =Submetering!AO10+Submetering!AP10+Submetering!AR10+Submetering!AS10 -> 217 | K10: =Submetering!E10 -> 172.89 | L10: =Submetering!F10 -> 0
A11: Singapore | B11: =B10+1 -> 10 | C11: 8 | D11: 2020 | E11: =Submetering!G11+Submetering!H11+Submetering!I11+Submetering!J11 -> 21908 | G11: =Submetering!AI11+Submetering!AJ11+Submetering!AK11+Submetering!AL11+Submetering!AM11+Submetering!AN11 -> 2292.525 | I11: =Submetering!AO11+Submetering!AP11+Submetering!AR11+Submetering!AS11 -> 210 | K11: =Submetering!E11 -> 125.97 | L11: =Submetering!F11 -> 0
A12: Singapore | B12: =B11+1 -> 11 | C12: 8 | D12: 2020 | E12: =Submetering!G12+Submetering!H12+Submetering!I12+Submetering!J12 -> 23111 | G12: =Submetering!AI12+Submetering!AJ12+Submetering!AK12+Submetering!AL12+Submetering!AM12+Submetering!AN12 -> 2292.525 | I12: =Submetering!AO12+Submetering!AP12+Submetering!AR12+Submetering!AS12 -> 188 | K12: =Submetering!E12 -> 121.125 | L12: =Submetering!F12 -> 0
A13: Singapore | B13: =B12+1 -> 12 | C13: 8 | D13: 2020 | E13: =Submetering!G13+Submetering!H13+Submetering!I13+Submetering!J13 -> 22791 | G13: =Submetering!AI13+Submetering!AJ13+Submetering!AK13+Submetering!AL13+Submetering!AM13+Submetering!AN13 -> 3834.675 | I13: =Submetering!AO13+Submetering!AP13+Submetering!AR13+Submetering!AS13 -> 199 | K13: =Submetering!E13 -> 123.93 | L13: =Submetering!F13 -> 0
A14: Singapore | B14: =B13+1 -> 13 | C14: 8 | D14: 2020 | E14: =Submetering!G14+Submetering!H14+Submetering!I14+Submetering!J14 -> 24684 | G14: =Submetering!AI14+Submetering!AJ14+Submetering!AK14+Submetering!AL14+Submetering!AM14+Submetering!AN14 -> 3627.675 | I14: =Submetering!AO14+Submetering!AP14+Submetering!AR14+Submetering!AS14 -> 188 | K14: =Submetering!E14 -> 124.95 | L14: =Submetering!F14 -> 0
... A32: Singapore | B32: =B31+1 -> 31 | C32: 8 | D32: 2020 | E32: =Submetering!G32+Submetering!H32+Submetering!I32+Submetering!J32 -> 21761 | G32: =Submetering!AI32+Submetering!AJ32+Submetering!AK32+Submetering!AL32+Submetering!AM32+Submetering!AN32 -> 1345.5 | I32: =Submetering!AO32+Submetering!AP32+Submetering!AR32+Submetering!AS32 -> 198 | K32: =Submetering!E32 -> 120.105 | L32: =Submetering!F32 -> 0

Sheet Submetering
A1: Site Name | B1: Day | C1: Month | D1: Year | E1: Room Nights | F1: Total Guests | G1: Feeder 1 Peak (KWh) | H1: Feeder 1 Off-Peak (KWh) | I1: Feeder 2 Peak (KWh) | J1: Feeder 2 Off-Peak (KWh) | K1: Chiller Main 1 (KWh) | L1: Chiller Main 2 (KWh) | M1: Total Chiller Plantroom (KWh) | N1: Chiller 1 Multistack (KWh) | O1: Chiller 2 Trane (KWh) | P1: Chiller 3 Trane (KWh) | Q1: Chiller 4 Trane (KWh) | R1: Chillers (KWh) | S1: Condenser Water Pump B1-1 (KWh) | T1: Condenser Water Pump B1-2 (KWh) | U1: Condenser Water Pump B1-3 (KWh) | V1: Condenser Water Pump B1-4 (KWh) | W1: Condenser Water Pumps (KWh) | X1: Chilled Water Pump B1-1 (KWh) | Y1: Chilled Water Pump B1-2 (KWh) | Z1: Chilled Water Pump B1-3 (KWh) | AA1: Chilled Water Pump B1-4 (KWh) | AB1: Chilled Water Pumps (KWh) | AC1: Total Chiller Plantroom (KWh) | AD1: Cooling Tower #1 (KWh) | AE1: Cooling Tower #2 (KWh) | AF1: Cooling Tower #3 (KWh) | AG1: Cooling Tower #4 (KWh) | AH1: Cooling Tower (KWh) | AI1: Gas Consumption Kutulu (m3) | AJ1: Gas Consumption Windows (m3) | AK1: Gas Consumption 190 Kitchen (m3) | AL1: Gas Consumption Main kitchen (m3) | AM1: Gas Consumption Pastry Kitchen (m3) | AN1: Gas Consumption JNC Kitchen (m3) | AO1: Domestic Water Meter 1 (m3) | AP1: Domestic Water Meter 2 (m3) | AQ1: Domestic Water Total (m3) | AR1: NewWater Meter 1 (m3) | AS1: NewWater Meter 2 (m3) | AT1: NewWater Total (m3)
A2: Singapore | B2: 1 | C2: 8 | D2: 2020 | E2: =Sheet1!E8*255 -> 158.1 | F2: 0 | G2: =Sheet1!E$24 -> 2368 | H2: =Sheet1!E$25 -> 1152 | I2: =Sheet1!E$27 -> 12314 | J2: =Sheet1!E$28 -> 4630 | K2: =Sheet1!E$57 -> 0 | L2: =Sheet1!E$58 -> 503 | M2: =K2+L2 -> 503 | N2: =Sheet1!E$61 -> 0 | O2: =Sheet1!E$62 -> 0 | P2: =Sheet1!E$63 -> 2200 | Q2: =Sheet1!E$64 -> 2450 | R2: =N2+O2+P2+Q2 -> 4650 | S2: =Sheet1!E$67 -> 0 | T2: =Sheet1!E$68 -> 0 | U2: =Sheet1!E$69 -> 152 | V2: =Sheet1!E$70 -> 192 | W2: =SUM(S2:V2) -> 344 | X2: =Sheet1!E$73 -> 0 | Y2: =Sheet1!E$74 -> 0 | Z2: =Sheet1!E$75 -> 103 | AA2: =Sheet1!E$76 -> 139 | AB2: =SUM(X2:AA2) -> 242 | AC2: =AB2+W2+R2 -> 5236 | AD2: =Sheet1!E$81 -> 140 | AE2: =Sheet1!E$82 -> 0 | AF2: =Sheet1!E$83 -> 266 | AG2: =Sheet1!E$84 -> 113 | AH2: =SUM(AD2:AG2) -> 519 | AI2: =Sheet1!E$98 -> 196.65 | AJ2: =Sheet1!E$99 -> 0 | AK2: =Sheet1!E$100 -> 1443.825 | AL2: =Sheet1!E$101 -> 382.95 | AM2: =Sheet1!E$102 -> 20.7 | AN2: =Sheet1!E$103 -> 983.25 | AO2: =Sheet1!E$112 -> 90 | AP2: =Sheet1!E$113 -> 16 | AQ2: =AO2+AP2 -> 106 | AR2: =Sheet1!E$123 -> 57 | AS2: =Sheet1!E$124 -> 3 | AT2: =AR2+AS2 -> 60
A3: Singapore | B3: =B2+1 -> 2 | C3: 8 | D3: 2020 | E3: =Sheet1!F8*255 -> 121.125 | F3: 0 | G3: =Sheet1!F$24 -> 2417 | H3: =Sheet1!F$25 -> 1080 | I3: =Sheet1!F$27 -> 13618 | J3: =Sheet1!F$28 -> 4393 | K3: =Sheet1!F$57 -> 0 | L3: =Sheet1!F$58 -> 514 | M3: =K3+L3 -> 514 | N3: =Sheet1!F$61 -> 0 | O3: =Sheet1!F$62 -> 0 | P3: =Sheet1!F$63 -> 3150 | Q3: =Sheet1!F$64 -> 1630 | R3: =N3+O3+P3+Q3 -> 4780 | S3: =Sheet1!F$67 -> 0 | T3: =Sheet1!F$68 -> 0 | U3: =Sheet1!F$69 -> 213 | V3: =Sheet1!F$70 -> 133 | W3: =SUM(S3:V3) -> 346 | X3: =Sheet1!F$73 -> 0 | Y3: =Sheet1!F$74 -> 0 | Z3: =Sheet1!F$75 -> 143 | AA3: =Sheet1!F$76 -> 0 | AB3: =SUM(X3:AA3) -> 143 | AC3: =AB3+W3+R3 -> 5269 | AD3: =Sheet1!F$81 -> 144 | AE3: =Sheet1!F$82 -> 0 | AF3: =Sheet1!F$83 -> 264 | AG3: =Sheet1!F$84 -> 119 | AH3: =SUM(AD3:AG3) -> 527 | AI3: =Sheet1!F$98 -> 150.075 | AJ3: =Sheet1!F$99 -> 0 | AK3: =Sheet1!F$100 -> 1417.95 | AL3: =Sheet1!F$101 -> 403.65 | AM3: =Sheet1!F$102 -> 20.7 | AN3: =Sheet1!F$103 -> 802.125 | AO3: =Sheet1!F$112 -> 80 | AP3: =Sheet1!F$113 -> 20 | AQ3: =AO3+AP3 -> 100 | AR3: =Sheet1!F$123 -> 47 | AS3: =Sheet1!F$124 -> 20 | AT3: =AR3+AS3 -> 67
A4: Singapore | B4: =B3+1 -> 3 | C4: 8 | D4: 2020 | E4: =Sheet1!G8*255 -> 121.125 | F4: 0 | G4: =Sheet1!G$24 -> 2507 | H4: =Sheet1!G$25 -> 1058 | I4: =Sheet1!G$27 -> 13482 | J4: =Sheet1!G$28 -> 4658 | K4: =Sheet1!G$57 -> 0 | L4: =Sheet1!G$58 -> 532 | M4: =K4+L4 -> 532 | N4: =Sheet1!G$61 -> 0 | O4: =Sheet1!G$62 -> 10 | P4: =Sheet1!G$63 -> 2310 | Q4: =Sheet1!G$64 -> 2580 | R4: =N4+O4+P4+Q4 -> 4900 | S4: =Sheet1!G$67 -> 0 | T4: =Sheet1!G$68 -> 0 | U4: =Sheet1!G$69 -> 199 | V4: =Sheet1!G$70 -> 168 | W4: =SUM(S4:V4) -> 367 | X4: =Sheet1!G$73 -> 0 | Y4: =Sheet1!G$74 -> 0 | Z4: =Sheet1!G$75 -> 141 | AA4: =Sheet1!G$76 -> 136 | AB4: =SUM(X4:AA4) -> 277 | AC4: =AB4+W4+R4 -> 5544 | AD4: =Sheet1!G$81 -> 137 | AE4: =Sheet1!G$82 -> 0 | AF4: =Sheet1!G$83 -> 272 | AG4: =Sheet1!G$84 -> 113 | AH4: =SUM(AD4:AG4) -> 522 | AI4: =Sheet1!G$98 -> 207 | AJ4: =Sheet1!G$99 -> 0 | AK4: =Sheet1!G$100 -> 1304.1 | AL4: =Sheet1!G$101 -> 212.175 | AM4: =Sheet1!G$102 -> 20.7 | AN4: =Sheet1!G$103 -> 0 | AO4: =Sheet1!G$112 -> 70 | AP4: =Sheet1!G$113 -> 24 | AQ4: =AO4+AP4 -> 94 | AR4: =Sheet1!G$123 -> 50 | AS4: =Sheet1!G$124 -> 13 | AT4: =AR4+AS4 -> 63
A5: Singapore | B5: =B4+1 -> 4 | C5: 8 | D5: 2020 | E5: =Sheet1!H8*255 -> 121.125 | F5: 0 | G5: =Sheet1!H$24 -> 2367 | H5: =Sheet1!H$25 -> 1207 | I5: =Sheet1!H$27 -> 13190 | J5: =Sheet1!H$28 -> 4504 | K5: =Sheet1!H$57 -> 0 | L5: =Sheet1!H$58 -> 494 | M5: =K5+L5 -> 494 | N5: =Sheet1!H$61 -> 0 | O5: =Sheet1!H$62 -> 10 | P5: =Sheet1!H$63 -> 2140 | Q5: =Sheet1!H$64 -> 2400 | R5: =N5+O5+P5+Q5 -> 4550 | S5: =Sheet1!H$67 -> 0 | T5: =Sheet1!H$68 -> 0 | U5: =Sheet1!H$69 -> 150 | V5: =Sheet1!H$70 -> 189 | W5: =SUM(S5:V5) -> 339 | X5: =Sheet1!H$73 -> 0 | Y5: =Sheet1!H$74 -> 0 | Z5: =Sheet1!H$75 -> 108 | AA5: =Sheet1!H$76 -> 143 | AB5: =SUM(X5:AA5) -> 251 | AC5: =AB5+W5+R5 -> 5140 | AD5: =Sheet1!H$81 -> 147 | AE5: =Sheet1!H$82 -> 0 | AF5: =Sheet1!H$83 -> 255 | AG5: =Sheet1!H$84 -> 122 | AH5: =SUM(AD5:AG5) -> 524 | AI5: =Sheet1!H$98 -> 186.3 | AJ5: =Sheet1!H$99 -> 0 | AK5: =Sheet1!H$100 -> 1345.5 | AL5: =Sheet1!H$101 -> 326.025 | AM5: =Sheet1!H$102 -> 25.875 | AN5: =Sheet1!H$103 -> 0 | AO5: =Sheet1!H$112 -> 80 | AP5: =Sheet1!H$113 -> 21 | AQ5: =AO5+AP5 -> 101 | AR5: =Sheet1!H$123 -> 34 | AS5: =Sheet1!H$124 -> 11 | AT5: =AR5+AS5 -> 45
A6: Singapore | B6: =B5+1 -> 5 | C6: 8 | D6: 2020 | E6: =Sheet1!I8*255 -> 118.83 | F6: 0 | G6: =Sheet1!I$24 -> 4677 | H6: =Sheet1!I$25 -> 1179 | I6: =Sheet1!I$27 -> 11864 | J6: =Sheet1!I$28 -> 4247 | K6: =Sheet1!I$57 -> 500 | L6: =Sheet1!I$58 -> 309 | M6: =K6+L6 -> 809 | N6: =Sheet1!I$61 -> 0 | O6: =Sheet1!I$62 -> 1940 | P6: =Sheet1!I$63 -> 0 | Q6: =Sheet1!I$64 -> 2770 | R6: =N6+O6+P6+Q6 -> 4710 | S6: =Sheet1!I$67 -> 0 | T6: =Sheet1!I$68 -> 151 | U6: =Sheet1!I$69 -> 0 | V6: =Sheet1!I$70 -> 194 | W6: =SUM(S6:V6) -> 345 | X6: =Sheet1!I$73 -> 0 | Y6: =Sheet1!I$74 -> 96 | Z6: =Sheet1!I$75 -> 0 | AA6: =Sheet1!I$76 -> 137 | AB6: =SUM(X6:AA6) -> 233 | AC6: =AB6+W6+R6 -> 5288 | AD6: =Sheet1!I$81 -> 164 | AE6: =Sheet1!I$82 -> 0 | AF6: =Sheet1!I$83 -> 242 | AG6: =Sheet1!I$84 -> 138 | AH6: =SUM(AD6:AG6) -> 544 | AI6: =Sheet1!I$98 -> 279.45 | AJ6: =Sheet1!I$99 -> 0 | AK6: =Sheet1!I$100 -> 1474.875 | AL6: =Sheet1!I$101 -> 947.025 | AM6: =Sheet1!I$102 -> 20.7 | AN6: =Sheet1!I$103 -> 760.725 | AO6: =Sheet1!I$112 -> 100 | AP6: =Sheet1!I$113 -> 22 | AQ6: =AO6+AP6 -> 122 | AR6: =Sheet1!I$123 -> 46 | AS6: =Sheet1!I$124 -> 16 | AT6: =AR6+AS6 -> 62
A7: Singapore | B7: =B6+1 -> 6 | C7: 8 | D7: 2020 | E7: =Sheet1!J8*255 -> 128.01 | F7: 0 | G7: =Sheet1!J$24 -> 4885 | H7: =Sheet1!J$25 -> 1449 | I7: =Sheet1!J$27 -> 12212 | J7: =Sheet1!J$28 -> 4671 | K7: =Sheet1!J$57 -> -80 | L7: =Sheet1!J$58 -> 333 | M7: =K7+L7 -> 253 | N7: =Sheet1!J$61 -> 0 | O7: =Sheet1!J$62 -> 2150 | P7: =Sheet1!J$63 -> 0 | Q7: =Sheet1!J$64 -> 3030 | R7: =N7+O7+P7+Q7 -> 5180 | S7: =Sheet1!J$67 -> 0 | T7: =Sheet1!J$68 -> 160 | U7: =Sheet1!J$69 -> 0 | V7: =Sheet1!J$70 -> 200 | W7: =SUM(S7:V7) -> 360 | X7: =Sheet1!J$73 -> 0 | Y7: =Sheet1!J$74 -> 99 | Z7: =Sheet1!J$75 -> 0 | AA7: =Sheet1!J$76 -> 138 | AB7: =SUM(X7:AA7) -> 237 | AC7: =AB7+W7+R7 -> 5777 | AD7: =Sheet1!J$81 -> 204 | AE7: =Sheet1!J$82 -> 0 | AF7: =Sheet1!J$83 -> 214 | AG7: =Sheet1!J$84 -> 175 | AH7: =SUM(AD7:AG7) -> 593 | AI7: =Sheet1!J$98 -> 222.525 | AJ7: =Sheet1!J$99 -> 0 | AK7: =Sheet1!J$100 -> 1552.5 | AL7: =Sheet1!J$101 -> 533.025 | AM7: =Sheet1!J$102 -> 15.525 | AN7: =Sheet1!J$103 -> 791.775 | AO7: =Sheet1!J$112 -> 120 | AP7: =Sheet1!J$113 -> 24 | AQ7: =AO7+AP7 -> 144 | AR7: =Sheet1!J$123 -> 61 | AS7: =Sheet1!J$124 -> 6 | AT7: =AR7+AS7 -> 67
A8: Singapore | B8: =B7+1 -> 7 | C8: 8 | D8: 2020 | E8: =Sheet1!K8*255 -> 132.09 | F8: 0 | G8: =Sheet1!K$24 -> 4931 | H8: =Sheet1!K$25 -> 2261 | I8: =Sheet1!K$27 -> 12586 | J8: =Sheet1!K$28 -> 4003 | K8: =Sheet1!K$57 -> 300 | L8: =Sheet1!K$58 -> 278 | M8: =K8+L8 -> 578 | N8: =Sheet1!K$61 -> 0 | O8: =Sheet1!K$62 -> 2930 | P8: =Sheet1!K$63 -> 0 | Q8: =Sheet1!K$64 -> 2500 | R8: =N8+O8+P8+Q8 -> 5430 | S8: =Sheet1!K$67 -> 0 | T8: =Sheet1!K$68 -> 225 | U8: =Sheet1!K$69 -> 0 | V8: =Sheet1!K$70 -> 163 | W8: =SUM(S8:V8) -> 388 | X8: =Sheet1!K$73 -> 0 | Y8: =Sheet1!K$74 -> 134 | Z8: =Sheet1!K$75 -> 0 | AA8: =Sheet1!K$76 -> 117 | AB8: =SUM(X8:AA8) -> 251 | AC8: =AB8+W8+R8 -> 6069 | AD8: =Sheet1!K$81 -> 209 | AE8: =Sheet1!K$82 -> 0 | AF8: =Sheet1!K$83 -> 207 | AG8: =Sheet1!K$84 -> 179 | AH8: =SUM(AD8:AG8) -> 595 | AI8: =Sheet1!K$98 -> 217.35 | AJ8: =Sheet1!K$99 -> 0 | AK8: =Sheet1!K$100 -> 1687.05 | AL8: =Sheet1!K$101 -> 486.45 | AM8: =Sheet1!K$102 -> 20.7 | AN8: =Sheet1!K$103 -> 864.225 | AO8: =Sheet1!K$112 -> 110 | AP8: =Sheet1!K$113 -> 24 | AQ8: =AO8+AP8 -> 134 | AR8: =Sheet1!K$123 -> 51 | AS8: =Sheet1!K$124 -> 11 | AT8: =AR8+AS8 -> 62
A9: Singapore | B9: =B8+1 -> 8 | C9: 8 | D9: 2020 | E9: =Sheet1!L8*255 -> 154.02 | F9: 0 | G9: =Sheet1!L$24 -> 5015 | H9: =Sheet1!L$25 -> 1726 | I9: =Sheet1!L$27 -> 12916 | J9: =Sheet1!L$28 -> 4311 | K9: =Sheet1!L$57 -> 259 | L9: =Sheet1!L$58 -> 343 | M9: =K9+L9 -> 602 | N9: =Sheet1!L$61 -> 0 | O9: =Sheet1!L$62 -> 2520 | P9: =Sheet1!L$63 -> 0 | Q9: =Sheet1!L$64 -> 3120 | R9: =N9+O9+P9+Q9 -> 5640 | S9: =Sheet1!L$67 -> 0 | T9: =Sheet1!L$68 -> 204 | U9: =Sheet1!L$69 -> 0 | V9: =Sheet1!L$70 -> 215 | W9: =SUM(S9:V9) -> 419 | X9: =Sheet1!L$73 -> 0 | Y9: =Sheet1!L$74 -> 111 | Z9: =Sheet1!L$75 -> 0 | AA9: =Sheet1!L$76 -> 133 | AB9: =SUM(X9:AA9) -> 244 | AC9: =AB9+W9+R9 -> 6303 | AD9: =Sheet1!L$81 -> 219 | AE9: =Sheet1!L$82 -> 0 | AF9: =Sheet1!L$83 -> 198 | AG9: =Sheet1!L$84 -> 189 | AH9: =SUM(AD9:AG9) -> 606 | AI9: =Sheet1!L$98 -> 150.075 | AJ9: =Sheet1!L$99 -> 0 | AK9: =Sheet1!L$100 -> 1790.55 | AL9: =Sheet1!L$101 -> 486.45 | AM9: =Sheet1!L$102 -> 15.525 | AN9: =Sheet1!L$103 -> 1086.75 | AO9: =Sheet1!L$112 -> 140 | AP9: =Sheet1!L$113 -> 20 | AQ9: =AO9+AP9 -> 160 | AR9: =Sheet1!L$123 -> 51 | AS9: =Sheet1!L$124 -> 10 | AT9: =AR9+AS9 -> 61
A10: Singapore | B10: =B9+1 -> 9 | C10: 8 | D10: 2020 | E10: =Sheet1!M8*255 -> 172.89 | F10: 0 | G10: =Sheet1!M$24 -> 5113 | H10: =Sheet1!M$25 -> 2517 | I10: =Sheet1!M$27 -> 12548 | J10: =Sheet1!M$28 -> 4238 | K10: =Sheet1!M$57 -> 323 | L10: =Sheet1!M$58 -> 302 | M10: =K10+L10 -> 625 | N10: =Sheet1!M$61 -> 0 | O10: =Sheet1!M$62 -> 3120 | P10: =Sheet1!M$63 -> 0 | Q10: =Sheet1!M$64 -> 2700 | R10: =N10+O10+P10+Q10 -> 5820 | S10: =Sheet1!M$67 -> 0 | T10: =Sheet1!M$68 -> 277 | U10: =Sheet1!M$69 -> 0 | V10: =Sheet1!M$70 -> 214 | W10: =SUM(S10:V10) -> 491 | X10: =Sheet1!M$73 -> 0 | Y10: =Sheet1!M$74 -> 131 | Z10: =Sheet1!M$75 -> 0 | AA10: =Sheet1!M$76 -> 115 | AB10: =SUM(X10:AA10) -> 246 | AC10: =AB10+W10+R10 -> 6557 | AD10: =Sheet1!M$81 -> 230 | AE10: =Sheet1!M$82 -> 0 | AF10: =Sheet1!M$83 -> 200 | AG10: =Sheet1!M$84 -> 199 | AH10: =SUM(AD10:AG10) -> 629 | AI10: =Sheet1!M$98 -> 139.725 | AJ10: =Sheet1!M$99 -> 0 | AK10: =Sheet1!M$100 -> 1635.3 | AL10: =Sheet1!M$101 -> 455.4 | AM10: =Sheet1!M$102 -> 15.525 | AN10: =Sheet1!M$103 -> 1055.7 | AO10: =Sheet1!M$112 -> 120 | AP10: =Sheet1!M$113 -> 22 | AQ10: =AO10+AP10 -> 142 | AR10: =Sheet1!M$123 -> 64 | AS10: =Sheet1!M$124 -> 11 | AT10: =AR10+AS10 -> 75
A11: Singapore | B11: =B10+1 -> 10 | C11: 8 | D11: 2020 | E11: =Sheet1!N8*255 -> 125.97 | F11: 0 | G11: =Sheet1!N$24 -> 4915 | H11: =Sheet1!N$25 -> 1415 | I11: =Sheet1!N$27 -> 11620 | J11: =Sheet1!N$28 -> 3958 | K11: =Sheet1!N$57 -> 244 | L11: =Sheet1!N$58 -> 325 | M11: =K11+L11 -> 569 | N11: =Sheet1!N$61 -> 0 | O11: =Sheet1!N$62 -> 2360 | P11: =Sheet1!N$63 -> 0 | Q11: =Sheet1!N$64 -> 2940 | R11: =N11+O11+P11+Q11 -> 5300 | S11: =Sheet1!N$67 -> 0 | T11: =Sheet1!N$68 -> 211 | U11: =Sheet1!N$69 -> 0 | V11: =Sheet1!N$70 -> 224 | W11: =SUM(S11:V11) -> 435 | X11: =Sheet1!N$73 -> 0 | Y11: =Sheet1!N$74 -> 102 | Z11: =Sheet1!N$75 -> 0 | AA11: =Sheet1!N$76 -> 125 | AB11: =SUM(X11:AA11) -> 227 | AC11: =AB11+W11+R11 -> 5962 | AD11: =Sheet1!N$81 -> 224 | AE11: =Sheet1!N$82 -> 0 | AF11: =Sheet1!N$83 -> 190 | AG11: =Sheet1!N$84 -> 194 | AH11: =SUM(AD11:AG11) -> 608 | AI11: =Sheet1!N$98 -> 217.35 | AJ11: =Sheet1!N$99 -> 0 | AK11: =Sheet1!N$100 -> 1687.05 | AL11: =Sheet1!N$101 -> 372.6 | AM11: =Sheet1!N$102 -> 15.525 | AN11: =Sheet1!N$103 -> 0 | AO11: =Sheet1!N$112 -> 120 | AP11: =Sheet1!N$113 -> 25 | AQ11: =AO11+AP11 -> 145 | AR11: =Sheet1!N$123 -> 53 | AS11: =Sheet1!N$124 -> 12 | AT11: =AR11+AS11 -> 65
A12: Singapore | B12: =B11+1 -> 11 | C12: 8 | D12: 2020 | E12: =Sheet1!O8*255 -> 121.125 | F12: 0 | G12: =Sheet1!O$24 -> 4911 | H12: =Sheet1!O$25 -> 2203 | I12: =Sheet1!O$27 -> 11770 | J12: =Sheet1!O$28 -> 4227 | K12: =Sheet1!O$57 -> 298 | L12: =Sheet1!O$58 -> 328 | M12: =K12+L12 -> 626 | N12: =Sheet1!O$61 -> 0 | O12: =Sheet1!O$62 -> 2870 | P12: =Sheet1!O$63 -> 0 | Q12: =Sheet1!O$64 -> 2940 | R12: =N12+O12+P12+Q12 -> 5810 | S12: =Sheet1!O$67 -> 0 | T12: =Sheet1!O$68 -> 253 | U12: =Sheet1!O$69 -> 0 | V12: =Sheet1!O$70 -> 219 | W12: =SUM(S12:V12) -> 472 | X12: =Sheet1!O$73 -> 0 | Y12: =Sheet1!O$74 -> 131 | Z12: =Sheet1!O$75 -> 0 | AA12: =Sheet1!O$76 -> 135 | AB12: =SUM(X12:AA12) -> 266 | AC12: =AB12+W12+R12 -> 6548 | AD12: =Sheet1!O$81 -> 228 | AE12: =Sheet1!O$82 -> 0 | AF12: =Sheet1!O$83 -> 191 | AG12: =Sheet1!O$84 -> 198 | AH12: =SUM(AD12:AG12) -> 617 | AI12: =Sheet1!O$98 -> 232.875 | AJ12: =Sheet1!O$99 -> 0 | AK12: =Sheet1!O$100 -> 1692.225 | AL12: =Sheet1!O$101 -> 351.9 | AM12: =Sheet1!O$102 -> 15.525 | AN12: =Sheet1!O$103 -> 0 | AO12: =Sheet1!O$112 -> 90 | AP12: =Sheet1!O$113 -> 20 | AQ12: =AO12+AP12 -> 110 | AR12: =Sheet1!O$123 -> 67 | AS12: =Sheet1!O$124 -> 11 | AT12: =AR12+AS12 -> 78
A13: Singapore | B13: =B12+1 -> 12 | C13: 8 | D13: 2020 | E13: =Sheet1!P8*255 -> 123.93 | F13: 0 | G13: =Sheet1!P$24 -> 4523 | H13: =Sheet1!P$25 -> 2187 | I13: =Sheet1!P$27 -> 11980 | J13: =Sheet1!P$28 -> 4101 | K13: =Sheet1!P$57 -> 278 | L13: =Sheet1!P$58 -> 301 | M13: =K13+L13 -> 579 | N13: =Sheet1!P$61 -> 0 | O13: =Sheet1!P$62 -> 2700 | P13: =Sheet1!P$63 -> 0 | Q13: =Sheet1!P$64 -> 2720 | R13: =N13+O13+P13+Q13 -> 5420 | S13: =Sheet1!P$67 -> 0 | T13: =Sheet1!P$68 -> 212 | U13: =Sheet1!P$69 -> 0 | V13: =Sheet1!P$70 -> 181 | W13: =SUM(S13:V13) -> 393 | X13: =Sheet1!P$73 -> 0 | Y13: =Sheet1!P$74 -> 133 | Z13: =Sheet1!P$75 -> 0 | AA13: =Sheet1!P$76 -> 136 | AB13: =SUM(X13:AA13) -> 269 | AC13: =AB13+W13+R13 -> 6082 | AD13: =Sheet1!P$81 -> 178 | AE13: =Sheet1!P$82 -> 0 | AF13: =Sheet1!P$83 -> 232 | AG13: =Sheet1!P$84 -> 150 | AH13: =SUM(AD13:AG13) -> 560 | AI13: =Sheet1!P$98 -> 331.2 | AJ13: =Sheet1!P$99 -> 0 | AK13: =Sheet1!P$100 -> 1562.85 | AL13: =Sheet1!P$101 -> 936.675 | AM13: =Sheet1!P$102 -> 15.525 | AN13: =Sheet1!P$103 -> 988.425 | AO13: =Sheet1!P$112 -> 120 | AP13: =Sheet1!P$113 -> 19 | AQ13: =AO13+AP13 -> 139 | AR13: =Sheet1!P$123 -> 45 | AS13: =Sheet1!P$124 -> 15 | AT13: =AR13+AS13 -> 60
A14: Singapore | B14: =B13+1 -> 13 | C14: 8 | D14: 2020 | E14: =Sheet1!Q8*255 -> 124.95 | F14: 0 | G14: =Sheet1!Q$24 -> 4674 | H14: =Sheet1!Q$25 -> 2470 | I14: =Sheet1!Q$27 -> 12600 | J14: =Sheet1!Q$28 -> 4940 | K14: =Sheet1!Q$57 -> 298 | L14: =Sheet1!Q$58 -> 324 | M14: =K14+L14 -> 622 | N14: =Sheet1!Q$61 -> 0 | O14: =Sheet1!Q$62 -> 2880 | P14: =Sheet1!Q$63 -> 0 | Q14: =Sheet1!Q$64 -> 2910 | R14: =N14+O14+P14+Q14 -> 5790 | S14: =Sheet1!Q$67 -> 0 | T14: =Sheet1!Q$68 -> 233 | U14: =Sheet1!Q$69 -> 0 | V14: =Sheet1!Q$70 -> 200 | W14: =SUM(S14:V14) -> 433 | X14: =Sheet1!Q$73 -> 0 | Y14: =Sheet1!Q$74 -> 144 | Z14: =Sheet1!Q$75 -> 0 | AA14: =Sheet1!Q$76 -> 148 | AB14: =SUM(X14:AA14) -> 292 | AC14: =AB14+W14+R14 -> 6515 | AD14: =Sheet1!Q$81 -> 135 | AE14: =Sheet1!Q$82 -> 0 | AF14: =Sheet1!Q$83 -> 270 | AG14: =Sheet1!Q$84 -> 108 | AH14: =SUM(AD14:AG14) -> 513 | AI14: =Sheet1!Q$98 -> 238.05 | AJ14: =Sheet1!Q$99 -> 0 | AK14: =Sheet1!Q$100 -> 1749.15 | AL14: =Sheet1!Q$101 -> 952.2 | AM14: =Sheet1!Q$102 -> 20.7 | AN14: =Sheet1!Q$103 -> 667.575 | AO14: =Sheet1!Q$112 -> 110 | AP14: =Sheet1!Q$113 -> 21 | AQ14: =AO14+AP14 -> 131 | AR14: =Sheet1!Q$123 -> 46 | AS14: =Sheet1!Q$124 -> 11 | AT14: =AR14+AS14 -> 57
A15: Singapore | B15: =B14+1 -> 14 | C15: 8 | D15: 2020 | E15: =Sheet1!R8*255 -> 133.11 | F15: 0 | G15: =Sheet1!R$24 -> 4457 | H15: =Sheet1!R$25 -> 1857 | I15: =Sheet1!R$27 -> 12398 | J15: =Sheet1!R$28 -> 3801 | K15: =Sheet1!R$57 -> 256 | L15: =Sheet1!R$58 -> 278 | M15: =K15+L15 -> 534 | N15: =Sheet1!R$61 -> 0 | O15: =Sheet1!R$62 -> 2460 | P15: =Sheet1!R$63 -> 0 | Q15: =Sheet1!R$64 -> 2470 | R15: =N15+O15+P15+Q15 -> 4930 | S15: =Sheet1!R$67 -> 0 | T15: =Sheet1!R$68 -> 207 | U15: =Sheet1!R$69 -> 0 | V15: =Sheet1!R$70 -> 177 | W15: =SUM(S15:V15) -> 384 | X15: =Sheet1!R$73 -> 0 | Y15: =Sheet1!R$74 -> 132 | Z15: =Sheet1!R$75 -> 0 | AA15: =Sheet1!R$76 -> 136 | AB15: =SUM(X15:AA15) -> 268 | AC15: =AB15+W15+R15 -> 5582 | AD15: =Sheet1!R$81 -> 136 | AE15: =Sheet1!R$82 -> 0 | AF15: =Sheet1!R$83 -> 263 | AG15: =Sheet1!R$84 -> 110 | AH15: =SUM(AD15:AG15) -> 509 | AI15: =Sheet1!R$98 -> 232.875 | AJ15: =Sheet1!R$99 -> 0 | AK15: =Sheet1!R$100 -> 1816.425 | AL15: =Sheet1!R$101 -> 517.5 | AM15: =Sheet1!R$102 -> 25.875 | AN15: =Sheet1!R$103 -> 947.025 | AO15: =Sheet1!R$112 -> 110 | AP15: =Sheet1!R$113 -> 22 | AQ15: =AO15+AP15 -> 132 | AR15: =Sheet1!R$123 -> 43 | AS15: =Sheet1!R$124 -> 11 | AT15: =AR15+AS15 -> 54
A16: Singapore | B16: =B15+1 -> 15 | C16: 8 | D16: 2020 | E16: =Sheet1!S8*255 -> 138.975 | F16: 0 | G16: =Sheet1!S$24 -> 4706 | H16: =Sheet1!S$25 -> 1900 | I16: =Sheet1!S$27 -> 12450 | J16: =Sheet1!S$28 -> 4159 | K16: =Sheet1!S$57 -> 320 | L16: =Sheet1!S$58 -> 288 | M16: =K16+L16 -> 608 | N16: =Sheet1!S$61 -> 0 | O16: =Sheet1!S$62 -> 2570 | P16: =Sheet1!S$63 -> 0 | Q16: =Sheet1!S$64 -> 2610 | R16: =N16+O16+P16+Q16 -> 5180 | S16: =Sheet1!S$67 -> 0 | T16: =Sheet1!S$68 -> 217 | U16: =Sheet1!S$69 -> 0 | V16: =Sheet1!S$70 -> 186 | W16: =SUM(S16:V16) -> 403 | X16: =Sheet1!S$73 -> 0 | Y16: =Sheet1!S$74 -> 135 | Z16: =Sheet1!S$75 -> 0 | AA16: =Sheet1!S$76 -> 139 | AB16: =SUM(X16:AA16) -> 274 | AC16: =AB16+W16+R16 -> 5857 | AD16: =Sheet1!S$81 -> 141 | AE16: =Sheet1!S$82 -> 0 | AF16: =Sheet1!S$83 -> 255 | AG16: =Sheet1!S$84 -> 119 | AH16: =SUM(AD16:AG16) -> 515 | AI16: =Sheet1!S$98 -> 217.35 | AJ16: =Sheet1!S$99 -> 0 | AK16: =Sheet1!S$100 -> 1857.825 | AL16: =Sheet1!S$101 -> 615.825 | AM16: =Sheet1!S$102 -> 5.175 | AN16: =Sheet1!S$103 -> 869.4 | AO16: =Sheet1!S$112 -> 110 | AP16: =Sheet1!S$113 -> 24 | AQ16: =AO16+AP16 -> 134 | AR16: =Sheet1!S$123 -> 48 | AS16: =Sheet1!S$124 -> 11 | AT16: =AR16+AS16 -> 59
A17: Singapore | B17: =B16+1 -> 16 | C17: 8 | D17: 2020 | E17: =Sheet1!T8*255 -> 120.105 | F17: 0 | G17: =Sheet1!T$24 -> 4524 | H17: =Sheet1!T$25 -> 1991 | I17: =Sheet1!T$27 -> 12160 | J17: =Sheet1!T$28 -> 4051 | K17: =Sheet1!T$57 -> 218 | L17: =Sheet1!T$58 -> 290 | M17: =K17+L17 -> 508 | N17: =Sheet1!T$61 -> 0 | O17: =Sheet1!T$62 -> 2620 | P17: =Sheet1!T$63 -> 0 | Q17: =Sheet1!T$64 -> 2630 | R17: =N17+O17+P17+Q17 -> 5250 | S17: =Sheet1!T$67 -> 0 | T17: =Sheet1!T$68 -> 217 | U17: =Sheet1!T$69 -> 0 | V17: =Sheet1!T$70 -> 185 | W17: =SUM(S17:V17) -> 402 | X17: =Sheet1!T$73 -> 0 | Y17: =Sheet1!T$74 -> 133 | Z17: =Sheet1!T$75 -> 0 | AA17: =Sheet1!T$76 -> 137 | AB17: =SUM(X17:AA17) -> 270 | AC17: =AB17+W17+R17 -> 5922 | AD17: =Sheet1!T$81 -> 137 | AE17: =Sheet1!T$82 -> 0 | AF17: =Sheet1!T$83 -> 274 | AG17: =Sheet1!T$84 -> 109 | AH17: =SUM(AD17:AG17) -> 520 | AI17: =Sheet1!T$98 -> 155.25 | AJ17: =Sheet1!T$99 -> 0 | AK17: =Sheet1!T$100 -> 1800.9 | AL17: =Sheet1!T$101 -> 289.8 | AM17: =Sheet1!T$102 -> 10.35 | AN17: =Sheet1!T$103 -> 921.15 | AO17: =Sheet1!T$112 -> 110 | AP17: =Sheet1!T$113 -> 19 | AQ17: =AO17+AP17 -> 129 | AR17: =Sheet1!T$123 -> 45 | AS17: =Sheet1!T$124 -> 11 | AT17: =AR17+AS17 -> 56
A18: Singapore | B18: =B17+1 -> 17 | C18: 8 | D18: 2020 | E18: =Sheet1!U8*255 -> 119.085 | F18: 0 | G18: =Sheet1!U$24 -> 4375 | H18: =Sheet1!U$25 -> 1807 | I18: =Sheet1!U$27 -> 11200 | J18: =Sheet1!U$28 -> 3838 | K18: =Sheet1!U$57 -> 257 | L18: =Sheet1!U$58 -> 278 | M18: =K18+L18 -> 535 | N18: =Sheet1!U$61 -> 0 | O18: =Sheet1!U$62 -> 2460 | P18: =Sheet1!U$63 -> 0 | Q18: =Sheet1!U$64 -> 2480 | R18: =N18+O18+P18+Q18 -> 4940 | S18: =Sheet1!U$67 -> 0 | T18: =Sheet1!U$68 -> 210 | U18: =Sheet1!U$69 -> 0 | V18: =Sheet1!U$70 -> 180 | W18: =SUM(S18:V18) -> 390 | X18: =Sheet1!U$73 -> 0 | Y18: =Sheet1!U$74 -> 137 | Z18: =Sheet1!U$75 -> 0 | AA18: =Sheet1!U$76 -> 140 | AB18: =SUM(X18:AA18) -> 277 | AC18: =AB18+W18+R18 -> 5607 | AD18: =Sheet1!U$81 -> 132 | AE18: =Sheet1!U$82 -> 0 | AF18: =Sheet1!U$83 -> 266 | AG18: =Sheet1!U$84 -> 107 | AH18: =SUM(AD18:AG18) -> 505 | AI18: =Sheet1!U$98 -> 217.35 | AJ18: =Sheet1!U$99 -> 0 | AK18: =Sheet1!U$100 -> 1645.65 | AL18: =Sheet1!U$101 -> 263.925 | AM18: =Sheet1!U$102 -> 10.35 | AN18: =Sheet1!U$103 -> 0 | AO18: =Sheet1!U$112 -> 80 | AP18: =Sheet1!U$113 -> 22 | AQ18: =AO18+AP18 -> 102 | AR18: =Sheet1!U$123 -> 34 | AS18: =Sheet1!U$124 -> 12 | AT18: =AR18+AS18 -> 46
A19: Singapore | B19: =B18+1 -> 18 | C19: 8 | D19: 2020 | E19: =Sheet1!V8*255 -> 118.065 | F19: 0 | G19: =Sheet1!V$24 -> 4359 | H19: =Sheet1!V$25 -> 1884 | I19: =Sheet1!V$27 -> 11238 | J19: =Sheet1!V$28 -> 4019 | K19: =Sheet1!V$57 -> 261 | L19: =Sheet1!V$58 -> 283 | M19: =K19+L19 -> 544 | N19: =Sheet1!V$61 -> 0 | O19: =Sheet1!V$62 -> 2490 | P19: =Sheet1!V$63 -> 0 | Q19: =Sheet1!V$64 -> 2510 | R19: =N19+O19+P19+Q19 -> 5000 | S19: =Sheet1!V$67 -> 0 | T19: =Sheet1!V$68 -> 219 | U19: =Sheet1!V$69 -> 0 | V19: =Sheet1!V$70 -> 188 | W19: =SUM(S19:V19) -> 407 | X19: =Sheet1!V$73 -> 0 | Y19: =Sheet1!V$74 -> 144 | Z19: =Sheet1!V$75 -> 0 | AA19: =Sheet1!V$76 -> 169 | AB19: =SUM(X19:AA19) -> 313 | AC19: =AB19+W19+R19 -> 5720 | AD19: =Sheet1!V$81 -> 118 | AE19: =Sheet1!V$82 -> 0 | AF19: =Sheet1!V$83 -> 284 | AG19: =Sheet1!V$84 -> 93 | AH19: =SUM(AD19:AG19) -> 495 | AI19: =Sheet1!V$98 -> 196.65 | AJ19: =Sheet1!V$99 -> 0 | AK19: =Sheet1!V$100 -> 1780.2 | AL19: =Sheet1!V$101 -> 238.05 | AM19: =Sheet1!V$102 -> 10.35 | AN19: =Sheet1!V$103 -> 0 | AO19: =Sheet1!V$112 -> 70 | AP19: =Sheet1!V$113 -> 22 | AQ19: =AO19+AP19 -> 92 | AR19: =Sheet1!V$123 -> 42 | AS19: =Sheet1!V$124 -> 11 | AT19: =AR19+AS19 -> 53
A20: Singapore | B20: =B19+1 -> 19 | C20: 8 | D20: 2020 | E20: =Sheet1!W8*255 -> 121.125 | F20: 0 | G20: =Sheet1!W$24 -> 4326 | H20: =Sheet1!W$25 -> 1894 | I20: =Sheet1!W$27 -> 11948 | J20: =Sheet1!W$28 -> 4156 | K20: =Sheet1!W$57 -> 249 | L20: =Sheet1!W$58 -> 271 | M20: =K20+L20 -> 520 | N20: =Sheet1!W$61 -> 0 | O20: =Sheet1!W$62 -> 2360 | P20: =Sheet1!W$63 -> 0 | Q20: =Sheet1!W$64 -> 2380 | R20: =N20+O20+P20+Q20 -> 4740 | S20: =Sheet1!W$67 -> 0 | T20: =Sheet1!W$68 -> 218 | U20: =Sheet1!W$69 -> 0 | V20: =Sheet1!W$70 -> 187 | W20: =SUM(S20:V20) -> 405 | X20: =Sheet1!W$73 -> 0 | Y20: =Sheet1!W$74 -> 142 | Z20: =Sheet1!W$75 -> 0 | AA20: =Sheet1!W$76 -> 125 | AB20: =SUM(X20:AA20) -> 267 | AC20: =AB20+W20+R20 -> 5412 | AD20: =Sheet1!W$81 -> 129 | AE20: =Sheet1!W$82 -> 0 | AF20: =Sheet1!W$83 -> 270 | AG20: =Sheet1!W$84 -> 105 | AH20: =SUM(AD20:AG20) -> 504 | AI20: =Sheet1!W$98 -> 331.2 | AJ20: =Sheet1!W$99 -> 0 | AK20: =Sheet1!W$100 -> 1614.6 | AL20: =Sheet1!W$101 -> 734.85 | AM20: =Sheet1!W$102 -> 10.35 | AN20: =Sheet1!W$103 -> 915.975 | AO20: =Sheet1!W$112 -> 80 | AP20: =Sheet1!W$113 -> 24 | AQ20: =AO20+AP20 -> 104 | AR20: =Sheet1!W$123 -> 45 | AS20: =Sheet1!W$124 -> 12 | AT20: =AR20+AS20 -> 57
A21: Singapore | B21: =B20+1 -> 20 | C21: 8 | D21: 2020 | E21: =Sheet1!X8*255 -> 128.01 | F21: 0 | G21: =Sheet1!X$24 -> 4424 | H21: =Sheet1!X$25 -> 1865 | I21: =Sheet1!X$27 -> 12088 | J21: =Sheet1!X$28 -> 4059 | K21: =Sheet1!X$57 -> 251 | L21: =Sheet1!X$58 -> 272 | M21: =K21+L21 -> 523 | N21: =Sheet1!X$61 -> 0 | O21: =Sheet1!X$62 -> 2400 | P21: =Sheet1!X$63 -> 0 | Q21: =Sheet1!X$64 -> 2410 | R21: =N21+O21+P21+Q21 -> 4810 | S21: =Sheet1!X$67 -> 0 | T21: =Sheet1!X$68 -> 0 | U21: =Sheet1!X$69 -> 0 | V21: =Sheet1!X$70 -> 184 | W21: =SUM(S21:V21) -> 184 | X21: =Sheet1!X$73 -> 0 | Y21: =Sheet1!X$74 -> 133 | Z21: =Sheet1!X$75 -> 0 | AA21: =Sheet1!X$76 -> 138 | AB21: =SUM(X21:AA21) -> 271 | AC21: =AB21+W21+R21 -> 5265 | AD21: =Sheet1!X$81 -> 158 | AE21: =Sheet1!X$82 -> 0 | AF21: =Sheet1!X$83 -> 234 | AG21: =Sheet1!X$84 -> 150 | AH21: =SUM(AD21:AG21) -> 542 | AI21: =Sheet1!X$98 -> 248.4 | AJ21: =Sheet1!X$99 -> 0 | AK21: =Sheet1!X$100 -> 1692.225 | AL21: =Sheet1!X$101 -> 476.1 | AM21: =Sheet1!X$102 -> 10.35 | AN21: =Sheet1!X$103 -> 822.825 | AO21: =Sheet1!X$112 -> 90 | AP21: =Sheet1!X$113 -> 22 | AQ21: =AO21+AP21 -> 112 | AR21: =Sheet1!X$123 -> 46 | AS21: =Sheet1!X$124 -> 13 | AT21: =AR21+AS21 -> 59
A22: Singapore | B22: =B21+1 -> 21 | C22: 8 | D22: 2020 | E22: =Sheet1!Y8*255 -> 142.035 | F22: 0 | G22: =Sheet1!Y$24 -> 4476 | H22: =Sheet1!Y$25 -> 1748 | I22: =Sheet1!Y$27 -> 12050 | J22: =Sheet1!Y$28 -> 3900 | K22: =Sheet1!Y$57 -> 249 | L22: =Sheet1!Y$58 -> 271 | M22: =K22+L22 -> 520 | N22: =Sheet1!Y$61 -> 0 | O22: =Sheet1!Y$62 -> 2370 | P22: =Sheet1!Y$63 -> 0 | Q22: =Sheet1!Y$64 -> 2390 | R22: =N22+O22+P22+Q22 -> 4760 | S22: =Sheet1!Y$67 -> 0 | T22: =Sheet1!Y$68 -> 214 | U22: =Sheet1!Y$69 -> 0 | V22: =Sheet1!Y$70 -> 188 | W22: =SUM(S22:V22) -> 402 | X22: =Sheet1!Y$73 -> 0 | Y22: =Sheet1!Y$74 -> 130 | Z22: =Sheet1!Y$75 -> 0 | AA22: =Sheet1!Y$76 -> 133 | AB22: =SUM(X22:AA22) -> 263 | AC22: =AB22+W22+R22 -> 5425 | AD22: =Sheet1!Y$81 -> 183 | AE22: =Sheet1!Y$82 -> 0 | AF22: =Sheet1!Y$83 -> 230 | AG22: =Sheet1!Y$84 -> 148 | AH22: =SUM(AD22:AG22) -> 561 | AI22: =Sheet1!Y$98 -> 222.525 | AJ22: =Sheet1!Y$99 -> 0 | AK22: =Sheet1!Y$100 -> 1826.775 | AL22: =Sheet1!Y$101 -> 527.85 | AM22: =Sheet1!Y$102 -> 10.35 | AN22: =Sheet1!Y$103 -> 729.675 | AO22: =Sheet1!Y$112 -> 120 | AP22: =Sheet1!Y$113 -> 20 | AQ22: =AO22+AP22 -> 140 | AR22: =Sheet1!Y$123 -> 67 | AS22: =Sheet1!Y$124 -> 14 | AT22: =AR22+AS22 -> 81
A23: Singapore | B23: =B22+1 -> 22 | C23: 8 | D23: 2020 | E23: =Sheet1!Z8*255 -> 161.925 | F23: 0 | G23: =Sheet1!Z$24 -> 4432 | H23: =Sheet1!Z$25 -> 2097 | I23: =Sheet1!Z$27 -> 12468 | J23: =Sheet1!Z$28 -> 4717 | K23: =Sheet1!Z$57 -> 0 | L23: =Sheet1!Z$58 -> 286 | M23: =K23+L23 -> 286 | N23: =Sheet1!Z$61 -> 0 | O23: =Sheet1!Z$62 -> 2510 | P23: =Sheet1!Z$63 -> 0 | Q23: =Sheet1!Z$64 -> 2520 | R23: =N23+O23+P23+Q23 -> 5030 | S23: =Sheet1!Z$67 -> 0 | T23: =Sheet1!Z$68 -> 217 | U23: =Sheet1!Z$69 -> 0 | V23: =Sheet1!Z$70 -> 226 | W23: =SUM(S23:V23) -> 443 | X23: =Sheet1!Z$73 -> 0 | Y23: =Sheet1!Z$74 -> 135 | Z23: =Sheet1!Z$75 -> 0 | AA23: =Sheet1!Z$76 -> 139 | AB23: =SUM(X23:AA23) -> 274 | AC23: =AB23+W23+R23 -> 5747 | AD23: =Sheet1!Z$81 -> 137 | AE23: =Sheet1!Z$82 -> 0 | AF23: =Sheet1!Z$83 -> 260 | AG23: =Sheet1!Z$84 -> 99 | AH23: =SUM(AD23:AG23) -> 496 | AI23: =Sheet1!Z$98 -> 207 | AJ23: =Sheet1!Z$99 -> 0 | AK23: =Sheet1!Z$100 -> 1863 | AL23: =Sheet1!Z$101 -> 455.4 | AM23: =Sheet1!Z$102 -> 15.525 | AN23: =Sheet1!Z$103 -> 936.675 | AO23: =Sheet1!Z$112 -> 130 | AP23: =Sheet1!Z$113 -> 23 | AQ23: =AO23+AP23 -> 153 | AR23: =Sheet1!Z$123 -> 57 | AS23: =Sheet1!Z$124 -> 15 | AT23: =AR23+AS23 -> 72
A24: Singapore | B24: =B23+1 -> 23 | C24: 8 | D24: 2020 | E24: =Sheet1!AA8*255 -> 129.03 | F24: 0 | G24: =Sheet1!AA$24 -> 4140 | H24: =Sheet1!AA$25 -> 1676 | I24: =Sheet1!AA$27 -> 12164 | J24: =Sheet1!AA$28 -> 3802 | K24: =Sheet1!AA$57 -> 240 | L24: =Sheet1!AA$58 -> 258 | M24: =K24+L24 -> 498 | N24: =Sheet1!AA$61 -> 0 | O24: =Sheet1!AA$62 -> 2250 | P24: =Sheet1!AA$63 -> 0 | Q24: =Sheet1!AA$64 -> 2270 | R24: =N24+O24+P24+Q24 -> 4520 | S24: =Sheet1!AA$67 -> 0 | T24: =Sheet1!AA$68 -> 217 | U24: =Sheet1!AA$69 -> 0 | V24: =Sheet1!AA$70 -> 194 | W24: =SUM(S24:V24) -> 411 | X24: =Sheet1!AA$73 -> 0 | Y24: =Sheet1!AA$74 -> 142 | Z24: =Sheet1!AA$75 -> 0 | AA24: =Sheet1!AA$76 -> 146 | AB24: =SUM(X24:AA24) -> 288 | AC24: =AB24+W24+R24 -> 5219 | AD24: =Sheet1!AA$81 -> 92 | AE24: =Sheet1!AA$82 -> 0 | AF24: =Sheet1!AA$83 -> 298 | AG24: =Sheet1!AA$84 -> 72 | AH24: =SUM(AD24:AG24) -> 462 | AI24: =Sheet1!AA$98 -> 165.6 | AJ24: =Sheet1!AA$99 -> 0 | AK24: =Sheet1!AA$100 -> 1800.9 | AL24: =Sheet1!AA$101 -> 398.475 | AM24: =Sheet1!AA$102 -> 10.35 | AN24: =Sheet1!AA$103 -> 864.225 | AO24: =Sheet1!AA$112 -> 120 | AP24: =Sheet1!AA$113 -> 24 | AQ24: =AO24+AP24 -> 144 | AR24: =Sheet1!AA$123 -> 31 | AS24: =Sheet1!AA$124 -> 12 | AT24: =AR24+AS24 -> 43
A25: Singapore | B25: =B24+1 -> 24 | C25: 8 | D25: 2020 | E25: =Sheet1!AB8*255 -> 124.95 | F25: 0 | G25: =Sheet1!AB$24 -> 4444 | H25: =Sheet1!AB$25 -> 1852 | I25: =Sheet1!AB$27 -> 11218 | J25: =Sheet1!AB$28 -> 4229 | K25: =Sheet1!AB$57 -> 253 | L25: =Sheet1!AB$58 -> 272 | M25: =K25+L25 -> 525 | N25: =Sheet1!AB$61 -> 0 | O25: =Sheet1!AB$62 -> 2400 | P25: =Sheet1!AB$63 -> 0 | Q25: =Sheet1!AB$64 -> 2390 | R25: =N25+O25+P25+Q25 -> 4790 | S25: =Sheet1!AB$67 -> 0 | T25: =Sheet1!AB$68 -> 219 | U25: =Sheet1!AB$69 -> 0 | V25: =Sheet1!AB$70 -> 197 | W25: =SUM(S25:V25) -> 416 | X25: =Sheet1!AB$73 -> 0 | Y25: =Sheet1!AB$74 -> 143 | Z25: =Sheet1!AB$75 -> 0 | AA25: =Sheet1!AB$76 -> 146 | AB25: =SUM(X25:AA25) -> 289 | AC25: =AB25+W25+R25 -> 5495 | AD25: =Sheet1!AB$81 -> 137 | AE25: =Sheet1!AB$82 -> 0 | AF25: =Sheet1!AB$83 -> 267 | AG25: =Sheet1!AB$84 -> 112 | AH25: =SUM(AD25:AG25) -> 516 | AI25: =Sheet1!AB$98 -> 238.05 | AJ25: =Sheet1!AB$99 -> 0 | AK25: =Sheet1!AB$100 -> 1831.95 | AL25: =Sheet1!AB$101 -> 388.125 | AM25: =Sheet1!AB$102 -> 20.7 | AN25: =Sheet1!AB$103 -> 0 | AO25: =Sheet1!AB$112 -> 110 | AP25: =Sheet1!AB$113 -> 22 | AQ25: =AO25+AP25 -> 132 | AR25: =Sheet1!AB$123 -> 44 | AS25: =Sheet1!AB$124 -> 13 | AT25: =AR25+AS25 -> 57
A26: Singapore | B26: =B25+1 -> 25 | C26: 8 | D26: 2020 | E26: =Sheet1!AC8*255 -> 128.01 | F26: 0 | G26: =Sheet1!AC$24 -> 4361 | H26: =Sheet1!AC$25 -> 1728 | I26: =Sheet1!AC$27 -> 11516 | J26: =Sheet1!AC$28 -> 3688 | K26: =Sheet1!AC$57 -> 241 | L26: =Sheet1!AC$58 -> 262 | M26: =K26+L26 -> 503 | N26: =Sheet1!AC$61 -> 0 | O26: =Sheet1!AC$62 -> 2290 | P26: =Sheet1!AC$63 -> 0 | Q26: =Sheet1!AC$64 -> 2330 | R26: =N26+O26+P26+Q26 -> 4620 | S26: =Sheet1!AC$67 -> 2 | T26: =Sheet1!AC$68 -> 208 | U26: =Sheet1!AC$69 -> 0 | V26: =Sheet1!AC$70 -> 189 | W26: =SUM(S26:V26) -> 399 | X26: =Sheet1!AC$73 -> 0 | Y26: =Sheet1!AC$74 -> 131 | Z26: =Sheet1!AC$75 -> 0 | AA26: =Sheet1!AC$76 -> 134 | AB26: =SUM(X26:AA26) -> 265 | AC26: =AB26+W26+R26 -> 5284 | AD26: =Sheet1!AC$81 -> 160 | AE26: =Sheet1!AC$82 -> 0 | AF26: =Sheet1!AC$83 -> 250 | AG26: =Sheet1!AC$84 -> 130 | AH26: =SUM(AD26:AG26) -> 540 | AI26: =Sheet1!AC$98 -> 175.95 | AJ26: =Sheet1!AC$99 -> 0 | AK26: =Sheet1!AC$100 -> 1749.15 | AL26: =Sheet1!AC$101 -> 388.125 | AM26: =Sheet1!AC$102 -> 10.35 | AN26: =Sheet1!AC$103 -> 31.05 | AO26: =Sheet1!AC$112 -> 80 | AP26: =Sheet1!AC$113 -> 23 | AQ26: =AO26+AP26 -> 103 | AR26: =Sheet1!AC$123 -> 66 | AS26: =Sheet1!AC$124 -> 11 | AT26: =AR26+AS26 -> 77
A27: Singapore | B27: =B26+1 -> 26 | C27: 8 | D27: 2020 | E27: =Sheet1!AD8*255 -> 128.01 | F27: 0 | G27: =Sheet1!AD$24 -> 4456 | H27: =Sheet1!AD$25 -> 1848 | I27: =Sheet1!AD$27 -> 12190 | J27: =Sheet1!AD$28 -> 4115 | K27: =Sheet1!AD$57 -> 254 | L27: =Sheet1!AD$58 -> 275 | M27: =K27+L27 -> 529 | N27: =Sheet1!AD$61 -> 10 | O27: =Sheet1!AD$62 -> 2410 | P27: =Sheet1!AD$63 -> 0 | Q27: =Sheet1!AD$64 -> 2380 | R27: =N27+O27+P27+Q27 -> 4800 | S27: =Sheet1!AD$67 -> 0 | T27: =Sheet1!AD$68 -> 219 | U27: =Sheet1!AD$69 -> 0 | V27: =Sheet1!AD$70 -> 197 | W27: =SUM(S27:V27) -> 416 | X27: =Sheet1!AD$73 -> 0 | Y27: =Sheet1!AD$74 -> 137 | Z27: =Sheet1!AD$75 -> 0 | AA27: =Sheet1!AD$76 -> 141 | AB27: =SUM(X27:AA27) -> 278 | AC27: =AB27+W27+R27 -> 5494 | AD27: =Sheet1!AD$81 -> 139 | AE27: =Sheet1!AD$82 -> 0 | AF27: =Sheet1!AD$83 -> 264 | AG27: =Sheet1!AD$84 -> 112 | AH27: =SUM(AD27:AG27) -> 515 | AI27: =Sheet1!AD$98 -> 232.875 | AJ27: =Sheet1!AD$99 -> 0 | AK27: =Sheet1!AD$100 -> 1790.55 | AL27: =Sheet1!AD$101 -> 1045.35 | AM27: =Sheet1!AD$102 -> 10.35 | AN27: =Sheet1!AD$103 -> 833.175 | AO27: =Sheet1!AD$112 -> 130 | AP27: =Sheet1!AD$113 -> 21 | AQ27: =AO27+AP27 -> 151 | AR27: =Sheet1!AD$123 -> 46 | AS27: =Sheet1!AD$124 -> 17 | AT27: =AR27+AS27 -> 63
A28: Singapore | B28: =B27+1 -> 27 | C28: 8 | D28: 2020 | E28: =Sheet1!AE8*255 -> 131.07 | F28: 0 | G28: =Sheet1!AE$24 -> 4561 | H28: =Sheet1!AE$25 -> 1926 | I28: =Sheet1!AE$27 -> 12048 | J28: =Sheet1!AE$28 -> 4266 | K28: =Sheet1!AE$57 -> 263 | L28: =Sheet1!AE$58 -> 282 | M28: =K28+L28 -> 545 | N28: =Sheet1!AE$61 -> 0 | O28: =Sheet1!AE$62 -> 2510 | P28: =Sheet1!AE$63 -> 0 | Q28: =Sheet1!AE$64 -> 2510 | R28: =N28+O28+P28+Q28 -> 5020 | S28: =Sheet1!AE$67 -> 0 | T28: =Sheet1!AE$68 -> 215 | U28: =Sheet1!AE$69 -> 0 | V28: =Sheet1!AE$70 -> 195 | W28: =SUM(S28:V28) -> 410 | X28: =Sheet1!AE$73 -> 0 | Y28: =Sheet1!AE$74 -> 144 | Z28: =Sheet1!AE$75 -> 0 | AA28: =Sheet1!AE$76 -> 148 | AB28: =SUM(X28:AA28) -> 292 | AC28: =AB28+W28+R28 -> 5722 | AD28: =Sheet1!AE$81 -> 158 | AE28: =Sheet1!AE$82 -> 0 | AF28: =Sheet1!AE$83 -> 247 | AG28: =Sheet1!AE$84 -> 132 | AH28: =SUM(AD28:AG28) -> 537 | AI28: =Sheet1!AE$98 -> 175.95 | AJ28: =Sheet1!AE$99 -> 921.15 | AK28: =Sheet1!AE$100 -> 1728.45 | AL28: =Sheet1!AE$101 -> 595.125 | AM28: =Sheet1!AE$102 -> 10.35 | AN28: =Sheet1!AE$103 -> 667.575 | AO28: =Sheet1!AE$112 -> 200 | AP28: =Sheet1!AE$113 -> 20 | AQ28: =AO28+AP28 -> 220 | AR28: =Sheet1!AE$123 -> 45 | AS28: =Sheet1!AE$124 -> 12 | AT28: =AR28+AS28 -> 57
A29: Singapore | B29: =B28+1 -> 28 | C29: 8 | D29: 2020 | E29: =Sheet1!AF8*255 -> 141.015 | F29: 0 | G29: =Sheet1!AF$24 -> 4629 | H29: =Sheet1!AF$25 -> 1939 | I29: =Sheet1!AF$27 -> 12108 | J29: =Sheet1!AF$28 -> 4241 | K29: =Sheet1!AF$57 -> 264 | L29: =Sheet1!AF$58 -> 285 | M29: =K29+L29 -> 549 | N29: =Sheet1!AF$61 -> 0 | O29: =Sheet1!AF$62 -> 2510 | P29: =Sheet1!AF$63 -> 0 | Q29: =Sheet1!AF$64 -> 2520 | R29: =N29+O29+P29+Q29 -> 5030 | S29: =Sheet1!AF$67 -> 0 | T29: =Sheet1!AF$68 -> 225 | U29: =Sheet1!AF$69 -> 0 | V29: =Sheet1!AF$70 -> 201 | W29: =SUM(S29:V29) -> 426 | X29: =Sheet1!AF$73 -> 0 | Y29: =Sheet1!AF$74 -> 146 | Z29: =Sheet1!AF$75 -> 0 | AA29: =Sheet1!AF$76 -> 150 | AB29: =SUM(X29:AA29) -> 296 | AC29: =AB29+W29+R29 -> 5752 | AD29: =Sheet1!AF$81 -> 151 | AE29: =Sheet1!AF$82 -> 0 | AF29: =Sheet1!AF$83 -> 255 | AG29: =Sheet1!AF$84 -> 124 | AH29: =SUM(AD29:AG29) -> 530 | AI29: =Sheet1!AF$98 -> 263.925 | AJ29: =Sheet1!AF$99 -> 0 | AK29: =Sheet1!AF$100 -> 1733.625 | AL29: =Sheet1!AF$101 -> 398.475 | AM29: =Sheet1!AF$102 -> 15.525 | AN29: =Sheet1!AF$103 -> 947.025 | AO29: =Sheet1!AF$112 -> 110 | AP29: =Sheet1!AF$113 -> 18 | AQ29: =AO29+AP29 -> 128 | AR29: =Sheet1!AF$123 -> 51 | AS29: =Sheet1!AF$124 -> 14 | AT29: =AR29+AS29 -> 65
A30: Singapore | B30: =B29+1 -> 29 | C30: 8 | D30: 2020 | E30: =Sheet1!AG8*255 -> 157.08 | F30: 0 | G30: =Sheet1!AG$24 -> 4925 | H30: =Sheet1!AG$25 -> 2369 | I30: =Sheet1!AG$27 -> 12832 | J30: =Sheet1!AG$28 -> 4965 | K30: =Sheet1!AG$57 -> 292 | L30: =Sheet1!AG$58 -> 319 | M30: =K30+L30 -> 611 | N30: =Sheet1!AG$61 -> 0 | O30: =Sheet1!AG$62 -> 2800 | P30: =Sheet1!AG$63 -> 0 | Q30: =Sheet1!AG$64 -> 2800 | R30: =N30+O30+P30+Q30 -> 5600 | S30: =Sheet1!AG$67 -> 0 | T30: =Sheet1!AG$68 -> 232 | U30: =Sheet1!AG$69 -> 0 | V30: =Sheet1!AG$70 -> 206 | W30: =SUM(S30:V30) -> 438 | X30: =Sheet1!AG$73 -> 0 | Y30: =Sheet1!AG$74 -> 153 | Z30: =Sheet1!AG$75 -> 0 | AA30: =Sheet1!AG$76 -> 157 | AB30: =SUM(X30:AA30) -> 310 | AC30: =AB30+W30+R30 -> 6348 | AD30: =Sheet1!AG$81 -> 181 | AE30: =Sheet1!AG$82 -> 0 | AF30: =Sheet1!AG$83 -> 233 | AG30: =Sheet1!AG$84 -> 151 | AH30: =SUM(AD30:AG30) -> 565 | AI30: =Sheet1!AG$98 -> 175.95 | AJ30: =Sheet1!AG$99 -> 0 | AK30: =Sheet1!AG$100 -> 1878.525 | AL30: =Sheet1!AG$101 -> 724.5 | AM30: =Sheet1!AG$102 -> 10.35 | AN30: =Sheet1!AG$103 -> 1066.05 | AO30: =Sheet1!AG$112 -> 140 | AP30: =Sheet1!AG$113 -> 21 | AQ30: =AO30+AP30 -> 161 | AR30: =Sheet1!AG$123 -> 46 | AS30: =Sheet1!AG$124 -> 15 | AT30: =AR30+AS30 -> 61
A31: Singapore | B31: =B30+1 -> 30 | C31: 8 | D31: 2020 | E31: =Sheet1!AH8*255 -> 122.91 | F31: 0 | G31: =Sheet1!AH$24 -> 4718 | H31: =Sheet1!AH$25 -> 2033 | I31: =Sheet1!AH$27 -> 12380 | J31: =Sheet1!AH$28 -> 4200 | K31: =Sheet1!AH$57 -> 274 | L31: =Sheet1!AH$58 -> 297 | M31: =K31+L31 -> 571 | N31: =Sheet1!AH$61 -> 0 | O31: =Sheet1!AH$62 -> 2640 | P31: =Sheet1!AH$63 -> 0 | Q31: =Sheet1!AH$64 -> 2650 | R31: =N31+O31+P31+Q31 -> 5290 | S31: =Sheet1!AH$67 -> 0 | T31: =Sheet1!AH$68 -> 215 | U31: =Sheet1!AH$69 -> 0 | V31: =Sheet1!AH$70 -> 192 | W31: =SUM(S31:V31) -> 407 | X31: =Sheet1!AH$73 -> 0 | Y31: =Sheet1!AH$74 -> 140 | Z31: =Sheet1!AH$75 -> 0 | AA31: =Sheet1!AH$76 -> 143 | AB31: =SUM(X31:AA31) -> 283 | AC31: =AB31+W31+R31 -> 5980 | AD31: =Sheet1!AH$81 -> 174 | AE31: =Sheet1!AH$82 -> 0 | AF31: =Sheet1!AH$83 -> 227 | AG31: =Sheet1!AH$84 -> 145 | AH31: =SUM(AD31:AG31) -> 546 | AI31: =Sheet1!AH$98 -> 160.425 | AJ31: =Sheet1!AH$99 -> 0 | AK31: =Sheet1!AH$100 -> 1868.175 | AL31: =Sheet1!AH$101 -> 408.825 | AM31: =Sheet1!AH$102 -> 10.35 | AN31: =Sheet1!AH$103 -> 993.6 | AO31: =Sheet1!AH$112 -> 110 | AP31: =Sheet1!AH$113 -> 15 | AQ31: =AO31+AP31 -> 125 | AR31: =Sheet1!AH$123 -> 50 | AS31: =Sheet1!AH$124 -> 13 | AT31: =AR31+AS31 -> 63
A32: Singapore | B32: =B31+1 -> 31 | C32: 8 | D32: 2020 | E32: =Sheet1!AI8*255 -> 120.105 | F32: 0 | G32: =Sheet1!AI$24 -> 4556 | H32: =Sheet1!AI$25 -> 1952 | I32: =Sheet1!AI$27 -> 11182 | J32: =Sheet1!AI$28 -> 4071 | K32: =Sheet1!AI$57 -> 534 | L32: =Sheet1!AI$58 -> 579 | M32: =K32+L32 -> 1113 | N32: =Sheet1!AI$61 -> 0 | O32: =Sheet1!AI$62 -> 5130 | P32: =Sheet1!AI$63 -> 0 | Q32: =Sheet1!AI$64 -> 5140 | R32: =N32+O32+P32+Q32 -> 10270 | S32: =Sheet1!AI$67 -> 0 | T32: =Sheet1!AI$68 -> 428 | U32: =Sheet1!AI$69 -> 0 | V32: =Sheet1!AI$70 -> 383 | W32: =SUM(S32:V32) -> 811 | X32: =Sheet1!AI$73 -> 0 | Y32: =Sheet1!AI$74 -> 275 | Z32: =Sheet1!AI$75 -> 0 | AA32: =Sheet1!AI$76 -> 281 | AB32: =SUM(X32:AA32) -> 556 | AC32: =AB32+W32+R32 -> 11637 | AD32: =Sheet1!AI$81 -> 184 | AE32: =Sheet1!AI$82 -> 0 | AF32: =Sheet1!AI$83 -> 229 | AG32: =Sheet1!AI$84 -> 152 | AH32: =SUM(AD32:AG32) -> 565 | AI32: =Sheet1!AI$98 -> 181.125 | AJ32: =Sheet1!AI$99 -> -921.15 | AK32: =Sheet1!AI$100 -> 1749.15 | AL32: =Sheet1!AI$101 -> 326.025 | AM32: =Sheet1!AI$102 -> 10.35 | AN32: =Sheet1!AI$103 -> 0 | AO32: =Sheet1!AI$112 -> 100 | AP32: =Sheet1!AI$113 -> 30 | AQ32: =AO32+AP32 -> 130 | AR32: =Sheet1!AI$123 -> 56 | AS32: =Sheet1!AI$124 -> 12 | AT32: =AR32+AS32 -> 68

Sheet Sheet1
A1: ELECTRICTY, WATER, & GAS CONSUMPTION - Aug 2020
B4: Date:
A7: Date: | B7: 1 | C7: =B7+1 -> 2 | D7: 31 | E7: 1 | F7: 2 | G7: =C7+1 -> 3 | H7: =G7+1 -> 4 | I7: =H7+1 -> 5 | J7: =I7+1 -> 6 | K7: =J7+1 -> 7 | L7: =K7+1 -> 8 | M7: =L7+1 -> 9 | N7: =M7+1 -> 10 | O7: =N7+1 -> 11 | ... AE7: =AD7+1 -> 27 | AF7: 28 | AG7: 29 | AH7: 30 | AI7: 31 | AJ7: TOTAL | AK7: AVE / DAY
A8: Actual Occupancy: | B8: 175 | C8: 146 | D8: 0.592 | E8: 0.62 | F8: 0.475 | G8: 0.475 | H8: 0.475 | I8: 0.466 | J8: 0.502 | K8: 0.518 | L8: 0.604 | M8: 0.678 | N8: 0.494 | O8: 0.475 | P8: 0.486 | Q8: 0.49 | R8: 0.522 | S8: 0.545 | T8: 0.471 | U8: 0.467 | V8: 0.463 | W8: 0.475 | X8: 0.502 | Y8: 0.557 | Z8: 0.635 | AA8: 0.506 | AB8: 0.49 | AC8: 0.502 | AD8: 0.502 | AE8: 0.514 | AF8: 0.553 | AG8: 0.616 | AH8: 0.482 | AI8: 0.471 | AJ8: =SUM(E8:AI8) -> 16.031 | AK8: =AJ8/31 -> 0.51712903
A9: Forecasted Occupancy as Aug: | D9: 0.8563 | E9: 0.9194 | F9: 0.9194 | G9: 0.9194 | H9: 0.9194 | I9: 0.9194 | J9: 0.9194 | K9: 0.9194 | L9: 0.9194 | M9: 0.9194 | N9: 0.9194 | O9: 0.9194 | P9: 0.9194 | Q9: 0.9194 | R9: 0.9194 | S9: 0.9194 | T9: 0.9194 | U9: 0.9194 | V9: 0.9194 | W9: 0.9194 | X9: 0.9194 | Y9: 0.9194 | Z9: 0.9194 | AA9: 0.9194 | AB9: 0.9194 | AC9: 0.9194 | AD9: 0.9194 | AE9: 0.9194 | AF9: 0.9194 | AG9: 0.9194 | AH9: 0.9194 | AI9: 0.9194 | AJ9: =SUM(E9:AI9) -> 28.5014 | AK9: =AJ9/31 -> 0.9194
A11: Actual Food Covers: | B11: 1310 | C11: 1537 | D11: 333 | E11: 398 | F11: 272 | G11: 154 | H11: 312 | I11: 262 | J11: 242 | K11: 350 | L11: 349 | M11: 383 | N11: 202 | O11: 141 | P11: 269 | Q11: 247 | R11: 314 | S11: 287 | T11: 269 | U11: 155 | V11: 181 | W11: 192 | X11: 252 | Y11: 328 | Z11: 346 | AA11: 298 | AB11: 184 | AC11: 185 | AD11: 213 | AE11: 246 | AF11: 345 | AG11: 367 | AH11: 306 | AI11: 149 | AJ11: =SUM(E11:AI11) -> 8198 | AK11: =AJ11/31 -> 264.45161
A12: Forecasted Food Cover: | D12: 821 | E12: 782 | F12: 782 | G12: 782 | H12: 782 | I12: 782 | J12: 782 | K12: 782 | L12: 782 | M12: 782 | N12: 782 | O12: 782 | P12: 782 | Q12: 782 | R12: 782 | S12: 782 | T12: 782 | U12: 782 | V12: 782 | W12: 782 | X12: 782 | Y12: 782 | Z12: 782 | AA12: 782 | AB12: 782 | AC12: 782 | AD12: 782 | AE12: 782 | AF12: 782 | AG12: 782 | AH12: 782 | AI12: 782 | AJ12: =SUM(E12:AI12) -> 24242 | AK12: =AJ12/31 -> 782
A14: Main Electricity Meter Reading
A15: Feeder 1
A16: Peak | B16: 3599965 | C16: 3606737 | D16: 7487241 | E16: 7489609 | F16: 7492026 | G16: 7494533 | H16: 7496900 | I16: 7501577 | J16: 7506462 | K16: 7511393 | L16: 7516408 | M16: 7521521 | N16: 7526436 | O16: 7531347 | P16: 7535870 | Q16: 7540544 | R16: 7545001 | S16: 7549707 | T16: 7554231 | U16: 7558606 | V16: 7562965 | W16: 7567291 | X16: 7571715 | Y16: 7576191 | Z16: 7580623 | AA16: 7584763 | AB16: 7589207 | AC16: 7593568 | AD16: 7598024 | AE16: 7602585 | AF16: 7607214 | AG16: 7612139 | AH16: 7616857 | AI16: 7621413
A17: Off-Peak | B17: 1579860 | C17: 1582980 | D17: 3237848 | E17: 3239000 | F17: 3240080 | G17: 3241138 | H17: 3242345 | I17: 3243524 | J17: 3244973 | K17: 3247234 | L17: 3248960 | M17: 3251477 | N17: 3252892 | O17: 3255095 | P17: 3257282 | Q17: 3259752 | R17: 3261609 | S17: 3263509 | T17: 3265500 | U17: 3267307 | V17: 3269191 | W17: 3271085 | X17: 3272950 | Y17: 3274698 | Z17: 3276795 | AA17: 3278471 | AB17: 3280323 | AC17: 3282051 | AD17: 3283899 | AE17: 3285825 | AF17: 3287764 | AG17: 3290133 | AH17: 3292166 | AI17: 3294118
A18: Feeder 2
A19: Peak | B19: 10573222 | C19: 10611021 | D19: 23791894 | E19: 23804208 | F19: 23817826 | G19: 23831308 | H19: 23844498 | I19: 23856362 | J19: 23868574 | K19: 23881160 | L19: 23894076 | M19: 23906624 | N19: 23918244 | O19: 23930014 | P19: 23941994 | Q19: 23954594 | R19: 23966992 | S19: 23979442 | T19: 23991602 | U19: 24002802 | V19: 24014040 | W19: 24025988 | X19: 24038076 | Y19: 24050126 | Z19: 24062594 | AA19: 24074758 | AB19: 24085976 | AC19: 24097492 | AD19: 24109682 | AE19: 24121730 | AF19: 24133838 | AG19: 24146670 | AH19: 24159050 | AI19: 24170232
A20: Off-Peak | B20: 3928636 | C20: 3943156 | D20: 8714018 | E20: 8718648 | F20: 8723041 | G20: 8727699 | H20: 8732203 | I20: 8736450 | J20: 8741121 | K20: 8745124 | L20: 8749435 | M20: 8753673 | N20: 8757631 | O20: 8761858 | P20: 8765959 | Q20: 8770899 | R20: 8774700 | S20: 8778859 | T20: 8782910 | U20: 8786748 | V20: 8790767 | W20: 8794923 | X20: 8798982 | Y20: 8802882 | Z20: 8807599 | AA20: 8811401 | AB20: 8815630 | AC20: 8819318 | AD20: 8823433 | AE20: 8827699 | AF20: 8831940 | AG20: 8836905 | AH20: 8841105 | AI20: 8845176
A22: Main Electricity Consumption
A23: Feeder 1
A24: Peak | B24: =B16-#REF! -> #REF! | C24: =C16-B16 -> 6772 | D24: =D16-C16 -> 3880504 | E24: =E16-D16 -> 2368 | F24: =F16-E16 -> 2417 | G24: =G16-F16 -> 2507 | H24: =H16-G16 -> 2367 | I24: =I16-H16 -> 4677 | J24: =J16-I16 -> 4885 | ... AI24: =AI16-AH16 -> 4556
A25: Off-Peak | B25: =B17-#REF! -> #REF! | C25: =C17-B17 -> 3120 | D25: =D17-C17 -> 1654868 | E25: =E17-D17 -> 1152 | F25: =F17-E17 -> 1080 | G25: =G17-F17 -> 1058 | H25: =H17-G17 -> 1207 | I25: =I17-H17 -> 1179 | J25: =J17-I17 -> 1449 | ... AI25: =AI17-AH17 -> 1952
A26: Feeder 2
A27: Peak | B27: =B19-#REF! -> #REF! | C27: =C19-B19 -> 37799 | D27: =D19-C19 -> 13180873 | E27: =E19-D19 -> 12314 | F27: =F19-E19 -> 13618 | G27: =G19-F19 -> 13482 | H27: =H19-G19 -> 13190 | I27: =I19-H19 -> 11864 | J27: =J19-I19 -> 12212 | ... AI27: =AI19-AH19 -> 11182
A28: Off-Peak | B28: =B20-#REF! -> #REF! | C28: =C20-B20 -> 14520 | D28: =D20-C20 -> 4770862 | E28: =E20-D20 -> 4630 | F28: =F20-E20 -> 4393 | G28: =G20-F20 -> 4658 | H28: =H20-G20 -> 4504 | I28: =I20-H20 -> 4247 | J28: =J20-I20 -> 4671 | ... AI28: =AI20-AH20 -> 4071 | AJ28: TOTAL | AK28: AVE / DAY
A29: Total Hotel KWh | B29: =SUM(B24:B28) -> #REF! | C29: =SUM(C24:C28) -> 62211 | D29: =SUM(D24:D28) -> 23487107 | E29: =SUM(E24:E28) -> 20464 | F29: =SUM(F24:F28) -> 21508 | G29: =SUM(G24:G28) -> 21705 | H29: =SUM(H24:H28) -> 21268 | I29: =SUM(I24:I28) -> 21967 | ... AI29: =SUM(AI24:AI28) -> 21761 | AJ29: =SUM(E29:AI29) -> 699938 | AK29: =AJ29/31 -> 22578.645
A30: Forecast for Aug = 780520 KWh | B30: 23235 | C30: 23235 | D30: 23480 | E30: 25178 | F30: 25178 | G30: 25178 | H30: 25178 | I30: 25178 | J30: 25178 | K30: 25178 | L30: 25178 | M30: 25178 | N30: 25178 | O30: 25178 | P30: 25178 | Q30: 25178 | R30: 25178 | S30: 25178 | T30: 25178 | U30: 25178 | V30: 25178 | W30: 25178 | X30: 25178 | Y30: 25178 | Z30: 25178 | AA30: 25178 | AB30: 25178 | AC30: 25178 | AD30: 25178 | AE30: 25178 | AF30: 25178 | AG30: 25178 | AH30: 25178 | AI30: 25178 | AJ30: =SUM(E30:AI30) -> 780518 | AK30: =AJ30/31 -> 25178
A32: Chiller Electricity Sub - Meter Reading
A33: Main 1 | B33: 5351900 | C33: 5351940 | D33: 700385 | E33: 700385 | F33: 700385 | G33: 700385 | H33: 700385 | I33: 700885 | J33: 700805 | K33: 701105 | L33: 701364 | M33: 701687 | N33: 701931 | O33: 702229 | P33: 702507 | Q33: 702805 | R33: 703061 | S33: 703381 | T33: 703599 | U33: 703856 | V33: 704117 | W33: 704366 | X33: 704617 | Y33: 704866 | Z33: 705131 | AA33: 705371 | AB33: 705624 | AC33: 705865 | AD33: 706119 | AE33: 706382 | AF33: 706646 | AG33: 706938 | AH33: 707212 | AI33: 707472
A34: Main 2 | B34: 8425020 | C34: 8440480 | D34: 259361 | E34: 259864 | F34: 260378 | G34: 260910 | H34: 261404 | I34: 261713 | J34: 262046 | K34: 262324 | L34: 262667 | M34: 262969 | N34: 263294 | O34: 263622 | P34: 263923 | Q34: 264247 | R34: 264525 | S34: 264813 | T34: 265103 | U34: 265381 | V34: 265664 | W34: 265935 | X34: 266207 | Y34: 266478 | Z34: 266764 | AA34: 267022 | AB34: 267294 | AC34: 267556 | AD34: 267831 | AE34: 268113 | AF34: 268398 | AG34: 268717 | AH34: 269014 | AI34: 269296
A36: Chiller 1 Multistack | B36: 982660 | C36: 982670 | D36: 52330 | E36: 52330 | F36: 52330 | G36: 52330 | H36: 52330 | I36: 52330 | J36: 52330 | K36: 52330 | L36: 52330 | M36: 52330 | N36: 52330 | O36: 52330 | P36: 52330 | Q36: 52330 | R36: 52330 | S36: 52330 | T36: 52330 | U36: 52330 | V36: 52330 | W36: 52330 | X36: 52330 | Y36: 52330 | Z36: 52330 | AA36: 52330 | AB36: 52330 | AC36: 52330 | AD36: 52340 | AE36: 52340 | AF36: 52340 | AG36: 52340 | AH36: 52340 | AI36: 52340
A37: Chiller 2 | B37: 959920 | C37: 959950 | D37: 235190 | E37: 235190 | F37: 235190 | G37: 235200 | H37: 235210 | I37: 237150 | J37: 239300 | K37: 242230 | L37: 244750 | M37: 247870 | N37: 250230 | O37: 253100 | P37: 255800 | Q37: 258680 | R37: 261140 | S37: 263710 | T37: 266330 | U37: 268790 | V37: 271280 | W37: 273640 | X37: 276040 | Y37: 278410 | Z37: 280920 | AA37: 283170 | AB37: 285570 | AC37: 287860 | AD37: 290270 | AE37: 292780 | AF37: 295290 | AG37: 298090 | AH37: 300730 | AI37: 303220
A38: Chiller 3 | B38: 413050 | C38: 415960 | D38: 265450 | E38: 267650 | F38: 270800 | G38: 273110 | H38: 275250 | I38: 275250 | J38: 275250 | K38: 275250 | L38: 275250 | M38: 275250 | N38: 275250 | O38: 275250 | P38: 275250 | Q38: 275250 | R38: 275250 | S38: 275250 | T38: 275250 | U38: 275250 | V38: 275250 | W38: 275250 | X38: 275250 | Y38: 275250 | Z38: 275250 | AA38: 275250 | AB38: 275250 | AC38: 275250 | AD38: 275250 | AE38: 275250 | AF38: 275250 | AG38: 275250 | AH38: 275250 | AI38: 275250
A39: Chiller 4 | B39: 618590 | C39: 624610 | D39: 64660 | E39: 67110 | F39: 68740 | G39: 71320 | H39: 73720 | I39: 76490 | J39: 79520 | K39: 82020 | L39: 85140 | M39: 87840 | N39: 90780 | O39: 93720 | P39: 96440 | Q39: 99350 | R39: 101820 | S39: 104430 | T39: 107060 | U39: 109540 | V39: 112050 | W39: 114430 | X39: 116840 | Y39: 119230 | Z39: 121750 | AA39: 124020 | AB39: 126410 | AC39: 128740 | AD39: 131120 | AE39: 133630 | AF39: 136150 | AG39: 138950 | AH39: 141600 | AI39: 144090
A41: Cooling Tower #1 | B41: 38549 | C41: 39036 | D41: 8853 | E41: 8993 | F41: 9137 | G41: 9274 | H41: 9421 | I41: 9585 | J41: 9789 | K41: 9998 | L41: 10217 | M41: 10447 | N41: 10671 | O41: 10899 | P41: 11077 | Q41: 11212 | R41: 11348 | S41: 11489 | T41: 11626 | U41: 11758 | V41: 11876 | W41: 12005 | X41: 12163 | Y41: 12346 | Z41: 12483 | AA41: 12575 | AB41: 12712 | AC41: 12872 | AD41: 13011 | AE41: 13169 | AF41: 13320 | AG41: 13501 | AH41: 13675 | AI41: 13859
A42: Cooling Tower #2 | B42: 25455 | C42: 25455 | D42: 23465 | E42: 23465 | F42: 23465 | G42: 23465 | H42: 23465 | I42: 23465 | J42: 23465 | K42: 23465 | L42: 23465 | M42: 23465 | N42: 23465 | O42: 23465 | P42: 23465 | Q42: 23465 | R42: 23465 | S42: 23465 | T42: 23465 | U42: 23465 | V42: 23465 | W42: 23465 | X42: 23465 | Y42: 23465 | Z42: 23465 | AA42: 23465 | AB42: 23465 | AC42: 23465 | AD42: 23465 | AE42: 23465 | AF42: 23465 | AG42: 23465 | AH42: 23465 | AI42: 23465
A43: Cooling Tower #3 | B43: 19116 | C43: 19571 | D43: 43796 | E43: 44062 | F43: 44326 | G43: 44598 | H43: 44853 | I43: 45095 | J43: 45309 | K43: 45516 | L43: 45714 | M43: 45914 | N43: 46104 | O43: 46295 | P43: 46527 | Q43: 46797 | R43: 47060 | S43: 47315 | T43: 47589 | U43: 47855 | V43: 48139 | W43: 48409 | X43: 48643 | Y43: 48873 | Z43: 49133 | AA43: 49431 | AB43: 49698 | AC43: 49948 | AD43: 50212 | AE43: 50459 | AF43: 50714 | AG43: 50947 | AH43: 51174 | AI43: 51403
A44: Cooling Tower #4 | B44: 21214 | C44: 21559 | D44: 18772 | E44: 18885 | F44: 19004 | G44: 19117 | H44: 19239 | I44: 19377 | J44: 19552 | K44: 19731 | L44: 19920 | M44: 20119 | N44: 20313 | O44: 20511 | P44: 20661 | Q44: 20769 | R44: 20879 | S44: 20998 | T44: 21107 | U44: 21214 | V44: 21307 | W44: 21412 | X44: 21562 | Y44: 21710 | Z44: 21809 | AA44: 21881 | AB44: 21993 | AC44: 22123 | AD44: 22235 | AE44: 22367 | AF44: 22491 | AG44: 22642 | AH44: 22787 | AI44: 22939
A46: Condenser Water Pump B1-1 | B46: 21070 | C46: 21082 | D46: 36745 | E46: 36745 | F46: 36745 | G46: 36745 | H46: 36745 | I46: 36745 | J46: 36745 | K46: 36745 | L46: 36745 | M46: 36745 | N46: 36745 | O46: 36745 | P46: 36745 | Q46: 36745 | R46: 36745 | S46: 36745 | T46: 36745 | U46: 36745 | V46: 36745 | W46: 36745 | X46: 36745 | Y46: 36745 | Z46: 36745 | AA46: 36745 | AB46: 36745 | AC46: 36747 | AD46: 36747 | AE46: 36747 | AF46: 36747 | AG46: 36747 | AH46: 36747 | AI46: 36747
A47: Condenser Water Pump B1-2 | B47: 20725 | C47: 20725 | D47: 3386 | E47: 3386 | F47: 3386 | G47: 3386 | H47: 3386 | I47: 3537 | J47: 3697 | K47: 3922 | L47: 4126 | M47: 4403 | N47: 4614 | O47: 4867 | P47: 5079 | Q47: 5312 | R47: 5519 | S47: 5736 | T47: 5953 | U47: 6163 | V47: 6382 | W47: 6600 | X47: 6814 | Y47: 7031 | Z47: 7282 | AA47: 7499 | AB47: 7718 | AC47: 7926 | AD47: 8145 | AE47: 8360 | AF47: 8585 | AG47: 8817 | AH47: 9032 | AI47: 9245
... A54: Chilled Water Pump B1-4 | B54: 33903 | C54: 34631 | D54: 1562 | E54: 1701 | F54: 1801 | G54: 1937 | H54: 2080 | I54: 2217 | J54: 2355 | K54: 2472 | L54: 2605 | M54: 2720 | N54: 2845 | O54: 2980 | P54: 3116 | Q54: 3264 | R54: 3400 | S54: 3539 | T54: 3676 | U54: 3816 | V54: 3985 | W54: 4110 | X54: 4248 | Y54: 4381 | Z54: 4520 | AA54: 4666 | AB54: 4812 | AC54: 4946 | AD54: 5087 | AE54: 5235 | AF54: 5385 | AG54: 5542 | AH54: 5685 | AI54: 5823
A56: Chiller Electricity Consumption
A57: Main 1 | B57: =B33-#REF! -> #REF! | C57: =C33-B33 -> 40 | D57: =D33-B33 -> -4651515 | E57: =E33-D33 -> 0 | F57: =F33-E33 -> 0 | G57: =G33-F33 -> 0 | H57: =H33-G33 -> 0 | I57: =I33-H33 -> 500 | J57: =J33-I33 -> -80 | K57: =K33-J33 -> 300 | L57: =L33-K33 -> 259 | ... Y57: =Y33-X33 -> 249 | AA57: =AA33-Z33 -> 240 | AB57: =AB33-AA33 -> 253 | AC57: =AC33-AB33 -> 241 | AD57: =AD33-AC33 -> 254 | AE57: =AE33-AD33 -> 263 | AF57: =AF33-AE33 -> 264 | AG57: =AG33-AF33 -> 292 | AH57: =AH33-AG33 -> 274 | AI57: =AI33-AG33 -> 534
A58: Main 2 | B58: =B34-#REF! -> #REF! | C58: =C34-B34 -> 15460 | D58: =D34-B34 -> -8165659 | E58: =E34-D34 -> 503 | F58: =F34-E34 -> 514 | G58: =G34-F34 -> 532 | H58: =H34-G34 -> 494 | I58: =I34-H34 -> 309 | J58: =J34-I34 -> 333 | K58: =K34-J34 -> 278 | L58: =L34-K34 -> 343 | ... AH58: =AH34-AG34 -> 297 | AI58: =AI34-AG34 -> 579 | AJ58: TOTAL | AK58: AVE / DAY
...
