Workbook

Sheet Total
A1: Site Name | B1: Day | C1: Month | D1: Year | E1: Total Electricity Kwh | F1: Electricity Tariff ($/Kwh) | G1: Total Fuel Oil (Liters) | H1: Fuel Oil $/Liter | I1: LPG (Kg) | J1: LPG $/Kg | K1: Water Utility Supply (m3) m3 | L1: Water Utility Supply (m3) $/m3 | M1: Irrigation Water (m3) m3 | N1: Irrigation water $/m3 | O1: Room Nights
A2: Beirut | B2: 1 | C2: 9 | D2: 2020 | E2: =ELEC!N3 -> 11078 | F2: =SUM('EDl log'!T4) -> 0.083178659 | G2: =-tanks!AW6 -> 155 | H2: =SUM(tanks!AV6) -> 0.53 | I2: =('B5'!AU5)*0.51 -> 0 | J2: ='B5'!AX5/0.51 -> 1.5686275 | K2: =WATER!I6 -> 0 | L2: =SUM(WATER!J6) -> 0 | M2: =WATER!Q6 -> 0 | N2: 0.6 | O2: =ELEC!B3 -> 0
A3: Beirut | B3: =B2+1 -> 2 | C3: 9 | D3: 2020 | E3: =ELEC!N4 -> 12266 | F3: =SUM('EDl log'!T5) -> 0.10639618 | G3: =-tanks!AW7 -> 0 | H3: =SUM(tanks!AV7) -> 0.53 | I3: =('B5'!AU6)*0.51 -> 0 | J3: ='B5'!AX6/0.51 -> 1.5686275 | K3: =WATER!I7 -> 0 | L3: =SUM(WATER!J7) -> 0 | M3: =WATER!Q7 -> 0 | N3: 0.6 | O3: =ELEC!B4 -> 0
A4: Beirut | B4: =B3+1 -> 3 | C4: 9 | D4: 2020 | E4: =ELEC!N5 -> 12559 | F4: =SUM('EDl log'!T6) -> 0.096652465 | G4: =-tanks!AW8 -> 350 | H4: =SUM(tanks!AV8) -> 0.53 | I4: =('B5'!AU7)*0.51 -> 0 | J4: ='B5'!AX7/0.51 -> 1.5686275 | K4: =WATER!I8 -> 0 | L4: =SUM(WATER!J8) -> 0 | M4: =WATER!Q8 -> 0 | N4: 0.6 | O4: =ELEC!B5 -> 0
A5: Beirut | B5: =B4+1 -> 4 | C5: 9 | D5: 2020 | E5: =ELEC!N6 -> 12925 | F5: =SUM('EDl log'!T7) -> 0.11097463 | G5: =-tanks!AW9 -> 303 | H5: =SUM(tanks!AV9) -> 0.53 | I5: =('B5'!AU8)*0.51 -> 0 | J5: ='B5'!AX8/0.51 -> 1.5686275 | K5: =WATER!I9 -> 0 | L5: =SUM(WATER!J9) -> 0 | M5: =WATER!Q9 -> 0 | N5: 0.6 | O5: =ELEC!B6 -> 0
A6: Beirut | B6: =B5+1 -> 5 | C6: 9 | D6: 2020 | E6: =ELEC!N7 -> 10761 | F6: =SUM('EDl log'!T8) -> 0.087390022 | G6: =-tanks!AW10 -> 0 | H6: =SUM(tanks!AV10) -> 0.53 | I6: =('B5'!AU9)*0.51 -> 0 | J6: ='B5'!AX9/0.51 -> 1.5686275 | K6: =WATER!I10 -> 0 | L6: =SUM(WATER!J10) -> 0 | M6: =WATER!Q10 -> 0 | N6: 0.6 | O6: =ELEC!B7 -> 0
A7: Beirut | B7: =B6+1 -> 6 | C7: 9 | D7: 2020 | E7: =ELEC!N8 -> 10340 | F7: =SUM('EDl log'!T9) -> 0.11498091 | G7: =-tanks!AW11 -> 0 | H7: =SUM(tanks!AV11) -> 0.53 | I7: =('B5'!AU10)*0.51 -> 0 | J7: ='B5'!AX10/0.51 -> 1.5686275 | K7: =WATER!I11 -> 118 | L7: =SUM(WATER!J11) -> 2.1186441 | M7: =WATER!Q11 -> 0 | N7: 0.6 | O7: =ELEC!B8 -> 0
A8: Beirut | B8: =B7+1 -> 7 | C8: 9 | D8: 2020 | E8: =ELEC!N9 -> 12789 | F8: =SUM('EDl log'!T10) -> 0.092334781 | G8: =-tanks!AW12 -> 0 | H8: =SUM(tanks!AV12) -> 0.53 | I8: =('B5'!AU11)*0.51 -> 0 | J8: ='B5'!AX11/0.51 -> 1.5686275 | K8: =WATER!I12 -> 0 | L8: =SUM(WATER!J12) -> 0 | M8: =WATER!Q12 -> 0 | N8: 0.6 | O8: =ELEC!B9 -> 0
A9: Beirut | B9: =B8+1 -> 8 | C9: 9 | D9: 2020 | E9: =ELEC!N10 -> 12367 | F9: =SUM('EDl log'!T11) -> 0.15042934 | G9: =-tanks!AW13 -> 0 | H9: =SUM(tanks!AV13) -> 0.53 | I9: =('B5'!AU12)*0.51 -> 0 | J9: ='B5'!AX12/0.51 -> 1.5686275 | K9: =WATER!I13 -> 0 | L9: =SUM(WATER!J13) -> 0 | M9: =WATER!Q13 -> 0 | N9: 0.6 | O9: =ELEC!B10 -> 0
A10: Beirut | B10: =B9+1 -> 9 | C10: 9 | D10: 2020 | E10: =ELEC!N11 -> 11724 | F10: =SUM('EDl log'!T12) -> 0.091466843 | G10: =-tanks!AW14 -> 0 | H10: =SUM(tanks!AV14) -> 0.53 | I10: =('B5'!AU13)*0.51 -> 183.6 | J10: ='B5'!AX13/0.51 -> 1.5686275 | K10: =WATER!I14 -> 0 | L10: =SUM(WATER!J14) -> 0 | M10: =WATER!Q14 -> 0 | N10: 0.6 | O10: =ELEC!B11 -> 0
A11: Beirut | B11: =B10+1 -> 10 | C11: 9 | D11: 2020 | E11: =ELEC!N12 -> 11004 | F11: =SUM('EDl log'!T13) -> 0.025994703 | G11: =-tanks!AW15 -> 0 | H11: =SUM(tanks!AV15) -> 0.54 | I11: =('B5'!AU14)*0.51 -> 0 | J11: ='B5'!AX14/0.51 -> 1.5686275 | K11: =WATER!I15 -> 0 | L11: =SUM(WATER!J15) -> 0 | M11: =WATER!Q15 -> 0 | N11: 0.6 | O11: =ELEC!B12 -> 0
A12: Beirut | B12: =B11+1 -> 11 | C12: 9 | D12: 2020 | E12: =ELEC!N13 -> 11016 | F12: =SUM('EDl log'!T14) -> 0.1003431 | G12: =-tanks!AW16 -> 0 | H12: =SUM(tanks!AV16) -> 0.54 | I12: =('B5'!AU15)*0.51 -> 0 | J12: ='B5'!AX15/0.51 -> 1.5686275 | K12: =WATER!I16 -> 0 | L12: =SUM(WATER!J16) -> 0 | M12: =WATER!Q16 -> 0 | N12: 0.6 | O12: =ELEC!B13 -> 0
A13: Beirut | B13: =B12+1 -> 12 | C13: 9 | D13: 2020 | E13: =ELEC!N14 -> 10368 | F13: =SUM('EDl log'!T15) -> 0.10096417 | G13: =-tanks!AW17 -> 0 | H13: =SUM(tanks!AV17) -> 0.54 | I13: =('B5'!AU16)*0.51 -> 0 | J13: ='B5'!AX16/0.51 -> 1.5686275 | K13: =WATER!I17 -> 0 | L13: =SUM(WATER!J17) -> 0 | M13: =WATER!Q17 -> 0 | N13: 0.6 | O13: =ELEC!B14 -> 0
A14: Beirut | B14: =B13+1 -> 13 | C14: 9 | D14: 2020 | E14: =ELEC!N15 -> 9041 | F14: =SUM('EDl log'!T16) -> 0.10004211 | G14: =-tanks!AW18 -> 0 | H14: =SUM(tanks!AV18) -> 0.54 | I14: =('B5'!AU17)*0.51 -> 45.9 | J14: ='B5'!AX17/0.51 -> 1.5686275 | K14: =WATER!I18 -> 0 | L14: =SUM(WATER!J18) -> 0 | M14: =WATER!Q18 -> 0 | N14: 0.6 | O14: =ELEC!B15 -> 0
... A31: Beirut | B31: =B30+1 -> 30 | C31: 9 | D31: 2020 | E31: =ELEC!N32 -> 11854 | F31: =SUM('EDl log'!T33) -> 0.10054052 | G31: =-tanks!AW35 -> 0 | H31: =SUM(tanks!AV35) -> 0.503 | I31: =('B5'!AU34)*0.51 -> 0 | J31: ='B5'!AX34/0.51 -> 1.5686275 | K31: =WATER!I35 -> 0 | L31: =SUM(WATER!J35) -> 0 | M31: =WATER!Q35 -> 0 | N31: 0.6 | O31: =ELEC!B32 -> 0

Sheet Submetering
A1: Site Name | B1: Day | C1: Month | D1: Year | E1: ATS1 Kwh | F1: ATS2 Kwh | G1: ATS3 Kwh | H1: ATS4 Kwh | I1: ATS5 Kwh | J1: Guest (m3) | K1: Kitchen & Laundry (m3) | L1: Room Nights
A2: Beirut | B2: 1 | C2: 9 | D2: 2020 | E2: =ELEC!M3 -> 3970 | F2: =ELEC!K3 -> 1156 | G2: =ELEC!I3 -> 1266 | H2: =ELEC!E3 -> 3758 | I2: =ELEC!G3 -> 928 | J2: =WATER!Y6 -> 80 | K2: =WATER!AJ6 -> 0 | L2: =ELEC!B3 -> 0
A3: Beirut | B3: =B2+1 -> 2 | C3: 9 | D3: 2020 | E3: =ELEC!M4 -> 5398 | F3: =ELEC!K4 -> 1040 | G3: =ELEC!I4 -> 1444 | H3: =ELEC!E4 -> 3418 | I3: =ELEC!G4 -> 966 | J3: =WATER!Y7 -> 58 | K3: =WATER!AJ7 -> 0 | L3: =ELEC!B4 -> 0
A4: Beirut | B4: =B3+1 -> 3 | C4: 9 | D4: 2020 | E4: =ELEC!M5 -> 3032 | F4: =ELEC!K5 -> 1114 | G4: =ELEC!I5 -> 1442 | H4: =ELEC!E5 -> 6014 | I4: =ELEC!G5 -> 957 | J4: =WATER!Y8 -> 0 | K4: =WATER!AJ8 -> 0 | L4: =ELEC!B5 -> 0
A5: Beirut | B5: =B4+1 -> 4 | C5: 9 | D5: 2020 | E5: =ELEC!M6 -> 2028 | F5: =ELEC!K6 -> 1124 | G5: =ELEC!I6 -> 1464 | H5: =ELEC!E6 -> 7308 | I5: =ELEC!G6 -> 1001 | J5: =WATER!Y9 -> 0 | K5: =WATER!AJ9 -> 66 | L5: =ELEC!B6 -> 0
A6: Beirut | B6: =B5+1 -> 5 | C6: 9 | D6: 2020 | E6: =ELEC!M7 -> 1700 | F6: =ELEC!K7 -> 898 | G6: =ELEC!I7 -> 1242 | H6: =ELEC!E7 -> 5960 | I6: =ELEC!G7 -> 961 | J6: =WATER!Y10 -> 0 | K6: =WATER!AJ10 -> 0 | L6: =ELEC!B7 -> 0
A7: Beirut | B7: =B6+1 -> 6 | C7: 9 | D7: 2020 | E7: =ELEC!M8 -> 1910 | F7: =ELEC!K8 -> 832 | G7: =ELEC!I8 -> 1282 | H7: =ELEC!E8 -> 5292 | I7: =ELEC!G8 -> 1024 | J7: =WATER!Y11 -> 0 | K7: =WATER!AJ11 -> 0 | L7: =ELEC!B8 -> 0
A8: Beirut | B8: =B7+1 -> 7 | C8: 9 | D8: 2020 | E8: =ELEC!M9 -> 4920 | F8: =ELEC!K9 -> 1196 | G8: =ELEC!I9 -> 1052 | H8: =ELEC!E9 -> 4710 | I8: =ELEC!G9 -> 911 | J8: =WATER!Y12 -> 0 | K8: =WATER!AJ12 -> 0 | L8: =ELEC!B9 -> 0
A9: Beirut | B9: =B8+1 -> 8 | C9: 9 | D9: 2020 | E9: =ELEC!M10 -> 4974 | F9: =ELEC!K10 -> 1196 | G9: =ELEC!I10 -> 900 | H9: =ELEC!E10 -> 4468 | I9: =ELEC!G10 -> 829 | J9: =WATER!Y13 -> 0 | K9: =WATER!AJ13 -> 0 | L9: =ELEC!B10 -> 0
A10: Beirut | B10: =B9+1 -> 9 | C10: 9 | D10: 2020 | E10: =ELEC!M11 -> 5108 | F10: =ELEC!K11 -> 1016 | G10: =ELEC!I11 -> 1040 | H10: =ELEC!E11 -> 3700 | I10: =ELEC!G11 -> 860 | J10: =WATER!Y14 -> 0 | K10: =WATER!AJ14 -> 0 | L10: =ELEC!B11 -> 0
A11: Beirut | B11: =B10+1 -> 10 | C11: 9 | D11: 2020 | E11: =ELEC!M12 -> 4768 | F11: =ELEC!K12 -> 960 | G11: =ELEC!I12 -> 956 | H11: =ELEC!E12 -> 3524 | I11: =ELEC!G12 -> 796 | J11: =WATER!Y15 -> 0 | K11: =WATER!AJ15 -> 0 | L11: =ELEC!B12 -> 0
A12: Beirut | B12: =B11+1 -> 11 | C12: 9 | D12: 2020 | E12: =ELEC!M13 -> 4722 | F12: =ELEC!K13 -> 1006 | G12: =ELEC!I13 -> 986 | H12: =ELEC!E13 -> 3482 | I12: =ELEC!G13 -> 820 | J12: =WATER!Y16 -> 0 | K12: =WATER!AJ16 -> 0 | L12: =ELEC!B13 -> 0
A13: Beirut | B13: =B12+1 -> 12 | C13: 9 | D13: 2020 | E13: =ELEC!M14 -> 4550 | F13: =ELEC!K14 -> 976 | G13: =ELEC!I14 -> 1002 | H13: =ELEC!E14 -> 2998 | I13: =ELEC!G14 -> 842 | J13: =WATER!Y17 -> 0 | K13: =WATER!AJ17 -> 32 | L13: =ELEC!B14 -> 0
A14: Beirut | B14: =B13+1 -> 13 | C14: 9 | D14: 2020 | E14: =ELEC!M15 -> 3956 | F14: =ELEC!K15 -> 786 | G14: =ELEC!I15 -> 972 | H14: =ELEC!E15 -> 2520 | I14: =ELEC!G15 -> 807 | J14: =WATER!Y18 -> 0 | K14: =WATER!AJ18 -> 0 | L14: =ELEC!B15 -> 0
... A31: Beirut | B31: =B30+1 -> 30 | C31: 9 | D31: 2020 | E31: =ELEC!M32 -> 5496 | F31: =ELEC!K32 -> 1056 | G31: =ELEC!I32 -> 940 | H31: =ELEC!E32 -> 3568 | I31: =ELEC!G32 -> 794 | J31: =WATER!Y35 -> 60 | K31: =WATER!AJ35 -> 23 | L31: =ELEC!B32 -> 0

Sheet ELEC
A1: OOC | B1: Room OCC | D1: MDB3 | E1: MDB3/day | F1: EMDB2 | G1: EMDB2/day | H1: EMDB1 | I1: EMDB1/day | J1: MDB2 | K1: mdb2/day | L1: MDB1 | M1: MDB1/Day | N1: Total KWH | O1: KWH/Rooc | P1: Gen MHW | Q1: Gen/Day KWH | R1: EDL KWH | S1: CH1 RH | T1: RH | U1: C1h1 power | V1: CH1 Con KWH | W1: CH2 RH | X1: RH | Y1: Ch2 power | Z1: CH2 Con KWH | AA1: CH3 RH | AB1: RH | AC1: Ch3 power | AD1: CH3 Con KWH | AE1: RH total | AF1: KWH total | AG1: AVG chiller KW/Hr
A2: =[1]ELEC!$A$33 -> 0 | B2: =[1]ELEC!$B$33 -> 0 | C2: 44074 | D2: =[1]ELEC!D33 -> 32168402 | E2: =[1]ELEC!E33 -> 2944 | F2: =[1]ELEC!F33 -> 3846115 | G2: =[1]ELEC!G33 -> 1023 | H2: =[1]ELEC!H33 -> 17640934 | I2: =[1]ELEC!I33 -> 1218 | J2: =[1]ELEC!J33 -> 28692174 | K2: =[1]ELEC!K33 -> 880 | ... AL2: =[1]ELEC!AL33 -> 0
A3: ='General information '!F6 -> 0 | B3: =SUM(230*A3) -> 0 | C3: 44075 | D3: 32172160 | E3: =D3-D2 -> 3758 | F3: 3847043 | G3: =F3-F2 -> 928 | H3: 17642200 | I3: =H3-H2 -> 1266 | J3: 28693330 | K3: =J3-J2 -> 1156 | L3: 23581616 | M3: =L3-L2 -> 3970 | N3: =M3+K3+I3+G3+E3 -> 11078 | O3: =IF(B3>0,N3/B3,0) -> 0 | P3: 16264 | Q3: =(P3-P2)*1000 -> 1000 | R3: =+N3-Q3 -> 10078 | S3: 9498 | T3: =S3-S2 -> 9 | U3: 285005 | V3: =U3-U2 -> 2005 | W3: 32049 | X3: =W3-W2 -> 0 | Y3: 673052 | Z3: =Y3-Y2 -> 0 | AA3: 35503 | AB3: =AA3-AA2 -> 2 | AC3: 876365 | AD3: =AC3-AC2 -> 468 | AE3: =AB3+X3+T3 -> 11 | AF3: =V3+Z3+AD3 -> 2473 | AG3: =IF(AE3>0,AF3/AE3,0) -> 224.81818
A4: ='General information '!F7 -> 0 | B4: =SUM(230*A4) -> 0 | C4: 44076 | D4: 32175578 | E4: =D4-D3 -> 3418 | F4: 3848009 | G4: =F4-F3 -> 966 | H4: 17643644 | I4: =H4-H3 -> 1444 | J4: 28694370 | K4: =J4-J3 -> 1040 | L4: 23587014 | M4: =L4-L3 -> 5398 | N4: =M4+K4+I4+G4+E4 -> 12266 | O4: =IF(B4>0,N4/B4,0) -> 0 | P4: 16269 | Q4: =(P4-P3)*1000 -> 5000 | R4: =N4-Q4 -> 7266 | S4: 9511 | T4: =S4-S3 -> 13 | U4: 288090 | V4: =U4-U3 -> 3085 | W4: =W3 -> 32049 | X4: =W4-W3 -> 0 | Y4: =Y3 -> 673052 | Z4: =Y4-Y3 -> 0 | AA4: =AA3 -> 35503 | AB4: =AA4-AA3 -> 0 | AC4: =AC3 -> 876365 | AD4: =AC4-AC3 -> 0 | AE4: =AB4+X4+T4 -> 13 | AF4: =V4+Z4+AD4 -> 3085 | AG4: =IF(AE4>0,AF4/AE4,0) -> 237.30769
A5: ='General information '!F8 -> 0 | B5: =SUM(230*A5) -> 0 | C5: 44077 | D5: 32181592 | E5: =D5-D4 -> 6014 | F5: 3848966 | G5: =F5-F4 -> 957 | H5: 17645086 | I5: =H5-H4 -> 1442 | J5: 28695484 | K5: =J5-J4 -> 1114 | L5: 23590046 | M5: =L5-L4 -> 3032 | N5: =M5+K5+I5+G5+E5 -> 12559 | O5: =IF(B5>0,N5/B5,0) -> 0 | P5: 16274 | Q5: =(P5-P4)*1000 -> 5000 | R5: =N5-Q5 -> 7559 | S5: 9517 | T5: =S5-S4 -> 6 | U5: 289529 | V5: =U5-U4 -> 1439 | W5: 32049 | X5: =W5-W4 -> 0 | Y5: =Y4 -> 673052 | Z5: =Y5-Y4 -> 0 | AA5: 35512 | AB5: =AA5-AA4 -> 9 | AC5: 878376 | AD5: =AC5-AC4 -> 2011 | AE5: =AB5+X5+T5 -> 15 | AF5: =V5+Z5+AD5 -> 3450 | AG5: =IF(AE5>0,AF5/AE5,0) -> 230 | AI5: =R5-'EDl log'!B3 -> -341719
A6: ='General information '!F9 -> 0 | B6: =SUM(230*A6) -> 0 | C6: 44078 | D6: 32188900 | E6: =D6-D5 -> 7308 | F6: 3849967 | G6: =F6-F5 -> 1001 | H6: 17646550 | I6: =H6-H5 -> 1464 | J6: 28696608 | K6: =J6-J5 -> 1124 | L6: 23592074 | M6: =L6-L5 -> 2028 | N6: =M6+K6+I6+G6+E6 -> 12925 | O6: =IF(B6>0,N6/B6,0) -> 0 | P6: 16279 | Q6: =(P6-P5)*1000 -> 5000 | R6: =N6-Q6 -> 7925 | S6: =S5 -> 9517 | T6: =S6-S5 -> 0 | U6: =U5 -> 289529 | V6: =U6-U5 -> 0 | W6: =W5 -> 32049 | X6: =W6-W5 -> 0 | Y6: =Y5 -> 673052 | Z6: =Y6-Y5 -> 0 | AA6: 35528 | AB6: =AA6-AA5 -> 16 | AC6: 881970 | AD6: =AC6-AC5 -> 3594 | AE6: =AB6+X6+T6 -> 16 | AF6: =V6+Z6+AD6 -> 3594 | AG6: =IF(AE6>0,AF6/AE6,0) -> 224.625 | AI6: =R6-'EDl log'!B4 -> -346172
A7: ='General information '!F10 -> 0 | B7: =SUM(230*A7) -> 0 | C7: 44079 | D7: 32194860 | E7: =D7-D6 -> 5960 | F7: 3850928 | G7: =F7-F6 -> 961 | H7: 17647792 | I7: =H7-H6 -> 1242 | J7: 28697506 | K7: =J7-J6 -> 898 | L7: 23593774 | M7: =L7-L6 -> 1700 | N7: =M7+K7+I7+G7+E7 -> 10761 | O7: =IF(B7>0,N7/B7,0) -> 0 | P7: 16281 | Q7: =(P7-P6)*1000 -> 2000 | R7: =N7-Q7 -> 8761 | S7: =S6 -> 9517 | T7: =S7-S6 -> 0 | U7: =U6 -> 289529 | V7: =U7-U6 -> 0 | W7: =W6 -> 32049 | X7: =W7-W6 -> 0 | Y7: =Y6 -> 673052 | Z7: =Y7-Y6 -> 0 | AA7: 35538 | AB7: =AA7-AA6 -> 10 | AC7: 884534 | AD7: =AC7-AC6 -> 2564 | AE7: =AB7+X7+T7 -> 10 | AF7: =V7+Z7+AD7 -> 2564 | AG7: =IF(AE7>0,AF7/AE7,0) -> 256.4 | AI7: =R7-'EDl log'!B5 -> -349353
A8: ='General information '!F11 -> 0 | B8: =SUM(230*A8) -> 0 | C8: 44080 | D8: 32200152 | E8: =D8-D7 -> 5292 | F8: 3851952 | G8: =F8-F7 -> 1024 | H8: 17649074 | I8: =H8-H7 -> 1282 | J8: 28698338 | K8: =J8-J7 -> 832 | L8: 23595684 | M8: =L8-L7 -> 1910 | N8: =M8+K8+I8+G8+E8 -> 10340 | O8: =IF(B8>0,N8/B8,0) -> 0 | P8: 16285 | Q8: =(P8-P7)*1000 -> 4000 | R8: =N8-Q8 -> 6340 | S8: =S7 -> 9517 | T8: =S8-S7 -> 0 | U8: =U7 -> 289529 | V8: =U8-U7 -> 0 | W8: =W7 -> 32049 | X8: =W8-W7 -> 0 | Y8: =Y7 -> 673052 | Z8: =Y8-Y7 -> 0 | AA8: 35545 | AB8: =AA8-AA7 -> 7 | AC8: 886156 | AD8: =AC8-AC7 -> 1622 | AE8: =AB8+X8+T8 -> 7 | AF8: =V8+Z8+AD8 -> 1622 | AG8: =IF(AE8>0,AF8/AE8,0) -> 231.71429 | AI8: =R8-'EDl log'!B6 -> -355743
A9: ='General information '!F12 -> 0 | B9: =SUM(230*A9) -> 0 | C9: 44081 | D9: 32204862 | E9: =D9-D8 -> 4710 | F9: 3852863 | G9: =F9-F8 -> 911 | H9: 17650126 | I9: =H9-H8 -> 1052 | J9: 28699534 | K9: =J9-J8 -> 1196 | L9: 23600604 | M9: =L9-L8 -> 4920 | N9: =M9+K9+I9+G9+E9 -> 12789 | O9: =IF(B9>0,N9/B9,0) -> 0 | P9: 16290 | Q9: =(P9-P8)*1000 -> 5000 | R9: =N9-Q9 -> 7789 | S9: 9527 | T9: =S9-S8 -> 10 | U9: 292016 | V9: =U9-U8 -> 2487 | W9: =W8 -> 32049 | X9: =W9-W8 -> 0 | Y9: =Y8 -> 673052 | Z9: =Y9-Y8 -> 0 | AA9: 35550 | AB9: =AA9-AA8 -> 5 | AC9: 887256 | AD9: =AC9-AC8 -> 1100 | AE9: =AB9+X9+T9 -> 15 | AF9: =V9+Z9+AD9 -> 3587 | AG9: =IF(AE9>0,AF9/AE9,0) -> 239.13333 | AI9: =R9-'EDl log'!B7 -> -358678
A10: ='General information '!F13 -> 0 | B10: =SUM(230*A10) -> 0 | C10: 44082 | D10: 32209330 | E10: =D10-D9 -> 4468 | F10: 3853692 | G10: =F10-F9 -> 829 | H10: 17651026 | I10: =H10-H9 -> 900 | J10: 28700730 | K10: =J10-J9 -> 1196 | L10: 23605578 | M10: =L10-L9 -> 4974 | N10: =M10+K10+I10+G10+E10 -> 12367 | O10: =IF(B10>0,N10/B10,0) -> 0 | P10: 16298 | Q10: =(P10-P9)*1000 -> 8000 | R10: =N10-Q10 -> 4367 | S10: 9541 | T10: =S10-S9 -> 14 | U10: 295149 | V10: =U10-U9 -> 3133 | W10: 32049 | X10: =W10-W9 -> 0 | Y10: =Y9 -> 673052 | Z10: =Y10-Y9 -> 0 | AA10: 35556 | AB10: =AA10-AA9 -> 6 | AC10: 888280 | AD10: =AC10-AC9 -> 1024 | AE10: =AB10+X10+T10 -> 20 | AF10: =V10+Z10+AD10 -> 4157 | AG10: =IF(AE10>0,AF10/AE10,0) -> 207.85 | AI10: =R10-'EDl log'!B8 -> -366632
A11: ='General information '!F14 -> 0 | B11: =SUM(230*A11) -> 0 | C11: 44083 | D11: 32213030 | E11: =D11-D10 -> 3700 | F11: 3854552 | G11: =F11-F10 -> 860 | H11: 17652066 | I11: =H11-H10 -> 1040 | J11: 28701746 | K11: =J11-J10 -> 1016 | L11: 23610686 | M11: =L11-L10 -> 5108 | N11: =M11+K11+I11+G11+E11 -> 11724 | O11: =IF(B11>0,N11/B11,0) -> 0 | P11: 16300 | Q11: =(P11-P10)*1000 -> 2000 | R11: =N11-Q11 -> 9724 | S11: 9554 | T11: =S11-S10 -> 13 | U11: 298048 | V11: =U11-U10 -> 2899 | W11: =W10 -> 32049 | X11: =W11-W10 -> 0 | Y11: =Y10 -> 673052 | Z11: =Y11-Y10 -> 0 | AA11: =AA10 -> 35556 | AB11: =AA11-AA10 -> 0 | AC11: =AC10 -> 888280 | AD11: =AC11-AC10 -> 0 | AE11: =AB11+X11+T11 -> 13 | AF11: =V11+Z11+AD11 -> 2899 | AG11: =IF(AE11>0,AF11/AE11,0) -> 223 | AI11: =R11-'EDl log'!B9 -> -364617
A12: ='General information '!F15 -> 0 | B12: =SUM(230*A12) -> 0 | C12: 44084 | D12: 32216554 | E12: =D12-D11 -> 3524 | F12: 3855348 | G12: =F12-F11 -> 796 | H12: 17653022 | I12: =H12-H11 -> 956 | J12: 28702706 | K12: =J12-J11 -> 960 | L12: 23615454 | M12: =L12-L11 -> 4768 | N12: =M12+K12+I12+G12+E12 -> 11004 | O12: =IF(B12>0,N12/B12,0) -> 0 | P12: 16302 | Q12: =(P12-P11)*1000 -> 2000 | R12: =N12-Q12 -> 9004 | S12: 9566 | T12: =S12-S11 -> 12 | U12: 300876 | V12: =U12-U11 -> 2828 | W12: =W11 -> 32049 | X12: =W12-W11 -> 0 | Y12: =Y11 -> 673052 | Z12: =Y12-Y11 -> 0 | AA12: =AA11 -> 35556 | AB12: =AA12-AA11 -> 0 | AC12: =AC11 -> 888280 | AD12: =AC12-AC11 -> 0 | AE12: =AB12+X12+T12 -> 12 | AF12: =V12+Z12+AD12 -> 2828 | AG12: =IF(AE12>0,AF12/AE12,0) -> 235.66667 | AI12: =R12-'EDl log'!B10 -> -369575
A13: ='General information '!F16 -> 0 | B13: =SUM(230*A13) -> 0 | C13: 44085 | D13: 32220036 | E13: =D13-D12 -> 3482 | F13: 3856168 | G13: =F13-F12 -> 820 | H13: 17654008 | I13: =H13-H12 -> 986 | J13: 28703712 | K13: =J13-J12 -> 1006 | L13: 23620176 | M13: =L13-L12 -> 4722 | N13: =M13+K13+I13+G13+E13 -> 11016 | O13: =IF(B13>0,N13/B13,0) -> 0 | P13: 16305 | Q13: =(P13-P12)*1000 -> 3000 | R13: =N13-Q13 -> 8016 | S13: 9579 | T13: =S13-S12 -> 13 | U13: 303680 | V13: =U13-U12 -> 2804 | W13: =W12 -> 32049 | X13: =W13-W12 -> 0 | Y13: =Y12 -> 673052 | Z13: =Y13-Y12 -> 0 | AA13: =AA12 -> 35556 | AB13: =AA13-AA12 -> 0 | AC13: =AC12 -> 888280 | AD13: =AC13-AC12 -> 0 | AE13: =AB13+X13+T13 -> 13 | AF13: =V13+Z13+AD13 -> 2804 | AG13: =IF(AE13>0,AF13/AE13,0) -> 215.69231 | AI13: =R13-'EDl log'!B11 -> -372739
A14: ='General information '!F17 -> 0 | B14: =SUM(230*A14) -> 0 | C14: 44086 | D14: 32223034 | E14: =D14-D13 -> 2998 | F14: 3857010 | G14: =F14-F13 -> 842 | H14: 17655010 | I14: =H14-H13 -> 1002 | J14: 28704688 | K14: =J14-J13 -> 976 | L14: 23624726 | M14: =L14-L13 -> 4550 | N14: =M14+K14+I14+G14+E14 -> 10368 | O14: =IF(B14>0,N14/B14,0) -> 0 | P14: 16308 | Q14: =(P14-P13)*1000 -> 3000 | R14: =N14-Q14 -> 7368 | S14: 9590 | T14: =S14-S13 -> 11 | U14: 306003 | V14: =U14-U13 -> 2323 | W14: =W13 -> 32049 | X14: =W14-W13 -> 0 | Y14: =Y13 -> 673052 | Z14: =Y14-Y13 -> 0 | AA14: =AA13 -> 35556 | AB14: =AA14-AA13 -> 0 | AC14: =AC13 -> 888280 | AD14: =AC14-AC13 -> 0 | AE14: =AB14+X14+T14 -> 11 | AF14: =V14+Z14+AD14 -> 2323 | AG14: =IF(AE14>0,AF14/AE14,0) -> 211.18182 | AI14: =R14-'EDl log'!B12 -> -378323
A15: ='General information '!F18 -> 0 | B15: =SUM(230*A15) -> 0 | C15: 44087 | D15: 32225554 | E15: =D15-D14 -> 2520 | F15: 3857817 | G15: =F15-F14 -> 807 | H15: 17655982 | I15: =H15-H14 -> 972 | J15: 28705474 | K15: =J15-J14 -> 786 | L15: 23628682 | M15: =L15-L14 -> 3956 | N15: =M15+K15+I15+G15+E15 -> 9041 | O15: =IF(B15>0,N15/B15,0) -> 0 | P15: 16310 | Q15: =(P15-P14)*1000 -> 2000 | R15: =N15-Q15 -> 7041 | S15: 9599 | T15: =S15-S14 -> 9 | U15: 307976 | V15: =U15-U14 -> 1973 | W15: =W14 -> 32049 | X15: =W15-W14 -> 0 | Y15: =Y14 -> 673052 | Z15: =Y15-Y14 -> 0 | AA15: =AA14 -> 35556 | AB15: =AA15-AA14 -> 0 | AC15: =AC14 -> 888280 | AD15: =AC15-AC14 -> 0 | AE15: =AB15+X15+T15 -> 9 | AF15: =V15+Z15+AD15 -> 1973 | AG15: =IF(AE15>0,AF15/AE15,0) -> 219.22222 | AI15: =R15-'EDl log'!B13 -> -383392
A16: ='General information '!F19 -> 0 | B16: =SUM(230*A16) -> 0 | C16: 44088 | D16: 32228614 | E16: =D16-D15 -> 3060 | F16: 3858662 | G16: =F16-F15 -> 845 | H16: 17656862 | I16: =H16-H15 -> 880 | J16: 28706274 | K16: =J16-J15 -> 800 | L16: 23632202 | M16: =L16-L15 -> 3520 | N16: =M16+K16+I16+G16+E16 -> 9105 | O16: =IF(B16>0,N16/B16,0) -> 0 | P16: 16312 | Q16: =(P16-P15)*1000 -> 2000 | R16: =N16-Q16 -> 7105 | S16: 9606 | T16: =S16-S15 -> 7 | U16: 309536 | V16: =U16-U15 -> 1560 | W16: =W15 -> 32049 | X16: =W16-W15 -> 0 | Y16: =Y15 -> 673052 | Z16: =Y16-Y15 -> 0 | AA16: =AA15 -> 35556 | AB16: =AA16-AA15 -> 0 | AC16: =AC15 -> 888280 | AD16: =AC16-AC15 -> 0 | AE16: =AB16+X16+T16 -> 7 | AF16: =V16+Z16+AD16 -> 1560 | AG16: =IF(AE16>0,AF16/AE16,0) -> 222.85714 | AI16: =R16-'EDl log'!B14 -> -387314
A17: ='General information '!F20 -> 0 | B17: =SUM(230*A17) -> 0 | C17: 44089 | D17: 32234230 | E17: =D17-D16 -> 5616 | F17: 3859581 | G17: =F17-F16 -> 919 | H17: 17657838 | I17: =H17-H16 -> 976 | J17: 28707206 | K17: =J17-J16 -> 932 | L17: 23634214 | M17: =L17-L16 -> 2012 | N17: =M17+K17+I17+G17+E17 -> 10455 | O17: =IF(B17>0,N17/B17,0) -> 0 | P17: 16315 | Q17: =(P17-P16)*1000 -> 3000 | R17: =N17-Q17 -> 7455 | S17: 9606 | T17: =S17-S16 -> 0 | U17: 309536 | V17: =U17-U16 -> 0 | W17: =W16 -> 32049 | X17: =W17-W16 -> 0 | Y17: =Y16 -> 673052 | Z17: =Y17-Y16 -> 0 | AA17: 35566 | AB17: =AA17-AA16 -> 10 | AC17: 890520 | AD17: =AC17-AC16 -> 2240 | AE17: =AB17+X17+T17 -> 10 | AF17: =V17+Z17+AD17 -> 2240 | AG17: =IF(AE17>0,AF17/AE17,0) -> 224 | AI17: =R17-'EDl log'!B15 -> -391299
A18: ='General information '!F21 -> 0 | B18: =SUM(230*A18) -> 0 | C18: 44090 | D18: 32240010 | E18: =D18-D17 -> 5780 | F18: 3860356 | G18: =F18-F17 -> 775 | H18: 17658660 | I18: =H18-H17 -> 822 | J18: 28708154 | K18: =J18-J17 -> 948 | L18: 23636052 | M18: =L18-L17 -> 1838 | N18: =M18+K18+I18+G18+E18 -> 10163 | O18: =IF(B18>0,N18/B18,0) -> 0 | P18: 16318 | Q18: =(P18-P17)*1000 -> 3000 | R18: =N18-Q18 -> 7163 | S18: =S17 -> 9606 | T18: =S18-S17 -> 0 | U18: =U17 -> 309536 | V18: =U18-U17 -> 0 | W18: =W17 -> 32049 | X18: =W18-W17 -> 0 | Y18: =Y17 -> 673052 | Z18: =Y18-Y17 -> 0 | AA18: 35581 | AB18: =AA18-AA17 -> 15 | AC18: 893493 | AD18: =AC18-AC17 -> 2973 | AE18: =AB18+X18+T18 -> 15 | AF18: =V18+Z18+AD18 -> 2973 | AG18: =IF(AE18>0,AF18/AE18,0) -> 198.2 | AI18: =R18-'EDl log'!B16 -> -395093
A19: ='General information '!F22 -> 0 | B19: =SUM(230*A19) -> 0 | C19: 44091 | D19: 32244176 | E19: =D19-D18 -> 4166 | F19: 3861274 | G19: =F19-F18 -> 918 | H19: 17659610 | I19: =H19-H18 -> 950 | J19: 28708896 | K19: =J19-J18 -> 742 | L19: 23638502 | M19: =L19-L18 -> 2450 | N19: =M19+K19+I19+G19+E19 -> 9226 | O19: =IF(B19>0,N19/B19,0) -> 0 | P19: 16319 | Q19: =(P19-P18)*1000 -> 1000 | R19: =N19-Q19 -> 8226 | S19: =S18 -> 9606 | T19: =S19-S18 -> 0 | U19: =U18 -> 309536 | V19: =U19-U18 -> 0 | W19: =W18 -> 32049 | X19: =W19-W18 -> 0 | Y19: =Y18 -> 673052 | Z19: =Y19-Y18 -> 0 | AA19: 35586 | AB19: =AA19-AA18 -> 5 | AC19: 894782 | AD19: =AC19-AC18 -> 1289 | AE19: =AB19+X19+T19 -> 5 | AF19: =V19+Z19+AD19 -> 1289 | AG19: =IF(AE19>0,AF19/AE19,0) -> 257.8 | AI19: =R19-'EDl log'!B17 -> -397757
A20: ='General information '!F23 -> 0 | B20: =SUM(230*A20) -> 0 | C20: 44092 | D20: 32247138 | E20: =D20-D19 -> 2962 | F20: 3862133 | G20: =F20-F19 -> 859 | H20: 17660518 | I20: =H20-H19 -> 908 | J20: 28709748 | K20: =J20-J19 -> 852 | L20: 23642594 | M20: =L20-L19 -> 4092 | N20: =M20+K20+I20+G20+E20 -> 9673 | O20: =IF(B20>0,N20/B20,0) -> 0 | P20: 16321 | Q20: =(P20-P19)*1000 -> 2000 | R20: =N20-Q20 -> 7673 | S20: 9617 | T20: =S20-S19 -> 11 | U20: 312110 | V20: =U20-U19 -> 2574 | W20: =W19 -> 32049 | X20: =W20-W19 -> 0 | Y20: =Y19 -> 673052 | Z20: =Y20-Y19 -> 0 | AA20: =AA19 -> 35586 | AB20: =AA20-AA19 -> 0 | AC20: =AC19 -> 894782 | AD20: =AC20-AC19 -> 0 | AE20: =AB20+X20+T20 -> 11 | AF20: =V20+Z20+AD20 -> 2574 | AG20: =IF(AE20>0,AF20/AE20,0) -> 234 | AI20: =R20-'EDl log'!B18 -> -402044
A21: ='General information '!F24 -> 0 | B21: =SUM(230*A21) -> 0 | C21: 44093 | D21: 32250282 | E21: =D21-D20 -> 3144 | F21: 3862894 | G21: =F21-F20 -> 761 | H21: 17661350 | I21: =H21-H20 -> 832 | J21: 28710350 | K21: =J21-J20 -> 602 | L21: 23645122 | M21: =L21-L20 -> 2528 | N21: =M21+K21+I21+G21+E21 -> 7867 | O21: =IF(B21>0,N21/B21,0) -> 0 | P21: 16323 | Q21: =(P21-P20)*1000 -> 2000 | R21: =N21-Q21 -> 5867 | S21: 9620 | T21: =S21-S20 -> 3 | U21: 312929 | V21: =U21-U20 -> 819 | W21: =W20 -> 32049 | X21: =W21-W20 -> 0 | Y21: =Y20 -> 673052 | Z21: =Y21-Y20 -> 0 | AA21: 35589 | AB21: =AA21-AA20 -> 3 | AC21: 895463 | AD21: =AC21-AC20 -> 681 | AE21: =AB21+X21+T21 -> 6 | AF21: =V21+Z21+AD21 -> 1500 | AG21: =IF(AE21>0,AF21/AE21,0) -> 250 | AI21: =R21-'EDl log'!B19 -> -407885
A22: ='General information '!F25 -> 0 | B22: =SUM(230*A22) -> 0 | C22: 44094 | D22: 32252830 | E22: =D22-D21 -> 2548 | F22: 3863701 | G22: =F22-F21 -> 807 | H22: 17662226 | I22: =H22-H21 -> 876 | J22: 28711104 | K22: =J22-J21 -> 754 | L22: 23649018 | M22: =L22-L21 -> 3896 | N22: =M22+K22+I22+G22+E22 -> 8881 | O22: =IF(B22>0,N22/B22,0) -> 0 | P22: 16325.495 | Q22: =(P22-P21)*1000 -> 2495 | R22: =N22-Q22 -> 6386 | S22: 9629 | T22: =S22-S21 -> 9 | U22: 314977 | V22: =U22-U21 -> 2048 | W22: =W21 -> 32049 | X22: =W22-W21 -> 0 | Y22: =Y21 -> 673052 | Z22: =Y22-Y21 -> 0 | AA22: 35589 | AB22: =AA22-AA21 -> 0 | AC22: 895463 | AD22: =AC22-AC21 -> 0 | AE22: =AB22+X22+T22 -> 9 | AF22: =V22+Z22+AD22 -> 2048 | AG22: =IF(AE22>0,AF22/AE22,0) -> 227.55556 | AI22: =R22-'EDl log'!B20 -> -411263
A23: ='General information '!F26 -> 0 | B23: =SUM(230*A23) -> 0 | C23: 44095 | D23: 32256638 | E23: =D23-D22 -> 3808 | F23: 3864507 | G23: =F23-F22 -> 806 | H23: 17663058 | I23: =H23-H22 -> 832 | J23: 28711894 | K23: =J23-J22 -> 790 | L23: 23652040 | M23: =L23-L22 -> 3022 | N23: =M23+K23+I23+G23+E23 -> 9258 | O23: =IF(B23>0,N23/B23,0) -> 0 | P23: 16327 | Q23: =(P23-P22)*1000 -> 1505 | R23: =N23-Q23 -> 7753 | S23: 9634 | T23: =S23-S22 -> 5 | U23: 316092 | V23: =U23-U22 -> 1115 | W23: =W22 -> 32049 | X23: =W23-W22 -> 0 | Y23: =Y22 -> 673052 | Z23: =Y23-Y22 -> 0 | AA23: 35594 | AB23: =AA23-AA22 -> 5 | AC23: 896638 | AD23: =AC23-AC22 -> 1175 | AE23: =AB23+X23+T23 -> 10 | AF23: =V23+Z23+AD23 -> 2290 | AG23: =IF(AE23>0,AF23/AE23,0) -> 229 | AI23: =R23-'EDl log'!B21 -> -414151
A24: ='General information '!F27 -> 0 | B24: =SUM(230*A24) -> 0 | C24: 44096 | D24: 32260010 | E24: =D24-D23 -> 3372 | F24: 3865337 | G24: =F24-F23 -> 830 | H24: 17663930 | I24: =H24-H23 -> 872 | J24: 28712882 | K24: =J24-J23 -> 988 | L24: 23656666 | M24: =L24-L23 -> 4626 | N24: =M24+K24+I24+G24+E24 -> 10688 | O24: =IF(B24>0,N24/B24,0) -> 0 | P24: 16331 | Q24: =(P24-P23)*1000 -> 4000 | R24: =N24-Q24 -> 6688 | S24: 9645 | T24: =S24-S23 -> 11 | U24: 318534 | V24: =U24-U23 -> 2442 | W24: =W23 -> 32049 | X24: =W24-W23 -> 0 | Y24: =Y23 -> 673052 | Z24: =Y24-Y23 -> 0 | AA24: 35594 | AB24: =AA24-AA23 -> 0 | AC24: 896638 | AD24: =AC24-AC23 -> 0 | AE24: =AB24+X24+T24 -> 11 | AF24: =V24+Z24+AD24 -> 2442 | AG24: =IF(AE24>0,AF24/AE24,0) -> 222 | AI24: =R24-'EDl log'!B22 -> -418321
A25: ='General information '!F28 -> 0 | B25: =SUM(230*A25) -> 0 | C25: 44097 | D25: 32265002 | E25: =D25-D24 -> 4992 | F25: 3866176 | G25: =F25-F24 -> 839 | H25: 17664806 | I25: =H25-H24 -> 876 | J25: 28713734 | K25: =J25-J24 -> 852 | L25: 23659450 | M25: =L25-L24 -> 2784 | N25: =M25+K25+I25+G25+E25 -> 10343 | O25: =IF(B25>0,N25/B25,0) -> 0 | P25: 16333 | Q25: =(P25-P24)*1000 -> 2000 | R25: =N25-Q25 -> 8343 | S25: 9647 | T25: =S25-S24 -> 2 | U25: 319062 | V25: =U25-U24 -> 528 | W25: =W24 -> 32049 | X25: =W25-W24 -> 0 | Y25: =Y24 -> 673052 | Z25: =Y25-Y24 -> 0 | AA25: 35603 | AB25: =AA25-AA24 -> 9 | AC25: 898412 | AD25: =AC25-AC24 -> 1774 | AE25: =AB25+X25+T25 -> 11 | AF25: =V25+Z25+AD25 -> 2302 | AG25: =IF(AE25>0,AF25/AE25,0) -> 209.27273 | AI25: =R25-'EDl log'!B23 -> -420247
A26: ='General information '!F29 -> 0 | B26: =SUM(230*A26) -> 0 | C26: 44098 | D26: 32269102 | E26: =D26-D25 -> 4100 | F26: 3867053 | G26: =F26-F25 -> 877 | H26: 17665670 | I26: =H26-H25 -> 864 | J26: 28714568 | K26: =J26-J25 -> 834 | L26: 23663002 | M26: =L26-L25 -> 3552 | N26: =M26+K26+I26+G26+E26 -> 10227 | O26: =IF(B26>0,N26/B26,0) -> 0 | P26: 16335 | Q26: =(P26-P25)*1000 -> 2000 | R26: =N26-Q26 -> 8227 | S26: 9653 | T26: =S26-S25 -> 6 | U26: 320308 | V26: =U26-U25 -> 1246 | W26: =W25 -> 32049 | X26: =W26-W25 -> 0 | Y26: =Y25 -> 673052 | Z26: =Y26-Y25 -> 0 | AA26: 35607 | AB26: =AA26-AA25 -> 4 | AC26: 899487 | AD26: =AC26-AC25 -> 1075 | AE26: =AB26+X26+T26 -> 10 | AF26: =V26+Z26+AD26 -> 2321 | AG26: =IF(AE26>0,AF26/AE26,0) -> 232.1 | AI26: =R26-'EDl log'!B24 -> -424041
A27: ='General information '!F30 -> 0 | B27: =SUM(230*A27) -> 0 | C27: 44099 | D27: 32271638 | E27: =D27-D26 -> 2536 | F27: 3867913 | G27: =F27-F26 -> 860 | H27: 17666516 | I27: =H27-H26 -> 846 | J27: 28715200 | K27: =J27-J26 -> 632 | L27: 23666314 | M27: =L27-L26 -> 3312 | N27: =M27+K27+I27+G27+E27 -> 8186 | O27: =IF(B27>0,N27/B27,0) -> 0 | P27: 16336 | Q27: =(P27-P26)*1000 -> 1000 | R27: =N27-Q27 -> 7186 | S27: 9659 | T27: =S27-S26 -> 6 | U27: 321733 | V27: =U27-U26 -> 1425 | W27: =W26 -> 32049 | X27: =W27-W26 -> 0 | Y27: =Y26 -> 673052 | Z27: =Y27-Y26 -> 0 | AA27: =AA26 -> 35607 | AB27: =AA27-AA26 -> 0 | AC27: =AC26 -> 899487 | AD27: =AC27-AC26 -> 0 | AE27: =AB27+X27+T27 -> 6 | AF27: =V27+Z27+AD27 -> 1425 | AG27: =IF(AE27>0,AF27/AE27,0) -> 237.5 | AI27: =R27-'EDl log'!B25 -> -428540
A28: ='General information '!F31 -> 0 | B28: =SUM(230*A28) -> 0 | C28: 44100 | D28: 32273914 | E28: =D28-D27 -> 2276 | F28: 3868769 | G28: =F28-F27 -> 856 | H28: 17667358 | I28: =H28-H27 -> 842 | J28: 28715794 | K28: =J28-J27 -> 594 | L28: 23669310 | M28: =L28-L27 -> 2996 | N28: =M28+K28+I28+G28+E28 -> 7564 | O28: =IF(B28>0,N28/B28,0) -> 0 | P28: 16338 | Q28: =(P28-P27)*1000 -> 2000 | R28: =N28-Q28 -> 5564 | S28: 9665 | T28: =S28-S27 -> 6 | U28: 322890 | V28: =U28-U27 -> 1157 | W28: =W27 -> 32049 | X28: =W28-W27 -> 0 | Y28: =Y27 -> 673052 | Z28: =Y28-Y27 -> 0 | AA28: =AA27 -> 35607 | AB28: =AA28-AA27 -> 0 | AC28: =AC27 -> 899487 | AD28: =AC28-AC27 -> 0 | AE28: =AB28+X28+T28 -> 6 | AF28: =V28+Z28+AD28 -> 1157 | AG28: =IF(AE28>0,AF28/AE28,0) -> 192.83333 | AI28: =R28-'EDl log'!B26 -> -434771
A29: ='General information '!F32 -> 0 | B29: =SUM(230*A29) -> 0 | C29: 44101 | D29: 32277052 | E29: =D29-D28 -> 3138 | F29: 3869563 | G29: =F29-F28 -> 794 | H29: 17668258 | I29: =H29-H28 -> 900 | J29: 28716674 | K29: =J29-J28 -> 880 | L29: 23673590 | M29: =L29-L28 -> 4280 | N29: =M29+K29+I29+G29+E29 -> 9992 | O29: =IF(B29>0,N29/B29,0) -> 0 | P29: 16338.9 | Q29: =(P29-P28)*1000 -> 900 | R29: =N29-Q29 -> 9092 | S29: 9673 | T29: =S29-S28 -> 8 | U29: 325151 | V29: =U29-U28 -> 2261 | W29: =W28 -> 32049 | X29: =W29-W28 -> 0 | Y29: =Y28 -> 673052 | Z29: =Y29-Y28 -> 0 | AA29: 35607 | AB29: =AA29-AA28 -> 0 | AC29: 899488 | AD29: =AC29-AC28 -> 1 | AE29: =AB29+X29+T29 -> 8 | AF29: =V29+Z29+AD29 -> 2262 | AG29: =IF(AE29>0,AF29/AE29,0) -> 282.75 | AI29: =R29-'EDl log'!B27 -> -435706
A30: ='General information '!F33 -> 0 | B30: =SUM(230*A30) -> 0 | C30: 44102 | D30: 32280280 | E30: =D30-D29 -> 3228 | F30: 3870362 | G30: =F30-F29 -> 799 | H30: 17669074 | I30: =H30-H29 -> 816 | J30: 28717602 | K30: =J30-J29 -> 928 | L30: 23677902 | M30: =L30-L29 -> 4312 | N30: =M30+K30+I30+G30+E30 -> 10083 | O30: =IF(B30>0,N30/B30,0) -> 0 | P30: 16340 | Q30: =(P30-P29)*1000 -> 1100 | R30: =N30-Q30 -> 8983 | S30: 9684 | T30: =S30-S29 -> 11 | U30: 327795 | V30: =U30-U29 -> 2644 | W30: =W29 -> 32049 | X30: =W30-W29 -> 0 | Y30: =Y29 -> 673052 | Z30: =Y30-Y29 -> 0 | AA30: 35607 | AB30: =AA30-AA29 -> 0 | AC30: 899488 | AD30: =AC30-AC29 -> 0 | AE30: =AB30+X30+T30 -> 11 | AF30: =V30+Z30+AD30 -> 2644 | AG30: =IF(AE30>0,AF30/AE30,0) -> 240.36364 | AI30: =R30-'EDl log'!B28 -> -439366
A31: ='General information '!F34 -> 0 | B31: =SUM(230*A31) -> 0 | C31: 44103 | D31: 32283632 | E31: =D31-D30 -> 3352 | F31: 3871226 | G31: =F31-F30 -> 864 | H31: 17669934 | I31: =H31-H30 -> 860 | J31: 28718582 | K31: =J31-J30 -> 980 | L31: 23683074 | M31: =L31-L30 -> 5172 | N31: =M31+K31+I31+G31+E31 -> 11228 | O31: =IF(B31>0,N31/B31,0) -> 0 | P31: 16342 | Q31: =(P31-P30)*1000 -> 2000 | R31: =N31-Q31 -> 9228 | S31: 9695 | T31: =S31-S30 -> 11 | U31: 330743 | V31: =U31-U30 -> 2948 | W31: =W30 -> 32049 | X31: =W31-W30 -> 0 | Y31: =Y30 -> 673052 | Z31: =Y31-Y30 -> 0 | AA31: =AA30 -> 35607 | AB31: =AA31-AA30 -> 0 | AC31: =AC30 -> 899488 | AD31: =AC31-AC30 -> 0 | AE31: =AB31+X31+T31 -> 11 | AF31: =V31+Z31+AD31 -> 2948 | AG31: =IF(AE31>0,AF31/AE31,0) -> 268 | AI31: =R31-'EDl log'!B29 -> -442364
A32: ='General information '!F35 -> 0 | B32: =SUM(230*A32) -> 0 | C32: 44104 | D32: 32287200 | E32: =D32-D31 -> 3568 | F32: 3872020 | G32: =F32-F31 -> 794 | H32: 17670874 | I32: =H32-H31 -> 940 | J32: 28719638 | K32: =J32-J31 -> 1056 | L32: 23688570 | M32: =L32-L31 -> 5496 | N32: =M32+K32+I32+G32+E32 -> 11854 | O32: =IF(B32>0,N32/B32,0) -> 0 | P32: 16346 | Q32: =(P32-P31)*1000 -> 4000 | R32: =N32-Q32 -> 7854 | S32: 9708 | T32: =S32-S31 -> 13 | U32: 333763 | V32: =U32-U31 -> 3020 | W32: =W31 -> 32049 | X32: =W32-W31 -> 0 | Y32: =Y31 -> 673052 | Z32: =Y32-Y31 -> 0 | AA32: =AA31 -> 35607 | AB32: =AA32-AA31 -> 0 | AC32: =AC31 -> 899488 | AD32: =AC32-AC31 -> 0 | AE32: =AB32+X32+T32 -> 13 | AF32: =V32+Z32+AD32 -> 3020 | AG32: =IF(AE32>0,AF32/AE32,0) -> 232.30769 | AI32: =R32-'EDl log'!B30 -> -448502

Sheet B5
F1: Boiler A | J1: =J35 -> 1 | K1: Boiler B | P1: Boiler C | V1: Boiler | X1: SteamA | AC1: SteamB | AH1: Steam | AI1: Boiler & steam | AL1: Total Boiler Runing H | AM1: Total Steam Runing H | AN1: GAS1 % | AO1: GAS1/L | AP1: GAS2% | AQ1: Gas2/L | AR1: GAS3% | AS1: GAS3/L | AU1: Gas Cons | AV1: Delivery | AW1: Cost/L
B2: Level Tank Gen | C2: Level tank Boiler | D2: Daily Cons Bo. | E2: Boiler litter | F2: Boiler A | G2: Run Hr a | H2: Boiler A fuel | I2: Daily consumption | J2: AVG | K2: index Run H | L2: Run Hrb | M2: Boiler B Fuel | O2: Daily consumption | P2: Boiler C | S2: Run C | U2: Total RH | V2: Total Fuel | X2: SteamA | Y2: Run SA | Z2: Steam A Conter | AA2: Liters | AC2: SteamB | AD2: Run SteamB | AE2: Steam B Conter | AF2: SB Litters | AG2: Avg | AH2: Total Fuel | AI2: Total Fuel
S3: 0
A4: =ELEC!C2 -> 44074 | B4: =[1]B5!B35 -> 239 | C4: =[1]B5!C35 -> 244 | D4: =[1]B5!D35 -> 4 | E4: =[1]B5!E35 -> 33.52 | F4: =[1]B5!F35 -> 1648 | G4: =[1]B5!G35 -> 0 | H4: =[1]B5!H35 -> 357868 | I4: =[1]B5!I35 -> 0 | ... AX4: =[1]B5!AX35 -> 0.8
A5: =ELEC!C3 -> 44075 | B5: 236 | C5: 242 | D5: =C4-C5 -> 2 | E5: =D5*8.38 -> 16.76 | F5: 1648 | G5: =F5-F4 -> 0 | H5: =H4 -> 357868 | I5: =SUM(H5-H4) -> 0 | J5: 1 | K5: =K4 -> 2110 | L5: =K5-K4 -> 0 | M5: =M4 -> 154820 | N5: =M5-M4 -> 0 | O5: =O4 -> 211.875 | P5: 1839 | Q5: 156094 | R5: =Q5-Q4 -> 155 | S5: =SUM(P5-P4) -> 2 | T5: =SUM(S5*$T$2) -> 0 | U5: =SUM(G5+L5+S5) -> 2 | V5: =R5+N5+I5:I5 -> 155 | W5: =SUM(V5/U5) -> 77.5 | X5: =X4 -> 2435 | Y5: =X5-X4 -> 0 | Z5: =Z4 -> 136853 | AA5: =Z5-Z4 -> 0 | AB5: =SUM(Y5*$AB$2) -> 0 | AC5: =AC4 -> 1933 | AD5: =AC5-AC4 -> 0 | AE5: =AE4 -> 365210.2 | AF5: =AE5-AE4 -> 0 | AG5: =IF(AD5>0,AF5/AD5,0) -> 0 | AH5: =AF5+AA5 -> 0 | AI5: =SUM(AH5+V5) -> 155 | AJ5: =-tanks!AW6 -> 155 | AK5: =SUM(AJ5-AI5) -> 0 | AL5: =S5+L5+G5 -> 2 | AM5: =Y5+AD5 -> 0 | AN5: =AN4 -> 63 | AO5: =(AN5/100)*3000 -> 1890 | AP5: =AP4 -> 69 | AQ5: =(AP5/100)*3000 -> 2070 | AR5: =AR4 -> 69 | AS5: =(AR5/100)*3000 -> 2070 | AT5: =SUM(AO5+AQ5+AS5) -> 6030 | AU5: =AT4-AT5+AV5 -> 0 | AX5: =IF(AV5>0,AW5,AX4) -> 0.8
A6: =ELEC!C4 -> 44076 | B6: 231 | C6: 237 | D6: =C5-C6 -> 5 | E6: =D6*8.38 -> 41.9 | F6: =F5 -> 1648 | G6: =F6-F5 -> 0 | H6: =H5 -> 357868 | I6: =SUM(H6-H5) -> 0 | J6: =IF(G6>0,I6/G6,0) -> 0 | K6: =K5 -> 2110 | L6: =K6-K5 -> 0 | M6: =M5 -> 154820 | N6: =M6-M5 -> 0 | O6: =O5 -> 211.875 | P6: =P5 -> 1839 | Q6: =Q5 -> 156094 | R6: =Q6-Q5 -> 0 | S6: =SUM(P6-P5) -> 0 | T6: =SUM(S6*$T$2) -> 0 | U6: =SUM(G6+L6+S6) -> 0 | V6: =R6+N6+I6:I6 -> 0 | W6: =SUM(V6/U6) -> #DIV/0! | X6: =X5 -> 2435 | Y6: =X6-X5 -> 0 | Z6: =Z5 -> 136853 | AA6: =Z6-Z5 -> 0 | AB6: =SUM(Y6*$AB$2) -> 0 | AC6: =AC5 -> 1933 | AD6: =AC6-AC5 -> 0 | AE6: =AE5 -> 365210.2 | AF6: =AE6-AE5 -> 0 | AG6: =IF(AD6>0,AF6/AD6,0) -> 0 | AH6: =AF6+AA6 -> 0 | AI6: =SUM(AH6+V6) -> 0 | AJ6: =-tanks!AW7 -> 0 | AK6: =SUM(AJ6-AI6) -> 0 | AL6: =S6+L6+G6 -> 0 | AM6: =Y6+AD6 -> 0 | AN6: =AN5 -> 63 | AO6: =(AN6/100)*3000 -> 1890 | AP6: =AP5 -> 69 | AQ6: =(AP6/100)*3000 -> 2070 | AR6: =AR5 -> 69 | AS6: =(AR6/100)*3000 -> 2070 | AT6: =SUM(AO6+AQ6+AS6) -> 6030 | AU6: =AT5-AT6+AV6 -> 0 | AX6: =IF(AV6>0,AW6,AX5) -> 0.8
A7: =ELEC!C5 -> 44077 | B7: 225 | C7: 231 | D7: =C6-C7 -> 6 | E7: =D7*8.38 -> 50.28 | F7: =F6 -> 1648 | G7: =F7-F6 -> 0 | H7: =H6 -> 357868 | I7: =SUM(H7-H6) -> 0 | J7: =IF(G7>0,I7/G7,0) -> 0 | K7: =K6 -> 2110 | L7: =K7-K6 -> 0 | M7: =M6 -> 154820 | N7: =M7-M6 -> 0 | O7: =O6 -> 211.875 | P7: =P6 -> 1839 | Q7: =Q6 -> 156094 | R7: =Q7-Q6 -> 0 | S7: =SUM(P7-P6) -> 0 | T7: =SUM(S7*$T$2) -> 0 | U7: =SUM(G7+L7+S7) -> 0 | V7: =R7+N7+I7:I7 -> 0 | W7: =SUM(V7/U7) -> #DIV/0! | X7: 2443 | Y7: =X7-X6 -> 8 | Z7: 137203 | AA7: =Z7-Z6 -> 350 | AB7: =SUM(Y7*$AB$2) -> 0 | AC7: =AC6 -> 1933 | AD7: =AC7-AC6 -> 0 | AE7: =AE6 -> 365210.2 | AF7: =AE7-AE6 -> 0 | AG7: =IF(AD7>0,AF7/AD7,0) -> 0 | AH7: =AF7+AA7 -> 350 | AI7: =SUM(AH7+V7) -> 350 | AJ7: =-tanks!AW8 -> 350 | AK7: =SUM(AJ7-AI7) -> 0 | AL7: =S7+L7+G7 -> 0 | AM7: =Y7+AD7 -> 8 | AN7: =AN6 -> 63 | AO7: =(AN7/100)*3000 -> 1890 | AP7: =AP6 -> 69 | AQ7: =(AP7/100)*3000 -> 2070 | AR7: =AR6 -> 69 | AS7: =(AR7/100)*3000 -> 2070 | AT7: =SUM(AO7+AQ7+AS7) -> 6030 | AU7: =AT6-AT7+AV7 -> 0 | AX7: =IF(AV7>0,AW7,AX6) -> 0.8
A8: =ELEC!C6 -> 44078 | B8: 218.4 | C8: 224.3 | D8: =C7-C8 -> 6.7 | E8: =D8*8.38 -> 56.146 | F8: =F7 -> 1648 | G8: =F8-F7 -> 0 | H8: =H7 -> 357868 | I8: =SUM(H8-H7) -> 0 | J8: =IF(G8>0,I8/G8,0) -> 0 | K8: =K7 -> 2110 | L8: =K8-K7 -> 0 | M8: =M7 -> 154820 | N8: =M8-M7 -> 0 | O8: =O7 -> 211.875 | P8: =P7 -> 1839 | Q8: =Q7 -> 156094 | R8: =Q8-Q7 -> 0 | S8: =SUM(P8-P7) -> 0 | T8: =SUM(S8*$T$2) -> 0 | U8: =SUM(G8+L8+S8) -> 0 | V8: =R8+N8+I8:I8 -> 0 | W8: =SUM(V8/U8) -> #DIV/0! | X8: 2448 | Y8: =X8-X7 -> 5 | Z8: 137506 | AA8: =Z8-Z7 -> 303 | AB8: =SUM(Y8*$AB$2) -> 0 | AC8: =AC7 -> 1933 | AD8: =AC8-AC7 -> 0 | AE8: =AE7 -> 365210.2 | AF8: =AE8-AE7 -> 0 | AG8: =IF(AD8>0,AF8/AD8,0) -> 0 | AH8: =AF8+AA8 -> 303 | AI8: =SUM(AH8+V8) -> 303 | AJ8: =-tanks!AW9 -> 303 | AK8: =SUM(AJ8-AI8) -> 0 | AL8: =S8+L8+G8 -> 0 | AM8: =Y8+AD8 -> 5 | AN8: 63 | AO8: =(AN8/100)*3000 -> 1890 | AP8: 69 | AQ8: =(AP8/100)*3000 -> 2070 | AR8: =AR7 -> 69 | AS8: =(AR8/100)*3000 -> 2070 | AT8: =SUM(AO8+AQ8+AS8) -> 6030 | AU8: =AT7-AT8+AV8 -> 0 | AX8: =IF(AV8>0,AW8,AX7) -> 0.8
A9: =ELEC!C7 -> 44079 | B9: 216 | C9: 222 | D9: =C8-C9 -> 2.3 | E9: =D9*8.38 -> 19.274 | F9: =F8 -> 1648 | G9: =F9-F8 -> 0 | H9: =H8 -> 357868 | I9: =SUM(H9-H8) -> 0 | J9: =IF(G9>0,I9/G9,0) -> 0 | K9: =K8 -> 2110 | L9: =K9-K8 -> 0 | M9: =M8 -> 154820 | N9: =M9-M8 -> 0 | O9: =O8 -> 211.875 | P9: =P8 -> 1839 | Q9: =Q8 -> 156094 | R9: =Q9-Q8 -> 0 | S9: =SUM(P9-P8) -> 0 | T9: =SUM(S9*$T$2) -> 0 | U9: =SUM(G9+L9+S9) -> 0 | V9: =R9+N9+I9:I9 -> 0 | W9: =SUM(V9/U9) -> #DIV/0! | X9: =X8 -> 2448 | Y9: =X9-X8 -> 0 | Z9: =Z8 -> 137506 | AA9: =Z9-Z8 -> 0 | AB9: =SUM(Y9*$AB$2) -> 0 | AC9: =AC8 -> 1933 | AD9: =AC9-AC8 -> 0 | AE9: =AE8 -> 365210.2 | AF9: =AE9-AE8 -> 0 | AG9: =IF(AD9>0,AF9/AD9,0) -> 0 | AH9: =AF9+AA9 -> 0 | AI9: =SUM(AH9+V9) -> 0 | AJ9: =-tanks!AW10 -> 0 | AK9: =SUM(AJ9-AI9) -> 0 | AL9: =S9+L9+G9 -> 0 | AM9: =Y9+AD9 -> 0 | AN9: =AN8 -> 63 | AO9: =(AN9/100)*3000 -> 1890 | AP9: =AP8 -> 69 | AQ9: =(AP9/100)*3000 -> 2070 | AR9: =AR8 -> 69 | AS9: =(AR9/100)*3000 -> 2070 | AT9: =SUM(AO9+AQ9+AS9) -> 6030 | AU9: =AT8-AT9+AV9 -> 0 | AX9: =IF(AV9>0,AW9,AX8) -> 0.8
A10: =ELEC!C8 -> 44080 | B10: 211 | C10: 218 | D10: =C9-C10 -> 4 | E10: =D10*8.38 -> 33.52 | F10: =F9 -> 1648 | G10: =F10-F9 -> 0 | H10: =H9 -> 357868 | I10: =SUM(H10-H9) -> 0 | J10: =IF(G10>0,I10/G10,0) -> 0 | K10: =K9 -> 2110 | L10: =K10-K9 -> 0 | M10: =M9 -> 154820 | N10: =M10-M9 -> 0 | O10: =O9 -> 211.875 | P10: =P9 -> 1839 | Q10: =Q9 -> 156094 | R10: =Q10-Q9 -> 0 | S10: =SUM(P10-P9) -> 0 | T10: =SUM(S10*$T$2) -> 0 | U10: =SUM(G10+L10+S10) -> 0 | V10: =R10+N10+I10:I10 -> 0 | W10: =SUM(V10/U10) -> #DIV/0! | X10: =X9 -> 2448 | Y10: =X10-X9 -> 0 | Z10: =Z9 -> 137506 | AA10: =Z10-Z9 -> 0 | AB10: =SUM(Y10*$AB$2) -> 0 | AC10: =AC9 -> 1933 | AD10: =AC10-AC9 -> 0 | AE10: =AE9 -> 365210.2 | AF10: =AE10-AE9 -> 0 | AG10: =IF(AD10>0,AF10/AD10,0) -> 0 | AH10: =AF10+AA10 -> 0 | AI10: =SUM(AH10+V10) -> 0 | AJ10: =-tanks!AW11 -> 0 | AK10: =SUM(AJ10-AI10) -> 0 | AL10: =S10+L10+G10 -> 0 | AM10: =Y10+AD10 -> 0 | AN10: =AN9 -> 63 | AO10: =(AN10/100)*3000 -> 1890 | AP10: =AP9 -> 69 | AQ10: =(AP10/100)*3000 -> 2070 | AR10: =AR9 -> 69 | AS10: =(AR10/100)*3000 -> 2070 | AT10: =SUM(AO10+AQ10+AS10) -> 6030 | AU10: =AT9-AT10+AV10 -> 0 | AX10: =IF(AV10>0,AW10,AX9) -> 0.8
A11: =ELEC!C9 -> 44081 | B11: 207 | C11: 213 | D11: =C10-C11 -> 5 | E11: =D11*8.38 -> 41.9 | F11: =F10 -> 1648 | G11: =F11-F10 -> 0 | H11: =H10 -> 357868 | I11: =SUM(H11-H10) -> 0 | J11: =IF(G11>0,I11/G11,0) -> 0 | K11: =K10 -> 2110 | L11: =K11-K10 -> 0 | M11: =M10 -> 154820 | N11: =M11-M10 -> 0 | O11: =O10 -> 211.875 | P11: =P10 -> 1839 | Q11: =Q10 -> 156094 | R11: =Q11-Q10 -> 0 | S11: =SUM(P11-P10) -> 0 | T11: =SUM(S11*$T$2) -> 0 | U11: =SUM(G11+L11+S11) -> 0 | V11: =R11+N11+I11:I11 -> 0 | W11: =SUM(V11/U11) -> #DIV/0! | X11: =X10 -> 2448 | Y11: =X11-X10 -> 0 | Z11: =Z10 -> 137506 | AA11: =Z11-Z10 -> 0 | AB11: =SUM(Y11*$AB$2) -> 0 | AC11: =AC10 -> 1933 | AD11: =AC11-AC10 -> 0 | AE11: =AE10 -> 365210.2 | AF11: =AE11-AE10 -> 0 | AG11: =IF(AD11>0,AF11/AD11,0) -> 0 | AH11: =AF11+AA11 -> 0 | AI11: =SUM(AH11+V11) -> 0 | AJ11: =-tanks!AW12 -> 0 | AK11: =SUM(AJ11-AI11) -> 0 | AL11: =S11+L11+G11 -> 0 | AM11: =Y11+AD11 -> 0 | AN11: =AN10 -> 63 | AO11: =(AN11/100)*3000 -> 1890 | AP11: =AP10 -> 69 | AQ11: =(AP11/100)*3000 -> 2070 | AR11: =AR10 -> 69 | AS11: =(AR11/100)*3000 -> 2070 | AT11: =SUM(AO11+AQ11+AS11) -> 6030 | AU11: =AT10-AT11+AV11 -> 0 | AX11: =IF(AV11>0,AW11,AX10) -> 0.8
A12: =ELEC!C10 -> 44082 | B12: 197.2 | C12: 204 | D12: =C11-C12 -> 9 | E12: =D12*8.38 -> 75.42 | F12: 1648 | G12: =F12-F11 -> 0 | H12: =H11 -> 357868 | I12: =SUM(H12-H11) -> 0 | J12: =IF(G12>0,I12/G12,0) -> 0 | K12: =K11 -> 2110 | L12: =K12-K11 -> 0 | M12: =M11 -> 154820 | N12: =M12-M11 -> 0 | O12: =O11 -> 211.875 | P12: =P11 -> 1839 | Q12: =Q11 -> 156094 | R12: =Q12-Q11 -> 0 | S12: =SUM(P12-P11) -> 0 | T12: =SUM(S12*$T$2) -> 0 | U12: =SUM(G12+L12+S12) -> 0 | V12: =R12+N12+I12:I12 -> 0 | W12: =SUM(V12/U12) -> #DIV/0! | X12: 2448 | Y12: =X12-X11 -> 0 | Z12: =Z11 -> 137506 | AA12: =Z12-Z11 -> 0 | AB12: =SUM(Y12*$AB$2) -> 0 | AC12: =AC11 -> 1933 | AD12: =AC12-AC11 -> 0 | AE12: =AE11 -> 365210.2 | AF12: =AE12-AE11 -> 0 | AG12: =IF(AD12>0,AF12/AD12,0) -> 0 | AH12: =AF12+AA12 -> 0 | AI12: =SUM(AH12+V12) -> 0 | AJ12: =-tanks!AW13 -> 0 | AK12: =SUM(AJ12-AI12) -> 0 | AL12: =S12+L12+G12 -> 0 | AM12: =Y12+AD12 -> 0 | AN12: =AN11 -> 63 | AO12: =(AN12/100)*3000 -> 1890 | AP12: =AP11 -> 69 | AQ12: =(AP12/100)*3000 -> 2070 | AR12: =AR11 -> 69 | AS12: =(AR12/100)*3000 -> 2070 | AT12: =SUM(AO12+AQ12+AS12) -> 6030 | AU12: =AT11-AT12+AV12 -> 0 | AX12: =IF(AV12>0,AW12,AX11) -> 0.8
A13: =ELEC!C11 -> 44083 | B13: 194 | C13: 201 | D13: =C12-C13 -> 3 | E13: =D13*8.38 -> 25.14 | F13: =F12 -> 1648 | G13: =F13-F12 -> 0 | H13: =H12 -> 357868 | I13: =SUM(H13-H12) -> 0 | J13: =IF(G13>0,I13/G13,0) -> 0 | K13: =K12 -> 2110 | L13: =K13-K12 -> 0 | M13: =M12 -> 154820 | N13: =M13-M12 -> 0 | O13: =O12 -> 211.875 | P13: =P12 -> 1839 | Q13: =Q12 -> 156094 | R13: =Q13-Q12 -> 0 | S13: =SUM(P13-P12) -> 0 | T13: =SUM(S13*$T$2) -> 0 | U13: =SUM(G13+L13+S13) -> 0 | V13: =R13+N13+I13:I13 -> 0 | W13: =SUM(V13/U13) -> #DIV/0! | X13: =X12 -> 2448 | Y13: =X13-X12 -> 0 | Z13: =Z12 -> 137506 | AA13: =Z13-Z12 -> 0 | AB13: =SUM(Y13*$AB$2) -> 0 | AC13: =AC12 -> 1933 | AD13: =AC13-AC12 -> 0 | AE13: =AE12 -> 365210.2 | AF13: =AE13-AE12 -> 0 | AG13: =IF(AD13>0,AF13/AD13,0) -> 0 | AH13: =AF13+AA13 -> 0 | AI13: =SUM(AH13+V13) -> 0 | AJ13: =-tanks!AW14 -> 0 | AK13: =SUM(AJ13-AI13) -> 0 | AL13: =S13+L13+G13 -> 0 | AM13: =Y13+AD13 -> 0 | AN13: =AN12 -> 63 | AO13: =(AN13/100)*3000 -> 1890 | AP13: 57 | AQ13: =(AP13/100)*3000 -> 1710 | AR13: =AR12 -> 69 | AS13: =(AR13/100)*3000 -> 2070 | AT13: =SUM(AO13+AQ13+AS13) -> 5670 | AU13: =AT12-AT13+AV13 -> 360 | AX13: =IF(AV13>0,AW13,AX12) -> 0.8
A14: =ELEC!C12 -> 44084 | B14: 245 | C14: 250 | D14: =C13-C14 -> -49 | E14: =D14*8.38 -> -410.62 | F14: =F13 -> 1648 | G14: =F14-F13 -> 0 | H14: =H13 -> 357868 | I14: =SUM(H14-H13) -> 0 | J14: =IF(G14>0,I14/G14,0) -> 0 | K14: =K13 -> 2110 | L14: =K14-K13 -> 0 | M14: =M13 -> 154820 | N14: =M14-M13 -> 0 | O14: =O13 -> 211.875 | P14: =P13 -> 1839 | Q14: =Q13 -> 156094 | R14: =Q14-Q13 -> 0 | S14: =SUM(P14-P13) -> 0 | T14: =SUM(S14*$T$2) -> 0 | U14: =SUM(G14+L14+S14) -> 0 | V14: =R14+N14+I14:I14 -> 0 | W14: =SUM(V14/U14) -> #DIV/0! | X14: =X13 -> 2448 | Y14: =X14-X13 -> 0 | Z14: =Z13 -> 137506 | AA14: =Z14-Z13 -> 0 | AB14: =SUM(Y14*$AB$2) -> 0 | AC14: =AC13 -> 1933 | AD14: =AC14-AC13 -> 0 | AE14: =AE13 -> 365210.2 | AF14: =AE14-AE13 -> 0 | AG14: =IF(AD14>0,AF14/AD14,0) -> 0 | AH14: =AF14+AA14 -> 0 | AI14: =SUM(AH14+V14) -> 0 | AJ14: =-tanks!AW15 -> 0 | AK14: =SUM(AJ14-AI14) -> 0 | AL14: =S14+L14+G14 -> 0 | AM14: =Y14+AD14 -> 0 | AN14: =AN13 -> 63 | AO14: =(AN14/100)*3000 -> 1890 | AP14: =AP13 -> 57 | AQ14: =(AP14/100)*3000 -> 1710 | AR14: =AR13 -> 69 | AS14: =(AR14/100)*3000 -> 2070 | AT14: =SUM(AO14+AQ14+AS14) -> 5670 | AU14: =AT13-AT14+AV14 -> 0 | AX14: =IF(AV14>0,AW14,AX13) -> 0.8
A15: =ELEC!C13 -> 44085 | B15: 241 | C15: 247 | D15: =C14-C15 -> 3 | E15: =D15*8.38 -> 25.14 | F15: =F14 -> 1648 | G15: =F15-F14 -> 0 | H15: =H14 -> 357868 | I15: =SUM(H15-H14) -> 0 | J15: =IF(G15>0,I15/G15,0) -> 0 | K15: =K14 -> 2110 | L15: =K15-K14 -> 0 | M15: =M14 -> 154820 | N15: =M15-M14 -> 0 | O15: =O14 -> 211.875 | P15: =P14 -> 1839 | Q15: =Q14 -> 156094 | R15: =Q15-Q14 -> 0 | S15: =SUM(P15-P14) -> 0 | T15: =SUM(S15*$T$2) -> 0 | U15: =SUM(G15+L15+S15) -> 0 | V15: =R15+N15+I15:I15 -> 0 | W15: =SUM(V15/U15) -> #DIV/0! | X15: =X14 -> 2448 | Y15: =X15-X14 -> 0 | Z15: =Z14 -> 137506 | AA15: =Z15-Z14 -> 0 | AB15: =SUM(Y15*$AB$2) -> 0 | AC15: =AC14 -> 1933 | AD15: =AC15-AC14 -> 0 | AE15: =AE14 -> 365210.2 | AF15: =AE15-AE14 -> 0 | AG15: =IF(AD15>0,AF15/AD15,0) -> 0 | AH15: =AF15+AA15 -> 0 | AI15: =SUM(AH15+V15) -> 0 | AJ15: =-tanks!AW16 -> 0 | AK15: =SUM(AJ15-AI15) -> 0 | AL15: =S15+L15+G15 -> 0 | AM15: =Y15+AD15 -> 0 | AN15: =AN14 -> 63 | AO15: =(AN15/100)*3000 -> 1890 | AP15: =AP14 -> 57 | AQ15: =(AP15/100)*3000 -> 1710 | AR15: =AR14 -> 69 | AS15: =(AR15/100)*3000 -> 2070 | AT15: =SUM(AO15+AQ15+AS15) -> 5670 | AU15: =AT14-AT15+AV15 -> 0 | AX15: =IF(AV15>0,AW15,AX14) -> 0.8
A16: =ELEC!C14 -> 44086 | B16: 238 | C16: 243.2 | D16: =C15-C16 -> 3.8 | E16: =D16*8.38 -> 31.844 | F16: =F15 -> 1648 | G16: =F16-F15 -> 0 | H16: =H15 -> 357868 | I16: =SUM(H16-H15) -> 0 | J16: =IF(G16>0,I16/G16,0) -> 0 | K16: =K15 -> 2110 | L16: =K16-K15 -> 0 | M16: =M15 -> 154820 | N16: =M16-M15 -> 0 | O16: =O15 -> 211.875 | P16: =P15 -> 1839 | Q16: =Q15 -> 156094 | R16: =Q16-Q15 -> 0 | S16: =SUM(P16-P15) -> 0 | T16: =SUM(S16*$T$2) -> 0 | U16: =SUM(G16+L16+S16) -> 0 | V16: =R16+N16+I16:I16 -> 0 | W16: =SUM(V16/U16) -> #DIV/0! | X16: =X15 -> 2448 | Y16: =X16-X15 -> 0 | Z16: =Z15 -> 137506 | AA16: =Z16-Z15 -> 0 | AB16: =SUM(Y16*$AB$2) -> 0 | AC16: =AC15 -> 1933 | AD16: =AC16-AC15 -> 0 | AE16: =AE15 -> 365210.2 | AF16: =AE16-AE15 -> 0 | AG16: =IF(AD16>0,AF16/AD16,0) -> 0 | AH16: =AF16+AA16 -> 0 | AI16: =SUM(AH16+V16) -> 0 | AJ16: =-tanks!AW17 -> 0 | AK16: =SUM(AJ16-AI16) -> 0 | AL16: =S16+L16+G16 -> 0 | AM16: =Y16+AD16 -> 0 | AN16: =AN15 -> 63 | AO16: =(AN16/100)*3000 -> 1890 | AP16: =AP15 -> 57 | AQ16: =(AP16/100)*3000 -> 1710 | AR16: =AR15 -> 69 | AS16: =(AR16/100)*3000 -> 2070 | AT16: =SUM(AO16+AQ16+AS16) -> 5670 | AU16: =AT15-AT16+AV16 -> 0 | AX16: =IF(AV16>0,AW16,AX15) -> 0.8
A17: =ELEC!C15 -> 44087 | B17: 235 | C17: 241.2 | D17: =C16-C17 -> 2 | E17: =D17*8.38 -> 16.76 | F17: 1648 | G17: =F17-F16 -> 0 | H17: =H16 -> 357868 | I17: =SUM(H17-H16) -> 0 | J17: =IF(G17>0,I17/G17,0) -> 0 | K17: =K16 -> 2110 | L17: =K17-K16 -> 0 | M17: =M16 -> 154820 | N17: =M17-M16 -> 0 | O17: =O16 -> 211.875 | P17: =P16 -> 1839 | Q17: =Q16 -> 156094 | R17: =Q17-Q16 -> 0 | S17: =SUM(P17-P16) -> 0 | T17: =SUM(S17*$T$2) -> 0 | U17: =SUM(G17+L17+S17) -> 0 | V17: =R17+N17+I17:I17 -> 0 | X17: =X16 -> 2448 | Y17: =X17-X16 -> 0 | Z17: =Z16 -> 137506 | AA17: =Z17-Z16 -> 0 | AB17: =SUM(Y17*$AB$2) -> 0 | AC17: =AC16 -> 1933 | AD17: =AC17-AC16 -> 0 | AE17: =AE16 -> 365210.2 | AF17: =AE17-AE16 -> 0 | AG17: =IF(AD17>0,AF17/AD17,0) -> 0 | AH17: =AF17+AA17 -> 0 | AI17: =SUM(AH17+V17) -> 0 | AJ17: =-tanks!AW18 -> 0 | AK17: =SUM(AJ17-AI17) -> 0 | AL17: =S17+L17+G17 -> 0 | AM17: =Y17+AD17 -> 0 | AN17: =AN16 -> 63 | AO17: =(AN17/100)*3000 -> 1890 | AP17: 54 | AQ17: =(AP17/100)*3000 -> 1620 | AR17: =AR16 -> 69 | AS17: =(AR17/100)*3000 -> 2070 | AT17: =SUM(AO17+AQ17+AS17) -> 5580 | AU17: =AT16-AT17+AV17 -> 90 | AX17: =IF(AV17>0,AW17,AX16) -> 0.8
A18: =ELEC!C16 -> 44088 | B18: 233.4 | C18: 239 | D18: =C17-C18 -> 2.2 | E18: =D18*8.38 -> 18.436 | F18: =F17 -> 1648 | G18: =F18-F17 -> 0 | H18: =H17 -> 357868 | I18: =SUM(H18-H17) -> 0 | J18: =IF(G18>0,I18/G18,0) -> 0 | K18: =K17 -> 2110 | L18: =K18-K17 -> 0 | M18: =M17 -> 154820 | N18: =M18-M17 -> 0 | O18: =O17 -> 211.875 | P18: =P17 -> 1839 | Q18: =Q17 -> 156094 | R18: =Q18-Q17 -> 0 | S18: =SUM(P18-P17) -> 0 | T18: =SUM(S18*$T$2) -> 0 | U18: =SUM(G18+L18+S18) -> 0 | V18: =R18+N18+I18:I18 -> 0 | X18: =X17 -> 2448 | Y18: =X18-X17 -> 0 | Z18: =Z17 -> 137506 | AA18: =Z18-Z17 -> 0 | AB18: =SUM(Y18*$AB$2) -> 0 | AC18: =AC17 -> 1933 | AD18: =AC18-AC17 -> 0 | AE18: =AE17 -> 365210.2 | AF18: =AE18-AE17 -> 0 | AG18: =IF(AD18>0,AF18/AD18,0) -> 0 | AH18: =AF18+AA18 -> 0 | AI18: =SUM(AH18+V18) -> 0 | AJ18: =-tanks!AW19 -> 0 | AK18: =SUM(AJ18-AI18) -> 0 | AL18: =S18+L18+G18 -> 0 | AM18: =Y18+AD18 -> 0 | AN18: 63 | AO18: =(AN18/100)*3000 -> 1890 | AP18: 54 | AQ18: =(AP18/100)*3000 -> 1620 | AR18: 69 | AS18: =(AR18/100)*3000 -> 2070 | AT18: =SUM(AO18+AQ18+AS18) -> 5580 | AU18: =AT17-AT18+AV18 -> 0 | AX18: =IF(AV18>0,AW18,AX17) -> 0.8
A19: =ELEC!C17 -> 44089 | B19: 229 | C19: 236 | D19: =C18-C19 -> 3 | E19: =D19*8.38 -> 25.14 | F19: 1648 | G19: =F19-F18 -> 0 | H19: =H18 -> 357868 | I19: =SUM(H19-H18) -> 0 | J19: =IF(G19>0,I19/G19,0) -> 0 | K19: =K18 -> 2110 | L19: =K19-K18 -> 0 | M19: =M18 -> 154820 | N19: =M19-M18 -> 0 | O19: =O18 -> 211.875 | P19: =P18 -> 1839 | Q19: =Q18 -> 156094 | R19: =Q19-Q18 -> 0 | S19: =SUM(P19-P18) -> 0 | T19: =SUM(S19*$T$2) -> 0 | U19: =SUM(G19+L19+S19) -> 0 | V19: =R19+N19+I19:I19 -> 0 | X19: =X18 -> 2448 | Y19: =X19-X18 -> 0 | Z19: =Z18 -> 137506 | AA19: =Z19-Z18 -> 0 | AB19: =SUM(Y19*$AB$2) -> 0 | AC19: =AC18 -> 1933 | AD19: =AC19-AC18 -> 0 | AE19: =AE18 -> 365210.2 | AF19: =AE19-AE18 -> 0 | AG19: =IF(AD19>0,AF19/AD19,0) -> 0 | AH19: =AF19+AA19 -> 0 | AI19: =SUM(AH19+V19) -> 0 | AJ19: =-tanks!AW20 -> 0 | AK19: =SUM(AJ19-AI19) -> 0 | AL19: =S19+L20+G19 -> 0 | AM19: =Y19+AD19 -> 0 | AN19: 63 | AO19: =(AN19/100)*3000 -> 1890 | AP19: 53 | AQ19: =(AP19/100)*3000 -> 1590 | AR19: 69 | AS19: =(AR19/100)*3000 -> 2070 | AT19: =SUM(AO19+AQ19+AS19) -> 5550 | AU19: =AT18-AT19+AV19 -> 30 | AX19: =IF(AV19>0,AW19,AX18) -> 0.8
A20: =ELEC!C18 -> 44090 | B20: 226.4 | C20: 232.4 | D20: =C19-C20 -> 3.6 | E20: =D20*8.38 -> 30.168 | F20: =F19 -> 1648 | G20: =F20-F19 -> 0 | H20: =H19 -> 357868 | I20: =SUM(H20-H19) -> 0 | J20: =IF(G20>0,I20/G20,0) -> 0 | K20: =K19 -> 2110 | L20: =K20-K19 -> 0 | M20: =M19 -> 154820 | N20: =M20-M19 -> 0 | O20: =O19 -> 211.875 | P20: =P19 -> 1839 | Q20: =Q19 -> 156094 | R20: =Q20-Q19 -> 0 | S20: =SUM(P20-P19) -> 0 | T20: =SUM(S20*$T$2) -> 0 | U20: =SUM(G20+L20+S20) -> 0 | V20: =R20+N20+I20:I20 -> 0 | X20: =X19 -> 2448 | Y20: =X20-X19 -> 0 | Z20: =Z19 -> 137506 | AA20: =Z20-Z19 -> 0 | AB20: =SUM(Y20*$AB$2) -> 0 | AC20: =AC19 -> 1933 | AD20: =AC20-AC19 -> 0 | AE20: =AE19 -> 365210.2 | AF20: =AE20-AE19 -> 0 | AG20: =IF(AD20>0,AF20/AD20,0) -> 0 | AH20: =AF20+AA20 -> 0 | AI20: =SUM(AH20+V20) -> 0 | AJ20: =-tanks!AW21 -> 0 | AK20: =SUM(AJ20-AI20) -> 0 | AL20: =S20+L21+G20 -> 0 | AM20: =Y20+AD20 -> 0 | AN20: =AN19 -> 63 | AO20: =(AN20/100)*3000 -> 1890 | AP20: 52 | AQ20: =(AP20/100)*3000 -> 1560 | AR20: 68 | AS20: =(AR20/100)*3000 -> 2040 | AT20: =SUM(AO20+AQ20+AS20) -> 5490 | AU20: =AT19-AT20+AV20 -> 60 | AX20: =IF(AV20>0,AW20,AX19) -> 0.8
A21: =ELEC!C19 -> 44091 | B21: 225 | C21: 231 | D21: =C20-C21 -> 1.4 | E21: =D21*8.38 -> 11.732 | F21: =F20 -> 1648 | G21: =F21-F20 -> 0 | H21: =H20 -> 357868 | I21: =SUM(H21-H20) -> 0 | J21: =IF(G21>0,I21/G21,0) -> 0 | K21: =K20 -> 2110 | L21: =K21-K20 -> 0 | M21: =M20 -> 154820 | N21: =M21-M20 -> 0 | O21: =O20 -> 211.875 | P21: =P20 -> 1839 | Q21: =Q20 -> 156094 | R21: =Q21-Q20 -> 0 | S21: =SUM(P21-P20) -> 0 | T21: =SUM(S21*$T$2) -> 0 | U21: =SUM(G21+L21+S21) -> 0 | V21: =R21+N21+I21:I21 -> 0 | X21: =X20 -> 2448 | Y21: =X21-X20 -> 0 | Z21: =Z20 -> 137506 | AA21: =Z21-Z20 -> 0 | AB21: =SUM(Y21*$AB$2) -> 0 | AC21: =AC20 -> 1933 | AD21: =AC21-AC20 -> 0 | AE21: =AE20 -> 365210.2 | AF21: =AE21-AE20 -> 0 | AG21: =IF(AD21>0,AF21/AD21,0) -> 0 | AH21: =AF21+AA21 -> 0 | AI21: =SUM(AH21+V21) -> 0 | AJ21: =-tanks!AW22 -> 0 | AK21: =SUM(AJ21-AI21) -> 0 | AL21: =S21+L21+G21 -> 0 | AM21: =Y21+AD21 -> 0 | AN21: =AN20 -> 63 | AO21: =(AN21/100)*3000 -> 1890 | AP21: =AP20 -> 52 | AQ21: =(AP21/100)*3000 -> 1560 | AR21: =AR20 -> 68 | AS21: =(AR21/100)*3000 -> 2040 | AT21: =SUM(AO21+AQ21+AS21) -> 5490 | AU21: =AT20-AT21+AV21 -> 0 | AX21: =IF(AV21>0,AW21,AX20) -> 0.8
A22: =ELEC!C20 -> 44092 | B22: 223 | C22: 229.1 | D22: =C21-C22 -> 1.9 | E22: =D22*8.38 -> 15.922 | F22: =F21 -> 1648 | G22: =F22-F21 -> 0 | H22: =H21 -> 357868 | I22: =SUM(H22-H21) -> 0 | J22: =IF(G22>0,I22/G22,0) -> 0 | K22: =K21 -> 2110 | L22: =K22-K21 -> 0 | M22: =M21 -> 154820 | N22: =M22-M21 -> 0 | O22: =O21 -> 211.875 | P22: =P21 -> 1839 | Q22: =Q21 -> 156094 | R22: =Q22-Q21 -> 0 | S22: =SUM(P22-P21) -> 0 | T22: =SUM(S22*$T$2) -> 0 | U22: =SUM(G22+L22+S22) -> 0 | V22: =R22+N22+I22:I22 -> 0 | X22: =X21 -> 2448 | Y22: =X22-X21 -> 0 | Z22: =Z21 -> 137506 | AA22: =Z22-Z21 -> 0 | AB22: =SUM(Y22*$AB$2) -> 0 | AC22: =AC21 -> 1933 | AD22: =AC22-AC21 -> 0 | AE22: =AE21 -> 365210.2 | AF22: =AE22-AE21 -> 0 | AG22: =IF(AD22>0,AF22/AD22,0) -> 0 | AH22: =AF22+AA22 -> 0 | AI22: =SUM(AH22+V22) -> 0 | AJ22: =-tanks!AW23 -> 0 | AK22: =SUM(AJ22-AI22) -> 0 | AL22: =S22+L22+G22 -> 0 | AM22: =Y22+AD22 -> 0 | AN22: 62 | AO22: =(AN22/100)*3000 -> 1860 | AP22: =AP21 -> 52 | AQ22: =(AP22/100)*3000 -> 1560 | AR22: =AR21 -> 68 | AS22: =(AR22/100)*3000 -> 2040 | AT22: =SUM(AO22+AQ22+AS22) -> 5460 | AU22: =AT21-AT22+AV22 -> 30 | AX22: =IF(AV22>0,AW22,AX21) -> 0.8
A23: =ELEC!C21 -> 44093 | B23: 220 | C23: 226 | D23: =C22-C23 -> 3.1 | E23: =D23*8.38 -> 25.978 | F23: =F22 -> 1648 | G23: =F23-F22 -> 0 | H23: =H22 -> 357868 | I23: =SUM(H23-H22) -> 0 | J23: =IF(G23>0,I23/G23,0) -> 0 | K23: =K22 -> 2110 | L23: =K23-K22 -> 0 | M23: =M22 -> 154820 | N23: =M23-M22 -> 0 | O23: =O22 -> 211.875 | P23: =P22 -> 1839 | Q23: =Q22 -> 156094 | R23: =Q23-Q22 -> 0 | S23: =SUM(P23-P22) -> 0 | T23: =SUM(S23*$T$2) -> 0 | U23: =SUM(G23+L23+S23) -> 0 | V23: =R23+N23+I23:I23 -> 0 | X23: =X22 -> 2448 | Y23: =X23-X22 -> 0 | Z23: =Z22 -> 137506 | AA23: =Z23-Z22 -> 0 | AB23: =SUM(Y23*$AB$2) -> 0 | AC23: =AC22 -> 1933 | AD23: =AC23-AC22 -> 0 | AE23: =AE22 -> 365210.2 | AF23: =AE23-AE22 -> 0 | AG23: =IF(AD23>0,AF23/AD23,0) -> 0 | AH23: =AF23+AA23 -> 0 | AI23: =SUM(AH23+V23) -> 0 | AJ23: =-tanks!AW24 -> 0 | AK23: =SUM(AJ23-AI23) -> 0 | AL23: =S23+L23+G23 -> 0 | AM23: =Y23+AD23 -> 0 | AN23: =AN22 -> 62 | AO23: =(AN23/100)*3000 -> 1860 | AP23: =AP22 -> 52 | AQ23: =(AP23/100)*3000 -> 1560 | AR23: =AR22 -> 68 | AS23: =(AR23/100)*3000 -> 2040 | AT23: =SUM(AO23+AQ23+AS23) -> 5460 | AU23: =AT22-AT23+AV23 -> 0 | AX23: =IF(AV23>0,AW23,AX22) -> 0.8
A24: =ELEC!C22 -> 44094 | B24: 218 | C24: 224 | D24: =C23-C24 -> 2 | E24: =D24*8.38 -> 16.76 | F24: 1648 | G24: =F24-F23 -> 0 | H24: =H23 -> 357868 | I24: =SUM(H24-H23) -> 0 | J24: =IF(G24>0,I24/G24,0) -> 0 | K24: =K23 -> 2110 | L24: =K24-K23 -> 0 | M24: =M23 -> 154820 | N24: =M24-M23 -> 0 | O24: =O23 -> 211.875 | P24: =P23 -> 1839 | Q24: =Q23 -> 156094 | R24: =Q24-Q23 -> 0 | S24: =SUM(P24-P23) -> 0 | T24: =SUM(S24*$T$2) -> 0 | U24: =SUM(G24+L24+S24) -> 0 | V24: =R24+N24+I24:I24 -> 0 | X24: =X23 -> 2448 | Y24: =X24-X23 -> 0 | Z24: =Z23 -> 137506 | AA24: =Z24-Z23 -> 0 | AB24: =SUM(Y24*$AB$2) -> 0 | AC24: =AC23 -> 1933 | AD24: =AC24-AC23 -> 0 | AE24: =AE23 -> 365210.2 | AF24: =AE24-AE23 -> 0 | AG24: =IF(AD24>0,AF24/AD24,0) -> 0 | AH24: =AF24+AA24 -> 0 | AI24: =SUM(AH24+V24) -> 0 | AJ24: =-tanks!AW25 -> 0 | AK24: =SUM(AJ24-AI24) -> 0 | AL24: =S24+L24+G24 -> 0 | AM24: =Y24+AD24 -> 0 | AN24: 62 | AO24: =(AN24/100)*3000 -> 1860 | AP24: 51 | AQ24: =(AP24/100)*3000 -> 1530 | AR24: 68 | AS24: =(AR24/100)*3000 -> 2040 | AT24: =SUM(AO24+AQ24+AS24) -> 5430 | AU24: =AT23-AT24+AV24 -> 30 | AX24: =IF(AV24>0,AW24,AX23) -> 0.8
A25: =ELEC!C23 -> 44095 | B25: 215 | C25: 221 | D25: =C24-C25 -> 3 | E25: =D25*8.38 -> 25.14 | F25: =F24 -> 1648 | G25: =F25-F24 -> 0 | H25: =H24 -> 357868 | I25: =SUM(H25-H24) -> 0 | J25: =IF(G25>0,I25/G25,0) -> 0 | K25: =K24 -> 2110 | L25: =K25-K24 -> 0 | M25: =M24 -> 154820 | N25: =M25-M24 -> 0 | O25: =O24 -> 211.875 | P25: =P24 -> 1839 | Q25: =Q24 -> 156094 | R25: =Q25-Q24 -> 0 | S25: =SUM(P25-P24) -> 0 | T25: =SUM(S25*$T$2) -> 0 | U25: =SUM(G25+L25+S25) -> 0 | V25: =R25+N25+I25:I25 -> 0 | X25: =X24 -> 2448 | Y25: =X25-X24 -> 0 | Z25: =Z24 -> 137506 | AA25: =Z25-Z24 -> 0 | AB25: =SUM(Y25*$AB$2) -> 0 | AC25: =AC24 -> 1933 | AD25: =AC25-AC24 -> 0 | AE25: =AE24 -> 365210.2 | AF25: =AE25-AE24 -> 0 | AG25: =IF(AD25>0,AF25/AD25,0) -> 0 | AH25: =AF25+AA25 -> 0 | AI25: =SUM(AH25+V25) -> 0 | AJ25: =-tanks!AW26 -> 0 | AK25: =SUM(AJ25-AI25) -> 0 | AL25: =S25+L25+G25 -> 0 | AM25: =Y25+AD25 -> 0 | AN25: =AN24 -> 62 | AO25: =(AN25/100)*3000 -> 1860 | AP25: =AP24 -> 51 | AQ25: =(AP25/100)*3000 -> 1530 | AR25: =AR24 -> 68 | AS25: =(AR25/100)*3000 -> 2040 | AT25: =SUM(AO25+AQ25+AS25) -> 5430 | AU25: =AT24-AT25+AV25 -> 0 | AX25: =IF(AV25>0,AW25,AX24) -> 0.8
A26: =ELEC!C24 -> 44096 | B26: 211 | C26: 217 | D26: =C25-C26 -> 4 | E26: =D26*8.38 -> 33.52 | F26: =F25 -> 1648 | G26: =F26-F25 -> 0 | H26: =H25 -> 357868 | I26: =SUM(H26-H25) -> 0 | J26: =IF(G26>0,I26/G26,0) -> 0 | K26: =K25 -> 2110 | L26: =K26-K25 -> 0 | M26: =M25 -> 154820 | N26: =M26-M25 -> 0 | O26: =O25 -> 211.875 | P26: =P25 -> 1839 | Q26: =Q25 -> 156094 | R26: =Q26-Q25 -> 0 | S26: =SUM(P26-P25) -> 0 | T26: =SUM(S26*$T$2) -> 0 | U26: =SUM(G26+L26+S26) -> 0 | V26: =R26+N26+I26:I26 -> 0 | X26: =X25 -> 2448 | Y26: =X26-X25 -> 0 | Z26: =Z25 -> 137506 | AA26: =Z26-Z25 -> 0 | AB26: =SUM(Y26*$AB$2) -> 0 | AC26: =AC25 -> 1933 | AD26: =AC26-AC25 -> 0 | AE26: =AE25 -> 365210.2 | AF26: =AE26-AE25 -> 0 | AG26: =IF(AD26>0,AF26/AD26,0) -> 0 | AH26: =AF26+AA26 -> 0 | AI26: =SUM(AH26+V26) -> 0 | AJ26: =-tanks!AW27 -> 0 | AK26: =SUM(AJ26-AI26) -> 0 | AL26: =S26+L26+G26 -> 0 | AM26: =Y26+AD26 -> 0 | AN26: =AN25 -> 62 | AO26: =(AN26/100)*3000 -> 1860 | AP26: =AP25 -> 51 | AQ26: =(AP26/100)*3000 -> 1530 | AR26: =AR25 -> 68 | AS26: =(AR26/100)*3000 -> 2040 | AT26: =SUM(AO26+AQ26+AS26) -> 5430 | AU26: =AT25-AT26+AV26 -> 0 | AX26: =IF(AV26>0,AW26,AX25) -> 0.8
A27: =ELEC!C25 -> 44097 | B27: 209 | C27: 215 | D27: =C26-C27 -> 2 | E27: =D27*8.38 -> 16.76 | F27: =F26 -> 1648 | G27: =F27-F26 -> 0 | H27: =H26 -> 357868 | I27: =SUM(H27-H26) -> 0 | J27: =IF(G27>0,I27/G27,0) -> 0 | K27: =K26 -> 2110 | L27: =K27-K26 -> 0 | M27: =M26 -> 154820 | N27: =M27-M26 -> 0 | O27: =O26 -> 211.875 | P27: =P26 -> 1839 | Q27: =Q26 -> 156094 | R27: =Q27-Q26 -> 0 | S27: =SUM(P27-P26) -> 0 | T27: =SUM(S27*$T$2) -> 0 | U27: =SUM(G27+L27+S27) -> 0 | V27: =R27+N27+I27:I27 -> 0 | X27: =X26 -> 2448 | Y27: =X27-X26 -> 0 | Z27: =Z26 -> 137506 | AA27: =Z27-Z26 -> 0 | AB27: =SUM(Y27*$AB$2) -> 0 | AC27: =AC26 -> 1933 | AD27: =AC27-AC26 -> 0 | AE27: =AE26 -> 365210.2 | AF27: =AE27-AE26 -> 0 | AG27: =IF(AD27>0,AF27/AD27,0) -> 0 | AH27: =AF27+AA27 -> 0 | AI27: =SUM(AH27+V27) -> 0 | AJ27: =-tanks!AW28 -> 0 | AK27: =SUM(AJ27-AI27) -> 0 | AL27: =S27+L27+G27 -> 0 | AM27: =Y27+AD27 -> 0 | AN27: =AN26 -> 62 | AO27: =(AN27/100)*3000 -> 1860 | AP27: =AP26 -> 51 | AQ27: =(AP27/100)*3000 -> 1530 | AR27: =AR26 -> 68 | AS27: =(AR27/100)*3000 -> 2040 | AT27: =SUM(AO27+AQ27+AS27) -> 5430 | AU27: =AT26-AT27+AV27 -> 0 | AX27: =IF(AV27>0,AW27,AX26) -> 0.8
