Workbook

Sheet TOTAL
A1: Site Name | B1: Day | C1: Month | D1: Year | E1: Total Electricity Kwh | F1: Electricity Tariff ($/Kwh) | G1: Natual Gas (m3) | H1: Natural Gas $/m3 | I1: Water Utility Supply (m3) m3 | J1: Water Utility Supply (m3) $/m3 | K1: Room Nights
A2: Orlando | B2: 5 | C2: 1 | D2: 2020 | E2: =Submetering!F3+Submetering!H3+Submetering!J3+Submetering!L3+Submetering!N3+Submetering!P3+Submetering!R3+Submetering!T3+Submetering!V3+Submetering!X3+Submetering!Z3+Submetering!AB3+Submetering!AC3+Submetering!AD3+Submetering!AE3 -> 241994 | F2: =((((Submetering!E3+Submetering!AD3)*0.13773+(Submetering!E3+Submetering!AD3)*0.02095)*1.09+(2.85/30)*2)+(((Submetering!F3+Submetering!H3+Submetering!J3+Submetering!L3+Submetering!N3+Submetering!P3+Submetering!R3+Submetering!T3+Submetering!V3+Submetering!X3+Submetering!Z3+Submetering!AB3+Submetering!AC3+Submetering!AE3)*0.05155)+((Submetering!F3+Submetering!H3+Submetering!J3+Submetering!L3+Submetering!N3+Submetering!P3+Submetering!R3+Submetering!T3+Submetering!V3+Submetering!X3+Submetering!Z3+Submetering!AB3+Submetering!AC3+Submetering!AE3)*0.02095)+(20/30)*15)*1.1048)/E2 -> 0.080716593 | G2: =Submetering!AK3+Submetering!AL3+Submetering!AU3 -> 5732.3038 | H2: 0.8166 | I2: =Submetering!AF3+Submetering!AG3+Submetering!AH3+Submetering!AI3+Submetering!AJ3+Submetering!AM3+Submetering!AN3+Submetering!AO3+Submetering!AQ3+Submetering!AR3+Submetering!AS3+Submetering!AT3+Submetering!AV3+Submetering!AY3+Submetering!AW3+Submetering!AZ3+Submetering!BA3 -> 10607.535 | J2: =((Submetering!AG3+Submetering!BA3)*0.8868+(1712.96+1070.52)/30+(Submetering!AF3+Submetering!AY3+Submetering!AV3+Submetering!AZ3)*1.1251+(2076.11+129.67+207.57+207.57)/30+(11680.53+56.61)/30)/I2 -> 0.41229836
A3: Orlando | B3: 12 | C3: 1 | D3: 2020 | E3: =Submetering!F4+Submetering!H4+Submetering!J4+Submetering!L4+Submetering!N4+Submetering!P4+Submetering!R4+Submetering!T4+Submetering!V4+Submetering!X4+Submetering!Z4+Submetering!AB4+Submetering!AC4+Submetering!AD4+Submetering!AE4 -> 295640 | F3: =((((Submetering!E4+Submetering!AD4)*0.13773+(Submetering!E4+Submetering!AD4)*0.02095)*1.09+(2.85/30)*2)+(((Submetering!F4+Submetering!H4+Submetering!J4+Submetering!L4+Submetering!N4+Submetering!P4+Submetering!R4+Submetering!T4+Submetering!V4+Submetering!X4+Submetering!Z4+Submetering!AB4+Submetering!AC4+Submetering!AE4)*0.05155)+((Submetering!F4+Submetering!H4+Submetering!J4+Submetering!L4+Submetering!N4+Submetering!P4+Submetering!R4+Submetering!T4+Submetering!V4+Submetering!X4+Submetering!Z4+Submetering!AB4+Submetering!AC4+Submetering!AE4)*0.02095)+(20/30)*15)*1.1048)/E3 -> 0.080717638 | G3: =Submetering!AK4+Submetering!AL4+Submetering!AU4 -> 7093.1256 | H3: 0.8166 | I3: =Submetering!AF4+Submetering!AG4+Submetering!AH4+Submetering!AI4+Submetering!AJ4+Submetering!AM4+Submetering!AN4+Submetering!AO4+Submetering!AQ4+Submetering!AR4+Submetering!AS4+Submetering!AT4+Submetering!AV4+Submetering!AY4+Submetering!AW4+Submetering!AZ4+Submetering!BA4 -> 13177.334 | J3: =((Submetering!AG4+Submetering!BA4)*0.8868+(1712.96+1070.52)/30+(Submetering!AF4+Submetering!AY4+Submetering!AV4+Submetering!AZ4)*1.1251+(2076.11+129.67+207.57+207.57)/30+(11680.53+56.61)/30)/I3 -> 0.36848524
A4: Orlando | B4: 19 | C4: 1 | D4: 2020 | E4: =Submetering!F5+Submetering!H5+Submetering!J5+Submetering!L5+Submetering!N5+Submetering!P5+Submetering!R5+Submetering!T5+Submetering!V5+Submetering!X5+Submetering!Z5+Submetering!AB5+Submetering!AC5+Submetering!AD5+Submetering!AE5 -> 325940 | F4: =((((Submetering!E5+Submetering!AD5)*0.13773+(Submetering!E5+Submetering!AD5)*0.02095)*1.09+(2.85/30)*2)+(((Submetering!F5+Submetering!H5+Submetering!J5+Submetering!L5+Submetering!N5+Submetering!P5+Submetering!R5+Submetering!T5+Submetering!V5+Submetering!X5+Submetering!Z5+Submetering!AB5+Submetering!AC5+Submetering!AE5)*0.05155)+((Submetering!F5+Submetering!H5+Submetering!J5+Submetering!L5+Submetering!N5+Submetering!P5+Submetering!R5+Submetering!T5+Submetering!V5+Submetering!X5+Submetering!Z5+Submetering!AB5+Submetering!AC5+Submetering!AE5)*0.02095)+(20/30)*15)*1.1048)/E4 -> 0.080664141 | G4: =Submetering!AK5+Submetering!AL5+Submetering!AU5 -> 5253.025 | H4: 0.8166 | I4: =Submetering!AF5+Submetering!AG5+Submetering!AH5+Submetering!AI5+Submetering!AJ5+Submetering!AM5+Submetering!AN5+Submetering!AO5+Submetering!AQ5+Submetering!AR5+Submetering!AS5+Submetering!AT5+Submetering!AV5+Submetering!AY5+Submetering!AW5+Submetering!AZ5+Submetering!BA5 -> 17578.248 | J4: =((Submetering!AG5+Submetering!BA5)*0.8868+(1712.96+1070.52)/30+(Submetering!AF5+Submetering!AY5+Submetering!AV5+Submetering!AZ5)*1.1251+(2076.11+129.67+207.57+207.57)/30+(11680.53+56.61)/30)/I4 -> 0.34688489
A5: Orlando | B5: 26 | C5: 1 | D5: 2020 | E5: =Submetering!F6+Submetering!H6+Submetering!J6+Submetering!L6+Submetering!N6+Submetering!P6+Submetering!R6+Submetering!T6+Submetering!V6+Submetering!X6+Submetering!Z6+Submetering!AB6+Submetering!AC6+Submetering!AD6+Submetering!AE6 -> 286013 | F5: =((((Submetering!E6+Submetering!AD6)*0.13773+(Submetering!E6+Submetering!AD6)*0.02095)*1.09+(2.85/30)*2)+(((Submetering!F6+Submetering!H6+Submetering!J6+Submetering!L6+Submetering!N6+Submetering!P6+Submetering!R6+Submetering!T6+Submetering!V6+Submetering!X6+Submetering!Z6+Submetering!AB6+Submetering!AC6+Submetering!AE6)*0.05155)+((Submetering!F6+Submetering!H6+Submetering!J6+Submetering!L6+Submetering!N6+Submetering!P6+Submetering!R6+Submetering!T6+Submetering!V6+Submetering!X6+Submetering!Z6+Submetering!AB6+Submetering!AC6+Submetering!AE6)*0.02095)+(20/30)*15)*1.1048)/E5 -> 0.080734408 | G5: =Submetering!AK6+Submetering!AL6+Submetering!AU6 -> 5892.812 | H5: 0.8166 | I5: =Submetering!AF6+Submetering!AG6+Submetering!AH6+Submetering!AI6+Submetering!AJ6+Submetering!AM6+Submetering!AN6+Submetering!AO6+Submetering!AQ6+Submetering!AR6+Submetering!AS6+Submetering!AT6+Submetering!AV6+Submetering!AY6+Submetering!AW6+Submetering!AZ6+Submetering!BA6 -> 11017.887 | J5: =((Submetering!AG6+Submetering!BA6)*0.8868+(1712.96+1070.52)/30+(Submetering!AF6+Submetering!AY6+Submetering!AV6+Submetering!AZ6)*1.1251+(2076.11+129.67+207.57+207.57)/30+(11680.53+56.61)/30)/I5 -> 0.47874689
A6: Orlando | B6: 31 | C6: 1 | D6: 2020 | E6: =Submetering!F7+Submetering!H7+Submetering!J7+Submetering!L7+Submetering!N7+Submetering!P7+Submetering!R7+Submetering!T7+Submetering!V7+Submetering!X7+Submetering!Z7+Submetering!AB7+Submetering!AC7+Submetering!AD7+Submetering!AE7 -> 280017 | F6: =((((Submetering!E7+Submetering!AD7)*0.13773+(Submetering!E7+Submetering!AD7)*0.02095)*1.09+(2.85/30)*2)+(((Submetering!F7+Submetering!H7+Submetering!J7+Submetering!L7+Submetering!N7+Submetering!P7+Submetering!R7+Submetering!T7+Submetering!V7+Submetering!X7+Submetering!Z7+Submetering!AB7+Submetering!AC7+Submetering!AE7)*0.05155)+((Submetering!F7+Submetering!H7+Submetering!J7+Submetering!L7+Submetering!N7+Submetering!P7+Submetering!R7+Submetering!T7+Submetering!V7+Submetering!X7+Submetering!Z7+Submetering!AB7+Submetering!AC7+Submetering!AE7)*0.02095)+(20/30)*15)*1.1048)/E6 -> 0.080749979 | G6: =Submetering!AK7+Submetering!AL7+Submetering!AU7 -> 6048.2434 | H6: 0.8166 | I6: =Submetering!AF7+Submetering!AG7+Submetering!AH7+Submetering!AI7+Submetering!AJ7+Submetering!AM7+Submetering!AN7+Submetering!AO7+Submetering!AQ7+Submetering!AR7+Submetering!AS7+Submetering!AT7+Submetering!AV7+Submetering!AY7+Submetering!AW7+Submetering!AZ7+Submetering!BA7 -> 12787.422 | J6: =((Submetering!AG7+Submetering!BA7)*0.8868+(1712.96+1070.52)/30+(Submetering!AF7+Submetering!AY7+Submetering!AV7+Submetering!AZ7)*1.1251+(2076.11+129.67+207.57+207.57)/30+(11680.53+56.61)/30)/I6 -> 0.51213336 | K6: =Occupancy!H4 -> 9827.496
A7: Orlando | B7: 9 | C7: 2 | D7: 2020 | E7: =Submetering!F8+Submetering!H8+Submetering!J8+Submetering!L8+Submetering!N8+Submetering!P8+Submetering!R8+Submetering!T8+Submetering!V8+Submetering!X8+Submetering!Z8+Submetering!AB8+Submetering!AC8+Submetering!AD8+Submetering!AE8 -> 303779 | F7: =((((Submetering!E8+Submetering!AD8)*0.13773+(Submetering!E8+Submetering!AD8)*0.02095)*1.09+(2.85/30)*2)+(((Submetering!F8+Submetering!H8+Submetering!J8+Submetering!L8+Submetering!N8+Submetering!P8+Submetering!R8+Submetering!T8+Submetering!V8+Submetering!X8+Submetering!Z8+Submetering!AB8+Submetering!AC8+Submetering!AE8)*0.05155)+((Submetering!F8+Submetering!H8+Submetering!J8+Submetering!L8+Submetering!N8+Submetering!P8+Submetering!R8+Submetering!T8+Submetering!V8+Submetering!X8+Submetering!Z8+Submetering!AB8+Submetering!AC8+Submetering!AE8)*0.02095)+(20/30)*15)*1.1048)/E7 -> 0.080698873 | G7: =Submetering!AK8+Submetering!AL8+Submetering!AU8 -> 7739.08 | H7: 0.8166 | I7: =Submetering!AF8+Submetering!AG8+Submetering!AH8+Submetering!AI8+Submetering!AJ8+Submetering!AM8+Submetering!AN8+Submetering!AO8+Submetering!AQ8+Submetering!AR8+Submetering!AS8+Submetering!AT8+Submetering!AV8+Submetering!AY8+Submetering!AW8+Submetering!AZ8+Submetering!BA8 -> 14341.008 | J7: =((Submetering!AG8+Submetering!BA8)*0.8868+(1712.96+1070.52)/30+(Submetering!AF8+Submetering!AY8+Submetering!AV8+Submetering!AZ8)*1.1251+(2076.11+129.67+207.57+207.57)/30+(11680.53+56.61)/30)/I7 -> 0.41286151
A8: Orlando | B8: 16 | C8: 2 | D8: 2020 | E8: =Submetering!F9+Submetering!H9+Submetering!J9+Submetering!L9+Submetering!N9+Submetering!P9+Submetering!R9+Submetering!T9+Submetering!V9+Submetering!X9+Submetering!Z9+Submetering!AB9+Submetering!AC9+Submetering!AD9+Submetering!AE9 -> 339448 | F8: =((((Submetering!E9+Submetering!AD9)*0.13773+(Submetering!E9+Submetering!AD9)*0.02095)*1.09+(2.85/30)*2)+(((Submetering!F9+Submetering!H9+Submetering!J9+Submetering!L9+Submetering!N9+Submetering!P9+Submetering!R9+Submetering!T9+Submetering!V9+Submetering!X9+Submetering!Z9+Submetering!AB9+Submetering!AC9+Submetering!AE9)*0.05155)+((Submetering!F9+Submetering!H9+Submetering!J9+Submetering!L9+Submetering!N9+Submetering!P9+Submetering!R9+Submetering!T9+Submetering!V9+Submetering!X9+Submetering!Z9+Submetering!AB9+Submetering!AC9+Submetering!AE9)*0.02095)+(20/30)*15)*1.1048)/E8 -> 0.080615158 | G8: =Submetering!AK9+Submetering!AL9+Submetering!AU9 -> 5602.9366 | H8: 0.8166 | I8: =Submetering!AF9+Submetering!AG9+Submetering!AH9+Submetering!AI9+Submetering!AJ9+Submetering!AM9+Submetering!AN9+Submetering!AO9+Submetering!AQ9+Submetering!AR9+Submetering!AS9+Submetering!AT9+Submetering!AV9+Submetering!AY9+Submetering!AW9+Submetering!AZ9+Submetering!BA9 -> 20007.963 | J8: =((Submetering!AG9+Submetering!BA9)*0.8868+(1712.96+1070.52)/30+(Submetering!AF9+Submetering!AY9+Submetering!AV9+Submetering!AZ9)*1.1251+(2076.11+129.67+207.57+207.57)/30+(11680.53+56.61)/30)/I8 -> 0.34435012
A9: Orlando | B9: 24 | C9: 2 | D9: 2020 | E9: =Submetering!F10+Submetering!H10+Submetering!J10+Submetering!L10+Submetering!N10+Submetering!P10+Submetering!R10+Submetering!T10+Submetering!V10+Submetering!X10+Submetering!Z10+Submetering!AB10+Submetering!AC10+Submetering!AD10+Submetering!AE10 -> 333247 | F9: =((((Submetering!E10+Submetering!AD10)*0.13773+(Submetering!E10+Submetering!AD10)*0.02095)*1.09+(2.85/30)*2)+(((Submetering!F10+Submetering!H10+Submetering!J10+Submetering!L10+Submetering!N10+Submetering!P10+Submetering!R10+Submetering!T10+Submetering!V10+Submetering!X10+Submetering!Z10+Submetering!AB10+Submetering!AC10+Submetering!AE10)*0.05155)+((Submetering!F10+Submetering!H10+Submetering!J10+Submetering!L10+Submetering!N10+Submetering!P10+Submetering!R10+Submetering!T10+Submetering!V10+Submetering!X10+Submetering!Z10+Submetering!AB10+Submetering!AC10+Submetering!AE10)*0.02095)+(20/30)*15)*1.1048)/E9 -> 0.080648352 | G9: =Submetering!AK10+Submetering!AL10+Submetering!AU10 -> 6087.22 | H9: 0.8166 | I9: =Submetering!AF10+Submetering!AG10+Submetering!AH10+Submetering!AI10+Submetering!AJ10+Submetering!AM10+Submetering!AN10+Submetering!AO10+Submetering!AQ10+Submetering!AR10+Submetering!AS10+Submetering!AT10+Submetering!AV10+Submetering!AY10+Submetering!AW10+Submetering!AZ10+Submetering!BA10 -> 18080.74 | J9: =((Submetering!AG10+Submetering!BA10)*0.8868+(1712.96+1070.52)/30+(Submetering!AF10+Submetering!AY10+Submetering!AV10+Submetering!AZ10)*1.1251+(2076.11+129.67+207.57+207.57)/30+(11680.53+56.61)/30)/I9 -> 0.39666512
A10: Orlando | B10: 29 | C10: 2 | D10: 2020 | E10: =Submetering!F11+Submetering!H11+Submetering!J11+Submetering!L11+Submetering!N11+Submetering!P11+Submetering!R11+Submetering!T11+Submetering!V11+Submetering!X11+Submetering!Z11+Submetering!AB11+Submetering!AC11+Submetering!AD11+Submetering!AE11 -> 274944 | F10: =((((Submetering!E11+Submetering!AD11)*0.13773+(Submetering!E11+Submetering!AD11)*0.02095)*1.09+(2.85/30)*2)+(((Submetering!F11+Submetering!H11+Submetering!J11+Submetering!L11+Submetering!N11+Submetering!P11+Submetering!R11+Submetering!T11+Submetering!V11+Submetering!X11+Submetering!Z11+Submetering!AB11+Submetering!AC11+Submetering!AE11)*0.05155)+((Submetering!F11+Submetering!H11+Submetering!J11+Submetering!L11+Submetering!N11+Submetering!P11+Submetering!R11+Submetering!T11+Submetering!V11+Submetering!X11+Submetering!Z11+Submetering!AB11+Submetering!AC11+Submetering!AE11)*0.02095)+(20/30)*15)*1.1048)/E10 -> 0.080677755 | G10: =Submetering!AK11+Submetering!AL11+Submetering!AU11 -> 6370.7722 | H10: 0.8166 | I10: =Submetering!AF11+Submetering!AG11+Submetering!AH11+Submetering!AI11+Submetering!AJ11+Submetering!AM11+Submetering!AN11+Submetering!AO11+Submetering!AQ11+Submetering!AR11+Submetering!AS11+Submetering!AT11+Submetering!AV11+Submetering!AY11+Submetering!AW11+Submetering!AZ11+Submetering!BA11 -> 13432.671 | J10: =((Submetering!AG11+Submetering!BA11)*0.8868+(1712.96+1070.52)/30+(Submetering!AF11+Submetering!AY11+Submetering!AV11+Submetering!AZ11)*1.1251+(2076.11+129.67+207.57+207.57)/30+(11680.53+56.61)/30)/I10 -> 0.46341344 | K10: =Occupancy!H5 -> 9771.552
A11: Orlando | B11: 8 | C11: 3 | D11: 2020 | E11: =Submetering!F12+Submetering!H12+Submetering!J12+Submetering!L12+Submetering!N12+Submetering!P12+Submetering!R12+Submetering!T12+Submetering!V12+Submetering!X12+Submetering!Z12+Submetering!AB12+Submetering!AC12+Submetering!AD12+Submetering!AE12 -> 349889 | F11: =((((Submetering!E12+Submetering!AD12)*0.13773+(Submetering!E12+Submetering!AD12)*0.02095)*1.09+(2.85/30)*2)+(((Submetering!F12+Submetering!H12+Submetering!J12+Submetering!L12+Submetering!N12+Submetering!P12+Submetering!R12+Submetering!T12+Submetering!V12+Submetering!X12+Submetering!Z12+Submetering!AB12+Submetering!AC12+Submetering!AE12)*0.05155)+((Submetering!F12+Submetering!H12+Submetering!J12+Submetering!L12+Submetering!N12+Submetering!P12+Submetering!R12+Submetering!T12+Submetering!V12+Submetering!X12+Submetering!Z12+Submetering!AB12+Submetering!AC12+Submetering!AE12)*0.02095)+(20/30)*15)*1.1048)/E11 -> 0.080614326 | G11: =Submetering!AK12+Submetering!AL12+Submetering!AU12 -> 7051.736 | H11: 0.8166 | I11: =Submetering!AF12+Submetering!AG12+Submetering!AH12+Submetering!AI12+Submetering!AJ12+Submetering!AM12+Submetering!AN12+Submetering!AO12+Submetering!AQ12+Submetering!AR12+Submetering!AS12+Submetering!AT12+Submetering!AV12+Submetering!AY12+Submetering!AW12+Submetering!AZ12+Submetering!BA12 -> 18624.405 | J11: =((Submetering!AG12+Submetering!BA12)*0.8868+(1712.96+1070.52)/30+(Submetering!AF12+Submetering!AY12+Submetering!AV12+Submetering!AZ12)*1.1251+(2076.11+129.67+207.57+207.57)/30+(11680.53+56.61)/30)/I11 -> 0.41712139
A12: Orlando | B12: 15 | C12: 3 | D12: 2020 | E12: =Submetering!F13+Submetering!H13+Submetering!J13+Submetering!L13+Submetering!N13+Submetering!P13+Submetering!R13+Submetering!T13+Submetering!V13+Submetering!X13+Submetering!Z13+Submetering!AB13+Submetering!AC13+Submetering!AD13+Submetering!AE13 -> 312051 | F12: =((((Submetering!E13+Submetering!AD13)*0.13773+(Submetering!E13+Submetering!AD13)*0.02095)*1.09+(2.85/30)*2)+(((Submetering!F13+Submetering!H13+Submetering!J13+Submetering!L13+Submetering!N13+Submetering!P13+Submetering!R13+Submetering!T13+Submetering!V13+Submetering!X13+Submetering!Z13+Submetering!AB13+Submetering!AC13+Submetering!AE13)*0.05155)+((Submetering!F13+Submetering!H13+Submetering!J13+Submetering!L13+Submetering!N13+Submetering!P13+Submetering!R13+Submetering!T13+Submetering!V13+Submetering!X13+Submetering!Z13+Submetering!AB13+Submetering!AC13+Submetering!AE13)*0.02095)+(20/30)*15)*1.1048)/E12 -> 0.080618394 | G12: =Submetering!AK13+Submetering!AL13+Submetering!AU13 -> 4599.9266 | H12: 0.8166 | I12: =Submetering!AF13+Submetering!AG13+Submetering!AH13+Submetering!AI13+Submetering!AJ13+Submetering!AM13+Submetering!AN13+Submetering!AO13+Submetering!AQ13+Submetering!AR13+Submetering!AS13+Submetering!AT13+Submetering!AV13+Submetering!AY13+Submetering!AW13+Submetering!AZ13+Submetering!BA13 -> 18493.69 | J12: =((Submetering!AG13+Submetering!BA13)*0.8868+(1712.96+1070.52)/30+(Submetering!AF13+Submetering!AY13+Submetering!AV13+Submetering!AZ13)*1.1251+(2076.11+129.67+207.57+207.57)/30+(11680.53+56.61)/30)/I12 -> 0.38956539
A13: Orlando | B13: 22 | C13: 3 | D13: 2020 | E13: =Submetering!F14+Submetering!H14+Submetering!J14+Submetering!L14+Submetering!N14+Submetering!P14+Submetering!R14+Submetering!T14+Submetering!V14+Submetering!X14+Submetering!Z14+Submetering!AB14+Submetering!AC14+Submetering!AD14+Submetering!AE14 -> 289491 | F13: =((((Submetering!E14+Submetering!AD14)*0.13773+(Submetering!E14+Submetering!AD14)*0.02095)*1.09+(2.85/30)*2)+(((Submetering!F14+Submetering!H14+Submetering!J14+Submetering!L14+Submetering!N14+Submetering!P14+Submetering!R14+Submetering!T14+Submetering!V14+Submetering!X14+Submetering!Z14+Submetering!AB14+Submetering!AC14+Submetering!AE14)*0.05155)+((Submetering!F14+Submetering!H14+Submetering!J14+Submetering!L14+Submetering!N14+Submetering!P14+Submetering!R14+Submetering!T14+Submetering!V14+Submetering!X14+Submetering!Z14+Submetering!AB14+Submetering!AC14+Submetering!AE14)*0.02095)+(20/30)*15)*1.1048)/E13 -> 0.080654766 | G13: =Submetering!AK14+Submetering!AL14+Submetering!AU14 -> 3333.36 | H13: 0.8166 | I13: =Submetering!AF14+Submetering!AG14+Submetering!AH14+Submetering!AI14+Submetering!AJ14+Submetering!AM14+Submetering!AN14+Submetering!AO14+Submetering!AQ14+Submetering!AR14+Submetering!AS14+Submetering!AT14+Submetering!AV14+Submetering!AY14+Submetering!AW14+Submetering!AZ14+Submetering!BA14 -> 17091.572 | J13: =((Submetering!AG14+Submetering!BA14)*0.8868+(1712.96+1070.52)/30+(Submetering!AF14+Submetering!AY14+Submetering!AV14+Submetering!AZ14)*1.1251+(2076.11+129.67+207.57+207.57)/30+(11680.53+56.61)/30)/I13 -> 0.35748184
A14: Orlando | B14: 29 | C14: 3 | D14: 2020 | E14: =Submetering!F15+Submetering!H15+Submetering!J15+Submetering!L15+Submetering!N15+Submetering!P15+Submetering!R15+Submetering!T15+Submetering!V15+Submetering!X15+Submetering!Z15+Submetering!AB15+Submetering!AC15+Submetering!AD15+Submetering!AE15 -> 177664 | F14: =((((Submetering!E15+Submetering!AD15)*0.13773+(Submetering!E15+Submetering!AD15)*0.02095)*1.09+(2.85/30)*2)+(((Submetering!F15+Submetering!H15+Submetering!J15+Submetering!L15+Submetering!N15+Submetering!P15+Submetering!R15+Submetering!T15+Submetering!V15+Submetering!X15+Submetering!Z15+Submetering!AB15+Submetering!AC15+Submetering!AE15)*0.05155)+((Submetering!F15+Submetering!H15+Submetering!J15+Submetering!L15+Submetering!N15+Submetering!P15+Submetering!R15+Submetering!T15+Submetering!V15+Submetering!X15+Submetering!Z15+Submetering!AB15+Submetering!AC15+Submetering!AE15)*0.02095)+(20/30)*15)*1.1048)/E14 -> 0.080613648 | G14: =Submetering!AK15+Submetering!AL15+Submetering!AU15 -> 1133.198 | H14: 0.8166 | I14: =Submetering!AF15+Submetering!AG15+Submetering!AH15+Submetering!AI15+Submetering!AJ15+Submetering!AM15+Submetering!AN15+Submetering!AO15+Submetering!AQ15+Submetering!AR15+Submetering!AS15+Submetering!AT15+Submetering!AV15+Submetering!AY15+Submetering!AW15+Submetering!AZ15+Submetering!BA15 -> 12638.4 | J14: =((Submetering!AG15+Submetering!BA15)*0.8868+(1712.96+1070.52)/30+(Submetering!AF15+Submetering!AY15+Submetering!AV15+Submetering!AZ15)*1.1251+(2076.11+129.67+207.57+207.57)/30+(11680.53+56.61)/30)/I14 -> 0.38619259
A15: Orlando | B15: 31 | C15: 3 | D15: 2020 | E15: =Submetering!F16+Submetering!H16+Submetering!J16+Submetering!L16+Submetering!N16+Submetering!P16+Submetering!R16+Submetering!T16+Submetering!V16+Submetering!X16+Submetering!Z16+Submetering!AB16+Submetering!AC16+Submetering!AD16+Submetering!AE16 -> 49771 | F15: =((((Submetering!E16+Submetering!AD16)*0.13773+(Submetering!E16+Submetering!AD16)*0.02095)*1.09+(2.85/30)*2)+(((Submetering!F16+Submetering!H16+Submetering!J16+Submetering!L16+Submetering!N16+Submetering!P16+Submetering!R16+Submetering!T16+Submetering!V16+Submetering!X16+Submetering!Z16+Submetering!AB16+Submetering!AC16+Submetering!AE16)*0.05155)+((Submetering!F16+Submetering!H16+Submetering!J16+Submetering!L16+Submetering!N16+Submetering!P16+Submetering!R16+Submetering!T16+Submetering!V16+Submetering!X16+Submetering!Z16+Submetering!AB16+Submetering!AC16+Submetering!AE16)*0.02095)+(20/30)*15)*1.1048)/E15 -> 0.080743793 | G15: =Submetering!AK16+Submetering!AL16+Submetering!AU16 -> 59.6752 | H15: 0.8166 | I15: =Submetering!AF16+Submetering!AG16+Submetering!AH16+Submetering!AI16+Submetering!AJ16+Submetering!AM16+Submetering!AN16+Submetering!AO16+Submetering!AQ16+Submetering!AR16+Submetering!AS16+Submetering!AT16+Submetering!AV16+Submetering!AY16+Submetering!AW16+Submetering!AZ16+Submetering!BA16 -> 4957.0544 | J15: =((Submetering!AG16+Submetering!BA16)*0.8868+(1712.96+1070.52)/30+(Submetering!AF16+Submetering!AY16+Submetering!AV16+Submetering!AZ16)*1.1251+(2076.11+129.67+207.57+207.57)/30+(11680.53+56.61)/30)/I15 -> 0.45669127 | K15: =Occupancy!H6 -> 3895.212
A16: Orlando | B16: 5 | C16: 4 | D16: 2020 | E16: =Submetering!F17+Submetering!H17+Submetering!J17+Submetering!L17+Submetering!N17+Submetering!P17+Submetering!R17+Submetering!T17+Submetering!V17+Submetering!X17+Submetering!Z17+Submetering!AB17+Submetering!AC17+Submetering!AD17+Submetering!AE17 -> 105497 | F16: =((((Submetering!E17+Submetering!AD17)*0.13773+(Submetering!E17+Submetering!AD17)*0.02095)*1.09+(2.85/30)*2)+(((Submetering!F17+Submetering!H17+Submetering!J17+Submetering!L17+Submetering!N17+Submetering!P17+Submetering!R17+Submetering!T17+Submetering!V17+Submetering!X17+Submetering!Z17+Submetering!AB17+Submetering!AC17+Submetering!AE17)*0.05155)+((Submetering!F17+Submetering!H17+Submetering!J17+Submetering!L17+Submetering!N17+Submetering!P17+Submetering!R17+Submetering!T17+Submetering!V17+Submetering!X17+Submetering!Z17+Submetering!AB17+Submetering!AC17+Submetering!AE17)*0.02095)+(20/30)*15)*1.1048)/E16 -> 0.080682448 | G16: =Submetering!AK17+Submetering!AL17+Submetering!AU17 -> 152.8056 | H16: 0.8166 | I16: =Submetering!AF17+Submetering!AG17+Submetering!AH17+Submetering!AI17+Submetering!AJ17+Submetering!AM17+Submetering!AN17+Submetering!AO17+Submetering!AQ17+Submetering!AR17+Submetering!AS17+Submetering!AT17+Submetering!AV17+Submetering!AY17+Submetering!AW17+Submetering!AZ17+Submetering!BA17 -> 6685.5735 | J16: =((Submetering!AG17+Submetering!BA17)*0.8868+(1712.96+1070.52)/30+(Submetering!AF17+Submetering!AY17+Submetering!AV17+Submetering!AZ17)*1.1251+(2076.11+129.67+207.57+207.57)/30+(11680.53+56.61)/30)/I16 -> 0.52078479
A17: Orlando | B17: 12 | C17: 4 | D17: 2020 | E17: =Submetering!F18+Submetering!H18+Submetering!J18+Submetering!L18+Submetering!N18+Submetering!P18+Submetering!R18+Submetering!T18+Submetering!V18+Submetering!X18+Submetering!Z18+Submetering!AB18+Submetering!AC18+Submetering!AD18+Submetering!AE18 -> 158920 | F17: =((((Submetering!E18+Submetering!AD18)*0.13773+(Submetering!E18+Submetering!AD18)*0.02095)*1.09+(2.85/30)*2)+(((Submetering!F18+Submetering!H18+Submetering!J18+Submetering!L18+Submetering!N18+Submetering!P18+Submetering!R18+Submetering!T18+Submetering!V18+Submetering!X18+Submetering!Z18+Submetering!AB18+Submetering!AC18+Submetering!AE18)*0.05155)+((Submetering!F18+Submetering!H18+Submetering!J18+Submetering!L18+Submetering!N18+Submetering!P18+Submetering!R18+Submetering!T18+Submetering!V18+Submetering!X18+Submetering!Z18+Submetering!AB18+Submetering!AC18+Submetering!AE18)*0.02095)+(20/30)*15)*1.1048)/E17 -> 0.080547591 | G17: =Submetering!AK18+Submetering!AL18+Submetering!AU18 -> 187.7884 | H17: 0.8166 | I17: =Submetering!AF18+Submetering!AG18+Submetering!AH18+Submetering!AI18+Submetering!AJ18+Submetering!AM18+Submetering!AN18+Submetering!AO18+Submetering!AQ18+Submetering!AR18+Submetering!AS18+Submetering!AT18+Submetering!AV18+Submetering!AY18+Submetering!AW18+Submetering!AZ18+Submetering!BA18 -> 10772.56 | J17: =((Submetering!AG18+Submetering!BA18)*0.8868+(1712.96+1070.52)/30+(Submetering!AF18+Submetering!AY18+Submetering!AV18+Submetering!AZ18)*1.1251+(2076.11+129.67+207.57+207.57)/30+(11680.53+56.61)/30)/I17 -> 0.38362285
A18: Orlando | B18: 19 | C18: 4 | D18: 2020 | E18: =Submetering!F19+Submetering!H19+Submetering!J19+Submetering!L19+Submetering!N19+Submetering!P19+Submetering!R19+Submetering!T19+Submetering!V19+Submetering!X19+Submetering!Z19+Submetering!AB19+Submetering!AC19+Submetering!AD19+Submetering!AE19 -> 164520 | F18: =((((Submetering!E19+Submetering!AD19)*0.13773+(Submetering!E19+Submetering!AD19)*0.02095)*1.09+(2.85/30)*2)+(((Submetering!F19+Submetering!H19+Submetering!J19+Submetering!L19+Submetering!N19+Submetering!P19+Submetering!R19+Submetering!T19+Submetering!V19+Submetering!X19+Submetering!Z19+Submetering!AB19+Submetering!AC19+Submetering!AE19)*0.05155)+((Submetering!F19+Submetering!H19+Submetering!J19+Submetering!L19+Submetering!N19+Submetering!P19+Submetering!R19+Submetering!T19+Submetering!V19+Submetering!X19+Submetering!Z19+Submetering!AB19+Submetering!AC19+Submetering!AE19)*0.02095)+(20/30)*15)*1.1048)/E18 -> 0.08056643 | G18: =Submetering!AK19+Submetering!AL19+Submetering!AU19 -> 169.5864 | H18: 0.8166 | I18: =Submetering!AF19+Submetering!AG19+Submetering!AH19+Submetering!AI19+Submetering!AJ19+Submetering!AM19+Submetering!AN19+Submetering!AO19+Submetering!AQ19+Submetering!AR19+Submetering!AS19+Submetering!AT19+Submetering!AV19+Submetering!AY19+Submetering!AW19+Submetering!AZ19+Submetering!BA19 -> 10992.376 | J18: =((Submetering!AG19+Submetering!BA19)*0.8868+(1712.96+1070.52)/30+(Submetering!AF19+Submetering!AY19+Submetering!AV19+Submetering!AZ19)*1.1251+(2076.11+129.67+207.57+207.57)/30+(11680.53+56.61)/30)/I18 -> 0.33489412
A19: Orlando | B19: 26 | C19: 4 | D19: 2020 | E19: =Submetering!F20+Submetering!H20+Submetering!J20+Submetering!L20+Submetering!N20+Submetering!P20+Submetering!R20+Submetering!T20+Submetering!V20+Submetering!X20+Submetering!Z20+Submetering!AB20+Submetering!AC20+Submetering!AD20+Submetering!AE20 -> 164908 | F19: =((((Submetering!E20+Submetering!AD20)*0.13773+(Submetering!E20+Submetering!AD20)*0.02095)*1.09+(2.85/30)*2)+(((Submetering!F20+Submetering!H20+Submetering!J20+Submetering!L20+Submetering!N20+Submetering!P20+Submetering!R20+Submetering!T20+Submetering!V20+Submetering!X20+Submetering!Z20+Submetering!AB20+Submetering!AC20+Submetering!AE20)*0.05155)+((Submetering!F20+Submetering!H20+Submetering!J20+Submetering!L20+Submetering!N20+Submetering!P20+Submetering!R20+Submetering!T20+Submetering!V20+Submetering!X20+Submetering!Z20+Submetering!AB20+Submetering!AC20+Submetering!AE20)*0.02095)+(20/30)*15)*1.1048)/E19 -> 0.080523734 | G19: =Submetering!AK20+Submetering!AL20+Submetering!AU20 -> 220.476 | H19: 0.8166 | I19: =Submetering!AF20+Submetering!AG20+Submetering!AH20+Submetering!AI20+Submetering!AJ20+Submetering!AM20+Submetering!AN20+Submetering!AO20+Submetering!AQ20+Submetering!AR20+Submetering!AS20+Submetering!AT20+Submetering!AV20+Submetering!AY20+Submetering!AW20+Submetering!AZ20+Submetering!BA20 -> 11634.725 | J19: =((Submetering!AG20+Submetering!BA20)*0.8868+(1712.96+1070.52)/30+(Submetering!AF20+Submetering!AY20+Submetering!AV20+Submetering!AZ20)*1.1251+(2076.11+129.67+207.57+207.57)/30+(11680.53+56.61)/30)/I19 -> 0.34055249
A20: Orlando | B20: 30 | C20: 4 | D20: 2020 | E20: =Submetering!F21+Submetering!H21+Submetering!J21+Submetering!L21+Submetering!N21+Submetering!P21+Submetering!R21+Submetering!T21+Submetering!V21+Submetering!X21+Submetering!Z21+Submetering!AB21+Submetering!AC21+Submetering!AD21+Submetering!AE21 -> 86857 | F20: =((((Submetering!E21+Submetering!AD21)*0.13773+(Submetering!E21+Submetering!AD21)*0.02095)*1.09+(2.85/30)*2)+(((Submetering!F21+Submetering!H21+Submetering!J21+Submetering!L21+Submetering!N21+Submetering!P21+Submetering!R21+Submetering!T21+Submetering!V21+Submetering!X21+Submetering!Z21+Submetering!AB21+Submetering!AC21+Submetering!AE21)*0.05155)+((Submetering!F21+Submetering!H21+Submetering!J21+Submetering!L21+Submetering!N21+Submetering!P21+Submetering!R21+Submetering!T21+Submetering!V21+Submetering!X21+Submetering!Z21+Submetering!AB21+Submetering!AC21+Submetering!AE21)*0.02095)+(20/30)*15)*1.1048)/E20 -> 0.080689959 | G20: =Submetering!AK21+Submetering!AL21+Submetering!AU21 -> 132.3046 | H20: 0.8166 | I20: =Submetering!AF21+Submetering!AG21+Submetering!AH21+Submetering!AI21+Submetering!AJ21+Submetering!AM21+Submetering!AN21+Submetering!AO21+Submetering!AQ21+Submetering!AR21+Submetering!AS21+Submetering!AT21+Submetering!AV21+Submetering!AY21+Submetering!AW21+Submetering!AZ21+Submetering!BA21 -> 6820.2159 | J20: =((Submetering!AG21+Submetering!BA21)*0.8868+(1712.96+1070.52)/30+(Submetering!AF21+Submetering!AY21+Submetering!AV21+Submetering!AZ21)*1.1251+(2076.11+129.67+207.57+207.57)/30+(11680.53+56.61)/30)/I20 -> 0.48243716 | K20: =Occupancy!H7 -> 0
A21: Orlando | B21: 4 | C21: 5 | D21: 2020 | E21: =Submetering!F22+Submetering!H22+Submetering!J22+Submetering!L22+Submetering!N22+Submetering!P22+Submetering!R22+Submetering!T22+Submetering!V22+Submetering!X22+Submetering!Z22+Submetering!AB22+Submetering!AC22+Submetering!AD22+Submetering!AE22 -> 49087 | F21: =((((Submetering!E22+Submetering!AD22)*0.13773+(Submetering!E22+Submetering!AD22)*0.02095)*1.09+(2.85/30)*2)+(((Submetering!F22+Submetering!H22+Submetering!J22+Submetering!L22+Submetering!N22+Submetering!P22+Submetering!R22+Submetering!T22+Submetering!V22+Submetering!X22+Submetering!Z22+Submetering!AB22+Submetering!AC22+Submetering!AE22)*0.05155)+((Submetering!F22+Submetering!H22+Submetering!J22+Submetering!L22+Submetering!N22+Submetering!P22+Submetering!R22+Submetering!T22+Submetering!V22+Submetering!X22+Submetering!Z22+Submetering!AB22+Submetering!AC22+Submetering!AE22)*0.02095)+(20/30)*15)*1.1048)/E21 -> 0.080670475 | G21: =Submetering!AK22+Submetering!AL22+Submetering!AU22 -> 91.9676 | H21: 0.8166 | I21: =Submetering!AF22+Submetering!AG22+Submetering!AH22+Submetering!AI22+Submetering!AJ22+Submetering!AM22+Submetering!AN22+Submetering!AO22+Submetering!AQ22+Submetering!AR22+Submetering!AS22+Submetering!AT22+Submetering!AV22+Submetering!AY22+Submetering!AW22+Submetering!AZ22+Submetering!BA22 -> 4164.2205 | J21: =((Submetering!AG22+Submetering!BA22)*0.8868+(1712.96+1070.52)/30+(Submetering!AF22+Submetering!AY22+Submetering!AV22+Submetering!AZ22)*1.1251+(2076.11+129.67+207.57+207.57)/30+(11680.53+56.61)/30)/I21 -> 0.5652277
A22: Orlando | B22: 10 | C22: 5 | D22: 2020 | E22: =Submetering!F23+Submetering!H23+Submetering!J23+Submetering!L23+Submetering!N23+Submetering!P23+Submetering!R23+Submetering!T23+Submetering!V23+Submetering!X23+Submetering!Z23+Submetering!AB23+Submetering!AC23+Submetering!AD23+Submetering!AE23 -> 154064 | F22: =((((Submetering!E23+Submetering!AD23)*0.13773+(Submetering!E23+Submetering!AD23)*0.02095)*1.09+(2.85/30)*2)+(((Submetering!F23+Submetering!H23+Submetering!J23+Submetering!L23+Submetering!N23+Submetering!P23+Submetering!R23+Submetering!T23+Submetering!V23+Submetering!X23+Submetering!Z23+Submetering!AB23+Submetering!AC23+Submetering!AE23)*0.05155)+((Submetering!F23+Submetering!H23+Submetering!J23+Submetering!L23+Submetering!N23+Submetering!P23+Submetering!R23+Submetering!T23+Submetering!V23+Submetering!X23+Submetering!Z23+Submetering!AB23+Submetering!AC23+Submetering!AE23)*0.02095)+(20/30)*15)*1.1048)/E22 -> 0.080872287 | G22: =Submetering!AK23+Submetering!AL23+Submetering!AU23 -> 220.5102 | H22: 0.8166 | I22: =Submetering!AF23+Submetering!AG23+Submetering!AH23+Submetering!AI23+Submetering!AJ23+Submetering!AM23+Submetering!AN23+Submetering!AO23+Submetering!AQ23+Submetering!AR23+Submetering!AS23+Submetering!AT23+Submetering!AV23+Submetering!AY23+Submetering!AW23+Submetering!AZ23+Submetering!BA23 -> 11082.527 | J22: =((Submetering!AG23+Submetering!BA23)*0.8868+(1712.96+1070.52)/30+(Submetering!AF23+Submetering!AY23+Submetering!AV23+Submetering!AZ23)*1.1251+(2076.11+129.67+207.57+207.57)/30+(11680.53+56.61)/30)/I22 -> 0.40379664
A23: Orlando | B23: 17 | C23: 5 | D23: 2020 | E23: =Submetering!F24+Submetering!H24+Submetering!J24+Submetering!L24+Submetering!N24+Submetering!P24+Submetering!R24+Submetering!T24+Submetering!V24+Submetering!X24+Submetering!Z24+Submetering!AB24+Submetering!AC24+Submetering!AD24+Submetering!AE24 -> 164094 | F23: =((((Submetering!E24+Submetering!AD24)*0.13773+(Submetering!E24+Submetering!AD24)*0.02095)*1.09+(2.85/30)*2)+(((Submetering!F24+Submetering!H24+Submetering!J24+Submetering!L24+Submetering!N24+Submetering!P24+Submetering!R24+Submetering!T24+Submetering!V24+Submetering!X24+Submetering!Z24+Submetering!AB24+Submetering!AC24+Submetering!AE24)*0.05155)+((Submetering!F24+Submetering!H24+Submetering!J24+Submetering!L24+Submetering!N24+Submetering!P24+Submetering!R24+Submetering!T24+Submetering!V24+Submetering!X24+Submetering!Z24+Submetering!AB24+Submetering!AC24+Submetering!AE24)*0.02095)+(20/30)*15)*1.1048)/E23 -> 0.080789286 | G23: =Submetering!AK24+Submetering!AL24+Submetering!AU24 -> 223.7668 | H23: 0.8166 | I23: =Submetering!AF24+Submetering!AG24+Submetering!AH24+Submetering!AI24+Submetering!AJ24+Submetering!AM24+Submetering!AN24+Submetering!AO24+Submetering!AQ24+Submetering!AR24+Submetering!AS24+Submetering!AT24+Submetering!AV24+Submetering!AY24+Submetering!AW24+Submetering!AZ24+Submetering!BA24 -> 13199.997 | J23: =((Submetering!AG24+Submetering!BA24)*0.8868+(1712.96+1070.52)/30+(Submetering!AF24+Submetering!AY24+Submetering!AV24+Submetering!AZ24)*1.1251+(2076.11+129.67+207.57+207.57)/30+(11680.53+56.61)/30)/I23 -> 0.42667455
A24: Orlando | B24: 24 | C24: 5 | D24: 2020 | E24: =Submetering!F25+Submetering!H25+Submetering!J25+Submetering!L25+Submetering!N25+Submetering!P25+Submetering!R25+Submetering!T25+Submetering!V25+Submetering!X25+Submetering!Z25+Submetering!AB25+Submetering!AC25+Submetering!AD25+Submetering!AE25 -> 175587 | F24: =((((Submetering!E25+Submetering!AD25)*0.13773+(Submetering!E25+Submetering!AD25)*0.02095)*1.09+(2.85/30)*2)+(((Submetering!F25+Submetering!H25+Submetering!J25+Submetering!L25+Submetering!N25+Submetering!P25+Submetering!R25+Submetering!T25+Submetering!V25+Submetering!X25+Submetering!Z25+Submetering!AB25+Submetering!AC25+Submetering!AE25)*0.05155)+((Submetering!F25+Submetering!H25+Submetering!J25+Submetering!L25+Submetering!N25+Submetering!P25+Submetering!R25+Submetering!T25+Submetering!V25+Submetering!X25+Submetering!Z25+Submetering!AB25+Submetering!AC25+Submetering!AE25)*0.02095)+(20/30)*15)*1.1048)/E24 -> 0.080751641 | G24: =Submetering!AK25+Submetering!AL25+Submetering!AU25 -> 206.5528 | H24: 0.8166 | I24: =Submetering!AF25+Submetering!AG25+Submetering!AH25+Submetering!AI25+Submetering!AJ25+Submetering!AM25+Submetering!AN25+Submetering!AO25+Submetering!AQ25+Submetering!AR25+Submetering!AS25+Submetering!AT25+Submetering!AV25+Submetering!AY25+Submetering!AW25+Submetering!AZ25+Submetering!BA25 -> 12806.225 | J24: =((Submetering!AG25+Submetering!BA25)*0.8868+(1712.96+1070.52)/30+(Submetering!AF25+Submetering!AY25+Submetering!AV25+Submetering!AZ25)*1.1251+(2076.11+129.67+207.57+207.57)/30+(11680.53+56.61)/30)/I24 -> 0.36307869
A25: Orlando | B25: 31 | C25: 5 | D25: 2020 | E25: =Submetering!F26+Submetering!H26+Submetering!J26+Submetering!L26+Submetering!N26+Submetering!P26+Submetering!R26+Submetering!T26+Submetering!V26+Submetering!X26+Submetering!Z26+Submetering!AB26+Submetering!AC26+Submetering!AD26+Submetering!AE26 -> 182491 | F25: =((((Submetering!E26+Submetering!AD26)*0.13773+(Submetering!E26+Submetering!AD26)*0.02095)*1.09+(2.85/30)*2)+(((Submetering!F26+Submetering!H26+Submetering!J26+Submetering!L26+Submetering!N26+Submetering!P26+Submetering!R26+Submetering!T26+Submetering!V26+Submetering!X26+Submetering!Z26+Submetering!AB26+Submetering!AC26+Submetering!AE26)*0.05155)+((Submetering!F26+Submetering!H26+Submetering!J26+Submetering!L26+Submetering!N26+Submetering!P26+Submetering!R26+Submetering!T26+Submetering!V26+Submetering!X26+Submetering!Z26+Submetering!AB26+Submetering!AC26+Submetering!AE26)*0.02095)+(20/30)*15)*1.1048)/E25 -> 0.080732739 | G25: =Submetering!AK26+Submetering!AL26+Submetering!AU26 -> 195.5632 | H25: 0.8166 | I25: =Submetering!AF26+Submetering!AG26+Submetering!AH26+Submetering!AI26+Submetering!AJ26+Submetering!AM26+Submetering!AN26+Submetering!AO26+Submetering!AQ26+Submetering!AR26+Submetering!AS26+Submetering!AT26+Submetering!AV26+Submetering!AY26+Submetering!AW26+Submetering!AZ26+Submetering!BA26 -> 11298.428 | J25: =((Submetering!AG26+Submetering!BA26)*0.8868+(1712.96+1070.52)/30+(Submetering!AF26+Submetering!AY26+Submetering!AV26+Submetering!AZ26)*1.1251+(2076.11+129.67+207.57+207.57)/30+(11680.53+56.61)/30)/I25 -> 0.30516211 | K25: =Occupancy!H8 -> 0
A26: Orlando | B26: 8 | C26: 6 | D26: 2020 | E26: =Submetering!F27+Submetering!H27+Submetering!J27+Submetering!L27+Submetering!N27+Submetering!P27+Submetering!R27+Submetering!T27+Submetering!V27+Submetering!X27+Submetering!Z27+Submetering!AB27+Submetering!AC27+Submetering!AD27+Submetering!AE27 -> 182461 | F26: =((((Submetering!E27+Submetering!AD27)*0.13773+(Submetering!E27+Submetering!AD27)*0.02095)*1.09+(2.85/30)*2)+(((Submetering!F27+Submetering!H27+Submetering!J27+Submetering!L27+Submetering!N27+Submetering!P27+Submetering!R27+Submetering!T27+Submetering!V27+Submetering!X27+Submetering!Z27+Submetering!AB27+Submetering!AC27+Submetering!AE27)*0.05155)+((Submetering!F27+Submetering!H27+Submetering!J27+Submetering!L27+Submetering!N27+Submetering!P27+Submetering!R27+Submetering!T27+Submetering!V27+Submetering!X27+Submetering!Z27+Submetering!AB27+Submetering!AC27+Submetering!AE27)*0.02095)+(20/30)*15)*1.1048)/E26 -> 0.080641897 | G26: =Submetering!AK27+Submetering!AL27+Submetering!AU27 -> 206.9822 | H26: 0.8166 | I26: =Submetering!AF27+Submetering!AG27+Submetering!AH27+Submetering!AI27+Submetering!AJ27+Submetering!AM27+Submetering!AN27+Submetering!AO27+Submetering!AQ27+Submetering!AR27+Submetering!AS27+Submetering!AT27+Submetering!AV27+Submetering!AY27+Submetering!AW27+Submetering!AZ27+Submetering!BA27 -> 9823.1392 | J26: =((Submetering!AG27+Submetering!BA27)*0.8868+(1712.96+1070.52)/30+(Submetering!AF27+Submetering!AY27+Submetering!AV27+Submetering!AZ27)*1.1251+(2076.11+129.67+207.57+207.57)/30+(11680.53+56.61)/30)/I26 -> 0.23496421
A27: Orlando | B27: 15 | C27: 6 | D27: 2020 | E27: =Submetering!F28+Submetering!H28+Submetering!J28+Submetering!L28+Submetering!N28+Submetering!P28+Submetering!R28+Submetering!T28+Submetering!V28+Submetering!X28+Submetering!Z28+Submetering!AB28+Submetering!AC28+Submetering!AD28+Submetering!AE28 -> 197001 | F27: =((((Submetering!E28+Submetering!AD28)*0.13773+(Submetering!E28+Submetering!AD28)*0.02095)*1.09+(2.85/30)*2)+(((Submetering!F28+Submetering!H28+Submetering!J28+Submetering!L28+Submetering!N28+Submetering!P28+Submetering!R28+Submetering!T28+Submetering!V28+Submetering!X28+Submetering!Z28+Submetering!AB28+Submetering!AC28+Submetering!AE28)*0.05155)+((Submetering!F28+Submetering!H28+Submetering!J28+Submetering!L28+Submetering!N28+Submetering!P28+Submetering!R28+Submetering!T28+Submetering!V28+Submetering!X28+Submetering!Z28+Submetering!AB28+Submetering!AC28+Submetering!AE28)*0.02095)+(20/30)*15)*1.1048)/E27 -> 0.080863807 | G27: =Submetering!AK28+Submetering!AL28+Submetering!AU28 -> 216.8394 | H27: 0.8166 | I27: =Submetering!AF28+Submetering!AG28+Submetering!AH28+Submetering!AI28+Submetering!AJ28+Submetering!AM28+Submetering!AN28+Submetering!AO28+Submetering!AQ28+Submetering!AR28+Submetering!AS28+Submetering!AT28+Submetering!AV28+Submetering!AY28+Submetering!AW28+Submetering!AZ28+Submetering!BA28 -> 11104.427 | J27: =((Submetering!AG28+Submetering!BA28)*0.8868+(1712.96+1070.52)/30+(Submetering!AF28+Submetering!AY28+Submetering!AV28+Submetering!AZ28)*1.1251+(2076.11+129.67+207.57+207.57)/30+(11680.53+56.61)/30)/I27 -> 0.21306937
A28: Orlando | B28: 22 | C28: 6 | D28: 2020 | E28: =Submetering!F29+Submetering!H29+Submetering!J29+Submetering!L29+Submetering!N29+Submetering!P29+Submetering!R29+Submetering!T29+Submetering!V29+Submetering!X29+Submetering!Z29+Submetering!AB29+Submetering!AC29+Submetering!AD29+Submetering!AE29 -> 253322 | F28: =((((Submetering!E29+Submetering!AD29)*0.13773+(Submetering!E29+Submetering!AD29)*0.02095)*1.09+(2.85/30)*2)+(((Submetering!F29+Submetering!H29+Submetering!J29+Submetering!L29+Submetering!N29+Submetering!P29+Submetering!R29+Submetering!T29+Submetering!V29+Submetering!X29+Submetering!Z29+Submetering!AB29+Submetering!AC29+Submetering!AE29)*0.05155)+((Submetering!F29+Submetering!H29+Submetering!J29+Submetering!L29+Submetering!N29+Submetering!P29+Submetering!R29+Submetering!T29+Submetering!V29+Submetering!X29+Submetering!Z29+Submetering!AB29+Submetering!AC29+Submetering!AE29)*0.02095)+(20/30)*15)*1.1048)/E28 -> 0.080643029 | G28: =Submetering!AK29+Submetering!AL29+Submetering!AU29 -> 280.6984 | H28: 0.8166 | I28: =Submetering!AF29+Submetering!AG29+Submetering!AH29+Submetering!AI29+Submetering!AJ29+Submetering!AM29+Submetering!AN29+Submetering!AO29+Submetering!AQ29+Submetering!AR29+Submetering!AS29+Submetering!AT29+Submetering!AV29+Submetering!AY29+Submetering!AW29+Submetering!AZ29+Submetering!BA29 -> 15585.752 | J28: =((Submetering!AG29+Submetering!BA29)*0.8868+(1712.96+1070.52)/30+(Submetering!AF29+Submetering!AY29+Submetering!AV29+Submetering!AZ29)*1.1251+(2076.11+129.67+207.57+207.57)/30+(11680.53+56.61)/30)/I28 -> 0.24697632
A29: Orlando | B29: 29 | C29: 6 | D29: 2020 | E29: =Submetering!F30+Submetering!H30+Submetering!J30+Submetering!L30+Submetering!N30+Submetering!P30+Submetering!R30+Submetering!T30+Submetering!V30+Submetering!X30+Submetering!Z30+Submetering!AB30+Submetering!AC30+Submetering!AD30+Submetering!AE30 -> 247272 | F29: =((((Submetering!E30+Submetering!AD30)*0.13773+(Submetering!E30+Submetering!AD30)*0.02095)*1.09+(2.85/30)*2)+(((Submetering!F30+Submetering!H30+Submetering!J30+Submetering!L30+Submetering!N30+Submetering!P30+Submetering!R30+Submetering!T30+Submetering!V30+Submetering!X30+Submetering!Z30+Submetering!AB30+Submetering!AC30+Submetering!AE30)*0.05155)+((Submetering!F30+Submetering!H30+Submetering!J30+Submetering!L30+Submetering!N30+Submetering!P30+Submetering!R30+Submetering!T30+Submetering!V30+Submetering!X30+Submetering!Z30+Submetering!AB30+Submetering!AC30+Submetering!AE30)*0.02095)+(20/30)*15)*1.1048)/E29 -> 0.080610674 | G29: =Submetering!AK30+Submetering!AL30+Submetering!AU30 -> 515.8614 | H29: 0.8166 | I29: =Submetering!AF30+Submetering!AG30+Submetering!AH30+Submetering!AI30+Submetering!AJ30+Submetering!AM30+Submetering!AN30+Submetering!AO30+Submetering!AQ30+Submetering!AR30+Submetering!AS30+Submetering!AT30+Submetering!AV30+Submetering!AY30+Submetering!AW30+Submetering!AZ30+Submetering!BA30 -> 16830.946 | J29: =((Submetering!AG30+Submetering!BA30)*0.8868+(1712.96+1070.52)/30+(Submetering!AF30+Submetering!AY30+Submetering!AV30+Submetering!AZ30)*1.1251+(2076.11+129.67+207.57+207.57)/30+(11680.53+56.61)/30)/I29 -> 0.29711404
A30: Orlando | B30: 30 | C30: 6 | D30: 2020 | E30: =Submetering!F31+Submetering!H31+Submetering!J31+Submetering!L31+Submetering!N31+Submetering!P31+Submetering!R31+Submetering!T31+Submetering!V31+Submetering!X31+Submetering!Z31+Submetering!AB31+Submetering!AC31+Submetering!AD31+Submetering!AE31 -> 81240 | F30: =((((Submetering!E31+Submetering!AD31)*0.13773+(Submetering!E31+Submetering!AD31)*0.02095)*1.09+(2.85/30)*2)+(((Submetering!F31+Submetering!H31+Submetering!J31+Submetering!L31+Submetering!N31+Submetering!P31+Submetering!R31+Submetering!T31+Submetering!V31+Submetering!X31+Submetering!Z31+Submetering!AB31+Submetering!AC31+Submetering!AE31)*0.05155)+((Submetering!F31+Submetering!H31+Submetering!J31+Submetering!L31+Submetering!N31+Submetering!P31+Submetering!R31+Submetering!T31+Submetering!V31+Submetering!X31+Submetering!Z31+Submetering!AB31+Submetering!AC31+Submetering!AE31)*0.02095)+(20/30)*15)*1.1048)/E30 -> 0.080625635 | G30: =Submetering!AK31+Submetering!AL31+Submetering!AU31 -> 121.6494 | H30: 0.8166 | I30: =Submetering!AF31+Submetering!AG31+Submetering!AH31+Submetering!AI31+Submetering!AJ31+Submetering!AM31+Submetering!AN31+Submetering!AO31+Submetering!AQ31+Submetering!AR31+Submetering!AS31+Submetering!AT31+Submetering!AV31+Submetering!AY31+Submetering!AW31+Submetering!AZ31+Submetering!BA31 -> 5320.653 | J30: =((Submetering!AG31+Submetering!BA31)*0.8868+(1712.96+1070.52)/30+(Submetering!AF31+Submetering!AY31+Submetering!AV31+Submetering!AZ31)*1.1251+(2076.11+129.67+207.57+207.57)/30+(11680.53+56.61)/30)/I30 -> 0.4251168 | K30: =Occupancy!H9 -> 0
A31: Orlando | B31: 6 | C31: 7 | D31: 2020 | E31: =Submetering!F32+Submetering!H32+Submetering!J32+Submetering!L32+Submetering!N32+Submetering!P32+Submetering!R32+Submetering!T32+Submetering!V32+Submetering!X32+Submetering!Z32+Submetering!AB32+Submetering!AC32+Submetering!AD32+Submetering!AE32 -> 241691 | F31: =((((Submetering!E32+Submetering!AD32)*0.13773+(Submetering!E32+Submetering!AD32)*0.02095)*1.09+(2.85/30)*2)+(((Submetering!F32+Submetering!H32+Submetering!J32+Submetering!L32+Submetering!N32+Submetering!P32+Submetering!R32+Submetering!T32+Submetering!V32+Submetering!X32+Submetering!Z32+Submetering!AB32+Submetering!AC32+Submetering!AE32)*0.05155)+((Submetering!F32+Submetering!H32+Submetering!J32+Submetering!L32+Submetering!N32+Submetering!P32+Submetering!R32+Submetering!T32+Submetering!V32+Submetering!X32+Submetering!Z32+Submetering!AB32+Submetering!AC32+Submetering!AE32)*0.02095)+(20/30)*15)*1.1048)/E31 -> 0.080583212 | G31: =Submetering!AK32+Submetering!AL32+Submetering!AU32 -> 986.309 | H31: 0.8166 | I31: =Submetering!AF32+Submetering!AG32+Submetering!AH32+Submetering!AI32+Submetering!AJ32+Submetering!AM32+Submetering!AN32+Submetering!AO32+Submetering!AQ32+Submetering!AR32+Submetering!AS32+Submetering!AT32+Submetering!AV32+Submetering!AY32+Submetering!AW32+Submetering!AZ32+Submetering!BA32 -> 13490.236 | J31: =((Submetering!AG32+Submetering!BA32)*0.8868+(1712.96+1070.52)/30+(Submetering!AF32+Submetering!AY32+Submetering!AV32+Submetering!AZ32)*1.1251+(2076.11+129.67+207.57+207.57)/30+(11680.53+56.61)/30)/I31 -> 0.28980055
A32: Orlando | B32: 13 | C32: 7 | D32: 2020 | E32: =Submetering!F33+Submetering!H33+Submetering!J33+Submetering!L33+Submetering!N33+Submetering!P33+Submetering!R33+Submetering!T33+Submetering!V33+Submetering!X33+Submetering!Z33+Submetering!AB33+Submetering!AC33+Submetering!AD33+Submetering!AE33 -> 307943 | F32: =((((Submetering!E33+Submetering!AD33)*0.13773+(Submetering!E33+Submetering!AD33)*0.02095)*1.09+(2.85/30)*2)+(((Submetering!F33+Submetering!H33+Submetering!J33+Submetering!L33+Submetering!N33+Submetering!P33+Submetering!R33+Submetering!T33+Submetering!V33+Submetering!X33+Submetering!Z33+Submetering!AB33+Submetering!AC33+Submetering!AE33)*0.05155)+((Submetering!F33+Submetering!H33+Submetering!J33+Submetering!L33+Submetering!N33+Submetering!P33+Submetering!R33+Submetering!T33+Submetering!V33+Submetering!X33+Submetering!Z33+Submetering!AB33+Submetering!AC33+Submetering!AE33)*0.02095)+(20/30)*15)*1.1048)/E32 -> 0.08059147 | G32: =Submetering!AK33+Submetering!AL33+Submetering!AU33 -> 1275.5536 | H32: 0.8166 | I32: =Submetering!AF33+Submetering!AG33+Submetering!AH33+Submetering!AI33+Submetering!AJ33+Submetering!AM33+Submetering!AN33+Submetering!AO33+Submetering!AQ33+Submetering!AR33+Submetering!AS33+Submetering!AT33+Submetering!AV33+Submetering!AY33+Submetering!AW33+Submetering!AZ33+Submetering!BA33 -> 16760.955 | J32: =((Submetering!AG33+Submetering!BA33)*0.8868+(1712.96+1070.52)/30+(Submetering!AF33+Submetering!AY33+Submetering!AV33+Submetering!AZ33)*1.1251+(2076.11+129.67+207.57+207.57)/30+(11680.53+56.61)/30)/I32 -> 0.24987606
A33: Orlando | B33: 20 | C33: 7 | D33: 2020 | E33: =Submetering!F34+Submetering!H34+Submetering!J34+Submetering!L34+Submetering!N34+Submetering!P34+Submetering!R34+Submetering!T34+Submetering!V34+Submetering!X34+Submetering!Z34+Submetering!AB34+Submetering!AC34+Submetering!AD34+Submetering!AE34 -> 334140 | F33: =((((Submetering!E34+Submetering!AD34)*0.13773+(Submetering!E34+Submetering!AD34)*0.02095)*1.09+(2.85/30)*2)+(((Submetering!F34+Submetering!H34+Submetering!J34+Submetering!L34+Submetering!N34+Submetering!P34+Submetering!R34+Submetering!T34+Submetering!V34+Submetering!X34+Submetering!Z34+Submetering!AB34+Submetering!AC34+Submetering!AE34)*0.05155)+((Submetering!F34+Submetering!H34+Submetering!J34+Submetering!L34+Submetering!N34+Submetering!P34+Submetering!R34+Submetering!T34+Submetering!V34+Submetering!X34+Submetering!Z34+Submetering!AB34+Submetering!AC34+Submetering!AE34)*0.02095)+(20/30)*15)*1.1048)/E33 -> 0.080582081 | G33: =Submetering!AK34+Submetering!AL34+Submetering!AU34 -> 1103.7594 | H33: 0.8166 | I33: =Submetering!AF34+Submetering!AG34+Submetering!AH34+Submetering!AI34+Submetering!AJ34+Submetering!AM34+Submetering!AN34+Submetering!AO34+Submetering!AQ34+Submetering!AR34+Submetering!AS34+Submetering!AT34+Submetering!AV34+Submetering!AY34+Submetering!AW34+Submetering!AZ34+Submetering!BA34 -> 20253.704 | J33: =((Submetering!AG34+Submetering!BA34)*0.8868+(1712.96+1070.52)/30+(Submetering!AF34+Submetering!AY34+Submetering!AV34+Submetering!AZ34)*1.1251+(2076.11+129.67+207.57+207.57)/30+(11680.53+56.61)/30)/I33 -> 0.2808731
A34: Orlando | B34: 27 | C34: 7 | D34: 2020 | E34: =Submetering!F35+Submetering!H35+Submetering!J35+Submetering!L35+Submetering!N35+Submetering!P35+Submetering!R35+Submetering!T35+Submetering!V35+Submetering!X35+Submetering!Z35+Submetering!AB35+Submetering!AC35+Submetering!AD35+Submetering!AE35 -> 330582 | F34: =((((Submetering!E35+Submetering!AD35)*0.13773+(Submetering!E35+Submetering!AD35)*0.02095)*1.09+(2.85/30)*2)+(((Submetering!F35+Submetering!H35+Submetering!J35+Submetering!L35+Submetering!N35+Submetering!P35+Submetering!R35+Submetering!T35+Submetering!V35+Submetering!X35+Submetering!Z35+Submetering!AB35+Submetering!AC35+Submetering!AE35)*0.05155)+((Submetering!F35+Submetering!H35+Submetering!J35+Submetering!L35+Submetering!N35+Submetering!P35+Submetering!R35+Submetering!T35+Submetering!V35+Submetering!X35+Submetering!Z35+Submetering!AB35+Submetering!AC35+Submetering!AE35)*0.02095)+(20/30)*15)*1.1048)/E34 -> 0.080591652 | G34: =Submetering!AK35+Submetering!AL35+Submetering!AU35 -> 1467.807 | H34: 0.8166 | I34: =Submetering!AF35+Submetering!AG35+Submetering!AH35+Submetering!AI35+Submetering!AJ35+Submetering!AM35+Submetering!AN35+Submetering!AO35+Submetering!AQ35+Submetering!AR35+Submetering!AS35+Submetering!AT35+Submetering!AV35+Submetering!AY35+Submetering!AW35+Submetering!AZ35+Submetering!BA35 -> 19488.486 | J34: =((Submetering!AG35+Submetering!BA35)*0.8868+(1712.96+1070.52)/30+(Submetering!AF35+Submetering!AY35+Submetering!AV35+Submetering!AZ35)*1.1251+(2076.11+129.67+207.57+207.57)/30+(11680.53+56.61)/30)/I34 -> 0.24506324
A35: Orlando | B35: 31 | C35: 7 | D35: 2020 | E35: =Submetering!F36+Submetering!H36+Submetering!J36+Submetering!L36+Submetering!N36+Submetering!P36+Submetering!R36+Submetering!T36+Submetering!V36+Submetering!X36+Submetering!Z36+Submetering!AB36+Submetering!AC36+Submetering!AD36+Submetering!AE36 -> 245138 | F35: =((((Submetering!E36+Submetering!AD36)*0.13773+(Submetering!E36+Submetering!AD36)*0.02095)*1.09+(2.85/30)*2)+(((Submetering!F36+Submetering!H36+Submetering!J36+Submetering!L36+Submetering!N36+Submetering!P36+Submetering!R36+Submetering!T36+Submetering!V36+Submetering!X36+Submetering!Z36+Submetering!AB36+Submetering!AC36+Submetering!AE36)*0.05155)+((Submetering!F36+Submetering!H36+Submetering!J36+Submetering!L36+Submetering!N36+Submetering!P36+Submetering!R36+Submetering!T36+Submetering!V36+Submetering!X36+Submetering!Z36+Submetering!AB36+Submetering!AC36+Submetering!AE36)*0.02095)+(20/30)*15)*1.1048)/E35 -> 0.080576252 | G35: =Submetering!AK36+Submetering!AL36+Submetering!AU36 -> 896.1958 | H35: 0.8166 | I35: =Submetering!AF36+Submetering!AG36+Submetering!AH36+Submetering!AI36+Submetering!AJ36+Submetering!AM36+Submetering!AN36+Submetering!AO36+Submetering!AQ36+Submetering!AR36+Submetering!AS36+Submetering!AT36+Submetering!AV36+Submetering!AY36+Submetering!AW36+Submetering!AZ36+Submetering!BA36 -> 15332.685 | J35: =((Submetering!AG36+Submetering!BA36)*0.8868+(1712.96+1070.52)/30+(Submetering!AF36+Submetering!AY36+Submetering!AV36+Submetering!AZ36)*1.1251+(2076.11+129.67+207.57+207.57)/30+(11680.53+56.61)/30)/I35 -> 0.24905789 | K35: =Occupancy!H10 -> 2821.62
A36: Orlando | B36: 3 | C36: 8 | D36: 2020 | E36: =Submetering!F37+Submetering!H37+Submetering!J37+Submetering!L37+Submetering!N37+Submetering!P37+Submetering!R37+Submetering!T37+Submetering!V37+Submetering!X37+Submetering!Z37+Submetering!AB37+Submetering!AC37+Submetering!AD37+Submetering!AE37 -> 88399 | F36: =((((Submetering!E37+Submetering!AD37)*0.13773+(Submetering!E37+Submetering!AD37)*0.02095)*1.09+(2.85/30)*2)+(((Submetering!F37+Submetering!H37+Submetering!J37+Submetering!L37+Submetering!N37+Submetering!P37+Submetering!R37+Submetering!T37+Submetering!V37+Submetering!X37+Submetering!Z37+Submetering!AB37+Submetering!AC37+Submetering!AE37)*0.05155)+((Submetering!F37+Submetering!H37+Submetering!J37+Submetering!L37+Submetering!N37+Submetering!P37+Submetering!R37+Submetering!T37+Submetering!V37+Submetering!X37+Submetering!Z37+Submetering!AB37+Submetering!AC37+Submetering!AE37)*0.02095)+(20/30)*15)*1.1048)/E36 -> 0.080894629 | G36: =Submetering!AK37+Submetering!AL37+Submetering!AU37 -> 250.5492 | H36: 0.8166 | I36: =Submetering!AF37+Submetering!AG37+Submetering!AH37+Submetering!AI37+Submetering!AJ37+Submetering!AM37+Submetering!AN37+Submetering!AO37+Submetering!AQ37+Submetering!AR37+Submetering!AS37+Submetering!AT37+Submetering!AV37+Submetering!AY37+Submetering!AW37+Submetering!AZ37+Submetering!BA37 -> 4566.9764 | J36: =((Submetering!AG37+Submetering!BA37)*0.8868+(1712.96+1070.52)/30+(Submetering!AF37+Submetering!AY37+Submetering!AV37+Submetering!AZ37)*1.1251+(2076.11+129.67+207.57+207.57)/30+(11680.53+56.61)/30)/I36 -> 0.44359529
A37: Orlando | B37: 10 | C37: 8 | D37: 2020 | E37: =Submetering!F38+Submetering!H38+Submetering!J38+Submetering!L38+Submetering!N38+Submetering!P38+Submetering!R38+Submetering!T38+Submetering!V38+Submetering!X38+Submetering!Z38+Submetering!AB38+Submetering!AC38+Submetering!AD38+Submetering!AE38 -> 333700 | F37: =((((Submetering!E38+Submetering!AD38)*0.13773+(Submetering!E38+Submetering!AD38)*0.02095)*1.09+(2.85/30)*2)+(((Submetering!F38+Submetering!H38+Submetering!J38+Submetering!L38+Submetering!N38+Submetering!P38+Submetering!R38+Submetering!T38+Submetering!V38+Submetering!X38+Submetering!Z38+Submetering!AB38+Submetering!AC38+Submetering!AE38)*0.05155)+((Submetering!F38+Submetering!H38+Submetering!J38+Submetering!L38+Submetering!N38+Submetering!P38+Submetering!R38+Submetering!T38+Submetering!V38+Submetering!X38+Submetering!Z38+Submetering!AB38+Submetering!AC38+Submetering!AE38)*0.02095)+(20/30)*15)*1.1048)/E37 -> 0.080578598 | G37: =Submetering!AK38+Submetering!AL38+Submetering!AU38 -> 1051.3042 | H37: 0.8166 | I37: =Submetering!AF38+Submetering!AG38+Submetering!AH38+Submetering!AI38+Submetering!AJ38+Submetering!AM38+Submetering!AN38+Submetering!AO38+Submetering!AQ38+Submetering!AR38+Submetering!AS38+Submetering!AT38+Submetering!AV38+Submetering!AY38+Submetering!AW38+Submetering!AZ38+Submetering!BA38 -> 20584.125 | J37: =((Submetering!AG38+Submetering!BA38)*0.8868+(1712.96+1070.52)/30+(Submetering!AF38+Submetering!AY38+Submetering!AV38+Submetering!AZ38)*1.1251+(2076.11+129.67+207.57+207.57)/30+(11680.53+56.61)/30)/I37 -> 0.26536198
A38: Orlando | B38: 17 | C38: 8 | D38: 2020 | E38: =Submetering!F39+Submetering!H39+Submetering!J39+Submetering!L39+Submetering!N39+Submetering!P39+Submetering!R39+Submetering!T39+Submetering!V39+Submetering!X39+Submetering!Z39+Submetering!AB39+Submetering!AC39+Submetering!AD39+Submetering!AE39 -> 344074 | F38: =((((Submetering!E39+Submetering!AD39)*0.13773+(Submetering!E39+Submetering!AD39)*0.02095)*1.09+(2.85/30)*2)+(((Submetering!F39+Submetering!H39+Submetering!J39+Submetering!L39+Submetering!N39+Submetering!P39+Submetering!R39+Submetering!T39+Submetering!V39+Submetering!X39+Submetering!Z39+Submetering!AB39+Submetering!AC39+Submetering!AE39)*0.05155)+((Submetering!F39+Submetering!H39+Submetering!J39+Submetering!L39+Submetering!N39+Submetering!P39+Submetering!R39+Submetering!T39+Submetering!V39+Submetering!X39+Submetering!Z39+Submetering!AB39+Submetering!AC39+Submetering!AE39)*0.02095)+(20/30)*15)*1.1048)/E38 -> 0.080571776 | G38: =Submetering!AK39+Submetering!AL39+Submetering!AU39 -> 1192.7478 | H38: 0.8166 | I38: =Submetering!AF39+Submetering!AG39+Submetering!AH39+Submetering!AI39+Submetering!AJ39+Submetering!AM39+Submetering!AN39+Submetering!AO39+Submetering!AQ39+Submetering!AR39+Submetering!AS39+Submetering!AT39+Submetering!AV39+Submetering!AY39+Submetering!AW39+Submetering!AZ39+Submetering!BA39 -> 21390.5 | J38: =((Submetering!AG39+Submetering!BA39)*0.8868+(1712.96+1070.52)/30+(Submetering!AF39+Submetering!AY39+Submetering!AV39+Submetering!AZ39)*1.1251+(2076.11+129.67+207.57+207.57)/30+(11680.53+56.61)/30)/I38 -> 0.26085849
A39: Orlando | B39: 24 | C39: 8 | D39: 2020 | E39: =Submetering!F40+Submetering!H40+Submetering!J40+Submetering!L40+Submetering!N40+Submetering!P40+Submetering!R40+Submetering!T40+Submetering!V40+Submetering!X40+Submetering!Z40+Submetering!AB40+Submetering!AC40+Submetering!AD40+Submetering!AE40 -> 322558 | F39: =((((Submetering!E40+Submetering!AD40)*0.13773+(Submetering!E40+Submetering!AD40)*0.02095)*1.09+(2.85/30)*2)+(((Submetering!F40+Submetering!H40+Submetering!J40+Submetering!L40+Submetering!N40+Submetering!P40+Submetering!R40+Submetering!T40+Submetering!V40+Submetering!X40+Submetering!Z40+Submetering!AB40+Submetering!AC40+Submetering!AE40)*0.05155)+((Submetering!F40+Submetering!H40+Submetering!J40+Submetering!L40+Submetering!N40+Submetering!P40+Submetering!R40+Submetering!T40+Submetering!V40+Submetering!X40+Submetering!Z40+Submetering!AB40+Submetering!AC40+Submetering!AE40)*0.02095)+(20/30)*15)*1.1048)/E39 -> 0.080634533 | G39: =Submetering!AK40+Submetering!AL40+Submetering!AU40 -> 1617.9526 | H39: 0.8166 | I39: =Submetering!AF40+Submetering!AG40+Submetering!AH40+Submetering!AI40+Submetering!AJ40+Submetering!AM40+Submetering!AN40+Submetering!AO40+Submetering!AQ40+Submetering!AR40+Submetering!AS40+Submetering!AT40+Submetering!AV40+Submetering!AY40+Submetering!AW40+Submetering!AZ40+Submetering!BA40 -> 20404.17 | J39: =((Submetering!AG40+Submetering!BA40)*0.8868+(1712.96+1070.52)/30+(Submetering!AF40+Submetering!AY40+Submetering!AV40+Submetering!AZ40)*1.1251+(2076.11+129.67+207.57+207.57)/30+(11680.53+56.61)/30)/I39 -> 0.29308447
