Workbook

Sheet Total
A1: Site Name | B1: Day | C1: Month | D1: Year | E1: Total Electricity Kwh | F1: Electricity Tariff ($/Kwh) | G1: Total Fuel Oil (Liters) | H1: Fuel Oil $/Liter | I1: LPG (Kg) | J1: LPG $/Kg | K1: Water Utility Supply (m3) m3 | L1: Water Utility Supply (m3) $/m3 | M1: Irrigation Water (m3) m3 | N1: Irrigation water $/m3 | O1: Room Nights
A2: Beirut | B2: 1 | C2: 11 | D2: 2020 | E2: =ELEC!N3 -> 8072 | F2: =SUM('EDl log'!T4) -> 0.079822341 | G2: =-tanks!AW6 -> 205 | H2: =SUM(tanks!AV6) -> 0.5 | I2: =('B5'!AU5)*0.51 -> -45.9 | J2: ='B5'!AX5/0.51 -> 1.5686275 | K2: =WATER!I6 -> 137 | L2: =SUM(WATER!J6) -> 1.8248175 | M2: =WATER!Q6 -> 0 | N2: 0.6 | O2: =ELEC!B3 -> 0
A3: Beirut | B3: =B2+1 -> 2 | C3: 11 | D3: 2020 | E3: =ELEC!N4 -> 7352 | F3: =SUM('EDl log'!T5) -> 0.096868709 | G3: =-tanks!AW7 -> 97 | H3: =SUM(tanks!AV7) -> 0.5 | I3: =('B5'!AU6)*0.51 -> 0 | J3: ='B5'!AX6/0.51 -> 1.5686275 | K3: =WATER!I7 -> 0 | L3: =SUM(WATER!J7) -> 0 | M3: =WATER!Q7 -> 0 | N3: 0.6 | O3: =ELEC!B4 -> 0
A4: Beirut | B4: =B3+1 -> 3 | C4: 11 | D4: 2020 | E4: =ELEC!N5 -> 8515 | F4: =SUM('EDl log'!T6) -> 0.091685672 | G4: =-tanks!AW8 -> 0 | H4: =SUM(tanks!AV8) -> 0.5 | I4: =('B5'!AU7)*0.51 -> 0 | J4: ='B5'!AX7/0.51 -> 1.5686275 | K4: =WATER!I8 -> 250 | L4: =SUM(WATER!J8) -> 1.83664 | M4: =WATER!Q8 -> 0 | N4: 0.6 | O4: =ELEC!B5 -> 0
A5: Beirut | B5: =B4+1 -> 4 | C5: 11 | D5: 2020 | E5: =ELEC!N6 -> 8156 | F5: =SUM('EDl log'!T7) -> 0.11045806 | G5: =-tanks!AW9 -> 0 | H5: =SUM(tanks!AV9) -> 0.5 | I5: =('B5'!AU8)*0.51 -> 0 | J5: ='B5'!AX8/0.51 -> 1.5686275 | K5: =WATER!I9 -> 0 | L5: =SUM(WATER!J9) -> 0 | M5: =WATER!Q9 -> 0 | N5: 0.6 | O5: =ELEC!B6 -> 0
A6: Beirut | B6: =B5+1 -> 5 | C6: 11 | D6: 2020 | E6: =ELEC!N7 -> 7853.4 | F6: =SUM('EDl log'!T8) -> 0.10812479 | G6: =-tanks!AW10 -> 0 | H6: =SUM(tanks!AV10) -> 0.5 | I6: =('B5'!AU9)*0.51 -> 0 | J6: ='B5'!AX9/0.51 -> 1.5686275 | K6: =WATER!I10 -> 193 | L6: =SUM(WATER!J10) -> 1.2953368 | M6: =WATER!Q10 -> 0 | N6: 0.6 | O6: =ELEC!B7 -> 0
A7: Beirut | B7: =B6+1 -> 6 | C7: 11 | D7: 2020 | E7: =ELEC!N8 -> 7743.2 | F7: =SUM('EDl log'!T9) -> 0.099338087 | G7: =-tanks!AW11 -> 0 | H7: =SUM(tanks!AV11) -> 0.5 | I7: =('B5'!AU10)*0.51 -> 0 | J7: ='B5'!AX10/0.51 -> 1.5686275 | K7: =WATER!I11 -> 0 | L7: =SUM(WATER!J11) -> 0 | M7: =WATER!Q11 -> 0 | N7: 0.6 | O7: =ELEC!B8 -> 0
A8: Beirut | B8: =B7+1 -> 7 | C8: 11 | D8: 2020 | E8: =ELEC!N9 -> 6591.6 | F8: =SUM('EDl log'!T10) -> 0.080356136 | G8: =-tanks!AW12 -> 238 | H8: =SUM(tanks!AV12) -> 0.5 | I8: =('B5'!AU11)*0.51 -> 0 | J8: ='B5'!AX11/0.51 -> 1.5686275 | K8: =WATER!I12 -> 190 | L8: =SUM(WATER!J12) -> 1.3157895 | M8: =WATER!Q12 -> 0 | N8: 0.6 | O8: =ELEC!B9 -> 0
A9: Beirut | B9: =B8+1 -> 8 | C9: 11 | D9: 2020 | E9: =ELEC!N10 -> 7125.8 | F9: =SUM('EDl log'!T11) -> 0.092226624 | G9: =-tanks!AW13 -> 162 | H9: =SUM(tanks!AV13) -> 0.5 | I9: =('B5'!AU12)*0.51 -> 0 | J9: ='B5'!AX12/0.51 -> 1.5686275 | K9: =WATER!I13 -> 0 | L9: =SUM(WATER!J13) -> 0 | M9: =WATER!Q13 -> 0 | N9: 0.6 | O9: =ELEC!B10 -> 0
A10: Beirut | B10: =B9+1 -> 9 | C10: 11 | D10: 2020 | E10: =ELEC!N11 -> 7376 | F10: =SUM('EDl log'!T12) -> 0.088024448 | G10: =-tanks!AW14 -> 137 | H10: =SUM(tanks!AV14) -> 0.5 | I10: =('B5'!AU13)*0.51 -> 0 | J10: ='B5'!AX13/0.51 -> 1.5686275 | K10: =WATER!I14 -> 191 | L10: =SUM(WATER!J14) -> 1.3089005 | M10: =WATER!Q14 -> 0 | N10: 0.6 | O10: =ELEC!B11 -> 0
A11: Beirut | B11: =B10+1 -> 10 | C11: 11 | D11: 2020 | E11: =ELEC!N12 -> 7892 | F11: =SUM('EDl log'!T13) -> 0.08949042 | G11: =-tanks!AW15 -> 144 | H11: =SUM(tanks!AV15) -> 0.5 | I11: =('B5'!AU14)*0.51 -> 0 | J11: ='B5'!AX14/0.51 -> 1.5686275 | K11: =WATER!I15 -> 0 | L11: =SUM(WATER!J15) -> 0 | M11: =WATER!Q15 -> 0 | N11: 0.6 | O11: =ELEC!B12 -> 0
A12: Beirut | B12: =B11+1 -> 11 | C12: 11 | D12: 2020 | E12: =ELEC!N13 -> 8345 | F12: =SUM('EDl log'!T14) -> 0.077396948 | G12: =-tanks!AW16 -> 162 | H12: =SUM(tanks!AV16) -> 0.5 | I12: =('B5'!AU15)*0.51 -> 0 | J12: ='B5'!AX15/0.51 -> 1.5686275 | K12: =WATER!I16 -> 185 | L12: =SUM(WATER!J16) -> 1.3513514 | M12: =WATER!Q16 -> 0 | N12: 0.6 | O12: =ELEC!B13 -> 0
A13: Beirut | B13: =B12+1 -> 12 | C13: 11 | D13: 2020 | E13: =ELEC!N14 -> 8791 | F13: =SUM('EDl log'!T15) -> 0.08275464 | G13: =-tanks!AW17 -> 244 | H13: =SUM(tanks!AV17) -> 0.5 | I13: =('B5'!AU16)*0.51 -> 0 | J13: ='B5'!AX16/0.51 -> 1.5686275 | K13: =WATER!I17 -> 0 | L13: =SUM(WATER!J17) -> 0 | M13: =WATER!Q17 -> 0 | N13: 0.6 | O13: =ELEC!B14 -> 0
A14: Beirut | B14: =B13+1 -> 13 | C14: 11 | D14: 2020 | E14: =ELEC!N15 -> 8409 | F14: =SUM('EDl log'!T16) -> 0.087717062 | G14: =-tanks!AW18 -> 137 | H14: =SUM(tanks!AV18) -> 0.5 | I14: =('B5'!AU17)*0.51 -> 0 | J14: ='B5'!AX17/0.51 -> 1.5686275 | K14: =WATER!I18 -> 117 | L14: =SUM(WATER!J18) -> 2.1367521 | M14: =WATER!Q18 -> 0 | N14: 0.6 | O14: =ELEC!B15 -> 0
... A31: Beirut | B31: =B30+1 -> 30 | C31: 11 | D31: 2020 | E31: =ELEC!N32 -> 0 | F31: =SUM('EDl log'!T33) -> 0 | G31: =-tanks!AW35 -> 0 | H31: =SUM(tanks!AV35) -> 0.49 | I31: =('B5'!AU34)*0.51 -> 0 | J31: ='B5'!AX34/0.51 -> 1.5686275 | K31: =WATER!I35 -> 0 | L31: =SUM(WATER!J35) -> 0 | M31: =WATER!Q35 -> 0 | N31: 0.6 | O31: =ELEC!B32 -> 0
A32: Beirut

Sheet Submetering
A1: Site Name | B1: Day | C1: Month | D1: Year | E1: ATS1 Kwh | F1: ATS2 Kwh | G1: ATS3 Kwh | H1: ATS4 Kwh | I1: ATS5 Kwh | J1: Guest (m3) | K1: Kitchen & Laundry (m3) | L1: Room Nights
A2: Beirut | B2: 1 | C2: 11 | D2: 2020 | E2: =ELEC!M3 -> 1934 | F2: =ELEC!K3 -> 1146 | G2: =ELEC!I3 -> 844 | H2: =ELEC!E3 -> 3496 | I2: =ELEC!G3 -> 652 | J2: =WATER!Y6 -> 104 | K2: =WATER!AJ6 -> 0 | L2: =ELEC!B3 -> 0
A3: Beirut | B3: =B2+1 -> 2 | C3: 11 | D3: 2020 | E3: =ELEC!M4 -> 2558 | F3: =ELEC!K4 -> 944 | G3: =ELEC!I4 -> 894 | H3: =ELEC!E4 -> 2200 | I3: =ELEC!G4 -> 756 | J3: =WATER!Y7 -> 0 | K3: =WATER!AJ7 -> 0 | L3: =ELEC!B4 -> 0
A4: Beirut | B4: =B3+1 -> 3 | C4: 11 | D4: 2020 | E4: =ELEC!M5 -> 3080 | F4: =ELEC!K5 -> 1166 | G4: =ELEC!I5 -> 924 | H4: =ELEC!E5 -> 2610 | I4: =ELEC!G5 -> 735 | J4: =WATER!Y8 -> 101 | K4: =WATER!AJ8 -> 10 | L4: =ELEC!B5 -> 0
A5: Beirut | B5: =B4+1 -> 4 | C5: 11 | D5: 2020 | E5: =ELEC!M6 -> 2992 | F5: =ELEC!K6 -> 1120 | G5: =ELEC!I6 -> 894 | H5: =ELEC!E6 -> 2366 | I5: =ELEC!G6 -> 784 | J5: =WATER!Y9 -> 74 | K5: =WATER!AJ9 -> 0 | L5: =ELEC!B6 -> 0
A6: Beirut | B6: =B5+1 -> 5 | C6: 11 | D6: 2020 | E6: =ELEC!M7 -> 2876 | F6: =ELEC!K7 -> 984 | G6: =ELEC!I7 -> 846 | H6: =ELEC!E7 -> 2448 | I6: =ELEC!G7 -> 699.4 | J6: =WATER!Y10 -> 0 | K6: =WATER!AJ10 -> 28 | L6: =ELEC!B7 -> 0
A7: Beirut | B7: =B6+1 -> 6 | C7: 11 | D7: 2020 | E7: =ELEC!M8 -> 2688 | F7: =ELEC!K8 -> 996 | G7: =ELEC!I8 -> 788 | H7: =ELEC!E8 -> 2604 | I7: =ELEC!G8 -> 667.2 | J7: =WATER!Y11 -> 64 | K7: =WATER!AJ11 -> 23 | L7: =ELEC!B8 -> 0
A8: Beirut | B8: =B7+1 -> 7 | C8: 11 | D8: 2020 | E8: =ELEC!M9 -> 2208 | F8: =ELEC!K9 -> 860 | G8: =ELEC!I9 -> 780 | H8: =ELEC!E9 -> 2056 | I8: =ELEC!G9 -> 687.6 | J8: =WATER!Y12 -> 40 | K8: =WATER!AJ12 -> 0 | L8: =ELEC!B9 -> 0
A9: Beirut | B9: =B8+1 -> 8 | C9: 11 | D9: 2020 | E9: =ELEC!M10 -> 2412 | F9: =ELEC!K10 -> 940 | G9: =ELEC!I10 -> 818 | H9: =ELEC!E10 -> 2290 | I9: =ELEC!G10 -> 665.8 | J9: =WATER!Y13 -> 0 | K9: =WATER!AJ13 -> 0 | L9: =ELEC!B10 -> 0
A10: Beirut | B10: =B9+1 -> 9 | C10: 11 | D10: 2020 | E10: =ELEC!M11 -> 2168 | F10: =ELEC!K11 -> 960 | G10: =ELEC!I11 -> 828 | H10: =ELEC!E11 -> 2716 | I10: =ELEC!G11 -> 704 | J10: =WATER!Y14 -> 66 | K10: =WATER!AJ14 -> 23 | L10: =ELEC!B11 -> 0
A11: Beirut | B11: =B10+1 -> 10 | C11: 11 | D11: 2020 | E11: =ELEC!M12 -> 2416 | F11: =ELEC!K12 -> 1392 | G11: =ELEC!I12 -> 780 | H11: =ELEC!E12 -> 2638 | I11: =ELEC!G12 -> 666 | J11: =WATER!Y15 -> 66 | K11: =WATER!AJ15 -> 24 | L11: =ELEC!B12 -> 0
A12: Beirut | B12: =B11+1 -> 11 | C12: 11 | D12: 2020 | E12: =ELEC!M13 -> 1820 | F12: =ELEC!K13 -> 2468 | G12: =ELEC!I13 -> 832 | H12: =ELEC!E13 -> 2512 | I12: =ELEC!G13 -> 713 | J12: =WATER!Y16 -> 0 | K12: =WATER!AJ16 -> 0 | L12: =ELEC!B13 -> 0
A13: Beirut | B13: =B12+1 -> 12 | C13: 11 | D13: 2020 | E13: =ELEC!M14 -> 1766 | F13: =ELEC!K14 -> 2864 | G13: =ELEC!I14 -> 870 | H13: =ELEC!E14 -> 2592 | I13: =ELEC!G14 -> 699 | J13: =WATER!Y17 -> 83 | K13: =WATER!AJ17 -> 42 | L13: =ELEC!B14 -> 0
A14: Beirut | B14: =B13+1 -> 13 | C14: 11 | D14: 2020 | E14: =ELEC!M15 -> 1744 | F14: =ELEC!K15 -> 2412 | G14: =ELEC!I15 -> 850 | H14: =ELEC!E15 -> 2752 | I14: =ELEC!G15 -> 651 | J14: =WATER!Y18 -> 0 | K14: =WATER!AJ18 -> 0 | L14: =ELEC!B15 -> 0
... A31: Beirut | B31: =B30+1 -> 30 | C31: 11 | D31: 2020 | E31: =ELEC!M32 -> 0 | F31: =ELEC!K32 -> 0 | G31: =ELEC!I32 -> 0 | H31: =ELEC!E32 -> 0 | I31: =ELEC!G32 -> 0 | J31: =WATER!Y35 -> 0 | K31: =WATER!AJ35 -> 0 | L31: =ELEC!B32 -> 0
A32: Beirut

Sheet ELEC
A1: OOC | B1: Room OCC | D1: MDB3 | E1: MDB3/day | F1: EMDB2 | G1: EMDB2/day | H1: EMDB1 | I1: EMDB1/day | J1: MDB2 | K1: mdb2/day | L1: MDB1 | M1: MDB1/Day | N1: Total KWH | O1: KWH/Rooc | P1: Gen MHW | Q1: Gen/Day KWH | R1: EDL KWH | S1: CH1 RH | T1: RH | U1: C1h1 power | V1: CH1 Con KWH | W1: CH2 RH | X1: RH | Y1: Ch2 power | Z1: CH2 Con KWH | AA1: CH3 RH | AB1: RH | AC1: Ch3 power | AD1: CH3 Con KWH | AE1: RH total | AF1: KWH total | AG1: AVG chiller KW/Hr
A2: =[1]ELEC!$A$33 -> 0 | B2: =[1]ELEC!$B$33 -> 0 | C2: 44135 | D2: =[1]ELEC!D33 -> 32384050 | E2: =[1]ELEC!E33 -> 2720 | F2: =[1]ELEC!F33 -> 3896366 | G2: =[1]ELEC!G33 -> 664 | H2: =[1]ELEC!H33 -> 17701778 | I2: =[1]ELEC!I33 -> 884 | J2: =[1]ELEC!J33 -> 28760594 | K2: =[1]ELEC!K33 -> 1408 | ... AL2: =[1]ELEC!AL33 -> 0
A3: ='General information '!F6 -> 0 | B3: =SUM(230*A3) -> 0 | C3: 44136 | D3: 32387546 | E3: =D3-D2 -> 3496 | F3: 3897018 | G3: =F3-F2 -> 652 | H3: 17702622 | I3: =H3-H2 -> 844 | J3: 28761740 | K3: =J3-J2 -> 1146 | L3: 23807624 | M3: =L3-L2 -> 1934 | N3: =M3+K3+I3+G3+E3 -> 8072 | O3: =IF(B3>0,N3/B3,0) -> 0 | P3: 16405 | Q3: =(P3-P2)*1000 -> 2000 | R3: =+N3-Q3 -> 6072 | S3: 9960 | T3: =S3-S2 -> 2 | U3: 392023 | V3: =U3-U2 -> 571 | W3: 32049 | X3: =W3-W2 -> 0 | Y3: =Y2 -> 673052 | Z3: =Y3-Y2 -> 0 | AA3: 35632 | AB3: =AA3-AA2 -> 4 | AC3: 905341 | AD3: =AC3-AC2 -> 1045 | AE3: =AB3+X3+T3 -> 6 | AF3: =V3+Z3+AD3 -> 1616 | AG3: =IF(AE3>0,AF3/AE3,0) -> 269.33333
A4: ='General information '!F7 -> 0 | B4: =SUM(230*A4) -> 0 | C4: 44137 | D4: 32389746 | E4: =D4-D3 -> 2200 | F4: 3897774 | G4: =F4-F3 -> 756 | H4: 17703516 | I4: =H4-H3 -> 894 | J4: 28762684 | K4: =J4-J3 -> 944 | L4: 23810182 | M4: =L4-L3 -> 2558 | N4: =M4+K4+I4+G4+E4 -> 7352 | O4: =IF(B4>0,N4/B4,0) -> 0 | P4: =P3 -> 16405 | Q4: =(P4-P3)*1000 -> 0 | R4: =N4-Q4 -> 7352 | S4: 9963 | T4: =S4-S3 -> 3 | U4: 392986 | V4: =U4-U3 -> 963 | W4: =W3 -> 32049 | X4: =W4-W3 -> 0 | Y4: =Y3 -> 673052 | Z4: =Y4-Y3 -> 0 | AA4: =AA3 -> 35632 | AB4: =AA4-AA3 -> 0 | AC4: =AC3 -> 905341 | AD4: =AC4-AC3 -> 0 | AE4: =AB4+X4+T4 -> 3 | AF4: =V4+Z4+AD4 -> 963 | AG4: =IF(AE4>0,AF4/AE4,0) -> 321
A5: ='General information '!F8 -> 0 | B5: =SUM(230*A5) -> 0 | C5: 44138 | D5: 32392356 | E5: =D5-D4 -> 2610 | F5: 3898509 | G5: =F5-F4 -> 735 | H5: 17704440 | I5: =H5-H4 -> 924 | J5: 28763850 | K5: =J5-J4 -> 1166 | L5: 23813262 | M5: =L5-L4 -> 3080 | N5: =M5+K5+I5+G5+E5 -> 8515 | O5: =IF(B5>0,N5/B5,0) -> 0 | P5: 16407 | Q5: =(P5-P4)*1000 -> 2000 | R5: =N5-Q5 -> 6515 | S5: 9971 | T5: =S5-S4 -> 8 | U5: =U4 -> 392986 | V5: =U5-U4 -> 0 | W5: =W4 -> 32049 | X5: =W5-W4 -> 0 | Y5: =Y4 -> 673052 | Z5: =Y5-Y4 -> 0 | AA5: =AA4 -> 35632 | AB5: =AA5-AA4 -> 0 | AC5: =AC4 -> 905341 | AD5: =AC5-AC4 -> 0 | AE5: =AB5+X5+T5 -> 8 | AF5: =V5+Z5+AD5 -> 0 | AG5: =IF(AE5>0,AF5/AE5,0) -> 0 | AI5: =R5-'EDl log'!B3 -> -595675
A6: ='General information '!F9 -> 0 | B6: =SUM(230*A6) -> 0 | C6: 44139 | D6: 32394722 | E6: =D6-D5 -> 2366 | F6: 3899293 | G6: =F6-F5 -> 784 | H6: 17705334 | I6: =H6-H5 -> 894 | J6: 28764970 | K6: =J6-J5 -> 1120 | L6: 23816254 | M6: =L6-L5 -> 2992 | N6: =M6+K6+I6+G6+E6 -> 8156 | O6: =IF(B6>0,N6/B6,0) -> 0 | P6: 16409 | Q6: =(P6-P5)*1000 -> 2000 | R6: =N6-Q6 -> 6156 | S6: 9976 | T6: =S6-S5 -> 5 | U6: 395262 | V6: =U6-U5 -> 2276 | W6: =W5 -> 32049 | X6: =W6-W5 -> 0 | Y6: =Y5 -> 673052 | Z6: =Y6-Y5 -> 0 | AA6: =AA5 -> 35632 | AB6: =AA6-AA5 -> 0 | AC6: =AC5 -> 905341 | AD6: =AC6-AC5 -> 0 | AE6: =AB6+X6+T6 -> 5 | AF6: =V6+Z6+AD6 -> 2276 | AG6: =IF(AE6>0,AF6/AE6,0) -> 455.2 | AI6: =R6-'EDl log'!B4 -> -599465
A7: ='General information '!F10 -> 0 | B7: =SUM(230*A7) -> 0 | C7: 44140 | D7: 32397170 | E7: =D7-D6 -> 2448 | F7: 3899992.4 | G7: =F7-F6 -> 699.4 | H7: 17706180 | I7: =H7-H6 -> 846 | J7: 28765954 | K7: =J7-J6 -> 984 | L7: 23819130 | M7: =L7-L6 -> 2876 | N7: =M7+K7+I7+G7+E7 -> 7853.4 | O7: =IF(B7>0,N7/B7,0) -> 0 | P7: 16410 | Q7: =(P7-P6)*1000 -> 1000 | R7: =N7-Q7 -> 6853.4 | S7: 9982 | T7: =S7-S6 -> 6 | U7: 396340 | V7: =U7-U6 -> 1078 | W7: =W6 -> 32049 | X7: =W7-W6 -> 0 | Y7: =Y6 -> 673052 | Z7: =Y7-Y6 -> 0 | AA7: =AA6 -> 35632 | AB7: =AA7-AA6 -> 0 | AC7: =AC6 -> 905341 | AD7: =AC7-AC6 -> 0 | AE7: =AB7+X7+T7 -> 6 | AF7: =V7+Z7+AD7 -> 1078 | AG7: =IF(AE7>0,AF7/AE7,0) -> 179.66667 | AI7: =R7-'EDl log'!B5 -> -602619.6
A8: ='General information '!F11 -> 0 | B8: =SUM(230*A8) -> 0 | C8: 44141 | D8: 32399774 | E8: =D8-D7 -> 2604 | F8: 3900659.6 | G8: =F8-F7 -> 667.2 | H8: 17706968 | I8: =H8-H7 -> 788 | J8: 28766950 | K8: =J8-J7 -> 996 | L8: 23821818 | M8: =L8-L7 -> 2688 | N8: =M8+K8+I8+G8+E8 -> 7743.2 | O8: =IF(B8>0,N8/B8,0) -> 0 | P8: 16412 | Q8: =(P8-P7)*1000 -> 2000 | R8: =N8-Q8 -> 5743.2 | S8: 9987 | T8: =S8-S7 -> 5 | U8: 397254 | V8: =U8-U7 -> 914 | W8: =W7 -> 32049 | X8: =W8-W7 -> 0 | Y8: =Y7 -> 673052 | Z8: =Y8-Y7 -> 0 | AA8: =AA7 -> 35632 | AB8: =AA8-AA7 -> 0 | AC8: =AC7 -> 905341 | AD8: =AC8-AC7 -> 0 | AE8: =AB8+X8+T8 -> 5 | AF8: =V8+Z8+AD8 -> 914 | AG8: =IF(AE8>0,AF8/AE8,0) -> 182.8 | AI8: =R8-'EDl log'!B6 -> -607268.8
A9: ='General information '!F12 -> 0 | B9: =SUM(230*A9) -> 0 | C9: 44142 | D9: 32401830 | E9: =D9-D8 -> 2056 | F9: 3901347.2 | G9: =F9-F8 -> 687.6 | H9: 17707748 | I9: =H9-H8 -> 780 | J9: 28767810 | K9: =J9-J8 -> 860 | L9: 23824026 | M9: =L9-L8 -> 2208 | N9: =M9+K9+I9+G9+E9 -> 6591.6 | O9: =IF(B9>0,N9/B9,0) -> 0 | P9: 16412 | Q9: =(P9-P8)*1000 -> 0 | R9: =N9-Q9 -> 6591.6 | S9: 9990 | T9: =S9-S8 -> 3 | U9: 397917 | V9: =U9-U8 -> 663 | W9: =W8 -> 32049 | X9: =W9-W8 -> 0 | Y9: =Y8 -> 673052 | Z9: =Y9-Y8 -> 0 | AA9: =AA8 -> 35632 | AB9: =AA9-AA8 -> 0 | AC9: =AC8 -> 905341 | AD9: =AC9-AC8 -> 0 | AE9: =AB9+X9+T9 -> 3 | AF9: =V9+Z9+AD9 -> 663 | AG9: =IF(AE9>0,AF9/AE9,0) -> 221 | AI9: =R9-'EDl log'!B7 -> -609779.4
A10: ='General information '!F13 -> 0 | B10: =SUM(230*A10) -> 0 | C10: 44143 | D10: 32404120 | E10: =D10-D9 -> 2290 | F10: 3902013 | G10: =F10-F9 -> 665.8 | H10: 17708566 | I10: =H10-H9 -> 818 | J10: 28768750 | K10: =J10-J9 -> 940 | L10: 23826438 | M10: =L10-L9 -> 2412 | N10: =M10+K10+I10+G10+E10 -> 7125.8 | O10: =IF(B10>0,N10/B10,0) -> 0 | P10: 16414 | Q10: =(P10-P9)*1000 -> 2000 | R10: =N10-Q10 -> 5125.8 | S10: 9995 | T10: =S10-S9 -> 5 | U10: 398801 | V10: =U10-U9 -> 884 | W10: 32049 | X10: =W10-W9 -> 0 | Y10: =Y9 -> 673052 | Z10: =Y10-Y9 -> 0 | AA10: 35632 | AB10: =AA10-AA9 -> 0 | AC10: 905341 | AD10: =AC10-AC9 -> 0 | AE10: =AB10+X10+T10 -> 5 | AF10: =V10+Z10+AD10 -> 884 | AG10: =IF(AE10>0,AF10/AE10,0) -> 176.8 | AI10: =R10-'EDl log'!B8 -> -614554.2
A11: ='General information '!F14 -> 0 | B11: =SUM(230*A11) -> 0 | C11: 44144 | D11: 32406836 | E11: =D11-D10 -> 2716 | F11: 3902717 | G11: =F11-F10 -> 704 | H11: 17709394 | I11: =H11-H10 -> 828 | J11: 28769710 | K11: =J11-J10 -> 960 | L11: 23828606 | M11: =L11-L10 -> 2168 | N11: =M11+K11+I11+G11+E11 -> 7376 | O11: =IF(B11>0,N11/B11,0) -> 0 | P11: 16415 | Q11: =(P11-P10)*1000 -> 1000 | R11: =N11-Q11 -> 6376 | S11: 9998 | T11: =S11-S10 -> 3 | U11: 399403 | V11: =U11-U10 -> 602 | W11: =W10 -> 32049 | X11: =W11-W10 -> 0 | Y11: =Y10 -> 673052 | Z11: =Y11-Y10 -> 0 | AA11: 35634 | AB11: =AA11-AA10 -> 2 | AC11: 905726 | AD11: =AC11-AC10 -> 385 | AE11: =AB11+X11+T11 -> 5 | AF11: =V11+Z11+AD11 -> 987 | AG11: =IF(AE11>0,AF11/AE11,0) -> 197.4 | AI11: =R11-'EDl log'!B9 -> -616616
A12: ='General information '!F15 -> 0 | B12: =SUM(230*A12) -> 0 | C12: 44145 | D12: 32409474 | E12: =D12-D11 -> 2638 | F12: 3903383 | G12: =F12-F11 -> 666 | H12: 17710174 | I12: =H12-H11 -> 780 | J12: 28771102 | K12: =J12-J11 -> 1392 | L12: 23831022 | M12: =L12-L11 -> 2416 | N12: =M12+K12+I12+G12+E12 -> 7892 | O12: =IF(B12>0,N12/B12,0) -> 0 | P12: 16416 | Q12: =(P12-P11)*1000 -> 1000 | R12: =N12-Q12 -> 6892 | S12: 10003 | T12: =S12-S11 -> 5 | U12: 400271 | V12: =U12-U11 -> 868 | W12: =W11 -> 32049 | X12: =W12-W11 -> 0 | Y12: =Y11 -> 673052 | Z12: =Y12-Y11 -> 0 | AA12: =AA11 -> 35634 | AB12: =AA12-AA11 -> 0 | AC12: =AC11 -> 905726 | AD12: =AC12-AC11 -> 0 | AE12: =AB12+X12+T12 -> 5 | AF12: =V12+Z12+AD12 -> 868 | AG12: =IF(AE12>0,AF12/AE12,0) -> 173.6 | AI12: =R12-'EDl log'!B10 -> -619155
A13: ='General information '!F16 -> 0 | B13: =SUM(230*A13) -> 0 | C13: 44146 | D13: 32411986 | E13: =D13-D12 -> 2512 | F13: 3904096 | G13: =F13-F12 -> 713 | H13: 17711006 | I13: =H13-H12 -> 832 | J13: 28773570 | K13: =J13-J12 -> 2468 | L13: 23832842 | M13: =L13-L12 -> 1820 | N13: =M13+K13+I13+G13+E13 -> 8345 | O13: =IF(B13>0,N13/B13,0) -> 0 | P13: 16417 | Q13: =(P13-P12)*1000 -> 1000 | R13: =N13-Q13 -> 7345 | S13: =S12 -> 10003 | T13: =S13-S12 -> 0 | U13: =U12 -> 400271 | V13: =U13-U12 -> 0 | W13: 32057 | X13: =W13-W12 -> 8 | Y13: 674517 | Z13: =Y13-Y12 -> 1465 | AA13: =AA12 -> 35634 | AB13: =AA13-AA12 -> 0 | AC13: =AC12 -> 905726 | AD13: =AC13-AC12 -> 0 | AE13: =AB13+X13+T13 -> 8 | AF13: =V13+Z13+AD13 -> 1465 | AG13: =IF(AE13>0,AF13/AE13,0) -> 183.125 | AI13: =R13-'EDl log'!B11 -> -621680
A14: ='General information '!F17 -> 0 | B14: =SUM(230*A14) -> 0 | C14: 44147 | D14: 32414578 | E14: =D14-D13 -> 2592 | F14: 3904795 | G14: =F14-F13 -> 699 | H14: 17711876 | I14: =H14-H13 -> 870 | J14: 28776434 | K14: =J14-J13 -> 2864 | L14: 23834608 | M14: =L14-L13 -> 1766 | N14: =M14+K14+I14+G14+E14 -> 8791 | O14: =IF(B14>0,N14/B14,0) -> 0 | P14: 16419 | Q14: =(P14-P13)*1000 -> 2000 | R14: =N14-Q14 -> 6791 | S14: 10003 | T14: =S14-S13 -> 0 | U14: =U13 -> 400271 | V14: =U14-U13 -> 0 | W14: 32064 | X14: =W14-W13 -> 7 | Y14: 675980 | Z14: =Y14-Y13 -> 1463 | AA14: 35634 | AB14: =AA14-AA13 -> 0 | AC14: 905726 | AD14: =AC14-AC13 -> 0 | AE14: =AB14+X14+T14 -> 7 | AF14: =V14+Z14+AD14 -> 1463 | AG14: =IF(AE14>0,AF14/AE14,0) -> 209 | AI14: =R14-'EDl log'!B12 -> -625529
A15: ='General information '!F18 -> 0 | B15: =SUM(230*A15) -> 0 | C15: 44148 | D15: 32417330 | E15: =D15-D14 -> 2752 | F15: 3905446 | G15: =F15-F14 -> 651 | H15: 17712726 | I15: =H15-H14 -> 850 | J15: 28778846 | K15: =J15-J14 -> 2412 | L15: 23836352 | M15: =L15-L14 -> 1744 | N15: =M15+K15+I15+G15+E15 -> 8409 | O15: =IF(B15>0,N15/B15,0) -> 0 | P15: 16420 | Q15: =(P15-P14)*1000 -> 1000 | R15: =N15-Q15 -> 7409 | S15: =S14 -> 10003 | T15: =S15-S14 -> 0 | U15: =U14 -> 400271 | V15: =U15-U14 -> 0 | W15: 32069 | X15: =W15-W14 -> 5 | Y15: 677178 | Z15: =Y15-Y14 -> 1198 | AA15: =AA14 -> 35634 | AB15: =AA15-AA14 -> 0 | AC15: =AC14 -> 905726 | AD15: =AC15-AC14 -> 0 | AE15: =AB15+X15+T15 -> 5 | AF15: =V15+Z15+AD15 -> 1198 | AG15: =IF(AE15>0,AF15/AE15,0) -> 239.6 | AI15: =R15-'EDl log'!B13 -> -628601
A16: ='General information '!F19 -> 0 | B16: =SUM(230*A16) -> 0 | C16: 44149 | D16: 32420022 | E16: =D16-D15 -> 2692 | F16: 3906171 | G16: =F16-F15 -> 725 | H16: 17713658 | I16: =H16-H15 -> 932 | J16: 28781474 | K16: =J16-J15 -> 2628 | L16: 23838222 | M16: =L16-L15 -> 1870 | N16: =M16+K16+I16+G16+E16 -> 8847 | O16: =IF(B16>0,N16/B16,0) -> 0 | P16: 16421 | Q16: =(P16-P15)*1000 -> 1000 | R16: =N16-Q16 -> 7847 | S16: =S15 -> 10003 | T16: =S16-S15 -> 0 | U16: =U15 -> 400271 | V16: =U16-U15 -> 0 | W16: 32073 | X16: =W16-W15 -> 4 | Y16: 677987 | Z16: =Y16-Y15 -> 809 | AA16: =AA15 -> 35634 | AB16: =AA16-AA15 -> 0 | AC16: =AC15 -> 905726 | AD16: =AC16-AC15 -> 0 | AE16: =AB16+X16+T16 -> 4 | AF16: =V16+Z16+AD16 -> 809 | AG16: =IF(AE16>0,AF16/AE16,0) -> 202.25 | AI16: =R16-'EDl log'!B14 -> -631807
A17: ='General information '!F20 -> 0 | B17: =SUM(230*A17) -> 0 | C17: 44150 | D17: 32421782 | E17: =D17-D16 -> 1760 | F17: 3906733 | G17: =F17-F16 -> 562 | H17: 17714344 | I17: =H17-H16 -> 686 | J17: 28782490 | K17: =J17-J16 -> 1016 | L17: 23839940 | M17: =L17-L16 -> 1718 | N17: =M17+K17+I17+G17+E17 -> 5742 | O17: =IF(B17>0,N17/B17,0) -> 0 | P17: 16422 | Q17: =(P17-P16)*1000 -> 1000 | R17: =N17-Q17 -> 4742 | S17: 10003 | T17: =S17-S16 -> 0 | U17: =U16 -> 400271 | V17: =U17-U16 -> 0 | W17: 32076 | X17: =W17-W16 -> 3 | Y17: 678759 | Z17: =Y17-Y16 -> 772 | AA17: =AA16 -> 35634 | AB17: =AA17-AA16 -> 0 | AC17: =AC16 -> 905726 | AD17: =AC17-AC16 -> 0 | AE17: =AB17+X17+T17 -> 3 | AF17: =V17+Z17+AD17 -> 772 | AG17: =IF(AE17>0,AF17/AE17,0) -> 257.33333 | AI17: =R17-'EDl log'!B15 -> -638797
A18: ='General information '!F21 -> 0 | B18: =SUM(230*A18) -> 0 | C18: 44151 | D18: 32424010 | E18: =D18-D17 -> 2228 | F18: 3907550 | G18: =F18-F17 -> 817 | H18: 17715166 | I18: =H18-H17 -> 822 | J18: 28785078 | K18: =J18-J17 -> 2588 | L18: 23842010 | M18: =L18-L17 -> 2070 | N18: =M18+K18+I18+G18+E18 -> 8525 | O18: =IF(B18>0,N18/B18,0) -> 0 | P18: 16423 | Q18: =(P18-P17)*1000 -> 1000 | R18: =N18-Q18 -> 7525 | S18: =S17 -> 10003 | T18: =S18-S17 -> 0 | U18: =U17 -> 400271 | V18: =U18-U17 -> 0 | W18: 32084 | X18: =W18-W17 -> 8 | Y18: 680076 | Z18: =Y18-Y17 -> 1317 | AA18: =AA17 -> 35634 | AB18: =AA18-AA17 -> 0 | AC18: =AC17 -> 905726 | AD18: =AC18-AC17 -> 0 | AE18: =AB18+X18+T18 -> 8 | AF18: =V18+Z18+AD18 -> 1317 | AG18: =IF(AE18>0,AF18/AE18,0) -> 164.625 | AI18: =R18-'EDl log'!B16 -> -639660
A19: ='General information '!F22 -> 0 | B19: =SUM(230*A19) -> 0 | C19: 44152 | D19: 32426106 | E19: =D19-D18 -> 2096 | F19: 3908207 | G19: =F19-F18 -> 657 | H19: 17715956 | I19: =H19-H18 -> 790 | J19: 28787096 | K19: =J19-J18 -> 2018 | L19: 23843998 | M19: =L19-L18 -> 1988 | N19: =M19+K19+I19+G19+E19 -> 7549 | O19: =IF(B19>0,N19/B19,0) -> 0 | P19: 16425 | Q19: =(P19-P18)*1000 -> 2000 | R19: =N19-Q19 -> 5549 | S19: 10003 | T19: =S19-S18 -> 0 | U19: =U18 -> 400271 | V19: =U19-U18 -> 0 | W19: 32089 | X19: =W19-W18 -> 5 | Y19: 681018 | Z19: =Y19-Y18 -> 942 | AA19: =AA18 -> 35634 | AB19: =AA19-AA18 -> 0 | AC19: =AC18 -> 905726 | AD19: =AC19-AC18 -> 0 | AE19: =AB19+X19+T19 -> 5 | AF19: =V19+Z19+AD19 -> 942 | AG19: =IF(AE19>0,AF19/AE19,0) -> 188.4 | AI19: =R19-'EDl log'!B17 -> -645820
A20: ='General information '!F23 -> 0 | B20: =SUM(230*A20) -> 0 | C20: 44153 | D20: 32428534 | E20: =D20-D19 -> 2428 | F20: 3908916 | G20: =F20-F19 -> 709 | H20: 17716882 | I20: =H20-H19 -> 926 | J20: 28789446 | K20: =J20-J19 -> 2350 | L20: 23845990 | M20: =L20-L19 -> 1992 | N20: =M20+K20+I20+G20+E20 -> 8405 | O20: =IF(B20>0,N20/B20,0) -> 0 | P20: 16425.649 | Q20: =(P20-P19)*1000 -> 649 | R20: =N20-Q20 -> 7756 | S20: =S19 -> 10003 | T20: =S20-S19 -> 0 | U20: =U19 -> 400271 | V20: =U20-U19 -> 0 | W20: 32093 | X20: =W20-W19 -> 4 | Y20: 682060 | Z20: =Y20-Y19 -> 1042 | AA20: =AA19 -> 35634 | AB20: =AA20-AA19 -> 0 | AC20: =AC19 -> 905726 | AD20: =AC20-AC19 -> 0 | AE20: =AB20+X20+T20 -> 4 | AF20: =V20+Z20+AD20 -> 1042 | AG20: =IF(AE20>0,AF20/AE20,0) -> 260.5 | AI20: =R20-'EDl log'!B18 -> -646087
A21: ='General information '!F24 -> 0 | B21: =SUM(230*A21) -> 0 | C21: 44154 | D21: 32430898 | E21: =D21-D20 -> 2364 | F21: 3909585 | G21: =F21-F20 -> 669 | H21: 17717680 | I21: =H21-H20 -> 798 | J21: 28791668 | K21: =J21-J20 -> 2222 | L21: 23847694 | M21: =L21-L20 -> 1704 | N21: =M21+K21+I21+G21+E21 -> 7757 | O21: =IF(B21>0,N21/B21,0) -> 0 | P21: 16426.989 | Q21: =(P21-P20)*1000 -> 1340 | R21: =N21-Q21 -> 6417 | S21: =S20 -> 10003 | T21: =S21-S20 -> 0 | U21: =U20 -> 400271 | V21: =U21-U20 -> 0 | W21: 32099 | X21: =W21-W20 -> 6 | Y21: 683094 | Z21: =Y21-Y20 -> 1034 | AA21: =AA20 -> 35634 | AB21: =AA21-AA20 -> 0 | AC21: =AC20 -> 905726 | AD21: =AC21-AC20 -> 0 | AE21: =AB21+X21+T21 -> 6 | AF21: =V21+Z21+AD21 -> 1034 | AG21: =IF(AE21>0,AF21/AE21,0) -> 172.33333 | AI21: =R21-'EDl log'!B19 -> -651270
A22: ='General information '!F25 -> 0 | B22: =SUM(230*A22) -> 0 | C22: 44155 | D22: 32433444 | E22: =D22-D21 -> 2546 | F22: 3910254 | G22: =F22-F21 -> 669 | H22: 17718520 | I22: =H22-H21 -> 840 | J22: 28793966 | K22: =J22-J21 -> 2298 | L22: 23849496 | M22: =L22-L21 -> 1802 | N22: =M22+K22+I22+G22+E22 -> 8155 | O22: =IF(B22>0,N22/B22,0) -> 0 | P22: 16428.392 | Q22: =(P22-P21)*1000 -> 1403 | R22: =N22-Q22 -> 6752 | S22: =S21 -> 10003 | T22: =S22-S21 -> 0 | U22: =U21 -> 400271 | V22: =U22-U21 -> 0 | W22: 32103 | X22: =W22-W21 -> 4 | Y22: 683944 | Z22: =Y22-Y21 -> 850 | AA22: =AA21 -> 35634 | AB22: =AA22-AA21 -> 0 | AC22: =AC21 -> 905726 | AD22: =AC22-AC21 -> 0 | AE22: =AB22+X22+T22 -> 4 | AF22: =V22+Z22+AD22 -> 850 | AG22: =IF(AE22>0,AF22/AE22,0) -> 212.5 | AI22: =R22-'EDl log'!B20 -> -654451
A23: ='General information '!F26 -> 0 | B23: =SUM(230*A23) -> 0 | C23: 44156 | D23: 32435430 | E23: =D23-D22 -> 1986 | F23: 3910857 | G23: =F23-F22 -> 603 | H23: 17719320 | I23: =H23-H22 -> 800 | J23: 28795322 | K23: =J23-J22 -> 1356 | L23: 23851314 | M23: =L23-L22 -> 1818 | N23: =M23+K23+I23+G23+E23 -> 6563 | O23: =IF(B23>0,N23/B23,0) -> 0 | P23: 16429.02 | Q23: =(P23-P22)*1000 -> 628 | R23: =N23-Q23 -> 5935 | S23: =S22 -> 10003 | T23: =S23-S22 -> 0 | U23: =U22 -> 400271 | V23: =U23-U22 -> 0 | W23: 32105 | X23: =W23-W22 -> 2 | Y23: 684442 | Z23: =Y23-Y22 -> 498 | AA23: =AA22 -> 35634 | AB23: =AA23-AA22 -> 0 | AC23: =AC22 -> 905726 | AD23: =AC23-AC22 -> 0 | AE23: =AB23+X23+T23 -> 2 | AF23: =V23+Z23+AD23 -> 498 | AG23: =IF(AE23>0,AF23/AE23,0) -> 249 | AI23: =R23-'EDl log'!B21 -> -659104
A24: ='General information '!F27 -> 0 | B24: =SUM(230*A24) -> 0 | C24: 44157 | D24: 32437858 | E24: =D24-D23 -> 2428 | F24: 3911443 | G24: =F24-F23 -> 586 | H24: 17720070 | I24: =H24-H23 -> 750 | J24: 28796310 | K24: =J24-J23 -> 988 | L24: 23853678 | M24: =L24-L23 -> 2364 | N24: =M24+K24+I24+G24+E24 -> 7116 | O24: =IF(B24>0,N24/B24,0) -> 0 | P24: 16429.02 | Q24: =(P24-P23)*1000 -> 0 | R24: =N24-Q24 -> 7116 | S24: 10006 | T24: =S24-S23 -> 3 | U24: 400936 | V24: =U24-U23 -> 665 | W24: 32105 | X24: =W24-W23 -> 0 | Y24: =Y23 -> 684442 | Z24: =Y24-Y23 -> 0 | AA24: =AA23 -> 35634 | AB24: =AA24-AA23 -> 0 | AC24: =AC23 -> 905726 | AD24: =AC24-AC23 -> 0 | AE24: =AB24+X24+T24 -> 3 | AF24: =V24+Z24+AD24 -> 665 | AG24: =IF(AE24>0,AF24/AE24,0) -> 221.66667 | AI24: =R24-'EDl log'!B22 -> -661317
A25: ='General information '!F28 -> 0 | B25: =SUM(230*A25) -> 0 | C25: 44158 | D25: 32440574 | E25: =D25-D24 -> 2716 | F25: 3912110 | G25: =F25-F24 -> 667 | H25: 17720954 | I25: =H25-H24 -> 884 | J25: 28798346 | K25: =J25-J24 -> 2036 | L25: 23855784 | M25: =L25-L24 -> 2106 | N25: =M25+K25+I25+G25+E25 -> 8409 | O25: =IF(B25>0,N25/B25,0) -> 0 | P25: 16430.715 | Q25: =(P25-P24)*1000 -> 1695 | R25: =N25-Q25 -> 6714 | S25: =S24 -> 10006 | T25: =S25-S24 -> 0 | U25: =U24 -> 400936 | V25: =U25-U24 -> 0 | W25: 32109 | X25: =W25-W24 -> 4 | Y25: 685162 | Z25: =Y25-Y24 -> 720 | AA25: =AA24 -> 35634 | AB25: =AA25-AA24 -> 0 | AC25: =AC24 -> 905726 | AD25: =AC25-AC24 -> 0 | AE25: =AB25+X25+T25 -> 4 | AF25: =V25+Z25+AD25 -> 720 | AG25: =IF(AE25>0,AF25/AE25,0) -> 180 | AI25: =R25-'EDl log'!B23 -> -665208
A26: ='General information '!F29 -> 0 | B26: =SUM(230*A26) -> 0 | C26: 44159 | D26: 32442562 | E26: =D26-D25 -> 1988 | F26: 3912645 | G26: =F26-F25 -> 535 | H26: 17721626 | I26: =H26-H25 -> 672 | J26: 28799946 | K26: =J26-J25 -> 1600 | L26: 23857174 | M26: =L26-L25 -> 1390 | N26: =M26+K26+I26+G26+E26 -> 6185 | O26: =IF(B26>0,N26/B26,0) -> 0 | P26: 16432.079 | Q26: =(P26-P25)*1000 -> 1364 | R26: =N26-Q26 -> 4821 | S26: =S25 -> 10006 | T26: =S26-S25 -> 0 | U26: =U25 -> 400936 | V26: =U26-U25 -> 0 | W26: 32112 | X26: =W26-W25 -> 3 | Y26: 685785 | Z26: =Y26-Y25 -> 623 | AA26: =AA25 -> 35634 | AB26: =AA26-AA25 -> 0 | AC26: =AC25 -> 905726 | AD26: =AC26-AC25 -> 0 | AE26: =AB26+X26+T26 -> 3 | AF26: =V26+Z26+AD26 -> 623 | AG26: =IF(AE26>0,AF26/AE26,0) -> 207.66667 | AI26: =R26-'EDl log'!B24 -> -670294
A27: ='General information '!F30 -> 0 | B27: =SUM(230*A27) -> 0 | C27: 44160 | D27: 32445110 | E27: =D27-D26 -> 2548 | F27: 3913385 | G27: =F27-F26 -> 740 | H27: 17722464 | I27: =H27-H26 -> 838 | J27: 28802008 | K27: =J27-J26 -> 2062 | L27: 23858882 | M27: =L27-L26 -> 1708 | N27: =M27+K27+I27+G27+E27 -> 7896 | O27: =IF(B27>0,N27/B27,0) -> 0 | P27: 16433.6 | Q27: =(P27-P26)*1000 -> 1521 | R27: =N27-Q27 -> 6375 | S27: =S26 -> 10006 | T27: =S27-S26 -> 0 | U27: =U26 -> 400936 | V27: =U27-U26 -> 0 | W27: 32116 | X27: =W27-W26 -> 4 | Y27: 686833 | Z27: =Y27-Y26 -> 1048 | AA27: =AA26 -> 35634 | AB27: =AA27-AA26 -> 0 | AC27: =AC26 -> 905726 | AD27: =AC27-AC26 -> 0 | AE27: =AB27+X27+T27 -> 4 | AF27: =V27+Z27+AD27 -> 1048 | AG27: =IF(AE27>0,AF27/AE27,0) -> 262 | AI27: =R27-'EDl log'!B25 -> -672475
A28: ='General information '!F31 -> 0 | B28: =SUM(230*A28) -> 0 | C28: 44161 | D28: 32447302 | E28: =D28-D27 -> 2192 | F28: 3914064 | G28: =F28-F27 -> 679 | H28: 17723222 | I28: =H28-H27 -> 758 | J28: 28803336 | K28: =J28-J27 -> 1328 | L28: 23860522 | M28: =L28-L27 -> 1640 | N28: =M28+K28+I28+G28+E28 -> 6597 | O28: =IF(B28>0,N28/B28,0) -> 0 | P28: 16434.734 | Q28: =(P28-P27)*1000 -> 1134 | R28: =N28-Q28 -> 5463 | S28: =S27 -> 10006 | T28: =S28-S27 -> 0 | U28: =U27 -> 400936 | V28: =U28-U27 -> 0 | W28: 32119 | X28: =W28-W27 -> 3 | Y28: 687201 | Z28: =Y28-Y27 -> 368 | AA28: =AA27 -> 35634 | AB28: =AA28-AA27 -> 0 | AC28: =AC27 -> 905726 | AD28: =AC28-AC27 -> 0 | AE28: =AB28+X28+T28 -> 3 | AF28: =V28+Z28+AD28 -> 368 | AG28: =IF(AE28>0,AF28/AE28,0) -> 122.66667 | AI28: =R28-'EDl log'!B26 -> -676920
A29: ='General information '!F32 -> 0 | B29: =SUM(230*A29) -> 0 | C29: 44162 | D29: =D28 -> 32447302 | E29: =D29-D28 -> 0 | F29: =F28 -> 3914064 | G29: =F29-F28 -> 0 | H29: =H28 -> 17723222 | I29: =H29-H28 -> 0 | J29: =J28 -> 28803336 | K29: =J29-J28 -> 0 | L29: =L28 -> 23860522 | M29: =L29-L28 -> 0 | N29: =M29+K29+I29+G29+E29 -> 0 | O29: =IF(B29>0,N29/B29,0) -> 0 | P29: =P28 -> 16434.734 | Q29: =(P29-P28)*1000 -> 0 | R29: =N29-Q29 -> 0 | S29: =S28 -> 10006 | T29: =S29-S28 -> 0 | U29: =U28 -> 400936 | V29: =U29-U28 -> 0 | W29: =W28 -> 32119 | X29: =W29-W28 -> 0 | Y29: =Y28 -> 687201 | Z29: =Y29-Y28 -> 0 | AA29: =AA28 -> 35634 | AB29: =AA29-AA28 -> 0 | AC29: =AC28 -> 905726 | AD29: =AC29-AC28 -> 0 | AE29: =AB29+X29+T29 -> 0 | AF29: =V29+Z29+AD29 -> 0 | AG29: =IF(AE29>0,AF29/AE29,0) -> 0 | AI29: =R29-'EDl log'!B27 -> -684952
A30: ='General information '!F33 -> 0 | B30: =SUM(230*A30) -> 0 | C30: 44163 | D30: =D29 -> 32447302 | E30: =D30-D29 -> 0 | F30: =F29 -> 3914064 | G30: =F30-F29 -> 0 | H30: =H29 -> 17723222 | I30: =H30-H29 -> 0 | J30: =J29 -> 28803336 | K30: =J30-J29 -> 0 | L30: =L29 -> 23860522 | M30: =L30-L29 -> 0 | N30: =M30+K30+I30+G30+E30 -> 0 | O30: =IF(B30>0,N30/B30,0) -> 0 | P30: =P29 -> 16434.734 | Q30: =(P30-P29)*1000 -> 0 | R30: =N30-Q30 -> 0 | S30: =S29 -> 10006 | T30: =S30-S29 -> 0 | U30: =U29 -> 400936 | V30: =U30-U29 -> 0 | W30: =W29 -> 32119 | X30: =W30-W29 -> 0 | Y30: =Y29 -> 687201 | Z30: =Y30-Y29 -> 0 | AA30: =AA29 -> 35634 | AB30: =AA30-AA29 -> 0 | AC30: =AC29 -> 905726 | AD30: =AC30-AC29 -> 0 | AE30: =AB30+X30+T30 -> 0 | AF30: =V30+Z30+AD30 -> 0 | AG30: =IF(AE30>0,AF30/AE30,0) -> 0 | AI30: =R30-'EDl log'!B28 -> -688194
A31: ='General information '!F34 -> 0 | B31: =SUM(230*A31) -> 0 | C31: 44164 | D31: =D30 -> 32447302 | E31: =D31-D30 -> 0 | F31: =F30 -> 3914064 | G31: =F31-F30 -> 0 | H31: =H30 -> 17723222 | I31: =H31-H30 -> 0 | J31: =J30 -> 28803336 | K31: =J31-J30 -> 0 | L31: =L30 -> 23860522 | M31: =L31-L30 -> 0 | N31: =M31+K31+I31+G31+E31 -> 0 | O31: =IF(B31>0,N31/B31,0) -> 0 | P31: =P30 -> 16434.734 | Q31: =(P31-P30)*1000 -> 0 | R31: =N31-Q31 -> 0 | S31: =S30 -> 10006 | T31: =S31-S30 -> 0 | U31: =U30 -> 400936 | V31: =U31-U30 -> 0 | W31: =W30 -> 32119 | X31: =W31-W30 -> 0 | Y31: =Y30 -> 687201 | Z31: =Y31-Y30 -> 0 | AA31: =AA30 -> 35634 | AB31: =AA31-AA30 -> 0 | AC31: =AC30 -> 905726 | AD31: =AC31-AC30 -> 0 | AE31: =AB31+X31+T31 -> 0 | AF31: =V31+Z31+AD31 -> 0 | AG31: =IF(AE31>0,AF31/AE31,0) -> 0 | AI31: =R31-'EDl log'!B29 -> -691215
A32: ='General information '!F35 -> 0 | B32: =SUM(230*A32) -> 0 | C32: 44165 | D32: =D31 -> 32447302 | E32: =D32-D31 -> 0 | F32: =F31 -> 3914064 | G32: =F32-F31 -> 0 | H32: =H31 -> 17723222 | I32: =H32-H31 -> 0 | J32: =J31 -> 28803336 | K32: =J32-J31 -> 0 | L32: =L31 -> 23860522 | M32: =L32-L31 -> 0 | N32: =M32+K32+I32+G32+E32 -> 0 | O32: =IF(B32>0,N32/B32,0) -> 0 | P32: =P31 -> 16434.734 | Q32: =(P32-P31)*1000 -> 0 | R32: =N32-Q32 -> 0 | S32: =S31 -> 10006 | T32: =S32-S31 -> 0 | U32: =U31 -> 400936 | V32: =U32-U31 -> 0 | W32: =W31 -> 32119 | X32: =W32-W31 -> 0 | Y32: =Y31 -> 687201 | Z32: =Y32-Y31 -> 0 | AA32: =AA31 -> 35634 | AB32: =AA32-AA31 -> 0 | AC32: =AC31 -> 905726 | AD32: =AC32-AC31 -> 0 | AE32: =AB32+X32+T32 -> 0 | AF32: =V32+Z32+AD32 -> 0 | AG32: =IF(AE32>0,AF32/AE32,0) -> 0 | AI32: =R32-'EDl log'!B30 -> -691215
A33: ='General information '!F36 -> 0 | B33: =SUM(230*A33) -> 0 | C33: 44166 | D33: =D32 -> 32447302 | E33: =D33-D32 -> 0 | F33: =F32 -> 3914064 | G33: =F33-F32 -> 0 | H33: =H32 -> 17723222 | I33: =H33-H32 -> 0 | J33: =J32 -> 28803336 | K33: =J33-J32 -> 0 | L33: =L32 -> 23860522 | M33: =L33-L32 -> 0 | N33: =M33+K33+I33+G33+E33 -> 0 | O33: =IF(B33>0,N33/B33,0) -> 0 | P33: =P32 -> 16434.734 | Q33: =(P33-P32)*1000 -> 0 | R33: =N33-Q33 -> 0 | S33: =S32 -> 10006 | T33: =S33-S32 -> 0 | U33: =U32 -> 400936 | V33: =U33-U32 -> 0 | W33: =W32 -> 32119 | X33: =W33-W32 -> 0 | Y33: =Y32 -> 687201 | Z33: =Y33-Y32 -> 0 | AA33: =AA32 -> 35634 | AB33: =AA33-AA32 -> 0 | AC33: =AC32 -> 905726 | AD33: =AC33-AC32 -> 0 | AE33: =AB33+X33+T33 -> 0 | AF33: =V33+Z33+AD33 -> 0 | AG33: =IF(AE33>0,AF33/AE33,0) -> 0 | AI33: =R33-'EDl log'!B31 -> -691215

Sheet B5
F1: Boiler A | J1: =J36 -> 0.75 | K1: Boiler B | P1: Boiler C | V1: Boiler | X1: SteamA | AC1: SteamB | AH1: Steam | AI1: Boiler & steam | AL1: Total Boiler Runing H | AM1: Total Steam Runing H | AN1: GAS1 % | AO1: GAS1/L | AP1: GAS2% | AQ1: Gas2/L | AR1: GAS3% | AS1: GAS3/L | AU1: Gas Cons | AV1: Delivery | AW1: Cost/L
B2: Level Tank Gen | C2: Level tank Boiler | D2: Daily Cons Bo. | E2: Boiler litter | F2: Boiler A | G2: Run Hr a | H2: Boiler A fuel | I2: Daily consumption | J2: AVG | K2: index Run H | L2: Run Hrb | M2: Boiler B Fuel | O2: Daily consumption | P2: Boiler C | S2: Run C | U2: Total RH | V2: Total Fuel | X2: SteamA | Y2: Run SA | Z2: Steam A Conter | AA2: Liters | AC2: SteamB | AD2: Run SteamB | AE2: Steam B Conter | AF2: SB Litters | AG2: Avg | AH2: Total Fuel | AI2: Total Fuel
S3: 0
A4: =ELEC!C2 -> 44135 | B4: =[1]B5!B35 -> 243 | C4: =[1]B5!C35 -> 249 | D4: =[1]B5!D35 -> 4 | E4: =[1]B5!E35 -> 33.52 | F4: =[1]B5!F35 -> 1648 | G4: =[1]B5!G35 -> 0 | H4: =[1]B5!H35 -> 357868 | I4: =[1]B5!I35 -> 0 | ... AM4: =[1]B5!AM35 -> 0 | AN4: 67 | AO4: =[1]B5!AO35 -> 1860 | AP4: =[1]B5!AP35 -> 52 | AQ4: =[1]B5!AQ35 -> 1560 | AR4: =[1]B5!AR35 -> 68 | AS4: =[1]B5!AS35 -> 2040 | AT4: =[1]B5!AT35 -> 5460 | AU4: =[1]B5!AU35 -> 0 | AV4: =[1]B5!AV35 -> 0 | ... AX4: =[1]B5!AX35 -> 0.8
A5: =ELEC!C3 -> 44136 | B5: 241 | C5: 247 | D5: =C4-C5 -> 2 | E5: =D5*8.38 -> 16.76 | F5: 1648 | G5: =F5-F4 -> 0 | H5: 357868 | I5: =SUM(H5-H4) -> 0 | J5: 1 | K5: 2147 | L5: =K5-K4 -> 2 | M5: 157656 | N5: =M5-M4 -> 205 | O5: =O4 -> 211.875 | P5: 1854 | Q5: 157348 | R5: =Q5-Q4 -> 0 | S5: =SUM(P5-P4) -> 0 | T5: =SUM(S5*$T$2) -> 0 | U5: =SUM(G5+L5+S5) -> 2 | V5: =R5+N5+I5:I5 -> 205 | W5: =SUM(V5/U5) -> 102.5 | X5: 2448 | Y5: =X5-X4 -> 0 | Z5: 137506 | AA5: =Z5-Z4 -> 0 | AB5: =SUM(Y5*$AB$2) -> 0 | AC5: 1933 | AD5: =AC5-AC4 -> 0 | AE5: 365212 | AF5: =AE5-AE4 -> 0 | AG5: =IF(AD5>0,AF5/AD5,0) -> 0 | AH5: =AF5+AA5 -> 0 | AI5: =SUM(AH5+V5) -> 205 | AJ5: =-tanks!AW6 -> 205 | AK5: =SUM(AJ5-AI5) -> 0 | AL5: =S5+L5+G5 -> 2 | AM5: =Y5+AD5 -> 0 | AN5: 67 | AO5: =(AN5/100)*3000 -> 2010 | AP5: 55 | AQ5: =(AP5/100)*3000 -> 1650 | AR5: 63 | AS5: =(AR5/100)*3000 -> 1890 | AT5: =SUM(AO5+AQ5+AS5) -> 5550 | AU5: =AT4-AT5+AV5 -> -90 | AX5: =IF(AV5>0,AW5,AX4) -> 0.8
A6: =ELEC!C4 -> 44137 | B6: 239.2 | C6: 246 | D6: =C5-C6 -> 1 | E6: =D6*8.38 -> 8.38 | F6: 1650 | G6: =F6-F5 -> 2 | H6: 357869 | I6: =SUM(H6-H5) -> 1 | J6: =IF(G6>0,I6/G6,0) -> 0.5 | K6: 2148 | L6: =K6-K5 -> 1 | M6: 157704 | N6: =M6-M5 -> 48 | O6: =O5 -> 211.875 | P6: 1855 | Q6: 157396 | R6: =Q6-Q5 -> 48 | S6: =SUM(P6-P5) -> 1 | T6: =SUM(S6*$T$2) -> 0 | U6: =SUM(G6+L6+S6) -> 4 | V6: =R6+N6+I6:I6 -> 97 | W6: =SUM(V6/U6) -> 24.25 | X6: =X5 -> 2448 | Y6: =X6-X5 -> 0 | Z6: =Z5 -> 137506 | AA6: =Z6-Z5 -> 0 | AB6: =SUM(Y6*$AB$2) -> 0 | AC6: =AC5 -> 1933 | AD6: =AC6-AC5 -> 0 | AE6: =AE5 -> 365212 | AF6: =AE6-AE5 -> 0 | AG6: =IF(AD6>0,AF6/AD6,0) -> 0 | AH6: =AF6+AA6 -> 0 | AI6: =SUM(AH6+V6) -> 97 | AJ6: =-tanks!AW7 -> 97 | AK6: =SUM(AJ6-AI6) -> 0 | AL6: =S6+L6+G6 -> 4 | AM6: =Y6+AD6 -> 0 | AN6: 67 | AO6: =(AN6/100)*3000 -> 2010 | AP6: 55 | AQ6: =(AP6/100)*3000 -> 1650 | AR6: =AR5 -> 63 | AS6: =(AR6/100)*3000 -> 1890 | AT6: =SUM(AO6+AQ6+AS6) -> 5550 | AU6: =AT5-AT6+AV6 -> 0 | AX6: =IF(AV6>0,AW6,AX5) -> 0.8
A7: =ELEC!C5 -> 44138 | B7: 237 | C7: 243 | D7: =C6-C7 -> 3 | E7: =D7*8.38 -> 25.14 | F7: 1653 | G7: =F7-F6 -> 3 | H7: 357869 | I7: =SUM(H7-H6) -> 0 | J7: =IF(G7>0,I7/G7,0) -> 0 | K7: =K6 -> 2148 | L7: =K7-K6 -> 0 | M7: =M6 -> 157704 | N7: =M7-M6 -> 0 | O7: =O6 -> 211.875 | P7: =P6 -> 1855 | Q7: =Q6 -> 157396 | R7: =Q7-Q6 -> 0 | S7: =SUM(P7-P6) -> 0 | T7: =SUM(S7*$T$2) -> 0 | U7: =SUM(G7+L7+S7) -> 3 | V7: =R7+N7+I7:I7 -> 0 | W7: =SUM(V7/U7) -> 0 | X7: =X6 -> 2448 | Y7: =X7-X6 -> 0 | Z7: =Z6 -> 137506 | AA7: =Z7-Z6 -> 0 | AB7: =SUM(Y7*$AB$2) -> 0 | AC7: =AC6 -> 1933 | AD7: =AC7-AC6 -> 0 | AE7: =AE6 -> 365212 | AF7: =AE7-AE6 -> 0 | AG7: =IF(AD7>0,AF7/AD7,0) -> 0 | AH7: =AF7+AA7 -> 0 | AI7: =SUM(AH7+V7) -> 0 | AJ7: =-tanks!AW8 -> 0 | AK7: =SUM(AJ7-AI7) -> 0 | AL7: =S7+L7+G7 -> 3 | AM7: =Y7+AD7 -> 0 | AN7: 67 | AO7: =(AN7/100)*3000 -> 2010 | AP7: =AP6 -> 55 | AQ7: =(AP7/100)*3000 -> 1650 | AR7: =AR6 -> 63 | AS7: =(AR7/100)*3000 -> 1890 | AT7: =SUM(AO7+AQ7+AS7) -> 5550 | AU7: =AT6-AT7+AV7 -> 0 | AX7: =IF(AV7>0,AW7,AX6) -> 0.8
A8: =ELEC!C6 -> 44139 | B8: 234 | C8: 240 | D8: =C7-C8 -> 3 | E8: =D8*8.38 -> 25.14 | F8: 1656 | G8: =F8-F7 -> 3 | H8: =H7 -> 357869 | I8: =SUM(H8-H7) -> 0 | J8: =IF(G8>0,I8/G8,0) -> 0 | K8: 2148 | L8: =K8-K7 -> 0 | M8: 157704 | N8: =M8-M7 -> 0 | O8: =O7 -> 211.875 | P8: 1855 | Q8: 157396 | R8: =Q8-Q7 -> 0 | S8: =SUM(P8-P7) -> 0 | T8: =SUM(S8*$T$2) -> 0 | U8: =SUM(G8+L8+S8) -> 3 | V8: =R8+N8+I8:I8 -> 0 | W8: =SUM(V8/U8) -> 0 | X8: =X7 -> 2448 | Y8: =X8-X7 -> 0 | Z8: =Z7 -> 137506 | AA8: =Z8-Z7 -> 0 | AB8: =SUM(Y8*$AB$2) -> 0 | AC8: =AC7 -> 1933 | AD8: =AC8-AC7 -> 0 | AE8: =AE7 -> 365212 | AF8: =AE8-AE7 -> 0 | AG8: =IF(AD8>0,AF8/AD8,0) -> 0 | AH8: =AF8+AA8 -> 0 | AI8: =SUM(AH8+V8) -> 0 | AJ8: =-tanks!AW9 -> 0 | AK8: =SUM(AJ8-AI8) -> 0 | AL8: =S8+L8+G8 -> 3 | AM8: =Y8+AD8 -> 0 | AN8: =AN7 -> 67 | AO8: =(AN8/100)*3000 -> 2010 | AP8: =AP7 -> 55 | AQ8: =(AP8/100)*3000 -> 1650 | AR8: =AR7 -> 63 | AS8: =(AR8/100)*3000 -> 1890 | AT8: =SUM(AO8+AQ8+AS8) -> 5550 | AU8: =AT7-AT8+AV8 -> 0 | AX8: =IF(AV8>0,AW8,AX7) -> 0.8
A9: =ELEC!C7 -> 44140 | B9: 231 | C9: 238 | D9: =C8-C9 -> 2 | E9: =D9*8.38 -> 16.76 | F9: 1659 | G9: =F9-F8 -> 3 | H9: =H8 -> 357869 | I9: =SUM(H9-H8) -> 0 | J9: =IF(G9>0,I9/G9,0) -> 0 | K9: =K8 -> 2148 | L9: =K9-K8 -> 0 | M9: =M8 -> 157704 | N9: =M9-M8 -> 0 | O9: =O8 -> 211.875 | P9: =P8 -> 1855 | Q9: =Q8 -> 157396 | R9: =Q9-Q8 -> 0 | S9: =SUM(P9-P8) -> 0 | T9: =SUM(S9*$T$2) -> 0 | U9: =SUM(G9+L9+S9) -> 3 | V9: =R9+N9+I9:I9 -> 0 | W9: =SUM(V9/U9) -> 0 | X9: =X8 -> 2448 | Y9: =X9-X8 -> 0 | Z9: =Z8 -> 137506 | AA9: =Z9-Z8 -> 0 | AB9: =SUM(Y9*$AB$2) -> 0 | AC9: =AC8 -> 1933 | AD9: =AC9-AC8 -> 0 | AE9: =AE8 -> 365212 | AF9: =AE9-AE8 -> 0 | AG9: =IF(AD9>0,AF9/AD9,0) -> 0 | AH9: =AF9+AA9 -> 0 | AI9: =SUM(AH9+V9) -> 0 | AJ9: =-tanks!AW10 -> 0 | AK9: =SUM(AJ9-AI9) -> 0 | AL9: =S9+L9+G9 -> 3 | AM9: =Y9+AD9 -> 0 | AN9: =AN8 -> 67 | AO9: =(AN9/100)*3000 -> 2010 | AP9: =AP8 -> 55 | AQ9: =(AP9/100)*3000 -> 1650 | AR9: =AR8 -> 63 | AS9: =(AR9/100)*3000 -> 1890 | AT9: =SUM(AO9+AQ9+AS9) -> 5550 | AU9: =AT8-AT9+AV9 -> 0 | AX9: =IF(AV9>0,AW9,AX8) -> 0.8
A10: =ELEC!C8 -> 44141 | B10: 229 | C10: 235 | D10: =C9-C10 -> 3 | E10: =D10*8.38 -> 25.14 | F10: =F9 -> 1659 | G10: =F10-F9 -> 0 | H10: =H9 -> 357869 | I10: =SUM(H10-H9) -> 0 | J10: =IF(G10>0,I10/G10,0) -> 0 | K10: =K9 -> 2148 | L10: =K10-K9 -> 0 | M10: =M9 -> 157704 | N10: =M10-M9 -> 0 | O10: =O9 -> 211.875 | P10: 1856 | Q10: 157396 | R10: =Q10-Q9 -> 0 | S10: =SUM(P10-P9) -> 1 | T10: =SUM(S10*$T$2) -> 0 | U10: =SUM(G10+L10+S10) -> 1 | V10: =R10+N10+I10:I10 -> 0 | W10: =SUM(V10/U10) -> 0 | X10: =X9 -> 2448 | Y10: =X10-X9 -> 0 | Z10: =Z9 -> 137506 | AA10: =Z10-Z9 -> 0 | AB10: =SUM(Y10*$AB$2) -> 0 | AC10: =AC9 -> 1933 | AD10: =AC10-AC9 -> 0 | AE10: =AE9 -> 365212 | AF10: =AE10-AE9 -> 0 | AG10: =IF(AD10>0,AF10/AD10,0) -> 0 | AH10: =AF10+AA10 -> 0 | AI10: =SUM(AH10+V10) -> 0 | AJ10: =-tanks!AW11 -> 0 | AK10: =SUM(AJ10-AI10) -> 0 | AL10: =S10+L10+G10 -> 1 | AM10: =Y10+AD10 -> 0 | AN10: =AN9 -> 67 | AO10: =(AN10/100)*3000 -> 2010 | AP10: =AP9 -> 55 | AQ10: =(AP10/100)*3000 -> 1650 | AR10: =AR9 -> 63 | AS10: =(AR10/100)*3000 -> 1890 | AT10: =SUM(AO10+AQ10+AS10) -> 5550 | AU10: =AT9-AT10+AV10 -> 0 | AX10: =IF(AV10>0,AW10,AX9) -> 0.8
A11: =ELEC!C9 -> 44142 | B11: 227 | C11: 234 | D11: =C10-C11 -> 1 | E11: =D11*8.38 -> 8.38 | F11: 1660 | G11: =F11-F10 -> 1 | H11: =H10 -> 357869 | I11: =SUM(H11-H10) -> 0 | J11: =IF(G11>0,I11/G11,0) -> 0 | K11: =K10 -> 2148 | L11: =K11-K10 -> 0 | M11: =M10 -> 157704 | N11: =M11-M10 -> 0 | O11: =O10 -> 211.875 | P11: 1858 | Q11: 157634 | R11: =Q11-Q10 -> 238 | S11: =SUM(P11-P10) -> 2 | T11: =SUM(S11*$T$2) -> 0 | U11: =SUM(G11+L11+S11) -> 3 | V11: =R11+N11+I11:I11 -> 238 | W11: =SUM(V11/U11) -> 79.333333 | X11: =X10 -> 2448 | Y11: =X11-X10 -> 0 | Z11: =Z10 -> 137506 | AA11: =Z11-Z10 -> 0 | AB11: =SUM(Y11*$AB$2) -> 0 | AC11: =AC10 -> 1933 | AD11: =AC11-AC10 -> 0 | AE11: =AE10 -> 365212 | AF11: =AE11-AE10 -> 0 | AG11: =IF(AD11>0,AF11/AD11,0) -> 0 | AH11: =AF11+AA11 -> 0 | AI11: =SUM(AH11+V11) -> 238 | AJ11: =-tanks!AW12 -> 238 | AK11: =SUM(AJ11-AI11) -> 0 | AL11: =S11+L11+G11 -> 3 | AM11: =Y11+AD11 -> 0 | AN11: =AN10 -> 67 | AO11: =(AN11/100)*3000 -> 2010 | AP11: =AP10 -> 55 | AQ11: =(AP11/100)*3000 -> 1650 | AR11: =AR10 -> 63 | AS11: =(AR11/100)*3000 -> 1890 | AT11: =SUM(AO11+AQ11+AS11) -> 5550 | AU11: =AT10-AT11+AV11 -> 0 | AX11: =IF(AV11>0,AW11,AX10) -> 0.8
A12: =ELEC!C10 -> 44143 | B12: 225 | C12: 231 | D12: =C11-C12 -> 3 | E12: =D12*8.38 -> 25.14 | F12: 1660 | G12: =F12-F11 -> 0 | H12: =H11 -> 357869 | I12: =SUM(H12-H11) -> 0 | J12: =IF(G12>0,I12/G12,0) -> 0 | K12: =K11 -> 2148 | L12: =K12-K11 -> 0 | M12: 157707 | N12: =M12-M11 -> 3 | O12: =O11 -> 211.875 | P12: 1860 | Q12: 157793 | R12: =Q12-Q11 -> 159 | S12: =SUM(P12-P11) -> 2 | T12: =SUM(S12*$T$2) -> 0 | U12: =SUM(G12+L12+S12) -> 2 | V12: =R12+N12+I12:I12 -> 162 | W12: =SUM(V12/U12) -> 81 | X12: =X11 -> 2448 | Y12: =X12-X11 -> 0 | Z12: =Z11 -> 137506 | AA12: =Z12-Z11 -> 0 | AB12: =SUM(Y12*$AB$2) -> 0 | AC12: =AC11 -> 1933 | AD12: =AC12-AC11 -> 0 | AE12: =AE11 -> 365212 | AF12: =AE12-AE11 -> 0 | AG12: =IF(AD12>0,AF12/AD12,0) -> 0 | AH12: =AF12+AA12 -> 0 | AI12: =SUM(AH12+V12) -> 162 | AJ12: =-tanks!AW13 -> 162 | AK12: =SUM(AJ12-AI12) -> 0 | AL12: =S12+L12+G12 -> 2 | AM12: =Y12+AD12 -> 0 | AN12: =AN11 -> 67 | AO12: =(AN12/100)*3000 -> 2010 | AP12: =AP11 -> 55 | AQ12: =(AP12/100)*3000 -> 1650 | AR12: =AR11 -> 63 | AS12: =(AR12/100)*3000 -> 1890 | AT12: =SUM(AO12+AQ12+AS12) -> 5550 | AU12: =AT11-AT12+AV12 -> 0 | AX12: =IF(AV12>0,AW12,AX11) -> 0.8
A13: =ELEC!C11 -> 44144 | B13: 223 | C13: 230 | D13: =C12-C13 -> 1 | E13: =D13*8.38 -> 8.38 | F13: =F12 -> 1660 | G13: =F13-F12 -> 0 | H13: =H12 -> 357869 | I13: =SUM(H13-H12) -> 0 | J13: =IF(G13>0,I13/G13,0) -> 0 | K13: =K12 -> 2148 | L13: =K13-K12 -> 0 | M13: =M12 -> 157707 | N13: =M13-M12 -> 0 | O13: =O12 -> 211.875 | P13: 1862 | Q13: 157930 | R13: =Q13-Q12 -> 137 | S13: =SUM(P13-P12) -> 2 | T13: =SUM(S13*$T$2) -> 0 | U13: =SUM(G13+L13+S13) -> 2 | V13: =R13+N13+I13:I13 -> 137 | W13: =SUM(V13/U13) -> 68.5 | X13: =X12 -> 2448 | Y13: =X13-X12 -> 0 | Z13: =Z12 -> 137506 | AA13: =Z13-Z12 -> 0 | AB13: =SUM(Y13*$AB$2) -> 0 | AC13: =AC12 -> 1933 | AD13: =AC13-AC12 -> 0 | AE13: =AE12 -> 365212 | AF13: =AE13-AE12 -> 0 | AG13: =IF(AD13>0,AF13/AD13,0) -> 0 | AH13: =AF13+AA13 -> 0 | AI13: =SUM(AH13+V13) -> 137 | AJ13: =-tanks!AW14 -> 137 | AK13: =SUM(AJ13-AI13) -> 0 | AL13: =S13+L13+G13 -> 2 | AM13: =Y13+AD13 -> 0 | AN13: =AN12 -> 67 | AO13: =(AN13/100)*3000 -> 2010 | AP13: =AP12 -> 55 | AQ13: =(AP13/100)*3000 -> 1650 | AR13: =AR12 -> 63 | AS13: =(AR13/100)*3000 -> 1890 | AT13: =SUM(AO13+AQ13+AS13) -> 5550 | AU13: =AT12-AT13+AV13 -> 0 | AX13: =IF(AV13>0,AW13,AX12) -> 0.8
A14: =ELEC!C12 -> 44145 | B14: 221 | C14: 228 | D14: =C13-C14 -> 2 | E14: =D14*8.38 -> 16.76 | F14: 1660 | G14: =F14-F13 -> 0 | H14: =H13 -> 357869 | I14: =SUM(H14-H13) -> 0 | J14: =IF(G14>0,I14/G14,0) -> 0 | K14: =K13 -> 2148 | L14: =K14-K13 -> 0 | M14: =M13 -> 157707 | N14: =M14-M13 -> 0 | O14: =O13 -> 211.875 | P14: 1863 | Q14: 158074 | R14: =Q14-Q13 -> 144 | S14: =SUM(P14-P13) -> 1 | T14: =SUM(S14*$T$2) -> 0 | U14: =SUM(G14+L14+S14) -> 1 | V14: =R14+N14+I14:I14 -> 144 | W14: =SUM(V14/U14) -> 144 | X14: =X13 -> 2448 | Y14: =X14-X13 -> 0 | Z14: =Z13 -> 137506 | AA14: =Z14-Z13 -> 0 | AB14: =SUM(Y14*$AB$2) -> 0 | AC14: =AC13 -> 1933 | AD14: =AC14-AC13 -> 0 | AE14: =AE13 -> 365212 | AF14: =AE14-AE13 -> 0 | AG14: =IF(AD14>0,AF14/AD14,0) -> 0 | AH14: =AF14+AA14 -> 0 | AI14: =SUM(AH14+V14) -> 144 | AJ14: =-tanks!AW15 -> 144 | AK14: =SUM(AJ14-AI14) -> 0 | AL14: =S14+L14+G14 -> 1 | AM14: =Y14+AD14 -> 0 | AN14: =AN13 -> 67 | AO14: =(AN14/100)*3000 -> 2010 | AP14: =AP13 -> 55 | AQ14: =(AP14/100)*3000 -> 1650 | AR14: =AR13 -> 63 | AS14: =(AR14/100)*3000 -> 1890 | AT14: =SUM(AO14+AQ14+AS14) -> 5550 | AU14: =AT13-AT14+AV14 -> 0 | AX14: =IF(AV14>0,AW14,AX13) -> 0.8
A15: =ELEC!C13 -> 44146 | B15: 219 | C15: 226 | D15: =C14-C15 -> 2 | E15: =D15*8.38 -> 16.76 | F15: 1660 | G15: =F15-F14 -> 0 | H15: =H14 -> 357869 | I15: =SUM(H15-H14) -> 0 | J15: =IF(G15>0,I15/G15,0) -> 0 | K15: =K14 -> 2148 | L15: =K15-K14 -> 0 | M15: =M14 -> 157707 | N15: =M15-M14 -> 0 | O15: =O14 -> 211.875 | P15: 1865 | Q15: 158236 | R15: =Q15-Q14 -> 162 | S15: =SUM(P15-P14) -> 2 | T15: =SUM(S15*$T$2) -> 0 | U15: =SUM(G15+L15+S15) -> 2 | V15: =R15+N15+I15:I15 -> 162 | W15: =SUM(V15/U15) -> 81 | X15: =X14 -> 2448 | Y15: =X15-X14 -> 0 | Z15: =Z14 -> 137506 | AA15: =Z15-Z14 -> 0 | AB15: =SUM(Y15*$AB$2) -> 0 | AC15: =AC14 -> 1933 | AD15: =AC15-AC14 -> 0 | AE15: =AE14 -> 365212 | AF15: =AE15-AE14 -> 0 | AG15: =IF(AD15>0,AF15/AD15,0) -> 0 | AH15: =AF15+AA15 -> 0 | AI15: =SUM(AH15+V15) -> 162 | AJ15: =-tanks!AW16 -> 162 | AK15: =SUM(AJ15-AI15) -> 0 | AL15: =S15+L15+G15 -> 2 | AM15: =Y15+AD15 -> 0 | AN15: =AN14 -> 67 | AO15: =(AN15/100)*3000 -> 2010 | AP15: =AP14 -> 55 | AQ15: =(AP15/100)*3000 -> 1650 | AR15: =AR14 -> 63 | AS15: =(AR15/100)*3000 -> 1890 | AT15: =SUM(AO15+AQ15+AS15) -> 5550 | AU15: =AT14-AT15+AV15 -> 0 | AX15: =IF(AV15>0,AW15,AX14) -> 0.8
A16: =ELEC!C14 -> 44147 | B16: 217 | C16: 223 | D16: =C15-C16 -> 3 | E16: =D16*8.38 -> 25.14 | F16: 1660 | G16: =F16-F15 -> 0 | H16: =H15 -> 357869 | I16: =SUM(H16-H15) -> 0 | J16: =IF(G16>0,I16/G16,0) -> 0 | K16: =K15 -> 2148 | L16: =K16-K15 -> 0 | M16: =M15 -> 157707 | N16: =M16-M15 -> 0 | O16: =O15 -> 211.875 | P16: 1867 | Q16: 158400 | R16: =Q16-Q15 -> 164 | S16: =SUM(P16-P15) -> 2 | T16: =SUM(S16*$T$2) -> 0 | U16: =SUM(G16+L16+S16) -> 2 | V16: =R16+N16+I16:I16 -> 164 | W16: =SUM(V16/U16) -> 82 | X16: 2449 | Y16: =X16-X15 -> 1 | Z16: 137586 | AA16: =Z16-Z15 -> 80 | AB16: =SUM(Y16*$AB$2) -> 0 | AC16: 1933 | AD16: =AC16-AC15 -> 0 | AE16: =AE15 -> 365212 | AF16: =AE16-AE15 -> 0 | AG16: =IF(AD16>0,AF16/AD16,0) -> 0 | AH16: =AF16+AA16 -> 80 | AI16: =SUM(AH16+V16) -> 244 | AJ16: =-tanks!AW17 -> 244 | AK16: =SUM(AJ16-AI16) -> 0 | AL16: =S16+L16+G16 -> 2 | AM16: =Y16+AD16 -> 1 | AN16: =AN15 -> 67 | AO16: =(AN16/100)*3000 -> 2010 | AP16: =AP15 -> 55 | AQ16: =(AP16/100)*3000 -> 1650 | AR16: =AR15 -> 63 | AS16: =(AR16/100)*3000 -> 1890 | AT16: =SUM(AO16+AQ16+AS16) -> 5550 | AU16: =AT15-AT16+AV16 -> 0 | AX16: =IF(AV16>0,AW16,AX15) -> 0.8
A17: =ELEC!C15 -> 44148 | B17: 215 | C17: 221 | D17: =C16-C17 -> 2 | E17: =D17*8.38 -> 16.76 | F17: =F16 -> 1660 | G17: =F17-F16 -> 0 | H17: =H16 -> 357869 | I17: =SUM(H17-H16) -> 0 | J17: =IF(G17>0,I17/G17,0) -> 0 | K17: =K16 -> 2148 | L17: =K17-K16 -> 0 | M17: =M16 -> 157707 | N17: =M17-M16 -> 0 | O17: =O16 -> 211.875 | P17: 1868 | Q17: 158537 | R17: =Q17-Q16 -> 137 | S17: =SUM(P17-P16) -> 1 | T17: =SUM(S17*$T$2) -> 0 | U17: =SUM(G17+L17+S17) -> 1 | V17: =R17+N17+I17:I17 -> 137 | X17: =X16 -> 2449 | Y17: =X17-X16 -> 0 | Z17: =Z16 -> 137586 | AA17: =Z17-Z16 -> 0 | AB17: =SUM(Y17*$AB$2) -> 0 | AC17: =AC16 -> 1933 | AD17: =AC17-AC16 -> 0 | AE17: =AE16 -> 365212 | AF17: =AE17-AE16 -> 0 | AG17: =IF(AD17>0,AF17/AD17,0) -> 0 | AH17: =AF17+AA17 -> 0 | AI17: =SUM(AH17+V17) -> 137 | AJ17: =-tanks!AW18 -> 137 | AK17: =SUM(AJ17-AI17) -> 0 | AL17: =S17+L17+G17 -> 1 | AM17: =Y17+AD17 -> 0 | AN17: =AN16 -> 67 | AO17: =(AN17/100)*3000 -> 2010 | AP17: =AP16 -> 55 | AQ17: =(AP17/100)*3000 -> 1650 | AR17: =AR16 -> 63 | AS17: =(AR17/100)*3000 -> 1890 | AT17: =SUM(AO17+AQ17+AS17) -> 5550 | AU17: =AT16-AT17+AV17 -> 0 | AX17: =IF(AV17>0,AW17,AX16) -> 0.8
A18: =ELEC!C16 -> 44149 | B18: 213 | C18: 219 | D18: =C17-C18 -> 2 | E18: =D18*8.38 -> 16.76 | F18: =F17 -> 1660 | G18: =F18-F17 -> 0 | H18: =H17 -> 357869 | I18: =SUM(H18-H17) -> 0 | J18: =IF(G18>0,I18/G18,0) -> 0 | K18: =K17 -> 2148 | L18: =K18-K17 -> 0 | M18: =M17 -> 157707 | N18: =M18-M17 -> 0 | O18: 1869 | P18: 1869 | Q18: 158699 | R18: =Q18-Q17 -> 162 | S18: =SUM(P18-P17) -> 1 | T18: =SUM(S18*$T$2) -> 0 | U18: =SUM(G18+L18+S18) -> 1 | V18: =R18+N18+I18:I18 -> 162 | X18: =X17 -> 2449 | Y18: =X18-X17 -> 0 | Z18: =Z17 -> 137586 | AA18: =Z18-Z17 -> 0 | AB18: =SUM(Y18*$AB$2) -> 0 | AC18: =AC17 -> 1933 | AD18: =AC18-AC17 -> 0 | AE18: =AE17 -> 365212 | AF18: =AE18-AE17 -> 0 | AG18: =IF(AD18>0,AF18/AD18,0) -> 0 | AH18: =AF18+AA18 -> 0 | AI18: =SUM(AH18+V18) -> 162 | AJ18: =-tanks!AW19 -> 162 | AK18: =SUM(AJ18-AI18) -> 0 | AL18: =S18+L18+G18 -> 1 | AM18: =Y18+AD18 -> 0 | AN18: =AN17 -> 67 | AO18: =(AN18/100)*3000 -> 2010 | AP18: =AP17 -> 55 | AQ18: =(AP18/100)*3000 -> 1650 | AR18: 62 | AS18: =(AR18/100)*3000 -> 1860 | AT18: =SUM(AO18+AQ18+AS18) -> 5520 | AU18: =AT17-AT18+AV18 -> 30 | AX18: =IF(AV18>0,AW18,AX17) -> 0.8
A19: =ELEC!C17 -> 44150 | B19: 211 | C19: 217.3 | D19: =C18-C19 -> 1.7 | E19: =D19*8.38 -> 14.246 | F19: =F18 -> 1660 | G19: =F19-F18 -> 0 | H19: =H18 -> 357869 | I19: =SUM(H19-H18) -> 0 | J19: =IF(G19>0,I19/G19,0) -> 0 | K19: 2148 | L19: =K19-K18 -> 0 | M19: 157707 | N19: =M19-M18 -> 0 | O19: =O18 -> 1869 | P19: 1870 | Q19: 158856 | R19: =Q19-Q18 -> 157 | S19: =SUM(P19-P18) -> 1 | T19: =SUM(S19*$T$2) -> 0 | U19: =SUM(G19+L19+S19) -> 1 | V19: =R19+N19+I19:I19 -> 157 | X19: =X18 -> 2449 | Y19: =X19-X18 -> 0 | Z19: =Z18 -> 137586 | AA19: =Z19-Z18 -> 0 | AB19: =SUM(Y19*$AB$2) -> 0 | AC19: =AC18 -> 1933 | AD19: =AC19-AC18 -> 0 | AE19: =AE18 -> 365212 | AF19: =AE19-AE18 -> 0 | AG19: =IF(AD19>0,AF19/AD19,0) -> 0 | AH19: =AF19+AA19 -> 0 | AI19: =SUM(AH19+V19) -> 157 | AJ19: =-tanks!AW20 -> 157 | AK19: =SUM(AJ19-AI19) -> 0 | AL19: =S19+L19+G19 -> 1 | AM19: =Y19+AD19 -> 0 | AN19: =AN18 -> 67 | AO19: =(AN19/100)*3000 -> 2010 | AP19: =AP18 -> 55 | AQ19: =(AP19/100)*3000 -> 1650 | AR19: =AR18 -> 62 | AS19: =(AR19/100)*3000 -> 1860 | AT19: =SUM(AO19+AQ19+AS19) -> 5520 | AU19: =AT18-AT19+AV19 -> 0 | AX19: =IF(AV19>0,AW19,AX18) -> 0.8
A20: =ELEC!C18 -> 44151 | B20: 248 | C20: 254 | D20: =C19-C20 -> -36.7 | E20: =D20*8.38 -> -307.546 | F20: =F19 -> 1660 | G20: =F20-F19 -> 0 | H20: =H19 -> 357869 | I20: =SUM(H20-H19) -> 0 | J20: =IF(G20>0,I20/G20,0) -> 0 | K20: =K19 -> 2148 | L20: =K20-K19 -> 0 | M20: =M19 -> 157707 | N20: =M20-M19 -> 0 | O20: =O19 -> 1869 | P20: 1871 | Q20: 158993 | R20: =Q20-Q19 -> 137 | S20: =SUM(P20-P19) -> 1 | T20: =SUM(S20*$T$2) -> 0 | U20: =SUM(G20+L20+S20) -> 1 | V20: =R20+N20+I20:I20 -> 137 | X20: =X19 -> 2449 | Y20: =X20-X19 -> 0 | Z20: =Z19 -> 137586 | AA20: =Z20-Z19 -> 0 | AB20: =SUM(Y20*$AB$2) -> 0 | AC20: =AC19 -> 1933 | AD20: =AC20-AC19 -> 0 | AE20: =AE19 -> 365212 | AF20: =AE20-AE19 -> 0 | AG20: =IF(AD20>0,AF20/AD20,0) -> 0 | AH20: =AF20+AA20 -> 0 | AI20: =SUM(AH20+V20) -> 137 | AJ20: =-tanks!AW21 -> 137 | AK20: =SUM(AJ20-AI20) -> 0 | AL20: =S20+L20+G20 -> 1 | AM20: =Y20+AD20 -> 0 | AN20: =AN19 -> 67 | AO20: =(AN20/100)*3000 -> 2010 | AP20: =AP19 -> 55 | AQ20: =(AP20/100)*3000 -> 1650 | AR20: =AR19 -> 62 | AS20: =(AR20/100)*3000 -> 1860 | AT20: =SUM(AO20+AQ20+AS20) -> 5520 | AU20: =AT19-AT20+AV20 -> 0 | AX20: =IF(AV20>0,AW20,AX19) -> 0.8
A21: =ELEC!C19 -> 44152 | B21: 246 | C21: 252 | D21: =C20-C21 -> 2 | E21: =D21*8.38 -> 16.76 | F21: =F20 -> 1660 | G21: =F21-F20 -> 0 | H21: =H20 -> 357869 | I21: =SUM(H21-H20) -> 0 | J21: =IF(G21>0,I21/G21,0) -> 0 | K21: =K20 -> 2148 | L21: =K21-K20 -> 0 | M21: =M20 -> 157707 | N21: =M21-M20 -> 0 | O21: =O20 -> 1869 | P21: 1872 | Q21: 159153 | R21: =Q21-Q20 -> 160 | S21: =SUM(P21-P20) -> 1 | T21: =SUM(S21*$T$2) -> 0 | U21: =SUM(G21+L21+S21) -> 1 | V21: =R21+N21+I21:I21 -> 160 | X21: =X20 -> 2449 | Y21: =X21-X20 -> 0 | Z21: =Z20 -> 137586 | AA21: =Z21-Z20 -> 0 | AB21: =SUM(Y21*$AB$2) -> 0 | AC21: =AC20 -> 1933 | AD21: =AC21-AC20 -> 0 | AE21: =AE20 -> 365212 | AF21: =AE21-AE20 -> 0 | AG21: =IF(AD21>0,AF21/AD21,0) -> 0 | AH21: =AF21+AA21 -> 0 | AI21: =SUM(AH21+V21) -> 160 | AJ21: =-tanks!AW22 -> 160 | AK21: =SUM(AJ21-AI21) -> 0 | AL21: =S21+L21+G21 -> 1 | AM21: =Y21+AD21 -> 0 | AN21: =AN20 -> 67 | AO21: =(AN21/100)*3000 -> 2010 | AP21: =AP20 -> 55 | AQ21: =(AP21/100)*3000 -> 1650 | AR21: =AR20 -> 62 | AS21: =(AR21/100)*3000 -> 1860 | AT21: =SUM(AO21+AQ21+AS21) -> 5520 | AU21: =AT20-AT21+AV21 -> 0 | AX21: =IF(AV21>0,AW21,AX20) -> 0.8
A22: =ELEC!C20 -> 44153 | B22: 244 | C22: 250 | D22: =C21-C22 -> 2 | E22: =D22*8.38 -> 16.76 | F22: =F21 -> 1660 | G22: =F22-F21 -> 0 | H22: =H21 -> 357869 | I22: =SUM(H22-H21) -> 0 | J22: =IF(G22>0,I22/G22,0) -> 0 | K22: =K21 -> 2148 | L22: =K22-K21 -> 0 | M22: =M21 -> 157707 | N22: =M22-M21 -> 0 | O22: =O21 -> 1869 | P22: 1875 | Q22: 159367 | R22: =Q22-Q21 -> 214 | S22: =SUM(P22-P21) -> 3 | T22: =SUM(S22*$T$2) -> 0 | U22: =SUM(G22+L22+S22) -> 3 | V22: =R22+N22+I22:I22 -> 214 | X22: =X21 -> 2449 | Y22: =X22-X21 -> 0 | Z22: =Z21 -> 137586 | AA22: =Z22-Z21 -> 0 | AB22: =SUM(Y22*$AB$2) -> 0 | AC22: =AC21 -> 1933 | AD22: =AC22-AC21 -> 0 | AE22: =AE21 -> 365212 | AF22: =AE22-AE21 -> 0 | AG22: =IF(AD22>0,AF22/AD22,0) -> 0 | AH22: =AF22+AA22 -> 0 | AI22: =SUM(AH22+V22) -> 214 | AJ22: =-tanks!AW23 -> 214 | AK22: =SUM(AJ22-AI22) -> 0 | AL22: =S22+L22+G22 -> 3 | AM22: =Y22+AD22 -> 0 | AN22: =AN21 -> 67 | AO22: =(AN22/100)*3000 -> 2010 | AP22: =AP21 -> 55 | AQ22: =(AP22/100)*3000 -> 1650 | AR22: =AR21 -> 62 | AS22: =(AR22/100)*3000 -> 1860 | AT22: =SUM(AO22+AQ22+AS22) -> 5520 | AU22: =AT21-AT22+AV22 -> 0 | AX22: =IF(AV22>0,AW22,AX21) -> 0.8
A23: =ELEC!C21 -> 44154 | B23: 243 | C23: 249 | D23: =C22-C23 -> 1 | E23: =D23*8.38 -> 8.38 | F23: =F22 -> 1660 | G23: =F23-F22 -> 0 | H23: =H22 -> 357869 | I23: =SUM(H23-H22) -> 0 | J23: =IF(G23>0,I23/G23,0) -> 0 | K23: =K22 -> 2148 | L23: =K23-K22 -> 0 | M23: =M22 -> 157707 | N23: =M23-M22 -> 0 | O23: =O22 -> 1869 | P23: 1876 | Q23: 159480 | R23: =Q23-Q22 -> 113 | S23: =SUM(P23-P22) -> 1 | T23: =SUM(S23*$T$2) -> 0 | U23: =SUM(G23+L23+S23) -> 1 | V23: =R23+N23+I23:I23 -> 113 | X23: =X22 -> 2449 | Y23: =X23-X22 -> 0 | Z23: =Z22 -> 137586 | AA23: =Z23-Z22 -> 0 | AB23: =SUM(Y23*$AB$2) -> 0 | AC23: =AC22 -> 1933 | AD23: =AC23-AC22 -> 0 | AE23: =AE22 -> 365212 | AF23: =AE23-AE22 -> 0 | AG23: =IF(AD23>0,AF23/AD23,0) -> 0 | AH23: =AF23+AA23 -> 0 | AI23: =SUM(AH23+V23) -> 113 | AJ23: =-tanks!AW24 -> 113 | AK23: =SUM(AJ23-AI23) -> 0 | AL23: =S23+L23+G23 -> 1 | AM23: =Y23+AD23 -> 0 | AN23: =AN22 -> 67 | AO23: =(AN23/100)*3000 -> 2010 | AP23: =AP22 -> 55 | AQ23: =(AP23/100)*3000 -> 1650 | AR23: =AR22 -> 62 | AS23: =(AR23/100)*3000 -> 1860 | AT23: =SUM(AO23+AQ23+AS23) -> 5520 | AU23: =AT22-AT23+AV23 -> 0 | AX23: =IF(AV23>0,AW23,AX22) -> 0.8
A24: =ELEC!C22 -> 44155 | B24: 239 | C24: 245 | D24: =C23-C24 -> 4 | E24: =D24*8.38 -> 33.52 | F24: 1660 | G24: =F24-F23 -> 0 | H24: =H23 -> 357869 | I24: =SUM(H24-H23) -> 0 | J24: =IF(G24>0,I24/G24,0) -> 0 | K24: =K23 -> 2148 | L24: =K24-K23 -> 0 | M24: =M23 -> 157707 | N24: =M24-M23 -> 0 | O24: =O23 -> 1869 | P24: 1879 | Q24: 159675 | R24: =Q24-Q23 -> 195 | S24: =SUM(P24-P23) -> 3 | T24: =SUM(S24*$T$2) -> 0 | U24: =SUM(G24+L24+S24) -> 3 | V24: =R24+N24+I24:I24 -> 195 | X24: =X23 -> 2449 | Y24: =X24-X23 -> 0 | Z24: =Z23 -> 137586 | AA24: =Z24-Z23 -> 0 | AB24: =SUM(Y24*$AB$2) -> 0 | AC24: =AC23 -> 1933 | AD24: =AC24-AC23 -> 0 | AE24: 365262 | AF24: =AE24-AE23 -> 50 | AG24: =IF(AD24>0,AF24/AD24,0) -> 0 | AH24: =AF24+AA24 -> 50 | AI24: =SUM(AH24+V24) -> 245 | AJ24: =-tanks!AW25 -> 245 | AK24: =SUM(AJ24-AI24) -> 0 | AL24: =S24+L24+G24 -> 3 | AM24: =Y24+AD24 -> 0 | AN24: 68 | AO24: =(AN24/100)*3000 -> 2040 | AP24: =AP23 -> 55 | AQ24: =(AP24/100)*3000 -> 1650 | AR24: =AR23 -> 62 | AS24: =(AR24/100)*3000 -> 1860 | AT24: =SUM(AO24+AQ24+AS24) -> 5550 | AU24: =AT23-AT24+AV24 -> -30 | AX24: =IF(AV24>0,AW24,AX23) -> 0.8
A25: =ELEC!C23 -> 44156 | B25: 238 | C25: 244 | D25: =C24-C25 -> 1 | E25: =D25*8.38 -> 8.38 | F25: =F24 -> 1660 | G25: =F25-F24 -> 0 | H25: =H24 -> 357869 | I25: =SUM(H25-H24) -> 0 | J25: =IF(G25>0,I25/G25,0) -> 0 | K25: =K24 -> 2148 | L25: =K25-K24 -> 0 | M25: =M24 -> 157707 | N25: =M25-M24 -> 0 | O25: =O24 -> 1869 | P25: 1880 | Q25: 159812 | R25: =Q25-Q24 -> 137 | S25: =SUM(P25-P24) -> 1 | T25: =SUM(S25*$T$2) -> 0 | U25: =SUM(G25+L25+S25) -> 1 | V25: =R25+N25+I25:I25 -> 137 | X25: =X24 -> 2449 | Y25: =X25-X24 -> 0 | Z25: =Z24 -> 137586 | AA25: =Z25-Z24 -> 0 | AB25: =SUM(Y25*$AB$2) -> 0 | AC25: =AC24 -> 1933 | AD25: =AC25-AC24 -> 0 | AE25: =AE24 -> 365262 | AF25: =AE25-AE24 -> 0 | AG25: =IF(AD25>0,AF25/AD25,0) -> 0 | AH25: =AF25+AA25 -> 0 | AI25: =SUM(AH25+V25) -> 137 | AJ25: =-tanks!AW26 -> 137 | AK25: =SUM(AJ25-AI25) -> 0 | AL25: =S25+L25+G25 -> 1 | AM25: =Y25+AD25 -> 0 | AN25: =AN24 -> 68 | AO25: =(AN25/100)*3000 -> 2040 | AP25: =AP24 -> 55 | AQ25: =(AP25/100)*3000 -> 1650 | AR25: =AR24 -> 62 | AS25: =(AR25/100)*3000 -> 1860 | AT25: =SUM(AO25+AQ25+AS25) -> 5550 | AU25: =AT24-AT25+AV25 -> 0 | AX25: =IF(AV25>0,AW25,AX24) -> 0.8
A26: =ELEC!C24 -> 44157 | B26: 237 | C26: 243 | D26: =C25-C26 -> 1 | E26: =D26*8.38 -> 8.38 | F26: =F25 -> 1660 | G26: =F26-F25 -> 0 | H26: =H25 -> 357869 | I26: =SUM(H26-H25) -> 0 | J26: =IF(G26>0,I26/G26,0) -> 0 | K26: 2151 | L26: =K26-K25 -> 3 | M26: 157944 | N26: =M26-M25 -> 237 | O26: =O25 -> 1869 | P26: =P25 -> 1880 | Q26: =Q25 -> 159812 | R26: =Q26-Q25 -> 0 | S26: =SUM(P26-P25) -> 0 | T26: =SUM(S26*$T$2) -> 0 | U26: =SUM(G26+L26+S26) -> 3 | V26: =R26+N26+I26:I26 -> 237 | X26: =X25 -> 2449 | Y26: =X26-X25 -> 0 | Z26: =Z25 -> 137586 | AA26: =Z26-Z25 -> 0 | AB26: =SUM(Y26*$AB$2) -> 0 | AC26: =AC25 -> 1933 | AD26: =AC26-AC25 -> 0 | AE26: =AE25 -> 365262 | AF26: =AE26-AE25 -> 0 | AG26: =IF(AD26>0,AF26/AD26,0) -> 0 | AH26: =AF26+AA26 -> 0 | AI26: =SUM(AH26+V26) -> 237 | AJ26: =-tanks!AW27 -> 237 | AK26: =SUM(AJ26-AI26) -> 0 | AL26: =S26+L26+G26 -> 3 | AM26: =Y26+AD26 -> 0 | AN26: =AN25 -> 68 | AO26: =(AN26/100)*3000 -> 2040 | AP26: =AP25 -> 55 | AQ26: =(AP26/100)*3000 -> 1650 | AR26: =AR25 -> 62 | AS26: =(AR26/100)*3000 -> 1860 | AT26: =SUM(AO26+AQ26+AS26) -> 5550 | AU26: =AT25-AT26+AV26 -> 0 | AX26: =IF(AV26>0,AW26,AX25) -> 0.8
