Workbook

Sheet TOTAL
A1: Site Name | B1: Day | C1: Month | D1: Year | E1: Total Electricity Kwh | F1: Electricity Tariff ($/Kwh) | G1: Natual Gas (m3) | H1: Natural Gas $/m3 | I1: Water Utility Supply (m3) m3 | J1: Water Utility Supply (m3) $/m3 | K1: Room Nights | L1: Total Guests
A2: Hampshire | B2: 1 | C2: 10 | D2: 2020 | E2: =(Submetering!E2+Submetering!F2) -> 9420 | F2: 0.142 | G2: =Submetering!M2 -> 1058 | H2: 0.16 | I2: =Submetering!N2 -> 241 | J2: 2.06 | K2: ='Hampshire Daily'!B5 -> 58 | L2: =Submetering!AA2 -> 115
A3: Hampshire | B3: =B2+1 -> 2 | C3: 10 | D3: 2020 | E3: =Submetering!E3+Submetering!F3 -> 7010 | F3: 0.142 | G3: =Submetering!M3 -> 1853 | H3: 0.16 | I3: =Submetering!N3 -> 76 | J3: 2.06 | K3: ='Hampshire Daily'!B6 -> 73 | L3: =Submetering!AA3 -> 178
A4: Hampshire | B4: =B3+1 -> 3 | C4: 10 | D4: 2020 | E4: =Submetering!E4+Submetering!F4 -> 7440 | F4: 0.142 | G4: =Submetering!M4 -> 2091 | H4: 0.16 | I4: =Submetering!N4 -> 128 | J4: 2.06 | K4: ='Hampshire Daily'!B7 -> 94 | L4: =Submetering!AA4 -> 225
A5: Hampshire | B5: =B4+1 -> 4 | C5: 10 | D5: 2020 | E5: =Submetering!E5+Submetering!F5 -> 8270 | F5: 0.142 | G5: =Submetering!M5 -> 2368 | H5: 0.16 | I5: =Submetering!N5 -> 128 | J5: 2.06 | K5: ='Hampshire Daily'!B8 -> 28 | L5: =Submetering!AA5 -> 70
A6: Hampshire | B6: =B5+1 -> 5 | C6: 10 | D6: 2020 | E6: =Submetering!E6+Submetering!F6 -> 5890 | F6: 0.142 | G6: =Submetering!M6 -> 1885 | H6: 0.16 | I6: =Submetering!N6 -> 239 | J6: 2.06 | K6: ='Hampshire Daily'!B9 -> 19 | L6: =Submetering!AA6 -> 53
A7: Hampshire | B7: =B6+1 -> 6 | C7: 10 | D7: 2020 | E7: =Submetering!E7+Submetering!F7 -> 6640 | F7: 0.142 | G7: =Submetering!M7 -> 1981 | H7: 0.16 | I7: =Submetering!N7 -> 92 | J7: 2.06 | K7: ='Hampshire Daily'!B10 -> 34 | L7: =Submetering!AA7 -> 73
A8: Hampshire | B8: =B7+1 -> 7 | C8: 10 | D8: 2020 | E8: =Submetering!E8+Submetering!F8 -> 7430 | F8: 0.142 | G8: =Submetering!M8 -> 1843 | H8: 0.16 | I8: =Submetering!N8 -> 114 | J8: 2.06 | K8: ='Hampshire Daily'!B11 -> 27 | L8: =Submetering!AA8 -> 64
A9: Hampshire | B9: =B8+1 -> 8 | C9: 10 | D9: 2020 | E9: =Submetering!E9+Submetering!F9 -> 6750 | F9: 0.142 | G9: =Submetering!M9 -> 1900 | H9: 0.16 | I9: =Submetering!N9 -> 141 | J9: 2.06 | K9: ='Hampshire Daily'!B12 -> 38 | L9: =Submetering!AA9 -> 92
A10: Hampshire | B10: =B9+1 -> 9 | C10: 10 | D10: 2020 | E10: =Submetering!E10+Submetering!F10 -> 7010 | F10: 0.142 | G10: =Submetering!M10 -> 1984 | H10: 0.16 | I10: =Submetering!N10 -> 108 | J10: 2.06 | K10: ='Hampshire Daily'!B13 -> 83 | L10: =Submetering!AA10 -> 190
A11: Hampshire | B11: =B10+1 -> 10 | C11: 10 | D11: 2020 | E11: =Submetering!E11+Submetering!F11 -> 7370 | F11: 0.142 | G11: =Submetering!M11 -> 2344 | H11: 0.16 | I11: =Submetering!N11 -> 132 | J11: 2.06 | K11: ='Hampshire Daily'!B14 -> 108 | L11: =Submetering!AA11 -> 268
A12: Hampshire | B12: =B11+1 -> 11 | C12: 10 | D12: 2020 | E12: =Submetering!E12+Submetering!F12 -> 7450 | F12: 0.142 | G12: =Submetering!M12 -> 2519 | H12: 0.16 | I12: =Submetering!N12 -> 90 | J12: 2.06 | K12: ='Hampshire Daily'!B15 -> 57 | L12: =Submetering!AA12 -> 144
A13: Hampshire | B13: =B12+1 -> 12 | C13: 10 | D13: 2020 | E13: =Submetering!E13+Submetering!F13 -> 7000 | F13: 0.142 | G13: =Submetering!M13 -> 2320 | H13: 0.16 | I13: =Submetering!N13 -> 218 | J13: 2.06 | K13: ='Hampshire Daily'!B16 -> 37 | L13: =Submetering!AA13 -> 92
A14: Hampshire | B14: =B13+1 -> 13 | C14: 10 | D14: 2020 | E14: =Submetering!E14+Submetering!F14 -> 15070 | F14: 0.142 | G14: =Submetering!M14 -> 2324 | H14: 0.16 | I14: =Submetering!N14 -> 128 | J14: 2.06 | K14: ='Hampshire Daily'!B17 -> 30 | L14: =Submetering!AA14 -> 70
... A32: Hampshire | B32: =B31+1 -> 31 | C32: 10 | D32: 2020 | E32: =Submetering!E32+Submetering!F32 -> 4606 | F32: 0.142 | G32: =Submetering!M32 -> 2419 | H32: 0.16 | I32: =Submetering!N32 -> 33 | J32: 2.06 | K32: ='Hampshire Daily'!B35 -> 91 | L32: =Submetering!AA32 -> 260
O33: NOV | P33: NOV
N35: 108 | O35: 28 | P35: =N35+O35 -> 136
N36: 117 | O36: 37 | P36: =N36+O36 -> 154
N37: 108 | O37: 24 | P37: =N37+O37 -> 132
N38: 38 | O38: 14 | P38: =N38+O38 -> 52
N39: 13 | O39: 0 | P39: =N39+O39 -> 13
N40: 13 | O40: 0 | P40: =N40+O40 -> 13
N41: 13 | O41: 0 | P41: =N41+O41 -> 13
N42: 13 | O42: 0 | P42: =N42+O42 -> 13
N43: 13 | O43: 0 | P43: =N43+O43 -> 13
N44: 13 | O44: 0 | P44: =N44+O44 -> 13
N45: 13 | O45: 0 | P45: =N45+O45 -> 13
N46: 13 | O46: 0 | P46: =N46+O46 -> 13
... N63: 7 | O63: 0 | P63: =N63+O63 -> 7
N64: - | O64: 0 | P64: =N64+O64 -> #VALUE!

Sheet Submetering
A1: Site Name | B1: Day | C1: Month | D1: Year | E1: Meter 1- KWh | F1: Meter 2- KWh | G1: East MCC- KWh | H1: South MCC 1- KWh | I1: South MCC 2- KWh | J1: West MCC- KWh | K1: Kitchen - KWh | L1: SPA - KWh | M1: Gas- KWh | N1: Main Site Water Meter - m3 | O1: Chiller 2- m3 | P1: Chiller 3- m3 | Q1: Chiller 4- m3 | R1: Hard Water Supply- m3 | S1: Pool Supply- m3 | T1: CL02- m3 | U1: LTHW SPA- m3 | V1: LTHW East- m3 | W1: Chilled make-up- m3 | X1: Orchard irrigation- m3 | Y1: Kids Pool- m3 | Z1: Room Nights | AA1: Total Guests
A2: Hampshire | B2: 1 | C2: 10 | D2: 2020 | E2: =IF(('Hampshire Daily'!D5-'Hampshire Daily'!D4<0), "0",('Hampshire Daily'!D5-'Hampshire Daily'!D4)*10) -> 5140 | F2: =IF(('Hampshire Daily'!F5-'Hampshire Daily'!F4<0), "0",('Hampshire Daily'!F5-'Hampshire Daily'!F4)*10) -> 4280 | G2: =IF(('Hampshire Daily'!H5-'Hampshire Daily'!H4<0), "0",'Hampshire Daily'!H5-'Hampshire Daily'!H4) -> 845 | H2: =IF(('Hampshire Daily'!I5-'Hampshire Daily'!I4<0), "0",'Hampshire Daily'!I5-'Hampshire Daily'!I4) -> 0 | I2: =IF(('Hampshire Daily'!J5-'Hampshire Daily'!J4<0), "0",'Hampshire Daily'!J5-'Hampshire Daily'!J4) -> 0 | J2: =IF(('Hampshire Daily'!K5-'Hampshire Daily'!K4<0), "0",'Hampshire Daily'!K5-'Hampshire Daily'!K4) -> 0 | K2: =IF(('Hampshire Daily'!L5-'Hampshire Daily'!L4<0), "0",'Hampshire Daily'!L5-'Hampshire Daily'!L4) -> 1590 | L2: =IF(('Hampshire Daily'!M5-'Hampshire Daily'!M4<0), "0",'Hampshire Daily'!M5-'Hampshire Daily'!M4) -> 500 | M2: =IF(('Hampshire Daily'!N5-'Hampshire Daily'!N4<0), "0",'Hampshire Daily'!N5-'Hampshire Daily'!N4) -> 1058 | N2: =IF(('Hampshire Daily'!O5-'Hampshire Daily'!O4<0), "0",'Hampshire Daily'!O5-'Hampshire Daily'!O4) -> 241 | ... Q2: =IF(('Hampshire Daily'!R5-'Hampshire Daily'!R4<0), "0",'Hampshire Daily'!R5-'Hampshire Daily'!R4) -> 3 | R2: =IF(('Hampshire Daily'!U5-'Hampshire Daily'!U4<0), "0",'Hampshire Daily'!U5-'Hampshire Daily'!U4) -> 10 | S2: =IF(('Hampshire Daily'!V5-'Hampshire Daily'!V4<0), "0",'Hampshire Daily'!V5-'Hampshire Daily'!V4) -> 13 | T2: =IF(('Hampshire Daily'!Y5-'Hampshire Daily'!W4<0), "0",'Hampshire Daily'!Y5-'Hampshire Daily'!W4) -> 855.347 | U2: =IF(('Hampshire Daily'!X5-'Hampshire Daily'!X4<0), "0",'Hampshire Daily'!X5-'Hampshire Daily'!X4) -> 2.777 | V2: =IF(('Hampshire Daily'!Y5-'Hampshire Daily'!Y4<0), "0",'Hampshire Daily'!Y5-'Hampshire Daily'!Y4) -> 0 | W2: =IF(('Hampshire Daily'!Z5-'Hampshire Daily'!Z4<0), "0",'Hampshire Daily'!Z5-'Hampshire Daily'!Z4) -> 0.029 | X2: 23 | Y2: 6 | Z2: ='Hampshire Daily'!B5 -> 58 | AA2: ='Hampshire Daily'!C5 -> 115
A3: Hampshire | B3: =B2+1 -> 2 | C3: 10 | D3: 2020 | E3: =IF(('Hampshire Daily'!D6-'Hampshire Daily'!D5<0), "0",('Hampshire Daily'!D6-'Hampshire Daily'!D5)*10) -> 2280 | F3: =IF(('Hampshire Daily'!F6-'Hampshire Daily'!F5<0), "0",('Hampshire Daily'!F6-'Hampshire Daily'!F5)*10) -> 4730 | G3: =IF(('Hampshire Daily'!H6-'Hampshire Daily'!H5<0), "0",'Hampshire Daily'!H6-'Hampshire Daily'!H5) -> 795 | H3: =IF(('Hampshire Daily'!I6-'Hampshire Daily'!I5<0), "0",'Hampshire Daily'!I6-'Hampshire Daily'!I5) -> 0 | I3: =IF(('Hampshire Daily'!J6-'Hampshire Daily'!J5<0), "0",'Hampshire Daily'!J6-'Hampshire Daily'!J5) -> 0 | J3: =IF(('Hampshire Daily'!K6-'Hampshire Daily'!K5<0), "0",'Hampshire Daily'!K6-'Hampshire Daily'!K5) -> 0 | K3: =IF(('Hampshire Daily'!L6-'Hampshire Daily'!L5<0), "0",'Hampshire Daily'!L6-'Hampshire Daily'!L5) -> 938 | L3: =IF(('Hampshire Daily'!M6-'Hampshire Daily'!M5<0), "0",'Hampshire Daily'!M6-'Hampshire Daily'!M5) -> 0 | M3: =IF(('Hampshire Daily'!N6-'Hampshire Daily'!N5<0), "0",'Hampshire Daily'!N6-'Hampshire Daily'!N5) -> 1853 | N3: =IF(('Hampshire Daily'!O6-'Hampshire Daily'!O5<0), "0",'Hampshire Daily'!O6-'Hampshire Daily'!O5) -> 76 | ... Q3: =IF(('Hampshire Daily'!R6-'Hampshire Daily'!R5<0), "0",'Hampshire Daily'!R6-'Hampshire Daily'!R5) -> 0 | R3: =IF(('Hampshire Daily'!U6-'Hampshire Daily'!U5<0), "0",'Hampshire Daily'!U6-'Hampshire Daily'!U5) -> 11 | S3: =IF(('Hampshire Daily'!V6-'Hampshire Daily'!V5<0), "0",'Hampshire Daily'!V6-'Hampshire Daily'!V5) -> 0 | T3: =IF(('Hampshire Daily'!Y6-'Hampshire Daily'!Y5<0), "0",'Hampshire Daily'!Y6-'Hampshire Daily'!Y5) -> 0.286 | U3: =IF(('Hampshire Daily'!X6-'Hampshire Daily'!X5<0), "0",'Hampshire Daily'!X6-'Hampshire Daily'!X5) -> 2.009 | V3: =IF(('Hampshire Daily'!Y6-'Hampshire Daily'!Y5<0), "0",'Hampshire Daily'!Y6-'Hampshire Daily'!Y5) -> 0.286 | W3: =IF(('Hampshire Daily'!Z6-'Hampshire Daily'!Z5<0), "0",'Hampshire Daily'!Z6-'Hampshire Daily'!Z5) -> 0.008 | X3: =IF(('Hampshire Daily'!AA6-'Hampshire Daily'!AA5<0), "0",'Hampshire Daily'!AA6-'Hampshire Daily'!AA5) -> 23 | Y3: =IF(('Hampshire Daily'!AB6-'Hampshire Daily'!AB5<0), "0",'Hampshire Daily'!AB6-'Hampshire Daily'!AB5) -> 6 | Z3: ='Hampshire Daily'!B6 -> 73 | AA3: ='Hampshire Daily'!C6 -> 178
A4: Hampshire | B4: =B3+1 -> 3 | C4: 10 | D4: 2020 | E4: =IF(('Hampshire Daily'!D7-'Hampshire Daily'!D6<0), "0",('Hampshire Daily'!D7-'Hampshire Daily'!D6)*10) -> 2380 | F4: =IF(('Hampshire Daily'!F7-'Hampshire Daily'!F6<0), "0",('Hampshire Daily'!F7-'Hampshire Daily'!F6)*10) -> 5060 | G4: =IF(('Hampshire Daily'!H7-'Hampshire Daily'!H6<0), "0",'Hampshire Daily'!H7-'Hampshire Daily'!H6) -> 776 | H4: =IF(('Hampshire Daily'!I7-'Hampshire Daily'!I6<0), "0",'Hampshire Daily'!I7-'Hampshire Daily'!I6) -> 0 | I4: =IF(('Hampshire Daily'!J7-'Hampshire Daily'!J6<0), "0",'Hampshire Daily'!J7-'Hampshire Daily'!J6) -> 0 | J4: =IF(('Hampshire Daily'!K7-'Hampshire Daily'!K6<0), "0",'Hampshire Daily'!K7-'Hampshire Daily'!K6) -> 0 | K4: =IF(('Hampshire Daily'!L7-'Hampshire Daily'!L6<0), "0",'Hampshire Daily'!L7-'Hampshire Daily'!L6) -> 938 | L4: =IF(('Hampshire Daily'!M7-'Hampshire Daily'!M6<0), "0",'Hampshire Daily'!M7-'Hampshire Daily'!M6) -> 0 | M4: =IF(('Hampshire Daily'!N7-'Hampshire Daily'!N6<0), "0",'Hampshire Daily'!N7-'Hampshire Daily'!N6) -> 2091 | N4: =IF(('Hampshire Daily'!O7-'Hampshire Daily'!O6<0), "0",'Hampshire Daily'!O7-'Hampshire Daily'!O6) -> 128 | ... Q4: =IF(('Hampshire Daily'!R7-'Hampshire Daily'!R6<0), "0",'Hampshire Daily'!R7-'Hampshire Daily'!R6) -> 0 | R4: =IF(('Hampshire Daily'!U7-'Hampshire Daily'!U6<0), "0",'Hampshire Daily'!U7-'Hampshire Daily'!U6) -> 12 | S4: =IF(('Hampshire Daily'!V7-'Hampshire Daily'!V6<0), "0",'Hampshire Daily'!V7-'Hampshire Daily'!V6) -> 0 | T4: =IF(('Hampshire Daily'!Y7-'Hampshire Daily'!Y6<0), "0",'Hampshire Daily'!Y7-'Hampshire Daily'!Y6) -> 0.022 | U4: =IF(('Hampshire Daily'!X7-'Hampshire Daily'!X6<0), "0",'Hampshire Daily'!X7-'Hampshire Daily'!X6) -> 2.054 | V4: =IF(('Hampshire Daily'!Y7-'Hampshire Daily'!Y6<0), "0",'Hampshire Daily'!Y7-'Hampshire Daily'!Y6) -> 0.022 | W4: =IF(('Hampshire Daily'!Z7-'Hampshire Daily'!Z6<0), "0",'Hampshire Daily'!Z7-'Hampshire Daily'!Z6) -> 0.005 | X4: =IF(('Hampshire Daily'!AA7-'Hampshire Daily'!AA6<0), "0",'Hampshire Daily'!AA7-'Hampshire Daily'!AA6) -> 31 | Y4: =IF(('Hampshire Daily'!AB7-'Hampshire Daily'!AB6<0), "0",'Hampshire Daily'!AB7-'Hampshire Daily'!AB6) -> 7 | Z4: ='Hampshire Daily'!B7 -> 94 | AA4: ='Hampshire Daily'!C7 -> 225
A5: Hampshire | B5: =B4+1 -> 4 | C5: 10 | D5: 2020 | E5: =IF(('Hampshire Daily'!D8-'Hampshire Daily'!D7<0), "0",('Hampshire Daily'!D8-'Hampshire Daily'!D7)*10) -> 2660 | F5: =IF(('Hampshire Daily'!F8-'Hampshire Daily'!F7<0), "0",('Hampshire Daily'!F8-'Hampshire Daily'!F7)*10) -> 5610 | G5: =IF(('Hampshire Daily'!H8-'Hampshire Daily'!H7<0), "0",'Hampshire Daily'!H8-'Hampshire Daily'!H7) -> 363 | H5: =IF(('Hampshire Daily'!I8-'Hampshire Daily'!I7<0), "0",'Hampshire Daily'!I8-'Hampshire Daily'!I7) -> 0 | I5: =IF(('Hampshire Daily'!J8-'Hampshire Daily'!J7<0), "0",'Hampshire Daily'!J8-'Hampshire Daily'!J7) -> 0 | J5: =IF(('Hampshire Daily'!K8-'Hampshire Daily'!K7<0), "0",'Hampshire Daily'!K8-'Hampshire Daily'!K7) -> 0 | K5: =IF(('Hampshire Daily'!L8-'Hampshire Daily'!L7<0), "0",'Hampshire Daily'!L8-'Hampshire Daily'!L7) -> 938 | L5: =IF(('Hampshire Daily'!M8-'Hampshire Daily'!M7<0), "0",'Hampshire Daily'!M8-'Hampshire Daily'!M7) -> 0 | M5: =IF(('Hampshire Daily'!N8-'Hampshire Daily'!N7<0), "0",'Hampshire Daily'!N8-'Hampshire Daily'!N7) -> 2368 | N5: =IF(('Hampshire Daily'!O8-'Hampshire Daily'!O7<0), "0",'Hampshire Daily'!O8-'Hampshire Daily'!O7) -> 128 | ... Q5: =IF(('Hampshire Daily'!R8-'Hampshire Daily'!R7<0), "0",'Hampshire Daily'!R8-'Hampshire Daily'!R7) -> 0 | R5: =IF(('Hampshire Daily'!U8-'Hampshire Daily'!U7<0), "0",'Hampshire Daily'!U8-'Hampshire Daily'!U7) -> 11 | S5: =IF(('Hampshire Daily'!V8-'Hampshire Daily'!V7<0), "0",'Hampshire Daily'!V8-'Hampshire Daily'!V7) -> 0 | T5: =IF(('Hampshire Daily'!Y8-'Hampshire Daily'!Y7<0), "0",'Hampshire Daily'!Y8-'Hampshire Daily'!Y7) -> 0.025 | U5: =IF(('Hampshire Daily'!X8-'Hampshire Daily'!X7<0), "0",'Hampshire Daily'!X8-'Hampshire Daily'!X7) -> 2.054 | V5: =IF(('Hampshire Daily'!Y8-'Hampshire Daily'!Y7<0), "0",'Hampshire Daily'!Y8-'Hampshire Daily'!Y7) -> 0.025 | W5: =IF(('Hampshire Daily'!Z8-'Hampshire Daily'!Z7<0), "0",'Hampshire Daily'!Z8-'Hampshire Daily'!Z7) -> 0.014 | X5: =IF(('Hampshire Daily'!AA8-'Hampshire Daily'!AA7<0), "0",'Hampshire Daily'!AA8-'Hampshire Daily'!AA7) -> 23 | Y5: =IF(('Hampshire Daily'!AB8-'Hampshire Daily'!AB7<0), "0",'Hampshire Daily'!AB8-'Hampshire Daily'!AB7) -> 0 | Z5: ='Hampshire Daily'!B8 -> 28 | AA5: ='Hampshire Daily'!C8 -> 70
A6: Hampshire | B6: =B5+1 -> 5 | C6: 10 | D6: 2020 | E6: =IF(('Hampshire Daily'!D9-'Hampshire Daily'!D8<0), "0",('Hampshire Daily'!D9-'Hampshire Daily'!D8)*10) -> 1730 | F6: =IF(('Hampshire Daily'!F9-'Hampshire Daily'!F8<0), "0",('Hampshire Daily'!F9-'Hampshire Daily'!F8)*10) -> 4160 | G6: =IF(('Hampshire Daily'!H9-'Hampshire Daily'!H8<0), "0",'Hampshire Daily'!H9-'Hampshire Daily'!H8) -> 1256 | H6: =IF(('Hampshire Daily'!I9-'Hampshire Daily'!I8<0), "0",'Hampshire Daily'!I9-'Hampshire Daily'!I8) -> 0 | I6: =IF(('Hampshire Daily'!J9-'Hampshire Daily'!J8<0), "0",'Hampshire Daily'!J9-'Hampshire Daily'!J8) -> 0 | J6: =IF(('Hampshire Daily'!K9-'Hampshire Daily'!K8<0), "0",'Hampshire Daily'!K9-'Hampshire Daily'!K8) -> 0 | K6: =IF(('Hampshire Daily'!L9-'Hampshire Daily'!L8<0), "0",'Hampshire Daily'!L9-'Hampshire Daily'!L8) -> 938 | L6: =IF(('Hampshire Daily'!M9-'Hampshire Daily'!M8<0), "0",'Hampshire Daily'!M9-'Hampshire Daily'!M8) -> 180 | M6: =IF(('Hampshire Daily'!N9-'Hampshire Daily'!N8<0), "0",'Hampshire Daily'!N9-'Hampshire Daily'!N8) -> 1885 | N6: =IF(('Hampshire Daily'!O9-'Hampshire Daily'!O8<0), "0",'Hampshire Daily'!O9-'Hampshire Daily'!O8) -> 239 | ... Q6: =IF(('Hampshire Daily'!R9-'Hampshire Daily'!R8<0), "0",'Hampshire Daily'!R9-'Hampshire Daily'!R8) -> 0 | R6: =IF(('Hampshire Daily'!U9-'Hampshire Daily'!U8<0), "0",'Hampshire Daily'!U9-'Hampshire Daily'!U8) -> 12 | S6: =IF(('Hampshire Daily'!V9-'Hampshire Daily'!V8<0), "0",'Hampshire Daily'!V9-'Hampshire Daily'!V8) -> 3 | T6: =IF(('Hampshire Daily'!Y9-'Hampshire Daily'!Y8<0), "0",'Hampshire Daily'!Y9-'Hampshire Daily'!Y8) -> 0.025 | U6: =IF(('Hampshire Daily'!X9-'Hampshire Daily'!X8<0), "0",'Hampshire Daily'!X9-'Hampshire Daily'!X8) -> 2.076 | V6: =IF(('Hampshire Daily'!Y9-'Hampshire Daily'!Y8<0), "0",'Hampshire Daily'!Y9-'Hampshire Daily'!Y8) -> 0.025 | W6: =IF(('Hampshire Daily'!Z9-'Hampshire Daily'!Z8<0), "0",'Hampshire Daily'!Z9-'Hampshire Daily'!Z8) -> 0.01 | X6: =IF(('Hampshire Daily'!AA9-'Hampshire Daily'!AA8<0), "0",'Hampshire Daily'!AA9-'Hampshire Daily'!AA8) -> 15 | Y6: =IF(('Hampshire Daily'!AB9-'Hampshire Daily'!AB8<0), "0",'Hampshire Daily'!AB9-'Hampshire Daily'!AB8) -> 36 | Z6: ='Hampshire Daily'!B9 -> 19 | AA6: ='Hampshire Daily'!C9 -> 53
A7: Hampshire | B7: =B6+1 -> 6 | C7: 10 | D7: 2020 | E7: =IF(('Hampshire Daily'!D10-'Hampshire Daily'!D9<0), "0",('Hampshire Daily'!D10-'Hampshire Daily'!D9)*10) -> 1980 | F7: =IF(('Hampshire Daily'!F10-'Hampshire Daily'!F9<0), "0",('Hampshire Daily'!F10-'Hampshire Daily'!F9)*10) -> 4660 | G7: =IF(('Hampshire Daily'!H10-'Hampshire Daily'!H9<0), "0",'Hampshire Daily'!H10-'Hampshire Daily'!H9) -> 805 | H7: =IF(('Hampshire Daily'!I10-'Hampshire Daily'!I9<0), "0",'Hampshire Daily'!I10-'Hampshire Daily'!I9) -> 0 | I7: =IF(('Hampshire Daily'!J10-'Hampshire Daily'!J9<0), "0",'Hampshire Daily'!J10-'Hampshire Daily'!J9) -> 0 | J7: =IF(('Hampshire Daily'!K10-'Hampshire Daily'!K9<0), "0",'Hampshire Daily'!K10-'Hampshire Daily'!K9) -> 0 | K7: =IF(('Hampshire Daily'!L10-'Hampshire Daily'!L9<0), "0",'Hampshire Daily'!L10-'Hampshire Daily'!L9) -> 938 | L7: =IF(('Hampshire Daily'!M10-'Hampshire Daily'!M9<0), "0",'Hampshire Daily'!M10-'Hampshire Daily'!M9) -> 0 | M7: =IF(('Hampshire Daily'!N10-'Hampshire Daily'!N9<0), "0",'Hampshire Daily'!N10-'Hampshire Daily'!N9) -> 1981 | N7: =IF(('Hampshire Daily'!O10-'Hampshire Daily'!O9<0), "0",'Hampshire Daily'!O10-'Hampshire Daily'!O9) -> 92 | ... Q7: =IF(('Hampshire Daily'!R10-'Hampshire Daily'!R9<0), "0",'Hampshire Daily'!R10-'Hampshire Daily'!R9) -> 0 | R7: =IF(('Hampshire Daily'!U10-'Hampshire Daily'!U9<0), "0",'Hampshire Daily'!U10-'Hampshire Daily'!U9) -> 10 | S7: =IF(('Hampshire Daily'!V10-'Hampshire Daily'!V9<0), "0",'Hampshire Daily'!V10-'Hampshire Daily'!V9) -> 1 | T7: =IF(('Hampshire Daily'!Y10-'Hampshire Daily'!Y9<0), "0",'Hampshire Daily'!Y10-'Hampshire Daily'!Y9) -> 0.003 | U7: =IF(('Hampshire Daily'!X10-'Hampshire Daily'!X9<0), "0",'Hampshire Daily'!X10-'Hampshire Daily'!X9) -> 2.104 | V7: =IF(('Hampshire Daily'!Y10-'Hampshire Daily'!Y9<0), "0",'Hampshire Daily'!Y10-'Hampshire Daily'!Y9) -> 0.003 | W7: =IF(('Hampshire Daily'!Z10-'Hampshire Daily'!Z9<0), "0",'Hampshire Daily'!Z10-'Hampshire Daily'!Z9) -> 0.009 | X7: =IF(('Hampshire Daily'!AA10-'Hampshire Daily'!AA9<0), "0",'Hampshire Daily'!AA10-'Hampshire Daily'!AA9) -> 24 | Y7: =IF(('Hampshire Daily'!AB10-'Hampshire Daily'!AB9<0), "0",'Hampshire Daily'!AB10-'Hampshire Daily'!AB9) -> 8 | Z7: ='Hampshire Daily'!B10 -> 34 | AA7: ='Hampshire Daily'!C10 -> 73
A8: Hampshire | B8: =B7+1 -> 7 | C8: 10 | D8: 2020 | E8: =IF(('Hampshire Daily'!D11-'Hampshire Daily'!D10<0), "0",('Hampshire Daily'!D11-'Hampshire Daily'!D10)*10) -> 2790 | F8: =IF(('Hampshire Daily'!F11-'Hampshire Daily'!F10<0), "0",('Hampshire Daily'!F11-'Hampshire Daily'!F10)*10) -> 4640 | G8: =IF(('Hampshire Daily'!H11-'Hampshire Daily'!H10<0), "0",'Hampshire Daily'!H11-'Hampshire Daily'!H10) -> 841 | H8: =IF(('Hampshire Daily'!I11-'Hampshire Daily'!I10<0), "0",'Hampshire Daily'!I11-'Hampshire Daily'!I10) -> 0 | I8: =IF(('Hampshire Daily'!J11-'Hampshire Daily'!J10<0), "0",'Hampshire Daily'!J11-'Hampshire Daily'!J10) -> 0 | J8: =IF(('Hampshire Daily'!K11-'Hampshire Daily'!K10<0), "0",'Hampshire Daily'!K11-'Hampshire Daily'!K10) -> 0 | K8: =IF(('Hampshire Daily'!L11-'Hampshire Daily'!L10<0), "0",'Hampshire Daily'!L11-'Hampshire Daily'!L10) -> 938 | L8: =IF(('Hampshire Daily'!M11-'Hampshire Daily'!M10<0), "0",'Hampshire Daily'!M11-'Hampshire Daily'!M10) -> 178 | M8: =IF(('Hampshire Daily'!N11-'Hampshire Daily'!N10<0), "0",'Hampshire Daily'!N11-'Hampshire Daily'!N10) -> 1843 | N8: =IF(('Hampshire Daily'!O11-'Hampshire Daily'!O10<0), "0",'Hampshire Daily'!O11-'Hampshire Daily'!O10) -> 114 | ... Q8: =IF(('Hampshire Daily'!R11-'Hampshire Daily'!R10<0), "0",'Hampshire Daily'!R11-'Hampshire Daily'!R10) -> 0 | R8: =IF(('Hampshire Daily'!U11-'Hampshire Daily'!U10<0), "0",'Hampshire Daily'!U11-'Hampshire Daily'!U10) -> 8 | S8: =IF(('Hampshire Daily'!V11-'Hampshire Daily'!V10<0), "0",'Hampshire Daily'!V11-'Hampshire Daily'!V10) -> 1 | T8: =IF(('Hampshire Daily'!Y11-'Hampshire Daily'!Y10<0), "0",'Hampshire Daily'!Y11-'Hampshire Daily'!Y10) -> 0.02 | U8: =IF(('Hampshire Daily'!X11-'Hampshire Daily'!X10<0), "0",'Hampshire Daily'!X11-'Hampshire Daily'!X10) -> 2.099 | V8: =IF(('Hampshire Daily'!Y11-'Hampshire Daily'!Y10<0), "0",'Hampshire Daily'!Y11-'Hampshire Daily'!Y10) -> 0.02 | W8: =IF(('Hampshire Daily'!Z11-'Hampshire Daily'!Z10<0), "0",'Hampshire Daily'!Z11-'Hampshire Daily'!Z10) -> 0.009 | X8: =IF(('Hampshire Daily'!AA11-'Hampshire Daily'!AA10<0), "0",'Hampshire Daily'!AA11-'Hampshire Daily'!AA10) -> 23 | Y8: =IF(('Hampshire Daily'!AB11-'Hampshire Daily'!AB10<0), "0",'Hampshire Daily'!AB11-'Hampshire Daily'!AB10) -> 4 | Z8: ='Hampshire Daily'!B11 -> 27 | AA8: ='Hampshire Daily'!C11 -> 64
A9: Hampshire | B9: =B8+1 -> 8 | C9: 10 | D9: 2020 | E9: =IF(('Hampshire Daily'!D12-'Hampshire Daily'!D11<0), "0",('Hampshire Daily'!D12-'Hampshire Daily'!D11)*10) -> 1910 | F9: =IF(('Hampshire Daily'!F12-'Hampshire Daily'!F11<0), "0",('Hampshire Daily'!F12-'Hampshire Daily'!F11)*10) -> 4840 | G9: =IF(('Hampshire Daily'!H12-'Hampshire Daily'!H11<0), "0",'Hampshire Daily'!H12-'Hampshire Daily'!H11) -> 363 | H9: =IF(('Hampshire Daily'!I12-'Hampshire Daily'!I11<0), "0",'Hampshire Daily'!I12-'Hampshire Daily'!I11) -> 0 | I9: =IF(('Hampshire Daily'!J12-'Hampshire Daily'!J11<0), "0",'Hampshire Daily'!J12-'Hampshire Daily'!J11) -> 0 | J9: =IF(('Hampshire Daily'!K12-'Hampshire Daily'!K11<0), "0",'Hampshire Daily'!K12-'Hampshire Daily'!K11) -> 0 | K9: =IF(('Hampshire Daily'!L12-'Hampshire Daily'!L11<0), "0",'Hampshire Daily'!L12-'Hampshire Daily'!L11) -> 1394 | L9: =IF(('Hampshire Daily'!M12-'Hampshire Daily'!M11<0), "0",'Hampshire Daily'!M12-'Hampshire Daily'!M11) -> 2 | M9: =IF(('Hampshire Daily'!N12-'Hampshire Daily'!N11<0), "0",'Hampshire Daily'!N12-'Hampshire Daily'!N11) -> 1900 | N9: =IF(('Hampshire Daily'!O12-'Hampshire Daily'!O11<0), "0",'Hampshire Daily'!O12-'Hampshire Daily'!O11) -> 141 | ... Q9: =IF(('Hampshire Daily'!R12-'Hampshire Daily'!R11<0), "0",'Hampshire Daily'!R12-'Hampshire Daily'!R11) -> 0 | R9: =IF(('Hampshire Daily'!U12-'Hampshire Daily'!U11<0), "0",'Hampshire Daily'!U12-'Hampshire Daily'!U11) -> 9 | S9: =IF(('Hampshire Daily'!V12-'Hampshire Daily'!V11<0), "0",'Hampshire Daily'!V12-'Hampshire Daily'!V11) -> 21 | T9: =IF(('Hampshire Daily'!Y12-'Hampshire Daily'!Y11<0), "0",'Hampshire Daily'!Y12-'Hampshire Daily'!Y11) -> 0.009 | U9: =IF(('Hampshire Daily'!X12-'Hampshire Daily'!X11<0), "0",'Hampshire Daily'!X12-'Hampshire Daily'!X11) -> 2.081 | V9: =IF(('Hampshire Daily'!Y12-'Hampshire Daily'!Y11<0), "0",'Hampshire Daily'!Y12-'Hampshire Daily'!Y11) -> 0.009 | W9: =IF(('Hampshire Daily'!Z12-'Hampshire Daily'!Z11<0), "0",'Hampshire Daily'!Z12-'Hampshire Daily'!Z11) -> 0.011 | X9: =IF(('Hampshire Daily'!AA12-'Hampshire Daily'!AA11<0), "0",'Hampshire Daily'!AA12-'Hampshire Daily'!AA11) -> 23 | Y9: =IF(('Hampshire Daily'!AB12-'Hampshire Daily'!AB11<0), "0",'Hampshire Daily'!AB12-'Hampshire Daily'!AB11) -> 5 | Z9: ='Hampshire Daily'!B12 -> 38 | AA9: ='Hampshire Daily'!C12 -> 92
A10: Hampshire | B10: =B9+1 -> 9 | C10: 10 | D10: 2020 | E10: =IF(('Hampshire Daily'!D13-'Hampshire Daily'!D12<0), "0",('Hampshire Daily'!D13-'Hampshire Daily'!D12)*10) -> 2170 | F10: =IF(('Hampshire Daily'!F13-'Hampshire Daily'!F12<0), "0",('Hampshire Daily'!F13-'Hampshire Daily'!F12)*10) -> 4840 | G10: =IF(('Hampshire Daily'!H13-'Hampshire Daily'!H12<0), "0",'Hampshire Daily'!H13-'Hampshire Daily'!H12) -> 1302 | H10: =IF(('Hampshire Daily'!I13-'Hampshire Daily'!I12<0), "0",'Hampshire Daily'!I13-'Hampshire Daily'!I12) -> 0 | I10: =IF(('Hampshire Daily'!J13-'Hampshire Daily'!J12<0), "0",'Hampshire Daily'!J13-'Hampshire Daily'!J12) -> 0 | J10: =IF(('Hampshire Daily'!K13-'Hampshire Daily'!K12<0), "0",'Hampshire Daily'!K13-'Hampshire Daily'!K12) -> 0 | K10: =IF(('Hampshire Daily'!L13-'Hampshire Daily'!L12<0), "0",'Hampshire Daily'!L13-'Hampshire Daily'!L12) -> 1019 | L10: =IF(('Hampshire Daily'!M13-'Hampshire Daily'!M12<0), "0",'Hampshire Daily'!M13-'Hampshire Daily'!M12) -> 24 | M10: =IF(('Hampshire Daily'!N13-'Hampshire Daily'!N12<0), "0",'Hampshire Daily'!N13-'Hampshire Daily'!N12) -> 1984 | N10: =IF(('Hampshire Daily'!O13-'Hampshire Daily'!O12<0), "0",'Hampshire Daily'!O13-'Hampshire Daily'!O12) -> 108 | ... Q10: =IF(('Hampshire Daily'!R13-'Hampshire Daily'!R12<0), "0",'Hampshire Daily'!R13-'Hampshire Daily'!R12) -> 0 | R10: =IF(('Hampshire Daily'!U13-'Hampshire Daily'!U12<0), "0",'Hampshire Daily'!U13-'Hampshire Daily'!U12) -> 8 | S10: =IF(('Hampshire Daily'!V13-'Hampshire Daily'!V12<0), "0",'Hampshire Daily'!V13-'Hampshire Daily'!V12) -> 1 | T10: =IF(('Hampshire Daily'!Y13-'Hampshire Daily'!Y12<0), "0",'Hampshire Daily'!Y13-'Hampshire Daily'!Y12) -> 0.861 | U10: =IF(('Hampshire Daily'!X13-'Hampshire Daily'!X12<0), "0",'Hampshire Daily'!X13-'Hampshire Daily'!X12) -> 2.18 | V10: =IF(('Hampshire Daily'!Y13-'Hampshire Daily'!Y12<0), "0",'Hampshire Daily'!Y13-'Hampshire Daily'!Y12) -> 0.861 | W10: =IF(('Hampshire Daily'!Z13-'Hampshire Daily'!Z12<0), "0",'Hampshire Daily'!Z13-'Hampshire Daily'!Z12) -> 0.013 | X10: =IF(('Hampshire Daily'!AA13-'Hampshire Daily'!AA12<0), "0",'Hampshire Daily'!AA13-'Hampshire Daily'!AA12) -> 23 | Y10: =IF(('Hampshire Daily'!AB13-'Hampshire Daily'!AB12<0), "0",'Hampshire Daily'!AB13-'Hampshire Daily'!AB12) -> 3 | Z10: ='Hampshire Daily'!B13 -> 83 | AA10: ='Hampshire Daily'!C13 -> 190
A11: Hampshire | B11: =B10+1 -> 10 | C11: 10 | D11: 2020 | E11: =IF(('Hampshire Daily'!D14-'Hampshire Daily'!D13<0), "0",('Hampshire Daily'!D14-'Hampshire Daily'!D13)*10) -> 2260 | F11: =IF(('Hampshire Daily'!F14-'Hampshire Daily'!F13<0), "0",('Hampshire Daily'!F14-'Hampshire Daily'!F13)*10) -> 5110 | G11: =IF(('Hampshire Daily'!H14-'Hampshire Daily'!H13<0), "0",'Hampshire Daily'!H14-'Hampshire Daily'!H13) -> 829 | H11: =IF(('Hampshire Daily'!I14-'Hampshire Daily'!I13<0), "0",'Hampshire Daily'!I14-'Hampshire Daily'!I13) -> 0 | I11: =IF(('Hampshire Daily'!J14-'Hampshire Daily'!J13<0), "0",'Hampshire Daily'!J14-'Hampshire Daily'!J13) -> 0 | J11: =IF(('Hampshire Daily'!K14-'Hampshire Daily'!K13<0), "0",'Hampshire Daily'!K14-'Hampshire Daily'!K13) -> 0 | K11: =IF(('Hampshire Daily'!L14-'Hampshire Daily'!L13<0), "0",'Hampshire Daily'!L14-'Hampshire Daily'!L13) -> 938 | L11: =IF(('Hampshire Daily'!M14-'Hampshire Daily'!M13<0), "0",'Hampshire Daily'!M14-'Hampshire Daily'!M13) -> 0 | M11: =IF(('Hampshire Daily'!N14-'Hampshire Daily'!N13<0), "0",'Hampshire Daily'!N14-'Hampshire Daily'!N13) -> 2344 | N11: =IF(('Hampshire Daily'!O14-'Hampshire Daily'!O13<0), "0",'Hampshire Daily'!O14-'Hampshire Daily'!O13) -> 132 | ... Q11: =IF(('Hampshire Daily'!R14-'Hampshire Daily'!R13<0), "0",'Hampshire Daily'!R14-'Hampshire Daily'!R13) -> 0 | R11: =IF(('Hampshire Daily'!U14-'Hampshire Daily'!U13<0), "0",'Hampshire Daily'!U14-'Hampshire Daily'!U13) -> 10 | S11: =IF(('Hampshire Daily'!V14-'Hampshire Daily'!V13<0), "0",'Hampshire Daily'!V14-'Hampshire Daily'!V13) -> 0 | T11: =IF(('Hampshire Daily'!Y14-'Hampshire Daily'!Y13<0), "0",'Hampshire Daily'!Y14-'Hampshire Daily'!Y13) -> 0.171 | U11: =IF(('Hampshire Daily'!X14-'Hampshire Daily'!X13<0), "0",'Hampshire Daily'!X14-'Hampshire Daily'!X13) -> 2.28 | V11: =IF(('Hampshire Daily'!Y14-'Hampshire Daily'!Y13<0), "0",'Hampshire Daily'!Y14-'Hampshire Daily'!Y13) -> 0.171 | W11: =IF(('Hampshire Daily'!Z14-'Hampshire Daily'!Z13<0), "0",'Hampshire Daily'!Z14-'Hampshire Daily'!Z13) -> 0.011 | X11: =IF(('Hampshire Daily'!AA14-'Hampshire Daily'!AA13<0), "0",'Hampshire Daily'!AA14-'Hampshire Daily'!AA13) -> 25 | Y11: =IF(('Hampshire Daily'!AB14-'Hampshire Daily'!AB13<0), "0",'Hampshire Daily'!AB14-'Hampshire Daily'!AB13) -> 7 | Z11: ='Hampshire Daily'!B14 -> 108 | AA11: ='Hampshire Daily'!C14 -> 268
A12: Hampshire | B12: =B11+1 -> 11 | C12: 10 | D12: 2020 | E12: =IF(('Hampshire Daily'!D15-'Hampshire Daily'!D14<0), "0",('Hampshire Daily'!D15-'Hampshire Daily'!D14)*10) -> 2370 | F12: =IF(('Hampshire Daily'!F15-'Hampshire Daily'!F14<0), "0",('Hampshire Daily'!F15-'Hampshire Daily'!F14)*10) -> 5080 | G12: =IF(('Hampshire Daily'!H15-'Hampshire Daily'!H14<0), "0",'Hampshire Daily'!H15-'Hampshire Daily'!H14) -> 832 | H12: =IF(('Hampshire Daily'!I15-'Hampshire Daily'!I14<0), "0",'Hampshire Daily'!I15-'Hampshire Daily'!I14) -> 0 | I12: =IF(('Hampshire Daily'!J15-'Hampshire Daily'!J14<0), "0",'Hampshire Daily'!J15-'Hampshire Daily'!J14) -> 0 | J12: =IF(('Hampshire Daily'!K15-'Hampshire Daily'!K14<0), "0",'Hampshire Daily'!K15-'Hampshire Daily'!K14) -> 0 | K12: =IF(('Hampshire Daily'!L15-'Hampshire Daily'!L14<0), "0",'Hampshire Daily'!L15-'Hampshire Daily'!L14) -> 938 | L12: =IF(('Hampshire Daily'!M15-'Hampshire Daily'!M14<0), "0",'Hampshire Daily'!M15-'Hampshire Daily'!M14) -> 1 | M12: =IF(('Hampshire Daily'!N15-'Hampshire Daily'!N14<0), "0",'Hampshire Daily'!N15-'Hampshire Daily'!N14) -> 2519 | N12: =IF(('Hampshire Daily'!O15-'Hampshire Daily'!O14<0), "0",'Hampshire Daily'!O15-'Hampshire Daily'!O14) -> 90 | ... Q12: =IF(('Hampshire Daily'!R15-'Hampshire Daily'!R14<0), "0",'Hampshire Daily'!R15-'Hampshire Daily'!R14) -> 0 | R12: =IF(('Hampshire Daily'!U15-'Hampshire Daily'!U14<0), "0",'Hampshire Daily'!U15-'Hampshire Daily'!U14) -> 10 | S12: =IF(('Hampshire Daily'!V15-'Hampshire Daily'!V14<0), "0",'Hampshire Daily'!V15-'Hampshire Daily'!V14) -> 1 | T12: =IF(('Hampshire Daily'!Y15-'Hampshire Daily'!Y14<0), "0",'Hampshire Daily'!Y15-'Hampshire Daily'!Y14) -> 0.053 | U12: =IF(('Hampshire Daily'!X15-'Hampshire Daily'!X14<0), "0",'Hampshire Daily'!X15-'Hampshire Daily'!X14) -> 2.26 | V12: =IF(('Hampshire Daily'!Y15-'Hampshire Daily'!Y14<0), "0",'Hampshire Daily'!Y15-'Hampshire Daily'!Y14) -> 0.053 | W12: =IF(('Hampshire Daily'!Z15-'Hampshire Daily'!Z14<0), "0",'Hampshire Daily'!Z15-'Hampshire Daily'!Z14) -> 0.008 | X12: =IF(('Hampshire Daily'!AA15-'Hampshire Daily'!AA14<0), "0",'Hampshire Daily'!AA15-'Hampshire Daily'!AA14) -> 23 | Y12: =IF(('Hampshire Daily'!AB15-'Hampshire Daily'!AB14<0), "0",'Hampshire Daily'!AB15-'Hampshire Daily'!AB14) -> 5 | Z12: ='Hampshire Daily'!B15 -> 57 | AA12: ='Hampshire Daily'!C15 -> 144
A13: Hampshire | B13: =B12+1 -> 12 | C13: 10 | D13: 2020 | E13: =IF(('Hampshire Daily'!D16-'Hampshire Daily'!D15<0), "0",('Hampshire Daily'!D16-'Hampshire Daily'!D15)*10) -> 2140 | F13: =IF(('Hampshire Daily'!F16-'Hampshire Daily'!F15<0), "0",('Hampshire Daily'!F16-'Hampshire Daily'!F15)*10) -> 4860 | G13: =IF(('Hampshire Daily'!H16-'Hampshire Daily'!H15<0), "0",'Hampshire Daily'!H16-'Hampshire Daily'!H15) -> 849 | H13: =IF(('Hampshire Daily'!I16-'Hampshire Daily'!I15<0), "0",'Hampshire Daily'!I16-'Hampshire Daily'!I15) -> 0 | I13: =IF(('Hampshire Daily'!J16-'Hampshire Daily'!J15<0), "0",'Hampshire Daily'!J16-'Hampshire Daily'!J15) -> 0 | J13: =IF(('Hampshire Daily'!K16-'Hampshire Daily'!K15<0), "0",'Hampshire Daily'!K16-'Hampshire Daily'!K15) -> 0 | K13: =IF(('Hampshire Daily'!L16-'Hampshire Daily'!L15<0), "0",'Hampshire Daily'!L16-'Hampshire Daily'!L15) -> 1490 | L13: =IF(('Hampshire Daily'!M16-'Hampshire Daily'!M15<0), "0",'Hampshire Daily'!M16-'Hampshire Daily'!M15) -> 2 | M13: =IF(('Hampshire Daily'!N16-'Hampshire Daily'!N15<0), "0",'Hampshire Daily'!N16-'Hampshire Daily'!N15) -> 2320 | N13: =IF(('Hampshire Daily'!O16-'Hampshire Daily'!O15<0), "0",'Hampshire Daily'!O16-'Hampshire Daily'!O15) -> 218 | ... Q13: =IF(('Hampshire Daily'!R16-'Hampshire Daily'!R15<0), "0",'Hampshire Daily'!R16-'Hampshire Daily'!R15) -> 0 | R13: =IF(('Hampshire Daily'!U16-'Hampshire Daily'!U15<0), "0",'Hampshire Daily'!U16-'Hampshire Daily'!U15) -> 10 | S13: =IF(('Hampshire Daily'!V16-'Hampshire Daily'!V15<0), "0",'Hampshire Daily'!V16-'Hampshire Daily'!V15) -> 8 | T13: =IF(('Hampshire Daily'!Y16-'Hampshire Daily'!Y15<0), "0",'Hampshire Daily'!Y16-'Hampshire Daily'!Y15) -> 0.013 | U13: =IF(('Hampshire Daily'!X16-'Hampshire Daily'!X15<0), "0",'Hampshire Daily'!X16-'Hampshire Daily'!X15) -> 2.272 | V13: =IF(('Hampshire Daily'!Y16-'Hampshire Daily'!Y15<0), "0",'Hampshire Daily'!Y16-'Hampshire Daily'!Y15) -> 0.013 | W13: =IF(('Hampshire Daily'!Z16-'Hampshire Daily'!Z15<0), "0",'Hampshire Daily'!Z16-'Hampshire Daily'!Z15) -> 0.009 | X13: =IF(('Hampshire Daily'!AA16-'Hampshire Daily'!AA15<0), "0",'Hampshire Daily'!AA16-'Hampshire Daily'!AA15) -> 21 | Y13: =IF(('Hampshire Daily'!AB16-'Hampshire Daily'!AB15<0), "0",'Hampshire Daily'!AB16-'Hampshire Daily'!AB15) -> 8 | Z13: ='Hampshire Daily'!B16 -> 37 | AA13: ='Hampshire Daily'!C16 -> 92
A14: Hampshire | B14: =B13+1 -> 13 | C14: 10 | D14: 2020 | E14: =IF(('Hampshire Daily'!D17-'Hampshire Daily'!D16<0), "0",('Hampshire Daily'!D17-'Hampshire Daily'!D16)*10) -> 2350 | F14: =IF(('Hampshire Daily'!F17-'Hampshire Daily'!F16<0), "0",('Hampshire Daily'!F17-'Hampshire Daily'!F16)*10) -> 12720 | G14: =IF(('Hampshire Daily'!H17-'Hampshire Daily'!H16<0), "0",'Hampshire Daily'!H17-'Hampshire Daily'!H16) -> 1835 | H14: =IF(('Hampshire Daily'!I17-'Hampshire Daily'!I16<0), "0",'Hampshire Daily'!I17-'Hampshire Daily'!I16) -> 1272 | I14: =IF(('Hampshire Daily'!J17-'Hampshire Daily'!J16<0), "0",'Hampshire Daily'!J17-'Hampshire Daily'!J16) -> 0 | J14: =IF(('Hampshire Daily'!K17-'Hampshire Daily'!K16<0), "0",'Hampshire Daily'!K17-'Hampshire Daily'!K16) -> 0 | K14: =IF(('Hampshire Daily'!L17-'Hampshire Daily'!L16<0), "0",'Hampshire Daily'!L17-'Hampshire Daily'!L16) -> 938 | L14: =IF(('Hampshire Daily'!M17-'Hampshire Daily'!M16<0), "0",'Hampshire Daily'!M17-'Hampshire Daily'!M16) -> 0 | M14: =IF(('Hampshire Daily'!N17-'Hampshire Daily'!N16<0), "0",'Hampshire Daily'!N17-'Hampshire Daily'!N16) -> 2324 | N14: =IF(('Hampshire Daily'!O17-'Hampshire Daily'!O16<0), "0",'Hampshire Daily'!O17-'Hampshire Daily'!O16) -> 128 | ... Q14: =IF(('Hampshire Daily'!R17-'Hampshire Daily'!R16<0), "0",'Hampshire Daily'!R17-'Hampshire Daily'!R16) -> 0 | R14: =IF(('Hampshire Daily'!U17-'Hampshire Daily'!U16<0), "0",'Hampshire Daily'!U17-'Hampshire Daily'!U16) -> 11 | S14: =IF(('Hampshire Daily'!V17-'Hampshire Daily'!V16<0), "0",'Hampshire Daily'!V17-'Hampshire Daily'!V16) -> 0 | T14: =IF(('Hampshire Daily'!Y17-'Hampshire Daily'!Y16<0), "0",'Hampshire Daily'!Y17-'Hampshire Daily'!Y16) -> 0.075 | U14: =IF(('Hampshire Daily'!X17-'Hampshire Daily'!X16<0), "0",'Hampshire Daily'!X17-'Hampshire Daily'!X16) -> 2.305 | V14: =IF(('Hampshire Daily'!Y17-'Hampshire Daily'!Y16<0), "0",'Hampshire Daily'!Y17-'Hampshire Daily'!Y16) -> 0.075 | W14: =IF(('Hampshire Daily'!Z17-'Hampshire Daily'!Z16<0), "0",'Hampshire Daily'!Z17-'Hampshire Daily'!Z16) -> 0.008 | X14: =IF(('Hampshire Daily'!AA17-'Hampshire Daily'!AA16<0), "0",'Hampshire Daily'!AA17-'Hampshire Daily'!AA16) -> 0 | Y14: =IF(('Hampshire Daily'!AB17-'Hampshire Daily'!AB16<0), "0",'Hampshire Daily'!AB17-'Hampshire Daily'!AB16) -> 10 | Z14: ='Hampshire Daily'!B17 -> 30 | AA14: ='Hampshire Daily'!C17 -> 70
A15: Hampshire | B15: =B14+1 -> 14 | C15: 10 | D15: 2020 | E15: 1813 | F15: 3525 | G15: =IF(('Hampshire Daily'!H18-'Hampshire Daily'!H17<0), "0",'Hampshire Daily'!H18-'Hampshire Daily'!H17) -> 363 | H15: =IF(('Hampshire Daily'!I18-'Hampshire Daily'!I17<0), "0",'Hampshire Daily'!I18-'Hampshire Daily'!I17) -> 0 | I15: =IF(('Hampshire Daily'!J18-'Hampshire Daily'!J17<0), "0",'Hampshire Daily'!J18-'Hampshire Daily'!J17) -> 0 | J15: =IF(('Hampshire Daily'!K18-'Hampshire Daily'!K17<0), "0",'Hampshire Daily'!K18-'Hampshire Daily'!K17) -> 0 | K15: =IF(('Hampshire Daily'!L18-'Hampshire Daily'!L17<0), "0",'Hampshire Daily'!L18-'Hampshire Daily'!L17) -> 938 | L15: =IF(('Hampshire Daily'!M18-'Hampshire Daily'!M17<0), "0",'Hampshire Daily'!M18-'Hampshire Daily'!M17) -> 0 | M15: =IF(('Hampshire Daily'!N18-'Hampshire Daily'!N17<0), "0",'Hampshire Daily'!N18-'Hampshire Daily'!N17) -> 2727 | N15: =IF(('Hampshire Daily'!O18-'Hampshire Daily'!O17<0), "0",'Hampshire Daily'!O18-'Hampshire Daily'!O17) -> 181 | ... Q15: =IF(('Hampshire Daily'!R18-'Hampshire Daily'!R17<0), "0",'Hampshire Daily'!R18-'Hampshire Daily'!R17) -> 0 | R15: =IF(('Hampshire Daily'!U18-'Hampshire Daily'!U17<0), "0",'Hampshire Daily'!U18-'Hampshire Daily'!U17) -> 9 | S15: =IF(('Hampshire Daily'!V18-'Hampshire Daily'!V17<0), "0",'Hampshire Daily'!V18-'Hampshire Daily'!V17) -> 0 | T15: =IF(('Hampshire Daily'!Y18-'Hampshire Daily'!Y17<0), "0",'Hampshire Daily'!Y18-'Hampshire Daily'!Y17) -> 0.031 | U15: =IF(('Hampshire Daily'!X18-'Hampshire Daily'!X17<0), "0",'Hampshire Daily'!X18-'Hampshire Daily'!X17) -> 2.404 | V15: =IF(('Hampshire Daily'!Y18-'Hampshire Daily'!Y17<0), "0",'Hampshire Daily'!Y18-'Hampshire Daily'!Y17) -> 0.031 | W15: =IF(('Hampshire Daily'!Z18-'Hampshire Daily'!Z17<0), "0",'Hampshire Daily'!Z18-'Hampshire Daily'!Z17) -> 0.008 | X15: =IF(('Hampshire Daily'!AA18-'Hampshire Daily'!AA17<0), "0",'Hampshire Daily'!AA18-'Hampshire Daily'!AA17) -> 23 | Y15: =IF(('Hampshire Daily'!AB18-'Hampshire Daily'!AB17<0), "0",'Hampshire Daily'!AB18-'Hampshire Daily'!AB17) -> 12 | Z15: ='Hampshire Daily'!B18 -> 32 | AA15: ='Hampshire Daily'!C18 -> 81
A16: Hampshire | B16: =B15+1 -> 15 | C16: 10 | D16: 2020 | E16: =IF(('Hampshire Daily'!D19-'Hampshire Daily'!D18<0), "0",('Hampshire Daily'!D19-'Hampshire Daily'!D18)*1) -> 2482 | F16: =IF(('Hampshire Daily'!F19-'Hampshire Daily'!F18<0), "0",('Hampshire Daily'!F19-'Hampshire Daily'!F18)*1) -> 4983 | G16: =IF(('Hampshire Daily'!H19-'Hampshire Daily'!H18<0), "0",'Hampshire Daily'!H19-'Hampshire Daily'!H18) -> 364 | H16: =IF(('Hampshire Daily'!I19-'Hampshire Daily'!I18<0), "0",'Hampshire Daily'!I19-'Hampshire Daily'!I18) -> 0 | I16: =IF(('Hampshire Daily'!J19-'Hampshire Daily'!J18<0), "0",'Hampshire Daily'!J19-'Hampshire Daily'!J18) -> 0 | J16: =IF(('Hampshire Daily'!K19-'Hampshire Daily'!K18<0), "0",'Hampshire Daily'!K19-'Hampshire Daily'!K18) -> 0 | K16: =IF(('Hampshire Daily'!L19-'Hampshire Daily'!L18<0), "0",'Hampshire Daily'!L19-'Hampshire Daily'!L18) -> 938 | L16: =IF(('Hampshire Daily'!M19-'Hampshire Daily'!M18<0), "0",'Hampshire Daily'!M19-'Hampshire Daily'!M18) -> 0 | M16: =IF(('Hampshire Daily'!N19-'Hampshire Daily'!N18<0), "0",'Hampshire Daily'!N19-'Hampshire Daily'!N18) -> 1780 | N16: =IF(('Hampshire Daily'!O19-'Hampshire Daily'!O18<0), "0",'Hampshire Daily'!O19-'Hampshire Daily'!O18) -> 128 | ... Q16: =IF(('Hampshire Daily'!R19-'Hampshire Daily'!R18<0), "0",'Hampshire Daily'!R19-'Hampshire Daily'!R18) -> 0 | R16: =IF(('Hampshire Daily'!U19-'Hampshire Daily'!U18<0), "0",'Hampshire Daily'!U19-'Hampshire Daily'!U18) -> 9 | S16: =IF(('Hampshire Daily'!V19-'Hampshire Daily'!V18<0), "0",'Hampshire Daily'!V19-'Hampshire Daily'!V18) -> 40 | T16: =IF(('Hampshire Daily'!Y19-'Hampshire Daily'!Y18<0), "0",'Hampshire Daily'!Y19-'Hampshire Daily'!Y18) -> 0.019 | U16: =IF(('Hampshire Daily'!X19-'Hampshire Daily'!X18<0), "0",'Hampshire Daily'!X19-'Hampshire Daily'!X18) -> 2.426 | V16: =IF(('Hampshire Daily'!Y19-'Hampshire Daily'!Y18<0), "0",'Hampshire Daily'!Y19-'Hampshire Daily'!Y18) -> 0.019 | W16: =IF(('Hampshire Daily'!Z19-'Hampshire Daily'!Z18<0), "0",'Hampshire Daily'!Z19-'Hampshire Daily'!Z18) -> 0.009 | X16: =IF(('Hampshire Daily'!AA19-'Hampshire Daily'!AA18<0), "0",'Hampshire Daily'!AA19-'Hampshire Daily'!AA18) -> 49 | Y16: =IF(('Hampshire Daily'!AB19-'Hampshire Daily'!AB18<0), "0",'Hampshire Daily'!AB19-'Hampshire Daily'!AB18) -> 8 | Z16: ='Hampshire Daily'!B19 -> 52 | AA16: ='Hampshire Daily'!C19 -> 115
A17: Hampshire | B17: =B16+1 -> 16 | C17: 10 | D17: 2020 | E17: =IF(('Hampshire Daily'!D20-'Hampshire Daily'!D19<0), "0",('Hampshire Daily'!D20-'Hampshire Daily'!D19)*1) -> 2248 | F17: =IF(('Hampshire Daily'!F20-'Hampshire Daily'!F19<0), "0",('Hampshire Daily'!F20-'Hampshire Daily'!F19)*1) -> 4521 | G17: =IF(('Hampshire Daily'!H20-'Hampshire Daily'!H19<0), "0",'Hampshire Daily'!H20-'Hampshire Daily'!H19) -> 783 | H17: =IF(('Hampshire Daily'!I20-'Hampshire Daily'!I19<0), "0",'Hampshire Daily'!I20-'Hampshire Daily'!I19) -> 0 | I17: =IF(('Hampshire Daily'!J20-'Hampshire Daily'!J19<0), "0",'Hampshire Daily'!J20-'Hampshire Daily'!J19) -> 0 | J17: =IF(('Hampshire Daily'!K20-'Hampshire Daily'!K19<0), "0",'Hampshire Daily'!K20-'Hampshire Daily'!K19) -> 0 | K17: =IF(('Hampshire Daily'!L20-'Hampshire Daily'!L19<0), "0",'Hampshire Daily'!L20-'Hampshire Daily'!L19) -> 938 | L17: =IF(('Hampshire Daily'!M20-'Hampshire Daily'!M19<0), "0",'Hampshire Daily'!M20-'Hampshire Daily'!M19) -> 0 | M17: =IF(('Hampshire Daily'!N20-'Hampshire Daily'!N19<0), "0",'Hampshire Daily'!N20-'Hampshire Daily'!N19) -> 2163 | N17: =IF(('Hampshire Daily'!O20-'Hampshire Daily'!O19<0), "0",'Hampshire Daily'!O20-'Hampshire Daily'!O19) -> 128 | ... Q17: =IF(('Hampshire Daily'!R20-'Hampshire Daily'!R19<0), "0",'Hampshire Daily'!R20-'Hampshire Daily'!R19) -> 0 | R17: =IF(('Hampshire Daily'!U20-'Hampshire Daily'!U19<0), "0",'Hampshire Daily'!U20-'Hampshire Daily'!U19) -> 9 | S17: =IF(('Hampshire Daily'!V20-'Hampshire Daily'!V19<0), "0",'Hampshire Daily'!V20-'Hampshire Daily'!V19) -> 1 | T17: =IF(('Hampshire Daily'!Y20-'Hampshire Daily'!Y19<0), "0",'Hampshire Daily'!Y20-'Hampshire Daily'!Y19) -> 0.032 | U17: =IF(('Hampshire Daily'!X20-'Hampshire Daily'!X19<0), "0",'Hampshire Daily'!X20-'Hampshire Daily'!X19) -> 2.455 | V17: =IF(('Hampshire Daily'!Y20-'Hampshire Daily'!Y19<0), "0",'Hampshire Daily'!Y20-'Hampshire Daily'!Y19) -> 0.032 | W17: =IF(('Hampshire Daily'!Z20-'Hampshire Daily'!Z19<0), "0",'Hampshire Daily'!Z20-'Hampshire Daily'!Z19) -> 0.006 | X17: =IF(('Hampshire Daily'!AA20-'Hampshire Daily'!AA19<0), "0",'Hampshire Daily'!AA20-'Hampshire Daily'!AA19) -> 21 | Y17: =IF(('Hampshire Daily'!AB20-'Hampshire Daily'!AB19<0), "0",'Hampshire Daily'!AB20-'Hampshire Daily'!AB19) -> 5 | Z17: ='Hampshire Daily'!B20 -> 74 | AA17: ='Hampshire Daily'!C20 -> 178
A18: Hampshire | B18: =B17+1 -> 17 | C18: 10 | D18: 2020 | E18: =IF(('Hampshire Daily'!D21-'Hampshire Daily'!D20<0), "0",('Hampshire Daily'!D21-'Hampshire Daily'!D20)*1) -> 2658 | F18: =IF(('Hampshire Daily'!F21-'Hampshire Daily'!F20<0), "0",('Hampshire Daily'!F21-'Hampshire Daily'!F20)*1) -> 5209 | G18: =IF(('Hampshire Daily'!H21-'Hampshire Daily'!H20<0), "0",'Hampshire Daily'!H21-'Hampshire Daily'!H20) -> 834 | H18: =IF(('Hampshire Daily'!I21-'Hampshire Daily'!I20<0), "0",'Hampshire Daily'!I21-'Hampshire Daily'!I20) -> 0 | I18: =IF(('Hampshire Daily'!J21-'Hampshire Daily'!J20<0), "0",'Hampshire Daily'!J21-'Hampshire Daily'!J20) -> 0 | J18: =IF(('Hampshire Daily'!K21-'Hampshire Daily'!K20<0), "0",'Hampshire Daily'!K21-'Hampshire Daily'!K20) -> 0 | K18: =IF(('Hampshire Daily'!L21-'Hampshire Daily'!L20<0), "0",'Hampshire Daily'!L21-'Hampshire Daily'!L20) -> 939 | L18: =IF(('Hampshire Daily'!M21-'Hampshire Daily'!M20<0), "0",'Hampshire Daily'!M21-'Hampshire Daily'!M20) -> 8 | M18: =IF(('Hampshire Daily'!N21-'Hampshire Daily'!N20<0), "0",'Hampshire Daily'!N21-'Hampshire Daily'!N20) -> 2366 | N18: =IF(('Hampshire Daily'!O21-'Hampshire Daily'!O20<0), "0",'Hampshire Daily'!O21-'Hampshire Daily'!O20) -> 128 | ... Q18: =IF(('Hampshire Daily'!R21-'Hampshire Daily'!R20<0), "0",'Hampshire Daily'!R21-'Hampshire Daily'!R20) -> 0 | R18: =IF(('Hampshire Daily'!U21-'Hampshire Daily'!U20<0), "0",'Hampshire Daily'!U21-'Hampshire Daily'!U20) -> 10 | S18: =IF(('Hampshire Daily'!V21-'Hampshire Daily'!V20<0), "0",'Hampshire Daily'!V21-'Hampshire Daily'!V20) -> 1 | T18: =IF(('Hampshire Daily'!Y21-'Hampshire Daily'!Y20<0), "0",'Hampshire Daily'!Y21-'Hampshire Daily'!Y20) -> 0.012 | U18: =IF(('Hampshire Daily'!X21-'Hampshire Daily'!X20<0), "0",'Hampshire Daily'!X21-'Hampshire Daily'!X20) -> 2.553 | V18: =IF(('Hampshire Daily'!Y21-'Hampshire Daily'!Y20<0), "0",'Hampshire Daily'!Y21-'Hampshire Daily'!Y20) -> 0.012 | W18: =IF(('Hampshire Daily'!Z21-'Hampshire Daily'!Z20<0), "0",'Hampshire Daily'!Z21-'Hampshire Daily'!Z20) -> 0.007 | X18: =IF(('Hampshire Daily'!AA21-'Hampshire Daily'!AA20<0), "0",'Hampshire Daily'!AA21-'Hampshire Daily'!AA20) -> 0 | Y18: =IF(('Hampshire Daily'!AB21-'Hampshire Daily'!AB20<0), "0",'Hampshire Daily'!AB21-'Hampshire Daily'!AB20) -> 5 | Z18: ='Hampshire Daily'!B21 -> 97 | AA18: ='Hampshire Daily'!C21 -> 243
A19: Hampshire | B19: =B18+1 -> 18 | C19: 10 | D19: 2020 | E19: =IF(('Hampshire Daily'!D22-'Hampshire Daily'!D21<0), "0",('Hampshire Daily'!D22-'Hampshire Daily'!D21)*1) -> 2538 | F19: =IF(('Hampshire Daily'!F22-'Hampshire Daily'!F21<0), "0",('Hampshire Daily'!F22-'Hampshire Daily'!F21)*1) -> 5332 | G19: =IF(('Hampshire Daily'!H22-'Hampshire Daily'!H21<0), "0",'Hampshire Daily'!H22-'Hampshire Daily'!H21) -> 853 | H19: =IF(('Hampshire Daily'!I22-'Hampshire Daily'!I21<0), "0",'Hampshire Daily'!I22-'Hampshire Daily'!I21) -> 0 | I19: =IF(('Hampshire Daily'!J22-'Hampshire Daily'!J21<0), "0",'Hampshire Daily'!J22-'Hampshire Daily'!J21) -> 0 | J19: =IF(('Hampshire Daily'!K22-'Hampshire Daily'!K21<0), "0",'Hampshire Daily'!K22-'Hampshire Daily'!K21) -> 0 | K19: =IF(('Hampshire Daily'!L22-'Hampshire Daily'!L21<0), "0",'Hampshire Daily'!L22-'Hampshire Daily'!L21) -> 1131 | L19: =IF(('Hampshire Daily'!M22-'Hampshire Daily'!M21<0), "0",'Hampshire Daily'!M22-'Hampshire Daily'!M21) -> 0 | M19: =IF(('Hampshire Daily'!N22-'Hampshire Daily'!N21<0), "0",'Hampshire Daily'!N22-'Hampshire Daily'!N21) -> 2407 | N19: =IF(('Hampshire Daily'!O22-'Hampshire Daily'!O21<0), "0",'Hampshire Daily'!O22-'Hampshire Daily'!O21) -> 128 | ... Q19: =IF(('Hampshire Daily'!R22-'Hampshire Daily'!R21<0), "0",'Hampshire Daily'!R22-'Hampshire Daily'!R21) -> 0 | R19: =IF(('Hampshire Daily'!U22-'Hampshire Daily'!U21<0), "0",'Hampshire Daily'!U22-'Hampshire Daily'!U21) -> 11 | S19: =IF(('Hampshire Daily'!V22-'Hampshire Daily'!V21<0), "0",'Hampshire Daily'!V22-'Hampshire Daily'!V21) -> 0 | T19: =IF(('Hampshire Daily'!Y22-'Hampshire Daily'!Y21<0), "0",'Hampshire Daily'!Y22-'Hampshire Daily'!Y21) -> 0.012 | U19: =IF(('Hampshire Daily'!X22-'Hampshire Daily'!X21<0), "0",'Hampshire Daily'!X22-'Hampshire Daily'!X21) -> 3.54 | V19: =IF(('Hampshire Daily'!Y22-'Hampshire Daily'!Y21<0), "0",'Hampshire Daily'!Y22-'Hampshire Daily'!Y21) -> 0.012 | W19: =IF(('Hampshire Daily'!Z22-'Hampshire Daily'!Z21<0), "0",'Hampshire Daily'!Z22-'Hampshire Daily'!Z21) -> 0.008 | X19: =IF(('Hampshire Daily'!AA22-'Hampshire Daily'!AA21<0), "0",'Hampshire Daily'!AA22-'Hampshire Daily'!AA21) -> 0 | Y19: =IF(('Hampshire Daily'!AB22-'Hampshire Daily'!AB21<0), "0",'Hampshire Daily'!AB22-'Hampshire Daily'!AB21) -> 13 | Z19: ='Hampshire Daily'!B22 -> 61 | AA19: ='Hampshire Daily'!C22 -> 166
A20: Hampshire | B20: =B19+1 -> 19 | C20: 10 | D20: 2020 | E20: =IF(('Hampshire Daily'!D23-'Hampshire Daily'!D22<0), "0",('Hampshire Daily'!D23-'Hampshire Daily'!D22)*1) -> 2194 | F20: =IF(('Hampshire Daily'!F23-'Hampshire Daily'!F22<0), "0",('Hampshire Daily'!F23-'Hampshire Daily'!F22)*1) -> 4875 | G20: =IF(('Hampshire Daily'!H23-'Hampshire Daily'!H22<0), "0",'Hampshire Daily'!H23-'Hampshire Daily'!H22) -> 830 | H20: =IF(('Hampshire Daily'!I23-'Hampshire Daily'!I22<0), "0",'Hampshire Daily'!I23-'Hampshire Daily'!I22) -> 0 | I20: =IF(('Hampshire Daily'!J23-'Hampshire Daily'!J22<0), "0",'Hampshire Daily'!J23-'Hampshire Daily'!J22) -> 0 | J20: =IF(('Hampshire Daily'!K23-'Hampshire Daily'!K22<0), "0",'Hampshire Daily'!K23-'Hampshire Daily'!K22) -> 0 | K20: =IF(('Hampshire Daily'!L23-'Hampshire Daily'!L22<0), "0",'Hampshire Daily'!L23-'Hampshire Daily'!L22) -> 1111 | L20: =IF(('Hampshire Daily'!M23-'Hampshire Daily'!M22<0), "0",'Hampshire Daily'!M23-'Hampshire Daily'!M22) -> 0 | M20: =IF(('Hampshire Daily'!N23-'Hampshire Daily'!N22<0), "0",'Hampshire Daily'!N23-'Hampshire Daily'!N22) -> 2244 | N20: =IF(('Hampshire Daily'!O23-'Hampshire Daily'!O22<0), "0",'Hampshire Daily'!O23-'Hampshire Daily'!O22) -> 128 | ... Q20: =IF(('Hampshire Daily'!R23-'Hampshire Daily'!R22<0), "0",'Hampshire Daily'!R23-'Hampshire Daily'!R22) -> 0 | R20: =IF(('Hampshire Daily'!U23-'Hampshire Daily'!U22<0), "0",'Hampshire Daily'!U23-'Hampshire Daily'!U22) -> 9 | S20: =IF(('Hampshire Daily'!V23-'Hampshire Daily'!V22<0), "0",'Hampshire Daily'!V23-'Hampshire Daily'!V22) -> 8 | T20: =IF(('Hampshire Daily'!Y23-'Hampshire Daily'!Y22<0), "0",'Hampshire Daily'!Y23-'Hampshire Daily'!Y22) -> 0.033 | U20: =IF(('Hampshire Daily'!X23-'Hampshire Daily'!X22<0), "0",'Hampshire Daily'!X23-'Hampshire Daily'!X22) -> 1.6 | V20: =IF(('Hampshire Daily'!Y23-'Hampshire Daily'!Y22<0), "0",'Hampshire Daily'!Y23-'Hampshire Daily'!Y22) -> 0.033 | W20: =IF(('Hampshire Daily'!Z23-'Hampshire Daily'!Z22<0), "0",'Hampshire Daily'!Z23-'Hampshire Daily'!Z22) -> 0.008 | X20: =IF(('Hampshire Daily'!AA23-'Hampshire Daily'!AA22<0), "0",'Hampshire Daily'!AA23-'Hampshire Daily'!AA22) -> 0 | Y20: =IF(('Hampshire Daily'!AB23-'Hampshire Daily'!AB22<0), "0",'Hampshire Daily'!AB23-'Hampshire Daily'!AB22) -> 8 | Z20: ='Hampshire Daily'!B23 -> 76 | AA20: ='Hampshire Daily'!C23 -> 199
A21: Hampshire | B21: =B20+1 -> 20 | C21: 10 | D21: 2020 | E21: =IF(('Hampshire Daily'!D24-'Hampshire Daily'!D23<0), "0",('Hampshire Daily'!D24-'Hampshire Daily'!D23)*1) -> 2505 | F21: =IF(('Hampshire Daily'!F24-'Hampshire Daily'!F23<0), "0",('Hampshire Daily'!F24-'Hampshire Daily'!F23)*1) -> 4772 | G21: =IF(('Hampshire Daily'!H24-'Hampshire Daily'!H23<0), "0",'Hampshire Daily'!H24-'Hampshire Daily'!H23) -> 806 | H21: =IF(('Hampshire Daily'!I24-'Hampshire Daily'!I23<0), "0",'Hampshire Daily'!I24-'Hampshire Daily'!I23) -> 0 | I21: =IF(('Hampshire Daily'!J24-'Hampshire Daily'!J23<0), "0",'Hampshire Daily'!J24-'Hampshire Daily'!J23) -> 0 | J21: =IF(('Hampshire Daily'!K24-'Hampshire Daily'!K23<0), "0",'Hampshire Daily'!K24-'Hampshire Daily'!K23) -> 0 | K21: =IF(('Hampshire Daily'!L24-'Hampshire Daily'!L23<0), "0",'Hampshire Daily'!L24-'Hampshire Daily'!L23) -> 938 | L21: =IF(('Hampshire Daily'!M24-'Hampshire Daily'!M23<0), "0",'Hampshire Daily'!M24-'Hampshire Daily'!M23) -> 108 | M21: =IF(('Hampshire Daily'!N24-'Hampshire Daily'!N23<0), "0",'Hampshire Daily'!N24-'Hampshire Daily'!N23) -> 2229 | N21: =IF(('Hampshire Daily'!O24-'Hampshire Daily'!O23<0), "0",'Hampshire Daily'!O24-'Hampshire Daily'!O23) -> 128 | ... Q21: =IF(('Hampshire Daily'!R24-'Hampshire Daily'!R23<0), "0",'Hampshire Daily'!R24-'Hampshire Daily'!R23) -> 0 | R21: =IF(('Hampshire Daily'!U24-'Hampshire Daily'!U23<0), "0",'Hampshire Daily'!U24-'Hampshire Daily'!U23) -> 10 | S21: =IF(('Hampshire Daily'!V24-'Hampshire Daily'!V23<0), "0",'Hampshire Daily'!V24-'Hampshire Daily'!V23) -> 0 | T21: =IF(('Hampshire Daily'!Y24-'Hampshire Daily'!Y23<0), "0",'Hampshire Daily'!Y24-'Hampshire Daily'!Y23) -> 0.167 | U21: =IF(('Hampshire Daily'!X24-'Hampshire Daily'!X23<0), "0",'Hampshire Daily'!X24-'Hampshire Daily'!X23) -> 2.619 | V21: =IF(('Hampshire Daily'!Y24-'Hampshire Daily'!Y23<0), "0",'Hampshire Daily'!Y24-'Hampshire Daily'!Y23) -> 0.167 | W21: =IF(('Hampshire Daily'!Z24-'Hampshire Daily'!Z23<0), "0",'Hampshire Daily'!Z24-'Hampshire Daily'!Z23) -> 0.006 | X21: =IF(('Hampshire Daily'!AA24-'Hampshire Daily'!AA23<0), "0",'Hampshire Daily'!AA24-'Hampshire Daily'!AA23) -> 0 | Y21: =IF(('Hampshire Daily'!AB24-'Hampshire Daily'!AB23<0), "0",'Hampshire Daily'!AB24-'Hampshire Daily'!AB23) -> 5 | Z21: ='Hampshire Daily'!B24 -> 74 | AA21: ='Hampshire Daily'!C24 -> 195
A22: Hampshire | B22: =B21+1 -> 21 | C22: 10 | D22: 2020 | E22: =IF(('Hampshire Daily'!D25-'Hampshire Daily'!D24<0), "0",('Hampshire Daily'!D25-'Hampshire Daily'!D24)*1) -> 3833 | F22: =IF(('Hampshire Daily'!F25-'Hampshire Daily'!F24<0), "0",('Hampshire Daily'!F25-'Hampshire Daily'!F24)*1) -> 4860 | G22: =IF(('Hampshire Daily'!H25-'Hampshire Daily'!H24<0), "0",'Hampshire Daily'!H25-'Hampshire Daily'!H24) -> 853 | H22: =IF(('Hampshire Daily'!I25-'Hampshire Daily'!I24<0), "0",'Hampshire Daily'!I25-'Hampshire Daily'!I24) -> 0 | I22: =IF(('Hampshire Daily'!J25-'Hampshire Daily'!J24<0), "0",'Hampshire Daily'!J25-'Hampshire Daily'!J24) -> 0 | J22: =IF(('Hampshire Daily'!K25-'Hampshire Daily'!K24<0), "0",'Hampshire Daily'!K25-'Hampshire Daily'!K24) -> 0 | K22: =IF(('Hampshire Daily'!L25-'Hampshire Daily'!L24<0), "0",'Hampshire Daily'!L25-'Hampshire Daily'!L24) -> 938 | L22: =IF(('Hampshire Daily'!M25-'Hampshire Daily'!M24<0), "0",'Hampshire Daily'!M25-'Hampshire Daily'!M24) -> 64 | M22: =IF(('Hampshire Daily'!N25-'Hampshire Daily'!N24<0), "0",'Hampshire Daily'!N25-'Hampshire Daily'!N24) -> 1979 | N22: =IF(('Hampshire Daily'!O25-'Hampshire Daily'!O24<0), "0",'Hampshire Daily'!O25-'Hampshire Daily'!O24) -> 119 | ... Q22: =IF(('Hampshire Daily'!R25-'Hampshire Daily'!R24<0), "0",'Hampshire Daily'!R25-'Hampshire Daily'!R24) -> 0 | R22: =IF(('Hampshire Daily'!U25-'Hampshire Daily'!U24<0), "0",'Hampshire Daily'!U25-'Hampshire Daily'!U24) -> 10 | S22: =IF(('Hampshire Daily'!V25-'Hampshire Daily'!V24<0), "0",'Hampshire Daily'!V25-'Hampshire Daily'!V24) -> 1 | T22: =IF(('Hampshire Daily'!Y25-'Hampshire Daily'!Y24<0), "0",'Hampshire Daily'!Y25-'Hampshire Daily'!Y24) -> 0.028 | U22: =IF(('Hampshire Daily'!X25-'Hampshire Daily'!X24<0), "0",'Hampshire Daily'!X25-'Hampshire Daily'!X24) -> 2.662 | V22: =IF(('Hampshire Daily'!Y25-'Hampshire Daily'!Y24<0), "0",'Hampshire Daily'!Y25-'Hampshire Daily'!Y24) -> 0.028 | W22: =IF(('Hampshire Daily'!Z25-'Hampshire Daily'!Z24<0), "0",'Hampshire Daily'!Z25-'Hampshire Daily'!Z24) -> 0.007 | X22: =IF(('Hampshire Daily'!AA25-'Hampshire Daily'!AA24<0), "0",'Hampshire Daily'!AA25-'Hampshire Daily'!AA24) -> 0 | Y22: =IF(('Hampshire Daily'!AB25-'Hampshire Daily'!AB24<0), "0",'Hampshire Daily'!AB25-'Hampshire Daily'!AB24) -> 9 | Z22: ='Hampshire Daily'!B25 -> 74 | AA22: ='Hampshire Daily'!C25 -> 204
A23: Hampshire | B23: =B22+1 -> 22 | C23: 10 | D23: 2020 | E23: =IF(('Hampshire Daily'!D26-'Hampshire Daily'!D25<0), "0",('Hampshire Daily'!D26-'Hampshire Daily'!D25)*1) -> 2503 | F23: =IF(('Hampshire Daily'!F26-'Hampshire Daily'!F25<0), "0",('Hampshire Daily'!F26-'Hampshire Daily'!F25)*1) -> 4648 | G23: =IF(('Hampshire Daily'!H26-'Hampshire Daily'!H25<0), "0",'Hampshire Daily'!H26-'Hampshire Daily'!H25) -> 698 | H23: =IF(('Hampshire Daily'!I26-'Hampshire Daily'!I25<0), "0",'Hampshire Daily'!I26-'Hampshire Daily'!I25) -> 0 | I23: =IF(('Hampshire Daily'!J26-'Hampshire Daily'!J25<0), "0",'Hampshire Daily'!J26-'Hampshire Daily'!J25) -> 0 | J23: =IF(('Hampshire Daily'!K26-'Hampshire Daily'!K25<0), "0",'Hampshire Daily'!K26-'Hampshire Daily'!K25) -> 0 | K23: =IF(('Hampshire Daily'!L26-'Hampshire Daily'!L25<0), "0",'Hampshire Daily'!L26-'Hampshire Daily'!L25) -> 1191 | L23: =IF(('Hampshire Daily'!M26-'Hampshire Daily'!M25<0), "0",'Hampshire Daily'!M26-'Hampshire Daily'!M25) -> 134 | M23: =IF(('Hampshire Daily'!N26-'Hampshire Daily'!N25<0), "0",'Hampshire Daily'!N26-'Hampshire Daily'!N25) -> 2246 | N23: =IF(('Hampshire Daily'!O26-'Hampshire Daily'!O25<0), "0",'Hampshire Daily'!O26-'Hampshire Daily'!O25) -> 128 | ... Q23: =IF(('Hampshire Daily'!R26-'Hampshire Daily'!R25<0), "0",'Hampshire Daily'!R26-'Hampshire Daily'!R25) -> 0 | R23: =IF(('Hampshire Daily'!U26-'Hampshire Daily'!U25<0), "0",'Hampshire Daily'!U26-'Hampshire Daily'!U25) -> 10 | S23: =IF(('Hampshire Daily'!V26-'Hampshire Daily'!V25<0), "0",'Hampshire Daily'!V26-'Hampshire Daily'!V25) -> 0 | T23: =IF(('Hampshire Daily'!Y26-'Hampshire Daily'!Y25<0), "0",'Hampshire Daily'!Y26-'Hampshire Daily'!Y25) -> 0.046 | U23: =IF(('Hampshire Daily'!X26-'Hampshire Daily'!X25<0), "0",'Hampshire Daily'!X26-'Hampshire Daily'!X25) -> 2.698 | V23: =IF(('Hampshire Daily'!Y26-'Hampshire Daily'!Y25<0), "0",'Hampshire Daily'!Y26-'Hampshire Daily'!Y25) -> 0.046 | W23: =IF(('Hampshire Daily'!Z26-'Hampshire Daily'!Z25<0), "0",'Hampshire Daily'!Z26-'Hampshire Daily'!Z25) -> 0.007 | X23: =IF(('Hampshire Daily'!AA26-'Hampshire Daily'!AA25<0), "0",'Hampshire Daily'!AA26-'Hampshire Daily'!AA25) -> 0 | Y23: =IF(('Hampshire Daily'!AB26-'Hampshire Daily'!AB25<0), "0",'Hampshire Daily'!AB26-'Hampshire Daily'!AB25) -> 10 | Z23: ='Hampshire Daily'!B26 -> 81 | AA23: ='Hampshire Daily'!C26 -> 220
A24: Hampshire | B24: =B23+1 -> 23 | C24: 10 | D24: 2020 | E24: =IF(('Hampshire Daily'!D27-'Hampshire Daily'!D26<0), "0",('Hampshire Daily'!D27-'Hampshire Daily'!D26)*1) -> 2675 | F24: =IF(('Hampshire Daily'!F27-'Hampshire Daily'!F26<0), "0",('Hampshire Daily'!F27-'Hampshire Daily'!F26)*1) -> 4281 | G24: =IF(('Hampshire Daily'!H27-'Hampshire Daily'!H26<0), "0",'Hampshire Daily'!H27-'Hampshire Daily'!H26) -> 666 | H24: =IF(('Hampshire Daily'!I27-'Hampshire Daily'!I26<0), "0",'Hampshire Daily'!I27-'Hampshire Daily'!I26) -> 0 | I24: =IF(('Hampshire Daily'!J27-'Hampshire Daily'!J26<0), "0",'Hampshire Daily'!J27-'Hampshire Daily'!J26) -> 0 | J24: =IF(('Hampshire Daily'!K27-'Hampshire Daily'!K26<0), "0",'Hampshire Daily'!K27-'Hampshire Daily'!K26) -> 0 | K24: =IF(('Hampshire Daily'!L27-'Hampshire Daily'!L26<0), "0",'Hampshire Daily'!L27-'Hampshire Daily'!L26) -> 1097 | L24: =IF(('Hampshire Daily'!M27-'Hampshire Daily'!M26<0), "0",'Hampshire Daily'!M27-'Hampshire Daily'!M26) -> 0 | M24: =IF(('Hampshire Daily'!N27-'Hampshire Daily'!N26<0), "0",'Hampshire Daily'!N27-'Hampshire Daily'!N26) -> 2237 | N24: =IF(('Hampshire Daily'!O27-'Hampshire Daily'!O26<0), "0",'Hampshire Daily'!O27-'Hampshire Daily'!O26) -> 128 | ... Q24: =IF(('Hampshire Daily'!R27-'Hampshire Daily'!R26<0), "0",'Hampshire Daily'!R27-'Hampshire Daily'!R26) -> 0 | R24: =IF(('Hampshire Daily'!U27-'Hampshire Daily'!U26<0), "0",'Hampshire Daily'!U27-'Hampshire Daily'!U26) -> 10 | S24: =IF(('Hampshire Daily'!V27-'Hampshire Daily'!V26<0), "0",'Hampshire Daily'!V27-'Hampshire Daily'!V26) -> 1 | T24: =IF(('Hampshire Daily'!Y27-'Hampshire Daily'!Y26<0), "0",'Hampshire Daily'!Y27-'Hampshire Daily'!Y26) -> 0.046 | U24: =IF(('Hampshire Daily'!X27-'Hampshire Daily'!X26<0), "0",'Hampshire Daily'!X27-'Hampshire Daily'!X26) -> 0.778 | V24: =IF(('Hampshire Daily'!Y27-'Hampshire Daily'!Y26<0), "0",'Hampshire Daily'!Y27-'Hampshire Daily'!Y26) -> 0.046 | W24: =IF(('Hampshire Daily'!Z27-'Hampshire Daily'!Z26<0), "0",'Hampshire Daily'!Z27-'Hampshire Daily'!Z26) -> 0.007 | X24: =IF(('Hampshire Daily'!AA27-'Hampshire Daily'!AA26<0), "0",'Hampshire Daily'!AA27-'Hampshire Daily'!AA26) -> 0 | Y24: =IF(('Hampshire Daily'!AB27-'Hampshire Daily'!AB26<0), "0",'Hampshire Daily'!AB27-'Hampshire Daily'!AB26) -> 9 | Z24: ='Hampshire Daily'!B27 -> 93 | AA24: ='Hampshire Daily'!C27 -> 253
