Workbook

Sheet Total
A1: Site Name | B1: Day | C1: Month | D1: Year | E1: Total Electricity Kwh | F1: Electricity Tariff ($/Kwh) | G1: LPG (Kg) | H1: LPG $/Kg | I1: Water Utility Supply (m3) m3 | J1: Water Utility Supply (m3) $/m3 | K1: Room Nights | L1: Utilities day cost dh
A2: Serengeti | B2: 1 | C2: 11 | D2: 2020 | E2: ='UTILITY REPORT 1'!F3 -> 2415 | F2: =('UTILITY REPORT 1'!E3*'UTILITY REPORT 1'!D3)/'UTILITY REPORT 1'!F3 -> 0.39587992 | G2: 57.42 | H2: 2.165 | I2: =IF('UTILITY REPORT 1'!G3<0,"0",'UTILITY REPORT 1'!G3) -> 54 | J2: 0 | K2: ='UTILITY REPORT 1'!C3 -> 3 | L2: =E2*F2+G2*H2+#REF!*#REF!+I2*J2 -> #REF!
A3: Serengeti | B3: =B2+1 -> 2 | C3: 11 | D3: 2020 | E3: ='UTILITY REPORT 1'!F4 -> 2617 | F3: =('UTILITY REPORT 1'!E4*'UTILITY REPORT 1'!D4)/'UTILITY REPORT 1'!F4 -> 0.42335499 | G3: =IF('Utility summery'!M7<0,"0",'Utility summery'!M7) -> 57.42 | H3: 2.165 | I3: =IF('UTILITY REPORT 1'!G4<0,"0",'UTILITY REPORT 1'!G4) -> 48 | J3: 0 | K3: ='UTILITY REPORT 1'!C4 -> 5 | L3: =E3*F3+G3*H3+#REF!*#REF!+I3*J3 -> #REF!
A4: Serengeti | B4: =B3+1 -> 3 | C4: 11 | D4: 2020 | E4: ='UTILITY REPORT 1'!F5 -> 2592 | F4: =('UTILITY REPORT 1'!E5*'UTILITY REPORT 1'!D5)/'UTILITY REPORT 1'!F5 -> 0.44945602 | G4: =IF('Utility summery'!M8<0,"0",'Utility summery'!M8) -> 50.16 | H4: 2.165 | I4: =IF('UTILITY REPORT 1'!G5<0,"0",'UTILITY REPORT 1'!G5) -> 81 | J4: 0 | K4: ='UTILITY REPORT 1'!C5 -> 7 | L4: =E4*F4+G4*H4+#REF!*#REF!+I4*J4 -> #REF!
A5: Serengeti | B5: =B4+1 -> 4 | C5: 11 | D5: 2020 | E5: ='UTILITY REPORT 1'!F6 -> 2655 | F5: =('UTILITY REPORT 1'!E6*'UTILITY REPORT 1'!D6)/'UTILITY REPORT 1'!F6 -> 0.39410546 | G5: =IF('Utility summery'!M9<0,"0",'Utility summery'!M9) -> 57.816 | H5: 2.165 | I5: =IF('UTILITY REPORT 1'!G6<0,"0",'UTILITY REPORT 1'!G6) -> 50 | J5: 0 | K5: ='UTILITY REPORT 1'!C6 -> 6 | L5: =E5*F5+G5*H5+#REF!*#REF!+I5*J5 -> #REF!
A6: Serengeti | B6: =B5+1 -> 5 | C6: 11 | D6: 2020 | E6: ='UTILITY REPORT 1'!F7 -> 2595 | F6: =('UTILITY REPORT 1'!E7*'UTILITY REPORT 1'!D7)/'UTILITY REPORT 1'!F7 -> 0.4077842 | G6: =IF('Utility summery'!M10<0,"0",'Utility summery'!M10) -> 59.972 | H6: 2.165 | I6: =IF('UTILITY REPORT 1'!G7<0,"0",'UTILITY REPORT 1'!G7) -> 58 | J6: 0 | K6: ='UTILITY REPORT 1'!C7 -> 3 | L6: =E6*F6+G6*H6+#REF!*#REF!+I6*J6 -> #REF!
A7: Serengeti | B7: =B6+1 -> 6 | C7: 11 | D7: 2020 | E7: ='UTILITY REPORT 1'!F8 -> 2217 | F7: =('UTILITY REPORT 1'!E8*'UTILITY REPORT 1'!D8)/'UTILITY REPORT 1'!F8 -> 0.4464682 | G7: =IF('Utility summery'!M11<0,"0",'Utility summery'!M11) -> 52.976 | H7: 2.165 | I7: =IF('UTILITY REPORT 1'!G8<0,"0",'UTILITY REPORT 1'!G8) -> 62 | J7: 0 | K7: ='UTILITY REPORT 1'!C8 -> 6 | L7: =E7*F7+G7*H7+#REF!*#REF!+I7*J7 -> #REF!
A8: Serengeti | B8: =B7+1 -> 7 | C8: 11 | D8: 2020 | E8: ='UTILITY REPORT 1'!F9 -> 2479 | F8: =('UTILITY REPORT 1'!E9*'UTILITY REPORT 1'!D9)/'UTILITY REPORT 1'!F9 -> 0.38424768 | G8: =IF('Utility summery'!M12<0,"0",'Utility summery'!M12) -> 75.68 | H8: 2.165 | I8: =IF('UTILITY REPORT 1'!G9<0,"0",'UTILITY REPORT 1'!G9) -> 83 | J8: 0 | K8: ='UTILITY REPORT 1'!C9 -> 5 | L8: =E8*F8+G8*H8+#REF!*#REF!+I8*J8 -> #REF!
A9: Serengeti | B9: =B8+1 -> 8 | C9: 11 | D9: 2020 | E9: ='UTILITY REPORT 1'!F10 -> 2341 | F9: =('UTILITY REPORT 1'!E10*'UTILITY REPORT 1'!D10)/'UTILITY REPORT 1'!F10 -> 0.43765912 | G9: =IF('Utility summery'!M13<0,"0",'Utility summery'!M13) -> 51.7 | H9: 2.165 | I9: =IF('UTILITY REPORT 1'!G10<0,"0",'UTILITY REPORT 1'!G10) -> 63 | J9: 0 | K9: ='UTILITY REPORT 1'!C10 -> 1 | L9: =E9*F9+G9*H9+#REF!*#REF!+I9*J9 -> #REF!
A10: Serengeti | B10: =B9+1 -> 9 | C10: 11 | D10: 2020 | E10: ='UTILITY REPORT 1'!F11 -> 2360 | F10: =('UTILITY REPORT 1'!E11*'UTILITY REPORT 1'!D11)/'UTILITY REPORT 1'!F11 -> 0.44400424 | G10: =IF('Utility summery'!M14<0,"0",'Utility summery'!M14) -> 53.592 | H10: 2.165 | I10: =IF('UTILITY REPORT 1'!G11<0,"0",'UTILITY REPORT 1'!G11) -> 46 | J10: 0 | K10: ='UTILITY REPORT 1'!C11 -> 2 | L10: =E10*F10+G10*H10+#REF!*#REF!+I10*J10 -> #REF!
A11: Serengeti | B11: =B10+1 -> 10 | C11: 11 | D11: 2020 | E11: ='UTILITY REPORT 1'!F12 -> 2323 | F11: =('UTILITY REPORT 1'!E12*'UTILITY REPORT 1'!D12)/'UTILITY REPORT 1'!F12 -> 0.40174344 | G11: =IF('Utility summery'!M15<0,"0",'Utility summery'!M15) -> 23.54 | H11: 2.165 | I11: =IF('UTILITY REPORT 1'!G12<0,"0",'UTILITY REPORT 1'!G12) -> 53 | J11: 0 | K11: ='UTILITY REPORT 1'!C12 -> 4 | L11: =E11*F11+G11*H11+#REF!*#REF!+I11*J11 -> #REF!
A12: Serengeti | B12: =B11+1 -> 11 | C12: 11 | D12: 2020 | E12: ='UTILITY REPORT 1'!F13 -> 2283 | F12: =('UTILITY REPORT 1'!E13*'UTILITY REPORT 1'!D13)/'UTILITY REPORT 1'!F13 -> 0.41271572 | G12: =IF('Utility summery'!M16<0,"0",'Utility summery'!M16) -> 75.328 | H12: 2.165 | I12: =IF('UTILITY REPORT 1'!G13<0,"0",'UTILITY REPORT 1'!G13) -> 63 | J12: 0 | K12: ='UTILITY REPORT 1'!C13 -> 6 | L12: =E12*F12+G12*H12+#REF!*#REF!+I12*J12 -> #REF!
A13: Serengeti | B13: =B12+1 -> 12 | C13: 11 | D13: 2020 | E13: ='UTILITY REPORT 1'!F14 -> 2328 | F13: =('UTILITY REPORT 1'!E14*'UTILITY REPORT 1'!D14)/'UTILITY REPORT 1'!F14 -> 0.465189 | G13: =IF('Utility summery'!M17<0,"0",'Utility summery'!M17) -> 54.164 | H13: 2.165 | I13: =IF('UTILITY REPORT 1'!G14<0,"0",'UTILITY REPORT 1'!G14) -> 48 | J13: 0 | K13: ='UTILITY REPORT 1'!C14 -> 5 | L13: =E13*F13+G13*H13+#REF!*#REF!+I13*J13 -> #REF!
A14: Serengeti | B14: =B13+1 -> 13 | C14: 11 | D14: 2020 | E14: ='UTILITY REPORT 1'!F15 -> 2362 | F14: =('UTILITY REPORT 1'!E15*'UTILITY REPORT 1'!D15)/'UTILITY REPORT 1'!F15 -> 0.40613463 | G14: =IF('Utility summery'!M18<0,"0",'Utility summery'!M18) -> 68.508 | H14: 2.165 | I14: =IF('UTILITY REPORT 1'!G15<0,"0",'UTILITY REPORT 1'!G15) -> 62 | J14: 0 | K14: ='UTILITY REPORT 1'!C15 -> 7 | L14: =E14*F14+G14*H14+#REF!*#REF!+I14*J14 -> #REF!
... A28: Serengeti | B28: =B27+1 -> 27 | C28: 11 | D28: 2020 | E28: ='UTILITY REPORT 1'!F29 -> 2395 | F28: =('UTILITY REPORT 1'!E29*'UTILITY REPORT 1'!D29)/'UTILITY REPORT 1'!F29 -> 0.42654697 | G28: =IF('Utility summery'!M32<0,"0",'Utility summery'!M32) -> 42.372 | H28: 2.165 | I28: =IF('UTILITY REPORT 1'!G29<0,"0",'UTILITY REPORT 1'!G29) -> 47 | J28: 0 | K28: ='UTILITY REPORT 1'!C29 -> 0 | L28: =E28*F28+G28*H28+#REF!*#REF!+I28*J28 -> #REF!
A29: Serengeti | B29: =B28+1 -> 28 | C29: 11 | D29: 2020 | E29: 2395 | F29: 0.43 | G29: =IF('Utility summery'!M33<0,"0",'Utility summery'!M33) -> 67.716 | H29: 2.165 | I29: =IF('UTILITY REPORT 1'!G30<0,"0",'UTILITY REPORT 1'!G30) -> 45 | J29: 0 | K29: ='UTILITY REPORT 1'!C30 -> 0 | L29: =E29*F29+G29*H29+#REF!*#REF!+I29*J29 -> #REF!
A30: Serengeti | B30: =B29+1 -> 29 | C30: 11 | D30: 2020 | E30: ='UTILITY REPORT 1'!F31 -> 2264 | F30: =('UTILITY REPORT 1'!E31*'UTILITY REPORT 1'!D31)/'UTILITY REPORT 1'!F31 -> 0.42375 | G30: =IF('Utility summery'!M34<0,"0",'Utility summery'!M34) -> 28.996 | H30: 2.165 | I30: =IF('UTILITY REPORT 1'!G31<0,"0",'UTILITY REPORT 1'!G31) -> 62 | J30: 0 | K30: ='UTILITY REPORT 1'!C31 -> 0 | L30: =E30*F30+G30*H30+#REF!*#REF!+I30*J30 -> #REF!
A31: Serengeti | B31: 30 | C31: 11 | D31: 2020 | E31: 2264 | F31: 0.42 | G31: =IF('Utility summery'!M35<0,"0",'Utility summery'!M35) -> 67.848 | H31: 2.165 | I31: =IF('UTILITY REPORT 1'!G32<0,"0",'UTILITY REPORT 1'!G32) -> 46 | J31: 0 | K31: ='UTILITY REPORT 1'!C32 -> 0 | L31: =E31*F31+G31*H31+#REF!*#REF!+I31*J31 -> #REF!

Sheet Submetering
A1: Site Name | B1: Day | C1: Month | D1: Year | E1: Transport Consumption (LT) | F1: Generators Consumption (LT) | G1: Total Electricity Kwh | H1: Kitchen (KWh) | I1: Laundry (KWh) | J1: STP (M3) | K1: RO prodution (M3) | L1: Amani Restaurant (M3) | M1: Kitchen (M3) | N1: Laundry (M3) | O1: Laundry (M3) | P1: Total water Consumption (M3) | Q1: Borehole #1 (M3) | R1: Borehole #2 (M3) | S1: Borehole #3 (M3) | T1: Borehole #4 (M3) | U1: Borehole #5 (M3) | V1: Borehole #6 (M3) | W1: Total Bore holes production (M3) | X1: Room Nights
A2: Serengeti | B2: 1 | C2: 11 | D2: 2020 | E2: ='UTILITY REPORT 1'!I3 -> 0 | F2: ='UTILITY REPORT 1'!E3 -> 956.05 | G2: ='UTILITY REPORT 1'!F3 -> 2415 | H2: =IF('Kit report'!F4<0,"0",'Kit report'!F4) -> 204 | I2: =IF('Kit report'!X4<0,"0",'Kit report'!X4) -> 140 | J2: =IF('Utility summery'!H6<0,"0",'Utility summery'!H6) -> 36 | K2: =IF('UTILITY REPORT 1'!H3<0,"0",'UTILITY REPORT 1'!H3) -> 41 | L2: ='Water-Meter'!K6 -> 0 | M2: ='Water-Meter'!H6 -> 0 | N2: ='Water-Meter'!Q6 -> 5 | O2: =K2*E2+H2*I2+#REF!*#REF!+J2*L2 -> #REF! | P2: ='Water-Meter'!E6 -> 54 | Q2: =IF('Water-Meter'!U6<0,"0",'Water-Meter'!U6) -> 0 | R2: =IF('Water-Meter'!X6<0,"0",'Water-Meter'!X6) -> 0 | S2: =IF('Water-Meter'!AA6<0,"0",'Water-Meter'!AA6) -> 1 | T2: =IF('Water-Meter'!AD6<0,"0",'Water-Meter'!AD6) -> 19 | U2: =IF('Water-Meter'!AG6<0,"0",'Water-Meter'!AG6) -> 0 | V2: =IF('Water-Meter'!AJ6<0,"0",'Water-Meter'!AJ6) -> 22 | W2: ='Water-Meter'!AN6 -> 42 | X2: =Total!K2 -> 3
A3: Serengeti | B3: =B2+1 -> 2 | C3: 11 | D3: 2020 | E3: ='UTILITY REPORT 1'!I4 -> 0 | F3: ='UTILITY REPORT 1'!E4 -> 1107.92 | G3: ='UTILITY REPORT 1'!F4 -> 2617 | H3: =IF('Kit report'!F5<0,"0",'Kit report'!F5) -> 216 | I3: =IF('Kit report'!X5<0,"0",'Kit report'!X5) -> 220 | J3: =IF('Utility summery'!H7<0,"0",'Utility summery'!H7) -> 26 | K3: =IF('UTILITY REPORT 1'!H4<0,"0",'UTILITY REPORT 1'!H4) -> 48 | L3: ='Water-Meter'!K7 -> 1 | M3: ='Water-Meter'!H7 -> 0 | N3: ='Water-Meter'!Q7 -> 3 | O3: =K3*E3+H3*I3+#REF!*#REF!+J3*L3 -> #REF! | P3: ='Water-Meter'!E7 -> 48 | Q3: =IF('Water-Meter'!U7<0,"0",'Water-Meter'!U7) -> 61 | R3: =IF('Water-Meter'!X7<0,"0",'Water-Meter'!X7) -> 0 | S3: =IF('Water-Meter'!AA7<0,"0",'Water-Meter'!AA7) -> 0 | T3: =IF('Water-Meter'!AD7<0,"0",'Water-Meter'!AD7) -> 19 | U3: =IF('Water-Meter'!AG7<0,"0",'Water-Meter'!AG7) -> 0 | V3: =IF('Water-Meter'!AJ7<0,"0",'Water-Meter'!AJ7) -> 23 | W3: ='Water-Meter'!AN7 -> 103 | X3: =Total!K3 -> 5
A4: Serengeti | B4: =B3+1 -> 3 | C4: 11 | D4: 2020 | E4: ='UTILITY REPORT 1'!I5 -> 0 | F4: ='UTILITY REPORT 1'!E5 -> 1164.99 | G4: ='UTILITY REPORT 1'!F5 -> 2592 | H4: =IF('Kit report'!F6<0,"0",'Kit report'!F6) -> 216 | I4: =IF('Kit report'!X6<0,"0",'Kit report'!X6) -> 100 | J4: =IF('Utility summery'!H8<0,"0",'Utility summery'!H8) -> 26 | K4: =IF('UTILITY REPORT 1'!H5<0,"0",'UTILITY REPORT 1'!H5) -> 48 | L4: ='Water-Meter'!K8 -> 2 | M4: ='Water-Meter'!H8 -> 0 | N4: ='Water-Meter'!Q8 -> 11 | O4: =K4*E4+H4*I4+#REF!*#REF!+J4*L4 -> #REF! | P4: ='Water-Meter'!E8 -> 81 | Q4: =IF('Water-Meter'!U8<0,"0",'Water-Meter'!U8) -> 85 | R4: =IF('Water-Meter'!X8<0,"0",'Water-Meter'!X8) -> 0 | S4: =IF('Water-Meter'!AA8<0,"0",'Water-Meter'!AA8) -> 31 | T4: =IF('Water-Meter'!AD8<0,"0",'Water-Meter'!AD8) -> 18 | U4: =IF('Water-Meter'!AG8<0,"0",'Water-Meter'!AG8) -> 0 | V4: =IF('Water-Meter'!AJ8<0,"0",'Water-Meter'!AJ8) -> 21 | W4: ='Water-Meter'!AN8 -> 155 | X4: =Total!K4 -> 7
A5: Serengeti | B5: =B4+1 -> 4 | C5: 11 | D5: 2020 | E5: ='UTILITY REPORT 1'!I6 -> 0 | F5: ='UTILITY REPORT 1'!E6 -> 1046.35 | G5: ='UTILITY REPORT 1'!F6 -> 2655 | H5: =IF('Kit report'!F7<0,"0",'Kit report'!F7) -> 228 | I5: =IF('Kit report'!X7<0,"0",'Kit report'!X7) -> 60 | J5: =IF('Utility summery'!H9<0,"0",'Utility summery'!H9) -> 45 | K5: =IF('UTILITY REPORT 1'!H6<0,"0",'UTILITY REPORT 1'!H6) -> 77 | L5: ='Water-Meter'!K9 -> 1 | M5: ='Water-Meter'!H9 -> 0 | N5: ='Water-Meter'!Q9 -> 9 | O5: =K5*E5+H5*I5+#REF!*#REF!+J5*L5 -> #REF! | P5: ='Water-Meter'!E9 -> 50 | Q5: =IF('Water-Meter'!U9<0,"0",'Water-Meter'!U9) -> 81 | R5: =IF('Water-Meter'!X9<0,"0",'Water-Meter'!X9) -> 0 | S5: =IF('Water-Meter'!AA9<0,"0",'Water-Meter'!AA9) -> 48 | T5: =IF('Water-Meter'!AD9<0,"0",'Water-Meter'!AD9) -> 18 | U5: =IF('Water-Meter'!AG9<0,"0",'Water-Meter'!AG9) -> 0 | V5: =IF('Water-Meter'!AJ9<0,"0",'Water-Meter'!AJ9) -> 22 | W5: ='Water-Meter'!AN9 -> 169 | X5: =Total!K5 -> 6
A6: Serengeti | B6: =B5+1 -> 5 | C6: 11 | D6: 2020 | E6: ='UTILITY REPORT 1'!I7 -> 0 | F6: ='UTILITY REPORT 1'!E7 -> 1058.2 | G6: ='UTILITY REPORT 1'!F7 -> 2595 | H6: =IF('Kit report'!F8<0,"0",'Kit report'!F8) -> 168 | I6: =IF('Kit report'!X8<0,"0",'Kit report'!X8) -> 160 | J6: =IF('Utility summery'!H10<0,"0",'Utility summery'!H10) -> 46 | K6: =IF('UTILITY REPORT 1'!H7<0,"0",'UTILITY REPORT 1'!H7) -> 13 | L6: ='Water-Meter'!K10 -> 1 | M6: ='Water-Meter'!H10 -> 0 | N6: ='Water-Meter'!Q10 -> 10 | O6: =K6*E6+H6*I6+#REF!*#REF!+J6*L6 -> #REF! | P6: ='Water-Meter'!E10 -> 58 | Q6: =IF('Water-Meter'!U10<0,"0",'Water-Meter'!U10) -> 87 | R6: =IF('Water-Meter'!X10<0,"0",'Water-Meter'!X10) -> 0 | S6: =IF('Water-Meter'!AA10<0,"0",'Water-Meter'!AA10) -> 0 | T6: =IF('Water-Meter'!AD10<0,"0",'Water-Meter'!AD10) -> 19 | U6: =IF('Water-Meter'!AG10<0,"0",'Water-Meter'!AG10) -> 0 | V6: =IF('Water-Meter'!AJ10<0,"0",'Water-Meter'!AJ10) -> 13 | W6: ='Water-Meter'!AN10 -> 119 | X6: =Total!K6 -> 3
A7: Serengeti | B7: =B6+1 -> 6 | C7: 11 | D7: 2020 | E7: ='UTILITY REPORT 1'!I8 -> 0 | F7: ='UTILITY REPORT 1'!E8 -> 989.82 | G7: ='UTILITY REPORT 1'!F8 -> 2217 | H7: =IF('Kit report'!F9<0,"0",'Kit report'!F9) -> 240 | I7: =IF('Kit report'!X9<0,"0",'Kit report'!X9) -> 40 | J7: =IF('Utility summery'!H11<0,"0",'Utility summery'!H11) -> 45 | K7: =IF('UTILITY REPORT 1'!H8<0,"0",'UTILITY REPORT 1'!H8) -> 47 | L7: ='Water-Meter'!K11 -> 0 | M7: ='Water-Meter'!H11 -> 0 | N7: ='Water-Meter'!Q11 -> 10 | O7: =K7*E7+H7*I7+#REF!*#REF!+J7*L7 -> #REF! | P7: ='Water-Meter'!E11 -> 62 | Q7: =IF('Water-Meter'!U11<0,"0",'Water-Meter'!U11) -> 15 | R7: =IF('Water-Meter'!X11<0,"0",'Water-Meter'!X11) -> 0 | S7: =IF('Water-Meter'!AA11<0,"0",'Water-Meter'!AA11) -> 0 | T7: =IF('Water-Meter'!AD11<0,"0",'Water-Meter'!AD11) -> 19 | U7: =IF('Water-Meter'!AG11<0,"0",'Water-Meter'!AG11) -> 0 | V7: =IF('Water-Meter'!AJ11<0,"0",'Water-Meter'!AJ11) -> 0 | W7: ='Water-Meter'!AN11 -> 34 | X7: =Total!K7 -> 6
A8: Serengeti | B8: =B7+1 -> 7 | C8: 11 | D8: 2020 | E8: ='UTILITY REPORT 1'!I9 -> 0 | F8: ='UTILITY REPORT 1'!E9 -> 952.55 | G8: ='UTILITY REPORT 1'!F9 -> 2479 | H8: =IF('Kit report'!F10<0,"0",'Kit report'!F10) -> 132 | I8: =IF('Kit report'!X10<0,"0",'Kit report'!X10) -> 160 | J8: =IF('Utility summery'!H12<0,"0",'Utility summery'!H12) -> 46 | K8: =IF('UTILITY REPORT 1'!H9<0,"0",'UTILITY REPORT 1'!H9) -> 45 | L8: ='Water-Meter'!K12 -> 1 | M8: ='Water-Meter'!H12 -> 0 | N8: ='Water-Meter'!Q12 -> 9 | O8: =K8*E8+H8*I8+#REF!*#REF!+J8*L8 -> #REF! | P8: ='Water-Meter'!E12 -> 83 | Q8: =IF('Water-Meter'!U12<0,"0",'Water-Meter'!U12) -> 58 | R8: =IF('Water-Meter'!X12<0,"0",'Water-Meter'!X12) -> 0 | S8: =IF('Water-Meter'!AA12<0,"0",'Water-Meter'!AA12) -> 22 | T8: =IF('Water-Meter'!AD12<0,"0",'Water-Meter'!AD12) -> 18 | U8: =IF('Water-Meter'!AG12<0,"0",'Water-Meter'!AG12) -> 0 | V8: =IF('Water-Meter'!AJ12<0,"0",'Water-Meter'!AJ12) -> 16 | W8: ='Water-Meter'!AN12 -> 114 | X8: =Total!K8 -> 5
A9: Serengeti | B9: =B8+1 -> 8 | C9: 11 | D9: 2020 | E9: ='UTILITY REPORT 1'!I10 -> 0 | F9: ='UTILITY REPORT 1'!E10 -> 1024.56 | G9: ='UTILITY REPORT 1'!F10 -> 2341 | H9: =IF('Kit report'!F11<0,"0",'Kit report'!F11) -> 156 | I9: =IF('Kit report'!X11<0,"0",'Kit report'!X11) -> 120 | J9: =IF('Utility summery'!H13<0,"0",'Utility summery'!H13) -> 46 | K9: =IF('UTILITY REPORT 1'!H10<0,"0",'UTILITY REPORT 1'!H10) -> 51 | L9: ='Water-Meter'!K13 -> 0 | M9: ='Water-Meter'!H13 -> 0 | N9: ='Water-Meter'!Q13 -> 13 | O9: =K9*E9+H9*I9+#REF!*#REF!+J9*L9 -> #REF! | P9: ='Water-Meter'!E13 -> 63 | Q9: =IF('Water-Meter'!U13<0,"0",'Water-Meter'!U13) -> 88 | R9: =IF('Water-Meter'!X13<0,"0",'Water-Meter'!X13) -> 0 | S9: =IF('Water-Meter'!AA13<0,"0",'Water-Meter'!AA13) -> 64 | T9: =IF('Water-Meter'!AD13<0,"0",'Water-Meter'!AD13) -> 19 | U9: =IF('Water-Meter'!AG13<0,"0",'Water-Meter'!AG13) -> 0 | V9: =IF('Water-Meter'!AJ13<0,"0",'Water-Meter'!AJ13) -> 26 | W9: ='Water-Meter'!AN13 -> 197 | X9: =Total!K9 -> 1
A10: Serengeti | B10: =B9+1 -> 9 | C10: 11 | D10: 2020 | E10: ='UTILITY REPORT 1'!I11 -> 0 | F10: ='UTILITY REPORT 1'!E11 -> 1047.85 | G10: ='UTILITY REPORT 1'!F11 -> 2360 | H10: =IF('Kit report'!F12<0,"0",'Kit report'!F12) -> 192 | I10: =IF('Kit report'!X12<0,"0",'Kit report'!X12) -> 120 | J10: =IF('Utility summery'!H14<0,"0",'Utility summery'!H14) -> 41 | K10: =IF('UTILITY REPORT 1'!H11<0,"0",'UTILITY REPORT 1'!H11) -> 47 | L10: ='Water-Meter'!K14 -> 2 | M10: ='Water-Meter'!H14 -> 0 | N10: ='Water-Meter'!Q14 -> 8 | O10: =K10*E10+H10*I10+#REF!*#REF!+J10*L10 -> #REF! | P10: ='Water-Meter'!E14 -> 46 | Q10: =IF('Water-Meter'!U14<0,"0",'Water-Meter'!U14) -> 76 | R10: =IF('Water-Meter'!X14<0,"0",'Water-Meter'!X14) -> 0 | S10: =IF('Water-Meter'!AA14<0,"0",'Water-Meter'!AA14) -> 47 | T10: =IF('Water-Meter'!AD14<0,"0",'Water-Meter'!AD14) -> 18 | U10: =IF('Water-Meter'!AG14<0,"0",'Water-Meter'!AG14) -> 0 | V10: =IF('Water-Meter'!AJ14<0,"0",'Water-Meter'!AJ14) -> 22 | W10: ='Water-Meter'!AN14 -> 163 | X10: =Total!K10 -> 2
A11: Serengeti | B11: =B10+1 -> 10 | C11: 11 | D11: 2020 | E11: ='UTILITY REPORT 1'!I12 -> 0 | F11: ='UTILITY REPORT 1'!E12 -> 933.25 | G11: ='UTILITY REPORT 1'!F12 -> 2323 | H11: =IF('Kit report'!F13<0,"0",'Kit report'!F13) -> 192 | I11: =IF('Kit report'!X13<0,"0",'Kit report'!X13) -> 100 | J11: =IF('Utility summery'!H15<0,"0",'Utility summery'!H15) -> 44 | K11: =IF('UTILITY REPORT 1'!H12<0,"0",'UTILITY REPORT 1'!H12) -> 49 | L11: ='Water-Meter'!K15 -> 1 | M11: ='Water-Meter'!H15 -> 0 | N11: ='Water-Meter'!Q15 -> 11 | O11: =K11*E11+H11*I11+#REF!*#REF!+J11*L11 -> #REF! | P11: ='Water-Meter'!E15 -> 53 | Q11: =IF('Water-Meter'!U15<0,"0",'Water-Meter'!U15) -> 86 | R11: =IF('Water-Meter'!X15<0,"0",'Water-Meter'!X15) -> 0 | S11: =IF('Water-Meter'!AA15<0,"0",'Water-Meter'!AA15) -> 56 | T11: =IF('Water-Meter'!AD15<0,"0",'Water-Meter'!AD15) -> 17 | U11: =IF('Water-Meter'!AG15<0,"0",'Water-Meter'!AG15) -> 0 | V11: =IF('Water-Meter'!AJ15<0,"0",'Water-Meter'!AJ15) -> 23 | W11: ='Water-Meter'!AN15 -> 182 | X11: =Total!K11 -> 4
A12: Serengeti | B12: =B11+1 -> 11 | C12: 11 | D12: 2020 | E12: ='UTILITY REPORT 1'!I13 -> 0 | F12: ='UTILITY REPORT 1'!E13 -> 942.23 | G12: ='UTILITY REPORT 1'!F13 -> 2283 | H12: =IF('Kit report'!F14<0,"0",'Kit report'!F14) -> 204 | I12: =IF('Kit report'!X14<0,"0",'Kit report'!X14) -> 60 | J12: =IF('Utility summery'!H16<0,"0",'Utility summery'!H16) -> 44 | K12: =IF('UTILITY REPORT 1'!H13<0,"0",'UTILITY REPORT 1'!H13) -> 46 | L12: ='Water-Meter'!K16 -> 1 | M12: ='Water-Meter'!H16 -> 0 | N12: ='Water-Meter'!Q16 -> 5 | O12: =K12*E12+H12*I12+#REF!*#REF!+J12*L12 -> #REF! | P12: ='Water-Meter'!E16 -> 63 | Q12: =IF('Water-Meter'!U16<0,"0",'Water-Meter'!U16) -> 85 | R12: =IF('Water-Meter'!X16<0,"0",'Water-Meter'!X16) -> 0 | S12: =IF('Water-Meter'!AA16<0,"0",'Water-Meter'!AA16) -> 55 | T12: =IF('Water-Meter'!AD16<0,"0",'Water-Meter'!AD16) -> 19 | U12: =IF('Water-Meter'!AG16<0,"0",'Water-Meter'!AG16) -> 0 | V12: =IF('Water-Meter'!AJ16<0,"0",'Water-Meter'!AJ16) -> 23 | W12: ='Water-Meter'!AN16 -> 182 | X12: =Total!K12 -> 6
A13: Serengeti | B13: =B12+1 -> 12 | C13: 11 | D13: 2020 | E13: ='UTILITY REPORT 1'!I14 -> 0 | F13: ='UTILITY REPORT 1'!E14 -> 1082.96 | G13: ='UTILITY REPORT 1'!F14 -> 2328 | H13: =IF('Kit report'!F15<0,"0",'Kit report'!F15) -> 204 | I13: =IF('Kit report'!X15<0,"0",'Kit report'!X15) -> 200 | J13: =IF('Utility summery'!H17<0,"0",'Utility summery'!H17) -> 43 | K13: =IF('UTILITY REPORT 1'!H14<0,"0",'UTILITY REPORT 1'!H14) -> 43 | L13: ='Water-Meter'!K17 -> 1 | M13: ='Water-Meter'!H17 -> 0 | N13: ='Water-Meter'!Q17 -> 3 | O13: =K13*E13+H13*I13+#REF!*#REF!+J13*L13 -> #REF! | P13: ='Water-Meter'!E17 -> 48 | Q13: =IF('Water-Meter'!U17<0,"0",'Water-Meter'!U17) -> 2 | R13: =IF('Water-Meter'!X17<0,"0",'Water-Meter'!X17) -> 0 | S13: =IF('Water-Meter'!AA17<0,"0",'Water-Meter'!AA17) -> 55 | T13: =IF('Water-Meter'!AD17<0,"0",'Water-Meter'!AD17) -> 18 | U13: =IF('Water-Meter'!AG17<0,"0",'Water-Meter'!AG17) -> 0 | V13: =IF('Water-Meter'!AJ17<0,"0",'Water-Meter'!AJ17) -> 23 | W13: ='Water-Meter'!AN17 -> 98 | X13: =Total!K13 -> 5
A14: Serengeti | B14: =B13+1 -> 13 | C14: 11 | D14: 2020 | E14: ='UTILITY REPORT 1'!I15 -> 0 | F14: ='UTILITY REPORT 1'!E15 -> 959.29 | G14: ='UTILITY REPORT 1'!F15 -> 2362 | H14: =IF('Kit report'!F16<0,"0",'Kit report'!F16) -> 216 | I14: =IF('Kit report'!X16<0,"0",'Kit report'!X16) -> 80 | J14: =IF('Utility summery'!H18<0,"0",'Utility summery'!H18) -> 41 | K14: =IF('UTILITY REPORT 1'!H15<0,"0",'UTILITY REPORT 1'!H15) -> 42 | L14: ='Water-Meter'!K18 -> 1 | M14: ='Water-Meter'!H18 -> 0 | N14: ='Water-Meter'!Q18 -> 4 | O14: =K14*E14+H14*I14+#REF!*#REF!+J14*L14 -> #REF! | P14: ='Water-Meter'!E18 -> 62 | Q14: =IF('Water-Meter'!U18<0,"0",'Water-Meter'!U18) -> 0 | R14: =IF('Water-Meter'!X18<0,"0",'Water-Meter'!X18) -> 0 | S14: =IF('Water-Meter'!AA18<0,"0",'Water-Meter'!AA18) -> 57 | T14: =IF('Water-Meter'!AD18<0,"0",'Water-Meter'!AD18) -> 19 | U14: =IF('Water-Meter'!AG18<0,"0",'Water-Meter'!AG18) -> 0 | V14: =IF('Water-Meter'!AJ18<0,"0",'Water-Meter'!AJ18) -> 22 | W14: ='Water-Meter'!AN18 -> 98 | X14: =Total!K14 -> 7
... A30: Serengeti | B30: =B29+1 -> 29 | C30: 11 | D30: 2020 | E30: ='UTILITY REPORT 1'!I31 -> 0 | F30: ='UTILITY REPORT 1'!E31 -> 959.37 | G30: ='UTILITY REPORT 1'!F31 -> 2264 | H30: =IF('Kit report'!F32<0,"0",'Kit report'!F32) -> 204 | I30: =IF('Kit report'!X32<0,"0",'Kit report'!X32) -> 160 | J30: =IF('Utility summery'!H34<0,"0",'Utility summery'!H34) -> 37 | K30: =IF('UTILITY REPORT 1'!H31<0,"0",'UTILITY REPORT 1'!H31) -> 44 | L30: ='Water-Meter'!K34 -> 1 | M30: ='Water-Meter'!H34 -> 0 | N30: ='Water-Meter'!Q34 -> 4 | O30: =K30*E30+H30*I30+#REF!*#REF!+J30*L30 -> #REF! | P30: ='Water-Meter'!E34 -> 62 | Q30: =IF('Water-Meter'!U34<0,"0",'Water-Meter'!U34) -> 0 | R30: =IF('Water-Meter'!X34<0,"0",'Water-Meter'!X34) -> 0 | S30: =IF('Water-Meter'!AA34<0,"0",'Water-Meter'!AA34) -> 54 | T30: =IF('Water-Meter'!AD34<0,"0",'Water-Meter'!AD34) -> 20 | U30: =IF('Water-Meter'!AG34<0,"0",'Water-Meter'!AG34) -> 0 | V30: =IF('Water-Meter'!AJ34<0,"0",'Water-Meter'!AJ34) -> 22 | W30: ='Water-Meter'!AN34 -> 96 | X30: =Total!K30 -> 0
A31: Serengeti | B31: 30 | C31: 11 | D31: 2020 | E31: ='UTILITY REPORT 1'!I32 -> 0 | F31: ='UTILITY REPORT 1'!E32 -> 923.68 | G31: ='UTILITY REPORT 1'!F32 -> 0 | H31: =IF('Kit report'!F33<0,"0",'Kit report'!F33) -> 168 | I31: =IF('Kit report'!X33<0,"0",'Kit report'!X33) -> 140 | J31: =IF('Utility summery'!H35<0,"0",'Utility summery'!H35) -> 34 | K31: =IF('UTILITY REPORT 1'!H32<0,"0",'UTILITY REPORT 1'!H32) -> 41 | L31: ='Water-Meter'!K35 -> 1 | M31: ='Water-Meter'!H35 -> 0 | N31: ='Water-Meter'!Q35 -> 2 | O31: =K31*E31+H31*I31+#REF!*#REF!+J31*L31 -> #REF! | P31: ='Water-Meter'!E35 -> 46 | Q31: =IF('Water-Meter'!U35<0,"0",'Water-Meter'!U35) -> 0 | R31: =IF('Water-Meter'!X35<0,"0",'Water-Meter'!X35) -> 0 | S31: =IF('Water-Meter'!AA35<0,"0",'Water-Meter'!AA35) -> 55 | T31: =IF('Water-Meter'!AD35<0,"0",'Water-Meter'!AD35) -> 19 | U31: =IF('Water-Meter'!AG35<0,"0",'Water-Meter'!AG35) -> 0 | V31: =IF('Water-Meter'!AJ35<0,"0",'Water-Meter'!AJ35) -> 23 | W31: ='Water-Meter'!AN35 -> 97 | X31: =Total!K31 -> 0

Sheet UTILITY REPORT 1
A1: UTILITY REPORT
A2: Date | B2: % | C2: Guest Rooms Occupied | D2: Diesel cost Per Liter ($) | E2: Diesel consumption (LT) | F2: Power production (KW) | G2: Water consumption (M3) | H2: RO prodution (M3) | I2: Transport Consupmtion (LT)
A3: =Gen!B11 -> 44136 | B3: =Gen!C11 -> 0.026 | C3: ='Summery Report'!E5 -> 3 | D3: 1 | E3: =Gen!T11 -> 956.05 | F3: =Gen!U11 -> 2415 | G3: ='Water-Meter'!E6 -> 54 | H3: ='Utility report '!AC6 -> 41 | I3: =Gen!AL11 -> 0
A4: =Gen!B12 -> 44137 | B4: =Gen!C12 -> 0.0519 | C4: ='Summery Report'!E6 -> 5 | D4: 1 | E4: =Gen!T12 -> 1107.92 | F4: =Gen!U12 -> 2617 | G4: ='Water-Meter'!E7 -> 48 | H4: ='Utility report '!AC7 -> 48 | I4: =Gen!AL12 -> 0
A5: =Gen!B13 -> 44138 | B5: =Gen!C13 -> 0.0779 | C5: ='Summery Report'!E7 -> 7 | D5: 1 | E5: =Gen!T13 -> 1164.99 | F5: =Gen!U13 -> 2592 | G5: ='Water-Meter'!E8 -> 81 | H5: ='Utility report '!AC8 -> 48 | I5: =Gen!AL13 -> 0
A6: =Gen!B14 -> 44139 | B6: =Gen!C14 -> 0.0649 | C6: ='Summery Report'!E8 -> 6 | D6: 1 | E6: =Gen!T14 -> 1046.35 | F6: =Gen!U14 -> 2655 | G6: ='Water-Meter'!E9 -> 50 | H6: ='Utility report '!AC9 -> 77 | I6: =Gen!AL14 -> 0
A7: =Gen!B15 -> 44140 | B7: =Gen!C15 -> 0.026 | C7: ='Summery Report'!E9 -> 3 | D7: 1 | E7: =Gen!T15 -> 1058.2 | F7: =Gen!U15 -> 2595 | G7: ='Water-Meter'!E10 -> 58 | H7: ='Utility report '!AC10 -> 13 | I7: =Gen!AL15 -> 0
A8: =Gen!B16 -> 44141 | B8: =Gen!C16 -> 0.0649 | C8: ='Summery Report'!E10 -> 6 | D8: 1 | E8: =Gen!T16 -> 989.82 | F8: =Gen!U16 -> 2217 | G8: ='Water-Meter'!E11 -> 62 | H8: ='Utility report '!AC11 -> 47 | I8: =Gen!AL16 -> 0
A9: =Gen!B17 -> 44142 | B9: =Gen!C17 -> 0.0519 | C9: ='Summery Report'!E11 -> 5 | D9: 1 | E9: =Gen!T17 -> 952.55 | F9: =Gen!U17 -> 2479 | G9: ='Water-Meter'!E12 -> 83 | H9: ='Utility report '!AC12 -> 45 | I9: =Gen!AL17 -> 0
A10: =Gen!B18 -> 44143 | B10: =Gen!C18 -> 0 | C10: ='Summery Report'!E12 -> 1 | D10: 1 | E10: =Gen!T18 -> 1024.56 | F10: =Gen!U18 -> 2341 | G10: ='Water-Meter'!E13 -> 63 | H10: ='Utility report '!AC13 -> 51 | I10: =Gen!AL18 -> 0
A11: =Gen!B19 -> 44144 | B11: =Gen!C19 -> 0.013 | C11: ='Summery Report'!E13 -> 2 | D11: 1 | E11: =Gen!T19 -> 1047.85 | F11: =Gen!U19 -> 2360 | G11: ='Water-Meter'!E14 -> 46 | H11: ='Utility report '!AC14 -> 47 | I11: =Gen!AL19 -> 0
A12: =Gen!B20 -> 44145 | B12: =Gen!C20 -> 0.039 | C12: ='Summery Report'!E14 -> 4 | D12: 1 | E12: =Gen!T20 -> 933.25 | F12: =Gen!U20 -> 2323 | G12: ='Water-Meter'!E15 -> 53 | H12: ='Utility report '!AC15 -> 49 | I12: =Gen!AL20 -> 0
A13: =Gen!B21 -> 44146 | B13: =Gen!C21 -> 0.0649 | C13: ='Summery Report'!E15 -> 6 | D13: 1 | E13: =Gen!T21 -> 942.23 | F13: =Gen!U21 -> 2283 | G13: ='Water-Meter'!E16 -> 63 | H13: ='Utility report '!AC16 -> 46 | I13: =Gen!AL21 -> 0
A14: =Gen!B22 -> 44147 | B14: =Gen!C22 -> 0.05 | C14: ='Summery Report'!E16 -> 5 | D14: 1 | E14: =Gen!T22 -> 1082.96 | F14: =Gen!U22 -> 2328 | G14: ='Water-Meter'!E17 -> 48 | H14: ='Utility report '!AC17 -> 43 | I14: =Gen!AL22 -> 0
... A33: =Gen!B41 -> 44166 | B33: =Gen!C41 -> 0 | C33: ='Summery Report'!E35 -> 0 | D33: 1 | E33: =Gen!T41 -> 0 | F33: =Gen!U41 -> 0 | G33: ='Water-Meter'!E36 -> 0 | H33: ='Utility report '!AC36 -> -41932 | I33: =Gen!AL41 -> 0
B34: =Gen!C42 -> 0 | C34: ='Summery Report'!E36 -> 0 | D34: 2 | E34: =Gen!T42 -> 0 | F34: =Gen!U42 -> 0 | G34: ='Water-Meter'!E37 -> 0 | H34: ='Utility report '!AC37 -> 0 | I34: =Gen!AL42 -> 0

Sheet Utility summery
A4: Date | B4: Room Occupied | C4: Electricity Units Generated KW | D4: Diseal | G4: Water | J4: Gas | N4: Cost of utilites
D5: Generator | E5: Transport | F5: Total | G5: RO | H5: STP | I5: Total Consumption | J5: 2 ton | K5: 1 Ton | L5: 1 Ton | M5: Total consumption | N5: Electricity /1.4$/liter | O5: Diseal for Transport | P5: Gas /2.38$/Kg | Q5: Total HLP Cost | R5: Electricity Cost/Room $ | S5: cost/Room $
A6: =Gen!B11 -> 44136 | B6: ='Summery Report'!E5 -> 3 | C6: =Gen!V11 -> 0.39587992 | D6: =Gen!U11 -> 2415 | E6: =Gen!AL11 -> 0 | F6: =Gen!AT11 -> 0 | G6: ='Utility report '!AC6 -> 41 | H6: ='Utility report '!AE6 -> 36 | I6: ='Water-Meter'!E6 -> 54 | J6: ='Lpg (2)'!B10 -> 30 | K6: ='Lpg (2)'!C10 -> 85 | L6: ='Lpg (2)'!D10 -> 85 | M6: ='Lpg (2)'!G10 -> 0 | O6: =E6 -> 0 | P6: ='[1]Lpg (2)'!#REF! -> #REF! | Q6: ='[1]Summery Report'!#REF! -> #REF! | R6: =N6/B6 -> 0 | S6: =Q6/B6 -> #REF!
A7: =Gen!B12 -> 44137 | B7: ='Summery Report'!E6 -> 5 | C7: =Gen!V12 -> 0.42335499 | D7: =Gen!U12 -> 2617 | E7: =Gen!AL12 -> 0 | F7: =Gen!AT12 -> 0 | G7: ='Utility report '!AC7 -> 48 | H7: ='Utility report '!AE7 -> 26 | I7: ='Water-Meter'!E7 -> 48 | J7: ='Lpg (2)'!B11 -> 25 | K7: ='Lpg (2)'!C11 -> 85 | L7: ='Lpg (2)'!D11 -> 85 | M7: ='Lpg (2)'!G11 -> 57.42 | N7: =D7*1.4 -> 3663.8 | O7: =E7*1.4 -> 0 | P7: ='[1]Lpg (2)'!#REF! -> #REF! | Q7: ='[1]Summery Report'!#REF! -> #REF! | R7: =N7/B7 -> 732.76 | S7: =Q7/B7 -> #REF!
A8: =Gen!B13 -> 44138 | B8: ='Summery Report'!E7 -> 7 | C8: =Gen!V13 -> 0.44945602 | D8: =Gen!U13 -> 2592 | E8: =Gen!AL13 -> 0 | F8: =Gen!AT13 -> 0 | G8: ='Utility report '!AC8 -> 48 | H8: ='Utility report '!AE8 -> 26 | I8: ='Water-Meter'!E8 -> 81 | J8: ='Lpg (2)'!B12 -> 22 | K8: ='Lpg (2)'!C12 -> 85 | L8: ='Lpg (2)'!D12 -> 85 | M8: ='Lpg (2)'!G12 -> 50.16 | N8: =D8*1.4 -> 3628.8 | O8: =E8*1.4 -> 0 | P8: ='[1]Lpg (2)'!#REF! -> #REF! | Q8: ='[1]Summery Report'!#REF! -> #REF! | R8: =N8/B8 -> 518.4 | S8: =Q8/B8 -> #REF!
A9: =Gen!B14 -> 44139 | B9: ='Summery Report'!E8 -> 6 | C9: =Gen!V14 -> 0.39410546 | D9: =Gen!U14 -> 2655 | E9: =Gen!AL14 -> 0 | F9: =Gen!AT14 -> 0 | G9: ='Utility report '!AC9 -> 77 | H9: ='Utility report '!AE9 -> 45 | I9: ='Water-Meter'!E9 -> 50 | J9: ='Lpg (2)'!B13 -> 20 | K9: ='Lpg (2)'!C13 -> 85 | L9: ='Lpg (2)'!D13 -> 85 | M9: ='Lpg (2)'!G13 -> 57.816 | N9: =D9*1.4 -> 3717 | O9: =E9*1.4 -> 0 | P9: ='[1]Lpg (2)'!#REF! -> #REF! | Q9: ='[1]Summery Report'!#REF! -> #REF! | R9: =N9/B9 -> 619.5 | S9: =Q9/B9 -> #REF!
A10: =Gen!B15 -> 44140 | B10: ='Summery Report'!E9 -> 3 | C10: =Gen!V15 -> 0.4077842 | D10: =Gen!U15 -> 2595 | E10: =Gen!AL15 -> 0 | F10: =Gen!AT15 -> 0 | G10: ='Utility report '!AC10 -> 13 | H10: ='Utility report '!AE10 -> 46 | I10: ='Water-Meter'!E10 -> 58 | J10: ='Lpg (2)'!B14 -> 19 | K10: ='Lpg (2)'!C14 -> 85 | L10: ='Lpg (2)'!D14 -> 85 | M10: ='Lpg (2)'!G14 -> 59.972 | N10: =D10*1.4 -> 3633 | O10: =E10*1.4 -> 0 | P10: ='[1]Lpg (2)'!#REF! -> #REF! | Q10: ='[1]Summery Report'!#REF! -> #REF! | R10: =N10/B10 -> 1211 | S10: =Q10/B10 -> #REF!
A11: =Gen!B16 -> 44141 | B11: ='Summery Report'!E10 -> 6 | C11: =Gen!V16 -> 0.4464682 | D11: =Gen!U16 -> 2217 | E11: =Gen!AL16 -> 0 | F11: =Gen!AT16 -> 0 | G11: ='Utility report '!AC11 -> 47 | H11: ='Utility report '!AE11 -> 45 | I11: ='Water-Meter'!E11 -> 62 | J11: ='Lpg (2)'!B15 -> 18 | K11: ='Lpg (2)'!C15 -> 85 | L11: ='Lpg (2)'!D15 -> 85 | M11: ='Lpg (2)'!G15 -> 52.976 | N11: =D11*1.4 -> 3103.8 | O11: =E11*1.4 -> 0 | P11: ='[1]Lpg (2)'!#REF! -> #REF! | Q11: ='[1]Summery Report'!#REF! -> #REF! | R11: =N11/B11 -> 517.3 | S11: =Q11/B11 -> #REF!
A12: =Gen!B17 -> 44142 | B12: ='Summery Report'!E11 -> 5 | C12: =Gen!V17 -> 0.38424768 | D12: =Gen!U17 -> 2479 | E12: =Gen!AL17 -> 0 | F12: =Gen!AT17 -> 0 | G12: ='Utility report '!AC12 -> 45 | H12: ='Utility report '!AE12 -> 46 | I12: ='Water-Meter'!E12 -> 83 | J12: ='Lpg (2)'!B16 -> 85 | K12: ='Lpg (2)'!C16 -> 85 | L12: ='Lpg (2)'!D16 -> 85 | M12: ='Lpg (2)'!G16 -> 75.68 | N12: =D12*1.4 -> 3470.6 | O12: =E12*1.4 -> 0 | P12: ='[1]Lpg (2)'!#REF! -> #REF! | Q12: ='[1]Summery Report'!#REF! -> #REF! | R12: =N12/B12 -> 694.12 | S12: =Q12/B12 -> #REF!
A13: =Gen!B18 -> 44143 | B13: ='Summery Report'!E12 -> 1 | C13: =Gen!V18 -> 0.43765912 | D13: =Gen!U18 -> 2341 | E13: =Gen!AL18 -> 0 | F13: =Gen!AT18 -> 0 | G13: ='Utility report '!AC13 -> 51 | H13: ='Utility report '!AE13 -> 46 | I13: ='Water-Meter'!E13 -> 63 | J13: ='Lpg (2)'!B17 -> 85 | K13: ='Lpg (2)'!C17 -> 83 | L13: ='Lpg (2)'!D17 -> 85 | M13: ='Lpg (2)'!G17 -> 51.7 | N13: =D13*1.4 -> 3277.4 | O13: =E13*1.4 -> 0 | P13: ='[1]Lpg (2)'!#REF! -> #REF! | Q13: ='[1]Summery Report'!#REF! -> #REF! | R13: =N13/B13 -> 3277.4 | S13: =Q13/B13 -> #REF!
A14: =Gen!B19 -> 44144 | B14: ='Summery Report'!E13 -> 2 | C14: =Gen!V19 -> 0.44400424 | D14: =Gen!U19 -> 2360 | E14: =Gen!AL19 -> 0 | F14: =Gen!AT19 -> 0 | G14: ='Utility report '!AC14 -> 47 | H14: ='Utility report '!AE14 -> 41 | I14: ='Water-Meter'!E14 -> 46 | J14: ='Lpg (2)'!B18 -> 85 | K14: ='Lpg (2)'!C18 -> 82 | L14: ='Lpg (2)'!D18 -> 85 | M14: ='Lpg (2)'!G18 -> 53.592 | N14: =D14*1.4 -> 3304 | O14: =E14*1.4 -> 0 | P14: ='[1]Lpg (2)'!#REF! -> #REF! | Q14: ='[1]Summery Report'!#REF! -> #REF! | R14: =N14/B14 -> 1652 | S14: =Q14/B14 -> #REF!
A15: =Gen!B20 -> 44145 | B15: ='Summery Report'!E14 -> 4 | C15: =Gen!V20 -> 0.40174344 | D15: =Gen!U20 -> 2323 | E15: =Gen!AL20 -> 0 | F15: =Gen!AT20 -> 0 | G15: ='Utility report '!AC15 -> 49 | H15: ='Utility report '!AE15 -> 44 | I15: ='Water-Meter'!E15 -> 53 | J15: ='Lpg (2)'!B19 -> 85 | K15: ='Lpg (2)'!C19 -> 80 | L15: ='Lpg (2)'!D19 -> 85 | M15: ='Lpg (2)'!G19 -> 23.54 | N15: =D15*1.4 -> 3252.2 | O15: =E15*1.4 -> 0 | P15: ='[1]Lpg (2)'!#REF! -> #REF! | Q15: ='[1]Summery Report'!#REF! -> #REF! | R15: =N15/B15 -> 813.05 | S15: =Q15/B15 -> #REF!
A16: =Gen!B21 -> 44146 | B16: ='Summery Report'!E15 -> 6 | C16: =Gen!V21 -> 0.41271572 | D16: =Gen!U21 -> 2283 | E16: =Gen!AL21 -> 0 | F16: =Gen!AT21 -> 0 | G16: ='Utility report '!AC16 -> 46 | H16: ='Utility report '!AE16 -> 44 | I16: ='Water-Meter'!E16 -> 63 | J16: ='Lpg (2)'!B20 -> 85 | K16: ='Lpg (2)'!C20 -> 72 | L16: ='Lpg (2)'!D20 -> 85 | M16: ='Lpg (2)'!G20 -> 75.328 | N16: =D16*1.4 -> 3196.2 | O16: =E16*1.4 -> 0 | P16: ='[1]Lpg (2)'!#REF! -> #REF! | Q16: ='[1]Summery Report'!#REF! -> #REF! | R16: =N16/B16 -> 532.7 | S16: =Q16/B16 -> #REF!
A17: =Gen!B22 -> 44147 | B17: ='Summery Report'!E16 -> 5 | C17: =Gen!V22 -> 0.465189 | D17: =Gen!U22 -> 2328 | E17: =Gen!AL22 -> 0 | F17: =Gen!AT22 -> 0 | G17: ='Utility report '!AC17 -> 43 | H17: ='Utility report '!AE17 -> 43 | I17: ='Water-Meter'!E17 -> 48 | J17: ='Lpg (2)'!B21 -> 85 | K17: ='Lpg (2)'!C22 -> 61 | L17: ='Lpg (2)'!D21 -> 85 | M17: ='Lpg (2)'!G21 -> 54.164 | N17: =D17*1.4 -> 3259.2 | O17: =E17*1.4 -> 0 | P17: ='[1]Lpg (2)'!#REF! -> #REF! | Q17: ='[1]Summery Report'!#REF! -> #REF! | R17: =N17/B17 -> 651.84 | S17: =Q17/B17 -> #REF!
A18: =Gen!B23 -> 44148 | B18: ='Summery Report'!E17 -> 7 | C18: =Gen!V23 -> 0.40613463 | D18: =Gen!U23 -> 2362 | E18: =Gen!AL23 -> 0 | F18: =Gen!AT23 -> 0 | G18: ='Utility report '!AC18 -> 42 | H18: ='Utility report '!AE18 -> 41 | I18: ='Water-Meter'!E18 -> 62 | J18: ='Lpg (2)'!B22 -> 85 | K18: ='Lpg (2)'!C23 -> 57 | L18: ='Lpg (2)'!D22 -> 85 | M18: ='Lpg (2)'!G22 -> 68.508 | N18: =D18*1.4 -> 3306.8 | O18: =E18*1.4 -> 0 | P18: ='[1]Lpg (2)'!#REF! -> #REF! | Q18: ='[1]Summery Report'!#REF! -> #REF! | R18: =N18/B18 -> 472.4 | S18: =Q18/B18 -> #REF!
A19: =Gen!B24 -> 44149 | B19: ='Summery Report'!E18 -> 15 | C19: =Gen!V24 -> 0.40457563 | D19: =Gen!U24 -> 2380 | E19: =Gen!AL24 -> 0 | F19: =Gen!AT24 -> 0 | G19: ='Utility report '!AC19 -> 42 | H19: ='Utility report '!AE19 -> 45 | I19: ='Water-Meter'!E19 -> 52 | J19: ='Lpg (2)'!B23 -> 85 | K19: ='Lpg (2)'!C24 -> 53 | L19: ='Lpg (2)'!D23 -> 85 | M19: ='Lpg (2)'!G23 -> 69.344 | N19: =D19*1.4 -> 3332 | O19: =E19*1.4 -> 0 | P19: ='[1]Lpg (2)'!#REF! -> #REF! | Q19: ='[1]Summery Report'!#REF! -> #REF! | R19: =N19/B19 -> 222.13333 | S19: =Q19/B19 -> #REF!
A20: =Gen!B25 -> 44150 | B20: ='Summery Report'!E19 -> 13 | C20: =Gen!V25 -> 0.45146341 | D20: =Gen!U25 -> 2337 | E20: =Gen!AL25 -> 0 | F20: =Gen!AT25 -> 0 | G20: ='Utility report '!AC20 -> 39 | H20: ='Utility report '!AE20 -> 43 | I20: ='Water-Meter'!E20 -> 78 | J20: ='Lpg (2)'!B24 -> 85 | K20: ='Lpg (2)'!C25 -> 45 | L20: ='Lpg (2)'!D24 -> 85 | M20: ='Lpg (2)'!G24 -> 95.392 | N20: =D20*1.4 -> 3271.8 | O20: =E20*1.4 -> 0 | P20: ='[1]Lpg (2)'!#REF! -> #REF! | Q20: ='[1]Summery Report'!#REF! -> #REF! | R20: =N20/B20 -> 251.67692 | S20: =Q20/B20 -> #REF!
A21: =Gen!B26 -> 44151 | B21: ='Summery Report'!E20 -> 12 | C21: =Gen!V26 -> 0.4577188 | D21: =Gen!U26 -> 2468 | E21: =Gen!AL26 -> 0 | F21: =Gen!AT26 -> 0 | G21: ='Utility report '!AC21 -> 37 | H21: ='Utility report '!AE21 -> 52 | I21: ='Water-Meter'!E21 -> 52 | J21: ='Lpg (2)'!B25 -> 85 | K21: ='Lpg (2)'!C25 -> 45 | L21: ='Lpg (2)'!D25 -> 85 | M21: ='Lpg (2)'!G25 -> 82.764 | N21: =D21*1.4 -> 3455.2 | O21: =E21*1.4 -> 0 | P21: ='[1]Lpg (2)'!#REF! -> #REF! | Q21: ='[1]Summery Report'!#REF! -> #REF! | R21: =N21/B21 -> 287.93333 | S21: =Q21/B21 -> #REF!
A22: =Gen!B27 -> 44152 | B22: ='Summery Report'!E21 -> 0 | C22: =Gen!V27 -> 0.4099647 | D22: =Gen!U27 -> 2266 | E22: =Gen!AL27 -> 0 | F22: =Gen!AT27 -> 0 | G22: ='Utility report '!AC22 -> 32 | H22: ='Utility report '!AE22 -> 10 | I22: ='Water-Meter'!E22 -> 53 | J22: ='Lpg (2)'!B26 -> 85 | K22: ='Lpg (2)'!C26 -> 42 | L22: ='Lpg (2)'!D26 -> 85 | M22: ='Lpg (2)'!G26 -> 77.572 | N22: =D22*1.4 -> 3172.4 | O22: =E22*1.4 -> 0 | P22: ='[1]Lpg (2)'!#REF! -> #REF! | Q22: ='[1]Summery Report'!#REF! -> #REF! | R22: =N22/B22 -> #DIV/0! | S22: =Q22/B22 -> #REF!
A23: =Gen!B28 -> 44153 | B23: ='Summery Report'!E22 -> 0 | C23: =Gen!V28 -> 0.41586322 | D23: =Gen!U28 -> 2398 | E23: =Gen!AL28 -> 0 | F23: =Gen!AT28 -> 0 | G23: ='Utility report '!AC23 -> 28 | H23: ='Utility report '!AE23 -> 13 | I23: ='Water-Meter'!E23 -> 51 | J23: ='Lpg (2)'!B27 -> 85 | K23: ='Lpg (2)'!C27 -> 35 | L23: ='Lpg (2)'!D27 -> 85 | M23: ='Lpg (2)'!G27 -> 75.284 | N23: =D23*1.4 -> 3357.2 | O23: =E23*1.4 -> 0 | P23: ='[1]Lpg (2)'!#REF! -> #REF! | Q23: ='[1]Summery Report'!#REF! -> #REF! | R23: =N23/B23 -> #DIV/0! | S23: =Q23/B23 -> #REF!
A24: =Gen!B29 -> 44154 | B24: ='Summery Report'!E23 -> 0 | C24: =Gen!V29 -> 0.40265559 | D24: =Gen!U29 -> 2587 | E24: =Gen!AL29 -> 0 | F24: =Gen!AT29 -> 0 | G24: ='Utility report '!AC24 -> 25 | H24: ='Utility report '!AE24 -> 35 | I24: ='Water-Meter'!E24 -> 127 | J24: ='Lpg (2)'!B28 -> 85 | K24: ='Lpg (2)'!C28 -> 31 | L24: ='Lpg (2)'!D28 -> 85 | M24: ='Lpg (2)'!G28 -> 73.524 | N24: =D24*1.4 -> 3621.8 | O24: =E24*1.4 -> 0 | P24: ='[1]Lpg (2)'!#REF! -> #REF! | Q24: ='[1]Summery Report'!#REF! -> #REF! | R24: =N24/B24 -> #DIV/0! | S24: =Q24/B24 -> #REF!
A25: =Gen!B30 -> 44155 | B25: ='Summery Report'!E24 -> 0 | C25: =Gen!V30 -> 0.38775463 | D25: =Gen!U30 -> 2592 | E25: =Gen!AL30 -> 0 | F25: =Gen!AT30 -> 0 | G25: ='Utility report '!AC25 -> 25 | H25: ='Utility report '!AE25 -> 37 | I25: ='Water-Meter'!E25 -> 46 | J25: ='Lpg (2)'!B29 -> 85 | K25: ='Lpg (2)'!C29 -> 25 | L25: ='Lpg (2)'!D29 -> 85 | M25: ='Lpg (2)'!G29 -> 99.176 | N25: =D25*1.4 -> 3628.8 | O25: =E25*1.4 -> 0 | P25: ='[1]Lpg (2)'!#REF! -> #REF! | Q25: ='[1]Summery Report'!#REF! -> #REF! | R25: =N25/B25 -> #DIV/0! | S25: =Q25/B25 -> #REF!
A26: =Gen!B31 -> 44156 | B26: ='Summery Report'!E25 -> 0 | C26: =Gen!V31 -> 0.4135578 | D26: =Gen!U31 -> 2673 | E26: =Gen!AL31 -> 0 | F26: =Gen!AT31 -> 0 | G26: ='Utility report '!AC26 -> 23 | H26: ='Utility report '!AE26 -> 35 | I26: ='Water-Meter'!E26 -> 47 | J26: ='Lpg (2)'!B30 -> 85 | K26: ='Lpg (2)'!C30 -> 20 | L26: ='Lpg (2)'!D30 -> 85 | M26: ='Lpg (2)'!G30 -> 85.36 | N26: =D26*1.4 -> 3742.2 | O26: =E26*1.4 -> 0 | P26: ='[1]Lpg (2)'!#REF! -> #REF! | Q26: ='[1]Summery Report'!#REF! -> #REF! | R26: =N26/B26 -> #DIV/0! | S26: =Q26/B26 -> #REF!
A27: =Gen!B32 -> 44157 | B27: ='Summery Report'!E26 -> 0 | C27: =Gen!V32 -> 0.40388395 | D27: =Gen!U32 -> 2585 | E27: =Gen!AL32 -> 0 | F27: =Gen!AT32 -> 0 | G27: ='Utility report '!AC27 -> 0 | H27: ='Utility report '!AE27 -> 35 | I27: ='Water-Meter'!E27 -> 51 | J27: ='Lpg (2)'!B31 -> 85 | K27: ='Lpg (2)'!C31 -> 15 | L27: ='Lpg (2)'!D31 -> 85 | M27: ='Lpg (2)'!G31 -> 86.548 | N27: =D27*1.4 -> 3619 | O27: =E27*1.4 -> 0 | P27: ='[1]Lpg (2)'!#REF! -> #REF! | Q27: ='[1]Summery Report'!#REF! -> #REF! | R27: =N27/B27 -> #DIV/0! | S27: =Q27/B27 -> #REF!
A28: =Gen!B33 -> 44158 | B28: ='Summery Report'!E27 -> 0 | C28: =Gen!V33 -> 0.41547739 | D28: =Gen!U33 -> 2587 | E28: =Gen!AL33 -> 0 | F28: =Gen!AT33 -> 0 | G28: ='Utility report '!AC28 -> 24 | H28: ='Utility report '!AE28 -> 36 | I28: ='Water-Meter'!E28 -> 61 | J28: ='Lpg (2)'!B32 -> 85 | K28: ='Lpg (2)'!C32 -> 11 | L28: ='Lpg (2)'!D32 -> 85 | M28: ='Lpg (2)'!G32 -> 65.736 | N28: =D28*1.4 -> 3621.8 | O28: =E28*1.4 -> 0 | P28: ='[1]Lpg (2)'!#REF! -> #REF! | Q28: ='[1]Summery Report'!#REF! -> #REF! | R28: =N28/B28 -> #DIV/0! | S28: =Q28/B28 -> #REF!
A29: =Gen!B34 -> 44159 | B29: ='Summery Report'!E28 -> 0 | C29: =Gen!V34 -> 0.42898569 | D29: =Gen!U34 -> 2376 | E29: =Gen!AL34 -> 0 | F29: =Gen!AT34 -> 0 | G29: ='Utility report '!AC29 -> 35 | H29: ='Utility report '!AE29 -> 35 | I29: ='Water-Meter'!E29 -> 49 | J29: ='Lpg (2)'!B33 -> 85 | K29: ='Lpg (2)'!C33 -> 9 | L29: ='Lpg (2)'!D33 -> 85 | M29: ='Lpg (2)'!G33 -> 64.108 | N29: =D29*1.4 -> 3326.4 | O29: =E29*1.4 -> 0 | P29: ='[1]Lpg (2)'!#REF! -> #REF! | Q29: ='[1]Summery Report'!#REF! -> #REF! | R29: =N29/B29 -> #DIV/0! | S29: =Q29/B29 -> #REF!
A30: =Gen!B35 -> 44160 | B30: ='Summery Report'!E29 -> 0 | C30: =Gen!V35 -> 0.43357839 | D30: =Gen!U35 -> 2258 | E30: =Gen!AL35 -> 0 | F30: =Gen!AT35 -> 0 | G30: ='Utility report '!AC30 -> 39 | H30: ='Utility report '!AE30 -> 33 | I30: ='Water-Meter'!E30 -> 50 | J30: ='Lpg (2)'!B34 -> 85 | K30: ='Lpg (2)'!C34 -> 5 | L30: ='Lpg (2)'!D34 -> 85 | M30: ='Lpg (2)'!G34 -> 80.344 | N30: =D30*1.4 -> 3161.2 | O30: =E30*1.4 -> 0 | P30: ='[1]Lpg (2)'!#REF! -> #REF! | Q30: ='[1]Summery Report'!#REF! -> #REF! | R30: =N30/B30 -> #DIV/0! | S30: =Q30/B30 -> #REF!
A31: =Gen!B36 -> 44161 | B31: ='Summery Report'!E30 -> 0 | C31: =Gen!V36 -> 0.41160089 | D31: =Gen!U36 -> 2255 | E31: =Gen!AL36 -> 0 | F31: =Gen!AT36 -> 0 | G31: ='Utility report '!AC31 -> 46 | H31: ='Utility report '!AE31 -> 35 | I31: ='Water-Meter'!E31 -> 56 | J31: ='Lpg (2)'!B35 -> 85 | K31: ='Lpg (2)'!C35 -> 3 | L31: ='Lpg (2)'!D35 -> 85 | M31: ='Lpg (2)'!G35 -> 78.716 | N31: =D31*1.4 -> 3157 | O31: =E31*1.4 -> 0 | P31: ='[1]Lpg (2)'!#REF! -> #REF! | Q31: ='[1]Summery Report'!#REF! -> #REF! | R31: =N31/B31 -> #DIV/0! | S31: =Q31/B31 -> #REF!
A32: =Gen!B37 -> 44162 | B32: ='Summery Report'!E31 -> 0 | C32: =Gen!V37 -> 0.42654697 | D32: =Gen!U37 -> 2395 | E32: =Gen!AL37 -> 0 | F32: =Gen!AT37 -> 0 | G32: ='Utility report '!AC32 -> 46 | H32: ='Utility report '!AE32 -> 32 | I32: ='Water-Meter'!E32 -> 47 | J32: ='Lpg (2)'!B36 -> 85 | K32: ='Lpg (2)'!C36 -> 2 | L32: ='Lpg (2)'!D36 -> 85 | M32: ='Lpg (2)'!G36 -> 42.372 | N32: =D32*1.4 -> 3353 | O32: =E32*1.4 -> 0 | P32: ='[1]Lpg (2)'!#REF! -> #REF! | Q32: ='[1]Summery Report'!#REF! -> #REF! | R32: =N32/B32 -> #DIV/0! | S32: =Q32/B32 -> #REF!
... A36: =Gen!B41 -> 44166 | B36: ='Summery Report'!E35 -> 0 | C36: =Gen!V41 -> #DIV/0! | D36: =Gen!U41 -> 0 | E36: =Gen!AL41 -> 0 | F36: =Gen!AT41 -> 0 | G36: ='Utility report '!AC36 -> -41932 | H36: ='Utility report '!AE36 -> -207823 | I36: ='Water-Meter'!E36 -> 0 | J36: ='Lpg (2)'!B40 -> 0 | K36: ='Lpg (2)'!C40 -> 0 | L36: ='Lpg (2)'!D40 -> 0 | M36: ='Lpg (2)'!G40 -> -323055.44 | N36: =D36*1.4 -> 0 | O36: =E36*1.4 -> 0 | P36: ='[1]Lpg (2)'!#REF! -> #REF! | Q36: ='[1]Summery Report'!#REF! -> #REF! | R36: =N36/B36 -> #DIV/0! | S36: =Q36/B36 -> #REF!
A37: =Gen!B42 -> 0 | B37: ='Summery Report'!E36 -> 0 | C37: =Gen!V42 -> 0 | D37: =Gen!U42 -> 0 | E37: =Gen!AL42 -> 0 | F37: =Gen!AT42 -> 0 | G37: ='Utility report '!AC37 -> 0 | H37: ='Utility report '!AE37 -> 0 | I37: ='Water-Meter'!E37 -> 0 | J37: ='Lpg (2)'!B41 -> 0 | K37: ='Lpg (2)'!C41 -> 0 | L37: ='Lpg (2)'!D41 -> 0 | M37: ='Lpg (2)'!G41 -> 0 | Q37: ='[1]Summery Report'!#REF! -> #REF! | R37: =N37/B37 -> #DIV/0! | S37: =Q37/B37 -> #REF!
A39: Total | B39: =SUM(B7:B37) -> 97 | C39: =SUM(C7:C35) -> #DIV/0! | D39: =SUM(D7:D35) -> 65573 | E39: =SUM(E7:E35) -> 0 | F39: =SUM(F7:F35) -> 0 | G39: =SUM(G7:G35) -> 1126 | H39: =SUM(H7:H35) -> 1073 | I39: =SUM(I7:I35) -> 1690 | J39: =SUM(J7:J35) -> 2144 | ... S39: =SUM(S7:S35) -> #REF!

Sheet Utility report 
A1: DAILY UTILITY REPORT NOVEMBER 2020
A2: Date | B2: Total occupancy | H2: Diesel balance LTS | I2: Diesel Deliveries | J2: Gen.Diesel consumption LTS | L2: Total Diesel consumption LTS | M2: Water Meter reading | N2: Water consumption m³ | O2: R.O WATER PRODUCTION LTRS + TIME | AA2: Total RO production | AB2: RO Meter reading | AD2: 0 | AE2: STP | AF2: GAS TANK A | AG2: GAS TANK B | AH2: GAS TANK C | AI2: Total Gas Tanks | AJ2: Kg /day | AK2: TOTAL GAS cons.
A3: Rate Tsh /$ | B3: 1640 | C3: Diesel cost / lits | D3: 2175 | F3: =SUM(D3/B3) -> 1.3262195 | H3: =Gen!D11 -> 32519.1 | K3: Transport consumption | M3: Balance | O3: PLANT NO 1 | S3: PLANT NO 2 | W3: PLANT NO 3 | AA3: /day | AB3: Balance | AD3: 0 | AE3: Production | AF3: Capacity | AG3: Capacity | AH3: Capacity | AI3: Kg | AJ3: /day | AK3: /day
B4: Rooms OCC | C4: % | D4: Guest Rooms Occ | F4: Electricity Production Cost /Room Occ by guest | G4: All Cost /Room Occ by guest | O4: Flow M3 | P4: Reading Hours Meter | Q4: Hrs | R4: total production M3 | S4: Flow M3 | T4: Reading Hours Meter | U4: Hrs | V4: total production M3 | W4: Flow M3 | X4: READING HOURS METER | Y4: Hrs | Z4: total production M3 | AA4: M3 | AC4: M3 | AE4: M3 | AF4: 2000 | AG4: 1000 | AH4: 1000 | AI4: =SUM([2]Sheet1!$AA$36) -> 950 | AJ4: Kg | AK4: M3
P5: 19032 | T5: 17126 | X5: 25503 | AB5: 40765 | AD5: 206714 | AF5: 0.85 | AG5: 0.85 | AH5: 0.85
A6: =Gen!B11 -> 44136 | B6: ='Summery Report'!E5 -> 3 | C6: =Gen!C11 -> 0.026 | D6: ='Summery Report'!E5 -> 3 | E6: =SUM(F3) -> 1.3262195 | F6: =SUM(J6*E6)/D6 -> 1067.6067 | G6: =SUM(L6*E6)/D6 -> 1067.6067 | H6: =Gen!D11 -> 32519.1 | I6: =Gen!F11 -> 0 | J6: =Gen!U11 -> 2415 | K6: =Gen!AL11 -> 0 | L6: =SUM(J6:K6) -> 2415 | M6: ='Water-Meter'!K46 -> 524.55387 | N6: ='Water-Meter'!E6 -> 54 | P6: 19032 | Q6: =SUM(P6-P5) -> 0 | R6: =SUM(Q6*O6) -> 0 | T6: 17126 | U6: =T6-T5 -> 0 | V6: - | W6: 2.3 | X6: 25523 | Y6: =X6-X5 -> 20 | Z6: =Y6-Y5 -> 20 | AA6: =Z6-Z5 -> 20 | AB6: 40806 | AC6: =AB6-AB5 -> 41 | AD6: 206750 | AE6: =AD6-AD5 -> 36 | AF6: ='Lpg (2)'!B10*2000/85 -> 705.88235 | AG6: ='Lpg (2)'!C10*1000/85 -> 1000 | AH6: ='Lpg (2)'!D10*1000/85 -> 1000 | AI6: =SUM(AF6*2000)+(AG6*1000)+(AH6*1000) -> 3411764.7 | AJ6: =SUM(AI5-AI6) -> -3411764.7
A7: =Gen!B12 -> 44137 | B7: ='Summery Report'!E6 -> 5 | C7: =Gen!C12 -> 0.0519 | D7: ='Summery Report'!E6 -> 5 | E7: =SUM(E6) -> 1.3262195 | F7: =SUM(J7*E7)/D7 -> 694.14329 | G7: =SUM(L7*E7)/D7 -> 694.14329 | H7: =Gen!D12 -> 31563.05 | I7: =Gen!F12 -> 0 | J7: =Gen!U12 -> 2617 | K7: =Gen!AL12 -> 0 | L7: =SUM(J7:K7) -> 2617 | M7: ='Water-Meter'!K47 -> 416.41124 | N7: ='Water-Meter'!E7 -> 48 | P7: 19032 | Q7: =SUM(P7-P6) -> 0 | R7: =SUM(Q7*O7) -> 0 | T7: 17126 | U7: =T7-T6 -> 0 | V7: =SUM(U7*S7) -> 0 | W7: 2.3 | X7: 25548 | Y7: =X7-X6 -> 25 | Z7: =SUM(Y7*W7) -> 57.5 | AA7: =SUM(Z7*X9) -> 1471770 | AB7: 40854 | AC7: =AB7-AB6 -> 48 | AD7: 206776 | AE7: =AD7-AD6 -> 26 | AF7: ='Lpg (2)'!B11*2000/85 -> 588.23529 | AG7: ='Lpg (2)'!C11*1000/85 -> 1000 | AH7: ='Lpg (2)'!D11*1000/85 -> 1000 | AI7: =SUM(AF6*2000)+(AG7*1000)+(AH7*1000) -> 3411764.7 | AJ7: =SUM(AI6-AI7) -> 0
A8: =Gen!B13 -> 44138 | B8: ='Summery Report'!E7 -> 7 | C8: =Gen!C13 -> 0.0779 | D8: ='Summery Report'!E7 -> 7 | E8: =SUM(E7) -> 1.3262195 | F8: =SUM(J8*E8)/D8 -> 491.08014 | G8: =SUM(L8*E8)/D8 -> 491.08014 | H8: =Gen!D13 -> 30433.51 | I8: =Gen!F13 -> 0 | J8: =Gen!U13 -> 2592 | K8: =Gen!AL13 -> 0 | L8: =SUM(J8:K8) -> 2592 | M8: ='Water-Meter'!K48 -> 420.68537 | N8: ='Water-Meter'!E8 -> 81 | P8: 19032 | Q8: =SUM(P8-P7) -> 0 | R8: =SUM(Q8*O8) -> 0 | T8: 17126 | U8: =T8-T7 -> 0 | V8: =SUM(U8*S8) -> 0 | W8: 2.3 | X8: 25572 | Y8: =X8-X7 -> 24 | Z8: =SUM(Y8*W8) -> 55.2 | AA8: =SUM(Z8*X10) -> 1414113.6 | AB8: 40902 | AC8: =AB8-AB7 -> 48 | AD8: 206802 | AE8: =AD8-AD7 -> 26 | AF8: ='Lpg (2)'!B12*2000/85 -> 517.64706 | AG8: ='Lpg (2)'!C12*1000/85 -> 1000 | AH8: ='Lpg (2)'!D12*1000/85 -> 1000 | AI8: =SUM(AF7*2000)+(AG8*1000)+(AH8*1000) -> 3176470.6 | AJ8: =SUM(AI7-AI8) -> 235294.12
A9: =Gen!B14 -> 44139 | B9: ='Summery Report'!E8 -> 6 | C9: =Gen!C14 -> 0.0649 | D9: ='Summery Report'!E8 -> 6 | E9: =SUM(E8) -> 1.3262195 | F9: =SUM(J9*E9)/D9 -> 586.85213 | G9: =SUM(L9*E9)/D9 -> 586.85213 | H9: =Gen!D14 -> 47230.25 | I9: =Gen!F14 -> 18000 | J9: =Gen!U14 -> 2655 | K9: =Gen!AL14 -> 0 | L9: =SUM(J9:K9) -> 2655 | M9: ='Water-Meter'!K49 -> 446.25444 | N9: ='Water-Meter'!E9 -> 50 | P9: 19032 | Q9: =SUM(P9-P8) -> 0 | R9: =SUM(Q9*O9) -> 0 | T9: 17126 | U9: =T9-T8 -> 0 | V9: =SUM(U9*S9) -> 0 | W9: 2.3 | X9: 25596 | Y9: =X9-X8 -> 24 | Z9: =SUM(Y9*W9) -> 55.2 | AA9: =SUM(Z9*X11) -> 1415438.4 | AB9: 40979 | AC9: =AB9-AB8 -> 77 | AD9: 206847 | AE9: =AD9-AD8 -> 45 | AF9: ='Lpg (2)'!B13*2000/85 -> 470.58824 | AG9: ='Lpg (2)'!C13*1000/85 -> 1000 | AH9: ='Lpg (2)'!D13*1000/85 -> 1000 | AI9: =SUM(AF8*2000)+(AG9*1000)+(AH9*1000) -> 3035294.1 | AJ9: =SUM(AI8-AI9) -> 141176.47
A10: =Gen!B15 -> 44140 | B10: ='Summery Report'!E9 -> 3 | C10: =Gen!C15 -> 0.026 | D10: ='Summery Report'!E9 -> 3 | E10: =SUM(E9) -> 1.3262195 | F10: =SUM(J10*E10)/D10 -> 1147.1799 | G10: =SUM(L10*E10)/D10 -> 1147.1799 | H10: =Gen!D15 -> 46132.8 | I10: =Gen!F15 -> 0 | J10: =Gen!U15 -> 2595 | K10: =Gen!AL15 -> 0 | L10: =SUM(J10:K10) -> 2595 | M10: ='Water-Meter'!K50 -> 533.57756 | N10: ='Water-Meter'!E10 -> 58 | P10: 19032 | Q10: =SUM(P10-P9) -> 0 | R10: =SUM(Q10*O10) -> 0 | T10: 17126 | U10: =T10-T9 -> 0 | V10: =SUM(U10*S10) -> 0 | W10: 2.1 | X10: 25618 | Y10: =X10-X9 -> 22 | Z10: =SUM(Y10*W10) -> 46.2 | AA10: =SUM(Z10*X12) -> 1185723 | AB10: 40992 | AC10: =AB10-AB9 -> 13 | AD10: 206893 | AE10: =AD10-AD9 -> 46 | AF10: ='Lpg (2)'!B14*2000/85 -> 447.05882 | AG10: ='Lpg (2)'!C14*1000/85 -> 1000 | AH10: ='Lpg (2)'!D14*1000/85 -> 1000 | AI10: =SUM(AF9*2000)+(AG10*1000)+(AH10*1000) -> 2941176.5 | AJ10: =SUM(AI9-AI10) -> 94117.647
A11: =Gen!B16 -> 44141 | B11: ='Summery Report'!E10 -> 6 | C11: =Gen!C16 -> 0.0649 | D11: ='Summery Report'!E10 -> 6 | E11: =SUM(E10) -> 1.3262195 | F11: =SUM(J11*E11)/D11 -> 490.03811 | G11: =SUM(L11*E11)/D11 -> 490.03811 | H11: =Gen!D16 -> 45014.45 | I11: =Gen!F16 -> 0 | J11: =Gen!U16 -> 2217 | K11: =Gen!AL16 -> 0 | L11: =SUM(J11:K11) -> 2217 | M11: ='Water-Meter'!K51 -> 553.0753 | N11: ='Water-Meter'!E11 -> 62 | P11: 19032 | Q11: =SUM(P11-P10) -> 0 | R11: =SUM(Q11*O11) -> 0 | T11: 17126 | U11: =T11-T10 -> 0 | V11: =SUM(U11*S11) -> 0 | W11: 2.1 | X11: 25642 | Y11: =X11-X10 -> 24 | Z11: =SUM(Y11*W11) -> 50.4 | AA11: =SUM(Z11*X13) -> 1294725.6 | AB11: 41039 | AC11: =AB11-AB10 -> 47 | AD11: 206938 | AE11: =AD11-AD10 -> 45 | AF11: ='Lpg (2)'!B15*2000/85 -> 423.52941 | AG11: ='Lpg (2)'!C15*1000/85 -> 1000 | AH11: ='Lpg (2)'!D15*1000/85 -> 1000 | AI11: =SUM(AF10*2000)+(AG11*1000)+(AH11*1000) -> 2894117.6 | AJ11: =SUM(AI10-AI11) -> 47058.824
A12: =Gen!B17 -> 44142 | B12: ='Summery Report'!E11 -> 5 | C12: =Gen!C17 -> 0.0519 | D12: ='Summery Report'!E11 -> 5 | E12: =SUM(E11) -> 1.3262195 | F12: =SUM(J12*E12)/D12 -> 657.53963 | G12: =SUM(L12*E12)/D12 -> 657.53963 | H12: =Gen!D17 -> 43932.63 | I12: =Gen!F17 -> 0 | J12: =Gen!U17 -> 2479 | K12: =Gen!AL17 -> 0 | L12: =SUM(J12:K12) -> 2479 | M12: ='Water-Meter'!K52 -> 466.9685 | N12: ='Water-Meter'!E12 -> 83 | P12: 19032 | Q12: =SUM(P12-P11) -> 0 | R12: =SUM(Q12*O12) -> 0 | T12: 17126 | U12: =T12-T11 -> 0 | V12: =SUM(U12*S12) -> 0 | W12: 2.3 | X12: 25665 | Y12: =X12-X11 -> 23 | Z12: =SUM(Y12*W12) -> 52.9 | AA12: =SUM(Z12*X14) -> 1360164.8 | AB12: 41084 | AC12: =AB12-AB11 -> 45 | AD12: 206984 | AE12: =AD12-AD11 -> 46 | AF12: ='Lpg (2)'!B16*2000/85 -> 2000 | AG12: ='Lpg (2)'!C16*1000/85 -> 1000 | AH12: ='Lpg (2)'!D16*1000/85 -> 1000 | AI12: =SUM(AF11*2000)+(AG12*1000)+(AH12*1000) -> 2847058.8 | AJ12: =SUM(AI11-AI12) -> 47058.824
A13: =Gen!B18 -> 44143 | B13: ='Summery Report'!E12 -> 1 | C13: =Gen!C18 -> 0 | D13: ='Summery Report'!E12 -> 1 | E13: =SUM(E12) -> 1.3262195 | F13: =SUM(J13*E13)/D13 -> 3104.6799 | G13: =SUM(L13*E13)/D13 -> 3104.6799 | H13: =Gen!D18 -> 42971.68 | I13: =Gen!F18 -> 0 | J13: =Gen!U18 -> 2341 | K13: =Gen!AL18 -> 0 | L13: =SUM(J13:K13) -> 2341 | M13: ='Water-Meter'!K53 -> 419.71089 | N13: ='Water-Meter'!E13 -> 63 | P13: 19032 | Q13: =SUM(P13-P12) -> 0 | R13: =SUM(Q13*O13) -> 0 | T13: 17126 | U13: =T13-T12 -> 0 | V13: =SUM(U13*S13) -> 0 | W13: 2.3 | X13: 25689 | Y13: =X13-X12 -> 24 | Z13: =SUM(Y13*W13) -> 55.2 | AA13: =SUM(Z13*X15) -> 1420627.2 | AB13: 41135 | AC13: =AB13-AB12 -> 51 | AD13: 207030 | AE13: =AD13-AD12 -> 46 | AF13: ='Lpg (2)'!B17*2000/85 -> 2000 | AG13: ='Lpg (2)'!C17*1000/85 -> 976.47059 | AH13: ='Lpg (2)'!D17*1000/85 -> 1000 | AI13: =SUM(AF12*2000)+(AG13*1000)+(AH13*1000) -> 5976470.6 | AJ13: =SUM(AI12-AI13) -> -3129411.8
A14: =Gen!B19 -> 44144 | B14: ='Summery Report'!E13 -> 2 | C14: =Gen!C19 -> 0.013 | D14: ='Summery Report'!E13 -> 2 | E14: =SUM(E13) -> 1.3262195 | F14: =SUM(J14*E14)/D14 -> 1564.939 | G14: =SUM(L14*E14)/D14 -> 1564.939 | H14: =Gen!D19 -> 41947.12 | I14: =Gen!F19 -> 0 | J14: =Gen!U19 -> 2360 | K14: =Gen!AL19 -> 0 | L14: =SUM(J14:K14) -> 2360 | M14: ='Water-Meter'!K54 -> 458.54699 | N14: ='Water-Meter'!E14 -> 46 | P14: 19032 | Q14: =SUM(P14-P13) -> 0 | R14: =SUM(Q14*O14) -> 0 | T14: 17126 | U14: =T14-T13 -> 0 | V14: =SUM(U14*S14) -> 0 | W14: 2.4 | X14: 25712 | Y14: =X14-X13 -> 23 | Z14: =SUM(Y14*W14) -> 55.2 | AA14: =SUM(Z14*X16) -> 1421952 | AB14: 41182 | AC14: =AB14-AB13 -> 47 | AD14: 207071 | AE14: =AD14-AD13 -> 41 | AF14: ='Lpg (2)'!B18*2000/85 -> 2000 | AG14: ='Lpg (2)'!C18*1000/85 -> 964.70588 | AH14: ='Lpg (2)'!D18*1000/85 -> 1000 | AI14: =SUM(AF13*2000)+(AG14*1000)+(AH14*1000) -> 5964705.9 | AJ14: =SUM(AI13-AI14) -> 11764.706
A15: =Gen!B20 -> 44145 | B15: ='Summery Report'!E14 -> 4 | C15: =Gen!C20 -> 0.039 | D15: ='Summery Report'!E14 -> 4 | E15: =SUM(E14) -> 1.3262195 | F15: =SUM(J15*E15)/D15 -> 770.20198 | G15: =SUM(L15*E15)/D15 -> 770.20198 | H15: =Gen!D20 -> 40854.97 | I15: =Gen!F20 -> 0 | J15: =Gen!U20 -> 2323 | K15: =Gen!AL20 -> 0 | L15: =SUM(J15:K15) -> 2323 | M15: ='Water-Meter'!K55 -> 514.39422 | N15: ='Water-Meter'!E15 -> 53 | P15: 19032 | Q15: =SUM(P15-P14) -> 0 | R15: =SUM(Q15*O15) -> 0 | T15: 17126 | U15: =T15-T14 -> 0 | V15: =SUM(U15*S15) -> 0 | W15: 2.2 | X15: 25736 | Y15: =X15-X14 -> 24 | Z15: =SUM(Y15*W15) -> 52.8 | AA15: =SUM(Z15*X17) -> 1361395.2 | AB15: 41231 | AC15: =AB15-AB14 -> 49 | AD15: 207115 | AE15: =AD15-AD14 -> 44 | AF15: ='Lpg (2)'!B19*2000/85 -> 2000 | AG15: ='Lpg (2)'!C19*1000/85 -> 941.17647 | AH15: ='Lpg (2)'!D19*1000/85 -> 1000 | AI15: =SUM(AF15*2000)+(AG15*1000)+(AH15*1000) -> 5941176.5 | AJ15: =SUM(AI14-AI15) -> 23529.412
A16: =Gen!B21 -> 44146 | B16: ='Summery Report'!E15 -> 6 | C16: =Gen!C21 -> 0.0649 | D16: ='Summery Report'!E15 -> 6 | E16: =SUM(E15) -> 1.3262195 | F16: =SUM(J16*E16)/D16 -> 504.62652 | G16: =SUM(L16*E16)/D16 -> 504.62652 | H16: =Gen!D21 -> 39872.98 | I16: =Gen!F21 -> 0 | J16: =Gen!U21 -> 2283 | K16: =Gen!AL21 -> 0 | L16: =SUM(J16:K16) -> 2283 | M16: ='Water-Meter'!K56 -> 580.01324 | N16: ='Water-Meter'!E16 -> 63 | P16: 19032 | Q16: =SUM(P16-P15) -> 0 | R16: =SUM(Q16*O16) -> 0 | T16: 17126 | U16: =T16-T15 -> 0 | V16: =SUM(U16*S16) -> 0 | W16: 2.2 | X16: 25760 | Y16: =X16-X15 -> 24 | Z16: =SUM(Y16*W16) -> 52.8 | AA16: =SUM(Z16*X18) -> 1362662.4 | AB16: 41277 | AC16: =AB16-AB15 -> 46 | AD16: 207159 | AE16: =AD16-AD15 -> 44 | AF16: ='Lpg (2)'!B20*2000/85 -> 2000 | AG16: ='Lpg (2)'!C20*1000/85 -> 847.05882 | AH16: ='Lpg (2)'!D20*1000/85 -> 1000 | AI16: =SUM(AF16*2000)+(AG16*1000)+(AH16*1000) -> 5847058.8 | AJ16: =SUM(AI15-AI16) -> 94117.647
A17: =Gen!B22 -> 44147 | B17: ='Summery Report'!E16 -> 5 | C17: =Gen!C22 -> 0.05 | D17: ='Summery Report'!E16 -> 5 | E17: =SUM(E16) -> 1.3262195 | F17: =SUM(J17*E17)/D17 -> 617.4878 | G17: =SUM(L17*E17)/D17 -> 617.4878 | H17: =Gen!D22 -> 38906.7 | I17: =Gen!F22 -> 0 | J17: =Gen!U22 -> 2328 | K17: =Gen!AL22 -> 0 | L17: =SUM(J17:K17) -> 2328 | M17: ='Water-Meter'!K57 -> 588.12919 | N17: ='Water-Meter'!E17 -> 48 | P17: 19032 | Q17: =SUM(P18-P16) -> 0 | R17: =SUM(Q17*O17) -> 0 | T17: 17126 | U17: =T17-T16 -> 0 | V17: =SUM(U17*S17) -> 0 | W17: 2.2 | X17: 25784 | Y17: =X17-X16 -> 24 | Z17: =SUM(Y17*W17) -> 52.8 | AA17: =SUM(Z17*X19) -> 1363929.6 | AB17: 41320 | AC17: =AB17-AB16 -> 43 | AD17: 207202 | AE17: =AD17-AD16 -> 43 | AF17: ='Lpg (2)'!B21*2000/85 -> 2000 | AG17: ='Lpg (2)'!C21*1000/85 -> 823.52941 | AH17: ='Lpg (2)'!D21*1000/85 -> 1000 | AI17: =SUM(AF17*2000)+(AG17*1000)+(AH17*1000) -> 5823529.4 | AJ17: =SUM(AI16-AI17) -> 23529.412
A18: =Gen!B23 -> 44148 | B18: ='Summery Report'!E17 -> 7 | C18: =Gen!C23 -> 0.0519 | D18: ='Summery Report'!E17 -> 7 | E18: =SUM(E17) -> 1.3262195 | F18: =SUM(J18*E18)/D18 -> 447.50436 | G18: =SUM(L18*E18)/D18 -> 447.50436 | H18: =Gen!D23 -> 37780.34 | I18: =Gen!F23 -> 0 | J18: =Gen!U23 -> 2362 | K18: =Gen!AL23 -> 0 | L18: =SUM(J18:K18) -> 2362 | M18: ='Water-Meter'!K58 -> 555.65602 | N18: ='Water-Meter'!E18 -> 62 | P18: 19032 | R18: =SUM(Q18*O18) -> 0 | T18: 17126 | U18: =T18-T17 -> 0 | V18: =SUM(U18*S18) -> 0 | W18: 2.2 | X18: 25808 | Y18: =X18-X17 -> 24 | Z18: =SUM(Y18*W18) -> 52.8 | AA18: =SUM(Z18*X20) -> 1365196.8 | AB18: 41362 | AC18: =AB18-AB17 -> 42 | AD18: 207243 | AE18: =AD18-AD17 -> 41 | AF18: ='Lpg (2)'!B22*2000/85 -> 2000 | AG18: ='Lpg (2)'!C22*1000/85 -> 717.64706 | AH18: ='Lpg (2)'!D22*1000/85 -> 1000 | AI18: =SUM(AF18*2000)+(AG18*1000)+(AH18*1000) -> 5717647.1 | AJ18: =SUM(AI17-AI18) -> 105882.35
A19: =Gen!B24 -> 44149 | B19: ='Summery Report'!E18 -> 15 | C19: =Gen!C24 -> 0.1818 | D19: ='Summery Report'!E18 -> 15 | E19: =SUM(E18) -> 1.3262195 | F19: =SUM(J19*E19)/D19 -> 210.42683 | G19: =SUM(L19*E19)/D19 -> 210.42683 | H19: =Gen!D24 -> 36687.05 | I19: =Gen!F24 -> 0 | J19: =Gen!U24 -> 2380 | K19: =Gen!AL24 -> 0 | L19: =SUM(J19:K19) -> 2380 | M19: ='Water-Meter'!K59 -> 530.42896 | N19: ='Water-Meter'!E19 -> 52 | P19: 19032 | R19: =SUM(Q19*O19) -> 0 | T19: 17126 | U19: =T19-T18 -> 0 | V19: =SUM(U19*S19) -> 0 | W19: 2.2 | X19: 25832 | Y19: =X19-X18 -> 24 | Z19: =SUM(Y19*W19) -> 52.8 | AA19: =SUM(Z19*X21) -> 1366464 | AB19: 41404 | AC19: =AB19-AB18 -> 42 | AD19: 207288 | AE19: =AD19-AD18 -> 45 | AF19: ='Lpg (2)'!B23*2000/85 -> 2000 | AG19: ='Lpg (2)'!C23*1000/85 -> 670.58824 | AH19: ='Lpg (2)'!D23*1000/85 -> 1000 | AI19: =SUM(AF19*2000)+(AG19*1000)+(AH19*1000) -> 5670588.2 | AJ19: =SUM(AI18-AI19) -> 47058.824
A20: =Gen!B25 -> 44150 | B20: ='Summery Report'!E19 -> 13 | C20: =Gen!C25 -> 0.1429 | D20: ='Summery Report'!E19 -> 13 | E20: =SUM(E19) -> 1.3262195 | F20: =SUM(J20*E20)/D20 -> 238.41346 | G20: =SUM(L20*E20)/D20 -> 238.41346 | H20: =Gen!D25 -> 35724.16 | I20: =Gen!F25 -> 0 | J20: =Gen!U25 -> 2337 | K20: =Gen!AL25 -> 0 | L20: =SUM(J20:K20) -> 2337 | M20: ='Water-Meter'!K60 -> 493.88787 | N20: ='Water-Meter'!E20 -> 78 | P20: 19032 | Q20: =SUM(P20-P19) -> 0 | R20: =SUM(Q20*O20) -> 0 | T20: 17126 | U20: =T20-T19 -> 0 | V20: =SUM(U20*S20) -> 0 | W20: 2 | X20: 25856 | Y20: =X20-X19 -> 24 | Z20: =SUM(Y20*W20) -> 48 | AA20: =SUM(Z20*X22) -> 1243392 | AB20: 41443 | AC20: =AB20-AB19 -> 39 | AD20: 207331 | AE20: =AD20-AD19 -> 43 | AF20: ='Lpg (2)'!B24*2000/85 -> 2000 | AG20: ='Lpg (2)'!C24*1000/85 -> 623.52941 | AH20: ='Lpg (2)'!D24*1000/85 -> 1000 | AI20: =SUM(AF20*2000)+(AG20*1000)+(AH20*1000) -> 5623529.4 | AJ20: =SUM(AI19-AI20) -> 47058.824
A21: =Gen!B26 -> 44151 | B21: ='Summery Report'!E20 -> 12 | C21: =Gen!C26 -> 0.1299 | D21: ='Summery Report'!E20 -> 12 | E21: =SUM(E20) -> 1.3262195 | F21: =SUM(J21*E21)/D21 -> 272.75915 | G21: =SUM(L21*E21)/D21 -> 272.75915 | H21: =Gen!D26 -> 34509.83 | I21: =Gen!F26 -> 0 | J21: =Gen!U26 -> 2468 | K21: =Gen!AL26 -> 0 | L21: =SUM(J21:K21) -> 2468 | M21: ='Water-Meter'!K61 -> 478.03633 | N21: ='Water-Meter'!E21 -> 52 | P21: 19032 | Q21: =SUM(P21-P20) -> 0 | R21: =SUM(Q21*O21) -> 0 | T21: 17126 | U21: =T22-T20 -> 0 | V21: =SUM(U21*S21) -> 0 | W21: 2 | X21: 25880 | Y21: =X21-X20 -> 24 | Z21: =SUM(Y21*W21) -> 48 | AA21: =SUM(Z21*X23) -> 1244544 | AB21: 41480 | AC21: =AB21-AB20 -> 37 | AD21: 207383 | AE21: =AD21-AD20 -> 52 | AF21: ='Lpg (2)'!B25*2000/85 -> 2000 | AG21: ='Lpg (2)'!C25*1000/85 -> 529.41176 | AH21: ='Lpg (2)'!D25*1000/85 -> 1000 | AI21: =SUM(AF21*2000)+(AG21*1000)+(AH21*1000) -> 5529411.8 | AJ21: =SUM(AI20-AI21) -> 94117.647
A22: =Gen!B27 -> 44152 | B22: ='Summery Report'!E21 -> 0 | C22: =Gen!C27 -> 0.03 | D22: ='Summery Report'!E21 -> 0 | E22: =SUM(E21) -> 1.3262195 | F22: =SUM(J22*E22)/D22 -> #DIV/0! | G22: =SUM(L22*E22)/D22 -> #DIV/0! | H22: =Gen!D27 -> 33312.67 | I22: =Gen!F27 -> 0 | J22: =Gen!U27 -> 2266 | K22: =Gen!AL27 -> 0 | L22: =SUM(J22:K22) -> 2266 | M22: ='Water-Meter'!K62 -> 415.70893 | N22: ='Water-Meter'!E22 -> 53 | P22: 19032 | Q22: =SUM(P22-P21) -> 0 | R22: =SUM(Q22*O22) -> 0 | T22: 17126 | U22: =T23-T21 -> 0 | V22: =SUM(U22*S22) -> 0 | W22: 2 | X22: 25904 | Y22: =X22-X21 -> 24 | Z22: =SUM(Y22*W22) -> 48 | AA22: =SUM(Z22*X24) -> 1245696 | AB22: 41512 | AC22: =AB22-AB21 -> 32 | AD22: 207393 | AE22: =AD22-AD21 -> 10 | AF22: ='Lpg (2)'!B26*2000/85 -> 2000 | AG22: ='Lpg (2)'!C26*1000/85 -> 494.11765 | AH22: ='Lpg (2)'!D26*1000/85 -> 1000 | AI22: =SUM(AF22*2000)+(AG22*1000)+(AH22*1000) -> 5494117.6 | AJ22: =SUM(AI21-AI22) -> 35294.118
