Workbook

Sheet TOTAL
A1: Site Name | B1: Day | C1: Month | D1: Year | E1: Total Electricity Kwh | F1: Electricity Tariff ($/Kwh) | G1: Natual Gas (m3) | H1: Natural Gas $/m3 | I1: Water Utility Supply (m3) m3 | J1: Water Utility Supply (m3) $/m3 | K1: Room Nights | L1: Food Covers
A2: Hong Kong | B2: 1 | C2: 10 | D2: 2020 | E2: =FSH!E2+FSP!E2 -> 55843 | G2: =(FSH!G2+FSP!G2)/38.3 -> 4746.9168 | I2: =FSH!I2+FSP!I2 -> 5716.521
A3: Hong Kong | B3: 2 | C3: 10 | D3: 2020 | E3: =FSH!E3+FSP!E3 -> 45790 | G3: =(FSH!G3+FSP!G3)/38.3 -> 4703.0575 | I3: =FSH!I3+FSP!I3 -> 6054.69
A4: Hong Kong | B4: 3 | C4: 10 | D4: 2020 | E4: =FSH!E4+FSP!E4 -> 47779 | G4: =(FSH!G4+FSP!G4)/38.3 -> 4921.4901 | I4: =FSH!I4+FSP!I4 -> 5865.879
A5: Hong Kong | B5: 4 | C5: 10 | D5: 2020 | E5: =FSH!E5+FSP!E5 -> 47467 | G5: =(FSH!G5+FSP!G5)/38.3 -> 5035.4883 | I5: =FSH!I5+FSP!I5 -> 6591.468
A6: Hong Kong | B6: 5 | C6: 10 | D6: 2020 | E6: =FSH!E6+FSP!E6 -> 56715 | G6: =(FSH!G6+FSP!G6)/38.3 -> 4868.8054 | I6: =FSH!I6+FSP!I6 -> 6341.439
A7: Hong Kong | B7: 6 | C7: 10 | D7: 2020 | E7: =FSH!E7+FSP!E7 -> 49049 | G7: =(FSH!G7+FSP!G7)/38.3 -> 4520.9909 | I7: =FSH!I7+FSP!I7 -> 6890.291
A8: Hong Kong | B8: 7 | C8: 10 | D8: 2020 | E8: =FSH!E8+FSP!E8 -> 43698 | G8: =(FSH!G8+FSP!G8)/38.3 -> 4579.1674 | I8: =FSH!I8+FSP!I8 -> 5374.775
A9: Hong Kong | B9: 8 | C9: 10 | D9: 2020 | E9: =FSH!E9+FSP!E9 -> 45508 | G9: =(FSH!G9+FSP!G9)/38.3 -> 4617.8306 | I9: =FSH!I9+FSP!I9 -> 5381.759
A10: Hong Kong | B10: 9 | C10: 10 | D10: 2020 | E10: =FSH!E10+FSP!E10 -> 46757 | G10: =(FSH!G10+FSP!G10)/38.3 -> 4847.3872 | I10: =FSH!I10+FSP!I10 -> 5799.523
A11: Hong Kong | B11: 10 | C11: 10 | D11: 2020 | E11: =FSH!E11+FSP!E11 -> 45961 | G11: =(FSH!G11+FSP!G11)/38.3 -> 4907.1854 | I11: =FSH!I11+FSP!I11 -> 6273.641
A12: Hong Kong | B12: 11 | C12: 10 | D12: 2020 | E12: =FSH!E12+FSP!E12 -> 45718 | G12: =(FSH!G12+FSP!G12)/38.3 -> 6259.5058 | I12: =FSH!I12+FSP!I12 -> 6734.961
A13: Hong Kong | B13: 12 | C13: 10 | D13: 2020 | E13: =FSH!E13+FSP!E13 -> 47917 | G13: =(FSH!G13+FSP!G13)/38.3 -> 3567.2961 | I13: =FSH!I13+FSP!I13 -> 6496.333
... A32: Hong Kong | B32: 31 | C32: 10 | D32: 2020 | E32: =FSH!E32+FSP!E32 -> 0 | G32: =(FSH!G32+FSP!G32)/38.3 -> 3257.6159 | I32: =FSH!I32+FSP!I32 -> 0

Sheet FSH
A1: Site Name | B1: Day | C1: Month | D1: Year | E1: Total Electricity Kwh | F1: Electricity Tariff ($/Kwh) | G1: Natural Gas (m3) | H1: Natural Gas $/m3 | I1: Water Utility Supply (m3) m3 | J1: Water Utility Supply (m3) $/m3 | K1: Room Nights | L1: Food Covers
A2: FSHK | B2: 1 | C2: 9 | D2: 2020 | E2: =Electricity!AK8 -> 44610 | G2: =Gas!BH9 -> 114942.91 | I2: =Water!R7 -> 4343.521
A3: FSHK | B3: 2 | C3: 9 | D3: 2020 | E3: =Electricity!AK9 -> 38661.5 | G3: =Gas!BH10 -> 114136.7 | I3: =Water!R8 -> 4715.19
A4: FSHK | B4: 3 | C4: 9 | D4: 2020 | E4: =Electricity!AK10 -> 39886 | G4: =Gas!BH11 -> 121859.47 | I4: =Water!R9 -> 4534.379
A5: FSHK | B5: 4 | C5: 9 | D5: 2020 | E5: =Electricity!AK11 -> 39482 | G5: =Gas!BH12 -> 124632 | I5: =Water!R10 -> 4891.968
A6: FSHK | B6: 5 | C6: 9 | D6: 2020 | E6: =Electricity!AK12 -> 44027 | G6: =Gas!BH13 -> 119640.05 | I6: =Water!R11 -> 4910.439
A7: FSHK | B7: 6 | C7: 9 | D7: 2020 | E7: =Electricity!AK13 -> 39508.5 | G7: =Gas!BH14 -> 111109.15 | I7: =Water!R12 -> 5110.291
A8: FSHK | B8: 7 | C8: 9 | D8: 2020 | E8: =Electricity!AK14 -> 36384 | G8: =Gas!BH15 -> 111388.51 | I8: =Water!R13 -> 4061.775
A9: FSHK | B9: 8 | C9: 9 | D9: 2020 | E9: =Electricity!AK15 -> 38124 | G9: =Gas!BH16 -> 112629.31 | I9: =Water!R14 -> 3919.759
A10: FSHK | B10: 9 | C10: 9 | D10: 2020 | E10: =Electricity!AK16 -> 39259 | G10: =Gas!BH17 -> 118474.13 | I10: =Water!R15 -> 4450.023
A11: FSHK | B11: 10 | C11: 9 | D11: 2020 | E11: =Electricity!AK17 -> 39159.5 | G11: =Gas!BH18 -> 122214 | I11: =Water!R16 -> 4779.641
A12: FSHK | B12: 11 | C12: 9 | D12: 2020 | E12: =Electricity!AK18 -> 38879 | G12: =Gas!BH19 -> 155076.67 | I12: =Water!R17 -> 5234.461
A13: FSHK | B13: 12 | C13: 9 | D13: 2020 | E13: =Electricity!AK19 -> 39715.5 | G13: =Gas!BH20 -> 89961.84 | I13: =Water!R18 -> 5087.833
... A30: FSHK | B30: 29 | C30: 9 | D30: 2020 | E30: =Electricity!AK36 -> 33733.5 | G30: =Gas!BH37 -> 124655.38 | I30: =Water!R35 -> 4477.903
A31: FSHK | B31: 30 | C31: 9 | D31: 2020 | E31: =Electricity!AK37 -> 33536 | G31: =Gas!BH38 -> 124026 | I31: =Water!R37 -> 15240.195
A32: FSHK | B32: 31 | C32: 9 | D32: 2020 | E32: =Electricity!AK38 -> 0 | G32: =Gas!BH39 -> 124766.69 | I32: =Water!R38 -> 0

Sheet FSP
A1: Site Name | B1: Day | C1: Month | D1: Year | E1: Total Electricity Kwh | F1: Electricity Tariff ($/Kwh) | G1: Natural Gas (m3) | H1: Natural Gas $/m3 | I1: Water Utility supply (m3) | J1: Water Utility (m3) $/m3 | K1: Rooms Nights | L1: Total Guests
A2: FSHK | B2: 1 | C2: 9 | D2: 2020 | E2: =Electricity!AL8 -> 11233 | G2: =Gas!BI9 -> 66864 | I2: =Water!S7 -> 1373
A3: FSHK | B3: 2 | C3: 9 | D3: 2020 | E3: =Electricity!AL9 -> 7128.5 | G3: =Gas!BI10 -> 65990.4 | I3: =Water!S8 -> 1339.5
A4: FSHK | B4: 3 | C4: 9 | D4: 2020 | E4: =Electricity!AL10 -> 7893 | G4: =Gas!BI11 -> 66633.6 | I4: =Water!S9 -> 1331.5
A5: FSHK | B5: 4 | C5: 9 | D5: 2020 | E5: =Electricity!AL11 -> 7985 | G5: =Gas!BI12 -> 68227.2 | I5: =Water!S10 -> 1699.5
A6: FSHK | B6: 5 | C6: 9 | D6: 2020 | E6: =Electricity!AL12 -> 12688 | G6: =Gas!BI13 -> 66835.2 | I6: =Water!S11 -> 1431
A7: FSHK | B7: 6 | C7: 9 | D7: 2020 | E7: =Electricity!AL13 -> 9540.5 | G7: =Gas!BI14 -> 62044.8 | I7: =Water!S12 -> 1780
A8: FSHK | B8: 7 | C8: 9 | D8: 2020 | E8: =Electricity!AL14 -> 7314 | G8: =Gas!BI15 -> 63993.6 | I8: =Water!S13 -> 1313
A9: FSHK | B9: 8 | C9: 9 | D9: 2020 | E9: =Electricity!AL15 -> 7384 | G9: =Gas!BI16 -> 64233.6 | I9: =Water!S14 -> 1462
A10: FSHK | B10: 9 | C10: 9 | D10: 2020 | E10: =Electricity!AL16 -> 7498 | G10: =Gas!BI17 -> 67180.8 | I10: =Water!S15 -> 1349.5
A11: FSHK | B11: 10 | C11: 9 | D11: 2020 | E11: =Electricity!AL17 -> 6801.5 | G11: =Gas!BI18 -> 65731.2 | I11: =Water!S16 -> 1494
A12: FSHK | B12: 11 | C12: 9 | D12: 2020 | E12: =Electricity!AL18 -> 6839 | G12: =Gas!BI19 -> 84662.4 | I12: =Water!S17 -> 1500.5
A13: FSHK | B13: 12 | C13: 9 | D13: 2020 | E13: =Electricity!AL19 -> 8201.5 | G13: =Gas!BI20 -> 46665.6 | I13: =Water!S18 -> 1408.5
... A30: FSHK | B30: 29 | C30: 9 | D30: 2020 | E30: =Electricity!AL36 -> 8346.5 | G30: =Gas!BI37 -> 66480 | I30: =Water!S35 -> 1325.5
A31: FSHK | B31: 30 | C31: 9 | D31: 2020 | E31: =Electricity!AL37 -> 7470 | G31: =Gas!BI38 -> 66345.6 | I31: =Water!S37 -> 2180

Sheet Electricity
C1: FSH | E1: FSH | G1: FSH | J1: FSH | L1: FSH | N1: FSH & FSP | Q1: FSH & FSP | T1: FSH & FSP | W1: FSH & FSP | Z1: FSP | AB1: FSP | AD1: FSP | AF1: FSP | AH1: FSP
C2: HOT Normal and Essential power for linen chute(9/F-45/F), HOT water pump at 8/F, Podium dimmer supply(P1-P6), MVAC system(B1/F-B2/F), Bus station BPTT supply. | E2: HOT Normal Power for Guest rooms supply (9/F-45/F), MVAC system (2/F & 46/F), P&D system(46/F) Podium MVAC system (P1/F-P6/F) | G2: P5 Pool Plant, Laundry (hotel 70%,Place 30%), 9/F - 28/F public area, 29/F 46/F Public area Podium normal power supply for water feature(G/F), Chiller WCC-01(B2/F)(FSH 50%, FSP 50%) | J2: Podium normal power for Administration office(P5/F & P6/F), P&D system supply(B2/F), Planter lighting supply(Open Space), Kitchen public supply(B1/F, P1/F, P2/F, P3/F, P4/F & P6/F), BMS room supply(B1/F), Security room supply(G/F), Computer & PABX room | L2: Podium normal power supply for Public supply(P1/F - P6/F), Kitchen(B1/F, P1/F, P2/F, P3/F, P4/F & P6/F), P&D system supply(B1/F), Refuse room supply(G/F), Gas boiler supply(B2/F) and MVAC system supply(P1/F-P6/F). | N2: Podium normal power supply for main P&D system supply(B1/F), MVAC chilled water pump(B1/F) Chiller WCC-02(B2/F) (FSH 50%, FSP 50%) | Q2: Chiller # 3 (FSH 50%, FSP 50%) | T2: Chiller # 4 (FSH 50%, FSP 50%) | W2: Chiller # 5 (FSH 50%, FSP 50%) | Z2: SHT normal power for Guest rooms supply (11/F-23/F). | AB2: SHT normal power for Guest rooms supply (25/F-57/F). | AD2: SHT Essential Power for Public Power supply, F.S. Pump (9/F, 57/F & 39/F), Podium F.S. pump(P1M), Lift LT/S1-LT/S7(LM/F), Lift LT/S8-S9(59/F) and Lift LT/S10(8/F). | AF2: SHT normal power for Guest rooms supply (25/F-57/F). | AH2: SHT normal power for MVAC System(8/F & 40/F), Public supply (8-R/F), P&D system(40/F & 60/F), swimming pool(57/F), SWB 3&4(40/F)
C3: 5065546 | E3: 5065547 | G3: 5008272 | J3: 5065548 | L3: 5465545 | N3: 5008273 | Q3: 5018351 | T3: 5018354 | W3: 5018350 | Z3: 5065543 | AB3: 5065544 | AD3: 5065541 | AF3: 5065542 | AH3: 5065540 | AK3: Daily Total consumption
C4: TXW1 | E4: TXW4 | G4: TXW2 | J4: TXC2 | L4: TXC1 | N4: TXW3 | Q4: TXN1 | T4: TXN2 | W4: TXN3 | Z4: TXN4 | AB4: TXE1 | AD4: TXE2 | AF4: TXE3 | AH4: TXE4
A5: Tariff Type | C5: MD-LV | E5: MD-LV | G5: MD-LV | J5: MD-LV | L5: MD-LV | N5: MD-LV | Q5: Non-Residential | T5: Non-Residential | W5: Non-Residential | Z5: MD-LV | AB5: MD-LV | AD5: MD-LV | AF5: MD-LV | AH5: MD-LV
A6: Date | C6: Reading Kwh | D6: Differecne Kwh | E6: Reading Kwh | F6: Differecne Kwh | G6: Reading Kwh | H6: Differecne Kwh | I6: FSH 50% / FSP 50% | J6: Reading Kwh | K6: Differecne Kwh | L6: Reading Kwh | M6: Differecne Kwh | N6: Reading Kwh | O6: Differecne Kwh | P6: FSH 50% / FSP 50% | Q6: Reading Kwh | R6: Differecne Kwh | S6: FSH 50% / FSP 50% | T6: Reading Kwh | U6: Differecne Kwh | V6: FSH 50% / FSP 50% | W6: Reading Kwh | X6: Differecne Kwh | Y6: FSH 50% / FSP 50% | Z6: Reading Kwh | AA6: Differecne Kwh | AB6: Reading Kwh | AC6: Differecne Kwh | AD6: Reading Kwh | AE6: Differecne Kwh | AF6: Reading Kwh | AG6: Differecne Kwh | AH6: Reading Kwh | AI6: Differecne Kwh | AK6: FSH | AL6: FSP
A7: 44104 | C7: 17096 | D7: =(C7-C6)*10 -> #VALUE! | E7: 25449 | F7: =(E7-E6)*10 -> #VALUE! | G7: 767558 | H7: =(G7-G6)*10 -> #VALUE! | I7: =H7*50% -> #VALUE! | J7: 23971 | K7: =(J7-J6)*10 -> #VALUE! | L7: 37356 | M7: =(L7-L6)*10 -> #VALUE! | N7: 759848 | O7: =(N7-N6)*10 -> #VALUE! | P7: =O7*50% -> #VALUE! | Q7: 103256 | R7: =(Q7-Q6)*10 -> #VALUE! | S7: =R7*50% -> #VALUE! | T7: 52845 | U7: =(T7-T6)*10 -> #VALUE! | V7: =U7*50% -> #VALUE! | W7: 118974 | X7: =W7-W6 -> #VALUE! | Y7: =X7*50% -> #VALUE! | Z7: 8419 | AA7: =Z7-Z6 -> #VALUE! | AB7: 16472 | AC7: =AB7-AB6 -> #VALUE! | AD7: 30779 | AE7: =AD7-AD6 -> #VALUE! | AF7: 16907 | AG7: =AF7-AF6 -> #VALUE! | AH7: 83469 | AI7: =AH7-AH6 -> #VALUE! | AK7: =SUM(D7,F7,I7,K7,M7,P7,S7,V7,Y7) -> #VALUE! | AL7: =SUM(P7,S7,V7,Y7,AA7,AC7,AE7,AG7,AI7) -> #VALUE!
A8: 44105 | C8: 17918 | D8: =(C8-C7)*10 -> 8220 | E8: 26059 | F8: =(E8-E7)*10 -> 6100 | G8: 768787 | H8: =(G8-G7)*10 -> 12290 | I8: =H8*50% -> 6145 | J8: 24532 | K8: =(J8-J7)*10 -> 5610 | L8: 38259 | M8: =(L8-L7)*10 -> 9030 | N8: 761297 | O8: =(N8-N7)*10 -> 14490 | P8: =O8*50% -> 7245 | Q8: 103258 | R8: =(Q8-Q7)*10 -> 20 | S8: =R8*50% -> 10 | T8: 52847 | U8: =(T8-T7)*10 -> 20 | V8: =U8*50% -> 10 | W8: 119422 | X8: =(W8-W7)*10 -> 4480 | Y8: =X8*50% -> 2240 | Z8: 8515 | AA8: =Z8-Z7 -> 96 | AB8: 16662 | AC8: =AB8-AB7 -> 190 | AD8: 31123 | AE8: =AD8-AD7 -> 344 | AF8: 17092 | AG8: =AF8-AF7 -> 185 | AH8: 84382 | AI8: =AH8-AH7 -> 913 | AK8: =SUM(D8,F8,I8,K8,M8,P8,S8,V8,Y8) -> 44610 | AL8: =SUM(P8,S8,V8,Y8,AA8,AC8,AE8,AG8,AI8) -> 11233
A9: 44106 | C9: 18355 | D9: =(C9-C8)*10 -> 4370 | E9: 26715 | F9: =(E9-E8)*10 -> 6560 | G9: 770243 | H9: =(G9-G8)*10 -> 14560 | I9: =H9*50% -> 7280 | J9: 25111 | K9: =(J9-J8)*10 -> 5790 | L9: 39197 | M9: =(L9-L8)*10 -> 9380 | N9: 762262 | O9: =(N9-N8)*10 -> 9650 | P9: =O9*50% -> 4825 | Q9: 103260 | R9: =(Q9-Q8)*10 -> 20 | S9: =R9*50% -> 10 | T9: 52849 | U9: =(T9-T8)*10 -> 20 | V9: =U9*50% -> 10 | W9: 120295 | X9: =W9-W8 -> 873 | Y9: =X9*50% -> 436.5 | Z9: 8614 | AA9: =Z9-Z8 -> 99 | AB9: 16869 | AC9: =AB9-AB8 -> 207 | AD9: 31483 | AE9: =AD9-AD8 -> 360 | AF9: 17294 | AG9: =AF9-AF8 -> 202 | AH9: 85361 | AI9: =AH9-AH8 -> 979 | AK9: =SUM(D9,F9,I9,K9,M9,P9,S9,V9,Y9) -> 38661.5 | AL9: =SUM(P9,S9,V9,Y9,AA9,AC9,AE9,AG9,AI9) -> 7128.5
A10: 44107 | C10: 18799 | D10: =(C10-C9)*10 -> 4440 | E10: 27362 | F10: =(E10-E9)*10 -> 6470 | G10: 771820 | H10: =(G10-G9)*10 -> 15770 | I10: =H10*50% -> 7885 | J10: 25694 | K10: =(J10-J9)*10 -> 5830 | L10: 40120 | M10: =(L10-L9)*10 -> 9230 | N10: 763394 | O10: =(N10-N9)*10 -> 11320 | P10: =O10*50% -> 5660 | Q10: 103262 | R10: =(Q10-Q9)*10 -> 20 | S10: =R10*50% -> 10 | T10: 52851 | U10: =(T10-T9)*10 -> 20 | V10: =U10*50% -> 10 | W10: 120997 | X10: =W10-W9 -> 702 | Y10: =X10*50% -> 351 | Z10: 8714 | AA10: =Z10-Z9 -> 100 | AB10: 17067 | AC10: =AB10-AB9 -> 198 | AD10: 31851 | AE10: =AD10-AD9 -> 368 | AF10: 17501 | AG10: =AF10-AF9 -> 207 | AH10: 86350 | AI10: =AH10-AH9 -> 989 | AK10: =SUM(D10,F10,I10,K10,M10,P10,S10,V10,Y10) -> 39886 | AL10: =SUM(P10,S10,V10,Y10,AA10,AC10,AE10,AG10,AI10) -> 7893
A11: 44108 | C11: 19228 | D11: =(C11-C10)*10 -> 4290 | E11: 27999 | F11: =(E11-E10)*10 -> 6370 | G11: 773363 | H11: =(G11-G10)*10 -> 15430 | I11: =H11*50% -> 7715 | J11: 26274 | K11: =(J11-J10)*10 -> 5800 | L11: 41034 | M11: =(L11-L10)*10 -> 9140 | N11: 764499 | O11: =(N11-N10)*10 -> 11050 | P11: =O11*50% -> 5525 | Q11: 103264 | R11: =(Q11-Q10)*10 -> 20 | S11: =R11*50% -> 10 | T11: 52881 | U11: =(T11-T10)*10 -> 300 | V11: =U11*50% -> 150 | W11: 121961 | X11: =W11-W10 -> 964 | Y11: =X11*50% -> 482 | Z11: 8815 | AA11: =Z11-Z10 -> 101 | AB11: 17262 | AC11: =AB11-AB10 -> 195 | AD11: 32212 | AE11: =AD11-AD10 -> 361 | AF11: 17696 | AG11: =AF11-AF10 -> 195 | AH11: 87316 | AI11: =AH11-AH10 -> 966 | AK11: =SUM(D11,F11,I11,K11,M11,P11,S11,V11,Y11) -> 39482 | AL11: =SUM(P11,S11,V11,Y11,AA11,AC11,AE11,AG11,AI11) -> 7985
A12: 44109 | C12: 19643 | D12: =(C12-C11)*10 -> 4150 | E12: 28659 | F12: =(E12-E11)*10 -> 6600 | G12: 774831 | H12: =(G12-G11)*10 -> 14680 | I12: =H12*50% -> 7340 | J12: 26865 | K12: =(J12-J11)*10 -> 5910 | L12: 41952 | M12: =(L12-L11)*10 -> 9180 | N12: 765998 | O12: =(N12-N11)*10 -> 14990 | P12: =O12*50% -> 7495 | Q12: 103512 | R12: =(Q12-Q11)*10 -> 2480 | S12: =R12*50% -> 1240 | T12: 53295 | U12: =(T12-T11)*10 -> 4140 | V12: =U12*50% -> 2070 | W12: 122045 | X12: =W12-W11 -> 84 | Y12: =X12*50% -> 42 | Z12: 8918 | AA12: =Z12-Z11 -> 103 | AB12: 17469 | AC12: =AB12-AB11 -> 207 | AD12: 32586 | AE12: =AD12-AD11 -> 374 | AF12: 17898 | AG12: =AF12-AF11 -> 202 | AH12: 88271 | AI12: =AH12-AH11 -> 955 | AK12: =SUM(D12,F12,I12,K12,M12,P12,S12,V12,Y12) -> 44027 | AL12: =SUM(P12,S12,V12,Y12,AA12,AC12,AE12,AG12,AI12) -> 12688
A13: 44110 | C13: 20031 | D13: =(C13-C12)*10 -> 3880 | E13: 29279 | F13: =(E13-E12)*10 -> 6200 | G13: 776266 | H13: =(G13-G12)*10 -> 14350 | I13: =H13*50% -> 7175 | J13: 27435 | K13: =(J13-J12)*10 -> 5700 | L13: 42832 | M13: =(L13-L12)*10 -> 8800 | N13: 766760 | O13: =(N13-N12)*10 -> 7620 | P13: =O13*50% -> 3810 | Q13: 104298 | R13: =(Q13-Q12)*10 -> 7860 | S13: =R13*50% -> 3930 | T13: 53297 | U13: =(T13-T12)*10 -> 20 | V13: =U13*50% -> 10 | W13: 122052 | X13: =W13-W12 -> 7 | Y13: =X13*50% -> 3.5 | Z13: 9013 | AA13: =Z13-Z12 -> 95 | AB13: 17677 | AC13: =AB13-AB12 -> 208 | AD13: 32965 | AE13: =AD13-AD12 -> 379 | AF13: 18093 | AG13: =AF13-AF12 -> 195 | AH13: 89181 | AI13: =AH13-AH12 -> 910 | AK13: =SUM(D13,F13,I13,K13,M13,P13,S13,V13,Y13) -> 39508.5 | AL13: =SUM(P13,S13,V13,Y13,AA13,AC13,AE13,AG13,AI13) -> 9540.5
A14: 44111 | C14: 20417 | D14: =(C14-C13)*10 -> 3860 | E14: 29888 | F14: =(E14-E13)*10 -> 6090 | G14: 777709 | H14: =(G14-G13)*10 -> 14430 | I14: =H14*50% -> 7215 | J14: 27907 | K14: =(J14-J13)*10 -> 4720 | L14: 43729 | M14: =(L14-L13)*10 -> 8970 | N14: 767426 | O14: =(N14-N13)*10 -> 6660 | P14: =O14*50% -> 3330 | Q14: 104735 | R14: =(Q14-Q13)*10 -> 4370 | S14: =R14*50% -> 2185 | T14: 53299 | U14: =(T14-T13)*10 -> 20 | V14: =U14*50% -> 10 | W14: 122060 | X14: =W14-W13 -> 8 | Y14: =X14*50% -> 4 | Z14: 9108 | AA14: =Z14-Z13 -> 95 | AB14: 17882 | AC14: =AB14-AB13 -> 205 | AD14: 33333 | AE14: =AD14-AD13 -> 368 | AF14: 18289 | AG14: =AF14-AF13 -> 196 | AH14: 90102 | AI14: =AH14-AH13 -> 921 | AK14: =SUM(D14,F14,I14,K14,M14,P14,S14,V14,Y14) -> 36384 | AL14: =SUM(P14,S14,V14,Y14,AA14,AC14,AE14,AG14,AI14) -> 7314
A15: 44112 | C15: 20802 | D15: =(C15-C14)*10 -> 3850 | E15: 30505 | F15: =(E15-E14)*10 -> 6170 | G15: 779080 | H15: =(G15-G14)*10 -> 13710 | I15: =H15*50% -> 6855 | J15: 28557 | K15: =(J15-J14)*10 -> 6500 | L15: 44646 | M15: =(L15-L14)*10 -> 9170 | N15: 767899 | O15: =(N15-N14)*10 -> 4730 | P15: =O15*50% -> 2365 | Q15: 105374 | R15: =(Q15-Q14)*10 -> 6390 | S15: =R15*50% -> 3195 | T15: 53302 | U15: =(T15-T14)*10 -> 30 | V15: =U15*50% -> 15 | W15: 122068 | X15: =W15-W14 -> 8 | Y15: =X15*50% -> 4 | Z15: 9208 | AA15: =Z15-Z14 -> 100 | AB15: 18088 | AC15: =AB15-AB14 -> 206 | AD15: 33704 | AE15: =AD15-AD14 -> 371 | AF15: 18491 | AG15: =AF15-AF14 -> 202 | AH15: 91028 | AI15: =AH15-AH14 -> 926 | AK15: =SUM(D15,F15,I15,K15,M15,P15,S15,V15,Y15) -> 38124 | AL15: =SUM(P15,S15,V15,Y15,AA15,AC15,AE15,AG15,AI15) -> 7384
A16: 44113 | C16: 21220 | D16: =(C16-C15)*10 -> 4180 | E16: 31195 | F16: =(E16-E15)*10 -> 6900 | G16: 780530 | H16: =(G16-G15)*10 -> 14500 | I16: =H16*50% -> 7250 | J16: 29153 | K16: =(J16-J15)*10 -> 5960 | L16: 45575 | M16: =(L16-L15)*10 -> 9290 | N16: 768380 | O16: =(N16-N15)*10 -> 4810 | P16: =O16*50% -> 2405 | Q16: 106026 | R16: =(Q16-Q15)*10 -> 6520 | S16: =R16*50% -> 3260 | T16: 53304 | U16: =(T16-T15)*10 -> 20 | V16: =U16*50% -> 10 | W16: 122076 | X16: =W16-W15 -> 8 | Y16: =X16*50% -> 4 | Z16: 9311 | AA16: =Z16-Z15 -> 103 | AB16: 18295 | AC16: =AB16-AB15 -> 207 | AD16: 34080 | AE16: =AD16-AD15 -> 376 | AF16: 18698 | AG16: =AF16-AF15 -> 207 | AH16: 91954 | AI16: =AH16-AH15 -> 926 | AK16: =SUM(D16,F16,I16,K16,M16,P16,S16,V16,Y16) -> 39259 | AL16: =SUM(P16,S16,V16,Y16,AA16,AC16,AE16,AG16,AI16) -> 7498
A17: 44114 | C17: 21633 | D17: =(C17-C16)*10 -> 4130 | E17: 31873 | F17: =(E17-E16)*10 -> 6780 | G17: 781969 | H17: =(G17-G16)*10 -> 14390 | I17: =H17*50% -> 7195 | J17: 29788 | K17: =(J17-J16)*10 -> 6350 | L17: 46546 | M17: =(L17-L16)*10 -> 9710 | N17: 768863 | O17: =(N17-N16)*10 -> 4830 | P17: =O17*50% -> 2415 | Q17: 106498 | R17: =(Q17-Q16)*10 -> 4720 | S17: =R17*50% -> 2360 | T17: 53306 | U17: =(T17-T16)*10 -> 20 | V17: =U17*50% -> 10 | W17: 122495 | X17: =W17-W16 -> 419 | Y17: =X17*50% -> 209.5 | Z17: 9418 | AA17: =Z17-Z16 -> 107 | AB17: 18500 | AC17: =AB17-AB16 -> 205 | AD17: 34451 | AE17: =AD17-AD16 -> 371 | AF17: 18901 | AG17: =AF17-AF16 -> 203 | AH17: 92875 | AI17: =AH17-AH16 -> 921 | AK17: =SUM(D17,F17,I17,K17,M17,P17,S17,V17,Y17) -> 39159.5 | AL17: =SUM(P17,S17,V17,Y17,AA17,AC17,AE17,AG17,AI17) -> 6801.5
A18: 44115 | C18: 22035 | D18: =(C18-C17)*10 -> 4020 | E18: 32555 | F18: =(E18-E17)*10 -> 6820 | G18: 783526 | H18: =(G18-G17)*10 -> 15570 | I18: =H18*50% -> 7785 | J18: 30381 | K18: =(J18-J17)*10 -> 5930 | L18: 47479 | M18: =(L18-L17)*10 -> 9330 | N18: 769355 | O18: =(N18-N17)*10 -> 4920 | P18: =O18*50% -> 2460 | Q18: 106953 | R18: =(Q18-Q17)*10 -> 4550 | S18: =R18*50% -> 2275 | T18: 53308 | U18: =(T18-T17)*10 -> 20 | V18: =U18*50% -> 10 | W18: 122993 | X18: =W18-W17 -> 498 | Y18: =X18*50% -> 249 | Z18: 9512 | AA18: =Z18-Z17 -> 94 | AB18: 18705 | AC18: =AB18-AB17 -> 205 | AD18: 34825 | AE18: =AD18-AD17 -> 374 | AF18: 19107 | AG18: =AF18-AF17 -> 206 | AH18: 93841 | AI18: =AH18-AH17 -> 966 | AK18: =SUM(D18,F18,I18,K18,M18,P18,S18,V18,Y18) -> 38879 | AL18: =SUM(P18,S18,V18,Y18,AA18,AC18,AE18,AG18,AI18) -> 6839
A19: 44116 | C19: 22428 | D19: =(C19-C18)*10 -> 3930 | E19: 33220 | F19: =(E19-E18)*10 -> 6650 | G19: 785014 | H19: =(G19-G18)*10 -> 14880 | I19: =H19*50% -> 7440 | J19: 30977 | K19: =(J19-J18)*10 -> 5960 | L19: 48413 | M19: =(L19-L18)*10 -> 9340 | N19: 769833 | O19: =(N19-N18)*10 -> 4780 | P19: =O19*50% -> 2390 | Q19: 107695 | R19: =(Q19-Q18)*10 -> 7420 | S19: =R19*50% -> 3710 | T19: 53310 | U19: =(T19-T18)*10 -> 20 | V19: =U19*50% -> 10 | W19: 123564 | X19: =W19-W18 -> 571 | Y19: =X19*50% -> 285.5 | Z19: 9604 | AA19: =Z19-Z18 -> 92 | AB19: 18907 | AC19: =AB19-AB18 -> 202 | AD19: 35196 | AE19: =AD19-AD18 -> 371 | AF19: 19306 | AG19: =AF19-AF18 -> 199 | AH19: 94783 | AI19: =AH19-AH18 -> 942 | AK19: =SUM(D19,F19,I19,K19,M19,P19,S19,V19,Y19) -> 39715.5 | AL19: =SUM(P19,S19,V19,Y19,AA19,AC19,AE19,AG19,AI19) -> 8201.5
A20: 44117 | C20: 22805 | D20: =(C20-C19)*10 -> 3770 | E20: 33851 | F20: =(E20-E19)*10 -> 6310 | G20: 786458 | H20: =(G20-G19)*10 -> 14440 | I20: =H20*50% -> 7220 | J20: 31522 | K20: =(J20-J19)*10 -> 5450 | L20: 49298 | M20: =(L20-L19)*10 -> 8850 | N20: 770296 | O20: =(N20-N19)*10 -> 4630 | P20: =O20*50% -> 2315 | Q20: 108077 | R20: =(Q20-Q19)*10 -> 3820 | S20: =R20*50% -> 1910 | T20: 53709 | U20: =(T20-T19)*10 -> 3990 | V20: =U20*50% -> 1995 | W20: 123745 | X20: =W20-W19 -> 181 | Y20: =X20*50% -> 90.5 | Z20: 9701 | AA20: =Z20-Z19 -> 97 | AB20: 19120 | AC20: =AB20-AB19 -> 213 | AD20: 35560 | AE20: =AD20-AD19 -> 364 | AF20: 19522 | AG20: =AF20-AF19 -> 216 | AH20: 95709 | AI20: =AH20-AH19 -> 926 | AK20: =SUM(D20,F20,I20,K20,M20,P20,S20,V20,Y20) -> 37910.5 | AL20: =SUM(P20,S20,V20,Y20,AA20,AC20,AE20,AG20,AI20) -> 8126.5
... A37: 44134 | C37: 29416 | D37: =(C37-C36)*10 -> 3830 | E37: 44823 | F37: =(E37-E36)*10 -> 6510 | G37: 794040 | H37: =(G37-G36)*10 -> 3480 | I37: =H37*50% -> 1740 | J37: 41574 | K37: =(J37-J36)*10 -> 6240 | L37: 65056 | M37: =(L37-L36)*10 -> 9580 | N37: 777800 | O37: =(N37-N36)*10 -> 4140 | P37: =O37*50% -> 2070 | Q37: 117360 | R37: =(Q37-Q36)*10 -> 6200 | S37: =R37*50% -> 3100 | T37: 64309 | U37: =(T37-T36)*10 -> 20 | V37: =U37*50% -> 10 | W37: 127258 | X37: =W37-W36 -> 912 | Y37: =X37*50% -> 456 | Z37: 11379 | AA37: =Z37-Z36 -> 109 | AB37: 22660 | AC37: =AB37-AB36 -> 212 | AD37: 41854 | AE37: =AD37-AD36 -> 376 | AF37: 23077 | AG37: =AF37-AF36 -> 214 | AH37: 111484 | AI37: =AH37-AH36 -> 923 | AK37: =SUM(D37,F37,I37,K37,M37,P37,S37,V37,Y37) -> 33536 | AL37: =SUM(P37,S37,V37,Y37,AA37,AC37,AE37,AG37,AI37) -> 7470
A38: 44135 | C38: 29805 | E38: 45475 | G38: 794369 | J38: 42175 | L38: 65994 | N38: 778213 | Q38: 117549 | T38: 64311 | W38: 128275 | Z38: 11481 | AB38: 22861 | AD38: 42225 | AF38: 23284 | AH38: 112404 | AK38: =SUM(D38,F38,I38,K38,M38,P38,S38,V38,Y38) -> 0 | AL38: =SUM(P38,S38,V38,Y38,AA38,AC38,AE38,AG38,AI38) -> 0
C39: 17521 | D39: =SUM(D8:D37) -> 123200 | F39: =SUM(F8:F37) -> 193740 | H39: =SUM(H8:H37) -> 264820 | K39: =SUM(K8:K37) -> 176030 | M39: =SUM(M8:M37) -> 277000 | O39: =SUM(O8:O37) -> 179520 | R39: =SUM(R8:R37) -> 141040 | U39: =SUM(U8:U37) -> 114640 | X39: =SUM(X8:X37) -> 12316 | AA39: =SUM(AA8:AA37) -> 2960 | AC39: =SUM(AC8:AC37) -> 6188 | AE39: =SUM(AE8:AE37) -> 11075 | AG39: =SUM(AG8:AG37) -> 6170 | AI39: =SUM(AI8:AI37) -> 28015

Sheet Water
C1: FSH | E1: FSH | G1: FSH | I1: FSH | K1: FSH & FSP | O1: FSP
C2: Hotel & podium Fresh Water | E2: Food & Beverage Outlets | G2: Fountains | I2: Swimming Pool | K2: Laundry (FSH 55% : FSP 45%) | O2: Place - Guest Floor Fresh Water
C3: M16601852 | E3: M118410300 | G3: M16449102 | I3: M9192527 | K3: M16601455 | O3: M16601818 | R3: Daily Total consumption
A4: Tariff Type
A5: Date | C5: Reading | D5: Differecne m3 | E5: Reading | F5: Differecne m3 | G5: Reading | H5: Differecne m3 | I5: Reading | J5: Differecne m3 | K5: Reading | L5: Differecne m3 | M5: FSH | N5: FSP | O5: Reading | P5: Differecne m3
A6: 44104 | C6: 175505 | D6: =(C6-C5)*10 -> #VALUE! | E6: 155621 | F6: =(E6-E5)*10 -> #VALUE! | G6: 5362.6358 | H6: =(G6-G5)*10 -> #VALUE! | I6: 10452 | J6: =(I6-I5)*10 -> #VALUE! | K6: 118742 | L6: =(K6-K5)*10 -> #VALUE! | M6: =L6*55% -> #VALUE! | N6: =L6*45% -> #VALUE! | O6: 87295 | P6: =(O6-O5)*10 -> #VALUE! | R6: =SUM(D6,F6,M70,H6) -> #VALUE! | S6: =SUM(N6,P6) -> #VALUE!
A7: 44105 | C7: 175677 | D7: =(C7-C6)*10 -> 1720 | E7: 155882 | F7: =(E7-E6)*10 -> 2610 | G7: 5363.9879 | H7: =(G7-G6)*10 -> 13.521 | I7: 10464 | J7: =(I7-I6)*10 -> 120 | K7: 118876 | L7: =(K7-K6)*10 -> 1340 | M7: =L7*55% -> 737 | N7: =L7*45% -> 603 | O7: 87372 | P7: =(O7-O6)*10 -> 770 | R7: =SUM(D7,F7,M71,H7) -> 4343.521 | S7: =SUM(N7,P7) -> 1373
A8: 44106 | C8: 175861 | D8: =(C8-C7)*10 -> 1840 | E8: 156167 | F8: =(E8-E7)*10 -> 2850 | G8: 5366.5069 | H8: =(G8-G7)*10 -> 25.19 | I8: 10479 | J8: =(I8-I7)*10 -> 150 | K8: 119007 | L8: =(K8-K7)*10 -> 1310 | M8: =L8*55% -> 720.5 | N8: =L8*45% -> 589.5 | O8: 87447 | P8: =(O8-O7)*10 -> 750 | R8: =SUM(D8,F8,M72,H8) -> 4715.19 | S8: =SUM(N8,P8) -> 1339.5
A9: 44107 | C9: 176050 | D9: =(C9-C8)*10 -> 1890 | E9: 156430 | F9: =(E9-E8)*10 -> 2630 | G9: 5367.9448 | H9: =(G9-G8)*10 -> 14.379 | I9: 10488 | J9: =(I9-I8)*10 -> 90 | K9: 119114 | L9: =(K9-K8)*10 -> 1070 | M9: =L9*55% -> 588.5 | N9: =L9*45% -> 481.5 | O9: 87532 | P9: =(O9-O8)*10 -> 850 | R9: =SUM(D9,F9,M73,H9) -> 4534.379 | S9: =SUM(N9,P9) -> 1331.5
A10: 44108 | C10: 176240 | D10: =(C10-C9)*10 -> 1900 | E10: 156726 | F10: =(E10-E9)*10 -> 2960 | G10: 5371.1416 | H10: =(G10-G9)*10 -> 31.968 | I10: 10509 | J10: =(I10-I9)*10 -> 210 | K10: 119305 | L10: =(K10-K9)*10 -> 1910 | M10: =L10*55% -> 1050.5 | N10: =L10*45% -> 859.5 | O10: 87616 | P10: =(O10-O9)*10 -> 840 | R10: =SUM(D10,F10,M74,H10) -> 4891.968 | S10: =SUM(N10,P10) -> 1699.5
A11: 44109 | C11: 176437 | D11: =(C11-C10)*10 -> 1970 | E11: 157018 | F11: =(E11-E10)*10 -> 2920 | G11: 5373.1855 | H11: =(G11-G10)*10 -> 20.439 | I11: 10523 | J11: =(I11-I10)*10 -> 140 | K11: 119463 | L11: =(K11-K10)*10 -> 1580 | M11: =L11*55% -> 869 | N11: =L11*45% -> 711 | O11: 87688 | P11: =(O11-O10)*10 -> 720 | R11: =SUM(D11,F11,M75,H11) -> 4910.439 | S11: =SUM(N11,P11) -> 1431
A12: 44110 | C12: 176617 | D12: =(C12-C11)*10 -> 1800 | E12: 157348 | F12: =(E12-E11)*10 -> 3300 | G12: 5374.2146 | H12: =(G12-G11)*10 -> 10.291 | I12: 10530 | J12: =(I12-I11)*10 -> 70 | K12: 119583 | L12: =(K12-K11)*10 -> 1200 | M12: =L12*55% -> 660 | N12: =L12*45% -> 540 | O12: 87812 | P12: =(O12-O11)*10 -> 1240 | R12: =SUM(D12,F12,M76,H12) -> 5110.291 | S12: =SUM(N12,P12) -> 1780
A13: 44111 | C13: 176754 | D13: =(C13-C12)*10 -> 1370 | E13: 157615 | F13: =(E13-E12)*10 -> 2670 | G13: 5376.3921 | H13: =(G13-G12)*10 -> 21.775 | I13: 10543 | J13: =(I13-I12)*10 -> 130 | K13: 119697 | L13: =(K13-K12)*10 -> 1140 | M13: =L13*55% -> 627 | N13: =L13*45% -> 513 | O13: 87892 | P13: =(O13-O12)*10 -> 800 | R13: =SUM(D13,F13,M77,H13) -> 4061.775 | S13: =SUM(N13,P13) -> 1313
A14: 44112 | C14: 176897 | D14: =(C14-C13)*10 -> 1430 | E14: 157861 | F14: =(E14-E13)*10 -> 2460 | G14: 5379.368 | H14: =(G14-G13)*10 -> 29.759 | I14: 10557 | J14: =(I14-I13)*10 -> 140 | K14: 119813 | L14: =(K14-K13)*10 -> 1160 | M14: =L14*55% -> 638 | N14: =L14*45% -> 522 | O14: 87986 | P14: =(O14-O13)*10 -> 940 | R14: =SUM(D14,F14,M78,H14) -> 3919.759 | S14: =SUM(N14,P14) -> 1462
A15: 44113 | C15: 177052 | D15: =(C15-C14)*10 -> 1550 | E15: 158148 | F15: =(E15-E14)*10 -> 2870 | G15: 5382.3703 | H15: =(G15-G14)*10 -> 30.023 | I15: 10576 | J15: =(I15-I14)*10 -> 190 | K15: 119944 | L15: =(K15-K14)*10 -> 1310 | M15: =L15*55% -> 720.5 | N15: =L15*45% -> 589.5 | O15: 88062 | P15: =(O15-O14)*10 -> 760 | R15: =SUM(D15,F15,M79,H15) -> 4450.023 | S15: =SUM(N15,P15) -> 1349.5
A16: 44114 | C16: 177231 | D16: =(C16-C15)*10 -> 1790 | E16: 158442 | F16: =(E16-E15)*10 -> 2940 | G16: 5387.3344 | H16: =(G16-G15)*10 -> 49.641 | I16: 10596 | J16: =(I16-I15)*10 -> 200 | K16: 120076 | L16: =(K16-K15)*10 -> 1320 | M16: =L16*55% -> 726 | N16: =L16*45% -> 594 | O16: 88152 | P16: =(O16-O15)*10 -> 900 | R16: =SUM(D16,F16,M80,H16) -> 4779.641 | S16: =SUM(N16,P16) -> 1494
A17: 44115 | C17: 177429 | D17: =(C17-C16)*10 -> 1980 | E17: 158765 | F17: =(E17-E16)*10 -> 3230 | G17: 5389.7805 | H17: =(G17-G16)*10 -> 24.461 | I17: 10627 | J17: =(I17-I16)*10 -> 310 | K17: 120225 | L17: =(K17-K16)*10 -> 1490 | M17: =L17*55% -> 819.5 | N17: =L17*45% -> 670.5 | O17: 88235 | P17: =(O17-O16)*10 -> 830 | R17: =SUM(D17,F17,M81,H17) -> 5234.461 | S17: =SUM(N17,P17) -> 1500.5
... A36: 44134 | C36: 180711 | D36: =(C36-C35)*10 -> 1700 | E36: 163906 | F36: =(E36-E35)*10 -> 2930 | G36: 5467.0709 | H36: =(G36-G35)*10 -> 19.037 | I36: 11005 | J36: =(I36-I35)*10 -> 170 | K36: 122723 | L36: =(K36-K35)*10 -> 1350 | M36: =L36*55% -> 742.5 | N36: =L36*45% -> 607.5 | O36: 89834 | P36: =(O36-O35)*10 -> 900 | R36: =SUM(D36,F36,M100,H36) -> 4649.037 | S36: =SUM(N36,P36) -> 1507.5
A37: 44135 | C37: 180882 | D37: =(C37-C35)*10 -> 3410 | E37: 164790 | F37: =(E37-E35)*10 -> 11770 | G37: 5471.1867 | H37: =(G37-G35)*10 -> 60.195 | I37: 11022 | J37: =(I37-I35)*10 -> 340 | K37: 122848 | L37: =(K37-K35)*10 -> 2600 | M37: =L37*55% -> 1430 | N37: =L37*45% -> 1170 | O37: 89935 | P37: =(O37-O36)*10 -> 1010 | R37: =SUM(D37,F37,M100,H37) -> 15240.195 | S37: =SUM(N37,P37) -> 2180
D38: =SUM(D7:D37) -> 55470 | F38: =SUM(F7:F37) -> 94620 | H38: =SUM(H7:H37) -> 1104.546 | J38: =SUM(J7:J37) -> 5870 | L38: =SUM(L7:L37) -> 42410 | P38: =SUM(P7:P37) -> 26400

Sheet Gas
C1: FSH & FSP | G1: FSH | I1: FSH | K1: FSH | M1: FSH | O1: FSH | Q1: FSH | S1: FSH | U1: FSH | W1: FSH | Y1: FSH | AA1: FSH | AC1: FSH | AE1: FSH | AG1: FSH | AI1: FSH | AK1: FSH | AM1: FSP | AO1: FSP | AQ1: FSP | AS1: FSP | AU1: FSP | AW1: FSP | AY1: FSP | BA1: FSP | BC1: FSP | BE1: FSP
C2: B2/F Steam Boiler Room | G2: B1/F Main Kitchen | I2: P1/F Lobby Lounge | K2: P2/F Grand Ball Room | M2: P3 Steward | O2: P4/F Chinese Restaurant | Q2: P4/F Junior Ball Room | S2: P5/F Staff Dining | U2: P6/F Pool side bar pantry | W2: P6/F French Restaurant | Y2: P5/F Condensing Boiler Room | AA2: P5/F Filtration Plan Room | AC2: L8/F Plant Room | AE2: L46/F Plant Room | AG2: L46/F Plant Room | AI2: L46/F Plant Room | AK2: L46/F Plant Room | AM2: SHT 8/F Plant Room | AO2: SHT 40/F Plant Room | AQ2: SHT 57/F Condensing Boiler Room | AS2: SHT 57/F Condensing Boiler Room | AU2: SHT 60/F - Room 6023 ( Penhouse 1 ) | AW2: SHT 60/F - Room 6038 ( Penhouse 2 ) | AY2: L40/F Plant Room | BA2: L40/F Plant Room | BC2: L57/F Plant Room | BE2: L57/F Plant Room
C3: Steam Boiler for Hot Water & Laundry ( FSH 60% : FSP 40%) | E3: FSH | F3: FSP | G3: Kitchen | I3: Kitchen | K3: Kitchen | M3: Dish Washing area | O3: Kitchen | Q3: Kitchen | S3: Kitchen | U3: Kitchen | W3: Kitchen | Y3: Condensing Boiler for P6 Swimming Pool & Jacuzzi | AA3: 6/F Patio Spaces heater | AC3: Dehumidifier for Guest Rooms RH Control | AE3: Dehumidifier for Guest Rooms RH Control | AG3: Presidential Room Room 4305 | AI3: New Gas Heat Pump | AK3: New Gas Heat Pump ( Heater ) | AM3: Dehumidifier For Guest Rooms RH Control | AO3: Dehumidifier For Guest Rooms RH Control | AQ3: Condensing Boiler for 59/F Swimming Pool & Jacuzzis | AS3: 59/F Patio Spaces heater | AU3: Gas appliances ( Include Patio Space Heater ) | AW3: Gas appliances ( Include Patio Space Heater ) | AY3: New Gas Heat Pump | BA3: New Gas Heat Pump ( Heater ) | BC3: New Gas Heat Pump | BE3: New Gas Heat Pump ( Heater )
C4: 0234229050 | E4: Ratio | G4: 0234229130 | I4: 0234230090 | K4: 0234229210 | M4: 7092801222 | O4: 0234229460 | Q4: 0234229380 | S4: 0234229540 | U4: 0234229620 | W4: 0234230740 | Y4: 0234229870 | AA4: 0234229790 | AC4: 0234228820 | AE4: 0234228990 | AG4: 0234230820 | AI4: 7105826734 | AK4: 7105825932 | AM4: 0234230170 | AO4: 0234230250 | AQ4: 0234230330 | AS4: 0234230410 | AU4: 0234230580 | AW4: 0234230660 | AY4: 7111912486 | BA4: 7111911842 | BC4: 7111913281 | BE4: 7111912723 | BH4: Daily Total consumption
A5: Gas Meter | C5: 9955475 | E5: 0.6 | F5: 0.4 | G5: 436641 | I5: 436656 | K5: 431271 | M5: 1038664 | O5: 522469 | Q5: 431269 | S5: 436624 | U5: 5399693 | W5: 522607 | Y5: 436606 | AA5: 432481 | AC5: 410677 | AE5: 431229 | AG5: 522557 | AI5: 0333732 | AK5: 0655375 | AM5: 431241 | AO5: 410724 | AQ5: 9313879 | AS5: 4500420S | AU5: 436758 | AW5: 431227 | AY5: 744483 | BA5: 119314 | BC5: 1053229 | BE5: 1053215
A6: Tariff Type
A7: Date | C7: Reading | D7: Differecne MJ | E7: Differecne MJ | F7: Differecne MJ | G7: Reading | H7: Differecne MJ | I7: Reading | J7: Differecne MJ | K7: Reading | L7: Differecne MJ | M7: Reading | N7: Differecne MJ | O7: Reading | P7: Differecne MJ | Q7: Reading | R7: Differecne MJ | S7: Reading | T7: Differecne MJ | U7: Reading | V7: Differecne MJ | W7: Reading | X7: Differecne MJ | Y7: Reading | Z7: Differecne MJ | AA7: Reading | AB7: Differecne MJ | AC7: Reading | AD7: Differecne MJ | AE7: Reading | AF7: Differecne MJ | AG7: Reading | AH7: Differecne MJ | AI7: Reading | AJ7: Differecne MJ | AK7: Reading | AL7: Differecne MJ | AM7: Reading | AN7: Differecne MJ | AO7: Reading | AP7: Differecne MJ | AQ7: Reading | AR7: Differecne MJ | AS7: Reading | AT7: Differecne MJ | AU7: Reading | AV7: Differecne MJ | AW7: Reading | AX7: Differecne MJ | AY7: Reading | AZ7: Differecne MJ | BA7: Reading | BB7: Differecne MJ | BC7: Reading | BD7: Differecne MJ | BE7: Reading | BF7: Differecne MJ | BH7: FSH | BI7: FSP
A8: 44104 | C8: 5502501 | D8: =(+C8-+C7)*48 -> #VALUE! | E8: =D8*0.6 -> #VALUE! | F8: =D8*0.4 -> #VALUE! | G8: 274910 | H8: =(+G8-+G7)*48 -> #VALUE! | I8: 85161 | J8: =(+I8-+I7)*48 -> #VALUE! | K8: 254425 | L8: =(+K8-+K7)*48 -> #VALUE! | M8: 24364 | N8: =(+M8-+M7)*48 -> #VALUE! | O8: 220565 | P8: =(+O8-+O7)*48 -> #VALUE! | Q8: 433126 | R8: =(+Q8-+Q7)*48 -> #VALUE! | S8: 694700 | T8: =(+S8-+S7)*48 -> #VALUE! | U8: 94741.069 | V8: =(+U8-+U7)*48 -> #VALUE! | W8: 77548 | X8: =(+W8-+W7)*48 -> #VALUE! | Y8: 1475798 | Z8: =(+Y8-+Y7)*48 -> #VALUE! | AA8: 13166 | AB8: =(+AA8-+AA7)*48 -> #VALUE! | AC8: 431416 | AD8: =(+AC8-+AC7)*48 -> #VALUE! | AE8: 508790 | AF8: =(+AE8-+AE7)*48 -> #VALUE! | AG8: 48738 | AH8: =(+AG8-+AG7)*48 -> #VALUE! | AI8: 390999 | AJ8: =(+AI8-+AI7)*48 -> #VALUE! | AK8: 102371 | AL8: =(+AK8-+AK7)*48 -> #VALUE! | AM8: 555238 | AN8: =(+AM8-+AM7)*48 -> #VALUE! | AO8: 891689 | AP8: =(+AO8-+AO7)*48 -> #VALUE! | AQ8: 66513 | AR8: =(+AQ8-+AQ7)*48 -> #VALUE! | AS8: 2204 | AT8: =(+AS8-+AS7)*48 -> #VALUE! | AU8: 918 | AV8: =(+AU8-+AU7)*48 -> #VALUE! | AW8: 3108 | AX8: =(+AW8-+AW7)*48 -> #VALUE! | AY8: 298784 | AZ8: =(+AY8-+AY7)*48 -> #VALUE! | BA8: 160167 | BB8: =(+BA8-+BA7)*48 -> #VALUE! | BC8: 204698 | BD8: =(+BC8-+BC7)*48 -> #VALUE! | BE8: 5347 | BF8: =(+BE8-+BE7)*48 -> #VALUE! | BH8: =SUM(E8,J8,P8,H8,L8,R8,T8,V8,X8,N8,AB8,Z8,AD8,AF8,AH8,AL8,AJ8) -> #VALUE! | BI8: =SUM(F8,AN8,AP8,AT8,AV8,AX8,AR8,AZ8,BB8,BD8,BF8) -> #VALUE!
A9: 44105 | C9: 5504676 | D9: =(+C9-+C8)*48 -> 104400 | E9: =D9*0.6 -> 62640 | F9: =D9*0.4 -> 41760 | G9: 274943 | H9: =(+G9-+G8)*48 -> 1584 | I9: 85335 | J9: =(+I9-+I8)*48 -> 8352 | K9: 254428 | L9: =(+K9-+K8)*48 -> 144 | M9: 24364 | N9: =(+M9-+M8)*48 -> 0 | O9: 220762 | P9: =(+O9-+O8)*48 -> 9456 | Q9: 433200 | R9: =(+Q9-+Q8)*48 -> 3552 | S9: 694835 | T9: =(+S9-+S8)*48 -> 6480 | U9: 94759.713 | V9: =(+U9-+U8)*48 -> 894.912 | W9: 77563 | X9: =(+W9-+W8)*48 -> 720 | Y9: 1475964 | Z9: =(+Y9-+Y8)*48 -> 7968 | AA9: 13166 | AB9: =(+AA9-+AA8)*48 -> 0 | AC9: 431508 | AD9: =(+AC9-+AC8)*48 -> 4416 | AE9: 508891 | AF9: =(+AE9-+AE8)*48 -> 4848 | AG9: 48742 | AH9: =(+AG9-+AG8)*48 -> 192 | AI9: 391076 | AJ9: =(+AI9-+AI8)*48 -> 3696 | AK9: 102371 | AL9: =(+AK9-+AK8)*48 -> 0 | AM9: 555362 | AN9: =(+AM9-+AM8)*48 -> 5952 | AO9: 891897 | AP9: =(+AO9-+AO8)*48 -> 9984 | AQ9: 66575 | AR9: =(+AQ9-+AQ8)*48 -> 2976 | AS9: 2204 | AT9: =(+AS9-+AS8)*48 -> 0 | AU9: 918 | AV9: =(+AU9-+AU8)*48 -> 0 | AW9: 3108 | AX9: =(+AW9-+AW8)*48 -> 0 | AY9: 298861 | AZ9: =(+AY9-+AY8)*48 -> 3696 | BA9: 160167 | BB9: =(+BA9-+BA8)*48 -> 0 | BC9: 204750 | BD9: =(+BC9-+BC8)*48 -> 2496 | BE9: 5347 | BF9: =(+BE9-+BE8)*48 -> 0 | BH9: =SUM(E9,J9,P9,H9,L9,R9,T9,V9,X9,N9,AB9,Z9,AD9,AF9,AH9,AL9,AJ9) -> 114942.91 | BI9: =SUM(F9,AN9,AP9,AT9,AV9,AX9,AR9,AZ9,BB9,BD9,BF9) -> 66864
A10: 44106 | C10: 5506663 | D10: =(+C10-+C9)*48 -> 95376 | E10: =D10*0.6 -> 57225.6 | F10: =D10*0.4 -> 38150.4 | G10: 274977 | H10: =(+G10-+G9)*48 -> 1632 | I10: 85499 | J10: =(+I10-+I9)*48 -> 7872 | K10: 254433 | L10: =(+K10-+K9)*48 -> 240 | M10: 24364 | N10: =(+M10-+M9)*48 -> 0 | O10: 220951 | P10: =(+O10-+O9)*48 -> 9072 | Q10: 433289 | R10: =(+Q10-+Q9)*48 -> 4272 | S10: 694972 | T10: =(+S10-+S9)*48 -> 6576 | U10: 94785.361 | V10: =(+U10-+U9)*48 -> 1231.104 | W10: 77576 | X10: =(+W10-+W9)*48 -> 624 | Y10: 1476218 | Z10: =(+Y10-+Y9)*48 -> 12192 | AA10: 13166 | AB10: =(+AA10-+AA9)*48 -> 0 | AC10: 431598 | AD10: =(+AC10-+AC9)*48 -> 4320 | AE10: 508991 | AF10: =(+AE10-+AE9)*48 -> 4800 | AG10: 48745 | AH10: =(+AG10-+AG9)*48 -> 144 | AI10: 391158 | AJ10: =(+AI10-+AI9)*48 -> 3936 | AK10: 102371 | AL10: =(+AK10-+AK9)*48 -> 0 | AM10: 555477 | AN10: =(+AM10-+AM9)*48 -> 5520 | AO10: 892096 | AP10: =(+AO10-+AO9)*48 -> 9552 | AQ10: 66730 | AR10: =(+AQ10-+AQ9)*48 -> 7440 | AS10: 2204 | AT10: =(+AS10-+AS9)*48 -> 0 | AU10: 918 | AV10: =(+AU10-+AU9)*48 -> 0 | AW10: 3108 | AX10: =(+AW10-+AW9)*48 -> 0 | AY10: 298925 | AZ10: =(+AY10-+AY9)*48 -> 3072 | BA10: 160167 | BB10: =(+BA10-+BA9)*48 -> 0 | BC10: 204797 | BD10: =(+BC10-+BC9)*48 -> 2256 | BE10: 5347 | BF10: =(+BE10-+BE9)*48 -> 0 | BH10: =SUM(E10,J10,P10,H10,L10,R10,T10,V10,X10,N10,AB10,Z10,AD10,AF10,AH10,AL10,AJ10) -> 114136.7 | BI10: =SUM(F10,AN10,AP10,AT10,AV10,AX10,AR10,AZ10,BB10,BD10,BF10) -> 65990.4
A11: 44107 | C11: 5508851 | D11: =(+C11-+C10)*48 -> 105024 | E11: =D11*0.6 -> 63014.4 | F11: =D11*0.4 -> 42009.6 | G11: 275007 | H11: =(+G11-+G10)*48 -> 1440 | I11: 85681 | J11: =(+I11-+I10)*48 -> 8736 | K11: 254436 | L11: =(+K11-+K10)*48 -> 144 | M11: 24364 | N11: =(+M11-+M10)*48 -> 0 | O11: 221155 | P11: =(+O11-+O10)*48 -> 9792 | Q11: 433386 | R11: =(+Q11-+Q10)*48 -> 4656 | S11: 695107 | T11: =(+S11-+S10)*48 -> 6480 | U11: 94812.3 | V11: =(+U11-+U10)*48 -> 1293.072 | W11: 77602 | X11: =(+W11-+W10)*48 -> 1248 | Y11: 1476433 | Z11: =(+Y11-+Y10)*48 -> 10320 | AA11: 13166 | AB11: =(+AA11-+AA10)*48 -> 0 | AC11: 431690 | AD11: =(+AC11-+AC10)*48 -> 4416 | AE11: 509093 | AF11: =(+AE11-+AE10)*48 -> 4896 | AG11: 48749 | AH11: =(+AG11-+AG10)*48 -> 192 | AI11: 391267 | AJ11: =(+AI11-+AI10)*48 -> 5232 | AK11: 102371 | AL11: =(+AK11-+AK10)*48 -> 0 | AM11: 555593 | AN11: =(+AM11-+AM10)*48 -> 5568 | AO11: 892299 | AP11: =(+AO11-+AO10)*48 -> 9744 | AQ11: 66809 | AR11: =(+AQ11-+AQ10)*48 -> 3792 | AS11: 2204 | AT11: =(+AS11-+AS10)*48 -> 0 | AU11: 918 | AV11: =(+AU11-+AU10)*48 -> 0 | AW11: 3108 | AX11: =(+AW11-+AW10)*48 -> 0 | AY11: 298992 | AZ11: =(+AY11-+AY10)*48 -> 3216 | BA11: 160167 | BB11: =(+BA11-+BA10)*48 -> 0 | BC11: 204845 | BD11: =(+BC11-+BC10)*48 -> 2304 | BE11: 5347 | BF11: =(+BE11-+BE10)*48 -> 0 | BH11: =SUM(E11,J11,P11,H11,L11,R11,T11,V11,X11,N11,AB11,Z11,AD11,AF11,AH11,AL11,AJ11) -> 121859.47 | BI11: =SUM(F11,AN11,AP11,AT11,AV11,AX11,AR11,AZ11,BB11,BD11,BF11) -> 66633.6
A12: 44108 | C12: 5511177 | D12: =(+C12-+C11)*48 -> 111648 | E12: =D12*0.6 -> 66988.8 | F12: =D12*0.4 -> 44659.2 | G12: 275043 | H12: =(+G12-+G11)*48 -> 1728 | I12: 85854 | J12: =(+I12-+I11)*48 -> 8304 | K12: 254442 | L12: =(+K12-+K11)*48 -> 288 | M12: 24364 | N12: =(+M12-+M11)*48 -> 0 | O12: 221360 | P12: =(+O12-+O11)*48 -> 9840 | Q12: 433485 | R12: =(+Q12-+Q11)*48 -> 4752 | S12: 695244 | T12: =(+S12-+S11)*48 -> 6576 | U12: 94838.2 | V12: =(+U12-+U11)*48 -> 1243.2 | W12: 77629 | X12: =(+W12-+W11)*48 -> 1296 | Y12: 1476611 | Z12: =(+Y12-+Y11)*48 -> 8544 | AA12: 13166 | AB12: =(+AA12-+AA11)*48 -> 0 | AC12: 431778 | AD12: =(+AC12-+AC11)*48 -> 4224 | AE12: 509192 | AF12: =(+AE12-+AE11)*48 -> 4752 | AG12: 48778 | AH12: =(+AG12-+AG11)*48 -> 1392 | AI12: 391365 | AJ12: =(+AI12-+AI11)*48 -> 4704 | AK12: 102371 | AL12: =(+AK12-+AK11)*48 -> 0 | AM12: 555706 | AN12: =(+AM12-+AM11)*48 -> 5424 | AO12: 892496 | AP12: =(+AO12-+AO11)*48 -> 9456 | AQ12: 66869 | AR12: =(+AQ12-+AQ11)*48 -> 2880 | AS12: 2204 | AT12: =(+AS12-+AS11)*48 -> 0 | AU12: 918 | AV12: =(+AU12-+AU11)*48 -> 0 | AW12: 3108 | AX12: =(+AW12-+AW11)*48 -> 0 | AY12: 299064 | AZ12: =(+AY12-+AY11)*48 -> 3456 | BA12: 160167 | BB12: =(+BA12-+BA11)*48 -> 0 | BC12: 204894 | BD12: =(+BC12-+BC11)*48 -> 2352 | BE12: 5347 | BF12: =(+BE12-+BE11)*48 -> 0 | BH12: =SUM(E12,J12,P12,H12,L12,R12,T12,V12,X12,N12,AB12,Z12,AD12,AF12,AH12,AL12,AJ12) -> 124632 | BI12: =SUM(F12,AN12,AP12,AT12,AV12,AX12,AR12,AZ12,BB12,BD12,BF12) -> 68227.2
A13: 44109 | C13: 5513533 | D13: =(+C13-+C12)*48 -> 113088 | E13: =D13*0.6 -> 67852.8 | F13: =D13*0.4 -> 45235.2 | G13: 275072 | H13: =(+G13-+G12)*48 -> 1392 | I13: 86034 | J13: =(+I13-+I12)*48 -> 8640 | K13: 254446 | L13: =(+K13-+K12)*48 -> 192 | M13: 24364 | N13: =(+M13-+M12)*48 -> 0 | O13: 221560 | P13: =(+O13-+O12)*48 -> 9600 | Q13: 433584 | R13: =(+Q13-+Q12)*48 -> 4752 | S13: 695369 | T13: =(+S13-+S12)*48 -> 6000 | U13: 94863.101 | V13: =(+U13-+U12)*48 -> 1195.248 | W13: 77641 | X13: =(+W13-+W12)*48 -> 576 | Y13: 1476747 | Z13: =(+Y13-+Y12)*48 -> 6528 | AA13: 13166 | AB13: =(+AA13-+AA12)*48 -> 0 | AC13: 431866 | AD13: =(+AC13-+AC12)*48 -> 4224 | AE13: 509292 | AF13: =(+AE13-+AE12)*48 -> 4800 | AG13: 48760 | AH13: =(+AG13-+AG12)*48 -> -864 | AI13: 391464 | AJ13: =(+AI13-+AI12)*48 -> 4752 | AK13: 102371 | AL13: =(+AK13-+AK12)*48 -> 0 | AM13: 555817 | AN13: =(+AM13-+AM12)*48 -> 5328 | AO13: 892670 | AP13: =(+AO13-+AO12)*48 -> 8352 | AQ13: 66922 | AR13: =(+AQ13-+AQ12)*48 -> 2544 | AS13: 2204 | AT13: =(+AS13-+AS12)*48 -> 0 | AU13: 918 | AV13: =(+AU13-+AU12)*48 -> 0 | AW13: 3108 | AX13: =(+AW13-+AW12)*48 -> 0 | AY13: 299129 | AZ13: =(+AY13-+AY12)*48 -> 3120 | BA13: 160167 | BB13: =(+BA13-+BA12)*48 -> 0 | BC13: 204941 | BD13: =(+BC13-+BC12)*48 -> 2256 | BE13: 5347 | BF13: =(+BE13-+BE12)*48 -> 0 | BH13: =SUM(E13,J13,P13,H13,L13,R13,T13,V13,X13,N13,AB13,Z13,AD13,AF13,AH13,AL13,AJ13) -> 119640.05 | BI13: =SUM(F13,AN13,AP13,AT13,AV13,AX13,AR13,AZ13,BB13,BD13,BF13) -> 66835.2
A14: 44110 | C14: 5515572 | D14: =(+C14-+C13)*48 -> 97872 | E14: =D14*0.6 -> 58723.2 | F14: =D14*0.4 -> 39148.8 | G14: 275101 | H14: =(+G14-+G13)*48 -> 1392 | I14: 86223 | J14: =(+I14-+I13)*48 -> 9072 | K14: 254464 | L14: =(+K14-+K13)*48 -> 864 | M14: 24364 | N14: =(+M14-+M13)*48 -> 0 | O14: 221764 | P14: =(+O14-+O13)*48 -> 9792 | Q14: 433668 | R14: =(+Q14-+Q13)*48 -> 4032 | S14: 695484 | T14: =(+S14-+S13)*48 -> 5520 | U14: 94879.475 | V14: =(+U14-+U13)*48 -> 785.952 | W14: 77654 | X14: =(+W14-+W13)*48 -> 624 | Y14: 1476883 | Z14: =(+Y14-+Y13)*48 -> 6528 | AA14: 13166 | AB14: =(+AA14-+AA13)*48 -> 0 | AC14: 431959 | AD14: =(+AC14-+AC13)*48 -> 4464 | AE14: 509394 | AF14: =(+AE14-+AE13)*48 -> 4896 | AG14: 48763 | AH14: =(+AG14-+AG13)*48 -> 144 | AI14: 391553 | AJ14: =(+AI14-+AI13)*48 -> 4272 | AK14: 102371 | AL14: =(+AK14-+AK13)*48 -> 0 | AM14: 555935 | AN14: =(+AM14-+AM13)*48 -> 5664 | AO14: 892850 | AP14: =(+AO14-+AO13)*48 -> 8640 | AQ14: 66979 | AR14: =(+AQ14-+AQ13)*48 -> 2736 | AS14: 2204 | AT14: =(+AS14-+AS13)*48 -> 0 | AU14: 918 | AV14: =(+AU14-+AU13)*48 -> 0 | AW14: 3108 | AX14: =(+AW14-+AW13)*48 -> 0 | AY14: 299201 | AZ14: =(+AY14-+AY13)*48 -> 3456 | BA14: 160167 | BB14: =(+BA14-+BA13)*48 -> 0 | BC14: 204991 | BD14: =(+BC14-+BC13)*48 -> 2400 | BE14: 5347 | BF14: =(+BE14-+BE13)*48 -> 0 | BH14: =SUM(E14,J14,P14,H14,L14,R14,T14,V14,X14,N14,AB14,Z14,AD14,AF14,AH14,AL14,AJ14) -> 111109.15 | BI14: =SUM(F14,AN14,AP14,AT14,AV14,AX14,AR14,AZ14,BB14,BD14,BF14) -> 62044.8
A15: 44111 | C15: 5517560 | D15: =(+C15-+C14)*48 -> 95424 | E15: =D15*0.6 -> 57254.4 | F15: =D15*0.4 -> 38169.6 | G15: 275130 | H15: =(+G15-+G14)*48 -> 1392 | I15: 86405 | J15: =(+I15-+I14)*48 -> 8736 | K15: 254467 | L15: =(+K15-+K14)*48 -> 144 | M15: 24364 | N15: =(+M15-+M14)*48 -> 0 | O15: 221951 | P15: =(+O15-+O14)*48 -> 8976 | Q15: 433707 | R15: =(+Q15-+Q14)*48 -> 1872 | S15: 695619 | T15: =(+S15-+S14)*48 -> 6480 | U15: 94898.269 | V15: =(+U15-+U14)*48 -> 902.112 | W15: 77670 | X15: =(+W15-+W14)*48 -> 768 | Y15: 1477115 | Z15: =(+Y15-+Y14)*48 -> 11136 | AA15: 13166 | AB15: =(+AA15-+AA14)*48 -> 0 | AC15: 432056 | AD15: =(+AC15-+AC14)*48 -> 4656 | AE15: 509500 | AF15: =(+AE15-+AE14)*48 -> 5088 | AG15: 48766 | AH15: =(+AG15-+AG14)*48 -> 144 | AI15: 391633 | AJ15: =(+AI15-+AI14)*48 -> 3840 | AK15: 102371 | AL15: =(+AK15-+AK14)*48 -> 0 | AM15: 556054 | AN15: =(+AM15-+AM14)*48 -> 5712 | AO15: 893029 | AP15: =(+AO15-+AO14)*48 -> 8592 | AQ15: 67094 | AR15: =(+AQ15-+AQ14)*48 -> 5520 | AS15: 2204 | AT15: =(+AS15-+AS14)*48 -> 0 | AU15: 918 | AV15: =(+AU15-+AU14)*48 -> 0 | AW15: 3108 | AX15: =(+AW15-+AW14)*48 -> 0 | AY15: 299276 | AZ15: =(+AY15-+AY14)*48 -> 3600 | BA15: 160167 | BB15: =(+BA15-+BA14)*48 -> 0 | BC15: 205041 | BD15: =(+BC15-+BC14)*48 -> 2400 | BE15: 5347 | BF15: =(+BE15-+BE14)*48 -> 0 | BH15: =SUM(E15,J15,P15,H15,L15,R15,T15,V15,X15,N15,AB15,Z15,AD15,AF15,AH15,AL15,AJ15) -> 111388.51 | BI15: =SUM(F15,AN15,AP15,AT15,AV15,AX15,AR15,AZ15,BB15,BD15,BF15) -> 63993.6
A16: 44112 | C16: 5519533 | D16: =(+C16-+C15)*48 -> 94704 | E16: =D16*0.6 -> 56822.4 | F16: =D16*0.4 -> 37881.6 | G16: 275168 | H16: =(+G16-+G15)*48 -> 1824 | I16: 86573 | J16: =(+I16-+I15)*48 -> 8064 | K16: 254482 | L16: =(+K16-+K15)*48 -> 720 | M16: 24364 | N16: =(+M16-+M15)*48 -> 0 | O16: 222126 | P16: =(+O16-+O15)*48 -> 8400 | Q16: 433753 | R16: =(+Q16-+Q15)*48 -> 2208 | S16: 695746 | T16: =(+S16-+S15)*48 -> 6096 | U16: 94916.913 | V16: =(+U16-+U15)*48 -> 894.912 | W16: 77694 | X16: =(+W16-+W15)*48 -> 1152 | Y16: 1477380 | Z16: =(+Y16-+Y15)*48 -> 12720 | AA16: 13166 | AB16: =(+AA16-+AA15)*48 -> 0 | AC16: 432159 | AD16: =(+AC16-+AC15)*48 -> 4944 | AE16: 509607 | AF16: =(+AE16-+AE15)*48 -> 5136 | AG16: 48770 | AH16: =(+AG16-+AG15)*48 -> 192 | AI16: 391705 | AJ16: =(+AI16-+AI15)*48 -> 3456 | AK16: 102371 | AL16: =(+AK16-+AK15)*48 -> 0 | AM16: 556163 | AN16: =(+AM16-+AM15)*48 -> 5232 | AO16: 893201 | AP16: =(+AO16-+AO15)*48 -> 8256 | AQ16: 67244 | AR16: =(+AQ16-+AQ15)*48 -> 7200 | AS16: 2204 | AT16: =(+AS16-+AS15)*48 -> 0 | AU16: 918 | AV16: =(+AU16-+AU15)*48 -> 0 | AW16: 3108 | AX16: =(+AW16-+AW15)*48 -> 0 | AY16: 299347 | AZ16: =(+AY16-+AY15)*48 -> 3408 | BA16: 160167 | BB16: =(+BA16-+BA15)*48 -> 0 | BC16: 205088 | BD16: =(+BC16-+BC15)*48 -> 2256 | BE16: 5347 | BF16: =(+BE16-+BE15)*48 -> 0 | BH16: =SUM(E16,J16,P16,H16,L16,R16,T16,V16,X16,N16,AB16,Z16,AD16,AF16,AH16,AL16,AJ16) -> 112629.31 | BI16: =SUM(F16,AN16,AP16,AT16,AV16,AX16,AR16,AZ16,BB16,BD16,BF16) -> 64233.6
A17: 44113 | C17: 5521462 | D17: =(+C17-+C16)*48 -> 92592 | E17: =D17*0.6 -> 55555.2 | F17: =D17*0.4 -> 37036.8 | G17: 275204 | H17: =(+G17-+G16)*48 -> 1728 | I17: 86749 | J17: =(+I17-+I16)*48 -> 8448 | K17: 254539 | L17: =(+K17-+K16)*48 -> 2736 | M17: 24373 | N17: =(+M17-+M16)*48 -> 432 | O17: 222314 | P17: =(+O17-+O16)*48 -> 9024 | Q17: 433824 | R17: =(+Q17-+Q16)*48 -> 3408 | S17: 695892 | T17: =(+S17-+S16)*48 -> 7008 | U17: 94936.724 | V17: =(+U17-+U16)*48 -> 950.928 | W17: 77709 | X17: =(+W17-+W16)*48 -> 720 | Y17: 1477669 | Z17: =(+Y17-+Y16)*48 -> 13872 | AA17: 13166 | AB17: =(+AA17-+AA16)*48 -> 0 | AC17: 432266 | AD17: =(+AC17-+AC16)*48 -> 5136 | AE17: 509714 | AF17: =(+AE17-+AE16)*48 -> 5136 | AG17: 48774 | AH17: =(+AG17-+AG16)*48 -> 192 | AI17: 391791 | AJ17: =(+AI17-+AI16)*48 -> 4128 | AK17: 102371 | AL17: =(+AK17-+AK16)*48 -> 0 | AM17: 556263 | AN17: =(+AM17-+AM16)*48 -> 4800 | AO17: 893363 | AP17: =(+AO17-+AO16)*48 -> 7776 | AQ17: 67489 | AR17: =(+AQ17-+AQ16)*48 -> 11760 | AS17: 2204 | AT17: =(+AS17-+AS16)*48 -> 0 | AU17: 918 | AV17: =(+AU17-+AU16)*48 -> 0 | AW17: 3108 | AX17: =(+AW17-+AW16)*48 -> 0 | AY17: 299418 | AZ17: =(+AY17-+AY16)*48 -> 3408 | BA17: 160167 | BB17: =(+BA17-+BA16)*48 -> 0 | BC17: 205138 | BD17: =(+BC17-+BC16)*48 -> 2400 | BE17: 5347 | BF17: =(+BE17-+BE16)*48 -> 0 | BH17: =SUM(E17,J17,P17,H17,L17,R17,T17,V17,X17,N17,AB17,Z17,AD17,AF17,AH17,AL17,AJ17) -> 118474.13 | BI17: =SUM(F17,AN17,AP17,AT17,AV17,AX17,AR17,AZ17,BB17,BD17,BF17) -> 67180.8
A18: 44114 | C18: 5523643 | D18: =(+C18-+C17)*48 -> 104688 | E18: =D18*0.6 -> 62812.8 | F18: =D18*0.4 -> 41875.2 | G18: 275247 | H18: =(+G18-+G17)*48 -> 2064 | I18: 86919 | J18: =(+I18-+I17)*48 -> 8160 | K18: 254574 | L18: =(+K18-+K17)*48 -> 1680 | M18: 24373 | N18: =(+M18-+M17)*48 -> 0 | O18: 222499 | P18: =(+O18-+O17)*48 -> 8880 | Q18: 433894 | R18: =(+Q18-+Q17)*48 -> 3360 | S18: 696027 | T18: =(+S18-+S17)*48 -> 6480 | U18: 94958.249 | V18: =(+U18-+U17)*48 -> 1033.2 | W18: 77736 | X18: =(+W18-+W17)*48 -> 1296 | Y18: 1477912 | Z18: =(+Y18-+Y17)*48 -> 11664 | AA18: 13166 | AB18: =(+AA18-+AA17)*48 -> 0 | AC18: 432368 | AD18: =(+AC18-+AC17)*48 -> 4896 | AE18: 509819 | AF18: =(+AE18-+AE17)*48 -> 5040 | AG18: 48777 | AH18: =(+AG18-+AG17)*48 -> 144 | AI18: 391889 | AJ18: =(+AI18-+AI17)*48 -> 4704 | AK18: 102371 | AL18: =(+AK18-+AK17)*48 -> 0 | AM18: 556357 | AN18: =(+AM18-+AM17)*48 -> 4512 | AO18: 893523 | AP18: =(+AO18-+AO17)*48 -> 7680 | AQ18: 67609 | AR18: =(+AQ18-+AQ17)*48 -> 5760 | AS18: 2204 | AT18: =(+AS18-+AS17)*48 -> 0 | AU18: 918 | AV18: =(+AU18-+AU17)*48 -> 0 | AW18: 3108 | AX18: =(+AW18-+AW17)*48 -> 0 | AY18: 299492 | AZ18: =(+AY18-+AY17)*48 -> 3552 | BA18: 160167 | BB18: =(+BA18-+BA17)*48 -> 0 | BC18: 205187 | BD18: =(+BC18-+BC17)*48 -> 2352 | BE18: 5347 | BF18: =(+BE18-+BE17)*48 -> 0 | BH18: =SUM(E18,J18,P18,H18,L18,R18,T18,V18,X18,N18,AB18,Z18,AD18,AF18,AH18,AL18,AJ18) -> 122214 | BI18: =SUM(F18,AN18,AP18,AT18,AV18,AX18,AR18,AZ18,BB18,BD18,BF18) -> 65731.2
A19: 44115 | C19: 5526870 | D19: =(+C19-+C18)*48 -> 154896 | E19: =D19*0.6 -> 92937.6 | F19: =D19*0.4 -> 61958.4 | G19: 275287 | H19: =(+G19-+G18)*48 -> 1920 | I19: 87093 | J19: =(+I19-+I18)*48 -> 8352 | K19: 254612 | L19: =(+K19-+K18)*48 -> 1824 | M19: 24380 | N19: =(+M19-+M18)*48 -> 336 | O19: 222695 | P19: =(+O19-+O18)*48 -> 9408 | Q19: 434009 | R19: =(+Q19-+Q18)*48 -> 5520 | S19: 696160 | T19: =(+S19-+S18)*48 -> 6384 | U19: 94982.813 | V19: =(+U19-+U18)*48 -> 1179.072 | W19: 77748 | X19: =(+W19-+W18)*48 -> 576 | Y19: 1478142 | Z19: =(+Y19-+Y18)*48 -> 11040 | AA19: 13166 | AB19: =(+AA19-+AA18)*48 -> 0 | AC19: 432470 | AD19: =(+AC19-+AC18)*48 -> 4896 | AE19: 509926 | AF19: =(+AE19-+AE18)*48 -> 5136 | AG19: 48782 | AH19: =(+AG19-+AG18)*48 -> 240 | AI19: 392000 | AJ19: =(+AI19-+AI18)*48 -> 5328 | AK19: 102371 | AL19: =(+AK19-+AK18)*48 -> 0 | AM19: 556462 | AN19: =(+AM19-+AM18)*48 -> 5040 | AO19: 893695 | AP19: =(+AO19-+AO18)*48 -> 8256 | AQ19: 67682 | AR19: =(+AQ19-+AQ18)*48 -> 3504 | AS19: 2204 | AT19: =(+AS19-+AS18)*48 -> 0 | AU19: 918 | AV19: =(+AU19-+AU18)*48 -> 0 | AW19: 3108 | AX19: =(+AW19-+AW18)*48 -> 0 | AY19: 299565 | AZ19: =(+AY19-+AY18)*48 -> 3504 | BA19: 160167 | BB19: =(+BA19-+BA18)*48 -> 0 | BC19: 205237 | BD19: =(+BC19-+BC18)*48 -> 2400 | BE19: 5347 | BF19: =(+BE19-+BE18)*48 -> 0 | BH19: =SUM(E19,J19,P19,H19,L19,R19,T19,V19,X19,N19,AB19,Z19,AD19,AF19,AH19,AL19,AJ19) -> 155076.67 | BI19: =SUM(F19,AN19,AP19,AT19,AV19,AX19,AR19,AZ19,BB19,BD19,BF19) -> 84662.4
... A39: 44135 | C39: 5566794 | D39: =(+C39-+C38)*48 -> 100848 | E39: =D39*0.6 -> 60508.8 | F39: =D39*0.4 -> 40339.2 | G39: 275933 | H39: =(+G39-+G38)*48 -> 2016 | I39: 90532 | J39: =(+I39-+I38)*48 -> 7872 | K39: 255291 | L39: =(+K39-+K38)*48 -> 2976 | M39: 24387 | N39: =(+M39-+M38)*48 -> 96 | O39: 226556 | P39: =(+O39-+O38)*48 -> 9312 | Q39: 435434 | R39: =(+Q39-+Q38)*48 -> 4800 | S39: 698814 | T39: =(+S39-+S38)*48 -> 6000 | U39: 95388.142 | V39: =(+U39-+U38)*48 -> 945.888 | W39: 78217 | X39: =(+W39-+W38)*48 -> 1200 | Y39: 1484465 | Z39: =(+Y39-+Y38)*48 -> 13200 | AA39: 13166 | AB39: =(+AA39-+AA38)*48 -> 0 | AC39: 434301 | AD39: =(+AC39-+AC38)*48 -> 4944 | AE39: 511909 | AF39: =(+AE39-+AE38)*48 -> 5184 | AG39: 48868 | AH39: =(+AG39-+AG38)*48 -> 192 | AI39: 394107 | AJ39: =(+AI39-+AI38)*48 -> 5520 | AK39: 102371 | AL39: =(+AK39-+AK38)*48 -> 0 | AM39: 558480 | AN39: =(+AM39-+AM38)*48 -> 6000 | AO39: 897214 | AP39: =(+AO39-+AO38)*48 -> 9840 | AQ39: 70227 | AR39: =(+AQ39-+AQ38)*48 -> 4848 | AS39: 2204 | AT39: =(+AS39-+AS38)*48 -> 0 | AU39: 918 | AV39: =(+AU39-+AU38)*48 -> 0 | AW39: 3108 | AX39: =(+AW39-+AW38)*48 -> 0 | AY39: 301169 | AZ39: =(+AY39-+AY38)*48 -> 3936 | BA39: 160167 | BB39: =(+BA39-+BA38)*48 -> 0 | BC39: 206260 | BD39: =(+BC39-+BC38)*48 -> 2496 | BE39: 5347 | BF39: =(+BE39-+BE38)*48 -> 0 | BH39: =SUM(E39,J39,P39,H39,L39,R39,T39,V39,X39,N39,AB39,Z39,AD39,AF39,AH39,AL39,AJ39) -> 124766.69 | BI39: =SUM(F39,AN39,AP39,AT39,AV39,AX39,AR39,AZ39,BB39,BD39,BF39) -> 67459.2

Sheet Submetering EL
C1: FSH | E1: Sub- meter | G1: Sub- meter | I1: Sub- meter | K1: Sub- meter | M1: Sub- meter | P1: FSH | R1: Sub- meter | T1: Sub- meter | V1: Sub- meter | X1: Sub- meter | AA1: FSH | AC1: Sub- meter | AE1: Sub- meter | AG1: Sub- meter | AI1: Sub- meter | AK1: Sub- meter | AM1: Sub- meter | AP1: FSH | AR1: Sub- meter | AT1: Sub- meter | AV1: Sub- meter | AX1: Sub- meter | AZ1: Sub- meter | BB1: Sub- meter | BD1: Sub- meter | BG1: FSH | BI1: Sub- meter | BK1: Sub- meter | BM1: Sub- meter | BO1: Sub- meter | BQ1: Sub- meter | BS1: Sub- meter | BV1: FSH & FSP | BX1: Sub- meter | BZ1: Sub- meter | CB1: Sub- meter | CE1: FSH & FSP | CH1: FSH & FSP | CK1: FSH & FSP | CN1: FSP | CQ1: FSP | CT1: FSP | CV1: Sub- meter | CX1: Sub- meter | CZ1: Sub- meter | DB1: Sub- meter | DD1: Sub- meter | DF1: Sub- meter | DI1: FSP | DL1: FSP | DN1: Sub- meter | DP1: Sub- meter | DR1: Sub- meter | DT1: Sub- meter | DV1: Sub- meter
C2: HOT Normal and Essential power for linen chute(9/F-45/F), HOT water pump at 8/F, Podium dimmer supply(P1-P6), MVAC system(B1/F-B2/F), Bus station BPTT supply. | E2: HOT Normal and Essential power for linen chute(9/F-45/F), | G2: HOT water pump at 8/F, | I2: Podium dimmer supply(P1-P6) | K2: MVAC system(B1/F-B2/F), | M2: Bus station BPTT supply. | P2: HOT Normal Power for Guest rooms supply (9/F-45/F), MVAC system (2/F & 46/F), P&D system(46/F) Podium MVAC system (P1/F-P6/F) | R2: HOT Normal Power for Guest rooms supply (9/F-45/F), | T2: MVAC system (2/F & 46/F), | V2: P&D system(46/F) | X2: Podium MVAC system (P1/F-P6/F) | AA2: P5 Pool Plant, Laundry (hotel 70%,Place 30%), 9/F - 28/F public area, 29/F 46/F Public area Podium normal power supply for water feature(G/F), Chiller WCC-01(B2/F)(FSH 50%, FSP 50%) | AC2: P5 Pool Plant, | AE2: Laundry (hotel 70%,Place 30%), | AG2: 9/F - 28/F public area, | AI2: 29/F 46/F Public area | AK2: Podium normal power supply for water feature(G/F), | AM2: Chiller WCC-01(B2/F)(FSH 50%, FSP 50%) | AP2: Podium normal power for Administration office(P5/F & P6/F), P&D system supply(B2/F), Planter lighting supply(Open Space), Kitchen public supply(B1/F, P1/F, P2/F, P3/F, P4/F & P6/F), BMS room supply(B1/F), Security room supply(G/F), Computer & PABX room | AR2: Podium normal power for Administration office(P5/F & P6/F), | AT2: P&D system supply(B2/F), | AV2: Planter lighting supply(Open Space), | AX2: Kitchen public supply(B1/F, P1/F, P2/F, P3/F, P4/F & P6/F), | AZ2: BMS room supply(B1/F), | BB2: Security room supply(G/F), | BD2: Computer & PABX room | BG2: Podium normal power supply for Public supply(P1/F - P6/F), Kitchen(B1/F, P1/F, P2/F, P3/F, P4/F & P6/F), P&D system supply(B1/F), Refuse room supply(G/F), Gas boiler supply(B2/F) and MVAC system supply(P1/F-P6/F). | BV2: Podium normal power supply for main P&D system supply(B1/F), MVAC chilled water pump(B1/F) Chiller WCC-02(B2/F) (FSH 50%, FSP 50%) | BX2: Podium normal power supply for main P&D system supply(B1/F), | BZ2: MVAC chilled water pump(B1/F) | CB2: Chiller WCC-02(B2/F) (FSH 50%, FSP 50%) | CE2: Chiller # 3 (FSH 50%, FSP 50%) | CH2: Chiller # 4 (FSH 50%, FSP 50%) | CK2: Chiller # 5 (FSH 50%, FSP 50%) | CN2: SHT normal power for Guest rooms supply (11/F-23/F). | CQ2: SHT normal power for Guest rooms supply (25/F-57/F). | CT2: SHT Essential Power for Public Power supply, F.S. Pump (9/F, 57/F & 39/F), Podium F.S. pump(P1M), Lift LT/S1-LT/S7(LM/F), Lift LT/S8-S9(59/F) and Lift LT/S10(8/F). | CV2: SHT Essential Power for Public Power supply, | CX2: F.S. Pump (9/F, 57/F & 39/F), | CZ2: Podium F.S. pump(P1M), | DB2: Lift LT/S1-LT/S7(LM/F), | DD2: Lift LT/S8-S9(59/F) and | DF2: Lift LT/S10(8/F). | DI2: SHT normal power for Guest rooms supply (25/F-57/F). | DL2: SHT normal power for MVAC System(8/F & 40/F), Public supply (8-R/F), P&D system(40/F & 60/F), swimming pool(57/F), SWB 3&4(40/F) | DN2: SHT normal power for MVAC System(8/F & 40/F), | DP2: Public supply (8-R/F), | DR2: P&D system(40/F & 60/F), | DT2: swimming pool(57/F), | DV2: SWB 3&4(40/F)
C3: 5065546 | P3: 5065547 | AA3: 5008272 | AP3: 5065548 | BG3: 5465545 | BV3: 5008273 | CE3: 5018351 | CH3: 5018354 | CK3: 5018350 | CN3: 5065543 | CQ3: 5065544 | CT3: 5065541 | DI3: 5065542 | DL3: 5065540
C4: TXW1 | P4: TXW4 | AA4: TXW2 | AP4: TXC2 | BG4: TXC1 | BV4: TXW3 | CE4: TXN1 | CH4: TXN2 | CK4: TXN3 | CN4: TXN4 | CQ4: TXE1 | CT4: TXE2 | DI4: TXE3 | DL4: TXE4
A6: Date | C6: Reading Kwh | D6: Differecne Kwh | E6: Reading Kwh | F6: Differecne Kwh | G6: Reading Kwh | H6: Differecne Kwh | I6: Reading Kwh | J6: Differecne Kwh | K6: Reading Kwh | L6: Differecne Kwh | M6: Reading Kwh | N6: Differecne Kwh | P6: Reading Kwh | Q6: Differecne Kwh | R6: Reading Kwh | S6: Differecne Kwh | T6: Reading Kwh | U6: Differecne Kwh | V6: Reading Kwh | W6: Differecne Kwh | X6: Reading Kwh | Y6: Differecne Kwh | AA6: Reading Kwh | AB6: Differecne Kwh | AC6: Reading Kwh | AD6: Differecne Kwh | AE6: Reading Kwh | AF6: Differecne Kwh | AG6: Reading Kwh | AH6: Differecne Kwh | AI6: Reading Kwh | AJ6: Differecne Kwh | AK6: Reading Kwh | AL6: Differecne Kwh | AM6: Reading Kwh | AN6: Differecne Kwh | AP6: Reading Kwh | AQ6: Differecne Kwh | AR6: Reading Kwh | AS6: Differecne Kwh | AT6: Reading Kwh | AU6: Differecne Kwh | AV6: Reading Kwh | AW6: Differecne Kwh | AX6: Reading Kwh | AY6: Differecne Kwh | AZ6: Reading Kwh | BA6: Differecne Kwh | BB6: Reading Kwh | BC6: Differecne Kwh | BD6: Reading Kwh | BE6: Differecne Kwh | BG6: Reading Kwh | BH6: Differecne Kwh | BI6: Reading Kwh | BJ6: Differecne Kwh | BK6: Reading Kwh | BL6: Differecne Kwh | BM6: Reading Kwh | BN6: Differecne Kwh | BO6: Reading Kwh | BP6: Differecne Kwh | BQ6: Reading Kwh | BR6: Differecne Kwh | BS6: Reading Kwh | BT6: Differecne Kwh | BV6: Reading Kwh | BW6: Differecne Kwh | BX6: Reading Kwh | BY6: Differecne Kwh | BZ6: Reading Kwh | CA6: Differecne Kwh | CB6: Reading Kwh | CC6: Differecne Kwh | CE6: Reading Kwh | CF6: Differecne Kwh | CH6: Reading Kwh | CI6: Differecne Kwh | CK6: Reading Kwh | CL6: Differecne Kwh | CN6: Reading Kwh | CO6: Differecne Kwh | CQ6: Reading Kwh | CR6: Differecne Kwh | CT6: Reading Kwh | CU6: Differecne Kwh | CV6: Reading Kwh | CW6: Differecne Kwh | CX6: Reading Kwh | CY6: Differecne Kwh | CZ6: Reading Kwh | DA6: Differecne Kwh | DB6: Reading Kwh | DC6: Differecne Kwh | DD6: Reading Kwh | DE6: Differecne Kwh | DF6: Reading Kwh | DG6: Differecne Kwh | DI6: Reading Kwh | DJ6: Differecne Kwh | DL6: Reading Kwh | DM6: Differecne Kwh | DN6: Reading Kwh | DO6: Differecne Kwh | DP6: Reading Kwh | DQ6: Differecne Kwh | DR6: Reading Kwh | DS6: Differecne Kwh | DT6: Reading Kwh | DU6: Differecne Kwh | DV6: Reading Kwh | DW6: Differecne Kwh

Sheet Submetering Water
