Workbook

Sheet TOTAL
A1: Site Name | B1: Day | C1: Month | D1: Year | E1: Total Electricity Kwh | F1: Electricity Tariff ($/Kwh) | G1: Natual Gas (m3) | H1: Natural Gas $/m3 | I1: Water Utility Supply (m3) m3 | J1: Water Utility Supply (m3) $/m3 | K1: Room Nights | L1: Food Covers
A2: Hong Kong | B2: 1 | C2: 11 | D2: 2020 | E2: ='Total - FSH'!E2 -> 35365 | G2: ='Total - FSH'!G2/38.3 -> 3442.5888 | I2: ='Athens Daily - Water'!R7 -> 3809.778
A3: Hong Kong | B3: 2 | C3: 11 | D3: 2020 | E3: ='Total - FSH'!E3 -> 29587 | G3: ='Total - FSH'!G3/38.3 -> 3274.7956 | I3: ='Athens Daily - Water'!R8 -> 5471.028
A4: Hong Kong | B4: 3 | C4: 11 | D4: 2020 | E4: ='Total - FSH'!E4 -> 29603 | G4: ='Total - FSH'!G4/38.3 -> 3009.4195 | I4: ='Athens Daily - Water'!R9 -> 4729.367
A5: Hong Kong | B5: 4 | C5: 11 | D5: 2020 | E5: ='Total - FSH'!E5 -> 32463.5 | G5: ='Total - FSH'!G5/38.3 -> 2954.9264 | I5: ='Athens Daily - Water'!R10 -> 4280.931
A6: Hong Kong | B6: 5 | C6: 11 | D6: 2020 | E6: ='Total - FSH'!E6 -> 32059 | G6: ='Total - FSH'!G6/38.3 -> 3188.1663 | I6: ='Athens Daily - Water'!R11 -> 4295.829
A7: Hong Kong | B7: 6 | C7: 11 | D7: 2020 | E7: ='Total - FSH'!E7 -> 32332 | G7: ='Total - FSH'!G7/38.3 -> 3046.3507 | I7: ='Athens Daily - Water'!R12 -> 4217.518
A8: Hong Kong | B8: 7 | C8: 11 | D8: 2020 | E8: ='Total - FSH'!E8 -> 34820.5 | G8: ='Total - FSH'!G8/38.3 -> 2850.1422 | I8: ='Athens Daily - Water'!R13 -> 4374.8
A9: Hong Kong | B9: 8 | C9: 11 | D9: 2020 | E9: ='Total - FSH'!E9 -> 35531.5 | G9: ='Total - FSH'!G9/38.3 -> 2921.4041 | I9: ='Athens Daily - Water'!R14 -> 5201.11
A10: Hong Kong | B10: 9 | C10: 11 | D10: 2020 | E10: ='Total - FSH'!E10 -> 29839 | G10: ='Total - FSH'!G10/38.3 -> 2983.4369 | I10: ='Athens Daily - Water'!R15 -> 4863.226
A11: Hong Kong | B11: 10 | C11: 11 | D11: 2020 | E11: ='Total - FSH'!E11 -> 28978 | G11: ='Total - FSH'!G11/38.3 -> 2913.9672 | I11: ='Athens Daily - Water'!R16 -> 4208.351
A12: Hong Kong | B12: 11 | C12: 11 | D12: 2020 | E12: ='Total - FSH'!E12 -> 28806.5 | G12: ='Total - FSH'!G12/38.3 -> 2990.4175 | I12: ='Athens Daily - Water'!R17 -> 4480.587
A13: Hong Kong | B13: 12 | C13: 11 | D13: 2020 | E13: ='Total - FSH'!E13 -> 27811 | G13: ='Total - FSH'!G13/38.3 -> 3192.391 | I13: ='Athens Daily - Water'!R18 -> 5048.029
... A31: Hong Kong | B31: 30 | C31: 11 | D31: 2020 | E31: ='Total - FSH'!E31 -> 31511 | G31: ='Total - FSH'!G31/38.3 -> 3086.9477 | I31: ='Athens Daily - Water'!R36 -> 5177.915

Sheet Total - FSH
A1: Site Name | B1: Day | C1: Month | D1: Year | E1: Total Electricity Kwh | F1: Electricity Tariff ($/Kwh) | G1: Town Gas (m3) | H1: Town Gas $/m3 | I1: Water Utility supply (m3) | J1: Water Utility (m3) $/m3 | K1: Rooms Nights | L1: Total Guests
A2: FSHK | B2: 1 | C2: 9 | D2: 2020 | E2: ='Athens Daily - EL'!AK8 -> 35365 | G2: ='Athens Daily - Gas'!BH9 -> 131851.15 | I2: ='Athens Daily - Water'!R8 -> 5471.028
A3: FSHK | B3: 2 | C3: 9 | D3: 2020 | E3: ='Athens Daily - EL'!AK9 -> 29587 | G3: ='Athens Daily - Gas'!BH10 -> 125424.67 | I3: ='Athens Daily - Water'!R8 -> 5471.028
A4: FSHK | B4: 3 | C4: 9 | D4: 2020 | E4: ='Athens Daily - EL'!AK10 -> 29603 | G4: ='Athens Daily - Gas'!BH11 -> 115260.77 | I4: ='Athens Daily - Water'!R9 -> 4729.367
A5: FSHK | B5: 4 | C5: 9 | D5: 2020 | E5: ='Athens Daily - EL'!AK11 -> 32463.5 | G5: ='Athens Daily - Gas'!BH12 -> 113173.68 | I5: ='Athens Daily - Water'!R10 -> 4280.931
A6: FSHK | B6: 5 | C6: 9 | D6: 2020 | E6: ='Athens Daily - EL'!AK12 -> 32059 | G6: ='Athens Daily - Gas'!BH13 -> 122106.77 | I6: ='Athens Daily - Water'!R11 -> 4295.829
A7: FSHK | B7: 6 | C7: 9 | D7: 2020 | E7: ='Athens Daily - EL'!AK13 -> 32332 | G7: ='Athens Daily - Gas'!BH14 -> 116675.23 | I7: ='Athens Daily - Water'!R12 -> 4217.518
A8: FSHK | B8: 7 | C8: 9 | D8: 2020 | E8: ='Athens Daily - EL'!AK14 -> 34820.5 | G8: ='Athens Daily - Gas'!BH15 -> 109160.45 | I8: ='Athens Daily - Water'!R13 -> 4374.8
A9: FSHK | B9: 8 | C9: 9 | D9: 2020 | E9: ='Athens Daily - EL'!AK15 -> 35531.5 | G9: ='Athens Daily - Gas'!BH16 -> 111889.78 | I9: ='Athens Daily - Water'!R14 -> 5201.11
A10: FSHK | B10: 9 | C10: 9 | D10: 2020 | E10: ='Athens Daily - EL'!AK16 -> 29839 | G10: ='Athens Daily - Gas'!BH17 -> 114265.63 | I10: ='Athens Daily - Water'!R15 -> 4863.226
A11: FSHK | B11: 10 | C11: 9 | D11: 2020 | E11: ='Athens Daily - EL'!AK17 -> 28978 | G11: ='Athens Daily - Gas'!BH18 -> 111604.94 | I11: ='Athens Daily - Water'!R16 -> 4208.351
A12: FSHK | B12: 11 | C12: 9 | D12: 2020 | E12: ='Athens Daily - EL'!AK18 -> 28806.5 | G12: ='Athens Daily - Gas'!BH19 -> 114532.99 | I12: ='Athens Daily - Water'!R17 -> 4480.587
A13: FSHK | B13: 12 | C13: 9 | D13: 2020 | E13: ='Athens Daily - EL'!AK19 -> 27811 | G13: ='Athens Daily - Gas'!BH20 -> 122268.58 | I13: ='Athens Daily - Water'!R18 -> 5048.029
A14: FSHK | B14: 13 | C14: 9 | D14: 2020 | E14: ='Athens Daily - EL'!AK20 -> 27969 | G14: ='Athens Daily - Gas'!BH21 -> 119453.28 | I14: ='Athens Daily - Water'!R19 -> 4991.929
... A31: FSHK | B31: 30 | C31: 9 | D31: 2020 | E31: ='Athens Daily - EL'!AK37 -> 31511 | G31: ='Athens Daily - Gas'!BH38 -> 118230.1 | I31: ='Athens Daily - Water'!R36 -> 5177.915

Sheet Total - FSP
A1: Site Name | B1: Day | C1: Month | D1: Year | E1: Total Electricity Kwh | F1: Electricity Tariff ($/Kwh) | G1: Town Gas (m3) | H1: Town Gas $/m3 | I1: Water Utility supply (m3) | J1: Water Utility (m3) $/m3 | K1: Rooms Nights | L1: Total Guests
A2: FSHK | B2: 1 | C2: 9 | D2: 2020 | E2: ='Athens Daily - EL'!AL8 -> 10331 | G2: ='Athens Daily - Gas'!BI9 -> 68976 | I2: ='Athens Daily - Water'!S7 -> 1556.5
A3: FSHK | B3: 2 | C3: 9 | D3: 2020 | E3: ='Athens Daily - EL'!AL9 -> 6272 | G3: ='Athens Daily - Gas'!BI10 -> 71932.8 | I3: ='Athens Daily - Water'!S8 -> 1498
A4: FSHK | B4: 3 | C4: 9 | D4: 2020 | E4: ='Athens Daily - EL'!AL10 -> 5831 | G4: ='Athens Daily - Gas'!BI11 -> 60537.6 | I4: ='Athens Daily - Water'!S9 -> 1454.5
A5: FSHK | B5: 4 | C5: 9 | D5: 2020 | E5: ='Athens Daily - EL'!AL11 -> 9032.5 | G5: ='Athens Daily - Gas'!BI12 -> 63312 | I5: ='Athens Daily - Water'!S10 -> 1428
A6: FSHK | B6: 5 | C6: 9 | D6: 2020 | E6: ='Athens Daily - EL'!AL12 -> 8976 | G6: ='Athens Daily - Gas'!BI13 -> 66028.8 | I6: ='Athens Daily - Water'!S11 -> 1313
A7: FSHK | B7: 6 | C7: 9 | D7: 2020 | E7: ='Athens Daily - EL'!AL13 -> 8668 | G7: ='Athens Daily - Gas'!BI14 -> 60835.2 | I7: ='Athens Daily - Water'!S12 -> 1489.5
A8: FSHK | B8: 7 | C8: 9 | D8: 2020 | E8: ='Athens Daily - EL'!AL14 -> 10686.5 | G8: ='Athens Daily - Gas'!BI15 -> 62390.4 | I8: ='Athens Daily - Water'!S13 -> 1505.5
A9: FSHK | B9: 8 | C9: 9 | D9: 2020 | E9: ='Athens Daily - EL'!AL15 -> 10433.5 | G9: ='Athens Daily - Gas'!BI16 -> 58752 | I9: ='Athens Daily - Water'!S14 -> 1511
A10: FSHK | B10: 9 | C10: 9 | D10: 2020 | E10: ='Athens Daily - EL'!AL16 -> 7043 | G10: ='Athens Daily - Gas'!BI17 -> 57417.6 | I10: ='Athens Daily - Water'!S15 -> 1362
A11: FSHK | B11: 10 | C11: 9 | D11: 2020 | E11: ='Athens Daily - EL'!AL17 -> 4654 | G11: ='Athens Daily - Gas'!BI18 -> 59337.6 | I11: ='Athens Daily - Water'!S16 -> 1337.5
A12: FSHK | B12: 11 | C12: 9 | D12: 2020 | E12: ='Athens Daily - EL'!AL18 -> 5064.5 | G12: ='Athens Daily - Gas'!BI19 -> 60201.6 | I12: ='Athens Daily - Water'!S17 -> 1419.5
A13: FSHK | B13: 12 | C13: 9 | D13: 2020 | E13: ='Athens Daily - EL'!AL19 -> 4875 | G13: ='Athens Daily - Gas'!BI20 -> 62390.4 | I13: ='Athens Daily - Water'!S18 -> 1431
... A30: FSHK | B30: 29 | C30: 9 | D30: 2020 | E30: ='Athens Daily - EL'!AL36 -> 4324 | G30: ='Athens Daily - Gas'!BI37 -> 62486.4 | I30: ='Athens Daily - Water'!S35 -> 1581
A31: FSHK | B31: 30 | C31: 9 | D31: 2020 | E31: ='Athens Daily - EL'!AL37 -> 4127 | G31: ='Athens Daily - Gas'!BI38 -> 65222.4 | I31: ='Athens Daily - Water'!S37 -> 0

Sheet Athens Daily - EL
C1: FSH | E1: FSH | G1: FSH | J1: FSH | L1: FSH | N1: FSH & FSP | Q1: FSH & FSP | T1: FSH & FSP | W1: FSH & FSP | Z1: FSP | AB1: FSP | AD1: FSP | AF1: FSP | AH1: FSP
C2: HOT Normal and Essential power for linen chute(9/F-45/F), HOT water pump at 8/F, Podium dimmer supply(P1-P6), MVAC system(B1/F-B2/F), Bus station BPTT supply. | E2: HOT Normal Power for Guest rooms supply (9/F-45/F), MVAC system (2/F & 46/F), P&D system(46/F) Podium MVAC system (P1/F-P6/F) | G2: P5 Pool Plant, Laundry (hotel 70%,Place 30%), 9/F - 28/F public area, 29/F 46/F Public area Podium normal power supply for water feature(G/F), Chiller WCC-01(B2/F)(FSH 50%, FSP 50%) | J2: Podium normal power for Administration office(P5/F & P6/F), P&D system supply(B2/F), Planter lighting supply(Open Space), Kitchen public supply(B1/F, P1/F, P2/F, P3/F, P4/F & P6/F), BMS room supply(B1/F), Security room supply(G/F), Computer & PABX room | L2: Podium normal power supply for Public supply(P1/F - P6/F), Kitchen(B1/F, P1/F, P2/F, P3/F, P4/F & P6/F), P&D system supply(B1/F), Refuse room supply(G/F), Gas boiler supply(B2/F) and MVAC system supply(P1/F-P6/F). | N2: Podium normal power supply for main P&D system supply(B1/F), MVAC chilled water pump(B1/F) Chiller WCC-02(B2/F) (FSH 50%, FSP 50%) | Q2: Chiller # 3 (FSH 50%, FSP 50%) | T2: Chiller # 4 (FSH 50%, FSP 50%) | W2: Chiller # 5 (FSH 50%, FSP 50%) | Z2: SHT normal power for Guest rooms supply (11/F-23/F). | AB2: SHT normal power for Guest rooms supply (25/F-57/F). | AD2: SHT Essential Power for Public Power supply, F.S. Pump (9/F, 57/F & 39/F), Podium F.S. pump(P1M), Lift LT/S1-LT/S7(LM/F), Lift LT/S8-S9(59/F) and Lift LT/S10(8/F). | AF2: SHT normal power for Guest rooms supply (25/F-57/F). | AH2: SHT normal power for MVAC System(8/F & 40/F), Public supply (8-R/F), P&D system(40/F & 60/F), swimming pool(57/F), SWB 3&4(40/F)
C3: 5065546 | E3: 5065547 | G3: 5008272 | J3: 5065548 | L3: 5465545 | N3: 5008273 | Q3: 5018351 | T3: 5018354 | W3: 5018350 | Z3: 5065543 | AB3: 5065544 | AD3: 5065541 | AF3: 5065542 | AH3: 5065540 | AK3: Daily Total consumption
C4: TXW1 | E4: TXW4 | G4: TXW2 | J4: TXC2 | L4: TXC1 | N4: TXW3 | Q4: TXN1 | T4: TXN2 | W4: TXN3 | Z4: TXN4 | AB4: TXE1 | AD4: TXE2 | AF4: TXE3 | AH4: TXE4
A5: Tariff Type | C5: MD-LV | E5: MD-LV | G5: MD-LV | J5: MD-LV | L5: MD-LV | N5: MD-LV | Q5: Non-Residential | T5: Non-Residential | W5: Non-Residential | Z5: MD-LV | AB5: MD-LV | AD5: MD-LV | AF5: MD-LV | AH5: MD-LV
A6: Date | C6: Reading Kwh | D6: Differecne Kwh | E6: Reading Kwh | F6: Differecne Kwh | G6: Reading Kwh | H6: Differecne Kwh | I6: FSH 50% / FSP 50% | J6: Reading Kwh | K6: Differecne Kwh | L6: Reading Kwh | M6: Differecne Kwh | N6: Reading Kwh | O6: Differecne Kwh | P6: FSH 50% / FSP 50% | Q6: Reading Kwh | R6: Differecne Kwh | S6: FSH 50% / FSP 50% | T6: Reading Kwh | U6: Differecne Kwh | V6: FSH 50% / FSP 50% | W6: Reading Kwh | X6: Differecne Kwh | Y6: FSH 50% / FSP 50% | Z6: Reading Kwh | AA6: Differecne Kwh | AB6: Reading Kwh | AC6: Differecne Kwh | AD6: Reading Kwh | AE6: Differecne Kwh | AF6: Reading Kwh | AG6: Differecne Kwh | AH6: Reading Kwh | AI6: Differecne Kwh | AK6: FSH | AL6: FSP
A7: 44135 | C7: 29805 | E7: 45475 | G7: 794369 | J7: 42175 | L7: 65994 | N7: 778213 | Q7: 117549 | T7: 64311 | W7: 128275 | Z7: 11481 | AB7: 22861 | AD7: 42225 | AF7: 23284 | AH7: 112404
A8: 44136 | C8: 30182 | D8: =(C8-C7)*10 -> 3770 | E8: 46104 | F8: =(E8-E7)*10 -> 6290 | G8: 794700 | H8: =(G8-G7)*10 -> 3310 | I8: =H8*50% -> 1655 | J8: 42759 | K8: =(J8-J7)*10 -> 5840 | L8: 66920 | M8: =(L8-L7)*10 -> 9260 | N8: 778618 | O8: =(N8-N7)*10 -> 4050 | P8: =O8*50% -> 2025 | Q8: 117851 | R8: =(Q8-Q7)*10 -> 3020 | S8: =R8*50% -> 1510 | T8: 64313 | U8: =(T8-T7)*10 -> 20 | V8: =U8*50% -> 10 | W8: 129276 | X8: =(W8-W7)*10 -> 10010 | Y8: =X8*50% -> 5005 | Z8: 11587 | AA8: =Z8-Z7 -> 106 | AB8: 23059 | AC8: =AB8-AB7 -> 198 | AD8: 42577 | AE8: =AD8-AD7 -> 352 | AF8: 23489 | AG8: =AF8-AF7 -> 205 | AH8: 113324 | AI8: =AH8-AH7 -> 920 | AK8: =SUM(D8,F8,I8,K8,M8,P8,S8,V8,Y8) -> 35365 | AL8: =SUM(P8,S8,V8,Y8,AA8,AC8,AE8,AG8,AI8) -> 10331
A9: 44137 | C9: 30540 | D9: =(C9-C8)*10 -> 3580 | E9: 46692 | F9: =(E9-E8)*10 -> 5880 | G9: 795033 | H9: =(G9-G8)*10 -> 3330 | I9: =H9*50% -> 1665 | J9: 43289 | K9: =(J9-J8)*10 -> 5300 | L9: 67787 | M9: =(L9-L8)*10 -> 8670 | N9: 779004 | O9: =(N9-N8)*10 -> 3860 | P9: =O9*50% -> 1930 | Q9: 118272 | R9: =(Q9-Q8)*10 -> 4210 | S9: =R9*50% -> 2105 | T9: 64315 | U9: =(T9-T8)*10 -> 20 | V9: =U9*50% -> 10 | W9: 130170 | X9: =W9-W8 -> 894 | Y9: =X9*50% -> 447 | Z9: 11677 | AA9: =Z9-Z8 -> 90 | AB9: 23256 | AC9: =AB9-AB8 -> 197 | AD9: 42947 | AE9: =AD9-AD8 -> 370 | AF9: 23690 | AG9: =AF9-AF8 -> 201 | AH9: 114246 | AI9: =AH9-AH8 -> 922 | AK9: =SUM(D9,F9,I9,K9,M9,P9,S9,V9,Y9) -> 29587 | AL9: =SUM(P9,S9,V9,Y9,AA9,AC9,AE9,AG9,AI9) -> 6272
A10: 44138 | C10: 30887 | D10: =(C10-C9)*10 -> 3470 | E10: 47266 | F10: =(E10-E9)*10 -> 5740 | G10: 795356 | H10: =(G10-G9)*10 -> 3230 | I10: =H10*50% -> 1615 | J10: 43849 | K10: =(J10-J9)*10 -> 5600 | L10: 68702 | M10: =(L10-L9)*10 -> 9150 | N10: 779405 | O10: =(N10-N9)*10 -> 4010 | P10: =O10*50% -> 2005 | Q10: 118584 | R10: =(Q10-Q9)*10 -> 3120 | S10: =R10*50% -> 1560 | T10: 64318 | U10: =(T10-T9)*10 -> 30 | V10: =U10*50% -> 15 | W10: 131066 | X10: =W10-W9 -> 896 | Y10: =X10*50% -> 448 | Z10: 11772 | AA10: =Z10-Z9 -> 95 | AB10: 23463 | AC10: =AB10-AB9 -> 207 | AD10: 43322 | AE10: =AD10-AD9 -> 375 | AF10: 23888 | AG10: =AF10-AF9 -> 198 | AH10: 115174 | AI10: =AH10-AH9 -> 928 | AK10: =SUM(D10,F10,I10,K10,M10,P10,S10,V10,Y10) -> 29603 | AL10: =SUM(P10,S10,V10,Y10,AA10,AC10,AE10,AG10,AI10) -> 5831
A11: 44139 | C11: 31232 | D11: =(C11-C10)*10 -> 3450 | E11: 47824 | F11: =(E11-E10)*10 -> 5580 | G11: 795707 | H11: =(G11-G10)*10 -> 3510 | I11: =H11*50% -> 1755 | J11: 44411 | K11: =(J11-J10)*10 -> 5620 | L11: 69588 | M11: =(L11-L10)*10 -> 8860 | N11: 779823 | O11: =(N11-N10)*10 -> 4180 | P11: =O11*50% -> 2090 | Q11: 119603 | R11: =(Q11-Q10)*10 -> 10190 | S11: =R11*50% -> 5095 | T11: 64320 | U11: =(T11-T10)*10 -> 20 | V11: =U11*50% -> 10 | W11: 131073 | X11: =W11-W10 -> 7 | Y11: =X11*50% -> 3.5 | Z11: 11869 | AA11: =Z11-Z10 -> 97 | AB11: 23678 | AC11: =AB11-AB10 -> 215 | AD11: 43700 | AE11: =AD11-AD10 -> 378 | AF11: 24093 | AG11: =AF11-AF10 -> 205 | AH11: 116113 | AI11: =AH11-AH10 -> 939 | AK11: =SUM(D11,F11,I11,K11,M11,P11,S11,V11,Y11) -> 32463.5 | AL11: =SUM(P11,S11,V11,Y11,AA11,AC11,AE11,AG11,AI11) -> 9032.5
A12: 44140 | C12: 31571 | D12: =(C12-C11)*10 -> 3390 | E12: 48366 | F12: =(E12-E11)*10 -> 5420 | G12: 796055 | H12: =(G12-G11)*10 -> 3480 | I12: =H12*50% -> 1740 | J12: 44963 | K12: =(J12-J11)*10 -> 5520 | L12: 70469 | M12: =(L12-L11)*10 -> 8810 | N12: 780267 | O12: =(N12-N11)*10 -> 4440 | P12: =O12*50% -> 2220 | Q12: 120592 | R12: =(Q12-Q11)*10 -> 9890 | S12: =R12*50% -> 4945 | T12: 64322 | U12: =(T12-T11)*10 -> 20 | V12: =U12*50% -> 10 | W12: 131081 | X12: =W12-W11 -> 8 | Y12: =X12*50% -> 4 | Z12: 11960 | AA12: =Z12-Z11 -> 91 | AB12: 23890 | AC12: =AB12-AB11 -> 212 | AD12: 44071 | AE12: =AD12-AD11 -> 371 | AF12: 24296 | AG12: =AF12-AF11 -> 203 | AH12: 117033 | AI12: =AH12-AH11 -> 920 | AK12: =SUM(D12,F12,I12,K12,M12,P12,S12,V12,Y12) -> 32059 | AL12: =SUM(P12,S12,V12,Y12,AA12,AC12,AE12,AG12,AI12) -> 8976
A13: 44141 | C13: 31921 | D13: =(C13-C12)*10 -> 3500 | E13: 48923 | F13: =(E13-E12)*10 -> 5570 | G13: 796405 | H13: =(G13-G12)*10 -> 3500 | I13: =H13*50% -> 1750 | J13: 45532 | K13: =(J13-J12)*10 -> 5690 | L13: 71368 | M13: =(L13-L12)*10 -> 8990 | N13: 780757 | O13: =(N13-N12)*10 -> 4900 | P13: =O13*50% -> 2450 | Q13: 121424 | R13: =(Q13-Q12)*10 -> 8320 | S13: =R13*50% -> 4160 | T13: 64324 | U13: =(T13-T12)*10 -> 20 | V13: =U13*50% -> 10 | W13: 131505 | X13: =W13-W12 -> 424 | Y13: =X13*50% -> 212 | Z13: 12059 | AA13: =Z13-Z12 -> 99 | AB13: 24101 | AC13: =AB13-AB12 -> 211 | AD13: 44447 | AE13: =AD13-AD12 -> 376 | AF13: 24500 | AG13: =AF13-AF12 -> 204 | AH13: 117979 | AI13: =AH13-AH12 -> 946 | AK13: =SUM(D13,F13,I13,K13,M13,P13,S13,V13,Y13) -> 32332 | AL13: =SUM(P13,S13,V13,Y13,AA13,AC13,AE13,AG13,AI13) -> 8668
A14: 44142 | C14: 32282 | D14: =(C14-C13)*10 -> 3610 | E14: 49507 | F14: =(E14-E13)*10 -> 5840 | G14: 796770 | H14: =(G14-G13)*10 -> 3650 | I14: =H14*50% -> 1825 | J14: 46085 | K14: =(J14-J13)*10 -> 5530 | L14: 72281 | M14: =(L14-L13)*10 -> 9130 | N14: 781257 | O14: =(N14-N13)*10 -> 5000 | P14: =O14*50% -> 2500 | Q14: 122236 | R14: =(Q14-Q13)*10 -> 8120 | S14: =R14*50% -> 4060 | T14: 64783 | U14: =(T14-T13)*10 -> 4590 | V14: =U14*50% -> 2295 | W14: 131566 | X14: =W14-W13 -> 61 | Y14: =X14*50% -> 30.5 | Z14: 12158 | AA14: =Z14-Z13 -> 99 | AB14: 24298 | AC14: =AB14-AB13 -> 197 | AD14: 44817 | AE14: =AD14-AD13 -> 370 | AF14: 24695 | AG14: =AF14-AF13 -> 195 | AH14: 118919 | AI14: =AH14-AH13 -> 940 | AK14: =SUM(D14,F14,I14,K14,M14,P14,S14,V14,Y14) -> 34820.5 | AL14: =SUM(P14,S14,V14,Y14,AA14,AC14,AE14,AG14,AI14) -> 10686.5
A15: 44143 | C15: 32640 | D15: =(C15-C14)*10 -> 3580 | E15: 50127 | F15: =(E15-E14)*10 -> 6200 | G15: 797125 | H15: =(G15-G14)*10 -> 3550 | I15: =H15*50% -> 1775 | J15: 46675 | K15: =(J15-J14)*10 -> 5900 | L15: 73224 | M15: =(L15-L14)*10 -> 9430 | N15: 781717 | O15: =(N15-N14)*10 -> 4600 | P15: =O15*50% -> 2300 | Q15: 123134 | R15: =(Q15-Q14)*10 -> 8980 | S15: =R15*50% -> 4490 | T15: 65151 | U15: =(T15-T14)*10 -> 3680 | V15: =U15*50% -> 1840 | W15: 131599 | X15: =W15-W14 -> 33 | Y15: =X15*50% -> 16.5 | Z15: 12260 | AA15: =Z15-Z14 -> 102 | AB15: 24490 | AC15: =AB15-AB14 -> 192 | AD15: 45180 | AE15: =AD15-AD14 -> 363 | AF15: 24890 | AG15: =AF15-AF14 -> 195 | AH15: 119854 | AI15: =AH15-AH14 -> 935 | AK15: =SUM(D15,F15,I15,K15,M15,P15,S15,V15,Y15) -> 35531.5 | AL15: =SUM(P15,S15,V15,Y15,AA15,AC15,AE15,AG15,AI15) -> 10433.5
A16: 44144 | C16: 32928 | D16: =(C16-C15)*10 -> 2880 | E16: 50685 | F16: =(E16-E15)*10 -> 5580 | G16: 797479 | H16: =(G16-G15)*10 -> 3540 | I16: =H16*50% -> 1770 | J16: 47230 | K16: =(J16-J15)*10 -> 5550 | L16: 74100 | M16: =(L16-L15)*10 -> 8760 | N16: 782161 | O16: =(N16-N15)*10 -> 4440 | P16: =O16*50% -> 2220 | Q16: 123678 | R16: =(Q16-Q15)*10 -> 5440 | S16: =R16*50% -> 2720 | T16: 65178 | U16: =(T16-T15)*10 -> 270 | V16: =U16*50% -> 135 | W16: 132047 | X16: =W16-W15 -> 448 | Y16: =X16*50% -> 224 | Z16: 12349 | AA16: =Z16-Z15 -> 89 | AB16: 24687 | AC16: =AB16-AB15 -> 197 | AD16: 45544 | AE16: =AD16-AD15 -> 364 | AF16: 25079 | AG16: =AF16-AF15 -> 189 | AH16: 120759 | AI16: =AH16-AH15 -> 905 | AK16: =SUM(D16,F16,I16,K16,M16,P16,S16,V16,Y16) -> 29839 | AL16: =SUM(P16,S16,V16,Y16,AA16,AC16,AE16,AG16,AI16) -> 7043
A17: 44145 | C17: 33336 | D17: =(C17-C16)*10 -> 4080 | E17: 51276 | F17: =(E17-E16)*10 -> 5910 | G17: 797778 | H17: =(G17-G16)*10 -> 2990 | I17: =H17*50% -> 1495 | J17: 47796 | K17: =(J17-J16)*10 -> 5660 | L17: 74998 | M17: =(L17-L16)*10 -> 8980 | N17: 782631 | O17: =(N17-N16)*10 -> 4700 | P17: =O17*50% -> 2350 | Q17: 123680 | R17: =(Q17-Q16)*10 -> 20 | S17: =R17*50% -> 10 | T17: 65180 | U17: =(T17-T16)*10 -> 20 | V17: =U17*50% -> 10 | W17: 133013 | X17: =W17-W16 -> 966 | Y17: =X17*50% -> 483 | Z17: 12445 | AA17: =Z17-Z16 -> 96 | AB17: 24894 | AC17: =AB17-AB16 -> 207 | AD17: 45920 | AE17: =AD17-AD16 -> 376 | AF17: 25284 | AG17: =AF17-AF16 -> 205 | AH17: 121676 | AI17: =AH17-AH16 -> 917 | AK17: =SUM(D17,F17,I17,K17,M17,P17,S17,V17,Y17) -> 28978 | AL17: =SUM(P17,S17,V17,Y17,AA17,AC17,AE17,AG17,AI17) -> 4654
A18: 44146 | C18: 33671 | D18: =(C18-C17)*10 -> 3350 | E18: 51836 | F18: =(E18-E17)*10 -> 5600 | G18: 798057 | H18: =(G18-G17)*10 -> 2790 | I18: =H18*50% -> 1395 | J18: 48384 | K18: =(J18-J17)*10 -> 5880 | L18: 75933 | M18: =(L18-L17)*10 -> 9350 | N18: 783068 | O18: =(N18-N17)*10 -> 4370 | P18: =O18*50% -> 2185 | Q18: 123682 | R18: =(Q18-Q17)*10 -> 20 | S18: =R18*50% -> 10 | T18: 65295 | U18: =(T18-T17)*10 -> 1150 | V18: =U18*50% -> 575 | W18: 133936 | X18: =W18-W17 -> 923 | Y18: =X18*50% -> 461.5 | Z18: 12542 | AA18: =Z18-Z17 -> 97 | AB18: 25111 | AC18: =AB18-AB17 -> 217 | AD18: 46294 | AE18: =AD18-AD17 -> 374 | AF18: 25493 | AG18: =AF18-AF17 -> 209 | AH18: 122612 | AI18: =AH18-AH17 -> 936 | AK18: =SUM(D18,F18,I18,K18,M18,P18,S18,V18,Y18) -> 28806.5 | AL18: =SUM(P18,S18,V18,Y18,AA18,AC18,AE18,AG18,AI18) -> 5064.5
A19: 44147 | C19: 34013 | D19: =(C19-C18)*10 -> 3420 | E19: 52394 | F19: =(E19-E18)*10 -> 5580 | G19: 798337 | H19: =(G19-G18)*10 -> 2800 | I19: =H19*50% -> 1400 | J19: 48944 | K19: =(J19-J18)*10 -> 5600 | L19: 76837 | M19: =(L19-L18)*10 -> 9040 | N19: 783519 | O19: =(N19-N18)*10 -> 4510 | P19: =O19*50% -> 2255 | Q19: 123684 | R19: =(Q19-Q18)*10 -> 20 | S19: =R19*50% -> 10 | T19: 65297 | U19: =(T19-T18)*10 -> 20 | V19: =U19*50% -> 10 | W19: 134928 | X19: =W19-W18 -> 992 | Y19: =X19*50% -> 496 | Z19: 12639 | AA19: =Z19-Z18 -> 97 | AB19: 25327 | AC19: =AB19-AB18 -> 216 | AD19: 46664 | AE19: =AD19-AD18 -> 370 | AF19: 25696 | AG19: =AF19-AF18 -> 203 | AH19: 123830 | AI19: =AH19-AH18 -> 1218 | AK19: =SUM(D19,F19,I19,K19,M19,P19,S19,V19,Y19) -> 27811 | AL19: =SUM(P19,S19,V19,Y19,AA19,AC19,AE19,AG19,AI19) -> 4875
A20: 44148 | C20: 34359 | D20: =(C20-C19)*10 -> 3460 | E20: 52947 | F20: =(E20-E19)*10 -> 5530 | G20: 798630 | H20: =(G20-G19)*10 -> 2930 | I20: =H20*50% -> 1465 | J20: 49514 | K20: =(J20-J19)*10 -> 5700 | L20: 77740 | M20: =(L20-L19)*10 -> 9030 | N20: 783975 | O20: =(N20-N19)*10 -> 4560 | P20: =O20*50% -> 2280 | Q20: 123686 | R20: =(Q20-Q19)*10 -> 20 | S20: =R20*50% -> 10 | T20: 65299 | U20: =(T20-T19)*10 -> 20 | V20: =U20*50% -> 10 | W20: 135896 | X20: =W20-W19 -> 968 | Y20: =X20*50% -> 484 | Z20: 12730 | AA20: =Z20-Z19 -> 91 | AB20: 25539 | AC20: =AB20-AB19 -> 212 | AD20: 47032 | AE20: =AD20-AD19 -> 368 | AF20: 25895 | AG20: =AF20-AF19 -> 199 | AH20: 124446 | AI20: =AH20-AH19 -> 616 | AK20: =SUM(D20,F20,I20,K20,M20,P20,S20,V20,Y20) -> 27969 | AL20: =SUM(P20,S20,V20,Y20,AA20,AC20,AE20,AG20,AI20) -> 4270
... A37: 44165 | C37: 40471 | D37: =(C37-C36)*10 -> 3520 | E37: 63494 | F37: =(E37-E36)*10 -> 6880 | G37: 807551 | H37: =(G37-G36)*10 -> 8560 | I37: =H37*50% -> 4280 | J37: 59521 | K37: =(J37-J36)*10 -> 5610 | L37: 93510 | M37: =(L37-L36)*10 -> 8860 | N37: 792045 | O37: =(N37-N36)*10 -> 4440 | P37: =O37*50% -> 2220 | Q37: 129880 | R37: =(Q37-Q36)*10 -> 20 | S37: =R37*50% -> 10 | T37: 70143 | U37: =(T37-T36)*10 -> 30 | V37: =U37*50% -> 15 | W37: 143258 | X37: =W37-W36 -> 232 | Y37: =X37*50% -> 116 | Z37: 14454 | AA37: =Z37-Z36 -> 96 | AB37: 29064 | AC37: =AB37-AB36 -> 212 | AD37: 53161 | AE37: =AD37-AD36 -> 359 | AF37: 29188 | AG37: =AF37-AF36 -> 194 | AH37: 140163 | AI37: =AH37-AH36 -> 905 | AK37: =SUM(D37,F37,I37,K37,M37,P37,S37,V37,Y37) -> 31511 | AL37: =SUM(P37,S37,V37,Y37,AA37,AC37,AE37,AG37,AI37) -> 4127
C39: 17521 | D39: =SUM(D8:D37) -> 106660 | F39: =SUM(F8:F37) -> 180190 | H39: =SUM(H8:H37) -> 131820 | K39: =SUM(K8:K37) -> 173460 | M39: =SUM(M8:M37) -> 275160 | O39: =SUM(O8:O37) -> 138320 | R39: =SUM(R8:R37) -> 123310 | U39: =SUM(U8:U37) -> 58320 | X39: =SUM(X8:X37) -> 23992 | AA39: =SUM(AA8:AA37) -> 2973 | AC39: =SUM(AC8:AC37) -> 6203 | AE39: =SUM(AE8:AE37) -> 10936 | AG39: =SUM(AG8:AG37) -> 5904 | AI39: =SUM(AI8:AI37) -> 27759

Sheet Athens Daily - Water
C1: FSH | E1: FSH | G1: FSH | I1: FSH | K1: FSH & FSP | O1: FSP
C2: Hotel & podium Fresh Water | E2: Food & Beverage Outlets | G2: Fountains | I2: Swimming Pool | K2: Laundry (FSH 55% : FSP 45%) | O2: Place - Guest Floor Fresh Water
C3: M16601852 | E3: M118410300 | G3: M16449102 | I3: M9192527 | K3: M16601455 | O3: M16601818 | R3: Daily Total consumption
A4: Tariff Type
A5: Date | C5: Reading | D5: Differecne m3 | E5: Reading | F5: Differecne m3 | G5: Reading | H5: Differecne m3 | I5: Reading | J5: Differecne m3 | K5: Reading | L5: Differecne m3 | M5: FSH | N5: FSP | O5: Reading | P5: Differecne m3
A6: 44135 | C6: 180882 | D6: =(C6-C4)*10 -> 1808820 | E6: 164390 | F6: =(E6-E4)*10 -> 1643900 | G6: 5471.1867 | H6: =(G6-G4)*10 -> 54711.867 | I6: 11022 | J6: =(I6-I4)*10 -> 110220 | K6: 122848 | L6: =(K6-K4)*10 -> 1228480 | M6: =L6*55% -> 675664 | N6: =L6*45% -> 552816 | O6: 89935 | R6: =SUM(D6,F6,M69,H6) -> 3507431.9 | S6: =SUM(N6,P6) -> 552816
A7: 44136 | C7: 181086 | D7: =(C7-C6)*10 -> 2040 | E7: 164463 | F7: =(E7-E6)*10 -> 730 | G7: 5474.8145 | H7: =(G7-G6)*10 -> 36.278 | I7: 11036 | J7: =(I7-I6)*10 -> 140 | K7: 123005 | L7: =(K7-K6)*10 -> 1570 | M7: =L7*55% -> 863.5 | N7: =L7*45% -> 706.5 | O7: 90020 | P7: =(O7-O6)*10 -> 850 | R7: =SUM(D7,F7,J7,M7,H7) -> 3809.778 | S7: =SUM(N7,P7) -> 1556.5
A8: 44137 | C8: 181282 | D8: =(C8-C7)*10 -> 1960 | E8: 164719 | F8: =(E8-E7)*10 -> 2560 | G8: 5478.7173 | H8: =(G8-G7)*10 -> 39.028 | I8: 11048 | J8: =(I8-I7)*10 -> 120 | K8: 123149 | L8: =(K8-K7)*10 -> 1440 | M8: =L8*55% -> 792 | N8: =L8*45% -> 648 | O8: 90105 | P8: =(O8-O7)*10 -> 850 | R8: =SUM(D8,F8,J8,M8,H8) -> 5471.028 | S8: =SUM(N8,P8) -> 1498
A9: 44138 | C9: 181407 | D9: =(C9-C8)*10 -> 1250 | E9: 164978 | F9: =(E9-E8)*10 -> 2590 | G9: 5482.104 | H9: =(G9-G8)*10 -> 33.867 | I9: 11067 | J9: =(I9-I8)*10 -> 190 | K9: 123270 | L9: =(K9-K8)*10 -> 1210 | M9: =L9*55% -> 665.5 | N9: =L9*45% -> 544.5 | O9: 90196 | P9: =(O9-O8)*10 -> 910 | R9: =SUM(D9,F9,J9,M9,H9) -> 4729.367 | S9: =SUM(N9,P9) -> 1454.5
A10: 44139 | C10: 181513 | D10: =(C10-C9)*10 -> 1060 | E10: 165217 | F10: =(E10-E9)*10 -> 2390 | G10: 5485.9971 | H10: =(G10-G9)*10 -> 38.931 | I10: 11078 | J10: =(I10-I9)*10 -> 110 | K10: 123394 | L10: =(K10-K9)*10 -> 1240 | M10: =L10*55% -> 682 | N10: =L10*45% -> 558 | O10: 90283 | P10: =(O10-O9)*10 -> 870 | R10: =SUM(D10,F10,J10,M10,H10) -> 4280.931 | S10: =SUM(N10,P10) -> 1428
A11: 44140 | C11: 181628 | D11: =(C11-C10)*10 -> 1150 | E11: 165448 | F11: =(E11-E10)*10 -> 2310 | G11: 5488.88 | H11: =(G11-G10)*10 -> 28.829 | I11: 11096 | J11: =(I11-I10)*10 -> 180 | K11: 123508 | L11: =(K11-K10)*10 -> 1140 | M11: =L11*55% -> 627 | N11: =L11*45% -> 513 | O11: 90363 | P11: =(O11-O10)*10 -> 800 | R11: =SUM(D11,F11,J11,M11,H11) -> 4295.829 | S11: =SUM(N11,P11) -> 1313
A12: 44141 | C12: 181732 | D12: =(C12-C11)*10 -> 1040 | E12: 165674 | F12: =(E12-E11)*10 -> 2260 | G12: 5491.5818 | H12: =(G12-G11)*10 -> 27.018 | I12: 11113 | J12: =(I12-I11)*10 -> 170 | K12: 123639 | L12: =(K12-K11)*10 -> 1310 | M12: =L12*55% -> 720.5 | N12: =L12*45% -> 589.5 | O12: 90453 | P12: =(O12-O11)*10 -> 900 | R12: =SUM(D12,F12,J12,M12,H12) -> 4217.518 | S12: =SUM(N12,P12) -> 1489.5
A13: 44142 | C13: 181841 | D13: =(C13-C12)*10 -> 1090 | E13: 165903 | F13: =(E13-E12)*10 -> 2290 | G13: 5494.6118 | H13: =(G13-G12)*10 -> 30.3 | I13: 11144 | J13: =(I13-I12)*10 -> 310 | K13: 123758 | L13: =(K13-K12)*10 -> 1190 | M13: =L13*55% -> 654.5 | N13: =L13*45% -> 535.5 | O13: 90550 | P13: =(O13-O12)*10 -> 970 | R13: =SUM(D13,F13,J13,M13,H13) -> 4374.8 | S13: =SUM(N13,P13) -> 1505.5
A14: 44143 | C14: 181989 | D14: =(C14-C13)*10 -> 1480 | E14: 166169 | F14: =(E14-E13)*10 -> 2660 | G14: 5497.8228 | H14: =(G14-G13)*10 -> 32.11 | I14: 11171 | J14: =(I14-I13)*10 -> 270 | K14: 123896 | L14: =(K14-K13)*10 -> 1380 | M14: =L14*55% -> 759 | N14: =L14*45% -> 621 | O14: 90639 | P14: =(O14-O13)*10 -> 890 | R14: =SUM(D14,F14,J14,M14,H14) -> 5201.11 | S14: =SUM(N14,P14) -> 1511
A15: 44144 | C15: 182113 | D15: =(C15-C14)*10 -> 1240 | E15: 166437 | F15: =(E15-E14)*10 -> 2680 | G15: 5501.3454 | H15: =(G15-G14)*10 -> 35.226 | I15: 11198 | J15: =(I15-I14)*10 -> 270 | K15: 124012 | L15: =(K15-K14)*10 -> 1160 | M15: =L15*55% -> 638 | N15: =L15*45% -> 522 | O15: 90723 | P15: =(O15-O14)*10 -> 840 | R15: =SUM(D15,F15,J15,M15,H15) -> 4863.226 | S15: =SUM(N15,P15) -> 1362
A16: 44145 | C16: 182233 | D16: =(C16-C15)*10 -> 1200 | E16: 166665 | F16: =(E16-E15)*10 -> 2280 | G16: 5504.9305 | H16: =(G16-G15)*10 -> 35.851 | I16: 11204 | J16: =(I16-I15)*10 -> 60 | K16: 124127 | L16: =(K16-K15)*10 -> 1150 | M16: =L16*55% -> 632.5 | N16: =L16*45% -> 517.5 | O16: 90805 | P16: =(O16-O15)*10 -> 820 | R16: =SUM(D16,F16,J16,M16,H16) -> 4208.351 | S16: =SUM(N16,P16) -> 1337.5
A17: 44146 | C17: 182349 | D17: =(C17-C16)*10 -> 1160 | E17: 166913 | F17: =(E17-E16)*10 -> 2480 | G17: 5507.9392 | H17: =(G17-G16)*10 -> 30.087 | I17: 11224 | J17: =(I17-I16)*10 -> 200 | K17: 124238 | L17: =(K17-K16)*10 -> 1110 | M17: =L17*55% -> 610.5 | N17: =L17*45% -> 499.5 | O17: 90897 | P17: =(O17-O16)*10 -> 920 | R17: =SUM(D17,F17,J17,M17,H17) -> 4480.587 | S17: =SUM(N17,P17) -> 1419.5
A18: 44147 | C18: 182502 | D18: =(C18-C17)*10 -> 1530 | E18: 167169 | F18: =(E18-E17)*10 -> 2560 | G18: 5535.8421 | H18: =(G18-G17)*10 -> 279.029 | I18: 11227 | J18: =(I18-I17)*10 -> 30 | K18: 124356 | L18: =(K18-K17)*10 -> 1180 | M18: =L18*55% -> 649 | N18: =L18*45% -> 531 | O18: 90987 | P18: =(O18-O17)*10 -> 900 | R18: =SUM(D18,F18,J18,M18,H18) -> 5048.029 | S18: =SUM(N18,P18) -> 1431
... A36: 44165 | C36: 185208 | D36: =(C36-C35)*10 -> 1560 | E36: 171979 | F36: =(E36-E35)*10 -> 2540 | G36: 5716.9 | H36: =(G36-G35)*10 -> 30.915 | I36: 11581 | J36: =(I36-I35)*10 -> 200 | K36: 126555 | L36: =(K36-K35)*10 -> 1540 | M36: =L36*55% -> 847 | N36: =L36*45% -> 693 | O36: 92677 | P36: =(O36-O35)*10 -> 970 | R36: =SUM(D36,F36,J36,M36,H36) -> 5177.915 | S36: =SUM(N36,P36) -> 1663
D38: =SUM(D7:D37) -> 43260 | F38: =SUM(F7:F37) -> 75890 | H38: =SUM(H7:H37) -> 2457.133 | J38: =SUM(J7:J37) -> 5590 | L38: =SUM(L7:L37) -> 37070 | P38: =SUM(P7:P37) -> 27420

Sheet Athens Daily - Gas
C1: FSH & FSP | G1: FSH | I1: FSH | K1: FSH | M1: FSH | O1: FSH | Q1: FSH | S1: FSH | U1: FSH | W1: FSH | Y1: FSH | AA1: FSH | AC1: FSH | AE1: FSH | AG1: FSH | AI1: FSH | AK1: FSH | AM1: FSP | AO1: FSP | AQ1: FSP | AS1: FSP | AU1: FSP | AW1: FSP | AY1: FSP | BA1: FSP | BC1: FSP | BE1: FSP
C2: B2/F Steam Boiler Room | G2: B1/F Main Kitchen | I2: P1/F Lobby Lounge | K2: P2/F Grand Ball Room | M2: P3 Steward | O2: P4/F Chinese Restaurant | Q2: P4/F Junior Ball Room | S2: P5/F Staff Dining | U2: P6/F Pool side bar pantry | W2: P6/F French Restaurant | Y2: P5/F Condensing Boiler Room | AA2: P5/F Filtration Plan Room | AC2: L8/F Plant Room | AE2: L46/F Plant Room | AG2: L46/F Plant Room | AI2: L46/F Plant Room | AK2: L46/F Plant Room | AM2: SHT 8/F Plant Room | AO2: SHT 40/F Plant Room | AQ2: SHT 57/F Condensing Boiler Room | AS2: SHT 57/F Condensing Boiler Room | AU2: SHT 60/F - Room 6023 ( Penhouse 1 ) | AW2: SHT 60/F - Room 6038 ( Penhouse 2 ) | AY2: L40/F Plant Room | BA2: L40/F Plant Room | BC2: L57/F Plant Room | BE2: L57/F Plant Room
C3: Steam Boiler for Hot Water & Laundry ( FSH 60% : FSP 40%) | E3: FSH | F3: FSP | G3: Kitchen | I3: Kitchen | K3: Kitchen | M3: Dish Washing area | O3: Kitchen | Q3: Kitchen | S3: Kitchen | U3: Kitchen | W3: Kitchen | Y3: Condensing Boiler for P6 Swimming Pool & Jacuzzi | AA3: 6/F Patio Spaces heater | AC3: Dehumidifier for Guest Rooms RH Control | AE3: Dehumidifier for Guest Rooms RH Control | AG3: Presidential Room Room 4305 | AI3: New Gas Heat Pump | AK3: New Gas Heat Pump ( Heater ) | AM3: Dehumidifier For Guest Rooms RH Control | AO3: Dehumidifier For Guest Rooms RH Control | AQ3: Condensing Boiler for 59/F Swimming Pool & Jacuzzis | AS3: 59/F Patio Spaces heater | AU3: Gas appliances ( Include Patio Space Heater ) | AW3: Gas appliances ( Include Patio Space Heater ) | AY3: New Gas Heat Pump | BA3: New Gas Heat Pump ( Heater ) | BC3: New Gas Heat Pump | BE3: New Gas Heat Pump ( Heater )
C4: 0234229050 | E4: Ratio | G4: 0234229130 | I4: 0234230090 | K4: 0234229210 | M4: 7092801222 | O4: 0234229460 | Q4: 0234229380 | S4: 0234229540 | U4: 0234229620 | W4: 0234230740 | Y4: 0234229870 | AA4: 0234229790 | AC4: 0234228820 | AE4: 0234228990 | AG4: 0234230820 | AI4: 7105826734 | AK4: 7105825932 | AM4: 0234230170 | AO4: 0234230250 | AQ4: 0234230330 | AS4: 0234230410 | AU4: 0234230580 | AW4: 0234230660 | AY4: 7111912486 | BA4: 7111911842 | BC4: 7111913281 | BE4: 7111912723 | BH4: Daily Total consumption
A5: Gas Meter | C5: 9955475 | E5: 0.6 | F5: 0.4 | G5: 436641 | I5: 436656 | K5: 431271 | M5: 1038664 | O5: 522469 | Q5: 431269 | S5: 436624 | U5: 5399693 | W5: 522607 | Y5: 436606 | AA5: 432481 | AC5: 410677 | AE5: 431229 | AG5: 522557 | AI5: 0333732 | AK5: 0655375 | AM5: 431241 | AO5: 410724 | AQ5: 9313879 | AS5: 4500420S | AU5: 436758 | AW5: 431227 | AY5: 744483 | BA5: 119314 | BC5: 1053229 | BE5: 1053215
A6: Tariff Type
A7: Date | C7: Reading | D7: Differecne MJ | E7: Differecne MJ | F7: Differecne MJ | G7: Reading | H7: Differecne MJ | I7: Reading | J7: Differecne MJ | K7: Reading | L7: Differecne MJ | M7: Reading | N7: Differecne MJ | O7: Reading | P7: Differecne MJ | Q7: Reading | R7: Differecne MJ | S7: Reading | T7: Differecne MJ | U7: Reading | V7: Differecne MJ | W7: Reading | X7: Differecne MJ | Y7: Reading | Z7: Differecne MJ | AA7: Reading | AB7: Differecne MJ | AC7: Reading | AD7: Differecne MJ | AE7: Reading | AF7: Differecne MJ | AG7: Reading | AH7: Differecne MJ | AI7: Reading | AJ7: Differecne MJ | AK7: Reading | AL7: Differecne MJ | AM7: Reading | AN7: Differecne MJ | AO7: Reading | AP7: Differecne MJ | AQ7: Reading | AR7: Differecne MJ | AS7: Reading | AT7: Differecne MJ | AU7: Reading | AV7: Differecne MJ | AW7: Reading | AX7: Differecne MJ | AY7: Reading | AZ7: Differecne MJ | BA7: Reading | BB7: Differecne MJ | BC7: Reading | BD7: Differecne MJ | BE7: Reading | BF7: Differecne MJ | BH7: FSH | BI7: FSP
A8: 44135 | C8: 5566794 | G8: 275933 | I8: 90532 | K8: 255291 | M8: 24387 | O8: 226556 | Q8: 435434 | S8: 698814 | U8: 95388.142 | W8: 78217 | Y8: 1484465 | AA8: 13166 | AC8: 434301 | AE8: 511909 | AG8: 48868 | AI8: 394107 | AK8: 102371 | AM8: 558480 | AO8: 897214 | AQ8: 70227 | AS8: 2204 | AU8: 918 | AW8: 3108 | AY8: 301169 | BA8: 160171 | BC8: 206260 | BE8: 5347
A9: 44136 | C9: 5569014 | D9: =(+C9-+C8)*48 -> 106560 | E9: =D9*0.6 -> 63936 | F9: =D9*0.4 -> 42624 | G9: 275969 | H9: =(+G9-+G8)*48 -> 1728 | I9: 90699 | J9: =(+I9-+I8)*48 -> 8016 | K9: 255299 | L9: =(+K9-+K8)*48 -> 384 | M9: 24390 | N9: =(+M9-+M8)*48 -> 144 | O9: 226747 | P9: =(+O9-+O8)*48 -> 9168 | Q9: 435547 | R9: =(+Q9-+Q8)*48 -> 5424 | S9: 698938 | T9: =(+S9-+S8)*48 -> 5952 | U9: 95412.041 | V9: =(+U9-+U8)*48 -> 1147.152 | W9: 78242 | X9: =(+W9-+W8)*48 -> 1200 | Y9: 1484856 | Z9: =(+Y9-+Y8)*48 -> 18768 | AA9: 13166 | AB9: =(+AA9-+AA8)*48 -> 0 | AC9: 434407 | AD9: =(+AC9-+AC8)*48 -> 5088 | AE9: 511998 | AF9: =(+AE9-+AE8)*48 -> 4272 | AG9: 48872 | AH9: =(+AG9-+AG8)*48 -> 192 | AI9: 394241 | AJ9: =(+AI9-+AI8)*48 -> 6432 | AK9: 102371 | AL9: =(+AK9-+AK8)*48 -> 0 | AM9: 558582 | AN9: =(+AM9-+AM8)*48 -> 4896 | AO9: 897413 | AP9: =(+AO9-+AO8)*48 -> 9552 | AQ9: 70339 | AR9: =(+AQ9-+AQ8)*48 -> 5376 | AS9: 2204 | AT9: =(+AS9-+AS8)*48 -> 0 | AU9: 918 | AV9: =(+AU9-+AU8)*48 -> 0 | AW9: 3108 | AX9: =(+AW9-+AW8)*48 -> 0 | AY9: 301251 | AZ9: =(+AY9-+AY8)*48 -> 3936 | BA9: 160171 | BB9: =(+BA9-+BA8)*48 -> 0 | BC9: 206314 | BD9: =(+BC9-+BC8)*48 -> 2592 | BE9: 5347 | BF9: =(+BE9-+BE8)*48 -> 0 | BH9: =SUM(E9,J9,P9,H9,L9,R9,T9,V9,X9,N9,AB9,Z9,AD9,AF9,AH9,AL9,AJ9) -> 131851.15 | BI9: =SUM(F9,AN9,AP9,AT9,AV9,AX9,AR9,AZ9,BB9,BD9,BF9) -> 68976
A10: 44137 | C10: 5571283 | D10: =(+C10-+C9)*48 -> 108912 | E10: =D10*0.6 -> 65347.2 | F10: =D10*0.4 -> 43564.8 | G10: 276000 | H10: =(+G10-+G9)*48 -> 1488 | I10: 90877 | J10: =(+I10-+I9)*48 -> 8544 | K10: 255302 | L10: =(+K10-+K9)*48 -> 144 | M10: 24394 | N10: =(+M10-+M9)*48 -> 192 | O10: 226944 | P10: =(+O10-+O9)*48 -> 9456 | Q10: 435619 | R10: =(+Q10-+Q9)*48 -> 3456 | S10: 699047 | T10: =(+S10-+S9)*48 -> 5232 | U10: 95435.655 | V10: =(+U10-+U9)*48 -> 1133.472 | W10: 78266 | X10: =(+W10-+W9)*48 -> 1152 | Y10: 1485126 | Z10: =(+Y10-+Y9)*48 -> 12960 | AA10: 13166 | AB10: =(+AA10-+AA9)*48 -> 0 | AC10: 434516 | AD10: =(+AC10-+AC9)*48 -> 5232 | AE10: 512073 | AF10: =(+AE10-+AE9)*48 -> 3600 | AG10: 48878 | AH10: =(+AG10-+AG9)*48 -> 288 | AI10: 394391 | AJ10: =(+AI10-+AI9)*48 -> 7200 | AK10: 102371 | AL10: =(+AK10-+AK9)*48 -> 0 | AM10: 558694 | AN10: =(+AM10-+AM9)*48 -> 5376 | AO10: 897624 | AP10: =(+AO10-+AO9)*48 -> 10128 | AQ10: 70457 | AR10: =(+AQ10-+AQ9)*48 -> 5664 | AS10: 2204 | AT10: =(+AS10-+AS9)*48 -> 0 | AU10: 918 | AV10: =(+AU10-+AU9)*48 -> 0 | AW10: 3108 | AX10: =(+AW10-+AW9)*48 -> 0 | AY10: 301350 | AZ10: =(+AY10-+AY9)*48 -> 4752 | BA10: 160171 | BB10: =(+BA10-+BA9)*48 -> 0 | BC10: 206365 | BD10: =(+BC10-+BC9)*48 -> 2448 | BE10: 5347 | BF10: =(+BE10-+BE9)*48 -> 0 | BH10: =SUM(E10,J10,P10,H10,L10,R10,T10,V10,X10,N10,AB10,Z10,AD10,AF10,AH10,AL10,AJ10) -> 125424.67 | BI10: =SUM(F10,AN10,AP10,AT10,AV10,AX10,AR10,AZ10,BB10,BD10,BF10) -> 71932.8
A11: 44138 | C11: 5573331 | D11: =(+C11-+C10)*48 -> 98304 | E11: =D11*0.6 -> 58982.4 | F11: =D11*0.4 -> 39321.6 | G11: 276029 | H11: =(+G11-+G10)*48 -> 1392 | I11: 91057 | J11: =(+I11-+I10)*48 -> 8640 | K11: 255305 | L11: =(+K11-+K10)*48 -> 144 | M11: 24397 | N11: =(+M11-+M10)*48 -> 144 | O11: 227115 | P11: =(+O11-+O10)*48 -> 8208 | Q11: 435640 | R11: =(+Q11-+Q10)*48 -> 1008 | S11: 699180 | T11: =(+S11-+S10)*48 -> 6384 | U11: 95454.121 | V11: =(+U11-+U10)*48 -> 886.368 | W11: 78292 | X11: =(+W11-+W10)*48 -> 1248 | Y11: 1485404 | Z11: =(+Y11-+Y10)*48 -> 13344 | AA11: 13166 | AB11: =(+AA11-+AA10)*48 -> 0 | AC11: 434621 | AD11: =(+AC11-+AC10)*48 -> 5040 | AE11: 512171 | AF11: =(+AE11-+AE10)*48 -> 4704 | AG11: 48880 | AH11: =(+AG11-+AG10)*48 -> 96 | AI11: 394496 | AJ11: =(+AI11-+AI10)*48 -> 5040 | AK11: 102371 | AL11: =(+AK11-+AK10)*48 -> 0 | AM11: 558781 | AN11: =(+AM11-+AM10)*48 -> 4176 | AO11: 897808 | AP11: =(+AO11-+AO10)*48 -> 8832 | AQ11: 70514 | AR11: =(+AQ11-+AQ10)*48 -> 2736 | AS11: 2204 | AT11: =(+AS11-+AS10)*48 -> 0 | AU11: 918 | AV11: =(+AU11-+AU10)*48 -> 0 | AW11: 3108 | AX11: =(+AW11-+AW10)*48 -> 0 | AY11: 301412 | AZ11: =(+AY11-+AY10)*48 -> 2976 | BA11: 160171 | BB11: =(+BA11-+BA10)*48 -> 0 | BC11: 206417 | BD11: =(+BC11-+BC10)*48 -> 2496 | BE11: 5347 | BF11: =(+BE11-+BE10)*48 -> 0 | BH11: =SUM(E11,J11,P11,H11,L11,R11,T11,V11,X11,N11,AB11,Z11,AD11,AF11,AH11,AL11,AJ11) -> 115260.77 | BI11: =SUM(F11,AN11,AP11,AT11,AV11,AX11,AR11,AZ11,BB11,BD11,BF11) -> 60537.6
A12: 44139 | C12: 5575266 | D12: =(+C12-+C11)*48 -> 92880 | E12: =D12*0.6 -> 55728 | F12: =D12*0.4 -> 37152 | G12: 276057 | H12: =(+G12-+G11)*48 -> 1344 | I12: 91229 | J12: =(+I12-+I11)*48 -> 8256 | K12: 255308 | L12: =(+K12-+K11)*48 -> 144 | M12: 24397 | N12: =(+M12-+M11)*48 -> 0 | O12: 227288 | P12: =(+O12-+O11)*48 -> 8304 | Q12: 435686 | R12: =(+Q12-+Q11)*48 -> 2208 | S12: 699319 | T12: =(+S12-+S11)*48 -> 6672 | U12: 95472.906 | V12: =(+U12-+U11)*48 -> 901.68 | W12: 78318 | X12: =(+W12-+W11)*48 -> 1248 | Y12: 1485694 | Z12: =(+Y12-+Y11)*48 -> 13920 | AA12: 13166 | AB12: =(+AA12-+AA11)*48 -> 0 | AC12: 434730 | AD12: =(+AC12-+AC11)*48 -> 5232 | AE12: 512278 | AF12: =(+AE12-+AE11)*48 -> 5136 | AG12: 48884 | AH12: =(+AG12-+AG11)*48 -> 192 | AI12: 394577 | AJ12: =(+AI12-+AI11)*48 -> 3888 | AK12: 102371 | AL12: =(+AK12-+AK11)*48 -> 0 | AM12: 558879 | AN12: =(+AM12-+AM11)*48 -> 4704 | AO12: 897999 | AP12: =(+AO12-+AO11)*48 -> 9168 | AQ12: 70632 | AR12: =(+AQ12-+AQ11)*48 -> 5664 | AS12: 2204 | AT12: =(+AS12-+AS11)*48 -> 0 | AU12: 918 | AV12: =(+AU12-+AU11)*48 -> 0 | AW12: 3108 | AX12: =(+AW12-+AW11)*48 -> 0 | AY12: 301497 | AZ12: =(+AY12-+AY11)*48 -> 4080 | BA12: 160171 | BB12: =(+BA12-+BA11)*48 -> 0 | BC12: 206470 | BD12: =(+BC12-+BC11)*48 -> 2544 | BE12: 5347 | BF12: =(+BE12-+BE11)*48 -> 0 | BH12: =SUM(E12,J12,P12,H12,L12,R12,T12,V12,X12,N12,AB12,Z12,AD12,AF12,AH12,AL12,AJ12) -> 113173.68 | BI12: =SUM(F12,AN12,AP12,AT12,AV12,AX12,AR12,AZ12,BB12,BD12,BF12) -> 63312
A13: 44140 | C13: 5577365 | D13: =(+C13-+C12)*48 -> 100752 | E13: =D13*0.6 -> 60451.2 | F13: =D13*0.4 -> 40300.8 | G13: 276091 | H13: =(+G13-+G12)*48 -> 1632 | I13: 91404 | J13: =(+I13-+I12)*48 -> 8400 | K13: 255315 | L13: =(+K13-+K12)*48 -> 336 | M13: 24397 | N13: =(+M13-+M12)*48 -> 0 | O13: 227457 | P13: =(+O13-+O12)*48 -> 8112 | Q13: 435752 | R13: =(+Q13-+Q12)*48 -> 3168 | S13: 699445 | T13: =(+S13-+S12)*48 -> 6048 | U13: 95492.397 | V13: =(+U13-+U12)*48 -> 935.568 | W13: 78345 | X13: =(+W13-+W12)*48 -> 1296 | Y13: 1486059 | Z13: =(+Y13-+Y12)*48 -> 17520 | AA13: 13166 | AB13: =(+AA13-+AA12)*48 -> 0 | AC13: 434835 | AD13: =(+AC13-+AC12)*48 -> 5040 | AE13: 512384 | AF13: =(+AE13-+AE12)*48 -> 5088 | AG13: 48888 | AH13: =(+AG13-+AG12)*48 -> 192 | AI13: 394658 | AJ13: =(+AI13-+AI12)*48 -> 3888 | AK13: 102371 | AL13: =(+AK13-+AK12)*48 -> 0 | AM13: 558967 | AN13: =(+AM13-+AM12)*48 -> 4224 | AO13: 898158 | AP13: =(+AO13-+AO12)*48 -> 7632 | AQ13: 70782 | AR13: =(+AQ13-+AQ12)*48 -> 7200 | AS13: 2204 | AT13: =(+AS13-+AS12)*48 -> 0 | AU13: 918 | AV13: =(+AU13-+AU12)*48 -> 0 | AW13: 3108 | AX13: =(+AW13-+AW12)*48 -> 0 | AY13: 301583 | AZ13: =(+AY13-+AY12)*48 -> 4128 | BA13: 160171 | BB13: =(+BA13-+BA12)*48 -> 0 | BC13: 206523 | BD13: =(+BC13-+BC12)*48 -> 2544 | BE13: 5347 | BF13: =(+BE13-+BE12)*48 -> 0 | BH13: =SUM(E13,J13,P13,H13,L13,R13,T13,V13,X13,N13,AB13,Z13,AD13,AF13,AH13,AL13,AJ13) -> 122106.77 | BI13: =SUM(F13,AN13,AP13,AT13,AV13,AX13,AR13,AZ13,BB13,BD13,BF13) -> 66028.8
A14: 44141 | C14: 5579266 | D14: =(+C14-+C13)*48 -> 91248 | E14: =D14*0.6 -> 54748.8 | F14: =D14*0.4 -> 36499.2 | G14: 276122 | H14: =(+G14-+G13)*48 -> 1488 | I14: 91575 | J14: =(+I14-+I13)*48 -> 8208 | K14: 255319 | L14: =(+K14-+K13)*48 -> 192 | M14: 24397 | N14: =(+M14-+M13)*48 -> 0 | O14: 227645 | P14: =(+O14-+O13)*48 -> 9024 | Q14: 435775 | R14: =(+Q14-+Q13)*48 -> 1104 | S14: 699571 | T14: =(+S14-+S13)*48 -> 6048 | U14: 95512.531 | V14: =(+U14-+U13)*48 -> 966.432 | W14: 78371 | X14: =(+W14-+W13)*48 -> 1248 | Y14: 1486451 | Z14: =(+Y14-+Y13)*48 -> 18816 | AA14: 13166 | AB14: =(+AA14-+AA13)*48 -> 0 | AC14: 434939 | AD14: =(+AC14-+AC13)*48 -> 4992 | AE14: 512487 | AF14: =(+AE14-+AE13)*48 -> 4944 | AG14: 48892 | AH14: =(+AG14-+AG13)*48 -> 192 | AI14: 394756 | AJ14: =(+AI14-+AI13)*48 -> 4704 | AK14: 102371 | AL14: =(+AK14-+AK13)*48 -> 0 | AM14: 559053 | AN14: =(+AM14-+AM13)*48 -> 4128 | AO14: 898312 | AP14: =(+AO14-+AO13)*48 -> 7392 | AQ14: 70917 | AR14: =(+AQ14-+AQ13)*48 -> 6480 | AS14: 2204 | AT14: =(+AS14-+AS13)*48 -> 0 | AU14: 918 | AV14: =(+AU14-+AU13)*48 -> 0 | AW14: 3108 | AX14: =(+AW14-+AW13)*48 -> 0 | AY14: 301664 | AZ14: =(+AY14-+AY13)*48 -> 3888 | BA14: 160171 | BB14: =(+BA14-+BA13)*48 -> 0 | BC14: 206574 | BD14: =(+BC14-+BC13)*48 -> 2448 | BE14: 5347 | BF14: =(+BE14-+BE13)*48 -> 0 | BH14: =SUM(E14,J14,P14,H14,L14,R14,T14,V14,X14,N14,AB14,Z14,AD14,AF14,AH14,AL14,AJ14) -> 116675.23 | BI14: =SUM(F14,AN14,AP14,AT14,AV14,AX14,AR14,AZ14,BB14,BD14,BF14) -> 60835.2
A15: 44142 | C15: 5581183 | D15: =(+C15-+C14)*48 -> 92016 | E15: =D15*0.6 -> 55209.6 | F15: =D15*0.4 -> 36806.4 | G15: 276152 | H15: =(+G15-+G14)*48 -> 1440 | I15: 91743 | J15: =(+I15-+I14)*48 -> 8064 | K15: 255322 | L15: =(+K15-+K14)*48 -> 144 | M15: 24397 | N15: =(+M15-+M14)*48 -> 0 | O15: 227830 | P15: =(+O15-+O14)*48 -> 8880 | Q15: 435792 | R15: =(+Q15-+Q14)*48 -> 816 | S15: 699686 | T15: =(+S15-+S14)*48 -> 5520 | U15: 95533.507 | V15: =(+U15-+U14)*48 -> 1006.848 | W15: 78396 | X15: =(+W15-+W14)*48 -> 1200 | Y15: 1486688 | Z15: =(+Y15-+Y14)*48 -> 11376 | AA15: 13166 | AB15: =(+AA15-+AA14)*48 -> 0 | AC15: 435044 | AD15: =(+AC15-+AC14)*48 -> 5040 | AE15: 512595 | AF15: =(+AE15-+AE14)*48 -> 5184 | AG15: 48896 | AH15: =(+AG15-+AG14)*48 -> 192 | AI15: 394862 | AJ15: =(+AI15-+AI14)*48 -> 5088 | AK15: 102371 | AL15: =(+AK15-+AK14)*48 -> 0 | AM15: 559152 | AN15: =(+AM15-+AM14)*48 -> 4752 | AO15: 898486 | AP15: =(+AO15-+AO14)*48 -> 8352 | AQ15: 71042 | AR15: =(+AQ15-+AQ14)*48 -> 6000 | AS15: 2204 | AT15: =(+AS15-+AS14)*48 -> 0 | AU15: 918 | AV15: =(+AU15-+AU14)*48 -> 0 | AW15: 3108 | AX15: =(+AW15-+AW14)*48 -> 0 | AY15: 301745 | AZ15: =(+AY15-+AY14)*48 -> 3888 | BA15: 160171 | BB15: =(+BA15-+BA14)*48 -> 0 | BC15: 206628 | BD15: =(+BC15-+BC14)*48 -> 2592 | BE15: 5347 | BF15: =(+BE15-+BE14)*48 -> 0 | BH15: =SUM(E15,J15,P15,H15,L15,R15,T15,V15,X15,N15,AB15,Z15,AD15,AF15,AH15,AL15,AJ15) -> 109160.45 | BI15: =SUM(F15,AN15,AP15,AT15,AV15,AX15,AR15,AZ15,BB15,BD15,BF15) -> 62390.4
A16: 44143 | C16: 5583208 | D16: =(+C16-+C15)*48 -> 97200 | E16: =D16*0.6 -> 58320 | F16: =D16*0.4 -> 38880 | G16: 276182 | H16: =(+G16-+G15)*48 -> 1440 | I16: 91917 | J16: =(+I16-+I15)*48 -> 8352 | K16: 255324 | L16: =(+K16-+K15)*48 -> 96 | M16: 24397 | N16: =(+M16-+M15)*48 -> 0 | O16: 228033 | P16: =(+O16-+O15)*48 -> 9744 | Q16: 435823 | R16: =(+Q16-+Q15)*48 -> 1488 | S16: 699799 | T16: =(+S16-+S15)*48 -> 5424 | U16: 95558.544 | V16: =(+U16-+U15)*48 -> 1201.776 | W16: 78424 | X16: =(+W16-+W15)*48 -> 1344 | Y16: 1486919 | Z16: =(+Y16-+Y15)*48 -> 11088 | AA16: 13166 | AB16: =(+AA16-+AA15)*48 -> 0 | AC16: 435135 | AD16: =(+AC16-+AC15)*48 -> 4368 | AE16: 512681 | AF16: =(+AE16-+AE15)*48 -> 4128 | AG16: 48900 | AH16: =(+AG16-+AG15)*48 -> 192 | AI16: 394960 | AJ16: =(+AI16-+AI15)*48 -> 4704 | AK16: 102371 | AL16: =(+AK16-+AK15)*48 -> 0 | AM16: 559214 | AN16: =(+AM16-+AM15)*48 -> 2976 | AO16: 898630 | AP16: =(+AO16-+AO15)*48 -> 6912 | AQ16: 71116 | AR16: =(+AQ16-+AQ15)*48 -> 3552 | AS16: 2204 | AT16: =(+AS16-+AS15)*48 -> 0 | AU16: 918 | AV16: =(+AU16-+AU15)*48 -> 0 | AW16: 3108 | AX16: =(+AW16-+AW15)*48 -> 0 | AY16: 301827 | AZ16: =(+AY16-+AY15)*48 -> 3936 | BA16: 160171 | BB16: =(+BA16-+BA15)*48 -> 0 | BC16: 206680 | BD16: =(+BC16-+BC15)*48 -> 2496 | BE16: 5347 | BF16: =(+BE16-+BE15)*48 -> 0 | BH16: =SUM(E16,J16,P16,H16,L16,R16,T16,V16,X16,N16,AB16,Z16,AD16,AF16,AH16,AL16,AJ16) -> 111889.78 | BI16: =SUM(F16,AN16,AP16,AT16,AV16,AX16,AR16,AZ16,BB16,BD16,BF16) -> 58752
A17: 44144 | C17: 5585156 | D17: =(+C17-+C16)*48 -> 93504 | E17: =D17*0.6 -> 56102.4 | F17: =D17*0.4 -> 37401.6 | G17: 276210 | H17: =(+G17-+G16)*48 -> 1344 | I17: 92076 | J17: =(+I17-+I16)*48 -> 7632 | K17: 255336 | L17: =(+K17-+K16)*48 -> 576 | M17: 24397 | N17: =(+M17-+M16)*48 -> 0 | O17: 228232 | P17: =(+O17-+O16)*48 -> 9552 | Q17: 435874 | R17: =(+Q17-+Q16)*48 -> 2448 | S17: 699909 | T17: =(+S17-+S16)*48 -> 5280 | U17: 95582.278 | V17: =(+U17-+U16)*48 -> 1139.232 | W17: 78451 | X17: =(+W17-+W16)*48 -> 1296 | Y17: 1487222 | Z17: =(+Y17-+Y16)*48 -> 14544 | AA17: 13166 | AB17: =(+AA17-+AA16)*48 -> 0 | AC17: 435224 | AD17: =(+AC17-+AC16)*48 -> 4272 | AE17: 512777 | AF17: =(+AE17-+AE16)*48 -> 4608 | AG17: 48904 | AH17: =(+AG17-+AG16)*48 -> 192 | AI17: 395070 | AJ17: =(+AI17-+AI16)*48 -> 5280 | AK17: 102371 | AL17: =(+AK17-+AK16)*48 -> 0 | AM17: 559276 | AN17: =(+AM17-+AM16)*48 -> 2976 | AO17: 898769 | AP17: =(+AO17-+AO16)*48 -> 6672 | AQ17: 71206 | AR17: =(+AQ17-+AQ16)*48 -> 4320 | AS17: 2204 | AT17: =(+AS17-+AS16)*48 -> 0 | AU17: 918 | AV17: =(+AU17-+AU16)*48 -> 0 | AW17: 3108 | AX17: =(+AW17-+AW16)*48 -> 0 | AY17: 301905 | AZ17: =(+AY17-+AY16)*48 -> 3744 | BA17: 160171 | BB17: =(+BA17-+BA16)*48 -> 0 | BC17: 206728 | BD17: =(+BC17-+BC16)*48 -> 2304 | BE17: 5347 | BF17: =(+BE17-+BE16)*48 -> 0 | BH17: =SUM(E17,J17,P17,H17,L17,R17,T17,V17,X17,N17,AB17,Z17,AD17,AF17,AH17,AL17,AJ17) -> 114265.63 | BI17: =SUM(F17,AN17,AP17,AT17,AV17,AX17,AR17,AZ17,BB17,BD17,BF17) -> 57417.6
A18: 44145 | C18: 5587074 | D18: =(+C18-+C17)*48 -> 92064 | E18: =D18*0.6 -> 55238.4 | F18: =D18*0.4 -> 36825.6 | G18: 276239 | H18: =(+G18-+G17)*48 -> 1392 | I18: 92236 | J18: =(+I18-+I17)*48 -> 7680 | K18: 255339 | L18: =(+K18-+K17)*48 -> 144 | M18: 24397 | N18: =(+M18-+M17)*48 -> 0 | O18: 228406 | P18: =(+O18-+O17)*48 -> 8352 | Q18: 435909 | R18: =(+Q18-+Q17)*48 -> 1680 | S18: 700039 | T18: =(+S18-+S17)*48 -> 6240 | U18: 95602.581 | V18: =(+U18-+U17)*48 -> 974.544 | W18: 78477 | X18: =(+W18-+W17)*48 -> 1248 | Y18: 1487586 | Z18: =(+Y18-+Y17)*48 -> 17472 | AA18: 13166 | AB18: =(+AA18-+AA17)*48 -> 0 | AC18: 435292 | AD18: =(+AC18-+AC17)*48 -> 3264 | AE18: 512850 | AF18: =(+AE18-+AE17)*48 -> 3504 | AG18: 48908 | AH18: =(+AG18-+AG17)*48 -> 192 | AI18: 395158 | AJ18: =(+AI18-+AI17)*48 -> 4224 | AK18: 102371 | AL18: =(+AK18-+AK17)*48 -> 0 | AM18: 559334 | AN18: =(+AM18-+AM17)*48 -> 2784 | AO18: 898890 | AP18: =(+AO18-+AO17)*48 -> 5808 | AQ18: 71360 | AR18: =(+AQ18-+AQ17)*48 -> 7392 | AS18: 2204 | AT18: =(+AS18-+AS17)*48 -> 0 | AU18: 918 | AV18: =(+AU18-+AU17)*48 -> 0 | AW18: 3108 | AX18: =(+AW18-+AW17)*48 -> 0 | AY18: 301989 | AZ18: =(+AY18-+AY17)*48 -> 4032 | BA18: 160171 | BB18: =(+BA18-+BA17)*48 -> 0 | BC18: 206780 | BD18: =(+BC18-+BC17)*48 -> 2496 | BE18: 5347 | BF18: =(+BE18-+BE17)*48 -> 0 | BH18: =SUM(E18,J18,P18,H18,L18,R18,T18,V18,X18,N18,AB18,Z18,AD18,AF18,AH18,AL18,AJ18) -> 111604.94 | BI18: =SUM(F18,AN18,AP18,AT18,AV18,AX18,AR18,AZ18,BB18,BD18,BF18) -> 59337.6
A19: 44146 | C19: 5589057 | D19: =(+C19-+C18)*48 -> 95184 | E19: =D19*0.6 -> 57110.4 | F19: =D19*0.4 -> 38073.6 | G19: 276268 | H19: =(+G19-+G18)*48 -> 1392 | I19: 92404 | J19: =(+I19-+I18)*48 -> 8064 | K19: 255346 | L19: =(+K19-+K18)*48 -> 336 | M19: 24397 | N19: =(+M19-+M18)*48 -> 0 | O19: 228562 | P19: =(+O19-+O18)*48 -> 7488 | Q19: 435939 | R19: =(+Q19-+Q18)*48 -> 1440 | S19: 700167 | T19: =(+S19-+S18)*48 -> 6144 | U19: 95622.885 | V19: =(+U19-+U18)*48 -> 974.592 | W19: 78503 | X19: =(+W19-+W18)*48 -> 1248 | Y19: 1487991 | Z19: =(+Y19-+Y18)*48 -> 19440 | AA19: 13166 | AB19: =(+AA19-+AA18)*48 -> 0 | AC19: 435358 | AD19: =(+AC19-+AC18)*48 -> 3168 | AE19: 512919 | AF19: =(+AE19-+AE18)*48 -> 3312 | AG19: 48911 | AH19: =(+AG19-+AG18)*48 -> 144 | AI19: 395247 | AJ19: =(+AI19-+AI18)*48 -> 4272 | AK19: 102371 | AL19: =(+AK19-+AK18)*48 -> 0 | AM19: 559377 | AN19: =(+AM19-+AM18)*48 -> 2064 | AO19: 899008 | AP19: =(+AO19-+AO18)*48 -> 5664 | AQ19: 71523 | AR19: =(+AQ19-+AQ18)*48 -> 7824 | AS19: 2204 | AT19: =(+AS19-+AS18)*48 -> 0 | AU19: 918 | AV19: =(+AU19-+AU18)*48 -> 0 | AW19: 3108 | AX19: =(+AW19-+AW18)*48 -> 0 | AY19: 302075 | AZ19: =(+AY19-+AY18)*48 -> 4128 | BA19: 160171 | BB19: =(+BA19-+BA18)*48 -> 0 | BC19: 206831 | BD19: =(+BC19-+BC18)*48 -> 2448 | BE19: 5347 | BF19: =(+BE19-+BE18)*48 -> 0 | BH19: =SUM(E19,J19,P19,H19,L19,R19,T19,V19,X19,N19,AB19,Z19,AD19,AF19,AH19,AL19,AJ19) -> 114532.99 | BI19: =SUM(F19,AN19,AP19,AT19,AV19,AX19,AR19,AZ19,BB19,BD19,BF19) -> 60201.6
A20: 44147 | C20: 5591124 | D20: =(+C20-+C19)*48 -> 99216 | E20: =D20*0.6 -> 59529.6 | F20: =D20*0.4 -> 39686.4 | G20: 276299 | H20: =(+G20-+G19)*48 -> 1488 | I20: 92574 | J20: =(+I20-+I19)*48 -> 8160 | K20: 255387 | L20: =(+K20-+K19)*48 -> 1968 | M20: 24397 | N20: =(+M20-+M19)*48 -> 0 | O20: 228751 | P20: =(+O20-+O19)*48 -> 9072 | Q20: 435987 | R20: =(+Q20-+Q19)*48 -> 2304 | S20: 700316 | T20: =(+S20-+S19)*48 -> 7152 | U20: 95641.947 | V20: =(+U20-+U19)*48 -> 914.976 | W20: 78521 | X20: =(+W20-+W19)*48 -> 864 | Y20: 1488340 | Z20: =(+Y20-+Y19)*48 -> 16752 | AA20: 13166 | AB20: =(+AA20-+AA19)*48 -> 0 | AC20: 435462 | AD20: =(+AC20-+AC19)*48 -> 4992 | AE20: 513020 | AF20: =(+AE20-+AE19)*48 -> 4848 | AG20: 48916 | AH20: =(+AG20-+AG19)*48 -> 240 | AI20: 395330 | AJ20: =(+AI20-+AI19)*48 -> 3984 | AK20: 102371 | AL20: =(+AK20-+AK19)*48 -> 0 | AM20: 559417 | AN20: =(+AM20-+AM19)*48 -> 1920 | AO20: 899184 | AP20: =(+AO20-+AO19)*48 -> 8448 | AQ20: 71641 | AR20: =(+AQ20-+AQ19)*48 -> 5664 | AS20: 2204 | AT20: =(+AS20-+AS19)*48 -> 0 | AU20: 918 | AV20: =(+AU20-+AU19)*48 -> 0 | AW20: 3108 | AX20: =(+AW20-+AW19)*48 -> 0 | AY20: 302159 | AZ20: =(+AY20-+AY19)*48 -> 4032 | BA20: 160171 | BB20: =(+BA20-+BA19)*48 -> 0 | BC20: 206886 | BD20: =(+BC20-+BC19)*48 -> 2640 | BE20: 5347 | BF20: =(+BE20-+BE19)*48 -> 0 | BH20: =SUM(E20,J20,P20,H20,L20,R20,T20,V20,X20,N20,AB20,Z20,AD20,AF20,AH20,AL20,AJ20) -> 122268.58 | BI20: =SUM(F20,AN20,AP20,AT20,AV20,AX20,AR20,AZ20,BB20,BD20,BF20) -> 62390.4
... A38: 44165 | C38: 5628460 | D38: =(+C38-+C37)*48 -> 103536 | E38: =D38*0.6 -> 62121.6 | F38: =D38*0.4 -> 41414.4 | G38: 276989 | H38: =(+G38-+G37)*48 -> 1440 | I38: 95642 | J38: =(+I38-+I37)*48 -> 8208 | K38: 255835 | L38: =(+K38-+K37)*48 -> 432 | M38: 24465 | N38: =(+M38-+M37)*48 -> 0 | O38: 232269 | P38: =(+O38-+O37)*48 -> 9264 | Q38: 437196 | R38: =(+Q38-+Q37)*48 -> 3984 | S38: 702616 | T38: =(+S38-+S37)*48 -> 5712 | U38: 96046.059 | V38: =(+U38-+U37)*48 -> 1004.496 | W38: 78897 | X38: =(+W38-+W37)*48 -> 144 | Y38: 1493535 | Z38: =(+Y38-+Y37)*48 -> 11712 | AA38: 13204 | AB38: =(+AA38-+AA37)*48 -> 144 | AC38: 437267 | AD38: =(+AC38-+AC37)*48 -> 4512 | AE38: 514736 | AF38: =(+AE38-+AE37)*48 -> 3360 | AG38: 48992 | AH38: =(+AG38-+AG37)*48 -> 240 | AI38: 397182 | AJ38: =(+AI38-+AI37)*48 -> 5952 | AK38: 102371 | AL38: =(+AK38-+AK37)*48 -> 0 | AM38: 561285 | AN38: =(+AM38-+AM37)*48 -> 912 | AO38: 902511 | AP38: =(+AO38-+AO37)*48 -> 5040 | AQ38: 73842 | AR38: =(+AQ38-+AQ37)*48 -> 11136 | AS38: 2235 | AT38: =(+AS38-+AS37)*48 -> 96 | AU38: 918 | AV38: =(+AU38-+AU37)*48 -> 0 | AW38: 3108 | AX38: =(+AW38-+AW37)*48 -> 0 | AY38: 303642 | AZ38: =(+AY38-+AY37)*48 -> 4080 | BA38: 160171 | BB38: =(+BA38-+BA37)*48 -> 0 | BC38: 207851 | BD38: =(+BC38-+BC37)*48 -> 2544 | BE38: 5347 | BF38: =(+BE38-+BE37)*48 -> 0 | BH38: =SUM(E38,J38,P38,H38,L38,R38,T38,V38,X38,N38,AB38,Z38,AD38,AF38,AH38,AL38,AJ38) -> 118230.1 | BI38: =SUM(F38,AN38,AP38,AT38,AV38,AX38,AR38,AZ38,BB38,BD38,BF38) -> 65222.4

Sheet Submetering EL
C1: FSH | E1: Sub- meter | G1: Sub- meter | I1: Sub- meter | K1: Sub- meter | M1: Sub- meter | P1: FSH | R1: Sub- meter | T1: Sub- meter | V1: Sub- meter | X1: Sub- meter | AA1: FSH | AC1: Sub- meter | AE1: Sub- meter | AG1: Sub- meter | AI1: Sub- meter | AK1: Sub- meter | AM1: Sub- meter | AP1: FSH | AR1: Sub- meter | AT1: Sub- meter | AV1: Sub- meter | AX1: Sub- meter | AZ1: Sub- meter | BB1: Sub- meter | BD1: Sub- meter | BG1: FSH | BI1: Sub- meter | BK1: Sub- meter | BM1: Sub- meter | BO1: Sub- meter | BQ1: Sub- meter | BS1: Sub- meter | BV1: FSH & FSP | BX1: Sub- meter | BZ1: Sub- meter | CB1: Sub- meter | CE1: FSH & FSP | CH1: FSH & FSP | CK1: FSH & FSP | CN1: FSP | CQ1: FSP | CT1: FSP | CV1: Sub- meter | CX1: Sub- meter | CZ1: Sub- meter | DB1: Sub- meter | DD1: Sub- meter | DF1: Sub- meter | DI1: FSP | DL1: FSP | DN1: Sub- meter | DP1: Sub- meter | DR1: Sub- meter | DT1: Sub- meter | DV1: Sub- meter
C2: HOT Normal and Essential power for linen chute(9/F-45/F), HOT water pump at 8/F, Podium dimmer supply(P1-P6), MVAC system(B1/F-B2/F), Bus station BPTT supply. | E2: HOT Normal and Essential power for linen chute(9/F-45/F), | G2: HOT water pump at 8/F, | I2: Podium dimmer supply(P1-P6) | K2: MVAC system(B1/F-B2/F), | M2: Bus station BPTT supply. | P2: HOT Normal Power for Guest rooms supply (9/F-45/F), MVAC system (2/F & 46/F), P&D system(46/F) Podium MVAC system (P1/F-P6/F) | R2: HOT Normal Power for Guest rooms supply (9/F-45/F), | T2: MVAC system (2/F & 46/F), | V2: P&D system(46/F) | X2: Podium MVAC system (P1/F-P6/F) | AA2: P5 Pool Plant, Laundry (hotel 70%,Place 30%), 9/F - 28/F public area, 29/F 46/F Public area Podium normal power supply for water feature(G/F), Chiller WCC-01(B2/F)(FSH 50%, FSP 50%) | AC2: P5 Pool Plant, | AE2: Laundry (hotel 70%,Place 30%), | AG2: 9/F - 28/F public area, | AI2: 29/F 46/F Public area | AK2: Podium normal power supply for water feature(G/F), | AM2: Chiller WCC-01(B2/F)(FSH 50%, FSP 50%) | AP2: Podium normal power for Administration office(P5/F & P6/F), P&D system supply(B2/F), Planter lighting supply(Open Space), Kitchen public supply(B1/F, P1/F, P2/F, P3/F, P4/F & P6/F), BMS room supply(B1/F), Security room supply(G/F), Computer & PABX room | AR2: Podium normal power for Administration office(P5/F & P6/F), | AT2: P&D system supply(B2/F), | AV2: Planter lighting supply(Open Space), | AX2: Kitchen public supply(B1/F, P1/F, P2/F, P3/F, P4/F & P6/F), | AZ2: BMS room supply(B1/F), | BB2: Security room supply(G/F), | BD2: Computer & PABX room | BG2: Podium normal power supply for Public supply(P1/F - P6/F), Kitchen(B1/F, P1/F, P2/F, P3/F, P4/F & P6/F), P&D system supply(B1/F), Refuse room supply(G/F), Gas boiler supply(B2/F) and MVAC system supply(P1/F-P6/F). | BV2: Podium normal power supply for main P&D system supply(B1/F), MVAC chilled water pump(B1/F) Chiller WCC-02(B2/F) (FSH 50%, FSP 50%) | BX2: Podium normal power supply for main P&D system supply(B1/F), | BZ2: MVAC chilled water pump(B1/F) | CB2: Chiller WCC-02(B2/F) (FSH 50%, FSP 50%) | CE2: Chiller # 3 (FSH 50%, FSP 50%) | CH2: Chiller # 4 (FSH 50%, FSP 50%) | CK2: Chiller # 5 (FSH 50%, FSP 50%) | CN2: SHT normal power for Guest rooms supply (11/F-23/F). | CQ2: SHT normal power for Guest rooms supply (25/F-57/F). | CT2: SHT Essential Power for Public Power supply, F.S. Pump (9/F, 57/F & 39/F), Podium F.S. pump(P1M), Lift LT/S1-LT/S7(LM/F), Lift LT/S8-S9(59/F) and Lift LT/S10(8/F). | CV2: SHT Essential Power for Public Power supply, | CX2: F.S. Pump (9/F, 57/F & 39/F), | CZ2: Podium F.S. pump(P1M), | DB2: Lift LT/S1-LT/S7(LM/F), | DD2: Lift LT/S8-S9(59/F) and | DF2: Lift LT/S10(8/F). | DI2: SHT normal power for Guest rooms supply (25/F-57/F). | DL2: SHT normal power for MVAC System(8/F & 40/F), Public supply (8-R/F), P&D system(40/F & 60/F), swimming pool(57/F), SWB 3&4(40/F) | DN2: SHT normal power for MVAC System(8/F & 40/F), | DP2: Public supply (8-R/F), | DR2: P&D system(40/F & 60/F), | DT2: swimming pool(57/F), | DV2: SWB 3&4(40/F)
C3: 5065546 | P3: 5065547 | AA3: 5008272 | AP3: 5065548 | BG3: 5465545 | BV3: 5008273 | CE3: 5018351 | CH3: 5018354 | CK3: 5018350 | CN3: 5065543 | CQ3: 5065544 | CT3: 5065541 | DI3: 5065542 | DL3: 5065540
C4: TXW1 | P4: TXW4 | AA4: TXW2 | AP4: TXC2 | BG4: TXC1 | BV4: TXW3 | CE4: TXN1 | CH4: TXN2 | CK4: TXN3 | CN4: TXN4 | CQ4: TXE1 | CT4: TXE2 | DI4: TXE3 | DL4: TXE4
A6: Date | C6: Reading Kwh | D6: Differecne Kwh | E6: Reading Kwh | F6: Differecne Kwh | G6: Reading Kwh | H6: Differecne Kwh | I6: Reading Kwh | J6: Differecne Kwh | K6: Reading Kwh | L6: Differecne Kwh | M6: Reading Kwh | N6: Differecne Kwh | P6: Reading Kwh | Q6: Differecne Kwh | R6: Reading Kwh | S6: Differecne Kwh | T6: Reading Kwh | U6: Differecne Kwh | V6: Reading Kwh | W6: Differecne Kwh | X6: Reading Kwh | Y6: Differecne Kwh | AA6: Reading Kwh | AB6: Differecne Kwh | AC6: Reading Kwh | AD6: Differecne Kwh | AE6: Reading Kwh | AF6: Differecne Kwh | AG6: Reading Kwh | AH6: Differecne Kwh | AI6: Reading Kwh | AJ6: Differecne Kwh | AK6: Reading Kwh | AL6: Differecne Kwh | AM6: Reading Kwh | AN6: Differecne Kwh | AP6: Reading Kwh | AQ6: Differecne Kwh | AR6: Reading Kwh | AS6: Differecne Kwh | AT6: Reading Kwh | AU6: Differecne Kwh | AV6: Reading Kwh | AW6: Differecne Kwh | AX6: Reading Kwh | AY6: Differecne Kwh | AZ6: Reading Kwh | BA6: Differecne Kwh | BB6: Reading Kwh | BC6: Differecne Kwh | BD6: Reading Kwh | BE6: Differecne Kwh | BG6: Reading Kwh | BH6: Differecne Kwh | BI6: Reading Kwh | BJ6: Differecne Kwh | BK6: Reading Kwh | BL6: Differecne Kwh | BM6: Reading Kwh | BN6: Differecne Kwh | BO6: Reading Kwh | BP6: Differecne Kwh | BQ6: Reading Kwh | BR6: Differecne Kwh | BS6: Reading Kwh | BT6: Differecne Kwh | BV6: Reading Kwh | BW6: Differecne Kwh | BX6: Reading Kwh | BY6: Differecne Kwh | BZ6: Reading Kwh | CA6: Differecne Kwh | CB6: Reading Kwh | CC6: Differecne Kwh | CE6: Reading Kwh | CF6: Differecne Kwh | CH6: Reading Kwh | CI6: Differecne Kwh | CK6: Reading Kwh | CL6: Differecne Kwh | CN6: Reading Kwh | CO6: Differecne Kwh | CQ6: Reading Kwh | CR6: Differecne Kwh | CT6: Reading Kwh | CU6: Differecne Kwh | CV6: Reading Kwh | CW6: Differecne Kwh | CX6: Reading Kwh | CY6: Differecne Kwh | CZ6: Reading Kwh | DA6: Differecne Kwh | DB6: Reading Kwh | DC6: Differecne Kwh | DD6: Reading Kwh | DE6: Differecne Kwh | DF6: Reading Kwh | DG6: Differecne Kwh | DI6: Reading Kwh | DJ6: Differecne Kwh | DL6: Reading Kwh | DM6: Differecne Kwh | DN6: Reading Kwh | DO6: Differecne Kwh | DP6: Reading Kwh | DQ6: Differecne Kwh | DR6: Reading Kwh | DS6: Differecne Kwh | DT6: Reading Kwh | DU6: Differecne Kwh | DV6: Reading Kwh | DW6: Differecne Kwh

Sheet Submetering Water
