Workbook

Sheet TOTAL
A1: Site Name | B1: Day | C1: Month | D1: Year | E1: Total Electricity Kwh | F1: Electricity Tariff ($/Kwh) | G1: LPG (Kg) | H1: LPG $/Kg | I1: Total Fuel Oil (Liters) | J1: Fuel Oil $/Liter | K1: Water Utility Supply (m3) m3 | L1: Water Utility Supply (m3) $/m3 | M1: Room Nights | N1: Food Covers
A2: Bali Jimbaran | B2: 1 | C2: 11 | D2: 2020 | E2: ='FS Jimbaran November 2020'!P12 -> 13820 | F2: ='FS Jimbaran November 2020'!O12/'FS Jimbaran November 2020'!P12 -> 1177.6107 | G2: ='FS Jimbaran November 2020'!AG12 -> 112 | H2: ='FS Jimbaran November 2020'!AH12/'FS Jimbaran November 2020'!AG12 -> 13190 | I2: ='FS Jimbaran November 2020'!AJ12 -> 157.09 | J2: ='FS Jimbaran November 2020'!AK12/'FS Jimbaran November 2020'!AJ12 -> 8400 | K2: ='FS Jimbaran November 2020'!V12 -> 884 | L2: ='FS Jimbaran November 2020'!AA12/'FS Jimbaran November 2020'!V12 -> 1685.2158 | M2: ='FS Jimbaran November 2020'!C12 -> 7 | N2: ='FS Jimbaran November 2020'!D12 -> 127
A3: Bali Jimbaran | B3: =B2+1 -> 2 | C3: 11 | D3: 2020 | E3: ='FS Jimbaran November 2020'!P13 -> 13920 | F3: ='FS Jimbaran November 2020'!O13/'FS Jimbaran November 2020'!P13 -> 1180.1076 | G3: ='FS Jimbaran November 2020'!AG13 -> 112 | H3: ='FS Jimbaran November 2020'!AH13/'FS Jimbaran November 2020'!AG13 -> 13190 | I3: ='FS Jimbaran November 2020'!AJ13 -> 139.94 | J3: ='FS Jimbaran November 2020'!AK13/'FS Jimbaran November 2020'!AJ13 -> 8400 | K3: ='FS Jimbaran November 2020'!V13 -> 875 | L3: ='FS Jimbaran November 2020'!AA13/'FS Jimbaran November 2020'!V13 -> 2150.1391 | M3: ='FS Jimbaran November 2020'!C13 -> 5 | N3: ='FS Jimbaran November 2020'!D13 -> 72
A4: Bali Jimbaran | B4: =B3+1 -> 3 | C4: 11 | D4: 2020 | E4: ='FS Jimbaran November 2020'!P14 -> 13920 | F4: ='FS Jimbaran November 2020'!O14/'FS Jimbaran November 2020'!P14 -> 1177.8931 | G4: ='FS Jimbaran November 2020'!AG14 -> 102 | H4: ='FS Jimbaran November 2020'!AH14/'FS Jimbaran November 2020'!AG14 -> 13190 | I4: ='FS Jimbaran November 2020'!AJ14 -> 132 | J4: ='FS Jimbaran November 2020'!AK14/'FS Jimbaran November 2020'!AJ14 -> 8400 | K4: ='FS Jimbaran November 2020'!V14 -> 891 | L4: ='FS Jimbaran November 2020'!AA14/'FS Jimbaran November 2020'!V14 -> 2093.8229 | M4: ='FS Jimbaran November 2020'!C14 -> 4 | N4: ='FS Jimbaran November 2020'!D14 -> 36
A5: Bali Jimbaran | B5: =B4+1 -> 4 | C5: 11 | D5: 2020 | E5: ='FS Jimbaran November 2020'!P15 -> 14100 | F5: ='FS Jimbaran November 2020'!O15/'FS Jimbaran November 2020'!P15 -> 1179.0175 | G5: ='FS Jimbaran November 2020'!AG15 -> 142 | H5: ='FS Jimbaran November 2020'!AH15/'FS Jimbaran November 2020'!AG15 -> 13190 | I5: ='FS Jimbaran November 2020'!AJ15 -> 122.7 | J5: ='FS Jimbaran November 2020'!AK15/'FS Jimbaran November 2020'!AJ15 -> 8400 | K5: ='FS Jimbaran November 2020'!V15 -> 925 | L5: ='FS Jimbaran November 2020'!AA15/'FS Jimbaran November 2020'!V15 -> 1847.9134 | M5: ='FS Jimbaran November 2020'!C15 -> 6 | N5: ='FS Jimbaran November 2020'!D15 -> 48
A6: Bali Jimbaran | B6: =B5+1 -> 5 | C6: 11 | D6: 2020 | E6: ='FS Jimbaran November 2020'!P16 -> 14020 | F6: ='FS Jimbaran November 2020'!O16/'FS Jimbaran November 2020'!P16 -> 1180.2967 | G6: ='FS Jimbaran November 2020'!AG16 -> 112 | H6: ='FS Jimbaran November 2020'!AH16/'FS Jimbaran November 2020'!AG16 -> 13190 | I6: ='FS Jimbaran November 2020'!AJ16 -> 207 | J6: ='FS Jimbaran November 2020'!AK16/'FS Jimbaran November 2020'!AJ16 -> 8400 | K6: ='FS Jimbaran November 2020'!V16 -> 913 | L6: ='FS Jimbaran November 2020'!AA16/'FS Jimbaran November 2020'!V16 -> 1674.9288 | M6: ='FS Jimbaran November 2020'!C16 -> 5 | N6: ='FS Jimbaran November 2020'!D16 -> 77
A7: Bali Jimbaran | B7: =B6+1 -> 6 | C7: 11 | D7: 2020 | E7: ='FS Jimbaran November 2020'!P17 -> 14620 | F7: ='FS Jimbaran November 2020'!O17/'FS Jimbaran November 2020'!P17 -> 1176.5263 | G7: ='FS Jimbaran November 2020'!AG17 -> 112 | H7: ='FS Jimbaran November 2020'!AH17/'FS Jimbaran November 2020'!AG17 -> 13190 | I7: ='FS Jimbaran November 2020'!AJ17 -> 131.1 | J7: ='FS Jimbaran November 2020'!AK17/'FS Jimbaran November 2020'!AJ17 -> 8400 | K7: ='FS Jimbaran November 2020'!V17 -> 945 | L7: ='FS Jimbaran November 2020'!AA17/'FS Jimbaran November 2020'!V17 -> 1698.1896 | M7: ='FS Jimbaran November 2020'!C17 -> 8 | N7: ='FS Jimbaran November 2020'!D17 -> 65
A8: Bali Jimbaran | B8: =B7+1 -> 7 | C8: 11 | D8: 2020 | E8: ='FS Jimbaran November 2020'!P18 -> 13440 | F8: ='FS Jimbaran November 2020'!O18/'FS Jimbaran November 2020'!P18 -> 1182.7374 | G8: ='FS Jimbaran November 2020'!AG18 -> 112 | H8: ='FS Jimbaran November 2020'!AH18/'FS Jimbaran November 2020'!AG18 -> 13190 | I8: ='FS Jimbaran November 2020'!AJ18 -> 634.73 | J8: ='FS Jimbaran November 2020'!AK18/'FS Jimbaran November 2020'!AJ18 -> 8400 | K8: ='FS Jimbaran November 2020'!V18 -> 909 | L8: ='FS Jimbaran November 2020'!AA18/'FS Jimbaran November 2020'!V18 -> 1996.0072 | M8: ='FS Jimbaran November 2020'!C18 -> 10 | N8: ='FS Jimbaran November 2020'!D18 -> 88
A9: Bali Jimbaran | B9: =B8+1 -> 8 | C9: 11 | D9: 2020 | E9: ='FS Jimbaran November 2020'!P19 -> 13880 | F9: ='FS Jimbaran November 2020'!O19/'FS Jimbaran November 2020'!P19 -> 1182.8176 | G9: ='FS Jimbaran November 2020'!AG19 -> 112 | H9: ='FS Jimbaran November 2020'!AH19/'FS Jimbaran November 2020'!AG19 -> 13190 | I9: ='FS Jimbaran November 2020'!AJ19 -> 199.65 | J9: ='FS Jimbaran November 2020'!AK19/'FS Jimbaran November 2020'!AJ19 -> 8400 | K9: ='FS Jimbaran November 2020'!V19 -> 854 | L9: ='FS Jimbaran November 2020'!AA19/'FS Jimbaran November 2020'!V19 -> 1886.2025 | M9: ='FS Jimbaran November 2020'!C19 -> 10 | N9: ='FS Jimbaran November 2020'!D19 -> 133
A10: Bali Jimbaran | B10: =B9+1 -> 9 | C10: 11 | D10: 2020 | E10: ='FS Jimbaran November 2020'!P20 -> 14460 | F10: ='FS Jimbaran November 2020'!O20/'FS Jimbaran November 2020'!P20 -> 1180.5191 | G10: ='FS Jimbaran November 2020'!AG20 -> 112 | H10: ='FS Jimbaran November 2020'!AH20/'FS Jimbaran November 2020'!AG20 -> 13190 | I10: ='FS Jimbaran November 2020'!AJ20 -> 111.25 | J10: ='FS Jimbaran November 2020'!AK20/'FS Jimbaran November 2020'!AJ20 -> 8400 | K10: ='FS Jimbaran November 2020'!V20 -> 939 | L10: ='FS Jimbaran November 2020'!AA20/'FS Jimbaran November 2020'!V20 -> 2031.4641 | M10: ='FS Jimbaran November 2020'!C20 -> 7 | N10: ='FS Jimbaran November 2020'!D20 -> 69
A11: Bali Jimbaran | B11: =B10+1 -> 10 | C11: 11 | D11: 2020 | E11: ='FS Jimbaran November 2020'!P21 -> 14500 | F11: ='FS Jimbaran November 2020'!O21/'FS Jimbaran November 2020'!P21 -> 1178.8336 | G11: ='FS Jimbaran November 2020'!AG21 -> 137 | H11: ='FS Jimbaran November 2020'!AH21/'FS Jimbaran November 2020'!AG21 -> 13190 | I11: ='FS Jimbaran November 2020'!AJ21 -> 152.78 | J11: ='FS Jimbaran November 2020'!AK21/'FS Jimbaran November 2020'!AJ21 -> 8400 | K11: ='FS Jimbaran November 2020'!V21 -> 863 | L11: ='FS Jimbaran November 2020'!AA21/'FS Jimbaran November 2020'!V21 -> 1723.0607 | M11: ='FS Jimbaran November 2020'!C21 -> 5 | N11: ='FS Jimbaran November 2020'!D21 -> 139
A12: Bali Jimbaran | B12: =B11+1 -> 11 | C12: 11 | D12: 2020 | E12: ='FS Jimbaran November 2020'!P22 -> 13420 | F12: ='FS Jimbaran November 2020'!O22/'FS Jimbaran November 2020'!P22 -> 1177.9209 | G12: ='FS Jimbaran November 2020'!AG22 -> 112 | H12: ='FS Jimbaran November 2020'!AH22/'FS Jimbaran November 2020'!AG22 -> 13190 | I12: ='FS Jimbaran November 2020'!AJ22 -> 634.56 | J12: ='FS Jimbaran November 2020'!AK22/'FS Jimbaran November 2020'!AJ22 -> 8400 | K12: ='FS Jimbaran November 2020'!V22 -> 812 | L12: ='FS Jimbaran November 2020'!AA22/'FS Jimbaran November 2020'!V22 -> 2152.9537 | M12: ='FS Jimbaran November 2020'!C22 -> 4 | N12: ='FS Jimbaran November 2020'!D22 -> 30
A13: Bali Jimbaran | B13: =B12+1 -> 12 | C13: 11 | D13: 2020 | E13: ='FS Jimbaran November 2020'!P23 -> 13880 | F13: ='FS Jimbaran November 2020'!O23/'FS Jimbaran November 2020'!P23 -> 1181.793 | G13: ='FS Jimbaran November 2020'!AG23 -> 62 | H13: ='FS Jimbaran November 2020'!AH23/'FS Jimbaran November 2020'!AG23 -> 13190 | I13: ='FS Jimbaran November 2020'!AJ23 -> 113.29 | J13: ='FS Jimbaran November 2020'!AK23/'FS Jimbaran November 2020'!AJ23 -> 8400 | K13: ='FS Jimbaran November 2020'!V23 -> 863 | L13: ='FS Jimbaran November 2020'!AA23/'FS Jimbaran November 2020'!V23 -> 1164.4445 | M13: ='FS Jimbaran November 2020'!C23 -> 6 | N13: ='FS Jimbaran November 2020'!D23 -> 48
A14: Bali Jimbaran | B14: =B13+1 -> 13 | C14: 11 | D14: 2020 | E14: ='FS Jimbaran November 2020'!P24 -> 14680 | F14: ='FS Jimbaran November 2020'!O24/'FS Jimbaran November 2020'!P24 -> 1181.9317 | G14: ='FS Jimbaran November 2020'!AG24 -> 112 | H14: ='FS Jimbaran November 2020'!AH24/'FS Jimbaran November 2020'!AG24 -> 13190 | I14: ='FS Jimbaran November 2020'!AJ24 -> 101.64 | J14: ='FS Jimbaran November 2020'!AK24/'FS Jimbaran November 2020'!AJ24 -> 8400 | K14: ='FS Jimbaran November 2020'!V24 -> 853 | L14: ='FS Jimbaran November 2020'!AA24/'FS Jimbaran November 2020'!V24 -> 1364.9604 | M14: ='FS Jimbaran November 2020'!C24 -> 15 | N14: ='FS Jimbaran November 2020'!D24 -> 94
... A31: Bali Jimbaran | B31: =B30+1 -> 30 | C31: 11 | D31: 2020 | E31: ='FS Jimbaran November 2020'!P41 -> 12580 | F31: ='FS Jimbaran November 2020'!O41/'FS Jimbaran November 2020'!P41 -> 1176.7257 | G31: ='FS Jimbaran November 2020'!AG41 -> 92 | H31: ='FS Jimbaran November 2020'!AH41/'FS Jimbaran November 2020'!AG41 -> 13190 | I31: ='FS Jimbaran November 2020'!AJ41 -> 620 | J31: ='FS Jimbaran November 2020'!AK41/'FS Jimbaran November 2020'!AJ41 -> 8400 | K31: ='FS Jimbaran November 2020'!V41 -> 838 | L31: ='FS Jimbaran November 2020'!AA41/'FS Jimbaran November 2020'!V41 -> 1791.894 | M31: ='FS Jimbaran November 2020'!C41 -> 1 | N31: ='FS Jimbaran November 2020'!D41 -> 16

Sheet FS Jimbaran November 2020
B6: Four Seasons Resort Bali at Jimbaran Bay
B7: NOVEMBER 2020
B8: Date | C8: Room Nights | D8: Food Covers | E8: ELECTRICITY Resort, Sundara & Residences | V8: WATER | AC8: GAS
E9: Electricity Resort | J9: Electricity - Sundara | O9: Sub Total (Resort & Sundara) Cost (IDR) | P9: Sub Total (Resort & Sundara), KWh | Q9: Residences- Electricity KWh (daily reading N/A), monthly report | R9: Residences- Electricity cost (IDR) | S9: TOTAL Electricity consumption (KWh) | T9: TOTAL Electricity cost | W9: Water (m3) | AA9: Total Water Cost | AC9: LPG | AJ9: Diesel
E10: BASED LOAD KWh (from 10 pm - 6 pm) | F10: Cost (IDR) | G10: PEAK LOAD KWh (from 6 pm - 10 pm) | H10: Cost (IDR) | I10: Resort Cost (IDR) | J10: BASED LOAD KWh (from 10 pm - 6 pm) | K10: Cost (IDR) | L10: PEAK LOAD KWh (from 6 pm - 10 pm) | M10: Cost (IDR) | N10: Sundara Cost (IDR) | T10: IDR | U10: USD | V10: Water consumption (m3) | W10: Municipal Water (m3) | X10: Municipal Water cost (IDR) | Y10: Deepwell Consumption (m3) | Z10: Deepwell water Cost (IDR) | AA10: IDR | AB10: USD | AC10: LPG Bulk (m3) | AD10: 50 Kg (tube) IVD & TW | AE10: Sundara 50 kg (tube) | AF10: 12 Kg (tube) | AG10: Total kg | AH10: IDR | AI10: USD | AJ10: Used (liters) | AK10: IDR | AL10: USD
D11: `
B12: 1 | C12: 7 | D12: 127 | E12: 10360 | F12: 11267198 | G12: 2000 | H12: 3262707 | I12: =H12+F12 -> 14529905 | J12: 1200 | K12: 1320523.6 | L12: 260 | M12: 424151.9 | N12: =M12+K12 -> 1744675.5 | O12: =N12+I12 -> 16274580 | P12: =L12+J12+G12+E12 -> 13820 | V12: =W12+Y12 -> 884 | W12: 77 | X12: 1384845 | Y12: 807 | Z12: 104885.79 | AA12: =Z12+X12 -> 1489730.8 | AB12: =AA12/$AL$47 -> 114.80583 | AD12: 0 | AE12: 100 | AF12: 12 | AG12: =SUM(AC12:AF12) -> 112 | AH12: 1477280 | AI12: =AH12/$AL$47 -> 113.84631 | AJ12: 157.09 | AK12: 1319556 | AL12: =AK12/$AL$47 -> 101.69134
B13: 2 | C13: 5 | D13: 72 | E13: 10360 | F13: 11267198 | G13: 2040 | H13: 3327961.1 | I13: =H13+F13 -> 14595159 | J13: 1220 | K13: 1342532.3 | L13: 300 | M13: 489406.03 | N13: =M13+K13 -> 1831938.3 | O13: =N13+I13 -> 16427097 | P13: =L13+J13+G13+E13 -> 13920 | V13: =W13+Y13 -> 875 | W13: 99 | X13: 1780515 | Y13: 776 | Z13: 100856.72 | AA13: =Z13+X13 -> 1881371.7 | AB13: =AA13/$AL$47 -> 144.98757 | AD13: 0 | AE13: 100 | AF13: 12 | AG13: =SUM(AC13:AF13) -> 112 | AH13: 1477280 | AI13: =AH13/$AL$47 -> 113.84631 | AJ13: 139.94 | AK13: 1175496 | AL13: =AK13/$AL$47 -> 90.589384
B14: 3 | C14: 4 | D14: 36 | E14: 10280 | F14: 11180193 | G14: 2000 | H14: 3262707 | I14: =H14+F14 -> 14442900 | J14: 1360 | K14: 1496593.4 | L14: 280 | M14: 456778.97 | N14: =M14+K14 -> 1953372.4 | O14: =N14+I14 -> 16396272 | P14: =L14+J14+G14+E14 -> 13920 | V14: =W14+Y14 -> 891 | W14: 98 | X14: 1762530 | Y14: 793 | Z14: 103066.21 | AA14: =Z14+X14 -> 1865596.2 | AB14: =AA14/$AL$47 -> 143.77183 | AD14: 0 | AE14: 90 | AF14: 12 | AG14: =SUM(AC14:AF14) -> 102 | AH14: 1345380 | AI14: =AH14/$AL$47 -> 103.68146 | AJ14: 132 | AK14: 1108800 | AL14: =AK14/$AL$47 -> 85.449469
B15: 4 | C15: 6 | D15: 48 | E15: 10440 | F15: 11354203 | G15: 2080 | H15: 3393215.2 | I15: =H15+F15 -> 14747419 | J15: 1320 | K15: 1452575.9 | L15: 260 | M15: 424151.9 | N15: =M15+K15 -> 1876727.8 | O15: =N15+I15 -> 16624146 | P15: =L15+J15+G15+E15 -> 14100 | T15: Include | V15: =W15+Y15 -> 925 | W15: 89 | X15: 1600665 | Y15: 836 | Z15: 108654.92 | AA15: =Z15+X15 -> 1709319.9 | AB15: =AA15/$AL$47 -> 131.72843 | AD15: 50 | AE15: 80 | AF15: 12 | AG15: =SUM(AC15:AF15) -> 142 | AH15: 1872980 | AI15: =AH15/$AL$47 -> 144.34086 | AJ15: 122.7 | AK15: 1030680 | AL15: =AK15/$AL$47 -> 79.429165
B16: 5 | C16: 5 | D16: 77 | E16: 10360 | F16: 11267198 | G16: 2080 | H16: 3393215.2 | I16: =H16+F16 -> 14660413 | J16: 1300 | K16: 1430567.2 | L16: 280 | M16: 456778.97 | N16: =M16+K16 -> 1887346.2 | O16: =N16+I16 -> 16547759 | P16: =L16+J16+G16+E16 -> 14020 | T16: Resort | V16: =W16+Y16 -> 913 | W16: 79 | X16: 1420815 | Y16: 834 | Z16: 108394.98 | AA16: =Z16+X16 -> 1529210 | AB16: =AA16/$AL$47 -> 117.84829 | AD16: 0 | AE16: 100 | AF16: 12 | AG16: =SUM(AC16:AF16) -> 112 | AH16: 1477280 | AI16: =AH16/$AL$47 -> 113.84631 | AJ16: 207 | AK16: 1738800 | AL16: =AK16/$AL$47 -> 134.0003
B17: 6 | C17: 8 | D17: 65 | E17: 10920 | F17: 11876236 | G17: 2080 | H17: 3393215.2 | I17: =H17+F17 -> 15269451 | J17: 1340 | K17: 1474584.7 | L17: 280 | M17: 456778.97 | N17: =M17+K17 -> 1931363.6 | O17: =N17+I17 -> 17200815 | P17: =L17+J17+G17+E17 -> 14620 | T17: Sundara | V17: =W17+Y17 -> 945 | W17: 83 | X17: 1492755 | Y17: 862 | Z17: 112034.14 | AA17: =Z17+X17 -> 1604789.1 | AB17: =AA17/$AL$47 -> 123.67278 | AD17: 0 | AE17: 100 | AF17: 12 | AG17: =SUM(AC17:AF17) -> 112 | AH17: 1477280 | AI17: =AH17/$AL$47 -> 113.84631 | AJ17: 131.1 | AK17: 1101240 | AL17: =AK17/$AL$47 -> 84.866859
B18: 7 | C18: 10 | D18: 88 | E18: 9760 | F18: 10614658 | G18: 2000 | H18: 3262707 | I18: =H18+F18 -> 13877365 | J18: 1360 | K18: 1496593.4 | L18: 320 | M18: 522033.1 | N18: =M18+K18 -> 2018626.5 | O18: =N18+I18 -> 15895991 | P18: =L18+J18+G18+E18 -> 13440 | T18: Residences | V18: =W18+Y18 -> 909 | W18: 95 | X18: 1708575 | Y18: 814 | Z18: 105795.58 | AA18: =Z18+X18 -> 1814370.6 | AB18: =AA18/$AL$47 -> 139.82414 | AD18: 0 | AE18: 100 | AF18: 12 | AG18: =SUM(AC18:AF18) -> 112 | AH18: 1477280 | AI18: =AH18/$AL$47 -> 113.84631 | AJ18: =108.73+526 -> 634.73 | AK18: 5331732 | AL18: =AK18/$AL$47 -> 410.88895
B19: 8 | C19: 10 | D19: 133 | E19: 10160 | F19: 11049684 | G19: 2120 | H19: 3458469.4 | I19: =H19+F19 -> 14508154 | J19: 1320 | K19: 1452575.9 | L19: 280 | M19: 456778.97 | N19: =M19+K19 -> 1909354.9 | O19: =N19+I19 -> 16417509 | P19: =L19+J19+G19+E19 -> 13880 | V19: =W19+Y19 -> 854 | W19: 84 | X19: 1510740 | Y19: 770 | Z19: 100076.9 | AA19: =Z19+X19 -> 1610816.9 | AB19: =AA19/$AL$47 -> 124.13731 | AE19: 100 | AF19: 12 | AG19: =SUM(AC19:AF19) -> 112 | AH19: 1477280 | AI19: =AH19/$AL$47 -> 113.84631 | AJ19: 199.65 | AK19: 1677060 | AL19: =AK19/$AL$47 -> 129.24232
B20: 9 | C20: 7 | D20: 69 | E20: 10680 | F20: 11615220 | G20: 2160 | H20: 3523723.5 | I20: =H20+F20 -> 15138943 | J20: 1340 | K20: 1474584.7 | L20: 280 | M20: 456778.97 | N20: =M20+K20 -> 1931363.6 | O20: =N20+I20 -> 17070307 | P20: =L20+J20+G20+E20 -> 14460 | V20: =W20+Y20 -> 939 | W20: 100 | X20: 1798500 | Y20: 839 | Z20: 109044.83 | AA20: =Z20+X20 -> 1907544.8 | AB20: =AA20/$AL$47 -> 147.00459 | AD20: 0 | AE20: 100 | AF20: 12 | AG20: =SUM(AC20:AF20) -> 112 | AH20: 1477280 | AI20: =AH20/$AL$47 -> 113.84631 | AJ20: 111.25 | AK20: 934500 | AL20: =AK20/$AL$47 -> 72.017071
B21: 10 | C21: 5 | D21: 139 | E21: 10680 | F21: 11615220 | G21: 2080 | H21: 3393215.2 | I21: =H21+F21 -> 15008435 | J21: 1420 | K21: 1562619.6 | L21: 320 | M21: 522033.1 | N21: =M21+K21 -> 2084652.7 | O21: =N21+I21 -> 17093087 | P21: =L21+J21+G21+E21 -> 14500 | V21: =W21+Y21 -> 863 | W21: 77 | X21: 1384845 | Y21: 786 | Z21: 102156.42 | AA21: =Z21+X21 -> 1487001.4 | AB21: =AA21/$AL$47 -> 114.59549 | AD21: 50 | AE21: 75 | AF21: 12 | AG21: =SUM(AC21:AF21) -> 137 | AH21: 1807030 | AI21: =AH21/$AL$47 -> 139.25844 | AJ21: 152.78 | AK21: 1283352 | AL21: =AK21/$AL$47 -> 98.901287
B22: 11 | C22: 4 | D22: 30 | E22: 9960 | F22: 10832171 | G22: 1880 | H22: 3066944.5 | I22: =H22+F22 -> 13899116 | J22: 1260 | K22: 1386549.8 | L22: 320 | M22: 522033.1 | N22: =M22+K22 -> 1908582.9 | O22: =N22+I22 -> 15807698 | P22: =L22+J22+G22+E22 -> 13420 | V22: =W22+Y22 -> 812 | W22: 92 | X22: 1654620 | Y22: 720 | Z22: 93578.4 | AA22: =Z22+X22 -> 1748198.4 | AB22: =AA22/$AL$47 -> 134.72459 | AD22: 0 | AE22: 100 | AF22: 12 | AG22: =SUM(AC22:AF22) -> 112 | AH22: 1477280 | AI22: =AH22/$AL$47 -> 113.84631 | AJ22: =43.22+591.34 -> 634.56 | AK22: 5330304 | AL22: =AK22/$AL$47 -> 410.7789
B23: 12 | C23: 6 | D23: 48 | E23: 10440 | F23: 11354203 | G23: 2040 | H23: 3327961.1 | I23: =H23+F23 -> 14682164 | J23: 1060 | K23: 1166462.5 | L23: 340 | M23: 554660.17 | N23: =M23+K23 -> 1721122.7 | O23: =N23+I23 -> 16403287 | P23: =L23+J23+G23+E23 -> 13880 | V23: =W23+Y23 -> 863 | W23: 50 | X23: 899250 | Y23: 813 | Z23: 105665.61 | AA23: =Z23+X23 -> 1004915.6 | AB23: =AA23/$AL$47 -> 77.443637 | AD23: 0 | AE23: 50 | AF23: 12 | AG23: =SUM(AC23:AF23) -> 62 | AH23: 817780 | AI23: =AH23/$AL$47 -> 63.022066 | AJ23: 113.29 | AK23: 951636 | AL23: =AK23/$AL$47 -> 73.337654
B24: 13 | C24: 15 | D24: 94 | E24: 11000 | F24: 11963241 | G24: 2200 | H24: 3588977.7 | I24: =H24+F24 -> 15552219 | J24: 1160 | K24: 1276506.1 | L24: 320 | M24: 522033.1 | N24: =M24+K24 -> 1798539.2 | O24: =N24+I24 -> 17350758 | P24: =L24+J24+G24+E24 -> 14680 | V24: =W24+Y24 -> 853 | W24: 59 | X24: 1061115 | Y24: 794 | Z24: 103196.18 | AA24: =Z24+X24 -> 1164311.2 | AB24: =AA24/$AL$47 -> 89.727428 | AD24: 0 | AE24: 100 | AF24: 12 | AG24: =SUM(AC24:AF24) -> 112 | AH24: 1477280 | AI24: =AH24/$AL$47 -> 113.84631 | AJ24: =101.64 -> 101.64 | AK24: 853776 | AL24: =AK24/$AL$47 -> 65.796091
B25: 14 | C25: 12 | D25: 158 | E25: 10240 | F25: 11136690 | G25: 2120 | H25: 3458469.4 | I25: =H25+F25 -> 14595159 | J25: 1960 | K25: 2156855.2 | L25: 340 | M25: 554660.17 | N25: =M25+K25 -> 2711515.4 | O25: =N25+I25 -> 17306675 | P25: =L25+J25+G25+E25 -> 14660 | V25: =W25+Y25 -> 862 | W25: 56 | X25: 1007160 | Y25: 806 | Z25: 104755.82 | AA25: =Z25+X25 -> 1111915.8 | AB25: =AA25/$AL$47 -> 85.689589 | AD25: 50 | AE25: 100 | AF25: 12 | AG25: =SUM(AC25:AF25) -> 162 | AH25: 2136780 | AI25: =AH25/$AL$47 -> 164.67056 | AJ25: =180.2+450 -> 630.2 | AK25: 5293680 | AL25: =AK25/$AL$47 -> 407.95648
B26: 15 | C26: 2 | D26: 123 | E26: 9696.456 | F26: 10545549 | G26: 1920 | H26: 3132198.7 | I26: =H26+F26 -> 13677748 | J26: 760 | K26: 836331.61 | L26: 340 | M26: 554660.17 | N26: =M26+K26 -> 1390991.8 | O26: =N26+I26 -> 15068740 | P26: =L26+J26+G26+E26 -> 12716.456 | V26: =W26+Y26 -> 846 | W26: 59 | X26: 1061115 | Y26: 787 | Z26: 102286.39 | AA26: =Z26+X26 -> 1163401.4 | AB26: =AA26/$AL$47 -> 89.657315 | AD26: 0 | AE26: 70 | AF26: 12 | AG26: =SUM(AC26:AF26) -> 82 | AH26: 1081580 | AI26: =AH26/$AL$47 -> 83.351765 | AJ26: 89.08 | AK26: 748272 | AL26: =AK26/$AL$47 -> 57.665445
B27: 16 | C27: 5 | D27: 32 | E27: 9760 | F27: 10614658 | G27: 2000 | H27: 3262707 | I27: =H27+F27 -> 13877365 | J27: 2240 | K27: 2464977.4 | L27: 340 | M27: 554660.17 | N27: =M27+K27 -> 3019637.5 | O27: =N27+I27 -> 16897002 | P27: =L27+J27+G27+E27 -> 14340 | V27: =W27+Y27 -> 912 | W27: 74 | X27: 1330890 | Y27: 838 | Z27: 108914.86 | AA27: =Z27+X27 -> 1439804.9 | AB27: =AA27/$AL$47 -> 110.9583 | AE27: 100 | AF27: 12 | AG27: =SUM(AC27:AF27) -> 112 | AH27: 1477280 | AI27: =AH27/$AL$47 -> 113.84631 | AJ27: 460 | AK27: 3864000 | AL27: =AK27/$AL$47 -> 297.77845
B28: 17 | C28: 4 | D28: 29 | E28: =10480-145 -> 10335 | F28: 11240009 | G28: 2040 | H28: 3327961.1 | I28: =H28+F28 -> 14567970 | J28: 1020 | K28: 1122445 | L28: 340 | M28: 554660.17 | N28: =M28+K28 -> 1677105.2 | O28: =N28+I28 -> 16245075 | P28: =L28+J28+G28+E28 -> 13735 | V28: =W28+Y28 -> 941 | W28: 88 | X28: 1582680 | Y28: 853 | Z28: 110864.41 | AA28: =Z28+X28 -> 1693544.4 | AB28: =AA28/$AL$47 -> 130.51269 | AE28: 90 | AF28: 12 | AG28: =SUM(AC28:AF28) -> 102 | AH28: 1345380 | AI28: =AH28/$AL$47 -> 103.68146 | AJ28: 480 | AK28: 4032000 | AL28: =AK28/$AL$47 -> 310.72534
B29: 18 | C29: 4 | D29: 34 | E29: =11280-120 -> 11160 | F29: 12137252 | G29: 2360 | H29: 3849994.2 | I29: =H29+F29 -> 15987246 | J29: 1000 | K29: 1100436.3 | L29: 280 | M29: 456778.97 | N29: =M29+K29 -> 1557215.3 | O29: =N29+I29 -> 17544461 | P29: =L29+J29+G29+E29 -> 14800 | V29: =W29+Y29 -> 958 | W29: 80 | X29: 1438800 | Y29: 878 | Z29: 114113.66 | AA29: =Z29+X29 -> 1552913.7 | AB29: =AA29/$AL$47 -> 119.67501 | AE29: 100 | AF29: 12 | AG29: =SUM(AC29:AF29) -> 112 | AH29: 1477280 | AI29: =AH29/$AL$47 -> 113.84631 | AJ29: 495 | AK29: 4158000 | AL29: =AK29/$AL$47 -> 320.43551
B30: 19 | C30: 7 | D30: 59 | E30: 9920 | F30: 10788668 | G30: 2120 | H30: 3458469.4 | I30: =H30+F30 -> 14247138 | J30: 1120 | K30: 1232488.7 | L30: 300 | M30: 489406.04 | N30: =M30+K30 -> 1721894.7 | O30: =N30+I30 -> 15969032 | P30: =L30+J30+G30+E30 -> 13460 | V30: =W30+Y30 -> 949 | W30: 69 | X30: 1240965 | Y30: 880 | Z30: 114373.6 | AA30: =Z30+X30 -> 1355338.6 | AB30: =AA30/$AL$47 -> 104.44892 | AE30: 110 | AF30: 12 | AG30: =SUM(AC30:AF30) -> 122 | AH30: 1609180 | AI30: =AH30/$AL$47 -> 124.01116 | AJ30: 415 | AK30: 3486000 | AL30: =AK30/$AL$47 -> 268.64795
B31: 20 | C31: 7 | D31: 134 | E31: 10360 | F31: 11267198 | G31: 2120 | H31: 3458469.4 | I31: =H31+F31 -> 14725667 | J31: 640 | K31: 704279.25 | L31: 320 | M31: 522033.1 | N31: =M31+K31 -> 1226312.4 | O31: =N31+I31 -> 15951980 | P31: =L31+J31+G31+E31 -> 13440 | V31: =W31+Y31 -> 936 | W31: 110 | X31: 1978350 | Y31: 826 | Z31: 107355.22 | AA31: =Z31+X31 -> 2085705.2 | AB31: =AA31/$AL$47 -> 160.73449 | AE31: 100 | AF31: 12 | AG31: =SUM(AC31:AF31) -> 112 | AH31: 1477280 | AI31: =AH31/$AL$47 -> 113.84631 | AJ31: 1230 | AK31: 10332000 | AL31: =AK31/$AL$47 -> 796.23369
B32: 21 | C32: 8 | D32: 175 | E32: 10960 | F32: 11919738 | G32: 2400 | H32: 3915248.4 | I32: =H32+F32 -> 15834987 | J32: 1400 | K32: 1540610.9 | L32: 300 | M32: 489406.03 | N32: =M32+K32 -> 2030016.9 | O32: =N32+I32 -> 17865004 | P32: =L32+J32+G32+E32 -> 15060 | V32: =W32+Y32 -> 899 | W32: 90 | X32: 1618650 | Y32: 809 | Z32: 105145.73 | AA32: =Z32+X32 -> 1723795.7 | AB32: =AA32/$AL$47 -> 132.844 | AE32: 110 | AF32: 12 | AG32: =SUM(AC32:AF32) -> 122 | AH32: 1609180 | AI32: =AH32/$AL$47 -> 124.01116 | AJ32: 865 | AK32: 7266000 | AL32: =AK32/$AL$47 -> 559.95296
B33: 22 | C33: 3 | D33: 93 | E33: 10160 | F33: 11049684 | G33: 1960 | H33: 3197452.8 | I33: =H33+F33 -> 14247137 | J33: 1760 | K33: 1936767.9 | L33: 240 | M33: 391524.83 | N33: =M33+K33 -> 2328292.8 | O33: =N33+I33 -> 16575430 | P33: =L33+J33+G33+E33 -> 14120 | V33: =W33+Y33 -> 924 | W33: 83 | X33: 1492755 | Y33: 841 | Z33: 109304.77 | AA33: =Z33+X33 -> 1602059.8 | AB33: =AA33/$AL$47 -> 123.46244 | AE33: 100 | AF33: 12 | AG33: =SUM(AC33:AF33) -> 112 | AH33: 1477280 | AI33: =AH33/$AL$47 -> 113.84631 | AJ33: 820 | AK33: 6888000 | AL33: =AK33/$AL$47 -> 530.82246
B34: 23 | C34: 6 | D34: 50 | E34: 10000 | F34: 10875674 | G34: 2000 | H34: 3262707 | I34: =H34+F34 -> 14138381 | J34: 1060 | K34: 1166462.5 | L34: 220 | M34: 358897.76 | N34: =M34+K34 -> 1525360.3 | O34: =N34+I34 -> 15663741 | P34: =L34+J34+G34+E34 -> 13280 | V34: =W34+Y34 -> 991 | W34: 97 | X34: 1744545 | Y34: 894 | Z34: 116193.18 | AA34: =Z34+X34 -> 1860738.2 | AB34: =AA34/$AL$47 -> 143.39745 | AE34: 100 | AF34: 12 | AG34: =SUM(AC34:AF34) -> 112 | AH34: 1477280 | AI34: =AH34/$AL$47 -> 113.84631 | AJ34: 850 | AK34: 7140000 | AL34: =AK34/$AL$47 -> 550.24279
B35: 24 | C35: 5 | D35: 30 | E35: 10200 | F35: 11093187 | G35: 1920 | H35: 3132198.7 | I35: =H35+F35 -> 14225386 | J35: 1280 | K35: 1408558.5 | L35: 220 | M35: 358897.76 | N35: =M35+K35 -> 1767456.3 | O35: =N35+I35 -> 15992842 | P35: =L35+J35+G35+E35 -> 13620 | V35: =W35+Y35 -> 898 | W35: 69 | X35: 1240965 | Y35: 829 | Z35: 107745.13 | AA35: =Z35+X35 -> 1348710.1 | AB35: =AA35/$AL$47 -> 103.9381 | AE35: 80 | AF35: 12 | AG35: =SUM(AC35:AF35) -> 92 | AH35: 1213480 | AI35: =AH35/$AL$47 -> 93.516614 | AJ35: 625 | AK35: 5250000 | AL35: =AK35/$AL$47 -> 404.59029
B36: 25 | C36: 3 | D36: 66 | E36: =17640-31 -> 17609 | F36: 19150974 | G36: 1840 | H36: 3001690.4 | I36: =H36+F36 -> 22152664 | J36: 1720 | K36: 1892750.5 | L36: 320 | M36: 522033.1 | N36: =M36+K36 -> 2414783.6 | O36: =N36+I36 -> 24567448 | P36: =L36+J36+G36+E36 -> 21489 | V36: =W36+Y36 -> 871 | W36: 95 | X36: 1708575 | Y36: 776 | Z36: 100856.72 | AA36: =Z36+X36 -> 1809431.7 | AB36: =AA36/$AL$47 -> 139.44352 | AE36: 90 | AF36: 12 | AG36: =SUM(AC36:AF36) -> 102 | AH36: 1345380 | AI36: =AH36/$AL$47 -> 103.68146 | AJ36: 765 | AK36: 6426000 | AL36: =AK36/$AL$47 -> 495.21851
B37: 26 | C37: 9 | D37: 69 | E37: 1920 | F37: 2088129.4 | G37: 2000 | H37: 3262707 | I37: =H37+F37 -> 5350836.3 | J37: 1200 | K37: 1320523.6 | L37: 280 | M37: 456778.97 | N37: =M37+K37 -> 1777302.6 | O37: =N37+I37 -> 7128138.9 | P37: =L37+J37+G37+E37 -> 5400 | V37: =W37+Y37 -> 906 | W37: 91 | X37: 1636635 | Y37: 815 | Z37: 105925.55 | AA37: =Z37+X37 -> 1742560.6 | AB37: =AA37/$AL$47 -> 134.29011 | AE37: 90 | AF37: 12 | AG37: =SUM(AC37:AF37) -> 102 | AH37: 1345380 | AI37: =AH37/$AL$47 -> 103.68146 | AJ37: 955 | AK37: 8022000 | AL37: =AK37/$AL$47 -> 618.21396
B38: 27 | C38: 6 | D38: 68 | E38: 9560 | F38: 10397144 | G38: 1920 | H38: 3132198.7 | I38: =H38+F38 -> 13529343 | J38: 700 | K38: 770305.43 | L38: 260 | M38: 424151.9 | N38: =M38+K38 -> 1194457.3 | O38: =N38+I38 -> 14723800 | P38: =L38+J38+G38+E38 -> 12440 | V38: =W38+Y38 -> 903 | W38: 93 | X38: 1672605 | Y38: 810 | Z38: 105275.7 | AA38: =Z38+X38 -> 1777880.7 | AB38: =AA38/$AL$47 -> 137.01205 | AE38: 92 | AF38: 12 | AG38: =SUM(AC38:AF38) -> 104 | AH38: 1371760 | AI38: =AH38/$AL$47 -> 105.71443 | AJ38: 1325 | AK38: 11130000 | AL38: =AK38/$AL$47 -> 857.73141
B39: 28 | C39: 7 | D39: 150 | E39: 9200 | F39: 10005620 | G39: 1800 | H39: 2936436.3 | I39: =H39+F39 -> 12942056 | J39: 1260 | K39: 1386549.8 | L39: 300 | M39: 489406.03 | N39: =M39+K39 -> 1875955.8 | O39: =N39+I39 -> 14818012 | P39: =L39+J39+G39+E39 -> 12560 | V39: =W39+Y39 -> 908 | W39: 94 | X39: 1690590 | Y39: 814 | Z39: 105795.58 | AA39: =Z39+X39 -> 1796385.6 | AB39: =AA39/$AL$47 -> 138.43813 | AE39: 98 | AF39: 12 | AG39: =SUM(AC39:AF39) -> 110 | AH39: 1450900 | AI39: =AH39/$AL$47 -> 111.81334 | AJ39: 820 | AK39: 6888000 | AL39: =AK39/$AL$47 -> 530.82246
B40: 29 | C40: 8 | D40: 109 | E40: 9680 | F40: 10527652 | G40: 1960 | H40: 3197452.8 | I40: =H40+F40 -> 13725105 | J40: 1300 | K40: 1430567.2 | L40: 280 | M40: 456778.97 | N40: =M40+K40 -> 1887346.2 | O40: =N40+I40 -> 15612451 | P40: =L40+J40+G40+E40 -> 13220 | V40: =W40+Y40 -> 906 | W40: 100 | X40: 1798500 | Y40: 806 | Z40: 104755.82 | AA40: =Z40+X40 -> 1903255.8 | AB40: =AA40/$AL$47 -> 146.67406 | AE40: 90 | AF40: 12 | AG40: =SUM(AC40:AF40) -> 102 | AH40: 1345380 | AI40: =AH40/$AL$47 -> 103.68146 | AJ40: 660 | AK40: 5544000 | AL40: =AK40/$AL$47 -> 427.24734
B41: 30 | C41: 1 | D41: 16 | E41: 8760 | F41: 9527090.2 | G41: 1720 | H41: 2805928 | I41: =H41+F41 -> 12333018 | J41: 1800 | K41: 1980785.4 | L41: 300 | M41: 489406.04 | N41: =M41+K41 -> 2470191.4 | O41: =N41+I41 -> 14803210 | P41: =L41+J41+G41+E41 -> 12580 | Q41: Refer to | R41: Refer to | V41: =W41+Y41 -> 838 | W41: 78 | X41: 1402830 | Y41: 760 | Z41: 98777.2 | AA41: =Z41+X41 -> 1501607.2 | AB41: =AA41/$AL$47 -> 115.72108 | AE41: 80 | AF41: 12 | AG41: =SUM(AC41:AF41) -> 92 | AH41: 1213480 | AI41: =AH41/$AL$47 -> 93.516614 | AJ41: 620 | AK41: 5208000 | AL41: =AK41/$AL$47 -> 401.35357
Q42: Electricity Residences '!A1 | R42: Electricity Residences '!A1
S43: =SUM(S12:S41) -> 0
C46: =SUM(C12:C42) -> 189 | D46: =SUM(D12:D42) -> 2421 | E46: =SUM(E12:E42) -> 304920.46 | F46: =SUM(F12:F42) -> 3.3162154e+08 | G46: =SUM(G12:G42) -> 60960 | H46: =SUM(H12:H42) -> 99447308 | I46: =SUM(I12:I42) -> 4.3106885e+08 | J46: =SUM(J12:J42) -> 38880 | ... P46: =SUM(P12:P42) -> 413580.46 | Q46: ='Electricity Residences '!F23 -> 30925 | R46: ='Electricity Residences '!F24 -> 55287318 | S46: =Q46+P46 -> 444505.46 | T46: =R46+O46 -> 5.4352967e+08 | U46: =T46/AL47 -> 41887.014 | V46: =SUM(V12:V41) -> 26974 | W46: =SUM(W12:W41) -> 2508 | X46: =SUM(X12:X41) -> 45106380 | Y46: =SUM(Y12:Y42) -> 24466 | Z46: =SUM(Z12:Z41) -> 3179846 | AA46: =SUM(AA12:AA41) -> 48286226 | AB46: =AA46/$AL$47 -> 3721.1692 | AC46: =SUM(AC12:AC41) -> 0 | AD46: =SUM(AD12:AD41) -> 150 | AE46: =SUM(AE12:AE41) -> 2795 | AF46: =SUM(AF12:AF41) -> 360 | AG46: =SUM(AG12:AG41) -> 3305 | AH46: =AG46*13190 -> 43592950 | AI46: =AH46/$AL$47 -> 3359.4827 | AJ46: =SUM(AJ12:AJ42) -> 14942.01 | AK46: =SUM(AK12:AK42) -> 125512884 | AL46: =AK46/AL47 -> 9672.6274
T47: kWh rate | U47: =U46/S46 -> 0.094232846 | AL47: 12976.09
...

Sheet Electricity Residences 
A2: Residences 2020 | C2: August | D2: September | E2: October | F2: November'20 | G2: December'20
A3: Office & Pantry | B3: Unit (KWh) - bill Estate Common | C3: 2161 | D3: 1975 | E3: 2111 | F3: 1295 | G3: 2160
B4: Charge | C4: 1736305 | D4: 3042772 | E4: 3202250 | F4: 1964431 | G4: =F4 -> 1964431
A5: Residence 001 | B5: Unit (KWh) - bill Estate 1 | C5: 984 | D5: 2640 | E5: 1288 | F5: 1853 | G5: 5896
B6: Charge | C6: 4454662 | D6: 4454662 | E6: 4386109 | F6: =E6 -> 4386109 | G6: 11250895
A7: Residence 002 | B7: Unit (KWh) - bill Estate 2 | C7: 5180 | D7: 2120 | E7: 1206 | F7: 1134 | G7: =D7 -> 2120
B8: Charge | C8: 8740587 | D8: 3577229 | E8: 3522178 | F8: =E8 -> 3522178 | G8: =D8 -> 3577229
A9: Residence 003 | B9: Unit (KWh) - bill Estate 3 | C9: 3668 | D9: 6957 | E9: 5874 | F9: 4772 | G9: =D9 -> 6957
B10: Charge | C10: 6189280 | D10: 11739047 | E10: 9759093 | F10: 7928224 | G10: =D10 -> 11739047
A11: Residence 005 | B11: Unit (KWh) - bill Estate 4 | C11: 3520 | D11: 5961 | E11: 10196 | F11: 6245 | G11: =D11 -> 5961
B12: Charge | C12: 5939550 | D12: 10058425 | E12: 16939685 | F12: 10375475 | G12: =D12 -> 10058425
A13: Residence 006 | B13: Unit (KWh)-bill Estate 5 | C13: 2593 | D13: 4274 | E13: 5349 | F13: 3034 | G13: 4878
B14: Charge | C14: 4712830 | D14: 7211829 | E14: 8886855 | F14: 5040703 | G14: 10962856
A15: Residence 007 | B15: Unit (KWh)-bill Estate 6 | C15: 1208 | D15: 3762 | E15: 2990 | F15: 2360 | G15: 6520
B16: Charge | C16: 3577229 | D16: 6347893 | E16: 4967601 | F16: 3920916 | G16: 7567905
A17: Residence 008 | B17: Unit (KWh)-bill Estate 7 | C17: 2168 | D17: 1558 | E17: 2375 | F17: 1446 | G17: 5675
B18: Charge | C18: 3658222 | D18: 3577229 | E18: 3945837 | F18: 3552178 | G18: 11284680
A19: Residence 009 | B19: Unit (KWh)-bill Estate 8 | C19: 5120 | D19: 4766 | E19: 5456 | F19: 5669 | G19: =E19 -> 5456
B20: Charge | C20: 8639345 | D20: 8042015 | E20: 9064625 | F20: 9418504 | G20: =E20 -> 9064625
A21: Residence 010 | B21: Unit (KWh)-billa Estate 9 | C21: 2678 | D21: 2690 | E21: 2890 | F21: 3117 | G21: 2980
B22: Charge | C22: 4518783 | D22: 4539030 | E22: 4801460 | F22: 5178600 | G22: 4902560
B23: Total KWh | C23: =C21+C19+C17+C15+C13+C11+C9+C7+C5+C3 -> 29280 | D23: =D21+D19+D17+D15+D13+D11+D9+D7+D5+D3 -> 36703 | E23: =E21+E19+E17+E15+E13+E11+E9+E7+E5+E3 -> 39735 | F23: =F21+F19+F17+J15+J13+F11+F9+F7+F5+F3+F15+F13 -> 30925 | G23: =G21+G19+G17+G15+G13+G11+G9+G7+G5+G3 -> 48603
B24: Total Charges | C24: =C22+C20+C18+C16+C14+C12+C10+C8+C6+C4 -> 52166793 | D24: =D22+D20+D18+D16+D14+D12+D10+D8+D6+D4 -> 62590131 | E24: =E22+E20+E18+E16+E14+E12+E10+E8+E6+E4 -> 69475693 | F24: =F22+F20+F18+F16+F14+F12+F10+F8+F6+F4 -> 55287318 | G24: =G22+G20+G18+G16+G14+G12+G10+G8+G6+G4 -> 82372653
G25: Forecast
A26: Minimum charges apply during each residence closure according to the contract | C26: =C24/C23 -> 1781.6528 | D26: During closure charges based on minimum contract

Sheet December'20 RNs & Covers Fcst
A1: Four Seasons Resort Bali at Jimbaran Bay
A2: 44166
A3: Date | B3: Room Nights | C3: Food Covers
A6: 1 | B6: 2 | C6: 44
A7: 2 | B7: 1 | C7: 52
A8: =A7+1 -> 3 | B8: 5 | C8: 74
A9: =A8+1 -> 4 | B9: 10 | C9: 115
A10: =A9+1 -> 5 | B10: 9 | C10: 138
A11: =A10+1 -> 6 | B11: 6 | C11: 66
A12: =A11+1 -> 7 | B12: 2 | C12: 45
A13: =A12+1 -> 8 | B13: 2 | C13: 49
A14: =A13+1 -> 9 | B14: 6 | C14: 82
A15: =A14+1 -> 10 | B15: 8 | C15: 88
A16: =A15+1 -> 11 | B16: 8 | C16: 116
A17: =A16+1 -> 12 | B17: 8 | C17: 136
A18: =A17+1 -> 13 | B18: 10 | C18: 83
A19: =A18+1 -> 14 | B19: 9 | C19: 64
... A36: =A35+1 -> 31 | B36: 38 | C36: 427
B38: =SUM(B6:B37) -> 469 | C38: =SUM(C6:C37) -> 4598
