Workbook

Sheet TOTAL
A1: Site Name | B1: Day | C1: Month | D1: Year | E1: Total Electricity Kwh | F1: Electricity Tariff ($/Kwh) | G1: LPG (Kg) | H1: LPG $/Kg | I1: District Energy Heating Kwh | J1: District Energy Heating $/Kwh | K1: Water Utility Supply (m3) m3 | L1: Water Utility Supply (m3) $/m3 | M1: Room Nights | N1: Total Guests | O1: Utilities day cost dh
A2: Marrakech | B2: 1 | C2: 12 | D2: 2020 | E2: ='Consommation du 01.12 au 31.12'!M10 -> 11011 | F2: 0.99 | G2: ='Consommation du 01.12 au 31.12'!U10 -> 185.5 | H2: 8.2658 | I2: ='Consommation du 01.12 au 31.12'!Y10*1000 -> 13570 | J2: 0.53 | K2: ='Consommation du 01.12 au 31.12'!D10 -> 190 | L2: 12.67 | M2: ='Consommation du 01.12 au 31.12'!AC10 -> 13 | N2: 13 | O2: =E2*F2+G2*H2+I2*J2+K2*L2 -> 22033.596
A3: Marrakech | B3: =B2+1 -> 2 | C3: 12 | D3: 2020 | E3: ='Consommation du 01.12 au 31.12'!M11 -> 11506 | F3: 0.99 | G3: ='Consommation du 01.12 au 31.12'!U11 -> 259.7 | H3: 8.2658 | I3: ='Consommation du 01.12 au 31.12'!Y11*1000 -> 14390 | J3: 0.53 | K3: ='Consommation du 01.12 au 31.12'!D11 -> 220 | L3: 12.67 | M3: ='Consommation du 01.12 au 31.12'!AC11 -> 14 | N3: 14 | O3: =E3*F3+G3*H3+I3*J3+K3*L3 -> 23951.668
A4: Marrakech | B4: =B3+1 -> 3 | C4: 12 | D4: 2020 | E4: ='Consommation du 01.12 au 31.12'!M12 -> 10340 | F4: 0.99 | G4: ='Consommation du 01.12 au 31.12'!U12 -> 296.8 | H4: 8.2658 | I4: ='Consommation du 01.12 au 31.12'!Y12*1000 -> 12630 | J4: 0.53 | K4: ='Consommation du 01.12 au 31.12'!D12 -> 210 | L4: 12.67 | M4: ='Consommation du 01.12 au 31.12'!AC12 -> 17 | N4: 17 | O4: =E4*F4+G4*H4+I4*J4+K4*L4 -> 22044.489
A5: Marrakech | B5: =B4+1 -> 4 | C5: 12 | D5: 2020 | E5: ='Consommation du 01.12 au 31.12'!M13 -> 9730 | F5: 0.99 | G5: ='Consommation du 01.12 au 31.12'!U13 -> 333.9 | H5: 8.2658 | I5: ='Consommation du 01.12 au 31.12'!Y13*1000 -> 14070 | J5: 0.53 | K5: ='Consommation du 01.12 au 31.12'!D13 -> 290 | L5: 12.67 | M5: ='Consommation du 01.12 au 31.12'!AC13 -> 18 | N5: 18 | O5: =E5*F5+G5*H5+I5*J5+K5*L5 -> 23524.051
A6: Marrakech | B6: =B5+1 -> 5 | C6: 12 | D6: 2020 | E6: ='Consommation du 01.12 au 31.12'!M14 -> 9236 | F6: 0.99 | G6: ='Consommation du 01.12 au 31.12'!U14 -> 74.2 | H6: 8.2658 | I6: ='Consommation du 01.12 au 31.12'!Y14*1000 -> 17520 | J6: 0.53 | K6: ='Consommation du 01.12 au 31.12'!D14 -> 230 | L6: 12.67 | M6: ='Consommation du 01.12 au 31.12'!AC14 -> 20 | N6: 20 | O6: =E6*F6+G6*H6+I6*J6+K6*L6 -> 21956.662
A7: Marrakech | B7: =B6+1 -> 6 | C7: 12 | D7: 2020 | E7: ='Consommation du 01.12 au 31.12'!M15 -> 9512 | F7: 0.99 | G7: ='Consommation du 01.12 au 31.12'!U15 -> 148.4 | H7: 8.2658 | I7: ='Consommation du 01.12 au 31.12'!Y15*1000 -> 18500 | J7: 0.53 | K7: ='Consommation du 01.12 au 31.12'!D15 -> 420 | L7: 12.67 | M7: ='Consommation du 01.12 au 31.12'!AC15 -> 13 | N7: 13 | O7: =E7*F7+G7*H7+I7*J7+K7*L7 -> 25769.925
A8: Marrakech | B8: =B7+1 -> 7 | C8: 12 | D8: 2020 | E8: ='Consommation du 01.12 au 31.12'!M16 -> 9554 | F8: 0.99 | G8: ='Consommation du 01.12 au 31.12'!U16 -> 111.3 | H8: 8.2658 | I8: ='Consommation du 01.12 au 31.12'!Y16*1000 -> 14630 | J8: 0.53 | K8: ='Consommation du 01.12 au 31.12'!D16 -> 260 | L8: 12.67 | M8: ='Consommation du 01.12 au 31.12'!AC16 -> 8 | N8: 8 | O8: =E8*F8+G8*H8+I8*J8+K8*L8 -> 21426.544
A9: Marrakech | B9: =B8+1 -> 8 | C9: 12 | D9: 2020 | E9: ='Consommation du 01.12 au 31.12'!M17 -> 9603 | F9: 0.99 | G9: ='Consommation du 01.12 au 31.12'!U17 -> 185.5 | H9: 8.2658 | I9: ='Consommation du 01.12 au 31.12'!Y17*1000 -> 15700 | J9: 0.53 | K9: ='Consommation du 01.12 au 31.12'!D17 -> 210 | L9: 12.67 | M9: ='Consommation du 01.12 au 31.12'!AC17 -> 5 | N9: 5 | O9: =E9*F9+G9*H9+I9*J9+K9*L9 -> 22021.976
A10: Marrakech | B10: =B9+1 -> 9 | C10: 12 | D10: 2020 | E10: ='Consommation du 01.12 au 31.12'!M18 -> 9848 | F10: 0.99 | G10: ='Consommation du 01.12 au 31.12'!U18 -> 259.7 | H10: 8.2658 | I10: ='Consommation du 01.12 au 31.12'!Y18*1000 -> 14450 | J10: 0.53 | K10: ='Consommation du 01.12 au 31.12'!D18 -> 190 | L10: 12.67 | M10: ='Consommation du 01.12 au 31.12'!AC18 -> 7 | N10: 7 | O10: =E10*F10+G10*H10+I10*J10+K10*L10 -> 21961.948
A11: Marrakech | B11: =B10+1 -> 10 | C11: 12 | D11: 2020 | E11: ='Consommation du 01.12 au 31.12'!M19 -> 7953 | F11: 0.99 | G11: ='Consommation du 01.12 au 31.12'!U19 -> 148.4 | H11: 8.2658 | I11: ='Consommation du 01.12 au 31.12'!Y19*1000 -> 13980 | J11: 0.53 | K11: ='Consommation du 01.12 au 31.12'!D19 -> 140 | L11: 12.67 | M11: ='Consommation du 01.12 au 31.12'!AC19 -> 7 | N11: 7 | O11: =E11*F11+G11*H11+I11*J11+K11*L11 -> 18283.315
A12: Marrakech | B12: =B11+1 -> 11 | C12: 12 | D12: 2020 | E12: ='Consommation du 01.12 au 31.12'!M20 -> 10151 | F12: 0.99 | G12: ='Consommation du 01.12 au 31.12'!U20 -> 333.9 | H12: 8.2658 | I12: ='Consommation du 01.12 au 31.12'!Y20*1000 -> 10000 | J12: 0.53 | K12: ='Consommation du 01.12 au 31.12'!D20 -> 170 | L12: 12.67 | M12: ='Consommation du 01.12 au 31.12'!AC20 -> 17 | N12: 17 | O12: =E12*F12+G12*H12+I12*J12+K12*L12 -> 20263.341
A13: Marrakech | B13: =B12+1 -> 12 | C13: 12 | D13: 2020 | E13: ='Consommation du 01.12 au 31.12'!M21 -> 9631 | F13: 0.99 | G13: ='Consommation du 01.12 au 31.12'!U21 -> 445.2 | H13: 8.2658 | I13: ='Consommation du 01.12 au 31.12'!Y21*1000 -> 12740 | J13: 0.53 | K13: ='Consommation du 01.12 au 31.12'!D21 -> 200 | L13: 12.67 | M13: ='Consommation du 01.12 au 31.12'!AC21 -> 23 | N13: 23 | O13: =E13*F13+G13*H13+I13*J13+K13*L13 -> 22500.824
A14: Marrakech | B14: =B13+1 -> 13 | C14: 12 | D14: 2020 | E14: ='Consommation du 01.12 au 31.12'!M22 -> 9236 | F14: 0.99 | G14: ='Consommation du 01.12 au 31.12'!U22 -> 296.8 | H14: 8.2658 | I14: ='Consommation du 01.12 au 31.12'!Y22*1000 -> 11250 | J14: 0.53 | K14: ='Consommation du 01.12 au 31.12'!D22 -> 380 | L14: 12.67 | M14: ='Consommation du 01.12 au 31.12'!AC22 -> 10 | N14: 10 | O14: =E14*F14+G14*H14+I14*J14+K14*L14 -> 22374.029
... A29: Marrakech | B29: =B28+1 -> 28 | C29: 12 | D29: 2020 | E29: ='Consommation du 01.12 au 31.12'!M37 -> 11753 | F29: 0.99 | G29: ='Consommation du 01.12 au 31.12'!U37 -> 779.1 | H29: 8.2658 | I29: ='Consommation du 01.12 au 31.12'!Y37*1000 -> 14960 | J29: 0.53 | K29: ='Consommation du 01.12 au 31.12'!D37 -> 370 | L29: 12.67 | M29: ='Consommation du 01.12 au 31.12'!AC37 -> 66 | N29: 66 | O29: =E29*F29+G29*H29+I29*J29+K29*L29 -> 30692.055
A30: Marrakech | B30: =B29+1 -> 29 | C30: 12 | D30: 2020 | E30: ='Consommation du 01.12 au 31.12'!M38 -> 0 | F30: 0.99 | G30: ='Consommation du 01.12 au 31.12'!U38 -> 0 | H30: 8.2658 | I30: ='Consommation du 01.12 au 31.12'!Y38*1000 -> 0 | J30: 0.53 | K30: ='Consommation du 01.12 au 31.12'!D38 -> 0 | L30: 12.67 | M30: ='Consommation du 01.12 au 31.12'!AC38 -> 0 | O30: =E30*F30+G30*H30+I30*J30+K30*L30 -> 0
A31: Marrakech | B31: =B30+1 -> 30 | C31: 12 | D31: 2020 | E31: ='Consommation du 01.12 au 31.12'!M39 -> 0 | F31: 0.99 | G31: ='Consommation du 01.12 au 31.12'!U39 -> 0 | H31: 8.2658 | I31: ='Consommation du 01.12 au 31.12'!Y39*1000 -> 0 | J31: 0.53 | K31: ='Consommation du 01.12 au 31.12'!D39 -> 0 | L31: 12.67 | M31: ='Consommation du 01.12 au 31.12'!AC39 -> 0 | O31: =E31*F31+G31*H31+I31*J31+K31*L31 -> 0
A32: Marrakech | B32: =B31+1 -> 31 | C32: 12 | D32: 2020 | E32: ='Consommation du 01.12 au 31.12'!M40 -> 0 | F32: 1.99 | G32: ='Consommation du 01.12 au 31.12'!U40 -> 0 | H32: 8.2658 | I32: ='Consommation du 01.12 au 31.12'!Y40*1000 -> 0 | J32: 1.53 | K32: ='Consommation du 01.12 au 31.12'!D40 -> 0 | L32: 13.67 | M32: ='Consommation du 01.12 au 31.12'!AC40 -> 0 | O32: =E32*F32+G32*H32+I32*J32+K32*L32 -> 0
O33: =SUM(O2:O32) -> 683948.52

Sheet Consommation du 01.12 au 31.12
B8: Date | D8: Cons Eau/Hotel | F8: Consommation du jour en DH | M8: total | O8: Consommation du jour en DH | Q8: Cons Elec/Villa | S8: Cons Elec/RIAD | U8: GAZ en Kg | W8: Consommation du jour en DH | X8: Compteur AVEO Mwh | Y8: consommation eau choud en Mwh | Z8: consommation du jour en DH | AB8: Température moyenne du jour °C | AC8: Total Occupation | AD8: % Occupation | AE8: Température Piscine Adulte à 7h00 °C | AF8: Température Piscine Adulte à 15h00 °C | AG8: Température Piscine famille à 07h00 ° C | AH8: Température Piscine famille à 15h00 ° C
J9: creuse 81 | K9: pleine 82 | L9: pointe 83 | AJ9: Consommation totale du jour | AK9: Consommation/Chambre
B10: 44166 | D10: ='Suivi EAU-ELEC'!C15 -> 190 | F10: =D10*12.67 -> 2407.3 | J10: ='Suivi EAU-ELEC'!E15 -> 3638 | K10: ='Suivi EAU-ELEC'!G15 -> 4702 | L10: ='Suivi EAU-ELEC'!I15 -> 2671 | M10: =L10+K10+J10 -> 11011 | O10: =J10*0.99+K10*0.99+L10*0.99 -> 10900.89 | U10: ='Suivi Gaz'!O10 -> 185.5 | W10: =U10*8.2658 -> 1533.3059 | X10: 17827.68 | Y10: =IF(X11<X10,0,X11-X10) -> 13.57 | Z10: =Y10*0.53*1000 -> 7192.1 | AB10: 22 | AC10: 13 | AD10: 0.0942 | AE10: 28 | AF10: 29 | AG10: 20 | AH10: 21 | AJ10: =(F10+O10+W10+Z10) -> 22033.596 | AK10: =AJ10/AC10 -> 1694.892
B11: =(B10+1) -> 44167 | D11: ='Suivi EAU-ELEC'!C16 -> 220 | F11: =D11*12.67 -> 2787.4 | J11: ='Suivi EAU-ELEC'!E16 -> 3907 | K11: ='Suivi EAU-ELEC'!G16 -> 5211 | L11: ='Suivi EAU-ELEC'!I16 -> 2388 | M11: =L11+K11+J11 -> 11506 | O11: =J11*0.99+K11*0.99+L11*0.99 -> 11390.94 | U11: ='Suivi Gaz'!O11 -> 259.7 | W11: =U11*8.2658 -> 2146.6283 | X11: 17841.25 | Y11: =IF(X12<X11,0,X12-X11) -> 14.39 | Z11: =Y11*0.53*1000 -> 7626.7 | AB11: 20 | AC11: 14 | AD11: 0.1007 | AE11: 28 | AF11: 29 | AG11: 17 | AH11: 19 | AJ11: =(F11+O11+W11+Z11) -> 23951.668 | AK11: =AJ11/AC11 -> 1710.8334
B12: =(B11+1) -> 44168 | D12: ='Suivi EAU-ELEC'!C17 -> 210 | F12: =D12*12.67 -> 2660.7 | J12: ='Suivi EAU-ELEC'!E17 -> 2757 | K12: ='Suivi EAU-ELEC'!G17 -> 5102 | L12: ='Suivi EAU-ELEC'!I17 -> 2481 | M12: =L12+K12+J12 -> 10340 | O12: =J12*0.99+K12*0.99+L12*0.99 -> 10236.6 | U12: ='Suivi Gaz'!O12 -> 296.8 | W12: =U12*8.2658 -> 2453.2894 | X12: 17855.64 | Y12: =IF(X13<X12,0,X13-X12) -> 12.63 | Z12: =Y12*0.53*1000 -> 6693.9 | AB12: 20 | AC12: 17 | AD12: 0.1259 | AE12: 28 | AF12: 29 | AG12: 18 | AH12: 18 | AJ12: =(F12+O12+W12+Z12) -> 22044.489 | AK12: =AJ12/AC12 -> 1296.7347
B13: =(B12+1) -> 44169 | D13: ='Suivi EAU-ELEC'!C18 -> 290 | F13: =D13*12.67 -> 3674.3 | J13: ='Suivi EAU-ELEC'!E18 -> 3024 | K13: ='Suivi EAU-ELEC'!G18 -> 4604 | L13: ='Suivi EAU-ELEC'!I18 -> 2102 | M13: =L13+K13+J13 -> 9730 | O13: =J13*0.99+K13*0.99+L13*0.99 -> 9632.7 | U13: ='Suivi Gaz'!O13 -> 333.9 | W13: =U13*8.2658 -> 2759.9506 | X13: 17868.27 | Y13: =IF(X14<X13,0,X14-X13) -> 14.07 | Z13: =Y13*0.53*1000 -> 7457.1 | AB13: 21 | AC13: 18 | AD13: 0.1295 | AE13: 28 | AF13: 28 | AG13: 18 | AH13: 19 | AJ13: =(F13+O13+W13+Z13) -> 23524.051 | AK13: =AJ13/AC13 -> 1306.8917
B14: =(B13+1) -> 44170 | D14: ='Suivi EAU-ELEC'!C19 -> 230 | F14: =D14*12.67 -> 2914.1 | J14: ='Suivi EAU-ELEC'!E19 -> 2839 | K14: ='Suivi EAU-ELEC'!G19 -> 4393 | L14: ='Suivi EAU-ELEC'!I19 -> 2004 | M14: =L14+K14+J14 -> 9236 | O14: =J14*0.99+K14*0.99+L14*0.99 -> 9143.64 | U14: ='Suivi Gaz'!O14 -> 74.2 | W14: =U14*8.2658 -> 613.32236 | X14: 17882.34 | Y14: =IF(X15<X14,0,X15-X14) -> 17.52 | Z14: =Y14*0.53*1000 -> 9285.6 | AB14: 18 | AC14: 20 | AD14: 0.1493 | AE14: 27 | AF14: 28 | AG14: 16 | AH14: 18 | AJ14: =(F14+O14+W14+Z14) -> 21956.662 | AK14: =AJ14/AC14 -> 1097.8331
B15: =(B14+1) -> 44171 | D15: ='Suivi EAU-ELEC'!C20 -> 420 | F15: =D15*12.67 -> 5321.4 | J15: ='Suivi EAU-ELEC'!E20 -> 3060 | K15: ='Suivi EAU-ELEC'!G20 -> 4345 | L15: ='Suivi EAU-ELEC'!I20 -> 2107 | M15: =L15+K15+J15 -> 9512 | O15: =J15*0.99+K15*0.99+L15*0.99 -> 9416.88 | U15: ='Suivi Gaz'!O15 -> 148.4 | W15: =U15*8.2658 -> 1226.6447 | X15: 17899.86 | Y15: =IF(X16<X15,0,X16-X15) -> 18.5 | Z15: =Y15*0.53*1000 -> 9805 | AB15: 18 | AC15: 13 | AD15: 0.0985 | AE15: 27 | AF15: 28 | AG15: 18 | AH15: 19 | AJ15: =(F15+O15+W15+Z15) -> 25769.925 | AK15: =AJ15/AC15 -> 1982.3019
B16: =(B15+1) -> 44172 | D16: ='Suivi EAU-ELEC'!C21 -> 260 | F16: =D16*12.67 -> 3294.2 | J16: ='Suivi EAU-ELEC'!E21 -> 3137 | K16: ='Suivi EAU-ELEC'!G21 -> 4471 | L16: ='Suivi EAU-ELEC'!I21 -> 1946 | M16: =L16+K16+J16 -> 9554 | O16: =J16*0.99+K16*0.99+L16*0.99 -> 9458.46 | U16: ='Suivi Gaz'!O16 -> 111.3 | W16: =U16*8.2658 -> 919.98354 | X16: 17918.36 | Y16: =IF(X17<X16,0,X17-X16) -> 14.63 | Z16: =Y16*0.53*1000 -> 7753.9 | AB16: 20 | AC16: 8 | AD16: 0.0602 | AE16: 26 | AF16: 26 | AG16: 18 | AH16: 19 | AJ16: =(F16+O16+W16+Z16) -> 21426.544 | AK16: =AJ16/AC16 -> 2678.3179
B17: =(B16+1) -> 44173 | D17: ='Suivi EAU-ELEC'!C22 -> 210 | F17: =D17*12.67 -> 2660.7 | J17: ='Suivi EAU-ELEC'!E22 -> 3172 | K17: ='Suivi EAU-ELEC'!G22 -> 4476 | L17: ='Suivi EAU-ELEC'!I22 -> 1955 | M17: =L17+K17+J17 -> 9603 | O17: =J17*0.99+K17*0.99+L17*0.99 -> 9506.97 | U17: ='Suivi Gaz'!O17 -> 185.5 | W17: =U17*8.2658 -> 1533.3059 | X17: 17932.99 | Y17: =IF(X18<X17,0,X18-X17) -> 15.7 | Z17: =Y17*0.53*1000 -> 8321 | AB17: 19 | AC17: 5 | AD17: 0.0373 | AE17: 25 | AF17: 26 | AG17: 18 | AH17: 19 | AJ17: =(F17+O17+W17+Z17) -> 22021.976 | AK17: =AJ17/AC17 -> 4404.3952
B18: =(B17+1) -> 44174 | D18: ='Suivi EAU-ELEC'!C23 -> 190 | F18: =D18*12.67 -> 2407.3 | J18: ='Suivi EAU-ELEC'!E23 -> 3092 | K18: ='Suivi EAU-ELEC'!G23 -> 4616 | L18: ='Suivi EAU-ELEC'!I23 -> 2140 | M18: =L18+K18+J18 -> 9848 | O18: =J18*0.99+K18*0.99+L18*0.99 -> 9749.52 | U18: ='Suivi Gaz'!O18 -> 259.7 | W18: =U18*8.2658 -> 2146.6283 | X18: 17948.69 | Y18: =IF(X19<X18,0,X19-X18) -> 14.45 | Z18: =Y18*0.53*1000 -> 7658.5 | AB18: 18 | AC18: 7 | AD18: 0.0504 | AE18: 26 | AF18: 27 | AG18: 18 | AH18: 19 | AJ18: =(F18+O18+W18+Z18) -> 21961.948 | AK18: =AJ18/AC18 -> 3137.4212
B19: =(B18+1) -> 44175 | D19: ='Suivi EAU-ELEC'!C24 -> 140 | F19: =D19*12.67 -> 1773.8 | J19: ='Suivi EAU-ELEC'!E24 -> 2962 | K19: ='Suivi EAU-ELEC'!G24 -> 3043 | L19: ='Suivi EAU-ELEC'!I24 -> 1948 | M19: =L19+K19+J19 -> 7953 | O19: =J19*0.99+K19*0.99+L19*0.99 -> 7873.47 | U19: ='Suivi Gaz'!O19 -> 148.4 | W19: =U19*8.2658 -> 1226.6447 | X19: 17963.14 | Y19: =IF(X20<X19,0,X20-X19) -> 13.98 | Z19: =Y19*0.53*1000 -> 7409.4 | AB19: 20 | AC19: 7 | AD19: 0.0504 | AE19: 26 | AF19: 27 | AG19: 17 | AH19: 18 | AJ19: =(F19+O19+W19+Z19) -> 18283.315 | AK19: =AJ19/AC19 -> 2611.9021
B20: =(B19+1) -> 44176 | D20: ='Suivi EAU-ELEC'!C25 -> 170 | F20: =D20*12.67 -> 2153.9 | J20: ='Suivi EAU-ELEC'!E25 -> 2418 | K20: ='Suivi EAU-ELEC'!G25 -> 5739 | L20: ='Suivi EAU-ELEC'!I25 -> 1994 | M20: =L20+K20+J20 -> 10151 | O20: =J20*0.99+K20*0.99+L20*0.99 -> 10049.49 | U20: ='Suivi Gaz'!O20 -> 333.9 | W20: =U20*8.2658 -> 2759.9506 | X20: 17977.12 | Y20: =IF(X21<X20,0,X21-X20) -> 10 | Z20: =Y20*0.53*1000 -> 5300 | AA20: 14 | AB20: 19 | AC20: 17 | AD20: 0.1223 | AE20: 28 | AF20: 28 | AG20: 18 | AH20: 19 | AJ20: =(F20+O20+W20+Z20) -> 20263.341 | AK20: =AJ20/AC20 -> 1191.9612
B21: =(B20+1) -> 44177 | D21: ='Suivi EAU-ELEC'!C26 -> 200 | F21: =D21*12.67 -> 2534 | J21: ='Suivi EAU-ELEC'!E26 -> 2939 | K21: ='Suivi EAU-ELEC'!G26 -> 4538 | L21: ='Suivi EAU-ELEC'!I26 -> 2154 | M21: =L21+K21+J21 -> 9631 | O21: =J21*0.99+K21*0.99+L21*0.99 -> 9534.69 | U21: ='Suivi Gaz'!O21 -> 445.2 | W21: =U21*8.2658 -> 3679.9342 | X21: 17987.12 | Y21: =IF(X22<X21,0,X22-X21) -> 12.74 | Z21: =Y21*0.53*1000 -> 6752.2 | AA21: 14 | AB21: 21 | AC21: 23 | AD21: 0.1655 | AE21: 28 | AF21: 28.5 | AG21: 18 | AH21: 19 | AJ21: =(F21+O21+W21+Z21) -> 22500.824 | AK21: =AJ21/AC21 -> 978.2967
B22: =(B21+1) -> 44178 | D22: ='Suivi EAU-ELEC'!C27 -> 380 | F22: =D22*12.67 -> 4814.6 | J22: ='Suivi EAU-ELEC'!E27 -> 2839 | K22: ='Suivi EAU-ELEC'!G27 -> 4393 | L22: ='Suivi EAU-ELEC'!I27 -> 2004 | M22: =L22+K22+J22 -> 9236 | O22: =J22*0.99+K22*0.99+L22*0.99 -> 9143.64 | U22: ='Suivi Gaz'!O22 -> 296.8 | W22: =U22*8.2658 -> 2453.2894 | X22: 17999.86 | Y22: =IF(X23<X22,0,X23-X22) -> 11.25 | Z22: =Y22*0.53*1000 -> 5962.5 | AB22: 20 | AC22: 10 | AD22: 0.0787 | AE22: 28 | AF22: 28 | AG22: 18 | AH22: 20 | AJ22: =(F22+O22+W22+Z22) -> 22374.029 | AK22: =AJ22/AC22 -> 2237.4029
B23: =(B22+1) -> 44179 | D23: ='Suivi EAU-ELEC'!C28 -> 140 | F23: =D23*12.67 -> 1773.8 | J23: ='Suivi EAU-ELEC'!E28 -> 3298 | K23: ='Suivi EAU-ELEC'!G28 -> 4263 | L23: ='Suivi EAU-ELEC'!I28 -> 1805 | M23: =L23+K23+J23 -> 9366 | O23: =J23*0.99+K23*0.99+L23*0.99 -> 9272.34 | U23: ='Suivi Gaz'!O23 -> 296.8 | W23: =U23*8.2658 -> 2453.2894 | X23: 18011.11 | Y23: =IF(X24<X23,0,X24-X23) -> 10.81 | Z23: =Y23*0.53*1000 -> 5729.3 | AB23: 20 | AC23: 5 | AD23: 0.0382 | AE23: 28 | AF23: 29 | AG23: 18 | AH23: 19 | AJ23: =(F23+O23+W23+Z23) -> 19228.729 | AK23: =AJ23/AC23 -> 3845.7459
B24: =(B23+1) -> 44180 | D24: ='Suivi EAU-ELEC'!C29 -> 170 | F24: =D24*12.67 -> 2153.9 | J24: ='Suivi EAU-ELEC'!E29 -> 2418 | K24: ='Suivi EAU-ELEC'!G29 -> 4340 | L24: ='Suivi EAU-ELEC'!I29 -> 1900 | M24: =L24+K24+J24 -> 8658 | O24: =J24*0.99+K24*0.99+L24*0.99 -> 8571.42 | U24: ='Suivi Gaz'!O24 -> 296.8 | W24: =U24*8.2658 -> 2453.2894 | X24: 18021.92 | Y24: =IF(X25<X24,0,X25-X24) -> 4.65 | Z24: =Y24*0.53*1000 -> 2464.5 | AB24: 21 | AC24: 8 | AD24: 0.0584 | AE24: 26 | AF24: 26 | AG24: 18 | AH24: 19 | AJ24: =(F24+O24+W24+Z24) -> 15643.109 | AK24: =AJ24/AC24 -> 1955.3887
B25: =(B24+1) -> 44181 | D25: ='Suivi EAU-ELEC'!C30 -> 190 | F25: =D25*12.67 -> 2407.3 | J25: ='Suivi EAU-ELEC'!E30 -> 3762 | K25: ='Suivi EAU-ELEC'!G30 -> 4301 | L25: ='Suivi EAU-ELEC'!I30 -> 2163 | M25: =L25+K25+J25 -> 10226 | O25: =J25*0.99+K25*0.99+L25*0.99 -> 10123.74 | U25: ='Suivi Gaz'!O25 -> 222.6 | W25: =U25*8.2658 -> 1839.9671 | X25: 18026.57 | Y25: =IF(X26<X25,0,X26-X25) -> 10.5 | Z25: =Y25*0.53*1000 -> 5565 | AB25: 15 | AC25: 5 | AD25: 0.0365 | AE25: 24 | AF25: 24 | AG25: 18 | AH25: 18 | AJ25: =(F25+O25+W25+Z25) -> 19936.007 | AK25: =AJ25/AC25 -> 3987.2014
B26: =(B25+1) -> 44182 | D26: ='Suivi EAU-ELEC'!C31 -> 410 | F26: =D26*12.67 -> 5194.7 | J26: ='Suivi EAU-ELEC'!E31 -> 4119 | K26: ='Suivi EAU-ELEC'!G31 -> 5058 | L26: ='Suivi EAU-ELEC'!I31 -> 2258 | M26: =L26+K26+J26 -> 11435 | O26: =J26*0.99+K26*0.99+L26*0.99 -> 11320.65 | U26: ='Suivi Gaz'!O26 -> 333.9 | W26: =U26*8.2658 -> 2759.9506 | X26: 18037.07 | Y26: =IF(X27<X26,0,X27-X26) -> 19.69 | Z26: =Y26*0.53*1000 -> 10435.7 | AB26: 16 | AC26: 7 | AD26: 0.0511 | AE26: 26 | AF26: 27 | AG26: 18 | AH26: 21 | AJ26: =(F26+O26+W26+Z26) -> 29711.001 | AK26: =AJ26/AC26 -> 4244.4287
B27: =(B26+1) -> 44183 | D27: ='Suivi EAU-ELEC'!C32 -> 200 | F27: =D27*12.67 -> 2534 | J27: ='Suivi EAU-ELEC'!E32 -> 2973 | K27: ='Suivi EAU-ELEC'!G32 -> 4531 | L27: ='Suivi EAU-ELEC'!I32 -> 2090 | M27: =L27+K27+J27 -> 9594 | O27: =J27*0.99+K27*0.99+L27*0.99 -> 9498.06 | U27: ='Suivi Gaz'!O27 -> 148.4 | W27: =U27*8.2658 -> 1226.6447 | X27: 18056.76 | Y27: =IF(X28<X27,0,X28-X27) -> 17.12 | Z27: =Y27*0.53*1000 -> 9073.6 | AB27: 16 | AC27: 17 | AD27: 0.125 | AE27: 27 | AF27: 28 | AG27: 23 | AH27: 24 | AJ27: =(F27+O27+W27+Z27) -> 22332.305 | AK27: =AJ27/AC27 -> 1313.665
B28: =(B27+1) -> 44184 | D28: ='Suivi EAU-ELEC'!C33 -> 210 | F28: =D28*12.67 -> 2660.7 | J28: ='Suivi EAU-ELEC'!E33 -> 3160 | K28: ='Suivi EAU-ELEC'!G33 -> 4615 | L28: ='Suivi EAU-ELEC'!I33 -> 2251 | M28: =L28+K28+J28 -> 10026 | O28: =J28*0.99+K28*0.99+L28*0.99 -> 9925.74 | U28: ='Suivi Gaz'!O28 -> 482.3 | W28: =U28*8.2658 -> 3986.5953 | X28: 18073.88 | Y28: =IF(X29<X28,0,X29-X28) -> 14.83 | Z28: =Y28*0.53*1000 -> 7859.9 | AB28: 16 | AC28: 33 | AD28: 0.2409 | AE28: 27 | AF28: 28 | AG28: 25 | AH28: 26 | AJ28: =(F28+O28+W28+Z28) -> 24432.935 | AK28: =AJ28/AC28 -> 740.39198
B29: =(B28+1) -> 44185 | D29: ='Suivi EAU-ELEC'!C34 -> 290 | F29: =D29*12.67 -> 3674.3 | J29: ='Suivi EAU-ELEC'!E34 -> 3145 | K29: ='Suivi EAU-ELEC'!G34 -> 4955 | L29: ='Suivi EAU-ELEC'!I34 -> 2267 | M29: =L29+K29+J29 -> 10367 | O29: =J29*0.99+K29*0.99+L29*0.99 -> 10263.33 | U29: ='Suivi Gaz'!O29 -> 408.1 | W29: =U29*8.2658 -> 3373.273 | X29: 18088.71 | Y29: =IF(X30<X29,0,X30-X29) -> 18.4 | Z29: =Y29*0.53*1000 -> 9752 | AB29: 18 | AC29: 37 | AD29: 0.2824 | AE29: 27 | AF29: 28 | AG29: 24 | AH29: 25 | AJ29: =(F29+O29+W29+Z29) -> 27062.903 | AK29: =AJ29/AC29 -> 731.42981
B30: =(B29+1) -> 44186 | D30: ='Suivi EAU-ELEC'!C35 -> 280 | F30: =D30*12.67 -> 3547.6 | J30: ='Suivi EAU-ELEC'!E35 -> 3203 | K30: ='Suivi EAU-ELEC'!G35 -> 5315 | L30: ='Suivi EAU-ELEC'!I35 -> 2350 | M30: =L30+K30+J30 -> 10868 | O30: =J30*0.99+K30*0.99+L30*0.99 -> 10759.32 | U30: ='Suivi Gaz'!O30 -> 779.1 | W30: =U30*8.2658 -> 6439.8848 | X30: 18107.11 | Y30: =IF(X31<X30,0,X31-X30) -> 13.34 | Z30: =Y30*0.53*1000 -> 7070.2 | AB30: 18 | AC30: 45 | AD30: 0.3462 | AE30: 27 | AF30: 28 | AG30: 25 | AH30: 25 | AJ30: =(F30+O30+W30+Z30) -> 27817.005 | AK30: =AJ30/AC30 -> 618.15566
B31: =(B30+1) -> 44187 | D31: ='Suivi EAU-ELEC'!C36 -> 310 | F31: =D31*12.67 -> 3927.7 | J31: ='Suivi EAU-ELEC'!E36 -> 3491 | K31: ='Suivi EAU-ELEC'!G36 -> 5519 | L31: ='Suivi EAU-ELEC'!I36 -> 2514 | M31: =L31+K31+J31 -> 11524 | O31: =J31*0.99+K31*0.99+L31*0.99 -> 11408.76 | U31: ='Suivi Gaz'!O31 -> 519.4 | W31: =U31*8.2658 -> 4293.2565 | X31: 18120.45 | Y31: =IF(X32<X31,0,X32-X31) -> 19.3 | Z31: =Y31*0.53*1000 -> 10229 | AB31: 20 | AC31: 54 | AD31: 0.4615 | AE31: 26 | AF31: 26 | AG31: 25.5 | AH31: 26 | AJ31: =(F31+O31+W31+Z31) -> 29858.717 | AK31: =AJ31/AC31 -> 552.93919
B32: =(B31+1) -> 44188 | D32: ='Suivi EAU-ELEC'!C37 -> 270 | F32: =D32*12.67 -> 3420.9 | J32: ='Suivi EAU-ELEC'!E37 -> 3454 | K32: ='Suivi EAU-ELEC'!G37 -> 5325 | L32: ='Suivi EAU-ELEC'!I37 -> 2312 | M32: =L32+K32+J32 -> 11091 | O32: =J32*0.99+K32*0.99+L32*0.99 -> 10980.09 | U32: ='Suivi Gaz'!O32 -> 742 | W32: =U32*8.2658 -> 6133.2236 | X32: 18139.75 | Y32: =IF(X33<X32,0,X33-X32) -> 17.23 | Z32: =Y32*0.53*1000 -> 9131.9 | AB32: 18 | AC32: 50 | AD32: 0.4386 | AE32: 26 | AF32: 28.5 | AG32: 26 | AH32: 27.5 | AJ32: =(F32+O32+W32+Z32) -> 29666.114 | AK32: =AJ32/AC32 -> 593.32227
B33: =(B32+1) -> 44189 | D33: ='Suivi EAU-ELEC'!C38 -> 230 | F33: =D33*12.67 -> 2914.1 | J33: ='Suivi EAU-ELEC'!E38 -> 3996 | K33: ='Suivi EAU-ELEC'!G38 -> 5200 | L33: ='Suivi EAU-ELEC'!I38 -> 2546 | M33: =L33+K33+J33 -> 11742 | O33: =J33*0.99+K33*0.99+L33*0.99 -> 11624.58 | U33: ='Suivi Gaz'!O33 -> 704.9 | W33: =U33*8.2658 -> 5826.5624 | X33: 18156.98 | Y33: =IF(X34<X33,0,X34-X33) -> 17.77 | Z33: =Y33*0.53*1000 -> 9418.1 | AB33: 17 | AC33: 47 | AD33: 0.4123 | AE33: 27.5 | AF33: 28.5 | AG33: 26 | AH33: 26.5 | AJ33: =(F33+O33+W33+Z33) -> 29783.342 | AK33: =AJ33/AC33 -> 633.68814
... B37: =(B36+1) -> 44193 | D37: ='Suivi EAU-ELEC'!C42 -> 370 | F37: =D37*12.67 -> 4687.9 | J37: ='Suivi EAU-ELEC'!E42 -> 3678 | K37: ='Suivi EAU-ELEC'!G42 -> 5499 | L37: ='Suivi EAU-ELEC'!I42 -> 2576 | M37: =L37+K37+J37 -> 11753 | O37: =J37*0.99+K37*0.99+L37*0.99 -> 11635.47 | U37: ='Suivi Gaz'!O37 -> 779.1 | W37: =U37*8.2658 -> 6439.8848 | X37: 18221.49 | Y37: =IF(X38<X37,0,X38-X37) -> 14.96 | Z37: =Y37*0.53*1000 -> 7928.8 | AB37: 18 | AC37: 66 | AD37: 0.5641 | AE37: 27.5 | AF37: 28.5 | AG37: 27.5 | AH37: 28 | AJ37: =(F37+O37+W37+Z37) -> 30692.055 | AK37: =AJ37/AC37 -> 465.03113
B38: =(B37+1) -> 44194 | D38: ='Suivi EAU-ELEC'!C43 -> 0 | F38: =D38*12.67 -> 0 | J38: ='Suivi EAU-ELEC'!E43 -> 0 | K38: ='Suivi EAU-ELEC'!G43 -> 0 | L38: ='Suivi EAU-ELEC'!I43 -> 0 | M38: =L38+K38+J38 -> 0 | O38: =J38*0.99+K38*0.99+L38*0.99 -> 0 | U38: ='Suivi Gaz'!O38 -> 0 | W38: =U38*8.2658 -> 0 | X38: 18236.45 | Y38: =IF(X39<X38,0,X39-X38) -> 0 | Z38: =Y38*0.53*1000 -> 0 | AJ38: =(F38+O38+W38+Z38) -> 0 | AK38: =AJ38/AC38 -> #DIV/0!
B39: =(B38+1) -> 44195 | D39: ='Suivi EAU-ELEC'!C44 -> 0 | F39: =D39*12.67 -> 0 | J39: ='Suivi EAU-ELEC'!E44 -> 0 | K39: ='Suivi EAU-ELEC'!G44 -> 0 | L39: ='Suivi EAU-ELEC'!I44 -> 0 | M39: =L39+K39+J39 -> 0 | O39: =J39*0.99+K39*0.99+L39*0.99 -> 0 | U39: ='Suivi Gaz'!O39 -> 0 | W39: =U39*8.2658 -> 0 | Y39: =IF(X40<X39,0,X40-X39) -> 0 | Z39: =Y39*0.53*1000 -> 0 | AJ39: =(F39+O39+W39+Z39) -> 0 | AK39: =AJ39/AC39 -> #DIV/0!
B40: =(B39+1) -> 44196 | D40: ='Suivi EAU-ELEC'!C45 -> 0 | F40: =D40*12.67 -> 0 | J40: ='Suivi EAU-ELEC'!E45 -> 0 | K40: ='Suivi EAU-ELEC'!G45 -> 0 | L40: ='Suivi EAU-ELEC'!I45 -> 0 | M40: =L40+K40+J40 -> 0 | O40: =J40*0.99+K40*0.99+L40*0.99 -> 0 | U40: ='Suivi Gaz'!O40 -> 0 | W40: =U40*8.2658 -> 0 | Y40: =IF(X41<X40,0,X41-X40) -> 0 | Z40: =Y40*0.53*1000 -> 0 | AJ40: =(F40+O40+W40+Z40) -> 0 | AK40: =AJ40/AC40 -> #DIV/0!
D41: ='Suivi EAU-ELEC'!C46 -> 0 | F41: =SUM(F10:H40) -> 89576.9 | J41: =SUM(J10:J40) -> 90343 | K41: =SUM(K10:K40) -> 134985 | L41: =SUM(L10:L40) -> 62354 | M41: =SUM(M10:M40) -> 287682 | O41: =SUM(O10:O40) -> 284805.18 | Q41: =SUM(Q10:Q40) -> 0 | S41: =SUM(S10:S40) -> 0 | U41: =SUM(U10:U40) -> 11241.3 | W41: =SUM(W10:W40) -> 92918.338 | Y41: =SUM(Y10:Y40) -> 408.77 | Z41: =SUM(Z10:Z40) -> 216648.1 | AJ41: =SUM(AJ10:AJ38) -> 683948.52 | AK41: =SUM(AK10:AK38) -> #DIV/0!
A43: ELECTRICITE / Kw/h | D43: creuse 81 | F43: 0.64895 | G43: =J41 -> 90343 | J43: =G43*F43 -> 58628.09 | L43: =J43+J44+J45 -> 255665.24
D44: pleine 82 | F44: 0.88605 | G44: =K41 -> 134985 | J44: =G44*F44 -> 119603.46
D45: pointe 83 | F45: 1.24184 | G45: =L41 -> 62354 | J45: =G45*F45 -> 77433.691
A46: EAU HOTEL M3 | F46: 12.67 | G46: =D41 -> 0 | J46: =G46*F46 -> 0 | L46: =J46 -> 0
A47: GAZ Kg | F47: 8.2658 | G47: =U41 -> 11241.3 | J47: =G47*F47 -> 92918.338 | L47: =J47 -> 92918.338

Sheet Suivi Gaz
D1: suivi Gaz
Q2: 803 | T2: 519 | W2: 800 | Z2: 802
B3: Relvé C1 | C3: cons C1 | D3: Relvé C2 | E3: cons C2 | F3: Relvé C3 | G3: cons C3 | H3: Relvé C4 | I3: cons C4 | J3: ∑ des relevés | K3: moyen general % | L3: con.j | M3: ∑ de volume en L | N3: cons./jen L | O3: cons./jen Kg | P3: cons./jen DH | Q3: livraison C1 | R3: %Avant | S3: % Après | T3: livraison C2 | U3: %Avant | V3: % Après | W3: livraison C3 | X3: %Avant | Y3: % Après | Z3: livraison C4 | AA3: %Avant | AB3: % Après | AC3: total livraison | AD3: moyen general % Avant L | AE3: moyen general % Aaprés L
A4: 44160 | B4: 77 | C4: =IF(AC4>0,((B4-R4)+(S4-B5)),IF(B5=0, ,(B4-B5))) -> 0 | D4: 73 | E4: =IF(AC4>0,((D4-U4)+(V4-D5)),IF(D5=0, ,(D4-D5))) -> 0 | F4: 80 | G4: =IF(AC4>0,((F4-X4)+(Y4-F5)),IF(F5=0, ,(F4-F5))) -> 2 | H4: 76 | I4: =IF(AC4>0,((H4-AA4)+(AB4-H5)),IF(H5=0, ,(H4-H5))) -> 1 | J4: =B4+D4+F4+H4 -> 306 | K4: =J4/4 -> 76.5 | L4: =IF(AC4>0,((K4-AD4)+(AE4-K5)),IF(K5=0, ,(K4-K5))) -> 0.75 | M4: =7000*4 -> 28000 | N4: =L4*M4/100 -> 210 | O4: =N4*0.53 -> 111.3 | P4: =O4*8.1757 -> 909.95541 | AC4: =Q4+T4+W4+Z4 -> 0 | AD4: =(R4+U4+X4+AA4)/4 -> 0 | AE4: =(S4+V4+Y4+AB4)/4 -> 0
A5: =(A4+1) -> 44161 | B5: 77 | C5: =IF(AC5>0,((B5-R5)+(S5-B6)),IF(B6=0, ,(B5-B6))) -> 3 | D5: 73 | E5: =IF(AC5>0,((D5-U5)+(V5-D6)),IF(D6=0, ,(D5-D6))) -> 0 | F5: 78 | G5: =IF(AC5>0,((F5-X5)+(Y5-F6)),IF(F6=0, ,(F5-F6))) -> 6 | H5: 75 | I5: =IF(AC5>0,((H5-AA5)+(AB5-H6)),IF(H6=0, ,(H5-H6))) -> 1 | J5: =B5+D5+F5+H5 -> 303 | K5: =J5/4 -> 75.75 | L5: =IF(AC5>0,((K5-AD5)+(AE5-K6)),IF(K6=0, ,(K5-K6))) -> 2.5 | M5: =7000*4 -> 28000 | N5: =L5*M5/100 -> 700 | O5: =N5*0.53 -> 371 | P5: =O5*8.1757 -> 3033.1847 | AC5: =Q5+T5+W5+Z5 -> 0 | AD5: =(R5+U5+X5+AA5)/4 -> 0 | AE5: =(S5+V5+Y5+AB5)/4 -> 0
A6: =(A5+1) -> 44162 | B6: 74 | C6: =IF(AC6>0,((B6-R6)+(S6-B7)),IF(B7=0, ,(B6-B7))) -> 2 | D6: 73 | E6: =IF(AC6>0,((D6-U6)+(V6-D7)),IF(D7=0, ,(D6-D7))) -> 2 | F6: 72 | G6: =IF(AC6>0,((F6-X6)+(Y6-F7)),IF(F7=0, ,(F6-F7))) -> 2 | H6: 74 | I6: =IF(AC6>0,((H6-AA6)+(AB6-H7)),IF(H7=0, ,(H6-H7))) -> 2 | J6: =B6+D6+F6+H6 -> 293 | K6: =J6/4 -> 73.25 | L6: =IF(AC6>0,((K6-AD6)+(AE6-K7)),IF(K7=0, ,(K6-K7))) -> 2 | M6: =7000*4 -> 28000 | N6: =L6*M6/100 -> 560 | O6: =N6*0.53 -> 296.8 | P6: =O6*8.1757 -> 2426.5478 | AC6: =Q6+T6+W6+Z6 -> 0 | AD6: =(R6+U6+X6+AA6)/4 -> 0 | AE6: =(S6+V6+Y6+AB6)/4 -> 0
A7: =(A6+1) -> 44163 | B7: 72 | C7: =IF(AC7>0,((B7-R7)+(S7-B8)),IF(B8=0, ,(B7-B8))) -> 0 | D7: 71 | E7: =IF(AC7>0,((D7-U7)+(V7-D8)),IF(D8=0, ,(D7-D8))) -> 1 | F7: 70 | G7: =IF(AC7>0,((F7-X7)+(Y7-F8)),IF(F8=0, ,(F7-F8))) -> 1 | H7: 72 | I7: =IF(AC7>0,((H7-AA7)+(AB7-H8)),IF(H8=0, ,(H7-H8))) -> 1 | J7: =B7+D7+F7+H7 -> 285 | K7: =J7/4 -> 71.25 | L7: =IF(AC7>0,((K7-AD7)+(AE7-K8)),IF(K8=0, ,(K7-K8))) -> 0.75 | M7: =7000*4 -> 28000 | N7: =L7*M7/100 -> 210 | O7: =N7*0.53 -> 111.3 | P7: =O7*8.1757 -> 909.95541 | AC7: =Q7+T7+W7+Z7 -> 0 | AD7: =(R7+U7+X7+AA7)/4 -> 0 | AE7: =(S7+V7+Y7+AB7)/4 -> 0
A8: =(A7+1) -> 44164 | B8: 72 | C8: =IF(AC8>0,((B8-R8)+(S8-B9)),IF(B9=0, ,(B8-B9))) -> 2 | D8: 70 | E8: =IF(AC8>0,((D8-U8)+(V8-D9)),IF(D9=0, ,(D8-D9))) -> 1 | F8: 69 | G8: =IF(AC8>0,((F8-X8)+(Y8-F9)),IF(F9=0, ,(F8-F9))) -> 2 | H8: 71 | I8: =IF(AC8>0,((H8-AA8)+(AB8-H9)),IF(H9=0, ,(H8-H9))) -> 1 | J8: =B8+D8+F8+H8 -> 282 | K8: =J8/4 -> 70.5 | L8: =IF(AC8>0,((K8-AD8)+(AE8-K9)),IF(K9=0, ,(K8-K9))) -> 1.5 | M8: =7000*4 -> 28000 | N8: =L8*M8/100 -> 420 | O8: =N8*0.53 -> 222.6 | P8: =O8*8.1757 -> 1819.9108 | AC8: =Q8+T8+W8+Z8 -> 0 | AD8: =(R8+U8+X8+AA8)/4 -> 0 | AE8: =(S8+V8+Y8+AB8)/4 -> 0
A9: =(A8+1) -> 44165 | B9: 70 | C9: =IF(AC9>0,((B9-R9)+(S9-B10)),IF(B10=0, ,(B9-B10))) -> 2 | D9: 69 | E9: =IF(AC9>0,((D9-U9)+(V9-D10)),IF(D10=0, ,(D9-D10))) -> 1 | F9: 67 | H9: 70 | I9: =IF(AC9>0,((H9-AA9)+(AB9-H10)),IF(H10=0, ,(H9-H10))) -> 1 | J9: =B9+D9+F9+H9 -> 276 | K9: =J9/4 -> 69 | L9: =IF(AC9>0,((K9-AD9)+(AE9-K10)),IF(K10=0, ,(K9-K10))) -> 1.25 | M9: =7000*4 -> 28000 | N9: =L9*M9/100 -> 350 | O9: =N9*0.53 -> 185.5 | P9: =O9*8.1757 -> 1516.5924 | AC9: =Q9+T9+W9+Z9 -> 0 | AD9: =(R9+U9+X9+AA9)/4 -> 0 | AE9: =(S9+V9+Y9+AB9)/4 -> 0
A10: =(A9+1) -> 44166 | B10: 68 | C10: =IF(AC10>0,((B10-R10)+(S10-B11)),IF(B11=0, ,(B10-B11))) -> 0 | D10: 68 | E10: =IF(AC10>0,((D10-U10)+(V10-D11)),IF(D11=0, ,(D10-D11))) -> 0 | F10: 66 | G10: =IF(AC10>0,((F10-X10)+(Y10-F11)),IF(F11=0, ,(F10-F11))) -> 1 | H10: 69 | I10: =IF(AC10>0,((H10-AA10)+(AB10-H11)),IF(H11=0, ,(H10-H11))) -> 4 | J10: =B10+D10+F10+H10 -> 271 | K10: =J10/4 -> 67.75 | L10: =IF(AC10>0,((K10-AD10)+(AE10-K11)),IF(K11=0, ,(K10-K11))) -> 1.25 | M10: =7000*4 -> 28000 | N10: =L10*M10/100 -> 350 | O10: =N10*0.53 -> 185.5 | P10: =O10*8.2658 -> 1533.3059 | AC10: =Q10+T10+W10+Z10 -> 0 | AD10: =(R10+U10+X10+AA10)/4 -> 0 | AE10: =(S10+V10+Y10+AB10)/4 -> 0
A11: =(A10+1) -> 44167 | B11: 68 | C11: =IF(AC11>0,((B11-R11)+(S11-B12)),IF(B12=0, ,(B11-B12))) -> 1 | D11: 68 | E11: =IF(AC11>0,((D11-U11)+(V11-D12)),IF(D12=0, ,(D11-D12))) -> 0 | F11: 65 | G11: =IF(AC11>0,((F11-X11)+(Y11-F12)),IF(F12=0, ,(F11-F12))) -> 3 | H11: 65 | I11: =IF(AC11>0,((H11-AA11)+(AB11-H12)),IF(H12=0, ,(H11-H12))) -> 3 | J11: =B11+D11+F11+H11 -> 266 | K11: =J11/4 -> 66.5 | L11: =IF(AC11>0,((K11-AD11)+(AE11-K12)),IF(K12=0, ,(K11-K12))) -> 1.75 | M11: =7000*4 -> 28000 | N11: =L11*M11/100 -> 490 | O11: =N11*0.53 -> 259.7 | P11: =O11*8.2658 -> 2146.6283 | AC11: =Q11+T11+W11+Z11 -> 0 | AD11: =(R11+U11+X11+AA11)/4 -> 0 | AE11: =(S11+V11+Y11+AB11)/4 -> 0
A12: =(A11+1) -> 44168 | B12: 67 | C12: =IF(AC12>0,((B12-R12)+(S12-B13)),IF(B13=0, ,(B12-B13))) -> 3 | D12: 68 | E12: =IF(AC12>0,((D12-U12)+(V12-D13)),IF(D13=0, ,(D12-D13))) -> 2 | F12: 62 | G12: =IF(AC12>0,((F12-X12)+(Y12-F13)),IF(F13=0, ,(F12-F13))) -> 2 | H12: 62 | I12: =IF(AC12>0,((H12-AA12)+(AB12-H13)),IF(H13=0, ,(H12-H13))) -> 1 | J12: =B12+D12+F12+H12 -> 259 | K12: =J12/4 -> 64.75 | L12: =IF(AC12>0,((K12-AD12)+(AE12-K13)),IF(K13=0, ,(K12-K13))) -> 2 | M12: =7000*4 -> 28000 | N12: =L12*M12/100 -> 560 | O12: =N12*0.53 -> 296.8 | P12: =O12*8.2658 -> 2453.2894 | AC12: =Q12+T12+W12+Z12 -> 0 | AD12: =(R12+U12+X12+AA12)/4 -> 0 | AE12: =(S12+V12+Y12+AB12)/4 -> 0
A13: =(A12+1) -> 44169 | B13: 64 | C13: =IF(AC13>0,((B13-R13)+(S13-B14)),IF(B14=0, ,(B13-B14))) -> 0 | D13: 66 | E13: =IF(AC13>0,((D13-U13)+(V13-D14)),IF(D14=0, ,(D13-D14))) -> 0 | F13: 60 | G13: =IF(AC13>0,((F13-X13)+(Y13-F14)),IF(F14=0, ,(F13-F14))) -> 5 | H13: 61 | I13: =IF(AC13>0,((H13-AA13)+(AB13-H14)),IF(H14=0, ,(H13-H14))) -> 4 | J13: =B13+D13+F13+H13 -> 251 | K13: =J13/4 -> 62.75 | L13: =IF(AC13>0,((K13-AD13)+(AE13-K14)),IF(K14=0, ,(K13-K14))) -> 2.25 | M13: =7000*4 -> 28000 | N13: =L13*M13/100 -> 630 | O13: =N13*0.53 -> 333.9 | P13: =O13*8.2658 -> 2759.9506 | W13: 1193 | X13: 59 | Y13: 70 | Z13: 1165 | AA13: 62 | AB13: 71 | AC13: =Q13+T13+W13+Z13 -> 2358 | AD13: =(R13+U13+X13+AA13)/4 -> 30.25 | AE13: =(S13+V13+Y13+AB13)/4 -> 35.25
A14: =(A13+1) -> 44170 | B14: 64 | C14: =IF(AC14>0,((B14-R14)+(S14-B15)),IF(B15=0, ,(B14-B15))) -> 0 | D14: 66 | E14: =IF(AC14>0,((D14-U14)+(V14-D15)),IF(D15=0, ,(D14-D15))) -> 0 | F14: 66 | G14: =IF(AC14>0,((F14-X14)+(Y14-F15)),IF(F15=0, ,(F14-F15))) -> 1 | H14: 66 | I14: =IF(AC14>0,((H14-AA14)+(AB14-H15)),IF(H15=0, ,(H14-H15))) -> 1 | J14: =B14+D14+F14+H14 -> 262 | K14: =J14/4 -> 65.5 | L14: =IF(AC14>0,((K14-AD14)+(AE14-K15)),IF(K15=0, ,(K14-K15))) -> 0.5 | M14: =7000*4 -> 28000 | N14: =L14*M14/100 -> 140 | O14: =N14*0.53 -> 74.2 | P14: =O14*8.2658 -> 613.32236 | AC14: =Q14+T14+W14+Z14 -> 0 | AD14: =(R14+U14+X14+AA14)/4 -> 0 | AE14: =(S14+V14+Y14+AB14)/4 -> 0
A15: =(A14+1) -> 44171 | B15: 64 | C15: =IF(AC15>0,((B15-R15)+(S15-B16)),IF(B16=0, ,(B15-B16))) -> 0 | D15: 66 | E15: =IF(AC15>0,((D15-U15)+(V15-D16)),IF(D16=0, ,(D15-D16))) -> 0 | F15: 65 | G15: =IF(AC15>0,((F15-X15)+(Y15-F16)),IF(F16=0, ,(F15-F16))) -> 2 | H15: 65 | I15: =IF(AC15>0,((H15-AA15)+(AB15-H16)),IF(H16=0, ,(H15-H16))) -> 2 | J15: =B15+D15+F15+H15 -> 260 | K15: =J15/4 -> 65 | L15: =IF(AC15>0,((K15-AD15)+(AE15-K16)),IF(K16=0, ,(K15-K16))) -> 1 | M15: =7000*4 -> 28000 | N15: =L15*M15/100 -> 280 | O15: =N15*0.53 -> 148.4 | P15: =O15*8.2658 -> 1226.6447 | AC15: =Q15+T15+W15+Z15 -> 0 | AD15: =(R15+U15+X15+AA15)/4 -> 0 | AE15: =(S15+V15+Y15+AB15)/4 -> 0
A16: =(A15+1) -> 44172 | B16: 64 | C16: =IF(AC16>0,((B16-R16)+(S16-B17)),IF(B17=0, ,(B16-B17))) -> 1 | D16: 66 | E16: =IF(AC16>0,((D16-U16)+(V16-D17)),IF(D17=0, ,(D16-D17))) -> 1 | F16: 63 | G16: =IF(AC16>0,((F16-X16)+(Y16-F17)),IF(F17=0, ,(F16-F17))) -> 1 | H16: 63 | I16: =IF(AC16>0,((H16-AA16)+(AB16-H17)),IF(H17=0, ,(H16-H17))) -> 0 | J16: =B16+D16+F16+H16 -> 256 | K16: =J16/4 -> 64 | L16: =IF(AC16>0,((K16-AD16)+(AE16-K17)),IF(K17=0, ,(K16-K17))) -> 0.75 | M16: =7000*4 -> 28000 | N16: =L16*M16/100 -> 210 | O16: =N16*0.53 -> 111.3 | P16: =O16*8.2658 -> 919.98354 | AC16: =Q16+T16+W16+Z16 -> 0 | AD16: =(R16+U16+X16+AA16)/4 -> 0 | AE16: =(S16+V16+Y16+AB16)/4 -> 0
A17: =(A16+1) -> 44173 | B17: 63 | C17: =IF(AC17>0,((B17-R17)+(S17-B18)),IF(B18=0, ,(B17-B18))) -> 0 | D17: 65 | E17: =IF(AC17>0,((D17-U17)+(V17-D18)),IF(D18=0, ,(D17-D18))) -> 1 | F17: 62 | G17: =IF(AC17>0,((F17-X17)+(Y17-F18)),IF(F18=0, ,(F17-F18))) -> 2 | H17: 63 | I17: =IF(AC17>0,((H17-AA17)+(AB17-H18)),IF(H18=0, ,(H17-H18))) -> 2 | J17: =B17+D17+F17+H17 -> 253 | K17: =J17/4 -> 63.25 | L17: =IF(AC17>0,((K17-AD17)+(AE17-K18)),IF(K18=0, ,(K17-K18))) -> 1.25 | M17: =7000*4 -> 28000 | N17: =L17*M17/100 -> 350 | O17: =N17*0.53 -> 185.5 | P17: =O17*8.2658 -> 1533.3059 | AC17: =Q17+T17+W17+Z17 -> 0 | AD17: =(R17+U17+X17+AA17)/4 -> 0 | AE17: =(S17+V17+Y17+AB17)/4 -> 0
A18: =(A17+1) -> 44174 | B18: 63 | C18: =IF(AC18>0,((B18-R18)+(S18-B19)),IF(B19=0, ,(B18-B19))) -> 1 | D18: 64 | E18: =IF(AC18>0,((D18-U18)+(V18-D19)),IF(D19=0, ,(D18-D19))) -> 3 | F18: 60 | G18: =IF(AC18>0,((F18-X18)+(Y18-F19)),IF(F19=0, ,(F18-F19))) -> 2 | H18: 61 | I18: =IF(AC18>0,((H18-AA18)+(AB18-H19)),IF(H19=0, ,(H18-H19))) -> 1 | J18: =B18+D18+F18+H18 -> 248 | K18: =J18/4 -> 62 | L18: =IF(AC18>0,((K18-AD18)+(AE18-K19)),IF(K19=0, ,(K18-K19))) -> 1.75 | M18: =7000*4 -> 28000 | N18: =L18*M18/100 -> 490 | O18: =N18*0.53 -> 259.7 | P18: =O18*8.2658 -> 2146.6283 | AC18: =Q18+T18+W18+Z18 -> 0 | AD18: =(R18+U18+X18+AA18)/4 -> 0 | AE18: =(S18+V18+Y18+AB18)/4 -> 0
A19: =(A18+1) -> 44175 | B19: 62 | C19: =IF(AC19>0,((B19-R19)+(S19-B20)),IF(B20=0, ,(B19-B20))) -> 13 | D19: 61 | E19: =IF(AC19>0,((D19-U19)+(V19-D20)),IF(D20=0, ,(D19-D20))) -> 7 | F19: 58 | G19: =IF(AC19>0,((F19-X19)+(Y19-F20)),IF(F20=0, ,(F19-F20))) -> 2 | H19: 60 | I19: =IF(AC19>0,((H19-AA19)+(AB19-H20)),IF(H20=0, ,(H19-H20))) -> -18 | J19: =B19+D19+F19+H19 -> 241 | K19: =J19/4 -> 60.25 | L19: =IF(AC19>0,((K19-AD19)+(AE19-K20)),IF(K20=0, ,(K19-K20))) -> 1 | M19: =7000*4 -> 28000 | N19: =L19*M19/100 -> 280 | O19: =N19*0.53 -> 148.4 | P19: =O19*8.2658 -> 1226.6447 | Q19: 1909 | R19: 62 | S19: 85 | T19: 1969 | U19: 62 | V19: 85 | W19: 1200 | X19: 56 | Y19: 70 | AC19: =Q19+T19+W19+Z19 -> 5078 | AD19: =(R19+U19+X19+AA19)/4 -> 45 | AE19: =(S19+V19+Y19+AB19)/4 -> 60
A20: =(A19+1) -> 44176 | B20: 72 | C20: =IF(AC20>0,((B20-R20)+(S20-B21)),IF(B21=0, ,(B20-B21))) -> 2 | D20: 77 | E20: =IF(AC20>0,((D20-U20)+(V20-D21)),IF(D21=0, ,(D20-D21))) -> 5 | F20: 70 | G20: =IF(AC20>0,((F20-X20)+(Y20-F21)),IF(F21=0, ,(F20-F21))) -> 0 | H20: 78 | I20: =IF(AC20>0,((H20-AA20)+(AB20-H21)),IF(H21=0, ,(H20-H21))) -> 2 | J20: =B20+D20+F20+H20 -> 297 | K20: =J20/4 -> 74.25 | L20: =IF(AC20>0,((K20-AD20)+(AE20-K21)),IF(K21=0, ,(K20-K21))) -> 2.25 | M20: =7000*4 -> 28000 | N20: =L20*M20/100 -> 630 | O20: =N20*0.53 -> 333.9 | P20: =O20*8.2658 -> 2759.9506 | AC20: =Q20+T20+W20+Z20 -> 0 | AD20: =(R20+U20+X20+AA20)/4 -> 0 | AE20: =(S20+V20+Y20+AB20)/4 -> 0
A21: =(A20+1) -> 44177 | B21: 70 | C21: =IF(AC21>0,((B21-R21)+(S21-B22)),IF(B22=0, ,(B21-B22))) -> 2 | D21: 72 | E21: =IF(AC21>0,((D21-U21)+(V21-D22)),IF(D22=0, ,(D21-D22))) -> 2 | F21: 70 | G21: =IF(AC21>0,((F21-X21)+(Y21-F22)),IF(F22=0, ,(F21-F22))) -> 0 | H21: 76 | I21: =IF(AC21>0,((H21-AA21)+(AB21-H22)),IF(H22=0, ,(H21-H22))) -> 8 | J21: =B21+D21+F21+H21 -> 288 | K21: =J21/4 -> 72 | L21: =IF(AC21>0,((K21-AD21)+(AE21-K22)),IF(K22=0, ,(K21-K22))) -> 3 | M21: =7000*4 -> 28000 | N21: =L21*M21/100 -> 840 | O21: =N21*0.53 -> 445.2 | P21: =O21*8.2658 -> 3679.9342 | AC21: =Q21+T21+W21+Z21 -> 0 | AD21: =(R21+U21+X21+AA21)/4 -> 0 | AE21: =(S21+V21+Y21+AB21)/4 -> 0
A22: =(A21+1) -> 44178 | B22: 68 | C22: =IF(AC22>0,((B22-R22)+(S22-B23)),IF(B23=0, ,(B22-B23))) -> 2 | D22: 70 | E22: =IF(AC22>0,((D22-U22)+(V22-D23)),IF(D23=0, ,(D22-D23))) -> 2 | F22: 70 | G22: =IF(AC22>0,((F22-X22)+(Y22-F23)),IF(F23=0, ,(F22-F23))) -> 2 | H22: 68 | I22: =IF(AC22>0,((H22-AA22)+(AB22-H23)),IF(H23=0, ,(H22-H23))) -> 2 | J22: =B22+D22+F22+H22 -> 276 | K22: =J22/4 -> 69 | L22: =IF(AC22>0,((K22-AD22)+(AE22-K23)),IF(K23=0, ,(K22-K23))) -> 2 | M22: =7000*4 -> 28000 | N22: =L22*M22/100 -> 560 | O22: =N22*0.53 -> 296.8 | P22: =O22*8.2658 -> 2453.2894 | AC22: =Q22+T22+W22+Z22 -> 0 | AD22: =(R22+U22+X22+AA22)/4 -> 0 | AE22: =(S22+V22+Y22+AB22)/4 -> 0
A23: =(A22+1) -> 44179 | B23: 66 | C23: =IF(AC23>0,((B23-R23)+(S23-B24)),IF(B24=0, ,(B23-B24))) -> 1 | D23: 68 | E23: =IF(AC23>0,((D23-U23)+(V23-D24)),IF(D24=0, ,(D23-D24))) -> 3 | F23: 68 | G23: =IF(AC23>0,((F23-X23)+(Y23-F24)),IF(F24=0, ,(F23-F24))) -> 0 | H23: 66 | I23: =IF(AC23>0,((H23-AA23)+(AB23-H24)),IF(H24=0, ,(H23-H24))) -> 4 | J23: =B23+D23+F23+H23 -> 268 | K23: =J23/4 -> 67 | L23: =IF(AC23>0,((K23-AD23)+(AE23-K24)),IF(K24=0, ,(K23-K24))) -> 2 | M23: =7000*4 -> 28000 | N23: =L23*M23/100 -> 560 | O23: =N23*0.53 -> 296.8 | P23: =O23*8.2658 -> 2453.2894 | AC23: =Q23+T23+W23+Z23 -> 0 | AD23: =(R23+U23+X23+AA23)/4 -> 0 | AE23: =(S23+V23+Y23+AB23)/4 -> 0
A24: =(A23+1) -> 44180 | B24: 65 | C24: =IF(AC24>0,((B24-R24)+(S24-B25)),IF(B25=0, ,(B24-B25))) -> 3 | D24: 65 | E24: =IF(AC24>0,((D24-U24)+(V24-D25)),IF(D25=0, ,(D24-D25))) -> 3 | F24: 68 | G24: =IF(AC24>0,((F24-X24)+(Y24-F25)),IF(F25=0, ,(F24-F25))) -> 0 | H24: 62 | I24: =IF(AC24>0,((H24-AA24)+(AB24-H25)),IF(H25=0, ,(H24-H25))) -> 2 | J24: =B24+D24+F24+H24 -> 260 | K24: =J24/4 -> 65 | L24: =IF(AC24>0,((K24-AD24)+(AE24-K25)),IF(K25=0, ,(K24-K25))) -> 2 | M24: =7000*4 -> 28000 | N24: =L24*M24/100 -> 560 | O24: =N24*0.53 -> 296.8 | P24: =O24*8.2658 -> 2453.2894 | AC24: =Q24+T24+W24+Z24 -> 0 | AD24: =(R24+U24+X24+AA24)/4 -> 0 | AE24: =(S24+V24+Y24+AB24)/4 -> 0
A25: =(A24+1) -> 44181 | B25: 62 | C25: =IF(AC25>0,((B25-R25)+(S25-B26)),IF(B26=0, ,(B25-B26))) -> 2 | D25: 62 | E25: =IF(AC25>0,((D25-U25)+(V25-D26)),IF(D26=0, ,(D25-D26))) -> 2 | F25: 68 | G25: =IF(AC25>0,((F25-X25)+(Y25-F26)),IF(F26=0, ,(F25-F26))) -> 0 | H25: 60 | I25: =IF(AC25>0,((H25-AA25)+(AB25-H26)),IF(H26=0, ,(H25-H26))) -> 2 | J25: =B25+D25+F25+H25 -> 252 | K25: =J25/4 -> 63 | L25: =IF(AC25>0,((K25-AD25)+(AE25-K26)),IF(K26=0, ,(K25-K26))) -> 1.5 | M25: =7000*4 -> 28000 | N25: =L25*M25/100 -> 420 | O25: =N25*0.53 -> 222.6 | P25: =O25*8.2658 -> 1839.9671 | AC25: =Q25+T25+W25+Z25 -> 0 | AD25: =(R25+U25+X25+AA25)/4 -> 0 | AE25: =(S25+V25+Y25+AB25)/4 -> 0
A26: =(A25+1) -> 44182 | B26: 60 | C26: =IF(AC26>0,((B26-R26)+(S26-B27)),IF(B27=0, ,(B26-B27))) -> 1 | D26: 60 | E26: =IF(AC26>0,((D26-U26)+(V26-D27)),IF(D27=0, ,(D26-D27))) -> 0 | F26: 68 | G26: =IF(AC26>0,((F26-X26)+(Y26-F27)),IF(F27=0, ,(F26-F27))) -> 0 | H26: 58 | I26: =IF(AC26>0,((H26-AA26)+(AB26-H27)),IF(H27=0, ,(H26-H27))) -> 8 | J26: =B26+D26+F26+H26 -> 246 | K26: =J26/4 -> 61.5 | L26: =IF(AC26>0,((K26-AD26)+(AE26-K27)),IF(K27=0, ,(K26-K27))) -> 2.25 | M26: =7000*4 -> 28000 | N26: =L26*M26/100 -> 630 | O26: =N26*0.53 -> 333.9 | P26: =O26*8.2658 -> 2759.9506 | AC26: =Q26+T26+W26+Z26 -> 0 | AD26: =(R26+U26+X26+AA26)/4 -> 0 | AE26: =(S26+V26+Y26+AB26)/4 -> 0
A27: =(A26+1) -> 44183 | B27: 59 | C27: =IF(AC27>0,((B27-R27)+(S27-B28)),IF(B28=0, ,(B27-B28))) -> 4 | D27: 60 | E27: =IF(AC27>0,((D27-U27)+(V27-D28)),IF(D28=0, ,(D27-D28))) -> 0 | F27: 68 | G27: =IF(AC27>0,((F27-X27)+(Y27-F28)),IF(F28=0, ,(F27-F28))) -> 0 | H27: 50 | I27: =IF(AC27>0,((H27-AA27)+(AB27-H28)),IF(H28=0, ,(H27-H28))) -> 0 | J27: =B27+D27+F27+H27 -> 237 | K27: =J27/4 -> 59.25 | L27: =IF(AC27>0,((K27-AD27)+(AE27-K28)),IF(K28=0, ,(K27-K28))) -> 1 | M27: =7000*4 -> 28000 | N27: =L27*M27/100 -> 280 | O27: =N27*0.53 -> 148.4 | P27: =O27*8.2658 -> 1226.6447 | AC27: =Q27+T27+W27+Z27 -> 0 | AD27: =(R27+U27+X27+AA27)/4 -> 0 | AE27: =(S27+V27+Y27+AB27)/4 -> 0
A28: =(A27+1) -> 44184 | B28: 55 | C28: =IF(AC28>0,((B28-R28)+(S28-B29)),IF(B29=0, ,(B28-B29))) -> 5 | D28: 60 | E28: =IF(AC28>0,((D28-U28)+(V28-D29)),IF(D29=0, ,(D28-D29))) -> 5 | F28: 68 | G28: =IF(AC28>0,((F28-X28)+(Y28-F29)),IF(F29=0, ,(F28-F29))) -> 0 | H28: 50 | I28: =IF(AC28>0,((H28-AA28)+(AB28-H29)),IF(H29=0, ,(H28-H29))) -> 3 | J28: =B28+D28+F28+H28 -> 233 | K28: =J28/4 -> 58.25 | L28: =IF(AC28>0,((K28-AD28)+(AE28-K29)),IF(K29=0, ,(K28-K29))) -> 3.25 | M28: =7000*4 -> 28000 | N28: =L28*M28/100 -> 910 | O28: =N28*0.53 -> 482.3 | P28: =O28*8.2658 -> 3986.5953 | AC28: =Q28+T28+W28+Z28 -> 0 | AD28: =(R28+U28+X28+AA28)/4 -> 0 | AE28: =(S28+V28+Y28+AB28)/4 -> 0
A29: =(A28+1) -> 44185 | B29: 50 | C29: =IF(AC29>0,((B29-R29)+(S29-B30)),IF(B30=0, ,(B29-B30))) -> 2 | D29: 55 | E29: =IF(AC29>0,((D29-U29)+(V29-D30)),IF(D30=0, ,(D29-D30))) -> 5 | F29: 68 | G29: =IF(AC29>0,((F29-X29)+(Y29-F30)),IF(F30=0, ,(F29-F30))) -> 0 | H29: 47 | I29: =IF(AC29>0,((H29-AA29)+(AB29-H30)),IF(H30=0, ,(H29-H30))) -> 4 | J29: =B29+D29+F29+H29 -> 220 | K29: =J29/4 -> 55 | L29: =IF(AC29>0,((K29-AD29)+(AE29-K30)),IF(K30=0, ,(K29-K30))) -> 2.75 | M29: =7000*4 -> 28000 | N29: =L29*M29/100 -> 770 | O29: =N29*0.53 -> 408.1 | P29: =O29*8.2658 -> 3373.273 | AC29: =Q29+T29+W29+Z29 -> 0 | AD29: =(R29+U29+X29+AA29)/4 -> 0 | AE29: =(S29+V29+Y29+AB29)/4 -> 0
A30: =(A29+1) -> 44186 | B30: 48 | C30: =IF(AC30>0,((B30-R30)+(S30-B31)),IF(B31=0, ,(B30-B31))) -> 7 | D30: 50 | E30: =IF(AC30>0,((D30-U30)+(V30-D31)),IF(D31=0, ,(D30-D31))) -> 10 | F30: 68 | G30: =IF(AC30>0,((F30-X30)+(Y30-F31)),IF(F31=0, ,(F30-F31))) -> 0 | H30: 43 | I30: =IF(AC30>0,((H30-AA30)+(AB30-H31)),IF(H31=0, ,(H30-H31))) -> 4 | J30: =B30+D30+F30+H30 -> 209 | K30: =J30/4 -> 52.25 | L30: =IF(AC30>0,((K30-AD30)+(AE30-K31)),IF(K31=0, ,(K30-K31))) -> 5.25 | M30: =7000*4 -> 28000 | N30: =L30*M30/100 -> 1470 | O30: =N30*0.53 -> 779.1 | P30: =O30*8.2658 -> 6439.8848 | AC30: =Q30+T30+W30+Z30 -> 0 | AD30: =(R30+U30+X30+AA30)/4 -> 0 | AE30: =(S30+V30+Y30+AB30)/4 -> 0
A31: =(A30+1) -> 44187 | B31: 41 | C31: =IF(AC31>0,((B31-R31)+(S31-B32)),IF(B32=0, ,(B31-B32))) -> 5 | D31: 40 | E31: =IF(AC31>0,((D31-U31)+(V31-D32)),IF(D32=0, ,(D31-D32))) -> 2 | F31: 68 | G31: =IF(AC31>0,((F31-X31)+(Y31-F32)),IF(F32=0, ,(F31-F32))) -> 0 | H31: 39 | I31: =IF(AC31>0,((H31-AA31)+(AB31-H32)),IF(H32=0, ,(H31-H32))) -> 7 | J31: =B31+D31+F31+H31 -> 188 | K31: =J31/4 -> 47 | L31: =IF(AC31>0,((K31-AD31)+(AE31-K32)),IF(K32=0, ,(K31-K32))) -> 3.5 | M31: =7000*4 -> 28000 | N31: =L31*M31/100 -> 980 | O31: =N31*0.53 -> 519.4 | P31: =O31*8.2658 -> 4293.2565 | AC31: =Q31+T31+W31+Z31 -> 0 | AD31: =(R31+U31+X31+AA31)/4 -> 0 | AE31: =(S31+V31+Y31+AB31)/4 -> 0
A32: =(A31+1) -> 44188 | B32: 36 | C32: =IF(AC32>0,((B32-R32)+(S32-B33)),IF(B33=0, ,(B32-B33))) -> 7 | D32: 38 | E32: =IF(AC32>0,((D32-U32)+(V32-D33)),IF(D33=0, ,(D32-D33))) -> 11 | F32: 68 | G32: =IF(AC32>0,((F32-X32)+(Y32-F33)),IF(F33=0, ,(F32-F33))) -> 18 | H32: 32 | I32: =IF(AC32>0,((H32-AA32)+(AB32-H33)),IF(H33=0, ,(H32-H33))) -> -16 | J32: =B32+D32+F32+H32 -> 174 | K32: =J32/4 -> 43.5 | L32: =IF(AC32>0,((K32-AD32)+(AE32-K33)),IF(K33=0, ,(K32-K33))) -> 5 | M32: =7000*4 -> 28000 | N32: =L32*M32/100 -> 1400 | O32: =N32*0.53 -> 742 | P32: =O32*8.2658 -> 6133.2236 | Q32: 2003 | R32: 34 | S32: 62 | T32: 2003 | U32: 35 | V32: 64 | AC32: =Q32+T32+W32+Z32 -> 4006 | AD32: =(R32+U32+X32+AA32)/4 -> 17.25 | AE32: =(S32+V32+Y32+AB32)/4 -> 31.5
A33: =(A32+1) -> 44189 | B33: 57 | C33: =IF(AC33>0,((B33-R33)+(S33-B34)),IF(B34=0, ,(B33-B34))) -> 4 | D33: 56 | E33: =IF(AC33>0,((D33-U33)+(V33-D34)),IF(D34=0, ,(D33-D34))) -> 6 | F33: 50 | G33: =IF(AC33>0,((F33-X33)+(Y33-F34)),IF(F34=0, ,(F33-F34))) -> 6 | H33: 48 | I33: =IF(AC33>0,((H33-AA33)+(AB33-H34)),IF(H34=0, ,(H33-H34))) -> 3 | J33: =B33+D33+F33+H33 -> 211 | K33: =J33/4 -> 52.75 | L33: =IF(AC33>0,((K33-AD33)+(AE33-K34)),IF(K34=0, ,(K33-K34))) -> 4.75 | M33: =7000*4 -> 28000 | N33: =L33*M33/100 -> 1330 | O33: =N33*0.53 -> 704.9 | P33: =O33*8.2658 -> 5826.5624 | AC33: =Q33+T33+W33+Z33 -> 0 | AD33: =(R33+U33+X33+AA33)/4 -> 0 | AE33: =(S33+V33+Y33+AB33)/4 -> 0
A34: =(A33+1) -> 44190 | B34: 53 | C34: =IF(AC34>0,((B34-R34)+(S34-B35)),IF(B35=0, ,(B34-B35))) -> 3 | D34: 50 | E34: =IF(AC34>0,((D34-U34)+(V34-D35)),IF(D35=0, ,(D34-D35))) -> 2 | F34: 44 | G34: =IF(AC34>0,((F34-X34)+(Y34-F35)),IF(F35=0, ,(F34-F35))) -> 0 | H34: 45 | I34: =IF(AC34>0,((H34-AA34)+(AB34-H35)),IF(H35=0, ,(H34-H35))) -> 8 | J34: =B34+D34+F34+H34 -> 192 | K34: =J34/4 -> 48 | L34: =IF(AC34>0,((K34-AD34)+(AE34-K35)),IF(K35=0, ,(K34-K35))) -> 3.25 | M34: =7000*4 -> 28000 | N34: =L34*M34/100 -> 910 | O34: =N34*0.53 -> 482.3 | P34: =O34*8.2658 -> 3986.5953 | Q34: 2780 | R34: 50 | S34: 85 | T34: 3083 | U34: 48 | V34: 85 | W34: 3061 | X34: 45 | Y34: 85 | Z34: 3308 | AA34: 40 | AB34: 85 | AC34: =Q34+T34+W34+Z34 -> 12232 | AD34: =(R34+U34+X34+AA34)/4 -> 45.75 | AE34: =(S34+V34+Y34+AB34)/4 -> 85
A35: =(A34+1) -> 44191 | B35: 85 | C35: =IF(AC35>0,((B35-R35)+(S35-B36)),IF(B36=0, ,(B35-B36))) -> 5 | D35: 85 | E35: =IF(AC35>0,((D35-U35)+(V35-D36)),IF(D36=0, ,(D35-D36))) -> 5 | F35: 84 | G35: =IF(AC35>0,((F35-X35)+(Y35-F36)),IF(F36=0, ,(F35-F36))) -> 9 | H35: 82 | I35: =IF(AC35>0,((H35-AA35)+(AB35-H36)),IF(H36=0, ,(H35-H36))) -> 3 | J35: =B35+D35+F35+H35 -> 336 | K35: =J35/4 -> 84 | L35: =IF(AC35>0,((K35-AD35)+(AE35-K36)),IF(K36=0, ,(K35-K36))) -> 5.5 | M35: =7000*4 -> 28000 | N35: =L35*M35/100 -> 1540 | O35: =N35*0.53 -> 816.2 | P35: =O35*8.2658 -> 6746.546 | AC35: =Q35+T35+W35+Z35 -> 0 | AD35: =(R35+U35+X35+AA35)/4 -> 0 | AE35: =(S35+V35+Y35+AB35)/4 -> 0
A36: =(A35+1) -> 44192 | B36: 80 | C36: =IF(AC36>0,((B36-R36)+(S36-B37)),IF(B37=0, ,(B36-B37))) -> 8 | D36: 80 | E36: =IF(AC36>0,((D36-U36)+(V36-D37)),IF(D37=0, ,(D36-D37))) -> 8 | F36: 75 | G36: =IF(AC36>0,((F36-X36)+(Y36-F37)),IF(F37=0, ,(F36-F37))) -> 6 | H36: 79 | I36: =IF(AC36>0,((H36-AA36)+(AB36-H37)),IF(H37=0, ,(H36-H37))) -> 9 | J36: =B36+D36+F36+H36 -> 314 | K36: =J36/4 -> 78.5 | L36: =IF(AC36>0,((K36-AD36)+(AE36-K37)),IF(K37=0, ,(K36-K37))) -> 7.75 | M36: =7000*4 -> 28000 | N36: =L36*M36/100 -> 2170 | O36: =N36*0.53 -> 1150.1 | P36: =O36*8.2658 -> 9506.4966 | AC36: =Q36+T36+W36+Z36 -> 0 | AD36: =(R36+U36+X36+AA36)/4 -> 0 | AE36: =(S36+V36+Y36+AB36)/4 -> 0
A37: =(A36+1) -> 44193 | B37: 72 | C37: =IF(AC37>0,((B37-R37)+(S37-B38)),IF(B38=0, ,(B37-B38))) -> 5 | D37: 72 | E37: =IF(AC37>0,((D37-U37)+(V37-D38)),IF(D38=0, ,(D37-D38))) -> 4 | F37: 69 | G37: =IF(AC37>0,((F37-X37)+(Y37-F38)),IF(F38=0, ,(F37-F38))) -> 7 | H37: 70 | I37: =IF(AC37>0,((H37-AA37)+(AB37-H38)),IF(H38=0, ,(H37-H38))) -> 5 | J37: =B37+D37+F37+H37 -> 283 | K37: =J37/4 -> 70.75 | L37: =IF(AC37>0,((K37-AD37)+(AE37-K38)),IF(K38=0, ,(K37-K38))) -> 5.25 | M37: =7000*4 -> 28000 | N37: =L37*M37/100 -> 1470 | O37: =N37*0.53 -> 779.1 | P37: =O37*8.2658 -> 6439.8848 | AC37: =Q37+T37+W37+Z37 -> 0 | AD37: =(R37+U37+X37+AA37)/4 -> 0 | AE37: =(S37+V37+Y37+AB37)/4 -> 0
A38: =(A37+1) -> 44194 | B38: 67 | C38: =IF(AC38>0,((B38-R38)+(S38-B39)),IF(B39=0, ,(B38-B39))) -> 0 | D38: 68 | E38: =IF(AC38>0,((D38-U38)+(V38-D39)),IF(D39=0, ,(D38-D39))) -> 0 | F38: 62 | G38: =IF(AC38>0,((F38-X38)+(Y38-F39)),IF(F39=0, ,(F38-F39))) -> 0 | H38: 65 | I38: =IF(AC38>0,((H38-AA38)+(AB38-H39)),IF(H39=0, ,(H38-H39))) -> 0 | J38: =B38+D38+F38+H38 -> 262 | K38: =J38/4 -> 65.5 | L38: =IF(AC38>0,((K38-AD38)+(AE38-K39)),IF(K39=0, ,(K38-K39))) -> 0 | M38: =7000*4 -> 28000 | N38: =L38*M38/100 -> 0 | O38: =N38*0.53 -> 0 | P38: =O38*8.2658 -> 0 | AC38: =Q38+T38+W38+Z38 -> 0 | AD38: =(R38+U38+X38+AA38)/4 -> 0 | AE38: =(S38+V38+Y38+AB38)/4 -> 0
A39: =(A38+1) -> 44195 | C39: =IF(AC39>0,((B39-R39)+(S39-B40)),IF(B40=0, ,(B39-B40))) -> 0 | E39: =IF(AC39>0,((D39-U39)+(V39-D40)),IF(D40=0, ,(D39-D40))) -> 0 | G39: =IF(AC39>0,((F39-X39)+(Y39-F40)),IF(F40=0, ,(F39-F40))) -> 0 | I39: =IF(AC39>0,((H39-AA39)+(AB39-H40)),IF(H40=0, ,(H39-H40))) -> 0 | J39: =B39+D39+F39+H39 -> 0 | K39: =J39/4 -> 0 | L39: =IF(AC39>0,((K39-AD39)+(AE39-K40)),IF(K40=0, ,(K39-K40))) -> 0 | M39: =7000*4 -> 28000 | N39: =L39*M39/100 -> 0 | O39: =N39*0.53 -> 0 | P39: =O39*8.2658 -> 0 | AC39: =Q39+T39+W39+Z39 -> 0 | AD39: =(R39+U39+X39+AA39)/4 -> 0 | AE39: =(S39+V39+Y39+AB39)/4 -> 0
A40: =(A39+1) -> 44196 | C40: =IF(AC40>0,((B40-R40)+(S40-B41)),IF(B41=0, ,(B40-B41))) -> 0 | E40: =IF(AC40>0,((D40-U40)+(V40-D41)),IF(D41=0, ,(D40-D41))) -> 0 | G40: =IF(AC40>0,((F40-X40)+(Y40-F41)),IF(F41=0, ,(F40-F41))) -> 0 | I40: =IF(AC40>0,((H40-AA40)+(AB40-H41)),IF(H41=0, ,(H40-H41))) -> 0 | J40: =B40+D40+F40+H40 -> 0 | K40: =J40/4 -> 0 | L40: =IF(AC40>0,((K40-AD40)+(AE40-K41)),IF(K41=0, ,(K40-K41))) -> 0 | M40: =7000*4 -> 28000 | N40: =L40*M40/100 -> 0 | O40: =N40*0.53 -> 0 | P40: =O40*8.2658 -> 0 | AC40: =Q40+T40+W40+Z40 -> 0 | AD40: =(R40+U40+X40+AA40)/4 -> 0 | AE40: =(S40+V40+Y40+AB40)/4 -> 0
...

Sheet Suivi EAU-ELEC
C1: Suivi Compteur d'Eau- électricité RADEEMA -
D5: =SUM(C16:C45) -> 6880
A7: Date | B7: Eau m3 | D7: Electricité Kw/h
B8: Compteur | C8: Consommation | D8: Compteur H.Creuse | E8: Consommation H.Creuse | F8: Compteur H.Pleine | G8: Consommation H.Pleine | H8: Compteur H.Pointe | I8: Consommation H.Pointe
A9: 44160 | B9: 126692 | C9: =IF(B10<B9,0,B10-B9)*10 -> 400 | D9: 18807948 | E9: =IF(D10<D9,0,D10-D9) -> 3032 | F9: 33731953 | G9: =IF(F10<F9,0,F10-F9) -> 4542 | H9: 14940535 | I9: =IF(H10<H9,0,H10-H9) -> 2066
A10: =(A9+1) -> 44161 | B10: 126732 | C10: =IF(B11<B10,0,B11-B10)*10 -> 150 | D10: 18810980 | E10: =IF(D11<D10,0,D11-D10) -> 3226 | F10: 33736495 | G10: =IF(F11<F10,0,F11-F10) -> 4478 | H10: 14942601 | I10: =IF(H11<H10,0,H11-H10) -> 2195
A11: =(A10+1) -> 44162 | B11: 126747 | C11: =IF(B12<B11,0,B12-B11)*10 -> 270 | D11: 18814206 | E11: =IF(D12<D11,0,D12-D11) -> 3035 | F11: 33740973 | G11: =IF(F12<F11,0,F12-F11) -> 4503 | H11: 14944796 | I11: =IF(H12<H11,0,H12-H11) -> 1980
A12: =(A11+1) -> 44163 | B12: 126774 | C12: =IF(B13<B12,0,B13-B12)*10 -> 200 | D12: 18817241 | E12: =IF(D13<D12,0,D13-D12) -> 3102 | F12: 33745476 | G12: =IF(F13<F12,0,F13-F12) -> 4519 | H12: 14946776 | I12: =IF(H13<H12,0,H13-H12) -> 2022
A13: =(A12+1) -> 44164 | B13: 126794 | C13: =IF(B14<B13,0,B14-B13)*10 -> 350 | D13: 18820343 | E13: =IF(D14<D13,0,D14-D13) -> 3035 | F13: 33749995 | G13: =IF(F14<F13,0,F14-F13) -> 4409 | H13: 14948798 | I13: =IF(H14<H13,0,H14-H13) -> 1902
A14: =(A13+1) -> 44165 | B14: 126829 | C14: =IF(B15<B14,0,B15-B14)*10 -> 240 | D14: 18823378 | E14: =IF(D15<D14,0,D15-D14) -> 3165 | F14: 33754404 | G14: =IF(F15<F14,0,F15-F14) -> 4653 | H14: 14950700 | I14: =IF(H15<H14,0,H15-H14) -> 2055
A15: =(A14+1) -> 44166 | B15: 126853 | C15: =IF(B16<B15,0,B16-B15)*10 -> 190 | D15: 18826543 | E15: =IF(D16<D15,0,D16-D15) -> 3638 | F15: 33759057 | G15: =IF(F16<F15,0,F16-F15) -> 4702 | H15: 14952755 | I15: =IF(H16<H15,0,H16-H15) -> 2671
A16: =(A15+1) -> 44167 | B16: 126872 | C16: =IF(B17<B16,0,B17-B16)*10 -> 220 | D16: 18830181 | E16: =IF(D17<D16,0,D17-D16) -> 3907 | F16: 33763759 | G16: =IF(F17<F16,0,F17-F16) -> 5211 | H16: 14955426 | I16: =IF(H17<H16,0,H17-H16) -> 2388
A17: =(A16+1) -> 44168 | B17: 126894 | C17: =IF(B18<B17,0,B18-B17)*10 -> 210 | D17: 18834088 | E17: =IF(D18<D17,0,D18-D17) -> 2757 | F17: 33768970 | G17: =IF(F18<F17,0,F18-F17) -> 5102 | H17: 14957814 | I17: =IF(H18<H17,0,H18-H17) -> 2481
A18: =(A17+1) -> 44169 | B18: 126915 | C18: =IF(B19<B18,0,B19-B18)*10 -> 290 | D18: 18836845 | E18: =IF(D19<D18,0,D19-D18) -> 3024 | F18: 33774072 | G18: =IF(F19<F18,0,F19-F18) -> 4604 | H18: 14960295 | I18: =IF(H19<H18,0,H19-H18) -> 2102
A19: =(A18+1) -> 44170 | B19: 126944 | C19: =IF(B20<B19,0,B20-B19)*10 -> 230 | D19: 18839869 | E19: =IF(D20<D19,0,D20-D19) -> 2839 | F19: 33778676 | G19: =IF(F20<F19,0,F20-F19) -> 4393 | H19: 14962397 | I19: =IF(H20<H19,0,H20-H19) -> 2004
A20: =(A19+1) -> 44171 | B20: 126967 | C20: =IF(B21<B20,0,B21-B20)*10 -> 420 | D20: 18842708 | E20: =IF(D21<D20,0,D21-D20) -> 3060 | F20: 33783069 | G20: =IF(F21<F20,0,F21-F20) -> 4345 | H20: 14964401 | I20: =IF(H21<H20,0,H21-H20) -> 2107
A21: =(A20+1) -> 44172 | B21: 127009 | C21: =IF(B22<B21,0,B22-B21)*10 -> 260 | D21: 18845768 | E21: =IF(D22<D21,0,D22-D21) -> 3137 | F21: 33787414 | G21: =IF(F22<F21,0,F22-F21) -> 4471 | H21: 14966508 | I21: =IF(H22<H21,0,H22-H21) -> 1946
... A43: =(A42+1) -> 44194 | B43: 127560 | C43: =IF(B44<B43,0,B44-B43)*10 -> 0 | D43: 18916886 | E43: =IF(D44<D43,0,D44-D43) -> 0 | F43: 33894042 | G43: =IF(F44<F43,0,F44-F43) -> 0 | H43: 15015109 | I43: =IF(H44<H43,0,H44-H43) -> 0
A44: =(A43+1) -> 44195 | C44: =IF(B45<B44,0,B45-B44)*10 -> 0 | E44: =IF(D45<D44,0,D45-D44) -> 0 | G44: =IF(F45<F44,0,F45-F44) -> 0 | I44: =IF(H45<H44,0,H45-H44) -> 0
A45: =(A44+1) -> 44196 | C45: =IF(B46<B45,0,B46-B45)*10 -> 0 | E45: =IF(D46<D45,0,D46-D45) -> 0 | G45: =IF(F46<F45,0,F46-F45) -> 0 | I45: =IF(H46<H45,0,H46-H45) -> 0
A46: =(A45+1) -> 44197 | C46: =IF(B47<B46,0,B47-B46)*10 -> 0 | E46: =IF(D47<D46,0,D47-D46) -> 0 | G46: =IF(F47<F46,0,F47-F46) -> 0 | I46: =IF(H47<H46,0,H47-H46) -> 0
A47: =(A46+1) -> 44198 | C47: =IF(B48<B47,0,B48-B47)*10 -> 0 | E47: =IF(D48<D47,0,D48-D47) -> 0 | G47: =IF(F48<F47,0,F48-F47) -> 0 | I47: =IF(H48<H47,0,H48-H47) -> 0
C48: =SUM(C15:C45) -> 7070 | E48: =SUM(E15:E45) -> 90343 | G48: =SUM(G15:G45) -> 134985 | I48: =SUM(I15:I45) -> 62354

Sheet Feuil1
