Workbook

Sheet TOTAL
A1: Site Name | B1: Day | C1: Month | D1: Year | E1: Total Electricity Kwh | F1: Electricity Tariff ($/Kwh) | G1: Natual Gas (m3) | H1: Natural Gas $/m3 | I1: Water Utility Supply (m3) m3 | J1: Water Utility Supply (m3) $/m3 | K1: Room Nights | L1: Total Guests | M1: Utilities day cost dh
A2: Mumbai | B2: 1 | C2: 11 | D2: 2020 | E2: ='Daily HLP'!I4 -> 18574 | F2: ='Daily HLP'!J4 -> 9.5 | G2: ='Daily HLP'!M4 -> 497.539 | H2: ='Daily HLP'!N4 -> 35 | I2: ='Daily HLP'!P4 -> 195 | J2: ='Daily HLP'!Q4 -> 134 | K2: =202*'Daily HLP'!F4 -> 60.6 | L2: ='[1]Consommation mensuel énergie'!E10 -> 0 | M2: =E2*F2+G2*H2+#REF!*#REF!+I2*J2 -> #REF!
A3: Mumbai | B3: =B2+1 -> 2 | C3: 11 | D3: 2020 | E3: ='Daily HLP'!I5 -> 19432 | F3: =F2 -> 9.5 | G3: ='Daily HLP'!M5 -> 706.539 | H3: =H2 -> 35 | I3: ='Daily HLP'!P5 -> 185 | J3: =J2 -> 134 | K3: =202*'Daily HLP'!F5 -> 60.6 | L3: ='[1]Consommation mensuel énergie'!E11 -> 0 | M3: =E3*F3+G3*H3+#REF!*#REF!+I3*J3 -> #REF!
A4: Mumbai | B4: =B3+1 -> 3 | C4: 11 | D4: 2020 | E4: ='Daily HLP'!I6 -> 18137 | F4: =F3 -> 9.5 | G4: ='Daily HLP'!M6 -> 445.86 | H4: =H3 -> 35 | I4: ='Daily HLP'!P6 -> 133 | J4: =J3 -> 134 | K4: =202*'Daily HLP'!F6 -> 60.6 | L4: ='[1]Consommation mensuel énergie'!E12 -> 0 | M4: =E4*F4+G4*H4+#REF!*#REF!+I4*J4 -> #REF!
A5: Mumbai | B5: =B4+1 -> 4 | C5: 11 | D5: 2020 | E5: ='Daily HLP'!I7 -> 17671 | F5: =F4 -> 9.5 | G5: ='Daily HLP'!M7 -> 331.514 | H5: =H4 -> 35 | I5: ='Daily HLP'!P7 -> 137 | J5: =J4 -> 134 | K5: =202*'Daily HLP'!F7 -> 60.6 | L5: ='[1]Consommation mensuel énergie'!E13 -> 0 | M5: =E5*F5+G5*H5+#REF!*#REF!+I5*J5 -> #REF!
A6: Mumbai | B6: =B5+1 -> 5 | C6: 11 | D6: 2020 | E6: ='Daily HLP'!I8 -> 18057 | F6: =F5 -> 9.5 | G6: ='Daily HLP'!M8 -> 465.094 | H6: =H5 -> 35 | I6: ='Daily HLP'!P8 -> 149 | J6: =J5 -> 134 | K6: =202*'Daily HLP'!F8 -> 50.5 | L6: ='[1]Consommation mensuel énergie'!E14 -> 0 | M6: =E6*F6+G6*H6+#REF!*#REF!+I6*J6 -> #REF!
A7: Mumbai | B7: =B6+1 -> 6 | C7: 11 | D7: 2020 | E7: ='Daily HLP'!I9 -> 18605 | F7: =F6 -> 9.5 | G7: ='Daily HLP'!M9 -> 617.474 | H7: =H6 -> 35 | I7: ='Daily HLP'!P9 -> 162 | J7: =J6 -> 134 | K7: =202*'Daily HLP'!F9 -> 50.5 | L7: ='[1]Consommation mensuel énergie'!E15 -> 0 | M7: =E7*F7+G7*H7+#REF!*#REF!+I7*J7 -> #REF!
A8: Mumbai | B8: =B7+1 -> 7 | C8: 11 | D8: 2020 | E8: ='Daily HLP'!I10 -> 18512 | F8: =F7 -> 9.5 | G8: ='Daily HLP'!M10 -> 527.368 | H8: =H7 -> 35 | I8: ='Daily HLP'!P10 -> 155 | J8: =J7 -> 134 | K8: =202*'Daily HLP'!F10 -> 109.08 | L8: ='[1]Consommation mensuel énergie'!E16 -> 0 | M8: =E8*F8+G8*H8+#REF!*#REF!+I8*J8 -> #REF!
A9: Mumbai | B9: =B8+1 -> 8 | C9: 11 | D9: 2020 | E9: ='Daily HLP'!I11 -> 19582 | F9: =F8 -> 9.5 | G9: ='Daily HLP'!M11 -> 379.039 | H9: =H8 -> 35 | I9: ='Daily HLP'!P11 -> 153 | J9: =J8 -> 134 | K9: =202*'Daily HLP'!F11 -> 90.9 | L9: ='[1]Consommation mensuel énergie'!E17 -> 0 | M9: =E9*F9+G9*H9+#REF!*#REF!+I9*J9 -> #REF!
A10: Mumbai | B10: =B9+1 -> 9 | C10: 11 | D10: 2020 | E10: ='Daily HLP'!I12 -> 19582 | F10: =F9 -> 9.5 | G10: ='Daily HLP'!M12 -> 379.039 | H10: =H9 -> 35 | I10: ='Daily HLP'!P12 -> 153 | J10: =J9 -> 134 | K10: =202*'Daily HLP'!F12 -> 90.9 | L10: ='[1]Consommation mensuel énergie'!E18 -> 0 | M10: =E10*F10+G10*H10+#REF!*#REF!+I10*J10 -> #REF!
A11: Mumbai | B11: =B10+1 -> 10 | C11: 11 | D11: 2020 | E11: ='Daily HLP'!I13 -> 37064 | F11: =F10 -> 9.5 | G11: ='Daily HLP'!M13 -> 1342.379 | H11: =H10 -> 35 | I11: ='Daily HLP'!P13 -> 266 | J11: =J10 -> 134 | K11: =202*'Daily HLP'!F13 -> 38.38 | L11: ='[1]Consommation mensuel énergie'!E19 -> 0 | M11: =E11*F11+G11*H11+#REF!*#REF!+I11*J11 -> #REF!
A12: Mumbai | B12: =B11+1 -> 11 | C12: 11 | D12: 2020 | E12: ='Daily HLP'!I14 -> 17244 | F12: =F11 -> 9.5 | G12: ='Daily HLP'!M14 -> 508 | H12: =H11 -> 35 | I12: ='Daily HLP'!P14 -> 236 | J12: =J11 -> 134 | K12: =202*'Daily HLP'!F14 -> 44.44 | L12: ='[1]Consommation mensuel énergie'!E20 -> 0 | M12: =E12*F12+G12*H12+#REF!*#REF!+I12*J12 -> #REF!
A13: Mumbai | B13: =B12+1 -> 12 | C13: 11 | D13: 2020 | E13: ='Daily HLP'!I15 -> 17812 | F13: =F12 -> 9.5 | G13: ='Daily HLP'!M15 -> 370 | H13: =H12 -> 35 | I13: ='Daily HLP'!P15 -> 192 | J13: =J12 -> 134 | K13: =202*'Daily HLP'!F15 -> 50.5 | L13: ='[1]Consommation mensuel énergie'!E21 -> 0 | M13: =E13*F13+G13*H13+#REF!*#REF!+I13*J13 -> #REF!
A14: Mumbai | B14: =B13+1 -> 13 | C14: 11 | D14: 2020 | E14: ='Daily HLP'!I16 -> 17390 | F14: =F13 -> 9.5 | G14: ='Daily HLP'!M16 -> 618.601 | H14: =H13 -> 35 | I14: ='Daily HLP'!P16 -> 153 | J14: =J13 -> 134 | K14: =202*'Daily HLP'!F16 -> 101 | L14: ='[1]Consommation mensuel énergie'!E22 -> 0 | M14: =E14*F14+G14*H14+#REF!*#REF!+I14*J14 -> #REF!
... A31: Mumbai | B31: =B30+1 -> 30 | C31: 11 | D31: 2020 | E31: ='Daily HLP'!I33 -> 21224 | F31: =F30 -> 9.5 | G31: ='Daily HLP'!M33 -> 675.187 | H31: =H30 -> 35 | I31: ='Daily HLP'!P33 -> 197 | J31: =J30 -> 134 | K31: =202*'Daily HLP'!F33 -> 60.6 | L31: ='[1]Consommation mensuel énergie'!E39 -> 0 | M31: =E31*F31+G31*H31+#REF!*#REF!+I31*J31 -> #REF!

Sheet Daily HLP
A2: Date | B2: Date | C2: Min.Tem (Degee) | D2: Avg.Temp (Degree) | E2: Hum % | F2: Occu. | G2: KWAH | I2: Electricity | M2: Gas | P2: Water | S2: Water per occiped room | T2: Diesel | W2: Water Consumption Zone | AA2: Chiller Running Hrs | AF2: Chiller Total | AG2: Chiller Avg. Laod | AH2: Boiler Running Hrs | AK2: Total boiler | AL2: Hot Water Generator | AO2: Total HWG RH | AP2: HWG Gas consumption | AQ2: Transformer -1 | BA2: Transformer -2 | BO2: Total HLP Cost | BQ2: Chiller lock at 70%
F3: % | H3: KVAH | I3: Units (Kwh) | J3: Rate | K3: Total Cost(Rs) | L3: Per room | M3: Total Units(CuM) | N3: Rate | O3: Total Cost(Rs) | P3: Units(KL) | Q3: Rate | R3: Total Cost(Rs) | T3: Ltrs | U3: Rate | V3: Total Cost(Rs) | W3: Zone-1 | X3: Zone-2 | Y3: Zone-3 | AA3: CH1 | AB3: CH2 | AC3: CH3 | AD3: CH4 | AE3: Total chiller | AH3: Boiler1 | AI3: Boiler2 | AJ3: Boiler3 | AL3: HWG1 | AM3: HWG2 | AQ3: HVAC-1 | AR3: FPP-1 | AS3: MPP | AT3: Lighting-1 | AU3: Cap bank 1100KVAR-1 | AV3: CH-1 | AW3: CH-2 | AX3: Chilled water Pump | AY3: Co Generator | AZ3: Ball Room-2 | BA3: HVAC-2 | BB3: FPP-2 | BC3: MPP | BD3: Lighting-2 | BE3: Cap bank 1200KVAR-2 | BF3: CH-3 | BG3: CH-4 | BH3: Chilled water Pump | BI3: Ball Room-1 | BK3: Cooling Tower consumption | BL3: HVAC% | BM3: Lighting% | BN3: Power% | BP3: Chiller Plant IKW
A4: 1 | B4: 1 | D4: ='1'!D3 -> 30 | E4: ='1'!D4 -> 0.8 | F4: ='1'!D2 -> 0.3 | G4: ='1'!G8 -> 18631 | H4: ='1'!G8 -> 18631 | I4: ='1'!G7 -> 18574 | J4: ='1'!F27 -> 9.5 | K4: =H4*J4 -> 176994.5 | L4: =I4/202 -> 91.950495 | M4: ='1'!G15 -> 497.539 | N4: 35 | O4: =M4*N4 -> 17413.865 | P4: ='1'!G20 -> 195 | Q4: 134 | R4: =P4*Q4 -> 26130 | S4: =P4/(F4*202/100) -> 321.78218 | T4: ='1'!G24 -> 0 | U4: 69 | V4: =T4*U4 -> 0 | W4: ='1'!G95 -> 48 | X4: ='1'!G96 -> 49 | Y4: ='1'!G97 -> 14 | Z4: =W4+X4+Y4 -> 111 | AA4: ='1'!G132 -> 0 | AB4: ='1'!G133 -> 0 | AC4: ='1'!G134 -> -0.27 | AD4: ='1'!G135 -> 24 | AE4: =AA4+AB4+AC4+AD4 -> 23.73 | AF4: =AV4+AW4+BF4+BG4 -> 4007.51 | AG4: =AF4/AE4 -> 168.87948 | AH4: ='1'!G136 -> 0 | AI4: ='1'!G137 -> 0 | AJ4: ='1'!G138 -> 8.7 | AK4: =AH4+AI4+AJ4 -> 8.7 | AL4: ='1'!G139 -> 5.44 | AM4: ='1'!G140 -> 0 | AO4: =AL4+AM4 -> 5.44 | AP4: ='1'!G123 -> 193.622 | AQ4: ='1'!G35 -> 2733.56 | AR4: ='1'!G37 -> 1525.16 | AS4: ='1'!G38 -> 0 | AT4: ='1'!G39 -> 4085.28 | AU4: ='1'!G40 -> 0 | AV4: ='1'!G41 -> 0 | AW4: ='1'!G42 -> 0 | AX4: ='1'!G43 -> 2401.24 | AY4: ='1'!G44 -> 0 | AZ4: ='1'!G36 -> 464.05 | BA4: ='1'!G49 -> 0 | BB4: ='1'!G51 -> 0 | BC4: ='1'!G52 -> 1920.4 | BD4: ='1'!G53 -> 0 | BE4: ='1'!G54 -> 75.2597 | BF4: ='1'!G55 -> -0.37 | BG4: ='1'!G56 -> 4007.88 | BH4: ='1'!G57 -> 0 | BI4: ='1'!G50 -> 887.18 | BJ4: =SUM(AV4,AW4,BF4,BG4) -> 4007.51 | BK4: ='1'!G84 -> 596 | BL4: =SUM(AQ4,AV4,AW4,AX4,BA4,BF4,BG4,BH4)/I4% -> 49.221008 | BM4: =SUM(AT4,BD4)/I4% -> 21.994616 | BN4: =(AS4+BC4)/I4 -> 0.10339184 | BO4: =K4+O4+R4+V4 -> 220538.37 | BP4: =SUM(AV4,AW4,AX4,BF4,BG4,BH4,BK4) -> 7004.75 | BQ4: =BP4/(AE4*280) -> 1.0542336 | BR4: =SUM(AV4,AW4,BF4,BG4)/(AE4*400) -> 0.42219869
A5: 2 | B5: 2 | D5: ='2'!D3 -> 30 | E5: ='2'!D4 -> 0.8 | F5: ='2'!D2 -> 0.3 | G5: ='2'!G8 -> 19518 | H5: ='2'!G8 -> 19518 | I5: ='2'!G7 -> 19432 | J5: 10 | K5: =H5*J5 -> 195180 | L5: =I5/202 -> 96.19802 | M5: ='2'!G15 -> 706.539 | N5: 35 | O5: =M5*N5 -> 24728.865 | P5: ='2'!G20 -> 185 | Q5: 134 | R5: =P5*Q5 -> 24790 | S5: =P5/(F5*202/100) -> 305.28053 | T5: ='2'!G24 -> 0 | U5: 69 | V5: =T5*U5 -> 0 | W5: ='2'!G95 -> 62 | X5: ='2'!G96 -> 36 | Y5: ='2'!G97 -> 14 | Z5: =W5+X5+Y5 -> 112 | AA5: ='2'!G132 -> 0 | AB5: ='2'!G133 -> 0 | AC5: ='2'!G134 -> 0 | AD5: ='2'!G135 -> 24 | AE5: =AA5+AB5+AC5+AD5 -> 24 | AF5: =AV5+AW5+BF5+BG5 -> 4613.87 | AG5: =AF5/AE5 -> 192.24458 | AH5: ='2'!G136 -> 8.12 | AI5: ='2'!G137 -> 0 | AJ5: ='2'!G138 -> 1.54 | AK5: =AH5+AI5+AJ5 -> 9.66 | AL5: ='2'!G139 -> 3.35 | AM5: ='2'!G140 -> 2.71 | AO5: =AL5+AM5 -> 6.06 | AP5: ='2'!G123 -> 203.858 | AQ5: ='2'!G35 -> 2528.08 | AR5: ='2'!G37 -> 1523.68 | AS5: ='2'!G38 -> 0 | AT5: ='2'!G39 -> 3998.4 | AU5: ='2'!G40 -> 0 | AV5: ='2'!G41 -> -0.07 | AW5: ='2'!G42 -> 0 | AX5: ='2'!G43 -> 2366.04 | AY5: ='2'!G44 -> 0 | AZ5: ='2'!G36 -> 595.21 | BA5: ='2'!G49 -> 0.014 | BB5: ='2'!G51 -> 0 | BC5: ='2'!G52 -> 1713.94 | BD5: ='2'!G53 -> 0 | BE5: ='2'!G54 -> 69.3053 | BF5: ='2'!G55 -> 0.1 | BG5: ='2'!G56 -> 4613.84 | BH5: ='2'!G57 -> 0 | BI5: ='2'!G50 -> 1344.42 | BJ5: =SUM(AV5,AW5,BF5,BG5) -> 4613.87 | BK5: ='2'!G84 -> 602 | BL5: =SUM(AQ5,AV5,AW5,AX5,BA5,BF5,BG5,BH5)/I5% -> 48.929621 | BM5: =SUM(AT5,BD5)/I5% -> 20.576369 | BN5: =(AS5+BC5)/I5 -> 0.088201935 | BO5: =K5+O5+R5+V5 -> 244698.87 | BP5: =SUM(AV5,AW5,AX5,BF5,BG5,BH5,BK5) -> 7581.91 | BQ5: =BP5/(AE5*280) -> 1.1282604
A6: 3 | B6: 3 | D6: ='3'!D3 -> 31 | E6: ='3'!D4 -> 0.8 | F6: ='3'!D2 -> 0.3 | G6: ='3'!G8 -> 18200 | H6: ='3'!G8 -> 18200 | I6: ='3'!G7 -> 18137 | J6: 10 | K6: =H6*J6 -> 182000 | L6: =I6/202 -> 89.787129 | M6: ='3'!G15 -> 445.86 | N6: 35 | O6: =M6*N6 -> 15605.1 | P6: ='3'!G20 -> 133 | Q6: 134 | R6: =P6*Q6 -> 17822 | S6: =P6/(F6*202/100) -> 219.47195 | T6: ='3'!G24 -> 0 | U6: 69 | V6: =T6*U6 -> 0 | W6: ='3'!G95 -> 39 | X6: ='3'!G96 -> 42 | Y6: ='3'!G97 -> 14 | Z6: =W6+X6+Y6 -> 95 | AA6: ='3'!G132 -> 0 | AB6: ='3'!G133 -> 0 | AC6: ='3'!G134 -> 0 | AD6: ='3'!G135 -> 24 | AE6: =AA6+AB6+AC6+AD6 -> 24 | AF6: =AV6+AW6+BF6+BG6 -> 4094.16 | AG6: =AF6/AE6 -> 170.59 | AH6: ='3'!G136 -> 0 | AI6: ='3'!G137 -> 0 | AJ6: ='3'!G138 -> 7.7 | AK6: =AH6+AI6+AJ6 -> 7.7 | AL6: ='3'!G139 -> 4.25 | AM6: ='3'!G140 -> 0 | AO6: =AL6+AM6 -> 4.25 | AP6: ='3'!G123 -> 148.517 | AQ6: ='3'!G35 -> 2530.8 | AR6: ='3'!G37 -> 1481.92 | AS6: ='3'!G38 -> 0 | AT6: ='3'!G39 -> 3926.64 | AU6: ='3'!G40 -> 0 | AV6: ='3'!G41 -> 0 | AW6: ='3'!G42 -> 0 | AX6: ='3'!G43 -> 2353.76 | AY6: ='3'!G44 -> 0 | AZ6: ='3'!G36 -> 552.72 | BA6: ='3'!G49 -> -0.002 | BB6: ='3'!G51 -> 0 | BC6: ='3'!G52 -> 1782.8 | BD6: ='3'!G53 -> 0 | BE6: ='3'!G54 -> 73.1676 | BF6: ='3'!G55 -> 0 | BG6: ='3'!G56 -> 4094.16 | BH6: ='3'!G57 -> 0 | BI6: ='3'!G50 -> 873.6 | BJ6: =SUM(AV6,AW6,BF6,BG6) -> 4094.16 | BK6: ='3'!G84 -> 598 | BL6: =SUM(AQ6,AV6,AW6,AX6,BA6,BF6,BG6,BH6)/I6% -> 49.504979 | BM6: =SUM(AT6,BD6)/I6% -> 21.649887 | BN6: =(AS6+BC6)/I6 -> 0.0982963 | BO6: =K6+O6+R6+V6 -> 215427.1 | BP6: =SUM(AV6,AW6,AX6,BF6,BG6,BH6,BK6) -> 7045.92 | BQ6: =BP6/(AE6*280) -> 1.0485
A7: 4 | B7: 4 | D7: ='4'!D3 -> 31 | E7: ='4'!D4 -> 0.8 | F7: ='4'!D2 -> 0.3 | G7: ='4'!G8 -> 17729 | H7: ='4'!G8 -> 17729 | I7: ='4'!G7 -> 17671 | J7: 10 | K7: =H7*J7 -> 177290 | L7: =I7/202 -> 87.480198 | M7: ='4'!G15 -> 331.514 | N7: 35 | O7: =M7*N7 -> 11602.99 | P7: ='4'!G20 -> 137 | Q7: 134 | R7: =P7*Q7 -> 18358 | S7: =P7/(F7*202/100) -> 226.07261 | T7: ='4'!G24 -> 0 | U7: 69 | V7: =T7*U7 -> 0 | W7: ='4'!G95 -> 39 | X7: ='4'!G96 -> 42 | Y7: ='4'!G97 -> 14 | Z7: =W7+X7+Y7 -> 95 | AA7: ='4'!G132 -> 0 | AB7: ='4'!G133 -> 0 | AC7: ='4'!G134 -> 0 | AD7: ='4'!G135 -> 23.98 | AE7: =AA7+AB7+AC7+AD7 -> 23.98 | AF7: =AV7+AW7+BF7+BG7 -> 3875.76 | AG7: =AF7/AE7 -> 161.62469 | AH7: ='4'!G136 -> 0 | AI7: ='4'!G137 -> 0 | AJ7: ='4'!G138 -> 0 | AK7: =AH7+AI7+AJ7 -> 0 | AL7: ='4'!G139 -> 5.19 | AM7: ='4'!G140 -> 0 | AO7: =AL7+AM7 -> 5.19 | AP7: ='4'!G123 -> 191.297 | AQ7: ='4'!G35 -> 2485.56 | AR7: ='4'!G37 -> 1454.85 | AS7: ='4'!G38 -> 0.2 | AT7: ='4'!G39 -> 3726.88 | AU7: ='4'!G40 -> 0 | AV7: ='4'!G41 -> 0 | AW7: ='4'!G42 -> 0 | AX7: ='4'!G43 -> 2343.68 | AY7: ='4'!G44 -> 0 | AZ7: ='4'!G36 -> 549.37 | BA7: ='4'!G49 -> -0.15 | BB7: ='4'!G51 -> 0 | BC7: ='4'!G52 -> 1499.6 | BD7: ='4'!G53 -> 0 | BE7: ='4'!G54 -> 71.3024 | BF7: ='4'!G55 -> 0 | BG7: ='4'!G56 -> 3875.76 | BH7: ='4'!G57 -> 0 | BI7: ='4'!G50 -> 947.6 | BJ7: =SUM(AV7,AW7,BF7,BG7) -> 3875.76 | BK7: ='3'!G84 -> 598 | BL7: =SUM(AQ7,AV7,AW7,AX7,BA7,BF7,BG7,BH7)/I7% -> 49.260653 | BM7: =SUM(AT7,BD7)/I7% -> 21.090374 | BN7: =(AS7+BC7)/I7 -> 0.084873522 | BO7: =K7+O7+R7+V7 -> 207250.99 | BP7: =SUM(AV7,AW7,AX7,BF7,BG7,BH7,BK7) -> 6817.44 | BQ7: =BP7/(AE7*280) -> 1.0153461
A8: 5 | B8: 5 | D8: ='5'!D3 -> 28 | E8: ='5'!D4 -> 0.76 | F8: ='5'!D2 -> 0.25 | G8: ='5'!G8 -> 18144 | H8: ='5'!G8 -> 18144 | I8: ='5'!G7 -> 18057 | J8: 10 | K8: =H8*J8 -> 181440 | L8: =I8/202 -> 89.391089 | M8: ='5'!G15 -> 465.094 | N8: 35 | O8: =M8*N8 -> 16278.29 | P8: ='5'!G20 -> 149 | Q8: 134 | R8: =P8*Q8 -> 19966 | S8: =P8/(F8*202/100) -> 295.0495 | T8: ='5'!G24 -> 0 | U8: 69 | V8: =T8*U8 -> 0 | W8: ='5'!G95 -> 91 | X8: ='5'!G96 -> 88 | Y8: ='5'!G97 -> 25 | Z8: =W8+X8+Y8 -> 204 | AA8: ='5'!G132 -> 0 | AB8: ='5'!G133 -> 0 | AC8: ='5'!G134 -> 0 | AD8: ='5'!G135 -> 24 | AE8: =AA8+AB8+AC8+AD8 -> 24 | AF8: =AV8+AW8+BF8+BG8 -> 4112.79 | AG8: =AF8/AE8 -> 171.36625 | AH8: ='5'!G136 -> 0.005 | AI8: ='5'!G137 -> 0 | AJ8: ='5'!G138 -> 8.75 | AK8: =AH8+AI8+AJ8 -> 8.755 | AL8: ='5'!G139 -> 5.12 | AM8: ='5'!G140 -> 0 | AO8: =AL8+AM8 -> 5.12 | AP8: ='5'!G123 -> 170.834 | AQ8: ='5'!G35 -> 2595.53 | AR8: ='5'!G37 -> 1501.19 | AS8: ='5'!G38 -> 0 | AT8: ='5'!G39 -> 3882 | AU8: ='5'!G40 -> 0 | AV8: ='5'!G41 -> 0 | AW8: ='5'!G42 -> -0.07 | AX8: ='5'!G43 -> 2369.52 | AY8: ='5'!G44 -> 0 | AZ8: ='5'!G36 -> 596.21 | BA8: ='5'!G49 -> 0.138 | BB8: ='5'!G51 -> 0 | BC8: ='5'!G52 -> 1811.36 | BD8: ='5'!G53 -> 0 | BE8: ='5'!G54 -> 74.5131 | BF8: ='5'!G55 -> 0 | BG8: ='5'!G56 -> 4112.86 | BH8: ='5'!G57 -> 0 | BI8: ='5'!G50 -> 908.48 | BJ8: =SUM(AV8,AW8,BF8,BG8) -> 4112.79 | BK8: ='5'!G84 -> 554 | BL8: =SUM(AQ8,AV8,AW8,AX8,BA8,BF8,BG8,BH8)/I8% -> 50.27401 | BM8: =SUM(AT8,BD8)/I8% -> 21.498588 | BN8: =(AS8+BC8)/I8 -> 0.10031345 | BO8: =K8+O8+R8+V8 -> 217684.29 | BP8: =SUM(AV8,AW8,AX8,BF8,BG8,BH8,BK8) -> 7036.31 | BQ8: =BP8/(AE8*280) -> 1.0470699
A9: 6 | B9: 6 | D9: ='6'!D3 -> 35 | E9: ='6'!D4 -> 0.8 | F9: ='6'!D2 -> 0.25 | G9: ='6'!G8 -> 18698 | H9: ='6'!G8 -> 18698 | I9: ='6'!G7 -> 18605 | J9: 10 | K9: =H9*J9 -> 186980 | L9: =I9/202 -> 92.10396 | M9: ='6'!G15 -> 617.474 | N9: 35 | O9: =M9*N9 -> 21611.59 | P9: ='6'!G20 -> 162 | Q9: 134 | R9: =P9*Q9 -> 21708 | S9: =P9/(F9*202/100) -> 320.79208 | T9: ='6'!G24 -> 0 | U9: 69 | V9: =T9*U9 -> 0 | W9: ='6'!G95 -> 72 | X9: ='6'!G96 -> 44 | Y9: ='6'!G97 -> 69 | Z9: =W9+X9+Y9 -> 185 | AA9: ='6'!G132 -> 0 | AB9: ='6'!G133 -> 0 | AC9: ='6'!G134 -> 0 | AD9: ='6'!G135 -> 24 | AE9: =AA9+AB9+AC9+AD9 -> 24 | AF9: =AV9+AW9+BF9+BG9 -> 4170.86 | AG9: =AF9/AE9 -> 173.78583 | AH9: ='6'!G136 -> 6.925 | AI9: ='6'!G137 -> 0 | AJ9: ='6'!G138 -> 0 | AK9: =AH9+AI9+AJ9 -> 6.925 | AL9: ='6'!G139 -> 4.98 | AM9: ='6'!G140 -> 0 | AO9: =AL9+AM9 -> 4.98 | AP9: ='6'!G123 -> 168.706 | AQ9: ='6'!G35 -> 2481.31 | AR9: ='6'!G37 -> 1516.44 | AS9: ='6'!G38 -> 0.18 | AT9: ='6'!G39 -> 3868.96 | AU9: ='6'!G40 -> 0 | AV9: ='6'!G41 -> 0 | AW9: ='6'!G42 -> 0 | AX9: ='6'!G43 -> 2406.84 | AY9: ='6'!G44 -> 0 | AZ9: ='6'!G36 -> 792.12 | BA9: ='6'!G49 -> -0.458 | BB9: ='6'!G51 -> 0 | BC9: ='6'!G52 -> 1767.4 | BD9: ='6'!G53 -> 0 | BE9: ='6'!G54 -> 75.3364 | BF9: ='6'!G55 -> 0 | BG9: ='6'!G56 -> 4170.86 | BH9: ='6'!G57 -> 0 | BI9: ='6'!G50 -> 922.38 | BJ9: =SUM(AV9,AW9,BF9,BG9) -> 4170.86 | BK9: ='6'!G84 -> 616 | BL9: =SUM(AQ9,AV9,AW9,AX9,BA9,BF9,BG9,BH9)/I9% -> 48.688804 | BM9: =SUM(AT9,BD9)/I9% -> 20.79527 | BN9: =(AS9+BC9)/I9 -> 0.095005644 | BO9: =K9+O9+R9+V9 -> 230299.59 | BP9: =SUM(AV9,AW9,AX9,BF9,BG9,BH9,BK9) -> 7193.7 | BQ9: =BP9/(AE9*280) -> 1.0704911
A10: 7 | B10: 7 | D10: ='7'!D3 -> 28 | E10: ='7'!D4 -> 0.78 | F10: ='7'!D2 -> 0.54 | G10: ='7'!G8 -> 18577 | H10: ='7'!G8 -> 18577 | I10: ='7'!G7 -> 18512 | J10: 10 | K10: =H10*J10 -> 185770 | L10: =I10/202 -> 91.643564 | M10: ='7'!G15 -> 527.368 | N10: 35 | O10: =M10*N10 -> 18457.88 | P10: ='7'!G20 -> 155 | Q10: 134 | R10: =P10*Q10 -> 20770 | S10: =P10/(F10*202/100) -> 142.09754 | T10: ='7'!G24 -> 0 | U10: 69 | V10: =T10*U10 -> 0 | W10: ='7'!G95 -> 45 | X10: ='7'!G96 -> 44 | Y10: ='7'!G97 -> 19 | Z10: =W10+X10+Y10 -> 108 | AA10: ='7'!G132 -> 0 | AB10: ='7'!G133 -> 0 | AC10: ='7'!G134 -> 0 | AD10: ='7'!G135 -> 24.47 | AE10: =AA10+AB10+AC10+AD10 -> 24.47 | AF10: =AV10+AW10+BF10+BG10 -> 4275.24 | AG10: =AF10/AE10 -> 174.71353 | AH10: ='7'!G136 -> 0 | AI10: ='7'!G137 -> -0.25 | AJ10: ='7'!G138 -> 9.22 | AK10: =AH10+AI10+AJ10 -> 8.97 | AL10: ='7'!G139 -> 5.48 | AM10: ='7'!G140 -> 0 | AO10: =AL10+AM10 -> 5.48 | AP10: ='7'!G123 -> 191.97 | AQ10: ='7'!G35 -> 2497.36 | AR10: ='7'!G37 -> 1537.76 | AS10: ='7'!G38 -> -0.38 | AT10: ='7'!G39 -> 4012.56 | AU10: ='7'!G40 -> 0 | AV10: ='7'!G41 -> 0 | AW10: ='7'!G42 -> 0 | AX10: ='7'!G43 -> 2337.48 | AY10: ='7'!G44 -> 0 | AZ10: ='7'!G36 -> 623.22 | BA10: ='7'!G49 -> 0 | BB10: ='7'!G51 -> 0 | BC10: ='7'!G52 -> 1702.34 | BD10: ='7'!G53 -> 0 | BE10: ='7'!G54 -> 72.6652 | BF10: ='7'!G55 -> 0 | BG10: ='7'!G56 -> 4275.24 | BH10: ='7'!G57 -> 0 | BI10: ='7'!G50 -> 946.34 | BJ10: =SUM(AV10,AW10,BF10,BG10) -> 4275.24 | BK10: ='7'!G84 -> 424 | BL10: =SUM(AQ10,AV10,AW10,AX10,BA10,BF10,BG10,BH10)/I10% -> 49.211755 | BM10: =SUM(AT10,BD10)/I10% -> 21.675454 | BN10: =(AS10+BC10)/I10 -> 0.091938202 | BO10: =K10+O10+R10+V10 -> 224997.88 | BP10: =SUM(AV10,AW10,AX10,BF10,BG10,BH10,BK10) -> 7036.72 | BQ10: =BP10/(AE10*280) -> 1.0270185
A11: 8 | B11: 8 | D11: ='8'!D3 -> 29 | E11: ='8'!D4 -> 0.79 | F11: ='8'!D2 -> 0.45 | G11: ='8'!G8 -> 19646 | H11: ='8'!G8 -> 19646 | I11: ='8'!G7 -> 19582 | J11: 10 | K11: =H11*J11 -> 196460 | L11: =I11/202 -> 96.940594 | M11: ='8'!G15 -> 379.039 | N11: 35 | O11: =M11*N11 -> 13266.365 | P11: ='8'!G20 -> 153 | Q11: 134 | R11: =P11*Q11 -> 20502 | S11: =P11/(F11*202/100) -> 168.31683 | T11: ='8'!G24 -> 0 | U11: 69 | V11: =T11*U11 -> 0 | W11: ='8'!G95 -> 41 | X11: ='8'!G96 -> 50 | Y11: ='8'!G97 -> 41 | Z11: =W11+X11+Y11 -> 132 | AA11: ='8'!G132 -> 0 | AB11: ='8'!G133 -> 0 | AC11: ='8'!G134 -> 0 | AD11: ='8'!G135 -> 23.53 | AE11: =AA11+AB11+AC11+AD11 -> 23.53 | AF11: =AV11+AW11+BF11+BG11 -> 4636.92 | AG11: =AF11/AE11 -> 197.06417 | AH11: ='8'!G136 -> 0 | AI11: ='8'!G137 -> 0.25 | AJ11: ='8'!G138 -> 0 | AK11: =AH11+AI11+AJ11 -> 0.25 | AL11: ='8'!G139 -> 6.1 | AM11: ='8'!G140 -> 0 | AO11: =AL11+AM11 -> 6.1 | AP11: ='8'!G123 -> 213.673 | AQ11: ='8'!G35 -> 2675.84 | AR11: ='8'!G37 -> 1574.52 | AS11: ='8'!G38 -> 0 | AT11: ='8'!G39 -> 4130.72 | AU11: ='8'!G40 -> 0 | AV11: ='8'!G41 -> 0 | AW11: ='8'!G42 -> 0 | AX11: ='8'!G43 -> 2425.52 | AY11: ='8'!G44 -> 0 | AZ11: ='8'!G36 -> 777.32 | BA11: ='8'!G49 -> 0 | BB11: ='8'!G51 -> 0 | BC11: ='8'!G52 -> 1753.74 | BD11: ='8'!G53 -> 0 | BE11: ='8'!G54 -> 74.8896 | BF11: ='8'!G55 -> 0 | BG11: ='8'!G56 -> 4636.92 | BH11: ='8'!G57 -> 0 | BI11: ='8'!G50 -> 1047.06 | BJ11: =SUM(AV11,AW11,BF11,BG11) -> 4636.92 | BK11: ='8'!G84 -> 411 | BL11: =SUM(AQ11,AV11,AW11,AX11,BA11,BF11,BG11,BH11)/I11% -> 49.730773 | BM11: =SUM(AT11,BD11)/I11% -> 21.094475 | BN11: =(AS11+BC11)/I11 -> 0.089558778 | BO11: =K11+O11+R11+V11 -> 230228.37 | BP11: =SUM(AV11,AW11,AX11,BF11,BG11,BH11,BK11) -> 7473.44 | BQ11: =BP11/(AE11*280) -> 1.1343331
A12: 9 | B12: 9 | D12: ='9'!D3 -> 29 | E12: ='9'!D4 -> 0.79 | F12: ='9'!D2 -> 0.45 | G12: ='9'!G8 -> 19646 | H12: ='9'!G8 -> 19646 | I12: ='9'!G7 -> 19582 | J12: 10 | K12: =H12*J12 -> 196460 | L12: =I12/202 -> 96.940594 | M12: ='9'!G15 -> 379.039 | N12: 35 | O12: =M12*N12 -> 13266.365 | P12: ='9'!G20 -> 153 | Q12: 134 | R12: =P12*Q12 -> 20502 | S12: =P12/(F12*202/100) -> 168.31683 | T12: ='9'!G24 -> 0 | U12: 69 | V12: =T12*U12 -> 0 | W12: ='9'!G95 -> 41 | X12: ='9'!G96 -> 50 | Y12: ='9'!G97 -> 41 | Z12: =W12+X12+Y12 -> 132 | AA12: ='9'!G132 -> 0 | AB12: ='9'!G133 -> 0 | AC12: ='9'!G134 -> 0 | AD12: ='9'!G135 -> 23.53 | AE12: =AA12+AB12+AC12+AD12 -> 23.53 | AF12: =AV12+AW12+BF12+BG12 -> 4636.92 | AG12: =AF12/AE12 -> 197.06417 | AH12: ='9'!G136 -> 0 | AI12: ='9'!G137 -> 0.25 | AJ12: ='9'!G138 -> 0 | AK12: =AH12+AI12+AJ12 -> 0.25 | AL12: ='9'!G139 -> 6.1 | AM12: ='9'!G140 -> 0 | AO12: =AL12+AM12 -> 6.1 | AP12: ='9'!G123 -> 213.673 | AQ12: ='9'!G35 -> 2675.84 | AR12: ='9'!G37 -> 1574.52 | AS12: ='9'!G38 -> 0 | AT12: ='9'!G39 -> 4130.72 | AU12: ='9'!G40 -> 0 | AV12: ='9'!G41 -> 0 | AW12: ='9'!G42 -> 0 | AX12: ='9'!G43 -> 2425.52 | AY12: ='9'!G44 -> 0 | AZ12: ='9'!G36 -> 777.32 | BA12: ='9'!G49 -> 0 | BB12: ='9'!G51 -> 0 | BC12: ='9'!G52 -> 1753.74 | BD12: ='9'!G53 -> 0 | BE12: ='9'!G54 -> 74.8896 | BF12: ='9'!G55 -> 0 | BG12: ='9'!G56 -> 4636.92 | BH12: ='9'!G57 -> 0 | BI12: ='9'!G50 -> 1047.06 | BJ12: =SUM(AV12,AW12,BF12,BG12) -> 4636.92 | BK12: ='8'!G84 -> 411 | BL12: =SUM(AQ12,AV12,AW12,AX12,BA12,BF12,BG12,BH12)/I12% -> 49.730773 | BM12: =SUM(AT12,BD12)/I12% -> 21.094475 | BN12: =(AS12+BC12)/I12 -> 0.089558778 | BO12: =K12+O12+R12+V12 -> 230228.37 | BP12: =SUM(AV12,AW12,AX12,BF12,BG12,BH12,BK12) -> 7473.44 | BQ12: =BP12/(AE12*280) -> 1.1343331
A13: 10 | B13: 10 | D13: ='10'!D3 -> 31 | E13: ='10'!D4 -> 0.82 | F13: ='10'!D2 -> 0.19 | G13: ='10'!G8 -> 37177 | H13: ='10'!G8 -> 37177 | I13: ='10'!G7 -> 37064 | J13: 10 | K13: =H13*J13 -> 371770 | L13: =I13/202 -> 183.48515 | M13: ='10'!G15 -> 1342.379 | N13: 35 | O13: =M13*N13 -> 46983.265 | P13: ='10'!G20 -> 266 | Q13: 134 | R13: =P13*Q13 -> 35644 | S13: =P13/(F13*202/100) -> 693.06931 | T13: ='10'!G24 -> 0 | U13: 69 | V13: =T13*U13 -> 0 | W13: ='10'!G95 -> 140 | X13: ='10'!G96 -> 93 | Y13: ='10'!G97 -> 35 | Z13: =W13+X13+Y13 -> 268 | AA13: ='10'!G132 -> 0 | AB13: ='10'!G133 -> 0 | AC13: ='10'!G134 -> -1 | AD13: ='10'!G135 -> 47.5 | AE13: =AA13+AB13+AC13+AD13 -> 46.5 | AF13: =AV13+AW13+BF13+BG13 -> 8054.69 | AG13: =AF13/AE13 -> 173.21914 | AH13: ='10'!G136 -> 14.23 | AI13: ='10'!G137 -> 0 | AJ13: ='10'!G138 -> 2.37 | AK13: =AH13+AI13+AJ13 -> 16.6 | AL13: ='10'!G139 -> 9.98 | AM13: ='10'!G140 -> 0 | AO13: =AL13+AM13 -> 9.98 | AP13: ='10'!G123 -> 351.637 | AQ13: ='10'!G35 -> 4846.49 | AR13: ='10'!G37 -> 2902.29 | AS13: ='10'!G38 -> 0 | AT13: ='10'!G39 -> 8066.85 | AU13: ='10'!G40 -> 0 | AV13: ='10'!G41 -> 0 | AW13: ='10'!G42 -> 0 | AX13: ='10'!G43 -> 4732.85 | AY13: ='10'!G44 -> 0 | AZ13: ='10'!G36 -> 1108.83 | BA13: ='10'!G49 -> 0.45 | BB13: ='10'!G51 -> 0 | BC13: ='10'!G52 -> 3624.73 | BD13: ='10'!G53 -> 0 | BE13: ='10'!G54 -> 148.8957 | BF13: ='10'!G55 -> 0 | BG13: ='10'!G56 -> 8054.69 | BH13: ='10'!G57 -> 0 | BI13: ='10'!G50 -> 2252.37 | BJ13: =SUM(AV13,AW13,BF13,BG13) -> 8054.69 | BK13: ='8'!G84 -> 411 | BL13: =SUM(AQ13,AV13,AW13,AX13,BA13,BF13,BG13,BH13)/I13% -> 47.578459 | BM13: =SUM(AT13,BD13)/I13% -> 21.76465 | BN13: =(AS13+BC13)/I13 -> 0.097796514 | BO13: =K13+O13+R13+V13 -> 454397.26 | BP13: =SUM(AV13,AW13,AX13,BF13,BG13,BH13,BK13) -> 13198.54 | BQ13: =BP13/(AE13*280) -> 1.0137127
A14: 11 | B14: 11 | D14: ='11'!D3 -> 31 | E14: ='11'!D4 -> 0.82 | F14: ='11'!D2 -> 0.22 | G14: ='11'!G8 -> 17356 | H14: ='11'!G8 -> 17356 | I14: ='11'!G7 -> 17244 | J14: 10 | K14: =H14*J14 -> 173560 | L14: =I14/202 -> 85.366337 | M14: ='11'!G15 -> 508 | N14: 35 | O14: =M14*N14 -> 17780 | P14: ='11'!G20 -> 236 | Q14: 134 | R14: =P14*Q14 -> 31624 | S14: =P14/(F14*202/100) -> 531.05311 | T14: ='11'!G24 -> 0 | U14: 69 | V14: =T14*U14 -> 0 | W14: ='11'!G95 -> 51 | X14: ='11'!G96 -> 57 | Y14: ='11'!G97 -> 15 | Z14: =W14+X14+Y14 -> 123 | AA14: ='11'!G132 -> 0 | AB14: ='11'!G133 -> 0 | AC14: ='11'!G134 -> 0 | AD14: ='11'!G135 -> 23.5 | AE14: =AA14+AB14+AC14+AD14 -> 23.5 | AF14: =AV14+AW14+BF14+BG14 -> 3361.34 | AG14: =AF14/AE14 -> 143.03574 | AH14: ='11'!G136 -> -0.31 | AI14: ='11'!G137 -> -0.25 | AJ14: ='11'!G138 -> 9.07 | AK14: =AH14+AI14+AJ14 -> 8.51 | AL14: ='11'!G139 -> 5.42 | AM14: ='11'!G140 -> 0 | AO14: =AL14+AM14 -> 5.42 | AP14: ='11'!G123 -> 193 | AQ14: ='11'!G35 -> 483 | AR14: ='11'!G37 -> 204 | AS14: ='11'!G38 -> 0 | AT14: ='11'!G39 -> 657 | AU14: ='11'!G40 -> 0 | AV14: ='11'!G41 -> 0 | AW14: ='11'!G42 -> 0.07 | AX14: ='11'!G43 -> 2350 | AY14: ='11'!G44 -> 0 | AZ14: ='11'!G36 -> 556 | BA14: ='11'!G49 -> 2024.17 | BB14: ='11'!G51 -> 0 | BC14: ='11'!G52 -> 1713 | BD14: ='11'!G53 -> 4110 | BE14: ='11'!G54 -> 65 | BF14: ='11'!G55 -> 0.27 | BG14: ='11'!G56 -> 3361 | BH14: ='11'!G57 -> 0 | BI14: ='11'!G50 -> 1072 | BJ14: =SUM(AV14,AW14,BF14,BG14) -> 3361.34 | BK14: ='11'!G84 -> 459 | BL14: =SUM(AQ14,AV14,AW14,AX14,BA14,BF14,BG14,BH14)/I14% -> 47.660114 | BM14: =SUM(AT14,BD14)/I14% -> 27.644398 | BN14: =(AS14+BC14)/I14 -> 0.0993389 | BO14: =K14+O14+R14+V14 -> 222964 | BP14: =SUM(AV14,AW14,AX14,BF14,BG14,BH14,BK14) -> 6170.34 | BQ14: =BP14/(AE14*280) -> 0.93774164
A15: 12 | B15: 12 | D15: ='12'!D3 -> 31 | E15: ='12'!D4 -> 0.82 | F15: ='12'!D2 -> 0.25 | G15: ='12'!G8 -> 17861 | H15: ='12'!G8 -> 17861 | I15: ='12'!G7 -> 17812 | J15: 10 | K15: =H15*J15 -> 178610 | L15: =I15/202 -> 88.178218 | M15: ='12'!G15 -> 370 | N15: 35 | O15: =M15*N15 -> 12950 | P15: ='12'!G20 -> 192 | Q15: 134 | R15: =P15*Q15 -> 25728 | S15: =P15/(F15*202/100) -> 380.19802 | T15: ='12'!G24 -> 0 | U15: 69 | V15: =T15*U15 -> 0 | W15: ='12'!G95 -> 43 | X15: ='12'!G96 -> 57 | Y15: ='12'!G97 -> 16 | Z15: =W15+X15+Y15 -> 116 | AA15: ='12'!G132 -> 0 | AB15: ='12'!G133 -> 0 | AC15: ='12'!G134 -> 0 | AD15: ='12'!G135 -> 24 | AE15: =AA15+AB15+AC15+AD15 -> 24 | AF15: =AV15+AW15+BF15+BG15 -> 3758.73 | AG15: =AF15/AE15 -> 156.61375 | AH15: ='12'!G136 -> 0 | AI15: ='12'!G137 -> 0 | AJ15: ='12'!G138 -> 0 | AK15: =AH15+AI15+AJ15 -> 0 | AL15: ='12'!G139 -> 5.99 | AM15: ='12'!G140 -> 0 | AO15: =AL15+AM15 -> 5.99 | AP15: ='12'!G123 -> 206 | AQ15: ='12'!G35 -> 0 | AR15: ='12'!G37 -> 0 | AS15: ='12'!G38 -> 0 | AT15: ='12'!G39 -> 0 | AU15: ='12'!G40 -> 0 | AV15: ='12'!G41 -> 0 | AW15: ='12'!G42 -> 0 | AX15: ='12'!G43 -> 2357 | AY15: ='12'!G44 -> 0 | AZ15: ='12'!G36 -> 552 | BA15: ='12'!G49 -> 2039 | BB15: ='12'!G51 -> 0 | BC15: ='12'!G52 -> 1691 | BD15: ='12'!G53 -> 3991 | BE15: ='12'!G54 -> 62 | BF15: ='12'!G55 -> -0.27 | BG15: ='12'!G56 -> 3759 | BH15: ='12'!G57 -> 0 | BI15: ='12'!G50 -> 1192 | BJ15: =SUM(AV15,AW15,BF15,BG15) -> 3758.73 | BK15: ='12'!G84 -> 462 | BL15: =SUM(AQ15,AV15,AW15,AX15,BA15,BF15,BG15,BH15)/I15% -> 45.782225 | BM15: =SUM(AT15,BD15)/I15% -> 22.406243 | BN15: =(AS15+BC15)/I15 -> 0.094935998 | BO15: =K15+O15+R15+V15 -> 217288 | BP15: =SUM(AV15,AW15,AX15,BF15,BG15,BH15,BK15) -> 6577.73 | BQ15: =BP15/(AE15*280) -> 0.97882887
A16: 13 | B16: 13 | D16: ='13'!D3 -> 32 | E16: ='13'!D4 -> 0.82 | F16: ='13'!D2 -> 0.5 | G16: ='13'!G8 -> 17476 | H16: ='13'!G8 -> 17476 | I16: ='13'!G7 -> 17390 | J16: 10 | K16: =H16*J16 -> 174760 | L16: =I16/202 -> 86.089109 | M16: ='13'!G15 -> 618.601 | N16: 35 | O16: =M16*N16 -> 21651.035 | P16: ='13'!G20 -> 153 | Q16: 134 | R16: =P16*Q16 -> 20502 | S16: =P16/(F16*202/100) -> 151.48515 | T16: ='13'!G24 -> 0 | U16: 69 | V16: =T16*U16 -> 0 | W16: ='13'!G95 -> 65 | X16: ='13'!G96 -> 48 | Y16: ='13'!G97 -> 13 | Z16: =W16+X16+Y16 -> 126 | AA16: ='13'!G132 -> 0 | AB16: ='13'!G133 -> 0 | AC16: ='13'!G134 -> 0 | AD16: ='13'!G135 -> 24 | AE16: =AA16+AB16+AC16+AD16 -> 24 | AF16: =AV16+AW16+BF16+BG16 -> 3984.64 | AG16: =AF16/AE16 -> 166.02667 | AH16: ='13'!G136 -> 0.37 | AI16: ='13'!G137 -> 7.24 | AJ16: ='13'!G138 -> 0.49 | AK16: =AH16+AI16+AJ16 -> 8.1 | AL16: ='13'!G139 -> 5.14 | AM16: ='13'!G140 -> -0.02 | AO16: =AL16+AM16 -> 5.12 | AP16: ='13'!G123 -> 178.241 | AQ16: ='13'!G35 -> 0 | AR16: ='13'!G37 -> 0 | AS16: ='13'!G38 -> 0 | AT16: ='13'!G39 -> 0 | AU16: ='13'!G40 -> 0 | AV16: ='13'!G41 -> 0.05 | AW16: ='13'!G42 -> 0 | AX16: ='13'!G43 -> 2302.55 | AY16: ='13'!G44 -> 0 | AZ16: ='13'!G36 -> 494.63 | BA16: ='13'!G49 -> 2070.141 | BB16: ='13'!G51 -> 4121.85 | BC16: ='13'!G52 -> 1723.35 | BD16: ='13'!G53 -> 0 | BE16: ='13'!G54 -> 63.6093 | BF16: ='13'!G55 -> 0 | BG16: ='13'!G56 -> 3984.59 | BH16: ='13'!G57 -> 0 | BI16: ='13'!G50 -> 1008.67 | BJ16: =SUM(AV16,AW16,BF16,BG16) -> 3984.64 | BK16: ='13'!G84 -> 531 | BL16: =SUM(AQ16,AV16,AW16,AX16,BA16,BF16,BG16,BH16)/I16% -> 48.058258 | BM16: =SUM(AT16,BD16)/I16% -> 0 | BN16: =(AS16+BC16)/I16 -> 0.099100058 | BO16: =K16+O16+R16+V16 -> 216913.04 | BP16: =SUM(AV16,AW16,AX16,BF16,BG16,BH16,BK16) -> 6818.19 | BQ16: =BP16/(AE16*280) -> 1.0146116
A17: 14 | B17: 14 | D17: ='14'!D3 -> 31 | E17: ='14'!D4 -> 0.82 | F17: ='14'!D2 -> 0.5 | G17: ='14'!G8 -> 18156 | H17: ='14'!G8 -> 18156 | I17: ='14'!G7 -> 18088 | J17: 10 | K17: =H17*J17 -> 181560 | L17: =I17/202 -> 89.544554 | M17: ='14'!G15 -> 361.776 | N17: 35 | O17: =M17*N17 -> 12662.16 | P17: ='14'!G20 -> 123 | Q17: 134 | R17: =P17*Q17 -> 16482 | S17: =P17/(F17*202/100) -> 121.78218 | T17: ='14'!G24 -> 0 | U17: 69 | V17: =T17*U17 -> 0 | W17: ='14'!G95 -> 45 | X17: ='14'!G96 -> 21.2 | Y17: ='14'!G97 -> 15 | Z17: =W17+X17+Y17 -> 81.2 | AA17: ='14'!G132 -> 0 | AB17: ='14'!G133 -> 0 | AC17: ='14'!G134 -> 0 | AD17: ='14'!G135 -> 24 | AE17: =AA17+AB17+AC17+AD17 -> 24 | AF17: =AV17+AW17+BF17+BG17 -> 4624.8 | AG17: =AF17/AE17 -> 192.7 | AH17: ='14'!G136 -> 0 | AI17: ='14'!G137 -> 0 | AJ17: ='14'!G138 -> -0.09 | AK17: =AH17+AI17+AJ17 -> -0.09 | AL17: ='14'!G139 -> 6 | AM17: ='14'!G140 -> 0.02 | AO17: =AL17+AM17 -> 6.02 | AP17: ='14'!G123 -> 208.289 | AQ17: ='14'!G35 -> 0 | AR17: ='14'!G37 -> 0 | AS17: ='14'!G38 -> 0 | AT17: ='14'!G39 -> 0 | AU17: ='14'!G40 -> 0 | AV17: ='14'!G41 -> 0 | AW17: ='14'!G42 -> 0 | AX17: ='14'!G43 -> 2387.24 | AY17: ='14'!G44 -> 0 | AZ17: ='14'!G36 -> 540.94 | BA17: ='14'!G49 -> 3101.312 | BB17: ='14'!G51 -> 1284.7459 | BC17: ='14'!G52 -> 1623.2 | BD17: ='14'!G53 -> 0 | BE17: ='14'!G54 -> 63.5447 | BF17: ='14'!G55 -> 0 | BG17: ='14'!G56 -> 4624.8 | BH17: ='14'!G57 -> 0 | BI17: ='14'!G50 -> 926.02 | BJ17: =SUM(AV17,AW17,BF17,BG17) -> 4624.8 | BK17: ='14'!G84 -> 485 | BL17: =SUM(AQ17,AV17,AW17,AX17,BA17,BF17,BG17,BH17)/I17% -> 55.911942 | BM17: =SUM(AT17,BD17)/I17% -> 0 | BN17: =(AS17+BC17)/I17 -> 0.089739054 | BO17: =K17+O17+R17+V17 -> 210704.16 | BP17: =SUM(AV17,AW17,AX17,BF17,BG17,BH17,BK17) -> 7497.04 | BQ17: =BP17/(AE17*280) -> 1.115631
A18: 15 | B18: 15 | D18: ='15'!D3 -> 29 | E18: ='15'!D4 -> 0.8 | F18: ='15'!D2 -> 0.5 | G18: ='15'!G8 -> 19281 | H18: ='15'!G8 -> 19281 | I18: ='15'!G7 -> 19222 | J18: 10 | K18: =H18*J18 -> 192810 | L18: =I18/202 -> 95.158416 | M18: ='15'!G15 -> 414.628 | N18: 35 | O18: =M18*N18 -> 14511.98 | P18: ='15'!G20 -> 112 | Q18: 134 | R18: =P18*Q18 -> 15008 | S18: =P18/(F18*202/100) -> 110.89109 | T18: ='15'!G24 -> 0 | U18: 69 | V18: =T18*U18 -> 0 | W18: ='15'!G95 -> 46 | X18: ='15'!G96 -> 22 | Y18: ='15'!G97 -> 12 | Z18: =W18+X18+Y18 -> 80 | AA18: ='15'!G132 -> 0 | AB18: ='15'!G133 -> 0 | AC18: ='15'!G134 -> 0 | AD18: ='15'!G135 -> 24 | AE18: =AA18+AB18+AC18+AD18 -> 24 | AF18: =AV18+AW18+BF18+BG18 -> 5319.14 | AG18: =AF18/AE18 -> 221.63083 | AH18: ='15'!G136 -> 0 | AI18: ='15'!G137 -> 0 | AJ18: ='15'!G138 -> -0.09 | AK18: =AH18+AI18+AJ18 -> -0.09 | AL18: ='15'!G139 -> 6.58 | AM18: ='15'!G140 -> 0 | AO18: =AL18+AM18 -> 6.58 | AP18: ='15'!G123 -> 230.37 | AQ18: ='15'!G35 -> 0 | AR18: ='15'!G37 -> 0 | AS18: ='15'!G38 -> 0 | AT18: ='15'!G39 -> 0 | AU18: ='15'!G40 -> 0 | AV18: ='15'!G41 -> 0 | AW18: ='15'!G42 -> 0 | AX18: ='15'!G43 -> 2364.6 | AY18: ='15'!G44 -> 0 | AZ18: ='15'!G36 -> 530.88 | BA18: ='15'!G49 -> 2554.388 | BB18: ='15'!G51 -> 1299.8829 | BC18: ='15'!G52 -> 1693.32 | BD18: ='15'!G53 -> 0 | BE18: ='15'!G54 -> 61.29 | BF18: ='15'!G55 -> 0 | BG18: ='15'!G56 -> 5319.14 | BH18: ='15'!G57 -> 0 | BI18: ='15'!G50 -> 1053.72 | BJ18: =SUM(AV18,AW18,BF18,BG18) -> 5319.14 | BK18: ='15'!G84 -> 482 | BL18: =SUM(AQ18,AV18,AW18,AX18,BA18,BF18,BG18,BH18)/I18% -> 53.262553 | BM18: =SUM(AT18,BD18)/I18% -> 0 | BN18: =(AS18+BC18)/I18 -> 0.08809281 | BO18: =K18+O18+R18+V18 -> 222329.98 | BP18: =SUM(AV18,AW18,AX18,BF18,BG18,BH18,BK18) -> 8165.74 | BQ18: =BP18/(AE18*280) -> 1.2151399
A19: 16 | B19: 16 | D19: ='16'!D3 -> 29 | E19: ='16'!D4 -> 0.8 | F19: ='16'!D2 -> 0.5 | G19: ='16'!G8 -> 19281 | H19: ='16'!G8 -> 19281 | I19: ='16'!G7 -> 19222 | J19: 10 | K19: =H19*J19 -> 192810 | L19: =I19/202 -> 95.158416 | M19: ='16'!G15 -> 414.628 | N19: 35 | O19: =M19*N19 -> 14511.98 | P19: ='16'!G20 -> 112 | Q19: 134 | R19: =P19*Q19 -> 15008 | S19: =P19/(F19*202/100) -> 110.89109 | T19: ='16'!G24 -> 0 | U19: 69 | V19: =T19*U19 -> 0 | W19: ='16'!G95 -> 46 | X19: ='16'!G96 -> 22 | Y19: ='16'!G97 -> 12 | Z19: =W19+X19+Y19 -> 80 | AA19: ='16'!G132 -> 0 | AB19: ='16'!G133 -> 0 | AC19: ='16'!G134 -> 0 | AD19: ='16'!G135 -> 24 | AE19: =AA19+AB19+AC19+AD19 -> 24 | AF19: =AV19+AW19+BF19+BG19 -> 5319.14 | AG19: =AF19/AE19 -> 221.63083 | AH19: ='16'!G136 -> 0 | AI19: ='16'!G137 -> 0 | AJ19: ='16'!G138 -> -0.09 | AK19: =AH19+AI19+AJ19 -> -0.09 | AL19: ='16'!G139 -> 6.58 | AM19: ='16'!G140 -> 0 | AO19: =AL19+AM19 -> 6.58 | AP19: ='16'!G123 -> 230.37 | AQ19: ='16'!G35 -> 0 | AR19: ='16'!G37 -> 0 | AS19: ='16'!G38 -> 0 | AT19: ='16'!G39 -> 0 | AU19: ='16'!G40 -> 0 | AV19: ='16'!G41 -> 0 | AW19: ='16'!G42 -> 0 | AX19: ='16'!G43 -> 2364.6 | AY19: ='16'!G44 -> 0 | AZ19: ='16'!G36 -> 530.88 | BA19: ='16'!G49 -> 2554.388 | BB19: ='16'!G51 -> 1299.8829 | BC19: ='16'!G52 -> 1693.32 | BD19: ='16'!G53 -> 0 | BE19: ='16'!G54 -> 61.29 | BF19: ='16'!G55 -> 0 | BG19: ='16'!G56 -> 5319.14 | BH19: ='16'!G57 -> 0 | BI19: ='16'!G50 -> 1053.72 | BJ19: =SUM(AV19,AW19,BF19,BG19) -> 5319.14 | BK19: ='16'!G84 -> 482 | BL19: =SUM(AQ19,AV19,AW19,AX19,BA19,BF19,BG19,BH19)/I19% -> 53.262553 | BM19: =SUM(AT19,BD19)/I19% -> 0 | BN19: =(AS19+BC19)/I19 -> 0.08809281 | BO19: =K19+O19+R19+V19 -> 222329.98 | BP19: =SUM(AV19,AW19,AX19,BF19,BG19,BH19,BK19) -> 8165.74 | BQ19: =BP19/(AE19*280) -> 1.2151399
A20: 17 | B20: 17 | D20: ='17'!D3 -> 28 | E20: ='17'!D4 -> 0.8 | F20: ='17'!D2 -> 0.5 | G20: ='17'!G8 -> 19940 | H20: ='17'!G8 -> 19940 | I20: ='17'!G7 -> 19868 | J20: 10 | K20: =H20*J20 -> 199400 | L20: =I20/202 -> 98.356436 | M20: ='17'!G15 -> 529.876 | N20: 35 | O20: =M20*N20 -> 18545.66 | P20: ='17'!G20 -> 155 | Q20: 134 | R20: =P20*Q20 -> 20770 | S20: =P20/(F20*202/100) -> 153.46535 | T20: ='17'!G24 -> 0 | U20: 69 | V20: =T20*U20 -> 0 | W20: ='17'!G95 -> 55 | X20: ='17'!G96 -> 24 | Y20: ='17'!G97 -> 26 | Z20: =W20+X20+Y20 -> 105 | AA20: ='17'!G132 -> 0 | AB20: ='17'!G133 -> 0 | AC20: ='17'!G134 -> 0 | AD20: ='17'!G135 -> 24.23 | AE20: =AA20+AB20+AC20+AD20 -> 24.23 | AF20: =AV20+AW20+BF20+BG20 -> 5385.33 | AG20: =AF20/AE20 -> 222.25877 | AH20: ='17'!G136 -> 0 | AI20: ='17'!G137 -> 1.36 | AJ20: ='17'!G138 -> 7.31 | AK20: =AH20+AI20+AJ20 -> 8.67 | AL20: ='17'!G139 -> 5.69 | AM20: ='17'!G140 -> 0 | AO20: =AL20+AM20 -> 5.69 | AP20: ='17'!G123 -> 202.009 | AQ20: ='17'!G35 -> 0 | AR20: ='17'!G37 -> 0 | AS20: ='17'!G38 -> 0 | AT20: ='17'!G39 -> 0 | AU20: ='17'!G40 -> 0 | AV20: ='17'!G41 -> 0 | AW20: ='17'!G42 -> 0 | AX20: ='17'!G43 -> 2391.81 | AY20: ='17'!G44 -> 0 | AZ20: ='17'!G36 -> 580.97 | BA20: ='17'!G49 -> 2613.133 | BB20: ='17'!G51 -> 844.69 | BC20: ='17'!G52 -> 1797.08 | BD20: ='17'!G53 -> 2150.28 | BE20: ='17'!G54 -> 66.8 | BF20: ='17'!G55 -> 0 | BG20: ='17'!G56 -> 5385.33 | BH20: ='17'!G57 -> 0 | BI20: ='17'!G50 -> 1165.73 | BJ20: =SUM(AV20,AW20,BF20,BG20) -> 5385.33 | BK20: ='17'!G84 -> 479 | BL20: =SUM(AQ20,AV20,AW20,AX20,BA20,BF20,BG20,BH20)/I20% -> 52.296522 | BM20: =SUM(AT20,BD20)/I20% -> 10.822831 | BN20: =(AS20+BC20)/I20 -> 0.090450976 | BO20: =K20+O20+R20+V20 -> 238715.66 | BP20: =SUM(AV20,AW20,AX20,BF20,BG20,BH20,BK20) -> 8256.14 | BQ20: =BP20/(AE20*280) -> 1.21693
A21: 18 | B21: 18 | D21: ='18'!D3 -> 29 | E21: ='18'!D4 -> 0.8 | F21: ='18'!D2 -> 0.5 | G21: ='18'!G8 -> 19399 | H21: ='18'!G8 -> 19399 | I21: ='18'!G7 -> 19329 | J21: 10 | K21: =H21*J21 -> 193990 | L21: =I21/202 -> 95.688119 | M21: ='18'!G15 -> 636.77 | N21: 35 | O21: =M21*N21 -> 22286.95 | P21: ='18'!G20 -> 136 | Q21: 134 | R21: =P21*Q21 -> 18224 | S21: =P21/(F21*202/100) -> 134.65347 | T21: ='18'!G24 -> 0 | U21: 69 | V21: =T21*U21 -> 0 | W21: ='18'!G95 -> 58 | X21: ='18'!G96 -> 34 | Y21: ='18'!G97 -> 23 | Z21: =W21+X21+Y21 -> 115 | AA21: ='18'!G132 -> 0 | AB21: ='18'!G133 -> 0 | AC21: ='18'!G134 -> 0 | AD21: ='18'!G135 -> 23.99 | AE21: =AA21+AB21+AC21+AD21 -> 23.99 | AF21: =AV21+AW21+BF21+BG21 -> 5039 | AG21: =AF21/AE21 -> 210.04585 | AH21: ='18'!G136 -> -0.15 | AI21: ='18'!G137 -> 5.96 | AJ21: ='18'!G138 -> 0 | AK21: =AH21+AI21+AJ21 -> 5.81 | AL21: ='18'!G139 -> 5.59 | AM21: ='18'!G140 -> 0 | AO21: =AL21+AM21 -> 5.59 | AP21: ='18'!G123 -> 199.52 | AQ21: ='18'!G35 -> 0 | AR21: ='18'!G37 -> 0 | AS21: ='18'!G38 -> 0 | AT21: ='18'!G39 -> 0 | AU21: ='18'!G40 -> 0 | AV21: ='18'!G41 -> 0 | AW21: ='18'!G42 -> 0 | AX21: ='18'!G43 -> 2444 | AY21: ='18'!G44 -> 0 | AZ21: ='18'!G36 -> 557 | BA21: ='18'!G49 -> 2508.84 | BB21: ='18'!G51 -> 1428.86 | BC21: ='18'!G52 -> 1769.41 | BD21: ='18'!G53 -> 629.72 | BE21: ='18'!G54 -> 38.97 | BF21: ='18'!G55 -> 0 | BG21: ='18'!G56 -> 5039 | BH21: ='18'!G57 -> 0 | BI21: ='18'!G50 -> 952 | BJ21: =SUM(AV21,AW21,BF21,BG21) -> 5039 | BK21: ='18'!G84 -> 484 | BL21: =SUM(AQ21,AV21,AW21,AX21,BA21,BF21,BG21,BH21)/I21% -> 51.693518 | BM21: =SUM(AT21,BD21)/I21% -> 3.2579026 | BN21: =(AS21+BC21)/I21 -> 0.091541725 | BO21: =K21+O21+R21+V21 -> 234500.95 | BP21: =SUM(AV21,AW21,AX21,BF21,BG21,BH21,BK21) -> 7967 | BQ21: =BP21/(AE21*280) -> 1.1860597
A22: 19 | B22: 19 | D22: ='19'!D3 -> 30 | E22: ='19'!D4 -> 0.8 | F22: ='19'!D2 -> 0.5 | G22: ='19'!G8 -> 19562 | H22: ='19'!G8 -> 19562 | I22: ='19'!G7 -> 19338 | J22: 10 | K22: =H22*J22 -> 195620 | L22: =I22/202 -> 95.732673 | M22: ='19'!G15 -> 563.12 | N22: 35 | O22: =M22*N22 -> 19709.2 | P22: ='19'!G20 -> 137 | Q22: 134 | R22: =P22*Q22 -> 18358 | S22: =P22/(F22*202/100) -> 135.64356 | T22: ='19'!G24 -> 0 | U22: 69 | V22: =T22*U22 -> 0 | W22: ='19'!G95 -> 46 | X22: ='19'!G96 -> 25 | Y22: ='19'!G97 -> 24 | Z22: =W22+X22+Y22 -> 95 | AA22: ='19'!G132 -> 0 | AB22: ='19'!G133 -> 0 | AC22: ='19'!G134 -> 0 | AD22: ='19'!G135 -> 24.2 | AE22: =AA22+AB22+AC22+AD22 -> 24.2 | AF22: =AV22+AW22+BF22+BG22 -> 4875.48 | AG22: =AF22/AE22 -> 201.46612 | AH22: ='19'!G136 -> 1.78 | AI22: ='19'!G137 -> 0 | AJ22: ='19'!G138 -> 6.14 | AK22: =AH22+AI22+AJ22 -> 7.92 | AL22: ='19'!G139 -> 5.96 | AM22: ='19'!G140 -> -0.08 | AO22: =AL22+AM22 -> 5.88 | AP22: ='19'!G123 -> 213.12 | AQ22: ='19'!G35 -> 0 | AR22: ='19'!G37 -> 0 | AS22: ='19'!G38 -> 0 | AT22: ='19'!G39 -> 0 | AU22: ='19'!G40 -> 0 | AV22: ='19'!G41 -> 0 | AW22: ='19'!G42 -> 0.48 | AX22: ='19'!G43 -> 2542.95 | AY22: ='19'!G44 -> 0 | AZ22: ='19'!G36 -> 579 | BA22: ='19'!G49 -> 2495.16 | BB22: ='19'!G51 -> 1411.45 | BC22: ='19'!G52 -> 1740 | BD22: ='19'!G53 -> 174.94 | BE22: ='19'!G54 -> 8.39 | BF22: ='19'!G55 -> 0 | BG22: ='19'!G56 -> 4875 | BH22: ='19'!G57 -> 0 | BI22: ='19'!G50 -> 1094 | BJ22: =SUM(AV22,AW22,BF22,BG22) -> 4875.48 | BK22: ='19'!G84 -> 490 | BL22: =SUM(AQ22,AV22,AW22,AX22,BA22,BF22,BG22,BH22)/I22% -> 51.264815 | BM22: =SUM(AT22,BD22)/I22% -> 0.90464371 | BN22: =(AS22+BC22)/I22 -> 0.089978281 | BO22: =K22+O22+R22+V22 -> 233687.2 | BP22: =SUM(AV22,AW22,AX22,BF22,BG22,BH22,BK22) -> 7908.43 | BQ22: =BP22/(AE22*280) -> 1.1671237
A23: 20 | B23: 20 | D23: ='20'!D3 -> 30 | E23: ='20'!D4 -> 0.81 | F23: ='20'!D2 -> 0.5 | G23: ='20'!G8 -> 19097 | H23: ='20'!G8 -> 19097 | I23: ='20'!G7 -> 18874 | J23: 10 | K23: =H23*J23 -> 190970 | L23: =I23/202 -> 93.435644 | M23: ='20'!G15 -> 640 | N23: 35 | O23: =M23*N23 -> 22400 | P23: ='20'!G20 -> 138 | Q23: 134 | R23: =P23*Q23 -> 18492 | S23: =P23/(F23*202/100) -> 136.63366 | T23: ='20'!G24 -> 0 | U23: 69 | V23: =T23*U23 -> 0 | W23: ='20'!G95 -> 65 | X23: ='20'!G96 -> 24 | Y23: ='20'!G97 -> 20 | Z23: =W23+X23+Y23 -> 109 | AA23: ='20'!G132 -> 0 | AB23: ='20'!G133 -> 0 | AC23: ='20'!G134 -> 0 | AD23: ='20'!G135 -> 24.06 | AE23: =AA23+AB23+AC23+AD23 -> 24.06 | AF23: =AV23+AW23+BF23+BG23 -> 4321.55 | AG23: =AF23/AE23 -> 179.61554 | AH23: ='20'!G136 -> 0 | AI23: ='20'!G137 -> 6.02 | AJ23: ='20'!G138 -> 0 | AK23: =AH23+AI23+AJ23 -> 6.02 | AL23: ='20'!G139 -> 5.99 | AM23: ='20'!G140 -> 0 | AO23: =AL23+AM23 -> 5.99 | AP23: ='20'!G123 -> 212.33 | AQ23: ='20'!G35 -> 0 | AR23: ='20'!G37 -> 0 | AS23: ='20'!G38 -> 0 | AT23: ='20'!G39 -> 0 | AU23: ='20'!G40 -> 0 | AV23: ='20'!G41 -> 0 | AW23: ='20'!G42 -> 0 | AX23: ='20'!G43 -> 2540.08 | AY23: ='20'!G44 -> 0 | AZ23: ='20'!G36 -> 584 | BA23: ='20'!G49 -> 2526.3 | BB23: ='20'!G51 -> 1387.74 | BC23: ='20'!G52 -> 1763.47 | BD23: ='20'!G576 -> 0 | BE23: ='20'!G54 -> 15.98 | BF23: ='20'!G55 -> 0 | BG23: ='20'!G56 -> 4321.55 | BH23: ='20'!G57 -> 0 | BI23: ='20'!G50 -> 1090.01 | BJ23: =SUM(AV23,AW23,BF23,BG23) -> 4321.55 | BK23: ='20'!G84 -> 489 | BL23: =SUM(AQ23,AV23,AW23,AX23,BA23,BF23,BG23,BH23)/I23% -> 49.740013 | BM23: =SUM(AT23,BD23)/I23% -> 0 | BN23: =(AS23+BC23)/I23 -> 0.093433824 | BO23: =K23+O23+R23+V23 -> 231862 | BP23: =SUM(AV23,AW23,AX23,BF23,BG23,BH23,BK23) -> 7350.63 | BQ23: =BP23/(AE23*280) -> 1.091116
A24: 21 | B24: 21 | D24: 21 | E24: ='21'!D4 -> 0.81 | F24: ='21'!D2 -> 0.5 | G24: ='21'!G8 -> 19510 | H24: ='21'!G8 -> 19510 | I24: ='21'!G7 -> 19287 | J24: 10 | K24: =H24*J24 -> 195100 | L24: =I24/202 -> 95.480198 | M24: ='21'!G15 -> 733 | N24: 35 | O24: =M24*N24 -> 25655 | P24: ='21'!G20 -> 158 | Q24: 134 | R24: =P24*Q24 -> 21172 | S24: =P24/(F24*202/100) -> 156.43564 | T24: ='21'!G24 -> 0 | U24: 69 | V24: =T24*U24 -> 0 | W24: ='21'!G95 -> 67 | X24: ='21'!G96 -> 28 | Y24: ='21'!G97 -> 30 | Z24: =W24+X24+Y24 -> 125 | AA24: ='21'!G132 -> 0 | AB24: ='21'!G133 -> 0 | AC24: ='21'!G134 -> 0 | AD24: ='21'!G135 -> 24.08 | AE24: =AA24+AB24+AC24+AD24 -> 24.08 | AF24: =AV24+AW24+BF24+BG24 -> 4688.72 | AG24: =AF24/AE24 -> 194.71429 | AH24: ='21'!G136 -> 7.59 | AI24: ='21'!G137 -> 0 | AJ24: ='21'!G138 -> 0.54 | AK24: =AH24+AI24+AJ24 -> 8.13 | AL24: ='21'!G139 -> 5.85 | AM24: ='21'!G140 -> 0 | AO24: =AL24+AM24 -> 5.85 | AP24: ='21'!G123 -> 209.08 | AQ24: ='21'!G35 -> 0 | AR24: ='21'!G37 -> 0 | AS24: ='21'!G38 -> 0.38 | AT24: ='21'!G39 -> 0 | AU24: ='21'!G40 -> 0 | AV24: ='21'!G41 -> 0 | AW24: ='21'!G42 -> 0 | AX24: ='21'!G43 -> 2540.92 | AY24: ='21'!G44 -> 0 | AZ24: ='21'!G36 -> 593.65 | BA24: ='21'!G49 -> 2502.92 | BB24: ='21'!G51 -> 1460.87 | BC24: ='21'!G52 -> 1776.88 | BD24: ='21'!G53 -> 3992.05 | BE24: ='21'!G54 -> 12.47 | BF24: ='21'!G55 -> 0 | BG24: ='21'!G56 -> 4688.72 | BH24: ='21'!G57 -> 0 | BI24: ='21'!G50 -> 1044.2 | BJ24: =SUM(AV24,AW24,BF24,BG24) -> 4688.72 | BK24: ='21'!G84 -> 485 | BL24: =SUM(AQ24,AV24,AW24,AX24,BA24,BF24,BG24,BH24)/I24% -> 50.461762 | BM24: =SUM(AT24,BD24)/I24% -> 20.698139 | BN24: =(AS24+BC24)/I24 -> 0.092148079 | BO24: =K24+O24+R24+V24 -> 241927 | BP24: =SUM(AV24,AW24,AX24,BF24,BG24,BH24,BK24) -> 7714.64 | BQ24: =BP24/(AE24*280) -> 1.1441979
A25: 22 | B25: 22 | D25: ='22'!D3 -> 30 | E25: ='22'!D4 -> 0.78 | F25: ='22'!D2 -> 0.5 | G25: ='22'!G8 -> 19518 | H25: ='22'!G8 -> 19518 | I25: ='22'!G7 -> 19321 | J25: 10 | K25: =H25*J25 -> 195180 | L25: =I25/202 -> 95.648515 | M25: ='22'!G15 -> 386 | N25: 35 | O25: =M25*N25 -> 13510 | P25: ='22'!G20 -> 171 | Q25: 134 | R25: =P25*Q25 -> 22914 | S25: =P25/(F25*202/100) -> 169.30693 | T25: ='22'!G24 -> 0 | U25: 69 | V25: =T25*U25 -> 0 | W25: ='22'!G95 -> 33 | X25: ='22'!G96 -> 36 | Y25: ='22'!G97 -> 33 | Z25: =W25+X25+Y25 -> 102 | AA25: ='22'!G132 -> 0 | AB25: ='22'!G133 -> 0 | AC25: ='22'!G134 -> 0 | AD25: ='22'!G135 -> 24.04 | AE25: =AA25+AB25+AC25+AD25 -> 24.04 | AF25: =AV25+AW25+BF25+BG25 -> 4842.76 | AG25: =AF25/AE25 -> 201.44592 | AH25: ='22'!G136 -> 0 | AI25: ='22'!G137 -> 0 | AJ25: ='22'!G138 -> 0 | AK25: =AH25+AI25+AJ25 -> 0 | AL25: ='22'!G139 -> 6.06 | AM25: ='22'!G140 -> 0 | AO25: =AL25+AM25 -> 6.06 | AP25: ='22'!G123 -> 214.13 | AQ25: ='22'!G35 -> 0 | AR25: ='22'!G37 -> 0 | AS25: ='22'!G38 -> 0 | AT25: ='22'!G39 -> 0 | AU25: ='22'!G40 -> 0 | AV25: ='22'!G41 -> 0 | AW25: ='22'!G42 -> 0 | AX25: ='22'!G43 -> 2571.72 | AY25: ='22'!G44 -> 0 | AZ25: ='22'!G36 -> 526.42 | BA25: ='22'!G49 -> 2714.1 | BB25: ='22'!G51 -> 1433.89 | BC25: ='22'!G52 -> 1660.72 | BD25: ='22'!G53 -> 3993.62 | BE25: ='22'!G54 -> 4.65 | BF25: ='22'!G55 -> 0 | BG25: ='22'!G56 -> 4842.76 | BH25: ='22'!G57 -> 0 | BI25: ='22'!G50 -> 1018.2 | BJ25: =SUM(AV25,AW25,BF25,BG25) -> 4842.76 | BK25: ='22'!G84 -> 480 | BL25: =SUM(AQ25,AV25,AW25,AX25,BA25,BF25,BG25,BH25)/I25% -> 52.422649 | BM25: =SUM(AT25,BD25)/I25% -> 20.669841 | BN25: =(AS25+BC25)/I25 -> 0.085954143 | BO25: =K25+O25+R25+V25 -> 231604 | BP25: =SUM(AV25,AW25,AX25,BF25,BG25,BH25,BK25) -> 7894.48 | BQ25: =BP25/(AE25*280) -> 1.1728191
A26: 23 | B26: 23 | D26: ='23'!D3 -> 30 | E26: ='23'!D4 -> 0.76 | F26: ='23'!D2 -> 0.5 | G26: ='23'!G8 -> 18175 | H26: ='23'!G8 -> 18175 | I26: ='23'!G7 -> 17852 | J26: 10 | K26: =H26*J26 -> 181750 | L26: =I26/202 -> 88.376238 | M26: ='23'!G15 -> 695.03 | N26: 35 | O26: =M26*N26 -> 24326.05 | P26: ='23'!G20 -> 155 | Q26: 134 | R26: =P26*Q26 -> 20770 | S26: =P26/(F26*202/100) -> 153.46535 | T26: ='23'!G24 -> 0 | U26: 69 | V26: =T26*U26 -> 0 | W26: ='23'!G95 -> 62 | X26: ='23'!G96 -> 27 | Y26: ='23'!G97 -> 27 | Z26: =W26+X26+Y26 -> 116 | AA26: ='23'!G132 -> 0 | AB26: ='23'!G133 -> 0 | AC26: ='23'!G134 -> 0 | AD26: ='23'!G135 -> 24.43 | AE26: =AA26+AB26+AC26+AD26 -> 24.43 | AF26: =AV26+AW26+BF26+BG26 -> 3616.32 | AG26: =AF26/AE26 -> 148.02783 | AH26: ='23'!G136 -> 7.47 | AI26: ='23'!G137 -> 0 | AJ26: ='23'!G138 -> 0.52 | AK26: =AH26+AI26+AJ26 -> 7.99 | AL26: ='23'!G139 -> 5.22 | AM26: ='23'!G140 -> 0 | AO26: =AL26+AM26 -> 5.22 | AP26: ='23'!G123 -> 186.22 | AQ26: ='23'!G35 -> 0 | AR26: ='23'!G37 -> 0 | AS26: ='23'!G38 -> 0 | AT26: ='23'!G39 -> 0 | AU26: ='23'!G40 -> 0 | AV26: ='23'!G41 -> 0 | AW26: ='23'!G42 -> 0 | AX26: ='23'!G43 -> 2376.6 | AY26: ='23'!G44 -> 0 | AZ26: ='23'!G36 -> 566.22 | BA26: ='23'!G49 -> 2466.98 | BB26: ='23'!G51 -> 1360.33 | BC26: ='23'!G52 -> 1770.84 | BD26: ='23'!G53 -> 4059.21 | BE26: ='23'!G54 -> 20.89 | BF26: ='23'!G55 -> 0 | BG26: ='23'!G56 -> 3616.32 | BH26: ='23'!G57 -> 0 | BI26: ='23'!G50 -> 981.7 | BJ26: =SUM(AV26,AW26,BF26,BG26) -> 3616.32 | BK26: ='23'!G84 -> 476 | BL26: =SUM(AQ26,AV26,AW26,AX26,BA26,BF26,BG26,BH26)/I26% -> 47.389088 | BM26: =SUM(AT26,BD26)/I26% -> 22.738125 | BN26: =(AS26+BC26)/I26 -> 0.099195608 | BO26: =K26+O26+R26+V26 -> 226846.05 | BP26: =SUM(AV26,AW26,AX26,BF26,BG26,BH26,BK26) -> 6468.92 | BQ26: =BP26/(AE26*280) -> 0.94569323
A27: 24 | B27: 24 | D27: ='24'!D3 -> 30 | E27: ='24'!D4 -> 0.82 | F27: ='24'!D2 -> 0.5 | G27: ='24'!G8 -> 17967 | H27: ='24'!G8 -> 17967 | I27: ='24'!G7 -> 17644 | J27: 10 | K27: =H27*J27 -> 179670 | L27: =I27/202 -> 87.346535 | M27: ='24'!G15 -> 613.17 | N27: 35 | O27: =M27*N27 -> 21460.95 | P27: ='24'!G20 -> 174 | Q27: 134 | R27: =P27*Q27 -> 23316 | S27: =P27/(F27*202/100) -> 172.27723 | T27: ='24'!G24 -> 0 | U27: 69 | V27: =T27*U27 -> 0 | W27: ='24'!G95 -> 73 | X27: ='24'!G96 -> 21 | Y27: ='24'!G97 -> 19 | Z27: =W27+X27+Y27 -> 113 | AA27: ='24'!G132 -> 0 | AB27: ='24'!G133 -> 0 | AC27: ='24'!G134 -> 0 | AD27: ='24'!G135 -> 24.2 | AE27: =AA27+AB27+AC27+AD27 -> 24.2 | AF27: =AV27+AW27+BF27+BG27 -> 3514.72 | AG27: =AF27/AE27 -> 145.23636 | AH27: ='24'!G136 -> 3.36 | AI27: ='24'!G137 -> 2.65 | AJ27: ='24'!G138 -> 0 | AK27: =AH27+AI27+AJ27 -> 6.01 | AL27: ='24'!G139 -> 5.43 | AM27: ='24'!G140 -> 0 | AO27: =AL27+AM27 -> 5.43 | AP27: ='24'!G123 -> 194.24 | AQ27: ='24'!G35 -> 0 | AR27: ='24'!G37 -> 0 | AS27: ='24'!G38 -> 0 | AT27: ='24'!G39 -> 0 | AU27: ='24'!G40 -> 0 | AV27: ='24'!G41 -> 0 | AW27: ='24'!G42 -> 0 | AX27: ='24'!G43 -> 2354.72 | AY27: ='24'!G44 -> 0 | AZ27: ='24'!G36 -> 543.64 | BA27: ='24'!G49 -> 2368.87 | BB27: ='24'!G51 -> 1360.59 | BC27: ='24'!G52 -> 1780.56 | BD27: ='24'!G53 -> 4093.36 | BE27: ='24'!G54 -> 18.86 | BF27: ='24'!G55 -> 0 | BG27: ='24'!G56 -> 3514.72 | BH27: ='24'!G57 -> 0 | BI27: ='24'!G50 -> 980.04 | BJ27: =SUM(AV27,AW27,BF27,BG27) -> 3514.72 | BK27: ='24'!G84 -> 503 | BL27: =SUM(AQ27,AV27,AW27,AX27,BA27,BF27,BG27,BH27)/I27% -> 46.69185 | BM27: =SUM(AT27,BD27)/I27% -> 23.199728 | BN27: =(AS27+BC27)/I27 -> 0.10091589 | BO27: =K27+O27+R27+V27 -> 224446.95 | BP27: =SUM(AV27,AW27,AX27,BF27,BG27,BH27,BK27) -> 6372.44 | BQ27: =BP27/(AE27*280) -> 0.94044274
A28: 25 | B28: 25 | D28: ='25'!D3 -> 31 | E28: ='25'!D4 -> 0.8 | F28: ='25'!D2 -> 0.5 | G28: ='25'!G8 -> 18627 | H28: ='25'!G8 -> 18627 | I28: ='25'!G7 -> 18314 | J28: 10 | K28: =H28*J28 -> 186270 | L28: =I28/202 -> 90.663366 | M28: ='25'!G15 -> 516.88 | N28: 35 | O28: =M28*N28 -> 18090.8 | P28: ='25'!G20 -> 155 | Q28: 134 | R28: =P28*Q28 -> 20770 | S28: =P28/(F28*202/100) -> 153.46535 | T28: ='25'!G24 -> 0 | U28: 69 | V28: =T28*U28 -> 0 | W28: ='25'!G95 -> 39 | X28: ='25'!G96 -> 24 | Y28: ='25'!G97 -> 18 | Z28: =W28+X28+Y28 -> 81 | AA28: ='25'!G132 -> 0 | AB28: ='25'!G133 -> 0 | AC28: ='25'!G134 -> 0 | AD28: ='25'!G135 -> 24.06 | AE28: =AA28+AB28+AC28+AD28 -> 24.06 | AF28: =AV28+AW28+BF28+BG28 -> 4159.56 | AG28: =AF28/AE28 -> 172.88279 | AH28: ='24'!G136 -> 3.36 | AI28: ='24'!G137 -> 2.65 | AJ28: ='24'!G138 -> 0 | AK28: =AH28+AI28+AJ28 -> 6.01 | AL28: ='23'!G139 -> 5.22 | AM28: ='24'!G140 -> 0 | AO28: =AL28+AM28 -> 5.22 | AP28: ='25'!G123 -> 196.63 | AQ28: ='25'!G35 -> 0 | AR28: ='25'!G37 -> 0 | AS28: ='25'!G38 -> 0 | AT28: ='25'!G39 -> 0 | AU28: ='25'!G40 -> 0 | AV28: ='25'!G41 -> 0 | AX28: ='25'!G43 -> 2413.52 | AY28: ='25'!G44 -> 0 | AZ28: ='25'!G36 -> 552.38 | BA28: ='25'!G49 -> 2412.11 | BB28: ='25'!G51 -> 1356.25 | BC28: ='25'!G52 -> 1692.4 | BD28: ='25'!G53 -> 4174.33 | BE28: ='24'!G54 -> 18.86 | BF28: ='25'!G55 -> 0 | BG28: ='25'!G56 -> 4159.56 | BH28: ='25'!G57 -> 0 | BI28: ='25'!G50 -> 958.86 | BJ28: =SUM(AV28,AW28,BF28,BG28) -> 4159.56 | BK28: ='25'!G84 -> 486 | BL28: =SUM(AQ28,AV28,AW28,AX28,BA28,BF28,BG28,BH28)/I28% -> 49.061865 | BM28: =SUM(AT28,BD28)/I28% -> 22.793109 | BN28: =(AS28+BC28)/I28 -> 0.092410178 | BO28: =K28+O28+R28+V28 -> 225130.8 | BP28: =SUM(AV28,AW28,AX28,BF28,BG28,BH28,BK28) -> 7059.08 | BQ28: =BP28/(AE28*280) -> 1.0478387
A29: 26 | B29: 26 | D29: ='26'!D3 -> 28 | E29: ='26'!D4 -> 0.85 | F29: ='26'!D2 -> 0.5 | G29: ='26'!G8 -> 18593 | H29: ='26'!G8 -> 18593 | I29: ='26'!G7 -> 18294 | J29: 10 | K29: =H29*J29 -> 185930 | L29: =I29/202 -> 90.564356 | M29: ='26'!G15 -> 411.925 | N29: 35 | O29: =M29*N29 -> 14417.375 | P29: ='26'!G20 -> 125 | Q29: 134 | R29: =P29*Q29 -> 16750 | S29: =P29/(F29*202/100) -> 123.76238 | T29: ='26'!G24 -> 0 | U29: 69 | V29: =T29*U29 -> 0 | W29: ='26'!G95 -> 41 | X29: ='26'!G96 -> 28 | Y29: ='26'!G97 -> 23 | Z29: =W29+X29+Y29 -> 92 | AA29: ='26'!G132 -> 0 | AB29: ='26'!G133 -> 0 | AC29: ='26'!G134 -> 0 | AD29: ='26'!G135 -> 23.81 | AE29: =AA29+AB29+AC29+AD29 -> 23.81 | AF29: =AV29+AW29+BF29+BG29 -> 4160.88 | AG29: =AF29/AE29 -> 174.75346 | AH29: ='26'!G136 -> -0.2 | AI29: ='26'!G137 -> 0 | AJ29: ='26'!G138 -> 0 | AK29: =AH29+AI29+AJ29 -> -0.2 | AL29: ='26'!G139 -> 5.82 | AM29: ='26'!G140 -> 0 | AO29: =AL29+AM29 -> 5.82 | AP29: ='26'!G123 -> 204.281 | AQ29: ='26'!G35 -> 0 | AR29: ='26'!G37 -> 0 | AS29: ='26'!G38 -> -0.38 | AT29: ='26'!G39 -> 0 | AU29: ='26'!G40 -> 0 | AV29: ='26'!G41 -> 0 | AW29: ='26'!G42 -> 0 | AX29: ='26'!G43 -> 2523.6 | AY29: ='26'!G44 -> 0 | AZ29: ='26'!G36 -> 634.24 | BA29: ='26'!G49 -> 2414.707 | BB29: ='26'!G51 -> 1416.394 | BC29: ='26'!G52 -> 1638.68 | BD29: ='26'!G53 -> 3992.471 | BE29: ='26'!G54 -> 23.3293 | BF29: ='26'!G55 -> 0 | BG29: ='26'!G56 -> 4160.88 | BH29: ='26'!G57 -> 0 | BI29: ='26'!G50 -> 1007.44 | BJ29: =SUM(AV29,AW29,BF29,BG29) -> 4160.88 | BK29: ='26'!G84 -> 491 | BL29: =SUM(AQ29,AV29,AW29,AX29,BA29,BF29,BG29,BH29)/I29% -> 49.738641 | BM29: =SUM(AT29,BD29)/I29% -> 21.823937 | BN29: =(AS29+BC29)/I29 -> 0.089553952 | BO29: =K29+O29+R29+V29 -> 217097.37 | BP29: =SUM(AV29,AW29,AX29,BF29,BG29,BH29,BK29) -> 7175.48 | BQ29: =BP29/(AE29*280) -> 1.0763005
A30: 27 | B30: 27 | D30: ='27'!D3 -> 28 | E30: ='27'!D4 -> 0.82 | F30: ='27'!D2 -> 0.3 | G30: ='27'!G8 -> 19471 | H30: ='27'!G8 -> 19471 | I30: ='27'!G7 -> 19216 | J30: 10 | K30: =H30*J30 -> 194710 | L30: =I30/202 -> 95.128713 | M30: ='27'!G15 -> 532.684 | N30: 35 | O30: =M30*N30 -> 18643.94 | P30: ='27'!G20 -> 137 | Q30: 134 | R30: =P30*Q30 -> 18358 | S30: =P30/(F30*202/100) -> 226.07261 | T30: ='27'!G24 -> 0 | U30: 69 | V30: =T30*U30 -> 0 | W30: ='27'!G95 -> 66 | X30: ='27'!G96 -> 21 | Y30: ='27'!G97 -> 23 | Z30: =W30+X30+Y30 -> 110 | AA30: ='27'!G132 -> 0 | AB30: ='27'!G133 -> 0 | AC30: ='27'!G134 -> 0 | AD30: ='27'!G135 -> 24.01 | AE30: =AA30+AB30+AC30+AD30 -> 24.01 | AF30: =AV30+AW30+BF30+BG30 -> 3939.12 | AG30: =AF30/AE30 -> 164.06164 | AH30: ='27'!G136 -> 4.31 | AI30: ='27'!G137 -> 0.86 | AJ30: ='27'!G138 -> 1.83 | AK30: =AH30+AI30+AJ30 -> 7 | AL30: ='27'!G139 -> 5.55 | AM30: ='27'!G140 -> 0 | AO30: =AL30+AM30 -> 5.55 | AP30: ='27'!G123 -> 197.399 | AQ30: ='27'!G35 -> 0.67 | AR30: ='27'!G37 -> 0 | AS30: ='27'!G38 -> 0 | AT30: ='27'!G39 -> 0 | AU30: ='27'!G40 -> 0 | AV30: ='27'!G41 -> 0 | AW30: ='27'!G42 -> 0 | AX30: ='27'!G43 -> 2518.76 | AY30: ='27'!G44 -> 0 | AZ30: ='27'!G36 -> 950.52 | BA30: ='27'!G49 -> 1485.884 | BB30: ='27'!G51 -> 1417.64 | BC30: ='27'!G52 -> 1687.6 | BD30: ='27'!G53 -> 4133.768 | BE30: ='27'!G54 -> 25.3077 | BF30: ='27'!G55 -> 0 | BG30: ='27'!G56 -> 3939.12 | BH30: ='27'!G57 -> 0 | BI30: ='27'!G50 -> 1426.96 | BJ30: =SUM(AV30,AW30,BF30,BG30) -> 3939.12 | BK30: ='27'!G84 -> 490 | BL30: =SUM(AQ30,AV30,AW30,AX30,BA30,BF30,BG30,BH30)/I30% -> 41.342808 | BM30: =SUM(AT30,BD30)/I30% -> 21.512115 | BN30: =(AS30+BC30)/I30 -> 0.087822648 | BO30: =K30+O30+R30+V30 -> 231711.94 | BP30: =SUM(AV30,AW30,AX30,BF30,BG30,BH30,BK30) -> 6947.88 | BQ30: =BP30/(AE30*280) -> 1.0334801
A31: 28 | B31: 28 | D31: ='28'!D3 -> 28 | E31: ='28'!D4 -> 0.82 | F31: ='28'!D2 -> 0.3 | G31: ='28'!G8 -> 19772 | H31: ='28'!G8 -> 19772 | I31: ='28'!G7 -> 19557 | J31: 10 | K31: =H31*J31 -> 197720 | L31: =I31/202 -> 96.816832 | M31: ='28'!G15 -> 805.717 | N31: 35 | O31: =M31*N31 -> 28200.095 | P31: ='28'!G20 -> 195 | Q31: 134 | R31: =P31*Q31 -> 26130 | S31: =P31/(F31*202/100) -> 321.78218 | T31: ='28'!G24 -> 0 | U31: 69 | V31: =T31*U31 -> 0 | W31: ='28'!G95 -> 86 | X31: ='28'!G96 -> 30 | Y31: ='28'!G97 -> 31 | Z31: =W31+X31+Y31 -> 147 | AA31: ='28'!G132 -> 0 | AB31: ='28'!G133 -> 0 | AC31: ='28'!G134 -> 0 | AD31: ='28'!G135 -> 24.11 | AE31: =AA31+AB31+AC31+AD31 -> 24.11 | AF31: =AV31+AW31+BF31+BG31 -> 4080.96 | AG31: =AF31/AE31 -> 169.26421 | AH31: ='28'!G136 -> 9.01 | AI31: ='28'!G137 -> 0 | AJ31: ='28'!G138 -> 0 | AK31: =AH31+AI31+AJ31 -> 9.01 | AL31: ='28'!G139 -> 5.67 | AM31: ='28'!G140 -> 0 | AO31: =AL31+AM31 -> 5.67 | AP31: ='28'!G123 -> 202.761 | AQ31: ='28'!G35 -> 0 | AR31: ='28'!G37 -> 0 | AS31: ='28'!G38 -> 0 | AT31: ='28'!G39 -> 0 | AU31: ='28'!G40 -> 0 | AV31: ='28'!G41 -> 0 | AW31: ='28'!G42 -> 0.05 | AX31: ='28'!G43 -> 2542.28 | AY31: ='28'!G44 -> 0 | AZ31: ='28'!G36 -> 903.56 | BA31: ='28'!G49 -> 3666.296 | BB31: ='28'!G51 -> 1446.515 | BC31: ='28'!G52 -> 1864.36 | BD31: ='28'!G53 -> 4127.494 | BE31: ='28'!G54 -> 4.5865 | BF31: ='28'!G55 -> 0.27 | BG31: ='28'!G56 -> 4080.64 | BH31: ='28'!G57 -> 0 | BI31: ='28'!G50 -> 1171.68 | BJ31: =SUM(AV31,AW31,BF31,BG31) -> 4080.96 | BK31: ='28'!G84 -> 443 | BL31: =SUM(AQ31,AV31,AW31,AX31,BA31,BF31,BG31,BH31)/I31% -> 52.613059 | BM31: =SUM(AT31,BD31)/I31% -> 21.104945 | BN31: =(AS31+BC31)/I31 -> 0.09532955 | BO31: =K31+O31+R31+V31 -> 252050.09 | BP31: =SUM(AV31,AW31,AX31,BF31,BG31,BH31,BK31) -> 7066.24 | BQ31: =BP31/(AE31*280) -> 1.0467263
A32: 29 | B32: 29 | D32: ='29'!D3 -> 30 | E32: ='29'!D4 -> 0.8 | F32: ='29'!D2 -> 0.3 | G32: ='29'!G8 -> 21286 | H32: ='29'!G8 -> 21286 | I32: ='29'!G7 -> 21144 | J32: 10 | K32: =H32*J32 -> 212860 | L32: =I32/202 -> 104.67327 | M32: ='29'!G15 -> 795.008 | N32: 35 | O32: =M32*N32 -> 27825.28 | P32: ='29'!G20 -> 201 | Q32: 134 | R32: =P32*Q32 -> 26934 | S32: =P32/(F32*202/100) -> 331.68317 | T32: ='29'!G24 -> 0 | U32: 69 | V32: =T32*U32 -> 0 | W32: ='29'!G95 -> 72 | X32: ='29'!G96 -> 32 | Y32: ='29'!G97 -> 35 | Z32: =W32+X32+Y32 -> 139 | AA32: ='29'!G132 -> 0 | AB32: ='29'!G133 -> 0 | AC32: ='29'!G134 -> 0 | AD32: ='29'!G135 -> 24.03 | AE32: =AA32+AB32+AC32+AD32 -> 24.03 | AF32: =AV32+AW32+BF32+BG32 -> 5257.93 | AG32: =AF32/AE32 -> 218.80691 | AH32: ='29'!G136 -> 7.71 | AI32: ='29'!G137 -> 0 | AJ32: ='29'!G138 -> 0 | AK32: =AH32+AI32+AJ32 -> 7.71 | AL32: ='29'!G139 -> 5.86 | AM32: ='29'!G140 -> 0 | AO32: =AL32+AM32 -> 5.86 | AP32: ='29'!G123 -> 210.212 | AQ32: ='29'!G35 -> 0 | AR32: ='29'!G37 -> 0 | AS32: ='29'!G38 -> 0 | AT32: ='29'!G39 -> 0 | AU32: ='29'!G40 -> 0 | AV32: ='29'!G41 -> 0 | AW32: ='29'!G42 -> 0 | AX32: ='29'!G43 -> 2512 | AY32: ='29'!G44 -> 0 | AZ32: ='29'!G36 -> 933.1 | BA32: ='29'!G49 -> 2733.496 | BB32: ='29'!G51 -> 1482.292 | BC32: ='29'!G52 -> 1856.56 | BD32: ='29'!G53 -> 4153.976 | BE32: ='29'!G54 -> 2.9172 | BF32: ='29'!G55 -> -0.27 | BG32: ='29'!G56 -> 5258.2 | BH32: ='29'!G57 -> 0 | BI32: ='29'!G50 -> 1489.12 | BJ32: =SUM(AV32,AW32,BF32,BG32) -> 5257.93 | BK32: ='29'!G84 -> 498 | BL32: =SUM(AQ32,AV32,AW32,AX32,BA32,BF32,BG32,BH32)/I32% -> 49.675681 | BM32: =SUM(AT32,BD32)/I32% -> 19.646122 | BN32: =(AS32+BC32)/I32 -> 0.087805524 | BO32: =K32+O32+R32+V32 -> 267619.28 | BP32: =SUM(AV32,AW32,AX32,BF32,BG32,BH32,BK32) -> 8267.93 | BQ32: =BP32/(AE32*280) -> 1.2288107
A33: 30 | B33: 30 | D33: ='30'!D33 -> 0 | E33: ='30'!D4 -> 0.8 | F33: ='30'!D2 -> 0.3 | G33: ='30'!G8 -> 21390 | H33: ='30'!G8 -> 21390 | I33: ='30'!G7 -> 21224 | J33: 10 | K33: =H33*J33 -> 213900 | L33: =I33/202 -> 105.06931 | M33: ='30'!G15 -> 675.187 | N33: 35 | O33: =M33*N33 -> 23631.545 | P33: ='30'!G20 -> 197 | Q33: 134 | R33: =P33*Q33 -> 26398 | S33: =P33/(F33*202/100) -> 325.08251 | T33: ='30'!G24 -> 0 | U33: 69 | V33: =T33*U33 -> 0 | W33: ='30'!G95 -> 74 | X33: ='30'!G96 -> 32 | Y33: ='30'!G97 -> 50 | Z33: =W33+X33+Y33 -> 156 | AA33: ='30'!G132 -> 0 | AB33: ='30'!G133 -> 0 | AC33: ='30'!G134 -> 0 | AD33: ='30'!G135 -> 24.18 | AE33: =AA33+AB33+AC33+AD33 -> 24.18 | AF33: =AV33+AW33+BF33+BG33 -> 0 | AG33: =AF33/AE33 -> 0 | AH33: ='30'!G136 -> 6.27 | AI33: ='30'!G137 -> 0 | AJ33: ='30'!G138 -> 0 | AK33: =AH33+AI33+AJ33 -> 6.27 | AL33: ='30'!G139 -> 5.55 | AM33: ='30'!G140 -> 0 | AO33: =AL33+AM33 -> 5.55 | AP33: ='30'!G123 -> 194.787 | AQ33: ='30'!G35 -> 0 | AR33: ='30'!G37 -> 0 | AS33: ='30'!G38 -> 0 | AT33: ='30'!G39 -> 0 | AU33: ='30'!G40 -> 0 | AV33: ='30'!G41 -> 0 | AW33: ='30'!G42 -> 0 | AX33: ='30'!G43 -> 2319.16 | AY33: ='30'!G44 -> 0 | AZ33: ='30'!G36 -> 0 | BA33: ='30'!BA33 -> 0 | BB33: ='30'!BA4 -> 0 | BC33: ='30'!BA2 -> 0 | BD33: ='30'!BD8 -> 0 | BE33: ='30'!BC7 -> 0 | BF33: ='30'!BD7 -> 0 | BG33: ='30'!G57 -> 0 | BH33: ='30'!H57 -> 0 | BI33: =BF33/202 -> 0 | BJ33: =SUM(AV33,AW33,BF33,BG33) -> 0 | BK33: ='31'!G84 -> -44441 | BL33: =SUM(AQ33,AV33,AW33,AX33,BA33,BF33,BG33,BH33)/I33% -> 10.927064 | BM33: =SUM(AT33,BD33)/I33% -> 0 | BN33: =(AS33+BC33)/I33 -> 0 | BO33: =K33+O33+R33+V33 -> 263929.54 | BP33: =SUM(AV33,AW33,AX33,BF33,BG33,BH33,BK33) -> -42121.84 | BQ33: =BP33/(AE33*280) -> -6.2214699
