Workbook

Sheet TOTAL
A1: Site Name | B1: Day | C1: Month | D1: Year | E1: Total Electricity Kwh | F1: Electricity Tariff ($/Kwh) | G1: LPG (Kg) | H1: LPG $/Kg | I1: Water Utility Supply (m3) m3 | J1: Water Utility Supply (m3) $/m3 | K1: Room Nights | L1: Food Covers
A2: Maldives at Landaa Giraavaru | B2: 1 | C2: 1 | D2: 2021 | E2: ='Maldives at LG Daily'!D5 -> 30450 | F2: 0.93 | G2: ='Maldives at LG Daily'!F5 -> 0 | H2: 4.39 | I2: ='Maldives at LG Daily'!H5 -> 0 | J2: 1.72 | K2: ='Maldives at LG Daily'!I5 -> 0 | L2: ='Maldives at LG Daily'!J5 -> 0
A3: Maldives at Landaa Giraavaru | B3: =B2+1 -> 2 | C3: 1 | D3: 2021 | E3: ='Maldives at LG Daily'!D6 -> 29767 | F3: 0.93 | G3: ='Maldives at LG Daily'!F6 -> 0 | H3: 4.39 | I3: ='Maldives at LG Daily'!H6 -> 25 | J3: 1.72 | K3: ='Maldives at LG Daily'!I6 -> 0 | L3: ='Maldives at LG Daily'!J6 -> 0
A4: Maldives at Landaa Giraavaru | B4: =B3+1 -> 3 | C4: 1 | D4: 2021 | E4: ='Maldives at LG Daily'!D7 -> 29515 | F4: 0.93 | G4: ='Maldives at LG Daily'!F7 -> 90 | H4: 4.39 | I4: ='Maldives at LG Daily'!H7 -> 0 | J4: 1.72 | K4: ='Maldives at LG Daily'!I7 -> 0 | L4: ='Maldives at LG Daily'!J7 -> 0
A5: Maldives at Landaa Giraavaru | B5: =B4+1 -> 4 | C5: 1 | D5: 2021 | E5: ='Maldives at LG Daily'!D8 -> 31514 | F5: 0.93 | G5: ='Maldives at LG Daily'!F8 -> 90 | H5: 4.39 | I5: ='Maldives at LG Daily'!H8 -> 0 | J5: 1.72 | K5: ='Maldives at LG Daily'!I8 -> 0 | L5: ='Maldives at LG Daily'!J8 -> 0
A6: Maldives at Landaa Giraavaru | B6: =B5+1 -> 5 | C6: 1 | D6: 2021 | E6: ='Maldives at LG Daily'!D9 -> 0 | F6: 0.93 | G6: ='Maldives at LG Daily'!F9 -> 0 | H6: 4.39 | I6: ='Maldives at LG Daily'!H9 -> 0 | J6: 1.72 | K6: ='Maldives at LG Daily'!I9 -> 0 | L6: ='Maldives at LG Daily'!J9 -> 0
A7: Maldives at Landaa Giraavaru | B7: =B6+1 -> 6 | C7: 1 | D7: 2021 | E7: ='Maldives at LG Daily'!D10 -> 0 | F7: 0.93 | G7: ='Maldives at LG Daily'!F10 -> 0 | H7: 4.39 | I7: ='Maldives at LG Daily'!H10 -> 0 | J7: 1.72 | K7: ='Maldives at LG Daily'!I10 -> 0 | L7: ='Maldives at LG Daily'!J10 -> 0
A8: Maldives at Landaa Giraavaru | B8: =B7+1 -> 7 | C8: 1 | D8: 2021 | E8: ='Maldives at LG Daily'!D11 -> 0 | F8: 0.93 | G8: ='Maldives at LG Daily'!F11 -> 0 | H8: 4.39 | I8: ='Maldives at LG Daily'!H11 -> 0 | J8: 1.72 | K8: ='Maldives at LG Daily'!I11 -> 0 | L8: ='Maldives at LG Daily'!J11 -> 0
A9: Maldives at Landaa Giraavaru | B9: =B8+1 -> 8 | C9: 1 | D9: 2021 | E9: ='Maldives at LG Daily'!D12 -> 0 | F9: 0.93 | G9: ='Maldives at LG Daily'!F12 -> 0 | H9: 4.39 | I9: ='Maldives at LG Daily'!H12 -> 0 | J9: 1.72 | K9: ='Maldives at LG Daily'!I12 -> 0 | L9: ='Maldives at LG Daily'!J12 -> 0
A10: Maldives at Landaa Giraavaru | B10: =B9+1 -> 9 | C10: 1 | D10: 2021 | E10: ='Maldives at LG Daily'!D13 -> 0 | F10: 0.93 | G10: ='Maldives at LG Daily'!F13 -> 0 | H10: 4.39 | I10: ='Maldives at LG Daily'!H13 -> 0 | J10: 1.72 | K10: ='Maldives at LG Daily'!I13 -> 0 | L10: ='Maldives at LG Daily'!J13 -> 0
A11: Maldives at Landaa Giraavaru | B11: =B10+1 -> 10 | C11: 1 | D11: 2021 | E11: ='Maldives at LG Daily'!D14 -> 0 | F11: 0.93 | G11: ='Maldives at LG Daily'!F14 -> 0 | H11: 4.39 | I11: ='Maldives at LG Daily'!H14 -> 0 | J11: 1.72 | K11: ='Maldives at LG Daily'!I14 -> 0 | L11: ='Maldives at LG Daily'!J14 -> 0
A12: Maldives at Landaa Giraavaru | B12: =B11+1 -> 11 | C12: 1 | D12: 2021 | E12: ='Maldives at LG Daily'!D15 -> 0 | F12: 0.93 | G12: ='Maldives at LG Daily'!F15 -> 0 | H12: 4.39 | I12: ='Maldives at LG Daily'!H15 -> 0 | J12: 1.72 | K12: ='Maldives at LG Daily'!I15 -> 0 | L12: ='Maldives at LG Daily'!J15 -> 0
A13: Maldives at Landaa Giraavaru | B13: =B12+1 -> 12 | C13: 1 | D13: 2021 | E13: ='Maldives at LG Daily'!D16 -> 0 | F13: 0.93 | G13: ='Maldives at LG Daily'!F16 -> 0 | H13: 4.39 | I13: ='Maldives at LG Daily'!H16 -> 0 | J13: 1.72 | K13: ='Maldives at LG Daily'!I16 -> 0 | L13: ='Maldives at LG Daily'!J16 -> 0
A14: Maldives at Landaa Giraavaru | B14: =B13+1 -> 13 | C14: 1 | D14: 2021 | E14: ='Maldives at LG Daily'!D17 -> 0 | F14: 0.93 | G14: ='Maldives at LG Daily'!F17 -> 0 | H14: 4.39 | I14: ='Maldives at LG Daily'!H17 -> 0 | J14: 1.72 | K14: ='Maldives at LG Daily'!I17 -> 0 | L14: ='Maldives at LG Daily'!J17 -> 0
... A32: Maldives at Landaa Giraavaru | B32: =B31+1 -> 31 | C32: 1 | D32: 2021 | E32: ='Maldives at LG Daily'!D35 -> 0 | F32: 0.93 | G32: ='Maldives at LG Daily'!F35 -> 0 | H32: 4.39 | I32: ='Maldives at LG Daily'!H35 -> 0 | J32: 1.72 | K32: ='Maldives at LG Daily'!I35 -> 0 | L32: ='Maldives at LG Daily'!J35 -> 0

Sheet Maldives at LG Daily
A2: Days | C2: Electricity Meter (KWh) | E2: Gas Kg | G2: Water m3
A3: Date | C3: Reading KWH | D3: Difference KWH | E3: Reading Kg | F3: Difference Kg | G3: Reading m³ | H3: Daily Consumption m³ | I3: ROOM NIGHTS | J3: TOTAL GUESTS
A4: 44196 | C4: =SUM('GENSET #1:GENSET #5'!B10) -> 86064450 | E4: ='Gas-2'!G5 -> 225 | G4: 415
A5: 44197 | C5: =SUM('GENSET #1:GENSET #5'!C10) -> 86094900 | D5: =IF((C5-C4<0), "0",C5-C4) -> 30450 | E5: ='Gas-2'!G6 -> 225 | F5: =IF((E5-E4<0), "0",E5-E4) -> 0 | G5: 368 | H5: =IF((G5-G4<0), "0",G5-G4) -> 0
A6: 44198 | C6: =SUM('GENSET #1:GENSET #5'!C11) -> 86124667 | D6: =IF((C6-C5<0), "0",C6-C5) -> 29767 | E6: ='Gas-2'!G7 -> 90 | F6: =IF((E6-E5<0), "0",E6-E5) -> 0 | G6: 393 | H6: =IF((G6-G5<0), "0",G6-G5) -> 25
A7: 44199 | C7: =SUM('GENSET #1:GENSET #5'!C12) -> 86154182 | D7: =IF((C7-C6<0), "0",C7-C6) -> 29515 | E7: ='Gas-2'!G8 -> 180 | F7: =IF((E7-E6<0), "0",E7-E6) -> 90 | G7: 0 | H7: =IF((G7-G6<0), "0",G7-G6) -> 0
A8: 44200 | C8: =SUM('GENSET #1:GENSET #5'!C13) -> 86185696 | D8: =IF((C8-C7<0), "0",C8-C7) -> 31514 | E8: ='Gas-2'!G9 -> 270 | F8: =IF((E8-E7<0), "0",E8-E7) -> 90 | G8: 0 | H8: =IF((G8-G7<0), "0",G8-G7) -> 0
A9: 44201 | C9: =SUM('GENSET #1:GENSET #5'!C14) -> 0 | D9: =IF((C9-C8<0), "0",C9-C8) -> 0 | E9: ='Gas-2'!G10 -> 0 | F9: =IF((E9-E8<0), "0",E9-E8) -> 0 | G9: 0 | H9: =IF((G9-G8<0), "0",G9-G8) -> 0
A10: 44202 | C10: =SUM('GENSET #1:GENSET #5'!C15) -> 0 | D10: =IF((C10-C9<0), "0",C10-C9) -> 0 | E10: ='Gas-2'!G11 -> 0 | F10: =IF((E10-E9<0), "0",E10-E9) -> 0 | G10: 0 | H10: =IF((G10-G9<0), "0",G10-G9) -> 0
A11: 44203 | C11: =SUM('GENSET #1:GENSET #5'!C16) -> 0 | D11: =IF((C11-C10<0), "0",C11-C10) -> 0 | E11: ='Gas-2'!G12 -> 0 | F11: =IF((E11-E10<0), "0",E11-E10) -> 0 | G11: 0 | H11: =IF((G11-G10<0), "0",G11-G10) -> 0
A12: 44204 | C12: =SUM('GENSET #1:GENSET #5'!C17) -> 0 | D12: =IF((C12-C11<0), "0",C12-C11) -> 0 | E12: ='Gas-2'!G13 -> 0 | F12: =IF((E12-E11<0), "0",E12-E11) -> 0 | G12: 0 | H12: =IF((G12-G11<0), "0",G12-G11) -> 0
A13: 44205 | C13: =SUM('GENSET #1:GENSET #5'!C18) -> 0 | D13: =IF((C13-C12<0), "0",C13-C12) -> 0 | E13: ='Gas-2'!G14 -> 0 | F13: =IF((E13-E12<0), "0",E13-E12) -> 0 | G13: 0 | H13: =IF((G13-G12<0), "0",G13-G12) -> 0
A14: 44206 | C14: =SUM('GENSET #1:GENSET #5'!C19) -> 0 | D14: =IF((C14-C13<0), "0",C14-C13) -> 0 | E14: ='Gas-2'!G15 -> 0 | F14: =IF((E14-E13<0), "0",E14-E13) -> 0 | G14: 0 | H14: =IF((G14-G13<0), "0",G14-G13) -> 0
A15: 44207 | C15: =SUM('GENSET #1:GENSET #5'!C20) -> 0 | D15: =IF((C15-C14<0), "0",C15-C14) -> 0 | E15: ='Gas-2'!G16 -> 0 | F15: =IF((E15-E14<0), "0",E15-E14) -> 0 | G15: 0 | H15: =IF((G15-G14<0), "0",G15-G14) -> 0
A16: 44208 | C16: =SUM('GENSET #1:GENSET #5'!C21) -> 0 | D16: =IF((C16-C15<0), "0",C16-C15) -> 0 | E16: ='Gas-2'!G17 -> 0 | F16: =IF((E16-E15<0), "0",E16-E15) -> 0 | G16: 0 | H16: =IF((G16-G15<0), "0",G16-G15) -> 0
... A35: 44227 | C35: =SUM('GENSET #1:GENSET #5'!C40) -> 0 | D35: =IF((C35-C34<0), "0",C35-C34) -> 0 | E35: ='Gas-2'!G36 -> 0 | F35: =IF((E35-E34<0), "0",E35-E34) -> 0 | G35: 0 | H35: =IF((G35-G34<0), "0",G35-G34) -> 0

Sheet Finance Only
A1: Four Seasons Landaa Giraavaru
A3: Property | B3: MLG
A4: Month | B4: January
A5: Year | B5: 2021
A7: DAY | B7: Electricity Consumption ( kwh) | C7: Diesel Consumption (Liters) | D7: Solar Power Consumption(kwh) | E7: Gas Consumption (kg) | F7: Water Consumption ( m3)
A8: 1 | B8: =SUM('GENSET #1:GENSET #5'!D10) -> 30450 | C8: ='Diesel consumption'!D5 -> 8440 | D8: ='SOLAR METER READING'!D9 -> 560 | E8: =+'Gas-2'!G6 -> 225 | F8: =+WATER!B7 -> 368
A9: 2 | B9: =SUM('GENSET #1:GENSET #5'!D11) -> 29767 | C9: ='Diesel consumption'!D6 -> 8080 | D9: ='SOLAR METER READING'!D10 -> 2728 | E9: =+'Gas-2'!G7 -> 90 | F9: =+WATER!B8 -> 393
A10: 3 | B10: =SUM('GENSET #1:GENSET #5'!D12) -> 29515 | C10: ='Diesel consumption'!D7 -> -42894120 | D10: ='SOLAR METER READING'!D11 -> -2251605 | E10: =+'Gas-2'!G8 -> 180 | F10: =+WATER!B9 -> 0
A11: 4 | B11: =SUM('GENSET #1:GENSET #5'!D13) -> 31514 | C11: ='Diesel consumption'!D8 -> 0 | D11: ='SOLAR METER READING'!D12 -> 0 | E11: =+'Gas-2'!G9 -> 270 | F11: =+WATER!B10 -> 0
A12: 5 | B12: =SUM('GENSET #1:GENSET #5'!D14) -> -86185696 | C12: ='Diesel consumption'!D9 -> 0 | D12: ='SOLAR METER READING'!D13 -> 0 | E12: =+'Gas-2'!G10 -> 0 | F12: =+WATER!B11 -> 0
A13: 6 | B13: =SUM('GENSET #1:GENSET #5'!D15) -> 0 | C13: ='Diesel consumption'!D10 -> 0 | D13: ='SOLAR METER READING'!D14 -> 0 | E13: =+'Gas-2'!G11 -> 0 | F13: =+WATER!B12 -> 0
A14: 7 | B14: =SUM('GENSET #1:GENSET #5'!D16) -> 0 | C14: ='Diesel consumption'!D11 -> 0 | D14: ='SOLAR METER READING'!D15 -> 0 | E14: =+'Gas-2'!G12 -> 0 | F14: =+WATER!B13 -> 0
A15: 8 | B15: =SUM('GENSET #1:GENSET #5'!D17) -> 0 | C15: ='Diesel consumption'!D12 -> 0 | D15: ='SOLAR METER READING'!D16 -> 0 | E15: =+'Gas-2'!G13 -> 0 | F15: =+WATER!B14 -> 0
A16: 9 | B16: =SUM('GENSET #1:GENSET #5'!D18) -> 0 | C16: ='Diesel consumption'!D13 -> 0 | D16: ='SOLAR METER READING'!D17 -> 0 | E16: =+'Gas-2'!G14 -> 0 | F16: =+WATER!B15 -> 0
A17: 10 | B17: =SUM('GENSET #1:GENSET #5'!D19) -> 0 | C17: ='Diesel consumption'!D14 -> 0 | D17: ='SOLAR METER READING'!D18 -> 0 | E17: =+'Gas-2'!G15 -> 0 | F17: =+WATER!B16 -> 0
A18: 11 | B18: =SUM('GENSET #1:GENSET #5'!D20) -> 0 | C18: ='Diesel consumption'!D15 -> 0 | D18: ='SOLAR METER READING'!D19 -> 0 | E18: =+'Gas-2'!G16 -> 0 | F18: =+WATER!B17 -> 0
A19: 12 | B19: =SUM('GENSET #1:GENSET #5'!D21) -> 0 | C19: ='Diesel consumption'!D16 -> 0 | D19: ='SOLAR METER READING'!D20 -> 0 | E19: =+'Gas-2'!G17 -> 0 | F19: =+WATER!B18 -> 0
... A38: 31 | B38: =SUM('GENSET #1:GENSET #5'!D40) -> 0 | C38: ='Diesel consumption'!D35 -> 0 | D38: ='SOLAR METER READING'!D39 -> 0 | E38: =+'Gas-2'!G36 -> 0 | F38: =+WATER!B37 -> 0
A39: Total | B39: =SUM(B8:B38) -> -86064450 | C39: =SUM(C8:C38) -> -42877600 | D39: =SUM(D8:D38) -> -2248317 | E39: =SUM(E8:E38) -> 765 | F39: =SUM(F8:F38) -> 761

Sheet GENSET #1
C1: 1000 KVA
C3: NO#1
A6: 44197
B8: GENSET NO 1
A9: DAY | B9: YESTARDAY | C9: TODAY | D9: Final Electricity Consumption( KWh)
A10: 1 | B10: 16755350 | C10: 16764967 | D10: =C10-B10 -> 9617
A11: 2 | B11: =C10 -> 16764967 | C11: 16765707 | D11: =C11-B11 -> 740
A12: 3 | B12: =C11 -> 16765707 | C12: 16775295 | D12: =C12-B12 -> 9588
A13: 4 | B13: =C12 -> 16775295 | C13: 16782241 | D13: =C13-B13 -> 6946
A14: 5 | B14: =C13 -> 16782241 | D14: =C14-B14 -> -16782241
A15: 6 | B15: =C14 -> 0 | D15: =C15-B15 -> 0
A16: 7 | B16: =C15 -> 0 | D16: =C16-B16 -> 0
A17: 8 | B17: =C16 -> 0 | D17: =C17-B17 -> 0
A18: 9 | B18: =C17 -> 0 | D18: =C18-B18 -> 0
A19: 10 | B19: =C18 -> 0 | D19: =C19-B19 -> 0
A20: 11 | B20: =C19 -> 0 | D20: =C20-B20 -> 0
A21: 12 | B21: =C20 -> 0 | D21: =C21-B21 -> 0
A22: 13 | B22: =C21 -> 0 | D22: =C22-B22 -> 0
A23: 14 | B23: =C22 -> 0 | D23: =C23-B23 -> 0
A24: 15 | B24: =C23 -> 0 | D24: =C24-B24 -> 0
A25: 16 | B25: =C24 -> 0 | D25: =C25-B25 -> 0
... A38: 29 | B38: =C37 -> 0 | D38: =C38-B38 -> 0
A39: 30 | B39: =C38 -> 0 | D39: =C39-B39 -> 0 | G39: NEW ENGINE PURCHASED FROM UK
A40: 31 | B40: =C39 -> 0 | D40: =C40-B40 -> 0
A41: Total | D41: =SUM(D10:D40) -> -16755350 | G41: INSTALLED: NOV 30 2013

Sheet GENSET #2
C1: 1600 KVA
C3: NO#2
A6: 44197
B8: GENSET NO 2
A9: DAY | B9: YESTARDAY | C9: TODAY | D9: Final Electricity Consumption( KW h)
A10: 1 | B10: 28298713 | C10: 28300234 | D10: =C10-B10 -> 1521
A11: 2 | B11: =C10 -> 28300234 | C11: 28317766 | D11: =C11-B11 -> 17532
A12: 3 | B12: =C11 -> 28317766 | C12: 28320930 | D12: =C12-B12 -> 3164
A13: 4 | B13: =C12 -> 28320930 | C13: 28333897 | D13: =C13-B13 -> 12967
A14: 5 | B14: =C13 -> 28333897 | D14: =C14-B14 -> -28333897
A15: 6 | B15: =C14 -> 0 | D15: =C15-B15 -> 0
A16: 7 | B16: =C15 -> 0 | D16: =C16-B16 -> 0
A17: 8 | B17: =C16 -> 0 | D17: =C17-B17 -> 0
A18: 9 | B18: =C17 -> 0 | D18: =C18-B18 -> 0
A19: 10 | B19: =C18 -> 0 | D19: =C19-B19 -> 0
A20: 11 | B20: =C19 -> 0 | D20: =C20-B20 -> 0
A21: 12 | B21: =C20 -> 0 | D21: =C21-B21 -> 0
A22: 13 | B22: =C21 -> 0 | D22: =C22-B22 -> 0
A23: 14 | B23: =C22 -> 0 | D23: =C23-B23 -> 0
A24: 15 | B24: =C23 -> 0 | D24: =C24-B24 -> 0
A25: 16 | B25: =C24 -> 0 | D25: =C25-B25 -> 0
... A40: 31 | B40: =C39 -> 0 | D40: =C40-B40 -> 0
A41: Total | D41: =SUM(D10:D40) -> -28298713

Sheet GENSET #3
C1: 900 KVA
C3: NO#3
A6: 44197
B8: GENSET NO 3
A9: DAY | B9: YESTARDAY | C9: TODAY | D9: Final Electricity Consumption( KW h)
A10: 1 | B10: 12278846 | C10: 12285327 | D10: =C10-B10 -> 6481
A11: 2 | B11: =C10 -> 12285327 | C11: 12292842 | D11: =C11-B11 -> 7515
A12: 3 | B12: =C11 -> 12292842 | C12: 12294612 | D12: =C12-B12 -> 1770
A13: 4 | B13: =C12 -> 12294612 | C13: 12300988 | D13: =C13-B13 -> 6376
A14: 5 | B14: =C13 -> 12300988 | D14: =C14-B14 -> -12300988
A15: 6 | B15: =C14 -> 0 | D15: =C15-B15 -> 0
A16: 7 | B16: =C15 -> 0 | D16: =C16-B16 -> 0
A17: 8 | B17: =C16 -> 0 | D17: =C17-B17 -> 0
A18: 9 | B18: =C17 -> 0 | D18: =C18-B18 -> 0
A19: 10 | B19: =C18 -> 0 | D19: =C19-B19 -> 0
A20: 11 | B20: =C19 -> 0 | D20: =C20-B20 -> 0
A21: 12 | B21: =C20 -> 0 | D21: =C21-B21 -> 0
A22: 13 | B22: =C21 -> 0 | D22: =C22-B22 -> 0
A23: 14 | B23: =C22 -> 0 | D23: =C23-B23 -> 0
A24: 15 | B24: =C23 -> 0 | D24: =C24-B24 -> 0
A25: 16 | B25: =C24 -> 0 | D25: =C25-B25 -> 0
... A40: 31 | B40: =C39 -> 0 | D40: =C40-B40 -> 0
A41: Total | D41: =SUM(D10:D40) -> -12278846

Sheet GENSET #4
C1: 500 KVA
C3: NO#4
A6: 44197
B8: GENSET NO 4
A9: DAY | B9: YESTARDAY | C9: TODAY | D9: Final Electricity Consumption( KW h)
A10: 1 | B10: 11340369 | C10: 11342642 | D10: =C10-B10 -> 2273
A11: 2 | B11: =C10 -> 11342642 | C11: 11345847 | D11: =C11-B11 -> 3205
A12: 3 | B12: =C11 -> 11345847 | C12: 11349375 | D12: =C12-B12 -> 3528
A13: 4 | B13: =C12 -> 11349375 | C13: 11351022 | D13: =C13-B13 -> 1647
A14: 5 | B14: =C13 -> 11351022 | D14: =C14-B14 -> -11351022
A15: 6 | B15: =C14 -> 0 | D15: =C15-B15 -> 0
A16: 7 | B16: =C15 -> 0 | D16: =C16-B16 -> 0
A17: 8 | B17: =C16 -> 0 | D17: =C17-B17 -> 0
A18: 9 | B18: =C17 -> 0 | D18: =C18-B18 -> 0
A19: 10 | B19: =C18 -> 0 | D19: =C19-B19 -> 0
A20: 11 | B20: =C19 -> 0 | D20: =C20-B20 -> 0
A21: 12 | B21: =C20 -> 0 | D21: =C21-B21 -> 0
A22: 13 | B22: =C21 -> 0 | D22: =C22-B22 -> 0
A23: 14 | B23: =C22 -> 0 | D23: =C23-B23 -> 0
A24: 15 | B24: =C23 -> 0 | D24: =C24-B24 -> 0
A25: 16 | B25: =C24 -> 0 | D25: =C25-B25 -> 0
... A40: 31 | B40: =C39 -> 0 | D40: =C40-B40 -> 0
A41: Total | D41: =SUM(D10:D40) -> -11340369

Sheet GENSET #5
C1: 1000 KVA
C3: NO#5
A6: 44197
B8: GENSET NO 5
A9: DAY | B9: YESTARDAY | C9: TODAY | D9: Final Electricity Consumption( KWh)
A10: 1 | B10: 17391172 | C10: 17401730 | D10: =C10-B10 -> 10558
A11: 2 | B11: =C10 -> 17401730 | C11: 17402505 | D11: =C11-B11 -> 775
A12: 3 | B12: =C11 -> 17402505 | C12: 17413970 | D12: =C12-B12 -> 11465
A13: 4 | B13: =C12 -> 17413970 | C13: 17417548 | D13: =C13-B13 -> 3578
A14: 5 | B14: =C13 -> 17417548 | D14: =C14-B14 -> -17417548
A15: 6 | B15: =C14 -> 0 | D15: =C15-B15 -> 0
A16: 7 | B16: =C15 -> 0 | D16: =C16-B16 -> 0
A17: 8 | B17: =C16 -> 0 | D17: =C17-B17 -> 0
A18: 9 | B18: =C17 -> 0 | D18: =C18-B18 -> 0
A19: 10 | B19: =C18 -> 0 | D19: =C19-B19 -> 0
A20: 11 | B20: =C19 -> 0 | D20: =C20-B20 -> 0
A21: 12 | B21: =C20 -> 0 | D21: =C21-B21 -> 0
A22: 13 | B22: =C21 -> 0 | D22: =C22-B22 -> 0
A23: 14 | B23: =C22 -> 0 | D23: =C23-B23 -> 0
A24: 15 | B24: =C23 -> 0 | D24: =C24-B24 -> 0
A25: 16 | B25: =C24 -> 0 | D25: =C25-B25 -> 0
... A40: 31 | B40: =C39 -> 0 | D40: =C40-B40 -> 0
A41: Total | D41: =SUM(D10:D40) -> -17391172

Sheet KWH Summary
B1: 44197
B3: Total KW Production
B4: Day | C4: Genset 1 | D4: Genset 2 | E4: Genset 3 | F4: Genset 4 | G4: Genset 5 | H4: Total
B5: 1 | C5: ='GENSET #1'!D10 -> 9617 | D5: ='GENSET #2'!D10 -> 1521 | E5: ='GENSET #3'!D10 -> 6481 | F5: ='GENSET #4'!D10 -> 2273 | G5: ='GENSET #5'!D10 -> 10558 | H5: =SUM(C5:G5) -> 30450
B6: 2 | C6: ='GENSET #1'!D11 -> 740 | D6: ='GENSET #2'!D11 -> 17532 | E6: ='GENSET #3'!D11 -> 7515 | F6: ='GENSET #4'!D11 -> 3205 | G6: ='GENSET #5'!D11 -> 775 | H6: =SUM(C6:G6) -> 29767
B7: 3 | C7: ='GENSET #1'!D12 -> 9588 | D7: ='GENSET #2'!D12 -> 3164 | E7: ='GENSET #3'!D12 -> 1770 | F7: ='GENSET #4'!D12 -> 3528 | G7: ='GENSET #5'!D12 -> 11465 | H7: =SUM(C7:G7) -> 29515
B8: 4 | C8: ='GENSET #1'!D13 -> 6946 | D8: ='GENSET #2'!D13 -> 12967 | E8: ='GENSET #3'!D13 -> 6376 | F8: ='GENSET #4'!D13 -> 1647 | G8: ='GENSET #5'!D13 -> 3578 | H8: =SUM(C8:G8) -> 31514
B9: 5 | C9: ='GENSET #1'!D14 -> -16782241 | D9: ='GENSET #2'!D14 -> -28333897 | E9: ='GENSET #3'!D14 -> -12300988 | F9: ='GENSET #4'!D14 -> -11351022 | G9: ='GENSET #5'!D14 -> -17417548 | H9: =SUM(C9:G9) -> -86185696
B10: 6 | C10: ='GENSET #1'!D15 -> 0 | D10: ='GENSET #2'!D15 -> 0 | E10: ='GENSET #3'!D15 -> 0 | F10: ='GENSET #4'!D15 -> 0 | G10: ='GENSET #5'!D15 -> 0 | H10: =SUM(C10:G10) -> 0
B11: 7 | C11: ='GENSET #1'!D16 -> 0 | D11: ='GENSET #2'!D16 -> 0 | E11: ='GENSET #3'!D16 -> 0 | F11: ='GENSET #4'!D16 -> 0 | G11: ='GENSET #5'!D16 -> 0 | H11: =SUM(C11:G11) -> 0
B12: 8 | C12: ='GENSET #1'!D17 -> 0 | D12: ='GENSET #2'!D17 -> 0 | E12: ='GENSET #3'!D17 -> 0 | F12: ='GENSET #4'!D17 -> 0 | G12: ='GENSET #5'!D17 -> 0 | H12: =SUM(C12:G12) -> 0
B13: 9 | C13: ='GENSET #1'!D18 -> 0 | D13: ='GENSET #2'!D18 -> 0 | E13: ='GENSET #3'!D18 -> 0 | F13: ='GENSET #4'!D18 -> 0 | G13: ='GENSET #5'!D18 -> 0 | H13: =SUM(C13:G13) -> 0
B14: 10 | C14: ='GENSET #1'!D19 -> 0 | D14: ='GENSET #2'!D19 -> 0 | E14: ='GENSET #3'!D19 -> 0 | F14: ='GENSET #4'!D19 -> 0 | G14: ='GENSET #5'!D19 -> 0 | H14: =SUM(C14:G14) -> 0
B15: 11 | C15: ='GENSET #1'!D20 -> 0 | D15: ='GENSET #2'!D20 -> 0 | E15: ='GENSET #3'!D20 -> 0 | F15: ='GENSET #4'!D20 -> 0 | G15: ='GENSET #5'!D20 -> 0 | H15: =SUM(C15:G15) -> 0
B16: 12 | C16: ='GENSET #1'!D21 -> 0 | D16: ='GENSET #2'!D21 -> 0 | E16: ='GENSET #3'!D21 -> 0 | F16: ='GENSET #4'!D21 -> 0 | G16: ='GENSET #5'!D21 -> 0 | H16: =SUM(C16:G16) -> 0
... B35: 31 | C35: ='GENSET #1'!D40 -> 0 | D35: ='GENSET #2'!D40 -> 0 | E35: ='GENSET #3'!D40 -> 0 | F35: ='GENSET #4'!D40 -> 0 | G35: ='GENSET #5'!D40 -> 0 | H35: =SUM(C35:G35) -> 0
A36: TOTAL | C36: =SUM(C5:C35) -> -16755350 | D36: =SUM(D5:D35) -> -28298713 | E36: =SUM(E5:E35) -> -12278846 | F36: =SUM(F5:F35) -> -11340369 | G36: =SUM(G5:G35) -> -17391172

Sheet Diesel consumption
A2: 44197
B3: Liters | F3: Boat meter Reading
A4: Date | B4: Yesterday | C4: Today | D4: In 24 hrs | F4: Yesterday | G4: Today | I4: In Barrels | K4: Carbon Emmision
A5: 1 | B5: 42877600 | C5: 42886040 | D5: =C5-B5 -> 8440 | I5: =D5/200 -> 42.2 | K5: =2.68*D5 -> 22619.2 | L5: =K5/1000 -> 22.6192
A6: 2 | B6: =C5 -> 42886040 | C6: 42894120 | D6: =C6-B6 -> 8080 | I6: =D6/200 -> 40.4 | K6: =2.68*D6 -> 21654.4 | L6: =K6/1000 -> 21.6544
A7: 3 | B7: =C6 -> 42894120 | D7: =C7-B7 -> -42894120 | I7: =D7/200 -> -214470.6 | K7: =2.68*D7 -> -1.1495624e+08 | L7: =K7/1000 -> -114956.24
A8: 4 | B8: =C7 -> 0 | D8: =C8-B8 -> 0 | I8: =D8/200 -> 0 | K8: =2.68*D8 -> 0 | L8: =K8/1000 -> 0
A9: 5 | B9: =C8 -> 0 | D9: =C9-B9 -> 0 | I9: =D9/200 -> 0 | K9: =2.68*D9 -> 0 | L9: =K9/1000 -> 0
A10: 6 | B10: =C9 -> 0 | D10: =C10-B10 -> 0 | I10: =D10/200 -> 0 | K10: =2.68*D10 -> 0 | L10: =K10/1000 -> 0
A11: 7 | B11: =C10 -> 0 | D11: =C11-B11 -> 0 | I11: =D11/200 -> 0 | K11: =2.68*D11 -> 0 | L11: =K11/1000 -> 0
A12: 8 | B12: =C11 -> 0 | D12: =C12-B12 -> 0 | I12: =D12/200 -> 0 | K12: =2.68*D12 -> 0 | L12: =K12/1000 -> 0
A13: 9 | B13: =C12 -> 0 | D13: =C13-B13 -> 0 | I13: =D13/200 -> 0 | K13: =2.68*D13 -> 0 | L13: =K13/1000 -> 0
A14: 10 | B14: =C13 -> 0 | D14: =C14-B14 -> 0 | I14: =D14/200 -> 0 | K14: =2.68*D14 -> 0 | L14: =K14/1000 -> 0
A15: 11 | B15: =C14 -> 0 | D15: =C15-B15 -> 0 | I15: =D15/200 -> 0 | K15: =2.68*D15 -> 0 | L15: =K15/1000 -> 0
A16: 12 | B16: =C15 -> 0 | D16: =C16-B16 -> 0 | I16: =D16/200 -> 0 | K16: =2.68*D16 -> 0 | L16: =K16/1000 -> 0
A17: 13 | B17: =C16 -> 0 | D17: =C17-B17 -> 0 | I17: =D17/200 -> 0 | K17: =2.68*D17 -> 0 | L17: =K17/1000 -> 0
A18: 14 | B18: =C17 -> 0 | D18: =C18-B18 -> 0 | I18: =D18/200 -> 0 | K18: =2.68*D18 -> 0 | L18: =K18/1000 -> 0
... A33: 29 | B33: =C32 -> 0 | D33: =C33-B33 -> 0 | I33: =D33/200 -> 0 | K33: =2.68*D33 -> 0 | L33: =K33/1000 -> 0
A34: 30 | B34: =C33 -> 0 | D34: =C34-B34 -> 0 | F34: 0 | I34: =D34/200 -> 0 | K34: =2.68*D34 -> 0 | L34: =K34/1000 -> 0
A35: 31 | B35: =C34 -> 0 | D35: =C35-B35 -> 0
D36: =SUM(D5:D34) -> -42877600 | I36: =SUM(I5:I34) -> -214388 | K36: =2.68*D36 -> -114911968 | L36: =K36/1000 -> -114911.97

Sheet WATER
A2: 44197
B4: m3
A6: Day | B6: WATER | C6: RESORT OCCUPANCY | E6: ADR $
A7: 1 | B7: 368 | C7: 97.09 | D7: % | E7: 4160
A8: 2 | B8: 393 | C8: 95.15 | D8: %
A9: 3 | D9: %
A10: 4 | D10: %
A11: 5 | D11: %
A12: 6 | D12: %
A13: 7 | D13: %
A14: 8 | D14: %
A15: 9 | D15: %
A16: 10 | D16: %
A17: 11 | D17: %
A18: 12 | D18: %
A19: 13 | D19: %
A20: 14 | D20: %
... A37: 31 | D37: %
B38: =SUM(B7:B37) -> 761 | C38: =SUM(C7:C37)/31 -> 6.2012903 | G38: =SUM(C27:C36) -> 0
G39: =G38/11 -> 0

Sheet Gas-2
A1: 43831
A2: GAS CONSUMPTION / CYLINDERS
A4: DAY | B4: BLUE + TIKI TORCH | C4: ALBARAKAT + TIKI TORCH | D4: FUEGO(cafelandaa) TIKI TORCH | E4: Main Kitchen & Fego kitchen | F4: Total | G4: Total Consumption
A5: 44561 | G5: 225
A6: 1 | D6: 5 | F6: =SUM(B6:C6,D6:E6) -> 5 | G6: =SUM(B6:E6)*45 -> 225
A7: 2 | D7: 2 | F7: =SUM(B7:C7,D7:E7) -> 2 | G7: =SUM(B7:E7)*45 -> 90
A8: 3 | D8: 4 | F8: =SUM(B8:C8,D8:E8) -> 4 | G8: =SUM(B8:E8)*45 -> 180
A9: 4 | D9: 6 | F9: =SUM(B9:C9,D9:E9) -> 6 | G9: =SUM(B9:E9)*45 -> 270
A10: 5 | F10: =SUM(B10:C10,D10:E10) -> 0 | G10: =SUM(B10:E10)*45 -> 0
A11: 6 | F11: =SUM(B11:C11,D11:E11) -> 0 | G11: =SUM(B11:E11)*45 -> 0
A12: 7 | F12: =SUM(B12:C12,D12:E12) -> 0 | G12: =SUM(B12:E12)*45 -> 0
A13: 8 | F13: =SUM(B13:C13,D13:E13) -> 0 | G13: =SUM(B13:E13)*45 -> 0
A14: 9 | F14: =SUM(B14:C14,D14:E14) -> 0 | G14: =SUM(B14:E14)*45 -> 0
A15: 10 | F15: =SUM(B15:C15,D15:E15) -> 0 | G15: =SUM(B15:E15)*45 -> 0
A16: 11 | F16: =SUM(B16:C16,D16:E16) -> 0 | G16: =SUM(B16:E16)*45 -> 0
A17: 12 | F17: =SUM(B17:C17,D17:E17) -> 0 | G17: =SUM(B17:E17)*45 -> 0
A18: 13 | F18: =SUM(B18:C18,D18:E18) -> 0 | G18: =SUM(B18:E18)*45 -> 0
A19: 14 | F19: =SUM(B19:C19,D19:E19) -> 0 | G19: =SUM(B19:E19)*45 -> 0
A20: 15 | F20: =SUM(B20:C20,D20:E20) -> 0 | G20: =SUM(B20:E20)*45 -> 0
A21: 16 | F21: =SUM(B21:C21,D21:E21) -> 0 | G21: =SUM(B21:E21)*45 -> 0
... A36: 31 | F36: =SUM(B36:C36,D36:E36) -> 0 | G36: =SUM(B36:E36)*45 -> 0
A37: Total | B37: =SUM(B6:B36) -> 0 | E37: =SUM(E6:E36) -> 0 | G37: =SUM(G6:G36) -> 765 | H37: =G37/45 -> 17
H38: =H37*60 -> 1020

Sheet SOLAR METER READING
C3: solar reading
B5: 44197
B7: solar meter reading
A8: DAY | B8: YESTARDAY | C8: TODAY | D8: Final Electricity Consumption( KW h)
A9: 1 | B9: 2248317 | C9: 2248877 | D9: =C9-B9 -> 560
A10: 2 | B10: =C9 -> 2248877 | C10: 2251605 | D10: =C10-B10 -> 2728
A11: 3 | B11: =C10 -> 2251605 | D11: =C11-B11 -> -2251605
A12: 4 | B12: =C11 -> 0 | D12: =C12-B12 -> 0
A13: 5 | B13: =C12 -> 0 | D13: =C13-B13 -> 0 | J13: 1 liter diesel | K13: 11.1 kwh
A14: 6 | B14: =C13 -> 0 | D14: =C14-B14 -> 0 | J14: 212.88 diesel | K14: 2363 kwh
A15: 7 | B15: =C14 -> 0 | D15: =C15-B15 -> 0
A16: 8 | B16: =C15 -> 0 | D16: =C16-B16 -> 0
A17: 9 | B17: =C16 -> 0 | D17: =C17-B17 -> 0
A18: 10 | B18: =C17 -> 0 | D18: =C18-B18 -> 0
A19: 11 | B19: =C18 -> 0 | D19: =C19-B19 -> 0
A20: 12 | B20: =C19 -> 0 | D20: =C20-B20 -> 0
A21: 13 | B21: =C20 -> 0 | D21: =C21-B21 -> 0
A22: 14 | B22: =C21 -> 0 | D22: =C22-B22 -> 0
A23: 15 | B23: =C22 -> 0 | D23: =C23-B23 -> 0
A24: 16 | B24: =C23 -> 0 | D24: =C24-B24 -> 0
A25: 17 | B25: =C24 -> 0 | D25: =C25-B25 -> 0
A26: 18 | B26: =C25 -> 0 | D26: =C26-B26 -> 0
... A39: 31 | B39: =C38 -> 0 | D39: =C39-B39 -> 0
A40: Total | D40: =SUM(D9:D39) -> -2248317

Sheet FEEDER Consumption 
C3: POWER HOUSE FEEDER READING
A5: 43313
B7: BLU FEEDER PANEL 1 | E7: BLU FEEDER PANEL 2 | H7: POWER HOUSE FEEDER PANEL NO:3 | K7: Main Kitchen -7 | N7: Main Kitchen -10 | Q7: Water treatment Plant | T7: Sewage treatment Plant | W7: Laundry--8SSB | Z7: Laundry-9 | AC7: New staff accomodation (E0) | AF7: Boat Dock feeder - 22 | AI7: Staff block-16(E2-E3) | AL7: Management block-5 | AO7: Staff Block Feeder-3(E4-E5) | AR7: DIESEL TANK JETTY METER | AU7: SNR STAFF BLOCK | AX7: RECEPTION | BA7: DIVE CENTER | BD7: 301-307 | BG7: 308-314 | BJ7: 315-320 | BM7: 401-407 | BP7: 408-414 | BS7: 415-420 | BV7: SPA - 1 | BY7: SPA - 2 | CB7: BLU KITCHEN - 1 | CE7: BLU KITCHEN - 2 | CH7: AL BARAKATH | CK7: STAFF KITCHEN | CN7: MANAGR BLOCK GARDEN
A8: DAY | B8: Yesterday | C8: Today | D8: Consumption | E8: Yesterday | F8: Today | G8: Consumption | H8: Yesterday | I8: Today | J8: Consumption | K8: Yesterday | L8: Today | M8: Consumption | N8: Yesterday | O8: Today | P8: Consumption | Q8: Yesterday | R8: Today | S8: Consumption | T8: Yesterday | U8: Today | V8: Consumption | W8: Yesterday | X8: Today | Y8: Consumption | Z8: Yesterday | AA8: Today | AB8: Consumption | AC8: Yesterday | AD8: Today | AE8: Consumption | AF8: Yesterday | AG8: Today | AH8: Consumption | AI8: Yesterday | AJ8: Today | AK8: Consumption | AL8: Yesterday | AM8: Today | AN8: Consumption | AO8: Yesterday | AP8: Today | AQ8: Consumption | AR8: Yesterday | AS8: Today | AT8: Consumption | AU8: Yesterday | AV8: Today | AW8: Consumption | AX8: Yesterday | AY8: Today | AZ8: Consumption | BA8: Yesterday | BB8: Today | BC8: Consumption | BD8: Yesterday | BE8: Today | BF8: Consumption | BG8: Yesterday | BH8: Today | BI8: Consumption | BJ8: Yesterday | BK8: Today | BL8: Consumption | BM8: Yesterday | BN8: Today | BO8: Consumption | BP8: Yesterday | BQ8: Today | BR8: Consumption | BS8: Yesterday | BT8: Today | BU8: Consumption | BV8: Yesterday | BW8: Today | BX8: Consumption | BY8: Yesterday | BZ8: Today | CA8: Consumption | CB8: Yesterday | CC8: Today | CD8: Consumption | CE8: Yesterday | CF8: Today | CG8: Consumption | CH8: Yesterday | CI8: Today | CJ8: Consumption | CK8: Yesterday | CL8: Today | CM8: Consumption | CN8: Yesterday | CO8: Today | CP8: Consumption
A9: 1 | B9: 25088084 | C9: 25091780 | D9: =C9-B9 -> 3696 | E9: 21981188 | F9: 21985367 | G9: =F9-E9 -> 4179 | H9: 83718230 | I9: 83733710 | J9: =I9-H9 -> 15480 | K9: 1722220 | L9: 1724500 | M9: =L9-K9 -> 2280 | N9: 2330923 | O9: 2333661 | P9: =O9-N9 -> 2738 | Q9: 1403900 | R9: 1405800 | S9: =R9-Q9 -> 1900 | T9: 659727 | U9: 660381 | V9: =U9-T9 -> 654 | W9: 6827800 | X9: 6834100 | Y9: =X9-W9 -> 6300 | Z9: 1485900 | AA9: 1489300 | AB9: =AA9-Z9 -> 3400 | AC9: 443008 | AD9: 443496 | AE9: =AD9-AC9 -> 488 | AF9: 312460 | AG9: 312980 | AH9: =AG9-AF9 -> 520 | AI9: 522300 | AJ9: 523370 | AK9: =AJ9-AI9 -> 1070 | AL9: 971190 | AM9: 972780 | AN9: =AM9-AL9 -> 1590 | AO9: 617560 | AP9: 618570 | AQ9: =AP9-AO9 -> 1010 | AR9: 455500 | AS9: 455500 | AT9: =AS9-AR9 -> 0 | AU9: 398160 | AV9: 402100 | AW9: =AV9-AU9 -> 3940 | AX9: 313610 | AY9: 314860 | AZ9: =AY9-AX9 -> 1250 | BA9: 838750 | BB9: 841820 | BC9: =BB9-BA9 -> 3070 | BD9: 16414 | BE9: 16514 | BF9: =BE9-BD9 -> 100 | BG9: 13337 | BH9: 13388 | BI9: =BH9-BG9 -> 51 | BJ9: 12664 | BK9: 12734 | BL9: =BK9-BJ9 -> 70 | BM9: 20408 | BN9: 20499 | BO9: =BN9-BM9 -> 91 | BP9: 13725 | BQ9: 13794 | BR9: =BQ9-BP9 -> 69 | BS9: 15869 | BT9: 15916 | BU9: =BT9-BS9 -> 47 | BV9: 10596 | BW9: 10645 | BX9: =BW9-BV9 -> 49 | BY9: 27031 | BZ9: 27263 | CA9: =BZ9-BY9 -> 232 | CB9: 22769 | CC9: 22906 | CD9: =CC9-CB9 -> 137 | CE9: 65938 | CF9: 66116 | CG9: =CF9-CE9 -> 178 | CH9: 33060 | CI9: 33329 | CJ9: =CI9-CH9 -> 269 | CK9: 10817 | CL9: 10864 | CM9: =CL9-CK9 -> 47 | CN9: 38022 | CO9: 38181 | CP9: =CO9-CN9 -> 159
A10: 2 | B10: =C9 -> 25091780 | C10: 25095537 | D10: =C10-B10 -> 3757 | E10: =F9 -> 21985367 | F10: 21990123 | G10: =F10-E10 -> 4756 | H10: =I9 -> 83733710 | I10: 83747555 | J10: =I10-H10 -> 13845 | K10: =L9 -> 1724500 | L10: 1726700 | M10: =L10-K10 -> 2200 | N10: =O9 -> 2333661 | O10: 2336315 | P10: =O10-N10 -> 2654 | Q10: =R9 -> 1405800 | R10: 1407800 | S10: =R10-Q10 -> 2000 | T10: =U9 -> 660381 | U10: 661098 | V10: =U10-T10 -> 717 | W10: =X9 -> 6834100 | X10: 6840600 | Y10: =X10-W10 -> 6500 | Z10: =AA9 -> 1489300 | AA10: 1492200 | AB10: =AA10-Z10 -> 2900 | AC10: =AD9 -> 443496 | AD10: 443924 | AE10: =AD10-AC10 -> 428 | AF10: =AG9 -> 312980 | AG10: 313400 | AH10: =AG10-AF10 -> 420 | AI10: =AJ9 -> 523370 | AJ10: 524130 | AK10: =AJ10-AI10 -> 760 | AL10: =AM9 -> 972780 | AM10: 973920 | AN10: =AM10-AL10 -> 1140 | AO10: =AP9 -> 618570 | AP10: 619280 | AQ10: =AP10-AO10 -> 710 | AR10: =AS9 -> 455500 | AS10: 456000 | AT10: =AS10-AR10 -> 500 | AU10: =AV9 -> 402100 | AV10: 402740 | AW10: =AV10-AU10 -> 640 | AX10: =AY9 -> 314860 | AY10: 316020 | AZ10: =AY10-AX10 -> 1160 | BA10: =BB9 -> 841820 | BB10: 845160 | BC10: =BB10-BA10 -> 3340 | BD10: =BE9 -> 16514 | BE10: 16623 | BF10: =BE10-BD10 -> 109 | BG10: =BH9 -> 13388 | BH10: 13470 | BI10: =BH10-BG10 -> 82 | BJ10: =BK9 -> 12734 | BK10: 12836 | BL10: =BK10-BJ10 -> 102 | BM10: =BN9 -> 20499 | BN10: 20600 | BO10: =BN10-BM10 -> 101 | BP10: =BQ9 -> 13794 | BQ10: 13870 | BR10: =BQ10-BP10 -> 76 | BS10: =BT9 -> 15916 | BT10: 15965 | BU10: =BT10-BS10 -> 49 | BV10: =BW9 -> 10645 | BW10: 10698 | BX10: =BW10-BV10 -> 53 | BY10: =BZ9 -> 27263 | BZ10: 27430 | CA10: =BZ10-BY10 -> 167 | CB10: =CC9 -> 22906 | CC10: 22994 | CD10: =CC10-CB10 -> 88 | CE10: =CF9 -> 66116 | CF10: 66398 | CG10: =CF10-CE10 -> 282 | CH10: =CI9 -> 33329 | CI10: 33706 | CJ10: =CI10-CH10 -> 377 | CK10: =CL9 -> 10864 | CL10: 10909 | CM10: =CL10-CK10 -> 45 | CN10: =CO9 -> 38181 | CO10: 38302 | CP10: =CO10-CN10 -> 121
A11: 3 | B11: =C10 -> 25095537 | D11: =C11-B11 -> -25095537 | E11: =F10 -> 21990123 | G11: =F11-E11 -> -21990123 | H11: =I10 -> 83747555 | J11: =I11-H11 -> -83747555 | K11: =L10 -> 1726700 | M11: =L11-K11 -> -1726700 | N11: =O10 -> 2336315 | P11: =O11-N11 -> -2336315 | Q11: =R10 -> 1407800 | S11: =R11-Q11 -> -1407800 | T11: =U10 -> 661098 | V11: =U11-T11 -> -661098 | W11: =X10 -> 6840600 | Y11: =X11-W11 -> -6840600 | Z11: =AA10 -> 1492200 | AB11: =AA11-Z11 -> -1492200 | AC11: =AD10 -> 443924 | AE11: =AD11-AC11 -> -443924 | AF11: =AG10 -> 313400 | AH11: =AG11-AF11 -> -313400 | AI11: =AJ10 -> 524130 | AK11: =AJ11-AI11 -> -524130 | AL11: =AM10 -> 973920 | AN11: =AM11-AL11 -> -973920 | AO11: =AP10 -> 619280 | AQ11: =AP11-AO11 -> -619280 | AR11: =AS10 -> 456000 | AT11: =AS11-AR11 -> -456000 | AU11: =AV10 -> 402740 | AW11: =AV11-AU11 -> -402740 | AX11: =AY10 -> 316020 | AZ11: =AY11-AX11 -> -316020 | BA11: =BB10 -> 845160 | BC11: =BB11-BA11 -> -845160 | BD11: =BE10 -> 16623 | BF11: =BE11-BD11 -> -16623 | BG11: =BH10 -> 13470 | BI11: =BH11-BG11 -> -13470 | BJ11: =BK10 -> 12836 | BL11: =BK11-BJ11 -> -12836 | BM11: =BN10 -> 20600 | BO11: =BN11-BM11 -> -20600 | BP11: =BQ10 -> 13870 | BR11: =BQ11-BP11 -> -13870 | BS11: =BT10 -> 15965 | BU11: =BT11-BS11 -> -15965 | BV11: =BW10 -> 10698 | BX11: =BW11-BV11 -> -10698 | BY11: =BZ10 -> 27430 | CA11: =BZ11-BY11 -> -27430 | CB11: =CC10 -> 22994 | CD11: =CC11-CB11 -> -22994 | CE11: =CF10 -> 66398 | CG11: =CF11-CE11 -> -66398 | CH11: =CI10 -> 33706 | CJ11: =CI11-CH11 -> -33706 | CK11: =CL10 -> 10909 | CM11: =CL11-CK11 -> -10909 | CN11: =CO10 -> 38302 | CP11: =CO11-CN11 -> -38302
A12: 4 | B12: =C11 -> 0 | D12: =C12-B12 -> 0 | E12: =F11 -> 0 | G12: =F12-E12 -> 0 | H12: =I11 -> 0 | J12: =I12-H12 -> 0 | K12: =L11 -> 0 | M12: =L12-K12 -> 0 | N12: =O11 -> 0 | P12: =O12-N12 -> 0 | Q12: =R11 -> 0 | S12: =R12-Q12 -> 0 | T12: =U11 -> 0 | V12: =U12-T12 -> 0 | W12: =X11 -> 0 | Y12: =X12-W12 -> 0 | Z12: =AA11 -> 0 | AB12: =AA12-Z12 -> 0 | AC12: =AD11 -> 0 | AE12: =AD12-AC12 -> 0 | AF12: =AG11 -> 0 | AH12: =AG12-AF12 -> 0 | AI12: =AJ11 -> 0 | AK12: =AJ12-AI12 -> 0 | AL12: =AM11 -> 0 | AN12: =AM12-AL12 -> 0 | AO12: =AP11 -> 0 | AQ12: =AP12-AO12 -> 0 | AR12: =AS11 -> 0 | AT12: =AS12-AR12 -> 0 | AU12: =AV11 -> 0 | AW12: =AV12-AU12 -> 0 | AX12: =AY11 -> 0 | AZ12: =AY12-AX12 -> 0 | BA12: =BB11 -> 0 | BC12: =BB12-BA12 -> 0 | BD12: =BE11 -> 0 | BF12: =BE12-BD12 -> 0 | BG12: =BH11 -> 0 | BI12: =BH12-BG12 -> 0 | BJ12: =BK11 -> 0 | BL12: =BK12-BJ12 -> 0 | BM12: =BN11 -> 0 | BO12: =BN12-BM12 -> 0 | BP12: =BQ11 -> 0 | BR12: =BQ12-BP12 -> 0 | BS12: =BT11 -> 0 | BU12: =BT12-BS12 -> 0 | BV12: =BW11 -> 0 | BX12: =BW12-BV12 -> 0 | BY12: =BZ11 -> 0 | CA12: =BZ12-BY12 -> 0 | CB12: =CC11 -> 0 | CD12: =CC12-CB12 -> 0 | CE12: =CF11 -> 0 | CG12: =CF12-CE12 -> 0 | CH12: =CI11 -> 0 | CJ12: =CI12-CH12 -> 0 | CK12: =CL11 -> 0 | CM12: =CL12-CK12 -> 0 | CN12: =CO11 -> 0 | CP12: =CO12-CN12 -> 0
A13: 5 | B13: =C12 -> 0 | D13: =C13-B13 -> 0 | E13: =F12 -> 0 | G13: =F13-E13 -> 0 | H13: =I12 -> 0 | J13: =I13-H13 -> 0 | K13: =L12 -> 0 | M13: =L13-K13 -> 0 | N13: =O12 -> 0 | P13: =O13-N13 -> 0 | Q13: =R12 -> 0 | S13: =R13-Q13 -> 0 | T13: =U12 -> 0 | V13: =U13-T13 -> 0 | W13: =X12 -> 0 | Y13: =X13-W13 -> 0 | Z13: =AA12 -> 0 | AB13: =AA13-Z13 -> 0 | AC13: =AD12 -> 0 | AE13: =AD13-AC13 -> 0 | AF13: =AG12 -> 0 | AH13: =AG13-AF13 -> 0 | AI13: =AJ12 -> 0 | AK13: =AJ13-AI13 -> 0 | AL13: =AM12 -> 0 | AN13: =AM13-AL13 -> 0 | AO13: =AP12 -> 0 | AQ13: =AP13-AO13 -> 0 | AR13: =AS12 -> 0 | AT13: =AS13-AR13 -> 0 | AU13: =AV12 -> 0 | AW13: =AV13-AU13 -> 0 | AX13: =AY12 -> 0 | AZ13: =AY13-AX13 -> 0 | BA13: =BB12 -> 0 | BC13: =BB13-BA13 -> 0 | BD13: =BE12 -> 0 | BF13: =BE13-BD13 -> 0 | BG13: =BH12 -> 0 | BI13: =BH13-BG13 -> 0 | BJ13: =BK12 -> 0 | BL13: =BK13-BJ13 -> 0 | BM13: =BN12 -> 0 | BO13: =BN13-BM13 -> 0 | BP13: =BQ12 -> 0 | BR13: =BQ13-BP13 -> 0 | BS13: =BT12 -> 0 | BU13: =BT13-BS13 -> 0 | BV13: =BW12 -> 0 | BX13: =BW13-BV13 -> 0 | BY13: =BZ12 -> 0 | CA13: =BZ13-BY13 -> 0 | CB13: =CC12 -> 0 | CD13: =CC13-CB13 -> 0 | CE13: =CF12 -> 0 | CG13: =CF13-CE13 -> 0 | CH13: =CI12 -> 0 | CJ13: =CI13-CH13 -> 0 | CK13: =CL12 -> 0 | CM13: =CL13-CK13 -> 0 | CN13: =CO12 -> 0 | CP13: =CO13-CN13 -> 0
A14: 6 | B14: =C13 -> 0 | D14: =C14-B14 -> 0 | E14: =F13 -> 0 | G14: =F14-E14 -> 0 | H14: =I13 -> 0 | J14: =I14-H14 -> 0 | K14: =L13 -> 0 | M14: =L14-K14 -> 0 | N14: =O13 -> 0 | P14: =O14-N14 -> 0 | Q14: =R13 -> 0 | S14: =R14-Q14 -> 0 | T14: =U13 -> 0 | V14: =U14-T14 -> 0 | W14: =X13 -> 0 | Y14: =X14-W14 -> 0 | Z14: =AA13 -> 0 | AB14: =AA14-Z14 -> 0 | AC14: =AD13 -> 0 | AE14: =AD14-AC14 -> 0 | AF14: =AG13 -> 0 | AH14: =AG14-AF14 -> 0 | AI14: =AJ13 -> 0 | AK14: =AJ14-AI14 -> 0 | AL14: =AM13 -> 0 | AN14: =AM14-AL14 -> 0 | AO14: =AP13 -> 0 | AQ14: =AP14-AO14 -> 0 | AR14: =AS13 -> 0 | AT14: =AS14-AR14 -> 0 | AU14: =AV13 -> 0 | AW14: =AV14-AU14 -> 0 | AX14: =AY13 -> 0 | AZ14: =AY14-AX14 -> 0 | BA14: =BB13 -> 0 | BC14: =BB14-BA14 -> 0 | BD14: =BE13 -> 0 | BF14: =BE14-BD14 -> 0 | BG14: =BH13 -> 0 | BI14: =BH14-BG14 -> 0 | BJ14: =BK13 -> 0 | BL14: =BK14-BJ14 -> 0 | BM14: =BN13 -> 0 | BO14: =BN14-BM14 -> 0 | BP14: =BQ13 -> 0 | BR14: =BQ14-BP14 -> 0 | BS14: =BT13 -> 0 | BU14: =BT14-BS14 -> 0 | BV14: =BW13 -> 0 | BX14: =BW14-BV14 -> 0 | BY14: =BZ13 -> 0 | CA14: =BZ14-BY14 -> 0 | CB14: =CC13 -> 0 | CD14: =CC14-CB14 -> 0 | CE14: =CF13 -> 0 | CG14: =CF14-CE14 -> 0 | CH14: =CI13 -> 0 | CJ14: =CI14-CH14 -> 0 | CK14: =CL13 -> 0 | CM14: =CL14-CK14 -> 0 | CN14: =CO13 -> 0 | CP14: =CO14-CN14 -> 0
A15: 7 | B15: =C14 -> 0 | D15: =C15-B15 -> 0 | E15: =F14 -> 0 | G15: =F15-E15 -> 0 | H15: =I14 -> 0 | J15: =I15-H15 -> 0 | K15: =L14 -> 0 | M15: =L15-K15 -> 0 | N15: =O14 -> 0 | P15: =O15-N15 -> 0 | Q15: =R14 -> 0 | S15: =R15-Q15 -> 0 | T15: =U14 -> 0 | V15: =U15-T15 -> 0 | W15: =X14 -> 0 | Y15: =X15-W15 -> 0 | Z15: =AA14 -> 0 | AB15: =AA15-Z15 -> 0 | AC15: =AD14 -> 0 | AE15: =AD15-AC15 -> 0 | AF15: =AG14 -> 0 | AH15: =AG15-AF15 -> 0 | AI15: =AJ14 -> 0 | AK15: =AJ15-AI15 -> 0 | AL15: =AM14 -> 0 | AN15: =AM15-AL15 -> 0 | AO15: =AP14 -> 0 | AQ15: =AP15-AO15 -> 0 | AR15: =AS14 -> 0 | AT15: =AS15-AR15 -> 0 | AU15: =AV14 -> 0 | AW15: =AV15-AU15 -> 0 | AX15: =AY14 -> 0 | AZ15: =AY15-AX15 -> 0 | BA15: =BB14 -> 0 | BC15: =BB15-BA15 -> 0 | BD15: =BE14 -> 0 | BF15: =BE15-BD15 -> 0 | BG15: =BH14 -> 0 | BI15: =BH15-BG15 -> 0 | BJ15: =BK14 -> 0 | BL15: =BK15-BJ15 -> 0 | BM15: =BN14 -> 0 | BO15: =BN15-BM15 -> 0 | BP15: =BQ14 -> 0 | BR15: =BQ15-BP15 -> 0 | BS15: =BT14 -> 0 | BU15: =BT15-BS15 -> 0 | BV15: =BW14 -> 0 | BX15: =BW15-BV15 -> 0 | BY15: =BZ14 -> 0 | CA15: =BZ15-BY15 -> 0 | CB15: =CC14 -> 0 | CD15: =CC15-CB15 -> 0 | CE15: =CF14 -> 0 | CG15: =CF15-CE15 -> 0 | CH15: =CI14 -> 0 | CJ15: =CI15-CH15 -> 0 | CK15: =CL14 -> 0 | CM15: =CL15-CK15 -> 0 | CN15: =CO14 -> 0 | CP15: =CO15-CN15 -> 0
A16: 8 | B16: =C15 -> 0 | D16: =C16-B16 -> 0 | E16: =F15 -> 0 | G16: =F16-E16 -> 0 | H16: =I15 -> 0 | J16: =I16-H16 -> 0 | K16: =L15 -> 0 | M16: =L16-K16 -> 0 | N16: =O15 -> 0 | P16: =O16-N16 -> 0 | Q16: =R15 -> 0 | S16: =R16-Q16 -> 0 | T16: =U15 -> 0 | V16: =U16-T16 -> 0 | W16: =X15 -> 0 | Y16: =X16-W16 -> 0 | Z16: =AA15 -> 0 | AB16: =AA16-Z16 -> 0 | AC16: =AD15 -> 0 | AE16: =AD16-AC16 -> 0 | AF16: =AG15 -> 0 | AH16: =AG16-AF16 -> 0 | AI16: =AJ15 -> 0 | AK16: =AJ16-AI16 -> 0 | AL16: =AM15 -> 0 | AN16: =AM16-AL16 -> 0 | AO16: =AP15 -> 0 | AQ16: =AP16-AO16 -> 0 | AR16: =AS15 -> 0 | AT16: =AS16-AR16 -> 0 | AU16: =AV15 -> 0 | AW16: =AV16-AU16 -> 0 | AX16: =AY15 -> 0 | AZ16: =AY16-AX16 -> 0 | BA16: =BB15 -> 0 | BC16: =BB16-BA16 -> 0 | BD16: =BE15 -> 0 | BF16: =BE16-BD16 -> 0 | BG16: =BH15 -> 0 | BI16: =BH16-BG16 -> 0 | BJ16: =BK15 -> 0 | BL16: =BK16-BJ16 -> 0 | BM16: =BN15 -> 0 | BO16: =BN16-BM16 -> 0 | BP16: =BQ15 -> 0 | BR16: =BQ16-BP16 -> 0 | BS16: =BT15 -> 0 | BU16: =BT16-BS16 -> 0 | BV16: =BW15 -> 0 | BX16: =BW16-BV16 -> 0 | BY16: =BZ15 -> 0 | CA16: =BZ16-BY16 -> 0 | CB16: =CC15 -> 0 | CD16: =CC16-CB16 -> 0 | CE16: =CF15 -> 0 | CG16: =CF16-CE16 -> 0 | CH16: =CI15 -> 0 | CJ16: =CI16-CH16 -> 0 | CK16: =CL15 -> 0 | CM16: =CL16-CK16 -> 0 | CN16: =CO15 -> 0 | CP16: =CO16-CN16 -> 0
A17: 9 | B17: =C16 -> 0 | D17: =C17-B17 -> 0 | E17: =F16 -> 0 | G17: =F17-E17 -> 0 | H17: =I16 -> 0 | J17: =I17-H17 -> 0 | K17: =L16 -> 0 | M17: =L17-K17 -> 0 | N17: =O16 -> 0 | P17: =O17-N17 -> 0 | Q17: =R16 -> 0 | S17: =R17-Q17 -> 0 | T17: =U16 -> 0 | V17: =U17-T17 -> 0 | W17: =X16 -> 0 | Y17: =X17-W17 -> 0 | Z17: =AA16 -> 0 | AB17: =AA17-Z17 -> 0 | AC17: =AD16 -> 0 | AE17: =AD17-AC17 -> 0 | AF17: =AG16 -> 0 | AH17: =AG17-AF17 -> 0 | AI17: =AJ16 -> 0 | AK17: =AJ17-AI17 -> 0 | AL17: =AM16 -> 0 | AN17: =AM17-AL17 -> 0 | AO17: =AP16 -> 0 | AQ17: =AP17-AO17 -> 0 | AR17: =AS16 -> 0 | AT17: =AS17-AR17 -> 0 | AU17: =AV16 -> 0 | AW17: =AV17-AU17 -> 0 | AX17: =AY16 -> 0 | AZ17: =AY17-AX17 -> 0 | BA17: =BB16 -> 0 | BC17: =BB17-BA17 -> 0 | BD17: =BE16 -> 0 | BF17: =BE17-BD17 -> 0 | BG17: =BH16 -> 0 | BI17: =BH17-BG17 -> 0 | BJ17: =BK16 -> 0 | BL17: =BK17-BJ17 -> 0 | BM17: =BN16 -> 0 | BO17: =BN17-BM17 -> 0 | BP17: =BQ16 -> 0 | BR17: =BQ17-BP17 -> 0 | BS17: =BT16 -> 0 | BU17: =BT17-BS17 -> 0 | BV17: =BW16 -> 0 | BX17: =BW17-BV17 -> 0 | BY17: =BZ16 -> 0 | CA17: =BZ17-BY17 -> 0 | CB17: =CC16 -> 0 | CD17: =CC17-CB17 -> 0 | CE17: =CF16 -> 0 | CG17: =CF17-CE17 -> 0 | CH17: =CI16 -> 0 | CJ17: =CI17-CH17 -> 0 | CK17: =CL16 -> 0 | CM17: =CL17-CK17 -> 0 | CN17: =CO16 -> 0 | CP17: =CO17-CN17 -> 0
A18: 10 | B18: =C17 -> 0 | D18: =C18-B18 -> 0 | E18: =F17 -> 0 | G18: =F18-E18 -> 0 | H18: =I17 -> 0 | J18: =I18-H18 -> 0 | K18: =L17 -> 0 | M18: =L18-K18 -> 0 | N18: =O17 -> 0 | P18: =O18-N18 -> 0 | Q18: =R17 -> 0 | S18: =R18-Q18 -> 0 | T18: =U17 -> 0 | V18: =U18-T18 -> 0 | W18: =X17 -> 0 | Y18: =X18-W18 -> 0 | Z18: =AA17 -> 0 | AB18: =AA18-Z18 -> 0 | AC18: =AD17 -> 0 | AE18: =AD18-AC18 -> 0 | AF18: =AG17 -> 0 | AH18: =AG18-AF18 -> 0 | AI18: =AJ17 -> 0 | AK18: =AJ18-AI18 -> 0 | AL18: =AM17 -> 0 | AN18: =AM18-AL18 -> 0 | AO18: =AP17 -> 0 | AQ18: =AP18-AO18 -> 0 | AR18: =AS17 -> 0 | AT18: =AS18-AR18 -> 0 | AU18: =AV17 -> 0 | AW18: =AV18-AU18 -> 0 | AX18: =AY17 -> 0 | AZ18: =AY18-AX18 -> 0 | BA18: =BB17 -> 0 | BC18: =BB18-BA18 -> 0 | BD18: =BE17 -> 0 | BF18: =BE18-BD18 -> 0 | BG18: =BH17 -> 0 | BI18: =BH18-BG18 -> 0 | BJ18: =BK17 -> 0 | BL18: =BK18-BJ18 -> 0 | BM18: =BN17 -> 0 | BO18: =BN18-BM18 -> 0 | BP18: =BQ17 -> 0 | BR18: =BQ18-BP18 -> 0 | BS18: =BT17 -> 0 | BU18: =BT18-BS18 -> 0 | BV18: =BW17 -> 0 | BX18: =BW18-BV18 -> 0 | BY18: =BZ17 -> 0 | CA18: =BZ18-BY18 -> 0 | CB18: =CC17 -> 0 | CD18: =CC18-CB18 -> 0 | CE18: =CF17 -> 0 | CG18: =CF18-CE18 -> 0 | CH18: =CI17 -> 0 | CJ18: =CI18-CH18 -> 0 | CK18: =CL17 -> 0 | CM18: =CL18-CK18 -> 0 | CN18: =CO17 -> 0 | CP18: =CO18-CN18 -> 0
A19: 11 | B19: =C18 -> 0 | D19: =C19-B19 -> 0 | E19: =F18 -> 0 | G19: =F19-E19 -> 0 | H19: =I18 -> 0 | J19: =I19-H19 -> 0 | K19: =L18 -> 0 | M19: =L19-K19 -> 0 | N19: =O18 -> 0 | P19: =O19-N19 -> 0 | Q19: =R18 -> 0 | S19: =R19-Q19 -> 0 | T19: =U18 -> 0 | V19: =U19-T19 -> 0 | W19: =X18 -> 0 | Y19: =X19-W19 -> 0 | Z19: =AA18 -> 0 | AB19: =AA19-Z19 -> 0 | AC19: =AD18 -> 0 | AE19: =AD19-AC19 -> 0 | AF19: =AG18 -> 0 | AH19: =AG19-AF19 -> 0 | AI19: =AJ18 -> 0 | AK19: =AJ19-AI19 -> 0 | AL19: =AM18 -> 0 | AN19: =AM19-AL19 -> 0 | AO19: =AP18 -> 0 | AQ19: =AP19-AO19 -> 0 | AR19: =AS18 -> 0 | AT19: =AS19-AR19 -> 0 | AU19: =AV18 -> 0 | AW19: =AV19-AU19 -> 0 | AX19: =AY18 -> 0 | AZ19: =AY19-AX19 -> 0 | BA19: =BB18 -> 0 | BC19: =BB19-BA19 -> 0 | BD19: =BE18 -> 0 | BF19: =BE19-BD19 -> 0 | BG19: =BH18 -> 0 | BI19: =BH19-BG19 -> 0 | BJ19: =BK18 -> 0 | BL19: =BK19-BJ19 -> 0 | BM19: =BN18 -> 0 | BO19: =BN19-BM19 -> 0 | BP19: =BQ18 -> 0 | BR19: =BQ19-BP19 -> 0 | BS19: =BT18 -> 0 | BU19: =BT19-BS19 -> 0 | BV19: =BW18 -> 0 | BX19: =BW19-BV19 -> 0 | BY19: =BZ18 -> 0 | CA19: =BZ19-BY19 -> 0 | CB19: =CC18 -> 0 | CD19: =CC19-CB19 -> 0 | CE19: =CF18 -> 0 | CG19: =CF19-CE19 -> 0 | CH19: =CI18 -> 0 | CJ19: =CI19-CH19 -> 0 | CK19: =CL18 -> 0 | CM19: =CL19-CK19 -> 0 | CN19: =CO18 -> 0 | CP19: =CO19-CN19 -> 0
A20: 12 | B20: =C19 -> 0 | D20: =C20-B20 -> 0 | E20: =F19 -> 0 | G20: =F20-E20 -> 0 | H20: =I19 -> 0 | J20: =I20-H20 -> 0 | K20: =L19 -> 0 | M20: =L20-K20 -> 0 | N20: =O19 -> 0 | P20: =O20-N20 -> 0 | Q20: =R19 -> 0 | S20: =R20-Q20 -> 0 | T20: =U19 -> 0 | V20: =U20-T20 -> 0 | W20: =X19 -> 0 | Y20: =X20-W20 -> 0 | Z20: =AA19 -> 0 | AB20: =AA20-Z20 -> 0 | AC20: =AD19 -> 0 | AE20: =AD20-AC20 -> 0 | AF20: =AG19 -> 0 | AH20: =AG20-AF20 -> 0 | AI20: =AJ19 -> 0 | AK20: =AJ20-AI20 -> 0 | AL20: =AM19 -> 0 | AN20: =AM20-AL20 -> 0 | AO20: =AP19 -> 0 | AQ20: =AP20-AO20 -> 0 | AR20: =AS19 -> 0 | AT20: =AS20-AR20 -> 0 | AU20: =AV19 -> 0 | AW20: =AV20-AU20 -> 0 | AX20: =AY19 -> 0 | AZ20: =AY20-AX20 -> 0 | BA20: =BB19 -> 0 | BC20: =BB20-BA20 -> 0 | BD20: =BE19 -> 0 | BF20: =BE20-BD20 -> 0 | BG20: =BH19 -> 0 | BI20: =BH20-BG20 -> 0 | BJ20: =BK19 -> 0 | BL20: =BK20-BJ20 -> 0 | BM20: =BN19 -> 0 | BO20: =BN20-BM20 -> 0 | BP20: =BQ19 -> 0 | BR20: =BQ20-BP20 -> 0 | BS20: =BT19 -> 0 | BU20: =BT20-BS20 -> 0 | BV20: =BW19 -> 0 | BX20: =BW20-BV20 -> 0 | BY20: =BZ19 -> 0 | CA20: =BZ20-BY20 -> 0 | CB20: =CC19 -> 0 | CD20: =CC20-CB20 -> 0 | CE20: =CF19 -> 0 | CG20: =CF20-CE20 -> 0 | CH20: =CI19 -> 0 | CJ20: =CI20-CH20 -> 0 | CK20: =CL19 -> 0 | CM20: =CL20-CK20 -> 0 | CN20: =CO19 -> 0 | CP20: =CO20-CN20 -> 0
A21: 13 | B21: =C20 -> 0 | D21: =C21-B21 -> 0 | E21: =F20 -> 0 | G21: =F21-E21 -> 0 | H21: =I20 -> 0 | J21: =I21-H21 -> 0 | K21: =L20 -> 0 | M21: =L21-K21 -> 0 | N21: =O20 -> 0 | P21: =O21-N21 -> 0 | Q21: =R20 -> 0 | S21: =R21-Q21 -> 0 | T21: =U20 -> 0 | V21: =U21-T21 -> 0 | W21: =X20 -> 0 | Y21: =X21-W21 -> 0 | Z21: =AA20 -> 0 | AB21: =AA21-Z21 -> 0 | AC21: =AD20 -> 0 | AE21: =AD21-AC21 -> 0 | AF21: =AG20 -> 0 | AH21: =AG21-AF21 -> 0 | AI21: =AJ20 -> 0 | AK21: =AJ21-AI21 -> 0 | AL21: =AM20 -> 0 | AN21: =AM21-AL21 -> 0 | AO21: =AP20 -> 0 | AQ21: =AP21-AO21 -> 0 | AR21: =AS20 -> 0 | AT21: =AS21-AR21 -> 0 | AU21: =AV20 -> 0 | AW21: =AV21-AU21 -> 0 | AX21: =AY20 -> 0 | AZ21: =AY21-AX21 -> 0 | BA21: =BB20 -> 0 | BC21: =BB21-BA21 -> 0 | BD21: =BE20 -> 0 | BF21: =BE21-BD21 -> 0 | BG21: =BH20 -> 0 | BI21: =BH21-BG21 -> 0 | BJ21: =BK20 -> 0 | BL21: =BK21-BJ21 -> 0 | BM21: =BN20 -> 0 | BO21: =BN21-BM21 -> 0 | BP21: =BQ20 -> 0 | BR21: =BQ21-BP21 -> 0 | BS21: =BT20 -> 0 | BU21: =BT21-BS21 -> 0 | BV21: =BW20 -> 0 | BX21: =BW21-BV21 -> 0 | BY21: =BZ20 -> 0 | CA21: =BZ21-BY21 -> 0 | CB21: =CC20 -> 0 | CD21: =CC21-CB21 -> 0 | CE21: =CF20 -> 0 | CG21: =CF21-CE21 -> 0 | CH21: =CI20 -> 0 | CJ21: =CI21-CH21 -> 0 | CK21: =CL20 -> 0 | CM21: =CL21-CK21 -> 0 | CN21: =CO20 -> 0 | CP21: =CO21-CN21 -> 0
A22: 14 | B22: =C21 -> 0 | D22: =C22-B22 -> 0 | E22: =F21 -> 0 | G22: =F22-E22 -> 0 | H22: =I21 -> 0 | J22: =I22-H22 -> 0 | K22: =L21 -> 0 | M22: =L22-K22 -> 0 | N22: =O21 -> 0 | P22: =O22-N22 -> 0 | Q22: =R21 -> 0 | S22: =R22-Q22 -> 0 | T22: =U21 -> 0 | V22: =U22-T22 -> 0 | W22: =X21 -> 0 | Y22: =X22-W22 -> 0 | Z22: =AA21 -> 0 | AB22: =AA22-Z22 -> 0 | AC22: =AD21 -> 0 | AE22: =AD22-AC22 -> 0 | AF22: =AG21 -> 0 | AH22: =AG22-AF22 -> 0 | AI22: =AJ21 -> 0 | AK22: =AJ22-AI22 -> 0 | AL22: =AM21 -> 0 | AN22: =AM22-AL22 -> 0 | AO22: =AP21 -> 0 | AQ22: =AP22-AO22 -> 0 | AR22: =AS21 -> 0 | AT22: =AS22-AR22 -> 0 | AU22: =AV21 -> 0 | AW22: =AV22-AU22 -> 0 | AX22: =AY21 -> 0 | AZ22: =AY22-AX22 -> 0 | BA22: =BB21 -> 0 | BC22: =BB22-BA22 -> 0 | BD22: =BE21 -> 0 | BF22: =BE22-BD22 -> 0 | BG22: =BH21 -> 0 | BI22: =BH22-BG22 -> 0 | BJ22: =BK21 -> 0 | BL22: =BK22-BJ22 -> 0 | BM22: =BN21 -> 0 | BO22: =BN22-BM22 -> 0 | BP22: =BQ21 -> 0 | BR22: =BQ22-BP22 -> 0 | BS22: =BT21 -> 0 | BU22: =BT22-BS22 -> 0 | BV22: =BW21 -> 0 | BX22: =BW22-BV22 -> 0 | BY22: =BZ21 -> 0 | CA22: =BZ22-BY22 -> 0 | CB22: =CC21 -> 0 | CD22: =CC22-CB22 -> 0 | CE22: =CF21 -> 0 | CG22: =CF22-CE22 -> 0 | CH22: =CI21 -> 0 | CJ22: =CI22-CH22 -> 0 | CK22: =CL21 -> 0 | CM22: =CL22-CK22 -> 0 | CN22: =CO21 -> 0 | CP22: =CO22-CN22 -> 0
... A38: 30 | B38: =C37 -> 0 | D38: =C38-B38 -> 0 | E38: =F37 -> 0 | G38: =F38-E38 -> 0 | H38: =I37 -> 0 | J38: =I38-H38 -> 0 | K38: =L37 -> 0 | M38: =L38-K38 -> 0 | N38: =O37 -> 0 | P38: =O38-N38 -> 0 | Q38: =R37 -> 0 | S38: =R38-Q38 -> 0 | T38: =U37 -> 0 | V38: =U38-T38 -> 0 | W38: =X37 -> 0 | Y38: =X38-W38 -> 0 | Z38: =AA37 -> 0 | AB38: =AA38-Z38 -> 0 | AC38: =AD37 -> 0 | AE38: =AD38-AC38 -> 0 | AF38: =AG37 -> 0 | AH38: =AG38-AF38 -> 0 | AI38: =AJ37 -> 0 | AK38: =AJ38-AI38 -> 0 | AL38: =AM37 -> 0 | AN38: =AM38-AL38 -> 0 | AO38: =AP37 -> 0 | AQ38: =AP38-AO38 -> 0 | AR38: =AS37 -> 0 | AT38: =AS38-AR38 -> 0 | AU38: =AV37 -> 0 | AW38: =AV38-AU38 -> 0 | AX38: =AY37 -> 0 | AZ38: =AY38-AX38 -> 0 | BA38: =BB37 -> 0 | BC38: =BB38-BA38 -> 0 | BD38: =BE37 -> 0 | BF38: =BE38-BD38 -> 0 | BG38: =BH37 -> 0 | BI38: =BH38-BG38 -> 0 | BJ38: =BK37 -> 0 | BL38: =BK38-BJ38 -> 0 | BM38: =BN37 -> 0 | BO38: =BN38-BM38 -> 0 | BP38: =BQ37 -> 0 | BR38: =BQ38-BP38 -> 0 | BS38: =BT37 -> 0 | BU38: =BT38-BS38 -> 0 | BV38: =BW37 -> 0 | BX38: =BW38-BV38 -> 0 | BY38: =BZ37 -> 0 | CA38: =BZ38-BY38 -> 0 | CB38: =CC37 -> 0 | CD38: =CC38-CB38 -> 0 | CE38: =CF37 -> 0 | CG38: =CF38-CE38 -> 0 | CH38: =CI37 -> 0 | CJ38: =CI38-CH38 -> 0 | CK38: =CL37 -> 0 | CM38: =CL38-CK38 -> 0 | CN38: =CO37 -> 0 | CP38: =CO38-CN38 -> 0
A39: 31 | B39: =C38 -> 0 | D39: =C39-B39 -> 0 | E39: =F38 -> 0 | G39: =F39-E39 -> 0 | H39: =I38 -> 0 | J39: =I39-H39 -> 0 | K39: =L38 -> 0 | M39: =L39-K39 -> 0 | N39: =O38 -> 0 | P39: =O39-N39 -> 0 | Q39: =R38 -> 0 | S39: =R39-Q39 -> 0 | T39: =U38 -> 0 | V39: =U39-T39 -> 0 | W39: =X38 -> 0 | Y39: =X39-W39 -> 0 | Z39: =AA38 -> 0 | AB39: =AA39-Z39 -> 0 | AC39: =AD38 -> 0 | AE39: =AD39-AC39 -> 0 | AF39: =AG38 -> 0 | AH39: =AG39-AF39 -> 0 | AI39: =AJ38 -> 0 | AK39: =AJ39-AI39 -> 0 | AL39: =AM38 -> 0 | AN39: =AM39-AL39 -> 0 | AO39: =AP38 -> 0 | AQ39: =AP39-AO39 -> 0 | AR39: =AS38 -> 0 | AT39: =AS39-AR39 -> 0 | AU39: =AV38 -> 0 | AW39: =AV39-AU39 -> 0 | AX39: =AY38 -> 0 | AZ39: =AY39-AX39 -> 0 | BA39: =BB38 -> 0 | BC39: =BB39-BA39 -> 0 | BD39: =BE38 -> 0 | BF39: =BE39-BD39 -> 0 | BG39: =BH38 -> 0 | BI39: =BH39-BG39 -> 0 | BJ39: =BK38 -> 0 | BL39: =BK39-BJ39 -> 0 | BM39: =BN38 -> 0 | BP39: =BQ38 -> 0 | BR39: =BQ39-BP39 -> 0 | BS39: =BT38 -> 0 | BU39: =BT39-BS39 -> 0 | BV39: =BW38 -> 0 | BX39: =BW39-BV39 -> 0 | BY39: =BZ38 -> 0 | CA39: =BZ39-BY39 -> 0 | CB39: =CC38 -> 0 | CD39: =CC39-CB39 -> 0 | CE39: =CF38 -> 0 | CG39: =CF39-CE39 -> 0 | CH39: =CI38 -> 0 | CJ39: =CI39-CH39 -> 0 | CK39: =CL38 -> 0 | CM39: =CL39-CK39 -> 0 | CN39: =CO38 -> 0 | CP39: =CO39-CN39 -> 0
A40: Total | D40: =SUM(D9:D39) -> -25088084 | G40: =SUM(G9:G39) -> -21981188 | J40: =SUM(J9:J39) -> -83718230 | M40: =SUM(M9:M39) -> -1722220 | P40: =SUM(P9:P39) -> -2330923 | S40: =SUM(S9:S39) -> -1403900 | V40: =SUM(V9:V39) -> -659727 | Y40: =SUM(Y9:Y39) -> -6827800 | AB40: =SUM(AB9:AB39) -> -1485900 | AE40: =SUM(AE9:AE39) -> -443008 | AH40: =SUM(AH9:AH39) -> -312460 | AK40: =SUM(AK9:AK39) -> -522300 | AN40: =SUM(AN9:AN39) -> -971190 | AQ40: =SUM(AQ9:AQ39) -> -617560 | AT40: =SUM(AT9:AT39) -> -455500 | AW40: =SUM(AW9:AW39) -> -398160 | AZ40: =SUM(AZ9:AZ39) -> -313610 | BC40: =SUM(BC9:BC39) -> -838750 | BF40: =SUM(BF9:BF39) -> -16414 | BI40: =SUM(BI9:BI39) -> -13337 | BL40: =SUM(BL9:BL39) -> -12664 | BO40: =SUM(BO9:BO39) -> -20408 | BR40: =SUM(BR9:BR39) -> -13725 | BU40: =SUM(BU9:BU39) -> -15869 | BX40: =SUM(BX9:BX39) -> -10596 | CA40: =SUM(CA9:CA39) -> -27031 | CD40: =SUM(CD9:CD39) -> -22769 | CG40: =SUM(CG9:CG39) -> -65938 | CJ40: =SUM(CJ9:CJ39) -> -33060 | CM40: =SUM(CM9:CM39) -> -10817 | CP40: =SUM(CP9:CP39) -> -38022

Sheet Focus Data
B4: 44201
A7: FS LANDAA GIRAAVARU
A8: Month-Feb- 17 | B8: Electricity (KWh) | C8: Diesel (Ltrs) | D8: Solar Power (KWh) | E8: Gas | F8: Water | G8: Resort Occupancy % | H8: Gen Avg | I8: Total Kwh
A9: 1 | B9: =SUM('GENSET #1:GENSET #5'!D10) -> 30450 | C9: ='Diesel consumption'!D5 -> 8440 | D9: ='SOLAR METER READING'!D9 -> 560 | E9: ='Gas-2'!G6 -> 225 | F9: =WATER!B7 -> 368 | G9: =WATER!C7 -> 97.09 | H9: =B9/C9 -> 3.6078199 | I9: =SUM(B9,D9) -> 31010
A10: 2 | B10: =SUM('GENSET #1:GENSET #5'!D11) -> 29767 | C10: ='Diesel consumption'!D6 -> 8080 | D10: ='SOLAR METER READING'!D10 -> 2728 | E10: ='Gas-2'!G7 -> 90 | F10: =WATER!B8 -> 393 | G10: =WATER!C8 -> 95.15 | H10: =B10/C10 -> 3.6840347 | I10: =SUM(B10,D10) -> 32495
A11: 3 | B11: =SUM('GENSET #1:GENSET #5'!D12) -> 29515 | C11: ='Diesel consumption'!D7 -> -42894120 | D11: ='SOLAR METER READING'!D11 -> -2251605 | E11: ='Gas-2'!G8 -> 180 | F11: =WATER!B9 -> 0 | G11: =WATER!C9 -> 0 | H11: =B11/C11 -> -0.00068808965 | I11: =SUM(B11,D11) -> -2222090
A12: 4 | B12: =SUM('GENSET #1:GENSET #5'!D13) -> 31514 | C12: ='Diesel consumption'!D8 -> 0 | D12: ='SOLAR METER READING'!D12 -> 0 | E12: ='Gas-2'!G9 -> 270 | F12: =WATER!B10 -> 0 | G12: =WATER!C10 -> 0 | H12: =B12/C12 -> #DIV/0! | I12: =SUM(B12,D12) -> 31514
A13: 5 | B13: =SUM('GENSET #1:GENSET #5'!D14) -> -86185696 | C13: ='Diesel consumption'!D9 -> 0 | D13: ='SOLAR METER READING'!D13 -> 0 | E13: ='Gas-2'!G10 -> 0 | F13: =WATER!B11 -> 0 | G13: =WATER!C11 -> 0 | H13: =B13/C13 -> #DIV/0! | I13: =SUM(B13,D13) -> -86185696
A14: 6 | B14: =SUM('GENSET #1:GENSET #5'!D15) -> 0 | C14: ='Diesel consumption'!D10 -> 0 | D14: ='SOLAR METER READING'!D14 -> 0 | E14: ='Gas-2'!G11 -> 0 | F14: =WATER!B12 -> 0 | G14: =WATER!C12 -> 0 | H14: =B14/C14 -> #DIV/0! | I14: =SUM(B14,D14) -> 0
A15: 7 | B15: =SUM('GENSET #1:GENSET #5'!D16) -> 0 | C15: ='Diesel consumption'!D11 -> 0 | D15: ='SOLAR METER READING'!D15 -> 0 | E15: ='Gas-2'!G12 -> 0 | F15: =WATER!B13 -> 0 | G15: =WATER!C13 -> 0 | H15: =B15/C15 -> #DIV/0! | I15: =SUM(B15,D15) -> 0
A16: 8 | B16: =SUM('GENSET #1:GENSET #5'!D17) -> 0 | C16: ='Diesel consumption'!D12 -> 0 | D16: ='SOLAR METER READING'!D16 -> 0 | E16: ='Gas-2'!G13 -> 0 | F16: =WATER!B14 -> 0 | G16: =WATER!C14 -> 0 | H16: =B16/C16 -> #DIV/0! | I16: =SUM(B16,D16) -> 0
A17: 9 | B17: =SUM('GENSET #1:GENSET #5'!D18) -> 0 | C17: ='Diesel consumption'!D13 -> 0 | D17: ='SOLAR METER READING'!D17 -> 0 | E17: ='Gas-2'!G14 -> 0 | F17: =WATER!B15 -> 0 | G17: =WATER!C15 -> 0 | H17: =B17/C17 -> #DIV/0! | I17: =SUM(B17,D17) -> 0
A18: 10 | B18: =SUM('GENSET #1:GENSET #5'!D19) -> 0 | C18: ='Diesel consumption'!D14 -> 0 | D18: ='SOLAR METER READING'!D18 -> 0 | E18: ='Gas-2'!G15 -> 0 | F18: =WATER!B16 -> 0 | G18: =WATER!C16 -> 0 | H18: =B18/C18 -> #DIV/0! | I18: =SUM(B18,D18) -> 0
A19: 11 | B19: =SUM('GENSET #1:GENSET #5'!D20) -> 0 | C19: ='Diesel consumption'!D15 -> 0 | D19: ='SOLAR METER READING'!D19 -> 0 | E19: ='Gas-2'!G16 -> 0 | F19: =WATER!B17 -> 0 | G19: =WATER!C17 -> 0 | H19: =B19/C19 -> #DIV/0! | I19: =SUM(B19,D19) -> 0
A20: 12 | B20: =SUM('GENSET #1:GENSET #5'!D21) -> 0 | C20: ='Diesel consumption'!D16 -> 0 | D20: ='SOLAR METER READING'!D20 -> 0 | E20: ='Gas-2'!G17 -> 0 | F20: =WATER!B18 -> 0 | G20: =WATER!C18 -> 0 | H20: =B20/C20 -> #DIV/0! | I20: =SUM(B20,D20) -> 0
... A36: 28 | B36: =SUM('GENSET #1:GENSET #5'!D37) -> 0 | C36: ='Diesel consumption'!D32 -> 0 | D36: ='SOLAR METER READING'!D36 -> 0 | E36: ='Gas-2'!G33 -> 0 | F36: =WATER!B34 -> 0 | G36: =WATER!C34 -> 0 | H36: =B36/C36 -> #DIV/0! | I36: =SUM(B36,D36) -> 0
A37: 29 | B37: =SUM('GENSET #1:GENSET #5'!D38) -> 0 | C37: ='Diesel consumption'!D33 -> 0 | D37: ='SOLAR METER READING'!D37 -> 0 | E37: ='Gas-2'!G34 -> 0 | F37: =WATER!B36 -> 0 | G37: =WATER!C35 -> 0 | H37: =B37/C37 -> #DIV/0! | I37: =SUM(B37,D37) -> 0
A38: 30 | B38: =SUM('GENSET #1:GENSET #5'!D39) -> 0 | C38: ='Diesel consumption'!D34 -> 0 | D38: ='SOLAR METER READING'!D38 -> 0 | E38: ='Gas-2'!G36 -> 0 | F38: =WATER!#REF! -> #REF! | G38: =WATER!C36 -> 0 | H38: =B38/C38 -> #DIV/0! | I38: =SUM(B38,D38) -> 0
A39: 31 | B39: =SUM('GENSET #1:GENSET #5'!D40) -> 0 | C39: ='Diesel consumption'!#REF! -> #REF! | D39: ='SOLAR METER READING'!#REF! -> #REF! | E39: ='Gas-2'!#REF! -> #REF! | G39: =WATER!#REF! -> #REF!
A40: Total | B40: =SUM(B9:B39) -> -86064450 | C40: =SUM(C9:C39) -> #REF! | D40: =SUM(D9:D39) -> #REF! | E40: =SUM(E9:E39) -> #REF! | F40: =SUM(F9:F39) -> #REF! | I40: =SUM(B40,D40) -> #REF!

Sheet WATER VILLA PRJECT
A1: 44170
A2: Total Kwh Consumption For Water Villa Project
A4: 1 | B4: ='FEEDER Consumption '!AT9+'FEEDER Consumption '!BI9+'FEEDER Consumption '!BL9+'FEEDER Consumption '!BO9+'FEEDER Consumption '!BR9+'FEEDER Consumption '!BU9 -> 328 | C4: Kwh
A5: 2 | B5: ='FEEDER Consumption '!AT10+'FEEDER Consumption '!BI10+'FEEDER Consumption '!BL10+'FEEDER Consumption '!BO10+'FEEDER Consumption '!BR10+'FEEDER Consumption '!BU10 -> 910 | C5: Kwh
A6: 3 | B6: ='FEEDER Consumption '!AT11+'FEEDER Consumption '!BI11+'FEEDER Consumption '!BL11+'FEEDER Consumption '!BO11+'FEEDER Consumption '!BR11+'FEEDER Consumption '!BU11 -> -532741 | C6: Kwh
A7: 4 | B7: ='FEEDER Consumption '!AT12+'FEEDER Consumption '!BI12+'FEEDER Consumption '!BL12+'FEEDER Consumption '!BO12+'FEEDER Consumption '!BR12+'FEEDER Consumption '!BU12 -> 0 | C7: Kwh
A8: 5 | B8: ='FEEDER Consumption '!AT13+'FEEDER Consumption '!BI13+'FEEDER Consumption '!BL13+'FEEDER Consumption '!BO13+'FEEDER Consumption '!BR13+'FEEDER Consumption '!BU13 -> 0 | C8: Kwh
A9: 6 | B9: ='FEEDER Consumption '!AT14+'FEEDER Consumption '!BI14+'FEEDER Consumption '!BL14+'FEEDER Consumption '!BO14+'FEEDER Consumption '!BR14+'FEEDER Consumption '!BU14 -> 0 | C9: Kwh
A10: 7 | B10: ='FEEDER Consumption '!AT15+'FEEDER Consumption '!BI15+'FEEDER Consumption '!BL15+'FEEDER Consumption '!BO15+'FEEDER Consumption '!BR15+'FEEDER Consumption '!BU15 -> 0 | C10: Kwh
A11: 8 | B11: ='FEEDER Consumption '!AT16+'FEEDER Consumption '!BI16+'FEEDER Consumption '!BL16+'FEEDER Consumption '!BO16+'FEEDER Consumption '!BR16+'FEEDER Consumption '!BU16 -> 0 | C11: Kwh
A12: 9 | B12: ='FEEDER Consumption '!AT17+'FEEDER Consumption '!BI17+'FEEDER Consumption '!BL17+'FEEDER Consumption '!BO17+'FEEDER Consumption '!BR17+'FEEDER Consumption '!BU17 -> 0 | C12: Kwh
A13: 10 | B13: ='FEEDER Consumption '!AT18+'FEEDER Consumption '!BI18+'FEEDER Consumption '!BL18+'FEEDER Consumption '!BO18+'FEEDER Consumption '!BR18+'FEEDER Consumption '!BU18 -> 0 | C13: Kwh
A14: 11 | B14: ='FEEDER Consumption '!AT19+'FEEDER Consumption '!BI19+'FEEDER Consumption '!BL19+'FEEDER Consumption '!BO19+'FEEDER Consumption '!BR19+'FEEDER Consumption '!BU19 -> 0 | C14: Kwh
A15: 12 | B15: ='FEEDER Consumption '!AT20+'FEEDER Consumption '!BI20+'FEEDER Consumption '!BL20+'FEEDER Consumption '!BO20+'FEEDER Consumption '!BR20+'FEEDER Consumption '!BU20 -> 0 | C15: Kwh
... A33: 30 | B33: ='FEEDER Consumption '!AT38+'FEEDER Consumption '!BI38+'FEEDER Consumption '!BL38+'FEEDER Consumption '!BO38+'FEEDER Consumption '!BR38+'FEEDER Consumption '!BU38 -> 0 | C33: Kwh
A34: Total | B34: ='FEEDER Consumption '!AT40+'FEEDER Consumption '!BI40+'FEEDER Consumption '!BL40+'FEEDER Consumption '!BO40+'FEEDER Consumption '!BR40+'FEEDER Consumption '!BU40 -> -531503 | C34: Kwh

Sheet FEEDER summry
B5: 44170
B7: BLU FEEDER PANEL1 | C7: BLU FEEDER PANEL 2 | D7: POWER HOUSE FEEDER PANEL NO:3 | E7: Main Kitchen -7 | F7: Main Kitchen -10 | G7: Water Treatment | H7: Sewage treatment Plant | I7: Laundry--8 | J7: Laundry -9 Power | K7: New staff accomodation | L7: Kitchen | M7: Laundry | N7: Plant | O7: Energy produce | P7: K% | Q7: L% | R7: P%
A8: DAY | B8: Consumption | C8: Consumption | D8: Consumption | E8: Consumption | F8: Consumption | G8: Consumption | H8: Consumption | I8: Consumption | J8: Consumption | K8: Consumption
A9: 1 | B9: ='FEEDER Consumption '!D9 -> 3696 | C9: ='FEEDER Consumption '!G9 -> 4179 | D9: ='FEEDER Consumption '!J9 -> 15480 | E9: ='FEEDER Consumption '!M9 -> 2280 | F9: ='FEEDER Consumption '!P9 -> 2738 | G9: ='FEEDER Consumption '!S9 -> 1900 | H9: ='FEEDER Consumption '!V9 -> 654 | I9: ='FEEDER Consumption '!Y9 -> 6300 | J9: ='FEEDER Consumption '!AB9 -> 3400 | K9: ='FEEDER Consumption '!AE9 -> 488 | L9: =SUM(E9:F9) -> 5018 | M9: =SUM(I9:J9) -> 9700 | N9: =SUM(G9:H9) -> 2554 | O9: ='Focus Data'!I9 -> 31010 | P9: =L9/O9% -> 16.181877 | Q9: =M9/O9% -> 31.280232 | R9: =N9/O9% -> 8.2360529
A10: 2 | B10: ='FEEDER Consumption '!D10 -> 3757 | C10: ='FEEDER Consumption '!G10 -> 4756 | D10: ='FEEDER Consumption '!J10 -> 13845 | E10: ='FEEDER Consumption '!M10 -> 2200 | F10: ='FEEDER Consumption '!P10 -> 2654 | G10: ='FEEDER Consumption '!S10 -> 2000 | H10: ='FEEDER Consumption '!V10 -> 717 | I10: ='FEEDER Consumption '!Y10 -> 6500 | J10: ='FEEDER Consumption '!AB10 -> 2900 | K10: ='FEEDER Consumption '!AE10 -> 428 | L10: =SUM(E10:F10) -> 4854 | M10: =SUM(I10:J10) -> 9400 | N10: =SUM(G10:H10) -> 2717 | O10: ='Focus Data'!I10 -> 32495 | P10: =L10/O10% -> 14.937683 | Q10: =M10/O10% -> 28.927527 | R10: =N10/O10% -> 8.3612864
A11: 3 | B11: ='FEEDER Consumption '!D11 -> -25095537 | C11: ='FEEDER Consumption '!G11 -> -21990123 | D11: ='FEEDER Consumption '!J11 -> -83747555 | E11: ='FEEDER Consumption '!M11 -> -1726700 | F11: ='FEEDER Consumption '!P11 -> -2336315 | G11: ='FEEDER Consumption '!S11 -> -1407800 | H11: ='FEEDER Consumption '!V11 -> -661098 | I11: ='FEEDER Consumption '!Y11 -> -6840600 | J11: ='FEEDER Consumption '!AB11 -> -1492200 | K11: ='FEEDER Consumption '!AE11 -> -443924 | L11: =SUM(E11:F11) -> -4063015 | M11: =SUM(I11:J11) -> -8332800 | N11: =SUM(G11:H11) -> -2068898 | O11: ='Focus Data'!I11 -> -2222090 | P11: =L11/O11% -> 182.84655 | Q11: =M11/O11% -> 374.99831 | R11: =N11/O11% -> 93.10595
A12: 4 | B12: ='FEEDER Consumption '!D12 -> 0 | C12: ='FEEDER Consumption '!G12 -> 0 | D12: ='FEEDER Consumption '!J12 -> 0 | E12: ='FEEDER Consumption '!M12 -> 0 | F12: ='FEEDER Consumption '!P12 -> 0 | G12: ='FEEDER Consumption '!S12 -> 0 | H12: ='FEEDER Consumption '!V12 -> 0 | I12: ='FEEDER Consumption '!Y12 -> 0 | J12: ='FEEDER Consumption '!AB12 -> 0 | K12: ='FEEDER Consumption '!AE12 -> 0 | L12: =SUM(E12:F12) -> 0 | M12: =SUM(I12:J12) -> 0 | N12: =SUM(G12:H12) -> 0 | O12: ='Focus Data'!I12 -> 31514 | P12: =L12/O12% -> 0 | Q12: =M12/O12% -> 0 | R12: =N12/O12% -> 0
