Workbook

Sheet TOTAL
A1: Site Name | B1: Day | C1: Month | D1: Year | E1: Total Electricity Kwh | F1: Electricity Tariff ($/Kwh) | G1: LPG (Kg) | H1: LPG $/Kg | I1: Water Utility Supply (m3) m3 | J1: Water Utility Supply (m3) $/m3 | K1: Room Nights | L1: Food Covers
A2: Maldives at Landaa Giraavaru | B2: 1 | C2: 1 | D2: 2021 | E2: ='Maldives at LG Daily'!D5 -> 30450 | F2: 0.93 | G2: ='Maldives at LG Daily'!F5 -> 0 | H2: 4.39 | I2: ='Maldives at LG Daily'!H5 -> 415 | J2: 1.72 | K2: ='Maldives at LG Daily'!I5 -> 103 | L2: ='Maldives at LG Daily'!J5 -> 878
A3: Maldives at Landaa Giraavaru | B3: =B2+1 -> 2 | C3: 1 | D3: 2021 | E3: ='Maldives at LG Daily'!D6 -> 29767 | F3: 0.93 | G3: ='Maldives at LG Daily'!F6 -> 270 | H3: 4.39 | I3: ='Maldives at LG Daily'!H6 -> 368 | J3: 1.72 | K3: ='Maldives at LG Daily'!I6 -> 98 | L3: ='Maldives at LG Daily'!J6 -> 865
A4: Maldives at Landaa Giraavaru | B4: =B3+1 -> 3 | C4: 1 | D4: 2021 | E4: ='Maldives at LG Daily'!D7 -> 29515 | F4: 0.93 | G4: ='Maldives at LG Daily'!F7 -> 0 | H4: 4.39 | I4: ='Maldives at LG Daily'!H7 -> 393 | J4: 1.72 | K4: ='Maldives at LG Daily'!I7 -> 101 | L4: ='Maldives at LG Daily'!J7 -> 915
A5: Maldives at Landaa Giraavaru | B5: =B4+1 -> 4 | C5: 1 | D5: 2021 | E5: ='Maldives at LG Daily'!D8 -> 31514 | F5: 0.93 | G5: ='Maldives at LG Daily'!F8 -> 0 | H5: 4.39 | I5: ='Maldives at LG Daily'!H8 -> 451 | J5: 1.72 | K5: ='Maldives at LG Daily'!I8 -> 96 | L5: ='Maldives at LG Daily'!J8 -> 861
A6: Maldives at Landaa Giraavaru | B6: =B5+1 -> 5 | C6: 1 | D6: 2021 | E6: ='Maldives at LG Daily'!D9 -> 29282 | F6: 0.93 | G6: ='Maldives at LG Daily'!F9 -> 0 | H6: 4.39 | I6: ='Maldives at LG Daily'!H9 -> 406 | J6: 1.72 | K6: ='Maldives at LG Daily'!I9 -> 0 | L6: ='Maldives at LG Daily'!J9 -> 0
A7: Maldives at Landaa Giraavaru | B7: =B6+1 -> 6 | C7: 1 | D7: 2021 | E7: ='Maldives at LG Daily'!D10 -> 0 | F7: 0.93 | G7: ='Maldives at LG Daily'!F10 -> 0 | H7: 4.39 | I7: ='Maldives at LG Daily'!H10 -> 356 | J7: 1.72 | K7: ='Maldives at LG Daily'!I10 -> 0 | L7: ='Maldives at LG Daily'!J10 -> 0
A8: Maldives at Landaa Giraavaru | B8: =B7+1 -> 7 | C8: 1 | D8: 2021 | E8: ='Maldives at LG Daily'!D11 -> 0 | F8: 0.93 | G8: ='Maldives at LG Daily'!F11 -> 0 | H8: 4.39 | I8: ='Maldives at LG Daily'!H11 -> 0 | J8: 1.72 | K8: ='Maldives at LG Daily'!I11 -> 0 | L8: ='Maldives at LG Daily'!J11 -> 0
A9: Maldives at Landaa Giraavaru | B9: =B8+1 -> 8 | C9: 1 | D9: 2021 | E9: ='Maldives at LG Daily'!D12 -> 0 | F9: 0.93 | G9: ='Maldives at LG Daily'!F12 -> 0 | H9: 4.39 | I9: ='Maldives at LG Daily'!H12 -> 0 | J9: 1.72 | K9: ='Maldives at LG Daily'!I12 -> 0 | L9: ='Maldives at LG Daily'!J12 -> 0
A10: Maldives at Landaa Giraavaru | B10: =B9+1 -> 9 | C10: 1 | D10: 2021 | E10: ='Maldives at LG Daily'!D13 -> 0 | F10: 0.93 | G10: ='Maldives at LG Daily'!F13 -> 0 | H10: 4.39 | I10: ='Maldives at LG Daily'!H13 -> 0 | J10: 1.72 | K10: ='Maldives at LG Daily'!I13 -> 0 | L10: ='Maldives at LG Daily'!J13 -> 0
A11: Maldives at Landaa Giraavaru | B11: =B10+1 -> 10 | C11: 1 | D11: 2021 | E11: ='Maldives at LG Daily'!D14 -> 0 | F11: 0.93 | G11: ='Maldives at LG Daily'!F14 -> 0 | H11: 4.39 | I11: ='Maldives at LG Daily'!H14 -> 0 | J11: 1.72 | K11: ='Maldives at LG Daily'!I14 -> 0 | L11: ='Maldives at LG Daily'!J14 -> 0
A12: Maldives at Landaa Giraavaru | B12: =B11+1 -> 11 | C12: 1 | D12: 2021 | E12: ='Maldives at LG Daily'!D15 -> 0 | F12: 0.93 | G12: ='Maldives at LG Daily'!F15 -> 0 | H12: 4.39 | I12: ='Maldives at LG Daily'!H15 -> 0 | J12: 1.72 | K12: ='Maldives at LG Daily'!I15 -> 0 | L12: ='Maldives at LG Daily'!J15 -> 0
A13: Maldives at Landaa Giraavaru | B13: =B12+1 -> 12 | C13: 1 | D13: 2021 | E13: ='Maldives at LG Daily'!D16 -> 0 | F13: 0.93 | G13: ='Maldives at LG Daily'!F16 -> 0 | H13: 4.39 | I13: ='Maldives at LG Daily'!H16 -> 0 | J13: 1.72 | K13: ='Maldives at LG Daily'!I16 -> 0 | L13: ='Maldives at LG Daily'!J16 -> 0
A14: Maldives at Landaa Giraavaru | B14: =B13+1 -> 13 | C14: 1 | D14: 2021 | E14: ='Maldives at LG Daily'!D17 -> 0 | F14: 0.93 | G14: ='Maldives at LG Daily'!F17 -> 0 | H14: 4.39 | I14: ='Maldives at LG Daily'!H17 -> 0 | J14: 1.72 | K14: ='Maldives at LG Daily'!I17 -> 0 | L14: ='Maldives at LG Daily'!J17 -> 0
... A32: Maldives at Landaa Giraavaru | B32: =B31+1 -> 31 | C32: 1 | D32: 2021 | E32: ='Maldives at LG Daily'!D35 -> 0 | F32: 0.93 | G32: ='Maldives at LG Daily'!F35 -> 0 | H32: 4.39 | I32: ='Maldives at LG Daily'!H35 -> 0 | J32: 1.72 | K32: ='Maldives at LG Daily'!I35 -> 0 | L32: ='Maldives at LG Daily'!J35 -> 0

Sheet Maldives at LG Daily
A2: Days | C2: Electricity Meter (KWh) | E2: Gas Kg | G2: Water m3
A3: Date | C3: Reading KWH | D3: Difference KWH | E3: Reading Kg | F3: Difference Kg | G3: Reading m³ | H3: Daily Consumption m³ | I3: ROOM NIGHTS | J3: TOTAL GUESTS
A4: 44196 | C4: =SUM('GENSET #1'!B10+'GENSET #2'!B10+'GENSET #3'!B10+'GENSET #4'!B10+'GENSET #5'!B10) -> 86064450 | E4: ='Gas-2'!G5 -> 225 | G4: =SUM(WATER!G6,WATER!L6,WATER!Q6,WATER!B6) -> 901297
A5: 44197 | C5: =SUM('GENSET #1'!B11+'GENSET #2'!B11+'GENSET #3'!B11+'GENSET #4'!B11+'GENSET #5'!B11) -> 86094900 | D5: =IF((C5-C4<0), "0",C5-C4) -> 30450 | E5: ='Gas-2'!G6 -> 135 | F5: =IF((E5-E4<0), "0",E5-E4) -> 0 | G5: =SUM(WATER!C6,WATER!H6,WATER!M6,WATER!R6) -> 901712 | H5: =IF((G5-G4<0), "0",G5-G4) -> 415 | I5: 103 | J5: 878
A6: 44198 | C6: =SUM('GENSET #1'!B12+'GENSET #2'!B12+'GENSET #3'!B12+'GENSET #4'!B12+'GENSET #5'!B12) -> 86124667 | D6: =IF((C6-C5<0), "0",C6-C5) -> 29767 | E6: ='Gas-2'!G7 -> 405 | F6: =IF((E6-E5<0), "0",E6-E5) -> 270 | G6: =SUM(WATER!C7,WATER!H7,WATER!M7,WATER!R7) -> 902080 | H6: =IF((G6-G5<0), "0",G6-G5) -> 368 | I6: 98 | J6: 865
A7: 44199 | C7: =SUM('GENSET #1'!B13+'GENSET #2'!B13+'GENSET #3'!B13+'GENSET #4'!B13+'GENSET #5'!B13) -> 86154182 | D7: =IF((C7-C6<0), "0",C7-C6) -> 29515 | E7: ='Gas-2'!G8 -> 405 | F7: =IF((E7-E6<0), "0",E7-E6) -> 0 | G7: =SUM(WATER!C8,WATER!H8,WATER!M8,WATER!R8) -> 902473 | H7: =IF((G7-G6<0), "0",G7-G6) -> 393 | I7: 101 | J7: 915
A8: 44200 | C8: =SUM('GENSET #1'!B14+'GENSET #2'!B14+'GENSET #3'!B14+'GENSET #4'!B14+'GENSET #5'!B14) -> 86185696 | D8: =IF((C8-C7<0), "0",C8-C7) -> 31514 | E8: ='Gas-2'!G9 -> 180 | F8: =IF((E8-E7<0), "0",E8-E7) -> 0 | G8: =SUM(WATER!C9,WATER!H9,WATER!M9,WATER!R9) -> 902924 | H8: =IF((G8-G7<0), "0",G8-G7) -> 451 | I8: 96 | J8: 861
A9: 44201 | C9: =SUM('GENSET #1'!B15+'GENSET #2'!B15+'GENSET #3'!B15+'GENSET #4'!B15+'GENSET #5'!B15) -> 86214978 | D9: =IF((C9-C8<0), "0",C9-C8) -> 29282 | E9: ='Gas-2'!G10 -> 180 | F9: =IF((E9-E8<0), "0",E9-E8) -> 0 | G9: =SUM(WATER!C10,WATER!H10,WATER!M10,WATER!R10) -> 903330 | H9: =IF((G9-G8<0), "0",G9-G8) -> 406
A10: 44202 | C10: =SUM('GENSET #1'!B16+'GENSET #2'!B16+'GENSET #3'!B16+'GENSET #4'!B16+'GENSET #5'!B16) -> 0 | D10: =IF((C10-C9<0), "0",C10-C9) -> 0 | E10: ='Gas-2'!G11 -> 0 | F10: =IF((E10-E9<0), "0",E10-E9) -> 0 | G10: =SUM(WATER!C11,WATER!H11,WATER!M11,WATER!R11) -> 903686 | H10: =IF((G10-G9<0), "0",G10-G9) -> 356
A11: 44203 | C11: =SUM('GENSET #1'!B17+'GENSET #2'!B17+'GENSET #3'!B17+'GENSET #4'!B17+'GENSET #5'!B17) -> 0 | D11: =IF((C11-C10<0), "0",C11-C10) -> 0 | E11: ='Gas-2'!G12 -> 0 | F11: =IF((E11-E10<0), "0",E11-E10) -> 0 | G11: =SUM(WATER!C12,WATER!H12,WATER!M12,WATER!R12) -> 0 | H11: =IF((G11-G10<0), "0",G11-G10) -> 0
A12: 44204 | C12: =SUM('GENSET #1'!B18+'GENSET #2'!B18+'GENSET #3'!B18+'GENSET #4'!B18+'GENSET #5'!B18) -> 0 | D12: =IF((C12-C11<0), "0",C12-C11) -> 0 | E12: ='Gas-2'!G13 -> 0 | F12: =IF((E12-E11<0), "0",E12-E11) -> 0 | G12: =SUM(WATER!C13,WATER!H13,WATER!M13,WATER!R13) -> 0 | H12: =IF((G12-G11<0), "0",G12-G11) -> 0
A13: 44205 | C13: =SUM('GENSET #1'!B19+'GENSET #2'!B19+'GENSET #3'!B19+'GENSET #4'!B19+'GENSET #5'!B19) -> 0 | D13: =IF((C13-C12<0), "0",C13-C12) -> 0 | E13: ='Gas-2'!G14 -> 0 | F13: =IF((E13-E12<0), "0",E13-E12) -> 0 | G13: =SUM(WATER!C14,WATER!H14,WATER!M14,WATER!R14) -> 0 | H13: =IF((G13-G12<0), "0",G13-G12) -> 0
A14: 44206 | C14: =SUM('GENSET #1'!B20+'GENSET #2'!B20+'GENSET #3'!B20+'GENSET #4'!B20+'GENSET #5'!B20) -> 0 | D14: =IF((C14-C13<0), "0",C14-C13) -> 0 | E14: ='Gas-2'!G15 -> 0 | F14: =IF((E14-E13<0), "0",E14-E13) -> 0 | G14: =SUM(WATER!C15,WATER!H15,WATER!M15,WATER!R15) -> 0 | H14: =IF((G14-G13<0), "0",G14-G13) -> 0
A15: 44207 | C15: =SUM('GENSET #1'!B21+'GENSET #2'!B21+'GENSET #3'!B21+'GENSET #4'!B21+'GENSET #5'!B21) -> 0 | D15: =IF((C15-C14<0), "0",C15-C14) -> 0 | E15: ='Gas-2'!G16 -> 0 | F15: =IF((E15-E14<0), "0",E15-E14) -> 0 | G15: =SUM(WATER!C16,WATER!H16,WATER!M16,WATER!R16) -> 0 | H15: =IF((G15-G14<0), "0",G15-G14) -> 0
A16: 44208 | C16: =SUM('GENSET #1'!B22+'GENSET #2'!B22+'GENSET #3'!B22+'GENSET #4'!B22+'GENSET #5'!B22) -> 0 | D16: =IF((C16-C15<0), "0",C16-C15) -> 0 | E16: ='Gas-2'!G17 -> 0 | F16: =IF((E16-E15<0), "0",E16-E15) -> 0 | G16: =SUM(WATER!C17,WATER!H17,WATER!M17,WATER!R17) -> 0 | H16: =IF((G16-G15<0), "0",G16-G15) -> 0
A17: 44209 | C17: =SUM('GENSET #1'!B23+'GENSET #2'!B23+'GENSET #3'!B23+'GENSET #4'!B23+'GENSET #5'!B23) -> 0 | D17: =IF((C17-C16<0), "0",C17-C16) -> 0 | E17: ='Gas-2'!G18 -> 0 | F17: =IF((E17-E16<0), "0",E17-E16) -> 0 | G17: =SUM(WATER!C18,WATER!H18,WATER!M18,WATER!R18) -> 0 | H17: =IF((G17-G16<0), "0",G17-G16) -> 0
A18: 44210 | C18: =SUM('GENSET #1'!B24+'GENSET #2'!B24+'GENSET #3'!B24+'GENSET #4'!B24+'GENSET #5'!B24) -> 0 | D18: =IF((C18-C17<0), "0",C18-C17) -> 0 | E18: ='Gas-2'!G19 -> 0 | F18: =IF((E18-E17<0), "0",E18-E17) -> 0 | G18: =SUM(WATER!C19,WATER!H19,WATER!M19,WATER!R19) -> 0 | H18: =IF((G18-G17<0), "0",G18-G17) -> 0
A19: 44211 | C19: =SUM('GENSET #1'!B25+'GENSET #2'!B25+'GENSET #3'!B25+'GENSET #4'!B25+'GENSET #5'!B25) -> 0 | D19: =IF((C19-C18<0), "0",C19-C18) -> 0 | E19: ='Gas-2'!G20 -> 0 | F19: =IF((E19-E18<0), "0",E19-E18) -> 0 | G19: =SUM(WATER!C20,WATER!H20,WATER!M20,WATER!R20) -> 0 | H19: =IF((G19-G18<0), "0",G19-G18) -> 0
A20: 44212 | C20: =SUM('GENSET #1'!B26+'GENSET #2'!B26+'GENSET #3'!B26+'GENSET #4'!B26+'GENSET #5'!B26) -> 0 | D20: =IF((C20-C19<0), "0",C20-C19) -> 0 | E20: ='Gas-2'!G21 -> 0 | F20: =IF((E20-E19<0), "0",E20-E19) -> 0 | G20: =SUM(WATER!C21,WATER!H21,WATER!M21,WATER!R21) -> 0 | H20: =IF((G20-G19<0), "0",G20-G19) -> 0
... A35: 44227 | C35: =SUM('GENSET #1'!B41+'GENSET #2'!B41+'GENSET #3'!B41+'GENSET #4'!B41+'GENSET #5'!B41) -> 0 | D35: =IF((C35-C34<0), "0",C35-C34) -> 0 | E35: ='Gas-2'!G36 -> 0 | F35: =IF((E35-E34<0), "0",E35-E34) -> 0 | G35: =SUM(WATER!C36,WATER!H36,WATER!M36,WATER!R36) -> 0 | H35: =IF((G35-G34<0), "0",G35-G34) -> 0

Sheet Finance Only
A1: Four Seasons Landaa Giraavaru
A3: Property | B3: MLG
A4: Month | B4: January
A5: Year | B5: 2021
A7: DAY | B7: Electricity Consumption ( kwh) | C7: Diesel Consumption (Liters) | D7: Solar Power Consumption(kwh) | E7: Gas Consumption (kg) | F7: Water Consumption ( m3)
A8: 1 | B8: =SUM('GENSET #1:GENSET #5'!D10) -> 30450 | C8: ='Diesel consumption'!D5 -> 8440 | D8: ='SOLAR METER READING'!D9 -> 560 | E8: ='Gas-2'!G6 -> 135 | F8: =WATER!V6 -> 415
A9: 2 | B9: =SUM('GENSET #1:GENSET #5'!D11) -> 29767 | C9: ='Diesel consumption'!D6 -> 8080 | D9: ='SOLAR METER READING'!D10 -> 2728 | E9: ='Gas-2'!G7 -> 405 | F9: =WATER!V7 -> 368
A10: 3 | B10: =SUM('GENSET #1:GENSET #5'!D12) -> 29515 | C10: ='Diesel consumption'!D7 -> 8230 | D10: ='SOLAR METER READING'!D11 -> 3002 | E10: ='Gas-2'!G8 -> 405 | F10: =WATER!V8 -> 393
A11: 4 | B11: =SUM('GENSET #1:GENSET #5'!D13) -> 31514 | C11: ='Diesel consumption'!D8 -> 8820 | D11: ='SOLAR METER READING'!D12 -> 2218 | E11: ='Gas-2'!G9 -> 180 | F11: =WATER!V9 -> 451
A12: 5 | B12: =SUM('GENSET #1:GENSET #5'!D14) -> 29282 | C12: ='Diesel consumption'!D9 -> 8190 | D12: ='SOLAR METER READING'!D13 -> 1694 | E12: ='Gas-2'!G10 -> 180 | F12: =WATER!V10 -> 406
A13: 6 | B13: =SUM('GENSET #1:GENSET #5'!D15) -> -86214978 | C13: ='Diesel consumption'!D10 -> -42919360 | D13: ='SOLAR METER READING'!D14 -> -2258519 | E13: ='Gas-2'!G11 -> 0 | F13: =WATER!V11 -> 356
A14: 7 | B14: =SUM('GENSET #1:GENSET #5'!D16) -> 0 | C14: ='Diesel consumption'!D11 -> 0 | D14: ='SOLAR METER READING'!D15 -> 0 | E14: ='Gas-2'!G12 -> 0 | F14: =WATER!V12 -> -903686
A15: 8 | B15: =SUM('GENSET #1:GENSET #5'!D17) -> 0 | C15: ='Diesel consumption'!D12 -> 0 | D15: ='SOLAR METER READING'!D16 -> 0 | E15: ='Gas-2'!G13 -> 0 | F15: =WATER!V13 -> 0
A16: 9 | B16: =SUM('GENSET #1:GENSET #5'!D18) -> 0 | C16: ='Diesel consumption'!D13 -> 0 | D16: ='SOLAR METER READING'!D17 -> 0 | E16: ='Gas-2'!G14 -> 0 | F16: =WATER!V14 -> 0
A17: 10 | B17: =SUM('GENSET #1:GENSET #5'!D19) -> 0 | C17: ='Diesel consumption'!D14 -> 0 | D17: ='SOLAR METER READING'!D18 -> 0 | E17: ='Gas-2'!G15 -> 0 | F17: =WATER!V15 -> 0
A18: 11 | B18: =SUM('GENSET #1:GENSET #5'!D20) -> 0 | C18: ='Diesel consumption'!D15 -> 0 | D18: ='SOLAR METER READING'!D19 -> 0 | E18: ='Gas-2'!G16 -> 0 | F18: =WATER!V16 -> 0
A19: 12 | B19: =SUM('GENSET #1:GENSET #5'!D21) -> 0 | C19: ='Diesel consumption'!D16 -> 0 | D19: ='SOLAR METER READING'!D20 -> 0 | E19: ='Gas-2'!G17 -> 0 | F19: =WATER!V17 -> 0
... A38: 31 | B38: =SUM('GENSET #1:GENSET #5'!D40) -> 0 | C38: ='Diesel consumption'!D35 -> 0 | D38: ='SOLAR METER READING'!D39 -> 0 | E38: ='Gas-2'!G36 -> 0 | F38: =WATER!V36 -> 0
A39: Total | B39: =SUM(B8:B38) -> -86064450 | C39: =SUM(C8:C38) -> -42877600 | D39: =SUM(D8:D38) -> -2248317 | E39: =SUM(E8:E38) -> 1305 | F39: =SUM(F8:F38) -> -901297

Sheet GENSET #1
C1: 1000 KVA
C3: NO#1
A6: 44197
B8: GENSET NO 1
A9: DAY | B9: YESTARDAY | C9: TODAY | D9: Final Electricity Consumption( KWh)
A10: 1 | B10: 16755350 | C10: 16764967 | D10: =C10-B10 -> 9617
A11: 2 | B11: =C10 -> 16764967 | C11: 16765707 | D11: =C11-B11 -> 740
A12: 3 | B12: =C11 -> 16765707 | C12: 16775295 | D12: =C12-B12 -> 9588
A13: 4 | B13: =C12 -> 16775295 | C13: 16782241 | D13: =C13-B13 -> 6946
A14: 5 | B14: =C13 -> 16782241 | C14: 16790551 | D14: =C14-B14 -> 8310
A15: 6 | B15: =C14 -> 16790551 | D15: =C15-B15 -> -16790551
A16: 7 | B16: =C15 -> 0 | D16: =C16-B16 -> 0
A17: 8 | B17: =C16 -> 0 | D17: =C17-B17 -> 0
A18: 9 | B18: =C17 -> 0 | D18: =C18-B18 -> 0
A19: 10 | B19: =C18 -> 0 | D19: =C19-B19 -> 0
A20: 11 | B20: =C19 -> 0 | D20: =C20-B20 -> 0
A21: 12 | B21: =C20 -> 0 | D21: =C21-B21 -> 0
A22: 13 | B22: =C21 -> 0 | D22: =C22-B22 -> 0
A23: 14 | B23: =C22 -> 0 | D23: =C23-B23 -> 0
A24: 15 | B24: =C23 -> 0 | D24: =C24-B24 -> 0
A25: 16 | B25: =C24 -> 0 | D25: =C25-B25 -> 0
A26: 17 | B26: =C25 -> 0 | D26: =C26-B26 -> 0
... A38: 29 | B38: =C37 -> 0 | D38: =C38-B38 -> 0
A39: 30 | B39: =C38 -> 0 | D39: =C39-B39 -> 0 | G39: NEW ENGINE PURCHASED FROM UK
A40: 31 | B40: =C39 -> 0 | D40: =C40-B40 -> 0
A41: Total | D41: =SUM(D10:D40) -> -16755350 | G41: INSTALLED: NOV 30 2013

Sheet GENSET #2
C1: 1600 KVA
C3: NO#2
A6: 44197
B8: GENSET NO 2
A9: DAY | B9: YESTARDAY | C9: TODAY | D9: Final Electricity Consumption( KW h)
A10: 1 | B10: 28298713 | C10: 28300234 | D10: =C10-B10 -> 1521
A11: 2 | B11: =C10 -> 28300234 | C11: 28317766 | D11: =C11-B11 -> 17532
A12: 3 | B12: =C11 -> 28317766 | C12: 28320930 | D12: =C12-B12 -> 3164
A13: 4 | B13: =C12 -> 28320930 | C13: 28333897 | D13: =C13-B13 -> 12967
A14: 5 | B14: =C13 -> 28333897 | C14: 28339386 | D14: =C14-B14 -> 5489
A15: 6 | B15: =C14 -> 28339386 | D15: =C15-B15 -> -28339386
A16: 7 | B16: =C15 -> 0 | D16: =C16-B16 -> 0
A17: 8 | B17: =C16 -> 0 | D17: =C17-B17 -> 0
A18: 9 | B18: =C17 -> 0 | D18: =C18-B18 -> 0
A19: 10 | B19: =C18 -> 0 | D19: =C19-B19 -> 0
A20: 11 | B20: =C19 -> 0 | D20: =C20-B20 -> 0
A21: 12 | B21: =C20 -> 0 | D21: =C21-B21 -> 0
A22: 13 | B22: =C21 -> 0 | D22: =C22-B22 -> 0
A23: 14 | B23: =C22 -> 0 | D23: =C23-B23 -> 0
A24: 15 | B24: =C23 -> 0 | D24: =C24-B24 -> 0
A25: 16 | B25: =C24 -> 0 | D25: =C25-B25 -> 0
A26: 17 | B26: =C25 -> 0 | D26: =C26-B26 -> 0
... A40: 31 | B40: =C39 -> 0 | D40: =C40-B40 -> 0
A41: Total | D41: =SUM(D10:D40) -> -28298713

Sheet GENSET #3
C1: 900 KVA
C3: NO#3
A6: 44197
B8: GENSET NO 3
A9: DAY | B9: YESTARDAY | C9: TODAY | D9: Final Electricity Consumption( KW h)
A10: 1 | B10: 12278846 | C10: 12285327 | D10: =C10-B10 -> 6481
A11: 2 | B11: =C10 -> 12285327 | C11: 12292842 | D11: =C11-B11 -> 7515
A12: 3 | B12: =C11 -> 12292842 | C12: 12294612 | D12: =C12-B12 -> 1770
A13: 4 | B13: =C12 -> 12294612 | C13: 12300988 | D13: =C13-B13 -> 6376
A14: 5 | B14: =C13 -> 12300988 | C14: 12307055 | D14: =C14-B14 -> 6067
A15: 6 | B15: =C14 -> 12307055 | D15: =C15-B15 -> -12307055
A16: 7 | B16: =C15 -> 0 | D16: =C16-B16 -> 0
A17: 8 | B17: =C16 -> 0 | D17: =C17-B17 -> 0
A18: 9 | B18: =C17 -> 0 | D18: =C18-B18 -> 0
A19: 10 | B19: =C18 -> 0 | D19: =C19-B19 -> 0
A20: 11 | B20: =C19 -> 0 | D20: =C20-B20 -> 0
A21: 12 | B21: =C20 -> 0 | D21: =C21-B21 -> 0
A22: 13 | B22: =C21 -> 0 | D22: =C22-B22 -> 0
A23: 14 | B23: =C22 -> 0 | D23: =C23-B23 -> 0
A24: 15 | B24: =C23 -> 0 | D24: =C24-B24 -> 0
A25: 16 | B25: =C24 -> 0 | D25: =C25-B25 -> 0
A26: 17 | B26: =C25 -> 0 | D26: =C26-B26 -> 0
... A40: 31 | B40: =C39 -> 0 | D40: =C40-B40 -> 0
A41: Total | D41: =SUM(D10:D40) -> -12278846

Sheet GENSET #4
C1: 500 KVA
C3: NO#4
A6: 44197
B8: GENSET NO 4
A9: DAY | B9: YESTARDAY | C9: TODAY | D9: Final Electricity Consumption( KW h)
A10: 1 | B10: 11340369 | C10: 11342642 | D10: =C10-B10 -> 2273
A11: 2 | B11: =C10 -> 11342642 | C11: 11345847 | D11: =C11-B11 -> 3205
A12: 3 | B12: =C11 -> 11345847 | C12: 11349375 | D12: =C12-B12 -> 3528
A13: 4 | B13: =C12 -> 11349375 | C13: 11351022 | D13: =C13-B13 -> 1647
A14: 5 | B14: =C13 -> 11351022 | C14: 11352858 | D14: =C14-B14 -> 1836
A15: 6 | B15: =C14 -> 11352858 | D15: =C15-B15 -> -11352858
A16: 7 | B16: =C15 -> 0 | D16: =C16-B16 -> 0
A17: 8 | B17: =C16 -> 0 | D17: =C17-B17 -> 0
A18: 9 | B18: =C17 -> 0 | D18: =C18-B18 -> 0
A19: 10 | B19: =C18 -> 0 | D19: =C19-B19 -> 0
A20: 11 | B20: =C19 -> 0 | D20: =C20-B20 -> 0
A21: 12 | B21: =C20 -> 0 | D21: =C21-B21 -> 0
A22: 13 | B22: =C21 -> 0 | D22: =C22-B22 -> 0
A23: 14 | B23: =C22 -> 0 | D23: =C23-B23 -> 0
A24: 15 | B24: =C23 -> 0 | D24: =C24-B24 -> 0
A25: 16 | B25: =C24 -> 0 | D25: =C25-B25 -> 0
A26: 17 | B26: =C25 -> 0 | D26: =C26-B26 -> 0
... A40: 31 | B40: =C39 -> 0 | D40: =C40-B40 -> 0
A41: Total | D41: =SUM(D10:D40) -> -11340369

Sheet GENSET #5
C1: 1000 KVA
C3: NO#5
A6: 44197
B8: GENSET NO 5
A9: DAY | B9: YESTARDAY | C9: TODAY | D9: Final Electricity Consumption( KWh)
A10: 1 | B10: 17391172 | C10: 17401730 | D10: =C10-B10 -> 10558
A11: 2 | B11: =C10 -> 17401730 | C11: 17402505 | D11: =C11-B11 -> 775
A12: 3 | B12: =C11 -> 17402505 | C12: 17413970 | D12: =C12-B12 -> 11465
A13: 4 | B13: =C12 -> 17413970 | C13: 17417548 | D13: =C13-B13 -> 3578
A14: 5 | B14: =C13 -> 17417548 | C14: 17425128 | D14: =C14-B14 -> 7580
A15: 6 | B15: =C14 -> 17425128 | D15: =C15-B15 -> -17425128
A16: 7 | B16: =C15 -> 0 | D16: =C16-B16 -> 0
A17: 8 | B17: =C16 -> 0 | D17: =C17-B17 -> 0
A18: 9 | B18: =C17 -> 0 | D18: =C18-B18 -> 0
A19: 10 | B19: =C18 -> 0 | D19: =C19-B19 -> 0
A20: 11 | B20: =C19 -> 0 | D20: =C20-B20 -> 0
A21: 12 | B21: =C20 -> 0 | D21: =C21-B21 -> 0
A22: 13 | B22: =C21 -> 0 | D22: =C22-B22 -> 0
A23: 14 | B23: =C22 -> 0 | D23: =C23-B23 -> 0
A24: 15 | B24: =C23 -> 0 | D24: =C24-B24 -> 0
A25: 16 | B25: =C24 -> 0 | D25: =C25-B25 -> 0
A26: 17 | B26: =C25 -> 0 | D26: =C26-B26 -> 0
... A40: 31 | B40: =C39 -> 0 | D40: =C40-B40 -> 0
A41: Total | D41: =SUM(D10:D40) -> -17391172

Sheet Diesel consumption
A2: 44197
B3: Liters | F3: Boat meter Reading
A4: Date | B4: Yesterday | C4: Today | D4: In 24 hrs | F4: Yesterday | G4: Today | I4: In Barrels | K4: Carbon Emmision
A5: 1 | B5: 42877600 | C5: 42886040 | D5: =C5-B5 -> 8440 | I5: =D5/200 -> 42.2 | K5: =2.68*D5 -> 22619.2 | L5: =K5/1000 -> 22.6192
A6: 2 | B6: =C5 -> 42886040 | C6: 42894120 | D6: =C6-B6 -> 8080 | I6: =D6/200 -> 40.4 | K6: =2.68*D6 -> 21654.4 | L6: =K6/1000 -> 21.6544
A7: 3 | B7: =C6 -> 42894120 | C7: 42902350 | D7: =C7-B7 -> 8230 | I7: =D7/200 -> 41.15 | K7: =2.68*D7 -> 22056.4 | L7: =K7/1000 -> 22.0564
A8: 4 | B8: =C7 -> 42902350 | C8: 42911170 | D8: =C8-B8 -> 8820 | I8: =D8/200 -> 44.1 | K8: =2.68*D8 -> 23637.6 | L8: =K8/1000 -> 23.6376
A9: 5 | B9: =C8 -> 42911170 | C9: 42919360 | D9: =C9-B9 -> 8190 | I9: =D9/200 -> 40.95 | K9: =2.68*D9 -> 21949.2 | L9: =K9/1000 -> 21.9492
A10: 6 | B10: =C9 -> 42919360 | D10: =C10-B10 -> -42919360 | I10: =D10/200 -> -214596.8 | K10: =2.68*D10 -> -1.1502388e+08 | L10: =K10/1000 -> -115023.88
A11: 7 | B11: =C10 -> 0 | D11: =C11-B11 -> 0 | I11: =D11/200 -> 0 | K11: =2.68*D11 -> 0 | L11: =K11/1000 -> 0
A12: 8 | B12: =C11 -> 0 | D12: =C12-B12 -> 0 | I12: =D12/200 -> 0 | K12: =2.68*D12 -> 0 | L12: =K12/1000 -> 0
A13: 9 | B13: =C12 -> 0 | D13: =C13-B13 -> 0 | I13: =D13/200 -> 0 | K13: =2.68*D13 -> 0 | L13: =K13/1000 -> 0
A14: 10 | B14: =C13 -> 0 | D14: =C14-B14 -> 0 | I14: =D14/200 -> 0 | K14: =2.68*D14 -> 0 | L14: =K14/1000 -> 0
A15: 11 | B15: =C14 -> 0 | D15: =C15-B15 -> 0 | I15: =D15/200 -> 0 | K15: =2.68*D15 -> 0 | L15: =K15/1000 -> 0
A16: 12 | B16: =C15 -> 0 | D16: =C16-B16 -> 0 | I16: =D16/200 -> 0 | K16: =2.68*D16 -> 0 | L16: =K16/1000 -> 0
A17: 13 | B17: =C16 -> 0 | D17: =C17-B17 -> 0 | I17: =D17/200 -> 0 | K17: =2.68*D17 -> 0 | L17: =K17/1000 -> 0
A18: 14 | B18: =C17 -> 0 | D18: =C18-B18 -> 0 | I18: =D18/200 -> 0 | K18: =2.68*D18 -> 0 | L18: =K18/1000 -> 0
A19: 15 | B19: =C18 -> 0 | D19: =C19-B19 -> 0 | I19: =D19/200 -> 0 | K19: =2.68*D19 -> 0 | L19: =K19/1000 -> 0
A20: 16 | B20: =C19 -> 0 | D20: =C20-B20 -> 0 | I20: =D20/200 -> 0 | K20: =2.68*D20 -> 0 | L20: =K20/1000 -> 0
A21: 17 | B21: =C20 -> 0 | D21: =C21-B21 -> 0 | I21: =D21/200 -> 0 | K21: =2.68*D21 -> 0 | L21: =K21/1000 -> 0
... A33: 29 | B33: =C32 -> 0 | D33: =C33-B33 -> 0 | I33: =D33/200 -> 0 | K33: =2.68*D33 -> 0 | L33: =K33/1000 -> 0
A34: 30 | B34: =C33 -> 0 | D34: =C34-B34 -> 0 | F34: 0 | I34: =D34/200 -> 0 | K34: =2.68*D34 -> 0 | L34: =K34/1000 -> 0
A35: 31 | B35: =C34 -> 0 | D35: =C35-B35 -> 0
D36: =SUM(D5:D34) -> -42877600 | I36: =SUM(I5:I34) -> -214388 | K36: =2.68*D36 -> -114911968 | L36: =K36/1000 -> -114911.97

Sheet SOLAR METER READING
C3: solar reading
B5: 44197
B7: solar meter reading
A8: DAY | B8: YESTARDAY | C8: TODAY | D8: Final Electricity Consumption( KW h)
A9: 1 | B9: 2248317 | C9: 2248877 | D9: =C9-B9 -> 560
A10: 2 | B10: =C9 -> 2248877 | C10: 2251605 | D10: =C10-B10 -> 2728
A11: 3 | B11: =C10 -> 2251605 | C11: 2254607 | D11: =C11-B11 -> 3002
A12: 4 | B12: =C11 -> 2254607 | C12: 2256825 | D12: =C12-B12 -> 2218
A13: 5 | B13: =C12 -> 2256825 | C13: 2258519 | D13: =C13-B13 -> 1694 | J13: 1 liter diesel | K13: 11.1 kwh
A14: 6 | B14: =C13 -> 2258519 | D14: =C14-B14 -> -2258519 | J14: 212.88 diesel | K14: 2363 kwh
A15: 7 | B15: =C14 -> 0 | D15: =C15-B15 -> 0
A16: 8 | B16: =C15 -> 0 | D16: =C16-B16 -> 0
A17: 9 | B17: =C16 -> 0 | D17: =C17-B17 -> 0
A18: 10 | B18: =C17 -> 0 | D18: =C18-B18 -> 0
A19: 11 | B19: =C18 -> 0 | D19: =C19-B19 -> 0
A20: 12 | B20: =C19 -> 0 | D20: =C20-B20 -> 0
A21: 13 | B21: =C20 -> 0 | D21: =C21-B21 -> 0
A22: 14 | B22: =C21 -> 0 | D22: =C22-B22 -> 0
A23: 15 | B23: =C22 -> 0 | D23: =C23-B23 -> 0
A24: 16 | B24: =C23 -> 0 | D24: =C24-B24 -> 0
A25: 17 | B25: =C24 -> 0 | D25: =C25-B25 -> 0
A26: 18 | B26: =C25 -> 0 | D26: =C26-B26 -> 0
... A39: 31 | B39: =C38 -> 0 | D39: =C39-B39 -> 0
A40: Total | D40: =SUM(D9:D39) -> -2248317

Sheet FEEDER Consumption 
C3: POWER HOUSE FEEDER READING
A5: 43313
B7: BLU FEEDER PANEL 1 | E7: BLU FEEDER PANEL 2 | H7: POWER HOUSE FEEDER PANEL NO:3 | K7: Main Kitchen -7 | N7: Main Kitchen -10 | Q7: Water treatment Plant | T7: Sewage treatment Plant | W7: Laundry--8SSB | Z7: Laundry-9 | AC7: New staff accomodation (E0) | AF7: Boat Dock feeder - 22 | AI7: Staff block-16(E2-E3) | AL7: Management block-5 | AO7: Staff Block Feeder-3(E4-E5) | AR7: DIESEL TANK JETTY METER | AU7: SNR STAFF BLOCK | AX7: RECEPTION | BA7: DIVE CENTER | BD7: 301-307 | BG7: 308-314 | BJ7: 315-320 | BM7: 401-407 | BP7: 408-414 | BS7: 415-420 | BV7: SPA - 1 | BY7: SPA - 2 | CB7: BLU KITCHEN - 1 | CE7: BLU KITCHEN - 2 | CH7: AL BARAKATH | CK7: STAFF KITCHEN | CN7: MANAGR BLOCK GARDEN
A8: DAY | B8: Yesterday | C8: Today | D8: Consumption | E8: Yesterday | F8: Today | G8: Consumption | H8: Yesterday | I8: Today | J8: Consumption | K8: Yesterday | L8: Today | M8: Consumption | N8: Yesterday | O8: Today | P8: Consumption | Q8: Yesterday | R8: Today | S8: Consumption | T8: Yesterday | U8: Today | V8: Consumption | W8: Yesterday | X8: Today | Y8: Consumption | Z8: Yesterday | AA8: Today | AB8: Consumption | AC8: Yesterday | AD8: Today | AE8: Consumption | AF8: Yesterday | AG8: Today | AH8: Consumption | AI8: Yesterday | AJ8: Today | AK8: Consumption | AL8: Yesterday | AM8: Today | AN8: Consumption | AO8: Yesterday | AP8: Today | AQ8: Consumption | AR8: Yesterday | AS8: Today | AT8: Consumption | AU8: Yesterday | AV8: Today | AW8: Consumption | AX8: Yesterday | AY8: Today | AZ8: Consumption | BA8: Yesterday | BB8: Today | BC8: Consumption | BD8: Yesterday | BE8: Today | BF8: Consumption | BG8: Yesterday | BH8: Today | BI8: Consumption | BJ8: Yesterday | BK8: Today | BL8: Consumption | BM8: Yesterday | BN8: Today | BO8: Consumption | BP8: Yesterday | BQ8: Today | BR8: Consumption | BS8: Yesterday | BT8: Today | BU8: Consumption | BV8: Yesterday | BW8: Today | BX8: Consumption | BY8: Yesterday | BZ8: Today | CA8: Consumption | CB8: Yesterday | CC8: Today | CD8: Consumption | CE8: Yesterday | CF8: Today | CG8: Consumption | CH8: Yesterday | CI8: Today | CJ8: Consumption | CK8: Yesterday | CL8: Today | CM8: Consumption | CN8: Yesterday | CO8: Today | CP8: Consumption
A9: 1 | B9: 25088084 | C9: 25091780 | D9: =C9-B9 -> 3696 | E9: 21981188 | F9: 21985367 | G9: =F9-E9 -> 4179 | H9: 83718230 | I9: 83733710 | J9: =I9-H9 -> 15480 | K9: 1722220 | L9: 1724500 | M9: =L9-K9 -> 2280 | N9: 2330923 | O9: 2333661 | P9: =O9-N9 -> 2738 | Q9: 1403900 | R9: 1405800 | S9: =R9-Q9 -> 1900 | T9: 659727 | U9: 660381 | V9: =U9-T9 -> 654 | W9: 6827800 | X9: 6834100 | Y9: =X9-W9 -> 6300 | Z9: 1485900 | AA9: 1489300 | AB9: =AA9-Z9 -> 3400 | AC9: 443008 | AD9: 443496 | AE9: =AD9-AC9 -> 488 | AF9: 312460 | AG9: 312980 | AH9: =AG9-AF9 -> 520 | AI9: 522300 | AJ9: 523370 | AK9: =AJ9-AI9 -> 1070 | AL9: 971190 | AM9: 972780 | AN9: =AM9-AL9 -> 1590 | AO9: 617560 | AP9: 618570 | AQ9: =AP9-AO9 -> 1010 | AR9: 455500 | AS9: 455500 | AT9: =AS9-AR9 -> 0 | AU9: 398160 | AV9: 402100 | AW9: =AV9-AU9 -> 3940 | AX9: 313610 | AY9: 314860 | AZ9: =AY9-AX9 -> 1250 | BA9: 838750 | BB9: 841820 | BC9: =BB9-BA9 -> 3070 | BD9: 16414 | BE9: 16514 | BF9: =BE9-BD9 -> 100 | BG9: 13337 | BH9: 13388 | BI9: =BH9-BG9 -> 51 | BJ9: 12664 | BK9: 12734 | BL9: =BK9-BJ9 -> 70 | BM9: 20408 | BN9: 20499 | BO9: =BN9-BM9 -> 91 | BP9: 13725 | BQ9: 13794 | BR9: =BQ9-BP9 -> 69 | BS9: 15869 | BT9: 15916 | BU9: =BT9-BS9 -> 47 | BV9: 10596 | BW9: 10645 | BX9: =BW9-BV9 -> 49 | BY9: 27031 | BZ9: 27263 | CA9: =BZ9-BY9 -> 232 | CB9: 22769 | CC9: 22906 | CD9: =CC9-CB9 -> 137 | CE9: 65938 | CF9: 66116 | CG9: =CF9-CE9 -> 178 | CH9: 33060 | CI9: 33329 | CJ9: =CI9-CH9 -> 269 | CK9: 10817 | CL9: 10864 | CM9: =CL9-CK9 -> 47 | CN9: 38022 | CO9: 38181 | CP9: =CO9-CN9 -> 159
A10: 2 | B10: =C9 -> 25091780 | C10: 25095537 | D10: =C10-B10 -> 3757 | E10: =F9 -> 21985367 | F10: 21990123 | G10: =F10-E10 -> 4756 | H10: =I9 -> 83733710 | I10: 83747555 | J10: =I10-H10 -> 13845 | K10: =L9 -> 1724500 | L10: 1726700 | M10: =L10-K10 -> 2200 | N10: =O9 -> 2333661 | O10: 2336315 | P10: =O10-N10 -> 2654 | Q10: =R9 -> 1405800 | R10: 1407800 | S10: =R10-Q10 -> 2000 | T10: =U9 -> 660381 | U10: 661098 | V10: =U10-T10 -> 717 | W10: =X9 -> 6834100 | X10: 6840600 | Y10: =X10-W10 -> 6500 | Z10: =AA9 -> 1489300 | AA10: 1492200 | AB10: =AA10-Z10 -> 2900 | AC10: =AD9 -> 443496 | AD10: 443924 | AE10: =AD10-AC10 -> 428 | AF10: =AG9 -> 312980 | AG10: 313400 | AH10: =AG10-AF10 -> 420 | AI10: =AJ9 -> 523370 | AJ10: 524130 | AK10: =AJ10-AI10 -> 760 | AL10: =AM9 -> 972780 | AM10: 973920 | AN10: =AM10-AL10 -> 1140 | AO10: =AP9 -> 618570 | AP10: 619280 | AQ10: =AP10-AO10 -> 710 | AR10: =AS9 -> 455500 | AS10: 456000 | AT10: =AS10-AR10 -> 500 | AU10: =AV9 -> 402100 | AV10: 402740 | AW10: =AV10-AU10 -> 640 | AX10: =AY9 -> 314860 | AY10: 316020 | AZ10: =AY10-AX10 -> 1160 | BA10: =BB9 -> 841820 | BB10: 845160 | BC10: =BB10-BA10 -> 3340 | BD10: =BE9 -> 16514 | BE10: 16623 | BF10: =BE10-BD10 -> 109 | BG10: =BH9 -> 13388 | BH10: 13470 | BI10: =BH10-BG10 -> 82 | BJ10: =BK9 -> 12734 | BK10: 12836 | BL10: =BK10-BJ10 -> 102 | BM10: =BN9 -> 20499 | BN10: 20600 | BO10: =BN10-BM10 -> 101 | BP10: =BQ9 -> 13794 | BQ10: 13870 | BR10: =BQ10-BP10 -> 76 | BS10: =BT9 -> 15916 | BT10: 15965 | BU10: =BT10-BS10 -> 49 | BV10: =BW9 -> 10645 | BW10: 10698 | BX10: =BW10-BV10 -> 53 | BY10: =BZ9 -> 27263 | BZ10: 27430 | CA10: =BZ10-BY10 -> 167 | CB10: =CC9 -> 22906 | CC10: 22994 | CD10: =CC10-CB10 -> 88 | CE10: =CF9 -> 66116 | CF10: 66398 | CG10: =CF10-CE10 -> 282 | CH10: =CI9 -> 33329 | CI10: 33706 | CJ10: =CI10-CH10 -> 377 | CK10: =CL9 -> 10864 | CL10: 10909 | CM10: =CL10-CK10 -> 45 | CN10: =CO9 -> 38181 | CO10: 38302 | CP10: =CO10-CN10 -> 121
A11: 3 | B11: =C10 -> 25095537 | C11: 25099648 | D11: =C11-B11 -> 4111 | E11: =F10 -> 21990123 | F11: 21994583 | G11: =F11-E11 -> 4460 | H11: =I10 -> 83747555 | I11: 83761438 | J11: =I11-H11 -> 13883 | K11: =L10 -> 1726700 | L11: 1728900 | M11: =L11-K11 -> 2200 | N11: =O10 -> 2336315 | O11: 2339105 | P11: =O11-N11 -> 2790 | Q11: =R10 -> 1407800 | R11: 1409800 | S11: =R11-Q11 -> 2000 | T11: =U10 -> 661098 | U11: 661786 | V11: =U11-T11 -> 688 | W11: =X10 -> 6840600 | X11: 6847000 | Y11: =X11-W11 -> 6400 | Z11: =AA10 -> 1492200 | AA11: 1494900 | AB11: =AA11-Z11 -> 2700 | AC11: =AD10 -> 443924 | AD11: 444336 | AE11: =AD11-AC11 -> 412 | AF11: =AG10 -> 313400 | AG11: 313750 | AH11: =AG11-AF11 -> 350 | AI11: =AJ10 -> 524130 | AJ11: 524950 | AK11: =AJ11-AI11 -> 820 | AL11: =AM10 -> 973920 | AM11: 975110 | AN11: =AM11-AL11 -> 1190 | AO11: =AP10 -> 619280 | AP11: 620070 | AQ11: =AP11-AO11 -> 790 | AR11: =AS10 -> 456000 | AS11: 456770 | AT11: =AS11-AR11 -> 770 | AU11: =AV10 -> 402740 | AV11: 404460 | AW11: =AV11-AU11 -> 1720 | AX11: =AY10 -> 316020 | AY11: 317180 | AZ11: =AY11-AX11 -> 1160 | BA11: =BB10 -> 845160 | BB11: 849030 | BC11: =BB11-BA11 -> 3870 | BD11: =BE10 -> 16623 | BE11: 16702 | BF11: =BE11-BD11 -> 79 | BG11: =BH10 -> 13470 | BH11: 13548 | BI11: =BH11-BG11 -> 78 | BJ11: =BK10 -> 12836 | BK11: 12928 | BL11: =BK11-BJ11 -> 92 | BM11: =BN10 -> 20600 | BN11: 20697 | BO11: =BN11-BM11 -> 97 | BP11: =BQ10 -> 13870 | BQ11: 13942 | BR11: =BQ11-BP11 -> 72 | BS11: =BT10 -> 15965 | BT11: 16018 | BU11: =BT11-BS11 -> 53 | BV11: =BW10 -> 10698 | BW11: 10751 | BX11: =BW11-BV11 -> 53 | BY11: =BZ10 -> 27430 | BZ11: 27617 | CA11: =BZ11-BY11 -> 187 | CB11: =CC10 -> 22994 | CC11: 23080 | CD11: =CC11-CB11 -> 86 | CE11: =CF10 -> 66398 | CF11: 66675 | CG11: =CF11-CE11 -> 277 | CH11: =CI10 -> 33706 | CI11: 34064 | CJ11: =CI11-CH11 -> 358 | CK11: =CL10 -> 10909 | CL11: 10998 | CM11: =CL11-CK11 -> 89 | CN11: =CO10 -> 38302 | CO11: 38411 | CP11: =CO11-CN11 -> 109
A12: 4 | B12: =C11 -> 25099648 | C12: 25103892 | D12: =C12-B12 -> 4244 | E12: =F11 -> 21994583 | F12: 21999466 | G12: =F12-E12 -> 4883 | H12: =I11 -> 83761438 | I12: 83776294 | J12: =I12-H12 -> 14856 | K12: =L11 -> 1728900 | L12: 1731100 | M12: =L12-K12 -> 2200 | N12: =O11 -> 2339105 | O12: 2341951 | P12: =O12-N12 -> 2846 | Q12: =R11 -> 1409800 | R12: 1411800 | S12: =R12-Q12 -> 2000 | T12: =U11 -> 661786 | U12: 662479 | V12: =U12-T12 -> 693 | W12: =X11 -> 6847000 | X12: 6852800 | Y12: =X12-W12 -> 5800 | Z12: =AA11 -> 1494900 | AA12: 1500900 | AB12: =AA12-Z12 -> 6000 | AC12: =AD11 -> 444336 | AD12: 444754 | AE12: =AD12-AC12 -> 418 | AF12: =AG11 -> 313750 | AG12: 314160 | AH12: =AG12-AF12 -> 410 | AI12: =AJ11 -> 524950 | AJ12: 525910 | AK12: =AJ12-AI12 -> 960 | AL12: =AM11 -> 975110 | AM12: 976460 | AN12: =AM12-AL12 -> 1350 | AO12: =AP11 -> 620070 | AP12: 620980 | AQ12: =AP12-AO12 -> 910 | AR12: =AS11 -> 456770 | AS12: 458420 | AT12: =AS12-AR12 -> 1650 | AU12: =AV11 -> 404460 | AV12: 406260 | AW12: =AV12-AU12 -> 1800 | AX12: =AY11 -> 317180 | AY12: 318380 | AZ12: =AY12-AX12 -> 1200 | BA12: =BB11 -> 849030 | BB12: 852760 | BC12: =BB12-BA12 -> 3730 | BD12: =BE11 -> 16702 | BE12: 16797 | BF12: =BE12-BD12 -> 95 | BG12: =BH11 -> 13548 | BH12: 13630 | BI12: =BH12-BG12 -> 82 | BJ12: =BK11 -> 12928 | BK12: 13019 | BL12: =BK12-BJ12 -> 91 | BM12: =BN11 -> 20697 | BN12: 20806 | BO12: =BN12-BM12 -> 109 | BP12: =BQ11 -> 13942 | BQ12: 14026 | BR12: =BQ12-BP12 -> 84 | BS12: =BT11 -> 16018 | BT12: 16069 | BU12: =BT12-BS12 -> 51 | BV12: =BW11 -> 10751 | BW12: 10802 | BX12: =BW12-BV12 -> 51 | BY12: =BZ11 -> 27617 | BZ12: 27811 | CA12: =BZ12-BY12 -> 194 | CB12: =CC11 -> 23080 | CC12: 23172 | CD12: =CC12-CB12 -> 92 | CE12: =CF11 -> 66675 | CF12: 66981 | CG12: =CF12-CE12 -> 306 | CH12: =CI11 -> 34064 | CI12: 34416 | CJ12: =CI12-CH12 -> 352 | CK12: =CL11 -> 10998 | CL12: 11004 | CM12: =CL12-CK12 -> 6 | CN12: =CO11 -> 38411 | CO12: 38597 | CP12: =CO12-CN12 -> 186
A13: 5 | B13: =C12 -> 25103892 | C13: 25107536 | D13: =C13-B13 -> 3644 | E13: =F12 -> 21999466 | F13: 22003536 | G13: =F13-E13 -> 4070 | H13: =I12 -> 83776294 | I13: 83790362 | J13: =I13-H13 -> 14068 | K13: =L12 -> 1731100 | L13: 1733200 | M13: =L13-K13 -> 2100 | N13: =O12 -> 2341951 | O13: 2344743 | P13: =O13-N13 -> 2792 | Q13: =R12 -> 1411800 | R13: 1413500 | S13: =R13-Q13 -> 1700 | T13: =U12 -> 662479 | U13: 663179 | V13: =U13-T13 -> 700 | W13: =X12 -> 6852800 | X13: 6858600 | Y13: =X13-W13 -> 5800 | Z13: =AA12 -> 1500900 | AB13: =AA13-Z13 -> -1500900 | AC13: =AD12 -> 444754 | AD13: 445195 | AE13: =AD13-AC13 -> 441 | AF13: =AG12 -> 314160 | AG13: 314640 | AH13: =AG13-AF13 -> 480 | AI13: =AJ12 -> 525910 | AJ13: 526810 | AK13: =AJ13-AI13 -> 900 | AL13: =AM12 -> 976460 | AM13: 977780 | AN13: =AM13-AL13 -> 1320 | AO13: =AP12 -> 620980 | AP13: 621850 | AQ13: =AP13-AO13 -> 870 | AR13: =AS12 -> 458420 | AS13: 460230 | AT13: =AS13-AR13 -> 1810 | AU13: =AV12 -> 406260 | AV13: 407700 | AW13: =AV13-AU13 -> 1440 | AX13: =AY12 -> 318380 | AY13: 319530 | AZ13: =AY13-AX13 -> 1150 | BA13: =BB12 -> 852760 | BB13: 856460 | BC13: =BB13-BA13 -> 3700 | BD13: =BE12 -> 16797 | BE13: 16886 | BF13: =BE13-BD13 -> 89 | BG13: =BH12 -> 13630 | BH13: 13707 | BI13: =BH13-BG13 -> 77 | BJ13: =BK12 -> 13019 | BK13: 13083 | BL13: =BK13-BJ13 -> 64 | BM13: =BN12 -> 20806 | BN13: 20900 | BO13: =BN13-BM13 -> 94 | BP13: =BQ12 -> 14026 | BQ13: 14103 | BR13: =BQ13-BP13 -> 77 | BS13: =BT12 -> 16069 | BT13: 16120 | BU13: =BT13-BS13 -> 51 | BV13: =BW12 -> 10802 | BW13: 10854 | BX13: =BW13-BV13 -> 52 | BY13: =BZ12 -> 27811 | BZ13: 27981 | CA13: =BZ13-BY13 -> 170 | CB13: =CC12 -> 23172 | CC13: 23254 | CD13: =CC13-CB13 -> 82 | CE13: =CF12 -> 66981 | CF13: 67256 | CG13: =CF13-CE13 -> 275 | CH13: =CI12 -> 34416 | CI13: 34793 | CJ13: =CI13-CH13 -> 377 | CK13: =CL12 -> 11004 | CL13: 11095 | CM13: =CL13-CK13 -> 91 | CN13: =CO12 -> 38597 | CO13: 38701 | CP13: =CO13-CN13 -> 104
A14: 6 | B14: =C13 -> 25107536 | D14: =C14-B14 -> -25107536 | E14: =F13 -> 22003536 | G14: =F14-E14 -> -22003536 | H14: =I13 -> 83790362 | J14: =I14-H14 -> -83790362 | K14: =L13 -> 1733200 | M14: =L14-K14 -> -1733200 | N14: =O13 -> 2344743 | P14: =O14-N14 -> -2344743 | Q14: =R13 -> 1413500 | S14: =R14-Q14 -> -1413500 | T14: =U13 -> 663179 | V14: =U14-T14 -> -663179 | W14: =X13 -> 6858600 | Y14: =X14-W14 -> -6858600 | Z14: =AA13 -> 0 | AB14: =AA14-Z14 -> 0 | AC14: =AD13 -> 445195 | AE14: =AD14-AC14 -> -445195 | AF14: =AG13 -> 314640 | AH14: =AG14-AF14 -> -314640 | AI14: =AJ13 -> 526810 | AK14: =AJ14-AI14 -> -526810 | AL14: =AM13 -> 977780 | AN14: =AM14-AL14 -> -977780 | AO14: =AP13 -> 621850 | AQ14: =AP14-AO14 -> -621850 | AR14: =AS13 -> 460230 | AT14: =AS14-AR14 -> -460230 | AU14: =AV13 -> 407700 | AW14: =AV14-AU14 -> -407700 | AX14: =AY13 -> 319530 | AZ14: =AY14-AX14 -> -319530 | BA14: =BB13 -> 856460 | BC14: =BB14-BA14 -> -856460 | BD14: =BE13 -> 16886 | BF14: =BE14-BD14 -> -16886 | BG14: =BH13 -> 13707 | BI14: =BH14-BG14 -> -13707 | BJ14: =BK13 -> 13083 | BL14: =BK14-BJ14 -> -13083 | BM14: =BN13 -> 20900 | BO14: =BN14-BM14 -> -20900 | BP14: =BQ13 -> 14103 | BR14: =BQ14-BP14 -> -14103 | BS14: =BT13 -> 16120 | BU14: =BT14-BS14 -> -16120 | BV14: =BW13 -> 10854 | BX14: =BW14-BV14 -> -10854 | BY14: =BZ13 -> 27981 | CA14: =BZ14-BY14 -> -27981 | CB14: =CC13 -> 23254 | CD14: =CC14-CB14 -> -23254 | CE14: =CF13 -> 67256 | CG14: =CF14-CE14 -> -67256 | CH14: =CI13 -> 34793 | CJ14: =CI14-CH14 -> -34793 | CK14: =CL13 -> 11095 | CM14: =CL14-CK14 -> -11095 | CN14: =CO13 -> 38701 | CP14: =CO14-CN14 -> -38701
A15: 7 | B15: =C14 -> 0 | D15: =C15-B15 -> 0 | E15: =F14 -> 0 | G15: =F15-E15 -> 0 | H15: =I14 -> 0 | J15: =I15-H15 -> 0 | K15: =L14 -> 0 | M15: =L15-K15 -> 0 | N15: =O14 -> 0 | P15: =O15-N15 -> 0 | Q15: =R14 -> 0 | S15: =R15-Q15 -> 0 | T15: =U14 -> 0 | V15: =U15-T15 -> 0 | W15: =X14 -> 0 | Y15: =X15-W15 -> 0 | Z15: =AA14 -> 0 | AB15: =AA15-Z15 -> 0 | AC15: =AD14 -> 0 | AE15: =AD15-AC15 -> 0 | AF15: =AG14 -> 0 | AH15: =AG15-AF15 -> 0 | AI15: =AJ14 -> 0 | AK15: =AJ15-AI15 -> 0 | AL15: =AM14 -> 0 | AN15: =AM15-AL15 -> 0 | AO15: =AP14 -> 0 | AQ15: =AP15-AO15 -> 0 | AR15: =AS14 -> 0 | AT15: =AS15-AR15 -> 0 | AU15: =AV14 -> 0 | AW15: =AV15-AU15 -> 0 | AX15: =AY14 -> 0 | AZ15: =AY15-AX15 -> 0 | BA15: =BB14 -> 0 | BC15: =BB15-BA15 -> 0 | BD15: =BE14 -> 0 | BF15: =BE15-BD15 -> 0 | BG15: =BH14 -> 0 | BI15: =BH15-BG15 -> 0 | BJ15: =BK14 -> 0 | BL15: =BK15-BJ15 -> 0 | BM15: =BN14 -> 0 | BO15: =BN15-BM15 -> 0 | BP15: =BQ14 -> 0 | BR15: =BQ15-BP15 -> 0 | BS15: =BT14 -> 0 | BU15: =BT15-BS15 -> 0 | BV15: =BW14 -> 0 | BX15: =BW15-BV15 -> 0 | BY15: =BZ14 -> 0 | CA15: =BZ15-BY15 -> 0 | CB15: =CC14 -> 0 | CD15: =CC15-CB15 -> 0 | CE15: =CF14 -> 0 | CG15: =CF15-CE15 -> 0 | CH15: =CI14 -> 0 | CJ15: =CI15-CH15 -> 0 | CK15: =CL14 -> 0 | CM15: =CL15-CK15 -> 0 | CN15: =CO14 -> 0 | CP15: =CO15-CN15 -> 0
A16: 8 | B16: =C15 -> 0 | D16: =C16-B16 -> 0 | E16: =F15 -> 0 | G16: =F16-E16 -> 0 | H16: =I15 -> 0 | J16: =I16-H16 -> 0 | K16: =L15 -> 0 | M16: =L16-K16 -> 0 | N16: =O15 -> 0 | P16: =O16-N16 -> 0 | Q16: =R15 -> 0 | S16: =R16-Q16 -> 0 | T16: =U15 -> 0 | V16: =U16-T16 -> 0 | W16: =X15 -> 0 | Y16: =X16-W16 -> 0 | Z16: =AA15 -> 0 | AB16: =AA16-Z16 -> 0 | AC16: =AD15 -> 0 | AE16: =AD16-AC16 -> 0 | AF16: =AG15 -> 0 | AH16: =AG16-AF16 -> 0 | AI16: =AJ15 -> 0 | AK16: =AJ16-AI16 -> 0 | AL16: =AM15 -> 0 | AN16: =AM16-AL16 -> 0 | AO16: =AP15 -> 0 | AQ16: =AP16-AO16 -> 0 | AR16: =AS15 -> 0 | AT16: =AS16-AR16 -> 0 | AU16: =AV15 -> 0 | AW16: =AV16-AU16 -> 0 | AX16: =AY15 -> 0 | AZ16: =AY16-AX16 -> 0 | BA16: =BB15 -> 0 | BC16: =BB16-BA16 -> 0 | BD16: =BE15 -> 0 | BF16: =BE16-BD16 -> 0 | BG16: =BH15 -> 0 | BI16: =BH16-BG16 -> 0 | BJ16: =BK15 -> 0 | BL16: =BK16-BJ16 -> 0 | BM16: =BN15 -> 0 | BO16: =BN16-BM16 -> 0 | BP16: =BQ15 -> 0 | BR16: =BQ16-BP16 -> 0 | BS16: =BT15 -> 0 | BU16: =BT16-BS16 -> 0 | BV16: =BW15 -> 0 | BX16: =BW16-BV16 -> 0 | BY16: =BZ15 -> 0 | CA16: =BZ16-BY16 -> 0 | CB16: =CC15 -> 0 | CD16: =CC16-CB16 -> 0 | CE16: =CF15 -> 0 | CG16: =CF16-CE16 -> 0 | CH16: =CI15 -> 0 | CJ16: =CI16-CH16 -> 0 | CK16: =CL15 -> 0 | CM16: =CL16-CK16 -> 0 | CN16: =CO15 -> 0 | CP16: =CO16-CN16 -> 0
A17: 9 | B17: =C16 -> 0 | D17: =C17-B17 -> 0 | E17: =F16 -> 0 | G17: =F17-E17 -> 0 | H17: =I16 -> 0 | J17: =I17-H17 -> 0 | K17: =L16 -> 0 | M17: =L17-K17 -> 0 | N17: =O16 -> 0 | P17: =O17-N17 -> 0 | Q17: =R16 -> 0 | S17: =R17-Q17 -> 0 | T17: =U16 -> 0 | V17: =U17-T17 -> 0 | W17: =X16 -> 0 | Y17: =X17-W17 -> 0 | Z17: =AA16 -> 0 | AB17: =AA17-Z17 -> 0 | AC17: =AD16 -> 0 | AE17: =AD17-AC17 -> 0 | AF17: =AG16 -> 0 | AH17: =AG17-AF17 -> 0 | AI17: =AJ16 -> 0 | AK17: =AJ17-AI17 -> 0 | AL17: =AM16 -> 0 | AN17: =AM17-AL17 -> 0 | AO17: =AP16 -> 0 | AQ17: =AP17-AO17 -> 0 | AR17: =AS16 -> 0 | AT17: =AS17-AR17 -> 0 | AU17: =AV16 -> 0 | AW17: =AV17-AU17 -> 0 | AX17: =AY16 -> 0 | AZ17: =AY17-AX17 -> 0 | BA17: =BB16 -> 0 | BC17: =BB17-BA17 -> 0 | BD17: =BE16 -> 0 | BF17: =BE17-BD17 -> 0 | BG17: =BH16 -> 0 | BI17: =BH17-BG17 -> 0 | BJ17: =BK16 -> 0 | BL17: =BK17-BJ17 -> 0 | BM17: =BN16 -> 0 | BO17: =BN17-BM17 -> 0 | BP17: =BQ16 -> 0 | BR17: =BQ17-BP17 -> 0 | BS17: =BT16 -> 0 | BU17: =BT17-BS17 -> 0 | BV17: =BW16 -> 0 | BX17: =BW17-BV17 -> 0 | BY17: =BZ16 -> 0 | CA17: =BZ17-BY17 -> 0 | CB17: =CC16 -> 0 | CD17: =CC17-CB17 -> 0 | CE17: =CF16 -> 0 | CG17: =CF17-CE17 -> 0 | CH17: =CI16 -> 0 | CJ17: =CI17-CH17 -> 0 | CK17: =CL16 -> 0 | CM17: =CL17-CK17 -> 0 | CN17: =CO16 -> 0 | CP17: =CO17-CN17 -> 0
A18: 10 | B18: =C17 -> 0 | D18: =C18-B18 -> 0 | E18: =F17 -> 0 | G18: =F18-E18 -> 0 | H18: =I17 -> 0 | J18: =I18-H18 -> 0 | K18: =L17 -> 0 | M18: =L18-K18 -> 0 | N18: =O17 -> 0 | P18: =O18-N18 -> 0 | Q18: =R17 -> 0 | S18: =R18-Q18 -> 0 | T18: =U17 -> 0 | V18: =U18-T18 -> 0 | W18: =X17 -> 0 | Y18: =X18-W18 -> 0 | Z18: =AA17 -> 0 | AB18: =AA18-Z18 -> 0 | AC18: =AD17 -> 0 | AE18: =AD18-AC18 -> 0 | AF18: =AG17 -> 0 | AH18: =AG18-AF18 -> 0 | AI18: =AJ17 -> 0 | AK18: =AJ18-AI18 -> 0 | AL18: =AM17 -> 0 | AN18: =AM18-AL18 -> 0 | AO18: =AP17 -> 0 | AQ18: =AP18-AO18 -> 0 | AR18: =AS17 -> 0 | AT18: =AS18-AR18 -> 0 | AU18: =AV17 -> 0 | AW18: =AV18-AU18 -> 0 | AX18: =AY17 -> 0 | AZ18: =AY18-AX18 -> 0 | BA18: =BB17 -> 0 | BC18: =BB18-BA18 -> 0 | BD18: =BE17 -> 0 | BF18: =BE18-BD18 -> 0 | BG18: =BH17 -> 0 | BI18: =BH18-BG18 -> 0 | BJ18: =BK17 -> 0 | BL18: =BK18-BJ18 -> 0 | BM18: =BN17 -> 0 | BO18: =BN18-BM18 -> 0 | BP18: =BQ17 -> 0 | BR18: =BQ18-BP18 -> 0 | BS18: =BT17 -> 0 | BU18: =BT18-BS18 -> 0 | BV18: =BW17 -> 0 | BX18: =BW18-BV18 -> 0 | BY18: =BZ17 -> 0 | CA18: =BZ18-BY18 -> 0 | CB18: =CC17 -> 0 | CD18: =CC18-CB18 -> 0 | CE18: =CF17 -> 0 | CG18: =CF18-CE18 -> 0 | CH18: =CI17 -> 0 | CJ18: =CI18-CH18 -> 0 | CK18: =CL17 -> 0 | CM18: =CL18-CK18 -> 0 | CN18: =CO17 -> 0 | CP18: =CO18-CN18 -> 0
A19: 11 | B19: =C18 -> 0 | D19: =C19-B19 -> 0 | E19: =F18 -> 0 | G19: =F19-E19 -> 0 | H19: =I18 -> 0 | J19: =I19-H19 -> 0 | K19: =L18 -> 0 | M19: =L19-K19 -> 0 | N19: =O18 -> 0 | P19: =O19-N19 -> 0 | Q19: =R18 -> 0 | S19: =R19-Q19 -> 0 | T19: =U18 -> 0 | V19: =U19-T19 -> 0 | W19: =X18 -> 0 | Y19: =X19-W19 -> 0 | Z19: =AA18 -> 0 | AB19: =AA19-Z19 -> 0 | AC19: =AD18 -> 0 | AE19: =AD19-AC19 -> 0 | AF19: =AG18 -> 0 | AH19: =AG19-AF19 -> 0 | AI19: =AJ18 -> 0 | AK19: =AJ19-AI19 -> 0 | AL19: =AM18 -> 0 | AN19: =AM19-AL19 -> 0 | AO19: =AP18 -> 0 | AQ19: =AP19-AO19 -> 0 | AR19: =AS18 -> 0 | AT19: =AS19-AR19 -> 0 | AU19: =AV18 -> 0 | AW19: =AV19-AU19 -> 0 | AX19: =AY18 -> 0 | AZ19: =AY19-AX19 -> 0 | BA19: =BB18 -> 0 | BC19: =BB19-BA19 -> 0 | BD19: =BE18 -> 0 | BF19: =BE19-BD19 -> 0 | BG19: =BH18 -> 0 | BI19: =BH19-BG19 -> 0 | BJ19: =BK18 -> 0 | BL19: =BK19-BJ19 -> 0 | BM19: =BN18 -> 0 | BO19: =BN19-BM19 -> 0 | BP19: =BQ18 -> 0 | BR19: =BQ19-BP19 -> 0 | BS19: =BT18 -> 0 | BU19: =BT19-BS19 -> 0 | BV19: =BW18 -> 0 | BX19: =BW19-BV19 -> 0 | BY19: =BZ18 -> 0 | CA19: =BZ19-BY19 -> 0 | CB19: =CC18 -> 0 | CD19: =CC19-CB19 -> 0 | CE19: =CF18 -> 0 | CG19: =CF19-CE19 -> 0 | CH19: =CI18 -> 0 | CJ19: =CI19-CH19 -> 0 | CK19: =CL18 -> 0 | CM19: =CL19-CK19 -> 0 | CN19: =CO18 -> 0 | CP19: =CO19-CN19 -> 0
A20: 12 | B20: =C19 -> 0 | D20: =C20-B20 -> 0 | E20: =F19 -> 0 | G20: =F20-E20 -> 0 | H20: =I19 -> 0 | J20: =I20-H20 -> 0 | K20: =L19 -> 0 | M20: =L20-K20 -> 0 | N20: =O19 -> 0 | P20: =O20-N20 -> 0 | Q20: =R19 -> 0 | S20: =R20-Q20 -> 0 | T20: =U19 -> 0 | V20: =U20-T20 -> 0 | W20: =X19 -> 0 | Y20: =X20-W20 -> 0 | Z20: =AA19 -> 0 | AB20: =AA20-Z20 -> 0 | AC20: =AD19 -> 0 | AE20: =AD20-AC20 -> 0 | AF20: =AG19 -> 0 | AH20: =AG20-AF20 -> 0 | AI20: =AJ19 -> 0 | AK20: =AJ20-AI20 -> 0 | AL20: =AM19 -> 0 | AN20: =AM20-AL20 -> 0 | AO20: =AP19 -> 0 | AQ20: =AP20-AO20 -> 0 | AR20: =AS19 -> 0 | AT20: =AS20-AR20 -> 0 | AU20: =AV19 -> 0 | AW20: =AV20-AU20 -> 0 | AX20: =AY19 -> 0 | AZ20: =AY20-AX20 -> 0 | BA20: =BB19 -> 0 | BC20: =BB20-BA20 -> 0 | BD20: =BE19 -> 0 | BF20: =BE20-BD20 -> 0 | BG20: =BH19 -> 0 | BI20: =BH20-BG20 -> 0 | BJ20: =BK19 -> 0 | BL20: =BK20-BJ20 -> 0 | BM20: =BN19 -> 0 | BO20: =BN20-BM20 -> 0 | BP20: =BQ19 -> 0 | BR20: =BQ20-BP20 -> 0 | BS20: =BT19 -> 0 | BU20: =BT20-BS20 -> 0 | BV20: =BW19 -> 0 | BX20: =BW20-BV20 -> 0 | BY20: =BZ19 -> 0 | CA20: =BZ20-BY20 -> 0 | CB20: =CC19 -> 0 | CD20: =CC20-CB20 -> 0 | CE20: =CF19 -> 0 | CG20: =CF20-CE20 -> 0 | CH20: =CI19 -> 0 | CJ20: =CI20-CH20 -> 0 | CK20: =CL19 -> 0 | CM20: =CL20-CK20 -> 0 | CN20: =CO19 -> 0 | CP20: =CO20-CN20 -> 0
A21: 13 | B21: =C20 -> 0 | D21: =C21-B21 -> 0 | E21: =F20 -> 0 | G21: =F21-E21 -> 0 | H21: =I20 -> 0 | J21: =I21-H21 -> 0 | K21: =L20 -> 0 | M21: =L21-K21 -> 0 | N21: =O20 -> 0 | P21: =O21-N21 -> 0 | Q21: =R20 -> 0 | S21: =R21-Q21 -> 0 | T21: =U20 -> 0 | V21: =U21-T21 -> 0 | W21: =X20 -> 0 | Y21: =X21-W21 -> 0 | Z21: =AA20 -> 0 | AB21: =AA21-Z21 -> 0 | AC21: =AD20 -> 0 | AE21: =AD21-AC21 -> 0 | AF21: =AG20 -> 0 | AH21: =AG21-AF21 -> 0 | AI21: =AJ20 -> 0 | AK21: =AJ21-AI21 -> 0 | AL21: =AM20 -> 0 | AN21: =AM21-AL21 -> 0 | AO21: =AP20 -> 0 | AQ21: =AP21-AO21 -> 0 | AR21: =AS20 -> 0 | AT21: =AS21-AR21 -> 0 | AU21: =AV20 -> 0 | AW21: =AV21-AU21 -> 0 | AX21: =AY20 -> 0 | AZ21: =AY21-AX21 -> 0 | BA21: =BB20 -> 0 | BC21: =BB21-BA21 -> 0 | BD21: =BE20 -> 0 | BF21: =BE21-BD21 -> 0 | BG21: =BH20 -> 0 | BI21: =BH21-BG21 -> 0 | BJ21: =BK20 -> 0 | BL21: =BK21-BJ21 -> 0 | BM21: =BN20 -> 0 | BO21: =BN21-BM21 -> 0 | BP21: =BQ20 -> 0 | BR21: =BQ21-BP21 -> 0 | BS21: =BT20 -> 0 | BU21: =BT21-BS21 -> 0 | BV21: =BW20 -> 0 | BX21: =BW21-BV21 -> 0 | BY21: =BZ20 -> 0 | CA21: =BZ21-BY21 -> 0 | CB21: =CC20 -> 0 | CD21: =CC21-CB21 -> 0 | CE21: =CF20 -> 0 | CG21: =CF21-CE21 -> 0 | CH21: =CI20 -> 0 | CJ21: =CI21-CH21 -> 0 | CK21: =CL20 -> 0 | CM21: =CL21-CK21 -> 0 | CN21: =CO20 -> 0 | CP21: =CO21-CN21 -> 0
A22: 14 | B22: =C21 -> 0 | D22: =C22-B22 -> 0 | E22: =F21 -> 0 | G22: =F22-E22 -> 0 | H22: =I21 -> 0 | J22: =I22-H22 -> 0 | K22: =L21 -> 0 | M22: =L22-K22 -> 0 | N22: =O21 -> 0 | P22: =O22-N22 -> 0 | Q22: =R21 -> 0 | S22: =R22-Q22 -> 0 | T22: =U21 -> 0 | V22: =U22-T22 -> 0 | W22: =X21 -> 0 | Y22: =X22-W22 -> 0 | Z22: =AA21 -> 0 | AB22: =AA22-Z22 -> 0 | AC22: =AD21 -> 0 | AE22: =AD22-AC22 -> 0 | AF22: =AG21 -> 0 | AH22: =AG22-AF22 -> 0 | AI22: =AJ21 -> 0 | AK22: =AJ22-AI22 -> 0 | AL22: =AM21 -> 0 | AN22: =AM22-AL22 -> 0 | AO22: =AP21 -> 0 | AQ22: =AP22-AO22 -> 0 | AR22: =AS21 -> 0 | AT22: =AS22-AR22 -> 0 | AU22: =AV21 -> 0 | AW22: =AV22-AU22 -> 0 | AX22: =AY21 -> 0 | AZ22: =AY22-AX22 -> 0 | BA22: =BB21 -> 0 | BC22: =BB22-BA22 -> 0 | BD22: =BE21 -> 0 | BF22: =BE22-BD22 -> 0 | BG22: =BH21 -> 0 | BI22: =BH22-BG22 -> 0 | BJ22: =BK21 -> 0 | BL22: =BK22-BJ22 -> 0 | BM22: =BN21 -> 0 | BO22: =BN22-BM22 -> 0 | BP22: =BQ21 -> 0 | BR22: =BQ22-BP22 -> 0 | BS22: =BT21 -> 0 | BU22: =BT22-BS22 -> 0 | BV22: =BW21 -> 0 | BX22: =BW22-BV22 -> 0 | BY22: =BZ21 -> 0 | CA22: =BZ22-BY22 -> 0 | CB22: =CC21 -> 0 | CD22: =CC22-CB22 -> 0 | CE22: =CF21 -> 0 | CG22: =CF22-CE22 -> 0 | CH22: =CI21 -> 0 | CJ22: =CI22-CH22 -> 0 | CK22: =CL21 -> 0 | CM22: =CL22-CK22 -> 0 | CN22: =CO21 -> 0 | CP22: =CO22-CN22 -> 0
A23: 15 | B23: =C22 -> 0 | D23: =C23-B23 -> 0 | E23: =F22 -> 0 | G23: =F23-E23 -> 0 | H23: =I22 -> 0 | J23: =I23-H23 -> 0 | K23: =L22 -> 0 | M23: =L23-K23 -> 0 | N23: =O22 -> 0 | P23: =O23-N23 -> 0 | Q23: =R22 -> 0 | S23: =R23-Q23 -> 0 | T23: =U22 -> 0 | V23: =U23-T23 -> 0 | W23: =X22 -> 0 | Y23: =X23-W23 -> 0 | Z23: =AA22 -> 0 | AB23: =AA23-Z23 -> 0 | AC23: =AD22 -> 0 | AE23: =AD23-AC23 -> 0 | AF23: =AG22 -> 0 | AH23: =AG23-AF23 -> 0 | AI23: =AJ22 -> 0 | AK23: =AJ23-AI23 -> 0 | AL23: =AM22 -> 0 | AN23: =AM23-AL23 -> 0 | AO23: =AP22 -> 0 | AQ23: =AP23-AO23 -> 0 | AR23: =AS22 -> 0 | AT23: =AS23-AR23 -> 0 | AU23: =AV22 -> 0 | AW23: =AV23-AU23 -> 0 | AX23: =AY22 -> 0 | AZ23: =AY23-AX23 -> 0 | BA23: =BB22 -> 0 | BC23: =BB23-BA23 -> 0 | BD23: =BE22 -> 0 | BF23: =BE23-BD23 -> 0 | BG23: =BH22 -> 0 | BI23: =BH23-BG23 -> 0 | BJ23: =BK22 -> 0 | BL23: =BK23-BJ23 -> 0 | BM23: =BN22 -> 0 | BO23: =BN23-BM23 -> 0 | BP23: =BQ22 -> 0 | BR23: =BQ23-BP23 -> 0 | BS23: =BT22 -> 0 | BU23: =BT23-BS23 -> 0 | BV23: =BW22 -> 0 | BX23: =BW23-BV23 -> 0 | BY23: =BZ22 -> 0 | CA23: =BZ23-BY23 -> 0 | CB23: =CC22 -> 0 | CD23: =CC23-CB23 -> 0 | CE23: =CF22 -> 0 | CG23: =CF23-CE23 -> 0 | CH23: =CI22 -> 0 | CJ23: =CI23-CH23 -> 0 | CK23: =CL22 -> 0 | CM23: =CL23-CK23 -> 0 | CN23: =CO22 -> 0 | CP23: =CO23-CN23 -> 0
A24: 16 | B24: =C23 -> 0 | D24: =C24-B24 -> 0 | E24: =F23 -> 0 | G24: =F24-E24 -> 0 | H24: =I23 -> 0 | J24: =I24-H24 -> 0 | K24: =L23 -> 0 | M24: =L24-K24 -> 0 | N24: =O23 -> 0 | P24: =O24-N24 -> 0 | Q24: =R23 -> 0 | S24: =R24-Q24 -> 0 | T24: =U23 -> 0 | V24: =U24-T24 -> 0 | W24: =X23 -> 0 | Y24: =X24-W24 -> 0 | Z24: =AA23 -> 0 | AB24: =AA24-Z24 -> 0 | AC24: =AD23 -> 0 | AE24: =AD24-AC24 -> 0 | AF24: =AG23 -> 0 | AH24: =AG24-AF24 -> 0 | AI24: =AJ23 -> 0 | AK24: =AJ24-AI24 -> 0 | AL24: =AM23 -> 0 | AN24: =AM24-AL24 -> 0 | AO24: =AP23 -> 0 | AQ24: =AP24-AO24 -> 0 | AR24: =AS23 -> 0 | AT24: =AS24-AR24 -> 0 | AU24: =AV23 -> 0 | AW24: =AV24-AU24 -> 0 | AX24: =AY23 -> 0 | AZ24: =AY24-AX24 -> 0 | BA24: =BB23 -> 0 | BC24: =BB24-BA24 -> 0 | BD24: =BE23 -> 0 | BF24: =BE24-BD24 -> 0 | BG24: =BH23 -> 0 | BI24: =BH24-BG24 -> 0 | BJ24: =BK23 -> 0 | BL24: =BK24-BJ24 -> 0 | BM24: =BN23 -> 0 | BO24: =BN24-BM24 -> 0 | BP24: =BQ23 -> 0 | BR24: =BQ24-BP24 -> 0 | BS24: =BT23 -> 0 | BU24: =BT24-BS24 -> 0 | BV24: =BW23 -> 0 | BX24: =BW24-BV24 -> 0 | BY24: =BZ23 -> 0 | CA24: =BZ24-BY24 -> 0 | CB24: =CC23 -> 0 | CD24: =CC24-CB24 -> 0 | CE24: =CF23 -> 0 | CG24: =CF24-CE24 -> 0 | CH24: =CI23 -> 0 | CJ24: =CI24-CH24 -> 0 | CK24: =CL23 -> 0 | CM24: =CL24-CK24 -> 0 | CN24: =CO23 -> 0 | CP24: =CO24-CN24 -> 0
A25: 17 | B25: =C24 -> 0 | D25: =C25-B25 -> 0 | E25: =F24 -> 0 | G25: =F25-E25 -> 0 | H25: =I24 -> 0 | J25: =I25-H25 -> 0 | K25: =L24 -> 0 | M25: =L25-K25 -> 0 | N25: =O24 -> 0 | P25: =O25-N25 -> 0 | Q25: =R24 -> 0 | S25: =R25-Q25 -> 0 | T25: =U24 -> 0 | V25: =U25-T25 -> 0 | W25: =X24 -> 0 | Y25: =X25-W25 -> 0 | Z25: =AA24 -> 0 | AB25: =AA25-Z25 -> 0 | AC25: =AD24 -> 0 | AE25: =AD25-AC25 -> 0 | AF25: =AG24 -> 0 | AH25: =AG25-AF25 -> 0 | AI25: =AJ24 -> 0 | AK25: =AJ25-AI25 -> 0 | AL25: =AM24 -> 0 | AN25: =AM25-AL25 -> 0 | AO25: =AP24 -> 0 | AQ25: =AP25-AO25 -> 0 | AR25: =AS24 -> 0 | AT25: =AS25-AR25 -> 0 | AU25: =AV24 -> 0 | AW25: =AV25-AU25 -> 0 | AX25: =AY24 -> 0 | AZ25: =AY25-AX25 -> 0 | BA25: =BB24 -> 0 | BC25: =BB25-BA25 -> 0 | BD25: =BE24 -> 0 | BF25: =BE25-BD25 -> 0 | BG25: =BH24 -> 0 | BI25: =BH25-BG25 -> 0 | BJ25: =BK24 -> 0 | BL25: =BK25-BJ25 -> 0 | BM25: =BN24 -> 0 | BO25: =BN25-BM25 -> 0 | BP25: =BQ24 -> 0 | BR25: =BQ25-BP25 -> 0 | BS25: =BT24 -> 0 | BU25: =BT25-BS25 -> 0 | BV25: =BW24 -> 0 | BX25: =BW25-BV25 -> 0 | BY25: =BZ24 -> 0 | CA25: =BZ25-BY25 -> 0 | CB25: =CC24 -> 0 | CD25: =CC25-CB25 -> 0 | CE25: =CF24 -> 0 | CG25: =CF25-CE25 -> 0 | CH25: =CI24 -> 0 | CJ25: =CI25-CH25 -> 0 | CK25: =CL24 -> 0 | CM25: =CL25-CK25 -> 0 | CN25: =CO24 -> 0 | CP25: =CO25-CN25 -> 0
... A38: 30 | B38: =C37 -> 0 | D38: =C38-B38 -> 0 | E38: =F37 -> 0 | G38: =F38-E38 -> 0 | H38: =I37 -> 0 | J38: =I38-H38 -> 0 | K38: =L37 -> 0 | M38: =L38-K38 -> 0 | N38: =O37 -> 0 | P38: =O38-N38 -> 0 | Q38: =R37 -> 0 | S38: =R38-Q38 -> 0 | T38: =U37 -> 0 | V38: =U38-T38 -> 0 | W38: =X37 -> 0 | Y38: =X38-W38 -> 0 | Z38: =AA37 -> 0 | AB38: =AA38-Z38 -> 0 | AC38: =AD37 -> 0 | AE38: =AD38-AC38 -> 0 | AF38: =AG37 -> 0 | AH38: =AG38-AF38 -> 0 | AI38: =AJ37 -> 0 | AK38: =AJ38-AI38 -> 0 | AL38: =AM37 -> 0 | AN38: =AM38-AL38 -> 0 | AO38: =AP37 -> 0 | AQ38: =AP38-AO38 -> 0 | AR38: =AS37 -> 0 | AT38: =AS38-AR38 -> 0 | AU38: =AV37 -> 0 | AW38: =AV38-AU38 -> 0 | AX38: =AY37 -> 0 | AZ38: =AY38-AX38 -> 0 | BA38: =BB37 -> 0 | BC38: =BB38-BA38 -> 0 | BD38: =BE37 -> 0 | BF38: =BE38-BD38 -> 0 | BG38: =BH37 -> 0 | BI38: =BH38-BG38 -> 0 | BJ38: =BK37 -> 0 | BL38: =BK38-BJ38 -> 0 | BM38: =BN37 -> 0 | BO38: =BN38-BM38 -> 0 | BP38: =BQ37 -> 0 | BR38: =BQ38-BP38 -> 0 | BS38: =BT37 -> 0 | BU38: =BT38-BS38 -> 0 | BV38: =BW37 -> 0 | BX38: =BW38-BV38 -> 0 | BY38: =BZ37 -> 0 | CA38: =BZ38-BY38 -> 0 | CB38: =CC37 -> 0 | CD38: =CC38-CB38 -> 0 | CE38: =CF37 -> 0 | CG38: =CF38-CE38 -> 0 | CH38: =CI37 -> 0 | CJ38: =CI38-CH38 -> 0 | CK38: =CL37 -> 0 | CM38: =CL38-CK38 -> 0 | CN38: =CO37 -> 0 | CP38: =CO38-CN38 -> 0
A39: 31 | B39: =C38 -> 0 | D39: =C39-B39 -> 0 | E39: =F38 -> 0 | G39: =F39-E39 -> 0 | H39: =I38 -> 0 | J39: =I39-H39 -> 0 | K39: =L38 -> 0 | M39: =L39-K39 -> 0 | N39: =O38 -> 0 | P39: =O39-N39 -> 0 | Q39: =R38 -> 0 | S39: =R39-Q39 -> 0 | T39: =U38 -> 0 | V39: =U39-T39 -> 0 | W39: =X38 -> 0 | Y39: =X39-W39 -> 0 | Z39: =AA38 -> 0 | AB39: =AA39-Z39 -> 0 | AC39: =AD38 -> 0 | AE39: =AD39-AC39 -> 0 | AF39: =AG38 -> 0 | AH39: =AG39-AF39 -> 0 | AI39: =AJ38 -> 0 | AK39: =AJ39-AI39 -> 0 | AL39: =AM38 -> 0 | AN39: =AM39-AL39 -> 0 | AO39: =AP38 -> 0 | AQ39: =AP39-AO39 -> 0 | AR39: =AS38 -> 0 | AT39: =AS39-AR39 -> 0 | AU39: =AV38 -> 0 | AW39: =AV39-AU39 -> 0 | AX39: =AY38 -> 0 | AZ39: =AY39-AX39 -> 0 | BA39: =BB38 -> 0 | BC39: =BB39-BA39 -> 0 | BD39: =BE38 -> 0 | BF39: =BE39-BD39 -> 0 | BG39: =BH38 -> 0 | BI39: =BH39-BG39 -> 0 | BJ39: =BK38 -> 0 | BL39: =BK39-BJ39 -> 0 | BM39: =BN38 -> 0 | BP39: =BQ38 -> 0 | BR39: =BQ39-BP39 -> 0 | BS39: =BT38 -> 0 | BU39: =BT39-BS39 -> 0 | BV39: =BW38 -> 0 | BX39: =BW39-BV39 -> 0 | BY39: =BZ38 -> 0 | CA39: =BZ39-BY39 -> 0 | CB39: =CC38 -> 0 | CD39: =CC39-CB39 -> 0 | CE39: =CF38 -> 0 | CG39: =CF39-CE39 -> 0 | CH39: =CI38 -> 0 | CJ39: =CI39-CH39 -> 0 | CK39: =CL38 -> 0 | CM39: =CL39-CK39 -> 0 | CN39: =CO38 -> 0 | CP39: =CO39-CN39 -> 0
A40: Total | D40: =SUM(D9:D39) -> -25088084 | G40: =SUM(G9:G39) -> -21981188 | J40: =SUM(J9:J39) -> -83718230 | M40: =SUM(M9:M39) -> -1722220 | P40: =SUM(P9:P39) -> -2330923 | S40: =SUM(S9:S39) -> -1403900 | V40: =SUM(V9:V39) -> -659727 | Y40: =SUM(Y9:Y39) -> -6827800 | AB40: =SUM(AB9:AB39) -> -1485900 | AE40: =SUM(AE9:AE39) -> -443008 | AH40: =SUM(AH9:AH39) -> -312460 | AK40: =SUM(AK9:AK39) -> -522300 | AN40: =SUM(AN9:AN39) -> -971190 | AQ40: =SUM(AQ9:AQ39) -> -617560 | AT40: =SUM(AT9:AT39) -> -455500 | AW40: =SUM(AW9:AW39) -> -398160 | AZ40: =SUM(AZ9:AZ39) -> -313610 | BC40: =SUM(BC9:BC39) -> -838750 | BF40: =SUM(BF9:BF39) -> -16414 | BI40: =SUM(BI9:BI39) -> -13337 | BL40: =SUM(BL9:BL39) -> -12664 | BO40: =SUM(BO9:BO39) -> -20408 | BR40: =SUM(BR9:BR39) -> -13725 | BU40: =SUM(BU9:BU39) -> -15869 | BX40: =SUM(BX9:BX39) -> -10596 | CA40: =SUM(CA9:CA39) -> -27031 | CD40: =SUM(CD9:CD39) -> -22769 | CG40: =SUM(CG9:CG39) -> -65938 | CJ40: =SUM(CJ9:CJ39) -> -33060 | CM40: =SUM(CM9:CM39) -> -10817 | CP40: =SUM(CP9:CP39) -> -38022

Sheet WATER
A1: RO Plant Water Production Reading
A3: Month | C3: 44197
A4: R/O Plant A | F4: R/O Plant B | K4: R/O Plant C | P4: R/O Plant D | U4: Total Production
A5: DAY | B5: YESTARDAY | C5: TODAY | D5: Production (M3) | F5: DAY | G5: YESTARDAY | H5: TODAY | I5: Production (M3) | K5: DAY | L5: YESTARDAY | M5: TODAY | N5: Production (M3) | P5: DAY | Q5: YESTARDAY | R5: TODAY | S5: Production (M3) | U5: Day | V5: Water | W5: Occ% | X5: ADR $
A6: 1 | B6: 0 | C6: 0 | D6: =C6-B6 -> 0 | F6: 1 | G6: 834 | H6: 907 | I6: =H6-G6 -> 73 | K6: 1 | L6: 708651 | M6: 708897 | N6: =M6-L6 -> 246 | P6: 1 | Q6: 191812 | R6: 191908 | S6: =R6-Q6 -> 96 | U6: 1 | V6: =SUM(S6+N6+I6+D6) -> 415 | W6: 97.09
A7: 2 | B7: =C6 -> 0 | C7: 0 | D7: =C7-B7 -> 0 | F7: 2 | G7: =H6 -> 907 | H7: 954 | I7: =H7-G7 -> 47 | K7: 2 | L7: =M6 -> 708897 | M7: 709136 | N7: =M7-L7 -> 239 | P7: 2 | Q7: =R6 -> 191908 | R7: 191990 | S7: =R7-Q7 -> 82 | U7: 2 | V7: =SUM(S7+N7+I7+D7) -> 368 | W7: 95.15
A8: 3 | B8: =C7 -> 0 | C8: 0 | D8: =C8-B8 -> 0 | F8: 3 | G8: =H7 -> 954 | H8: 1036 | I8: =H8-G8 -> 82 | K8: 3 | L8: =M7 -> 709136 | M8: 709343 | N8: =M8-L8 -> 207 | P8: 3 | Q8: =R7 -> 191990 | R8: 192094 | S8: =R8-Q8 -> 104 | U8: 3 | V8: =SUM(S8+N8+I8+D8) -> 393 | W8: 99.03
A9: 4 | B9: =C8 -> 0 | C9: 0 | D9: =C9-B9 -> 0 | F9: 4 | G9: =H8 -> 1036 | H9: 1114 | I9: =H9-G9 -> 78 | K9: 4 | L9: =M8 -> 709343 | M9: 709605 | N9: =M9-L9 -> 262 | P9: 4 | Q9: =R8 -> 192094 | R9: 192205 | S9: =R9-Q9 -> 111 | U9: 4 | V9: =SUM(S9+N9+I9+D9) -> 451 | W9: 98.06
A10: 5 | B10: =C9 -> 0 | C10: 0 | D10: =C10-B10 -> 0 | F10: 5 | G10: =H9 -> 1114 | H10: 1177 | I10: =H10-G10 -> 63 | K10: 5 | L10: =M9 -> 709605 | M10: 709849 | N10: =M10-L10 -> 244 | P10: 5 | Q10: =R9 -> 192205 | R10: 192304 | S10: =R10-Q10 -> 99 | U10: 5 | V10: =SUM(S10+N10+I10+D10) -> 406 | W10: 98.06
A11: 6 | B11: =C10 -> 0 | C11: 0 | D11: =C11-B11 -> 0 | F11: 6 | G11: =H10 -> 1177 | H11: 1247 | I11: =H11-G11 -> 70 | K11: 6 | L11: =M10 -> 709849 | M11: 710060 | N11: =M11-L11 -> 211 | P11: 6 | Q11: =R10 -> 192304 | R11: 192379 | S11: =R11-Q11 -> 75 | U11: 6 | V11: =SUM(S11+N11+I11+D11) -> 356
A12: 7 | B12: =C11 -> 0 | D12: =C12-B12 -> 0 | F12: 7 | G12: =H11 -> 1247 | I12: =H12-G12 -> -1247 | K12: 7 | L12: =M11 -> 710060 | N12: =M12-L12 -> -710060 | P12: 7 | Q12: =R11 -> 192379 | S12: =R12-Q12 -> -192379 | U12: 7 | V12: =SUM(S12+N12+I12+D12) -> -903686
A13: 8 | B13: =C12 -> 0 | D13: =C13-B13 -> 0 | F13: 8 | G13: =H12 -> 0 | I13: =H13-G13 -> 0 | K13: 8 | L13: =M12 -> 0 | N13: =M13-L13 -> 0 | P13: 8 | Q13: =R12 -> 0 | S13: =R13-Q13 -> 0 | U13: 8 | V13: =SUM(S13+N13+I13+D13) -> 0
A14: 9 | B14: =C13 -> 0 | D14: =C14-B14 -> 0 | F14: 9 | G14: =H13 -> 0 | I14: =H14-G14 -> 0 | K14: 9 | L14: =M13 -> 0 | N14: =M14-L14 -> 0 | P14: 9 | Q14: =R13 -> 0 | S14: =R14-Q14 -> 0 | U14: 9 | V14: =SUM(S14+N14+I14+D14) -> 0
A15: 10 | B15: =C14 -> 0 | D15: =C15-B15 -> 0 | F15: 10 | G15: =H14 -> 0 | I15: =H15-G15 -> 0 | K15: 10 | L15: =M14 -> 0 | N15: =M15-L15 -> 0 | P15: 10 | Q15: =R14 -> 0 | S15: =R15-Q15 -> 0 | U15: 10 | V15: =SUM(S15+N15+I15+D15) -> 0
A16: 11 | B16: =C15 -> 0 | D16: =C16-B16 -> 0 | F16: 11 | G16: =H15 -> 0 | I16: =H16-G16 -> 0 | K16: 11 | L16: =M15 -> 0 | N16: =M16-L16 -> 0 | P16: 11 | Q16: =R15 -> 0 | S16: =R16-Q16 -> 0 | U16: 11 | V16: =SUM(S16+N16+I16+D16) -> 0
A17: 12 | B17: =C16 -> 0 | D17: =C17-B17 -> 0 | F17: 12 | G17: =H16 -> 0 | I17: =H17-G17 -> 0 | K17: 12 | L17: =M16 -> 0 | N17: =M17-L17 -> 0 | P17: 12 | Q17: =R16 -> 0 | S17: =R17-Q17 -> 0 | U17: 12 | V17: =SUM(S17+N17+I17+D17) -> 0
A18: 13 | B18: =C17 -> 0 | D18: =C18-B18 -> 0 | F18: 13 | G18: =H17 -> 0 | I18: =H18-G18 -> 0 | K18: 13 | L18: =M17 -> 0 | N18: =M18-L18 -> 0 | P18: 13 | Q18: =R17 -> 0 | S18: =R18-Q18 -> 0 | U18: 13 | V18: =SUM(S18+N18+I18+D18) -> 0
A19: 14 | B19: =C18 -> 0 | D19: =C19-B19 -> 0 | F19: 14 | G19: =H18 -> 0 | I19: =H19-G19 -> 0 | K19: 14 | L19: =M18 -> 0 | N19: =M19-L19 -> 0 | P19: 14 | Q19: =R18 -> 0 | S19: =R19-Q19 -> 0 | U19: 14 | V19: =SUM(S19+N19+I19+D19) -> 0
A20: 15 | B20: =C19 -> 0 | D20: =C20-B20 -> 0 | F20: 15 | G20: =H19 -> 0 | I20: =H20-G20 -> 0 | K20: 15 | L20: =M19 -> 0 | N20: =M20-L20 -> 0 | P20: 15 | Q20: =R19 -> 0 | S20: =R20-Q20 -> 0 | U20: 15 | V20: =SUM(S20+N20+I20+D20) -> 0
A21: 16 | B21: =C20 -> 0 | D21: =C21-B21 -> 0 | F21: 16 | G21: =H20 -> 0 | I21: =H21-G21 -> 0 | K21: 16 | L21: =M20 -> 0 | N21: =M21-L21 -> 0 | P21: 16 | Q21: =R20 -> 0 | S21: =R21-Q21 -> 0 | U21: 16 | V21: =SUM(S21+N21+I21+D21) -> 0
A22: 17 | B22: =C21 -> 0 | D22: =C22-B22 -> 0 | F22: 17 | G22: =H21 -> 0 | I22: =H22-G22 -> 0 | K22: 17 | L22: =M21 -> 0 | N22: =M22-L22 -> 0 | P22: 17 | Q22: =R21 -> 0 | S22: =R22-Q22 -> 0 | U22: 17 | V22: =SUM(S22+N22+I22+D22) -> 0
A23: 18 | B23: =C22 -> 0 | D23: =C23-B23 -> 0 | F23: 18 | G23: =H22 -> 0 | I23: =H23-G23 -> 0 | K23: 18 | L23: =M22 -> 0 | N23: =M23-L23 -> 0 | P23: 18 | Q23: =R22 -> 0 | S23: =R23-Q23 -> 0 | U23: 18 | V23: =SUM(S23+N23+I23+D23) -> 0
... A33: 28 | B33: =C32 -> 0 | D33: =C33-B33 -> 0 | F33: 28 | G33: =H32 -> 0 | I33: =H33-G33 -> 0 | K33: 28 | L33: =M32 -> 0 | N33: =M33-L33 -> 0 | P33: 28 | Q33: =R32 -> 0 | S33: =R33-Q33 -> 0 | U33: 28 | V33: =SUM(S33+N33+I33+D33) -> 0
A34: 29 | B34: =C33 -> 0 | D34: =C34-B34 -> 0 | F34: 29 | G34: =H33 -> 0 | I34: =H34-G34 -> 0 | K34: 29 | L34: =M33 -> 0 | N34: =M34-L34 -> 0 | P34: 29 | Q34: =R33 -> 0 | S34: =R34-Q34 -> 0 | U34: 29 | V34: =SUM(S34+N34+I34+D34) -> 0 | Z34: =SUM(W23:W32) -> 0
A35: 30 | B35: =C34 -> 0 | D35: =C35-B35 -> 0 | F35: 30 | G35: =H34 -> 0 | I35: =H35-G35 -> 0 | K35: 30 | L35: =M34 -> 0 | N35: =M35-L35 -> 0 | P35: 30 | Q35: =R34 -> 0 | S35: =R35-Q35 -> 0 | U35: 30 | V35: =SUM(S35+N35+I35+D35) -> 0 | Z35: =Z34/11 -> 0
