Workbook

Sheet TOTAL
A1: Site Name | B1: Day | C1: Month | D1: Year | E1: Total Electricity Kwh | F1: Electricity Tariff ($/Kwh) | G1: Water Utility Supply (m3) m3 | H1: Water Utility Supply (m3) $/m3 | I1: Room Nights | J1: Total Guests | K1: Food Covers
A2: Maldives at Kuda Huraa | B2: 1 | C2: 1 | D2: 2021 | E2: 19020 | F2: 0.13924 | G2: ='Water consumption'!B4 -> 306 | H2: 0.404 | I2: 65 | J2: 182 | K2: 488
A3: Maldives at Kuda Huraa | B3: =B2+1 -> 2 | C3: 1 | D3: 2021 | E3: 22270 | F3: 0.13924 | G3: ='Water consumption'!B5 -> 253 | H3: 0.404 | I3: 57 | J3: 161 | K3: 468
A4: Maldives at Kuda Huraa | B4: =B3+1 -> 3 | C4: 1 | D4: 2021 | E4: 23276 | F4: 0.13924 | G4: ='Water consumption'!B6 -> 266 | H4: 0.404 | I4: 55 | J4: 157 | K4: 427
A5: Maldives at Kuda Huraa | B5: =B4+1 -> 4 | C5: 1 | D5: 2021 | E5: 20044 | F5: 0.13924 | G5: ='Water consumption'!B7 -> 316 | H5: 0.404 | I5: 55 | J5: 157 | K5: 415
A6: Maldives at Kuda Huraa | B6: =B5+1 -> 5 | C6: 1 | D6: 2021 | E6: 19110 | F6: 0.13924 | G6: ='Water consumption'!B8 -> 318 | H6: 0.404 | I6: 60 | J6: 168 | K6: 428
A7: Maldives at Kuda Huraa | B7: =B6+1 -> 6 | C7: 1 | D7: 2021 | E7: 18760 | F7: 0.13924 | G7: ='Water consumption'!B9 -> 283 | H7: 0.404 | I7: 59 | J7: 167 | K7: 430
A8: Maldives at Kuda Huraa | B8: =B7+1 -> 7 | C8: 1 | D8: 2021 | E8: 22080 | F8: 0.13924 | G8: ='Water consumption'!B10 -> 253 | H8: 0.404 | I8: 58 | J8: 165 | K8: 448
A9: Maldives at Kuda Huraa | B9: =B8+1 -> 8 | C9: 1 | D9: 2021 | E9: 19940 | F9: 0.13924 | G9: ='Water consumption'!B11 -> 296 | H9: 0.404 | I9: 61 | J9: 173 | K9: 450
A10: Maldives at Kuda Huraa | B10: =B9+1 -> 9 | C10: 1 | D10: 2021 | E10: 20900 | F10: 0.13924 | G10: ='Water consumption'!B12 -> 266 | H10: 0.404 | I10: 55 | J10: 158 | K10: 427
A11: Maldives at Kuda Huraa | B11: =B10+1 -> 10 | C11: 1 | D11: 2021 | E11: 21480 | F11: 0.13924 | G11: ='Water consumption'!B13 -> 276 | H11: 0.404 | I11: 42 | J11: 113 | K11: 371
A12: Maldives at Kuda Huraa | B12: =B11+1 -> 11 | C12: 1 | D12: 2021 | E12: 20740 | F12: 0.13924 | G12: 318 | H12: 0.404 | I12: 50 | J12: 126 | K12: 380
A13: Maldives at Kuda Huraa | B13: =B12+1 -> 12 | C13: 1 | D13: 2021 | E13: 19420 | F13: 0.13924 | G13: 268 | H13: 0.404
A14: Maldives at Kuda Huraa | B14: =B13+1 -> 13 | C14: 1 | D14: 2021 | E14: 0 | F14: 0.13924 | G14: ='Water consumption'!B16 -> 0 | H14: 0.404
A15: Maldives at Kuda Huraa | B15: =B14+1 -> 14 | C15: 1 | D15: 2021 | E15: 0 | F15: 0.13924 | G15: ='Water consumption'!B17 -> 0 | H15: 0.404
A16: Maldives at Kuda Huraa | B16: =B15+1 -> 15 | C16: 1 | D16: 2021 | E16: 0 | F16: 0.13924 | G16: ='Water consumption'!B18 -> 0 | H16: 0.404
A17: Maldives at Kuda Huraa | B17: =B16+1 -> 16 | C17: 1 | D17: 2021 | E17: 0 | F17: 0.13924 | G17: ='Water consumption'!B19 -> 0 | H17: 0.404
A18: Maldives at Kuda Huraa | B18: =B17+1 -> 17 | C18: 1 | D18: 2021 | E18: 0 | F18: 0.13924 | G18: ='Water consumption'!B20 -> 0 | H18: 0.404
A19: Maldives at Kuda Huraa | B19: =B18+1 -> 18 | C19: 1 | D19: 2021 | E19: 0 | F19: 0.13924 | G19: ='Water consumption'!B21 -> 0 | H19: 0.404
A20: Maldives at Kuda Huraa | B20: =B19+1 -> 19 | C20: 1 | D20: 2021 | E20: 0 | F20: 0.13924 | G20: ='Water consumption'!B22 -> 0 | H20: 0.404
A21: Maldives at Kuda Huraa | B21: =B20+1 -> 20 | C21: 1 | D21: 2021 | E21: 0 | F21: 0.13924 | G21: ='Water consumption'!B23 -> 0 | H21: 0.404
A22: Maldives at Kuda Huraa | B22: =B21+1 -> 21 | C22: 1 | D22: 2021 | E22: 0 | F22: 0.13924 | G22: ='Water consumption'!B24 -> 0 | H22: 0.404
A23: Maldives at Kuda Huraa | B23: =B22+1 -> 22 | C23: 1 | D23: 2021 | E23: 0 | F23: 0.13924 | G23: ='Water consumption'!B25 -> 0 | H23: 0.404
A24: Maldives at Kuda Huraa | B24: =B23+1 -> 23 | C24: 1 | D24: 2021 | E24: 0 | F24: 0.13924 | G24: ='Water consumption'!B26 -> 0 | H24: 0.404
A25: Maldives at Kuda Huraa | B25: =B24+1 -> 24 | C25: 1 | D25: 2021 | E25: 0 | F25: 0.13924 | G25: ='Water consumption'!B27 -> 0 | H25: 0.404
... A32: Maldives at Kuda Huraa | B32: =B31+1 -> 31 | C32: 1 | D32: 2021 | E32: 0 | F32: 0.13924 | G32: ='Water consumption'!B34 -> 0 | H32: 0.404
A33: Total | E33: =SUM(E2:E32) -> 247040 | F33: =E33*F32 -> 34397.85 | G33: =SUM(G2:G32) -> 3419 | H33: =G33*H32 -> 1381.276 | I33: =SUM(I2:I32) -> 617 | J33: =SUM(J2:J32) -> 1727 | K33: =SUM(K2:K32) -> 4732

Sheet Kwh Reading
A1: Electric Consumption Record (4pm)
A2: Month | B2: BOH-1/ B&C Block MWH | C2: Pastry MWH | D2: Feeder 401-419 KWH | E2: Feeder 301-319 KWH | F2: Kitchen GWH | G2: Feeder 201-208 MWH | H2: Feeder 113-123 | I2: M - Block /PC MWH | J2: Laundry MWH | M2: Feeder 101-112 MWH | N2: Feeder 217-224 | O2: Spa MWH | P2: Feeder 124-134 | Q2: Feeder 209-216 | R2: STP -1 &2 MWH | S2: STP -3 MWH | T2: Reef Club MWH | V2: Room Nights | W2: Total Guests | X2: Food Covers
J3: A | K3: B | L3: C
A4: 44197 | B4: 754.53 | C4: 187.45 | D4: 7066749.8 | E4: 7644266.1 | F4: 1.9355 | G4: 583.6 | H4: 482.03 | I4: 181.59 | J4: 272.09 | K4: 283.61 | L4: 194.77 | M4: 387.46 | N4: 331.81 | O4: 107.36 | P4: 447.39 | Q4: 331.31 | R4: 114.3 | S4: 91.218 | T4: 334.74 | V4: 65 | W4: 182 | X4: 488
A5: 44198 | B5: 755.46 | C5: 187.73 | D5: 7068521.7 | E5: 7646855.7 | F5: 1.9381 | G5: 584.27 | H5: 482.67 | I5: 181.77 | J5: 272.49 | K5: 284 | L5: 195.1 | M5: 387.99 | N5: 332.4 | O5: 107.59 | P5: 448.11 | Q5: 331.75 | R5: 114.49 | S5: 91.362 | T5: 335.27 | V5: 57 | W5: 161 | X5: 468
A6: 44199 | B6: 756.55 | C6: 188 | D6: 7070662.1 | E6: 7649705.3 | F6: 1.9407 | G6: 585.12 | H6: 483.37 | I6: 182.01 | J6: 272.7 | K6: 284.41 | L6: 195.37 | M6: 388.69 | N6: 333.12 | O6: 107.9 | P6: 448.95 | Q6: 332.33 | R6: 114.6 | S6: 91.495 | T6: 335.86 | V6: 55 | W6: 157 | X6: 427
A7: 44200 | B7: 757.72 | C7: 188.25 | D7: 7072890.6 | E7: 7652764.3 | F7: 1.9433 | G7: 585.92 | H7: 484.15 | I7: 182.28 | J7: 273.22 | K7: 284.87 | L7: 195.73 | M7: 389.45 | N7: 333.86 | O7: 108.17 | P7: 449.84 | Q7: 332.94 | R7: 114.78 | S7: 91.642 | T7: 336.41 | V7: 55 | W7: 157 | X7: 415
A8: 44201 | B8: 758.78 | C8: 188.52 | D8: 7074706.2 | E8: 7655451.2 | F8: 1.9458 | G8: 586.64 | H8: 484.79 | I8: 182.49 | J8: 273.51 | K8: 285.23 | L8: 196.01 | M8: 390.1 | N8: 334.5 | O8: 108.44 | P8: 450.54 | Q8: 333.44 | R8: 114.96 | S8: 91.784 | T8: 336.72 | V8: 60 | W8: 168 | X8: 428
A9: 44202 | B9: 759.78 | C9: 188.81 | D9: 7076240.8 | E9: 7657898.1 | F9: 1.9483 | G9: 587.33 | H9: 485.38 | I9: 182.69 | J9: 273.81 | K9: 285.81 | L9: 196.33 | M9: 390.6 | N9: 334.98 | O9: 108.72 | P9: 451.28 | Q9: 333.96 | R9: 115.11 | S9: 91.935 | T9: 337.58 | V9: 59 | W9: 167 | X9: 430
A10: 44203 | B10: 760.82 | C10: 189.06 | D10: 7078000.9 | E10: 7660426.5 | F10: 1.9507 | G10: 588.11 | H10: 486.04 | I10: 182.92 | J10: 274.13 | K10: 286.2 | L10: 196.61 | M10: 391.09 | N10: 335.31 | O10: 109.01 | P10: 452.01 | Q10: 334.5 | R10: 115.32 | S10: 92.078 | T10: 338.18 | V10: 58 | W10: 165 | X10: 448
A11: 44204 | B11: 762.21 | C11: 189.34 | D11: 7080122.9 | E11: 7663424.2 | F11: 1.9534 | G11: 589.01 | H11: 486.81 | I11: 183.15 | J11: 274.68 | K11: 286.7 | L11: 196.97 | M11: 391.7 | N11: 336.21 | O11: 109.28 | P11: 452.86 | Q11: 335.13 | R11: 115.57 | S11: 92.222 | T11: 338.43 | V11: 61 | W11: 173 | X11: 450
A12: 44205 | B12: 763.27 | C12: 189.6 | D12: 7082216.7 | E12: 7666194 | F12: 1.9559 | G12: 589.78 | H12: 487.52 | I12: 183.38 | J12: 275.23 | K12: 287.16 | L12: 197.28 | M12: 392.26 | N12: 336.84 | O12: 109.54 | P12: 453.65 | Q12: 335.74 | R12: 115.69 | S12: 92.379 | T12: 339.28 | V12: 55 | W12: 158 | X12: 427
A13: 44206 | B13: 764.37 | C13: 189.85 | D13: 7084075.4 | E13: 7668813.6 | F13: 1.9583 | G13: 590.54 | H13: 488.27 | I13: 183.58 | J13: 275.4 | K13: 287.53 | L13: 197.51 | M13: 392.87 | N13: 337.48 | O13: 109.84 | P13: 454.37 | Q13: 336.26 | R13: 115.94 | S13: 92.518 | T13: 339.82 | V13: 42 | W13: 113 | X13: 371
A14: 44207 | B14: 765.85 | C14: 190.11 | D14: 7086031.2 | E14: 7671644.1 | F14: 1.9608 | G14: 591.35 | H14: 489.06 | I14: 183.81 | J14: 275.74 | K14: 287.91 | L14: 197.77 | M14: 393.5 | N14: 338.22 | O14: 110.08 | P14: 455.12 | Q14: 336.85 | R14: 116.14 | S14: 92.668 | T14: 340.25 | V14: 50 | W14: 126 | X14: 380
A15: 44208 | B15: 766.77 | C15: 190.36 | D15: 7088047.7 | E15: 7674635.5 | F15: 1.9633 | G15: 592.25 | H15: 489.94 | I15: 184.04 | J15: 276.04 | K15: 288.23 | L15: 198.01 | M15: 394.14 | N15: 338.85 | O15: 110.34 | P15: 455.87 | Q15: 337.49 | R15: 116.32 | S15: 92.804 | T15: 340.99
A16: 44209 | B16: 767.85 | C16: 190.65 | D16: 7089819.7 | E16: 7677656.7 | F16: 1.9658 | G16: 593.01 | H16: 490.77 | I16: 184.29 | J16: 276.39 | K16: 288.65 | L16: 198.28 | M16: 394.75 | N16: 339.49 | O16: 110.58 | P16: 456.63 | Q16: 338.02 | R16: 116.48 | S16: 92.951 | T16: 341.37
A17: 44210
A18: 44211
A19: 44212
A20: 44213
A21: 44214
A22: 44215
A23: 44216
A24: 44217
A25: 44218
A26: 44219
A27: 44220
A28: 44221
... A34: 44227
A35: 44228 | V35: =SUM(V4:V34) -> 617 | W35: =SUM(W4:W34) -> 1727 | X35: =SUM(X4:X34) -> 4732
T42: ……..

Sheet Kwh Consumption
A2: Date | B2: Total KWH | C2: Reef Club KWH | D2: Kitchen KWH | E2: Pastry KWH | F2: Laundry KWH | I2: STP -1 &2 KWH | J2: STP -3 KWH | K2: M - Block /PC KWH | L2: B&C Block KWH | M2: Guest Room Beach Pavilion & Beach Bungalow KWH | S2: Guest Room Water Bungalow KWH | U2: Spa KWH | V2: Others KWH
F3: A | G3: B | H3: C | M3: Feeder -101-112 | N3: Feeder -113-123 | O3: Feeder -124-134 | P3: Feeder -201-208 | Q3: Feeder -209-216 | R3: Feeder -217-224 | S3: Feeder -301-319 | T3: Feeder 401-419
A4: ='Kwh Reading'!A4 -> 44197 | B4: =TOTAL!E2 -> 19020 | C4: =('Kwh Reading'!T5-'Kwh Reading'!T4)*1000 -> 530 | D4: =('Kwh Reading'!F5-'Kwh Reading'!F4)*1000000 -> 2600 | E4: =('Kwh Reading'!C5-'Kwh Reading'!C4)*1000 -> 280 | F4: =('Kwh Reading'!J5-'Kwh Reading'!J4)*1000 -> 400 | G4: =('Kwh Reading'!K5-'Kwh Reading'!K4)*1000 -> 390 | H4: =('Kwh Reading'!L5-'Kwh Reading'!L4)*1000 -> 330 | I4: =('Kwh Reading'!R5-'Kwh Reading'!R4)*1000 -> 190 | J4: =('Kwh Reading'!S5-'Kwh Reading'!S4)*1000 -> 144 | K4: =('Kwh Reading'!I5-'Kwh Reading'!I4)*1000 -> 180 | L4: =('Kwh Reading'!B5-'Kwh Reading'!B4)*1000 -> 930 | M4: =('Kwh Reading'!M5-'Kwh Reading'!M4)*1000 -> 530 | N4: =('Kwh Reading'!H5-'Kwh Reading'!H4)*1000 -> 640 | O4: =('Kwh Reading'!P5-'Kwh Reading'!P4)*1000 -> 720 | P4: =('Kwh Reading'!G5-'Kwh Reading'!G4)*1000 -> 670 | Q4: =('Kwh Reading'!Q5-'Kwh Reading'!Q4)*1000 -> 440 | R4: =('Kwh Reading'!N5-'Kwh Reading'!N4)*1000 -> 590 | S4: ='Kwh Reading'!E5-'Kwh Reading'!E4 -> 2589.65 | T4: ='Kwh Reading'!D5-'Kwh Reading'!D4 -> 1771.84 | U4: =('Kwh Reading'!O5-'Kwh Reading'!O4)*1000 -> 230 | V4: =B4-(SUM(C4:U4)) -> 4864.51
A5: ='Kwh Reading'!A5 -> 44198 | B5: =TOTAL!E3 -> 22270 | C5: =('Kwh Reading'!T6-'Kwh Reading'!T5)*1000 -> 590 | D5: =('Kwh Reading'!F6-'Kwh Reading'!F5)*1000000 -> 2600 | E5: =('Kwh Reading'!C6-'Kwh Reading'!C5)*1000 -> 270 | F5: =('Kwh Reading'!J6-'Kwh Reading'!J5)*1000 -> 210 | G5: =('Kwh Reading'!K6-'Kwh Reading'!K5)*1000 -> 410 | H5: =('Kwh Reading'!L6-'Kwh Reading'!L5)*1000 -> 270 | I5: =('Kwh Reading'!R6-'Kwh Reading'!R5)*1000 -> 110 | J5: =('Kwh Reading'!S6-'Kwh Reading'!S5)*1000 -> 133 | K5: =('Kwh Reading'!I6-'Kwh Reading'!I5)*1000 -> 240 | L5: =('Kwh Reading'!B6-'Kwh Reading'!B5)*1000 -> 1090 | M5: =('Kwh Reading'!M6-'Kwh Reading'!M5)*1000 -> 700 | N5: =('Kwh Reading'!H6-'Kwh Reading'!H5)*1000 -> 700 | O5: =('Kwh Reading'!P6-'Kwh Reading'!P5)*1000 -> 840 | P5: =('Kwh Reading'!G6-'Kwh Reading'!G5)*1000 -> 850 | Q5: =('Kwh Reading'!Q6-'Kwh Reading'!Q5)*1000 -> 580 | R5: =('Kwh Reading'!N6-'Kwh Reading'!N5)*1000 -> 720 | S5: ='Kwh Reading'!E6-'Kwh Reading'!E5 -> 2849.61 | T5: ='Kwh Reading'!D6-'Kwh Reading'!D5 -> 2140.42 | U5: =('Kwh Reading'!O6-'Kwh Reading'!O5)*1000 -> 310 | V5: =B5-(SUM(C5:U5)) -> 6656.97
A6: ='Kwh Reading'!A6 -> 44199 | B6: =TOTAL!E4 -> 23276 | C6: =('Kwh Reading'!T7-'Kwh Reading'!T6)*1000 -> 550 | D6: =('Kwh Reading'!F7-'Kwh Reading'!F6)*1000000 -> 2600 | E6: =('Kwh Reading'!C7-'Kwh Reading'!C6)*1000 -> 250 | F6: =('Kwh Reading'!J7-'Kwh Reading'!J6)*1000 -> 520 | G6: =('Kwh Reading'!K7-'Kwh Reading'!K6)*1000 -> 460 | H6: =('Kwh Reading'!L7-'Kwh Reading'!L6)*1000 -> 360 | I6: =('Kwh Reading'!R7-'Kwh Reading'!R6)*1000 -> 180 | J6: =('Kwh Reading'!S7-'Kwh Reading'!S6)*1000 -> 147 | K6: =('Kwh Reading'!I7-'Kwh Reading'!I6)*1000 -> 270 | L6: =('Kwh Reading'!B7-'Kwh Reading'!B6)*1000 -> 1170 | M6: =('Kwh Reading'!M7-'Kwh Reading'!M6)*1000 -> 760 | N6: =('Kwh Reading'!H7-'Kwh Reading'!H6)*1000 -> 780 | O6: =('Kwh Reading'!P7-'Kwh Reading'!P6)*1000 -> 890 | P6: =('Kwh Reading'!G7-'Kwh Reading'!G6)*1000 -> 800 | Q6: =('Kwh Reading'!Q7-'Kwh Reading'!Q6)*1000 -> 610 | R6: =('Kwh Reading'!N7-'Kwh Reading'!N6)*1000 -> 740 | S6: ='Kwh Reading'!E7-'Kwh Reading'!E6 -> 3058.94 | T6: ='Kwh Reading'!D7-'Kwh Reading'!D6 -> 2228.56 | U6: =('Kwh Reading'!O7-'Kwh Reading'!O6)*1000 -> 270 | V6: =B6-(SUM(C6:U6)) -> 6631.5
A7: ='Kwh Reading'!A7 -> 44200 | B7: =TOTAL!E5 -> 20044 | C7: =('Kwh Reading'!T8-'Kwh Reading'!T7)*1000 -> 310 | D7: =('Kwh Reading'!F8-'Kwh Reading'!F7)*1000000 -> 2500 | E7: =('Kwh Reading'!C8-'Kwh Reading'!C7)*1000 -> 270 | F7: =('Kwh Reading'!J8-'Kwh Reading'!J7)*1000 -> 290 | G7: =('Kwh Reading'!K8-'Kwh Reading'!K7)*1000 -> 360 | H7: =('Kwh Reading'!L8-'Kwh Reading'!L7)*1000 -> 280 | I7: =('Kwh Reading'!R8-'Kwh Reading'!R7)*1000 -> 180 | J7: =('Kwh Reading'!S8-'Kwh Reading'!S7)*1000 -> 142 | K7: =('Kwh Reading'!I8-'Kwh Reading'!I7)*1000 -> 210 | L7: =('Kwh Reading'!B8-'Kwh Reading'!B7)*1000 -> 1060 | M7: =('Kwh Reading'!M8-'Kwh Reading'!M7)*1000 -> 650 | N7: =('Kwh Reading'!H8-'Kwh Reading'!H7)*1000 -> 640 | O7: =('Kwh Reading'!P8-'Kwh Reading'!P7)*1000 -> 700 | P7: =('Kwh Reading'!G8-'Kwh Reading'!G7)*1000 -> 720 | Q7: =('Kwh Reading'!Q8-'Kwh Reading'!Q7)*1000 -> 500 | R7: =('Kwh Reading'!N8-'Kwh Reading'!N7)*1000 -> 640 | S7: ='Kwh Reading'!E8-'Kwh Reading'!E7 -> 2686.91 | T7: ='Kwh Reading'!D8-'Kwh Reading'!D7 -> 1815.6 | U7: =('Kwh Reading'!O8-'Kwh Reading'!O7)*1000 -> 270 | V7: =B7-(SUM(C7:U7)) -> 5819.49
A8: ='Kwh Reading'!A8 -> 44201 | B8: =TOTAL!E6 -> 19110 | C8: =('Kwh Reading'!T9-'Kwh Reading'!T8)*1000 -> 860 | D8: =('Kwh Reading'!F9-'Kwh Reading'!F8)*1000000 -> 2500 | E8: =('Kwh Reading'!C9-'Kwh Reading'!C8)*1000 -> 290 | F8: =('Kwh Reading'!J9-'Kwh Reading'!J8)*1000 -> 300 | G8: =('Kwh Reading'!K9-'Kwh Reading'!K8)*1000 -> 580 | H8: =('Kwh Reading'!L9-'Kwh Reading'!L8)*1000 -> 320 | I8: =('Kwh Reading'!R9-'Kwh Reading'!R8)*1000 -> 150 | J8: =('Kwh Reading'!S9-'Kwh Reading'!S8)*1000 -> 151 | K8: =('Kwh Reading'!I9-'Kwh Reading'!I8)*1000 -> 200 | L8: =('Kwh Reading'!B9-'Kwh Reading'!B8)*1000 -> 1000 | M8: =('Kwh Reading'!M9-'Kwh Reading'!M8)*1000 -> 500 | N8: =('Kwh Reading'!H9-'Kwh Reading'!H8)*1000 -> 590 | O8: =('Kwh Reading'!P9-'Kwh Reading'!P8)*1000 -> 740 | P8: =('Kwh Reading'!G9-'Kwh Reading'!G8)*1000 -> 690 | Q8: =('Kwh Reading'!Q9-'Kwh Reading'!Q8)*1000 -> 520 | R8: =('Kwh Reading'!N9-'Kwh Reading'!N8)*1000 -> 480 | S8: ='Kwh Reading'!E9-'Kwh Reading'!E8 -> 2446.88 | T8: ='Kwh Reading'!D9-'Kwh Reading'!D8 -> 1534.55 | U8: =('Kwh Reading'!O9-'Kwh Reading'!O8)*1000 -> 280 | V8: =B8-(SUM(C8:U8)) -> 4977.57
A9: ='Kwh Reading'!A9 -> 44202 | B9: =TOTAL!E7 -> 18760 | C9: =('Kwh Reading'!T10-'Kwh Reading'!T9)*1000 -> 600 | D9: =('Kwh Reading'!F10-'Kwh Reading'!F9)*1000000 -> 2400 | E9: =('Kwh Reading'!C10-'Kwh Reading'!C9)*1000 -> 250 | F9: =('Kwh Reading'!J10-'Kwh Reading'!J9)*1000 -> 320 | G9: =('Kwh Reading'!K10-'Kwh Reading'!K9)*1000 -> 390 | H9: =('Kwh Reading'!L10-'Kwh Reading'!L9)*1000 -> 280 | I9: =('Kwh Reading'!R10-'Kwh Reading'!R9)*1000 -> 210 | J9: =('Kwh Reading'!S10-'Kwh Reading'!S9)*1000 -> 143 | K9: =('Kwh Reading'!I10-'Kwh Reading'!I9)*1000 -> 230 | L9: =('Kwh Reading'!B10-'Kwh Reading'!B9)*1000 -> 1040 | M9: =('Kwh Reading'!M10-'Kwh Reading'!M9)*1000 -> 490 | N9: =('Kwh Reading'!H10-'Kwh Reading'!H9)*1000 -> 660 | O9: =('Kwh Reading'!P10-'Kwh Reading'!P9)*1000 -> 730 | P9: =('Kwh Reading'!G10-'Kwh Reading'!G9)*1000 -> 780 | Q9: =('Kwh Reading'!Q10-'Kwh Reading'!Q9)*1000 -> 540 | R9: =('Kwh Reading'!N10-'Kwh Reading'!N9)*1000 -> 330 | S9: ='Kwh Reading'!E10-'Kwh Reading'!E9 -> 2528.43 | T9: ='Kwh Reading'!D10-'Kwh Reading'!D9 -> 1760.09 | U9: =('Kwh Reading'!O10-'Kwh Reading'!O9)*1000 -> 290 | V9: =B9-(SUM(C9:U9)) -> 4788.48
A10: ='Kwh Reading'!A10 -> 44203 | B10: =TOTAL!E8 -> 22080 | C10: =('Kwh Reading'!T11-'Kwh Reading'!T10)*1000 -> 250 | D10: =('Kwh Reading'!F11-'Kwh Reading'!F10)*1000000 -> 2700 | E10: =('Kwh Reading'!C11-'Kwh Reading'!C10)*1000 -> 280 | F10: =('Kwh Reading'!J11-'Kwh Reading'!J10)*1000 -> 550 | G10: =('Kwh Reading'!K11-'Kwh Reading'!K10)*1000 -> 500 | H10: =('Kwh Reading'!L11-'Kwh Reading'!L10)*1000 -> 360 | I10: =('Kwh Reading'!R11-'Kwh Reading'!R10)*1000 -> 250 | J10: =('Kwh Reading'!S11-'Kwh Reading'!S10)*1000 -> 144 | K10: =('Kwh Reading'!I11-'Kwh Reading'!I10)*1000 -> 230 | L10: =('Kwh Reading'!B11-'Kwh Reading'!B10)*1000 -> 1390 | M10: =('Kwh Reading'!M11-'Kwh Reading'!M10)*1000 -> 610 | N10: =('Kwh Reading'!H11-'Kwh Reading'!H10)*1000 -> 770 | O10: =('Kwh Reading'!P11-'Kwh Reading'!P10)*1000 -> 850 | P10: =('Kwh Reading'!G11-'Kwh Reading'!G10)*1000 -> 900 | Q10: =('Kwh Reading'!Q11-'Kwh Reading'!Q10)*1000 -> 630 | R10: =('Kwh Reading'!N11-'Kwh Reading'!N10)*1000 -> 900 | S10: ='Kwh Reading'!E11-'Kwh Reading'!E10 -> 2997.69 | T10: ='Kwh Reading'!D11-'Kwh Reading'!D10 -> 2121.99 | U10: =('Kwh Reading'!O11-'Kwh Reading'!O10)*1000 -> 270 | V10: =B10-(SUM(C10:U10)) -> 5376.32
A11: ='Kwh Reading'!A11 -> 44204 | B11: =TOTAL!E9 -> 19940 | C11: =('Kwh Reading'!T12-'Kwh Reading'!T11)*1000 -> 850 | D11: =('Kwh Reading'!F12-'Kwh Reading'!F11)*1000000 -> 2500 | E11: =('Kwh Reading'!C12-'Kwh Reading'!C11)*1000 -> 260 | F11: =('Kwh Reading'!J12-'Kwh Reading'!J11)*1000 -> 550 | G11: =('Kwh Reading'!K12-'Kwh Reading'!K11)*1000 -> 460 | H11: =('Kwh Reading'!L12-'Kwh Reading'!L11)*1000 -> 310 | I11: =('Kwh Reading'!R12-'Kwh Reading'!R11)*1000 -> 120 | J11: =('Kwh Reading'!S12-'Kwh Reading'!S11)*1000 -> 157 | K11: =('Kwh Reading'!I12-'Kwh Reading'!I11)*1000 -> 230 | L11: =('Kwh Reading'!B12-'Kwh Reading'!B11)*1000 -> 1060 | M11: =('Kwh Reading'!M12-'Kwh Reading'!M11)*1000 -> 560 | N11: =('Kwh Reading'!H12-'Kwh Reading'!H11)*1000 -> 710 | O11: =('Kwh Reading'!P12-'Kwh Reading'!P11)*1000 -> 790 | P11: =('Kwh Reading'!G12-'Kwh Reading'!G11)*1000 -> 770 | Q11: =('Kwh Reading'!Q12-'Kwh Reading'!Q11)*1000 -> 610 | R11: =('Kwh Reading'!N12-'Kwh Reading'!N11)*1000 -> 630 | S11: ='Kwh Reading'!E12-'Kwh Reading'!E11 -> 2769.8 | T11: ='Kwh Reading'!D12-'Kwh Reading'!D11 -> 2093.88 | U11: =('Kwh Reading'!O12-'Kwh Reading'!O11)*1000 -> 260 | V11: =B11-(SUM(C11:U11)) -> 4249.32
A12: ='Kwh Reading'!A12 -> 44205 | B12: 20900 | C12: =('Kwh Reading'!T13-'Kwh Reading'!T12)*1000 -> 540 | D12: =('Kwh Reading'!F13-'Kwh Reading'!F12)*1000000 -> 2400 | E12: =('Kwh Reading'!C13-'Kwh Reading'!C12)*1000 -> 250 | F12: =('Kwh Reading'!J13-'Kwh Reading'!J12)*1000 -> 170 | G12: =('Kwh Reading'!K13-'Kwh Reading'!K12)*1000 -> 370 | H12: =('Kwh Reading'!L13-'Kwh Reading'!L12)*1000 -> 230 | I12: =('Kwh Reading'!R13-'Kwh Reading'!R12)*1000 -> 250 | J12: =('Kwh Reading'!S13-'Kwh Reading'!S12)*1000 -> 139 | K12: =('Kwh Reading'!I13-'Kwh Reading'!I12)*1000 -> 200 | L12: =('Kwh Reading'!B13-'Kwh Reading'!B12)*1000 -> 1100 | M12: =('Kwh Reading'!M13-'Kwh Reading'!M12)*1000 -> 610 | N12: =('Kwh Reading'!H13-'Kwh Reading'!H12)*1000 -> 750 | O12: =('Kwh Reading'!P13-'Kwh Reading'!P12)*1000 -> 720 | P12: =('Kwh Reading'!G13-'Kwh Reading'!G12)*1000 -> 760 | Q12: =('Kwh Reading'!Q13-'Kwh Reading'!Q12)*1000 -> 520 | R12: =('Kwh Reading'!N13-'Kwh Reading'!N12)*1000 -> 640 | S12: ='Kwh Reading'!E13-'Kwh Reading'!E12 -> 2619.66 | T12: ='Kwh Reading'!D13-'Kwh Reading'!D12 -> 1858.62 | U12: =('Kwh Reading'!O13-'Kwh Reading'!O12)*1000 -> 300 | V12: =B12-(SUM(C12:U12)) -> 6472.72
A13: ='Kwh Reading'!A13 -> 44206 | B13: 21480 | C13: =('Kwh Reading'!T14-'Kwh Reading'!T13)*1000 -> 430 | D13: =('Kwh Reading'!F14-'Kwh Reading'!F13)*1000000 -> 2500 | E13: =('Kwh Reading'!C14-'Kwh Reading'!C13)*1000 -> 260 | F13: =('Kwh Reading'!J14-'Kwh Reading'!J13)*1000 -> 340 | G13: =('Kwh Reading'!K14-'Kwh Reading'!K13)*1000 -> 380 | H13: =('Kwh Reading'!L14-'Kwh Reading'!L13)*1000 -> 260 | I13: =('Kwh Reading'!R14-'Kwh Reading'!R13)*1000 -> 200 | J13: =('Kwh Reading'!S14-'Kwh Reading'!S13)*1000 -> 150 | K13: =('Kwh Reading'!I14-'Kwh Reading'!I13)*1000 -> 230 | L13: =('Kwh Reading'!B14-'Kwh Reading'!B13)*1000 -> 1480 | M13: =('Kwh Reading'!M14-'Kwh Reading'!M13)*1000 -> 630 | N13: =('Kwh Reading'!H14-'Kwh Reading'!H13)*1000 -> 790 | O13: =('Kwh Reading'!P14-'Kwh Reading'!P13)*1000 -> 750 | P13: =('Kwh Reading'!G14-'Kwh Reading'!G13)*1000 -> 810 | Q13: =('Kwh Reading'!Q14-'Kwh Reading'!Q13)*1000 -> 590 | R13: =('Kwh Reading'!N14-'Kwh Reading'!N13)*1000 -> 740 | S13: ='Kwh Reading'!E14-'Kwh Reading'!E13 -> 2830.48 | T13: ='Kwh Reading'!D14-'Kwh Reading'!D13 -> 1955.81 | U13: =('Kwh Reading'!O14-'Kwh Reading'!O13)*1000 -> 240 | V13: =B13-(SUM(C13:U13)) -> 5913.71
A14: ='Kwh Reading'!A14 -> 44207 | B14: =TOTAL!E12 -> 20740 | C14: =('Kwh Reading'!T15-'Kwh Reading'!T14)*1000 -> 740 | D14: =('Kwh Reading'!F15-'Kwh Reading'!F14)*1000000 -> 2500 | E14: =('Kwh Reading'!C15-'Kwh Reading'!C14)*1000 -> 250 | F14: =('Kwh Reading'!J15-'Kwh Reading'!J14)*1000 -> 300 | G14: =('Kwh Reading'!K15-'Kwh Reading'!K14)*1000 -> 320 | H14: =('Kwh Reading'!L15-'Kwh Reading'!L14)*1000 -> 240 | I14: =('Kwh Reading'!R15-'Kwh Reading'!R14)*1000 -> 180 | J14: =('Kwh Reading'!S15-'Kwh Reading'!S14)*1000 -> 136 | K14: =('Kwh Reading'!I15-'Kwh Reading'!I14)*1000 -> 230 | L14: =('Kwh Reading'!B15-'Kwh Reading'!B14)*1000 -> 920 | M14: =('Kwh Reading'!M15-'Kwh Reading'!M14)*1000 -> 640 | N14: =('Kwh Reading'!H15-'Kwh Reading'!H14)*1000 -> 880 | O14: =('Kwh Reading'!P15-'Kwh Reading'!P14)*1000 -> 750 | P14: =('Kwh Reading'!G15-'Kwh Reading'!G14)*1000 -> 900 | Q14: =('Kwh Reading'!Q15-'Kwh Reading'!Q14)*1000 -> 640 | R14: =('Kwh Reading'!N15-'Kwh Reading'!N14)*1000 -> 630 | S14: ='Kwh Reading'!E15-'Kwh Reading'!E14 -> 2991.34 | T14: ='Kwh Reading'!D15-'Kwh Reading'!D14 -> 2016.51 | U14: =('Kwh Reading'!O15-'Kwh Reading'!O14)*1000 -> 260 | V14: =B14-(SUM(C14:U14)) -> 5216.15
A15: ='Kwh Reading'!A15 -> 44208 | B15: =TOTAL!E13 -> 19420 | C15: =('Kwh Reading'!T16-'Kwh Reading'!T15)*1000 -> 380 | D15: =('Kwh Reading'!F16-'Kwh Reading'!F15)*1000000 -> 2500 | E15: =('Kwh Reading'!C16-'Kwh Reading'!C15)*1000 -> 290 | F15: =('Kwh Reading'!J16-'Kwh Reading'!J15)*1000 -> 350 | G15: =('Kwh Reading'!K16-'Kwh Reading'!K15)*1000 -> 420 | H15: =('Kwh Reading'!L16-'Kwh Reading'!L15)*1000 -> 270 | I15: =('Kwh Reading'!R16-'Kwh Reading'!R15)*1000 -> 160 | J15: =('Kwh Reading'!S16-'Kwh Reading'!S15)*1000 -> 147 | K15: =('Kwh Reading'!I16-'Kwh Reading'!I15)*1000 -> 250 | L15: =('Kwh Reading'!B16-'Kwh Reading'!B15)*1000 -> 1080 | M15: =('Kwh Reading'!M16-'Kwh Reading'!M15)*1000 -> 610 | N15: =('Kwh Reading'!H16-'Kwh Reading'!H15)*1000 -> 830 | O15: =('Kwh Reading'!P16-'Kwh Reading'!P15)*1000 -> 760 | P15: =('Kwh Reading'!G16-'Kwh Reading'!G15)*1000 -> 760 | Q15: =('Kwh Reading'!Q16-'Kwh Reading'!Q15)*1000 -> 530 | R15: =('Kwh Reading'!N16-'Kwh Reading'!N15)*1000 -> 640 | S15: ='Kwh Reading'!E16-'Kwh Reading'!E15 -> 3021.28 | T15: ='Kwh Reading'!D16-'Kwh Reading'!D15 -> 1772 | U15: =('Kwh Reading'!O16-'Kwh Reading'!O15)*1000 -> 240 | V15: =B15-(SUM(C15:U15)) -> 4409.72
A16: ='Kwh Reading'!A16 -> 44209 | B16: =TOTAL!E14 -> 0 | C16: =('Kwh Reading'!T17-'Kwh Reading'!T16)*1000 -> -341370 | D16: =('Kwh Reading'!F17-'Kwh Reading'!F16)*1000000 -> -1965800 | E16: =('Kwh Reading'!C17-'Kwh Reading'!C16)*1000 -> -190650 | F16: =('Kwh Reading'!J17-'Kwh Reading'!J16)*1000 -> -276390 | G16: =('Kwh Reading'!K17-'Kwh Reading'!K16)*1000 -> -288650 | H16: =('Kwh Reading'!L17-'Kwh Reading'!L16)*1000 -> -198280 | I16: =('Kwh Reading'!R17-'Kwh Reading'!R16)*1000 -> -116480 | J16: =('Kwh Reading'!S17-'Kwh Reading'!S16)*1000 -> -92951 | K16: =('Kwh Reading'!I17-'Kwh Reading'!I16)*1000 -> -184290 | L16: =('Kwh Reading'!B17-'Kwh Reading'!B16)*1000 -> -767850 | M16: =('Kwh Reading'!M17-'Kwh Reading'!M16)*1000 -> -394750 | N16: =('Kwh Reading'!H17-'Kwh Reading'!H16)*1000 -> -490770 | O16: =('Kwh Reading'!P17-'Kwh Reading'!P16)*1000 -> -456630 | P16: =('Kwh Reading'!G17-'Kwh Reading'!G16)*1000 -> -593010 | Q16: =('Kwh Reading'!Q17-'Kwh Reading'!Q16)*1000 -> -338020 | R16: =('Kwh Reading'!N17-'Kwh Reading'!N16)*1000 -> -339490 | S16: ='Kwh Reading'!E17-'Kwh Reading'!E16 -> -7677656.7 | T16: ='Kwh Reading'!D17-'Kwh Reading'!D16 -> -7089819.7 | U16: =('Kwh Reading'!O17-'Kwh Reading'!O16)*1000 -> -110580 | V16: =B16-(SUM(C16:U16)) -> 21913437
A17: ='Kwh Reading'!A17 -> 44210 | B17: =TOTAL!E15 -> 0 | C17: =('Kwh Reading'!T18-'Kwh Reading'!T17)*1000 -> 0 | D17: =('Kwh Reading'!F18-'Kwh Reading'!F17)*1000000 -> 0 | E17: =('Kwh Reading'!C18-'Kwh Reading'!C17)*1000 -> 0 | F17: =('Kwh Reading'!J18-'Kwh Reading'!J17)*1000 -> 0 | G17: =('Kwh Reading'!K18-'Kwh Reading'!K17)*1000 -> 0 | H17: =('Kwh Reading'!L18-'Kwh Reading'!L17)*1000 -> 0 | I17: =('Kwh Reading'!R18-'Kwh Reading'!R17)*1000 -> 0 | J17: =('Kwh Reading'!S18-'Kwh Reading'!S17)*1000 -> 0 | K17: =('Kwh Reading'!I18-'Kwh Reading'!I17)*1000 -> 0 | L17: =('Kwh Reading'!B18-'Kwh Reading'!B17)*1000 -> 0 | M17: =('Kwh Reading'!M18-'Kwh Reading'!M17)*1000 -> 0 | N17: =('Kwh Reading'!H18-'Kwh Reading'!H17)*1000 -> 0 | O17: =('Kwh Reading'!P18-'Kwh Reading'!P17)*1000 -> 0 | P17: =('Kwh Reading'!G18-'Kwh Reading'!G17)*1000 -> 0 | Q17: =('Kwh Reading'!Q18-'Kwh Reading'!Q17)*1000 -> 0 | R17: =('Kwh Reading'!N18-'Kwh Reading'!N17)*1000 -> 0 | S17: ='Kwh Reading'!E18-'Kwh Reading'!E17 -> 0 | T17: ='Kwh Reading'!D18-'Kwh Reading'!D17 -> 0 | U17: =('Kwh Reading'!O18-'Kwh Reading'!O17)*1000 -> 0 | V17: =B17-(SUM(C17:U17)) -> 0
A18: ='Kwh Reading'!A18 -> 44211 | B18: =TOTAL!E16 -> 0 | C18: =('Kwh Reading'!T19-'Kwh Reading'!T18)*1000 -> 0 | D18: =('Kwh Reading'!F19-'Kwh Reading'!F18)*1000000 -> 0 | E18: =('Kwh Reading'!C19-'Kwh Reading'!C18)*1000 -> 0 | F18: =('Kwh Reading'!J19-'Kwh Reading'!J18)*1000 -> 0 | G18: =('Kwh Reading'!K19-'Kwh Reading'!K18)*1000 -> 0 | H18: =('Kwh Reading'!L19-'Kwh Reading'!L18)*1000 -> 0 | I18: =('Kwh Reading'!R19-'Kwh Reading'!R18)*1000 -> 0 | J18: =('Kwh Reading'!S19-'Kwh Reading'!S18)*1000 -> 0 | K18: =('Kwh Reading'!I19-'Kwh Reading'!I18)*1000 -> 0 | L18: =('Kwh Reading'!B19-'Kwh Reading'!B18)*1000 -> 0 | M18: =('Kwh Reading'!M19-'Kwh Reading'!M18)*1000 -> 0 | N18: =('Kwh Reading'!H19-'Kwh Reading'!H18)*1000 -> 0 | O18: =('Kwh Reading'!P19-'Kwh Reading'!P18)*1000 -> 0 | P18: =('Kwh Reading'!G19-'Kwh Reading'!G18)*1000 -> 0 | Q18: =('Kwh Reading'!Q19-'Kwh Reading'!Q18)*1000 -> 0 | R18: =('Kwh Reading'!N19-'Kwh Reading'!N18)*1000 -> 0 | S18: ='Kwh Reading'!E19-'Kwh Reading'!E18 -> 0 | T18: ='Kwh Reading'!D19-'Kwh Reading'!D18 -> 0 | U18: =('Kwh Reading'!O19-'Kwh Reading'!O18)*1000 -> 0 | V18: =B18-(SUM(C18:U18)) -> 0
A19: ='Kwh Reading'!A19 -> 44212 | B19: =TOTAL!E17 -> 0 | C19: =('Kwh Reading'!T20-'Kwh Reading'!T19)*1000 -> 0 | D19: =('Kwh Reading'!F20-'Kwh Reading'!F19)*1000000 -> 0 | E19: =('Kwh Reading'!C20-'Kwh Reading'!C19)*1000 -> 0 | F19: =('Kwh Reading'!J20-'Kwh Reading'!J19)*1000 -> 0 | G19: =('Kwh Reading'!K20-'Kwh Reading'!K19)*1000 -> 0 | H19: =('Kwh Reading'!L20-'Kwh Reading'!L19)*1000 -> 0 | I19: =('Kwh Reading'!R20-'Kwh Reading'!R19)*1000 -> 0 | J19: =('Kwh Reading'!S20-'Kwh Reading'!S19)*1000 -> 0 | K19: =('Kwh Reading'!I20-'Kwh Reading'!I19)*1000 -> 0 | L19: =('Kwh Reading'!B20-'Kwh Reading'!B19)*1000 -> 0 | M19: =('Kwh Reading'!M20-'Kwh Reading'!M19)*1000 -> 0 | N19: =('Kwh Reading'!H20-'Kwh Reading'!H19)*1000 -> 0 | O19: =('Kwh Reading'!P20-'Kwh Reading'!P19)*1000 -> 0 | P19: =('Kwh Reading'!G20-'Kwh Reading'!G19)*1000 -> 0 | Q19: =('Kwh Reading'!Q20-'Kwh Reading'!Q19)*1000 -> 0 | R19: =('Kwh Reading'!N20-'Kwh Reading'!N19)*1000 -> 0 | S19: ='Kwh Reading'!E20-'Kwh Reading'!E19 -> 0 | T19: ='Kwh Reading'!D20-'Kwh Reading'!D19 -> 0 | U19: =('Kwh Reading'!O20-'Kwh Reading'!O19)*1000 -> 0 | V19: =B19-(SUM(C19:U19)) -> 0
A20: ='Kwh Reading'!A20 -> 44213 | B20: =TOTAL!E18 -> 0 | C20: =('Kwh Reading'!T21-'Kwh Reading'!T20)*1000 -> 0 | D20: =('Kwh Reading'!F21-'Kwh Reading'!F20)*1000000 -> 0 | E20: =('Kwh Reading'!C21-'Kwh Reading'!C20)*1000 -> 0 | F20: =('Kwh Reading'!J21-'Kwh Reading'!J20)*1000 -> 0 | G20: =('Kwh Reading'!K21-'Kwh Reading'!K20)*1000 -> 0 | H20: =('Kwh Reading'!L21-'Kwh Reading'!L20)*1000 -> 0 | I20: =('Kwh Reading'!R21-'Kwh Reading'!R20)*1000 -> 0 | J20: =('Kwh Reading'!S21-'Kwh Reading'!S20)*1000 -> 0 | K20: =('Kwh Reading'!I21-'Kwh Reading'!I20)*1000 -> 0 | L20: =('Kwh Reading'!B21-'Kwh Reading'!B20)*1000 -> 0 | M20: =('Kwh Reading'!M21-'Kwh Reading'!M20)*1000 -> 0 | N20: =('Kwh Reading'!H21-'Kwh Reading'!H20)*1000 -> 0 | O20: =('Kwh Reading'!P21-'Kwh Reading'!P20)*1000 -> 0 | P20: =('Kwh Reading'!G21-'Kwh Reading'!G20)*1000 -> 0 | Q20: =('Kwh Reading'!Q21-'Kwh Reading'!Q20)*1000 -> 0 | R20: =('Kwh Reading'!N21-'Kwh Reading'!N20)*1000 -> 0 | S20: ='Kwh Reading'!E21-'Kwh Reading'!E20 -> 0 | T20: ='Kwh Reading'!D21-'Kwh Reading'!D20 -> 0 | U20: =('Kwh Reading'!O21-'Kwh Reading'!O20)*1000 -> 0 | V20: =B20-(SUM(C20:U20)) -> 0
A21: ='Kwh Reading'!A21 -> 44214 | B21: =TOTAL!E19 -> 0 | C21: =('Kwh Reading'!T22-'Kwh Reading'!T21)*1000 -> 0 | D21: =('Kwh Reading'!F22-'Kwh Reading'!F21)*1000000 -> 0 | E21: =('Kwh Reading'!C22-'Kwh Reading'!C21)*1000 -> 0 | F21: =('Kwh Reading'!J22-'Kwh Reading'!J21)*1000 -> 0 | G21: =('Kwh Reading'!K22-'Kwh Reading'!K21)*1000 -> 0 | H21: =('Kwh Reading'!L22-'Kwh Reading'!L21)*1000 -> 0 | I21: =('Kwh Reading'!R22-'Kwh Reading'!R21)*1000 -> 0 | J21: =('Kwh Reading'!S22-'Kwh Reading'!S21)*1000 -> 0 | K21: =('Kwh Reading'!I22-'Kwh Reading'!I21)*1000 -> 0 | L21: =('Kwh Reading'!B22-'Kwh Reading'!B21)*1000 -> 0 | M21: =('Kwh Reading'!M22-'Kwh Reading'!M21)*1000 -> 0 | N21: =('Kwh Reading'!H22-'Kwh Reading'!H21)*1000 -> 0 | O21: =('Kwh Reading'!P22-'Kwh Reading'!P21)*1000 -> 0 | P21: =('Kwh Reading'!G22-'Kwh Reading'!G21)*1000 -> 0 | Q21: =('Kwh Reading'!Q22-'Kwh Reading'!Q21)*1000 -> 0 | R21: =('Kwh Reading'!N22-'Kwh Reading'!N21)*1000 -> 0 | S21: ='Kwh Reading'!E22-'Kwh Reading'!E21 -> 0 | T21: ='Kwh Reading'!D22-'Kwh Reading'!D21 -> 0 | U21: =('Kwh Reading'!O22-'Kwh Reading'!O21)*1000 -> 0 | V21: =B21-(SUM(C21:U21)) -> 0
A22: ='Kwh Reading'!A22 -> 44215 | B22: =TOTAL!E20 -> 0 | C22: =('Kwh Reading'!T23-'Kwh Reading'!T22)*1000 -> 0 | D22: =('Kwh Reading'!F23-'Kwh Reading'!F22)*1000000 -> 0 | E22: =('Kwh Reading'!C23-'Kwh Reading'!C22)*1000 -> 0 | F22: =('Kwh Reading'!J23-'Kwh Reading'!J22)*1000 -> 0 | G22: =('Kwh Reading'!K23-'Kwh Reading'!K22)*1000 -> 0 | H22: =('Kwh Reading'!L23-'Kwh Reading'!L22)*1000 -> 0 | I22: =('Kwh Reading'!R23-'Kwh Reading'!R22)*1000 -> 0 | J22: =('Kwh Reading'!S23-'Kwh Reading'!S22)*1000 -> 0 | K22: =('Kwh Reading'!I23-'Kwh Reading'!I22)*1000 -> 0 | L22: =('Kwh Reading'!B23-'Kwh Reading'!B22)*1000 -> 0 | M22: =('Kwh Reading'!M23-'Kwh Reading'!M22)*1000 -> 0 | N22: =('Kwh Reading'!H23-'Kwh Reading'!H22)*1000 -> 0 | O22: =('Kwh Reading'!P23-'Kwh Reading'!P22)*1000 -> 0 | P22: =('Kwh Reading'!G23-'Kwh Reading'!G22)*1000 -> 0 | Q22: =('Kwh Reading'!Q23-'Kwh Reading'!Q22)*1000 -> 0 | R22: =('Kwh Reading'!N23-'Kwh Reading'!N22)*1000 -> 0 | S22: ='Kwh Reading'!E23-'Kwh Reading'!E22 -> 0 | T22: ='Kwh Reading'!D23-'Kwh Reading'!D22 -> 0 | U22: =('Kwh Reading'!O23-'Kwh Reading'!O22)*1000 -> 0 | V22: =B22-(SUM(C22:U22)) -> 0
A23: ='Kwh Reading'!A23 -> 44216 | B23: =TOTAL!E21 -> 0 | C23: =('Kwh Reading'!T24-'Kwh Reading'!T23)*1000 -> 0 | D23: =('Kwh Reading'!F24-'Kwh Reading'!F23)*1000000 -> 0 | E23: =('Kwh Reading'!C24-'Kwh Reading'!C23)*1000 -> 0 | F23: =('Kwh Reading'!J24-'Kwh Reading'!J23)*1000 -> 0 | G23: =('Kwh Reading'!K24-'Kwh Reading'!K23)*1000 -> 0 | H23: =('Kwh Reading'!L24-'Kwh Reading'!L23)*1000 -> 0 | I23: =('Kwh Reading'!R24-'Kwh Reading'!R23)*1000 -> 0 | J23: =('Kwh Reading'!S24-'Kwh Reading'!S23)*1000 -> 0 | K23: =('Kwh Reading'!I24-'Kwh Reading'!I23)*1000 -> 0 | L23: =('Kwh Reading'!B24-'Kwh Reading'!B23)*1000 -> 0 | M23: =('Kwh Reading'!M24-'Kwh Reading'!M23)*1000 -> 0 | N23: =('Kwh Reading'!H24-'Kwh Reading'!H23)*1000 -> 0 | O23: =('Kwh Reading'!P24-'Kwh Reading'!P23)*1000 -> 0 | P23: =('Kwh Reading'!G24-'Kwh Reading'!G23)*1000 -> 0 | Q23: =('Kwh Reading'!Q24-'Kwh Reading'!Q23)*1000 -> 0 | R23: =('Kwh Reading'!N24-'Kwh Reading'!N23)*1000 -> 0 | S23: ='Kwh Reading'!E24-'Kwh Reading'!E23 -> 0 | T23: ='Kwh Reading'!D24-'Kwh Reading'!D23 -> 0 | U23: =('Kwh Reading'!O24-'Kwh Reading'!O23)*1000 -> 0 | V23: =B23-(SUM(C23:U23)) -> 0
A24: ='Kwh Reading'!A24 -> 44217 | B24: =TOTAL!E22 -> 0 | C24: =('Kwh Reading'!T25-'Kwh Reading'!T24)*1000 -> 0 | D24: =('Kwh Reading'!F25-'Kwh Reading'!F24)*1000000 -> 0 | E24: =('Kwh Reading'!C25-'Kwh Reading'!C24)*1000 -> 0 | F24: =('Kwh Reading'!J25-'Kwh Reading'!J24)*1000 -> 0 | G24: =('Kwh Reading'!K25-'Kwh Reading'!K24)*1000 -> 0 | H24: =('Kwh Reading'!L25-'Kwh Reading'!L24)*1000 -> 0 | I24: =('Kwh Reading'!R25-'Kwh Reading'!R24)*1000 -> 0 | J24: =('Kwh Reading'!S25-'Kwh Reading'!S24)*1000 -> 0 | K24: =('Kwh Reading'!I25-'Kwh Reading'!I24)*1000 -> 0 | L24: =('Kwh Reading'!B25-'Kwh Reading'!B24)*1000 -> 0 | M24: =('Kwh Reading'!M25-'Kwh Reading'!M24)*1000 -> 0 | N24: =('Kwh Reading'!H25-'Kwh Reading'!H24)*1000 -> 0 | O24: =('Kwh Reading'!P25-'Kwh Reading'!P24)*1000 -> 0 | P24: =('Kwh Reading'!G25-'Kwh Reading'!G24)*1000 -> 0 | Q24: =('Kwh Reading'!Q25-'Kwh Reading'!Q24)*1000 -> 0 | R24: =('Kwh Reading'!N25-'Kwh Reading'!N24)*1000 -> 0 | S24: ='Kwh Reading'!E25-'Kwh Reading'!E24 -> 0 | T24: ='Kwh Reading'!D25-'Kwh Reading'!D24 -> 0 | U24: =('Kwh Reading'!O25-'Kwh Reading'!O24)*1000 -> 0 | V24: =B24-(SUM(C24:U24)) -> 0
A25: ='Kwh Reading'!A25 -> 44218 | B25: =TOTAL!E23 -> 0 | C25: =('Kwh Reading'!T26-'Kwh Reading'!T25)*1000 -> 0 | D25: =('Kwh Reading'!F26-'Kwh Reading'!F25)*1000000 -> 0 | E25: =('Kwh Reading'!C26-'Kwh Reading'!C25)*1000 -> 0 | F25: =('Kwh Reading'!J26-'Kwh Reading'!J25)*1000 -> 0 | G25: =('Kwh Reading'!K26-'Kwh Reading'!K25)*1000 -> 0 | H25: =('Kwh Reading'!L26-'Kwh Reading'!L25)*1000 -> 0 | I25: =('Kwh Reading'!R26-'Kwh Reading'!R25)*1000 -> 0 | J25: =('Kwh Reading'!S26-'Kwh Reading'!S25)*1000 -> 0 | K25: =('Kwh Reading'!I26-'Kwh Reading'!I25)*1000 -> 0 | L25: =('Kwh Reading'!B26-'Kwh Reading'!B25)*1000 -> 0 | M25: =('Kwh Reading'!M26-'Kwh Reading'!M25)*1000 -> 0 | N25: =('Kwh Reading'!H26-'Kwh Reading'!H25)*1000 -> 0 | O25: =('Kwh Reading'!P26-'Kwh Reading'!P25)*1000 -> 0 | P25: =('Kwh Reading'!G26-'Kwh Reading'!G25)*1000 -> 0 | Q25: =('Kwh Reading'!Q26-'Kwh Reading'!Q25)*1000 -> 0 | R25: =('Kwh Reading'!N26-'Kwh Reading'!N25)*1000 -> 0 | S25: ='Kwh Reading'!E26-'Kwh Reading'!E25 -> 0 | T25: ='Kwh Reading'!D26-'Kwh Reading'!D25 -> 0 | U25: =('Kwh Reading'!O26-'Kwh Reading'!O25)*1000 -> 0 | V25: =B25-(SUM(C25:U25)) -> 0
A26: ='Kwh Reading'!A26 -> 44219 | B26: =TOTAL!E24 -> 0 | C26: =('Kwh Reading'!T27-'Kwh Reading'!T26)*1000 -> 0 | D26: =('Kwh Reading'!F27-'Kwh Reading'!F26)*1000000 -> 0 | E26: =('Kwh Reading'!C27-'Kwh Reading'!C26)*1000 -> 0 | F26: =('Kwh Reading'!J27-'Kwh Reading'!J26)*1000 -> 0 | G26: =('Kwh Reading'!K27-'Kwh Reading'!K26)*1000 -> 0 | H26: =('Kwh Reading'!L27-'Kwh Reading'!L26)*1000 -> 0 | I26: =('Kwh Reading'!R27-'Kwh Reading'!R26)*1000 -> 0 | J26: =('Kwh Reading'!S27-'Kwh Reading'!S26)*1000 -> 0 | K26: =('Kwh Reading'!I27-'Kwh Reading'!I26)*1000 -> 0 | L26: =('Kwh Reading'!B27-'Kwh Reading'!B26)*1000 -> 0 | M26: =('Kwh Reading'!M27-'Kwh Reading'!M26)*1000 -> 0 | N26: =('Kwh Reading'!H27-'Kwh Reading'!H26)*1000 -> 0 | O26: =('Kwh Reading'!P27-'Kwh Reading'!P26)*1000 -> 0 | P26: =('Kwh Reading'!G27-'Kwh Reading'!G26)*1000 -> 0 | Q26: =('Kwh Reading'!Q27-'Kwh Reading'!Q26)*1000 -> 0 | R26: =('Kwh Reading'!N27-'Kwh Reading'!N26)*1000 -> 0 | S26: ='Kwh Reading'!E27-'Kwh Reading'!E26 -> 0 | T26: ='Kwh Reading'!D27-'Kwh Reading'!D26 -> 0 | U26: =('Kwh Reading'!O27-'Kwh Reading'!O26)*1000 -> 0 | V26: =B26-(SUM(C26:U26)) -> 0
A27: ='Kwh Reading'!A27 -> 44220 | B27: =TOTAL!E25 -> 0 | C27: =('Kwh Reading'!T28-'Kwh Reading'!T27)*1000 -> 0 | D27: =('Kwh Reading'!F28-'Kwh Reading'!F27)*1000000 -> 0 | E27: =('Kwh Reading'!C28-'Kwh Reading'!C27)*1000 -> 0 | F27: =('Kwh Reading'!J28-'Kwh Reading'!J27)*1000 -> 0 | G27: =('Kwh Reading'!K28-'Kwh Reading'!K27)*1000 -> 0 | H27: =('Kwh Reading'!L28-'Kwh Reading'!L27)*1000 -> 0 | I27: =('Kwh Reading'!R28-'Kwh Reading'!R27)*1000 -> 0 | J27: =('Kwh Reading'!S28-'Kwh Reading'!S27)*1000 -> 0 | K27: =('Kwh Reading'!I28-'Kwh Reading'!I27)*1000 -> 0 | L27: =('Kwh Reading'!B28-'Kwh Reading'!B27)*1000 -> 0 | M27: =('Kwh Reading'!M28-'Kwh Reading'!M27)*1000 -> 0 | N27: =('Kwh Reading'!H28-'Kwh Reading'!H27)*1000 -> 0 | O27: =('Kwh Reading'!P28-'Kwh Reading'!P27)*1000 -> 0 | P27: =('Kwh Reading'!G28-'Kwh Reading'!G27)*1000 -> 0 | Q27: =('Kwh Reading'!Q28-'Kwh Reading'!Q27)*1000 -> 0 | R27: =('Kwh Reading'!N28-'Kwh Reading'!N27)*1000 -> 0 | S27: 0 | T27: ='Kwh Reading'!D28-'Kwh Reading'!D27 -> 0 | U27: =('Kwh Reading'!O28-'Kwh Reading'!O27)*1000 -> 0 | V27: =B27-(SUM(C27:U27)) -> 0
A28: ='Kwh Reading'!A28 -> 44221 | B28: =TOTAL!E26 -> 0 | C28: =('Kwh Reading'!T29-'Kwh Reading'!T28)*1000 -> 0 | D28: =('Kwh Reading'!F29-'Kwh Reading'!F28)*1000000 -> 0 | E28: =('Kwh Reading'!C29-'Kwh Reading'!C28)*1000 -> 0 | F28: =('Kwh Reading'!J29-'Kwh Reading'!J28)*1000 -> 0 | G28: =('Kwh Reading'!K29-'Kwh Reading'!K28)*1000 -> 0 | H28: =('Kwh Reading'!L29-'Kwh Reading'!L28)*1000 -> 0 | I28: =('Kwh Reading'!R29-'Kwh Reading'!R28)*1000 -> 0 | J28: =('Kwh Reading'!S29-'Kwh Reading'!S28)*1000 -> 0 | K28: =('Kwh Reading'!I29-'Kwh Reading'!I28)*1000 -> 0 | L28: =('Kwh Reading'!B29-'Kwh Reading'!B28)*1000 -> 0 | M28: =('Kwh Reading'!M29-'Kwh Reading'!M28)*1000 -> 0 | N28: =('Kwh Reading'!H29-'Kwh Reading'!H28)*1000 -> 0 | O28: =('Kwh Reading'!P29-'Kwh Reading'!P28)*1000 -> 0 | P28: =('Kwh Reading'!G29-'Kwh Reading'!G28)*1000 -> 0 | Q28: =('Kwh Reading'!Q29-'Kwh Reading'!Q28)*1000 -> 0 | R28: =('Kwh Reading'!N29-'Kwh Reading'!N28)*1000 -> 0 | S28: ='Kwh Reading'!E29-'Kwh Reading'!E28 -> 0 | T28: ='Kwh Reading'!D29-'Kwh Reading'!D28 -> 0 | U28: =('Kwh Reading'!O29-'Kwh Reading'!O28)*1000 -> 0 | V28: =B28-(SUM(C28:U28)) -> 0
A29: ='Kwh Reading'!A29 -> 44222 | B29: =TOTAL!E27 -> 0 | C29: =('Kwh Reading'!T30-'Kwh Reading'!T29)*1000 -> 0 | D29: =('Kwh Reading'!F30-'Kwh Reading'!F29)*1000000 -> 0 | E29: =('Kwh Reading'!C30-'Kwh Reading'!C29)*1000 -> 0 | F29: =('Kwh Reading'!J30-'Kwh Reading'!J29)*1000 -> 0 | G29: =('Kwh Reading'!K30-'Kwh Reading'!K29)*1000 -> 0 | H29: =('Kwh Reading'!L30-'Kwh Reading'!L29)*1000 -> 0 | I29: =('Kwh Reading'!R30-'Kwh Reading'!R29)*1000 -> 0 | J29: =('Kwh Reading'!S30-'Kwh Reading'!S29)*1000 -> 0 | K29: =('Kwh Reading'!I30-'Kwh Reading'!I29)*1000 -> 0 | L29: =('Kwh Reading'!B30-'Kwh Reading'!B29)*1000 -> 0 | M29: =('Kwh Reading'!M30-'Kwh Reading'!M29)*1000 -> 0 | N29: =('Kwh Reading'!H30-'Kwh Reading'!H29)*1000 -> 0 | O29: =('Kwh Reading'!P30-'Kwh Reading'!P29)*1000 -> 0 | P29: =('Kwh Reading'!G30-'Kwh Reading'!G29)*1000 -> 0 | Q29: =('Kwh Reading'!Q30-'Kwh Reading'!Q29)*1000 -> 0 | R29: =('Kwh Reading'!N30-'Kwh Reading'!N29)*1000 -> 0 | S29: ='Kwh Reading'!E30-'Kwh Reading'!E29 -> 0 | T29: ='Kwh Reading'!D30-'Kwh Reading'!D29 -> 0 | U29: =('Kwh Reading'!O30-'Kwh Reading'!O29)*1000 -> 0 | V29: =B29-(SUM(C29:U29)) -> 0
A30: ='Kwh Reading'!A30 -> 44223 | B30: =TOTAL!E28 -> 0 | C30: =('Kwh Reading'!T31-'Kwh Reading'!T30)*1000 -> 0 | D30: =('Kwh Reading'!F31-'Kwh Reading'!F30)*1000000 -> 0 | E30: =('Kwh Reading'!C31-'Kwh Reading'!C30)*1000 -> 0 | F30: =('Kwh Reading'!J31-'Kwh Reading'!J30)*1000 -> 0 | G30: =('Kwh Reading'!K31-'Kwh Reading'!K30)*1000 -> 0 | H30: =('Kwh Reading'!L31-'Kwh Reading'!L30)*1000 -> 0 | I30: =('Kwh Reading'!R31-'Kwh Reading'!R30)*1000 -> 0 | J30: =('Kwh Reading'!S31-'Kwh Reading'!S30)*1000 -> 0 | K30: =('Kwh Reading'!I31-'Kwh Reading'!I30)*1000 -> 0 | L30: =('Kwh Reading'!B31-'Kwh Reading'!B30)*1000 -> 0 | M30: =('Kwh Reading'!M31-'Kwh Reading'!M30)*1000 -> 0 | N30: =('Kwh Reading'!H31-'Kwh Reading'!H30)*1000 -> 0 | O30: =('Kwh Reading'!P31-'Kwh Reading'!P30)*1000 -> 0 | P30: =('Kwh Reading'!G31-'Kwh Reading'!G30)*1000 -> 0 | Q30: =('Kwh Reading'!Q31-'Kwh Reading'!Q30)*1000 -> 0 | R30: =('Kwh Reading'!N31-'Kwh Reading'!N30)*1000 -> 0 | S30: ='Kwh Reading'!E31-'Kwh Reading'!E30 -> 0 | T30: ='Kwh Reading'!D31-'Kwh Reading'!D30 -> 0 | U30: =('Kwh Reading'!O31-'Kwh Reading'!O30)*1000 -> 0 | V30: =B30-(SUM(C30:U30)) -> 0
A31: ='Kwh Reading'!A31 -> 44224 | B31: =TOTAL!E29 -> 0 | C31: =('Kwh Reading'!T32-'Kwh Reading'!T31)*1000 -> 0 | D31: =('Kwh Reading'!F32-'Kwh Reading'!F31)*1000000 -> 0 | E31: =('Kwh Reading'!C32-'Kwh Reading'!C31)*1000 -> 0 | F31: =('Kwh Reading'!J32-'Kwh Reading'!J31)*1000 -> 0 | G31: =('Kwh Reading'!K32-'Kwh Reading'!K31)*1000 -> 0 | H31: =('Kwh Reading'!L32-'Kwh Reading'!L31)*1000 -> 0 | I31: =('Kwh Reading'!R32-'Kwh Reading'!R31)*1000 -> 0 | J31: =('Kwh Reading'!S32-'Kwh Reading'!S31)*1000 -> 0 | K31: =('Kwh Reading'!I32-'Kwh Reading'!I31)*1000 -> 0 | L31: =('Kwh Reading'!B32-'Kwh Reading'!B31)*1000 -> 0 | M31: =('Kwh Reading'!M32-'Kwh Reading'!M31)*1000 -> 0 | N31: =('Kwh Reading'!H32-'Kwh Reading'!H31)*1000 -> 0 | O31: =('Kwh Reading'!P32-'Kwh Reading'!P31)*1000 -> 0 | P31: =('Kwh Reading'!G32-'Kwh Reading'!G31)*1000 -> 0 | Q31: =('Kwh Reading'!Q32-'Kwh Reading'!Q31)*1000 -> 0 | R31: =('Kwh Reading'!N32-'Kwh Reading'!N31)*1000 -> 0 | S31: ='Kwh Reading'!E32-'Kwh Reading'!E31 -> 0 | T31: ='Kwh Reading'!D32-'Kwh Reading'!D31 -> 0 | U31: =('Kwh Reading'!O32-'Kwh Reading'!O31)*1000 -> 0 | V31: =B31-(SUM(C31:U31)) -> 0
A32: ='Kwh Reading'!A32 -> 44225 | B32: =TOTAL!E30 -> 0 | C32: =('Kwh Reading'!T33-'Kwh Reading'!T32)*1000 -> 0 | D32: =('Kwh Reading'!F33-'Kwh Reading'!F32)*1000000 -> 0 | E32: =('Kwh Reading'!C33-'Kwh Reading'!C32)*1000 -> 0 | F32: =('Kwh Reading'!J33-'Kwh Reading'!J32)*1000 -> 0 | G32: =('Kwh Reading'!K33-'Kwh Reading'!K32)*1000 -> 0 | H32: =('Kwh Reading'!L33-'Kwh Reading'!L32)*1000 -> 0 | I32: =('Kwh Reading'!R33-'Kwh Reading'!R32)*1000 -> 0 | J32: =('Kwh Reading'!S33-'Kwh Reading'!S32)*1000 -> 0 | K32: =('Kwh Reading'!I33-'Kwh Reading'!I32)*1000 -> 0 | L32: =('Kwh Reading'!B33-'Kwh Reading'!B32)*1000 -> 0 | M32: =('Kwh Reading'!M33-'Kwh Reading'!M32)*1000 -> 0 | N32: =('Kwh Reading'!H33-'Kwh Reading'!H32)*1000 -> 0 | O32: =('Kwh Reading'!P33-'Kwh Reading'!P32)*1000 -> 0 | P32: =('Kwh Reading'!G33-'Kwh Reading'!G32)*1000 -> 0 | Q32: =('Kwh Reading'!Q33-'Kwh Reading'!Q32)*1000 -> 0 | R32: =('Kwh Reading'!N33-'Kwh Reading'!N32)*1000 -> 0 | S32: ='Kwh Reading'!E33-'Kwh Reading'!E32 -> 0 | T32: ='Kwh Reading'!D33-'Kwh Reading'!D32 -> 0 | U32: =('Kwh Reading'!O33-'Kwh Reading'!O32)*1000 -> 0 | V32: =B32-(SUM(C32:U32)) -> 0
A33: ='Kwh Reading'!A33 -> 44226 | B33: =TOTAL!E31 -> 0 | C33: =('Kwh Reading'!T34-'Kwh Reading'!T33)*1000 -> 0 | D33: =('Kwh Reading'!F34-'Kwh Reading'!F33)*1000000 -> 0 | E33: =('Kwh Reading'!C34-'Kwh Reading'!C33)*1000 -> 0 | F33: =('Kwh Reading'!J34-'Kwh Reading'!J33)*1000 -> 0 | G33: =('Kwh Reading'!K34-'Kwh Reading'!K33)*1000 -> 0 | H33: =('Kwh Reading'!L34-'Kwh Reading'!L33)*1000 -> 0 | I33: =('Kwh Reading'!R34-'Kwh Reading'!R33)*1000 -> 0 | J33: =('Kwh Reading'!S34-'Kwh Reading'!S33)*1000 -> 0 | K33: =('Kwh Reading'!I34-'Kwh Reading'!I33)*1000 -> 0 | L33: =('Kwh Reading'!B34-'Kwh Reading'!B33)*1000 -> 0 | M33: =('Kwh Reading'!M34-'Kwh Reading'!M33)*1000 -> 0 | N33: =('Kwh Reading'!H34-'Kwh Reading'!H33)*1000 -> 0 | O33: =('Kwh Reading'!P34-'Kwh Reading'!P33)*1000 -> 0 | P33: =('Kwh Reading'!G34-'Kwh Reading'!G33)*1000 -> 0 | Q33: =('Kwh Reading'!Q34-'Kwh Reading'!Q33)*1000 -> 0 | R33: =('Kwh Reading'!N34-'Kwh Reading'!N33)*1000 -> 0 | S33: ='Kwh Reading'!E34-'Kwh Reading'!E33 -> 0 | T33: ='Kwh Reading'!D34-'Kwh Reading'!D33 -> 0 | U33: =('Kwh Reading'!O34-'Kwh Reading'!O33)*1000 -> 0 | V33: =B33-(SUM(C33:U33)) -> 0
A34: ='Kwh Reading'!A34 -> 44227 | B34: =TOTAL!E32 -> 0 | C34: =('Kwh Reading'!T35-'Kwh Reading'!T34)*1000 -> 0 | D34: =('Kwh Reading'!F35-'Kwh Reading'!F34)*1000000 -> 0 | E34: =('Kwh Reading'!C35-'Kwh Reading'!C34)*1000 -> 0 | F34: =('Kwh Reading'!J35-'Kwh Reading'!J34)*1000 -> 0 | G34: =('Kwh Reading'!K35-'Kwh Reading'!K34)*1000 -> 0 | H34: =('Kwh Reading'!L35-'Kwh Reading'!L34)*1000 -> 0 | I34: =('Kwh Reading'!R35-'Kwh Reading'!R34)*1000 -> 0 | J34: =('Kwh Reading'!S35-'Kwh Reading'!S34)*1000 -> 0 | K34: =('Kwh Reading'!I35-'Kwh Reading'!I34)*1000 -> 0 | L34: =('Kwh Reading'!B35-'Kwh Reading'!B34)*1000 -> 0 | M34: =('Kwh Reading'!M35-'Kwh Reading'!M34)*1000 -> 0 | N34: =('Kwh Reading'!H35-'Kwh Reading'!H34)*1000 -> 0 | O34: =('Kwh Reading'!P35-'Kwh Reading'!P34)*1000 -> 0 | P34: =('Kwh Reading'!G35-'Kwh Reading'!G34)*1000 -> 0 | Q34: =('Kwh Reading'!Q35-'Kwh Reading'!Q34)*1000 -> 0 | R34: =('Kwh Reading'!N35-'Kwh Reading'!N34)*1000 -> 0 | S34: ='Kwh Reading'!E35-'Kwh Reading'!E34 -> 0 | T34: ='Kwh Reading'!D35-'Kwh Reading'!D34 -> 0 | U34: =('Kwh Reading'!O35-'Kwh Reading'!O34)*1000 -> 0 | V34: =B34-(SUM(C34:U34)) -> 0
A35: Total | B35: =SUM(B4:B34) -> 247040 | C35: =SUM(C4:C34) -> -334740 | D35: =SUM(D4:D34) -> -1935500 | E35: =SUM(E4:E34) -> -187450 | F35: =SUM(F4:F34) -> -272090 | G35: =SUM(G4:G34) -> -283610 | H35: =SUM(H4:H34) -> -194770 | I35: =SUM(I4:I34) -> -114300 | ... V35: =SUM(V4:V34) -> 21978814

Sheet Kwh area wise 
A2: Month | B2: Total KWH | C2: Reef Club Kitchen KWH | D2: Main Kitchen KWH | E2: Pastry Kitchen KWH | F2: Laundry KWH | G2: STP KWH | H2: Kuda Huraa Accomodation KWH | I2: Guest Room Beach Pavilion & Beach Bungalow KWH | J2: Guest Room Water Bungalow KWH | K2: Spa KWH | L2: Others KWH
A3: ='Kwh Reading'!A4 -> 44197 | B3: =TOTAL!E2 -> 19020 | C3: ='Kwh Consumption'!C4 -> 530 | D3: ='Kwh Consumption'!D4 -> 2600 | E3: ='Kwh Consumption'!E4 -> 280 | F3: =('Kwh Consumption'!F4+'Kwh Consumption'!G4+'Kwh Consumption'!H4) -> 1120 | G3: =('Kwh Consumption'!I4+'Kwh Consumption'!J4) -> 334 | H3: =('Kwh Consumption'!K4+'Kwh Consumption'!L4) -> 1110 | I3: =('Kwh Consumption'!M4+'Kwh Consumption'!N4+'Kwh Consumption'!O4+'Kwh Consumption'!P4+'Kwh Consumption'!Q4+'Kwh Consumption'!R4) -> 3590 | J3: =('Kwh Consumption'!S4+'Kwh Consumption'!T4) -> 4361.49 | K3: ='Kwh Consumption'!U4 -> 230 | L3: =B3-C3-D3-E3-F3-G3-H3-I3-J3-K3 -> 4864.51
A4: ='Kwh Reading'!A5 -> 44198 | B4: =TOTAL!E3 -> 22270 | C4: ='Kwh Consumption'!C5 -> 590 | D4: ='Kwh Consumption'!D5 -> 2600 | E4: ='Kwh Consumption'!E5 -> 270 | F4: =('Kwh Consumption'!F5+'Kwh Consumption'!G5+'Kwh Consumption'!H5) -> 890 | G4: =('Kwh Consumption'!I5+'Kwh Consumption'!J5) -> 243 | H4: =('Kwh Consumption'!K5+'Kwh Consumption'!L5) -> 1330 | I4: =('Kwh Consumption'!M5+'Kwh Consumption'!N5+'Kwh Consumption'!O5+'Kwh Consumption'!P5+'Kwh Consumption'!Q5+'Kwh Consumption'!R5) -> 4390 | J4: =('Kwh Consumption'!S5+'Kwh Consumption'!T5) -> 4990.03 | K4: ='Kwh Consumption'!U5 -> 310 | L4: =B4-C4-D4-E4-F4-G4-H4-I4-J4-K4 -> 6656.97
A5: ='Kwh Reading'!A6 -> 44199 | B5: =TOTAL!E4 -> 23276 | C5: ='Kwh Consumption'!C6 -> 550 | D5: ='Kwh Consumption'!D6 -> 2600 | E5: ='Kwh Consumption'!E6 -> 250 | F5: =('Kwh Consumption'!F6+'Kwh Consumption'!G6+'Kwh Consumption'!H6) -> 1340 | G5: =('Kwh Consumption'!I6+'Kwh Consumption'!J6) -> 327 | H5: =('Kwh Consumption'!K6+'Kwh Consumption'!L6) -> 1440 | I5: =('Kwh Consumption'!M6+'Kwh Consumption'!N6+'Kwh Consumption'!O6+'Kwh Consumption'!P6+'Kwh Consumption'!Q6+'Kwh Consumption'!R6) -> 4580 | J5: =('Kwh Consumption'!S6+'Kwh Consumption'!T6) -> 5287.5 | K5: ='Kwh Consumption'!U6 -> 270 | L5: =B5-C5-D5-E5-F5-G5-H5-I5-J5-K5 -> 6631.5
A6: ='Kwh Reading'!A7 -> 44200 | B6: =TOTAL!E5 -> 20044 | C6: ='Kwh Consumption'!C7 -> 310 | D6: ='Kwh Consumption'!D7 -> 2500 | E6: ='Kwh Consumption'!E7 -> 270 | F6: =('Kwh Consumption'!F7+'Kwh Consumption'!G7+'Kwh Consumption'!H7) -> 930 | G6: =('Kwh Consumption'!I7+'Kwh Consumption'!J7) -> 322 | H6: =('Kwh Consumption'!K7+'Kwh Consumption'!L7) -> 1270 | I6: =('Kwh Consumption'!M7+'Kwh Consumption'!N7+'Kwh Consumption'!O7+'Kwh Consumption'!P7+'Kwh Consumption'!Q7+'Kwh Consumption'!R7) -> 3850 | J6: =('Kwh Consumption'!S7+'Kwh Consumption'!T7) -> 4502.51 | K6: ='Kwh Consumption'!U7 -> 270 | L6: =B6-C6-D6-E6-F6-G6-H6-I6-J6-K6 -> 5819.49
A7: ='Kwh Reading'!A8 -> 44201 | B7: =TOTAL!E6 -> 19110 | C7: ='Kwh Consumption'!C8 -> 860 | D7: ='Kwh Consumption'!D8 -> 2500 | E7: ='Kwh Consumption'!E8 -> 290 | F7: =('Kwh Consumption'!F8+'Kwh Consumption'!G8+'Kwh Consumption'!H8) -> 1200 | G7: =('Kwh Consumption'!I8+'Kwh Consumption'!J8) -> 301 | H7: =('Kwh Consumption'!K8+'Kwh Consumption'!L8) -> 1200 | I7: =('Kwh Consumption'!M8+'Kwh Consumption'!N8+'Kwh Consumption'!O8+'Kwh Consumption'!P8+'Kwh Consumption'!Q8+'Kwh Consumption'!R8) -> 3520 | J7: =('Kwh Consumption'!S8+'Kwh Consumption'!T8) -> 3981.43 | K7: ='Kwh Consumption'!U8 -> 280 | L7: =B7-C7-D7-E7-F7-G7-H7-I7-J7-K7 -> 4977.57
A8: ='Kwh Reading'!A9 -> 44202 | B8: =TOTAL!E7 -> 18760 | C8: ='Kwh Consumption'!C9 -> 600 | D8: ='Kwh Consumption'!D9 -> 2400 | E8: ='Kwh Consumption'!E9 -> 250 | F8: =('Kwh Consumption'!F9+'Kwh Consumption'!G9+'Kwh Consumption'!H9) -> 990 | G8: =('Kwh Consumption'!I9+'Kwh Consumption'!J9) -> 353 | H8: =('Kwh Consumption'!K9+'Kwh Consumption'!L9) -> 1270 | I8: =('Kwh Consumption'!M9+'Kwh Consumption'!N9+'Kwh Consumption'!O9+'Kwh Consumption'!P9+'Kwh Consumption'!Q9+'Kwh Consumption'!R9) -> 3530 | J8: =('Kwh Consumption'!S9+'Kwh Consumption'!T9) -> 4288.52 | K8: ='Kwh Consumption'!U9 -> 290 | L8: =B8-C8-D8-E8-F8-G8-H8-I8-J8-K8 -> 4788.48
A9: ='Kwh Reading'!A10 -> 44203 | B9: =TOTAL!E8 -> 22080 | C9: ='Kwh Consumption'!C10 -> 250 | D9: ='Kwh Consumption'!D10 -> 2700 | E9: ='Kwh Consumption'!E10 -> 280 | F9: =('Kwh Consumption'!F10+'Kwh Consumption'!G10+'Kwh Consumption'!H10) -> 1410 | G9: =('Kwh Consumption'!I10+'Kwh Consumption'!J10) -> 394 | H9: =('Kwh Consumption'!K10+'Kwh Consumption'!L10) -> 1620 | I9: =('Kwh Consumption'!M10+'Kwh Consumption'!N10+'Kwh Consumption'!O10+'Kwh Consumption'!P10+'Kwh Consumption'!Q10+'Kwh Consumption'!R10) -> 4660 | J9: =('Kwh Consumption'!S10+'Kwh Consumption'!T10) -> 5119.68 | K9: ='Kwh Consumption'!U10 -> 270 | L9: =B9-C9-D9-E9-F9-G9-H9-I9-J9-K9 -> 5376.32
A10: ='Kwh Reading'!A11 -> 44204 | B10: =TOTAL!E9 -> 19940 | C10: ='Kwh Consumption'!C11 -> 850 | D10: ='Kwh Consumption'!D11 -> 2500 | E10: ='Kwh Consumption'!E11 -> 260 | F10: =('Kwh Consumption'!F11+'Kwh Consumption'!G11+'Kwh Consumption'!H11) -> 1320 | G10: =('Kwh Consumption'!I11+'Kwh Consumption'!J11) -> 277 | H10: =('Kwh Consumption'!K11+'Kwh Consumption'!L11) -> 1290 | I10: =('Kwh Consumption'!M11+'Kwh Consumption'!N11+'Kwh Consumption'!O11+'Kwh Consumption'!P11+'Kwh Consumption'!Q11+'Kwh Consumption'!R11) -> 4070 | J10: =('Kwh Consumption'!S11+'Kwh Consumption'!T11) -> 4863.68 | K10: ='Kwh Consumption'!U11 -> 260 | L10: =B10-C10-D10-E10-F10-G10-H10-I10-J10-K10 -> 4249.32
A11: ='Kwh Reading'!A12 -> 44205 | B11: =TOTAL!E10 -> 20900 | C11: ='Kwh Consumption'!C12 -> 540 | D11: ='Kwh Consumption'!D12 -> 2400 | E11: ='Kwh Consumption'!E12 -> 250 | F11: =('Kwh Consumption'!F12+'Kwh Consumption'!G12+'Kwh Consumption'!H12) -> 770 | G11: =('Kwh Consumption'!I12+'Kwh Consumption'!J12) -> 389 | H11: =('Kwh Consumption'!K12+'Kwh Consumption'!L12) -> 1300 | I11: =('Kwh Consumption'!M12+'Kwh Consumption'!N12+'Kwh Consumption'!O12+'Kwh Consumption'!P12+'Kwh Consumption'!Q12+'Kwh Consumption'!R12) -> 4000 | J11: =('Kwh Consumption'!S12+'Kwh Consumption'!T12) -> 4478.28 | K11: ='Kwh Consumption'!U12 -> 300 | L11: =B11-C11-D11-E11-F11-G11-H11-I11-J11-K11 -> 6472.72
A12: ='Kwh Reading'!A13 -> 44206 | B12: =TOTAL!E11 -> 21480 | C12: ='Kwh Consumption'!C13 -> 430 | D12: ='Kwh Consumption'!D13 -> 2500 | E12: ='Kwh Consumption'!E13 -> 260 | F12: =('Kwh Consumption'!F13+'Kwh Consumption'!G13+'Kwh Consumption'!H13) -> 980 | G12: =('Kwh Consumption'!I13+'Kwh Consumption'!J13) -> 350 | H12: =('Kwh Consumption'!K13+'Kwh Consumption'!L13) -> 1710 | I12: =('Kwh Consumption'!M13+'Kwh Consumption'!N13+'Kwh Consumption'!O13+'Kwh Consumption'!P13+'Kwh Consumption'!Q13+'Kwh Consumption'!R13) -> 4310 | J12: =('Kwh Consumption'!S13+'Kwh Consumption'!T13) -> 4786.29 | K12: ='Kwh Consumption'!U13 -> 240 | L12: =B12-C12-D12-E12-F12-G12-H12-I12-J12-K12 -> 5913.71
A13: ='Kwh Reading'!A14 -> 44207 | B13: =TOTAL!E12 -> 20740 | C13: ='Kwh Consumption'!C14 -> 740 | D13: ='Kwh Consumption'!D14 -> 2500 | E13: ='Kwh Consumption'!E14 -> 250 | F13: =('Kwh Consumption'!F14+'Kwh Consumption'!G14+'Kwh Consumption'!H14) -> 860 | G13: =('Kwh Consumption'!I14+'Kwh Consumption'!J14) -> 316 | H13: =('Kwh Consumption'!K14+'Kwh Consumption'!L14) -> 1150 | I13: =('Kwh Consumption'!M14+'Kwh Consumption'!N14+'Kwh Consumption'!O14+'Kwh Consumption'!P14+'Kwh Consumption'!Q14+'Kwh Consumption'!R14) -> 4440 | J13: =('Kwh Consumption'!S14+'Kwh Consumption'!T14) -> 5007.85 | K13: ='Kwh Consumption'!U14 -> 260 | L13: =B13-C13-D13-E13-F13-G13-H13-I13-J13-K13 -> 5216.15
A14: ='Kwh Reading'!A15 -> 44208 | B14: =TOTAL!E13 -> 19420 | C14: ='Kwh Consumption'!C15 -> 380 | D14: ='Kwh Consumption'!D15 -> 2500 | E14: ='Kwh Consumption'!E15 -> 290 | F14: =('Kwh Consumption'!F15+'Kwh Consumption'!G15+'Kwh Consumption'!H15) -> 1040 | G14: =('Kwh Consumption'!I15+'Kwh Consumption'!J15) -> 307 | H14: =('Kwh Consumption'!K15+'Kwh Consumption'!L15) -> 1330 | I14: =('Kwh Consumption'!M15+'Kwh Consumption'!N15+'Kwh Consumption'!O15+'Kwh Consumption'!P15+'Kwh Consumption'!Q15+'Kwh Consumption'!R15) -> 4130 | J14: =('Kwh Consumption'!S15+'Kwh Consumption'!T15) -> 4793.28 | K14: ='Kwh Consumption'!U15 -> 240 | L14: =B14-C14-D14-E14-F14-G14-H14-I14-J14-K14 -> 4409.72
... A33: ='Kwh Reading'!A34 -> 44227 | B33: =TOTAL!E32 -> 0 | C33: ='Kwh Consumption'!C34 -> 0 | D33: ='Kwh Consumption'!D34 -> 0 | E33: ='Kwh Consumption'!E34 -> 0 | F33: =('Kwh Consumption'!F34+'Kwh Consumption'!G34+'Kwh Consumption'!H34) -> 0 | G33: =('Kwh Consumption'!I34+'Kwh Consumption'!J34) -> 0 | H33: =('Kwh Consumption'!K34+'Kwh Consumption'!L34) -> 0 | I33: =('Kwh Consumption'!M34+'Kwh Consumption'!N34+'Kwh Consumption'!O34+'Kwh Consumption'!P34+'Kwh Consumption'!Q34+'Kwh Consumption'!R34) -> 0 | J33: =('Kwh Consumption'!S34+'Kwh Consumption'!T34) -> 0 | K33: ='Kwh Consumption'!U34 -> 0 | L33: =B33-C33-D33-E33-F33-G33-H33-I33-J33-K33 -> 0
A34: Total kwh | B34: =SUM(B3:B33) -> 247040 | C34: =SUM(C3:C33) -> -334740 | D34: =SUM(D3:D33) -> -1935500 | E34: =SUM(E3:E33) -> -187450 | F34: =SUM(F3:F33) -> -750470 | G34: =SUM(G3:G33) -> -205518 | H34: =SUM(H3:H33) -> -936120 | I34: =SUM(I3:I33) -> -2563600 | ... L34: =SUM(L3:L33) -> 21978814 | M34: =C34+D34+E34+F34+G34+H34+I34+J34+K34+L34 -> 247040
A36: Total $ | B36: =TOTAL!F2 -> 0.13924 | C36: =C34*B36 -> -46609.198 | D36: =D34*B36 -> -269499.02 | E36: =E34*B36 -> -26100.538 | F36: =F34*B36 -> -104495.44 | G36: =G34*B36 -> -28616.326 | H36: =H34*B36 -> -130345.35 | I36: =I34*B36 -> -356955.66 | J36: =J34*B36 -> -2048361.9 | K36: =K34*B36 -> -14948.806 | L36: =L34*B36 -> 3060330 | M36: =C36+D36+E36+F36+G36+H36+I36+J36+K36+L36 -> 34397.85

Sheet  Kwh area wise $ 
A2: Month | B2: $ /Per KWH | C2: Total $ | D2: Reef Club $ | E2: Kitchen $ | F2: Pastry $ | G2: Laundry $ | H2: STP $ | I2: Kuda Huraa Accomodation $ | J2: Guest Room Beach Pavilion & Beach Bungalow $ | K2: Guest Room Water Bungalow $ | L2: Spa $ | M2: Others $
A3: ='Kwh Reading'!A4 -> 44197 | B3: =TOTAL!F2 -> 0.13924 | C3: ='Kwh Consumption'!B4*' Kwh area wise $ '!B3 -> 2648.3448 | D3: ='Kwh Consumption'!C4*' Kwh area wise $ '!B3 -> 73.7972 | E3: ='Kwh Consumption'!D4*' Kwh area wise $ '!B3 -> 362.024 | F3: ='Kwh Consumption'!E4*' Kwh area wise $ '!B3 -> 38.9872 | G3: =('Kwh Consumption'!F4+'Kwh Consumption'!G4+'Kwh Consumption'!H4)*' Kwh area wise $ '!B3 -> 155.9488 | H3: =('Kwh Consumption'!I4+'Kwh Consumption'!J4)*' Kwh area wise $ '!B3 -> 46.50616 | I3: =('Kwh Consumption'!K4+'Kwh Consumption'!L4)*' Kwh area wise $ '!B3 -> 154.5564 | J3: =('Kwh Consumption'!M4+'Kwh Consumption'!N4+'Kwh Consumption'!O4+'Kwh Consumption'!P4+'Kwh Consumption'!Q4+'Kwh Consumption'!R4)*' Kwh area wise $ '!B3 -> 499.8716 | K3: =('Kwh Consumption'!S4+'Kwh Consumption'!T4)*' Kwh area wise $ '!B3 -> 607.29387 | L3: ='Kwh Consumption'!U4*' Kwh area wise $ '!B3 -> 32.0252 | M3: ='Kwh Consumption'!V4*' Kwh area wise $ '!B3 -> 677.33437
A4: ='Kwh Reading'!A5 -> 44198 | B4: =TOTAL!F3 -> 0.13924 | C4: ='Kwh Consumption'!B5*' Kwh area wise $ '!B4 -> 3100.8748 | D4: ='Kwh Consumption'!C5*' Kwh area wise $ '!B4 -> 82.1516 | E4: ='Kwh Consumption'!D5*' Kwh area wise $ '!B4 -> 362.024 | F4: ='Kwh Consumption'!E5*' Kwh area wise $ '!B4 -> 37.5948 | G4: =('Kwh Consumption'!F5+'Kwh Consumption'!G5+'Kwh Consumption'!H5)*' Kwh area wise $ '!B4 -> 123.9236 | H4: =('Kwh Consumption'!I5+'Kwh Consumption'!J5)*' Kwh area wise $ '!B4 -> 33.83532 | I4: =('Kwh Consumption'!K5+'Kwh Consumption'!L5)*' Kwh area wise $ '!B4 -> 185.1892 | J4: =('Kwh Consumption'!M5+'Kwh Consumption'!N5+'Kwh Consumption'!O5+'Kwh Consumption'!P5+'Kwh Consumption'!Q5+'Kwh Consumption'!R5)*' Kwh area wise $ '!B4 -> 611.2636 | K4: =('Kwh Consumption'!S5+'Kwh Consumption'!T5)*' Kwh area wise $ '!B4 -> 694.81178 | L4: ='Kwh Consumption'!U5*' Kwh area wise $ '!B4 -> 43.1644 | M4: ='Kwh Consumption'!V5*' Kwh area wise $ '!B4 -> 926.9165
A5: ='Kwh Reading'!A6 -> 44199 | B5: =TOTAL!F4 -> 0.13924 | C5: ='Kwh Consumption'!B6*' Kwh area wise $ '!B5 -> 3240.9502 | D5: ='Kwh Consumption'!C6*' Kwh area wise $ '!B5 -> 76.582 | E5: ='Kwh Consumption'!D6*' Kwh area wise $ '!B5 -> 362.024 | F5: ='Kwh Consumption'!E6*' Kwh area wise $ '!B5 -> 34.81 | G5: =('Kwh Consumption'!F6+'Kwh Consumption'!G6+'Kwh Consumption'!H6)*' Kwh area wise $ '!B5 -> 186.5816 | H5: =('Kwh Consumption'!I6+'Kwh Consumption'!J6)*' Kwh area wise $ '!B5 -> 45.53148 | I5: =('Kwh Consumption'!K6+'Kwh Consumption'!L6)*' Kwh area wise $ '!B5 -> 200.5056 | J5: =('Kwh Consumption'!M6+'Kwh Consumption'!N6+'Kwh Consumption'!O6+'Kwh Consumption'!P6+'Kwh Consumption'!Q6+'Kwh Consumption'!R6)*' Kwh area wise $ '!B5 -> 637.7192 | K5: =('Kwh Consumption'!S6+'Kwh Consumption'!T6)*' Kwh area wise $ '!B5 -> 736.2315 | L5: ='Kwh Consumption'!U6*' Kwh area wise $ '!B5 -> 37.5948 | M5: ='Kwh Consumption'!V6*' Kwh area wise $ '!B5 -> 923.37006
A6: ='Kwh Reading'!A7 -> 44200 | B6: =TOTAL!F5 -> 0.13924 | C6: ='Kwh Consumption'!B7*' Kwh area wise $ '!B6 -> 2790.9266 | D6: ='Kwh Consumption'!C7*' Kwh area wise $ '!B6 -> 43.1644 | E6: ='Kwh Consumption'!D7*' Kwh area wise $ '!B6 -> 348.1 | F6: ='Kwh Consumption'!E7*' Kwh area wise $ '!B6 -> 37.5948 | G6: =('Kwh Consumption'!F7+'Kwh Consumption'!G7+'Kwh Consumption'!H7)*' Kwh area wise $ '!B6 -> 129.4932 | H6: =('Kwh Consumption'!I7+'Kwh Consumption'!J7)*' Kwh area wise $ '!B6 -> 44.83528 | I6: =('Kwh Consumption'!K7+'Kwh Consumption'!L7)*' Kwh area wise $ '!B6 -> 176.8348 | J6: =('Kwh Consumption'!M7+'Kwh Consumption'!N7+'Kwh Consumption'!O7+'Kwh Consumption'!P7+'Kwh Consumption'!Q7+'Kwh Consumption'!R7)*' Kwh area wise $ '!B6 -> 536.074 | K6: =('Kwh Consumption'!S7+'Kwh Consumption'!T7)*' Kwh area wise $ '!B6 -> 626.92949 | L6: ='Kwh Consumption'!U7*' Kwh area wise $ '!B6 -> 37.5948 | M6: ='Kwh Consumption'!V7*' Kwh area wise $ '!B6 -> 810.30579
