Workbook

Sheet TOTAL
A1: Site Name | B1: Day | C1: Month | D1: Year | E1: Total Electricity Kwh | F1: Electricity Tariff ($/Kwh) | G1: LPG (Kg) | H1: LPG $/Kg | I1: District Energy Heating Kwh | J1: District Energy Heating $/Kwh | K1: Water Utility Supply (m3) m3 | L1: Water Utility Supply (m3) $/m3 | M1: Room Nights | N1: Total Guests | O1: Utilities day cost dh
A2: Marrakech | B2: 1 | C2: 1 | D2: 2021 | E2: ='Consommation du 01.01 au 31.01'!M10 -> 11675 | F2: 0.99 | G2: ='Consommation du 01.01 au 31.01'!U10 -> 1780.8 | H2: 8.2658 | I2: ='Consommation du 01.01 au 31.01'!Y10*1000 -> 13170 | J2: 0.53 | K2: ='Consommation du 01.01 au 31.01'!D10 -> 390 | L2: 12.67 | M2: ='Consommation du 01.01 au 31.01'!AC10 -> 57 | N2: 57 | O2: =E2*F2+G2*H2+I2*J2+K2*L2 -> 38199.387
A3: Marrakech | B3: =B2+1 -> 2 | C3: 1 | D3: 2021 | E3: ='Consommation du 01.01 au 31.01'!M11 -> 11043 | F3: 0.99 | G3: ='Consommation du 01.01 au 31.01'!U11 -> 593.6 | H3: 8.2658 | I3: ='Consommation du 01.01 au 31.01'!Y11*1000 -> 13420 | J3: 0.53 | K3: ='Consommation du 01.01 au 31.01'!D11 -> 330 | L3: 12.67 | M3: ='Consommation du 01.01 au 31.01'!AC11 -> 53 | N3: 53 | O3: =E3*F3+G3*H3+I3*J3+K3*L3 -> 27132.849
A4: Marrakech | B4: =B3+1 -> 3 | C4: 1 | D4: 2021 | E4: ='Consommation du 01.01 au 31.01'!M12 -> 11010 | F4: 0.99 | G4: ='Consommation du 01.01 au 31.01'!U12 -> 371 | H4: 8.2658 | I4: ='Consommation du 01.01 au 31.01'!Y12*1000 -> 13870 | J4: 0.53 | K4: ='Consommation du 01.01 au 31.01'!D12 -> 280 | L4: 12.67 | M4: ='Consommation du 01.01 au 31.01'!AC12 -> 18 | N4: 18 | O4: =E4*F4+G4*H4+I4*J4+K4*L4 -> 24865.212
A5: Marrakech | B5: =B4+1 -> 4 | C5: 1 | D5: 2021 | E5: ='Consommation du 01.01 au 31.01'!M13 -> 11102 | F5: 0.99 | G5: ='Consommation du 01.01 au 31.01'!U13 -> 259.7 | H5: 8.2658 | I5: ='Consommation du 01.01 au 31.01'!Y13*1000 -> 13770 | J5: 0.53 | K5: ='Consommation du 01.01 au 31.01'!D13 -> 230 | L5: 12.67 | M5: ='Consommation du 01.01 au 31.01'!AC13 -> 14 | N5: 14 | O5: =E5*F5+G5*H5+I5*J5+K5*L5 -> 23349.808
A6: Marrakech | B6: =B5+1 -> 5 | C6: 1 | D6: 2021 | E6: ='Consommation du 01.01 au 31.01'!M14 -> 10491 | F6: 0.99 | G6: ='Consommation du 01.01 au 31.01'!U14 -> 890.4 | H6: 8.2658 | I6: ='Consommation du 01.01 au 31.01'!Y14*1000 -> 9130 | J6: 0.53 | K6: ='Consommation du 01.01 au 31.01'!D14 -> 250 | L6: 12.67 | M6: ='Consommation du 01.01 au 31.01'!AC14 -> 11 | N6: 11 | O6: =E6*F6+G6*H6+I6*J6+K6*L6 -> 25752.358
A7: Marrakech | B7: =B6+1 -> 6 | C7: 1 | D7: 2021 | E7: ='Consommation du 01.01 au 31.01'!M15 -> 10563 | F7: 0.99 | G7: ='Consommation du 01.01 au 31.01'!U15 -> 704.9 | H7: 8.2658 | I7: ='Consommation du 01.01 au 31.01'!Y15*1000 -> 4180 | J7: 0.53 | K7: ='Consommation du 01.01 au 31.01'!D15 -> 270 | L7: 12.67 | M7: ='Consommation du 01.01 au 31.01'!AC15 -> 10 | N7: 10 | O7: =E7*F7+G7*H7+I7*J7+K7*L7 -> 21920.232
A8: Marrakech | B8: =B7+1 -> 7 | C8: 1 | D8: 2021 | E8: ='Consommation du 01.01 au 31.01'!M16 -> 9867 | F8: 0.99 | G8: ='Consommation du 01.01 au 31.01'!U16 -> 296.8 | H8: 8.2658 | I8: ='Consommation du 01.01 au 31.01'!Y16*1000 -> 12520 | J8: 0.53 | K8: ='Consommation du 01.01 au 31.01'!D16 -> 230 | L8: 12.67 | M8: ='Consommation du 01.01 au 31.01'!AC16 -> 6 | N8: 6 | O8: =E8*F8+G8*H8+I8*J8+K8*L8 -> 21771.319
A9: Marrakech | B9: =B8+1 -> 8 | C9: 1 | D9: 2021 | E9: ='Consommation du 01.01 au 31.01'!M17 -> 9200 | F9: 0.99 | G9: ='Consommation du 01.01 au 31.01'!U17 -> 148.4 | H9: 8.2658 | I9: ='Consommation du 01.01 au 31.01'!Y17*1000 -> 11040 | J9: 0.53 | K9: ='Consommation du 01.01 au 31.01'!D17 -> 300 | L9: 12.67 | M9: ='Consommation du 01.01 au 31.01'!AC17 -> 8 | N9: 8 | O9: =E9*F9+G9*H9+I9*J9+K9*L9 -> 19986.845
A10: Marrakech | B10: =B9+1 -> 9 | C10: 1 | D10: 2021 | E10: ='Consommation du 01.01 au 31.01'!M18 -> 10217 | F10: 0.99 | G10: ='Consommation du 01.01 au 31.01'!U18 -> 259.7 | H10: 8.2658 | I10: ='Consommation du 01.01 au 31.01'!Y18*1000 -> 12490 | J10: 0.53 | K10: ='Consommation du 01.01 au 31.01'!D18 -> 300 | L10: 12.67 | M10: ='Consommation du 01.01 au 31.01'!AC18 -> 23 | N10: 23 | O10: =E10*F10+G10*H10+I10*J10+K10*L10 -> 22682.158
A11: Marrakech | B11: =B10+1 -> 10 | C11: 1 | D11: 2021 | E11: ='Consommation du 01.01 au 31.01'!M19 -> 10573 | F11: 0.99 | G11: ='Consommation du 01.01 au 31.01'!U19 -> 964.6 | H11: 8.2658 | I11: ='Consommation du 01.01 au 31.01'!Y19*1000 -> 11510 | J11: 0.53 | K11: ='Consommation du 01.01 au 31.01'!D19 -> 380 | L11: 12.67 | M11: ='Consommation du 01.01 au 31.01'!AC19 -> 18 | N11: 18 | O11: =E11*F11+G11*H11+I11*J11+K11*L11 -> 29355.361
A12: Marrakech | B12: =B11+1 -> 11 | C12: 1 | D12: 2021 | E12: ='Consommation du 01.01 au 31.01'!M20 -> 9968 | F12: 0.99 | G12: ='Consommation du 01.01 au 31.01'!U20 -> 630.7 | H12: 8.2658 | I12: ='Consommation du 01.01 au 31.01'!Y20*1000 -> 14670 | J12: 0.53 | K12: ='Consommation du 01.01 au 31.01'!D20 -> 300 | L12: 12.67 | M12: ='Consommation du 01.01 au 31.01'!AC20 -> 6 | N12: 6 | O12: =E12*F12+G12*H12+I12*J12+K12*L12 -> 26657.66
A13: Marrakech | B13: =B12+1 -> 12 | C13: 1 | D13: 2021 | E13: ='Consommation du 01.01 au 31.01'!M21 -> 10400 | F13: 0.99 | G13: ='Consommation du 01.01 au 31.01'!U21 -> 779.1 | H13: 8.2658 | I13: ='Consommation du 01.01 au 31.01'!Y21*1000 -> 10270 | J13: 0.53 | K13: ='Consommation du 01.01 au 31.01'!D21 -> 320 | L13: 12.67 | M13: ='Consommation du 01.01 au 31.01'!AC21 -> 6 | N13: 6 | O13: =E13*F13+G13*H13+I13*J13+K13*L13 -> 26233.385
A14: Marrakech | B14: =B13+1 -> 13 | C14: 1 | D14: 2021 | E14: ='Consommation du 01.01 au 31.01'!M22 -> 10088 | F14: 0.99 | G14: ='Consommation du 01.01 au 31.01'!U22 -> 371 | H14: 8.2658 | I14: ='Consommation du 01.01 au 31.01'!Y22*1000 -> 16500 | J14: 0.53 | K14: ='Consommation du 01.01 au 31.01'!D22 -> 390 | L14: 12.67 | M14: ='Consommation du 01.01 au 31.01'!AC22 -> 7 | N14: 7 | O14: =E14*F14+G14*H14+I14*J14+K14*L14 -> 26740.032
... A18: Marrakech | B18: =B17+1 -> 17 | C18: 1 | D18: 2021 | E18: ='Consommation du 01.01 au 31.01'!M26 -> 9502 | F18: 0.99 | G18: ='Consommation du 01.01 au 31.01'!U26 -> 445.2 | H18: 8.2658 | I18: ='Consommation du 01.01 au 31.01'!Y26*1000 -> 15760 | J18: 0.53 | K18: ='Consommation du 01.01 au 31.01'!D26 -> 360 | L18: 12.67 | M18: ='Consommation du 01.01 au 31.01'!AC26 -> 10 | N18: 10 | O18: =E18*F18+G18*H18+I18*J18+K18*L18 -> 26000.914
A19: Marrakech | B19: =B18+1 -> 18 | C19: 1 | D19: 2021 | E19: ='Consommation du 01.01 au 31.01'!M27 -> 0 | F19: 0.99 | G19: ='Consommation du 01.01 au 31.01'!U27 -> 0 | H19: 8.2658 | I19: ='Consommation du 01.01 au 31.01'!Y27*1000 -> 0 | J19: 0.53 | K19: ='Consommation du 01.01 au 31.01'!D27 -> 0 | L19: 12.67 | M19: ='Consommation du 01.01 au 31.01'!AC27 -> 0 | O19: =E19*F19+G19*H19+I19*J19+K19*L19 -> 0
A20: Marrakech | B20: =B19+1 -> 19 | C20: 1 | D20: 2021 | E20: ='Consommation du 01.01 au 31.01'!M28 -> 0 | F20: 0.99 | G20: ='Consommation du 01.01 au 31.01'!U28 -> 0 | H20: 8.2658 | I20: ='Consommation du 01.01 au 31.01'!Y28*1000 -> 0 | J20: 0.53 | K20: ='Consommation du 01.01 au 31.01'!D28 -> 0 | L20: 12.67 | M20: ='Consommation du 01.01 au 31.01'!AC28 -> 0 | O20: =E20*F20+G20*H20+I20*J20+K20*L20 -> 0
A21: Marrakech | B21: =B20+1 -> 20 | C21: 1 | D21: 2021 | E21: ='Consommation du 01.01 au 31.01'!M29 -> 0 | F21: 0.99 | G21: ='Consommation du 01.01 au 31.01'!U29 -> 0 | H21: 8.2658 | I21: ='Consommation du 01.01 au 31.01'!Y29*1000 -> 0 | J21: 0.53 | K21: ='Consommation du 01.01 au 31.01'!D29 -> 0 | L21: 12.67 | M21: ='Consommation du 01.01 au 31.01'!AC29 -> 0 | O21: =E21*F21+G21*H21+I21*J21+K21*L21 -> 0
A22: Marrakech | B22: =B21+1 -> 21 | C22: 1 | D22: 2021 | E22: ='Consommation du 01.01 au 31.01'!M30 -> 0 | F22: 0.99 | G22: ='Consommation du 01.01 au 31.01'!U30 -> 0 | H22: 8.2658 | I22: ='Consommation du 01.01 au 31.01'!Y30*1000 -> 0 | J22: 0.53 | K22: ='Consommation du 01.01 au 31.01'!D30 -> 0 | L22: 12.67 | M22: ='Consommation du 01.01 au 31.01'!AC30 -> 0 | O22: =E22*F22+G22*H22+I22*J22+K22*L22 -> 0
A23: Marrakech | B23: =B22+1 -> 22 | C23: 1 | D23: 2021 | E23: ='Consommation du 01.01 au 31.01'!M31 -> 0 | F23: 0.99 | G23: ='Consommation du 01.01 au 31.01'!U31 -> 0 | H23: 8.2658 | I23: ='Consommation du 01.01 au 31.01'!Y31*1000 -> 0 | J23: 0.53 | K23: ='Consommation du 01.01 au 31.01'!D31 -> 0 | L23: 12.67 | M23: ='Consommation du 01.01 au 31.01'!AC31 -> 0 | O23: =E23*F23+G23*H23+I23*J23+K23*L23 -> 0
A24: Marrakech | B24: =B23+1 -> 23 | C24: 1 | D24: 2021 | E24: ='Consommation du 01.01 au 31.01'!M32 -> 0 | F24: 0.99 | G24: ='Consommation du 01.01 au 31.01'!U32 -> 0 | H24: 8.2658 | I24: ='Consommation du 01.01 au 31.01'!Y32*1000 -> 0 | J24: 0.53 | K24: ='Consommation du 01.01 au 31.01'!D32 -> 0 | L24: 12.67 | M24: ='Consommation du 01.01 au 31.01'!AC32 -> 0 | O24: =E24*F24+G24*H24+I24*J24+K24*L24 -> 0
A25: Marrakech | B25: =B24+1 -> 24 | C25: 1 | D25: 2021 | E25: ='Consommation du 01.01 au 31.01'!M33 -> 0 | F25: 0.99 | G25: ='Consommation du 01.01 au 31.01'!U33 -> 0 | H25: 8.2658 | I25: ='Consommation du 01.01 au 31.01'!Y33*1000 -> 0 | J25: 0.53 | K25: ='Consommation du 01.01 au 31.01'!D33 -> 0 | L25: 12.67 | M25: ='Consommation du 01.01 au 31.01'!AC33 -> 0 | O25: =E25*F25+G25*H25+I25*J25+K25*L25 -> 0
A26: Marrakech | B26: =B25+1 -> 25 | C26: 1 | D26: 2021 | E26: ='Consommation du 01.01 au 31.01'!M34 -> 0 | F26: 0.99 | G26: ='Consommation du 01.01 au 31.01'!U34 -> 0 | H26: 8.2658 | I26: ='Consommation du 01.01 au 31.01'!Y34*1000 -> 0 | J26: 0.53 | K26: ='Consommation du 01.01 au 31.01'!D34 -> 0 | L26: 12.67 | M26: ='Consommation du 01.01 au 31.01'!AC34 -> 0 | O26: =E26*F26+G26*H26+I26*J26+K26*L26 -> 0
A27: Marrakech | B27: =B26+1 -> 26 | C27: 1 | D27: 2021 | E27: ='Consommation du 01.01 au 31.01'!M35 -> 0 | F27: 0.99 | G27: ='Consommation du 01.01 au 31.01'!U35 -> 0 | H27: 8.2658 | I27: ='Consommation du 01.01 au 31.01'!Y35*1000 -> 0 | J27: 0.53 | K27: ='Consommation du 01.01 au 31.01'!D35 -> 0 | L27: 12.67 | M27: ='Consommation du 01.01 au 31.01'!AC35 -> 0 | O27: =E27*F27+G27*H27+I27*J27+K27*L27 -> 0
A28: Marrakech | B28: =B27+1 -> 27 | C28: 1 | D28: 2021 | E28: ='Consommation du 01.01 au 31.01'!M36 -> 0 | F28: 0.99 | G28: ='Consommation du 01.01 au 31.01'!U36 -> 0 | H28: 8.2658 | I28: ='Consommation du 01.01 au 31.01'!Y36*1000 -> 0 | J28: 0.53 | K28: ='Consommation du 01.01 au 31.01'!D36 -> 0 | L28: 12.67 | M28: ='Consommation du 01.01 au 31.01'!AC36 -> 0 | O28: =E28*F28+G28*H28+I28*J28+K28*L28 -> 0
A29: Marrakech | B29: =B28+1 -> 28 | C29: 1 | D29: 2021 | E29: ='Consommation du 01.01 au 31.01'!M37 -> 0 | F29: 0.99 | G29: ='Consommation du 01.01 au 31.01'!U37 -> 0 | H29: 8.2658 | I29: ='Consommation du 01.01 au 31.01'!Y37*1000 -> 0 | J29: 0.53 | K29: ='Consommation du 01.01 au 31.01'!D37 -> 0 | L29: 12.67 | M29: ='Consommation du 01.01 au 31.01'!AC37 -> 0 | O29: =E29*F29+G29*H29+I29*J29+K29*L29 -> 0
A30: Marrakech | B30: =B29+1 -> 29 | C30: 1 | D30: 2021 | E30: ='Consommation du 01.01 au 31.01'!M38 -> 0 | F30: 0.99 | G30: ='Consommation du 01.01 au 31.01'!U38 -> 0 | H30: 8.2658 | I30: ='Consommation du 01.01 au 31.01'!Y38*1000 -> 0 | J30: 0.53 | K30: ='Consommation du 01.01 au 31.01'!D38 -> 0 | L30: 12.67 | M30: ='Consommation du 01.01 au 31.01'!AC38 -> 0 | O30: =E30*F30+G30*H30+I30*J30+K30*L30 -> 0
... A32: Marrakech | B32: =B31+1 -> 31 | C32: 1 | D32: 2021 | E32: ='Consommation du 01.01 au 31.01'!M40 -> 0 | F32: 1.99 | G32: ='Consommation du 01.01 au 31.01'!U40 -> 0 | H32: 8.2658 | I32: ='Consommation du 01.01 au 31.01'!Y40*1000 -> 0 | J32: 1.53 | K32: ='Consommation du 01.01 au 31.01'!D40 -> 0 | L32: 13.67 | M32: ='Consommation du 01.01 au 31.01'!AC40 -> 0 | O32: =E32*F32+G32*H32+I32*J32+K32*L32 -> 0
O33: =SUM(O2:O32) -> 445043.23

Sheet Consommation du 01.01 au 31.01
B8: Date | D8: Cons Eau/Hotel | F8: Consommation du jour en DH | M8: total | O8: Consommation du jour en DH | Q8: Cons Elec/Villa | S8: Cons Elec/RIAD | U8: GAZ en Kg | W8: Consommation du jour en DH | X8: Compteur AVEO Mwh | Y8: consommation eau choud en Mwh | Z8: consommation du jour en DH | AB8: Température moyenne du jour °C | AC8: Total Occupation | AD8: % Occupation | AE8: Température Piscine Adulte à 7h00 °C | AF8: Température Piscine Adulte à 15h00 °C | AG8: Température Piscine famille à 07h00 ° C | AH8: Température Piscine famille à 15h00 ° C
J9: creuse 81 | K9: pleine 82 | L9: pointe 83 | AJ9: Consommation totale du jour | AK9: Consommation/Chambre
B10: 44197 | D10: ='Suivi EAU-ELEC'!C16 -> 390 | F10: =D10*12.67 -> 4941.3 | J10: ='Suivi EAU-ELEC'!E16 -> 3405 | K10: ='Suivi EAU-ELEC'!G16 -> 5810 | L10: ='Suivi EAU-ELEC'!I16 -> 2460 | M10: =L10+K10+J10 -> 11675 | O10: =J10*0.99+K10*0.99+L10*0.99 -> 11558.25 | U10: ='Suivi Gaz'!O11 -> 1780.8 | W10: =U10*8.2658 -> 14719.737 | X10: 18277.08 | Y10: =IF(X11<X10,0,X11-X10) -> 13.17 | Z10: =Y10*0.53*1000 -> 6980.1 | AB10: 14 | AC10: 57 | AD10: 0.5 | AE10: 27.5 | AF10: 28 | AG10: 27.5 | AH10: 28 | AJ10: =(F10+O10+W10+Z10) -> 38199.387 | AK10: =AJ10/AC10 -> 670.16468
B11: =(B10+1) -> 44198 | D11: ='Suivi EAU-ELEC'!C17 -> 330 | F11: =D11*12.67 -> 4181.1 | J11: ='Suivi EAU-ELEC'!E17 -> 3413 | K11: ='Suivi EAU-ELEC'!G17 -> 5222 | L11: ='Suivi EAU-ELEC'!I17 -> 2408 | M11: =L11+K11+J11 -> 11043 | O11: =J11*0.99+K11*0.99+L11*0.99 -> 10932.57 | U11: ='Suivi Gaz'!O12 -> 593.6 | W11: =U11*8.2658 -> 4906.5789 | X11: 18290.25 | Y11: =IF(X12<X11,0,X12-X11) -> 13.42 | Z11: =Y11*0.53*1000 -> 7112.6 | AB11: 14 | AC11: 53 | AD11: 0.3985 | AE11: 27.5 | AF11: 28 | AG11: 27 | AH11: 27.5 | AJ11: =(F11+O11+W11+Z11) -> 27132.849 | AK11: =AJ11/AC11 -> 511.94054
B12: =(B11+1) -> 44199 | D12: ='Suivi EAU-ELEC'!C18 -> 280 | F12: =D12*12.67 -> 3547.6 | J12: ='Suivi EAU-ELEC'!E18 -> 3457 | K12: ='Suivi EAU-ELEC'!G18 -> 5248 | L12: ='Suivi EAU-ELEC'!I18 -> 2305 | M12: =L12+K12+J12 -> 11010 | O12: =J12*0.99+K12*0.99+L12*0.99 -> 10899.9 | U12: ='Suivi Gaz'!O13 -> 371 | W12: =U12*8.2658 -> 3066.6118 | X12: 18303.67 | Y12: =IF(X13<X12,0,X13-X12) -> 13.87 | Z12: =Y12*0.53*1000 -> 7351.1 | AB12: 12 | AC12: 18 | AD12: 0.1385 | AE12: 25 | AF12: 26 | AG12: 22 | AH12: 24 | AJ12: =(F12+O12+W12+Z12) -> 24865.212 | AK12: =AJ12/AC12 -> 1381.4007
B13: =(B12+1) -> 44200 | D13: ='Suivi EAU-ELEC'!C19 -> 230 | F13: =D13*12.67 -> 2914.1 | J13: ='Suivi EAU-ELEC'!E19 -> 3741 | K13: ='Suivi EAU-ELEC'!G19 -> 5189 | L13: ='Suivi EAU-ELEC'!I19 -> 2172 | M13: =L13+K13+J13 -> 11102 | O13: =J13*0.99+K13*0.99+L13*0.99 -> 10990.98 | U13: ='Suivi Gaz'!O14 -> 259.7 | W13: =U13*8.2658 -> 2146.6283 | X13: 18317.54 | Y13: =IF(X14<X13,0,X14-X13) -> 13.77 | Z13: =Y13*0.53*1000 -> 7298.1 | AB13: 16 | AC13: 14 | AD13: 0.1094 | AE13: 21.5 | AF13: 22 | AG13: 19 | AH13: 19 | AJ13: =(F13+O13+W13+Z13) -> 23349.808 | AK13: =AJ13/AC13 -> 1667.8434
B14: =(B13+1) -> 44201 | D14: ='Suivi EAU-ELEC'!C20 -> 250 | F14: =D14*12.67 -> 3167.5 | J14: ='Suivi EAU-ELEC'!E20 -> 3319 | K14: ='Suivi EAU-ELEC'!G20 -> 5047 | L14: ='Suivi EAU-ELEC'!I20 -> 2125 | M14: =L14+K14+J14 -> 10491 | O14: =J14*0.99+K14*0.99+L14*0.99 -> 10386.09 | U14: ='Suivi Gaz'!O15 -> 890.4 | W14: =U14*8.2658 -> 7359.8683 | X14: 18331.31 | Y14: =IF(X15<X14,0,X15-X14) -> 9.13 | Z14: =Y14*0.53*1000 -> 4838.9 | AB14: 18 | AC14: 11 | AD14: 0.0859 | AE14: 22 | AF14: 25 | AG14: 18 | AH14: 18 | AJ14: =(F14+O14+W14+Z14) -> 25752.358 | AK14: =AJ14/AC14 -> 2341.1235
B15: =(B14+1) -> 44202 | D15: ='Suivi EAU-ELEC'!C21 -> 270 | F15: =D15*12.67 -> 3420.9 | J15: ='Suivi EAU-ELEC'!E21 -> 3396 | K15: ='Suivi EAU-ELEC'!G21 -> 5062 | L15: ='Suivi EAU-ELEC'!I21 -> 2105 | M15: =L15+K15+J15 -> 10563 | O15: =J15*0.99+K15*0.99+L15*0.99 -> 10457.37 | U15: ='Suivi Gaz'!O16 -> 704.9 | W15: =U15*8.2658 -> 5826.5624 | X15: 18340.44 | Y15: =IF(X16<X15,0,X16-X15) -> 4.18 | Z15: =Y15*0.53*1000 -> 2215.4 | AB15: 19 | AC15: 10 | AD15: 0.0769 | AE15: ar | AF15: ar | AG15: ar | AH15: ar | AJ15: =(F15+O15+W15+Z15) -> 21920.232 | AK15: =AJ15/AC15 -> 2192.0232
B16: =(B15+1) -> 44203 | D16: ='Suivi EAU-ELEC'!C22 -> 230 | F16: =D16*12.67 -> 2914.1 | J16: ='Suivi EAU-ELEC'!E22 -> 3030 | K16: ='Suivi EAU-ELEC'!G22 -> 4884 | L16: ='Suivi EAU-ELEC'!I22 -> 1953 | M16: =L16+K16+J16 -> 9867 | O16: =J16*0.99+K16*0.99+L16*0.99 -> 9768.33 | U16: ='Suivi Gaz'!O17 -> 296.8 | W16: =U16*8.2658 -> 2453.2894 | X16: 18344.62 | Y16: =IF(X17<X16,0,X17-X16) -> 12.52 | Z16: =Y16*0.53*1000 -> 6635.6 | AB16: 19 | AC16: 6 | AD16: 0.0455 | AE16: ar | AF16: ar | AG16: ar | AH16: ar | AJ16: =(F16+O16+W16+Z16) -> 21771.319 | AK16: =AJ16/AC16 -> 3628.5532
B17: =(B16+1) -> 44204 | D17: ='Suivi EAU-ELEC'!C23 -> 300 | F17: =D17*12.67 -> 3801 | J17: ='Suivi EAU-ELEC'!E23 -> 2795 | K17: ='Suivi EAU-ELEC'!G23 -> 4464 | L17: ='Suivi EAU-ELEC'!I23 -> 1941 | M17: =L17+K17+J17 -> 9200 | O17: =J17*0.99+K17*0.99+L17*0.99 -> 9108 | U17: ='Suivi Gaz'!O18 -> 148.4 | W17: =U17*8.2658 -> 1226.6447 | X17: 18357.14 | Y17: =IF(X18<X17,0,X18-X17) -> 11.04 | Z17: =Y17*0.53*1000 -> 5851.2 | AB17: 18 | AC17: 8 | AD17: 0.0593 | AE17: 26.5 | AF17: 27 | AG17: ar | AH17: ar | AJ17: =(F17+O17+W17+Z17) -> 19986.845 | AK17: =AJ17/AC17 -> 2498.3556
B18: =(B17+1) -> 44205 | D18: ='Suivi EAU-ELEC'!C24 -> 300 | F18: =D18*12.67 -> 3801 | J18: ='Suivi EAU-ELEC'!E24 -> 3263 | K18: ='Suivi EAU-ELEC'!G24 -> 4832 | L18: ='Suivi EAU-ELEC'!I24 -> 2122 | M18: =L18+K18+J18 -> 10217 | O18: =J18*0.99+K18*0.99+L18*0.99 -> 10114.83 | U18: ='Suivi Gaz'!O19 -> 259.7 | W18: =U18*8.2658 -> 2146.6283 | X18: 18368.18 | Y18: =IF(X19<X18,0,X19-X18) -> 12.49 | Z18: =Y18*0.53*1000 -> 6619.7 | AB18: 12 | AC18: 23 | AD18: 0.1729 | AE18: 26 | AF18: 26.6 | AG18: ar | AH18: ar | AJ18: =(F18+O18+W18+Z18) -> 22682.158 | AK18: =AJ18/AC18 -> 986.18079
B19: =(B18+1) -> 44206 | D19: ='Suivi EAU-ELEC'!C25 -> 380 | F19: =D19*12.67 -> 4814.6 | J19: ='Suivi EAU-ELEC'!E25 -> 3259 | K19: ='Suivi EAU-ELEC'!G25 -> 5154 | L19: ='Suivi EAU-ELEC'!I25 -> 2160 | M19: =L19+K19+J19 -> 10573 | O19: =J19*0.99+K19*0.99+L19*0.99 -> 10467.27 | U19: ='Suivi Gaz'!O20 -> 964.6 | W19: =U19*8.2658 -> 7973.1907 | X19: 18380.67 | Y19: =IF(X20<X19,0,X20-X19) -> 11.51 | Z19: =Y19*0.53*1000 -> 6100.3 | AB19: 9 | AC19: 18 | AD19: 0.1343 | AE19: 26 | AF19: 26.5 | AG19: ar | AH19: ar | AJ19: =(F19+O19+W19+Z19) -> 29355.361 | AK19: =AJ19/AC19 -> 1630.8534
B20: =(B19+1) -> 44207 | D20: ='Suivi EAU-ELEC'!C26 -> 300 | F20: =D20*12.67 -> 3801 | J20: ='Suivi EAU-ELEC'!E26 -> 2966 | K20: ='Suivi EAU-ELEC'!G26 -> 5012 | L20: ='Suivi EAU-ELEC'!I26 -> 1990 | M20: =L20+K20+J20 -> 9968 | O20: =J20*0.99+K20*0.99+L20*0.99 -> 9868.32 | U20: ='Suivi Gaz'!O21 -> 630.7 | W20: =U20*8.2658 -> 5213.2401 | X20: 18392.18 | Y20: =IF(X21<X20,0,X21-X20) -> 14.67 | Z20: =Y20*0.53*1000 -> 7775.1 | AA20: 14 | AB20: 11 | AC20: 6 | AD20: 0.0451 | AE20: 26.5 | AF20: 27.5 | AG20: ar | AH20: ar | AJ20: =(F20+O20+W20+Z20) -> 26657.66 | AK20: =AJ20/AC20 -> 4442.9433
B21: =(B20+1) -> 44208 | D21: ='Suivi EAU-ELEC'!C27 -> 320 | F21: =D21*12.67 -> 4054.4 | J21: ='Suivi EAU-ELEC'!E27 -> 3179 | K21: ='Suivi EAU-ELEC'!G27 -> 5091 | L21: ='Suivi EAU-ELEC'!I27 -> 2130 | M21: =L21+K21+J21 -> 10400 | O21: =J21*0.99+K21*0.99+L21*0.99 -> 10296 | U21: ='Suivi Gaz'!O22 -> 779.1 | W21: =U21*8.2658 -> 6439.8848 | X21: 18406.85 | Y21: =IF(X22<X21,0,X22-X21) -> 10.27 | Z21: =Y21*0.53*1000 -> 5443.1 | AA21: 14 | AB21: 13 | AC21: 6 | AD21: 0.0438 | AE21: 26 | AF21: 27 | AG21: ar | AH21: ar | AJ21: =(F21+O21+W21+Z21) -> 26233.385 | AK21: =AJ21/AC21 -> 4372.2308
B22: =(B21+1) -> 44209 | D22: ='Suivi EAU-ELEC'!C28 -> 390 | F22: =D22*12.67 -> 4941.3 | J22: ='Suivi EAU-ELEC'!E28 -> 3111 | K22: ='Suivi EAU-ELEC'!G28 -> 4849 | L22: ='Suivi EAU-ELEC'!I28 -> 2128 | M22: =L22+K22+J22 -> 10088 | O22: =J22*0.99+K22*0.99+L22*0.99 -> 9987.12 | U22: ='Suivi Gaz'!O23 -> 371 | W22: =U22*8.2658 -> 3066.6118 | X22: 18417.12 | Y22: =IF(X23<X22,0,X23-X22) -> 16.5 | Z22: =Y22*0.53*1000 -> 8745 | AB22: 14 | AC22: 7 | AD22: 0.0511 | AE22: 26 | AF22: 27 | AG22: 16 | AH22: 20 | AJ22: =(F22+O22+W22+Z22) -> 26740.032 | AK22: =AJ22/AC22 -> 3820.0045
B23: =(B22+1) -> 44210 | D23: ='Suivi EAU-ELEC'!C29 -> 480 | F23: =D23*12.67 -> 6081.6 | J23: ='Suivi EAU-ELEC'!E29 -> 3056 | K23: ='Suivi EAU-ELEC'!G29 -> 4731 | L23: ='Suivi EAU-ELEC'!I29 -> 1976 | M23: =L23+K23+J23 -> 9763 | O23: =J23*0.99+K23*0.99+L23*0.99 -> 9665.37 | U23: ='Suivi Gaz'!O24 -> 333.9 | W23: =U23*8.2658 -> 2759.9506 | X23: 18433.62 | Y23: =IF(X24<X23,0,X24-X23) -> 15.94 | Z23: =Y23*0.53*1000 -> 8448.2 | AB23: 13 | AC23: 8 | AD23: 0.0588 | AE23: 26 | AF23: 27 | AG23: 16 | AH23: 20 | AJ23: =(F23+O23+W23+Z23) -> 26955.121 | AK23: =AJ23/AC23 -> 3369.3901
B24: =(B23+1) -> 44211 | D24: ='Suivi EAU-ELEC'!C30 -> 270 | F24: =D24*12.67 -> 3420.9 | J24: ='Suivi EAU-ELEC'!E30 -> 3006 | K24: ='Suivi EAU-ELEC'!G30 -> 4862 | L24: ='Suivi EAU-ELEC'!I30 -> 2124 | M24: =L24+K24+J24 -> 9992 | O24: =J24*0.99+K24*0.99+L24*0.99 -> 9892.08 | U24: ='Suivi Gaz'!O25 -> 927.5 | W24: =U24*8.2658 -> 7666.5295 | X24: 18449.56 | Y24: =IF(X25<X24,0,X25-X24) -> 15.16 | Z24: =Y24*0.53*1000 -> 8034.8 | AB24: 14 | AC24: 12 | AD24: 0.0882 | AE24: 26 | AF24: 27 | AG24: 16 | AH24: 20 | AJ24: =(F24+O24+W24+Z24) -> 29014.309 | AK24: =AJ24/AC24 -> 2417.8591
B25: =(B24+1) -> 44212 | D25: ='Suivi EAU-ELEC'!C31 -> 600 | F25: =D25*12.67 -> 7602 | J25: ='Suivi EAU-ELEC'!E31 -> 3014 | K25: ='Suivi EAU-ELEC'!G31 -> 4591 | L25: ='Suivi EAU-ELEC'!I31 -> 2018 | M25: =L25+K25+J25 -> 9623 | O25: =J25*0.99+K25*0.99+L25*0.99 -> 9526.77 | U25: ='Suivi Gaz'!O26 -> 371 | W25: =U25*8.2658 -> 3066.6118 | X25: 18464.72 | Y25: =IF(X26<X25,0,X26-X25) -> 15.53 | Z25: =Y25*0.53*1000 -> 8230.9 | AB25: 12 | AC25: 12 | AD25: 0.0882 | AE25: 26 | AF25: 27 | AG25: 18 | AH25: 20 | AJ25: =(F25+O25+W25+Z25) -> 28426.282 | AK25: =AJ25/AC25 -> 2368.8568
B26: =(B25+1) -> 44213 | D26: ='Suivi EAU-ELEC'!C32 -> 360 | F26: =D26*12.67 -> 4561.2 | J26: ='Suivi EAU-ELEC'!E32 -> 3013 | K26: ='Suivi EAU-ELEC'!G32 -> 4512 | L26: ='Suivi EAU-ELEC'!I32 -> 1977 | M26: =L26+K26+J26 -> 9502 | O26: =J26*0.99+K26*0.99+L26*0.99 -> 9406.98 | U26: ='Suivi Gaz'!O27 -> 445.2 | W26: =U26*8.2658 -> 3679.9342 | X26: 18480.25 | Y26: =IF(X27<X26,0,X27-X26) -> 15.76 | Z26: =Y26*0.53*1000 -> 8352.8 | AB26: 12 | AC26: 10 | AD26: 0.073 | AE26: 25.5 | AF26: 26.5 | AG26: 16 | AH26: 20 | AJ26: =(F26+O26+W26+Z26) -> 26000.914 | AK26: =AJ26/AC26 -> 2600.0914
B27: =(B26+1) -> 44214 | D27: ='Suivi EAU-ELEC'!C33 -> 0 | F27: =D27*12.67 -> 0 | J27: ='Suivi EAU-ELEC'!E33 -> 0 | K27: ='Suivi EAU-ELEC'!G33 -> 0 | L27: ='Suivi EAU-ELEC'!I33 -> 0 | M27: =L27+K27+J27 -> 0 | O27: =J27*0.99+K27*0.99+L27*0.99 -> 0 | U27: ='Suivi Gaz'!O28 -> 0 | W27: =U27*8.2658 -> 0 | X27: 18496.01 | Y27: =IF(X28<X27,0,X28-X27) -> 0 | Z27: =Y27*0.53*1000 -> 0 | AJ27: =(F27+O27+W27+Z27) -> 0 | AK27: =AJ27/AC27 -> #DIV/0!
B28: =(B27+1) -> 44215 | D28: ='Suivi EAU-ELEC'!C34 -> 0 | F28: =D28*12.67 -> 0 | J28: ='Suivi EAU-ELEC'!E34 -> 0 | K28: ='Suivi EAU-ELEC'!G34 -> 0 | L28: ='Suivi EAU-ELEC'!I34 -> 0 | M28: =L28+K28+J28 -> 0 | O28: =J28*0.99+K28*0.99+L28*0.99 -> 0 | U28: ='Suivi Gaz'!O29 -> 0 | W28: =U28*8.2658 -> 0 | Y28: =IF(X29<X28,0,X29-X28) -> 0 | Z28: =Y28*0.53*1000 -> 0 | AJ28: =(F28+O28+W28+Z28) -> 0 | AK28: =AJ28/AC28 -> #DIV/0!
B29: =(B28+1) -> 44216 | D29: ='Suivi EAU-ELEC'!C35 -> 0 | F29: =D29*12.67 -> 0 | J29: ='Suivi EAU-ELEC'!E35 -> 0 | K29: ='Suivi EAU-ELEC'!G35 -> 0 | L29: ='Suivi EAU-ELEC'!I35 -> 0 | M29: =L29+K29+J29 -> 0 | O29: =J29*0.99+K29*0.99+L29*0.99 -> 0 | U29: ='Suivi Gaz'!O30 -> 0 | W29: =U29*8.2658 -> 0 | Y29: =IF(X30<X29,0,X30-X29) -> 0 | Z29: =Y29*0.53*1000 -> 0 | AJ29: =(F29+O29+W29+Z29) -> 0 | AK29: =AJ29/AC29 -> #DIV/0!
B30: =(B29+1) -> 44217 | D30: ='Suivi EAU-ELEC'!C36 -> 0 | F30: =D30*12.67 -> 0 | J30: ='Suivi EAU-ELEC'!E36 -> 0 | K30: ='Suivi EAU-ELEC'!G36 -> 0 | L30: ='Suivi EAU-ELEC'!I36 -> 0 | M30: =L30+K30+J30 -> 0 | O30: =J30*0.99+K30*0.99+L30*0.99 -> 0 | U30: ='Suivi Gaz'!O31 -> 0 | W30: =U30*8.2658 -> 0 | Y30: =IF(X31<X30,0,X31-X30) -> 0 | Z30: =Y30*0.53*1000 -> 0 | AJ30: =(F30+O30+W30+Z30) -> 0 | AK30: =AJ30/AC30 -> #DIV/0!
B31: =(B30+1) -> 44218 | D31: ='Suivi EAU-ELEC'!C37 -> 0 | F31: =D31*12.67 -> 0 | J31: ='Suivi EAU-ELEC'!E37 -> 0 | K31: ='Suivi EAU-ELEC'!G37 -> 0 | L31: ='Suivi EAU-ELEC'!I37 -> 0 | M31: =L31+K31+J31 -> 0 | O31: =J31*0.99+K31*0.99+L31*0.99 -> 0 | U31: ='Suivi Gaz'!O32 -> 0 | W31: =U31*8.2658 -> 0 | Y31: =IF(X32<X31,0,X32-X31) -> 0 | Z31: =Y31*0.53*1000 -> 0 | AJ31: =(F31+O31+W31+Z31) -> 0 | AK31: =AJ31/AC31 -> #DIV/0!
B32: =(B31+1) -> 44219 | D32: ='Suivi EAU-ELEC'!C38 -> 0 | F32: =D32*12.67 -> 0 | J32: ='Suivi EAU-ELEC'!E38 -> 0 | K32: ='Suivi EAU-ELEC'!G38 -> 0 | L32: ='Suivi EAU-ELEC'!I38 -> 0 | M32: =L32+K32+J32 -> 0 | O32: =J32*0.99+K32*0.99+L32*0.99 -> 0 | U32: ='Suivi Gaz'!O33 -> 0 | W32: =U32*8.2658 -> 0 | Y32: =IF(X33<X32,0,X33-X32) -> 0 | Z32: =Y32*0.53*1000 -> 0 | AJ32: =(F32+O32+W32+Z32) -> 0 | AK32: =AJ32/AC32 -> #DIV/0!
B33: =(B32+1) -> 44220 | D33: ='Suivi EAU-ELEC'!C39 -> 0 | F33: =D33*12.67 -> 0 | J33: ='Suivi EAU-ELEC'!E39 -> 0 | K33: ='Suivi EAU-ELEC'!G39 -> 0 | L33: ='Suivi EAU-ELEC'!I39 -> 0 | M33: =L33+K33+J33 -> 0 | O33: =J33*0.99+K33*0.99+L33*0.99 -> 0 | U33: ='Suivi Gaz'!O34 -> 0 | W33: =U33*8.2658 -> 0 | Y33: =IF(X34<X33,0,X34-X33) -> 0 | Z33: =Y33*0.53*1000 -> 0 | AJ33: =(F33+O33+W33+Z33) -> 0 | AK33: =AJ33/AC33 -> #DIV/0!
B34: =(B33+1) -> 44221 | D34: ='Suivi EAU-ELEC'!C40 -> 0 | F34: =D34*12.67 -> 0 | J34: ='Suivi EAU-ELEC'!E40 -> 0 | K34: ='Suivi EAU-ELEC'!G40 -> 0 | L34: ='Suivi EAU-ELEC'!I40 -> 0 | M34: =L34+K34+J34 -> 0 | O34: =J34*0.99+K34*0.99+L34*0.99 -> 0 | U34: ='Suivi Gaz'!O35 -> 0 | W34: =U34*8.2658 -> 0 | Y34: =IF(X35<X34,0,X35-X34) -> 0 | Z34: =Y34*0.53*1000 -> 0 | AJ34: =(F34+O34+W34+Z34) -> 0 | AK34: =AJ34/AC34 -> #DIV/0!
B35: =(B34+1) -> 44222 | D35: ='Suivi EAU-ELEC'!C41 -> 0 | F35: =D35*12.67 -> 0 | J35: ='Suivi EAU-ELEC'!E41 -> 0 | K35: ='Suivi EAU-ELEC'!G41 -> 0 | L35: ='Suivi EAU-ELEC'!I41 -> 0 | M35: =L35+K35+J35 -> 0 | O35: =J35*0.99+K35*0.99+L35*0.99 -> 0 | U35: ='Suivi Gaz'!O36 -> 0 | W35: =U35*8.2658 -> 0 | Y35: =IF(X36<X35,0,X36-X35) -> 0 | Z35: =Y35*0.53*1000 -> 0 | AJ35: =(F35+O35+W35+Z35) -> 0 | AK35: =AJ35/AC35 -> #DIV/0!
B36: =(B35+1) -> 44223 | D36: ='Suivi EAU-ELEC'!C42 -> 0 | F36: =D36*12.67 -> 0 | J36: ='Suivi EAU-ELEC'!E42 -> 0 | K36: ='Suivi EAU-ELEC'!G42 -> 0 | L36: ='Suivi EAU-ELEC'!I42 -> 0 | M36: =L36+K36+J36 -> 0 | O36: =J36*0.99+K36*0.99+L36*0.99 -> 0 | U36: ='Suivi Gaz'!O37 -> 0 | W36: =U36*8.2658 -> 0 | Y36: =IF(X37<X36,0,X37-X36) -> 0 | Z36: =Y36*0.53*1000 -> 0 | AJ36: =(F36+O36+W36+Z36) -> 0 | AK36: =AJ36/AC36 -> #DIV/0!
B37: =(B36+1) -> 44224 | D37: ='Suivi EAU-ELEC'!C43 -> 0 | F37: =D37*12.67 -> 0 | J37: ='Suivi EAU-ELEC'!E43 -> 0 | K37: ='Suivi EAU-ELEC'!G43 -> 0 | L37: ='Suivi EAU-ELEC'!I43 -> 0 | M37: =L37+K37+J37 -> 0 | O37: =J37*0.99+K37*0.99+L37*0.99 -> 0 | U37: ='Suivi Gaz'!O38 -> 0 | W37: =U37*8.2658 -> 0 | Y37: =IF(X38<X37,0,X38-X37) -> 0 | Z37: =Y37*0.53*1000 -> 0 | AJ37: =(F37+O37+W37+Z37) -> 0 | AK37: =AJ37/AC37 -> #DIV/0!
B38: =(B37+1) -> 44225 | D38: ='Suivi EAU-ELEC'!C44 -> 0 | F38: =D38*12.67 -> 0 | J38: ='Suivi EAU-ELEC'!E44 -> 0 | K38: ='Suivi EAU-ELEC'!G44 -> 0 | L38: ='Suivi EAU-ELEC'!I44 -> 0 | M38: =L38+K38+J38 -> 0 | O38: =J38*0.99+K38*0.99+L38*0.99 -> 0 | U38: ='Suivi Gaz'!O39 -> 0 | W38: =U38*8.2658 -> 0 | Y38: =IF(X39<X38,0,X39-X38) -> 0 | Z38: =Y38*0.53*1000 -> 0 | AJ38: =(F38+O38+W38+Z38) -> 0 | AK38: =AJ38/AC38 -> #DIV/0!
B39: =(B38+1) -> 44226 | D39: ='Suivi EAU-ELEC'!C45 -> 0 | F39: =D39*12.67 -> 0 | J39: ='Suivi EAU-ELEC'!E45 -> 0 | K39: ='Suivi EAU-ELEC'!G45 -> 0 | L39: ='Suivi EAU-ELEC'!I45 -> 0 | M39: =L39+K39+J39 -> 0 | O39: =J39*0.99+K39*0.99+L39*0.99 -> 0 | U39: ='Suivi Gaz'!O40 -> 0 | W39: =U39*8.2658 -> 0 | Y39: =IF(X40<X39,0,X40-X39) -> 0 | Z39: =Y39*0.53*1000 -> 0 | AJ39: =(F39+O39+W39+Z39) -> 0 | AK39: =AJ39/AC39 -> #DIV/0!
B40: =(B39+1) -> 44227 | D40: ='Suivi EAU-ELEC'!C46 -> 0 | F40: =D40*12.67 -> 0 | J40: ='Suivi EAU-ELEC'!E46 -> 0 | K40: ='Suivi EAU-ELEC'!G46 -> 0 | L40: ='Suivi EAU-ELEC'!I46 -> 0 | M40: =L40+K40+J40 -> 0 | O40: =J40*0.99+K40*0.99+L40*0.99 -> 0 | U40: ='Suivi Gaz'!O41 -> 0 | W40: =U40*8.2658 -> 0 | Y40: =IF(X41<X40,0,X41-X40) -> 0 | Z40: =Y40*0.53*1000 -> 0 | AJ40: =(F40+O40+W40+Z40) -> 0 | AK40: =AJ40/AC40 -> #DIV/0!
D41: =SUM(D10:D40) -> 5680 | F41: =SUM(F10:H40) -> 71965.6 | J41: =SUM(J10:J40) -> 54423 | K41: =SUM(K10:K40) -> 84560 | L41: =SUM(L10:L40) -> 36094 | M41: =SUM(M10:M40) -> 175077 | O41: =SUM(O10:O40) -> 173326.23 | Q41: =SUM(Q10:Q40) -> 0 | S41: =SUM(S10:S40) -> 0 | U41: =SUM(U10:U40) -> 10128.3 | W41: =SUM(W10:W40) -> 83718.502 | Y41: =SUM(Y10:Y40) -> 218.93 | Z41: =SUM(Z10:Z40) -> 116032.9 | AJ41: =SUM(AJ10:AJ38) -> 445043.23 | AK41: =SUM(AK10:AK38) -> #DIV/0!
A43: ELECTRICITE / Kw/h | D43: creuse 81 | F43: 0.64895 | G43: =J41 -> 54423 | J43: =G43*F43 -> 35317.806 | L43: =J43+J44+J45 -> 155065.17
D44: pleine 82 | F44: 0.88605 | G44: =K41 -> 84560 | J44: =G44*F44 -> 74924.388
D45: pointe 83 | F45: 1.24184 | G45: =L41 -> 36094 | J45: =G45*F45 -> 44822.973
A46: EAU HOTEL M3 | F46: 12.67 | G46: =D41 -> 5680 | J46: =G46*F46 -> 71965.6 | L46: =J46 -> 71965.6
A47: GAZ Kg | F47: 8.2658 | G47: =U41 -> 10128.3 | J47: =G47*F47 -> 83718.502 | L47: =J47 -> 83718.502

Sheet Suivi Gaz
D1: suivi Gaz
Q2: 803 | T2: 519 | W2: 800 | Z2: 802
B3: Relvé C1 | C3: cons C1 | D3: Relvé C2 | E3: cons C2 | F3: Relvé C3 | G3: cons C3 | H3: Relvé C4 | I3: cons C4 | J3: ∑ des relevés | K3: moyen general % | L3: con.j | M3: ∑ de volume en L | N3: cons./jen L | O3: cons./jen Kg | P3: cons./jen DH | Q3: livraison C1 | R3: %Avant | S3: % Après | T3: livraison C2 | U3: %Avant | V3: % Après | W3: livraison C3 | X3: %Avant | Y3: % Après | Z3: livraison C4 | AA3: %Avant | AB3: % Après | AC3: total livraison | AD3: moyen general % Avant L | AE3: moyen general % Aaprés L
A4: 44190 | B4: 53 | C4: =IF(AC4>0,((B4-R4)+(S4-B5)),IF(B5=0, ,(B4-B5))) -> 3 | D4: 50 | E4: =IF(AC4>0,((D4-U4)+(V4-D5)),IF(D5=0, ,(D4-D5))) -> 2 | F4: 44 | G4: =IF(AC4>0,((F4-X4)+(Y4-F5)),IF(F5=0, ,(F4-F5))) -> 0 | H4: 45 | I4: =IF(AC4>0,((H4-AA4)+(AB4-H5)),IF(H5=0, ,(H4-H5))) -> 8 | J4: =B4+D4+F4+H4 -> 192 | K4: =J4/4 -> 48 | L4: =IF(AC4>0,((K4-AD4)+(AE4-K5)),IF(K5=0, ,(K4-K5))) -> 3.25 | M4: =7000*4 -> 28000 | N4: =L4*M4/100 -> 910 | O4: =N4*0.53 -> 482.3 | P4: =O4*8.1757 -> 3943.1401 | Q4: 2780 | R4: 50 | S4: 85 | T4: 3083 | U4: 48 | V4: 85 | W4: 3061 | X4: 45 | Y4: 85 | Z4: 3308 | AA4: 40 | AB4: 85 | AC4: =Q4+T4+W4+Z4 -> 12232 | AD4: =(R4+U4+X4+AA4)/4 -> 45.75 | AE4: =(S4+V4+Y4+AB4)/4 -> 85
A5: =(A4+1) -> 44191 | B5: 85 | C5: =IF(AC5>0,((B5-R5)+(S5-B6)),IF(B6=0, ,(B5-B6))) -> 5 | D5: 85 | E5: =IF(AC5>0,((D5-U5)+(V5-D6)),IF(D6=0, ,(D5-D6))) -> 5 | F5: 84 | G5: =IF(AC5>0,((F5-X5)+(Y5-F6)),IF(F6=0, ,(F5-F6))) -> 9 | H5: 82 | I5: =IF(AC5>0,((H5-AA5)+(AB5-H6)),IF(H6=0, ,(H5-H6))) -> 3 | J5: =B5+D5+F5+H5 -> 336 | K5: =J5/4 -> 84 | L5: =IF(AC5>0,((K5-AD5)+(AE5-K6)),IF(K6=0, ,(K5-K6))) -> 5.5 | M5: =7000*4 -> 28000 | N5: =L5*M5/100 -> 1540 | O5: =N5*0.53 -> 816.2 | P5: =O5*8.1757 -> 6673.0063 | AC5: =Q5+T5+W5+Z5 -> 0 | AD5: =(R5+U5+X5+AA5)/4 -> 0 | AE5: =(S5+V5+Y5+AB5)/4 -> 0
A6: =(A5+1) -> 44192 | B6: 80 | C6: =IF(AC6>0,((B6-R6)+(S6-B7)),IF(B7=0, ,(B6-B7))) -> 8 | D6: 80 | E6: =IF(AC6>0,((D6-U6)+(V6-D7)),IF(D7=0, ,(D6-D7))) -> 8 | F6: 75 | G6: =IF(AC6>0,((F6-X6)+(Y6-F7)),IF(F7=0, ,(F6-F7))) -> 6 | H6: 79 | I6: =IF(AC6>0,((H6-AA6)+(AB6-H7)),IF(H7=0, ,(H6-H7))) -> 9 | J6: =B6+D6+F6+H6 -> 314 | K6: =J6/4 -> 78.5 | L6: =IF(AC6>0,((K6-AD6)+(AE6-K7)),IF(K7=0, ,(K6-K7))) -> 7.75 | M6: =7000*4 -> 28000 | N6: =L6*M6/100 -> 2170 | O6: =N6*0.53 -> 1150.1 | P6: =O6*8.1757 -> 9402.8726 | AC6: =Q6+T6+W6+Z6 -> 0 | AD6: =(R6+U6+X6+AA6)/4 -> 0 | AE6: =(S6+V6+Y6+AB6)/4 -> 0
A7: =(A6+1) -> 44193 | B7: 72 | C7: =IF(AC7>0,((B7-R7)+(S7-B8)),IF(B8=0, ,(B7-B8))) -> 5 | D7: 72 | E7: =IF(AC7>0,((D7-U7)+(V7-D8)),IF(D8=0, ,(D7-D8))) -> 4 | F7: 69 | G7: =IF(AC7>0,((F7-X7)+(Y7-F8)),IF(F8=0, ,(F7-F8))) -> 7 | H7: 70 | I7: =IF(AC7>0,((H7-AA7)+(AB7-H8)),IF(H8=0, ,(H7-H8))) -> 5 | J7: =B7+D7+F7+H7 -> 283 | K7: =J7/4 -> 70.75 | L7: =IF(AC7>0,((K7-AD7)+(AE7-K8)),IF(K8=0, ,(K7-K8))) -> 5.25 | M7: =7000*4 -> 28000 | N7: =L7*M7/100 -> 1470 | O7: =N7*0.53 -> 779.1 | P7: =O7*8.1757 -> 6369.6879 | AC7: =Q7+T7+W7+Z7 -> 0 | AD7: =(R7+U7+X7+AA7)/4 -> 0 | AE7: =(S7+V7+Y7+AB7)/4 -> 0
A8: =(A7+1) -> 44194 | B8: 67 | C8: =IF(AC8>0,((B8-R8)+(S8-B9)),IF(B9=0, ,(B8-B9))) -> 7 | D8: 68 | E8: =IF(AC8>0,((D8-U8)+(V8-D9)),IF(D9=0, ,(D8-D9))) -> 6 | F8: 62 | G8: =IF(AC8>0,((F8-X8)+(Y8-F9)),IF(F9=0, ,(F8-F9))) -> 7 | H8: 65 | I8: =IF(AC8>0,((H8-AA8)+(AB8-H9)),IF(H9=0, ,(H8-H9))) -> 5 | J8: =B8+D8+F8+H8 -> 262 | K8: =J8/4 -> 65.5 | L8: =IF(AC8>0,((K8-AD8)+(AE8-K9)),IF(K9=0, ,(K8-K9))) -> 6.25 | M8: =7000*4 -> 28000 | N8: =L8*M8/100 -> 1750 | O8: =N8*0.53 -> 927.5 | P8: =O8*8.1757 -> 7582.9618 | AC8: =Q8+T8+W8+Z8 -> 0 | AD8: =(R8+U8+X8+AA8)/4 -> 0 | AE8: =(S8+V8+Y8+AB8)/4 -> 0
A9: =(A8+1) -> 44195 | B9: 60 | C9: =IF(AC9>0,((B9-R9)+(S9-B10)),IF(B10=0, ,(B9-B10))) -> 10 | D9: 62 | E9: =IF(AC9>0,((D9-U9)+(V9-D10)),IF(D10=0, ,(D9-D10))) -> 11 | F9: 55 | G9: =IF(AC9>0,((F9-X9)+(Y9-F10)),IF(F10=0, ,(F9-F10))) -> 11 | H9: 60 | I9: =IF(AC9>0,((H9-AA9)+(AB9-H10)),IF(H10=0, ,(H9-H10))) -> 10 | J9: =B9+D9+F9+H9 -> 237 | K9: =J9/4 -> 59.25 | L9: =IF(AC9>0,((K9-AD9)+(AE9-K10)),IF(K10=0, ,(K9-K10))) -> 10.5 | M9: =7000*4 -> 28000 | N9: =L9*M9/100 -> 2940 | O9: =N9*0.53 -> 1558.2 | P9: =O9*8.1757 -> 12739.376 | AC9: =Q9+T9+W9+Z9 -> 0 | AD9: =(R9+U9+X9+AA9)/4 -> 0 | AE9: =(S9+V9+Y9+AB9)/4 -> 0
A10: =(A9+1) -> 44196 | B10: 50 | C10: =IF(AC10>0,((B10-R10)+(S10-B11)),IF(B11=0, ,(B10-B11))) -> 1 | D10: 51 | E10: =IF(AC10>0,((D10-U10)+(V10-D11)),IF(D11=0, ,(D10-D11))) -> 2 | F10: 44 | G10: =IF(AC10>0,((F10-X10)+(Y10-F11)),IF(F11=0, ,(F10-F11))) -> 6 | H10: 50 | I10: =IF(AC10>0,((H10-AA10)+(AB10-H11)),IF(H11=0, ,(H10-H11))) -> 6 | J10: =B10+D10+F10+H10 -> 195 | K10: =J10/4 -> 48.75 | L10: =IF(AC10>0,((K10-AD10)+(AE10-K11)),IF(K11=0, ,(K10-K11))) -> 3.75 | M10: =7000*4 -> 28000 | N10: =L10*M10/100 -> 1050 | O10: =N10*0.53 -> 556.5 | P10: =O10*8.2658 -> 4599.9177 | Q10: 3017 | R10: 50 | S10: 85 | T10: 2836 | U10: 50 | V10: 85 | W10: 3384 | X10: 43 | Y10: 85 | Z10: 3330 | AA10: 49 | AB10: 85 | AC10: =Q10+T10+W10+Z10 -> 12567 | AD10: =(R10+U10+X10+AA10)/4 -> 48 | AE10: =(S10+V10+Y10+AB10)/4 -> 85
A11: =(A10+1) -> 44197 | B11: 84 | C11: =IF(AC11>0,((B11-R11)+(S11-B12)),IF(B12=0, ,(B11-B12))) -> 13 | D11: 84 | E11: =IF(AC11>0,((D11-U11)+(V11-D12)),IF(D12=0, ,(D11-D12))) -> 13 | F11: 80 | G11: =IF(AC11>0,((F11-X11)+(Y11-F12)),IF(F12=0, ,(F11-F12))) -> 12 | H11: 80 | I11: =IF(AC11>0,((H11-AA11)+(AB11-H12)),IF(H12=0, ,(H11-H12))) -> 10 | J11: =B11+D11+F11+H11 -> 328 | K11: =J11/4 -> 82 | L11: =IF(AC11>0,((K11-AD11)+(AE11-K12)),IF(K12=0, ,(K11-K12))) -> 12 | M11: =7000*4 -> 28000 | N11: =L11*M11/100 -> 3360 | O11: =N11*0.53 -> 1780.8 | P11: =O11*8.2658 -> 14719.737 | AC11: =Q11+T11+W11+Z11 -> 0 | AD11: =(R11+U11+X11+AA11)/4 -> 0 | AE11: =(S11+V11+Y11+AB11)/4 -> 0
A12: =(A11+1) -> 44198 | B12: 71 | C12: =IF(AC12>0,((B12-R12)+(S12-B13)),IF(B13=0, ,(B12-B13))) -> 5 | D12: 71 | E12: =IF(AC12>0,((D12-U12)+(V12-D13)),IF(D13=0, ,(D12-D13))) -> 3 | F12: 68 | G12: =IF(AC12>0,((F12-X12)+(Y12-F13)),IF(F13=0, ,(F12-F13))) -> 4 | H12: 70 | I12: =IF(AC12>0,((H12-AA12)+(AB12-H13)),IF(H13=0, ,(H12-H13))) -> 4 | J12: =B12+D12+F12+H12 -> 280 | K12: =J12/4 -> 70 | L12: =IF(AC12>0,((K12-AD12)+(AE12-K13)),IF(K13=0, ,(K12-K13))) -> 4 | M12: =7000*4 -> 28000 | N12: =L12*M12/100 -> 1120 | O12: =N12*0.53 -> 593.6 | P12: =O12*8.2658 -> 4906.5789 | AC12: =Q12+T12+W12+Z12 -> 0 | AD12: =(R12+U12+X12+AA12)/4 -> 0 | AE12: =(S12+V12+Y12+AB12)/4 -> 0
A13: =(A12+1) -> 44199 | B13: 66 | C13: =IF(AC13>0,((B13-R13)+(S13-B14)),IF(B14=0, ,(B13-B14))) -> 0 | D13: 68 | E13: =IF(AC13>0,((D13-U13)+(V13-D14)),IF(D14=0, ,(D13-D14))) -> 2 | F13: 64 | G13: =IF(AC13>0,((F13-X13)+(Y13-F14)),IF(F14=0, ,(F13-F14))) -> 4 | H13: 66 | I13: =IF(AC13>0,((H13-AA13)+(AB13-H14)),IF(H14=0, ,(H13-H14))) -> 4 | J13: =B13+D13+F13+H13 -> 264 | K13: =J13/4 -> 66 | L13: =IF(AC13>0,((K13-AD13)+(AE13-K14)),IF(K14=0, ,(K13-K14))) -> 2.5 | M13: =7000*4 -> 28000 | N13: =L13*M13/100 -> 700 | O13: =N13*0.53 -> 371 | P13: =O13*8.2658 -> 3066.6118 | AC13: =Q13+T13+W13+Z13 -> 0 | AD13: =(R13+U13+X13+AA13)/4 -> 0 | AE13: =(S13+V13+Y13+AB13)/4 -> 0
A14: =(A13+1) -> 44200 | B14: 66 | C14: =IF(AC14>0,((B14-R14)+(S14-B15)),IF(B15=0, ,(B14-B15))) -> 4 | D14: 66 | E14: =IF(AC14>0,((D14-U14)+(V14-D15)),IF(D15=0, ,(D14-D15))) -> 1 | F14: 60 | G14: =IF(AC14>0,((F14-X14)+(Y14-F15)),IF(F15=0, ,(F14-F15))) -> 2 | H14: 62 | I14: =IF(AC14>0,((H14-AA14)+(AB14-H15)),IF(H15=0, ,(H14-H15))) -> 0 | J14: =B14+D14+F14+H14 -> 254 | K14: =J14/4 -> 63.5 | L14: =IF(AC14>0,((K14-AD14)+(AE14-K15)),IF(K15=0, ,(K14-K15))) -> 1.75 | M14: =7000*4 -> 28000 | N14: =L14*M14/100 -> 490 | O14: =N14*0.53 -> 259.7 | P14: =O14*8.2658 -> 2146.6283 | AC14: =Q14+T14+W14+Z14 -> 0 | AD14: =(R14+U14+X14+AA14)/4 -> 0 | AE14: =(S14+V14+Y14+AB14)/4 -> 0
A15: =(A14+1) -> 44201 | B15: 62 | C15: =IF(AC15>0,((B15-R15)+(S15-B16)),IF(B16=0, ,(B15-B16))) -> 4 | D15: 65 | F15: 58 | G15: =IF(AC15>0,((F15-X15)+(Y15-F16)),IF(F16=0, ,(F15-F16))) -> 8 | H15: 62 | I15: =IF(AC15>0,((H15-AA15)+(AB15-H16)),IF(H16=0, ,(H15-H16))) -> 7 | J15: =B15+D15+F15+H15 -> 247 | K15: =J15/4 -> 61.75 | L15: =IF(AC15>0,((K15-AD15)+(AE15-K16)),IF(K16=0, ,(K15-K16))) -> 6 | M15: =7000*4 -> 28000 | N15: =L15*M15/100 -> 1680 | O15: =N15*0.53 -> 890.4 | P15: =O15*8.2658 -> 7359.8683 | AC15: =Q15+T15+W15+Z15 -> 0 | AD15: =(R15+U15+X15+AA15)/4 -> 0 | AE15: =(S15+V15+Y15+AB15)/4 -> 0
A16: =(A15+1) -> 44202 | B16: 58 | C16: =IF(AC16>0,((B16-R16)+(S16-B17)),IF(B17=0, ,(B16-B17))) -> 8 | D16: 60 | E16: =IF(AC16>0,((D16-U16)+(V16-D17)),IF(D17=0, ,(D16-D17))) -> 5 | F16: 50 | G16: =IF(AC16>0,((F16-X16)+(Y16-F17)),IF(F17=0, ,(F16-F17))) -> 1 | H16: 55 | I16: =IF(AC16>0,((H16-AA16)+(AB16-H17)),IF(H17=0, ,(H16-H17))) -> 5 | J16: =B16+D16+F16+H16 -> 223 | K16: =J16/4 -> 55.75 | L16: =IF(AC16>0,((K16-AD16)+(AE16-K17)),IF(K17=0, ,(K16-K17))) -> 4.75 | M16: =7000*4 -> 28000 | N16: =L16*M16/100 -> 1330 | O16: =N16*0.53 -> 704.9 | P16: =O16*8.2658 -> 5826.5624 | AC16: =Q16+T16+W16+Z16 -> 0 | AD16: =(R16+U16+X16+AA16)/4 -> 0 | AE16: =(S16+V16+Y16+AB16)/4 -> 0
A17: =(A16+1) -> 44203 | B17: 50 | C17: =IF(AC17>0,((B17-R17)+(S17-B18)),IF(B18=0, ,(B17-B18))) -> 0 | D17: 55 | E17: =IF(AC17>0,((D17-U17)+(V17-D18)),IF(D18=0, ,(D17-D18))) -> 3 | F17: 49 | G17: =IF(AC17>0,((F17-X17)+(Y17-F18)),IF(F18=0, ,(F17-F18))) -> 4 | H17: 50 | I17: =IF(AC17>0,((H17-AA17)+(AB17-H18)),IF(H18=0, ,(H17-H18))) -> 1 | J17: =B17+D17+F17+H17 -> 204 | K17: =J17/4 -> 51 | L17: =IF(AC17>0,((K17-AD17)+(AE17-K18)),IF(K18=0, ,(K17-K18))) -> 2 | M17: =7000*4 -> 28000 | N17: =L17*M17/100 -> 560 | O17: =N17*0.53 -> 296.8 | P17: =O17*8.2658 -> 2453.2894 | AC17: =Q17+T17+W17+Z17 -> 0 | AD17: =(R17+U17+X17+AA17)/4 -> 0 | AE17: =(S17+V17+Y17+AB17)/4 -> 0
A18: =(A17+1) -> 44204 | B18: 50 | C18: =IF(AC18>0,((B18-R18)+(S18-B19)),IF(B19=0, ,(B18-B19))) -> 0 | D18: 52 | E18: =IF(AC18>0,((D18-U18)+(V18-D19)),IF(D19=0, ,(D18-D19))) -> 0 | F18: 45 | G18: =IF(AC18>0,((F18-X18)+(Y18-F19)),IF(F19=0, ,(F18-F19))) -> 0 | H18: 49 | I18: =IF(AC18>0,((H18-AA18)+(AB18-H19)),IF(H19=0, ,(H18-H19))) -> 4 | J18: =B18+D18+F18+H18 -> 196 | K18: =J18/4 -> 49 | L18: =IF(AC18>0,((K18-AD18)+(AE18-K19)),IF(K19=0, ,(K18-K19))) -> 1 | M18: =7000*4 -> 28000 | N18: =L18*M18/100 -> 280 | O18: =N18*0.53 -> 148.4 | P18: =O18*8.2658 -> 1226.6447 | Q18: 1836 | R18: 50 | S18: 85 | T18: 1462 | U18: 55 | V18: 85 | W18: 1535 | X18: 55 | Y18: 85 | Z18: 1338 | AA18: 55 | AB18: 85 | AC18: =Q18+T18+W18+Z18 -> 6171 | AD18: =(R18+U18+X18+AA18)/4 -> 53.75 | AE18: =(S18+V18+Y18+AB18)/4 -> 85
A19: =(A18+1) -> 44205 | B19: 85 | C19: =IF(AC19>0,((B19-R19)+(S19-B20)),IF(B20=0, ,(B19-B20))) -> 5 | D19: 82 | E19: =IF(AC19>0,((D19-U19)+(V19-D20)),IF(D20=0, ,(D19-D20))) -> 2 | F19: 75 | G19: =IF(AC19>0,((F19-X19)+(Y19-F20)),IF(F20=0, ,(F19-F20))) -> 0 | H19: 75 | I19: =IF(AC19>0,((H19-AA19)+(AB19-H20)),IF(H20=0, ,(H19-H20))) -> 0 | J19: =B19+D19+F19+H19 -> 317 | K19: =J19/4 -> 79.25 | L19: =IF(AC19>0,((K19-AD19)+(AE19-K20)),IF(K20=0, ,(K19-K20))) -> 1.75 | M19: =7000*4 -> 28000 | N19: =L19*M19/100 -> 490 | O19: =N19*0.53 -> 259.7 | P19: =O19*8.2658 -> 2146.6283 | AC19: =Q19+T19+W19+Z19 -> 0 | AD19: =(R19+U19+X19+AA19)/4 -> 0 | AE19: =(S19+V19+Y19+AB19)/4 -> 0
A20: =(A19+1) -> 44206 | B20: 80 | C20: =IF(AC20>0,((B20-R20)+(S20-B21)),IF(B21=0, ,(B20-B21))) -> 8 | D20: 80 | E20: =IF(AC20>0,((D20-U20)+(V20-D21)),IF(D21=0, ,(D20-D21))) -> 8 | F20: 75 | G20: =IF(AC20>0,((F20-X20)+(Y20-F21)),IF(F21=0, ,(F20-F21))) -> 5 | H20: 75 | I20: =IF(AC20>0,((H20-AA20)+(AB20-H21)),IF(H21=0, ,(H20-H21))) -> 5 | J20: =B20+D20+F20+H20 -> 310 | K20: =J20/4 -> 77.5 | L20: =IF(AC20>0,((K20-AD20)+(AE20-K21)),IF(K21=0, ,(K20-K21))) -> 6.5 | M20: =7000*4 -> 28000 | N20: =L20*M20/100 -> 1820 | O20: =N20*0.53 -> 964.6 | P20: =O20*8.2658 -> 7973.1907 | AC20: =Q20+T20+W20+Z20 -> 0 | AD20: =(R20+U20+X20+AA20)/4 -> 0 | AE20: =(S20+V20+Y20+AB20)/4 -> 0
A21: =(A20+1) -> 44207 | B21: 72 | C21: =IF(AC21>0,((B21-R21)+(S21-B22)),IF(B22=0, ,(B21-B22))) -> 4 | D21: 72 | E21: =IF(AC21>0,((D21-U21)+(V21-D22)),IF(D22=0, ,(D21-D22))) -> 2 | F21: 70 | G21: =IF(AC21>0,((F21-X21)+(Y21-F22)),IF(F22=0, ,(F21-F22))) -> 6 | H21: 70 | I21: =IF(AC21>0,((H21-AA21)+(AB21-H22)),IF(H22=0, ,(H21-H22))) -> 5 | J21: =B21+D21+F21+H21 -> 284 | K21: =J21/4 -> 71 | L21: =IF(AC21>0,((K21-AD21)+(AE21-K22)),IF(K22=0, ,(K21-K22))) -> 4.25 | M21: =7000*4 -> 28000 | N21: =L21*M21/100 -> 1190 | O21: =N21*0.53 -> 630.7 | P21: =O21*8.2658 -> 5213.2401 | AC21: =Q21+T21+W21+Z21 -> 0 | AD21: =(R21+U21+X21+AA21)/4 -> 0 | AE21: =(S21+V21+Y21+AB21)/4 -> 0
A22: =(A21+1) -> 44208 | B22: 68 | C22: =IF(AC22>0,((B22-R22)+(S22-B23)),IF(B23=0, ,(B22-B23))) -> 6 | D22: 70 | E22: =IF(AC22>0,((D22-U22)+(V22-D23)),IF(D23=0, ,(D22-D23))) -> 7 | F22: 64 | G22: =IF(AC22>0,((F22-X22)+(Y22-F23)),IF(F23=0, ,(F22-F23))) -> 4 | H22: 65 | I22: =IF(AC22>0,((H22-AA22)+(AB22-H23)),IF(H23=0, ,(H22-H23))) -> 4 | J22: =B22+D22+F22+H22 -> 267 | K22: =J22/4 -> 66.75 | L22: =IF(AC22>0,((K22-AD22)+(AE22-K23)),IF(K23=0, ,(K22-K23))) -> 5.25 | M22: =7000*4 -> 28000 | N22: =L22*M22/100 -> 1470 | O22: =N22*0.53 -> 779.1 | P22: =O22*8.2658 -> 6439.8848 | AC22: =Q22+T22+W22+Z22 -> 0 | AD22: =(R22+U22+X22+AA22)/4 -> 0 | AE22: =(S22+V22+Y22+AB22)/4 -> 0
A23: =(A22+1) -> 44209 | B23: 62 | C23: =IF(AC23>0,((B23-R23)+(S23-B24)),IF(B24=0, ,(B23-B24))) -> 2 | D23: 63 | E23: =IF(AC23>0,((D23-U23)+(V23-D24)),IF(D24=0, ,(D23-D24))) -> 2 | F23: 60 | G23: =IF(AC23>0,((F23-X23)+(Y23-F24)),IF(F24=0, ,(F23-F24))) -> 5 | H23: 61 | I23: =IF(AC23>0,((H23-AA23)+(AB23-H24)),IF(H24=0, ,(H23-H24))) -> 1 | J23: =B23+D23+F23+H23 -> 246 | K23: =J23/4 -> 61.5 | L23: =IF(AC23>0,((K23-AD23)+(AE23-K24)),IF(K24=0, ,(K23-K24))) -> 2.5 | M23: =7000*4 -> 28000 | N23: =L23*M23/100 -> 700 | O23: =N23*0.53 -> 371 | P23: =O23*8.2658 -> 3066.6118 | AC23: =Q23+T23+W23+Z23 -> 0 | AD23: =(R23+U23+X23+AA23)/4 -> 0 | AE23: =(S23+V23+Y23+AB23)/4 -> 0
A24: =(A23+1) -> 44210 | B24: 60 | C24: =IF(AC24>0,((B24-R24)+(S24-B25)),IF(B25=0, ,(B24-B25))) -> 1 | D24: 61 | E24: =IF(AC24>0,((D24-U24)+(V24-D25)),IF(D25=0, ,(D24-D25))) -> 1 | F24: 55 | G24: =IF(AC24>0,((F24-X24)+(Y24-F25)),IF(F25=0, ,(F24-F25))) -> 5 | H24: 60 | I24: =IF(AC24>0,((H24-AA24)+(AB24-H25)),IF(H25=0, ,(H24-H25))) -> 2 | J24: =B24+D24+F24+H24 -> 236 | K24: =J24/4 -> 59 | L24: =IF(AC24>0,((K24-AD24)+(AE24-K25)),IF(K25=0, ,(K24-K25))) -> 2.25 | M24: =7000*4 -> 28000 | N24: =L24*M24/100 -> 630 | O24: =N24*0.53 -> 333.9 | P24: =O24*8.2658 -> 2759.9506 | AC24: =Q24+T24+W24+Z24 -> 0 | AD24: =(R24+U24+X24+AA24)/4 -> 0 | AE24: =(S24+V24+Y24+AB24)/4 -> 0
A25: =(A24+1) -> 44211 | B25: 59 | C25: =IF(AC25>0,((B25-R25)+(S25-B26)),IF(B26=0, ,(B25-B26))) -> 9 | D25: 60 | E25: =IF(AC25>0,((D25-U25)+(V25-D26)),IF(D26=0, ,(D25-D26))) -> 5 | F25: 50 | G25: =IF(AC25>0,((F25-X25)+(Y25-F26)),IF(F26=0, ,(F25-F26))) -> 3 | H25: 58 | I25: =IF(AC25>0,((H25-AA25)+(AB25-H26)),IF(H26=0, ,(H25-H26))) -> 8 | J25: =B25+D25+F25+H25 -> 227 | K25: =J25/4 -> 56.75 | L25: =IF(AC25>0,((K25-AD25)+(AE25-K26)),IF(K26=0, ,(K25-K26))) -> 6.25 | M25: =7000*4 -> 28000 | N25: =L25*M25/100 -> 1750 | O25: =N25*0.53 -> 927.5 | P25: =O25*8.2658 -> 7666.5295 | AC25: =Q25+T25+W25+Z25 -> 0 | AD25: =(R25+U25+X25+AA25)/4 -> 0 | AE25: =(S25+V25+Y25+AB25)/4 -> 0
A26: =(A25+1) -> 44212 | B26: 50 | C26: =IF(AC26>0,((B26-R26)+(S26-B27)),IF(B27=0, ,(B26-B27))) -> 1 | D26: 55 | E26: =IF(AC26>0,((D26-U26)+(V26-D27)),IF(D27=0, ,(D26-D27))) -> 6 | F26: 47 | G26: =IF(AC26>0,((F26-X26)+(Y26-F27)),IF(F27=0, ,(F26-F27))) -> 1 | H26: 50 | I26: =IF(AC26>0,((H26-AA26)+(AB26-H27)),IF(H27=0, ,(H26-H27))) -> 2 | J26: =B26+D26+F26+H26 -> 202 | K26: =J26/4 -> 50.5 | L26: =IF(AC26>0,((K26-AD26)+(AE26-K27)),IF(K27=0, ,(K26-K27))) -> 2.5 | M26: =7000*4 -> 28000 | N26: =L26*M26/100 -> 700 | O26: =N26*0.53 -> 371 | P26: =O26*8.2658 -> 3066.6118 | Q26: 2117 | R26: 50 | S26: 75 | T26: 2103 | U26: 50 | V26: 75 | W26: 2109 | X26: 45 | Y26: 70 | Z26: 2105 | AA26: 55 | AB26: 80 | AC26: =Q26+T26+W26+Z26 -> 8434 | AD26: =(R26+U26+X26+AA26)/4 -> 50 | AE26: =(S26+V26+Y26+AB26)/4 -> 75
A27: =(A26+1) -> 44213 | B27: 74 | C27: =IF(AC27>0,((B27-R27)+(S27-B28)),IF(B28=0, ,(B27-B28))) -> 4 | D27: 74 | E27: =IF(AC27>0,((D27-U27)+(V27-D28)),IF(D28=0, ,(D27-D28))) -> 2 | F27: 71 | G27: =IF(AC27>0,((F27-X27)+(Y27-F28)),IF(F28=0, ,(F27-F28))) -> 3 | H27: 73 | I27: =IF(AC27>0,((H27-AA27)+(AB27-H28)),IF(H28=0, ,(H27-H28))) -> 3 | J27: =B27+D27+F27+H27 -> 292 | K27: =J27/4 -> 73 | L27: =IF(AC27>0,((K27-AD27)+(AE27-K28)),IF(K28=0, ,(K27-K28))) -> 3 | M27: =7000*4 -> 28000 | N27: =L27*M27/100 -> 840 | O27: =N27*0.53 -> 445.2 | P27: =O27*8.2658 -> 3679.9342 | AC27: =Q27+T27+W27+Z27 -> 0 | AD27: =(R27+U27+X27+AA27)/4 -> 0 | AE27: =(S27+V27+Y27+AB27)/4 -> 0
A28: =(A27+1) -> 44214 | B28: 70 | C28: =IF(AC28>0,((B28-R28)+(S28-B29)),IF(B29=0, ,(B28-B29))) -> 0 | D28: 72 | E28: =IF(AC28>0,((D28-U28)+(V28-D29)),IF(D29=0, ,(D28-D29))) -> 0 | F28: 68 | G28: =IF(AC28>0,((F28-X28)+(Y28-F29)),IF(F29=0, ,(F28-F29))) -> 0 | H28: 70 | I28: =IF(AC28>0,((H28-AA28)+(AB28-H29)),IF(H29=0, ,(H28-H29))) -> 0 | J28: =B28+D28+F28+H28 -> 280 | K28: =J28/4 -> 70 | L28: =IF(AC28>0,((K28-AD28)+(AE28-K29)),IF(K29=0, ,(K28-K29))) -> 0 | M28: =7000*4 -> 28000 | N28: =L28*M28/100 -> 0 | O28: =N28*0.53 -> 0 | P28: =O28*8.2658 -> 0 | AC28: =Q28+T28+W28+Z28 -> 0 | AD28: =(R28+U28+X28+AA28)/4 -> 0 | AE28: =(S28+V28+Y28+AB28)/4 -> 0
A29: =(A28+1) -> 44215 | C29: =IF(AC29>0,((B29-R29)+(S29-B30)),IF(B30=0, ,(B29-B30))) -> 0 | E29: =IF(AC29>0,((D29-U29)+(V29-D30)),IF(D30=0, ,(D29-D30))) -> 0 | G29: =IF(AC29>0,((F29-X29)+(Y29-F30)),IF(F30=0, ,(F29-F30))) -> 0 | I29: =IF(AC29>0,((H29-AA29)+(AB29-H30)),IF(H30=0, ,(H29-H30))) -> 0 | J29: =B29+D29+F29+H29 -> 0 | K29: =J29/4 -> 0 | L29: =IF(AC29>0,((K29-AD29)+(AE29-K30)),IF(K30=0, ,(K29-K30))) -> 0 | M29: =7000*4 -> 28000 | N29: =L29*M29/100 -> 0 | O29: =N29*0.53 -> 0 | P29: =O29*8.2658 -> 0 | AC29: =Q29+T29+W29+Z29 -> 0 | AD29: =(R29+U29+X29+AA29)/4 -> 0 | AE29: =(S29+V29+Y29+AB29)/4 -> 0
A30: =(A29+1) -> 44216 | C30: =IF(AC30>0,((B30-R30)+(S30-B31)),IF(B31=0, ,(B30-B31))) -> 0 | E30: =IF(AC30>0,((D30-U30)+(V30-D31)),IF(D31=0, ,(D30-D31))) -> 0 | G30: =IF(AC30>0,((F30-X30)+(Y30-F31)),IF(F31=0, ,(F30-F31))) -> 0 | I30: =IF(AC30>0,((H30-AA30)+(AB30-H31)),IF(H31=0, ,(H30-H31))) -> 0 | J30: =B30+D30+F30+H30 -> 0 | K30: =J30/4 -> 0 | L30: =IF(AC30>0,((K30-AD30)+(AE30-K31)),IF(K31=0, ,(K30-K31))) -> 0 | M30: =7000*4 -> 28000 | N30: =L30*M30/100 -> 0 | O30: =N30*0.53 -> 0 | P30: =O30*8.2658 -> 0 | AC30: =Q30+T30+W30+Z30 -> 0 | AD30: =(R30+U30+X30+AA30)/4 -> 0 | AE30: =(S30+V30+Y30+AB30)/4 -> 0
A31: =(A30+1) -> 44217 | C31: =IF(AC31>0,((B31-R31)+(S31-B32)),IF(B32=0, ,(B31-B32))) -> 0 | E31: =IF(AC31>0,((D31-U31)+(V31-D32)),IF(D32=0, ,(D31-D32))) -> 0 | G31: =IF(AC31>0,((F31-X31)+(Y31-F32)),IF(F32=0, ,(F31-F32))) -> 0 | I31: =IF(AC31>0,((H31-AA31)+(AB31-H32)),IF(H32=0, ,(H31-H32))) -> 0 | J31: =B31+D31+F31+H31 -> 0 | K31: =J31/4 -> 0 | L31: =IF(AC31>0,((K31-AD31)+(AE31-K32)),IF(K32=0, ,(K31-K32))) -> 0 | M31: =7000*4 -> 28000 | N31: =L31*M31/100 -> 0 | O31: =N31*0.53 -> 0 | P31: =O31*8.2658 -> 0 | AC31: =Q31+T31+W31+Z31 -> 0 | AD31: =(R31+U31+X31+AA31)/4 -> 0 | AE31: =(S31+V31+Y31+AB31)/4 -> 0
A32: =(A31+1) -> 44218 | C32: =IF(AC32>0,((B32-R32)+(S32-B33)),IF(B33=0, ,(B32-B33))) -> 0 | E32: =IF(AC32>0,((D32-U32)+(V32-D33)),IF(D33=0, ,(D32-D33))) -> 0 | G32: =IF(AC32>0,((F32-X32)+(Y32-F33)),IF(F33=0, ,(F32-F33))) -> 0 | I32: =IF(AC32>0,((H32-AA32)+(AB32-H33)),IF(H33=0, ,(H32-H33))) -> 0 | J32: =B32+D32+F32+H32 -> 0 | K32: =J32/4 -> 0 | L32: =IF(AC32>0,((K32-AD32)+(AE32-K33)),IF(K33=0, ,(K32-K33))) -> 0 | M32: =7000*4 -> 28000 | N32: =L32*M32/100 -> 0 | O32: =N32*0.53 -> 0 | P32: =O32*8.2658 -> 0 | AC32: =Q32+T32+W32+Z32 -> 0 | AD32: =(R32+U32+X32+AA32)/4 -> 0 | AE32: =(S32+V32+Y32+AB32)/4 -> 0
A33: =(A32+1) -> 44219 | C33: =IF(AC33>0,((B33-R33)+(S33-B34)),IF(B34=0, ,(B33-B34))) -> 0 | E33: =IF(AC33>0,((D33-U33)+(V33-D34)),IF(D34=0, ,(D33-D34))) -> 0 | G33: =IF(AC33>0,((F33-X33)+(Y33-F34)),IF(F34=0, ,(F33-F34))) -> 0 | I33: =IF(AC33>0,((H33-AA33)+(AB33-H34)),IF(H34=0, ,(H33-H34))) -> 0 | J33: =B33+D33+F33+H33 -> 0 | K33: =J33/4 -> 0 | L33: =IF(AC33>0,((K33-AD33)+(AE33-K34)),IF(K34=0, ,(K33-K34))) -> 0 | M33: =7000*4 -> 28000 | N33: =L33*M33/100 -> 0 | O33: =N33*0.53 -> 0 | P33: =O33*8.2658 -> 0 | AC33: =Q33+T33+W33+Z33 -> 0 | AD33: =(R33+U33+X33+AA33)/4 -> 0 | AE33: =(S33+V33+Y33+AB33)/4 -> 0
A34: =(A33+1) -> 44220 | C34: =IF(AC34>0,((B34-R34)+(S34-B35)),IF(B35=0, ,(B34-B35))) -> 0 | E34: =IF(AC34>0,((D34-U34)+(V34-D35)),IF(D35=0, ,(D34-D35))) -> 0 | G34: =IF(AC34>0,((F34-X34)+(Y34-F35)),IF(F35=0, ,(F34-F35))) -> 0 | I34: =IF(AC34>0,((H34-AA34)+(AB34-H35)),IF(H35=0, ,(H34-H35))) -> 0 | J34: =B34+D34+F34+H34 -> 0 | K34: =J34/4 -> 0 | L34: =IF(AC34>0,((K34-AD34)+(AE34-K35)),IF(K35=0, ,(K34-K35))) -> 0 | M34: =7000*4 -> 28000 | N34: =L34*M34/100 -> 0 | O34: =N34*0.53 -> 0 | P34: =O34*8.2658 -> 0 | AC34: =Q34+T34+W34+Z34 -> 0 | AD34: =(R34+U34+X34+AA34)/4 -> 0 | AE34: =(S34+V34+Y34+AB34)/4 -> 0
A35: =(A34+1) -> 44221 | C35: =IF(AC35>0,((B35-R35)+(S35-B36)),IF(B36=0, ,(B35-B36))) -> 0 | E35: =IF(AC35>0,((D35-U35)+(V35-D36)),IF(D36=0, ,(D35-D36))) -> 0 | G35: =IF(AC35>0,((F35-X35)+(Y35-F36)),IF(F36=0, ,(F35-F36))) -> 0 | I35: =IF(AC35>0,((H35-AA35)+(AB35-H36)),IF(H36=0, ,(H35-H36))) -> 0 | J35: =B35+D35+F35+H35 -> 0 | K35: =J35/4 -> 0 | L35: =IF(AC35>0,((K35-AD35)+(AE35-K36)),IF(K36=0, ,(K35-K36))) -> 0 | M35: =7000*4 -> 28000 | N35: =L35*M35/100 -> 0 | O35: =N35*0.53 -> 0 | P35: =O35*8.2658 -> 0 | AC35: =Q35+T35+W35+Z35 -> 0 | AD35: =(R35+U35+X35+AA35)/4 -> 0 | AE35: =(S35+V35+Y35+AB35)/4 -> 0
A36: =(A35+1) -> 44222 | C36: =IF(AC36>0,((B36-R36)+(S36-B37)),IF(B37=0, ,(B36-B37))) -> 0 | E36: =IF(AC36>0,((D36-U36)+(V36-D37)),IF(D37=0, ,(D36-D37))) -> 0 | G36: =IF(AC36>0,((F36-X36)+(Y36-F37)),IF(F37=0, ,(F36-F37))) -> 0 | I36: =IF(AC36>0,((H36-AA36)+(AB36-H37)),IF(H37=0, ,(H36-H37))) -> 0 | J36: =B36+D36+F36+H36 -> 0 | K36: =J36/4 -> 0 | L36: =IF(AC36>0,((K36-AD36)+(AE36-K37)),IF(K37=0, ,(K36-K37))) -> 0 | M36: =7000*4 -> 28000 | N36: =L36*M36/100 -> 0 | O36: =N36*0.53 -> 0 | P36: =O36*8.2658 -> 0 | AC36: =Q36+T36+W36+Z36 -> 0 | AD36: =(R36+U36+X36+AA36)/4 -> 0 | AE36: =(S36+V36+Y36+AB36)/4 -> 0
A37: =(A36+1) -> 44223 | C37: =IF(AC37>0,((B37-R37)+(S37-B38)),IF(B38=0, ,(B37-B38))) -> 0 | E37: =IF(AC37>0,((D37-U37)+(V37-D38)),IF(D38=0, ,(D37-D38))) -> 0 | G37: =IF(AC37>0,((F37-X37)+(Y37-F38)),IF(F38=0, ,(F37-F38))) -> 0 | I37: =IF(AC37>0,((H37-AA37)+(AB37-H38)),IF(H38=0, ,(H37-H38))) -> 0 | J37: =B37+D37+F37+H37 -> 0 | K37: =J37/4 -> 0 | L37: =IF(AC37>0,((K37-AD37)+(AE37-K38)),IF(K38=0, ,(K37-K38))) -> 0 | M37: =7000*4 -> 28000 | N37: =L37*M37/100 -> 0 | O37: =N37*0.53 -> 0 | P37: =O37*8.2658 -> 0 | AC37: =Q37+T37+W37+Z37 -> 0 | AD37: =(R37+U37+X37+AA37)/4 -> 0 | AE37: =(S37+V37+Y37+AB37)/4 -> 0
A38: =(A37+1) -> 44224 | C38: =IF(AC38>0,((B38-R38)+(S38-B39)),IF(B39=0, ,(B38-B39))) -> 0 | E38: =IF(AC38>0,((D38-U38)+(V38-D39)),IF(D39=0, ,(D38-D39))) -> 0 | G38: =IF(AC38>0,((F38-X38)+(Y38-F39)),IF(F39=0, ,(F38-F39))) -> 0 | I38: =IF(AC38>0,((H38-AA38)+(AB38-H39)),IF(H39=0, ,(H38-H39))) -> 0 | J38: =B38+D38+F38+H38 -> 0 | K38: =J38/4 -> 0 | L38: =IF(AC38>0,((K38-AD38)+(AE38-K39)),IF(K39=0, ,(K38-K39))) -> 0 | M38: =7000*4 -> 28000 | N38: =L38*M38/100 -> 0 | O38: =N38*0.53 -> 0 | P38: =O38*8.2658 -> 0 | AC38: =Q38+T38+W38+Z38 -> 0 | AD38: =(R38+U38+X38+AA38)/4 -> 0 | AE38: =(S38+V38+Y38+AB38)/4 -> 0
A39: =(A38+1) -> 44225 | C39: =IF(AC39>0,((B39-R39)+(S39-B40)),IF(B40=0, ,(B39-B40))) -> 0 | E39: =IF(AC39>0,((D39-U39)+(V39-D40)),IF(D40=0, ,(D39-D40))) -> 0 | G39: =IF(AC39>0,((F39-X39)+(Y39-F40)),IF(F40=0, ,(F39-F40))) -> 0 | I39: =IF(AC39>0,((H39-AA39)+(AB39-H40)),IF(H40=0, ,(H39-H40))) -> 0 | J39: =B39+D39+F39+H39 -> 0 | K39: =J39/4 -> 0 | L39: =IF(AC39>0,((K39-AD39)+(AE39-K40)),IF(K40=0, ,(K39-K40))) -> 0 | M39: =7000*4 -> 28000 | N39: =L39*M39/100 -> 0 | O39: =N39*0.53 -> 0 | P39: =O39*8.2658 -> 0 | AC39: =Q39+T39+W39+Z39 -> 0 | AD39: =(R39+U39+X39+AA39)/4 -> 0 | AE39: =(S39+V39+Y39+AB39)/4 -> 0
A40: =(A39+1) -> 44226 | C40: =IF(AC40>0,((B40-R40)+(S40-B41)),IF(B41=0, ,(B40-B41))) -> 0 | E40: =IF(AC40>0,((D40-U40)+(V40-D41)),IF(D41=0, ,(D40-D41))) -> 0 | G40: =IF(AC40>0,((F40-X40)+(Y40-F41)),IF(F41=0, ,(F40-F41))) -> 0 | I40: =IF(AC40>0,((H40-AA40)+(AB40-H41)),IF(H41=0, ,(H40-H41))) -> 0 | J40: =B40+D40+F40+H40 -> 0 | K40: =J40/4 -> 0 | L40: =IF(AC40>0,((K40-AD40)+(AE40-K41)),IF(K41=0, ,(K40-K41))) -> 0 | M40: =7000*4 -> 28000 | N40: =L40*M40/100 -> 0 | O40: =N40*0.53 -> 0 | P40: =O40*8.2658 -> 0 | AC40: =Q40+T40+W40+Z40 -> 0 | AD40: =(R40+U40+X40+AA40)/4 -> 0 | AE40: =(S40+V40+Y40+AB40)/4 -> 0
...

Sheet Suivi EAU-ELEC
C1: Suivi Compteur d'Eau- électricité RADEEMA -
D5: =SUM(C16:C45) -> 5680
A7: Date | B7: Eau m3 | D7: Electricité Kw/h
B8: Compteur | C8: Consommation | D8: Compteur H.Creuse | E8: Consommation H.Creuse | F8: Compteur H.Pleine | G8: Consommation H.Pleine | H8: Compteur H.Pointe | I8: Consommation H.Pointe
A9: 44190 | B9: 127434 | C9: =IF(B10<B9,0,B10-B9)*10 -> 260 | D9: 18903346 | E9: =IF(D10<D9,0,D10-D9) -> 2868 | F9: 33872112 | G9: =IF(F10<F9,0,F10-F9) -> 5367 | H9: 15005105 | I9: =IF(H10<H9,0,H10-H9) -> 2446
A10: =(A9+1) -> 44191 | B10: 127460 | C10: =IF(B11<B10,0,B11-B10)*10 -> 310 | D10: 18906214 | E10: =IF(D11<D10,0,D11-D10) -> 3629 | F10: 33877479 | G10: =IF(F11<F10,0,F11-F10) -> 5617 | H10: 15007551 | I10: =IF(H11<H10,0,H11-H10) -> 2485
A11: =(A10+1) -> 44192 | B11: 127491 | C11: =IF(B12<B11,0,B12-B11)*10 -> 320 | D11: 18909843 | E11: =IF(D12<D11,0,D12-D11) -> 3365 | F11: 33883096 | G11: =IF(F12<F11,0,F12-F11) -> 5447 | H11: 15010036 | I11: =IF(H12<H11,0,H12-H11) -> 2497
A12: =(A11+1) -> 44193 | B12: 127523 | C12: =IF(B13<B12,0,B13-B12)*10 -> 370 | D12: 18913208 | E12: =IF(D13<D12,0,D13-D12) -> 3678 | F12: 33888543 | G12: =IF(F13<F12,0,F13-F12) -> 5499 | H12: 15012533 | I12: =IF(H13<H12,0,H13-H12) -> 2576
A13: =(A12+1) -> 44194 | B13: 127560 | C13: =IF(B14<B13,0,B14-B13)*10 -> 300 | D13: 18916886 | E13: =IF(D14<D13,0,D14-D13) -> 3691 | F13: 33894042 | G13: =IF(F14<F13,0,F14-F13) -> 5786 | H13: 15015109 | I13: =IF(H14<H13,0,H14-H13) -> 2455
A14: =(A13+1) -> 44195 | B14: 127590 | C14: =IF(B15<B14,0,B15-B14)*10 -> 300 | D14: 18920577 | E14: =IF(D15<D14,0,D15-D14) -> 3525 | F14: 33899828 | G14: =IF(F15<F14,0,F15-F14) -> 5908 | H14: 15017564 | I14: =IF(H15<H14,0,H15-H14) -> 2562
A15: =(A14+1) -> 44196 | B15: 127620 | C15: =IF(B16<B15,0,B16-B15)*10 -> 370 | D15: 18924102 | E15: =IF(D16<D15,0,D16-D15) -> 3616 | F15: 33905736 | G15: =IF(F16<F15,0,F16-F15) -> 5610 | H15: 15020126 | I15: =IF(H16<H15,0,H16-H15) -> 2487
A16: =(A15+1) -> 44197 | B16: 127657 | C16: =IF(B17<B16,0,B17-B16)*10 -> 390 | D16: 18927718 | E16: =IF(D17<D16,0,D17-D16) -> 3405 | F16: 33911346 | G16: =IF(F17<F16,0,F17-F16) -> 5810 | H16: 15022613 | I16: =IF(H17<H16,0,H17-H16) -> 2460
A17: =(A16+1) -> 44198 | B17: 127696 | C17: =IF(B18<B17,0,B18-B17)*10 -> 330 | D17: 18931123 | E17: =IF(D18<D17,0,D18-D17) -> 3413 | F17: 33917156 | G17: =IF(F18<F17,0,F18-F17) -> 5222 | H17: 15025073 | I17: =IF(H18<H17,0,H18-H17) -> 2408
A18: =(A17+1) -> 44199 | B18: 127729 | C18: =IF(B19<B18,0,B19-B18)*10 -> 280 | D18: 18934536 | E18: =IF(D19<D18,0,D19-D18) -> 3457 | F18: 33922378 | G18: =IF(F19<F18,0,F19-F18) -> 5248 | H18: 15027481 | I18: =IF(H19<H18,0,H19-H18) -> 2305
A19: =(A18+1) -> 44200 | B19: 127757 | C19: =IF(B20<B19,0,B20-B19)*10 -> 230 | D19: 18937993 | E19: =IF(D20<D19,0,D20-D19) -> 3741 | F19: 33927626 | G19: =IF(F20<F19,0,F20-F19) -> 5189 | H19: 15029786 | I19: =IF(H20<H19,0,H20-H19) -> 2172
A20: =(A19+1) -> 44201 | B20: 127780 | C20: =IF(B21<B20,0,B21-B20)*10 -> 250 | D20: 18941734 | E20: =IF(D21<D20,0,D21-D20) -> 3319 | F20: 33932815 | G20: =IF(F21<F20,0,F21-F20) -> 5047 | H20: 15031958 | I20: =IF(H21<H20,0,H21-H20) -> 2125
A21: =(A20+1) -> 44202 | B21: 127805 | C21: =IF(B22<B21,0,B22-B21)*10 -> 270 | D21: 18945053 | E21: =IF(D22<D21,0,D22-D21) -> 3396 | F21: 33937862 | G21: =IF(F22<F21,0,F22-F21) -> 5062 | H21: 15034083 | I21: =IF(H22<H21,0,H22-H21) -> 2105
... A33: =(A32+1) -> 44214 | B33: 128225 | C33: =IF(B34<B33,0,B34-B33)*10 -> 0 | D33: 18982141 | E33: =IF(D34<D33,0,D34-D33) -> 0 | F33: 33995906 | G33: =IF(F34<F33,0,F34-F33) -> 0 | H33: 15058707 | I33: =IF(H34<H33,0,H34-H33) -> 0
A34: =(A33+1) -> 44215 | C34: =IF(B35<B34,0,B35-B34)*10 -> 0 | E34: =IF(D35<D34,0,D35-D34) -> 0 | G34: =IF(F35<F34,0,F35-F34) -> 0 | I34: =IF(H35<H34,0,H35-H34) -> 0
A35: =(A34+1) -> 44216 | C35: =IF(B36<B35,0,B36-B35)*10 -> 0 | E35: =IF(D36<D35,0,D36-D35) -> 0 | G35: =IF(F36<F35,0,F36-F35) -> 0 | I35: =IF(H36<H35,0,H36-H35) -> 0
A36: =(A35+1) -> 44217 | C36: =IF(B37<B36,0,B37-B36)*10 -> 0 | E36: =IF(D37<D36,0,D37-D36) -> 0 | G36: =IF(F37<F36,0,F37-F36) -> 0 | I36: =IF(H37<H36,0,H37-H36) -> 0
A37: =(A36+1) -> 44218 | C37: =IF(B38<B37,0,B38-B37)*10 -> 0 | E37: =IF(D38<D37,0,D38-D37) -> 0 | G37: =IF(F38<F37,0,F38-F37) -> 0 | I37: =IF(H38<H37,0,H38-H37) -> 0
A38: =(A37+1) -> 44219 | C38: =IF(B39<B38,0,B39-B38)*10 -> 0 | E38: =IF(D39<D38,0,D39-D38) -> 0 | G38: =IF(F39<F38,0,F39-F38) -> 0 | I38: =IF(H39<H38,0,H39-H38) -> 0
A39: =(A38+1) -> 44220 | C39: =IF(B40<B39,0,B40-B39)*10 -> 0 | E39: =IF(D40<D39,0,D40-D39) -> 0 | G39: =IF(F40<F39,0,F40-F39) -> 0 | I39: =IF(H40<H39,0,H40-H39) -> 0
A40: =(A39+1) -> 44221 | C40: =IF(B41<B40,0,B41-B40)*10 -> 0 | E40: =IF(D41<D40,0,D41-D40) -> 0 | G40: =IF(F41<F40,0,F41-F40) -> 0 | I40: =IF(H41<H40,0,H41-H40) -> 0
A41: =(A40+1) -> 44222 | C41: =IF(B42<B41,0,B42-B41)*10 -> 0 | E41: =IF(D42<D41,0,D42-D41) -> 0 | G41: =IF(F42<F41,0,F42-F41) -> 0 | I41: =IF(H42<H41,0,H42-H41) -> 0
A42: =(A41+1) -> 44223 | C42: =IF(B43<B42,0,B43-B42)*10 -> 0 | E42: =IF(D43<D42,0,D43-D42) -> 0 | G42: =IF(F43<F42,0,F43-F42) -> 0 | I42: =IF(H43<H42,0,H43-H42) -> 0
A43: =(A42+1) -> 44224 | C43: =IF(B44<B43,0,B44-B43)*10 -> 0 | E43: =IF(D44<D43,0,D44-D43) -> 0 | G43: =IF(F44<F43,0,F44-F43) -> 0 | I43: =IF(H44<H43,0,H44-H43) -> 0
A44: =(A43+1) -> 44225 | C44: =IF(B45<B44,0,B45-B44)*10 -> 0 | E44: =IF(D45<D44,0,D45-D44) -> 0 | G44: =IF(F45<F44,0,F45-F44) -> 0 | I44: =IF(H45<H44,0,H45-H44) -> 0
A45: =(A44+1) -> 44226 | C45: =IF(B46<B45,0,B46-B45)*10 -> 0 | E45: =IF(D46<D45,0,D46-D45) -> 0 | G45: =IF(F46<F45,0,F46-F45) -> 0 | I45: =IF(H46<H45,0,H46-H45) -> 0
... A47: =(A46+1) -> 44228 | C47: =IF(B48<B47,0,B48-B47)*10 -> 0 | E47: =IF(D48<D47,0,D48-D47) -> 0 | G47: =IF(F48<F47,0,F48-F47) -> 0 | I47: =IF(H48<H47,0,H48-H47) -> 0
C48: =SUM(C16:C46) -> 5680 | E48: =SUM(E16:E46) -> 54423 | G48: =SUM(G16:G46) -> 84560 | I48: =SUM(I16:I46) -> 36094

Sheet Feuil1
