Workbook

Sheet TOTAL
A1: Site Name | B1: Day | C1: Month | D1: Year | E1: Total Electricity Kwh | F1: Electricity Tariff ($/Kwh) | G1: Natual Gas (m3) | H1: Natural Gas $/m3 | I1: Water Utility Supply (m3) m3 | J1: Water Utility Supply (m3) $/m3 | K1: Room Nights | L1: Total Guests | M1: Utilities day cost dh
A2: Mumbai | B2: 1 | C2: 1 | D2: 2021 | E2: ='Daily HLP'!I4 -> 20215 | F2: ='Daily HLP'!J4 -> 9 | G2: ='Daily HLP'!M4 -> 693.9 | H2: ='Daily HLP'!N4 -> 35 | I2: ='Daily HLP'!P4 -> 197 | J2: ='Daily HLP'!Q4 -> 134 | K2: =SUM(G2:H2) -> 728.9 | L2: ='[1]Consommation mensuel énergie'!E10 -> 0 | M2: =E2*F2+G2*H2+#REF!*#REF!+I2*J2 -> #REF!
A3: Mumbai | B3: =B2+1 -> 2 | C3: 1 | D3: 2021 | E3: ='Daily HLP'!I5 -> 19576 | F3: =F2 -> 9 | G3: ='Daily HLP'!M5 -> 822.62 | H3: =H2 -> 35 | I3: ='Daily HLP'!P5 -> 175 | J3: =J2 -> 134 | K3: =SUM(G3:H3) -> 857.62 | L3: ='[1]Consommation mensuel énergie'!E11 -> 0 | M3: =E3*F3+G3*H3+#REF!*#REF!+I3*J3 -> #REF!
A4: Mumbai | B4: =B3+1 -> 3 | C4: 1 | D4: 2021 | E4: ='Daily HLP'!I6 -> 19258 | F4: =F3 -> 9 | G4: ='Daily HLP'!M6 -> 815.69 | H4: =H3 -> 35 | I4: ='Daily HLP'!P6 -> 167 | J4: =J3 -> 134 | K4: =SUM(G4:H4) -> 850.69 | L4: ='[1]Consommation mensuel énergie'!E12 -> 0 | M4: =E4*F4+G4*H4+#REF!*#REF!+I4*J4 -> #REF!
A5: Mumbai | B5: =B4+1 -> 4 | C5: 1 | D5: 2021 | E5: ='Daily HLP'!I7 -> 18476 | F5: =F4 -> 9 | G5: ='Daily HLP'!M7 -> 757.69 | H5: =H4 -> 35 | I5: ='Daily HLP'!P7 -> 153 | J5: =J4 -> 134 | K5: 0 | L5: ='[1]Consommation mensuel énergie'!E13 -> 0 | M5: =E5*F5+G5*H5+#REF!*#REF!+I5*J5 -> #REF!
A6: Mumbai | B6: =B5+1 -> 5 | C6: 1 | D6: 2021 | E6: ='Daily HLP'!I8 -> 17831 | F6: =F5 -> 9 | G6: ='Daily HLP'!M8 -> 526 | H6: =H5 -> 35 | I6: ='Daily HLP'!P8 -> 132 | J6: =J5 -> 134 | K6: 0 | L6: ='[1]Consommation mensuel énergie'!E14 -> 0 | M6: =E6*F6+G6*H6+#REF!*#REF!+I6*J6 -> #REF!
A7: Mumbai | B7: =B6+1 -> 6 | C7: 1 | D7: 2021 | E7: ='Daily HLP'!I9 -> 17839 | F7: =F6 -> 9 | G7: ='Daily HLP'!M9 -> 694.7 | H7: =H6 -> 35 | I7: ='Daily HLP'!P9 -> 118 | J7: =J6 -> 134 | K7: 0 | L7: ='[1]Consommation mensuel énergie'!E15 -> 0 | M7: =E7*F7+G7*H7+#REF!*#REF!+I7*J7 -> #REF!
A8: Mumbai | B8: =B7+1 -> 7 | C8: 1 | D8: 2021 | E8: ='Daily HLP'!I10 -> 17899 | F8: =F7 -> 9 | G8: ='Daily HLP'!M10 -> 621.3 | H8: =H7 -> 35 | I8: ='Daily HLP'!P10 -> 122 | J8: =J7 -> 134 | K8: 117 | L8: ='[1]Consommation mensuel énergie'!E16 -> 0 | M8: =E8*F8+G8*H8+#REF!*#REF!+I8*J8 -> #REF!
A9: Mumbai | B9: =B8+1 -> 8 | C9: 1 | D9: 2021 | E9: ='Daily HLP'!I11 -> 18873 | F9: =F8 -> 9 | G9: ='Daily HLP'!M11 -> 752 | H9: =H8 -> 35 | I9: ='Daily HLP'!P11 -> 128 | J9: =J8 -> 134 | K9: 117 | L9: ='[1]Consommation mensuel énergie'!E17 -> 0 | M9: =E9*F9+G9*H9+#REF!*#REF!+I9*J9 -> #REF!
A10: Mumbai | B10: =B9+1 -> 9 | C10: 1 | D10: 2021 | E10: ='Daily HLP'!I12 -> 18833 | F10: =F9 -> 9 | G10: ='Daily HLP'!M12 -> 759 | H10: =H9 -> 35 | I10: ='Daily HLP'!P12 -> 157 | J10: =J9 -> 134 | K10: 117 | L10: ='[1]Consommation mensuel énergie'!E18 -> 0 | M10: =E10*F10+G10*H10+#REF!*#REF!+I10*J10 -> #REF!
A11: Mumbai | B11: =B10+1 -> 10 | C11: 1 | D11: 2021 | E11: ='Daily HLP'!I13 -> 20209 | F11: =F10 -> 9 | G11: ='Daily HLP'!M13 -> 776 | H11: =H10 -> 35 | I11: ='Daily HLP'!P13 -> 141 | J11: =J10 -> 134 | K11: 182 | L11: ='[1]Consommation mensuel énergie'!E19 -> 0 | M11: =E11*F11+G11*H11+#REF!*#REF!+I11*J11 -> #REF!
A12: Mumbai | B12: =B11+1 -> 11 | C12: 1 | D12: 2021 | E12: ='Daily HLP'!I14 -> 20389 | F12: =F11 -> 9 | G12: ='Daily HLP'!M14 -> 919.052 | H12: =H11 -> 35 | I12: ='Daily HLP'!P14 -> 194 | J12: =J11 -> 134 | K12: 181 | L12: ='[1]Consommation mensuel énergie'!E20 -> 0 | M12: =E12*F12+G12*H12+#REF!*#REF!+I12*J12 -> #REF!
A13: Mumbai | B13: =B12+1 -> 12 | C13: 1 | D13: 2021 | E13: ='Daily HLP'!I15 -> 20105 | F13: =F12 -> 9 | G13: ='Daily HLP'!M15 -> 954.904 | H13: =H12 -> 35 | I13: ='Daily HLP'!P15 -> 152 | J13: =J12 -> 134 | K13: 169 | L13: ='[1]Consommation mensuel énergie'!E21 -> 0 | M13: =E13*F13+G13*H13+#REF!*#REF!+I13*J13 -> #REF!
A14: Mumbai | B14: =B13+1 -> 13 | C14: 1 | D14: 2021 | E14: ='Daily HLP'!I16 -> 20850 | F14: =F13 -> 9 | G14: ='Daily HLP'!M16 -> 902.523 | H14: =H13 -> 35 | I14: ='Daily HLP'!P16 -> 174 | J14: =J13 -> 134 | K14: 174 | L14: ='[1]Consommation mensuel énergie'!E22 -> 0 | M14: =E14*F14+G14*H14+#REF!*#REF!+I14*J14 -> #REF!
A15: Mumbai | B15: =B14+1 -> 14 | C15: 1 | D15: 2021 | E15: ='Daily HLP'!I17 -> 19342 | F15: =F14 -> 9 | G15: ='Daily HLP'!M17 -> 854.403 | H15: =H14 -> 35 | I15: ='Daily HLP'!P17 -> 151 | J15: =J14 -> 134 | K15: 148 | L15: ='[1]Consommation mensuel énergie'!E23 -> 0 | M15: =E15*F15+G15*H15+#REF!*#REF!+I15*J15 -> #REF!
A16: Mumbai | B16: =B15+1 -> 15 | C16: 1 | D16: 2021 | E16: ='Daily HLP'!I18 -> 20815 | F16: =F15 -> 9 | G16: ='Daily HLP'!M18 -> 920.068 | H16: =H15 -> 35 | I16: ='Daily HLP'!P18 -> 173 | J16: =J15 -> 134 | K16: 148 | L16: ='[1]Consommation mensuel énergie'!E24 -> 0 | M16: =E16*F16+G16*H16+#REF!*#REF!+I16*J16 -> #REF!
... A19: Mumbai | B19: =B18+1 -> 18 | C19: 1 | D19: 2021 | E19: ='Daily HLP'!I21 -> 20163 | F19: =F18 -> 9 | G19: ='Daily HLP'!M21 -> 944.776 | H19: =H18 -> 35 | I19: ='Daily HLP'!P21 -> 192 | J19: =J18 -> 134 | K19: 197 | L19: ='[1]Consommation mensuel énergie'!E27 -> 0 | M19: =E19*F19+G19*H19+#REF!*#REF!+I19*J19 -> #REF!
A20: Mumbai | B20: =B19+1 -> 19 | C20: 1 | D20: 2021 | E20: ='Daily HLP'!I22 -> 19963 | F20: =F19 -> 9 | G20: ='Daily HLP'!M22 -> 914.15 | H20: =H19 -> 35 | I20: ='Daily HLP'!P22 -> 172 | J20: =J19 -> 134 | K20: 166 | L20: 283 | M20: =E20*F20+G20*H20+#REF!*#REF!+I20*J20 -> #REF!
A21: Mumbai | B21: =B20+1 -> 20 | C21: 1 | D21: 2021 | E21: ='Daily HLP'!I23 -> 19855 | F21: =F20 -> 9 | G21: ='Daily HLP'!M23 -> 930.07 | H21: =H20 -> 35 | I21: ='Daily HLP'!P23 -> 190 | J21: =J20 -> 134 | K21: 168 | L21: 333 | M21: =E21*F21+G21*H21+#REF!*#REF!+I21*J21 -> #REF!
A22: Mumbai | B22: =B21+1 -> 21 | C22: 1 | D22: 2021 | E22: ='Daily HLP'!I24 -> 19415 | F22: =F21 -> 9 | G22: ='Daily HLP'!M24 -> 906.94 | H22: =H21 -> 35 | I22: ='Daily HLP'!P24 -> 179 | J22: =J21 -> 134 | K22: 159 | L22: 324 | M22: =E22*F22+G22*H22+#REF!*#REF!+I22*J22 -> #REF!
A23: Mumbai | B23: =B22+1 -> 22 | C23: 1 | D23: 2021 | E23: ='Daily HLP'!I25 -> 19510 | F23: =F22 -> 9 | G23: ='Daily HLP'!M25 -> 904 | H23: =H22 -> 35 | I23: ='Daily HLP'!P25 -> 177 | J23: =J22 -> 134 | K23: 147 | L23: 381 | M23: =E23*F23+G23*H23+#REF!*#REF!+I23*J23 -> #REF!
A24: Mumbai | B24: =B23+1 -> 23 | C24: 1 | D24: 2021 | E24: ='Daily HLP'!I26 -> 19709 | F24: =F23 -> 9 | G24: ='Daily HLP'!M26 -> 934.94 | H24: =H23 -> 35 | I24: ='Daily HLP'!P26 -> 203 | J24: =J23 -> 134 | K24: 178 | L24: 592 | M24: =E24*F24+G24*H24+#REF!*#REF!+I24*J24 -> #REF!
A25: Mumbai | B25: =B24+1 -> 24 | C25: 1 | D25: 2021 | E25: ='Daily HLP'!I27 -> 19391 | F25: =F24 -> 9 | G25: ='Daily HLP'!M27 -> 748.12 | H25: =H24 -> 35 | I25: ='Daily HLP'!P27 -> 190 | J25: =J24 -> 134 | K25: 197 | L25: 412 | M25: =E25*F25+G25*H25+#REF!*#REF!+I25*J25 -> #REF!
A26: Mumbai | B26: =B25+1 -> 25 | C26: 1 | D26: 2021 | E26: ='Daily HLP'!I28 -> 19169 | F26: =F25 -> 9 | G26: ='Daily HLP'!M28 -> 930.86 | H26: =H25 -> 35 | I26: ='Daily HLP'!P28 -> 183 | J26: =J25 -> 134 | K26: 116 | L26: 524 | M26: =E26*F26+G26*H26+#REF!*#REF!+I26*J26 -> #REF!
A27: Mumbai | B27: =B26+1 -> 26 | C27: 1 | D27: 2021 | E27: ='Daily HLP'!I29 -> 18998 | F27: =F26 -> 9 | G27: ='Daily HLP'!M29 -> 855.14 | H27: =H26 -> 35 | I27: ='Daily HLP'!P29 -> 189 | J27: =J26 -> 134 | K27: 128 | L27: 354 | M27: =E27*F27+G27*H27+#REF!*#REF!+I27*J27 -> #REF!
A28: Mumbai | B28: =B27+1 -> 27 | C28: 1 | D28: 2021 | E28: ='Daily HLP'!I30 -> 18736 | F28: =F27 -> 9 | G28: ='Daily HLP'!M30 -> 843.94 | H28: =H27 -> 35 | I28: ='Daily HLP'!P30 -> 174 | J28: =J27 -> 134 | K28: 86 | L28: 249 | M28: =E28*F28+G28*H28+#REF!*#REF!+I28*J28 -> #REF!
A29: Mumbai | B29: =B28+1 -> 28 | C29: 1 | D29: 2021 | E29: ='Daily HLP'!I31 -> 19357 | F29: =F28 -> 9 | G29: ='Daily HLP'!M31 -> 434.06 | H29: =H28 -> 35 | I29: ='Daily HLP'!P31 -> 173 | J29: =J28 -> 134 | K29: 96 | L29: 325 | M29: =E29*F29+G29*H29+#REF!*#REF!+I29*J29 -> #REF!
A30: Mumbai | B30: =B29+1 -> 29 | C30: 1 | D30: 2021 | E30: ='Daily HLP'!I32 -> 18748 | F30: =F29 -> 9 | G30: ='Daily HLP'!M32 -> 826.97 | H30: =H29 -> 35 | I30: ='Daily HLP'!P32 -> 151 | J30: =J29 -> 134 | K30: 102 | L30: 423 | M30: =E30*F30+G30*H30+#REF!*#REF!+I30*J30 -> #REF!
A31: Mumbai | B31: =B30+1 -> 30 | C31: 1 | D31: 2021 | E31: ='Daily HLP'!I33 -> -2314382 | F31: =F30 -> 9 | G31: ='Daily HLP'!M33 -> -77642.192 | H31: =H30 -> 35 | I31: ='Daily HLP'!P33 -> -6373 | J31: =J30 -> 134 | K31: 125 | L31: ='[1]Consommation mensuel énergie'!E39 -> 0 | M31: =E31*F31+G31*H31+#REF!*#REF!+I31*J31 -> #REF!

Sheet Daily HLP
A2: Date | B2: Date | C2: Min.Tem (Degee) | D2: Avg.Temp (Degree) | E2: Hum % | F2: Occu. | G2: KWAH | I2: Electricity | M2: Gas | P2: Water | S2: Water per occiped room | T2: Diesel | W2: Water Consumption Zone | AA2: Chiller Running Hrs | AF2: Chiller Total | AG2: Chiller Avg. Laod | AH2: Boiler Running Hrs | AK2: Total boiler | AL2: Hot Water Generator | AO2: Total HWG RH | AP2: HWG Gas consumption | AQ2: Transformer -1 | BA2: Transformer -2 | BO2: Total HLP Cost | BQ2: Chiller lock at 70%
F3: % | H3: KVAH | I3: Units (Kwh) | J3: Rate | K3: Total Cost(Rs) | L3: Per room | M3: Total Units(CuM) | N3: Rate | O3: Total Cost(Rs) | P3: Units(KL) | Q3: Rate | R3: Total Cost(Rs) | T3: Ltrs | U3: Rate | V3: Total Cost(Rs) | W3: Zone-1 | X3: Zone-2 | Y3: Zone-3 | AA3: CH1 | AB3: CH2 | AC3: CH3 | AD3: CH4 | AE3: Total chiller | AH3: Boiler1 | AI3: Boiler2 | AJ3: Boiler3 | AL3: HWG1 | AM3: HWG2 | AQ3: HVAC-1 | AR3: FPP-1 | AS3: MPP | AT3: Lighting-1 | AU3: Cap bank 1100KVAR-1 | AV3: CH-1 | AW3: CH-2 | AX3: Chilled water Pump | AY3: Co Generator | AZ3: Ball Room-2 | BA3: HVAC-2 | BB3: FPP-2 | BC3: MPP | BD3: Lighting-2 | BE3: Cap bank 1200KVAR-2 | BF3: CH-3 | BG3: CH-4 | BH3: Chilled water Pump | BI3: Ball Room-1 | BK3: Cooling Tower consumption | BL3: HVAC% | BM3: Lighting% | BN3: Power% | BP3: Chiller Plant IKW
A4: 1 | B4: 1 | D4: ='1'!D3 -> 31 | E4: ='1'!D4 -> 0.72 | F4: ='1'!D2 -> 0.43 | G4: ='1'!G8 -> 20383 | H4: ='1'!G8 -> 20383 | I4: ='1'!G7 -> 20215 | J4: ='1'!F27 -> 9 | K4: =H4*J4 -> 183447 | L4: =I4/202 -> 100.07426 | M4: ='1'!G15 -> 693.9 | N4: 35 | O4: =M4*N4 -> 24286.5 | P4: ='1'!G20 -> 197 | Q4: 134 | R4: =P4*Q4 -> 26398 | S4: =P4/(F4*202/100) -> 226.80175 | T4: ='1'!G24 -> 0 | U4: 69 | V4: =T4*U4 -> 0 | W4: ='1'!G95 -> 60 | X4: ='1'!G96 -> 33 | Y4: ='1'!G97 -> 37 | Z4: =W4+X4+Y4 -> 130 | AA4: ='1'!G132 -> 0 | AB4: ='1'!G133 -> 0 | AC4: ='1'!G134 -> 0 | AD4: ='1'!G135 -> 23.61 | AE4: =AA4+AB4+AC4+AD4 -> 23.61 | AF4: =AV4+AW4+BF4+BG4 -> 5051.9 | AG4: =AF4/AE4 -> 213.97289 | AH4: ='1'!G136 -> 2.15 | AI4: ='1'!G137 -> 0 | AJ4: ='1'!G138 -> 5.36 | AK4: =AH4+AI4+AJ4 -> 7.51 | AL4: ='1'!G139 -> 0 | AM4: ='1'!G140 -> 9.75 | AO4: =AL4+AM4 -> 9.75 | AP4: ='1'!G123 -> 293.95 | AQ4: ='1'!G35 -> 0 | AR4: ='1'!G37 -> 0 | AS4: ='1'!G38 -> 0 | AT4: ='1'!G39 -> 0 | AU4: ='1'!G40 -> 0 | AV4: ='1'!G41 -> 0.02 | AW4: ='1'!G42 -> 0 | AX4: ='1'!G43 -> 1964.57 | AY4: ='1'!G44 -> 0 | AZ4: ='1'!G36 -> 693.93 | BA4: ='1'!G49 -> 2937 | BB4: ='1'!G51 -> 1471.89 | BC4: ='1'!G52 -> 2161.37 | BD4: ='1'!G53 -> 4286.03 | BE4: ='1'!G54 -> 62.46 | BF4: ='1'!G55 -> -0.37 | BG4: ='1'!G56 -> 5052.25 | BH4: ='1'!G57 -> 0 | BI4: ='1'!G50 -> 1013.57 | BJ4: =SUM(AV4,AW4,BF4,BG4) -> 5051.9 | BK4: ='1'!G84 -> 446 | BL4: =SUM(AQ4,AV4,AW4,AX4,BA4,BF4,BG4,BH4)/I4% -> 49.238041 | BM4: =SUM(AT4,BD4)/I4% -> 21.202226 | BN4: =(AS4+BC4)/I4 -> 0.10691912 | BO4: =K4+O4+R4+V4 -> 234131.5 | BP4: =SUM(AV4,AW4,AX4,BF4,BG4,BH4,BK4) -> 7462.47 | BQ4: =BP4/(AE4*280) -> 1.1288301 | BR4: =SUM(AV4,AW4,BF4,BG4)/(AE4*400) -> 0.53493223
A5: 2 | B5: 2 | D5: ='2'!D3 -> 27 | E5: ='2'!D4 -> 0.74 | F5: ='2'!D2 -> 0.54 | G5: ='2'!G8 -> 19732 | H5: ='2'!G8 -> 19732 | I5: ='2'!G7 -> 19576 | J5: 10 | K5: =H5*J5 -> 197320 | L5: =I5/202 -> 96.910891 | M5: ='2'!G15 -> 822.62 | N5: 35 | O5: =M5*N5 -> 28791.7 | P5: ='2'!G20 -> 175 | Q5: 134 | R5: =P5*Q5 -> 23450 | S5: =P5/(F5*202/100) -> 160.43271 | T5: ='2'!G24 -> 0 | U5: 69 | V5: =T5*U5 -> 0 | W5: ='2'!G95 -> 71 | X5: ='2'!G96 -> 16 | Y5: ='2'!G97 -> 23 | Z5: =W5+X5+Y5 -> 110 | AA5: ='2'!G132 -> 0 | AB5: ='2'!G133 -> 0 | AC5: ='2'!G134 -> 0 | AD5: ='2'!G135 -> 24.47 | AE5: =AA5+AB5+AC5+AD5 -> 24.47 | AF5: =AV5+AW5+BF5+BG5 -> 4714.86 | AG5: =AF5/AE5 -> 192.6792 | AH5: ='2'!G136 -> 7.01 | AI5: ='2'!G137 -> 0 | AJ5: ='2'!G138 -> 0 | AK5: =AH5+AI5+AJ5 -> 7.01 | AL5: ='2'!G139 -> 0 | AM5: ='2'!G140 -> 9.13 | AO5: =AL5+AM5 -> 9.13 | AP5: ='2'!G123 -> 276.39 | AQ5: ='2'!G35 -> 0 | AR5: ='2'!G37 -> 0 | AS5: ='2'!G38 -> 0 | AT5: ='2'!G39 -> 0 | AU5: ='2'!G40 -> 0 | AV5: ='2'!G41 -> -0.07 | AW5: ='2'!G42 -> 0 | AX5: ='2'!G43 -> 2000 | AY5: ='2'!G44 -> 0 | AZ5: ='2'!G36 -> 643.55 | BA5: ='2'!G49 -> 2838.81 | BB5: ='2'!G51 -> 1418 | BC5: ='2'!G52 -> 2047 | BD5: ='2'!G53 -> 4119 | BE5: ='2'!G54 -> 59.98 | BF5: ='2'!G55 -> 0.1 | BG5: ='2'!G56 -> 4714.83 | BH5: ='2'!G57 -> 0 | BI5: ='2'!G50 -> 977.51 | BJ5: =SUM(AV5,AW5,BF5,BG5) -> 4714.86 | BK5: ='2'!G84 -> 484 | BL5: =SUM(AQ5,AV5,AW5,AX5,BA5,BF5,BG5,BH5)/I5% -> 48.802973 | BM5: =SUM(AT5,BD5)/I5% -> 21.041071 | BN5: =(AS5+BC5)/I5 -> 0.10456682 | BO5: =K5+O5+R5+V5 -> 249561.7 | BP5: =SUM(AV5,AW5,AX5,BF5,BG5,BH5,BK5) -> 7198.86 | BQ5: =BP5/(AE5*280) -> 1.0506831
A6: 3 | B6: 3 | D6: ='3'!D3 -> 24 | E6: ='3'!D4 -> 0.76 | F6: ='3'!D2 -> 0.39 | G6: ='3'!G8 -> 19432 | H6: ='3'!G8 -> 19432 | I6: ='3'!G7 -> 19258 | J6: 10 | K6: =H6*J6 -> 194320 | L6: =I6/202 -> 95.336634 | M6: ='3'!G15 -> 815.69 | N6: 35 | O6: =M6*N6 -> 28549.15 | P6: ='3'!G20 -> 167 | Q6: 134 | R6: =P6*Q6 -> 22378 | S6: =P6/(F6*202/100) -> 211.98274 | T6: ='3'!G24 -> 0 | U6: 69 | V6: =T6*U6 -> 0 | W6: ='3'!G95 -> 60 | X6: ='3'!G96 -> 20 | Y6: ='3'!G97 -> 17 | Z6: =W6+X6+Y6 -> 97 | AA6: ='3'!G132 -> 0 | AB6: ='3'!G133 -> 0 | AC6: ='3'!G134 -> 0 | AD6: ='3'!G135 -> 23.85 | AE6: =AA6+AB6+AC6+AD6 -> 23.85 | AF6: =AV6+AW6+BF6+BG6 -> 4109.17 | AG6: =AF6/AE6 -> 172.29224 | AH6: ='3'!G136 -> 7.94 | AI6: ='3'!G137 -> 0 | AJ6: ='3'!G138 -> 0 | AK6: =AH6+AI6+AJ6 -> 7.94 | AL6: ='3'!G139 -> 0 | AM6: ='3'!G140 -> 7.93 | AO6: =AL6+AM6 -> 7.93 | AP6: ='3'!G123 -> 245.61 | AQ6: ='3'!G35 -> 0 | AR6: ='3'!G37 -> 0 | AS6: ='3'!G38 -> 0 | AT6: ='3'!G39 -> 0 | AU6: ='3'!G40 -> 0 | AV6: ='3'!G41 -> 0 | AW6: ='3'!G42 -> 0 | AX6: ='3'!G43 -> 2040.79 | AY6: ='3'!G44 -> 0 | AZ6: ='3'!G36 -> 597.26 | BA6: ='3'!G49 -> 2802.63 | BB6: ='3'!G51 -> 1376.59 | BC6: ='3'!G52 -> 2064 | BD6: ='3'!G53 -> 4158.79 | BE6: ='3'!G54 -> 59.02 | BF6: ='3'!G55 -> 0 | BG6: ='3'!G56 -> 4109.17 | BH6: ='3'!G57 -> 0 | BI6: ='3'!G50 -> 1334.16 | BJ6: =SUM(AV6,AW6,BF6,BG6) -> 4109.17 | BK6: ='3'!G84 -> 489 | BL6: =SUM(AQ6,AV6,AW6,AX6,BA6,BF6,BG6,BH6)/I6% -> 46.487641 | BM6: =SUM(AT6,BD6)/I6% -> 21.595129 | BN6: =(AS6+BC6)/I6 -> 0.10717624 | BO6: =K6+O6+R6+V6 -> 245247.15 | BP6: =SUM(AV6,AW6,AX6,BF6,BG6,BH6,BK6) -> 6638.96 | BQ6: =BP6/(AE6*280) -> 0.99415394
A7: 4 | B7: 4 | D7: ='4'!D3 -> 28 | E7: ='4'!D4 -> 0.8 | F7: ='4'!D2 -> 0.21 | G7: ='4'!G8 -> 18672 | H7: ='4'!G8 -> 18672 | I7: ='4'!G7 -> 18476 | J7: 10 | K7: =H7*J7 -> 186720 | L7: =I7/202 -> 91.465347 | M7: ='4'!G15 -> 757.69 | N7: 35 | O7: =M7*N7 -> 26519.15 | P7: ='4'!G20 -> 153 | Q7: 134 | R7: =P7*Q7 -> 20502 | S7: =P7/(F7*202/100) -> 360.67893 | T7: ='4'!G24 -> 0 | U7: 69 | V7: =T7*U7 -> 0 | W7: ='4'!G95 -> 68 | X7: ='4'!G96 -> 14 | Y7: ='4'!G97 -> 15 | Z7: =W7+X7+Y7 -> 97 | AA7: ='4'!G132 -> 0 | AB7: ='4'!G133 -> 0 | AC7: ='4'!G134 -> 0 | AD7: ='4'!G135 -> 24.14 | AE7: =AA7+AB7+AC7+AD7 -> 24.14 | AF7: =AV7+AW7+BF7+BG7 -> 4016.91 | AG7: =AF7/AE7 -> 166.40058 | AH7: ='4'!G136 -> 8.59 | AI7: ='4'!G137 -> 0 | AJ7: ='4'!G138 -> 0 | AK7: =AH7+AI7+AJ7 -> 8.59 | AL7: ='4'!G139 -> 0 | AM7: ='4'!G140 -> 7.66 | AO7: =AL7+AM7 -> 7.66 | AP7: ='4'!G123 -> 226.42 | AQ7: ='4'!G35 -> 0 | AR7: ='4'!G37 -> 0 | AS7: ='4'!G38 -> 0.38 | AT7: ='4'!G39 -> 0 | AU7: ='4'!G40 -> 0 | AV7: ='4'!G41 -> 0 | AW7: ='4'!G42 -> -0.09 | AX7: ='4'!G43 -> 1991.21 | AY7: ='4'!G44 -> 0 | AZ7: ='4'!G36 -> 635.19 | BA7: ='4'!G49 -> 2986.56 | BB7: ='4'!G51 -> 1381.41 | BC7: ='4'!G52 -> 1862 | BD7: ='4'!G53 -> 3898.21 | BE7: ='4'!G54 -> 57.52 | BF7: ='4'!G55 -> 0 | BG7: ='4'!G56 -> 4017 | BH7: ='4'!G57 -> 0 | BI7: ='4'!G50 -> 930.33 | BJ7: =SUM(AV7,AW7,BF7,BG7) -> 4016.91 | BK7: ='3'!G84 -> 489 | BL7: =SUM(AQ7,AV7,AW7,AX7,BA7,BF7,BG7,BH7)/I7% -> 48.683048 | BM7: =SUM(AT7,BD7)/I7% -> 21.098777 | BN7: =(AS7+BC7)/I7 -> 0.10079996 | BO7: =K7+O7+R7+V7 -> 233741.15 | BP7: =SUM(AV7,AW7,AX7,BF7,BG7,BH7,BK7) -> 6497.12 | BQ7: =BP7/(AE7*280) -> 0.96122618
A8: 5 | B8: 5 | D8: ='5'!D3 -> 22 | E8: ='5'!D4 -> 0.78 | F8: ='5'!D2 -> 0.23 | G8: ='5'!G8 -> 18082 | H8: ='5'!G8 -> 18082 | I8: ='5'!G7 -> 17831 | J8: 10 | K8: =H8*J8 -> 180820 | L8: =I8/202 -> 88.272277 | M8: ='5'!G15 -> 526 | N8: 35 | O8: =M8*N8 -> 18410 | P8: ='5'!G20 -> 132 | Q8: 134 | R8: =P8*Q8 -> 17688 | S8: =P8/(F8*202/100) -> 284.11537 | T8: ='5'!G24 -> 0 | U8: 69 | V8: =T8*U8 -> 0 | W8: ='5'!G95 -> 44 | X8: ='5'!G96 -> 18 | Y8: ='5'!G97 -> 15 | Z8: =W8+X8+Y8 -> 77 | AA8: ='5'!G132 -> 0 | AB8: ='5'!G133 -> 0 | AC8: ='5'!G134 -> 0 | AD8: ='5'!G135 -> 24.1 | AE8: =AA8+AB8+AC8+AD8 -> 24.1 | AF8: =AV8+AW8+BF8+BG8 -> 3520 | AG8: =AF8/AE8 -> 146.05809 | AH8: ='5'!G136 -> -0.39 | AI8: ='5'!G137 -> 0 | AJ8: ='5'!G138 -> 7.72 | AK8: =AH8+AI8+AJ8 -> 7.33 | AL8: ='5'!G139 -> 0 | AM8: ='5'!G140 -> 7.86 | AO8: =AL8+AM8 -> 7.86 | AP8: ='5'!G123 -> 238.07 | AQ8: ='5'!G35 -> 0 | AR8: ='5'!G37 -> 0 | AS8: ='5'!G38 -> 0 | AT8: ='5'!G39 -> 0 | AU8: ='5'!G40 -> 0 | AV8: ='5'!G41 -> 0 | AW8: ='5'!G42 -> 0 | AX8: ='5'!G43 -> 2032.87 | AY8: ='5'!G44 -> 0 | AZ8: ='5'!G36 -> 816.73 | BA8: ='5'!G49 -> 2800.66 | BB8: ='5'!G51 -> 1371.48 | BC8: ='5'!G52 -> 1884 | BD8: ='5'!G53 -> 3854 | BE8: ='5'!G54 -> 57.28 | BF8: ='5'!G55 -> 0 | BG8: ='5'!G56 -> 3520 | BH8: ='5'!G57 -> 0 | BI8: ='5'!G50 -> 956.67 | BJ8: =SUM(AV8,AW8,BF8,BG8) -> 3520 | BK8: ='5'!G84 -> 568 | BL8: =SUM(AQ8,AV8,AW8,AX8,BA8,BF8,BG8,BH8)/I8% -> 46.848354 | BM8: =SUM(AT8,BD8)/I8% -> 21.614043 | BN8: =(AS8+BC8)/I8 -> 0.10565868 | BO8: =K8+O8+R8+V8 -> 216918 | BP8: =SUM(AV8,AW8,AX8,BF8,BG8,BH8,BK8) -> 6120.87 | BQ8: =BP8/(AE8*280) -> 0.90706432
A9: 6 | B9: 6 | D9: ='6'!D3 -> 24 | E9: ='6'!D4 -> 0.72 | F9: ='6'!D2 -> 0.41 | G9: ='6'!G8 -> 18075 | H9: ='6'!G8 -> 18075 | I9: ='6'!G7 -> 17839 | J9: 10 | K9: =H9*J9 -> 180750 | L9: =I9/202 -> 88.311881 | M9: ='6'!G15 -> 694.7 | N9: 35 | O9: =M9*N9 -> 24314.5 | P9: ='6'!G20 -> 118 | Q9: 134 | R9: =P9*Q9 -> 15812 | S9: =P9/(F9*202/100) -> 142.47766 | T9: ='6'!G24 -> 0 | U9: 69 | V9: =T9*U9 -> 0 | W9: ='6'!G95 -> 57 | X9: ='6'!G96 -> 21 | Y9: ='6'!G97 -> 12 | Z9: =W9+X9+Y9 -> 90 | AA9: ='6'!G132 -> 0 | AB9: ='6'!G133 -> 0 | AC9: ='6'!G134 -> 0 | AD9: ='6'!G135 -> 24.47 | AE9: =AA9+AB9+AC9+AD9 -> 24.47 | AF9: =AV9+AW9+BF9+BG9 -> 3389 | AG9: =AF9/AE9 -> 138.49612 | AH9: ='6'!G136 -> 7.38 | AI9: ='6'!G137 -> 0 | AJ9: ='6'!G138 -> 0 | AK9: =AH9+AI9+AJ9 -> 7.38 | AL9: ='6'!G139 -> 0 | AM9: ='6'!G140 -> 6.59 | AO9: =AL9+AM9 -> 6.59 | AP9: ='6'!G123 -> 200.51 | AQ9: ='6'!G35 -> 0 | AR9: ='6'!G37 -> 0 | AS9: ='6'!G38 -> 0 | AT9: ='6'!G39 -> 0 | AU9: ='6'!G40 -> 0 | AV9: ='6'!G41 -> 0 | AW9: ='6'!G42 -> 0 | AX9: ='6'!G43 -> 2064.13 | AY9: ='6'!G44 -> 0 | AZ9: ='6'!G36 -> 872.27 | BA9: ='6'!G49 -> 2791.14 | BB9: ='6'!G51 -> 1400.52 | BC9: ='6'!G52 -> 1958 | BD9: ='6'!G53 -> 3789 | BE9: ='6'!G54 -> 65.63 | BF9: ='6'!G55 -> 0 | BG9: ='6'!G56 -> 3389 | BH9: ='6'!G57 -> 0 | BI9: ='6'!G50 -> 899.33 | BJ9: =SUM(AV9,AW9,BF9,BG9) -> 3389 | BK9: ='6'!G84 -> 544 | BL9: =SUM(AQ9,AV9,AW9,AX9,BA9,BF9,BG9,BH9)/I9% -> 46.214866 | BM9: =SUM(AT9,BD9)/I9% -> 21.23998 | BN9: =(AS9+BC9)/I9 -> 0.10975952 | BO9: =K9+O9+R9+V9 -> 220876.5 | BP9: =SUM(AV9,AW9,AX9,BF9,BG9,BH9,BK9) -> 5997.13 | BQ9: =BP9/(AE9*280) -> 0.87528898
A10: 7 | B10: 7 | D10: ='7'!D3 -> 30 | E10: ='7'!D4 -> 0.65 | F10: ='7'!D2 -> 0.44 | G10: ='7'!G8 -> 18172 | H10: ='7'!G8 -> 18172 | I10: ='7'!G7 -> 17899 | J10: 10 | K10: =H10*J10 -> 181720 | L10: =I10/202 -> 88.608911 | M10: ='7'!G15 -> 621.3 | N10: 35 | O10: =M10*N10 -> 21745.5 | P10: ='7'!G20 -> 122 | Q10: 134 | R10: =P10*Q10 -> 16348 | S10: =P10/(F10*202/100) -> 137.26373 | T10: ='7'!G24 -> 0 | U10: 69 | V10: =T10*U10 -> 0 | W10: ='7'!G95 -> 48 | X10: ='7'!G96 -> 14 | Y10: ='7'!G97 -> 15 | Z10: =W10+X10+Y10 -> 77 | AA10: ='7'!G132 -> 0 | AB10: ='7'!G133 -> 0 | AC10: ='7'!G134 -> 0 | AD10: ='7'!G135 -> 23.97 | AE10: =AA10+AB10+AC10+AD10 -> 23.97 | AF10: =AV10+AW10+BF10+BG10 -> 3605 | AG10: =AF10/AE10 -> 150.39633 | AH10: ='7'!G136 -> 2.07 | AI10: ='7'!G137 -> 0 | AJ10: ='7'!G138 -> 7.37 | AK10: =AH10+AI10+AJ10 -> 9.44 | AL10: ='7'!G139 -> 0 | AM10: ='7'!G140 -> 7.67 | AO10: =AL10+AM10 -> 7.67 | AP10: ='7'!G123 -> 238 | AQ10: ='7'!G35 -> 0 | AR10: ='7'!G37 -> 0 | AS10: ='7'!G38 -> -0.38 | AT10: ='7'!G39 -> 0 | AU10: ='7'!G40 -> 0 | AV10: ='7'!G41 -> 0 | AW10: ='7'!G42 -> 0 | AX10: ='7'!G43 -> 2063 | AY10: ='7'!G44 -> 0 | AZ10: ='7'!G36 -> 812 | BA10: ='7'!G49 -> 2601.2 | BB10: ='7'!G51 -> 1423 | BC10: ='7'!G52 -> 2008 | BD10: ='7'!G53 -> 3874 | BE10: ='7'!G54 -> 62.57 | BF10: ='7'!G55 -> 0 | BG10: ='7'!G56 -> 3605 | BH10: ='7'!G57 -> 0 | BI10: ='7'!G50 -> 938 | BJ10: =SUM(AV10,AW10,BF10,BG10) -> 3605 | BK10: ='7'!G84 -> 452 | BL10: =SUM(AQ10,AV10,AW10,AX10,BA10,BF10,BG10,BH10)/I10% -> 46.199229 | BM10: =SUM(AT10,BD10)/I10% -> 21.643667 | BN10: =(AS10+BC10)/I10 -> 0.11216381 | BO10: =K10+O10+R10+V10 -> 219813.5 | BP10: =SUM(AV10,AW10,AX10,BF10,BG10,BH10,BK10) -> 6120 | BQ10: =BP10/(AE10*280) -> 0.9118541
A11: 8 | B11: 8 | D11: ='8'!D3 -> 30 | E11: ='8'!D4 -> 0.66 | F11: ='8'!D2 -> 0.45 | G11: ='8'!G8 -> 19066 | H11: ='8'!G8 -> 19066 | I11: ='8'!G7 -> 18873 | J11: 10 | K11: =H11*J11 -> 190660 | L11: =I11/202 -> 93.430693 | M11: ='8'!G15 -> 752 | N11: 35 | O11: =M11*N11 -> 26320 | P11: ='8'!G20 -> 128 | Q11: 134 | R11: =P11*Q11 -> 17152 | S11: =P11/(F11*202/100) -> 140.81408 | T11: ='8'!G24 -> 0 | U11: 69 | V11: =T11*U11 -> 0 | W11: ='8'!G95 -> 59 | X11: ='8'!G96 -> 16 | Y11: ='8'!G97 -> 16 | Z11: =W11+X11+Y11 -> 91 | AA11: ='8'!G132 -> 0 | AB11: ='8'!G133 -> 0 | AC11: ='8'!G134 -> 0 | AD11: ='8'!G135 -> 24 | AE11: =AA11+AB11+AC11+AD11 -> 24 | AF11: =AV11+AW11+BF11+BG11 -> 4131 | AG11: =AF11/AE11 -> 172.125 | AH11: ='8'!G136 -> 8.21 | AI11: ='8'!G137 -> 0 | AJ11: ='8'!G138 -> 0 | AK11: =AH11+AI11+AJ11 -> 8.21 | AL11: ='8'!G139 -> 0 | AM11: ='8'!G140 -> 6.97 | AO11: =AL11+AM11 -> 6.97 | AP11: ='8'!G123 -> 209 | AQ11: ='8'!G35 -> 0 | AR11: ='8'!G37 -> 0 | AS11: ='8'!G38 -> 0 | AT11: ='8'!G39 -> 0 | AU11: ='8'!G40 -> 0 | AV11: ='8'!G41 -> 0 | AW11: ='8'!G42 -> 0 | AX11: ='8'!G43 -> 2058 | AY11: ='8'!G44 -> 0 | AZ11: ='8'!G36 -> 787 | BA11: ='8'!G49 -> 2830 | BB11: ='8'!G51 -> 1426 | BC11: ='8'!G52 -> 1991 | BD11: ='8'!G53 -> 3961 | BE11: ='8'!G54 -> 56 | BF11: ='8'!G55 -> 0 | BG11: ='8'!G56 -> 4131 | BH11: ='8'!G57 -> 0 | BI11: ='8'!G50 -> 990 | BJ11: =SUM(AV11,AW11,BF11,BG11) -> 4131 | BK11: ='8'!G84 -> 518 | BL11: =SUM(AQ11,AV11,AW11,AX11,BA11,BF11,BG11,BH11)/I11% -> 47.787845 | BM11: =SUM(AT11,BD11)/I11% -> 20.987654 | BN11: =(AS11+BC11)/I11 -> 0.10549462 | BO11: =K11+O11+R11+V11 -> 234132 | BP11: =SUM(AV11,AW11,AX11,BF11,BG11,BH11,BK11) -> 6707 | BQ11: =BP11/(AE11*280) -> 0.99806548
A12: 9 | B12: 9 | D12: ='9'!D3 -> 31 | E12: ='9'!D4 -> 0.65 | F12: ='9'!D2 -> 0.75 | G12: ='9'!G8 -> 19030 | H12: ='9'!G8 -> 19030 | I12: ='9'!G7 -> 18833 | J12: 10 | K12: =H12*J12 -> 190300 | L12: =I12/202 -> 93.232673 | M12: ='9'!G15 -> 759 | N12: 35 | O12: =M12*N12 -> 26565 | P12: ='9'!G20 -> 157 | Q12: 134 | R12: =P12*Q12 -> 21038 | S12: =P12/(F12*202/100) -> 103.63036 | T12: ='9'!G24 -> 0 | U12: 69 | V12: =T12*U12 -> 0 | W12: ='9'!G95 -> 68 | X12: ='9'!G96 -> 17 | Y12: ='9'!G97 -> 22 | Z12: =W12+X12+Y12 -> 107 | AA12: ='9'!G132 -> 0 | AB12: ='9'!G133 -> 0 | AC12: ='9'!G134 -> 0 | AD12: ='9'!G135 -> 24 | AE12: =AA12+AB12+AC12+AD12 -> 24 | AF12: =AV12+AW12+BF12+BG12 -> 4116 | AG12: =AF12/AE12 -> 171.5 | AH12: ='9'!G136 -> 7.19 | AI12: ='9'!G137 -> 0 | AJ12: ='9'!G138 -> 0.72 | AK12: =AH12+AI12+AJ12 -> 7.91 | AL12: ='9'!G139 -> 0 | AM12: ='9'!G140 -> 7.15 | AO12: =AL12+AM12 -> 7.15 | AP12: ='9'!G123 -> 217 | AQ12: ='9'!G35 -> 0 | AR12: ='9'!G37 -> 0 | AS12: ='9'!G38 -> 0 | AT12: ='9'!G39 -> 0 | AU12: ='9'!G40 -> 0 | AV12: ='9'!G41 -> 0 | AW12: ='9'!G42 -> 0 | AX12: ='9'!G43 -> 2063 | AY12: ='9'!G44 -> 0 | AZ12: ='9'!G36 -> 624 | BA12: ='9'!G49 -> 2759 | BB12: ='9'!G51 -> 1480 | BC12: ='9'!G52 -> 2047 | BD12: ='9'!G53 -> 4014 | BE12: ='9'!G54 -> 55 | BF12: ='9'!G55 -> 0 | BG12: ='9'!G56 -> 4116 | BH12: ='9'!G57 -> 0 | BI12: ='9'!G50 -> 995 | BJ12: =SUM(AV12,AW12,BF12,BG12) -> 4116 | BK12: ='8'!G84 -> 518 | BL12: =SUM(AQ12,AV12,AW12,AX12,BA12,BF12,BG12,BH12)/I12% -> 47.459247 | BM12: =SUM(AT12,BD12)/I12% -> 21.313652 | BN12: =(AS12+BC12)/I12 -> 0.10869219 | BO12: =K12+O12+R12+V12 -> 237903 | BP12: =SUM(AV12,AW12,AX12,BF12,BG12,BH12,BK12) -> 6697 | BQ12: =BP12/(AE12*280) -> 0.99657738
A13: 10 | B13: 10 | D13: ='10'!D3 -> 29 | E13: ='10'!D4 -> 0.77 | F13: ='10'!D2 -> 0.64 | G13: ='10'!G8 -> 20381 | H13: ='10'!G8 -> 20381 | I13: ='10'!G7 -> 20209 | J13: 10 | K13: =H13*J13 -> 203810 | L13: =I13/202 -> 100.04455 | M13: ='10'!G15 -> 776 | N13: 35 | O13: =M13*N13 -> 27160 | P13: ='10'!G20 -> 141 | Q13: 134 | R13: =P13*Q13 -> 18894 | S13: =P13/(F13*202/100) -> 109.06559 | T13: ='10'!G24 -> 0 | U13: 69 | V13: =T13*U13 -> 0 | W13: ='10'!G95 -> 61 | X13: ='10'!G96 -> 21 | Y13: ='10'!G97 -> 27 | Z13: =W13+X13+Y13 -> 109 | AA13: ='10'!G132 -> 0 | AB13: ='10'!G133 -> 0 | AC13: ='10'!G134 -> 0 | AD13: ='10'!G135 -> 24 | AE13: =AA13+AB13+AC13+AD13 -> 24 | AF13: =AV13+AW13+BF13+BG13 -> 4689 | AG13: =AF13/AE13 -> 195.375 | AH13: ='10'!G136 -> 4.11 | AI13: ='10'!G137 -> 0 | AJ13: ='10'!G138 -> 4.77 | AK13: =AH13+AI13+AJ13 -> 8.88 | AL13: ='10'!G139 -> 0 | AM13: ='10'!G140 -> 8.26 | AO13: =AL13+AM13 -> 8.26 | AP13: ='10'!G123 -> 251 | AQ13: ='10'!G35 -> 0 | AR13: ='10'!G37 -> 0 | AS13: ='10'!G38 -> 0 | AT13: ='10'!G39 -> 0 | AU13: ='10'!G40 -> 0 | AV13: ='10'!G41 -> 0 | AW13: ='10'!G42 -> 0 | AX13: ='10'!G43 -> 2061 | AY13: ='10'!G44 -> 0 | AZ13: ='10'!G36 -> 601 | BA13: ='10'!G49 -> 2846 | BB13: ='10'!G51 -> 1451 | BC13: ='10'!G52 -> 2096 | BD13: ='10'!G53 -> 4463 | BE13: ='10'!G54 -> 57 | BF13: ='10'!G55 -> 0 | BG13: ='10'!G56 -> 4689 | BH13: ='10'!G57 -> 0 | BI13: ='10'!G50 -> 1317 | BJ13: =SUM(AV13,AW13,BF13,BG13) -> 4689 | BK13: ='8'!G84 -> 518 | BL13: =SUM(AQ13,AV13,AW13,AX13,BA13,BF13,BG13,BH13)/I13% -> 47.483794 | BM13: =SUM(AT13,BD13)/I13% -> 22.08422 | BN13: =(AS13+BC13)/I13 -> 0.10371617 | BO13: =K13+O13+R13+V13 -> 249864 | BP13: =SUM(AV13,AW13,AX13,BF13,BG13,BH13,BK13) -> 7268 | BQ13: =BP13/(AE13*280) -> 1.0815476
A14: 11 | B14: 11 | D14: ='11'!D3 -> 29 | E14: ='11'!D4 -> 0.68 | F14: ='11'!D2 -> 0.599 | G14: ='11'!G8 -> 20492 | H14: ='11'!G8 -> 20492 | I14: ='11'!G7 -> 20389 | J14: 10 | K14: =H14*J14 -> 204920 | L14: =I14/202 -> 100.93564 | M14: ='11'!G15 -> 919.052 | N14: 35 | O14: =M14*N14 -> 32166.82 | P14: ='11'!G20 -> 194 | Q14: 134 | R14: =P14*Q14 -> 25996 | S14: =P14/(F14*202/100) -> 160.33323 | T14: ='11'!G24 -> 0 | U14: 69 | V14: =T14*U14 -> 0 | W14: ='11'!G95 -> 93 | X14: ='11'!G96 -> 19 | Y14: ='11'!G97 -> 20 | Z14: =W14+X14+Y14 -> 132 | AA14: ='11'!G132 -> 0 | AB14: ='11'!G133 -> 0 | AC14: ='11'!G134 -> 9.27 | AD14: ='11'!G135 -> 15 | AE14: =AA14+AB14+AC14+AD14 -> 24.27 | AF14: =AV14+AW14+BF14+BG14 -> 4923.0387 | AG14: =AF14/AE14 -> 202.84461 | AH14: ='11'!G136 -> 0 | AI14: ='11'!G137 -> 9.89 | AJ14: ='11'!G138 -> 0 | AK14: =AH14+AI14+AJ14 -> 9.89 | AL14: ='11'!G139 -> -0.37 | AM14: ='11'!G140 -> 7.54 | AO14: =AL14+AM14 -> 7.17 | AP14: ='11'!G123 -> 228.85 | AQ14: ='11'!G35 -> 0.67 | AR14: ='11'!G37 -> 0 | AS14: ='11'!G38 -> 0 | AT14: ='11'!G39 -> 0 | AU14: ='11'!G40 -> 0 | AV14: ='11'!G41 -> 0 | AW14: ='11'!G42 -> 0.099 | AX14: ='11'!G43 -> 2107.83 | AY14: ='11'!G44 -> 0 | AZ14: ='11'!G36 -> 585.07 | BA14: ='11'!G49 -> 2990.63 | BB14: ='11'!G51 -> 1460.735 | BC14: ='11'!G52 -> 2206.59 | BD14: ='11'!G53 -> 4114.21 | BE14: ='11'!G54 -> 55.5955 | BF14: ='11'!G55 -> 1753.7097 | BG14: ='11'!G56 -> 3169.23 | BH14: ='11'!G57 -> 0 | BI14: ='11'!G50 -> 1238.47 | BJ14: =SUM(AV14,AW14,BF14,BG14) -> 4923.0387 | BK14: ='11'!G84 -> 661 | BL14: =SUM(AQ14,AV14,AW14,AX14,BA14,BF14,BG14,BH14)/I14% -> 49.154783 | BM14: =SUM(AT14,BD14)/I14% -> 20.178577 | BN14: =(AS14+BC14)/I14 -> 0.10822453 | BO14: =K14+O14+R14+V14 -> 263082.82 | BP14: =SUM(AV14,AW14,AX14,BF14,BG14,BH14,BK14) -> 7691.8687 | BQ14: =BP14/(AE14*280) -> 1.1318896
A15: 12 | B15: 12 | D15: ='12'!D3 -> 24 | E15: ='12'!D4 -> 0.68 | F15: ='12'!D2 -> 0.72 | G15: ='12'!G8 -> 20191 | H15: ='12'!G8 -> 20191 | I15: ='12'!G7 -> 20105 | J15: 10 | K15: =H15*J15 -> 201910 | L15: =I15/202 -> 99.529703 | M15: ='12'!G15 -> 954.904 | N15: 35 | O15: =M15*N15 -> 33421.64 | P15: ='12'!G20 -> 152 | Q15: 134 | R15: =P15*Q15 -> 20368 | S15: =P15/(F15*202/100) -> 104.51045 | T15: ='12'!G24 -> 0 | U15: 69 | V15: =T15*U15 -> 0 | W15: ='12'!G95 -> 71 | X15: ='12'!G96 -> 21 | Y15: ='12'!G97 -> 17 | Z15: =W15+X15+Y15 -> 109 | AA15: ='12'!G132 -> 0 | AB15: ='12'!G133 -> 0 | AC15: ='12'!G134 -> 24.12 | AD15: ='12'!G135 -> 0 | AE15: =AA15+AB15+AC15+AD15 -> 24.12 | AF15: =AV15+AW15+BF15+BG15 -> 4720.4603 | AG15: =AF15/AE15 -> 195.70731 | AH15: ='12'!G136 -> 9.95 | AI15: ='12'!G137 -> 0.06 | AJ15: ='12'!G138 -> 1.19 | AK15: =AH15+AI15+AJ15 -> 11.2 | AL15: ='12'!G139 -> 0 | AM15: ='12'!G140 -> 8.51 | AO15: =AL15+AM15 -> 8.51 | AP15: ='12'!G123 -> 260.16 | AQ15: ='12'!G35 -> 0 | AR15: ='12'!G37 -> 0 | AS15: ='12'!G38 -> 0 | AT15: ='12'!G39 -> 0 | AU15: ='12'!G40 -> 0 | AV15: ='12'!G41 -> 0 | AW15: ='12'!G42 -> 0 | AX15: ='12'!G43 -> 2279.68 | AY15: ='12'!G44 -> 0 | AZ15: ='12'!G36 -> 617.88 | BA15: ='12'!G49 -> 3294.72 | BB15: ='12'!G51 -> 1498.432 | BC15: ='12'!G52 -> 1956.24 | BD15: ='12'!G53 -> 4087.22 | BE15: ='12'!G54 -> 57.8545 | BF15: ='12'!G55 -> 4720.4603 | BG15: ='12'!G56 -> 0 | BH15: ='12'!G57 -> 0 | BI15: ='12'!G50 -> 985.96 | BJ15: =SUM(AV15,AW15,BF15,BG15) -> 4720.4603 | BK15: ='12'!G84 -> 776 | BL15: =SUM(AQ15,AV15,AW15,AX15,BA15,BF15,BG15,BH15)/I15% -> 51.205473 | BM15: =SUM(AT15,BD15)/I15% -> 20.329371 | BN15: =(AS15+BC15)/I15 -> 0.097301169 | BO15: =K15+O15+R15+V15 -> 255699.64 | BP15: =SUM(AV15,AW15,AX15,BF15,BG15,BH15,BK15) -> 7776.1403 | BQ15: =BP15/(AE15*280) -> 1.1514067
A16: 13 | B16: 13 | D16: ='13'!D3 -> 26 | E16: ='13'!D4 -> 0.74 | F16: ='13'!D2 -> 0.71 | G16: ='13'!G8 -> 20917 | H16: ='13'!G8 -> 20917 | I16: ='13'!G7 -> 20850 | J16: 10 | K16: =H16*J16 -> 209170 | L16: =I16/202 -> 103.21782 | M16: ='13'!G15 -> 902.523 | N16: 35 | O16: =M16*N16 -> 31588.305 | P16: ='13'!G20 -> 174 | Q16: 134 | R16: =P16*Q16 -> 23316 | S16: =P16/(F16*202/100) -> 121.32199 | T16: ='13'!G24 -> 0 | U16: 69 | V16: =T16*U16 -> 0 | W16: ='13'!G95 -> 67 | X16: ='13'!G96 -> 16 | Y16: ='13'!G97 -> 17 | Z16: =W16+X16+Y16 -> 100 | AA16: ='13'!G132 -> 0 | AB16: ='13'!G133 -> 0 | AC16: ='13'!G134 -> 23.61 | AD16: ='13'!G135 -> 0 | AE16: =AA16+AB16+AC16+AD16 -> 23.61 | AF16: =AV16+AW16+BF16+BG16 -> 4888.042 | AG16: =AF16/AE16 -> 207.0327 | AH16: ='13'!G136 -> 7.36 | AI16: ='13'!G137 -> 0 | AJ16: ='13'!G138 -> 4.85 | AK16: =AH16+AI16+AJ16 -> 12.21 | AL16: ='13'!G139 -> 2.5 | AM16: ='13'!G140 -> 6.1 | AO16: =AL16+AM16 -> 8.6 | AP16: ='13'!G123 -> 275.92 | AQ16: ='13'!G35 -> 0 | AR16: ='13'!G37 -> 0 | AS16: ='13'!G38 -> 0 | AT16: ='13'!G39 -> 0 | AU16: ='13'!G40 -> 0 | AV16: ='13'!G41 -> 0.05 | AW16: ='13'!G42 -> 0 | AX16: ='13'!G43 -> 2454.32 | AY16: ='13'!G44 -> 0 | AZ16: ='13'!G36 -> 697.96 | BA16: ='13'!G49 -> 3612.24 | BB16: ='13'!G51 -> 1492.583 | BC16: ='13'!G52 -> 1969.8 | BD16: ='13'!G53 -> 4090.82 | BE16: ='13'!G54 -> 50.65 | BF16: ='13'!G55 -> 4887.992 | BG16: ='13'!G56 -> 0 | BH16: ='13'!G57 -> 0 | BI16: ='13'!G50 -> 1073.24 | BJ16: =SUM(AV16,AW16,BF16,BG16) -> 4888.042 | BK16: ='13'!G84 -> 872 | BL16: =SUM(AQ16,AV16,AW16,AX16,BA16,BF16,BG16,BH16)/I16% -> 52.540058 | BM16: =SUM(AT16,BD16)/I16% -> 19.62024 | BN16: =(AS16+BC16)/I16 -> 0.09447482 | BO16: =K16+O16+R16+V16 -> 264074.31 | BP16: =SUM(AV16,AW16,AX16,BF16,BG16,BH16,BK16) -> 8214.362 | BQ16: =BP16/(AE16*280) -> 1.242567
A17: 14 | B17: 14 | D17: ='14'!D3 -> 24 | E17: ='14'!D4 -> 0.64 | F17: ='14'!D2 -> 0.6683 | G17: ='14'!G8 -> 19411 | H17: ='14'!G8 -> 19411 | I17: ='14'!G7 -> 19342 | J17: 10 | K17: =H17*J17 -> 194110 | L17: =I17/202 -> 95.752475 | M17: ='14'!G15 -> 854.403 | N17: 35 | O17: =M17*N17 -> 29904.105 | P17: ='14'!G20 -> 151 | Q17: 134 | R17: =P17*Q17 -> 20234 | S17: =P17/(F17*202/100) -> 111.85467 | T17: ='14'!G24 -> 0 | U17: 69 | V17: =T17*U17 -> 0 | W17: ='14'!G95 -> 68 | X17: ='14'!G96 -> 10 | Y17: ='14'!G97 -> 15 | Z17: =W17+X17+Y17 -> 93 | AA17: ='14'!G132 -> 0 | AB17: ='14'!G133 -> 0 | AC17: ='14'!G134 -> 24.4 | AD17: ='14'!G135 -> 0 | AE17: =AA17+AB17+AC17+AD17 -> 24.4 | AF17: =AV17+AW17+BF17+BG17 -> 4347.538 | AG17: =AF17/AE17 -> 178.17779 | AH17: ='14'!G136 -> 8.05 | AI17: ='14'!G137 -> 0 | AJ17: ='14'!G138 -> 2.42 | AK17: =AH17+AI17+AJ17 -> 10.47 | AL17: ='14'!G139 -> 6.7 | AM17: ='14'!G140 -> 0 | AO17: =AL17+AM17 -> 6.7 | AP17: ='14'!G123 -> 241.663 | AQ17: ='14'!G35 -> 0 | AR17: ='14'!G37 -> 0 | AS17: ='14'!G38 -> 0 | AT17: ='14'!G39 -> 0 | AU17: ='14'!G40 -> 0 | AV17: ='14'!G41 -> 0 | AW17: ='14'!G42 -> 0 | AX17: ='14'!G43 -> 2310.72 | AY17: ='14'!G44 -> 0 | AZ17: ='14'!G36 -> 689.28 | BA17: ='14'!G49 -> 3348.92 | BB17: ='14'!G51 -> 1404.801 | BC17: ='14'!G52 -> 1878.24 | BD17: ='14'!G53 -> 3857.73 | BE17: ='14'!G54 -> 61.93 | BF17: ='14'!G55 -> 4347.498 | BG17: ='14'!G56 -> 0.04 | BH17: ='14'!G57 -> 0 | BI17: ='14'!G50 -> 979.32 | BJ17: =SUM(AV17,AW17,BF17,BG17) -> 4347.538 | BK17: ='14'!G84 -> 791 | BL17: =SUM(AQ17,AV17,AW17,AX17,BA17,BF17,BG17,BH17)/I17% -> 51.738073 | BM17: =SUM(AT17,BD17)/I17% -> 19.944835 | BN17: =(AS17+BC17)/I17 -> 0.097106814 | BO17: =K17+O17+R17+V17 -> 244248.1 | BP17: =SUM(AV17,AW17,AX17,BF17,BG17,BH17,BK17) -> 7449.258 | BQ17: =BP17/(AE17*280) -> 1.0903481
A18: 15 | B18: 15 | D18: ='15'!D3 -> 29 | E18: ='15'!D4 -> 0.8 | F18: ='15'!D2 -> 0.5 | G18: ='15'!G8 -> 20900 | H18: ='15'!G8 -> 20900 | I18: ='15'!G7 -> 20815 | J18: 10 | K18: =H18*J18 -> 209000 | L18: =I18/202 -> 103.04455 | M18: ='15'!G15 -> 920.068 | N18: 35 | O18: =M18*N18 -> 32202.38 | P18: ='15'!G20 -> 173 | Q18: 134 | R18: =P18*Q18 -> 23182 | S18: =P18/(F18*202/100) -> 171.28713 | T18: ='15'!G24 -> 0 | U18: 69 | V18: =T18*U18 -> 0 | W18: ='15'!G95 -> 115 | X18: ='15'!G96 -> 12 | Y18: ='15'!G97 -> 22 | Z18: =W18+X18+Y18 -> 149 | AA18: ='15'!G132 -> 0 | AB18: ='15'!G133 -> 0 | AC18: ='15'!G134 -> 23.6 | AD18: ='15'!G135 -> 0 | AE18: =AA18+AB18+AC18+AD18 -> 23.6 | AF18: =AV18+AW18+BF18+BG18 -> 4453.713 | AG18: =AF18/AE18 -> 188.71665 | AH18: ='15'!G136 -> 8.22 | AI18: ='15'!G137 -> 0 | AJ18: ='15'!G138 -> 3 | AK18: =AH18+AI18+AJ18 -> 11.22 | AL18: ='15'!G139 -> 7.53 | AM18: ='15'!G140 -> 0 | AO18: =AL18+AM18 -> 7.53 | AP18: ='15'!G123 -> 270.457 | AQ18: ='15'!G35 -> 0 | AR18: ='15'!G37 -> 0 | AS18: ='15'!G38 -> 0 | AT18: ='15'!G39 -> 0 | AU18: ='15'!G40 -> 0 | AV18: ='15'!G41 -> 0 | AW18: ='15'!G42 -> 0 | AX18: ='15'!G43 -> 2449.45 | AY18: ='15'!G44 -> 0 | AZ18: ='15'!G36 -> 747.6 | BA18: ='15'!G49 -> 3589.14 | BB18: ='15'!G51 -> 1550.839 | BC18: ='15'!G52 -> 2055.88 | BD18: ='15'!G53 -> 4189.97 | BE18: ='15'!G54 -> 63.71 | BF18: ='15'!G55 -> 4453.513 | BG18: ='15'!G56 -> 0.2 | BH18: ='15'!G57 -> 0 | BI18: ='15'!G50 -> 1141.4 | BJ18: =SUM(AV18,AW18,BF18,BG18) -> 4453.713 | BK18: ='15'!G84 -> 836 | BL18: =SUM(AQ18,AV18,AW18,AX18,BA18,BF18,BG18,BH18)/I18% -> 50.407413 | BM18: =SUM(AT18,BD18)/I18% -> 20.12957 | BN18: =(AS18+BC18)/I18 -> 0.098769157 | BO18: =K18+O18+R18+V18 -> 264384.38 | BP18: =SUM(AV18,AW18,AX18,BF18,BG18,BH18,BK18) -> 7739.163 | BQ18: =BP18/(AE18*280) -> 1.1711808
A19: 16 | B19: 16 | D19: ='16'!D3 -> 29 | E19: ='16'!D4 -> 0.8 | F19: ='16'!D2 -> 0.5 | G19: ='16'!G8 -> 20048 | H19: ='16'!G8 -> 20048 | I19: ='16'!G7 -> 19975 | J19: 10 | K19: =H19*J19 -> 200480 | L19: =I19/202 -> 98.886139 | M19: ='16'!G15 -> 1070.379 | N19: 35 | O19: =M19*N19 -> 37463.265 | P19: ='16'!G20 -> 254 | Q19: 134 | R19: =P19*Q19 -> 34036 | S19: =P19/(F19*202/100) -> 251.48515 | T19: ='16'!G24 -> 0 | U19: 69 | V19: =T19*U19 -> 0 | W19: ='16'!G95 -> 113 | X19: ='16'!G96 -> 21 | Y19: ='16'!G97 -> 26 | Z19: =W19+X19+Y19 -> 160 | AA19: ='16'!G132 -> 0 | AB19: ='16'!G133 -> 0 | AC19: ='16'!G134 -> 24 | AD19: ='16'!G135 -> 0 | AE19: =AA19+AB19+AC19+AD19 -> 24 | AF19: =AV19+AW19+BF19+BG19 -> 3822.508 | AG19: =AF19/AE19 -> 159.27117 | AH19: ='16'!G136 -> 10.01 | AI19: ='16'!G137 -> 0 | AJ19: ='16'!G138 -> 2.08 | AK19: =AH19+AI19+AJ19 -> 12.09 | AL19: ='16'!G139 -> 7.82 | AM19: ='16'!G140 -> 0 | AO19: =AL19+AM19 -> 7.82 | AP19: ='16'!G123 -> 281.81 | AQ19: ='16'!G35 -> 0 | AR19: ='16'!G37 -> 0 | AS19: ='16'!G38 -> 0 | AT19: ='16'!G39 -> 0 | AU19: ='16'!G40 -> 0 | AV19: ='16'!G41 -> 0 | AW19: ='16'!G42 -> -0.099 | AX19: ='16'!G43 -> 2311.51 | AY19: ='16'!G44 -> 0 | AZ19: ='16'!G36 -> 648.82 | BA19: ='16'!G49 -> 3407.92 | BB19: ='16'!G51 -> 1488.92 | BC19: ='16'!G52 -> 2161.28 | BD19: ='16'!G53 -> 4135.9 | BE19: ='16'!G54 -> 61.44 | BF19: ='16'!G55 -> 3822.607 | BG19: ='16'!G56 -> 0 | BH19: ='16'!G57 -> 0 | BI19: ='16'!G50 -> 1364.32 | BJ19: =SUM(AV19,AW19,BF19,BG19) -> 3822.508 | BK19: ='16'!G84 -> 815 | BL19: =SUM(AQ19,AV19,AW19,AX19,BA19,BF19,BG19,BH19)/I19% -> 47.769402 | BM19: =SUM(AT19,BD19)/I19% -> 20.705382 | BN19: =(AS19+BC19)/I19 -> 0.10819925 | BO19: =K19+O19+R19+V19 -> 271979.26 | BP19: =SUM(AV19,AW19,AX19,BF19,BG19,BH19,BK19) -> 6949.018 | BQ19: =BP19/(AE19*280) -> 1.0340801
A20: 17 | B20: 17 | D20: ='17'!D3 -> 28 | E20: ='17'!D4 -> 0.8 | F20: ='17'!D2 -> 0.5 | G20: ='17'!G8 -> 20933 | H20: ='17'!G8 -> 20933 | I20: ='17'!G7 -> 20881 | J20: 10 | K20: =H20*J20 -> 209330 | L20: =I20/202 -> 103.37129 | M20: ='17'!G15 -> 972.675 | N20: 35 | O20: =M20*N20 -> 34043.625 | P20: ='17'!G20 -> 179 | Q20: 134 | R20: =P20*Q20 -> 23986 | S20: =P20/(F20*202/100) -> 177.22772 | T20: ='17'!G24 -> 0 | U20: 69 | V20: =T20*U20 -> 0 | W20: ='17'!G95 -> 86 | X20: ='17'!G96 -> 22 | Y20: ='17'!G97 -> 30 | Z20: =W20+X20+Y20 -> 138 | AA20: ='17'!G132 -> 0 | AB20: ='17'!G133 -> 0 | AC20: ='17'!G134 -> 24.47 | AD20: ='17'!G135 -> 0 | AE20: =AA20+AB20+AC20+AD20 -> 24.47 | AF20: =AV20+AW20+BF20+BG20 -> 4283.539 | AG20: =AF20/AE20 -> 175.05268 | AH20: ='17'!G136 -> 9.69 | AI20: ='17'!G137 -> 0 | AJ20: ='17'!G138 -> 1.27 | AK20: =AH20+AI20+AJ20 -> 10.96 | AL20: ='17'!G139 -> 8.21 | AM20: ='17'!G140 -> 0 | AO20: =AL20+AM20 -> 8.21 | AP20: ='17'!G123 -> 295.324 | AQ20: ='17'!G35 -> 0 | AR20: ='17'!G37 -> 0 | AS20: ='17'!G38 -> 0 | AT20: ='17'!G39 -> 0 | AU20: ='17'!G40 -> 0 | AV20: ='17'!G41 -> 0 | AW20: ='17'!G42 -> 0.099 | AX20: ='17'!G43 -> 2443.92 | AY20: ='17'!G44 -> 0 | AZ20: ='17'!G36 -> 643.22 | BA20: ='17'!G49 -> 3574.2 | BB20: ='17'!G51 -> 1509.43 | BC20: ='17'!G52 -> 2085.72 | BD20: ='17'!G53 -> 4374.6 | BE20: ='17'!G54 -> 58.84 | BF20: ='17'!G55 -> 4282.52 | BG20: ='17'!G56 -> 0.92 | BH20: ='17'!G57 -> 0 | BI20: ='17'!G50 -> 1191.76 | BJ20: =SUM(AV20,AW20,BF20,BG20) -> 4283.539 | BK20: ='17'!G84 -> 847 | BL20: =SUM(AQ20,AV20,AW20,AX20,BA20,BF20,BG20,BH20)/I20% -> 49.335085 | BM20: =SUM(AT20,BD20)/I20% -> 20.950146 | BN20: =(AS20+BC20)/I20 -> 0.099886021 | BO20: =K20+O20+R20+V20 -> 267359.63 | BP20: =SUM(AV20,AW20,AX20,BF20,BG20,BH20,BK20) -> 7574.459 | BQ20: =BP20/(AE20*280) -> 1.1055022
A21: 18 | B21: 18 | D21: ='18'!D3 -> 29 | E21: ='18'!D4 -> 0.8 | F21: ='18'!D2 -> 0.5 | G21: ='18'!G8 -> 20245 | H21: ='18'!G8 -> 20245 | I21: ='18'!G7 -> 20163 | J21: 10 | K21: =H21*J21 -> 202450 | L21: =I21/202 -> 99.816832 | M21: ='18'!G15 -> 944.776 | N21: 35 | O21: =M21*N21 -> 33067.16 | P21: ='18'!G20 -> 192 | Q21: 134 | R21: =P21*Q21 -> 25728 | S21: =P21/(F21*202/100) -> 190.09901 | T21: ='18'!G24 -> 0 | U21: 69 | V21: =T21*U21 -> 0 | W21: ='18'!G95 -> 84 | X21: ='18'!G96 -> 17 | Y21: ='18'!G97 -> 24 | Z21: =W21+X21+Y21 -> 125 | AA21: ='18'!G132 -> 0 | AB21: ='18'!G133 -> 0 | AC21: ='18'!G134 -> 24.45 | AD21: ='18'!G135 -> 0 | AE21: =AA21+AB21+AC21+AD21 -> 24.45 | AF21: =AV21+AW21+BF21+BG21 -> 4436.681 | AG21: =AF21/AE21 -> 181.45935 | AH21: ='18'!G136 -> 9.1 | AI21: ='18'!G137 -> 0 | AJ21: ='18'!G138 -> 3.35 | AK21: =AH21+AI21+AJ21 -> 12.45 | AL21: ='18'!G139 -> 7.6 | AM21: ='18'!G140 -> 0 | AO21: =AL21+AM21 -> 7.6 | AP21: ='18'!G123 -> 271.816 | AQ21: ='18'!G35 -> 0 | AR21: ='18'!G37 -> 0 | AS21: ='18'!G38 -> 0 | AT21: ='18'!G39 -> 0 | AU21: ='18'!G40 -> 0 | AV21: ='18'!G41 -> 0 | AW21: ='18'!G42 -> -0.009 | AX21: ='18'!G43 -> 2394.88 | AY21: ='18'!G44 -> 0 | AZ21: ='18'!G36 -> 705.58 | BA21: ='18'!G49 -> 3500.42 | BB21: ='18'!G51 -> 1485.15 | BC21: ='18'!G52 -> 1920.16 | BD21: ='18'!G53 -> 4182.22 | BE21: ='18'!G54 -> 50.72 | BF21: ='18'!G55 -> 4436.69 | BG21: ='18'!G56 -> 0 | BH21: ='18'!G57 -> 0 | BI21: ='18'!G50 -> 1095.24 | BJ21: =SUM(AV21,AW21,BF21,BG21) -> 4436.681 | BK21: ='18'!G84 -> 814 | BL21: =SUM(AQ21,AV21,AW21,AX21,BA21,BF21,BG21,BH21)/I21% -> 51.24228 | BM21: =SUM(AT21,BD21)/I21% -> 20.742052 | BN21: =(AS21+BC21)/I21 -> 0.09523186 | BO21: =K21+O21+R21+V21 -> 261245.16 | BP21: =SUM(AV21,AW21,AX21,BF21,BG21,BH21,BK21) -> 7645.561 | BQ21: =BP21/(AE21*280) -> 1.1167924
A22: 19 | B22: 19 | D22: ='19'!D3 -> 30 | E22: ='19'!D4 -> 0.8 | F22: ='19'!D2 -> 0.5 | G22: ='19'!G8 -> 20035 | H22: ='19'!G8 -> 20035 | I22: ='19'!G7 -> 19963 | J22: 10 | K22: =H22*J22 -> 200350 | L22: =I22/202 -> 98.826733 | M22: ='19'!G15 -> 914.15 | N22: 35 | O22: =M22*N22 -> 31995.25 | P22: ='19'!G20 -> 172 | Q22: 134 | R22: =P22*Q22 -> 23048 | S22: =P22/(F22*202/100) -> 170.29703 | T22: ='19'!G24 -> 0 | U22: 69 | V22: =T22*U22 -> 0 | W22: ='19'!G95 -> 81 | X22: ='19'!G96 -> 13 | Y22: ='19'!G97 -> 19 | Z22: =W22+X22+Y22 -> 113 | AA22: ='19'!G132 -> 0 | AB22: ='19'!G133 -> 0 | AC22: ='19'!G134 -> 24.47 | AD22: ='19'!G135 -> 0 | AE22: =AA22+AB22+AC22+AD22 -> 24.47 | AF22: =AV22+AW22+BF22+BG22 -> 4360.94 | AG22: =AF22/AE22 -> 178.21577 | AH22: ='19'!G136 -> 9.01 | AI22: ='19'!G137 -> 0 | AJ22: ='19'!G138 -> 3.58 | AK22: =AH22+AI22+AJ22 -> 12.59 | AL22: ='19'!G139 -> 7.36 | AM22: ='19'!G140 -> 0 | AO22: =AL22+AM22 -> 7.36 | AP22: ='19'!G123 -> 265 | AQ22: ='19'!G35 -> 0 | AR22: ='19'!G37 -> 0 | AS22: ='19'!G38 -> 0 | AT22: ='19'!G39 -> 0 | AU22: ='19'!G40 -> 0 | AV22: ='19'!G41 -> 0 | AW22: ='19'!G42 -> 0 | AX22: ='19'!G43 -> 2404.72 | AY22: ='19'!G44 -> 0 | AZ22: ='19'!G36 -> 689.44 | BA22: ='19'!G49 -> 3402.08 | BB22: ='19'!G51 -> 1469.8 | BC22: ='19'!G52 -> 1881.76 | BD22: ='19'!G53 -> 4176.7 | BE22: ='19'!G54 -> 56.78 | BF22: ='19'!G55 -> 4360.94 | BG22: ='19'!G56 -> 0 | BH22: ='19'!G57 -> 0 | BI22: ='19'!G50 -> 1051.9 | BJ22: =SUM(AV22,AW22,BF22,BG22) -> 4360.94 | BK22: ='19'!G84 -> 820 | BL22: =SUM(AQ22,AV22,AW22,AX22,BA22,BF22,BG22,BH22)/I22% -> 50.932926 | BM22: =SUM(AT22,BD22)/I22% -> 20.922206 | BN22: =(AS22+BC22)/I22 -> 0.094262385 | BO22: =K22+O22+R22+V22 -> 255393.25 | BP22: =SUM(AV22,AW22,AX22,BF22,BG22,BH22,BK22) -> 7585.66 | BQ22: =BP22/(AE22*280) -> 1.107137
A23: 20 | B23: 20 | D23: ='20'!D3 -> 30 | E23: ='20'!D4 -> 0.81 | F23: ='20'!D2 -> 0.5 | G23: ='20'!G8 -> 19981 | H23: ='20'!G8 -> 19981 | I23: ='20'!G7 -> 19855 | J23: 10 | K23: =H23*J23 -> 199810 | L23: =I23/202 -> 98.292079 | M23: ='20'!G15 -> 930.07 | N23: 35 | O23: =M23*N23 -> 32552.45 | P23: ='20'!G20 -> 190 | Q23: 134 | R23: =P23*Q23 -> 25460 | S23: =P23/(F23*202/100) -> 188.11881 | T23: ='20'!G24 -> 0 | U23: 69 | V23: =T23*U23 -> 0 | W23: ='20'!G95 -> 88 | X23: ='20'!G96 -> 16 | Y23: ='20'!G97 -> 21 | Z23: =W23+X23+Y23 -> 125 | AA23: ='20'!G132 -> 11.57 | AB23: ='20'!G133 -> 0.02 | AC23: ='20'!G134 -> 13.66 | AD23: ='20'!G135 -> 0 | AE23: =AA23+AB23+AC23+AD23 -> 25.25 | AF23: =AV23+AW23+BF23+BG23 -> 4191.09 | AG23: =AF23/AE23 -> 165.98376 | AH23: ='20'!G136 -> 8.52 | AI23: ='20'!G137 -> 0 | AJ23: ='20'!G138 -> 3.75 | AK23: =AH23+AI23+AJ23 -> 12.27 | AL23: ='20'!G139 -> 6.93 | AM23: ='20'!G140 -> 0 | AO23: =AL23+AM23 -> 6.93 | AP23: ='20'!G123 -> 249.84 | AQ23: ='20'!G35 -> 0 | AR23: ='20'!G37 -> 0 | AS23: ='20'!G38 -> 0 | AT23: ='20'!G39 -> 0 | AU23: ='20'!G40 -> 0 | AV23: ='20'!G41 -> 2136.44 | AW23: ='20'!G42 -> 0 | AX23: ='20'!G43 -> 2411.84 | AY23: ='20'!G44 -> 0 | AZ23: ='20'!G36 -> 707.12 | BA23: ='20'!G49 -> 3213.34 | BB23: ='20'!G51 -> 1505.79 | BC23: ='20'!G52 -> 1801.12 | BD23: ='20'!G576 -> 0 | BE23: ='20'!G54 -> 54.63 | BF23: ='20'!G55 -> 2054.65 | BG23: ='20'!G56 -> 0 | BH23: ='20'!G57 -> 0 | BI23: ='20'!G50 -> 1253.9 | BJ23: =SUM(AV23,AW23,BF23,BG23) -> 4191.09 | BK23: ='20'!G84 -> 669 | BL23: =SUM(AQ23,AV23,AW23,AX23,BA23,BF23,BG23,BH23)/I23% -> 49.439788 | BM23: =SUM(AT23,BD23)/I23% -> 0 | BN23: =(AS23+BC23)/I23 -> 0.090713674 | BO23: =K23+O23+R23+V23 -> 257822.45 | BP23: =SUM(AV23,AW23,AX23,BF23,BG23,BH23,BK23) -> 7271.93 | BQ23: =BP23/(AE23*280) -> 1.0285615
A24: 21 | B24: 21 | D24: 21 | E24: ='21'!D4 -> 0.81 | F24: ='21'!D2 -> 0.5 | G24: ='21'!G8 -> 19575 | H24: ='21'!G8 -> 19575 | I24: ='21'!G7 -> 19415 | J24: 10 | K24: =H24*J24 -> 195750 | L24: =I24/202 -> 96.113861 | M24: ='21'!G15 -> 906.94 | N24: 35 | O24: =M24*N24 -> 31742.9 | P24: ='21'!G20 -> 179 | Q24: 134 | R24: =P24*Q24 -> 23986 | S24: =P24/(F24*202/100) -> 177.22772 | T24: ='21'!G24 -> 0 | U24: 69 | V24: =T24*U24 -> 0 | W24: ='21'!G95 -> 75 | X24: ='21'!G96 -> 17 | Y24: ='21'!G97 -> 16 | Z24: =W24+X24+Y24 -> 108 | AA24: ='21'!G132 -> 23.53 | AB24: ='21'!G133 -> 0 | AC24: ='21'!G134 -> 0 | AD24: ='21'!G135 -> 0 | AE24: =AA24+AB24+AC24+AD24 -> 23.53 | AF24: =AV24+AW24+BF24+BG24 -> 4111.33 | AG24: =AF24/AE24 -> 174.72716 | AH24: ='21'!G136 -> 0 | AI24: ='21'!G137 -> 9.86 | AJ24: ='21'!G138 -> 0 | AK24: =AH24+AI24+AJ24 -> 9.86 | AL24: ='21'!G139 -> 6.75 | AM24: ='21'!G140 -> 0 | AO24: =AL24+AM24 -> 6.75 | AP24: ='21'!G123 -> 243.01 | AQ24: ='21'!G35 -> 0 | AR24: ='21'!G37 -> 0 | AS24: ='21'!G38 -> 0.38 | AT24: ='21'!G39 -> 0 | AU24: ='21'!G40 -> 0 | AV24: ='21'!G41 -> 4107.73 | AW24: ='21'!G42 -> 0 | AX24: ='21'!G43 -> 2320.16 | AY24: ='21'!G44 -> 0 | AZ24: ='21'!G36 -> 762.06 | BA24: ='21'!G49 -> 3092.92 | BB24: ='21'!G51 -> 1457.35 | BC24: ='21'!G52 -> 1745.96 | BD24: ='21'!G53 -> 4123.86 | BE24: ='21'!G54 -> 44.38 | BF24: ='21'!G55 -> 0 | BG24: ='21'!G56 -> 3.6 | BH24: ='21'!G57 -> 0 | BI24: ='21'!G50 -> 1198 | BJ24: =SUM(AV24,AW24,BF24,BG24) -> 4111.33 | BK24: ='21'!G84 -> 537 | BL24: =SUM(AQ24,AV24,AW24,AX24,BA24,BF24,BG24,BH24)/I24% -> 49.056966 | BM24: =SUM(AT24,BD24)/I24% -> 21.240587 | BN24: =(AS24+BC24)/I24 -> 0.089947978 | BO24: =K24+O24+R24+V24 -> 251478.9 | BP24: =SUM(AV24,AW24,AX24,BF24,BG24,BH24,BK24) -> 6968.49 | BQ24: =BP24/(AE24*280) -> 1.0576908
A25: 22 | B25: 22 | D25: ='22'!D3 -> 30 | E25: ='22'!D4 -> 0.78 | F25: ='22'!D2 -> 0.5 | G25: ='22'!G8 -> 19676 | H25: ='22'!G8 -> 19676 | I25: ='22'!G7 -> 19510 | J25: 10 | K25: =H25*J25 -> 196760 | L25: =I25/202 -> 96.584158 | M25: ='22'!G15 -> 904 | N25: 35 | O25: =M25*N25 -> 31640 | P25: ='22'!G20 -> 177 | Q25: 134 | R25: =P25*Q25 -> 23718 | S25: =P25/(F25*202/100) -> 175.24752 | T25: ='22'!G24 -> 0 | U25: 69 | V25: =T25*U25 -> 0 | W25: ='22'!G95 -> 83 | X25: ='22'!G96 -> 18 | Y25: ='22'!G97 -> 20 | Z25: =W25+X25+Y25 -> 121 | AA25: ='22'!G132 -> 24.48 | AB25: ='22'!G133 -> 0 | AC25: ='22'!G134 -> 0 | AD25: ='22'!G135 -> 0 | AE25: =AA25+AB25+AC25+AD25 -> 24.48 | AF25: =AV25+AW25+BF25+BG25 -> 4213.01 | AG25: =AF25/AE25 -> 172.10008 | AH25: ='22'!G136 -> 0 | AI25: ='22'!G137 -> 9.52 | AJ25: ='22'!G138 -> 0 | AK25: =AH25+AI25+AJ25 -> 9.52 | AL25: ='22'!G139 -> 7.49 | AM25: ='22'!G140 -> 0 | AO25: =AL25+AM25 -> 7.49 | AP25: ='22'!G123 -> 268.23 | AQ25: ='22'!G35 -> 0 | AR25: ='22'!G37 -> 0 | AS25: ='22'!G38 -> 0 | AT25: ='22'!G39 -> 0 | AU25: ='22'!G40 -> 0 | AV25: ='22'!G41 -> 4212.37 | AW25: ='22'!G42 -> 0 | AX25: ='22'!G43 -> 2388.08 | AY25: ='22'!G44 -> 0 | AZ25: ='22'!G36 -> 671.76 | BA25: ='22'!G49 -> 3188.47 | BB25: ='22'!G51 -> 1492.14 | BC25: ='22'!G52 -> 1877.8 | BD25: ='22'!G53 -> 4075.6 | BE25: ='22'!G54 -> 61.18 | BF25: ='22'!G55 -> 0 | BG25: ='22'!G56 -> 0.64 | BH25: ='22'!G57 -> 0 | BI25: ='22'!G50 -> 1029.84 | BJ25: =SUM(AV25,AW25,BF25,BG25) -> 4213.01 | BK25: ='22'!G84 -> 553 | BL25: =SUM(AQ25,AV25,AW25,AX25,BA25,BF25,BG25,BH25)/I25% -> 50.17714 | BM25: =SUM(AT25,BD25)/I25% -> 20.8898 | BN25: =(AS25+BC25)/I25 -> 0.096248078 | BO25: =K25+O25+R25+V25 -> 252118 | BP25: =SUM(AV25,AW25,AX25,BF25,BG25,BH25,BK25) -> 7154.09 | BQ25: =BP25/(AE25*280) -> 1.0437223
A26: 23 | B26: 23 | D26: ='23'!D3 -> 30 | E26: ='23'!D4 -> 0.76 | F26: ='23'!D2 -> 0.5 | G26: ='23'!G8 -> 19855 | H26: ='23'!G8 -> 19855 | I26: ='23'!G7 -> 19709 | J26: 10 | K26: =H26*J26 -> 198550 | L26: =I26/202 -> 97.569307 | M26: ='23'!G15 -> 934.94 | N26: 35 | O26: =M26*N26 -> 32722.9 | P26: ='23'!G20 -> 203 | Q26: 134 | R26: =P26*Q26 -> 27202 | S26: =P26/(F26*202/100) -> 200.9901 | T26: ='23'!G24 -> 0 | U26: 69 | V26: =T26*U26 -> 0 | W26: ='23'!G95 -> 75 | X26: ='23'!G96 -> 18 | Y26: ='23'!G97 -> 26 | Z26: =W26+X26+Y26 -> 119 | AA26: ='23'!G132 -> 23.95 | AB26: ='23'!G133 -> -0.01 | AC26: ='23'!G134 -> 0 | AD26: ='23'!G135 -> 0 | AE26: =AA26+AB26+AC26+AD26 -> 23.94 | AF26: =AV26+AW26+BF26+BG26 -> 4346.66 | AG26: =AF26/AE26 -> 181.56475 | AH26: ='23'!G136 -> 10.18 | AI26: ='23'!G137 -> 0 | AJ26: ='23'!G138 -> 0 | AK26: =AH26+AI26+AJ26 -> 10.18 | AL26: ='23'!G139 -> 7.01 | AM26: ='23'!G140 -> 0 | AO26: =AL26+AM26 -> 7.01 | AP26: ='23'!G123 -> 245.86 | AQ26: ='23'!G35 -> 0 | AR26: ='23'!G37 -> 0 | AS26: ='23'!G38 -> 0 | AT26: ='23'!G39 -> 0 | AU26: ='23'!G40 -> 0 | AV26: ='23'!G41 -> 4346.14 | AW26: ='23'!G42 -> 0 | AX26: ='23'!G43 -> 2363.52 | AY26: ='23'!G44 -> 0 | AZ26: ='23'!G36 -> 654.22 | BA26: ='23'!G49 -> 3038.57 | BB26: ='23'!G51 -> 1462.67 | BC26: ='23'!G52 -> 1944.04 | BD26: ='23'!G53 -> 4262.76 | BE26: ='23'!G54 -> 67.12 | BF26: ='23'!G55 -> 0 | BG26: ='23'!G56 -> 0.52 | BH26: ='23'!G57 -> 0 | BI26: ='23'!G50 -> 1048.36 | BJ26: =SUM(AV26,AW26,BF26,BG26) -> 4346.66 | BK26: ='23'!G84 -> 552 | BL26: =SUM(AQ26,AV26,AW26,AX26,BA26,BF26,BG26,BH26)/I26% -> 49.463443 | BM26: =SUM(AT26,BD26)/I26% -> 21.628495 | BN26: =(AS26+BC26)/I26 -> 0.098637171 | BO26: =K26+O26+R26+V26 -> 258474.9 | BP26: =SUM(AV26,AW26,AX26,BF26,BG26,BH26,BK26) -> 7262.18 | BQ26: =BP26/(AE26*280) -> 1.08339
A27: 24 | B27: 24 | D27: ='24'!D3 -> 27 | E27: ='24'!D4 -> 0.78 | F27: ='24'!D2 -> 0.33 | G27: ='24'!G8 -> 19558 | H27: ='24'!G8 -> 19558 | I27: ='24'!G7 -> 19391 | J27: 10 | K27: =H27*J27 -> 195580 | L27: =I27/202 -> 95.99505 | M27: ='24'!G15 -> 748.12 | N27: 35 | O27: =M27*N27 -> 26184.2 | P27: ='24'!G20 -> 190 | Q27: 134 | R27: =P27*Q27 -> 25460 | S27: =P27/(F27*202/100) -> 285.0285 | T27: ='24'!G24 -> 0 | U27: 69 | V27: =T27*U27 -> 0 | W27: ='24'!G95 -> 71 | X27: ='24'!G96 -> 25 | Y27: ='24'!G97 -> 33 | Z27: =W27+X27+Y27 -> 129 | AA27: ='24'!G132 -> 23.55 | AB27: ='24'!G133 -> 0 | AC27: ='24'!G134 -> 0 | AD27: ='24'!G135 -> 0 | AE27: =AA27+AB27+AC27+AD27 -> 23.55 | AF27: =AV27+AW27+BF27+BG27 -> 4221.23 | AG27: =AF27/AE27 -> 179.24544 | AH27: ='24'!G136 -> 6.88 | AI27: ='24'!G137 -> 0 | AJ27: ='24'!G138 -> 0 | AK27: =AH27+AI27+AJ27 -> 6.88 | AL27: ='24'!G139 -> 7.91 | AM27: ='24'!G140 -> 0 | AO27: =AL27+AM27 -> 7.91 | AP27: ='24'!G123 -> 269.06 | AQ27: ='24'!G35 -> 0 | AR27: ='24'!G37 -> 0 | AS27: ='24'!G38 -> 0 | AT27: ='24'!G39 -> 0 | AU27: ='24'!G40 -> 0 | AV27: ='24'!G41 -> 4221.32 | AW27: ='24'!G42 -> -0.09 | AX27: ='24'!G43 -> 2378.37 | AY27: ='24'!G44 -> 0 | AZ27: ='24'!G36 -> 725.9 | BA27: ='24'!G49 -> 3075.43 | BB27: ='24'!G51 -> 1478.36 | BC27: ='24'!G52 -> 1833.92 | BD27: ='24'!G53 -> 4203.95 | BE27: ='24'!G54 -> 47.17 | BF27: ='24'!G55 -> 0 | BG27: ='24'!G56 -> 0 | BH27: ='24'!G57 -> 0 | BI27: ='24'!G50 -> 999 | BJ27: =SUM(AV27,AW27,BF27,BG27) -> 4221.23 | BK27: ='24'!G84 -> 524 | BL27: =SUM(AQ27,AV27,AW27,AX27,BA27,BF27,BG27,BH27)/I27% -> 49.894436 | BM27: =SUM(AT27,BD27)/I27% -> 21.679903 | BN27: =(AS27+BC27)/I27 -> 0.094575834 | BO27: =K27+O27+R27+V27 -> 247224.2 | BP27: =SUM(AV27,AW27,AX27,BF27,BG27,BH27,BK27) -> 7123.6 | BQ27: =BP27/(AE27*280) -> 1.0803154
A28: 25 | B28: 25 | D28: ='25'!D3 -> 31 | E28: ='25'!D4 -> 0.8 | F28: ='25'!D2 -> 0.65 | G28: ='25'!G8 -> 19342 | H28: ='25'!G8 -> 19342 | I28: ='25'!G7 -> 19169 | J28: 10 | K28: =H28*J28 -> 193420 | L28: =I28/202 -> 94.89604 | M28: ='25'!G15 -> 930.86 | N28: 35 | O28: =M28*N28 -> 32580.1 | P28: ='25'!G20 -> 183 | Q28: 134 | R28: =P28*Q28 -> 24522 | S28: =P28/(F28*202/100) -> 139.37548 | T28: ='25'!G24 -> 0 | U28: 69 | V28: =T28*U28 -> 0 | W28: ='25'!G95 -> 83 | X28: ='25'!G96 -> 24 | Y28: ='25'!G97 -> 25 | Z28: =W28+X28+Y28 -> 132 | AA28: ='25'!G132 -> 23.96 | AB28: ='25'!G133 -> 0 | AC28: ='25'!G134 -> 0 | AD28: ='25'!G135 -> 0 | AE28: =AA28+AB28+AC28+AD28 -> 23.96 | AF28: =AV28+AW28+BF28+BG28 -> 3515.11 | AG28: =AF28/AE28 -> 146.70743 | AH28: ='24'!G136 -> 6.88 | AI28: ='24'!G137 -> 0 | AJ28: ='24'!G138 -> 0 | AK28: =AH28+AI28+AJ28 -> 6.88 | AL28: ='23'!G139 -> 7.01 | AM28: ='24'!G140 -> 0 | AO28: =AL28+AM28 -> 7.01 | AP28: ='25'!G123 -> 269.21 | AQ28: ='25'!G35 -> 0 | AR28: ='25'!G37 -> 0 | AS28: ='25'!G38 -> 0 | AT28: ='25'!G39 -> 0 | AU28: ='25'!G40 -> 0 | AV28: ='25'!G41 -> 3515.11 | AX28: ='25'!G43 -> 2253.31 | AY28: ='25'!G44 -> 0 | AZ28: ='25'!G36 -> 956.09 | BA28: ='25'!G49 -> 3187.61 | BB28: ='25'!G51 -> 1503.88 | BC28: ='25'!G52 -> 1825 | BD28: ='25'!G53 -> 4326 | BE28: ='24'!G54 -> 47.17 | BF28: ='25'!G55 -> 0 | BG28: ='25'!G56 -> 0 | BH28: ='25'!G57 -> 0 | BI28: ='25'!G50 -> 1041.96 | BJ28: =SUM(AV28,AW28,BF28,BG28) -> 3515.11 | BK28: ='25'!G84 -> 516 | BL28: =SUM(AQ28,AV28,AW28,AX28,BA28,BF28,BG28,BH28)/I28% -> 46.721425 | BM28: =SUM(AT28,BD28)/I28% -> 22.567687 | BN28: =(AS28+BC28)/I28 -> 0.095205801 | BO28: =K28+O28+R28+V28 -> 250522.1 | BP28: =SUM(AV28,AW28,AX28,BF28,BG28,BH28,BK28) -> 6284.42 | BQ28: =BP28/(AE28*280) -> 0.93674279
A29: 26 | B29: 26 | D29: ='26'!D3 -> 23 | E29: ='26'!D4 -> 0.74 | F29: ='26'!D2 -> 0.44 | G29: ='26'!G8 -> 19147 | H29: ='26'!G8 -> 19147 | I29: ='26'!G7 -> 18998 | J29: 10 | K29: =H29*J29 -> 191470 | L29: =I29/202 -> 94.049505 | M29: ='26'!G15 -> 855.14 | N29: 35 | O29: =M29*N29 -> 29929.9 | P29: ='26'!G20 -> 189 | Q29: 134 | R29: =P29*Q29 -> 25326 | S29: =P29/(F29*202/100) -> 212.64626 | T29: ='26'!G24 -> 0 | U29: 69 | V29: =T29*U29 -> 0 | W29: ='26'!G95 -> 60 | X29: ='26'!G96 -> 19 | Y29: ='26'!G97 -> 25 | Z29: =W29+X29+Y29 -> 104 | AA29: ='26'!G132 -> 23.88 | AB29: ='26'!G133 -> -0.01 | AC29: ='26'!G134 -> -0.05 | AD29: ='26'!G135 -> 0 | AE29: =AA29+AB29+AC29+AD29 -> 23.82 | AF29: =AV29+AW29+BF29+BG29 -> 3760.38 | AG29: =AF29/AE29 -> 157.8665 | AH29: ='26'!G136 -> 8.68 | AI29: ='26'!G137 -> 0 | AJ29: ='26'!G138 -> 0 | AK29: =AH29+AI29+AJ29 -> 8.68 | AL29: ='26'!G139 -> 7.76 | AM29: ='26'!G140 -> 0 | AO29: =AL29+AM29 -> 7.76 | AP29: ='26'!G123 -> 266.14 | AQ29: ='26'!G35 -> 0 | AR29: ='26'!G37 -> 0 | AS29: ='26'!G38 -> -0.38 | AT29: ='26'!G39 -> 0 | AU29: ='26'!G40 -> 0 | AV29: ='26'!G41 -> 3760.38 | AW29: ='26'!G42 -> 0 | AX29: ='26'!G43 -> 2328.54 | AY29: ='26'!G44 -> 0 | AZ29: ='26'!G36 -> 748 | BA29: ='26'!G49 -> 3198.39 | BB29: ='26'!G51 -> 1422.12 | BC29: ='26'!G52 -> 1907.12 | BD29: ='26'!G53 -> 4151.85 | BE29: ='26'!G54 -> 46 | BF29: ='26'!G55 -> 0 | BG29: ='26'!G56 -> 0 | BH29: ='26'!G57 -> 0 | BI29: ='26'!G50 -> 938.04 | BJ29: =SUM(AV29,AW29,BF29,BG29) -> 3760.38 | BK29: ='26'!G84 -> 528 | BL29: =SUM(AQ29,AV29,AW29,AX29,BA29,BF29,BG29,BH29)/I29% -> 48.885725 | BM29: =SUM(AT29,BD29)/I29% -> 21.854143 | BN29: =(AS29+BC29)/I29 -> 0.1003653 | BO29: =K29+O29+R29+V29 -> 246725.9 | BP29: =SUM(AV29,AW29,AX29,BF29,BG29,BH29,BK29) -> 6616.92 | BQ29: =BP29/(AE29*280) -> 0.99210148
A30: 27 | B30: 27 | D30: ='27'!D3 -> 22 | E30: ='27'!D4 -> 0.76 | F30: ='27'!D2 -> 0.49 | G30: ='27'!G8 -> 18909 | H30: ='27'!G8 -> 18909 | I30: ='27'!G7 -> 18736 | J30: 10 | K30: =H30*J30 -> 189090 | L30: =I30/202 -> 92.752475 | M30: ='27'!G15 -> 843.94 | N30: 35 | O30: =M30*N30 -> 29537.9 | P30: ='27'!G20 -> 174 | Q30: 134 | R30: =P30*Q30 -> 23316 | S30: =P30/(F30*202/100) -> 175.79309 | T30: ='27'!G24 -> 0 | U30: 69 | V30: =T30*U30 -> 0 | W30: ='27'!G95 -> 71 | X30: ='27'!G96 -> 15 | Y30: ='27'!G97 -> 13 | Z30: =W30+X30+Y30 -> 99 | AA30: ='27'!G132 -> 24.27 | AB30: ='27'!G133 -> 0 | AC30: ='27'!G134 -> 0 | AD30: ='27'!G135 -> 0 | AE30: =AA30+AB30+AC30+AD30 -> 24.27 | AF30: =AV30+AW30+BF30+BG30 -> 3663.51 | AG30: =AF30/AE30 -> 150.94808 | AH30: ='27'!G136 -> 9.43 | AI30: ='27'!G137 -> 0 | AJ30: ='27'!G138 -> 0 | AK30: =AH30+AI30+AJ30 -> 9.43 | AL30: ='27'!G139 -> 7.28 | AM30: ='27'!G140 -> 0 | AO30: =AL30+AM30 -> 7.28 | AP30: ='27'!G123 -> 250.61 | AQ30: ='27'!G35 -> 0 | AR30: ='27'!G37 -> 0 | AS30: ='27'!G38 -> 0 | AT30: ='27'!G39 -> 0 | AU30: ='27'!G40 -> 0 | AV30: ='27'!G41 -> 3663.51 | AW30: ='27'!G42 -> 0 | AX30: ='27'!G43 -> 2320.1 | AY30: ='27'!G44 -> 0 | AZ30: ='27'!G36 -> 626.73 | BA30: ='27'!G49 -> 3187.45 | BB30: ='27'!G51 -> 1436.54 | BC30: ='27'!G52 -> 1764.16 | BD30: ='27'!G53 -> 4080.15 | BE30: ='27'!G54 -> 56.55 | BF30: ='27'!G55 -> 0 | BG30: ='27'!G56 -> 0 | BH30: ='27'!G57 -> 0 | BI30: ='27'!G50 -> 1027.29 | BJ30: =SUM(AV30,AW30,BF30,BG30) -> 3663.51 | BK30: ='27'!G84 -> 556 | BL30: =SUM(AQ30,AV30,AW30,AX30,BA30,BF30,BG30,BH30)/I30% -> 48.948868 | BM30: =SUM(AT30,BD30)/I30% -> 21.77706 | BN30: =(AS30+BC30)/I30 -> 0.094158839 | BO30: =K30+O30+R30+V30 -> 241943.9 | BP30: =SUM(AV30,AW30,AX30,BF30,BG30,BH30,BK30) -> 6539.61 | BQ30: =BP30/(AE30*280) -> 0.96233004
A31: 28 | B31: 28 | D31: ='28'!D3 -> 23 | E31: ='28'!D4 -> 0.77 | F31: ='28'!D2 -> 0.52 | G31: ='28'!G8 -> 19519 | H31: ='28'!G8 -> 19519 | I31: ='28'!G7 -> 19357 | J31: 10 | K31: =H31*J31 -> 195190 | L31: =I31/202 -> 95.826733 | M31: ='28'!G15 -> 434.06 | N31: 35 | O31: =M31*N31 -> 15192.1 | P31: ='28'!G20 -> 173 | Q31: 134 | R31: =P31*Q31 -> 23182 | S31: =P31/(F31*202/100) -> 164.69916 | T31: ='28'!G24 -> 0 | U31: 69 | V31: =T31*U31 -> 0 | W31: ='28'!G95 -> 43 | X31: ='28'!G96 -> 23 | Y31: ='28'!G97 -> 11 | Z31: =W31+X31+Y31 -> 77 | AA31: ='28'!G132 -> 23.81 | AB31: ='28'!G133 -> 0 | AC31: ='28'!G134 -> 0 | AD31: ='28'!G135 -> 0 | AE31: =AA31+AB31+AC31+AD31 -> 23.81 | AF31: =AV31+AW31+BF31+BG31 -> 3834.83 | AG31: =AF31/AE31 -> 161.05964 | AH31: ='28'!G136 -> -0.01 | AI31: ='28'!G137 -> 0 | AJ31: ='28'!G138 -> 0 | AK31: =AH31+AI31+AJ31 -> -0.01 | AL31: ='28'!G139 -> 7.97 | AM31: ='28'!G140 -> 0.47 | AO31: =AL31+AM31 -> 8.44 | AP31: ='28'!G123 -> 267.04 | AQ31: ='28'!G35 -> 0.33 | AR31: ='28'!G37 -> 0 | AS31: ='28'!G38 -> 0 | AT31: ='28'!G39 -> 0 | AU31: ='28'!G40 -> 0 | AV31: ='28'!G41 -> 3834.56 | AW31: ='28'!G42 -> 0 | AX31: ='28'!G43 -> 2323.05 | AY31: ='28'!G44 -> 0 | AZ31: ='28'!G36 -> 735.27 | BA31: ='28'!G49 -> 3272.55 | BB31: ='28'!G51 -> 1445.46 | BC31: ='28'!G52 -> 1734.21 | BD31: ='28'!G53 -> 4173 | BE31: ='28'!G54 -> 50.45 | BF31: ='28'!G55 -> 0.42 | BG31: ='28'!G56 -> -0.15 | BH31: ='28'!G57 -> 0 | BI31: ='28'!G50 -> 1462 | BJ31: =SUM(AV31,AW31,BF31,BG31) -> 3834.83 | BK31: ='28'!G84 -> 540 | BL31: =SUM(AQ31,AV31,AW31,AX31,BA31,BF31,BG31,BH31)/I31% -> 48.720153 | BM31: =SUM(AT31,BD31)/I31% -> 21.558093 | BN31: =(AS31+BC31)/I31 -> 0.089590846 | BO31: =K31+O31+R31+V31 -> 233564.1 | BP31: =SUM(AV31,AW31,AX31,BF31,BG31,BH31,BK31) -> 6697.88 | BQ31: =BP31/(AE31*280) -> 1.0046619
