Workbook

Sheet Total
A1: Site Name | B1: Day | C1: Month | D1: Year | E1: Total Electricity Kwh | F1: Electricity Tariff ($/Kwh) | G1: Total Fuel Oil (Liters) | H1: Fuel Oil $/Liter | I1: LPG (Kg) | J1: LPG $/Kg | K1: Water Utility Supply (m3) m3 | L1: Water Utility Supply (m3) $/m3 | M1: Irrigation Water (m3) m3 | N1: Irrigation water $/m3 | O1: Room Nights
A2: Beirut | B2: 1 | C2: 1 | D2: 2021 | E2: =ELEC!N3 -> 6404.4 | F2: =SUM('EDl log'!T4) -> 0.093949341 | G2: =-tanks!AW6 -> 467.6 | H2: =SUM(tanks!AV6) -> 0.1 | I2: =('B5'!AU5)*0.51 -> 0 | J2: ='B5'!AX5/0.51 -> 1.5686275 | K2: =WATER!I6 -> 0 | L2: =SUM(WATER!J6) -> 0 | M2: =WATER!Q6 -> 0 | N2: 0.6 | O2: =ELEC!B3 -> 0
A3: Beirut | B3: =B2+1 -> 2 | C3: 1 | D3: 2021 | E3: =ELEC!N4 -> 6622 | F3: =SUM('EDl log'!T5) -> 0.084333644 | G3: =-tanks!AW7 -> 234 | H3: =SUM(tanks!AV7) -> 0.1 | I3: =('B5'!AU6)*0.51 -> 0 | J3: ='B5'!AX6/0.51 -> 1.5686275 | K3: =WATER!I7 -> 0 | L3: =SUM(WATER!J7) -> 0 | M3: =WATER!Q7 -> 0 | N3: 0.6 | O3: =ELEC!B4 -> 0
A4: Beirut | B4: =B3+1 -> 3 | C4: 1 | D4: 2021 | E4: =ELEC!N5 -> 6753 | F4: =SUM('EDl log'!T6) -> 0.089263909 | G4: =-tanks!AW8 -> 289 | H4: =SUM(tanks!AV8) -> 0.1 | I4: =('B5'!AU7)*0.51 -> 0 | J4: ='B5'!AX7/0.51 -> 1.5686275 | K4: =WATER!I8 -> 0 | L4: =SUM(WATER!J8) -> 0 | M4: =WATER!Q8 -> 0 | N4: 0.6 | O4: =ELEC!B5 -> 0
A5: Beirut | B5: =B4+1 -> 4 | C5: 1 | D5: 2021 | E5: =ELEC!N6 -> 6587 | F5: =SUM('EDl log'!T7) -> 0.096457613 | G5: =-tanks!AW9 -> 314 | H5: =SUM(tanks!AV9) -> 0.1 | I5: =('B5'!AU8)*0.51 -> 0 | J5: ='B5'!AX8/0.51 -> 1.5686275 | K5: =WATER!I9 -> 0 | L5: =SUM(WATER!J9) -> 0 | M5: =WATER!Q9 -> 0 | N5: 0.6 | O5: =ELEC!B6 -> 0
A6: Beirut | B6: =B5+1 -> 5 | C6: 1 | D6: 2021 | E6: =ELEC!N7 -> 5932 | F6: =SUM('EDl log'!T8) -> 0.017181491 | G6: =-tanks!AW10 -> 391 | H6: =SUM(tanks!AV10) -> 0.674 | I6: =('B5'!AU9)*0.51 -> 0 | J6: ='B5'!AX9/0.51 -> 1.5686275 | K6: =WATER!I10 -> 0 | L6: =SUM(WATER!J10) -> 0 | M6: =WATER!Q10 -> 0 | N6: 0.6 | O6: =ELEC!B7 -> 0
A7: Beirut | B7: =B6+1 -> 6 | C7: 1 | D7: 2021 | E7: =ELEC!N8 -> 5977 | F7: =SUM('EDl log'!T9) -> 0.083584348 | G7: =-tanks!AW11 -> 311 | H7: =SUM(tanks!AV11) -> 0.674 | I7: =('B5'!AU10)*0.51 -> 0 | J7: ='B5'!AX10/0.51 -> 1.5686275 | K7: =WATER!I11 -> 0 | L7: =SUM(WATER!J11) -> 0 | M7: =WATER!Q11 -> 0 | N7: 0.6 | O7: =ELEC!B8 -> 0
A8: Beirut | B8: =B7+1 -> 7 | C8: 1 | D8: 2021 | E8: =ELEC!N9 -> 6551.2 | F8: =SUM('EDl log'!T10) -> 0.099245072 | G8: =-tanks!AW12 -> 279 | H8: =SUM(tanks!AV12) -> 0.674 | I8: =('B5'!AU11)*0.51 -> 0 | J8: ='B5'!AX11/0.51 -> 1.5686275 | K8: =WATER!I12 -> 0 | L8: =SUM(WATER!J12) -> 0 | M8: =WATER!Q12 -> 0 | N8: 0.6 | O8: =ELEC!B9 -> 0
A9: Beirut | B9: =B8+1 -> 8 | C9: 1 | D9: 2021 | E9: =ELEC!N10 -> 6289.8 | F9: =SUM('EDl log'!T11) -> 0.081623986 | G9: =-tanks!AW13 -> 333.4 | H9: =SUM(tanks!AV13) -> 0.674 | I9: =('B5'!AU12)*0.51 -> 0 | J9: ='B5'!AX12/0.51 -> 1.5686275 | K9: =WATER!I13 -> 0 | L9: =SUM(WATER!J13) -> 0 | M9: =WATER!Q13 -> 0 | N9: 0.6 | O9: =ELEC!B10 -> 0
A10: Beirut | B10: =B9+1 -> 9 | C10: 1 | D10: 2021 | E10: =ELEC!N11 -> 7008 | F10: =SUM('EDl log'!T12) -> 0.087597788 | G10: =-tanks!AW14 -> 236 | H10: =SUM(tanks!AV14) -> 0.674 | I10: =('B5'!AU13)*0.51 -> 0 | J10: ='B5'!AX13/0.51 -> 1.5686275 | K10: =WATER!I14 -> 0 | L10: =SUM(WATER!J14) -> 0 | M10: =WATER!Q14 -> 0 | N10: 0.6 | O10: =ELEC!B11 -> 0
A11: Beirut | B11: =B10+1 -> 10 | C11: 1 | D11: 2021 | E11: =ELEC!N12 -> 7276 | F11: =SUM('EDl log'!T13) -> 0.11594008 | G11: =-tanks!AW15 -> 236 | H11: =SUM(tanks!AV15) -> 0.674 | I11: =('B5'!AU14)*0.51 -> 0 | J11: ='B5'!AX14/0.51 -> 1.5686275 | K11: =WATER!I15 -> 0 | L11: =SUM(WATER!J15) -> 0 | M11: =WATER!Q15 -> 0 | N11: 0.6 | O11: =ELEC!B12 -> 0
A12: Beirut | B12: =B11+1 -> 11 | C12: 1 | D12: 2021 | E12: =ELEC!N13 -> 7236 | F12: =SUM('EDl log'!T14) -> 0.098706635 | G12: =-tanks!AW16 -> 253 | H12: =SUM(tanks!AV16) -> 0.674 | I12: =('B5'!AU15)*0.51 -> 0 | J12: ='B5'!AX15/0.51 -> 1.5686275 | K12: =WATER!I16 -> 0 | L12: =SUM(WATER!J16) -> 0 | M12: =WATER!Q16 -> 0 | N12: 0.6 | O12: =ELEC!B13 -> 0
A13: Beirut | B13: =B12+1 -> 12 | C13: 1 | D13: 2021 | E13: =ELEC!N14 -> 5643 | F13: =SUM('EDl log'!T15) -> 0.092903396 | G13: =-tanks!AW17 -> 234 | H13: =SUM(tanks!AV17) -> 0.674 | I13: =('B5'!AU16)*0.51 -> 0 | J13: ='B5'!AX16/0.51 -> 1.5686275 | K13: =WATER!I17 -> 0 | L13: =SUM(WATER!J17) -> 0 | M13: =WATER!Q17 -> 0 | N13: 0.6 | O13: =ELEC!B14 -> 0
A14: Beirut | B14: =B13+1 -> 13 | C14: 1 | D14: 2021 | E14: =ELEC!N15 -> 0 | F14: =SUM('EDl log'!T16) -> 0 | G14: =-tanks!AW18 -> 0 | H14: =SUM(tanks!AV18) -> 0.674 | I14: =('B5'!AU17)*0.51 -> 0 | J14: ='B5'!AX17/0.51 -> 1.5686275 | K14: =WATER!I18 -> 0 | L14: =SUM(WATER!J18) -> 0 | M14: =WATER!Q18 -> 0 | N14: 0.6 | O14: =ELEC!B15 -> 0
... A29: Beirut | B29: =B28+1 -> 28 | C29: 1 | D29: 2021 | E29: =ELEC!N30 -> 0 | F29: =SUM('EDl log'!T31) -> 0 | G29: =-tanks!AW33 -> 0 | H29: =SUM(tanks!AV33) -> 0.674 | I29: =('B5'!AU32)*0.51 -> 0 | J29: ='B5'!AX32/0.51 -> 1.5686275 | K29: =WATER!I33 -> 0 | L29: =SUM(WATER!J33) -> 0 | M29: =WATER!Q33 -> 0 | N29: 0.6 | O29: =ELEC!B30 -> 0

Sheet Submetering
A1: Site Name | B1: Day | C1: Month | D1: Year | E1: ATS1 Kwh | F1: ATS2 Kwh | G1: ATS3 Kwh | H1: ATS4 Kwh | I1: ATS5 Kwh | J1: Guest (m3) | K1: Kitchen & Laundry (m3) | L1: Room Nights
A2: Beirut | B2: 1 | C2: 1 | D2: 2021 | E2: =ELEC!M3 -> 1898 | F2: =ELEC!K3 -> 970 | G2: =ELEC!I3 -> 874 | H2: =ELEC!E3 -> 2060 | I2: =ELEC!G3 -> 602.4 | J2: =WATER!Y6 -> 0 | K2: =WATER!AJ6 -> 0 | L2: =ELEC!B3 -> 0
A3: Beirut | B3: =B2+1 -> 2 | C3: 1 | D3: 2021 | E3: =ELEC!M4 -> 2070 | F3: =ELEC!K4 -> 912 | G3: =ELEC!I4 -> 812 | H3: =ELEC!E4 -> 2192 | I3: =ELEC!G4 -> 636 | J3: =WATER!Y7 -> 0 | K3: =WATER!AJ7 -> 0 | L3: =ELEC!B4 -> 0
A4: Beirut | B4: =B3+1 -> 3 | C4: 1 | D4: 2021 | E4: =ELEC!M5 -> 1956 | F4: =ELEC!K5 -> 928 | G4: =ELEC!I5 -> 820 | H4: =ELEC!E5 -> 2410 | I4: =ELEC!G5 -> 639 | J4: =WATER!Y8 -> 0 | K4: =WATER!AJ8 -> 0 | L4: =ELEC!B5 -> 0
A5: Beirut | B5: =B4+1 -> 4 | C5: 1 | D5: 2021 | E5: =ELEC!M6 -> 1846 | F5: =ELEC!K6 -> 956 | G5: =ELEC!I6 -> 840 | H5: =ELEC!E6 -> 2294 | I5: =ELEC!G6 -> 651 | J5: =WATER!Y9 -> 0 | K5: =WATER!AJ9 -> 0 | L5: =ELEC!B6 -> 0
A6: Beirut | B6: =B5+1 -> 5 | C6: 1 | D6: 2021 | E6: =ELEC!M7 -> 1612 | F6: =ELEC!K7 -> 916 | G6: =ELEC!I7 -> 740 | H6: =ELEC!E7 -> 2056 | I6: =ELEC!G7 -> 608 | J6: =WATER!Y10 -> 0 | K6: =WATER!AJ10 -> 0 | L6: =ELEC!B7 -> 0
A7: Beirut | B7: =B6+1 -> 6 | C7: 1 | D7: 2021 | E7: =ELEC!M8 -> 1658 | F7: =ELEC!K8 -> 902 | G7: =ELEC!I8 -> 800 | H7: =ELEC!E8 -> 1952 | I7: =ELEC!G8 -> 665 | J7: =WATER!Y11 -> 0 | K7: =WATER!AJ11 -> 0 | L7: =ELEC!B8 -> 0
A8: Beirut | B8: =B7+1 -> 7 | C8: 1 | D8: 2021 | E8: =ELEC!M9 -> 1976 | F8: =ELEC!K9 -> 1446 | G8: =ELEC!I9 -> 816 | H8: =ELEC!E9 -> 1710 | I8: =ELEC!G9 -> 603.2 | J8: =WATER!Y12 -> 0 | K8: =WATER!AJ12 -> 0 | L8: =ELEC!B9 -> 0
A9: Beirut | B9: =B8+1 -> 8 | C9: 1 | D9: 2021 | E9: =ELEC!M10 -> 1758 | F9: =ELEC!K10 -> 1470 | G9: =ELEC!I10 -> 796 | H9: =ELEC!E10 -> 1662 | I9: =ELEC!G10 -> 603.8 | J9: =WATER!Y13 -> 0 | K9: =WATER!AJ13 -> 0 | L9: =ELEC!B10 -> 0
A10: Beirut | B10: =B9+1 -> 9 | C10: 1 | D10: 2021 | E10: =ELEC!M11 -> 1638 | F10: =ELEC!K11 -> 1918 | G10: =ELEC!I11 -> 876 | H10: =ELEC!E11 -> 1908 | I10: =ELEC!G11 -> 668 | J10: =WATER!Y14 -> 0 | K10: =WATER!AJ14 -> 0 | L10: =ELEC!B11 -> 0
A11: Beirut | B11: =B10+1 -> 10 | C11: 1 | D11: 2021 | E11: =ELEC!M12 -> 1680 | F11: =ELEC!K12 -> 2182 | G11: =ELEC!I12 -> 832 | H11: =ELEC!E12 -> 1948 | I11: =ELEC!G12 -> 634 | J11: =WATER!Y15 -> 0 | K11: =WATER!AJ15 -> 0 | L11: =ELEC!B12 -> 0
A12: Beirut | B12: =B11+1 -> 11 | C12: 1 | D12: 2021 | E12: =ELEC!M13 -> 1740 | F12: =ELEC!K13 -> 2034 | G12: =ELEC!I13 -> 888 | H12: =ELEC!E13 -> 1926 | I12: =ELEC!G13 -> 648 | J12: =WATER!Y16 -> 0 | K12: =WATER!AJ16 -> 0 | L12: =ELEC!B13 -> 0
A13: Beirut | B13: =B12+1 -> 12 | C13: 1 | D13: 2021 | E13: =ELEC!M14 -> 1352 | F13: =ELEC!K14 -> 1496 | G13: =ELEC!I14 -> 764 | H13: =ELEC!E14 -> 1422 | I13: =ELEC!G14 -> 609 | J13: =WATER!Y17 -> 0 | K13: =WATER!AJ17 -> 0 | L13: =ELEC!B14 -> 0
A14: Beirut | B14: =B13+1 -> 13 | C14: 1 | D14: 2021 | E14: =ELEC!M15 -> 0 | F14: =ELEC!K15 -> 0 | G14: =ELEC!I15 -> 0 | H14: =ELEC!E15 -> 0 | I14: =ELEC!G15 -> 0 | J14: =WATER!Y18 -> 0 | K14: =WATER!AJ18 -> 0 | L14: =ELEC!B15 -> 0
... A29: Beirut | B29: =B28+1 -> 28 | C29: 1 | D29: 2021 | E29: =ELEC!M30 -> 0 | F29: =ELEC!K30 -> 0 | G29: =ELEC!I30 -> 0 | H29: =ELEC!E30 -> 0 | I29: =ELEC!G30 -> 0 | J29: =WATER!Y33 -> 0 | K29: =WATER!AJ33 -> 0 | L29: =ELEC!B30 -> 0

Sheet ELEC
A1: OOC | B1: Room OCC | D1: MDB3 | E1: MDB3/day | F1: EMDB2 | G1: EMDB2/day | H1: EMDB1 | I1: EMDB1/day | J1: MDB2 | K1: mdb2/day | L1: MDB1 | M1: MDB1/Day | N1: Total KWH | O1: KWH/Rooc | P1: Gen MHW | Q1: Gen/Day KWH | R1: EDL KWH | S1: CH1 RH | T1: RH | U1: C1h1 power | V1: CH1 Con KWH | W1: CH2 RH | X1: RH | Y1: Ch2 power | Z1: CH2 Con KWH | AA1: CH3 RH | AB1: RH | AC1: Ch3 power | AD1: CH3 Con KWH | AE1: RH total | AF1: KWH total | AG1: AVG chiller KW/Hr
A2: =[1]ELEC!A33 -> 0 | B2: =[1]ELEC!B33 -> 0 | C2: =[2]ELEC!$C$33 -> 44227 | D2: =[2]ELEC!D33 -> 32583138 | E2: =[2]ELEC!E33 -> 2268 | F2: =[2]ELEC!F33 -> 3954026.6 | G2: =[2]ELEC!G33 -> 559 | H2: =[2]ELEC!H33 -> 17779688 | I2: =[2]ELEC!I33 -> 842 | J2: =[2]ELEC!J33 -> 28877552 | K2: =[2]ELEC!K33 -> 1066 | ... AG2: =[2]ELEC!AG33 -> 159.25 | AH2: =[1]ELEC!AH33 -> 0 | AI2: =[1]ELEC!AI33 -> -770946 | AJ2: =[1]ELEC!AJ33 -> 0 | AK2: =[1]ELEC!AK33 -> 0 | AL2: =[1]ELEC!AL33 -> 0 | AM2: =[1]ELEC!AM33 -> 0 | AN2: =[1]ELEC!AN33 -> 0 | AO2: =[1]ELEC!AO33 -> 0 | ... DD2: =[1]ELEC!DD33 -> 0
A3: ='General information '!F6 -> 0 | B3: =SUM(230*A3) -> 0 | C3: 44228 | D3: 32585198 | E3: =D3-D2 -> 2060 | F3: 3954629 | G3: =F3-F2 -> 602.4 | H3: 17780562 | I3: =H3-H2 -> 874 | J3: 28878522 | K3: =J3-J2 -> 970 | L3: 23999456 | M3: =L3-L2 -> 1898 | N3: =M3+K3+I3+G3+E3 -> 6404.4 | O3: =IF(B3>0,N3/B3,0) -> 0 | P3: 16577.595 | Q3: =(P3-P2)*1000 -> 1968 | R3: =+N3-Q3 -> 4436.4 | S3: =S2 -> 10118 | T3: =S3-S2 -> 0 | U3: =U2 -> 420722 | V3: =U3-U2 -> 0 | W3: =W2 -> 32167 | X3: =W3-W2 -> 0 | Y3: =Y2 -> 696352 | Z3: =Y3-Y2 -> 0 | AA3: 35673 | AB3: =AA3-AA2 -> 2 | AC3: 912749 | AD3: =AC3-AC2 -> 397 | AE3: =AB3+X3+T3 -> 2 | AF3: =V3+Z3+AD3 -> 397 | AG3: =IF(AE3>0,AF3/AE3,0) -> 198.5
A4: ='General information '!F7 -> 0 | B4: =SUM(230*A4) -> 0 | C4: 44229 | D4: 32587390 | E4: =D4-D3 -> 2192 | F4: 3955265 | G4: =F4-F3 -> 636 | H4: 17781374 | I4: =H4-H3 -> 812 | J4: 28879434 | K4: =J4-J3 -> 912 | L4: 24001526 | M4: =L4-L3 -> 2070 | N4: =M4+K4+I4+G4+E4 -> 6622 | O4: =IF(B4>0,N4/B4,0) -> 0 | P4: 16579.85 | Q4: =(P4-P3)*1000 -> 2255 | R4: =N4-Q4 -> 4367 | S4: =S3 -> 10118 | T4: =S4-S3 -> 0 | U4: =U3 -> 420722 | V4: =U4-U3 -> 0 | W4: =W3 -> 32167 | X4: =W4-W3 -> 0 | Y4: =Y3 -> 696352 | Z4: =Y4-Y3 -> 0 | AA4: 35677 | AB4: =AA4-AA3 -> 4 | AC4: 913263 | AD4: =AC4-AC3 -> 514 | AE4: =AB4+X4+T4 -> 4 | AF4: =V4+Z4+AD4 -> 514 | AG4: =IF(AE4>0,AF4/AE4,0) -> 128.5
A5: ='General information '!F8 -> 0 | B5: =SUM(230*A5) -> 0 | C5: 44230 | D5: 32589800 | E5: =D5-D4 -> 2410 | F5: 3955904 | G5: =F5-F4 -> 639 | H5: 17782194 | I5: =H5-H4 -> 820 | J5: 28880362 | K5: =J5-J4 -> 928 | L5: 24003482 | M5: =L5-L4 -> 1956 | N5: =M5+K5+I5+G5+E5 -> 6753 | O5: =IF(B5>0,N5/B5,0) -> 0 | P5: 16582.771 | Q5: =(P5-P4)*1000 -> 2921 | R5: =N5-Q5 -> 3832 | S5: =S4 -> 10118 | T5: =S5-S4 -> 0 | U5: =U4 -> 420722 | V5: =U5-U4 -> 0 | W5: =W4 -> 32167 | X5: =W5-W4 -> 0 | Y5: =Y4 -> 696352 | Z5: =Y5-Y4 -> 0 | AA5: 35680 | AB5: =AA5-AA4 -> 3 | AC5: 913951 | AD5: =AC5-AC4 -> 688 | AE5: =AB5+X5+T5 -> 3 | AF5: =V5+Z5+AD5 -> 688 | AG5: =IF(AE5>0,AF5/AE5,0) -> 229.33333 | AI5: =R5-'EDl log'!B3 -> -849794
A6: ='General information '!F9 -> 0 | B6: =SUM(230*A6) -> 0 | C6: 44231 | D6: 32592094 | E6: =D6-D5 -> 2294 | F6: 3956555 | G6: =F6-F5 -> 651 | H6: 17783034 | I6: =H6-H5 -> 840 | J6: 28881318 | K6: =J6-J5 -> 956 | L6: 24005328 | M6: =L6-L5 -> 1846 | N6: =M6+K6+I6+G6+E6 -> 6587 | O6: =IF(B6>0,N6/B6,0) -> 0 | P6: 16585.395 | Q6: =(P6-P5)*1000 -> 2624 | R6: =N6-Q6 -> 3963 | S6: =S5 -> 10118 | T6: =S6-S5 -> 0 | U6: =U5 -> 420722 | V6: =U6-U5 -> 0 | W6: =W5 -> 32167 | X6: =W6-W5 -> 0 | Y6: =Y5 -> 696352 | Z6: =Y6-Y5 -> 0 | AA6: 35684 | AB6: =AA6-AA5 -> 4 | AC6: 914499 | AD6: =AC6-AC5 -> 548 | AE6: =AB6+X6+T6 -> 4 | AF6: =V6+Z6+AD6 -> 548 | AG6: =IF(AE6>0,AF6/AE6,0) -> 137 | AI6: =R6-'EDl log'!B4 -> -852163
A7: ='General information '!F10 -> 0 | B7: =SUM(230*A7) -> 0 | C7: 44232 | D7: 32594150 | E7: =D7-D6 -> 2056 | F7: 3957163 | G7: =F7-F6 -> 608 | H7: 17783774 | I7: =H7-H6 -> 740 | J7: 28882234 | K7: =J7-J6 -> 916 | L7: 24006940 | M7: =L7-L6 -> 1612 | N7: =M7+K7+I7+G7+E7 -> 5932 | O7: =IF(B7>0,N7/B7,0) -> 0 | P7: 16587.36 | Q7: =(P7-P6)*1000 -> 1965 | R7: =N7-Q7 -> 3967 | S7: =S6 -> 10118 | T7: =S7-S6 -> 0 | U7: =U6 -> 420722 | V7: =U7-U6 -> 0 | W7: =W6 -> 32167 | X7: =W7-W6 -> 0 | Y7: =Y6 -> 696352 | Z7: =Y7-Y6 -> 0 | AA7: 35687 | AB7: =AA7-AA6 -> 3 | AC7: 914939 | AD7: =AC7-AC6 -> 440 | AE7: =AB7+X7+T7 -> 3 | AF7: =V7+Z7+AD7 -> 440 | AG7: =IF(AE7>0,AF7/AE7,0) -> 146.66667 | AI7: =R7-'EDl log'!B5 -> -854387
A8: ='General information '!F11 -> 0 | B8: =SUM(230*A8) -> 0 | C8: 44233 | D8: 32596102 | E8: =D8-D7 -> 1952 | F8: 3957828 | G8: =F8-F7 -> 665 | H8: 17784574 | I8: =H8-H7 -> 800 | J8: 28883136 | K8: =J8-J7 -> 902 | L8: 24008598 | M8: =L8-L7 -> 1658 | N8: =M8+K8+I8+G8+E8 -> 5977 | O8: =IF(B8>0,N8/B8,0) -> 0 | P8: 16589.054 | Q8: =(P8-P7)*1000 -> 1694 | R8: =N8-Q8 -> 4283 | S8: =S7 -> 10118 | T8: =S8-S7 -> 0 | U8: =U7 -> 420722 | V8: =U8-U7 -> 0 | W8: =W7 -> 32167 | X8: =W8-W7 -> 0 | Y8: =Y7 -> 696352 | Z8: =Y8-Y7 -> 0 | AA8: 35689 | AB8: =AA8-AA7 -> 2 | AC8: 915313 | AD8: =AC8-AC7 -> 374 | AE8: =AB8+X8+T8 -> 2 | AF8: =V8+Z8+AD8 -> 374 | AG8: =IF(AE8>0,AF8/AE8,0) -> 187 | AI8: =R8-'EDl log'!B6 -> -856158
A9: ='General information '!F12 -> 0 | B9: =SUM(230*A9) -> 0 | C9: 44234 | D9: 32597812 | E9: =D9-D8 -> 1710 | F9: 3958431.2 | G9: =F9-F8 -> 603.2 | H9: 17785390 | I9: =H9-H8 -> 816 | J9: 28884582 | K9: =J9-J8 -> 1446 | L9: 24010574 | M9: =L9-L8 -> 1976 | N9: =M9+K9+I9+G9+E9 -> 6551.2 | O9: =IF(B9>0,N9/B9,0) -> 0 | P9: 16591.098 | Q9: =(P9-P8)*1000 -> 2044 | R9: =N9-Q9 -> 4507.2 | S9: =S8 -> 10118 | T9: =S9-S8 -> 0 | U9: =U8 -> 420722 | V9: =U9-U8 -> 0 | W9: 32169 | X9: =W9-W8 -> 2 | Y9: 696833 | Z9: =Y9-Y8 -> 481 | AA9: =AA8 -> 35689 | AB9: =AA9-AA8 -> 0 | AC9: 915313 | AD9: =AC9-AC8 -> 0 | AE9: =AB9+X9+T9 -> 2 | AF9: =V9+Z9+AD9 -> 481 | AG9: =IF(AE9>0,AF9/AE9,0) -> 240.5 | AI9: =R9-'EDl log'!B7 -> -858088.8
A10: ='General information '!F13 -> 0 | B10: =SUM(230*A10) -> 0 | C10: 44235 | D10: 32599474 | E10: =D10-D9 -> 1662 | F10: 3959035 | G10: =F10-F9 -> 603.8 | H10: 17786186 | I10: =H10-H9 -> 796 | J10: 28886052 | K10: =J10-J9 -> 1470 | L10: 24012332 | M10: =L10-L9 -> 1758 | N10: =M10+K10+I10+G10+E10 -> 6289.8 | O10: =IF(B10>0,N10/B10,0) -> 0 | P10: 16593.143 | Q10: =(P10-P9)*1000 -> 2045 | R10: =N10-Q10 -> 4244.8 | S10: =S9 -> 10118 | T10: =S10-S9 -> 0 | U10: =U9 -> 420722 | V10: =U10-U9 -> 0 | W10: 32172 | X10: =W10-W9 -> 3 | Y10: 697351 | Z10: =Y10-Y9 -> 518 | AA10: =AA9 -> 35689 | AB10: =AA10-AA9 -> 0 | AC10: =AC9 -> 915313 | AD10: =AC10-AC9 -> 0 | AE10: =AB10+X10+T10 -> 3 | AF10: =V10+Z10+AD10 -> 518 | AG10: =IF(AE10>0,AF10/AE10,0) -> 172.66667 | AI10: =R10-'EDl log'!B8 -> -860497.2
A11: ='General information '!F14 -> 0 | B11: =SUM(230*A11) -> 0 | C11: 44236 | D11: 32601382 | E11: =D11-D10 -> 1908 | F11: 3959703 | G11: =F11-F10 -> 668 | H11: 17787062 | I11: =H11-H10 -> 876 | J11: 28887970 | K11: =J11-J10 -> 1918 | L11: 24013970 | M11: =L11-L10 -> 1638 | N11: =M11+K11+I11+G11+E11 -> 7008 | O11: =IF(B11>0,N11/B11,0) -> 0 | P11: 16596.579 | Q11: =(P11-P10)*1000 -> 3436 | R11: =N11-Q11 -> 3572 | S11: =S10 -> 10118 | T11: =S11-S10 -> 0 | U11: =U10 -> 420722 | V11: =U11-U10 -> 0 | W11: 32176 | X11: =W11-W10 -> 4 | Y11: 698227 | Z11: =Y11-Y10 -> 876 | AA11: =AA10 -> 35689 | AB11: =AA11-AA10 -> 0 | AC11: =AC10 -> 915313 | AD11: =AC11-AC10 -> 0 | AE11: =AB11+X11+T11 -> 4 | AF11: =V11+Z11+AD11 -> 876 | AG11: =IF(AE11>0,AF11/AE11,0) -> 219 | AI11: =R11-'EDl log'!B9 -> -863499
A12: ='General information '!F15 -> 0 | B12: =SUM(230*A12) -> 0 | C12: 44237 | D12: 32603330 | E12: =D12-D11 -> 1948 | F12: 3960337 | G12: =F12-F11 -> 634 | H12: 17787894 | I12: =H12-H11 -> 832 | J12: 28890152 | K12: =J12-J11 -> 2182 | L12: 24015650 | M12: =L12-L11 -> 1680 | N12: =M12+K12+I12+G12+E12 -> 7276 | O12: =IF(B12>0,N12/B12,0) -> 0 | P12: 16601.021 | Q12: =(P12-P11)*1000 -> 4442 | R12: =N12-Q12 -> 2834 | S12: =S11 -> 10118 | T12: =S12-S11 -> 0 | U12: =U11 -> 420722 | V12: =U12-U11 -> 0 | W12: 32182 | X12: =W12-W11 -> 6 | Y12: 699173 | Z12: =Y12-Y11 -> 946 | AA12: 35689 | AB12: =AA12-AA11 -> 0 | AC12: =AC11 -> 915313 | AD12: =AC12-AC11 -> 0 | AE12: =AB12+X12+T12 -> 6 | AF12: =V12+Z12+AD12 -> 946 | AG12: =IF(AE12>0,AF12/AE12,0) -> 157.66667 | AI12: =R12-'EDl log'!B10 -> -866646
A13: ='General information '!F16 -> 0 | B13: =SUM(230*A13) -> 0 | C13: 44238 | D13: 32605256 | E13: =D13-D12 -> 1926 | F13: 3960985 | G13: =F13-F12 -> 648 | H13: 17788782 | I13: =H13-H12 -> 888 | J13: 28892186 | K13: =J13-J12 -> 2034 | L13: 24017390 | M13: =L13-L12 -> 1740 | N13: =M13+K13+I13+G13+E13 -> 7236 | O13: =IF(B13>0,N13/B13,0) -> 0 | P13: 16605.02 | Q13: =(P13-P12)*1000 -> 3999 | R13: =N13-Q13 -> 3237 | S13: =S12 -> 10118 | T13: =S13-S12 -> 0 | U13: =U12 -> 420722 | V13: =U13-U12 -> 0 | W13: 32187 | X13: =W13-W12 -> 5 | Y13: 699988 | Z13: =Y13-Y12 -> 815 | AA13: =AA12 -> 35689 | AB13: =AA13-AA12 -> 0 | AC13: =AC12 -> 915313 | AD13: =AC13-AC12 -> 0 | AE13: =AB13+X13+T13 -> 5 | AF13: =V13+Z13+AD13 -> 815 | AG13: =IF(AE13>0,AF13/AE13,0) -> 163 | AI13: =R13-'EDl log'!B11 -> -868526
A14: ='General information '!F17 -> 0 | B14: =SUM(230*A14) -> 0 | C14: 44239 | D14: 32606678 | E14: =D14-D13 -> 1422 | F14: 3961594 | G14: =F14-F13 -> 609 | H14: 17789546 | I14: =H14-H13 -> 764 | J14: 28893682 | K14: =J14-J13 -> 1496 | L14: 24018742 | M14: =L14-L13 -> 1352 | N14: =M14+K14+I14+G14+E14 -> 5643 | O14: =IF(B14>0,N14/B14,0) -> 0 | P14: 16607.648 | Q14: =(P14-P13)*1000 -> 2628 | R14: =N14-Q14 -> 3015 | S14: =S13 -> 10118 | T14: =S14-S13 -> 0 | U14: =U13 -> 420722 | V14: =U14-U13 -> 0 | W14: 32191 | X14: =W14-W13 -> 4 | Y14: 700543 | Z14: =Y14-Y13 -> 555 | AA14: =AA13 -> 35689 | AB14: =AA14-AA13 -> 0 | AC14: =AC13 -> 915313 | AD14: =AC14-AC13 -> 0 | AE14: =AB14+X14+T14 -> 4 | AF14: =V14+Z14+AD14 -> 555 | AG14: =IF(AE14>0,AF14/AE14,0) -> 138.75 | AI14: =R14-'EDl log'!B12 -> -870707
A15: ='General information '!F18 -> 0 | B15: =SUM(230*A15) -> 0 | C15: 44240 | D15: =D14 -> 32606678 | E15: =D15-D14 -> 0 | F15: =F14 -> 3961594 | G15: =F15-F14 -> 0 | H15: =H14 -> 17789546 | I15: =H15-H14 -> 0 | J15: =J14 -> 28893682 | K15: =J15-J14 -> 0 | L15: =L14 -> 24018742 | M15: =L15-L14 -> 0 | N15: =M15+K15+I15+G15+E15 -> 0 | O15: =IF(B15>0,N15/B15,0) -> 0 | P15: =P14 -> 16607.648 | Q15: =(P15-P14)*1000 -> 0 | R15: =N15-Q15 -> 0 | S15: =S14 -> 10118 | T15: =S15-S14 -> 0 | U15: =U14 -> 420722 | V15: =U15-U14 -> 0 | W15: =W14 -> 32191 | X15: =W15-W14 -> 0 | Y15: =Y14 -> 700543 | Z15: =Y15-Y14 -> 0 | AA15: =AA14 -> 35689 | AB15: =AA15-AA14 -> 0 | AC15: =AC14 -> 915313 | AD15: =AC15-AC14 -> 0 | AE15: =AB15+X15+T15 -> 0 | AF15: =V15+Z15+AD15 -> 0 | AG15: =IF(AE15>0,AF15/AE15,0) -> 0 | AI15: =R15-'EDl log'!B13 -> -875296
A16: ='General information '!F19 -> 0 | B16: =SUM(230*A16) -> 0 | C16: 44241 | D16: =D15 -> 32606678 | E16: =D16-D15 -> 0 | F16: =F15 -> 3961594 | G16: =F16-F15 -> 0 | H16: =H15 -> 17789546 | I16: =H16-H15 -> 0 | J16: =J15 -> 28893682 | K16: =J16-J15 -> 0 | L16: =L15 -> 24018742 | M16: =L16-L15 -> 0 | N16: =M16+K16+I16+G16+E16 -> 0 | O16: =IF(B16>0,N16/B16,0) -> 0 | P16: =P15 -> 16607.648 | Q16: =(P16-P15)*1000 -> 0 | R16: =N16-Q16 -> 0 | S16: =S15 -> 10118 | T16: =S16-S15 -> 0 | U16: =U15 -> 420722 | V16: =U16-U15 -> 0 | W16: =W15 -> 32191 | X16: =W16-W15 -> 0 | Y16: =Y15 -> 700543 | Z16: =Y16-Y15 -> 0 | AA16: =AA15 -> 35689 | AB16: =AA16-AA15 -> 0 | AC16: =AC15 -> 915313 | AD16: =AC16-AC15 -> 0 | AE16: =AB16+X16+T16 -> 0 | AF16: =V16+Z16+AD16 -> 0 | AG16: =IF(AE16>0,AF16/AE16,0) -> 0 | AI16: =R16-'EDl log'!B14 -> -877076
A17: ='General information '!F20 -> 0 | B17: =SUM(230*A17) -> 0 | C17: 44242 | D17: =D16 -> 32606678 | E17: =D17-D16 -> 0 | F17: =F16 -> 3961594 | G17: =F17-F16 -> 0 | H17: =H16 -> 17789546 | I17: =H17-H16 -> 0 | J17: =J16 -> 28893682 | K17: =J17-J16 -> 0 | L17: =L16 -> 24018742 | M17: =L17-L16 -> 0 | N17: =M17+K17+I17+G17+E17 -> 0 | O17: =IF(B17>0,N17/B17,0) -> 0 | P17: =P16 -> 16607.648 | Q17: =(P17-P16)*1000 -> 0 | R17: =N17-Q17 -> 0 | S17: =S16 -> 10118 | T17: =S17-S16 -> 0 | U17: =U16 -> 420722 | V17: =U17-U16 -> 0 | W17: =W16 -> 32191 | X17: =W17-W16 -> 0 | Y17: =Y16 -> 700543 | Z17: =Y17-Y16 -> 0 | AA17: =AA16 -> 35689 | AB17: =AA17-AA16 -> 0 | AC17: =AC16 -> 915313 | AD17: =AC17-AC16 -> 0 | AE17: =AB17+X17+T17 -> 0 | AF17: =V17+Z17+AD17 -> 0 | AG17: =IF(AE17>0,AF17/AE17,0) -> 0 | AI17: =R17-'EDl log'!B15 -> -878743
A18: ='General information '!F21 -> 0 | B18: =SUM(230*A18) -> 0 | C18: 44243 | D18: =D17 -> 32606678 | E18: =D18-D17 -> 0 | F18: =F17 -> 3961594 | G18: =F18-F17 -> 0 | H18: =H17 -> 17789546 | I18: =H18-H17 -> 0 | J18: =J17 -> 28893682 | K18: =J18-J17 -> 0 | L18: =L17 -> 24018742 | M18: =L18-L17 -> 0 | N18: =M18+K18+I18+G18+E18 -> 0 | O18: =IF(B18>0,N18/B18,0) -> 0 | P18: =P17 -> 16607.648 | Q18: =(P18-P17)*1000 -> 0 | R18: =N18-Q18 -> 0 | S18: =S17 -> 10118 | T18: =S18-S17 -> 0 | U18: =U17 -> 420722 | V18: =U18-U17 -> 0 | W18: =W17 -> 32191 | X18: =W18-W17 -> 0 | Y18: =Y17 -> 700543 | Z18: =Y18-Y17 -> 0 | AA18: =AA17 -> 35689 | AB18: =AA18-AA17 -> 0 | AC18: =AC17 -> 915313 | AD18: =AC18-AC17 -> 0 | AE18: =AB18+X18+T18 -> 0 | AF18: =V18+Z18+AD18 -> 0 | AG18: =IF(AE18>0,AF18/AE18,0) -> 0 | AI18: =R18-'EDl log'!B16 -> -878743
A19: ='General information '!F22 -> 0 | B19: =SUM(230*A19) -> 0 | C19: 44244 | D19: =D18 -> 32606678 | E19: =D19-D18 -> 0 | F19: =F18 -> 3961594 | G19: =F19-F18 -> 0 | H19: =H18 -> 17789546 | I19: =H19-H18 -> 0 | J19: =J18 -> 28893682 | K19: =J19-J18 -> 0 | L19: =L18 -> 24018742 | M19: =L19-L18 -> 0 | N19: =M19+K19+I19+G19+E19 -> 0 | O19: =IF(B19>0,N19/B19,0) -> 0 | P19: =P18 -> 16607.648 | Q19: =(P19-P18)*1000 -> 0 | R19: =N19-Q19 -> 0 | S19: =S18 -> 10118 | T19: =S19-S18 -> 0 | U19: =U18 -> 420722 | V19: =U19-U18 -> 0 | W19: =W18 -> 32191 | X19: =W19-W18 -> 0 | Y19: =Y18 -> 700543 | Z19: =Y19-Y18 -> 0 | AA19: =AA18 -> 35689 | AB19: =AA19-AA18 -> 0 | AC19: =AC18 -> 915313 | AD19: =AC19-AC18 -> 0 | AE19: =AB19+X19+T19 -> 0 | AF19: =V19+Z19+AD19 -> 0 | AG19: =IF(AE19>0,AF19/AE19,0) -> 0 | AI19: =R19-'EDl log'!B17 -> -878743
A20: ='General information '!F23 -> 0 | B20: =SUM(230*A20) -> 0 | C20: 44245 | D20: =D19 -> 32606678 | E20: =D20-D19 -> 0 | F20: =F19 -> 3961594 | G20: =F20-F19 -> 0 | H20: =H19 -> 17789546 | I20: =H20-H19 -> 0 | J20: =J19 -> 28893682 | K20: =J20-J19 -> 0 | L20: =L19 -> 24018742 | M20: =L20-L19 -> 0 | N20: =M20+K20+I20+G20+E20 -> 0 | O20: =IF(B20>0,N20/B20,0) -> 0 | P20: =P19 -> 16607.648 | Q20: =(P20-P19)*1000 -> 0 | R20: =N20-Q20 -> 0 | S20: =S19 -> 10118 | T20: =S20-S19 -> 0 | U20: =U19 -> 420722 | V20: =U20-U19 -> 0 | W20: =W19 -> 32191 | X20: =W20-W19 -> 0 | Y20: =Y19 -> 700543 | Z20: =Y20-Y19 -> 0 | AA20: =AA19 -> 35689 | AB20: =AA20-AA19 -> 0 | AC20: =AC19 -> 915313 | AD20: =AC20-AC19 -> 0 | AE20: =AB20+X20+T20 -> 0 | AF20: =V20+Z20+AD20 -> 0 | AG20: =IF(AE20>0,AF20/AE20,0) -> 0 | AI20: =R20-'EDl log'!B18 -> -878743
A21: ='General information '!F24 -> 0 | B21: =SUM(230*A21) -> 0 | C21: 44246 | D21: =D20 -> 32606678 | E21: =D21-D20 -> 0 | F21: =F20 -> 3961594 | G21: =F21-F20 -> 0 | H21: =H20 -> 17789546 | I21: =H21-H20 -> 0 | J21: =J20 -> 28893682 | K21: =J21-J20 -> 0 | L21: =L20 -> 24018742 | M21: =L21-L20 -> 0 | N21: =M21+K21+I21+G21+E21 -> 0 | O21: =IF(B21>0,N21/B21,0) -> 0 | P21: =P20 -> 16607.648 | Q21: =(P21-P20)*1000 -> 0 | R21: =N21-Q21 -> 0 | S21: =S20 -> 10118 | T21: =S21-S20 -> 0 | U21: =U20 -> 420722 | V21: =U21-U20 -> 0 | W21: =W20 -> 32191 | X21: =W21-W20 -> 0 | Y21: =Y20 -> 700543 | Z21: =Y21-Y20 -> 0 | AA21: =AA20 -> 35689 | AB21: =AA21-AA20 -> 0 | AC21: =AC20 -> 915313 | AD21: =AC21-AC20 -> 0 | AE21: =AB21+X21+T21 -> 0 | AF21: =V21+Z21+AD21 -> 0 | AG21: =IF(AE21>0,AF21/AE21,0) -> 0 | AI21: =R21-'EDl log'!B19 -> -878743
A22: ='General information '!F25 -> 0 | B22: =SUM(230*A22) -> 0 | C22: 44247 | D22: =D21 -> 32606678 | E22: =D22-D21 -> 0 | F22: =F21 -> 3961594 | G22: =F22-F21 -> 0 | H22: =H21 -> 17789546 | I22: =H22-H21 -> 0 | J22: =J21 -> 28893682 | K22: =J22-J21 -> 0 | L22: =L21 -> 24018742 | M22: =L22-L21 -> 0 | N22: =M22+K22+I22+G22+E22 -> 0 | O22: =IF(B22>0,N22/B22,0) -> 0 | P22: =P21 -> 16607.648 | Q22: =(P22-P21)*1000 -> 0 | R22: =N22-Q22 -> 0 | S22: =S21 -> 10118 | T22: =S22-S21 -> 0 | U22: =U21 -> 420722 | V22: =U22-U21 -> 0 | W22: =W21 -> 32191 | X22: =W22-W21 -> 0 | Y22: =Y21 -> 700543 | Z22: =Y22-Y21 -> 0 | AA22: =AA21 -> 35689 | AB22: =AA22-AA21 -> 0 | AC22: =AC21 -> 915313 | AD22: =AC22-AC21 -> 0 | AE22: =AB22+X22+T22 -> 0 | AF22: =V22+Z22+AD22 -> 0 | AG22: =IF(AE22>0,AF22/AE22,0) -> 0 | AI22: =R22-'EDl log'!B20 -> -878743
A23: ='General information '!F26 -> 0 | B23: =SUM(230*A23) -> 0 | C23: 44248 | D23: =D22 -> 32606678 | E23: =D23-D22 -> 0 | F23: =F22 -> 3961594 | G23: =F23-F22 -> 0 | H23: =H22 -> 17789546 | I23: =H23-H22 -> 0 | J23: =J22 -> 28893682 | K23: =J23-J22 -> 0 | L23: =L22 -> 24018742 | M23: =L23-L22 -> 0 | N23: =M23+K23+I23+G23+E23 -> 0 | O23: =IF(B23>0,N23/B23,0) -> 0 | P23: =P22 -> 16607.648 | Q23: =(P23-P22)*1000 -> 0 | R23: =N23-Q23 -> 0 | S23: =S22 -> 10118 | T23: =S23-S22 -> 0 | U23: =U22 -> 420722 | V23: =U23-U22 -> 0 | W23: =W22 -> 32191 | X23: =W23-W22 -> 0 | Y23: =Y22 -> 700543 | Z23: =Y23-Y22 -> 0 | AA23: =AA22 -> 35689 | AB23: =AA23-AA22 -> 0 | AC23: =AC22 -> 915313 | AD23: =AC23-AC22 -> 0 | AE23: =AB23+X23+T23 -> 0 | AF23: =V23+Z23+AD23 -> 0 | AG23: =IF(AE23>0,AF23/AE23,0) -> 0 | AI23: =R23-'EDl log'!B21 -> -878743
A24: ='General information '!F27 -> 0 | B24: =SUM(230*A24) -> 0 | C24: 44249 | D24: =D23 -> 32606678 | E24: =D24-D23 -> 0 | F24: =F23 -> 3961594 | G24: =F24-F23 -> 0 | H24: =H23 -> 17789546 | I24: =H24-H23 -> 0 | J24: =J23 -> 28893682 | K24: =J24-J23 -> 0 | L24: =L23 -> 24018742 | M24: =L24-L23 -> 0 | N24: =M24+K24+I24+G24+E24 -> 0 | O24: =IF(B24>0,N24/B24,0) -> 0 | P24: =P23 -> 16607.648 | Q24: =(P24-P23)*1000 -> 0 | R24: =N24-Q24 -> 0 | S24: =S23 -> 10118 | T24: =S24-S23 -> 0 | U24: =U23 -> 420722 | V24: =U24-U23 -> 0 | W24: =W23 -> 32191 | X24: =W24-W23 -> 0 | Y24: =Y23 -> 700543 | Z24: =Y24-Y23 -> 0 | AA24: =AA23 -> 35689 | AB24: =AA24-AA23 -> 0 | AC24: =AC23 -> 915313 | AD24: =AC24-AC23 -> 0 | AE24: =AB24+X24+T24 -> 0 | AF24: =V24+Z24+AD24 -> 0 | AG24: =IF(AE24>0,AF24/AE24,0) -> 0 | AI24: =R24-'EDl log'!B22 -> -878743
A25: ='General information '!F28 -> 0 | B25: =SUM(230*A25) -> 0 | C25: 44250 | D25: =D24 -> 32606678 | E25: =D25-D24 -> 0 | F25: =F24 -> 3961594 | G25: =F25-F24 -> 0 | H25: =H24 -> 17789546 | I25: =H25-H24 -> 0 | J25: =J24 -> 28893682 | K25: =J25-J24 -> 0 | L25: =L24 -> 24018742 | M25: =L25-L24 -> 0 | N25: =M25+K25+I25+G25+E25 -> 0 | O25: =IF(B25>0,N25/B25,0) -> 0 | P25: =P24 -> 16607.648 | Q25: =(P25-P24)*1000 -> 0 | R25: =N25-Q25 -> 0 | S25: =S24 -> 10118 | T25: =S25-S24 -> 0 | U25: =U24 -> 420722 | V25: =U25-U24 -> 0 | W25: =W24 -> 32191 | X25: =W25-W24 -> 0 | Y25: =Y24 -> 700543 | Z25: =Y25-Y24 -> 0 | AA25: =AA24 -> 35689 | AB25: =AA25-AA24 -> 0 | AC25: =AC24 -> 915313 | AD25: =AC25-AC24 -> 0 | AE25: =AB25+X25+T25 -> 0 | AF25: =V25+Z25+AD25 -> 0 | AG25: =IF(AE25>0,AF25/AE25,0) -> 0 | AI25: =R25-'EDl log'!B23 -> -878743
A26: ='General information '!F29 -> 0 | B26: =SUM(230*A26) -> 0 | C26: 44251 | D26: =D25 -> 32606678 | E26: =D26-D25 -> 0 | F26: =F25 -> 3961594 | G26: =F26-F25 -> 0 | H26: =H25 -> 17789546 | I26: =H26-H25 -> 0 | J26: =J25 -> 28893682 | K26: =J26-J25 -> 0 | L26: =L25 -> 24018742 | M26: =L26-L25 -> 0 | N26: =M26+K26+I26+G26+E26 -> 0 | O26: =IF(B26>0,N26/B26,0) -> 0 | P26: =P25 -> 16607.648 | Q26: =(P26-P25)*1000 -> 0 | R26: =N26-Q26 -> 0 | S26: =S25 -> 10118 | T26: =S26-S25 -> 0 | U26: =U25 -> 420722 | V26: =U26-U25 -> 0 | W26: =W25 -> 32191 | X26: =W26-W25 -> 0 | Y26: =Y25 -> 700543 | Z26: =Y26-Y25 -> 0 | AA26: =AA25 -> 35689 | AB26: =AA26-AA25 -> 0 | AC26: =AC25 -> 915313 | AD26: =AC26-AC25 -> 0 | AE26: =AB26+X26+T26 -> 0 | AF26: =V26+Z26+AD26 -> 0 | AG26: =IF(AE26>0,AF26/AE26,0) -> 0 | AI26: =R26-'EDl log'!B24 -> -878743
... A30: ='General information '!F33 -> 0 | B30: =SUM(230*A30) -> 0 | C30: 44255 | D30: =D29 -> 32606678 | E30: =D30-D29 -> 0 | F30: =F29 -> 3961594 | G30: =F30-F29 -> 0 | H30: =H29 -> 17789546 | I30: =H30-H29 -> 0 | J30: =J29 -> 28893682 | K30: =J30-J29 -> 0 | L30: =L29 -> 24018742 | M30: =L30-L29 -> 0 | N30: =M30+K30+I30+G30+E30 -> 0 | O30: =IF(B30>0,N30/B30,0) -> 0 | P30: =P29 -> 16607.648 | Q30: =(P30-P29)*1000 -> 0 | R30: =N30-Q30 -> 0 | S30: =S29 -> 10118 | T30: =S30-S29 -> 0 | U30: =U29 -> 420722 | V30: =U30-U29 -> 0 | W30: =W29 -> 32191 | X30: =W30-W29 -> 0 | Y30: =Y29 -> 700543 | Z30: =Y30-Y29 -> 0 | AA30: =AA29 -> 35689 | AB30: =AA30-AA29 -> 0 | AC30: =AC29 -> 915313 | AD30: =AC30-AC29 -> 0 | AE30: =AB30+X30+T30 -> 0 | AF30: =V30+Z30+AD30 -> 0 | AG30: =IF(AE30>0,AF30/AE30,0) -> 0 | AI30: =R30-'EDl log'!B28 -> -878743

Sheet B5
F1: Boiler A | J1: =J33 -> 64.625 | K1: Boiler B | P1: Boiler C | V1: Boiler | X1: SteamA | AC1: SteamB | AH1: Steam | AI1: Boiler & steam | AL1: Total Boiler Runing H | AM1: Total Steam Runing H | AN1: GAS1 % | AO1: GAS1/L | AP1: GAS2% | AQ1: Gas2/L | AR1: GAS3% | AS1: GAS3/L | AU1: Gas Cons | AV1: Delivery | AW1: Cost/L
B2: Level Tank Gen | C2: Level tank Boiler | D2: Daily Cons Bo. | E2: Boiler litter | F2: Boiler A | G2: Run Hr a | H2: Boiler A fuel | I2: Daily consumption | J2: AVG | K2: index Run H | L2: Run Hrb | M2: Boiler B Fuel | O2: Daily consumption | P2: Boiler C | S2: Run C | U2: Total RH | V2: Total Fuel | X2: SteamA | Y2: Run SA | Z2: Steam A Conter | AA2: Liters | AC2: SteamB | AD2: Run SteamB | AE2: Steam B Conter | AF2: SB Litters | AG2: Avg | AH2: Total Fuel | AI2: Total Fuel
S3: 0
A4: =ELEC!C2 -> 44227 | B4: =[2]B5!B35 -> 236 | C4: =[2]B5!C35 -> 242 | D4: =[2]B5!D35 -> 3 | E4: =[2]B5!E35 -> 25.14 | F4: =[2]B5!F35 -> 1715 | G4: =[2]B5!G35 -> 0 | H4: =[2]B5!H35 -> 3991 | I4: =[2]B5!I35 -> 0 | ... AU4: =[2]B5!AU35 -> 0 | AV4: 0.1 | AW4: 0.1 | AX4: =[2]B5!AX35 -> 0.8
A5: =ELEC!C3 -> 44228 | B5: 232 | C5: 238 | D5: =C4-C5 -> 4 | E5: =D5*8.38 -> 33.52 | F5: 1717 | G5: =F5-F4 -> 2 | H5: 4147 | I5: =SUM(H5-H4) -> 156 | J5: 1 | K5: =K4 -> 2216 | L5: =K5-K4 -> 0 | M5: =M4 -> 162924 | N5: =M5-M4 -> 0 | O5: =O4 -> 1869 | P5: 1966 | Q5: 166371 | R5: =Q5-Q4 -> 192 | S5: =SUM(P5-P4) -> 2 | T5: =SUM(S5*$T$2) -> 0 | U5: =SUM(G5+L5+S5) -> 4 | V5: =R5+N5+I5:I5 -> 348 | W5: =SUM(V5/U5) -> 87 | X5: 2453 | Y5: =X5-X4 -> 1 | Z5: 137950.7 | AA5: =Z5-Z4 -> 119.6 | AB5: =SUM(Y5*$AB$2) -> 0 | AC5: =AC4 -> 1934 | AD5: =AC5-AC4 -> 0 | AE5: =AE4 -> 365317 | AF5: =AE5-AE4 -> 0 | AG5: =IF(AD5>0,AF5/AD5,0) -> 0 | AH5: =AF5+AA5 -> 119.6 | AI5: =SUM(AH5+V5) -> 467.6 | AJ5: =-tanks!AW6 -> 467.6 | AK5: =SUM(AJ5-AI5) -> 0 | AL5: =S5+L5+G5 -> 4 | AM5: =Y5+AD5 -> 1 | AN5: =AN4 -> 67 | AO5: =(AN5/100)*3000 -> 2010 | AP5: =AP4 -> 55 | AQ5: =(AP5/100)*3000 -> 1650 | AR5: =AR4 -> 61 | AS5: =(AR5/100)*3000 -> 1830 | AT5: =SUM(AO5+AQ5+AS5) -> 5490 | AU5: =AT4-AT5+AV5 -> 0 | AX5: =IF(AV5>0,AW5,AX4) -> 0.8
A6: =ELEC!C4 -> 44229 | B6: 229 | C6: 235 | D6: =C5-C6 -> 3 | E6: =D6*8.38 -> 25.14 | F6: 1719 | G6: =F6-F5 -> 2 | H6: 4287 | I6: =SUM(H6-H5) -> 140 | J6: =IF(G6>0,I6/G6,0) -> 70 | K6: 2218 | L6: =K6-K5 -> 2 | M6: 163018 | N6: =M6-M5 -> 94 | O6: =O5 -> 1869 | P6: =P5 -> 1966 | Q6: =Q5 -> 166371 | R6: =Q6-Q5 -> 0 | S6: =SUM(P6-P5) -> 0 | T6: =SUM(S6*$T$2) -> 0 | U6: =SUM(G6+L6+S6) -> 4 | V6: =R6+N6+I6:I6 -> 234 | W6: =SUM(V6/U6) -> 58.5 | X6: =X5 -> 2453 | Y6: =X6-X5 -> 0 | Z6: =Z5 -> 137950.7 | AA6: =Z6-Z5 -> 0 | AB6: =SUM(Y6*$AB$2) -> 0 | AC6: =AC5 -> 1934 | AD6: =AC6-AC5 -> 0 | AE6: =AE5 -> 365317 | AF6: =AE6-AE5 -> 0 | AG6: =IF(AD6>0,AF6/AD6,0) -> 0 | AH6: =AF6+AA6 -> 0 | AI6: =SUM(AH6+V6) -> 234 | AJ6: =-tanks!AW7 -> 234 | AK6: =SUM(AJ6-AI6) -> 0 | AL6: =S6+L6+G6 -> 4 | AM6: =Y6+AD6 -> 0 | AN6: =AN5 -> 67 | AO6: =(AN6/100)*3000 -> 2010 | AP6: =AP5 -> 55 | AQ6: =(AP6/100)*3000 -> 1650 | AR6: =AR5 -> 61 | AS6: =(AR6/100)*3000 -> 1830 | AT6: =SUM(AO6+AQ6+AS6) -> 5490 | AU6: =AT5-AT6+AV6 -> 0 | AX6: =IF(AV6>0,AW6,AX5) -> 0.8
A7: =ELEC!C5 -> 44230 | B7: 225 | C7: 231 | D7: =C6-C7 -> 4 | E7: =D7*8.38 -> 33.52 | F7: =F6 -> 1719 | G7: =F7-F6 -> 0 | H7: =H6 -> 4287 | I7: =SUM(H7-H6) -> 0 | J7: =IF(G7>0,I7/G7,0) -> 0 | K7: 2220 | L7: =K7-K6 -> 2 | M7: 163181 | N7: =M7-M6 -> 163 | O7: =O6 -> 1869 | P7: 1968 | Q7: 166462 | R7: =Q7-Q6 -> 91 | S7: =SUM(P7-P6) -> 2 | T7: =SUM(S7*$T$2) -> 0 | U7: =SUM(G7+L7+S7) -> 4 | V7: =R7+N7+I7:I7 -> 254 | W7: =SUM(V7/U7) -> 63.5 | X7: =X6 -> 2453 | Y7: =X7-X6 -> 0 | Z7: =Z6 -> 137950.7 | AA7: =Z7-Z6 -> 0 | AB7: =SUM(Y7*$AB$2) -> 0 | AC7: =AC6 -> 1934 | AD7: =AC7-AC6 -> 0 | AE7: 365352 | AF7: =AE7-AE6 -> 35 | AG7: =IF(AD7>0,AF7/AD7,0) -> 0 | AH7: =AF7+AA7 -> 35 | AI7: =SUM(AH7+V7) -> 289 | AJ7: =-tanks!AW8 -> 289 | AK7: =SUM(AJ7-AI7) -> 0 | AL7: =S7+L7+G7 -> 4 | AM7: =Y7+AD7 -> 0 | AN7: =AN6 -> 67 | AO7: =(AN7/100)*3000 -> 2010 | AP7: =AP6 -> 55 | AQ7: =(AP7/100)*3000 -> 1650 | AR7: =AR6 -> 61 | AS7: =(AR7/100)*3000 -> 1830 | AT7: =SUM(AO7+AQ7+AS7) -> 5490 | AU7: =AT6-AT7+AV7 -> 0 | AX7: =IF(AV7>0,AW7,AX6) -> 0.8
A8: =ELEC!C6 -> 44231 | B8: 221 | C8: 227 | D8: =C7-C8 -> 4 | E8: =D8*8.38 -> 33.52 | F8: 1721 | G8: =F8-F7 -> 2 | H8: 4416 | I8: =SUM(H8-H7) -> 129 | J8: =IF(G8>0,I8/G8,0) -> 64.5 | K8: =K7 -> 2220 | L8: =K8-K7 -> 0 | M8: =M7 -> 163181 | N8: =M8-M7 -> 0 | O8: =O7 -> 1869 | P8: 1970 | Q8: 166647 | R8: =Q8-Q7 -> 185 | S8: =SUM(P8-P7) -> 2 | T8: =SUM(S8*$T$2) -> 0 | U8: =SUM(G8+L8+S8) -> 4 | V8: =R8+N8+I8:I8 -> 314 | W8: =SUM(V8/U8) -> 78.5 | X8: =X7 -> 2453 | Y8: =X8-X7 -> 0 | Z8: =Z7 -> 137950.7 | AA8: =Z8-Z7 -> 0 | AB8: =SUM(Y8*$AB$2) -> 0 | AC8: =AC7 -> 1934 | AD8: =AC8-AC7 -> 0 | AE8: =AE7 -> 365352 | AF8: =AE8-AE7 -> 0 | AG8: =IF(AD8>0,AF8/AD8,0) -> 0 | AH8: =AF8+AA8 -> 0 | AI8: =SUM(AH8+V8) -> 314 | AJ8: =-tanks!AW9 -> 314 | AK8: =SUM(AJ8-AI8) -> 0 | AL8: =S8+L8+G8 -> 4 | AM8: =Y8+AD8 -> 0 | AN8: =AN7 -> 67 | AO8: =(AN8/100)*3000 -> 2010 | AP8: =AP7 -> 55 | AQ8: =(AP8/100)*3000 -> 1650 | AR8: =AR7 -> 61 | AS8: =(AR8/100)*3000 -> 1830 | AT8: =SUM(AO8+AQ8+AS8) -> 5490 | AU8: =AT7-AT8+AV8 -> 0 | AX8: =IF(AV8>0,AW8,AX7) -> 0.8
A9: =ELEC!C7 -> 44232 | B9: 247 | C9: 252 | D9: =C8-C9 -> -25 | E9: =D9*8.38 -> -209.5 | F9: 1724 | G9: =F9-F8 -> 3 | H9: 4626 | I9: =SUM(H9-H8) -> 210 | J9: =IF(G9>0,I9/G9,0) -> 70 | K9: 2222 | L9: =K9-K8 -> 2 | M9: 163362 | N9: =M9-M8 -> 181 | O9: =O8 -> 1869 | P9: =P8 -> 1970 | Q9: =Q8 -> 166647 | R9: =Q9-Q8 -> 0 | S9: =SUM(P9-P8) -> 0 | T9: =SUM(S9*$T$2) -> 0 | U9: =SUM(G9+L9+S9) -> 5 | V9: =R9+N9+I9:I9 -> 391 | W9: =SUM(V9/U9) -> 78.2 | X9: =X8 -> 2453 | Y9: =X9-X8 -> 0 | Z9: =Z8 -> 137950.7 | AA9: =Z9-Z8 -> 0 | AB9: =SUM(Y9*$AB$2) -> 0 | AC9: 1934 | AD9: =AC9-AC8 -> 0 | AE9: =AE8 -> 365352 | AF9: =AE9-AE8 -> 0 | AG9: =IF(AD9>0,AF9/AD9,0) -> 0 | AH9: =AF9+AA9 -> 0 | AI9: =SUM(AH9+V9) -> 391 | AJ9: =-tanks!AW10 -> 391 | AK9: =SUM(AJ9-AI9) -> 0 | AL9: =S9+L9+G9 -> 5 | AM9: =Y9+AD9 -> 0 | AN9: =AN8 -> 67 | AO9: =(AN9/100)*3000 -> 2010 | AP9: =AP8 -> 55 | AQ9: =(AP9/100)*3000 -> 1650 | AR9: =AR8 -> 61 | AS9: =(AR9/100)*3000 -> 1830 | AT9: =SUM(AO9+AQ9+AS9) -> 5490 | AU9: =AT8-AT9+AV9 -> 0 | AX9: =IF(AV9>0,AW9,AX8) -> 0.8
A10: =ELEC!C8 -> 44233 | B10: 244 | C10: 250 | D10: =C9-C10 -> 2 | E10: =D10*8.38 -> 16.76 | F10: =F9 -> 1724 | G10: =F10-F9 -> 0 | H10: =H9 -> 4626 | I10: =SUM(H10-H9) -> 0 | J10: =IF(G10>0,I10/G10,0) -> 0 | K10: 2224 | L10: =K10-K9 -> 2 | M10: 163480 | N10: =M10-M9 -> 118 | O10: =O9 -> 1869 | P10: 1973 | Q10: 166840 | R10: =Q10-Q9 -> 193 | S10: =SUM(P10-P9) -> 3 | T10: =SUM(S10*$T$2) -> 0 | U10: =SUM(G10+L10+S10) -> 5 | V10: =R10+N10+I10:I10 -> 311 | W10: =SUM(V10/U10) -> 62.2 | X10: =X9 -> 2453 | Y10: =X10-X9 -> 0 | Z10: =Z9 -> 137950.7 | AA10: =Z10-Z9 -> 0 | AB10: =SUM(Y10*$AB$2) -> 0 | AC10: =AC9 -> 1934 | AD10: =AC10-AC9 -> 0 | AE10: =AE9 -> 365352 | AF10: =AE10-AE9 -> 0 | AG10: =IF(AD10>0,AF10/AD10,0) -> 0 | AH10: =AF10+AA10 -> 0 | AI10: =SUM(AH10+V10) -> 311 | AJ10: =-tanks!AW11 -> 311 | AK10: =SUM(AJ10-AI10) -> 0 | AL10: =S10+L10+G10 -> 5 | AM10: =Y10+AD10 -> 0 | AN10: =AN9 -> 67 | AO10: =(AN10/100)*3000 -> 2010 | AP10: =AP9 -> 55 | AQ10: =(AP10/100)*3000 -> 1650 | AR10: =AR9 -> 61 | AS10: =(AR10/100)*3000 -> 1830 | AT10: =SUM(AO10+AQ10+AS10) -> 5490 | AU10: =AT9-AT10+AV10 -> 0 | AX10: =IF(AV10>0,AW10,AX9) -> 0.8
A11: =ELEC!C9 -> 44234 | B11: 240 | C11: 246 | D11: =C10-C11 -> 4 | E11: =D11*8.38 -> 33.52 | F11: 1725 | G11: =F11-F10 -> 1 | H11: 4721 | I11: =SUM(H11-H10) -> 95 | J11: =IF(G11>0,I11/G11,0) -> 95 | K11: =K10 -> 2224 | L11: =K11-K10 -> 0 | M11: =M10 -> 163480 | N11: =M11-M10 -> 0 | O11: =O10 -> 1869 | P11: 1975 | Q11: 167024 | R11: =Q11-Q10 -> 184 | S11: =SUM(P11-P10) -> 2 | T11: =SUM(S11*$T$2) -> 0 | U11: =SUM(G11+L11+S11) -> 3 | V11: =R11+N11+I11:I11 -> 279 | W11: =SUM(V11/U11) -> 93 | X11: =X10 -> 2453 | Y11: =X11-X10 -> 0 | Z11: =Z10 -> 137950.7 | AA11: =Z11-Z10 -> 0 | AB11: =SUM(Y11*$AB$2) -> 0 | AC11: =AC10 -> 1934 | AD11: =AC11-AC10 -> 0 | AE11: =AE10 -> 365352 | AF11: =AE11-AE10 -> 0 | AG11: =IF(AD11>0,AF11/AD11,0) -> 0 | AH11: =AF11+AA11 -> 0 | AI11: =SUM(AH11+V11) -> 279 | AJ11: =-tanks!AW12 -> 279 | AK11: =SUM(AJ11-AI11) -> 0 | AL11: =S11+L11+G11 -> 3 | AM11: =Y11+AD11 -> 0 | AN11: =AN10 -> 67 | AO11: =(AN11/100)*3000 -> 2010 | AP11: =AP10 -> 55 | AQ11: =(AP11/100)*3000 -> 1650 | AR11: =AR10 -> 61 | AS11: =(AR11/100)*3000 -> 1830 | AT11: =SUM(AO11+AQ11+AS11) -> 5490 | AU11: =AT10-AT11+AV11 -> 0 | AX11: =IF(AV11>0,AW11,AX10) -> 0.8
A12: =ELEC!C10 -> 44235 | B12: 237 | C12: 243 | D12: =C11-C12 -> 3 | E12: =D12*8.38 -> 25.14 | F12: 1727 | G12: =F12-F11 -> 2 | H12: 4872 | I12: =SUM(H12-H11) -> 151 | J12: =IF(G12>0,I12/G12,0) -> 75.5 | K12: 2225 | L12: =K12-K11 -> 1 | M12: 163585 | N12: =M12-M11 -> 105 | O12: =O11 -> 1869 | P12: =P11 -> 1975 | Q12: =Q11 -> 167024 | R12: =Q12-Q11 -> 0 | S12: =SUM(P12-P11) -> 0 | T12: =SUM(S12*$T$2) -> 0 | U12: =SUM(G12+L12+S12) -> 3 | V12: =R12+N12+I12:I12 -> 256 | W12: =SUM(V12/U12) -> 85.333333 | X12: 2454 | Y12: =X12-X11 -> 1 | Z12: 138028.1 | AA12: =Z12-Z11 -> 77.4 | AB12: =SUM(Y12*$AB$2) -> 0 | AC12: =AC11 -> 1934 | AD12: =AC12-AC11 -> 0 | AE12: =AE11 -> 365352 | AF12: =AE12-AE11 -> 0 | AG12: =IF(AD12>0,AF12/AD12,0) -> 0 | AH12: =AF12+AA12 -> 77.4 | AI12: =SUM(AH12+V12) -> 333.4 | AJ12: =-tanks!AW13 -> 333.4 | AK12: =SUM(AJ12-AI12) -> 0 | AL12: =S12+L12+G12 -> 3 | AM12: =Y12+AD12 -> 1 | AN12: =AN11 -> 67 | AO12: =(AN12/100)*3000 -> 2010 | AP12: =AP11 -> 55 | AQ12: =(AP12/100)*3000 -> 1650 | AR12: =AR11 -> 61 | AS12: =(AR12/100)*3000 -> 1830 | AT12: =SUM(AO12+AQ12+AS12) -> 5490 | AU12: =AT11-AT12+AV12 -> 0 | AX12: =IF(AV12>0,AW12,AX11) -> 0.8
A13: =ELEC!C11 -> 44236 | B13: 233 | C13: 239 | D13: =C12-C13 -> 4 | E13: =D13*8.38 -> 33.52 | F13: =F12 -> 1727 | G13: =F13-F12 -> 0 | H13: =H12 -> 4872 | I13: =SUM(H13-H12) -> 0 | J13: =IF(G13>0,I13/G13,0) -> 0 | K13: 2227 | L13: =K13-K12 -> 2 | M13: 163735 | N13: =M13-M12 -> 150 | O13: =O12 -> 1869 | P13: 1976 | Q13: 167110 | R13: =Q13-Q12 -> 86 | S13: =SUM(P13-P12) -> 1 | T13: =SUM(S13*$T$2) -> 0 | U13: =SUM(G13+L13+S13) -> 3 | V13: =R13+N13+I13:I13 -> 236 | W13: =SUM(V13/U13) -> 78.666667 | X13: =X12 -> 2454 | Y13: =X13-X12 -> 0 | Z13: =Z12 -> 138028.1 | AA13: =Z13-Z12 -> 0 | AB13: =SUM(Y13*$AB$2) -> 0 | AC13: =AC12 -> 1934 | AD13: =AC13-AC12 -> 0 | AE13: =AE12 -> 365352 | AF13: =AE13-AE12 -> 0 | AG13: =IF(AD13>0,AF13/AD13,0) -> 0 | AH13: =AF13+AA13 -> 0 | AI13: =SUM(AH13+V13) -> 236 | AJ13: =-tanks!AW14 -> 236 | AK13: =SUM(AJ13-AI13) -> 0 | AL13: =S13+L13+G13 -> 3 | AM13: =Y13+AD13 -> 0 | AN13: =AN12 -> 67 | AO13: =(AN13/100)*3000 -> 2010 | AP13: =AP12 -> 55 | AQ13: =(AP13/100)*3000 -> 1650 | AR13: =AR12 -> 61 | AS13: =(AR13/100)*3000 -> 1830 | AT13: =SUM(AO13+AQ13+AS13) -> 5490 | AU13: =AT12-AT13+AV13 -> 0 | AX13: =IF(AV13>0,AW13,AX12) -> 0.8
A14: =ELEC!C12 -> 44237 | B14: 227 | C14: 233 | D14: =C13-C14 -> 6 | E14: =D14*8.38 -> 50.28 | F14: 1728 | G14: =F14-F13 -> 1 | H14: 4957 | I14: =SUM(H14-H13) -> 85 | J14: =IF(G14>0,I14/G14,0) -> 85 | K14: =K13 -> 2227 | L14: =K14-K13 -> 0 | M14: =M13 -> 163735 | N14: =M14-M13 -> 0 | O14: =O13 -> 1869 | P14: 1978 | Q14: 167261 | R14: =Q14-Q13 -> 151 | S14: =SUM(P14-P13) -> 2 | T14: =SUM(S14*$T$2) -> 0 | U14: =SUM(G14+L14+S14) -> 3 | V14: =R14+N14+I14:I14 -> 236 | W14: =SUM(V14/U14) -> 78.666667 | X14: =X13 -> 2454 | Y14: =X14-X13 -> 0 | Z14: =Z13 -> 138028.1 | AA14: =Z14-Z13 -> 0 | AB14: =SUM(Y14*$AB$2) -> 0 | AC14: =AC13 -> 1934 | AD14: =AC14-AC13 -> 0 | AE14: =AE13 -> 365352 | AF14: =AE14-AE13 -> 0 | AG14: =IF(AD14>0,AF14/AD14,0) -> 0 | AH14: =AF14+AA14 -> 0 | AI14: =SUM(AH14+V14) -> 236 | AJ14: =-tanks!AW15 -> 236 | AK14: =SUM(AJ14-AI14) -> 0 | AL14: =S14+L14+G14 -> 3 | AM14: =Y14+AD14 -> 0 | AN14: =AN13 -> 67 | AO14: =(AN14/100)*3000 -> 2010 | AP14: =AP13 -> 55 | AQ14: =(AP14/100)*3000 -> 1650 | AR14: =AR13 -> 61 | AS14: =(AR14/100)*3000 -> 1830 | AT14: =SUM(AO14+AQ14+AS14) -> 5490 | AU14: =AT13-AT14+AV14 -> 0 | AX14: =IF(AV14>0,AW14,AX13) -> 0.8
A15: =ELEC!C13 -> 44238 | B15: 222 | C15: 228 | D15: =C14-C15 -> 5 | E15: =D15*8.38 -> 41.9 | F15: 1731 | G15: =F15-F14 -> 3 | H15: 5125 | I15: =SUM(H15-H14) -> 168 | J15: =IF(G15>0,I15/G15,0) -> 56 | K15: 2228 | L15: =K15-K14 -> 1 | M15: 163820 | N15: =M15-M14 -> 85 | O15: =O14 -> 1869 | P15: =P14 -> 1978 | Q15: =Q14 -> 167261 | R15: =Q15-Q14 -> 0 | S15: =SUM(P15-P14) -> 0 | T15: =SUM(S15*$T$2) -> 0 | U15: =SUM(G15+L15+S15) -> 4 | V15: =R15+N15+I15:I15 -> 253 | W15: =SUM(V15/U15) -> 63.25 | X15: =X14 -> 2454 | Y15: =X15-X14 -> 0 | Z15: =Z14 -> 138028.1 | AA15: =Z15-Z14 -> 0 | AB15: =SUM(Y15*$AB$2) -> 0 | AC15: =AC14 -> 1934 | AD15: =AC15-AC14 -> 0 | AE15: =AE14 -> 365352 | AF15: =AE15-AE14 -> 0 | AG15: =IF(AD15>0,AF15/AD15,0) -> 0 | AH15: =AF15+AA15 -> 0 | AI15: =SUM(AH15+V15) -> 253 | AJ15: =-tanks!AW16 -> 253 | AK15: =SUM(AJ15-AI15) -> 0 | AL15: =S15+L15+G15 -> 4 | AM15: =Y15+AD15 -> 0 | AN15: =AN14 -> 67 | AO15: =(AN15/100)*3000 -> 2010 | AP15: =AP14 -> 55 | AQ15: =(AP15/100)*3000 -> 1650 | AR15: =AR14 -> 61 | AS15: =(AR15/100)*3000 -> 1830 | AT15: =SUM(AO15+AQ15+AS15) -> 5490 | AU15: =AT14-AT15+AV15 -> 0 | AX15: =IF(AV15>0,AW15,AX14) -> 0.8
A16: =ELEC!C14 -> 44239 | B16: 219 | C16: 224 | D16: =C15-C16 -> 4 | E16: =D16*8.38 -> 33.52 | F16: 1731 | G16: =F16-F15 -> 0 | H16: =H15 -> 5125 | I16: =SUM(H16-H15) -> 0 | J16: =IF(G16>0,I16/G16,0) -> 0 | K16: 2230 | L16: =K16-K15 -> 2 | M16: 163965 | N16: =M16-M15 -> 145 | O16: =O15 -> 1869 | P16: 1979 | Q16: 167350 | R16: =Q16-Q15 -> 89 | S16: =SUM(P16-P15) -> 1 | T16: =SUM(S16*$T$2) -> 0 | U16: =SUM(G16+L16+S16) -> 3 | V16: =R16+N16+I16:I16 -> 234 | W16: =SUM(V16/U16) -> 78 | X16: =X15 -> 2454 | Y16: =X16-X15 -> 0 | Z16: =Z15 -> 138028.1 | AA16: =Z16-Z15 -> 0 | AB16: =SUM(Y16*$AB$2) -> 0 | AC16: =AC15 -> 1934 | AD16: =AC16-AC15 -> 0 | AE16: =AE15 -> 365352 | AF16: =AE16-AE15 -> 0 | AG16: =IF(AD16>0,AF16/AD16,0) -> 0 | AH16: =AF16+AA16 -> 0 | AI16: =SUM(AH16+V16) -> 234 | AJ16: =-tanks!AW17 -> 234 | AK16: =SUM(AJ16-AI16) -> 0 | AL16: =S16+L16+G16 -> 3 | AM16: =Y16+AD16 -> 0 | AN16: =AN15 -> 67 | AO16: =(AN16/100)*3000 -> 2010 | AP16: =AP15 -> 55 | AQ16: =(AP16/100)*3000 -> 1650 | AR16: =AR15 -> 61 | AS16: =(AR16/100)*3000 -> 1830 | AT16: =SUM(AO16+AQ16+AS16) -> 5490 | AU16: =AT15-AT16+AV16 -> 0 | AX16: =IF(AV16>0,AW16,AX15) -> 0.8
A17: =ELEC!C15 -> 44240 | B17: =B16 -> 219 | C17: =C16 -> 224 | D17: =C16-C17 -> 0 | E17: =D17*8.38 -> 0 | F17: =F16 -> 1731 | G17: =F17-F16 -> 0 | H17: =H16 -> 5125 | I17: =SUM(H17-H16) -> 0 | J17: =IF(G17>0,I17/G17,0) -> 0 | K17: =K16 -> 2230 | L17: =K17-K16 -> 0 | M17: =M16 -> 163965 | N17: =M17-M16 -> 0 | O17: =O16 -> 1869 | P17: =P16 -> 1979 | Q17: =Q16 -> 167350 | R17: =Q17-Q16 -> 0 | S17: =SUM(P17-P16) -> 0 | T17: =SUM(S17*$T$2) -> 0 | U17: =SUM(G17+L17+S17) -> 0 | V17: =R17+N17+I17:I17 -> 0 | X17: =X16 -> 2454 | Y17: =X17-X16 -> 0 | Z17: =Z16 -> 138028.1 | AA17: =Z17-Z16 -> 0 | AB17: =SUM(Y17*$AB$2) -> 0 | AC17: =AC16 -> 1934 | AD17: =AC17-AC16 -> 0 | AE17: =AE16 -> 365352 | AF17: =AE17-AE16 -> 0 | AG17: =IF(AD17>0,AF17/AD17,0) -> 0 | AH17: =AF17+AA17 -> 0 | AI17: =SUM(AH17+V17) -> 0 | AJ17: =-tanks!AW18 -> 0 | AK17: =SUM(AJ17-AI17) -> 0 | AL17: =S17+L17+G17 -> 0 | AM17: =Y17+AD17 -> 0 | AN17: =AN16 -> 67 | AO17: =(AN17/100)*3000 -> 2010 | AP17: =AP16 -> 55 | AQ17: =(AP17/100)*3000 -> 1650 | AR17: =AR16 -> 61 | AS17: =(AR17/100)*3000 -> 1830 | AT17: =SUM(AO17+AQ17+AS17) -> 5490 | AU17: =AT16-AT17+AV17 -> 0 | AX17: =IF(AV17>0,AW17,AX16) -> 0.8
A18: =ELEC!C16 -> 44241 | B18: =B17 -> 219 | C18: =C17 -> 224 | D18: =C17-C18 -> 0 | E18: =D18*8.38 -> 0 | F18: =F17 -> 1731 | G18: =F18-F17 -> 0 | H18: =H17 -> 5125 | I18: =SUM(H18-H17) -> 0 | J18: =IF(G18>0,I18/G18,0) -> 0 | K18: =K17 -> 2230 | L18: =K18-K17 -> 0 | M18: =M17 -> 163965 | N18: =M18-M17 -> 0 | O18: 1869 | P18: =P17 -> 1979 | Q18: =Q17 -> 167350 | R18: =Q18-Q17 -> 0 | S18: =SUM(P18-P17) -> 0 | T18: =SUM(S18*$T$2) -> 0 | U18: =SUM(G18+L18+S18) -> 0 | V18: =R18+N18+I18:I18 -> 0 | X18: =X17 -> 2454 | Y18: =X18-X17 -> 0 | Z18: =Z17 -> 138028.1 | AA18: =Z18-Z17 -> 0 | AB18: =SUM(Y18*$AB$2) -> 0 | AC18: =AC17 -> 1934 | AD18: =AC18-AC17 -> 0 | AE18: =AE17 -> 365352 | AF18: =AE18-AE17 -> 0 | AG18: =IF(AD18>0,AF18/AD18,0) -> 0 | AH18: =AF18+AA18 -> 0 | AI18: =SUM(AH18+V18) -> 0 | AJ18: =-tanks!AW19 -> 0 | AK18: =SUM(AJ18-AI18) -> 0 | AL18: =S18+L18+G18 -> 0 | AM18: =Y18+AD18 -> 0 | AN18: =AN17 -> 67 | AO18: =(AN18/100)*3000 -> 2010 | AP18: =AP17 -> 55 | AQ18: =(AP18/100)*3000 -> 1650 | AR18: =AR17 -> 61 | AS18: =(AR18/100)*3000 -> 1830 | AT18: =SUM(AO18+AQ18+AS18) -> 5490 | AU18: =AT17-AT18+AV18 -> 0 | AX18: =IF(AV18>0,AW18,AX17) -> 0.8
A19: =ELEC!C17 -> 44242 | B19: =B18 -> 219 | C19: =C18 -> 224 | D19: =C18-C19 -> 0 | E19: =D19*8.38 -> 0 | F19: =F18 -> 1731 | G19: =F19-F18 -> 0 | H19: =H18 -> 5125 | I19: =SUM(H19-H18) -> 0 | J19: =IF(G19>0,I19/G19,0) -> 0 | K19: =K18 -> 2230 | L19: =K19-K18 -> 0 | M19: =M18 -> 163965 | N19: =M19-M18 -> 0 | O19: =O18 -> 1869 | P19: =P18 -> 1979 | Q19: =Q18 -> 167350 | R19: =Q19-Q18 -> 0 | S19: =SUM(P19-P18) -> 0 | T19: =SUM(S19*$T$2) -> 0 | U19: =SUM(G19+L19+S19) -> 0 | V19: =R19+N19+I19:I19 -> 0 | X19: =X18 -> 2454 | Y19: =X19-X18 -> 0 | Z19: =Z18 -> 138028.1 | AA19: =Z19-Z18 -> 0 | AB19: =SUM(Y19*$AB$2) -> 0 | AC19: =AC18 -> 1934 | AD19: =AC19-AC18 -> 0 | AE19: =AE18 -> 365352 | AF19: =AE19-AE18 -> 0 | AG19: =IF(AD19>0,AF19/AD19,0) -> 0 | AH19: =AF19+AA19 -> 0 | AI19: =SUM(AH19+V19) -> 0 | AJ19: =-tanks!AW20 -> 0 | AK19: =SUM(AJ19-AI19) -> 0 | AL19: =S19+L19+G19 -> 0 | AM19: =Y19+AD19 -> 0 | AN19: =AN18 -> 67 | AO19: =(AN19/100)*3000 -> 2010 | AP19: =AP18 -> 55 | AQ19: =(AP19/100)*3000 -> 1650 | AR19: =AR18 -> 61 | AS19: =(AR19/100)*3000 -> 1830 | AT19: =SUM(AO19+AQ19+AS19) -> 5490 | AU19: =AT18-AT19+AV19 -> 0 | AX19: =IF(AV19>0,AW19,AX18) -> 0.8
A20: =ELEC!C18 -> 44243 | B20: =B19 -> 219 | C20: =C19 -> 224 | D20: =C19-C20 -> 0 | E20: =D20*8.38 -> 0 | F20: =F19 -> 1731 | G20: =F20-F19 -> 0 | H20: =H19 -> 5125 | I20: =SUM(H20-H19) -> 0 | J20: =IF(G20>0,I20/G20,0) -> 0 | K20: =K19 -> 2230 | L20: =K20-K19 -> 0 | M20: =M19 -> 163965 | N20: =M20-M19 -> 0 | O20: =O19 -> 1869 | P20: =P19 -> 1979 | Q20: =Q19 -> 167350 | R20: =Q20-Q19 -> 0 | S20: =SUM(P20-P19) -> 0 | T20: =SUM(S20*$T$2) -> 0 | U20: =SUM(G20+L20+S20) -> 0 | V20: =R20+N20+I20:I20 -> 0 | X20: =X19 -> 2454 | Y20: =X20-X19 -> 0 | Z20: =Z19 -> 138028.1 | AA20: =Z20-Z19 -> 0 | AB20: =SUM(Y20*$AB$2) -> 0 | AC20: =AC19 -> 1934 | AD20: =AC20-AC19 -> 0 | AE20: =AE19 -> 365352 | AF20: =AE20-AE19 -> 0 | AG20: =IF(AD20>0,AF20/AD20,0) -> 0 | AH20: =AF20+AA20 -> 0 | AI20: =SUM(AH20+V20) -> 0 | AJ20: =-tanks!AW21 -> 0 | AK20: =SUM(AJ20-AI20) -> 0 | AL20: =S20+L20+G20 -> 0 | AM20: =Y20+AD20 -> 0 | AN20: =AN19 -> 67 | AO20: =(AN20/100)*3000 -> 2010 | AP20: =AP19 -> 55 | AQ20: =(AP20/100)*3000 -> 1650 | AR20: =AR19 -> 61 | AS20: =(AR20/100)*3000 -> 1830 | AT20: =SUM(AO20+AQ20+AS20) -> 5490 | AU20: =AT19-AT20+AV20 -> 0 | AX20: =IF(AV20>0,AW20,AX19) -> 0.8
A21: =ELEC!C19 -> 44244 | B21: =B20 -> 219 | C21: =C20 -> 224 | D21: =C20-C21 -> 0 | E21: =D21*8.38 -> 0 | F21: =F20 -> 1731 | G21: =F21-F20 -> 0 | H21: =H20 -> 5125 | I21: =SUM(H21-H20) -> 0 | J21: =IF(G21>0,I21/G21,0) -> 0 | K21: =K20 -> 2230 | L21: =K21-K20 -> 0 | M21: =M20 -> 163965 | N21: =M21-M20 -> 0 | O21: =O20 -> 1869 | P21: =P20 -> 1979 | Q21: =Q20 -> 167350 | R21: =Q21-Q20 -> 0 | S21: =SUM(P21-P20) -> 0 | T21: =SUM(S21*$T$2) -> 0 | U21: =SUM(G21+L21+S21) -> 0 | V21: =R21+N21+I21:I21 -> 0 | X21: =X20 -> 2454 | Y21: =X21-X20 -> 0 | Z21: =Z20 -> 138028.1 | AA21: =Z21-Z20 -> 0 | AB21: =SUM(Y21*$AB$2) -> 0 | AC21: =AC20 -> 1934 | AD21: =AC21-AC20 -> 0 | AE21: =AE20 -> 365352 | AF21: =AE21-AE20 -> 0 | AG21: =IF(AD21>0,AF21/AD21,0) -> 0 | AH21: =AF21+AA21 -> 0 | AI21: =SUM(AH21+V21) -> 0 | AJ21: =-tanks!AW22 -> 0 | AK21: =SUM(AJ21-AI21) -> 0 | AL21: =S21+L21+G21 -> 0 | AM21: =Y21+AD21 -> 0 | AN21: =AN20 -> 67 | AO21: =(AN21/100)*3000 -> 2010 | AP21: =AP20 -> 55 | AQ21: =(AP21/100)*3000 -> 1650 | AR21: =AR20 -> 61 | AS21: =(AR21/100)*3000 -> 1830 | AT21: =SUM(AO21+AQ21+AS21) -> 5490 | AU21: =AT20-AT21+AV21 -> 0 | AX21: =IF(AV21>0,AW21,AX20) -> 0.8
A22: =ELEC!C20 -> 44245 | B22: =B21 -> 219 | C22: =C21 -> 224 | D22: =C21-C22 -> 0 | E22: =D22*8.38 -> 0 | F22: =F21 -> 1731 | G22: =F22-F21 -> 0 | H22: =H21 -> 5125 | I22: =SUM(H22-H21) -> 0 | J22: =IF(G22>0,I22/G22,0) -> 0 | K22: =K21 -> 2230 | L22: =K22-K21 -> 0 | M22: =M21 -> 163965 | N22: =M22-M21 -> 0 | O22: =O21 -> 1869 | P22: =P21 -> 1979 | Q22: =Q21 -> 167350 | R22: =Q22-Q21 -> 0 | S22: =SUM(P22-P21) -> 0 | T22: =SUM(S22*$T$2) -> 0 | U22: =SUM(G22+L22+S22) -> 0 | V22: =R22+N22+I22:I22 -> 0 | X22: =X21 -> 2454 | Y22: =X22-X21 -> 0 | Z22: =Z21 -> 138028.1 | AA22: =Z22-Z21 -> 0 | AB22: =SUM(Y22*$AB$2) -> 0 | AC22: =AC21 -> 1934 | AD22: =AC22-AC21 -> 0 | AE22: =AE21 -> 365352 | AF22: =AE22-AE21 -> 0 | AG22: =IF(AD22>0,AF22/AD22,0) -> 0 | AH22: =AF22+AA22 -> 0 | AI22: =SUM(AH22+V22) -> 0 | AJ22: =-tanks!AW23 -> 0 | AK22: =SUM(AJ22-AI22) -> 0 | AL22: =S22+L22+G22 -> 0 | AM22: =Y22+AD22 -> 0 | AN22: =AN21 -> 67 | AO22: =(AN22/100)*3000 -> 2010 | AP22: =AP21 -> 55 | AQ22: =(AP22/100)*3000 -> 1650 | AR22: =AR21 -> 61 | AS22: =(AR22/100)*3000 -> 1830 | AT22: =SUM(AO22+AQ22+AS22) -> 5490 | AU22: =AT21-AT22+AV22 -> 0 | AX22: =IF(AV22>0,AW22,AX21) -> 0.8
A23: =[3]ELEC!C21 -> 44215 | B23: =B22 -> 219 | C23: =C22 -> 224 | D23: =C22-C23 -> 0 | E23: =D23*8.38 -> 0 | F23: =F22 -> 1731 | G23: =F23-F22 -> 0 | H23: =H22 -> 5125 | I23: =SUM(H23-H22) -> 0 | J23: =IF(G23>0,I23/G23,0) -> 0 | K23: =K22 -> 2230 | L23: =K23-K22 -> 0 | M23: =M22 -> 163965 | N23: =M23-M22 -> 0 | O23: =O22 -> 1869 | P23: =P22 -> 1979 | Q23: =Q22 -> 167350 | R23: =Q23-Q22 -> 0 | S23: =SUM(P23-P22) -> 0 | T23: =SUM(S23*$T$2) -> 0 | U23: =SUM(G23+L23+S23) -> 0 | V23: =R23+N23+I23:I23 -> 0 | X23: =X22 -> 2454 | Y23: =X23-X22 -> 0 | Z23: =Z22 -> 138028.1 | AA23: =Z23-Z22 -> 0 | AB23: =SUM(Y23*$AB$2) -> 0 | AC23: =AC22 -> 1934 | AD23: =AC23-AC22 -> 0 | AE23: =AE22 -> 365352 | AF23: =AE23-AE22 -> 0 | AG23: =IF(AD23>0,AF23/AD23,0) -> 0 | AH23: =AF23+AA23 -> 0 | AI23: =SUM(AH23+V23) -> 0 | AJ23: =-[3]tanks!AW24 -> 231 | AK23: =SUM(AJ23-AI23) -> 231 | AL23: =S23+L23+G23 -> 0 | AM23: =Y23+AD23 -> 0 | AN23: =AN22 -> 67 | AO23: =(AN23/100)*3000 -> 2010 | AP23: =AP22 -> 55 | AQ23: =(AP23/100)*3000 -> 1650 | AR23: =AR22 -> 61 | AS23: =(AR23/100)*3000 -> 1830 | AT23: =SUM(AO23+AQ23+AS23) -> 5490 | AU23: =AT22-AT23+AV23 -> 0 | AX23: =IF(AV23>0,AW23,AX22) -> 0.8
A24: =ELEC!C22 -> 44247 | B24: =B23 -> 219 | C24: =C23 -> 224 | D24: =C23-C24 -> 0 | E24: =D24*8.38 -> 0 | F24: =F23 -> 1731 | G24: =F24-F23 -> 0 | H24: =H23 -> 5125 | I24: =SUM(H24-H23) -> 0 | J24: =IF(G24>0,I24/G24,0) -> 0 | K24: =K23 -> 2230 | L24: =K24-K23 -> 0 | M24: =M23 -> 163965 | N24: =M24-M23 -> 0 | O24: =O23 -> 1869 | P24: =P23 -> 1979 | Q24: =Q23 -> 167350 | R24: =Q24-Q23 -> 0 | S24: =SUM(P24-P23) -> 0 | T24: =SUM(S24*$T$2) -> 0 | U24: =SUM(G24+L24+S24) -> 0 | V24: =R24+N24+I24:I24 -> 0 | X24: =X23 -> 2454 | Y24: =X24-X23 -> 0 | Z24: =Z23 -> 138028.1 | AA24: =Z24-Z23 -> 0 | AB24: =SUM(Y24*$AB$2) -> 0 | AC24: =AC23 -> 1934 | AD24: =AC24-AC23 -> 0 | AE24: =AE23 -> 365352 | AF24: =AE24-AE23 -> 0 | AG24: =IF(AD24>0,AF24/AD24,0) -> 0 | AH24: =AF24+AA24 -> 0 | AI24: =SUM(AH24+V24) -> 0 | AJ24: =-tanks!AW25 -> 0 | AK24: =SUM(AJ24-AI24) -> 0 | AL24: =S24+L24+G24 -> 0 | AM24: =Y24+AD24 -> 0 | AN24: =AN23 -> 67 | AO24: =(AN24/100)*3000 -> 2010 | AP24: =AP23 -> 55 | AQ24: =(AP24/100)*3000 -> 1650 | AR24: =AR23 -> 61 | AS24: =(AR24/100)*3000 -> 1830 | AT24: =SUM(AO24+AQ24+AS24) -> 5490 | AU24: =AT23-AT24+AV24 -> 0 | AX24: =IF(AV24>0,AW24,AX23) -> 0.8
A25: =ELEC!C23 -> 44248 | B25: =B24 -> 219 | C25: =C24 -> 224 | D25: =C24-C25 -> 0 | E25: =D25*8.38 -> 0 | F25: =F24 -> 1731 | G25: =F25-F24 -> 0 | H25: =H24 -> 5125 | I25: =SUM(H25-H24) -> 0 | J25: =IF(G25>0,I25/G25,0) -> 0 | K25: =K24 -> 2230 | L25: =K25-K24 -> 0 | M25: =M24 -> 163965 | N25: =M25-M24 -> 0 | O25: =O24 -> 1869 | P25: =P24 -> 1979 | Q25: =Q24 -> 167350 | R25: =Q25-Q24 -> 0 | S25: =SUM(P25-P24) -> 0 | T25: =SUM(S25*$T$2) -> 0 | U25: =SUM(G25+L25+S25) -> 0 | V25: =R25+N25+I25:I25 -> 0 | X25: =X24 -> 2454 | Y25: =X25-X24 -> 0 | Z25: =Z24 -> 138028.1 | AA25: =Z25-Z24 -> 0 | AB25: =SUM(Y25*$AB$2) -> 0 | AC25: =AC24 -> 1934 | AD25: =AC25-AC24 -> 0 | AE25: =AE24 -> 365352 | AF25: =AE25-AE24 -> 0 | AG25: =IF(AD25>0,AF25/AD25,0) -> 0 | AH25: =AF25+AA25 -> 0 | AI25: =SUM(AH25+V25) -> 0 | AJ25: =-tanks!AW26 -> 0 | AK25: =SUM(AJ25-AI25) -> 0 | AL25: =S25+L25+G25 -> 0 | AM25: =Y25+AD25 -> 0 | AN25: =AN24 -> 67 | AO25: =(AN25/100)*3000 -> 2010 | AP25: =AP24 -> 55 | AQ25: =(AP25/100)*3000 -> 1650 | AR25: =AR24 -> 61 | AS25: =(AR25/100)*3000 -> 1830 | AT25: =SUM(AO25+AQ25+AS25) -> 5490 | AU25: =AT24-AT25+AV25 -> 0 | AX25: =IF(AV25>0,AW25,AX24) -> 0.8
A26: =ELEC!C24 -> 44249 | B26: =B25 -> 219 | C26: =C25 -> 224 | D26: =C25-C26 -> 0 | E26: =D26*8.38 -> 0 | F26: =F25 -> 1731 | G26: =F26-F25 -> 0 | H26: =H25 -> 5125 | I26: =SUM(H26-H25) -> 0 | J26: =IF(G26>0,I26/G26,0) -> 0 | K26: =K25 -> 2230 | L26: =K26-K25 -> 0 | M26: =M25 -> 163965 | N26: =M26-M25 -> 0 | O26: =O25 -> 1869 | P26: =P25 -> 1979 | Q26: =Q25 -> 167350 | R26: =Q26-Q25 -> 0 | S26: =SUM(P26-P25) -> 0 | T26: =SUM(S26*$T$2) -> 0 | U26: =SUM(G26+L26+S26) -> 0 | V26: =R26+N26+I26:I26 -> 0 | X26: =X25 -> 2454 | Y26: =X26-X25 -> 0 | Z26: =Z25 -> 138028.1 | AA26: =Z26-Z25 -> 0 | AB26: =SUM(Y26*$AB$2) -> 0 | AC26: =AC25 -> 1934 | AD26: =AC26-AC25 -> 0 | AE26: =AE25 -> 365352 | AF26: =AE26-AE25 -> 0 | AG26: =IF(AD26>0,AF26/AD26,0) -> 0 | AH26: =AF26+AA26 -> 0 | AI26: =SUM(AH26+V26) -> 0 | AJ26: =-tanks!AW27 -> 0 | AK26: =SUM(AJ26-AI26) -> 0 | AL26: =S26+L26+G26 -> 0 | AM26: =Y26+AD26 -> 0 | AN26: =AN25 -> 67 | AO26: =(AN26/100)*3000 -> 2010 | AP26: =AP25 -> 55 | AQ26: =(AP26/100)*3000 -> 1650 | AR26: =AR25 -> 61 | AS26: =(AR26/100)*3000 -> 1830 | AT26: =SUM(AO26+AQ26+AS26) -> 5490 | AU26: =AT25-AT26+AV26 -> 0 | AX26: =IF(AV26>0,AW26,AX25) -> 0.8
A27: =ELEC!C25 -> 44250 | B27: =B26 -> 219 | C27: =C26 -> 224 | D27: =C26-C27 -> 0 | E27: =D27*8.38 -> 0 | F27: =F26 -> 1731 | G27: =F27-F26 -> 0 | H27: =H26 -> 5125 | I27: =SUM(H27-H26) -> 0 | J27: =IF(G27>0,I27/G27,0) -> 0 | K27: =K26 -> 2230 | L27: =K27-K26 -> 0 | M27: =M26 -> 163965 | N27: =M27-M26 -> 0 | O27: =O26 -> 1869 | P27: =P26 -> 1979 | Q27: =Q26 -> 167350 | R27: =Q27-Q26 -> 0 | S27: =SUM(P27-P26) -> 0 | T27: =SUM(S27*$T$2) -> 0 | U27: =SUM(G27+L27+S27) -> 0 | V27: =R27+N27+I27:I27 -> 0 | X27: =X26 -> 2454 | Y27: =X27-X26 -> 0 | Z27: =Z26 -> 138028.1 | AA27: =Z27-Z26 -> 0 | AB27: =SUM(Y27*$AB$2) -> 0 | AC27: =AC26 -> 1934 | AD27: =AC27-AC26 -> 0 | AE27: =AE26 -> 365352 | AF27: =AE27-AE26 -> 0 | AG27: =IF(AD27>0,AF27/AD27,0) -> 0 | AH27: =AF27+AA27 -> 0 | AI27: =SUM(AH27+V27) -> 0 | AJ27: =-tanks!AW28 -> 0 | AK27: =SUM(AJ27-AI27) -> 0 | AL27: =S27+L27+G27 -> 0 | AM27: =Y27+AD27 -> 0 | AN27: =AN26 -> 67 | AO27: =(AN27/100)*3000 -> 2010 | AP27: =AP26 -> 55 | AQ27: =(AP27/100)*3000 -> 1650 | AR27: =AR26 -> 61 | AS27: =(AR27/100)*3000 -> 1830 | AT27: =SUM(AO27+AQ27+AS27) -> 5490 | AU27: =AT26-AT27+AV27 -> 0 | AX27: =IF(AV27>0,AW27,AX26) -> 0.8
A28: =ELEC!C26 -> 44251 | B28: =B27 -> 219 | C28: =C27 -> 224 | D28: =C27-C28 -> 0 | E28: =D28*8.38 -> 0 | F28: =F27 -> 1731 | G28: =F28-F27 -> 0 | H28: =H27 -> 5125 | I28: =SUM(H28-H27) -> 0 | J28: =IF(G28>0,I28/G28,0) -> 0 | K28: =K27 -> 2230 | L28: =K28-K27 -> 0 | M28: =M27 -> 163965 | N28: =M28-M27 -> 0 | O28: =O27 -> 1869 | P28: =P27 -> 1979 | Q28: =Q27 -> 167350 | R28: =Q28-Q27 -> 0 | S28: =SUM(P28-P27) -> 0 | T28: =SUM(S28*$T$2) -> 0 | U28: =SUM(G28+L28+S28) -> 0 | V28: =R28+N28+I28:I28 -> 0 | X28: =X27 -> 2454 | Y28: =X28-X27 -> 0 | Z28: =Z27 -> 138028.1 | AA28: =Z28-Z27 -> 0 | AB28: =SUM(Y28*$AB$2) -> 0 | AC28: =AC27 -> 1934 | AD28: =AC28-AC27 -> 0 | AE28: =AE27 -> 365352 | AF28: =AE28-AE27 -> 0 | AG28: =IF(AD28>0,AF28/AD28,0) -> 0 | AH28: =AF28+AA28 -> 0 | AI28: =SUM(AH28+V28) -> 0 | AJ28: =-tanks!AW29 -> 0 | AK28: =SUM(AJ28-AI28) -> 0 | AL28: =S28+L28+G28 -> 0 | AM28: =Y28+AD28 -> 0 | AN28: =AN27 -> 67 | AO28: =(AN28/100)*3000 -> 2010 | AP28: =AP27 -> 55 | AQ28: =(AP28/100)*3000 -> 1650 | AR28: =AR27 -> 61 | AS28: =(AR28/100)*3000 -> 1830 | AT28: =SUM(AO28+AQ28+AS28) -> 5490 | AU28: =AT27-AT28+AV28 -> 0 | AX28: =IF(AV28>0,AW28,AX27) -> 0.8
A29: =ELEC!C27 -> 44252 | B29: =B28 -> 219 | C29: =C28 -> 224 | D29: =C28-C29 -> 0 | E29: =D29*8.38 -> 0 | F29: =F28 -> 1731 | G29: =F29-F28 -> 0 | H29: =H28 -> 5125 | I29: =SUM(H29-H28) -> 0 | J29: =IF(G29>0,I29/G29,0) -> 0 | K29: =K28 -> 2230 | L29: =K29-K28 -> 0 | M29: =M28 -> 163965 | N29: =M29-M28 -> 0 | O29: =O28 -> 1869 | P29: =P28 -> 1979 | Q29: =Q28 -> 167350 | R29: =Q29-Q28 -> 0 | S29: =SUM(P29-P28) -> 0 | T29: =SUM(S29*$T$2) -> 0 | U29: =SUM(G29+L29+S29) -> 0 | V29: =R29+N29+I29:I29 -> 0 | X29: =X28 -> 2454 | Y29: =X29-X28 -> 0 | Z29: =Z28 -> 138028.1 | AA29: =Z29-Z28 -> 0 | AB29: =SUM(Y29*$AB$2) -> 0 | AC29: =AC28 -> 1934 | AD29: =AC29-AC28 -> 0 | AE29: =AE28 -> 365352 | AF29: =AE29-AE28 -> 0 | AG29: =IF(AD29>0,AF29/AD29,0) -> 0 | AH29: =AF29+AA29 -> 0 | AI29: =SUM(AH29+V29) -> 0 | AJ29: =-tanks!AW30 -> 0 | AK29: =SUM(AJ29-AI29) -> 0 | AL29: =S29+L29+G29 -> 0 | AM29: =Y29+AD29 -> 0 | AN29: =AN28 -> 67 | AO29: =(AN29/100)*3000 -> 2010 | AP29: =AP28 -> 55 | AQ29: =(AP29/100)*3000 -> 1650 | AR29: =AR28 -> 61 | AS29: =(AR29/100)*3000 -> 1830 | AT29: =SUM(AO29+AQ29+AS29) -> 5490 | AU29: =AT28-AT29+AV29 -> 0 | AX29: =IF(AV29>0,AW29,AX28) -> 0.8
