Workbook

Sheet TOTAL
A1: Site Name | B1: Day | C1: Month | D1: Year | E1: Total Electricity Kwh | F1: Electricity Tariff ($/Kwh) | G1: Total Fuel Oil (Liters) | H1: Fuel Oil $/Liter | I1: Water Utility Supply (m3) m3 | J1: Water Utility Supply (m3) $/m3 | K1: LPG (Kg) | L1: LPG $/Kg | M1: Room Nights | N1: Total Guests | O1: Food Covers
A2: Maldives at Kuda Huraa | B2: 1 | C2: 2 | D2: 2021 | E2: 20560 | F2: 0.14 | G2: 5493 | H2: 0.44534802 | I2: 279 | J2: 0.4 | K2: =K33/31 -> 0 | L2: 1.5287028 | M2: 23 | N2: 52 | O2: 148
A3: Maldives at Kuda Huraa | B3: =B2+1 -> 2 | C3: 2 | D3: 2021 | E3: 24530 | F3: 0.14 | G3: 6460 | H3: 0.44534802 | I3: 248 | J3: 0.4 | K3: 0 | L3: 1.5287028 | M3: 26 | N3: 64 | O3: 195
A4: Maldives at Kuda Huraa | B4: =B3+1 -> 3 | C4: 2 | D4: 2021 | E4: 21160 | F4: 0.14 | G4: 6147 | H4: 0.44534802 | I4: 241 | J4: 0.4 | K4: 0 | L4: 1.5287028 | M4: 27 | N4: 68 | O4: 217
A5: Maldives at Kuda Huraa | B5: =B4+1 -> 4 | C5: 2 | D5: 2021 | E5: 20480 | F5: 0.14 | G5: 5852 | H5: 0.44534802 | I5: 216 | J5: 0.4 | K5: 0 | L5: 1.5287028 | M5: 28 | N5: 68 | O5: 199
A6: Maldives at Kuda Huraa | B6: =B5+1 -> 5 | C6: 2 | D6: 2021 | E6: 20840 | F6: 0.14 | G6: 5479 | H6: 0.44534802 | I6: 240 | J6: 0.4 | K6: 0 | L6: 1.5287028 | M6: 31 | N6: 76 | O6: 204
A7: Maldives at Kuda Huraa | B7: =B6+1 -> 6 | C7: 2 | D7: 2021 | E7: 21680 | F7: 0.14 | G7: 5802 | H7: 0.44534802 | I7: 231 | J7: 0.4 | K7: 0 | L7: 1.5287028 | M7: 29 | N7: 74 | O7: 223
A8: Maldives at Kuda Huraa | B8: =B7+1 -> 7 | C8: 2 | D8: 2021 | E8: 20130 | F8: 0.14 | G8: 5630 | H8: 0.44534802 | I8: 174 | J8: 0.4 | K8: 0 | L8: 1.5287028 | M8: 24 | N8: 59 | O8: 172
A9: Maldives at Kuda Huraa | B9: =B8+1 -> 8 | C9: 2 | D9: 2021 | E9: 21680 | F9: 0.14 | G9: 5898 | H9: 0.44534802 | I9: 305 | J9: 0.4 | K9: 0 | L9: 1.5287028 | M9: 24 | N9: 62 | O9: 176
A10: Maldives at Kuda Huraa | B10: =B9+1 -> 9 | C10: 2 | D10: 2021 | E10: 20390 | F10: 0.14 | G10: 5654 | H10: 0.44534802 | I10: 258 | J10: 0.4 | K10: 0 | L10: 1.5287028 | M10: 27 | N10: 70 | O10: 193
A11: Maldives at Kuda Huraa | B11: =B10+1 -> 10 | C11: 2 | D11: 2021 | E11: 21710 | F11: 0.14 | G11: 5698 | H11: 0.44534802 | I11: 280 | J11: 0.4 | K11: 0 | L11: 1.5287028 | M11: 23 | N11: 58 | O11: 160
A12: Maldives at Kuda Huraa | B12: =B11+1 -> 11 | C12: 2 | D12: 2021 | E12: 20670 | F12: 0.14 | G12: 5401 | H12: 0.44534802 | I12: 240 | J12: 0.4 | K12: 0 | L12: 1.5287028 | M12: 23 | N12: 59 | O12: 175
A13: Maldives at Kuda Huraa | B13: =B12+1 -> 12 | C13: 2 | D13: 2021 | E13: 20600 | F13: 0.14 | G13: 5795 | H13: 0.44534802 | I13: 257 | J13: 0.4 | K13: 0 | L13: 1.5287028
A14: Maldives at Kuda Huraa | B14: =B13+1 -> 13 | C14: 2 | D14: 2021 | E14: 0 | F14: 0.14 | G14: 0 | H14: 0.44534802 | I14: 0 | J14: 0.4 | K14: 0 | L14: 1.5287028
A15: Maldives at Kuda Huraa | B15: =B14+1 -> 14 | C15: 2 | D15: 2021 | E15: 0 | F15: 0.14 | G15: 0 | H15: 0.44534802 | I15: 0 | J15: 0.4 | K15: 0 | L15: 1.5287028
A16: Maldives at Kuda Huraa | B16: =B15+1 -> 15 | C16: 2 | D16: 2021 | E16: 0 | F16: 0.14 | G16: 0 | H16: 0.44534802 | I16: 0 | J16: 0.4 | K16: 0 | L16: 1.5287028
A17: Maldives at Kuda Huraa | B17: =B16+1 -> 16 | C17: 2 | D17: 2021 | E17: 0 | F17: 0.14 | G17: 0 | H17: 0.44534802 | I17: 0 | J17: 0.4 | K17: 0 | L17: 1.5287028
A18: Maldives at Kuda Huraa | B18: =B17+1 -> 17 | C18: 2 | D18: 2021 | E18: 0 | F18: 0.14 | G18: 0 | H18: 0.44534802 | I18: 0 | J18: 0.4 | K18: 0 | L18: 1.5287028
A19: Maldives at Kuda Huraa | B19: =B18+1 -> 18 | C19: 2 | D19: 2021 | E19: 0 | F19: 0.14 | G19: 0 | H19: 0.44534802 | I19: 0 | J19: 0.4 | K19: 0 | L19: 1.5287028
A20: Maldives at Kuda Huraa | B20: =B19+1 -> 19 | C20: 2 | D20: 2021 | E20: 0 | F20: 0.14 | G20: 0 | H20: 0.44534802 | I20: 0 | J20: 0.4 | K20: 0 | L20: 1.5287028
A21: Maldives at Kuda Huraa | B21: =B20+1 -> 20 | C21: 2 | D21: 2021 | E21: 0 | F21: 0.14 | G21: 0 | H21: 0.44534802 | I21: 0 | J21: 0.4 | K21: 0 | L21: 1.5287028
A22: Maldives at Kuda Huraa | B22: =B21+1 -> 21 | C22: 2 | D22: 2021 | E22: 0 | F22: 0.14 | G22: 0 | H22: 0.44534802 | I22: 0 | J22: 0.4 | K22: 0 | L22: 1.5287028
A23: Maldives at Kuda Huraa | B23: =B22+1 -> 22 | C23: 2 | D23: 2021 | E23: 0 | F23: 0.14 | G23: 0 | H23: 0.44534802 | I23: 0 | J23: 0.4 | K23: 0 | L23: 1.5287028
A24: Maldives at Kuda Huraa | B24: =B23+1 -> 23 | C24: 2 | D24: 2021 | E24: 0 | F24: 0.14 | G24: 0 | H24: 0.44534802 | I24: 0 | J24: 0.4 | K24: 0 | L24: 1.5287028
... A32: Maldives at Kuda Huraa | B32: =B31+1 -> 31 | C32: 0 | D32: 2021 | E32: 0 | F32: 0.14 | G32: 0 | H32: 0.44534802 | I32: 0 | J32: 0.4 | K32: 0 | L32: 1.5287028
A33: Total | E33: =SUM(E2:E32) -> 254430 | F33: 0 | G33: =SUM(G2:G32) -> 69309 | H33: 0 | I33: =SUM(I2:I32) -> 2969 | J33: 0 | K33: 0 | L33: 0 | M33: =SUM(M2:M32) -> 285 | N33: =SUM(N2:N32) -> 710 | O33: =SUM(O2:O32) -> 2062

Sheet Kwh Reading
A1: Electric Consumption Record (4pm)
A2: Month | B2: BOH-1/ B&C Block MWH | C2: Pastry MWH | D2: Feeder 401-419 KWH | E2: Feeder 301-319 KWH | F2: Kitchen GWH | G2: Feeder 201-208 MWH | H2: Feeder 113-123 | I2: M - Block /PC MWH | J2: Laundry MWH | M2: Feeder 101-112 MWH | N2: Feeder 217-224 | O2: Spa MWH | P2: Feeder 124-134 | Q2: Feeder 209-216 | R2: STP -1 &2 MWH | S2: STP -3 MWH | T2: Reef Club MWH | V2: Room Nights | W2: Total Guests | X2: Food Covers
J3: A | K3: B | L3: C
A4: 44228 | B4: 789.94 | C4: 195.33 | D4: 7127780.3 | E4: 7729754.4 | F4: 2.0137 | G4: 609.18 | H4: 507.25 | I4: 189.12 | J4: 282.31 | K4: 295.32 | L4: 202.65 | M4: 407.78 | N4: 353.62 | O4: 114.83 | P4: 471.72 | Q4: 350.86 | R4: 119.31 | S4: 95.496 | T4: 350.44 | V4: 23 | W4: 52 | X4: 148
A5: 44229 | B5: 791.11 | C5: 195.59 | D5: 7129899.7 | E5: 7732600.4 | F5: 2.0161 | G5: 610.13 | H5: 508.09 | I5: 189.36 | J5: 282.63 | K5: 295.62 | L5: 202.84 | M5: 408.46 | N5: 354.45 | O5: 115.03 | P5: 472.5 | Q5: 351.4 | R5: 119.48 | S5: 95.629 | T5: 350.86 | V5: 26 | W5: 64 | X5: 195
A6: 44230 | B6: 792.35 | C6: 195.88 | D6: 7132506.8 | E6: 7735877.5 | F6: 2.0186 | G6: 611.03 | H6: 509 | I6: 189.64 | J6: 283.05 | K6: 295.97 | L6: 203.04 | M6: 409.18 | N6: 355.3 | O6: 115.23 | P6: 473.4 | Q6: 352.09 | R6: 119.71 | S6: 95.779 | T6: 351.42 | V6: 27 | W6: 68 | X6: 217
A7: 44231 | B7: 793.49 | C7: 196.12 | D7: 7134799.5 | E7: 7738767.1 | F7: 2.021 | G7: 611.85 | H7: 509.88 | I7: 189.92 | J7: 283.32 | K7: 296.33 | L7: 203.25 | M7: 409.96 | N7: 356.07 | O7: 115.43 | P7: 474.27 | Q7: 352.7 | R7: 119.87 | S7: 95.908 | T7: 351.94 | V7: 28 | W7: 68 | X7: 199
A8: 44232 | B8: 794.65 | C8: 196.37 | D8: 7137019.3 | E8: 7741800.5 | F8: 2.0235 | G8: 612.7 | H8: 510.79 | I8: 190.2 | J8: 283.61 | K8: 296.66 | L8: 203.49 | M8: 410.7 | N8: 356.85 | O8: 115.62 | P8: 475.13 | Q8: 353.42 | R8: 119.98 | S8: 96.043 | T8: 352.42 | V8: 31 | W8: 76 | X8: 204
A9: 44233 | B9: 794.7 | C9: 196.62 | D9: 7138950 | E9: 7744227 | F9: 2.026 | G9: 613.46 | H9: 511.62 | I9: 190.43 | J9: 283.88 | K9: 297.01 | L9: 203.7 | M9: 411.29 | N9: 357.53 | O9: 115.83 | P9: 475.93 | Q9: 354.13 | R9: 112.16 | S9: 96.181 | T9: 352.7 | V9: 29 | W9: 74 | X9: 223
A10: 44234 | B10: 796.92 | C10: 196.9 | D10: 7141207.6 | E10: 7747292.3 | F10: 2.0286 | G10: 614.26 | H10: 512.61 | I10: 190.76 | J10: 284.12 | K10: 297.38 | L10: 203.95 | M10: 411.92 | N10: 358.37 | O10: 116.04 | P10: 476.73 | Q10: 354.94 | R10: 120.37 | S10: 96.323 | T10: 353.22 | V10: 24 | W10: 59 | X10: 172
A11: 44235 | B11: 797.96 | C11: 197.09 | D11: 7143016.5 | E11: 7750049.4 | F11: 2.0309 | G11: 615.03 | H11: 513.46 | I11: 191.02 | J11: 284.36 | K11: 297.63 | L11: 204.13 | M11: 412.59 | N11: 359.06 | O11: 116.24 | P11: 477.43 | Q11: 355.56 | R11: 120.49 | S11: 96.452 | T11: 353.73 | V11: 24 | W11: 62 | X11: 176
A12: 44236 | B12: 799.1 | C12: 197.34 | D12: 7145185.9 | E12: 7753203.5 | F12: 2.033 | G12: 615.94 | H12: 514.4 | I12: 191.3 | J12: 284.65 | K12: 297.97 | L12: 204.37 | M12: 413.36 | N12: 359.81 | O12: 116.44 | P12: 478.24 | Q12: 356.23 | R12: 120.69 | S12: 96.59 | T12: 354.24 | V12: 27 | W12: 70 | X12: 193
A13: 44237 | B13: 800.19 | C13: 197.59 | D13: 7147129.1 | E13: 7756079.7 | F13: 2.0357 | G13: 616.76 | H13: 515.33 | I13: 191.6 | J13: 284.86 | K13: 298.28 | L13: 204.59 | M13: 414.07 | N13: 360.56 | O13: 116.66 | P13: 479.05 | Q13: 356.94 | R13: 120.88 | S13: 96.726 | T13: 354.74 | V13: 23 | W13: 58 | X13: 160
A14: 44238 | B14: 801.37 | C14: 197.83 | D14: 7149129 | E14: 7758821.2 | F14: 2.0382 | G14: 617.56 | H14: 516.24 | I14: 191.89 | J14: 285.13 | K14: 298.64 | L14: 204.85 | M14: 414.79 | N14: 361.32 | O14: 116.86 | P14: 479.9 | Q14: 357.58 | R14: 120.99 | S14: 96.856 | T14: 355.27 | V14: 23 | W14: 59 | X14: 175
A15: 44239 | B15: 802.43 | C15: 198.07 | D15: 7151024.8 | E15: 7761424 | F15: 2.0405 | G15: 618.35 | H15: 517.1 | I15: 192.17 | J15: 285.32 | K15: 298.92 | L15: 205.07 | M15: 415.4 | N15: 362 | O15: 117.05 | P15: 480.64 | Q15: 358.19 | R15: 121.14 | S15: 96.98 | T15: 355.75
A16: 44240 | B16: 802.5 | C16: 198.3 | D16: 7153148.3 | E16: 7763924.6 | F16: 2.043 | G16: 619.19 | H16: 517.97 | I16: 192.42 | J16: 285.51 | K16: 299.26 | L16: 205.28 | M16: 416.04 | N16: 362.72 | O16: 117.24 | P16: 481.48 | Q16: 358.77 | R16: 121.36 | S16: 97.125 | T16: 356.02
A17: 44241
A18: 44242
A19: 44243
A20: 44244
A21: 44245
A22: 44246
A23: 44247
A24: 44248
A25: 44249
A26: 44250
A27: 44251
A28: 44252
... A31: 44255
V35: =SUM(V4:V34) -> 285 | W35: =SUM(W4:W34) -> 710 | X35: =SUM(X4:X34) -> 2062
T42: ……..

Sheet Kwh Consumption
A2: Date | B2: Total KWH | C2: Reef Club KWH | D2: Kitchen KWH | E2: Pastry KWH | F2: Laundry KWH | I2: STP -1 &2 KWH | J2: STP -3 KWH | K2: M - Block /PC KWH | L2: B&C Block KWH | M2: Guest Room Beach Pavilion & Beach Bungalow KWH | S2: Guest Room Water Bungalow KWH | U2: Spa KWH | V2: Others KWH
F3: A | G3: B | H3: C | M3: Feeder -101-112 | N3: Feeder -113-123 | O3: Feeder -124-134 | P3: Feeder -201-208 | Q3: Feeder -209-216 | R3: Feeder -217-224 | S3: Feeder -301-319 | T3: Feeder 401-419
A4: ='Kwh Reading'!A4 -> 44228 | B4: 20560 | C4: =('Kwh Reading'!T5-'Kwh Reading'!T4)*1000 -> 420 | D4: =('Kwh Reading'!F5-'Kwh Reading'!F4)*1000000 -> 2400 | E4: =('Kwh Reading'!C5-'Kwh Reading'!C4)*1000 -> 260 | F4: =('Kwh Reading'!J5-'Kwh Reading'!J4)*1000 -> 320 | G4: =('Kwh Reading'!K5-'Kwh Reading'!K4)*1000 -> 300 | H4: =('Kwh Reading'!L5-'Kwh Reading'!L4)*1000 -> 190 | I4: =('Kwh Reading'!R5-'Kwh Reading'!R4)*1000 -> 170 | J4: =('Kwh Reading'!S5-'Kwh Reading'!S4)*1000 -> 133 | K4: =('Kwh Reading'!I5-'Kwh Reading'!I4)*1000 -> 240 | L4: =('Kwh Reading'!B5-'Kwh Reading'!B4)*1000 -> 1170 | M4: =('Kwh Reading'!M5-'Kwh Reading'!M4)*1000 -> 680 | N4: =('Kwh Reading'!H5-'Kwh Reading'!H4)*1000 -> 840 | O4: =('Kwh Reading'!P5-'Kwh Reading'!P4)*1000 -> 780 | P4: =('Kwh Reading'!G5-'Kwh Reading'!G4)*1000 -> 950 | Q4: =('Kwh Reading'!Q5-'Kwh Reading'!Q4)*1000 -> 540 | R4: =('Kwh Reading'!N5-'Kwh Reading'!N4)*1000 -> 830 | S4: ='Kwh Reading'!E5-'Kwh Reading'!E4 -> 2846.04 | T4: ='Kwh Reading'!D5-'Kwh Reading'!D4 -> 2119.36 | U4: =('Kwh Reading'!O5-'Kwh Reading'!O4)*1000 -> 200 | V4: =B4-(SUM(C4:U4)) -> 5171.6
A5: ='Kwh Reading'!A5 -> 44229 | B5: =TOTAL!E3 -> 24530 | C5: =('Kwh Reading'!T6-'Kwh Reading'!T5)*1000 -> 560 | D5: =('Kwh Reading'!F6-'Kwh Reading'!F5)*1000000 -> 2500 | E5: =('Kwh Reading'!C6-'Kwh Reading'!C5)*1000 -> 290 | F5: =('Kwh Reading'!J6-'Kwh Reading'!J5)*1000 -> 420 | G5: =('Kwh Reading'!K6-'Kwh Reading'!K5)*1000 -> 350 | H5: =('Kwh Reading'!L6-'Kwh Reading'!L5)*1000 -> 200 | I5: =('Kwh Reading'!R6-'Kwh Reading'!R5)*1000 -> 230 | J5: =('Kwh Reading'!S6-'Kwh Reading'!S5)*1000 -> 150 | K5: =('Kwh Reading'!I6-'Kwh Reading'!I5)*1000 -> 280 | L5: =('Kwh Reading'!B6-'Kwh Reading'!B5)*1000 -> 1240 | M5: =('Kwh Reading'!M6-'Kwh Reading'!M5)*1000 -> 720 | N5: =('Kwh Reading'!H6-'Kwh Reading'!H5)*1000 -> 910 | O5: =('Kwh Reading'!P6-'Kwh Reading'!P5)*1000 -> 900 | P5: =('Kwh Reading'!G6-'Kwh Reading'!G5)*1000 -> 900 | Q5: =('Kwh Reading'!Q6-'Kwh Reading'!Q5)*1000 -> 690 | R5: =('Kwh Reading'!N6-'Kwh Reading'!N5)*1000 -> 850 | S5: ='Kwh Reading'!E6-'Kwh Reading'!E5 -> 3277.11 | T5: ='Kwh Reading'!D6-'Kwh Reading'!D5 -> 2607.1 | U5: =('Kwh Reading'!O6-'Kwh Reading'!O5)*1000 -> 200 | V5: =B5-(SUM(C5:U5)) -> 7255.79
A6: ='Kwh Reading'!A6 -> 44230 | B6: =TOTAL!E4 -> 21160 | C6: =('Kwh Reading'!T7-'Kwh Reading'!T6)*1000 -> 520 | D6: =('Kwh Reading'!F7-'Kwh Reading'!F6)*1000000 -> 2400 | E6: =('Kwh Reading'!C7-'Kwh Reading'!C6)*1000 -> 240 | F6: =('Kwh Reading'!J7-'Kwh Reading'!J6)*1000 -> 270 | G6: =('Kwh Reading'!K7-'Kwh Reading'!K6)*1000 -> 360 | H6: =('Kwh Reading'!L7-'Kwh Reading'!L6)*1000 -> 210 | I6: =('Kwh Reading'!R7-'Kwh Reading'!R6)*1000 -> 160 | J6: =('Kwh Reading'!S7-'Kwh Reading'!S6)*1000 -> 129 | K6: =('Kwh Reading'!I7-'Kwh Reading'!I6)*1000 -> 280 | L6: =('Kwh Reading'!B7-'Kwh Reading'!B6)*1000 -> 1140 | M6: =('Kwh Reading'!M7-'Kwh Reading'!M6)*1000 -> 780 | N6: =('Kwh Reading'!H7-'Kwh Reading'!H6)*1000 -> 880 | O6: =('Kwh Reading'!P7-'Kwh Reading'!P6)*1000 -> 870 | P6: =('Kwh Reading'!G7-'Kwh Reading'!G6)*1000 -> 820 | Q6: =('Kwh Reading'!Q7-'Kwh Reading'!Q6)*1000 -> 610 | R6: =('Kwh Reading'!N7-'Kwh Reading'!N6)*1000 -> 770 | S6: ='Kwh Reading'!E7-'Kwh Reading'!E6 -> 2889.61 | T6: ='Kwh Reading'!D7-'Kwh Reading'!D6 -> 2292.67 | U6: =('Kwh Reading'!O7-'Kwh Reading'!O6)*1000 -> 200 | V6: =B6-(SUM(C6:U6)) -> 5338.72
A7: ='Kwh Reading'!A7 -> 44231 | B7: =TOTAL!E5 -> 20480 | C7: =('Kwh Reading'!T8-'Kwh Reading'!T7)*1000 -> 480 | D7: =('Kwh Reading'!F8-'Kwh Reading'!F7)*1000000 -> 2500 | E7: =('Kwh Reading'!C8-'Kwh Reading'!C7)*1000 -> 250 | F7: =('Kwh Reading'!J8-'Kwh Reading'!J7)*1000 -> 290 | G7: =('Kwh Reading'!K8-'Kwh Reading'!K7)*1000 -> 330 | H7: =('Kwh Reading'!L8-'Kwh Reading'!L7)*1000 -> 240 | I7: =('Kwh Reading'!R8-'Kwh Reading'!R7)*1000 -> 110 | J7: =('Kwh Reading'!S8-'Kwh Reading'!S7)*1000 -> 135 | K7: =('Kwh Reading'!I8-'Kwh Reading'!I7)*1000 -> 280 | L7: =('Kwh Reading'!B8-'Kwh Reading'!B7)*1000 -> 1160 | M7: =('Kwh Reading'!M8-'Kwh Reading'!M7)*1000 -> 740 | N7: =('Kwh Reading'!H8-'Kwh Reading'!H7)*1000 -> 910 | O7: =('Kwh Reading'!P8-'Kwh Reading'!P7)*1000 -> 860 | P7: =('Kwh Reading'!G8-'Kwh Reading'!G7)*1000 -> 850 | Q7: =('Kwh Reading'!Q8-'Kwh Reading'!Q7)*1000 -> 720 | R7: =('Kwh Reading'!N8-'Kwh Reading'!N7)*1000 -> 780 | S7: ='Kwh Reading'!E8-'Kwh Reading'!E7 -> 3033.39 | T7: ='Kwh Reading'!D8-'Kwh Reading'!D7 -> 2219.83 | U7: =('Kwh Reading'!O8-'Kwh Reading'!O7)*1000 -> 190 | V7: =B7-(SUM(C7:U7)) -> 4401.78
A8: ='Kwh Reading'!A8 -> 44232 | B8: =TOTAL!E6 -> 20840 | C8: =('Kwh Reading'!T9-'Kwh Reading'!T8)*1000 -> 280 | D8: =('Kwh Reading'!F9-'Kwh Reading'!F8)*1000000 -> 2500 | E8: =('Kwh Reading'!C9-'Kwh Reading'!C8)*1000 -> 250 | F8: =('Kwh Reading'!J9-'Kwh Reading'!J8)*1000 -> 270 | G8: =('Kwh Reading'!K9-'Kwh Reading'!K8)*1000 -> 350 | H8: =('Kwh Reading'!L9-'Kwh Reading'!L8)*1000 -> 210 | I8: =('Kwh Reading'!R9-'Kwh Reading'!R8)*1000 -> -7820 | J8: =('Kwh Reading'!S9-'Kwh Reading'!S8)*1000 -> 138 | K8: =('Kwh Reading'!I9-'Kwh Reading'!I8)*1000 -> 230 | L8: =('Kwh Reading'!B9-'Kwh Reading'!B8)*1000 -> 50 | M8: =('Kwh Reading'!M9-'Kwh Reading'!M8)*1000 -> 590 | N8: =('Kwh Reading'!H9-'Kwh Reading'!H8)*1000 -> 830 | O8: =('Kwh Reading'!P9-'Kwh Reading'!P8)*1000 -> 800 | P8: =('Kwh Reading'!G9-'Kwh Reading'!G8)*1000 -> 760 | Q8: =('Kwh Reading'!Q9-'Kwh Reading'!Q8)*1000 -> 710 | R8: =('Kwh Reading'!N9-'Kwh Reading'!N8)*1000 -> 680 | S8: ='Kwh Reading'!E9-'Kwh Reading'!E8 -> 2426.53 | T8: ='Kwh Reading'!D9-'Kwh Reading'!D8 -> 1930.74 | U8: =('Kwh Reading'!O9-'Kwh Reading'!O8)*1000 -> 210 | V8: =B8-(SUM(C8:U8)) -> 15444.73
A9: ='Kwh Reading'!A9 -> 44233 | B9: =TOTAL!E7 -> 21680 | C9: =('Kwh Reading'!T10-'Kwh Reading'!T9)*1000 -> 520 | D9: =('Kwh Reading'!F10-'Kwh Reading'!F9)*1000000 -> 2600 | E9: =('Kwh Reading'!C10-'Kwh Reading'!C9)*1000 -> 280 | F9: =('Kwh Reading'!J10-'Kwh Reading'!J9)*1000 -> 240 | G9: =('Kwh Reading'!K10-'Kwh Reading'!K9)*1000 -> 370 | H9: =('Kwh Reading'!L10-'Kwh Reading'!L9)*1000 -> 250 | I9: =('Kwh Reading'!R10-'Kwh Reading'!R9)*1000 -> 8210 | J9: =('Kwh Reading'!S10-'Kwh Reading'!S9)*1000 -> 142 | K9: =('Kwh Reading'!I10-'Kwh Reading'!I9)*1000 -> 330 | L9: =('Kwh Reading'!B10-'Kwh Reading'!B9)*1000 -> 2220 | M9: =('Kwh Reading'!M10-'Kwh Reading'!M9)*1000 -> 630 | N9: =('Kwh Reading'!H10-'Kwh Reading'!H9)*1000 -> 990 | O9: =('Kwh Reading'!P10-'Kwh Reading'!P9)*1000 -> 800 | P9: =('Kwh Reading'!G10-'Kwh Reading'!G9)*1000 -> 800 | Q9: =('Kwh Reading'!Q10-'Kwh Reading'!Q9)*1000 -> 810 | R9: =('Kwh Reading'!N10-'Kwh Reading'!N9)*1000 -> 840 | S9: ='Kwh Reading'!E10-'Kwh Reading'!E9 -> 3065.22 | T9: ='Kwh Reading'!D10-'Kwh Reading'!D9 -> 2257.59 | U9: =('Kwh Reading'!O10-'Kwh Reading'!O9)*1000 -> 210 | V9: =B9-(SUM(C9:U9)) -> -3884.81
A10: ='Kwh Reading'!A10 -> 44234 | B10: =TOTAL!E8 -> 20130 | C10: =('Kwh Reading'!T11-'Kwh Reading'!T10)*1000 -> 510 | D10: =('Kwh Reading'!F11-'Kwh Reading'!F10)*1000000 -> 2300 | E10: =('Kwh Reading'!C11-'Kwh Reading'!C10)*1000 -> 190 | F10: =('Kwh Reading'!J11-'Kwh Reading'!J10)*1000 -> 240 | G10: =('Kwh Reading'!K11-'Kwh Reading'!K10)*1000 -> 250 | H10: =('Kwh Reading'!L11-'Kwh Reading'!L10)*1000 -> 180 | I10: =('Kwh Reading'!R11-'Kwh Reading'!R10)*1000 -> 120 | J10: =('Kwh Reading'!S11-'Kwh Reading'!S10)*1000 -> 129 | K10: =('Kwh Reading'!I11-'Kwh Reading'!I10)*1000 -> 260 | L10: =('Kwh Reading'!B11-'Kwh Reading'!B10)*1000 -> 1040 | M10: =('Kwh Reading'!M11-'Kwh Reading'!M10)*1000 -> 670 | N10: =('Kwh Reading'!H11-'Kwh Reading'!H10)*1000 -> 850 | O10: =('Kwh Reading'!P11-'Kwh Reading'!P10)*1000 -> 700 | P10: =('Kwh Reading'!G11-'Kwh Reading'!G10)*1000 -> 770 | Q10: =('Kwh Reading'!Q11-'Kwh Reading'!Q10)*1000 -> 620 | R10: =('Kwh Reading'!N11-'Kwh Reading'!N10)*1000 -> 690 | S10: ='Kwh Reading'!E11-'Kwh Reading'!E10 -> 2757.15 | T10: ='Kwh Reading'!D11-'Kwh Reading'!D10 -> 1808.91 | U10: =('Kwh Reading'!O11-'Kwh Reading'!O10)*1000 -> 200 | V10: =B10-(SUM(C10:U10)) -> 5844.94
A11: ='Kwh Reading'!A11 -> 44235 | B11: =TOTAL!E9 -> 21680 | C11: =('Kwh Reading'!T12-'Kwh Reading'!T11)*1000 -> 510 | D11: =('Kwh Reading'!F12-'Kwh Reading'!F11)*1000000 -> 2100 | E11: =('Kwh Reading'!C12-'Kwh Reading'!C11)*1000 -> 250 | F11: =('Kwh Reading'!J12-'Kwh Reading'!J11)*1000 -> 290 | G11: =('Kwh Reading'!K12-'Kwh Reading'!K11)*1000 -> 340 | H11: =('Kwh Reading'!L12-'Kwh Reading'!L11)*1000 -> 240 | I11: =('Kwh Reading'!R12-'Kwh Reading'!R11)*1000 -> 200 | J11: =('Kwh Reading'!S12-'Kwh Reading'!S11)*1000 -> 138 | K11: =('Kwh Reading'!I12-'Kwh Reading'!I11)*1000 -> 280 | L11: =('Kwh Reading'!B12-'Kwh Reading'!B11)*1000 -> 1140 | M11: =('Kwh Reading'!M12-'Kwh Reading'!M11)*1000 -> 770 | N11: =('Kwh Reading'!H12-'Kwh Reading'!H11)*1000 -> 940 | O11: =('Kwh Reading'!P12-'Kwh Reading'!P11)*1000 -> 810 | P11: =('Kwh Reading'!G12-'Kwh Reading'!G11)*1000 -> 910 | Q11: =('Kwh Reading'!Q12-'Kwh Reading'!Q11)*1000 -> 670 | R11: =('Kwh Reading'!N12-'Kwh Reading'!N11)*1000 -> 750 | S11: ='Kwh Reading'!E12-'Kwh Reading'!E11 -> 3154.05 | T11: ='Kwh Reading'!D12-'Kwh Reading'!D11 -> 2169.35 | U11: =('Kwh Reading'!O12-'Kwh Reading'!O11)*1000 -> 200 | V11: =B11-(SUM(C11:U11)) -> 5818.6
A12: ='Kwh Reading'!A12 -> 44236 | B12: =TOTAL!E10 -> 20390 | C12: =('Kwh Reading'!T13-'Kwh Reading'!T12)*1000 -> 500 | D12: =('Kwh Reading'!F13-'Kwh Reading'!F12)*1000000 -> 2700 | E12: =('Kwh Reading'!C13-'Kwh Reading'!C12)*1000 -> 250 | F12: =('Kwh Reading'!J13-'Kwh Reading'!J12)*1000 -> 210 | G12: =('Kwh Reading'!K13-'Kwh Reading'!K12)*1000 -> 310 | H12: =('Kwh Reading'!L13-'Kwh Reading'!L12)*1000 -> 220 | I12: =('Kwh Reading'!R13-'Kwh Reading'!R12)*1000 -> 190 | J12: =('Kwh Reading'!S13-'Kwh Reading'!S12)*1000 -> 136 | K12: =('Kwh Reading'!I13-'Kwh Reading'!I12)*1000 -> 300 | L12: =('Kwh Reading'!B13-'Kwh Reading'!B12)*1000 -> 1090 | M12: =('Kwh Reading'!M13-'Kwh Reading'!M12)*1000 -> 710 | N12: =('Kwh Reading'!H13-'Kwh Reading'!H12)*1000 -> 930 | O12: =('Kwh Reading'!P13-'Kwh Reading'!P12)*1000 -> 810 | P12: =('Kwh Reading'!G13-'Kwh Reading'!G12)*1000 -> 820 | Q12: =('Kwh Reading'!Q13-'Kwh Reading'!Q12)*1000 -> 710 | R12: =('Kwh Reading'!N13-'Kwh Reading'!N12)*1000 -> 750 | S12: ='Kwh Reading'!E13-'Kwh Reading'!E12 -> 2876.28 | T12: ='Kwh Reading'!D13-'Kwh Reading'!D12 -> 1943.19 | U12: =('Kwh Reading'!O13-'Kwh Reading'!O12)*1000 -> 220 | V12: =B12-(SUM(C12:U12)) -> 4714.53
A13: ='Kwh Reading'!A13 -> 44237 | B13: =TOTAL!E11 -> 21710 | C13: =('Kwh Reading'!T14-'Kwh Reading'!T13)*1000 -> 530 | D13: =('Kwh Reading'!F14-'Kwh Reading'!F13)*1000000 -> 2500 | E13: =('Kwh Reading'!C14-'Kwh Reading'!C13)*1000 -> 240 | F13: =('Kwh Reading'!J14-'Kwh Reading'!J13)*1000 -> 270 | G13: =('Kwh Reading'!K14-'Kwh Reading'!K13)*1000 -> 360 | H13: =('Kwh Reading'!L14-'Kwh Reading'!L13)*1000 -> 260 | I13: =('Kwh Reading'!R14-'Kwh Reading'!R13)*1000 -> 110 | J13: =('Kwh Reading'!S14-'Kwh Reading'!S13)*1000 -> 130 | K13: =('Kwh Reading'!I14-'Kwh Reading'!I13)*1000 -> 290 | L13: =('Kwh Reading'!B14-'Kwh Reading'!B13)*1000 -> 1180 | M13: =('Kwh Reading'!M14-'Kwh Reading'!M13)*1000 -> 720 | N13: =('Kwh Reading'!H14-'Kwh Reading'!H13)*1000 -> 910 | O13: =('Kwh Reading'!P14-'Kwh Reading'!P13)*1000 -> 850 | P13: =('Kwh Reading'!G14-'Kwh Reading'!G13)*1000 -> 800 | Q13: =('Kwh Reading'!Q14-'Kwh Reading'!Q13)*1000 -> 640 | R13: =('Kwh Reading'!N14-'Kwh Reading'!N13)*1000 -> 760 | S13: ='Kwh Reading'!E14-'Kwh Reading'!E13 -> 2741.41 | T13: ='Kwh Reading'!D14-'Kwh Reading'!D13 -> 1999.94 | U13: =('Kwh Reading'!O14-'Kwh Reading'!O13)*1000 -> 200 | V13: =B13-(SUM(C13:U13)) -> 6218.65
A14: ='Kwh Reading'!A14 -> 44238 | B14: =TOTAL!E12 -> 20670 | C14: =('Kwh Reading'!T15-'Kwh Reading'!T14)*1000 -> 480 | D14: =('Kwh Reading'!F15-'Kwh Reading'!F14)*1000000 -> 2300 | E14: =('Kwh Reading'!C15-'Kwh Reading'!C14)*1000 -> 240 | F14: =('Kwh Reading'!J15-'Kwh Reading'!J14)*1000 -> 190 | G14: =('Kwh Reading'!K15-'Kwh Reading'!K14)*1000 -> 280 | H14: =('Kwh Reading'!L15-'Kwh Reading'!L14)*1000 -> 220 | I14: =('Kwh Reading'!R15-'Kwh Reading'!R14)*1000 -> 150 | J14: =('Kwh Reading'!S15-'Kwh Reading'!S14)*1000 -> 124 | K14: =('Kwh Reading'!I15-'Kwh Reading'!I14)*1000 -> 280 | L14: =('Kwh Reading'!B15-'Kwh Reading'!B14)*1000 -> 1060 | M14: =('Kwh Reading'!M15-'Kwh Reading'!M14)*1000 -> 610 | N14: =('Kwh Reading'!H15-'Kwh Reading'!H14)*1000 -> 860 | O14: =('Kwh Reading'!P15-'Kwh Reading'!P14)*1000 -> 740 | P14: =('Kwh Reading'!G15-'Kwh Reading'!G14)*1000 -> 790 | Q14: =('Kwh Reading'!Q15-'Kwh Reading'!Q14)*1000 -> 610 | R14: =('Kwh Reading'!N15-'Kwh Reading'!N14)*1000 -> 680 | S14: ='Kwh Reading'!E15-'Kwh Reading'!E14 -> 2602.9 | T14: ='Kwh Reading'!D15-'Kwh Reading'!D14 -> 1895.77 | U14: =('Kwh Reading'!O15-'Kwh Reading'!O14)*1000 -> 190 | V14: =B14-(SUM(C14:U14)) -> 6367.33
A15: ='Kwh Reading'!A15 -> 44239 | B15: =TOTAL!E13 -> 20600 | C15: =('Kwh Reading'!T16-'Kwh Reading'!T15)*1000 -> 270 | D15: =('Kwh Reading'!F16-'Kwh Reading'!F15)*1000000 -> 2500 | E15: =('Kwh Reading'!C16-'Kwh Reading'!C15)*1000 -> 230 | F15: =('Kwh Reading'!J16-'Kwh Reading'!J15)*1000 -> 190 | G15: =('Kwh Reading'!K16-'Kwh Reading'!K15)*1000 -> 340 | H15: =('Kwh Reading'!L16-'Kwh Reading'!L15)*1000 -> 210 | I15: =('Kwh Reading'!R16-'Kwh Reading'!R15)*1000 -> 220 | J15: =('Kwh Reading'!S16-'Kwh Reading'!S15)*1000 -> 145 | K15: =('Kwh Reading'!I16-'Kwh Reading'!I15)*1000 -> 250 | L15: =('Kwh Reading'!B16-'Kwh Reading'!B15)*1000 -> 70 | M15: =('Kwh Reading'!M16-'Kwh Reading'!M15)*1000 -> 640 | N15: =('Kwh Reading'!H16-'Kwh Reading'!H15)*1000 -> 870 | O15: =('Kwh Reading'!P16-'Kwh Reading'!P15)*1000 -> 840 | P15: =('Kwh Reading'!G16-'Kwh Reading'!G15)*1000 -> 840 | Q15: =('Kwh Reading'!Q16-'Kwh Reading'!Q15)*1000 -> 580 | R15: =('Kwh Reading'!N16-'Kwh Reading'!N15)*1000 -> 720 | S15: ='Kwh Reading'!E16-'Kwh Reading'!E15 -> 2500.57 | T15: ='Kwh Reading'!D16-'Kwh Reading'!D15 -> 2123.5 | U15: =('Kwh Reading'!O16-'Kwh Reading'!O15)*1000 -> 190 | V15: =B15-(SUM(C15:U15)) -> 6870.93
A16: ='Kwh Reading'!A16 -> 44240 | B16: =TOTAL!E14 -> 0 | C16: =('Kwh Reading'!T17-'Kwh Reading'!T16)*1000 -> -356020 | D16: =('Kwh Reading'!F17-'Kwh Reading'!F16)*1000000 -> -2043000 | E16: =('Kwh Reading'!C17-'Kwh Reading'!C16)*1000 -> -198300 | F16: =('Kwh Reading'!J17-'Kwh Reading'!J16)*1000 -> -285510 | G16: =('Kwh Reading'!K17-'Kwh Reading'!K16)*1000 -> -299260 | H16: =('Kwh Reading'!L17-'Kwh Reading'!L16)*1000 -> -205280 | I16: =('Kwh Reading'!R17-'Kwh Reading'!R16)*1000 -> -121360 | J16: =('Kwh Reading'!S17-'Kwh Reading'!S16)*1000 -> -97125 | K16: =('Kwh Reading'!I17-'Kwh Reading'!I16)*1000 -> -192420 | L16: =('Kwh Reading'!B17-'Kwh Reading'!B16)*1000 -> -802500 | M16: =('Kwh Reading'!M17-'Kwh Reading'!M16)*1000 -> -416040 | N16: =('Kwh Reading'!H17-'Kwh Reading'!H16)*1000 -> -517970 | O16: =('Kwh Reading'!P17-'Kwh Reading'!P16)*1000 -> -481480 | P16: =('Kwh Reading'!G17-'Kwh Reading'!G16)*1000 -> -619190 | Q16: =('Kwh Reading'!Q17-'Kwh Reading'!Q16)*1000 -> -358770 | R16: =('Kwh Reading'!N17-'Kwh Reading'!N16)*1000 -> -362720 | S16: ='Kwh Reading'!E17-'Kwh Reading'!E16 -> -7763924.6 | T16: ='Kwh Reading'!D17-'Kwh Reading'!D16 -> -7153148.3 | U16: =('Kwh Reading'!O17-'Kwh Reading'!O16)*1000 -> -117240 | V16: =B16-(SUM(C16:U16)) -> 22391258
... A26: ='Kwh Reading'!A26 -> 44250 | B26: =TOTAL!E24 -> 0 | C26: =('Kwh Reading'!T27-'Kwh Reading'!T26)*1000 -> 0 | D26: =('Kwh Reading'!F27-'Kwh Reading'!F26)*1000000 -> 0 | E26: =('Kwh Reading'!C27-'Kwh Reading'!C26)*1000 -> 0 | F26: =('Kwh Reading'!J27-'Kwh Reading'!J26)*1000 -> 0 | G26: =('Kwh Reading'!K27-'Kwh Reading'!K26)*1000 -> 0 | H26: =('Kwh Reading'!L27-'Kwh Reading'!L26)*1000 -> 0 | I26: =('Kwh Reading'!R27-'Kwh Reading'!R26)*1000 -> 0 | J26: =('Kwh Reading'!S27-'Kwh Reading'!S26)*1000 -> 0 | K26: =('Kwh Reading'!I27-'Kwh Reading'!I26)*1000 -> 0 | L26: =('Kwh Reading'!B27-'Kwh Reading'!B26)*1000 -> 0 | M26: =('Kwh Reading'!M27-'Kwh Reading'!M26)*1000 -> 0 | N26: =('Kwh Reading'!H27-'Kwh Reading'!H26)*1000 -> 0 | O26: =('Kwh Reading'!P27-'Kwh Reading'!P26)*1000 -> 0 | P26: =('Kwh Reading'!G27-'Kwh Reading'!G26)*1000 -> 0 | Q26: =('Kwh Reading'!Q27-'Kwh Reading'!Q26)*1000 -> 0 | R26: =('Kwh Reading'!N27-'Kwh Reading'!N26)*1000 -> 0 | S26: ='Kwh Reading'!E27-'Kwh Reading'!E26 -> 0 | T26: ='Kwh Reading'!D27-'Kwh Reading'!D26 -> 0 | U26: =('Kwh Reading'!O27-'Kwh Reading'!O26)*1000 -> 0 | V26: =B26-(SUM(C26:U26)) -> 0
A27: ='Kwh Reading'!A27 -> 44251 | B27: =TOTAL!E25 -> 0 | C27: =('Kwh Reading'!T28-'Kwh Reading'!T27)*1000 -> 0 | D27: =('Kwh Reading'!F28-'Kwh Reading'!F27)*1000000 -> 0 | E27: =('Kwh Reading'!C28-'Kwh Reading'!C27)*1000 -> 0 | F27: =('Kwh Reading'!J28-'Kwh Reading'!J27)*1000 -> 0 | G27: =('Kwh Reading'!K28-'Kwh Reading'!K27)*1000 -> 0 | H27: =('Kwh Reading'!L28-'Kwh Reading'!L27)*1000 -> 0 | I27: =('Kwh Reading'!R28-'Kwh Reading'!R27)*1000 -> 0 | J27: =('Kwh Reading'!S28-'Kwh Reading'!S27)*1000 -> 0 | K27: =('Kwh Reading'!I28-'Kwh Reading'!I27)*1000 -> 0 | L27: =('Kwh Reading'!B28-'Kwh Reading'!B27)*1000 -> 0 | M27: =('Kwh Reading'!M28-'Kwh Reading'!M27)*1000 -> 0 | N27: =('Kwh Reading'!H28-'Kwh Reading'!H27)*1000 -> 0 | O27: =('Kwh Reading'!P28-'Kwh Reading'!P27)*1000 -> 0 | P27: =('Kwh Reading'!G28-'Kwh Reading'!G27)*1000 -> 0 | Q27: =('Kwh Reading'!Q28-'Kwh Reading'!Q27)*1000 -> 0 | R27: =('Kwh Reading'!N28-'Kwh Reading'!N27)*1000 -> 0 | S27: 0 | T27: ='Kwh Reading'!D28-'Kwh Reading'!D27 -> 0 | U27: =('Kwh Reading'!O28-'Kwh Reading'!O27)*1000 -> 0 | V27: =B27-(SUM(C27:U27)) -> 0
A28: ='Kwh Reading'!A28 -> 44252 | B28: =TOTAL!E26 -> 0 | C28: =('Kwh Reading'!T29-'Kwh Reading'!T28)*1000 -> 0 | D28: =('Kwh Reading'!F29-'Kwh Reading'!F28)*1000000 -> 0 | E28: =('Kwh Reading'!C29-'Kwh Reading'!C28)*1000 -> 0 | F28: =('Kwh Reading'!J29-'Kwh Reading'!J28)*1000 -> 0 | G28: =('Kwh Reading'!K29-'Kwh Reading'!K28)*1000 -> 0 | H28: =('Kwh Reading'!L29-'Kwh Reading'!L28)*1000 -> 0 | I28: =('Kwh Reading'!R29-'Kwh Reading'!R28)*1000 -> 0 | J28: =('Kwh Reading'!S29-'Kwh Reading'!S28)*1000 -> 0 | K28: =('Kwh Reading'!I29-'Kwh Reading'!I28)*1000 -> 0 | L28: =('Kwh Reading'!B29-'Kwh Reading'!B28)*1000 -> 0 | M28: =('Kwh Reading'!M29-'Kwh Reading'!M28)*1000 -> 0 | N28: =('Kwh Reading'!H29-'Kwh Reading'!H28)*1000 -> 0 | O28: =('Kwh Reading'!P29-'Kwh Reading'!P28)*1000 -> 0 | P28: =('Kwh Reading'!G29-'Kwh Reading'!G28)*1000 -> 0 | Q28: =('Kwh Reading'!Q29-'Kwh Reading'!Q28)*1000 -> 0 | R28: =('Kwh Reading'!N29-'Kwh Reading'!N28)*1000 -> 0 | S28: ='Kwh Reading'!E29-'Kwh Reading'!E28 -> 0 | T28: ='Kwh Reading'!D29-'Kwh Reading'!D28 -> 0 | U28: =('Kwh Reading'!O29-'Kwh Reading'!O28)*1000 -> 0 | V28: =B28-(SUM(C28:U28)) -> 0
A29: ='Kwh Reading'!A29 -> 44253 | B29: =TOTAL!E27 -> 0 | C29: =('Kwh Reading'!T30-'Kwh Reading'!T29)*1000 -> 0 | D29: =('Kwh Reading'!F30-'Kwh Reading'!F29)*1000000 -> 0 | E29: =('Kwh Reading'!C30-'Kwh Reading'!C29)*1000 -> 0 | F29: =('Kwh Reading'!J30-'Kwh Reading'!J29)*1000 -> 0 | G29: =('Kwh Reading'!K30-'Kwh Reading'!K29)*1000 -> 0 | H29: =('Kwh Reading'!L30-'Kwh Reading'!L29)*1000 -> 0 | I29: =('Kwh Reading'!R30-'Kwh Reading'!R29)*1000 -> 0 | J29: =('Kwh Reading'!S30-'Kwh Reading'!S29)*1000 -> 0 | K29: =('Kwh Reading'!I30-'Kwh Reading'!I29)*1000 -> 0 | L29: =('Kwh Reading'!B30-'Kwh Reading'!B29)*1000 -> 0 | M29: =('Kwh Reading'!M30-'Kwh Reading'!M29)*1000 -> 0 | N29: =('Kwh Reading'!H30-'Kwh Reading'!H29)*1000 -> 0 | O29: =('Kwh Reading'!P30-'Kwh Reading'!P29)*1000 -> 0 | P29: =('Kwh Reading'!G30-'Kwh Reading'!G29)*1000 -> 0 | Q29: =('Kwh Reading'!Q30-'Kwh Reading'!Q29)*1000 -> 0 | R29: =('Kwh Reading'!N30-'Kwh Reading'!N29)*1000 -> 0 | S29: ='Kwh Reading'!E30-'Kwh Reading'!E29 -> 0 | T29: ='Kwh Reading'!D30-'Kwh Reading'!D29 -> 0 | U29: =('Kwh Reading'!O30-'Kwh Reading'!O29)*1000 -> 0 | V29: =B29-(SUM(C29:U29)) -> 0
A30: ='Kwh Reading'!A30 -> 44254 | B30: =TOTAL!E28 -> 0 | C30: =('Kwh Reading'!T31-'Kwh Reading'!T30)*1000 -> 0 | D30: =('Kwh Reading'!F31-'Kwh Reading'!F30)*1000000 -> 0 | E30: =('Kwh Reading'!C31-'Kwh Reading'!C30)*1000 -> 0 | F30: =('Kwh Reading'!J31-'Kwh Reading'!J30)*1000 -> 0 | G30: =('Kwh Reading'!K31-'Kwh Reading'!K30)*1000 -> 0 | H30: =('Kwh Reading'!L31-'Kwh Reading'!L30)*1000 -> 0 | I30: =('Kwh Reading'!R31-'Kwh Reading'!R30)*1000 -> 0 | J30: =('Kwh Reading'!S31-'Kwh Reading'!S30)*1000 -> 0 | K30: =('Kwh Reading'!I31-'Kwh Reading'!I30)*1000 -> 0 | L30: =('Kwh Reading'!B31-'Kwh Reading'!B30)*1000 -> 0 | M30: =('Kwh Reading'!M31-'Kwh Reading'!M30)*1000 -> 0 | N30: =('Kwh Reading'!H31-'Kwh Reading'!H30)*1000 -> 0 | O30: =('Kwh Reading'!P31-'Kwh Reading'!P30)*1000 -> 0 | P30: =('Kwh Reading'!G31-'Kwh Reading'!G30)*1000 -> 0 | Q30: =('Kwh Reading'!Q31-'Kwh Reading'!Q30)*1000 -> 0 | R30: =('Kwh Reading'!N31-'Kwh Reading'!N30)*1000 -> 0 | S30: ='Kwh Reading'!E31-'Kwh Reading'!E30 -> 0 | T30: ='Kwh Reading'!D31-'Kwh Reading'!D30 -> 0 | U30: =('Kwh Reading'!O31-'Kwh Reading'!O30)*1000 -> 0 | V30: =B30-(SUM(C30:U30)) -> 0
A31: ='Kwh Reading'!A31 -> 44255 | B31: =TOTAL!E29 -> 0 | C31: =('Kwh Reading'!T32-'Kwh Reading'!T31)*1000 -> 0 | D31: =('Kwh Reading'!F32-'Kwh Reading'!F31)*1000000 -> 0 | E31: =('Kwh Reading'!C32-'Kwh Reading'!C31)*1000 -> 0 | F31: =('Kwh Reading'!J32-'Kwh Reading'!J31)*1000 -> 0 | G31: =('Kwh Reading'!K32-'Kwh Reading'!K31)*1000 -> 0 | H31: =('Kwh Reading'!L32-'Kwh Reading'!L31)*1000 -> 0 | I31: =('Kwh Reading'!R32-'Kwh Reading'!R31)*1000 -> 0 | J31: =('Kwh Reading'!S32-'Kwh Reading'!S31)*1000 -> 0 | K31: =('Kwh Reading'!I32-'Kwh Reading'!I31)*1000 -> 0 | L31: =('Kwh Reading'!B32-'Kwh Reading'!B31)*1000 -> 0 | M31: =('Kwh Reading'!M32-'Kwh Reading'!M31)*1000 -> 0 | N31: =('Kwh Reading'!H32-'Kwh Reading'!H31)*1000 -> 0 | O31: =('Kwh Reading'!P32-'Kwh Reading'!P31)*1000 -> 0 | P31: =('Kwh Reading'!G32-'Kwh Reading'!G31)*1000 -> 0 | Q31: =('Kwh Reading'!Q32-'Kwh Reading'!Q31)*1000 -> 0 | R31: =('Kwh Reading'!N32-'Kwh Reading'!N31)*1000 -> 0 | S31: ='Kwh Reading'!E32-'Kwh Reading'!E31 -> 0 | T31: ='Kwh Reading'!D32-'Kwh Reading'!D31 -> 0 | U31: =('Kwh Reading'!O32-'Kwh Reading'!O31)*1000 -> 0 | V31: =B31-(SUM(C31:U31)) -> 0
A32: ='Kwh Reading'!A32 -> 0 | B32: =TOTAL!E30 -> 0 | C32: =('Kwh Reading'!T33-'Kwh Reading'!T32)*1000 -> 0 | D32: =('Kwh Reading'!F33-'Kwh Reading'!F32)*1000000 -> 0 | E32: =('Kwh Reading'!C33-'Kwh Reading'!C32)*1000 -> 0 | F32: =('Kwh Reading'!J33-'Kwh Reading'!J32)*1000 -> 0 | G32: =('Kwh Reading'!K33-'Kwh Reading'!K32)*1000 -> 0 | H32: =('Kwh Reading'!L33-'Kwh Reading'!L32)*1000 -> 0 | I32: =('Kwh Reading'!R33-'Kwh Reading'!R32)*1000 -> 0 | J32: =('Kwh Reading'!S33-'Kwh Reading'!S32)*1000 -> 0 | K32: =('Kwh Reading'!I33-'Kwh Reading'!I32)*1000 -> 0 | L32: =('Kwh Reading'!B33-'Kwh Reading'!B32)*1000 -> 0 | M32: =('Kwh Reading'!M33-'Kwh Reading'!M32)*1000 -> 0 | N32: =('Kwh Reading'!H33-'Kwh Reading'!H32)*1000 -> 0 | O32: =('Kwh Reading'!P33-'Kwh Reading'!P32)*1000 -> 0 | P32: =('Kwh Reading'!G33-'Kwh Reading'!G32)*1000 -> 0 | Q32: =('Kwh Reading'!Q33-'Kwh Reading'!Q32)*1000 -> 0 | R32: =('Kwh Reading'!N33-'Kwh Reading'!N32)*1000 -> 0 | S32: ='Kwh Reading'!E33-'Kwh Reading'!E32 -> 0 | T32: ='Kwh Reading'!D33-'Kwh Reading'!D32 -> 0 | U32: =('Kwh Reading'!O33-'Kwh Reading'!O32)*1000 -> 0 | V32: =B32-(SUM(C32:U32)) -> 0
A33: ='Kwh Reading'!A33 -> 0 | B33: =TOTAL!E31 -> 0 | C33: =('Kwh Reading'!T34-'Kwh Reading'!T33)*1000 -> 0 | D33: =('Kwh Reading'!F34-'Kwh Reading'!F33)*1000000 -> 0 | E33: =('Kwh Reading'!C34-'Kwh Reading'!C33)*1000 -> 0 | F33: =('Kwh Reading'!J34-'Kwh Reading'!J33)*1000 -> 0 | G33: =('Kwh Reading'!K34-'Kwh Reading'!K33)*1000 -> 0 | H33: =('Kwh Reading'!L34-'Kwh Reading'!L33)*1000 -> 0 | I33: =('Kwh Reading'!R34-'Kwh Reading'!R33)*1000 -> 0 | J33: =('Kwh Reading'!S34-'Kwh Reading'!S33)*1000 -> 0 | K33: =('Kwh Reading'!I34-'Kwh Reading'!I33)*1000 -> 0 | L33: =('Kwh Reading'!B34-'Kwh Reading'!B33)*1000 -> 0 | M33: =('Kwh Reading'!M34-'Kwh Reading'!M33)*1000 -> 0 | N33: =('Kwh Reading'!H34-'Kwh Reading'!H33)*1000 -> 0 | O33: =('Kwh Reading'!P34-'Kwh Reading'!P33)*1000 -> 0 | P33: =('Kwh Reading'!G34-'Kwh Reading'!G33)*1000 -> 0 | Q33: =('Kwh Reading'!Q34-'Kwh Reading'!Q33)*1000 -> 0 | R33: =('Kwh Reading'!N34-'Kwh Reading'!N33)*1000 -> 0 | S33: ='Kwh Reading'!E34-'Kwh Reading'!E33 -> 0 | T33: ='Kwh Reading'!D34-'Kwh Reading'!D33 -> 0 | U33: =('Kwh Reading'!O34-'Kwh Reading'!O33)*1000 -> 0 | V33: =B33-(SUM(C33:U33)) -> 0
A34: ='Kwh Reading'!A34 -> 0 | B34: =TOTAL!E32 -> 0 | C34: =('Kwh Reading'!T35-'Kwh Reading'!T34)*1000 -> 0 | D34: =('Kwh Reading'!F35-'Kwh Reading'!F34)*1000000 -> 0 | E34: =('Kwh Reading'!C35-'Kwh Reading'!C34)*1000 -> 0 | F34: =('Kwh Reading'!J35-'Kwh Reading'!J34)*1000 -> 0 | G34: =('Kwh Reading'!K35-'Kwh Reading'!K34)*1000 -> 0 | H34: =('Kwh Reading'!L35-'Kwh Reading'!L34)*1000 -> 0 | I34: =('Kwh Reading'!R35-'Kwh Reading'!R34)*1000 -> 0 | J34: =('Kwh Reading'!S35-'Kwh Reading'!S34)*1000 -> 0 | K34: =('Kwh Reading'!I35-'Kwh Reading'!I34)*1000 -> 0 | L34: =('Kwh Reading'!B35-'Kwh Reading'!B34)*1000 -> 0 | M34: =('Kwh Reading'!M35-'Kwh Reading'!M34)*1000 -> 0 | N34: =('Kwh Reading'!H35-'Kwh Reading'!H34)*1000 -> 0 | O34: =('Kwh Reading'!P35-'Kwh Reading'!P34)*1000 -> 0 | P34: =('Kwh Reading'!G35-'Kwh Reading'!G34)*1000 -> 0 | Q34: =('Kwh Reading'!Q35-'Kwh Reading'!Q34)*1000 -> 0 | R34: =('Kwh Reading'!N35-'Kwh Reading'!N34)*1000 -> 0 | S34: ='Kwh Reading'!E35-'Kwh Reading'!E34 -> 0 | T34: ='Kwh Reading'!D35-'Kwh Reading'!D34 -> 0 | U34: =('Kwh Reading'!O35-'Kwh Reading'!O34)*1000 -> 0 | V34: =B34-(SUM(C34:U34)) -> 0
A35: Total | B35: =SUM(B4:B34) -> 254430 | C35: =SUM(C4:C34) -> -350440 | D35: =SUM(D4:D34) -> -2013700 | E35: =SUM(E4:E34) -> -195330 | F35: =SUM(F4:F34) -> -282310 | G35: =SUM(G4:G34) -> -295320 | H35: =SUM(H4:H34) -> -202650 | I35: =SUM(I4:I34) -> -119310 | ... V35: =SUM(V4:V34) -> 22460821

Sheet Kwh area wise 
A2: Month | B2: Total KWH | C2: Reef Club Kitchen KWH | D2: Main Kitchen KWH | E2: Pastry Kitchen KWH | F2: Laundry KWH | G2: STP KWH | H2: Kuda Huraa Accomodation KWH | I2: Guest Room Beach Pavilion & Beach Bungalow KWH | J2: Guest Room Water Bungalow KWH | K2: Spa KWH | L2: Others KWH
A3: ='Kwh Reading'!A4 -> 44228 | B3: =TOTAL!E2 -> 20560 | C3: ='Kwh Consumption'!C4 -> 420 | D3: ='Kwh Consumption'!D4 -> 2400 | E3: ='Kwh Consumption'!E4 -> 260 | F3: =('Kwh Consumption'!F4+'Kwh Consumption'!G4+'Kwh Consumption'!H4) -> 810 | G3: =('Kwh Consumption'!I4+'Kwh Consumption'!J4) -> 303 | H3: =('Kwh Consumption'!K4+'Kwh Consumption'!L4) -> 1410 | I3: =('Kwh Consumption'!M4+'Kwh Consumption'!N4+'Kwh Consumption'!O4+'Kwh Consumption'!P4+'Kwh Consumption'!Q4+'Kwh Consumption'!R4) -> 4620 | J3: =('Kwh Consumption'!S4+'Kwh Consumption'!T4) -> 4965.4 | K3: ='Kwh Consumption'!U4 -> 200 | L3: =B3-C3-D3-E3-F3-G3-H3-I3-J3-K3 -> 5171.6
A4: ='Kwh Reading'!A5 -> 44229 | B4: =TOTAL!E3 -> 24530 | C4: ='Kwh Consumption'!C5 -> 560 | D4: ='Kwh Consumption'!D5 -> 2500 | E4: ='Kwh Consumption'!E5 -> 290 | F4: =('Kwh Consumption'!F5+'Kwh Consumption'!G5+'Kwh Consumption'!H5) -> 970 | G4: =('Kwh Consumption'!I5+'Kwh Consumption'!J5) -> 380 | H4: =('Kwh Consumption'!K5+'Kwh Consumption'!L5) -> 1520 | I4: =('Kwh Consumption'!M5+'Kwh Consumption'!N5+'Kwh Consumption'!O5+'Kwh Consumption'!P5+'Kwh Consumption'!Q5+'Kwh Consumption'!R5) -> 4970 | J4: =('Kwh Consumption'!S5+'Kwh Consumption'!T5) -> 5884.21 | K4: ='Kwh Consumption'!U5 -> 200 | L4: =B4-C4-D4-E4-F4-G4-H4-I4-J4-K4 -> 7255.79
A5: ='Kwh Reading'!A6 -> 44230 | B5: =TOTAL!E4 -> 21160 | C5: ='Kwh Consumption'!C6 -> 520 | D5: ='Kwh Consumption'!D6 -> 2400 | E5: ='Kwh Consumption'!E6 -> 240 | F5: =('Kwh Consumption'!F6+'Kwh Consumption'!G6+'Kwh Consumption'!H6) -> 840 | G5: =('Kwh Consumption'!I6+'Kwh Consumption'!J6) -> 289 | H5: =('Kwh Consumption'!K6+'Kwh Consumption'!L6) -> 1420 | I5: =('Kwh Consumption'!M6+'Kwh Consumption'!N6+'Kwh Consumption'!O6+'Kwh Consumption'!P6+'Kwh Consumption'!Q6+'Kwh Consumption'!R6) -> 4730 | J5: =('Kwh Consumption'!S6+'Kwh Consumption'!T6) -> 5182.28 | K5: ='Kwh Consumption'!U6 -> 200 | L5: =B5-C5-D5-E5-F5-G5-H5-I5-J5-K5 -> 5338.72
A6: ='Kwh Reading'!A7 -> 44231 | B6: =TOTAL!E5 -> 20480 | C6: ='Kwh Consumption'!C7 -> 480 | D6: ='Kwh Consumption'!D7 -> 2500 | E6: ='Kwh Consumption'!E7 -> 250 | F6: =('Kwh Consumption'!F7+'Kwh Consumption'!G7+'Kwh Consumption'!H7) -> 860 | G6: =('Kwh Consumption'!I7+'Kwh Consumption'!J7) -> 245 | H6: =('Kwh Consumption'!K7+'Kwh Consumption'!L7) -> 1440 | I6: =('Kwh Consumption'!M7+'Kwh Consumption'!N7+'Kwh Consumption'!O7+'Kwh Consumption'!P7+'Kwh Consumption'!Q7+'Kwh Consumption'!R7) -> 4860 | J6: =('Kwh Consumption'!S7+'Kwh Consumption'!T7) -> 5253.22 | K6: ='Kwh Consumption'!U7 -> 190 | L6: =B6-C6-D6-E6-F6-G6-H6-I6-J6-K6 -> 4401.78
A7: ='Kwh Reading'!A8 -> 44232 | B7: =TOTAL!E6 -> 20840 | C7: ='Kwh Consumption'!C8 -> 280 | D7: ='Kwh Consumption'!D8 -> 2500 | E7: ='Kwh Consumption'!E8 -> 250 | F7: =('Kwh Consumption'!F8+'Kwh Consumption'!G8+'Kwh Consumption'!H8) -> 830 | G7: =('Kwh Consumption'!I8+'Kwh Consumption'!J8) -> -7682 | H7: =('Kwh Consumption'!K8+'Kwh Consumption'!L8) -> 280 | I7: =('Kwh Consumption'!M8+'Kwh Consumption'!N8+'Kwh Consumption'!O8+'Kwh Consumption'!P8+'Kwh Consumption'!Q8+'Kwh Consumption'!R8) -> 4370 | J7: =('Kwh Consumption'!S8+'Kwh Consumption'!T8) -> 4357.27 | K7: ='Kwh Consumption'!U8 -> 210 | L7: =B7-C7-D7-E7-F7-G7-H7-I7-J7-K7 -> 15444.73
A8: ='Kwh Reading'!A9 -> 44233 | B8: =TOTAL!E7 -> 21680 | C8: ='Kwh Consumption'!C9 -> 520 | D8: ='Kwh Consumption'!D9 -> 2600 | E8: ='Kwh Consumption'!E9 -> 280 | F8: =('Kwh Consumption'!F9+'Kwh Consumption'!G9+'Kwh Consumption'!H9) -> 860 | G8: =('Kwh Consumption'!I9+'Kwh Consumption'!J9) -> 8352 | H8: =('Kwh Consumption'!K9+'Kwh Consumption'!L9) -> 2550 | I8: =('Kwh Consumption'!M9+'Kwh Consumption'!N9+'Kwh Consumption'!O9+'Kwh Consumption'!P9+'Kwh Consumption'!Q9+'Kwh Consumption'!R9) -> 4870 | J8: =('Kwh Consumption'!S9+'Kwh Consumption'!T9) -> 5322.81 | K8: ='Kwh Consumption'!U9 -> 210 | L8: =B8-C8-D8-E8-F8-G8-H8-I8-J8-K8 -> -3884.81
A9: ='Kwh Reading'!A10 -> 44234 | B9: =TOTAL!E8 -> 20130 | C9: ='Kwh Consumption'!C10 -> 510 | D9: ='Kwh Consumption'!D10 -> 2300 | E9: ='Kwh Consumption'!E10 -> 190 | F9: =('Kwh Consumption'!F10+'Kwh Consumption'!G10+'Kwh Consumption'!H10) -> 670 | G9: =('Kwh Consumption'!I10+'Kwh Consumption'!J10) -> 249 | H9: =('Kwh Consumption'!K10+'Kwh Consumption'!L10) -> 1300 | I9: =('Kwh Consumption'!M10+'Kwh Consumption'!N10+'Kwh Consumption'!O10+'Kwh Consumption'!P10+'Kwh Consumption'!Q10+'Kwh Consumption'!R10) -> 4300 | J9: =('Kwh Consumption'!S10+'Kwh Consumption'!T10) -> 4566.06 | K9: ='Kwh Consumption'!U10 -> 200 | L9: =B9-C9-D9-E9-F9-G9-H9-I9-J9-K9 -> 5844.94
A10: ='Kwh Reading'!A11 -> 44235 | B10: =TOTAL!E9 -> 21680 | C10: ='Kwh Consumption'!C11 -> 510 | D10: ='Kwh Consumption'!D11 -> 2100 | E10: ='Kwh Consumption'!E11 -> 250 | F10: =('Kwh Consumption'!F11+'Kwh Consumption'!G11+'Kwh Consumption'!H11) -> 870 | G10: =('Kwh Consumption'!I11+'Kwh Consumption'!J11) -> 338 | H10: =('Kwh Consumption'!K11+'Kwh Consumption'!L11) -> 1420 | I10: =('Kwh Consumption'!M11+'Kwh Consumption'!N11+'Kwh Consumption'!O11+'Kwh Consumption'!P11+'Kwh Consumption'!Q11+'Kwh Consumption'!R11) -> 4850 | J10: =('Kwh Consumption'!S11+'Kwh Consumption'!T11) -> 5323.4 | K10: ='Kwh Consumption'!U11 -> 200 | L10: =B10-C10-D10-E10-F10-G10-H10-I10-J10-K10 -> 5818.6
A11: ='Kwh Reading'!A12 -> 44236 | B11: =TOTAL!E10 -> 20390 | C11: ='Kwh Consumption'!C12 -> 500 | D11: ='Kwh Consumption'!D12 -> 2700 | E11: ='Kwh Consumption'!E12 -> 250 | F11: =('Kwh Consumption'!F12+'Kwh Consumption'!G12+'Kwh Consumption'!H12) -> 740 | G11: =('Kwh Consumption'!I12+'Kwh Consumption'!J12) -> 326 | H11: =('Kwh Consumption'!K12+'Kwh Consumption'!L12) -> 1390 | I11: =('Kwh Consumption'!M12+'Kwh Consumption'!N12+'Kwh Consumption'!O12+'Kwh Consumption'!P12+'Kwh Consumption'!Q12+'Kwh Consumption'!R12) -> 4730 | J11: =('Kwh Consumption'!S12+'Kwh Consumption'!T12) -> 4819.47 | K11: ='Kwh Consumption'!U12 -> 220 | L11: =B11-C11-D11-E11-F11-G11-H11-I11-J11-K11 -> 4714.53
A12: ='Kwh Reading'!A13 -> 44237 | B12: =TOTAL!E11 -> 21710 | C12: ='Kwh Consumption'!C13 -> 530 | D12: ='Kwh Consumption'!D13 -> 2500 | E12: ='Kwh Consumption'!E13 -> 240 | F12: =('Kwh Consumption'!F13+'Kwh Consumption'!G13+'Kwh Consumption'!H13) -> 890 | G12: =('Kwh Consumption'!I13+'Kwh Consumption'!J13) -> 240 | H12: =('Kwh Consumption'!K13+'Kwh Consumption'!L13) -> 1470 | I12: =('Kwh Consumption'!M13+'Kwh Consumption'!N13+'Kwh Consumption'!O13+'Kwh Consumption'!P13+'Kwh Consumption'!Q13+'Kwh Consumption'!R13) -> 4680 | J12: =('Kwh Consumption'!S13+'Kwh Consumption'!T13) -> 4741.35 | K12: ='Kwh Consumption'!U13 -> 200 | L12: =B12-C12-D12-E12-F12-G12-H12-I12-J12-K12 -> 6218.65
A13: ='Kwh Reading'!A14 -> 44238 | B13: =TOTAL!E12 -> 20670 | C13: ='Kwh Consumption'!C14 -> 480 | D13: ='Kwh Consumption'!D14 -> 2300 | E13: ='Kwh Consumption'!E14 -> 240 | F13: =('Kwh Consumption'!F14+'Kwh Consumption'!G14+'Kwh Consumption'!H14) -> 690 | G13: =('Kwh Consumption'!I14+'Kwh Consumption'!J14) -> 274 | H13: =('Kwh Consumption'!K14+'Kwh Consumption'!L14) -> 1340 | I13: =('Kwh Consumption'!M14+'Kwh Consumption'!N14+'Kwh Consumption'!O14+'Kwh Consumption'!P14+'Kwh Consumption'!Q14+'Kwh Consumption'!R14) -> 4290 | J13: =('Kwh Consumption'!S14+'Kwh Consumption'!T14) -> 4498.67 | K13: ='Kwh Consumption'!U14 -> 190 | L13: =B13-C13-D13-E13-F13-G13-H13-I13-J13-K13 -> 6367.33
A14: ='Kwh Reading'!A15 -> 44239 | B14: =TOTAL!E13 -> 20600 | C14: ='Kwh Consumption'!C15 -> 270 | D14: ='Kwh Consumption'!D15 -> 2500 | E14: ='Kwh Consumption'!E15 -> 230 | F14: =('Kwh Consumption'!F15+'Kwh Consumption'!G15+'Kwh Consumption'!H15) -> 740 | G14: =('Kwh Consumption'!I15+'Kwh Consumption'!J15) -> 365 | H14: =('Kwh Consumption'!K15+'Kwh Consumption'!L15) -> 320 | I14: =('Kwh Consumption'!M15+'Kwh Consumption'!N15+'Kwh Consumption'!O15+'Kwh Consumption'!P15+'Kwh Consumption'!Q15+'Kwh Consumption'!R15) -> 4490 | J14: =('Kwh Consumption'!S15+'Kwh Consumption'!T15) -> 4624.07 | K14: ='Kwh Consumption'!U15 -> 190 | L14: =B14-C14-D14-E14-F14-G14-H14-I14-J14-K14 -> 6870.93
... A33: ='Kwh Reading'!A34 -> 0 | B33: =TOTAL!E32 -> 0 | C33: ='Kwh Consumption'!C34 -> 0 | D33: ='Kwh Consumption'!D34 -> 0 | E33: ='Kwh Consumption'!E34 -> 0 | F33: =('Kwh Consumption'!F34+'Kwh Consumption'!G34+'Kwh Consumption'!H34) -> 0 | G33: =('Kwh Consumption'!I34+'Kwh Consumption'!J34) -> 0 | H33: =('Kwh Consumption'!K34+'Kwh Consumption'!L34) -> 0 | I33: =('Kwh Consumption'!M34+'Kwh Consumption'!N34+'Kwh Consumption'!O34+'Kwh Consumption'!P34+'Kwh Consumption'!Q34+'Kwh Consumption'!R34) -> 0 | J33: =('Kwh Consumption'!S34+'Kwh Consumption'!T34) -> 0 | K33: ='Kwh Consumption'!U34 -> 0 | L33: =B33-C33-D33-E33-F33-G33-H33-I33-J33-K33 -> 0
A34: Total kwh | B34: =SUM(B3:B33) -> 254430 | C34: =SUM(C3:C33) -> -350440 | D34: =SUM(D3:D33) -> -2013700 | E34: =SUM(E3:E33) -> -195330 | F34: =SUM(F3:F33) -> -780280 | G34: =SUM(G3:G33) -> -214806 | H34: =SUM(H3:H33) -> -979060 | I34: =SUM(I3:I33) -> -2700410 | ... L34: =SUM(L3:L33) -> 22460821 | M34: =C34+D34+E34+F34+G34+H34+I34+J34+K34+L34 -> 254430
A36: Total $ | B36: =TOTAL!F2 -> 0.14 | C36: =C34*B36 -> -49061.6 | D36: =D34*B36 -> -281918 | E36: =E34*B36 -> -27346.2 | F36: =F34*B36 -> -109239.2 | G36: =G34*B36 -> -30072.84 | H36: =H34*B36 -> -137068.4 | I36: =I34*B36 -> -378057.4 | J36: =J34*B36 -> -2080054.9 | K36: =K34*B36 -> -16076.2 | L36: =L34*B36 -> 3144514.9 | M36: =C36+D36+E36+F36+G36+H36+I36+J36+K36+L36 -> 35620.2

Sheet  Kwh area wise $ 
A2: Month | B2: $ /Per KWH | C2: Total $ | D2: Reef Club $ | E2: Kitchen $ | F2: Pastry $ | G2: Laundry $ | H2: STP $ | I2: Kuda Huraa Accomodation $ | J2: Guest Room Beach Pavilion & Beach Bungalow $ | K2: Guest Room Water Bungalow $ | L2: Spa $ | M2: Others $
A3: ='Kwh Reading'!A4 -> 44228 | B3: =TOTAL!F2 -> 0.14 | C3: ='Kwh Consumption'!B4*' Kwh area wise $ '!B3 -> 2878.4 | D3: ='Kwh Consumption'!C4*' Kwh area wise $ '!B3 -> 58.8 | E3: ='Kwh Consumption'!D4*' Kwh area wise $ '!B3 -> 336 | F3: ='Kwh Consumption'!E4*' Kwh area wise $ '!B3 -> 36.4 | G3: =('Kwh Consumption'!F4+'Kwh Consumption'!G4+'Kwh Consumption'!H4)*' Kwh area wise $ '!B3 -> 113.4 | H3: =('Kwh Consumption'!I4+'Kwh Consumption'!J4)*' Kwh area wise $ '!B3 -> 42.42 | I3: =('Kwh Consumption'!K4+'Kwh Consumption'!L4)*' Kwh area wise $ '!B3 -> 197.4 | J3: =('Kwh Consumption'!M4+'Kwh Consumption'!N4+'Kwh Consumption'!O4+'Kwh Consumption'!P4+'Kwh Consumption'!Q4+'Kwh Consumption'!R4)*' Kwh area wise $ '!B3 -> 646.8 | K3: =('Kwh Consumption'!S4+'Kwh Consumption'!T4)*' Kwh area wise $ '!B3 -> 695.156 | L3: ='Kwh Consumption'!U4*' Kwh area wise $ '!B3 -> 28 | M3: ='Kwh Consumption'!V4*' Kwh area wise $ '!B3 -> 724.024
A4: ='Kwh Reading'!A5 -> 44229 | B4: =TOTAL!F3 -> 0.14 | C4: ='Kwh Consumption'!B5*' Kwh area wise $ '!B4 -> 3434.2 | D4: ='Kwh Consumption'!C5*' Kwh area wise $ '!B4 -> 78.4 | E4: ='Kwh Consumption'!D5*' Kwh area wise $ '!B4 -> 350 | F4: ='Kwh Consumption'!E5*' Kwh area wise $ '!B4 -> 40.6 | G4: =('Kwh Consumption'!F5+'Kwh Consumption'!G5+'Kwh Consumption'!H5)*' Kwh area wise $ '!B4 -> 135.8 | H4: =('Kwh Consumption'!I5+'Kwh Consumption'!J5)*' Kwh area wise $ '!B4 -> 53.2 | I4: =('Kwh Consumption'!K5+'Kwh Consumption'!L5)*' Kwh area wise $ '!B4 -> 212.8 | J4: =('Kwh Consumption'!M5+'Kwh Consumption'!N5+'Kwh Consumption'!O5+'Kwh Consumption'!P5+'Kwh Consumption'!Q5+'Kwh Consumption'!R5)*' Kwh area wise $ '!B4 -> 695.8 | K4: =('Kwh Consumption'!S5+'Kwh Consumption'!T5)*' Kwh area wise $ '!B4 -> 823.7894 | L4: ='Kwh Consumption'!U5*' Kwh area wise $ '!B4 -> 28 | M4: ='Kwh Consumption'!V5*' Kwh area wise $ '!B4 -> 1015.8106
A5: ='Kwh Reading'!A6 -> 44230 | B5: =TOTAL!F4 -> 0.14 | C5: ='Kwh Consumption'!B6*' Kwh area wise $ '!B5 -> 2962.4 | D5: ='Kwh Consumption'!C6*' Kwh area wise $ '!B5 -> 72.8 | E5: ='Kwh Consumption'!D6*' Kwh area wise $ '!B5 -> 336 | F5: ='Kwh Consumption'!E6*' Kwh area wise $ '!B5 -> 33.6 | G5: =('Kwh Consumption'!F6+'Kwh Consumption'!G6+'Kwh Consumption'!H6)*' Kwh area wise $ '!B5 -> 117.6 | H5: =('Kwh Consumption'!I6+'Kwh Consumption'!J6)*' Kwh area wise $ '!B5 -> 40.46 | I5: =('Kwh Consumption'!K6+'Kwh Consumption'!L6)*' Kwh area wise $ '!B5 -> 198.8 | J5: =('Kwh Consumption'!M6+'Kwh Consumption'!N6+'Kwh Consumption'!O6+'Kwh Consumption'!P6+'Kwh Consumption'!Q6+'Kwh Consumption'!R6)*' Kwh area wise $ '!B5 -> 662.2 | K5: =('Kwh Consumption'!S6+'Kwh Consumption'!T6)*' Kwh area wise $ '!B5 -> 725.5192 | L5: ='Kwh Consumption'!U6*' Kwh area wise $ '!B5 -> 28 | M5: ='Kwh Consumption'!V6*' Kwh area wise $ '!B5 -> 747.4208
A6: ='Kwh Reading'!A7 -> 44231 | B6: =TOTAL!F5 -> 0.14 | C6: ='Kwh Consumption'!B7*' Kwh area wise $ '!B6 -> 2867.2 | D6: ='Kwh Consumption'!C7*' Kwh area wise $ '!B6 -> 67.2 | E6: ='Kwh Consumption'!D7*' Kwh area wise $ '!B6 -> 350 | F6: ='Kwh Consumption'!E7*' Kwh area wise $ '!B6 -> 35 | G6: =('Kwh Consumption'!F7+'Kwh Consumption'!G7+'Kwh Consumption'!H7)*' Kwh area wise $ '!B6 -> 120.4 | H6: =('Kwh Consumption'!I7+'Kwh Consumption'!J7)*' Kwh area wise $ '!B6 -> 34.3 | I6: =('Kwh Consumption'!K7+'Kwh Consumption'!L7)*' Kwh area wise $ '!B6 -> 201.6 | J6: =('Kwh Consumption'!M7+'Kwh Consumption'!N7+'Kwh Consumption'!O7+'Kwh Consumption'!P7+'Kwh Consumption'!Q7+'Kwh Consumption'!R7)*' Kwh area wise $ '!B6 -> 680.4 | K6: =('Kwh Consumption'!S7+'Kwh Consumption'!T7)*' Kwh area wise $ '!B6 -> 735.4508 | L6: ='Kwh Consumption'!U7*' Kwh area wise $ '!B6 -> 26.6 | M6: ='Kwh Consumption'!V7*' Kwh area wise $ '!B6 -> 616.2492
A7: ='Kwh Reading'!A8 -> 44232 | B7: =TOTAL!F6 -> 0.14 | C7: ='Kwh Consumption'!B8*' Kwh area wise $ '!B7 -> 2917.6 | D7: ='Kwh Consumption'!C8*' Kwh area wise $ '!B7 -> 39.2 | E7: ='Kwh Consumption'!D8*' Kwh area wise $ '!B7 -> 350 | F7: ='Kwh Consumption'!E8*' Kwh area wise $ '!B7 -> 35 | G7: =('Kwh Consumption'!F8+'Kwh Consumption'!G8+'Kwh Consumption'!H8)*' Kwh area wise $ '!B7 -> 116.2 | H7: =('Kwh Consumption'!I8+'Kwh Consumption'!J8)*' Kwh area wise $ '!B7 -> -1075.48 | I7: =('Kwh Consumption'!K8+'Kwh Consumption'!L8)*' Kwh area wise $ '!B7 -> 39.2 | J7: =('Kwh Consumption'!M8+'Kwh Consumption'!N8+'Kwh Consumption'!O8+'Kwh Consumption'!P8+'Kwh Consumption'!Q8+'Kwh Consumption'!R8)*' Kwh area wise $ '!B7 -> 611.8 | K7: =('Kwh Consumption'!S8+'Kwh Consumption'!T8)*' Kwh area wise $ '!B7 -> 610.0178 | L7: ='Kwh Consumption'!U8*' Kwh area wise $ '!B7 -> 29.4 | M7: ='Kwh Consumption'!V8*' Kwh area wise $ '!B7 -> 2162.2622
A8: ='Kwh Reading'!A9 -> 44233 | B8: =TOTAL!F7 -> 0.14 | C8: ='Kwh Consumption'!B9*' Kwh area wise $ '!B8 -> 3035.2 | D8: ='Kwh Consumption'!C9*' Kwh area wise $ '!B8 -> 72.8 | E8: ='Kwh Consumption'!D9*' Kwh area wise $ '!B8 -> 364 | F8: ='Kwh Consumption'!E9*' Kwh area wise $ '!B8 -> 39.2 | G8: =('Kwh Consumption'!F9+'Kwh Consumption'!G9+'Kwh Consumption'!H9)*' Kwh area wise $ '!B8 -> 120.4 | H8: =('Kwh Consumption'!I9+'Kwh Consumption'!J9)*' Kwh area wise $ '!B8 -> 1169.28 | I8: =('Kwh Consumption'!K9+'Kwh Consumption'!L9)*' Kwh area wise $ '!B8 -> 357 | J8: =('Kwh Consumption'!M9+'Kwh Consumption'!N9+'Kwh Consumption'!O9+'Kwh Consumption'!P9+'Kwh Consumption'!Q9+'Kwh Consumption'!R9)*' Kwh area wise $ '!B8 -> 681.8 | K8: =('Kwh Consumption'!S9+'Kwh Consumption'!T9)*' Kwh area wise $ '!B8 -> 745.1934 | L8: ='Kwh Consumption'!U9*' Kwh area wise $ '!B8 -> 29.4 | M8: ='Kwh Consumption'!V9*' Kwh area wise $ '!B8 -> -543.8734
A9: ='Kwh Reading'!A10 -> 44234 | B9: =TOTAL!F8 -> 0.14 | C9: ='Kwh Consumption'!B10*' Kwh area wise $ '!B9 -> 2818.2 | D9: ='Kwh Consumption'!C10*' Kwh area wise $ '!B9 -> 71.4 | E9: ='Kwh Consumption'!D10*' Kwh area wise $ '!B9 -> 322 | F9: ='Kwh Consumption'!E10*' Kwh area wise $ '!B9 -> 26.6 | G9: =('Kwh Consumption'!F10+'Kwh Consumption'!G10+'Kwh Consumption'!H10)*' Kwh area wise $ '!B9 -> 93.8 | H9: =('Kwh Consumption'!I10+'Kwh Consumption'!J10)*' Kwh area wise $ '!B9 -> 34.86 | I9: =('Kwh Consumption'!K10+'Kwh Consumption'!L10)*' Kwh area wise $ '!B9 -> 182 | J9: =('Kwh Consumption'!M10+'Kwh Consumption'!N10+'Kwh Consumption'!O10+'Kwh Consumption'!P10+'Kwh Consumption'!Q10+'Kwh Consumption'!R10)*' Kwh area wise $ '!B9 -> 602 | K9: =('Kwh Consumption'!S10+'Kwh Consumption'!T10)*' Kwh area wise $ '!B9 -> 639.2484 | L9: ='Kwh Consumption'!U10*' Kwh area wise $ '!B9 -> 28 | M9: ='Kwh Consumption'!V10*' Kwh area wise $ '!B9 -> 818.2916
A10: ='Kwh Reading'!A11 -> 44235 | B10: =TOTAL!F9 -> 0.14 | C10: ='Kwh Consumption'!B11*' Kwh area wise $ '!B10 -> 3035.2 | D10: ='Kwh Consumption'!C11*' Kwh area wise $ '!B10 -> 71.4 | E10: ='Kwh Consumption'!D11*' Kwh area wise $ '!B10 -> 294 | F10: ='Kwh Consumption'!E11*' Kwh area wise $ '!B10 -> 35 | G10: =('Kwh Consumption'!F11+'Kwh Consumption'!G11+'Kwh Consumption'!H11)*' Kwh area wise $ '!B10 -> 121.8 | H10: =('Kwh Consumption'!I11+'Kwh Consumption'!J11)*' Kwh area wise $ '!B10 -> 47.32 | I10: =('Kwh Consumption'!K11+'Kwh Consumption'!L11)*' Kwh area wise $ '!B10 -> 198.8 | J10: =('Kwh Consumption'!M11+'Kwh Consumption'!N11+'Kwh Consumption'!O11+'Kwh Consumption'!P11+'Kwh Consumption'!Q11+'Kwh Consumption'!R11)*' Kwh area wise $ '!B10 -> 679 | K10: =('Kwh Consumption'!S11+'Kwh Consumption'!T11)*' Kwh area wise $ '!B10 -> 745.276 | L10: ='Kwh Consumption'!U11*' Kwh area wise $ '!B10 -> 28 | M10: ='Kwh Consumption'!V11*' Kwh area wise $ '!B10 -> 814.604
A11: ='Kwh Reading'!A12 -> 44236 | B11: =TOTAL!F10 -> 0.14 | C11: ='Kwh Consumption'!B12*' Kwh area wise $ '!B11 -> 2854.6 | D11: ='Kwh Consumption'!C12*' Kwh area wise $ '!B11 -> 70 | E11: ='Kwh Consumption'!D12*' Kwh area wise $ '!B11 -> 378 | F11: ='Kwh Consumption'!E12*' Kwh area wise $ '!B11 -> 35 | G11: =('Kwh Consumption'!F12+'Kwh Consumption'!G12+'Kwh Consumption'!H12)*' Kwh area wise $ '!B11 -> 103.6 | H11: =('Kwh Consumption'!I12+'Kwh Consumption'!J12)*' Kwh area wise $ '!B11 -> 45.64 | I11: =('Kwh Consumption'!K12+'Kwh Consumption'!L12)*' Kwh area wise $ '!B11 -> 194.6 | J11: =('Kwh Consumption'!M12+'Kwh Consumption'!N12+'Kwh Consumption'!O12+'Kwh Consumption'!P12+'Kwh Consumption'!Q12+'Kwh Consumption'!R12)*' Kwh area wise $ '!B11 -> 662.2 | K11: =('Kwh Consumption'!S12+'Kwh Consumption'!T12)*' Kwh area wise $ '!B11 -> 674.7258 | L11: ='Kwh Consumption'!U12*' Kwh area wise $ '!B11 -> 30.8 | M11: ='Kwh Consumption'!V12*' Kwh area wise $ '!B11 -> 660.0342
A12: ='Kwh Reading'!A13 -> 44237 | B12: =TOTAL!F11 -> 0.14 | C12: ='Kwh Consumption'!B13*' Kwh area wise $ '!B12 -> 3039.4 | D12: ='Kwh Consumption'!C13*' Kwh area wise $ '!B12 -> 74.2 | E12: ='Kwh Consumption'!D13*' Kwh area wise $ '!B12 -> 350 | F12: ='Kwh Consumption'!E13*' Kwh area wise $ '!B12 -> 33.6 | G12: =('Kwh Consumption'!F13+'Kwh Consumption'!G13+'Kwh Consumption'!H13)*' Kwh area wise $ '!B12 -> 124.6 | H12: =('Kwh Consumption'!I13+'Kwh Consumption'!J13)*' Kwh area wise $ '!B12 -> 33.6 | I12: =('Kwh Consumption'!K13+'Kwh Consumption'!L13)*' Kwh area wise $ '!B12 -> 205.8 | J12: =('Kwh Consumption'!M13+'Kwh Consumption'!N13+'Kwh Consumption'!O13+'Kwh Consumption'!P13+'Kwh Consumption'!Q13+'Kwh Consumption'!R13)*' Kwh area wise $ '!B12 -> 655.2 | K12: =('Kwh Consumption'!S13+'Kwh Consumption'!T13)*' Kwh area wise $ '!B12 -> 663.789 | L12: ='Kwh Consumption'!U13*' Kwh area wise $ '!B12 -> 28 | M12: ='Kwh Consumption'!V13*' Kwh area wise $ '!B12 -> 870.611
A13: ='Kwh Reading'!A14 -> 44238 | B13: =TOTAL!F12 -> 0.14 | C13: ='Kwh Consumption'!B14*' Kwh area wise $ '!B13 -> 2893.8 | D13: ='Kwh Consumption'!C14*' Kwh area wise $ '!B13 -> 67.2 | E13: ='Kwh Consumption'!D14*' Kwh area wise $ '!B13 -> 322 | F13: ='Kwh Consumption'!E14*' Kwh area wise $ '!B13 -> 33.6 | G13: =('Kwh Consumption'!F14+'Kwh Consumption'!G14+'Kwh Consumption'!H14)*' Kwh area wise $ '!B13 -> 96.6 | H13: =('Kwh Consumption'!I14+'Kwh Consumption'!J14)*' Kwh area wise $ '!B13 -> 38.36 | I13: =('Kwh Consumption'!K14+'Kwh Consumption'!L14)*' Kwh area wise $ '!B13 -> 187.6 | J13: =('Kwh Consumption'!M14+'Kwh Consumption'!N14+'Kwh Consumption'!O14+'Kwh Consumption'!P14+'Kwh Consumption'!Q14+'Kwh Consumption'!R14)*' Kwh area wise $ '!B13 -> 600.6 | K13: =('Kwh Consumption'!S14+'Kwh Consumption'!T14)*' Kwh area wise $ '!B13 -> 629.8138 | L13: ='Kwh Consumption'!U14*' Kwh area wise $ '!B13 -> 26.6 | M13: ='Kwh Consumption'!V14*' Kwh area wise $ '!B13 -> 891.4262
A14: ='Kwh Reading'!A15 -> 44239 | B14: =TOTAL!F13 -> 0.14 | C14: ='Kwh Consumption'!B15*' Kwh area wise $ '!B14 -> 2884 | D14: ='Kwh Consumption'!C15*' Kwh area wise $ '!B14 -> 37.8 | E14: ='Kwh Consumption'!D15*' Kwh area wise $ '!B14 -> 350 | F14: ='Kwh Consumption'!E15*' Kwh area wise $ '!B14 -> 32.2 | G14: =('Kwh Consumption'!F15+'Kwh Consumption'!G15+'Kwh Consumption'!H15)*' Kwh area wise $ '!B14 -> 103.6 | H14: =('Kwh Consumption'!I15+'Kwh Consumption'!J15)*' Kwh area wise $ '!B14 -> 51.1 | I14: =('Kwh Consumption'!K15+'Kwh Consumption'!L15)*' Kwh area wise $ '!B14 -> 44.8 | J14: =('Kwh Consumption'!M15+'Kwh Consumption'!N15+'Kwh Consumption'!O15+'Kwh Consumption'!P15+'Kwh Consumption'!Q15+'Kwh Consumption'!R15)*' Kwh area wise $ '!B14 -> 628.6 | K14: =('Kwh Consumption'!S15+'Kwh Consumption'!T15)*' Kwh area wise $ '!B14 -> 647.3698 | L14: ='Kwh Consumption'!U15*' Kwh area wise $ '!B14 -> 26.6 | M14: ='Kwh Consumption'!V15*' Kwh area wise $ '!B14 -> 961.9302
... A33: ='Kwh Reading'!A34 -> 0 | B33: =TOTAL!F32 -> 0.14 | C33: ='Kwh Consumption'!B34*' Kwh area wise $ '!B33 -> 0 | D33: ='Kwh Consumption'!C34*' Kwh area wise $ '!B33 -> 0 | E33: ='Kwh Consumption'!D34*' Kwh area wise $ '!B33 -> 0 | F33: ='Kwh Consumption'!E34*' Kwh area wise $ '!B33 -> 0 | G33: =('Kwh Consumption'!F34+'Kwh Consumption'!G34+'Kwh Consumption'!H34)*' Kwh area wise $ '!B33 -> 0 | H33: =('Kwh Consumption'!I34+'Kwh Consumption'!J34)*' Kwh area wise $ '!B33 -> 0 | I33: =('Kwh Consumption'!K34+'Kwh Consumption'!L34)*' Kwh area wise $ '!B33 -> 0 | J33: =('Kwh Consumption'!M34+'Kwh Consumption'!N34+'Kwh Consumption'!O34+'Kwh Consumption'!P34+'Kwh Consumption'!Q34+'Kwh Consumption'!R34)*' Kwh area wise $ '!B33 -> 0 | K33: =('Kwh Consumption'!S34+'Kwh Consumption'!T34)*' Kwh area wise $ '!B33 -> 0 | L33: ='Kwh Consumption'!U34*' Kwh area wise $ '!B33 -> 0 | M33: ='Kwh Consumption'!V34*' Kwh area wise $ '!B33 -> 0
A34: Total | C34: =SUM(C3:C33) -> 35620.2 | D34: =SUM(D3:D33) -> -49061.6 | E34: =SUM(E3:E33) -> -281918 | F34: =SUM(F3:F33) -> -27346.2 | G34: =SUM(G3:G33) -> -109239.2 | H34: =SUM(H3:H33) -> -30072.84 | I34: =SUM(I3:I33) -> -137068.4 | J34: =SUM(J3:J33) -> -378057.4 | ... M34: =SUM(M3:M33) -> 3144514.9 | N34: =D34+E34+F34+G34+H34+I34+J34+K34+L34+M34 -> 35620.2

Sheet Water Reading
B1: Meter 1 | C1: Meter 2 | D1: Meter 6 | E1: Meter 8 | F1: Meter 7 | G1: Meter 9 | H1: Meter 3 | I1: Meter 5 | J1: Meter 10 | K1: Meter 13 | L1: Meter 16 | M1: Meter 17 | N1: Meter 15 | O1: Meter 14 | P1: Meter 4 | Q1: Meter 11 | R1: Meter 12
A2: Date | B2: Main Meter 1 | C2: Main Meter 2 | D2: Beach Bunglow | E2: Kuda Huraa staff | F2: Bodu hura staff | G2: Laundry | H2: Water Bunglow | I2: Main Kitchen | J2: Second stage | K2: Supply jetty | L2: Staff housing A | M2: Staff housing B | N2: Spa | O2: Staff jetty | P2: Main pool | Q2: Reef club pool | R2: Reef club kitchen
A3: 44228 | B3: 142036 | C3: 98010 | D3: 187883 | E3: 238934 | F3: 66842 | G3: 108776 | H3: 45508 | I3: 57588 | J3: 18332 | K3: 1024 | L3: 16228 | M3: 22024 | N3: 6669 | O3: 1544 | P3: 25830 | Q3: 61 | R3: 5466
A4: 44229 | B4: 142215 | C4: 98165 | D4: 188057 | E4: 238991 | F4: 66843 | G4: 108797 | H4: 45543 | I4: 57601 | J4: 18343 | K4: 1024 | L4: 16235 | M4: 22038 | N4: 6671 | O4: 1545 | P4: 25830 | Q4: 61 | R4: 5468
A5: 44230 | B5: 142337 | C5: 98346 | D5: 188224 | E5: 239056 | F5: 66843 | G5: 108821 | H5: 45581 | I5: 57614 | J5: 18354 | K5: 1024 | L5: 16242 | M5: 22052 | N5: 6673 | O5: 1546 | P5: 25830 | Q5: 68 | R5: 5476
A6: 44231 | B6: 142448 | C6: 98512 | D6: 188332 | E6: 239110 | F6: 66843 | G6: 108840 | H6: 45603 | I6: 57630 | J6: 18365 | K6: 1024 | L6: 16248 | M6: 22067 | N6: 6675 | O6: 1546 | P6: 25830 | Q6: 68 | R6: 5484
