Workbook

Sheet TOTAL
A1: Site Name | B1: Day | C1: Month | D1: Year | E1: Total Electricity Kwh | F1: Electricity Tariff ($/Kwh) | G1: LPG (Kg) | H1: LPG $/Kg | I1: Water Utility Supply (m3) m3 | J1: Water Utility Supply (m3) $/m3 | K1: Room Nights | L1: Food Covers
A2: Maldives at Landaa Giraavaru | B2: 1 | C2: 2 | D2: 2021 | E2: ='Maldives at LG Daily'!D5 -> 27179 | F2: 0.93 | G2: ='Maldives at LG Daily'!F5 -> 225 | H2: 1.24 | I2: ='Maldives at LG Daily'!H5 -> 357 | J2: 1.72 | K2: ='Maldives at LG Daily'!I5 -> 52 | L2: ='Maldives at LG Daily'!J5 -> 410
A3: Maldives at Landaa Giraavaru | B3: =B2+1 -> 2 | C3: 2 | D3: 2021 | E3: ='Maldives at LG Daily'!D6 -> 27052 | F3: 0.93 | G3: ='Maldives at LG Daily'!F6 -> 0 | H3: 1.24 | I3: ='Maldives at LG Daily'!H6 -> 274 | J3: 1.72 | K3: ='Maldives at LG Daily'!I6 -> 55 | L3: ='Maldives at LG Daily'!J6 -> 391
A4: Maldives at Landaa Giraavaru | B4: =B3+1 -> 3 | C4: 2 | D4: 2021 | E4: ='Maldives at LG Daily'!D7 -> 27844 | F4: 0.93 | G4: ='Maldives at LG Daily'!F7 -> 315 | H4: 1.24 | I4: ='Maldives at LG Daily'!H7 -> 327 | J4: 1.72 | K4: ='Maldives at LG Daily'!I7 -> 59 | L4: ='Maldives at LG Daily'!J7 -> 316
A5: Maldives at Landaa Giraavaru | B5: =B4+1 -> 4 | C5: 2 | D5: 2021 | E5: ='Maldives at LG Daily'!D8 -> 28535 | F5: 0.93 | G5: ='Maldives at LG Daily'!F8 -> 0 | H5: 1.24 | I5: ='Maldives at LG Daily'!H8 -> 374 | J5: 1.72 | K5: ='Maldives at LG Daily'!I8 -> 59 | L5: ='Maldives at LG Daily'!J8 -> 484
A6: Maldives at Landaa Giraavaru | B6: =B5+1 -> 5 | C6: 2 | D6: 2021 | E6: ='Maldives at LG Daily'!D9 -> 27066 | F6: 0.93 | G6: ='Maldives at LG Daily'!F9 -> 225 | H6: 1.24 | I6: ='Maldives at LG Daily'!H9 -> 325 | J6: 1.72 | K6: ='Maldives at LG Daily'!I9 -> 59 | L6: ='Maldives at LG Daily'!J9 -> 460
A7: Maldives at Landaa Giraavaru | B7: =B6+1 -> 6 | C7: 2 | D7: 2021 | E7: ='Maldives at LG Daily'!D10 -> 27114 | F7: 0.93 | G7: ='Maldives at LG Daily'!F10 -> 0 | H7: 1.24 | I7: ='Maldives at LG Daily'!H10 -> 392 | J7: 1.72 | K7: ='Maldives at LG Daily'!I10 -> 59 | L7: ='Maldives at LG Daily'!J10 -> 469
A8: Maldives at Landaa Giraavaru | B8: =B7+1 -> 7 | C8: 2 | D8: 2021 | E8: ='Maldives at LG Daily'!D11 -> 27684 | F8: 0.93 | G8: ='Maldives at LG Daily'!F11 -> 180 | H8: 1.24 | I8: ='Maldives at LG Daily'!H11 -> 336 | J8: 1.72 | K8: ='Maldives at LG Daily'!I11 -> 57 | L8: ='Maldives at LG Daily'!J11 -> 416
A9: Maldives at Landaa Giraavaru | B9: =B8+1 -> 8 | C9: 2 | D9: 2021 | E9: ='Maldives at LG Daily'!D12 -> 28636 | F9: 0.93 | G9: ='Maldives at LG Daily'!F12 -> 45 | H9: 1.24 | I9: ='Maldives at LG Daily'!H12 -> 363 | J9: 1.72 | K9: ='Maldives at LG Daily'!I12 -> 63 | L9: ='Maldives at LG Daily'!J12 -> 484
A10: Maldives at Landaa Giraavaru | B10: =B9+1 -> 9 | C10: 2 | D10: 2021 | E10: ='Maldives at LG Daily'!D13 -> 27903 | F10: 0.93 | G10: ='Maldives at LG Daily'!F13 -> 0 | H10: 1.24 | I10: ='Maldives at LG Daily'!H13 -> 361 | J10: 1.72 | K10: ='Maldives at LG Daily'!I13 -> 56 | L10: ='Maldives at LG Daily'!J13 -> 445
A11: Maldives at Landaa Giraavaru | B11: =B10+1 -> 10 | C11: 2 | D11: 2021 | E11: ='Maldives at LG Daily'!D14 -> 27665 | F11: 0.93 | G11: ='Maldives at LG Daily'!F14 -> 270 | H11: 1.24 | I11: ='Maldives at LG Daily'!H14 -> 370 | J11: 1.72 | K11: ='Maldives at LG Daily'!I14 -> 57 | L11: ='Maldives at LG Daily'!J14 -> 506
A12: Maldives at Landaa Giraavaru | B12: =B11+1 -> 11 | C12: 2 | D12: 2021 | E12: ='Maldives at LG Daily'!D15 -> 26582 | F12: 0.93 | G12: ='Maldives at LG Daily'!F15 -> 0 | H12: 1.24 | I12: ='Maldives at LG Daily'!H15 -> 372 | J12: 1.72 | K12: ='Maldives at LG Daily'!I15 -> 70 | L12: ='Maldives at LG Daily'!J15 -> 558
A13: Maldives at Landaa Giraavaru | B13: =B12+1 -> 12 | C13: 2 | D13: 2021 | E13: ='Maldives at LG Daily'!D16 -> 27100 | F13: 0.93 | G13: ='Maldives at LG Daily'!F16 -> 270 | H13: 1.24 | I13: ='Maldives at LG Daily'!H16 -> 361 | J13: 1.72 | K13: ='Maldives at LG Daily'!I16 -> 75 | L13: ='Maldives at LG Daily'!J16 -> 649
A14: Maldives at Landaa Giraavaru | B14: =B13+1 -> 13 | C14: 2 | D14: 2021 | E14: ='Maldives at LG Daily'!D17 -> 27484 | F14: 0.93 | G14: ='Maldives at LG Daily'!F17 -> 0 | H14: 1.24 | I14: ='Maldives at LG Daily'!H17 -> 396 | J14: 1.72 | K14: ='Maldives at LG Daily'!I17 -> 71 | L14: ='Maldives at LG Daily'!J17 -> 629
... A29: Maldives at Landaa Giraavaru | B29: =B28+1 -> 28 | C29: 2 | D29: 2021 | E29: ='Maldives at LG Daily'!D32 -> 0 | F29: 0.93 | G29: ='Maldives at LG Daily'!F32 -> 0 | H29: 1.24 | I29: ='Maldives at LG Daily'!H32 -> 0 | J29: 1.72 | K29: ='Maldives at LG Daily'!I32 -> 0 | L29: ='Maldives at LG Daily'!J32 -> 0

Sheet Maldives at LG Daily
A2: Days | C2: Electricity Meter (KWh) | E2: Gas Kg | G2: Water m3
A3: Date | C3: Reading KWH | D3: Difference KWH | E3: Reading Kg | F3: Difference Kg | G3: Reading m³ | H3: Daily Consumption m³ | I3: ROOM NIGHTS | J3: TOTAL GUESTS
A4: 44227 | C4: =SUM('GENSET #1'!B10+'GENSET #2'!B10+'GENSET #3'!B10+'GENSET #4'!B10+'GENSET #5'!B10) -> 86935793 | E4: ='Gas-2'!G5 -> 180 | G4: =SUM(WATER!G6,WATER!L6,WATER!Q6,WATER!B6) -> 912639
A5: 44228 | C5: =SUM('GENSET #1'!B11+'GENSET #2'!B11+'GENSET #3'!B11+'GENSET #4'!B11+'GENSET #5'!B11) -> 86962972 | D5: =IF((C5-C4<0), "0",C5-C4) -> 27179 | E5: ='Gas-2'!G6 -> 405 | F5: =IF((E5-E4<0), "0",E5-E4) -> 225 | G5: =SUM(WATER!C6,WATER!H6,WATER!M6,WATER!R6) -> 912996 | H5: =IF((G5-G4<0), "0",G5-G4) -> 357 | I5: 52 | J5: 410
A6: 44229 | C6: =SUM('GENSET #1'!B12+'GENSET #2'!B12+'GENSET #3'!B12+'GENSET #4'!B12+'GENSET #5'!B12) -> 86990024 | D6: =IF((C6-C5<0), "0",C6-C5) -> 27052 | E6: ='Gas-2'!G7 -> 90 | F6: =IF((E6-E5<0), "0",E6-E5) -> 0 | G6: =SUM(WATER!C7,WATER!H7,WATER!M7,WATER!R7) -> 913270 | H6: =IF((G6-G5<0), "0",G6-G5) -> 274 | I6: 55 | J6: 391
A7: 44230 | C7: =SUM('GENSET #1'!B13+'GENSET #2'!B13+'GENSET #3'!B13+'GENSET #4'!B13+'GENSET #5'!B13) -> 87017868 | D7: =IF((C7-C6<0), "0",C7-C6) -> 27844 | E7: ='Gas-2'!G8 -> 405 | F7: =IF((E7-E6<0), "0",E7-E6) -> 315 | G7: =SUM(WATER!C8,WATER!H8,WATER!M8,WATER!R8) -> 913597 | H7: =IF((G7-G6<0), "0",G7-G6) -> 327 | I7: 59 | J7: 316
A8: 44231 | C8: =SUM('GENSET #1'!B14+'GENSET #2'!B14+'GENSET #3'!B14+'GENSET #4'!B14+'GENSET #5'!B14) -> 87046403 | D8: =IF((C8-C7<0), "0",C8-C7) -> 28535 | E8: ='Gas-2'!G9 -> 180 | F8: =IF((E8-E7<0), "0",E8-E7) -> 0 | G8: =SUM(WATER!C9,WATER!H9,WATER!M9,WATER!R9) -> 913971 | H8: =IF((G8-G7<0), "0",G8-G7) -> 374 | I8: 59 | J8: 484
A9: 44232 | C9: =SUM('GENSET #1'!B15+'GENSET #2'!B15+'GENSET #3'!B15+'GENSET #4'!B15+'GENSET #5'!B15) -> 87073469 | D9: =IF((C9-C8<0), "0",C9-C8) -> 27066 | E9: ='Gas-2'!G10 -> 405 | F9: =IF((E9-E8<0), "0",E9-E8) -> 225 | G9: =SUM(WATER!C10,WATER!H10,WATER!M10,WATER!R10) -> 914296 | H9: =IF((G9-G8<0), "0",G9-G8) -> 325 | I9: 59 | J9: 460
A10: 44233 | C10: =SUM('GENSET #1'!B16+'GENSET #2'!B16+'GENSET #3'!B16+'GENSET #4'!B16+'GENSET #5'!B16) -> 87100583 | D10: =IF((C10-C9<0), "0",C10-C9) -> 27114 | E10: ='Gas-2'!G11 -> 90 | F10: =IF((E10-E9<0), "0",E10-E9) -> 0 | G10: =SUM(WATER!C11,WATER!H11,WATER!M11,WATER!R11) -> 914688 | H10: =IF((G10-G9<0), "0",G10-G9) -> 392 | I10: 59 | J10: 469
A11: 44234 | C11: =SUM('GENSET #1'!B17+'GENSET #2'!B17+'GENSET #3'!B17+'GENSET #4'!B17+'GENSET #5'!B17) -> 87128267 | D11: =IF((C11-C10<0), "0",C11-C10) -> 27684 | E11: ='Gas-2'!G12 -> 270 | F11: =IF((E11-E10<0), "0",E11-E10) -> 180 | G11: =SUM(WATER!C12,WATER!H12,WATER!M12,WATER!R12) -> 915024 | H11: =IF((G11-G10<0), "0",G11-G10) -> 336 | I11: 57 | J11: 416
A12: 44235 | C12: =SUM('GENSET #1'!B18+'GENSET #2'!B18+'GENSET #3'!B18+'GENSET #4'!B18+'GENSET #5'!B18) -> 87156903 | D12: =IF((C12-C11<0), "0",C12-C11) -> 28636 | E12: ='Gas-2'!G13 -> 315 | F12: =IF((E12-E11<0), "0",E12-E11) -> 45 | G12: =SUM(WATER!C13,WATER!H13,WATER!M13,WATER!R13) -> 915387 | H12: =IF((G12-G11<0), "0",G12-G11) -> 363 | I12: 63 | J12: 484
A13: 44236 | C13: =SUM('GENSET #1'!B19+'GENSET #2'!B19+'GENSET #3'!B19+'GENSET #4'!B19+'GENSET #5'!B19) -> 87184806 | D13: =IF((C13-C12<0), "0",C13-C12) -> 27903 | E13: ='Gas-2'!G14 -> 135 | F13: =IF((E13-E12<0), "0",E13-E12) -> 0 | G13: =SUM(WATER!C14,WATER!H14,WATER!M14,WATER!R14) -> 915748 | H13: =IF((G13-G12<0), "0",G13-G12) -> 361 | I13: 56 | J13: 445
A14: 44237 | C14: =SUM('GENSET #1'!B20+'GENSET #2'!B20+'GENSET #3'!B20+'GENSET #4'!B20+'GENSET #5'!B20) -> 87212471 | D14: =IF((C14-C13<0), "0",C14-C13) -> 27665 | E14: ='Gas-2'!G15 -> 405 | F14: =IF((E14-E13<0), "0",E14-E13) -> 270 | G14: =SUM(WATER!C15,WATER!H15,WATER!M15,WATER!R15) -> 916118 | H14: =IF((G14-G13<0), "0",G14-G13) -> 370 | I14: 57 | J14: 506
A15: 44238 | C15: =SUM('GENSET #1'!B21+'GENSET #2'!B21+'GENSET #3'!B21+'GENSET #4'!B21+'GENSET #5'!B21) -> 87239053 | D15: =IF((C15-C14<0), "0",C15-C14) -> 26582 | E15: ='Gas-2'!G16 -> 180 | F15: =IF((E15-E14<0), "0",E15-E14) -> 0 | G15: =SUM(WATER!C16,WATER!H16,WATER!M16,WATER!R16) -> 916490 | H15: =IF((G15-G14<0), "0",G15-G14) -> 372 | I15: 70 | J15: 558
A16: 44239 | C16: =SUM('GENSET #1'!B22+'GENSET #2'!B22+'GENSET #3'!B22+'GENSET #4'!B22+'GENSET #5'!B22) -> 87266153 | D16: =IF((C16-C15<0), "0",C16-C15) -> 27100 | E16: ='Gas-2'!G17 -> 450 | F16: =IF((E16-E15<0), "0",E16-E15) -> 270 | G16: =SUM(WATER!C17,WATER!H17,WATER!M17,WATER!R17) -> 916851 | H16: =IF((G16-G15<0), "0",G16-G15) -> 361 | I16: 75 | J16: 649
... A23: 44246 | C23: =SUM('GENSET #1'!B29+'GENSET #2'!B29+'GENSET #3'!B29+'GENSET #4'!B29+'GENSET #5'!B29) -> 87471433 | D23: =IF((C23-C22<0), "0",C23-C22) -> 30969 | E23: ='Gas-2'!G24 -> 315 | F23: =IF((E23-E22<0), "0",E23-E22) -> 270 | G23: =SUM(WATER!C24,WATER!H24,WATER!M24,WATER!R24) -> 919782 | H23: =IF((G23-G22<0), "0",G23-G22) -> 405 | I23: 80.6 | J23: 703
A24: 44247 | C24: =SUM('GENSET #1'!B30+'GENSET #2'!B30+'GENSET #3'!B30+'GENSET #4'!B30+'GENSET #5'!B30) -> 87501837 | D24: =IF((C24-C23<0), "0",C24-C23) -> 30404 | E24: ='Gas-2'!G25 -> 225 | F24: =IF((E24-E23<0), "0",E24-E23) -> 0 | G24: =SUM(WATER!C25,WATER!H25,WATER!M25,WATER!R25) -> 920228 | H24: =IF((G24-G23<0), "0",G24-G23) -> 446
A25: 44248 | C25: =SUM('GENSET #1'!B31+'GENSET #2'!B31+'GENSET #3'!B31+'GENSET #4'!B31+'GENSET #5'!B31) -> 0 | D25: =IF((C25-C24<0), "0",C25-C24) -> 0 | E25: ='Gas-2'!G26 -> 0 | F25: =IF((E25-E24<0), "0",E25-E24) -> 0 | G25: =SUM(WATER!C26,WATER!H26,WATER!M26,WATER!R26) -> 920592 | H25: =IF((G25-G24<0), "0",G25-G24) -> 364
A26: 44249 | C26: =SUM('GENSET #1'!B32+'GENSET #2'!B32+'GENSET #3'!B32+'GENSET #4'!B32+'GENSET #5'!B32) -> 0 | D26: =IF((C26-C25<0), "0",C26-C25) -> 0 | E26: ='Gas-2'!G27 -> 0 | F26: =IF((E26-E25<0), "0",E26-E25) -> 0 | G26: =SUM(WATER!C27,WATER!H27,WATER!M27,WATER!R27) -> 0 | H26: =IF((G26-G25<0), "0",G26-G25) -> 0
A27: 44250 | C27: =SUM('GENSET #1'!B33+'GENSET #2'!B33+'GENSET #3'!B33+'GENSET #4'!B33+'GENSET #5'!B33) -> 0 | D27: =IF((C27-C26<0), "0",C27-C26) -> 0 | E27: ='Gas-2'!G28 -> 0 | F27: =IF((E27-E26<0), "0",E27-E26) -> 0 | G27: =SUM(WATER!C28,WATER!H28,WATER!M28,WATER!R28) -> 0 | H27: =IF((G27-G26<0), "0",G27-G26) -> 0
A28: 44251 | C28: =SUM('GENSET #1'!B34+'GENSET #2'!B34+'GENSET #3'!B34+'GENSET #4'!B34+'GENSET #5'!B34) -> 0 | D28: =IF((C28-C27<0), "0",C28-C27) -> 0 | E28: ='Gas-2'!G29 -> 0 | F28: =IF((E28-E27<0), "0",E28-E27) -> 0 | G28: =SUM(WATER!C29,WATER!H29,WATER!M29,WATER!R29) -> 0 | H28: =IF((G28-G27<0), "0",G28-G27) -> 0
A29: 44252 | C29: =SUM('GENSET #1'!B35+'GENSET #2'!B35+'GENSET #3'!B35+'GENSET #4'!B35+'GENSET #5'!B35) -> 0 | D29: =IF((C29-C28<0), "0",C29-C28) -> 0 | E29: ='Gas-2'!G30 -> 0 | F29: =IF((E29-E28<0), "0",E29-E28) -> 0 | G29: =SUM(WATER!C30,WATER!H30,WATER!M30,WATER!R30) -> 0 | H29: =IF((G29-G28<0), "0",G29-G28) -> 0
A30: 44253 | C30: =SUM('GENSET #1'!B36+'GENSET #2'!B36+'GENSET #3'!B36+'GENSET #4'!B36+'GENSET #5'!B36) -> 0 | D30: =IF((C30-C29<0), "0",C30-C29) -> 0 | E30: ='Gas-2'!G31 -> 0 | F30: =IF((E30-E29<0), "0",E30-E29) -> 0 | G30: =SUM(WATER!C31,WATER!H31,WATER!M31,WATER!R31) -> 0 | H30: =IF((G30-G29<0), "0",G30-G29) -> 0
A31: 44254 | C31: =SUM('GENSET #1'!B37+'GENSET #2'!B37+'GENSET #3'!B37+'GENSET #4'!B37+'GENSET #5'!B37) -> 0 | D31: =IF((C31-C30<0), "0",C31-C30) -> 0 | E31: ='Gas-2'!G32 -> 0 | F31: =IF((E31-E30<0), "0",E31-E30) -> 0 | G31: =SUM(WATER!C32,WATER!H32,WATER!M32,WATER!R32) -> 0 | H31: =IF((G31-G30<0), "0",G31-G30) -> 0
A32: 44255 | C32: =SUM('GENSET #1'!B38+'GENSET #2'!B38+'GENSET #3'!B38+'GENSET #4'!B38+'GENSET #5'!B38) -> 0 | D32: =IF((C32-C31<0), "0",C32-C31) -> 0 | E32: ='Gas-2'!G33 -> 0 | F32: =IF((E32-E31<0), "0",E32-E31) -> 0 | G32: =SUM(WATER!C33,WATER!H33,WATER!M33,WATER!R33) -> 0 | H32: =IF((G32-G31<0), "0",G32-G31) -> 0
C33: =SUM('GENSET #1'!B39+'GENSET #2'!B39+'GENSET #3'!B39+'GENSET #4'!B39+'GENSET #5'!B39) -> 0 | D33: =IF((C33-C32<0), "0",C33-C32) -> 0 | E33: ='Gas-2'!G34 -> 0 | F33: =IF((E33-E32<0), "0",E33-E32) -> 0 | G33: =SUM(WATER!C34,WATER!H34,WATER!M34,WATER!R34) -> 0 | H33: =IF((G33-G32<0), "0",G33-G32) -> 0
C34: =SUM('GENSET #1'!B40+'GENSET #2'!B40+'GENSET #3'!B40+'GENSET #4'!B40+'GENSET #5'!B40) -> 0 | D34: =IF((C34-C33<0), "0",C34-C33) -> 0 | E34: ='Gas-2'!G35 -> 0 | F34: =IF((E34-E33<0), "0",E34-E33) -> 0 | G34: =SUM(WATER!C35,WATER!H35,WATER!M35,WATER!R35) -> 0 | H34: =IF((G34-G33<0), "0",G34-G33) -> 0
C35: =SUM('GENSET #1'!B41+'GENSET #2'!B41+'GENSET #3'!B41+'GENSET #4'!B41+'GENSET #5'!B41) -> 0 | D35: =IF((C35-C34<0), "0",C35-C34) -> 0 | E35: ='Gas-2'!G36 -> 0 | F35: =IF((E35-E34<0), "0",E35-E34) -> 0 | G35: =SUM(WATER!C36,WATER!H36,WATER!M36,WATER!R36) -> 0 | H35: =IF((G35-G34<0), "0",G35-G34) -> 0

Sheet Finance Only
A1: Four Seasons Landaa Giraavaru
A3: Property | B3: MLG
A4: Month | B4: Feb
A5: Year | B5: 2021
A7: DAY | B7: Electricity Consumption ( kwh) | C7: Diesel Consumption (Liters) | D7: Solar Power Consumption(kwh) | E7: Gas Consumption (kg) | F7: Water Consumption ( m3)
A8: 1 | B8: =SUM('GENSET #1:GENSET #5'!D10) -> 27179 | C8: ='Diesel consumption'!D5 -> 7550 | D8: ='SOLAR METER READING'!D9 -> 1446 | E8: ='Gas-2'!G6 -> 405 | F8: =WATER!V6 -> 357
A9: 2 | B9: =SUM('GENSET #1:GENSET #5'!D11) -> 27052 | C9: ='Diesel consumption'!D6 -> 7310 | D9: ='SOLAR METER READING'!D10 -> 3163 | E9: ='Gas-2'!G7 -> 90 | F9: =WATER!V7 -> 314
A10: 3 | B10: =SUM('GENSET #1:GENSET #5'!D12) -> 27844 | C10: ='Diesel consumption'!D7 -> 7700 | D10: ='SOLAR METER READING'!D11 -> 2804 | E10: ='Gas-2'!G8 -> 405 | F10: =WATER!V8 -> 327
A11: 4 | B11: =SUM('GENSET #1:GENSET #5'!D13) -> 28535 | C11: ='Diesel consumption'!D8 -> 7660 | D11: ='SOLAR METER READING'!D12 -> 3067 | E11: ='Gas-2'!G9 -> 180 | F11: =WATER!V9 -> 374
A12: 5 | B12: =SUM('GENSET #1:GENSET #5'!D14) -> 27066 | C12: ='Diesel consumption'!D9 -> 7500 | D12: ='SOLAR METER READING'!D13 -> 3078 | E12: ='Gas-2'!G10 -> 405 | F12: =WATER!V10 -> 325
A13: 6 | B13: =SUM('GENSET #1:GENSET #5'!D15) -> 27114 | C13: ='Diesel consumption'!D10 -> 7340 | D13: ='SOLAR METER READING'!D14 -> 3057 | E13: ='Gas-2'!G11 -> 90 | F13: =WATER!V11 -> 392
A14: 7 | B14: =SUM('GENSET #1:GENSET #5'!D16) -> 27684 | C14: ='Diesel consumption'!D11 -> 7680 | D14: ='SOLAR METER READING'!D15 -> 2974 | E14: ='Gas-2'!G12 -> 270 | F14: =WATER!V12 -> 336
A15: 8 | B15: =SUM('GENSET #1:GENSET #5'!D17) -> 28636 | C15: ='Diesel consumption'!D12 -> 7810 | D15: ='SOLAR METER READING'!D16 -> 3106 | E15: ='Gas-2'!G13 -> 315 | F15: =WATER!V13 -> 363
A16: 9 | B16: =SUM('GENSET #1:GENSET #5'!D18) -> 27903 | C16: ='Diesel consumption'!D13 -> 7740 | D16: ='SOLAR METER READING'!D17 -> 3008 | E16: ='Gas-2'!G14 -> 135 | F16: =WATER!V14 -> 361
A17: 10 | B17: =SUM('GENSET #1:GENSET #5'!D19) -> 27665 | C17: ='Diesel consumption'!D14 -> 7440 | D17: ='SOLAR METER READING'!D18 -> 3047 | E17: ='Gas-2'!G15 -> 405 | F17: =WATER!V15 -> 370
A18: 11 | B18: =SUM('GENSET #1:GENSET #5'!D20) -> 26582 | C18: ='Diesel consumption'!D15 -> 7520 | D18: ='SOLAR METER READING'!D19 -> 3015 | E18: ='Gas-2'!G16 -> 180 | F18: =WATER!V16 -> 372
A19: 12 | B19: =SUM('GENSET #1:GENSET #5'!D21) -> 27100 | C19: ='Diesel consumption'!D16 -> 7460 | D19: ='SOLAR METER READING'!D20 -> 3023 | E19: ='Gas-2'!G17 -> 450 | F19: =WATER!V17 -> 361
... A38: 31 | B38: =SUM('GENSET #1:GENSET #5'!D40) -> 0 | C38: ='Diesel consumption'!D35 -> 0 | D38: ='SOLAR METER READING'!D39 -> 0 | E38: ='Gas-2'!G36 -> 0 | F38: =WATER!V36 -> 0
A39: Total | B39: =SUM(B8:B38) -> -86935793 | C39: =SUM(C8:C38) -> -43119420 | D39: =SUM(D8:D38) -> -2329152 | E39: =SUM(E8:E38) -> 4995 | F39: =SUM(F8:F38) -> -912599

Sheet GENSET #1
C1: 1000 KVA
C3: NO#1
A6: 44228
B8: GENSET NO 1
A9: DAY | B9: YESTARDAY | C9: TODAY | D9: Final Electricity Consumption( KWh)
A10: 1 | B10: 16920895 | C10: 16923848 | D10: =C10-B10 -> 2953
A11: 2 | B11: =C10 -> 16923848 | C11: 16923848 | D11: =C11-B11 -> 0
A12: 3 | B12: =C11 -> 16923848 | C12: 16926251 | D12: =C12-B12 -> 2403
A13: 4 | B13: =C12 -> 16926251 | C13: 16930675 | D13: =C13-B13 -> 4424
A14: 5 | B14: =C13 -> 16930675 | C14: 16934875 | D14: =C14-B14 -> 4200
A15: 6 | B15: =C14 -> 16934875 | C15: 16936706 | D15: =C15-B15 -> 1831
A16: 7 | B16: =C15 -> 16936706 | C16: 16936706 | D16: =C16-B16 -> 0
A17: 8 | B17: =C16 -> 16936706 | C17: 16936706 | D17: =C17-B17 -> 0
A18: 9 | B18: =C17 -> 16936706 | C18: 16943098 | D18: =C18-B18 -> 6392
A19: 10 | B19: =C18 -> 16943098 | C19: 16943512 | D19: =C19-B19 -> 414
A20: 11 | B20: =C19 -> 16943512 | C20: 16947289 | D20: =C20-B20 -> 3777
A21: 12 | B21: =C20 -> 16947289 | C21: 16947289 | D21: =C21-B21 -> 0
A22: 13 | B22: =C21 -> 16947289 | C22: 16950489 | D22: =C22-B22 -> 3200
... A29: 20 | B29: =C28 -> 16975713 | C29: 16982234 | D29: =C29-B29 -> 6521
A30: 21 | B30: =C29 -> 16982234 | D30: =C30-B30 -> -16982234
A31: 22 | B31: =C30 -> 0 | D31: =C31-B31 -> 0
A32: 23 | B32: =C31 -> 0 | D32: =C32-B32 -> 0
A33: 24 | B33: =C32 -> 0 | D33: =C33-B33 -> 0
A34: 25 | B34: =C33 -> 0 | D34: =C34-B34 -> 0
A35: 26 | B35: =C34 -> 0 | D35: =C35-B35 -> 0
A36: 27 | B36: =C35 -> 0 | D36: =C36-B36 -> 0
A37: 28 | B37: =C36 -> 0 | D37: =C37-B37 -> 0
A38: 29 | B38: =C37 -> 0 | D38: =C38-B38 -> 0
A39: 30 | B39: =C38 -> 0 | D39: =C39-B39 -> 0 | G39: NEW ENGINE PURCHASED FROM UK
A40: 31 | B40: =C39 -> 0 | D40: =C40-B40 -> 0
A41: Total | B41: =C40 -> 0 | D41: =SUM(D10:D40) -> -16920895 | G41: INSTALLED: NOV 30 2013

Sheet GENSET #2
C1: 1600 KVA
C3: NO#2
A6: 44228
B8: GENSET NO 2
A9: DAY | B9: YESTARDAY | C9: TODAY | D9: Final Electricity Consumption( KW h)
A10: 1 | B10: 28604837 | C10: 28611852 | D10: =C10-B10 -> 7015
A11: 2 | B11: =C10 -> 28611852 | C11: 28625529 | D11: =C11-B11 -> 13677
A12: 3 | B12: =C11 -> 28625529 | C12: 28637293 | D12: =C12-B12 -> 11764
A13: 4 | B13: =C12 -> 28637293 | C13: 28637293 | D13: =C13-B13 -> 0
A14: 5 | B14: =C13 -> 28637293 | C14: 28649139 | D14: =C14-B14 -> 11846
A15: 6 | B15: =C14 -> 28649139 | C15: 28660139 | D15: =C15-B15 -> 11000
A16: 7 | B16: =C15 -> 28660139 | C16: 28672700 | D16: =C16-B16 -> 12561
A17: 8 | B17: =C16 -> 28672700 | C17: 28685519 | D17: =C17-B17 -> 12819
A18: 9 | B18: =C17 -> 28685519 | C18: 28697320 | D18: =C18-B18 -> 11801
A19: 10 | B19: =C18 -> 28697320 | C19: 28709840 | D19: =C19-B19 -> 12520
A20: 11 | B20: =C19 -> 28709840 | C20: 28720378 | D20: =C20-B20 -> 10538
A21: 12 | B21: =C20 -> 28720378 | C21: 28731732 | D21: =C21-B21 -> 11354
A22: 13 | B22: =C21 -> 28731732 | C22: 28744258 | D22: =C22-B22 -> 12526
... A29: 20 | B29: =C28 -> 28817479 | C29: 28822733 | D29: =C29-B29 -> 5254
A30: 21 | B30: =C29 -> 28822733 | D30: =C30-B30 -> -28822733
A31: 22 | B31: =C30 -> 0 | D31: =C31-B31 -> 0
A32: 23 | B32: =C31 -> 0 | D32: =C32-B32 -> 0
A33: 24 | B33: =C32 -> 0 | D33: =C33-B33 -> 0
A34: 25 | B34: =C33 -> 0 | D34: =C34-B34 -> 0
A35: 26 | B35: =C34 -> 0 | D35: =C35-B35 -> 0
A36: 27 | B36: =C35 -> 0 | D36: =C36-B36 -> 0
A37: 28 | B37: =C36 -> 0 | D37: =C37-B37 -> 0
A38: 29 | B38: =C37 -> 0 | D38: =C38-B38 -> 0
A39: 30 | B39: =C38 -> 0 | D39: =C39-B39 -> 0
A40: 31 | B40: =C39 -> 0 | D40: =C40-B40 -> 0
A41: Total | B41: =C40 -> 0 | D41: =SUM(D10:D40) -> -28604837

Sheet GENSET #3
C1: 900 KVA
C3: NO#3
A6: 44228
B8: GENSET NO 3
A9: DAY | B9: YESTARDAY | C9: TODAY | D9: Final Electricity Consumption( KW h)
A10: 1 | B10: 12445913 | C10: 12453553 | D10: =C10-B10 -> 7640
A11: 2 | B11: =C10 -> 12453553 | C11: 12462045 | D11: =C11-B11 -> 8492
A12: 3 | B12: =C11 -> 12462045 | C12: 12469290 | D12: =C12-B12 -> 7245
A13: 4 | B13: =C12 -> 12469290 | C13: 12480291 | D13: =C13-B13 -> 11001
A14: 5 | B14: =C13 -> 12480291 | C14: 12484113 | D14: =C14-B14 -> 3822
A15: 6 | B15: =C14 -> 12484113 | C15: 12490349 | D15: =C15-B15 -> 6236
A16: 7 | B16: =C15 -> 12490349 | C16: 12498528 | D16: =C16-B16 -> 8179
A17: 8 | B17: =C16 -> 12498528 | C17: 12502172 | D17: =C17-B17 -> 3644
A18: 9 | B18: =C17 -> 12502172 | C18: 12503953 | D18: =C18-B18 -> 1781
A19: 10 | B19: =C18 -> 12503953 | C19: 12512393 | D19: =C19-B19 -> 8440
A20: 11 | B20: =C19 -> 12512393 | C20: 12515854 | D20: =C20-B20 -> 3461
A21: 12 | B21: =C20 -> 12515854 | C21: 12522493 | D21: =C21-B21 -> 6639
A22: 13 | B22: =C21 -> 12522493 | C22: 12527833 | D22: =C22-B22 -> 5340
... A29: 20 | B29: =C28 -> 12556159 | C29: 12563688 | D29: =C29-B29 -> 7529
A30: 21 | B30: =C29 -> 12563688 | D30: =C30-B30 -> -12563688
A31: 22 | B31: =C30 -> 0 | D31: =C31-B31 -> 0
A32: 23 | B32: =C31 -> 0 | D32: =C32-B32 -> 0
A33: 24 | B33: =C32 -> 0 | D33: =C33-B33 -> 0
A34: 25 | B34: =C33 -> 0 | D34: =C34-B34 -> 0
A35: 26 | B35: =C34 -> 0 | D35: =C35-B35 -> 0
A36: 27 | B36: =C35 -> 0 | D36: =C36-B36 -> 0
A37: 28 | B37: =C36 -> 0 | D37: =C37-B37 -> 0
A38: 29 | B38: =C37 -> 0 | D38: =C38-B38 -> 0
A39: 30 | B39: =C38 -> 0 | D39: =C39-B39 -> 0
A40: 31 | B40: =C39 -> 0 | D40: =C40-B40 -> 0
A41: Total | B41: =C40 -> 0 | D41: =SUM(D10:D40) -> -12445913

Sheet GENSET #4
C1: 500 KVA
C3: NO#4
A6: 44228
B8: GENSET NO 4
A9: DAY | B9: YESTARDAY | C9: TODAY | D9: Final Electricity Consumption( KW h)
A10: 1 | B10: 11405429 | C10: 11407737 | D10: =C10-B10 -> 2308
A11: 2 | B11: =C10 -> 11407737 | C11: 11409014 | D11: =C11-B11 -> 1277
A12: 3 | B12: =C11 -> 11409014 | C12: 11411124 | D12: =C12-B12 -> 2110
A13: 4 | B13: =C12 -> 11411124 | C13: 11415636 | D13: =C13-B13 -> 4512
A14: 5 | B14: =C13 -> 11415636 | C14: 11418749 | D14: =C14-B14 -> 3113
A15: 6 | B15: =C14 -> 11418749 | C15: 11420876 | D15: =C15-B15 -> 2127
A16: 7 | B16: =C15 -> 11420876 | C16: 11424049 | D16: =C16-B16 -> 3173
A17: 8 | B17: =C16 -> 11424049 | C17: 11424858 | D17: =C17-B17 -> 809
A18: 9 | B18: =C17 -> 11424858 | C18: 11427480 | D18: =C18-B18 -> 2622
A19: 10 | B19: =C18 -> 11427480 | C19: 11429518 | D19: =C19-B19 -> 2038
A20: 11 | B20: =C19 -> 11429518 | C20: 11431580 | D20: =C20-B20 -> 2062
A21: 12 | B21: =C20 -> 11431580 | C21: 11433380 | D21: =C21-B21 -> 1800
A22: 13 | B22: =C21 -> 11433380 | C22: 11434586 | D22: =C22-B22 -> 1206
... A29: 20 | B29: =C28 -> 11445635 | C29: 11446617 | D29: =C29-B29 -> 982
A30: 21 | B30: =C29 -> 11446617 | D30: =C30-B30 -> -11446617
A31: 22 | B31: =C30 -> 0 | D31: =C31-B31 -> 0
A32: 23 | B32: =C31 -> 0 | D32: =C32-B32 -> 0
A33: 24 | B33: =C32 -> 0 | D33: =C33-B33 -> 0
A34: 25 | B34: =C33 -> 0 | D34: =C34-B34 -> 0
A35: 26 | B35: =C34 -> 0 | D35: =C35-B35 -> 0
A36: 27 | B36: =C35 -> 0 | D36: =C36-B36 -> 0
A37: 28 | B37: =C36 -> 0 | D37: =C37-B37 -> 0
A38: 29 | B38: =C37 -> 0 | D38: =C38-B38 -> 0
A39: 30 | B39: =C38 -> 0 | D39: =C39-B39 -> 0
A40: 31 | B40: =C39 -> 0 | D40: =C40-B40 -> 0
A41: Total | B41: =C40 -> 0 | D41: =SUM(D10:D40) -> -11405429

Sheet GENSET #5
C1: 1000 KVA
C3: NO#5
A6: 44228
B8: GENSET NO 5
A9: DAY | B9: YESTARDAY | C9: TODAY | D9: Final Electricity Consumption( KWh)
A10: 1 | B10: 17558719 | C10: 17565982 | D10: =C10-B10 -> 7263
A11: 2 | B11: =C10 -> 17565982 | C11: 17569588 | D11: =C11-B11 -> 3606
A12: 3 | B12: =C11 -> 17569588 | C12: 17573910 | D12: =C12-B12 -> 4322
A13: 4 | B13: =C12 -> 17573910 | C13: 17582508 | D13: =C13-B13 -> 8598
A14: 5 | B14: =C13 -> 17582508 | C14: 17586593 | D14: =C14-B14 -> 4085
A15: 6 | B15: =C14 -> 17586593 | C15: 17592513 | D15: =C15-B15 -> 5920
A16: 7 | B16: =C15 -> 17592513 | C16: 17596284 | D16: =C16-B16 -> 3771
A17: 8 | B17: =C16 -> 17596284 | C17: 17607648 | D17: =C17-B17 -> 11364
A18: 9 | B18: =C17 -> 17607648 | C18: 17612955 | D18: =C18-B18 -> 5307
A19: 10 | B19: =C18 -> 17612955 | C19: 17617208 | D19: =C19-B19 -> 4253
A20: 11 | B20: =C19 -> 17617208 | C20: 17623952 | D20: =C20-B20 -> 6744
A21: 12 | B21: =C20 -> 17623952 | C21: 17631259 | D21: =C21-B21 -> 7307
A22: 13 | B22: =C21 -> 17631259 | C22: 17636471 | D22: =C22-B22 -> 5212
... A29: 20 | B29: =C28 -> 17676447 | C29: 17686565 | D29: =C29-B29 -> 10118
A30: 21 | B30: =C29 -> 17686565 | D30: =C30-B30 -> -17686565
A31: 22 | B31: =C30 -> 0 | D31: =C31-B31 -> 0
A32: 23 | B32: =C31 -> 0 | D32: =C32-B32 -> 0
A33: 24 | B33: =C32 -> 0 | D33: =C33-B33 -> 0
A34: 25 | B34: =C33 -> 0 | D34: =C34-B34 -> 0
A35: 26 | B35: =C34 -> 0 | D35: =C35-B35 -> 0
A36: 27 | B36: =C35 -> 0 | D36: =C36-B36 -> 0
A37: 28 | B37: =C36 -> 0 | D37: =C37-B37 -> 0
A38: 29 | B38: =C37 -> 0 | D38: =C38-B38 -> 0
A39: 30 | B39: =C38 -> 0 | D39: =C39-B39 -> 0
A40: 31 | B40: =C39 -> 0 | D40: =C40-B40 -> 0
A41: Total | B41: =C40 -> 0 | D41: =SUM(D10:D40) -> -17558719

Sheet Diesel consumption
A1: Diesel Consumption
A2: 44228
B3: Liters | F3: Boat meter Reading
A4: Date | B4: Yesterday | C4: Today | D4: In 24 hrs | F4: Yesterday | G4: Today | I4: In Barrels | K4: Carbon Emmision
A5: 1 | B5: 43119420 | C5: 43126970 | D5: =C5-B5 -> 7550 | I5: =D5/200 -> 37.75 | K5: =2.68*D5 -> 20234 | L5: =K5/1000 -> 20.234
A6: 2 | B6: =C5 -> 43126970 | C6: 43134280 | D6: =C6-B6 -> 7310 | I6: =D6/200 -> 36.55 | K6: =2.68*D6 -> 19590.8 | L6: =K6/1000 -> 19.5908
A7: 3 | B7: =C6 -> 43134280 | C7: 43141980 | D7: =C7-B7 -> 7700 | I7: =D7/200 -> 38.5 | K7: =2.68*D7 -> 20636 | L7: =K7/1000 -> 20.636
A8: 4 | B8: =C7 -> 43141980 | C8: 43149640 | D8: =C8-B8 -> 7660 | I8: =D8/200 -> 38.3 | K8: =2.68*D8 -> 20528.8 | L8: =K8/1000 -> 20.5288
A9: 5 | B9: =C8 -> 43149640 | C9: 43157140 | D9: =C9-B9 -> 7500 | I9: =D9/200 -> 37.5 | K9: =2.68*D9 -> 20100 | L9: =K9/1000 -> 20.1
A10: 6 | B10: =C9 -> 43157140 | C10: 43164480 | D10: =C10-B10 -> 7340 | I10: =D10/200 -> 36.7 | K10: =2.68*D10 -> 19671.2 | L10: =K10/1000 -> 19.6712
A11: 7 | B11: =C10 -> 43164480 | C11: 43172160 | D11: =C11-B11 -> 7680 | I11: =D11/200 -> 38.4 | K11: =2.68*D11 -> 20582.4 | L11: =K11/1000 -> 20.5824
A12: 8 | B12: =C11 -> 43172160 | C12: 43179970 | D12: =C12-B12 -> 7810 | I12: =D12/200 -> 39.05 | K12: =2.68*D12 -> 20930.8 | L12: =K12/1000 -> 20.9308
A13: 9 | B13: =C12 -> 43179970 | C13: 43187710 | D13: =C13-B13 -> 7740 | I13: =D13/200 -> 38.7 | K13: =2.68*D13 -> 20743.2 | L13: =K13/1000 -> 20.7432
A14: 10 | B14: =C13 -> 43187710 | C14: 43195150 | D14: =C14-B14 -> 7440 | I14: =D14/200 -> 37.2 | K14: =2.68*D14 -> 19939.2 | L14: =K14/1000 -> 19.9392
A15: 11 | B15: =C14 -> 43195150 | C15: 43202670 | D15: =C15-B15 -> 7520 | I15: =D15/200 -> 37.6 | K15: =2.68*D15 -> 20153.6 | L15: =K15/1000 -> 20.1536
A16: 12 | B16: =C15 -> 43202670 | C16: 43210130 | D16: =C16-B16 -> 7460 | I16: =D16/200 -> 37.3 | K16: =2.68*D16 -> 19992.8 | L16: =K16/1000 -> 19.9928
A17: 13 | B17: =C16 -> 43210130 | C17: 43217700 | D17: =C17-B17 -> 7570 | I17: =D17/200 -> 37.85 | K17: =2.68*D17 -> 20287.6 | L17: =K17/1000 -> 20.2876
... A24: 20 | B24: =C23 -> 43266780 | C24: 43275400 | D24: =C24-B24 -> 8620 | I24: =D24/200 -> 43.1 | K24: =2.68*D24 -> 23101.6 | L24: =K24/1000 -> 23.1016
A25: 21 | B25: =C24 -> 43275400 | D25: =C25-B25 -> -43275400 | I25: =D25/200 -> -216377 | K25: =2.68*D25 -> -115978072 | L25: =K25/1000 -> -115978.07
A26: 22 | B26: =C25 -> 0 | D26: =C26-B26 -> 0 | I26: =D26/200 -> 0 | K26: =2.68*D26 -> 0 | L26: =K26/1000 -> 0
A27: 23 | B27: =C26 -> 0 | D27: =C27-B27 -> 0 | I27: =D27/200 -> 0 | K27: =2.68*D27 -> 0 | L27: =K27/1000 -> 0
A28: 24 | B28: =C27 -> 0 | D28: =C28-B28 -> 0 | I28: =D28/200 -> 0 | K28: =2.68*D28 -> 0 | L28: =K28/1000 -> 0
A29: 25 | B29: =C28 -> 0 | D29: =C29-B29 -> 0 | I29: =D29/200 -> 0 | K29: =2.68*D29 -> 0 | L29: =K29/1000 -> 0
A30: 26 | B30: =C29 -> 0 | D30: =C30-B30 -> 0 | I30: =D30/200 -> 0 | K30: =2.68*D30 -> 0 | L30: =K30/1000 -> 0
A31: 27 | B31: =C30 -> 0 | D31: =C31-B31 -> 0 | I31: =D31/200 -> 0 | K31: =2.68*D31 -> 0 | L31: =K31/1000 -> 0
A32: 28 | B32: =C31 -> 0 | D32: =C32-B32 -> 0 | I32: =D32/200 -> 0 | K32: =2.68*D32 -> 0 | L32: =K32/1000 -> 0
A33: 29 | B33: =C32 -> 0 | D33: =C33-B33 -> 0 | I33: =D33/200 -> 0 | K33: =2.68*D33 -> 0 | L33: =K33/1000 -> 0
A34: 30 | B34: =C33 -> 0 | D34: =C34-B34 -> 0 | F34: 0 | I34: =D34/200 -> 0 | K34: =2.68*D34 -> 0 | L34: =K34/1000 -> 0
A35: 31 | B35: =C34 -> 0 | D35: =C35-B35 -> 0
D36: =SUM(D5:D34) -> -43119420 | I36: =SUM(I5:I34) -> -215597.1 | K36: =2.68*D36 -> -1.1556005e+08 | L36: =K36/1000 -> -115560.05

Sheet SOLAR METER READING
C3: solar reading
B5: 44228
B7: solar meter reading
A8: DAY | B8: YESTARDAY | C8: TODAY | D8: Final Electricity Consumption( KW h)
A9: 1 | B9: 2329152 | C9: 2330598 | D9: =C9-B9 -> 1446
A10: 2 | B10: =C9 -> 2330598 | C10: 2333761 | D10: =C10-B10 -> 3163
A11: 3 | B11: =C10 -> 2333761 | C11: 2336565 | D11: =C11-B11 -> 2804
A12: 4 | B12: =C11 -> 2336565 | C12: 2339632 | D12: =C12-B12 -> 3067
A13: 5 | B13: =C12 -> 2339632 | C13: 2342710 | D13: =C13-B13 -> 3078 | J13: 1 liter diesel | K13: 11.1 kwh
A14: 6 | B14: =C13 -> 2342710 | C14: 2345767 | D14: =C14-B14 -> 3057 | J14: 212.88 diesel | K14: 2363 kwh
A15: 7 | B15: =C14 -> 2345767 | C15: 2348741 | D15: =C15-B15 -> 2974
A16: 8 | B16: =C15 -> 2348741 | C16: 2351847 | D16: =C16-B16 -> 3106
A17: 9 | B17: =C16 -> 2351847 | C17: 2354855 | D17: =C17-B17 -> 3008
A18: 10 | B18: =C17 -> 2354855 | C18: 2357902 | D18: =C18-B18 -> 3047
A19: 11 | B19: =C18 -> 2357902 | C19: 2360917 | D19: =C19-B19 -> 3015
A20: 12 | B20: =C19 -> 2360917 | C20: 2363940 | D20: =C20-B20 -> 3023
A21: 13 | B21: =C20 -> 2363940 | C21: 2367161 | D21: =C21-B21 -> 3221
A22: 14 | B22: =C21 -> 2367161 | C22: 2370215 | D22: =C22-B22 -> 3054
A23: 15 | B23: =C22 -> 2370215 | C23: 2373309 | D23: =C23-B23 -> 3094
A24: 16 | B24: =C23 -> 2373309 | C24: 2376370 | D24: =C24-B24 -> 3061
A25: 17 | B25: =C24 -> 2376370 | C25: 2379442 | D25: =C25-B25 -> 3072
A26: 18 | B26: =C25 -> 2379442 | C26: 2382365 | D26: =C26-B26 -> 2923
... A28: 20 | B28: =C27 -> 2385580 | C28: 2388558 | D28: =C28-B28 -> 2978
A29: 21 | B29: =C28 -> 2388558 | D29: =C29-B29 -> -2388558
A30: 22 | B30: =C29 -> 0 | D30: =C30-B30 -> 0
A31: 23 | B31: =C30 -> 0 | D31: =C31-B31 -> 0
A32: 24 | B32: =C31 -> 0 | D32: =C32-B32 -> 0
A33: 25 | B33: =C32 -> 0 | D33: =C33-B33 -> 0
A34: 26 | B34: =C33 -> 0 | D34: =C34-B34 -> 0
A35: 27 | B35: =C34 -> 0 | D35: =C35-B35 -> 0
A36: 28 | B36: =C35 -> 0 | D36: =C36-B36 -> 0
A37: 29 | B37: =C36 -> 0 | D37: =C37-B37 -> 0
A38: 30 | B38: =C37 -> 0 | D38: =C38-B38 -> 0
A39: 31 | B39: =C38 -> 0 | D39: =C39-B39 -> 0
A40: Total | D40: =SUM(D9:D39) -> -2329152

Sheet FEEDER Consumption 
C3: POWER HOUSE FEEDER READING
A5: 43313
B7: BLU FEEDER PANEL 1 | E7: BLU FEEDER PANEL 2 | H7: POWER HOUSE FEEDER PANEL NO:3 | K7: Main Kitchen -7 | N7: Main Kitchen -10 | Q7: Water treatment Plant | T7: Sewage treatment Plant | W7: Laundry--8SSB | Z7: Laundry-9 | AC7: New staff accomodation (E0) | AF7: Boat Dock feeder - 22 | AI7: Staff block-16(E2-E3) | AL7: Management block-5 | AO7: Staff Block Feeder-3(E4-E5) | AR7: DIESEL TANK JETTY METER | AU7: SNR STAFF BLOCK | AX7: RECEPTION | BA7: DIVE CENTER | BD7: 301-307 | BG7: 308-314 | BJ7: 315-320 | BM7: 401-407 | BP7: 408-414 | BS7: 415-420 | BV7: SPA - 1 | BY7: SPA - 2 | CB7: BLU KITCHEN - 1 | CE7: BLU KITCHEN - 2 | CH7: AL BARAKATH | CK7: STAFF KITCHEN | CN7: MANAGR BLOCK GARDEN
A8: DAY | B8: Yesterday | C8: Today | D8: Consumption | E8: Yesterday | F8: Today | G8: Consumption | H8: Yesterday | I8: Today | J8: Consumption | K8: Yesterday | L8: Today | M8: Consumption | N8: Yesterday | O8: Today | P8: Consumption | Q8: Yesterday | R8: Today | S8: Consumption | T8: Yesterday | U8: Today | V8: Consumption | W8: Yesterday | X8: Today | Y8: Consumption | Z8: Yesterday | AA8: Today | AB8: Consumption | AC8: Yesterday | AD8: Today | AE8: Consumption | AF8: Yesterday | AG8: Today | AH8: Consumption | AI8: Yesterday | AJ8: Today | AK8: Consumption | AL8: Yesterday | AM8: Today | AN8: Consumption | AO8: Yesterday | AP8: Today | AQ8: Consumption | AR8: Yesterday | AS8: Today | AT8: Consumption | AU8: Yesterday | AV8: Today | AW8: Consumption | AX8: Yesterday | AY8: Today | AZ8: Consumption | BA8: Yesterday | BB8: Today | BC8: Consumption | BD8: Yesterday | BE8: Today | BF8: Consumption | BG8: Yesterday | BH8: Today | BI8: Consumption | BJ8: Yesterday | BK8: Today | BL8: Consumption | BM8: Yesterday | BN8: Today | BO8: Consumption | BP8: Yesterday | BQ8: Today | BR8: Consumption | BS8: Yesterday | BT8: Today | BU8: Consumption | BV8: Yesterday | BW8: Today | BX8: Consumption | BY8: Yesterday | BZ8: Today | CA8: Consumption | CB8: Yesterday | CC8: Today | CD8: Consumption | CE8: Yesterday | CF8: Today | CG8: Consumption | CH8: Yesterday | CI8: Today | CJ8: Consumption | CK8: Yesterday | CL8: Today | CM8: Consumption | CN8: Yesterday | CO8: Today | CP8: Consumption
A9: 1 | B9: 25196905 | C9: 25199953 | D9: =C9-B9 -> 3048 | E9: 22118523 | F9: 22122813 | G9: =F9-E9 -> 4290 | H9: 84139908 | I9: 84153340 | J9: =I9-H9 -> 13432 | K9: 1787800 | L9: 1789600 | M9: =L9-K9 -> 1800 | N9: 2415996 | O9: 2418545 | P9: =O9-N9 -> 2549 | Q9: 1459300 | R9: 1461200 | S9: =R9-Q9 -> 1900 | T9: 678159 | U9: 678649 | V9: =U9-T9 -> 490 | W9: 7022800 | X9: 7028700 | Y9: =X9-W9 -> 5900 | Z9: 1555800 | AA9: 1558100 | AB9: =AA9-Z9 -> 2300 | AC9: 455505 | AD9: 455929 | AE9: =AD9-AC9 -> 424 | AF9: 323370 | AG9: 323760 | AH9: =AG9-AF9 -> 390 | AI9: 548330 | AJ9: 549310 | AK9: =AJ9-AI9 -> 980 | AL9: 1010000 | AM9: 1011400 | AN9: =AM9-AL9 -> 1400 | AO9: 642560 | AP9: 643470 | AQ9: =AP9-AO9 -> 910 | AR9: 498770 | AS9: 499770 | AT9: =AS9-AR9 -> 1000 | AU9: 445730 | AV9: 447150 | AW9: =AV9-AU9 -> 1420 | AX9: 349000 | AY9: 350110 | AZ9: =AY9-AX9 -> 1110 | BA9: 951600 | BB9: 954450 | BC9: =BB9-BA9 -> 2850 | BD9: 19362 | BE9: 19464 | BF9: =BE9-BD9 -> 102 | BG9: 15795 | BH9: 15885 | BI9: =BH9-BG9 -> 90 | BJ9: 14732 | BK9: 14803 | BL9: =BK9-BJ9 -> 71 | BM9: 23491 | BN9: 23578 | BO9: =BN9-BM9 -> 87 | BP9: 16426 | BQ9: 16504 | BR9: =BQ9-BP9 -> 78 | BS9: 17670 | BT9: 17722 | BU9: =BT9-BS9 -> 52 | BV9: 12155 | BW9: 12204 | BX9: =BW9-BV9 -> 49 | BY9: 31718 | BZ9: 31855 | CA9: =BZ9-BY9 -> 137 | CB9: 25360 | CC9: 25440 | CD9: =CC9-CB9 -> 80 | CE9: 74185 | CF9: 74432 | CG9: =CF9-CE9 -> 247 | CH9: 44428 | CI9: 44798 | CJ9: =CI9-CH9 -> 370 | CK9: 12241 | CL9: 12290 | CM9: =CL9-CK9 -> 49 | CN9: 43908 | CO9: 44123 | CP9: =CO9-CN9 -> 215
A10: 2 | B10: =C9 -> 25199953 | C10: 25203251 | D10: =C10-B10 -> 3298 | E10: =F9 -> 22122813 | F10: 22128035 | G10: =F10-E10 -> 5222 | H10: =I9 -> 84153340 | I10: 84165868 | J10: =I10-H10 -> 12528 | K10: =L9 -> 1789600 | L10: 1791600 | M10: =L10-K10 -> 2000 | N10: =O9 -> 2418545 | O10: 2421250 | P10: =O10-N10 -> 2705 | Q10: =R9 -> 1461200 | R10: 1462500 | S10: =R10-Q10 -> 1300 | T10: =U9 -> 678649 | U10: 679172 | V10: =U10-T10 -> 523 | W10: =X9 -> 7028700 | X10: 7035100 | Y10: =X10-W10 -> 6400 | Z10: =AA9 -> 1558100 | AA10: 1559900 | AB10: =AA10-Z10 -> 1800 | AC10: =AD9 -> 455929 | AD10: 456390 | AE10: =AD10-AC10 -> 461 | AF10: =AG9 -> 323760 | AG10: 324100 | AH10: =AG10-AF10 -> 340 | AI10: =AJ9 -> 549310 | AJ10: 550100 | AK10: =AJ10-AI10 -> 790 | AL10: =AM9 -> 1011400 | AM10: 1012700 | AN10: =AM10-AL10 -> 1300 | AO10: =AP9 -> 643470 | AP10: 644270 | AQ10: =AP10-AO10 -> 800 | AR10: =AS9 -> 499770 | AS10: 500080 | AT10: =AS10-AR10 -> 310 | AU10: =AV9 -> 447150 | AV10: 448730 | AW10: =AV10-AU10 -> 1580 | AX10: =AY9 -> 350110 | AY10: 351260 | AZ10: =AY10-AX10 -> 1150 | BA10: =BB9 -> 954450 | BB10: 957710 | BC10: =BB10-BA10 -> 3260 | BD10: =BE9 -> 19464 | BE10: 19557 | BF10: =BE10-BD10 -> 93 | BG10: =BH9 -> 15885 | BH10: 15987 | BI10: =BH10-BG10 -> 102 | BJ10: =BK9 -> 14803 | BK10: 14885 | BL10: =BK10-BJ10 -> 82 | BM10: =BN9 -> 23578 | BN10: 23689 | BO10: =BN10-BM10 -> 111 | BP10: =BQ9 -> 16504 | BQ10: 16598 | BR10: =BQ10-BP10 -> 94 | BS10: =BT9 -> 17722 | BT10: 17792 | BU10: =BT10-BS10 -> 70 | BV10: =BW9 -> 12204 | BW10: 12257 | BX10: =BW10-BV10 -> 53 | BY10: =BZ9 -> 31855 | BZ10: 31986 | CA10: =BZ10-BY10 -> 131 | CB10: =CC9 -> 25440 | CC10: 25520 | CD10: =CC10-CB10 -> 80 | CE10: =CF9 -> 74432 | CF10: 74710 | CG10: =CF10-CE10 -> 278 | CH10: =CI9 -> 44798 | CI10: 45172 | CJ10: =CI10-CH10 -> 374 | CK10: =CL9 -> 12290 | CL10: 12337 | CM10: =CL10-CK10 -> 47 | CN10: =CO9 -> 44123 | CO10: 44328 | CP10: =CO10-CN10 -> 205
A11: 3 | B11: =C10 -> 25203251 | C11: 25206588 | D11: =C11-B11 -> 3337 | E11: =F10 -> 22128035 | F11: 22133188 | G11: =F11-E11 -> 5153 | H11: =I10 -> 84165868 | I11: 84179181 | J11: =I11-H11 -> 13313 | K11: =L10 -> 1791600 | L11: 1793600 | M11: =L11-K11 -> 2000 | N11: =O10 -> 2421250 | O11: 2424028 | P11: =O11-N11 -> 2778 | Q11: =R10 -> 1462500 | R11: 1463900 | S11: =R11-Q11 -> 1400 | T11: =U10 -> 679172 | U11: 679659 | V11: =U11-T11 -> 487 | W11: =X10 -> 7035100 | X11: 7041400 | Y11: =X11-W11 -> 6300 | Z11: =AA10 -> 1559900 | AA11: 1561600 | AB11: =AA11-Z11 -> 1700 | AC11: =AD10 -> 456390 | AD11: 456914 | AE11: =AD11-AC11 -> 524 | AF11: =AG10 -> 324100 | AG11: 324500 | AH11: =AG11-AF11 -> 400 | AI11: =AJ10 -> 550100 | AJ11: 550910 | AK11: =AJ11-AI11 -> 810 | AL11: =AM10 -> 1012700 | AM11: 1014100 | AN11: =AM11-AL11 -> 1400 | AO11: =AP10 -> 644270 | AP11: 645120 | AQ11: =AP11-AO11 -> 850 | AR11: =AS10 -> 500080 | AS11: 501880 | AT11: =AS11-AR11 -> 1800 | AU11: =AV10 -> 448730 | AV11: 450190 | AW11: =AV11-AU11 -> 1460 | AX11: =AY10 -> 351260 | AY11: 352420 | AZ11: =AY11-AX11 -> 1160 | BA11: =BB10 -> 957710 | BB11: 961380 | BC11: =BB11-BA11 -> 3670 | BD11: =BE10 -> 19557 | BE11: 19730 | BF11: =BE11-BD11 -> 173 | BG11: =BH10 -> 15987 | BH11: 16097 | BI11: =BH11-BG11 -> 110 | BJ11: =BK10 -> 14885 | BK11: 14961 | BL11: =BK11-BJ11 -> 76 | BM11: =BN10 -> 23689 | BN11: 23801 | BO11: =BN11-BM11 -> 112 | BP11: =BQ10 -> 16598 | BQ11: 16687 | BR11: =BQ11-BP11 -> 89 | BS11: =BT10 -> 17792 | BT11: 17858 | BU11: =BT11-BS11 -> 66 | BV11: =BW10 -> 12257 | BW11: 12309 | BX11: =BW11-BV11 -> 52 | BY11: =BZ10 -> 31986 | BZ11: 32106 | CA11: =BZ11-BY11 -> 120 | CB11: =CC10 -> 25520 | CC11: 25595 | CD11: =CC11-CB11 -> 75 | CE11: =CF10 -> 74710 | CF11: 74973 | CG11: =CF11-CE11 -> 263 | CH11: =CI10 -> 45172 | CI11: 45530 | CJ11: =CI11-CH11 -> 358 | CK11: =CL10 -> 12337 | CL11: 12389 | CM11: =CL11-CK11 -> 52 | CN11: =CO10 -> 44328 | CO11: 44509 | CP11: =CO11-CN11 -> 181
A12: 4 | B12: =C11 -> 25206588 | C12: 25210076 | D12: =C12-B12 -> 3488 | E12: =F11 -> 22133188 | F12: 22138559 | G12: =F12-E12 -> 5371 | H12: =I11 -> 84179181 | I12: 84192766 | J12: =I12-H12 -> 13585 | K12: =L11 -> 1793600 | L12: 1795700 | M12: =L12-K12 -> 2100 | N12: =O11 -> 2424028 | O12: 2426907 | P12: =O12-N12 -> 2879 | Q12: =R11 -> 1463900 | R12: 1465700 | S12: =R12-Q12 -> 1800 | T12: =U11 -> 679659 | U12: 680161 | V12: =U12-T12 -> 502 | W12: =X11 -> 7041400 | X12: 7047800 | Y12: =X12-W12 -> 6400 | Z12: =AA11 -> 1561600 | AA12: 1563300 | AB12: =AA12-Z12 -> 1700 | AC12: =AD11 -> 456914 | AD12: 457396 | AE12: =AD12-AC12 -> 482 | AF12: =AG11 -> 324500 | AG12: 324870 | AH12: =AG12-AF12 -> 370 | AI12: =AJ11 -> 550910 | AJ12: 551710 | AK12: =AJ12-AI12 -> 800 | AL12: =AM11 -> 1014100 | AM12: 1015400 | AN12: =AM12-AL12 -> 1300 | AO12: =AP11 -> 645120 | AP12: 645930 | AQ12: =AP12-AO12 -> 810 | AR12: =AS11 -> 501880 | AS12: 503690 | AT12: =AS12-AR12 -> 1810 | AU12: =AV11 -> 450190 | AV12: 451630 | AW12: =AV12-AU12 -> 1440 | AX12: =AY11 -> 352420 | AY12: 353620 | AZ12: =AY12-AX12 -> 1200 | BA12: =BB11 -> 961380 | BB12: 964860 | BC12: =BB12-BA12 -> 3480 | BD12: =BE11 -> 19730 | BE12: 19882 | BF12: =BE12-BD12 -> 152 | BG12: =BH11 -> 16097 | BH12: 16190 | BI12: =BH12-BG12 -> 93 | BJ12: =BK11 -> 14961 | BK12: 15031 | BL12: =BK12-BJ12 -> 70 | BM12: =BN11 -> 23801 | BN12: 23914 | BO12: =BN12-BM12 -> 113 | BP12: =BQ11 -> 16687 | BQ12: 16780 | BR12: =BQ12-BP12 -> 93 | BS12: =BT11 -> 17858 | BT12: 17921 | BU12: =BT12-BS12 -> 63 | BV12: =BW11 -> 12309 | BW12: 12367 | BX12: =BW12-BV12 -> 58 | BY12: =BZ11 -> 32106 | BZ12: 32230 | CA12: =BZ12-BY12 -> 124 | CB12: =CC11 -> 25595 | CC12: 25670 | CD12: =CC12-CB12 -> 75 | CE12: =CF11 -> 74973 | CF12: 75220 | CG12: =CF12-CE12 -> 247 | CH12: =CI11 -> 45530 | CI12: 45918 | CJ12: =CI12-CH12 -> 388 | CK12: =CL11 -> 12389 | CL12: 12438 | CM12: =CL12-CK12 -> 49 | CN12: =CO11 -> 44509 | CO12: 44747 | CP12: =CO12-CN12 -> 238
A13: 5 | B13: =C12 -> 25210076 | C13: 25213489 | D13: =C13-B13 -> 3413 | E13: =F12 -> 22138559 | F13: 22143241 | G13: =F13-E13 -> 4682 | H13: =I12 -> 84192766 | I13: 84205643 | J13: =I13-H13 -> 12877 | K13: =L12 -> 1795700 | L13: 1797700 | M13: =L13-K13 -> 2000 | N13: =O12 -> 2426907 | O13: 2429684 | P13: =O13-N13 -> 2777 | Q13: =R12 -> 1465700 | R13: 1467300 | S13: =R13-Q13 -> 1600 | T13: =U12 -> 680161 | U13: 680656 | V13: =U13-T13 -> 495 | W13: =X12 -> 7047800 | X13: 7053800 | Y13: =X13-W13 -> 6000 | Z13: =AA12 -> 1563300 | AA13: 1565000 | AB13: =AA13-Z13 -> 1700 | AC13: =AD12 -> 457396 | AD13: 457833 | AE13: =AD13-AC13 -> 437 | AF13: =AG12 -> 324870 | AG13: 325230 | AH13: =AG13-AF13 -> 360 | AI13: =AJ12 -> 551710 | AJ13: 552470 | AK13: =AJ13-AI13 -> 760 | AL13: =AM12 -> 1015400 | AM13: 1016700 | AN13: =AM13-AL13 -> 1300 | AO13: =AP12 -> 645930 | AP13: 646750 | AQ13: =AP13-AO13 -> 820 | AR13: =AS12 -> 503690 | AS13: 505190 | AT13: =AS13-AR13 -> 1500 | AU13: =AV12 -> 451630 | AV13: 453050 | AW13: =AV13-AU13 -> 1420 | AX13: =AY12 -> 353620 | AY13: 354790 | AZ13: =AY13-AX13 -> 1170 | BA13: =BB12 -> 964860 | BB13: 968580 | BC13: =BB13-BA13 -> 3720 | BD13: =BE12 -> 19882 | BE13: 20015 | BF13: =BE13-BD13 -> 133 | BG13: =BH12 -> 16190 | BH13: 16278 | BI13: =BH13-BG13 -> 88 | BJ13: =BK12 -> 15031 | BK13: 15099 | BL13: =BK13-BJ13 -> 68 | BM13: =BN12 -> 23914 | BN13: 24012 | BO13: =BN13-BM13 -> 98 | BP13: =BQ12 -> 16780 | BQ13: 16881 | BR13: =BQ13-BP13 -> 101 | BS13: =BT12 -> 17921 | BT13: 17982 | BU13: =BT13-BS13 -> 61 | BV13: =BW12 -> 12367 | BW13: 12419 | BX13: =BW13-BV13 -> 52 | BY13: =BZ12 -> 32230 | BZ13: 32377 | CA13: =BZ13-BY13 -> 147 | CB13: =CC12 -> 25670 | CC13: 25750 | CD13: =CC13-CB13 -> 80 | CE13: =CF12 -> 75220 | CF13: 75477 | CG13: =CF13-CE13 -> 257 | CH13: =CI12 -> 45918 | CI13: 46290 | CJ13: =CI13-CH13 -> 372 | CK13: =CL12 -> 12438 | CL13: 12520 | CM13: =CL13-CK13 -> 82 | CN13: =CO12 -> 44747 | CO13: 44939 | CP13: =CO13-CN13 -> 192
A14: 6 | B14: =C13 -> 25213489 | C14: 25216851 | D14: =C14-B14 -> 3362 | E14: =F13 -> 22143241 | F14: 22147701 | G14: =F14-E14 -> 4460 | H14: =I13 -> 84205643 | I14: 84218389 | J14: =I14-H14 -> 12746 | K14: =L13 -> 1797700 | L14: 1799700 | M14: =L14-K14 -> 2000 | N14: =O13 -> 2429684 | O14: 2432361 | P14: =O14-N14 -> 2677 | Q14: =R13 -> 1467300 | R14: 1468800 | S14: =R14-Q14 -> 1500 | T14: =U13 -> 680656 | U14: 681103 | V14: =U14-T14 -> 447 | W14: =X13 -> 7053800 | X14: 7059700 | Y14: =X14-W14 -> 5900 | Z14: =AA13 -> 1565000 | AA14: 1566900 | AB14: =AA14-Z14 -> 1900 | AC14: =AD13 -> 457833 | AD14: 458225 | AE14: =AD14-AC14 -> 392 | AF14: =AG13 -> 325230 | AG14: 325560 | AH14: =AG14-AF14 -> 330 | AI14: =AJ13 -> 552470 | AJ14: 553260 | AK14: =AJ14-AI14 -> 790 | AL14: =AM13 -> 1016700 | AM14: 1017900 | AN14: =AM14-AL14 -> 1200 | AO14: =AP13 -> 646750 | AP14: 647550 | AQ14: =AP14-AO14 -> 800 | AR14: =AS13 -> 505190 | AS14: 505830 | AT14: =AS14-AR14 -> 640 | AU14: =AV13 -> 453050 | AV14: 454540 | AW14: =AV14-AU14 -> 1490 | AX14: =AY13 -> 354790 | AY14: 356000 | AZ14: =AY14-AX14 -> 1210 | BA14: =BB13 -> 968580 | BB14: 972790 | BC14: =BB14-BA14 -> 4210 | BD14: =BE13 -> 20015 | BE14: 20132 | BF14: =BE14-BD14 -> 117 | BG14: =BH13 -> 16278 | BH14: 16350 | BI14: =BH14-BG14 -> 72 | BJ14: =BK13 -> 15099 | BK14: 15162 | BL14: =BK14-BJ14 -> 63 | BM14: =BN13 -> 24012 | BN14: 24104 | BO14: =BN14-BM14 -> 92 | BP14: =BQ13 -> 16881 | BQ14: 16982 | BR14: =BQ14-BP14 -> 101 | BS14: =BT13 -> 17982 | BT14: 18037 | BU14: =BT14-BS14 -> 55 | BV14: =BW13 -> 12419 | BW14: 12469 | BX14: =BW14-BV14 -> 50 | BY14: =BZ13 -> 32377 | BZ14: 32499 | CA14: =BZ14-BY14 -> 122 | CB14: =CC13 -> 25750 | CC14: 25830 | CD14: =CC14-CB14 -> 80 | CE14: =CF13 -> 75477 | CF14: 75738 | CG14: =CF14-CE14 -> 261 | CH14: =CI13 -> 46290 | CI14: 46657 | CJ14: =CI14-CH14 -> 367 | CK14: =CL13 -> 12520 | CL14: 12528 | CM14: =CL14-CK14 -> 8 | CN14: =CO13 -> 44939 | CO14: 45058 | CP14: =CO14-CN14 -> 119
A15: 7 | B15: =C14 -> 25216851 | C15: 25220331 | D15: =C15-B15 -> 3480 | E15: =F14 -> 22147701 | F15: 22152372 | G15: =F15-E15 -> 4671 | H15: =I14 -> 84218389 | I15: 84231806 | J15: =I15-H15 -> 13417 | K15: =L14 -> 1799700 | L15: 1801800 | M15: =L15-K15 -> 2100 | N15: =O14 -> 2432361 | O15: 2435199 | P15: =O15-N15 -> 2838 | Q15: =R14 -> 1468800 | R15: 1470600 | S15: =R15-Q15 -> 1800 | T15: =U14 -> 681103 | U15: 681586 | V15: =U15-T15 -> 483 | W15: =X14 -> 7059700 | X15: 7066200 | Y15: =X15-W15 -> 6500 | Z15: =AA14 -> 1566900 | AA15: 1568600 | AB15: =AA15-Z15 -> 1700 | AC15: =AD14 -> 458225 | AD15: 458649 | AE15: =AD15-AC15 -> 424 | AF15: =AG14 -> 325560 | AG15: 325950 | AH15: =AG15-AF15 -> 390 | AI15: =AJ14 -> 553260 | AJ15: 554100 | AK15: =AJ15-AI15 -> 840 | AL15: =AM14 -> 1017900 | AM15: 1019300 | AN15: =AM15-AL15 -> 1400 | AO15: =AP14 -> 647550 | AP15: 648410 | AQ15: =AP15-AO15 -> 860 | AR15: =AS14 -> 505830 | AS15: 508060 | AT15: =AS15-AR15 -> 2230 | AU15: =AV14 -> 454540 | AV15: 457790 | AW15: =AV15-AU15 -> 3250 | AX15: =AY14 -> 356000 | AY15: 357150 | AZ15: =AY15-AX15 -> 1150 | BA15: =BB14 -> 972790 | BB15: 976030 | BC15: =BB15-BA15 -> 3240 | BD15: =BE14 -> 20132 | BE15: 20261 | BF15: =BE15-BD15 -> 129 | BG15: =BH14 -> 16350 | BH15: 16432 | BI15: =BH15-BG15 -> 82 | BJ15: =BK14 -> 15162 | BK15: 15230 | BL15: =BK15-BJ15 -> 68 | BM15: =BN14 -> 24104 | BN15: 24199 | BO15: =BN15-BM15 -> 95 | BP15: =BQ14 -> 16982 | BQ15: 17072 | BR15: =BQ15-BP15 -> 90 | BS15: =BT14 -> 18037 | BT15: 18102 | BU15: =BT15-BS15 -> 65 | BV15: =BW14 -> 12469 | BW15: 12520 | BX15: =BW15-BV15 -> 51 | BY15: =BZ14 -> 32499 | BZ15: 32604 | CA15: =BZ15-BY15 -> 105 | CB15: =CC14 -> 25830 | CC15: 25913 | CD15: =CC15-CB15 -> 83 | CE15: =CF14 -> 75738 | CF15: 75991 | CG15: =CF15-CE15 -> 253 | CH15: =CI14 -> 46657 | CI15: 47041 | CJ15: =CI15-CH15 -> 384 | CK15: =CL14 -> 12528 | CL15: 12583 | CM15: =CL15-CK15 -> 55 | CN15: =CO14 -> 45058 | CO15: 45147 | CP15: =CO15-CN15 -> 89
A16: 8 | B16: =C15 -> 25220331 | C16: 25224037 | D16: =C16-B16 -> 3706 | E16: =F15 -> 22152372 | F16: 22157370 | G16: =F16-E16 -> 4998 | H16: =I15 -> 84231806 | I16: 84245691 | J16: =I16-H16 -> 13885 | K16: =L15 -> 1801800 | L16: 1803800 | M16: =L16-K16 -> 2000 | N16: =O15 -> 2435199 | O16: 2438120 | P16: =O16-N16 -> 2921 | Q16: =R15 -> 1470600 | R16: 1472400 | S16: =R16-Q16 -> 1800 | T16: =U15 -> 681586 | U16: 682117 | V16: =U16-T16 -> 531 | W16: =X15 -> 7066200 | X16: 7072800 | Y16: =X16-W16 -> 6600 | Z16: =AA15 -> 1568600 | AA16: 1570400 | AB16: =AA16-Z16 -> 1800 | AC16: =AD15 -> 458649 | AD16: 459138 | AE16: =AD16-AC16 -> 489 | AF16: =AG15 -> 325950 | AG16: 326340 | AH16: =AG16-AF16 -> 390 | AI16: =AJ15 -> 554100 | AJ16: 554980 | AK16: =AJ16-AI16 -> 880 | AL16: =AM15 -> 1019300 | AM16: 1020600 | AN16: =AM16-AL16 -> 1300 | AO16: =AP15 -> 648410 | AP16: 649310 | AQ16: =AP16-AO16 -> 900 | AR16: =AS15 -> 508060 | AS16: 508650 | AT16: =AS16-AR16 -> 590 | AU16: =AV15 -> 457790 | AV16: 457790 | AW16: =AV16-AU16 -> 0 | AX16: =AY15 -> 357150 | AY16: 358380 | AZ16: =AY16-AX16 -> 1230 | BA16: =BB15 -> 976030 | BB16: 979500 | BC16: =BB16-BA16 -> 3470 | BD16: =BE15 -> 20261 | BE16: 20399 | BF16: =BE16-BD16 -> 138 | BG16: =BH15 -> 16432 | BH16: 16516 | BI16: =BH16-BG16 -> 84 | BJ16: =BK15 -> 15230 | BK16: 15295 | BL16: =BK16-BJ16 -> 65 | BM16: =BN15 -> 24199 | BN16: 24280 | BO16: =BN16-BM16 -> 81 | BP16: =BQ15 -> 17072 | BQ16: 17176 | BR16: =BQ16-BP16 -> 104 | BS16: =BT15 -> 18102 | BT16: 18165 | BU16: =BT16-BS16 -> 63 | BV16: =BW15 -> 12520 | BW16: 12573 | BX16: =BW16-BV16 -> 53 | BY16: =BZ15 -> 32604 | BZ16: 32725 | CA16: =BZ16-BY16 -> 121 | CB16: =CC15 -> 25913 | CC16: 25995 | CD16: =CC16-CB16 -> 82 | CE16: =CF15 -> 75991 | CF16: 76257 | CG16: =CF16-CE16 -> 266 | CH16: =CI15 -> 47041 | CI16: 47409 | CJ16: =CI16-CH16 -> 368 | CK16: =CL15 -> 12583 | CL16: 12633 | CM16: =CL16-CK16 -> 50 | CN16: =CO15 -> 45147 | CO16: 45268 | CP16: =CO16-CN16 -> 121
A17: 9 | B17: =C16 -> 25224037 | C17: 25227504 | D17: =C17-B17 -> 3467 | E17: =F16 -> 22157370 | F17: 22162210 | G17: =F17-E17 -> 4840 | H17: =I16 -> 84245691 | I17: 84259009 | J17: =I17-H17 -> 13318 | K17: =L16 -> 1803800 | L17: 1805800 | M17: =L17-K17 -> 2000 | N17: =O16 -> 2438120 | O17: 2440818 | P17: =O17-N17 -> 2698 | Q17: =R16 -> 1472400 | R17: 1474000 | S17: =R17-Q17 -> 1600 | T17: =U16 -> 682117 | U17: 682621 | V17: =U17-T17 -> 504 | W17: =X16 -> 7072800 | X17: 7079200 | Y17: =X17-W17 -> 6400 | Z17: =AA16 -> 1570400 | AA17: 1572200 | AB17: =AA17-Z17 -> 1800 | AC17: =AD16 -> 459138 | AD17: 459565 | AE17: =AD17-AC17 -> 427 | AF17: =AG16 -> 326340 | AG17: 326720 | AH17: =AG17-AF17 -> 380 | AI17: =AJ16 -> 554980 | AJ17: 555840 | AK17: =AJ17-AI17 -> 860 | AL17: =AM16 -> 1020600 | AM17: 1021900 | AN17: =AM17-AL17 -> 1300 | AO17: =AP16 -> 649310 | AP17: 650210 | AQ17: =AP17-AO17 -> 900 | AR17: =AS16 -> 508650 | AS17: 510960 | AT17: =AS17-AR17 -> 2310 | AU17: =AV16 -> 457790 | AV17: 458760 | AW17: =AV17-AU17 -> 970 | AX17: =AY16 -> 358380 | AY17: 359590 | AZ17: =AY17-AX17 -> 1210 | BA17: =BB16 -> 979500 | BB17: 983320 | BC17: =BB17-BA17 -> 3820 | BD17: =BE16 -> 20399 | BE17: 20530 | BF17: =BE17-BD17 -> 131 | BG17: =BH16 -> 16516 | BH17: 16603 | BI17: =BH17-BG17 -> 87 | BJ17: =BK16 -> 15295 | BK17: 15364 | BL17: =BK17-BJ17 -> 69 | BM17: =BN16 -> 24280 | BN17: 24428 | BO17: =BN17-BM17 -> 148 | BP17: =BQ16 -> 17176 | BQ17: 17259 | BR17: =BQ17-BP17 -> 83 | BS17: =BT16 -> 18165 | BT17: 18222 | BU17: =BT17-BS17 -> 57 | BV17: =BW16 -> 12573 | BW17: 12624 | BX17: =BW17-BV17 -> 51 | BY17: =BZ16 -> 32725 | BZ17: 32834 | CA17: =BZ17-BY17 -> 109 | CB17: =CC16 -> 25995 | CC17: 26075 | CD17: =CC17-CB17 -> 80 | CE17: =CF16 -> 76257 | CF17: 76497 | CG17: =CF17-CE17 -> 240 | CH17: =CI16 -> 47409 | CI17: 47768 | CJ17: =CI17-CH17 -> 359 | CK17: =CL16 -> 12633 | CL17: 12683 | CM17: =CL17-CK17 -> 50 | CN17: =CO16 -> 45268 | CO17: 45347 | CP17: =CO17-CN17 -> 79
A18: 10 | B18: =C17 -> 25227504 | C18: 25231004 | D18: =C18-B18 -> 3500 | E18: =F17 -> 22162210 | F18: 22166746 | G18: =F18-E18 -> 4536 | H18: =I17 -> 84259009 | I18: 84272658 | J18: =I18-H18 -> 13649 | K18: =L17 -> 1805800 | L18: 1807800 | M18: =L18-K18 -> 2000 | N18: =O17 -> 2440818 | O18: 2443519 | P18: =O18-N18 -> 2701 | Q18: =R17 -> 1474000 | R18: 1475900 | S18: =R18-Q18 -> 1900 | T18: =U17 -> 682621 | U18: 683167 | V18: =U18-T18 -> 546 | W18: =X17 -> 7079200 | X18: 7085700 | Y18: =X18-W18 -> 6500 | Z18: =AA17 -> 1572200 | AA18: 1574000 | AB18: =AA18-Z18 -> 1800 | AC18: =AD17 -> 459565 | AD18: 459988 | AE18: =AD18-AC18 -> 423 | AF18: =AG17 -> 326720 | AG18: 327110 | AH18: =AG18-AF18 -> 390 | AI18: =AJ17 -> 555840 | AJ18: 556690 | AK18: =AJ18-AI18 -> 850 | AL18: =AM17 -> 1021900 | AM18: 1023300 | AN18: =AM18-AL18 -> 1400 | AO18: =AP17 -> 650210 | AP18: 651090 | AQ18: =AP18-AO18 -> 880 | AR18: =AS17 -> 510960 | AS18: 512780 | AT18: =AS18-AR18 -> 1820 | AU18: =AV17 -> 458760 | AV18: 459930 | AW18: =AV18-AU18 -> 1170 | AX18: =AY17 -> 359590 | AY18: 360780 | AZ18: =AY18-AX18 -> 1190 | BA18: =BB17 -> 983320 | BB18: 986800 | BC18: =BB18-BA18 -> 3480 | BD18: =BE17 -> 20530 | BE18: 20651 | BF18: =BE18-BD18 -> 121 | BG18: =BH17 -> 16603 | BH18: 16677 | BI18: =BH18-BG18 -> 74 | BJ18: =BK17 -> 15364 | BK18: 15424 | BL18: =BK18-BJ18 -> 60 | BM18: =BN17 -> 24428 | BN18: 24543 | BO18: =BN18-BM18 -> 115 | BP18: =BQ17 -> 17259 | BQ18: 17347 | BR18: =BQ18-BP18 -> 88 | BS18: =BT17 -> 18222 | BT18: 18273 | BU18: =BT18-BS18 -> 51 | BV18: =BW17 -> 12624 | BW18: 12675 | BX18: =BW18-BV18 -> 51 | BY18: =BZ17 -> 32834 | BZ18: 32946 | CA18: =BZ18-BY18 -> 112 | CB18: =CC17 -> 26075 | CC18: 26154 | CD18: =CC18-CB18 -> 79 | CE18: =CF17 -> 76497 | CF18: 76746 | CG18: =CF18-CE18 -> 249 | CH18: =CI17 -> 47768 | CI18: 48166 | CJ18: =CI18-CH18 -> 398 | CK18: =CL17 -> 12683 | CL18: 12731 | CM18: =CL18-CK18 -> 48 | CN18: =CO17 -> 45347 | CO18: 45452 | CP18: =CO18-CN18 -> 105
A19: 11 | B19: =C18 -> 25231004 | C19: 25234359 | D19: =C19-B19 -> 3355 | E19: =F18 -> 22166746 | F19: 22171143 | G19: =F19-E19 -> 4397 | H19: =I18 -> 84272658 | I19: 84285975 | J19: =I19-H19 -> 13317 | K19: =L18 -> 1807800 | L19: 1809700 | M19: =L19-K19 -> 1900 | N19: =O18 -> 2443519 | O19: 2446141 | P19: =O19-N19 -> 2622 | Q19: =R18 -> 1475900 | R19: 1477700 | S19: =R19-Q19 -> 1800 | T19: =U18 -> 683167 | U19: 683755 | V19: =U19-T19 -> 588 | W19: =X18 -> 7085700 | X19: 7091300 | Y19: =X19-W19 -> 5600 | Z19: =AA18 -> 1574000 | AA19: 1575600 | AB19: =AA19-Z19 -> 1600 | AC19: =AD18 -> 459988 | AD19: 460407 | AE19: =AD19-AC19 -> 419 | AF19: =AG18 -> 327110 | AG19: 327470 | AH19: =AG19-AF19 -> 360 | AI19: =AJ18 -> 556690 | AJ19: 556690 | AK19: =AJ19-AI19 -> 0 | AL19: =AM18 -> 1023300 | AM19: 1024600 | AN19: =AM19-AL19 -> 1300 | AO19: =AP18 -> 651090 | AP19: 651960 | AQ19: =AP19-AO19 -> 870 | AR19: =AS18 -> 512780 | AS19: 513650 | AT19: =AS19-AR19 -> 870 | AU19: =AV18 -> 459930 | AV19: 461290 | AW19: =AV19-AU19 -> 1360 | AX19: =AY18 -> 360780 | AY19: 361940 | AZ19: =AY19-AX19 -> 1160 | BA19: =BB18 -> 986800 | BB19: 990530 | BC19: =BB19-BA19 -> 3730 | BD19: =BE18 -> 20651 | BE19: 20749 | BF19: =BE19-BD19 -> 98 | BG19: =BH18 -> 16677 | BH19: 16747 | BI19: =BH19-BG19 -> 70 | BJ19: =BK18 -> 15424 | BK19: 15488 | BL19: =BK19-BJ19 -> 64 | BM19: =BN18 -> 24543 | BN19: 24659 | BO19: =BN19-BM19 -> 116 | BP19: =BQ18 -> 17347 | BQ19: 17430 | BR19: =BQ19-BP19 -> 83 | BS19: =BT18 -> 18273 | BT19: 18333 | BU19: =BT19-BS19 -> 60 | BV19: =BW18 -> 12675 | BW19: 12728 | BX19: =BW19-BV19 -> 53 | BY19: =BZ18 -> 32946 | BZ19: 33049 | CA19: =BZ19-BY19 -> 103 | CB19: =CC18 -> 26154 | CC19: 26235 | CD19: =CC19-CB19 -> 81 | CE19: =CF18 -> 76746 | CF19: 76981 | CG19: =CF19-CE19 -> 235 | CH19: =CI18 -> 48166 | CI19: 48581 | CJ19: =CI19-CH19 -> 415 | CK19: =CL18 -> 12731 | CL19: 12777 | CM19: =CL19-CK19 -> 46 | CN19: =CO18 -> 45452 | CO19: 45566 | CP19: =CO19-CN19 -> 114
A20: 12 | B20: =C19 -> 25234359 | C20: 25237687 | D20: =C20-B20 -> 3328 | E20: =F19 -> 22171143 | F20: 22175318 | G20: =F20-E20 -> 4175 | H20: =I19 -> 84285975 | I20: 84299441 | J20: =I20-H20 -> 13466 | K20: =L19 -> 1809700 | L20: 1811600 | M20: =L20-K20 -> 1900 | N20: =O19 -> 2446141 | O20: 2448764 | P20: =O20-N20 -> 2623 | Q20: =R19 -> 1477700 | R20: 1479500 | S20: =R20-Q20 -> 1800 | T20: =U19 -> 683755 | U20: 684376 | V20: =U20-T20 -> 621 | W20: =X19 -> 7091300 | X20: 7097400 | Y20: =X20-W20 -> 6100 | Z20: =AA19 -> 1575600 | AA20: 1577600 | AB20: =AA20-Z20 -> 2000 | AC20: =AD19 -> 460407 | AD20: 460837 | AE20: =AD20-AC20 -> 430 | AF20: =AG19 -> 327470 | AG20: 327820 | AH20: =AG20-AF20 -> 350 | AI20: =AJ19 -> 556690 | AJ20: 558330 | AK20: =AJ20-AI20 -> 1640 | AL20: =AM19 -> 1024600 | AM20: 1025800 | AN20: =AM20-AL20 -> 1200 | AO20: =AP19 -> 651960 | AP20: 652800 | AQ20: =AP20-AO20 -> 840 | AR20: =AS19 -> 513650 | AS20: 516200 | AT20: =AS20-AR20 -> 2550 | AU20: =AV19 -> 461290 | AV20: 462920 | AW20: =AV20-AU20 -> 1630 | AX20: =AY19 -> 361940 | AY20: 363110 | AZ20: =AY20-AX20 -> 1170 | BA20: =BB19 -> 990530 | BB20: 994180 | BC20: =BB20-BA20 -> 3650 | BD20: =BE19 -> 20749 | BE20: 20848 | BF20: =BE20-BD20 -> 99 | BG20: =BH19 -> 16747 | BH20: 16813 | BI20: =BH20-BG20 -> 66 | BJ20: =BK19 -> 15488 | BK20: 15553 | BL20: =BK20-BJ20 -> 65 | BM20: =BN19 -> 24659 | BN20: 24766 | BO20: =BN20-BM20 -> 107 | BP20: =BQ19 -> 17430 | BQ20: 17513 | BR20: =BQ20-BP20 -> 83 | BS20: =BT19 -> 18333 | BT20: 18385 | BU20: =BT20-BS20 -> 52 | BV20: =BW19 -> 12728 | BW20: 12779 | BX20: =BW20-BV20 -> 51 | BY20: =BZ19 -> 33049 | BZ20: 33152 | CA20: =BZ20-BY20 -> 103 | CB20: =CC19 -> 26235 | CC20: 26315 | CD20: =CC20-CB20 -> 80 | CE20: =CF19 -> 76981 | CF20: 77238 | CG20: =CF20-CE20 -> 257 | CH20: =CI19 -> 48581 | CI20: 48976 | CJ20: =CI20-CH20 -> 395 | CK20: =CL19 -> 12777 | CL20: 12826 | CM20: =CL20-CK20 -> 49 | CN20: =CO19 -> 45566 | CO20: 45689 | CP20: =CO20-CN20 -> 123
A21: 13 | B21: =C20 -> 25237687 | C21: 25241162 | D21: =C21-B21 -> 3475 | E21: =F20 -> 22175318 | F21: 22179764 | G21: =F21-E21 -> 4446 | H21: =I20 -> 84299441 | I21: 84312596 | J21: =I21-H21 -> 13155 | K21: =L20 -> 1811600 | L21: 1813400 | M21: =L21-K21 -> 1800 | N21: =O20 -> 2448764 | O21: 2451411 | P21: =O21-N21 -> 2647 | Q21: =R20 -> 1479500 | R21: 1481200 | S21: =R21-Q21 -> 1700 | T21: =U20 -> 684376 | U21: 684985 | V21: =U21-T21 -> 609 | W21: =X20 -> 7097400 | X21: 7103500 | Y21: =X21-W21 -> 6100 | Z21: =AA20 -> 1577600 | AA21: 1579600 | AB21: =AA21-Z21 -> 2000 | AC21: =AD20 -> 460837 | AD21: 461238 | AE21: =AD21-AC21 -> 401 | AF21: =AG20 -> 327820 | AG21: 328170 | AH21: =AG21-AF21 -> 350 | AI21: =AJ20 -> 558330 | AJ21: 559130 | AK21: =AJ21-AI21 -> 800 | AL21: =AM20 -> 1025800 | AM21: 1027000 | AN21: =AM21-AL21 -> 1200 | AO21: =AP20 -> 652800 | AP21: 653630 | AQ21: =AP21-AO21 -> 830 | AR21: =AS20 -> 516200 | AS21: 516430 | AT21: =AS21-AR21 -> 230 | AU21: =AV20 -> 462920 | AV21: 464450 | AW21: =AV21-AU21 -> 1530 | AX21: =AY20 -> 363110 | AY21: 364270 | AZ21: =AY21-AX21 -> 1160 | BA21: =BB20 -> 994180 | BB21: 997730 | BC21: =BB21-BA21 -> 3550 | BD21: =BE20 -> 20848 | BE21: 20951 | BF21: =BE21-BD21 -> 103 | BG21: =BH20 -> 16813 | BH21: 16893 | BI21: =BH21-BG21 -> 80 | BJ21: =BK20 -> 15553 | BK21: 15616 | BL21: =BK21-BJ21 -> 63 | BM21: =BN20 -> 24766 | BN21: 24870 | BO21: =BN21-BM21 -> 104 | BP21: =BQ20 -> 17513 | BQ21: 17597 | BR21: =BQ21-BP21 -> 84 | BS21: =BT20 -> 18385 | BT21: 18437 | BU21: =BT21-BS21 -> 52 | BV21: =BW20 -> 12779 | BW21: 12832 | BX21: =BW21-BV21 -> 53 | BY21: =BZ20 -> 33152 | BZ21: 33261 | CA21: =BZ21-BY21 -> 109 | CB21: =CC20 -> 26315 | CC21: 26397 | CD21: =CC21-CB21 -> 82 | CE21: =CF20 -> 77238 | CF21: 77517 | CG21: =CF21-CE21 -> 279 | CH21: =CI20 -> 48976 | CI21: 49355 | CJ21: =CI21-CH21 -> 379 | CK21: =CL20 -> 12826 | CL21: 12872 | CM21: =CL21-CK21 -> 46 | CN21: =CO20 -> 45689 | CO21: 45837 | CP21: =CO21-CN21 -> 148
