Workbook

Sheet TOTAL
A1: Site Name | B1: Day | C1: Month | D1: Year | E1: Total Electricity Kwh | F1: Electricity Tariff ($/Kwh) | G1: Natual Gas (m3) | H1: Natural Gas $/m3 | I1: Water Utility Supply (m3) m3 | J1: Water Utility Supply (m3) $/m3 | K1: Room Nights | L1: Total Guests | M1: Utilities day cost dh
A2: Mumbai | B2: 1 | C2: 2 | D2: 2021 | E2: ='Daily HLP'!I4 -> 19291 | F2: ='Daily HLP'!J4 -> 9 | G2: ='Daily HLP'!M4 -> 797.95 | H2: 44 | I2: ='Daily HLP'!P4 -> 171 | J2: 100 | K2: =Occupancy!G2 -> 91 | L2: 327 | M2: =E2*F2+G2*H2+#REF!*#REF!+I2*J2 -> #REF!
A3: Mumbai | B3: =B2+1 -> 2 | C3: 2 | D3: 2021 | E3: ='Daily HLP'!I5 -> 19381 | F3: =F2 -> 9 | G3: ='Daily HLP'!M5 -> 860.9 | H3: 44 | I3: ='Daily HLP'!P5 -> 171 | J3: 100 | K3: =Occupancy!G3 -> 120 | L3: 310 | M3: =E3*F3+G3*H3+#REF!*#REF!+I3*J3 -> #REF!
A4: Mumbai | B4: =B3+1 -> 3 | C4: 2 | D4: 2021 | E4: ='Daily HLP'!I6 -> 19375 | F4: =F3 -> 9 | G4: ='Daily HLP'!M6 -> 873 | H4: 44 | I4: ='Daily HLP'!P6 -> 161 | J4: 100 | K4: =Occupancy!G4 -> 112 | L4: 386 | M4: =E4*F4+G4*H4+#REF!*#REF!+I4*J4 -> #REF!
A5: Mumbai | B5: =B4+1 -> 4 | C5: 2 | D5: 2021 | E5: ='Daily HLP'!I7 -> 18251 | F5: =F4 -> 9 | G5: ='Daily HLP'!M7 -> 796 | H5: 44 | I5: ='Daily HLP'!P7 -> 150 | J5: 100 | K5: =Occupancy!G5 -> 112 | L5: 558 | M5: =E5*F5+G5*H5+#REF!*#REF!+I5*J5 -> #REF!
A6: Mumbai | B6: =B5+1 -> 5 | C6: 2 | D6: 2021 | E6: ='Daily HLP'!I8 -> 18524 | F6: =F5 -> 9 | G6: ='Daily HLP'!M8 -> 778 | H6: 44 | I6: ='Daily HLP'!P8 -> 181 | J6: 100 | K6: =Occupancy!G6 -> 105 | L6: 416 | M6: =E6*F6+G6*H6+#REF!*#REF!+I6*J6 -> #REF!
A7: Mumbai | B7: =B6+1 -> 6 | C7: 2 | D7: 2021 | E7: ='Daily HLP'!I9 -> 19190 | F7: =F6 -> 9 | G7: ='Daily HLP'!M9 -> 814 | H7: 44 | I7: ='Daily HLP'!P9 -> 271 | J7: 100 | K7: =Occupancy!G7 -> 150 | L7: 582 | M7: =E7*F7+G7*H7+#REF!*#REF!+I7*J7 -> #REF!
A8: Mumbai | B8: =B7+1 -> 7 | C8: 2 | D8: 2021 | E8: ='Daily HLP'!I10 -> 18255 | F8: =F7 -> 9 | G8: ='Daily HLP'!M10 -> 844.45 | H8: 44 | I8: ='Daily HLP'!P10 -> 212 | J8: 100 | K8: =Occupancy!G8 -> 107 | L8: 437 | M8: =E8*F8+G8*H8+#REF!*#REF!+I8*J8 -> #REF!
A9: Mumbai | B9: =B8+1 -> 8 | C9: 2 | D9: 2021 | E9: ='Daily HLP'!I11 -> 15387 | F9: =F8 -> 9 | G9: ='Daily HLP'!M11 -> 816.28 | H9: 44 | I9: ='Daily HLP'!P11 -> 211 | J9: 100 | K9: =Occupancy!G9 -> 120 | L9: 355 | M9: =E9*F9+G9*H9+#REF!*#REF!+I9*J9 -> #REF!
A10: Mumbai | B10: =B9+1 -> 9 | C10: 2 | D10: 2021 | E10: ='Daily HLP'!I12 -> 18397 | F10: =F9 -> 9 | G10: ='Daily HLP'!M12 -> 637.05 | H10: 44 | I10: ='Daily HLP'!P12 -> 192 | J10: 100 | K10: =Occupancy!G10 -> 125 | L10: 382 | M10: =E10*F10+G10*H10+#REF!*#REF!+I10*J10 -> #REF!
A11: Mumbai | B11: =B10+1 -> 10 | C11: 2 | D11: 2021 | E11: ='Daily HLP'!I13 -> 18869 | F11: =F10 -> 9 | G11: ='Daily HLP'!M13 -> 899.1 | H11: 44 | I11: ='Daily HLP'!P13 -> 250 | J11: 100 | K11: =Occupancy!G11 -> 142 | L11: 434 | M11: =E11*F11+G11*H11+#REF!*#REF!+I11*J11 -> #REF!
A12: Mumbai | B12: =B11+1 -> 11 | C12: 2 | D12: 2021 | E12: ='Daily HLP'!I14 -> 18625 | F12: =F11 -> 9 | G12: ='Daily HLP'!M14 -> 887.12 | H12: 44 | I12: ='Daily HLP'!P14 -> 211 | J12: 100 | K12: =Occupancy!G12 -> 122 | L12: 309 | M12: =E12*F12+G12*H12+#REF!*#REF!+I12*J12 -> #REF!
A13: Mumbai | B13: =B12+1 -> 12 | C13: 2 | D13: 2021 | E13: ='Daily HLP'!I15 -> 19448 | F13: =F12 -> 9 | G13: ='Daily HLP'!M15 -> 914.918 | H13: 44 | I13: ='Daily HLP'!P15 -> 211 | J13: 100 | K13: =Occupancy!G13 -> 131 | L13: 505 | M13: =E13*F13+G13*H13+#REF!*#REF!+I13*J13 -> #REF!
A14: Mumbai | B14: =B13+1 -> 13 | C14: 2 | D14: 2021 | E14: ='Daily HLP'!I16 -> 20224 | F14: =F13 -> 9 | G14: ='Daily HLP'!M16 -> 1043.67 | H14: 44 | I14: ='Daily HLP'!P16 -> 272 | J14: 100 | K14: =Occupancy!G14 -> 195 | L14: 581 | M14: =E14*F14+G14*H14+#REF!*#REF!+I14*J14 -> #REF!
... A20: Mumbai | B20: =B19+1 -> 19 | C20: 2 | D20: 2021 | E20: ='Daily HLP'!I22 -> 19578 | F20: =F19 -> 9 | G20: ='Daily HLP'!M22 -> 881.41 | H20: 44 | I20: ='Daily HLP'!P22 -> 190 | J20: 100 | K20: =Occupancy!G20 -> 163 | L20: 459 | M20: =E20*F20+G20*H20+#REF!*#REF!+I20*J20 -> #REF!
A21: Mumbai | B21: =B20+1 -> 20 | C21: 2 | D21: 2021 | E21: ='Daily HLP'!I23 -> 19799 | F21: =F20 -> 9 | G21: ='Daily HLP'!M23 -> 1086 | H21: 44 | I21: ='Daily HLP'!P23 -> 191 | J21: 100 | K21: =Occupancy!G21 -> 197 | L21: =Occupancy!F21 -> 537 | M21: =E21*F21+G21*H21+#REF!*#REF!+I21*J21 -> #REF!
A22: Mumbai | B22: =B21+1 -> 21 | C22: 2 | D22: 2021 | E22: ='Daily HLP'!I24 -> 20106 | F22: =F21 -> 9 | G22: ='Daily HLP'!M24 -> 940 | H22: 44 | I22: ='Daily HLP'!P24 -> 231 | J22: 100 | K22: =Occupancy!G22 -> 99 | L22: =Occupancy!F22 -> 561 | M22: =E22*F22+G22*H22+#REF!*#REF!+I22*J22 -> #REF!
A23: Mumbai | B23: =B22+1 -> 22 | C23: 2 | D23: 2021 | E23: ='Daily HLP'!I25 -> -580711 | F23: =F22 -> 9 | G23: ='Daily HLP'!M25 -> -26134.06 | H23: 44 | I23: ='Daily HLP'!P25 -> -1395 | J23: 100 | K23: =Occupancy!G23 -> 0 | L23: =Occupancy!F23 -> 0 | M23: =E23*F23+G23*H23+#REF!*#REF!+I23*J23 -> #REF!
A24: Mumbai | B24: =B23+1 -> 23 | C24: 2 | D24: 2021 | E24: ='Daily HLP'!I26 -> 19709 | F24: =F23 -> 9 | G24: ='Daily HLP'!M26 -> 934.94 | H24: 44 | I24: ='Daily HLP'!P26 -> 203 | J24: 100 | K24: =Occupancy!G24 -> 0 | L24: =Occupancy!F24 -> 0 | M24: =E24*F24+G24*H24+#REF!*#REF!+I24*J24 -> #REF!
A25: Mumbai | B25: =B24+1 -> 24 | C25: 2 | D25: 2021 | E25: ='Daily HLP'!I27 -> 19391 | F25: =F24 -> 9 | G25: ='Daily HLP'!M27 -> 748.12 | H25: 44 | I25: ='Daily HLP'!P27 -> 190 | J25: 100 | K25: =Occupancy!G25 -> 0 | L25: =Occupancy!F25 -> 0 | M25: =E25*F25+G25*H25+#REF!*#REF!+I25*J25 -> #REF!
A26: Mumbai | B26: =B25+1 -> 25 | C26: 2 | D26: 2021 | E26: ='Daily HLP'!I28 -> 19169 | F26: =F25 -> 9 | G26: ='Daily HLP'!M28 -> 930.86 | H26: 44 | I26: ='Daily HLP'!P28 -> 183 | J26: 100 | K26: =Occupancy!G26 -> 0 | L26: =Occupancy!F26 -> 0 | M26: =E26*F26+G26*H26+#REF!*#REF!+I26*J26 -> #REF!
A27: Mumbai | B27: =B26+1 -> 26 | C27: 2 | D27: 2021 | E27: ='Daily HLP'!I29 -> 18998 | F27: =F26 -> 9 | G27: ='Daily HLP'!M29 -> 855.14 | H27: 44 | I27: ='Daily HLP'!P29 -> 189 | J27: 100 | K27: =Occupancy!G27 -> 0 | L27: =Occupancy!F27 -> 0 | M27: =E27*F27+G27*H27+#REF!*#REF!+I27*J27 -> #REF!
A28: Mumbai | B28: =B27+1 -> 27 | C28: 2 | D28: 2021 | E28: ='Daily HLP'!I30 -> 18736 | F28: =F27 -> 9 | G28: ='Daily HLP'!M30 -> 843.94 | H28: 44 | I28: ='Daily HLP'!P30 -> 174 | J28: 100 | K28: =Occupancy!G28 -> 0 | L28: =Occupancy!F28 -> 0 | M28: =E28*F28+G28*H28+#REF!*#REF!+I28*J28 -> #REF!
A29: Mumbai | B29: =B28+1 -> 28 | C29: 2 | D29: 2021 | E29: ='Daily HLP'!I31 -> 19357 | F29: =F28 -> 9 | G29: ='Daily HLP'!M31 -> 434.06 | H29: 44 | I29: ='Daily HLP'!P31 -> 173 | J29: 100 | K29: =Occupancy!G29 -> 0 | L29: =Occupancy!F29 -> 0 | M29: =E29*F29+G29*H29+#REF!*#REF!+I29*J29 -> #REF!
A30: Mumbai | B30: =B29+1 -> 29 | C30: 2 | D30: 2021 | E30: ='Daily HLP'!I32 -> 18748 | F30: =F29 -> 9 | G30: ='Daily HLP'!M32 -> 826.97 | H30: 44 | I30: ='Daily HLP'!P32 -> 151 | J30: 100 | K30: =Occupancy!G30 -> 0 | L30: =Occupancy!F30 -> 0 | M30: =E30*F30+G30*H30+#REF!*#REF!+I30*J30 -> #REF!
A31: Mumbai | B31: =B30+1 -> 30 | C31: 2 | D31: 2021 | E31: ='Daily HLP'!I33 -> 18917 | F31: =F30 -> 9 | G31: ='Daily HLP'!M33 -> 667.76 | H31: 44 | I31: ='Daily HLP'!P33 -> 171 | J31: 100 | K31: =Occupancy!G31 -> 0 | L31: =Occupancy!F31 -> 0 | M31: =E31*F31+G31*H31+#REF!*#REF!+I31*J31 -> #REF!

Sheet Submetering
A1: Site Name | B1: Day | C1: Month | D1: Year | E1: Main HVAC Power Panel- 800A | F1: Main Panel BALLROOM LVL-2 -2000A | G1: Fire Emergency Power Panel - 1000A | H1: Main Power Panel -1600A | I1: Main Lighting and Small power Panel | J1: Capacitor Bank -1 1100KVAR- 2500A | K1: Chiller No 1 | L1: Chiller No 2- | M1: Chiller Water pump Panel- 630A | N1: Co-Genrator | O1: Lawn Pantry | P1: Pavilion Power | Q1: Main HVAC Power Panel 2- 800A | R1: Main MV Panel BALLROOM LVL-1- 2000A | S1: Fire Emergency Power Panel 2 - 1000A | T1: Main Power Panel 2 -1800A | U1: Main Lighting and Small power Panel 2 | V1: Capacitor Bank -2 1200KVAR- 2500A | W1: Chiller No -3 - 1200A | X1: Chiller No-4 - 1200A | Y1: Chiller Water pump Panel- 630A | Z1: B2-Loundry power panel | AA1: 2nd floor plant room | AB1: 5th floor spa | AC1: 5th Floor | AD1: 12th Floor | AE1: 20th Floor | AF1: 27th Floor | AG1: 34th Floor | AH1: Sanqi | AI1: Consumption of Extra AHU run | AJ1: Main kitchen power panel no 1 | AK1: Main kitchen power panel no 2 | AL1: Prato kitchen power panel | AM1: San- Qi Indian Kitchen | AN1: San- Qi Japanese Kitchen | AO1: The club kitchen | AP1: AER Kitchen | AQ1: COLD ROOM'S | AR1: Ball Room 1 kitchen | AS1: Ball Room 2 kitchen | AT1: B1 Laundry | AU1: STP Electrical | AV1: Cooling Tower | AW1: R.o.plant | AX1: STP Water Prod | AY1: Domestic Zone-1 | AZ1: Domestic Zone-2 | BA1: Domestic Zone-3 | BB1: Flush Zone -1 | BC1: Flush Zone -2 | BD1: Flush Zone -3 | BE1: Swimming pool | BF1: B2 Laundry | BG1: Boiler Feed Water | BH1: cooling tower filling water | BI1: STP flush(new water meter) | BJ1: Garden Water Pump | BK1: Flush Zone 2 pump meter | BL1: Flush Zone 3 Pump Meter (wtp transfer ) | BM1: Flush Tanker | BN1: Total Domestic Water (R.O +BMC) | BO1: Total Domestic Consumption | BP1: Total STP Consumption | BQ1: H.W.G. Gas meter reading | BR1: Prato Kitchen Gas meter Reading | BS1: BallRoom Gas | BT1: Sanqi IndianGas meter Reading | BU1: Sanqi Japanese Gas meter Reading | BV1: Boiler Gas Consumption
A2: Mumbai | B2: 1 | C2: 2 | D2: 2021 | E2: ='1'!$H$35 -> 0 | F2: ='1'!$H$36 -> 555.2 | G2: ='1'!$H$37 -> 0 | H2: ='1'!$H$38 -> 0 | I2: ='1'!$H$39 -> 0 | J2: ='1'!$H$40 -> 0 | K2: ='1'!$H$41 -> 4365.99 | L2: ='1'!$H$42 -> 0 | M2: ='1'!$H$43 -> 2272.96 | N2: ='1'!$H$44 -> 0 | O2: ='1'!$H$45 -> 0 | P2: ='1'!$H$46 -> 0 | Q2: ='1'!$H$49 -> 2996.04 | R2: ='1'!$H$50 -> 1021.36 | S2: ='1'!$H$51 -> 1437.83 | T2: ='1'!$H$52 -> 2015.04 | U2: ='1'!$H$53 -> 4103.76 | V2: ='1'!$H$54 -> 40.32 | W2: ='1'!$H$55 -> 0 | X2: ='1'!$H$56 -> 0.52 | Y2: ='1'!$H$57 -> 0 | Z2: ='1'!$H$58 -> 174.52 | AA2: ='1'!$H$62 -> 0 | AB2: ='1'!$H$63 -> 14.46 | AC2: ='1'!$H$64 -> 445.63 | AD2: ='1'!$H$65 -> 382.9 | AE2: ='1'!$H$66 -> 390.09 | AF2: ='1'!$H$67 -> 657.86 | AG2: ='1'!$H$68 -> 327.79 | AH2: ='1'!$H$69 -> 319.9 | AI2: ='1'!$H$70 -> 0 | AJ2: ='1'!$H$72 -> 84 | AK2: ='1'!$H$73 -> 0 | AL2: ='1'!$H$74 -> 23 | AM2: ='1'!$H$75 -> 183 | AN2: ='1'!$H$76 -> 74 | AO2: ='1'!$H$77 -> 48 | AP2: ='1'!$H$78 -> 334 | AQ2: ='1'!$H$79 -> 205 | AR2: ='1'!$H$80 -> 308 | AS2: ='1'!$H$81 -> 76 | AT2: ='1'!$H$82 -> 45 | AU2: ='1'!$H$83 -> 433 | AV2: ='1'!$H$84 -> 521 | AW2: ='1'!$H$92 -> 87 | AX2: ='1'!$H$93 -> 200 | AY2: ='1'!$H$95 -> 72 | AZ2: ='1'!$H$96 -> 23 | BA2: ='1'!$H$97 -> 18 | BB2: ='1'!$H$98 -> 83 | BC2: ='1'!$H$99 -> 13 | BD2: ='1'!$H$100 -> 6 | BE2: ='1'!$H$104 -> 0 | BF2: ='1'!$H$105 -> 8 | BG2: ='1'!$H$106 -> 7 | BH2: ='1'!$H$109 -> 41 | BI2: ='1'!$H$110 -> 79 | BJ2: ='1'!$H$111 -> 0 | BK2: ='1'!$H$114 -> 16 | BL2: ='1'!$H$115 -> 5 | BM2: ='1'!$H$116 -> 0 | BN2: ='1'!$H$118 -> 138 | BO2: ='1'!$H$119 -> 132 | BP2: ='1'!$H$120 -> 120 | BQ2: ='1'!$H$123 -> 270.38 | BR2: ='1'!$H$124 -> 0 | BS2: ='1'!$H$125 -> 59 | BT2: ='1'!$H$126 -> 28.2 | BU2: ='1'!$H$127 -> 0 | BV2: ='1'!$H$128 -> 440.37
A3: Mumbai | B3: =B2+1 -> 2 | C3: 2 | D3: 2021 | E3: ='2'!$H$35 -> 0 | F3: ='2'!$H$36 -> 1176.55 | G3: ='2'!$H$37 -> 0 | H3: ='2'!$H$38 -> 0 | I3: ='2'!$H$39 -> 0 | J3: ='2'!$H$40 -> 0 | K3: ='2'!$H$41 -> 8536.48 | L3: ='2'!$H$42 -> 0.09 | M3: ='2'!$H$43 -> 4533.09 | N3: ='2'!$H$44 -> 0 | O3: ='2'!$H$45 -> -0.48 | P3: ='2'!$H$46 -> -0.49 | Q3: ='2'!$H$49 -> 6054.95 | R3: ='2'!$H$50 -> 2057.69 | S3: ='2'!$H$51 -> 2879.26 | T3: ='2'!$H$52 -> 4037.33 | U3: ='2'!$H$53 -> 8262.73 | V3: ='2'!$H$54 -> 79.36 | W3: ='2'!$H$55 -> 0 | X3: ='2'!$H$56 -> 2.52 | Y3: ='2'!$H$57 -> 0 | Z3: ='2'!$H$58 -> 328.09 | AA3: ='2'!$H$62 -> 0 | AB3: ='2'!$H$63 -> 29.47 | AC3: ='2'!$H$64 -> 881.54 | AD3: ='2'!$H$65 -> 760.89 | AE3: ='2'!$H$66 -> 794.26 | AF3: ='2'!$H$67 -> 1328.47 | AG3: ='2'!$H$68 -> 669.14 | AH3: ='2'!$H$69 -> 630.29 | AI3: ='2'!$H$70 -> 0 | AJ3: ='2'!$H$72 -> 168 | AK3: ='2'!$H$73 -> 0 | AL3: ='2'!$H$74 -> 50 | AM3: ='2'!$H$75 -> 367 | AN3: ='2'!$H$76 -> 147 | AO3: ='2'!$H$77 -> 107 | AP3: ='2'!$H$78 -> 714 | AQ3: ='2'!$H$79 -> 401 | AR3: ='2'!$H$80 -> 626 | AS3: ='2'!$H$81 -> 178 | AT3: ='2'!$H$82 -> 100 | AU3: ='2'!$H$83 -> 861 | AV3: ='2'!$H$84 -> 1055 | AW3: ='2'!$H$92 -> 162 | AX3: ='2'!$H$93 -> 351 | AY3: ='2'!$H$95 -> 142 | AZ3: ='2'!$H$96 -> 53 | BA3: ='2'!$H$97 -> 34 | BB3: ='2'!$H$98 -> 150 | BC3: ='2'!$H$99 -> 21 | BD3: ='2'!$H$100 -> 11 | BE3: ='2'!$H$104 -> 0 | BF3: ='2'!$H$105 -> 16 | BG3: ='2'!$H$106 -> 12 | BH3: ='2'!$H$109 -> 102 | BI3: ='2'!$H$110 -> 118 | BJ3: ='2'!$H$111 -> 16 | BK3: ='2'!$H$114 -> 27 | BL3: ='2'!$H$115 -> 8 | BM3: ='2'!$H$116 -> 0 | BN3: ='2'!$H$118 -> 264 | BO3: ='2'!$H$119 -> 261 | BP3: ='2'!$H$120 -> 236 | BQ3: ='2'!$H$123 -> 528.6 | BR3: ='2'!$H$124 -> 0 | BS3: ='2'!$H$125 -> 121 | BT3: ='2'!$H$126 -> 80.3 | BU3: ='2'!$H$127 -> 3 | BV3: ='2'!$H$128 -> 925.95
A4: Mumbai | B4: =B3+1 -> 3 | C4: 2 | D4: 2021 | E4: ='3'!$H$35 -> 2568.33 | F4: ='3'!$H$36 -> 1960.55 | G4: ='3'!$H$37 -> 0 | H4: ='3'!$H$38 -> 0 | I4: ='3'!$H$39 -> 0 | J4: ='3'!$H$40 -> 0 | K4: ='3'!$H$41 -> 12547.48 | L4: ='3'!$H$42 -> 0.09 | M4: ='3'!$H$43 -> 6826.09 | N4: ='3'!$H$44 -> 0 | O4: ='3'!$H$45 -> -0.48 | P4: ='3'!$H$46 -> -0.49 | Q4: ='3'!$H$49 -> 6068.95 | R4: ='3'!$H$50 -> 3443.69 | S4: ='3'!$H$51 -> 4411.26 | T4: ='3'!$H$52 -> 5986.33 | U4: ='3'!$H$53 -> 12531.73 | V4: ='3'!$H$54 -> 94.36 | W4: ='3'!$H$55 -> 0 | X4: ='3'!$H$56 -> 2.52 | Y4: ='3'!$H$57 -> 0 | Z4: ='3'!$H$58 -> 498.09 | AA4: ='3'!$H$62 -> 0 | AB4: ='3'!$H$63 -> 44.47 | AC4: ='3'!$H$64 -> 1299.54 | AD4: ='3'!$H$65 -> 1134.89 | AE4: ='3'!$H$66 -> 1213.26 | AF4: ='3'!$H$67 -> 2053.47 | AG4: ='3'!$H$68 -> 1000.14 | AH4: ='3'!$H$69 -> 943.29 | AI4: ='3'!$H$70 -> 0 | AJ4: ='3'!$H$72 -> 256 | AK4: ='3'!$H$73 -> 1 | AL4: ='3'!$H$74 -> 74 | AM4: ='3'!$H$75 -> 559 | AN4: ='3'!$H$76 -> 236 | AO4: ='3'!$H$77 -> 154 | AP4: ='3'!$H$78 -> 1139 | AQ4: ='3'!$H$79 -> 604 | AR4: ='3'!$H$80 -> 953 | AS4: ='3'!$H$81 -> 282 | AT4: ='3'!$H$82 -> 141 | AU4: ='3'!$H$83 -> 1255 | AV4: ='3'!$H$84 -> 1512 | AW4: ='3'!$H$92 -> 250 | AX4: ='3'!$H$93 -> 501 | AY4: ='3'!$H$95 -> 206 | AZ4: ='3'!$H$96 -> 89 | BA4: ='3'!$H$97 -> 65 | BB4: ='3'!$H$98 -> 222 | BC4: ='3'!$H$99 -> 31 | BD4: ='3'!$H$100 -> 16 | BE4: ='3'!$H$104 -> 0 | BF4: ='3'!$H$105 -> 22 | BG4: ='3'!$H$106 -> 17 | BH4: ='3'!$H$109 -> 160 | BI4: ='3'!$H$110 -> 211 | BJ4: ='3'!$H$111 -> 16 | BK4: ='3'!$H$114 -> 39 | BL4: ='3'!$H$115 -> 14 | BM4: ='3'!$H$116 -> 0 | BN4: ='3'!$H$118 -> 403 | BO4: ='3'!$H$119 -> 407 | BP4: ='3'!$H$120 -> 387 | BQ4: ='3'!$H$123 -> 793.6 | BR4: ='3'!$H$124 -> 0 | BS4: ='3'!$H$125 -> 204 | BT4: ='3'!$H$126 -> 137.3 | BU4: ='3'!$H$127 -> 7 | BV4: ='3'!$H$128 -> 1389.95
A5: Mumbai | B5: =B4+1 -> 4 | C5: 2 | D5: 2021 | E5: ='4'!$H$35 -> 5175.33 | F5: ='4'!$H$36 -> 2554.55 | G5: ='4'!$H$37 -> 1302 | H5: ='4'!$H$38 -> 806.12 | I5: ='4'!$H$39 -> 3521 | J5: ='4'!$H$40 -> 0 | K5: ='4'!$H$41 -> 13992.48 | L5: ='4'!$H$42 -> 0 | M5: ='4'!$H$43 -> 9077.09 | N5: ='4'!$H$44 -> 0 | O5: ='4'!$H$45 -> -0.48 | P5: ='4'!$H$46 -> -0.49 | Q5: ='4'!$H$49 -> 6068.95 | R5: ='4'!$H$50 -> 4528.69 | S5: ='4'!$H$51 -> 4618.26 | T5: ='4'!$H$52 -> 7091.33 | U5: ='4'!$H$53 -> 13158.73 | V5: ='4'!$H$54 -> 102.36 | W5: ='4'!$H$55 -> 2283.42 | X5: ='4'!$H$56 -> 7.09 | Y5: ='4'!$H$57 -> 0 | Z5: ='4'!$H$58 -> 677.09 | AA5: ='4'!$H$62 -> -0.001 | AB5: ='4'!$H$63 -> 58.47 | AC5: ='4'!$H$64 -> 1718.54 | AD5: ='4'!$H$65 -> 1505.89 | AE5: ='4'!$H$66 -> 1609.26 | AF5: ='4'!$H$67 -> 2754.47 | AG5: ='4'!$H$68 -> 1343.14 | AH5: ='4'!$H$69 -> 1239.29 | AI5: ='4'!$H$70 -> 0 | AJ5: ='4'!$H$72 -> 339 | AK5: ='4'!$H$73 -> 1 | AL5: ='4'!$H$74 -> 106 | AM5: ='4'!$H$75 -> 732 | AN5: ='4'!$H$76 -> 323 | AO5: ='4'!$H$77 -> 225 | AP5: ='4'!$H$78 -> 1571 | AQ5: ='4'!$H$79 -> 797 | AR5: ='4'!$H$80 -> 1263 | AS5: ='4'!$H$81 -> 377 | AT5: ='4'!$H$82 -> 169 | AU5: ='4'!$H$83 -> 1673 | AV5: ='4'!$H$84 -> 1986 | AW5: ='4'!$H$92 -> 352 | AX5: ='4'!$H$93 -> 641 | AY5: ='4'!$H$95 -> 284 | AZ5: ='4'!$H$96 -> 124 | BA5: ='4'!$H$97 -> 110 | BB5: ='4'!$H$98 -> 289 | BC5: ='4'!$H$99 -> 41 | BD5: ='4'!$H$100 -> 23 | BE5: ='4'!$H$104 -> 0 | BF5: ='4'!$H$105 -> 28 | BG5: ='4'!$H$106 -> 23 | BH5: ='4'!$H$109 -> 215 | BI5: ='4'!$H$110 -> 258 | BJ5: ='4'!$H$111 -> 30 | BK5: ='4'!$H$114 -> 53 | BL5: ='4'!$H$115 -> 21 | BM5: ='4'!$H$116 -> 0 | BN5: ='4'!$H$118 -> 555 | BO5: ='4'!$H$119 -> 582 | BP5: ='4'!$H$120 -> 503 | BQ5: ='4'!$H$123 -> 1068.6 | BR5: ='4'!$H$124 -> 0 | BS5: ='4'!$H$125 -> 272 | BT5: ='4'!$H$126 -> 169.3 | BU5: ='4'!$H$127 -> 8 | BV5: ='4'!$H$128 -> 1809.95
A6: Mumbai | B6: =B5+1 -> 5 | C6: 2 | D6: 2021 | E6: ='5'!$H$35 -> 5175.33 | F6: ='5'!$H$36 -> 3118.55 | G6: ='5'!$H$37 -> 1472 | H6: ='5'!$H$38 -> 806.12 | I6: ='5'!$H$39 -> 4103 | J6: ='5'!$H$40 -> 0 | K6: ='5'!$H$41 -> 13993.48 | L6: ='5'!$H$42 -> 0 | M6: ='5'!$H$43 -> 9409.09 | N6: ='5'!$H$44 -> 0 | O6: ='5'!$H$45 -> -0.48 | P6: ='5'!$H$46 -> -0.49 | Q6: ='5'!$H$49 -> 8717.95 | R6: ='5'!$H$50 -> 5633.69 | S6: ='5'!$H$51 -> 5906.26 | T6: ='5'!$H$52 -> 9166.33 | U6: ='5'!$H$53 -> 16804.73 | V6: ='5'!$H$54 -> 177.36 | W6: ='5'!$H$55 -> 5934.42 | X6: ='5'!$H$56 -> 7.09 | Y6: ='5'!$H$57 -> 1933 | Z6: ='5'!$H$58 -> 820.09 | AA6: ='5'!$H$62 -> -0.189 | AB6: ='5'!$H$63 -> 73.47 | AC6: ='5'!$H$64 -> 2170.54 | AD6: ='5'!$H$65 -> 1875.89 | AE6: ='5'!$H$66 -> 1997.26 | AF6: ='5'!$H$67 -> 3464.47 | AG6: ='5'!$H$68 -> 1687.14 | AH6: ='5'!$H$69 -> 1536.29 | AI6: ='5'!$H$70 -> 0 | AJ6: ='5'!$H$72 -> 409 | AK6: ='5'!$H$73 -> 2 | AL6: ='5'!$H$74 -> 134 | AM6: ='5'!$H$75 -> 905 | AN6: ='5'!$H$76 -> 407 | AO6: ='5'!$H$77 -> 307 | AP6: ='5'!$H$78 -> 1970 | AQ6: ='5'!$H$79 -> 990 | AR6: ='5'!$H$80 -> 1573 | AS6: ='5'!$H$81 -> 477 | AT6: ='5'!$H$82 -> 191 | AU6: ='5'!$H$83 -> 2176 | AV6: ='5'!$H$84 -> 2453 | AW6: ='5'!$H$92 -> 462 | AX6: ='5'!$H$93 -> 823 | AY6: ='5'!$H$95 -> 339 | AZ6: ='5'!$H$96 -> 147 | BA6: ='5'!$H$97 -> 150 | BB6: ='5'!$H$98 -> 329 | BC6: ='5'!$H$99 -> 48 | BD6: ='5'!$H$100 -> 29 | BE6: ='5'!$H$104 -> 0 | BF6: ='5'!$H$105 -> 42 | BG6: ='5'!$H$106 -> 32 | BH6: ='5'!$H$109 -> 330 | BI6: ='5'!$H$110 -> 337 | BJ6: ='5'!$H$111 -> 30 | BK6: ='5'!$H$114 -> 74 | BL6: ='5'!$H$115 -> 32 | BM6: ='5'!$H$116 -> 0 | BN6: ='5'!$H$118 -> 706 | BO6: ='5'!$H$119 -> 713 | BP6: ='5'!$H$120 -> 697 | BQ6: ='5'!$H$123 -> 1337.6 | BR6: ='5'!$H$124 -> 0 | BS6: ='5'!$H$125 -> 349 | BT6: ='5'!$H$126 -> 199.3 | BU6: ='5'!$H$127 -> 13 | BV6: ='5'!$H$128 -> 2206.95
A7: Mumbai | B7: =B6+1 -> 6 | C7: 2 | D7: 2021 | E7: ='6'!$H$35 -> 5175.33 | F7: ='6'!$H$36 -> 3847.55 | G7: ='6'!$H$37 -> 1472 | H7: ='6'!$H$38 -> 806.12 | I7: ='6'!$H$39 -> 4103 | J7: ='6'!$H$40 -> 0 | K7: ='6'!$H$41 -> 13993.48 | L7: ='6'!$H$42 -> 0 | M7: ='6'!$H$43 -> 9409.09 | N7: ='6'!$H$44 -> 0 | O7: ='6'!$H$45 -> -0.48 | P7: ='6'!$H$46 -> -0.49 | Q7: ='6'!$H$49 -> 11365.95 | R7: ='6'!$H$50 -> 7113.69 | S7: ='6'!$H$51 -> 7415.26 | T7: ='6'!$H$52 -> 11166.33 | U7: ='6'!$H$53 -> 20957.73 | V7: ='6'!$H$54 -> 247.36 | W7: ='6'!$H$55 -> 9839.42 | X7: ='6'!$H$56 -> 7.09 | Y7: ='6'!$H$57 -> 4215 | Z7: ='6'!$H$58 -> 978.09 | AA7: ='6'!$H$62 -> -0.189 | AB7: ='6'!$H$63 -> 87.47 | AC7: ='6'!$H$64 -> 2575.54 | AD7: ='6'!$H$65 -> 2242.89 | AE7: ='6'!$H$66 -> 2390.26 | AF7: ='6'!$H$67 -> 4179.47 | AG7: ='6'!$H$68 -> 2042.14 | AH7: ='6'!$H$69 -> 1816.29 | AI7: ='6'!$H$70 -> 0 | AJ7: ='6'!$H$72 -> 476 | AK7: ='6'!$H$73 -> 2 | AL7: ='6'!$H$74 -> 164 | AM7: ='6'!$H$75 -> 1076 | AN7: ='6'!$H$76 -> 488 | AO7: ='6'!$H$77 -> 371 | AP7: ='6'!$H$78 -> 2438 | AQ7: ='6'!$H$79 -> 1193 | AR7: ='6'!$H$80 -> 1881 | AS7: ='6'!$H$81 -> 581 | AT7: ='6'!$H$82 -> 212 | AU7: ='6'!$H$83 -> 2661 | AV7: ='6'!$H$84 -> 2930 | AW7: ='6'!$H$92 -> 551 | AX7: ='6'!$H$93 -> 924 | AY7: ='6'!$H$95 -> 400 | AZ7: ='6'!$H$96 -> 181 | BA7: ='6'!$H$97 -> 181 | BB7: ='6'!$H$98 -> 401 | BC7: ='6'!$H$99 -> 57 | BD7: ='6'!$H$100 -> 38 | BE7: ='6'!$H$104 -> 0 | BF7: ='6'!$H$105 -> 48 | BG7: ='6'!$H$106 -> 38 | BH7: ='6'!$H$109 -> 370 | BI7: ='6'!$H$110 -> 382 | BJ7: ='6'!$H$111 -> 62 | BK7: ='6'!$H$114 -> 85 | BL7: ='6'!$H$115 -> 38 | BM7: ='6'!$H$116 -> 0 | BN7: ='6'!$H$118 -> 846 | BO7: ='6'!$H$119 -> 857 | BP7: ='6'!$H$120 -> 814 | BQ7: ='6'!$H$123 -> 1625.6 | BR7: ='6'!$H$124 -> 0 | BS7: ='6'!$H$125 -> 412 | BT7: ='6'!$H$126 -> 242.3 | BU7: ='6'!$H$127 -> 16 | BV7: ='6'!$H$128 -> 2623.95
A8: Mumbai | B8: =B7+1 -> 7 | C8: 2 | D8: 2021 | E8: ='7'!$H$35 -> 5175.33 | F8: ='7'!$H$36 -> 4425.36 | G8: ='7'!$H$37 -> 1472 | H8: ='7'!$H$38 -> 806.12 | I8: ='7'!$H$39 -> 4103 | J8: ='7'!$H$40 -> 0 | K8: ='7'!$H$41 -> 13993.48 | L8: ='7'!$H$42 -> 0 | M8: ='7'!$H$43 -> 9409.09 | N8: ='7'!$H$44 -> 0 | O8: ='7'!$H$45 -> -0.48 | P8: ='7'!$H$46 -> -0.49 | Q8: ='7'!$H$49 -> 13865.62 | R8: ='7'!$H$50 -> 8222.69 | S8: ='7'!$H$51 -> 8842.26 | T8: ='7'!$H$52 -> 13284.33 | U8: ='7'!$H$53 -> 25133.73 | V8: ='7'!$H$54 -> 318.36 | W8: ='7'!$H$55 -> 13335.4 | X8: ='7'!$H$56 -> 7.09 | Y8: ='7'!$H$57 -> 6534 | Z8: ='7'!$H$58 -> 1147.09 | AA8: ='7'!$H$62 -> -0.189 | AB8: ='7'!$H$63 -> 101.47 | AC8: ='7'!$H$64 -> 2950.14 | AD8: ='7'!$H$65 -> 2621.56 | AE8: ='7'!$H$66 -> 2799.26 | AF8: ='7'!$H$67 -> 4907.46 | AG8: ='7'!$H$68 -> 2372.14 | AH8: ='7'!$H$69 -> 2126.29 | AI8: ='7'!$H$70 -> 0 | AJ8: ='7'!$H$72 -> 558 | AK8: ='7'!$H$73 -> 2 | AL8: ='7'!$H$74 -> 188 | AM8: ='7'!$H$75 -> 1255 | AN8: ='7'!$H$76 -> 575 | AO8: ='7'!$H$77 -> 422 | AP8: ='7'!$H$78 -> 2896 | AQ8: ='7'!$H$79 -> 1387 | AR8: ='7'!$H$80 -> 2198 | AS8: ='7'!$H$81 -> 684 | AT8: ='7'!$H$82 -> 238 | AU8: ='7'!$H$83 -> 3142 | AV8: ='7'!$H$84 -> 3396 | AW8: ='7'!$H$92 -> 655 | AX8: ='7'!$H$93 -> 1131 | AY8: ='7'!$H$95 -> 457 | AZ8: ='7'!$H$96 -> 224 | BA8: ='7'!$H$97 -> 204 | BB8: ='7'!$H$98 -> 459 | BC8: ='7'!$H$99 -> 71 | BD8: ='7'!$H$100 -> 46 | BE8: ='7'!$H$104 -> 0 | BF8: ='7'!$H$105 -> 54 | BG8: ='7'!$H$106 -> 42 | BH8: ='7'!$H$109 -> 409 | BI8: ='7'!$H$110 -> 483 | BJ8: ='7'!$H$111 -> 62 | BK8: ='7'!$H$114 -> 101 | BL8: ='7'!$H$115 -> 45 | BM8: ='7'!$H$116 -> 0 | BN8: ='7'!$H$118 -> 1002 | BO8: ='7'!$H$119 -> 1002 | BP8: ='7'!$H$120 -> 954 | BQ8: ='7'!$H$123 -> 1921.6 | BR8: ='7'!$H$124 -> 1.4 | BS8: ='7'!$H$125 -> 472.97 | BT8: ='7'!$H$126 -> 282.3 | BU8: ='7'!$H$127 -> 18 | BV8: ='7'!$H$128 -> 3068.03
A9: Mumbai | B9: =B8+1 -> 8 | C9: 2 | D9: 2021 | E9: ='8'!$H$35 -> 6726.24 | F9: ='8'!$H$36 -> 5053.96 | G9: ='8'!$H$37 -> 2139.27 | H9: ='8'!$H$38 -> 2026.04 | I9: ='8'!$H$39 -> 5850.78 | J9: ='8'!$H$40 -> 0 | K9: ='8'!$H$41 -> 14637.35 | L9: ='8'!$H$42 -> 0 | M9: ='8'!$H$43 -> 10571.76 | N9: ='8'!$H$44 -> 0 | O9: ='8'!$H$45 -> -0.48 | P9: ='8'!$H$46 -> -0.49 | Q9: ='8'!$H$49 -> 14832.95 | R9: ='8'!$H$50 -> 9303.69 | S9: ='8'!$H$51 -> 9951.18 | T9: ='8'!$H$52 -> 14104.04 | U9: ='8'!$H$53 -> 27556.24 | V9: ='8'!$H$54 -> 378.36 | W9: ='8'!$H$55 -> 16549.42 | X9: ='8'!$H$56 -> 7.09 | Y9: ='8'!$H$57 -> 7711 | Z9: ='8'!$H$58 -> 1348.65 | AA9: ='8'!$H$62 -> -0.189 | AB9: ='8'!$H$63 -> 115.47 | AC9: ='8'!$H$64 -> 3368.54 | AD9: ='8'!$H$65 -> 3010.46 | AE9: ='8'!$H$66 -> 3192.26 | AF9: ='8'!$H$67 -> 5605 | AG9: ='8'!$H$68 -> 2716.14 | AH9: ='8'!$H$69 -> 2410.29 | AI9: ='8'!$H$70 -> 0 | AJ9: ='8'!$H$72 -> 625 | AK9: ='8'!$H$73 -> 2 | AL9: ='8'!$H$74 -> 211 | AM9: ='8'!$H$75 -> 1433 | AN9: ='8'!$H$76 -> 670 | AO9: ='8'!$H$77 -> 471 | AP9: ='8'!$H$78 -> 3309 | AQ9: ='8'!$H$79 -> 1557 | AR9: ='8'!$H$80 -> 2462.96 | AS9: ='8'!$H$81 -> 773 | AT9: ='8'!$H$82 -> 262.8 | AU9: ='8'!$H$83 -> 3626 | AV9: ='8'!$H$84 -> 3872 | AW9: ='8'!$H$92 -> 750 | AX9: ='8'!$H$93 -> 1338 | AY9: ='8'!$H$95 -> 528 | AZ9: ='8'!$H$96 -> 275 | BA9: ='8'!$H$97 -> 224 | BB9: ='8'!$H$98 -> 537 | BC9: ='8'!$H$99 -> 83 | BD9: ='8'!$H$100 -> 54 | BE9: ='8'!$H$104 -> 0 | BF9: ='8'!$H$105 -> 63 | BG9: ='8'!$H$106 -> 47 | BH9: ='8'!$H$109 -> 483 | BI9: ='8'!$H$110 -> 526 | BJ9: ='8'!$H$111 -> 62 | BK9: ='8'!$H$114 -> 117 | BL9: ='8'!$H$115 -> 52 | BM9: ='8'!$H$116 -> 0 | BN9: ='8'!$H$118 -> 1148 | BO9: ='8'!$H$119 -> 1164 | BP9: ='8'!$H$120 -> 1071 | BQ9: ='8'!$H$123 -> 2196.58 | BR9: ='8'!$H$124 -> 1.4 | BS9: ='8'!$H$125 -> 529.72 | BT9: ='8'!$H$126 -> 314.6 | BU9: ='8'!$H$127 -> 20 | BV9: ='8'!$H$128 -> 0
A10: Mumbai | B10: =B9+1 -> 9 | C10: 2 | D10: 2021 | E10: ='9'!$H$35 -> 9240.16 | F10: ='9'!$H$36 -> 5699.36 | G10: ='9'!$H$37 -> 3572.52 | H10: ='9'!$H$38 -> 3922.58 | I10: ='9'!$H$39 -> 9967 | J10: ='9'!$H$40 -> 0 | K10: ='9'!$H$41 -> 14637.35 | L10: ='9'!$H$42 -> 0 | M10: ='9'!$H$43 -> 13111.09 | N10: ='9'!$H$44 -> 0 | O10: ='9'!$H$45 -> -0.48 | P10: ='9'!$H$46 -> -0.49 | Q10: ='9'!$H$49 -> 14832.95 | R10: ='9'!$H$50 -> 10476.69 | S10: ='9'!$H$51 -> 9951.18 | T10: ='9'!$H$52 -> 14104.04 | U10: ='9'!$H$53 -> 27556.24 | V10: ='9'!$H$54 -> 448.2 | W10: ='9'!$H$55 -> 20085.42 | X10: ='9'!$H$56 -> 7.09 | Y10: ='9'!$H$57 -> 7711 | Z10: ='9'!$H$58 -> 1448.88 | AA10: ='9'!$H$62 -> -0.189 | AB10: ='9'!$H$63 -> 128.72 | AC10: ='9'!$H$64 -> 3774.54 | AD10: ='9'!$H$65 -> 3387.77 | AE10: ='9'!$H$66 -> 3570.26 | AF10: ='9'!$H$67 -> 6298.47 | AG10: ='9'!$H$68 -> 3059.14 | AH10: ='9'!$H$69 -> 2686.29 | AI10: ='9'!$H$70 -> 0 | AJ10: ='9'!$H$72 -> 675 | AK10: ='9'!$H$73 -> 2 | AL10: ='9'!$H$74 -> 235 | AM10: ='9'!$H$75 -> 1608 | AN10: ='9'!$H$76 -> 813 | AO10: ='9'!$H$77 -> 515 | AP10: ='9'!$H$78 -> 3721 | AQ10: ='9'!$H$79 -> 1747 | AR10: ='9'!$H$80 -> 2749 | AS10: ='9'!$H$81 -> 875.92 | AT10: ='9'!$H$82 -> 294.82 | AU10: ='9'!$H$83 -> 4039 | AV10: ='9'!$H$84 -> 4354 | AW10: ='9'!$H$92 -> 854 | AX10: ='9'!$H$93 -> 1444 | AY10: ='9'!$H$95 -> 590 | AZ10: ='9'!$H$96 -> 315 | BA10: ='9'!$H$97 -> 253 | BB10: ='9'!$H$98 -> 604 | BC10: ='9'!$H$99 -> 96 | BD10: ='9'!$H$100 -> 63 | BE10: ='9'!$H$104 -> 0 | BF10: ='9'!$H$105 -> 63 | BG10: ='9'!$H$106 -> 51 | BH10: ='9'!$H$109 -> 536 | BI10: ='9'!$H$110 -> 589 | BJ10: ='9'!$H$111 -> 99 | BK10: ='9'!$H$114 -> 132 | BL10: ='9'!$H$115 -> 59 | BM10: ='9'!$H$116 -> 0 | BN10: ='9'!$H$118 -> 1304 | BO10: ='9'!$H$119 -> 1317 | BP10: ='9'!$H$120 -> 1224 | BQ10: ='9'!$H$123 -> 2506.6 | BR10: ='9'!$H$124 -> 1.4 | BS10: ='9'!$H$125 -> 577.58 | BT10: ='9'!$H$126 -> 346.3 | BU10: ='9'!$H$127 -> 21.8 | BV10: ='9'!$H$128 -> 0
A11: Mumbai | B11: =B10+1 -> 10 | C11: 2 | D11: 2021 | E11: ='10'!$H$35 -> 11901.33 | F11: ='10'!$H$36 -> 6313.44 | G11: ='10'!$H$37 -> 5027.49 | H11: ='10'!$H$38 -> 5824.12 | I11: ='10'!$H$39 -> 14156.47 | J11: ='10'!$H$40 -> 0 | K11: ='10'!$H$41 -> 14637.35 | L11: ='10'!$H$42 -> 0 | M11: ='10'!$H$43 -> 15659.09 | N11: ='10'!$H$44 -> 0 | O11: ='10'!$H$45 -> -0.48 | P11: ='10'!$H$46 -> -0.49 | Q11: ='10'!$H$49 -> 14832.95 | R11: ='10'!$H$50 -> 11519.69 | S11: ='10'!$H$51 -> 9951.18 | T11: ='10'!$H$52 -> 14104.04 | U11: ='10'!$H$53 -> 27556.24 | V11: ='10'!$H$54 -> 520.36 | W11: ='10'!$H$55 -> 23952.82 | X11: ='10'!$H$56 -> 7.09 | Y11: ='10'!$H$57 -> 7711 | Z11: ='10'!$H$58 -> 1646.51 | AA11: ='10'!$H$62 -> -0.189 | AB11: ='10'!$H$63 -> 141.17 | AC11: ='10'!$H$64 -> 4215.25 | AD11: ='10'!$H$65 -> 3761.89 | AE11: ='10'!$H$66 -> 3944.26 | AF11: ='10'!$H$67 -> 7023.47 | AG11: ='10'!$H$68 -> 3404.14 | AH11: ='10'!$H$69 -> 2982.09 | AI11: ='10'!$H$70 -> 0 | AJ11: ='10'!$H$72 -> 719 | AK11: ='10'!$H$73 -> 2 | AL11: ='10'!$H$74 -> 250.21 | AM11: ='10'!$H$75 -> 1791.85 | AN11: ='10'!$H$76 -> 893.05 | AO11: ='10'!$H$77 -> 563 | AP11: ='10'!$H$78 -> 4154 | AQ11: ='10'!$H$79 -> 1932 | AR11: ='10'!$H$80 -> 3033.76 | AS11: ='10'!$H$81 -> 979 | AT11: ='10'!$H$82 -> 319.98 | AU11: ='10'!$H$83 -> 4301 | AV11: ='10'!$H$84 -> 4850 | AW11: ='10'!$H$92 -> 991 | AX11: ='10'!$H$93 -> 1599 | AY11: ='10'!$H$95 -> 667 | AZ11: ='10'!$H$96 -> 355 | BA11: ='10'!$H$97 -> 299 | BB11: ='10'!$H$98 -> 684 | BC11: ='10'!$H$99 -> 108 | BD11: ='10'!$H$100 -> 75 | BE11: ='10'!$H$104 -> 0 | BF11: ='10'!$H$105 -> 75 | BG11: ='10'!$H$106 -> 54 | BH11: ='10'!$H$109 -> 597 | BI11: ='10'!$H$110 -> 653 | BJ11: ='10'!$H$111 -> 105 | BK11: ='10'!$H$114 -> 146 | BL11: ='10'!$H$115 -> 72 | BM11: ='10'!$H$116 -> 0 | BN11: ='10'!$H$118 -> 1491 | BO11: ='10'!$H$119 -> 1504 | BP11: ='10'!$H$120 -> 1355 | BQ11: ='10'!$H$123 -> 2792.6 | BR11: ='10'!$H$124 -> 1.4 | BS11: ='10'!$H$125 -> 655.84 | BT11: ='10'!$H$126 -> 378.3 | BU11: ='10'!$H$127 -> 23 | BV11: ='10'!$H$128 -> 0
A12: Mumbai | B12: =B11+1 -> 11 | C12: 2 | D12: 2021 | E12: ='11'!$H$35 -> 14259.33 | F12: ='11'!$H$36 -> 7010.55 | G12: ='11'!$H$37 -> 6499.81 | H12: ='11'!$H$38 -> 7655.12 | I12: ='11'!$H$39 -> 18260 | J12: ='11'!$H$40 -> 0 | K12: ='11'!$H$41 -> 14637.35 | L12: ='11'!$H$42 -> 0 | M12: ='11'!$H$43 -> 18202.09 | N12: ='11'!$H$44 -> 0 | O12: ='11'!$H$45 -> -0.48 | P12: ='11'!$H$46 -> 0 | Q12: ='11'!$H$49 -> 14832.95 | R12: ='11'!$H$50 -> 11515.4 | S12: ='11'!$H$51 -> 9951.18 | T12: ='11'!$H$52 -> 14104.04 | U12: ='11'!$H$53 -> 27556.24 | V12: ='11'!$H$54 -> 518.91 | W12: ='11'!$H$55 -> 24137.02 | X12: ='11'!$H$56 -> 7.09 | Y12: ='11'!$H$57 -> 7711 | Z12: ='11'!$H$58 -> 1616.46 | AA12: ='11'!$H$62 -> -0.189 | AB12: ='11'!$H$63 -> 153.47 | AC12: ='11'!$H$64 -> 4609.54 | AD12: ='11'!$H$65 -> 4131.89 | AE12: ='11'!$H$66 -> 4325.26 | AF12: ='11'!$H$67 -> 7731.47 | AG12: ='11'!$H$68 -> 3726.14 | AH12: ='11'!$H$69 -> 3294.29 | AI12: ='11'!$H$70 -> 0 | AJ12: ='11'!$H$72 -> 769 | AK12: ='11'!$H$73 -> 3 | AL12: ='11'!$H$74 -> 265.33 | AM12: ='11'!$H$75 -> 1963.33 | AN12: ='11'!$H$76 -> 953.72 | AO12: ='11'!$H$77 -> 621 | AP12: ='11'!$H$78 -> 4588 | AQ12: ='11'!$H$79 -> 2118 | AR12: ='11'!$H$80 -> 3351.92 | AS12: ='11'!$H$81 -> 1101.52 | AT12: ='11'!$H$82 -> 343.46 | AU12: ='11'!$H$83 -> 4607 | AV12: ='11'!$H$84 -> 5297 | AW12: ='11'!$H$92 -> 1092 | AX12: ='11'!$H$93 -> 1733 | AY12: ='11'!$H$95 -> 738 | AZ12: ='11'!$H$96 -> 404 | BA12: ='11'!$H$97 -> 322 | BB12: ='11'!$H$98 -> 759 | BC12: ='11'!$H$99 -> 118 | BD12: ='11'!$H$100 -> 84 | BE12: ='11'!$H$104 -> 74 | BF12: ='11'!$H$105 -> 55 | BG12: ='11'!$H$106 -> 340 | BH12: ='11'!$H$109 -> 181 | BI12: ='11'!$H$110 -> 144 | BJ12: ='11'!$H$111 -> 445 | BK12: ='11'!$H$114 -> 12 | BL12: ='11'!$H$115 -> 90 | BM12: ='11'!$H$116 -> 200 | BN12: ='11'!$H$118 -> 175 | BO12: ='11'!$H$119 -> 245 | BP12: ='11'!$H$120 -> 222 | BQ12: ='11'!$H$123 -> 3095.46 | BR12: ='11'!$H$124 -> 1.4 | BS12: ='11'!$H$125 -> 720.86 | BT12: ='11'!$H$126 -> 417.1 | BU12: ='11'!$H$127 -> 23 | BV12: ='11'!$H$128 -> 0
A13: Mumbai | B13: =B12+1 -> 12 | C13: 2 | D13: 2021 | E13: ='12'!$H$35 -> 16666.28 | F13: ='12'!$H$36 -> 7622.3 | G13: ='12'!$H$37 -> 8004.01 | H13: ='12'!$H$38 -> 9646.06 | I13: ='12'!$H$39 -> 22323.9 | J13: ='12'!$H$40 -> -0.06 | K13: ='12'!$H$41 -> 14637.35 | L13: ='12'!$H$42 -> 0.099 | M13: ='12'!$H$43 -> 20602.12 | N13: ='12'!$H$44 -> 0 | O13: ='12'!$H$45 -> -0.48 | P13: ='12'!$H$46 -> 0 | Q13: ='12'!$H$49 -> 14833.08 | R13: ='12'!$H$50 -> 12561.44 | S13: ='12'!$H$51 -> 9951.18 | T13: ='12'!$H$52 -> 14104.04 | U13: ='12'!$H$53 -> 27556.24 | V13: ='12'!$H$54 -> 589.24 | W13: ='12'!$H$55 -> 29022.495 | X13: ='12'!$H$56 -> 7.09 | Y13: ='12'!$H$57 -> 7711 | Z13: ='12'!$H$58 -> 1796.54 | AA13: ='12'!$H$62 -> -0.189 | AB13: ='12'!$H$63 -> 161.34 | AC13: ='12'!$H$64 -> 5034.13 | AD13: ='12'!$H$65 -> 4508.09 | AE13: ='12'!$H$66 -> 4684.405 | AF13: ='12'!$H$67 -> 8397.18 | AG13: ='12'!$H$68 -> 4076 | AH13: ='12'!$H$69 -> 3600.84 | AI13: ='12'!$H$70 -> 0 | AJ13: ='12'!$H$72 -> 869 | AK13: ='12'!$H$73 -> 6 | AL13: ='12'!$H$74 -> 280.11 | AM13: ='12'!$H$75 -> 2145.78 | AN13: ='12'!$H$76 -> 1034.93 | AO13: ='12'!$H$77 -> 675 | AP13: ='12'!$H$78 -> 4956 | AQ13: ='12'!$H$79 -> 2292 | AR13: ='12'!$H$80 -> 3647.44 | AS13: ='12'!$H$81 -> 1205.44 | AT13: ='12'!$H$82 -> 366.69 | AU13: ='12'!$H$83 -> 4910 | AV13: ='12'!$H$84 -> 5645 | AW13: ='12'!$H$92 -> 1221 | AX13: ='12'!$H$93 -> 1850 | AY13: ='12'!$H$95 -> 824 | AZ13: ='12'!$H$96 -> 442 | BA13: ='12'!$H$97 -> 349 | BB13: ='12'!$H$98 -> 842 | BC13: ='12'!$H$99 -> 128 | BD13: ='12'!$H$100 -> 91 | BE13: ='12'!$H$104 -> 74 | BF13: ='12'!$H$105 -> 57 | BG13: ='12'!$H$106 -> 346 | BH13: ='12'!$H$109 -> 140 | BI13: ='12'!$H$110 -> 104 | BJ13: ='12'!$H$111 -> 433 | BK13: ='12'!$H$114 -> 14 | BL13: ='12'!$H$115 -> 95 | BM13: ='12'!$H$116 -> 200 | BN13: ='12'!$H$118 -> 203 | BO13: ='12'!$H$119 -> 251 | BP13: ='12'!$H$120 -> 129 | BQ13: ='12'!$H$123 -> 3369.48 | BR13: ='12'!$H$124 -> 1.4 | BS13: ='12'!$H$125 -> 799 | BT13: ='12'!$H$126 -> 454.8 | BU13: ='12'!$H$127 -> 26.4 | BV13: ='12'!$H$128 -> 5267.688
A14: Mumbai | B14: =B13+1 -> 13 | C14: 2 | D14: 2021 | E14: ='13'!$H$35 -> 19370 | F14: ='13'!$H$36 -> 8307.88 | G14: ='13'!$H$37 -> 9603.93 | H14: ='13'!$H$38 -> 11965.98 | I14: ='13'!$H$39 -> 26707.7 | J14: ='13'!$H$40 -> -0.06 | K14: ='13'!$H$41 -> 14637.35 | L14: ='13'!$H$42 -> 0.099 | M14: ='13'!$H$43 -> 22977.28 | N14: ='13'!$H$44 -> 0 | O14: ='13'!$H$45 -> -0.48 | P14: ='13'!$H$46 -> 0 | Q14: ='13'!$H$49 -> 14833.08 | R14: ='13'!$H$50 -> 13693.6 | S14: ='13'!$H$51 -> 9951.18 | T14: ='13'!$H$52 -> 14104.04 | U14: ='13'!$H$53 -> 27556.24 | V14: ='13'!$H$54 -> 660.68 | W14: ='13'!$H$55 -> 33434.955 | X14: ='13'!$H$56 -> 7.09 | Y14: ='13'!$H$57 -> 7711.33 | Z14: ='13'!$H$58 -> 1990.43 | AA14: ='13'!$H$62 -> -0.009 | AB14: ='13'!$H$63 -> 174.72 | AC14: ='13'!$H$64 -> 5434.98 | AD14: ='13'!$H$65 -> 4900.73 | AE14: ='13'!$H$66 -> 5084.363 | AF14: ='13'!$H$67 -> 9111.8 | AG14: ='13'!$H$68 -> 4442.91 | AH14: ='13'!$H$69 -> 3920.33 | AI14: ='13'!$H$70 -> 0 | AJ14: ='13'!$H$72 -> 956 | AK14: ='13'!$H$73 -> 9 | AL14: ='13'!$H$74 -> 304.045 | AM14: ='13'!$H$75 -> 2336.08 | AN14: ='13'!$H$76 -> 1116.03 | AO14: ='13'!$H$77 -> 730 | AP14: ='13'!$H$78 -> 5372 | AQ14: ='13'!$H$79 -> 2507 | AR14: ='13'!$H$80 -> 3961.68 | AS14: ='13'!$H$81 -> 1333.12 | AT14: ='13'!$H$82 -> 394.02 | AU14: ='13'!$H$83 -> 5471 | AV14: ='13'!$H$84 -> 6157 | AW14: ='13'!$H$92 -> 1370 | AX14: ='13'!$H$93 -> 2099 | AY14: ='13'!$H$95 -> 912 | AZ14: ='13'!$H$96 -> 485 | BA14: ='13'!$H$97 -> 395 | BB14: ='13'!$H$98 -> 905 | BC14: ='13'!$H$99 -> 144 | BD14: ='13'!$H$100 -> 105 | BE14: ='13'!$H$104 -> 74 | BF14: ='13'!$H$105 -> 59 | BG14: ='13'!$H$106 -> 340 | BH14: ='13'!$H$109 -> 136 | BI14: ='13'!$H$110 -> 131 | BJ14: ='13'!$H$111 -> 446 | BK14: ='13'!$H$114 -> 20 | BL14: ='13'!$H$115 -> 93 | BM14: ='13'!$H$116 -> 200 | BN14: ='13'!$H$118 -> 224 | BO14: ='13'!$H$119 -> 290 | BP14: ='13'!$H$120 -> 165 | BQ14: ='13'!$H$123 -> 3663 | BR14: ='13'!$H$124 -> 1.4 | BS14: ='13'!$H$125 -> 898.25 | BT14: ='13'!$H$126 -> 503.6 | BU14: ='13'!$H$127 -> 31.3 | BV14: ='13'!$H$128 -> 0
A15: Mumbai | B15: =B14+1 -> 14 | C15: 2 | D15: 2021 | E15: ='14'!$H$35 -> 22338.2 | F15: ='14'!$H$36 -> 9172.5 | G15: ='14'!$H$37 -> 11184.16 | H15: ='14'!$H$38 -> 14407.04 | I15: ='14'!$H$39 -> 31362.84 | J15: ='14'!$H$40 -> -0.06 | K15: ='14'!$H$41 -> 14637.35 | L15: ='14'!$H$42 -> 0.099 | M15: ='14'!$H$43 -> 25337.36 | N15: ='14'!$H$44 -> 0 | O15: ='14'!$H$45 -> -0.48 | P15: ='14'!$H$46 -> 0 | Q15: ='14'!$H$49 -> 14833.08 | R15: ='14'!$H$50 -> 15062.88 | S15: ='14'!$H$51 -> 9951.18 | T15: ='14'!$H$52 -> 14104.04 | U15: ='14'!$H$53 -> 27556.24 | V15: ='14'!$H$54 -> 732.04 | W15: ='14'!$H$55 -> 39073.71 | X15: ='14'!$H$56 -> 7.09 | Y15: ='14'!$H$57 -> 7711.33 | Z15: ='14'!$H$58 -> 2215.8 | AA15: ='14'!$H$62 -> -0.009 | AB15: ='14'!$H$63 -> 187.95 | AC15: ='14'!$H$64 -> 5826.24 | AD15: ='14'!$H$65 -> 5304.82 | AE15: ='14'!$H$66 -> 5487.2 | AF15: ='14'!$H$67 -> 9850.16 | AG15: ='14'!$H$68 -> 4800.677 | AH15: ='14'!$H$69 -> 4232.68 | AI15: ='14'!$H$70 -> 0 | AJ15: ='14'!$H$72 -> 972 | AK15: ='14'!$H$73 -> 957 | AL15: ='14'!$H$74 -> 365.54 | AM15: ='14'!$H$75 -> 2543.76 | AN15: ='14'!$H$76 -> 2426.59 | AO15: ='14'!$H$77 -> 784 | AP15: ='14'!$H$78 -> 5826 | AQ15: ='14'!$H$79 -> 5564 | AR15: ='14'!$H$80 -> 2893.88 | AS15: ='14'!$H$81 -> 1468.32 | AT15: ='14'!$H$82 -> 420.95 | AU15: ='14'!$H$83 -> 5961 | AV15: ='14'!$H$84 -> 6655 | AW15: ='14'!$H$92 -> 1536 | AX15: ='14'!$H$93 -> 2273 | AY15: ='14'!$H$95 -> 1033 | AZ15: ='14'!$H$96 -> 532 | BA15: ='14'!$H$97 -> 441 | BB15: ='14'!$H$98 -> 976 | BC15: ='14'!$H$99 -> 163 | BD15: ='14'!$H$100 -> 129 | BE15: ='14'!$H$104 -> 161 | BF15: ='14'!$H$105 -> 59 | BG15: ='14'!$H$106 -> 339 | BH15: ='14'!$H$109 -> 136 | BI15: ='14'!$H$110 -> 87 | BJ15: ='14'!$H$111 -> 433 | BK15: ='14'!$H$114 -> 22 | BL15: ='14'!$H$115 -> 107 | BM15: ='14'!$H$116 -> 200 | BN15: ='14'!$H$118 -> 240 | BO15: ='14'!$H$119 -> 340 | BP15: ='14'!$H$120 -> 108 | BQ15: ='14'!$H$123 -> 3970.53 | BR15: ='14'!$H$124 -> 1.4 | BS15: ='14'!$H$125 -> 1010.59 | BT15: ='14'!$H$126 -> 555.7 | BU15: ='14'!$H$127 -> 39.8 | BV15: ='14'!$H$128 -> 0
A16: Mumbai | B16: =B15+1 -> 15 | C16: 2 | D16: 2021 | E16: ='15'!$H$35 -> 25257.96 | F16: ='15'!$H$36 -> 10114.02 | G16: ='15'!$H$37 -> 12764.25 | H16: ='15'!$H$38 -> 16875.94 | I16: ='15'!$H$39 -> 36017.43 | J16: ='15'!$H$40 -> -0.06 | K16: ='15'!$H$41 -> 14637.35 | L16: ='15'!$H$42 -> 0 | M16: ='15'!$H$43 -> 27683.52 | N16: ='15'!$H$44 -> 0 | O16: ='15'!$H$45 -> -0.48 | P16: ='15'!$H$46 -> 0 | Q16: ='15'!$H$49 -> 14833.08 | R16: ='15'!$H$50 -> 17052.88 | S16: ='15'!$H$51 -> 9951.18 | T16: ='15'!$H$52 -> 14104.04 | U16: ='15'!$H$53 -> 27556.24 | V16: ='15'!$H$54 -> 801.02 | W16: ='15'!$H$55 -> 44606.03 | X16: ='15'!$H$56 -> 57.84 | Y16: ='15'!$H$57 -> 7711.33 | Z16: ='15'!$H$58 -> 2502.13 | AA16: ='15'!$H$62 -> -0.009 | AB16: ='15'!$H$63 -> 200.17 | AC16: ='15'!$H$64 -> 6253.12 | AD16: ='15'!$H$65 -> 5709.24 | AE16: ='15'!$H$66 -> 5887.89 | AF16: ='15'!$H$67 -> 10564.64 | AG16: ='15'!$H$68 -> 5138.52 | AH16: ='15'!$H$69 -> 4538.5 | AI16: ='15'!$H$70 -> 0 | AJ16: ='15'!$H$72 -> 1065 | AK16: ='15'!$H$73 -> 958 | AL16: ='15'!$H$74 -> 428.92 | AM16: ='15'!$H$75 -> 2753.12 | AN16: ='15'!$H$76 -> 2505.6 | AO16: ='15'!$H$77 -> 838 | AP16: ='15'!$H$78 -> 6227 | AQ16: ='15'!$H$79 -> 5775 | AR16: ='15'!$H$80 -> 3306.84 | AS16: ='15'!$H$81 -> 1608.04 | AT16: ='15'!$H$82 -> 449.01 | AU16: ='15'!$H$83 -> 6499 | AV16: ='15'!$H$84 -> 7191 | AW16: ='15'!$H$92 -> 1728 | AX16: ='15'!$H$93 -> 2467 | AY16: ='15'!$H$95 -> 1164 | AZ16: ='15'!$H$96 -> 557 | BA16: ='15'!$H$97 -> 476 | BB16: ='15'!$H$98 -> 1052 | BC16: ='15'!$H$99 -> 193 | BD16: ='15'!$H$100 -> 152 | BE16: ='15'!$H$104 -> 74 | BF16: ='15'!$H$105 -> 65 | BG16: ='15'!$H$106 -> 345 | BH16: ='15'!$H$109 -> 159 | BI16: ='15'!$H$110 -> 131 | BJ16: ='15'!$H$111 -> 446 | BK16: ='15'!$H$114 -> 35 | BL16: ='15'!$H$115 -> 100 | BM16: ='15'!$H$116 -> 200 | BN16: ='15'!$H$118 -> 267 | BO16: ='15'!$H$119 -> 327 | BP16: ='15'!$H$120 -> 188 | BQ16: ='15'!$H$123 -> 4246.94 | BR16: ='15'!$H$124 -> 1.4 | BS16: ='15'!$H$125 -> 1145.94 | BT16: ='15'!$H$126 -> 597.2 | BU16: ='15'!$H$127 -> 45.3 | BV16: ='15'!$H$128 -> 0
A17: Mumbai | B17: =B16+1 -> 16 | C17: 2 | D17: 2021 | E17: ='16'!$H$35 -> 28296.48 | F17: ='16'!$H$36 -> 11071.3 | G17: ='16'!$H$37 -> 14281.36 | H17: ='16'!$H$38 -> 19109.59 | I17: ='16'!$H$39 -> 40245.55 | J17: ='16'!$H$40 -> -0.06 | K17: ='16'!$H$41 -> 14637.35 | L17: ='16'!$H$42 -> 0 | M17: ='16'!$H$43 -> 30044.88 | N17: ='16'!$H$44 -> 0 | O17: ='16'!$H$45 -> -0.48 | P17: ='16'!$H$46 -> 0 | Q17: ='16'!$H$49 -> 14833.08 | R17: ='16'!$H$50 -> 18307.88 | S17: ='16'!$H$51 -> 9951.18 | T17: ='16'!$H$52 -> 14104.04 | U17: ='16'!$H$53 -> 27556.24 | V17: ='16'!$H$54 -> 870.8 | W17: ='16'!$H$55 -> 49308.69 | X17: ='16'!$H$56 -> 64.2 | Y17: ='16'!$H$57 -> 7711.33 | Z17: ='16'!$H$58 -> 2712.66 | AA17: ='16'!$H$62 -> -0.009 | AB17: ='16'!$H$63 -> 212.1 | AC17: ='16'!$H$64 -> 6685.39 | AD17: ='16'!$H$65 -> 6110.81 | AE17: ='16'!$H$66 -> 6297.65 | AF17: ='16'!$H$67 -> 11242.72 | AG17: ='16'!$H$68 -> 5453.32 | AH17: ='16'!$H$69 -> 4840.85 | AI17: ='16'!$H$70 -> 0 | AJ17: ='16'!$H$72 -> 1161 | AK17: ='16'!$H$73 -> 959 | AL17: ='16'!$H$74 -> 478.44 | AM17: ='16'!$H$75 -> 2955.73 | AN17: ='16'!$H$76 -> 2578.2 | AO17: ='16'!$H$77 -> 892 | AP17: ='16'!$H$78 -> 6610 | AQ17: ='16'!$H$79 -> 5987 | AR17: ='16'!$H$80 -> 3698.32 | AS17: ='16'!$H$81 -> 1729 | AT17: ='16'!$H$82 -> 475.44 | AU17: ='16'!$H$83 -> 6996 | AV17: ='16'!$H$84 -> 7850 | AW17: ='16'!$H$92 -> 1860 | AX17: ='16'!$H$93 -> 2621 | AY17: ='16'!$H$95 -> 1261 | AZ17: ='16'!$H$96 -> 575 | BA17: ='16'!$H$97 -> 500 | BB17: ='16'!$H$98 -> 1108 | BC17: ='16'!$H$99 -> 210 | BD17: ='16'!$H$100 -> 158 | BE17: ='16'!$H$104 -> 74 | BF17: ='16'!$H$105 -> 60 | BG17: ='16'!$H$106 -> 340 | BH17: ='16'!$H$109 -> 136 | BI17: ='16'!$H$110 -> 103 | BJ17: ='16'!$H$111 -> 433 | BK17: ='16'!$H$114 -> 21 | BL17: ='16'!$H$115 -> 100 | BM17: ='16'!$H$116 -> 200 | BN17: ='16'!$H$118 -> 205 | BO17: ='16'!$H$119 -> 245 | BP17: ='16'!$H$120 -> 124 | BQ17: ='16'!$H$123 -> 4521.38 | BR17: ='16'!$H$124 -> 1.4 | BS17: ='16'!$H$125 -> 1233.88 | BT17: ='16'!$H$126 -> 622 | BU17: ='16'!$H$127 -> 47.4 | BV17: ='16'!$H$128 -> 623.29
A18: Mumbai | B18: =B17+1 -> 17 | C18: 2 | D18: 2021 | E18: ='17'!$H$35 -> 31008.12 | F18: ='17'!$H$36 -> 11734.3 | G18: ='17'!$H$37 -> 15757.98 | H18: ='17'!$H$38 -> 21110.98 | I18: ='17'!$H$39 -> 44433.18 | J18: ='17'!$H$40 -> -0.06 | K18: ='17'!$H$41 -> 17238.37 | L18: ='17'!$H$42 -> 0 | M18: ='17'!$H$43 -> 32379.68 | N18: ='17'!$H$44 -> 0 | O18: ='17'!$H$45 -> -0.48 | P18: ='17'!$H$46 -> 0 | Q18: ='17'!$H$49 -> 14833.08 | R18: ='17'!$H$50 -> 19373.16 | S18: ='17'!$H$51 -> 9951.18 | T18: ='17'!$H$52 -> 14104.04 | U18: ='17'!$H$53 -> 27556.24 | V18: ='17'!$H$54 -> 940.57 | W18: ='17'!$H$55 -> 51230.44 | X18: ='17'!$H$56 -> 70.6 | Y18: ='17'!$H$57 -> 7711.33 | Z18: ='17'!$H$58 -> 2913.77 | AA18: ='17'!$H$62 -> -0.009 | AB18: ='17'!$H$63 -> 225.82 | AC18: ='17'!$H$64 -> 7115.32 | AD18: ='17'!$H$65 -> 6514.7 | AE18: ='17'!$H$66 -> 6692.6 | AF18: ='17'!$H$67 -> 11921.36 | AG18: ='17'!$H$68 -> 5792.31 | AH18: ='17'!$H$69 -> 5148.54 | AI18: ='17'!$H$70 -> 0 | AJ18: ='17'!$H$72 -> 1232 | AK18: ='17'!$H$73 -> 959 | AL18: ='17'!$H$74 -> 530.86 | AM18: ='17'!$H$75 -> 3145.95 | AN18: ='17'!$H$76 -> 2655.7 | AO18: ='17'!$H$77 -> 946 | AP18: ='17'!$H$78 -> 6972 | AQ18: ='17'!$H$79 -> 6179 | AR18: ='17'!$H$80 -> 4040.28 | AS18: ='17'!$H$81 -> 1820.16 | AT18: ='17'!$H$82 -> 504.32 | AU18: ='17'!$H$83 -> 7446 | AV18: ='17'!$H$84 -> 8332 | AW18: ='17'!$H$92 -> 1944 | AX18: ='17'!$H$93 -> 2755 | AY18: ='17'!$H$95 -> 1333 | AZ18: ='17'!$H$96 -> 590 | BA18: ='17'!$H$97 -> 520 | BB18: ='17'!$H$98 -> 1143 | BC18: ='17'!$H$99 -> 224 | BD18: ='17'!$H$100 -> 164 | BE18: ='17'!$H$104 -> 74 | BF18: ='17'!$H$105 -> 57 | BG18: ='17'!$H$106 -> 339 | BH18: ='17'!$H$109 -> 116 | BI18: ='17'!$H$110 -> 82 | BJ18: ='17'!$H$111 -> 455 | BK18: ='17'!$H$114 -> 17 | BL18: ='17'!$H$115 -> 93 | BM18: ='17'!$H$116 -> 200 | BN18: ='17'!$H$118 -> 158 | BO18: ='17'!$H$119 -> 210 | BP18: ='17'!$H$120 -> 105 | BQ18: ='17'!$H$123 -> 4780.53 | BR18: ='17'!$H$124 -> 1.4 | BS18: ='17'!$H$125 -> 1301.48 | BT18: ='17'!$H$126 -> 638.1 | BU18: ='17'!$H$127 -> 52.1 | BV18: ='17'!$H$128 -> 1206.25
A19: Mumbai | B19: =B18+1 -> 18 | C19: 2 | D19: 2021 | E19: ='18'!$H$35 -> 33748.28 | F19: ='18'!$H$36 -> 12618.1 | G19: ='18'!$H$37 -> 17226.91 | H19: ='18'!$H$38 -> 23161.52 | I19: ='18'!$H$39 -> 48714.36 | J19: ='18'!$H$40 -> -0.06 | K19: ='18'!$H$41 -> 19259.85 | L19: ='18'!$H$42 -> 202.85 | M19: ='18'!$H$43 -> 34713.84 | N19: ='18'!$H$44 -> 0 | O19: ='18'!$H$45 -> -0.48 | P19: ='18'!$H$46 -> -0.05 | Q19: ='18'!$H$49 -> 14833.08 | R19: ='18'!$H$50 -> 20501.72 | S19: ='18'!$H$51 -> 9951.18 | T19: ='18'!$H$52 -> 14104.04 | U19: ='18'!$H$53 -> 27556.24 | V19: ='18'!$H$54 -> 1010.6 | W19: ='18'!$H$55 -> 51282.42 | X19: ='18'!$H$56 -> 2381.16 | Y19: ='18'!$H$57 -> 7711.33 | Z19: ='18'!$H$58 -> 3128.15 | AA19: ='18'!$H$62 -> -0.009 | AB19: ='18'!$H$63 -> 239.19 | AC19: ='18'!$H$64 -> 7544.52 | AD19: ='18'!$H$65 -> 6911.99 | AE19: ='18'!$H$66 -> 7091.54 | AF19: ='18'!$H$67 -> 12586.47 | AG19: ='18'!$H$68 -> 6182.44 | AH19: ='18'!$H$69 -> 5464.56 | AI19: ='18'!$H$70 -> 0 | AJ19: ='18'!$H$72 -> 1297 | AK19: ='18'!$H$73 -> 959 | AL19: ='18'!$H$74 -> 582.88 | AM19: ='18'!$H$75 -> 3346.01 | AN19: ='18'!$H$76 -> 2743.14 | AO19: ='18'!$H$77 -> 997 | AP19: ='18'!$H$78 -> 7342 | AQ19: ='18'!$H$79 -> 6355 | AR19: ='18'!$H$80 -> 4377.32 | AS19: ='18'!$H$81 -> 1915 | AT19: ='18'!$H$82 -> 525 | AU19: ='18'!$H$83 -> 7945 | AV19: ='18'!$H$84 -> 8814 | AW19: ='18'!$H$92 -> 2025 | AX19: ='18'!$H$93 -> 2892 | AY19: ='18'!$H$95 -> 1407 | AZ19: ='18'!$H$96 -> 606 | BA19: ='18'!$H$97 -> 537 | BB19: ='18'!$H$98 -> 1221 | BC19: ='18'!$H$99 -> 246 | BD19: ='18'!$H$100 -> 169 | BE19: ='18'!$H$104 -> 74 | BF19: ='18'!$H$105 -> 56 | BG19: ='18'!$H$106 -> 344 | BH19: ='18'!$H$109 -> 136 | BI19: ='18'!$H$110 -> 137 | BJ19: ='18'!$H$111 -> 440 | BK19: ='18'!$H$114 -> 25 | BL19: ='18'!$H$115 -> 92 | BM19: ='18'!$H$116 -> 200 | BN19: ='18'!$H$118 -> 151 | BO19: ='18'!$H$119 -> 217 | BP19: ='18'!$H$120 -> 165 | BQ19: ='18'!$H$123 -> 5040.94 | BR19: ='18'!$H$124 -> 1.4 | BS19: ='18'!$H$125 -> 1378.75 | BT19: ='18'!$H$126 -> 663.8 | BU19: ='18'!$H$127 -> 53.2 | BV19: ='18'!$H$128 -> 1681.91
A20: Mumbai | B20: =B19+1 -> 19 | C20: 2 | D20: 2021 | E20: ='19'!$H$35 -> 36429.33 | F20: ='19'!$H$36 -> 13282.55 | G20: ='19'!$H$37 -> 18705 | H20: ='19'!$H$38 -> 25078.12 | I20: ='19'!$H$39 -> 52877 | J20: ='19'!$H$40 -> -0.06 | K20: ='19'!$H$41 -> 19259.48 | L20: ='19'!$H$42 -> 203 | M20: ='19'!$H$43 -> 37023.09 | N20: ='19'!$H$44 -> 0 | O20: ='19'!$H$45 -> -0.48 | P20: ='19'!$H$46 -> -0.05 | Q20: ='19'!$H$49 -> 14832.95 | R20: ='19'!$H$50 -> 21937.69 | S20: ='19'!$H$51 -> 9951.26 | T20: ='19'!$H$52 -> 14104.33 | U20: ='19'!$H$53 -> 27556.73 | V20: ='19'!$H$54 -> 1079.2 | W20: ='19'!$H$55 -> 51282.02 | X20: ='19'!$H$56 -> 6515.09 | Y20: ='19'!$H$57 -> 7711 | Z20: ='19'!$H$58 -> 3347.46 | AA20: ='19'!$H$62 -> 0.011 | AB20: ='19'!$H$63 -> 252.47 | AC20: ='19'!$H$64 -> 7956.54 | AD20: ='19'!$H$65 -> 7314.89 | AE20: ='19'!$H$66 -> 7497.26 | AF20: ='19'!$H$67 -> 13225.47 | AG20: ='19'!$H$68 -> 6525.14 | AH20: ='19'!$H$69 -> 5776.29 | AI20: ='19'!$H$70 -> 0 | AJ20: ='19'!$H$72 -> 1368 | AK20: ='19'!$H$73 -> 959 | AL20: ='19'!$H$74 -> 612.1 | AM20: ='19'!$H$75 -> 3506.4 | AN20: ='19'!$H$76 -> 2812.2 | AO20: ='19'!$H$77 -> 1049 | AP20: ='19'!$H$78 -> 7675 | AQ20: ='19'!$H$79 -> 6533 | AR20: ='19'!$H$80 -> 4721.32 | AS20: ='19'!$H$81 -> 2023 | AT20: ='19'!$H$82 -> 550 | AU20: ='19'!$H$83 -> 8300 | AV20: ='19'!$H$84 -> 9313 | AW20: ='19'!$H$92 -> 2120 | AX20: ='19'!$H$93 -> 3034 | AY20: ='19'!$H$95 -> 1486 | AZ20: ='19'!$H$96 -> 615 | BA20: ='19'!$H$97 -> 561 | BB20: ='19'!$H$98 -> 1284 | BC20: ='19'!$H$99 -> 269 | BD20: ='19'!$H$100 -> 175 | BE20: ='19'!$H$104 -> 74 | BF20: ='19'!$H$105 -> 63 | BG20: ='19'!$H$106 -> 350 | BH20: ='19'!$H$109 -> 176 | BI20: ='19'!$H$110 -> 168 | BJ20: ='19'!$H$111 -> 440 | BK20: ='19'!$H$114 -> 51 | BL20: ='19'!$H$115 -> 94 | BM20: ='19'!$H$116 -> 200 | BN20: ='19'!$H$118 -> 296 | BO20: ='19'!$H$119 -> 358 | BP20: ='19'!$H$120 -> 236 | BQ20: ='19'!$H$123 -> 5282.6 | BR20: ='19'!$H$124 -> 1 | BS20: ='19'!$H$125 -> 1468 | BT20: ='19'!$H$126 -> 687.3 | BU20: ='19'!$H$127 -> 55 | BV20: ='19'!$H$128 -> 2207.51
A21: Mumbai | B21: =B20+1 -> 20 | C21: 2 | D21: 2021 | E21: ='20'!$H$35 -> 39283.33 | F21: ='20'!$H$36 -> 13907.55 | G21: ='20'!$H$37 -> 20216 | H21: ='20'!$H$38 -> 27043.12 | I21: ='20'!$H$39 -> 57266 | J21: ='20'!$H$40 -> -0.06 | K21: ='20'!$H$41 -> 19259.48 | L21: ='20'!$H$42 -> 203 | M21: ='20'!$H$43 -> 39325.09 | N21: ='20'!$H$44 -> 0 | O21: ='20'!$H$45 -> -0.48 | P21: ='20'!$H$46 -> -0.05 | Q21: ='20'!$H$49 -> 14832.95 | R21: ='20'!$H$50 -> 23093.69 | S21: ='20'!$H$51 -> 9951.26 | T21: ='20'!$H$52 -> 14104.33 | U21: ='20'!$H$53 -> 27556.73 | V21: ='20'!$H$54 -> 1149.2 | W21: ='20'!$H$55 -> 51282.02 | X21: ='20'!$H$56 -> 10566.09 | Y21: ='20'!$H$57 -> 7711 | Z21: ='20'!$H$58 -> 3598.46 | AA21: ='20'!$H$62 -> 0.011 | AB21: ='20'!$H$63 -> 264.47 | AC21: ='20'!$H$64 -> 8356.54 | AD21: ='20'!$H$65 -> 7718.89 | AE21: ='20'!$H$66 -> 7908.26 | AF21: ='20'!$H$67 -> 13920.47 | AG21: ='20'!$H$68 -> 7875.14 | AH21: ='20'!$H$69 -> 6094.29 | AI21: ='20'!$H$70 -> 0 | AJ21: ='20'!$H$72 -> 1434 | AK21: ='20'!$H$73 -> 960 | AL21: ='20'!$H$74 -> 632.1 | AM21: ='20'!$H$75 -> 3684.4 | AN21: ='20'!$H$76 -> 2890.2 | AO21: ='20'!$H$77 -> 1097 | AP21: ='20'!$H$78 -> 8077 | AQ21: ='20'!$H$79 -> 6724 | AR21: ='20'!$H$80 -> 5077.32 | AS21: ='20'!$H$81 -> 2113 | AT21: ='20'!$H$82 -> 576 | AU21: ='20'!$H$83 -> 8699 | AV21: ='20'!$H$84 -> 9875 | AW21: ='20'!$H$92 -> 2227 | AX21: ='20'!$H$93 -> 3167 | AY21: ='20'!$H$95 -> 1572 | AZ21: ='20'!$H$96 -> 637 | BA21: ='20'!$H$97 -> 593 | BB21: ='20'!$H$98 -> 1352 | BC21: ='20'!$H$99 -> 290 | BD21: ='20'!$H$100 -> 183 | BE21: ='20'!$H$104 -> 74 | BF21: ='20'!$H$105 -> 76 | BG21: ='20'!$H$106 -> 358 | BH21: ='20'!$H$109 -> 235 | BI21: ='20'!$H$110 -> 243 | BJ21: ='20'!$H$111 -> 460 | BK21: ='20'!$H$114 -> 77 | BL21: ='20'!$H$115 -> 102 | BM21: ='20'!$H$116 -> 200 | BN21: ='20'!$H$118 -> 454 | BO21: ='20'!$H$119 -> 527 | BP21: ='20'!$H$120 -> 390 | BQ21: ='20'!$H$123 -> 5582.6 | BR21: ='20'!$H$124 -> 1 | BS21: ='20'!$H$125 -> 1554 | BT21: ='20'!$H$126 -> 717.3 | BU21: ='20'!$H$127 -> 58 | BV21: ='20'!$H$128 -> 2874.51
A22: Mumbai | B22: =B21+1 -> 21 | C22: 2 | D22: 2021 | E22: ='21'!$H$35 -> 42318.33 | F22: ='21'!$H$36 -> 14683.55 | G22: ='21'!$H$37 -> 21738 | H22: ='21'!$H$38 -> 29069.12 | I22: ='21'!$H$39 -> 61480 | J22: ='21'!$H$40 -> -0.06 | K22: ='21'!$H$41 -> 19259.48 | L22: ='21'!$H$42 -> 203 | M22: ='21'!$H$43 -> 41679.09 | N22: ='21'!$H$44 -> 0 | O22: ='21'!$H$45 -> -0.48 | P22: ='21'!$H$46 -> -0.05 | Q22: ='21'!$H$49 -> 14832.95 | R22: ='21'!$H$50 -> 24204.69 | S22: ='21'!$H$51 -> 9951.26 | T22: ='21'!$H$52 -> 14104.33 | U22: ='21'!$H$53 -> 27556.73 | V22: ='21'!$H$54 -> 1218.2 | W22: ='21'!$H$55 -> 51282.02 | X22: ='21'!$H$56 -> 14920.09 | Y22: ='21'!$H$57 -> 7711 | Z22: ='21'!$H$58 -> 3786.46 | AA22: ='21'!$H$62 -> 0.011 | AB22: ='21'!$H$63 -> 278.47 | AC22: ='21'!$H$64 -> 8754.54 | AD22: ='21'!$H$65 -> 8118.89 | AE22: ='21'!$H$66 -> 8280.26 | AF22: ='21'!$H$67 -> 14636.47 | AG22: ='21'!$H$68 -> 8185.14 | AH22: ='21'!$H$69 -> 6433.29 | AI22: ='21'!$H$70 -> 0 | AJ22: ='21'!$H$72 -> 1456 | AK22: ='21'!$H$73 -> 982 | AL22: ='21'!$H$74 -> 667.1 | AM22: ='21'!$H$75 -> 3859.4 | AN22: ='21'!$H$76 -> 2966.2 | AO22: ='21'!$H$77 -> 1147 | AP22: ='21'!$H$78 -> 8531 | AQ22: ='21'!$H$79 -> 6896 | AR22: ='21'!$H$80 -> 5463.32 | AS22: ='21'!$H$81 -> 2223 | AT22: ='21'!$H$82 -> 598 | AU22: ='21'!$H$83 -> 9128 | AV22: ='21'!$H$84 -> 10443 | AW22: ='21'!$H$92 -> 2349 | AX22: ='21'!$H$93 -> 3277 | AY22: ='21'!$H$95 -> 1644 | AZ22: ='21'!$H$96 -> 664 | BA22: ='21'!$H$97 -> 628 | BB22: ='21'!$H$98 -> 1439 | BC22: ='21'!$H$99 -> 305 | BD22: ='21'!$H$100 -> 195 | BE22: ='21'!$H$104 -> 74 | BF22: ='21'!$H$105 -> 83 | BG22: ='21'!$H$106 -> 364 | BH22: ='21'!$H$109 -> 295 | BI22: ='21'!$H$110 -> 343 | BJ22: ='21'!$H$111 -> 466 | BK22: ='21'!$H$114 -> 94 | BL22: ='21'!$H$115 -> 111 | BM22: ='21'!$H$116 -> 200 | BN22: ='21'!$H$118 -> 627 | BO22: ='21'!$H$119 -> 688 | BP22: ='21'!$H$120 -> 556 | BQ22: ='21'!$H$123 -> 5865.6 | BR22: ='21'!$H$124 -> 1 | BS22: ='21'!$H$125 -> 1634 | BT22: ='21'!$H$126 -> 747.3 | BU22: ='21'!$H$127 -> 60 | BV22: ='21'!$H$128 -> 3419.51
A23: Mumbai | B23: =B22+1 -> 22 | C23: 2 | D23: 2021 | E23: ='22'!$H$35 -> 0 | F23: ='22'!$H$36 -> -6151.66 | G23: ='22'!$H$37 -> 415066 | H23: ='22'!$H$38 -> 150616.5 | I23: ='22'!$H$39 -> 912480 | J23: ='22'!$H$40 -> -0.06 | K23: ='22'!$H$41 -> -34165.98 | L23: ='22'!$H$42 -> 0.09 | M23: ='22'!$H$43 -> -20942.8 | N23: ='22'!$H$44 -> 0 | O23: ='22'!$H$45 -> -0.48 | P23: ='22'!$H$46 -> -0.49 | Q23: ='22'!$H$49 -> -27932.05 | R23: ='22'!$H$50 -> -10804.96 | S23: ='22'!$H$51 -> -13376.77 | T23: ='22'!$H$52 -> -16970.12 | U23: ='22'!$H$53 -> -37748.98 | V23: ='22'!$H$54 -> -529.09 | W23: ='22'!$H$55 -> -3867.4 | X23: ='22'!$H$56 -> -2.28 | Y23: ='22'!$H$57 -> 0 | Z23: ='22'!$H$58 -> -1657.26 | AA23: ='22'!$H$62 -> 0.011 | AB23: ='22'!$H$63 -> -95.54 | AC23: ='22'!$H$64 -> -3809.58 | AD23: ='22'!$H$65 -> -3634.49 | AE23: ='22'!$H$66 -> -3676.96 | AF23: ='22'!$H$67 -> -5948.53 | AG23: ='22'!$H$68 -> -2912.3 | AH23: ='22'!$H$69 -> -2776.57 | AI23: ='22'!$H$70 -> 0 | AJ23: ='22'!$H$72 -> -725 | AK23: ='22'!$H$73 -> 930 | AL23: ='22'!$H$74 -> 882300.1 | AM23: ='22'!$H$75 -> 737283.4 | AN23: ='22'!$H$76 -> 688306.2 | AO23: ='22'!$H$77 -> -483 | AP23: ='22'!$H$78 -> -3331 | AQ23: ='22'!$H$79 -> 1168 | AR23: ='22'!$H$80 -> -4260.68 | AS23: ='22'!$H$81 -> -975 | AT23: ='22'!$H$82 -> -424 | AU23: ='22'!$H$83 -> -2601 | AV23: ='22'!$H$84 -> -4756 | AW23: ='22'!$H$92 -> -791 | AX23: ='22'!$H$93 -> -1243 | AY23: ='22'!$H$95 -> -591 | AZ23: ='22'!$H$96 -> -221 | BA23: ='22'!$H$97 -> -204 | BB23: ='22'!$H$98 -> -533 | BC23: ='22'!$H$99 -> -170 | BD23: ='22'!$H$100 -> -72 | BE23: ='22'!$H$104 -> -13 | BF23: ='22'!$H$105 -> -202 | BG23: ='22'!$H$106 -> 161 | BH23: ='22'!$H$109 -> -1623 | BI23: ='22'!$H$110 -> -1822 | BJ23: ='22'!$H$111 -> 189 | BK23: ='22'!$H$114 -> -566 | BL23: ='22'!$H$115 -> -136 | BM23: ='22'!$H$116 -> 200 | BN23: ='22'!$H$118 -> -4632 | BO23: ='22'!$H$119 -> -4611 | BP23: ='22'!$H$120 -> -3804 | BQ23: ='22'!$H$123 -> -2363.32 | BR23: ='22'!$H$124 -> 0.3 | BS23: ='22'!$H$125 -> -606.95 | BT23: ='22'!$H$126 -> -286.7 | BU23: ='22'!$H$127 -> -31 | BV23: ='22'!$H$128 -> -11118.98
A24: Mumbai | B24: =B23+1 -> 23 | C24: 2 | D24: 2021 | E24: ='23'!$H$35 -> 0 | F24: ='23'!$H$36 -> -5497.44 | G24: ='23'!$H$37 -> 415066 | H24: ='23'!$H$38 -> 150616.5 | I24: ='23'!$H$39 -> 912480 | J24: ='23'!$H$40 -> -0.06 | K24: ='23'!$H$41 -> -29819.84 | L24: ='23'!$H$42 -> 0.09 | M24: ='23'!$H$43 -> -18579.28 | N24: ='23'!$H$44 -> 0 | O24: ='23'!$H$45 -> -0.48 | P24: ='23'!$H$46 -> -0.49 | Q24: ='23'!$H$49 -> -24893.48 | R24: ='23'!$H$50 -> -9756.6 | S24: ='23'!$H$51 -> -11914.1 | T24: ='23'!$H$52 -> -15026.08 | U24: ='23'!$H$53 -> -33486.22 | V24: ='23'!$H$54 -> -461.97 | W24: ='23'!$H$55 -> -3867.4 | X24: ='23'!$H$56 -> -1.76 | Y24: ='23'!$H$57 -> 0 | Z24: ='23'!$H$58 -> -1452.48 | AA24: ='23'!$H$62 -> -0.189 | AB24: ='23'!$H$63 -> -87.1 | AC24: ='23'!$H$64 -> -3382.36 | AD24: ='23'!$H$65 -> -3221.06 | AE24: ='23'!$H$66 -> -3334.93 | AF24: ='23'!$H$67 -> -5322.08 | AG24: ='23'!$H$68 -> -2596.55 | AH24: ='23'!$H$69 -> -2474.44 | AI24: ='23'!$H$70 -> 0 | AJ24: ='23'!$H$72 -> -685 | AK24: ='23'!$H$73 -> 943 | AL24: ='23'!$H$74 -> 882339.1 | AM24: ='23'!$H$75 -> 737504.4 | AN24: ='23'!$H$76 -> 688386.2 | AO24: ='23'!$H$77 -> -428 | AP24: ='23'!$H$78 -> -2992 | AQ24: ='23'!$H$79 -> 1361 | AR24: ='23'!$H$80 -> -3941.68 | AS24: ='23'!$H$81 -> -892 | AT24: ='23'!$H$82 -> -366 | AU24: ='23'!$H$83 -> -2373 | AV24: ='23'!$H$84 -> -4204 | AW24: ='23'!$H$92 -> -688 | AX24: ='23'!$H$93 -> -1123 | AY24: ='23'!$H$95 -> -516 | AZ24: ='23'!$H$96 -> -203 | BA24: ='23'!$H$97 -> -178 | BB24: ='23'!$H$98 -> -477 | BC24: ='23'!$H$99 -> -160 | BD24: ='23'!$H$100 -> -59 | BE24: ='23'!$H$104 -> 74 | BF24: ='23'!$H$105 -> 54 | BG24: ='23'!$H$106 -> 342 | BH24: ='23'!$H$109 -> 121 | BI24: ='23'!$H$110 -> 86 | BJ24: ='23'!$H$111 -> 446 | BK24: ='23'!$H$114 -> 12 | BL24: ='23'!$H$115 -> 99 | BM24: ='23'!$H$116 -> 200 | BN24: ='23'!$H$118 -> 169 | BO24: ='23'!$H$119 -> 225 | BP24: ='23'!$H$120 -> 105 | BQ24: ='23'!$H$123 -> -2117.46 | BR24: ='23'!$H$124 -> 0.3 | BS24: ='23'!$H$125 -> -523.52 | BT24: ='23'!$H$126 -> -246.3 | BU24: ='23'!$H$127 -> -26.9 | BV24: ='23'!$H$128 -> -10557.83
A25: Mumbai | B25: =B24+1 -> 24 | C25: 2 | D25: 2021 | E25: ='24'!$H$35 -> 0 | F25: ='24'!$H$36 -> -4771.54 | G25: ='24'!$H$37 -> 415066 | H25: ='24'!$H$38 -> 150616.5 | I25: ='24'!$H$39 -> 912480 | J25: ='24'!$H$40 -> -0.06 | K25: ='24'!$H$41 -> -25598.52 | L25: ='24'!$H$42 -> 0 | M25: ='24'!$H$43 -> -16200.91 | N25: ='24'!$H$44 -> 0 | O25: ='24'!$H$45 -> -0.48 | P25: ='24'!$H$46 -> -0.49 | Q25: ='24'!$H$49 -> -21818.05 | R25: ='24'!$H$50 -> -8757.6 | S25: ='24'!$H$51 -> -10435.74 | T25: ='24'!$H$52 -> -13192.16 | U25: ='24'!$H$53 -> -29282.27 | V25: ='24'!$H$54 -> -414.8 | W25: ='24'!$H$55 -> -3867.4 | X25: ='24'!$H$56 -> -1.76 | Y25: ='24'!$H$57 -> 0 | Z25: ='24'!$H$58 -> -1329.54 | AA25: ='24'!$H$62 -> -0.009 | AB25: ='24'!$H$63 -> -78.53 | AC25: ='24'!$H$64 -> -2978.46 | AD25: ='24'!$H$65 -> -2781.11 | AE25: ='24'!$H$66 -> -2937.74 | AF25: ='24'!$H$67 -> -4701.53 | AG25: ='24'!$H$68 -> -2245.86 | AH25: ='24'!$H$69 -> -2174.71 | AI25: ='24'!$H$70 -> 0 | AJ25: ='24'!$H$72 -> -635 | AK25: ='24'!$H$73 -> 945 | AL25: ='24'!$H$74 -> 882377.1 | AM25: ='24'!$H$75 -> 737689.4 | AN25: ='24'!$H$76 -> 688468.2 | AO25: ='24'!$H$77 -> -373 | AP25: ='24'!$H$78 -> -2659 | AQ25: ='24'!$H$79 -> 1537 | AR25: ='24'!$H$80 -> -3624.68 | AS25: ='24'!$H$81 -> -796 | AT25: ='24'!$H$82 -> -329 | AU25: ='24'!$H$83 -> -2140 | AV25: ='24'!$H$84 -> -3680 | AW25: ='24'!$H$92 -> -585 | AX25: ='24'!$H$93 -> -974 | AY25: ='24'!$H$95 -> -445 | AZ25: ='24'!$H$96 -> -178 | BA25: ='24'!$H$97 -> -145 | BB25: ='24'!$H$98 -> -432 | BC25: ='24'!$H$99 -> -148 | BD25: ='24'!$H$100 -> -50 | BE25: ='24'!$H$104 -> 74 | BF25: ='24'!$H$105 -> 54 | BG25: ='24'!$H$106 -> 339 | BH25: ='24'!$H$109 -> 137 | BI25: ='24'!$H$110 -> 80 | BJ25: ='24'!$H$111 -> 433 | BK25: ='24'!$H$114 -> 15 | BL25: ='24'!$H$115 -> 95 | BM25: ='24'!$H$116 -> 200 | BN25: ='24'!$H$118 -> 176 | BO25: ='24'!$H$119 -> 233 | BP25: ='24'!$H$120 -> 102 | BQ25: ='24'!$H$123 -> -1848.4 | BR25: ='24'!$H$124 -> 0 | BS25: ='24'!$H$125 -> -458.63 | BT25: ='24'!$H$126 -> -211.7 | BU25: ='24'!$H$127 -> -23 | BV25: ='24'!$H$128 -> -10181.86
A26: Mumbai | B26: =B25+1 -> 25 | C26: 2 | D26: 2021 | E26: ='25'!$H$35 -> 0 | F26: ='25'!$H$36 -> -3815.45 | G26: ='25'!$H$37 -> 415066 | H26: ='25'!$H$38 -> 150616.5 | I26: ='25'!$H$39 -> 912480 | J26: ='25'!$H$40 -> -0.06 | K26: ='25'!$H$41 -> -22083.41 | L26: ='25'!$H$42 -> 0 | M26: ='25'!$H$43 -> -13947.6 | N26: ='25'!$H$44 -> 0 | O26: ='25'!$H$45 -> -0.48 | P26: ='25'!$H$46 -> -0.49 | Q26: ='25'!$H$49 -> -18630.44 | R26: ='25'!$H$50 -> -7715.64 | S26: ='25'!$H$51 -> -8931.86 | T26: ='25'!$H$52 -> -11367.16 | U26: ='25'!$H$53 -> -24956.27 | V26: ='25'!$H$54 -> -364.8 | W26: ='25'!$H$55 -> -3867.4 | X26: ='25'!$H$56 -> -1.76 | Y26: ='25'!$H$57 -> 0 | Z26: ='25'!$H$58 -> -1150.4 | AA26: ='25'!$H$62 -> -0.009 | AB26: ='25'!$H$63 -> -68.22 | AC26: ='25'!$H$64 -> -2555.46 | AD26: ='25'!$H$65 -> -2365.11 | AE26: ='25'!$H$66 -> -2503.05 | AF26: ='25'!$H$67 -> -4029.53 | AG26: ='25'!$H$68 -> -1895.01 | AH26: ='25'!$H$69 -> -1870.71 | AI26: ='25'!$H$70 -> 0 | AJ26: ='25'!$H$72 -> -587 | AK26: ='25'!$H$73 -> 945 | AL26: ='25'!$H$74 -> 882410.1 | AM26: ='25'!$H$75 -> 737889.4 | AN26: ='25'!$H$76 -> 688563.2 | AO26: ='25'!$H$77 -> -312 | AP26: ='25'!$H$78 -> -2314 | AQ26: ='25'!$H$79 -> 1733 | AR26: ='25'!$H$80 -> -3296.12 | AS26: ='25'!$H$81 -> -643.44 | AT26: ='25'!$H$82 -> -271 | AU26: ='25'!$H$83 -> -1900 | AV26: ='25'!$H$84 -> -3164 | AW26: ='25'!$H$92 -> -489 | AX26: ='25'!$H$93 -> -813 | AY26: ='25'!$H$95 -> -362 | AZ26: ='25'!$H$96 -> -154 | BA26: ='25'!$H$97 -> -120 | BB26: ='25'!$H$98 -> -382 | BC26: ='25'!$H$99 -> -131 | BD26: ='25'!$H$100 -> -42 | BE26: ='25'!$H$104 -> 74 | BF26: ='25'!$H$105 -> 62 | BG26: ='25'!$H$106 -> 341 | BH26: ='25'!$H$109 -> 117 | BI26: ='25'!$H$110 -> 105 | BJ26: ='25'!$H$111 -> 447 | BK26: ='25'!$H$114 -> 20 | BL26: ='25'!$H$115 -> 93 | BM26: ='25'!$H$116 -> 200 | BN26: ='25'!$H$118 -> 172 | BO26: ='25'!$H$119 -> 240 | BP26: ='25'!$H$120 -> 121 | BQ26: ='25'!$H$123 -> -1579.19 | BR26: ='25'!$H$124 -> 0 | BS26: ='25'!$H$125 -> -369 | BT26: ='25'!$H$126 -> -177.7 | BU26: ='25'!$H$127 -> -19.4 | BV26: ='25'!$H$128 -> -9647.44
