Workbook

Sheet Total
A1: Site Name | B1: Day | C1: Month | D1: Year | E1: Total Electricity Kwh | F1: Electricity Tariff ($/Kwh) | G1: Total Fuel Oil (Liters) | H1: Fuel Oil $/Liter | I1: LPG (Kg) | J1: LPG $/Kg | K1: Water Utility Supply (m3) m3 | L1: Water Utility Supply (m3) $/m3 | M1: Irrigation Water (m3) m3 | N1: Irrigation water $/m3 | O1: Room Nights
A2: Beirut | B2: 1 | C2: 3 | D2: 2021 | E2: =ELEC!N3 -> 8408 | F2: =SUM('EDl log'!T4) -> 0.2998851 | G2: =-tanks!AW6 -> 420.2 | H2: =SUM(tanks!AV6) -> 0.74 | I2: =('B5'!AU5)*0.51 -> 0 | J2: ='B5'!AX5/0.51 -> 1.5686275 | K2: =WATER!I6 -> 0 | L2: =SUM(WATER!J6) -> 0 | M2: =WATER!Q6 -> 0 | N2: 0.6 | O2: =ELEC!B3 -> 0
A3: Beirut | B3: =B2+1 -> 2 | C3: 3 | D3: 2021 | E3: =ELEC!N4 -> 9041 | F3: =SUM('EDl log'!T5) -> 0.19622806 | G3: =-tanks!AW7 -> 351 | H3: =SUM(tanks!AV7) -> 0.74 | I3: =('B5'!AU6)*0.51 -> 0 | J3: ='B5'!AX6/0.51 -> 1.5686275 | K3: =WATER!I7 -> 0 | L3: =SUM(WATER!J7) -> 0 | M3: =WATER!Q7 -> 0 | N3: 0.6 | O3: =ELEC!B4 -> 0
A4: Beirut | B4: =B3+1 -> 3 | C4: 3 | D4: 2021 | E4: =ELEC!N5 -> 7715 | F4: =SUM('EDl log'!T6) -> 0.19000605 | G4: =-tanks!AW8 -> 216 | H4: =SUM(tanks!AV8) -> 0.74 | I4: =('B5'!AU7)*0.51 -> 0 | J4: ='B5'!AX7/0.51 -> 1.5686275 | K4: =WATER!I8 -> 0 | L4: =SUM(WATER!J8) -> 0 | M4: =WATER!Q8 -> 0 | N4: 0.6 | O4: =ELEC!B5 -> 0
A5: Beirut | B5: =B4+1 -> 4 | C5: 3 | D5: 2021 | E5: =ELEC!N6 -> 7405 | F5: =SUM('EDl log'!T7) -> 0.18666534 | G5: =-tanks!AW9 -> 312 | H5: =SUM(tanks!AV9) -> 0.74 | I5: =('B5'!AU8)*0.51 -> 0 | J5: ='B5'!AX8/0.51 -> 1.5686275 | K5: =WATER!I9 -> 0 | L5: =SUM(WATER!J9) -> 0 | M5: =WATER!Q9 -> 0 | N5: 0.6 | O5: =ELEC!B6 -> 0
A6: Beirut | B6: =B5+1 -> 5 | C6: 3 | D6: 2021 | E6: =ELEC!N7 -> 7744 | F6: =SUM('EDl log'!T8) -> 0.060488366 | G6: =-tanks!AW10 -> 238 | H6: =SUM(tanks!AV10) -> 0.78 | I6: =('B5'!AU9)*0.51 -> 0 | J6: ='B5'!AX9/0.51 -> 1.5686275 | K6: =WATER!I10 -> 0 | L6: =SUM(WATER!J10) -> 0 | M6: =WATER!Q10 -> 0 | N6: 0.6 | O6: =ELEC!B7 -> 0
A7: Beirut | B7: =B6+1 -> 6 | C7: 3 | D7: 2021 | E7: =ELEC!N8 -> 7618 | F7: =SUM('EDl log'!T9) -> 0.18981186 | G7: =-tanks!AW11 -> 228 | H7: =SUM(tanks!AV11) -> 0.78 | I7: =('B5'!AU10)*0.51 -> 0 | J7: ='B5'!AX10/0.51 -> 1.5686275 | K7: =WATER!I11 -> 0 | L7: =SUM(WATER!J11) -> 0 | M7: =WATER!Q11 -> 0 | N7: 0.6 | O7: =ELEC!B8 -> 0
A8: Beirut | B8: =B7+1 -> 7 | C8: 3 | D8: 2021 | E8: =ELEC!N9 -> 6359 | F8: =SUM('EDl log'!T10) -> 0.12407569 | G8: =-tanks!AW12 -> 230 | H8: =SUM(tanks!AV12) -> 0.78 | I8: =('B5'!AU11)*0.51 -> 0 | J8: ='B5'!AX11/0.51 -> 1.5686275 | K8: =WATER!I12 -> 0 | L8: =SUM(WATER!J12) -> 0 | M8: =WATER!Q12 -> 0 | N8: 0.6 | O8: =ELEC!B9 -> 0
A9: Beirut | B9: =B8+1 -> 8 | C9: 3 | D9: 2021 | E9: =ELEC!N10 -> 6832 | F9: =SUM('EDl log'!T11) -> 0.15950008 | G9: =-tanks!AW13 -> 290 | H9: =SUM(tanks!AV13) -> 0.78 | I9: =('B5'!AU12)*0.51 -> 0 | J9: ='B5'!AX12/0.51 -> 1.5686275 | K9: =WATER!I13 -> 0 | L9: =SUM(WATER!J13) -> 0 | M9: =WATER!Q13 -> 0 | N9: 0.6 | O9: =ELEC!B10 -> 0
A10: Beirut | B10: =B9+1 -> 9 | C10: 3 | D10: 2021 | E10: =ELEC!N11 -> 6552 | F10: =SUM('EDl log'!T12) -> 0.10694154 | G10: =-tanks!AW14 -> 220 | H10: =SUM(tanks!AV14) -> 0.78 | I10: =('B5'!AU13)*0.51 -> 0 | J10: ='B5'!AX13/0.51 -> 1.5686275 | K10: =WATER!I14 -> 0 | L10: =SUM(WATER!J14) -> 0 | M10: =WATER!Q14 -> 0 | N10: 0.6 | O10: =ELEC!B11 -> 0
A11: Beirut | B11: =B10+1 -> 10 | C11: 3 | D11: 2021 | E11: =ELEC!N12 -> 6673 | F11: =SUM('EDl log'!T13) -> 0.16386207 | G11: =-tanks!AW15 -> 276 | H11: =SUM(tanks!AV15) -> 0.78 | I11: =('B5'!AU14)*0.51 -> 0 | J11: ='B5'!AX14/0.51 -> 1.5686275 | K11: =WATER!I15 -> 299 | L11: =SUM(WATER!J15) -> 0.80914878 | M11: =WATER!Q15 -> 0 | N11: 0.6 | O11: =ELEC!B12 -> 0
A12: Beirut | B12: =B11+1 -> 11 | C12: 3 | D12: 2021 | E12: =ELEC!N13 -> 6832 | F12: =SUM('EDl log'!T14) -> 0.13414335 | G12: =-tanks!AW16 -> 242 | H12: =SUM(tanks!AV16) -> 0.78 | I12: =('B5'!AU15)*0.51 -> 0 | J12: ='B5'!AX15/0.51 -> 1.5686275 | K12: =WATER!I16 -> 0 | L12: =SUM(WATER!J16) -> 0 | M12: =WATER!Q16 -> 0 | N12: 0.6 | O12: =ELEC!B13 -> 0
A13: Beirut | B13: =B12+1 -> 12 | C13: 3 | D13: 2021 | E13: =ELEC!N14 -> 6743 | F13: =SUM('EDl log'!T15) -> 0.12261294 | G13: =-tanks!AW17 -> 257 | H13: =SUM(tanks!AV17) -> 0.78 | I13: =('B5'!AU16)*0.51 -> 0 | J13: ='B5'!AX16/0.51 -> 1.5686275 | K13: =WATER!I17 -> 0 | L13: =SUM(WATER!J17) -> 0 | M13: =WATER!Q17 -> 0 | N13: 0.6 | O13: =ELEC!B14 -> 0
A14: Beirut | B14: =B13+1 -> 13 | C14: 3 | D14: 2021 | E14: =ELEC!N15 -> 6400 | F14: =SUM('EDl log'!T16) -> 0.13411117 | G14: =-tanks!AW18 -> 233 | H14: =SUM(tanks!AV18) -> 0.78 | I14: =('B5'!AU17)*0.51 -> 0 | J14: ='B5'!AX17/0.51 -> 1.5686275 | K14: =WATER!I18 -> 0 | L14: =SUM(WATER!J18) -> 0 | M14: =WATER!Q18 -> 0 | N14: 0.6 | O14: =ELEC!B15 -> 0
... A28: Beirut | B28: =B27+1 -> 27 | C28: 3 | D28: 2021 | E28: =ELEC!N29 -> 0 | F28: =SUM('EDl log'!T30) -> 0 | G28: =-tanks!AW32 -> 0 | H28: =SUM(tanks!AV32) -> 0.78 | I28: =('B5'!AU31)*0.51 -> 0 | J28: ='B5'!AX31/0.51 -> 1.5686275 | K28: =WATER!I32 -> 0 | L28: =SUM(WATER!J32) -> 0 | M28: =WATER!Q32 -> 0 | N28: 0.6 | O28: =ELEC!B29 -> 0
A29: Beirut | B29: =B28+1 -> 28 | C29: 3 | D29: 2021 | E29: =ELEC!N30 -> 0 | F29: =SUM('EDl log'!T34) -> 0 | G29: =-tanks!AW33 -> 0 | H29: =SUM(tanks!AV33) -> 0.78 | I29: =('B5'!AU32)*0.51 -> 0 | J29: ='B5'!AX32/0.51 -> 1.5686275 | K29: =WATER!I33 -> 0 | L29: =SUM(WATER!J33) -> 0 | M29: =WATER!Q33 -> 0 | N29: 0.6 | O29: =ELEC!B30 -> 0
A30: Beirut | B30: =B29+1 -> 29 | C30: 3 | D30: 2021 | E30: =ELEC!N31 -> 0 | F30: =SUM('EDl log'!T32) -> 0 | G30: =-tanks!AW34 -> 0 | H30: =SUM(tanks!AV34) -> 0.78 | I30: =('B5'!AU33)*0.51 -> 0 | J30: ='B5'!AX33/0.51 -> 1.5686275 | K30: =WATER!I34 -> 0 | L30: =SUM(WATER!J34) -> 0 | M30: =WATER!Q34 -> 0 | N30: 0.6 | O30: =ELEC!B31 -> 0
A31: Beirut | B31: =B30+1 -> 30 | C31: 3 | D31: 2021 | E31: =ELEC!N32 -> 0 | F31: =SUM('EDl log'!T33) -> 0 | G31: =-tanks!AW35 -> 0 | H31: =SUM(tanks!AV35) -> 0.78 | I31: =('B5'!AU34)*0.51 -> 0 | J31: ='B5'!AX34/0.51 -> 1.5686275 | K31: =WATER!I35 -> 0 | L31: =SUM(WATER!J35) -> 0 | M31: =WATER!Q35 -> 0 | N31: 0.6 | O31: =ELEC!B32 -> 0
A32: Beirut | B32: =B31+1 -> 31 | C32: 3 | D32: 2021 | E32: =ELEC!N33 -> 0 | F32: =SUM('EDl log'!T37) -> 0 | G32: =-tanks!AW36 -> 0 | H32: =SUM(tanks!AV36) -> 0.78 | I32: =('B5'!AU35)*0.51 -> 0 | J32: ='B5'!AX35/0.51 -> 1.5686275 | K32: =WATER!I36 -> 0 | L32: =SUM(WATER!J36) -> 0 | M32: =WATER!Q36 -> 0 | N32: 0.6 | O32: =ELEC!B33 -> 0

Sheet Submetering
A1: Site Name | B1: Day | C1: Month | D1: Year | E1: ATS1 Kwh | F1: ATS2 Kwh | G1: ATS3 Kwh | H1: ATS4 Kwh | I1: ATS5 Kwh | J1: Guest (m3) | K1: Kitchen & Laundry (m3) | L1: Room Nights
A2: Beirut | B2: 1 | C2: 3 | D2: 2021 | E2: =ELEC!M3 -> 2408 | F2: =ELEC!K3 -> 1676 | G2: =ELEC!I3 -> 928 | H2: =ELEC!E3 -> 2697 | I2: =ELEC!G3 -> 699 | J2: =WATER!Y6 -> 0 | K2: =WATER!AJ6 -> 0 | L2: =ELEC!B3 -> 0
A3: Beirut | B3: =B2+1 -> 2 | C3: 3 | D3: 2021 | E3: =ELEC!M4 -> 2568 | F3: =ELEC!K4 -> 1428 | G3: =ELEC!I4 -> 938 | H3: =ELEC!E4 -> 3467 | I3: =ELEC!G4 -> 640 | J3: =WATER!Y7 -> 0 | K3: =WATER!AJ7 -> 0 | L3: =ELEC!B4 -> 0
A4: Beirut | B4: =B3+1 -> 3 | C4: 3 | D4: 2021 | E4: =ELEC!M5 -> 1992 | F4: =ELEC!K5 -> 1192 | G4: =ELEC!I5 -> 902 | H4: =ELEC!E5 -> 2976 | I4: =ELEC!G5 -> 653 | J4: =WATER!Y8 -> 0 | K4: =WATER!AJ8 -> 0 | L4: =ELEC!B5 -> 0
A5: Beirut | B5: =B4+1 -> 4 | C5: 3 | D5: 2021 | E5: =ELEC!M6 -> 1952 | F5: =ELEC!K6 -> 1152 | G5: =ELEC!I6 -> 900 | H5: =ELEC!E6 -> 2760 | I5: =ELEC!G6 -> 641 | J5: =WATER!Y9 -> 0 | K5: =WATER!AJ9 -> 0 | L5: =ELEC!B6 -> 0
A6: Beirut | B6: =B5+1 -> 5 | C6: 3 | D6: 2021 | E6: =ELEC!M7 -> 1822 | F6: =ELEC!K7 -> 1132 | G6: =ELEC!I7 -> 916 | H6: =ELEC!E7 -> 3292 | I6: =ELEC!G7 -> 582 | J6: =WATER!Y10 -> 0 | K6: =WATER!AJ10 -> 0 | L6: =ELEC!B7 -> 0
A7: Beirut | B7: =B6+1 -> 6 | C7: 3 | D7: 2021 | E7: =ELEC!M8 -> 1966 | F7: =ELEC!K8 -> 1168 | G7: =ELEC!I8 -> 870 | H7: =ELEC!E8 -> 3066 | I7: =ELEC!G8 -> 548 | J7: =WATER!Y11 -> 0 | K7: =WATER!AJ11 -> 0 | L7: =ELEC!B8 -> 0
A8: Beirut | B8: =B7+1 -> 7 | C8: 3 | D8: 2021 | E8: =ELEC!M9 -> 1752 | F8: =ELEC!K9 -> 926 | G8: =ELEC!I9 -> 858 | H8: =ELEC!E9 -> 2250 | I8: =ELEC!G9 -> 573 | J8: =WATER!Y12 -> 0 | K8: =WATER!AJ12 -> 0 | L8: =ELEC!B9 -> 0
A9: Beirut | B9: =B8+1 -> 8 | C9: 3 | D9: 2021 | E9: =ELEC!M10 -> 1668 | F9: =ELEC!K10 -> 1002 | G9: =ELEC!I10 -> 836 | H9: =ELEC!E10 -> 2724 | I9: =ELEC!G10 -> 602 | J9: =WATER!Y13 -> 0 | K9: =WATER!AJ13 -> 0 | L9: =ELEC!B10 -> 0
A10: Beirut | B10: =B9+1 -> 9 | C10: 3 | D10: 2021 | E10: =ELEC!M11 -> 1518 | F10: =ELEC!K11 -> 1056 | G10: =ELEC!I11 -> 780 | H10: =ELEC!E11 -> 2592 | I10: =ELEC!G11 -> 606 | J10: =WATER!Y14 -> 15 | K10: =WATER!AJ14 -> 30 | L10: =ELEC!B11 -> 0
A11: Beirut | B11: =B10+1 -> 10 | C11: 3 | D11: 2021 | E11: =ELEC!M12 -> 1698 | F11: =ELEC!K12 -> 1072 | G11: =ELEC!I12 -> 804 | H11: =ELEC!E12 -> 2504 | I11: =ELEC!G12 -> 595 | J11: =WATER!Y15 -> 55 | K11: =WATER!AJ15 -> 31 | L11: =ELEC!B12 -> 0
A12: Beirut | B12: =B11+1 -> 11 | C12: 3 | D12: 2021 | E12: =ELEC!M13 -> 1724 | F12: =ELEC!K13 -> 960 | G12: =ELEC!I13 -> 876 | H12: =ELEC!E13 -> 2612 | I12: =ELEC!G13 -> 660 | J12: =WATER!Y16 -> 27 | K12: =WATER!AJ16 -> 0 | L12: =ELEC!B13 -> 0
A13: Beirut | B13: =B12+1 -> 12 | C13: 3 | D13: 2021 | E13: =ELEC!M14 -> 1862 | F13: =ELEC!K14 -> 950 | G13: =ELEC!I14 -> 904 | H13: =ELEC!E14 -> 2356 | I13: =ELEC!G14 -> 671 | J13: =WATER!Y17 -> 0 | K13: =WATER!AJ17 -> 0 | L13: =ELEC!B14 -> 0
A14: Beirut | B14: =B13+1 -> 13 | C14: 3 | D14: 2021 | E14: =ELEC!M15 -> 1726 | F14: =ELEC!K15 -> 902 | G14: =ELEC!I15 -> 756 | H14: =ELEC!E15 -> 2450 | I14: =ELEC!G15 -> 566 | J14: =WATER!Y18 -> 0 | K14: =WATER!AJ18 -> 0 | L14: =ELEC!B15 -> 0
... A32: Beirut | B32: =B31+1 -> 31 | C32: 3 | D32: 2021 | E32: =ELEC!M33 -> 0 | F32: =ELEC!K33 -> 0 | G32: =ELEC!I33 -> 0 | H32: =ELEC!E33 -> 0 | I32: =ELEC!G33 -> 0 | J32: =WATER!Y36 -> 0 | K32: =WATER!AJ36 -> 0 | L32: =ELEC!B33 -> 0

Sheet ELEC
A1: OOC | B1: Room OCC | D1: MDB3 | E1: MDB3/day | F1: EMDB2 | G1: EMDB2/day | H1: EMDB1 | I1: EMDB1/day | J1: MDB2 | K1: mdb2/day | L1: MDB1 | M1: MDB1/Day | N1: Total KWH | O1: KWH/Rooc | P1: Gen MHW | Q1: Gen/Day KWH | R1: EDL KWH | S1: CH1 RH | T1: RH | U1: C1h1 power | V1: CH1 Con KWH | W1: CH2 RH | X1: RH | Y1: Ch2 power | Z1: CH2 Con KWH | AA1: CH3 RH | AB1: RH | AC1: Ch3 power | AD1: CH3 Con KWH | AE1: RH total | AF1: KWH total | AG1: AVG chiller KW/Hr
A2: =[1]ELEC!A30 -> 0 | B2: =[2]ELEC!B33 -> 0 | C2: =[1]ELEC!$C$30 -> 44255 | D2: =[1]ELEC!D30 -> 32641226 | E2: =[1]ELEC!E30 -> 1904 | F2: =[1]ELEC!F30 -> 3971481 | G2: =[1]ELEC!G30 -> 621 | H2: =[1]ELEC!H30 -> 17803738 | I2: =[1]ELEC!I30 -> 908 | J2: =[1]ELEC!J30 -> 28920206 | K2: =[1]ELEC!K30 -> 1956 | ... CZ2: =[1]ELEC!CZ30 -> 0 | DA2: =[2]ELEC!DA33 -> 0 | DB2: =[2]ELEC!DB33 -> 0 | DC2: =[2]ELEC!DC33 -> 0 | DD2: =[2]ELEC!DD33 -> 0
A3: ='General information '!F6 -> 0 | B3: =SUM(230*A3) -> 0 | C3: 44256 | D3: 32643923 | E3: =D3-D2 -> 2697 | F3: 3972180 | G3: =F3-F2 -> 699 | H3: 17804666 | I3: =H3-H2 -> 928 | J3: 28921882 | K3: =J3-J2 -> 1676 | L3: 24055550 | M3: =L3-L2 -> 2408 | N3: =M3+K3+I3+G3+E3 -> 8408 | O3: =IF(B3>0,N3/B3,0) -> 0 | P3: 16685.501 | Q3: =(P3-P2)*1000 -> 6164 | R3: =+N3-Q3 -> 2244 | S3: =S2 -> 10128 | T3: =S3-S2 -> 0 | U3: =U2 -> 422437 | V3: =U3-U2 -> 0 | W3: 32246 | X3: =W3-W2 -> 2 | Y3: 708475 | Z3: =Y3-Y2 -> 334 | AA3: 35699 | AB3: =AA3-AA2 -> 2 | AC3: 916997 | AD3: =AC3-AC2 -> 341 | AE3: =AB3+X3+T3 -> 4 | AF3: =V3+Z3+AD3 -> 675 | AG3: =IF(AE3>0,AF3/AE3,0) -> 168.75
A4: ='General information '!F7 -> 0 | B4: =SUM(230*A4) -> 0 | C4: 44257 | D4: 32647390 | E4: =D4-D3 -> 3467 | F4: 3972820 | G4: =F4-F3 -> 640 | H4: 17805604 | I4: =H4-H3 -> 938 | J4: 28923310 | K4: =J4-J3 -> 1428 | L4: 24058118 | M4: =L4-L3 -> 2568 | N4: =M4+K4+I4+G4+E4 -> 9041 | O4: =IF(B4>0,N4/B4,0) -> 0 | P4: 16692.837 | Q4: =(P4-P3)*1000 -> 7336 | R4: =N4-Q4 -> 1705 | S4: =S3 -> 10128 | T4: =S4-S3 -> 0 | U4: =U3 -> 422437 | V4: =U4-U3 -> 0 | W4: =W3 -> 32246 | X4: =W4-W3 -> 0 | Y4: =Y3 -> 708475 | Z4: =Y4-Y3 -> 0 | AA4: 35704 | AB4: =AA4-AA3 -> 5 | AC4: 917856 | AD4: =AC4-AC3 -> 859 | AE4: =AB4+X4+T4 -> 5 | AF4: =V4+Z4+AD4 -> 859 | AG4: =IF(AE4>0,AF4/AE4,0) -> 171.8
A5: ='General information '!F8 -> 0 | B5: =SUM(230*A5) -> 0 | C5: 44258 | D5: 32650366 | E5: =D5-D4 -> 2976 | F5: 3973473 | G5: =F5-F4 -> 653 | H5: 17806506 | I5: =H5-H4 -> 902 | J5: 28924502 | K5: =J5-J4 -> 1192 | L5: 24060110 | M5: =L5-L4 -> 1992 | N5: =M5+K5+I5+G5+E5 -> 7715 | O5: =IF(B5>0,N5/B5,0) -> 0 | P5: 16697.687 | Q5: =(P5-P4)*1000 -> 4850 | R5: =N5-Q5 -> 2865 | S5: =S4 -> 10128 | T5: =S5-S4 -> 0 | U5: =U4 -> 422437 | V5: =U5-U4 -> 0 | W5: =W4 -> 32246 | X5: =W5-W4 -> 0 | Y5: =Y4 -> 708475 | Z5: =Y5-Y4 -> 0 | AA5: 35709 | AB5: =AA5-AA4 -> 5 | AC5: 918536 | AD5: =AC5-AC4 -> 680 | AE5: =AB5+X5+T5 -> 5 | AF5: =V5+Z5+AD5 -> 680 | AG5: =IF(AE5>0,AF5/AE5,0) -> 136 | AI5: =R5-'EDl log'!B3 -> -902113
A6: ='General information '!F9 -> 0 | B6: =SUM(230*A6) -> 0 | C6: 44259 | D6: 32653126 | E6: =D6-D5 -> 2760 | F6: 3974114 | G6: =F6-F5 -> 641 | H6: 17807406 | I6: =H6-H5 -> 900 | J6: 28925654 | K6: =J6-J5 -> 1152 | L6: 24062062 | M6: =L6-L5 -> 1952 | N6: =M6+K6+I6+G6+E6 -> 7405 | O6: =IF(B6>0,N6/B6,0) -> 0 | P6: 16701.182 | Q6: =(P6-P5)*1000 -> 3495 | R6: =N6-Q6 -> 3910 | S6: =S5 -> 10128 | T6: =S6-S5 -> 0 | U6: =U5 -> 422437 | V6: =U6-U5 -> 0 | W6: =W5 -> 32246 | X6: =W6-W5 -> 0 | Y6: =Y5 -> 708475 | Z6: =Y6-Y5 -> 0 | AA6: 35712 | AB6: =AA6-AA5 -> 3 | AC6: 919105 | AD6: =AC6-AC5 -> 569 | AE6: =AB6+X6+T6 -> 3 | AF6: =V6+Z6+AD6 -> 569 | AG6: =IF(AE6>0,AF6/AE6,0) -> 189.66667 | AI6: =R6-'EDl log'!B4 -> -902318
A7: ='General information '!F10 -> 0 | B7: =SUM(230*A7) -> 0 | C7: 44260 | D7: 32656418 | E7: =D7-D6 -> 3292 | F7: 3974696 | G7: =F7-F6 -> 582 | H7: 17808322 | I7: =H7-H6 -> 916 | J7: 28926786 | K7: =J7-J6 -> 1132 | L7: 24063884 | M7: =L7-L6 -> 1822 | N7: =M7+K7+I7+G7+E7 -> 7744 | O7: =IF(B7>0,N7/B7,0) -> 0 | P7: 16705.77 | Q7: =(P7-P6)*1000 -> 4588 | R7: =N7-Q7 -> 3156 | S7: 10128 | T7: =S7-S6 -> 0 | U7: =U6 -> 422437 | V7: =U7-U6 -> 0 | W7: 32246 | X7: =W7-W6 -> 0 | Y7: =Y6 -> 708475 | Z7: =Y7-Y6 -> 0 | AA7: 35717 | AB7: =AA7-AA6 -> 5 | AC7: 919927 | AD7: =AC7-AC6 -> 822 | AE7: =AB7+X7+T7 -> 5 | AF7: =V7+Z7+AD7 -> 822 | AG7: =IF(AE7>0,AF7/AE7,0) -> 164.4 | AI7: =R7-'EDl log'!B5 -> -904028
A8: ='General information '!F11 -> 0 | B8: =SUM(230*A8) -> 0 | C8: 44261 | D8: 32659484 | E8: =D8-D7 -> 3066 | F8: 3975244 | G8: =F8-F7 -> 548 | H8: 17809192 | I8: =H8-H7 -> 870 | J8: 28927954 | K8: =J8-J7 -> 1168 | L8: 24065850 | M8: =L8-L7 -> 1966 | N8: =M8+K8+I8+G8+E8 -> 7618 | O8: =IF(B8>0,N8/B8,0) -> 0 | P8: 16710.65 | Q8: =(P8-P7)*1000 -> 4880 | R8: =N8-Q8 -> 2738 | S8: =S7 -> 10128 | T8: =S8-S7 -> 0 | U8: =U7 -> 422437 | V8: =U8-U7 -> 0 | W8: =W7 -> 32246 | X8: =W8-W7 -> 0 | Y8: =Y7 -> 708475 | Z8: =Y8-Y7 -> 0 | AA8: 35721 | AB8: =AA8-AA7 -> 4 | AC8: 920665 | AD8: =AC8-AC7 -> 738 | AE8: =AB8+X8+T8 -> 4 | AF8: =V8+Z8+AD8 -> 738 | AG8: =IF(AE8>0,AF8/AE8,0) -> 184.5 | AI8: =R8-'EDl log'!B6 -> -906015
A9: ='General information '!F12 -> 0 | B9: =SUM(230*A9) -> 0 | C9: 44262 | D9: 32661734 | E9: =D9-D8 -> 2250 | F9: 3975817 | G9: =F9-F8 -> 573 | H9: 17810050 | I9: =H9-H8 -> 858 | J9: 28928880 | K9: =J9-J8 -> 926 | L9: 24067602 | M9: =L9-L8 -> 1752 | N9: =M9+K9+I9+G9+E9 -> 6359 | O9: =IF(B9>0,N9/B9,0) -> 0 | P9: 16712.709 | Q9: =(P9-P8)*1000 -> 2059 | R9: =N9-Q9 -> 4300 | S9: =S8 -> 10128 | T9: =S9-S8 -> 0 | U9: =U8 -> 422437 | V9: =U9-U8 -> 0 | W9: =W8 -> 32246 | X9: =W9-W8 -> 0 | Y9: =Y8 -> 708475 | Z9: =Y9-Y8 -> 0 | AA9: 35724 | AB9: =AA9-AA8 -> 3 | AC9: 921046 | AD9: =AC9-AC8 -> 381 | AE9: =AB9+X9+T9 -> 3 | AF9: =V9+Z9+AD9 -> 381 | AG9: =IF(AE9>0,AF9/AE9,0) -> 127 | AI9: =R9-'EDl log'!B7 -> -906552
A10: ='General information '!F13 -> 0 | B10: =SUM(230*A10) -> 0 | C10: 44263 | D10: 32664458 | E10: =D10-D9 -> 2724 | F10: 3976419 | G10: =F10-F9 -> 602 | H10: 17810886 | I10: =H10-H9 -> 836 | J10: 28929882 | K10: =J10-J9 -> 1002 | L10: 24069270 | M10: =L10-L9 -> 1668 | N10: =M10+K10+I10+G10+E10 -> 6832 | O10: =IF(B10>0,N10/B10,0) -> 0 | P10: 16715.519 | Q10: =(P10-P9)*1000 -> 2810 | R10: =N10-Q10 -> 4022 | S10: =S9 -> 10128 | T10: =S10-S9 -> 0 | U10: =U9 -> 422437 | V10: =U10-U9 -> 0 | W10: =W9 -> 32246 | X10: =W10-W9 -> 0 | Y10: =Y9 -> 708475 | Z10: =Y10-Y9 -> 0 | AA10: 35727 | AB10: =AA10-AA9 -> 3 | AC10: 921652 | AD10: =AC10-AC9 -> 606 | AE10: =AB10+X10+T10 -> 3 | AF10: =V10+Z10+AD10 -> 606 | AG10: =IF(AE10>0,AF10/AE10,0) -> 202 | AI10: =R10-'EDl log'!B8 -> -908545
A11: ='General information '!F14 -> 0 | B11: =SUM(230*A11) -> 0 | C11: 44264 | D11: 32667050 | E11: =D11-D10 -> 2592 | F11: 3977025 | G11: =F11-F10 -> 606 | H11: 17811666 | I11: =H11-H10 -> 780 | J11: 28930938 | K11: =J11-J10 -> 1056 | L11: 24070788 | M11: =L11-L10 -> 1518 | N11: =M11+K11+I11+G11+E11 -> 6552 | O11: =IF(B11>0,N11/B11,0) -> 0 | P11: 16717.637 | Q11: =(P11-P10)*1000 -> 2118 | R11: =N11-Q11 -> 4434 | S11: =S10 -> 10128 | T11: =S11-S10 -> 0 | U11: =U10 -> 422437 | V11: =U11-U10 -> 0 | W11: =W10 -> 32246 | X11: =W11-W10 -> 0 | Y11: =Y10 -> 708475 | Z11: =Y11-Y10 -> 0 | AA11: 35730 | AB11: =AA11-AA10 -> 3 | AC11: 922141 | AD11: =AC11-AC10 -> 489 | AE11: =AB11+X11+T11 -> 3 | AF11: =V11+Z11+AD11 -> 489 | AG11: =IF(AE11>0,AF11/AE11,0) -> 163 | AI11: =R11-'EDl log'!B9 -> -909643
A12: ='General information '!F15 -> 0 | B12: =SUM(230*A12) -> 0 | C12: 44265 | D12: 32669554 | E12: =D12-D11 -> 2504 | F12: 3977620 | G12: =F12-F11 -> 595 | H12: 17812470 | I12: =H12-H11 -> 804 | J12: 28932010 | K12: =J12-J11 -> 1072 | L12: 24072486 | M12: =L12-L11 -> 1698 | N12: =M12+K12+I12+G12+E12 -> 6673 | O12: =IF(B12>0,N12/B12,0) -> 0 | P12: 16720.616 | Q12: =(P12-P11)*1000 -> 2979 | R12: =N12-Q12 -> 3694 | S12: 10129 | T12: =S12-S11 -> 1 | U12: 422541 | V12: =U12-U11 -> 104 | W12: 32247 | X12: =W12-W11 -> 1 | Y12: 708695 | Z12: =Y12-Y11 -> 220 | AA12: 35733 | AB12: =AA12-AA11 -> 3 | AC12: 922618 | AD12: =AC12-AC11 -> 477 | AE12: =AB12+X12+T12 -> 5 | AF12: =V12+Z12+AD12 -> 801 | AG12: =IF(AE12>0,AF12/AE12,0) -> 160.2 | AI12: =R12-'EDl log'!B10 -> -912671
A13: ='General information '!F16 -> 0 | B13: =SUM(230*A13) -> 0 | C13: 44266 | D13: 32672166 | E13: =D13-D12 -> 2612 | F13: 3978280 | G13: =F13-F12 -> 660 | H13: 17813346 | I13: =H13-H12 -> 876 | J13: 28932970 | K13: =J13-J12 -> 960 | L13: 24074210 | M13: =L13-L12 -> 1724 | N13: =M13+K13+I13+G13+E13 -> 6832 | O13: =IF(B13>0,N13/B13,0) -> 0 | P13: 16722.646 | Q13: =(P13-P12)*1000 -> 2030 | R13: =N13-Q13 -> 4802 | S13: =S12 -> 10129 | T13: =S13-S12 -> 0 | U13: =U12 -> 422541 | V13: =U13-U12 -> 0 | W13: =W12 -> 32247 | X13: =W13-W12 -> 0 | Y13: =Y12 -> 708695 | Z13: =Y13-Y12 -> 0 | AA13: 35736 | AB13: =AA13-AA12 -> 3 | AC13: 923192 | AD13: =AC13-AC12 -> 574 | AE13: =AB13+X13+T13 -> 3 | AF13: =V13+Z13+AD13 -> 574 | AG13: =IF(AE13>0,AF13/AE13,0) -> 191.33333 | AI13: =R13-'EDl log'!B11 -> -913718
A14: ='General information '!F17 -> 0 | B14: =SUM(230*A14) -> 0 | C14: 44267 | D14: 32674522 | E14: =D14-D13 -> 2356 | F14: 3978951 | G14: =F14-F13 -> 671 | H14: 17814250 | I14: =H14-H13 -> 904 | J14: 28933920 | K14: =J14-J13 -> 950 | L14: 24076072 | M14: =L14-L13 -> 1862 | N14: =M14+K14+I14+G14+E14 -> 6743 | O14: =IF(B14>0,N14/B14,0) -> 0 | P14: 16724.51 | Q14: =(P14-P13)*1000 -> 1864 | R14: =N14-Q14 -> 4879 | S14: =S13 -> 10129 | T14: =S14-S13 -> 0 | U14: =U13 -> 422541 | V14: =U14-U13 -> 0 | W14: =W13 -> 32247 | X14: =W14-W13 -> 0 | Y14: =Y13 -> 708695 | Z14: =Y14-Y13 -> 0 | AA14: 35738 | AB14: =AA14-AA13 -> 2 | AC14: 923570 | AD14: =AC14-AC13 -> 378 | AE14: =AB14+X14+T14 -> 2 | AF14: =V14+Z14+AD14 -> 378 | AG14: =IF(AE14>0,AF14/AE14,0) -> 189 | AI14: =R14-'EDl log'!B12 -> -916010
A15: ='General information '!F18 -> 0 | B15: =SUM(230*A15) -> 0 | C15: 44268 | D15: 32676972 | E15: =D15-D14 -> 2450 | F15: 3979517 | G15: =F15-F14 -> 566 | H15: 17815006 | I15: =H15-H14 -> 756 | J15: 28934822 | K15: =J15-J14 -> 902 | L15: 24077798 | M15: =L15-L14 -> 1726 | N15: =M15+K15+I15+G15+E15 -> 6400 | O15: =IF(B15>0,N15/B15,0) -> 0 | P15: 16726.414 | Q15: =(P15-P14)*1000 -> 1904 | R15: =N15-Q15 -> 4496 | S15: =S14 -> 10129 | T15: =S15-S14 -> 0 | U15: =U14 -> 422541 | V15: =U15-U14 -> 0 | W15: =W14 -> 32247 | X15: =W15-W14 -> 0 | Y15: =Y14 -> 708695 | Z15: =Y15-Y14 -> 0 | AA15: 35740 | AB15: =AA15-AA14 -> 2 | AC15: 924043 | AD15: =AC15-AC14 -> 473 | AE15: =AB15+X15+T15 -> 2 | AF15: =V15+Z15+AD15 -> 473 | AG15: =IF(AE15>0,AF15/AE15,0) -> 236.5 | AI15: =R15-'EDl log'!B13 -> -918391
A16: ='General information '!F19 -> 0 | B16: =SUM(230*A16) -> 0 | C16: 44269 | D16: =D15 -> 32676972 | E16: =D16-D15 -> 0 | F16: =F15 -> 3979517 | G16: =F16-F15 -> 0 | H16: =H15 -> 17815006 | I16: =H16-H15 -> 0 | J16: =J15 -> 28934822 | K16: =J16-J15 -> 0 | L16: =L15 -> 24077798 | M16: =L16-L15 -> 0 | N16: =M16+K16+I16+G16+E16 -> 0 | O16: =IF(B16>0,N16/B16,0) -> 0 | P16: =P15 -> 16726.414 | Q16: =(P16-P15)*1000 -> 0 | R16: =N16-Q16 -> 0 | S16: =S15 -> 10129 | T16: =S16-S15 -> 0 | U16: =U15 -> 422541 | V16: =U16-U15 -> 0 | W16: =W15 -> 32247 | X16: =W16-W15 -> 0 | Y16: =Y15 -> 708695 | Z16: =Y16-Y15 -> 0 | AA16: =AA15 -> 35740 | AB16: =AA16-AA15 -> 0 | AC16: =AC15 -> 924043 | AD16: =AC16-AC15 -> 0 | AE16: =AB16+X16+T16 -> 0 | AF16: =V16+Z16+AD16 -> 0 | AG16: =IF(AE16>0,AF16/AE16,0) -> 0 | AI16: =R16-'EDl log'!B14 -> -925453
A17: ='General information '!F20 -> 0 | B17: =SUM(230*A17) -> 0 | C17: 44270 | D17: =D16 -> 32676972 | E17: =D17-D16 -> 0 | F17: =F16 -> 3979517 | G17: =F17-F16 -> 0 | H17: =H16 -> 17815006 | I17: =H17-H16 -> 0 | J17: =J16 -> 28934822 | K17: =J17-J16 -> 0 | L17: =L16 -> 24077798 | M17: =L17-L16 -> 0 | N17: =M17+K17+I17+G17+E17 -> 0 | O17: =IF(B17>0,N17/B17,0) -> 0 | P17: =P16 -> 16726.414 | Q17: =(P17-P16)*1000 -> 0 | R17: =N17-Q17 -> 0 | S17: =S16 -> 10129 | T17: =S17-S16 -> 0 | U17: =U16 -> 422541 | V17: =U17-U16 -> 0 | W17: =W16 -> 32247 | X17: =W17-W16 -> 0 | Y17: =Y16 -> 708695 | Z17: =Y17-Y16 -> 0 | AA17: =AA16 -> 35740 | AB17: =AA17-AA16 -> 0 | AC17: =AC16 -> 924043 | AD17: =AC17-AC16 -> 0 | AE17: =AB17+X17+T17 -> 0 | AF17: =V17+Z17+AD17 -> 0 | AG17: =IF(AE17>0,AF17/AE17,0) -> 0 | AI17: =R17-'EDl log'!B15 -> -928063
A18: ='General information '!F21 -> 0 | B18: =SUM(230*A18) -> 0 | C18: 44271 | D18: =D17 -> 32676972 | E18: =D18-D17 -> 0 | F18: =F17 -> 3979517 | G18: =F18-F17 -> 0 | H18: =H17 -> 17815006 | I18: =H18-H17 -> 0 | J18: =J17 -> 28934822 | K18: =J18-J17 -> 0 | L18: =L17 -> 24077798 | M18: =L18-L17 -> 0 | N18: =M18+K18+I18+G18+E18 -> 0 | O18: =IF(B18>0,N18/B18,0) -> 0 | P18: =P17 -> 16726.414 | Q18: =(P18-P17)*1000 -> 0 | R18: =N18-Q18 -> 0 | S18: =S17 -> 10129 | T18: =S18-S17 -> 0 | U18: =U17 -> 422541 | V18: =U18-U17 -> 0 | W18: =W17 -> 32247 | X18: =W18-W17 -> 0 | Y18: =Y17 -> 708695 | Z18: =Y18-Y17 -> 0 | AA18: =AA17 -> 35740 | AB18: =AA18-AA17 -> 0 | AC18: =AC17 -> 924043 | AD18: =AC18-AC17 -> 0 | AE18: =AB18+X18+T18 -> 0 | AF18: =V18+Z18+AD18 -> 0 | AG18: =IF(AE18>0,AF18/AE18,0) -> 0 | AI18: =R18-'EDl log'!B16 -> -930474
A19: ='General information '!F22 -> 0 | B19: =SUM(230*A19) -> 0 | C19: 44272 | D19: =D18 -> 32676972 | E19: =D19-D18 -> 0 | F19: =F18 -> 3979517 | G19: =F19-F18 -> 0 | H19: =H18 -> 17815006 | I19: =H19-H18 -> 0 | J19: =J18 -> 28934822 | K19: =J19-J18 -> 0 | L19: =L18 -> 24077798 | M19: =L19-L18 -> 0 | N19: =M19+K19+I19+G19+E19 -> 0 | O19: =IF(B19>0,N19/B19,0) -> 0 | P19: =P18 -> 16726.414 | Q19: =(P19-P18)*1000 -> 0 | R19: =N19-Q19 -> 0 | S19: =S18 -> 10129 | T19: =S19-S18 -> 0 | U19: =U18 -> 422541 | V19: =U19-U18 -> 0 | W19: =W18 -> 32247 | X19: =W19-W18 -> 0 | Y19: =Y18 -> 708695 | Z19: =Y19-Y18 -> 0 | AA19: =AA18 -> 35740 | AB19: =AA19-AA18 -> 0 | AC19: =AC18 -> 924043 | AD19: =AC19-AC18 -> 0 | AE19: =AB19+X19+T19 -> 0 | AF19: =V19+Z19+AD19 -> 0 | AG19: =IF(AE19>0,AF19/AE19,0) -> 0 | AI19: =R19-'EDl log'!B17 -> -930474
A20: ='General information '!F23 -> 0 | B20: =SUM(230*A20) -> 0 | C20: 44273 | D20: =D19 -> 32676972 | E20: =D20-D19 -> 0 | F20: =F19 -> 3979517 | G20: =F20-F19 -> 0 | H20: =H19 -> 17815006 | I20: =H20-H19 -> 0 | J20: =J19 -> 28934822 | K20: =J20-J19 -> 0 | L20: =L19 -> 24077798 | M20: =L20-L19 -> 0 | N20: =M20+K20+I20+G20+E20 -> 0 | O20: =IF(B20>0,N20/B20,0) -> 0 | P20: =P19 -> 16726.414 | Q20: =(P20-P19)*1000 -> 0 | R20: =N20-Q20 -> 0 | S20: =S19 -> 10129 | T20: =S20-S19 -> 0 | U20: =U19 -> 422541 | V20: =U20-U19 -> 0 | W20: =W19 -> 32247 | X20: =W20-W19 -> 0 | Y20: =Y19 -> 708695 | Z20: =Y20-Y19 -> 0 | AA20: =AA19 -> 35740 | AB20: =AA20-AA19 -> 0 | AC20: =AC19 -> 924043 | AD20: =AC20-AC19 -> 0 | AE20: =AB20+X20+T20 -> 0 | AF20: =V20+Z20+AD20 -> 0 | AG20: =IF(AE20>0,AF20/AE20,0) -> 0 | AI20: =R20-'EDl log'!B18 -> -930474
A21: ='General information '!F24 -> 0 | B21: =SUM(230*A21) -> 0 | C21: 44274 | D21: =D20 -> 32676972 | E21: =D21-D20 -> 0 | F21: =F20 -> 3979517 | G21: =F21-F20 -> 0 | H21: =H20 -> 17815006 | I21: =H21-H20 -> 0 | J21: =J20 -> 28934822 | K21: =J21-J20 -> 0 | L21: =L20 -> 24077798 | M21: =L21-L20 -> 0 | N21: =M21+K21+I21+G21+E21 -> 0 | O21: =IF(B21>0,N21/B21,0) -> 0 | P21: =P20 -> 16726.414 | Q21: =(P21-P20)*1000 -> 0 | R21: =N21-Q21 -> 0 | S21: =S20 -> 10129 | T21: =S21-S20 -> 0 | U21: =U20 -> 422541 | V21: =U21-U20 -> 0 | W21: =W20 -> 32247 | X21: =W21-W20 -> 0 | Y21: =Y20 -> 708695 | Z21: =Y21-Y20 -> 0 | AA21: =AA20 -> 35740 | AB21: =AA21-AA20 -> 0 | AC21: =AC20 -> 924043 | AD21: =AC21-AC20 -> 0 | AE21: =AB21+X21+T21 -> 0 | AF21: =V21+Z21+AD21 -> 0 | AG21: =IF(AE21>0,AF21/AE21,0) -> 0 | AI21: =R21-'EDl log'!B19 -> -930474
A22: ='General information '!F25 -> 0 | B22: =SUM(230*A22) -> 0 | C22: 44275 | D22: =D21 -> 32676972 | E22: =D22-D21 -> 0 | F22: =F21 -> 3979517 | G22: =F22-F21 -> 0 | H22: =H21 -> 17815006 | I22: =H22-H21 -> 0 | J22: =J21 -> 28934822 | K22: =J22-J21 -> 0 | L22: =L21 -> 24077798 | M22: =L22-L21 -> 0 | N22: =M22+K22+I22+G22+E22 -> 0 | O22: =IF(B22>0,N22/B22,0) -> 0 | P22: =P21 -> 16726.414 | Q22: =(P22-P21)*1000 -> 0 | R22: =N22-Q22 -> 0 | S22: =S21 -> 10129 | T22: =S22-S21 -> 0 | U22: =U21 -> 422541 | V22: =U22-U21 -> 0 | W22: =W21 -> 32247 | X22: =W22-W21 -> 0 | Y22: =Y21 -> 708695 | Z22: =Y22-Y21 -> 0 | AA22: =AA21 -> 35740 | AB22: =AA22-AA21 -> 0 | AC22: =AC21 -> 924043 | AD22: =AC22-AC21 -> 0 | AE22: =AB22+X22+T22 -> 0 | AF22: =V22+Z22+AD22 -> 0 | AG22: =IF(AE22>0,AF22/AE22,0) -> 0 | AI22: =R22-'EDl log'!B20 -> -930474
A23: ='General information '!F26 -> 0 | B23: =SUM(230*A23) -> 0 | C23: 44276 | D23: =D22 -> 32676972 | E23: =D23-D22 -> 0 | F23: =F22 -> 3979517 | G23: =F23-F22 -> 0 | H23: =H22 -> 17815006 | I23: =H23-H22 -> 0 | J23: =J22 -> 28934822 | K23: =J23-J22 -> 0 | L23: =L22 -> 24077798 | M23: =L23-L22 -> 0 | N23: =M23+K23+I23+G23+E23 -> 0 | O23: =IF(B23>0,N23/B23,0) -> 0 | P23: =P22 -> 16726.414 | Q23: =(P23-P22)*1000 -> 0 | R23: =N23-Q23 -> 0 | S23: =S22 -> 10129 | T23: =S23-S22 -> 0 | U23: =U22 -> 422541 | V23: =U23-U22 -> 0 | W23: =W22 -> 32247 | X23: =W23-W22 -> 0 | Y23: =Y22 -> 708695 | Z23: =Y23-Y22 -> 0 | AA23: =AA22 -> 35740 | AB23: =AA23-AA22 -> 0 | AC23: =AC22 -> 924043 | AD23: =AC23-AC22 -> 0 | AE23: =AB23+X23+T23 -> 0 | AF23: =V23+Z23+AD23 -> 0 | AG23: =IF(AE23>0,AF23/AE23,0) -> 0 | AI23: =R23-'EDl log'!B21 -> -930474
A24: ='General information '!F27 -> 0 | B24: =SUM(230*A24) -> 0 | C24: 44277 | D24: =D23 -> 32676972 | E24: =D24-D23 -> 0 | F24: =F23 -> 3979517 | G24: =F24-F23 -> 0 | H24: =H23 -> 17815006 | I24: =H24-H23 -> 0 | J24: =J23 -> 28934822 | K24: =J24-J23 -> 0 | L24: =L23 -> 24077798 | M24: =L24-L23 -> 0 | N24: =M24+K24+I24+G24+E24 -> 0 | O24: =IF(B24>0,N24/B24,0) -> 0 | P24: =P23 -> 16726.414 | Q24: =(P24-P23)*1000 -> 0 | R24: =N24-Q24 -> 0 | S24: =S23 -> 10129 | T24: =S24-S23 -> 0 | U24: =U23 -> 422541 | V24: =U24-U23 -> 0 | W24: =W23 -> 32247 | X24: =W24-W23 -> 0 | Y24: =Y23 -> 708695 | Z24: =Y24-Y23 -> 0 | AA24: =AA23 -> 35740 | AB24: =AA24-AA23 -> 0 | AC24: =AC23 -> 924043 | AD24: =AC24-AC23 -> 0 | AE24: =AB24+X24+T24 -> 0 | AF24: =V24+Z24+AD24 -> 0 | AG24: =IF(AE24>0,AF24/AE24,0) -> 0 | AI24: =R24-'EDl log'!B22 -> -930474
A25: ='General information '!F28 -> 0 | B25: =SUM(230*A25) -> 0 | C25: 44278 | D25: =D24 -> 32676972 | E25: =D25-D24 -> 0 | F25: =F24 -> 3979517 | G25: =F25-F24 -> 0 | H25: =H24 -> 17815006 | I25: =H25-H24 -> 0 | J25: =J24 -> 28934822 | K25: =J25-J24 -> 0 | L25: =L24 -> 24077798 | M25: =L25-L24 -> 0 | N25: =M25+K25+I25+G25+E25 -> 0 | O25: =IF(B25>0,N25/B25,0) -> 0 | P25: =P24 -> 16726.414 | Q25: =(P25-P24)*1000 -> 0 | R25: =N25-Q25 -> 0 | S25: =S24 -> 10129 | T25: =S25-S24 -> 0 | U25: =U24 -> 422541 | V25: =U25-U24 -> 0 | W25: =W24 -> 32247 | X25: =W25-W24 -> 0 | Y25: =Y24 -> 708695 | Z25: =Y25-Y24 -> 0 | AA25: =AA24 -> 35740 | AB25: =AA25-AA24 -> 0 | AC25: =AC24 -> 924043 | AD25: =AC25-AC24 -> 0 | AE25: =AB25+X25+T25 -> 0 | AF25: =V25+Z25+AD25 -> 0 | AG25: =IF(AE25>0,AF25/AE25,0) -> 0 | AI25: =R25-'EDl log'!B23 -> -930474
A26: ='General information '!F29 -> 0 | B26: =SUM(230*A26) -> 0 | C26: 44279 | D26: =D25 -> 32676972 | E26: =D26-D25 -> 0 | F26: =F25 -> 3979517 | G26: =F26-F25 -> 0 | H26: =H25 -> 17815006 | I26: =H26-H25 -> 0 | J26: =J25 -> 28934822 | K26: =J26-J25 -> 0 | L26: =L25 -> 24077798 | M26: =L26-L25 -> 0 | N26: =M26+K26+I26+G26+E26 -> 0 | O26: =IF(B26>0,N26/B26,0) -> 0 | P26: =P25 -> 16726.414 | Q26: =(P26-P25)*1000 -> 0 | R26: =N26-Q26 -> 0 | S26: =S25 -> 10129 | T26: =S26-S25 -> 0 | U26: =U25 -> 422541 | V26: =U26-U25 -> 0 | W26: =W25 -> 32247 | X26: =W26-W25 -> 0 | Y26: =Y25 -> 708695 | Z26: =Y26-Y25 -> 0 | AA26: =AA25 -> 35740 | AB26: =AA26-AA25 -> 0 | AC26: =AC25 -> 924043 | AD26: =AC26-AC25 -> 0 | AE26: =AB26+X26+T26 -> 0 | AF26: =V26+Z26+AD26 -> 0 | AG26: =IF(AE26>0,AF26/AE26,0) -> 0 | AI26: =R26-'EDl log'!B24 -> -930474
A27: ='General information '!F30 -> 0 | B27: =SUM(230*A27) -> 0 | C27: 44280 | D27: =D26 -> 32676972 | E27: =D27-D26 -> 0 | F27: =F26 -> 3979517 | G27: =F27-F26 -> 0 | H27: =H26 -> 17815006 | I27: =H27-H26 -> 0 | J27: =J26 -> 28934822 | K27: =J27-J26 -> 0 | L27: =L26 -> 24077798 | M27: =L27-L26 -> 0 | N27: =M27+K27+I27+G27+E27 -> 0 | O27: =IF(B27>0,N27/B27,0) -> 0 | P27: =P26 -> 16726.414 | Q27: =(P27-P26)*1000 -> 0 | R27: =N27-Q27 -> 0 | S27: =S26 -> 10129 | T27: =S27-S26 -> 0 | U27: =U26 -> 422541 | V27: =U27-U26 -> 0 | W27: =W26 -> 32247 | X27: =W27-W26 -> 0 | Y27: =Y26 -> 708695 | Z27: =Y27-Y26 -> 0 | AA27: =AA26 -> 35740 | AB27: =AA27-AA26 -> 0 | AC27: =AC26 -> 924043 | AD27: =AC27-AC26 -> 0 | AE27: =AB27+X27+T27 -> 0 | AF27: =V27+Z27+AD27 -> 0 | AG27: =IF(AE27>0,AF27/AE27,0) -> 0 | AI27: =R27-'EDl log'!B25 -> -930474
... A30: ='General information '!F33 -> 0 | B30: =SUM(230*A30) -> 0 | C30: 44283 | D30: =D29 -> 32676972 | E30: =D30-D29 -> 0 | F30: =F29 -> 3979517 | G30: =F30-F29 -> 0 | H30: =H29 -> 17815006 | I30: =H30-H29 -> 0 | J30: =J29 -> 28934822 | K30: =J30-J29 -> 0 | L30: =L29 -> 24077798 | M30: =L30-L29 -> 0 | N30: =M30+K30+I30+G30+E30 -> 0 | O30: =IF(B30>0,N30/B30,0) -> 0 | P30: =P29 -> 16726.414 | Q30: =(P30-P29)*1000 -> 0 | R30: =N30-Q30 -> 0 | S30: =S29 -> 10129 | T30: =S30-S29 -> 0 | U30: =U29 -> 422541 | V30: =U30-U29 -> 0 | W30: =W29 -> 32247 | X30: =W30-W29 -> 0 | Y30: =Y29 -> 708695 | Z30: =Y30-Y29 -> 0 | AA30: =AA29 -> 35740 | AB30: =AA30-AA29 -> 0 | AC30: =AC29 -> 924043 | AD30: =AC30-AC29 -> 0 | AE30: =AB30+X30+T30 -> 0 | AF30: =V30+Z30+AD30 -> 0 | AG30: =IF(AE30>0,AF30/AE30,0) -> 0 | AI30: =R30-'EDl log'!B28 -> -930474
C31: 44284 | D31: =D30 -> 32676972 | E31: =D31-D30 -> 0 | F31: =F30 -> 3979517 | G31: =F31-F30 -> 0 | H31: =H30 -> 17815006 | I31: =H31-H30 -> 0 | J31: =J30 -> 28934822 | K31: =J31-J30 -> 0 | L31: =L30 -> 24077798 | M31: =L31-L30 -> 0 | N31: =M31+K31+I31+G31+E31 -> 0 | O31: =IF(B31>0,N31/B31,0) -> 0 | P31: =P30 -> 16726.414 | Q31: =(P31-P30)*1000 -> 0 | R31: =N31-Q31 -> 0 | S31: =S30 -> 10129 | T31: =S31-S30 -> 0 | U31: =U30 -> 422541 | V31: =U31-U30 -> 0 | W31: =W30 -> 32247 | X31: =W31-W30 -> 0 | Y31: =Y30 -> 708695 | Z31: =Y31-Y30 -> 0 | AA31: =AA30 -> 35740 | AB31: =AA31-AA30 -> 0 | AC31: =AC30 -> 924043 | AD31: =AC31-AC30 -> 0 | AE31: =AB31+X31+T31 -> 0 | AF31: =V31+Z31+AD31 -> 0 | AG31: =IF(AE31>0,AF31/AE31,0) -> 0 | AI31: =R31-'EDl log'!B29 -> -930474
C32: 44285 | D32: =D31 -> 32676972 | E32: =D32-D31 -> 0 | F32: =F31 -> 3979517 | G32: =F32-F31 -> 0 | H32: =H31 -> 17815006 | I32: =H32-H31 -> 0 | J32: =J31 -> 28934822 | K32: =J32-J31 -> 0 | L32: =L31 -> 24077798 | M32: =L32-L31 -> 0 | N32: =M32+K32+I32+G32+E32 -> 0 | O32: =IF(B32>0,N32/B32,0) -> 0 | P32: =P31 -> 16726.414 | Q32: =(P32-P31)*1000 -> 0 | R32: =N32-Q32 -> 0 | S32: =S31 -> 10129 | T32: =S32-S31 -> 0 | U32: =U31 -> 422541 | V32: =U32-U31 -> 0 | W32: =W31 -> 32247 | X32: =W32-W31 -> 0 | Y32: =Y31 -> 708695 | Z32: =Y32-Y31 -> 0 | AA32: =AA31 -> 35740 | AB32: =AA32-AA31 -> 0 | AC32: =AC31 -> 924043 | AD32: =AC32-AC31 -> 0 | AE32: =AB32+X32+T32 -> 0 | AF32: =V32+Z32+AD32 -> 0 | AG32: =IF(AE32>0,AF32/AE32,0) -> 0 | AI32: =R32-'EDl log'!B30 -> -930474
C33: 44286 | D33: =D32 -> 32676972 | E33: =D33-D32 -> 0 | F33: =F32 -> 3979517 | G33: =F33-F32 -> 0 | H33: =H32 -> 17815006 | I33: =H33-H32 -> 0 | J33: =J32 -> 28934822 | K33: =J33-J32 -> 0 | L33: =L32 -> 24077798 | M33: =L33-L32 -> 0 | N33: =M33+K33+I33+G33+E33 -> 0 | O33: =IF(B33>0,N33/B33,0) -> 0 | P33: =P32 -> 16726.414 | Q33: =(P33-P32)*1000 -> 0 | R33: =N33-Q33 -> 0 | S33: =S32 -> 10129 | T33: =S33-S32 -> 0 | U33: =U32 -> 422541 | V33: =U33-U32 -> 0 | W33: =W32 -> 32247 | X33: =W33-W32 -> 0 | Y33: =Y32 -> 708695 | Z33: =Y33-Y32 -> 0 | AA33: =AA32 -> 35740 | AB33: =AA33-AA32 -> 0 | AC33: =AC32 -> 924043 | AD33: =AC33-AC32 -> 0 | AE33: =AB33+X33+T33 -> 0 | AF33: =V33+Z33+AD33 -> 0 | AG33: =IF(AE33>0,AF33/AE33,0) -> 0 | AI33: =R33-'EDl log'!B31 -> -930474

Sheet B5
F1: Boiler A | J1: =J37 -> 66.851852 | K1: Boiler B | P1: Boiler C | V1: Boiler | X1: SteamA | AC1: SteamB | AH1: Steam | AI1: Boiler & steam | AL1: Total Boiler Runing H | AM1: Total Steam Runing H | AN1: GAS1 % | AO1: GAS1/L | AP1: GAS2% | AQ1: Gas2/L | AR1: GAS3% | AS1: GAS3/L | AU1: Gas Cons | AV1: Delivery | AW1: Cost/L
B2: Level Tank Gen | C2: Level tank Boiler | D2: Daily Cons Bo. | E2: Boiler litter | F2: Boiler A | G2: Run Hr a | H2: Boiler A fuel | I2: Daily consumption | J2: AVG | K2: index Run H | L2: Run Hrb | M2: Boiler B Fuel | O2: Daily consumption | P2: Boiler C | S2: Run C | U2: Total RH | V2: Total Fuel | X2: SteamA | Y2: Run SA | Z2: Steam A Conter | AA2: Liters | AC2: SteamB | AD2: Run SteamB | AE2: Steam B Conter | AF2: SB Litters | AG2: Avg | AH2: Total Fuel | AI2: Total Fuel
S3: 0
A4: =ELEC!C2 -> 44255 | B4: =[1]B5!B32 -> 218 | C4: =[1]B5!C32 -> 225 | D4: =[1]B5!D32 -> 6 | E4: =[1]B5!E32 -> 50.28 | F4: =[1]B5!F32 -> 1749 | G4: =[1]B5!G32 -> 0 | H4: =[1]B5!H32 -> 6488 | I4: =[1]B5!I32 -> 26 | ... AX4: =[1]B5!AX32 -> 0.8
A5: =ELEC!C3 -> 44256 | B5: 209 | C5: 206 | D5: =C4-C5 -> 19 | E5: =D5*8.38 -> 159.22 | F5: 1752 | G5: =F5-F4 -> 3 | H5: 6668 | I5: =SUM(H5-H4) -> 180 | J5: 1 | K5: =K4 -> 2246 | L5: =K5-K4 -> 0 | M5: =M4 -> 165218 | N5: =M5-M4 -> 0 | O5: =O4 -> 1869 | P5: 2002 | Q5: 169047 | R5: =Q5-Q4 -> 64 | S5: =SUM(P5-P4) -> 1 | T5: =SUM(S5*$T$2) -> 0 | U5: =SUM(G5+L5+S5) -> 4 | V5: =R5+N5+I5:I5 -> 244 | W5: =SUM(V5/U5) -> 61 | X5: 2459 | Y5: =X5-X4 -> 3 | Z5: 138315 | AA5: =Z5-Z4 -> 176.2 | AB5: =SUM(Y5*$AB$2) -> 0 | AC5: =AC4 -> 1935 | AD5: =AC5-AC4 -> 0 | AE5: =AE4 -> 365429 | AF5: =AE5-AE4 -> 0 | AG5: =IF(AD5>0,AF5/AD5,0) -> 0 | AH5: =AF5+AA5 -> 176.2 | AI5: =SUM(AH5+V5) -> 420.2 | AJ5: =-tanks!AW6 -> 420.2 | AK5: =SUM(AJ5-AI5) -> 0 | AL5: =S5+L5+G5 -> 4 | AM5: =Y5+AD5 -> 3 | AN5: =AN4 -> 67 | AO5: =(AN5/100)*3000 -> 2010 | AP5: =AP4 -> 55 | AQ5: =(AP5/100)*3000 -> 1650 | AR5: =AR4 -> 61 | AS5: =(AR5/100)*3000 -> 1830 | AT5: =SUM(AO5+AQ5+AS5) -> 5490 | AU5: =AT4-AT5+AV5 -> 0 | AX5: =IF(AV5>0,AW5,AX4) -> 0.8
A6: =ELEC!C4 -> 44257 | B6: 199 | C6: 205 | D6: =C5-C6 -> 1 | E6: =D6*8.38 -> 8.38 | F6: 1753 | G6: =F6-F5 -> 1 | H6: 6720 | I6: =SUM(H6-H5) -> 52 | J6: =IF(G6>0,I6/G6,0) -> 52 | K6: 2248 | L6: =K6-K5 -> 2 | M6: 165407 | N6: =M6-M5 -> 189 | O6: =O5 -> 1869 | P6: =P5 -> 2002 | Q6: =Q5 -> 169047 | R6: =Q6-Q5 -> 0 | S6: =SUM(P6-P5) -> 0 | T6: =SUM(S6*$T$2) -> 0 | U6: =SUM(G6+L6+S6) -> 3 | V6: =R6+N6+I6:I6 -> 241 | W6: =SUM(V6/U6) -> 80.333333 | X6: 2461 | Y6: =X6-X5 -> 2 | Z6: 138425 | AA6: =Z6-Z5 -> 110 | AB6: =SUM(Y6*$AB$2) -> 0 | AC6: =AC5 -> 1935 | AD6: =AC6-AC5 -> 0 | AE6: =AE5 -> 365429 | AF6: =AE6-AE5 -> 0 | AG6: =IF(AD6>0,AF6/AD6,0) -> 0 | AH6: =AF6+AA6 -> 110 | AI6: =SUM(AH6+V6) -> 351 | AJ6: =-tanks!AW7 -> 351 | AK6: =SUM(AJ6-AI6) -> 0 | AL6: =S6+L6+G6 -> 3 | AM6: =Y6+AD6 -> 2 | AN6: =AN5 -> 67 | AO6: =(AN6/100)*3000 -> 2010 | AP6: =AP5 -> 55 | AQ6: =(AP6/100)*3000 -> 1650 | AR6: =AR5 -> 61 | AS6: =(AR6/100)*3000 -> 1830 | AT6: =SUM(AO6+AQ6+AS6) -> 5490 | AU6: =AT5-AT6+AV6 -> 0 | AX6: =IF(AV6>0,AW6,AX5) -> 0.8
A7: =ELEC!C5 -> 44258 | B7: 193 | C7: 199 | D7: =C6-C7 -> 6 | E7: =D7*8.38 -> 50.28 | F7: =F6 -> 1753 | G7: =F7-F6 -> 0 | H7: =H6 -> 6720 | I7: =SUM(H7-H6) -> 0 | J7: =IF(G7>0,I7/G7,0) -> 0 | K7: 2249 | L7: =K7-K6 -> 1 | M7: 165481 | N7: =M7-M6 -> 74 | O7: =O6 -> 1869 | P7: 2004 | Q7: 169189 | R7: =Q7-Q6 -> 142 | S7: =SUM(P7-P6) -> 2 | T7: =SUM(S7*$T$2) -> 0 | U7: =SUM(G7+L7+S7) -> 3 | V7: =R7+N7+I7:I7 -> 216 | W7: =SUM(V7/U7) -> 72 | X7: =X6 -> 2461 | Y7: =X7-X6 -> 0 | Z7: =Z6 -> 138425 | AA7: =Z7-Z6 -> 0 | AB7: =SUM(Y7*$AB$2) -> 0 | AC7: =AC6 -> 1935 | AD7: =AC7-AC6 -> 0 | AE7: =AE6 -> 365429 | AF7: =AE7-AE6 -> 0 | AG7: =IF(AD7>0,AF7/AD7,0) -> 0 | AH7: =AF7+AA7 -> 0 | AI7: =SUM(AH7+V7) -> 216 | AJ7: =-tanks!AW8 -> 216 | AK7: =SUM(AJ7-AI7) -> 0 | AL7: =S7+L7+G7 -> 3 | AM7: =Y7+AD7 -> 0 | AN7: =AN6 -> 67 | AO7: =(AN7/100)*3000 -> 2010 | AP7: =AP6 -> 55 | AQ7: =(AP7/100)*3000 -> 1650 | AR7: =AR6 -> 61 | AS7: =(AR7/100)*3000 -> 1830 | AT7: =SUM(AO7+AQ7+AS7) -> 5490 | AU7: =AT6-AT7+AV7 -> 0 | AX7: =IF(AV7>0,AW7,AX6) -> 0.8
A8: =ELEC!C6 -> 44259 | B8: 187 | C8: 194 | D8: =C7-C8 -> 5 | E8: =D8*8.38 -> 41.9 | F8: 1755 | G8: =F8-F7 -> 2 | H8: 6869 | I8: =SUM(H8-H7) -> 149 | J8: =IF(G8>0,I8/G8,0) -> 74.5 | K8: =K7 -> 2249 | L8: =K8-K7 -> 0 | M8: =M7 -> 165481 | N8: =M8-M7 -> 0 | O8: =O7 -> 1869 | P8: 2005 | Q8: 169314 | R8: =Q8-Q7 -> 125 | S8: =SUM(P8-P7) -> 1 | T8: =SUM(S8*$T$2) -> 0 | U8: =SUM(G8+L8+S8) -> 3 | V8: =R8+N8+I8:I8 -> 274 | W8: =SUM(V8/U8) -> 91.333333 | X8: =X7 -> 2461 | Y8: =X8-X7 -> 0 | Z8: =Z7 -> 138425 | AA8: =Z8-Z7 -> 0 | AB8: =SUM(Y8*$AB$2) -> 0 | AC8: =AC7 -> 1935 | AD8: =AC8-AC7 -> 0 | AE8: 365467 | AF8: =AE8-AE7 -> 38 | AG8: =IF(AD8>0,AF8/AD8,0) -> 0 | AH8: =AF8+AA8 -> 38 | AI8: =SUM(AH8+V8) -> 312 | AJ8: =-tanks!AW9 -> 312 | AK8: =SUM(AJ8-AI8) -> 0 | AL8: =S8+L8+G8 -> 3 | AM8: =Y8+AD8 -> 0 | AN8: =AN7 -> 67 | AO8: =(AN8/100)*3000 -> 2010 | AP8: =AP7 -> 55 | AQ8: =(AP8/100)*3000 -> 1650 | AR8: =AR7 -> 61 | AS8: =(AR8/100)*3000 -> 1830 | AT8: =SUM(AO8+AQ8+AS8) -> 5490 | AU8: =AT7-AT8+AV8 -> 0 | AX8: =IF(AV8>0,AW8,AX7) -> 0.8
A9: =ELEC!C7 -> 44260 | B9: 208 | C9: 214 | D9: =C8-C9 -> -20 | E9: =D9*8.38 -> -167.6 | F9: 1756 | G9: =F9-F8 -> 1 | H9: 6937 | I9: =SUM(H9-H8) -> 68 | J9: =IF(G9>0,I9/G9,0) -> 68 | K9: 2251 | L9: =K9-K8 -> 2 | M9: 165621 | N9: =M9-M8 -> 140 | O9: =O8 -> 1869 | P9: 2006 | Q9: 169344 | R9: =Q9-Q8 -> 30 | S9: =SUM(P9-P8) -> 1 | T9: =SUM(S9*$T$2) -> 0 | U9: =SUM(G9+L9+S9) -> 4 | V9: =R9+N9+I9:I9 -> 238 | W9: =SUM(V9/U9) -> 59.5 | X9: =X8 -> 2461 | Y9: =X9-X8 -> 0 | Z9: =Z8 -> 138425 | AA9: =Z9-Z8 -> 0 | AB9: =SUM(Y9*$AB$2) -> 0 | AC9: =AC8 -> 1935 | AD9: =AC9-AC8 -> 0 | AE9: =AE8 -> 365467 | AF9: =AE9-AE8 -> 0 | AG9: =IF(AD9>0,AF9/AD9,0) -> 0 | AH9: =AF9+AA9 -> 0 | AI9: =SUM(AH9+V9) -> 238 | AJ9: =-tanks!AW10 -> 238 | AK9: =SUM(AJ9-AI9) -> 0 | AL9: =S9+L9+G9 -> 4 | AM9: =Y9+AD9 -> 0 | AN9: =AN8 -> 67 | AO9: =(AN9/100)*3000 -> 2010 | AP9: =AP8 -> 55 | AQ9: =(AP9/100)*3000 -> 1650 | AR9: =AR8 -> 61 | AS9: =(AR9/100)*3000 -> 1830 | AT9: =SUM(AO9+AQ9+AS9) -> 5490 | AU9: =AT8-AT9+AV9 -> 0 | AX9: =IF(AV9>0,AW9,AX8) -> 0.8
A10: =ELEC!C8 -> 44261 | B10: 202 | C10: 208 | D10: =C9-C10 -> 6 | E10: =D10*8.38 -> 50.28 | F10: =F9 -> 1756 | G10: =F10-F9 -> 0 | H10: 6975 | I10: =SUM(H10-H9) -> 38 | J10: =IF(G10>0,I10/G10,0) -> 0 | K10: 2252 | L10: =K10-K9 -> 1 | M10: 165709 | N10: =M10-M9 -> 88 | O10: =O9 -> 1869 | P10: 2007 | Q10: 169446 | R10: =Q10-Q9 -> 102 | S10: =SUM(P10-P9) -> 1 | T10: =SUM(S10*$T$2) -> 0 | U10: =SUM(G10+L10+S10) -> 2 | V10: =R10+N10+I10:I10 -> 228 | W10: =SUM(V10/U10) -> 114 | X10: =X9 -> 2461 | Y10: =X10-X9 -> 0 | Z10: =Z9 -> 138425 | AA10: =Z10-Z9 -> 0 | AB10: =SUM(Y10*$AB$2) -> 0 | AC10: =AC9 -> 1935 | AD10: =AC10-AC9 -> 0 | AE10: =AE9 -> 365467 | AF10: =AE10-AE9 -> 0 | AG10: =IF(AD10>0,AF10/AD10,0) -> 0 | AH10: =AF10+AA10 -> 0 | AI10: =SUM(AH10+V10) -> 228 | AJ10: =-tanks!AW11 -> 228 | AK10: =SUM(AJ10-AI10) -> 0 | AL10: =S10+L10+G10 -> 2 | AM10: =Y10+AD10 -> 0 | AN10: =AN9 -> 67 | AO10: =(AN10/100)*3000 -> 2010 | AP10: =AP9 -> 55 | AQ10: =(AP10/100)*3000 -> 1650 | AR10: =AR9 -> 61 | AS10: =(AR10/100)*3000 -> 1830 | AT10: =SUM(AO10+AQ10+AS10) -> 5490 | AU10: =AT9-AT10+AV10 -> 0 | AX10: =IF(AV10>0,AW10,AX9) -> 0.8
A11: =ELEC!C9 -> 44262 | B11: 199 | C11: 205 | D11: =C10-C11 -> 3 | E11: =D11*8.38 -> 25.14 | F11: 1759 | G11: =F11-F10 -> 3 | H11: 7205 | I11: =SUM(H11-H10) -> 230 | J11: =IF(G11>0,I11/G11,0) -> 76.666667 | K11: =K10 -> 2252 | L11: =K11-K10 -> 0 | M11: =M10 -> 165709 | N11: =M11-M10 -> 0 | O11: =O10 -> 1869 | P11: =P10 -> 2007 | Q11: =Q10 -> 169446 | R11: =Q11-Q10 -> 0 | S11: =SUM(P11-P10) -> 0 | T11: =SUM(S11*$T$2) -> 0 | U11: =SUM(G11+L11+S11) -> 3 | V11: =R11+N11+I11:I11 -> 230 | W11: =SUM(V11/U11) -> 76.666667 | X11: =X10 -> 2461 | Y11: =X11-X10 -> 0 | Z11: =Z10 -> 138425 | AA11: =Z11-Z10 -> 0 | AB11: =SUM(Y11*$AB$2) -> 0 | AC11: =AC10 -> 1935 | AD11: =AC11-AC10 -> 0 | AE11: =AE10 -> 365467 | AF11: =AE11-AE10 -> 0 | AG11: =IF(AD11>0,AF11/AD11,0) -> 0 | AH11: =AF11+AA11 -> 0 | AI11: =SUM(AH11+V11) -> 230 | AJ11: =-tanks!AW12 -> 230 | AK11: =SUM(AJ11-AI11) -> 0 | AL11: =S11+L11+G11 -> 3 | AM11: =Y11+AD11 -> 0 | AN11: =AN10 -> 67 | AO11: =(AN11/100)*3000 -> 2010 | AP11: =AP10 -> 55 | AQ11: =(AP11/100)*3000 -> 1650 | AR11: =AR10 -> 61 | AS11: =(AR11/100)*3000 -> 1830 | AT11: =SUM(AO11+AQ11+AS11) -> 5490 | AU11: =AT10-AT11+AV11 -> 0 | AX11: =IF(AV11>0,AW11,AX10) -> 0.8
A12: =ELEC!C10 -> 44263 | B12: 194.5 | C12: 201 | D12: =C11-C12 -> 4 | E12: =D12*8.38 -> 33.52 | F12: 1760 | G12: =F12-F11 -> 1 | H12: 7285 | I12: =SUM(H12-H11) -> 80 | J12: =IF(G12>0,I12/G12,0) -> 80 | K12: 2254 | L12: =K12-K11 -> 2 | M12: 165849 | N12: =M12-M11 -> 140 | O12: =O11 -> 1869 | P12: 2008 | Q12: 169516 | R12: =Q12-Q11 -> 70 | S12: =SUM(P12-P11) -> 1 | T12: =SUM(S12*$T$2) -> 0 | U12: =SUM(G12+L12+S12) -> 4 | V12: =R12+N12+I12:I12 -> 290 | W12: =SUM(V12/U12) -> 72.5 | X12: =X11 -> 2461 | Y12: =X12-X11 -> 0 | Z12: =Z11 -> 138425 | AA12: =Z12-Z11 -> 0 | AB12: =SUM(Y12*$AB$2) -> 0 | AC12: =AC11 -> 1935 | AD12: =AC12-AC11 -> 0 | AE12: =AE11 -> 365467 | AF12: =AE12-AE11 -> 0 | AG12: =IF(AD12>0,AF12/AD12,0) -> 0 | AH12: =AF12+AA12 -> 0 | AI12: =SUM(AH12+V12) -> 290 | AJ12: =-tanks!AW13 -> 290 | AK12: =SUM(AJ12-AI12) -> 0 | AL12: =S12+L12+G12 -> 4 | AM12: =Y12+AD12 -> 0 | AN12: =AN11 -> 67 | AO12: =(AN12/100)*3000 -> 2010 | AP12: =AP11 -> 55 | AQ12: =(AP12/100)*3000 -> 1650 | AR12: =AR11 -> 61 | AS12: =(AR12/100)*3000 -> 1830 | AT12: =SUM(AO12+AQ12+AS12) -> 5490 | AU12: =AT11-AT12+AV12 -> 0 | AX12: =IF(AV12>0,AW12,AX11) -> 0.8
A13: =ELEC!C11 -> 44264 | B13: 192 | C13: 198.5 | D13: =C12-C13 -> 2.5 | E13: =D13*8.38 -> 20.95 | F13: =F12 -> 1760 | G13: =F13-F12 -> 0 | H13: =H12 -> 7285 | I13: =SUM(H13-H12) -> 0 | J13: =IF(G13>0,I13/G13,0) -> 0 | K13: 2255 | L13: =K13-K12 -> 1 | M13: 165921 | N13: =M13-M12 -> 72 | O13: =O12 -> 1869 | P13: 2010 | Q13: 169664 | R13: =Q13-Q12 -> 148 | S13: =SUM(P13-P12) -> 2 | T13: =SUM(S13*$T$2) -> 0 | U13: =SUM(G13+L13+S13) -> 3 | V13: =R13+N13+I13:I13 -> 220 | W13: =SUM(V13/U13) -> 73.333333 | X13: =X12 -> 2461 | Y13: =X13-X12 -> 0 | Z13: =Z12 -> 138425 | AA13: =Z13-Z12 -> 0 | AB13: =SUM(Y13*$AB$2) -> 0 | AC13: =AC12 -> 1935 | AD13: =AC13-AC12 -> 0 | AE13: =AE12 -> 365467 | AF13: =AE13-AE12 -> 0 | AG13: =IF(AD13>0,AF13/AD13,0) -> 0 | AH13: =AF13+AA13 -> 0 | AI13: =SUM(AH13+V13) -> 220 | AJ13: =-tanks!AW14 -> 220 | AK13: =SUM(AJ13-AI13) -> 0 | AL13: =S13+L13+G13 -> 3 | AM13: =Y13+AD13 -> 0 | AN13: =AN12 -> 67 | AO13: =(AN13/100)*3000 -> 2010 | AP13: =AP12 -> 55 | AQ13: =(AP13/100)*3000 -> 1650 | AR13: =AR12 -> 61 | AS13: =(AR13/100)*3000 -> 1830 | AT13: =SUM(AO13+AQ13+AS13) -> 5490 | AU13: =AT12-AT13+AV13 -> 0 | AX13: =IF(AV13>0,AW13,AX12) -> 0.8
A14: =ELEC!C12 -> 44265 | B14: 187.5 | C14: 194 | D14: =C13-C14 -> 4.5 | E14: =D14*8.38 -> 37.71 | F14: 1762 | G14: =F14-F13 -> 2 | H14: 7415 | I14: =SUM(H14-H13) -> 130 | J14: =IF(G14>0,I14/G14,0) -> 65 | K14: =K13 -> 2255 | L14: =K14-K13 -> 0 | M14: =M13 -> 165921 | N14: =M14-M13 -> 0 | O14: =O13 -> 1869 | P14: 2011 | Q14: 169745 | R14: =Q14-Q13 -> 81 | S14: =SUM(P14-P13) -> 1 | T14: =SUM(S14*$T$2) -> 0 | U14: =SUM(G14+L14+S14) -> 3 | V14: =R14+N14+I14:I14 -> 211 | W14: =SUM(V14/U14) -> 70.333333 | X14: 2462 | Y14: =X14-X13 -> 1 | Z14: 138490 | AA14: =Z14-Z13 -> 65 | AB14: =SUM(Y14*$AB$2) -> 0 | AC14: =AC13 -> 1935 | AD14: =AC14-AC13 -> 0 | AE14: =AE13 -> 365467 | AF14: =AE14-AE13 -> 0 | AG14: =IF(AD14>0,AF14/AD14,0) -> 0 | AH14: =AF14+AA14 -> 65 | AI14: =SUM(AH14+V14) -> 276 | AJ14: =-tanks!AW15 -> 276 | AK14: =SUM(AJ14-AI14) -> 0 | AL14: =S14+L14+G14 -> 3 | AM14: =Y14+AD14 -> 1 | AN14: =AN13 -> 67 | AO14: =(AN14/100)*3000 -> 2010 | AP14: =AP13 -> 55 | AQ14: =(AP14/100)*3000 -> 1650 | AR14: =AR13 -> 61 | AS14: =(AR14/100)*3000 -> 1830 | AT14: =SUM(AO14+AQ14+AS14) -> 5490 | AU14: =AT13-AT14+AV14 -> 0 | AX14: =IF(AV14>0,AW14,AX13) -> 0.8
A15: =ELEC!C13 -> 44266 | B15: 184 | C15: 190.5 | D15: =C14-C15 -> 3.5 | E15: =D15*8.38 -> 29.33 | F15: 1763 | G15: =F15-F14 -> 1 | H15: 7522 | I15: =SUM(H15-H14) -> 107 | J15: =IF(G15>0,I15/G15,0) -> 107 | K15: 2257 | L15: =K15-K14 -> 2 | M15: 166056 | N15: =M15-M14 -> 135 | O15: =O14 -> 1869 | P15: =P14 -> 2011 | Q15: =Q14 -> 169745 | R15: =Q15-Q14 -> 0 | S15: =SUM(P15-P14) -> 0 | T15: =SUM(S15*$T$2) -> 0 | U15: =SUM(G15+L15+S15) -> 3 | V15: =R15+N15+I15:I15 -> 242 | W15: =SUM(V15/U15) -> 80.666667 | X15: =X14 -> 2462 | Y15: =X15-X14 -> 0 | Z15: =Z14 -> 138490 | AA15: =Z15-Z14 -> 0 | AB15: =SUM(Y15*$AB$2) -> 0 | AC15: =AC14 -> 1935 | AD15: =AC15-AC14 -> 0 | AE15: =AE14 -> 365467 | AF15: =AE15-AE14 -> 0 | AG15: =IF(AD15>0,AF15/AD15,0) -> 0 | AH15: =AF15+AA15 -> 0 | AI15: =SUM(AH15+V15) -> 242 | AJ15: =-tanks!AW16 -> 242 | AK15: =SUM(AJ15-AI15) -> 0 | AL15: =S15+L15+G15 -> 3 | AM15: =Y15+AD15 -> 0 | AN15: =AN14 -> 67 | AO15: =(AN15/100)*3000 -> 2010 | AP15: =AP14 -> 55 | AQ15: =(AP15/100)*3000 -> 1650 | AR15: =AR14 -> 61 | AS15: =(AR15/100)*3000 -> 1830 | AT15: =SUM(AO15+AQ15+AS15) -> 5490 | AU15: =AT14-AT15+AV15 -> 0 | AX15: =IF(AV15>0,AW15,AX14) -> 0.8
A16: =ELEC!C14 -> 44267 | B16: 181 | C16: 187.5 | D16: =C15-C16 -> 3 | E16: =D16*8.38 -> 25.14 | F16: =F15 -> 1763 | G16: =F16-F15 -> 0 | H16: =H15 -> 7522 | I16: =SUM(H16-H15) -> 0 | J16: =IF(G16>0,I16/G16,0) -> 0 | K16: 2258 | L16: =K16-K15 -> 1 | M16: 166149 | N16: =M16-M15 -> 93 | O16: =O15 -> 1869 | P16: 2013 | Q16: 169909 | R16: =Q16-Q15 -> 164 | S16: =SUM(P16-P15) -> 2 | T16: =SUM(S16*$T$2) -> 0 | U16: =SUM(G16+L16+S16) -> 3 | V16: =R16+N16+I16:I16 -> 257 | W16: =SUM(V16/U16) -> 85.666667 | X16: =X15 -> 2462 | Y16: =X16-X15 -> 0 | Z16: =Z15 -> 138490 | AA16: =Z16-Z15 -> 0 | AB16: =SUM(Y16*$AB$2) -> 0 | AC16: =AC15 -> 1935 | AD16: =AC16-AC15 -> 0 | AE16: =AE15 -> 365467 | AF16: =AE16-AE15 -> 0 | AG16: =IF(AD16>0,AF16/AD16,0) -> 0 | AH16: =AF16+AA16 -> 0 | AI16: =SUM(AH16+V16) -> 257 | AJ16: =-tanks!AW17 -> 257 | AK16: =SUM(AJ16-AI16) -> 0 | AL16: =S16+L16+G16 -> 3 | AM16: =Y16+AD16 -> 0 | AN16: =AN15 -> 67 | AO16: =(AN16/100)*3000 -> 2010 | AP16: =AP15 -> 55 | AQ16: =(AP16/100)*3000 -> 1650 | AR16: =AR15 -> 61 | AS16: =(AR16/100)*3000 -> 1830 | AT16: =SUM(AO16+AQ16+AS16) -> 5490 | AU16: =AT15-AT16+AV16 -> 0 | AX16: =IF(AV16>0,AW16,AX15) -> 0.8
A17: =ELEC!C15 -> 44268 | B17: 178 | C17: 184 | D17: =C16-C17 -> 3.5 | E17: =D17*8.38 -> 29.33 | F17: 1765 | G17: =F17-F16 -> 2 | H17: 7677 | I17: =SUM(H17-H16) -> 155 | J17: =IF(G17>0,I17/G17,0) -> 77.5 | K17: =K16 -> 2258 | L17: =K17-K16 -> 0 | M17: =M16 -> 166149 | N17: =M17-M16 -> 0 | O17: =O16 -> 1869 | P17: 2014 | Q17: 169987 | R17: =Q17-Q16 -> 78 | S17: =SUM(P17-P16) -> 1 | T17: =SUM(S17*$T$2) -> 0 | U17: =SUM(G17+L17+S17) -> 3 | V17: =R17+N17+I17:I17 -> 233 | X17: =X16 -> 2462 | Y17: =X17-X16 -> 0 | Z17: =Z16 -> 138490 | AA17: =Z17-Z16 -> 0 | AB17: =SUM(Y17*$AB$2) -> 0 | AC17: =AC16 -> 1935 | AD17: =AC17-AC16 -> 0 | AE17: =AE16 -> 365467 | AF17: =AE17-AE16 -> 0 | AG17: =IF(AD17>0,AF17/AD17,0) -> 0 | AH17: =AF17+AA17 -> 0 | AI17: =SUM(AH17+V17) -> 233 | AJ17: =-tanks!AW18 -> 233 | AK17: =SUM(AJ17-AI17) -> 0 | AL17: =S17+L17+G17 -> 3 | AM17: =Y17+AD17 -> 0 | AN17: =AN16 -> 67 | AO17: =(AN17/100)*3000 -> 2010 | AP17: =AP16 -> 55 | AQ17: =(AP17/100)*3000 -> 1650 | AR17: =AR16 -> 61 | AS17: =(AR17/100)*3000 -> 1830 | AT17: =SUM(AO17+AQ17+AS17) -> 5490 | AU17: =AT16-AT17+AV17 -> 0 | AX17: =IF(AV17>0,AW17,AX16) -> 0.8
A18: =ELEC!C16 -> 44269 | B18: =B17 -> 178 | C18: =C17 -> 184 | D18: =C17-C18 -> 0 | E18: =D18*8.38 -> 0 | F18: =F17 -> 1765 | G18: =F18-F17 -> 0 | H18: =H17 -> 7677 | I18: =SUM(H18-H17) -> 0 | J18: =IF(G18>0,I18/G18,0) -> 0 | K18: =K17 -> 2258 | L18: =K18-K17 -> 0 | M18: =M17 -> 166149 | N18: =M18-M17 -> 0 | O18: 1869 | P18: =P17 -> 2014 | Q18: =Q17 -> 169987 | R18: =Q18-Q17 -> 0 | S18: =SUM(P18-P17) -> 0 | T18: =SUM(S18*$T$2) -> 0 | U18: =SUM(G18+L18+S18) -> 0 | V18: =R18+N18+I18:I18 -> 0 | X18: =X17 -> 2462 | Y18: =X18-X17 -> 0 | Z18: =Z17 -> 138490 | AA18: =Z18-Z17 -> 0 | AB18: =SUM(Y18*$AB$2) -> 0 | AC18: =AC17 -> 1935 | AD18: =AC18-AC17 -> 0 | AE18: =AE17 -> 365467 | AF18: =AE18-AE17 -> 0 | AG18: =IF(AD18>0,AF18/AD18,0) -> 0 | AH18: =AF18+AA18 -> 0 | AI18: =SUM(AH18+V18) -> 0 | AJ18: =-tanks!AW19 -> 0 | AK18: =SUM(AJ18-AI18) -> 0 | AL18: =S18+L18+G18 -> 0 | AM18: =Y18+AD18 -> 0 | AN18: =AN17 -> 67 | AO18: =(AN18/100)*3000 -> 2010 | AP18: =AP17 -> 55 | AQ18: =(AP18/100)*3000 -> 1650 | AR18: =AR17 -> 61 | AS18: =(AR18/100)*3000 -> 1830 | AT18: =SUM(AO18+AQ18+AS18) -> 5490 | AU18: =AT17-AT18+AV18 -> 0 | AX18: =IF(AV18>0,AW18,AX17) -> 0.8
A19: =ELEC!C17 -> 44270 | B19: =B18 -> 178 | C19: =C18 -> 184 | D19: =C18-C19 -> 0 | E19: =D19*8.38 -> 0 | F19: =F18 -> 1765 | G19: =F19-F18 -> 0 | H19: =H18 -> 7677 | I19: =SUM(H19-H18) -> 0 | J19: =IF(G19>0,I19/G19,0) -> 0 | K19: =K18 -> 2258 | L19: =K19-K18 -> 0 | M19: =M18 -> 166149 | N19: =M19-M18 -> 0 | O19: =O18 -> 1869 | P19: =P18 -> 2014 | Q19: =Q18 -> 169987 | R19: =Q19-Q18 -> 0 | S19: =SUM(P19-P18) -> 0 | T19: =SUM(S19*$T$2) -> 0 | U19: =SUM(G19+L19+S19) -> 0 | V19: =R19+N19+I19:I19 -> 0 | X19: =X18 -> 2462 | Y19: =X19-X18 -> 0 | Z19: =Z18 -> 138490 | AA19: =Z19-Z18 -> 0 | AB19: =SUM(Y19*$AB$2) -> 0 | AC19: =AC18 -> 1935 | AD19: =AC19-AC18 -> 0 | AE19: =AE18 -> 365467 | AF19: =AE19-AE18 -> 0 | AG19: =IF(AD19>0,AF19/AD19,0) -> 0 | AH19: =AF19+AA19 -> 0 | AI19: =SUM(AH19+V19) -> 0 | AJ19: =-tanks!AW20 -> 0 | AK19: =SUM(AJ19-AI19) -> 0 | AL19: =S19+L19+G19 -> 0 | AM19: =Y19+AD19 -> 0 | AN19: =AN18 -> 67 | AO19: =(AN19/100)*3000 -> 2010 | AP19: =AP18 -> 55 | AQ19: =(AP19/100)*3000 -> 1650 | AR19: =AR18 -> 61 | AS19: =(AR19/100)*3000 -> 1830 | AT19: =SUM(AO19+AQ19+AS19) -> 5490 | AU19: =AT18-AT19+AV19 -> 0 | AX19: =IF(AV19>0,AW19,AX18) -> 0.8
A20: =ELEC!C18 -> 44271 | B20: =B19 -> 178 | C20: =C19 -> 184 | D20: =C19-C20 -> 0 | E20: =D20*8.38 -> 0 | F20: =F19 -> 1765 | G20: =F20-F19 -> 0 | H20: =H19 -> 7677 | I20: =SUM(H20-H19) -> 0 | J20: =IF(G20>0,I20/G20,0) -> 0 | K20: =K19 -> 2258 | L20: =K20-K19 -> 0 | M20: =M19 -> 166149 | N20: =M20-M19 -> 0 | O20: =O19 -> 1869 | P20: =P19 -> 2014 | Q20: =Q19 -> 169987 | R20: =Q20-Q19 -> 0 | S20: =SUM(P20-P19) -> 0 | T20: =SUM(S20*$T$2) -> 0 | U20: =SUM(G20+L20+S20) -> 0 | V20: =R20+N20+I20:I20 -> 0 | X20: =X19 -> 2462 | Y20: =X20-X19 -> 0 | Z20: =Z19 -> 138490 | AA20: =Z20-Z19 -> 0 | AB20: =SUM(Y20*$AB$2) -> 0 | AC20: =AC19 -> 1935 | AD20: =AC20-AC19 -> 0 | AE20: =AE19 -> 365467 | AF20: =AE20-AE19 -> 0 | AG20: =IF(AD20>0,AF20/AD20,0) -> 0 | AH20: =AF20+AA20 -> 0 | AI20: =SUM(AH20+V20) -> 0 | AJ20: =-tanks!AW21 -> 0 | AK20: =SUM(AJ20-AI20) -> 0 | AL20: =S20+L20+G20 -> 0 | AM20: =Y20+AD20 -> 0 | AN20: =AN19 -> 67 | AO20: =(AN20/100)*3000 -> 2010 | AP20: =AP19 -> 55 | AQ20: =(AP20/100)*3000 -> 1650 | AR20: =AR19 -> 61 | AS20: =(AR20/100)*3000 -> 1830 | AT20: =SUM(AO20+AQ20+AS20) -> 5490 | AU20: =AT19-AT20+AV20 -> 0 | AX20: =IF(AV20>0,AW20,AX19) -> 0.8
A21: =ELEC!C19 -> 44272 | B21: =B20 -> 178 | C21: =C20 -> 184 | D21: =C20-C21 -> 0 | E21: =D21*8.38 -> 0 | F21: =F20 -> 1765 | G21: =F21-F20 -> 0 | H21: =H20 -> 7677 | I21: =SUM(H21-H20) -> 0 | J21: =IF(G21>0,I21/G21,0) -> 0 | K21: =K20 -> 2258 | L21: =K21-K20 -> 0 | M21: =M20 -> 166149 | N21: =M21-M20 -> 0 | O21: =O20 -> 1869 | P21: =P20 -> 2014 | Q21: =Q20 -> 169987 | R21: =Q21-Q20 -> 0 | S21: =SUM(P21-P20) -> 0 | T21: =SUM(S21*$T$2) -> 0 | U21: =SUM(G21+L21+S21) -> 0 | V21: =R21+N21+I21:I21 -> 0 | X21: =X20 -> 2462 | Y21: =X21-X20 -> 0 | Z21: =Z20 -> 138490 | AA21: =Z21-Z20 -> 0 | AB21: =SUM(Y21*$AB$2) -> 0 | AC21: =AC20 -> 1935 | AD21: =AC21-AC20 -> 0 | AE21: =AE20 -> 365467 | AF21: =AE21-AE20 -> 0 | AG21: =IF(AD21>0,AF21/AD21,0) -> 0 | AH21: =AF21+AA21 -> 0 | AI21: =SUM(AH21+V21) -> 0 | AJ21: =-tanks!AW22 -> 0 | AK21: =SUM(AJ21-AI21) -> 0 | AL21: =S21+L21+G21 -> 0 | AM21: =Y21+AD21 -> 0 | AN21: =AN20 -> 67 | AO21: =(AN21/100)*3000 -> 2010 | AP21: =AP20 -> 55 | AQ21: =(AP21/100)*3000 -> 1650 | AR21: =AR20 -> 61 | AS21: =(AR21/100)*3000 -> 1830 | AT21: =SUM(AO21+AQ21+AS21) -> 5490 | AU21: =AT20-AT21+AV21 -> 0 | AX21: =IF(AV21>0,AW21,AX20) -> 0.8
A22: =ELEC!C20 -> 44273 | B22: =B21 -> 178 | C22: =C21 -> 184 | D22: =C21-C22 -> 0 | E22: =D22*8.38 -> 0 | F22: =F21 -> 1765 | G22: =F22-F21 -> 0 | H22: =H21 -> 7677 | I22: =SUM(H22-H21) -> 0 | J22: =IF(G22>0,I22/G22,0) -> 0 | K22: =K21 -> 2258 | L22: =K22-K21 -> 0 | M22: =M21 -> 166149 | N22: =M22-M21 -> 0 | O22: =O21 -> 1869 | P22: =P21 -> 2014 | Q22: =Q21 -> 169987 | R22: =Q22-Q21 -> 0 | S22: =SUM(P22-P21) -> 0 | T22: =SUM(S22*$T$2) -> 0 | U22: =SUM(G22+L22+S22) -> 0 | V22: =R22+N22+I22:I22 -> 0 | X22: =X21 -> 2462 | Y22: =X22-X21 -> 0 | Z22: =Z21 -> 138490 | AA22: =Z22-Z21 -> 0 | AB22: =SUM(Y22*$AB$2) -> 0 | AC22: =AC21 -> 1935 | AD22: =AC22-AC21 -> 0 | AE22: =AE21 -> 365467 | AF22: =AE22-AE21 -> 0 | AG22: =IF(AD22>0,AF22/AD22,0) -> 0 | AH22: =AF22+AA22 -> 0 | AI22: =SUM(AH22+V22) -> 0 | AJ22: =-tanks!AW23 -> 0 | AK22: =SUM(AJ22-AI22) -> 0 | AL22: =S22+L22+G22 -> 0 | AM22: =Y22+AD22 -> 0 | AN22: =AN21 -> 67 | AO22: =(AN22/100)*3000 -> 2010 | AP22: =AP21 -> 55 | AQ22: =(AP22/100)*3000 -> 1650 | AR22: =AR21 -> 61 | AS22: =(AR22/100)*3000 -> 1830 | AT22: =SUM(AO22+AQ22+AS22) -> 5490 | AU22: =AT21-AT22+AV22 -> 0 | AX22: =IF(AV22>0,AW22,AX21) -> 0.8
A23: =[3]ELEC!C21 -> 44215 | B23: =B22 -> 178 | C23: =C22 -> 184 | D23: =C22-C23 -> 0 | E23: =D23*8.38 -> 0 | F23: =F22 -> 1765 | G23: =F23-F22 -> 0 | H23: =H22 -> 7677 | I23: =SUM(H23-H22) -> 0 | J23: =IF(G23>0,I23/G23,0) -> 0 | K23: =K22 -> 2258 | L23: =K23-K22 -> 0 | M23: =M22 -> 166149 | N23: =M23-M22 -> 0 | O23: =O22 -> 1869 | P23: =P22 -> 2014 | Q23: =Q22 -> 169987 | R23: =Q23-Q22 -> 0 | S23: =SUM(P23-P22) -> 0 | T23: =SUM(S23*$T$2) -> 0 | U23: =SUM(G23+L23+S23) -> 0 | V23: =R23+N23+I23:I23 -> 0 | X23: =X22 -> 2462 | Y23: =X23-X22 -> 0 | Z23: =Z22 -> 138490 | AA23: =Z23-Z22 -> 0 | AB23: =SUM(Y23*$AB$2) -> 0 | AC23: =AC22 -> 1935 | AD23: =AC23-AC22 -> 0 | AE23: =AE22 -> 365467 | AF23: =AE23-AE22 -> 0 | AG23: =IF(AD23>0,AF23/AD23,0) -> 0 | AH23: =AF23+AA23 -> 0 | AI23: =SUM(AH23+V23) -> 0 | AJ23: =-tanks!AW24 -> 0 | AK23: =SUM(AJ23-AI23) -> 0 | AL23: =S23+L23+G23 -> 0 | AM23: =Y23+AD23 -> 0 | AN23: =AN22 -> 67 | AO23: =(AN23/100)*3000 -> 2010 | AP23: =AP22 -> 55 | AQ23: =(AP23/100)*3000 -> 1650 | AR23: =AR22 -> 61 | AS23: =(AR23/100)*3000 -> 1830 | AT23: =SUM(AO23+AQ23+AS23) -> 5490 | AU23: =AT22-AT23+AV23 -> 0 | AX23: =IF(AV23>0,AW23,AX22) -> 0.8
A24: =ELEC!C22 -> 44275 | B24: =B23 -> 178 | C24: =C23 -> 184 | D24: =C23-C24 -> 0 | E24: =D24*8.38 -> 0 | F24: =F23 -> 1765 | G24: =F24-F23 -> 0 | H24: =H23 -> 7677 | I24: =SUM(H24-H23) -> 0 | J24: =IF(G24>0,I24/G24,0) -> 0 | K24: =K23 -> 2258 | L24: =K24-K23 -> 0 | M24: =M23 -> 166149 | N24: =M24-M23 -> 0 | O24: =O23 -> 1869 | P24: =P23 -> 2014 | Q24: =Q23 -> 169987 | R24: =Q24-Q23 -> 0 | S24: =SUM(P24-P23) -> 0 | T24: =SUM(S24*$T$2) -> 0 | U24: =SUM(G24+L24+S24) -> 0 | V24: =R24+N24+I24:I24 -> 0 | X24: =X23 -> 2462 | Y24: =X24-X23 -> 0 | Z24: =Z23 -> 138490 | AA24: =Z24-Z23 -> 0 | AB24: =SUM(Y24*$AB$2) -> 0 | AC24: =AC23 -> 1935 | AD24: =AC24-AC23 -> 0 | AE24: =AE23 -> 365467 | AF24: =AE24-AE23 -> 0 | AG24: =IF(AD24>0,AF24/AD24,0) -> 0 | AH24: =AF24+AA24 -> 0 | AI24: =SUM(AH24+V24) -> 0 | AJ24: =-tanks!AW25 -> 0 | AK24: =SUM(AJ24-AI24) -> 0 | AL24: =S24+L24+G24 -> 0 | AM24: =Y24+AD24 -> 0 | AN24: =AN23 -> 67 | AO24: =(AN24/100)*3000 -> 2010 | AP24: =AP23 -> 55 | AQ24: =(AP24/100)*3000 -> 1650 | AR24: =AR23 -> 61 | AS24: =(AR24/100)*3000 -> 1830 | AT24: =SUM(AO24+AQ24+AS24) -> 5490 | AU24: =AT23-AT24+AV24 -> 0 | AX24: =IF(AV24>0,AW24,AX23) -> 0.8
A25: =ELEC!C23 -> 44276 | B25: =B24 -> 178 | C25: =C24 -> 184 | D25: =C24-C25 -> 0 | E25: =D25*8.38 -> 0 | F25: =F24 -> 1765 | G25: =F25-F24 -> 0 | H25: =H24 -> 7677 | I25: =SUM(H25-H24) -> 0 | J25: =IF(G25>0,I25/G25,0) -> 0 | K25: =K24 -> 2258 | L25: =K25-K24 -> 0 | M25: =M24 -> 166149 | N25: =M25-M24 -> 0 | O25: =O24 -> 1869 | P25: =P24 -> 2014 | Q25: =Q24 -> 169987 | R25: =Q25-Q24 -> 0 | S25: =SUM(P25-P24) -> 0 | T25: =SUM(S25*$T$2) -> 0 | U25: =SUM(G25+L25+S25) -> 0 | V25: =R25+N25+I25:I25 -> 0 | X25: =X24 -> 2462 | Y25: =X25-X24 -> 0 | Z25: =Z24 -> 138490 | AA25: =Z25-Z24 -> 0 | AB25: =SUM(Y25*$AB$2) -> 0 | AC25: =AC24 -> 1935 | AD25: =AC25-AC24 -> 0 | AE25: =AE24 -> 365467 | AF25: =AE25-AE24 -> 0 | AG25: =IF(AD25>0,AF25/AD25,0) -> 0 | AH25: =AF25+AA25 -> 0 | AI25: =SUM(AH25+V25) -> 0 | AJ25: =-tanks!AW26 -> 0 | AK25: =SUM(AJ25-AI25) -> 0 | AL25: =S25+L25+G25 -> 0 | AM25: =Y25+AD25 -> 0 | AN25: =AN24 -> 67 | AO25: =(AN25/100)*3000 -> 2010 | AP25: =AP24 -> 55 | AQ25: =(AP25/100)*3000 -> 1650 | AR25: =AR24 -> 61 | AS25: =(AR25/100)*3000 -> 1830 | AT25: =SUM(AO25+AQ25+AS25) -> 5490 | AU25: =AT24-AT25+AV25 -> 0 | AX25: =IF(AV25>0,AW25,AX24) -> 0.8
A26: =ELEC!C24 -> 44277 | B26: =B25 -> 178 | C26: =C25 -> 184 | D26: =C25-C26 -> 0 | E26: =D26*8.38 -> 0 | F26: =F25 -> 1765 | G26: =F26-F25 -> 0 | H26: =H25 -> 7677 | I26: =SUM(H26-H25) -> 0 | J26: =IF(G26>0,I26/G26,0) -> 0 | K26: =K25 -> 2258 | L26: =K26-K25 -> 0 | M26: =M25 -> 166149 | N26: =M26-M25 -> 0 | O26: =O25 -> 1869 | P26: =P25 -> 2014 | Q26: =Q25 -> 169987 | R26: =Q26-Q25 -> 0 | S26: =SUM(P26-P25) -> 0 | T26: =SUM(S26*$T$2) -> 0 | U26: =SUM(G26+L26+S26) -> 0 | V26: =R26+N26+I26:I26 -> 0 | X26: =X25 -> 2462 | Y26: =X26-X25 -> 0 | Z26: =Z25 -> 138490 | AA26: =Z26-Z25 -> 0 | AB26: =SUM(Y26*$AB$2) -> 0 | AC26: =AC25 -> 1935 | AD26: =AC26-AC25 -> 0 | AE26: =AE25 -> 365467 | AF26: =AE26-AE25 -> 0 | AG26: =IF(AD26>0,AF26/AD26,0) -> 0 | AH26: =AF26+AA26 -> 0 | AI26: =SUM(AH26+V26) -> 0 | AJ26: =-tanks!AW27 -> 0 | AK26: =SUM(AJ26-AI26) -> 0 | AL26: =S26+L26+G26 -> 0 | AM26: =Y26+AD26 -> 0 | AN26: =AN25 -> 67 | AO26: =(AN26/100)*3000 -> 2010 | AP26: =AP25 -> 55 | AQ26: =(AP26/100)*3000 -> 1650 | AR26: =AR25 -> 61 | AS26: =(AR26/100)*3000 -> 1830 | AT26: =SUM(AO26+AQ26+AS26) -> 5490 | AU26: =AT25-AT26+AV26 -> 0 | AX26: =IF(AV26>0,AW26,AX25) -> 0.8
