Workbook

Sheet TOTAL
A1: Site Name | B1: Day | C1: Month | D1: Year | E1: Total Electricity Kwh | F1: Electricity Tariff ($/Kwh) | G1: Natual Gas (m3) | H1: Natural Gas $/m3 | I1: Water Utility Supply (m3) m3 | J1: Water Utility Supply (m3) $/m3 | K1: Room Nights | L1: Total Guests | M1: Utilities day cost dh
A2: Mumbai | B2: 1 | C2: 2 | D2: 2021 | E2: ='Daily HLP'!I4 -> 19291 | F2: ='Daily HLP'!J4 -> 9 | G2: ='Daily HLP'!M4 -> 797.95 | H2: 44 | I2: ='Daily HLP'!P4 -> 171 | J2: 100 | K2: =Occupancy!G2 -> 91 | L2: 327 | M2: =E2*F2+G2*H2+#REF!*#REF!+I2*J2 -> #REF!
A3: Mumbai | B3: =B2+1 -> 2 | C3: 2 | D3: 2021 | E3: ='Daily HLP'!I5 -> 19381 | F3: =F2 -> 9 | G3: ='Daily HLP'!M5 -> 860.9 | H3: 44 | I3: ='Daily HLP'!P5 -> 171 | J3: 100 | K3: =Occupancy!G3 -> 120 | L3: 310 | M3: =E3*F3+G3*H3+#REF!*#REF!+I3*J3 -> #REF!
A4: Mumbai | B4: =B3+1 -> 3 | C4: 2 | D4: 2021 | E4: ='Daily HLP'!I6 -> 19375 | F4: =F3 -> 9 | G4: ='Daily HLP'!M6 -> 873 | H4: 44 | I4: ='Daily HLP'!P6 -> 161 | J4: 100 | K4: =Occupancy!G4 -> 112 | L4: 386 | M4: =E4*F4+G4*H4+#REF!*#REF!+I4*J4 -> #REF!
A5: Mumbai | B5: =B4+1 -> 4 | C5: 2 | D5: 2021 | E5: ='Daily HLP'!I7 -> 18251 | F5: =F4 -> 9 | G5: ='Daily HLP'!M7 -> 796 | H5: 44 | I5: ='Daily HLP'!P7 -> 150 | J5: 100 | K5: =Occupancy!G5 -> 112 | L5: 558 | M5: =E5*F5+G5*H5+#REF!*#REF!+I5*J5 -> #REF!
A6: Mumbai | B6: =B5+1 -> 5 | C6: 2 | D6: 2021 | E6: ='Daily HLP'!I8 -> 18524 | F6: =F5 -> 9 | G6: ='Daily HLP'!M8 -> 778 | H6: 44 | I6: ='Daily HLP'!P8 -> 181 | J6: 100 | K6: =Occupancy!G6 -> 105 | L6: 416 | M6: =E6*F6+G6*H6+#REF!*#REF!+I6*J6 -> #REF!
A7: Mumbai | B7: =B6+1 -> 6 | C7: 2 | D7: 2021 | E7: ='Daily HLP'!I9 -> 19190 | F7: =F6 -> 9 | G7: ='Daily HLP'!M9 -> 814 | H7: 44 | I7: ='Daily HLP'!P9 -> 271 | J7: 100 | K7: =Occupancy!G7 -> 150 | L7: 582 | M7: =E7*F7+G7*H7+#REF!*#REF!+I7*J7 -> #REF!
A8: Mumbai | B8: =B7+1 -> 7 | C8: 2 | D8: 2021 | E8: ='Daily HLP'!I10 -> 18255 | F8: =F7 -> 9 | G8: ='Daily HLP'!M10 -> 844.45 | H8: 44 | I8: ='Daily HLP'!P10 -> 212 | J8: 100 | K8: =Occupancy!G8 -> 107 | L8: 437 | M8: =E8*F8+G8*H8+#REF!*#REF!+I8*J8 -> #REF!
A9: Mumbai | B9: =B8+1 -> 8 | C9: 2 | D9: 2021 | E9: ='Daily HLP'!I11 -> 15387 | F9: =F8 -> 9 | G9: ='Daily HLP'!M11 -> 816.28 | H9: 44 | I9: ='Daily HLP'!P11 -> 211 | J9: 100 | K9: =Occupancy!G9 -> 120 | L9: 355 | M9: =E9*F9+G9*H9+#REF!*#REF!+I9*J9 -> #REF!
A10: Mumbai | B10: =B9+1 -> 9 | C10: 2 | D10: 2021 | E10: ='Daily HLP'!I12 -> 18397 | F10: =F9 -> 9 | G10: ='Daily HLP'!M12 -> 637.05 | H10: 44 | I10: ='Daily HLP'!P12 -> 192 | J10: 100 | K10: =Occupancy!G10 -> 125 | L10: 382 | M10: =E10*F10+G10*H10+#REF!*#REF!+I10*J10 -> #REF!
A11: Mumbai | B11: =B10+1 -> 10 | C11: 2 | D11: 2021 | E11: ='Daily HLP'!I13 -> 18869 | F11: =F10 -> 9 | G11: ='Daily HLP'!M13 -> 899.1 | H11: 44 | I11: ='Daily HLP'!P13 -> 250 | J11: 100 | K11: =Occupancy!G11 -> 142 | L11: 434 | M11: =E11*F11+G11*H11+#REF!*#REF!+I11*J11 -> #REF!
A12: Mumbai | B12: =B11+1 -> 11 | C12: 2 | D12: 2021 | E12: ='Daily HLP'!I14 -> 18625 | F12: =F11 -> 9 | G12: ='Daily HLP'!M14 -> 887.12 | H12: 44 | I12: ='Daily HLP'!P14 -> 211 | J12: 100 | K12: =Occupancy!G12 -> 122 | L12: 309 | M12: =E12*F12+G12*H12+#REF!*#REF!+I12*J12 -> #REF!
A13: Mumbai | B13: =B12+1 -> 12 | C13: 2 | D13: 2021 | E13: ='Daily HLP'!I15 -> 19448 | F13: =F12 -> 9 | G13: ='Daily HLP'!M15 -> 914.918 | H13: 44 | I13: ='Daily HLP'!P15 -> 211 | J13: 100 | K13: =Occupancy!G13 -> 131 | L13: 505 | M13: =E13*F13+G13*H13+#REF!*#REF!+I13*J13 -> #REF!
A14: Mumbai | B14: =B13+1 -> 13 | C14: 2 | D14: 2021 | E14: ='Daily HLP'!I16 -> 20224 | F14: =F13 -> 9 | G14: ='Daily HLP'!M16 -> 1043.67 | H14: 44 | I14: ='Daily HLP'!P16 -> 272 | J14: 100 | K14: =Occupancy!G14 -> 195 | L14: 581 | M14: =E14*F14+G14*H14+#REF!*#REF!+I14*J14 -> #REF!
... A20: Mumbai | B20: =B19+1 -> 19 | C20: 2 | D20: 2021 | E20: ='Daily HLP'!I22 -> 19578 | F20: =F19 -> 9 | G20: ='Daily HLP'!M22 -> 881.41 | H20: 44 | I20: ='Daily HLP'!P22 -> 190 | J20: 100 | K20: =Occupancy!G20 -> 163 | L20: 459 | M20: =E20*F20+G20*H20+#REF!*#REF!+I20*J20 -> #REF!
A21: Mumbai | B21: =B20+1 -> 20 | C21: 2 | D21: 2021 | E21: ='Daily HLP'!I23 -> 19799 | F21: =F20 -> 9 | G21: ='Daily HLP'!M23 -> 1086 | H21: 44 | I21: ='Daily HLP'!P23 -> 191 | J21: 100 | K21: =Occupancy!G21 -> 197 | L21: =Occupancy!F21 -> 537 | M21: =E21*F21+G21*H21+#REF!*#REF!+I21*J21 -> #REF!
A22: Mumbai | B22: =B21+1 -> 21 | C22: 2 | D22: 2021 | E22: ='Daily HLP'!I24 -> 20106 | F22: =F21 -> 9 | G22: ='Daily HLP'!M24 -> 940 | H22: 44 | I22: ='Daily HLP'!P24 -> 231 | J22: 100 | K22: =Occupancy!G22 -> 99 | L22: =Occupancy!F22 -> 561 | M22: =E22*F22+G22*H22+#REF!*#REF!+I22*J22 -> #REF!
A23: Mumbai | B23: =B22+1 -> 22 | C23: 2 | D23: 2021 | E23: ='Daily HLP'!I25 -> 20271 | F23: =F22 -> 9 | G23: ='Daily HLP'!M25 -> 935 | H23: 44 | I23: ='Daily HLP'!P25 -> 201 | J23: 100 | K23: =Occupancy!G23 -> 107 | L23: =Occupancy!F23 -> 344 | M23: =E23*F23+G23*H23+#REF!*#REF!+I23*J23 -> #REF!
A24: Mumbai | B24: =B23+1 -> 23 | C24: 2 | D24: 2021 | E24: ='Daily HLP'!I26 -> 21273 | F24: =F23 -> 9 | G24: ='Daily HLP'!M26 -> 972.81 | H24: 44 | I24: ='Daily HLP'!P26 -> 211 | J24: 100 | K24: =Occupancy!G24 -> 116 | L24: =Occupancy!F24 -> 379 | M24: =E24*F24+G24*H24+#REF!*#REF!+I24*J24 -> #REF!
A25: Mumbai | B25: =B24+1 -> 24 | C25: 2 | D25: 2021 | E25: ='Daily HLP'!I27 -> 22810 | F25: =F24 -> 9 | G25: ='Daily HLP'!M27 -> 787.75 | H25: 44 | I25: ='Daily HLP'!P27 -> 192 | J25: 100 | K25: =Occupancy!G25 -> 107 | L25: =Occupancy!F25 -> 628 | M25: =E25*F25+G25*H25+#REF!*#REF!+I25*J25 -> #REF!
A26: Mumbai | B26: =B25+1 -> 25 | C26: 2 | D26: 2021 | E26: ='Daily HLP'!I28 -> 20603 | F26: =F25 -> 9 | G26: ='Daily HLP'!M28 -> 861.99 | H26: 44 | I26: ='Daily HLP'!P28 -> 192 | J26: 100 | K26: =Occupancy!G26 -> 93 | L26: =Occupancy!F26 -> 326 | M26: =E26*F26+G26*H26+#REF!*#REF!+I26*J26 -> #REF!
A27: Mumbai | B27: =B26+1 -> 26 | C27: 2 | D27: 2021 | E27: ='Daily HLP'!I29 -> 20278 | F27: =F26 -> 9 | G27: ='Daily HLP'!M29 -> 838.45 | H27: 44 | I27: ='Daily HLP'!P29 -> 171 | J27: 100 | K27: =Occupancy!G27 -> 109 | L27: =Occupancy!F27 -> 408 | M27: =E27*F27+G27*H27+#REF!*#REF!+I27*J27 -> #REF!
A28: Mumbai | B28: =B27+1 -> 27 | C28: 2 | D28: 2021 | E28: ='Daily HLP'!I30 -> 20601 | F28: =F27 -> 9 | G28: ='Daily HLP'!M30 -> 961.603 | H28: 44 | I28: ='Daily HLP'!P30 -> 234 | J28: 100 | K28: =Occupancy!G28 -> 0 | L28: =Occupancy!F28 -> 0 | M28: =E28*F28+G28*H28+#REF!*#REF!+I28*J28 -> #REF!
A29: Mumbai | B29: =B28+1 -> 28 | C29: 2 | D29: 2021 | E29: ='Daily HLP'!I31 -> 21818 | F29: =F28 -> 9 | G29: ='Daily HLP'!M31 -> 1060.007 | H29: 44 | I29: ='Daily HLP'!P31 -> 222 | J29: 100 | K29: =Occupancy!G29 -> 0 | L29: =Occupancy!F29 -> 0 | M29: =E29*F29+G29*H29+#REF!*#REF!+I29*J29 -> #REF!
A30: Mumbai | B30: =B29+1 -> 29 | C30: 2 | D30: 2021 | E30: ='Daily HLP'!I32 -> -594257 | F30: =F29 -> 9 | G30: ='Daily HLP'!M32 -> -26977.64 | H30: 44 | I30: ='Daily HLP'!P32 -> -1425 | J30: 100 | K30: =Occupancy!G30 -> 0 | L30: =Occupancy!F30 -> 0 | M30: =E30*F30+G30*H30+#REF!*#REF!+I30*J30 -> #REF!
A31: Mumbai | B31: =B30+1 -> 30 | C31: 2 | D31: 2021 | E31: ='Daily HLP'!I33 -> 18917 | F31: =F30 -> 9 | G31: ='Daily HLP'!M33 -> 667.76 | H31: 44 | I31: ='Daily HLP'!P33 -> 171 | J31: 100 | K31: =Occupancy!G31 -> 0 | L31: =Occupancy!F31 -> 0 | M31: =E31*F31+G31*H31+#REF!*#REF!+I31*J31 -> #REF!

Sheet Submetering
A1: Site Name | B1: Day | C1: Month | D1: Year | E1: ='Section Load'!B4 -> HVAC | F1: ='Section Load'!C4 -> Fire & Emergency PP | G1: ='Section Load'!D4 -> Main PP | H1: ='Section Load'!E4 -> Lighting PP | I1: ='Section Load'!F4 -> CH-1+ CH2+CH3+CH4 | J1: ='Section Load'!G4 -> Chilled water Pump | K1: ='Section Load'!H4 -> Ball Room-1 | L1: ='Section Load'!I4 -> Ball Room-2 | ... AL1: ='Section Load'!AI4 -> Cooling Tower | AM1: R.o.plant | AN1: STP Water Prod | AO1: Domestic Zone-1 | AP1: Domestic Zone-2 | AQ1: Domestic Zone-3 | AR1: Flush Zone -1 | AS1: Flush Zone -2 | AT1: Flush Zone -3 | AU1: Swimming pool | AV1: B2 Laundry | AW1: Boiler Feed Water | AX1: cooling tower filling water | AY1: STP flush(new water meter) | AZ1: Garden Water Pump | BA1: Flush Zone 2 pump meter | BB1: Flush Zone 3 Pump Meter (wtp transfer ) | BC1: Flush Tanker | BD1: Total Domestic Water (R.O +BMC) | BE1: Total Domestic Consumption | BF1: Total STP Consumption | BG1: ='Section Load'!AJ4 -> MGL | BH1: ='Section Load'!AK4 -> HWG | BI1: ='Section Load'!AL4 -> Prato | BJ1: ='Section Load'!AM4 -> BR-1 | BK1: ='Section Load'!AN4 -> SanQi IND | BL1: ='Section Load'!AO4 -> SanQi JPN | BM1: ='Section Load'!AP4 -> Boiler
A2: Mumbai | B2: 1 | C2: 2 | D2: 2021 | E2: ='Section Load'!B5 -> 2996.04 | F2: ='Section Load'!C5 -> 1437.83 | G2: ='Section Load'!D5 -> 2015.04 | H2: ='Section Load'!E5 -> 4103.76 | I2: ='Section Load'!F5 -> 4366.51 | J2: ='Section Load'!G5 -> 2272.96 | K2: ='Section Load'!H5 -> 1021.36 | L2: ='Section Load'!I5 -> 555.2 | ... AL2: ='Section Load'!AI5 -> 521 | AM2: ='[1]1'!$H$92 -> 87 | AN2: ='[1]1'!$H$93 -> 200 | AO2: ='[1]1'!$H$95 -> 72 | AP2: ='[1]1'!$H$96 -> 23 | AQ2: ='[1]1'!$H$97 -> 18 | AR2: ='[1]1'!$H$98 -> 83 | AS2: ='[1]1'!$H$99 -> 13 | AT2: ='[1]1'!$H$100 -> 6 | AU2: ='[1]1'!$H$104 -> 0 | AV2: ='[1]1'!$H$105 -> 8 | AW2: ='[1]1'!$H$106 -> 7 | AX2: ='[1]1'!$H$109 -> 41 | AY2: ='[1]1'!$H$110 -> 79 | AZ2: ='[1]1'!$H$111 -> 0 | BA2: ='[1]1'!$H$114 -> 16 | BB2: ='[1]1'!$H$115 -> 5 | BC2: ='[1]1'!$H$116 -> 0 | BD2: ='[1]1'!$H$118 -> 138 | BE2: ='[1]1'!$H$119 -> 132 | BF2: ='[1]1'!$H$120 -> 120 | BG2: ='Section Load'!AJ5 -> 797.95 | BH2: ='Section Load'!AK5 -> 270.38 | BI2: ='Section Load'!AL5 -> 0 | BJ2: ='Section Load'!AM5 -> 59 | BK2: ='Section Load'!AN5 -> 28.2 | BL2: ='Section Load'!AO5 -> 0 | BM2: ='Section Load'!AP5 -> 440.37
A3: Mumbai | B3: =B2+1 -> 2 | C3: 2 | D3: 2021 | E3: ='Section Load'!B6 -> 3058.91 | F3: ='Section Load'!C6 -> 1441.43 | G3: ='Section Load'!D6 -> 2022.29 | H3: ='Section Load'!E6 -> 4158.97 | I3: ='Section Load'!F6 -> 4172.58 | J3: ='Section Load'!G6 -> 2260.13 | K3: ='Section Load'!H6 -> 1036.33 | L3: ='Section Load'!I6 -> 621.35 | ... AL3: ='Section Load'!AI6 -> 534 | AM3: ='[1]2'!$H$92 -> 162 | AN3: ='[1]2'!$H$93 -> 351 | AO3: ='[1]2'!$H$95 -> 142 | AP3: ='[1]2'!$H$96 -> 53 | AQ3: ='[1]2'!$H$97 -> 34 | AR3: ='[1]2'!$H$98 -> 150 | AS3: ='[1]2'!$H$99 -> 21 | AT3: ='[1]2'!$H$100 -> 11 | AU3: ='[1]2'!$H$104 -> 0 | AV3: ='[1]2'!$H$105 -> 16 | AW3: ='[1]2'!$H$106 -> 12 | AX3: ='[1]2'!$H$109 -> 102 | AY3: ='[1]2'!$H$110 -> 118 | AZ3: ='[1]2'!$H$111 -> 16 | BA3: ='[1]2'!$H$114 -> 27 | BB3: ='[1]2'!$H$115 -> 8 | BC3: ='[1]2'!$H$116 -> 0 | BD3: ='[1]2'!$H$118 -> 264 | BE3: ='[1]2'!$H$119 -> 261 | BF3: ='[1]2'!$H$120 -> 236 | BG3: ='Section Load'!AJ6 -> 860.9 | BH3: ='Section Load'!AK6 -> 258.22 | BI3: ='Section Load'!AL6 -> 0 | BJ3: ='Section Load'!AM6 -> 62 | BK3: ='Section Load'!AN6 -> 52.1 | BL3: ='Section Load'!AO6 -> 3 | BM3: ='Section Load'!AP6 -> 485.58
A4: Mumbai | B4: =B3+1 -> 3 | C4: 2 | D4: 2021 | E4: ='Section Load'!B7 -> 2582.33 | F4: ='Section Load'!C7 -> 1532 | G4: ='Section Load'!D7 -> 1949 | H4: ='Section Load'!E7 -> 4269 | I4: ='Section Load'!F7 -> 4011 | J4: ='Section Load'!G7 -> 2293 | K4: ='Section Load'!H7 -> 1386 | L4: ='Section Load'!I7 -> 784 | ... AL4: ='Section Load'!AI7 -> 457 | AM4: ='[1]3'!$H$92 -> 250 | AN4: ='[1]3'!$H$93 -> 501 | AO4: ='[1]3'!$H$95 -> 206 | AP4: ='[1]3'!$H$96 -> 89 | AQ4: ='[1]3'!$H$97 -> 65 | AR4: ='[1]3'!$H$98 -> 222 | AS4: ='[1]3'!$H$99 -> 31 | AT4: ='[1]3'!$H$100 -> 16 | AU4: ='[1]3'!$H$104 -> 0 | AV4: ='[1]3'!$H$105 -> 22 | AW4: ='[1]3'!$H$106 -> 17 | AX4: ='[1]3'!$H$109 -> 160 | AY4: ='[1]3'!$H$110 -> 211 | AZ4: ='[1]3'!$H$111 -> 16 | BA4: ='[1]3'!$H$114 -> 39 | BB4: ='[1]3'!$H$115 -> 14 | BC4: ='[1]3'!$H$116 -> 0 | BD4: ='[1]3'!$H$118 -> 403 | BE4: ='[1]3'!$H$119 -> 407 | BF4: ='[1]3'!$H$120 -> 387 | BG4: ='Section Load'!AJ7 -> 873 | BH4: ='Section Load'!AK7 -> 265 | BI4: ='Section Load'!AL7 -> 0 | BJ4: ='Section Load'!AM7 -> 83 | BK4: ='Section Load'!AN7 -> 57 | BL4: ='Section Load'!AO7 -> 4 | BM4: ='Section Load'!AP7 -> 464
A5: Mumbai | B5: =B4+1 -> 4 | C5: 2 | D5: 2021 | E5: ='Section Load'!B8 -> 2607 | F5: ='Section Load'!C8 -> 1509 | G5: ='Section Load'!D8 -> 1911.12 | H5: ='Section Load'!E8 -> 4148 | I5: ='Section Load'!F8 -> 3732.9 | J5: ='Section Load'!G8 -> 2251 | K5: ='Section Load'!H8 -> 1085 | L5: ='Section Load'!I8 -> 594 | ... AL5: ='Section Load'!AI8 -> 474 | AM5: ='[1]4'!$H$92 -> 352 | AN5: ='[1]4'!$H$93 -> 641 | AO5: ='[1]4'!$H$95 -> 284 | AP5: ='[1]4'!$H$96 -> 124 | AQ5: ='[1]4'!$H$97 -> 110 | AR5: ='[1]4'!$H$98 -> 289 | AS5: ='[1]4'!$H$99 -> 41 | AT5: ='[1]4'!$H$100 -> 23 | AU5: ='[1]4'!$H$104 -> 0 | AV5: ='[1]4'!$H$105 -> 28 | AW5: ='[1]4'!$H$106 -> 23 | AX5: ='[1]4'!$H$109 -> 215 | AY5: ='[1]4'!$H$110 -> 258 | AZ5: ='[1]4'!$H$111 -> 30 | BA5: ='[1]4'!$H$114 -> 53 | BB5: ='[1]4'!$H$115 -> 21 | BC5: ='[1]4'!$H$116 -> 0 | BD5: ='[1]4'!$H$118 -> 555 | BE5: ='[1]4'!$H$119 -> 582 | BF5: ='[1]4'!$H$120 -> 503 | BG5: ='Section Load'!AJ8 -> 796 | BH5: ='Section Load'!AK8 -> 275 | BI5: ='Section Load'!AL8 -> 0 | BJ5: ='Section Load'!AM8 -> 68 | BK5: ='Section Load'!AN8 -> 32 | BL5: ='Section Load'!AO8 -> 1 | BM5: ='Section Load'!AP8 -> 420
A6: Mumbai | B6: =B5+1 -> 5 | C6: 2 | D6: 2021 | E6: ='Section Load'!B9 -> 2649 | F6: ='Section Load'!C9 -> 1458 | G6: ='Section Load'!D9 -> 2075 | H6: ='Section Load'!E9 -> 4228 | I6: ='Section Load'!F9 -> 3652 | J6: ='Section Load'!G9 -> 2265 | K6: ='Section Load'!H9 -> 1105 | L6: ='Section Load'!I9 -> 564 | ... AL6: ='Section Load'!AI9 -> 467 | AM6: ='[1]5'!$H$92 -> 462 | AN6: ='[1]5'!$H$93 -> 823 | AO6: ='[1]5'!$H$95 -> 339 | AP6: ='[1]5'!$H$96 -> 147 | AQ6: ='[1]5'!$H$97 -> 150 | AR6: ='[1]5'!$H$98 -> 329 | AS6: ='[1]5'!$H$99 -> 48 | AT6: ='[1]5'!$H$100 -> 29 | AU6: ='[1]5'!$H$104 -> 0 | AV6: ='[1]5'!$H$105 -> 42 | AW6: ='[1]5'!$H$106 -> 32 | AX6: ='[1]5'!$H$109 -> 330 | AY6: ='[1]5'!$H$110 -> 337 | AZ6: ='[1]5'!$H$111 -> 30 | BA6: ='[1]5'!$H$114 -> 74 | BB6: ='[1]5'!$H$115 -> 32 | BC6: ='[1]5'!$H$116 -> 0 | BD6: ='[1]5'!$H$118 -> 706 | BE6: ='[1]5'!$H$119 -> 713 | BF6: ='[1]5'!$H$120 -> 697 | BG6: ='Section Load'!AJ9 -> 778 | BH6: ='Section Load'!AK9 -> 269 | BI6: ='Section Load'!AL9 -> 0 | BJ6: ='Section Load'!AM9 -> 77 | BK6: ='Section Load'!AN9 -> 30 | BL6: ='Section Load'!AO9 -> 5 | BM6: ='Section Load'!AP9 -> 397
A7: Mumbai | B7: =B6+1 -> 6 | C7: 2 | D7: 2021 | E7: ='Section Load'!B10 -> 2648 | F7: ='Section Load'!C10 -> 1509 | G7: ='Section Load'!D10 -> 2000 | H7: ='Section Load'!E10 -> 4153 | I7: ='Section Load'!F10 -> 3905 | J7: ='Section Load'!G10 -> 2282 | K7: ='Section Load'!H10 -> 1480 | L7: ='Section Load'!I10 -> 729 | ... AL7: ='Section Load'!AI10 -> 477 | AM7: ='[1]6'!$H$92 -> 551 | AN7: ='[1]6'!$H$93 -> 924 | AO7: ='[1]6'!$H$95 -> 400 | AP7: ='[1]6'!$H$96 -> 181 | AQ7: ='[1]6'!$H$97 -> 181 | AR7: ='[1]6'!$H$98 -> 401 | AS7: ='[1]6'!$H$99 -> 57 | AT7: ='[1]6'!$H$100 -> 38 | AU7: ='[1]6'!$H$104 -> 0 | AV7: ='[1]6'!$H$105 -> 48 | AW7: ='[1]6'!$H$106 -> 38 | AX7: ='[1]6'!$H$109 -> 370 | AY7: ='[1]6'!$H$110 -> 382 | AZ7: ='[1]6'!$H$111 -> 62 | BA7: ='[1]6'!$H$114 -> 85 | BB7: ='[1]6'!$H$115 -> 38 | BC7: ='[1]6'!$H$116 -> 0 | BD7: ='[1]6'!$H$118 -> 846 | BE7: ='[1]6'!$H$119 -> 857 | BF7: ='[1]6'!$H$120 -> 814 | BG7: ='Section Load'!AJ10 -> 814 | BH7: ='Section Load'!AK10 -> 288 | BI7: ='Section Load'!AL10 -> 0 | BJ7: ='Section Load'!AM10 -> 63 | BK7: ='Section Load'!AN10 -> 43 | BL7: ='Section Load'!AO10 -> 3 | BM7: ='Section Load'!AP10 -> 417
A8: Mumbai | B8: =B7+1 -> 7 | C8: 2 | D8: 2021 | E8: ='Section Load'!B11 -> 2499.67 | F8: ='Section Load'!C11 -> 1427 | G8: ='Section Load'!D11 -> 2118 | H8: ='Section Load'!E11 -> 4176 | I8: ='Section Load'!F11 -> 3495.98 | J8: ='Section Load'!G11 -> 2319 | K8: ='Section Load'!H11 -> 1109 | L8: ='Section Load'!I11 -> 577.81 | ... AL8: ='Section Load'!AI11 -> 466 | AM8: ='[1]7'!$H$92 -> 655 | AN8: ='[1]7'!$H$93 -> 1131 | AO8: ='[1]7'!$H$95 -> 457 | AP8: ='[1]7'!$H$96 -> 224 | AQ8: ='[1]7'!$H$97 -> 204 | AR8: ='[1]7'!$H$98 -> 459 | AS8: ='[1]7'!$H$99 -> 71 | AT8: ='[1]7'!$H$100 -> 46 | AU8: ='[1]7'!$H$104 -> 0 | AV8: ='[1]7'!$H$105 -> 54 | AW8: ='[1]7'!$H$106 -> 42 | AX8: ='[1]7'!$H$109 -> 409 | AY8: ='[1]7'!$H$110 -> 483 | AZ8: ='[1]7'!$H$111 -> 62 | BA8: ='[1]7'!$H$114 -> 101 | BB8: ='[1]7'!$H$115 -> 45 | BC8: ='[1]7'!$H$116 -> 0 | BD8: ='[1]7'!$H$118 -> 1002 | BE8: ='[1]7'!$H$119 -> 1002 | BF8: ='[1]7'!$H$120 -> 954 | BG8: ='Section Load'!AJ11 -> 844.45 | BH8: ='Section Load'!AK11 -> 296 | BI8: ='Section Load'!AL11 -> 1.4 | BJ8: ='Section Load'!AM11 -> 60.97 | BK8: ='Section Load'!AN11 -> 40 | BL8: ='Section Load'!AO11 -> 2 | BM8: ='Section Load'!AP11 -> 444.08
A9: Mumbai | B9: =B8+1 -> 8 | C9: 2 | D9: 2021 | E9: ='Section Load'!B12 -> 2518.24 | F9: ='Section Load'!C12 -> 1776.19 | G9: ='Section Load'!D12 -> 2039.63 | H9: ='Section Load'!E12 -> 4170.29 | I9: ='Section Load'!F12 -> 3857.89 | J9: ='Section Load'!G12 -> 2339.67 | K9: ='Section Load'!H12 -> 1081 | L9: ='Section Load'!I12 -> 628.6 | ... AL9: ='Section Load'!AI12 -> 476 | AM9: ='[1]8'!$H$92 -> 750 | AN9: ='[1]8'!$H$93 -> 1338 | AO9: ='[1]8'!$H$95 -> 528 | AP9: ='[1]8'!$H$96 -> 275 | AQ9: ='[1]8'!$H$97 -> 224 | AR9: ='[1]8'!$H$98 -> 537 | AS9: ='[1]8'!$H$99 -> 83 | AT9: ='[1]8'!$H$100 -> 54 | AU9: ='[1]8'!$H$104 -> 0 | AV9: ='[1]8'!$H$105 -> 63 | AW9: ='[1]8'!$H$106 -> 47 | AX9: ='[1]8'!$H$109 -> 483 | AY9: ='[1]8'!$H$110 -> 526 | AZ9: ='[1]8'!$H$111 -> 62 | BA9: ='[1]8'!$H$114 -> 117 | BB9: ='[1]8'!$H$115 -> 52 | BC9: ='[1]8'!$H$116 -> 0 | BD9: ='[1]8'!$H$118 -> 1148 | BE9: ='[1]8'!$H$119 -> 1164 | BF9: ='[1]8'!$H$120 -> 1071 | BG9: ='Section Load'!AJ12 -> 816.28 | BH9: ='Section Load'!AK12 -> 274.98 | BI9: ='Section Load'!AL12 -> 0 | BJ9: ='Section Load'!AM12 -> 56.75 | BK9: ='Section Load'!AN12 -> 32.3 | BL9: ='Section Load'!AO12 -> 2 | BM9: ='Section Load'!AP12 -> 450.25
A10: Mumbai | B10: =B9+1 -> 9 | C10: 2 | D10: 2021 | E10: ='Section Load'!B13 -> 2513.92 | F10: ='Section Load'!C13 -> 1433.25 | G10: ='Section Load'!D13 -> 1896.54 | H10: ='Section Load'!E13 -> 4116.22 | I10: ='Section Load'!F13 -> 3536 | J10: ='Section Load'!G13 -> 2539.33 | K10: ='Section Load'!H13 -> 1173 | L10: ='Section Load'!I13 -> 645.4 | ... AL10: ='Section Load'!AI13 -> 482 | AM10: ='[1]9'!$H$92 -> 854 | AN10: ='[1]9'!$H$93 -> 1444 | AO10: ='[1]9'!$H$95 -> 590 | AP10: ='[1]9'!$H$96 -> 315 | AQ10: ='[1]9'!$H$97 -> 253 | AR10: ='[1]9'!$H$98 -> 604 | AS10: ='[1]9'!$H$99 -> 96 | AT10: ='[1]9'!$H$100 -> 63 | AU10: ='[1]9'!$H$104 -> 0 | AV10: ='[1]9'!$H$105 -> 63 | AW10: ='[1]9'!$H$106 -> 51 | AX10: ='[1]9'!$H$109 -> 536 | AY10: ='[1]9'!$H$110 -> 589 | AZ10: ='[1]9'!$H$111 -> 99 | BA10: ='[1]9'!$H$114 -> 132 | BB10: ='[1]9'!$H$115 -> 59 | BC10: ='[1]9'!$H$116 -> 0 | BD10: ='[1]9'!$H$118 -> 1304 | BE10: ='[1]9'!$H$119 -> 1317 | BF10: ='[1]9'!$H$120 -> 1224 | BG10: ='Section Load'!AJ13 -> 637.05 | BH10: ='Section Load'!AK13 -> 310.02 | BI10: ='Section Load'!AL13 -> 0 | BJ10: ='Section Load'!AM13 -> 47.86 | BK10: ='Section Load'!AN13 -> 31.7 | BL10: ='Section Load'!AO13 -> 1.8 | BM10: ='Section Load'!AP13 -> 245.67
A11: Mumbai | B11: =B10+1 -> 10 | C11: 2 | D11: 2021 | E11: ='Section Load'!B14 -> 2661.17 | F11: ='Section Load'!C14 -> 1454.97 | G11: ='Section Load'!D14 -> 1901.54 | H11: ='Section Load'!E14 -> 4189.47 | I11: ='Section Load'!F14 -> 3867.4 | J11: ='Section Load'!G14 -> 2548 | K11: ='Section Load'!H14 -> 1043 | L11: ='Section Load'!I14 -> 614.08 | ... AL11: ='Section Load'!AI14 -> 496 | AM11: ='[1]10'!$H$92 -> 991 | AN11: ='[1]10'!$H$93 -> 1599 | AO11: ='[1]10'!$H$95 -> 667 | AP11: ='[1]10'!$H$96 -> 355 | AQ11: ='[1]10'!$H$97 -> 299 | AR11: ='[1]10'!$H$98 -> 684 | AS11: ='[1]10'!$H$99 -> 108 | AT11: ='[1]10'!$H$100 -> 75 | AU11: ='[1]10'!$H$104 -> 0 | AV11: ='[1]10'!$H$105 -> 75 | AW11: ='[1]10'!$H$106 -> 54 | AX11: ='[1]10'!$H$109 -> 597 | AY11: ='[1]10'!$H$110 -> 653 | AZ11: ='[1]10'!$H$111 -> 105 | BA11: ='[1]10'!$H$114 -> 146 | BB11: ='[1]10'!$H$115 -> 72 | BC11: ='[1]10'!$H$116 -> 0 | BD11: ='[1]10'!$H$118 -> 1491 | BE11: ='[1]10'!$H$119 -> 1504 | BF11: ='[1]10'!$H$120 -> 1355 | BG11: ='Section Load'!AJ14 -> 899.1 | BH11: ='Section Load'!AK14 -> 286 | BI11: ='Section Load'!AL14 -> 0 | BJ11: ='Section Load'!AM14 -> 78.26 | BK11: ='Section Load'!AN14 -> 32 | BL11: ='Section Load'!AO14 -> 1.2 | BM11: ='Section Load'!AP14 -> 501.64
A12: Mumbai | B12: =B11+1 -> 11 | C12: 2 | D12: 2021 | E12: ='Section Load'!B15 -> 2358 | F12: ='Section Load'!C15 -> 1472.32 | G12: ='Section Load'!D15 -> 1831 | H12: ='Section Load'!E15 -> 4103.53 | I12: ='Section Load'!F15 -> 4051.6 | J12: ='Section Load'!G15 -> 2543 | K12: ='Section Load'!H15 -> 1038.71 | L12: ='Section Load'!I15 -> 697.11 | ... AL12: ='Section Load'!AI15 -> 447 | AM12: ='[1]11'!$H$92 -> 1092 | AN12: ='[1]11'!$H$93 -> 1733 | AO12: ='[1]11'!$H$95 -> 738 | AP12: ='[1]11'!$H$96 -> 404 | AQ12: ='[1]11'!$H$97 -> 322 | AR12: ='[1]11'!$H$98 -> 759 | AS12: ='[1]11'!$H$99 -> 118 | AT12: ='[1]11'!$H$100 -> 84 | AU12: ='[1]11'!$H$104 -> 74 | AV12: ='[1]11'!$H$105 -> 55 | AW12: ='[1]11'!$H$106 -> 340 | AX12: ='[1]11'!$H$109 -> 181 | AY12: ='[1]11'!$H$110 -> 144 | AZ12: ='[1]11'!$H$111 -> 445 | BA12: ='[1]11'!$H$114 -> 12 | BB12: ='[1]11'!$H$115 -> 90 | BC12: ='[1]11'!$H$116 -> 200 | BD12: ='[1]11'!$H$118 -> 175 | BE12: ='[1]11'!$H$119 -> 245 | BF12: ='[1]11'!$H$120 -> 222 | BG12: ='Section Load'!AJ15 -> 887.12 | BH12: ='Section Load'!AK15 -> 302.86 | BI12: ='Section Load'!AL15 -> 0 | BJ12: ='Section Load'!AM15 -> 65.02 | BK12: ='Section Load'!AN15 -> 38.8 | BL12: ='Section Load'!AO15 -> 0 | BM12: ='Section Load'!AP15 -> 480.44
A13: Mumbai | B13: =B12+1 -> 12 | C13: 2 | D13: 2021 | E13: ='Section Load'!B16 -> 2407.08 | F13: ='Section Load'!C16 -> 1504.2 | G13: ='Section Load'!D16 -> 1990.94 | H13: ='Section Load'!E16 -> 4063.9 | I13: ='Section Load'!F16 -> 4885.574 | J13: ='Section Load'!G16 -> 2400.03 | K13: ='Section Load'!H16 -> 1046.04 | L13: ='Section Load'!I16 -> 611.75 | ... AL13: ='Section Load'!AI16 -> 348 | AM13: ='[1]12'!$H$92 -> 1221 | AN13: ='[1]12'!$H$93 -> 1850 | AO13: ='[1]12'!$H$95 -> 824 | AP13: ='[1]12'!$H$96 -> 442 | AQ13: ='[1]12'!$H$97 -> 349 | AR13: ='[1]12'!$H$98 -> 842 | AS13: ='[1]12'!$H$99 -> 128 | AT13: ='[1]12'!$H$100 -> 91 | AU13: ='[1]12'!$H$104 -> 74 | AV13: ='[1]12'!$H$105 -> 57 | AW13: ='[1]12'!$H$106 -> 346 | AX13: ='[1]12'!$H$109 -> 140 | AY13: ='[1]12'!$H$110 -> 104 | AZ13: ='[1]12'!$H$111 -> 433 | BA13: ='[1]12'!$H$114 -> 14 | BB13: ='[1]12'!$H$115 -> 95 | BC13: ='[1]12'!$H$116 -> 200 | BD13: ='[1]12'!$H$118 -> 203 | BE13: ='[1]12'!$H$119 -> 251 | BF13: ='[1]12'!$H$120 -> 129 | BG13: ='Section Load'!AJ16 -> 914.918 | BH13: ='Section Load'!AK16 -> 274.02 | BI13: ='Section Load'!AL16 -> 0 | BJ13: ='Section Load'!AM16 -> 78.14 | BK13: ='Section Load'!AN16 -> 37.7 | BL13: ='Section Load'!AO16 -> 3.4 | BM13: ='Section Load'!AP16 -> 521.658
A14: Mumbai | B14: =B13+1 -> 13 | C14: 2 | D14: 2021 | E14: ='Section Load'!B17 -> 2703.72 | F14: ='Section Load'!C17 -> 1599.92 | G14: ='Section Load'!D17 -> 2319.92 | H14: ='Section Load'!E17 -> 4383.8 | I14: ='Section Load'!F17 -> 4412.46 | J14: ='Section Load'!G17 -> 2375.49 | K14: ='Section Load'!H17 -> 1132.16 | L14: ='Section Load'!I17 -> 685.58 | ... AL14: ='Section Load'!AI17 -> 512 | AM14: ='[1]13'!$H$92 -> 1370 | AN14: ='[1]13'!$H$93 -> 2099 | AO14: ='[1]13'!$H$95 -> 912 | AP14: ='[1]13'!$H$96 -> 485 | AQ14: ='[1]13'!$H$97 -> 395 | AR14: ='[1]13'!$H$98 -> 905 | AS14: ='[1]13'!$H$99 -> 144 | AT14: ='[1]13'!$H$100 -> 105 | AU14: ='[1]13'!$H$104 -> 74 | AV14: ='[1]13'!$H$105 -> 59 | AW14: ='[1]13'!$H$106 -> 340 | AX14: ='[1]13'!$H$109 -> 136 | AY14: ='[1]13'!$H$110 -> 131 | AZ14: ='[1]13'!$H$111 -> 446 | BA14: ='[1]13'!$H$114 -> 20 | BB14: ='[1]13'!$H$115 -> 93 | BC14: ='[1]13'!$H$116 -> 200 | BD14: ='[1]13'!$H$118 -> 224 | BE14: ='[1]13'!$H$119 -> 290 | BF14: ='[1]13'!$H$120 -> 165 | BG14: ='Section Load'!AJ17 -> 1043.67 | BH14: ='Section Load'!AK17 -> 293.52 | BI14: ='Section Load'!AL17 -> 0 | BJ14: ='Section Load'!AM17 -> 99.25 | BK14: ='Section Load'!AN17 -> 48.8 | BL14: ='Section Load'!AO17 -> 4.9 | BM14: ='Section Load'!AP17 -> 597.2
A15: Mumbai | B15: =B14+1 -> 14 | C15: 2 | D15: 2021 | E15: ='Section Load'!B18 -> 2968.2 | F15: ='Section Load'!C18 -> 1580.23 | G15: ='Section Load'!D18 -> 2441.06 | H15: ='Section Load'!E18 -> 4655.14 | I15: ='Section Load'!F18 -> 5638.755 | J15: ='Section Load'!G18 -> 2360.08 | K15: ='Section Load'!H18 -> 1369.28 | L15: ='Section Load'!I18 -> 864.62 | ... AL15: ='Section Load'!AI18 -> 498 | AM15: ='[1]14'!$H$92 -> 1536 | AN15: ='[1]14'!$H$93 -> 2273 | AO15: ='[1]14'!$H$95 -> 1033 | AP15: ='[1]14'!$H$96 -> 532 | AQ15: ='[1]14'!$H$97 -> 441 | AR15: ='[1]14'!$H$98 -> 976 | AS15: ='[1]14'!$H$99 -> 163 | AT15: ='[1]14'!$H$100 -> 129 | AU15: ='[1]14'!$H$104 -> 161 | AV15: ='[1]14'!$H$105 -> 59 | AW15: ='[1]14'!$H$106 -> 339 | AX15: ='[1]14'!$H$109 -> 136 | AY15: ='[1]14'!$H$110 -> 87 | AZ15: ='[1]14'!$H$111 -> 433 | BA15: ='[1]14'!$H$114 -> 22 | BB15: ='[1]14'!$H$115 -> 107 | BC15: ='[1]14'!$H$116 -> 200 | BD15: ='[1]14'!$H$118 -> 240 | BE15: ='[1]14'!$H$119 -> 340 | BF15: ='[1]14'!$H$120 -> 108 | BG15: ='Section Load'!AJ18 -> 1135.493 | BH15: ='Section Load'!AK18 -> 307.53 | BI15: ='Section Load'!AL18 -> 0 | BJ15: ='Section Load'!AM18 -> 112.34 | BK15: ='Section Load'!AN18 -> 52.1 | BL15: ='Section Load'!AO18 -> 8.5 | BM15: ='Section Load'!AP18 -> 655.023
A16: Mumbai | B16: =B15+1 -> 15 | C16: 2 | D16: 2021 | E16: ='Section Load'!B19 -> 2919.76 | F16: ='Section Load'!C19 -> 1580.09 | G16: ='Section Load'!D19 -> 2468.9 | H16: ='Section Load'!E19 -> 4654.59 | I16: ='Section Load'!F19 -> 5582.971 | J16: ='Section Load'!G19 -> 2346.16 | K16: ='Section Load'!H19 -> 1990 | L16: ='Section Load'!I19 -> 941.52 | ... AL16: ='Section Load'!AI19 -> 536 | AM16: ='[1]15'!$H$92 -> 1728 | AN16: ='[1]15'!$H$93 -> 2467 | AO16: ='[1]15'!$H$95 -> 1164 | AP16: ='[1]15'!$H$96 -> 557 | AQ16: ='[1]15'!$H$97 -> 476 | AR16: ='[1]15'!$H$98 -> 1052 | AS16: ='[1]15'!$H$99 -> 193 | AT16: ='[1]15'!$H$100 -> 152 | AU16: ='[1]15'!$H$104 -> 74 | AV16: ='[1]15'!$H$105 -> 65 | AW16: ='[1]15'!$H$106 -> 345 | AX16: ='[1]15'!$H$109 -> 159 | AY16: ='[1]15'!$H$110 -> 131 | AZ16: ='[1]15'!$H$111 -> 446 | BA16: ='[1]15'!$H$114 -> 35 | BB16: ='[1]15'!$H$115 -> 100 | BC16: ='[1]15'!$H$116 -> 200 | BD16: ='[1]15'!$H$118 -> 267 | BE16: ='[1]15'!$H$119 -> 327 | BF16: ='[1]15'!$H$120 -> 188 | BG16: ='Section Load'!AJ19 -> 1235.289 | BH16: ='Section Load'!AK19 -> 276.41 | BI16: ='Section Load'!AL19 -> 0 | BJ16: ='Section Load'!AM19 -> 135.35 | BK16: ='Section Load'!AN19 -> 41.5 | BL16: ='Section Load'!AO19 -> 5.5 | BM16: ='Section Load'!AP19 -> 776.529
A17: Mumbai | B17: =B16+1 -> 16 | C17: 2 | D17: 2021 | E17: ='Section Load'!B20 -> 3038.52 | F17: ='Section Load'!C20 -> 1517.11 | G17: ='Section Load'!D20 -> 2233.65 | H17: ='Section Load'!E20 -> 4228.12 | I17: ='Section Load'!F20 -> 4709.02 | J17: ='Section Load'!G20 -> 2361.36 | K17: ='Section Load'!H20 -> 1255 | L17: ='Section Load'!I20 -> 957.28 | ... AL17: ='Section Load'!AI20 -> 659 | AM17: ='[1]16'!$H$92 -> 1860 | AN17: ='[1]16'!$H$93 -> 2621 | AO17: ='[1]16'!$H$95 -> 1261 | AP17: ='[1]16'!$H$96 -> 575 | AQ17: ='[1]16'!$H$97 -> 500 | AR17: ='[1]16'!$H$98 -> 1108 | AS17: ='[1]16'!$H$99 -> 210 | AT17: ='[1]16'!$H$100 -> 158 | AU17: ='[1]16'!$H$104 -> 74 | AV17: ='[1]16'!$H$105 -> 60 | AW17: ='[1]16'!$H$106 -> 340 | AX17: ='[1]16'!$H$109 -> 136 | AY17: ='[1]16'!$H$110 -> 103 | AZ17: ='[1]16'!$H$111 -> 433 | BA17: ='[1]16'!$H$114 -> 21 | BB17: ='[1]16'!$H$115 -> 100 | BC17: ='[1]16'!$H$116 -> 200 | BD17: ='[1]16'!$H$118 -> 205 | BE17: ='[1]16'!$H$119 -> 245 | BF17: ='[1]16'!$H$120 -> 124 | BG17: ='Section Load'!AJ20 -> 1012.57 | BH17: ='Section Load'!AK20 -> 274.44 | BI17: ='Section Load'!AL20 -> 0 | BJ17: ='Section Load'!AM20 -> 87.94 | BK17: ='Section Load'!AN20 -> 24.8 | BL17: ='Section Load'!AO20 -> 2.1 | BM17: ='Section Load'!AP20 -> 623.29
A18: Mumbai | B18: =B17+1 -> 17 | C18: 2 | D18: 2021 | E18: ='Section Load'!B21 -> 2711.64 | F18: ='Section Load'!C21 -> 1476.62 | G18: ='Section Load'!D21 -> 2001.39 | H18: ='Section Load'!E21 -> 4187.63 | I18: ='Section Load'!F21 -> 4529.17 | J18: ='Section Load'!G21 -> 2334.8 | K18: ='Section Load'!H21 -> 1128.56 | L18: ='Section Load'!I21 -> 883.8 | ... AL18: ='Section Load'!AI21 -> 482 | AM18: ='[1]17'!$H$92 -> 1944 | AN18: ='[1]17'!$H$93 -> 2755 | AO18: ='[1]17'!$H$95 -> 1333 | AP18: ='[1]17'!$H$96 -> 590 | AQ18: ='[1]17'!$H$97 -> 520 | AR18: ='[1]17'!$H$98 -> 1143 | AS18: ='[1]17'!$H$99 -> 224 | AT18: ='[1]17'!$H$100 -> 164 | AU18: ='[1]17'!$H$104 -> 74 | AV18: ='[1]17'!$H$105 -> 57 | AW18: ='[1]17'!$H$106 -> 339 | AX18: ='[1]17'!$H$109 -> 116 | AY18: ='[1]17'!$H$110 -> 82 | AZ18: ='[1]17'!$H$111 -> 455 | BA18: ='[1]17'!$H$114 -> 17 | BB18: ='[1]17'!$H$115 -> 93 | BC18: ='[1]17'!$H$116 -> 200 | BD18: ='[1]17'!$H$118 -> 158 | BE18: ='[1]17'!$H$119 -> 210 | BF18: ='[1]17'!$H$120 -> 105 | BG18: ='Section Load'!AJ21 -> 930.51 | BH18: ='Section Load'!AK21 -> 259.15 | BI18: ='Section Load'!AL21 -> 0 | BJ18: ='Section Load'!AM21 -> 67.6 | BK18: ='Section Load'!AN21 -> 16.1 | BL18: ='Section Load'!AO21 -> 4.7 | BM18: ='Section Load'!AP21 -> 582.96
A19: Mumbai | B19: =B18+1 -> 18 | C19: 2 | D19: 2021 | E19: ='Section Load'!B22 -> 2740.16 | F19: ='Section Load'!C22 -> 1468.93 | G19: ='Section Load'!D22 -> 2050.54 | H19: ='Section Load'!E22 -> 4281.18 | I19: ='Section Load'!F22 -> 4586.87 | J19: ='Section Load'!G22 -> 2334.16 | K19: ='Section Load'!H22 -> 1128.56 | L19: ='Section Load'!I22 -> 883.8 | ... AL19: ='Section Load'!AI22 -> 482 | AM19: ='[1]18'!$H$92 -> 2025 | AN19: ='[1]18'!$H$93 -> 2892 | AO19: ='[1]18'!$H$95 -> 1407 | AP19: ='[1]18'!$H$96 -> 606 | AQ19: ='[1]18'!$H$97 -> 537 | AR19: ='[1]18'!$H$98 -> 1221 | AS19: ='[1]18'!$H$99 -> 246 | AT19: ='[1]18'!$H$100 -> 169 | AU19: ='[1]18'!$H$104 -> 74 | AV19: ='[1]18'!$H$105 -> 56 | AW19: ='[1]18'!$H$106 -> 344 | AX19: ='[1]18'!$H$109 -> 136 | AY19: ='[1]18'!$H$110 -> 137 | AZ19: ='[1]18'!$H$111 -> 440 | BA19: ='[1]18'!$H$114 -> 25 | BB19: ='[1]18'!$H$115 -> 92 | BC19: ='[1]18'!$H$116 -> 200 | BD19: ='[1]18'!$H$118 -> 151 | BE19: ='[1]18'!$H$119 -> 217 | BF19: ='[1]18'!$H$120 -> 165 | BG19: ='Section Load'!AJ22 -> 840.14 | BH19: ='Section Load'!AK22 -> 260.41 | BI19: ='Section Load'!AL22 -> 0 | BJ19: ='Section Load'!AM22 -> 77.27 | BK19: ='Section Load'!AN22 -> 25.7 | BL19: ='Section Load'!AO22 -> 1.1 | BM19: ='Section Load'!AP22 -> 475.66
A20: Mumbai | B20: =B19+1 -> 19 | C20: 2 | D20: 2021 | E20: ='Section Load'!B23 -> 2680.92 | F20: ='Section Load'!C23 -> 1478.17 | G20: ='Section Load'!D23 -> 1916.89 | H20: ='Section Load'!E23 -> 4163.13 | I20: ='Section Load'!F23 -> 4133.31 | J20: ='Section Load'!G23 -> 2308.92 | K20: ='Section Load'!H23 -> 1435.97 | L20: ='Section Load'!I23 -> 664.45 | ... AL20: ='Section Load'!AI23 -> 499 | AM20: ='[1]19'!$H$92 -> 2120 | AN20: ='[1]19'!$H$93 -> 3034 | AO20: ='[1]19'!$H$95 -> 1486 | AP20: ='[1]19'!$H$96 -> 615 | AQ20: ='[1]19'!$H$97 -> 561 | AR20: ='[1]19'!$H$98 -> 1284 | AS20: ='[1]19'!$H$99 -> 269 | AT20: ='[1]19'!$H$100 -> 175 | AU20: ='[1]19'!$H$104 -> 74 | AV20: ='[1]19'!$H$105 -> 63 | AW20: ='[1]19'!$H$106 -> 350 | AX20: ='[1]19'!$H$109 -> 176 | AY20: ='[1]19'!$H$110 -> 168 | AZ20: ='[1]19'!$H$111 -> 440 | BA20: ='[1]19'!$H$114 -> 51 | BB20: ='[1]19'!$H$115 -> 94 | BC20: ='[1]19'!$H$116 -> 200 | BD20: ='[1]19'!$H$118 -> 296 | BE20: ='[1]19'!$H$119 -> 358 | BF20: ='[1]19'!$H$120 -> 236 | BG20: ='Section Load'!AJ23 -> 881.41 | BH20: ='Section Load'!AK23 -> 241.66 | BI20: ='Section Load'!AL23 -> -0.4 | BJ20: ='Section Load'!AM23 -> 89.25 | BK20: ='Section Load'!AN23 -> 23.5 | BL20: ='Section Load'!AO23 -> 1.8 | BM20: ='Section Load'!AP23 -> 525.6
A21: Mumbai | B21: =B20+1 -> 20 | C21: 2 | D21: 2021 | E21: ='Section Load'!B24 -> 2854 | F21: ='Section Load'!C24 -> 1511 | G21: ='Section Load'!D24 -> 1965 | H21: ='Section Load'!E24 -> 4389 | I21: ='Section Load'!F24 -> 4051 | J21: ='Section Load'!G24 -> 2302 | K21: ='Section Load'!H24 -> 1156 | L21: ='Section Load'!I24 -> 625 | ... AL21: ='Section Load'!AI24 -> 562 | AM21: ='[1]20'!$H$92 -> 2227 | AN21: ='[1]20'!$H$93 -> 3167 | AO21: ='[1]20'!$H$95 -> 1572 | AP21: ='[1]20'!$H$96 -> 637 | AQ21: ='[1]20'!$H$97 -> 593 | AR21: ='[1]20'!$H$98 -> 1352 | AS21: ='[1]20'!$H$99 -> 290 | AT21: ='[1]20'!$H$100 -> 183 | AU21: ='[1]20'!$H$104 -> 74 | AV21: ='[1]20'!$H$105 -> 76 | AW21: ='[1]20'!$H$106 -> 358 | AX21: ='[1]20'!$H$109 -> 235 | AY21: ='[1]20'!$H$110 -> 243 | AZ21: ='[1]20'!$H$111 -> 460 | BA21: ='[1]20'!$H$114 -> 77 | BB21: ='[1]20'!$H$115 -> 102 | BC21: ='[1]20'!$H$116 -> 200 | BD21: ='[1]20'!$H$118 -> 454 | BE21: ='[1]20'!$H$119 -> 527 | BF21: ='[1]20'!$H$120 -> 390 | BG21: ='Section Load'!AJ24 -> 1086 | BH21: ='Section Load'!AK24 -> 300 | BI21: ='Section Load'!AL24 -> 0 | BJ21: ='Section Load'!AM24 -> 86 | BK21: ='Section Load'!AN24 -> 30 | BL21: ='Section Load'!AO24 -> 3 | BM21: ='Section Load'!AP24 -> 667
A22: Mumbai | B22: =B21+1 -> 21 | C22: 2 | D22: 2021 | E22: ='Section Load'!B25 -> 3035 | F22: ='Section Load'!C25 -> 1522 | G22: ='Section Load'!D25 -> 2026 | H22: ='Section Load'!E25 -> 4214 | I22: ='Section Load'!F25 -> 4354 | J22: ='Section Load'!G25 -> 2354 | K22: ='Section Load'!H25 -> 1111 | L22: ='Section Load'!I25 -> 776 | ... AL22: ='Section Load'!AI25 -> 568 | AM22: ='[1]21'!$H$92 -> 2349 | AN22: ='[1]21'!$H$93 -> 3277 | AO22: ='[1]21'!$H$95 -> 1644 | AP22: ='[1]21'!$H$96 -> 664 | AQ22: ='[1]21'!$H$97 -> 628 | AR22: ='[1]21'!$H$98 -> 1439 | AS22: ='[1]21'!$H$99 -> 305 | AT22: ='[1]21'!$H$100 -> 195 | AU22: ='[1]21'!$H$104 -> 74 | AV22: ='[1]21'!$H$105 -> 83 | AW22: ='[1]21'!$H$106 -> 364 | AX22: ='[1]21'!$H$109 -> 295 | AY22: ='[1]21'!$H$110 -> 343 | AZ22: ='[1]21'!$H$111 -> 466 | BA22: ='[1]21'!$H$114 -> 94 | BB22: ='[1]21'!$H$115 -> 111 | BC22: ='[1]21'!$H$116 -> 200 | BD22: ='[1]21'!$H$118 -> 627 | BE22: ='[1]21'!$H$119 -> 688 | BF22: ='[1]21'!$H$120 -> 556 | BG22: ='Section Load'!AJ25 -> 940 | BH22: ='Section Load'!AK25 -> 283 | BI22: ='Section Load'!AL25 -> 0 | BJ22: ='Section Load'!AM25 -> 80 | BK22: ='Section Load'!AN25 -> 30 | BL22: ='Section Load'!AO25 -> 2 | BM22: ='Section Load'!AP25 -> 545
A23: Mumbai | B23: =B22+1 -> 22 | C23: 2 | D23: 2021 | E23: ='Section Load'!B26 -> 2796 | F23: ='Section Load'!C26 -> 1467 | G23: ='Section Load'!D26 -> 2080 | H23: ='Section Load'!E26 -> 4115 | I23: ='Section Load'!F26 -> 4684 | J23: ='Section Load'!G26 -> 2349 | K23: ='Section Load'!H26 -> 1196 | L23: ='Section Load'!I26 -> 729 | ... AL23: ='Section Load'!AI26 -> 565 | AM23: ='[1]22'!$H$92 -> -791 | AN23: ='[1]22'!$H$93 -> -1243 | AO23: ='[1]22'!$H$95 -> -591 | AP23: ='[1]22'!$H$96 -> -221 | AQ23: ='[1]22'!$H$97 -> -204 | AR23: ='[1]22'!$H$98 -> -533 | AS23: ='[1]22'!$H$99 -> -170 | AT23: ='[1]22'!$H$100 -> -72 | AU23: ='[1]22'!$H$104 -> -13 | AV23: ='[1]22'!$H$105 -> -202 | AW23: ='[1]22'!$H$106 -> 161 | AX23: ='[1]22'!$H$109 -> -1623 | AY23: ='[1]22'!$H$110 -> -1822 | AZ23: ='[1]22'!$H$111 -> 189 | BA23: ='[1]22'!$H$114 -> -566 | BB23: ='[1]22'!$H$115 -> -136 | BC23: ='[1]22'!$H$116 -> 200 | BD23: ='[1]22'!$H$118 -> -4632 | BE23: ='[1]22'!$H$119 -> -4611 | BF23: ='[1]22'!$H$120 -> -3804 | BG23: ='Section Load'!AJ26 -> 935 | BH23: ='Section Load'!AK26 -> 252 | BI23: ='Section Load'!AL26 -> 0 | BJ23: ='Section Load'!AM26 -> 76 | BK23: ='Section Load'!AN26 -> 18 | BL23: ='Section Load'!AO26 -> 2 | BM23: ='Section Load'!AP26 -> 587
A24: Mumbai | B24: =B23+1 -> 23 | C24: 2 | D24: 2021 | E24: ='Section Load'!B27 -> 3006 | F24: ='Section Load'!C27 -> 1462 | G24: ='Section Load'!D27 -> 2020 | H24: ='Section Load'!E27 -> 4149.83 | I24: ='Section Load'!F27 -> 5151 | J24: ='Section Load'!G27 -> 2348 | K24: ='Section Load'!H27 -> 1384.71 | L24: ='Section Load'!I27 -> 911 | ... AL24: ='Section Load'!AI27 -> 533 | AM24: ='[1]23'!$H$92 -> -688 | AN24: ='[1]23'!$H$93 -> -1123 | AO24: ='[1]23'!$H$95 -> -516 | AP24: ='[1]23'!$H$96 -> -203 | AQ24: ='[1]23'!$H$97 -> -178 | AR24: ='[1]23'!$H$98 -> -477 | AS24: ='[1]23'!$H$99 -> -160 | AT24: ='[1]23'!$H$100 -> -59 | AU24: ='[1]23'!$H$104 -> 74 | AV24: ='[1]23'!$H$105 -> 54 | AW24: ='[1]23'!$H$106 -> 342 | AX24: ='[1]23'!$H$109 -> 121 | AY24: ='[1]23'!$H$110 -> 86 | AZ24: ='[1]23'!$H$111 -> 446 | BA24: ='[1]23'!$H$114 -> 12 | BB24: ='[1]23'!$H$115 -> 99 | BC24: ='[1]23'!$H$116 -> 200 | BD24: ='[1]23'!$H$118 -> 169 | BE24: ='[1]23'!$H$119 -> 225 | BF24: ='[1]23'!$H$120 -> 105 | BG24: ='Section Load'!AJ27 -> 972.81 | BH24: ='Section Load'!AK27 -> 252 | BI24: ='Section Load'!AL27 -> 0 | BJ24: ='Section Load'!AM27 -> 77 | BK24: ='Section Load'!AN27 -> 22 | BL24: ='Section Load'!AO27 -> 2 | BM24: ='Section Load'!AP27 -> 619.81
A25: Mumbai | B25: =B24+1 -> 24 | C25: 2 | D25: 2021 | E25: ='Section Load'!B28 -> 3198 | F25: ='Section Load'!C28 -> 1506 | G25: ='Section Load'!D28 -> 2074 | H25: ='Section Load'!E28 -> 4084.17 | I25: ='Section Load'!F28 -> 5857 | J25: ='Section Load'!G28 -> 2469 | K25: ='Section Load'!H28 -> 1749.29 | L25: ='Section Load'!I28 -> 1101 | ... AL25: ='Section Load'!AI28 -> 602 | AM25: ='[1]24'!$H$92 -> -585 | AN25: ='[1]24'!$H$93 -> -974 | AO25: ='[1]24'!$H$95 -> -445 | AP25: ='[1]24'!$H$96 -> -178 | AQ25: ='[1]24'!$H$97 -> -145 | AR25: ='[1]24'!$H$98 -> -432 | AS25: ='[1]24'!$H$99 -> -148 | AT25: ='[1]24'!$H$100 -> -50 | AU25: ='[1]24'!$H$104 -> 74 | AV25: ='[1]24'!$H$105 -> 54 | AW25: ='[1]24'!$H$106 -> 339 | AX25: ='[1]24'!$H$109 -> 137 | AY25: ='[1]24'!$H$110 -> 80 | AZ25: ='[1]24'!$H$111 -> 433 | BA25: ='[1]24'!$H$114 -> 15 | BB25: ='[1]24'!$H$115 -> 95 | BC25: ='[1]24'!$H$116 -> 200 | BD25: ='[1]24'!$H$118 -> 176 | BE25: ='[1]24'!$H$119 -> 233 | BF25: ='[1]24'!$H$120 -> 102 | BG25: ='Section Load'!AJ28 -> 787.75 | BH25: ='Section Load'!AK28 -> 260 | BI25: ='Section Load'!AL28 -> 0 | BJ25: ='Section Load'!AM28 -> 74 | BK25: ='Section Load'!AN28 -> 16 | BL25: ='Section Load'!AO28 -> 2 | BM25: ='Section Load'!AP28 -> 435.75
A26: Mumbai | B26: =B25+1 -> 25 | C26: 2 | D26: 2021 | E26: ='Section Load'!B29 -> 3189 | F26: ='Section Load'!C29 -> 1492 | G26: ='Section Load'!D29 -> 1987 | H26: ='Section Load'!E29 -> 4098 | I26: ='Section Load'!F29 -> 5048 | J26: ='Section Load'!G29 -> 2279 | K26: ='Section Load'!H29 -> 1200 | L26: ='Section Load'!I29 -> 743 | ... AL26: ='Section Load'!AI29 -> 554 | AM26: ='[1]25'!$H$92 -> -489 | AN26: ='[1]25'!$H$93 -> -813 | AO26: ='[1]25'!$H$95 -> -362 | AP26: ='[1]25'!$H$96 -> -154 | AQ26: ='[1]25'!$H$97 -> -120 | AR26: ='[1]25'!$H$98 -> -382 | AS26: ='[1]25'!$H$99 -> -131 | AT26: ='[1]25'!$H$100 -> -42 | AU26: ='[1]25'!$H$104 -> 74 | AV26: ='[1]25'!$H$105 -> 62 | AW26: ='[1]25'!$H$106 -> 341 | AX26: ='[1]25'!$H$109 -> 117 | AY26: ='[1]25'!$H$110 -> 105 | AZ26: ='[1]25'!$H$111 -> 447 | BA26: ='[1]25'!$H$114 -> 20 | BB26: ='[1]25'!$H$115 -> 93 | BC26: ='[1]25'!$H$116 -> 200 | BD26: ='[1]25'!$H$118 -> 172 | BE26: ='[1]25'!$H$119 -> 240 | BF26: ='[1]25'!$H$120 -> 121 | BG26: ='Section Load'!AJ29 -> 861.99 | BH26: ='Section Load'!AK29 -> 265 | BI26: ='Section Load'!AL29 -> 0 | BJ26: ='Section Load'!AM29 -> 67 | BK26: ='Section Load'!AN29 -> 22 | BL26: ='Section Load'!AO29 -> 0 | BM26: ='Section Load'!AP29 -> 507.99
A27: Mumbai | B27: =B26+1 -> 26 | C27: 2 | D27: 2021 | E27: ='Section Load'!B30 -> 3115 | F27: ='Section Load'!C30 -> 1421 | G27: ='Section Load'!D30 -> 1988 | H27: ='Section Load'!E30 -> 4202 | I27: ='Section Load'!F30 -> 5077 | J27: ='Section Load'!G30 -> 2292 | K27: ='Section Load'!H30 -> 1005 | L27: ='Section Load'!I30 -> 610 | ... AL27: ='Section Load'!AI30 -> 617 | AM27: ='[1]26'!$H$92 -> -381 | AN27: ='[1]26'!$H$93 -> -708 | AO27: ='[1]26'!$H$95 -> -302 | AP27: ='[1]26'!$H$96 -> -135 | AQ27: ='[1]26'!$H$97 -> -95 | AR27: ='[1]26'!$H$98 -> -320 | AS27: ='[1]26'!$H$99 -> -92 | AT27: ='[1]26'!$H$100 -> -32 | AU27: ='[1]26'!$H$104 -> 74 | AV27: ='[1]26'!$H$105 -> 55 | AW27: ='[1]26'!$H$106 -> 337 | AX27: ='[1]26'!$H$109 -> 118 | AY27: ='[1]26'!$H$110 -> 105 | AZ27: ='[1]26'!$H$111 -> 433 | BA27: ='[1]26'!$H$114 -> 44 | BB27: ='[1]26'!$H$115 -> 97 | BC27: ='[1]26'!$H$116 -> 200 | BD27: ='[1]26'!$H$118 -> 180 | BE27: ='[1]26'!$H$119 -> 236 | BF27: ='[1]26'!$H$120 -> 108 | BG27: ='Section Load'!AJ30 -> 838.45 | BH27: ='Section Load'!AK30 -> 251 | BI27: ='Section Load'!AL30 -> 0 | BJ27: ='Section Load'!AM30 -> 57 | BK27: ='Section Load'!AN30 -> 23 | BL27: ='Section Load'!AO30 -> 1 | BM27: ='Section Load'!AP30 -> 506.45
A28: Mumbai | B28: =B27+1 -> 27 | C28: 2 | D28: 2021 | E28: ='Section Load'!B31 -> 3121.48 | F28: ='Section Load'!C31 -> 1489.99 | G28: ='Section Load'!D31 -> 2224.465 | H28: ='Section Load'!E31 -> 4174.96 | I28: ='Section Load'!F31 -> 5238.66 | J28: ='Section Load'!G31 -> 2278.56 | K28: ='Section Load'!H31 -> 972.27 | L28: ='Section Load'!I31 -> 562.33 | ... AL28: ='Section Load'!AI31 -> 672 | AM28: ='[1]27'!$H$92 -> -291 | AN28: ='[1]27'!$H$93 -> -595 | AO28: ='[1]27'!$H$95 -> -231 | AP28: ='[1]27'!$H$96 -> -120 | AQ28: ='[1]27'!$H$97 -> -82 | AR28: ='[1]27'!$H$98 -> -256 | AS28: ='[1]27'!$H$99 -> -60 | AT28: ='[1]27'!$H$100 -> -27 | AU28: ='[1]27'!$H$104 -> 74 | AV28: ='[1]27'!$H$105 -> 60 | AW28: ='[1]27'!$H$106 -> 341 | AX28: ='[1]27'!$H$109 -> 118 | AY28: ='[1]27'!$H$110 -> 104 | AZ28: ='[1]27'!$H$111 -> 438 | BA28: ='[1]27'!$H$114 -> 37 | BB28: ='[1]27'!$H$115 -> 92 | BC28: ='[1]27'!$H$116 -> 200 | BD28: ='[1]27'!$H$118 -> 167 | BE28: ='[1]27'!$H$119 -> 219 | BF28: ='[1]27'!$H$120 -> 112 | BG28: ='Section Load'!AJ31 -> 961.603 | BH28: ='Section Load'!AK31 -> 252.098 | BI28: ='Section Load'!AL31 -> 0.4 | BJ28: ='Section Load'!AM31 -> 78.53 | BK28: ='Section Load'!AN31 -> 25.5 | BL28: ='Section Load'!AO31 -> 2.4 | BM28: ='Section Load'!AP31 -> 602.675
A29: Mumbai | B29: =B28+1 -> 28 | C29: 2 | D29: 2021 | E29: ='Section Load'!B32 -> 3316.24 | F29: ='Section Load'!C32 -> 1486.03 | G29: ='Section Load'!D32 -> 2272.735 | H29: ='Section Load'!E32 -> 4370.94 | I29: ='Section Load'!F32 -> 5659.28 | J29: ='Section Load'!G32 -> 2391.6 | K29: ='Section Load'!H32 -> 1090.76 | L29: ='Section Load'!I32 -> 614.24 | ... AL29: ='Section Load'!AI32 -> 739 | AM29: ='[1]28'!$H$92 -> -234 | AN29: ='[1]28'!$H$93 -> -495 | AO29: ='[1]28'!$H$95 -> -188 | AP29: ='[1]28'!$H$96 -> -97 | AQ29: ='[1]28'!$H$97 -> -71 | AR29: ='[1]28'!$H$98 -> -197 | AS29: ='[1]28'!$H$99 -> -38 | AT29: ='[1]28'!$H$100 -> -19 | AU29: ='[1]28'!$H$104 -> 74 | AV29: ='[1]28'!$H$105 -> 48 | AW29: ='[1]28'!$H$106 -> 334 | AX29: ='[1]28'!$H$109 -> 139 | AY29: ='[1]28'!$H$110 -> 93 | AZ29: ='[1]28'!$H$111 -> 433 | BA29: ='[1]28'!$H$114 -> 25 | BB29: ='[1]28'!$H$115 -> 94 | BC29: ='[1]28'!$H$116 -> 200 | BD29: ='[1]28'!$H$118 -> 133 | BE29: ='[1]28'!$H$119 -> 190 | BF29: ='[1]28'!$H$120 -> 117 | BG29: ='Section Load'!AJ32 -> 1060.007 | BH29: ='Section Load'!AK32 -> 273.742 | BI29: ='Section Load'!AL32 -> 0 | BJ29: ='Section Load'!AM32 -> 67.81 | BK29: ='Section Load'!AN32 -> 41.4 | BL29: ='Section Load'!AO32 -> 2.4 | BM29: ='Section Load'!AP32 -> 674.655

Sheet Daily HLP
A2: Date | B2: Date | C2: Min.Tem (Degee) | D2: Avg.Temp (Degree) | E2: Hum % | F2: Occu. | G2: KWAH | I2: Electricity | M2: Gas | P2: Water | S2: Water per occiped room | T2: Diesel | W2: Water Consumption Zone | AA2: Chiller Running Hrs | AF2: Chiller Total | AG2: Chiller Avg. Laod | AH2: Boiler Running Hrs | AK2: Total boiler | AL2: Hot Water Generator | AO2: Total HWG RH | AP2: HWG Gas consumption | AQ2: Transformer -1 | BA2: Transformer -2 | BO2: Total HLP Cost | BQ2: Chiller lock at 70%
F3: % | H3: KVAH | I3: Units (Kwh) | J3: Rate | K3: Total Cost(Rs) | L3: Per room | M3: Total Units(CuM) | N3: Rate | O3: Total Cost(Rs) | P3: Units(KL) | Q3: Rate | R3: Total Cost(Rs) | T3: Ltrs | U3: Rate | V3: Total Cost(Rs) | W3: Zone-1 | X3: Zone-2 | Y3: Zone-3 | AA3: CH1 | AB3: CH2 | AC3: CH3 | AD3: CH4 | AE3: Total chiller | AH3: Boiler1 | AI3: Boiler2 | AJ3: Boiler3 | AL3: HWG1 | AM3: HWG2 | AQ3: HVAC-1 | AR3: FPP-1 | AS3: MPP | AT3: Lighting-1 | AU3: Cap bank 1100KVAR-1 | AV3: CH-1 | AW3: CH-2 | AX3: Chilled water Pump | AY3: Co Generator | AZ3: Ball Room-2 | BA3: HVAC-2 | BB3: FPP-2 | BC3: MPP | BD3: Lighting-2 | BE3: Cap bank 1200KVAR-2 | BF3: CH-3 | BG3: CH-4 | BH3: Chilled water Pump | BI3: Ball Room-1 | BK3: Cooling Tower consumption | BL3: HVAC% | BM3: Lighting% | BN3: Power% | BP3: Chiller Plant IKW
A4: 1 | B4: 1 | D4: ='1'!D3 -> 25 | E4: ='1'!D4 -> 0.8 | F4: ='1'!D2 -> 0.47 | G4: ='1'!G8 -> 19474 | H4: ='1'!G8 -> 19474 | I4: ='1'!G7 -> 19291 | J4: ='1'!F27 -> 9 | K4: =H4*J4 -> 175266 | L4: =I4/202 -> 95.5 | M4: ='1'!G15 -> 797.95 | N4: 35 | O4: =M4*N4 -> 27928.25 | P4: ='1'!G20 -> 171 | Q4: 134 | R4: =P4*Q4 -> 22914 | S4: =P4/(F4*202/100) -> 180.11376 | T4: ='1'!G24 -> 0 | U4: 69 | V4: =T4*U4 -> 0 | W4: ='1'!G95 -> 72 | X4: ='1'!G96 -> 23 | Y4: ='1'!G97 -> 18 | Z4: =W4+X4+Y4 -> 113 | AA4: ='1'!G132 -> 24.04 | AB4: ='1'!G133 -> 0 | AC4: ='1'!G134 -> 0 | AD4: ='1'!G135 -> 0 | AE4: =AA4+AB4+AC4+AD4 -> 24.04 | AF4: =AV4+AW4+BF4+BG4 -> 4366.51 | AG4: =AF4/AE4 -> 181.63519 | AH4: ='1'!G136 -> 7.89 | AI4: ='1'!G137 -> 0.4 | AJ4: ='1'!G138 -> 0 | AK4: =AH4+AI4+AJ4 -> 8.29 | AL4: ='1'!G139 -> 7.95 | AM4: ='1'!G140 -> 0 | AO4: =AL4+AM4 -> 7.95 | AP4: ='1'!G123 -> 270.38 | AQ4: ='1'!G35 -> 0 | AR4: ='1'!G37 -> 0 | AS4: ='1'!G38 -> 0 | AT4: ='1'!G39 -> 0 | AU4: ='1'!G40 -> 0 | AV4: ='1'!G41 -> 4365.99 | AW4: ='1'!G42 -> 0 | AX4: ='1'!G43 -> 2272.96 | AY4: ='1'!G44 -> 0 | AZ4: ='1'!G36 -> 555.2 | BA4: ='1'!G49 -> 2996.04 | BB4: ='1'!G51 -> 1437.83 | BC4: ='1'!G52 -> 2015.04 | BD4: ='1'!G53 -> 4103.76 | BE4: ='1'!G54 -> 40.32 | BF4: ='1'!G55 -> 0 | BG4: ='1'!G56 -> 0.52 | BH4: ='1'!G57 -> 0 | BI4: ='1'!G50 -> 1021.36 | BJ4: =SUM(AV4,AW4,BF4,BG4) -> 4366.51 | BK4: ='1'!G84 -> 521 | BL4: =SUM(AQ4,AV4,AW4,AX4,BA4,BF4,BG4,BH4)/I4% -> 49.948214 | BM4: =SUM(AT4,BD4)/I4% -> 21.272925 | BN4: =(AS4+BC4)/I4 -> 0.10445493 | BO4: =K4+O4+R4+V4 -> 226108.25 | BP4: =SUM(AV4,AW4,AX4,BF4,BG4,BH4,BK4) -> 7160.47 | BQ4: =BP4/(AE4*280) -> 1.0637732 | BR4: =SUM(AV4,AW4,BF4,BG4)/(AE4*400) -> 0.45408798
A5: 2 | B5: 2 | D5: ='2'!D3 -> 27 | E5: ='2'!D4 -> 0.75 | F5: ='2'!D2 -> 0.48 | G5: ='2'!G8 -> 19533 | H5: ='2'!G8 -> 19533 | I5: ='2'!G7 -> 19381 | J5: 10 | K5: =H5*J5 -> 195330 | L5: =I5/202 -> 95.945545 | M5: ='2'!G15 -> 860.9 | N5: 35 | O5: =M5*N5 -> 30131.5 | P5: ='2'!G20 -> 171 | Q5: 134 | R5: =P5*Q5 -> 22914 | S5: =P5/(F5*202/100) -> 176.36139 | T5: ='2'!G24 -> 0 | U5: 69 | V5: =T5*U5 -> 0 | W5: ='2'!G95 -> 70 | X5: ='2'!G96 -> 30 | Y5: ='2'!G97 -> 16 | Z5: =W5+X5+Y5 -> 116 | AA5: ='2'!G132 -> 23.52 | AB5: ='2'!G133 -> 0 | AC5: ='2'!G134 -> 0 | AD5: ='2'!G135 -> 0 | AE5: =AA5+AB5+AC5+AD5 -> 23.52 | AF5: =AV5+AW5+BF5+BG5 -> 4172.58 | AG5: =AF5/AE5 -> 177.40561 | AH5: ='2'!G136 -> 8.73 | AI5: ='2'!G137 -> 0.19 | AJ5: ='2'!G138 -> 0 | AK5: =AH5+AI5+AJ5 -> 8.92 | AL5: ='2'!G139 -> 7.63 | AM5: ='2'!G140 -> 0 | AO5: =AL5+AM5 -> 7.63 | AP5: ='2'!G123 -> 258.22 | AQ5: ='2'!G35 -> 0 | AR5: ='2'!G37 -> 0 | AS5: ='2'!G38 -> 0 | AT5: ='2'!G39 -> 0 | AU5: ='2'!G40 -> 0 | AV5: ='2'!G41 -> 4170.49 | AW5: ='2'!G42 -> 0.09 | AX5: ='2'!G43 -> 2260.13 | AY5: ='2'!G44 -> 0 | AZ5: ='2'!G36 -> 621.35 | BA5: ='2'!G49 -> 3058.91 | BB5: ='2'!G51 -> 1441.43 | BC5: ='2'!G52 -> 2022.29 | BD5: ='2'!G53 -> 4158.97 | BE5: ='2'!G54 -> 39.04 | BF5: ='2'!G55 -> 0 | BG5: ='2'!G56 -> 2 | BH5: ='2'!G57 -> 0 | BI5: ='2'!G50 -> 1036.33 | BJ5: =SUM(AV5,AW5,BF5,BG5) -> 4172.58 | BK5: ='2'!G84 -> 534 | BL5: =SUM(AQ5,AV5,AW5,AX5,BA5,BF5,BG5,BH5)/I5% -> 48.97384 | BM5: =SUM(AT5,BD5)/I5% -> 21.459006 | BN5: =(AS5+BC5)/I5 -> 0.10434395 | BO5: =K5+O5+R5+V5 -> 248375.5 | BP5: =SUM(AV5,AW5,AX5,BF5,BG5,BH5,BK5) -> 6966.71 | BQ5: =BP5/(AE5*280) -> 1.0578702
A6: 3 | B6: 3 | D6: ='3'!D3 -> 27 | E6: ='3'!D4 -> 0.75 | F6: ='3'!D2 -> 0.35 | G6: ='3'!G8 -> 19671 | H6: ='3'!G8 -> 19671 | I6: ='3'!G7 -> 19375 | J6: 10 | K6: =H6*J6 -> 196710 | L6: =I6/202 -> 95.915842 | M6: ='3'!G15 -> 873 | N6: 35 | O6: =M6*N6 -> 30555 | P6: ='3'!G20 -> 161 | Q6: 134 | R6: =P6*Q6 -> 21574 | S6: =P6/(F6*202/100) -> 227.72277 | T6: ='3'!G24 -> 0 | U6: 69 | V6: =T6*U6 -> 0 | W6: ='3'!G95 -> 64 | X6: ='3'!G96 -> 36 | Y6: ='3'!G97 -> 31 | Z6: =W6+X6+Y6 -> 131 | AA6: ='3'!G132 -> 24 | AB6: ='3'!G133 -> 0 | AC6: ='3'!G134 -> 0 | AD6: ='3'!G135 -> 0 | AE6: =AA6+AB6+AC6+AD6 -> 24 | AF6: =AV6+AW6+BF6+BG6 -> 4011 | AG6: =AF6/AE6 -> 167.125 | AH6: ='3'!G136 -> 3.42 | AI6: ='3'!G137 -> 4.47 | AJ6: ='3'!G138 -> 0 | AK6: =AH6+AI6+AJ6 -> 7.89 | AL6: ='3'!G139 -> 7.78 | AM6: ='3'!G140 -> 0 | AO6: =AL6+AM6 -> 7.78 | AP6: ='3'!G123 -> 265 | AQ6: ='3'!G35 -> 2568.33 | AR6: ='3'!G37 -> 0 | AS6: ='3'!G38 -> 0 | AT6: ='3'!G39 -> 0 | AU6: ='3'!G40 -> 0 | AV6: ='3'!G41 -> 4011 | AW6: ='3'!G42 -> 0 | AX6: ='3'!G43 -> 2293 | AY6: ='3'!G44 -> 0 | AZ6: ='3'!G36 -> 784 | BA6: ='3'!G49 -> 14 | BB6: ='3'!G51 -> 1532 | BC6: ='3'!G52 -> 1949 | BD6: ='3'!G53 -> 4269 | BE6: ='3'!G54 -> 15 | BF6: ='3'!G55 -> 0 | BG6: ='3'!G56 -> 0 | BH6: ='3'!G57 -> 0 | BI6: ='3'!G50 -> 1386 | BJ6: =SUM(AV6,AW6,BF6,BG6) -> 4011 | BK6: ='3'!G84 -> 457 | BL6: =SUM(AQ6,AV6,AW6,AX6,BA6,BF6,BG6,BH6)/I6% -> 45.864929 | BM6: =SUM(AT6,BD6)/I6% -> 22.033548 | BN6: =(AS6+BC6)/I6 -> 0.10059355 | BO6: =K6+O6+R6+V6 -> 248839 | BP6: =SUM(AV6,AW6,AX6,BF6,BG6,BH6,BK6) -> 6761 | BQ6: =BP6/(AE6*280) -> 1.0061012
A7: 4 | B7: 4 | D7: ='4'!D3 -> 28 | E7: ='4'!D4 -> 0.75 | F7: ='4'!D2 -> 0.38 | G7: ='4'!G8 -> 18753 | H7: ='4'!G8 -> 18753 | I7: ='4'!G7 -> 18251 | J7: 10 | K7: =H7*J7 -> 187530 | L7: =I7/202 -> 90.351485 | M7: ='4'!G15 -> 796 | N7: 35 | O7: =M7*N7 -> 27860 | P7: ='4'!G20 -> 150 | Q7: 134 | R7: =P7*Q7 -> 20100 | S7: =P7/(F7*202/100) -> 195.41428 | T7: ='4'!G24 -> 380 | U7: 69 | V7: =T7*U7 -> 26220 | W7: ='4'!G95 -> 78 | X7: ='4'!G96 -> 35 | Y7: ='4'!G97 -> 45 | Z7: =W7+X7+Y7 -> 158 | AA7: ='4'!G132 -> 12 | AB7: ='4'!G133 -> 0 | AC7: ='4'!G134 -> 12 | AD7: ='4'!G135 -> 0 | AE7: =AA7+AB7+AC7+AD7 -> 24 | AF7: =AV7+AW7+BF7+BG7 -> 3732.9 | AG7: =AF7/AE7 -> 155.5375 | AH7: ='4'!G136 -> 5.23 | AI7: ='4'!G137 -> 2.17 | AJ7: ='4'!G138 -> 0 | AK7: =AH7+AI7+AJ7 -> 7.4 | AL7: ='4'!G139 -> 8.05 | AM7: ='4'!G140 -> 0 | AO7: =AL7+AM7 -> 8.05 | AP7: ='4'!G123 -> 275 | AQ7: ='4'!G35 -> 2607 | AR7: ='4'!G37 -> 1302 | AS7: ='4'!G38 -> 806.12 | AT7: ='4'!G39 -> 3521 | AU7: ='4'!G40 -> 0 | AV7: ='4'!G41 -> 1445 | AW7: ='4'!G42 -> -0.09 | AX7: ='4'!G43 -> 2251 | AY7: ='4'!G44 -> 0 | AZ7: ='4'!G36 -> 594 | BA7: ='4'!G49 -> 0 | BB7: ='4'!G51 -> 207 | BC7: ='4'!G52 -> 1105 | BD7: ='4'!G53 -> 627 | BE7: ='4'!G54 -> 8 | BF7: ='4'!G55 -> 2283.42 | BG7: ='4'!G56 -> 4.57 | BH7: ='4'!G57 -> 0 | BI7: ='4'!G50 -> 1085 | BJ7: =SUM(AV7,AW7,BF7,BG7) -> 3732.9 | BK7: ='3'!G84 -> 457 | BL7: =SUM(AQ7,AV7,AW7,AX7,BA7,BF7,BG7,BH7)/I7% -> 47.070845 | BM7: =SUM(AT7,BD7)/I7% -> 22.727522 | BN7: =(AS7+BC7)/I7 -> 0.10471317 | BO7: =K7+O7+R7+V7 -> 261710 | BP7: =SUM(AV7,AW7,AX7,BF7,BG7,BH7,BK7) -> 6440.9 | BQ7: =BP7/(AE7*280) -> 0.95846726
A8: 5 | B8: 5 | D8: ='5'!D3 -> 27 | E8: ='5'!D4 -> 0.75 | F8: ='5'!D2 -> 0.42 | G8: ='5'!G8 -> 18596 | H8: ='5'!G8 -> 18596 | I8: ='5'!G7 -> 18524 | J8: 10 | K8: =H8*J8 -> 185960 | L8: =I8/202 -> 91.70297 | M8: ='5'!G15 -> 778 | N8: 35 | O8: =M8*N8 -> 27230 | P8: ='5'!G20 -> 181 | Q8: 134 | R8: =P8*Q8 -> 24254 | S8: =P8/(F8*202/100) -> 213.34276 | T8: ='5'!G24 -> 0 | U8: 69 | V8: =T8*U8 -> 0 | W8: ='5'!G95 -> 55 | X8: ='5'!G96 -> 23 | Y8: ='5'!G97 -> 40 | Z8: =W8+X8+Y8 -> 118 | AA8: ='5'!G132 -> 0 | AB8: ='5'!G133 -> 0 | AC8: ='5'!G134 -> 24 | AD8: ='5'!G135 -> 0 | AE8: =AA8+AB8+AC8+AD8 -> 24 | AF8: =AV8+AW8+BF8+BG8 -> 3652 | AG8: =AF8/AE8 -> 152.16667 | AH8: ='5'!G136 -> 5.99 | AI8: ='5'!G137 -> 0.61 | AJ8: ='5'!G138 -> 0 | AK8: =AH8+AI8+AJ8 -> 6.6 | AL8: ='5'!G139 -> 7.38 | AM8: ='5'!G140 -> 0 | AO8: =AL8+AM8 -> 7.38 | AP8: ='5'!G123 -> 269 | AQ8: ='5'!G35 -> 0 | AR8: ='5'!G37 -> 170 | AS8: ='5'!G38 -> 0 | AT8: ='5'!G39 -> 582 | AU8: ='5'!G40 -> 0 | AV8: ='5'!G41 -> 1 | AW8: ='5'!G42 -> 0 | AX8: ='5'!G43 -> 332 | AY8: ='5'!G44 -> 0 | AZ8: ='5'!G36 -> 564 | BA8: ='5'!G49 -> 2649 | BB8: ='5'!G51 -> 1288 | BC8: ='5'!G52 -> 2075 | BD8: ='5'!G53 -> 3646 | BE8: ='5'!G54 -> 75 | BF8: ='5'!G55 -> 3651 | BG8: ='5'!G56 -> 0 | BH8: ='5'!G57 -> 1933 | BI8: ='5'!G50 -> 1105 | BJ8: =SUM(AV8,AW8,BF8,BG8) -> 3652 | BK8: ='5'!G84 -> 467 | BL8: =SUM(AQ8,AV8,AW8,AX8,BA8,BF8,BG8,BH8)/I8% -> 46.242712 | BM8: =SUM(AT8,BD8)/I8% -> 22.824444 | BN8: =(AS8+BC8)/I8 -> 0.11201684 | BO8: =K8+O8+R8+V8 -> 237444 | BP8: =SUM(AV8,AW8,AX8,BF8,BG8,BH8,BK8) -> 6384 | BQ8: =BP8/(AE8*280) -> 0.95
A9: 6 | B9: 6 | D9: ='6'!D3 -> 27 | E9: ='6'!D4 -> 0.75 | F9: ='6'!D2 -> 0.36 | G9: ='6'!G8 -> 19282 | H9: ='6'!G8 -> 19282 | I9: ='6'!G7 -> 19190 | J9: 10 | K9: =H9*J9 -> 192820 | L9: =I9/202 -> 95 | M9: ='6'!G15 -> 814 | N9: 35 | O9: =M9*N9 -> 28490 | P9: ='6'!G20 -> 271 | Q9: 134 | R9: =P9*Q9 -> 36314 | S9: =P9/(F9*202/100) -> 372.66227 | T9: ='6'!G24 -> 0 | U9: 69 | V9: =T9*U9 -> 0 | W9: ='6'!G95 -> 61 | X9: ='6'!G96 -> 34 | Y9: ='6'!G97 -> 31 | Z9: =W9+X9+Y9 -> 126 | AA9: ='6'!G132 -> 0 | AB9: ='6'!G133 -> 0 | AC9: ='6'!G134 -> 24 | AD9: ='6'!G135 -> 0 | AE9: =AA9+AB9+AC9+AD9 -> 24 | AF9: =AV9+AW9+BF9+BG9 -> 3905 | AG9: =AF9/AE9 -> 162.70833 | AH9: ='6'!G136 -> 4.8 | AI9: ='6'!G137 -> 2.25 | AJ9: ='6'!G138 -> 0 | AK9: =AH9+AI9+AJ9 -> 7.05 | AL9: ='6'!G139 -> 8.99 | AM9: ='6'!G140 -> 0 | AO9: =AL9+AM9 -> 8.99 | AP9: ='6'!G123 -> 288 | AQ9: ='6'!G35 -> 0 | AR9: ='6'!G37 -> 0 | AS9: ='6'!G38 -> 0 | AT9: ='6'!G39 -> 0 | AU9: ='6'!G40 -> 0 | AV9: ='6'!G41 -> 0 | AW9: ='6'!G42 -> 0 | AX9: ='6'!G43 -> 0 | AY9: ='6'!G44 -> 0 | AZ9: ='6'!G36 -> 729 | BA9: ='6'!G49 -> 2648 | BB9: ='6'!G51 -> 1509 | BC9: ='6'!G52 -> 2000 | BD9: ='6'!G53 -> 4153 | BE9: ='6'!G54 -> 70 | BF9: ='6'!G55 -> 3905 | BG9: ='6'!G56 -> 0 | BH9: ='6'!G57 -> 2282 | BI9: ='6'!G50 -> 1480 | BJ9: =SUM(AV9,AW9,BF9,BG9) -> 3905 | BK9: ='6'!G84 -> 477 | BL9: =SUM(AQ9,AV9,AW9,AX9,BA9,BF9,BG9,BH9)/I9% -> 46.039604 | BM9: =SUM(AT9,BD9)/I9% -> 21.64148 | BN9: =(AS9+BC9)/I9 -> 0.10422095 | BO9: =K9+O9+R9+V9 -> 257624 | BP9: =SUM(AV9,AW9,AX9,BF9,BG9,BH9,BK9) -> 6664 | BQ9: =BP9/(AE9*280) -> 0.99166667
A10: 7 | B10: 7 | D10: ='7'!D3 -> 26 | E10: ='7'!D4 -> 0.78 | F10: ='7'!D2 -> 0.54 | G10: ='7'!G8 -> 18315 | H10: ='7'!G8 -> 18315 | I10: ='7'!G7 -> 18255 | J10: 10 | K10: =H10*J10 -> 183150 | L10: =I10/202 -> 90.371287 | M10: ='7'!G15 -> 844.45 | N10: 35 | O10: =M10*N10 -> 29555.75 | P10: ='7'!G20 -> 212 | Q10: 134 | R10: =P10*Q10 -> 28408 | S10: =P10/(F10*202/100) -> 194.35277 | T10: ='7'!G24 -> 0 | U10: 69 | V10: =T10*U10 -> 0 | W10: ='7'!G95 -> 57 | X10: ='7'!G96 -> 43 | Y10: ='7'!G97 -> 23 | Z10: =W10+X10+Y10 -> 123 | AA10: ='7'!G132 -> 0 | AB10: ='7'!G133 -> 0 | AC10: ='7'!G134 -> 24 | AD10: ='7'!G135 -> 0 | AE10: =AA10+AB10+AC10+AD10 -> 24 | AF10: =AV10+AW10+BF10+BG10 -> 3495.98 | AG10: =AF10/AE10 -> 145.66583 | AH10: ='7'!G136 -> 7.92 | AI10: ='7'!G137 -> -0.03 | AJ10: ='7'!G138 -> 0 | AK10: =AH10+AI10+AJ10 -> 7.89 | AL10: ='7'!G139 -> 8.63 | AM10: ='7'!G140 -> 0 | AO10: =AL10+AM10 -> 8.63 | AP10: ='7'!G123 -> 296 | AQ10: ='7'!G35 -> 0 | AR10: ='7'!G37 -> 0 | AS10: ='7'!G38 -> 0 | AT10: ='7'!G39 -> 0 | AU10: ='7'!G40 -> 0 | AV10: ='7'!G41 -> 0 | AW10: ='7'!G42 -> 0 | AX10: ='7'!G43 -> 0 | AY10: ='7'!G44 -> 0 | AZ10: ='7'!G36 -> 577.81 | BA10: ='7'!G49 -> 2499.67 | BB10: ='7'!G51 -> 1427 | BC10: ='7'!G52 -> 2118 | BD10: ='7'!G53 -> 4176 | BE10: ='7'!G54 -> 71 | BF10: ='7'!G55 -> 3495.98 | BG10: ='7'!G56 -> 0 | BH10: ='7'!G57 -> 2319 | BI10: ='7'!G50 -> 1109 | BJ10: =SUM(AV10,AW10,BF10,BG10) -> 3495.98 | BK10: ='7'!G84 -> 466 | BL10: =SUM(AQ10,AV10,AW10,AX10,BA10,BF10,BG10,BH10)/I10% -> 45.547247 | BM10: =SUM(AT10,BD10)/I10% -> 22.875924 | BN10: =(AS10+BC10)/I10 -> 0.11602301 | BO10: =K10+O10+R10+V10 -> 241113.75 | BP10: =SUM(AV10,AW10,AX10,BF10,BG10,BH10,BK10) -> 6280.98 | BQ10: =BP10/(AE10*280) -> 0.93466964
A11: 8 | B11: 8 | D11: ='8'!D3 -> 25 | E11: ='8'!D4 -> 0.77 | F11: ='8'!D2 -> 0.63 | G11: ='8'!G8 -> 15437 | H11: ='8'!G8 -> 15437 | I11: ='8'!G7 -> 15387 | J11: 10 | K11: =H11*J11 -> 154370 | L11: =I11/202 -> 76.173267 | M11: ='8'!G15 -> 816.28 | N11: 35 | O11: =M11*N11 -> 28569.8 | P11: ='8'!G20 -> 211 | Q11: 134 | R11: =P11*Q11 -> 28274 | S11: =P11/(F11*202/100) -> 165.80229 | T11: ='8'!G24 -> 1970 | U11: 69 | V11: =T11*U11 -> 135930 | W11: ='8'!G95 -> 71 | X11: ='8'!G96 -> 51 | Y11: ='8'!G97 -> 20 | Z11: =W11+X11+Y11 -> 142 | AA11: ='8'!G132 -> 3.29 | AB11: ='8'!G133 -> 0 | AC11: ='8'!G134 -> 20.45 | AD11: ='8'!G135 -> 0 | AE11: =AA11+AB11+AC11+AD11 -> 23.74 | AF11: =AV11+AW11+BF11+BG11 -> 3857.89 | AG11: =AF11/AE11 -> 162.5059 | AH11: ='8'!G136 -> 8.63 | AI11: ='8'!G137 -> 0.03 | AJ11: ='8'!G138 -> 0 | AK11: =AH11+AI11+AJ11 -> 8.66 | AL11: ='8'!G139 -> 8 | AM11: ='8'!G140 -> 0 | AO11: =AL11+AM11 -> 8 | AP11: ='8'!G123 -> 274.98 | AQ11: ='8'!G35 -> 1550.91 | AR11: ='8'!G37 -> 667.27 | AS11: ='8'!G38 -> 1219.92 | AT11: ='8'!G39 -> 1747.78 | AU11: ='8'!G40 -> 0 | AV11: ='8'!G41 -> 643.87 | AW11: ='8'!G42 -> 0 | AX11: ='8'!G43 -> 1162.67 | AY11: ='8'!G44 -> 0 | AZ11: ='8'!G36 -> 628.6 | BA11: ='8'!G49 -> 967.33 | BB11: ='8'!G51 -> 1108.92 | BC11: ='8'!G52 -> 819.71 | BD11: ='8'!G53 -> 2422.51 | BE11: ='8'!G54 -> 60 | BF11: ='8'!G55 -> 3214.02 | BG11: ='8'!G56 -> 0 | BH11: ='8'!G57 -> 1177 | BI11: ='8'!G50 -> 1081 | BJ11: =SUM(AV11,AW11,BF11,BG11) -> 3857.89 | BK11: ='8'!G84 -> 476 | BL11: =SUM(AQ11,AV11,AW11,AX11,BA11,BF11,BG11,BH11)/I11% -> 56.64392 | BM11: =SUM(AT11,BD11)/I11% -> 27.102684 | BN11: =(AS11+BC11)/I11 -> 0.1325554 | BO11: =K11+O11+R11+V11 -> 347143.8 | BP11: =SUM(AV11,AW11,AX11,BF11,BG11,BH11,BK11) -> 6673.56 | BQ11: =BP11/(AE11*280) -> 1.0039656
A12: 9 | B12: 9 | D12: ='9'!D3 -> 25 | E12: ='9'!D4 -> 0.77 | F12: ='9'!D2 -> 0.65 | G12: ='9'!G8 -> 18453 | H12: ='9'!G8 -> 18453 | I12: ='9'!G7 -> 18397 | J12: 10 | K12: =H12*J12 -> 184530 | L12: =I12/202 -> 91.074257 | M12: ='9'!G15 -> 637.05 | N12: 35 | O12: =M12*N12 -> 22296.75 | P12: ='9'!G20 -> 192 | Q12: 134 | R12: =P12*Q12 -> 25728 | S12: =P12/(F12*202/100) -> 146.23001 | T12: ='9'!G24 -> 0 | U12: 69 | V12: =T12*U12 -> 0 | W12: ='9'!G95 -> 62 | X12: ='9'!G96 -> 40 | Y12: ='9'!G97 -> 29 | Z12: =W12+X12+Y12 -> 131 | AA12: ='9'!G132 -> 0 | AB12: ='9'!G133 -> 0 | AC12: ='9'!G134 -> 24.04 | AD12: ='9'!G135 -> 0 | AE12: =AA12+AB12+AC12+AD12 -> 24.04 | AF12: =AV12+AW12+BF12+BG12 -> 3536 | AG12: =AF12/AE12 -> 147.08819 | AH12: ='9'!G136 -> 0.25 | AI12: ='9'!G137 -> -0.03 | AJ12: ='9'!G138 -> 9.08 | AK12: =AH12+AI12+AJ12 -> 9.3 | AL12: ='9'!G139 -> 9 | AM12: ='9'!G140 -> 0 | AO12: =AL12+AM12 -> 9 | AP12: ='9'!G123 -> 310.02 | AQ12: ='9'!G35 -> 2513.92 | AR12: ='9'!G37 -> 1433.25 | AS12: ='9'!G38 -> 1896.54 | AT12: ='9'!G39 -> 4116.22 | AU12: ='9'!G40 -> 0 | AV12: ='9'!G41 -> 0 | AW12: ='9'!G42 -> 0 | AX12: ='9'!G43 -> 2539.33 | AY12: ='9'!G44 -> 0 | AZ12: ='9'!G36 -> 645.4 | BA12: ='9'!G49 -> 0 | BB12: ='9'!G51 -> 0 | BC12: ='9'!G52 -> 0 | BD12: ='9'!G53 -> 0 | BE12: ='9'!G54 -> 69.84 | BF12: ='9'!G55 -> 3536 | BG12: ='9'!G56 -> 0 | BH12: ='9'!G57 -> 0 | BI12: ='9'!G50 -> 1173 | BJ12: =SUM(AV12,AW12,BF12,BG12) -> 3536 | BK12: ='8'!G84 -> 476 | BL12: =SUM(AQ12,AV12,AW12,AX12,BA12,BF12,BG12,BH12)/I12% -> 46.688319 | BM12: =SUM(AT12,BD12)/I12% -> 22.374409 | BN12: =(AS12+BC12)/I12 -> 0.10308963 | BO12: =K12+O12+R12+V12 -> 232554.75 | BP12: =SUM(AV12,AW12,AX12,BF12,BG12,BH12,BK12) -> 6551.33 | BQ12: =BP12/(AE12*280) -> 0.97327817
