Workbook

Sheet TOTAL
A1: Site Name | B1: Day | C1: Month | D1: Year | E1: Total Electricity Kwh | F1: Electricity Tariff ($/Kwh) | G1: LPG (Kg) | H1: LPG $/Kg | I1: Water Utility Supply (m3) m3 | J1: Water Utility Supply (m3) $/m3 | K1: Room Nights | L1: Food Covers
A2: Maldives at Landaa Giraavaru | B2: 1 | C2: 3 | D2: 2021 | E2: ='Maldives at LG Daily'!D5 -> 30462 | F2: 0.93 | G2: ='Maldives at LG Daily'!F5 -> 90 | H2: 1.24 | I2: ='Maldives at LG Daily'!H5 -> 418 | J2: 1.72 | K2: ='Maldives at LG Daily'!I5 -> 78.6 | L2: ='Maldives at LG Daily'!J5 -> 577
A3: Maldives at Landaa Giraavaru | B3: =B2+1 -> 2 | C3: 3 | D3: 2021 | E3: ='Maldives at LG Daily'!D6 -> 31274 | F3: 0.93 | G3: ='Maldives at LG Daily'!F6 -> 90 | H3: 1.24 | I3: ='Maldives at LG Daily'!H6 -> 386 | J3: 1.72 | K3: ='Maldives at LG Daily'!I6 -> 78.6 | L3: ='Maldives at LG Daily'!J6 -> 583
A4: Maldives at Landaa Giraavaru | B4: =B3+1 -> 3 | C4: 3 | D4: 2021 | E4: ='Maldives at LG Daily'!D7 -> 30266 | F4: 0.93 | G4: ='Maldives at LG Daily'!F7 -> 0 | H4: 1.24 | I4: ='Maldives at LG Daily'!H7 -> 452 | J4: 1.72 | K4: ='Maldives at LG Daily'!I7 -> 71.8 | L4: ='Maldives at LG Daily'!J7 -> 570
A5: Maldives at Landaa Giraavaru | B5: =B4+1 -> 4 | C5: 3 | D5: 2021 | E5: ='Maldives at LG Daily'!D8 -> 29095 | F5: 0.93 | G5: ='Maldives at LG Daily'!F8 -> 180 | H5: 1.24 | I5: ='Maldives at LG Daily'!H8 -> 435 | J5: 1.72 | K5: ='Maldives at LG Daily'!I8 -> 69.9 | L5: ='Maldives at LG Daily'!J8 -> 553
A6: Maldives at Landaa Giraavaru | B6: =B5+1 -> 5 | C6: 3 | D6: 2021 | E6: ='Maldives at LG Daily'!D9 -> 30371 | F6: 0.93 | G6: ='Maldives at LG Daily'!F9 -> 0 | H6: 1.24 | I6: ='Maldives at LG Daily'!H9 -> 444 | J6: 1.72 | K6: ='Maldives at LG Daily'!I9 -> 61.2 | L6: ='Maldives at LG Daily'!J9 -> 538
A7: Maldives at Landaa Giraavaru | B7: =B6+1 -> 6 | C7: 3 | D7: 2021 | E7: ='Maldives at LG Daily'!D10 -> 31077 | F7: 0.93 | G7: ='Maldives at LG Daily'!F10 -> 270 | H7: 1.24 | I7: ='Maldives at LG Daily'!H10 -> 477 | J7: 1.72 | K7: ='Maldives at LG Daily'!I10 -> 60.2 | L7: ='Maldives at LG Daily'!J10 -> 466
A8: Maldives at Landaa Giraavaru | B8: =B7+1 -> 7 | C8: 3 | D8: 2021 | E8: ='Maldives at LG Daily'!D11 -> 30879 | F8: 0.93 | G8: ='Maldives at LG Daily'!F11 -> 0 | H8: 1.24 | I8: ='Maldives at LG Daily'!H11 -> 411 | J8: 1.72 | K8: ='Maldives at LG Daily'!I11 -> 55.3 | L8: ='Maldives at LG Daily'!J11 -> 459
A9: Maldives at Landaa Giraavaru | B9: =B8+1 -> 8 | C9: 3 | D9: 2021 | E9: ='Maldives at LG Daily'!D12 -> 30415 | F9: 0.93 | G9: ='Maldives at LG Daily'!F12 -> 540 | H9: 1.24 | I9: ='Maldives at LG Daily'!H12 -> 423 | J9: 1.72 | K9: ='Maldives at LG Daily'!I12 -> 53.4 | L9: ='Maldives at LG Daily'!J12 -> 462
A10: Maldives at Landaa Giraavaru | B10: =B9+1 -> 9 | C10: 3 | D10: 2021 | E10: ='Maldives at LG Daily'!D13 -> 31010 | F10: 0.93 | G10: ='Maldives at LG Daily'!F13 -> 0 | H10: 1.24 | I10: ='Maldives at LG Daily'!H13 -> 410 | J10: 1.72 | K10: ='Maldives at LG Daily'!I13 -> 45.6 | L10: ='Maldives at LG Daily'!J13 -> 378
A11: Maldives at Landaa Giraavaru | B11: =B10+1 -> 10 | C11: 3 | D11: 2021 | E11: ='Maldives at LG Daily'!D14 -> 28059 | F11: 0.93 | G11: ='Maldives at LG Daily'!F14 -> 360 | H11: 1.24 | I11: ='Maldives at LG Daily'!H14 -> 415 | J11: 1.72 | K11: ='Maldives at LG Daily'!I14 -> 41.7 | L11: ='Maldives at LG Daily'!J14 -> 339
A12: Maldives at Landaa Giraavaru | B12: =B11+1 -> 11 | C12: 3 | D12: 2021 | E12: ='Maldives at LG Daily'!D15 -> 24815 | F12: 0.93 | G12: ='Maldives at LG Daily'!F15 -> 0 | H12: 1.24 | I12: ='Maldives at LG Daily'!H15 -> 396 | J12: 1.72 | K12: ='Maldives at LG Daily'!I15 -> 43.7 | L12: ='Maldives at LG Daily'!J15 -> 371
A13: Maldives at Landaa Giraavaru | B13: =B12+1 -> 12 | C13: 3 | D13: 2021 | E13: ='Maldives at LG Daily'!D16 -> 26393 | F13: 0.93 | G13: ='Maldives at LG Daily'!F16 -> 180 | H13: 1.24 | I13: ='Maldives at LG Daily'!H16 -> 341 | J13: 1.72 | K13: ='Maldives at LG Daily'!I16 -> 42.7 | L13: ='Maldives at LG Daily'!J16 -> 376
A14: Maldives at Landaa Giraavaru | B14: =B13+1 -> 13 | C14: 3 | D14: 2021 | E14: ='Maldives at LG Daily'!D17 -> 27554 | F14: 0.93 | G14: ='Maldives at LG Daily'!F17 -> 0 | H14: 1.24 | I14: ='Maldives at LG Daily'!H17 -> 345 | J14: 1.72 | K14: ='Maldives at LG Daily'!I17 -> 43.7 | L14: ='Maldives at LG Daily'!J17 -> 380
... A32: Maldives at Landaa Giraavaru | B32: =B31+1 -> 31 | C32: 3 | D32: 2021 | E32: ='Maldives at LG Daily'!D35 -> 0 | F32: 0.93 | G32: ='Maldives at LG Daily'!F35 -> 0 | H32: 4.24 | I32: ='Maldives at LG Daily'!H35 -> 0 | J32: 4.72 | K32: ='Maldives at LG Daily'!I35 -> 0 | L32: ='Maldives at LG Daily'!J35 -> 0

Sheet Maldives at LG Daily
A2: Days | C2: Electricity Meter (KWh) | E2: Gas Kg | G2: Water m3
A3: Date | C3: Reading KWH | D3: Difference KWH | E3: Reading Kg | F3: Difference Kg | G3: Reading m³ | H3: Daily Consumption m³ | I3: ROOM NIGHTS | J3: TOTAL GUESTS
A4: 44255 | C4: =SUM('GENSET #1'!B10+'GENSET #2'!B10+'GENSET #3'!B10+'GENSET #4'!B10+'GENSET #5'!B10) -> 87747538 | D4: 30577 | E4: ='Gas-2'!G5 -> 180 | F4: 90 | G4: =SUM(WATER!G6,WATER!L6,WATER!Q6,WATER!B6) -> 923511.8 | H4: 423 | I4: 81 | J4: 598
A5: =A4+1 -> 44256 | C5: =SUM('GENSET #1'!B11+'GENSET #2'!B11+'GENSET #3'!B11+'GENSET #4'!B11+'GENSET #5'!B11) -> 87778000 | D5: =IF((C5-C4<0), "0",C5-C4) -> 30462 | E5: ='Gas-2'!G6 -> 270 | F5: =IF((E5-E4<0), "0",E5-E4) -> 90 | G5: =SUM(WATER!C6,WATER!H6,WATER!M6,WATER!R6) -> 922337 | H5: 418 | I5: 78.6 | J5: 577
A6: =A5+1 -> 44257 | C6: =SUM('GENSET #1'!B12+'GENSET #2'!B12+'GENSET #3'!B12+'GENSET #4'!B12+'GENSET #5'!B12) -> 87809274 | D6: =IF((C6-C5<0), "0",C6-C5) -> 31274 | E6: ='Gas-2'!G7 -> 360 | F6: =IF((E6-E5<0), "0",E6-E5) -> 90 | G6: =SUM(WATER!C7,WATER!H7,WATER!M7,WATER!R7) -> 922723 | H6: =IF((G6-G5<0), "0",G6-G5) -> 386 | I6: 78.6 | J6: 583
A7: =A6+1 -> 44258 | C7: =SUM('GENSET #1'!B13+'GENSET #2'!B13+'GENSET #3'!B13+'GENSET #4'!B13+'GENSET #5'!B13) -> 87839540 | D7: =IF((C7-C6<0), "0",C7-C6) -> 30266 | E7: ='Gas-2'!G8 -> 135 | F7: =IF((E7-E6<0), "0",E7-E6) -> 0 | G7: =SUM(WATER!C8,WATER!H8,WATER!M8,WATER!R8) -> 923175 | H7: =IF((G7-G6<0), "0",G7-G6) -> 452 | I7: 71.8 | J7: 570
A8: =A7+1 -> 44259 | C8: =SUM('GENSET #1'!B14+'GENSET #2'!B14+'GENSET #3'!B14+'GENSET #4'!B14+'GENSET #5'!B14) -> 87868635 | D8: =IF((C8-C7<0), "0",C8-C7) -> 29095 | E8: ='Gas-2'!G9 -> 315 | F8: =IF((E8-E7<0), "0",E8-E7) -> 180 | G8: =SUM(WATER!C9,WATER!H9,WATER!M9,WATER!R9) -> 923610 | H8: =IF((G8-G7<0), "0",G8-G7) -> 435 | I8: 69.9 | J8: 553
A9: =A8+1 -> 44260 | C9: =SUM('GENSET #1'!B15+'GENSET #2'!B15+'GENSET #3'!B15+'GENSET #4'!B15+'GENSET #5'!B15) -> 87899006 | D9: =IF((C9-C8<0), "0",C9-C8) -> 30371 | E9: ='Gas-2'!G10 -> 45 | F9: =IF((E9-E8<0), "0",E9-E8) -> 0 | G9: =SUM(WATER!C10,WATER!H10,WATER!M10,WATER!R10) -> 924054 | H9: =IF((G9-G8<0), "0",G9-G8) -> 444 | I9: 61.2 | J9: 538
A10: =A9+1 -> 44261 | C10: =SUM('GENSET #1'!B16+'GENSET #2'!B16+'GENSET #3'!B16+'GENSET #4'!B16+'GENSET #5'!B16) -> 87930083 | D10: =IF((C10-C9<0), "0",C10-C9) -> 31077 | E10: ='Gas-2'!G11 -> 315 | F10: =IF((E10-E9<0), "0",E10-E9) -> 270 | G10: =SUM(WATER!C11,WATER!H11,WATER!M11,WATER!R11) -> 924531 | H10: =IF((G10-G9<0), "0",G10-G9) -> 477 | I10: 60.2 | J10: 466
A11: =A10+1 -> 44262 | C11: =SUM('GENSET #1'!B17+'GENSET #2'!B17+'GENSET #3'!B17+'GENSET #4'!B17+'GENSET #5'!B17) -> 87960962 | D11: =IF((C11-C10<0), "0",C11-C10) -> 30879 | E11: ='Gas-2'!G12 -> 0 | F11: =IF((E11-E10<0), "0",E11-E10) -> 0 | G11: =SUM(WATER!C12,WATER!H12,WATER!M12,WATER!R12) -> 924942 | H11: =IF((G11-G10<0), "0",G11-G10) -> 411 | I11: 55.3 | J11: 459
A12: =A11+1 -> 44263 | C12: =SUM('GENSET #1'!B18+'GENSET #2'!B18+'GENSET #3'!B18+'GENSET #4'!B18+'GENSET #5'!B18) -> 87991377 | D12: =IF((C12-C11<0), "0",C12-C11) -> 30415 | E12: ='Gas-2'!G13 -> 540 | F12: =IF((E12-E11<0), "0",E12-E11) -> 540 | G12: =SUM(WATER!C13,WATER!H13,WATER!M13,WATER!R13) -> 925365 | H12: =IF((G12-G11<0), "0",G12-G11) -> 423 | I12: 53.4 | J12: 462
A13: =A12+1 -> 44264 | C13: =SUM('GENSET #1'!B19+'GENSET #2'!B19+'GENSET #3'!B19+'GENSET #4'!B19+'GENSET #5'!B19) -> 88022387 | D13: =IF((C13-C12<0), "0",C13-C12) -> 31010 | E13: ='Gas-2'!G14 -> 0 | F13: =IF((E13-E12<0), "0",E13-E12) -> 0 | G13: =SUM(WATER!C14,WATER!H14,WATER!M14,WATER!R14) -> 925775 | H13: =IF((G13-G12<0), "0",G13-G12) -> 410 | I13: 45.6 | J13: 378
A14: =A13+1 -> 44265 | C14: =SUM('GENSET #1'!B20+'GENSET #2'!B20+'GENSET #3'!B20+'GENSET #4'!B20+'GENSET #5'!B20) -> 88050446 | D14: =IF((C14-C13<0), "0",C14-C13) -> 28059 | E14: ='Gas-2'!G15 -> 360 | F14: =IF((E14-E13<0), "0",E14-E13) -> 360 | G14: =SUM(WATER!C15,WATER!H15,WATER!M15,WATER!R15) -> 926190 | H14: =IF((G14-G13<0), "0",G14-G13) -> 415 | I14: 41.7 | J14: 339
A15: =A14+1 -> 44266 | C15: =SUM('GENSET #1'!B21+'GENSET #2'!B21+'GENSET #3'!B21+'GENSET #4'!B21+'GENSET #5'!B21) -> 88075261 | D15: =IF((C15-C14<0), "0",C15-C14) -> 24815 | E15: ='Gas-2'!G16 -> 0 | F15: =IF((E15-E14<0), "0",E15-E14) -> 0 | G15: =SUM(WATER!C16,WATER!H16,WATER!M16,WATER!R16) -> 926586 | H15: =IF((G15-G14<0), "0",G15-G14) -> 396 | I15: 43.7 | J15: 371
A16: =A15+1 -> 44267 | C16: =SUM('GENSET #1'!B22+'GENSET #2'!B22+'GENSET #3'!B22+'GENSET #4'!B22+'GENSET #5'!B22) -> 88101654 | D16: =IF((C16-C15<0), "0",C16-C15) -> 26393 | E16: ='Gas-2'!G17 -> 180 | F16: =IF((E16-E15<0), "0",E16-E15) -> 180 | G16: =SUM(WATER!C17,WATER!H17,WATER!M17,WATER!R17) -> 926927 | H16: =IF((G16-G15<0), "0",G16-G15) -> 341 | I16: 42.7 | J16: 376
A17: =A16+1 -> 44268 | C17: =SUM('GENSET #1'!B23+'GENSET #2'!B23+'GENSET #3'!B23+'GENSET #4'!B23+'GENSET #5'!B23) -> 88129208 | D17: =IF((C17-C16<0), "0",C17-C16) -> 27554 | E17: ='Gas-2'!G18 -> 135 | F17: =IF((E17-E16<0), "0",E17-E16) -> 0 | G17: =SUM(WATER!C18,WATER!H18,WATER!M18,WATER!R18) -> 927272 | H17: =IF((G17-G16<0), "0",G17-G16) -> 345 | I17: 43.7 | J17: 380
... A23: =A22+1 -> 44274 | C23: =SUM('GENSET #1'!B29+'GENSET #2'!B29+'GENSET #3'!B29+'GENSET #4'!B29+'GENSET #5'!B29) -> 88302511 | D23: =IF((C23-C22<0), "0",C23-C22) -> 29287 | E23: ='Gas-2'!G24 -> 0 | F23: =IF((E23-E22<0), "0",E23-E22) -> 0 | G23: =SUM(WATER!C24,WATER!H24,WATER!M24,WATER!R24) -> 929807 | H23: =IF((G23-G22<0), "0",G23-G22) -> 392 | I23: 47.6 | J23: 378
A24: =A23+1 -> 44275 | C24: =SUM('GENSET #1'!B30+'GENSET #2'!B30+'GENSET #3'!B30+'GENSET #4'!B30+'GENSET #5'!B30) -> 88331778 | D24: =IF((C24-C23<0), "0",C24-C23) -> 29267 | E24: ='Gas-2'!G25 -> 495 | F24: =IF((E24-E23<0), "0",E24-E23) -> 495 | G24: =SUM(WATER!C25,WATER!H25,WATER!M25,WATER!R25) -> 930208 | H24: =IF((G24-G23<0), "0",G24-G23) -> 401
A25: =A24+1 -> 44276 | C25: =SUM('GENSET #1'!B31+'GENSET #2'!B31+'GENSET #3'!B31+'GENSET #4'!B31+'GENSET #5'!B31) -> 0 | D25: =IF((C25-C24<0), "0",C25-C24) -> 0 | E25: ='Gas-2'!G26 -> 0 | F25: =IF((E25-E24<0), "0",E25-E24) -> 0 | G25: =SUM(WATER!C26,WATER!H26,WATER!M26,WATER!R26) -> 930616 | H25: =IF((G25-G24<0), "0",G25-G24) -> 408
A26: =A25+1 -> 44277 | C26: =SUM('GENSET #1'!B32+'GENSET #2'!B32+'GENSET #3'!B32+'GENSET #4'!B32+'GENSET #5'!B32) -> 0 | D26: =IF((C26-C25<0), "0",C26-C25) -> 0 | E26: ='Gas-2'!G27 -> 0 | F26: =IF((E26-E25<0), "0",E26-E25) -> 0 | G26: =SUM(WATER!C27,WATER!H27,WATER!M27,WATER!R27) -> 0 | H26: =IF((G26-G25<0), "0",G26-G25) -> 0
A27: =A26+1 -> 44278 | C27: =SUM('GENSET #1'!B33+'GENSET #2'!B33+'GENSET #3'!B33+'GENSET #4'!B33+'GENSET #5'!B33) -> 0 | D27: =IF((C27-C26<0), "0",C27-C26) -> 0 | E27: ='Gas-2'!G28 -> 0 | F27: =IF((E27-E26<0), "0",E27-E26) -> 0 | G27: =SUM(WATER!C28,WATER!H28,WATER!M28,WATER!R28) -> 0 | H27: =IF((G27-G26<0), "0",G27-G26) -> 0
A28: =A27+1 -> 44279 | C28: =SUM('GENSET #1'!B34+'GENSET #2'!B34+'GENSET #3'!B34+'GENSET #4'!B34+'GENSET #5'!B34) -> 0 | D28: =IF((C28-C27<0), "0",C28-C27) -> 0 | E28: ='Gas-2'!G29 -> 0 | F28: =IF((E28-E27<0), "0",E28-E27) -> 0 | G28: =SUM(WATER!C29,WATER!H29,WATER!M29,WATER!R29) -> 0 | H28: =IF((G28-G27<0), "0",G28-G27) -> 0
A29: =A28+1 -> 44280 | C29: =SUM('GENSET #1'!B35+'GENSET #2'!B35+'GENSET #3'!B35+'GENSET #4'!B35+'GENSET #5'!B35) -> 0 | D29: =IF((C29-C28<0), "0",C29-C28) -> 0 | E29: ='Gas-2'!G30 -> 0 | F29: =IF((E29-E28<0), "0",E29-E28) -> 0 | G29: =SUM(WATER!C30,WATER!H30,WATER!M30,WATER!R30) -> 0 | H29: =IF((G29-G28<0), "0",G29-G28) -> 0
A30: =A29+1 -> 44281 | C30: =SUM('GENSET #1'!B36+'GENSET #2'!B36+'GENSET #3'!B36+'GENSET #4'!B36+'GENSET #5'!B36) -> 0 | D30: =IF((C30-C29<0), "0",C30-C29) -> 0 | E30: ='Gas-2'!G31 -> 0 | F30: =IF((E30-E29<0), "0",E30-E29) -> 0 | G30: =SUM(WATER!C31,WATER!H31,WATER!M31,WATER!R31) -> 0 | H30: =IF((G30-G29<0), "0",G30-G29) -> 0
A31: =A30+1 -> 44282 | C31: =SUM('GENSET #1'!B37+'GENSET #2'!B37+'GENSET #3'!B37+'GENSET #4'!B37+'GENSET #5'!B37) -> 0 | D31: =IF((C31-C30<0), "0",C31-C30) -> 0 | E31: ='Gas-2'!G32 -> 0 | F31: =IF((E31-E30<0), "0",E31-E30) -> 0 | G31: =SUM(WATER!C32,WATER!H32,WATER!M32,WATER!R32) -> 0 | H31: =IF((G31-G30<0), "0",G31-G30) -> 0
A32: =A31+1 -> 44283 | C32: =SUM('GENSET #1'!B38+'GENSET #2'!B38+'GENSET #3'!B38+'GENSET #4'!B38+'GENSET #5'!B38) -> 0 | D32: =IF((C32-C31<0), "0",C32-C31) -> 0 | E32: ='Gas-2'!G33 -> 0 | F32: =IF((E32-E31<0), "0",E32-E31) -> 0 | G32: =SUM(WATER!C33,WATER!H33,WATER!M33,WATER!R33) -> 0 | H32: =IF((G32-G31<0), "0",G32-G31) -> 0
A33: =A32+1 -> 44284 | C33: =SUM('GENSET #1'!B39+'GENSET #2'!B39+'GENSET #3'!B39+'GENSET #4'!B39+'GENSET #5'!B39) -> 0 | D33: =IF((C33-C32<0), "0",C33-C32) -> 0 | E33: ='Gas-2'!G34 -> 0 | F33: =IF((E33-E32<0), "0",E33-E32) -> 0 | G33: =SUM(WATER!C34,WATER!H34,WATER!M34,WATER!R34) -> 0 | H33: =IF((G33-G32<0), "0",G33-G32) -> 0
A34: =A33+1 -> 44285 | C34: =SUM('GENSET #1'!B40+'GENSET #2'!B40+'GENSET #3'!B40+'GENSET #4'!B40+'GENSET #5'!B40) -> 0 | D34: =IF((C34-C33<0), "0",C34-C33) -> 0 | E34: ='Gas-2'!G35 -> 0 | F34: =IF((E34-E33<0), "0",E34-E33) -> 0 | G34: =SUM(WATER!C35,WATER!H35,WATER!M35,WATER!R35) -> 0 | H34: =IF((G34-G33<0), "0",G34-G33) -> 0
A35: =A34+1 -> 44286 | C35: =SUM('GENSET #1'!B41+'GENSET #2'!B41+'GENSET #3'!B41+'GENSET #4'!B41+'GENSET #5'!B41) -> 0 | D35: =IF((C35-C34<0), "0",C35-C34) -> 0 | E35: ='Gas-2'!G36 -> 0 | F35: =IF((E35-E34<0), "0",E35-E34) -> 0 | G35: =SUM(WATER!C36,WATER!H36,WATER!M36,WATER!R36) -> 0 | H35: =IF((G35-G34<0), "0",G35-G34) -> 0

Sheet Finance Only
A1: Four Seasons Landaa Giraavaru
A3: Property | B3: MLG
A4: Month | B4: March
A5: Year | B5: 2021
A7: DAY | B7: Electricity Consumption ( kwh) | C7: Diesel Consumption (Liters) | D7: Solar Power Consumption(kwh) | E7: Gas Consumption (kg) | F7: Water Consumption ( m3)
A8: 1 | B8: =SUM('GENSET #1:GENSET #5'!D10) -> 30462 | C8: ='Diesel consumption'!D5 -> 8470 | D8: ='SOLAR METER READING'!D9 -> 3074 | E8: ='Gas-2'!G6 -> 270 | F8: =WATER!V6 -> 418
A9: 2 | B9: =SUM('GENSET #1:GENSET #5'!D11) -> 31274 | C9: ='Diesel consumption'!D6 -> 8650 | D9: ='SOLAR METER READING'!D10 -> 3257 | E9: ='Gas-2'!G7 -> 360 | F9: =WATER!V7 -> 386
A10: 3 | B10: =SUM('GENSET #1:GENSET #5'!D12) -> 30266 | C10: ='Diesel consumption'!D7 -> 8340 | D10: ='SOLAR METER READING'!D11 -> 3651 | E10: ='Gas-2'!G8 -> 135 | F10: =WATER!V8 -> 452
A11: 4 | B11: =SUM('GENSET #1:GENSET #5'!D13) -> 29095 | C11: ='Diesel consumption'!D8 -> 8260 | D11: ='SOLAR METER READING'!D12 -> 2690 | E11: ='Gas-2'!G9 -> 315 | F11: =WATER!V9 -> 435
A12: 5 | B12: =SUM('GENSET #1:GENSET #5'!D14) -> 30371 | C12: ='Diesel consumption'!D9 -> 8550 | D12: ='SOLAR METER READING'!D13 -> 3273 | E12: ='Gas-2'!G10 -> 45 | F12: =WATER!V10 -> 444
A13: 6 | B13: =SUM('GENSET #1:GENSET #5'!D15) -> 31077 | C13: ='Diesel consumption'!D10 -> 8670 | D13: ='SOLAR METER READING'!D14 -> 3257 | E13: ='Gas-2'!G11 -> 315 | F13: =WATER!V11 -> 477
A14: 7 | B14: =SUM('GENSET #1:GENSET #5'!D16) -> 30879 | C14: ='Diesel consumption'!D11 -> 8570 | D14: ='SOLAR METER READING'!D15 -> 3200 | E14: ='Gas-2'!G12 -> 0 | F14: =WATER!V12 -> 411
A15: 8 | B15: =SUM('GENSET #1:GENSET #5'!D17) -> 30415 | C15: ='Diesel consumption'!D12 -> 8480 | D15: ='SOLAR METER READING'!D16 -> 3134 | E15: ='Gas-2'!G13 -> 540 | F15: =WATER!V13 -> 423
A16: 9 | B16: =SUM('GENSET #1:GENSET #5'!D18) -> 31010 | C16: ='Diesel consumption'!D13 -> 8620 | D16: ='SOLAR METER READING'!D17 -> 1708 | E16: ='Gas-2'!G14 -> 0 | F16: =WATER!V14 -> 410
A17: 10 | B17: =SUM('GENSET #1:GENSET #5'!D19) -> 28059 | C17: ='Diesel consumption'!D14 -> 8020 | D17: ='SOLAR METER READING'!D18 -> 1299 | E17: ='Gas-2'!G15 -> 360 | F17: =WATER!V15 -> 415
A18: 11 | B18: =SUM('GENSET #1:GENSET #5'!D20) -> 24815 | C18: ='Diesel consumption'!D15 -> 6800 | D18: ='SOLAR METER READING'!D19 -> 2321 | E18: ='Gas-2'!G16 -> 0 | F18: =WATER!V16 -> 396
A19: 12 | B19: =SUM('GENSET #1:GENSET #5'!D21) -> 26393 | C19: ='Diesel consumption'!D16 -> 7410 | D19: ='SOLAR METER READING'!D20 -> 2438 | E19: ='Gas-2'!G17 -> 180 | F19: =WATER!V17 -> 341
... A38: 31 | B38: =SUM('GENSET #1:GENSET #5'!D40) -> 0 | C38: ='Diesel consumption'!D35 -> 0 | D38: ='SOLAR METER READING'!D39 -> 0 | E38: ='Gas-2'!G36 -> 0 | F38: =WATER!V36 -> 0
A39: Total | B39: =SUM(B8:B38) -> -87747538 | C39: =SUM(C8:C38) -> -43343220 | D39: =SUM(D8:D38) -> -2412901 | E39: =SUM(E8:E38) -> 4275 | F39: =SUM(F8:F38) -> -921919

Sheet GENSET #1
C1: 1000 KVA
C3: NO#1
A6: 44256
B8: GENSET NO 1
A9: DAY | B9: YESTARDAY | C9: TODAY | D9: Final Electricity Consumption( KWh)
A10: 1 | B10: ='[1]GENSET #1'!$C$37 -> 17010072 | C10: 17013059 | D10: =C10-B10 -> 2987
A11: 2 | B11: =C10 -> 17013059 | C11: 17016763 | D11: =C11-B11 -> 3704
A12: 3 | B12: =C11 -> 17016763 | C12: 17020624 | D12: =C12-B12 -> 3861
A13: 4 | B13: =C12 -> 17020624 | C13: 17030624 | D13: =C13-B13 -> 10000
A14: 5 | B14: =C13 -> 17030624 | C14: 17034720 | D14: =C14-B14 -> 4096
A15: 6 | B15: =C14 -> 17034720 | C15: 17038544 | D15: =C15-B15 -> 3824
A16: 7 | B16: =C15 -> 17038544 | C16: 17043950 | D16: =C16-B16 -> 5406
A17: 8 | B17: =C16 -> 17043950 | C17: 17055320 | D17: =C17-B17 -> 11370
A18: 9 | B18: =C17 -> 17055320 | C18: 17056960 | D18: =C18-B18 -> 1640
A19: 10 | B19: =C18 -> 17056960 | C19: 17065558 | D19: =C19-B19 -> 8598
A20: 11 | B20: =C19 -> 17065558 | C20: 17076192 | D20: =C20-B20 -> 10634
A21: 12 | B21: =C20 -> 17076192 | C21: 17082256 | D21: =C21-B21 -> 6064
A22: 13 | B22: =C21 -> 17082256 | C22: 17082256 | D22: =C22-B22 -> 0
... A29: 20 | B29: =C28 -> 17082256 | C29: 17082256 | D29: =C29-B29 -> 0
A30: 21 | B30: =C29 -> 17082256 | D30: =C30-B30 -> -17082256
A31: 22 | B31: =C30 -> 0 | D31: =C31-B31 -> 0
A32: 23 | B32: =C31 -> 0 | D32: =C32-B32 -> 0
A33: 24 | B33: =C32 -> 0 | D33: =C33-B33 -> 0
A34: 25 | B34: =C33 -> 0 | D34: =C34-B34 -> 0
A35: 26 | B35: =C34 -> 0 | D35: =C35-B35 -> 0
A36: 27 | B36: =C35 -> 0 | D36: =C36-B36 -> 0
A37: 28 | B37: =C36 -> 0 | D37: =C37-B37 -> 0
A38: 29 | B38: =C37 -> 0 | D38: =C38-B38 -> 0
A39: 30 | B39: =C38 -> 0 | D39: =C39-B39 -> 0 | G39: NEW ENGINE PURCHASED FROM UK
A40: 31 | B40: =C39 -> 0 | D40: =C40-B40 -> 0
A41: Total | B41: =C40 -> 0 | D41: =SUM(D10:D40) -> -17010072 | G41: INSTALLED: NOV 30 2013

Sheet GENSET #2
C1: 1600 KVA
C3: NO#2
A6: 44256
B8: GENSET NO 2
A9: DAY | B9: YESTARDAY | C9: TODAY | D9: Final Electricity Consumption( KW h)
A10: 1 | B10: ='[1]GENSET #2'!$C$37 -> 28925329 | C10: 28939147 | D10: =C10-B10 -> 13818
A11: 2 | B11: =C10 -> 28939147 | C11: 28952046 | D11: =C11-B11 -> 12899
A12: 3 | B12: =C11 -> 28952046 | C12: 28965164 | D12: =C12-B12 -> 13118
A13: 4 | B13: =C12 -> 28965164 | C13: 28972244 | D13: =C13-B13 -> 7080
A14: 5 | B14: =C13 -> 28972244 | C14: 28986058 | D14: =C14-B14 -> 13814
A15: 6 | B15: =C14 -> 28986058 | C15: 28998423 | D15: =C15-B15 -> 12365
A16: 7 | B16: =C15 -> 28998423 | C16: 29010583 | D16: =C16-B16 -> 12160
A17: 8 | B17: =C16 -> 29010583 | C17: 29010705 | D17: =C17-B17 -> 122
A18: 9 | B18: =C17 -> 29010705 | C18: 29027911 | D18: =C18-B18 -> 17206
A19: 10 | B19: =C18 -> 29027911 | C19: 29032134 | D19: =C19-B19 -> 4223
A20: 11 | B20: =C19 -> 29032134 | C20: 29032134 | D20: =C20-B20 -> 0
A21: 12 | B21: =C20 -> 29032134 | C21: 29040006 | D21: =C21-B21 -> 7872
A22: 13 | B22: =C21 -> 29040006 | C22: 29058174 | D22: =C22-B22 -> 18168
... A29: 20 | B29: =C28 -> 29124886 | C29: 29138812 | D29: =C29-B29 -> 13926
A30: 21 | B30: =C29 -> 29138812 | D30: =C30-B30 -> -29138812
A31: 22 | B31: =C30 -> 0 | D31: =C31-B31 -> 0
A32: 23 | B32: =C31 -> 0 | D32: =C32-B32 -> 0
A33: 24 | B33: =C32 -> 0 | D33: =C33-B33 -> 0
A34: 25 | B34: =C33 -> 0 | D34: =C34-B34 -> 0
A35: 26 | B35: =C34 -> 0 | D35: =C35-B35 -> 0
A36: 27 | B36: =C35 -> 0 | D36: =C36-B36 -> 0
A37: 28 | B37: =C36 -> 0 | D37: =C37-B37 -> 0
A38: 29 | B38: =C37 -> 0 | D38: =C38-B38 -> 0
A39: 30 | B39: =C38 -> 0 | D39: =C39-B39 -> 0
A40: 31 | B40: =C39 -> 0 | D40: =C40-B40 -> 0
A41: Total | B41: =C40 -> 0 | D41: =SUM(D10:D40) -> -28925329

Sheet GENSET #3
C1: 900 KVA
C3: NO#3
A6: 44256
B8: GENSET NO 3
A9: DAY | B9: YESTARDAY | C9: TODAY | D9: Final Electricity Consumption( KW h)
A10: 1 | B10: ='[1]GENSET #3'!$C$37 -> 12602173 | C10: 12610675 | D10: =C10-B10 -> 8502
A11: 2 | B11: =C10 -> 12610675 | C11: 12617817 | D11: =C11-B11 -> 7142
A12: 3 | B12: =C11 -> 12617817 | C12: 12618222 | D12: =C12-B12 -> 405
A13: 4 | B13: =C12 -> 12618222 | C13: 12623343 | D13: =C13-B13 -> 5121
A14: 5 | B14: =C13 -> 12623343 | C14: 12630078 | D14: =C14-B14 -> 6735
A15: 6 | B15: =C14 -> 12630078 | C15: 12636997 | D15: =C15-B15 -> 6919
A16: 7 | B16: =C15 -> 12636997 | C16: 12643754 | D16: =C16-B16 -> 6757
A17: 8 | B17: =C16 -> 12643754 | C17: 12650643 | D17: =C17-B17 -> 6889
A18: 9 | B18: =C17 -> 12650643 | C18: 12658898 | D18: =C18-B18 -> 8255
A19: 10 | B19: =C18 -> 12658898 | C19: 12665227 | D19: =C19-B19 -> 6329
A20: 11 | B20: =C19 -> 12665227 | C20: 12672628 | D20: =C20-B20 -> 7401
A21: 12 | B21: =C20 -> 12672628 | C21: 12678583 | D21: =C21-B21 -> 5955
A22: 13 | B22: =C21 -> 12678583 | C22: 12685091 | D22: =C22-B22 -> 6508
... A29: 20 | B29: =C28 -> 12731727 | C29: 12741421 | D29: =C29-B29 -> 9694
A30: 21 | B30: =C29 -> 12741421 | D30: =C30-B30 -> -12741421
A31: 22 | B31: =C30 -> 0 | D31: =C31-B31 -> 0
A32: 23 | B32: =C31 -> 0 | D32: =C32-B32 -> 0
A33: 24 | B33: =C32 -> 0 | D33: =C33-B33 -> 0
A34: 25 | B34: =C33 -> 0 | D34: =C34-B34 -> 0
A35: 26 | B35: =C34 -> 0 | D35: =C35-B35 -> 0
A36: 27 | B36: =C35 -> 0 | D36: =C36-B36 -> 0
A37: 28 | B37: =C36 -> 0 | D37: =C37-B37 -> 0
A38: 29 | B38: =C37 -> 0 | D38: =C38-B38 -> 0
A39: 30 | B39: =C38 -> 0 | D39: =C39-B39 -> 0
A40: 31 | B40: =C39 -> 0 | D40: =C40-B40 -> 0
A41: Total | B41: =C40 -> 0 | D41: =SUM(D10:D40) -> -12602173

Sheet GENSET #4
C1: 500 KVA
C3: NO#4
A6: 44256
B8: GENSET NO 4
A9: DAY | B9: YESTARDAY | C9: TODAY | D9: Final Electricity Consumption( KW h)
A10: 1 | B10: ='[1]GENSET #4'!$C$37 -> 11468630 | C10: 11471648 | D10: =C10-B10 -> 3018
A11: 2 | B11: =C10 -> 11471648 | C11: 11475491 | D11: =C11-B11 -> 3843
A12: 3 | B12: =C11 -> 11475491 | C12: 11478098 | D12: =C12-B12 -> 2607
A13: 4 | B13: =C12 -> 11478098 | C13: 11480206 | D13: =C13-B13 -> 2108
A14: 5 | B14: =C13 -> 11480206 | C14: 11482867 | D14: =C14-B14 -> 2661
A15: 6 | B15: =C14 -> 11482867 | C15: 11486982 | D15: =C15-B15 -> 4115
A16: 7 | B16: =C15 -> 11486982 | C16: 11489429 | D16: =C16-B16 -> 2447
A17: 8 | B17: =C16 -> 11489429 | C17: 11490064 | D17: =C17-B17 -> 635
A18: 9 | B18: =C17 -> 11490064 | C18: 11492970 | D18: =C18-B18 -> 2906
A19: 10 | B19: =C18 -> 11492970 | C19: 11495035 | D19: =C19-B19 -> 2065
A20: 11 | B20: =C19 -> 11495035 | C20: 11497676 | D20: =C20-B20 -> 2641
A21: 12 | B21: =C20 -> 11497676 | C21: 11498118 | D21: =C21-B21 -> 442
A22: 13 | B22: =C21 -> 11498118 | C22: 11500996 | D22: =C22-B22 -> 2878
... A29: 20 | B29: =C28 -> 11518646 | C29: 11520863 | D29: =C29-B29 -> 2217
A30: 21 | B30: =C29 -> 11520863 | D30: =C30-B30 -> -11520863
A31: 22 | B31: =C30 -> 0 | D31: =C31-B31 -> 0
A32: 23 | B32: =C31 -> 0 | D32: =C32-B32 -> 0
A33: 24 | B33: =C32 -> 0 | D33: =C33-B33 -> 0
A34: 25 | B34: =C33 -> 0 | D34: =C34-B34 -> 0
A35: 26 | B35: =C34 -> 0 | D35: =C35-B35 -> 0
A36: 27 | B36: =C35 -> 0 | D36: =C36-B36 -> 0
A37: 28 | B37: =C36 -> 0 | D37: =C37-B37 -> 0
A38: 29 | B38: =C37 -> 0 | D38: =C38-B38 -> 0
A39: 30 | B39: =C38 -> 0 | D39: =C39-B39 -> 0
A40: 31 | B40: =C39 -> 0 | D40: =C40-B40 -> 0
A41: Total | B41: =C40 -> 0 | D41: =SUM(D10:D40) -> -11468630

Sheet GENSET #5
C1: 1000 KVA
C3: NO#5
A6: 44256
B8: GENSET NO 5
A9: DAY | B9: YESTARDAY | C9: TODAY | D9: Final Electricity Consumption( KWh)
A10: 1 | B10: ='[1]GENSET #5'!$C$37 -> 17741334 | C10: 17743471 | D10: =C10-B10 -> 2137
A11: 2 | B11: =C10 -> 17743471 | C11: 17747157 | D11: =C11-B11 -> 3686
A12: 3 | B12: =C11 -> 17747157 | C12: 17757432 | D12: =C12-B12 -> 10275
A13: 4 | B13: =C12 -> 17757432 | C13: 17762218 | D13: =C13-B13 -> 4786
A14: 5 | B14: =C13 -> 17762218 | C14: 17765283 | D14: =C14-B14 -> 3065
A15: 6 | B15: =C14 -> 17765283 | C15: 17769137 | D15: =C15-B15 -> 3854
A16: 7 | B16: =C15 -> 17769137 | C16: 17773246 | D16: =C16-B16 -> 4109
A17: 8 | B17: =C16 -> 17773246 | C17: 17784645 | D17: =C17-B17 -> 11399
A18: 9 | B18: =C17 -> 17784645 | C18: 17785648 | D18: =C18-B18 -> 1003
A19: 10 | B19: =C18 -> 17785648 | C19: 17792492 | D19: =C19-B19 -> 6844
A20: 11 | B20: =C19 -> 17792492 | C20: 17796631 | D20: =C20-B20 -> 4139
A21: 12 | B21: =C20 -> 17796631 | C21: 17802691 | D21: =C21-B21 -> 6060
A22: 13 | B22: =C21 -> 17802691 | C22: 17802691 | D22: =C22-B22 -> 0
... A29: 20 | B29: =C28 -> 17844996 | C29: 17848426 | D29: =C29-B29 -> 3430
A30: 21 | B30: =C29 -> 17848426 | D30: =C30-B30 -> -17848426
A31: 22 | B31: =C30 -> 0 | D31: =C31-B31 -> 0
A32: 23 | B32: =C31 -> 0 | D32: =C32-B32 -> 0
A33: 24 | B33: =C32 -> 0 | D33: =C33-B33 -> 0
A34: 25 | B34: =C33 -> 0 | D34: =C34-B34 -> 0
A35: 26 | B35: =C34 -> 0 | D35: =C35-B35 -> 0
A36: 27 | B36: =C35 -> 0 | D36: =C36-B36 -> 0
A37: 28 | B37: =C36 -> 0 | D37: =C37-B37 -> 0
A38: 29 | B38: =C37 -> 0 | D38: =C38-B38 -> 0
A39: 30 | B39: =C38 -> 0 | D39: =C39-B39 -> 0
A40: 31 | B40: =C39 -> 0 | D40: =C40-B40 -> 0
A41: Total | B41: =C40 -> 0 | D41: =SUM(D10:D40) -> -17741334

Sheet Diesel consumption
A1: Diesel Consumption
A2: 44256
B3: Liters | F3: Boat meter Reading
A4: Date | B4: Yesterday | C4: Today | D4: In 24 hrs | F4: Yesterday | G4: Today | I4: In Barrels | K4: Carbon Emmision
A5: 1 | B5: ='[1]Diesel consumption'!$C$32 -> 43343220 | C5: 43351690 | D5: =C5-B5 -> 8470 | I5: =D5/200 -> 42.35 | K5: =2.68*D5 -> 22699.6 | L5: =K5/1000 -> 22.6996
A6: 2 | B6: =C5 -> 43351690 | C6: 43360340 | D6: =C6-B6 -> 8650 | I6: =D6/200 -> 43.25 | K6: =2.68*D6 -> 23182 | L6: =K6/1000 -> 23.182
A7: 3 | B7: =C6 -> 43360340 | C7: 43368680 | D7: =C7-B7 -> 8340 | I7: =D7/200 -> 41.7 | K7: =2.68*D7 -> 22351.2 | L7: =K7/1000 -> 22.3512
A8: 4 | B8: =C7 -> 43368680 | C8: 43376940 | D8: =C8-B8 -> 8260 | I8: =D8/200 -> 41.3 | K8: =2.68*D8 -> 22136.8 | L8: =K8/1000 -> 22.1368
A9: 5 | B9: =C8 -> 43376940 | C9: 43385490 | D9: =C9-B9 -> 8550 | I9: =D9/200 -> 42.75 | K9: =2.68*D9 -> 22914 | L9: =K9/1000 -> 22.914
A10: 6 | B10: =C9 -> 43385490 | C10: 43394160 | D10: =C10-B10 -> 8670 | I10: =D10/200 -> 43.35 | K10: =2.68*D10 -> 23235.6 | L10: =K10/1000 -> 23.2356
A11: 7 | B11: =C10 -> 43394160 | C11: 43402730 | D11: =C11-B11 -> 8570 | I11: =D11/200 -> 42.85 | K11: =2.68*D11 -> 22967.6 | L11: =K11/1000 -> 22.9676
A12: 8 | B12: =C11 -> 43402730 | C12: 43411210 | D12: =C12-B12 -> 8480 | I12: =D12/200 -> 42.4 | K12: =2.68*D12 -> 22726.4 | L12: =K12/1000 -> 22.7264
A13: 9 | B13: =C12 -> 43411210 | C13: 43419830 | D13: =C13-B13 -> 8620 | I13: =D13/200 -> 43.1 | K13: =2.68*D13 -> 23101.6 | L13: =K13/1000 -> 23.1016
A14: 10 | B14: =C13 -> 43419830 | C14: 43427850 | D14: =C14-B14 -> 8020 | I14: =D14/200 -> 40.1 | K14: =2.68*D14 -> 21493.6 | L14: =K14/1000 -> 21.4936
A15: 11 | B15: =C14 -> 43427850 | C15: 43434650 | D15: =C15-B15 -> 6800 | I15: =D15/200 -> 34 | K15: =2.68*D15 -> 18224 | L15: =K15/1000 -> 18.224
A16: 12 | B16: =C15 -> 43434650 | C16: 43442060 | D16: =C16-B16 -> 7410 | I16: =D16/200 -> 37.05 | K16: =2.68*D16 -> 19858.8 | L16: =K16/1000 -> 19.8588
A17: 13 | B17: =C16 -> 43442060 | C17: 43449830 | D17: =C17-B17 -> 7770 | I17: =D17/200 -> 38.85 | K17: =2.68*D17 -> 20823.6 | L17: =K17/1000 -> 20.8236
... A24: 20 | B24: =C23 -> 43497580 | C24: 43505680 | D24: =C24-B24 -> 8100 | I24: =D24/200 -> 40.5 | K24: =2.68*D24 -> 21708 | L24: =K24/1000 -> 21.708
A25: 21 | B25: =C24 -> 43505680 | D25: =C25-B25 -> -43505680 | I25: =D25/200 -> -217528.4 | K25: =2.68*D25 -> -1.1659522e+08 | L25: =K25/1000 -> -116595.22
A26: 22 | B26: =C25 -> 0 | D26: =C26-B26 -> 0 | I26: =D26/200 -> 0 | K26: =2.68*D26 -> 0 | L26: =K26/1000 -> 0
A27: 23 | B27: =C26 -> 0 | D27: =C27-B27 -> 0 | I27: =D27/200 -> 0 | K27: =2.68*D27 -> 0 | L27: =K27/1000 -> 0
A28: 24 | B28: =C27 -> 0 | D28: =C28-B28 -> 0 | I28: =D28/200 -> 0 | K28: =2.68*D28 -> 0 | L28: =K28/1000 -> 0
A29: 25 | B29: =C28 -> 0 | D29: =C29-B29 -> 0 | I29: =D29/200 -> 0 | K29: =2.68*D29 -> 0 | L29: =K29/1000 -> 0
A30: 26 | B30: =C29 -> 0 | D30: =C30-B30 -> 0 | I30: =D30/200 -> 0 | K30: =2.68*D30 -> 0 | L30: =K30/1000 -> 0
A31: 27 | B31: =C30 -> 0 | D31: =C31-B31 -> 0 | I31: =D31/200 -> 0 | K31: =2.68*D31 -> 0 | L31: =K31/1000 -> 0
A32: 28 | B32: =C31 -> 0 | D32: =C32-B32 -> 0 | I32: =D32/200 -> 0 | K32: =2.68*D32 -> 0 | L32: =K32/1000 -> 0
A33: 29 | B33: =C32 -> 0 | D33: =C33-B33 -> 0 | I33: =D33/200 -> 0 | K33: =2.68*D33 -> 0 | L33: =K33/1000 -> 0
A34: 30 | B34: =C33 -> 0 | D34: =C34-B34 -> 0 | F34: 0 | I34: =D34/200 -> 0 | K34: =2.68*D34 -> 0 | L34: =K34/1000 -> 0
A35: 31 | B35: =C34 -> 0 | D35: =C35-B35 -> 0
D36: =SUM(D5:D34) -> -43343220 | I36: =SUM(I5:I34) -> -216716.1 | K36: =2.68*D36 -> -1.1615983e+08 | L36: =K36/1000 -> -116159.83

Sheet SOLAR METER READING
C3: solar reading
B5: 44256
B7: solar meter reading
A8: DAY | B8: YESTARDAY | C8: TODAY | D8: Final Electricity Consumption( KW h)
A9: 1 | B9: ='[1]SOLAR METER READING'!$C$36 -> 2412901 | C9: 2415975 | D9: =C9-B9 -> 3074
A10: 2 | B10: =C9 -> 2415975 | C10: 2419232 | D10: =C10-B10 -> 3257
A11: 3 | B11: =C10 -> 2419232 | C11: 2422883 | D11: =C11-B11 -> 3651
A12: 4 | B12: =C11 -> 2422883 | C12: 2425573 | D12: =C12-B12 -> 2690
A13: 5 | B13: =C12 -> 2425573 | C13: 2428846 | D13: =C13-B13 -> 3273 | J13: 1 liter diesel | K13: 11.1 kwh
A14: 6 | B14: =C13 -> 2428846 | C14: 2432103 | D14: =C14-B14 -> 3257 | J14: 212.88 diesel | K14: 2363 kwh
A15: 7 | B15: =C14 -> 2432103 | C15: 2435303 | D15: =C15-B15 -> 3200
A16: 8 | B16: =C15 -> 2435303 | C16: 2438437 | D16: =C16-B16 -> 3134
A17: 9 | B17: =C16 -> 2438437 | C17: 2440145 | D17: =C17-B17 -> 1708
A18: 10 | B18: =C17 -> 2440145 | C18: 2441444 | D18: =C18-B18 -> 1299
A19: 11 | B19: =C18 -> 2441444 | C19: 2443765 | D19: =C19-B19 -> 2321
A20: 12 | B20: =C19 -> 2443765 | C20: 2446203 | D20: =C20-B20 -> 2438
A21: 13 | B21: =C20 -> 2446203 | C21: 2449417 | D21: =C21-B21 -> 3214
A22: 14 | B22: =C21 -> 2449417 | C22: 2452411 | D22: =C22-B22 -> 2994
A23: 15 | B23: =C22 -> 2452411 | C23: 2455511 | D23: =C23-B23 -> 3100
A24: 16 | B24: =C23 -> 2455511 | C24: 2458845 | D24: =C24-B24 -> 3334
A25: 17 | B25: =C24 -> 2458845 | C25: 2461883 | D25: =C25-B25 -> 3038
A26: 18 | B26: =C25 -> 2461883 | C26: 2464995 | D26: =C26-B26 -> 3112
... A28: 20 | B28: =C27 -> 2468200 | C28: 2471364 | D28: =C28-B28 -> 3164
A29: 21 | B29: =C28 -> 2471364 | D29: =C29-B29 -> -2471364
A30: 22 | B30: =C29 -> 0 | D30: =C30-B30 -> 0
A31: 23 | B31: =C30 -> 0 | D31: =C31-B31 -> 0
A32: 24 | B32: =C31 -> 0 | D32: =C32-B32 -> 0
A33: 25 | B33: =C32 -> 0 | D33: =C33-B33 -> 0
A34: 26 | B34: =C33 -> 0 | D34: =C34-B34 -> 0
A35: 27 | B35: =C34 -> 0 | D35: =C35-B35 -> 0
A36: 28 | B36: =C35 -> 0 | D36: =C36-B36 -> 0
A37: 29 | B37: =C36 -> 0 | D37: =C37-B37 -> 0
A38: 30 | B38: =C37 -> 0 | D38: =C38-B38 -> 0
A39: 31 | B39: =C38 -> 0 | D39: =C39-B39 -> 0
A40: Total | D40: =SUM(D9:D39) -> -2412901

Sheet FEEDER Consumption 
A1: 44256
A2: POWER HOUSE FEEDER READING
B3: BLU FEEDER PANEL 1 | E3: BLU FEEDER PANEL 2 | H3: POWER HOUSE FEEDER PANEL NO:3 | K3: Main Kitchen -7 | N3: Main Kitchen -10 | Q3: Water treatment Plant | T3: Sewage treatment Plant | W3: Laundry--8SSB | Z3: Laundry-9 | AC3: New staff accomodation (E0) | AF3: Boat Dock feeder - 22 | AI3: Staff block-16(E2-E3) | AL3: Management block-5 | AO3: Staff Block Feeder-3(E4-E5) | AR3: DIESEL TANK JETTY METER | AU3: SNR STAFF BLOCK | AX3: RECEPTION | BA3: DIVE CENTER | BD3: 301-307 | BG3: 308-314 | BJ3: 315-320 | BM3: 401-407 | BP3: 408-414 | BS3: 415-420 | BV3: SPA - 1 | BY3: SPA - 2 | CB3: BLU KITCHEN - 1 | CE3: BLU KITCHEN - 2 | CH3: AL BARAKATH | CK3: STAFF KITCHEN | CN3: MANAGR BLOCK GARDEN
A4: DAY | B4: Yesterday | C4: Today | D4: Consumption | E4: Yesterday | F4: Today | G4: Consumption | H4: Yesterday | I4: Today | J4: Consumption | K4: Yesterday | L4: Today | M4: Consumption | N4: Yesterday | O4: Today | P4: Consumption | Q4: Yesterday | R4: Today | S4: Consumption | T4: Yesterday | U4: Today | V4: Consumption | W4: Yesterday | X4: Today | Y4: Consumption | Z4: Yesterday | AA4: Today | AB4: Consumption | AC4: Yesterday | AD4: Today | AE4: Consumption | AF4: Yesterday | AG4: Today | AH4: Consumption | AI4: Yesterday | AJ4: Today | AK4: Consumption | AL4: Yesterday | AM4: Today | AN4: Consumption | AO4: Yesterday | AP4: Today | AQ4: Consumption | AR4: Yesterday | AS4: Today | AT4: Consumption | AU4: Yesterday | AV4: Today | AW4: Consumption | AX4: Yesterday | AY4: Today | AZ4: Consumption | BA4: Yesterday | BB4: Today | BC4: Consumption | BD4: Yesterday | BE4: Today | BF4: Consumption | BG4: Yesterday | BH4: Today | BI4: Consumption | BJ4: Yesterday | BK4: Today | BL4: Consumption | BM4: Yesterday | BN4: Today | BO4: Consumption | BP4: Yesterday | BQ4: Today | BR4: Consumption | BS4: Yesterday | BT4: Today | BU4: Consumption | BV4: Yesterday | BW4: Today | BX4: Consumption | BY4: Yesterday | BZ4: Today | CA4: Consumption | CB4: Yesterday | CC4: Today | CD4: Consumption | CE4: Yesterday | CF4: Today | CG4: Consumption | CH4: Yesterday | CI4: Today | CJ4: Consumption | CK4: Yesterday | CL4: Today | CM4: Consumption | CN4: Yesterday | CO4: Today | CP4: Consumption
A5: 1 | B5: ='[1]FEEDER Consumption '!$C$36 -> 25299446 | C5: 25303383 | D5: =C5-B5 -> 3937 | E5: ='[1]FEEDER Consumption '!$F$36 -> 22256534 | F5: 22261774 | G5: =F5-E5 -> 5240 | H5: ='[1]FEEDER Consumption '!$I$36 -> 84529864 | I5: 84544183 | J5: =I5-H5 -> 14319 | K5: ='[1]FEEDER Consumption '!$L$36 -> 1842900 | L5: 1844900 | M5: =L5-K5 -> 2000 | N5: ='[1]FEEDER Consumption '!$O$36 -> 2491793 | O5: 2494491 | P5: =O5-N5 -> 2698 | Q5: ='[1]FEEDER Consumption '!$R$36 -> 1509500 | R5: 1511400 | S5: =R5-Q5 -> 1900 | T5: ='[1]FEEDER Consumption '!$U$36 -> 695400 | U5: 696020 | V5: =U5-T5 -> 620 | W5: ='[1]FEEDER Consumption '!$X$36 -> 7199500 | X5: 7205600 | Y5: =X5-W5 -> 6100 | Z5: ='[1]FEEDER Consumption '!$AA$36 -> 1614900 | AA5: 1617400 | AB5: =AA5-Z5 -> 2500 | AC5: ='[1]FEEDER Consumption '!$AD$36 -> 467628 | AD5: 468034 | AE5: =AD5-AC5 -> 406 | AF5: ='[1]FEEDER Consumption '!$AG$36 -> 334120 | AG5: 334540 | AH5: =AG5-AF5 -> 420 | AI5: ='[1]FEEDER Consumption '!$AJ$36 -> 572210 | AJ5: 573070 | AK5: =AJ5-AI5 -> 860 | AL5: ='[1]FEEDER Consumption '!$AM$36 -> 1047400 | AM5: 1048700 | AN5: =AM5-AL5 -> 1300 | AO5: ='[1]FEEDER Consumption '!$AP$36 -> 666850 | AP5: 667720 | AQ5: =AP5-AO5 -> 870 | AR5: ='[1]FEEDER Consumption '!$AS$36 -> 540890 | AS5: 541880 | AT5: =AS5-AR5 -> 990 | AU5: ='[1]FEEDER Consumption '!$AV$36 -> 491370 | AV5: 493180 | AW5: =AV5-AU5 -> 1810 | AX5: ='[1]FEEDER Consumption '!$AY$36 -> 382690 | AY5: 383900 | AZ5: =AY5-AX5 -> 1210 | BA5: ='[1]FEEDER Consumption '!$BB$36 -> 1059100 | BB5: 1063200 | BC5: =BB5-BA5 -> 4100 | BD5: ='[1]FEEDER Consumption '!$BE$36 -> 22670 | BE5: 22771 | BF5: =BE5-BD5 -> 101 | BG5: ='[1]FEEDER Consumption '!$BH$36 -> 18223 | BH5: 18318 | BI5: =BH5-BG5 -> 95 | BJ5: ='[1]FEEDER Consumption '!$BK$36 -> 16778 | BK5: 16859 | BL5: =BK5-BJ5 -> 81 | BM5: ='[1]FEEDER Consumption '!$BN$36 -> 26640 | BN5: 26754 | BO5: =BN5-BM5 -> 114 | BP5: ='[1]FEEDER Consumption '!$BQ$36 -> 19074 | BQ5: 19165 | BR5: =BQ5-BP5 -> 91 | BS5: ='[1]FEEDER Consumption '!$BT$36 -> 19564 | BT5: 19653 | BU5: =BT5-BS5 -> 89 | BV5: ='[1]FEEDER Consumption '!$BW$36 -> 13606 | BW5: 13653 | BX5: =BW5-BV5 -> 47 | BY5: ='[1]FEEDER Consumption '!$BZ$36 -> 35302 | BZ5: 35474 | CA5: =BZ5-BY5 -> 172 | CB5: ='[1]FEEDER Consumption '!$CC$36 -> 27666 | CC5: 27747 | CD5: =CC5-CB5 -> 81 | CE5: ='[1]FEEDER Consumption '!$CF$36 -> 81511 | CF5: 81766 | CG5: =CF5-CE5 -> 255 | CH5: ='[1]FEEDER Consumption '!$CI$36 -> 55072 | CI5: 55417 | CJ5: =CI5-CH5 -> 345 | CK5: ='[1]FEEDER Consumption '!$CL$36 -> 13610 | CL5: 13660 | CM5: =CL5-CK5 -> 50 | CN5: ='[1]FEEDER Consumption '!$CO$36 -> 48296 | CO5: 48430 | CP5: =CO5-CN5 -> 134
A6: 2 | B6: =C5 -> 25303383 | C6: 25307325 | D6: =C6-B6 -> 3942 | E6: =F5 -> 22261774 | F6: 22267391 | G6: =F6-E6 -> 5617 | H6: =I5 -> 84544183 | I6: 84558930 | J6: =I6-H6 -> 14747 | K6: =L5 -> 1844900 | L6: 1846900 | M6: =L6-K6 -> 2000 | N6: =O5 -> 2494491 | O6: 2497325 | P6: =O6-N6 -> 2834 | Q6: =R5 -> 1511400 | R6: 1513300 | S6: =R6-Q6 -> 1900 | T6: =U5 -> 696020 | U6: 696670 | V6: =U6-T6 -> 650 | W6: =X5 -> 7205600 | X6: 7212000 | Y6: =X6-W6 -> 6400 | Z6: =AA5 -> 1617400 | AA6: 1619900 | AB6: =AA6-Z6 -> 2500 | AC6: =AD5 -> 468034 | AD6: 468451 | AE6: =AD6-AC6 -> 417 | AF6: =AG5 -> 334540 | AG6: 334980 | AH6: =AG6-AF6 -> 440 | AI6: =AJ5 -> 573070 | AJ6: 573920 | AK6: =AJ6-AI6 -> 850 | AL6: =AM5 -> 1048700 | AM6: 1050100 | AN6: =AM6-AL6 -> 1400 | AO6: =AP5 -> 667720 | AP6: 668600 | AQ6: =AP6-AO6 -> 880 | AR6: =AS5 -> 541880 | AS6: 544780 | AT6: =AS6-AR6 -> 2900 | AU6: =AV5 -> 493180 | AV6: 495020 | AW6: =AV6-AU6 -> 1840 | AX6: =AY5 -> 383900 | AY6: 385120 | AZ6: =AY6-AX6 -> 1220 | BA6: =BB5 -> 1063200 | BB6: 1067000 | BC6: =BB6-BA6 -> 3800 | BD6: =BE5 -> 22771 | BE6: 22903 | BF6: =BE6-BD6 -> 132 | BG6: =BH5 -> 18318 | BH6: 18441 | BI6: =BH6-BG6 -> 123 | BJ6: =BK5 -> 16859 | BK6: 16948 | BL6: =BK6-BJ6 -> 89 | BM6: =BN5 -> 26754 | BN6: 26885 | BO6: =BN6-BM6 -> 131 | BP6: =BQ5 -> 19165 | BQ6: 19266 | BR6: =BQ6-BP6 -> 101 | BS6: =BT5 -> 19653 | BT6: 19747 | BU6: =BT6-BS6 -> 94 | BV6: =BW5 -> 13653 | BW6: 13709 | BX6: =BW6-BV6 -> 56 | BY6: =BZ5 -> 35474 | BZ6: 35645 | CA6: =BZ6-BY6 -> 171 | CB6: =CC5 -> 27747 | CC6: 27834 | CD6: =CC6-CB6 -> 87 | CE6: =CF5 -> 81766 | CF6: 82063 | CG6: =CF6-CE6 -> 297 | CH6: =CI5 -> 55417 | CI6: 55838 | CJ6: =CI6-CH6 -> 421 | CK6: =CL5 -> 13660 | CL6: 13713 | CM6: =CL6-CK6 -> 53 | CN6: =CO5 -> 48430 | CO6: 48567 | CP6: =CO6-CN6 -> 137
A7: 3 | B7: =C6 -> 25307325 | C7: 25311054 | D7: =C7-B7 -> 3729 | E7: =F6 -> 22267391 | F7: 22272655 | G7: =F7-E7 -> 5264 | H7: =I6 -> 84558930 | I7: 84573189 | J7: =I7-H7 -> 14259 | K7: =L6 -> 1846900 | L7: 1848700 | M7: =L7-K7 -> 1800 | N7: =O6 -> 2497325 | O7: 2500138 | P7: =O7-N7 -> 2813 | Q7: =R6 -> 1513300 | R7: 1515200 | S7: =R7-Q7 -> 1900 | T7: =U6 -> 696670 | U7: 697267 | V7: =U7-T7 -> 597 | W7: =X6 -> 7212000 | X7: 7218400 | Y7: =X7-W7 -> 6400 | Z7: =AA6 -> 1619900 | AA7: 1622000 | AB7: =AA7-Z7 -> 2100 | AC7: =AD6 -> 468451 | AD7: 468833 | AE7: =AD7-AC7 -> 382 | AF7: =AG6 -> 334980 | AG7: 335420 | AH7: =AG7-AF7 -> 440 | AI7: =AJ6 -> 573920 | AJ7: 574780 | AK7: =AJ7-AI7 -> 860 | AL7: =AM6 -> 1050100 | AM7: 1051500 | AN7: =AM7-AL7 -> 1400 | AO7: =AP6 -> 668600 | AP7: 669470 | AQ7: =AP7-AO7 -> 870 | AR7: =AS6 -> 544780 | AS7: 547420 | AT7: =AS7-AR7 -> 2640 | AU7: =AV6 -> 495020 | AV7: 496940 | AW7: =AV7-AU7 -> 1920 | AX7: =AY6 -> 385120 | AY7: 386330 | AZ7: =AY7-AX7 -> 1210 | BA7: =BB6 -> 1067000 | BB7: 1070900 | BC7: =BB7-BA7 -> 3900 | BD7: =BE6 -> 22903 | BE7: 23017 | BF7: =BE7-BD7 -> 114 | BG7: =BH6 -> 18441 | BH7: 18549 | BI7: =BH7-BG7 -> 108 | BJ7: =BK6 -> 16948 | BK7: 17033 | BL7: =BK7-BJ7 -> 85 | BM7: =BN6 -> 26885 | BN7: 26994 | BO7: =BN7-BM7 -> 109 | BP7: =BQ6 -> 19266 | BQ7: 19357 | BR7: =BQ7-BP7 -> 91 | BS7: =BT6 -> 19747 | BT7: 19822 | BU7: =BT7-BS7 -> 75 | BV7: =BW6 -> 13709 | BW7: 13762 | BX7: =BW7-BV7 -> 53 | BY7: =BZ6 -> 35645 | BZ7: 35818 | CA7: =BZ7-BY7 -> 173 | CB7: =CC6 -> 27834 | CC7: 27906 | CD7: =CC7-CB7 -> 72 | CE7: =CF6 -> 82063 | CF7: 82348 | CG7: =CF7-CE7 -> 285 | CH7: =CI6 -> 55838 | CI7: 56240 | CJ7: =CI7-CH7 -> 402 | CK7: =CL6 -> 13713 | CL7: 13768 | CM7: =CL7-CK7 -> 55 | CN7: =CO6 -> 48567 | CO7: 48625 | CP7: =CO7-CN7 -> 58
A8: 4 | B8: =C7 -> 25311054 | C8: 25314699 | D8: =C8-B8 -> 3645 | E8: =F7 -> 22272655 | F8: 22277784 | G8: =F8-E8 -> 5129 | H8: =I7 -> 84573189 | I8: 84587346 | J8: =I8-H8 -> 14157 | K8: =L7 -> 1848700 | L8: 1850700 | M8: =L8-K8 -> 2000 | N8: =O7 -> 2500138 | O8: 2502934 | P8: =O8-N8 -> 2796 | Q8: =R7 -> 1515200 | R8: 1516900 | S8: =R8-Q8 -> 1700 | T8: =U7 -> 697267 | U8: 697894 | V8: =U8-T8 -> 627 | W8: =X7 -> 7218400 | X8: 7224500 | Y8: =X8-W8 -> 6100 | Z8: =AA7 -> 1622000 | AA8: 1623800 | AB8: =AA8-Z8 -> 1800 | AC8: =AD7 -> 468833 | AD8: 469212 | AE8: =AD8-AC8 -> 379 | AF8: =AG7 -> 335420 | AG8: 335830 | AH8: =AG8-AF8 -> 410 | AI8: =AJ7 -> 574780 | AJ8: 575630 | AK8: =AJ8-AI8 -> 850 | AL8: =AM7 -> 1051500 | AM8: 1052800 | AN8: =AM8-AL8 -> 1300 | AO8: =AP7 -> 669470 | AP8: 670350 | AQ8: =AP8-AO8 -> 880 | AR8: =AS7 -> 547420 | AS8: 547420 | AT8: =AS8-AR8 -> 0 | AU8: =AV7 -> 496940 | AV8: 498880 | AW8: =AV8-AU8 -> 1940 | AX8: =AY7 -> 386330 | AY8: 387500 | AZ8: =AY8-AX8 -> 1170 | BA8: =BB7 -> 1070900 | BB8: 1075400 | BC8: =BB8-BA8 -> 4500 | BD8: =BE7 -> 23017 | BE8: 23131 | BF8: =BE8-BD8 -> 114 | BG8: =BH7 -> 18549 | BH8: 18640 | BI8: =BH8-BG8 -> 91 | BJ8: =BK7 -> 17033 | BK8: 17112 | BL8: =BK8-BJ8 -> 79 | BM8: =BN7 -> 26994 | BN8: 27099 | BO8: =BN8-BM8 -> 105 | BP8: =BQ7 -> 19357 | BQ8: 19441 | BR8: =BQ8-BP8 -> 84 | BS8: =BT7 -> 19822 | BT8: 19899 | BU8: =BT8-BS8 -> 77 | BV8: =BW7 -> 13762 | BW8: 13807 | BX8: =BW8-BV8 -> 45 | BY8: =BZ7 -> 35818 | BZ8: 35961 | CA8: =BZ8-BY8 -> 143 | CB8: =CC7 -> 27906 | CC8: 27981 | CD8: =CC8-CB8 -> 75 | CE8: =CF7 -> 82348 | CF8: 82626 | CG8: =CF8-CE8 -> 278 | CH8: =CI7 -> 56240 | CI8: 56612 | CJ8: =CI8-CH8 -> 372 | CK8: =CL7 -> 13768 | CL8: 13813 | CM8: =CL8-CK8 -> 45 | CN8: =CO7 -> 48625 | CO8: 48696 | CP8: =CO8-CN8 -> 71
A9: 5 | B9: =C8 -> 25314699 | C9: 25318471 | D9: =C9-B9 -> 3772 | E9: =F8 -> 22277784 | F9: 22283483 | G9: =F9-E9 -> 5699 | H9: =I8 -> 84587346 | I9: 84601848 | J9: =I9-H9 -> 14502 | K9: =L8 -> 1850700 | L9: 1852600 | M9: =L9-K9 -> 1900 | N9: =O8 -> 2502934 | O9: 2505661 | P9: =O9-N9 -> 2727 | Q9: =R8 -> 1516900 | R9: 1518700 | S9: =R9-Q9 -> 1800 | T9: =U8 -> 697894 | U9: 698550 | V9: =U9-T9 -> 656 | W9: =X8 -> 7224500 | X9: 7230900 | Y9: =X9-W9 -> 6400 | Z9: =AA8 -> 1623800 | AA9: 1625800 | AB9: =AA9-Z9 -> 2000 | AC9: =AD8 -> 469212 | AD9: 469816 | AE9: =AD9-AC9 -> 604 | AF9: =AG8 -> 335830 | AG9: 336220 | AH9: =AG9-AF9 -> 390 | AI9: =AJ8 -> 575630 | AJ9: 576510 | AK9: =AJ9-AI9 -> 880 | AL9: =AM8 -> 1052800 | AM9: 1054200 | AN9: =AM9-AL9 -> 1400 | AO9: =AP8 -> 670350 | AP9: 671260 | AQ9: =AP9-AO9 -> 910 | AR9: =AS8 -> 547420 | AS9: 548010 | AT9: =AS9-AR9 -> 590 | AU9: =AV8 -> 498880 | AV9: 500510 | AW9: =AV9-AU9 -> 1630 | AX9: =AY8 -> 387500 | AY9: 388740 | AZ9: =AY9-AX9 -> 1240 | BA9: =BB8 -> 1075400 | BB9: 1079100 | BC9: =BB9-BA9 -> 3700 | BD9: =BE8 -> 23131 | BE9: 23247 | BF9: =BE9-BD9 -> 116 | BG9: =BH8 -> 18640 | BH9: 18754 | BI9: =BH9-BG9 -> 114 | BJ9: =BK8 -> 17112 | BK9: 17203 | BL9: =BK9-BJ9 -> 91 | BM9: =BN8 -> 27099 | BN9: 27225 | BO9: =BN9-BM9 -> 126 | BP9: =BQ8 -> 19441 | BQ9: 19531 | BR9: =BQ9-BP9 -> 90 | BS9: =BT8 -> 19899 | BT9: 19985 | BU9: =BT9-BS9 -> 86 | BV9: =BW8 -> 13807 | BW9: 13859 | BX9: =BW9-BV9 -> 52 | BY9: =BZ8 -> 35961 | BZ9: 36144 | CA9: =BZ9-BY9 -> 183 | CB9: =CC8 -> 27981 | CC9: 28056 | CD9: =CC9-CB9 -> 75 | CE9: =CF8 -> 82626 | CF9: 82876 | CG9: =CF9-CE9 -> 250 | CH9: =CI8 -> 56612 | CI9: 56944 | CJ9: =CI9-CH9 -> 332 | CK9: =CL8 -> 13813 | CL9: 13863 | CM9: =CL9-CK9 -> 50 | CN9: =CO8 -> 48696 | CO9: 48772 | CP9: =CO9-CN9 -> 76
A10: 6 | B10: =C9 -> 25318471 | C10: 25322179 | D10: =C10-B10 -> 3708 | E10: =F9 -> 22283483 | F10: 22289258 | G10: =F10-E10 -> 5775 | H10: =I9 -> 84601848 | I10: 84616647 | J10: =I10-H10 -> 14799 | K10: =L9 -> 1852600 | L10: 1854600 | M10: =L10-K10 -> 2000 | N10: =O9 -> 2505661 | O10: 2508291 | P10: =O10-N10 -> 2630 | Q10: =R9 -> 1518700 | R10: 1520600 | S10: =R10-Q10 -> 1900 | T10: =U9 -> 698550 | U10: 699208 | V10: =U10-T10 -> 658 | W10: =X9 -> 7230900 | X10: 7237400 | Y10: =X10-W10 -> 6500 | Z10: =AA9 -> 1625800 | AA10: 1628000 | AB10: =AA10-Z10 -> 2200 | AC10: =AD9 -> 469816 | AD10: 470276 | AE10: =AD10-AC10 -> 460 | AF10: =AG9 -> 336220 | AG10: 336600 | AH10: =AG10-AF10 -> 380 | AI10: =AJ9 -> 576510 | AJ10: 577360 | AK10: =AJ10-AI10 -> 850 | AL10: =AM9 -> 1054200 | AM10: 1055600 | AN10: =AM10-AL10 -> 1400 | AO10: =AP9 -> 671260 | AP10: 672180 | AQ10: =AP10-AO10 -> 920 | AR10: =AS9 -> 548010 | AS10: 548010 | AT10: =AS10-AR10 -> 0 | AU10: =AV9 -> 500510 | AV10: 502190 | AW10: =AV10-AU10 -> 1680 | AX10: =AY9 -> 388740 | AY10: 389940 | AZ10: =AY10-AX10 -> 1200 | BA10: =BB9 -> 1079100 | BB10: 1082900 | BC10: =BB10-BA10 -> 3800 | BD10: =BE9 -> 23247 | BE10: 23377 | BF10: =BE10-BD10 -> 130 | BG10: =BH9 -> 18754 | BH10: 18861 | BI10: =BH10-BG10 -> 107 | BJ10: =BK9 -> 17203 | BK10: 17291 | BL10: =BK10-BJ10 -> 88 | BM10: =BN9 -> 27225 | BN10: 27371 | BO10: =BN10-BM10 -> 146 | BP10: =BQ9 -> 19531 | BQ10: 19534 | BR10: =BQ10-BP10 -> 3 | BS10: =BT9 -> 19985 | BT10: 20076 | BU10: =BT10-BS10 -> 91 | BV10: =BW9 -> 13859 | BW10: 13911 | BX10: =BW10-BV10 -> 52 | BY10: =BZ9 -> 36144 | BZ10: 36314 | CA10: =BZ10-BY10 -> 170 | CB10: =CC9 -> 28056 | CC10: 28137 | CD10: =CC10-CB10 -> 81 | CE10: =CF9 -> 82876 | CF10: 83171 | CG10: =CF10-CE10 -> 295 | CH10: =CI9 -> 56944 | CI10: 57304 | CJ10: =CI10-CH10 -> 360 | CK10: =CL9 -> 13863 | CL10: 13913 | CM10: =CL10-CK10 -> 50 | CN10: =CO9 -> 48772 | CO10: 48806 | CP10: =CO10-CN10 -> 34
A11: 7 | B11: =C10 -> 25322179 | C11: 25325953 | D11: =C11-B11 -> 3774 | E11: =F10 -> 22289258 | F11: 22294975 | G11: =F11-E11 -> 5717 | H11: =I10 -> 84616647 | I11: 84631570 | J11: =I11-H11 -> 14923 | K11: =L10 -> 1854600 | L11: 1856600 | M11: =L11-K11 -> 2000 | N11: =O10 -> 2508291 | O11: 2511128 | P11: =O11-N11 -> 2837 | Q11: =R10 -> 1520600 | R11: 1522400 | S11: =R11-Q11 -> 1800 | T11: =U10 -> 699208 | U11: 699883 | V11: =U11-T11 -> 675 | W11: =X10 -> 7237400 | X11: 7244000 | Y11: =X11-W11 -> 6600 | Z11: =AA10 -> 1628000 | AA11: 1630100 | AB11: =AA11-Z11 -> 2100 | AC11: =AD10 -> 470276 | AD11: 470748 | AE11: =AD11-AC11 -> 472 | AF11: =AG10 -> 336600 | AG11: 337010 | AH11: =AG11-AF11 -> 410 | AI11: =AJ10 -> 577360 | AJ11: 578320 | AK11: =AJ11-AI11 -> 960 | AL11: =AM10 -> 1055600 | AM11: 1057200 | AN11: =AM11-AL11 -> 1600 | AO11: =AP10 -> 672180 | AP11: 673130 | AQ11: =AP11-AO11 -> 950 | AR11: =AS10 -> 548010 | AS11: 550060 | AT11: =AS11-AR11 -> 2050 | AU11: =AV10 -> 502190 | AV11: 503980 | AW11: =AV11-AU11 -> 1790 | AX11: =AY10 -> 389940 | AY11: 391130 | AZ11: =AY11-AX11 -> 1190 | BA11: =BB10 -> 1082900 | BB11: 1086400 | BC11: =BB11-BA11 -> 3500 | BD11: =BE10 -> 23377 | BE11: 23513 | BF11: =BE11-BD11 -> 136 | BG11: =BH10 -> 18861 | BH11: 18975 | BI11: =BH11-BG11 -> 114 | BJ11: =BK10 -> 17291 | BK11: 17368 | BL11: =BK11-BJ11 -> 77 | BM11: =BN10 -> 27371 | BN11: 27512 | BO11: =BN11-BM11 -> 141 | BP11: =BQ10 -> 19534 | BQ11: 19741 | BR11: =BQ11-BP11 -> 207 | BS11: =BT10 -> 20076 | BT11: 20160 | BU11: =BT11-BS11 -> 84 | BV11: =BW10 -> 13911 | BW11: 13962 | BX11: =BW11-BV11 -> 51 | BY11: =BZ10 -> 36314 | BZ11: 36506 | CA11: =BZ11-BY11 -> 192 | CB11: =CC10 -> 28137 | CC11: 28218 | CD11: =CC11-CB11 -> 81 | CE11: =CF10 -> 83171 | CF11: 83449 | CG11: =CF11-CE11 -> 278 | CH11: =CI10 -> 57304 | CI11: 57703 | CJ11: =CI11-CH11 -> 399 | CK11: =CL10 -> 13913 | CL11: 13971 | CM11: =CL11-CK11 -> 58 | CN11: =CO10 -> 48806 | CO11: 48847 | CP11: =CO11-CN11 -> 41
A12: 8 | B12: =C11 -> 25325953 | C12: 25329714 | D12: =C12-B12 -> 3761 | E12: =F11 -> 22294975 | F12: 22300671 | G12: =F12-E12 -> 5696 | H12: =I11 -> 84631570 | I12: 84646174 | J12: =I12-H12 -> 14604 | K12: =L11 -> 1856600 | L12: 1858600 | M12: =L12-K12 -> 2000 | N12: =O11 -> 2511128 | O12: 2513905 | P12: =O12-N12 -> 2777 | Q12: =R11 -> 1522400 | R12: 1524100 | S12: =R12-Q12 -> 1700 | T12: =U11 -> 699883 | U12: 700576 | V12: =U12-T12 -> 693 | W12: =X11 -> 7244000 | X12: 7250600 | Y12: =X12-W12 -> 6600 | Z12: =AA11 -> 1630100 | AA12: 1631900 | AB12: =AA12-Z12 -> 1800 | AC12: =AD11 -> 470748 | AD12: 471216 | AE12: =AD12-AC12 -> 468 | AF12: =AG11 -> 337010 | AG12: 337430 | AH12: =AG12-AF12 -> 420 | AI12: =AJ11 -> 578320 | AJ12: 579240 | AK12: =AJ12-AI12 -> 920 | AL12: =AM11 -> 1057200 | AM12: 1058600 | AN12: =AM12-AL12 -> 1400 | AO12: =AP11 -> 673130 | AP12: 674100 | AQ12: =AP12-AO12 -> 970 | AR12: =AS11 -> 550060 | AS12: 551760 | AT12: =AS12-AR12 -> 1700 | AU12: =AV11 -> 503980 | AV12: 505770 | AW12: =AV12-AU12 -> 1790 | AX12: =AY11 -> 391130 | AY12: 392310 | AZ12: =AY12-AX12 -> 1180 | BA12: =BB11 -> 1086400 | BB12: 1090300 | BC12: =BB12-BA12 -> 3900 | BD12: =BE11 -> 23513 | BE12: 23635 | BF12: =BE12-BD12 -> 122 | BG12: =BH11 -> 18975 | BH12: 19096 | BI12: =BH12-BG12 -> 121 | BJ12: =BK11 -> 17368 | BK12: 17448 | BL12: =BK12-BJ12 -> 80 | BM12: =BN11 -> 27512 | BN12: 27631 | BO12: =BN12-BM12 -> 119 | BP12: =BQ11 -> 19741 | BQ12: 19842 | BR12: =BQ12-BP12 -> 101 | BS12: =BT11 -> 20160 | BT12: 20237 | BU12: =BT12-BS12 -> 77 | BV12: =BW11 -> 13962 | BW12: 14016 | BX12: =BW12-BV12 -> 54 | BY12: =BZ11 -> 36506 | BZ12: 36652 | CA12: =BZ12-BY12 -> 146 | CB12: =CC11 -> 28218 | CC12: 28300 | CD12: =CC12-CB12 -> 82 | CE12: =CF11 -> 83449 | CF12: 83704 | CG12: =CF12-CE12 -> 255 | CH12: =CI11 -> 57703 | CI12: 58044 | CJ12: =CI12-CH12 -> 341 | CK12: =CL11 -> 13971 | CL12: 14020 | CM12: =CL12-CK12 -> 49 | CN12: =CO11 -> 48847 | CO12: 48881 | CP12: =CO12-CN12 -> 34
A13: 9 | B13: =C12 -> 25329714 | C13: 25333254 | D13: =C13-B13 -> 3540 | E13: =F12 -> 22300671 | F13: 22306180 | G13: =F13-E13 -> 5509 | H13: =I12 -> 84646174 | I13: 84661487 | J13: =I13-H13 -> 15313 | K13: =L12 -> 1858600 | L13: 1860500 | M13: =L13-K13 -> 1900 | N13: =O12 -> 2513905 | O13: 2516442 | P13: =O13-N13 -> 2537 | Q13: =R12 -> 1524100 | R13: 1525800 | S13: =R13-Q13 -> 1700 | T13: =U12 -> 700576 | U13: 701197 | V13: =U13-T13 -> 621 | W13: =X12 -> 7250600 | X13: 7256800 | Y13: =X13-W13 -> 6200 | Z13: =AA12 -> 1631900 | AA13: 1633900 | AB13: =AA13-Z13 -> 2000 | AC13: =AD12 -> 471216 | AD13: 471703 | AE13: =AD13-AC13 -> 487 | AF13: =AG12 -> 337430 | AG13: 337960 | AH13: =AG13-AF13 -> 530 | AI13: =AJ12 -> 579240 | AJ13: 580320 | AK13: =AJ13-AI13 -> 1080 | AL13: =AM12 -> 1058600 | AM13: 1060300 | AN13: =AM13-AL13 -> 1700 | AO13: =AP12 -> 674100 | AP13: 675230 | AQ13: =AP13-AO13 -> 1130 | AR13: =AS12 -> 551760 | AS13: 552400 | AT13: =AS13-AR13 -> 640 | AU13: =AV12 -> 505770 | AV13: 507830 | AW13: =AV13-AU13 -> 2060 | AX13: =AY12 -> 392310 | AY13: 393470 | AZ13: =AY13-AX13 -> 1160 | BA13: =BB12 -> 1090300 | BB13: 1094400 | BC13: =BB13-BA13 -> 4100 | BD13: =BE12 -> 23635 | BE13: 23773 | BF13: =BE13-BD13 -> 138 | BG13: =BH12 -> 19096 | BH13: 19222 | BI13: =BH13-BG13 -> 126 | BJ13: =BK12 -> 17448 | BK13: 17536 | BL13: =BK13-BJ13 -> 88 | BM13: =BN12 -> 27631 | BN13: 27761 | BO13: =BN13-BM13 -> 130 | BP13: =BQ12 -> 19842 | BQ13: 19929 | BR13: =BQ13-BP13 -> 87 | BS13: =BT12 -> 20237 | BT13: 20311 | BU13: =BT13-BS13 -> 74 | BV13: =BW12 -> 14016 | BW13: 14067 | BX13: =BW13-BV13 -> 51 | BY13: =BZ12 -> 36652 | BZ13: 36783 | CA13: =BZ13-BY13 -> 131 | CB13: =CC12 -> 28300 | CC13: 28383 | CD13: =CC13-CB13 -> 83 | CE13: =CF12 -> 83704 | CF13: 83976 | CG13: =CF13-CE13 -> 272 | CH13: =CI12 -> 58044 | CI13: 58411 | CJ13: =CI13-CH13 -> 367 | CK13: =CL12 -> 14020 | CL13: 14072 | CM13: =CL13-CK13 -> 52 | CN13: =CO12 -> 48881 | CO13: 48929 | CP13: =CO13-CN13 -> 48
A14: 10 | B14: =C13 -> 25333254 | C14: 25336508 | D14: =C14-B14 -> 3254 | E14: =F13 -> 22306180 | F14: 22310345 | G14: =F14-E14 -> 4165 | H14: =I13 -> 84661487 | I14: 84676008 | J14: =I14-H14 -> 14521 | K14: =L13 -> 1860500 | L14: 1862300 | M14: =L14-K14 -> 1800 | N14: =O13 -> 2516442 | O14: 2518907 | P14: =O14-N14 -> 2465 | Q14: =R13 -> 1525800 | R14: 1527700 | S14: =R14-Q14 -> 1900 | T14: =U13 -> 701197 | U14: 701872 | V14: =U14-T14 -> 675 | W14: =X13 -> 7256800 | X14: 7262900 | Y14: =X14-W14 -> 6100 | Z14: =AA13 -> 1633900 | AA14: 1635800 | AB14: =AA14-Z14 -> 1900 | AC14: =AD13 -> 471703 | AD14: 472068 | AE14: =AD14-AC14 -> 365 | AF14: =AG13 -> 337960 | AG14: 338490 | AH14: =AG14-AF14 -> 530 | AI14: =AJ13 -> 580320 | AJ14: 581360 | AK14: =AJ14-AI14 -> 1040 | AL14: =AM13 -> 1060300 | AM14: 1061900 | AN14: =AM14-AL14 -> 1600 | AO14: =AP13 -> 675230 | AP14: 676260 | AQ14: =AP14-AO14 -> 1030 | AR14: =AS13 -> 552400 | AS14: 554210 | AT14: =AS14-AR14 -> 1810 | AU14: =AV13 -> 507830 | AV14: 509600 | AW14: =AV14-AU14 -> 1770 | AX14: =AY13 -> 393470 | AY14: 394570 | AZ14: =AY14-AX14 -> 1100 | BA14: =BB13 -> 1094400 | BB14: 1097700 | BC14: =BB14-BA14 -> 3300 | BD14: =BE13 -> 23773 | BE14: 23871 | BF14: =BE14-BD14 -> 98 | BG14: =BH13 -> 19222 | BH14: 19298 | BI14: =BH14-BG14 -> 76 | BJ14: =BK13 -> 17536 | BK14: 17608 | BL14: =BK14-BJ14 -> 72 | BM14: =BN13 -> 27761 | BN14: 27856 | BO14: =BN14-BM14 -> 95 | BP14: =BQ13 -> 19929 | BQ14: 19995 | BR14: =BQ14-BP14 -> 66 | BS14: =BT13 -> 20311 | BT14: 20361 | BU14: =BT14-BS14 -> 50 | BV14: =BW13 -> 14067 | BW14: 14116 | BX14: =BW14-BV14 -> 49 | BY14: =BZ13 -> 36783 | BZ14: 36978 | CA14: =BZ14-BY14 -> 195 | CB14: =CC13 -> 28383 | CC14: 28462 | CD14: =CC14-CB14 -> 79 | CE14: =CF13 -> 83976 | CF14: 84245 | CG14: =CF14-CE14 -> 269 | CH14: =CI13 -> 58411 | CI14: 58790 | CJ14: =CI14-CH14 -> 379 | CK14: =CL13 -> 14072 | CL14: 14122 | CM14: =CL14-CK14 -> 50 | CN14: =CO13 -> 48929 | CO14: 48973 | CP14: =CO14-CN14 -> 44
A15: 11 | B15: =C14 -> 25336508 | C15: 25339657 | D15: =C15-B15 -> 3149 | E15: =F14 -> 22310345 | F15: 22313991 | G15: =F15-E15 -> 3646 | H15: =I14 -> 84676008 | I15: 84688060 | J15: =I15-H15 -> 12052 | K15: =L14 -> 1862300 | L15: 1864100 | M15: =L15-K15 -> 1800 | N15: =O14 -> 2518907 | O15: 2521408 | P15: =O15-N15 -> 2501 | Q15: =R14 -> 1527700 | R15: 1529100 | S15: =R15-Q15 -> 1400 | T15: =U14 -> 701872 | U15: 702496 | V15: =U15-T15 -> 624 | W15: =X14 -> 7262900 | X15: 7268600 | Y15: =X15-W15 -> 5700 | Z15: =AA14 -> 1635800 | AA15: 1637900 | AB15: =AA15-Z15 -> 2100 | AC15: =AD14 -> 472068 | AD15: 472486 | AE15: =AD15-AC15 -> 418 | AF15: =AG14 -> 338490 | AG15: 338890 | AH15: =AG15-AF15 -> 400 | AI15: =AJ14 -> 581360 | AJ15: 582140 | AK15: =AJ15-AI15 -> 780 | AL15: =AM14 -> 1061900 | AM15: 1063100 | AN15: =AM15-AL15 -> 1200 | AO15: =AP14 -> 676260 | AP15: 677010 | AQ15: =AP15-AO15 -> 750 | AR15: =AS14 -> 554210 | AS15: 554440 | AT15: =AS15-AR15 -> 230 | AU15: =AV14 -> 509600 | AV15: 510990 | AW15: =AV15-AU15 -> 1390 | AX15: =AY14 -> 394570 | AY15: 395650 | AZ15: =AY15-AX15 -> 1080 | BA15: =BB14 -> 1097700 | BB15: 1100900 | BC15: =BB15-BA15 -> 3200 | BD15: =BE14 -> 23871 | BE15: 23953 | BF15: =BE15-BD15 -> 82 | BG15: =BH14 -> 19298 | BH15: 19368 | BI15: =BH15-BG15 -> 70 | BJ15: =BK14 -> 17608 | BK15: 17655 | BL15: =BK15-BJ15 -> 47 | BM15: =BN14 -> 27856 | BN15: 27930 | BO15: =BN15-BM15 -> 74 | BP15: =BQ14 -> 19995 | BQ15: 20052 | BR15: =BQ15-BP15 -> 57 | BS15: =BT14 -> 20361 | BT15: 20411 | BU15: =BT15-BS15 -> 50 | BV15: =BW14 -> 14116 | BW15: 14162 | BX15: =BW15-BV15 -> 46 | BY15: =BZ14 -> 36978 | BZ15: 37198 | CA15: =BZ15-BY15 -> 220 | CB15: =CC14 -> 28462 | CC15: 28539 | CD15: =CC15-CB15 -> 77 | CE15: =CF14 -> 84245 | CF15: 84488 | CG15: =CF15-CE15 -> 243 | CH15: =CI14 -> 58790 | CI15: 59135 | CJ15: =CI15-CH15 -> 345 | CK15: =CL14 -> 14122 | CL15: 14170 | CM15: =CL15-CK15 -> 48 | CN15: =CO14 -> 48973 | CO15: 49068 | CP15: =CO15-CN15 -> 95
A16: 12 | B16: =C15 -> 25339657 | C16: 25342834 | D16: =C16-B16 -> 3177 | E16: =F15 -> 22313991 | F16: 22318162 | G16: =F16-E16 -> 4171 | H16: =I15 -> 84688060 | I16: 84700846 | J16: =I16-H16 -> 12786 | K16: =L15 -> 1864100 | L16: 1865900 | M16: =L16-K16 -> 1800 | N16: =O15 -> 2521408 | O16: 2523930 | P16: =O16-N16 -> 2522 | Q16: =R15 -> 1529100 | R16: 1530600 | S16: =R16-Q16 -> 1500 | T16: =U15 -> 702496 | U16: 703179 | V16: =U16-T16 -> 683 | W16: =X15 -> 7268600 | X16: 7274400 | Y16: =X16-W16 -> 5800 | Z16: =AA15 -> 1637900 | AA16: 1639900 | AB16: =AA16-Z16 -> 2000 | AC16: =AD15 -> 472486 | AD16: 472872 | AE16: =AD16-AC16 -> 386 | AF16: =AG15 -> 338890 | AG16: 339310 | AH16: =AG16-AF16 -> 420 | AI16: =AJ15 -> 582140 | AJ16: 582960 | AK16: =AJ16-AI16 -> 820 | AL16: =AM15 -> 1063100 | AM16: 1064400 | AN16: =AM16-AL16 -> 1300 | AO16: =AP15 -> 677010 | AP16: 677830 | AQ16: =AP16-AO16 -> 820 | AR16: =AS15 -> 554440 | AS16: 554940 | AT16: =AS16-AR16 -> 500 | AU16: =AV15 -> 510990 | AV16: 512310 | AW16: =AV16-AU16 -> 1320 | AX16: =AY15 -> 395650 | AY16: 396760 | AZ16: =AY16-AX16 -> 1110 | BA16: =BB15 -> 1100900 | BB16: 1103800 | BC16: =BB16-BA16 -> 2900 | BD16: =BE15 -> 23953 | BE16: 24049 | BF16: =BE16-BD16 -> 96 | BG16: =BH15 -> 19368 | BH16: 19452 | BI16: =BH16-BG16 -> 84 | BJ16: =BK15 -> 17655 | BK16: 17723 | BL16: =BK16-BJ16 -> 68 | BM16: =BN15 -> 27930 | BN16: 28015 | BO16: =BN16-BM16 -> 85 | BP16: =BQ15 -> 20052 | BQ16: 20120 | BR16: =BQ16-BP16 -> 68 | BS16: =BT15 -> 20411 | BT16: 20464 | BU16: =BT16-BS16 -> 53 | BV16: =BW15 -> 14162 | BW16: 14208 | BX16: =BW16-BV16 -> 46 | BY16: =BZ15 -> 37198 | BZ16: 37374 | CA16: =BZ16-BY16 -> 176 | CB16: =CC15 -> 28539 | CC16: 28614 | CD16: =CC16-CB16 -> 75 | CE16: =CF15 -> 84488 | CF16: 84726 | CG16: =CF16-CE16 -> 238 | CH16: =CI15 -> 59135 | CI16: 59480 | CJ16: =CI16-CH16 -> 345 | CK16: =CL15 -> 14170 | CL16: 14219 | CM16: =CL16-CK16 -> 49 | CN16: =CO15 -> 49068 | CO16: 49142 | CP16: =CO16-CN16 -> 74
A17: 13 | B17: =C16 -> 25342834 | C17: 25346424 | D17: =C17-B17 -> 3590 | E17: =F16 -> 22318162 | F17: 22322973 | G17: =F17-E17 -> 4811 | H17: =I16 -> 84700846 | I17: 84714069 | J17: =I17-H17 -> 13223 | K17: =L16 -> 1865900 | L17: 1867900 | M17: =L17-K17 -> 2000 | N17: =O16 -> 2523930 | O17: 2526638 | P17: =O17-N17 -> 2708 | Q17: =R16 -> 1530600 | R17: 1531900 | S17: =R17-Q17 -> 1300 | T17: =U16 -> 703179 | U17: 703829 | V17: =U17-T17 -> 650 | W17: =X16 -> 7274400 | X17: 7280900 | Y17: =X17-W17 -> 6500 | Z17: =AA16 -> 1639900 | AA17: 1641700 | AB17: =AA17-Z17 -> 1800 | AC17: =AD16 -> 472872 | AD17: 473296 | AE17: =AD17-AC17 -> 424 | AF17: =AG16 -> 339310 | AG17: 339710 | AH17: =AG17-AF17 -> 400 | AI17: =AJ16 -> 582960 | AJ17: 583760 | AK17: =AJ17-AI17 -> 800 | AL17: =AM16 -> 1064400 | AM17: 1065700 | AN17: =AM17-AL17 -> 1300 | AO17: =AP16 -> 677830 | AP17: 678670 | AQ17: =AP17-AO17 -> 840 | AR17: =AS16 -> 554940 | AS17: 555030 | AT17: =AS17-AR17 -> 90 | AU17: =AV16 -> 512310 | AV17: 513860 | AW17: =AV17-AU17 -> 1550 | AX17: =AY16 -> 396760 | AY17: 397920 | AZ17: =AY17-AX17 -> 1160 | BA17: =BB16 -> 1103800 | BB17: 1107300 | BC17: =BB17-BA17 -> 3500 | BD17: =BE16 -> 24049 | BE17: 24163 | BF17: =BE17-BD17 -> 114 | BG17: =BH16 -> 19452 | BH17: 19554 | BI17: =BH17-BG17 -> 102 | BJ17: =BK16 -> 17723 | BK17: 17802 | BL17: =BK17-BJ17 -> 79 | BM17: =BN16 -> 28015 | BN17: 28113 | BO17: =BN17-BM17 -> 98 | BP17: =BQ16 -> 20120 | BQ17: 20193 | BR17: =BQ17-BP17 -> 73 | BS17: =BT16 -> 20464 | BT17: 20529 | BU17: =BT17-BS17 -> 65 | BV17: =BW16 -> 14208 | BW17: 14256 | BX17: =BW17-BV17 -> 48 | BY17: =BZ16 -> 37374 | BZ17: 37513 | CA17: =BZ17-BY17 -> 139 | CB17: =CC16 -> 28614 | CC17: 28695 | CD17: =CC17-CB17 -> 81 | CE17: =CF16 -> 84726 | CF17: 84985 | CG17: =CF17-CE17 -> 259 | CH17: =CI16 -> 59480 | CI17: 59853 | CJ17: =CI17-CH17 -> 373 | CK17: =CL16 -> 14219 | CL17: 14266 | CM17: =CL17-CK17 -> 47 | CN17: =CO16 -> 49142 | CO17: 49224 | CP17: =CO17-CN17 -> 82
