Workbook

Sheet TOTAL
A1: Site Name | B1: Day | C1: Month | D1: Year | E1: Total Electricity Kwh | F1: Electricity Tariff ($/Kwh) | G1: Natual Gas (m3) | H1: Natural Gas $/m3 | I1: Water Utility Supply (m3) m3 | J1: Water Utility Supply (m3) $/m3 | K1: Room Nights
A2: Cairo at Nile Plaza | B2: 1 | C2: 2 | D2: 2021 | E2: =(((Submetering!O2+Submetering!P2)*0.842284+Submetering!Q2+(Submetering!M2+Submetering!N2+Submetering!Y2)*0.7362)+(Submetering!O2+Submetering!P2+Submetering!Q2)*0.1488+(Submetering!M2+Submetering!N2+Submetering!Y2)*0.1167+(Submetering!K2+Submetering!L2-Submetering!Z2-Submetering!AA2-Submetering!AB2-Submetering!AC2-Submetering!Q2)+(Submetering!M2+Submetering!N2+Submetering!Y2)*0.1139) -> 90191.939 | F2: 1.27 | G2: =Gas!C3*0.9147 -> 0 | H2: 3.65 | I2: =Submetering!AE2+Submetering!AD2+Submetering!H2 -> 1416 | J2: 10.03 | K2: =ELECT.!B3 -> 69.35
A3: Cairo at Nile Plaza | B3: =B2+1 -> 2 | C3: 2 | D3: 2021 | E3: =(((Submetering!O3+Submetering!P3)*0.842284+Submetering!Q3+(Submetering!M3+Submetering!N3+Submetering!Y3)*0.7362)+(Submetering!O3+Submetering!P3+Submetering!Q3)*0.1488+(Submetering!M3+Submetering!N3+Submetering!Y3)*0.1167+(Submetering!K3+Submetering!L3-Submetering!Z3-Submetering!AA3-Submetering!AB3-Submetering!AC3-Submetering!Q3)+(Submetering!M3+Submetering!N3+Submetering!Y3)*0.1139) -> 49685.37 | F3: 1.27 | G3: =Gas!C4*0.9147 -> 2126.6775 | H3: 3.65 | I3: =Submetering!AE3+Submetering!AD3+Submetering!H3 -> 296 | J3: 10.03 | K3: =ELECT.!B4 -> 69.35
A4: Cairo at Nile Plaza | B4: =B3+1 -> 3 | C4: 2 | D4: 2021 | E4: 0 | F4: 1.27 | G4: =Gas!C5*0.9147 -> 0 | H4: 3.65 | I4: =Submetering!AE4+Submetering!AD4+Submetering!H4 -> 326 | J4: 10.03 | K4: =ELECT.!B5 -> 80
A5: Cairo at Nile Plaza | B5: =B4+1 -> 4 | C5: 2 | D5: 2021 | E5: =(((Submetering!O5+Submetering!P5)*0.842284+Submetering!Q5+(Submetering!M5+Submetering!N5+Submetering!Y5)*0.7362)+(Submetering!O5+Submetering!P5+Submetering!Q5)*0.1488+(Submetering!M5+Submetering!N5+Submetering!Y5)*0.1167+(Submetering!K5+Submetering!L5-Submetering!Z5-Submetering!AA5-Submetering!AB5-Submetering!AC5-Submetering!Q5)+(Submetering!M5+Submetering!N5+Submetering!Y5)*0.1139) -> 89995.149 | F5: 1.27 | G5: =Gas!C6*0.9147 -> 0 | H5: 3.65 | I5: =Submetering!AE5+Submetering!AD5+Submetering!H5 -> 306 | J5: 10.03 | K5: =ELECT.!B6 -> 62.05
A6: Cairo at Nile Plaza | B6: =B5+1 -> 5 | C6: 2 | D6: 2021 | E6: =(((Submetering!O6+Submetering!P6)*0.842284+Submetering!Q6+(Submetering!M6+Submetering!N6+Submetering!Y6)*0.7362)+(Submetering!O6+Submetering!P6+Submetering!Q6)*0.1488+(Submetering!M6+Submetering!N6+Submetering!Y6)*0.1167+(Submetering!K6+Submetering!L6-Submetering!Z6-Submetering!AA6-Submetering!AB6-Submetering!AC6-Submetering!Q6)+(Submetering!M6+Submetering!N6+Submetering!Y6)*0.1139) -> 76197.077 | F6: 1.27 | G6: =Gas!C7*0.9147 -> 0 | H6: 3.65 | I6: =Submetering!AE6+Submetering!AD6+Submetering!H6 -> 476 | J6: 10.03 | K6: =ELECT.!B7 -> 62.05
A7: Cairo at Nile Plaza | B7: =B6+1 -> 6 | C7: 2 | D7: 2021 | E7: =(((Submetering!O7+Submetering!P7)*0.842284+Submetering!Q7+(Submetering!M7+Submetering!N7+Submetering!Y7)*0.7362)+(Submetering!O7+Submetering!P7+Submetering!Q7)*0.1488+(Submetering!M7+Submetering!N7+Submetering!Y7)*0.1167+(Submetering!K7+Submetering!L7-Submetering!Z7-Submetering!AA7-Submetering!AB7-Submetering!AC7-Submetering!Q7)+(Submetering!M7+Submetering!N7+Submetering!Y7)*0.1139) -> 23073.915 | F7: 1.27 | G7: =Gas!C8*0.9147 -> 0 | H7: 3.65 | I7: =Submetering!AE7+Submetering!AD7+Submetering!H7 -> 296 | J7: 10.03 | K7: =ELECT.!B8 -> 58.4
A8: Cairo at Nile Plaza | B8: =B7+1 -> 7 | C8: 2 | D8: 2021 | E8: =(((Submetering!O8+Submetering!P8)*0.842284+Submetering!Q8+(Submetering!M8+Submetering!N8+Submetering!Y8)*0.7362)+(Submetering!O8+Submetering!P8+Submetering!Q8)*0.1488+(Submetering!M8+Submetering!N8+Submetering!Y8)*0.1167+(Submetering!K8+Submetering!L8-Submetering!Z8-Submetering!AA8-Submetering!AB8-Submetering!AC8-Submetering!Q8)+(Submetering!M8+Submetering!N8+Submetering!Y8)*0.1139) -> 49729.028 | F8: 1.27 | G8: =Gas!C9*0.9147 -> 0 | H8: 3.65 | I8: =Submetering!AE8+Submetering!AD8+Submetering!H8 -> 216 | J8: 10.03 | K8: =ELECT.!B9 -> 58.4
A9: Cairo at Nile Plaza | B9: =B8+1 -> 8 | C9: 2 | D9: 2021 | E9: =(((Submetering!O9+Submetering!P9)*0.842284+Submetering!Q9+(Submetering!M9+Submetering!N9+Submetering!Y9)*0.7362)+(Submetering!O9+Submetering!P9+Submetering!Q9)*0.1488+(Submetering!M9+Submetering!N9+Submetering!Y9)*0.1167+(Submetering!K9+Submetering!L9-Submetering!Z9-Submetering!AA9-Submetering!AB9-Submetering!AC9-Submetering!Q9)+(Submetering!M9+Submetering!N9+Submetering!Y9)*0.1139) -> 41927.049 | F9: 1.27 | G9: =Gas!C10*0.9147 -> 15519.715 | H9: 3.65 | I9: =Submetering!AE9+Submetering!AD9+Submetering!H9 -> 326 | J9: 10.03 | K9: =ELECT.!B10 -> 88
A10: Cairo at Nile Plaza | B10: =B9+1 -> 9 | C10: 2 | D10: 2021 | E10: =(((Submetering!O10+Submetering!P10)*0.842284+Submetering!Q10+(Submetering!M10+Submetering!N10+Submetering!Y10)*0.7362)+(Submetering!O10+Submetering!P10+Submetering!Q10)*0.1488+(Submetering!M10+Submetering!N10+Submetering!Y10)*0.1167+(Submetering!K10+Submetering!L10-Submetering!Z10-Submetering!AA10-Submetering!AB10-Submetering!AC10-Submetering!Q10)+(Submetering!M10+Submetering!N10+Submetering!Y10)*0.1139) -> 58770.885 | F10: 1.27 | G10: =Gas!C11*0.9147 -> 2745.0147 | H10: 3.65 | I10: =Submetering!AE10+Submetering!AD10+Submetering!H10 -> 356 | J10: 10.03 | K10: =ELECT.!B11 -> 73
A11: Cairo at Nile Plaza | B11: =B10+1 -> 10 | C11: 2 | D11: 2021 | E11: =(((Submetering!O11+Submetering!P11)*0.842284+Submetering!Q11+(Submetering!M11+Submetering!N11+Submetering!Y11)*0.7362)+(Submetering!O11+Submetering!P11+Submetering!Q11)*0.1488+(Submetering!M11+Submetering!N11+Submetering!Y11)*0.1167+(Submetering!K11+Submetering!L11-Submetering!Z11-Submetering!AA11-Submetering!AB11-Submetering!AC11-Submetering!Q11)+(Submetering!M11+Submetering!N11+Submetering!Y11)*0.1139) -> 40243.24 | F11: 1.27 | G11: =Gas!C12*0.9147 -> 1884.282 | H11: 3.65 | I11: =Submetering!AE11+Submetering!AD11+Submetering!H11 -> 346 | J11: 10.03 | K11: =ELECT.!B12 -> 73
A12: Cairo at Nile Plaza | B12: =B11+1 -> 11 | C12: 2 | D12: 2021 | E12: =(((Submetering!O12+Submetering!P12)*0.842284+Submetering!Q12+(Submetering!M12+Submetering!N12+Submetering!Y12)*0.7362)+(Submetering!O12+Submetering!P12+Submetering!Q12)*0.1488+(Submetering!M12+Submetering!N12+Submetering!Y12)*0.1167+(Submetering!K12+Submetering!L12-Submetering!Z12-Submetering!AA12-Submetering!AB12-Submetering!AC12-Submetering!Q12)+(Submetering!M12+Submetering!N12+Submetering!Y12)*0.1139) -> 45905.617 | F12: 1.27 | G12: =Gas!C13*0.9147 -> 1721.4654 | H12: 3.65 | I12: =Submetering!AE12+Submetering!AD12+Submetering!H12 -> 326 | J12: 10.03 | K12: =ELECT.!B13 -> 54.75
A13: Cairo at Nile Plaza | B13: =B12+1 -> 12 | C13: 2 | D13: 2021 | E13: =(((Submetering!O13+Submetering!P13)*0.842284+Submetering!Q13+(Submetering!M13+Submetering!N13+Submetering!Y13)*0.7362)+(Submetering!O13+Submetering!P13+Submetering!Q13)*0.1488+(Submetering!M13+Submetering!N13+Submetering!Y13)*0.1167+(Submetering!K13+Submetering!L13-Submetering!Z13-Submetering!AA13-Submetering!AB13-Submetering!AC13-Submetering!Q13)+(Submetering!M13+Submetering!N13+Submetering!Y13)*0.1139) -> 66057.998 | F13: 1.27 | G13: =Gas!C14*0.9147 -> 2198.0241 | H13: 3.65 | I13: =Submetering!AE13+Submetering!AD13+Submetering!H13 -> 446 | J13: 10.03 | K13: =ELECT.!B14 -> 54.75
A14: Cairo at Nile Plaza | B14: =B13+1 -> 13 | C14: 2 | D14: 2021 | E14: =(((Submetering!O14+Submetering!P14)*0.842284+Submetering!Q14+(Submetering!M14+Submetering!N14+Submetering!Y14)*0.7362)+(Submetering!O14+Submetering!P14+Submetering!Q14)*0.1488+(Submetering!M14+Submetering!N14+Submetering!Y14)*0.1167+(Submetering!K14+Submetering!L14-Submetering!Z14-Submetering!AA14-Submetering!AB14-Submetering!AC14-Submetering!Q14)+(Submetering!M14+Submetering!N14+Submetering!Y14)*0.1139) -> 40860.419 | F14: 1.27 | G14: =Gas!C15*0.9147 -> 2122.104 | H14: 3.65 | I14: =Submetering!AE14+Submetering!AD14+Submetering!H14 -> 386 | J14: 10.03 | K14: =ELECT.!B15 -> 54.75
A15: Cairo at Nile Plaza | B15: =B14+1 -> 14 | C15: 2 | D15: 2021 | E15: =(((Submetering!O15+Submetering!P15)*0.842284+Submetering!Q15+(Submetering!M15+Submetering!N15+Submetering!Y15)*0.7362)+(Submetering!O15+Submetering!P15+Submetering!Q15)*0.1488+(Submetering!M15+Submetering!N15+Submetering!Y15)*0.1167+(Submetering!K15+Submetering!L15-Submetering!Z15-Submetering!AA15-Submetering!AB15-Submetering!AC15-Submetering!Q15)+(Submetering!M15+Submetering!N15+Submetering!Y15)*0.1139) -> 45938.445 | F15: 1.27 | G15: =Gas!C16*0.9147 -> 2135.8245 | H15: 3.65 | I15: =Submetering!AE15+Submetering!AD15+Submetering!H15 -> 446 | J15: 10.03 | K15: =ELECT.!B16 -> 78
A16: Cairo at Nile Plaza | B16: =B15+1 -> 15 | C16: 2 | D16: 2021 | E16: =(((Submetering!O16+Submetering!P16)*0.842284+Submetering!Q16+(Submetering!M16+Submetering!N16+Submetering!Y16)*0.7362)+(Submetering!O16+Submetering!P16+Submetering!Q16)*0.1488+(Submetering!M16+Submetering!N16+Submetering!Y16)*0.1167+(Submetering!K16+Submetering!L16-Submetering!Z16-Submetering!AA16-Submetering!AB16-Submetering!AC16-Submetering!Q16)+(Submetering!M16+Submetering!N16+Submetering!Y16)*0.1139) -> 49773.083 | F16: 1.27 | G16: =Gas!C17*0.9147 -> 2233.6974 | H16: 3.65 | I16: =Submetering!AE16+Submetering!AD16+Submetering!H16 -> 296 | J16: 10.03 | K16: =ELECT.!B17 -> 65.7
... A29: Cairo at Nile Plaza | B29: =B28+1 -> 28 | C29: 2 | D29: 2021 | E29: =(((Submetering!O29+Submetering!P29)*0.842284+Submetering!Q29+(Submetering!M29+Submetering!N29+Submetering!Y29)*0.7362)+(Submetering!O29+Submetering!P29+Submetering!Q29)*0.1488+(Submetering!M29+Submetering!N29+Submetering!Y29)*0.1167+(Submetering!K29+Submetering!L29-Submetering!Z29-Submetering!AA29-Submetering!AB29-Submetering!AC29-Submetering!Q29)+(Submetering!M29+Submetering!N29+Submetering!Y29)*0.1139) -> 33203.034 | F29: 1.27 | G29: =Gas!C30*0.9147 -> 2734.0383 | H29: 3.65 | I29: =Submetering!AE29+Submetering!AD29+Submetering!H29 -> 276 | J29: 10.03 | K29: =ELECT.!B30 -> 73

Sheet Submetering
A1: Site Name | B1: Day | C1: Month | D1: Year | E1: Main (m3) | F1: Podium (m3) | G1: Hotel (m3) | H1: Large (m3) | I1: Feeder 1 (KWh) | J1: Feeder 2 (KWh) | K1: T1 (KWh) | L1: T2 (KWh) | M1: T3 (KWh) | N1: T4 (KWh) | O1: T5 (KWh) | P1: T7 (KWh) | Q1: New Chiller (KWh) | R1: Hotel (BTU) | S1: B.S (BTU) | T1: LS (BTU) | U1: Mall (BTU) | V1: AHU#25 (BTU) | W1: AHU#9 (BTU) | X1: Room Nights | Y1: Loss (KWH) | Z1: Mall (KWH) | AA1: Citadel (KWH) | AB1: Rotana (KWH) | AC1: CIB (KWH) | AD1: Plaza suits water consumption (M3) | AE1: Hotel water consumption (M3)
A2: Cairo at Nile Plaza | B2: 1 | C2: 2 | D2: 2021 | E2: =Water!C3 -> 1610 | F2: =Water!E3 -> 445.5 | G2: =Water!G3 -> 337.5 | H2: =Water!I3 -> 8.829 | I2: =ELECT.!F3 -> 14596 | J2: =ELECT.!H3 -> 80974 | K2: =ELECT.!K3 -> 11068 | L2: =ELECT.!M3 -> 11167 | M2: =ELECT.!O3 -> 3144 | N2: =ELECT.!Q3 -> 14328 | O2: =ELECT.!S3 -> 16552 | P2: =ELECT.!W3*2 -> 37550 | Q2: =ELECT.!D3 -> 960 | R2: =BTU!C3 -> 6.627 | S2: =BTU!F3 -> 1.914 | T2: =BTU!I3 -> 9 | U2: =BTU!O3 -> 1.737 | V2: =BTU!L3 -> 2.02 | W2: =BTU!R3 -> 0.03 | X2: =ELECT.!B3 -> 69.35 | Y2: =I2+J2-(K2+L2+M2+N2+O2+P2) -> 1761 | Z2: ='Mall, Citadel, Rotana'!C3+'Mall, Citadel, Rotana'!E3+'Mall, Citadel, Rotana'!G3+'Mall, Citadel, Rotana'!I3 -> 2564 | AA2: ='Mall, Citadel, Rotana'!K3+'Mall, Citadel, Rotana'!M3 -> 1440 | AB2: ='Mall, Citadel, Rotana'!O3 -> 268 | AC2: ='Mall, Citadel, Rotana'!Q3+'Mall, Citadel, Rotana'!S3 -> 128 | AD2: =(E2-H2-194)*0.1318 -> 185.46514 | AE2: =E2-H2-AD2-194 -> 1221.7059
A3: Cairo at Nile Plaza | B3: =B2+1 -> 2 | C3: 2 | D3: 2021 | E3: =Water!C4 -> 490 | F3: =Water!E4 -> 305.1 | G3: =Water!G4 -> 245.7 | H3: =Water!I4 -> 6.075 | I3: =ELECT.!F4 -> 8139 | J3: =ELECT.!H4 -> 44555 | K3: =ELECT.!K4 -> 6347 | L3: =ELECT.!M4 -> 5518 | M3: =ELECT.!O4 -> 2454 | N3: =ELECT.!Q4 -> 7332 | O3: =ELECT.!S4 -> 9352 | P3: =ELECT.!W4*2 -> 20638 | Q3: =ELECT.!D4 -> 320 | R3: =BTU!C4 -> 3.33 | S3: =BTU!F4 -> 0.893 | T3: =BTU!I4 -> 4 | U3: =BTU!O4 -> 0.863 | V3: =BTU!L4 -> 0.041 | W3: =BTU!R4 -> 0 | X3: =ELECT.!B4 -> 69.35 | Y3: =I3+J3-(K3+L3+M3+N3+O3+P3) -> 1053 | Z3: ='Mall, Citadel, Rotana'!C4+'Mall, Citadel, Rotana'!E4+'Mall, Citadel, Rotana'!G4+'Mall, Citadel, Rotana'!I4 -> 1391 | AA3: ='Mall, Citadel, Rotana'!K4+'Mall, Citadel, Rotana'!M4 -> 960 | AB3: ='Mall, Citadel, Rotana'!O4 -> 78 | AC3: ='Mall, Citadel, Rotana'!Q4+'Mall, Citadel, Rotana'!S4 -> 0 | AD3: =(E3-H3-194)*0.1318 -> 38.212115 | AE3: =E3-H3-AD3-194 -> 251.71289
A4: Cairo at Nile Plaza | B4: =B3+1 -> 3 | C4: 2 | D4: 2021 | E4: =Water!C5 -> 520 | F4: =Water!E5 -> 256.5 | G4: =Water!G5 -> 186.3 | H4: =Water!I5 -> 5.022 | I4: =ELECT.!F5 -> 0 | J4: =ELECT.!H5 -> 0 | K4: =ELECT.!K5 -> 0 | L4: =ELECT.!M5 -> 0 | M4: =ELECT.!O5 -> 0 | N4: =ELECT.!Q5 -> 0 | O4: =ELECT.!S5 -> 0 | P4: =ELECT.!W5*2 -> 0 | Q4: =ELECT.!D5 -> 320 | R4: =BTU!C5 -> 0 | S4: =BTU!F5 -> 0 | T4: =BTU!I5 -> 0 | U4: =BTU!O5 -> 0 | V4: =BTU!L5 -> 0 | W4: =BTU!R5 -> 0 | X4: =ELECT.!B5 -> 80 | Y4: =I4+J4-(K4+L4+M4+N4+O4+P4) -> 0 | Z4: ='Mall, Citadel, Rotana'!C5+'Mall, Citadel, Rotana'!E5+'Mall, Citadel, Rotana'!G5+'Mall, Citadel, Rotana'!I5 -> 1653 | AA4: ='Mall, Citadel, Rotana'!K5+'Mall, Citadel, Rotana'!M5 -> 320 | AB4: ='Mall, Citadel, Rotana'!O5 -> 90 | AC4: ='Mall, Citadel, Rotana'!Q5+'Mall, Citadel, Rotana'!S5 -> 101 | AD4: =(E4-H4-194)*0.1318 -> 42.3049 | AE4: =E4-H4-AD4-194 -> 278.6731
A5: Cairo at Nile Plaza | B5: =B4+1 -> 4 | C5: 2 | D5: 2021 | E5: =Water!C6 -> 500 | F5: =Water!E6 -> 383.4 | G5: =Water!G6 -> 189 | H5: =Water!I6 -> 5.4 | I5: =ELECT.!F6 -> 15054 | J5: =ELECT.!H6 -> 77640 | K5: =ELECT.!K6 -> 10727 | L5: =ELECT.!M6 -> 10427 | M5: =ELECT.!O6 -> 4324 | N5: =ELECT.!Q6 -> 12734 | O5: =ELECT.!S6 -> 16354 | P5: =ELECT.!W6*2 -> 36226 | Q5: =ELECT.!D6 -> 480 | R5: =BTU!C6 -> 6.876 | S5: =BTU!F6 -> 2.077 | T5: =BTU!I6 -> 9 | U5: =BTU!O6 -> 1.834 | V5: =BTU!L6 -> 3.359 | W5: =BTU!R6 -> 0 | X5: =ELECT.!B6 -> 62.05 | Y5: =I5+J5-(K5+L5+M5+N5+O5+P5) -> 1902 | Z5: ='Mall, Citadel, Rotana'!C6+'Mall, Citadel, Rotana'!E6+'Mall, Citadel, Rotana'!G6+'Mall, Citadel, Rotana'!I6 -> 1251 | AA5: ='Mall, Citadel, Rotana'!K6+'Mall, Citadel, Rotana'!M6 -> 320 | AB5: ='Mall, Citadel, Rotana'!O6 -> 24 | AC5: ='Mall, Citadel, Rotana'!Q6+'Mall, Citadel, Rotana'!S6 -> 77 | AD5: =(E5-H5-194)*0.1318 -> 39.61908 | AE5: =E5-H5-AD5-194 -> 260.98092
A6: Cairo at Nile Plaza | B6: =B5+1 -> 5 | C6: 2 | D6: 2021 | E6: =Water!C7 -> 670 | F6: =Water!E7 -> 191.7 | G6: =Water!G7 -> 221.4 | H6: =Water!I7 -> 4.59 | I6: =ELECT.!F7 -> 7154 | J6: =ELECT.!H7 -> 71772 | K6: =ELECT.!K7 -> 7830 | L6: =ELECT.!M7 -> 7085 | M6: =ELECT.!O7 -> 3464 | N6: =ELECT.!Q7 -> 10340 | O6: =ELECT.!S7 -> 12968 | P6: =ELECT.!W7*2 -> 29292 | Q6: =ELECT.!D7 -> 0 | R6: =BTU!C7 -> 3.186 | S6: =BTU!F7 -> 0.461 | T6: =BTU!I7 -> 3 | U6: =BTU!O7 -> 0.933 | V6: =BTU!L7 -> 1.41 | W6: =BTU!R7 -> 0 | X6: =ELECT.!B7 -> 62.05 | Y6: =I6+J6-(K6+L6+M6+N6+O6+P6) -> 7947 | Z6: ='Mall, Citadel, Rotana'!C7+'Mall, Citadel, Rotana'!E7+'Mall, Citadel, Rotana'!G7+'Mall, Citadel, Rotana'!I7 -> 1068 | AA6: ='Mall, Citadel, Rotana'!K7+'Mall, Citadel, Rotana'!M7 -> 480 | AB6: ='Mall, Citadel, Rotana'!O7 -> 82 | AC6: ='Mall, Citadel, Rotana'!Q7+'Mall, Citadel, Rotana'!S7 -> 0 | AD6: =(E6-H6-194)*0.1318 -> 62.131838 | AE6: =E6-H6-AD6-194 -> 409.27816
A7: Cairo at Nile Plaza | B7: =B6+1 -> 6 | C7: 2 | D7: 2021 | E7: =Water!C8 -> 490 | F7: =Water!E8 -> 224.1 | G7: =Water!G8 -> 189 | H7: =Water!I8 -> 4.914 | I7: =ELECT.!F8 -> 9045 | J7: =ELECT.!H8 -> 15682 | K7: =ELECT.!K8 -> 3375 | L7: =ELECT.!M8 -> 3958 | M7: =ELECT.!O8 -> 1356 | N7: =ELECT.!Q8 -> 4344 | O7: =ELECT.!S8 -> 5390 | P7: =ELECT.!W8*2 -> 12118 | Q7: =ELECT.!D8 -> 640 | R7: =BTU!C8 -> 3.256 | S7: =BTU!F8 -> 0.561 | T7: =BTU!I8 -> 5 | U7: =BTU!O8 -> 0.989 | V7: =BTU!L8 -> 1.28 | W7: =BTU!R8 -> 0 | X7: =ELECT.!B8 -> 58.4 | Y7: =I7+J7-(K7+L7+M7+N7+O7+P7) -> -5814 | Z7: ='Mall, Citadel, Rotana'!C8+'Mall, Citadel, Rotana'!E8+'Mall, Citadel, Rotana'!G8+'Mall, Citadel, Rotana'!I8 -> 1062 | AA7: ='Mall, Citadel, Rotana'!K8+'Mall, Citadel, Rotana'!M8 -> 320 | AB7: ='Mall, Citadel, Rotana'!O8 -> 214 | AC7: ='Mall, Citadel, Rotana'!Q8+'Mall, Citadel, Rotana'!S8 -> 0 | AD7: =(E7-H7-194)*0.1318 -> 38.365135 | AE7: =E7-H7-AD7-194 -> 252.72087
A8: Cairo at Nile Plaza | B8: =B7+1 -> 7 | C8: 2 | D8: 2021 | E8: =Water!C9 -> 410 | F8: =Water!E9 -> 205.2 | G8: =Water!G9 -> 135 | H8: =Water!I9 -> 4.32 | I8: =ELECT.!F9 -> 8099 | J8: =ELECT.!H9 -> 43934 | K8: =ELECT.!K9 -> 5902 | L8: =ELECT.!M9 -> 5625 | M8: =ELECT.!O9 -> 2318 | N8: =ELECT.!Q9 -> 8445 | O8: =ELECT.!S9 -> 9062 | P8: =ELECT.!W9*2 -> 24302 | Q8: =ELECT.!D9 -> 320 | R8: =BTU!C9 -> 3.419 | S8: =BTU!F9 -> 1.233 | T8: =BTU!I9 -> 4 | U8: =BTU!O9 -> 0.982 | V8: =BTU!L9 -> 1.36 | W8: =BTU!R9 -> 0 | X8: =ELECT.!B9 -> 58.4 | Y8: =I8+J8-(K8+L8+M8+N8+O8+P8) -> -3621 | Z8: ='Mall, Citadel, Rotana'!C9+'Mall, Citadel, Rotana'!E9+'Mall, Citadel, Rotana'!G9+'Mall, Citadel, Rotana'!I9 -> 1054 | AA8: ='Mall, Citadel, Rotana'!K9+'Mall, Citadel, Rotana'!M9 -> 640 | AB8: ='Mall, Citadel, Rotana'!O9 -> 123 | AC8: ='Mall, Citadel, Rotana'!Q9+'Mall, Citadel, Rotana'!S9 -> 0 | AD8: =(E8-H8-194)*0.1318 -> 27.899424 | AE8: =E8-H8-AD8-194 -> 183.78058
A9: Cairo at Nile Plaza | B9: =B8+1 -> 8 | C9: 2 | D9: 2021 | E9: =Water!C10 -> 520 | F9: =Water!E10 -> 261.9 | G9: =Water!G10 -> 170.1 | H9: =Water!I10 -> 4.941 | I9: =ELECT.!F10 -> 6442 | J9: =ELECT.!H10 -> 38105 | K9: =ELECT.!K10 -> 4962 | L9: =ELECT.!M10 -> 4277 | M9: =ELECT.!O10 -> 2024 | N9: =ELECT.!Q10 -> 5912 | O9: =ELECT.!S10 -> 7773 | P9: =ELECT.!W10*2 -> 14038 | Q9: =ELECT.!D10 -> 320 | R9: =BTU!C10 -> 3.863 | S9: =BTU!F10 -> 1.161 | T9: =BTU!I10 -> 4 | U9: =BTU!O10 -> 1.086 | V9: =BTU!L10 -> 0.24 | W9: =BTU!R10 -> 1.3 | X9: =ELECT.!B10 -> 88 | Y9: =I9+J9-(K9+L9+M9+N9+O9+P9) -> 5561 | Z9: ='Mall, Citadel, Rotana'!C10+'Mall, Citadel, Rotana'!E10+'Mall, Citadel, Rotana'!G10+'Mall, Citadel, Rotana'!I10 -> 1168 | AA9: ='Mall, Citadel, Rotana'!K10+'Mall, Citadel, Rotana'!M10 -> 480 | AB9: ='Mall, Citadel, Rotana'!O10 -> 54 | AC9: ='Mall, Citadel, Rotana'!Q10+'Mall, Citadel, Rotana'!S10 -> 323 | AD9: =(E9-H9-194)*0.1318 -> 42.315576 | AE9: =E9-H9-AD9-194 -> 278.74342
A10: Cairo at Nile Plaza | B10: =B9+1 -> 9 | C10: 2 | D10: 2021 | E10: =Water!C11 -> 550 | F10: =Water!E11 -> 278.1 | G10: =Water!G11 -> 186.3 | H10: =Water!I11 -> 4.752 | I10: =ELECT.!F11 -> 9356 | J10: =ELECT.!H11 -> 52416 | K10: =ELECT.!K11 -> 6907 | L10: =ELECT.!M11 -> 6424 | M10: =ELECT.!O11 -> 2754 | N10: =ELECT.!Q11 -> 9271 | O10: =ELECT.!S11 -> 10727 | P10: =ELECT.!W11*2 -> 24420 | Q10: =ELECT.!D11 -> 320 | R10: =BTU!C11 -> 4.616 | S10: =BTU!F11 -> 1.287 | T10: =BTU!I11 -> 5 | U10: =BTU!O11 -> 1.205 | V10: =BTU!L11 -> 1.17 | W10: =BTU!R11 -> 0.53 | X10: =ELECT.!B11 -> 73 | Y10: =I10+J10-(K10+L10+M10+N10+O10+P10) -> 1269 | Z10: ='Mall, Citadel, Rotana'!C11+'Mall, Citadel, Rotana'!E11+'Mall, Citadel, Rotana'!G11+'Mall, Citadel, Rotana'!I11 -> 1338 | AA10: ='Mall, Citadel, Rotana'!K11+'Mall, Citadel, Rotana'!M11 -> 800 | AB10: ='Mall, Citadel, Rotana'!O11 -> 62 | AC10: ='Mall, Citadel, Rotana'!Q11+'Mall, Citadel, Rotana'!S11 -> 94 | AD10: =(E10-H10-194)*0.1318 -> 46.294486 | AE10: =E10-H10-AD10-194 -> 304.95351
A11: Cairo at Nile Plaza | B11: =B10+1 -> 10 | C11: 2 | D11: 2021 | E11: =Water!C12 -> 540 | F11: =Water!E12 -> 410.4 | G11: =Water!G12 -> 216 | H11: =Water!I12 -> 6.102 | I11: =ELECT.!F12 -> 6593 | J11: =ELECT.!H12 -> 35584 | K11: =ELECT.!K12 -> 4660 | L11: =ELECT.!M12 -> 4648 | M11: =ELECT.!O12 -> 1806 | N11: =ELECT.!Q12 -> 6516 | O11: =ELECT.!S12 -> 7165 | P11: =ELECT.!W12*2 -> 16310 | Q11: =ELECT.!D12 -> 480 | R11: =BTU!C12 -> 4.564 | S11: =BTU!F12 -> 1.324 | T11: =BTU!I12 -> 5 | U11: =BTU!O12 -> 1.007 | V11: =BTU!L12 -> 1.38 | W11: =BTU!R12 -> 0.65 | X11: =ELECT.!B12 -> 73 | Y11: =I11+J11-(K11+L11+M11+N11+O11+P11) -> 1072 | Z11: ='Mall, Citadel, Rotana'!C12+'Mall, Citadel, Rotana'!E12+'Mall, Citadel, Rotana'!G12+'Mall, Citadel, Rotana'!I12 -> 709 | AA11: ='Mall, Citadel, Rotana'!K12+'Mall, Citadel, Rotana'!M12 -> 480 | AB11: ='Mall, Citadel, Rotana'!O12 -> 45 | AC11: ='Mall, Citadel, Rotana'!Q12+'Mall, Citadel, Rotana'!S12 -> 250 | AD11: =(E11-H11-194)*0.1318 -> 44.798556 | AE11: =E11-H11-AD11-194 -> 295.09944
A12: Cairo at Nile Plaza | B12: =B11+1 -> 11 | C12: 2 | D12: 2021 | E12: =Water!C13 -> 520 | F12: =Water!E13 -> 283.5 | G12: =Water!G13 -> 137.7 | H12: =Water!I13 -> 4.779 | I12: =ELECT.!F13 -> 7485 | J12: =ELECT.!H13 -> 41788 | K12: =ELECT.!K13 -> 5380 | L12: =ELECT.!M13 -> 5183 | M12: =ELECT.!O13 -> 2154 | N12: =ELECT.!Q13 -> 7245 | O12: =ELECT.!S13 -> 8501 | P12: =ELECT.!W13*2 -> 19714 | Q12: =ELECT.!D13 -> 320 | R12: =BTU!C13 -> 1.363 | S12: =BTU!F13 -> 1.179 | T12: =BTU!I13 -> 5 | U12: =BTU!O13 -> 1.047 | V12: =BTU!L13 -> 1.5 | W12: =BTU!R13 -> 0.73 | X12: =ELECT.!B13 -> 54.75 | Y12: =I12+J12-(K12+L12+M12+N12+O12+P12) -> 1096 | Z12: ='Mall, Citadel, Rotana'!C13+'Mall, Citadel, Rotana'!E13+'Mall, Citadel, Rotana'!G13+'Mall, Citadel, Rotana'!I13 -> 2320 | AA12: ='Mall, Citadel, Rotana'!K13+'Mall, Citadel, Rotana'!M13 -> 320 | AB12: ='Mall, Citadel, Rotana'!O13 -> 39 | AC12: ='Mall, Citadel, Rotana'!Q13+'Mall, Citadel, Rotana'!S13 -> 136 | AD12: =(E12-H12-194)*0.1318 -> 42.336928 | AE12: =E12-H12-AD12-194 -> 278.88407
A13: Cairo at Nile Plaza | B13: =B12+1 -> 12 | C13: 2 | D13: 2021 | E13: =Water!C14 -> 640 | F13: =Water!E14 -> 234.9 | G13: =Water!G14 -> 135 | H13: =Water!I14 -> 3.942 | I13: =ELECT.!F14 -> 10714 | J13: =ELECT.!H14 -> 57739 | K13: =ELECT.!K14 -> 7098 | L13: =ELECT.!M14 -> 7402 | M13: =ELECT.!O14 -> 3090 | N13: =ELECT.!Q14 -> 10301 | O13: =ELECT.!S14 -> 12050 | P13: =ELECT.!W14*2 -> 27096 | Q13: =ELECT.!D14 -> 320 | R13: =BTU!C14 -> 7.323 | S13: =BTU!F14 -> 0.494 | T13: =BTU!I14 -> 5 | U13: =BTU!O14 -> 0.989 | V13: =BTU!L14 -> 1.42 | W13: =BTU!R14 -> 0.82 | X13: =ELECT.!B14 -> 54.75 | Y13: =I13+J13-(K13+L13+M13+N13+O13+P13) -> 1416 | Z13: ='Mall, Citadel, Rotana'!C14+'Mall, Citadel, Rotana'!E14+'Mall, Citadel, Rotana'!G14+'Mall, Citadel, Rotana'!I14 -> 1029 | AA13: ='Mall, Citadel, Rotana'!K14+'Mall, Citadel, Rotana'!M14 -> 480 | AB13: ='Mall, Citadel, Rotana'!O14 -> 67 | AC13: ='Mall, Citadel, Rotana'!Q14+'Mall, Citadel, Rotana'!S14 -> 26 | AD13: =(E13-H13-194)*0.1318 -> 58.263244 | AE13: =E13-H13-AD13-194 -> 383.79476
A14: Cairo at Nile Plaza | B14: =B13+1 -> 13 | C14: 2 | D14: 2021 | E14: =Water!C15 -> 580 | F14: =Water!E15 -> 253.8 | G14: =Water!G15 -> 159.3 | H14: =Water!I15 -> 4.671 | I14: =ELECT.!F15 -> 7020 | J14: =ELECT.!H15 -> 36178 | K14: =ELECT.!K15 -> 4578 | L14: =ELECT.!M15 -> 4927 | M14: =ELECT.!O15 -> 1958 | N14: =ELECT.!Q15 -> 6294 | O14: =ELECT.!S15 -> 7544 | P14: =ELECT.!W15*2 -> 17114 | Q14: =ELECT.!D15 -> 640 | R14: =BTU!C15 -> 4.216 | S14: =BTU!F15 -> 0.535 | T14: =BTU!I15 -> 5 | U14: =BTU!O15 -> 1.062 | V14: =BTU!L15 -> 1.24 | W14: =BTU!R15 -> 0.74 | X14: =ELECT.!B15 -> 54.75 | Y14: =I14+J14-(K14+L14+M14+N14+O14+P14) -> 783 | Z14: ='Mall, Citadel, Rotana'!C15+'Mall, Citadel, Rotana'!E15+'Mall, Citadel, Rotana'!G15+'Mall, Citadel, Rotana'!I15 -> 982 | AA14: ='Mall, Citadel, Rotana'!K15+'Mall, Citadel, Rotana'!M15 -> 480 | AB14: ='Mall, Citadel, Rotana'!O15 -> 375 | AC14: ='Mall, Citadel, Rotana'!Q15+'Mall, Citadel, Rotana'!S15 -> 76 | AD14: =(E14-H14-194)*0.1318 -> 50.259162 | AE14: =E14-H14-AD14-194 -> 331.06984
... A29: Cairo at Nile Plaza | B29: =B28+1 -> 28 | C29: 2 | D29: 2021 | E29: =Water!C30 -> 470 | F29: =Water!E30 -> 256.5 | G29: =Water!G30 -> 148.5 | H29: =Water!I30 -> 3.456 | I29: =ELECT.!F30 -> 8924 | J29: =ELECT.!H30 -> 26259 | K29: =ELECT.!K30 -> 6518 | L29: =ELECT.!M30 -> 6172 | M29: =ELECT.!O30 -> 2586 | N29: =ELECT.!Q30 -> 7891 | O29: =ELECT.!S30 -> 9177 | P29: =ELECT.!W30*2 -> 21872 | Q29: =ELECT.!D30 -> 160 | R29: =BTU!C30 -> 3.798 | S29: =BTU!F30 -> 0.999 | T29: =BTU!I30 -> 5 | U29: =BTU!O30 -> 0.951 | V29: =BTU!L30 -> 0.77 | W29: =BTU!R30 -> 0.23 | X29: =ELECT.!B30 -> 73 | Y29: =I29+J29-(K29+L29+M29+N29+O29+P29) -> -19033 | Z29: ='Mall, Citadel, Rotana'!C30+'Mall, Citadel, Rotana'!E30+'Mall, Citadel, Rotana'!G30+'Mall, Citadel, Rotana'!I30 -> 1217 | AA29: ='Mall, Citadel, Rotana'!K30+'Mall, Citadel, Rotana'!M30 -> 640 | AB29: ='Mall, Citadel, Rotana'!O30 -> 113 | AC29: ='Mall, Citadel, Rotana'!Q30+'Mall, Citadel, Rotana'!S30 -> 41 | AD29: =(E29-H29-194)*0.1318 -> 35.921299 | AE29: =E29-H29-AD29-194 -> 236.6227

Sheet Mall, Citadel, Rotana
A1: Day | B1: R1 | C1: Cons | D1: R2 | E1: Cons | F1: R3 | G1: Cons | H1: R4 | I1: Cons | J1: RO1 | K1: Cons | L1: RO2 | M1: Cons | N1: ROE | O1: Cons | P1: CIB. 1 | Q1: Cons | R1: CIB. E | S1: Cons | T1: Co | U1: Cons
A2: Last | B2: 44752 | C2: 0 | D2: 39227 | E2: 0 | F2: 20014 | G2: 0 | H2: 238893 | I2: 0 | J2: 303517 | K2: 0 | L2: 24568 | M2: 0 | N2: 206458 | O2: 0 | P2: 91688 | Q2: 0 | R2: 55047 | S2: 0 | T2: 3501 | U2: 0
A3: 44228 | B3: 44762 | C3: =(B3-B2)*800/5 -> 1600 | D3: 39233 | E3: =(D3-D2)*800/5 -> 960 | F3: 20023 | G3: =(F3-F2)*100/5 -> 180 | H3: 238717 | I3: =(H3-H2) -> -176 | J3: 303517 | K3: =(J3-J2)*800/5 -> 0 | L3: 24577 | M3: =(L3-L2)*800/5 -> 1440 | N3: 206726 | O3: =N3-N2 -> 268 | P3: 91816 | Q3: =P3-P2 -> 128 | R3: 55047 | S3: 0 | T3: 3504 | U3: =(T3-T2)*800/5 -> 480
A4: 44229 | B4: 44767 | C4: =(B4-B3)*800/5 -> 800 | D4: 39236 | E4: =(D4-D3)*800/5 -> 480 | F4: 20028 | G4: =(F4-F3)*100/5 -> 100 | H4: 238728 | I4: =(H4-H3) -> 11 | J4: 303517 | K4: =(J4-J3)*800/5 -> 0 | L4: 24583 | M4: =(L4-L3)*800/5 -> 960 | N4: 206804 | O4: =N4-N3 -> 78 | P4: 91816 | Q4: =P4-P3 -> 0 | R4: 55047 | S4: =R4-R3 -> 0 | T4: 3506 | U4: =(T4-T3)*800/5 -> 320
A5: 44230 | B5: 44771 | C5: =(B5-B4)*800/5 -> 640 | D5: 39242 | E5: =(D5-D4)*800/5 -> 960 | F5: 20030 | G5: =(F5-F4)*100/5 -> 40 | H5: 238741 | I5: =(H5-H4) -> 13 | J5: 303517 | K5: =(J5-J4)*800/5 -> 0 | L5: 24585 | M5: =(L5-L4)*800/5 -> 320 | N5: 206894 | O5: =N5-N4 -> 90 | P5: 91917 | Q5: =P5-P4 -> 101 | R5: 55047 | S5: =R5-R4 -> 0 | T5: 3508 | U5: =(T5-T4)*800/5 -> 320
A6: 44231 | B6: 44774 | C6: =(B6-B5)*800/5 -> 480 | D6: 39246 | E6: =(D6-D5)*800/5 -> 640 | F6: 20035 | G6: =(F6-F5)*100/5 -> 100 | H6: 238772 | I6: =(H6-H5) -> 31 | J6: 303517 | K6: =(J6-J5)*800/5 -> 0 | L6: 24587 | M6: =(L6-L5)*800/5 -> 320 | N6: 206918 | O6: =N6-N5 -> 24 | P6: 91994 | Q6: =P6-P5 -> 77 | R6: 55047 | S6: =R30-R5 -> 0 | T6: 3509 | U6: =(T6-T5)*800/5 -> 160
A7: 44232 | B7: 44779 | C7: =(B7-B6)*800/5 -> 800 | D7: 39247 | E7: =(D7-D6)*800/5 -> 160 | F7: 20039 | G7: =(F7-F6)*100/5 -> 80 | H7: 238800 | I7: =(H7-H6) -> 28 | J7: 303517 | K7: =(J7-J6)*800/5 -> 0 | L7: 24590 | M7: =(L7-L6)*800/5 -> 480 | N7: 207000 | O7: =N7-N6 -> 82 | P7: 91994 | Q7: =P7-P6 -> 0 | R7: 55047 | S7: =R7-R30 -> 0 | T7: 3510 | U7: =(T7-T6)*800/5 -> 160
A8: 44233 | B8: 44783 | C8: =(B8-B7)*800/5 -> 640 | D8: 39249 | E8: =(D8-D7)*800/5 -> 320 | F8: 20043 | G8: =(F8-F7)*100/5 -> 80 | H8: 238822 | I8: =(H8-H7) -> 22 | J8: 303517 | K8: =(J8-J7)*800/5 -> 0 | L8: 24592 | M8: =(L8-L7)*800/5 -> 320 | N8: 207214 | O8: =N8-N7 -> 214 | P8: 91994 | Q8: =P8-P7 -> 0 | R8: 55047 | S8: =R8-R7 -> 0 | T8: 3510 | U8: =(T8-T7)*800/5 -> 0
A9: 44234 | B9: 44788 | C9: =(B9-B8)*800/5 -> 800 | D9: 39250 | E9: =(D9-D8)*800/5 -> 160 | F9: 20047 | G9: =(F9-F8)*100/5 -> 80 | H9: 238836 | I9: =(H9-H8) -> 14 | J9: 303517 | K9: =(J9-J8)*800/5 -> 0 | L9: 24596 | M9: =(L9-L8)*800/5 -> 640 | N9: 207337 | O9: =N9-N8 -> 123 | P9: 91994 | Q9: =P9-P8 -> 0 | R9: 55047 | S9: =R9-R8 -> 0 | T9: 3511 | U9: =(T9-T8)*800/5 -> 160
A10: 44235 | B10: 44791 | C10: =(B10-B9)*800/5 -> 480 | D10: 39254 | E10: =(D10-D9)*800/5 -> 640 | F10: 20049 | G10: =(F10-F9)*100/5 -> 40 | H10: 238844 | I10: =(H10-H9) -> 8 | J10: 303517 | K10: =(J10-J9)*800/5 -> 0 | L10: 24599 | M10: =(L10-L9)*800/5 -> 480 | N10: 207391 | O10: =N10-N9 -> 54 | P10: 92317 | Q10: =P10-P9 -> 323 | R10: 55047 | S10: =R10-R9 -> 0 | T10: 3513 | U10: =(T10-T9)*800/5 -> 320
A11: 44236 | B11: 44796 | C11: =(B11-B10)*800/5 -> 800 | D11: 39257 | E11: =(D11-D10)*800/5 -> 480 | F11: 20051 | G11: =(F11-F10)*100/5 -> 40 | H11: 238862 | I11: =(H11-H10) -> 18 | J11: 303517 | K11: =(J11-J10)*800/5 -> 0 | L11: 24604 | M11: =(L11-L10)*800/5 -> 800 | N11: 207453 | O11: =N11-N10 -> 62 | P11: 92411 | Q11: =P11-P10 -> 94 | R11: 55047 | S11: =R11-R10 -> 0 | T11: 3515 | U11: =(T11-T10)*800/5 -> 320
A12: 44237 | B12: 44798 | C12: =(B12-B11)*800/5 -> 320 | D12: 39259 | E12: =(D12-D11)*800/5 -> 320 | F12: 20054 | G12: =(F12-F11)*100/5 -> 60 | H12: 238871 | I12: =(H12-H11) -> 9 | J12: 303517 | K12: =(J12-J11)*800/5 -> 0 | L12: 24607 | M12: =(L12-L11)*800/5 -> 480 | N12: 207498 | O12: =N12-N11 -> 45 | P12: 92661 | Q12: =P12-P11 -> 250 | R12: 55047 | S12: =R12-R11 -> 0 | T12: 3517 | U12: =(T12-T11)*800/5 -> 320
A13: 44238 | B13: 44810 | C13: =(B13-B12)*800/5 -> 1920 | D13: 39261 | E13: =(D13-D12)*800/5 -> 320 | F13: 20057 | G13: =(F13-F12)*100/5 -> 60 | H13: 238891 | I13: =(H13-H12) -> 20 | J13: 303517 | K13: =(J13-J12)*800/5 -> 0 | L13: 24609 | M13: =(L13-L12)*800/5 -> 320 | N13: 207537 | O13: =N13-N12 -> 39 | P13: 92797 | Q13: =P13-P12 -> 136 | R13: 55047 | S13: =R13-R12 -> 0 | T13: 3519 | U13: =(T13-T12)*800/5 -> 320
A14: 44239 | B14: 44813 | C14: =(B14-B13)*800/5 -> 480 | D14: 39264 | E14: =(D14-D13)*800/5 -> 480 | F14: 20059 | G14: =(F14-F13)*100/5 -> 40 | H14: 238920 | I14: =(H14-H13) -> 29 | J14: =J13 -> 303517 | K14: =(J14-J13)*800/5 -> 0 | L14: 24612 | M14: =(L14-L13)*800/5 -> 480 | N14: 207604 | O14: =N14-N13 -> 67 | P14: 92823 | Q14: =P14-P13 -> 26 | R14: =R13 -> 55047 | S14: =R14-R13 -> 0 | T14: 3518 | U14: =(T14-T13)*800/5 -> -160
A15: 44240 | B15: 44815 | C15: =(B15-B14)*800/5 -> 320 | D15: 39267 | E15: =(D15-D14)*800/5 -> 480 | F15: 20068 | G15: =(F15-F14)*100/5 -> 180 | H15: 238922 | I15: =(H15-H14) -> 2 | J15: =J14 -> 303517 | K15: =(J15-J14)*800/5 -> 0 | L15: 24615 | M15: =(L15-L14)*800/5 -> 480 | N15: 207979 | O15: =N15-N14 -> 375 | P15: 92899 | Q15: =P15-P14 -> 76 | R15: =R14 -> 55047 | S15: =R15-R14 -> 0 | T15: 3519 | U15: =(T15-T14)*800/5 -> 160
A16: 44241 | B16: 44820 | C16: =(B16-B15)*800/5 -> 800 | D16: 39270 | E16: =(D16-D15)*800/5 -> 480 | F16: 20071 | G16: =(F16-F15)*100/5 -> 60 | H16: 238937 | I16: =(H16-H15) -> 15 | J16: 303517 | K16: =(J16-J15)*800/5 -> 0 | L16: 24619 | M16: =(L16-L15)*800/5 -> 640 | N16: 208094 | O16: =N16-N15 -> 115 | P16: 92899 | Q16: =P16-P15 -> 0 | R16: 55047 | S16: =R16-R15 -> 0 | T16: 3520 | U16: =(T16-T15)*800/5 -> 160
A17: 44242 | B17: 44825 | C17: =(B17-B16)*800/5 -> 800 | D17: 39273 | E17: =(D17-D16)*800/5 -> 480 | F17: 20074 | G17: =(F17-F16)*100/5 -> 60 | H17: 238954 | I17: =(H17-H16) -> 17 | J17: 303517 | K17: =(J17-J16)*800/5 -> 0 | L17: 24623 | M17: =(L17-L16)*800/5 -> 640 | N17: 208219 | O17: =N17-N16 -> 125 | P17: 92899 | Q17: =P17-P16 -> 0 | R17: 55047 | S17: =S16 -> 0 | T17: 3523 | U17: =(T17-T16)*800/5 -> 480
A18: 44243 | B18: 44830 | C18: =(B18-B17)*800/5 -> 800 | D18: 39276 | E18: =(D18-D17)*800/5 -> 480 | F18: 20078 | G18: =(F18-F17)*100/5 -> 80 | H18: 238972 | I18: =(H18-H17) -> 18 | J18: 303517 | K18: =(J18-J17)*800/5 -> 0 | L18: 24626 | M18: =(L18-L17)*800/5 -> 480 | N18: 208334 | O18: =N18-N17 -> 115 | P18: 93561 | Q18: =P18-P17 -> 662 | R18: 55047 | S18: =R18-R17 -> 0 | T18: 3523 | U18: =(T18-T17)*800/5 -> 0
A19: 44244 | B19: 44835 | C19: =(B19-B18)*800/5 -> 800 | D19: 39278 | E19: =(D19-D18)*800/5 -> 320 | F19: 20082 | G19: =(F19-F18)*100/5 -> 80 | H19: 238992 | I19: =(H19-H18) -> 20 | J19: 303517 | K19: =(J19-J18)*800/5 -> 0 | L19: 24630 | M19: =(L19-L18)*800/5 -> 640 | N19: 208455 | O19: =N19-N18 -> 121 | P19: 93612 | Q19: =P19-P18 -> 51 | R19: 55047 | S19: =R19-R18 -> 0 | T19: 3524 | U19: =(T19-T18)*800/5 -> 160
A20: 44245 | B20: 44840 | C20: =(B20-B19)*800/5 -> 800 | D20: 39281 | E20: =(D20-D19)*800/5 -> 480 | F20: 20084 | G20: =(F20-F19)*100/5 -> 40 | H20: 239007 | I20: =(H20-H19) -> 15 | J20: 303517 | K20: 0 | L20: 24633 | M20: =(L20-L19)*800/5 -> 480 | N20: 208582 | O20: =N20-N19 -> 127 | P20: 93789 | Q20: =P20-P19 -> 177 | R20: 55047 | S20: =R20-R19 -> 0 | T20: 3526 | U20: =(T20-T19)*800/5 -> 320
A21: 44246 | B21: 44845 | C21: =(B21-B20)*800/5 -> 800 | D21: 39284 | E21: =(D21-D20)*800/5 -> 480 | F21: 20088 | G21: =(F21-F20)*100/5 -> 80 | H21: 239024 | I21: =(H21-H20) -> 17 | J21: =J20 -> 303517 | K21: =(J21-J20)*800/5 -> 0 | L21: 24636 | M21: =(L21-L20)*800/5 -> 480 | N21: 208651 | O21: =N21-N20 -> 69 | P21: 93861 | Q21: =P21-P20 -> 72 | R21: =R20 -> 55047 | S21: =R21-R20 -> 0 | T21: 3527 | U21: =(T21-T20)*800/5 -> 160
A22: 44247 | B22: 44849 | C22: =(B22-B21)*800/5 -> 640 | D22: 39287 | E22: =(D22-D21)*800/5 -> 480 | F22: 20091 | G22: =(F22-F21)*100/5 -> 60 | H22: 239031 | I22: =(H22-H21) -> 7 | J22: =J21 -> 303517 | K22: =(J22-J21)*800/5 -> 0 | L22: 24639 | M22: =(L22-L21)*800/5 -> 480 | N22: 208695 | O22: =N22-N21 -> 44 | P22: 93954 | Q22: =P22-P21 -> 93 | R22: =R21 -> 55047 | S22: =R22-R21 -> 0 | T22: 3528 | U22: =(T22-T21)*800/5 -> 160
A23: 44248 | B23: 44855 | C23: =(B23-B22)*800/5 -> 960 | D23: 39289 | E23: =(D23-D22)*800/5 -> 320 | F23: 20095 | G23: =(F23-F22)*100/5 -> 80 | H23: 239058 | I23: =(H23-H22) -> 27 | J23: =J22 -> 303517 | K23: =(J23-J22)*800/5 -> 0 | L23: 24642 | M23: =(L23-L22)*800/5 -> 480 | N23: 208857 | O23: =N23-N22 -> 162 | P23: 94044 | Q23: =P23-P22 -> 90 | R23: =R22 -> 55047 | S23: =R23-R22 -> 0 | T23: 3529 | U23: =(T23-T22)*800/5 -> 160
A24: 44249 | B24: 44858 | C24: =(B24-B23)*800/5 -> 480 | D24: 39292 | E24: =(D24-D23)*800/5 -> 480 | F24: 20097 | G24: =(F24-F23)*100/5 -> 40 | H24: 239069 | I24: =(H24-H23) -> 11 | J24: =J23 -> 303517 | K24: =(J24-J23)*800/5 -> 0 | L24: 24646 | M24: =(L24-L23)*800/5 -> 640 | N24: 208909 | O24: =N24-N23 -> 52 | P24: 94193 | Q24: =P24-P23 -> 149 | R24: =R23 -> 55047 | S24: =R24-R23 -> 0 | T24: 3530 | U24: =(T24-T23)*800/5 -> 160
A25: 44250 | B25: 44861 | C25: =(B25-B24)*800/5 -> 480 | D25: 39296 | E25: =(D25-D24)*800/5 -> 640 | F25: 20099 | G25: =(F25-F24)*100/5 -> 40 | H25: 239092 | I25: =(H25-H24) -> 23 | J25: =J24 -> 303517 | K25: =(J25-J24)*800/5 -> 0 | L25: 24651 | M25: =(L25-L24)*800/5 -> 800 | N25: 208951 | O25: =N25-N24 -> 42 | P25: 94275 | Q25: =P25-P24 -> 82 | R25: =R24 -> 55047 | S25: =R25-R24 -> 0 | T25: 3531 | U25: =(T25-T24)*800/5 -> 160
A26: 44251 | B26: 44863 | C26: =(B26-B25)*800/5 -> 320 | D26: 39298 | E26: =(D26-D25)*800/5 -> 320 | F26: 20101 | G26: =(F26-F25)*100/5 -> 40 | H26: 239095 | I26: =(H26-H25) -> 3 | J26: =J25 -> 303517 | K26: =(J26-J25)*800/5 -> 0 | L26: 24657 | M26: =(L26-L25)*800/5 -> 960 | N26: 208978 | O26: =N26-N25 -> 27 | P26: 94404 | Q26: =P26-P25 -> 129 | R26: =R25 -> 55047 | S26: =R26-R25 -> 0 | T26: 3532 | U26: =(T26-T25)*800/5 -> 160
A27: 44252 | B27: 44865 | C27: =(B27-B26)*800/5 -> 320 | D27: 39301 | E27: =(D27-D26)*800/5 -> 480 | F27: 20104 | G27: =(F27-F26)*100/5 -> 60 | H27: 239098 | I27: =(H27-H26) -> 3 | J27: =J26 -> 303517 | K27: =(J27-J26)*800/5 -> 0 | L27: 24659 | M27: =(L27-L26)*800/5 -> 320 | N27: 209007 | O27: =N27-N26 -> 29 | P27: 94578 | Q27: =P27-P26 -> 174 | R27: =R26 -> 55047 | S27: =R27-R26 -> 0 | T27: 3533 | U27: =(T27-T26)*800/5 -> 160
A28: 44253 | B28: 44867 | C28: =(B28-B27)*800/5 -> 320 | D28: 39303 | E28: =(D28-D27)*800/5 -> 320 | F28: 20107 | G28: =(F28-F27)*100/5 -> 60 | H28: 239104 | I28: =(H28-H27) -> 6 | J28: =J27 -> 303517 | K28: =(J28-J27)*800/5 -> 0 | L28: 24663 | M28: =(L28-L27)*800/5 -> 640 | N28: 209028 | O28: =N28-N27 -> 21 | P28: 94683 | Q28: =P28-P27 -> 105 | R28: =R27 -> 55047 | S28: =R28-R27 -> 0 | T28: 3535 | U28: =(T28-T27)*800/5 -> 320
A29: 44254 | B29: 44885 | C29: =(B29-B28)*800/5 -> 2880 | D29: 39306 | E29: =(D29-D28)*800/5 -> 480 | F29: 20116 | G29: =(F29-F28)*100/5 -> 180 | H29: 239166 | I29: =(H29-H28) -> 62 | J29: =J28 -> 303517 | K29: =(J29-J28)*800/5 -> 0 | L29: 24666 | M29: =(L29-L28)*800/5 -> 480 | N29: 209525 | O29: =N29-N28 -> 497 | P29: 94729 | Q29: =P29-P28 -> 46 | R29: =R28 -> 55047 | S29: =R29-R28 -> 0 | T29: 3537 | U29: =(T29-T28)*800/5 -> 320
A30: 44255 | B30: 44890 | C30: =(B30-B29)*800/5 -> 800 | D30: 39308 | E30: =(D30-D29)*800/5 -> 320 | F30: 20120 | G30: =(F30-F29)*100/5 -> 80 | H30: 239183 | I30: =(H30-H29) -> 17 | J30: =J29 -> 303517 | K30: =(J30-J29)*800/5 -> 0 | L30: 24670 | M30: =(L30-L29)*800/5 -> 640 | N30: 209638 | O30: =N30-N29 -> 113 | P30: 94770 | Q30: =P30-P29 -> 41 | R30: =R29 -> 55047 | S30: =R30-R29 -> 0 | T30: 3539 | U30: =(T30-T29)*800/5 -> 320
B31: 44890 | C31: =(B31-B30)*800/5 -> 0 | D31: 39308 | E31: =(D31-D30)*800/5 -> 0 | F31: 20120 | G31: =(F31-F30)*100/5 -> 0 | H31: 239183 | I31: =(H31-H30) -> 0 | J31: =J30 -> 303517 | K31: =(J31-J30)*800/5 -> 0 | L31: 24670 | M31: =(L31-L30)*800/5 -> 0 | N31: 209638 | O31: =N31-N30 -> 0 | P31: 94770 | Q31: =P31-P30 -> 0 | R31: =R30 -> 55047 | S31: =R31-R30 -> 0 | T31: 3539 | U31: =(T31-T30)*800/5 -> 0
B32: 44890 | C32: =(B32-B31)*800/5 -> 0 | D32: 39308 | E32: =(D32-D31)*800/5 -> 0 | F32: 20120 | G32: =(F32-F31)*100/5 -> 0 | H32: 239183 | I32: =(H32-H31) -> 0 | J32: =J31 -> 303517 | K32: =(J32-J31)*800/5 -> 0 | L32: 24670 | M32: =(L32-L31)*800/5 -> 0 | N32: 209638 | O32: =N32-N31 -> 0 | P32: 94770 | Q32: =P32-P31 -> 0 | R32: =R31 -> 55047 | S32: =R32-R31 -> 0 | T32: 3539 | U32: =(T32-T31)*800/5 -> 0
B33: 44890 | D33: 39308 | E33: =(D33-D32)*800/5 -> 0 | F33: 20120 | H33: 239183 | I33: =(H33-H32) -> 0 | J33: =J32 -> 303517 | L33: 24670 | M33: =(L33-L32)*800/5 -> 0 | N33: 209638 | O33: =N33-N32 -> 0 | P33: 94770 | R33: =R32 -> 55047 | T33: 3539
A34: Total | C34: =SUM(C3:C33) -> 22080 | E34: =SUM(E3:E33) -> 12960 | G34: =SUM(G3:G33) -> 2120 | I34: =SUM(I3:I33) -> 290 | K34: =SUM(K3:K33) -> 0 | M34: =SUM(M3:M33) -> 16320 | O34: =SUM(O3:O33) -> 3180 | Q34: =SUM(Q3:Q33) -> 3082 | S34: =SUM(S3:S33) -> 0 | U34: =SUM(U3:U33) -> 6080

Sheet Water
A1: Day | B1: Main Reading | C1: Cons. | D1: Podium | E1: Cons. | F1: Hotel | G1: Cons. | H1: Large | I1: Cons. | J1: Total | K1: cost.LE
A2: Last | B2: 404038 | C2: 0 | D2: 3128500 | E2: 0 | F2: 2097500 | G2: 0 | H2: 716673 | I2: 0 | J2: 0 | K2: 0
A3: 44228 | B3: 404199 | C3: =(IF((B3-B2)<0,"0",(B3-B2)))*10 -> 1610 | D3: 3145000 | E3: =(IF((D3-D2)<0,"0",(D3-D2)))*0.027 -> 445.5 | F3: 2110000 | G3: =(IF((F3-F2)<0,"0",(F3-F2)))*0.027 -> 337.5 | H3: 717000 | I3: =(IF((H3-H2)<0,"0",(H3-H2)))*0.027 -> 8.829 | J3: =C3+E3+G3+I3 -> 2401.829 | K3: =J3*5.86 -> 14074.718
A4: 44229 | B4: 404248 | C4: =(IF((B4-B3)<0,"0",(B4-B3)))*10 -> 490 | D4: 3156300 | E4: =(IF((D4-D3)<0,"0",(D4-D3)))*0.027 -> 305.1 | F4: 2119100 | G4: =(IF((F4-F3)<0,"0",(F4-F3)))*0.027 -> 245.7 | H4: 717225 | I4: =(IF((H4-H3)<0,"0",(H4-H3)))*0.027 -> 6.075 | J4: =C4+E4+G4+I4 -> 1046.875 | K4: =J4*5.86 -> 6134.6875
A5: 44230 | B5: 404300 | C5: =(IF((B5-B4)<0,"0",(B5-B4)))*10 -> 520 | D5: 3165800 | E5: =(IF((D5-D4)<0,"0",(D5-D4)))*0.027 -> 256.5 | F5: 2126000 | G5: =(IF((F5-F4)<0,"0",(F5-F4)))*0.027 -> 186.3 | H5: 717411 | I5: =(IF((H5-H4)<0,"0",(H5-H4)))*0.027 -> 5.022 | J5: =C5+E5+G5+I5 -> 967.822 | K5: =J5*5.86 -> 5671.4369
A6: 44231 | B6: 404350 | C6: =(IF((B6-B5)<0,"0",(B6-B5)))*10 -> 500 | D6: 3180000 | E6: =(IF((D6-D5)<0,"0",(D6-D5)))*0.027 -> 383.4 | F6: 2133000 | G6: =(IF((F6-F5)<0,"0",(F6-F5)))*0.027 -> 189 | H6: 717611 | I6: =(IF((H6-H5)<0,"0",(H6-H5)))*0.027 -> 5.4 | J6: =C6+E6+G6+I6 -> 1077.8 | K6: =J6*5.86 -> 6315.908
A7: 44232 | B7: 404417 | C7: =(IF((B7-B6)<0,"0",(B7-B6)))*10 -> 670 | D7: 3187100 | E7: =(IF((D7-D6)<0,"0",(D7-D6)))*0.027 -> 191.7 | F7: 2141200 | G7: =(IF((F7-F6)<0,"0",(F7-F6)))*0.027 -> 221.4 | H7: 717781 | I7: =(IF((H7-H6)<0,"0",(H7-H6)))*0.027 -> 4.59 | J7: =C7+E7+G7+I7 -> 1087.69 | K7: =J7*5.86 -> 6373.8634
A8: 44233 | B8: 404466 | C8: =(IF((B8-B7)<0,"0",(B8-B7)))*10 -> 490 | D8: 3195400 | E8: =(IF((D8-D7)<0,"0",(D8-D7)))*0.027 -> 224.1 | F8: 2148200 | G8: =(IF((F8-F7)<0,"0",(F8-F7)))*0.027 -> 189 | H8: 717963 | I8: =(IF((H8-H7)<0,"0",(H8-H7)))*0.027 -> 4.914 | J8: =C8+E8+G8+I8 -> 908.014 | K8: =J8*5.86 -> 5320.962
A9: 44234 | B9: 404507 | C9: =(IF((B9-B8)<0,"0",(B9-B8)))*10 -> 410 | D9: 3203000 | E9: =(IF((D9-D8)<0,"0",(D9-D8)))*0.027 -> 205.2 | F9: 2153200 | G9: =(IF((F9-F8)<0,"0",(F9-F8)))*0.027 -> 135 | H9: 718123 | I9: =(IF((H9-H8)<0,"0",(H9-H8)))*0.027 -> 4.32 | J9: =C9+E9+G9+I9 -> 754.52 | K9: =J9*5.86 -> 4421.4872
A10: 44235 | B10: 404559 | C10: =(IF((B10-B9)<0,"0",(B10-B9)))*10 -> 520 | D10: 3212700 | E10: =(IF((D10-D9)<0,"0",(D10-D9)))*0.027 -> 261.9 | F10: 2159500 | G10: =(IF((F10-F9)<0,"0",(F10-F9)))*0.027 -> 170.1 | H10: 718306 | I10: =(IF((H10-H9)<0,"0",(H10-H9)))*0.027 -> 4.941 | J10: =C10+E10+G10+I10 -> 956.941 | K10: =J10*5.86 -> 5607.6743
A11: 44236 | B11: 404614 | C11: =(IF((B11-B10)<0,"0",(B11-B10)))*10 -> 550 | D11: 3223000 | E11: =(IF((D11-D10)<0,"0",(D11-D10)))*0.027 -> 278.1 | F11: 2166400 | G11: =(IF((F11-F10)<0,"0",(F11-F10)))*0.027 -> 186.3 | H11: 718482 | I11: =(IF((H11-H10)<0,"0",(H11-H10)))*0.027 -> 4.752 | J11: =C11+E11+G11+I11 -> 1019.152 | K11: =J11*5.86 -> 5972.2307
A12: 44237 | B12: 404668 | C12: =(IF((B12-B11)<0,"0",(B12-B11)))*10 -> 540 | D12: 3238200 | E12: =(IF((D12-D11)<0,"0",(D12-D11)))*0.027 -> 410.4 | F12: 2174400 | G12: =(IF((F12-F11)<0,"0",(F12-F11)))*0.027 -> 216 | H12: 718708 | I12: =(IF((H12-H11)<0,"0",(H12-H11)))*0.027 -> 6.102 | J12: =C12+E12+G12+I12 -> 1172.502 | K12: =J12*5.86 -> 6870.8617
A13: 44238 | B13: 404720 | C13: =(IF((B13-B12)<0,"0",(B13-B12)))*10 -> 520 | D13: 3248700 | E13: =(IF((D13-D12)<0,"0",(D13-D12)))*0.027 -> 283.5 | F13: 2179500 | G13: =(IF((F13-F12)<0,"0",(F13-F12)))*0.027 -> 137.7 | H13: 718885 | I13: =(IF((H13-H12)<0,"0",(H13-H12)))*0.027 -> 4.779 | J13: =C13+E13+G13+I13 -> 945.979 | K13: =J13*5.86 -> 5543.4369
A14: 44239 | B14: 404784 | C14: =(IF((B14-B13)<0,"0",(B14-B13)))*10 -> 640 | D14: 3257400 | E14: =(IF((D14-D13)<0,"0",(D14-D13)))*0.027 -> 234.9 | F14: 2184500 | G14: =(IF((F14-F13)<0,"0",(F14-F13)))*0.027 -> 135 | H14: 719031 | I14: =(IF((H14-H13)<0,"0",(H14-H13)))*0.027 -> 3.942 | J14: =C14+E14+G14+I14 -> 1013.842 | K14: =J14*5.86 -> 5941.1141
... A17: 44242 | B17: 404955 | C17: =(IF((B17-B16)<0,"0",(B17-B16)))*10 -> 490 | D17: 3289000 | E17: =(IF((D17-D16)<0,"0",(D17-D16)))*0.027 -> 251.1 | F17: 2206800 | G17: =(IF((F17-F16)<0,"0",(F17-F16)))*0.027 -> 172.8 | H17: 719608 | I17: =(IF((H17-H16)<0,"0",(H17-H16)))*0.027 -> 4.617 | J17: =C17+E17+G17+I17 -> 918.517 | K17: =J17*5.86 -> 5382.5096
A18: 44243 | B18: 405005 | C18: =(IF((B18-B17)<0,"0",(B18-B17)))*10 -> 500 | D18: 3299000 | E18: =(IF((D18-D17)<0,"0",(D18-D17)))*0.027 -> 270 | F18: 2212200 | G18: =(IF((F18-F17)<0,"0",(F18-F17)))*0.027 -> 145.8 | H18: 719792 | I18: =(IF((H18-H17)<0,"0",(H18-H17)))*0.027 -> 4.968 | J18: =C18+E18+G18+I18 -> 920.768 | K18: =J18*5.86 -> 5395.7005 | Q18: `
A19: 44244 | B19: 405055 | C19: =(IF((B19-B18)<0,"0",(B19-B18)))*10 -> 500 | D19: 3310700 | E19: =(IF((D19-D18)<0,"0",(D19-D18)))*0.027 -> 315.9 | F19: 2217100 | G19: =(IF((F19-F18)<0,"0",(F19-F18)))*0.027 -> 132.3 | H19: 719978 | I19: =(IF((H19-H18)<0,"0",(H19-H18)))*0.027 -> 5.022 | J19: =C19+E19+G19+I19 -> 953.222 | K19: =J19*5.86 -> 5585.8809
A20: 44245 | B20: 405100 | C20: =(IF((B20-B19)<0,"0",(B20-B19)))*10 -> 450 | D20: 3320700 | E20: =(IF((D20-D19)<0,"0",(D20-D19)))*0.027 -> 270 | F20: 2221100 | G20: =(IF((F20-F19)<0,"0",(F20-F19)))*0.027 -> 108 | H20: 720128 | I20: =(IF((H20-H19)<0,"0",(H20-H19)))*0.027 -> 4.05 | J20: =C20+E20+G20+I20 -> 832.05 | K20: =J20*5.86 -> 4875.813
A21: 44246 | B21: 405158 | C21: =(IF((B21-B20)<0,"0",(B21-B20)))*10 -> 580 | D21: 3332000 | E21: =(IF((D21-D20)<0,"0",(D21-D20)))*0.027 -> 305.1 | F21: 2225500 | G21: =(IF((F21-F20)<0,"0",(F21-F20)))*0.027 -> 118.8 | H21: 720257 | I21: =(IF((H21-H20)<0,"0",(H21-H20)))*0.027 -> 3.483 | J21: =C21+E21+G21+I21 -> 1007.383 | K21: =J21*5.86 -> 5903.2644
A22: 44247 | B22: 405210 | C22: =(IF((B22-B21)<0,"0",(B22-B21)))*10 -> 520 | D22: 3342300 | E22: =(IF((D22-D21)<0,"0",(D22-D21)))*0.027 -> 278.1 | F22: 2232000 | G22: =(IF((F22-F21)<0,"0",(F22-F21)))*0.027 -> 175.5 | H22: 720394 | I22: =(IF((H22-H21)<0,"0",(H22-H21)))*0.027 -> 3.699 | J22: =C22+E22+G22+I22 -> 977.299 | K22: =J22*5.86 -> 5726.9721
A23: 44248 | B23: 405260 | C23: =(IF((B23-B22)<0,"0",(B23-B22)))*10 -> 500 | D23: 3352000 | E23: =(IF((D23-D22)<0,"0",(D23-D22)))*0.027 -> 261.9 | F23: 2237400 | G23: =(IF((F23-F22)<0,"0",(F23-F22)))*0.027 -> 145.8 | H23: 720563 | I23: =(IF((H23-H22)<0,"0",(H23-H22)))*0.027 -> 4.563 | J23: =C23+E23+G23+I23 -> 912.263 | K23: =J23*5.86 -> 5345.8612
A24: 44249 | B24: 405305 | C24: =(IF((B24-B23)<0,"0",(B24-B23)))*10 -> 450 | D24: 3360800 | E24: =(IF((D24-D23)<0,"0",(D24-D23)))*0.027 -> 237.6 | F24: 2241800 | G24: =(IF((F24-F23)<0,"0",(F24-F23)))*0.027 -> 118.8 | H24: 720726 | I24: =(IF((H24-H23)<0,"0",(H24-H23)))*0.027 -> 4.401 | J24: =C24+E24+G24+I24 -> 810.801 | K24: =J24*5.86 -> 4751.2939
A25: 44250 | B25: 405350 | C25: =(IF((B25-B24)<0,"0",(B25-B24)))*10 -> 450 | D25: 3372800 | E25: =(IF((D25-D24)<0,"0",(D25-D24)))*0.027 -> 324 | F25: 2247000 | G25: =(IF((F25-F24)<0,"0",(F25-F24)))*0.027 -> 140.4 | H25: 720890 | I25: =(IF((H25-H24)<0,"0",(H25-H24)))*0.027 -> 4.428 | J25: =C25+E25+G25+I25 -> 918.828 | K25: =J25*5.86 -> 5384.3321
A26: 44251 | B26: 405400 | C26: =(IF((B26-B25)<0,"0",(B26-B25)))*10 -> 500 | D26: 3383000 | E26: =(IF((D26-D25)<0,"0",(D26-D25)))*0.027 -> 275.4 | F26: 2253400 | G26: =(IF((F26-F25)<0,"0",(F26-F25)))*0.027 -> 172.8 | H26: 721070 | I26: =(IF((H26-H25)<0,"0",(H26-H25)))*0.027 -> 4.86 | J26: =C26+E26+G26+I26 -> 953.06 | K26: =J26*5.86 -> 5584.9316
A27: 44252 | B27: 405451 | C27: =(IF((B27-B26)<0,"0",(B27-B26)))*10 -> 510 | D27: 3391000 | E27: =(IF((D27-D26)<0,"0",(D27-D26)))*0.027 -> 216 | F27: 2259900 | G27: =(IF((F27-F26)<0,"0",(F27-F26)))*0.027 -> 175.5 | H27: 721198 | I27: =(IF((H27-H26)<0,"0",(H27-H26)))*0.027 -> 3.456 | J27: =C27+E27+G27+I27 -> 904.956 | K27: =J27*5.86 -> 5303.0422
A28: 44253 | B28: 405524 | C28: =(IF((B28-B27)<0,"0",(B28-B27)))*10 -> 730 | D28: 3404000 | E28: =(IF((D28-D27)<0,"0",(D28-D27)))*0.027 -> 351 | F28: 2266700 | G28: =(IF((F28-F27)<0,"0",(F28-F27)))*0.027 -> 183.6 | H28: 721382 | I28: =(IF((H28-H27)<0,"0",(H28-H27)))*0.027 -> 4.968 | J28: =C28+E28+G28+I28 -> 1269.568 | K28: =J28*5.86 -> 7439.6685
A29: 44254 | B29: 405567 | C29: =(IF((B29-B28)<0,"0",(B29-B28)))*10 -> 430 | D29: 3412500 | E29: =(IF((D29-D28)<0,"0",(D29-D28)))*0.027 -> 229.5 | F29: 2272000 | G29: =(IF((F29-F28)<0,"0",(F29-F28)))*0.027 -> 143.1 | H29: 721490 | I29: =(IF((H29-H28)<0,"0",(H29-H28)))*0.027 -> 2.916 | J29: =C29+E29+G29+I29 -> 805.516 | K29: =J29*5.86 -> 4720.3238
A30: 44255 | B30: 405614 | C30: =(IF((B30-B29)<0,"0",(B30-B29)))*10 -> 470 | D30: 3422000 | E30: =(IF((D30-D29)<0,"0",(D30-D29)))*0.027 -> 256.5 | F30: 2277500 | G30: =(IF((F30-F29)<0,"0",(F30-F29)))*0.027 -> 148.5 | H30: 721618 | I30: =(IF((H30-H29)<0,"0",(H30-H29)))*0.027 -> 3.456 | J30: =C30+E30+G30+I30 -> 878.456 | K30: =J30*5.86 -> 5147.7522
A31: Total | C31: =SUM(C3:C30) -> 15760 | E31: =SUM(E3:E30) -> 7924.5 | G31: =SUM(G3:G30) -> 4860 | I31: =SUM(I3:I30) -> 133.515 | J31: =SUM(J3:J30) -> 28678.015 | K31: =SUM(K3:K30) -> 168053.17

Sheet ELECT.
A1: Day | B1: Rooms Sold | C1: New Chillers | D1: Cons | E1: F-1 | F1: Cons. | G1: F-2 | H1: Cons. | I1: Total | J1: T-1 | K1: Cons. | L1: T-2 | M1: Cons. | N1: T-3 | O1: Cons. | P1: T-4 | Q1: Cons. | R1: T-5 | S1: Cons. | T1: T-6 | U1: Cons. | V1: T-7 | W1: Cons. | X1: Total | Y1: Diff | Z1: Daily Money Value | AA1: MTD Total Money
A2: Last | C2: 17929 | D2: 0 | E2: 24958787 | F2: 0 | G2: 77289999 | H2: 0 | I2: 0 | J2: 7430512 | K2: 0 | L2: 7442711 | M2: 0 | N2: 4942119 | O2: 0 | P2: 2437148 | Q2: 0 | R2: 16464700 | S2: 0 | V2: 3978655 | W2: 0 | X2: 0 | Y2: 0 | Z2: 0 | AA2: 17124.033
A3: 44228 | B3: 69.35 | C3: 17935 | D3: =IF((C3-C2)<0,"0",(C3-C2))*160 -> 960 | E3: 24973383 | F3: =IF((E3-E2)<0,"0",(E3-E2)) -> 14596 | G3: 77370973 | H3: =IF((G3-G2)<0,"0",(G3-G2)) -> 80974 | I3: =F3+H3 -> 95570 | J3: 7441580 | K3: =IF((J3-J2)<0,"0",(J3-J2)) -> 11068 | L3: 7453878 | M3: =IF((L3-L2)<0,"0",(L3-L2)) -> 11167 | N3: 4943691 | O3: =(IF((N3-N2)<0,"0",(N3-N2)))*2 -> 3144 | P3: 2451476 | Q3: =IF((P3-P2)<0,"0",(P3-P2)) -> 14328 | R3: 16481252 | S3: =IF((R3-R2)<0,"0",(R3-R2)) -> 16552 | T3: 0 | V3: 3997430 | W3: =IF((V3-V2)<0,"0",(V3-V2)) -> 18775 | X3: =K3+M3+O3+Q3+S3+U3+W3 -> 75034 | Y3: =I3-X3 -> 20536 | Z3: =(0.93352*(W3+S3)+0.5568*(Q3+O3))*0.26 -> 11103.786 | AA3: =SUM(Z1:Z3) -> 11103.786
A4: 44229 | B4: 69.35 | C4: 17937 | D4: =IF((C4-C3)<0,"0",(C4-C3))*160 -> 320 | E4: 24981522 | F4: =IF((E4-E3)<0,"0",(E4-E3)) -> 8139 | G4: 77415528 | H4: =IF((G4-G3)<0,"0",(G4-G3)) -> 44555 | I4: =F4+H4 -> 52694 | J4: 7447927 | K4: =IF((J4-J3)<0,"0",(J4-J3)) -> 6347 | L4: 7459396 | M4: =IF((L4-L3)<0,"0",(L4-L3)) -> 5518 | N4: 4944918 | O4: =(IF((N4-N3)<P96,"0",(N4-N3)))*2 -> 2454 | P4: 2458808 | Q4: =IF((P4-P3)<0,"0",(P4-P3)) -> 7332 | R4: 16490604 | S4: =IF((R4-R3)<0,"0",(R4-R3)) -> 9352 | T4: 0 | V4: 4007749 | W4: =IF((V4-V3)<0,"0",(V4-V3)) -> 10319 | X4: =K4+M4+O4+Q4+S4+U4+W4 -> 41322 | Y4: =I4-X4 -> 11372 | Z4: =(0.93352*(W4+S4)+0.5568*(Q4+O4))*0.26 -> 6191.1503 | AA4: =SUM(Z2:Z4) -> 17294.937
A5: 44230 | B5: 80 | C5: 17939 | D5: =IF((C5-C4)<0,"0",(C5-C4))*160 -> 320 | E5: 24981522 | F5: =IF((E5-E4)<0,"0",(E5-E4)) -> 0 | G5: 77415528 | H5: =IF((G5-G4)<0,"0",(G5-G4)) -> 0 | I5: =F5+H5 -> 0 | J5: 7447927 | K5: =IF((J5-J4)<0,"0",(J5-J4)) -> 0 | L5: 7459396 | M5: =IF((L5-L4)<0,"0",(L5-L4)) -> 0 | N5: 4944918 | O5: =(IF((N5-N4)<0,"0",(N5-N4)))*2 -> 0 | P5: 2458808 | Q5: =IF((P5-P4)<0,"0",(P5-P4)) -> 0 | R5: 16490604 | S5: =IF((R5-R4)<0,"0",(R5-R4)) -> 0 | T5: 0 | V5: 4007749 | W5: =IF((V5-V4)<0,"0",(V5-V4)) -> 0 | X5: =K5+M5+O5+Q5+S5+U5+W5 -> 0 | Y5: =I5-X5 -> 0 | Z5: =(0.93352*(W5+S5)+0.5568*(Q5+O5))*0.26 -> 0 | AA5: =SUM(Z3:Z5) -> 17294.937
A6: 44231 | B6: 62.05 | C6: 17942 | D6: =IF((C6-C5)<0,"0",(C6-C5))*160 -> 480 | E6: 24996576 | F6: =IF((E6-E5)<0,"0",(E6-E5)) -> 15054 | G6: 77493168 | H6: =IF((G6-G5)<0,"0",(G6-G5)) -> 77640 | I6: =F6+H6 -> 92694 | J6: 7458654 | K6: =IF((J6-J5)<0,"0",(J6-J5)) -> 10727 | L6: 7469823 | M6: =IF((L6-L5)<0,"0",(L6-L5)) -> 10427 | N6: 4947080 | O6: =(IF((N6-N5)<0,"0",(N6-N5)))*2 -> 4324 | P6: 2471542 | Q6: =IF((P6-P5)<0,"0",(P6-P5)) -> 12734 | R6: 16506958 | S6: =IF((R6-R5)<0,"0",(R6-R5)) -> 16354 | T6: 0 | V6: 4025862 | W6: =IF((V6-V5)<0,"0",(V6-V5)) -> 18113 | X6: =K6+M6+O6+Q6+S6+U6+W6 -> 72679 | Y6: =I6-X6 -> 20015 | Z6: =(0.93352*(W6+S6)+0.5568*(Q6+O6))*0.26 -> 10835.117 | AA6: =SUM(Z4:Z6) -> 17026.268
A7: 44232 | B7: 62.05 | C7: 17942 | D7: =IF((C7-C6)<0,"0",(C7-C6))*160 -> 0 | E7: 25003730 | F7: =IF((E7-E6)<0,"0",(E7-E6)) -> 7154 | G7: 77564940 | H7: =IF((G7-G6)<0,"0",(G7-G6)) -> 71772 | I7: =F7+H7 -> 78926 | J7: 7466484 | K7: =IF((J7-J6)<0,"0",(J7-J6)) -> 7830 | L7: 7476908 | M7: =IF((L7-L6)<0,"0",(L7-L6)) -> 7085 | N7: 4948812 | O7: =(IF((N7-N6)<0,"0",(N7-N6)))*2 -> 3464 | P7: 2481882 | Q7: =IF((P7-P6)<0,"0",(P7-P6)) -> 10340 | R7: 16519926 | S7: =IF((R7-R6)<0,"0",(R7-R6)) -> 12968 | T7: 0 | V7: 4040508 | W7: =IF((V7-V6)<0,"0",(V7-V6)) -> 14646 | X7: =K7+M7+O7+Q7+S7+U7+W7 -> 56333 | Y7: =I7-X7 -> 22593 | Z7: =(0.93352*(W7+S7)+0.5568*(Q7+O7))*0.26 -> 8700.715 | AA7: =SUM(Z4:Z7) -> 25726.983
A8: 44233 | B8: 58.4 | C8: 17946 | D8: =IF((C8-C7)<0,"0",(C8-C7))*160 -> 640 | E8: 25012775 | F8: =IF((E8-E7)<0,"0",(E8-E7)) -> 9045 | G8: 77580622 | H8: =IF((G8-G7)<0,"0",(G8-G7)) -> 15682 | I8: =F8+H8 -> 24727 | J8: 7469859 | K8: =IF((J8-J7)<0,"0",(J8-J7)) -> 3375 | L8: 7480866 | M8: =IF((L8-L7)<0,"0",(L8-L7)) -> 3958 | N8: 4949490 | O8: =(IF((N8-N7)<0,"0",(N8-N7)))*2 -> 1356 | P8: 2486226 | Q8: =IF((P8-P7)<0,"0",(P8-P7)) -> 4344 | R8: 16525316 | S8: =IF((R8-R7)<0,"0",(R8-R7)) -> 5390 | T8: 0 | V8: 4046567 | W8: =IF((V8-V7)<0,"0",(V8-V7)) -> 6059 | X8: =K8+M8+O8+Q8+S8+U8+W8 -> 24482 | Y8: =I8-X8 -> 245 | Z8: =(0.93352*(W8+S8)+0.5568*(Q8+O8))*0.26 -> 3604.0239 | AA8: =SUM(Z5:Z8) -> 23139.856
A9: 44234 | B9: 58.4 | C9: 17948 | D9: =IF((C9-C8)<0,"0",(C9-C8))*160 -> 320 | E9: 25020874 | F9: =IF((E9-E8)<0,"0",(E9-E8)) -> 8099 | G9: 77624556 | H9: =IF((G9-G8)<0,"0",(G9-G8)) -> 43934 | I9: =F9+H9 -> 52033 | J9: 7475761 | K9: =IF((J9-J8)<0,"0",(J9-J8)) -> 5902 | L9: 7486491 | M9: =IF((L9-L8)<0,"0",(L9-L8)) -> 5625 | N9: 4950649 | O9: =(IF((N9-N8)<0,"0",(N9-N8)))*2 -> 2318 | P9: 2494671 | Q9: =IF((P9-P8)<0,"0",(P9-P8)) -> 8445 | R9: 16534378 | S9: =IF((R9-R8)<0,"0",(R9-R8)) -> 9062 | T9: 0 | V9: 4058718 | W9: =IF((V9-V8)<0,"0",(V9-V8)) -> 12151 | X9: =K9+M9+O9+Q9+S9+U9+W9 -> 43503 | Y9: =I9-X9 -> 8530 | Z9: =(0.93352*(W9+S9)+0.5568*(Q9+O9))*0.26 -> 6706.8555 | AA9: =SUM(Z6:Z9) -> 29846.712
A10: 44235 | B10: 88 | C10: 17950 | D10: =IF((C10-C9)<0,"0",(C10-C9))*160 -> 320 | E10: 25027316 | F10: =IF((E10-E9)<0,"0",(E10-E9)) -> 6442 | G10: 77662661 | H10: =IF((G10-G9)<0,"0",(G10-G9)) -> 38105 | I10: =F10+H10 -> 44547 | J10: 7480723 | K10: =IF((J10-J9)<0,"0",(J10-J9)) -> 4962 | L10: 7490768 | M10: =IF((L10-L9)<0,"0",(L10-L9)) -> 4277 | N10: 4951661 | O10: =(IF((N10-N9)<0,"0",(N10-N9)))*2 -> 2024 | P10: 2500583 | Q10: =IF((P10-P9)<0,"0",(P10-P9)) -> 5912 | R10: 16542151 | S10: =IF((R10-R9)<0,"0",(R10-R9)) -> 7773 | T10: 0 | V10: 4065737 | W10: =IF((V10-V9)<0,"0",(V10-V9)) -> 7019 | X10: =K10+M10+O10+Q10+S10+U10+W10 -> 31967 | Y10: =I10-X10 -> 12580 | Z10: =(0.93352*(W10+S10)+0.5568*(Q10+O10))*0.26 -> 4739.1221 | AA10: =SUM(Z7:Z10) -> 23750.717
A11: 44236 | B11: 73 | C11: 17952 | D11: =IF((C11-C10)<0,"0",(C11-C10))*160 -> 320 | E11: 25036672 | F11: =IF((E11-E10)<0,"0",(E11-E10)) -> 9356 | G11: 77715077 | H11: =IF((G11-G10)<0,"0",(G11-G10)) -> 52416 | I11: =F11+H11 -> 61772 | J11: 7487630 | K11: =IF((J11-J10)<0,"0",(J11-J10)) -> 6907 | L11: 7497192 | M11: =IF((L11-L10)<0,"0",(L11-L10)) -> 6424 | N11: 4953038 | O11: =(IF((N11-N10)<0,"0",(N11-N10)))*2 -> 2754 | P11: 2509854 | Q11: =IF((P11-P10)<0,"0",(P11-P10)) -> 9271 | R11: 16552878 | S11: =IF((R11-R10)<0,"0",(R11-R10)) -> 10727 | T11: 0 | V11: 4077947 | W11: =IF((V11-V10)<0,"0",(V11-V10)) -> 12210 | X11: =K11+M11+O11+Q11+S11+U11+W11 -> 48293 | Y11: =I11-X11 -> 13479 | Z11: =(0.93352*(W11+S11)+0.5568*(Q11+O11))*0.26 -> 7307.9937 | AA11: =SUM(Z8:Z11) -> 22357.995
A12: 44237 | B12: 73 | C12: 17955 | D12: =IF((C12-C11)<0,"0",(C12-C11))*160 -> 480 | E12: 25043265 | F12: =IF((E12-E11)<0,"0",(E12-E11)) -> 6593 | G12: 77750661 | H12: =IF((G12-G11)<0,"0",(G12-G11)) -> 35584 | I12: =F12+H12 -> 42177 | J12: 7492290 | K12: =IF((J12-J11)<0,"0",(J12-J11)) -> 4660 | L12: 7501840 | M12: =IF((L12-L11)<0,"0",(L12-L11)) -> 4648 | N12: 4953941 | O12: =(IF((N12-N11)<0,"0",(N12-N11)))*2 -> 1806 | P12: 2516370 | Q12: =IF((P12-P11)<0,"0",(P12-P11)) -> 6516 | R12: 16560043 | S12: =IF((R12-R11)<0,"0",(R12-R11)) -> 7165 | T12: 0 | V12: 4086102 | W12: =IF((V12-V11)<0,"0",(V12-V11)) -> 8155 | X12: =K12+M12+O12+Q12+S12+U12+W12 -> 32950 | Y12: =I12-X12 -> 9227 | Z12: =(0.93352*(W12+S12)+0.5568*(Q12+O12))*0.26 -> 4923.1562 | AA12: =SUM(Z9:Z12) -> 23677.128
A13: 44238 | B13: 54.75 | C13: 17957 | D13: =IF((C13-C12)<0,"0",(C13-C12))*160 -> 320 | E13: 25050750 | F13: =IF((E13-E12)<0,"0",(E13-E12)) -> 7485 | G13: 77792449 | H13: =IF((G13-G12)<0,"0",(G13-G12)) -> 41788 | I13: =F13+H13 -> 49273 | J13: 7497670 | K13: =IF((J13-J12)<0,"0",(J13-J12)) -> 5380 | L13: 7507023 | M13: =IF((L13-L12)<0,"0",(L13-L12)) -> 5183 | N13: 4955018 | O13: =(IF((N13-N12)<0,"0",(N13-N12)))*2 -> 2154 | P13: 2523615 | Q13: =IF((P13-P12)<0,"0",(P13-P12)) -> 7245 | R13: 16568544 | S13: =IF((R13-R12)<0,"0",(R13-R12)) -> 8501 | T13: 0 | V13: 4095959 | W13: =IF((V13-V12)<0,"0",(V13-V12)) -> 9857 | X13: =K13+M13+O13+Q13+S13+U13+W13 -> 38320 | Y13: =I13-X13 -> 10953 | Z13: =(0.93352*(W13+S13)+0.5568*(Q13+O13))*0.26 -> 5816.4401 | AA13: =SUM(Z10:Z13) -> 22786.712
A14: 44239 | B14: 54.75 | C14: 17959 | D14: =IF((C14-C13)<0,"0",(C14-C13))*160 -> 320 | E14: 25061464 | F14: =IF((E14-E13)<0,"0",(E14-E13)) -> 10714 | G14: 77850188 | H14: =IF((G14-G13)<0,"0",(G14-G13)) -> 57739 | I14: =F14+H14 -> 68453 | J14: 7504768 | K14: =IF((J14-J13)<0,"0",(J14-J13)) -> 7098 | L14: 7514425 | M14: =IF((L14-L13)<0,"0",(L14-L13)) -> 7402 | N14: 4956563 | O14: =(IF((N14-N13)<0,"0",(N14-N13)))*2 -> 3090 | P14: 2533916 | Q14: =IF((P14-P13)<0,"0",(P14-P13)) -> 10301 | R14: 16580594 | S14: =IF((R14-R13)<0,"0",(R14-R13)) -> 12050 | T14: 0 | V14: 4109507 | W14: =IF((V14-V13)<0,"0",(V14-V13)) -> 13548 | X14: =K14+M14+O14+Q14+S14+U14+W14 -> 53489 | Y14: =I14-X14 -> 14964 | Z14: =(0.93352*(W14+S14)+0.5568*(Q14+O14))*0.26 -> 8151.612 | AA14: =SUM(Z11:Z14) -> 26199.202
A15: 44240 | B15: 54.75 | C15: 17963 | D15: =IF((C15-C14)<0,"0",(C15-C14))*160 -> 640 | E15: 25068484 | F15: =IF((E15-E14)<0,"0",(E15-E14)) -> 7020 | G15: 77886366 | H15: =IF((G15-G14)<0,"0",(G15-G14)) -> 36178 | I15: =F15+H15 -> 43198 | J15: 7509346 | K15: =IF((J15-J14)<0,"0",(J15-J14)) -> 4578 | L15: 7519352 | M15: =IF((L15-L14)<0,"0",(L15-L14)) -> 4927 | N15: 4957542 | O15: =(IF((N15-N14)<0,"0",(N15-N14)))*2 -> 1958 | P15: 2540210 | Q15: =IF((P15-P14)<0,"0",(P15-P14)) -> 6294 | R15: 16588138 | S15: =IF((R15-R14)<0,"0",(R15-R14)) -> 7544 | T15: 0 | V15: 4118064 | W15: =IF((V15-V14)<0,"0",(V15-V14)) -> 8557 | X15: =K15+M15+O15+Q15+S15+U15+W15 -> 33858 | Y15: =I15-X15 -> 9340 | Z15: =(0.93352*(W15+S15)+0.5568*(Q15+O15))*0.26 -> 5102.583 | AA15: =SUM(Z12:Z15) -> 23993.791
A16: 44241 | B16: 78 | C16: 17965 | D16: =IF((C16-C15)<0,"0",(C16-C15))*160 -> 320 | E16: 25076116 | F16: =IF((E16-E15)<0,"0",(E16-E15)) -> 7632 | G16: 77927566 | H16: =IF((G16-G15)<0,"0",(G16-G15)) -> 41200 | I16: =F16+H16 -> 48832 | J16: 7514840 | K16: =IF((J16-J15)<0,"0",(J16-J15)) -> 5494 | L16: 7524654 | M16: =IF((L16-L15)<0,"0",(L16-L15)) -> 5302 | N16: 4958634 | O16: =(IF((N16-N15)<0,"0",(N16-N15)))*2 -> 2184 | P16: 2547388 | Q16: =IF((P16-P15)<0,"0",(P16-P15)) -> 7178 | R16: 16596600 | S16: =IF((R16-R15)<0,"0",(R16-R15)) -> 8462 | T16: 0 | V16: 4122720 | W16: =IF((V16-V15)<0,"0",(V16-V15)) -> 4656 | X16: =K16+M16+O16+Q16+S16+U16+W16 -> 33276 | Y16: =I16-X16 -> 15556 | Z16: =(0.93352*(W16+S16)+0.5568*(Q16+O16))*0.26 -> 4539.256 | AA16: =SUM(Z13:Z16) -> 23609.891
A17: 44242 | B17: 65.7 | C17: 17968 | D17: =IF((C17-C16)<0,"0",(C17-C16))*160 -> 480 | E17: 25084370 | F17: =IF((E17-E16)<0,"0",(E17-E16)) -> 8254 | G17: 77971520 | H17: =IF((G17-G16)<0,"0",(G17-G16)) -> 43954 | I17: =F17+H17 -> 52208 | J17: 7520508 | K17: =IF((J17-J16)<0,"0",(J17-J16)) -> 5668 | L17: 7530424 | M17: =IF((L17-L16)<0,"0",(L17-L16)) -> 5770 | N17: 4959796 | O17: =(IF((N17-N16)<0,"0",(N17-N16)))*2 -> 2324 | P17: 2554815 | Q17: =IF((P17-P16)<0,"0",(P17-P16)) -> 7427 | R17: 16605364 | S17: =IF((R17-R16)<0,"0",(R17-R16)) -> 8764 | T17: 0 | V17: 4138294 | W17: =IF((V17-V16)<0,"0",(V17-V16)) -> 15574 | X17: =K17+M17+O17+Q17+S17+U17+W17 -> 45527 | Y17: =I17-X17 -> 6681 | Z17: =(0.93352*(W17+S17)+0.5568*(Q17+O17))*0.26 -> 7318.8353 | AA17: =SUM(Z14:Z17) -> 25112.286
A18: 44243 | B18: 73 | C18: 17970 | D18: =IF((C18-C17)<0,"0",(C18-C17))*160 -> 320 | E18: 25091456 | F18: =IF((E18-E17)<0,"0",(E18-E17)) -> 7086 | G18: 78010731 | H18: =IF((G18-G17)<0,"0",(G18-G17)) -> 39211 | I18: =F18+H18 -> 46297 | J18: 7525801 | K18: =IF((J18-J17)<0,"0",(J18-J17)) -> 5293 | L18: 7535296 | M18: =IF((L18-L17)<0,"0",(L18-L17)) -> 4872 | N18: 4960829 | O18: =(IF((N18-N17)<0,"0",(N18-N17)))*2 -> 2066 | P18: 2560912 | Q18: =IF((P18-P17)<0,"0",(P18-P17)) -> 6097 | R18: 16613423 | S18: =IF((R18-R17)<0,"0",(R18-R17)) -> 8059 | T18: 0 | V18: 4147784 | W18: =IF((V18-V17)<0,"0",(V18-V17)) -> 9490 | X18: =K18+M18+O18+Q18+S18+U18+W18 -> 35877 | Y18: =I18-X18 -> 10420 | Z18: =(0.93352*(W18+S18)+0.5568*(Q18+O18))*0.26 -> 5441.1502 | AA18: =SUM(Z15:Z18) -> 22401.825
