Workbook

Sheet TOTAL
A1: Site Name | B1: Day | C1: Month | D1: Year | E1: Total Electricity Kwh | F1: Electricity Tariff ($/Kwh) | G1: Natual Gas (m3) | H1: Natural Gas $/m3 | I1: Water Utility Supply (m3) m3 | J1: Water Utility Supply (m3) $/m3 | K1: Room Nights | L1: Total Guests | M1: Utilities day cost dh
A2: Mumbai | B2: 1 | C2: 3 | D2: 2021 | E2: ='Daily HLP'!I4 -> 22397 | F2: =9.17*0.014 -> 0.12838 | G2: ='Daily HLP'!M4 -> 880.632 | H2: =48.88*0.014 -> 0.68432 | I2: ='Daily HLP'!P4 -> 228 | J2: =100*0.014 -> 1.4 | K2: =Occupancy!G2 -> 1 | L2: =Occupancy!F2 -> 0 | M2: =E2*F2+G2*H2+#REF!*#REF!+I2*J2 -> #REF!
A3: Mumbai | B3: =B2+1 -> 2 | C3: 3 | D3: 2021 | E3: ='Daily HLP'!I5 -> 22379 | F3: =9.17*0.014 -> 0.12838 | G3: ='Daily HLP'!M5 -> 993.178 | H3: =48.88*0.014 -> 0.68432 | I3: ='Daily HLP'!P5 -> 192 | J3: =100*0.014 -> 1.4 | K3: =Occupancy!G3 -> 121 | L3: =Occupancy!F3 -> 349 | M3: =E3*F3+G3*H3+#REF!*#REF!+I3*J3 -> #REF!
A4: Mumbai | B4: =B3+1 -> 3 | C4: 3 | D4: 2021 | E4: ='Daily HLP'!I6 -> 21109 | F4: =9.17*0.014 -> 0.12838 | G4: ='Daily HLP'!M6 -> 830.41 | H4: =48.88*0.014 -> 0.68432 | I4: ='Daily HLP'!P6 -> 192 | J4: =100*0.014 -> 1.4 | K4: =Occupancy!G4 -> 84 | L4: =Occupancy!F4 -> 399 | M4: =E4*F4+G4*H4+#REF!*#REF!+I4*J4 -> #REF!
A5: Mumbai | B5: =B4+1 -> 4 | C5: 3 | D5: 2021 | E5: ='Daily HLP'!I7 -> 19792 | F5: =9.17*0.014 -> 0.12838 | G5: ='Daily HLP'!M7 -> 884.17 | H5: =48.88*0.014 -> 0.68432 | I5: ='Daily HLP'!P7 -> 192 | J5: =100*0.014 -> 1.4 | K5: =Occupancy!G5 -> 86 | L5: =Occupancy!F5 -> 369 | M5: =E5*F5+G5*H5+#REF!*#REF!+I5*J5 -> #REF!
A6: Mumbai | B6: =B5+1 -> 5 | C6: 3 | D6: 2021 | E6: ='Daily HLP'!I8 -> 20391 | F6: =9.17*0.014 -> 0.12838 | G6: ='Daily HLP'!M8 -> 893.64 | H6: =48.88*0.014 -> 0.68432 | I6: ='Daily HLP'!P8 -> 191 | J6: =100*0.014 -> 1.4 | K6: =Occupancy!G6 -> 97 | L6: =Occupancy!F6 -> 328 | M6: =E6*F6+G6*H6+#REF!*#REF!+I6*J6 -> #REF!
A7: Mumbai | B7: =B6+1 -> 6 | C7: 3 | D7: 2021 | E7: ='Daily HLP'!I9 -> 21871 | F7: =9.17*0.014 -> 0.12838 | G7: ='Daily HLP'!M9 -> 944.36 | H7: =48.88*0.014 -> 0.68432 | I7: ='Daily HLP'!P9 -> 191 | J7: =100*0.014 -> 1.4 | K7: =Occupancy!G7 -> 162 | L7: =Occupancy!F7 -> 506 | M7: =E7*F7+G7*H7+#REF!*#REF!+I7*J7 -> #REF!
A8: Mumbai | B8: =B7+1 -> 7 | C8: 3 | D8: 2021 | E8: ='Daily HLP'!I10 -> 21611 | F8: =9.17*0.014 -> 0.12838 | G8: ='Daily HLP'!M10 -> 931 | H8: =48.88*0.014 -> 0.68432 | I8: ='Daily HLP'!P10 -> 251 | J8: =100*0.014 -> 1.4 | K8: =Occupancy!G8 -> 99 | L8: =Occupancy!F8 -> 607 | M8: =E8*F8+G8*H8+#REF!*#REF!+I8*J8 -> #REF!
A9: Mumbai | B9: =B8+1 -> 8 | C9: 3 | D9: 2021 | E9: ='Daily HLP'!I11 -> 22521 | F9: =9.17*0.014 -> 0.12838 | G9: ='Daily HLP'!M11 -> 859.85 | H9: =48.88*0.014 -> 0.68432 | I9: ='Daily HLP'!P11 -> 193 | J9: =100*0.014 -> 1.4 | K9: =Occupancy!G9 -> 82 | L9: =Occupancy!F9 -> 406 | M9: =E9*F9+G9*H9+#REF!*#REF!+I9*J9 -> #REF!
A10: Mumbai | B10: =B9+1 -> 9 | C10: 3 | D10: 2021 | E10: ='Daily HLP'!I12 -> 20912 | F10: =9.17*0.014 -> 0.12838 | G10: ='Daily HLP'!M12 -> 779.02 | H10: =48.88*0.014 -> 0.68432 | I10: ='Daily HLP'!P12 -> 172 | J10: =100*0.014 -> 1.4 | K10: =Occupancy!G10 -> 84 | L10: =Occupancy!F10 -> 328 | M10: =E10*F10+G10*H10+#REF!*#REF!+I10*J10 -> #REF!
A11: Mumbai | B11: =B10+1 -> 10 | C11: 3 | D11: 2021 | E11: ='Daily HLP'!I13 -> 21790 | F11: =9.17*0.014 -> 0.12838 | G11: ='Daily HLP'!M13 -> 847.13 | H11: =48.88*0.014 -> 0.68432 | I11: ='Daily HLP'!P13 -> 152 | J11: =100*0.014 -> 1.4 | K11: =Occupancy!G11 -> 81 | L11: =Occupancy!F11 -> 362 | M11: =E11*F11+G11*H11+#REF!*#REF!+I11*J11 -> #REF!
A12: Mumbai | B12: =B11+1 -> 11 | C12: 3 | D12: 2021 | E12: ='Daily HLP'!I14 -> 21316 | F12: =9.17*0.014 -> 0.12838 | G12: ='Daily HLP'!M14 -> 852 | H12: =48.88*0.014 -> 0.68432 | I12: ='Daily HLP'!P14 -> 171 | J12: =100*0.014 -> 1.4 | K12: =Occupancy!G12 -> 69 | L12: =Occupancy!F12 -> 305 | M12: =E12*F12+G12*H12+#REF!*#REF!+I12*J12 -> #REF!
A13: Mumbai | B13: =B12+1 -> 12 | C13: 3 | D13: 2021 | E13: ='Daily HLP'!I15 -> 21182 | F13: =9.17*0.014 -> 0.12838 | G13: ='Daily HLP'!M15 -> 804.77 | H13: =48.88*0.014 -> 0.68432 | I13: ='Daily HLP'!P15 -> 154 | J13: =100*0.014 -> 1.4 | K13: =Occupancy!G13 -> 78 | L13: =Occupancy!F13 -> 455 | M13: =E13*F13+G13*H13+#REF!*#REF!+I13*J13 -> #REF!
A14: Mumbai | B14: =B13+1 -> 13 | C14: 3 | D14: 2021 | E14: ='Daily HLP'!I16 -> 21531 | F14: =9.17*0.014 -> 0.12838 | G14: ='Daily HLP'!M16 -> 836.23 | H14: =48.88*0.014 -> 0.68432 | I14: ='Daily HLP'!P16 -> 213 | J14: =100*0.014 -> 1.4 | K14: =Occupancy!G14 -> 140 | L14: =Occupancy!F14 -> 415 | M14: =E14*F14+G14*H14+#REF!*#REF!+I14*J14 -> #REF!
... A31: Mumbai | B31: =B30+1 -> 30 | C31: 3 | D31: 2021 | E31: ='Daily HLP'!I33 -> 0 | F31: =9.17*0.014 -> 0.12838 | G31: ='Daily HLP'!M33 -> 0 | H31: =48.88*0.014 -> 0.68432 | I31: ='Daily HLP'!P33 -> 0 | J31: =100*0.014 -> 1.4 | K31: =Occupancy!G31 -> 0 | L31: =Occupancy!F31 -> 0 | M31: =E31*F31+G31*H31+#REF!*#REF!+I31*J31 -> #REF!

Sheet Submetering
A1: Site Name | B1: Day | C1: Month | D1: Year | E1: ='Section Load'!B4 -> HVAC | F1: ='Section Load'!C4 -> Fire & Emergency PP | G1: ='Section Load'!D4 -> Main PP | H1: ='Section Load'!E4 -> Lighting PP | I1: ='Section Load'!F4 -> CH-1+ CH2+CH3+CH4 | J1: ='Section Load'!G4 -> Chilled water Pump | K1: ='Section Load'!H4 -> Ball Room-1 | L1: ='Section Load'!I4 -> Ball Room-2 | ... AL1: ='Section Load'!AI4 -> Cooling Tower | AM1: R.o.plant | AN1: STP Water Prod | AO1: Domestic Zone-1 | AP1: Domestic Zone-2 | AQ1: Domestic Zone-3 | AR1: Flush Zone -1 | AS1: Flush Zone -2 | AT1: Flush Zone -3 | AU1: Swimming pool | AV1: B2 Laundry | AW1: Boiler Feed Water | AX1: cooling tower filling water | AY1: STP flush(new water meter) | AZ1: Garden Water Pump | BA1: Flush Zone 2 pump meter | BB1: Flush Zone 3 Pump Meter (wtp transfer ) | BC1: Flush Tanker | BD1: Total Domestic Water (R.O +BMC) | BE1: Total Domestic Consumption | BF1: Total STP Consumption | BG1: ='Section Load'!AJ4 -> MGL | BH1: ='Section Load'!AK4 -> HWG | BI1: ='Section Load'!AL4 -> Prato | BJ1: ='Section Load'!AM4 -> BR-1 | BK1: ='Section Load'!AN4 -> SanQi IND | BL1: ='Section Load'!AO4 -> SanQi JPN | BM1: ='Section Load'!AP4 -> Boiler
A2: Mumbai | B2: 1 | C2: 3 | D2: 2021 | E2: ='Section Load'!B5 -> 3193.12 | F2: ='Section Load'!C5 -> 1450.45 | G2: ='Section Load'!D5 -> 2140.42 | H2: ='Section Load'!E5 -> 4328.8 | I2: ='Section Load'!F5 -> 5749.65 | J2: ='Section Load'!G5 -> 2455.36 | K2: ='Section Load'!H5 -> 1635.92 | L2: ='Section Load'!I5 -> 759.24 | ... AL2: ='Section Load'!AI5 -> 690 | AM2: ='[1]1'!$G$92 -> 87 | AN2: ='[1]1'!$G$93 -> 200 | AO2: ='[1]1'!$G$95 -> 72 | AP2: ='[1]1'!$G$96 -> 23 | AQ2: ='[1]1'!$G$97 -> 18 | AR2: ='[1]1'!$G$98 -> 83 | AS2: ='[1]1'!$G$99 -> 13 | AT2: ='[1]1'!$G$100 -> 6 | AU2: ='[1]1'!$G$104 -> 0 | AV2: ='[1]1'!$G$105 -> 8 | AW2: ='[1]1'!$G$106 -> 7 | AX2: ='[1]1'!$G$109 -> 41 | AY2: ='[1]1'!$G$110 -> 79 | AZ2: ='[1]1'!$G$111 -> 0 | BA2: ='[1]1'!$G$114 -> 16 | BB2: ='[1]1'!$G$115 -> 5 | BC2: ='[1]1'!$G$116 -> 0 | BD2: ='[1]1'!$G$118 -> 138 | BE2: ='[1]1'!$G$119 -> 132 | BF2: ='[1]1'!$G$120 -> 120 | BG2: ='Section Load'!AJ5 -> 880.632 | BH2: ='Section Load'!AK5 -> 266.26 | BI2: ='Section Load'!AL5 -> 0 | BJ2: ='Section Load'!AM5 -> 63.95 | BK2: ='Section Load'!AN5 -> 25.1 | BL2: ='Section Load'!AO5 -> 2.1 | BM2: ='Section Load'!AP5 -> 523.222
A3: Mumbai | B3: =B2+1 -> 2 | C3: 3 | D3: 2021 | E3: ='Section Load'!B6 -> 3503.76 | F3: ='Section Load'!C6 -> 1456.84 | G3: ='Section Load'!D6 -> 2089.51 | H3: ='Section Load'!E6 -> 4368.93 | I3: ='Section Load'!F6 -> 5632.661 | J3: ='Section Load'!G6 -> 2485.52 | K3: ='Section Load'!H6 -> 1600.36 | L3: ='Section Load'!I6 -> 669.28 | ... AL3: ='Section Load'!AI6 -> 727 | AM3: ='[1]2'!$G$92 -> 75 | AN3: ='[1]2'!$G$93 -> 151 | AO3: ='[1]2'!$G$95 -> 70 | AP3: ='[1]2'!$G$96 -> 30 | AQ3: ='[1]2'!$G$97 -> 16 | AR3: ='[1]2'!$G$98 -> 67 | AS3: ='[1]2'!$G$99 -> 8 | AT3: ='[1]2'!$G$100 -> 5 | AU3: ='[1]2'!$G$104 -> 0 | AV3: ='[1]2'!$G$105 -> 8 | AW3: ='[1]2'!$G$106 -> 5 | AX3: ='[1]2'!$G$109 -> 61 | AY3: ='[1]2'!$G$110 -> 39 | AZ3: ='[1]2'!$G$111 -> 16 | BA3: ='[1]2'!$G$114 -> 11 | BB3: ='[1]2'!$G$115 -> 3 | BC3: ='[1]2'!$G$116 -> 0 | BD3: ='[1]2'!$G$118 -> 126 | BE3: ='[1]2'!$G$119 -> 129 | BF3: ='[1]2'!$G$120 -> 116 | BG3: ='Section Load'!AJ6 -> 993.178 | BH3: ='Section Load'!AK6 -> 278.29 | BI3: ='Section Load'!AL6 -> 0 | BJ3: ='Section Load'!AM6 -> 81.7 | BK3: ='Section Load'!AN6 -> 26.9 | BL3: ='Section Load'!AO6 -> 0.5 | BM3: ='Section Load'!AP6 -> 605.788
A4: Mumbai | B4: =B3+1 -> 3 | C4: 3 | D4: 2021 | E4: ='Section Load'!B7 -> 3426.88 | F4: ='Section Load'!C7 -> 1469.49 | G4: ='Section Load'!D7 -> 2172.05 | H4: ='Section Load'!E7 -> 4356.42 | I4: ='Section Load'!F7 -> 4924.529 | J4: ='Section Load'!G7 -> 2463.82 | K4: ='Section Load'!H7 -> 1065.36 | L4: ='Section Load'!I7 -> 626.42 | ... AL4: ='Section Load'!AI7 -> 553 | AM4: ='[1]3'!$G$92 -> 88 | AN4: ='[1]3'!$G$93 -> 150 | AO4: ='[1]3'!$G$95 -> 64 | AP4: ='[1]3'!$G$96 -> 36 | AQ4: ='[1]3'!$G$97 -> 31 | AR4: ='[1]3'!$G$98 -> 72 | AS4: ='[1]3'!$G$99 -> 10 | AT4: ='[1]3'!$G$100 -> 5 | AU4: ='[1]3'!$G$104 -> 0 | AV4: ='[1]3'!$G$105 -> 6 | AW4: ='[1]3'!$G$106 -> 5 | AX4: ='[1]3'!$G$109 -> 58 | AY4: ='[1]3'!$G$110 -> 93 | AZ4: ='[1]3'!$G$111 -> 0 | BA4: ='[1]3'!$G$114 -> 12 | BB4: ='[1]3'!$G$115 -> 6 | BC4: ='[1]3'!$G$116 -> 0 | BD4: ='[1]3'!$G$118 -> 139 | BE4: ='[1]3'!$G$119 -> 146 | BF4: ='[1]3'!$G$120 -> 151 | BG4: ='Section Load'!AJ7 -> 830.41 | BH4: ='Section Load'!AK7 -> 245.65 | BI4: ='Section Load'!AL7 -> 0 | BJ4: ='Section Load'!AM7 -> 63.66 | BK4: ='Section Load'!AN7 -> 18.7 | BL4: ='Section Load'!AO7 -> 3.7 | BM4: ='Section Load'!AP7 -> 498.7
A5: Mumbai | B5: =B4+1 -> 4 | C5: 3 | D5: 2021 | E5: ='Section Load'!B8 -> 3260.52 | F5: ='Section Load'!C8 -> 1488.38 | G5: ='Section Load'!D8 -> 2010.82 | H5: ='Section Load'!E8 -> 4163.23 | I5: ='Section Load'!F8 -> 4227.22 | J5: ='Section Load'!G8 -> 2461.14 | K5: ='Section Load'!H8 -> 1029.33 | L5: ='Section Load'!I8 -> 622.49 | ... AL5: ='Section Load'!AI8 -> 700 | AM5: ='[1]4'!$G$92 -> 102 | AN5: ='[1]4'!$G$93 -> 140 | AO5: ='[1]4'!$G$95 -> 78 | AP5: ='[1]4'!$G$96 -> 35 | AQ5: ='[1]4'!$G$97 -> 45 | AR5: ='[1]4'!$G$98 -> 67 | AS5: ='[1]4'!$G$99 -> 10 | AT5: ='[1]4'!$G$100 -> 7 | AU5: ='[1]4'!$G$104 -> 0 | AV5: ='[1]4'!$G$105 -> 6 | AW5: ='[1]4'!$G$106 -> 6 | AX5: ='[1]4'!$G$109 -> 55 | AY5: ='[1]4'!$G$110 -> 47 | AZ5: ='[1]4'!$G$111 -> 14 | BA5: ='[1]4'!$G$114 -> 14 | BB5: ='[1]4'!$G$115 -> 7 | BC5: ='[1]4'!$G$116 -> 0 | BD5: ='[1]4'!$G$118 -> 152 | BE5: ='[1]4'!$G$119 -> 175 | BF5: ='[1]4'!$G$120 -> 116 | BG5: ='Section Load'!AJ8 -> 884.17 | BH5: ='Section Load'!AK8 -> 244.96 | BI5: ='Section Load'!AL8 -> -0.4 | BJ5: ='Section Load'!AM8 -> 71.35 | BK5: ='Section Load'!AN8 -> 29.4 | BL5: ='Section Load'!AO8 -> 1.9 | BM5: ='Section Load'!AP8 -> 536.96
A6: Mumbai | B6: =B5+1 -> 5 | C6: 3 | D6: 2021 | E6: ='Section Load'!B9 -> 3368 | F6: ='Section Load'!C9 -> 36659 | G6: ='Section Load'!D9 -> 1822 | H6: ='Section Load'!E9 -> 104331 | I6: ='Section Load'!F9 -> 4900.74 | J6: ='Section Load'!G9 -> 2387 | K6: ='Section Load'!H9 -> 1011 | L6: ='Section Load'!I9 -> 577 | ... AL6: ='Section Load'!AI9 -> 954 | AM6: ='[1]5'!$G$92 -> 110 | AN6: ='[1]5'!$G$93 -> 182 | AO6: ='[1]5'!$G$95 -> 55 | AP6: ='[1]5'!$G$96 -> 23 | AQ6: ='[1]5'!$G$97 -> 40 | AR6: ='[1]5'!$G$98 -> 40 | AS6: ='[1]5'!$G$99 -> 7 | AT6: ='[1]5'!$G$100 -> 6 | AU6: ='[1]5'!$G$104 -> 0 | AV6: ='[1]5'!$G$105 -> 14 | AW6: ='[1]5'!$G$106 -> 9 | AX6: ='[1]5'!$G$109 -> 115 | AY6: ='[1]5'!$G$110 -> 79 | AZ6: ='[1]5'!$G$111 -> 0 | BA6: ='[1]5'!$G$114 -> 21 | BB6: ='[1]5'!$G$115 -> 11 | BC6: ='[1]5'!$G$116 -> 0 | BD6: ='[1]5'!$G$118 -> 151 | BE6: ='[1]5'!$G$119 -> 131 | BF6: ='[1]5'!$G$120 -> 194 | BG6: ='Section Load'!AJ9 -> 893.64 | BH6: ='Section Load'!AK9 -> 245 | BI6: ='Section Load'!AL9 -> 0 | BJ6: ='Section Load'!AM9 -> 61 | BK6: ='Section Load'!AN9 -> 21 | BL6: ='Section Load'!AO9 -> 2 | BM6: ='Section Load'!AP9 -> 564.64
A7: Mumbai | B7: =B6+1 -> 6 | C7: 3 | D7: 2021 | E7: ='Section Load'!B10 -> 3484 | F7: ='Section Load'!C10 -> 1518 | G7: ='Section Load'!D10 -> 2123 | H7: ='Section Load'!E10 -> 4237 | I7: ='Section Load'!F10 -> 5904 | J7: ='Section Load'!G10 -> 2437 | K7: ='Section Load'!H10 -> 1043 | L7: ='Section Load'!I10 -> 624 | ... AL7: ='Section Load'!AI10 -> 644 | AM7: ='[1]6'!$G$92 -> 89 | AN7: ='[1]6'!$G$93 -> 101 | AO7: ='[1]6'!$G$95 -> 61 | AP7: ='[1]6'!$G$96 -> 34 | AQ7: ='[1]6'!$G$97 -> 31 | AR7: ='[1]6'!$G$98 -> 72 | AS7: ='[1]6'!$G$99 -> 9 | AT7: ='[1]6'!$G$100 -> 9 | AU7: ='[1]6'!$G$104 -> 0 | AV7: ='[1]6'!$G$105 -> 6 | AW7: ='[1]6'!$G$106 -> 6 | AX7: ='[1]6'!$G$109 -> 40 | AY7: ='[1]6'!$G$110 -> 45 | AZ7: ='[1]6'!$G$111 -> 32 | BA7: ='[1]6'!$G$114 -> 11 | BB7: ='[1]6'!$G$115 -> 6 | BC7: ='[1]6'!$G$116 -> 0 | BD7: ='[1]6'!$G$118 -> 140 | BE7: ='[1]6'!$G$119 -> 144 | BF7: ='[1]6'!$G$120 -> 117 | BG7: ='Section Load'!AJ10 -> 944.36 | BH7: ='Section Load'!AK10 -> 264 | BI7: ='Section Load'!AL10 -> 0 | BJ7: ='Section Load'!AM10 -> 71 | BK7: ='Section Load'!AN10 -> 32 | BL7: ='Section Load'!AO10 -> 3 | BM7: ='Section Load'!AP10 -> 574.36
A8: Mumbai | B8: =B7+1 -> 7 | C8: 3 | D8: 2021 | E8: ='Section Load'!B11 -> 3319 | F8: ='Section Load'!C11 -> 1500 | G8: ='Section Load'!D11 -> 2331 | H8: ='Section Load'!E11 -> 4230 | I8: ='Section Load'!F11 -> 5494 | J8: ='Section Load'!G11 -> 2417 | K8: ='Section Load'!H11 -> 1230 | L8: ='Section Load'!I11 -> 611 | ... AL8: ='Section Load'!AI11 -> 834 | AM8: ='[1]7'!$G$92 -> 104 | AN8: ='[1]7'!$G$93 -> 207 | AO8: ='[1]7'!$G$95 -> 57 | AP8: ='[1]7'!$G$96 -> 43 | AQ8: ='[1]7'!$G$97 -> 23 | AR8: ='[1]7'!$G$98 -> 58 | AS8: ='[1]7'!$G$99 -> 14 | AT8: ='[1]7'!$G$100 -> 8 | AU8: ='[1]7'!$G$104 -> 0 | AV8: ='[1]7'!$G$105 -> 6 | AW8: ='[1]7'!$G$106 -> 4 | AX8: ='[1]7'!$G$109 -> 39 | AY8: ='[1]7'!$G$110 -> 101 | AZ8: ='[1]7'!$G$111 -> 0 | BA8: ='[1]7'!$G$114 -> 16 | BB8: ='[1]7'!$G$115 -> 7 | BC8: ='[1]7'!$G$116 -> 0 | BD8: ='[1]7'!$G$118 -> 156 | BE8: ='[1]7'!$G$119 -> 145 | BF8: ='[1]7'!$G$120 -> 140 | BG8: ='Section Load'!AJ11 -> 931 | BH8: ='Section Load'!AK11 -> 275 | BI8: ='Section Load'!AL11 -> 0 | BJ8: ='Section Load'!AM11 -> 72 | BK8: ='Section Load'!AN11 -> 38 | BL8: ='Section Load'!AO11 -> 4 | BM8: ='Section Load'!AP11 -> 542
A9: Mumbai | B9: =B8+1 -> 8 | C9: 3 | D9: 2021 | E9: ='Section Load'!B12 -> 3394 | F9: ='Section Load'!C12 -> 1483 | G9: ='Section Load'!D12 -> 2160 | H9: ='Section Load'!E12 -> 4272 | I9: ='Section Load'!F12 -> 5838.26 | J9: ='Section Load'!G12 -> 2516 | K9: ='Section Load'!H12 -> 1538 | L9: ='Section Load'!I12 -> 676 | ... AL9: ='Section Load'!AI12 -> 793 | AM9: ='[1]8'!$G$92 -> 95 | AN9: ='[1]8'!$G$93 -> 207 | AO9: ='[1]8'!$G$95 -> 71 | AP9: ='[1]8'!$G$96 -> 51 | AQ9: ='[1]8'!$G$97 -> 20 | AR9: ='[1]8'!$G$98 -> 78 | AS9: ='[1]8'!$G$99 -> 12 | AT9: ='[1]8'!$G$100 -> 8 | AU9: ='[1]8'!$G$104 -> 0 | AV9: ='[1]8'!$G$105 -> 9 | AW9: ='[1]8'!$G$106 -> 5 | AX9: ='[1]8'!$G$109 -> 74 | AY9: ='[1]8'!$G$110 -> 43 | AZ9: ='[1]8'!$G$111 -> 0 | BA9: ='[1]8'!$G$114 -> 16 | BB9: ='[1]8'!$G$115 -> 7 | BC9: ='[1]8'!$G$116 -> 0 | BD9: ='[1]8'!$G$118 -> 146 | BE9: ='[1]8'!$G$119 -> 162 | BF9: ='[1]8'!$G$120 -> 117 | BG9: ='Section Load'!AJ12 -> 859.85 | BH9: ='Section Load'!AK12 -> 241 | BI9: ='Section Load'!AL12 -> 0.4 | BJ9: ='Section Load'!AM12 -> 63 | BK9: ='Section Load'!AN12 -> 16 | BL9: ='Section Load'!AO12 -> 1 | BM9: ='Section Load'!AP12 -> 538.45
A10: Mumbai | B10: =B9+1 -> 9 | C10: 3 | D10: 2021 | E10: ='Section Load'!B13 -> 3381 | F10: ='Section Load'!C13 -> 1491 | G10: ='Section Load'!D13 -> 2121 | H10: ='Section Load'!E13 -> 4195 | I10: ='Section Load'!F13 -> 5115 | J10: ='Section Load'!G13 -> 2377 | K10: ='Section Load'!H13 -> 1028 | L10: ='Section Load'!I13 -> 667 | ... AL10: ='Section Load'!AI13 -> 882 | AM10: ='[1]9'!$G$92 -> 104 | AN10: ='[1]9'!$G$93 -> 106 | AO10: ='[1]9'!$G$95 -> 62 | AP10: ='[1]9'!$G$96 -> 40 | AQ10: ='[1]9'!$G$97 -> 29 | AR10: ='[1]9'!$G$98 -> 67 | AS10: ='[1]9'!$G$99 -> 13 | AT10: ='[1]9'!$G$100 -> 9 | AU10: ='[1]9'!$G$104 -> 0 | AV10: ='[1]9'!$G$105 -> 0 | AW10: ='[1]9'!$G$106 -> 4 | AX10: ='[1]9'!$G$109 -> 53 | AY10: ='[1]9'!$G$110 -> 63 | AZ10: ='[1]9'!$G$111 -> 37 | BA10: ='[1]9'!$G$114 -> 15 | BB10: ='[1]9'!$G$115 -> 7 | BC10: ='[1]9'!$G$116 -> 0 | BD10: ='[1]9'!$G$118 -> 156 | BE10: ='[1]9'!$G$119 -> 153 | BF10: ='[1]9'!$G$120 -> 153 | BG10: ='Section Load'!AJ13 -> 779.02 | BH10: ='Section Load'!AK13 -> 253 | BI10: ='Section Load'!AL13 -> 0 | BJ10: ='Section Load'!AM13 -> 43 | BK10: ='Section Load'!AN13 -> 85 | BL10: ='Section Load'!AO13 -> 2 | BM10: ='Section Load'!AP13 -> 396.02
A11: Mumbai | B11: =B10+1 -> 10 | C11: 3 | D11: 2021 | E11: ='Section Load'!B14 -> 3447 | F11: ='Section Load'!C14 -> 1549 | G11: ='Section Load'!D14 -> 2046 | H11: ='Section Load'!E14 -> 4185 | I11: ='Section Load'!F14 -> 4999 | J11: ='Section Load'!G14 -> 2507 | K11: ='Section Load'!H14 -> 1194 | L11: ='Section Load'!I14 -> 702 | ... AL11: ='Section Load'!AI14 -> 885 | AM11: ='[1]10'!$G$92 -> 137 | AN11: ='[1]10'!$G$93 -> 155 | AO11: ='[1]10'!$G$95 -> 77 | AP11: ='[1]10'!$G$96 -> 40 | AQ11: ='[1]10'!$G$97 -> 46 | AR11: ='[1]10'!$G$98 -> 80 | AS11: ='[1]10'!$G$99 -> 12 | AT11: ='[1]10'!$G$100 -> 12 | AU11: ='[1]10'!$G$104 -> 0 | AV11: ='[1]10'!$G$105 -> 12 | AW11: ='[1]10'!$G$106 -> 3 | AX11: ='[1]10'!$G$109 -> 61 | AY11: ='[1]10'!$G$110 -> 64 | AZ11: ='[1]10'!$G$111 -> 6 | BA11: ='[1]10'!$G$114 -> 14 | BB11: ='[1]10'!$G$115 -> 13 | BC11: ='[1]10'!$G$116 -> 0 | BD11: ='[1]10'!$G$118 -> 187 | BE11: ='[1]10'!$G$119 -> 187 | BF11: ='[1]10'!$G$120 -> 131 | BG11: ='Section Load'!AJ14 -> 847.13 | BH11: ='Section Load'!AK14 -> 247 | BI11: ='Section Load'!AL14 -> -0.4 | BJ11: ='Section Load'!AM14 -> 76 | BK11: ='Section Load'!AN14 -> 51 | BL11: ='Section Load'!AO14 -> 3 | BM11: ='Section Load'!AP14 -> 470.53
A12: Mumbai | B12: =B11+1 -> 11 | C12: 3 | D12: 2021 | E12: ='Section Load'!B15 -> 3850 | F12: ='Section Load'!C15 -> 1551 | G12: ='Section Load'!D15 -> 2085 | H12: ='Section Load'!E15 -> 4105 | I12: ='Section Load'!F15 -> 5075 | J12: ='Section Load'!G15 -> 2394 | K12: ='Section Load'!H15 -> 1135 | L12: ='Section Load'!I15 -> 598 | ... AL12: ='Section Load'!AI15 -> 998 | AM12: ='[1]11'!$G$92 -> 101 | AN12: ='[1]11'!$G$93 -> 134 | AO12: ='[1]11'!$G$95 -> 71 | AP12: ='[1]11'!$G$96 -> 49 | AQ12: ='[1]11'!$G$97 -> 23 | AR12: ='[1]11'!$G$98 -> 75 | AS12: ='[1]11'!$G$99 -> 10 | AT12: ='[1]11'!$G$100 -> 9 | AU12: ='[1]11'!$G$104 -> 0 | AV12: ='[1]11'!$G$105 -> 7 | AW12: ='[1]11'!$G$106 -> 6 | AX12: ='[1]11'!$G$109 -> 105 | AY12: ='[1]11'!$G$110 -> 99 | AZ12: ='[1]11'!$G$111 -> 12 | BA12: ='[1]11'!$G$114 -> 12 | BB12: ='[1]11'!$G$115 -> 3 | BC12: ='[1]11'!$G$116 -> 0 | BD12: ='[1]11'!$G$118 -> 152 | BE12: ='[1]11'!$G$119 -> 162 | BF12: ='[1]11'!$G$120 -> 216 | BG12: ='Section Load'!AJ15 -> 852 | BH12: ='Section Load'!AK15 -> 233 | BI12: ='Section Load'!AL15 -> 0 | BJ12: ='Section Load'!AM15 -> 68 | BK12: ='Section Load'!AN15 -> 17 | BL12: ='Section Load'!AO15 -> 3 | BM12: ='Section Load'!AP15 -> 531
A13: Mumbai | B13: =B12+1 -> 12 | C13: 3 | D13: 2021 | E13: ='Section Load'!B16 -> 3783 | F13: ='Section Load'!C16 -> 1569 | G13: ='Section Load'!D16 -> 1820 | H13: ='Section Load'!E16 -> 4165 | I13: ='Section Load'!F16 -> 5122 | J13: ='Section Load'!G16 -> 2392 | K13: ='Section Load'!H16 -> 1179 | L13: ='Section Load'!I16 -> 629 | ... AL13: ='Section Load'!AI16 -> 991 | AM13: ='[1]12'!$G$92 -> 129 | AN13: ='[1]12'!$G$93 -> 117 | AO13: ='[1]12'!$G$95 -> 86 | AP13: ='[1]12'!$G$96 -> 38 | AQ13: ='[1]12'!$G$97 -> 27 | AR13: ='[1]12'!$G$98 -> 83 | AS13: ='[1]12'!$G$99 -> 10 | AT13: ='[1]12'!$G$100 -> 7 | AU13: ='[1]12'!$G$104 -> 0 | AV13: ='[1]12'!$G$105 -> 9 | AW13: ='[1]12'!$G$106 -> 12 | AX13: ='[1]12'!$G$109 -> 64 | AY13: ='[1]12'!$G$110 -> 59 | AZ13: ='[1]12'!$G$111 -> 0 | BA13: ='[1]12'!$G$114 -> 14 | BB13: ='[1]12'!$G$115 -> 8 | BC13: ='[1]12'!$G$116 -> 0 | BD13: ='[1]12'!$G$118 -> 180 | BE13: ='[1]12'!$G$119 -> 168 | BF13: ='[1]12'!$G$120 -> 123 | BG13: ='Section Load'!AJ16 -> 804.77 | BH13: ='Section Load'!AK16 -> 245 | BI13: ='Section Load'!AL16 -> 0 | BJ13: ='Section Load'!AM16 -> 60 | BK13: ='Section Load'!AN16 -> 20 | BL13: ='Section Load'!AO16 -> 3 | BM13: ='Section Load'!AP16 -> 476.77
A14: Mumbai | B14: =B13+1 -> 13 | C14: 3 | D14: 2021 | E14: ='Section Load'!B17 -> 3627 | F14: ='Section Load'!C17 -> 1606 | G14: ='Section Load'!D17 -> 2030 | H14: ='Section Load'!E17 -> 4243 | I14: ='Section Load'!F17 -> 5361 | J14: ='Section Load'!G17 -> 2397.33 | K14: ='Section Load'!H17 -> 1073 | L14: ='Section Load'!I17 -> 667 | ... AL14: ='Section Load'!AI17 -> 758 | AM14: ='[1]13'!$G$92 -> 149 | AN14: ='[1]13'!$G$93 -> 249 | AO14: ='[1]13'!$G$95 -> 88 | AP14: ='[1]13'!$G$96 -> 43 | AQ14: ='[1]13'!$G$97 -> 46 | AR14: ='[1]13'!$G$98 -> 63 | AS14: ='[1]13'!$G$99 -> 16 | AT14: ='[1]13'!$G$100 -> 14 | AU14: ='[1]13'!$G$104 -> 0 | AV14: ='[1]13'!$G$105 -> 11 | AW14: ='[1]13'!$G$106 -> 6 | AX14: ='[1]13'!$G$109 -> 60 | AY14: ='[1]13'!$G$110 -> 86 | AZ14: ='[1]13'!$G$111 -> 13 | BA14: ='[1]13'!$G$114 -> 20 | BB14: ='[1]13'!$G$115 -> 6 | BC14: ='[1]13'!$G$116 -> 0 | BD14: ='[1]13'!$G$118 -> 201 | BE14: ='[1]13'!$G$119 -> 207 | BF14: ='[1]13'!$G$120 -> 159 | BG14: ='Section Load'!AJ17 -> 836.23 | BH14: ='Section Load'!AK17 -> 246 | BI14: ='Section Load'!AL17 -> 0.4 | BJ14: ='Section Load'!AM17 -> 63 | BK14: ='Section Load'!AN17 -> 28 | BL14: ='Section Load'!AO17 -> 3 | BM14: ='Section Load'!AP17 -> 495.83
A15: Mumbai | B15: =B14+1 -> 14 | C15: 3 | D15: 2021 | E15: ='Section Load'!B18 -> 3483 | F15: ='Section Load'!C18 -> 1563 | G15: ='Section Load'!D18 -> 2010 | H15: ='Section Load'!E18 -> 4133 | I15: ='Section Load'!F18 -> 5010 | J15: ='Section Load'!G18 -> 2407 | K15: ='Section Load'!H18 -> 1184 | L15: ='Section Load'!I18 -> 659 | ... AL15: ='Section Load'!AI18 -> 742 | AM15: ='[1]14'!$G$92 -> 166 | AN15: ='[1]14'!$G$93 -> 174 | AO15: ='[1]14'!$G$95 -> 121 | AP15: ='[1]14'!$G$96 -> 47 | AQ15: ='[1]14'!$G$97 -> 46 | AR15: ='[1]14'!$G$98 -> 71 | AS15: ='[1]14'!$G$99 -> 19 | AT15: ='[1]14'!$G$100 -> 24 | AU15: ='[1]14'!$G$104 -> 87 | AV15: ='[1]14'!$G$105 -> 11 | AW15: ='[1]14'!$G$106 -> 5 | AX15: ='[1]14'!$G$109 -> 60 | AY15: ='[1]14'!$G$110 -> 42 | AZ15: ='[1]14'!$G$111 -> 0 | BA15: ='[1]14'!$G$114 -> 22 | BB15: ='[1]14'!$G$115 -> 20 | BC15: ='[1]14'!$G$116 -> 0 | BD15: ='[1]14'!$G$118 -> 217 | BE15: ='[1]14'!$G$119 -> 257 | BF15: ='[1]14'!$G$120 -> 102 | BG15: ='Section Load'!AJ18 -> 855 | BH15: ='Section Load'!AK18 -> 245 | BI15: ='Section Load'!AL18 -> 0 | BJ15: ='Section Load'!AM18 -> 61.21 | BK15: ='Section Load'!AN18 -> -66.5 | BL15: ='Section Load'!AO18 -> 3.3 | BM15: ='Section Load'!AP18 -> 611.99
A16: Mumbai | B16: =B15+1 -> 15 | C16: 3 | D16: 2021 | E16: ='Section Load'!B19 -> 3462.76 | F16: ='Section Load'!C19 -> 1624.67 | G16: ='Section Load'!D19 -> 1887.91 | H16: ='Section Load'!E19 -> 4262.21 | I16: ='Section Load'!F19 -> 5696.453 | J16: ='Section Load'!G19 -> 2431.55 | K16: ='Section Load'!H19 -> 1168.67 | L16: ='Section Load'!I19 -> 718 | ... AL16: ='Section Load'!AI19 -> 731 | AM16: ='[1]15'!$G$92 -> 192 | AN16: ='[1]15'!$G$93 -> 194 | AO16: ='[1]15'!$G$95 -> 131 | AP16: ='[1]15'!$G$96 -> 25 | AQ16: ='[1]15'!$G$97 -> 35 | AR16: ='[1]15'!$G$98 -> 76 | AS16: ='[1]15'!$G$99 -> 30 | AT16: ='[1]15'!$G$100 -> 23 | AU16: ='[1]15'!$G$104 -> 0 | AV16: ='[1]15'!$G$105 -> 17 | AW16: ='[1]15'!$G$106 -> 11 | AX16: ='[1]15'!$G$109 -> 83 | AY16: ='[1]15'!$G$110 -> 86 | AZ16: ='[1]15'!$G$111 -> 13 | BA16: ='[1]15'!$G$114 -> 35 | BB16: ='[1]15'!$G$115 -> 13 | BC16: ='[1]15'!$G$116 -> 0 | BD16: ='[1]15'!$G$118 -> 244 | BE16: ='[1]15'!$G$119 -> 244 | BF16: ='[1]15'!$G$120 -> 182 | BG16: ='Section Load'!AJ19 -> 827.709 | BH16: ='Section Load'!AK19 -> 248.97 | BI16: ='Section Load'!AL19 -> 0 | BJ16: ='Section Load'!AM19 -> 61.67 | BK16: ='Section Load'!AN19 -> 14.4 | BL16: ='Section Load'!AO19 -> 2.5 | BM16: ='Section Load'!AP19 -> 500.169
A17: Mumbai | B17: =B16+1 -> 16 | C17: 3 | D17: 2021 | E17: ='Section Load'!B20 -> 3222.48 | F17: ='Section Load'!C20 -> 1585.1 | G17: ='Section Load'!D20 -> 1760.32 | H17: ='Section Load'!E20 -> 4153.46 | I17: ='Section Load'!F20 -> 5084.16 | J17: ='Section Load'!G20 -> 2381.44 | K17: ='Section Load'!H20 -> 1068.24 | L17: ='Section Load'!I20 -> 616.75 | ... AL17: ='Section Load'!AI20 -> 692 | AM17: ='[1]16'!$G$92 -> 132 | AN17: ='[1]16'!$G$93 -> 154 | AO17: ='[1]16'!$G$95 -> 97 | AP17: ='[1]16'!$G$96 -> 18 | AQ17: ='[1]16'!$G$97 -> 24 | AR17: ='[1]16'!$G$98 -> 56 | AS17: ='[1]16'!$G$99 -> 17 | AT17: ='[1]16'!$G$100 -> 6 | AU17: ='[1]16'!$G$104 -> 0 | AV17: ='[1]16'!$G$105 -> 12 | AW17: ='[1]16'!$G$106 -> 6 | AX17: ='[1]16'!$G$109 -> 60 | AY17: ='[1]16'!$G$110 -> 58 | AZ17: ='[1]16'!$G$111 -> 0 | BA17: ='[1]16'!$G$114 -> 21 | BB17: ='[1]16'!$G$115 -> 13 | BC17: ='[1]16'!$G$116 -> 0 | BD17: ='[1]16'!$G$118 -> 182 | BE17: ='[1]16'!$G$119 -> 162 | BF17: ='[1]16'!$G$120 -> 118 | BG17: ='Section Load'!AJ20 -> 821.111 | BH17: ='Section Load'!AK20 -> 235.94 | BI17: ='Section Load'!AL20 -> 0 | BJ17: ='Section Load'!AM20 -> 50.3 | BK17: ='Section Load'!AN20 -> 16.1 | BL17: ='Section Load'!AO20 -> 0.6 | BM17: ='Section Load'!AP20 -> 518.171
A18: Mumbai | B18: =B17+1 -> 17 | C18: 3 | D18: 2021 | E18: ='Section Load'!B21 -> 3306.64 | F18: ='Section Load'!C21 -> 1574.53 | G18: ='Section Load'!D21 -> 1736.4 | H18: ='Section Load'!E21 -> 4104.48 | I18: ='Section Load'!F21 -> 4907.517 | J18: ='Section Load'!G21 -> 2358 | K18: ='Section Load'!H21 -> 1167.56 | L18: ='Section Load'!I21 -> 641.94 | ... AL18: ='Section Load'!AI21 -> 661 | AM18: ='[1]17'!$G$92 -> 84 | AN18: ='[1]17'!$G$93 -> 134 | AO18: ='[1]17'!$G$95 -> 72 | AP18: ='[1]17'!$G$96 -> 15 | AQ18: ='[1]17'!$G$97 -> 20 | AR18: ='[1]17'!$G$98 -> 35 | AS18: ='[1]17'!$G$99 -> 14 | AT18: ='[1]17'!$G$100 -> 6 | AU18: ='[1]17'!$G$104 -> 0 | AV18: ='[1]17'!$G$105 -> 9 | AW18: ='[1]17'!$G$106 -> 5 | AX18: ='[1]17'!$G$109 -> 40 | AY18: ='[1]17'!$G$110 -> 37 | AZ18: ='[1]17'!$G$111 -> 22 | BA18: ='[1]17'!$G$114 -> 17 | BB18: ='[1]17'!$G$115 -> 6 | BC18: ='[1]17'!$G$116 -> 0 | BD18: ='[1]17'!$G$118 -> 135 | BE18: ='[1]17'!$G$119 -> 127 | BF18: ='[1]17'!$G$120 -> 99 | BG18: ='Section Load'!AJ21 -> 780.709 | BH18: ='Section Load'!AK21 -> 236.1 | BI18: ='Section Load'!AL21 -> 0 | BJ18: ='Section Load'!AM21 -> 72.25 | BK18: ='Section Load'!AN21 -> 16.8 | BL18: ='Section Load'!AO21 -> 4.5 | BM18: ='Section Load'!AP21 -> 451.059
A19: Mumbai | B19: =B18+1 -> 18 | C19: 3 | D19: 2021 | E19: ='Section Load'!B22 -> 3524.64 | F19: ='Section Load'!C22 -> 1640.26 | G19: ='Section Load'!D22 -> 1769.36 | H19: ='Section Load'!E22 -> 4365.4 | I19: ='Section Load'!F22 -> 6598.273 | J19: ='Section Load'!G22 -> 2617.36 | K19: ='Section Load'!H22 -> 1567.92 | L19: ='Section Load'!I22 -> 789.31 | ... AL19: ='Section Load'!AI22 -> 727 | AM19: ='[1]18'!$G$92 -> 81 | AN19: ='[1]18'!$G$93 -> 137 | AO19: ='[1]18'!$G$95 -> 74 | AP19: ='[1]18'!$G$96 -> 16 | AQ19: ='[1]18'!$G$97 -> 17 | AR19: ='[1]18'!$G$98 -> 78 | AS19: ='[1]18'!$G$99 -> 22 | AT19: ='[1]18'!$G$100 -> 5 | AU19: ='[1]18'!$G$104 -> 0 | AV19: ='[1]18'!$G$105 -> 8 | AW19: ='[1]18'!$G$106 -> 10 | AX19: ='[1]18'!$G$109 -> 60 | AY19: ='[1]18'!$G$110 -> 92 | AZ19: ='[1]18'!$G$111 -> 7 | BA19: ='[1]18'!$G$114 -> 25 | BB19: ='[1]18'!$G$115 -> 5 | BC19: ='[1]18'!$G$116 -> 0 | BD19: ='[1]18'!$G$118 -> 128 | BE19: ='[1]18'!$G$119 -> 134 | BF19: ='[1]18'!$G$120 -> 159 | BG19: ='Section Load'!AJ22 -> 810.475 | BH19: ='Section Load'!AK22 -> 261.28 | BI19: ='Section Load'!AL22 -> 0 | BJ19: ='Section Load'!AM22 -> 73.05 | BK19: ='Section Load'!AN22 -> 16.5 | BL19: ='Section Load'!AO22 -> 1.4 | BM19: ='Section Load'!AP22 -> 458.245
A20: Mumbai | B20: =B19+1 -> 19 | C20: 3 | D20: 2021 | E20: ='Section Load'!B23 -> 3067.2 | F20: ='Section Load'!C23 -> 1459.42 | G20: ='Section Load'!D23 -> 1724.9 | H20: ='Section Load'!E23 -> 4021.53 | I20: ='Section Load'!F23 -> 4813.65 | J20: ='Section Load'!G23 -> 2380.95 | K20: ='Section Load'!H23 -> 1178.96 | L20: ='Section Load'!I23 -> 604.67 | ... AL20: ='Section Load'!AI23 -> 715 | AM20: ='[1]19'!$G$92 -> 95 | AN20: ='[1]19'!$G$93 -> 142 | AO20: ='[1]19'!$G$95 -> 79 | AP20: ='[1]19'!$G$96 -> 9 | AQ20: ='[1]19'!$G$97 -> 24 | AR20: ='[1]19'!$G$98 -> 63 | AS20: ='[1]19'!$G$99 -> 23 | AT20: ='[1]19'!$G$100 -> 6 | AU20: ='[1]19'!$G$104 -> 0 | AV20: ='[1]19'!$G$105 -> 7 | AW20: ='[1]19'!$G$106 -> 6 | AX20: ='[1]19'!$G$109 -> 40 | AY20: ='[1]19'!$G$110 -> 31 | AZ20: ='[1]19'!$G$111 -> 0 | BA20: ='[1]19'!$G$114 -> 26 | BB20: ='[1]19'!$G$115 -> 2 | BC20: ='[1]19'!$G$116 -> 0 | BD20: ='[1]19'!$G$118 -> 145 | BE20: ='[1]19'!$G$119 -> 141 | BF20: ='[1]19'!$G$120 -> 71 | BG20: ='Section Load'!AJ23 -> 806.656 | BH20: ='Section Load'!AK23 -> 244.44 | BI20: ='Section Load'!AL23 -> -0.4 | BJ20: ='Section Load'!AM23 -> 75.65 | BK20: ='Section Load'!AN23 -> 14.3 | BL20: ='Section Load'!AO23 -> 1.6 | BM20: ='Section Load'!AP23 -> 471.066
A21: Mumbai | B21: =B20+1 -> 20 | C21: 3 | D21: 2021 | E21: ='Section Load'!B24 -> 3354 | F21: ='Section Load'!C24 -> 1568.42 | G21: ='Section Load'!D24 -> 1803.91 | H21: ='Section Load'!E24 -> 4428.92 | I21: ='Section Load'!F24 -> 5278.36 | J21: ='Section Load'!G24 -> 2443.92 | K21: ='Section Load'!H24 -> 1405.48 | L21: ='Section Load'!I24 -> 603.14 | ... AL21: ='Section Load'!AI24 -> 686 | AM21: ='[1]20'!$G$92 -> 107 | AN21: ='[1]20'!$G$93 -> 133 | AO21: ='[1]20'!$G$95 -> 86 | AP21: ='[1]20'!$G$96 -> 22 | AQ21: ='[1]20'!$G$97 -> 32 | AR21: ='[1]20'!$G$98 -> 68 | AS21: ='[1]20'!$G$99 -> 21 | AT21: ='[1]20'!$G$100 -> 8 | AU21: ='[1]20'!$G$104 -> 0 | AV21: ='[1]20'!$G$105 -> 13 | AW21: ='[1]20'!$G$106 -> 8 | AX21: ='[1]20'!$G$109 -> 59 | AY21: ='[1]20'!$G$110 -> 75 | AZ21: ='[1]20'!$G$111 -> 20 | BA21: ='[1]20'!$G$114 -> 26 | BB21: ='[1]20'!$G$115 -> 8 | BC21: ='[1]20'!$G$116 -> 0 | BD21: ='[1]20'!$G$118 -> 158 | BE21: ='[1]20'!$G$119 -> 169 | BF21: ='[1]20'!$G$120 -> 154 | BG21: ='Section Load'!AJ24 -> 922.34 | BH21: ='Section Load'!AK24 -> 267.74 | BI21: ='Section Load'!AL24 -> 0 | BJ21: ='Section Load'!AM24 -> 76.88 | BK21: ='Section Load'!AN24 -> 24.2 | BL21: ='Section Load'!AO24 -> 4.5 | BM21: ='Section Load'!AP24 -> 549.02
A22: Mumbai | B22: =B21+1 -> 21 | C22: 3 | D22: 2021 | E22: ='Section Load'!B25 -> 3387.04 | F22: ='Section Load'!C25 -> 1605.37 | G22: ='Section Load'!D25 -> 1861.43 | H22: ='Section Load'!E25 -> 4385.28 | I22: ='Section Load'!F25 -> 5380.737 | J22: ='Section Load'!G25 -> 2440.45 | K22: ='Section Load'!H25 -> 1212.48 | L22: ='Section Load'!I25 -> 605.14 | ... AL22: ='Section Load'!AI25 -> 683 | AM22: ='[1]21'!$G$92 -> 122 | AN22: ='[1]21'!$G$93 -> 110 | AO22: ='[1]21'!$G$95 -> 72 | AP22: ='[1]21'!$G$96 -> 27 | AQ22: ='[1]21'!$G$97 -> 35 | AR22: ='[1]21'!$G$98 -> 87 | AS22: ='[1]21'!$G$99 -> 15 | AT22: ='[1]21'!$G$100 -> 12 | AU22: ='[1]21'!$G$104 -> 0 | AV22: ='[1]21'!$G$105 -> 7 | AW22: ='[1]21'!$G$106 -> 6 | AX22: ='[1]21'!$G$109 -> 60 | AY22: ='[1]21'!$G$110 -> 100 | AZ22: ='[1]21'!$G$111 -> 6 | BA22: ='[1]21'!$G$114 -> 17 | BB22: ='[1]21'!$G$115 -> 9 | BC22: ='[1]21'!$G$116 -> 0 | BD22: ='[1]21'!$G$118 -> 173 | BE22: ='[1]21'!$G$119 -> 161 | BF22: ='[1]21'!$G$120 -> 166 | BG22: ='Section Load'!AJ25 -> 979.97 | BH22: ='Section Load'!AK25 -> 300.25 | BI22: ='Section Load'!AL25 -> 0 | BJ22: ='Section Load'!AM25 -> 73.28 | BK22: ='Section Load'!AN25 -> 29.8 | BL22: ='Section Load'!AO25 -> 2.5 | BM22: ='Section Load'!AP25 -> 574.14
A23: Mumbai | B23: =B22+1 -> 22 | C23: 3 | D23: 2021 | E23: ='Section Load'!B26 -> 3337.84 | F23: ='Section Load'!C26 -> 1553.18 | G23: ='Section Load'!D26 -> 1793.54 | H23: ='Section Load'!E26 -> 4335.4 | I23: ='Section Load'!F26 -> 5689.22 | J23: ='Section Load'!G26 -> 2399.47 | K23: ='Section Load'!H26 -> 1248.44 | L23: ='Section Load'!I26 -> 664.16 | ... AL23: ='Section Load'!AI26 -> 675 | AM23: ='[1]22'!$G$92 -> 122 | AN23: ='[1]22'!$G$93 -> 186 | AO23: ='[1]22'!$G$95 -> 107 | AP23: ='[1]22'!$G$96 -> 21 | AQ23: ='[1]22'!$G$97 -> 17 | AR23: ='[1]22'!$G$98 -> 71 | AS23: ='[1]22'!$G$99 -> 17 | AT23: ='[1]22'!$G$100 -> 8 | AU23: ='[1]22'!$G$104 -> 8 | AV23: ='[1]22'!$G$105 -> 12 | AW23: ='[1]22'!$G$106 -> 5 | AX23: ='[1]22'!$G$109 -> 62 | AY23: ='[1]22'!$G$110 -> 70 | AZ23: ='[1]22'!$G$111 -> 8 | BA23: ='[1]22'!$G$114 -> 21 | BB23: ='[1]22'!$G$115 -> 10 | BC23: ='[1]22'!$G$116 -> 0 | BD23: ='[1]22'!$G$118 -> 173 | BE23: ='[1]22'!$G$119 -> 170 | BF23: ='[1]22'!$G$120 -> 140 | BG23: ='Section Load'!AJ26 -> 949.8 | BH23: ='Section Load'!AK26 -> 281.96 | BI23: ='Section Load'!AL26 -> 0 | BJ23: ='Section Load'!AM26 -> 65.19 | BK23: ='Section Load'!AN26 -> 16.6 | BL23: ='Section Load'!AO26 -> 1.6 | BM23: ='Section Load'!AP26 -> 584.45
A24: Mumbai | B24: =B23+1 -> 23 | C24: 3 | D24: 2021 | E24: ='Section Load'!B27 -> 3280.4 | F24: ='Section Load'!C27 -> 1487.92 | G24: ='Section Load'!D27 -> 1823.23 | H24: ='Section Load'!E27 -> 4120.79 | I24: ='Section Load'!F27 -> 5237.78 | J24: ='Section Load'!G27 -> 2358.53 | K24: ='Section Load'!H27 -> 1181.25 | L24: ='Section Load'!I27 -> 620.89 | ... AL24: ='Section Load'!AI27 -> 708 | AM24: ='[1]23'!$G$92 -> 104 | AN24: ='[1]23'!$G$93 -> 179 | AO24: ='[1]23'!$G$95 -> 101 | AP24: ='[1]23'!$G$96 -> 18 | AQ24: ='[1]23'!$G$97 -> 14 | AR24: ='[1]23'!$G$98 -> 82 | AS24: ='[1]23'!$G$99 -> 12 | AT24: ='[1]23'!$G$100 -> 7 | AU24: ='[1]23'!$G$104 -> 10 | AV24: ='[1]23'!$G$105 -> 13 | AW24: ='[1]23'!$G$106 -> 6 | AX24: ='[1]23'!$G$109 -> 59 | AY24: ='[1]23'!$G$110 -> 89 | AZ24: ='[1]23'!$G$111 -> 5 | BA24: ='[1]23'!$G$114 -> 14 | BB24: ='[1]23'!$G$115 -> 2 | BC24: ='[1]23'!$G$116 -> 0 | BD24: ='[1]23'!$G$118 -> 155 | BE24: ='[1]23'!$G$119 -> 152 | BF24: ='[1]23'!$G$120 -> 153 | BG24: ='Section Load'!AJ27 -> 913.23 | BH24: ='Section Load'!AK27 -> 273.32 | BI24: ='Section Load'!AL27 -> 0 | BJ24: ='Section Load'!AM27 -> 78.52 | BK24: ='Section Load'!AN27 -> 22.8 | BL24: ='Section Load'!AO27 -> 1.5 | BM24: ='Section Load'!AP27 -> 537.09
A25: Mumbai | B25: =B24+1 -> 24 | C25: 3 | D25: 2021 | E25: ='Section Load'!B28 -> 3119 | F25: ='Section Load'!C28 -> 1480.13 | G25: ='Section Load'!D28 -> 1763 | H25: ='Section Load'!E28 -> 4090.53 | I25: ='Section Load'!F28 -> 5174.85 | J25: ='Section Load'!G28 -> 2354 | K25: ='Section Load'!H28 -> 1818 | L25: ='Section Load'!I28 -> 598 | ... AL25: ='Section Load'!AI28 -> 738 | AM25: ='[1]24'!$G$92 -> 88 | AN25: ='[1]24'!$G$93 -> 142 | AO25: ='[1]24'!$G$95 -> 71 | AP25: ='[1]24'!$G$96 -> 13 | AQ25: ='[1]24'!$G$97 -> 18 | AR25: ='[1]24'!$G$98 -> 94 | AS25: ='[1]24'!$G$99 -> 25 | AT25: ='[1]24'!$G$100 -> 13 | AU25: ='[1]24'!$G$104 -> 10 | AV25: ='[1]24'!$G$105 -> 9 | AW25: ='[1]24'!$G$106 -> 5 | AX25: ='[1]24'!$G$109 -> 82 | AY25: ='[1]24'!$G$110 -> 41 | AZ25: ='[1]24'!$G$111 -> 10 | BA25: ='[1]24'!$G$114 -> 30 | BB25: ='[1]24'!$G$115 -> 11 | BC25: ='[1]24'!$G$116 -> 0 | BD25: ='[1]24'!$G$118 -> 140 | BE25: ='[1]24'!$G$119 -> 140 | BF25: ='[1]24'!$G$120 -> 133 | BG25: ='Section Load'!AJ28 -> 296 | BH25: ='Section Load'!AK28 -> 101 | BI25: ='Section Load'!AL28 -> 0 | BJ25: ='Section Load'!AM28 -> 23.58 | BK25: ='Section Load'!AN28 -> 3 | BL25: ='Section Load'!AO28 -> 0 | BM25: ='Section Load'!AP28 -> 168.42
A26: Mumbai | B26: =B25+1 -> 25 | C26: 3 | D26: 2021 | E26: ='Section Load'!B29 -> -1035402 | F26: ='Section Load'!C29 -> -188879 | G26: ='Section Load'!D29 -> -598611 | H26: ='Section Load'!E29 -> -524043 | I26: ='Section Load'!F29 -> -953862 | J26: ='Section Load'!G29 -> -891872 | K26: ='Section Load'!H29 -> -432426 | L26: ='Section Load'!I29 -> -311995 | ... AL26: ='Section Load'!AI29 -> -448965 | AM26: ='[1]25'!$G$92 -> 103 | AN26: ='[1]25'!$G$93 -> 190 | AO26: ='[1]25'!$G$95 -> 103 | AP26: ='[1]25'!$G$96 -> 14 | AQ26: ='[1]25'!$G$97 -> 15 | AR26: ='[1]25'!$G$98 -> 108 | AS26: ='[1]25'!$G$99 -> 16 | AT26: ='[1]25'!$G$100 -> 5 | AU26: ='[1]25'!$G$104 -> 0 | AV26: ='[1]25'!$G$105 -> 6 | AW26: ='[1]25'!$G$106 -> 4 | AX26: ='[1]25'!$G$109 -> 40 | AY26: ='[1]25'!$G$110 -> 148 | AZ26: ='[1]25'!$G$111 -> 0 | BA26: ='[1]25'!$G$114 -> 19 | BB26: ='[1]25'!$G$115 -> 5 | BC26: ='[1]25'!$G$116 -> 0 | BD26: ='[1]25'!$G$118 -> 155 | BE26: ='[1]25'!$G$119 -> 153 | BF26: ='[1]25'!$G$120 -> 188 | BG26: ='Section Load'!AJ29 -> -1640178 | BH26: ='Section Load'!AK29 -> -816987 | BI26: ='Section Load'!AL29 -> -73583 | BJ26: ='Section Load'!AM29 -> -141548.58 | BK26: ='Section Load'!AN29 -> -59823 | BL26: ='Section Load'!AO29 -> -8944 | BM26: ='Section Load'!AP29 -> -539292.42
A27: Mumbai | B27: =B26+1 -> 26 | C27: 3 | D27: 2021 | E27: ='Section Load'!B30 -> 0 | F27: ='Section Load'!C30 -> 0 | G27: ='Section Load'!D30 -> 0 | H27: ='Section Load'!E30 -> 0 | I27: ='Section Load'!F30 -> 0 | J27: ='Section Load'!G30 -> 0 | K27: ='Section Load'!H30 -> 0 | L27: ='Section Load'!I30 -> 0 | ... AL27: ='Section Load'!AI30 -> 0 | AM27: ='[1]26'!$G$92 -> 69 | AN27: ='[1]26'!$G$93 -> 158 | AO27: ='[1]26'!$G$95 -> 79 | AP27: ='[1]26'!$G$96 -> 12 | AQ27: ='[1]26'!$G$97 -> 19 | AR27: ='[1]26'!$G$98 -> 129 | AS27: ='[1]26'!$G$99 -> 13 | AT27: ='[1]26'!$G$100 -> 12 | AU27: ='[1]26'!$G$104 -> 3 | AV27: ='[1]26'!$G$105 -> 9 | AW27: ='[1]26'!$G$106 -> 6 | AX27: ='[1]26'!$G$109 -> 60 | AY27: ='[1]26'!$G$110 -> 123 | AZ27: ='[1]26'!$G$111 -> 12 | BA27: ='[1]26'!$G$114 -> 16 | BB27: ='[1]26'!$G$115 -> 6 | BC27: ='[1]26'!$G$116 -> 0 | BD27: ='[1]26'!$G$118 -> 120 | BE27: ='[1]26'!$G$119 -> 135 | BF27: ='[1]26'!$G$120 -> 195 | BG27: ='Section Load'!AJ30 -> 0 | BH27: ='Section Load'!AK30 -> 0 | BI27: ='Section Load'!AL30 -> 0 | BJ27: ='Section Load'!AM30 -> 0 | BK27: ='Section Load'!AN30 -> 0 | BL27: ='Section Load'!AO30 -> 0 | BM27: ='Section Load'!AP30 -> 0
A28: Mumbai | B28: =B27+1 -> 27 | C28: 3 | D28: 2021 | E28: ='Section Load'!B31 -> 0 | F28: ='Section Load'!C31 -> 0 | G28: ='Section Load'!D31 -> 0 | H28: ='Section Load'!E31 -> 0 | I28: ='Section Load'!F31 -> 0 | J28: ='Section Load'!G31 -> 0 | K28: ='Section Load'!H31 -> 0 | L28: ='Section Load'!I31 -> 0 | ... AL28: ='Section Load'!AI31 -> 0 | AM28: ='[1]27'!$G$92 -> 146 | AN28: ='[1]27'!$G$93 -> 152 | AO28: ='[1]27'!$G$95 -> 85 | AP28: ='[1]27'!$G$96 -> 16 | AQ28: ='[1]27'!$G$97 -> 31 | AR28: ='[1]27'!$G$98 -> 62 | AS28: ='[1]27'!$G$99 -> 19 | AT28: ='[1]27'!$G$100 -> 34 | AU28: ='[1]27'!$G$104 -> 0 | AV28: ='[1]27'!$G$105 -> 8 | AW28: ='[1]27'!$G$106 -> 6 | AX28: ='[1]27'!$G$109 -> 82 | AY28: ='[1]27'!$G$110 -> 95 | AZ28: ='[1]27'!$G$111 -> 7 | BA28: ='[1]27'!$G$114 -> 22 | BB28: ='[1]27'!$G$115 -> 25 | BC28: ='[1]27'!$G$116 -> 0 | BD28: ='[1]27'!$G$118 -> 200 | BE28: ='[1]27'!$G$119 -> 185 | BF28: ='[1]27'!$G$120 -> 184 | BG28: ='Section Load'!AJ31 -> 0 | BH28: ='Section Load'!AK31 -> 0 | BI28: ='Section Load'!AL31 -> 0 | BJ28: ='Section Load'!AM31 -> 0 | BK28: ='Section Load'!AN31 -> 0 | BL28: ='Section Load'!AO31 -> 0 | BM28: ='Section Load'!AP31 -> 0
A29: Mumbai | B29: =B28+1 -> 28 | C29: 3 | D29: 2021 | E29: ='Section Load'!B32 -> 0 | F29: ='Section Load'!C32 -> 0 | G29: ='Section Load'!D32 -> 0 | H29: ='Section Load'!E32 -> 0 | I29: ='Section Load'!F32 -> 0 | J29: ='Section Load'!G32 -> 0 | K29: ='Section Load'!H32 -> 0 | L29: ='Section Load'!I32 -> 0 | ... AL29: ='Section Load'!AI32 -> 0 | AM29: ='[1]28'!$G$92 -> 144 | AN29: ='[1]28'!$G$93 -> 201 | AO29: ='[1]28'!$G$95 -> 90 | AP29: ='[1]28'!$G$96 -> 40 | AQ29: ='[1]28'!$G$97 -> 30 | AR29: ='[1]28'!$G$98 -> 69 | AS29: ='[1]28'!$G$99 -> 27 | AT29: ='[1]28'!$G$100 -> 32 | AU29: ='[1]28'!$G$104 -> 0 | AV29: ='[1]28'!$G$105 -> 9 | AW29: ='[1]28'!$G$106 -> 6 | AX29: ='[1]28'!$G$109 -> 61 | AY29: ='[1]28'!$G$110 -> 49 | AZ29: ='[1]28'!$G$111 -> 0 | BA29: ='[1]28'!$G$114 -> 32 | BB29: ='[1]28'!$G$115 -> 23 | BC29: ='[1]28'!$G$116 -> 0 | BD29: ='[1]28'!$G$118 -> 196 | BE29: ='[1]28'!$G$119 -> 219 | BF29: ='[1]28'!$G$120 -> 110 | BG29: ='Section Load'!AJ32 -> 0 | BH29: ='Section Load'!AK32 -> 0 | BI29: ='Section Load'!AL32 -> 0 | BJ29: ='Section Load'!AM32 -> 0 | BK29: ='Section Load'!AN32 -> 0 | BL29: ='Section Load'!AO32 -> 0 | BM29: ='Section Load'!AP32 -> 0
A30: Mumbai | B30: =B29+1 -> 29 | C30: 3 | D30: 2021 | E30: ='Section Load'!B33 -> 0 | F30: ='Section Load'!C33 -> 0 | G30: ='Section Load'!D33 -> 0 | H30: ='Section Load'!E33 -> 0 | I30: ='Section Load'!F33 -> 7.92 | J30: ='Section Load'!G33 -> 0 | K30: ='Section Load'!H33 -> 0 | L30: ='Section Load'!I33 -> 0 | ... AL30: ='Section Load'!AI33 -> 0 | AM30: ='[1]28'!$G$92 -> 144 | AN30: ='[1]28'!$G$93 -> 201 | AO30: ='[1]28'!$G$95 -> 90 | AP30: ='[1]28'!$G$96 -> 40 | AQ30: ='[1]28'!$G$97 -> 30 | AR30: ='[1]28'!$G$98 -> 69 | AS30: ='[1]28'!$G$99 -> 27 | AT30: ='[1]28'!$G$100 -> 32 | AU30: ='[1]28'!$G$104 -> 0 | AV30: ='[1]28'!$G$105 -> 9 | AW30: ='[1]28'!$G$106 -> 6 | AX30: ='[1]28'!$G$109 -> 61 | AY30: ='[1]28'!$G$110 -> 49 | AZ30: ='[1]28'!$G$111 -> 0 | BA30: ='[1]28'!$G$114 -> 32 | BB30: ='[1]28'!$G$115 -> 23 | BC30: ='[1]28'!$G$116 -> 0 | BD30: ='[1]28'!$G$118 -> 196 | BE30: ='[1]28'!$G$119 -> 219 | BF30: ='[1]28'!$G$120 -> 110 | BG30: ='Section Load'!AJ33 -> 0 | BH30: ='Section Load'!AK33 -> 0 | BI30: ='Section Load'!AL33 -> 0 | BJ30: ='Section Load'!AM33 -> 0 | BK30: ='Section Load'!AN33 -> 0 | BL30: ='Section Load'!AO33 -> 0 | BM30: ='Section Load'!AP33 -> 0
A31: Mumbai | B31: =B30+1 -> 30 | C31: 3 | D31: 2021 | E31: ='Section Load'!B34 -> 0 | F31: ='Section Load'!C34 -> 0 | G31: ='Section Load'!D34 -> 0 | H31: ='Section Load'!E34 -> 0 | I31: ='Section Load'!F34 -> 0 | J31: ='Section Load'!G34 -> 0 | K31: ='Section Load'!H34 -> 0 | L31: ='Section Load'!I34 -> 0 | ... AL31: ='Section Load'!AI34 -> 0 | AM31: ='[1]28'!$G$92 -> 144 | AN31: ='[1]28'!$G$93 -> 201 | AO31: ='[1]28'!$G$95 -> 90 | AP31: ='[1]28'!$G$96 -> 40 | AQ31: ='[1]28'!$G$97 -> 30 | AR31: ='[1]28'!$G$98 -> 69 | AS31: ='[1]28'!$G$99 -> 27 | AT31: ='[1]28'!$G$100 -> 32 | AU31: ='[1]28'!$G$104 -> 0 | AV31: ='[1]28'!$G$105 -> 9 | AW31: ='[1]28'!$G$106 -> 6 | AX31: ='[1]28'!$G$109 -> 61 | AY31: ='[1]28'!$G$110 -> 49 | AZ31: ='[1]28'!$G$111 -> 0 | BA31: ='[1]28'!$G$114 -> 32 | BB31: ='[1]28'!$G$115 -> 23 | BC31: ='[1]28'!$G$116 -> 0 | BD31: ='[1]28'!$G$118 -> 196 | BE31: ='[1]28'!$G$119 -> 219 | BF31: ='[1]28'!$G$120 -> 110 | BG31: ='Section Load'!AJ34 -> 0 | BH31: ='Section Load'!AK34 -> 0 | BI31: ='Section Load'!AL34 -> 0 | BJ31: ='Section Load'!AM34 -> 0 | BK31: ='Section Load'!AN34 -> 0 | BL31: ='Section Load'!AO34 -> 0 | BM31: ='Section Load'!AP34 -> 0
A32: Mumbai | B32: =B31+1 -> 31 | C32: 3 | D32: 2021 | E32: ='Section Load'!B35 -> 0 | F32: ='Section Load'!C35 -> 0 | G32: ='Section Load'!D35 -> 0 | H32: ='Section Load'!E35 -> 0 | I32: ='Section Load'!F35 -> 0 | J32: ='Section Load'!G35 -> 0 | K32: ='Section Load'!H35 -> 0 | L32: ='Section Load'!I35 -> 0 | ... AL32: ='Section Load'!AI35 -> 0 | AM32: ='[1]28'!$G$92 -> 144 | AN32: ='[1]28'!$G$93 -> 201 | AO32: ='[1]28'!$G$95 -> 90 | AP32: ='[1]28'!$G$96 -> 40 | AQ32: ='[1]28'!$G$97 -> 30 | AR32: ='[1]28'!$G$98 -> 69 | AS32: ='[1]28'!$G$99 -> 27 | AT32: ='[1]28'!$G$100 -> 32 | AU32: ='[1]28'!$G$104 -> 0 | AV32: ='[1]28'!$G$105 -> 9 | AW32: ='[1]28'!$G$106 -> 6 | AX32: ='[1]28'!$G$109 -> 61 | AY32: ='[1]28'!$G$110 -> 49 | AZ32: ='[1]28'!$G$111 -> 0 | BA32: ='[1]28'!$G$114 -> 32 | BB32: ='[1]28'!$G$115 -> 23 | BC32: ='[1]28'!$G$116 -> 0 | BD32: ='[1]28'!$G$118 -> 196 | BE32: ='[1]28'!$G$119 -> 219 | BF32: ='[1]28'!$G$120 -> 110 | BG32: ='Section Load'!AJ35 -> 0 | BH32: ='Section Load'!AK35 -> 0 | BI32: ='Section Load'!AL35 -> 0 | BJ32: ='Section Load'!AM35 -> 0 | BK32: ='Section Load'!AN35 -> 0 | BL32: ='Section Load'!AO35 -> 0 | BM32: ='Section Load'!AP35 -> 0

Sheet Daily HLP
A2: Date | B2: Date | C2: Min.Tem (Degee) | D2: Avg.Temp (Degree) | E2: Hum % | F2: Occu. | G2: KWAH | I2: Electricity | M2: Gas | P2: Water | S2: Water per occiped room | T2: Diesel | W2: Water Consumption Zone | AA2: Chiller Running Hrs | AF2: Chiller Total | AG2: Chiller Avg. Laod | AH2: Boiler Running Hrs | AK2: Total boiler | AL2: Hot Water Generator | AO2: Total HWG RH | AP2: HWG Gas consumption | AQ2: Transformer -1 | BA2: Transformer -2 | BO2: Total HLP Cost | BQ2: Chiller lock at 70%
F3: % | H3: KVAH | I3: Units (Kwh) | J3: Rate | K3: Total Cost(Rs) | L3: Per room | M3: Total Units(CuM) | N3: Rate | O3: Total Cost(Rs) | P3: Units(KL) | Q3: Rate | R3: Total Cost(Rs) | T3: Ltrs | U3: Rate | V3: Total Cost(Rs) | W3: Zone-1 | X3: Zone-2 | Y3: Zone-3 | AA3: CH1 | AB3: CH2 | AC3: CH3 | AD3: CH4 | AE3: Total chiller | AH3: Boiler1 | AI3: Boiler2 | AJ3: Boiler3 | AL3: HWG1 | AM3: HWG2 | AQ3: HVAC-1 | AR3: FPP-1 | AS3: MPP | AT3: Lighting-1 | AU3: Cap bank 1100KVAR-1 | AV3: CH-1 | AW3: CH-2 | AX3: Chilled water Pump | AY3: Co Generator | AZ3: Ball Room-2 | BA3: HVAC-2 | BB3: FPP-2 | BC3: MPP | BD3: Lighting-2 | BE3: Cap bank 1200KVAR-2 | BF3: CH-3 | BG3: CH-4 | BH3: Chilled water Pump | BI3: Ball Room-1 | BK3: Cooling Tower consumption | BL3: HVAC% | BM3: Lighting% | BN3: Power% | BP3: Chiller Plant IKW
A4: 1 | B4: 1 | D4: ='1'!D3 -> 25 | E4: ='1'!D4 -> 0.8 | F4: ='1'!D2 -> 0.47 | G4: ='1'!G8 -> 22554 | H4: ='1'!G8 -> 22554 | I4: ='1'!G7 -> 22397 | J4: ='1'!F27 -> 9 | K4: =H4*J4 -> 202986 | L4: =I4/202 -> 110.87624 | M4: ='1'!G15 -> 880.632 | N4: 35 | O4: =M4*N4 -> 30822.12 | P4: ='1'!G20 -> 228 | Q4: 134 | R4: =P4*Q4 -> 30552 | S4: =P4/(F4*202/100) -> 240.15167 | T4: ='1'!G24 -> 0 | U4: 69 | V4: =T4*U4 -> 0 | W4: ='1'!G95 -> 76 | X4: ='1'!G96 -> 13 | Y4: ='1'!G97 -> 24 | Z4: =W4+X4+Y4 -> 113 | AA4: ='1'!G132 -> 0 | AB4: ='1'!G133 -> 0 | AC4: ='1'!G134 -> 24 | AD4: ='1'!G135 -> 3.44 | AE4: =AA4+AB4+AC4+AD4 -> 27.44 | AF4: =AV4+AW4+BF4+BG4 -> 5749.65 | AG4: =AF4/AE4 -> 209.53535 | AH4: ='1'!G136 -> 8.77 | AI4: ='1'!G137 -> 0 | AJ4: ='1'!G138 -> 5.37 | AK4: =AH4+AI4+AJ4 -> 14.14 | AL4: ='1'!G139 -> 7.71 | AM4: ='1'!G140 -> -0.47 | AO4: =AL4+AM4 -> 7.24 | AP4: ='1'!G123 -> 266.26 | AQ4: ='1'!G35 -> 3193.12 | AR4: ='1'!G37 -> 1450.45 | AS4: ='1'!G38 -> 2140.42 | AT4: ='1'!G39 -> 4328.8 | AU4: ='1'!G40 -> 0 | AV4: ='1'!G41 -> 0 | AW4: ='1'!G42 -> 0 | AX4: ='1'!G43 -> 2455.36 | AY4: ='1'!G44 -> 0 | AZ4: ='1'!G36 -> 759.24 | BA4: ='1'!G49 -> 0 | BB4: ='1'!G51 -> 0 | BC4: ='1'!G52 -> 0 | BD4: ='1'!G53 -> 0 | BE4: ='1'!G54 -> 68.19 | BF4: ='1'!G55 -> 5092.77 | BG4: ='1'!G56 -> 656.88 | BH4: ='1'!G57 -> 0 | BI4: ='1'!G50 -> 1635.92 | BJ4: =SUM(AV4,AW4,BF4,BG4) -> 5749.65 | BK4: ='1'!G84 -> 690 | BL4: =SUM(AQ4,AV4,AW4,AX4,BA4,BF4,BG4,BH4)/I4% -> 50.891325 | BM4: =SUM(AT4,BD4)/I4% -> 19.327589 | BN4: =(AS4+BC4)/I4 -> 0.095567263 | BO4: =K4+O4+R4+V4 -> 264360.12 | BP4: =SUM(AV4,AW4,AX4,BF4,BG4,BH4,BK4) -> 8895.01 | BQ4: =BP4/(AE4*280) -> 1.157722 | BR4: =SUM(AV4,AW4,BF4,BG4)/(AE4*400) -> 0.52383837
A5: 2 | B5: 2 | D5: ='2'!D3 -> 27 | E5: ='2'!D4 -> 0.75 | F5: ='2'!D2 -> 0.48 | G5: ='2'!G8 -> 22596 | H5: ='2'!G8 -> 22596 | I5: ='2'!G7 -> 22379 | J5: 10 | K5: =H5*J5 -> 225960 | L5: =I5/202 -> 110.78713 | M5: ='2'!G15 -> 993.178 | N5: 35 | O5: =M5*N5 -> 34761.23 | P5: ='2'!G20 -> 192 | Q5: 134 | R5: =P5*Q5 -> 25728 | S5: =P5/(F5*202/100) -> 198.0198 | T5: ='2'!G24 -> 0 | U5: 69 | V5: =T5*U5 -> 0 | W5: ='2'!G95 -> 85 | X5: ='2'!G96 -> 18 | Y5: ='2'!G97 -> 19 | Z5: =W5+X5+Y5 -> 122 | AA5: ='2'!G132 -> 0 | AB5: ='2'!G133 -> 0 | AC5: ='2'!G134 -> 19 | AD5: ='2'!G135 -> 7.65 | AE5: =AA5+AB5+AC5+AD5 -> 26.65 | AF5: =AV5+AW5+BF5+BG5 -> 5632.661 | AG5: =AF5/AE5 -> 211.35689 | AH5: ='2'!G136 -> 8.84 | AI5: ='2'!G137 -> 0 | AJ5: ='2'!G138 -> 6.64 | AK5: =AH5+AI5+AJ5 -> 15.48 | AL5: ='2'!G139 -> 8.06 | AM5: ='2'!G140 -> 0.47 | AO5: =AL5+AM5 -> 8.53 | AP5: ='2'!G123 -> 278.29 | AQ5: ='2'!G35 -> 3503.76 | AR5: ='2'!G37 -> 1456.84 | AS5: ='2'!G38 -> 2089.51 | AT5: ='2'!G39 -> 4368.93 | AU5: ='2'!G40 -> 0 | AV5: ='2'!G41 -> 0 | AW5: ='2'!G42 -> 0.001 | AX5: ='2'!G43 -> 2485.52 | AY5: ='2'!G44 -> 0 | AZ5: ='2'!G36 -> 669.28 | BA5: ='2'!G49 -> 0 | BB5: ='2'!G51 -> 0 | BC5: ='2'!G52 -> 0 | BD5: ='2'!G53 -> 0 | BE5: ='2'!G54 -> 36.21 | BF5: ='2'!G55 -> 3791.54 | BG5: ='2'!G56 -> 1841.12 | BH5: ='2'!G57 -> 0 | BI5: ='2'!G50 -> 1600.36 | BJ5: =SUM(AV5,AW5,BF5,BG5) -> 5632.661 | BK5: ='2'!G84 -> 727 | BL5: =SUM(AQ5,AV5,AW5,AX5,BA5,BF5,BG5,BH5)/I5% -> 51.932352 | BM5: =SUM(AT5,BD5)/I5% -> 19.522454 | BN5: =(AS5+BC5)/I5 -> 0.09336923 | BO5: =K5+O5+R5+V5 -> 286449.23 | BP5: =SUM(AV5,AW5,AX5,BF5,BG5,BH5,BK5) -> 8845.181 | BQ5: =BP5/(AE5*280) -> 1.1853633
A6: 3 | B6: 3 | D6: ='3'!D3 -> 27 | E6: ='3'!D4 -> 0.75 | F6: ='3'!D2 -> 0.4352 | G6: ='3'!G8 -> 21194 | H6: ='3'!G8 -> 21194 | I6: ='3'!G7 -> 21109 | J6: 10 | K6: =H6*J6 -> 211940 | L6: =I6/202 -> 104.5 | M6: ='3'!G15 -> 830.41 | N6: 35 | O6: =M6*N6 -> 29064.35 | P6: ='3'!G20 -> 192 | Q6: 134 | R6: =P6*Q6 -> 25728 | S6: =P6/(F6*202/100) -> 218.40419 | T6: ='3'!G24 -> 0 | U6: 69 | V6: =T6*U6 -> 0 | W6: ='3'!G95 -> 76 | X6: ='3'!G96 -> 17 | Y6: ='3'!G97 -> 16 | Z6: =W6+X6+Y6 -> 109 | AA6: ='3'!G132 -> 0 | AB6: ='3'!G133 -> -0.48 | AC6: ='3'!G134 -> 24.06 | AD6: ='3'!G135 -> 0 | AE6: =AA6+AB6+AC6+AD6 -> 23.58 | AF6: =AV6+AW6+BF6+BG6 -> 4924.529 | AG6: =AF6/AE6 -> 208.84347 | AH6: ='3'!G136 -> 8.53 | AI6: ='3'!G137 -> 0 | AJ6: ='3'!G138 -> 5.46 | AK6: =AH6+AI6+AJ6 -> 13.99 | AL6: ='3'!G139 -> 7.06 | AM6: ='3'!G140 -> 0 | AO6: =AL6+AM6 -> 7.06 | AP6: ='3'!G123 -> 245.65 | AQ6: ='3'!G35 -> 3426.88 | AR6: ='3'!G37 -> 197.79 | AS6: ='3'!G38 -> 290.09 | AT6: ='3'!G39 -> 695.16 | AU6: ='3'!G40 -> 0 | AV6: ='3'!G41 -> 0 | AW6: ='3'!G42 -> -0.001 | AX6: ='3'!G43 -> 2463.82 | AY6: ='3'!G44 -> 0 | AZ6: ='3'!G36 -> 626.42 | BA6: ='3'!G49 -> 0 | BB6: ='3'!G51 -> 1271.7 | BC6: ='3'!G52 -> 1881.96 | BD6: ='3'!G53 -> 3661.26 | BE6: ='3'!G54 -> -0.03 | BF6: ='3'!G55 -> 4916.61 | BG6: ='3'!G56 -> 7.92 | BH6: ='3'!G57 -> 0 | BI6: ='3'!G50 -> 1065.36 | BJ6: =SUM(AV6,AW6,BF6,BG6) -> 4924.529 | BK6: ='3'!G84 -> 553 | BL6: =SUM(AQ6,AV6,AW6,AX6,BA6,BF6,BG6,BH6)/I6% -> 51.235156 | BM6: =SUM(AT6,BD6)/I6% -> 20.637737 | BN6: =(AS6+BC6)/I6 -> 0.10289687 | BO6: =K6+O6+R6+V6 -> 266732.35 | BP6: =SUM(AV6,AW6,AX6,BF6,BG6,BH6,BK6) -> 7941.349 | BQ6: =BP6/(AE6*280) -> 1.2027973
A7: 4 | B7: 4 | D7: ='4'!D3 -> 28 | E7: ='4'!D4 -> 0.78 | F7: ='4'!D2 -> 0.45 | G7: ='4'!G8 -> 19927 | H7: ='4'!G8 -> 19927 | I7: ='4'!G7 -> 19792 | J7: 10 | K7: =H7*J7 -> 199270 | L7: =I7/202 -> 97.980198 | M7: ='4'!G15 -> 884.17 | N7: 35 | O7: =M7*N7 -> 30945.95 | P7: ='4'!G20 -> 192 | Q7: 134 | R7: =P7*Q7 -> 25728 | S7: =P7/(F7*202/100) -> 211.22112 | T7: ='4'!G24 -> 0 | U7: 69 | V7: =T7*U7 -> 0 | W7: ='4'!G95 -> 98 | X7: ='4'!G96 -> 10 | Y7: ='4'!G97 -> 16 | Z7: =W7+X7+Y7 -> 124 | AA7: ='4'!G132 -> 0 | AB7: ='4'!G133 -> 0.48 | AC7: ='4'!G134 -> 23.8 | AD7: ='4'!G135 -> -0.09 | AE7: =AA7+AB7+AC7+AD7 -> 24.19 | AF7: =AV7+AW7+BF7+BG7 -> 4227.22 | AG7: =AF7/AE7 -> 174.75072 | AH7: ='4'!G136 -> 8.08 | AI7: ='4'!G137 -> 0 | AJ7: ='4'!G138 -> 3.19 | AK7: =AH7+AI7+AJ7 -> 11.27 | AL7: ='4'!G139 -> 7.03 | AM7: ='4'!G140 -> 0 | AO7: =AL7+AM7 -> 7.03 | AP7: ='4'!G123 -> 244.96 | AQ7: ='4'!G35 -> 3260.65 | AR7: ='4'!G37 -> 0 | AS7: ='4'!G38 -> 0.49 | AT7: ='4'!G39 -> 0 | AU7: ='4'!G40 -> 0 | AV7: ='4'!G41 -> -0.37 | AW7: ='4'!G42 -> 0.15 | AX7: ='4'!G43 -> 2461.47 | AY7: ='4'!G44 -> 0 | AZ7: ='4'!G36 -> 622.49 | BA7: ='4'!G49 -> -0.13 | BB7: ='4'!G51 -> 1488.38 | BC7: ='4'!G52 -> 2010.33 | BD7: ='4'!G53 -> 4163.23 | BE7: ='4'!G54 -> 0 | BF7: ='4'!G55 -> 4227.39 | BG7: ='4'!G56 -> 0.05 | BH7: ='4'!G57 -> -0.33 | BI7: ='4'!G50 -> 1029.33 | BJ7: =SUM(AV7,AW7,BF7,BG7) -> 4227.22 | BK7: ='3'!G84 -> 553 | BL7: =SUM(AQ7,AV7,AW7,AX7,BA7,BF7,BG7,BH7)/I7% -> 50.267179 | BM7: =SUM(AT7,BD7)/I7% -> 21.034913 | BN7: =(AS7+BC7)/I7 -> 0.10159762 | BO7: =K7+O7+R7+V7 -> 255943.95 | BP7: =SUM(AV7,AW7,AX7,BF7,BG7,BH7,BK7) -> 7241.36 | BQ7: =BP7/(AE7*280) -> 1.0691195
A8: 5 | B8: 5 | D8: ='5'!D3 -> 28 | E8: ='5'!D4 -> 0.78 | F8: ='5'!D2 -> 0.48 | G8: ='5'!G8 -> 20535 | H8: ='5'!G8 -> 20535 | I8: ='5'!G7 -> 20391 | J8: 10 | K8: =H8*J8 -> 205350 | L8: =I8/202 -> 100.94554 | M8: ='5'!G15 -> 893.64 | N8: 35 | O8: =M8*N8 -> 31277.4 | P8: ='5'!G20 -> 191 | Q8: 134 | R8: =P8*Q8 -> 25594 | S8: =P8/(F8*202/100) -> 196.98845 | T8: ='5'!G24 -> 0 | U8: 69 | V8: =T8*U8 -> 0 | W8: ='5'!G95 -> 83 | X8: ='5'!G96 -> 11 | Y8: ='5'!G97 -> 11 | Z8: =W8+X8+Y8 -> 105 | AA8: ='5'!G132 -> 386 | AB8: ='5'!G133 -> -1 | AC8: ='5'!G134 -> 24 | AD8: ='5'!G135 -> -0.45 | AE8: =AA8+AB8+AC8+AD8 -> 408.55 | AF8: =AV8+AW8+BF8+BG8 -> 4900.74 | AG8: =AF8/AE8 -> 11.995447 | AH8: ='5'!G136 -> 9.25 | AI8: ='5'!G137 -> -0.31 | AJ8: ='5'!G138 -> 5 | AK8: =AH8+AI8+AJ8 -> 13.94 | AL8: ='5'!G139 -> 7 | AM8: ='5'!G140 -> 0 | AO8: =AL8+AM8 -> 7 | AP8: ='5'!G123 -> 245 | AQ8: ='5'!G35 -> 3368 | AR8: ='5'!G37 -> 35167 | AS8: ='5'!G38 -> -1 | AT8: ='5'!G39 -> 100066 | AU8: ='5'!G40 -> 0 | AV8: ='5'!G41 -> -0.26 | AW8: ='5'!G42 -> -1 | AX8: ='5'!G43 -> 2387 | AY8: ='5'!G44 -> 0 | AZ8: ='5'!G36 -> 577 | BA8: ='5'!G49 -> 0 | BB8: ='5'!G51 -> 1492 | BC8: ='5'!G52 -> 1823 | BD8: ='5'!G53 -> 4265 | BE8: ='5'!G54 -> 0 | BF8: ='5'!G55 -> 4924 | BG8: ='5'!G56 -> -22 | BH8: ='5'!G57 -> 0 | BI8: ='5'!G50 -> 1011 | BJ8: =SUM(AV8,AW8,BF8,BG8) -> 4900.74 | BK8: ='5'!G84 -> 954 | BL8: =SUM(AQ8,AV8,AW8,AX8,BA8,BF8,BG8,BH8)/I8% -> 52.257074 | BM8: =SUM(AT8,BD8)/I8% -> 511.6522 | BN8: =(AS8+BC8)/I8 -> 0.089353146 | BO8: =K8+O8+R8+V8 -> 262221.4 | BP8: =SUM(AV8,AW8,AX8,BF8,BG8,BH8,BK8) -> 8241.74 | BQ8: =BP8/(AE8*280) -> 0.072046961
A9: 6 | B9: 6 | D9: ='6'!D3 -> 29 | E9: ='6'!D4 -> 0.8 | F9: ='6'!D2 -> 0.8 | G9: ='6'!G8 -> 21971 | H9: ='6'!G8 -> 21971 | I9: ='6'!G7 -> 21871 | J9: 10 | K9: =H9*J9 -> 219710 | L9: =I9/202 -> 108.27228 | M9: ='6'!G15 -> 944.36 | N9: 35 | O9: =M9*N9 -> 33052.6 | P9: ='6'!G20 -> 191 | Q9: 134 | R9: =P9*Q9 -> 25594 | S9: =P9/(F9*202/100) -> 118.19307 | T9: ='6'!G24 -> 0 | U9: 69 | V9: =T9*U9 -> 0 | W9: ='6'!G95 -> 120 | X9: ='6'!G96 -> 21 | Y9: ='6'!G97 -> 25 | Z9: =W9+X9+Y9 -> 166 | AA9: ='6'!G132 -> 0 | AB9: ='6'!G133 -> 0 | AC9: ='6'!G134 -> 24 | AD9: ='6'!G135 -> 1.01 | AE9: =AA9+AB9+AC9+AD9 -> 25.01 | AF9: =AV9+AW9+BF9+BG9 -> 5904 | AG9: =AF9/AE9 -> 236.06557 | AH9: ='6'!G136 -> 8.32 | AI9: ='6'!G137 -> 0 | AJ9: ='6'!G138 -> 6 | AK9: =AH9+AI9+AJ9 -> 14.32 | AL9: ='6'!G139 -> 8 | AM9: ='6'!G140 -> 0 | AO9: =AL9+AM9 -> 8 | AP9: ='6'!G123 -> 264 | AQ9: ='6'!G35 -> 3484 | AR9: ='6'!G37 -> 0 | AS9: ='6'!G38 -> 0 | AT9: ='6'!G39 -> 0 | AU9: ='6'!G40 -> 0 | AV9: ='6'!G41 -> 0 | AW9: ='6'!G42 -> 0 | AX9: ='6'!G43 -> 2437 | AY9: ='6'!G44 -> 0 | AZ9: ='6'!G36 -> 624 | BA9: ='6'!G49 -> 0 | BB9: ='6'!G51 -> 1518 | BC9: ='6'!G52 -> 2123 | BD9: ='6'!G53 -> 4237 | BE9: ='6'!G54 -> 0 | BF9: ='6'!G55 -> 5678 | BG9: ='6'!G56 -> 226 | BH9: ='6'!G57 -> 0 | BI9: ='6'!G50 -> 1043 | BJ9: =SUM(AV9,AW9,BF9,BG9) -> 5904 | BK9: ='6'!G84 -> 644 | BL9: =SUM(AQ9,AV9,AW9,AX9,BA9,BF9,BG9,BH9)/I9% -> 54.067029 | BM9: =SUM(AT9,BD9)/I9% -> 19.372685 | BN9: =(AS9+BC9)/I9 -> 0.097069178 | BO9: =K9+O9+R9+V9 -> 278356.6 | BP9: =SUM(AV9,AW9,AX9,BF9,BG9,BH9,BK9) -> 8985 | BQ9: =BP9/(AE9*280) -> 1.2830582
A10: 7 | B10: 7 | D10: ='7'!D3 -> 29 | E10: ='7'!D4 -> 0.82 | F10: ='7'!D2 -> 0.51 | G10: ='7'!G8 -> 21681 | H10: ='7'!G8 -> 21681 | I10: ='7'!G7 -> 21611 | J10: 10 | K10: =H10*J10 -> 216810 | L10: =I10/202 -> 106.98515 | M10: ='7'!G15 -> 931 | N10: 35 | O10: =M10*N10 -> 32585 | P10: ='7'!G20 -> 251 | Q10: 134 | R10: =P10*Q10 -> 33634 | S10: =P10/(F10*202/100) -> 243.64201 | T10: ='7'!G24 -> 0 | U10: 69 | V10: =T10*U10 -> 0 | W10: ='7'!G95 -> 119 | X10: ='7'!G96 -> 32 | Y10: ='7'!G97 -> 28 | Z10: =W10+X10+Y10 -> 179 | AA10: ='7'!G132 -> 0 | AB10: ='7'!G133 -> 0 | AC10: ='7'!G134 -> 24 | AD10: ='7'!G135 -> 0 | AE10: =AA10+AB10+AC10+AD10 -> 24 | AF10: =AV10+AW10+BF10+BG10 -> 5494 | AG10: =AF10/AE10 -> 228.91667 | AH10: ='7'!G136 -> 9.92 | AI10: ='7'!G137 -> 0 | AJ10: ='7'!G138 -> 3 | AK10: =AH10+AI10+AJ10 -> 12.92 | AL10: ='7'!G139 -> 8 | AM10: ='7'!G140 -> 0 | AO10: =AL10+AM10 -> 8 | AP10: ='7'!G123 -> 275 | AQ10: ='7'!G35 -> 3319 | AR10: ='7'!G37 -> 0 | AS10: ='7'!G38 -> 0 | AT10: ='7'!G39 -> 0 | AU10: ='7'!G40 -> 0 | AV10: ='7'!G41 -> 0 | AW10: ='7'!G42 -> 0 | AX10: ='7'!G43 -> 2417 | AY10: ='7'!G44 -> 0 | AZ10: ='7'!G36 -> 611 | BA10: ='7'!G49 -> 0 | BB10: ='7'!G51 -> 1500 | BC10: ='7'!G52 -> 2331 | BD10: ='7'!G53 -> 4230 | BE10: ='7'!G54 -> 0 | BF10: ='7'!G55 -> 5494 | BG10: ='7'!G56 -> 0 | BH10: ='7'!G57 -> 0 | BI10: ='7'!G50 -> 1230 | BJ10: =SUM(AV10,AW10,BF10,BG10) -> 5494 | BK10: ='7'!G84 -> 834 | BL10: =SUM(AQ10,AV10,AW10,AX10,BA10,BF10,BG10,BH10)/I10% -> 51.964277 | BM10: =SUM(AT10,BD10)/I10% -> 19.573365 | BN10: =(AS10+BC10)/I10 -> 0.10786174 | BO10: =K10+O10+R10+V10 -> 283029 | BP10: =SUM(AV10,AW10,AX10,BF10,BG10,BH10,BK10) -> 8745 | BQ10: =BP10/(AE10*280) -> 1.3013393
A11: 8 | B11: 8 | D11: ='8'!D3 -> 27 | E11: ='8'!D4 -> 0.78 | F11: ='8'!D2 -> 0.41 | G11: ='8'!G8 -> 22672 | H11: ='8'!G8 -> 22672 | I11: ='8'!G7 -> 22521 | J11: 10 | K11: =H11*J11 -> 226720 | L11: =I11/202 -> 111.4901 | M11: ='8'!G15 -> 859.85 | N11: 35 | O11: =M11*N11 -> 30094.75 | P11: ='8'!G20 -> 193 | Q11: 134 | R11: =P11*Q11 -> 25862 | S11: =P11/(F11*202/100) -> 233.0355 | T11: ='8'!G24 -> 0 | U11: 69 | V11: =T11*U11 -> 0 | W11: ='8'!G95 -> 72 | X11: ='8'!G96 -> 13 | Y11: ='8'!G97 -> 13 | Z11: =W11+X11+Y11 -> 98 | AA11: ='8'!G132 -> 4.35 | AB11: ='8'!G133 -> 0 | AC11: ='8'!G134 -> 24 | AD11: ='8'!G135 -> 0 | AE11: =AA11+AB11+AC11+AD11 -> 28.35 | AF11: =AV11+AW11+BF11+BG11 -> 5838.26 | AG11: =AF11/AE11 -> 205.9351 | AH11: ='8'!G136 -> 9.69 | AI11: ='8'!G137 -> 0 | AJ11: ='8'!G138 -> 1.82 | AK11: =AH11+AI11+AJ11 -> 11.51 | AL11: ='8'!G139 -> 6.68 | AM11: ='8'!G140 -> 0 | AO11: =AL11+AM11 -> 6.68 | AP11: ='8'!G123 -> 241 | AQ11: ='8'!G35 -> 3394 | AR11: ='8'!G37 -> 0 | AS11: ='8'!G38 -> 0 | AT11: ='8'!G39 -> 0 | AU11: ='8'!G40 -> 0 | AV11: ='8'!G41 -> 885.26 | AW11: ='8'!G42 -> 0 | AX11: ='8'!G43 -> 2516 | AY11: ='8'!G44 -> 0 | AZ11: ='8'!G36 -> 676 | BA11: ='8'!G49 -> 0 | BB11: ='8'!G51 -> 1483 | BC11: ='8'!G52 -> 2160 | BD11: ='8'!G53 -> 4272 | BE11: ='8'!G54 -> 0 | BF11: ='8'!G55 -> 4953 | BG11: ='8'!G56 -> 0 | BH11: ='8'!G57 -> 0 | BI11: ='8'!G50 -> 1538 | BJ11: =SUM(AV11,AW11,BF11,BG11) -> 5838.26 | BK11: ='8'!G84 -> 793 | BL11: =SUM(AQ11,AV11,AW11,AX11,BA11,BF11,BG11,BH11)/I11% -> 52.165801 | BM11: =SUM(AT11,BD11)/I11% -> 18.968962 | BN11: =(AS11+BC11)/I11 -> 0.095910484 | BO11: =K11+O11+R11+V11 -> 282676.75 | BP11: =SUM(AV11,AW11,AX11,BF11,BG11,BH11,BK11) -> 9147.26 | BQ11: =BP11/(AE11*280) -> 1.1523381
