Workbook

Sheet TOTAL
A1: Site Name | B1: Day | C1: Month | D1: Year | E1: Total Electricity Kwh | F1: Electricity Tariff ($/Kwh) | G1: Total Fuel Oil (Liters) | H1: Fuel Oil $/Liter | I1: Water Utility Supply (m3) m3 | J1: Water Utility Supply (m3) $/m3 | K1: LPG (Kg) | L1: LPG $/Kg | M1: Room Nights | N1: Total Guests | O1: Food Covers
A2: Maldives at Kuda Huraa | B2: 1 | C2: 3 | D2: 2021 | E2: 22070 | F2: 0.14 | G2: 6660 | H2: 0.44534802 | I2: 286.7 | J2: 0.4 | K2: =K33/31 -> 0 | L2: 1.5287028 | M2: 56 | N2: 128 | O2: 304
A3: Maldives at Kuda Huraa | B3: =B2+1 -> 2 | C3: 3 | D3: 2021 | E3: 23210 | F3: 0.14 | G3: 6198 | H3: 0.44534802 | I3: 259 | J3: 0.4 | K3: 0 | L3: 1.5287028 | M3: 51 | N3: 113 | O3: 342
A4: Maldives at Kuda Huraa | B4: =B3+1 -> 3 | C4: 3 | D4: 2021 | E4: 22360 | F4: 0.14 | G4: 6395 | H4: 0.44534802 | I4: 265 | J4: 0.4 | K4: 0 | L4: 1.5287028 | M4: 50 | N4: 111 | O4: 341
A5: Maldives at Kuda Huraa | B5: =B4+1 -> 4 | C5: 3 | D5: 2021 | E5: 22910 | F5: 0.14 | G5: 6606 | H5: 0.44534802 | I5: 330 | J5: 0.4 | K5: 0 | L5: 1.5287028 | M5: 55 | N5: 126 | O5: 339
A6: Maldives at Kuda Huraa | B6: =B5+1 -> 5 | C6: 3 | D6: 2021 | E6: 23110 | F6: 0.14 | G6: 6572 | H6: 0.44534802 | I6: 273 | J6: 0.4 | K6: 0 | L6: 1.5287028 | M6: 28 | N6: 69 | O6: 178
A7: Maldives at Kuda Huraa | B7: =B6+1 -> 6 | C7: 3 | D7: 2021 | E7: 22680 | F7: 0.14 | G7: 6477 | H7: 0.44534802 | I7: 220 | J7: 0.4 | K7: 0 | L7: 1.5287028 | M7: 28 | N7: 70 | O7: 175
A8: Maldives at Kuda Huraa | B8: =B7+1 -> 7 | C8: 3 | D8: 2021 | E8: 21100 | F8: 0.14 | G8: 6035 | H8: 0.44534802 | I8: 329 | J8: 0.4 | K8: 0 | L8: 1.5287028 | M8: 30 | N8: 78 | O8: 205
A9: Maldives at Kuda Huraa | B9: =B8+1 -> 8 | C9: 3 | D9: 2021 | E9: 21140 | F9: 0.14 | G9: 5946 | H9: 0.44534802 | I9: 242.4 | J9: 0.4 | K9: 0 | L9: 1.5287028 | M9: 34 | N9: 87 | O9: 226
A10: Maldives at Kuda Huraa | B10: =B9+1 -> 9 | C10: 3 | D10: 2021 | E10: 21810 | F10: 0.14 | G10: 6086 | H10: 0.44534802 | I10: 219.6 | J10: 0.4 | K10: 0 | L10: 1.5287028 | M10: 32 | N10: 82 | O10: 220
A11: Maldives at Kuda Huraa | B11: =B10+1 -> 10 | C11: 3 | D11: 2021 | E11: 20780 | F11: 0.14 | G11: 6030 | H11: 0.44534802 | I11: 297 | J11: 0.4 | K11: 0 | L11: 1.5287028 | M11: 32 | N11: 84 | O11: 190
A12: Maldives at Kuda Huraa | B12: =B11+1 -> 11 | C12: 3 | D12: 2021 | E12: 18450 | F12: 0.14 | G12: 5145 | H12: 0.44534802 | I12: 300 | J12: 0.4 | K12: 0 | L12: 1.5287028 | M12: 36 | N12: 94 | O12: 242
A13: Maldives at Kuda Huraa | B13: =B12+1 -> 12 | C13: 3 | D13: 2021 | E13: 21800 | F13: 0.14 | G13: 6214 | H13: 0.44534802 | I13: 213 | J13: 0.4 | K13: 0 | L13: 1.5287028 | M13: 38 | N13: 92 | O13: 275
A14: Maldives at Kuda Huraa | B14: =B13+1 -> 13 | C14: 3 | D14: 2021 | E14: 23610 | F14: 0.14 | G14: 6590 | H14: 0.44534802 | I14: 339 | J14: 0.4 | K14: 0 | L14: 1.5287028 | M14: 36 | N14: 93 | O14: 277
... A26: Maldives at Kuda Huraa | B26: =B25+1 -> 25 | C26: 3 | D26: 2021 | E26: 21860 | F26: 0.14 | G26: 6191 | H26: 0.44534802 | I26: 251 | J26: 0.4 | K26: 0 | L26: 1.5287028 | M26: 44 | N26: 109 | O26: 321
A27: Maldives at Kuda Huraa | B27: =B26+1 -> 26 | C27: 3 | D27: 2021 | E27: 23070 | F27: 0.14 | G27: 6816 | H27: 0.44534802 | I27: 243 | J27: 0.4 | K27: 0 | L27: 1.5287028
A28: Maldives at Kuda Huraa | B28: =B27+1 -> 27 | C28: 3 | D28: 2021 | F28: 0.14 | H28: 0.44534802 | J28: 0.4 | K28: 0 | L28: 1.5287028
A29: Maldives at Kuda Huraa | B29: =B28+1 -> 28 | C29: 3 | D29: 2021 | F29: 0.14 | H29: 0.44534802 | J29: 0.4 | K29: 0 | L29: 1.5287028
A30: Maldives at Kuda Huraa | B30: =B29+1 -> 29 | C30: 3 | D30: 2021 | F30: 0.14 | H30: 0.44534802 | J30: 0.4 | K30: 0 | L30: 1.5287028
A31: Maldives at Kuda Huraa | B31: =B30+1 -> 30 | C31: 3 | D31: 2021 | F31: 0.14 | H31: 0.44534802 | J31: 0.4 | K31: 0 | L31: 1.5287028
A32: Maldives at Kuda Huraa | B32: =B31+1 -> 31 | C32: 3 | D32: 2021 | F32: 0.14 | H32: 0.44534802 | J32: 0.4 | K32: 0 | L32: 1.5287028
A33: Total | E33: =SUM(E2:E32) -> 568510 | F33: 0 | G33: =SUM(G2:G32) -> 161532 | H33: 0 | I33: =SUM(I2:I32) -> 6902.7 | J33: 0 | K33: 0 | L33: 0 | M33: =SUM(M2:M32) -> 921 | N33: =SUM(N2:N32) -> 2279 | O33: =SUM(O2:O32) -> 6348

Sheet Kwh Reading
A1: Electric Consumption Record (4pm)
A2: Month | B2: BOH-1/ B&C Block MWH | C2: Pastry MWH | D2: Feeder 401-419 KWH | E2: Feeder 301-319 KWH | F2: Kitchen GWH | G2: Feeder 201-208 MWH | H2: Feeder 113-123 | I2: M - Block /PC MWH | J2: Laundry MWH | M2: Feeder 101-112 MWH | N2: Feeder 217-224 | O2: Spa MWH | P2: Feeder 124-134 | Q2: Feeder 209-216 | R2: STP -1 &2 MWH | S2: STP -3 MWH | T2: Reef Club MWH | V2: Room Nights | W2: Total Guests | X2: Food Covers
J3: A | K3: B | L3: C
A4: 44256 | B4: 822.66 | C4: 202.2 | D4: 7188944.2 | E4: 7810758 | F4: 2.084 | G4: 634.35 | H4: 532.79 | I4: 197.09 | J4: 290.29 | K4: 305.37 | L4: 209.05 | M4: 427.59 | N4: 376.04 | O4: 121.34 | P4: 495.62 | Q4: 370.65 | R4: 124.01 | S4: 99.441 | T4: 364.12 | V4: 56 | W4: 128 | X4: 304
A5: 44257 | B5: 823.87 | C5: 202.45 | D5: 7191198.1 | E5: 7813711.2 | F5: 2.0863 | G5: 635.36 | H5: 533.65 | I5: 197.4 | J5: 290.52 | K5: 305.72 | L5: 209.29 | M5: 428.35 | N5: 376.91 | O5: 121.59 | P5: 496.52 | Q5: 371.5 | R5: 124.05 | S5: 99.592 | T5: 364.63 | V5: 51 | W5: 113 | X5: 342
A6: 44258 | B6: 825.05 | C6: 202.7 | D6: 7193371.4 | E6: 7816547.7 | F6: 2.0887 | G6: 636.39 | H6: 534.48 | I6: 197.76 | J6: 290.79 | K6: 306.15 | L6: 209.53 | M6: 429.07 | N6: 377.73 | O6: 121.9 | P6: 497.5 | Q6: 372.36 | R6: 124.12 | S6: 99.74 | T6: 365.13 | V6: 50 | W6: 111 | X6: 341
A7: 44259 | B7: 826.2 | C7: 202.94 | D7: 7195478.5 | E7: 7819494.3 | F7: 2.0912 | G7: 637.38 | H7: 535.25 | I7: 198.1 | J7: 291.12 | K7: 306.56 | L7: 209.79 | M7: 429.74 | N7: 378.57 | O7: 122.15 | P7: 498.46 | Q7: 373.16 | R7: 124.2 | S7: 99.83 | T7: 365.65 | V7: 55 | W7: 126 | X7: 339
A8: 44260 | B8: 827.4 | C8: 203.17 | D8: 7197919.7 | E8: 7822436.9 | F8: 2.0936 | G8: 638.38 | H8: 536.1 | I8: 198.36 | J8: 291.42 | K8: 307 | L8: 210.04 | M8: 430.45 | N8: 379.49 | O8: 122.48 | P8: 499.43 | Q8: 373.93 | R8: 124.29 | S8: 99.883 | T8: 366.17 | V8: 28 | W8: 69 | X8: 178
A9: 44261 | B9: 828.63 | C9: 203.42 | D9: 7200430.9 | E9: 7825459.3 | F9: 2.0959 | G9: 639.3 | H9: 537.12 | I9: 198.7 | J9: 291.69 | K9: 307.4 | L9: 210.26 | M9: 431.16 | N9: 380.45 | O9: 122.74 | P9: 500.44 | Q9: 374.83 | R9: 124.46 | S9: 100.02 | T9: 366.68 | V9: 28 | W9: 70 | X9: 175
A10: 44262 | B10: 829.97 | C10: 203.67 | D10: 7202605.1 | E10: 7828346.1 | F10: 2.0983 | G10: 640.18 | H10: 538.06 | I10: 199.04 | J10: 291.98 | K10: 307.83 | L10: 210.5 | M10: 431.88 | N10: 381.35 | O10: 122.97 | P10: 501.51 | Q10: 375.61 | R10: 124.65 | S10: 100.16 | T10: 367.18 | V10: 30 | W10: 78 | X10: 205
A11: 44263 | B11: 831.24 | C11: 203.88 | D11: 7204562.9 | E11: 7831066.2 | F11: 2.1006 | G11: 641.01 | H11: 538.92 | I11: 199.36 | J11: 292.2 | K11: 308.19 | L11: 210.73 | M11: 432.57 | N11: 382.25 | O11: 123.19 | P11: 502.51 | Q11: 376.32 | R11: 124.75 | S11: 100.21 | T11: 367.66 | V11: 34 | W11: 87 | X11: 226
A12: 44264 | B12: 832.36 | C12: 204.13 | D12: 7206805.2 | E12: 7833854.7 | F12: 2.1029 | G12: 641.96 | H12: 539.66 | I12: 199.7 | J12: 292.24 | K12: 308.54 | L12: 210.97 | M12: 433.33 | N12: 383.06 | O12: 123.44 | P12: 503.49 | Q12: 377.04 | R12: 124.87 | S12: 100.27 | T12: 368.15 | V12: 32 | W12: 82 | X12: 220
A13: 44265 | B13: 833.46 | C13: 204.35 | D13: 7209153.2 | E13: 7836583 | F13: 2.1053 | G13: 642.82 | H13: 540.42 | I13: 200 | J13: 292.28 | K13: 308.88 | L13: 211.2 | M13: 434.07 | N13: 383.93 | O13: 123.66 | P13: 504.53 | Q13: 377.81 | R13: 124.92 | S13: 100.27 | T13: 368.84 | V13: 32 | W13: 84 | X13: 190
A14: 44266 | B14: 834.68 | C14: 204.58 | D14: 7211533.6 | E14: 7839332.1 | F14: 2.1077 | G14: 643.59 | H14: 541.15 | I14: 200.3 | J14: 292.48 | K14: 309.25 | L14: 211.45 | M14: 434.78 | N14: 384.69 | O14: 123.89 | P14: 505.44 | Q14: 378.53 | R14: 125.07 | S14: 100.36 | T14: 369.13 | V14: 36 | W14: 94 | X14: 242
A15: 44267 | B15: 835.6 | C15: 204.8 | D15: 7213309.6 | E15: 7841305.6 | F15: 2.1098 | G15: 644.2 | H15: 541.59 | I15: 200.49 | J15: 292.72 | K15: 309.52 | L15: 211.64 | M15: 435.21 | N15: 385.17 | O15: 124.11 | P15: 506.1 | Q15: 378.99 | R15: 125.26 | S15: 100.51 | T15: 369.56 | V15: 38 | W15: 92 | X15: 275
... A28: 44280 | B28: 852.04 | C28: 207.85 | D28: 7242688.8 | E28: 7878323.7 | F28: 2.1412 | G28: 656.45 | H28: 552.87 | I28: 204.32 | J28: 296.06 | K28: 313.78 | L28: 214.5 | M28: 443.52 | N28: 395.6 | O28: 127 | P28: 518.09 | Q28: 388.08 | R28: 128.48 | S28: 102.33 | T28: 375.59 | V28: 44 | W28: 109 | X28: 321
A29: 44281 | B29: 852.22 | C29: 208.1 | D29: 7244931 | E29: 7881288.2 | F29: 2.1436 | G29: 657.37 | H29: 553.65 | I29: 204.59 | J29: 296.3 | K29: 314.13 | L29: 214.73 | M29: 444.16 | N29: 396.46 | O29: 127.22 | P29: 518.76 | Q29: 388.81 | R29: 128.77 | S29: 102.47 | T29: 376.05
A30: 44282 | B30: 854.56 | C30: 208.37 | D30: 7247513.4 | E30: 788423.24 | F30: 2.1463 | G30: 658.39 | H30: 554.5 | I30: 204.86 | J30: 296.6 | K30: 314.52 | L30: 214.97 | M30: 444.96 | N30: 397.34 | O30: 127.45 | P30: 519.72 | Q30: 389.66 | R30: 129.01 | S30: 102.58 | T30: 376.3
A31: 44283
A32: 44284
A33: 44285
A34: 44286
V35: =SUM(V4:V34) -> 921 | W35: =SUM(W4:W34) -> 2279 | X35: =SUM(X4:X34) -> 6348
T42: ……..

Sheet Kwh Consumption
A2: Date | B2: Total KWH | C2: Reef Club KWH | D2: Kitchen KWH | E2: Pastry KWH | F2: Laundry KWH | I2: STP -1 &2 KWH | J2: STP -3 KWH | K2: M - Block /PC KWH | L2: B&C Block KWH | M2: Guest Room Beach Pavilion & Beach Bungalow KWH | S2: Guest Room Water Bungalow KWH | U2: Spa KWH | V2: Others KWH
F3: A | G3: B | H3: C | M3: Feeder -101-112 | N3: Feeder -113-123 | O3: Feeder -124-134 | P3: Feeder -201-208 | Q3: Feeder -209-216 | R3: Feeder -217-224 | S3: Feeder -301-319 | T3: Feeder 401-419
A4: ='Kwh Reading'!A4 -> 44256 | B4: =TOTAL!E2 -> 22070 | C4: =('Kwh Reading'!T5-'Kwh Reading'!T4)*1000 -> 510 | D4: =('Kwh Reading'!F5-'Kwh Reading'!F4)*1000000 -> 2300 | E4: =('Kwh Reading'!C5-'Kwh Reading'!C4)*1000 -> 250 | F4: =('Kwh Reading'!J5-'Kwh Reading'!J4)*1000 -> 230 | G4: =('Kwh Reading'!K5-'Kwh Reading'!K4)*1000 -> 350 | H4: =('Kwh Reading'!L5-'Kwh Reading'!L4)*1000 -> 240 | I4: =('Kwh Reading'!R5-'Kwh Reading'!R4)*1000 -> 40 | J4: =('Kwh Reading'!S5-'Kwh Reading'!S4)*1000 -> 151 | K4: =('Kwh Reading'!I5-'Kwh Reading'!I4)*1000 -> 310 | L4: =('Kwh Reading'!B5-'Kwh Reading'!B4)*1000 -> 1210 | M4: =('Kwh Reading'!M5-'Kwh Reading'!M4)*1000 -> 760 | N4: =('Kwh Reading'!H5-'Kwh Reading'!H4)*1000 -> 860 | O4: =('Kwh Reading'!P5-'Kwh Reading'!P4)*1000 -> 900 | P4: =('Kwh Reading'!G5-'Kwh Reading'!G4)*1000 -> 1010 | Q4: =('Kwh Reading'!Q5-'Kwh Reading'!Q4)*1000 -> 850 | R4: =('Kwh Reading'!N5-'Kwh Reading'!N4)*1000 -> 870 | S4: ='Kwh Reading'!E5-'Kwh Reading'!E4 -> 2953.17 | T4: ='Kwh Reading'!D5-'Kwh Reading'!D4 -> 2253.82 | U4: =('Kwh Reading'!O5-'Kwh Reading'!O4)*1000 -> 250 | V4: =B4-(SUM(C4:U4)) -> 5772.01
A5: ='Kwh Reading'!A5 -> 44257 | B5: =TOTAL!E3 -> 23210 | C5: =('Kwh Reading'!T6-'Kwh Reading'!T5)*1000 -> 500 | D5: =('Kwh Reading'!F6-'Kwh Reading'!F5)*1000000 -> 2400 | E5: =('Kwh Reading'!C6-'Kwh Reading'!C5)*1000 -> 250 | F5: =('Kwh Reading'!J6-'Kwh Reading'!J5)*1000 -> 270 | G5: =('Kwh Reading'!K6-'Kwh Reading'!K5)*1000 -> 430 | H5: =('Kwh Reading'!L6-'Kwh Reading'!L5)*1000 -> 240 | I5: =('Kwh Reading'!R6-'Kwh Reading'!R5)*1000 -> 70 | J5: =('Kwh Reading'!S6-'Kwh Reading'!S5)*1000 -> 148 | K5: =('Kwh Reading'!I6-'Kwh Reading'!I5)*1000 -> 360 | L5: =('Kwh Reading'!B6-'Kwh Reading'!B5)*1000 -> 1180 | M5: =('Kwh Reading'!M6-'Kwh Reading'!M5)*1000 -> 720 | N5: =('Kwh Reading'!H6-'Kwh Reading'!H5)*1000 -> 830 | O5: =('Kwh Reading'!P6-'Kwh Reading'!P5)*1000 -> 980 | P5: =('Kwh Reading'!G6-'Kwh Reading'!G5)*1000 -> 1030 | Q5: =('Kwh Reading'!Q6-'Kwh Reading'!Q5)*1000 -> 860 | R5: =('Kwh Reading'!N6-'Kwh Reading'!N5)*1000 -> 820 | S5: ='Kwh Reading'!E6-'Kwh Reading'!E5 -> 2836.5 | T5: ='Kwh Reading'!D6-'Kwh Reading'!D5 -> 2173.34 | U5: =('Kwh Reading'!O6-'Kwh Reading'!O5)*1000 -> 310 | V5: =B5-(SUM(C5:U5)) -> 6802.16
A6: ='Kwh Reading'!A6 -> 44258 | B6: =TOTAL!E4 -> 22360 | C6: =('Kwh Reading'!T7-'Kwh Reading'!T6)*1000 -> 520 | D6: =('Kwh Reading'!F7-'Kwh Reading'!F6)*1000000 -> 2500 | E6: =('Kwh Reading'!C7-'Kwh Reading'!C6)*1000 -> 240 | F6: =('Kwh Reading'!J7-'Kwh Reading'!J6)*1000 -> 330 | G6: =('Kwh Reading'!K7-'Kwh Reading'!K6)*1000 -> 410 | H6: =('Kwh Reading'!L7-'Kwh Reading'!L6)*1000 -> 260 | I6: =('Kwh Reading'!R7-'Kwh Reading'!R6)*1000 -> 80 | J6: =('Kwh Reading'!S7-'Kwh Reading'!S6)*1000 -> 90 | K6: =('Kwh Reading'!I7-'Kwh Reading'!I6)*1000 -> 340 | L6: =('Kwh Reading'!B7-'Kwh Reading'!B6)*1000 -> 1150 | M6: =('Kwh Reading'!M7-'Kwh Reading'!M6)*1000 -> 670 | N6: =('Kwh Reading'!H7-'Kwh Reading'!H6)*1000 -> 770 | O6: =('Kwh Reading'!P7-'Kwh Reading'!P6)*1000 -> 960 | P6: =('Kwh Reading'!G7-'Kwh Reading'!G6)*1000 -> 990 | Q6: =('Kwh Reading'!Q7-'Kwh Reading'!Q6)*1000 -> 800 | R6: =('Kwh Reading'!N7-'Kwh Reading'!N6)*1000 -> 840 | S6: ='Kwh Reading'!E7-'Kwh Reading'!E6 -> 2946.69 | T6: ='Kwh Reading'!D7-'Kwh Reading'!D6 -> 2107.05 | U6: =('Kwh Reading'!O7-'Kwh Reading'!O6)*1000 -> 250 | V6: =B6-(SUM(C6:U6)) -> 6106.26
A7: ='Kwh Reading'!A7 -> 44259 | B7: =TOTAL!E5 -> 22910 | C7: =('Kwh Reading'!T8-'Kwh Reading'!T7)*1000 -> 520 | D7: =('Kwh Reading'!F8-'Kwh Reading'!F7)*1000000 -> 2400 | E7: =('Kwh Reading'!C8-'Kwh Reading'!C7)*1000 -> 230 | F7: =('Kwh Reading'!J8-'Kwh Reading'!J7)*1000 -> 300 | G7: =('Kwh Reading'!K8-'Kwh Reading'!K7)*1000 -> 440 | H7: =('Kwh Reading'!L8-'Kwh Reading'!L7)*1000 -> 250 | I7: =('Kwh Reading'!R8-'Kwh Reading'!R7)*1000 -> 90 | J7: =('Kwh Reading'!S8-'Kwh Reading'!S7)*1000 -> 53 | K7: =('Kwh Reading'!I8-'Kwh Reading'!I7)*1000 -> 260 | L7: =('Kwh Reading'!B8-'Kwh Reading'!B7)*1000 -> 1200 | M7: =('Kwh Reading'!M8-'Kwh Reading'!M7)*1000 -> 710 | N7: =('Kwh Reading'!H8-'Kwh Reading'!H7)*1000 -> 850 | O7: =('Kwh Reading'!P8-'Kwh Reading'!P7)*1000 -> 970 | P7: =('Kwh Reading'!G8-'Kwh Reading'!G7)*1000 -> 1000 | Q7: =('Kwh Reading'!Q8-'Kwh Reading'!Q7)*1000 -> 770 | R7: =('Kwh Reading'!N8-'Kwh Reading'!N7)*1000 -> 920 | S7: ='Kwh Reading'!E8-'Kwh Reading'!E7 -> 2942.55 | T7: ='Kwh Reading'!D8-'Kwh Reading'!D7 -> 2441.25 | U7: =('Kwh Reading'!O8-'Kwh Reading'!O7)*1000 -> 330 | V7: =B7-(SUM(C7:U7)) -> 6233.2
A8: ='Kwh Reading'!A8 -> 44260 | B8: 23110 | C8: =('Kwh Reading'!T9-'Kwh Reading'!T8)*1000 -> 510 | D8: =('Kwh Reading'!F9-'Kwh Reading'!F8)*1000000 -> 2300 | E8: =('Kwh Reading'!C9-'Kwh Reading'!C8)*1000 -> 250 | F8: =('Kwh Reading'!J9-'Kwh Reading'!J8)*1000 -> 270 | G8: =('Kwh Reading'!K9-'Kwh Reading'!K8)*1000 -> 400 | H8: =('Kwh Reading'!L9-'Kwh Reading'!L8)*1000 -> 220 | I8: =('Kwh Reading'!R9-'Kwh Reading'!R8)*1000 -> 170 | J8: =('Kwh Reading'!S9-'Kwh Reading'!S8)*1000 -> 137 | K8: =('Kwh Reading'!I9-'Kwh Reading'!I8)*1000 -> 340 | L8: =('Kwh Reading'!B9-'Kwh Reading'!B8)*1000 -> 1230 | M8: =('Kwh Reading'!M9-'Kwh Reading'!M8)*1000 -> 710 | N8: =('Kwh Reading'!H9-'Kwh Reading'!H8)*1000 -> 1020 | O8: =('Kwh Reading'!P9-'Kwh Reading'!P8)*1000 -> 1010 | P8: =('Kwh Reading'!G9-'Kwh Reading'!G8)*1000 -> 920 | Q8: =('Kwh Reading'!Q9-'Kwh Reading'!Q8)*1000 -> 900 | R8: =('Kwh Reading'!N9-'Kwh Reading'!N8)*1000 -> 960 | S8: ='Kwh Reading'!E9-'Kwh Reading'!E8 -> 3022.41 | T8: ='Kwh Reading'!D9-'Kwh Reading'!D8 -> 2511.21 | U8: =('Kwh Reading'!O9-'Kwh Reading'!O8)*1000 -> 260 | V8: =B8-(SUM(C8:U8)) -> 5969.38
A9: ='Kwh Reading'!A9 -> 44261 | B9: =TOTAL!E7 -> 22680 | C9: =('Kwh Reading'!T10-'Kwh Reading'!T9)*1000 -> 500 | D9: =('Kwh Reading'!F10-'Kwh Reading'!F9)*1000000 -> 2400 | E9: =('Kwh Reading'!C10-'Kwh Reading'!C9)*1000 -> 250 | F9: =('Kwh Reading'!J10-'Kwh Reading'!J9)*1000 -> 290 | G9: =('Kwh Reading'!K10-'Kwh Reading'!K9)*1000 -> 430 | H9: =('Kwh Reading'!L10-'Kwh Reading'!L9)*1000 -> 240 | I9: =('Kwh Reading'!R10-'Kwh Reading'!R9)*1000 -> 190 | J9: =('Kwh Reading'!S10-'Kwh Reading'!S9)*1000 -> 140 | K9: =('Kwh Reading'!I10-'Kwh Reading'!I9)*1000 -> 340 | L9: =('Kwh Reading'!B10-'Kwh Reading'!B9)*1000 -> 1340 | M9: =('Kwh Reading'!M10-'Kwh Reading'!M9)*1000 -> 720 | N9: =('Kwh Reading'!H10-'Kwh Reading'!H9)*1000 -> 940 | O9: =('Kwh Reading'!P10-'Kwh Reading'!P9)*1000 -> 1070 | P9: =('Kwh Reading'!G10-'Kwh Reading'!G9)*1000 -> 880 | Q9: =('Kwh Reading'!Q10-'Kwh Reading'!Q9)*1000 -> 780 | R9: =('Kwh Reading'!N10-'Kwh Reading'!N9)*1000 -> 900 | S9: ='Kwh Reading'!E10-'Kwh Reading'!E9 -> 2886.76 | T9: ='Kwh Reading'!D10-'Kwh Reading'!D9 -> 2174.17 | U9: =('Kwh Reading'!O10-'Kwh Reading'!O9)*1000 -> 230 | V9: =B9-(SUM(C9:U9)) -> 5979.07
A10: ='Kwh Reading'!A10 -> 44262 | B10: =TOTAL!E8 -> 21100 | C10: =('Kwh Reading'!T11-'Kwh Reading'!T10)*1000 -> 480 | D10: =('Kwh Reading'!F11-'Kwh Reading'!F10)*1000000 -> 2300 | E10: =('Kwh Reading'!C11-'Kwh Reading'!C10)*1000 -> 210 | F10: =('Kwh Reading'!J11-'Kwh Reading'!J10)*1000 -> 220 | G10: =('Kwh Reading'!K11-'Kwh Reading'!K10)*1000 -> 360 | H10: =('Kwh Reading'!L11-'Kwh Reading'!L10)*1000 -> 230 | I10: =('Kwh Reading'!R11-'Kwh Reading'!R10)*1000 -> 100 | J10: =('Kwh Reading'!S11-'Kwh Reading'!S10)*1000 -> 50 | K10: =('Kwh Reading'!I11-'Kwh Reading'!I10)*1000 -> 320 | L10: =('Kwh Reading'!B11-'Kwh Reading'!B10)*1000 -> 1270 | M10: =('Kwh Reading'!M11-'Kwh Reading'!M10)*1000 -> 690 | N10: =('Kwh Reading'!H11-'Kwh Reading'!H10)*1000 -> 860 | O10: =('Kwh Reading'!P11-'Kwh Reading'!P10)*1000 -> 1000 | P10: =('Kwh Reading'!G11-'Kwh Reading'!G10)*1000 -> 830 | Q10: =('Kwh Reading'!Q11-'Kwh Reading'!Q10)*1000 -> 710 | R10: =('Kwh Reading'!N11-'Kwh Reading'!N10)*1000 -> 900 | S10: ='Kwh Reading'!E11-'Kwh Reading'!E10 -> 2720.14 | T10: ='Kwh Reading'!D11-'Kwh Reading'!D10 -> 1957.82 | U10: =('Kwh Reading'!O11-'Kwh Reading'!O10)*1000 -> 220 | V10: =B10-(SUM(C10:U10)) -> 5672.04
A11: ='Kwh Reading'!A11 -> 44263 | B11: =TOTAL!E9 -> 21140 | C11: =('Kwh Reading'!T12-'Kwh Reading'!T11)*1000 -> 490 | D11: =('Kwh Reading'!F12-'Kwh Reading'!F11)*1000000 -> 2300 | E11: =('Kwh Reading'!C12-'Kwh Reading'!C11)*1000 -> 250 | F11: =('Kwh Reading'!J12-'Kwh Reading'!J11)*1000 -> 40 | G11: =('Kwh Reading'!K12-'Kwh Reading'!K11)*1000 -> 350 | H11: =('Kwh Reading'!L12-'Kwh Reading'!L11)*1000 -> 240 | I11: =('Kwh Reading'!R12-'Kwh Reading'!R11)*1000 -> 120 | J11: =('Kwh Reading'!S12-'Kwh Reading'!S11)*1000 -> 60 | K11: =('Kwh Reading'!I12-'Kwh Reading'!I11)*1000 -> 340 | L11: =('Kwh Reading'!B12-'Kwh Reading'!B11)*1000 -> 1120 | M11: =('Kwh Reading'!M12-'Kwh Reading'!M11)*1000 -> 760 | N11: =('Kwh Reading'!H12-'Kwh Reading'!H11)*1000 -> 740 | O11: =('Kwh Reading'!P12-'Kwh Reading'!P11)*1000 -> 980 | P11: =('Kwh Reading'!G12-'Kwh Reading'!G11)*1000 -> 950 | Q11: =('Kwh Reading'!Q12-'Kwh Reading'!Q11)*1000 -> 720 | R11: =('Kwh Reading'!N12-'Kwh Reading'!N11)*1000 -> 810 | S11: ='Kwh Reading'!E12-'Kwh Reading'!E11 -> 2788.52 | T11: ='Kwh Reading'!D12-'Kwh Reading'!D11 -> 2242.3 | U11: =('Kwh Reading'!O12-'Kwh Reading'!O11)*1000 -> 250 | V11: =B11-(SUM(C11:U11)) -> 5589.18
A12: ='Kwh Reading'!A12 -> 44264 | B12: =TOTAL!E10 -> 21810 | C12: =('Kwh Reading'!T13-'Kwh Reading'!T12)*1000 -> 690 | D12: =('Kwh Reading'!F13-'Kwh Reading'!F12)*1000000 -> 2400 | E12: =('Kwh Reading'!C13-'Kwh Reading'!C12)*1000 -> 220 | F12: =('Kwh Reading'!J13-'Kwh Reading'!J12)*1000 -> 40 | G12: =('Kwh Reading'!K13-'Kwh Reading'!K12)*1000 -> 340 | H12: =('Kwh Reading'!L13-'Kwh Reading'!L12)*1000 -> 230 | I12: =('Kwh Reading'!R13-'Kwh Reading'!R12)*1000 -> 50 | J12: =('Kwh Reading'!S13-'Kwh Reading'!S12)*1000 -> 0 | K12: =('Kwh Reading'!I13-'Kwh Reading'!I12)*1000 -> 300 | L12: =('Kwh Reading'!B13-'Kwh Reading'!B12)*1000 -> 1100 | M12: =('Kwh Reading'!M13-'Kwh Reading'!M12)*1000 -> 740 | N12: =('Kwh Reading'!H13-'Kwh Reading'!H12)*1000 -> 760 | O12: =('Kwh Reading'!P13-'Kwh Reading'!P12)*1000 -> 1040 | P12: =('Kwh Reading'!G13-'Kwh Reading'!G12)*1000 -> 860 | Q12: =('Kwh Reading'!Q13-'Kwh Reading'!Q12)*1000 -> 770 | R12: =('Kwh Reading'!N13-'Kwh Reading'!N12)*1000 -> 870 | S12: ='Kwh Reading'!E13-'Kwh Reading'!E12 -> 2728.23 | T12: ='Kwh Reading'!D13-'Kwh Reading'!D12 -> 2347.99 | U12: =('Kwh Reading'!O13-'Kwh Reading'!O12)*1000 -> 220 | V12: =B12-(SUM(C12:U12)) -> 6103.78
A13: ='Kwh Reading'!A13 -> 44265 | B13: =TOTAL!E11 -> 20780 | C13: =('Kwh Reading'!T14-'Kwh Reading'!T13)*1000 -> 290 | D13: =('Kwh Reading'!F14-'Kwh Reading'!F13)*1000000 -> 2400 | E13: =('Kwh Reading'!C14-'Kwh Reading'!C13)*1000 -> 230 | F13: =('Kwh Reading'!J14-'Kwh Reading'!J13)*1000 -> 200 | G13: =('Kwh Reading'!K14-'Kwh Reading'!K13)*1000 -> 370 | H13: =('Kwh Reading'!L14-'Kwh Reading'!L13)*1000 -> 250 | I13: =('Kwh Reading'!R14-'Kwh Reading'!R13)*1000 -> 150 | J13: =('Kwh Reading'!S14-'Kwh Reading'!S13)*1000 -> 90 | K13: =('Kwh Reading'!I14-'Kwh Reading'!I13)*1000 -> 300 | L13: =('Kwh Reading'!B14-'Kwh Reading'!B13)*1000 -> 1220 | M13: =('Kwh Reading'!M14-'Kwh Reading'!M13)*1000 -> 710 | N13: =('Kwh Reading'!H14-'Kwh Reading'!H13)*1000 -> 730 | O13: =('Kwh Reading'!P14-'Kwh Reading'!P13)*1000 -> 910 | P13: =('Kwh Reading'!G14-'Kwh Reading'!G13)*1000 -> 770 | Q13: =('Kwh Reading'!Q14-'Kwh Reading'!Q13)*1000 -> 720 | R13: =('Kwh Reading'!N14-'Kwh Reading'!N13)*1000 -> 760 | S13: ='Kwh Reading'!E14-'Kwh Reading'!E13 -> 2749.15 | T13: ='Kwh Reading'!D14-'Kwh Reading'!D13 -> 2380.4 | U13: =('Kwh Reading'!O14-'Kwh Reading'!O13)*1000 -> 230 | V13: =B13-(SUM(C13:U13)) -> 5320.45
A14: ='Kwh Reading'!A14 -> 44266 | B14: =TOTAL!E12 -> 18450 | C14: =('Kwh Reading'!T15-'Kwh Reading'!T14)*1000 -> 430 | D14: =('Kwh Reading'!F15-'Kwh Reading'!F14)*1000000 -> 2100 | E14: =('Kwh Reading'!C15-'Kwh Reading'!C14)*1000 -> 220 | F14: =('Kwh Reading'!J15-'Kwh Reading'!J14)*1000 -> 240 | G14: =('Kwh Reading'!K15-'Kwh Reading'!K14)*1000 -> 270 | H14: =('Kwh Reading'!L15-'Kwh Reading'!L14)*1000 -> 190 | I14: =('Kwh Reading'!R15-'Kwh Reading'!R14)*1000 -> 190 | J14: =('Kwh Reading'!S15-'Kwh Reading'!S14)*1000 -> 150 | K14: =('Kwh Reading'!I15-'Kwh Reading'!I14)*1000 -> 190 | L14: =('Kwh Reading'!B15-'Kwh Reading'!B14)*1000 -> 920 | M14: =('Kwh Reading'!M15-'Kwh Reading'!M14)*1000 -> 430 | N14: =('Kwh Reading'!H15-'Kwh Reading'!H14)*1000 -> 440 | O14: =('Kwh Reading'!P15-'Kwh Reading'!P14)*1000 -> 660 | P14: =('Kwh Reading'!G15-'Kwh Reading'!G14)*1000 -> 610 | Q14: =('Kwh Reading'!Q15-'Kwh Reading'!Q14)*1000 -> 460 | R14: =('Kwh Reading'!N15-'Kwh Reading'!N14)*1000 -> 480 | S14: ='Kwh Reading'!E15-'Kwh Reading'!E14 -> 1973.5 | T14: ='Kwh Reading'!D15-'Kwh Reading'!D14 -> 1776.02 | U14: =('Kwh Reading'!O15-'Kwh Reading'!O14)*1000 -> 220 | V14: =B14-(SUM(C14:U14)) -> 6500.48
A15: ='Kwh Reading'!A15 -> 44267 | B15: =TOTAL!E13 -> 21800 | C15: =('Kwh Reading'!T16-'Kwh Reading'!T15)*1000 -> 240 | D15: =('Kwh Reading'!F16-'Kwh Reading'!F15)*1000000 -> 2400 | E15: =('Kwh Reading'!C16-'Kwh Reading'!C15)*1000 -> 260 | F15: =('Kwh Reading'!J16-'Kwh Reading'!J15)*1000 -> 220 | G15: =('Kwh Reading'!K16-'Kwh Reading'!K15)*1000 -> 340 | H15: =('Kwh Reading'!L16-'Kwh Reading'!L15)*1000 -> 220 | I15: =('Kwh Reading'!R16-'Kwh Reading'!R15)*1000 -> 260 | J15: =('Kwh Reading'!S16-'Kwh Reading'!S15)*1000 -> 160 | K15: =('Kwh Reading'!I16-'Kwh Reading'!I15)*1000 -> 300 | L15: =('Kwh Reading'!B16-'Kwh Reading'!B15)*1000 -> 1220 | M15: =('Kwh Reading'!M16-'Kwh Reading'!M15)*1000 -> 660 | N15: =('Kwh Reading'!H16-'Kwh Reading'!H15)*1000 -> 880 | O15: =('Kwh Reading'!P16-'Kwh Reading'!P15)*1000 -> 930 | P15: =('Kwh Reading'!G16-'Kwh Reading'!G15)*1000 -> 950 | Q15: =('Kwh Reading'!Q16-'Kwh Reading'!Q15)*1000 -> 580 | R15: =('Kwh Reading'!N16-'Kwh Reading'!N15)*1000 -> 770 | S15: ='Kwh Reading'!E16-'Kwh Reading'!E15 -> 2668.56 | T15: ='Kwh Reading'!D16-'Kwh Reading'!D15 -> 2594.27 | U15: =('Kwh Reading'!O16-'Kwh Reading'!O15)*1000 -> 240 | V15: =B15-(SUM(C15:U15)) -> 5907.17
A16: ='Kwh Reading'!A16 -> 44268 | B16: =TOTAL!E14 -> 23610 | C16: =('Kwh Reading'!T17-'Kwh Reading'!T16)*1000 -> 510 | D16: =('Kwh Reading'!F17-'Kwh Reading'!F16)*1000000 -> 2400 | E16: =('Kwh Reading'!C17-'Kwh Reading'!C16)*1000 -> 220 | F16: =('Kwh Reading'!J17-'Kwh Reading'!J16)*1000 -> 290 | G16: =('Kwh Reading'!K17-'Kwh Reading'!K16)*1000 -> 350 | H16: =('Kwh Reading'!L17-'Kwh Reading'!L16)*1000 -> 230 | I16: =('Kwh Reading'!R17-'Kwh Reading'!R16)*1000 -> 280 | J16: =('Kwh Reading'!S17-'Kwh Reading'!S16)*1000 -> 140 | K16: =('Kwh Reading'!I17-'Kwh Reading'!I16)*1000 -> 320 | L16: =('Kwh Reading'!B17-'Kwh Reading'!B16)*1000 -> 1260 | M16: =('Kwh Reading'!M17-'Kwh Reading'!M16)*1000 -> 700 | N16: =('Kwh Reading'!H17-'Kwh Reading'!H16)*1000 -> 830 | O16: =('Kwh Reading'!P17-'Kwh Reading'!P16)*1000 -> 1010 | P16: =('Kwh Reading'!G17-'Kwh Reading'!G16)*1000 -> 950 | Q16: =('Kwh Reading'!Q17-'Kwh Reading'!Q16)*1000 -> 660 | R16: =('Kwh Reading'!N17-'Kwh Reading'!N16)*1000 -> 830 | S16: ='Kwh Reading'!E17-'Kwh Reading'!E16 -> 3090.6 | T16: ='Kwh Reading'!D17-'Kwh Reading'!D16 -> 2619.43 | U16: =('Kwh Reading'!O17-'Kwh Reading'!O16)*1000 -> 200 | V16: =B16-(SUM(C16:U16)) -> 6719.97
A17: ='Kwh Reading'!A17 -> 44269 | B17: =TOTAL!E15 -> 21940 | C17: =('Kwh Reading'!T18-'Kwh Reading'!T17)*1000 -> 600 | D17: =('Kwh Reading'!F18-'Kwh Reading'!F17)*1000000 -> 2400 | E17: =('Kwh Reading'!C18-'Kwh Reading'!C17)*1000 -> 230 | F17: =('Kwh Reading'!J18-'Kwh Reading'!J17)*1000 -> 280 | G17: =('Kwh Reading'!K18-'Kwh Reading'!K17)*1000 -> 140 | H17: =('Kwh Reading'!L18-'Kwh Reading'!L17)*1000 -> 230 | I17: =('Kwh Reading'!R18-'Kwh Reading'!R17)*1000 -> 300 | J17: =('Kwh Reading'!S18-'Kwh Reading'!S17)*1000 -> 120 | K17: =('Kwh Reading'!I18-'Kwh Reading'!I17)*1000 -> 290 | L17: =('Kwh Reading'!B18-'Kwh Reading'!B17)*1000 -> 1210 | M17: =('Kwh Reading'!M18-'Kwh Reading'!M17)*1000 -> 640 | N17: =('Kwh Reading'!H18-'Kwh Reading'!H17)*1000 -> 870 | O17: =('Kwh Reading'!P18-'Kwh Reading'!P17)*1000 -> 910 | P17: =('Kwh Reading'!G18-'Kwh Reading'!G17)*1000 -> 980 | Q17: =('Kwh Reading'!Q18-'Kwh Reading'!Q17)*1000 -> 750 | R17: =('Kwh Reading'!N18-'Kwh Reading'!N17)*1000 -> 780 | S17: ='Kwh Reading'!E18-'Kwh Reading'!E17 -> 2937.59 | T17: ='Kwh Reading'!D18-'Kwh Reading'!D17 -> 2460.42 | U17: =('Kwh Reading'!O18-'Kwh Reading'!O17)*1000 -> 220 | V17: =B17-(SUM(C17:U17)) -> 5591.99
A18: ='Kwh Reading'!A18 -> 44270 | B18: =TOTAL!E16 -> 21920 | C18: =('Kwh Reading'!T19-'Kwh Reading'!T18)*1000 -> 400 | D18: =('Kwh Reading'!F19-'Kwh Reading'!F18)*1000000 -> 2600 | E18: =('Kwh Reading'!C19-'Kwh Reading'!C18)*1000 -> 250 | F18: =('Kwh Reading'!J19-'Kwh Reading'!J18)*1000 -> 320 | G18: =('Kwh Reading'!K19-'Kwh Reading'!K18)*1000 -> 600 | H18: =('Kwh Reading'!L19-'Kwh Reading'!L18)*1000 -> 250 | I18: =('Kwh Reading'!R19-'Kwh Reading'!R18)*1000 -> 310 | J18: =('Kwh Reading'!S19-'Kwh Reading'!S18)*1000 -> 960 | K18: =('Kwh Reading'!I19-'Kwh Reading'!I18)*1000 -> 320 | L18: =('Kwh Reading'!B19-'Kwh Reading'!B18)*1000 -> 1310 | M18: =('Kwh Reading'!M19-'Kwh Reading'!M18)*1000 -> 700 | N18: =('Kwh Reading'!H19-'Kwh Reading'!H18)*1000 -> 960 | O18: =('Kwh Reading'!P19-'Kwh Reading'!P18)*1000 -> 920 | P18: =('Kwh Reading'!G19-'Kwh Reading'!G18)*1000 -> 960 | Q18: =('Kwh Reading'!Q19-'Kwh Reading'!Q18)*1000 -> 740 | R18: =('Kwh Reading'!N19-'Kwh Reading'!N18)*1000 -> 900 | S18: ='Kwh Reading'!E19-'Kwh Reading'!E18 -> 3027.21 | T18: ='Kwh Reading'!D19-'Kwh Reading'!D18 -> 2257 | U18: =('Kwh Reading'!O19-'Kwh Reading'!O18)*1000 -> 230 | V18: =B18-(SUM(C18:U18)) -> 3905.79
A19: ='Kwh Reading'!A19 -> 44271 | B19: =TOTAL!E17 -> 21260 | C19: =('Kwh Reading'!T20-'Kwh Reading'!T19)*1000 -> 530 | D19: =('Kwh Reading'!F20-'Kwh Reading'!F19)*1000000 -> 2200 | E19: =('Kwh Reading'!C20-'Kwh Reading'!C19)*1000 -> 210 | F19: =('Kwh Reading'!J20-'Kwh Reading'!J19)*1000 -> 240 | G19: =('Kwh Reading'!K20-'Kwh Reading'!K19)*1000 -> 200 | H19: =('Kwh Reading'!L20-'Kwh Reading'!L19)*1000 -> 170 | I19: =('Kwh Reading'!R20-'Kwh Reading'!R19)*1000 -> 220 | J19: =('Kwh Reading'!S20-'Kwh Reading'!S19)*1000 -> -660 | K19: =('Kwh Reading'!I20-'Kwh Reading'!I19)*1000 -> 290 | L19: =('Kwh Reading'!B20-'Kwh Reading'!B19)*1000 -> 1210 | M19: =('Kwh Reading'!M20-'Kwh Reading'!M19)*1000 -> 590 | N19: =('Kwh Reading'!H20-'Kwh Reading'!H19)*1000 -> 820 | O19: =('Kwh Reading'!P20-'Kwh Reading'!P19)*1000 -> 850 | P19: =('Kwh Reading'!G20-'Kwh Reading'!G19)*1000 -> 850 | Q19: =('Kwh Reading'!Q20-'Kwh Reading'!Q19)*1000 -> 660 | R19: =('Kwh Reading'!N20-'Kwh Reading'!N19)*1000 -> 750 | S19: ='Kwh Reading'!E20-'Kwh Reading'!E19 -> 2660.48 | T19: ='Kwh Reading'!D20-'Kwh Reading'!D19 -> 1864.13 | U19: =('Kwh Reading'!O20-'Kwh Reading'!O19)*1000 -> 210 | V19: =B19-(SUM(C19:U19)) -> 7395.39
A20: ='Kwh Reading'!A20 -> 44272 | B20: =TOTAL!E18 -> 21260 | C20: =('Kwh Reading'!T21-'Kwh Reading'!T20)*1000 -> 510 | D20: =('Kwh Reading'!F21-'Kwh Reading'!F20)*1000000 -> 2400 | E20: =('Kwh Reading'!C21-'Kwh Reading'!C20)*1000 -> 230 | F20: =('Kwh Reading'!J21-'Kwh Reading'!J20)*1000 -> 250 | G20: =('Kwh Reading'!K21-'Kwh Reading'!K20)*1000 -> 370 | H20: =('Kwh Reading'!L21-'Kwh Reading'!L20)*1000 -> 230 | I20: =('Kwh Reading'!R21-'Kwh Reading'!R20)*1000 -> 150 | J20: =('Kwh Reading'!S21-'Kwh Reading'!S20)*1000 -> 140 | K20: =('Kwh Reading'!I21-'Kwh Reading'!I20)*1000 -> 290 | L20: =('Kwh Reading'!B21-'Kwh Reading'!B20)*1000 -> 1240 | M20: =('Kwh Reading'!M21-'Kwh Reading'!M20)*1000 -> 630 | N20: =('Kwh Reading'!H21-'Kwh Reading'!H20)*1000 -> 870 | O20: =('Kwh Reading'!P21-'Kwh Reading'!P20)*1000 -> 960 | P20: =('Kwh Reading'!G21-'Kwh Reading'!G20)*1000 -> 920 | Q20: =('Kwh Reading'!Q21-'Kwh Reading'!Q20)*1000 -> 770 | R20: =('Kwh Reading'!N21-'Kwh Reading'!N20)*1000 -> 870 | S20: ='Kwh Reading'!E21-'Kwh Reading'!E20 -> 2983.74 | T20: ='Kwh Reading'!D21-'Kwh Reading'!D20 -> 2111.33 | U20: =('Kwh Reading'!O21-'Kwh Reading'!O20)*1000 -> 220 | V20: =B20-(SUM(C20:U20)) -> 5114.93
... A34: ='Kwh Reading'!A34 -> 44286 | B34: =TOTAL!E32 -> 0 | C34: =('Kwh Reading'!T35-'Kwh Reading'!T34)*1000 -> 0 | D34: =('Kwh Reading'!F35-'Kwh Reading'!F34)*1000000 -> 0 | E34: =('Kwh Reading'!C35-'Kwh Reading'!C34)*1000 -> 0 | F34: =('Kwh Reading'!J35-'Kwh Reading'!J34)*1000 -> 0 | G34: =('Kwh Reading'!K35-'Kwh Reading'!K34)*1000 -> 0 | H34: =('Kwh Reading'!L35-'Kwh Reading'!L34)*1000 -> 0 | I34: =('Kwh Reading'!R35-'Kwh Reading'!R34)*1000 -> 0 | J34: =('Kwh Reading'!S35-'Kwh Reading'!S34)*1000 -> 0 | K34: =('Kwh Reading'!I35-'Kwh Reading'!I34)*1000 -> 0 | L34: =('Kwh Reading'!B35-'Kwh Reading'!B34)*1000 -> 0 | M34: =('Kwh Reading'!M35-'Kwh Reading'!M34)*1000 -> 0 | N34: =('Kwh Reading'!H35-'Kwh Reading'!H34)*1000 -> 0 | O34: =('Kwh Reading'!P35-'Kwh Reading'!P34)*1000 -> 0 | P34: =('Kwh Reading'!G35-'Kwh Reading'!G34)*1000 -> 0 | Q34: =('Kwh Reading'!Q35-'Kwh Reading'!Q34)*1000 -> 0 | R34: =('Kwh Reading'!N35-'Kwh Reading'!N34)*1000 -> 0 | S34: ='Kwh Reading'!E35-'Kwh Reading'!E34 -> 0 | T34: ='Kwh Reading'!D35-'Kwh Reading'!D34 -> 0 | U34: =('Kwh Reading'!O35-'Kwh Reading'!O34)*1000 -> 0 | V34: =B34-(SUM(C34:U34)) -> 0
A35: Total | B35: =SUM(B4:B34) -> 568510 | C35: =SUM(C4:C34) -> -364120 | D35: =SUM(D4:D34) -> -2084000 | E35: =SUM(E4:E34) -> -202200 | F35: =SUM(F4:F34) -> -290290 | G35: =SUM(G4:G34) -> -305370 | H35: =SUM(H4:H34) -> -209050 | I35: =SUM(I4:I34) -> -124010 | ... V35: =SUM(V4:V34) -> 23224823

Sheet Kwh area wise 
A2: Month | B2: Total KWH | C2: Reef Club Kitchen KWH | D2: Main Kitchen KWH | E2: Pastry Kitchen KWH | F2: Laundry KWH | G2: STP KWH | H2: Kuda Huraa Accomodation KWH | I2: Guest Room Beach Pavilion & Beach Bungalow KWH | J2: Guest Room Water Bungalow KWH | K2: Spa KWH | L2: Others KWH
A3: ='Kwh Reading'!A4 -> 44256 | B3: =TOTAL!E2 -> 22070 | C3: ='Kwh Consumption'!C4 -> 510 | D3: ='Kwh Consumption'!D4 -> 2300 | E3: ='Kwh Consumption'!E4 -> 250 | F3: =('Kwh Consumption'!F4+'Kwh Consumption'!G4+'Kwh Consumption'!H4) -> 820 | G3: =('Kwh Consumption'!I4+'Kwh Consumption'!J4) -> 191 | H3: =('Kwh Consumption'!K4+'Kwh Consumption'!L4) -> 1520 | I3: =('Kwh Consumption'!M4+'Kwh Consumption'!N4+'Kwh Consumption'!O4+'Kwh Consumption'!P4+'Kwh Consumption'!Q4+'Kwh Consumption'!R4) -> 5250 | J3: =('Kwh Consumption'!S4+'Kwh Consumption'!T4) -> 5206.99 | K3: ='Kwh Consumption'!U4 -> 250 | L3: =B3-C3-D3-E3-F3-G3-H3-I3-J3-K3 -> 5772.01
A4: ='Kwh Reading'!A5 -> 44257 | B4: =TOTAL!E3 -> 23210 | C4: ='Kwh Consumption'!C5 -> 500 | D4: ='Kwh Consumption'!D5 -> 2400 | E4: ='Kwh Consumption'!E5 -> 250 | F4: =('Kwh Consumption'!F5+'Kwh Consumption'!G5+'Kwh Consumption'!H5) -> 940 | G4: =('Kwh Consumption'!I5+'Kwh Consumption'!J5) -> 218 | H4: =('Kwh Consumption'!K5+'Kwh Consumption'!L5) -> 1540 | I4: =('Kwh Consumption'!M5+'Kwh Consumption'!N5+'Kwh Consumption'!O5+'Kwh Consumption'!P5+'Kwh Consumption'!Q5+'Kwh Consumption'!R5) -> 5240 | J4: =('Kwh Consumption'!S5+'Kwh Consumption'!T5) -> 5009.84 | K4: ='Kwh Consumption'!U5 -> 310 | L4: =B4-C4-D4-E4-F4-G4-H4-I4-J4-K4 -> 6802.16
A5: ='Kwh Reading'!A6 -> 44258 | B5: =TOTAL!E4 -> 22360 | C5: ='Kwh Consumption'!C6 -> 520 | D5: ='Kwh Consumption'!D6 -> 2500 | E5: ='Kwh Consumption'!E6 -> 240 | F5: =('Kwh Consumption'!F6+'Kwh Consumption'!G6+'Kwh Consumption'!H6) -> 1000 | G5: =('Kwh Consumption'!I6+'Kwh Consumption'!J6) -> 170 | H5: =('Kwh Consumption'!K6+'Kwh Consumption'!L6) -> 1490 | I5: =('Kwh Consumption'!M6+'Kwh Consumption'!N6+'Kwh Consumption'!O6+'Kwh Consumption'!P6+'Kwh Consumption'!Q6+'Kwh Consumption'!R6) -> 5030 | J5: =('Kwh Consumption'!S6+'Kwh Consumption'!T6) -> 5053.74 | K5: ='Kwh Consumption'!U6 -> 250 | L5: =B5-C5-D5-E5-F5-G5-H5-I5-J5-K5 -> 6106.26
A6: ='Kwh Reading'!A7 -> 44259 | B6: =TOTAL!E5 -> 22910 | C6: ='Kwh Consumption'!C7 -> 520 | D6: ='Kwh Consumption'!D7 -> 2400 | E6: ='Kwh Consumption'!E7 -> 230 | F6: =('Kwh Consumption'!F7+'Kwh Consumption'!G7+'Kwh Consumption'!H7) -> 990 | G6: =('Kwh Consumption'!I7+'Kwh Consumption'!J7) -> 143 | H6: =('Kwh Consumption'!K7+'Kwh Consumption'!L7) -> 1460 | I6: =('Kwh Consumption'!M7+'Kwh Consumption'!N7+'Kwh Consumption'!O7+'Kwh Consumption'!P7+'Kwh Consumption'!Q7+'Kwh Consumption'!R7) -> 5220 | J6: =('Kwh Consumption'!S7+'Kwh Consumption'!T7) -> 5383.8 | K6: ='Kwh Consumption'!U7 -> 330 | L6: =B6-C6-D6-E6-F6-G6-H6-I6-J6-K6 -> 6233.2
A7: ='Kwh Reading'!A8 -> 44260 | B7: =TOTAL!E6 -> 23110 | C7: ='Kwh Consumption'!C8 -> 510 | D7: ='Kwh Consumption'!D8 -> 2300 | E7: ='Kwh Consumption'!E8 -> 250 | F7: =('Kwh Consumption'!F8+'Kwh Consumption'!G8+'Kwh Consumption'!H8) -> 890 | G7: =('Kwh Consumption'!I8+'Kwh Consumption'!J8) -> 307 | H7: =('Kwh Consumption'!K8+'Kwh Consumption'!L8) -> 1570 | I7: =('Kwh Consumption'!M8+'Kwh Consumption'!N8+'Kwh Consumption'!O8+'Kwh Consumption'!P8+'Kwh Consumption'!Q8+'Kwh Consumption'!R8) -> 5520 | J7: =('Kwh Consumption'!S8+'Kwh Consumption'!T8) -> 5533.62 | K7: ='Kwh Consumption'!U8 -> 260 | L7: =B7-C7-D7-E7-F7-G7-H7-I7-J7-K7 -> 5969.38
A8: ='Kwh Reading'!A9 -> 44261 | B8: =TOTAL!E7 -> 22680 | C8: ='Kwh Consumption'!C9 -> 500 | D8: ='Kwh Consumption'!D9 -> 2400 | E8: ='Kwh Consumption'!E9 -> 250 | F8: =('Kwh Consumption'!F9+'Kwh Consumption'!G9+'Kwh Consumption'!H9) -> 960 | G8: =('Kwh Consumption'!I9+'Kwh Consumption'!J9) -> 330 | H8: =('Kwh Consumption'!K9+'Kwh Consumption'!L9) -> 1680 | I8: =('Kwh Consumption'!M9+'Kwh Consumption'!N9+'Kwh Consumption'!O9+'Kwh Consumption'!P9+'Kwh Consumption'!Q9+'Kwh Consumption'!R9) -> 5290 | J8: =('Kwh Consumption'!S9+'Kwh Consumption'!T9) -> 5060.93 | K8: ='Kwh Consumption'!U9 -> 230 | L8: =B8-C8-D8-E8-F8-G8-H8-I8-J8-K8 -> 5979.07
A9: ='Kwh Reading'!A10 -> 44262 | B9: =TOTAL!E8 -> 21100 | C9: ='Kwh Consumption'!C10 -> 480 | D9: ='Kwh Consumption'!D10 -> 2300 | E9: ='Kwh Consumption'!E10 -> 210 | F9: =('Kwh Consumption'!F10+'Kwh Consumption'!G10+'Kwh Consumption'!H10) -> 810 | G9: =('Kwh Consumption'!I10+'Kwh Consumption'!J10) -> 150 | H9: =('Kwh Consumption'!K10+'Kwh Consumption'!L10) -> 1590 | I9: =('Kwh Consumption'!M10+'Kwh Consumption'!N10+'Kwh Consumption'!O10+'Kwh Consumption'!P10+'Kwh Consumption'!Q10+'Kwh Consumption'!R10) -> 4990 | J9: =('Kwh Consumption'!S10+'Kwh Consumption'!T10) -> 4677.96 | K9: ='Kwh Consumption'!U10 -> 220 | L9: =B9-C9-D9-E9-F9-G9-H9-I9-J9-K9 -> 5672.04
A10: ='Kwh Reading'!A11 -> 44263 | B10: =TOTAL!E9 -> 21140 | C10: ='Kwh Consumption'!C11 -> 490 | D10: ='Kwh Consumption'!D11 -> 2300 | E10: ='Kwh Consumption'!E11 -> 250 | F10: =('Kwh Consumption'!F11+'Kwh Consumption'!G11+'Kwh Consumption'!H11) -> 630 | G10: =('Kwh Consumption'!I11+'Kwh Consumption'!J11) -> 180 | H10: =('Kwh Consumption'!K11+'Kwh Consumption'!L11) -> 1460 | I10: =('Kwh Consumption'!M11+'Kwh Consumption'!N11+'Kwh Consumption'!O11+'Kwh Consumption'!P11+'Kwh Consumption'!Q11+'Kwh Consumption'!R11) -> 4960 | J10: =('Kwh Consumption'!S11+'Kwh Consumption'!T11) -> 5030.82 | K10: ='Kwh Consumption'!U11 -> 250 | L10: =B10-C10-D10-E10-F10-G10-H10-I10-J10-K10 -> 5589.18
A11: ='Kwh Reading'!A12 -> 44264 | B11: =TOTAL!E10 -> 21810 | C11: ='Kwh Consumption'!C12 -> 690 | D11: ='Kwh Consumption'!D12 -> 2400 | E11: ='Kwh Consumption'!E12 -> 220 | F11: =('Kwh Consumption'!F12+'Kwh Consumption'!G12+'Kwh Consumption'!H12) -> 610 | G11: =('Kwh Consumption'!I12+'Kwh Consumption'!J12) -> 50 | H11: =('Kwh Consumption'!K12+'Kwh Consumption'!L12) -> 1400 | I11: =('Kwh Consumption'!M12+'Kwh Consumption'!N12+'Kwh Consumption'!O12+'Kwh Consumption'!P12+'Kwh Consumption'!Q12+'Kwh Consumption'!R12) -> 5040 | J11: =('Kwh Consumption'!S12+'Kwh Consumption'!T12) -> 5076.22 | K11: ='Kwh Consumption'!U12 -> 220 | L11: =B11-C11-D11-E11-F11-G11-H11-I11-J11-K11 -> 6103.78
A12: ='Kwh Reading'!A13 -> 44265 | B12: =TOTAL!E11 -> 20780 | C12: ='Kwh Consumption'!C13 -> 290 | D12: ='Kwh Consumption'!D13 -> 2400 | E12: ='Kwh Consumption'!E13 -> 230 | F12: =('Kwh Consumption'!F13+'Kwh Consumption'!G13+'Kwh Consumption'!H13) -> 820 | G12: =('Kwh Consumption'!I13+'Kwh Consumption'!J13) -> 240 | H12: =('Kwh Consumption'!K13+'Kwh Consumption'!L13) -> 1520 | I12: =('Kwh Consumption'!M13+'Kwh Consumption'!N13+'Kwh Consumption'!O13+'Kwh Consumption'!P13+'Kwh Consumption'!Q13+'Kwh Consumption'!R13) -> 4600 | J12: =('Kwh Consumption'!S13+'Kwh Consumption'!T13) -> 5129.55 | K12: ='Kwh Consumption'!U13 -> 230 | L12: =B12-C12-D12-E12-F12-G12-H12-I12-J12-K12 -> 5320.45
A13: ='Kwh Reading'!A14 -> 44266 | B13: =TOTAL!E12 -> 18450 | C13: ='Kwh Consumption'!C14 -> 430 | D13: ='Kwh Consumption'!D14 -> 2100 | E13: ='Kwh Consumption'!E14 -> 220 | F13: =('Kwh Consumption'!F14+'Kwh Consumption'!G14+'Kwh Consumption'!H14) -> 700 | G13: =('Kwh Consumption'!I14+'Kwh Consumption'!J14) -> 340 | H13: =('Kwh Consumption'!K14+'Kwh Consumption'!L14) -> 1110 | I13: =('Kwh Consumption'!M14+'Kwh Consumption'!N14+'Kwh Consumption'!O14+'Kwh Consumption'!P14+'Kwh Consumption'!Q14+'Kwh Consumption'!R14) -> 3080 | J13: =('Kwh Consumption'!S14+'Kwh Consumption'!T14) -> 3749.52 | K13: ='Kwh Consumption'!U14 -> 220 | L13: =B13-C13-D13-E13-F13-G13-H13-I13-J13-K13 -> 6500.48
A14: ='Kwh Reading'!A15 -> 44267 | B14: =TOTAL!E13 -> 21800 | C14: ='Kwh Consumption'!C15 -> 240 | D14: ='Kwh Consumption'!D15 -> 2400 | E14: ='Kwh Consumption'!E15 -> 260 | F14: =('Kwh Consumption'!F15+'Kwh Consumption'!G15+'Kwh Consumption'!H15) -> 780 | G14: =('Kwh Consumption'!I15+'Kwh Consumption'!J15) -> 420 | H14: =('Kwh Consumption'!K15+'Kwh Consumption'!L15) -> 1520 | I14: =('Kwh Consumption'!M15+'Kwh Consumption'!N15+'Kwh Consumption'!O15+'Kwh Consumption'!P15+'Kwh Consumption'!Q15+'Kwh Consumption'!R15) -> 4770 | J14: =('Kwh Consumption'!S15+'Kwh Consumption'!T15) -> 5262.83 | K14: ='Kwh Consumption'!U15 -> 240 | L14: =B14-C14-D14-E14-F14-G14-H14-I14-J14-K14 -> 5907.17
... A33: ='Kwh Reading'!A34 -> 44286 | B33: =TOTAL!E32 -> 0 | C33: ='Kwh Consumption'!C34 -> 0 | D33: ='Kwh Consumption'!D34 -> 0 | E33: ='Kwh Consumption'!E34 -> 0 | F33: =('Kwh Consumption'!F34+'Kwh Consumption'!G34+'Kwh Consumption'!H34) -> 0 | G33: =('Kwh Consumption'!I34+'Kwh Consumption'!J34) -> 0 | H33: =('Kwh Consumption'!K34+'Kwh Consumption'!L34) -> 0 | I33: =('Kwh Consumption'!M34+'Kwh Consumption'!N34+'Kwh Consumption'!O34+'Kwh Consumption'!P34+'Kwh Consumption'!Q34+'Kwh Consumption'!R34) -> 0 | J33: =('Kwh Consumption'!S34+'Kwh Consumption'!T34) -> 0 | K33: ='Kwh Consumption'!U34 -> 0 | L33: =B33-C33-D33-E33-F33-G33-H33-I33-J33-K33 -> 0
A34: Total kwh | B34: =SUM(B3:B33) -> 568510 | C34: =SUM(C3:C33) -> -364120 | D34: =SUM(D3:D33) -> -2084000 | E34: =SUM(E3:E33) -> -202200 | F34: =SUM(F3:F33) -> -804710 | G34: =SUM(G3:G33) -> -223451 | H34: =SUM(H3:H33) -> -1019750 | I34: =SUM(I3:I33) -> -2837040 | ... L34: =SUM(L3:L33) -> 23224823 | M34: =C34+D34+E34+F34+G34+H34+I34+J34+K34+L34 -> 568510
A36: Total $ | B36: =TOTAL!F2 -> 0.14 | C36: =C34*B36 -> -50976.8 | D36: =D34*B36 -> -291760 | E36: =E34*B36 -> -28308 | F36: =F34*B36 -> -112659.4 | G36: =G34*B36 -> -31283.14 | H36: =H34*B36 -> -142765 | I36: =I34*B36 -> -397185.6 | J36: =J34*B36 -> -2099958.3 | K36: =K34*B36 -> -16987.6 | L36: =L34*B36 -> 3251475.3 | M36: =C36+D36+E36+F36+G36+H36+I36+J36+K36+L36 -> 79591.4

Sheet  Kwh area wise $ 
A2: Month | B2: $ /Per KWH | C2: Total $ | D2: Reef Club $ | E2: Kitchen $ | F2: Pastry $ | G2: Laundry $ | H2: STP $ | I2: Kuda Huraa Accomodation $ | J2: Guest Room Beach Pavilion & Beach Bungalow $ | K2: Guest Room Water Bungalow $ | L2: Spa $ | M2: Others $
A3: ='Kwh Reading'!A4 -> 44256 | B3: =TOTAL!F2 -> 0.14 | C3: ='Kwh Consumption'!B4*' Kwh area wise $ '!B3 -> 3089.8 | D3: ='Kwh Consumption'!C4*' Kwh area wise $ '!B3 -> 71.4 | E3: ='Kwh Consumption'!D4*' Kwh area wise $ '!B3 -> 322 | F3: ='Kwh Consumption'!E4*' Kwh area wise $ '!B3 -> 35 | G3: =('Kwh Consumption'!F4+'Kwh Consumption'!G4+'Kwh Consumption'!H4)*' Kwh area wise $ '!B3 -> 114.8 | H3: =('Kwh Consumption'!I4+'Kwh Consumption'!J4)*' Kwh area wise $ '!B3 -> 26.74 | I3: =('Kwh Consumption'!K4+'Kwh Consumption'!L4)*' Kwh area wise $ '!B3 -> 212.8 | J3: =('Kwh Consumption'!M4+'Kwh Consumption'!N4+'Kwh Consumption'!O4+'Kwh Consumption'!P4+'Kwh Consumption'!Q4+'Kwh Consumption'!R4)*' Kwh area wise $ '!B3 -> 735 | K3: =('Kwh Consumption'!S4+'Kwh Consumption'!T4)*' Kwh area wise $ '!B3 -> 728.9786 | L3: ='Kwh Consumption'!U4*' Kwh area wise $ '!B3 -> 35 | M3: ='Kwh Consumption'!V4*' Kwh area wise $ '!B3 -> 808.0814
A4: ='Kwh Reading'!A5 -> 44257 | B4: =TOTAL!F3 -> 0.14 | C4: ='Kwh Consumption'!B5*' Kwh area wise $ '!B4 -> 3249.4 | D4: ='Kwh Consumption'!C5*' Kwh area wise $ '!B4 -> 70 | E4: ='Kwh Consumption'!D5*' Kwh area wise $ '!B4 -> 336 | F4: ='Kwh Consumption'!E5*' Kwh area wise $ '!B4 -> 35 | G4: =('Kwh Consumption'!F5+'Kwh Consumption'!G5+'Kwh Consumption'!H5)*' Kwh area wise $ '!B4 -> 131.6 | H4: =('Kwh Consumption'!I5+'Kwh Consumption'!J5)*' Kwh area wise $ '!B4 -> 30.52 | I4: =('Kwh Consumption'!K5+'Kwh Consumption'!L5)*' Kwh area wise $ '!B4 -> 215.6 | J4: =('Kwh Consumption'!M5+'Kwh Consumption'!N5+'Kwh Consumption'!O5+'Kwh Consumption'!P5+'Kwh Consumption'!Q5+'Kwh Consumption'!R5)*' Kwh area wise $ '!B4 -> 733.6 | K4: =('Kwh Consumption'!S5+'Kwh Consumption'!T5)*' Kwh area wise $ '!B4 -> 701.3776 | L4: ='Kwh Consumption'!U5*' Kwh area wise $ '!B4 -> 43.4 | M4: ='Kwh Consumption'!V5*' Kwh area wise $ '!B4 -> 952.3024
A5: ='Kwh Reading'!A6 -> 44258 | B5: =TOTAL!F4 -> 0.14 | C5: ='Kwh Consumption'!B6*' Kwh area wise $ '!B5 -> 3130.4 | D5: ='Kwh Consumption'!C6*' Kwh area wise $ '!B5 -> 72.8 | E5: ='Kwh Consumption'!D6*' Kwh area wise $ '!B5 -> 350 | F5: ='Kwh Consumption'!E6*' Kwh area wise $ '!B5 -> 33.6 | G5: =('Kwh Consumption'!F6+'Kwh Consumption'!G6+'Kwh Consumption'!H6)*' Kwh area wise $ '!B5 -> 140 | H5: =('Kwh Consumption'!I6+'Kwh Consumption'!J6)*' Kwh area wise $ '!B5 -> 23.8 | I5: =('Kwh Consumption'!K6+'Kwh Consumption'!L6)*' Kwh area wise $ '!B5 -> 208.6 | J5: =('Kwh Consumption'!M6+'Kwh Consumption'!N6+'Kwh Consumption'!O6+'Kwh Consumption'!P6+'Kwh Consumption'!Q6+'Kwh Consumption'!R6)*' Kwh area wise $ '!B5 -> 704.2 | K5: =('Kwh Consumption'!S6+'Kwh Consumption'!T6)*' Kwh area wise $ '!B5 -> 707.5236 | L5: ='Kwh Consumption'!U6*' Kwh area wise $ '!B5 -> 35 | M5: ='Kwh Consumption'!V6*' Kwh area wise $ '!B5 -> 854.8764
A6: ='Kwh Reading'!A7 -> 44259 | B6: =TOTAL!F5 -> 0.14 | C6: ='Kwh Consumption'!B7*' Kwh area wise $ '!B6 -> 3207.4 | D6: ='Kwh Consumption'!C7*' Kwh area wise $ '!B6 -> 72.8 | E6: ='Kwh Consumption'!D7*' Kwh area wise $ '!B6 -> 336 | F6: ='Kwh Consumption'!E7*' Kwh area wise $ '!B6 -> 32.2 | G6: =('Kwh Consumption'!F7+'Kwh Consumption'!G7+'Kwh Consumption'!H7)*' Kwh area wise $ '!B6 -> 138.6 | H6: =('Kwh Consumption'!I7+'Kwh Consumption'!J7)*' Kwh area wise $ '!B6 -> 20.02 | I6: =('Kwh Consumption'!K7+'Kwh Consumption'!L7)*' Kwh area wise $ '!B6 -> 204.4 | J6: =('Kwh Consumption'!M7+'Kwh Consumption'!N7+'Kwh Consumption'!O7+'Kwh Consumption'!P7+'Kwh Consumption'!Q7+'Kwh Consumption'!R7)*' Kwh area wise $ '!B6 -> 730.8 | K6: =('Kwh Consumption'!S7+'Kwh Consumption'!T7)*' Kwh area wise $ '!B6 -> 753.732 | L6: ='Kwh Consumption'!U7*' Kwh area wise $ '!B6 -> 46.2 | M6: ='Kwh Consumption'!V7*' Kwh area wise $ '!B6 -> 872.648
A7: ='Kwh Reading'!A8 -> 44260 | B7: =TOTAL!F6 -> 0.14 | C7: ='Kwh Consumption'!B8*' Kwh area wise $ '!B7 -> 3235.4 | D7: ='Kwh Consumption'!C8*' Kwh area wise $ '!B7 -> 71.4 | E7: ='Kwh Consumption'!D8*' Kwh area wise $ '!B7 -> 322 | F7: ='Kwh Consumption'!E8*' Kwh area wise $ '!B7 -> 35 | G7: =('Kwh Consumption'!F8+'Kwh Consumption'!G8+'Kwh Consumption'!H8)*' Kwh area wise $ '!B7 -> 124.6 | H7: =('Kwh Consumption'!I8+'Kwh Consumption'!J8)*' Kwh area wise $ '!B7 -> 42.98 | I7: =('Kwh Consumption'!K8+'Kwh Consumption'!L8)*' Kwh area wise $ '!B7 -> 219.8 | J7: =('Kwh Consumption'!M8+'Kwh Consumption'!N8+'Kwh Consumption'!O8+'Kwh Consumption'!P8+'Kwh Consumption'!Q8+'Kwh Consumption'!R8)*' Kwh area wise $ '!B7 -> 772.8 | K7: =('Kwh Consumption'!S8+'Kwh Consumption'!T8)*' Kwh area wise $ '!B7 -> 774.7068 | L7: ='Kwh Consumption'!U8*' Kwh area wise $ '!B7 -> 36.4 | M7: ='Kwh Consumption'!V8*' Kwh area wise $ '!B7 -> 835.7132
A8: ='Kwh Reading'!A9 -> 44261 | B8: =TOTAL!F7 -> 0.14 | C8: ='Kwh Consumption'!B9*' Kwh area wise $ '!B8 -> 3175.2 | D8: ='Kwh Consumption'!C9*' Kwh area wise $ '!B8 -> 70 | E8: ='Kwh Consumption'!D9*' Kwh area wise $ '!B8 -> 336 | F8: ='Kwh Consumption'!E9*' Kwh area wise $ '!B8 -> 35 | G8: =('Kwh Consumption'!F9+'Kwh Consumption'!G9+'Kwh Consumption'!H9)*' Kwh area wise $ '!B8 -> 134.4 | H8: =('Kwh Consumption'!I9+'Kwh Consumption'!J9)*' Kwh area wise $ '!B8 -> 46.2 | I8: =('Kwh Consumption'!K9+'Kwh Consumption'!L9)*' Kwh area wise $ '!B8 -> 235.2 | J8: =('Kwh Consumption'!M9+'Kwh Consumption'!N9+'Kwh Consumption'!O9+'Kwh Consumption'!P9+'Kwh Consumption'!Q9+'Kwh Consumption'!R9)*' Kwh area wise $ '!B8 -> 740.6 | K8: =('Kwh Consumption'!S9+'Kwh Consumption'!T9)*' Kwh area wise $ '!B8 -> 708.5302 | L8: ='Kwh Consumption'!U9*' Kwh area wise $ '!B8 -> 32.2 | M8: ='Kwh Consumption'!V9*' Kwh area wise $ '!B8 -> 837.0698
A9: ='Kwh Reading'!A10 -> 44262 | B9: =TOTAL!F8 -> 0.14 | C9: ='Kwh Consumption'!B10*' Kwh area wise $ '!B9 -> 2954 | D9: ='Kwh Consumption'!C10*' Kwh area wise $ '!B9 -> 67.2 | E9: ='Kwh Consumption'!D10*' Kwh area wise $ '!B9 -> 322 | F9: ='Kwh Consumption'!E10*' Kwh area wise $ '!B9 -> 29.4 | G9: =('Kwh Consumption'!F10+'Kwh Consumption'!G10+'Kwh Consumption'!H10)*' Kwh area wise $ '!B9 -> 113.4 | H9: =('Kwh Consumption'!I10+'Kwh Consumption'!J10)*' Kwh area wise $ '!B9 -> 21 | I9: =('Kwh Consumption'!K10+'Kwh Consumption'!L10)*' Kwh area wise $ '!B9 -> 222.6 | J9: =('Kwh Consumption'!M10+'Kwh Consumption'!N10+'Kwh Consumption'!O10+'Kwh Consumption'!P10+'Kwh Consumption'!Q10+'Kwh Consumption'!R10)*' Kwh area wise $ '!B9 -> 698.6 | K9: =('Kwh Consumption'!S10+'Kwh Consumption'!T10)*' Kwh area wise $ '!B9 -> 654.9144 | L9: ='Kwh Consumption'!U10*' Kwh area wise $ '!B9 -> 30.8 | M9: ='Kwh Consumption'!V10*' Kwh area wise $ '!B9 -> 794.0856
A10: ='Kwh Reading'!A11 -> 44263 | B10: =TOTAL!F9 -> 0.14 | C10: ='Kwh Consumption'!B11*' Kwh area wise $ '!B10 -> 2959.6 | D10: ='Kwh Consumption'!C11*' Kwh area wise $ '!B10 -> 68.6 | E10: ='Kwh Consumption'!D11*' Kwh area wise $ '!B10 -> 322 | F10: ='Kwh Consumption'!E11*' Kwh area wise $ '!B10 -> 35 | G10: =('Kwh Consumption'!F11+'Kwh Consumption'!G11+'Kwh Consumption'!H11)*' Kwh area wise $ '!B10 -> 88.2 | H10: =('Kwh Consumption'!I11+'Kwh Consumption'!J11)*' Kwh area wise $ '!B10 -> 25.2 | I10: =('Kwh Consumption'!K11+'Kwh Consumption'!L11)*' Kwh area wise $ '!B10 -> 204.4 | J10: =('Kwh Consumption'!M11+'Kwh Consumption'!N11+'Kwh Consumption'!O11+'Kwh Consumption'!P11+'Kwh Consumption'!Q11+'Kwh Consumption'!R11)*' Kwh area wise $ '!B10 -> 694.4 | K10: =('Kwh Consumption'!S11+'Kwh Consumption'!T11)*' Kwh area wise $ '!B10 -> 704.3148 | L10: ='Kwh Consumption'!U11*' Kwh area wise $ '!B10 -> 35 | M10: ='Kwh Consumption'!V11*' Kwh area wise $ '!B10 -> 782.4852
A11: ='Kwh Reading'!A12 -> 44264 | B11: =TOTAL!F10 -> 0.14 | C11: ='Kwh Consumption'!B12*' Kwh area wise $ '!B11 -> 3053.4 | D11: ='Kwh Consumption'!C12*' Kwh area wise $ '!B11 -> 96.6 | E11: ='Kwh Consumption'!D12*' Kwh area wise $ '!B11 -> 336 | F11: ='Kwh Consumption'!E12*' Kwh area wise $ '!B11 -> 30.8 | G11: =('Kwh Consumption'!F12+'Kwh Consumption'!G12+'Kwh Consumption'!H12)*' Kwh area wise $ '!B11 -> 85.4 | H11: =('Kwh Consumption'!I12+'Kwh Consumption'!J12)*' Kwh area wise $ '!B11 -> 7 | I11: =('Kwh Consumption'!K12+'Kwh Consumption'!L12)*' Kwh area wise $ '!B11 -> 196 | J11: =('Kwh Consumption'!M12+'Kwh Consumption'!N12+'Kwh Consumption'!O12+'Kwh Consumption'!P12+'Kwh Consumption'!Q12+'Kwh Consumption'!R12)*' Kwh area wise $ '!B11 -> 705.6 | K11: =('Kwh Consumption'!S12+'Kwh Consumption'!T12)*' Kwh area wise $ '!B11 -> 710.6708 | L11: ='Kwh Consumption'!U12*' Kwh area wise $ '!B11 -> 30.8 | M11: ='Kwh Consumption'!V12*' Kwh area wise $ '!B11 -> 854.5292
A12: ='Kwh Reading'!A13 -> 44265 | B12: =TOTAL!F11 -> 0.14 | C12: ='Kwh Consumption'!B13*' Kwh area wise $ '!B12 -> 2909.2 | D12: ='Kwh Consumption'!C13*' Kwh area wise $ '!B12 -> 40.6 | E12: ='Kwh Consumption'!D13*' Kwh area wise $ '!B12 -> 336 | F12: ='Kwh Consumption'!E13*' Kwh area wise $ '!B12 -> 32.2 | G12: =('Kwh Consumption'!F13+'Kwh Consumption'!G13+'Kwh Consumption'!H13)*' Kwh area wise $ '!B12 -> 114.8 | H12: =('Kwh Consumption'!I13+'Kwh Consumption'!J13)*' Kwh area wise $ '!B12 -> 33.6 | I12: =('Kwh Consumption'!K13+'Kwh Consumption'!L13)*' Kwh area wise $ '!B12 -> 212.8 | J12: =('Kwh Consumption'!M13+'Kwh Consumption'!N13+'Kwh Consumption'!O13+'Kwh Consumption'!P13+'Kwh Consumption'!Q13+'Kwh Consumption'!R13)*' Kwh area wise $ '!B12 -> 644 | K12: =('Kwh Consumption'!S13+'Kwh Consumption'!T13)*' Kwh area wise $ '!B12 -> 718.137 | L12: ='Kwh Consumption'!U13*' Kwh area wise $ '!B12 -> 32.2 | M12: ='Kwh Consumption'!V13*' Kwh area wise $ '!B12 -> 744.863
A13: ='Kwh Reading'!A14 -> 44266 | B13: =TOTAL!F12 -> 0.14 | C13: ='Kwh Consumption'!B14*' Kwh area wise $ '!B13 -> 2583 | D13: ='Kwh Consumption'!C14*' Kwh area wise $ '!B13 -> 60.2 | E13: ='Kwh Consumption'!D14*' Kwh area wise $ '!B13 -> 294 | F13: ='Kwh Consumption'!E14*' Kwh area wise $ '!B13 -> 30.8 | G13: =('Kwh Consumption'!F14+'Kwh Consumption'!G14+'Kwh Consumption'!H14)*' Kwh area wise $ '!B13 -> 98 | H13: =('Kwh Consumption'!I14+'Kwh Consumption'!J14)*' Kwh area wise $ '!B13 -> 47.6 | I13: =('Kwh Consumption'!K14+'Kwh Consumption'!L14)*' Kwh area wise $ '!B13 -> 155.4 | J13: =('Kwh Consumption'!M14+'Kwh Consumption'!N14+'Kwh Consumption'!O14+'Kwh Consumption'!P14+'Kwh Consumption'!Q14+'Kwh Consumption'!R14)*' Kwh area wise $ '!B13 -> 431.2 | K13: =('Kwh Consumption'!S14+'Kwh Consumption'!T14)*' Kwh area wise $ '!B13 -> 524.9328 | L13: ='Kwh Consumption'!U14*' Kwh area wise $ '!B13 -> 30.8 | M13: ='Kwh Consumption'!V14*' Kwh area wise $ '!B13 -> 910.0672
A14: ='Kwh Reading'!A15 -> 44267 | B14: =TOTAL!F13 -> 0.14 | C14: ='Kwh Consumption'!B15*' Kwh area wise $ '!B14 -> 3052 | D14: ='Kwh Consumption'!C15*' Kwh area wise $ '!B14 -> 33.6 | E14: ='Kwh Consumption'!D15*' Kwh area wise $ '!B14 -> 336 | F14: ='Kwh Consumption'!E15*' Kwh area wise $ '!B14 -> 36.4 | G14: =('Kwh Consumption'!F15+'Kwh Consumption'!G15+'Kwh Consumption'!H15)*' Kwh area wise $ '!B14 -> 109.2 | H14: =('Kwh Consumption'!I15+'Kwh Consumption'!J15)*' Kwh area wise $ '!B14 -> 58.8 | I14: =('Kwh Consumption'!K15+'Kwh Consumption'!L15)*' Kwh area wise $ '!B14 -> 212.8 | J14: =('Kwh Consumption'!M15+'Kwh Consumption'!N15+'Kwh Consumption'!O15+'Kwh Consumption'!P15+'Kwh Consumption'!Q15+'Kwh Consumption'!R15)*' Kwh area wise $ '!B14 -> 667.8 | K14: =('Kwh Consumption'!S15+'Kwh Consumption'!T15)*' Kwh area wise $ '!B14 -> 736.7962 | L14: ='Kwh Consumption'!U15*' Kwh area wise $ '!B14 -> 33.6 | M14: ='Kwh Consumption'!V15*' Kwh area wise $ '!B14 -> 827.0038
... A33: ='Kwh Reading'!A34 -> 44286 | B33: =TOTAL!F32 -> 0.14 | C33: ='Kwh Consumption'!B34*' Kwh area wise $ '!B33 -> 0 | D33: ='Kwh Consumption'!C34*' Kwh area wise $ '!B33 -> 0 | E33: ='Kwh Consumption'!D34*' Kwh area wise $ '!B33 -> 0 | F33: ='Kwh Consumption'!E34*' Kwh area wise $ '!B33 -> 0 | G33: =('Kwh Consumption'!F34+'Kwh Consumption'!G34+'Kwh Consumption'!H34)*' Kwh area wise $ '!B33 -> 0 | H33: =('Kwh Consumption'!I34+'Kwh Consumption'!J34)*' Kwh area wise $ '!B33 -> 0 | I33: =('Kwh Consumption'!K34+'Kwh Consumption'!L34)*' Kwh area wise $ '!B33 -> 0 | J33: =('Kwh Consumption'!M34+'Kwh Consumption'!N34+'Kwh Consumption'!O34+'Kwh Consumption'!P34+'Kwh Consumption'!Q34+'Kwh Consumption'!R34)*' Kwh area wise $ '!B33 -> 0 | K33: =('Kwh Consumption'!S34+'Kwh Consumption'!T34)*' Kwh area wise $ '!B33 -> 0 | L33: ='Kwh Consumption'!U34*' Kwh area wise $ '!B33 -> 0 | M33: ='Kwh Consumption'!V34*' Kwh area wise $ '!B33 -> 0
A34: Total | C34: =SUM(C3:C33) -> 79591.4 | D34: =SUM(D3:D33) -> -50976.8 | E34: =SUM(E3:E33) -> -291760 | F34: =SUM(F3:F33) -> -28308 | G34: =SUM(G3:G33) -> -112659.4 | H34: =SUM(H3:H33) -> -31283.14 | I34: =SUM(I3:I33) -> -142765 | J34: =SUM(J3:J33) -> -397185.6 | ... M34: =SUM(M3:M33) -> 3251475.3 | N34: =D34+E34+F34+G34+H34+I34+J34+K34+L34+M34 -> 79591.4

Sheet Water Reading
B1: Meter 1 | C1: Meter 2 | D1: Meter 6 | E1: Meter 8 | F1: Meter 7 | G1: Meter 9 | H1: Meter 3 | I1: Meter 5 | J1: Meter 10 | K1: Meter 13 | L1: Meter 16 | M1: Meter 17 | N1: Meter 15 | O1: Meter 14 | P1: Meter 4 | Q1: Meter 11 | R1: Meter 12
A2: Date | B2: Main Meter 1 | C2: Main Meter 2 | D2: Beach Bunglow | E2: Kuda Huraa staff | F2: Bodu hura staff | G2: Laundry | H2: Water Bunglow | I2: Main Kitchen | J2: Second stage | K2: Supply jetty | L2: Staff housing A | M2: Staff housing B | N2: Spa | O2: Staff jetty | P2: Main pool | Q2: Reef club pool | R2: Reef club kitchen
A3: 44256 | B3: 145881 | C3: 102975 | D3: 191438 | E3: 240566 | F3: 66852 | G3: 109390 | H3: 46691 | I3: 58267 | J3: 18657 | K3: 1024 | L3: 16433 | M3: 22429 | N3: 6743 | O3: 1564 | P3: 25975 | Q3: 162 | R3: 5645
A4: 44257 | B4: 146021 | C4: 103127 | D4: 191527 | E4: 240626 | F4: 66852 | G4: 109410 | H4: 46725 | I4: 58342 | J4: 18668 | K4: 1024 | L4: 16441 | M4: 22443 | N4: 6746 | O4: 1566 | P4: 26031 | Q4: 165 | R4: 5651
A5: 44258 | B5: 146232 | C5: 103277 | D5: 191639 | E5: 240680 | F5: 66853 | G5: 109435 | H5: 46804 | I5: 58359 | J5: 18680 | K5: 1024 | L5: 16447 | M5: 22457 | N5: 6754 | O5: 1568 | P5: 26031 | Q5: 170 | R5: 5658
A6: 44259 | B6: 146427 | C6: 103495 | D6: 191820 | E6: 240740 | F6: 66853 | G6: 109459 | H6: 46853 | I6: 58377 | J6: 18691 | K6: 1024 | L6: 16454 | M6: 22471 | N6: 6762 | O6: 1568 | P6: 26031 | Q6: 172 | R6: 5666
A7: 44260 | B7: 146613 | C7: 103692 | D7: 192001 | E7: 240798 | F7: 66853 | G7: 109483 | H7: 46892 | I7: 58395 | J7: 18704 | K7: 1024 | L7: 16462 | M7: 22485 | N7: 6767 | O7: 1570 | P7: 26031 | Q7: 174 | R7: 5673
A8: 44261 | B8: 146875 | C8: 103849 | D8: 192132 | E8: 240871 | F8: 66854 | G8: 109506 | H8: 46932 | I8: 58425 | J8: 18715 | K8: 1024 | L8: 16468 | M8: 22501 | N8: 6772 | O8: 1570 | P8: 26041 | Q8: 177 | R8: 5679
A9: 44262 | B9: 147051 | C9: 103995 | D9: 192241 | E9: 240940 | F9: 66854 | G9: 109529 | H9: 46963 | I9: 58440 | J9: 18727 | K9: 1024 | L9: 16474 | M9: 22516 | N9: 6774 | O9: 1571 | P9: 26041 | Q9: 181 | R9: 5686
A10: 44263 | B10: 147207 | C10: 104194 | D10: 192398 | E10: 241004 | F10: 66854 | G10: 109548 | H10: 47013 | I10: 58483 | J10: 18739 | K10: 1024 | L10: 16481 | M10: 22532 | N10: 6778 | O10: 1572 | P10: 26063 | Q10: 182 | R10: 5693
A11: 44264 | B11: 147328 | C11: 104364 | D11: 192523 | E11: 241033 | F11: 66854 | G11: 109568 | H11: 47054 | I11: 58500 | J11: 18751 | K11: 1024 | L11: 16487 | M11: 22547 | N11: 6779 | O11: 1572 | P11: 26063 | Q11: 190 | R11: 5699
A12: 44265 | B12: 147500 | C12: 104517 | D12: 192684 | E12: 241118 | F12: 66855 | G12: 109587 | H12: 47094 | I12: 58513 | J12: 18763 | K12: 1024 | L12: 16493 | M12: 22561 | N12: 6786 | O12: 1572 | P12: 26063 | Q12: 193 | R12: 5705
A13: 44266 | B13: 147631 | C13: 104722 | D13: 192810 | E13: 241180 | F13: 66855 | G13: 109608 | H13: 47144 | I13: 58569 | J13: 18775 | K13: 1024 | L13: 16499 | M13: 22574 | N13: 6796 | O13: 1574 | P13: 26096 | Q13: 199 | R13: 5712
A14: 44267 | B14: 147752 | C14: 104912 | D14: 192976 | E14: 241229 | F14: 66855 | G14: 109627 | H14: 47183 | I14: 58584 | J14: 18787 | K14: 1024 | L14: 16505 | M14: 22588 | N14: 6799 | O14: 1574 | P14: 26096 | Q14: 201.8 | R14: 5718
... A29: 44282 | B29: 150068 | C29: 107700 | D29: 195043 | E29: 242078 | F29: 66863 | G29: 109945 | H29: 47828 | I29: 59043 | J29: 18954 | K29: 1024 | L29: 16605 | M29: 22819 | N29: 6834 | O29: 1588 | P29: 26141 | Q29: 267 | R29: 5801
A30: 44283
A31: 44284
A32: 44285
A33: 44286
A34: 44287

Sheet Water consumption
A2: Date | B2: RO production (Ro 1 : 4) | C2: Total Consumption M3 (Meter 1 : 2) | E2: Water Bunglow | G2: Beach bunglow | I2: Main Pool | K2: Main kitchen | M2: Reef club kitchen | O2: Reef club pool | Q2: Bodu Huraa staff | S2: Kuda Huraa staff | U2: Laundry | W2: Second stage | Y2: Total
C3: M3 | D3: % of Total production | E3: M3 | F3: % | G3: M3 | H3: % | I3: M3 | J3: % | K3: M3 | L3: % | M3: M3 | N3: % | O3: M3 | P3: % | Q3: M3 | R3: % | S3: M3 | T3: % | U3: M3 | V3: % | W3: M3 | X3: % | Y3: M3 | Z3: %
A4: ='Water Reading'!A3 -> 44256 | B4: =TOTAL!I2 -> 286.7 | C4: =('Water Reading'!B4-'Water Reading'!B3)+('Water Reading'!C4-'Water Reading'!C3) -> 292 | D4: =C4/B4 -> 1.0184862 | E4: ='Water Reading'!H4-'Water Reading'!H3 -> 34 | F4: =E4/C4 -> 0.11643836 | G4: =('Water Reading'!D4-'Water Reading'!D3)-('Water Reading'!R4-'Water Reading'!R3)-('Water Reading'!Q4-'Water Reading'!Q3) -> 80 | H4: =G4/C4 -> 0.2739726 | I4: ='Water Reading'!P4-'Water Reading'!P3 -> 56 | J4: =I4/C4 -> 0.19178082 | K4: =('Water Reading'!I4-'Water Reading'!I3) -> 75 | L4: =K4/C4 -> 0.25684932 | M4: ='Water Reading'!R4-'Water Reading'!R3 -> 6 | N4: =M4/C4 -> 0.020547945 | O4: ='Water Reading'!Q4-'Water Reading'!Q3 -> 3 | P4: =O4/C4 -> 0.010273973 | Q4: ='Water Reading'!F4-'Water Reading'!F3 -> 0 | R4: =Q4/C4 -> 0 | S4: ='Water Reading'!E4-'Water Reading'!E3 -> 60 | T4: =S4/C4 -> 0.20547945 | U4: ='Water Reading'!G4-'Water Reading'!G3 -> 20 | V4: =U4/C4 -> 0.068493151 | W4: ='Water Reading'!J4-'Water Reading'!J3 -> 11 | X4: =W4/C4 -> 0.037671233 | Y4: =E4+I4+K4+M4+O4+G4+Q4+S4+U4+W4 -> 345 | Z4: =Y4/B4 -> 1.2033484
