Workbook

Sheet TOTAL
A1: Site Name | B1: Day | C1: Month | D1: Year | E1: Total Electricity Kwh | F1: Electricity Tariff ($/Kwh) | G1: Natual Gas (m3) | H1: Natural Gas $/m3 | I1: Water Utility Supply (m3) m3 | J1: Water Utility Supply (m3) $/m3 | K1: Room Nights
A2: Cairo at Nile Plaza | B2: 1 | C2: 3 | D2: 2021 | E2: =(((Submetering!O2+Submetering!P2)*0.842284+Submetering!Q2+(Submetering!M2+Submetering!N2+Submetering!Y2)*0.7362)+(Submetering!O2+Submetering!P2+Submetering!Q2)*0.1488+(Submetering!M2+Submetering!N2+Submetering!Y2)*0.1167+(Submetering!K2+Submetering!L2-Submetering!Z2-Submetering!AA2-Submetering!AB2-Submetering!AC2-Submetering!Q2)+(Submetering!M2+Submetering!N2+Submetering!Y2)*0.1139) -> 69872.762 | F2: 1.27 | G2: =Gas!C3*0.9147 -> 2258.3943 | H2: 3.65 | I2: =Water!C3 -> 680 | J2: 10.03 | K2: =ELECT.!B3 -> 96
A3: Cairo at Nile Plaza | B3: =B2+1 -> 2 | C3: 3 | D3: 2021 | E3: =(((Submetering!O3+Submetering!P3)*0.842284+Submetering!Q3+(Submetering!M3+Submetering!N3+Submetering!Y3)*0.7362)+(Submetering!O3+Submetering!P3+Submetering!Q3)*0.1488+(Submetering!M3+Submetering!N3+Submetering!Y3)*0.1167+(Submetering!K3+Submetering!L3-Submetering!Z3-Submetering!AA3-Submetering!AB3-Submetering!AC3-Submetering!Q3)+(Submetering!M3+Submetering!N3+Submetering!Y3)*0.1139) -> 0 | F3: 1.27 | G3: =Gas!C4*0.9147 -> 0 | H3: 3.65 | I3: =Water!C4 -> 0 | J3: 10.03 | K3: =ELECT.!B4 -> 108
A4: Cairo at Nile Plaza | B4: =B3+1 -> 3 | C4: 3 | D4: 2021 | E4: =(((Submetering!O4+Submetering!P4)*0.842284+Submetering!Q4+(Submetering!M4+Submetering!N4+Submetering!Y4)*0.7362)+(Submetering!O4+Submetering!P4+Submetering!Q4)*0.1488+(Submetering!M4+Submetering!N4+Submetering!Y4)*0.1167+(Submetering!K4+Submetering!L4-Submetering!Z4-Submetering!AA4-Submetering!AB4-Submetering!AC4-Submetering!Q4)+(Submetering!M4+Submetering!N4+Submetering!Y4)*0.1139) -> 0 | F4: 1.27 | G4: =Gas!C5*0.9147 -> 0 | H4: 3.65 | I4: =Water!C5 -> 0 | J4: 10.03 | K4: =ELECT.!B5 -> 98
A5: Cairo at Nile Plaza | B5: =B4+1 -> 4 | C5: 3 | D5: 2021 | E5: =(((Submetering!O5+Submetering!P5)*0.842284+Submetering!Q5+(Submetering!M5+Submetering!N5+Submetering!Y5)*0.7362)+(Submetering!O5+Submetering!P5+Submetering!Q5)*0.1488+(Submetering!M5+Submetering!N5+Submetering!Y5)*0.1167+(Submetering!K5+Submetering!L5-Submetering!Z5-Submetering!AA5-Submetering!AB5-Submetering!AC5-Submetering!Q5)+(Submetering!M5+Submetering!N5+Submetering!Y5)*0.1139) -> 151044.44 | F5: 1.27 | G5: =Gas!C6*0.9147 -> 7345.9557 | H5: 3.65 | I5: =Water!C6 -> 1630 | J5: 10.03 | K5: =ELECT.!B6 -> 108
A6: Cairo at Nile Plaza | B6: =B5+1 -> 5 | C6: 3 | D6: 2021 | E6: =(((Submetering!O6+Submetering!P6)*0.842284+Submetering!Q6+(Submetering!M6+Submetering!N6+Submetering!Y6)*0.7362)+(Submetering!O6+Submetering!P6+Submetering!Q6)*0.1488+(Submetering!M6+Submetering!N6+Submetering!Y6)*0.1167+(Submetering!K6+Submetering!L6-Submetering!Z6-Submetering!AA6-Submetering!AB6-Submetering!AC6-Submetering!Q6)+(Submetering!M6+Submetering!N6+Submetering!Y6)*0.1139) -> 47152.711 | F6: 1.27 | G6: =Gas!C7*0.9147 -> 2672.7534 | H6: 3.65 | I6: =Water!C7 -> 550 | J6: 10.03 | K6: =ELECT.!B7 -> 119
A7: Cairo at Nile Plaza | B7: =B6+1 -> 6 | C7: 3 | D7: 2021 | E7: =(((Submetering!O7+Submetering!P7)*0.842284+Submetering!Q7+(Submetering!M7+Submetering!N7+Submetering!Y7)*0.7362)+(Submetering!O7+Submetering!P7+Submetering!Q7)*0.1488+(Submetering!M7+Submetering!N7+Submetering!Y7)*0.1167+(Submetering!K7+Submetering!L7-Submetering!Z7-Submetering!AA7-Submetering!AB7-Submetering!AC7-Submetering!Q7)+(Submetering!M7+Submetering!N7+Submetering!Y7)*0.1139) -> 33244.983 | F7: 1.27 | G7: =Gas!C8*0.9147 -> 2560.2453 | H7: 3.65 | I7: =Water!C8 -> 540 | J7: 10.03 | K7: =ELECT.!B8 -> 106
A8: Cairo at Nile Plaza | B8: =B7+1 -> 7 | C8: 3 | D8: 2021 | E8: =(((Submetering!O8+Submetering!P8)*0.842284+Submetering!Q8+(Submetering!M8+Submetering!N8+Submetering!Y8)*0.7362)+(Submetering!O8+Submetering!P8+Submetering!Q8)*0.1488+(Submetering!M8+Submetering!N8+Submetering!Y8)*0.1167+(Submetering!K8+Submetering!L8-Submetering!Z8-Submetering!AA8-Submetering!AB8-Submetering!AC8-Submetering!Q8)+(Submetering!M8+Submetering!N8+Submetering!Y8)*0.1139) -> 68321.108 | F8: 1.27 | G8: =Gas!C9*0.9147 -> 3043.2069 | H8: 3.65 | I8: =Water!C9 -> 480 | J8: 10.03 | K8: =ELECT.!B9 -> 93
A9: Cairo at Nile Plaza | B9: =B8+1 -> 8 | C9: 3 | D9: 2021 | E9: =(((Submetering!O9+Submetering!P9)*0.842284+Submetering!Q9+(Submetering!M9+Submetering!N9+Submetering!Y9)*0.7362)+(Submetering!O9+Submetering!P9+Submetering!Q9)*0.1488+(Submetering!M9+Submetering!N9+Submetering!Y9)*0.1167+(Submetering!K9+Submetering!L9-Submetering!Z9-Submetering!AA9-Submetering!AB9-Submetering!AC9-Submetering!Q9)+(Submetering!M9+Submetering!N9+Submetering!Y9)*0.1139) -> 35554.339 | F9: 1.27 | G9: =Gas!C10*0.9147 -> 2746.8441 | H9: 3.65 | I9: =Water!C10 -> 570 | J9: 10.03 | K9: =ELECT.!B10 -> 114
A10: Cairo at Nile Plaza | B10: =B9+1 -> 9 | C10: 3 | D10: 2021 | E10: =(((Submetering!O10+Submetering!P10)*0.842284+Submetering!Q10+(Submetering!M10+Submetering!N10+Submetering!Y10)*0.7362)+(Submetering!O10+Submetering!P10+Submetering!Q10)*0.1488+(Submetering!M10+Submetering!N10+Submetering!Y10)*0.1167+(Submetering!K10+Submetering!L10-Submetering!Z10-Submetering!AA10-Submetering!AB10-Submetering!AC10-Submetering!Q10)+(Submetering!M10+Submetering!N10+Submetering!Y10)*0.1139) -> 62887.392 | F10: 1.27 | G10: =Gas!C11*0.9147 -> 2659.9476 | H10: 3.65 | I10: =Water!C11 -> 1050 | J10: 10.03 | K10: =ELECT.!B11 -> 118
A11: Cairo at Nile Plaza | B11: =B10+1 -> 10 | C11: 3 | D11: 2021 | E11: =(((Submetering!O11+Submetering!P11)*0.842284+Submetering!Q11+(Submetering!M11+Submetering!N11+Submetering!Y11)*0.7362)+(Submetering!O11+Submetering!P11+Submetering!Q11)*0.1488+(Submetering!M11+Submetering!N11+Submetering!Y11)*0.1167+(Submetering!K11+Submetering!L11-Submetering!Z11-Submetering!AA11-Submetering!AB11-Submetering!AC11-Submetering!Q11)+(Submetering!M11+Submetering!N11+Submetering!Y11)*0.1139) -> 52575.471 | F11: 1.27 | G11: =Gas!C12*0.9147 -> 2259.309 | H11: 3.65 | I11: =Water!C12 -> 50 | J11: 10.03 | K11: =ELECT.!B12 -> 146
A12: Cairo at Nile Plaza | B12: =B11+1 -> 11 | C12: 3 | D12: 2021 | E12: =(((Submetering!O12+Submetering!P12)*0.842284+Submetering!Q12+(Submetering!M12+Submetering!N12+Submetering!Y12)*0.7362)+(Submetering!O12+Submetering!P12+Submetering!Q12)*0.1488+(Submetering!M12+Submetering!N12+Submetering!Y12)*0.1167+(Submetering!K12+Submetering!L12-Submetering!Z12-Submetering!AA12-Submetering!AB12-Submetering!AC12-Submetering!Q12)+(Submetering!M12+Submetering!N12+Submetering!Y12)*0.1139) -> 50997.527 | F12: 1.27 | G12: =Gas!C13*0.9147 -> 2627.9331 | H12: 3.65 | I12: =Water!C13 -> 830 | J12: 10.03 | K12: =ELECT.!B13 -> 116
A13: Cairo at Nile Plaza | B13: =B12+1 -> 12 | C13: 3 | D13: 2021 | E13: =(((Submetering!O13+Submetering!P13)*0.842284+Submetering!Q13+(Submetering!M13+Submetering!N13+Submetering!Y13)*0.7362)+(Submetering!O13+Submetering!P13+Submetering!Q13)*0.1488+(Submetering!M13+Submetering!N13+Submetering!Y13)*0.1167+(Submetering!K13+Submetering!L13-Submetering!Z13-Submetering!AA13-Submetering!AB13-Submetering!AC13-Submetering!Q13)+(Submetering!M13+Submetering!N13+Submetering!Y13)*0.1139) -> 50755.12 | F13: 1.27 | G13: =Gas!C14*0.9147 -> 1562.3076 | H13: 3.65 | I13: =Water!C14 -> 180 | J13: 10.03 | K13: =ELECT.!B14 -> 110
A14: Cairo at Nile Plaza | B14: =B13+1 -> 13 | C14: 3 | D14: 2021 | E14: =(((Submetering!O14+Submetering!P14)*0.842284+Submetering!Q14+(Submetering!M14+Submetering!N14+Submetering!Y14)*0.7362)+(Submetering!O14+Submetering!P14+Submetering!Q14)*0.1488+(Submetering!M14+Submetering!N14+Submetering!Y14)*0.1167+(Submetering!K14+Submetering!L14-Submetering!Z14-Submetering!AA14-Submetering!AB14-Submetering!AC14-Submetering!Q14)+(Submetering!M14+Submetering!N14+Submetering!Y14)*0.1139) -> 44332.741 | F14: 1.27 | G14: =Gas!C15*0.9147 -> 0 | H14: 3.65 | I14: =Water!C15 -> 400 | J14: 10.03 | K14: =ELECT.!B15 -> 103
A15: Cairo at Nile Plaza | B15: =B14+1 -> 14 | C15: 3 | D15: 2021 | E15: 98 | F15: 1.27 | G15: =Gas!C16*0.9147 -> 0 | H15: 3.65 | I15: =Water!C16 -> 0 | J15: 10.03 | K15: =ELECT.!B16 -> 114
A16: Cairo at Nile Plaza | B16: =B15+1 -> 15 | C16: 3 | D16: 2021 | E16: =(((Submetering!O16+Submetering!P16)*0.842284+Submetering!Q16+(Submetering!M16+Submetering!N16+Submetering!Y16)*0.7362)+(Submetering!O16+Submetering!P16+Submetering!Q16)*0.1488+(Submetering!M16+Submetering!N16+Submetering!Y16)*0.1167+(Submetering!K16+Submetering!L16-Submetering!Z16-Submetering!AA16-Submetering!AB16-Submetering!AC16-Submetering!Q16)+(Submetering!M16+Submetering!N16+Submetering!Y16)*0.1139) -> 323.62992 | F16: 1.27 | G16: =Gas!C17*0.9147 -> 0 | H16: 3.65 | I16: =Water!C17 -> 0 | J16: 10.03 | K16: =ELECT.!B17 -> 132
A17: Cairo at Nile Plaza | B17: =B16+1 -> 16 | C17: 3 | D17: 2021 | E17: =(((Submetering!O17+Submetering!P17)*0.842284+Submetering!Q17+(Submetering!M17+Submetering!N17+Submetering!Y17)*0.7362)+(Submetering!O17+Submetering!P17+Submetering!Q17)*0.1488+(Submetering!M17+Submetering!N17+Submetering!Y17)*0.1167+(Submetering!K17+Submetering!L17-Submetering!Z17-Submetering!AA17-Submetering!AB17-Submetering!AC17-Submetering!Q17)+(Submetering!M17+Submetering!N17+Submetering!Y17)*0.1139) -> 136229.49 | F17: 1.27 | G17: =Gas!C18*0.9147 -> 9136.9383 | H17: 3.65 | I17: =Water!C18 -> 2500 | J17: 10.03 | K17: =ELECT.!B18 -> 97
A18: Cairo at Nile Plaza | B18: =B17+1 -> 17 | C18: 3 | D18: 2021 | E18: 101 | F18: 1.27 | G18: =Gas!C19*0.9147 -> 0 | H18: 3.65 | I18: =Water!C19 -> 0 | J18: 10.03 | K18: =ELECT.!B19 -> 97
A19: Cairo at Nile Plaza | B19: =B18+1 -> 18 | C19: 3 | D19: 2021 | E19: 99 | F19: 1.27 | G19: =Gas!C20*0.9147 -> 0 | H19: 3.65 | I19: =Water!C20 -> 0 | J19: 10.03 | K19: =ELECT.!B20 -> 95
A20: Cairo at Nile Plaza | B20: =B19+1 -> 19 | C20: 3 | D20: 2021 | E20: =(((Submetering!O20+Submetering!P20)*0.842284+Submetering!Q20+(Submetering!M20+Submetering!N20+Submetering!Y20)*0.7362)+(Submetering!O20+Submetering!P20+Submetering!Q20)*0.1488+(Submetering!M20+Submetering!N20+Submetering!Y20)*0.1167+(Submetering!K20+Submetering!L20-Submetering!Z20-Submetering!AA20-Submetering!AB20-Submetering!AC20-Submetering!Q20)+(Submetering!M20+Submetering!N20+Submetering!Y20)*0.1139) -> 170099.94 | F20: 1.27 | G20: =Gas!C21*0.9147 -> 6969.0993 | H20: 3.65 | I20: =Water!C21 -> 1740 | J20: 10.03 | K20: =ELECT.!B21 -> 77
A21: Cairo at Nile Plaza | B21: =B20+1 -> 20 | C21: 3 | D21: 2021 | E21: =(((Submetering!O21+Submetering!P21)*0.842284+Submetering!Q21+(Submetering!M21+Submetering!N21+Submetering!Y21)*0.7362)+(Submetering!O21+Submetering!P21+Submetering!Q21)*0.1488+(Submetering!M21+Submetering!N21+Submetering!Y21)*0.1167+(Submetering!K21+Submetering!L21-Submetering!Z21-Submetering!AA21-Submetering!AB21-Submetering!AC21-Submetering!Q21)+(Submetering!M21+Submetering!N21+Submetering!Y21)*0.1139) -> 45556.535 | F21: 1.27 | G21: =Gas!C22*0.9147 -> 2475.1782 | H21: 3.65 | I21: =Water!C22 -> 580 | J21: 10.03 | K21: =ELECT.!B22 -> 124
A22: Cairo at Nile Plaza | B22: =B21+1 -> 21 | C22: 3 | D22: 2021 | E22: =(((Submetering!O22+Submetering!P22)*0.842284+Submetering!Q22+(Submetering!M22+Submetering!N22+Submetering!Y22)*0.7362)+(Submetering!O22+Submetering!P22+Submetering!Q22)*0.1488+(Submetering!M22+Submetering!N22+Submetering!Y22)*0.1167+(Submetering!K22+Submetering!L22-Submetering!Z22-Submetering!AA22-Submetering!AB22-Submetering!AC22-Submetering!Q22)+(Submetering!M22+Submetering!N22+Submetering!Y22)*0.1139) -> 44139.948 | F22: 1.27 | G22: =Gas!C23*0.9147 -> 2494.3869 | H22: 3.65 | I22: =Water!C23 -> 620 | J22: 10.03 | K22: =ELECT.!B23 -> 111
A23: Cairo at Nile Plaza | B23: =B22+1 -> 22 | C23: 3 | D23: 2021 | E23: =(((Submetering!O23+Submetering!P23)*0.842284+Submetering!Q23+(Submetering!M23+Submetering!N23+Submetering!Y23)*0.7362)+(Submetering!O23+Submetering!P23+Submetering!Q23)*0.1488+(Submetering!M23+Submetering!N23+Submetering!Y23)*0.1167+(Submetering!K23+Submetering!L23-Submetering!Z23-Submetering!AA23-Submetering!AB23-Submetering!AC23-Submetering!Q23)+(Submetering!M23+Submetering!N23+Submetering!Y23)*0.1139) -> 58384.683 | F23: 1.27 | G23: =Gas!C24*0.9147 -> 2624.2743 | H23: 3.65 | I23: =Water!C24 -> 550 | J23: 10.03 | K23: =ELECT.!B24 -> 115
A24: Cairo at Nile Plaza | B24: =B23+1 -> 23 | C24: 3 | D24: 2021 | E24: =(((Submetering!O24+Submetering!P24)*0.842284+Submetering!Q24+(Submetering!M24+Submetering!N24+Submetering!Y24)*0.7362)+(Submetering!O24+Submetering!P24+Submetering!Q24)*0.1488+(Submetering!M24+Submetering!N24+Submetering!Y24)*0.1167+(Submetering!K24+Submetering!L24-Submetering!Z24-Submetering!AA24-Submetering!AB24-Submetering!AC24-Submetering!Q24)+(Submetering!M24+Submetering!N24+Submetering!Y24)*0.1139) -> 53573.23 | F24: 1.27 | G24: =Gas!C25*0.9147 -> 2723.0619 | H24: 3.65 | I24: =Water!C25 -> 800 | J24: 10.03 | K24: =ELECT.!B25 -> 111
A25: Cairo at Nile Plaza | B25: =B24+1 -> 24 | C25: 3 | D25: 2021 | E25: =(((Submetering!O25+Submetering!P25)*0.842284+Submetering!Q25+(Submetering!M25+Submetering!N25+Submetering!Y25)*0.7362)+(Submetering!O25+Submetering!P25+Submetering!Q25)*0.1488+(Submetering!M25+Submetering!N25+Submetering!Y25)*0.1167+(Submetering!K25+Submetering!L25-Submetering!Z25-Submetering!AA25-Submetering!AB25-Submetering!AC25-Submetering!Q25)+(Submetering!M25+Submetering!N25+Submetering!Y25)*0.1139) -> 42704.661 | F25: 1.27 | G25: =Gas!C26*0.9147 -> 1739.7594 | H25: 3.65 | I25: =Water!C26 -> 650 | J25: 10.03 | K25: =ELECT.!B26 -> 89
A26: Cairo at Nile Plaza | B26: =B25+1 -> 25 | C26: 3 | D26: 2021 | E26: =(((Submetering!O26+Submetering!P26)*0.842284+Submetering!Q26+(Submetering!M26+Submetering!N26+Submetering!Y26)*0.7362)+(Submetering!O26+Submetering!P26+Submetering!Q26)*0.1488+(Submetering!M26+Submetering!N26+Submetering!Y26)*0.1167+(Submetering!K26+Submetering!L26-Submetering!Z26-Submetering!AA26-Submetering!AB26-Submetering!AC26-Submetering!Q26)+(Submetering!M26+Submetering!N26+Submetering!Y26)*0.1139) -> 56054.627 | F26: 1.27 | G26: =Gas!C27*0.9147 -> 1419.6144 | H26: 3.65 | I26: =Water!C27 -> 310 | J26: 10.03 | K26: =ELECT.!B27 -> 87
A27: Cairo at Nile Plaza | B27: =B26+1 -> 26 | C27: 3 | D27: 2021 | E27: =(((Submetering!O27+Submetering!P27)*0.842284+Submetering!Q27+(Submetering!M27+Submetering!N27+Submetering!Y27)*0.7362)+(Submetering!O27+Submetering!P27+Submetering!Q27)*0.1488+(Submetering!M27+Submetering!N27+Submetering!Y27)*0.1167+(Submetering!K27+Submetering!L27-Submetering!Z27-Submetering!AA27-Submetering!AB27-Submetering!AC27-Submetering!Q27)+(Submetering!M27+Submetering!N27+Submetering!Y27)*0.1139) -> 39679.483 | F27: 1.27 | G27: =Gas!C28*0.9147 -> 1598.8956 | H27: 3.65 | I27: =Water!C28 -> 980 | J27: 10.03 | K27: =ELECT.!B28 -> 90
A28: Cairo at Nile Plaza | B28: =B27+1 -> 27 | C28: 3 | D28: 2021 | E28: =(((Submetering!O28+Submetering!P28)*0.842284+Submetering!Q28+(Submetering!M28+Submetering!N28+Submetering!Y28)*0.7362)+(Submetering!O28+Submetering!P28+Submetering!Q28)*0.1488+(Submetering!M28+Submetering!N28+Submetering!Y28)*0.1167+(Submetering!K28+Submetering!L28-Submetering!Z28-Submetering!AA28-Submetering!AB28-Submetering!AC28-Submetering!Q28)+(Submetering!M28+Submetering!N28+Submetering!Y28)*0.1139) -> 51621.524 | F28: 1.27 | G28: =Gas!C29*0.9147 -> 1839.4617 | H28: 3.65 | I28: =Water!C29 -> 620 | J28: 10.03 | K28: =ELECT.!B29 -> 91
A29: Cairo at Nile Plaza | B29: =B28+1 -> 28 | C29: 3 | D29: 2021 | E29: =(((Submetering!O29+Submetering!P29)*0.842284+Submetering!Q29+(Submetering!M29+Submetering!N29+Submetering!Y29)*0.7362)+(Submetering!O29+Submetering!P29+Submetering!Q29)*0.1488+(Submetering!M29+Submetering!N29+Submetering!Y29)*0.1167+(Submetering!K29+Submetering!L29-Submetering!Z29-Submetering!AA29-Submetering!AB29-Submetering!AC29-Submetering!Q29)+(Submetering!M29+Submetering!N29+Submetering!Y29)*0.1139) -> 42173.298 | F29: 1.27 | G29: =Gas!C30*0.9147 -> 1819.3383 | H29: 3.65 | I29: =Water!C30 -> 600 | J29: 10.03 | K29: =ELECT.!B30 -> 92
A30: Cairo at Nile Plaza | B30: =B29+1 -> 29 | C30: 3 | D30: 2021 | E30: =(((Submetering!O30+Submetering!P30)*0.842284+Submetering!Q30+(Submetering!M30+Submetering!N30+Submetering!Y30)*0.7362)+(Submetering!O30+Submetering!P30+Submetering!Q30)*0.1488+(Submetering!M30+Submetering!N30+Submetering!Y30)*0.1167+(Submetering!K30+Submetering!L30-Submetering!Z30-Submetering!AA30-Submetering!AB30-Submetering!AC30-Submetering!Q30)+(Submetering!M30+Submetering!N30+Submetering!Y30)*0.1139) -> 33717.642 | F30: 1.27 | G30: =Gas!C31*0.9147 -> 1737.0153 | H30: 3.65 | I30: =Water!C31 -> 720 | J30: 10.03 | K30: =ELECT.!B31 -> 90
A31: Cairo at Nile Plaza | B31: =B30+1 -> 30 | C31: 3 | D31: 2021 | E31: =(((Submetering!O31+Submetering!P31)*0.842284+Submetering!Q31+(Submetering!M31+Submetering!N31+Submetering!Y31)*0.7362)+(Submetering!O31+Submetering!P31+Submetering!Q31)*0.1488+(Submetering!M31+Submetering!N31+Submetering!Y31)*0.1167+(Submetering!K31+Submetering!L31-Submetering!Z31-Submetering!AA31-Submetering!AB31-Submetering!AC31-Submetering!Q31)+(Submetering!M31+Submetering!N31+Submetering!Y31)*0.1139) -> 47066.004 | F31: 1.27 | G31: =Gas!C32*0.9147 -> 2709.3414 | H31: 3.65 | I31: =Water!C32 -> 660 | J31: 10.03 | K31: =ELECT.!B32 -> 112
A32: Cairo at Nile Plaza | B32: =B31+1 -> 31 | C32: 3 | D32: 2021 | E32: =(((Submetering!O32+Submetering!P32)*0.842284+Submetering!Q32+(Submetering!M32+Submetering!N32+Submetering!Y32)*0.7362)+(Submetering!O32+Submetering!P32+Submetering!Q32)*0.1488+(Submetering!M32+Submetering!N32+Submetering!Y32)*0.1167+(Submetering!K32+Submetering!L32-Submetering!Z32-Submetering!AA32-Submetering!AB32-Submetering!AC32-Submetering!Q32)+(Submetering!M32+Submetering!N32+Submetering!Y32)*0.1139) -> 41489.547 | F32: 1.27 | G32: =Gas!C33*0.9147 -> 1723.2948 | H32: 3.65 | I32: =Water!C33 -> 740 | J32: 10.03 | K32: =ELECT.!B33 -> 160

Sheet Submetering
A1: Site Name | B1: Day | C1: Month | D1: Year | E1: Main (m3) | F1: Podium (m3) | G1: Hotel (m3) | H1: Large (m3) | I1: Feeder 1 (KWh) | J1: Feeder 2 (KWh) | K1: T1 (KWh) | L1: T2 (KWh) | M1: T3 (KWh) | N1: T4 (KWh) | O1: T5 (KWh) | P1: T7 (KWh) | Q1: New Chiller (KWh) | R1: Hotel (BTU) | S1: B.S (BTU) | T1: LS (BTU) | U1: Mall (BTU) | V1: AHU#25 (BTU) | W1: AHU#9 (BTU) | X1: Room Nights | Y1: Loss (KWH) | Z1: Mall (KWH) | AA1: Citadel (KWH) | AB1: Rotana (KWH) | AC1: CIB (KWH) | AD1: Plaza suits water consumption (M3) | AE1: Hotel water consumption (M3)
A2: Cairo at Nile Plaza | B2: 1 | C2: 3 | D2: 2021 | E2: =Water!C3 -> 680 | F2: =Water!E3 -> 413.1 | G2: =Water!G3 -> 159.3 | H2: =Water!I3 -> 5.994 | I2: =ELECT.!F3 -> 8627 | J2: =ELECT.!H3 -> 65314 | K2: =ELECT.!K3 -> 6009 | L2: =ELECT.!M3 -> 5968 | M2: =ELECT.!O3 -> 2502 | N2: =ELECT.!Q3 -> 7811 | O2: =ELECT.!S3 -> 8799 | P2: =ELECT.!W3 -> 10858 | Q2: =ELECT.!D3 -> 320 | R2: =BTU!C3 -> 4.006 | S2: =BTU!F3 -> 1 | T2: =BTU!I3 -> 4 | U2: =BTU!O3 -> 0.901 | V2: =BTU!L3 -> 0.75 | W2: =BTU!R3 -> 0.91 | X2: =ELECT.!B3 -> 96 | Y2: =(I2+J2)-(K2+L2+M2+N2+O2+P2) -> 31994 | Z2: ='Mall, Citadel, Rotana'!C3+'Mall, Citadel, Rotana'!E3+'Mall, Citadel, Rotana'!G3+'Mall, Citadel, Rotana'!I3 -> 1689 | AA2: ='Mall, Citadel, Rotana'!K3+'Mall, Citadel, Rotana'!M3 -> 640 | AB2: ='Mall, Citadel, Rotana'!O3 -> 73 | AC2: ='Mall, Citadel, Rotana'!Q3+'Mall, Citadel, Rotana'!S3 -> 134 | AD2: =(E2-H2-194)*0.1318 -> 63.264791 | AE2: =E2-H2-AD2-194 -> 416.74121
A3: Cairo at Nile Plaza | B3: =B2+1 -> 2 | C3: 3 | D3: 2021 | E3: =Water!C4 -> 0 | F3: =Water!E4 -> 0 | G3: =Water!G4 -> 0 | H3: =Water!I4 -> 0 | I3: =ELECT.!F4 -> 0 | J3: =ELECT.!H4 -> 0 | K3: =ELECT.!K4 -> 0 | L3: =ELECT.!M4 -> 0 | M3: =ELECT.!O4 -> 0 | N3: =ELECT.!Q4 -> 0 | O3: =ELECT.!S4 -> 0 | P3: =ELECT.!W4*2 -> 0 | Q3: =ELECT.!D4 -> 0 | R3: =BTU!C4 -> 0 | S3: =BTU!F4 -> 0 | T3: =BTU!I4 -> 0 | U3: =BTU!O4 -> 0 | V3: =BTU!L4 -> 0 | W3: =BTU!R4 -> 0 | X3: =ELECT.!B4 -> 108 | Y3: =(I3+J3)-(K3+L3+M3+N3+O3+P3) -> 0 | Z3: ='Mall, Citadel, Rotana'!C4+'Mall, Citadel, Rotana'!E4+'Mall, Citadel, Rotana'!G4+'Mall, Citadel, Rotana'!I4 -> 0 | AA3: ='Mall, Citadel, Rotana'!K4+'Mall, Citadel, Rotana'!M4 -> 0 | AB3: ='Mall, Citadel, Rotana'!O4 -> 0 | AC3: ='Mall, Citadel, Rotana'!Q4+'Mall, Citadel, Rotana'!S4 -> 0 | AD3: =(E3-H3-194)*0.1318 -> -25.5692 | AE3: =E3-H3-AD3-194 -> -168.4308
A4: Cairo at Nile Plaza | B4: =B3+1 -> 3 | C4: 3 | D4: 2021 | E4: =Water!C5 -> 0 | F4: =Water!E5 -> 0 | G4: =Water!G5 -> 0 | H4: =Water!I5 -> 0 | I4: =ELECT.!F5 -> 0 | J4: =ELECT.!H5 -> 0 | K4: =ELECT.!K5 -> 0 | L4: =ELECT.!M5 -> 0 | M4: =ELECT.!O5 -> 0 | N4: =ELECT.!Q5 -> 0 | O4: =ELECT.!S5 -> 0 | P4: =ELECT.!W5*2 -> 0 | Q4: =ELECT.!D5 -> 0 | R4: =BTU!C5 -> 0 | S4: =BTU!F5 -> 0 | T4: =BTU!I5 -> 0 | U4: =BTU!O5 -> 0 | V4: =BTU!L5 -> 0 | W4: =BTU!R5 -> 0 | X4: =ELECT.!B5 -> 98 | Y4: =(I4+J4)-(K4+L4+M4+N4+O4+P4) -> 0 | Z4: ='Mall, Citadel, Rotana'!C5+'Mall, Citadel, Rotana'!E5+'Mall, Citadel, Rotana'!G5+'Mall, Citadel, Rotana'!I5 -> 0 | AA4: ='Mall, Citadel, Rotana'!K5+'Mall, Citadel, Rotana'!M5 -> 0 | AB4: ='Mall, Citadel, Rotana'!O5 -> 0 | AC4: ='Mall, Citadel, Rotana'!Q5+'Mall, Citadel, Rotana'!S5 -> 0 | AD4: =(E4-H4-194)*0.1318 -> -25.5692 | AE4: =E4-H4-AD4-194 -> -168.4308
A5: Cairo at Nile Plaza | B5: =B4+1 -> 4 | C5: 3 | D5: 2021 | E5: =Water!C6 -> 1630 | F5: =Water!E6 -> 731.7 | G5: =Water!G6 -> 502.2 | H5: =Water!I6 -> 13.554 | I5: =ELECT.!F6 -> 25400 | J5: =ELECT.!H6 -> 132340 | K5: =ELECT.!K6 -> 17501 | L5: =ELECT.!M6 -> 18494 | M5: =ELECT.!O6 -> 6416 | N5: =ELECT.!Q6 -> 21474 | O5: =ELECT.!S6 -> 26933 | P5: =ELECT.!W6*2 -> 63864 | Q5: =ELECT.!D6 -> 1280 | R5: =BTU!C6 -> 11.097 | S5: =BTU!F6 -> 2.994 | T5: =BTU!I6 -> 12 | U5: =BTU!O6 -> 28.537 | V5: =BTU!L6 -> 1.34 | W5: =BTU!R6 -> 1.58 | X5: =ELECT.!B6 -> 108 | Y5: =(I5+J5)-(K5+L5+M5+N5+O5+P5) -> 3058 | Z5: ='Mall, Citadel, Rotana'!C6+'Mall, Citadel, Rotana'!E6+'Mall, Citadel, Rotana'!G6+'Mall, Citadel, Rotana'!I6 -> 3237 | AA5: ='Mall, Citadel, Rotana'!K6+'Mall, Citadel, Rotana'!M6 -> 1440 | AB5: ='Mall, Citadel, Rotana'!O6 -> 276 | AC5: ='Mall, Citadel, Rotana'!Q6+'Mall, Citadel, Rotana'!S6 -> 96 | AD5: =(E5-H5-194)*0.1318 -> 187.47838 | AE5: =E5-H5-AD5-194 -> 1234.9676
A6: Cairo at Nile Plaza | B6: =B5+1 -> 5 | C6: 3 | D6: 2021 | E6: =Water!C7 -> 550 | F6: =Water!E7 -> 426.6 | G6: =Water!G7 -> 180.9 | H6: =Water!I7 -> 3.753 | I6: =ELECT.!F7 -> 6938 | J6: =ELECT.!H7 -> 42033 | K6: =ELECT.!K7 -> 5230 | L6: =ELECT.!M7 -> 4953 | M6: =ELECT.!O7 -> 1838 | N6: =ELECT.!Q7 -> 7097 | O6: =ELECT.!S7 -> 8314 | P6: =ELECT.!W7*2 -> 20588 | Q6: =ELECT.!D7 -> 320 | R6: =BTU!C7 -> 3.645 | S6: =BTU!F7 -> 0.543 | T6: =BTU!I7 -> 4 | U6: =BTU!O7 -> 0.985 | V6: =BTU!L7 -> 0.06 | W6: =BTU!R7 -> 0.07 | X6: =ELECT.!B7 -> 119 | Y6: =(I6+J6)-(K6+L6+M6+N6+O6+P6) -> 951 | Z6: ='Mall, Citadel, Rotana'!C7+'Mall, Citadel, Rotana'!E7+'Mall, Citadel, Rotana'!G7+'Mall, Citadel, Rotana'!I7 -> 846 | AA6: ='Mall, Citadel, Rotana'!K7+'Mall, Citadel, Rotana'!M7 -> 320 | AB6: ='Mall, Citadel, Rotana'!O7 -> 12 | AC6: ='Mall, Citadel, Rotana'!Q7+'Mall, Citadel, Rotana'!S7 -> 102 | AD6: =(E6-H6-194)*0.1318 -> 46.426155 | AE6: =E6-H6-AD6-194 -> 305.82085
A7: Cairo at Nile Plaza | B7: =B6+1 -> 6 | C7: 3 | D7: 2021 | E7: =Water!C8 -> 540 | F7: =Water!E8 -> 275.4 | G7: =Water!G8 -> 170.1 | H7: =Water!I8 -> 4.833 | I7: =ELECT.!F8 -> 5398 | J7: =ELECT.!H8 -> 32455 | K7: =ELECT.!K8 -> 4355 | L7: =ELECT.!M8 -> 3725 | M7: =ELECT.!O8 -> 1562 | N7: =ELECT.!Q8 -> 5716 | O7: =ELECT.!S8 -> 6294 | P7: =ELECT.!W8*2 -> 15532 | Q7: =ELECT.!D8 -> 480 | R7: =BTU!C8 -> 3.843 | S7: =BTU!F8 -> 0.679 | T7: =BTU!I8 -> 4 | U7: =BTU!O8 -> 1.117 | V7: =BTU!L8 -> 0 | W7: =BTU!R8 -> 0.1 | X7: =ELECT.!B8 -> 106 | Y7: =(I7+J7)-(K7+L7+M7+N7+O7+P7) -> 669 | Z7: ='Mall, Citadel, Rotana'!C8+'Mall, Citadel, Rotana'!E8+'Mall, Citadel, Rotana'!G8+'Mall, Citadel, Rotana'!I8 -> 2653 | AA7: ='Mall, Citadel, Rotana'!K8+'Mall, Citadel, Rotana'!M8 -> 1120 | AB7: ='Mall, Citadel, Rotana'!O8 -> 305 | AC7: ='Mall, Citadel, Rotana'!Q8+'Mall, Citadel, Rotana'!S8 -> 143 | AD7: =(E7-H7-194)*0.1318 -> 44.965811 | AE7: =E7-H7-AD7-194 -> 296.20119
A8: Cairo at Nile Plaza | B8: =B7+1 -> 7 | C8: 3 | D8: 2021 | E8: =Water!C9 -> 480 | F8: =Water!E9 -> 270 | G8: =Water!G9 -> 197.1 | H8: =Water!I9 -> 4.968 | I8: =ELECT.!F9 -> 10737 | J8: =ELECT.!H9 -> 60010 | K8: =ELECT.!K9 -> 7737 | L8: =ELECT.!M9 -> 7470 | M8: =ELECT.!O9 -> 3044 | N8: =ELECT.!Q9 -> 10599 | O8: =ELECT.!S9 -> 11803 | P8: =ELECT.!W9*2 -> 28776 | Q8: =ELECT.!D9 -> 320 | R8: =BTU!C9 -> 3.954 | S8: =BTU!F9 -> 1.154 | T8: =BTU!I9 -> 5 | U8: =BTU!O9 -> 1.158 | V8: =BTU!L9 -> 0.83 | W8: =BTU!R9 -> 0.33 | X8: =ELECT.!B9 -> 93 | Y8: =(I8+J8)-(K8+L8+M8+N8+O8+P8) -> 1318 | Z8: ='Mall, Citadel, Rotana'!C9+'Mall, Citadel, Rotana'!E9+'Mall, Citadel, Rotana'!G9+'Mall, Citadel, Rotana'!I9 -> 893 | AA8: ='Mall, Citadel, Rotana'!K9+'Mall, Citadel, Rotana'!M9 -> 640 | AB8: ='Mall, Citadel, Rotana'!O9 -> 17 | AC8: ='Mall, Citadel, Rotana'!Q9+'Mall, Citadel, Rotana'!S9 -> 65 | AD8: =(E8-H8-194)*0.1318 -> 37.040018 | AE8: =E8-H8-AD8-194 -> 243.99198
A9: Cairo at Nile Plaza | B9: =B8+1 -> 8 | C9: 3 | D9: 2021 | E9: =Water!C10 -> 570 | F9: =Water!E10 -> 245.7 | G9: =Water!G10 -> 194.4 | H9: =Water!I10 -> 4.563 | I9: =ELECT.!F10 -> 6139 | J9: =ELECT.!H10 -> 32747 | K9: =ELECT.!K10 -> 4110 | L9: =ELECT.!M10 -> 4467 | M9: =ELECT.!O10 -> 1570 | N9: =ELECT.!Q10 -> 5995 | O9: =ELECT.!S10 -> 6513 | P9: =ELECT.!W10*2 -> 16382 | Q9: =ELECT.!D10 -> 320 | R9: =BTU!C10 -> 3.945 | S9: =BTU!F10 -> 1.245 | T9: =BTU!I10 -> 4 | U9: =BTU!O10 -> 1.15 | V9: =BTU!L10 -> 1.07 | W9: =BTU!R10 -> 0.94 | X9: =ELECT.!B10 -> 114 | Y9: =(I9+J9)-(K9+L9+M9+N9+O9+P9) -> -151 | Z9: ='Mall, Citadel, Rotana'!C10+'Mall, Citadel, Rotana'!E10+'Mall, Citadel, Rotana'!G10+'Mall, Citadel, Rotana'!I10 -> 1802 | AA9: ='Mall, Citadel, Rotana'!K10+'Mall, Citadel, Rotana'!M10 -> 800 | AB9: ='Mall, Citadel, Rotana'!O10 -> 217 | AC9: ='Mall, Citadel, Rotana'!Q10+'Mall, Citadel, Rotana'!S10 -> 110 | AD9: =(E9-H9-194)*0.1318 -> 48.955397 | AE9: =E9-H9-AD9-194 -> 322.4816
A10: Cairo at Nile Plaza | B10: =B9+1 -> 9 | C10: 3 | D10: 2021 | E10: =Water!C11 -> 1050 | F10: =Water!E11 -> 275.4 | G10: =Water!G11 -> 234.9 | H10: =Water!I11 -> 3.699 | I10: =ELECT.!F11 -> 10231 | J10: =ELECT.!H11 -> 55876 | K10: =ELECT.!K11 -> 7791 | L10: =ELECT.!M11 -> 6747 | M10: =ELECT.!O11 -> 3304 | N10: =ELECT.!Q11 -> 10425 | O10: =ELECT.!S11 -> 10778 | P10: =ELECT.!W11*2 -> 25372 | Q10: =ELECT.!D11 -> 320 | R10: =BTU!C11 -> 3.927 | S10: =BTU!F11 -> 1.375 | T10: =BTU!I11 -> 5 | U10: =BTU!O11 -> 1.293 | V10: =BTU!L11 -> 0.14 | W10: =BTU!R11 -> 0.55 | X10: =ELECT.!B11 -> 118 | Y10: =(I10+J10)-(K10+L10+M10+N10+O10+P10) -> 1690 | Z10: ='Mall, Citadel, Rotana'!C11+'Mall, Citadel, Rotana'!E11+'Mall, Citadel, Rotana'!G11+'Mall, Citadel, Rotana'!I11 -> 1545 | AA10: ='Mall, Citadel, Rotana'!K11+'Mall, Citadel, Rotana'!M11 -> 640 | AB10: ='Mall, Citadel, Rotana'!O11 -> 119 | AC10: ='Mall, Citadel, Rotana'!Q11+'Mall, Citadel, Rotana'!S11 -> 129 | AD10: =(E10-H10-194)*0.1318 -> 112.33327 | AE10: =E10-H10-AD10-194 -> 739.96773
A11: Cairo at Nile Plaza | B11: =B10+1 -> 10 | C11: 3 | D11: 2021 | E11: =Water!C12 -> 50 | F11: =Water!E12 -> 318.6 | G11: =Water!G12 -> 340.2 | H11: =Water!I12 -> 4.158 | I11: =ELECT.!F12 -> 8878 | J11: =ELECT.!H12 -> 46476 | K11: =ELECT.!K12 -> 5637 | L11: =ELECT.!M12 -> 6376 | M11: =ELECT.!O12 -> 2340 | N11: =ELECT.!Q12 -> 9581 | O11: =ELECT.!S12 -> 8946 | P11: =ELECT.!W12*2 -> 21196 | Q11: =ELECT.!D12 -> 480 | R11: =BTU!C12 -> 4.89 | S11: =BTU!F12 -> 1.566 | T11: =BTU!I12 -> 6 | U11: =BTU!O12 -> 1.508 | V11: =BTU!L12 -> 1.35 | W11: =BTU!R12 -> 0.76 | X11: =ELECT.!B12 -> 146 | Y11: =(I11+J11)-(K11+L11+M11+N11+O11+P11) -> 1278 | Z11: ='Mall, Citadel, Rotana'!C12+'Mall, Citadel, Rotana'!E12+'Mall, Citadel, Rotana'!G12+'Mall, Citadel, Rotana'!I12 -> 1495 | AA11: ='Mall, Citadel, Rotana'!K12+'Mall, Citadel, Rotana'!M12 -> 480 | AB11: ='Mall, Citadel, Rotana'!O12 -> 118 | AC11: ='Mall, Citadel, Rotana'!Q12+'Mall, Citadel, Rotana'!S12 -> 50 | AD11: =(E11-H11-194)*0.1318 -> -19.527224 | AE11: =E11-H11-AD11-194 -> -128.63078
A12: Cairo at Nile Plaza | B12: =B11+1 -> 11 | C12: 3 | D12: 2021 | E12: =Water!C13 -> 830 | F12: =Water!E13 -> 291.6 | G12: =Water!G13 -> 275.4 | H12: =Water!I13 -> 4.212 | I12: =ELECT.!F13 -> 9078 | J12: =ELECT.!H13 -> 44509 | K12: =ELECT.!K13 -> 3907 | L12: =ELECT.!M13 -> 6661 | M12: =ELECT.!O13 -> 2240 | N12: =ELECT.!Q13 -> 9256 | O12: =ELECT.!S13 -> 8991 | P12: =ELECT.!W13*2 -> 20664 | Q12: =ELECT.!D13 -> 320 | R12: =BTU!C13 -> 4.427 | S12: =BTU!F13 -> 1.614 | T12: =BTU!I13 -> 5 | U12: =BTU!O13 -> 1.445 | V12: =BTU!L13 -> 1.25 | W12: =BTU!R13 -> 0.66 | X12: =ELECT.!B13 -> 116 | Y12: =(I12+J12)-(K12+L12+M12+N12+O12+P12) -> 1868 | Z12: ='Mall, Citadel, Rotana'!C13+'Mall, Citadel, Rotana'!E13+'Mall, Citadel, Rotana'!G13+'Mall, Citadel, Rotana'!I13 -> 1334 | AA12: ='Mall, Citadel, Rotana'!K13+'Mall, Citadel, Rotana'!M13 -> 480 | AB12: ='Mall, Citadel, Rotana'!O13 -> 16 | AC12: ='Mall, Citadel, Rotana'!Q13+'Mall, Citadel, Rotana'!S13 -> 99 | AD12: =(E12-H12-194)*0.1318 -> 83.269658 | AE12: =E12-H12-AD12-194 -> 548.51834
A13: Cairo at Nile Plaza | B13: =B12+1 -> 12 | C13: 3 | D13: 2021 | E13: =Water!C14 -> 180 | F13: =Water!E14 -> 310.5 | G13: =Water!G14 -> 234.9 | H13: =Water!I14 -> 3.753 | I13: =ELECT.!F14 -> 8539 | J13: =ELECT.!H14 -> 44609 | K13: =ELECT.!K14 -> 5121 | L13: =ELECT.!M14 -> 5982 | M13: =ELECT.!O14 -> 2390 | N13: =ELECT.!Q14 -> 8379 | O13: =ELECT.!S14 -> 9591 | P13: =ELECT.!W14*2 -> 21530 | Q13: =ELECT.!D14 -> 1440 | R13: =BTU!C14 -> 4.318 | S13: =BTU!F14 -> 0.637 | T13: =BTU!I14 -> 5 | U13: =BTU!O14 -> 1.183 | V13: =BTU!L14 -> 1.26 | W13: =BTU!R14 -> 0.43 | X13: =ELECT.!B14 -> 110 | Y13: =(I13+J13)-(K13+L13+M13+N13+O13+P13) -> 155 | Z13: ='Mall, Citadel, Rotana'!C14+'Mall, Citadel, Rotana'!E14+'Mall, Citadel, Rotana'!G14+'Mall, Citadel, Rotana'!I14 -> 1100 | AA13: ='Mall, Citadel, Rotana'!K14+'Mall, Citadel, Rotana'!M14 -> 640 | AB13: ='Mall, Citadel, Rotana'!O14 -> 175 | AC13: ='Mall, Citadel, Rotana'!Q14+'Mall, Citadel, Rotana'!S14 -> 52 | AD13: =(E13-H13-194)*0.1318 -> -2.3398454 | AE13: =E13-H13-AD13-194 -> -15.413155
A14: Cairo at Nile Plaza | B14: =B13+1 -> 13 | C14: 3 | D14: 2021 | E14: =Water!C15 -> 400 | F14: =Water!E15 -> 310.5 | G14: =Water!G15 -> 224.1 | H14: =Water!I15 -> 3.564 | I14: =ELECT.!F15 -> 7137 | J14: =ELECT.!H15 -> 39568 | K14: =ELECT.!K15 -> 3996 | L14: =ELECT.!M15 -> 4868 | M14: =ELECT.!O15 -> 2138 | N14: =ELECT.!Q15 -> 7232 | O14: =ELECT.!S15 -> 8249 | P14: =ELECT.!W15*2 -> 19434 | Q14: =ELECT.!D15 -> 160 | R14: =BTU!C15 -> 4.001 | S14: =BTU!F15 -> 0.628 | T14: =BTU!I15 -> 5 | U14: =BTU!O15 -> 1.312 | V14: =BTU!L15 -> 0.2 | W14: =BTU!R15 -> 0.14 | X14: =ELECT.!B15 -> 103 | Y14: =(I14+J14)-(K14+L14+M14+N14+O14+P14) -> 788 | Z14: ='Mall, Citadel, Rotana'!C15+'Mall, Citadel, Rotana'!E15+'Mall, Citadel, Rotana'!G15+'Mall, Citadel, Rotana'!I15 -> 1200 | AA14: ='Mall, Citadel, Rotana'!K15+'Mall, Citadel, Rotana'!M15 -> 480 | AB14: ='Mall, Citadel, Rotana'!O15 -> 82 | AC14: ='Mall, Citadel, Rotana'!Q15+'Mall, Citadel, Rotana'!S15 -> 50 | AD14: =(E14-H14-194)*0.1318 -> 26.681065 | AE14: =E14-H14-AD14-194 -> 175.75494
... A29: Cairo at Nile Plaza | B29: =B28+1 -> 28 | C29: 3 | D29: 2021 | E29: =Water!C30 -> 600 | F29: =Water!E30 -> 329.4 | G29: =Water!G30 -> 218.7 | H29: =Water!I30 -> 3.159 | I29: =ELECT.!F30 -> 7885 | J29: =ELECT.!H30 -> 36907 | K29: =ELECT.!K30 -> 3907 | L29: =ELECT.!M30 -> 5464 | M29: =ELECT.!O30 -> 2286 | N29: =ELECT.!Q30 -> 4620 | O29: =ELECT.!S30 -> 7744 | P29: =ELECT.!W30*2 -> 17732 | Q29: =ELECT.!D30 -> 320 | R29: =BTU!C30 -> 4.458 | S29: =BTU!F30 -> 1.049 | T29: =BTU!I30 -> 5 | U29: =BTU!O30 -> 1.353 | V29: =BTU!L30 -> 0 | W29: =BTU!R30 -> 0.51 | X29: =ELECT.!B30 -> 92 | Y29: =(I29+J29)-(K29+L29+M29+N29+O29+P29) -> 3039 | Z29: ='Mall, Citadel, Rotana'!C30+'Mall, Citadel, Rotana'!E30+'Mall, Citadel, Rotana'!G30+'Mall, Citadel, Rotana'!I30 -> 1257 | AA29: ='Mall, Citadel, Rotana'!K30+'Mall, Citadel, Rotana'!M30 -> 640 | AB29: ='Mall, Citadel, Rotana'!O30 -> 117 | AC29: ='Mall, Citadel, Rotana'!Q30+'Mall, Citadel, Rotana'!S30 -> 95 | AD29: =(E29-H29-194)*0.1318 -> 53.094444 | AE29: =E29-H29-AD29-194 -> 349.74656
A30: Cairo at Nile Plaza | B30: =B29+1 -> 29 | C30: 3 | D30: 2021 | E30: =Water!C31 -> 720 | F30: =Water!E31 -> 356.4 | G30: =Water!E31 -> 356.4 | H30: =Water!I31 -> 3.456 | I30: =Water!G31 -> 278.1 | J30: =ELECT.!H31 -> 36820 | K30: =Water!I31 -> 3.456 | L30: =Water!J31 -> 1357.956 | M30: =Water!K31 -> 7957.6222 | N30: =Water!L31 -> 0 | O30: =Water!M31 -> 0 | P30: =Water!N31 -> 0 | Q30: =Water!O31 -> 0 | R30: =BTU!C31 -> 4.332 | S30: =BTU!F31 -> 1.188 | T30: =BTU!I31 -> 6 | U30: =BTU!O31 -> 1.391 | V30: =BTU!L31 -> 0 | W30: =BTU!R31 -> 0 | X30: =ELECT.!B31 -> 90 | Y30: =(I30+J30)-(K30+L30+M30+N30+O30+P30) -> 27779.066 | Z30: ='Mall, Citadel, Rotana'!C31+'Mall, Citadel, Rotana'!E31+'Mall, Citadel, Rotana'!G31+'Mall, Citadel, Rotana'!I31 -> 1382 | AA30: ='Mall, Citadel, Rotana'!K31+'Mall, Citadel, Rotana'!M31 -> 480 | AB30: ='Mall, Citadel, Rotana'!O31 -> 123 | AC30: ='Mall, Citadel, Rotana'!Q31+'Mall, Citadel, Rotana'!S31 -> 209 | AD30: =(E30-H30-194)*0.1318 -> 68.871299 | AE30: =E30-H30-AD30-194 -> 453.6727
A31: Cairo at Nile Plaza | B31: =B30+1 -> 30 | C31: 3 | D31: 2021 | E31: =Water!C32 -> 660 | F31: =Water!E32 -> 334.8 | G31: =Water!E32 -> 334.8 | H31: =Water!I32 -> 4.644 | I31: =Water!G32 -> 270 | J31: =ELECT.!H32 -> 50010 | K31: =Water!I32 -> 4.644 | L31: =Water!J32 -> 1269.444 | M31: =Water!K32 -> 7438.9418 | N31: =Water!L32 -> 0 | O31: =Water!M32 -> 0 | P31: =Water!N32 -> 0 | Q31: =Water!O32 -> 0 | R31: =BTU!C32 -> 3.29 | S31: =BTU!F32 -> 1.116 | T31: =BTU!I32 -> 4 | U31: =BTU!O32 -> 1.101 | V31: =BTU!L32 -> 0.74 | W31: =BTU!R32 -> 0.88 | X31: =ELECT.!B32 -> 112 | Y31: =(I31+J31)-(K31+L31+M31+N31+O31+P31) -> 41566.97 | Z31: ='Mall, Citadel, Rotana'!C32+'Mall, Citadel, Rotana'!E32+'Mall, Citadel, Rotana'!G32+'Mall, Citadel, Rotana'!I32 -> 871 | AA31: ='Mall, Citadel, Rotana'!K32+'Mall, Citadel, Rotana'!M32 -> 640 | AB31: ='Mall, Citadel, Rotana'!O32 -> 76 | AC31: ='Mall, Citadel, Rotana'!Q32+'Mall, Citadel, Rotana'!S32 -> 0 | AD31: =(E31-H31-194)*0.1318 -> 60.806721 | AE31: =E31-H31-AD31-194 -> 400.54928
A32: Cairo at Nile Plaza | B32: =B31+1 -> 31 | C32: 3 | D32: 2021 | E32: =Water!C33 -> 740 | F32: =Water!E33 -> 359.1 | G32: =Water!E33 -> 359.1 | H32: =Water!I33 -> 3.348 | I32: =Water!G33 -> 191.7 | J32: =ELECT.!H33 -> 45508 | K32: =Water!I33 -> 3.348 | L32: =Water!J33 -> 1294.148 | M32: =Water!K33 -> 7583.7073 | N32: =Water!L33 -> 0 | O32: =Water!M33 -> 0 | P32: =Water!N33 -> 0 | Q32: =Water!O33 -> 0 | R32: =BTU!C33 -> 4.125 | S32: =BTU!F33 -> 1.291 | T32: =BTU!I33 -> 5 | U32: =BTU!O33 -> 1.172 | V32: =BTU!L33 -> 0.81 | W32: =BTU!R33 -> 0.115 | X32: =ELECT.!B33 -> 160 | Y32: =(I32+J32)-(K32+L32+M32+N32+O32+P32) -> 36818.497 | Z32: ='Mall, Citadel, Rotana'!C33+'Mall, Citadel, Rotana'!E33+'Mall, Citadel, Rotana'!G33+'Mall, Citadel, Rotana'!I33 -> 1712 | AA32: ='Mall, Citadel, Rotana'!K33+'Mall, Citadel, Rotana'!M33 -> 800 | AB32: ='Mall, Citadel, Rotana'!O33 -> 163 | AC32: ='Mall, Citadel, Rotana'!Q33+'Mall, Citadel, Rotana'!S33 -> 61 | AD32: =(E32-H32-194)*0.1318 -> 71.521534 | AE32: =E32-H32-AD32-194 -> 471.13047

Sheet Mall, Citadel, Rotana
A1: Day | B1: R1 | C1: Cons | D1: R2 | E1: Cons | F1: R3 | G1: Cons | H1: R4 | I1: Cons | J1: RO1 | K1: Cons | L1: RO2 | M1: Cons | N1: ROE | O1: Cons | P1: CIB. 1 | Q1: Cons | R1: CIB. E | S1: Cons | T1: Co | U1: Cons
A2: Last | B2: 44890 | D2: 39308 | F2: 20120 | H2: 239183 | J2: 303517 | L2: 24670 | N2: 209638 | P2: 94770 | R2: 55047 | T2: 3539
A3: 44256 | B3: 44897 | C3: =(B3-B2)*800/5 -> 1120 | D3: 39311 | E3: =(D3-D2)*800/5 -> 480 | F3: 20124 | G3: =(F3-F2)*100/5 -> 80 | H3: 239192 | I3: =(H3-H2) -> 9 | J3: =J2 -> 303517 | K3: =(J3-J2)*800/5 -> 0 | L3: 24674 | M3: =(L3-L2)*800/5 -> 640 | N3: 209711 | O3: =N3-N2 -> 73 | P3: 94904 | Q3: =P3-P2 -> 134 | R3: 55047 | S3: 0 | T3: 3541 | U3: =(T3-T2)*800/5 -> 320
A4: 44257 | B4: =B3 -> 44897 | C4: =(B4-B3)*800/5 -> 0 | D4: =D3 -> 39311 | E4: =(D4-D3)*800/5 -> 0 | F4: =F3 -> 20124 | G4: =(F4-F3)*100/5 -> 0 | H4: =H3 -> 239192 | I4: =(H4-H3) -> 0 | J4: =J3 -> 303517 | K4: =(J4-J3)*800/5 -> 0 | L4: =L3 -> 24674 | M4: =(L4-L3)*800/5 -> 0 | N4: =N3 -> 209711 | O4: =N4-N3 -> 0 | P4: =P3 -> 94904 | Q4: =P4-P3 -> 0 | R4: =R3 -> 55047 | S4: =R4-R3 -> 0 | T4: =T3 -> 3541 | U4: =(T4-T3)*800/5 -> 0
A5: 44258 | B5: =B4 -> 44897 | C5: =(B5-B4)*800/5 -> 0 | D5: =D4 -> 39311 | E5: =(D5-D4)*800/5 -> 0 | F5: =F4 -> 20124 | G5: =(F5-F4)*100/5 -> 0 | H5: =H4 -> 239192 | I5: =(H5-H4) -> 0 | J5: =J4 -> 303517 | K5: =(J5-J4)*800/5 -> 0 | L5: =L4 -> 24674 | M5: =(L5-L4)*800/5 -> 0 | N5: =N4 -> 209711 | O5: =N5-N4 -> 0 | P5: =P4 -> 94904 | Q5: =P5-P4 -> 0 | R5: =R4 -> 55047 | S5: =R5-R4 -> 0 | T5: =T4 -> 3541 | U5: =(T5-T4)*800/5 -> 0
A6: 44259 | B6: 44906 | C6: =(B6-B5)*800/5 -> 1440 | D6: 39321 | E6: =(D6-D5)*800/5 -> 1600 | F6: 20131 | G6: =(F6-F5)*100/5 -> 140 | H6: 239249 | I6: =(H6-H5) -> 57 | J6: =J5 -> 303517 | K6: =(J6-J5)*800/5 -> 0 | L6: 24683 | M6: =(L6-L5)*800/5 -> 1440 | N6: 209987 | O6: =N6-N5 -> 276 | P6: 95000 | Q6: =P6-P5 -> 96 | R6: =R5 -> 55047 | S6: =R30-R5 -> 0 | T6: 3546 | U6: =(T6-T5)*800/5 -> 800
A7: 44260 | B7: 44908 | C7: =(B7-B6)*800/5 -> 320 | D7: 39324 | E7: =(D7-D6)*800/5 -> 480 | F7: 20133 | G7: =(F7-F6)*100/5 -> 40 | H7: 239255 | I7: =(H7-H6) -> 6 | J7: =J6 -> 303517 | K7: =(J7-J6)*800/5 -> 0 | L7: 24685 | M7: =(L7-L6)*800/5 -> 320 | N7: 209999 | O7: =N7-N6 -> 12 | P7: 95102 | Q7: =P7-P6 -> 102 | R7: =R6 -> 55047 | S7: =R7-R30 -> 0 | T7: 3547 | U7: =(T7-T6)*800/5 -> 160
A8: 44261 | B8: 44921 | C8: =(B8-B7)*800/5 -> 2080 | D8: 39326 | E8: =(D8-D7)*800/5 -> 320 | F8: 20143 | G8: =(F8-F7)*100/5 -> 200 | H8: 239308 | I8: =(H8-H7) -> 53 | J8: =J7 -> 303517 | K8: =(J8-J7)*800/5 -> 0 | L8: 24692 | M8: =(L8-L7)*800/5 -> 1120 | N8: 210304 | O8: =N8-N7 -> 305 | P8: 95245 | Q8: =P8-P7 -> 143 | R8: =R7 -> 55047 | S8: =R8-R7 -> 0 | T8: 3548 | U8: =(T8-T7)*800/5 -> 160
A9: 44262 | B9: 44923 | C9: =(B9-B8)*800/5 -> 320 | D9: 39329 | E9: =(D9-D8)*800/5 -> 480 | F9: 20147 | G9: =(F9-F8)*100/5 -> 80 | H9: 239321 | I9: =(H9-H8) -> 13 | J9: =J8 -> 303517 | K9: =(J9-J8)*800/5 -> 0 | L9: 24696 | M9: =(L9-L8)*800/5 -> 640 | N9: 210321 | O9: =N9-N8 -> 17 | P9: 95310 | Q9: =P9-P8 -> 65 | R9: =R8 -> 55047 | S9: =R9-R8 -> 0 | T9: 3549 | U9: =(T9-T8)*800/5 -> 160
A10: 44263 | B10: 44931 | C10: =(B10-B9)*800/5 -> 1280 | D10: 39332 | E10: =(D10-D9)*800/5 -> 480 | F10: 20148 | G10: =(F10-F9)*100/5 -> 20 | H10: 239343 | I10: =(H10-H9) -> 22 | J10: =J9 -> 303517 | K10: =(J10-J9)*800/5 -> 0 | L10: 24701 | M10: =(L10-L9)*800/5 -> 800 | N10: 210538 | O10: =N10-N9 -> 217 | P10: 95420 | Q10: =P10-P9 -> 110 | R10: =R9 -> 55047 | S10: =R10-R9 -> 0 | T10: 3550 | U10: =(T10-T9)*800/5 -> 160
A11: 44264 | B11: 44937 | C11: =(B11-B10)*800/5 -> 960 | D11: 39335 | E11: =(D11-D10)*800/5 -> 480 | F11: 20152 | G11: =(F11-F10)*100/5 -> 80 | H11: 239368 | I11: =(H11-H10) -> 25 | J11: =J10 -> 303517 | K11: =(J11-J10)*800/5 -> 0 | L11: 24705 | M11: =(L11-L10)*800/5 -> 640 | N11: 210657 | O11: =N11-N10 -> 119 | P11: 95549 | Q11: =P11-P10 -> 129 | R11: =R10 -> 55047 | S11: =R11-R10 -> 0 | T11: 3552 | U11: =(T11-T10)*800/5 -> 320
A12: 44265 | B12: 44942 | C12: =(B12-B11)*800/5 -> 800 | D12: 39339 | E12: =(D12-D11)*800/5 -> 640 | F12: 20154 | G12: =(F12-F11)*100/5 -> 40 | H12: 239383 | I12: =(H12-H11) -> 15 | J12: =J11 -> 303517 | K12: =(J12-J11)*800/5 -> 0 | L12: 24708 | M12: =(L12-L11)*800/5 -> 480 | N12: 210775 | O12: =N12-N11 -> 118 | P12: 95599 | Q12: =P12-P11 -> 50 | R12: =R11 -> 55047 | S12: =R12-R11 -> 0 | T12: 3553 | U12: =(T12-T11)*800/5 -> 160
A13: 44266 | B13: 44947 | C13: =(B13-B12)*800/5 -> 800 | D13: 39342 | E13: =(D13-D12)*800/5 -> 480 | F13: 20156 | G13: =(F13-F12)*100/5 -> 40 | H13: 239397 | I13: =(H13-H12) -> 14 | J13: =J12 -> 303517 | K13: =(J13-J12)*800/5 -> 0 | L13: 24711 | M13: =(L13-L12)*800/5 -> 480 | N13: 210791 | O13: =N13-N12 -> 16 | P13: 95698 | Q13: =P13-P12 -> 99 | R13: =R12 -> 55047 | S13: =R13-R12 -> 0 | T13: 3554 | U13: =(T13-T12)*800/5 -> 160
A14: 44267 | B14: 44952 | C14: =(B14-B13)*800/5 -> 800 | D14: 39343 | E14: =(D14-D13)*800/5 -> 160 | F14: 20161 | G14: =(F14-F13)*100/5 -> 100 | H14: 239437 | I14: =(H14-H13) -> 40 | J14: =J13 -> 303517 | K14: =(J14-J13)*800/5 -> 0 | L14: 24715 | M14: =(L14-L13)*800/5 -> 640 | N14: 210966 | O14: =N14-N13 -> 175 | P14: 95750 | Q14: =P14-P13 -> 52 | R14: =R13 -> 55047 | S14: =R14-R13 -> 0 | T14: 3555 | U14: =(T14-T13)*800/5 -> 160
A15: 44268 | B15: 44956 | C15: =(B15-B14)*800/5 -> 640 | D15: 39346 | E15: =(D15-D14)*800/5 -> 480 | F15: 20164 | G15: =(F15-F14)*100/5 -> 60 | H15: 239457 | I15: =(H15-H14) -> 20 | J15: =J14 -> 303517 | K15: =(J15-J14)*800/5 -> 0 | L15: 24718 | M15: =(L15-L14)*800/5 -> 480 | N15: 211048 | O15: =N15-N14 -> 82 | P15: 95800 | Q15: =P15-P14 -> 50 | R15: =R14 -> 55047 | S15: =R15-R14 -> 0 | T15: 3557 | U15: =(T15-T14)*800/5 -> 320
A16: 44269 | B16: =B15 -> 44956 | C16: =(B16-B15)*800/5 -> 0 | D16: =D15 -> 39346 | E16: =(D16-D15)*800/5 -> 0 | F16: =F15 -> 20164 | G16: =(F16-F15)*100/5 -> 0 | H16: =H15 -> 239457 | I16: =(H16-H15) -> 0 | J16: =J15 -> 303517 | K16: =(J16-J15)*800/5 -> 0 | L16: =L15 -> 24718 | M16: =(L16-L15)*800/5 -> 0 | N16: =N15 -> 211048 | O16: =N16-N15 -> 0 | P16: 95898 | Q16: =P16-P15 -> 98 | R16: =R15 -> 55047 | S16: =R16-R15 -> 0 | T16: =T15 -> 3557 | U16: =(T16-T15)*800/5 -> 0
A17: 44270 | B17: =B16 -> 44956 | C17: =(B17-B16)*800/5 -> 0 | D17: =D16 -> 39346 | E17: =(D17-D16)*800/5 -> 0 | F17: =F16 -> 20164 | G17: =(F17-F16)*100/5 -> 0 | H17: =H16 -> 239457 | I17: =(H17-H16) -> 0 | J17: =J16 -> 303517 | K17: =(J17-J16)*800/5 -> 0 | L17: =L16 -> 24718 | M17: =(L17-L16)*800/5 -> 0 | N17: =N16 -> 211048 | O17: =N17-N16 -> 0 | P17: 95960 | Q17: =P17-P16 -> 62 | R17: =R16 -> 55047 | S17: =S16 -> 0 | T17: =T16 -> 3557 | U17: =(T17-T16)*800/5 -> 0
A18: 44271 | B18: 44971 | C18: =(B18-B17)*800/5 -> 2400 | D18: 39355 | E18: =(D18-D17)*800/5 -> 1440 | F18: 20174 | G18: =(F18-F17)*100/5 -> 200 | H18: 239545 | I18: =(H18-H17) -> 88 | J18: =J17 -> 303517 | K18: =(J18-J17)*800/5 -> 0 | L18: 24731 | M18: =(L18-L17)*800/5 -> 2080 | N18: 211419 | O18: =N18-N17 -> 371 | P18: 96099 | Q18: =P18-P17 -> 139 | R18: 55047 | S18: =R18-R17 -> 0 | T18: 3560 | U18: =(T18-T17)*800/5 -> 480
A19: 44272 | B19: =B18 -> 44971 | C19: =(B19-B18)*800/5 -> 0 | D19: =D18 -> 39355 | E19: =(D19-D18)*800/5 -> 0 | F19: =F18 -> 20174 | G19: =(F19-F18)*100/5 -> 0 | H19: =H18 -> 239545 | I19: =(H19-H18) -> 0 | J19: =J18 -> 303517 | K19: =(J19-J18)*800/5 -> 0 | L19: =L18 -> 24731 | M19: =(L19-L18)*800/5 -> 0 | N19: =N18 -> 211419 | O19: =N19-N18 -> 0 | P19: 96200 | Q19: =P19-P18 -> 101 | R19: =R18 -> 55047 | S19: =R19-R18 -> 0 | T19: =T18 -> 3560 | U19: =(T19-T18)*800/5 -> 0
A20: 44273 | B20: =B19 -> 44971 | C20: =(B20-B19)*800/5 -> 0 | D20: =D19 -> 39355 | E20: =(D20-D19)*800/5 -> 0 | F20: =F19 -> 20174 | G20: =(F20-F19)*100/5 -> 0 | H20: =H19 -> 239545 | I20: =(H20-H19) -> 0 | J20: =J19 -> 303517 | K20: 0 | L20: =L19 -> 24731 | M20: =(L20-L19)*800/5 -> 0 | N20: =N19 -> 211419 | O20: =N20-N19 -> 0 | P20: 96299 | Q20: =P20-P19 -> 99 | R20: =R19 -> 55047 | S20: =R20-R19 -> 0 | T20: =T19 -> 3560 | U20: =(T20-T19)*800/5 -> 0
A21: 44274 | B21: 44978 | C21: =(B21-B20)*800/5 -> 1120 | D21: 39363 | E21: =(D21-D20)*800/5 -> 1280 | F21: 20182 | G21: =(F21-F20)*100/5 -> 160 | H21: 239571 | I21: =(H21-H20) -> 26 | J21: =J20 -> 303517 | K21: =(J21-J20)*800/5 -> 0 | L21: 24741 | M21: =(L21-L20)*800/5 -> 1600 | N21: 211522 | O21: =N21-N20 -> 103 | P21: 96390 | Q21: =P21-P20 -> 91 | R21: =R20 -> 55047 | S21: =R21-R20 -> 0 | T21: 3566 | U21: =(T21-T20)*800/5 -> 960
A22: 44275 | B22: 44992 | C22: =(B22-B21)*800/5 -> 2240 | D22: 39366 | E22: =(D22-D21)*800/5 -> 480 | F22: 20189 | G22: =(F22-F21)*100/5 -> 140 | H22: 239630 | I22: =(H22-H21) -> 59 | J22: =J21 -> 303517 | K22: =(J22-J21)*800/5 -> 0 | L22: 24744 | M22: =(L22-L21)*800/5 -> 480 | N22: 211833 | O22: =N22-N21 -> 311 | P22: 96469 | Q22: =P22-P21 -> 79 | R22: =R21 -> 55047 | S22: =R22-R21 -> 0 | T22: 3567 | U22: =(T22-T21)*800/5 -> 160
A23: 44276 | B23: 44997 | C23: =(B23-B22)*800/5 -> 800 | D23: 39368 | E23: =(D23-D22)*800/5 -> 320 | F23: 20192 | G23: =(F23-F22)*100/5 -> 60 | H23: 239650 | I23: =(H23-H22) -> 20 | J23: =J22 -> 303517 | K23: =(J23-J22)*800/5 -> 0 | L23: 24747 | M23: =(L23-L22)*800/5 -> 480 | N23: 211946 | O23: =N23-N22 -> 113 | P23: 96550 | Q23: =P23-P22 -> 81 | R23: =R22 -> 55047 | S23: =R23-R22 -> 0 | T23: 3568 | U23: =(T23-T22)*800/5 -> 160
A24: 44277 | B24: 45002 | C24: =(B24-B23)*800/5 -> 800 | D24: 39371 | E24: =(D24-D23)*800/5 -> 480 | F24: 20195 | G24: =(F24-F23)*100/5 -> 60 | H24: 239689 | I24: =(H24-H23) -> 39 | J24: =J23 -> 303517 | K24: =(J24-J23)*800/5 -> 0 | L24: 24751 | M24: =(L24-L23)*800/5 -> 640 | N24: 212070 | O24: =N24-N23 -> 124 | P24: 96745 | Q24: =P24-P23 -> 195 | R24: =R23 -> 55047 | S24: =R24-R23 -> 0 | T24: 3570 | U24: =(T24-T23)*800/5 -> 320
A25: 44278 | B25: 45006 | C25: =(B25-B24)*800/5 -> 640 | D25: 39373 | E25: =(D25-D24)*800/5 -> 320 | F25: 20198 | G25: =(F25-F24)*100/5 -> 60 | H25: 239719 | I25: =(H25-H24) -> 30 | J25: =J24 -> 303517 | K25: =(J25-J24)*800/5 -> 0 | L25: 24754 | M25: =(L25-L24)*800/5 -> 480 | N25: 212184 | O25: =N25-N24 -> 114 | P25: 97200 | Q25: =P25-P24 -> 455 | R25: =R24 -> 55047 | S25: =R25-R24 -> 0 | T25: 3571 | U25: =(T25-T24)*800/5 -> 160
A26: 44279 | B26: 45009 | C26: =(B26-B25)*800/5 -> 480 | D26: 39375 | E26: =(D26-D25)*800/5 -> 320 | F26: 20201 | G26: =(F26-F25)*100/5 -> 60 | H26: 239802 | I26: =(H26-H25) -> 83 | J26: 303517 | K26: =(J26-J25)*800/5 -> 0 | L26: 24757 | M26: =(L26-L25)*800/5 -> 480 | N26: 212257 | O26: =N26-N25 -> 73 | P26: 97495 | Q26: =P26-P25 -> 295 | R26: =R25 -> 55047 | S26: =R26-R25 -> 0 | T26: 3572 | U26: =(T26-T25)*800/5 -> 160
A27: 44280 | B27: 45011 | C27: =(B27-B26)*800/5 -> 320 | D27: 39378 | E27: =(D27-D26)*800/5 -> 480 | F27: 20203 | G27: =(F27-F26)*100/5 -> 40 | H27: 239881 | I27: =(H27-H26) -> 79 | J27: 303517 | K27: =(J27-J26)*800/5 -> 0 | L27: 24759 | M27: =(L27-L26)*800/5 -> 320 | N27: 212298 | O27: =N27-N26 -> 41 | P27: 97631 | Q27: =P27-P26 -> 136 | R27: 55047 | S27: =R27-R26 -> 0 | T27: 3573 | U27: =(T27-T26)*800/5 -> 160
A28: 44281 | B28: 45022 | C28: =(B28-B27)*800/5 -> 1760 | D28: 39383 | E28: =(D28-D27)*800/5 -> 800 | F28: 20208 | G28: =(F28-F27)*100/5 -> 100 | H28: 239888 | I28: =(H28-H27) -> 7 | J28: 303517 | K28: =(J28-J27)*800/5 -> 0 | L28: 24764 | M28: =(L28-L27)*800/5 -> 800 | N28: 212505 | O28: =N28-N27 -> 207 | P28: 97714 | Q28: =P28-P27 -> 83 | R28: 55047 | S28: =R28-R27 -> 0 | T28: 3576 | U28: =(T28-T27)*800/5 -> 480
A29: 44282 | B29: 45027 | C29: =(B29-B28)*800/5 -> 800 | D29: 39384 | E29: =(D29-D28)*800/5 -> 160 | F29: 20211 | G29: =(F29-F28)*100/5 -> 60 | H29: 239899 | I29: =(H29-H28) -> 11 | J29: =J28 -> 303517 | K29: =(J29-J28)*800/5 -> 0 | L29: 24767 | M29: =(L29-L28)*800/5 -> 480 | N29: 212588 | O29: =N29-N28 -> 83 | P29: 97806 | Q29: =P29-P28 -> 92 | R29: =R28 -> 55047 | S29: =R29-R28 -> 0 | T29: 3577 | U29: =(T29-T28)*800/5 -> 160
A30: 44283 | B30: 45032 | C30: =(B30-B29)*800/5 -> 800 | D30: 39387 | E30: =(D30-D29)*800/5 -> 480 | F30: 20214 | G30: =(F30-F29)*100/5 -> 60 | H30: 239816 | I30: =(H30-H29) -> -83 | J30: 303517 | K30: =(J30-J29)*800/5 -> 0 | L30: 24771 | M30: =(L30-L29)*800/5 -> 640 | N30: 212705 | O30: =N30-N29 -> 117 | P30: 97901 | Q30: =P30-P29 -> 95 | R30: 55047 | S30: =R30-R29 -> 0 | T30: 3578 | U30: =(T30-T29)*800/5 -> 160
A31: 44284 | B31: 45037 | C31: =(B31-B30)*800/5 -> 800 | D31: 39390 | E31: =(D31-D30)*800/5 -> 480 | F31: 20218 | G31: =(F31-F30)*100/5 -> 80 | H31: 239838 | I31: =(H31-H30) -> 22 | J31: =J30 -> 303517 | K31: =(J31-J30)*800/5 -> 0 | L31: 24774 | M31: =(L31-L30)*800/5 -> 480 | N31: 212828 | O31: =N31-N30 -> 123 | P31: 98110 | Q31: =P31-P30 -> 209 | R31: =R30 -> 55047 | S31: =R31-R30 -> 0 | T31: =T30 -> 3578 | U31: =(T31-T30)*800/5 -> 0
A32: 44285 | B32: 45039 | C32: =(B32-B31)*800/5 -> 320 | D32: 39393 | E32: =(D32-D31)*800/5 -> 480 | F32: 20221 | G32: =(F32-F31)*100/5 -> 60 | H32: 239849 | I32: =(H32-H31) -> 11 | J32: 303517 | K32: =(J32-J31)*800/5 -> 0 | L32: 24778 | M32: =(L32-L31)*800/5 -> 640 | N32: 212904 | O32: =N32-N31 -> 76 | P32: =P31 -> 98110 | Q32: =P32-P31 -> 0 | R32: 55047 | S32: =R32-R31 -> 0 | T32: 3580 | U32: =(T32-T31)*800/5 -> 320
A33: 44286 | B33: 45047 | C33: 1280 | D33: 39395 | E33: 320 | F33: 20224 | G33: 60 | H33: 239901 | I33: 52 | J33: 303517 | K33: 0 | L33: 24783 | M33: 800 | N33: 213067 | O33: 163 | P33: 98551 | Q33: 61 | R33: 55047 | S33: 0 | T33: 3583 | U33: 160
A34: Total | C34: =SUM(C3:C33) -> 25120 | E34: =SUM(E3:E33) -> 13920 | G34: =SUM(G3:G33) -> 2080 | I34: =SUM(I3:I33) -> 718 | K34: =SUM(K3:K33) -> 0 | M34: =SUM(M3:M33) -> 18080 | O34: =SUM(O3:O33) -> 3429 | Q34: =SUM(Q3:Q33) -> 3401 | S34: =SUM(S3:S33) -> 0 | U34: =SUM(U3:U33) -> 6720

Sheet Water
A1: Day | B1: Main Reading | C1: Cons. | D1: Podium | E1: Cons. | F1: Hotel | G1: Cons. | H1: Large | I1: Cons. | J1: Total | K1: cost.LE
A2: Last | B2: 405614 | D2: 3422000 | F2: 2277500 | H2: 721618
A3: 44256 | B3: 405682 | C3: =(IF((B3-B2)<0,"0",(B3-B2)))*10 -> 680 | D3: 3437300 | E3: =(IF((D3-D2)<0,"0",(D3-D2)))*0.027 -> 413.1 | F3: 2283400 | G3: =(IF((F3-F2)<0,"0",(F3-F2)))*0.027 -> 159.3 | H3: 721840 | I3: =(IF((H3-H2)<0,"0",(H3-H2)))*0.027 -> 5.994 | J3: =C3+E3+G3+I3 -> 1258.394 | K3: =J3*5.86 -> 7374.1888
A4: 44257 | B4: =B3 -> 405682 | C4: =(IF((B4-B3)<0,"0",(B4-B3)))*10 -> 0 | D4: =D3 -> 3437300 | E4: =(IF((D4-D3)<0,"0",(D4-D3)))*0.027 -> 0 | F4: =F3 -> 2283400 | G4: =(IF((F4-F3)<0,"0",(F4-F3)))*0.027 -> 0 | H4: =H3 -> 721840 | I4: =(IF((H4-H3)<0,"0",(H4-H3)))*0.027 -> 0 | J4: =C4+E4+G4+I4 -> 0 | K4: =J4*5.86 -> 0
A5: 44258 | B5: =B4 -> 405682 | C5: =(IF((B5-B4)<0,"0",(B5-B4)))*10 -> 0 | D5: =D4 -> 3437300 | E5: =(IF((D5-D4)<0,"0",(D5-D4)))*0.027 -> 0 | F5: =F4 -> 2283400 | G5: =(IF((F5-F4)<0,"0",(F5-F4)))*0.027 -> 0 | H5: =H4 -> 721840 | I5: =(IF((H5-H4)<0,"0",(H5-H4)))*0.027 -> 0 | J5: =C5+E5+G5+I5 -> 0 | K5: =J5*5.86 -> 0
A6: 44259 | B6: 405845 | C6: =(IF((B6-B5)<0,"0",(B6-B5)))*10 -> 1630 | D6: 3464400 | E6: =(IF((D6-D5)<0,"0",(D6-D5)))*0.027 -> 731.7 | F6: 2302000 | G6: =(IF((F6-F5)<0,"0",(F6-F5)))*0.027 -> 502.2 | H6: 722342 | I6: =(IF((H6-H5)<0,"0",(H6-H5)))*0.027 -> 13.554 | J6: =C6+E6+G6+I6 -> 2877.454 | K6: =J6*5.86 -> 16861.88
A7: 44260 | B7: 405900 | C7: =(IF((B7-B6)<0,"0",(B7-B6)))*10 -> 550 | D7: 3480200 | E7: =(IF((D7-D6)<0,"0",(D7-D6)))*0.027 -> 426.6 | F7: 2308700 | G7: =(IF((F7-F6)<0,"0",(F7-F6)))*0.027 -> 180.9 | H7: 722481 | I7: =(IF((H7-H6)<0,"0",(H7-H6)))*0.027 -> 3.753 | J7: =C7+E7+G7+I7 -> 1161.253 | K7: =J7*5.86 -> 6804.9426
A8: 44261 | B8: 405954 | C8: =(IF((B8-B7)<0,"0",(B8-B7)))*10 -> 540 | D8: 3490400 | E8: =(IF((D8-D7)<0,"0",(D8-D7)))*0.027 -> 275.4 | F8: 2315000 | G8: =(IF((F8-F7)<0,"0",(F8-F7)))*0.027 -> 170.1 | H8: 722660 | I8: =(IF((H8-H7)<0,"0",(H8-H7)))*0.027 -> 4.833 | J8: =C8+E8+G8+I8 -> 990.333 | K8: =J8*5.86 -> 5803.3514
A9: 44262 | B9: 406002 | C9: =(IF((B9-B8)<0,"0",(B9-B8)))*10 -> 480 | D9: 3500400 | E9: =(IF((D9-D8)<0,"0",(D9-D8)))*0.027 -> 270 | F9: 2322300 | G9: =(IF((F9-F8)<0,"0",(F9-F8)))*0.027 -> 197.1 | H9: 722844 | I9: =(IF((H9-H8)<0,"0",(H9-H8)))*0.027 -> 4.968 | J9: =C9+E9+G9+I9 -> 952.068 | K9: =J9*5.86 -> 5579.1185
A10: 44263 | B10: 406059 | C10: =(IF((B10-B9)<0,"0",(B10-B9)))*10 -> 570 | D10: 3509500 | E10: =(IF((D10-D9)<0,"0",(D10-D9)))*0.027 -> 245.7 | F10: 2329500 | G10: =(IF((F10-F9)<0,"0",(F10-F9)))*0.027 -> 194.4 | H10: 723013 | I10: =(IF((H10-H9)<0,"0",(H10-H9)))*0.027 -> 4.563 | J10: =C10+E10+G10+I10 -> 1014.663 | K10: =J10*5.86 -> 5945.9252
A11: 44264 | B11: 406164 | C11: =(IF((B11-B10)<0,"0",(B11-B10)))*10 -> 1050 | D11: 3519700 | E11: =(IF((D11-D10)<0,"0",(D11-D10)))*0.027 -> 275.4 | F11: 2338200 | G11: =(IF((F11-F10)<0,"0",(F11-F10)))*0.027 -> 234.9 | H11: 723150 | I11: =(IF((H11-H10)<0,"0",(H11-H10)))*0.027 -> 3.699 | J11: =C11+E11+G11+I11 -> 1563.999 | K11: =J11*5.86 -> 9165.0341
A12: 44265 | B12: 406169 | C12: =(IF((B12-B11)<0,"0",(B12-B11)))*10 -> 50 | D12: 3531500 | E12: =(IF((D12-D11)<0,"0",(D12-D11)))*0.027 -> 318.6 | F12: 2350800 | G12: =(IF((F12-F11)<0,"0",(F12-F11)))*0.027 -> 340.2 | H12: 723304 | I12: =(IF((H12-H11)<0,"0",(H12-H11)))*0.027 -> 4.158 | J12: =C12+E12+G12+I12 -> 712.958 | K12: =J12*5.86 -> 4177.9339
A13: 44266 | B13: 406252 | C13: =(IF((B13-B12)<0,"0",(B13-B12)))*10 -> 830 | D13: 3542300 | E13: =(IF((D13-D12)<0,"0",(D13-D12)))*0.027 -> 291.6 | F13: 2361000 | G13: =(IF((F13-F12)<0,"0",(F13-F12)))*0.027 -> 275.4 | H13: 723460 | I13: =(IF((H13-H12)<0,"0",(H13-H12)))*0.027 -> 4.212 | J13: =C13+E13+G13+I13 -> 1401.212 | K13: =J13*5.86 -> 8211.1023
A14: 44267 | B14: 406270 | C14: =(IF((B14-B13)<0,"0",(B14-B13)))*10 -> 180 | D14: 3553800 | E14: =(IF((D14-D13)<0,"0",(D14-D13)))*0.027 -> 310.5 | F14: 2369700 | G14: =(IF((F14-F13)<0,"0",(F14-F13)))*0.027 -> 234.9 | H14: 723599 | I14: =(IF((H14-H13)<0,"0",(H14-H13)))*0.027 -> 3.753 | J14: =C14+E14+G14+I14 -> 729.153 | K14: =J14*5.86 -> 4272.8366
A15: 44268 | B15: 406310 | C15: =(IF((B15-B14)<0,"0",(B15-B14)))*10 -> 400 | D15: 3565300 | E15: =(IF((D15-D14)<0,"0",(D15-D14)))*0.027 -> 310.5 | F15: 2378000 | G15: =(IF((F15-F14)<0,"0",(F15-F14)))*0.027 -> 224.1 | H15: 723731 | I15: =(IF((H15-H14)<0,"0",(H15-H14)))*0.027 -> 3.564 | J15: =C15+E15+G15+I15 -> 938.164 | K15: =J15*5.86 -> 5497.641
A16: 44269 | B16: =B15 -> 406310 | C16: =(IF((B16-B15)<0,"0",(B16-B15)))*10 -> 0 | D16: =D15 -> 3565300 | E16: =(IF((D16-D15)<0,"0",(D16-D15)))*0.027 -> 0 | F16: =F15 -> 2378000 | G16: =(IF((F16-F15)<0,"0",(F16-F15)))*0.027 -> 0 | H16: =H15 -> 723731 | I16: =(IF((H16-H15)<0,"0",(H16-H15)))*0.027 -> 0 | J16: =C16+E16+G16+I16 -> 0 | K16: =J16*5.86 -> 0
A17: 44270 | B17: =B16 -> 406310 | C17: =(IF((B17-B16)<0,"0",(B17-B16)))*10 -> 0 | D17: =D16 -> 3565300 | E17: =(IF((D17-D16)<0,"0",(D17-D16)))*0.027 -> 0 | F17: =F16 -> 2378000 | G17: =(IF((F17-F16)<0,"0",(F17-F16)))*0.027 -> 0 | H17: =H16 -> 723731 | I17: =(IF((H17-H16)<0,"0",(H17-H16)))*0.027 -> 0 | J17: =C17+E17+G17+I17 -> 0 | K17: =J17*5.86 -> 0
A18: 44271 | B18: 406560 | C18: =(IF((B18-B17)<0,"0",(B18-B17)))*10 -> 2500 | D18: 3601500 | E18: =(IF((D18-D17)<0,"0",(D18-D17)))*0.027 -> 977.4 | F18: 2402400 | G18: =(IF((F18-F17)<0,"0",(F18-F17)))*0.027 -> 658.8 | H18: 724200 | I18: =(IF((H18-H17)<0,"0",(H18-H17)))*0.027 -> 12.663 | J18: =C18+E18+G18+I18 -> 4148.863 | K18: =J18*5.86 -> 24312.337 | Q18: `
A19: 44272 | B19: =B18 -> 406560 | C19: =(IF((B19-B18)<0,"0",(B19-B18)))*10 -> 0 | D19: =D18 -> 3601500 | E19: =(IF((D19-D18)<0,"0",(D19-D18)))*0.027 -> 0 | F19: =F18 -> 2402400 | G19: =(IF((F19-F18)<0,"0",(F19-F18)))*0.027 -> 0 | H19: =H18 -> 724200 | I19: =(IF((H19-H18)<0,"0",(H19-H18)))*0.027 -> 0 | J19: =C19+E19+G19+I19 -> 0 | K19: =J19*5.86 -> 0
A20: 44273 | B20: =B19 -> 406560 | C20: =(IF((B20-B19)<0,"0",(B20-B19)))*10 -> 0 | D20: =D19 -> 3601500 | E20: =(IF((D20-D19)<0,"0",(D20-D19)))*0.027 -> 0 | F20: =F19 -> 2402400 | G20: =(IF((F20-F19)<0,"0",(F20-F19)))*0.027 -> 0 | H20: =H19 -> 724200 | I20: =(IF((H20-H19)<0,"0",(H20-H19)))*0.027 -> 0 | J20: =C20+E20+G20+I20 -> 0 | K20: =J20*5.86 -> 0
A21: 44274 | B21: 406734 | C21: =(IF((B21-B20)<0,"0",(B21-B20)))*10 -> 1740 | D21: 3634300 | E21: =(IF((D21-D20)<0,"0",(D21-D20)))*0.027 -> 885.6 | F21: 2427400 | G21: =(IF((F21-F20)<0,"0",(F21-F20)))*0.027 -> 675 | H21: 724580 | I21: =(IF((H21-H20)<0,"0",(H21-H20)))*0.027 -> 10.26 | J21: =C21+E21+G21+I21 -> 3310.86 | K21: =J21*5.86 -> 19401.64
A22: 44275 | B22: 406792 | C22: =(IF((B22-B21)<0,"0",(B22-B21)))*10 -> 580 | D22: 3645100 | E22: =(IF((D22-D21)<0,"0",(D22-D21)))*0.027 -> 291.6 | F22: 2435800 | G22: =(IF((F22-F21)<0,"0",(F22-F21)))*0.027 -> 226.8 | H22: 724697 | I22: =(IF((H22-H21)<0,"0",(H22-H21)))*0.027 -> 3.159 | J22: =C22+E22+G22+I22 -> 1101.559 | K22: =J22*5.86 -> 6455.1357
A23: 44276 | B23: 406854 | C23: =(IF((B23-B22)<0,"0",(B23-B22)))*10 -> 620 | D23: 3657400 | E23: =(IF((D23-D22)<0,"0",(D23-D22)))*0.027 -> 332.1 | F23: 2444800 | G23: =(IF((F23-F22)<0,"0",(F23-F22)))*0.027 -> 243 | H23: 724823 | I23: =(IF((H23-H22)<0,"0",(H23-H22)))*0.027 -> 3.402 | J23: =C23+E23+G23+I23 -> 1198.502 | K23: =J23*5.86 -> 7023.2217
A24: 44277 | B24: 406909 | C24: =(IF((B24-B23)<0,"0",(B24-B23)))*10 -> 550 | D24: 3667700 | E24: =(IF((D24-D23)<0,"0",(D24-D23)))*0.027 -> 278.1 | F24: 2454800 | G24: =(IF((F24-F23)<0,"0",(F24-F23)))*0.027 -> 270 | H24: 724943 | I24: =(IF((H24-H23)<0,"0",(H24-H23)))*0.027 -> 3.24 | J24: =C24+E24+G24+I24 -> 1101.34 | K24: =J24*5.86 -> 6453.8524
A25: 44278 | B25: 406989 | C25: =(IF((B25-B24)<0,"0",(B25-B24)))*10 -> 800 | D25: 3680600 | E25: =(IF((D25-D24)<0,"0",(D25-D24)))*0.027 -> 348.3 | F25: 2454800 | G25: =F25-F24 -> 0 | H25: 726081 | I25: =(IF((H25-H24)<0,"0",(H25-H24)))*0.027 -> 30.726 | J25: =C25+E25+G25+I25 -> 1179.026 | K25: =J25*5.86 -> 6909.0924
A26: 44279 | B26: 407054 | C26: =(IF((B26-B25)<0,"0",(B26-B25)))*10 -> 650 | D26: 3692500 | E26: =(IF((D26-D25)<0,"0",(D26-D25)))*0.027 -> 321.3 | F26: 2474400 | G26: =(IF((F26-F25)<0,"0",(F26-F25)))*0.027 -> 529.2 | H26: 726218 | I26: =(IF((H26-H25)<0,"0",(H26-H25)))*0.027 -> 3.699 | J26: =C26+E26+G26+I26 -> 1504.199 | K26: =J26*5.86 -> 8814.6061
A27: 44280 | B27: 407085 | C27: =(IF((B27-B26)<0,"0",(B27-B26)))*10 -> 310 | D27: 3705400 | E27: =(IF((D27-D26)<0,"0",(D27-D26)))*0.027 -> 348.3 | F27: 2483100 | G27: =(IF((F27-F26)<0,"0",(F27-F26)))*0.027 -> 234.9 | H27: 725385 | I27: =(IF((H27-H26)<0,"0",(H27-H26)))*0.027 -> 0 | J27: =C27+E27+G27+I27 -> 893.2 | K27: =J27*5.86 -> 5234.152
A28: 44281 | B28: 407183 | C28: =(IF((B28-B27)<0,"0",(B28-B27)))*10 -> 980 | D28: 3717700 | E28: =(IF((D28-D27)<0,"0",(D28-D27)))*0.027 -> 332.1 | F28: 2491000 | G28: =(IF((F28-F27)<0,"0",(F28-F27)))*0.027 -> 213.3 | H28: 725495 | I28: =(IF((H28-H27)<0,"0",(H28-H27)))*0.027 -> 2.97 | J28: =C28+E28+G28+I28 -> 1528.37 | K28: =J28*5.86 -> 8956.2482
A29: 44282 | B29: 407245 | C29: =(IF((B29-B28)<0,"0",(B29-B28)))*10 -> 620 | D29: 3730000 | E29: =(IF((D29-D28)<0,"0",(D29-D28)))*0.027 -> 332.1 | F29: 2499000 | G29: =(IF((F29-F28)<0,"0",(F29-F28)))*0.027 -> 216 | H29: 725607 | I29: =(IF((H29-H28)<0,"0",(H29-H28)))*0.027 -> 3.024 | J29: =C29+E29+G29+I29 -> 1171.124 | K29: =J29*5.86 -> 6862.7866
A30: 44283 | B30: 407305 | C30: =(IF((B30-B29)<0,"0",(B30-B29)))*10 -> 600 | D30: 3742200 | E30: =(IF((D30-D29)<0,"0",(D30-D29)))*0.027 -> 329.4 | F30: 2507100 | G30: =(IF((F30-F29)<0,"0",(F30-F29)))*0.027 -> 218.7 | H30: 725724 | I30: =(IF((H30-H29)<0,"0",(H30-H29)))*0.027 -> 3.159 | J30: =C30+E30+G30+I30 -> 1151.259 | K30: =J30*5.86 -> 6746.3777
A31: 44284 | B31: 407377 | C31: =(IF((B31-B30)<0,"0",(B31-B30)))*10 -> 720 | D31: 3755400 | E31: =(IF((D31-D30)<0,"0",(D31-D30)))*0.027 -> 356.4 | F31: 2517400 | G31: =(IF((F31-F30)<0,"0",(F31-F30)))*0.027 -> 278.1 | H31: 725852 | I31: =(IF((H31-H30)<0,"0",(H31-H30)))*0.027 -> 3.456 | J31: =C31+E31+G31+I31 -> 1357.956 | K31: =J31*5.86 -> 7957.6222
A32: 44285 | B32: 407443 | C32: =(IF((B32-B31)<0,"0",(B32-B31)))*10 -> 660 | D32: 3767800 | E32: =(IF((D32-D31)<0,"0",(D32-D31)))*0.027 -> 334.8 | F32: 2527400 | G32: =(IF((F32-F31)<0,"0",(F32-F31)))*0.027 -> 270 | H32: 726024 | I32: =(IF((H32-H31)<0,"0",(H32-H31)))*0.027 -> 4.644 | J32: =C32+E32+G32+I32 -> 1269.444 | K32: =J32*5.86 -> 7438.9418
A33: 44286 | B33: 407517 | C33: 740 | D33: 3781100 | E33: 359.1 | F33: 2534500 | G33: 191.7 | H33: 726148 | I33: 3.348 | J33: 1294.148 | K33: 7583.7073
A34: Total | C34: =SUM(C3:C33) -> 19030 | E34: =SUM(E3:E33) -> 9695.7 | G34: =SUM(G3:G33) -> 6939 | I34: =SUM(I3:I33) -> 144.801 | J34: =SUM(J3:J33) -> 35809.501 | K34: =SUM(K3:K33) -> 209843.68

Sheet ELECT.
