Workbook

Sheet TOTAL
A1: Site Name | B1: Day | C1: Month | D1: Year | E1: Total Electricity Kwh | F1: Electricity Tariff ($/Kwh) | G1: LPG (Kg) | H1: LPG $/Kg | I1: Water Utility Supply (m3) m3 | J1: Water Utility Supply (m3) $/m3 | K1: Room Nights | N1: Water Tanks | O1: Cost of Water Tanks Rs | P1: Water Utility Supply (m3) Rs/m3 | Q1: Electricity Tariff (Rs/Kwh) | R1: LPG Rs/Kg | S1: Exchange Rate | T1: Total LPG Cost | U1: Total Water Cost
A2: Mauritius at Anahita | B2: 1 | C2: 3 | D2: 2021 | E2: =HOTEL!E4 -> 6266 | F2: 6.21 | G2: =HOTEL!CK4 -> 0 | H2: 57.45 | I2: =HOTEL!V4+HOTEL!Y4 -> 56 | J2: =P2 -> 99.99903 | K2: =HOTEL!EE4 -> 2 | N2: =HOTEL!X12 -> 152370 | O2: =N2*2500 -> 380925000 | P2: =IFERROR(((((HOTEL!V4*34))+(N2*2500))/(I2+N2*25)),0) -> 99.99903 | Q2: 6.21 | R2: =H2 -> 57.45 | S2: 33.88 | T2: =G2*H2 -> 0 | U2: =I2*P2 -> 5599.9457
A3: Mauritius at Anahita | B3: =B2+1 -> 2 | C3: 3 | D3: 2021 | E3: =HOTEL!E5 -> 6059 | F3: 6.21 | G3: =HOTEL!CK5 -> 108 | H3: 57.45 | I3: =HOTEL!V5+HOTEL!Y5 -> 60 | J3: =P3 -> 99.99896 | K3: =HOTEL!EE5 -> 2 | N3: =HOTEL!X13 -> 152370 | O3: =N3*2500 -> 380925000 | P3: =IFERROR(((((HOTEL!V5*34))+(N3*2500))/(I3+N3*25)),0) -> 99.99896 | Q3: 6.21 | R3: =H3 -> 57.45 | S3: 33.88 | T3: =G3*H3 -> 6204.6 | U3: =I3*P3 -> 5999.9376
A4: Mauritius at Anahita | B4: =B3+1 -> 3 | C4: 3 | D4: 2021 | E4: =HOTEL!E6 -> 6475 | F4: 6.21 | G4: =HOTEL!CK6 -> 0 | H4: 57.45 | I4: =HOTEL!V6+HOTEL!Y6 -> 71 | J4: =P4 -> 99.99877 | K4: =HOTEL!EE6 -> 2 | N4: =HOTEL!X14 -> 152370 | O4: =N4*2500 -> 380925000 | P4: =IFERROR(((((HOTEL!V6*34))+(N4*2500))/(I4+N4*25)),0) -> 99.99877 | Q4: 6.21 | R4: =H4 -> 57.45 | S4: 33.88 | T4: =G4*H4 -> 0 | U4: =I4*P4 -> 7099.9127
A5: Mauritius at Anahita | B5: =B4+1 -> 4 | C5: 3 | D5: 2021 | E5: =HOTEL!E7 -> 6476 | F5: 6.21 | G5: =HOTEL!CK7 -> 0 | H5: 57.45 | I5: =HOTEL!V7+HOTEL!Y7 -> 77 | J5: =P5 -> 99.998666 | K5: =HOTEL!EE7 -> 2 | N5: =HOTEL!X15 -> 152370 | O5: =N5*2500 -> 380925000 | P5: =IFERROR(((((HOTEL!V7*34))+(N5*2500))/(I5+N5*25)),0) -> 99.998666 | Q5: 6.21 | R5: =H5 -> 57.45 | S5: 33.88 | T5: =G5*H5 -> 0 | U5: =I5*P5 -> 7699.8973
A6: Mauritius at Anahita | B6: =B5+1 -> 5 | C6: 3 | D6: 2021 | E6: =HOTEL!E8 -> 5896 | F6: 6.21 | G6: =HOTEL!CK8 -> 0 | H6: 57.45 | I6: =HOTEL!V8+HOTEL!Y8 -> 33 | J6: =P6 -> 99.999428 | K6: =HOTEL!EE8 -> 2 | N6: =HOTEL!X16 -> 152370 | O6: =N6*2500 -> 380925000 | P6: =IFERROR(((((HOTEL!V8*34))+(N6*2500))/(I6+N6*25)),0) -> 99.999428 | Q6: 6.21 | R6: =H6 -> 57.45 | S6: 33.88 | T6: =G6*H6 -> 0 | U6: =I6*P6 -> 3299.9811
A7: Mauritius at Anahita | B7: =B6+1 -> 6 | C7: 3 | D7: 2021 | E7: =HOTEL!E9 -> 5315 | F7: 6.21 | G7: =HOTEL!CK9 -> 108 | H7: 57.45 | I7: =HOTEL!V9+HOTEL!Y9 -> 40 | J7: =P7 -> 99.999307 | K7: =HOTEL!EE9 -> 2 | N7: =HOTEL!X17 -> 152370 | O7: =N7*2500 -> 380925000 | P7: =IFERROR(((((HOTEL!V9*34))+(N7*2500))/(I7+N7*25)),0) -> 99.999307 | Q7: 6.21 | R7: =H7 -> 57.45 | S7: 33.88 | T7: =G7*H7 -> 6204.6 | U7: =I7*P7 -> 3999.9723
A8: Mauritius at Anahita | B8: =B7+1 -> 7 | C8: 3 | D8: 2021 | E8: =HOTEL!E10 -> 6678 | F8: 6.21 | G8: =HOTEL!CK10 -> 0 | H8: 57.45 | I8: =HOTEL!V10+HOTEL!Y10 -> 35 | J8: =P8 -> 99.999394 | K8: =HOTEL!EE10 -> 2 | N8: =HOTEL!X18 -> 152370 | O8: =N8*2500 -> 380925000 | P8: =IFERROR(((((HOTEL!V10*34))+(N8*2500))/(I8+N8*25)),0) -> 99.999394 | Q8: 6.21 | R8: =H8 -> 57.45 | S8: 33.88 | T8: =G8*H8 -> 0 | U8: =I8*P8 -> 3499.9788
A9: Mauritius at Anahita | B9: =B8+1 -> 8 | C9: 3 | D9: 2021 | E9: =HOTEL!E11 -> 5960 | F9: 6.21 | G9: =HOTEL!CK11 -> 108 | H9: 57.45 | I9: =HOTEL!V11+HOTEL!Y11 -> 55 | J9: =P9 -> 99.999047 | K9: =HOTEL!EE11 -> 2 | N9: =HOTEL!X19 -> 152370 | O9: =N9*2500 -> 380925000 | P9: =IFERROR(((((HOTEL!V11*34))+(N9*2500))/(I9+N9*25)),0) -> 99.999047 | Q9: 6.21 | R9: =H9 -> 57.45 | S9: 33.88 | T9: =G9*H9 -> 6204.6 | U9: =I9*P9 -> 5499.9476
A10: Mauritius at Anahita | B10: =B9+1 -> 9 | C10: 3 | D10: 2021 | E10: =HOTEL!E12 -> 5456 | F10: 6.21 | G10: =HOTEL!CK12 -> 108 | H10: 57.45 | I10: =HOTEL!V12+HOTEL!Y12 -> 5 | J10: =P10 -> 99.999913 | K10: =HOTEL!EE12 -> 2 | N10: =HOTEL!X20 -> 152370 | O10: =N10*2500 -> 380925000 | P10: =IFERROR(((((HOTEL!V12*34))+(N10*2500))/(I10+N10*25)),0) -> 99.999913 | Q10: 6.21 | R10: =H10 -> 57.45 | S10: 33.93 | T10: =G10*H10 -> 6204.6 | U10: =I10*P10 -> 499.99957
A11: Mauritius at Anahita | B11: =B10+1 -> 10 | C11: 3 | D11: 2021 | E11: =HOTEL!E13 -> 6272 | F11: 6.21 | G11: =HOTEL!CK13 -> 0 | H11: 57.45 | I11: =HOTEL!V13+HOTEL!Y13 -> 32 | J11: =P11 -> 99.999446 | K11: =HOTEL!EE13 -> 2 | N11: =HOTEL!X21 -> 152370 | O11: =N11*2500 -> 380925000 | P11: =IFERROR(((((HOTEL!V13*34))+(N11*2500))/(I11+N11*25)),0) -> 99.999446 | Q11: 6.21 | R11: =H11 -> 57.45 | S11: 33.93 | T11: =G11*H11 -> 0 | U11: =I11*P11 -> 3199.9823
A12: Mauritius at Anahita | B12: =B11+1 -> 11 | C12: 3 | D12: 2021 | E12: =HOTEL!E14 -> 5797 | F12: 6.21 | G12: =HOTEL!CK14 -> 108 | H12: 57.45 | I12: =HOTEL!V14+HOTEL!Y14 -> 28 | J12: =P12 -> 99.999515 | K12: =HOTEL!EE14 -> 2 | N12: =HOTEL!X22 -> 152370 | O12: =N12*2500 -> 380925000 | P12: =IFERROR(((((HOTEL!V14*34))+(N12*2500))/(I12+N12*25)),0) -> 99.999515 | Q12: 6.21 | R12: =H12 -> 57.45 | S12: 33.93 | T12: =G12*H12 -> 6204.6 | U12: =I12*P12 -> 2799.9864
A13: Mauritius at Anahita | B13: =B12+1 -> 12 | C13: 3 | D13: 2021 | E13: =HOTEL!E15 -> 5602 | F13: 6.21 | G13: =HOTEL!CK15 -> 108 | H13: 57.45 | I13: =HOTEL!V15+HOTEL!Y15 -> 10 | J13: =P13 -> 99.999827 | K13: =HOTEL!EE15 -> 2 | N13: =HOTEL!X23 -> 152370 | O13: =N13*2500 -> 380925000 | P13: =IFERROR(((((HOTEL!V15*34))+(N13*2500))/(I13+N13*25)),0) -> 99.999827 | Q13: 6.21 | R13: =H13 -> 57.45 | S13: 33.93 | T13: =G13*H13 -> 6204.6 | U13: =I13*P13 -> 999.99827
A14: Mauritius at Anahita | B14: =B13+1 -> 13 | C14: 3 | D14: 2021 | E14: =HOTEL!E16 -> 6460 | F14: 6.21 | G14: =HOTEL!CK16 -> 108 | H14: 57.45 | I14: =HOTEL!V16+HOTEL!Y16 -> 77 | J14: =P14 -> 99.998666 | K14: =HOTEL!EE16 -> 2 | N14: =HOTEL!X24 -> 152370 | O14: =N14*2500 -> 380925000 | P14: =IFERROR(((((HOTEL!V16*34))+(N14*2500))/(I14+N14*25)),0) -> 99.998666 | Q14: 6.21 | R14: =H14 -> 57.45 | S14: 33.93 | T14: =G14*H14 -> 6204.6 | U14: =I14*P14 -> 7699.8973
... A29: Mauritius at Anahita | B29: =B28+1 -> 28 | C29: 3 | D29: 2021 | E29: =HOTEL!E31 -> 6136 | F29: 6.21 | G29: =HOTEL!CK31 -> 0 | H29: 57.45 | I29: =HOTEL!V31+HOTEL!Y31 -> 33 | J29: =P29 -> 34 | K29: =HOTEL!EE31 -> 3 | N29: =HOTEL!X39 -> 0 | O29: =N29*2500 -> 0 | P29: =IFERROR(((((HOTEL!V31*34))+(N29*2500))/(I29+N29*25)),0) -> 34 | Q29: 6.21 | R29: =H29 -> 57.45 | S29: 33.93 | T29: =G29*H29 -> 0 | U29: =I29*P29 -> 1122
A30: Mauritius at Anahita | B30: =B29+1 -> 29 | C30: 3 | D30: 2021 | E30: =HOTEL!E32 -> 6254 | F30: 6.21 | G30: =HOTEL!CK32 -> 0 | H30: 57.45 | I30: =HOTEL!V32+HOTEL!Y32 -> 32 | J30: =P30 -> 34 | K30: =HOTEL!EE32 -> 3 | N30: =HOTEL!X40 -> 0 | O30: =N30*2500 -> 0 | P30: =IFERROR(((((HOTEL!V32*34))+(N30*2500))/(I30+N30*25)),0) -> 34 | Q30: 6.21 | R30: =H30 -> 57.45 | T30: =G30*H30 -> 0 | U30: =I30*P30 -> 1088
A31: Mauritius at Anahita | B31: =B30+1 -> 30 | C31: 3 | D31: 2021 | E31: =HOTEL!E33 -> 6237 | F31: 6.21 | G31: =HOTEL!CK33 -> 0 | H31: 57.45 | I31: =HOTEL!V33+HOTEL!Y33 -> 41 | J31: =P31 -> 34 | K31: =HOTEL!EE33 -> 3 | N31: =HOTEL!X41 -> 0 | O31: =N31*2500 -> 0 | P31: =IFERROR(((((HOTEL!V33*34))+(N31*2500))/(I31+N31*25)),0) -> 34 | Q31: 6.21 | R31: =H31 -> 57.45 | T31: =G31*H31 -> 0 | U31: =I31*P31 -> 1394
A32: Mauritius at Anahita | B32: =B31+1 -> 31 | C32: 3 | D32: 2021 | E32: =HOTEL!E34 -> 6355 | F32: 6.21 | G32: =HOTEL!CK34 -> 0 | H32: 57.45 | I32: =HOTEL!V34+HOTEL!Y34 -> 34 | J32: =P32 -> 34 | K32: =HOTEL!EE34 -> 3 | N32: =HOTEL!X42 -> 0 | O32: =N32*2500 -> 0 | P32: =IFERROR(((((HOTEL!V34*34))+(N32*2500))/(I32+N32*25)),0) -> 34 | Q32: 6.21 | R32: =H32 -> 57.45 | T32: =G32*H32 -> 0 | U32: =I32*P32 -> 1156

Sheet Submetering
A1: Site Name | B1: Day | C1: Month | D1: Year | E1: Hotel (KWh) | F1: Vacoas (KWh) | G1: Laundry (KWh) | H1: Villa 145 (KWh) | I1: Villa 146 (KWh) | J1: Villa 111 (KWh) | K1: Villa 128 (KWh) | L1: Hotel (m3) | M1: Bamboo Pool (m3) | N1: Island (m3) | O1: Main Building (m3) | P1: Pantry A (m3) | Q1: Pantry B (m3) | R1: Pantry C (m3) | S1: Pantry D (m3) | T1: Pantry E (m3) | U1: Pantry F (m3) | V1: Pantry G (m3) | W1: North Parcel (m3) | X1: South Parcel (m3) | Y1: Beau champ (Kg) | Z1: Acquapazza (Kg) | AA1: Bamboo (Kg) | AB1: Steam Boiler (Kg) | AC1: Laundry (Kg) | AD1: Pantry A (Kg) | AE1: Pantry B (Kg) | AF1: Pantry C (Kg) | AG1: Pantry D (Kg) | AH1: Pantry E (Kg) | AI1: Pantry F (Kg) | AJ1: Pantry G (Kg) | AK1: Room Nights
A2: Mauritius at Anahita | B2: 1 | C2: 3 | D2: 2021 | E2: =TOTAL!E2 -> 6266 | F2: =HOTEL!R4 -> 96 | G2: =HOTEL!T4 -> 4 | H2: =HOTEL!DX4 -> 0 | I2: =HOTEL!DZ4 -> 0 | J2: =HOTEL!EB4 -> 0 | K2: =HOTEL!ED4 -> 0 | L2: =N2+W2+X2 -> 50 | M2: =HOTEL!AE4 -> 0 | N2: =HOTEL!AI4 -> 30 | O2: =HOTEL!AM4 -> 1 | P2: =HOTEL!AO4 -> 0 | Q2: =HOTEL!AQ4 -> 0 | R2: =HOTEL!AS4 -> 1 | S2: =HOTEL!AU4 -> 0 | T2: =HOTEL!AW4 -> 0 | U2: =HOTEL!AY4 -> 0 | V2: =HOTEL!BA4 -> 1 | W2: =HOTEL!BM4 -> 20 | X2: =HOTEL!BT4 -> 0 | Y2: =HOTEL!CO4 -> 2.44 | Z2: =HOTEL!CR3 -> 0 | AA2: =HOTEL!CU4 -> 0 | AB2: =HOTEL!CX4 -> 0 | AC2: =HOTEL!DA4 -> 2.39 | AD2: =HOTEL!DD4 -> 0 | AE2: =HOTEL!DG4 -> 0 | AF2: =HOTEL!DJ4 -> 0 | AG2: =HOTEL!DM4 -> 0 | AH2: =HOTEL!DP4 -> 0 | AI2: =HOTEL!DS4 -> 0 | AJ2: =HOTEL!DV4 -> 14.34 | AK2: =TOTAL!K2 -> 2
A3: Mauritius at Anahita | B3: =B2+1 -> 2 | C3: 3 | D3: 2021 | E3: =TOTAL!E3 -> 6059 | F3: =HOTEL!R5 -> 63 | G3: =HOTEL!T5 -> 48 | H3: =HOTEL!DX5 -> 0 | I3: =HOTEL!DZ5 -> 0 | J3: =HOTEL!EB5 -> 0 | K3: =HOTEL!ED5 -> 0 | L3: =N3+W3+X3 -> 50 | M3: =HOTEL!AE5 -> 0 | N3: =HOTEL!AI5 -> 20 | O3: =HOTEL!AM5 -> 4 | P3: =HOTEL!AO5 -> 0 | Q3: =HOTEL!AQ5 -> 0 | R3: =HOTEL!AS5 -> 0 | S3: =HOTEL!AU5 -> 0 | T3: =HOTEL!AW5 -> 0 | U3: =HOTEL!AY5 -> 0 | V3: =HOTEL!BA5 -> 0 | W3: =HOTEL!BM5 -> 20 | X3: =HOTEL!BT5 -> 10 | Y3: =HOTEL!CO5 -> 4.88 | Z3: =HOTEL!CR4 -> 0 | AA3: =HOTEL!CU5 -> 0 | AB3: =HOTEL!CX5 -> 12.2 | AC3: =HOTEL!DA5 -> 4.78 | AD3: =HOTEL!DD5 -> 0 | AE3: =HOTEL!DG5 -> 0 | AF3: =HOTEL!DJ5 -> 0 | AG3: =HOTEL!DM5 -> 0 | AH3: =HOTEL!DP5 -> 0 | AI3: =HOTEL!DS5 -> 0 | AJ3: =HOTEL!DV5 -> 4.78 | AK3: =TOTAL!K3 -> 2
A4: Mauritius at Anahita | B4: =B3+1 -> 3 | C4: 3 | D4: 2021 | E4: =TOTAL!E4 -> 6475 | F4: =HOTEL!R6 -> 33 | G4: =HOTEL!T6 -> 1 | H4: =HOTEL!DX6 -> 0 | I4: =HOTEL!DZ6 -> 0 | J4: =HOTEL!EB6 -> 0 | K4: =HOTEL!ED6 -> 0 | L4: =N4+W4+X4 -> 70 | M4: =HOTEL!AE6 -> 0 | N4: =HOTEL!AI6 -> 30 | O4: =HOTEL!AM6 -> 1 | P4: =HOTEL!AO6 -> 0 | Q4: =HOTEL!AQ6 -> 0 | R4: =HOTEL!AS6 -> 1 | S4: =HOTEL!AU6 -> 0 | T4: =HOTEL!AW6 -> 0 | U4: =HOTEL!AY6 -> 0 | V4: =HOTEL!BA6 -> 0 | W4: =HOTEL!BM6 -> 30 | X4: =HOTEL!BT6 -> 10 | Y4: =HOTEL!CO6 -> 4.88 | Z4: =HOTEL!CR5 -> 0 | AA4: =HOTEL!CU6 -> 0 | AB4: =HOTEL!CX6 -> 0 | AC4: =HOTEL!DA6 -> 2.39 | AD4: =HOTEL!DD6 -> 0 | AE4: =HOTEL!DG6 -> 0 | AF4: =HOTEL!DJ6 -> 0 | AG4: =HOTEL!DM6 -> 0 | AH4: =HOTEL!DP6 -> 0 | AI4: =HOTEL!DS6 -> 0 | AJ4: =HOTEL!DV6 -> 9.56 | AK4: =TOTAL!K4 -> 2
A5: Mauritius at Anahita | B5: =B4+1 -> 4 | C5: 3 | D5: 2021 | E5: =TOTAL!E5 -> 6476 | F5: =HOTEL!R7 -> 138 | G5: =HOTEL!T7 -> 4 | H5: =HOTEL!DX7 -> 0 | I5: =HOTEL!DZ7 -> 0 | J5: =HOTEL!EB7 -> 0 | K5: =HOTEL!ED7 -> 0 | L5: =N5+W5+X5 -> 80 | M5: =HOTEL!AE7 -> 10 | N5: =HOTEL!AI7 -> 40 | O5: =HOTEL!AM7 -> 0 | P5: =HOTEL!AO7 -> 0 | Q5: =HOTEL!AQ7 -> 0 | R5: =HOTEL!AS7 -> 1 | S5: =HOTEL!AU7 -> 0 | T5: =HOTEL!AW7 -> 0 | U5: =HOTEL!AY7 -> 0 | V5: =HOTEL!BA7 -> 0 | W5: =HOTEL!BM7 -> 30 | X5: =HOTEL!BT7 -> 10 | Y5: =HOTEL!CO7 -> 7.32 | Z5: =HOTEL!CR6 -> 0 | AA5: =HOTEL!CU7 -> 0 | AB5: =HOTEL!CX7 -> 0 | AC5: =HOTEL!DA7 -> 2.39 | AD5: =HOTEL!DD7 -> 0 | AE5: =HOTEL!DG7 -> 0 | AF5: =HOTEL!DJ7 -> 0 | AG5: =HOTEL!DM7 -> 0 | AH5: =HOTEL!DP7 -> 0 | AI5: =HOTEL!DS7 -> 0 | AJ5: =HOTEL!DV7 -> 14.34 | AK5: =TOTAL!K5 -> 2
A6: Mauritius at Anahita | B6: =B5+1 -> 5 | C6: 3 | D6: 2021 | E6: =TOTAL!E6 -> 5896 | F6: =HOTEL!R8 -> 91 | G6: =HOTEL!T8 -> 3 | H6: =HOTEL!DX8 -> 0 | I6: =HOTEL!DZ8 -> 0 | J6: =HOTEL!EB8 -> 0 | K6: =HOTEL!ED8 -> 0 | L6: =N6+W6+X6 -> 20 | M6: =HOTEL!AE8 -> 0 | N6: =HOTEL!AI8 -> 0 | O6: =HOTEL!AM8 -> 1 | P6: =HOTEL!AO8 -> 0 | Q6: =HOTEL!AQ8 -> 0 | R6: =HOTEL!AS8 -> 0 | S6: =HOTEL!AU8 -> 0 | T6: =HOTEL!AW8 -> 0 | U6: =HOTEL!AY8 -> 0 | V6: =HOTEL!BA8 -> 0 | W6: =HOTEL!BM8 -> 20 | X6: =HOTEL!BT8 -> 0 | Y6: =HOTEL!CO8 -> 2.44 | Z6: =HOTEL!CR7 -> 0 | AA6: =HOTEL!CU8 -> 0 | AB6: =HOTEL!CX8 -> 0 | AC6: =HOTEL!DA8 -> 0 | AD6: =HOTEL!DD8 -> 0 | AE6: =HOTEL!DG8 -> 0 | AF6: =HOTEL!DJ8 -> 0 | AG6: =HOTEL!DM8 -> 0 | AH6: =HOTEL!DP8 -> 0 | AI6: =HOTEL!DS8 -> 0 | AJ6: =HOTEL!DV8 -> 0 | AK6: =TOTAL!K6 -> 2
A7: Mauritius at Anahita | B7: =B6+1 -> 6 | C7: 3 | D7: 2021 | E7: =TOTAL!E7 -> 5315 | F7: =HOTEL!R9 -> 26 | G7: =HOTEL!T9 -> 0 | H7: =HOTEL!DX9 -> 0 | I7: =HOTEL!DZ9 -> 0 | J7: =HOTEL!EB9 -> 0 | K7: =HOTEL!ED9 -> 0 | L7: =N7+W7+X7 -> 20 | M7: =HOTEL!AE9 -> 0 | N7: =HOTEL!AI9 -> 0 | O7: =HOTEL!AM9 -> 0 | P7: =HOTEL!AO9 -> 0 | Q7: =HOTEL!AQ9 -> 0 | R7: =HOTEL!AS9 -> 0 | S7: =HOTEL!AU9 -> 0 | T7: =HOTEL!AW9 -> 0 | U7: =HOTEL!AY9 -> 0 | V7: =HOTEL!BA9 -> 1 | W7: =HOTEL!BM9 -> 10 | X7: =HOTEL!BT9 -> 10 | Y7: =HOTEL!CO9 -> 4.88 | Z7: =HOTEL!CR8 -> 0 | AA7: =HOTEL!CU9 -> 0 | AB7: =HOTEL!CX9 -> 0 | AC7: =HOTEL!DA9 -> 2.39 | AD7: =HOTEL!DD9 -> 0 | AE7: =HOTEL!DG9 -> 0 | AF7: =HOTEL!DJ9 -> 0 | AG7: =HOTEL!DM9 -> 0 | AH7: =HOTEL!DP9 -> 0 | AI7: =HOTEL!DS9 -> 0 | AJ7: =HOTEL!DV9 -> 14.34 | AK7: =TOTAL!K7 -> 2
A8: Mauritius at Anahita | B8: =B7+1 -> 7 | C8: 3 | D8: 2021 | E8: =TOTAL!E8 -> 6678 | F8: =HOTEL!R10 -> 163 | G8: =HOTEL!T10 -> 4 | H8: =HOTEL!DX10 -> 0 | I8: =HOTEL!DZ10 -> 0 | J8: =HOTEL!EB10 -> 0 | K8: =HOTEL!ED10 -> 0 | L8: =N8+W8+X8 -> 20 | M8: =HOTEL!AE10 -> 0 | N8: =HOTEL!AI10 -> 0 | O8: =HOTEL!AM10 -> 0 | P8: =HOTEL!AO10 -> 1 | Q8: =HOTEL!AQ10 -> 0 | R8: =HOTEL!AS10 -> 0 | S8: =HOTEL!AU10 -> 0 | T8: =HOTEL!AW10 -> 0 | U8: =HOTEL!AY10 -> 0 | V8: =HOTEL!BA10 -> 0 | W8: =HOTEL!BM10 -> 20 | X8: =HOTEL!BT10 -> 0 | Y8: =HOTEL!CO10 -> 2.44 | Z8: =HOTEL!CR9 -> 0 | AA8: =HOTEL!CU10 -> 0 | AB8: =HOTEL!CX10 -> 0 | AC8: =HOTEL!DA10 -> 2.39 | AD8: =HOTEL!DD10 -> 0 | AE8: =HOTEL!DG10 -> 0 | AF8: =HOTEL!DJ10 -> 0 | AG8: =HOTEL!DM10 -> 0 | AH8: =HOTEL!DP10 -> 0 | AI8: =HOTEL!DS10 -> 0 | AJ8: =HOTEL!DV10 -> 14.34 | AK8: =TOTAL!K8 -> 2
A9: Mauritius at Anahita | B9: =B8+1 -> 8 | C9: 3 | D9: 2021 | E9: =TOTAL!E9 -> 5960 | F9: =HOTEL!R11 -> 59 | G9: =HOTEL!T11 -> 3 | H9: =HOTEL!DX11 -> 0 | I9: =HOTEL!DZ11 -> 0 | J9: =HOTEL!EB11 -> 0 | K9: =HOTEL!ED11 -> 0 | L9: =N9+W9+X9 -> 30 | M9: =HOTEL!AE11 -> 5 | N9: =HOTEL!AI11 -> 20 | O9: =HOTEL!AM11 -> 0 | P9: =HOTEL!AO11 -> 0 | Q9: =HOTEL!AQ11 -> 0 | R9: =HOTEL!AS11 -> 0 | S9: =HOTEL!AU11 -> 0 | T9: =HOTEL!AW11 -> 0 | U9: =HOTEL!AY11 -> 0 | V9: =HOTEL!BA11 -> 0 | W9: =HOTEL!BM11 -> 10 | X9: =HOTEL!BT11 -> 0 | Y9: =HOTEL!CO11 -> 2.44 | Z9: =HOTEL!CR10 -> 0 | AA9: =HOTEL!CU11 -> 0 | AB9: =HOTEL!CX11 -> 0 | AC9: =HOTEL!DA11 -> 0 | AD9: =HOTEL!DD11 -> 0 | AE9: =HOTEL!DG11 -> 0 | AF9: =HOTEL!DJ11 -> 0 | AG9: =HOTEL!DM11 -> 0 | AH9: =HOTEL!DP11 -> 0 | AI9: =HOTEL!DS11 -> 0 | AJ9: =HOTEL!DV11 -> 4.78 | AK9: =TOTAL!K9 -> 2
A10: Mauritius at Anahita | B10: =B9+1 -> 9 | C10: 3 | D10: 2021 | E10: =TOTAL!E10 -> 5456 | F10: =HOTEL!R12 -> 24 | G10: =HOTEL!T12 -> 0 | H10: =HOTEL!DX12 -> 0 | I10: =HOTEL!DZ12 -> 0 | J10: =HOTEL!EB12 -> 0 | K10: =HOTEL!ED12 -> 0 | L10: =N10+W10+X10 -> 30 | M10: =HOTEL!AE12 -> 0 | N10: =HOTEL!AI12 -> 10 | O10: =HOTEL!AM12 -> 0 | P10: =HOTEL!AO12 -> 0 | Q10: =HOTEL!AQ12 -> 0 | R10: =HOTEL!AS12 -> 1 | S10: =HOTEL!AU12 -> 0 | T10: =HOTEL!AW12 -> 0 | U10: =HOTEL!AY12 -> 0 | V10: =HOTEL!BA12 -> 0 | W10: =HOTEL!BM12 -> 20 | X10: =HOTEL!BT12 -> 0 | Y10: =HOTEL!CO12 -> 2.44 | Z10: =HOTEL!CR11 -> 0 | AA10: =HOTEL!CU12 -> 0 | AB10: =HOTEL!CX12 -> 2.44 | AC10: =HOTEL!DA12 -> 2.39 | AD10: =HOTEL!DD12 -> 0 | AE10: =HOTEL!DG12 -> 0 | AF10: =HOTEL!DJ12 -> 0 | AG10: =HOTEL!DM12 -> 0 | AH10: =HOTEL!DP12 -> 0 | AI10: =HOTEL!DS12 -> 0 | AJ10: =HOTEL!DV12 -> 9.56 | AK10: =TOTAL!K10 -> 2
A11: Mauritius at Anahita | B11: =B10+1 -> 10 | C11: 3 | D11: 2021 | E11: =TOTAL!E11 -> 6272 | F11: =HOTEL!R13 -> 90 | G11: =HOTEL!T13 -> 4 | H11: =HOTEL!DX13 -> 0 | I11: =HOTEL!DZ13 -> 0 | J11: =HOTEL!EB13 -> 0 | K11: =HOTEL!ED13 -> 0 | L11: =N11+W11+X11 -> 20 | M11: =HOTEL!AE13 -> 0 | N11: =HOTEL!AI13 -> 0 | O11: =HOTEL!AM13 -> 0 | P11: =HOTEL!AO13 -> 0 | Q11: =HOTEL!AQ13 -> 0 | R11: =HOTEL!AS13 -> 0 | S11: =HOTEL!AU13 -> 0 | T11: =HOTEL!AW13 -> 0 | U11: =HOTEL!AY13 -> 0 | V11: =HOTEL!BA13 -> 0 | W11: =HOTEL!BM13 -> 10 | X11: =HOTEL!BT13 -> 10 | Y11: =HOTEL!CO13 -> 0 | Z11: =HOTEL!CR12 -> 0 | AA11: =HOTEL!CU13 -> 0 | AB11: =HOTEL!CX13 -> 0 | AC11: =HOTEL!DA13 -> 0 | AD11: =HOTEL!DD13 -> 0 | AE11: =HOTEL!DG13 -> 0 | AF11: =HOTEL!DJ13 -> 0 | AG11: =HOTEL!DM13 -> 0 | AH11: =HOTEL!DP13 -> 0 | AI11: =HOTEL!DS13 -> 0 | AJ11: =HOTEL!DV13 -> 14.34 | AK11: =TOTAL!K11 -> 2
A12: Mauritius at Anahita | B12: =B11+1 -> 11 | C12: 3 | D12: 2021 | E12: =TOTAL!E12 -> 5797 | F12: =HOTEL!R14 -> 65 | G12: =HOTEL!T14 -> 3 | H12: =HOTEL!DX14 -> 0 | I12: =HOTEL!DZ14 -> 0 | J12: =HOTEL!EB14 -> 0 | K12: =HOTEL!ED14 -> 0 | L12: =N12+W12+X12 -> 10 | M12: =HOTEL!AE14 -> 0 | N12: =HOTEL!AI14 -> 0 | O12: =HOTEL!AM14 -> 0 | P12: =HOTEL!AO14 -> 0 | Q12: =HOTEL!AQ14 -> 0 | R12: =HOTEL!AS14 -> 0 | S12: =HOTEL!AU14 -> 0 | T12: =HOTEL!AW14 -> 0 | U12: =HOTEL!AY14 -> 0 | V12: =HOTEL!BA14 -> 0 | W12: =HOTEL!BM14 -> 10 | X12: =HOTEL!BT14 -> 0 | Y12: =HOTEL!CO14 -> 2.196 | Z12: =HOTEL!CR13 -> 0 | AA12: =HOTEL!CU14 -> 0 | AB12: =HOTEL!CX14 -> 0 | AC12: =HOTEL!DA14 -> 0 | AD12: =HOTEL!DD14 -> 0 | AE12: =HOTEL!DG14 -> 0 | AF12: =HOTEL!DJ14 -> 0 | AG12: =HOTEL!DM14 -> 0 | AH12: =HOTEL!DP14 -> 0 | AI12: =HOTEL!DS14 -> 0 | AJ12: =HOTEL!DV14 -> 4.78 | AK12: =TOTAL!K12 -> 2
A13: Mauritius at Anahita | B13: =B12+1 -> 12 | C13: 3 | D13: 2021 | E13: =TOTAL!E13 -> 5602 | F13: =HOTEL!R15 -> 45 | G13: =HOTEL!T15 -> 1 | H13: =HOTEL!DX15 -> 0 | I13: =HOTEL!DZ15 -> 0 | J13: =HOTEL!EB15 -> 0 | K13: =HOTEL!ED15 -> 0 | L13: =N13+W13+X13 -> 30 | M13: =HOTEL!AE15 -> 0 | N13: =HOTEL!AI15 -> 0 | O13: =HOTEL!AM15 -> 0 | P13: =HOTEL!AO15 -> 0 | Q13: =HOTEL!AQ15 -> 0 | R13: =HOTEL!AS15 -> 0 | S13: =HOTEL!AU15 -> 0 | T13: =HOTEL!AW15 -> 0 | U13: =HOTEL!AY15 -> 0 | V13: =HOTEL!BA15 -> 1 | W13: =HOTEL!BM15 -> 20 | X13: =HOTEL!BT15 -> 10 | Y13: =HOTEL!CO15 -> 0.976 | Z13: =HOTEL!CR14 -> 0 | AA13: =HOTEL!CU15 -> 0 | AB13: =HOTEL!CX15 -> 0 | AC13: =HOTEL!DA15 -> 2.39 | AD13: =HOTEL!DD15 -> 0 | AE13: =HOTEL!DG15 -> 0 | AF13: =HOTEL!DJ15 -> 0 | AG13: =HOTEL!DM15 -> 0 | AH13: =HOTEL!DP15 -> 0 | AI13: =HOTEL!DS15 -> 0 | AJ13: =HOTEL!DV15 -> 9.56 | AK13: =TOTAL!K13 -> 2
A14: Mauritius at Anahita | B14: =B13+1 -> 13 | C14: 3 | D14: 2021 | E14: =TOTAL!E14 -> 6460 | F14: =HOTEL!R16 -> 97 | G14: =HOTEL!T16 -> 4 | H14: =HOTEL!DX16 -> 0 | I14: =HOTEL!DZ16 -> 0 | J14: =HOTEL!EB16 -> 0 | K14: =HOTEL!ED16 -> 0 | L14: =N14+W14+X14 -> 20 | M14: =HOTEL!AE16 -> 0 | N14: =HOTEL!AI16 -> 0 | O14: =HOTEL!AM16 -> 0 | P14: =HOTEL!AO16 -> 0 | Q14: =HOTEL!AQ16 -> 0 | R14: =HOTEL!AS16 -> 0 | S14: =HOTEL!AU16 -> 0 | T14: =HOTEL!AW16 -> 0 | U14: =HOTEL!AY16 -> 0 | V14: =HOTEL!BA16 -> 16 | W14: =HOTEL!BM16 -> 10 | X14: =HOTEL!BT16 -> 10 | Y14: =HOTEL!CO16 -> 2.684 | Z14: =HOTEL!CR15 -> 0 | AA14: =HOTEL!CU16 -> 0 | AB14: =HOTEL!CX16 -> 0 | AC14: =HOTEL!DA16 -> 0 | AD14: =HOTEL!DD16 -> 0 | AE14: =HOTEL!DG16 -> 0 | AF14: =HOTEL!DJ16 -> 0 | AG14: =HOTEL!DM16 -> 0 | AH14: =HOTEL!DP16 -> 0 | AI14: =HOTEL!DS16 -> 0 | AJ14: =HOTEL!DV16 -> 16.73 | AK14: =TOTAL!K14 -> 2
... A32: Mauritius at Anahita | B32: =B31+1 -> 31 | C32: 3 | D32: 2021 | E32: =TOTAL!E32 -> 6355 | F32: =HOTEL!R34 -> 28 | G32: =HOTEL!T34 -> 1 | H32: =HOTEL!DX34 -> 0 | I32: =HOTEL!DZ34 -> 0 | J32: =HOTEL!EB34 -> 0 | K32: =HOTEL!ED34 -> 0 | L32: =N32+W32+X32 -> 20 | M32: =HOTEL!AE34 -> 7 | N32: =HOTEL!AI34 -> 0 | O32: =HOTEL!AM34 -> 0 | P32: =HOTEL!AO34 -> 1 | Q32: =HOTEL!AQ34 -> 0 | R32: =HOTEL!AS34 -> 0 | S32: =HOTEL!AU34 -> 0 | T32: =HOTEL!AW34 -> 0 | U32: =HOTEL!AY34 -> 0 | V32: =HOTEL!BA34 -> 0 | W32: =HOTEL!BM34 -> 10 | X32: =HOTEL!BT34 -> 10 | Y32: =HOTEL!CO34 -> 4.636 | Z32: =HOTEL!CR33 -> 0 | AA32: =HOTEL!CU34 -> 0 | AB32: =HOTEL!CX34 -> 0 | AC32: =HOTEL!DA34 -> 2.39 | AD32: =HOTEL!DD34 -> 0 | AE32: =HOTEL!DG34 -> 0 | AF32: =HOTEL!DJ34 -> 0 | AG32: =HOTEL!DM34 -> 0 | AH32: =HOTEL!DP34 -> 0 | AI32: =HOTEL!DS34 -> 0 | AJ32: =HOTEL!DV34 -> 4.302 | AK32: =TOTAL!K32 -> 3

Sheet HOTEL
B1: Hotel Electricity | I1: Gen 01 | M1: Gen 02 | Q1: Vacoas KW | R1: CONS | S1: Laundry (KWh) | T1: CONS | U1: Hotel | W1: % Water Available | AB1: Water Softener | AD1: bamboo pool | AF1: laundry | AG1: CONS | AH1: Island | AJ1: Island Sub | AL1: Main Building | AN1: Pantry A | AP1: Pantry B | AR1: Pantry C | AT1: Pantry D | AV1: Pantry E | AX1: Pantry F | AZ1: Pantry G | BL1: North | BN1: North Sub | BP1: South | BR1: South Sub | BW1: Diesel | CA1: Gas | CV1: Steam Boiler | CY1: Main Building | DB1: Pantry A | DE1: Pantry B | DH1: Pantry C | DK1: Pantry D | DN1: Pantry E | DQ1: Pantry F | DT1: Pantry G | EH1: Pool Temperature
A2: Date | B2: KVAH | C2: CONS | D2: KWH | E2: CONS | F2: PF | G2: KVA | H2: KVA max | U2: CWA23 | V2: CONS | X2: Truck Meter | Y2: Cons | Z2: UV reading | AB2: chiller | AC2: CONS | AE2: CONS | AH2: island | AI2: cons | AL2: M.Buil | AM2: Cons | AN2: Pantry A | AO2: Cons | AP2: Pantry B | AQ2: Cons | AR2: Pantry C | AS2: cons | AT2: Pantry D | AU2: cons | AV2: Pantry E | AW2: cons | AX2: Pantry F | AY2: Cons | AZ2: Pantry G | BA2: Cons | BB2: Main Kitchen | BC2: Cons | BD2: Bamboo H | BE2: Cons | BF2: Bamboo C | BG2: Cons | BH2: cyclon bridge | BI2: cons | BJ2: Island - Hot | BK2: Island Cold | BL2: north | BM2: cons | BP2: south | BQ2: cons | BT2: south | BU2: Total water consump | BV2: Total HW consump | BW2: DIESEL | BX2: stock | BY2: Del | BZ2: CONS | CA2: Meter | CB2: cons | CC2: Kg | CD2: LPG 1 | CE2: stock | CF2: LPG 2 | CG2: stock | CH2: LPG 3 | CI2: stock | CJ2: total stock | CK2: cons | CL2: del | CM2: Beau champ | CN2: cons(Litres) | CO2: Cons(Kg) | CP2: Acquapazza | CQ2: cons(Litres) | CR2: Cons(Kg) | CS2: Bamboo | CT2: cons(Litres) | CU2: Cons(Kg) | CW2: cons(Litres) | CX2: Cons(Kg) | CZ2: cons(Litres) | DA2: Cons(Kg) | DC2: cons(Litres) | DD2: Cons(Kg) | DF2: cons(Litres) | DG2: Cons(Kg) | DI2: cons(Litres) | DJ2: Cons(Kg) | DL2: cons(Litres) | DM2: Cons(Kg) | DO2: cons(Litres) | DP2: Cons(Kg) | DR2: cons(Litres) | DS2: Cons(Kg) | DU2: cons(Litres) | DV2: Cons(Kg) | DW2: 145 | DX2: CONS | DY2: 146 | DZ2: CONS | EA2: Villa 111 | EB2: CONS | EC2: Villa 128 | ED2: CONS | EE2: Room Nights | EF2: Bed Nights | EG2: % OCC | EH2: California | EI2: Infiniti | EJ2: Fitness
A3: 44255 | B3: 6452825 | C3: 5869 | D3: 5701596 | E3: 5606 | F3: 0.95518828 | G3: 524 | H3: 478 | I3: 287894 | J3: 0 | K3: 773 | L3: 0 | M3: 633765 | N3: 0 | O3: 991 | P3: 0 | Q3: 2545624 | R3: 25 | S3: 2191525 | T3: 1 | U3: 107968 | V3: 29 | W3: 100 | X3: 152370 | Y3: 0 | Z3: 39467 | AA3: 3 | AB3: 1110 | AC3: 0 | AD3: 4521 | AE3: 0 | AF3: 579380 | AG3: 30 | AH3: 579860 | AI3: 10 | AJ3: 458 | AK3: 0 | AL3: 52216 | AM3: 1 | AN3: 8909 | AO3: 0 | AP3: 10571 | AQ3: 0 | AR3: 14547 | AS3: 0 | AT3: 19369 | AU3: 0 | AV3: 20677 | AW3: 0 | AX3: 13871 | AY3: 0 | AZ3: 6189 | BA3: 0 | BB3: 26455 | BC3: 1 | BD3: 1115 | BE3: 0 | BF3: 4369 | BG3: 0 | BH3: 3636 | BI3: 0 | BJ3: 0 | BK3: 10 | BL3: 600230 | BM3: 30 | BN3: 676 | BO3: 0 | BP3: 778120 | BQ3: 10 | BR3: 6487 | BS3: 0 | BT3: 0 | BU3: 40 | BV3: 1 | BW3: 126 | BX3: 15750.41 | BZ3: 0 | CA3: 206430 | CB3: 0.3 | CC3: 1.713 | CD3: 43 | CE3: 4633 | CF3: 42 | CG3: 4526 | CH3: 44 | CI3: 4741 | CJ3: 13900 | CK3: 108 | CM3: 34470 | CN3: 1 | CO3: 2.44 | CP3: 34300 | CQ3: 0 | CR3: 0 | CS3: 10235.6 | CT3: 0 | CU3: 0 | CV3: 832139 | CW3: 0 | CX3: 0 | CY3: 5950 | CZ3: 0.6 | DA3: 1.434 | DB3: 7420 | DC3: 0 | DD3: 0 | DE3: 3840 | DF3: 0 | DG3: 0 | DH3: 1855.9 | DI3: 0 | DJ3: 0 | DK3: 5081.7 | DL3: 0 | DM3: 0 | DN3: 4454.7 | DO3: 0 | DP3: 0 | DQ3: 5089.6 | DR3: 0 | DS3: 0 | DT3: 4813 | DU3: 4.1 | DV3: 9.799 | DW3: 12871 | DX3: 0 | DY3: 62789 | DZ3: 0 | EA3: 15599 | EB3: 0 | EC3: 24679 | ED3: 0 | EE3: 2 | EF3: 6 | EG3: 0.015
A4: 44256 | B4: 6459307 | C4: 6482 | D4: 5707862 | E4: 6266 | F4: 0.96667695 | G4: 320 | H4: 478 | I4: 287894 | J4: 0 | K4: 773 | L4: 0 | M4: 633765 | N4: 0 | O4: 991 | P4: 0 | Q4: 2545720 | R4: 96 | S4: 2191529 | T4: 4 | U4: 108024 | V4: 56 | W4: 100 | X4: 152370 | Y4: 0 | Z4: 39467 | AA4: 0 | AB4: 1110 | AC4: 0 | AD4: 4521 | AE4: 0 | AF4: 579390 | AG4: 10 | AH4: 579890 | AI4: 30 | AJ4: 458 | AK4: 0 | AL4: 52217 | AM4: 1 | AN4: 8909 | AO4: 0 | AP4: 10571 | AQ4: 0 | AR4: 14548 | AS4: 1 | AT4: 19369 | AU4: 0 | AV4: 20677 | AW4: 0 | AX4: 13871 | AY4: 0 | AZ4: 6190 | BA4: 1 | BB4: 26455 | BC4: 0 | BD4: 1115 | BE4: 0 | BF4: 4371 | BG4: 2 | BH4: 3636 | BI4: 0 | BJ4: 1 | BK4: 29 | BL4: 600250 | BM4: 20 | BN4: 676 | BO4: 0 | BP4: 778150 | BQ4: 30 | BR4: 6488 | BS4: 1 | BT4: 0 | BU4: 50 | BV4: 3 | BW4: 126 | BX4: 15750.41 | BZ4: 0 | CA4: 206431 | CB4: 1 | CC4: 5.71 | CD4: 43 | CE4: 4633 | CF4: 42 | CG4: 4526 | CH4: 44 | CI4: 4741 | CJ4: 13900 | CK4: 0 | CM4: 34471 | CN4: 1 | CO4: 2.44 | CP4: 34300 | CQ4: 0 | CR4: 0 | CS4: 10235.6 | CT4: 0 | CU4: 0 | CV4: 832139 | CW4: 0 | CX4: 0 | CY4: 5951 | CZ4: 1 | DA4: 2.39 | DB4: 7420 | DC4: 0 | DD4: 0 | DE4: 3840 | DF4: 0 | DG4: 0 | DH4: 1855.9 | DI4: 0 | DJ4: 0 | DK4: 5081.7 | DL4: 0 | DM4: 0 | DN4: 4454.7 | DO4: 0 | DP4: 0 | DQ4: 5089.6 | DR4: 0 | DS4: 0 | DT4: 4819 | DU4: 6 | DV4: 14.34 | DW4: 12871 | DX4: 0 | DY4: 62789 | DZ4: 0 | EA4: 15599 | EB4: 0 | EC4: 24679 | ED4: 0 | EE4: 2 | EF4: 6 | EG4: 0.015
A5: 44257 | B5: 6465622 | C5: 6315 | D5: 5713921 | E5: 6059 | F5: 0.9594616 | G5: 340 | H5: 478 | I5: 287894 | J5: 0 | K5: 773 | L5: 0 | M5: 633765 | N5: 0 | O5: 991 | P5: 0 | Q5: 2545783 | R5: 63 | S5: 2191577 | T5: 48 | U5: 108084 | V5: 60 | W5: 100 | X5: 152370 | Y5: 0 | Z5: 39479 | AA5: 12 | AB5: 1110 | AC5: 0 | AD5: 4521 | AE5: 0 | AF5: 579400 | AG5: 10 | AH5: 579910 | AI5: 20 | AJ5: 461 | AK5: 3 | AL5: 52221 | AM5: 4 | AN5: 8909 | AO5: 0 | AP5: 10571 | AQ5: 0 | AR5: 14548 | AS5: 0 | AT5: 19369 | AU5: 0 | AV5: 20677 | AW5: 0 | AX5: 13871 | AY5: 0 | AZ5: 6190 | BA5: 0 | BB5: 26456 | BC5: 1 | BD5: 1115 | BE5: 0 | BF5: 4371 | BG5: 0 | BH5: 3636 | BI5: 0 | BJ5: 0 | BK5: 20 | BL5: 600270 | BM5: 20 | BN5: 676 | BO5: 0 | BP5: 778180 | BQ5: 30 | BR5: 6492 | BS5: 4 | BT5: 10 | BU5: 50 | BV5: 4 | BW5: 126 | BX5: 15750.41 | BZ5: 0 | CA5: 206452 | CB5: 21 | CC5: 119.91 | CD5: 43 | CE5: 4633 | CF5: 42 | CG5: 4526 | CH5: 43 | CI5: 4633 | CJ5: 13792 | CK5: 108 | CM5: 34473 | CN5: 2 | CO5: 4.88 | CP5: 34300 | CQ5: 0 | CR5: 0 | CS5: 10235.6 | CT5: 0 | CU5: 0 | CV5: 832144 | CW5: 5 | CX5: 12.2 | CY5: 5953 | CZ5: 2 | DA5: 4.78 | DB5: 7420 | DC5: 0 | DD5: 0 | DE5: 3840 | DF5: 0 | DG5: 0 | DH5: 1855.9 | DI5: 0 | DJ5: 0 | DK5: 5081.7 | DL5: 0 | DM5: 0 | DN5: 4454.7 | DO5: 0 | DP5: 0 | DQ5: 5089.6 | DR5: 0 | DS5: 0 | DT5: 4821 | DU5: 2 | DV5: 4.78 | DW5: 12871 | DX5: 0 | DY5: 62789 | DZ5: 0 | EA5: 15599 | EB5: 0 | EC5: 24679 | ED5: 0 | EE5: 2 | EF5: 6 | EG5: 0.015
A6: 44258 | B6: 6472310 | C6: 6688 | D6: 5720396 | E6: 6475 | F6: 0.96815191 | G6: 374 | H6: 478 | I6: 287894 | J6: 0 | K6: 773 | L6: 0 | M6: 633765 | N6: 0 | O6: 991 | P6: 0 | Q6: 2545816 | R6: 33 | S6: 2191578 | T6: 1 | U6: 108155 | V6: 71 | W6: 100 | X6: 152370 | Y6: 0 | Z6: 39485 | AA6: 6 | AB6: 1110 | AC6: 0 | AD6: 4521 | AE6: 0 | AF6: 579450 | AG6: 50 | AH6: 579940 | AI6: 30 | AJ6: 465 | AK6: 4 | AL6: 52222 | AM6: 1 | AN6: 8909 | AO6: 0 | AP6: 10571 | AQ6: 0 | AR6: 14549 | AS6: 1 | AT6: 19369 | AU6: 0 | AV6: 20677 | AW6: 0 | AX6: 13871 | AY6: 0 | AZ6: 6190 | BA6: 0 | BB6: 26457 | BC6: 1 | BD6: 1115 | BE6: 0 | BF6: 4372 | BG6: 1 | BH6: 3636 | BI6: 0 | BJ6: 1 | BK6: 29 | BL6: 600300 | BM6: 30 | BN6: 676 | BO6: 0 | BP6: 778220 | BQ6: 40 | BR6: 6503 | BS6: 11 | BT6: 10 | BU6: 70 | BV6: 2 | BW6: 126 | BX6: 15750.41 | BZ6: 0 | CA6: 206454 | CB6: 2 | CC6: 11.42 | CD6: 43 | CE6: 4633 | CF6: 42 | CG6: 4526 | CH6: 43 | CI6: 4633 | CJ6: 13792 | CK6: 0 | CM6: 34475 | CN6: 2 | CO6: 4.88 | CP6: 34300 | CQ6: 0 | CR6: 0 | CS6: 10235.6 | CT6: 0 | CU6: 0 | CV6: 832144 | CW6: 0 | CX6: 0 | CY6: 5954 | CZ6: 1 | DA6: 2.39 | DB6: 7420 | DC6: 0 | DD6: 0 | DE6: 3840 | DF6: 0 | DG6: 0 | DH6: 1855.9 | DI6: 0 | DJ6: 0 | DK6: 5081.7 | DL6: 0 | DM6: 0 | DN6: 4454.7 | DO6: 0 | DP6: 0 | DQ6: 5089.6 | DR6: 0 | DS6: 0 | DT6: 4825 | DU6: 4 | DV6: 9.56 | DW6: 12871 | DX6: 0 | DY6: 62789 | DZ6: 0 | EA6: 15599 | EB6: 0 | EC6: 24679 | ED6: 0 | EE6: 2 | EF6: 6 | EG6: 0.015
A7: 44259 | B7: 6478961 | C7: 6651 | D7: 5726872 | E7: 6476 | F7: 0.97368817 | G7: 374 | H7: 478 | I7: 287894 | J7: 0 | K7: 773 | L7: 0 | M7: 633765 | N7: 0 | O7: 991 | P7: 0 | Q7: 2545954 | R7: 138 | S7: 2191582 | T7: 4 | U7: 108232 | V7: 77 | W7: 100 | X7: 152370 | Y7: 0 | Z7: 39494 | AA7: 9 | AB7: 1110 | AC7: 0 | AD7: 4531 | AE7: 10 | AF7: 579470 | AG7: 20 | AH7: 579980 | AI7: 40 | AJ7: 467 | AK7: 2 | AL7: 52222 | AM7: 0 | AN7: 8909 | AO7: 0 | AP7: 10571 | AQ7: 0 | AR7: 14550 | AS7: 1 | AT7: 19369 | AU7: 0 | AV7: 20677 | AW7: 0 | AX7: 13871 | AY7: 0 | AZ7: 6190 | BA7: 0 | BB7: 26458 | BC7: 1 | BD7: 1115 | BE7: 0 | BF7: 4372 | BG7: 0 | BH7: 3636 | BI7: 0 | BJ7: 1 | BK7: 39 | BL7: 600330 | BM7: 30 | BN7: 676 | BO7: 0 | BP7: 778270 | BQ7: 50 | BR7: 6513 | BS7: 10 | BT7: 10 | BU7: 80 | BV7: 1 | BW7: 126 | BX7: 15750.41 | BZ7: 0 | CA7: 206455 | CB7: 1 | CC7: 5.71 | CD7: 43 | CE7: 4633 | CF7: 42 | CG7: 4526 | CH7: 43 | CI7: 4633 | CJ7: 13792 | CK7: 0 | CM7: 34478 | CN7: 3 | CO7: 7.32 | CP7: 34300 | CQ7: 0 | CR7: 0 | CS7: 10235.6 | CT7: 0 | CU7: 0 | CV7: 832144 | CW7: 0 | CX7: 0 | CY7: 5955 | CZ7: 1 | DA7: 2.39 | DB7: 7420 | DC7: 0 | DD7: 0 | DE7: 3840 | DF7: 0 | DG7: 0 | DH7: 1855.9 | DI7: 0 | DJ7: 0 | DK7: 5081.7 | DL7: 0 | DM7: 0 | DN7: 4454.7 | DO7: 0 | DP7: 0 | DQ7: 5089.6 | DR7: 0 | DS7: 0 | DT7: 4831 | DU7: 6 | DV7: 14.34 | DW7: 12871 | DX7: 0 | DY7: 62789 | DZ7: 0 | EA7: 15599 | EB7: 0 | EC7: 24679 | ED7: 0 | EE7: 2 | EF7: 6 | EG7: 0.015
A8: 44260 | B8: 6485112 | C8: 6151 | D8: 5732768 | E8: 5896 | F8: 0.95854333 | G8: 394 | H8: 478 | I8: 287902 | J8: 8 | K8: 774 | L8: 0 | M8: 633790 | N8: 0 | O8: 991 | P8: 0 | Q8: 2546045 | R8: 91 | S8: 2191585 | T8: 3 | U8: 108265 | V8: 33 | W8: 100 | X8: 152370 | Y8: 0 | Z8: 39497 | AA8: 3 | AB8: 1110 | AC8: 0 | AD8: 4531 | AE8: 0 | AF8: 579490 | AG8: 20 | AH8: 579980 | AI8: 0 | AJ8: 467 | AK8: 0 | AL8: 52223 | AM8: 1 | AN8: 8909 | AO8: 0 | AP8: 10571 | AQ8: 0 | AR8: 14550 | AS8: 0 | AT8: 19369 | AU8: 0 | AV8: 20677 | AW8: 0 | AX8: 13871 | AY8: 0 | AZ8: 6190 | BA8: 0 | BB8: 26458 | BC8: 0 | BD8: 1115 | BE8: 0 | BF8: 4372 | BG8: 0 | BH8: 3636 | BI8: 0 | BJ8: 0 | BK8: 0 | BL8: 600350 | BM8: 20 | BN8: 676 | BO8: 0 | BP8: 778270 | BQ8: 0 | BR8: 6518 | BS8: 5 | BT8: 0 | BU8: 20 | BV8: 1 | BW8: 126 | BX8: 15750.41 | BZ8: 0 | CA8: 206455 | CB8: 0 | CC8: 0 | CD8: 43 | CE8: 4633 | CF8: 42 | CG8: 4526 | CH8: 43 | CI8: 4633 | CJ8: 13792 | CK8: 0 | CM8: 34479 | CN8: 1 | CO8: 2.44 | CP8: 34300 | CQ8: 0 | CR8: 0 | CS8: 10235.6 | CT8: 0 | CU8: 0 | CV8: 832144 | CW8: 0 | CX8: 0 | CY8: 5955 | CZ8: 0 | DA8: 0 | DB8: 7420 | DC8: 0 | DD8: 0 | DE8: 3840 | DF8: 0 | DG8: 0 | DH8: 1855.9 | DI8: 0 | DJ8: 0 | DK8: 5081.7 | DL8: 0 | DM8: 0 | DN8: 4454.7 | DO8: 0 | DP8: 0 | DQ8: 5089.6 | DR8: 0 | DS8: 0 | DT8: 4831 | DU8: 0 | DV8: 0 | DW8: 12871 | DX8: 0 | DY8: 62789 | DZ8: 0 | EA8: 15599 | EB8: 0 | EC8: 24679 | ED8: 0 | EE8: 2 | EF8: 6 | EG8: 0.015
A9: 44261 | B9: 6490630 | C9: 5518 | D9: 5738083 | E9: 5315 | F9: 0.96321131 | G9: 394 | H9: 478 | I9: 287902 | J9: 0 | K9: 774 | L9: 0 | M9: 633790 | N9: 0 | O9: 991 | P9: 0 | Q9: 2546071 | R9: 26 | S9: 2191585 | T9: 0 | U9: 108305 | V9: 40 | W9: 100 | X9: 152370 | Y9: 0 | Z9: 39478 | AA9: 0 | AB9: 1110 | AC9: 0 | AD9: 4531 | AE9: 0 | AF9: 579490 | AG9: 0 | AH9: 579980 | AI9: 0 | AJ9: 467 | AK9: 0 | AL9: 52223 | AM9: 0 | AN9: 8909 | AO9: 0 | AP9: 10571 | AQ9: 0 | AR9: 14550 | AS9: 0 | AT9: 19369 | AU9: 0 | AV9: 20677 | AW9: 0 | AX9: 13871 | AY9: 0 | AZ9: 6191 | BA9: 1 | BB9: 26459 | BC9: 1 | BD9: 1115 | BE9: 0 | BF9: 4372 | BG9: 0 | BH9: 3636 | BI9: 0 | BJ9: 0 | BK9: 0 | BL9: 600360 | BM9: 10 | BN9: 676 | BO9: 0 | BP9: 778280 | BQ9: 10 | BR9: 6519 | BS9: 1 | BT9: 10 | BU9: 20 | BV9: 1 | BW9: 126 | BX9: 15750.41 | BZ9: 0 | CA9: 206456 | CB9: 1 | CC9: 5.71 | CD9: 42 | CE9: 4526 | CF9: 42 | CG9: 4526 | CH9: 43 | CI9: 4633 | CJ9: 13684 | CK9: 108 | CM9: 34481 | CN9: 2 | CO9: 4.88 | CP9: 34300 | CQ9: 0 | CR9: 0 | CS9: 10235.6 | CT9: 0 | CU9: 0 | CV9: 832144 | CW9: 0 | CX9: 0 | CY9: 5956 | CZ9: 1 | DA9: 2.39 | DB9: 7420 | DC9: 0 | DD9: 0 | DE9: 3840 | DF9: 0 | DG9: 0 | DH9: 1855.9 | DI9: 0 | DJ9: 0 | DK9: 5081.7 | DL9: 0 | DM9: 0 | DN9: 4454.7 | DO9: 0 | DP9: 0 | DQ9: 5089.6 | DR9: 0 | DS9: 0 | DT9: 4837 | DU9: 6 | DV9: 14.34 | DW9: 12871 | DX9: 0 | DY9: 62789 | DZ9: 0 | EA9: 15599 | EB9: 0 | EC9: 24679 | ED9: 0 | EE9: 2 | EF9: 6 | EG9: 0.015
A10: 44262 | B10: 6497526 | C10: 6896 | D10: 5744761 | E10: 6678 | F10: 0.96838747 | G10: 394 | H10: 478 | I10: 287902 | J10: 0 | K10: 774 | L10: 0 | M10: 633790 | N10: 0 | O10: 991 | P10: 0 | Q10: 2546234 | R10: 163 | S10: 2191589 | T10: 4 | U10: 108340 | V10: 35 | W10: 100 | X10: 152370 | Y10: 0 | Z10: 39500 | AA10: 22 | AB10: 1111 | AC10: 1 | AD10: 4531 | AE10: 0 | AF10: 579490 | AG10: 0 | AH10: 579980 | AI10: 0 | AJ10: 467 | AK10: 0 | AL10: 52223 | AM10: 0 | AN10: 8910 | AO10: 1 | AP10: 10571 | AQ10: 0 | AR10: 14550 | AS10: 0 | AT10: 19369 | AU10: 0 | AV10: 20677 | AW10: 0 | AX10: 13871 | AY10: 0 | AZ10: 6191 | BA10: 0 | BB10: 26459 | BC10: 0 | BD10: 1115 | BE10: 0 | BF10: 4372 | BG10: 0 | BH10: 3636 | BI10: 0 | BJ10: 0 | BK10: 0 | BL10: 600380 | BM10: 20 | BN10: 676 | BO10: 0 | BP10: 778280 | BQ10: 0 | BR10: 6519 | BS10: 0 | BT10: 0 | BU10: 20 | BV10: 1 | BW10: 126 | BX10: 15750.41 | BZ10: 0 | CA10: 206456 | CB10: 0 | CC10: 0 | CD10: 42 | CE10: 4526 | CF10: 42 | CG10: 4526 | CH10: 43 | CI10: 4633 | CJ10: 13684 | CK10: 0 | CM10: 34482 | CN10: 1 | CO10: 2.44 | CP10: 34300 | CQ10: 0 | CR10: 0 | CS10: 10235.6 | CT10: 0 | CU10: 0 | CV10: 832144 | CW10: 0 | CX10: 0 | CY10: 5957 | CZ10: 1 | DA10: 2.39 | DB10: 7420 | DC10: 0 | DD10: 0 | DE10: 3840 | DF10: 0 | DG10: 0 | DH10: 1855.9 | DI10: 0 | DJ10: 0 | DK10: 5081.7 | DL10: 0 | DM10: 0 | DN10: 4454.7 | DO10: 0 | DP10: 0 | DQ10: 5089.6 | DR10: 0 | DS10: 0 | DT10: 4843 | DU10: 6 | DV10: 14.34 | DW10: 12871 | DX10: 0 | DY10: 62789 | DZ10: 0 | EA10: 15599 | EB10: 0 | EC10: 24679 | ED10: 0 | EE10: 2 | EF10: 6 | EG10: 0.015
A11: 44263 | B11: 6503697 | C11: 6171 | D11: 5750721 | E11: 5960 | F11: 0.96580781 | G11: 394 | H11: 478 | I11: 287902 | J11: 0 | K11: 774 | L11: 0 | M11: 633790 | N11: 0 | O11: 991 | P11: 0 | Q11: 2546293 | R11: 59 | S11: 2191592 | T11: 3 | U11: 108395 | V11: 55 | W11: 100 | X11: 152370 | Y11: 0 | Z11: 39504 | AA11: 4 | AB11: 1111 | AC11: 0 | AD11: 4536 | AE11: 5 | AF11: 579510 | AG11: 20 | AH11: 580000 | AI11: 20 | AJ11: 467 | AK11: 0 | AL11: 52223 | AM11: 0 | AN11: 8910 | AO11: 0 | AP11: 10571 | AQ11: 0 | AR11: 14550 | AS11: 0 | AT11: 19369 | AU11: 0 | AV11: 20677 | AW11: 0 | AX11: 13871 | AY11: 0 | AZ11: 6191 | BA11: 0 | BB11: 26460 | BC11: 1 | BD11: 1115 | BE11: 0 | BF11: 4372 | BG11: 0 | BH11: 3636 | BI11: 0 | BJ11: 0 | BK11: 20 | BL11: 600390 | BM11: 10 | BN11: 676 | BO11: 0 | BP11: 778300 | BQ11: 20 | BR11: 6522 | BS11: 3 | BT11: 0 | BU11: 30 | BV11: 0 | BW11: 125 | BX11: 15594.96 | BZ11: 0 | CA11: 206456 | CB11: 0 | CC11: 0 | CD11: 42 | CE11: 4526 | CF11: 42 | CG11: 4526 | CH11: 42 | CI11: 4526 | CJ11: 13577 | CK11: 108 | CM11: 34483 | CN11: 1 | CO11: 2.44 | CP11: 34300 | CQ11: 0 | CR11: 0 | CS11: 10235.6 | CT11: 0 | CU11: 0 | CV11: 832144 | CW11: 0 | CX11: 0 | CY11: 5957 | CZ11: 0 | DA11: 0 | DB11: 7420 | DC11: 0 | DD11: 0 | DE11: 3840 | DF11: 0 | DG11: 0 | DH11: 1855.9 | DI11: 0 | DJ11: 0 | DK11: 5081.7 | DL11: 0 | DM11: 0 | DN11: 4454.7 | DO11: 0 | DP11: 0 | DQ11: 5089.6 | DR11: 0 | DS11: 0 | DT11: 4845 | DU11: 2 | DV11: 4.78 | DW11: 12871 | DX11: 0 | DY11: 62789 | DZ11: 0 | EA11: 15599 | EB11: 0 | EC11: 24679 | ED11: 0 | EE11: 2 | EF11: 6 | EG11: 0.015
A12: 44264 | B12: 6509392 | C12: 5695 | D12: 5756177 | E12: 5456 | F12: 0.95803336 | G12: 394 | H12: 474 | I12: 287902 | J12: 0 | K12: 774 | L12: 0 | M12: 633790 | N12: 0 | O12: 991 | P12: 0 | Q12: 2546317 | R12: 24 | S12: 2191592 | T12: 0 | U12: 108400 | V12: 5 | W12: 100 | X12: 152370 | Y12: 0 | Z12: 39507 | AA12: 3 | AB12: 1111 | AC12: 0 | AD12: 4536 | AE12: 0 | AF12: 579520 | AG12: 10 | AH12: 580010 | AI12: 10 | AJ12: 467 | AK12: 0 | AL12: 52223 | AM12: 0 | AN12: 8910 | AO12: 0 | AP12: 10571 | AQ12: 0 | AR12: 14551 | AS12: 1 | AT12: 19369 | AU12: 0 | AV12: 20677 | AW12: 0 | AX12: 13871 | AY12: 0 | AZ12: 6191 | BA12: 0 | BB12: 26460 | BC12: 0 | BD12: 1115 | BE12: 0 | BF12: 4372 | BG12: 0 | BH12: 3636 | BI12: 0 | BJ12: 1 | BK12: 9 | BL12: 600410 | BM12: 20 | BN12: 676 | BO12: 0 | BP12: 778310 | BQ12: 10 | BR12: 6523 | BS12: 1 | BT12: 0 | BU12: 30 | BV12: 1 | BW12: 125 | BX12: 15594.96 | BZ12: 0 | CA12: 206456 | CB12: 0 | CC12: 0 | CD12: 42 | CE12: 4526 | CF12: 41 | CG12: 4418 | CH12: 42 | CI12: 4526 | CJ12: 13469 | CK12: 108 | CM12: 34484 | CN12: 1 | CO12: 2.44 | CP12: 34300 | CQ12: 0 | CR12: 0 | CS12: 10235.6 | CT12: 0 | CU12: 0 | CV12: 832145 | CW12: 1 | CX12: 2.44 | CY12: 5958 | CZ12: 1 | DA12: 2.39 | DB12: 7420 | DC12: 0 | DD12: 0 | DE12: 3840 | DF12: 0 | DG12: 0 | DH12: 1855.9 | DI12: 0 | DJ12: 0 | DK12: 5081.7 | DL12: 0 | DM12: 0 | DN12: 4454.7 | DO12: 0 | DP12: 0 | DQ12: 5089.6 | DR12: 0 | DS12: 0 | DT12: 4849 | DU12: 4 | DV12: 9.56 | DW12: 12871 | DX12: 0 | DY12: 62789 | DZ12: 0 | EA12: 15599 | EB12: 0 | EC12: 24679 | ED12: 0 | EE12: 2 | EF12: 6 | EG12: 0.015
A13: 44265 | B13: 6515886 | C13: 6494 | D13: 5762449 | E13: 6272 | F13: 0.9658146 | G13: 396 | H13: 478 | I13: 287902 | J13: 0 | K13: 774 | L13: 0 | M13: 633790 | N13: 0 | O13: 991 | P13: 0 | Q13: 2546407 | R13: 90 | S13: 2191596 | T13: 4 | U13: 108432 | V13: 32 | W13: 100 | X13: 152370 | Y13: 0 | Z13: 39509 | AA13: 2 | AB13: 1111 | AC13: 0 | AD13: 4536 | AE13: 0 | AF13: 579550 | AG13: 30 | AH13: 580010 | AI13: 0 | AJ13: 467 | AK13: 0 | AL13: 52223 | AM13: 0 | AN13: 8910 | AO13: 0 | AP13: 10571 | AQ13: 0 | AR13: 14551 | AS13: 0 | AT13: 19369 | AU13: 0 | AV13: 20677 | AW13: 0 | AX13: 13871 | AY13: 0 | AZ13: 6191 | BA13: 0 | BB13: 26460 | BC13: 0 | BD13: 1115 | BE13: 0 | BF13: 4372 | BG13: 0 | BH13: 3636 | BI13: 0 | BJ13: 0 | BK13: 0 | BL13: 600420 | BM13: 10 | BN13: 676 | BO13: 0 | BP13: 778320 | BQ13: 10 | BR13: 6524 | BS13: 1 | BT13: 10 | BU13: 20 | BV13: 0 | BW13: 125 | BX13: 15594.96 | BZ13: 0 | CA13: 206456 | CB13: 0 | CC13: 0 | CD13: 42 | CE13: 4526 | CF13: 41 | CG13: 4418 | CH13: 42 | CI13: 4526 | CJ13: 13469 | CK13: 0 | CM13: 34484 | CN13: 0 | CO13: 0 | CP13: 34300 | CQ13: 0 | CR13: 0 | CS13: 10235.6 | CT13: 0 | CU13: 0 | CV13: 832145 | CW13: 0 | CX13: 0 | CY13: 5958 | CZ13: 0 | DA13: 0 | DB13: 7420 | DC13: 0 | DD13: 0 | DE13: 3840 | DF13: 0 | DG13: 0 | DH13: 1855.9 | DI13: 0 | DJ13: 0 | DK13: 5081.7 | DL13: 0 | DM13: 0 | DN13: 4454.7 | DO13: 0 | DP13: 0 | DQ13: 5089.6 | DR13: 0 | DS13: 0 | DT13: 4855 | DU13: 6 | DV13: 14.34 | DW13: 12871 | DX13: 0 | DY13: 62789 | DZ13: 0 | EA13: 15599 | EB13: 0 | EC13: 24679 | ED13: 0 | EE13: 2 | EF13: 6 | EG13: 0.015
A14: 44266 | B14: 6521900 | C14: 6014 | D14: 5768246 | E14: 5797 | F14: 0.96391753 | G14: 394 | H14: 478 | I14: 287902 | J14: 0 | K14: 774 | L14: 0 | M14: 633790 | N14: 0 | O14: 991 | P14: 0 | Q14: 2546472 | R14: 65 | S14: 2191599 | T14: 3 | U14: 108460 | V14: 28 | W14: 100 | X14: 152370 | Y14: 0 | Z14: 39511 | AA14: 2 | AB14: 1111 | AC14: 0 | AD14: 4536 | AE14: 0 | AF14: 579560 | AG14: 10 | AH14: 580010 | AI14: 0 | AJ14: 467 | AK14: 0 | AL14: 52223 | AM14: 0 | AN14: 8910 | AO14: 0 | AP14: 10571 | AQ14: 0 | AR14: 14551 | AS14: 0 | AT14: 19369 | AU14: 0 | AV14: 20677 | AW14: 0 | AX14: 13871 | AY14: 0 | AZ14: 6191 | BA14: 0 | BB14: 26460 | BC14: 0 | BD14: 1115 | BE14: 0 | BF14: 4372 | BG14: 0 | BH14: 3636 | BI14: 0 | BJ14: 0 | BK14: 0 | BL14: 600430 | BM14: 10 | BN14: 676 | BO14: 0 | BP14: 778320 | BQ14: 0 | BR14: 6524 | BS14: 0 | BT14: 0 | BU14: 10 | BV14: 0 | BW14: 125 | BX14: 15594.96 | BZ14: 0 | CA14: 206456 | CB14: 0 | CC14: 0 | CD14: 41 | CE14: 4418 | CF14: 41 | CG14: 4418 | CH14: 42 | CI14: 4526 | CJ14: 13361 | CK14: 108 | CM14: 34484.9 | CN14: 0.9 | CO14: 2.196 | CP14: 34300 | CQ14: 0 | CR14: 0 | CS14: 10235.6 | CT14: 0 | CU14: 0 | CV14: 832145 | CW14: 0 | CX14: 0 | CY14: 5958 | CZ14: 0 | DA14: 0 | DB14: 7420 | DC14: 0 | DD14: 0 | DE14: 3840 | DF14: 0 | DG14: 0 | DH14: 1855.9 | DI14: 0 | DJ14: 0 | DK14: 5081.7 | DL14: 0 | DM14: 0 | DN14: 4454.7 | DO14: 0 | DP14: 0 | DQ14: 5089.6 | DR14: 0 | DS14: 0 | DT14: 4857 | DU14: 2 | DV14: 4.78 | DW14: 12871 | DX14: 0 | DY14: 62789 | DZ14: 0 | EA14: 15599 | EB14: 0 | EC14: 24679 | ED14: 0 | EE14: 2 | EF14: 6 | EG14: 0.015
... A21: 44273 | B21: 6571008 | C21: 7887 | D21: 5815618 | E21: 7644 | F21: 0.96918981 | G21: 464 | H21: 478 | I21: 287902 | J21: 0 | K21: 774 | L21: 0 | M21: 633790 | N21: 0 | O21: 991 | P21: 0 | Q21: 2546932 | R21: 119 | S21: 2191615 | T21: 4 | U21: 108773 | V21: 40 | W21: 100 | X21: 152370 | Y21: 0 | Z21: 39541 | AA21: 5 | AB21: 1111 | AC21: 0 | AD21: 4549 | AE21: 0 | AF21: 579680 | AG21: 10 | AH21: 580050 | AI21: 10 | AJ21: 467 | AK21: 0 | AL21: 52225 | AM21: 1 | AN21: 8910 | AO21: 0 | AP21: 10571 | AQ21: 0 | AR21: 14551 | AS21: 0 | AT21: 19369 | AU21: 0 | AV21: 20677 | AW21: 0 | AX21: 13871 | AY21: 0 | AZ21: 6214 | BA21: 2 | BB21: 26463 | BC21: 1 | BD21: 1115 | BE21: 0 | BF21: 4373 | BG21: 1 | BH21: 3636 | BI21: 0 | BJ21: 0 | BK21: 10 | BL21: 600590 | BM21: 30 | BN21: 693 | BO21: 0 | BP21: 778420 | BQ21: 10 | BR21: 6587 | BS21: 8 | BT21: 0 | BU21: 40 | BV21: 3 | BW21: 125 | BX21: 15594.96 | BZ21: 0 | CA21: 206460.5 | CB21: 0.4 | CC21: 2.284 | CD21: 40 | CE21: 4310 | CF21: 39 | CG21: 4202 | CH21: 41 | CI21: 4418 | CJ21: 12930 | CK21: 0 | CM21: 34492 | CN21: 1.2 | CO21: 2.928 | CP21: 34300 | CQ21: 0 | CR21: 0 | CS21: 10235.6 | CT21: 0 | CU21: 0 | CV21: 832145 | CW21: 0 | CX21: 0 | CY21: 5962 | CZ21: 1 | DA21: 2.39 | DB21: 7420 | DC21: 0 | DD21: 0 | DE21: 3840 | DF21: 0 | DG21: 0 | DH21: 1855.9 | DI21: 0 | DJ21: 0 | DK21: 5081.7 | DL21: 0 | DM21: 0 | DN21: 4454.7 | DO21: 0 | DP21: 0 | DQ21: 5089.6 | DR21: 0 | DS21: 0 | DT21: 4891 | DU21: 5 | DV21: 11.95 | DW21: 12871 | DX21: 0 | DY21: 62789 | DZ21: 0 | EA21: 15599 | EB21: 0 | EC21: 24679 | ED21: 0 | EE21: 2 | EF21: 6 | EG21: 0.015
A22: 44274 | B22: 6578500 | C22: 7492 | D22: 5822985 | E22: 7367 | F22: 0.98331554 | G22: 476 | H22: 478 | I22: 288023 | J22: 121 | K22: 774 | L22: 0 | M22: 633922 | N22: 132 | O22: 992 | P22: 1 | Q22: 2546970 | R22: 38 | S22: 2191616 | T22: 1 | U22: 108804 | V22: 31 | W22: 100 | X22: 152370 | Y22: 0 | Z22: 39544 | AA22: 3 | AB22: 1112 | AC22: 1 | AD22: 4549 | AE22: 0 | AF22: 579690 | AG22: 10 | AH22: 580050 | AI22: 0 | AJ22: 467 | AK22: 0 | AL22: 52225 | AM22: 0 | AN22: 8911 | AO22: 1 | AP22: 10571 | AQ22: 0 | AR22: 14551 | AS22: 0 | AT22: 19369 | AU22: 0 | AV22: 20677 | AW22: 0 | AX22: 13871 | AY22: 0 | AZ22: 6214 | BA22: 0 | BB22: 26463 | BC22: 0 | BD22: 1115 | BE22: 0 | BF22: 4373 | BG22: 0 | BH22: 3636 | BI22: 0 | BJ22: 0 | BK22: 0 | BL22: 600600 | BM22: 10 | BN22: 694 | BO22: 1 | BP22: 778440 | BQ22: 20 | BR22: 6589 | BS22: 2 | BT22: 20 | BU22: 30 | BV22: 1 | BW22: 125 | BX22: 15594.96 | BZ22: 0 | CA22: 206460.8 | CB22: 0.3 | CC22: 1.713 | CD22: 40 | CE22: 4310 | CF22: 39 | CG22: 4202 | CH22: 41 | CI22: 4418 | CJ22: 12930 | CK22: 0 | CM22: 34492.9 | CN22: 0.9 | CO22: 2.196 | CP22: 34300 | CQ22: 0 | CR22: 0 | CS22: 10235.6 | CT22: 0 | CU22: 0 | CV22: 832145 | CW22: 0 | CX22: 0 | CY22: 5962 | CZ22: 0 | DA22: 0 | DB22: 7420 | DC22: 0 | DD22: 0 | DE22: 3840 | DF22: 0 | DG22: 0 | DH22: 1855.9 | DI22: 0 | DJ22: 0 | DK22: 5081.7 | DL22: 0 | DM22: 0 | DN22: 4454.7 | DP22: 0 | DQ22: 5089.6 | DR22: 0 | DS22: 0 | DT22: 4893 | DU22: 2 | DV22: 4.78 | DW22: 12871 | DX22: 0 | DY22: 62789 | DZ22: 0 | EA22: 15599 | EB22: 0 | EC22: 24679 | ED22: 0 | EE22: 2 | EF22: 6 | EG22: 0.015
A23: 44275 | B23: 6586545 | C23: 8045 | D23: 5830642 | E23: 7657 | F23: 0.95177129 | G23: 476 | H23: 478 | I23: 288023 | J23: 0 | K23: 774 | L23: 0 | M23: 633922 | N23: 0 | O23: 992 | P23: 0 | Q23: 2547080 | R23: 110 | S23: 2191621 | T23: 5 | U23: 108850 | V23: 46 | W23: 100 | X23: 152370 | Y23: 0 | Z23: 39547 | AA23: 3 | AB23: 1112 | AC23: 0 | AD23: 4549 | AE23: 0 | AH23: 580050 | AI23: 0 | AJ23: 467 | AK23: 0 | AL23: 52225 | AM23: 0 | AN23: 8911 | AO23: 0 | AP23: 10571 | AQ23: 0 | AR23: 14552 | AS23: 1 | AT23: 19369 | AU23: 0 | AV23: 20677 | AW23: 0 | AX23: 13871 | AY23: 0 | AZ23: 6216 | BA23: 2 | BB23: 26464 | BC23: 1 | BD23: 1115 | BE23: 0 | BF23: 4373 | BG23: 0 | BH23: 3636 | BI23: 0 | BJ23: 1 | BK23: -1 | BL23: 600640 | BM23: 40 | BN23: 703 | BO23: 9 | BP23: 778440 | BQ23: 0 | BR23: 6596 | BS23: 7 | BT23: 0 | BU23: 40 | BV23: 3 | BW23: 125 | BX23: 15594.96 | BZ23: 0 | CA23: 206461.2 | CB23: 0.4 | CC23: 2.284 | CD23: 40 | CE23: 4310 | CF23: 39 | CG23: 4202 | CH23: 40 | CI23: 4310 | CJ23: 12822 | CK23: 108 | CM23: 34493.8 | CN23: 0.9 | CO23: 2.196 | CP23: 34300 | CQ23: 0 | CR23: 0 | CS23: 10235.6 | CT23: 0 | CU23: 0 | CV23: 832145 | CW23: 0 | CX23: 0 | CY23: 5963 | CZ23: 1 | DA23: 2.39 | DB23: 7420 | DC23: 0 | DD23: 0 | DE23: 3840 | DF23: 0 | DG23: 0 | DH23: 1855.9 | DI23: 0 | DJ23: 0 | DK23: 5081.7 | DL23: 0 | DM23: 0 | DN23: 4454.7 | DO23: 0 | DP23: 0 | DQ23: 5089.6 | DR23: 0 | DS23: 0 | DT23: 4897 | DU23: 4 | DV23: 9.56 | DW23: 12871 | DX23: 0 | DY23: 62789 | DZ23: 0 | EA23: 15599 | EB23: 0 | EC23: 24679 | ED23: 0 | EE23: 2 | EF23: 6 | EG23: 0.015
A24: 44276 | B24: 6594222 | C24: 7677 | D24: 5837916 | E24: 7274 | F24: 0.94750554 | G24: 476 | H24: 478 | I24: 288023 | J24: 0 | K24: 774 | L24: 0 | M24: 633922 | N24: 0 | O24: 992 | P24: 0 | Q24: 2547139 | R24: 59 | S24: 2191623 | T24: 2 | U24: 108904 | V24: 54 | W24: 100 | X24: 152370 | Y24: 0 | Z24: 39553 | AA24: 6 | AB24: 1112 | AC24: 0 | AD24: 4549 | AE24: 0 | AH24: 580080 | AI24: 30 | AJ24: 467 | AK24: 0 | AL24: 52225 | AM24: 0 | AN24: 8911 | AO24: 0 | AP24: 10571 | AQ24: 0 | AR24: 14552 | AS24: 0 | AT24: 19369 | AU24: 0 | AV24: 20677 | AW24: 0 | AX24: 13871 | AY24: 0 | AZ24: 6216 | BA24: 0 | BB24: 26464 | BC24: 0 | BD24: 1115 | BE24: 0 | BF24: 4373 | BG24: 0 | BH24: 3636 | BI24: 0 | BJ24: 0 | BK24: 30 | BL24: 600650 | BM24: 10 | BN24: 703 | BO24: 0 | BP24: 778480 | BQ24: 40 | BR24: 6599 | BS24: 3 | BT24: 10 | BU24: 50 | BV24: 0 | BW24: 125 | BX24: 15594.96 | BZ24: 0 | CA24: 206461.5 | CB24: 0.3 | CC24: 1.713 | CD24: 40 | CE24: 4310 | CF24: 39 | CG24: 4202 | CH24: 40 | CI24: 4310 | CJ24: 12822 | CK24: 0 | CM24: 34494.7 | CN24: 0.9 | CO24: 2.196 | CP24: 34300 | CQ24: 0 | CR24: 0 | CS24: 10235.6 | CT24: 0 | CU24: 0 | CV24: 832145 | CW24: 0 | CX24: 0 | CY24: 5964 | CZ24: 1 | DA24: 2.39 | DB24: 7420 | DC24: 0 | DD24: 0 | DE24: 3840 | DF24: 0 | DG24: 0 | DH24: 1855.9 | DI24: 0 | DJ24: 0 | DK24: 5081.7 | DL24: 0 | DM24: 0 | DN24: 4454.7 | DO24: 0 | DP24: 0 | DQ24: 5089.6 | DR24: 0 | DS24: 0 | DT24: 4904 | DU24: 7 | DV24: 16.73 | DW24: 12871 | DX24: 0 | DY24: 62789 | DZ24: 0 | EA24: 15599 | EB24: 0 | EC24: 24679 | ED24: 0 | EE24: 2 | EF24: 6 | EG24: 0.015
A25: 44277 | B25: 6601760 | C25: 7538 | D25: 5845005 | E25: 7089 | F25: 0.94043513 | G25: 528 | H25: 478 | I25: 288023 | J25: 0 | K25: 774 | L25: 0 | M25: 633922 | N25: 0 | O25: 992 | P25: 0 | Q25: 2547167 | R25: 28 | S25: 2191623 | T25: 0 | U25: 108936 | V25: 32 | W25: 100 | X25: 152370 | Y25: 0 | Z25: 39555 | AA25: 2 | AB25: 1112 | AC25: 0 | AD25: 4549 | AE25: 0 | AH25: 580080 | AI25: 0 | AJ25: 467 | AK25: 0 | AL25: 52226 | AM25: 1 | AN25: 8911 | AO25: 0 | AP25: 10571 | AQ25: 0 | AR25: 14552 | AS25: 0 | AT25: 19369 | AU25: 0 | AV25: 20677 | AW25: 0 | AX25: 13871 | AY25: 0 | AZ25: 6216 | BA25: 0 | BB25: 26464 | BC25: 0 | BD25: 1115 | BE25: 0 | BF25: 4373 | BG25: 0 | BH25: 3636 | BI25: 0 | BJ25: 0 | BK25: 0 | BL25: 600670 | BM25: 20 | BN25: 703 | BO25: 0 | BP25: 778490 | BQ25: 10 | BR25: 6602 | BS25: 3 | BT25: 10 | BU25: 30 | BV25: 1 | BW25: 125 | BX25: 15594.96 | BZ25: 0 | CA25: 206461.7 | CB25: 0.2 | CC25: 1.142 | CD25: 39 | CE25: 4202 | CF25: 39 | CG25: 4202 | CH25: 40 | CI25: 4310 | CJ25: 12715 | CK25: 108 | CM25: 34495.6 | CN25: 0.9 | CO25: 2.196 | CP25: 34300 | CQ25: 0 | CR25: 0 | CS25: 10235.6 | CT25: 0 | CU25: 0 | CV25: 832145 | CW25: 0 | CX25: 0 | CY25: 5964 | CZ25: 0 | DA25: 0 | DB25: 7420 | DC25: 0 | DD25: 0 | DE25: 3840 | DF25: 0 | DG25: 0 | DH25: 1855.9 | DI25: 0 | DJ25: 0 | DK25: 5081.7 | DL25: 0 | DM25: 0 | DN25: 4454.7 | DO25: 0 | DP25: 0 | DQ25: 5089.6 | DR25: 0 | DS25: 0 | DT25: 4906 | DU25: 2 | DV25: 4.78 | DW25: 12871 | DX25: 0 | DY25: 62789 | DZ25: 0 | EA25: 15599 | EB25: 0 | EC25: 24679 | ED25: 0 | EE25: 2 | EF25: 6 | EG25: 0.015
A26: 44278 | B26: 6608811 | C26: 7051 | D26: 5851892 | E26: 6887 | F26: 0.97674089 | G26: 528 | H26: 478 | I26: 288023 | J26: 0 | K26: 774 | L26: 0 | M26: 633922 | O26: 992 | P26: 0 | Q26: 2547277 | R26: 110 | S26: 2191625 | T26: 2 | U26: 108971 | V26: 35 | W26: 100 | X26: 152370 | Y26: 0 | Z26: 39559 | AA26: 4 | AB26: 1112 | AC26: 0 | AD26: 4549 | AE26: 0 | AH26: 580090 | AI26: 10 | AJ26: 467 | AK26: 0 | AL26: 52226 | AM26: 0 | AN26: 8911 | AO26: 0 | AP26: 10571 | AQ26: 0 | AR26: 14552 | AS26: 0 | AT26: 19369 | AU26: 0 | AV26: 20677 | AW26: 0 | AX26: 13871 | AY26: 0 | AZ26: 6217 | BA26: 1 | BB26: 26464 | BC26: 0 | BD26: 1115 | BE26: 0 | BF26: 4373 | BG26: 0 | BH26: 3636 | BI26: 0 | BJ26: 0 | BK26: 10 | BL26: 600690 | BM26: 20 | BN26: 706 | BO26: 3 | BP26: 778500 | BQ26: 10 | BR26: 6608 | BS26: 6 | BT26: 0 | BU26: 30 | BV26: 1 | BW26: 125 | BX26: 15594.96 | BZ26: 0 | CA26: 206462 | CB26: 0.3 | CC26: 1.713 | CD26: 39 | CE26: 4202 | CF26: 39 | CG26: 4202 | CH26: 40 | CI26: 4310 | CJ26: 12715 | CK26: 0 | CM26: 34496.6 | CN26: 1 | CO26: 2.44 | CP26: 34300 | CQ26: 0 | CR26: 0 | CS26: 10235.6 | CT26: 0 | CU26: 0 | CV26: 832145 | CW26: 0 | CX26: 0 | CY26: 5965 | CZ26: 1 | DA26: 2.39 | DB26: 7420 | DC26: 0 | DD26: 0 | DE26: 3840 | DF26: 0 | DG26: 0 | DH26: 1855.9 | DI26: 0 | DJ26: 0 | DK26: 5081.7 | DL26: 0 | DM26: 0 | DN26: 4454.7 | DO26: 0 | DP26: 0 | DQ26: 5089.6 | DR26: 0 | DS26: 0 | DT26: 4909 | DU26: 3 | DV26: 7.17 | DW26: 12871 | DX26: 0 | DY26: 62789 | DZ26: 0 | EA26: 15599 | EB26: 0 | EC26: 24679 | ED26: 0 | EE26: 2 | EF26: 6 | EG26: 0.015
A27: 44279 | B27: 6616216 | C27: 7405 | D27: 5858878 | E27: 6986 | F27: 0.94341661 | G27: 528 | H27: 478 | I27: 288023 | J27: 0 | K27: 774 | L27: 0 | M27: 633922 | N27: 0 | O27: 992 | P27: 0 | Q27: 2547339 | R27: 62 | S27: 2191629 | T27: 4 | U27: 109021 | V27: 50 | W27: 100 | X27: 152370 | Y27: 0 | Z27: 39564 | AA27: 5 | AB27: 1112 | AC27: 0 | AD27: 4575 | AE27: 26 | AH27: 580110 | AI27: 20 | AJ27: 467 | AK27: 0 | AL27: 52227 | AM27: 1 | AN27: 8911 | AO27: 0 | AP27: 10571 | AQ27: 0 | AR27: 14552 | AS27: 0 | AT27: 19369 | AU27: 0 | AV27: 20677 | AW27: 0 | AX27: 13871 | AY27: 0 | AZ27: 6217 | BA27: 0 | BB27: 26465 | BC27: 1 | BD27: 1115 | BE27: 0 | BF27: 4373 | BG27: 0 | BH27: 3636 | BI27: 0 | BJ27: 0 | BK27: 20 | BL27: 600720 | BM27: 30 | BN27: 706 | BO27: 0 | BP27: 778530 | BQ27: 30 | BR27: 6609 | BS27: 1 | BT27: 10 | BU27: 60 | BV27: 1 | BW27: 125 | BX27: 15594.96 | BZ27: 0 | CA27: 206462.2 | CB27: 0.2 | CC27: 1.142 | CD27: 39 | CE27: 4202 | CF27: 38 | CG27: 4095 | CH27: 40 | CI27: 4310 | CJ27: 12607 | CK27: 108 | CM27: 34497.4 | CN27: 0.8 | CO27: 1.952 | CP27: 34300 | CQ27: 0 | CR27: 0 | CS27: 10235.6 | CT27: 0 | CU27: 0 | CV27: 832145 | CW27: 0 | CX27: 0 | CY27: 5966 | CZ27: 1 | DA27: 2.39 | DB27: 7420 | DC27: 0 | DD27: 0 | DE27: 3840 | DF27: 0 | DG27: 40 | DH27: 1855.9 | DI27: 0 | DJ27: 0 | DK27: 5081.7 | DL27: 0 | DM27: 0 | DN27: 4454.7 | DO27: 0 | DP27: 0 | DQ27: 5089.6 | DR27: 0 | DS27: 0 | DT27: 4916 | DU27: 7 | DV27: 16.73 | DW27: 12871 | DX27: 0 | DY27: 62789 | DZ27: 0 | EA27: 15599 | EB27: 0 | EC27: 24679 | ED27: 0 | EE27: 3 | EF27: 7 | EG27: 0.023
A28: 44280 | B28: 6623580 | C28: 7364 | D28: 5866051 | E28: 7173 | F28: 0.97406301 | G28: 528 | H28: 478 | I28: 288023 | J28: 0 | K28: 774 | L28: 0 | M28: 633922 | N28: 0 | O28: 992 | P28: 0 | Q28: 2547368 | R28: 29 | S28: 2191630 | T28: 1 | U28: 109057 | V28: 36 | W28: 100 | X28: 152370 | Y28: 0 | Z28: 39567 | AA28: 3 | AB28: 1112 | AC28: 0 | AD28: 4575 | AE28: 0 | AH28: 580120 | AI28: 10 | AJ28: 467 | AK28: 0 | AL28: 52227 | AM28: 0 | AN28: 8911 | AO28: 0 | AP28: 10571 | AQ28: 0 | AR28: 14553 | AS28: 1 | AT28: 19369 | AU28: 0 | AV28: 20677 | AW28: 0 | AX28: 13871 | AY28: 0 | AZ28: 6217 | BA28: 0 | BB28: 26465 | BC28: 0 | BD28: 1115 | BE28: 0 | BF28: 4373 | BG28: 0 | BH28: 3636 | BI28: 0 | BJ28: 1 | BK28: 9 | BL28: 600730 | BM28: 10 | BN28: 706 | BO28: 0 | BP28: 778540 | BQ28: 10 | BR28: 6612 | BS28: 3 | BT28: 0 | BU28: 20 | BV28: 1 | BW28: 125 | BX28: 15594.96 | BZ28: 0 | CA28: 206462.4 | CB28: 0.2 | CC28: 1.142 | CD28: 39 | CE28: 4202 | CF28: 38 | CG28: 4095 | CH28: 40 | CI28: 4310 | CJ28: 12607 | CK28: 0 | CM28: 34498.4 | CN28: 1 | CO28: 2.44 | CP28: 34300 | CQ28: 0 | CR28: 0 | CS28: 10235.6 | CT28: 0 | CU28: 0 | CV28: 832145 | CW28: 0 | CX28: 0 | CY28: 5966 | CZ28: 0 | DA28: 0 | DB28: 7420 | DC28: 0 | DD28: 0 | DE28: 3840 | DF28: 0 | DG28: 0 | DH28: 1855.9 | DI28: 0 | DJ28: 0 | DK28: 5081.7 | DL28: 0 | DM28: 0 | DN28: 4454.7 | DO28: 0 | DP28: 0 | DQ28: 5089.6 | DR28: 0 | DS28: 0 | DT28: 4917.9 | DU28: 1.9 | DV28: 4.541 | DW28: 12871 | DX28: 0 | DY28: 62789 | DZ28: 0 | EA28: 15599 | EB28: 0 | EC28: 24679 | ED28: 0 | EE28: 3 | EF28: 7 | EG28: 0.023
A29: 44281 | B29: 6630196 | C29: 6616 | D29: 5872342 | E29: 6291 | F29: 0.95087666 | G29: 528 | H29: 478 | I29: 288023 | J29: 0 | K29: 774 | L29: 0 | M29: 633922 | N29: 0 | O29: 992 | P29: 0 | Q29: 2547461 | R29: 93 | S29: 2191634 | T29: 4 | U29: 109088 | V29: 31 | W29: 100 | X29: 152370 | Y29: 0 | Z29: 39569 | AA29: 2 | AB29: 1112 | AC29: 0 | AD29: 4575 | AE29: 0 | AH29: 580120 | AI29: 0 | AJ29: 467 | AK29: 0 | AL29: 52227 | AM29: 0 | AN29: 8911 | AO29: 0 | AP29: 10571 | AQ29: 0 | AR29: 14553 | AS29: 0 | AT29: 19369 | AU29: 0 | AV29: 20677 | AW29: 0 | AX29: 13871 | AY29: 0 | AZ29: 6217 | BA29: 0 | BB29: 26466 | BC29: 1 | BD29: 1115 | BE29: 0 | BF29: 4373 | BG29: 0 | BH29: 3636 | BI29: 0 | BJ29: 0 | BK29: 0 | BL29: 600740 | BM29: 10 | BN29: 706 | BO29: 0 | BP29: 778540 | BQ29: 0 | BR29: 6613 | BS29: 1 | BT29: 0 | BU29: 10 | BV29: 0 | BW29: 125 | BX29: 15594.96 | BZ29: 0 | CA29: 206462.7 | CB29: 0.3 | CC29: 1.713 | CD29: 39 | CE29: 4202 | CF29: 38 | CG29: 4095 | CH29: 40 | CI29: 4310 | CJ29: 12607 | CK29: 0 | CM29: 34499.5 | CN29: 1.1 | CO29: 2.684 | CP29: 34300 | CQ29: 0 | CR29: 0 | CS29: 10235.6 | CT29: 0 | CU29: 0 | CV29: 832145 | CW29: 0 | CX29: 0 | CY29: 5967 | CZ29: 1 | DA29: 2.39 | DB29: 7420 | DC29: 0 | DD29: 0 | DE29: 3840 | DF29: 0 | DG29: 0 | DH29: 1855.9 | DI29: 0 | DJ29: 0 | DK29: 5081.7 | DL29: 0 | DM29: 0 | DN29: 4454.7 | DO29: 0 | DP29: 0 | DQ29: 5089.6 | DR29: 0 | DS29: 0 | DT29: 4921.9 | DU29: 4 | DV29: 9.56 | DW29: 12871 | DX29: 0 | DY29: 62789 | DZ29: 0 | EA29: 15599 | EB29: 0 | EC29: 24679 | ED29: 0 | EE29: 3 | EF29: 7 | EG29: 0.023
A30: 44282 | B30: 6636624 | C30: 6428 | D30: 5878472 | E30: 6130 | F30: 0.95364032 | G30: 528 | H30: 478 | I30: 288023 | J30: 0 | K30: 774 | L30: 0 | M30: 633922 | N30: 0 | O30: 992 | P30: 0 | Q30: 2547523 | R30: 62 | S30: 2191636 | T30: 2 | U30: 109122 | V30: 34 | W30: 100 | X30: 152370 | Y30: 0 | Z30: 39569 | AA30: 0 | AB30: 1112 | AC30: 0 | AD30: 4575 | AE30: 0 | AH30: 580120 | AI30: 0 | AJ30: 467 | AK30: 0 | AL30: 52227 | AM30: 0 | AN30: 8911 | AO30: 0 | AP30: 10571 | AQ30: 0 | AR30: 14553 | AS30: 0 | AT30: 19369 | AU30: 0 | AV30: 20677 | AW30: 0 | AX30: 13871 | AY30: 0 | AZ30: 6217 | BA30: 0 | BB30: 26466 | BC30: 0 | BD30: 1115 | BE30: 0 | BF30: 4373 | BG30: 0 | BH30: 3636 | BI30: 0 | BJ30: 0 | BK30: 0 | BL30: 600770 | BM30: 30 | BN30: 707 | BO30: 1 | BP30: 778550 | BQ30: 10 | BR30: 6615 | BS30: 2 | BT30: 10 | BU30: 40 | BV30: 0 | BW30: 125 | BX30: 15594.96 | BZ30: 0 | CA30: 206463 | CB30: 0.3 | CC30: 1.713 | CD30: 39 | CE30: 4202 | CF30: 38 | CG30: 4095 | CH30: 40 | CI30: 4310 | CJ30: 12607 | CK30: 0 | CM30: 34499.8 | CN30: 0.3 | CO30: 0.732 | CP30: 34300 | CQ30: 0 | CR30: 0 | CS30: 10235.6 | CT30: 0 | CU30: 0 | CV30: 832145 | CW30: 0 | CX30: 0 | CY30: 5968 | CZ30: 1 | DA30: 2.39 | DB30: 7420 | DC30: 0 | DD30: 0 | DE30: 3840 | DF30: 0 | DG30: 0 | DH30: 1855.9 | DI30: 0 | DJ30: 0 | DK30: 5081.7 | DL30: 0 | DM30: 0 | DN30: 4454.7 | DO30: 0 | DP30: 0 | DQ30: 5089.6 | DS30: 0 | DT30: 4926 | DU30: 4.1 | DV30: 9.799 | DW30: 12871 | DX30: 0 | DY30: 62789 | DZ30: 0 | EA30: 15599 | EB30: 0 | EC30: 24679 | ED30: 0 | EE30: 3 | EF30: 7 | EG30: 0.023
A31: 44283 | B31: 6643059 | C31: 6435 | D31: 5884608 | E31: 6136 | F31: 0.95353535 | G31: 528 | H31: 478 | I31: 288023 | J31: 0 | K31: 774 | L31: 0 | M31: 633922 | N31: 0 | O31: 992 | P31: 0 | Q31: 2547550 | R31: 27 | S31: 2191637 | T31: 1 | U31: 109155 | V31: 33 | W31: 100 | X31: 152370 | Y31: 0 | Z31: 39574 | AA31: 5 | AB31: 1112 | AC31: 0 | AD31: 4575 | AE31: 0 | AH31: 580130 | AI31: 10 | AJ31: 467 | AK31: 0 | AL31: 52227 | AM31: 0 | AN31: 8911 | AO31: 0 | AP31: 10571 | AQ31: 0 | AR31: 14553 | AS31: 0 | AT31: 19369 | AU31: 0 | AV31: 20677 | AW31: 0 | AX31: 13871 | AY31: 0 | AZ31: 6217 | BA31: 0 | BB31: 26466 | BC31: 0 | BD31: 1115 | BE31: 0 | BF31: 4373 | BG31: 0 | BH31: 3636 | BI31: 0 | BJ31: 0 | BK31: 10 | BL31: 600780 | BM31: 10 | BN31: 708 | BO31: 1 | BP31: 778560 | BQ31: 10 | BR31: 6615 | BS31: 0 | BT31: 0 | BU31: 20 | BV31: 0 | BW31: 125 | BX31: 15594.96 | BZ31: 0 | CA31: 206463.2 | CB31: 0.2 | CC31: 1.142 | CD31: 39 | CE31: 4202 | CF31: 38 | CG31: 4095 | CH31: 40 | CI31: 4310 | CJ31: 12607 | CK31: 0 | CM31: 34500.3 | CN31: 0.5 | CO31: 1.22 | CP31: 34300 | CQ31: 0 | CR31: 0 | CS31: 10235.6 | CT31: 0 | CU31: 0 | CV31: 832145 | CW31: 0 | CX31: 0 | CY31: 5968 | CZ31: 0 | DA31: 0 | DB31: 7420 | DC31: 0 | DD31: 0 | DE31: 3840 | DF31: 0 | DG31: 0 | DH31: 1855.9 | DI31: 0 | DJ31: 0 | DK31: 5081.7 | DL31: 0 | DM31: 0 | DN31: 4454.7 | DO31: 0 | DP31: 0 | DQ31: 5089.6 | DR31: 0 | DS31: 0 | DT31: 4927.8 | DU31: 1.8 | DV31: 4.302 | DW31: 12871 | DX31: 0 | DY31: 62789 | DZ31: 0 | EA31: 15599 | EB31: 0 | EC31: 24679 | ED31: 0 | EE31: 3 | EF31: 7 | EG31: 0.023
A32: 44284 | B32: 6649667 | C32: 6608 | D32: 5890862 | E32: 6254 | F32: 0.94642857 | G32: 528 | H32: 478 | I32: 288023 | J32: 0 | K32: 774 | L32: 0 | M32: 633922 | N32: 0 | O32: 992 | P32: 0 | Q32: 2547632 | R32: 82 | S32: 2191640 | T32: 3 | U32: 109187 | V32: 32 | W32: 100 | X32: 152370 | Y32: 0 | Z32: 39576 | AA32: 2 | AB32: 1112 | AC32: 0 | AD32: 4575 | AE32: 0 | AH32: 580130 | AI32: 0 | AJ32: 467 | AK32: 0 | AL32: 52227 | AM32: 0 | AN32: 8912 | AO32: 1 | AP32: 10571 | AQ32: 0 | AR32: 14553 | AS32: 0 | AT32: 19369 | AV32: 20677 | AW32: 0 | AX32: 13871 | AY32: 0 | AZ32: 6217 | BA32: 0 | BB32: 26468 | BC32: 2 | BD32: 1115 | BE32: 0 | BF32: 4373 | BG32: 0 | BH32: 3636 | BI32: 0 | BJ32: 0 | BK32: 0 | BL32: 600800 | BM32: 20 | BN32: 708 | BO32: 0 | BP32: 778560 | BQ32: 0 | BR32: 6615 | BS32: 0 | BT32: 0 | BU32: 20 | BV32: 1 | BW32: 125 | BX32: 15594.96 | BZ32: 0 | CA32: 206463.5 | CB32: 0.3 | CC32: 1.713 | CD32: 39 | CE32: 4202 | CF32: 38 | CG32: 4095 | CH32: 40 | CI32: 4310 | CJ32: 12607 | CK32: 0 | CM32: 34501.4 | CN32: 1.1 | CO32: 2.684 | CP32: 34300 | CQ32: 0 | CR32: 0 | CS32: 10235.6 | CT32: 0 | CU32: 0 | CV32: 832145 | CW32: 0 | CX32: 0 | CY32: 5968 | CZ32: 0 | DA32: 0 | DB32: 7420 | DC32: 0 | DD32: 0 | DE32: 3840 | DF32: 0 | DG32: 0 | DH32: 1855.9 | DI32: 0 | DJ32: 0 | DK32: 5081.7 | DL32: 0 | DM32: 0 | DN32: 4454.7 | DO32: 0 | DP32: 0 | DQ32: 5089.6 | DR32: 0 | DS32: 0 | DT32: 4931.9 | DU32: 4.1 | DV32: 9.799 | DW32: 12871 | DX32: 30761.69 | DY32: 62789 | DZ32: 150065.71 | EA32: 15599 | EB32: 37281.61 | EC32: 24679 | ED32: 58982.81 | EE32: 3 | EF32: 7 | EG32: 0.023
