Workbook

Sheet TOTAL
A1: Site Name | B1: Day | C1: Month | D1: Year | E1: Total Electricity Kwh | F1: Electricity Tariff ($/Kwh) | G1: LPG (Kg) | H1: LPG $/Kg | I1: Water Utility Supply (m3) m3 | J1: Water Utility Supply (m3) $/m3 | K1: Room Nights | L1: Food Covers
A2: Maldives at Landaa Giraavaru | B2: 1 | C2: 4 | D2: 2021 | E2: ='Maldives at LG Daily'!D5 -> 32376 | F2: 0.93 | G2: ='Maldives at LG Daily'!F5 -> 315 | H2: 1.24 | I2: ='Maldives at LG Daily'!H5 -> 418 | J2: 1.72 | K2: ='Maldives at LG Daily'!I5 -> 83 | L2: ='Maldives at LG Daily'!J5 -> 730
A3: Maldives at Landaa Giraavaru | B3: =B2+1 -> 2 | C3: 4 | D3: 2021 | E3: ='Maldives at LG Daily'!D6 -> 32947 | F3: 0.93 | G3: ='Maldives at LG Daily'!F6 -> 0 | H3: 1.24 | I3: ='Maldives at LG Daily'!H6 -> 473 | J3: 1.72 | K3: ='Maldives at LG Daily'!I6 -> 78 | L3: ='Maldives at LG Daily'!J6 -> 666
A4: Maldives at Landaa Giraavaru | B4: =B3+1 -> 3 | C4: 4 | D4: 2021 | E4: ='Maldives at LG Daily'!D7 -> 32579 | F4: 0.93 | G4: ='Maldives at LG Daily'!F7 -> 0 | H4: 1.24 | I4: ='Maldives at LG Daily'!H7 -> 445 | J4: 1.72 | K4: ='Maldives at LG Daily'!I7 -> 78 | L4: ='Maldives at LG Daily'!J7 -> 702
A5: Maldives at Landaa Giraavaru | B5: =B4+1 -> 4 | C5: 4 | D5: 2021 | E5: ='Maldives at LG Daily'!D8 -> 32791 | F5: 0.93 | G5: ='Maldives at LG Daily'!F8 -> 90 | H5: 1.24 | I5: ='Maldives at LG Daily'!H8 -> 488 | J5: 1.72 | K5: ='Maldives at LG Daily'!I8 -> 72 | L5: ='Maldives at LG Daily'!J8 -> 666
A6: Maldives at Landaa Giraavaru | B6: =B5+1 -> 5 | C6: 4 | D6: 2021 | E6: ='Maldives at LG Daily'!D9 -> 33358 | F6: 0.93 | G6: ='Maldives at LG Daily'!F9 -> 0 | H6: 1.24 | I6: ='Maldives at LG Daily'!H9 -> 428 | J6: 1.72 | K6: ='Maldives at LG Daily'!I9 -> 73 | L6: ='Maldives at LG Daily'!J9 -> 684
A7: Maldives at Landaa Giraavaru | B7: =B6+1 -> 6 | C7: 4 | D7: 2021 | E7: ='Maldives at LG Daily'!D10 -> 31978 | F7: 0.93 | G7: ='Maldives at LG Daily'!F10 -> 0 | H7: 1.24 | I7: ='Maldives at LG Daily'!H10 -> 432 | J7: 1.72 | K7: ='Maldives at LG Daily'!I10 -> 73 | L7: ='Maldives at LG Daily'!J10 -> 671
A8: Maldives at Landaa Giraavaru | B8: =B7+1 -> 7 | C8: 4 | D8: 2021 | E8: ='Maldives at LG Daily'!D11 -> 32564 | F8: 0.93 | G8: ='Maldives at LG Daily'!F11 -> 45 | H8: 1.24 | I8: ='Maldives at LG Daily'!H11 -> 491 | J8: 1.72 | K8: ='Maldives at LG Daily'!I11 -> 71 | L8: ='Maldives at LG Daily'!J11 -> 651
A9: Maldives at Landaa Giraavaru | B9: =B8+1 -> 8 | C9: 4 | D9: 2021 | E9: ='Maldives at LG Daily'!D12 -> 32369 | F9: 0.93 | G9: ='Maldives at LG Daily'!F12 -> 45 | H9: 1.24 | I9: ='Maldives at LG Daily'!H12 -> 424 | J9: 1.72 | K9: ='Maldives at LG Daily'!I12 -> 65 | L9: ='Maldives at LG Daily'!J12 -> 637
A10: Maldives at Landaa Giraavaru | B10: =B9+1 -> 9 | C10: 4 | D10: 2021 | E10: ='Maldives at LG Daily'!D13 -> 31375 | F10: 0.93 | G10: ='Maldives at LG Daily'!F13 -> 0 | H10: 1.24 | I10: ='Maldives at LG Daily'!H13 -> 432 | J10: 1.72 | K10: ='Maldives at LG Daily'!I13 -> 57 | L10: ='Maldives at LG Daily'!J13 -> 530
A11: Maldives at Landaa Giraavaru | B11: =B10+1 -> 10 | C11: 4 | D11: 2021 | E11: ='Maldives at LG Daily'!D14 -> 30622 | F11: 0.93 | G11: ='Maldives at LG Daily'!F14 -> 0 | H11: 1.24 | I11: ='Maldives at LG Daily'!H14 -> 403 | J11: 1.72 | K11: ='Maldives at LG Daily'!I14 -> 56 | L11: ='Maldives at LG Daily'!J14 -> 484
A12: Maldives at Landaa Giraavaru | B12: =B11+1 -> 11 | C12: 4 | D12: 2021 | E12: ='Maldives at LG Daily'!D15 -> 31458 | F12: 0.93 | G12: ='Maldives at LG Daily'!F15 -> 90 | H12: 1.24 | I12: ='Maldives at LG Daily'!H15 -> 425 | J12: 1.72 | K12: ='Maldives at LG Daily'!I15 -> 48 | L12: ='Maldives at LG Daily'!J15 -> 437
A13: Maldives at Landaa Giraavaru | B13: =B12+1 -> 12 | C13: 4 | D13: 2021 | E13: ='Maldives at LG Daily'!D16 -> 0 | F13: 0.93 | G13: ='Maldives at LG Daily'!F16 -> 0 | H13: 1.24 | I13: ='Maldives at LG Daily'!H16 -> 341 | J13: 1.72 | K13: ='Maldives at LG Daily'!I16 -> 0 | L13: ='Maldives at LG Daily'!J16 -> 0
A14: Maldives at Landaa Giraavaru | B14: =B13+1 -> 13 | C14: 4 | D14: 2021 | E14: ='Maldives at LG Daily'!D17 -> 0 | F14: 0.93 | G14: ='Maldives at LG Daily'!F17 -> 0 | H14: 1.24 | I14: ='Maldives at LG Daily'!H17 -> 0 | J14: 1.72 | K14: ='Maldives at LG Daily'!I17 -> 0 | L14: ='Maldives at LG Daily'!J17 -> 0
... A31: Maldives at Landaa Giraavaru | B31: =B30+1 -> 30 | C31: 4 | D31: 2021 | E31: ='Maldives at LG Daily'!D34 -> 0 | F31: 0.93 | G31: ='Maldives at LG Daily'!F34 -> 0 | H31: 3.24 | I31: ='Maldives at LG Daily'!H34 -> 0 | J31: 3.72 | K31: ='Maldives at LG Daily'!I34 -> 0 | L31: ='Maldives at LG Daily'!J34 -> 0

Sheet Maldives at LG Daily
A2: Days | C2: Electricity Meter (KWh) | E2: Gas Kg | G2: Water m3
A3: Date | C3: Reading KWH | D3: Difference KWH | E3: Reading Kg | F3: Difference Kg | G3: Reading m³ | H3: Daily Consumption m³ | I3: ROOM NIGHTS | J3: TOTAL GUESTS
A4: 44286 | C4: =SUM('GENSET #1'!B10+'GENSET #2'!B10+'GENSET #3'!B10+'GENSET #4'!B10+'GENSET #5'!B10) -> 88667657 | D4: 30577 | E4: ='Gas-2'!G5 -> 0 | F4: 90 | G4: =SUM(WATER!G6,WATER!L6,WATER!Q6,WATER!B6) -> 934830 | H4: 423 | I4: 81 | J4: 598
A5: =A4+1 -> 44287 | C5: =SUM('GENSET #1'!B11+'GENSET #2'!B11+'GENSET #3'!B11+'GENSET #4'!B11+'GENSET #5'!B11) -> 88700033 | D5: =IF((C5-C4<0), "0",C5-C4) -> 32376 | E5: ='Gas-2'!G6 -> 315 | F5: =IF((E5-E4<0), "0",E5-E4) -> 315 | G5: =SUM(WATER!C6,WATER!H6,WATER!M6,WATER!R6) -> 935255 | H5: 418 | I5: 83 | J5: 730
A6: =A5+1 -> 44288 | C6: =SUM('GENSET #1'!B12+'GENSET #2'!B12+'GENSET #3'!B12+'GENSET #4'!B12+'GENSET #5'!B12) -> 88732980 | D6: =IF((C6-C5<0), "0",C6-C5) -> 32947 | E6: ='Gas-2'!G7 -> 315 | F6: =IF((E6-E5<0), "0",E6-E5) -> 0 | G6: =SUM(WATER!C7,WATER!H7,WATER!M7,WATER!R7) -> 935728 | H6: =IF((G6-G5<0), "0",G6-G5) -> 473 | I6: 78 | J6: 666
A7: =A6+1 -> 44289 | C7: =SUM('GENSET #1'!B13+'GENSET #2'!B13+'GENSET #3'!B13+'GENSET #4'!B13+'GENSET #5'!B13) -> 88765559 | D7: =IF((C7-C6<0), "0",C7-C6) -> 32579 | E7: ='Gas-2'!G8 -> 225 | F7: =IF((E7-E6<0), "0",E7-E6) -> 0 | G7: =SUM(WATER!C8,WATER!H8,WATER!M8,WATER!R8) -> 936173 | H7: =IF((G7-G6<0), "0",G7-G6) -> 445 | I7: 78 | J7: 702
A8: =A7+1 -> 44290 | C8: =SUM('GENSET #1'!B14+'GENSET #2'!B14+'GENSET #3'!B14+'GENSET #4'!B14+'GENSET #5'!B14) -> 88798350 | D8: =IF((C8-C7<0), "0",C8-C7) -> 32791 | E8: ='Gas-2'!G9 -> 315 | F8: =IF((E8-E7<0), "0",E8-E7) -> 90 | G8: =SUM(WATER!C9,WATER!H9,WATER!M9,WATER!R9) -> 936661 | H8: =IF((G8-G7<0), "0",G8-G7) -> 488 | I8: 72 | J8: 666
A9: =A8+1 -> 44291 | C9: =SUM('GENSET #1'!B15+'GENSET #2'!B15+'GENSET #3'!B15+'GENSET #4'!B15+'GENSET #5'!B15) -> 88831708 | D9: =IF((C9-C8<0), "0",C9-C8) -> 33358 | E9: ='Gas-2'!G10 -> 270 | F9: =IF((E9-E8<0), "0",E9-E8) -> 0 | G9: =SUM(WATER!C10,WATER!H10,WATER!M10,WATER!R10) -> 937089 | H9: =IF((G9-G8<0), "0",G9-G8) -> 428 | I9: 73 | J9: 684
A10: =A9+1 -> 44292 | C10: =SUM('GENSET #1'!B16+'GENSET #2'!B16+'GENSET #3'!B16+'GENSET #4'!B16+'GENSET #5'!B16) -> 88863686 | D10: =IF((C10-C9<0), "0",C10-C9) -> 31978 | E10: ='Gas-2'!G11 -> 270 | F10: =IF((E10-E9<0), "0",E10-E9) -> 0 | G10: =SUM(WATER!C11,WATER!H11,WATER!M11,WATER!R11) -> 937521 | H10: =IF((G10-G9<0), "0",G10-G9) -> 432 | I10: 73 | J10: 671
A11: =A10+1 -> 44293 | C11: =SUM('GENSET #1'!B17+'GENSET #2'!B17+'GENSET #3'!B17+'GENSET #4'!B17+'GENSET #5'!B17) -> 88896250 | D11: =IF((C11-C10<0), "0",C11-C10) -> 32564 | E11: ='Gas-2'!G12 -> 315 | F11: =IF((E11-E10<0), "0",E11-E10) -> 45 | G11: =SUM(WATER!C12,WATER!H12,WATER!M12,WATER!R12) -> 938012 | H11: =IF((G11-G10<0), "0",G11-G10) -> 491 | I11: 71 | J11: 651
A12: =A11+1 -> 44294 | C12: =SUM('GENSET #1'!B18+'GENSET #2'!B18+'GENSET #3'!B18+'GENSET #4'!B18+'GENSET #5'!B18) -> 88928619 | D12: =IF((C12-C11<0), "0",C12-C11) -> 32369 | E12: ='Gas-2'!G13 -> 360 | F12: =IF((E12-E11<0), "0",E12-E11) -> 45 | G12: =SUM(WATER!C13,WATER!H13,WATER!M13,WATER!R13) -> 938436 | H12: =IF((G12-G11<0), "0",G12-G11) -> 424 | I12: 65 | J12: 637
A13: =A12+1 -> 44295 | C13: =SUM('GENSET #1'!B19+'GENSET #2'!B19+'GENSET #3'!B19+'GENSET #4'!B19+'GENSET #5'!B19) -> 88959994 | D13: =IF((C13-C12<0), "0",C13-C12) -> 31375 | E13: ='Gas-2'!G14 -> 270 | F13: =IF((E13-E12<0), "0",E13-E12) -> 0 | G13: =SUM(WATER!C14,WATER!H14,WATER!M14,WATER!R14) -> 938868 | H13: =IF((G13-G12<0), "0",G13-G12) -> 432 | I13: 57 | J13: 530
A14: =A13+1 -> 44296 | C14: =SUM('GENSET #1'!B20+'GENSET #2'!B20+'GENSET #3'!B20+'GENSET #4'!B20+'GENSET #5'!B20) -> 88990616 | D14: =IF((C14-C13<0), "0",C14-C13) -> 30622 | E14: ='Gas-2'!G15 -> 135 | F14: =IF((E14-E13<0), "0",E14-E13) -> 0 | G14: =SUM(WATER!C15,WATER!H15,WATER!M15,WATER!R15) -> 939271 | H14: =IF((G14-G13<0), "0",G14-G13) -> 403 | I14: 56 | J14: 484
A15: =A14+1 -> 44297 | C15: =SUM('GENSET #1'!B21+'GENSET #2'!B21+'GENSET #3'!B21+'GENSET #4'!B21+'GENSET #5'!B21) -> 89022074 | D15: =IF((C15-C14<0), "0",C15-C14) -> 31458 | E15: ='Gas-2'!G16 -> 225 | F15: =IF((E15-E14<0), "0",E15-E14) -> 90 | G15: =SUM(WATER!C16,WATER!H16,WATER!M16,WATER!R16) -> 939696 | H15: =IF((G15-G14<0), "0",G15-G14) -> 425 | I15: 48 | J15: 437
A16: =A15+1 -> 44298 | C16: =SUM('GENSET #1'!B22+'GENSET #2'!B22+'GENSET #3'!B22+'GENSET #4'!B22+'GENSET #5'!B22) -> 17082256 | D16: =IF((C16-C15<0), "0",C16-C15) -> 0 | E16: ='Gas-2'!G17 -> 0 | F16: =IF((E16-E15<0), "0",E16-E15) -> 0 | G16: =SUM(WATER!C17,WATER!H17,WATER!M17,WATER!R17) -> 940037 | H16: =IF((G16-G15<0), "0",G16-G15) -> 341
A17: =A16+1 -> 44299 | C17: =SUM('GENSET #1'!B23+'GENSET #2'!B23+'GENSET #3'!B23+'GENSET #4'!B23+'GENSET #5'!B23) -> 0 | D17: =IF((C17-C16<0), "0",C17-C16) -> 0 | E17: ='Gas-2'!G18 -> 0 | F17: =IF((E17-E16<0), "0",E17-E16) -> 0 | G17: =SUM(WATER!C18,WATER!H18,WATER!M18,WATER!R18) -> 0 | H17: =IF((G17-G16<0), "0",G17-G16) -> 0
A18: =A17+1 -> 44300 | C18: =SUM('GENSET #1'!B24+'GENSET #2'!B24+'GENSET #3'!B24+'GENSET #4'!B24+'GENSET #5'!B24) -> 0 | D18: =IF((C18-C17<0), "0",C18-C17) -> 0 | E18: ='Gas-2'!G19 -> 0 | F18: =IF((E18-E17<0), "0",E18-E17) -> 0 | G18: =SUM(WATER!C19,WATER!H19,WATER!M19,WATER!R19) -> 0 | H18: =IF((G18-G17<0), "0",G18-G17) -> 0
A19: =A18+1 -> 44301 | C19: =SUM('GENSET #1'!B25+'GENSET #2'!B25+'GENSET #3'!B25+'GENSET #4'!B25+'GENSET #5'!B25) -> 0 | D19: =IF((C19-C18<0), "0",C19-C18) -> 0 | E19: ='Gas-2'!G20 -> 0 | F19: =IF((E19-E18<0), "0",E19-E18) -> 0 | G19: =SUM(WATER!C20,WATER!H20,WATER!M20,WATER!R20) -> 0 | H19: =IF((G19-G18<0), "0",G19-G18) -> 0
A20: =A19+1 -> 44302 | C20: =SUM('GENSET #1'!B26+'GENSET #2'!B26+'GENSET #3'!B26+'GENSET #4'!B26+'GENSET #5'!B26) -> 0 | D20: =IF((C20-C19<0), "0",C20-C19) -> 0 | E20: ='Gas-2'!G21 -> 0 | F20: =IF((E20-E19<0), "0",E20-E19) -> 0 | G20: =SUM(WATER!C21,WATER!H21,WATER!M21,WATER!R21) -> 0 | H20: =IF((G20-G19<0), "0",G20-G19) -> 0
A21: =A20+1 -> 44303 | C21: =SUM('GENSET #1'!B27+'GENSET #2'!B27+'GENSET #3'!B27+'GENSET #4'!B27+'GENSET #5'!B27) -> 0 | D21: =IF((C21-C20<0), "0",C21-C20) -> 0 | E21: ='Gas-2'!G22 -> 0 | F21: =IF((E21-E20<0), "0",E21-E20) -> 0 | G21: =SUM(WATER!C22,WATER!H22,WATER!M22,WATER!R22) -> 0 | H21: =IF((G21-G20<0), "0",G21-G20) -> 0
A22: =A21+1 -> 44304 | C22: =SUM('GENSET #1'!B28+'GENSET #2'!B28+'GENSET #3'!B28+'GENSET #4'!B28+'GENSET #5'!B28) -> 0 | D22: =IF((C22-C21<0), "0",C22-C21) -> 0 | E22: ='Gas-2'!G23 -> 0 | F22: =IF((E22-E21<0), "0",E22-E21) -> 0 | G22: =SUM(WATER!C23,WATER!H23,WATER!M23,WATER!R23) -> 0 | H22: =IF((G22-G21<0), "0",G22-G21) -> 0
A23: =A22+1 -> 44305 | C23: =SUM('GENSET #1'!B29+'GENSET #2'!B29+'GENSET #3'!B29+'GENSET #4'!B29+'GENSET #5'!B29) -> 0 | D23: =IF((C23-C22<0), "0",C23-C22) -> 0 | E23: ='Gas-2'!G24 -> 0 | F23: =IF((E23-E22<0), "0",E23-E22) -> 0 | G23: =SUM(WATER!C24,WATER!H24,WATER!M24,WATER!R24) -> 0 | H23: =IF((G23-G22<0), "0",G23-G22) -> 0
A24: =A23+1 -> 44306 | C24: =SUM('GENSET #1'!B30+'GENSET #2'!B30+'GENSET #3'!B30+'GENSET #4'!B30+'GENSET #5'!B30) -> 0 | D24: =IF((C24-C23<0), "0",C24-C23) -> 0 | E24: ='Gas-2'!G25 -> 0 | F24: =IF((E24-E23<0), "0",E24-E23) -> 0 | G24: =SUM(WATER!C25,WATER!H25,WATER!M25,WATER!R25) -> 0 | H24: =IF((G24-G23<0), "0",G24-G23) -> 0
A25: =A24+1 -> 44307 | C25: =SUM('GENSET #1'!B31+'GENSET #2'!B31+'GENSET #3'!B31+'GENSET #4'!B31+'GENSET #5'!B31) -> 0 | D25: =IF((C25-C24<0), "0",C25-C24) -> 0 | E25: ='Gas-2'!G26 -> 0 | F25: =IF((E25-E24<0), "0",E25-E24) -> 0 | G25: =SUM(WATER!C26,WATER!H26,WATER!M26,WATER!R26) -> 0 | H25: =IF((G25-G24<0), "0",G25-G24) -> 0
A26: =A25+1 -> 44308 | C26: =SUM('GENSET #1'!B32+'GENSET #2'!B32+'GENSET #3'!B32+'GENSET #4'!B32+'GENSET #5'!B32) -> 0 | D26: =IF((C26-C25<0), "0",C26-C25) -> 0 | E26: ='Gas-2'!G27 -> 0 | F26: =IF((E26-E25<0), "0",E26-E25) -> 0 | G26: =SUM(WATER!C27,WATER!H27,WATER!M27,WATER!R27) -> 0 | H26: =IF((G26-G25<0), "0",G26-G25) -> 0
A27: =A26+1 -> 44309 | C27: =SUM('GENSET #1'!B33+'GENSET #2'!B33+'GENSET #3'!B33+'GENSET #4'!B33+'GENSET #5'!B33) -> 0 | D27: =IF((C27-C26<0), "0",C27-C26) -> 0 | E27: ='Gas-2'!G28 -> 0 | F27: =IF((E27-E26<0), "0",E27-E26) -> 0 | G27: =SUM(WATER!C28,WATER!H28,WATER!M28,WATER!R28) -> 0 | H27: =IF((G27-G26<0), "0",G27-G26) -> 0
... A35: =A34+1 -> 44317 | C35: =SUM('GENSET #1'!B41+'GENSET #2'!B41+'GENSET #3'!B41+'GENSET #4'!B41+'GENSET #5'!B41) -> 0 | D35: =IF((C35-C34<0), "0",C35-C34) -> 0 | E35: ='Gas-2'!G36 -> 0 | F35: =IF((E35-E34<0), "0",E35-E34) -> 0 | G35: =SUM(WATER!C36,WATER!H36,WATER!M36,WATER!R36) -> 0 | H35: =IF((G35-G34<0), "0",G35-G34) -> 0

Sheet Finance Only
A1: Four Seasons Landaa Giraavaru
A3: Property | B3: MLG
A4: Month | B4: April
A5: Year | B5: 2021
A7: DAY | B7: Electricity Consumption ( kwh) | C7: Diesel Consumption (Liters) | D7: Solar Power Consumption(kwh) | E7: Gas Consumption (kg) | F7: Water Consumption ( m3) | G7: Occupancy | H7: Weather
A8: 1 | B8: =SUM('GENSET #1:GENSET #5'!D10) -> 32376 | C8: ='Diesel consumption'!D5 -> 8870 | D8: ='SOLAR METER READING'!D9 -> 2792 | E8: ='Gas-2'!G6 -> 315 | F8: =WATER!V6 -> 351 | G8: =WATER!W6 -> 83 | H8: ='SOLAR METER READING'!E9 -> partly sunny
A9: 2 | B9: =SUM('GENSET #1:GENSET #5'!D11) -> 32947 | C9: ='Diesel consumption'!D6 -> 9130 | D9: ='SOLAR METER READING'!D10 -> 2408 | E9: ='Gas-2'!G7 -> 315 | F9: =WATER!V7 -> 473 | G9: =WATER!W7 -> 78 | H9: ='SOLAR METER READING'!E10 -> partly sunny
A10: 3 | B10: =SUM('GENSET #1:GENSET #5'!D12) -> 32579 | C10: ='Diesel consumption'!D7 -> 9000 | D10: ='SOLAR METER READING'!D11 -> 3130 | E10: ='Gas-2'!G8 -> 225 | F10: =WATER!V8 -> 445 | G10: =WATER!W8 -> 78 | H10: ='SOLAR METER READING'!E11 -> very sunny
A11: 4 | B11: =SUM('GENSET #1:GENSET #5'!D13) -> 32791 | C11: ='Diesel consumption'!D8 -> 9050 | D11: ='SOLAR METER READING'!D12 -> 3122 | E11: ='Gas-2'!G9 -> 315 | F11: =WATER!V9 -> 488 | G11: =WATER!W9 -> 72 | H11: ='SOLAR METER READING'!E12 -> very sunny
A12: 5 | B12: =SUM('GENSET #1:GENSET #5'!D14) -> 33358 | C12: ='Diesel consumption'!D9 -> 9000 | D12: ='SOLAR METER READING'!D13 -> 3091 | E12: ='Gas-2'!G10 -> 270 | F12: =WATER!V10 -> 428 | G12: =WATER!W10 -> 73 | H12: ='SOLAR METER READING'!E13 -> very sunny
A13: 6 | B13: =SUM('GENSET #1:GENSET #5'!D15) -> 31978 | C13: ='Diesel consumption'!D10 -> 8860 | D13: ='SOLAR METER READING'!D14 -> 3161 | E13: ='Gas-2'!G11 -> 270 | F13: =WATER!V11 -> 432 | G13: =WATER!W11 -> 73 | H13: ='SOLAR METER READING'!E14 -> very sunny
A14: 7 | B14: =SUM('GENSET #1:GENSET #5'!D16) -> 32564 | C14: ='Diesel consumption'!D11 -> 8940 | D14: ='SOLAR METER READING'!D15 -> 3104 | E14: ='Gas-2'!G12 -> 315 | F14: =WATER!V12 -> 491 | G14: =WATER!W12 -> 71 | H14: ='SOLAR METER READING'!E15 -> very sunny
A15: 8 | B15: =SUM('GENSET #1:GENSET #5'!D17) -> 32369 | C15: ='Diesel consumption'!D12 -> 8950 | D15: ='SOLAR METER READING'!D16 -> 3188 | E15: ='Gas-2'!G13 -> 360 | F15: =WATER!V13 -> 424 | G15: =WATER!W13 -> 65 | H15: ='SOLAR METER READING'!E16 -> very sunny
A16: 9 | B16: =SUM('GENSET #1:GENSET #5'!D18) -> 31375 | C16: ='Diesel consumption'!D13 -> 8700 | D16: ='SOLAR METER READING'!D17 -> 2863 | E16: ='Gas-2'!G14 -> 270 | F16: =WATER!V14 -> 432 | G16: =WATER!W14 -> 57 | H16: ='SOLAR METER READING'!E17 -> very sunny
A17: 10 | B17: =SUM('GENSET #1:GENSET #5'!D19) -> 30622 | C17: ='Diesel consumption'!D14 -> 8350 | D17: ='SOLAR METER READING'!D18 -> 3286 | E17: ='Gas-2'!G15 -> 135 | F17: =WATER!V15 -> 403 | G17: =WATER!W15 -> 56 | H17: ='SOLAR METER READING'!E18 -> very sunny
A18: 11 | B18: =SUM('GENSET #1:GENSET #5'!D20) -> 31458 | C18: ='Diesel consumption'!D15 -> 8630 | D18: ='SOLAR METER READING'!D19 -> 3341 | E18: ='Gas-2'!G16 -> 225 | F18: =WATER!V16 -> 425 | G18: =WATER!W16 -> 48 | H18: ='SOLAR METER READING'!E19 -> very sunny
A19: 12 | B19: =SUM('GENSET #1:GENSET #5'!D21) -> -71939818 | C19: ='Diesel consumption'!D16 -> -43695650 | D19: ='SOLAR METER READING'!D20 -> -2536509 | E19: ='Gas-2'!G17 -> 0 | F19: =WATER!V17 -> 341 | G19: =WATER!W17 -> 0 | H19: ='SOLAR METER READING'!E20 -> 0
... A38: 31 | B38: =SUM('GENSET #1:GENSET #5'!D40) -> 0 | C38: ='Diesel consumption'!D35 -> 0 | D38: ='SOLAR METER READING'!D39 -> 0 | E38: ='Gas-2'!G36 -> 0 | F38: =WATER!V36 -> 0 | G38: =WATER!W36 -> 0 | H38: ='SOLAR METER READING'!E39 -> 0
A39: Total | B39: =SUM(B8:B38) -> -88667657 | C39: =SUM(C8:C38) -> -43598170 | D39: =SUM(D8:D38) -> -2503023 | E39: =SUM(E8:E38) -> 3015 | F39: =SUM(F8:F38) -> -934904 | G39: =SUM(G8:G38)/31 -> 24.322581
B40: =B39/31 -> -2860247 | C40: =C39/31 -> -1406392.6 | D40: =D39/31 -> -80742.677 | E40: =E39/31 -> 97.258065 | F40: =F39/31 -> -30158.194

Sheet GENSET #1
C1: 1000 KVA
C3: NO#1
A6: 44287
B8: GENSET NO 1
A9: DAY | B9: YESTARDAY | C9: TODAY | D9: Final Electricity Consumption( KWh)
A10: 1 | B10: 17082256 | C10: 17082256 | D10: =C10-B10 -> 0
A11: 2 | B11: =C10 -> 17082256 | C11: 17082256 | D11: =C11-B11 -> 0
A12: 3 | B12: =C11 -> 17082256 | C12: 17082256 | D12: =C12-B12 -> 0
A13: 4 | B13: =C12 -> 17082256 | C13: 17082256 | D13: =C13-B13 -> 0
A14: 5 | B14: =C13 -> 17082256 | C14: 17082256 | D14: =C14-B14 -> 0
A15: 6 | B15: =C14 -> 17082256 | C15: 17082256 | D15: =C15-B15 -> 0
A16: 7 | B16: =C15 -> 17082256 | C16: 17082256 | D16: =C16-B16 -> 0
A17: 8 | B17: =C16 -> 17082256 | C17: 17082256 | D17: =C17-B17 -> 0
A18: 9 | B18: =C17 -> 17082256 | C18: 17082256 | D18: =C18-B18 -> 0
A19: 10 | B19: =C18 -> 17082256 | C19: 17082256 | D19: =C19-B19 -> 0
A20: 11 | B20: =C19 -> 17082256 | C20: 17082256 | D20: =C20-B20 -> 0
A21: 12 | B21: =C20 -> 17082256 | C21: 17082256 | D21: =C21-B21 -> 0
A22: 13 | B22: =C21 -> 17082256 | D22: =C22-B22 -> -17082256
A23: 14 | B23: =C22 -> 0 | D23: =C23-B23 -> 0
A24: 15 | B24: =C23 -> 0 | D24: =C24-B24 -> 0
A25: 16 | B25: =C24 -> 0 | D25: =C25-B25 -> 0
A26: 17 | B26: =C25 -> 0 | D26: =C26-B26 -> 0
A27: 18 | B27: =C26 -> 0 | D27: =C27-B27 -> 0
A28: 19 | B28: =C27 -> 0 | D28: =C28-B28 -> 0
A29: 20 | B29: =C28 -> 0 | D29: =C29-B29 -> 0
A30: 21 | B30: =C29 -> 0 | D30: =C30-B30 -> 0
A31: 22 | B31: =C30 -> 0 | D31: =C31-B31 -> 0
A32: 23 | B32: =C31 -> 0 | D32: =C32-B32 -> 0
A33: 24 | B33: =C32 -> 0 | D33: =C33-B33 -> 0
... A38: 29 | B38: =C37 -> 0 | D38: =C38-B38 -> 0
A39: 30 | B39: =C38 -> 0 | D39: =C39-B39 -> 0 | G39: NEW ENGINE PURCHASED FROM UK
A40: 31 | B40: =C39 -> 0 | D40: =C40-B40 -> 0
A41: Total | B41: =C40 -> 0 | D41: =SUM(D10:D40) -> -17082256 | G41: INSTALLED: NOV 30 2013

Sheet GENSET #2
C1: 1600 KVA
C3: NO#2
A6: 44287
B8: GENSET NO 2
A9: DAY | B9: YESTARDAY | C9: TODAY | D9: Final Electricity Consumption( KW h)
A10: 1 | B10: 29276496 | C10: 29291540 | D10: =C10-B10 -> 15044
A11: 2 | B11: =C10 -> 29291540 | C11: 29307246 | D11: =C11-B11 -> 15706
A12: 3 | B12: =C11 -> 29307246 | C12: 29320763 | D12: =C12-B12 -> 13517
A13: 4 | B13: =C12 -> 29320763 | C13: 29334489 | D13: =C13-B13 -> 13726
A14: 5 | B14: =C13 -> 29334489 | C14: 29348389 | D14: =C14-B14 -> 13900
A15: 6 | B15: =C14 -> 29348389 | C15: 29364112 | D15: =C15-B15 -> 15723
A16: 7 | B16: =C15 -> 29364112 | C16: 29379742 | D16: =C16-B16 -> 15630
A17: 8 | B17: =C16 -> 29379742 | C17: 29394695 | D17: =C17-B17 -> 14953
A18: 9 | B18: =C17 -> 29394695 | C18: 29410588 | D18: =C18-B18 -> 15893
A19: 10 | B19: =C18 -> 29410588 | C19: 29425372 | D19: =C19-B19 -> 14784
A20: 11 | B20: =C19 -> 29425372 | C20: 29439352 | D20: =C20-B20 -> 13980
A21: 12 | B21: =C20 -> 29439352 | D21: =C21-B21 -> -29439352
A22: 13 | B22: =C21 -> 0 | D22: =C22-B22 -> 0
A23: 14 | B23: =C22 -> 0 | D23: =C23-B23 -> 0
A24: 15 | B24: =C23 -> 0 | D24: =C24-B24 -> 0
A25: 16 | B25: =C24 -> 0 | D25: =C25-B25 -> 0
A26: 17 | B26: =C25 -> 0 | D26: =C26-B26 -> 0
A27: 18 | B27: =C26 -> 0 | D27: =C27-B27 -> 0
A28: 19 | B28: =C27 -> 0 | D28: =C28-B28 -> 0
A29: 20 | B29: =C28 -> 0 | D29: =C29-B29 -> 0
A30: 21 | B30: =C29 -> 0 | D30: =C30-B30 -> 0
A31: 22 | B31: =C30 -> 0 | D31: =C31-B31 -> 0
A32: 23 | B32: =C31 -> 0 | D32: =C32-B32 -> 0
... A40: 31 | B40: =C39 -> 0 | D40: =C40-B40 -> 0
A41: Total | B41: =C40 -> 0 | D41: =SUM(D10:D40) -> -29276496

Sheet GENSET #3
C1: 900 KVA
C3: NO#3
A6: 44287
B8: GENSET NO 3
A9: DAY | B9: YESTARDAY | C9: TODAY | D9: Final Electricity Consumption( KW h)
A10: 1 | B10: 12820864 | C10: 12829716 | D10: =C10-B10 -> 8852
A11: 2 | B11: =C10 -> 12829716 | C11: 12832463 | D11: =C11-B11 -> 2747
A12: 3 | B12: =C11 -> 12832463 | C12: 12841046 | D12: =C12-B12 -> 8583
A13: 4 | B13: =C12 -> 12841046 | C13: 12847876 | D13: =C13-B13 -> 6830
A14: 5 | B14: =C13 -> 12847876 | C14: 12855745 | D14: =C14-B14 -> 7869
A15: 6 | B15: =C14 -> 12855745 | C15: 12863564 | D15: =C15-B15 -> 7819
A16: 7 | B16: =C15 -> 12863564 | C16: 12870010 | D16: =C16-B16 -> 6446
A17: 8 | B17: =C16 -> 12870010 | C17: 12877533 | D17: =C17-B17 -> 7523
A18: 9 | B18: =C17 -> 12877533 | C18: 12886791 | D18: =C18-B18 -> 9258
A19: 10 | B19: =C18 -> 12886791 | C19: 12890054 | D19: =C19-B19 -> 3263
A20: 11 | B20: =C19 -> 12890054 | C20: 12900099 | D20: =C20-B20 -> 10045
A21: 12 | B21: =C20 -> 12900099 | D21: =C21-B21 -> -12900099
A22: 13 | B22: =C21 -> 0 | D22: =C22-B22 -> 0
A23: 14 | B23: =C22 -> 0 | D23: =C23-B23 -> 0
A24: 15 | B24: =C23 -> 0 | D24: =C24-B24 -> 0
A25: 16 | B25: =C24 -> 0 | D25: =C25-B25 -> 0
A26: 17 | B26: =C25 -> 0 | D26: =C26-B26 -> 0
A27: 18 | B27: =C26 -> 0 | D27: =C27-B27 -> 0
A28: 19 | B28: =C27 -> 0 | D28: =C28-B28 -> 0
A29: 20 | B29: =C28 -> 0 | D29: =C29-B29 -> 0
A30: 21 | B30: =C29 -> 0 | D30: =C30-B30 -> 0
A31: 22 | B31: =C30 -> 0 | D31: =C31-B31 -> 0
A32: 23 | B32: =C31 -> 0 | D32: =C32-B32 -> 0
... A40: 31 | B40: =C39 -> 0 | D40: =C40-B40 -> 0
A41: Total | B41: =C40 -> 0 | D41: =SUM(D10:D40) -> -12820864

Sheet GENSET #4
C1: 500 KVA
C3: NO#4
A6: 44287
B8: GENSET NO 4
A9: DAY | B9: YESTARDAY | C9: TODAY | D9: Final Electricity Consumption( KW h)
A10: 1 | B10: 11557744 | C10: 11561760 | D10: =C10-B10 -> 4016
A11: 2 | B11: =C10 -> 11561760 | C11: 11566660 | D11: =C11-B11 -> 4900
A12: 3 | B12: =C11 -> 11566660 | C12: 11569734 | D12: =C12-B12 -> 3074
A13: 4 | B13: =C12 -> 11569734 | C13: 11572268 | D13: =C13-B13 -> 2534
A14: 5 | B14: =C13 -> 11572268 | C14: 11576590 | D14: =C14-B14 -> 4322
A15: 6 | B15: =C14 -> 11576590 | C15: 11579383 | D15: =C15-B15 -> 2793
A16: 7 | B16: =C15 -> 11579383 | C16: 11582022 | D16: =C16-B16 -> 2639
A17: 8 | B17: =C16 -> 11582022 | C17: 11585278 | D17: =C17-B17 -> 3256
A18: 9 | B18: =C17 -> 11585278 | C18: 11589540 | D18: =C18-B18 -> 4262
A19: 10 | B19: =C18 -> 11589540 | C19: 11590071 | D19: =C19-B19 -> 531
A20: 11 | B20: =C19 -> 11590071 | C20: 11594028 | D20: =C20-B20 -> 3957
A21: 12 | B21: =C20 -> 11594028 | D21: =C21-B21 -> -11594028
A22: 13 | B22: =C21 -> 0 | D22: =C22-B22 -> 0
A23: 14 | B23: =C22 -> 0 | D23: =C23-B23 -> 0
A24: 15 | B24: =C23 -> 0 | D24: =C24-B24 -> 0
A25: 16 | B25: =C24 -> 0 | D25: =C25-B25 -> 0
A26: 17 | B26: =C25 -> 0 | D26: =C26-B26 -> 0
A27: 18 | B27: =C26 -> 0 | D27: =C27-B27 -> 0
A28: 19 | B28: =C27 -> 0 | D28: =C28-B28 -> 0
A29: 20 | B29: =C28 -> 0 | D29: =C29-B29 -> 0
A30: 21 | B30: =C29 -> 0 | D30: =C30-B30 -> 0
A31: 22 | B31: =C30 -> 0 | D31: =C31-B31 -> 0
A32: 23 | B32: =C31 -> 0 | D32: =C32-B32 -> 0
... A40: 31 | B40: =C39 -> 0 | D40: =C40-B40 -> 0
A41: Total | B41: =C40 -> 0 | D41: =SUM(D10:D40) -> -11557744

Sheet GENSET #5
C1: 1000 KVA
C3: NO#5
A6: 44287
B8: GENSET NO 5
A9: DAY | B9: YESTARDAY | C9: TODAY | D9: Final Electricity Consumption( KWh)
A10: 1 | B10: 17930297 | C10: 17934761 | D10: =C10-B10 -> 4464
A11: 2 | B11: =C10 -> 17934761 | C11: 17944355 | D11: =C11-B11 -> 9594
A12: 3 | B12: =C11 -> 17944355 | C12: 17951760 | D12: =C12-B12 -> 7405
A13: 4 | B13: =C12 -> 17951760 | C13: 17961461 | D13: =C13-B13 -> 9701
A14: 5 | B14: =C13 -> 17961461 | C14: 17968728 | D14: =C14-B14 -> 7267
A15: 6 | B15: =C14 -> 17968728 | C15: 17974371 | D15: =C15-B15 -> 5643
A16: 7 | B16: =C15 -> 17974371 | C16: 17982220 | D16: =C16-B16 -> 7849
A17: 8 | B17: =C16 -> 17982220 | C17: 17988857 | D17: =C17-B17 -> 6637
A18: 9 | B18: =C17 -> 17988857 | C18: 17990819 | D18: =C18-B18 -> 1962
A19: 10 | B19: =C18 -> 17990819 | C19: 18002863 | D19: =C19-B19 -> 12044
A20: 11 | B20: =C19 -> 18002863 | C20: 18006339 | D20: =C20-B20 -> 3476
A21: 12 | B21: =C20 -> 18006339 | D21: =C21-B21 -> -18006339
A22: 13 | B22: =C21 -> 0 | D22: =C22-B22 -> 0
A23: 14 | B23: =C22 -> 0 | D23: =C23-B23 -> 0
A24: 15 | B24: =C23 -> 0 | D24: =C24-B24 -> 0
A25: 16 | B25: =C24 -> 0 | D25: =C25-B25 -> 0
A26: 17 | B26: =C25 -> 0 | D26: =C26-B26 -> 0
A27: 18 | B27: =C26 -> 0 | D27: =C27-B27 -> 0
A28: 19 | B28: =C27 -> 0 | D28: =C28-B28 -> 0
A29: 20 | B29: =C28 -> 0 | D29: =C29-B29 -> 0
A30: 21 | B30: =C29 -> 0 | D30: =C30-B30 -> 0
A31: 22 | B31: =C30 -> 0 | D31: =C31-B31 -> 0
A32: 23 | B32: =C31 -> 0 | D32: =C32-B32 -> 0
... A40: 31 | B40: =C39 -> 0 | D40: =C40-B40 -> 0
A41: Total | B41: =C40 -> 0 | D41: =SUM(D10:D40) -> -17930297

Sheet Diesel consumption
A1: Diesel Consumption
A2: 44287
B3: Liters | F3: Boat meter Reading
A4: Date | B4: Yesterday | C4: Today | D4: In 24 hrs | F4: Yesterday | G4: Today | I4: In Barrels | K4: Carbon Emmision
A5: 1 | B5: 43598170 | C5: 43607040 | D5: =C5-B5 -> 8870 | I5: =D5/200 -> 44.35 | K5: =2.68*D5 -> 23771.6 | L5: =K5/1000 -> 23.7716
A6: 2 | B6: =C5 -> 43607040 | C6: 43616170 | D6: =C6-B6 -> 9130 | I6: =D6/200 -> 45.65 | K6: =2.68*D6 -> 24468.4 | L6: =K6/1000 -> 24.4684
A7: 3 | B7: =C6 -> 43616170 | C7: 43625170 | D7: =C7-B7 -> 9000 | I7: =D7/200 -> 45 | K7: =2.68*D7 -> 24120 | L7: =K7/1000 -> 24.12
A8: 4 | B8: =C7 -> 43625170 | C8: 43634220 | D8: =C8-B8 -> 9050 | I8: =D8/200 -> 45.25 | K8: =2.68*D8 -> 24254 | L8: =K8/1000 -> 24.254
A9: 5 | B9: =C8 -> 43634220 | C9: 43643220 | D9: =C9-B9 -> 9000 | I9: =D9/200 -> 45 | K9: =2.68*D9 -> 24120 | L9: =K9/1000 -> 24.12
A10: 6 | B10: =C9 -> 43643220 | C10: 43652080 | D10: =C10-B10 -> 8860 | I10: =D10/200 -> 44.3 | K10: =2.68*D10 -> 23744.8 | L10: =K10/1000 -> 23.7448
A11: 7 | B11: =C10 -> 43652080 | C11: 43661020 | D11: =C11-B11 -> 8940 | I11: =D11/200 -> 44.7 | K11: =2.68*D11 -> 23959.2 | L11: =K11/1000 -> 23.9592
A12: 8 | B12: =C11 -> 43661020 | C12: 43669970 | D12: =C12-B12 -> 8950 | I12: =D12/200 -> 44.75 | K12: =2.68*D12 -> 23986 | L12: =K12/1000 -> 23.986
A13: 9 | B13: =C12 -> 43669970 | C13: 43678670 | D13: =C13-B13 -> 8700 | I13: =D13/200 -> 43.5 | K13: =2.68*D13 -> 23316 | L13: =K13/1000 -> 23.316
A14: 10 | B14: =C13 -> 43678670 | C14: 43687020 | D14: =C14-B14 -> 8350 | I14: =D14/200 -> 41.75 | K14: =2.68*D14 -> 22378 | L14: =K14/1000 -> 22.378
A15: 11 | B15: =C14 -> 43687020 | C15: 43695650 | D15: =C15-B15 -> 8630 | I15: =D15/200 -> 43.15 | K15: =2.68*D15 -> 23128.4 | L15: =K15/1000 -> 23.1284
A16: 12 | B16: =C15 -> 43695650 | D16: =C16-B16 -> -43695650 | I16: =D16/200 -> -218478.25 | K16: =2.68*D16 -> -117104342 | L16: =K16/1000 -> -117104.34
A17: 13 | B17: =C16 -> 0 | D17: =C17-B17 -> 0 | I17: =D17/200 -> 0 | K17: =2.68*D17 -> 0 | L17: =K17/1000 -> 0
A18: 14 | B18: =C17 -> 0 | D18: =C18-B18 -> 0 | I18: =D18/200 -> 0 | K18: =2.68*D18 -> 0 | L18: =K18/1000 -> 0
A19: 15 | B19: =C18 -> 0 | D19: =C19-B19 -> 0 | I19: =D19/200 -> 0 | K19: =2.68*D19 -> 0 | L19: =K19/1000 -> 0
A20: 16 | B20: =C19 -> 0 | D20: =C20-B20 -> 0 | I20: =D20/200 -> 0 | K20: =2.68*D20 -> 0 | L20: =K20/1000 -> 0
A21: 17 | B21: =C20 -> 0 | D21: =C21-B21 -> 0 | I21: =D21/200 -> 0 | K21: =2.68*D21 -> 0 | L21: =K21/1000 -> 0
A22: 18 | B22: =C21 -> 0 | D22: =C22-B22 -> 0 | I22: =D22/200 -> 0 | K22: =2.68*D22 -> 0 | L22: =K22/1000 -> 0
A23: 19 | B23: =C22 -> 0 | D23: =C23-B23 -> 0 | I23: =D23/200 -> 0 | K23: =2.68*D23 -> 0 | L23: =K23/1000 -> 0
A24: 20 | B24: =C23 -> 0 | D24: =C24-B24 -> 0 | I24: =D24/200 -> 0 | K24: =2.68*D24 -> 0 | L24: =K24/1000 -> 0
A25: 21 | B25: =C24 -> 0 | D25: =C25-B25 -> 0 | I25: =D25/200 -> 0 | K25: =2.68*D25 -> 0 | L25: =K25/1000 -> 0
A26: 22 | B26: =C25 -> 0 | D26: =C26-B26 -> 0 | I26: =D26/200 -> 0 | K26: =2.68*D26 -> 0 | L26: =K26/1000 -> 0
A27: 23 | B27: =C26 -> 0 | D27: =C27-B27 -> 0 | I27: =D27/200 -> 0 | K27: =2.68*D27 -> 0 | L27: =K27/1000 -> 0
... A33: 29 | B33: =C32 -> 0 | D33: =C33-B33 -> 0 | I33: =D33/200 -> 0 | K33: =2.68*D33 -> 0 | L33: =K33/1000 -> 0
A34: 30 | B34: =C33 -> 0 | D34: =C34-B34 -> 0 | F34: 0 | I34: =D34/200 -> 0 | K34: =2.68*D34 -> 0 | L34: =K34/1000 -> 0
A35: 31 | B35: =C34 -> 0 | D35: =C35-B35 -> 0
D36: =SUM(D5:D34) -> -43598170 | I36: =SUM(I5:I34) -> -217990.85 | K36: =2.68*D36 -> -1.168431e+08 | L36: =K36/1000 -> -116843.1

Sheet SOLAR METER READING
C3: solar reading
B5: 44256
B7: solar meter reading
A8: DAY | B8: YESTARDAY | C8: TODAY | D8: Final Electricity Consumption( KW h) | E8: Weather Condition
A9: 1 | B9: 2503023 | C9: 2505815 | D9: =C9-B9 -> 2792 | E9: partly sunny
A10: 2 | B10: =C9 -> 2505815 | C10: 2508223 | D10: =C10-B10 -> 2408 | E10: partly sunny
A11: 3 | B11: =C10 -> 2508223 | C11: 2511353 | D11: =C11-B11 -> 3130 | E11: very sunny
A12: 4 | B12: =C11 -> 2511353 | C12: 2514475 | D12: =C12-B12 -> 3122 | E12: very sunny
A13: 5 | B13: =C12 -> 2514475 | C13: 2517566 | D13: =C13-B13 -> 3091 | E13: very sunny | J13: 1 liter diesel | K13: 11.1 kwh
A14: 6 | B14: =C13 -> 2517566 | C14: 2520727 | D14: =C14-B14 -> 3161 | E14: very sunny | J14: 212.88 diesel | K14: 2363 kwh
A15: 7 | B15: =C14 -> 2520727 | C15: 2523831 | D15: =C15-B15 -> 3104 | E15: very sunny
A16: 8 | B16: =C15 -> 2523831 | C16: 2527019 | D16: =C16-B16 -> 3188 | E16: very sunny
A17: 9 | B17: =C16 -> 2527019 | C17: 2529882 | D17: =C17-B17 -> 2863 | E17: very sunny
A18: 10 | B18: =C17 -> 2529882 | C18: 2533168 | D18: =C18-B18 -> 3286 | E18: very sunny
A19: 11 | B19: =C18 -> 2533168 | C19: 2536509 | D19: =C19-B19 -> 3341 | E19: very sunny
A20: 12 | B20: =C19 -> 2536509 | D20: =C20-B20 -> -2536509
A21: 13 | B21: =C20 -> 0 | D21: =C21-B21 -> 0
A22: 14 | B22: =C21 -> 0 | D22: =C22-B22 -> 0
A23: 15 | B23: =C22 -> 0 | D23: =C23-B23 -> 0
A24: 16 | B24: =C23 -> 0 | D24: =C24-B24 -> 0
A25: 17 | B25: =C24 -> 0 | D25: =C25-B25 -> 0
A26: 18 | B26: =C25 -> 0 | D26: =C26-B26 -> 0
A27: 19 | B27: =C26 -> 0 | D27: =C27-B27 -> 0
A28: 20 | B28: =C27 -> 0 | D28: =C28-B28 -> 0
A29: 21 | B29: =C28 -> 0 | D29: =C29-B29 -> 0
A30: 22 | B30: =C29 -> 0 | D30: =C30-B30 -> 0
A31: 23 | B31: =C30 -> 0 | D31: =C31-B31 -> 0
... A39: 31 | B39: =C38 -> 0 | D39: =C39-B39 -> 0
A40: Total | D40: =SUM(D9:D39) -> -2503023

Sheet FEEDER Consumption 
A1: 44256
A2: POWER HOUSE FEEDER READING
B3: BLU FEEDER PANEL 1 | E3: BLU FEEDER PANEL 2 | H3: POWER HOUSE FEEDER PANEL NO:3 | K3: Main Kitchen -7 | N3: Main Kitchen -10 | Q3: Water treatment Plant | T3: Sewage treatment Plant | W3: Laundry--8SSB | Z3: Laundry-9 | AC3: New staff accomodation (E0) | AF3: Boat Dock feeder - 22 | AI3: Staff block-16(E2-E3) | AL3: Management block-5 | AO3: Staff Block Feeder-3(E4-E5) | AR3: DIESEL TANK JETTY METER | AU3: SNR STAFF BLOCK | AX3: RECEPTION | BA3: DIVE CENTER | BD3: 301-307 | BG3: 308-314 | BJ3: 315-320 | BM3: 401-407 | BP3: 408-414 | BS3: 415-420 | BV3: SPA - 1 | BY3: SPA - 2 | CB3: BLU KITCHEN - 1 | CE3: BLU KITCHEN - 2 | CH3: AL BARAKATH | CK3: STAFF KITCHEN | CN3: MANAGR BLOCK GARDEN
A4: DAY | B4: Yesterday | C4: Today | D4: Consumption | E4: Yesterday | F4: Today | G4: Consumption | H4: Yesterday | I4: Today | J4: Consumption | K4: Yesterday | L4: Today | M4: Consumption | N4: Yesterday | O4: Today | P4: Consumption | Q4: Yesterday | R4: Today | S4: Consumption | T4: Yesterday | U4: Today | V4: Consumption | W4: Yesterday | X4: Today | Y4: Consumption | Z4: Yesterday | AA4: Today | AB4: Consumption | AC4: Yesterday | AD4: Today | AE4: Consumption | AF4: Yesterday | AG4: Today | AH4: Consumption | AI4: Yesterday | AJ4: Today | AK4: Consumption | AL4: Yesterday | AM4: Today | AN4: Consumption | AO4: Yesterday | AP4: Today | AQ4: Consumption | AR4: Yesterday | AS4: Today | AT4: Consumption | AU4: Yesterday | AV4: Today | AW4: Consumption | AX4: Yesterday | AY4: Today | AZ4: Consumption | BA4: Yesterday | BB4: Today | BC4: Consumption | BD4: Yesterday | BE4: Today | BF4: Consumption | BG4: Yesterday | BH4: Today | BI4: Consumption | BJ4: Yesterday | BK4: Today | BL4: Consumption | BM4: Yesterday | BN4: Today | BO4: Consumption | BP4: Yesterday | BQ4: Today | BR4: Consumption | BS4: Yesterday | BT4: Today | BU4: Consumption | BV4: Yesterday | BW4: Today | BX4: Consumption | BY4: Yesterday | BZ4: Today | CA4: Consumption | CB4: Yesterday | CC4: Today | CD4: Consumption | CE4: Yesterday | CF4: Today | CG4: Consumption | CH4: Yesterday | CI4: Today | CJ4: Consumption | CK4: Yesterday | CL4: Today | CM4: Consumption | CN4: Yesterday | CO4: Today | CP4: Consumption
A5: 1 | B5: 25415038 | C5: 25419266 | D5: =C5-B5 -> 4228 | E5: 22415724 | F5: 22421222 | G5: =F5-E5 -> 5498 | H5: 84973340 | I5: 84988512 | J5: =I5-H5 -> 15172 | K5: 1904300 | L5: 1906400 | M5: =L5-K5 -> 2100 | N5: 2575806 | O5: 2578702 | P5: =O5-N5 -> 2896 | Q5: 1564500 | R5: 1566300 | S5: =R5-Q5 -> 1800 | T5: 714530 | U5: 715185 | V5: =U5-T5 -> 655 | W5: 7396800 | X5: 7403700 | Y5: =X5-W5 -> 6900 | Z5: 1679900 | AA5: 1682400 | AB5: =AA5-Z5 -> 2500 | AC5: 481218 | AD5: 481668 | AE5: =AD5-AC5 -> 450 | AF5: 347510 | AG5: 347930 | AH5: =AG5-AF5 -> 420 | AI5: 599710 | AJ5: 600660 | AK5: =AJ5-AI5 -> 950 | AL5: 1091800 | AM5: 1093300 | AN5: =AM5-AL5 -> 1500 | AO5: 695510 | AP5: 696520 | AQ5: =AP5-AO5 -> 1010 | AR5: 585480 | AS5: 586480 | AT5: =AS5-AR5 -> 1000 | AU5: 544830 | AV5: 546540 | AW5: =AV5-AU5 -> 1710 | AX5: 419210 | AY5: 420250 | AZ5: =AY5-AX5 -> 1040 | BA5: 1182300 | BB5: 1187400 | BC5: =BB5-BA5 -> 5100 | BD5: 26360 | BE5: 26484 | BF5: =BE5-BD5 -> 124 | BG5: 21277 | BH5: 21368 | BI5: =BH5-BG5 -> 91 | BJ5: 19194 | BK5: 19280 | BL5: =BK5-BJ5 -> 86 | BM5: 30186 | BN5: 30312 | BO5: =BN5-BM5 -> 126 | BP5: 22000 | BQ5: 22122 | BR5: =BQ5-BP5 -> 122 | BS5: 21845 | BT5: 21928 | BU5: =BT5-BS5 -> 83 | BV5: 15122 | BW5: 15176 | BX5: =BW5-BV5 -> 54 | BY5: 40090 | BZ5: 40254 | CA5: =BZ5-BY5 -> 164 | CB5: 30100 | CC5: 30183 | CD5: =CC5-CB5 -> 83 | CE5: 89918 | CF5: 90212 | CG5: =CF5-CE5 -> 294 | CH5: 66101 | CI5: 66575 | CJ5: =CI5-CH5 -> 474 | CK5: 15176 | CL5: 15229 | CM5: =CL5-CK5 -> 53 | CN5: 96664 | CO5: 100630 | CP5: =CO5-CN5 -> 3966
A6: 2 | B6: =C5 -> 25419266 | C6: 25423389 | D6: =C6-B6 -> 4123 | E6: =F5 -> 22421222 | F6: 22426671 | G6: =F6-E6 -> 5449 | H6: =I5 -> 84988512 | I6: 85004111 | J6: =I6-H6 -> 15599 | K6: =L5 -> 1906400 | L6: 1908700 | M6: =L6-K6 -> 2300 | N6: =O5 -> 2578702 | O6: 2581557 | P6: =O6-N6 -> 2855 | Q6: =R5 -> 1566300 | R6: 1568500 | S6: =R6-Q6 -> 2200 | T6: =U5 -> 715185 | U6: 715776 | V6: =U6-T6 -> 591 | W6: =X5 -> 7403700 | X6: 7410300 | Y6: =X6-W6 -> 6600 | Z6: =AA5 -> 1682400 | AA6: 1685200 | AB6: =AA6-Z6 -> 2800 | AC6: =AD5 -> 481668 | AD6: 482125 | AE6: =AD6-AC6 -> 457 | AF6: =AG5 -> 347930 | AG6: 348360 | AH6: =AG6-AF6 -> 430 | AI6: =AJ5 -> 600660 | AJ6: 601610 | AK6: =AJ6-AI6 -> 950 | AL6: =AM5 -> 1093300 | AM6: 1094900 | AN6: =AM6-AL6 -> 1600 | AO6: =AP5 -> 696520 | AP6: 697570 | AQ6: =AP6-AO6 -> 1050 | AR6: =AS5 -> 586480 | AS6: 587510 | AT6: =AS6-AR6 -> 1030 | AU6: =AV5 -> 546540 | AV6: 548490 | AW6: =AV6-AU6 -> 1950 | AX6: =AY5 -> 420250 | AY6: 421400 | AZ6: =AY6-AX6 -> 1150 | BA6: =BB5 -> 1187400 | BB6: 1192000 | BC6: =BB6-BA6 -> 4600 | BD6: =BE5 -> 26484 | BE6: 26610 | BF6: =BE6-BD6 -> 126 | BG6: =BH5 -> 21368 | BH6: 21449 | BI6: =BH6-BG6 -> 81 | BJ6: =BK5 -> 19280 | BK6: 19368 | BL6: =BK6-BJ6 -> 88 | BM6: =BN5 -> 30312 | BN6: 30453 | BO6: =BN6-BM6 -> 141 | BP6: =BQ5 -> 22122 | BQ6: 22249 | BR6: =BQ6-BP6 -> 127 | BS6: =BT5 -> 21928 | BT6: 22017 | BU6: =BT6-BS6 -> 89 | BV6: =BW5 -> 15176 | BW6: 15226 | BX6: =BW6-BV6 -> 50 | BY6: =BZ5 -> 40254 | BZ6: 40444 | CA6: =BZ6-BY6 -> 190 | CB6: =CC5 -> 30183 | CC6: 30268 | CD6: =CC6-CB6 -> 85 | CE6: =CF5 -> 90212 | CF6: 90525 | CG6: =CF6-CE6 -> 313 | CH6: =CI5 -> 66575 | CI6: 66943 | CJ6: =CI6-CH6 -> 368 | CK6: =CL5 -> 15229 | CL6: 15282 | CM6: =CL6-CK6 -> 53 | CN6: =CO5 -> 100630 | CO6: 104480 | CP6: =CO6-CN6 -> 3850
A7: 3 | B7: =C6 -> 25423389 | C7: 25427772 | D7: =C7-B7 -> 4383 | E7: =F6 -> 22426671 | F7: 22432132 | G7: =F7-E7 -> 5461 | H7: =I6 -> 85004111 | I7: 85019438 | J7: =I7-H7 -> 15327 | K7: =L6 -> 1908700 | L7: 1910800 | M7: =L7-K7 -> 2100 | N7: =O6 -> 2581557 | O7: 2584259 | P7: =O7-N7 -> 2702 | Q7: =R6 -> 1568500 | R7: 1570500 | S7: =R7-Q7 -> 2000 | T7: =U6 -> 715776 | U7: 716414 | V7: =U7-T7 -> 638 | W7: =X6 -> 7410300 | X7: 7416900 | Y7: =X7-W7 -> 6600 | Z7: =AA6 -> 1685200 | AA7: 1687900 | AB7: =AA7-Z7 -> 2700 | AC7: =AD6 -> 482125 | AD7: 482593 | AE7: =AD7-AC7 -> 468 | AF7: =AG6 -> 348360 | AG7: 348750 | AH7: =AG7-AF7 -> 390 | AI7: =AJ6 -> 601610 | AJ7: 602490 | AK7: =AJ7-AI7 -> 880 | AL7: =AM6 -> 1094900 | AM7: 1096400 | AN7: =AM7-AL7 -> 1500 | AO7: =AP6 -> 697570 | AP7: 698530 | AQ7: =AP7-AO7 -> 960 | AR7: =AS6 -> 587510 | AS7: 587910 | AT7: =AS7-AR7 -> 400 | AU7: =AV6 -> 548490 | AV7: 550090 | AW7: =AV7-AU7 -> 1600 | AX7: =AY6 -> 421400 | AY7: 422690 | AZ7: =AY7-AX7 -> 1290 | BA7: =BB6 -> 1192000 | BB7: 1197500 | BC7: =BB7-BA7 -> 5500 | BD7: =BE6 -> 26610 | BE7: 26717 | BF7: =BE7-BD7 -> 107 | BG7: =BH6 -> 21449 | BH7: 21532 | BI7: =BH7-BG7 -> 83 | BJ7: =BK6 -> 19368 | BK7: 19457 | BL7: =BK7-BJ7 -> 89 | BM7: =BN6 -> 30453 | BN7: 30560 | BO7: =BN7-BM7 -> 107 | BP7: =BQ6 -> 22249 | BQ7: 22475 | BR7: =BQ7-BP7 -> 226 | BS7: =BT6 -> 22017 | BT7: 22091 | BU7: =BT7-BS7 -> 74 | BV7: =BW6 -> 15226 | BW7: 15275 | BX7: =BW7-BV7 -> 49 | BY7: =BZ6 -> 40444 | BZ7: 40579 | CA7: =BZ7-BY7 -> 135 | CB7: =CC6 -> 30268 | CC7: 30343 | CD7: =CC7-CB7 -> 75 | CE7: =CF6 -> 90525 | CF7: 90797 | CG7: =CF7-CE7 -> 272 | CH7: =CI6 -> 66943 | CI7: 67253 | CJ7: =CI7-CH7 -> 310 | CK7: =CL6 -> 15282 | CL7: 15331 | CM7: =CL7-CK7 -> 49 | CN7: =CO6 -> 104480 | CO7: 107920 | CP7: =CO7-CN7 -> 3440
A8: 4 | B8: =C7 -> 25427772 | C8: 25432240 | D8: =C8-B8 -> 4468 | E8: =F7 -> 22432132 | F8: 22437743 | G8: =F8-E8 -> 5611 | H8: =I7 -> 85019438 | I8: 85035217 | J8: =I8-H8 -> 15779 | K8: =L7 -> 1910800 | L8: 1913000 | M8: =L8-K8 -> 2200 | N8: =O7 -> 2584259 | O8: 2587174 | P8: =O8-N8 -> 2915 | Q8: =R7 -> 1570500 | R8: 1572900 | S8: =R8-Q8 -> 2400 | T8: =U7 -> 716414 | U8: 717038 | V8: =U8-T8 -> 624 | W8: =X7 -> 7416900 | X8: 7423700 | Y8: =X8-W8 -> 6800 | Z8: =AA7 -> 1687900 | AA8: 1690300 | AB8: =AA8-Z8 -> 2400 | AC8: =AD7 -> 482593 | AD8: 483033 | AE8: =AD8-AC8 -> 440 | AF8: =AG7 -> 348750 | AG8: 349160 | AH8: =AG8-AF8 -> 410 | AI8: =AJ7 -> 602490 | AJ8: 603450 | AK8: =AJ8-AI8 -> 960 | AL8: =AM7 -> 1096400 | AM8: 1097800 | AN8: =AM8-AL8 -> 1400 | AO8: =AP7 -> 698530 | AP8: 699510 | AQ8: =AP8-AO8 -> 980 | AR8: =AS7 -> 587910 | AS8: 591350 | AT8: =AS8-AR8 -> 3440 | AU8: =AV7 -> 550090 | AV8: 552110 | AW8: =AV8-AU8 -> 2020 | AX8: =AY7 -> 422690 | AY8: 424000 | AZ8: =AY8-AX8 -> 1310 | BA8: =BB7 -> 1197500 | BB8: 1202100 | BC8: =BB8-BA8 -> 4600 | BD8: =BE7 -> 26717 | BE8: 26840 | BF8: =BE8-BD8 -> 123 | BG8: =BH7 -> 21532 | BH8: 21647 | BI8: =BH8-BG8 -> 115 | BJ8: =BK7 -> 19457 | BK8: 19550 | BL8: =BK8-BJ8 -> 93 | BM8: =BN7 -> 30560 | BN8: 30686 | BO8: =BN8-BM8 -> 126 | BP8: =BQ7 -> 22475 | BQ8: 22597 | BR8: =BQ8-BP8 -> 122 | BS8: =BT7 -> 22091 | BT8: 22167 | BU8: =BT8-BS8 -> 76 | BV8: =BW7 -> 15275 | BW8: 15330 | BX8: =BW8-BV8 -> 55 | BY8: =BZ7 -> 40579 | BZ8: 40735 | CA8: =BZ8-BY8 -> 156 | CB8: =CC7 -> 30343 | CC8: 30431 | CD8: =CC8-CB8 -> 88 | CE8: =CF7 -> 90797 | CF8: 91080 | CG8: =CF8-CE8 -> 283 | CH8: =CI7 -> 67253 | CI8: 67658 | CJ8: =CI8-CH8 -> 405 | CK8: =CL7 -> 15331 | CL8: 15376 | CM8: =CL8-CK8 -> 45 | CN8: =CO7 -> 107920 | CO8: 111930 | CP8: =CO8-CN8 -> 4010
A9: 5 | B9: =C8 -> 25432240 | C9: 25436818 | D9: =C9-B9 -> 4578 | E9: =F8 -> 22437743 | F9: 22443548 | G9: =F9-E9 -> 5805 | H9: =I8 -> 85035217 | I9: 85051241 | J9: =I9-H9 -> 16024 | K9: =L8 -> 1913000 | L9: 1915100 | M9: =L9-K9 -> 2100 | N9: =O8 -> 2587174 | O9: 2590080 | P9: =O9-N9 -> 2906 | Q9: =R8 -> 1572900 | R9: 1575000 | S9: =R9-Q9 -> 2100 | T9: =U8 -> 717038 | U9: 717722 | V9: =U9-T9 -> 684 | W9: =X8 -> 7423700 | X9: 7430700 | Y9: =X9-W9 -> 7000 | Z9: =AA8 -> 1690300 | AA9: 1692900 | AB9: =AA9-Z9 -> 2600 | AC9: =AD8 -> 483033 | AD9: 483508 | AE9: =AD9-AC9 -> 475 | AF9: =AG8 -> 349160 | AG9: 349580 | AH9: =AG9-AF9 -> 420 | AI9: =AJ8 -> 603450 | AJ9: 604444 | AK9: =AJ9-AI9 -> 994 | AL9: =AM8 -> 1097800 | AM9: 1099400 | AN9: =AM9-AL9 -> 1600 | AO9: =AP8 -> 699510 | AP9: 700580 | AQ9: =AP9-AO9 -> 1070 | AR9: =AS8 -> 591350 | AS9: 591870 | AT9: =AS9-AR9 -> 520 | AU9: =AV8 -> 552110 | AV9: 553720 | AW9: =AV9-AU9 -> 1610 | AX9: =AY8 -> 424000 | AY9: 425360 | AZ9: =AY9-AX9 -> 1360 | BA9: =BB8 -> 1202100 | BB9: 1206900 | BC9: =BB9-BA9 -> 4800 | BD9: =BE8 -> 26840 | BE9: 26950 | BF9: =BE9-BD9 -> 110 | BG9: =BH8 -> 21647 | BH9: 21754 | BI9: =BH9-BG9 -> 107 | BJ9: =BK8 -> 19550 | BK9: 19638 | BL9: =BK9-BJ9 -> 88 | BM9: =BN8 -> 30686 | BN9: 30799 | BO9: =BN9-BM9 -> 113 | BP9: =BQ8 -> 22597 | BQ9: 22736 | BR9: =BQ9-BP9 -> 139 | BS9: =BT8 -> 22167 | BT9: 22248 | BU9: =BT9-BS9 -> 81 | BV9: =BW8 -> 15330 | BW9: 15383 | BX9: =BW9-BV9 -> 53 | BY9: =BZ8 -> 40735 | BZ9: 40897 | CA9: =BZ9-BY9 -> 162 | CB9: =CC8 -> 30431 | CC9: 30512 | CD9: =CC9-CB9 -> 81 | CE9: =CF8 -> 91080 | CF9: 91333 | CG9: =CF9-CE9 -> 253 | CH9: =CI8 -> 67658 | CI9: 68015 | CJ9: =CI9-CH9 -> 357 | CK9: =CL8 -> 15376 | CL9: 15441 | CM9: =CL9-CK9 -> 65 | CN9: =CO8 -> 111930 | CO9: 115560 | CP9: =CO9-CN9 -> 3630
A10: 6 | B10: =C9 -> 25436818 | C10: 25441088 | D10: =C10-B10 -> 4270 | E10: =F9 -> 22443548 | F10: 22448913 | G10: =F10-E10 -> 5365 | H10: =I9 -> 85051241 | I10: 85066574 | J10: =I10-H10 -> 15333 | K10: =L9 -> 1915100 | L10: 1917300 | M10: =L10-K10 -> 2200 | N10: =O9 -> 2590080 | O10: 2592934 | P10: =O10-N10 -> 2854 | Q10: =R9 -> 1575000 | R10: 1577200 | S10: =R10-Q10 -> 2200 | T10: =U9 -> 717722 | U10: 718398 | V10: =U10-T10 -> 676 | W10: =X9 -> 7430700 | X10: 7437700 | Y10: =X10-W10 -> 7000 | Z10: =AA9 -> 1692900 | AA10: 1695200 | AB10: =AA10-Z10 -> 2300 | AC10: =AD9 -> 483508 | AD10: 483964 | AE10: =AD10-AC10 -> 456 | AF10: =AG9 -> 349580 | AG10: 349970 | AH10: =AG10-AF10 -> 390 | AI10: =AJ9 -> 604444 | AJ10: 605360 | AK10: =AJ10-AI10 -> 916 | AL10: =AM9 -> 1099400 | AM10: 1100900 | AN10: =AM10-AL10 -> 1500 | AO10: =AP9 -> 700580 | AP10: 701590 | AQ10: =AP10-AO10 -> 1010 | AR10: =AS9 -> 591870 | AS10: 591870 | AT10: =AS10-AR10 -> 0 | AU10: =AV9 -> 553720 | AV10: 555230 | AW10: =AV10-AU10 -> 1510 | AX10: =AY9 -> 425360 | AY10: 426700 | AZ10: =AY10-AX10 -> 1340 | BA10: =BB9 -> 1206900 | BB10: 1212100 | BC10: =BB10-BA10 -> 5200 | BD10: =BE9 -> 26950 | BE10: 27060 | BF10: =BE10-BD10 -> 110 | BG10: =BH9 -> 21754 | BH10: 21863 | BI10: =BH10-BG10 -> 109 | BJ10: =BK9 -> 19638 | BK10: 19734 | BL10: =BK10-BJ10 -> 96 | BM10: =BN9 -> 30799 | BN10: 30940 | BO10: =BN10-BM10 -> 141 | BP10: =BQ9 -> 22736 | BQ10: 22825 | BR10: =BQ10-BP10 -> 89 | BS10: =BT9 -> 22248 | BT10: 22351 | BU10: =BT10-BS10 -> 103 | BV10: =BW9 -> 15383 | BW10: 15468 | BX10: =BW10-BV10 -> 85 | BY10: =BZ9 -> 40897 | BZ10: 41062 | CA10: =BZ10-BY10 -> 165 | CB10: =CC9 -> 30512 | CC10: 30619 | CD10: =CC10-CB10 -> 107 | CE10: =CF9 -> 91333 | CF10: 91615 | CG10: =CF10-CE10 -> 282 | CH10: =CI9 -> 68015 | CI10: 68348 | CJ10: =CI10-CH10 -> 333 | CK10: =CL9 -> 15441 | CL10: 15494 | CM10: =CL10-CK10 -> 53 | CN10: =CO9 -> 115560 | CO10: 119120 | CP10: =CO10-CN10 -> 3560
A11: 7 | B11: =C10 -> 25441088 | C11: 25445244 | D11: =C11-B11 -> 4156 | E11: =F10 -> 22448913 | F11: 22454614 | G11: =F11-E11 -> 5701 | H11: =I10 -> 85066574 | I11: 85082504 | J11: =I11-H11 -> 15930 | K11: =L10 -> 1917300 | L11: 1919300 | M11: =L11-K11 -> 2000 | N11: =O10 -> 2592934 | O11: 2595831 | P11: =O11-N11 -> 2897 | Q11: =R10 -> 1577200 | R11: 1579700 | S11: =R11-Q11 -> 2500 | T11: =U10 -> 718398 | U11: 719066 | V11: =U11-T11 -> 668 | W11: =X10 -> 7437700 | X11: 7444900 | Y11: =X11-W11 -> 7200 | Z11: =AA10 -> 1695200 | AA11: 1697400 | AB11: =AA11-Z11 -> 2200 | AC11: =AD10 -> 483964 | AD11: 484401 | AE11: =AD11-AC11 -> 437 | AF11: =AG10 -> 349970 | AG11: 350450 | AH11: =AG11-AF11 -> 480 | AI11: =AJ10 -> 605360 | AJ11: 606320 | AK11: =AJ11-AI11 -> 960 | AL11: =AM10 -> 1100900 | AM11: 1102300 | AN11: =AM11-AL11 -> 1400 | AO11: =AP10 -> 701590 | AP11: 702660 | AQ11: =AP11-AO11 -> 1070 | AR11: =AS10 -> 591870 | AS11: 596590 | AT11: =AS11-AR11 -> 4720 | AU11: =AV10 -> 555230 | AV11: 557080 | AW11: =AV11-AU11 -> 1850 | AX11: =AY10 -> 426700 | AY11: 428050 | AZ11: =AY11-AX11 -> 1350 | BA11: =BB10 -> 1212100 | BB11: 1216900 | BC11: =BB11-BA11 -> 4800 | BD11: =BE10 -> 27060 | BE11: 27189 | BF11: =BE11-BD11 -> 129 | BG11: =BH10 -> 21863 | BH11: 21970 | BI11: =BH11-BG11 -> 107 | BJ11: =BK10 -> 19734 | BK11: 19814 | BL11: =BK11-BJ11 -> 80 | BM11: =BN10 -> 30940 | BN11: 31043 | BO11: =BN11-BM11 -> 103 | BP11: =BQ10 -> 22825 | BQ11: 22736 | BR11: =BQ11-BP11 -> -89 | BS11: =BT10 -> 22351 | BT11: 22406 | BU11: =BT11-BS11 -> 55 | BV11: =BW10 -> 15468 | BW11: 15489 | BX11: =BW11-BV11 -> 21 | BY11: =BZ10 -> 41062 | BZ11: 41188 | CA11: =BZ11-BY11 -> 126 | CB11: =CC10 -> 30619 | CC11: 30678 | CD11: =CC11-CB11 -> 59 | CE11: =CF10 -> 91615 | CF11: 91907 | CG11: =CF11-CE11 -> 292 | CH11: =CI10 -> 68348 | CI11: 68735 | CJ11: =CI11-CH11 -> 387 | CK11: =CL10 -> 15494 | CL11: 15549 | CM11: =CL11-CK11 -> 55 | CN11: =CO10 -> 119120 | CO11: 122650 | CP11: =CO11-CN11 -> 3530
A12: 8 | B12: =C11 -> 25445244 | C12: 25449373 | D12: =C12-B12 -> 4129 | E12: =F11 -> 22454614 | F12: 22460658 | G12: =F12-E12 -> 6044 | H12: =I11 -> 85082504 | I12: 85097970 | J12: =I12-H12 -> 15466 | K12: =L11 -> 1919300 | L12: 1921400 | M12: =L12-K12 -> 2100 | N12: =O11 -> 2595831 | O12: 2598695 | P12: =O12-N12 -> 2864 | Q12: =R11 -> 1579700 | R12: 1581700 | S12: =R12-Q12 -> 2000 | T12: =U11 -> 719066 | U12: 719719 | V12: =U12-T12 -> 653 | W12: =X11 -> 7444900 | X12: 7451800 | Y12: =X12-W12 -> 6900 | Z12: =AA11 -> 1697400 | AA12: 1699500 | AB12: =AA12-Z12 -> 2100 | AC12: =AD11 -> 484401 | AD12: 484844 | AE12: =AD12-AC12 -> 443 | AF12: =AG11 -> 350450 | AG12: 350900 | AH12: =AG12-AF12 -> 450 | AI12: =AJ11 -> 606320 | AJ12: 607280 | AK12: =AJ12-AI12 -> 960 | AL12: =AM11 -> 1102300 | AM12: 1103800 | AN12: =AM12-AL12 -> 1500 | AO12: =AP11 -> 702660 | AP12: 703670 | AQ12: =AP12-AO12 -> 1010 | AR12: =AS11 -> 596590 | AS12: 597280 | AT12: =AS12-AR12 -> 690 | AU12: =AV11 -> 557080 | AV12: 558670 | AW12: =AV12-AU12 -> 1590 | AX12: =AY11 -> 428050 | AY12: 429370 | AZ12: =AY12-AX12 -> 1320 | BA12: =BB11 -> 1216900 | BB12: 1222100 | BC12: =BB12-BA12 -> 5200 | BD12: =BE11 -> 27189 | BE12: 27316 | BF12: =BE12-BD12 -> 127 | BG12: =BH11 -> 21970 | BH12: 22087 | BI12: =BH12-BG12 -> 117 | BJ12: =BK11 -> 19814 | BK12: 19913 | BL12: =BK12-BJ12 -> 99 | BM12: =BN11 -> 31043 | BN12: 31196 | BO12: =BN12-BM12 -> 153 | BP12: =BQ11 -> 22736 | BQ12: 22943 | BR12: =BQ12-BP12 -> 207 | BS12: =BT11 -> 22406 | BT12: 22511 | BU12: =BT12-BS12 -> 105 | BV12: =BW11 -> 15489 | BW12: 15538 | BX12: =BW12-BV12 -> 49 | BY12: =BZ11 -> 41188 | BZ12: 41346 | CA12: =BZ12-BY12 -> 158 | CB12: =CC11 -> 30678 | CC12: 30759 | CD12: =CC12-CB12 -> 81 | CE12: =CF11 -> 91907 | CF12: 92191 | CG12: =CF12-CE12 -> 284 | CH12: =CI11 -> 68735 | CI12: 68735 | CJ12: =CI12-CH12 -> 0 | CK12: =CL11 -> 15549 | CL12: 15604 | CM12: =CL12-CK12 -> 55 | CN12: =CO11 -> 122650 | CO12: 125380 | CP12: =CO12-CN12 -> 2730
A13: 9 | B13: =C12 -> 25449373 | C13: 25453268 | D13: =C13-B13 -> 3895 | E13: =F12 -> 22460658 | F13: 22466192 | G13: =F13-E13 -> 5534 | H13: =I12 -> 85097970 | I13: 85113342 | J13: =I13-H13 -> 15372 | K13: =L12 -> 1921400 | L13: 1923400 | M13: =L13-K13 -> 2000 | N13: =O12 -> 2598695 | O13: 2601521 | P13: =O13-N13 -> 2826 | Q13: =R12 -> 1581700 | R13: 1583800 | S13: =R13-Q13 -> 2100 | T13: =U12 -> 719719 | U13: 720387 | V13: =U13-T13 -> 668 | W13: =X12 -> 7451800 | X13: 7458500 | Y13: =X13-W13 -> 6700 | Z13: =AA12 -> 1699500 | AA13: 1701400 | AB13: =AA13-Z13 -> 1900 | AC13: =AD12 -> 484844 | AD13: 485290 | AE13: =AD13-AC13 -> 446 | AF13: =AG12 -> 350900 | AG13: 351360 | AH13: =AG13-AF13 -> 460 | AI13: =AJ12 -> 607280 | AJ13: 608270 | AK13: =AJ13-AI13 -> 990 | AL13: =AM12 -> 1103800 | AM13: 1105400 | AN13: =AM13-AL13 -> 1600 | AO13: =AP12 -> 703670 | AP13: 704760 | AQ13: =AP13-AO13 -> 1090 | AR13: =AS12 -> 597280 | AS13: 597780 | AT13: =AS13-AR13 -> 500 | AU13: =AV12 -> 558670 | AV13: 560390 | AW13: =AV13-AU13 -> 1720 | AX13: =AY12 -> 429370 | AY13: 430590 | AZ13: =AY13-AX13 -> 1220 | BA13: =BB12 -> 1222100 | BB13: 1227000 | BC13: =BB13-BA13 -> 4900 | BD13: =BE12 -> 27316 | BE13: 27426 | BF13: =BE13-BD13 -> 110 | BG13: =BH12 -> 22087 | BH13: 22183 | BI13: =BH13-BG13 -> 96 | BJ13: =BK12 -> 19913 | BK13: 19994 | BL13: =BK13-BJ13 -> 81 | BM13: =BN12 -> 31196 | BN13: 31310 | BO13: =BN13-BM13 -> 114 | BP13: =BQ12 -> 22943 | BQ13: 23052 | BR13: =BQ13-BP13 -> 109 | BS13: =BT12 -> 22511 | BT13: 22589 | BU13: =BT13-BS13 -> 78 | BV13: =BW12 -> 15538 | BW13: 15587 | BX13: =BW13-BV13 -> 49 | BY13: =BZ12 -> 41346 | BZ13: 41470 | CA13: =BZ13-BY13 -> 124 | CB13: =CC12 -> 30759 | CC13: 30832 | CD13: =CC13-CB13 -> 73 | CE13: =CF12 -> 92191 | CF13: 92435 | CG13: =CF13-CE13 -> 244 | CH13: =CI12 -> 68735 | CI13: 69132 | CJ13: =CI13-CH13 -> 397 | CK13: =CL12 -> 15604 | CL13: 15657 | CM13: =CL13-CK13 -> 53 | CN13: =CO12 -> 125380 | CO13: 129820 | CP13: =CO13-CN13 -> 4440
A14: 10 | B14: =C13 -> 25453268 | C14: 25457084 | D14: =C14-B14 -> 3816 | E14: =F13 -> 22466192 | F14: 22471634 | G14: =F14-E14 -> 5442 | H14: =I13 -> 85113342 | I14: 85127919 | J14: =I14-H14 -> 14577 | K14: =L13 -> 1923400 | L14: 1925200 | M14: =L14-K14 -> 1800 | N14: =O13 -> 2601521 | O14: 2604466 | P14: =O14-N14 -> 2945 | Q14: =R13 -> 1583800 | R14: 1585800 | S14: =R14-Q14 -> 2000 | T14: =U13 -> 720387 | U14: 721034 | V14: =U14-T14 -> 647 | W14: =X13 -> 7458500 | X14: 7464700 | Y14: =X14-W14 -> 6200 | Z14: =AA13 -> 1701400 | AA14: 1703600 | AB14: =AA14-Z14 -> 2200 | AC14: =AD13 -> 485290 | AD14: 485702 | AE14: =AD14-AC14 -> 412 | AF14: =AG13 -> 351360 | AG14: 351750 | AH14: =AG14-AF14 -> 390 | AI14: =AJ13 -> 608270 | AJ14: 609190 | AK14: =AJ14-AI14 -> 920 | AL14: =AM13 -> 1105400 | AM14: 1106800 | AN14: =AM14-AL14 -> 1400 | AO14: =AP13 -> 704760 | AP14: 705730 | AQ14: =AP14-AO14 -> 970 | AR14: =AS13 -> 597780 | AS14: 597784 | AT14: =AS14-AR14 -> 4 | AU14: =AV13 -> 560390 | AV14: 562070 | AW14: =AV14-AU14 -> 1680 | AX14: =AY13 -> 430590 | AY14: 431840 | AZ14: =AY14-AX14 -> 1250 | BA14: =BB13 -> 1227000 | BB14: 1231800 | BC14: =BB14-BA14 -> 4800 | BD14: =BE13 -> 27426 | BF14: =BE14-BD14 -> -27426 | BG14: =BH13 -> 22183 | BI14: =BH14-BG14 -> -22183 | BJ14: =BK13 -> 19994 | BL14: =BK14-BJ14 -> -19994 | BM14: =BN13 -> 31310 | BO14: =BN14-BM14 -> -31310 | BP14: =BQ13 -> 23052 | BR14: =BQ14-BP14 -> -23052 | BS14: =BT13 -> 22589 | BU14: =BT14-BS14 -> -22589 | BV14: =BW13 -> 15587 | BX14: =BW14-BV14 -> -15587 | BY14: =BZ13 -> 41470 | CA14: =BZ14-BY14 -> -41470 | CB14: =CC13 -> 30832 | CD14: =CC14-CB14 -> -30832 | CE14: =CF13 -> 92435 | CG14: =CF14-CE14 -> -92435 | CH14: =CI13 -> 69132 | CJ14: =CI14-CH14 -> -69132 | CK14: =CL13 -> 15657 | CM14: =CL14-CK14 -> -15657 | CN14: =CO13 -> 129820 | CP14: =CO14-CN14 -> -129820
A15: 11 | B15: =C14 -> 25457084 | C15: 25460879 | D15: =C15-B15 -> 3795 | E15: =F14 -> 22471634 | F15: 22477367 | G15: =F15-E15 -> 5733 | H15: =I14 -> 85127919 | I15: 85142907 | J15: =I15-H15 -> 14988 | K15: =L14 -> 1925200 | L15: 1927200 | M15: =L15-K15 -> 2000 | N15: =O14 -> 2604466 | O15: 2607739 | P15: =O15-N15 -> 3273 | Q15: =R14 -> 1585800 | R15: 1587700 | S15: =R15-Q15 -> 1900 | T15: =U14 -> 721034 | U15: 721738 | V15: =U15-T15 -> 704 | W15: =X14 -> 7464700 | X15: 7471900 | Y15: =X15-W15 -> 7200 | Z15: =AA14 -> 1703600 | AA15: 1705700 | AB15: =AA15-Z15 -> 2100 | AC15: =AD14 -> 485702 | AD15: 486128 | AE15: =AD15-AC15 -> 426 | AF15: =AG14 -> 351750 | AG15: 352150 | AH15: =AG15-AF15 -> 400 | AI15: =AJ14 -> 609190 | AJ15: 610120 | AK15: =AJ15-AI15 -> 930 | AL15: =AM14 -> 1106800 | AM15: 1108300 | AN15: =AM15-AL15 -> 1500 | AO15: =AP14 -> 705730 | AP15: 706730 | AQ15: =AP15-AO15 -> 1000 | AR15: =AS14 -> 597784 | AS15: 601250 | AT15: =AS15-AR15 -> 3466 | AU15: =AV14 -> 562070 | AV15: 563860 | AW15: =AV15-AU15 -> 1790 | AX15: =AY14 -> 431840 | AY15: 433110 | AZ15: =AY15-AX15 -> 1270 | BA15: =BB14 -> 1231800 | BB15: 1236500 | BC15: =BB15-BA15 -> 4700 | BD15: =BE14 -> 0 | BF15: =BE15-BD15 -> 0 | BG15: =BH14 -> 0 | BI15: =BH15-BG15 -> 0 | BJ15: =BK14 -> 0 | BL15: =BK15-BJ15 -> 0 | BM15: =BN14 -> 0 | BO15: =BN15-BM15 -> 0 | BP15: =BQ14 -> 0 | BR15: =BQ15-BP15 -> 0 | BS15: =BT14 -> 0 | BU15: =BT15-BS15 -> 0 | BV15: =BW14 -> 0 | BX15: =BW15-BV15 -> 0 | BY15: =BZ14 -> 0 | CA15: =BZ15-BY15 -> 0 | CB15: =CC14 -> 0 | CD15: =CC15-CB15 -> 0 | CE15: =CF14 -> 0 | CG15: =CF15-CE15 -> 0 | CH15: =CI14 -> 0 | CJ15: =CI15-CH15 -> 0 | CK15: =CL14 -> 0 | CM15: =CL15-CK15 -> 0 | CN15: =CO14 -> 0 | CP15: =CO15-CN15 -> 0
A16: 12 | B16: =C15 -> 25460879 | D16: =C16-B16 -> -25460879 | E16: =F15 -> 22477367 | G16: =F16-E16 -> -22477367 | H16: =I15 -> 85142907 | J16: =I16-H16 -> -85142907 | K16: =L15 -> 1927200 | M16: =L16-K16 -> -1927200 | N16: =O15 -> 2607739 | P16: =O16-N16 -> -2607739 | Q16: =R15 -> 1587700 | S16: =R16-Q16 -> -1587700 | T16: =U15 -> 721738 | V16: =U16-T16 -> -721738 | W16: =X15 -> 7471900 | Y16: =X16-W16 -> -7471900 | Z16: =AA15 -> 1705700 | AB16: =AA16-Z16 -> -1705700 | AC16: =AD15 -> 486128 | AE16: =AD16-AC16 -> -486128 | AF16: =AG15 -> 352150 | AH16: =AG16-AF16 -> -352150 | AI16: =AJ15 -> 610120 | AK16: =AJ16-AI16 -> -610120 | AL16: =AM15 -> 1108300 | AN16: =AM16-AL16 -> -1108300 | AO16: =AP15 -> 706730 | AQ16: =AP16-AO16 -> -706730 | AR16: =AS15 -> 601250 | AT16: =AS16-AR16 -> -601250 | AU16: =AV15 -> 563860 | AW16: =AV16-AU16 -> -563860 | AX16: =AY15 -> 433110 | AZ16: =AY16-AX16 -> -433110 | BA16: =BB15 -> 1236500 | BC16: =BB16-BA16 -> -1236500 | BD16: =BE15 -> 0 | BF16: =BE16-BD16 -> 0 | BG16: =BH15 -> 0 | BI16: =BH16-BG16 -> 0 | BJ16: =BK15 -> 0 | BL16: =BK16-BJ16 -> 0 | BM16: =BN15 -> 0 | BO16: =BN16-BM16 -> 0 | BP16: =BQ15 -> 0 | BR16: =BQ16-BP16 -> 0 | BS16: =BT15 -> 0 | BU16: =BT16-BS16 -> 0 | BV16: =BW15 -> 0 | BX16: =BW16-BV16 -> 0 | BY16: =BZ15 -> 0 | CA16: =BZ16-BY16 -> 0 | CB16: =CC15 -> 0 | CD16: =CC16-CB16 -> 0 | CE16: =CF15 -> 0 | CG16: =CF16-CE16 -> 0 | CH16: =CI15 -> 0 | CJ16: =CI16-CH16 -> 0 | CK16: =CL15 -> 0 | CM16: =CL16-CK16 -> 0 | CN16: =CO15 -> 0 | CP16: =CO16-CN16 -> 0
A17: 13 | B17: =C16 -> 0 | D17: =C17-B17 -> 0 | E17: =F16 -> 0 | G17: =F17-E17 -> 0 | H17: =I16 -> 0 | J17: =I17-H17 -> 0 | K17: =L16 -> 0 | M17: =L17-K17 -> 0 | N17: =O16 -> 0 | P17: =O17-N17 -> 0 | Q17: =R16 -> 0 | S17: =R17-Q17 -> 0 | T17: =U16 -> 0 | V17: =U17-T17 -> 0 | W17: =X16 -> 0 | Y17: =X17-W17 -> 0 | Z17: =AA16 -> 0 | AB17: =AA17-Z17 -> 0 | AC17: =AD16 -> 0 | AE17: =AD17-AC17 -> 0 | AF17: =AG16 -> 0 | AH17: =AG17-AF17 -> 0 | AI17: =AJ16 -> 0 | AK17: =AJ17-AI17 -> 0 | AL17: =AM16 -> 0 | AN17: =AM17-AL17 -> 0 | AO17: =AP16 -> 0 | AQ17: =AP17-AO17 -> 0 | AR17: =AS16 -> 0 | AT17: =AS17-AR17 -> 0 | AU17: =AV16 -> 0 | AW17: =AV17-AU17 -> 0 | AX17: =AY16 -> 0 | AZ17: =AY17-AX17 -> 0 | BA17: =BB16 -> 0 | BC17: =BB17-BA17 -> 0 | BD17: =BE16 -> 0 | BF17: =BE17-BD17 -> 0 | BG17: =BH16 -> 0 | BI17: =BH17-BG17 -> 0 | BJ17: =BK16 -> 0 | BL17: =BK17-BJ17 -> 0 | BM17: =BN16 -> 0 | BO17: =BN17-BM17 -> 0 | BP17: =BQ16 -> 0 | BR17: =BQ17-BP17 -> 0 | BS17: =BT16 -> 0 | BU17: =BT17-BS17 -> 0 | BV17: =BW16 -> 0 | BX17: =BW17-BV17 -> 0 | BY17: =BZ16 -> 0 | CA17: =BZ17-BY17 -> 0 | CB17: =CC16 -> 0 | CD17: =CC17-CB17 -> 0 | CE17: =CF16 -> 0 | CG17: =CF17-CE17 -> 0 | CH17: =CI16 -> 0 | CJ17: =CI17-CH17 -> 0 | CK17: =CL16 -> 0 | CM17: =CL17-CK17 -> 0 | CN17: =CO16 -> 0 | CP17: =CO17-CN17 -> 0
A18: 14 | B18: =C17 -> 0 | D18: =C18-B18 -> 0 | E18: =F17 -> 0 | G18: =F18-E18 -> 0 | H18: =I17 -> 0 | J18: =I18-H18 -> 0 | K18: =L17 -> 0 | M18: =L18-K18 -> 0 | N18: =O17 -> 0 | P18: =O18-N18 -> 0 | Q18: =R17 -> 0 | S18: =R18-Q18 -> 0 | T18: =U17 -> 0 | V18: =U18-T18 -> 0 | W18: =X17 -> 0 | Y18: =X18-W18 -> 0 | Z18: =AA17 -> 0 | AB18: =AA18-Z18 -> 0 | AC18: =AD17 -> 0 | AE18: =AD18-AC18 -> 0 | AF18: =AG17 -> 0 | AH18: =AG18-AF18 -> 0 | AI18: =AJ17 -> 0 | AK18: =AJ18-AI18 -> 0 | AL18: =AM17 -> 0 | AN18: =AM18-AL18 -> 0 | AO18: =AP17 -> 0 | AQ18: =AP18-AO18 -> 0 | AR18: =AS17 -> 0 | AT18: =AS18-AR18 -> 0 | AU18: =AV17 -> 0 | AW18: =AV18-AU18 -> 0 | AX18: =AY17 -> 0 | AZ18: =AY18-AX18 -> 0 | BA18: =BB17 -> 0 | BC18: =BB18-BA18 -> 0 | BD18: =BE17 -> 0 | BF18: =BE18-BD18 -> 0 | BG18: =BH17 -> 0 | BI18: =BH18-BG18 -> 0 | BJ18: =BK17 -> 0 | BL18: =BK18-BJ18 -> 0 | BM18: =BN17 -> 0 | BO18: =BN18-BM18 -> 0 | BP18: =BQ17 -> 0 | BR18: =BQ18-BP18 -> 0 | BS18: =BT17 -> 0 | BU18: =BT18-BS18 -> 0 | BV18: =BW17 -> 0 | BX18: =BW18-BV18 -> 0 | BY18: =BZ17 -> 0 | CA18: =BZ18-BY18 -> 0 | CB18: =CC17 -> 0 | CD18: =CC18-CB18 -> 0 | CE18: =CF17 -> 0 | CG18: =CF18-CE18 -> 0 | CH18: =CI17 -> 0 | CJ18: =CI18-CH18 -> 0 | CK18: =CL17 -> 0 | CM18: =CL18-CK18 -> 0 | CN18: =CO17 -> 0 | CP18: =CO18-CN18 -> 0
A19: 15 | B19: =C18 -> 0 | D19: =C19-B19 -> 0 | E19: =F18 -> 0 | G19: =F19-E19 -> 0 | H19: =I18 -> 0 | J19: =I19-H19 -> 0 | K19: =L18 -> 0 | M19: =L19-K19 -> 0 | N19: =O18 -> 0 | P19: =O19-N19 -> 0 | Q19: =R18 -> 0 | S19: =R19-Q19 -> 0 | T19: =U18 -> 0 | V19: =U19-T19 -> 0 | W19: =X18 -> 0 | Y19: =X19-W19 -> 0 | Z19: =AA18 -> 0 | AB19: =AA19-Z19 -> 0 | AC19: =AD18 -> 0 | AE19: =AD19-AC19 -> 0 | AF19: =AG18 -> 0 | AH19: =AG19-AF19 -> 0 | AI19: =AJ18 -> 0 | AK19: =AJ19-AI19 -> 0 | AL19: =AM18 -> 0 | AN19: =AM19-AL19 -> 0 | AO19: =AP18 -> 0 | AQ19: =AP19-AO19 -> 0 | AR19: =AS18 -> 0 | AT19: =AS19-AR19 -> 0 | AU19: =AV18 -> 0 | AW19: =AV19-AU19 -> 0 | AX19: =AY18 -> 0 | AZ19: =AY19-AX19 -> 0 | BA19: =BB18 -> 0 | BC19: =BB19-BA19 -> 0 | BD19: =BE18 -> 0 | BF19: =BE19-BD19 -> 0 | BG19: =BH18 -> 0 | BI19: =BH19-BG19 -> 0 | BJ19: =BK18 -> 0 | BL19: =BK19-BJ19 -> 0 | BM19: =BN18 -> 0 | BO19: =BN19-BM19 -> 0 | BP19: =BQ18 -> 0 | BR19: =BQ19-BP19 -> 0 | BS19: =BT18 -> 0 | BU19: =BT19-BS19 -> 0 | BV19: =BW18 -> 0 | BX19: =BW19-BV19 -> 0 | BY19: =BZ18 -> 0 | CA19: =BZ19-BY19 -> 0 | CB19: =CC18 -> 0 | CD19: =CC19-CB19 -> 0 | CE19: =CF18 -> 0 | CG19: =CF19-CE19 -> 0 | CH19: =CI18 -> 0 | CJ19: =CI19-CH19 -> 0 | CK19: =CL18 -> 0 | CM19: =CL19-CK19 -> 0 | CN19: =CO18 -> 0 | CP19: =CO19-CN19 -> 0
