Workbook

Sheet TOTAL
A1: Site Name | B1: Day | C1: Month | D1: Year | E1: Total Electricity Kwh | F1: Electricity Tariff ($/Kwh) | G1: Total Fuel Oil (Liters) | H1: Fuel Oil $/Liter | I1: Water Utility Supply (m3) m3 | J1: Water Utility Supply (m3) $/m3 | K1: LPG (Kg) | L1: LPG $/Kg | M1: Room Nights | N1: Total Guests | O1: Food Covers
A2: Maldives at Kuda Huraa | B2: 1 | C2: 4 | D2: 2021 | E2: 25520 | F2: 0.14 | G2: 7195 | H2: 0.44534802 | I2: 349 | J2: 0.4 | K2: =K33/31 -> 0 | L2: 1.5287028 | M2: 61 | N2: 168 | O2: 434
A3: Maldives at Kuda Huraa | B3: =B2+1 -> 2 | C3: 4 | D3: 2021 | E3: 25880 | F3: 0.14 | G3: 7289 | H3: 0.44534802 | I3: 296 | J3: 0.4 | K3: 0 | L3: 1.5287028 | M3: 67 | N3: 182 | O3: 486
A4: Maldives at Kuda Huraa | B4: =B3+1 -> 3 | C4: 4 | D4: 2021 | E4: 25550 | F4: 0.14 | G4: 6971 | H4: 0.44534802 | I4: 381 | J4: 0.4 | K4: 0 | L4: 1.5287028 | M4: 65 | N4: 176 | O4: 535
A5: Maldives at Kuda Huraa | B5: =B4+1 -> 4 | C5: 4 | D5: 2021 | E5: 26880 | F5: 0.14 | G5: 7461 | H5: 0.44534802 | I5: 370 | J5: 0.4 | K5: 0 | L5: 1.5287028 | M5: 62 | N5: 172 | O5: 452
A6: Maldives at Kuda Huraa | B6: =B5+1 -> 5 | C6: 4 | D6: 2021 | E6: 25850 | F6: 0.14 | G6: 7045 | H6: 0.44534802 | I6: 350 | J6: 0.4 | K6: 0 | L6: 1.5287028 | M6: 53 | N6: 148 | O6: 419
A7: Maldives at Kuda Huraa | B7: =B6+1 -> 6 | C7: 4 | D7: 2021 | E7: 25300 | F7: 0.14 | G7: 6830 | H7: 0.44534802 | I7: 309 | J7: 0.4 | K7: 0 | L7: 1.5287028 | M7: 52 | N7: 147 | O7: 431
A8: Maldives at Kuda Huraa | B8: =B7+1 -> 7 | C8: 4 | D8: 2021 | E8: 20730 | F8: 0.14 | G8: 6845 | H8: 0.44534802 | I8: 331 | J8: 0.4 | K8: 0 | L8: 1.5287028 | M8: 43 | N8: 118 | O8: 319
A9: Maldives at Kuda Huraa | B9: =B8+1 -> 8 | C9: 4 | D9: 2021 | E9: 24890 | F9: 0.14 | G9: 6819 | H9: 0.44534802 | I9: 266 | J9: 0.4 | K9: 0 | L9: 1.5287028 | M9: 39 | N9: 109 | O9: 296
A10: Maldives at Kuda Huraa | B10: =B9+1 -> 9 | C10: 4 | D10: 2021 | E10: 22380 | F10: 0.14 | G10: 6513 | H10: 0.44534802 | I10: 316 | J10: 0.4 | K10: 0 | L10: 1.5287028 | M10: 31 | N10: 92 | O10: 287
A11: Maldives at Kuda Huraa | B11: =B10+1 -> 10 | C11: 4 | D11: 2021 | E11: 24860 | F11: 0.14 | G11: 6382 | H11: 0.44534802 | I11: 316 | J11: 0.4 | K11: 0 | L11: 1.5287028
A12: Maldives at Kuda Huraa | B12: =B11+1 -> 11 | C12: 4 | D12: 2021 | E12: 23700 | F12: 0.14 | G12: 6520 | H12: 0.44534802 | I12: 326 | J12: 0.4 | K12: 0 | L12: 1.5287028
A13: Maldives at Kuda Huraa | B13: =B12+1 -> 12 | C13: 4 | D13: 2021 | E13: 23130 | F13: 0.14 | G13: 6351 | H13: 0.44534802 | I13: 274 | J13: 0.4 | K13: 0 | L13: 1.5287028
A14: Maldives at Kuda Huraa | B14: =B13+1 -> 13 | C14: 4 | D14: 2021 | E14: 24080 | F14: 0.14 | G14: 6658 | H14: 0.44534802 | I14: 332 | J14: 0.4 | K14: 0 | L14: 1.5287028
A15: Maldives at Kuda Huraa | B15: =B14+1 -> 14 | C15: 4 | D15: 2021 | F15: 0.14 | H15: 0.44534802 | J15: 0.4 | K15: 0 | L15: 1.5287028
A16: Maldives at Kuda Huraa | B16: =B15+1 -> 15 | C16: 4 | D16: 2021 | F16: 0.14 | H16: 0.44534802 | J16: 0.4 | K16: 0 | L16: 1.5287028
A17: Maldives at Kuda Huraa | B17: =B16+1 -> 16 | C17: 4 | D17: 2021 | F17: 0.14 | H17: 0.44534802 | J17: 0.4 | K17: 0 | L17: 1.5287028
A18: Maldives at Kuda Huraa | B18: =B17+1 -> 17 | C18: 4 | D18: 2021 | F18: 0.14 | H18: 0.44534802 | J18: 0.4 | K18: 0 | L18: 1.5287028
A19: Maldives at Kuda Huraa | B19: =B18+1 -> 18 | C19: 4 | D19: 2021 | F19: 0.14 | H19: 0.44534802 | J19: 0.4 | K19: 0 | L19: 1.5287028
A20: Maldives at Kuda Huraa | B20: =B19+1 -> 19 | C20: 4 | D20: 2021 | F20: 0.14 | H20: 0.44534802 | J20: 0.4 | K20: 0 | L20: 1.5287028
A21: Maldives at Kuda Huraa | B21: =B20+1 -> 20 | C21: 4 | D21: 2021 | F21: 0.14 | H21: 0.44534802 | J21: 0.4 | K21: 0 | L21: 1.5287028
A22: Maldives at Kuda Huraa | B22: =B21+1 -> 21 | C22: 4 | D22: 2021 | F22: 0.14 | H22: 0.44534802 | J22: 0.4 | K22: 0 | L22: 1.5287028
A23: Maldives at Kuda Huraa | B23: =B22+1 -> 22 | C23: 4 | D23: 2021 | F23: 0.14 | H23: 0.44534802 | J23: 0.4 | K23: 0 | L23: 1.5287028
A24: Maldives at Kuda Huraa | B24: =B23+1 -> 23 | C24: 4 | D24: 2021 | F24: 0.14 | H24: 0.44534802 | J24: 0.4 | K24: 0 | L24: 1.5287028
A25: Maldives at Kuda Huraa | B25: =B24+1 -> 24 | C25: 4 | D25: 2021 | F25: 0.14 | H25: 0.44534802 | J25: 0.4 | K25: 0 | L25: 1.5287028
A26: Maldives at Kuda Huraa | B26: =B25+1 -> 25 | C26: 4 | D26: 2021 | F26: 0.14 | H26: 0.44534802 | J26: 0.4 | K26: 0 | L26: 1.5287028
... A32: Maldives at Kuda Huraa | B32: =B31+1 -> 31 | C32: 4 | D32: 2021 | F32: 0.14 | H32: 0.44534802 | J32: 0.4 | K32: 0 | L32: 1.5287028
A33: Total | E33: =SUM(E2:E32) -> 318750 | F33: 0 | G33: =SUM(G2:G32) -> 88879 | H33: 0 | I33: =SUM(I2:I32) -> 4216 | J33: 0 | K33: 0 | L33: 0 | M33: =SUM(M2:M32) -> 473 | N33: =SUM(N2:N32) -> 1312 | O33: =SUM(O2:O32) -> 3659

Sheet Kwh Reading
A1: Electric Consumption Record (4pm)
A2: Month | B2: BOH-1/ B&C Block MWH | C2: Pastry MWH | D2: Feeder 401-419 KWH | E2: Feeder 301-319 KWH | F2: Kitchen GWH | G2: Feeder 201-208 MWH | H2: Feeder 113-123 | I2: M - Block /PC MWH | J2: Laundry MWH | M2: Feeder 101-112 MWH | N2: Feeder 217-224 | O2: Spa MWH | P2: Feeder 124-134 | Q2: Feeder 209-216 | R2: STP -1 &2 MWH | S2: STP -3 MWH | T2: Reef Club MWH | V2: Room Nights | W2: Total Guests | X2: Food Covers
J3: A | K3: B | L3: C
A4: 44287 | B4: 860.77 | C4: 209.57 | D4: 7259830 | E4: 7898651.4 | F4: 2.1588 | G4: 662.88 | H4: 558.3 | I4: 206.17 | J4: 298.13 | K4: 316.49 | L4: 216.26 | M4: 448.28 | N4: 400.92 | O4: 128.64 | P4: 524.32 | Q4: 393.27 | R4: 130.52 | S4: 103.33 | T4: 378.95 | V4: 61 | W4: 168 | X4: 434
A5: 44288 | B5: 862.1 | C5: 209.82 | D5: 7262447.8 | E5: 7902483.7 | F5: 2.1614 | G5: 663.9 | H5: 559.18 | I5: 206.43 | J5: 298.46 | K5: 316.93 | L5: 216.53 | M5: 449.09 | N5: 401.76 | O5: 128.91 | P5: 525.43 | Q5: 394.02 | R5: 130.83 | S5: 103.49 | T5: 379.49 | V5: 67 | W5: 182 | X5: 486
A6: 44289 | B6: 863.48 | C6: 210.07 | D6: 7265219.9 | E6: 7906464.5 | F6: 2.164 | G6: 664.95 | H6: 560.12 | I6: 206.76 | J6: 298.81 | K6: 317.39 | L6: 216.8 | M6: 449.89 | N6: 402.71 | O6: 129.19 | P6: 526.56 | Q6: 394.89 | R6: 131.03 | S6: 103.63 | T6: 380.04 | V6: 65 | W6: 176 | X6: 535
A7: 44290 | B7: 864.83 | C7: 210.34 | D7: 7267990.1 | E7: 7910306.6 | F7: 2.1668 | G7: 665.96 | H7: 561.05 | I7: 207.05 | J7: 299.21 | K7: 317.9 | L7: 217.12 | M7: 450.65 | N7: 403.61 | O7: 129.48 | P7: 527.71 | Q7: 395.75 | R7: 131.27 | S7: 103.75 | T7: 380.66 | V7: 62 | W7: 172 | X7: 452
A8: 44291 | B8: 866.08 | C8: 210.56 | D8: 7270854.6 | E8: 7914233.4 | F8: 2.1693 | G8: 666.94 | H8: 562.09 | I8: 207.36 | J8: 299.56 | K8: 318.31 | L8: 217.39 | M8: 451.42 | N8: 404.5 | O8: 129.72 | P8: 528.76 | Q8: 396.63 | R8: 131.59 | S8: 103.89 | T8: 381.23 | V8: 53 | W8: 148 | X8: 419
A9: 44292 | B9: 867.44 | C9: 210.82 | D9: 7273739 | E9: 7918241.9 | F9: 2.1721 | G9: 667.98 | H9: 563.18 | I9: 207.7 | J9: 300.02 | K9: 318.81 | L9: 217.68 | M9: 452.23 | N9: 405.46 | O9: 130 | P9: 529.92 | Q9: 397.47 | R9: 131.91 | S9: 104.02 | T9: 381.8 | V9: 52 | W9: 147 | X9: 431
A10: 44293 | B10: 868.73 | C10: 211.06 | D10: 7276083 | E10: 7921697.8 | F10: 2.1746 | G10: 668.87 | H10: 564.16 | I10: 208.01 | J10: 300.34 | K10: 319.19 | L10: 217.92 | M10: 452.98 | N10: 406.27 | O10: 130.23 | P10: 530.91 | Q10: 398.26 | R10: 132.24 | S10: 104.14 | T10: 382.37 | V10: 43 | W10: 118 | X10: 319
A11: 44294 | B11: 870.09 | C11: 211.29 | D11: 7278703.2 | E11: 7925228 | F11: 2.1771 | G11: 669.79 | H11: 565.24 | I11: 208.33 | J11: 300.69 | K11: 319.6 | L11: 218.17 | M11: 453.82 | N11: 406.95 | O11: 130.49 | P11: 531.85 | Q11: 399.18 | R11: 132.54 | S11: 104.27 | T11: 382.9 | V11: 39 | W11: 109 | X11: 296
A12: 44295 | B12: 871.46 | C12: 211.53 | D12: 7281406.1 | E12: 7928757.1 | F12: 2.1797 | G12: 670.74 | H12: 566.31 | I12: 208.64 | J12: 300.98 | K12: 320 | L12: 218.38 | M12: 454.73 | N12: 407.62 | O12: 130.8 | P12: 532.89 | Q12: 400.13 | R12: 132.87 | S12: 104.39 | T12: 383.45 | V12: 31 | W12: 92 | X12: 287
A13: 44296 | B13: 872.81 | C13: 211.76 | D13: 7283841.8 | E13: 7931531 | F13: 2.1822 | G13: 671.61 | H13: 567.26 | I13: 208.97 | J13: 301.31 | K13: 320.32 | L13: 218.61 | M13: 455.61 | N13: 408.21 | O13: 131.07 | P13: 533.81 | Q13: 400.84 | R13: 133.2 | S13: 104.52 | T13: 383.71
A14: 44297 | B14: 874.27 | C14: 211.99 | D14: 7286342.5 | E14: 7934889.8 | F14: 2.1847 | G14: 672.65 | H14: 568.34 | I14: 209.32 | J14: 301.64 | K14: 320.7 | L14: 218.86 | M14: 456.53 | N14: 409.01 | O14: 131.34 | P14: 534.8 | Q14: 401.6 | R14: 133.53 | S14: 104.65 | T14: 384.25
A15: 44298 | B15: 875.6 | C15: 212.19 | D15: 7288764.9 | E15: 7937789.4 | F15: 2.187 | G15: 673.64 | H15: 569.29 | I15: 209.66 | J15: 301.89 | K15: 320.97 | L15: 219.04 | M15: 457.38 | N15: 409.88 | O15: 131.58 | P15: 535.65 | Q15: 402.35 | R15: 133.81 | S15: 104.78 | T15: 384.73
A16: 44299 | B16: 876.99 | C16: 212.42 | D16: 7291266.1 | E16: 7940809.6 | F16: 2.1895 | G16: 674.59 | H16: 570.23 | I16: 210.03 | J16: 302.14 | K16: 321.32 | L16: 219.24 | M16: 458.15 | N16: 410.86 | O16: 131.82 | P16: 536.6 | Q16: 403.12 | R16: 134.11 | S16: 104.91 | T16: 385.23
A17: 44300 | B17: 878.33 | C17: 212.66 | D17: 7293555.9 | E17: 7943907.5 | F17: 2.1917 | G17: 675.45 | H17: 571.18 | I17: 210.36 | J17: 302.3 | K17: 321.6 | L17: 219.42 | M17: 458.94 | N17: 411.74 | O17: 132.04 | P17: 537.51 | Q17: 403.84 | R17: 134.36 | S17: 105.05 | T17: 385.72
A18: 44301
A19: 44302
A20: 44303
A21: 44304
A22: 44305
A23: 44306
A24: 44307
A25: 44308
A26: 44309
A27: 44310
A28: 44311
A29: 44312
... A34: 44317
V35: =SUM(V4:V34) -> 473 | W35: =SUM(W4:W34) -> 1312 | X35: =SUM(X4:X34) -> 3659
T42: ……..

Sheet Kwh Consumption
A2: Date | B2: Total KWH | C2: Reef Club KWH | D2: Kitchen KWH | E2: Pastry KWH | F2: Laundry KWH | I2: STP -1 &2 KWH | J2: STP -3 KWH | K2: M - Block /PC KWH | L2: B&C Block KWH | M2: Guest Room Beach Pavilion & Beach Bungalow KWH | S2: Guest Room Water Bungalow KWH | U2: Spa KWH | V2: Others KWH
F3: A | G3: B | H3: C | M3: Feeder -101-112 | N3: Feeder -113-123 | O3: Feeder -124-134 | P3: Feeder -201-208 | Q3: Feeder -209-216 | R3: Feeder -217-224 | S3: Feeder -301-319 | T3: Feeder 401-419
A4: ='Kwh Reading'!A4 -> 44287 | B4: 25520 | C4: =('Kwh Reading'!T5-'Kwh Reading'!T4)*1000 -> 540 | D4: =('Kwh Reading'!F5-'Kwh Reading'!F4)*1000000 -> 2600 | E4: =('Kwh Reading'!C5-'Kwh Reading'!C4)*1000 -> 250 | F4: =('Kwh Reading'!J5-'Kwh Reading'!J4)*1000 -> 330 | G4: =('Kwh Reading'!K5-'Kwh Reading'!K4)*1000 -> 440 | H4: =('Kwh Reading'!L5-'Kwh Reading'!L4)*1000 -> 270 | I4: =('Kwh Reading'!R5-'Kwh Reading'!R4)*1000 -> 310 | J4: =('Kwh Reading'!S5-'Kwh Reading'!S4)*1000 -> 160 | K4: =('Kwh Reading'!I5-'Kwh Reading'!I4)*1000 -> 260 | L4: =('Kwh Reading'!B5-'Kwh Reading'!B4)*1000 -> 1330 | M4: =('Kwh Reading'!M5-'Kwh Reading'!M4)*1000 -> 810 | N4: =('Kwh Reading'!H5-'Kwh Reading'!H4)*1000 -> 880 | O4: =('Kwh Reading'!P5-'Kwh Reading'!P4)*1000 -> 1110 | P4: =('Kwh Reading'!G5-'Kwh Reading'!G4)*1000 -> 1020 | Q4: =('Kwh Reading'!Q5-'Kwh Reading'!Q4)*1000 -> 750 | R4: =('Kwh Reading'!N5-'Kwh Reading'!N4)*1000 -> 840 | S4: ='Kwh Reading'!E5-'Kwh Reading'!E4 -> 3832.3 | T4: ='Kwh Reading'!D5-'Kwh Reading'!D4 -> 2617.74 | U4: =('Kwh Reading'!O5-'Kwh Reading'!O4)*1000 -> 270 | V4: =B4-(SUM(C4:U4)) -> 6899.96
A5: ='Kwh Reading'!A5 -> 44288 | B5: =TOTAL!E3 -> 25880 | C5: =('Kwh Reading'!T6-'Kwh Reading'!T5)*1000 -> 550 | D5: =('Kwh Reading'!F6-'Kwh Reading'!F5)*1000000 -> 2600 | E5: =('Kwh Reading'!C6-'Kwh Reading'!C5)*1000 -> 250 | F5: =('Kwh Reading'!J6-'Kwh Reading'!J5)*1000 -> 350 | G5: =('Kwh Reading'!K6-'Kwh Reading'!K5)*1000 -> 460 | H5: =('Kwh Reading'!L6-'Kwh Reading'!L5)*1000 -> 270 | I5: =('Kwh Reading'!R6-'Kwh Reading'!R5)*1000 -> 200 | J5: =('Kwh Reading'!S6-'Kwh Reading'!S5)*1000 -> 140 | K5: =('Kwh Reading'!I6-'Kwh Reading'!I5)*1000 -> 330 | L5: =('Kwh Reading'!B6-'Kwh Reading'!B5)*1000 -> 1380 | M5: =('Kwh Reading'!M6-'Kwh Reading'!M5)*1000 -> 800 | N5: =('Kwh Reading'!H6-'Kwh Reading'!H5)*1000 -> 940 | O5: =('Kwh Reading'!P6-'Kwh Reading'!P5)*1000 -> 1130 | P5: =('Kwh Reading'!G6-'Kwh Reading'!G5)*1000 -> 1050 | Q5: =('Kwh Reading'!Q6-'Kwh Reading'!Q5)*1000 -> 870 | R5: =('Kwh Reading'!N6-'Kwh Reading'!N5)*1000 -> 950 | S5: ='Kwh Reading'!E6-'Kwh Reading'!E5 -> 3980.85 | T5: ='Kwh Reading'!D6-'Kwh Reading'!D5 -> 2772.15 | U5: =('Kwh Reading'!O6-'Kwh Reading'!O5)*1000 -> 280 | V5: =B5-(SUM(C5:U5)) -> 6577
A6: ='Kwh Reading'!A6 -> 44289 | B6: =TOTAL!E4 -> 25550 | C6: =('Kwh Reading'!T7-'Kwh Reading'!T6)*1000 -> 620 | D6: =('Kwh Reading'!F7-'Kwh Reading'!F6)*1000000 -> 2800 | E6: =('Kwh Reading'!C7-'Kwh Reading'!C6)*1000 -> 270 | F6: =('Kwh Reading'!J7-'Kwh Reading'!J6)*1000 -> 400 | G6: =('Kwh Reading'!K7-'Kwh Reading'!K6)*1000 -> 510 | H6: =('Kwh Reading'!L7-'Kwh Reading'!L6)*1000 -> 320 | I6: =('Kwh Reading'!R7-'Kwh Reading'!R6)*1000 -> 240 | J6: =('Kwh Reading'!S7-'Kwh Reading'!S6)*1000 -> 120 | K6: =('Kwh Reading'!I7-'Kwh Reading'!I6)*1000 -> 290 | L6: =('Kwh Reading'!B7-'Kwh Reading'!B6)*1000 -> 1350 | M6: =('Kwh Reading'!M7-'Kwh Reading'!M6)*1000 -> 760 | N6: =('Kwh Reading'!H7-'Kwh Reading'!H6)*1000 -> 930 | O6: =('Kwh Reading'!P7-'Kwh Reading'!P6)*1000 -> 1150 | P6: =('Kwh Reading'!G7-'Kwh Reading'!G6)*1000 -> 1010 | Q6: =('Kwh Reading'!Q7-'Kwh Reading'!Q6)*1000 -> 860 | R6: =('Kwh Reading'!N7-'Kwh Reading'!N6)*1000 -> 900 | S6: ='Kwh Reading'!E7-'Kwh Reading'!E6 -> 3842.08 | T6: ='Kwh Reading'!D7-'Kwh Reading'!D6 -> 2770.21 | U6: =('Kwh Reading'!O7-'Kwh Reading'!O6)*1000 -> 290 | V6: =B6-(SUM(C6:U6)) -> 6117.71
A7: ='Kwh Reading'!A7 -> 44290 | B7: =TOTAL!E5 -> 26880 | C7: =('Kwh Reading'!T8-'Kwh Reading'!T7)*1000 -> 570 | D7: =('Kwh Reading'!F8-'Kwh Reading'!F7)*1000000 -> 2500 | E7: =('Kwh Reading'!C8-'Kwh Reading'!C7)*1000 -> 220 | F7: =('Kwh Reading'!J8-'Kwh Reading'!J7)*1000 -> 350 | G7: =('Kwh Reading'!K8-'Kwh Reading'!K7)*1000 -> 410 | H7: =('Kwh Reading'!L8-'Kwh Reading'!L7)*1000 -> 270 | I7: =('Kwh Reading'!R8-'Kwh Reading'!R7)*1000 -> 320 | J7: =('Kwh Reading'!S8-'Kwh Reading'!S7)*1000 -> 140 | K7: =('Kwh Reading'!I8-'Kwh Reading'!I7)*1000 -> 310 | L7: =('Kwh Reading'!B8-'Kwh Reading'!B7)*1000 -> 1250 | M7: =('Kwh Reading'!M8-'Kwh Reading'!M7)*1000 -> 770 | N7: =('Kwh Reading'!H8-'Kwh Reading'!H7)*1000 -> 1040 | O7: =('Kwh Reading'!P8-'Kwh Reading'!P7)*1000 -> 1050 | P7: =('Kwh Reading'!G8-'Kwh Reading'!G7)*1000 -> 980 | Q7: =('Kwh Reading'!Q8-'Kwh Reading'!Q7)*1000 -> 880 | R7: =('Kwh Reading'!N8-'Kwh Reading'!N7)*1000 -> 890 | S7: ='Kwh Reading'!E8-'Kwh Reading'!E7 -> 3926.75 | T7: ='Kwh Reading'!D8-'Kwh Reading'!D7 -> 2864.49 | U7: =('Kwh Reading'!O8-'Kwh Reading'!O7)*1000 -> 240 | V7: =B7-(SUM(C7:U7)) -> 7898.76
A8: ='Kwh Reading'!A8 -> 44291 | B8: =TOTAL!E6 -> 25850 | C8: =('Kwh Reading'!T9-'Kwh Reading'!T8)*1000 -> 570 | D8: =('Kwh Reading'!F9-'Kwh Reading'!F8)*1000000 -> 2800 | E8: =('Kwh Reading'!C9-'Kwh Reading'!C8)*1000 -> 260 | F8: =('Kwh Reading'!J9-'Kwh Reading'!J8)*1000 -> 460 | G8: =('Kwh Reading'!K9-'Kwh Reading'!K8)*1000 -> 500 | H8: =('Kwh Reading'!L9-'Kwh Reading'!L8)*1000 -> 290 | I8: =('Kwh Reading'!R9-'Kwh Reading'!R8)*1000 -> 320 | J8: =('Kwh Reading'!S9-'Kwh Reading'!S8)*1000 -> 130 | K8: =('Kwh Reading'!I9-'Kwh Reading'!I8)*1000 -> 340 | L8: =('Kwh Reading'!B9-'Kwh Reading'!B8)*1000 -> 1360 | M8: =('Kwh Reading'!M9-'Kwh Reading'!M8)*1000 -> 810 | N8: =('Kwh Reading'!H9-'Kwh Reading'!H8)*1000 -> 1090 | O8: =('Kwh Reading'!P9-'Kwh Reading'!P8)*1000 -> 1160 | P8: =('Kwh Reading'!G9-'Kwh Reading'!G8)*1000 -> 1040 | Q8: =('Kwh Reading'!Q9-'Kwh Reading'!Q8)*1000 -> 840 | R8: =('Kwh Reading'!N9-'Kwh Reading'!N8)*1000 -> 960 | S8: ='Kwh Reading'!E9-'Kwh Reading'!E8 -> 4008.57 | T8: ='Kwh Reading'!D9-'Kwh Reading'!D8 -> 2884.4 | U8: =('Kwh Reading'!O9-'Kwh Reading'!O8)*1000 -> 280 | V8: =B8-(SUM(C8:U8)) -> 5747.03
A9: ='Kwh Reading'!A9 -> 44292 | B9: =TOTAL!E7 -> 25300 | C9: =('Kwh Reading'!T10-'Kwh Reading'!T9)*1000 -> 570 | D9: =('Kwh Reading'!F10-'Kwh Reading'!F9)*1000000 -> 2500 | E9: =('Kwh Reading'!C10-'Kwh Reading'!C9)*1000 -> 240 | F9: =('Kwh Reading'!J10-'Kwh Reading'!J9)*1000 -> 320 | G9: =('Kwh Reading'!K10-'Kwh Reading'!K9)*1000 -> 380 | H9: =('Kwh Reading'!L10-'Kwh Reading'!L9)*1000 -> 240 | I9: =('Kwh Reading'!R10-'Kwh Reading'!R9)*1000 -> 330 | J9: =('Kwh Reading'!S10-'Kwh Reading'!S9)*1000 -> 120 | K9: =('Kwh Reading'!I10-'Kwh Reading'!I9)*1000 -> 310 | L9: =('Kwh Reading'!B10-'Kwh Reading'!B9)*1000 -> 1290 | M9: =('Kwh Reading'!M10-'Kwh Reading'!M9)*1000 -> 750 | N9: =('Kwh Reading'!H10-'Kwh Reading'!H9)*1000 -> 980 | O9: =('Kwh Reading'!P10-'Kwh Reading'!P9)*1000 -> 990 | P9: =('Kwh Reading'!G10-'Kwh Reading'!G9)*1000 -> 890 | Q9: =('Kwh Reading'!Q10-'Kwh Reading'!Q9)*1000 -> 790 | R9: =('Kwh Reading'!N10-'Kwh Reading'!N9)*1000 -> 810 | S9: ='Kwh Reading'!E10-'Kwh Reading'!E9 -> 3455.83 | T9: ='Kwh Reading'!D10-'Kwh Reading'!D9 -> 2344.05 | U9: =('Kwh Reading'!O10-'Kwh Reading'!O9)*1000 -> 230 | V9: =B9-(SUM(C9:U9)) -> 7760.12
A10: ='Kwh Reading'!A10 -> 44293 | B10: =TOTAL!E8 -> 20730 | C10: =('Kwh Reading'!T11-'Kwh Reading'!T10)*1000 -> 530 | D10: =('Kwh Reading'!F11-'Kwh Reading'!F10)*1000000 -> 2500 | E10: =('Kwh Reading'!C11-'Kwh Reading'!C10)*1000 -> 230 | F10: =('Kwh Reading'!J11-'Kwh Reading'!J10)*1000 -> 350 | G10: =('Kwh Reading'!K11-'Kwh Reading'!K10)*1000 -> 410 | H10: =('Kwh Reading'!L11-'Kwh Reading'!L10)*1000 -> 250 | I10: =('Kwh Reading'!R11-'Kwh Reading'!R10)*1000 -> 300 | J10: =('Kwh Reading'!S11-'Kwh Reading'!S10)*1000 -> 130 | K10: =('Kwh Reading'!I11-'Kwh Reading'!I10)*1000 -> 320 | L10: =('Kwh Reading'!B11-'Kwh Reading'!B10)*1000 -> 1360 | M10: =('Kwh Reading'!M11-'Kwh Reading'!M10)*1000 -> 840 | N10: =('Kwh Reading'!H11-'Kwh Reading'!H10)*1000 -> 1080 | O10: =('Kwh Reading'!P11-'Kwh Reading'!P10)*1000 -> 940 | P10: =('Kwh Reading'!G11-'Kwh Reading'!G10)*1000 -> 920 | Q10: =('Kwh Reading'!Q11-'Kwh Reading'!Q10)*1000 -> 920 | R10: =('Kwh Reading'!N11-'Kwh Reading'!N10)*1000 -> 680 | S10: ='Kwh Reading'!E11-'Kwh Reading'!E10 -> 3530.22 | T10: ='Kwh Reading'!D11-'Kwh Reading'!D10 -> 2620.14 | U10: =('Kwh Reading'!O11-'Kwh Reading'!O10)*1000 -> 260 | V10: =B10-(SUM(C10:U10)) -> 2559.64
A11: ='Kwh Reading'!A11 -> 44294 | B11: =TOTAL!E9 -> 24890 | C11: =('Kwh Reading'!T12-'Kwh Reading'!T11)*1000 -> 550 | D11: =('Kwh Reading'!F12-'Kwh Reading'!F11)*1000000 -> 2600 | E11: =('Kwh Reading'!C12-'Kwh Reading'!C11)*1000 -> 240 | F11: =('Kwh Reading'!J12-'Kwh Reading'!J11)*1000 -> 290 | G11: =('Kwh Reading'!K12-'Kwh Reading'!K11)*1000 -> 400 | H11: =('Kwh Reading'!L12-'Kwh Reading'!L11)*1000 -> 210 | I11: =('Kwh Reading'!R12-'Kwh Reading'!R11)*1000 -> 330 | J11: =('Kwh Reading'!S12-'Kwh Reading'!S11)*1000 -> 120 | K11: =('Kwh Reading'!I12-'Kwh Reading'!I11)*1000 -> 310 | L11: =('Kwh Reading'!B12-'Kwh Reading'!B11)*1000 -> 1370 | M11: =('Kwh Reading'!M12-'Kwh Reading'!M11)*1000 -> 910 | N11: =('Kwh Reading'!H12-'Kwh Reading'!H11)*1000 -> 1070 | O11: =('Kwh Reading'!P12-'Kwh Reading'!P11)*1000 -> 1040 | P11: =('Kwh Reading'!G12-'Kwh Reading'!G11)*1000 -> 950 | Q11: =('Kwh Reading'!Q12-'Kwh Reading'!Q11)*1000 -> 950 | R11: =('Kwh Reading'!N12-'Kwh Reading'!N11)*1000 -> 670 | S11: ='Kwh Reading'!E12-'Kwh Reading'!E11 -> 3529.09 | T11: ='Kwh Reading'!D12-'Kwh Reading'!D11 -> 2702.93 | U11: =('Kwh Reading'!O12-'Kwh Reading'!O11)*1000 -> 310 | V11: =B11-(SUM(C11:U11)) -> 6337.98
A12: ='Kwh Reading'!A12 -> 44295 | B12: =TOTAL!E10 -> 22380 | C12: =('Kwh Reading'!T13-'Kwh Reading'!T12)*1000 -> 260 | D12: =('Kwh Reading'!F13-'Kwh Reading'!F12)*1000000 -> 2500 | E12: =('Kwh Reading'!C13-'Kwh Reading'!C12)*1000 -> 230 | F12: =('Kwh Reading'!J13-'Kwh Reading'!J12)*1000 -> 330 | G12: =('Kwh Reading'!K13-'Kwh Reading'!K12)*1000 -> 320 | H12: =('Kwh Reading'!L13-'Kwh Reading'!L12)*1000 -> 230 | I12: =('Kwh Reading'!R13-'Kwh Reading'!R12)*1000 -> 330 | J12: =('Kwh Reading'!S13-'Kwh Reading'!S12)*1000 -> 130 | K12: =('Kwh Reading'!I13-'Kwh Reading'!I12)*1000 -> 330 | L12: =('Kwh Reading'!B13-'Kwh Reading'!B12)*1000 -> 1350 | M12: =('Kwh Reading'!M13-'Kwh Reading'!M12)*1000 -> 880 | N12: =('Kwh Reading'!H13-'Kwh Reading'!H12)*1000 -> 950 | O12: =('Kwh Reading'!P13-'Kwh Reading'!P12)*1000 -> 920 | P12: =('Kwh Reading'!G13-'Kwh Reading'!G12)*1000 -> 870 | Q12: =('Kwh Reading'!Q13-'Kwh Reading'!Q12)*1000 -> 710 | R12: =('Kwh Reading'!N13-'Kwh Reading'!N12)*1000 -> 590 | S12: ='Kwh Reading'!E13-'Kwh Reading'!E12 -> 2773.92 | T12: ='Kwh Reading'!D13-'Kwh Reading'!D12 -> 2435.68 | U12: =('Kwh Reading'!O13-'Kwh Reading'!O12)*1000 -> 270 | V12: =B12-(SUM(C12:U12)) -> 5970.4
A13: ='Kwh Reading'!A13 -> 44296 | B13: =TOTAL!E11 -> 24860 | C13: =('Kwh Reading'!T14-'Kwh Reading'!T13)*1000 -> 540 | D13: =('Kwh Reading'!F14-'Kwh Reading'!F13)*1000000 -> 2500 | E13: =('Kwh Reading'!C14-'Kwh Reading'!C13)*1000 -> 230 | F13: =('Kwh Reading'!J14-'Kwh Reading'!J13)*1000 -> 330 | G13: =('Kwh Reading'!K14-'Kwh Reading'!K13)*1000 -> 380 | H13: =('Kwh Reading'!L14-'Kwh Reading'!L13)*1000 -> 250 | I13: =('Kwh Reading'!R14-'Kwh Reading'!R13)*1000 -> 330 | J13: =('Kwh Reading'!S14-'Kwh Reading'!S13)*1000 -> 130 | K13: =('Kwh Reading'!I14-'Kwh Reading'!I13)*1000 -> 350 | L13: =('Kwh Reading'!B14-'Kwh Reading'!B13)*1000 -> 1460 | M13: =('Kwh Reading'!M14-'Kwh Reading'!M13)*1000 -> 920 | N13: =('Kwh Reading'!H14-'Kwh Reading'!H13)*1000 -> 1080 | O13: =('Kwh Reading'!P14-'Kwh Reading'!P13)*1000 -> 990 | P13: =('Kwh Reading'!G14-'Kwh Reading'!G13)*1000 -> 1040 | Q13: =('Kwh Reading'!Q14-'Kwh Reading'!Q13)*1000 -> 760 | R13: =('Kwh Reading'!N14-'Kwh Reading'!N13)*1000 -> 800 | S13: ='Kwh Reading'!E14-'Kwh Reading'!E13 -> 3358.85 | T13: ='Kwh Reading'!D14-'Kwh Reading'!D13 -> 2500.69 | U13: =('Kwh Reading'!O14-'Kwh Reading'!O13)*1000 -> 270 | V13: =B13-(SUM(C13:U13)) -> 6640.46
A14: ='Kwh Reading'!A14 -> 44297 | B14: =TOTAL!E12 -> 23700 | C14: =('Kwh Reading'!T15-'Kwh Reading'!T14)*1000 -> 480 | D14: =('Kwh Reading'!F15-'Kwh Reading'!F14)*1000000 -> 2300 | E14: =('Kwh Reading'!C15-'Kwh Reading'!C14)*1000 -> 200 | F14: =('Kwh Reading'!J15-'Kwh Reading'!J14)*1000 -> 250 | G14: =('Kwh Reading'!K15-'Kwh Reading'!K14)*1000 -> 270 | H14: =('Kwh Reading'!L15-'Kwh Reading'!L14)*1000 -> 180 | I14: =('Kwh Reading'!R15-'Kwh Reading'!R14)*1000 -> 280 | J14: =('Kwh Reading'!S15-'Kwh Reading'!S14)*1000 -> 130 | K14: =('Kwh Reading'!I15-'Kwh Reading'!I14)*1000 -> 340 | L14: =('Kwh Reading'!B15-'Kwh Reading'!B14)*1000 -> 1330 | M14: =('Kwh Reading'!M15-'Kwh Reading'!M14)*1000 -> 850 | N14: =('Kwh Reading'!H15-'Kwh Reading'!H14)*1000 -> 950 | O14: =('Kwh Reading'!P15-'Kwh Reading'!P14)*1000 -> 850 | P14: =('Kwh Reading'!G15-'Kwh Reading'!G14)*1000 -> 990 | Q14: =('Kwh Reading'!Q15-'Kwh Reading'!Q14)*1000 -> 750 | R14: =('Kwh Reading'!N15-'Kwh Reading'!N14)*1000 -> 870 | S14: ='Kwh Reading'!E15-'Kwh Reading'!E14 -> 2899.56 | T14: ='Kwh Reading'!D15-'Kwh Reading'!D14 -> 2422.45 | U14: =('Kwh Reading'!O15-'Kwh Reading'!O14)*1000 -> 240 | V14: =B14-(SUM(C14:U14)) -> 7117.99
A15: ='Kwh Reading'!A15 -> 44298 | B15: =TOTAL!E13 -> 23130 | C15: =('Kwh Reading'!T16-'Kwh Reading'!T15)*1000 -> 500 | D15: =('Kwh Reading'!F16-'Kwh Reading'!F15)*1000000 -> 2500 | E15: =('Kwh Reading'!C16-'Kwh Reading'!C15)*1000 -> 230 | F15: =('Kwh Reading'!J16-'Kwh Reading'!J15)*1000 -> 250 | G15: =('Kwh Reading'!K16-'Kwh Reading'!K15)*1000 -> 350 | H15: =('Kwh Reading'!L16-'Kwh Reading'!L15)*1000 -> 200 | I15: =('Kwh Reading'!R16-'Kwh Reading'!R15)*1000 -> 300 | J15: =('Kwh Reading'!S16-'Kwh Reading'!S15)*1000 -> 130 | K15: =('Kwh Reading'!I16-'Kwh Reading'!I15)*1000 -> 370 | L15: =('Kwh Reading'!B16-'Kwh Reading'!B15)*1000 -> 1390 | M15: =('Kwh Reading'!M16-'Kwh Reading'!M15)*1000 -> 770 | N15: =('Kwh Reading'!H16-'Kwh Reading'!H15)*1000 -> 940 | O15: =('Kwh Reading'!P16-'Kwh Reading'!P15)*1000 -> 950 | P15: =('Kwh Reading'!G16-'Kwh Reading'!G15)*1000 -> 950 | Q15: =('Kwh Reading'!Q16-'Kwh Reading'!Q15)*1000 -> 770 | R15: =('Kwh Reading'!N16-'Kwh Reading'!N15)*1000 -> 980 | S15: ='Kwh Reading'!E16-'Kwh Reading'!E15 -> 3020.22 | T15: ='Kwh Reading'!D16-'Kwh Reading'!D15 -> 2501.12 | U15: =('Kwh Reading'!O16-'Kwh Reading'!O15)*1000 -> 240 | V15: =B15-(SUM(C15:U15)) -> 5788.66
A16: ='Kwh Reading'!A16 -> 44299 | B16: =TOTAL!E14 -> 24080 | C16: =('Kwh Reading'!T17-'Kwh Reading'!T16)*1000 -> 490 | D16: =('Kwh Reading'!F17-'Kwh Reading'!F16)*1000000 -> 2200 | E16: =('Kwh Reading'!C17-'Kwh Reading'!C16)*1000 -> 240 | F16: =('Kwh Reading'!J17-'Kwh Reading'!J16)*1000 -> 160 | G16: =('Kwh Reading'!K17-'Kwh Reading'!K16)*1000 -> 280 | H16: =('Kwh Reading'!L17-'Kwh Reading'!L16)*1000 -> 180 | I16: =('Kwh Reading'!R17-'Kwh Reading'!R16)*1000 -> 250 | J16: =('Kwh Reading'!S17-'Kwh Reading'!S16)*1000 -> 140 | K16: =('Kwh Reading'!I17-'Kwh Reading'!I16)*1000 -> 330 | L16: =('Kwh Reading'!B17-'Kwh Reading'!B16)*1000 -> 1340 | M16: =('Kwh Reading'!M17-'Kwh Reading'!M16)*1000 -> 790 | N16: =('Kwh Reading'!H17-'Kwh Reading'!H16)*1000 -> 950 | O16: =('Kwh Reading'!P17-'Kwh Reading'!P16)*1000 -> 910 | P16: =('Kwh Reading'!G17-'Kwh Reading'!G16)*1000 -> 860 | Q16: =('Kwh Reading'!Q17-'Kwh Reading'!Q16)*1000 -> 720 | R16: =('Kwh Reading'!N17-'Kwh Reading'!N16)*1000 -> 880 | S16: ='Kwh Reading'!E17-'Kwh Reading'!E16 -> 3097.84 | T16: ='Kwh Reading'!D17-'Kwh Reading'!D16 -> 2289.84 | U16: =('Kwh Reading'!O17-'Kwh Reading'!O16)*1000 -> 220 | V16: =B16-(SUM(C16:U16)) -> 7752.32
... A34: ='Kwh Reading'!A34 -> 44317 | B34: =TOTAL!E32 -> 0 | C34: =('Kwh Reading'!T35-'Kwh Reading'!T34)*1000 -> 0 | D34: =('Kwh Reading'!F35-'Kwh Reading'!F34)*1000000 -> 0 | E34: =('Kwh Reading'!C35-'Kwh Reading'!C34)*1000 -> 0 | F34: =('Kwh Reading'!J35-'Kwh Reading'!J34)*1000 -> 0 | G34: =('Kwh Reading'!K35-'Kwh Reading'!K34)*1000 -> 0 | H34: =('Kwh Reading'!L35-'Kwh Reading'!L34)*1000 -> 0 | I34: =('Kwh Reading'!R35-'Kwh Reading'!R34)*1000 -> 0 | J34: =('Kwh Reading'!S35-'Kwh Reading'!S34)*1000 -> 0 | K34: =('Kwh Reading'!I35-'Kwh Reading'!I34)*1000 -> 0 | L34: =('Kwh Reading'!B35-'Kwh Reading'!B34)*1000 -> 0 | M34: =('Kwh Reading'!M35-'Kwh Reading'!M34)*1000 -> 0 | N34: =('Kwh Reading'!H35-'Kwh Reading'!H34)*1000 -> 0 | O34: =('Kwh Reading'!P35-'Kwh Reading'!P34)*1000 -> 0 | P34: =('Kwh Reading'!G35-'Kwh Reading'!G34)*1000 -> 0 | Q34: =('Kwh Reading'!Q35-'Kwh Reading'!Q34)*1000 -> 0 | R34: =('Kwh Reading'!N35-'Kwh Reading'!N34)*1000 -> 0 | S34: ='Kwh Reading'!E35-'Kwh Reading'!E34 -> 0 | T34: ='Kwh Reading'!D35-'Kwh Reading'!D34 -> 0 | U34: =('Kwh Reading'!O35-'Kwh Reading'!O34)*1000 -> 0 | V34: =B34-(SUM(C34:U34)) -> 0
A35: Total | B35: =SUM(B4:B34) -> 318750 | C35: =SUM(C4:C34) -> -378950 | D35: =SUM(D4:D34) -> -2158800 | E35: =SUM(E4:E34) -> -209570 | F35: =SUM(F4:F34) -> -298130 | G35: =SUM(G4:G34) -> -316490 | H35: =SUM(H4:H34) -> -216260 | I35: =SUM(I4:I34) -> -130520 | ... V35: =SUM(V4:V34) -> 23472831

Sheet Kwh area wise 
A2: Month | B2: Total KWH | C2: Reef Club Kitchen KWH | D2: Main Kitchen KWH | E2: Pastry Kitchen KWH | F2: Laundry KWH | G2: STP KWH | H2: Kuda Huraa Accomodation KWH | I2: Guest Room Beach Pavilion & Beach Bungalow KWH | J2: Guest Room Water Bungalow KWH | K2: Spa KWH | L2: Others KWH
A3: ='Kwh Reading'!A4 -> 44287 | B3: =TOTAL!E2 -> 25520 | C3: ='Kwh Consumption'!C4 -> 540 | D3: ='Kwh Consumption'!D4 -> 2600 | E3: ='Kwh Consumption'!E4 -> 250 | F3: =('Kwh Consumption'!F4+'Kwh Consumption'!G4+'Kwh Consumption'!H4) -> 1040 | G3: =('Kwh Consumption'!I4+'Kwh Consumption'!J4) -> 470 | H3: =('Kwh Consumption'!K4+'Kwh Consumption'!L4) -> 1590 | I3: =('Kwh Consumption'!M4+'Kwh Consumption'!N4+'Kwh Consumption'!O4+'Kwh Consumption'!P4+'Kwh Consumption'!Q4+'Kwh Consumption'!R4) -> 5410 | J3: =('Kwh Consumption'!S4+'Kwh Consumption'!T4) -> 6450.04 | K3: ='Kwh Consumption'!U4 -> 270 | L3: =B3-C3-D3-E3-F3-G3-H3-I3-J3-K3 -> 6899.96
A4: ='Kwh Reading'!A5 -> 44288 | B4: =TOTAL!E3 -> 25880 | C4: ='Kwh Consumption'!C5 -> 550 | D4: ='Kwh Consumption'!D5 -> 2600 | E4: ='Kwh Consumption'!E5 -> 250 | F4: =('Kwh Consumption'!F5+'Kwh Consumption'!G5+'Kwh Consumption'!H5) -> 1080 | G4: =('Kwh Consumption'!I5+'Kwh Consumption'!J5) -> 340 | H4: =('Kwh Consumption'!K5+'Kwh Consumption'!L5) -> 1710 | I4: =('Kwh Consumption'!M5+'Kwh Consumption'!N5+'Kwh Consumption'!O5+'Kwh Consumption'!P5+'Kwh Consumption'!Q5+'Kwh Consumption'!R5) -> 5740 | J4: =('Kwh Consumption'!S5+'Kwh Consumption'!T5) -> 6753 | K4: ='Kwh Consumption'!U5 -> 280 | L4: =B4-C4-D4-E4-F4-G4-H4-I4-J4-K4 -> 6577
A5: ='Kwh Reading'!A6 -> 44289 | B5: =TOTAL!E4 -> 25550 | C5: ='Kwh Consumption'!C6 -> 620 | D5: ='Kwh Consumption'!D6 -> 2800 | E5: ='Kwh Consumption'!E6 -> 270 | F5: =('Kwh Consumption'!F6+'Kwh Consumption'!G6+'Kwh Consumption'!H6) -> 1230 | G5: =('Kwh Consumption'!I6+'Kwh Consumption'!J6) -> 360 | H5: =('Kwh Consumption'!K6+'Kwh Consumption'!L6) -> 1640 | I5: =('Kwh Consumption'!M6+'Kwh Consumption'!N6+'Kwh Consumption'!O6+'Kwh Consumption'!P6+'Kwh Consumption'!Q6+'Kwh Consumption'!R6) -> 5610 | J5: =('Kwh Consumption'!S6+'Kwh Consumption'!T6) -> 6612.29 | K5: ='Kwh Consumption'!U6 -> 290 | L5: =B5-C5-D5-E5-F5-G5-H5-I5-J5-K5 -> 6117.71
A6: ='Kwh Reading'!A7 -> 44290 | B6: =TOTAL!E5 -> 26880 | C6: ='Kwh Consumption'!C7 -> 570 | D6: ='Kwh Consumption'!D7 -> 2500 | E6: ='Kwh Consumption'!E7 -> 220 | F6: =('Kwh Consumption'!F7+'Kwh Consumption'!G7+'Kwh Consumption'!H7) -> 1030 | G6: =('Kwh Consumption'!I7+'Kwh Consumption'!J7) -> 460 | H6: =('Kwh Consumption'!K7+'Kwh Consumption'!L7) -> 1560 | I6: =('Kwh Consumption'!M7+'Kwh Consumption'!N7+'Kwh Consumption'!O7+'Kwh Consumption'!P7+'Kwh Consumption'!Q7+'Kwh Consumption'!R7) -> 5610 | J6: =('Kwh Consumption'!S7+'Kwh Consumption'!T7) -> 6791.24 | K6: ='Kwh Consumption'!U7 -> 240 | L6: =B6-C6-D6-E6-F6-G6-H6-I6-J6-K6 -> 7898.76
A7: ='Kwh Reading'!A8 -> 44291 | B7: =TOTAL!E6 -> 25850 | C7: ='Kwh Consumption'!C8 -> 570 | D7: ='Kwh Consumption'!D8 -> 2800 | E7: ='Kwh Consumption'!E8 -> 260 | F7: =('Kwh Consumption'!F8+'Kwh Consumption'!G8+'Kwh Consumption'!H8) -> 1250 | G7: =('Kwh Consumption'!I8+'Kwh Consumption'!J8) -> 450 | H7: =('Kwh Consumption'!K8+'Kwh Consumption'!L8) -> 1700 | I7: =('Kwh Consumption'!M8+'Kwh Consumption'!N8+'Kwh Consumption'!O8+'Kwh Consumption'!P8+'Kwh Consumption'!Q8+'Kwh Consumption'!R8) -> 5900 | J7: =('Kwh Consumption'!S8+'Kwh Consumption'!T8) -> 6892.97 | K7: ='Kwh Consumption'!U8 -> 280 | L7: =B7-C7-D7-E7-F7-G7-H7-I7-J7-K7 -> 5747.03
A8: ='Kwh Reading'!A9 -> 44292 | B8: =TOTAL!E7 -> 25300 | C8: ='Kwh Consumption'!C9 -> 570 | D8: ='Kwh Consumption'!D9 -> 2500 | E8: ='Kwh Consumption'!E9 -> 240 | F8: =('Kwh Consumption'!F9+'Kwh Consumption'!G9+'Kwh Consumption'!H9) -> 940 | G8: =('Kwh Consumption'!I9+'Kwh Consumption'!J9) -> 450 | H8: =('Kwh Consumption'!K9+'Kwh Consumption'!L9) -> 1600 | I8: =('Kwh Consumption'!M9+'Kwh Consumption'!N9+'Kwh Consumption'!O9+'Kwh Consumption'!P9+'Kwh Consumption'!Q9+'Kwh Consumption'!R9) -> 5210 | J8: =('Kwh Consumption'!S9+'Kwh Consumption'!T9) -> 5799.88 | K8: ='Kwh Consumption'!U9 -> 230 | L8: =B8-C8-D8-E8-F8-G8-H8-I8-J8-K8 -> 7760.12
A9: ='Kwh Reading'!A10 -> 44293 | B9: =TOTAL!E8 -> 20730 | C9: ='Kwh Consumption'!C10 -> 530 | D9: ='Kwh Consumption'!D10 -> 2500 | E9: ='Kwh Consumption'!E10 -> 230 | F9: =('Kwh Consumption'!F10+'Kwh Consumption'!G10+'Kwh Consumption'!H10) -> 1010 | G9: =('Kwh Consumption'!I10+'Kwh Consumption'!J10) -> 430 | H9: =('Kwh Consumption'!K10+'Kwh Consumption'!L10) -> 1680 | I9: =('Kwh Consumption'!M10+'Kwh Consumption'!N10+'Kwh Consumption'!O10+'Kwh Consumption'!P10+'Kwh Consumption'!Q10+'Kwh Consumption'!R10) -> 5380 | J9: =('Kwh Consumption'!S10+'Kwh Consumption'!T10) -> 6150.36 | K9: ='Kwh Consumption'!U10 -> 260 | L9: =B9-C9-D9-E9-F9-G9-H9-I9-J9-K9 -> 2559.64
A10: ='Kwh Reading'!A11 -> 44294 | B10: =TOTAL!E9 -> 24890 | C10: ='Kwh Consumption'!C11 -> 550 | D10: ='Kwh Consumption'!D11 -> 2600 | E10: ='Kwh Consumption'!E11 -> 240 | F10: =('Kwh Consumption'!F11+'Kwh Consumption'!G11+'Kwh Consumption'!H11) -> 900 | G10: =('Kwh Consumption'!I11+'Kwh Consumption'!J11) -> 450 | H10: =('Kwh Consumption'!K11+'Kwh Consumption'!L11) -> 1680 | I10: =('Kwh Consumption'!M11+'Kwh Consumption'!N11+'Kwh Consumption'!O11+'Kwh Consumption'!P11+'Kwh Consumption'!Q11+'Kwh Consumption'!R11) -> 5590 | J10: =('Kwh Consumption'!S11+'Kwh Consumption'!T11) -> 6232.02 | K10: ='Kwh Consumption'!U11 -> 310 | L10: =B10-C10-D10-E10-F10-G10-H10-I10-J10-K10 -> 6337.98
A11: ='Kwh Reading'!A12 -> 44295 | B11: =TOTAL!E10 -> 22380 | C11: ='Kwh Consumption'!C12 -> 260 | D11: ='Kwh Consumption'!D12 -> 2500 | E11: ='Kwh Consumption'!E12 -> 230 | F11: =('Kwh Consumption'!F12+'Kwh Consumption'!G12+'Kwh Consumption'!H12) -> 880 | G11: =('Kwh Consumption'!I12+'Kwh Consumption'!J12) -> 460 | H11: =('Kwh Consumption'!K12+'Kwh Consumption'!L12) -> 1680 | I11: =('Kwh Consumption'!M12+'Kwh Consumption'!N12+'Kwh Consumption'!O12+'Kwh Consumption'!P12+'Kwh Consumption'!Q12+'Kwh Consumption'!R12) -> 4920 | J11: =('Kwh Consumption'!S12+'Kwh Consumption'!T12) -> 5209.6 | K11: ='Kwh Consumption'!U12 -> 270 | L11: =B11-C11-D11-E11-F11-G11-H11-I11-J11-K11 -> 5970.4
A12: ='Kwh Reading'!A13 -> 44296 | B12: =TOTAL!E11 -> 24860 | C12: ='Kwh Consumption'!C13 -> 540 | D12: ='Kwh Consumption'!D13 -> 2500 | E12: ='Kwh Consumption'!E13 -> 230 | F12: =('Kwh Consumption'!F13+'Kwh Consumption'!G13+'Kwh Consumption'!H13) -> 960 | G12: =('Kwh Consumption'!I13+'Kwh Consumption'!J13) -> 460 | H12: =('Kwh Consumption'!K13+'Kwh Consumption'!L13) -> 1810 | I12: =('Kwh Consumption'!M13+'Kwh Consumption'!N13+'Kwh Consumption'!O13+'Kwh Consumption'!P13+'Kwh Consumption'!Q13+'Kwh Consumption'!R13) -> 5590 | J12: =('Kwh Consumption'!S13+'Kwh Consumption'!T13) -> 5859.54 | K12: ='Kwh Consumption'!U13 -> 270 | L12: =B12-C12-D12-E12-F12-G12-H12-I12-J12-K12 -> 6640.46
A13: ='Kwh Reading'!A14 -> 44297 | B13: =TOTAL!E12 -> 23700 | C13: ='Kwh Consumption'!C14 -> 480 | D13: ='Kwh Consumption'!D14 -> 2300 | E13: ='Kwh Consumption'!E14 -> 200 | F13: =('Kwh Consumption'!F14+'Kwh Consumption'!G14+'Kwh Consumption'!H14) -> 700 | G13: =('Kwh Consumption'!I14+'Kwh Consumption'!J14) -> 410 | H13: =('Kwh Consumption'!K14+'Kwh Consumption'!L14) -> 1670 | I13: =('Kwh Consumption'!M14+'Kwh Consumption'!N14+'Kwh Consumption'!O14+'Kwh Consumption'!P14+'Kwh Consumption'!Q14+'Kwh Consumption'!R14) -> 5260 | J13: =('Kwh Consumption'!S14+'Kwh Consumption'!T14) -> 5322.01 | K13: ='Kwh Consumption'!U14 -> 240 | L13: =B13-C13-D13-E13-F13-G13-H13-I13-J13-K13 -> 7117.99
A14: ='Kwh Reading'!A15 -> 44298 | B14: =TOTAL!E13 -> 23130 | C14: ='Kwh Consumption'!C15 -> 500 | D14: ='Kwh Consumption'!D15 -> 2500 | E14: ='Kwh Consumption'!E15 -> 230 | F14: =('Kwh Consumption'!F15+'Kwh Consumption'!G15+'Kwh Consumption'!H15) -> 800 | G14: =('Kwh Consumption'!I15+'Kwh Consumption'!J15) -> 430 | H14: =('Kwh Consumption'!K15+'Kwh Consumption'!L15) -> 1760 | I14: =('Kwh Consumption'!M15+'Kwh Consumption'!N15+'Kwh Consumption'!O15+'Kwh Consumption'!P15+'Kwh Consumption'!Q15+'Kwh Consumption'!R15) -> 5360 | J14: =('Kwh Consumption'!S15+'Kwh Consumption'!T15) -> 5521.34 | K14: ='Kwh Consumption'!U15 -> 240 | L14: =B14-C14-D14-E14-F14-G14-H14-I14-J14-K14 -> 5788.66
... A33: ='Kwh Reading'!A34 -> 44317 | B33: =TOTAL!E32 -> 0 | C33: ='Kwh Consumption'!C34 -> 0 | D33: ='Kwh Consumption'!D34 -> 0 | E33: ='Kwh Consumption'!E34 -> 0 | F33: =('Kwh Consumption'!F34+'Kwh Consumption'!G34+'Kwh Consumption'!H34) -> 0 | G33: =('Kwh Consumption'!I34+'Kwh Consumption'!J34) -> 0 | H33: =('Kwh Consumption'!K34+'Kwh Consumption'!L34) -> 0 | I33: =('Kwh Consumption'!M34+'Kwh Consumption'!N34+'Kwh Consumption'!O34+'Kwh Consumption'!P34+'Kwh Consumption'!Q34+'Kwh Consumption'!R34) -> 0 | J33: =('Kwh Consumption'!S34+'Kwh Consumption'!T34) -> 0 | K33: ='Kwh Consumption'!U34 -> 0 | L33: =B33-C33-D33-E33-F33-G33-H33-I33-J33-K33 -> 0
A34: Total kwh | B34: =SUM(B3:B33) -> 318750 | C34: =SUM(C3:C33) -> -378950 | D34: =SUM(D3:D33) -> -2158800 | E34: =SUM(E3:E33) -> -209570 | F34: =SUM(F3:F33) -> -830880 | G34: =SUM(G3:G33) -> -233850 | H34: =SUM(H3:H33) -> -1066940 | I34: =SUM(I3:I33) -> -2987970 | ... L34: =SUM(L3:L33) -> 23472831 | M34: =C34+D34+E34+F34+G34+H34+I34+J34+K34+L34 -> 318750
A36: Total $ | B36: =TOTAL!F2 -> 0.14 | C36: =C34*B36 -> -53053 | D36: =D34*B36 -> -302232 | E36: =E34*B36 -> -29339.8 | F36: =F34*B36 -> -116323.2 | G36: =G34*B36 -> -32739 | H36: =H34*B36 -> -149371.6 | I36: =I34*B36 -> -418315.8 | J36: =J34*B36 -> -2122187.4 | K36: =K34*B36 -> -18009.6 | L36: =L34*B36 -> 3286196.4 | M36: =C36+D36+E36+F36+G36+H36+I36+J36+K36+L36 -> 44625

Sheet  Kwh area wise $ 
A2: Month | B2: $ /Per KWH | C2: Total $ | D2: Reef Club $ | E2: Kitchen $ | F2: Pastry $ | G2: Laundry $ | H2: STP $ | I2: Kuda Huraa Accomodation $ | J2: Guest Room Beach Pavilion & Beach Bungalow $ | K2: Guest Room Water Bungalow $ | L2: Spa $ | M2: Others $
A3: ='Kwh Reading'!A4 -> 44287 | B3: =TOTAL!F2 -> 0.14 | C3: ='Kwh Consumption'!B4*' Kwh area wise $ '!B3 -> 3572.8 | D3: ='Kwh Consumption'!C4*' Kwh area wise $ '!B3 -> 75.6 | E3: ='Kwh Consumption'!D4*' Kwh area wise $ '!B3 -> 364 | F3: ='Kwh Consumption'!E4*' Kwh area wise $ '!B3 -> 35 | G3: =('Kwh Consumption'!F4+'Kwh Consumption'!G4+'Kwh Consumption'!H4)*' Kwh area wise $ '!B3 -> 145.6 | H3: =('Kwh Consumption'!I4+'Kwh Consumption'!J4)*' Kwh area wise $ '!B3 -> 65.8 | I3: =('Kwh Consumption'!K4+'Kwh Consumption'!L4)*' Kwh area wise $ '!B3 -> 222.6 | J3: =('Kwh Consumption'!M4+'Kwh Consumption'!N4+'Kwh Consumption'!O4+'Kwh Consumption'!P4+'Kwh Consumption'!Q4+'Kwh Consumption'!R4)*' Kwh area wise $ '!B3 -> 757.4 | K3: =('Kwh Consumption'!S4+'Kwh Consumption'!T4)*' Kwh area wise $ '!B3 -> 903.0056 | L3: ='Kwh Consumption'!U4*' Kwh area wise $ '!B3 -> 37.8 | M3: ='Kwh Consumption'!V4*' Kwh area wise $ '!B3 -> 965.9944
A4: ='Kwh Reading'!A5 -> 44288 | B4: =TOTAL!F3 -> 0.14 | C4: ='Kwh Consumption'!B5*' Kwh area wise $ '!B4 -> 3623.2 | D4: ='Kwh Consumption'!C5*' Kwh area wise $ '!B4 -> 77 | E4: ='Kwh Consumption'!D5*' Kwh area wise $ '!B4 -> 364 | F4: ='Kwh Consumption'!E5*' Kwh area wise $ '!B4 -> 35 | G4: =('Kwh Consumption'!F5+'Kwh Consumption'!G5+'Kwh Consumption'!H5)*' Kwh area wise $ '!B4 -> 151.2 | H4: =('Kwh Consumption'!I5+'Kwh Consumption'!J5)*' Kwh area wise $ '!B4 -> 47.6 | I4: =('Kwh Consumption'!K5+'Kwh Consumption'!L5)*' Kwh area wise $ '!B4 -> 239.4 | J4: =('Kwh Consumption'!M5+'Kwh Consumption'!N5+'Kwh Consumption'!O5+'Kwh Consumption'!P5+'Kwh Consumption'!Q5+'Kwh Consumption'!R5)*' Kwh area wise $ '!B4 -> 803.6 | K4: =('Kwh Consumption'!S5+'Kwh Consumption'!T5)*' Kwh area wise $ '!B4 -> 945.42 | L4: ='Kwh Consumption'!U5*' Kwh area wise $ '!B4 -> 39.2 | M4: ='Kwh Consumption'!V5*' Kwh area wise $ '!B4 -> 920.78
A5: ='Kwh Reading'!A6 -> 44289 | B5: =TOTAL!F4 -> 0.14 | C5: ='Kwh Consumption'!B6*' Kwh area wise $ '!B5 -> 3577 | D5: ='Kwh Consumption'!C6*' Kwh area wise $ '!B5 -> 86.8 | E5: ='Kwh Consumption'!D6*' Kwh area wise $ '!B5 -> 392 | F5: ='Kwh Consumption'!E6*' Kwh area wise $ '!B5 -> 37.8 | G5: =('Kwh Consumption'!F6+'Kwh Consumption'!G6+'Kwh Consumption'!H6)*' Kwh area wise $ '!B5 -> 172.2 | H5: =('Kwh Consumption'!I6+'Kwh Consumption'!J6)*' Kwh area wise $ '!B5 -> 50.4 | I5: =('Kwh Consumption'!K6+'Kwh Consumption'!L6)*' Kwh area wise $ '!B5 -> 229.6 | J5: =('Kwh Consumption'!M6+'Kwh Consumption'!N6+'Kwh Consumption'!O6+'Kwh Consumption'!P6+'Kwh Consumption'!Q6+'Kwh Consumption'!R6)*' Kwh area wise $ '!B5 -> 785.4 | K5: =('Kwh Consumption'!S6+'Kwh Consumption'!T6)*' Kwh area wise $ '!B5 -> 925.7206 | L5: ='Kwh Consumption'!U6*' Kwh area wise $ '!B5 -> 40.6 | M5: ='Kwh Consumption'!V6*' Kwh area wise $ '!B5 -> 856.4794
A6: ='Kwh Reading'!A7 -> 44290 | B6: =TOTAL!F5 -> 0.14 | C6: ='Kwh Consumption'!B7*' Kwh area wise $ '!B6 -> 3763.2 | D6: ='Kwh Consumption'!C7*' Kwh area wise $ '!B6 -> 79.8 | E6: ='Kwh Consumption'!D7*' Kwh area wise $ '!B6 -> 350 | F6: ='Kwh Consumption'!E7*' Kwh area wise $ '!B6 -> 30.8 | G6: =('Kwh Consumption'!F7+'Kwh Consumption'!G7+'Kwh Consumption'!H7)*' Kwh area wise $ '!B6 -> 144.2 | H6: =('Kwh Consumption'!I7+'Kwh Consumption'!J7)*' Kwh area wise $ '!B6 -> 64.4 | I6: =('Kwh Consumption'!K7+'Kwh Consumption'!L7)*' Kwh area wise $ '!B6 -> 218.4 | J6: =('Kwh Consumption'!M7+'Kwh Consumption'!N7+'Kwh Consumption'!O7+'Kwh Consumption'!P7+'Kwh Consumption'!Q7+'Kwh Consumption'!R7)*' Kwh area wise $ '!B6 -> 785.4 | K6: =('Kwh Consumption'!S7+'Kwh Consumption'!T7)*' Kwh area wise $ '!B6 -> 950.7736 | L6: ='Kwh Consumption'!U7*' Kwh area wise $ '!B6 -> 33.6 | M6: ='Kwh Consumption'!V7*' Kwh area wise $ '!B6 -> 1105.8264
A7: ='Kwh Reading'!A8 -> 44291 | B7: =TOTAL!F6 -> 0.14 | C7: ='Kwh Consumption'!B8*' Kwh area wise $ '!B7 -> 3619 | D7: ='Kwh Consumption'!C8*' Kwh area wise $ '!B7 -> 79.8 | E7: ='Kwh Consumption'!D8*' Kwh area wise $ '!B7 -> 392 | F7: ='Kwh Consumption'!E8*' Kwh area wise $ '!B7 -> 36.4 | G7: =('Kwh Consumption'!F8+'Kwh Consumption'!G8+'Kwh Consumption'!H8)*' Kwh area wise $ '!B7 -> 175 | H7: =('Kwh Consumption'!I8+'Kwh Consumption'!J8)*' Kwh area wise $ '!B7 -> 63 | I7: =('Kwh Consumption'!K8+'Kwh Consumption'!L8)*' Kwh area wise $ '!B7 -> 238 | J7: =('Kwh Consumption'!M8+'Kwh Consumption'!N8+'Kwh Consumption'!O8+'Kwh Consumption'!P8+'Kwh Consumption'!Q8+'Kwh Consumption'!R8)*' Kwh area wise $ '!B7 -> 826 | K7: =('Kwh Consumption'!S8+'Kwh Consumption'!T8)*' Kwh area wise $ '!B7 -> 965.0158 | L7: ='Kwh Consumption'!U8*' Kwh area wise $ '!B7 -> 39.2 | M7: ='Kwh Consumption'!V8*' Kwh area wise $ '!B7 -> 804.5842
A8: ='Kwh Reading'!A9 -> 44292 | B8: =TOTAL!F7 -> 0.14 | C8: ='Kwh Consumption'!B9*' Kwh area wise $ '!B8 -> 3542 | D8: ='Kwh Consumption'!C9*' Kwh area wise $ '!B8 -> 79.8 | E8: ='Kwh Consumption'!D9*' Kwh area wise $ '!B8 -> 350 | F8: ='Kwh Consumption'!E9*' Kwh area wise $ '!B8 -> 33.6 | G8: =('Kwh Consumption'!F9+'Kwh Consumption'!G9+'Kwh Consumption'!H9)*' Kwh area wise $ '!B8 -> 131.6 | H8: =('Kwh Consumption'!I9+'Kwh Consumption'!J9)*' Kwh area wise $ '!B8 -> 63 | I8: =('Kwh Consumption'!K9+'Kwh Consumption'!L9)*' Kwh area wise $ '!B8 -> 224 | J8: =('Kwh Consumption'!M9+'Kwh Consumption'!N9+'Kwh Consumption'!O9+'Kwh Consumption'!P9+'Kwh Consumption'!Q9+'Kwh Consumption'!R9)*' Kwh area wise $ '!B8 -> 729.4 | K8: =('Kwh Consumption'!S9+'Kwh Consumption'!T9)*' Kwh area wise $ '!B8 -> 811.9832 | L8: ='Kwh Consumption'!U9*' Kwh area wise $ '!B8 -> 32.2 | M8: ='Kwh Consumption'!V9*' Kwh area wise $ '!B8 -> 1086.4168
A9: ='Kwh Reading'!A10 -> 44293 | B9: =TOTAL!F8 -> 0.14 | C9: ='Kwh Consumption'!B10*' Kwh area wise $ '!B9 -> 2902.2 | D9: ='Kwh Consumption'!C10*' Kwh area wise $ '!B9 -> 74.2 | E9: ='Kwh Consumption'!D10*' Kwh area wise $ '!B9 -> 350 | F9: ='Kwh Consumption'!E10*' Kwh area wise $ '!B9 -> 32.2 | G9: =('Kwh Consumption'!F10+'Kwh Consumption'!G10+'Kwh Consumption'!H10)*' Kwh area wise $ '!B9 -> 141.4 | H9: =('Kwh Consumption'!I10+'Kwh Consumption'!J10)*' Kwh area wise $ '!B9 -> 60.2 | I9: =('Kwh Consumption'!K10+'Kwh Consumption'!L10)*' Kwh area wise $ '!B9 -> 235.2 | J9: =('Kwh Consumption'!M10+'Kwh Consumption'!N10+'Kwh Consumption'!O10+'Kwh Consumption'!P10+'Kwh Consumption'!Q10+'Kwh Consumption'!R10)*' Kwh area wise $ '!B9 -> 753.2 | K9: =('Kwh Consumption'!S10+'Kwh Consumption'!T10)*' Kwh area wise $ '!B9 -> 861.0504 | L9: ='Kwh Consumption'!U10*' Kwh area wise $ '!B9 -> 36.4 | M9: ='Kwh Consumption'!V10*' Kwh area wise $ '!B9 -> 358.3496
A10: ='Kwh Reading'!A11 -> 44294 | B10: =TOTAL!F9 -> 0.14 | C10: ='Kwh Consumption'!B11*' Kwh area wise $ '!B10 -> 3484.6 | D10: ='Kwh Consumption'!C11*' Kwh area wise $ '!B10 -> 77 | E10: ='Kwh Consumption'!D11*' Kwh area wise $ '!B10 -> 364 | F10: ='Kwh Consumption'!E11*' Kwh area wise $ '!B10 -> 33.6 | G10: =('Kwh Consumption'!F11+'Kwh Consumption'!G11+'Kwh Consumption'!H11)*' Kwh area wise $ '!B10 -> 126 | H10: =('Kwh Consumption'!I11+'Kwh Consumption'!J11)*' Kwh area wise $ '!B10 -> 63 | I10: =('Kwh Consumption'!K11+'Kwh Consumption'!L11)*' Kwh area wise $ '!B10 -> 235.2 | J10: =('Kwh Consumption'!M11+'Kwh Consumption'!N11+'Kwh Consumption'!O11+'Kwh Consumption'!P11+'Kwh Consumption'!Q11+'Kwh Consumption'!R11)*' Kwh area wise $ '!B10 -> 782.6 | K10: =('Kwh Consumption'!S11+'Kwh Consumption'!T11)*' Kwh area wise $ '!B10 -> 872.4828 | L10: ='Kwh Consumption'!U11*' Kwh area wise $ '!B10 -> 43.4 | M10: ='Kwh Consumption'!V11*' Kwh area wise $ '!B10 -> 887.3172
A11: ='Kwh Reading'!A12 -> 44295 | B11: =TOTAL!F10 -> 0.14 | C11: ='Kwh Consumption'!B12*' Kwh area wise $ '!B11 -> 3133.2 | D11: ='Kwh Consumption'!C12*' Kwh area wise $ '!B11 -> 36.4 | E11: ='Kwh Consumption'!D12*' Kwh area wise $ '!B11 -> 350 | F11: ='Kwh Consumption'!E12*' Kwh area wise $ '!B11 -> 32.2 | G11: =('Kwh Consumption'!F12+'Kwh Consumption'!G12+'Kwh Consumption'!H12)*' Kwh area wise $ '!B11 -> 123.2 | H11: =('Kwh Consumption'!I12+'Kwh Consumption'!J12)*' Kwh area wise $ '!B11 -> 64.4 | I11: =('Kwh Consumption'!K12+'Kwh Consumption'!L12)*' Kwh area wise $ '!B11 -> 235.2 | J11: =('Kwh Consumption'!M12+'Kwh Consumption'!N12+'Kwh Consumption'!O12+'Kwh Consumption'!P12+'Kwh Consumption'!Q12+'Kwh Consumption'!R12)*' Kwh area wise $ '!B11 -> 688.8 | K11: =('Kwh Consumption'!S12+'Kwh Consumption'!T12)*' Kwh area wise $ '!B11 -> 729.344 | L11: ='Kwh Consumption'!U12*' Kwh area wise $ '!B11 -> 37.8 | M11: ='Kwh Consumption'!V12*' Kwh area wise $ '!B11 -> 835.856
A12: ='Kwh Reading'!A13 -> 44296 | B12: =TOTAL!F11 -> 0.14 | C12: ='Kwh Consumption'!B13*' Kwh area wise $ '!B12 -> 3480.4 | D12: ='Kwh Consumption'!C13*' Kwh area wise $ '!B12 -> 75.6 | E12: ='Kwh Consumption'!D13*' Kwh area wise $ '!B12 -> 350 | F12: ='Kwh Consumption'!E13*' Kwh area wise $ '!B12 -> 32.2 | G12: =('Kwh Consumption'!F13+'Kwh Consumption'!G13+'Kwh Consumption'!H13)*' Kwh area wise $ '!B12 -> 134.4 | H12: =('Kwh Consumption'!I13+'Kwh Consumption'!J13)*' Kwh area wise $ '!B12 -> 64.4 | I12: =('Kwh Consumption'!K13+'Kwh Consumption'!L13)*' Kwh area wise $ '!B12 -> 253.4 | J12: =('Kwh Consumption'!M13+'Kwh Consumption'!N13+'Kwh Consumption'!O13+'Kwh Consumption'!P13+'Kwh Consumption'!Q13+'Kwh Consumption'!R13)*' Kwh area wise $ '!B12 -> 782.6 | K12: =('Kwh Consumption'!S13+'Kwh Consumption'!T13)*' Kwh area wise $ '!B12 -> 820.3356 | L12: ='Kwh Consumption'!U13*' Kwh area wise $ '!B12 -> 37.8 | M12: ='Kwh Consumption'!V13*' Kwh area wise $ '!B12 -> 929.6644
A13: ='Kwh Reading'!A14 -> 44297 | B13: =TOTAL!F12 -> 0.14 | C13: ='Kwh Consumption'!B14*' Kwh area wise $ '!B13 -> 3318 | D13: ='Kwh Consumption'!C14*' Kwh area wise $ '!B13 -> 67.2 | E13: ='Kwh Consumption'!D14*' Kwh area wise $ '!B13 -> 322 | F13: ='Kwh Consumption'!E14*' Kwh area wise $ '!B13 -> 28 | G13: =('Kwh Consumption'!F14+'Kwh Consumption'!G14+'Kwh Consumption'!H14)*' Kwh area wise $ '!B13 -> 98 | H13: =('Kwh Consumption'!I14+'Kwh Consumption'!J14)*' Kwh area wise $ '!B13 -> 57.4 | I13: =('Kwh Consumption'!K14+'Kwh Consumption'!L14)*' Kwh area wise $ '!B13 -> 233.8 | J13: =('Kwh Consumption'!M14+'Kwh Consumption'!N14+'Kwh Consumption'!O14+'Kwh Consumption'!P14+'Kwh Consumption'!Q14+'Kwh Consumption'!R14)*' Kwh area wise $ '!B13 -> 736.4 | K13: =('Kwh Consumption'!S14+'Kwh Consumption'!T14)*' Kwh area wise $ '!B13 -> 745.0814 | L13: ='Kwh Consumption'!U14*' Kwh area wise $ '!B13 -> 33.6 | M13: ='Kwh Consumption'!V14*' Kwh area wise $ '!B13 -> 996.5186
A14: ='Kwh Reading'!A15 -> 44298 | B14: =TOTAL!F13 -> 0.14 | C14: ='Kwh Consumption'!B15*' Kwh area wise $ '!B14 -> 3238.2 | D14: ='Kwh Consumption'!C15*' Kwh area wise $ '!B14 -> 70 | E14: ='Kwh Consumption'!D15*' Kwh area wise $ '!B14 -> 350 | F14: ='Kwh Consumption'!E15*' Kwh area wise $ '!B14 -> 32.2 | G14: =('Kwh Consumption'!F15+'Kwh Consumption'!G15+'Kwh Consumption'!H15)*' Kwh area wise $ '!B14 -> 112 | H14: =('Kwh Consumption'!I15+'Kwh Consumption'!J15)*' Kwh area wise $ '!B14 -> 60.2 | I14: =('Kwh Consumption'!K15+'Kwh Consumption'!L15)*' Kwh area wise $ '!B14 -> 246.4 | J14: =('Kwh Consumption'!M15+'Kwh Consumption'!N15+'Kwh Consumption'!O15+'Kwh Consumption'!P15+'Kwh Consumption'!Q15+'Kwh Consumption'!R15)*' Kwh area wise $ '!B14 -> 750.4 | K14: =('Kwh Consumption'!S15+'Kwh Consumption'!T15)*' Kwh area wise $ '!B14 -> 772.9876 | L14: ='Kwh Consumption'!U15*' Kwh area wise $ '!B14 -> 33.6 | M14: ='Kwh Consumption'!V15*' Kwh area wise $ '!B14 -> 810.4124
... A33: ='Kwh Reading'!A34 -> 44317 | B33: =TOTAL!F32 -> 0.14 | C33: ='Kwh Consumption'!B34*' Kwh area wise $ '!B33 -> 0 | D33: ='Kwh Consumption'!C34*' Kwh area wise $ '!B33 -> 0 | E33: ='Kwh Consumption'!D34*' Kwh area wise $ '!B33 -> 0 | F33: ='Kwh Consumption'!E34*' Kwh area wise $ '!B33 -> 0 | G33: =('Kwh Consumption'!F34+'Kwh Consumption'!G34+'Kwh Consumption'!H34)*' Kwh area wise $ '!B33 -> 0 | H33: =('Kwh Consumption'!I34+'Kwh Consumption'!J34)*' Kwh area wise $ '!B33 -> 0 | I33: =('Kwh Consumption'!K34+'Kwh Consumption'!L34)*' Kwh area wise $ '!B33 -> 0 | J33: =('Kwh Consumption'!M34+'Kwh Consumption'!N34+'Kwh Consumption'!O34+'Kwh Consumption'!P34+'Kwh Consumption'!Q34+'Kwh Consumption'!R34)*' Kwh area wise $ '!B33 -> 0 | K33: =('Kwh Consumption'!S34+'Kwh Consumption'!T34)*' Kwh area wise $ '!B33 -> 0 | L33: ='Kwh Consumption'!U34*' Kwh area wise $ '!B33 -> 0 | M33: ='Kwh Consumption'!V34*' Kwh area wise $ '!B33 -> 0
A34: Total | C34: =SUM(C3:C33) -> 44625 | D34: =SUM(D3:D33) -> -53053 | E34: =SUM(E3:E33) -> -302232 | F34: =SUM(F3:F33) -> -29339.8 | G34: =SUM(G3:G33) -> -116323.2 | H34: =SUM(H3:H33) -> -32739 | I34: =SUM(I3:I33) -> -149371.6 | J34: =SUM(J3:J33) -> -418315.8 | ... M34: =SUM(M3:M33) -> 3286196.4 | N34: =D34+E34+F34+G34+H34+I34+J34+K34+L34+M34 -> 44625

Sheet Water Reading
B1: Meter 1 | C1: Meter 2 | D1: Meter 6 | E1: Meter 8 | F1: Meter 7 | G1: Meter 9 | H1: Meter 3 | I1: Meter 5 | J1: Meter 10 | K1: Meter 13 | L1: Meter 16 | M1: Meter 17 | N1: Meter 15 | O1: Meter 14 | P1: Meter 4 | Q1: Meter 11 | R1: Meter 12
A2: Date | B2: Main Meter 1 | C2: Main Meter 2 | D2: Beach Bunglow | E2: Kuda Huraa staff | F2: Bodu hura staff | G2: Laundry | H2: Water Bunglow | I2: Main Kitchen | J2: Second stage | K2: Supply jetty | L2: Staff housing A | M2: Staff housing B | N2: Spa | O2: Staff jetty | P2: Main pool | Q2: Reef club pool | R2: Reef club kitchen
A3: 44287 | B3: 150806 | C3: 108815 | D3: 195982 | E3: 242368 | F3: 66868 | G3: 110066 | H3: 48022 | I3: 59209 | J3: 19008 | K3: 1024 | L3: 16640 | M3: 22889 | N3: 6642 | O3: 1592 | P3: 26141 | Q3: 297 | R3: 5832
A4: 44288 | B4: 150946 | C4: 109025 | D4: 196125 | E4: 242429 | F4: 66868 | G4: 110092 | H4: 48062 | I4: 59254 | J4: 19018 | K4: 1024 | L4: 16648 | M4: 22903 | N4: 6845 | O4: 1592 | P4: 26141 | Q4: 299 | R4: 5838
A5: 44289 | B5: 151094 | C5: 109249 | D5: 196281 | E5: 242492 | F5: 66868 | G5: 110119 | H5: 48105 | I5: 59303 | J5: 19030 | K5: 1024 | L5: 16656 | M5: 22917 | N5: 6848 | O5: 1594 | P5: 26141 | Q5: 304 | R5: 5845
A6: 44290 | B6: 151263 | C6: 109508 | D6: 196482 | E6: 242552 | F6: 66868 | G6: 110150 | H6: 48154 | I6: 59362 | J6: 19041 | K6: 1024 | L6: 16664 | M6: 22929 | N6: 6850 | O6: 1595 | P6: 26141 | Q6: 305 | R6: 5851
A7: 44291 | B7: 151446 | C7: 109807 | D7: 196691 | E7: 242624 | F7: 66868 | G7: 110180 | H7: 48208 | I7: 59460 | J7: 19054 | K7: 1024 | L7: 16672 | M7: 22942 | N7: 6851 | O7: 1595 | P7: 26177 | Q7: 309.1 | R7: 5862
A8: 44292 | B8: 151611 | C8: 110074 | D8: 196896 | E8: 242687 | F8: 66868 | G8: 110208 | H8: 48260 | I8: 59526 | J8: 19066 | K8: 1024 | L8: 16678 | M8: 22954 | N8: 6854 | O8: 1597 | P8: 26182 | Q8: 313 | R8: 5869
A9: 44293 | B9: 151727 | C9: 110272 | D9: 196985 | E9: 242747 | F9: 66868 | G9: 110232 | H9: 48304 | I9: 59603 | J9: 19078 | K9: 1024 | L9: 16685 | M9: 22978 | N9: 6857 | O9: 1598 | P9: 26197 | Q9: 317 | R9: 5877
A10: 44294 | B10: 151865 | C10: 110497 | D10: 197120 | E10: 242813 | F10: 66869 | G10: 110257 | H10: 48358 | I10: 59674 | J10: 19089 | K10: 1024 | L10: 16693 | M10: 22984 | N10: 6661 | O10: 1601 | P10: 26205 | Q10: 323 | R10: 5885
A11: 44295 | B11: 152004 | C11: 110716 | D11: 197248 | E11: 242876 | F11: 66870 | G11: 110280 | H11: 48401 | I11: 59747 | J11: 19100 | K11: 1024 | L11: 16700 | M11: 22697 | N11: 6865 | O11: 1602 | P11: 26211 | Q11: 327 | R11: 5890
A12: 44296 | B12: 152192 | C12: 111001 | D12: 197468 | E12: 242941 | F12: 66871 | G12: 110305 | H12: 48463 | I12: 59824 | J12: 19113 | K12: 1024 | L12: 16708 | M12: 23010 | N12: 6867 | O12: 1603 | P12: 26214 | Q12: 329 | R12: 5891
A13: 44297 | B13: 152328 | C13: 111221 | D13: 197616 | E13: 243002 | F13: 66871 | G13: 110325 | H13: 48505 | I13: 59897 | J13: 19126 | K13: 1024 | L13: 16715 | M13: 23024 | N13: 6869 | O13: 1603 | P13: 26219 | Q13: 335 | R13: 5896
A14: 44298 | B14: 152450 | C14: 111422 | D14: 197725 | E14: 243061 | F14: 66872 | G14: 110342 | H14: 48549 | I14: 59972 | J14: 19140 | K14: 1024 | L14: 16723 | M14: 23037 | N14: 6871 | O14: 1603 | P14: 26234 | Q14: 339 | R14: 5900
... A16: 44300 | B16: 152830 | C16: 111873 | D16: 197979 | E16: 243204 | F16: 66874 | G16: 110378 | H16: 48631 | I16: 60184 | J16: 19161 | K16: 1024 | L16: 16738 | M16: 23068 | N16: 6878 | O16: 1603 | P16: 26289 | Q16: 347 | R16: 5909
A17: 44301
A18: 44302
A19: 44303
A20: 44304
A21: 44305
A22: 44306
A23: 44307
A24: 44308
A25: 44309
A26: 44310
A27: 44311
A28: 44312
... A33: 44317

Sheet Water consumption
A2: Date | B2: RO production (Ro 1 : 4) | C2: Total Consumption M3 (Meter 1 : 2) | E2: Water Bunglow | G2: Beach bunglow | I2: Main Pool | K2: Main kitchen | M2: Reef club kitchen | O2: Reef club pool | Q2: Bodu Huraa staff | S2: Kuda Huraa staff | U2: Laundry | W2: Second stage | Y2: Total
C3: M3 | D3: % of Total production | E3: M3 | F3: % | G3: M3 | H3: % | I3: M3 | J3: % | K3: M3 | L3: % | M3: M3 | N3: % | O3: M3 | P3: % | Q3: M3 | R3: % | S3: M3 | T3: % | U3: M3 | V3: % | W3: M3 | X3: % | Y3: M3 | Z3: %
A4: ='Water Reading'!A3 -> 44287 | B4: 469 | C4: =('Water Reading'!B4-'Water Reading'!B3)+('Water Reading'!C4-'Water Reading'!C3) -> 350 | D4: =C4/B4 -> 0.74626866 | E4: ='Water Reading'!H4-'Water Reading'!H3 -> 40 | F4: =E4/C4 -> 0.11428571 | G4: =('Water Reading'!D4-'Water Reading'!D3)-('Water Reading'!R4-'Water Reading'!R3)-('Water Reading'!Q4-'Water Reading'!Q3) -> 135 | H4: =G4/C4 -> 0.38571429 | I4: ='Water Reading'!P4-'Water Reading'!P3 -> 0 | J4: =I4/C4 -> 0 | K4: =('Water Reading'!I4-'Water Reading'!I3) -> 45 | L4: =K4/C4 -> 0.12857143 | M4: ='Water Reading'!R4-'Water Reading'!R3 -> 6 | N4: =M4/C4 -> 0.017142857 | O4: ='Water Reading'!Q4-'Water Reading'!Q3 -> 2 | P4: =O4/C4 -> 0.0057142857 | Q4: ='Water Reading'!F4-'Water Reading'!F3 -> 0 | R4: =Q4/C4 -> 0 | S4: ='Water Reading'!E4-'Water Reading'!E3 -> 61 | T4: =S4/C4 -> 0.17428571 | U4: ='Water Reading'!G4-'Water Reading'!G3 -> 26 | V4: =U4/C4 -> 0.074285714 | W4: ='Water Reading'!J4-'Water Reading'!J3 -> 10 | X4: =W4/C4 -> 0.028571429 | Y4: =E4+I4+K4+M4+O4+G4+Q4+S4+U4+W4 -> 325 | Z4: =Y4/B4 -> 0.69296375
A5: ='Water Reading'!A4 -> 44288 | B5: =TOTAL!I3 -> 296 | C5: =('Water Reading'!B5-'Water Reading'!B4)+('Water Reading'!C5-'Water Reading'!C4) -> 372 | D5: =C5/B5 -> 1.2567568 | E5: ='Water Reading'!H5-'Water Reading'!H4 -> 43 | F5: =E5/C5 -> 0.1155914 | G5: =('Water Reading'!D5-'Water Reading'!D4)-('Water Reading'!R5-'Water Reading'!R4)-('Water Reading'!Q5-'Water Reading'!Q4) -> 144 | H5: =G5/C5 -> 0.38709677 | I5: ='Water Reading'!P5-'Water Reading'!P4 -> 0 | J5: =I5/C5 -> 0 | K5: =('Water Reading'!I5-'Water Reading'!I4) -> 49 | L5: =K5/C5 -> 0.13172043 | M5: ='Water Reading'!R5-'Water Reading'!R4 -> 7 | N5: =M5/C5 -> 0.018817204 | O5: ='Water Reading'!Q5-'Water Reading'!Q4 -> 5 | P5: =O5/C5 -> 0.01344086 | Q5: ='Water Reading'!F5-'Water Reading'!F4 -> 0 | R5: =Q5/C5 -> 0 | S5: ='Water Reading'!E5-'Water Reading'!E4 -> 63 | T5: =S5/C5 -> 0.16935484 | U5: ='Water Reading'!G5-'Water Reading'!G4 -> 27 | V5: =U5/C5 -> 0.072580645 | W5: ='Water Reading'!J5-'Water Reading'!J4 -> 12 | X5: =W5/C5 -> 0.032258065 | Y5: =E5+I5+K5+M5+O5+G5+Q5+S5+U5+W5 -> 350 | Z5: =Y5/B5 -> 1.1824324
A6: ='Water Reading'!A5 -> 44289 | B6: =TOTAL!I4 -> 381 | C6: =('Water Reading'!B6-'Water Reading'!B5)+('Water Reading'!C6-'Water Reading'!C5) -> 428 | D6: =C6/B6 -> 1.1233596 | E6: ='Water Reading'!H6-'Water Reading'!H5 -> 49 | F6: =E6/C6 -> 0.11448598 | G6: =('Water Reading'!D6-'Water Reading'!D5)-('Water Reading'!R6-'Water Reading'!R5)-('Water Reading'!Q6-'Water Reading'!Q5) -> 194 | H6: =G6/C6 -> 0.45327103 | I6: ='Water Reading'!P6-'Water Reading'!P5 -> 0 | J6: =I6/C6 -> 0 | K6: =('Water Reading'!I6-'Water Reading'!I5) -> 59 | L6: =K6/C6 -> 0.13785047 | M6: ='Water Reading'!R6-'Water Reading'!R5 -> 6 | N6: =M6/C6 -> 0.014018692 | O6: ='Water Reading'!Q6-'Water Reading'!Q5 -> 1 | P6: =O6/C6 -> 0.0023364486 | Q6: ='Water Reading'!F6-'Water Reading'!F5 -> 0 | R6: =Q6/C6 -> 0 | S6: ='Water Reading'!E6-'Water Reading'!E5 -> 60 | T6: =S6/C6 -> 0.14018692 | U6: ='Water Reading'!G6-'Water Reading'!G5 -> 31 | V6: =U6/C6 -> 0.072429907 | W6: ='Water Reading'!J6-'Water Reading'!J5 -> 11 | X6: =W6/C6 -> 0.025700935 | Y6: =E6+I6+K6+M6+O6+G6+Q6+S6+U6+W6 -> 411 | Z6: =Y6/B6 -> 1.0787402
A7: ='Water Reading'!A6 -> 44290 | B7: =TOTAL!I5 -> 370 | C7: =('Water Reading'!B7-'Water Reading'!B6)+('Water Reading'!C7-'Water Reading'!C6) -> 482 | D7: =C7/B7 -> 1.3027027 | E7: ='Water Reading'!H7-'Water Reading'!H6 -> 54 | F7: =E7/C7 -> 0.1120332 | G7: =('Water Reading'!D7-'Water Reading'!D6)-('Water Reading'!R7-'Water Reading'!R6)-('Water Reading'!Q7-'Water Reading'!Q6) -> 193.9 | H7: =G7/C7 -> 0.40228216 | I7: ='Water Reading'!P7-'Water Reading'!P6 -> 36 | J7: =I7/C7 -> 0.074688797 | K7: =('Water Reading'!I7-'Water Reading'!I6)-I7 -> 62 | L7: =K7/C7 -> 0.12863071 | M7: ='Water Reading'!R7-'Water Reading'!R6 -> 11 | N7: =M7/C7 -> 0.022821577 | O7: ='Water Reading'!Q7-'Water Reading'!Q6 -> 4.1 | P7: =O7/C7 -> 0.0085062241 | Q7: ='Water Reading'!F7-'Water Reading'!F6 -> 0 | R7: =Q7/C7 -> 0 | S7: ='Water Reading'!E7-'Water Reading'!E6 -> 72 | T7: =S7/C7 -> 0.14937759 | U7: ='Water Reading'!G7-'Water Reading'!G6 -> 30 | V7: =U7/C7 -> 0.062240664 | W7: ='Water Reading'!J7-'Water Reading'!J6 -> 13 | X7: =W7/C7 -> 0.026970954 | Y7: =E7+I7+K7+M7+O7+G7+Q7+S7+U7+W7 -> 476 | Z7: =Y7/B7 -> 1.2864865
A8: ='Water Reading'!A7 -> 44291 | B8: =TOTAL!I6 -> 350 | C8: =('Water Reading'!B8-'Water Reading'!B7)+('Water Reading'!C8-'Water Reading'!C7) -> 432 | D8: =C8/B8 -> 1.2342857 | E8: ='Water Reading'!H8-'Water Reading'!H7 -> 52 | F8: =E8/C8 -> 0.12037037 | G8: =('Water Reading'!D8-'Water Reading'!D7)-('Water Reading'!R8-'Water Reading'!R7)-('Water Reading'!Q8-'Water Reading'!Q7) -> 194.1 | H8: =G8/C8 -> 0.44930556 | I8: ='Water Reading'!P8-'Water Reading'!P7 -> 5 | J8: =I8/C8 -> 0.011574074 | K8: =('Water Reading'!I8-'Water Reading'!I7)-I8 -> 61 | L8: =K8/C8 -> 0.1412037 | M8: ='Water Reading'!R8-'Water Reading'!R7 -> 7 | N8: =M8/C8 -> 0.016203704 | O8: ='Water Reading'!Q8-'Water Reading'!Q7 -> 3.9 | P8: =O8/C8 -> 0.0090277778 | Q8: ='Water Reading'!F8-'Water Reading'!F7 -> 0 | R8: =Q8/C8 -> 0 | S8: ='Water Reading'!E8-'Water Reading'!E7 -> 63 | T8: =S8/C8 -> 0.14583333 | U8: ='Water Reading'!G8-'Water Reading'!G7 -> 28 | V8: =U8/C8 -> 0.064814815 | W8: ='Water Reading'!J8-'Water Reading'!J7 -> 12 | X8: =W8/C8 -> 0.027777778 | Y8: =E8+I8+K8+M8+O8+G8+Q8+S8+U8+W8 -> 426 | Z8: =Y8/B8 -> 1.2171429
