Workbook

Sheet Total
A1: Site Name | B1: Day | C1: Month | D1: Year | E1: Total Electricity Kwh | F1: Electricity Tariff ($/Kwh) | G1: Total Fuel Oil (Liters) | H1: Fuel Oil $/Liter | I1: LPG (Kg) | J1: LPG $/Kg | K1: Water Utility Supply (m3) m3 | L1: Water Utility Supply (m3) $/m3 | M1: Irrigation Water (m3) m3 | N1: Irrigation water $/m3 | O1: Room Nights
A2: Beirut | B2: 1 | C2: 4 | D2: 2021 | E2: =ELEC!N3 -> 10627 | F2: =SUM('EDl log'!T4) -> 0.15397996 | G2: =-tanks!AW6 -> 359 | H2: =SUM(tanks!AV6) -> 0.96 | I2: =('B5'!AU5)*0.51 -> 0 | J2: ='B5'!AX5/0.51 -> 1.5686275 | K2: =WATER!I6 -> 0 | L2: =SUM(WATER!J6) -> 0 | M2: =WATER!Q6 -> 0 | N2: 0.6 | O2: =ELEC!B3 -> 0
A3: Beirut | B3: =B2+1 -> 2 | C3: 4 | D3: 2021 | E3: =ELEC!N4 -> 8566 | F3: =SUM('EDl log'!T5) -> 0.36446978 | G3: =-tanks!AW7 -> 298 | H3: =SUM(tanks!AV7) -> 0.96 | I3: =('B5'!AU6)*0.51 -> 0 | J3: ='B5'!AX6/0.51 -> 1.5686275 | K3: =WATER!I7 -> 0 | L3: =SUM(WATER!J7) -> 0 | M3: =WATER!Q7 -> 0 | N3: 0.6 | O3: =ELEC!B4 -> 0
A4: Beirut | B4: =B3+1 -> 3 | C4: 4 | D4: 2021 | E4: =ELEC!N5 -> 9686 | F4: =SUM('EDl log'!T6) -> 0.3283817 | G4: =-tanks!AW8 -> 287 | H4: =SUM(tanks!AV8) -> 0.96 | I4: =('B5'!AU7)*0.51 -> 0 | J4: ='B5'!AX7/0.51 -> 1.5686275 | K4: =WATER!I8 -> 0 | L4: =SUM(WATER!J8) -> 0 | M4: =WATER!Q8 -> 0 | N4: 0.6 | O4: =ELEC!B5 -> 0
A5: Beirut | B5: =B4+1 -> 4 | C5: 4 | D5: 2021 | E5: =ELEC!N6 -> 9198 | F5: =SUM('EDl log'!T7) -> 0.34102969 | G5: =-tanks!AW9 -> 290 | H5: =SUM(tanks!AV9) -> 0.96 | I5: =('B5'!AU8)*0.51 -> 0 | J5: ='B5'!AX8/0.51 -> 1.5686275 | K5: =WATER!I9 -> 54 | L5: =SUM(WATER!J9) -> 4.6296296 | M5: =WATER!Q9 -> 0 | N5: 0.6 | O5: =ELEC!B6 -> 0
A6: Beirut | B6: =B5+1 -> 5 | C6: 4 | D6: 2021 | E6: =ELEC!N7 -> 9569 | F6: =SUM('EDl log'!T8) -> 0.26208634 | G6: =-tanks!AW10 -> 404 | H6: =SUM(tanks!AV10) -> 0.96 | I6: =('B5'!AU9)*0.51 -> 0 | J6: ='B5'!AX9/0.51 -> 1.5686275 | K6: =WATER!I10 -> 100 | L6: =SUM(WATER!J10) -> 2.5 | M6: =WATER!Q10 -> 0 | N6: 0.6 | O6: =ELEC!B7 -> 0
A7: Beirut | B7: =B6+1 -> 6 | C7: 4 | D7: 2021 | E7: =ELEC!N8 -> 10832 | F7: =SUM('EDl log'!T9) -> 0.29715327 | G7: =-tanks!AW11 -> 308 | H7: =SUM(tanks!AV11) -> 0.96 | I7: =('B5'!AU10)*0.51 -> 0 | J7: ='B5'!AX10/0.51 -> 1.5686275 | K7: =WATER!I11 -> 0 | L7: =SUM(WATER!J11) -> 0 | M7: =WATER!Q11 -> 0 | N7: 0.6 | O7: =ELEC!B8 -> 0
A8: Beirut | B8: =B7+1 -> 7 | C8: 4 | D8: 2021 | E8: =ELEC!N9 -> 8792 | F8: =SUM('EDl log'!T10) -> -0.032783652 | G8: =-tanks!AW12 -> 287 | H8: =SUM(tanks!AV12) -> 0.96 | I8: =('B5'!AU11)*0.51 -> 0 | J8: ='B5'!AX11/0.51 -> 1.5686275 | K8: =WATER!I12 -> 28 | L8: =SUM(WATER!J12) -> 8.9285714 | M8: =WATER!Q12 -> 0 | N8: 0.6 | O8: =ELEC!B9 -> 0
A9: Beirut | B9: =B8+1 -> 8 | C9: 4 | D9: 2021 | E9: =ELEC!N10 -> 8207 | F9: =SUM('EDl log'!T11) -> 0.2129289 | G9: =-tanks!AW13 -> 416 | H9: =SUM(tanks!AV13) -> 0.96 | I9: =('B5'!AU12)*0.51 -> 0 | J9: ='B5'!AX12/0.51 -> 1.5686275 | K9: =WATER!I13 -> 0 | L9: =SUM(WATER!J13) -> 0 | M9: =WATER!Q13 -> 0 | N9: 0.6 | O9: =ELEC!B10 -> 0
A10: Beirut | B10: =B9+1 -> 9 | C10: 4 | D10: 2021 | E10: =ELEC!N11 -> 7584 | F10: =SUM('EDl log'!T12) -> 0.19166069 | G10: =-tanks!AW14 -> 326 | H10: =SUM(tanks!AV14) -> 0.96 | I10: =('B5'!AU13)*0.51 -> 0 | J10: ='B5'!AX13/0.51 -> 1.5686275 | K10: =WATER!I14 -> 211 | L10: =SUM(WATER!J14) -> 1.1848341 | M10: =WATER!Q14 -> 0 | N10: 0.6 | O10: =ELEC!B11 -> 0
A11: Beirut | B11: =B10+1 -> 10 | C11: 4 | D11: 2021 | E11: =ELEC!N12 -> 6883 | F11: =SUM('EDl log'!T13) -> 0.23950285 | G11: =-tanks!AW15 -> 409 | H11: =SUM(tanks!AV15) -> 0.96 | I11: =('B5'!AU14)*0.51 -> 0 | J11: ='B5'!AX14/0.51 -> 1.5686275 | K11: =WATER!I15 -> 0 | L11: =SUM(WATER!J15) -> 0 | M11: =WATER!Q15 -> 0 | N11: 0.6 | O11: =ELEC!B12 -> 0
A12: Beirut | B12: =B11+1 -> 11 | C12: 4 | D12: 2021 | E12: =ELEC!N13 -> 6760.8 | F12: =SUM('EDl log'!T14) -> 0.17657196 | G12: =-tanks!AW16 -> 368 | H12: =SUM(tanks!AV16) -> 0.96 | I12: =('B5'!AU15)*0.51 -> 0 | J12: ='B5'!AX15/0.51 -> 1.5686275 | K12: =WATER!I16 -> 5 | L12: =SUM(WATER!J16) -> 50 | M12: =WATER!Q16 -> 0 | N12: 0.6 | O12: =ELEC!B13 -> 0
A13: Beirut | B13: =B12+1 -> 12 | C13: 4 | D13: 2021 | E13: =ELEC!N14 -> 7293.2 | F13: =SUM('EDl log'!T15) -> 0.26227485 | G13: =-tanks!AW17 -> 367 | H13: =SUM(tanks!AV17) -> 0.96 | I13: =('B5'!AU16)*0.51 -> 0 | J13: ='B5'!AX16/0.51 -> 1.5686275 | K13: =WATER!I17 -> 0 | L13: =SUM(WATER!J17) -> 0 | M13: =WATER!Q17 -> 0 | N13: 0.6 | O13: =ELEC!B14 -> 0
A14: Beirut | B14: =B13+1 -> 13 | C14: 4 | D14: 2021 | E14: =ELEC!N15 -> 6843 | F14: =SUM('EDl log'!T16) -> 0.24010536 | G14: =-tanks!AW18 -> 113 | H14: =SUM(tanks!AV18) -> 0.96 | I14: =('B5'!AU17)*0.51 -> 0 | J14: ='B5'!AX17/0.51 -> 1.5686275 | K14: =WATER!I18 -> 0 | L14: =SUM(WATER!J18) -> 0 | M14: =WATER!Q18 -> 0 | N14: 0.6 | O14: =ELEC!B15 -> 0
... A31: Beirut | B31: =B30+1 -> 30 | C31: 4 | D31: 2021 | E31: =ELEC!N32 -> 0 | F31: =SUM('EDl log'!T33) -> 0 | G31: =-tanks!AW35 -> 0 | H31: =SUM(tanks!AV35) -> 0.93 | I31: =('B5'!AU34)*0.51 -> 0 | J31: ='B5'!AX34/0.51 -> 1.5686275 | K31: =WATER!I35 -> 0 | L31: =SUM(WATER!J35) -> 0 | M31: =WATER!Q35 -> 0 | N31: 0.6 | O31: =ELEC!B32 -> 0

Sheet Submetering
A1: Site Name | B1: Day | C1: Month | D1: Year | E1: ATS1 Kwh | F1: ATS2 Kwh | G1: ATS3 Kwh | H1: ATS4 Kwh | I1: ATS5 Kwh | J1: Guest (m3) | K1: Kitchen & Laundry (m3) | L1: Room Nights
A2: Beirut | B2: 1 | C2: 4 | D2: 2021 | E2: =ELEC!M3 -> 4066 | F2: =ELEC!K3 -> 1692 | G2: =ELEC!I3 -> 1006 | H2: =ELEC!E3 -> 3148 | I2: =ELEC!G3 -> 715 | J2: =WATER!Y6 -> 0 | K2: =WATER!AJ6 -> 0 | L2: =ELEC!B3 -> 0
A3: Beirut | B3: =B2+1 -> 2 | C3: 4 | D3: 2021 | E3: =ELEC!M4 -> 2420 | F3: =ELEC!K4 -> 1836 | G3: =ELEC!I4 -> 838 | H3: =ELEC!E4 -> 2912 | I3: =ELEC!G4 -> 560 | J3: =WATER!Y7 -> 64 | K3: =WATER!AJ7 -> 20 | L3: =ELEC!B4 -> 0
A4: Beirut | B4: =B3+1 -> 3 | C4: 4 | D4: 2021 | E4: =ELEC!M5 -> 2272 | F4: =ELEC!K5 -> 2844 | G4: =ELEC!I5 -> 838 | H4: =ELEC!E5 -> 3110 | I4: =ELEC!G5 -> 622 | J4: =WATER!Y8 -> 0 | K4: =WATER!AJ8 -> 0 | L4: =ELEC!B5 -> 0
A5: Beirut | B5: =B4+1 -> 4 | C5: 4 | D5: 2021 | E5: =ELEC!M6 -> 2340 | F5: =ELEC!K6 -> 1680 | G5: =ELEC!I6 -> 1054 | H5: =ELEC!E6 -> 3590 | I5: =ELEC!G6 -> 534 | J5: =WATER!Y9 -> 0 | K5: =WATER!AJ9 -> 0 | L5: =ELEC!B6 -> 0
A6: Beirut | B6: =B5+1 -> 5 | C6: 4 | D6: 2021 | E6: =ELEC!M7 -> 2120 | F6: =ELEC!K7 -> 2528 | G6: =ELEC!I7 -> 944 | H6: =ELEC!E7 -> 3232 | I6: =ELEC!G7 -> 745 | J6: =WATER!Y10 -> 12 | K6: =WATER!AJ10 -> 4 | L6: =ELEC!B7 -> 0
A7: Beirut | B7: =B6+1 -> 6 | C7: 4 | D7: 2021 | E7: =ELEC!M8 -> 2152 | F7: =ELEC!K8 -> 2220 | G7: =ELEC!I8 -> 938 | H7: =ELEC!E8 -> 4856 | I7: =ELEC!G8 -> 666 | J7: =WATER!Y11 -> 0 | K7: =WATER!AJ11 -> 0 | L7: =ELEC!B8 -> 0
A8: Beirut | B8: =B7+1 -> 7 | C8: 4 | D8: 2021 | E8: =ELEC!M9 -> 1656 | F8: =ELEC!K9 -> 1678 | G8: =ELEC!I9 -> 898 | H8: =ELEC!E9 -> 3864 | I8: =ELEC!G9 -> 696 | J8: =WATER!Y12 -> 0 | K8: =WATER!AJ12 -> 2 | L8: =ELEC!B9 -> 0
A9: Beirut | B9: =B8+1 -> 8 | C9: 4 | D9: 2021 | E9: =ELEC!M10 -> 1662 | F9: =ELEC!K10 -> 2522 | G9: =ELEC!I10 -> 870 | H9: =ELEC!E10 -> 2382 | I9: =ELEC!G10 -> 771 | J9: =WATER!Y13 -> 102 | K9: =WATER!AJ13 -> 37 | L9: =ELEC!B10 -> 0
A10: Beirut | B10: =B9+1 -> 9 | C10: 4 | D10: 2021 | E10: =ELEC!M11 -> 1656 | F10: =ELEC!K11 -> 1358 | G10: =ELEC!I11 -> 918 | H10: =ELEC!E11 -> 2910 | I10: =ELEC!G11 -> 742 | J10: =WATER!Y14 -> 0 | K10: =WATER!AJ14 -> 0 | L10: =ELEC!B11 -> 0
A11: Beirut | B11: =B10+1 -> 10 | C11: 4 | D11: 2021 | E11: =ELEC!M12 -> 1918 | F11: =ELEC!K12 -> 1238 | G11: =ELEC!I12 -> 936 | H11: =ELEC!E12 -> 2068 | I11: =ELEC!G12 -> 723 | J11: =WATER!Y15 -> 0 | K11: =WATER!AJ15 -> 0 | L11: =ELEC!B12 -> 0
A12: Beirut | B12: =B11+1 -> 11 | C12: 4 | D12: 2021 | E12: =ELEC!M13 -> 1688 | F12: =ELEC!K13 -> 1249 | G12: =ELEC!I13 -> 848 | H12: =ELEC!E13 -> 2320 | I12: =ELEC!G13 -> 655.8 | J12: =WATER!Y16 -> 0 | K12: =WATER!AJ16 -> 0 | L12: =ELEC!B13 -> 0
A13: Beirut | B13: =B12+1 -> 12 | C13: 4 | D13: 2021 | E13: =ELEC!M14 -> 1608 | F13: =ELEC!K14 -> 1323 | G13: =ELEC!I14 -> 802 | H13: =ELEC!E14 -> 2920 | I13: =ELEC!G14 -> 640.2 | J13: =WATER!Y17 -> 0 | K13: =WATER!AJ17 -> 0 | L13: =ELEC!B14 -> 0
A14: Beirut | B14: =B13+1 -> 13 | C14: 4 | D14: 2021 | E14: =ELEC!M15 -> 1576 | F14: =ELEC!K15 -> 1280 | G14: =ELEC!I15 -> 794 | H14: =ELEC!E15 -> 2584 | I14: =ELEC!G15 -> 609 | J14: =WATER!Y18 -> 0 | K14: =WATER!AJ18 -> 0 | L14: =ELEC!B15 -> 0
... A31: Beirut | B31: =B30+1 -> 30 | C31: 4 | D31: 2021 | E31: =ELEC!M32 -> 0 | F31: =ELEC!K32 -> 0 | G31: =ELEC!I32 -> 0 | H31: =ELEC!E32 -> 0 | I31: =ELEC!G32 -> 0 | J31: =WATER!Y35 -> 0 | K31: =WATER!AJ35 -> 0 | L31: =ELEC!B32 -> 0
D46: .

Sheet ELEC
A1: OOC | B1: Room OCC | D1: MDB3 | E1: MDB3/day | F1: EMDB2 | G1: EMDB2/day | H1: EMDB1 | I1: EMDB1/day | J1: MDB2 | K1: mdb2/day | L1: MDB1 | M1: MDB1/Day | N1: Total KWH | O1: KWH/Rooc | P1: Gen MHW | Q1: Gen/Day KWH | R1: EDL KWH | S1: CH1 RH | T1: RH | U1: C1h1 power | V1: CH1 Con KWH | W1: CH2 RH | X1: RH | Y1: Ch2 power | Z1: CH2 Con KWH | AA1: CH3 RH | AB1: RH | AC1: Ch3 power | AD1: CH3 Con KWH | AE1: RH total | AF1: KWH total | AG1: AVG chiller KW/Hr
A2: =[1]ELEC!A30 -> 0 | B2: =[2]ELEC!B33 -> 0 | C2: 44286 | D2: =[3]ELEC!D33 -> 32737038 | E2: =[3]ELEC!E33 -> 3610 | F2: =[3]ELEC!F33 -> 3990693 | G2: =[3]ELEC!G33 -> 632 | H2: =[3]ELEC!H33 -> 17830854 | I2: =[3]ELEC!I33 -> 974 | J2: =[3]ELEC!J33 -> 28959514 | K2: =[3]ELEC!K33 -> 1686 | ... AL2: =[3]ELEC!AL33 -> 0 | AM2: =[1]ELEC!AM30 -> 0 | AN2: =[1]ELEC!AN30 -> 0 | AO2: =[1]ELEC!AO30 -> 0 | AP2: =[1]ELEC!AP30 -> 0 | AQ2: =[1]ELEC!AQ30 -> 0 | AR2: =[1]ELEC!AR30 -> 0 | AS2: =[1]ELEC!AS30 -> 0 | AT2: =[1]ELEC!AT30 -> 0 | ... CZ2: =[1]ELEC!CZ30 -> 0 | DA2: =[2]ELEC!DA33 -> 0 | DB2: =[2]ELEC!DB33 -> 0 | DC2: =[2]ELEC!DC33 -> 0 | DD2: =[2]ELEC!DD33 -> 0
A3: ='General information '!F6 -> 0 | B3: =SUM(230*A3) -> 0 | C3: 44287 | D3: 32740186 | E3: =D3-D2 -> 3148 | F3: 3991408 | G3: =F3-F2 -> 715 | H3: 17831860 | I3: =H3-H2 -> 1006 | J3: 28961206 | K3: =J3-J2 -> 1692 | L3: 24125630 | M3: =L3-L2 -> 4066 | N3: =M3+K3+I3+G3+E3 -> 10627 | O3: =IF(B3>0,N3/B3,0) -> 0 | P3: 16844.05 | Q3: =(P3-P2)*1000 -> 9208 | R3: =+N3-Q3 -> 1419 | S3: 10175 | T3: =S3-S2 -> 8 | U3: 429166 | V3: =U3-U2 -> 1217 | W3: =W2 -> 32247 | X3: =W3-W2 -> 0 | Y3: =Y2 -> 708695 | Z3: =Y3-Y2 -> 0 | AA3: =AA2 -> 35814 | AB3: =AA3-AA2 -> 0 | AC3: =AC2 -> 936218 | AD3: =AC3-AC2 -> 0 | AE3: =AB3+X3+T3 -> 8 | AF3: =V3+Z3+AD3 -> 1217 | AG3: =IF(AE3>0,AF3/AE3,0) -> 152.125
A4: ='General information '!F7 -> 0 | B4: =SUM(230*A4) -> 0 | C4: 44288 | D4: 32743098 | E4: =D4-D3 -> 2912 | F4: 3991968 | G4: =F4-F3 -> 560 | H4: 17832698 | I4: =H4-H3 -> 838 | J4: 28963042 | K4: =J4-J3 -> 1836 | L4: 24128050 | M4: =L4-L3 -> 2420 | N4: =M4+K4+I4+G4+E4 -> 8566 | O4: =IF(B4>0,N4/B4,0) -> 0 | P4: 16851.772 | Q4: =(P4-P3)*1000 -> 7722 | R4: =N4-Q4 -> 844 | S4: =S3 -> 10175 | T4: =S4-S3 -> 0 | U4: =U3 -> 429166 | V4: =U4-U3 -> 0 | W4: 32249 | X4: =W4-W3 -> 2 | Y4: 709120 | Z4: =Y4-Y3 -> 425 | AA4: 35815 | AB4: =AA4-AA3 -> 1 | AC4: 936339 | AD4: =AC4-AC3 -> 121 | AE4: =AB4+X4+T4 -> 3 | AF4: =V4+Z4+AD4 -> 546 | AG4: =IF(AE4>0,AF4/AE4,0) -> 182
A5: ='General information '!F8 -> 0 | B5: =SUM(230*A5) -> 0 | C5: 44289 | D5: 32746208 | E5: =D5-D4 -> 3110 | F5: 3992590 | G5: =F5-F4 -> 622 | H5: 17833536 | I5: =H5-H4 -> 838 | J5: 28965886 | K5: =J5-J4 -> 2844 | L5: 24130322 | M5: =L5-L4 -> 2272 | N5: =M5+K5+I5+G5+E5 -> 9686 | O5: =IF(B5>0,N5/B5,0) -> 0 | P5: 16860.034 | Q5: =(P5-P4)*1000 -> 8262 | R5: =N5-Q5 -> 1424 | S5: =S4 -> 10175 | T5: =S5-S4 -> 0 | U5: =U4 -> 429166 | V5: =U5-U4 -> 0 | W5: 32257 | X5: =W5-W4 -> 8 | Y5: 710354 | Z5: =Y5-Y4 -> 1234 | AA5: =AA4 -> 35815 | AB5: =AA5-AA4 -> 0 | AC5: =AC4 -> 936339 | AD5: =AC5-AC4 -> 0 | AE5: =AB5+X5+T5 -> 8 | AF5: =V5+Z5+AD5 -> 1234 | AG5: =IF(AE5>0,AF5/AE5,0) -> 154.25 | AI5: =R5-'EDl log'!B3 -> -955232
A6: ='General information '!F9 -> 0 | B6: =SUM(230*A6) -> 0 | C6: 44290 | D6: 32749798 | E6: =D6-D5 -> 3590 | F6: 3993124 | G6: =F6-F5 -> 534 | H6: 17834590 | I6: =H6-H5 -> 1054 | J6: 28967566 | K6: =J6-J5 -> 1680 | L6: 24132662 | M6: =L6-L5 -> 2340 | N6: =M6+K6+I6+G6+E6 -> 9198 | O6: =IF(B6>0,N6/B6,0) -> 0 | P6: 16867.975 | Q6: =(P6-P5)*1000 -> 7941 | R6: =N6-Q6 -> 1257 | S6: =S5 -> 10175 | T6: =S6-S5 -> 0 | U6: =U5 -> 429166 | V6: =U6-U5 -> 0 | W6: 32258 | X6: =W6-W5 -> 1 | Y6: 710563 | Z6: =Y6-Y5 -> 209 | AA6: 35819 | AB6: =AA6-AA5 -> 4 | AC6: 936894 | AD6: =AC6-AC5 -> 555 | AE6: =AB6+X6+T6 -> 5 | AF6: =V6+Z6+AD6 -> 764 | AG6: =IF(AE6>0,AF6/AE6,0) -> 152.8 | AI6: =R6-'EDl log'!B4 -> -956254
A7: ='General information '!F10 -> 0 | B7: =SUM(230*A7) -> 0 | C7: 44291 | D7: 32753030 | E7: =D7-D6 -> 3232 | F7: 3993869 | G7: =F7-F6 -> 745 | H7: 17835534 | I7: =H7-H6 -> 944 | J7: 28970094 | K7: =J7-J6 -> 2528 | L7: 24134782 | M7: =L7-L6 -> 2120 | N7: =M7+K7+I7+G7+E7 -> 9569 | O7: =IF(B7>0,N7/B7,0) -> 0 | P7: 16875.518 | Q7: =(P7-P6)*1000 -> 7543 | R7: =N7-Q7 -> 2026 | S7: =S6 -> 10175 | T7: =S7-S6 -> 0 | U7: =U6 -> 429166 | V7: =U7-U6 -> 0 | W7: 32263 | X7: =W7-W6 -> 5 | Y7: 711420 | Z7: =Y7-Y6 -> 857 | AA7: 35820 | AB7: =AA7-AA6 -> 1 | AC7: 937184 | AD7: =AC7-AC6 -> 290 | AE7: =AB7+X7+T7 -> 6 | AF7: =V7+Z7+AD7 -> 1147 | AG7: =IF(AE7>0,AF7/AE7,0) -> 191.16667 | AI7: =R7-'EDl log'!B5 -> -956097
A8: ='General information '!F11 -> 0 | B8: =SUM(230*A8) -> 0 | C8: 44292 | D8: 32757886 | E8: =D8-D7 -> 4856 | F8: 3994535 | G8: =F8-F7 -> 666 | H8: 17836472 | I8: =H8-H7 -> 938 | J8: 28972314 | K8: =J8-J7 -> 2220 | L8: 24136934 | M8: =L8-L7 -> 2152 | N8: =M8+K8+I8+G8+E8 -> 10832 | O8: =IF(B8>0,N8/B8,0) -> 0 | P8: 16884.382 | Q8: =(P8-P7)*1000 -> 8864 | R8: =N8-Q8 -> 1968 | S8: =S7 -> 10175 | T8: =S8-S7 -> 0 | U8: =U7 -> 429166 | V8: =U8-U7 -> 0 | W8: 32264 | X8: =W8-W7 -> 1 | Y8: 711752 | Z8: =Y8-Y7 -> 332 | AA8: 35829 | AB8: =AA8-AA7 -> 9 | AC8: 938828 | AD8: =AC8-AC7 -> 1644 | AE8: =AB8+X8+T8 -> 10 | AF8: =V8+Z8+AD8 -> 1976 | AG8: =IF(AE8>0,AF8/AE8,0) -> 197.6 | AI8: =R8-'EDl log'!B6 -> -957001
A9: ='General information '!F12 -> 0 | B9: =SUM(230*A9) -> 0 | C9: 44293 | D9: 32761750 | E9: =D9-D8 -> 3864 | F9: 3995231 | G9: =F9-F8 -> 696 | H9: 17837370 | I9: =H9-H8 -> 898 | J9: 28973992 | K9: =J9-J8 -> 1678 | L9: 24138590 | M9: =L9-L8 -> 1656 | N9: =M9+K9+I9+G9+E9 -> 8792 | O9: =IF(B9>0,N9/B9,0) -> 0 | P9: 16889.852 | Q9: =(P9-P8)*1000 -> 5470 | R9: =N9-Q9 -> 3322 | S9: =S8 -> 10175 | T9: =S9-S8 -> 0 | U9: =U8 -> 429166 | V9: =U9-U8 -> 0 | W9: =W8 -> 32264 | X9: =W9-W8 -> 0 | Y9: =Y8 -> 711752 | Z9: =Y9-Y8 -> 0 | AA9: 35835 | AB9: =AA9-AA8 -> 6 | AC9: 940208 | AD9: =AC9-AC8 -> 1380 | AE9: =AB9+X9+T9 -> 6 | AF9: =V9+Z9+AD9 -> 1380 | AG9: =IF(AE9>0,AF9/AE9,0) -> 230 | AI9: =R9-'EDl log'!B7 -> -956336
A10: ='General information '!F13 -> 0 | B10: =SUM(230*A10) -> 0 | C10: 44294 | D10: 32764132 | E10: =D10-D9 -> 2382 | F10: 3996002 | G10: =F10-F9 -> 771 | H10: 17838240 | I10: =H10-H9 -> 870 | J10: 28976514 | K10: =J10-J9 -> 2522 | L10: 24140252 | M10: =L10-L9 -> 1662 | N10: =M10+K10+I10+G10+E10 -> 8207 | O10: =IF(B10>0,N10/B10,0) -> 0 | P10: 16894.339 | Q10: =(P10-P9)*1000 -> 4487 | R10: =N10-Q10 -> 3720 | S10: =S9 -> 10175 | T10: =S10-S9 -> 0 | U10: =U9 -> 429166 | V10: =U10-U9 -> 0 | W10: 32270 | X10: =W10-W9 -> 6 | Y10: 712865 | Z10: =Y10-Y9 -> 1113 | AA10: =AA9 -> 35835 | AB10: =AA10-AA9 -> 0 | AC10: =AC9 -> 940208 | AD10: =AC10-AC9 -> 0 | AE10: =AB10+X10+T10 -> 6 | AF10: =V10+Z10+AD10 -> 1113 | AG10: =IF(AE10>0,AF10/AE10,0) -> 185.5 | AI10: =R10-'EDl log'!B8 -> -957419
A11: ='General information '!F14 -> 0 | B11: =SUM(230*A11) -> 0 | C11: 44295 | D11: 32767042 | E11: =D11-D10 -> 2910 | F11: 3996744 | G11: =F11-F10 -> 742 | H11: 17839158 | I11: =H11-H10 -> 918 | J11: 28977872 | K11: =J11-J10 -> 1358 | L11: 24141908 | M11: =L11-L10 -> 1656 | N11: =M11+K11+I11+G11+E11 -> 7584 | O11: =IF(B11>0,N11/B11,0) -> 0 | P11: 16898.479 | Q11: =(P11-P10)*1000 -> 4140 | R11: =N11-Q11 -> 3444 | S11: =S10 -> 10175 | T11: =S11-S10 -> 0 | U11: =U10 -> 429166 | V11: =U11-U10 -> 0 | W11: =W10 -> 32270 | X11: =W11-W10 -> 0 | Y11: =Y10 -> 712865 | Z11: =Y11-Y10 -> 0 | AA11: 35839 | AB11: =AA11-AA10 -> 4 | AC11: 940903 | AD11: =AC11-AC10 -> 695 | AE11: =AB11+X11+T11 -> 4 | AF11: =V11+Z11+AD11 -> 695 | AG11: =IF(AE11>0,AF11/AE11,0) -> 173.75 | AI11: =R11-'EDl log'!B9 -> -958520
A12: ='General information '!F15 -> 0 | B12: =SUM(230*A12) -> 0 | C12: 44296 | D12: 32769110 | E12: =D12-D11 -> 2068 | F12: 3997467 | G12: =F12-F11 -> 723 | H12: 17840094 | I12: =H12-H11 -> 936 | J12: 28979110 | K12: =J12-J11 -> 1238 | L12: 24143826 | M12: =L12-L11 -> 1918 | N12: =M12+K12+I12+G12+E12 -> 6883 | O12: =IF(B12>0,N12/B12,0) -> 0 | P12: 16901.314 | Q12: =(P12-P11)*1000 -> 2835 | R12: =N12-Q12 -> 4048 | S12: =S11 -> 10175 | T12: =S12-S11 -> 0 | U12: =U11 -> 429166 | V12: =U12-U11 -> 0 | W12: =W11 -> 32270 | X12: =W12-W11 -> 0 | Y12: =Y11 -> 712865 | Z12: =Y12-Y11 -> 0 | AA12: 35841 | AB12: =AA12-AA11 -> 2 | AC12: 941299 | AD12: =AC12-AC11 -> 396 | AE12: =AB12+X12+T12 -> 2 | AF12: =V12+Z12+AD12 -> 396 | AG12: =IF(AE12>0,AF12/AE12,0) -> 198 | AI12: =R12-'EDl log'!B10 -> -959610
A13: ='General information '!F16 -> 0 | B13: =SUM(230*A13) -> 0 | C13: 44297 | D13: 32771430 | E13: =D13-D12 -> 2320 | F13: 3998122.8 | G13: =F13-F12 -> 655.8 | H13: 17840942 | I13: =H13-H12 -> 848 | J13: 28980359 | K13: =J13-J12 -> 1249 | L13: 24145514 | M13: =L13-L12 -> 1688 | N13: =M13+K13+I13+G13+E13 -> 6760.8 | O13: =IF(B13>0,N13/B13,0) -> 0 | P13: 16904.397 | Q13: =(P13-P12)*1000 -> 3083 | R13: =N13-Q13 -> 3677.8 | S13: =S12 -> 10175 | T13: =S13-S12 -> 0 | U13: =U12 -> 429166 | V13: =U13-U12 -> 0 | W13: =W12 -> 32270 | X13: =W13-W12 -> 0 | Y13: =Y12 -> 712865 | Z13: =Y13-Y12 -> 0 | AA13: 35844 | AB13: =AA13-AA12 -> 3 | AC13: 941856 | AD13: =AC13-AC12 -> 557 | AE13: =AB13+X13+T13 -> 3 | AF13: =V13+Z13+AD13 -> 557 | AG13: =IF(AE13>0,AF13/AE13,0) -> 185.66667 | AI13: =R13-'EDl log'!B11 -> -961997.2
A14: ='General information '!F17 -> 0 | B14: =SUM(230*A14) -> 0 | C14: 44298 | D14: 32774350 | E14: =D14-D13 -> 2920 | F14: 3998763 | G14: =F14-F13 -> 640.2 | H14: 17841744 | I14: =H14-H13 -> 802 | J14: 28981682 | K14: =J14-J13 -> 1323 | L14: 24147122 | M14: =L14-L13 -> 1608 | N14: =M14+K14+I14+G14+E14 -> 7293.2 | O14: =IF(B14>0,N14/B14,0) -> 0 | P14: 16908.744 | Q14: =(P14-P13)*1000 -> 4347 | R14: =N14-Q14 -> 2946.2 | S14: =S13 -> 10175 | T14: =S14-S13 -> 0 | U14: =U13 -> 429166 | V14: =U14-U13 -> 0 | W14: =W13 -> 32270 | X14: =W14-W13 -> 0 | Y14: =Y13 -> 712865 | Z14: =Y14-Y13 -> 0 | AA14: 35848 | AB14: =AA14-AA13 -> 4 | AC14: 942587 | AD14: =AC14-AC13 -> 731 | AE14: =AB14+X14+T14 -> 4 | AF14: =V14+Z14+AD14 -> 731 | AG14: =IF(AE14>0,AF14/AE14,0) -> 182.75 | AI14: =R14-'EDl log'!B12 -> -964589.8
A15: ='General information '!F18 -> 0 | B15: =SUM(230*A15) -> 0 | C15: 44299 | D15: 32776934 | E15: =D15-D14 -> 2584 | F15: 3999372 | G15: =F15-F14 -> 609 | H15: 17842538 | I15: =H15-H14 -> 794 | J15: 28982962 | K15: =J15-J14 -> 1280 | L15: 24148698 | M15: =L15-L14 -> 1576 | N15: =M15+K15+I15+G15+E15 -> 6843 | O15: =IF(B15>0,N15/B15,0) -> 0 | P15: 16912 | Q15: =(P15-P14)*1000 -> 3256 | R15: =N15-Q15 -> 3587 | S15: =S14 -> 10175 | T15: =S15-S14 -> 0 | U15: =U14 -> 429166 | V15: =U15-U14 -> 0 | W15: =W14 -> 32270 | X15: =W15-W14 -> 0 | Y15: =Y14 -> 712865 | Z15: =Y15-Y14 -> 0 | AA15: 35852 | AB15: =AA15-AA14 -> 4 | AC15: 943255 | AD15: =AC15-AC14 -> 668 | AE15: =AB15+X15+T15 -> 4 | AF15: =V15+Z15+AD15 -> 668 | AG15: =IF(AE15>0,AF15/AE15,0) -> 167 | AI15: =R15-'EDl log'!B13 -> -966120
A16: ='General information '!F19 -> 0 | B16: =SUM(230*A16) -> 0 | C16: 44300 | D16: 32778910 | E16: =D16-D15 -> 1976 | F16: 4000042 | G16: =F16-F15 -> 670 | H16: 17843334 | I16: =H16-H15 -> 796 | J16: 28984462 | K16: =J16-J15 -> 1500 | L16: 24150556 | M16: =L16-L15 -> 1858 | N16: =M16+K16+I16+G16+E16 -> 6800 | O16: =IF(B16>0,N16/B16,0) -> 0 | P16: 16915 | Q16: =(P16-P15)*1000 -> 3000 | R16: =N16-Q16 -> 3800 | S16: =S15 -> 10175 | T16: =S16-S15 -> 0 | U16: =U15 -> 429166 | V16: =U16-U15 -> 0 | W16: 32272 | X16: =W16-W15 -> 2 | Y16: 713410 | Z16: =Y16-Y15 -> 545 | AA16: =AA15 -> 35852 | AB16: =AA16-AA15 -> 0 | AC16: =AC15 -> 943255 | AD16: =AC16-AC15 -> 0 | AE16: =AB16+X16+T16 -> 2 | AF16: =V16+Z16+AD16 -> 545 | AG16: =IF(AE16>0,AF16/AE16,0) -> 272.5 | AI16: =R16-'EDl log'!B14 -> -967898
A17: ='General information '!F20 -> 0 | B17: =SUM(230*A17) -> 0 | C17: 44301 | D17: 32781494 | E17: =D17-D16 -> 2584 | F17: 4000629 | G17: =F17-F16 -> 587 | H17: 17844118 | I17: =H17-H16 -> 784 | J17: 28986530 | K17: =J17-J16 -> 2068 | L17: 24152120 | M17: =L17-L16 -> 1564 | N17: =M17+K17+I17+G17+E17 -> 7587 | O17: =IF(B17>0,N17/B17,0) -> 0 | P17: 16920 | Q17: =(P17-P16)*1000 -> 5000 | R17: =N17-Q17 -> 2587 | S17: =S16 -> 10175 | T17: =S17-S16 -> 0 | U17: =U16 -> 429166 | V17: =U17-U16 -> 0 | W17: 32276 | X17: =W17-W16 -> 4 | Y17: 714183 | Z17: =Y17-Y16 -> 773 | AA17: =AA16 -> 35852 | AB17: =AA17-AA16 -> 0 | AC17: =AC16 -> 943255 | AD17: =AC17-AC16 -> 0 | AE17: =AB17+X17+T17 -> 4 | AF17: =V17+Z17+AD17 -> 773 | AG17: =IF(AE17>0,AF17/AE17,0) -> 193.25 | AI17: =R17-'EDl log'!B15 -> -970705
A18: ='General information '!F21 -> 0 | B18: =SUM(230*A18) -> 0 | C18: 44302 | D18: =D17 -> 32781494 | E18: =D18-D17 -> 0 | F18: =F17 -> 4000629 | G18: =F18-F17 -> 0 | H18: =H17 -> 17844118 | I18: =H18-H17 -> 0 | J18: =J17 -> 28986530 | K18: =J18-J17 -> 0 | L18: =L17 -> 24152120 | M18: =L18-L17 -> 0 | N18: =M18+K18+I18+G18+E18 -> 0 | O18: =IF(B18>0,N18/B18,0) -> 0 | P18: =P17 -> 16920 | Q18: =(P18-P17)*1000 -> 0 | R18: =N18-Q18 -> 0 | S18: =S17 -> 10175 | T18: =S18-S17 -> 0 | U18: =U17 -> 429166 | V18: =U18-U17 -> 0 | W18: =W17 -> 32276 | X18: =W18-W17 -> 0 | Y18: =Y17 -> 714183 | Z18: =Y18-Y17 -> 0 | AA18: =AA17 -> 35852 | AB18: =AA18-AA17 -> 0 | AC18: =AC17 -> 943255 | AD18: =AC18-AC17 -> 0 | AE18: =AB18+X18+T18 -> 0 | AF18: =V18+Z18+AD18 -> 0 | AG18: =IF(AE18>0,AF18/AE18,0) -> 0 | AI18: =R18-'EDl log'!B16 -> -975030
A19: ='General information '!F22 -> 0 | B19: =SUM(230*A19) -> 0 | C19: 44303 | D19: =D18 -> 32781494 | E19: =D19-D18 -> 0 | F19: =F18 -> 4000629 | G19: =F19-F18 -> 0 | H19: =H18 -> 17844118 | I19: =H19-H18 -> 0 | J19: =J18 -> 28986530 | K19: =J19-J18 -> 0 | L19: =L18 -> 24152120 | M19: =L19-L18 -> 0 | N19: =M19+K19+I19+G19+E19 -> 0 | O19: =IF(B19>0,N19/B19,0) -> 0 | P19: =P18 -> 16920 | Q19: =(P19-P18)*1000 -> 0 | R19: =N19-Q19 -> 0 | S19: =S18 -> 10175 | T19: =S19-S18 -> 0 | U19: =U18 -> 429166 | V19: =U19-U18 -> 0 | W19: =W18 -> 32276 | X19: =W19-W18 -> 0 | Y19: =Y18 -> 714183 | Z19: =Y19-Y18 -> 0 | AA19: =AA18 -> 35852 | AB19: =AA19-AA18 -> 0 | AC19: =AC18 -> 943255 | AD19: =AC19-AC18 -> 0 | AE19: =AB19+X19+T19 -> 0 | AF19: =V19+Z19+AD19 -> 0 | AG19: =IF(AE19>0,AF19/AE19,0) -> 0 | AI19: =R19-'EDl log'!B17 -> -976859
A20: ='General information '!F23 -> 0 | B20: =SUM(230*A20) -> 0 | C20: 44304 | D20: =D19 -> 32781494 | E20: =D20-D19 -> 0 | F20: =F19 -> 4000629 | G20: =F20-F19 -> 0 | H20: =H19 -> 17844118 | I20: =H20-H19 -> 0 | J20: =J19 -> 28986530 | K20: =J20-J19 -> 0 | L20: =L19 -> 24152120 | M20: =L20-L19 -> 0 | N20: =M20+K20+I20+G20+E20 -> 0 | O20: =IF(B20>0,N20/B20,0) -> 0 | P20: =P19 -> 16920 | Q20: =(P20-P19)*1000 -> 0 | R20: =N20-Q20 -> 0 | S20: =S19 -> 10175 | T20: =S20-S19 -> 0 | U20: =U19 -> 429166 | V20: =U20-U19 -> 0 | W20: =W19 -> 32276 | X20: =W20-W19 -> 0 | Y20: =Y19 -> 714183 | Z20: =Y20-Y19 -> 0 | AA20: =AA19 -> 35852 | AB20: =AA20-AA19 -> 0 | AC20: =AC19 -> 943255 | AD20: =AC20-AC19 -> 0 | AE20: =AB20+X20+T20 -> 0 | AF20: =V20+Z20+AD20 -> 0 | AG20: =IF(AE20>0,AF20/AE20,0) -> 0 | AI20: =R20-'EDl log'!B18 -> -978719
A21: ='General information '!F24 -> 0 | B21: =SUM(230*A21) -> 0 | C21: 44305 | D21: =D20 -> 32781494 | E21: =D21-D20 -> 0 | F21: =F20 -> 4000629 | G21: =F21-F20 -> 0 | H21: =H20 -> 17844118 | I21: =H21-H20 -> 0 | J21: =J20 -> 28986530 | K21: =J21-J20 -> 0 | L21: =L20 -> 24152120 | M21: =L21-L20 -> 0 | N21: =M21+K21+I21+G21+E21 -> 0 | O21: =IF(B21>0,N21/B21,0) -> 0 | P21: =P20 -> 16920 | Q21: =(P21-P20)*1000 -> 0 | R21: =N21-Q21 -> 0 | S21: =S20 -> 10175 | T21: =S21-S20 -> 0 | U21: =U20 -> 429166 | V21: =U21-U20 -> 0 | W21: =W20 -> 32276 | X21: =W21-W20 -> 0 | Y21: =Y20 -> 714183 | Z21: =Y21-Y20 -> 0 | AA21: =AA20 -> 35852 | AB21: =AA21-AA20 -> 0 | AC21: =AC20 -> 943255 | AD21: =AC21-AC20 -> 0 | AE21: =AB21+X21+T21 -> 0 | AF21: =V21+Z21+AD21 -> 0 | AG21: =IF(AE21>0,AF21/AE21,0) -> 0 | AI21: =R21-'EDl log'!B19 -> -978719
A22: ='General information '!F25 -> 0 | B22: =SUM(230*A22) -> 0 | C22: 44306 | D22: =D21 -> 32781494 | E22: =D22-D21 -> 0 | F22: =F21 -> 4000629 | G22: =F22-F21 -> 0 | H22: =H21 -> 17844118 | I22: =H22-H21 -> 0 | J22: =J21 -> 28986530 | K22: =J22-J21 -> 0 | L22: =L21 -> 24152120 | M22: =L22-L21 -> 0 | N22: =M22+K22+I22+G22+E22 -> 0 | O22: =IF(B22>0,N22/B22,0) -> 0 | P22: =P21 -> 16920 | Q22: =(P22-P21)*1000 -> 0 | R22: =N22-Q22 -> 0 | S22: =S21 -> 10175 | T22: =S22-S21 -> 0 | U22: =U21 -> 429166 | V22: =U22-U21 -> 0 | W22: =W21 -> 32276 | X22: =W22-W21 -> 0 | Y22: =Y21 -> 714183 | Z22: =Y22-Y21 -> 0 | AA22: =AA21 -> 35852 | AB22: =AA22-AA21 -> 0 | AC22: =AC21 -> 943255 | AD22: =AC22-AC21 -> 0 | AE22: =AB22+X22+T22 -> 0 | AF22: =V22+Z22+AD22 -> 0 | AG22: =IF(AE22>0,AF22/AE22,0) -> 0 | AI22: =R22-'EDl log'!B20 -> -978719
A23: ='General information '!F26 -> 0 | B23: =SUM(230*A23) -> 0 | C23: 44307 | D23: =D22 -> 32781494 | E23: =D23-D22 -> 0 | F23: =F22 -> 4000629 | G23: =F23-F22 -> 0 | H23: =H22 -> 17844118 | I23: =H23-H22 -> 0 | J23: =J22 -> 28986530 | K23: =J23-J22 -> 0 | L23: =L22 -> 24152120 | M23: =L23-L22 -> 0 | N23: =M23+K23+I23+G23+E23 -> 0 | O23: =IF(B23>0,N23/B23,0) -> 0 | P23: =P22 -> 16920 | Q23: =(P23-P22)*1000 -> 0 | R23: =N23-Q23 -> 0 | S23: =S22 -> 10175 | T23: =S23-S22 -> 0 | U23: =U22 -> 429166 | V23: =U23-U22 -> 0 | W23: =W22 -> 32276 | X23: =W23-W22 -> 0 | Y23: =Y22 -> 714183 | Z23: =Y23-Y22 -> 0 | AA23: =AA22 -> 35852 | AB23: =AA23-AA22 -> 0 | AC23: =AC22 -> 943255 | AD23: =AC23-AC22 -> 0 | AE23: =AB23+X23+T23 -> 0 | AF23: =V23+Z23+AD23 -> 0 | AG23: =IF(AE23>0,AF23/AE23,0) -> 0 | AI23: =R23-'EDl log'!B21 -> -978719
A24: ='General information '!F27 -> 0 | B24: =SUM(230*A24) -> 0 | C24: 44308 | D24: =D23 -> 32781494 | E24: =D24-D23 -> 0 | F24: =F23 -> 4000629 | G24: =F24-F23 -> 0 | H24: =H23 -> 17844118 | I24: =H24-H23 -> 0 | J24: =J23 -> 28986530 | K24: =J24-J23 -> 0 | L24: =L23 -> 24152120 | M24: =L24-L23 -> 0 | N24: =M24+K24+I24+G24+E24 -> 0 | O24: =IF(B24>0,N24/B24,0) -> 0 | P24: =P23 -> 16920 | Q24: =(P24-P23)*1000 -> 0 | R24: =N24-Q24 -> 0 | S24: =S23 -> 10175 | T24: =S24-S23 -> 0 | U24: =U23 -> 429166 | V24: =U24-U23 -> 0 | W24: =W23 -> 32276 | X24: =W24-W23 -> 0 | Y24: =Y23 -> 714183 | Z24: =Y24-Y23 -> 0 | AA24: =AA23 -> 35852 | AB24: =AA24-AA23 -> 0 | AC24: =AC23 -> 943255 | AD24: =AC24-AC23 -> 0 | AE24: =AB24+X24+T24 -> 0 | AF24: =V24+Z24+AD24 -> 0 | AG24: =IF(AE24>0,AF24/AE24,0) -> 0 | AI24: =R24-'EDl log'!B22 -> -978719
A25: ='General information '!F28 -> 0 | B25: =SUM(230*A25) -> 0 | C25: 44309 | D25: =D24 -> 32781494 | E25: =D25-D24 -> 0 | F25: =F24 -> 4000629 | G25: =F25-F24 -> 0 | H25: =H24 -> 17844118 | I25: =H25-H24 -> 0 | J25: =J24 -> 28986530 | K25: =J25-J24 -> 0 | L25: =L24 -> 24152120 | M25: =L25-L24 -> 0 | N25: =M25+K25+I25+G25+E25 -> 0 | O25: =IF(B25>0,N25/B25,0) -> 0 | P25: =P24 -> 16920 | Q25: =(P25-P24)*1000 -> 0 | R25: =N25-Q25 -> 0 | S25: =S24 -> 10175 | T25: =S25-S24 -> 0 | U25: =U24 -> 429166 | V25: =U25-U24 -> 0 | W25: =W24 -> 32276 | X25: =W25-W24 -> 0 | Y25: =Y24 -> 714183 | Z25: =Y25-Y24 -> 0 | AA25: =AA24 -> 35852 | AB25: =AA25-AA24 -> 0 | AC25: =AC24 -> 943255 | AD25: =AC25-AC24 -> 0 | AE25: =AB25+X25+T25 -> 0 | AF25: =V25+Z25+AD25 -> 0 | AG25: =IF(AE25>0,AF25/AE25,0) -> 0 | AI25: =R25-'EDl log'!B23 -> -978719
A26: ='General information '!F29 -> 0 | B26: =SUM(230*A26) -> 0 | C26: 44310 | D26: =D25 -> 32781494 | E26: =D26-D25 -> 0 | F26: =F25 -> 4000629 | G26: =F26-F25 -> 0 | H26: =H25 -> 17844118 | I26: =H26-H25 -> 0 | J26: =J25 -> 28986530 | K26: =J26-J25 -> 0 | L26: =L25 -> 24152120 | M26: =L26-L25 -> 0 | N26: =M26+K26+I26+G26+E26 -> 0 | O26: =IF(B26>0,N26/B26,0) -> 0 | P26: =P25 -> 16920 | Q26: =(P26-P25)*1000 -> 0 | R26: =N26-Q26 -> 0 | S26: =S25 -> 10175 | T26: =S26-S25 -> 0 | U26: =U25 -> 429166 | V26: =U26-U25 -> 0 | W26: =W25 -> 32276 | X26: =W26-W25 -> 0 | Y26: =Y25 -> 714183 | Z26: =Y26-Y25 -> 0 | AA26: =AA25 -> 35852 | AB26: =AA26-AA25 -> 0 | AC26: =AC25 -> 943255 | AD26: =AC26-AC25 -> 0 | AE26: =AB26+X26+T26 -> 0 | AF26: =V26+Z26+AD26 -> 0 | AG26: =IF(AE26>0,AF26/AE26,0) -> 0 | AI26: =R26-'EDl log'!B24 -> -978719
A27: ='General information '!F30 -> 0 | B27: =SUM(230*A27) -> 0 | C27: 44311 | D27: =D26 -> 32781494 | E27: =D27-D26 -> 0 | F27: =F26 -> 4000629 | G27: =F27-F26 -> 0 | H27: =H26 -> 17844118 | I27: =H27-H26 -> 0 | J27: =J26 -> 28986530 | K27: =J27-J26 -> 0 | L27: =L26 -> 24152120 | M27: =L27-L26 -> 0 | N27: =M27+K27+I27+G27+E27 -> 0 | O27: =IF(B27>0,N27/B27,0) -> 0 | P27: =P26 -> 16920 | Q27: =(P27-P26)*1000 -> 0 | R27: =N27-Q27 -> 0 | S27: =S26 -> 10175 | T27: =S27-S26 -> 0 | U27: =U26 -> 429166 | V27: =U27-U26 -> 0 | W27: =W26 -> 32276 | X27: =W27-W26 -> 0 | Y27: =Y26 -> 714183 | Z27: =Y27-Y26 -> 0 | AA27: =AA26 -> 35852 | AB27: =AA27-AA26 -> 0 | AC27: =AC26 -> 943255 | AD27: =AC27-AC26 -> 0 | AE27: =AB27+X27+T27 -> 0 | AF27: =V27+Z27+AD27 -> 0 | AG27: =IF(AE27>0,AF27/AE27,0) -> 0 | AI27: =R27-'EDl log'!B25 -> -978719
A28: ='General information '!F31 -> 0 | B28: =SUM(230*A28) -> 0 | C28: 44312 | D28: =D27 -> 32781494 | E28: =D28-D27 -> 0 | F28: =F27 -> 4000629 | G28: =F28-F27 -> 0 | H28: =H27 -> 17844118 | I28: =H28-H27 -> 0 | J28: =J27 -> 28986530 | K28: =J28-J27 -> 0 | L28: =L27 -> 24152120 | M28: =L28-L27 -> 0 | N28: =M28+K28+I28+G28+E28 -> 0 | O28: =IF(B28>0,N28/B28,0) -> 0 | P28: =P27 -> 16920 | Q28: =(P28-P27)*1000 -> 0 | R28: =N28-Q28 -> 0 | S28: =S27 -> 10175 | T28: =S28-S27 -> 0 | U28: =U27 -> 429166 | V28: =U28-U27 -> 0 | W28: =W27 -> 32276 | X28: =W28-W27 -> 0 | Y28: =Y27 -> 714183 | Z28: =Y28-Y27 -> 0 | AA28: =AA27 -> 35852 | AB28: =AA28-AA27 -> 0 | AC28: =AC27 -> 943255 | AD28: =AC28-AC27 -> 0 | AE28: =AB28+X28+T28 -> 0 | AF28: =V28+Z28+AD28 -> 0 | AG28: =IF(AE28>0,AF28/AE28,0) -> 0 | AI28: =R28-'EDl log'!B26 -> -978719
A29: ='General information '!F32 -> 0 | B29: =SUM(230*A29) -> 0 | C29: 44313 | D29: =D28 -> 32781494 | E29: =D29-D28 -> 0 | F29: =F28 -> 4000629 | G29: =F29-F28 -> 0 | H29: =H28 -> 17844118 | I29: =H29-H28 -> 0 | J29: =J28 -> 28986530 | K29: =J29-J28 -> 0 | L29: =L28 -> 24152120 | M29: =L29-L28 -> 0 | N29: =M29+K29+I29+G29+E29 -> 0 | O29: =IF(B29>0,N29/B29,0) -> 0 | P29: =P28 -> 16920 | Q29: =(P29-P28)*1000 -> 0 | R29: =N29-Q29 -> 0 | S29: =S28 -> 10175 | T29: =S29-S28 -> 0 | U29: =U28 -> 429166 | V29: =U29-U28 -> 0 | W29: =W28 -> 32276 | X29: =W29-W28 -> 0 | Y29: =Y28 -> 714183 | Z29: =Y29-Y28 -> 0 | AA29: =AA28 -> 35852 | AB29: =AA29-AA28 -> 0 | AC29: =AC28 -> 943255 | AD29: =AC29-AC28 -> 0 | AE29: =AB29+X29+T29 -> 0 | AF29: =V29+Z29+AD29 -> 0 | AG29: =IF(AE29>0,AF29/AE29,0) -> 0 | AI29: =R29-'EDl log'!B27 -> -978719
... A32: ='General information '!F35 -> 0 | B32: =SUM(230*A32) -> 0 | C32: 44316 | D32: =D31 -> 32781494 | E32: =D32-D31 -> 0 | F32: =F31 -> 4000629 | G32: =F32-F31 -> 0 | H32: =H31 -> 17844118 | I32: =H32-H31 -> 0 | J32: =J31 -> 28986530 | K32: =J32-J31 -> 0 | L32: =L31 -> 24152120 | M32: =L32-L31 -> 0 | N32: =M32+K32+I32+G32+E32 -> 0 | O32: =IF(B32>0,N32/B32,0) -> 0 | P32: =P31 -> 16920 | Q32: =(P32-P31)*1000 -> 0 | R32: =N32-Q32 -> 0 | S32: =S31 -> 10175 | T32: =S32-S31 -> 0 | U32: =U31 -> 429166 | V32: =U32-U31 -> 0 | W32: =W31 -> 32276 | X32: =W32-W31 -> 0 | Y32: =Y31 -> 714183 | Z32: =Y32-Y31 -> 0 | AA32: =AA31 -> 35852 | AB32: =AA32-AA31 -> 0 | AC32: =AC31 -> 943255 | AD32: =AC32-AC31 -> 0 | AE32: =AB32+X32+T32 -> 0 | AF32: =V32+Z32+AD32 -> 0 | AG32: =IF(AE32>0,AF32/AE32,0) -> 0 | AI32: =R32-'EDl log'!B30 -> -978719

Sheet B5
F1: Boiler A | J1: =J36 -> 76.183333 | K1: Boiler B | P1: Boiler C | V1: Boiler | X1: SteamA | AC1: SteamB | AH1: Steam | AI1: Boiler & steam | AL1: Total Boiler Runing H | AM1: Total Steam Runing H | AN1: GAS1 % | AO1: GAS1/L | AP1: GAS2% | AQ1: Gas2/L | AR1: GAS3% | AS1: GAS3/L | AU1: Gas Cons | AV1: Delivery | AW1: Cost/L
B2: Level Tank Gen | C2: Level tank Boiler | D2: Daily Cons Bo. | E2: Boiler litter | F2: Boiler A | G2: Run Hr a | H2: Boiler A fuel | I2: Daily consumption | J2: AVG | K2: index Run H | L2: Run Hrb | M2: Boiler B Fuel | O2: Daily consumption | P2: Boiler C | S2: Run C | U2: Total RH | V2: Total Fuel | X2: SteamA | Y2: Run SA | Z2: Steam A Conter | AA2: Liters | AC2: SteamB | AD2: Run SteamB | AE2: Steam B Conter | AF2: SB Litters | AG2: Avg | AH2: Total Fuel | AI2: Total Fuel
S3: 0
A4: =ELEC!C2 -> 44286 | B4: =[3]B5!B35 -> 216 | C4: =[3]B5!C35 -> 223 | D4: =[3]B5!D35 -> 12 | E4: =[3]B5!E35 -> 100.56 | F4: =[3]B5!F35 -> 1795 | G4: =[3]B5!G35 -> 3 | H4: =[3]B5!H35 -> 9885 | I4: =[3]B5!I35 -> 203 | ... AX4: =[3]B5!AX35 -> 0.8
A5: =ELEC!C3 -> 44287 | B5: 230 | C5: 237 | D5: =C4-C5 -> -14 | E5: =D5*8.38 -> -117.32 | F5: 1797 | G5: =F5-F4 -> 2 | H5: 10038 | I5: =SUM(H5-H4) -> 153 | J5: 1 | K5: 2288 | L5: =K5-K4 -> 3 | M5: 168501 | N5: =M5-M4 -> 206 | O5: =O4 -> 1869 | P5: =P4 -> 2046 | Q5: =Q4 -> 172429 | R5: =Q5-Q4 -> 0 | S5: =SUM(P5-P4) -> 0 | T5: =SUM(S5*$T$2) -> 0 | U5: =SUM(G5+L5+S5) -> 5 | V5: =R5+N5+I5:I5 -> 359 | W5: =SUM(V5/U5) -> 71.8 | X5: =X4 -> 2463 | Y5: =X5-X4 -> 0 | Z5: =Z4 -> 138550 | AA5: =Z5-Z4 -> 0 | AB5: =SUM(Y5*$AB$2) -> 0 | AC5: =AC4 -> 1936 | AD5: =AC5-AC4 -> 0 | AE5: =AE4 -> 365520.8 | AF5: =AE5-AE4 -> 0 | AG5: =IF(AD5>0,AF5/AD5,0) -> 0 | AH5: =AF5+AA5 -> 0 | AI5: =SUM(AH5+V5) -> 359 | AJ5: =-tanks!AW6 -> 359 | AK5: =SUM(AJ5-AI5) -> 0 | AL5: =S5+L5+G5 -> 5 | AM5: =Y5+AD5 -> 0 | AN5: =AN4 -> 67 | AO5: =(AN5/100)*3000 -> 2010 | AP5: =AP4 -> 55 | AQ5: =(AP5/100)*3000 -> 1650 | AR5: =AR4 -> 61 | AS5: =(AR5/100)*3000 -> 1830 | AT5: =SUM(AO5+AQ5+AS5) -> 5490 | AU5: =AT4-AT5+AV5 -> 0 | AX5: =IF(AV5>0,AW5,AX4) -> 0.8
A6: =ELEC!C4 -> 44288 | B6: 219 | C6: 226 | D6: =C5-C6 -> 11 | E6: =D6*8.38 -> 92.18 | F6: =F5 -> 1797 | G6: =F6-F5 -> 0 | H6: =H5 -> 10038 | I6: =SUM(H6-H5) -> 0 | J6: =IF(G6>0,I6/G6,0) -> 0 | K6: 2290 | L6: =K6-K5 -> 2 | M6: 168619 | N6: =M6-M5 -> 118 | O6: =O5 -> 1869 | P6: 2049 | Q6: 172609 | R6: =Q6-Q5 -> 180 | S6: =SUM(P6-P5) -> 3 | T6: =SUM(S6*$T$2) -> 0 | U6: =SUM(G6+L6+S6) -> 5 | V6: =R6+N6+I6:I6 -> 298 | W6: =SUM(V6/U6) -> 59.6 | X6: =X5 -> 2463 | Y6: =X6-X5 -> 0 | Z6: =Z5 -> 138550 | AA6: =Z6-Z5 -> 0 | AB6: =SUM(Y6*$AB$2) -> 0 | AC6: =AC5 -> 1936 | AD6: =AC6-AC5 -> 0 | AE6: =AE5 -> 365520.8 | AF6: =AE6-AE5 -> 0 | AG6: =IF(AD6>0,AF6/AD6,0) -> 0 | AH6: =AF6+AA6 -> 0 | AI6: =SUM(AH6+V6) -> 298 | AJ6: =-tanks!AW7 -> 298 | AK6: =SUM(AJ6-AI6) -> 0 | AL6: =S6+L6+G6 -> 5 | AM6: =Y6+AD6 -> 0 | AN6: =AN5 -> 67 | AO6: =(AN6/100)*3000 -> 2010 | AP6: =AP5 -> 55 | AQ6: =(AP6/100)*3000 -> 1650 | AR6: =AR5 -> 61 | AS6: =(AR6/100)*3000 -> 1830 | AT6: =SUM(AO6+AQ6+AS6) -> 5490 | AU6: =AT5-AT6+AV6 -> 0 | AX6: =IF(AV6>0,AW6,AX5) -> 0.8
A7: =ELEC!C5 -> 44289 | B7: 208 | C7: 215 | D7: =C6-C7 -> 11 | E7: =D7*8.38 -> 92.18 | F7: 1799 | G7: =F7-F6 -> 2 | H7: 10207 | I7: =SUM(H7-H6) -> 169 | J7: =IF(G7>0,I7/G7,0) -> 84.5 | K7: =K6 -> 2290 | L7: =K7-K6 -> 0 | M7: =M6 -> 168619 | N7: =M7-M6 -> 0 | O7: =O6 -> 1869 | P7: 2050 | Q7: 172727 | R7: =Q7-Q6 -> 118 | S7: =SUM(P7-P6) -> 1 | T7: =SUM(S7*$T$2) -> 0 | U7: =SUM(G7+L7+S7) -> 3 | V7: =R7+N7+I7:I7 -> 287 | W7: =SUM(V7/U7) -> 95.666667 | X7: =X6 -> 2463 | Y7: =X7-X6 -> 0 | Z7: =Z6 -> 138550 | AA7: =Z7-Z6 -> 0 | AB7: =SUM(Y7*$AB$2) -> 0 | AC7: =AC6 -> 1936 | AD7: =AC7-AC6 -> 0 | AE7: =AE6 -> 365520.8 | AF7: =AE7-AE6 -> 0 | AG7: =IF(AD7>0,AF7/AD7,0) -> 0 | AH7: =AF7+AA7 -> 0 | AI7: =SUM(AH7+V7) -> 287 | AJ7: =-tanks!AW8 -> 287 | AK7: =SUM(AJ7-AI7) -> 0 | AL7: =S7+L7+G7 -> 3 | AM7: =Y7+AD7 -> 0 | AN7: =AN6 -> 67 | AO7: =(AN7/100)*3000 -> 2010 | AP7: =AP6 -> 55 | AQ7: =(AP7/100)*3000 -> 1650 | AR7: =AR6 -> 61 | AS7: =(AR7/100)*3000 -> 1830 | AT7: =SUM(AO7+AQ7+AS7) -> 5490 | AU7: =AT6-AT7+AV7 -> 0 | AX7: =IF(AV7>0,AW7,AX6) -> 0.8
A8: =ELEC!C6 -> 44290 | B8: 197 | C8: 204 | D8: =C7-C8 -> 11 | E8: =D8*8.38 -> 92.18 | F8: 1801 | G8: =F8-F7 -> 2 | H8: 10338 | I8: =SUM(H8-H7) -> 131 | J8: =IF(G8>0,I8/G8,0) -> 65.5 | K8: 2292 | L8: =K8-K7 -> 2 | M8: 168778 | N8: =M8-M7 -> 159 | O8: =O7 -> 1869 | P8: 2050 | Q8: =Q7 -> 172727 | R8: =Q8-Q7 -> 0 | S8: =SUM(P8-P7) -> 0 | T8: =SUM(S8*$T$2) -> 0 | U8: =SUM(G8+L8+S8) -> 4 | V8: =R8+N8+I8:I8 -> 290 | W8: =SUM(V8/U8) -> 72.5 | X8: =X7 -> 2463 | Y8: =X8-X7 -> 0 | Z8: =Z7 -> 138550 | AA8: =Z8-Z7 -> 0 | AB8: =SUM(Y8*$AB$2) -> 0 | AC8: =AC7 -> 1936 | AD8: =AC8-AC7 -> 0 | AE8: =AE7 -> 365520.8 | AF8: =AE8-AE7 -> 0 | AG8: =IF(AD8>0,AF8/AD8,0) -> 0 | AH8: =AF8+AA8 -> 0 | AI8: =SUM(AH8+V8) -> 290 | AJ8: =-tanks!AW9 -> 290 | AK8: =SUM(AJ8-AI8) -> 0 | AL8: =S8+L8+G8 -> 4 | AM8: =Y8+AD8 -> 0 | AN8: =AN7 -> 67 | AO8: =(AN8/100)*3000 -> 2010 | AP8: =AP7 -> 55 | AQ8: =(AP8/100)*3000 -> 1650 | AR8: =AR7 -> 61 | AS8: =(AR8/100)*3000 -> 1830 | AT8: =SUM(AO8+AQ8+AS8) -> 5490 | AU8: =AT7-AT8+AV8 -> 0 | AX8: =IF(AV8>0,AW8,AX7) -> 0.8
A9: =ELEC!C7 -> 44291 | B9: 188 | C9: 195 | D9: =C8-C9 -> 9 | E9: =D9*8.38 -> 75.42 | F9: =F8 -> 1801 | G9: =F9-F8 -> 0 | H9: =H8 -> 10338 | I9: =SUM(H9-H8) -> 0 | J9: =IF(G9>0,I9/G9,0) -> 0 | K9: 2293 | L9: =K9-K8 -> 1 | M9: 168927 | N9: =M9-M8 -> 149 | O9: =O8 -> 1869 | P9: 2052 | Q9: 172900 | R9: =Q9-Q8 -> 173 | S9: =SUM(P9-P8) -> 2 | T9: =SUM(S9*$T$2) -> 0 | U9: =SUM(G9+L9+S9) -> 3 | V9: =R9+N9+I9:I9 -> 322 | W9: =SUM(V9/U9) -> 107.33333 | X9: 2464 | Y9: =X9-X8 -> 1 | Z9: 138632 | AA9: =Z9-Z8 -> 82 | AB9: =SUM(Y9*$AB$2) -> 0 | AC9: =AC8 -> 1936 | AD9: =AC9-AC8 -> 0 | AE9: =AE8 -> 365520.8 | AF9: =AE9-AE8 -> 0 | AG9: =IF(AD9>0,AF9/AD9,0) -> 0 | AH9: =AF9+AA9 -> 82 | AI9: =SUM(AH9+V9) -> 404 | AJ9: =-tanks!AW10 -> 404 | AK9: =SUM(AJ9-AI9) -> 0 | AL9: =S9+L9+G9 -> 3 | AM9: =Y9+AD9 -> 1 | AN9: =AN8 -> 67 | AO9: =(AN9/100)*3000 -> 2010 | AP9: =AP8 -> 55 | AQ9: =(AP9/100)*3000 -> 1650 | AR9: =AR8 -> 61 | AS9: =(AR9/100)*3000 -> 1830 | AT9: =SUM(AO9+AQ9+AS9) -> 5490 | AU9: =AT8-AT9+AV9 -> 0 | AX9: =IF(AV9>0,AW9,AX8) -> 0.8
A10: =ELEC!C8 -> 44292 | B10: 177 | C10: 183 | D10: =C9-C10 -> 12 | E10: =D10*8.38 -> 100.56 | F10: 1803 | G10: =F10-F9 -> 2 | H10: 10506 | I10: =SUM(H10-H9) -> 168 | J10: =IF(G10>0,I10/G10,0) -> 84 | K10: =K9 -> 2293 | L10: =K10-K9 -> 0 | M10: =M9 -> 168927 | N10: =M10-M9 -> 0 | O10: =O9 -> 1869 | P10: 2054 | Q10: 173040 | R10: =Q10-Q9 -> 140 | S10: =SUM(P10-P9) -> 2 | T10: =SUM(S10*$T$2) -> 0 | U10: =SUM(G10+L10+S10) -> 4 | V10: =R10+N10+I10:I10 -> 308 | W10: =SUM(V10/U10) -> 77 | X10: =X9 -> 2464 | Y10: =X10-X9 -> 0 | Z10: =Z9 -> 138632 | AA10: =Z10-Z9 -> 0 | AB10: =SUM(Y10*$AB$2) -> 0 | AC10: =AC9 -> 1936 | AD10: =AC10-AC9 -> 0 | AE10: =AE9 -> 365520.8 | AF10: =AE10-AE9 -> 0 | AG10: =IF(AD10>0,AF10/AD10,0) -> 0 | AH10: =AF10+AA10 -> 0 | AI10: =SUM(AH10+V10) -> 308 | AJ10: =-tanks!AW11 -> 308 | AK10: =SUM(AJ10-AI10) -> 0 | AL10: =S10+L10+G10 -> 4 | AM10: =Y10+AD10 -> 0 | AN10: =AN9 -> 67 | AO10: =(AN10/100)*3000 -> 2010 | AP10: =AP9 -> 55 | AQ10: =(AP10/100)*3000 -> 1650 | AR10: =AR9 -> 61 | AS10: =(AR10/100)*3000 -> 1830 | AT10: =SUM(AO10+AQ10+AS10) -> 5490 | AU10: =AT9-AT10+AV10 -> 0 | AX10: =IF(AV10>0,AW10,AX9) -> 0.8
A11: =ELEC!C9 -> 44293 | B11: 228 | C11: 235 | D11: =C10-C11 -> -52 | E11: =D11*8.38 -> -435.76 | F11: 1805 | G11: =F11-F10 -> 2 | H11: 10625 | I11: =SUM(H11-H10) -> 119 | J11: =IF(G11>0,I11/G11,0) -> 59.5 | K11: 2296 | L11: =K11-K10 -> 3 | M11: 169095 | N11: =M11-M10 -> 168 | O11: =O10 -> 1869 | P11: =P10 -> 2054 | Q11: =Q10 -> 173040 | R11: =Q11-Q10 -> 0 | S11: =SUM(P11-P10) -> 0 | T11: =SUM(S11*$T$2) -> 0 | U11: =SUM(G11+L11+S11) -> 5 | V11: =R11+N11+I11:I11 -> 287 | W11: =SUM(V11/U11) -> 57.4 | X11: =X10 -> 2464 | Y11: =X11-X10 -> 0 | Z11: =Z10 -> 138632 | AA11: =Z11-Z10 -> 0 | AB11: =SUM(Y11*$AB$2) -> 0 | AC11: =AC10 -> 1936 | AD11: =AC11-AC10 -> 0 | AE11: =AE10 -> 365520.8 | AF11: =AE11-AE10 -> 0 | AG11: =IF(AD11>0,AF11/AD11,0) -> 0 | AH11: =AF11+AA11 -> 0 | AI11: =SUM(AH11+V11) -> 287 | AJ11: =-tanks!AW12 -> 287 | AK11: =SUM(AJ11-AI11) -> 0 | AL11: =S11+L11+G11 -> 5 | AM11: =Y11+AD11 -> 0 | AN11: =AN10 -> 67 | AO11: =(AN11/100)*3000 -> 2010 | AP11: =AP10 -> 55 | AQ11: =(AP11/100)*3000 -> 1650 | AR11: =AR10 -> 61 | AS11: =(AR11/100)*3000 -> 1830 | AT11: =SUM(AO11+AQ11+AS11) -> 5490 | AU11: =AT10-AT11+AV11 -> 0 | AX11: =IF(AV11>0,AW11,AX10) -> 0.8
A12: =ELEC!C10 -> 44294 | B12: 222 | C12: 228 | D12: =C11-C12 -> 7 | E12: =D12*8.38 -> 58.66 | F12: =F11 -> 1805 | G12: =F12-F11 -> 0 | H12: =H11 -> 10625 | I12: =SUM(H12-H11) -> 0 | J12: =IF(G12>0,I12/G12,0) -> 0 | K12: 2297 | L12: =K12-K11 -> 1 | M12: 169228 | N12: =M12-M11 -> 133 | O12: =O11 -> 1869 | P12: 2057 | Q12: 173215 | R12: =Q12-Q11 -> 175 | S12: =SUM(P12-P11) -> 3 | T12: =SUM(S12*$T$2) -> 0 | U12: =SUM(G12+L12+S12) -> 4 | V12: =R12+N12+I12:I12 -> 308 | W12: =SUM(V12/U12) -> 77 | X12: 2465 | Y12: =X12-X11 -> 1 | Z12: 138740 | AA12: =Z12-Z11 -> 108 | AB12: =SUM(Y12*$AB$2) -> 0 | AC12: =AC11 -> 1936 | AD12: =AC12-AC11 -> 0 | AE12: =AE11 -> 365520.8 | AF12: =AE12-AE11 -> 0 | AG12: =IF(AD12>0,AF12/AD12,0) -> 0 | AH12: =AF12+AA12 -> 108 | AI12: =SUM(AH12+V12) -> 416 | AJ12: =-tanks!AW13 -> 416 | AK12: =SUM(AJ12-AI12) -> 0 | AL12: =S12+L12+G12 -> 4 | AM12: =Y12+AD12 -> 1 | AN12: =AN11 -> 67 | AO12: =(AN12/100)*3000 -> 2010 | AP12: =AP11 -> 55 | AQ12: =(AP12/100)*3000 -> 1650 | AR12: =AR11 -> 61 | AS12: =(AR12/100)*3000 -> 1830 | AT12: =SUM(AO12+AQ12+AS12) -> 5490 | AU12: =AT11-AT12+AV12 -> 0 | AX12: =IF(AV12>0,AW12,AX11) -> 0.8
A13: =ELEC!C11 -> 44295 | B13: 217 | C13: 223 | D13: =C12-C13 -> 5 | E13: =D13*8.38 -> 41.9 | F13: 1808 | G13: =F13-F12 -> 3 | H13: 10857 | I13: =SUM(H13-H12) -> 232 | J13: =IF(G13>0,I13/G13,0) -> 77.333333 | K13: =K12 -> 2297 | L13: =K13-K12 -> 0 | M13: =M12 -> 169228 | N13: =M13-M12 -> 0 | O13: =O12 -> 1869 | P13: 2058 | Q13: 173309 | R13: =Q13-Q12 -> 94 | S13: =SUM(P13-P12) -> 1 | T13: =SUM(S13*$T$2) -> 0 | U13: =SUM(G13+L13+S13) -> 4 | V13: =R13+N13+I13:I13 -> 326 | W13: =SUM(V13/U13) -> 81.5 | X13: =X12 -> 2465 | Y13: =X13-X12 -> 0 | Z13: =Z12 -> 138740 | AA13: =Z13-Z12 -> 0 | AB13: =SUM(Y13*$AB$2) -> 0 | AC13: =AC12 -> 1936 | AD13: =AC13-AC12 -> 0 | AE13: =AE12 -> 365520.8 | AF13: =AE13-AE12 -> 0 | AG13: =IF(AD13>0,AF13/AD13,0) -> 0 | AH13: =AF13+AA13 -> 0 | AI13: =SUM(AH13+V13) -> 326 | AJ13: =-tanks!AW14 -> 326 | AK13: =SUM(AJ13-AI13) -> 0 | AL13: =S13+L13+G13 -> 4 | AM13: =Y13+AD13 -> 0 | AN13: =AN12 -> 67 | AO13: =(AN13/100)*3000 -> 2010 | AP13: =AP12 -> 55 | AQ13: =(AP13/100)*3000 -> 1650 | AR13: =AR12 -> 61 | AS13: =(AR13/100)*3000 -> 1830 | AT13: =SUM(AO13+AQ13+AS13) -> 5490 | AU13: =AT12-AT13+AV13 -> 0 | AX13: =IF(AV13>0,AW13,AX12) -> 0.8
A14: =ELEC!C12 -> 44296 | B14: 211 | C14: 218 | D14: =C13-C14 -> 5 | E14: =D14*8.38 -> 41.9 | F14: 1809 | G14: =F14-F13 -> 1 | H14: 10998 | I14: =SUM(H14-H13) -> 141 | J14: =IF(G14>0,I14/G14,0) -> 141 | K14: 2301 | L14: =K14-K13 -> 4 | M14: 169496 | N14: =M14-M13 -> 268 | O14: =O13 -> 1869 | P14: =P13 -> 2058 | Q14: =Q13 -> 173309 | R14: =Q14-Q13 -> 0 | S14: =SUM(P14-P13) -> 0 | T14: =SUM(S14*$T$2) -> 0 | U14: =SUM(G14+L14+S14) -> 5 | V14: =R14+N14+I14:I14 -> 409 | W14: =SUM(V14/U14) -> 81.8 | X14: =X13 -> 2465 | Y14: =X14-X13 -> 0 | Z14: =Z13 -> 138740 | AA14: =Z14-Z13 -> 0 | AB14: =SUM(Y14*$AB$2) -> 0 | AC14: =AC13 -> 1936 | AD14: =AC14-AC13 -> 0 | AE14: =AE13 -> 365520.8 | AF14: =AE14-AE13 -> 0 | AG14: =IF(AD14>0,AF14/AD14,0) -> 0 | AH14: =AF14+AA14 -> 0 | AI14: =SUM(AH14+V14) -> 409 | AJ14: =-tanks!AW15 -> 409 | AK14: =SUM(AJ14-AI14) -> 0 | AL14: =S14+L14+G14 -> 5 | AM14: =Y14+AD14 -> 0 | AN14: =AN13 -> 67 | AO14: =(AN14/100)*3000 -> 2010 | AP14: =AP13 -> 55 | AQ14: =(AP14/100)*3000 -> 1650 | AR14: =AR13 -> 61 | AS14: =(AR14/100)*3000 -> 1830 | AT14: =SUM(AO14+AQ14+AS14) -> 5490 | AU14: =AT13-AT14+AV14 -> 0 | AX14: =IF(AV14>0,AW14,AX13) -> 0.8
A15: =ELEC!C13 -> 44297 | B15: 207 | C15: 213 | D15: =C14-C15 -> 5 | E15: =D15*8.38 -> 41.9 | F15: =F14 -> 1809 | G15: =F15-F14 -> 0 | H15: =H14 -> 10998 | I15: =SUM(H15-H14) -> 0 | J15: =IF(G15>0,I15/G15,0) -> 0 | K15: 2302 | L15: =K15-K14 -> 1 | M15: 169624 | N15: =M15-M14 -> 128 | O15: =O14 -> 1869 | P15: 2061 | Q15: 173549 | R15: =Q15-Q14 -> 240 | S15: =SUM(P15-P14) -> 3 | T15: =SUM(S15*$T$2) -> 0 | U15: =SUM(G15+L15+S15) -> 4 | V15: =R15+N15+I15:I15 -> 368 | W15: =SUM(V15/U15) -> 92 | X15: =X14 -> 2465 | Y15: =X15-X14 -> 0 | Z15: =Z14 -> 138740 | AA15: =Z15-Z14 -> 0 | AB15: =SUM(Y15*$AB$2) -> 0 | AC15: =AC14 -> 1936 | AD15: =AC15-AC14 -> 0 | AE15: =AE14 -> 365520.8 | AF15: =AE15-AE14 -> 0 | AG15: =IF(AD15>0,AF15/AD15,0) -> 0 | AH15: =AF15+AA15 -> 0 | AI15: =SUM(AH15+V15) -> 368 | AJ15: =-tanks!AW16 -> 368 | AK15: =SUM(AJ15-AI15) -> 0 | AL15: =S15+L15+G15 -> 4 | AM15: =Y15+AD15 -> 0 | AN15: =AN14 -> 67 | AO15: =(AN15/100)*3000 -> 2010 | AP15: =AP14 -> 55 | AQ15: =(AP15/100)*3000 -> 1650 | AR15: =AR14 -> 61 | AS15: =(AR15/100)*3000 -> 1830 | AT15: =SUM(AO15+AQ15+AS15) -> 5490 | AU15: =AT14-AT15+AV15 -> 0 | AX15: =IF(AV15>0,AW15,AX14) -> 0.8
A16: =ELEC!C14 -> 44298 | B16: 200 | C16: 207 | D16: =C15-C16 -> 6 | E16: =D16*8.38 -> 50.28 | F16: 1813 | G16: =F16-F15 -> 4 | H16: 11248 | I16: =SUM(H16-H15) -> 250 | J16: =IF(G16>0,I16/G16,0) -> 62.5 | K16: =K15 -> 2302 | L16: =K16-K15 -> 0 | M16: =M15 -> 169624 | N16: =M16-M15 -> 0 | O16: =O15 -> 1869 | P16: 2063 | Q16: 173666 | R16: =Q16-Q15 -> 117 | S16: =SUM(P16-P15) -> 2 | T16: =SUM(S16*$T$2) -> 0 | U16: =SUM(G16+L16+S16) -> 6 | V16: =R16+N16+I16:I16 -> 367 | W16: =SUM(V16/U16) -> 61.166667 | X16: =X15 -> 2465 | Y16: =X16-X15 -> 0 | Z16: =Z15 -> 138740 | AA16: =Z16-Z15 -> 0 | AB16: =SUM(Y16*$AB$2) -> 0 | AC16: =AC15 -> 1936 | AD16: =AC16-AC15 -> 0 | AE16: =AE15 -> 365520.8 | AF16: =AE16-AE15 -> 0 | AG16: =IF(AD16>0,AF16/AD16,0) -> 0 | AH16: =AF16+AA16 -> 0 | AI16: =SUM(AH16+V16) -> 367 | AJ16: =-tanks!AW17 -> 367 | AK16: =SUM(AJ16-AI16) -> 0 | AL16: =S16+L16+G16 -> 6 | AM16: =Y16+AD16 -> 0 | AN16: =AN15 -> 67 | AO16: =(AN16/100)*3000 -> 2010 | AP16: =AP15 -> 55 | AQ16: =(AP16/100)*3000 -> 1650 | AR16: =AR15 -> 61 | AS16: =(AR16/100)*3000 -> 1830 | AT16: =SUM(AO16+AQ16+AS16) -> 5490 | AU16: =AT15-AT16+AV16 -> 0 | AX16: =IF(AV16>0,AW16,AX15) -> 0.8
A17: =ELEC!C15 -> 44299 | B17: 195 | C17: 202 | D17: =C16-C17 -> 5 | E17: =D17*8.38 -> 41.9 | F17: 1814 | G17: =F17-F16 -> 1 | H17: 11361 | I17: =SUM(H17-H16) -> 113 | J17: =IF(G17>0,I17/G17,0) -> 113 | K17: 2305 | L17: 169842 | M17: =M16 -> 169624 | N17: =M17-M16 -> 0 | O17: =O16 -> 1869 | P17: =P16 -> 2063 | Q17: =Q16 -> 173666 | R17: =Q17-Q16 -> 0 | S17: =SUM(P17-P16) -> 0 | T17: =SUM(S17*$T$2) -> 0 | U17: =SUM(G17+L17+S17) -> 169843 | V17: =R17+N17+I17:I17 -> 113 | X17: =X16 -> 2465 | Y17: =X17-X16 -> 0 | Z17: =Z16 -> 138740 | AA17: =Z17-Z16 -> 0 | AB17: =SUM(Y17*$AB$2) -> 0 | AC17: =AC16 -> 1936 | AD17: =AC17-AC16 -> 0 | AE17: =AE16 -> 365520.8 | AF17: =AE17-AE16 -> 0 | AG17: =IF(AD17>0,AF17/AD17,0) -> 0 | AH17: =AF17+AA17 -> 0 | AI17: =SUM(AH17+V17) -> 113 | AJ17: =-tanks!AW18 -> 113 | AK17: =SUM(AJ17-AI17) -> 0 | AL17: =S17+L17+G17 -> 169843 | AM17: =Y17+AD17 -> 0 | AN17: =AN16 -> 67 | AO17: =(AN17/100)*3000 -> 2010 | AP17: =AP16 -> 55 | AQ17: =(AP17/100)*3000 -> 1650 | AR17: =AR16 -> 61 | AS17: =(AR17/100)*3000 -> 1830 | AT17: =SUM(AO17+AQ17+AS17) -> 5490 | AU17: =AT16-AT17+AV17 -> 0 | AX17: =IF(AV17>0,AW17,AX16) -> 0.8
A18: =ELEC!C16 -> 44300 | B18: 246 | C18: 252 | D18: =C17-C18 -> -50 | E18: =D18*8.38 -> -419 | F18: =F17 -> 1814 | G18: =F18-F17 -> 0 | H18: =H17 -> 11361 | I18: =SUM(H18-H17) -> 0 | J18: =IF(G18>0,I18/G18,0) -> 0 | K18: 2306 | L18: =K18-K17 -> 1 | M18: 169940 | N18: =M18-M17 -> 316 | O18: 1869 | P18: 2066 | Q18: 173941 | R18: =Q18-Q17 -> 275 | S18: =SUM(P18-P17) -> 3 | T18: =SUM(S18*$T$2) -> 0 | U18: =SUM(G18+L18+S18) -> 4 | V18: =R18+N18+I18:I18 -> 591 | X18: =X17 -> 2465 | Y18: =X18-X17 -> 0 | Z18: =Z17 -> 138740 | AA18: =Z18-Z17 -> 0 | AB18: =SUM(Y18*$AB$2) -> 0 | AC18: =AC17 -> 1936 | AD18: =AC18-AC17 -> 0 | AE18: =AE17 -> 365520.8 | AF18: =AE18-AE17 -> 0 | AG18: =IF(AD18>0,AF18/AD18,0) -> 0 | AH18: =AF18+AA18 -> 0 | AI18: =SUM(AH18+V18) -> 591 | AJ18: =-tanks!AW19 -> 591 | AK18: =SUM(AJ18-AI18) -> 0 | AL18: =S18+L18+G18 -> 4 | AM18: =Y18+AD18 -> 0 | AN18: =AN17 -> 67 | AO18: =(AN18/100)*3000 -> 2010 | AP18: =AP17 -> 55 | AQ18: =(AP18/100)*3000 -> 1650 | AR18: =AR17 -> 61 | AS18: =(AR18/100)*3000 -> 1830 | AT18: =SUM(AO18+AQ18+AS18) -> 5490 | AU18: =AT17-AT18+AV18 -> 0 | AX18: =IF(AV18>0,AW18,AX17) -> 0.8
A19: =ELEC!C17 -> 44301 | B19: 240 | C19: 247 | D19: =C18-C19 -> 5 | E19: =D19*8.38 -> 41.9 | F19: 1816 | G19: =F19-F18 -> 2 | H19: 11508 | I19: =SUM(H19-H18) -> 147 | J19: =IF(G19>0,I19/G19,0) -> 73.5 | K19: =K18 -> 2306 | L19: =K19-K18 -> 0 | M19: =M18 -> 169940 | N19: =M19-M18 -> 0 | O19: =O18 -> 1869 | P19: 2068 | Q19: 174085 | R19: =Q19-Q18 -> 144 | S19: =SUM(P19-P18) -> 2 | T19: =SUM(S19*$T$2) -> 0 | U19: =SUM(G19+L19+S19) -> 4 | V19: =R19+N19+I19:I19 -> 291 | X19: =X18 -> 2465 | Y19: =X19-X18 -> 0 | Z19: =Z18 -> 138740 | AA19: =Z19-Z18 -> 0 | AB19: =SUM(Y19*$AB$2) -> 0 | AC19: =AC18 -> 1936 | AD19: =AC19-AC18 -> 0 | AE19: =AE18 -> 365520.8 | AF19: =AE19-AE18 -> 0 | AG19: =IF(AD19>0,AF19/AD19,0) -> 0 | AH19: =AF19+AA19 -> 0 | AI19: =SUM(AH19+V19) -> 291 | AJ19: =-tanks!AW20 -> 291 | AK19: =SUM(AJ19-AI19) -> 0 | AL19: =S19+L19+G19 -> 4 | AM19: =Y19+AD19 -> 0 | AN19: =AN18 -> 67 | AO19: =(AN19/100)*3000 -> 2010 | AP19: =AP18 -> 55 | AQ19: =(AP19/100)*3000 -> 1650 | AR19: =AR18 -> 61 | AS19: =(AR19/100)*3000 -> 1830 | AT19: =SUM(AO19+AQ19+AS19) -> 5490 | AU19: =AT18-AT19+AV19 -> 0 | AX19: =IF(AV19>0,AW19,AX18) -> 0.8
A20: =ELEC!C18 -> 44302 | B20: =B19 -> 240 | C20: =C19 -> 247 | D20: =C19-C20 -> 0 | E20: =D20*8.38 -> 0 | F20: =F19 -> 1816 | G20: =F20-F19 -> 0 | H20: =H19 -> 11508 | I20: =SUM(H20-H19) -> 0 | J20: =IF(G20>0,I20/G20,0) -> 0 | K20: =K19 -> 2306 | L20: =K20-K19 -> 0 | M20: =M19 -> 169940 | N20: =M20-M19 -> 0 | O20: =O19 -> 1869 | P20: =P19 -> 2068 | Q20: =Q19 -> 174085 | R20: =Q20-Q19 -> 0 | S20: =SUM(P20-P19) -> 0 | T20: =SUM(S20*$T$2) -> 0 | U20: =SUM(G20+L20+S20) -> 0 | V20: =R20+N20+I20:I20 -> 0 | X20: =X19 -> 2465 | Y20: =X20-X19 -> 0 | Z20: =Z19 -> 138740 | AA20: =Z20-Z19 -> 0 | AB20: =SUM(Y20*$AB$2) -> 0 | AC20: =AC19 -> 1936 | AD20: =AC20-AC19 -> 0 | AE20: =AE19 -> 365520.8 | AF20: =AE20-AE19 -> 0 | AG20: =IF(AD20>0,AF20/AD20,0) -> 0 | AH20: =AF20+AA20 -> 0 | AI20: =SUM(AH20+V20) -> 0 | AJ20: =-tanks!AW21 -> 0 | AK20: =SUM(AJ20-AI20) -> 0 | AL20: =S20+L20+G20 -> 0 | AM20: =Y20+AD20 -> 0 | AN20: =AN19 -> 67 | AO20: =(AN20/100)*3000 -> 2010 | AP20: =AP19 -> 55 | AQ20: =(AP20/100)*3000 -> 1650 | AR20: =AR19 -> 61 | AS20: =(AR20/100)*3000 -> 1830 | AT20: =SUM(AO20+AQ20+AS20) -> 5490 | AU20: =AT19-AT20+AV20 -> 0 | AX20: =IF(AV20>0,AW20,AX19) -> 0.8
A21: =ELEC!C19 -> 44303 | B21: =B20 -> 240 | C21: =C20 -> 247 | D21: =C20-C21 -> 0 | E21: =D21*8.38 -> 0 | F21: =F20 -> 1816 | G21: =F21-F20 -> 0 | H21: =H20 -> 11508 | I21: =SUM(H21-H20) -> 0 | J21: =IF(G21>0,I21/G21,0) -> 0 | K21: =K20 -> 2306 | L21: =K21-K20 -> 0 | M21: =M20 -> 169940 | N21: =M21-M20 -> 0 | O21: =O20 -> 1869 | P21: =P20 -> 2068 | Q21: =Q20 -> 174085 | R21: =Q21-Q20 -> 0 | S21: =SUM(P21-P20) -> 0 | T21: =SUM(S21*$T$2) -> 0 | U21: =SUM(G21+L21+S21) -> 0 | V21: =R21+N21+I21:I21 -> 0 | X21: =X20 -> 2465 | Y21: =X21-X20 -> 0 | Z21: =Z20 -> 138740 | AA21: =Z21-Z20 -> 0 | AB21: =SUM(Y21*$AB$2) -> 0 | AC21: =AC20 -> 1936 | AD21: =AC21-AC20 -> 0 | AE21: =AE20 -> 365520.8 | AF21: =AE21-AE20 -> 0 | AG21: =IF(AD21>0,AF21/AD21,0) -> 0 | AH21: =AF21+AA21 -> 0 | AI21: =SUM(AH21+V21) -> 0 | AJ21: =-tanks!AW22 -> 0 | AK21: =SUM(AJ21-AI21) -> 0 | AL21: =S21+L21+G21 -> 0 | AM21: =Y21+AD21 -> 0 | AN21: =AN20 -> 67 | AO21: =(AN21/100)*3000 -> 2010 | AP21: =AP20 -> 55 | AQ21: =(AP21/100)*3000 -> 1650 | AR21: =AR20 -> 61 | AS21: =(AR21/100)*3000 -> 1830 | AT21: =SUM(AO21+AQ21+AS21) -> 5490 | AU21: =AT20-AT21+AV21 -> 0 | AX21: =IF(AV21>0,AW21,AX20) -> 0.8
A22: =ELEC!C20 -> 44304 | B22: =B21 -> 240 | C22: =C21 -> 247 | D22: =C21-C22 -> 0 | E22: =D22*8.38 -> 0 | F22: =F21 -> 1816 | G22: =F22-F21 -> 0 | H22: =H21 -> 11508 | I22: =SUM(H22-H21) -> 0 | J22: =IF(G22>0,I22/G22,0) -> 0 | K22: =K21 -> 2306 | L22: =K22-K21 -> 0 | M22: =M21 -> 169940 | N22: =M22-M21 -> 0 | O22: =O21 -> 1869 | P22: =P21 -> 2068 | Q22: =Q21 -> 174085 | R22: =Q22-Q21 -> 0 | S22: =SUM(P22-P21) -> 0 | T22: =SUM(S22*$T$2) -> 0 | U22: =SUM(G22+L22+S22) -> 0 | V22: =R22+N22+I22:I22 -> 0 | X22: =X21 -> 2465 | Y22: =X22-X21 -> 0 | Z22: =Z21 -> 138740 | AA22: =Z22-Z21 -> 0 | AB22: =SUM(Y22*$AB$2) -> 0 | AC22: =AC21 -> 1936 | AD22: =AC22-AC21 -> 0 | AE22: =AE21 -> 365520.8 | AF22: =AE22-AE21 -> 0 | AG22: =IF(AD22>0,AF22/AD22,0) -> 0 | AH22: =AF22+AA22 -> 0 | AI22: =SUM(AH22+V22) -> 0 | AJ22: =-tanks!AW23 -> 0 | AK22: =SUM(AJ22-AI22) -> 0 | AL22: =S22+L22+G22 -> 0 | AM22: =Y22+AD22 -> 0 | AN22: =AN21 -> 67 | AO22: =(AN22/100)*3000 -> 2010 | AP22: =AP21 -> 55 | AQ22: =(AP22/100)*3000 -> 1650 | AR22: =AR21 -> 61 | AS22: =(AR22/100)*3000 -> 1830 | AT22: =SUM(AO22+AQ22+AS22) -> 5490 | AU22: =AT21-AT22+AV22 -> 0 | AX22: =IF(AV22>0,AW22,AX21) -> 0.8
A23: =ELEC!C21 -> 44305 | B23: =B22 -> 240 | C23: =C22 -> 247 | D23: =C22-C23 -> 0 | E23: =D23*8.38 -> 0 | F23: =F22 -> 1816 | G23: =F23-F22 -> 0 | H23: =H22 -> 11508 | I23: =SUM(H23-H22) -> 0 | J23: =IF(G23>0,I23/G23,0) -> 0 | K23: =K22 -> 2306 | L23: =K23-K22 -> 0 | M23: =M22 -> 169940 | N23: =M23-M22 -> 0 | O23: =O22 -> 1869 | P23: =P22 -> 2068 | Q23: =Q22 -> 174085 | R23: =Q23-Q22 -> 0 | S23: =SUM(P23-P22) -> 0 | T23: =SUM(S23*$T$2) -> 0 | U23: =SUM(G23+L23+S23) -> 0 | V23: =R23+N23+I23:I23 -> 0 | X23: =X22 -> 2465 | Y23: =X23-X22 -> 0 | Z23: =Z22 -> 138740 | AA23: =Z23-Z22 -> 0 | AB23: =SUM(Y23*$AB$2) -> 0 | AC23: =AC22 -> 1936 | AD23: =AC23-AC22 -> 0 | AE23: =AE22 -> 365520.8 | AF23: =AE23-AE22 -> 0 | AG23: =IF(AD23>0,AF23/AD23,0) -> 0 | AH23: =AF23+AA23 -> 0 | AI23: =SUM(AH23+V23) -> 0 | AJ23: =-tanks!AW24 -> 0 | AK23: =SUM(AJ23-AI23) -> 0 | AL23: =S23+L23+G23 -> 0 | AM23: =Y23+AD23 -> 0 | AN23: =AN22 -> 67 | AO23: =(AN23/100)*3000 -> 2010 | AP23: =AP22 -> 55 | AQ23: =(AP23/100)*3000 -> 1650 | AR23: =AR22 -> 61 | AS23: =(AR23/100)*3000 -> 1830 | AT23: =SUM(AO23+AQ23+AS23) -> 5490 | AU23: =AT22-AT23+AV23 -> 0 | AX23: =IF(AV23>0,AW23,AX22) -> 0.8
A24: =ELEC!C22 -> 44306 | B24: =B23 -> 240 | C24: =C23 -> 247 | D24: =C23-C24 -> 0 | E24: =D24*8.38 -> 0 | F24: =F23 -> 1816 | G24: =F24-F23 -> 0 | H24: =H23 -> 11508 | I24: =SUM(H24-H23) -> 0 | J24: =IF(G24>0,I24/G24,0) -> 0 | K24: =K23 -> 2306 | L24: =K24-K23 -> 0 | M24: =M23 -> 169940 | N24: =M24-M23 -> 0 | O24: =O23 -> 1869 | P24: =P23 -> 2068 | Q24: =Q23 -> 174085 | R24: =Q24-Q23 -> 0 | S24: =SUM(P24-P23) -> 0 | T24: =SUM(S24*$T$2) -> 0 | U24: =SUM(G24+L24+S24) -> 0 | V24: =R24+N24+I24:I24 -> 0 | X24: =X23 -> 2465 | Y24: =X24-X23 -> 0 | Z24: =Z23 -> 138740 | AA24: =Z24-Z23 -> 0 | AB24: =SUM(Y24*$AB$2) -> 0 | AC24: =AC23 -> 1936 | AD24: =AC24-AC23 -> 0 | AE24: =AE23 -> 365520.8 | AF24: =AE24-AE23 -> 0 | AG24: =IF(AD24>0,AF24/AD24,0) -> 0 | AH24: =AF24+AA24 -> 0 | AI24: =SUM(AH24+V24) -> 0 | AJ24: =-tanks!AW25 -> 0 | AK24: =SUM(AJ24-AI24) -> 0 | AL24: =S24+L24+G24 -> 0 | AM24: =Y24+AD24 -> 0 | AN24: =AN23 -> 67 | AO24: =(AN24/100)*3000 -> 2010 | AP24: =AP23 -> 55 | AQ24: =(AP24/100)*3000 -> 1650 | AR24: =AR23 -> 61 | AS24: =(AR24/100)*3000 -> 1830 | AT24: =SUM(AO24+AQ24+AS24) -> 5490 | AU24: =AT23-AT24+AV24 -> 0 | AX24: =IF(AV24>0,AW24,AX23) -> 0.8
A25: =ELEC!C23 -> 44307 | B25: =B24 -> 240 | C25: =C24 -> 247 | D25: =C24-C25 -> 0 | E25: =D25*8.38 -> 0 | F25: =F24 -> 1816 | G25: =F25-F24 -> 0 | H25: =H24 -> 11508 | I25: =SUM(H25-H24) -> 0 | J25: =IF(G25>0,I25/G25,0) -> 0 | K25: =K24 -> 2306 | L25: =K25-K24 -> 0 | M25: =M24 -> 169940 | N25: =M25-M24 -> 0 | O25: =O24 -> 1869 | P25: =P24 -> 2068 | Q25: =Q24 -> 174085 | R25: =Q25-Q24 -> 0 | S25: =SUM(P25-P24) -> 0 | T25: =SUM(S25*$T$2) -> 0 | U25: =SUM(G25+L25+S25) -> 0 | V25: =R25+N25+I25:I25 -> 0 | X25: =X24 -> 2465 | Y25: =X25-X24 -> 0 | Z25: =Z24 -> 138740 | AA25: =Z25-Z24 -> 0 | AB25: =SUM(Y25*$AB$2) -> 0 | AC25: =AC24 -> 1936 | AD25: =AC25-AC24 -> 0 | AE25: =AE24 -> 365520.8 | AF25: =AE25-AE24 -> 0 | AG25: =IF(AD25>0,AF25/AD25,0) -> 0 | AH25: =AF25+AA25 -> 0 | AI25: =SUM(AH25+V25) -> 0 | AJ25: =-tanks!AW26 -> 0 | AK25: =SUM(AJ25-AI25) -> 0 | AL25: =S25+L25+G25 -> 0 | AM25: =Y25+AD25 -> 0 | AN25: =AN24 -> 67 | AO25: =(AN25/100)*3000 -> 2010 | AP25: =AP24 -> 55 | AQ25: =(AP25/100)*3000 -> 1650 | AR25: =AR24 -> 61 | AS25: =(AR25/100)*3000 -> 1830 | AT25: =SUM(AO25+AQ25+AS25) -> 5490 | AU25: =AT24-AT25+AV25 -> 0 | AX25: =IF(AV25>0,AW25,AX24) -> 0.8
A26: =ELEC!C24 -> 44308 | B26: =B25 -> 240 | C26: =C25 -> 247 | D26: =C25-C26 -> 0 | E26: =D26*8.38 -> 0 | F26: =F25 -> 1816 | G26: =F26-F25 -> 0 | H26: =H25 -> 11508 | I26: =SUM(H26-H25) -> 0 | J26: =IF(G26>0,I26/G26,0) -> 0 | K26: =K25 -> 2306 | L26: =K26-K25 -> 0 | M26: =M25 -> 169940 | N26: =M26-M25 -> 0 | O26: =O25 -> 1869 | P26: =P25 -> 2068 | Q26: =Q25 -> 174085 | R26: =Q26-Q25 -> 0 | S26: =SUM(P26-P25) -> 0 | T26: =SUM(S26*$T$2) -> 0 | U26: =SUM(G26+L26+S26) -> 0 | V26: =R26+N26+I26:I26 -> 0 | X26: =X25 -> 2465 | Y26: =X26-X25 -> 0 | Z26: =Z25 -> 138740 | AA26: =Z26-Z25 -> 0 | AB26: =SUM(Y26*$AB$2) -> 0 | AC26: =AC25 -> 1936 | AD26: =AC26-AC25 -> 0 | AE26: =AE25 -> 365520.8 | AF26: =AE26-AE25 -> 0 | AG26: =IF(AD26>0,AF26/AD26,0) -> 0 | AH26: =AF26+AA26 -> 0 | AI26: =SUM(AH26+V26) -> 0 | AJ26: =-tanks!AW27 -> 0 | AK26: =SUM(AJ26-AI26) -> 0 | AL26: =S26+L26+G26 -> 0 | AM26: =Y26+AD26 -> 0 | AN26: =AN25 -> 67 | AO26: =(AN26/100)*3000 -> 2010 | AP26: =AP25 -> 55 | AQ26: =(AP26/100)*3000 -> 1650 | AR26: =AR25 -> 61 | AS26: =(AR26/100)*3000 -> 1830 | AT26: =SUM(AO26+AQ26+AS26) -> 5490 | AU26: =AT25-AT26+AV26 -> 0 | AX26: =IF(AV26>0,AW26,AX25) -> 0.8
A27: =ELEC!C25 -> 44309 | B27: =B26 -> 240 | C27: =C26 -> 247 | D27: =C26-C27 -> 0 | E27: =D27*8.38 -> 0 | F27: =F26 -> 1816 | G27: =F27-F26 -> 0 | H27: =H26 -> 11508 | I27: =SUM(H27-H26) -> 0 | J27: =IF(G27>0,I27/G27,0) -> 0 | K27: =K26 -> 2306 | L27: =K27-K26 -> 0 | M27: =M26 -> 169940 | N27: =M27-M26 -> 0 | O27: =O26 -> 1869 | P27: =P26 -> 2068 | Q27: =Q26 -> 174085 | R27: =Q27-Q26 -> 0 | S27: =SUM(P27-P26) -> 0 | T27: =SUM(S27*$T$2) -> 0 | U27: =SUM(G27+L27+S27) -> 0 | V27: =R27+N27+I27:I27 -> 0 | X27: =X26 -> 2465 | Y27: =X27-X26 -> 0 | Z27: =Z26 -> 138740 | AA27: =Z27-Z26 -> 0 | AB27: =SUM(Y27*$AB$2) -> 0 | AC27: =AC26 -> 1936 | AD27: =AC27-AC26 -> 0 | AE27: =AE26 -> 365520.8 | AF27: =AE27-AE26 -> 0 | AG27: =IF(AD27>0,AF27/AD27,0) -> 0 | AH27: =AF27+AA27 -> 0 | AI27: =SUM(AH27+V27) -> 0 | AJ27: =-tanks!AW28 -> 0 | AK27: =SUM(AJ27-AI27) -> 0 | AL27: =S27+L27+G27 -> 0 | AM27: =Y27+AD27 -> 0 | AN27: =AN26 -> 67 | AO27: =(AN27/100)*3000 -> 2010 | AP27: =AP26 -> 55 | AQ27: =(AP27/100)*3000 -> 1650 | AR27: =AR26 -> 61 | AS27: =(AR27/100)*3000 -> 1830 | AT27: =SUM(AO27+AQ27+AS27) -> 5490 | AU27: =AT26-AT27+AV27 -> 0 | AX27: =IF(AV27>0,AW27,AX26) -> 0.8
