Workbook

Sheet Total Daily 
A1: Site Name | B1: Day | C1: Month | D1: Year | E1: Total Electricity Kwh | F1: Electricity Tariff ($/Kwh) | G1: LPG (Kg) | H1: LPG $/Kg | I1: District Energy Cooling Kwh | J1: District Energy Cooling $/Kwh | K1: Water Utility Supply (m3) m3 | L1: Water Utility Supply (m3) m3 | M1: Water Utility Supply (m3) $/m3 | N1: Room Nights
A2: Dubai DIFC | B2: 1 | C2: 4 | D2: 2021 | E2: ='4 - 2021'!B8-'4 - 2021'!B7+'4 - 2021'!C8-'4 - 2021'!C7 -> 8784 | F2: 0.118 | G2: =(('4 - 2021'!E8-'4 - 2021'!E7)+('4 - 2021'!F8-'4 - 2021'!F7)+('4 - 2021'!G8-'4 - 2021'!G7))*1.81 -> 132.1119 | H2: 0.99 | I2: ='4 - 2021'!J8-'4 - 2021'!J7 -> 22979 | J2: 0.081 | K2: ='4 - 2021'!H8-'4 - 2021'!H7 -> 0 | L2: ='4 - 2021'!I8-'4 - 2021'!I7 -> 101 | M2: 4.3936294 | N2: 73
A3: Dubai DIFC | B3: =B2+1 -> 2 | C3: 4 | D3: 2021 | E3: ='4 - 2021'!B9-'4 - 2021'!B8+'4 - 2021'!C9-'4 - 2021'!C8 -> 9031 | F3: 0.118 | G3: =(('4 - 2021'!E9-'4 - 2021'!E8)+('4 - 2021'!F9-'4 - 2021'!F8)+('4 - 2021'!G9-'4 - 2021'!G8))*1.81 -> 138.5736 | H3: 0.99 | I3: ='4 - 2021'!J9-'4 - 2021'!J8 -> 21493 | J3: 0.081 | K3: ='4 - 2021'!H9-'4 - 2021'!H8 -> 0 | L3: ='4 - 2021'!I9-'4 - 2021'!I8 -> 97 | M3: 4.3936294 | N3: 78
A4: Dubai DIFC | B4: =B3+1 -> 3 | C4: 4 | D4: 2021 | E4: ='4 - 2021'!B10-'4 - 2021'!B9+'4 - 2021'!C10-'4 - 2021'!C9 -> 8772 | F4: 0.118 | G4: =(('4 - 2021'!E10-'4 - 2021'!E9)+('4 - 2021'!F10-'4 - 2021'!F9)+('4 - 2021'!G10-'4 - 2021'!G9))*1.81 -> 139.1347 | H4: 0.99 | I4: ='4 - 2021'!J10-'4 - 2021'!J9 -> 20619 | J4: 0.081 | K4: ='4 - 2021'!H10-'4 - 2021'!H9 -> 0 | L4: ='4 - 2021'!I10-'4 - 2021'!I9 -> 84 | M4: 4.3936294 | N4: 79
A5: Dubai DIFC | B5: =B4+1 -> 4 | C5: 4 | D5: 2021 | E5: ='4 - 2021'!B11-'4 - 2021'!B10+'4 - 2021'!C11-'4 - 2021'!C10 -> 8857 | F5: 0.118 | G5: =(('4 - 2021'!E11-'4 - 2021'!E10)+('4 - 2021'!F11-'4 - 2021'!F10)+('4 - 2021'!G11-'4 - 2021'!G10))*1.81 -> 138.7908 | H5: 0.99 | I5: ='4 - 2021'!J11-'4 - 2021'!J10 -> 19939 | J5: 0.081 | K5: ='4 - 2021'!H11-'4 - 2021'!H10 -> 0 | L5: ='4 - 2021'!I11-'4 - 2021'!I10 -> 101 | M5: 4.3936294 | N5: 86
A6: Dubai DIFC | B6: =B5+1 -> 5 | C6: 4 | D6: 2021 | E6: ='4 - 2021'!B12-'4 - 2021'!B11+'4 - 2021'!C12-'4 - 2021'!C11 -> 9039 | F6: 0.118 | G6: =(('4 - 2021'!E12-'4 - 2021'!E11)+('4 - 2021'!F12-'4 - 2021'!F11)+('4 - 2021'!G12-'4 - 2021'!G11))*1.81 -> 137.8677 | H6: 0.99 | I6: ='4 - 2021'!J12-'4 - 2021'!J11 -> 23039 | J6: 0.081 | K6: ='4 - 2021'!H12-'4 - 2021'!H11 -> 0 | L6: ='4 - 2021'!I12-'4 - 2021'!I11 -> 100 | M6: 4.3936294 | N6: 82
A7: Dubai DIFC | B7: =B6+1 -> 6 | C7: 4 | D7: 2021 | E7: ='4 - 2021'!B13-'4 - 2021'!B12+'4 - 2021'!C13-'4 - 2021'!C12 -> 8921 | F7: 0.118 | G7: =(('4 - 2021'!E13-'4 - 2021'!E12)+('4 - 2021'!F13-'4 - 2021'!F12)+('4 - 2021'!G13-'4 - 2021'!G12))*1.81 -> 147.515 | H7: 0.99 | I7: ='4 - 2021'!J13-'4 - 2021'!J12 -> 20586 | J7: 0.081 | K7: ='4 - 2021'!H13-'4 - 2021'!H12 -> 0 | L7: ='4 - 2021'!I13-'4 - 2021'!I12 -> 93 | M7: 4.3936294 | N7: 86
A8: Dubai DIFC | B8: =B7+1 -> 7 | C8: 4 | D8: 2021 | E8: ='4 - 2021'!B14-'4 - 2021'!B13+'4 - 2021'!C14-'4 - 2021'!C13 -> 8972 | F8: 0.118 | G8: =(('4 - 2021'!E14-'4 - 2021'!E13)+('4 - 2021'!F14-'4 - 2021'!F13)+('4 - 2021'!G14-'4 - 2021'!G13))*1.81 -> 137.1256 | H8: 0.99 | I8: ='4 - 2021'!J14-'4 - 2021'!J13 -> 19080 | J8: 0.081 | K8: ='4 - 2021'!H14-'4 - 2021'!H13 -> 0 | L8: ='4 - 2021'!I14-'4 - 2021'!I13 -> 102 | M8: 4.3936294 | N8: 91
A9: Dubai DIFC | B9: =B8+1 -> 8 | C9: 4 | D9: 2021 | E9: ='4 - 2021'!B15-'4 - 2021'!B14+'4 - 2021'!C15-'4 - 2021'!C14 -> 8435 | F9: 0.118 | G9: 134 | H9: 0.99 | I9: ='4 - 2021'!J15-'4 - 2021'!J14 -> 19506 | J9: 0.081 | K9: ='4 - 2021'!H15-'4 - 2021'!H14 -> 0 | L9: ='4 - 2021'!I15-'4 - 2021'!I14 -> 101 | M9: 4.3936294 | N9: 91
A10: Dubai DIFC | B10: =B9+1 -> 9 | C10: 4 | D10: 2021 | E10: ='4 - 2021'!B16-'4 - 2021'!B15+'4 - 2021'!C16-'4 - 2021'!C15 -> 8940 | F10: 0.118 | G10: =(('4 - 2021'!E16-'4 - 2021'!E15)+('4 - 2021'!F16-'4 - 2021'!F15)+('4 - 2021'!G16-'4 - 2021'!G15))*1.81 -> 142.7728 | H10: 0.99 | I10: ='4 - 2021'!J16-'4 - 2021'!J15 -> 21047 | J10: 0.081 | K10: ='4 - 2021'!H16-'4 - 2021'!H15 -> 0 | L10: ='4 - 2021'!I16-'4 - 2021'!I15 -> 114 | M10: 4.3936294 | N10: 89
A11: Dubai DIFC | B11: =B10+1 -> 10 | C11: 4 | D11: 2021 | E11: ='4 - 2021'!B17-'4 - 2021'!B16+'4 - 2021'!C17-'4 - 2021'!C16 -> 8887 | F11: 0.118 | G11: =(('4 - 2021'!E17-'4 - 2021'!E16)+('4 - 2021'!F17-'4 - 2021'!F16)+('4 - 2021'!G17-'4 - 2021'!G16))*1.81 -> 142.1031 | H11: 0.99 | I11: ='4 - 2021'!J17-'4 - 2021'!J16 -> 22058 | J11: 0.081 | K11: ='4 - 2021'!H17-'4 - 2021'!H16 -> 0 | L11: ='4 - 2021'!I17-'4 - 2021'!I16 -> 92 | M11: 4.3936294 | N11: 81
A12: Dubai DIFC | B12: =B11+1 -> 11 | C12: 4 | D12: 2021 | E12: ='4 - 2021'!B18-'4 - 2021'!B17+'4 - 2021'!C18-'4 - 2021'!C17 -> 8562 | F12: 0.118 | G12: =(('4 - 2021'!E18-'4 - 2021'!E17)+('4 - 2021'!F18-'4 - 2021'!F17)+('4 - 2021'!G18-'4 - 2021'!G17))*1.81 -> 133.6323 | H12: 0.99 | I12: ='4 - 2021'!J18-'4 - 2021'!J17 -> 20630 | J12: 0.081 | K12: ='4 - 2021'!H18-'4 - 2021'!H17 -> 0 | L12: ='4 - 2021'!I18-'4 - 2021'!I17 -> 106 | M12: 4.3936294 | N12: 95
A13: Dubai DIFC | B13: =B12+1 -> 12 | C13: 4 | D13: 2021 | E13: ='4 - 2021'!B19-'4 - 2021'!B18+'4 - 2021'!C19-'4 - 2021'!C18 -> 8768 | F13: 0.118 | G13: =(('4 - 2021'!E19-'4 - 2021'!E18)+('4 - 2021'!F19-'4 - 2021'!F18)+('4 - 2021'!G19-'4 - 2021'!G18))*1.81 -> 141.8859 | H13: 0.99 | I13: ='4 - 2021'!J19-'4 - 2021'!J18 -> 21269 | J13: 0.081 | K13: ='4 - 2021'!H19-'4 - 2021'!H18 -> 0 | L13: ='4 - 2021'!I19-'4 - 2021'!I18 -> 107 | M13: 4.3936294 | N13: 92
A14: Dubai DIFC | B14: =B13+1 -> 13 | C14: 4 | D14: 2021 | E14: ='4 - 2021'!B20-'4 - 2021'!B19+'4 - 2021'!C20-'4 - 2021'!C19 -> 8651 | F14: 0.118 | G14: =(('4 - 2021'!E20-'4 - 2021'!E19)+('4 - 2021'!F20-'4 - 2021'!F19)+('4 - 2021'!G20-'4 - 2021'!G19))*1.81 -> 141.4877 | H14: 0.99 | I14: ='4 - 2021'!J20-'4 - 2021'!J19 -> 22164 | J14: 0.081 | K14: ='4 - 2021'!H20-'4 - 2021'!H19 -> 0 | L14: ='4 - 2021'!I20-'4 - 2021'!I19 -> 95 | M14: 4.3936294 | N14: 74
A15: Dubai DIFC | B15: =B14+1 -> 14 | C15: 4 | D15: 2021 | E15: ='4 - 2021'!B21-'4 - 2021'!B20+'4 - 2021'!C21-'4 - 2021'!C20 -> 8745 | F15: 0.118 | G15: =(('4 - 2021'!E21-'4 - 2021'!E20)+('4 - 2021'!F21-'4 - 2021'!F20)+('4 - 2021'!G21-'4 - 2021'!G20))*1.81 -> 131.406 | H15: 0.99 | I15: ='4 - 2021'!J21-'4 - 2021'!J20 -> 20808 | J15: 0.081 | K15: ='4 - 2021'!H21-'4 - 2021'!H20 -> 0 | L15: ='4 - 2021'!I21-'4 - 2021'!I20 -> 93 | M15: 4.3936294 | N15: 77
A16: Dubai DIFC | B16: =B15+1 -> 15 | C16: 4 | D16: 2021 | E16: ='4 - 2021'!B22-'4 - 2021'!B21+'4 - 2021'!C22-'4 - 2021'!C21 -> 8919 | F16: 0.118 | G16: =(('4 - 2021'!E22-'4 - 2021'!E21)+('4 - 2021'!F22-'4 - 2021'!F21)+('4 - 2021'!G22-'4 - 2021'!G21))*1.81 -> 142.1755 | H16: 0.99 | I16: ='4 - 2021'!J22-'4 - 2021'!J21 -> 21954 | J16: 0.081 | K16: ='4 - 2021'!H22-'4 - 2021'!H21 -> 0 | L16: ='4 - 2021'!I22-'4 - 2021'!I21 -> 101 | M16: 4.3936294 | N16: 74
A17: Dubai DIFC | B17: =B16+1 -> 16 | C17: 4 | D17: 2021 | E17: ='4 - 2021'!B23-'4 - 2021'!B22+'4 - 2021'!C23-'4 - 2021'!C22 -> 9176 | F17: 0.118 | G17: =(('4 - 2021'!E23-'4 - 2021'!E22)+('4 - 2021'!F23-'4 - 2021'!F22)+('4 - 2021'!G23-'4 - 2021'!G22))*1.81 -> 150.773 | H17: 0.99 | I17: ='4 - 2021'!J23-'4 - 2021'!J22 -> 23756 | J17: 0.081 | K17: ='4 - 2021'!H23-'4 - 2021'!H22 -> 0 | L17: ='4 - 2021'!I23-'4 - 2021'!I22 -> 104 | M17: 4.3936294 | N17: 67
A18: Dubai DIFC | B18: =B17+1 -> 17 | C18: 4 | D18: 2021 | E18: ='4 - 2021'!B24-'4 - 2021'!B23+'4 - 2021'!C24-'4 - 2021'!C23 -> 8947 | F18: 0.118 | G18: =(('4 - 2021'!E24-'4 - 2021'!E23)+('4 - 2021'!F24-'4 - 2021'!F23)+('4 - 2021'!G24-'4 - 2021'!G23))*1.81 -> 151.8409 | H18: 0.99 | I18: ='4 - 2021'!J24-'4 - 2021'!J23 -> 23095 | J18: 0.081 | K18: ='4 - 2021'!H24-'4 - 2021'!H23 -> 0 | L18: ='4 - 2021'!I24-'4 - 2021'!I23 -> 99 | M18: 4.3936294 | N18: 57
A19: Dubai DIFC | B19: =B18+1 -> 18 | C19: 4 | D19: 2021 | E19: 0 | F19: 0.118 | G19: 0 | H19: 0.99 | I19: 0 | J19: 0.081 | K19: 0 | L19: 0 | M19: 4.3936294
A20: Dubai DIFC | B20: =B19+1 -> 19 | C20: 4 | D20: 2021 | E20: ='4 - 2021'!B26-'4 - 2021'!B25+'4 - 2021'!C26-'4 - 2021'!C25 -> 0 | F20: 0.118 | G20: =(('4 - 2021'!E26-'4 - 2021'!E25)+('4 - 2021'!F26-'4 - 2021'!F25)+('4 - 2021'!G26-'4 - 2021'!G25))*1.81 -> 0 | H20: 0.99 | I20: ='4 - 2021'!J26-'4 - 2021'!J25 -> 0 | J20: 0.081 | K20: ='4 - 2021'!H26-'4 - 2021'!H25 -> 0 | L20: ='4 - 2021'!I26-'4 - 2021'!I25 -> 0 | M20: 4.3936294
A21: Dubai DIFC | B21: =B20+1 -> 20 | C21: 4 | D21: 2021 | E21: ='4 - 2021'!B27-'4 - 2021'!B26+'4 - 2021'!C27-'4 - 2021'!C26 -> 0 | F21: 0.118 | G21: =(('4 - 2021'!E27-'4 - 2021'!E26)+('4 - 2021'!F27-'4 - 2021'!F26)+('4 - 2021'!G27-'4 - 2021'!G26))*1.81 -> 0 | H21: 0.99 | I21: ='4 - 2021'!J27-'4 - 2021'!J26 -> 0 | J21: 0.081 | K21: ='4 - 2021'!H27-'4 - 2021'!H26 -> 0 | L21: ='4 - 2021'!I27-'4 - 2021'!I26 -> 0 | M21: 4.3936294
A22: Dubai DIFC | B22: =B21+1 -> 21 | C22: 4 | D22: 2021 | E22: ='4 - 2021'!B28-'4 - 2021'!B27+'4 - 2021'!C28-'4 - 2021'!C27 -> 0 | F22: 0.118 | G22: =(('4 - 2021'!E28-'4 - 2021'!E27)+('4 - 2021'!F28-'4 - 2021'!F27)+('4 - 2021'!G28-'4 - 2021'!G27))*1.81 -> 0 | H22: 0.99 | I22: ='4 - 2021'!J28-'4 - 2021'!J27 -> 0 | J22: 0.081 | K22: ='4 - 2021'!H28-'4 - 2021'!H27 -> 0 | L22: ='4 - 2021'!I28-'4 - 2021'!I27 -> 0 | M22: 4.3936294
A23: Dubai DIFC | B23: =B22+1 -> 22 | C23: 4 | D23: 2021 | E23: ='4 - 2021'!B29-'4 - 2021'!B28+'4 - 2021'!C29-'4 - 2021'!C28 -> 0 | F23: 0.118 | G23: =(('4 - 2021'!E29-'4 - 2021'!E28)+('4 - 2021'!F29-'4 - 2021'!F28)+('4 - 2021'!G29-'4 - 2021'!G28))*1.81 -> 0 | H23: 0.99 | I23: ='4 - 2021'!J29-'4 - 2021'!J28 -> 0 | J23: 0.081 | K23: ='4 - 2021'!H29-'4 - 2021'!H28 -> 0 | L23: ='4 - 2021'!I29-'4 - 2021'!I28 -> 0 | M23: 4.3936294
A24: Dubai DIFC | B24: =B23+1 -> 23 | C24: 4 | D24: 2021 | E24: ='4 - 2021'!B30-'4 - 2021'!B29+'4 - 2021'!C30-'4 - 2021'!C29 -> 0 | F24: 0.118 | G24: =(('4 - 2021'!E30-'4 - 2021'!E29)+('4 - 2021'!F30-'4 - 2021'!F29)+('4 - 2021'!G30-'4 - 2021'!G29))*1.81 -> 0 | H24: 0.99 | I24: ='4 - 2021'!J30-'4 - 2021'!J29 -> 0 | J24: 0.081 | K24: ='4 - 2021'!H30-'4 - 2021'!H29 -> 0 | L24: ='4 - 2021'!I30-'4 - 2021'!I29 -> 0 | M24: 4.3936294
A25: Dubai DIFC | B25: =B24+1 -> 24 | C25: 4 | D25: 2021 | E25: ='4 - 2021'!B31-'4 - 2021'!B30+'4 - 2021'!C31-'4 - 2021'!C30 -> 0 | F25: 0.118 | G25: =(('4 - 2021'!E31-'4 - 2021'!E30)+('4 - 2021'!F31-'4 - 2021'!F30)+('4 - 2021'!G31-'4 - 2021'!G30))*1.81 -> 0 | H25: 0.99 | I25: ='4 - 2021'!J31-'4 - 2021'!J30 -> 0 | J25: 0.081 | K25: ='4 - 2021'!H31-'4 - 2021'!H30 -> 0 | L25: ='4 - 2021'!I31-'4 - 2021'!I30 -> 0 | M25: 4.3936294
A26: Dubai DIFC | B26: =B25+1 -> 25 | C26: 4 | D26: 2021 | E26: ='4 - 2021'!B32-'4 - 2021'!B31+'4 - 2021'!C32-'4 - 2021'!C31 -> 0 | F26: 0.118 | G26: =(('4 - 2021'!E32-'4 - 2021'!E31)+('4 - 2021'!F32-'4 - 2021'!F31)+('4 - 2021'!G32-'4 - 2021'!G31))*1.81 -> 0 | H26: 0.99 | I26: ='4 - 2021'!J32-'4 - 2021'!J31 -> 0 | J26: 0.081 | K26: ='4 - 2021'!H32-'4 - 2021'!H31 -> 0 | L26: ='4 - 2021'!I32-'4 - 2021'!I31 -> 0 | M26: 4.3936294
A27: Dubai DIFC | B27: =B26+1 -> 26 | C27: 4 | D27: 2021 | E27: ='4 - 2021'!B33-'4 - 2021'!B32+'4 - 2021'!C33-'4 - 2021'!C32 -> 0 | F27: 0.118 | G27: =(('4 - 2021'!E33-'4 - 2021'!E32)+('4 - 2021'!F33-'4 - 2021'!F32)+('4 - 2021'!G33-'4 - 2021'!G32))*1.81 -> 0 | H27: 0.99 | I27: ='4 - 2021'!J33-'4 - 2021'!J32 -> 0 | J27: 0.081 | K27: ='4 - 2021'!H33-'4 - 2021'!H32 -> 0 | L27: ='4 - 2021'!I33-'4 - 2021'!I32 -> 0 | M27: 4.3936294
A28: Dubai DIFC | B28: =B27+1 -> 27 | C28: 4 | D28: 2021 | E28: ='4 - 2021'!B34-'4 - 2021'!B33+'4 - 2021'!C34-'4 - 2021'!C33 -> 0 | F28: 0.118 | G28: =(('4 - 2021'!E34-'4 - 2021'!E33)+('4 - 2021'!F34-'4 - 2021'!F33)+('4 - 2021'!G34-'4 - 2021'!G33))*1.81 -> 0 | H28: 0.99 | I28: ='4 - 2021'!J34-'4 - 2021'!J33 -> 0 | J28: 0.081 | K28: ='4 - 2021'!H34-'4 - 2021'!H33 -> 0 | L28: ='4 - 2021'!I34-'4 - 2021'!I33 -> 0 | M28: 4.3936294
A29: Dubai DIFC | B29: =B28+1 -> 28 | C29: 4 | D29: 2021 | E29: ='4 - 2021'!B35-'4 - 2021'!B34+'4 - 2021'!C35-'4 - 2021'!C34 -> 0 | F29: 0.118 | G29: =(('4 - 2021'!E35-'4 - 2021'!E34)+('4 - 2021'!F35-'4 - 2021'!F34)+('4 - 2021'!G35-'4 - 2021'!G34))*1.81 -> 0 | H29: 0.99 | I29: ='4 - 2021'!J35-'4 - 2021'!J34 -> 0 | J29: 0.081 | K29: ='4 - 2021'!H35-'4 - 2021'!H34 -> 0 | L29: ='4 - 2021'!I35-'4 - 2021'!I34 -> 0 | M29: 4.3936294
A30: Dubai DIFC | B30: =B29+1 -> 29 | C30: 4 | D30: 2021 | E30: ='4 - 2021'!B36-'4 - 2021'!B35+'4 - 2021'!C36-'4 - 2021'!C35 -> 0 | F30: 0.118 | G30: =(('4 - 2021'!E36-'4 - 2021'!E35)+('4 - 2021'!F36-'4 - 2021'!F35)+('4 - 2021'!G36-'4 - 2021'!G35))*1.81 -> 0 | H30: 0.99 | I30: ='4 - 2021'!J36-'4 - 2021'!J35 -> 0 | J30: 0.081 | K30: ='4 - 2021'!H36-'4 - 2021'!H35 -> 0 | L30: ='4 - 2021'!I36-'4 - 2021'!I35 -> 0 | M30: 4.3936294
A31: Dubai DIFC | B31: =B30+1 -> 30 | C31: 4 | D31: 2021 | E31: ='4 - 2021'!B37-'4 - 2021'!B36+'4 - 2021'!C37-'4 - 2021'!C36 -> 0 | F31: 0.118 | G31: =(('4 - 2021'!E37-'4 - 2021'!E36)+('4 - 2021'!F37-'4 - 2021'!F36)+('4 - 2021'!G37-'4 - 2021'!G36))*1.81 -> 0 | H31: 0.99 | I31: ='4 - 2021'!J37-'4 - 2021'!J36 -> 0 | J31: 0.081 | K31: ='4 - 2021'!H37-'4 - 2021'!H36 -> 0 | L31: ='4 - 2021'!I37-'4 - 2021'!I36 -> 0 | M31: 4.3936294

Sheet Submetering Daily 
A1: Site Name | B1: Day | C1: Month | D1: Year | E1: Panel LV1 Kwh | F1: Panel LV2 Kwh | G1: Electricity Tariff ($/Kwh) | H1: Main Kitchen LPG (Kg) | I1: Podium Kitchen LPG (Kg) | J1: Boiler LPG (Kg) | K1: LPG $/Kg | L1: Room Nights
A2: Dubai DIFC | B2: 1 | C2: 4 | D2: 2021 | E2: ='4 - 2021'!B8-'4 - 2021'!B7 -> 3061 | F2: ='4 - 2021'!C8-'4 - 2021'!C7 -> 5723 | G2: 0.118 | H2: ='4 - 2021'!E8-'4 - 2021'!E7 -> 26 | I2: ='4 - 2021'!F8-'4 - 2021'!F7 -> 5.2 | J2: ='4 - 2021'!G8-'4 - 2021'!G7 -> 41.79 | K2: 0.74 | L2: 73
A3: Dubai DIFC | B3: =B2+1 -> 2 | C3: 4 | D3: 2021 | E3: ='4 - 2021'!B9-'4 - 2021'!B8 -> 3359 | F3: ='4 - 2021'!C9-'4 - 2021'!C8 -> 5672 | G3: 0.118 | H3: ='4 - 2021'!E9-'4 - 2021'!E8 -> 26 | I3: ='4 - 2021'!F9-'4 - 2021'!F8 -> 5.13 | J3: ='4 - 2021'!G9-'4 - 2021'!G8 -> 45.43 | K3: 0.74 | L3: 78
A4: Dubai DIFC | B4: =B3+1 -> 3 | C4: 4 | D4: 2021 | E4: ='4 - 2021'!B10-'4 - 2021'!B9 -> 3219 | F4: ='4 - 2021'!C10-'4 - 2021'!C9 -> 5553 | G4: 0.118 | H4: ='4 - 2021'!E10-'4 - 2021'!E9 -> 26 | I4: ='4 - 2021'!F10-'4 - 2021'!F9 -> 5.41 | J4: ='4 - 2021'!G10-'4 - 2021'!G9 -> 45.46 | K4: 0.74 | L4: 79
A5: Dubai DIFC | B5: =B4+1 -> 4 | C5: 4 | D5: 2021 | E5: ='4 - 2021'!B11-'4 - 2021'!B10 -> 3257 | F5: ='4 - 2021'!C11-'4 - 2021'!C10 -> 5600 | G5: 0.118 | H5: ='4 - 2021'!E11-'4 - 2021'!E10 -> 26 | I5: ='4 - 2021'!F11-'4 - 2021'!F10 -> 5.31 | J5: ='4 - 2021'!G11-'4 - 2021'!G10 -> 45.37 | K5: 0.74 | L5: 86
A6: Dubai DIFC | B6: =B5+1 -> 5 | C6: 4 | D6: 2021 | E6: ='4 - 2021'!B12-'4 - 2021'!B11 -> 3540 | F6: ='4 - 2021'!C12-'4 - 2021'!C11 -> 5499 | G6: 0.118 | H6: ='4 - 2021'!E12-'4 - 2021'!E11 -> 26 | I6: ='4 - 2021'!F12-'4 - 2021'!F11 -> 5.41 | J6: ='4 - 2021'!G12-'4 - 2021'!G11 -> 44.76 | K6: 0.74 | L6: 82
A7: Dubai DIFC | B7: =B6+1 -> 6 | C7: 4 | D7: 2021 | E7: ='4 - 2021'!B13-'4 - 2021'!B12 -> 3440 | F7: ='4 - 2021'!C13-'4 - 2021'!C12 -> 5481 | G7: 0.118 | H7: ='4 - 2021'!E13-'4 - 2021'!E12 -> 26 | I7: ='4 - 2021'!F13-'4 - 2021'!F12 -> 5.32 | J7: ='4 - 2021'!G13-'4 - 2021'!G12 -> 50.18 | K7: 0.74 | L7: 86
A8: Dubai DIFC | B8: =B7+1 -> 7 | C8: 4 | D8: 2021 | E8: ='4 - 2021'!B14-'4 - 2021'!B13 -> 3428 | F8: ='4 - 2021'!C14-'4 - 2021'!C13 -> 5544 | G8: 0.118 | H8: ='4 - 2021'!E14-'4 - 2021'!E13 -> 26 | I8: ='4 - 2021'!F14-'4 - 2021'!F13 -> 5.08 | J8: ='4 - 2021'!G14-'4 - 2021'!G13 -> 44.68 | K8: 0.74 | L8: 91
A9: Dubai DIFC | B9: =B8+1 -> 8 | C9: 4 | D9: 2021 | E9: ='4 - 2021'!B15-'4 - 2021'!B14 -> 3200 | F9: ='4 - 2021'!C15-'4 - 2021'!C14 -> 5235 | G9: 0.118 | H9: 26 | I9: ='4 - 2021'!F15-'4 - 2021'!F14 -> 4.76 | J9: ='4 - 2021'!G15-'4 - 2021'!G14 -> 43.44 | K9: 0.74 | L9: 91
A10: Dubai DIFC | B10: =B9+1 -> 9 | C10: 4 | D10: 2021 | E10: ='4 - 2021'!B16-'4 - 2021'!B15 -> 3347 | F10: ='4 - 2021'!C16-'4 - 2021'!C15 -> 5593 | G10: 0.118 | H10: ='4 - 2021'!E16-'4 - 2021'!E15 -> 23.44 | I10: ='4 - 2021'!F16-'4 - 2021'!F15 -> 5.25 | J10: ='4 - 2021'!G16-'4 - 2021'!G15 -> 50.19 | K10: 0.74 | L10: 89
A11: Dubai DIFC | B11: =B10+1 -> 10 | C11: 4 | D11: 2021 | E11: ='4 - 2021'!B17-'4 - 2021'!B16 -> 3216 | F11: ='4 - 2021'!C17-'4 - 2021'!C16 -> 5671 | G11: 0.118 | H11: ='4 - 2021'!E17-'4 - 2021'!E16 -> 27.21 | I11: ='4 - 2021'!F17-'4 - 2021'!F16 -> 4.8 | J11: ='4 - 2021'!G17-'4 - 2021'!G16 -> 46.5 | K11: 0.74 | L11: 81
A12: Dubai DIFC | B12: =B11+1 -> 11 | C12: 4 | D12: 2021 | E12: ='4 - 2021'!B18-'4 - 2021'!B17 -> 3148 | F12: ='4 - 2021'!C18-'4 - 2021'!C17 -> 5414 | G12: 0.118 | H12: ='4 - 2021'!E18-'4 - 2021'!E17 -> 24.8 | I12: ='4 - 2021'!F18-'4 - 2021'!F17 -> 4.96 | J12: ='4 - 2021'!G18-'4 - 2021'!G17 -> 44.07 | K12: 0.74 | L12: 95
A13: Dubai DIFC | B13: =B12+1 -> 12 | C13: 4 | D13: 2021 | E13: ='4 - 2021'!B19-'4 - 2021'!B18 -> 3293 | F13: ='4 - 2021'!C19-'4 - 2021'!C18 -> 5475 | G13: 0.118 | H13: ='4 - 2021'!E19-'4 - 2021'!E18 -> 29.28 | I13: ='4 - 2021'!F19-'4 - 2021'!F18 -> 5.19 | J13: ='4 - 2021'!G19-'4 - 2021'!G18 -> 43.92 | K13: 0.74 | L13: 92
A14: Dubai DIFC | B14: =B13+1 -> 13 | C14: 4 | D14: 2021 | E14: ='4 - 2021'!B20-'4 - 2021'!B19 -> 3220 | F14: ='4 - 2021'!C20-'4 - 2021'!C19 -> 5431 | G14: 0.118 | H14: ='4 - 2021'!E20-'4 - 2021'!E19 -> 25.89 | I14: ='4 - 2021'!F20-'4 - 2021'!F19 -> 4.92 | J14: ='4 - 2021'!G20-'4 - 2021'!G19 -> 47.36 | K14: 0.74 | L14: 74
A15: Dubai DIFC | B15: =B14+1 -> 14 | C15: 4 | D15: 2021 | E15: ='4 - 2021'!B21-'4 - 2021'!B20 -> 3255 | F15: ='4 - 2021'!C21-'4 - 2021'!C20 -> 5490 | G15: 0.118 | H15: ='4 - 2021'!E21-'4 - 2021'!E20 -> 25.58 | I15: ='4 - 2021'!F21-'4 - 2021'!F20 -> 4.82 | J15: ='4 - 2021'!G21-'4 - 2021'!G20 -> 42.2 | K15: 0.74 | L15: 77
A16: Dubai DIFC | B16: =B15+1 -> 15 | C16: 4 | D16: 2021 | E16: ='4 - 2021'!B22-'4 - 2021'!B21 -> 3383 | F16: ='4 - 2021'!C22-'4 - 2021'!C21 -> 5536 | G16: 0.118 | H16: ='4 - 2021'!E22-'4 - 2021'!E21 -> 28.64 | I16: ='4 - 2021'!F22-'4 - 2021'!F21 -> 4.54 | J16: ='4 - 2021'!G22-'4 - 2021'!G21 -> 45.37 | K16: 0.74 | L16: 74
A17: Dubai DIFC | B17: =B16+1 -> 16 | C17: 4 | D17: 2021 | E17: ='4 - 2021'!B23-'4 - 2021'!B22 -> 3466 | F17: ='4 - 2021'!C23-'4 - 2021'!C22 -> 5710 | G17: 0.118 | H17: ='4 - 2021'!E23-'4 - 2021'!E22 -> 27.71 | I17: ='4 - 2021'!F23-'4 - 2021'!F22 -> 4.42 | J17: ='4 - 2021'!G23-'4 - 2021'!G22 -> 51.17 | K17: 0.74 | L17: 67
A18: Dubai DIFC | B18: =B17+1 -> 17 | C18: 4 | D18: 2021 | E18: ='4 - 2021'!B24-'4 - 2021'!B23 -> 3421 | F18: ='4 - 2021'!C24-'4 - 2021'!C23 -> 5526 | G18: 0.118 | H18: ='4 - 2021'!E24-'4 - 2021'!E23 -> 30.28 | I18: ='4 - 2021'!F24-'4 - 2021'!F23 -> 4.39 | J18: ='4 - 2021'!G24-'4 - 2021'!G23 -> 49.22 | K18: 0.74 | L18: 57
A19: Dubai DIFC | B19: =B18+1 -> 18 | C19: 4 | D19: 2021 | E19: 0 | F19: 0 | G19: 0.118 | H19: 0 | I19: 0 | J19: 0 | K19: 0.74
A20: Dubai DIFC | B20: =B19+1 -> 19 | C20: 4 | D20: 2021 | E20: ='4 - 2021'!B26-'4 - 2021'!B25 -> 0 | F20: ='4 - 2021'!C26-'4 - 2021'!C25 -> 0 | G20: 0.118 | H20: ='4 - 2021'!E26-'4 - 2021'!E25 -> 0 | I20: ='4 - 2021'!F26-'4 - 2021'!F25 -> 0 | J20: ='4 - 2021'!G26-'4 - 2021'!G25 -> 0 | K20: 0.74
A21: Dubai DIFC | B21: =B20+1 -> 20 | C21: 4 | D21: 2021 | E21: ='4 - 2021'!B27-'4 - 2021'!B26 -> 0 | F21: ='4 - 2021'!C27-'4 - 2021'!C26 -> 0 | G21: 0.118 | H21: ='4 - 2021'!E27-'4 - 2021'!E26 -> 0 | I21: ='4 - 2021'!F27-'4 - 2021'!F26 -> 0 | J21: ='4 - 2021'!G27-'4 - 2021'!G26 -> 0 | K21: 0.74
A22: Dubai DIFC | B22: =B21+1 -> 21 | C22: 4 | D22: 2021 | E22: ='4 - 2021'!B28-'4 - 2021'!B27 -> 0 | F22: ='4 - 2021'!C28-'4 - 2021'!C27 -> 0 | G22: 0.118 | H22: ='4 - 2021'!E28-'4 - 2021'!E27 -> 0 | I22: ='4 - 2021'!F28-'4 - 2021'!F27 -> 0 | J22: ='4 - 2021'!G28-'4 - 2021'!G27 -> 0 | K22: 0.74
A23: Dubai DIFC | B23: =B22+1 -> 22 | C23: 4 | D23: 2021 | E23: ='4 - 2021'!B29-'4 - 2021'!B28 -> 0 | F23: ='4 - 2021'!C29-'4 - 2021'!C28 -> 0 | G23: 0.118 | H23: ='4 - 2021'!E29-'4 - 2021'!E28 -> 0 | I23: ='4 - 2021'!F29-'4 - 2021'!F28 -> 0 | J23: ='4 - 2021'!G29-'4 - 2021'!G28 -> 0 | K23: 0.74
A24: Dubai DIFC | B24: =B23+1 -> 23 | C24: 4 | D24: 2021 | E24: ='4 - 2021'!B30-'4 - 2021'!B29 -> 0 | F24: ='4 - 2021'!C30-'4 - 2021'!C29 -> 0 | G24: 0.118 | H24: ='4 - 2021'!E30-'4 - 2021'!E29 -> 0 | I24: ='4 - 2021'!F30-'4 - 2021'!F29 -> 0 | J24: ='4 - 2021'!G30-'4 - 2021'!G29 -> 0 | K24: 0.74
A25: Dubai DIFC | B25: =B24+1 -> 24 | C25: 4 | D25: 2021 | E25: ='4 - 2021'!B31-'4 - 2021'!B30 -> 0 | F25: ='4 - 2021'!C31-'4 - 2021'!C30 -> 0 | G25: 0.118 | H25: ='4 - 2021'!E31-'4 - 2021'!E30 -> 0 | I25: ='4 - 2021'!F31-'4 - 2021'!F30 -> 0 | J25: ='4 - 2021'!G31-'4 - 2021'!G30 -> 0 | K25: 0.74
A26: Dubai DIFC | B26: =B25+1 -> 25 | C26: 4 | D26: 2021 | E26: ='4 - 2021'!B32-'4 - 2021'!B31 -> 0 | F26: ='4 - 2021'!C32-'4 - 2021'!C31 -> 0 | G26: 0.118 | H26: ='4 - 2021'!E32-'4 - 2021'!E31 -> 0 | I26: ='4 - 2021'!F32-'4 - 2021'!F31 -> 0 | J26: ='4 - 2021'!G32-'4 - 2021'!G31 -> 0 | K26: 0.74
A27: Dubai DIFC | B27: =B26+1 -> 26 | C27: 4 | D27: 2021 | E27: ='4 - 2021'!B33-'4 - 2021'!B32 -> 0 | F27: ='4 - 2021'!C33-'4 - 2021'!C32 -> 0 | G27: 0.118 | H27: ='4 - 2021'!E33-'4 - 2021'!E32 -> 0 | I27: ='4 - 2021'!F33-'4 - 2021'!F32 -> 0 | J27: ='4 - 2021'!G33-'4 - 2021'!G32 -> 0 | K27: 0.74
A28: Dubai DIFC | B28: =B27+1 -> 27 | C28: 4 | D28: 2021 | E28: ='4 - 2021'!B34-'4 - 2021'!B33 -> 0 | F28: ='4 - 2021'!C34-'4 - 2021'!C33 -> 0 | G28: 0.118 | H28: ='4 - 2021'!E34-'4 - 2021'!E33 -> 0 | I28: ='4 - 2021'!F34-'4 - 2021'!F33 -> 0 | J28: ='4 - 2021'!G34-'4 - 2021'!G33 -> 0 | K28: 0.74
A29: Dubai DIFC | B29: =B28+1 -> 28 | C29: 4 | D29: 2021 | E29: ='4 - 2021'!B35-'4 - 2021'!B34 -> 0 | F29: ='4 - 2021'!C35-'4 - 2021'!C34 -> 0 | G29: 0.118 | H29: ='4 - 2021'!E35-'4 - 2021'!E34 -> 0 | I29: ='4 - 2021'!F35-'4 - 2021'!F34 -> 0 | J29: ='4 - 2021'!G35-'4 - 2021'!G34 -> 0 | K29: 0.74
A30: Dubai DIFC | B30: =B29+1 -> 29 | C30: 4 | D30: 2021 | E30: ='4 - 2021'!B36-'4 - 2021'!B35 -> 0 | F30: ='4 - 2021'!C36-'4 - 2021'!C35 -> 0 | G30: 0.118 | H30: ='4 - 2021'!E36-'4 - 2021'!E35 -> 0 | I30: ='4 - 2021'!F36-'4 - 2021'!F35 -> 0 | J30: ='4 - 2021'!G36-'4 - 2021'!G35 -> 0 | K30: 0.74
A31: Dubai DIFC | B31: =B30+1 -> 30 | C31: 4 | D31: 2021 | E31: ='4 - 2021'!B37-'4 - 2021'!B36 -> 0 | F31: ='4 - 2021'!C37-'4 - 2021'!C36 -> 0 | G31: 0.118 | H31: ='4 - 2021'!E37-'4 - 2021'!E36 -> 0 | I31: ='4 - 2021'!F37-'4 - 2021'!F36 -> 0 | J31: ='4 - 2021'!G37-'4 - 2021'!G36 -> 0 | K31: 0.74

Sheet 4 - 2021
A3: FOUR SEASONS HOTEL - DIFC
A4: HLP READING MONTH OF APRIL' 2021
B5: Electricity | D5: LPG (cu.m) | H5: Water (cu.m) | J5: BTU
A6: Date | B6: LV-01, 2025952759 | C6: LV-2, 2030235407 | D6: Main Meter % | E6: Main Kitchen | F6: Podium Kitchen | G6: Boiler | H6: B-3 Water Meter (DIFC) | I6: MainWater Meter (DEWA) | J6: Chilled Water (KWH) | K6: Gas Received (Litres) | L6: Remark
A7: 44286 | B7: 509328 | C7: 455305 | D7: 0.55 | E7: 13687.97 | F7: 3279.36 | G7: 27719.1 | H7: 14528 | I7: 114409 | J7: 45003433
A8: =A7+1 -> 44287 | B8: 512389 | C8: 461028 | D8: 0.48 | E8: =E7+26 -> 13713.97 | F8: 3284.56 | G8: 27760.89 | H8: 14528 | I8: 114510 | J8: 45026412
A9: =A8+1 -> 44288 | B9: 515748 | C9: 466700 | D9: 0.4 | E9: =E8+26 -> 13739.97 | F9: 3289.69 | G9: 27806.32 | H9: 14528 | I9: 114607 | J9: 45047905
A10: =A9+1 -> 44289 | B10: 518967 | C10: 472253 | D10: 0.32 | E10: 13765.97 | F10: 3295.1 | G10: 27851.78 | H10: 14528 | I10: 114691 | J10: 45068524
A11: =A10+1 -> 44290 | B11: 522224 | C11: 477853 | D11: 0.8 | E11: =E10+26 -> 13791.97 | F11: 3300.41 | G11: 27897.15 | H11: 14528 | I11: 114792 | J11: 45088463
A12: =A11+1 -> 44291 | B12: 525764 | C12: 483352 | D12: 0.73 | E12: 13817.97 | F12: 3305.82 | G12: 27941.91 | H12: 14528 | I12: 114892 | J12: 45111502
A13: =A12+1 -> 44292 | B13: 529204 | C13: 488833 | D13: 0.65 | E13: 13843.97 | F13: 3311.14 | G13: 27992.09 | H13: 14528 | I13: 114985 | J13: 45132088
A14: =A13+1 -> 44293 | B14: 532632 | C14: 494377 | D14: 0.56 | E14: 13869.97 | F14: 3316.22 | G14: 28036.77 | H14: 14528 | I14: 115087 | J14: 45151168
A15: =A14+1 -> 44294 | B15: 535832 | C15: 499612 | D15: 0.45 | E15: 0 | F15: 3320.98 | G15: 28080.21 | H15: 14528 | I15: 115188 | J15: 45170674 | L15: Main Kitchen Gas Meter Replced
A16: =A15+1 -> 44295 | B16: 539179 | C16: 505205 | D16: 0.39 | E16: 23.44 | F16: 3326.23 | G16: 28130.4 | H16: 14528 | I16: 115302 | J16: 45191721
A17: =A16+1 -> 44296 | B17: 542395 | C17: 510876 | D17: 0.3 | E17: 50.65 | F17: 3331.03 | G17: 28176.9 | H17: 14528 | I17: 115394 | J17: 45213779
A18: =A17+1 -> 44297 | B18: 545543 | C18: 516290 | D18: 0.2 | E18: 75.45 | F18: 3335.99 | G18: 28220.97 | H18: 14528 | I18: 115500 | J18: 45234409
A19: =A18+1 -> 44298 | B19: 548836 | C19: 521765 | D19: 0.75 | E19: 104.73 | F19: 3341.18 | G19: 28264.89 | H19: 14528 | I19: 115607 | J19: 45255678
A20: =A19+1 -> 44299 | B20: 552056 | C20: 527196 | D20: 0.69 | E20: 130.62 | F20: 3346.1 | G20: 28312.25 | H20: 14528 | I20: 115702 | J20: 45277842
A21: =A20+1 -> 44300 | B21: 555311 | C21: 532686 | D21: 0.6 | E21: 156.2 | F21: 3350.92 | G21: 28354.45 | H21: 14528 | I21: 115795 | J21: 45298650
A22: =A21+1 -> 44301 | B22: 558694 | C22: 538222 | D22: 0.52 | E22: 184.84 | F22: 3355.46 | G22: 28399.82 | H22: 14528 | I22: 115896 | J22: 45320604
A23: =A22+1 -> 44302 | B23: 562160 | C23: 543932 | D23: 0.42 | E23: 212.55 | F23: 3359.88 | G23: 28450.99 | H23: 14528 | I23: 116000 | J23: 45344360
A24: =A23+1 -> 44303 | B24: 565581 | C24: 549458 | D24: 0.33 | E24: 242.83 | F24: 3364.27 | G24: 28500.21 | H24: 14528 | I24: 116099 | J24: 45367455
A25: =A24+1 -> 44304
A26: =A25+1 -> 44305
A27: =A26+1 -> 44306
A28: =A27+1 -> 44307
A29: =A28+1 -> 44308
A30: =A29+1 -> 44309
A31: =A30+1 -> 44310
A32: =A31+1 -> 44311
A33: =A32+1 -> 44312
A34: =A33+1 -> 44313
A35: =A34+1 -> 44314
A36: =A35+1 -> 44315
A37: =A36+1 -> 44316
A38: Readings | B38: =B37-B7 -> -509328 | C38: =C37-C7 -> -455305 | D38: =D37-D7 -> -0.55 | E38: =E37-E7 -> -13687.97 | F38: =F37-F7 -> -3279.36 | G38: =G37-G7 -> -27719.1 | H38: =H37-H7 -> -14528 | I38: =I37-I7 -> -114409 | J38: =J37-J7 -> -45003433 | K38: =SUM(K7:K37) -> 0
H39: =H38*219.969 -> -3195709.6 | I39: =I38*219.969 -> -25166433
H40: for IG unit
B41: =B32-B10 -> -518967 | C41: =C32-C10 -> -472253 | E41: =E32-E10 -> -13765.97 | F41: =F32-F10 -> -3295.1 | G41: =G32-G10 -> -27851.78 | H41: =H32-H10 -> -14528 | I41: =I32-I10 -> -114691 | J41: =J32-J10 -> -45068524
I42: =I41*219.969 -> -25228465 | J42: 768611
...
