Workbook

Sheet TOTAL
A1: Site Name | B1: Day | C1: Month | D1: Year | E1: Total Electricity Kwh | F1: Electricity Tariff ($/Kwh) | G1: LPG (Kg) | H1: LPG $/Kg | I1: District Energy Heating Kwh | J1: District Energy Heating $/Kwh | K1: Water Utility Supply (m3) m3 | L1: Water Utility Supply (m3) $/m3 | M1: Room Nights | N1: Total Guests | O1: Utilities day cost dh
A2: Marrakech | B2: 1 | C2: 4 | D2: 2021 | E2: ='Consommation du 01.04 au 30.04'!M10 -> 13966 | F2: 1.002 | G2: ='Consommation du 01.04 au 30.04'!U10 -> 259.7 | H2: 9.32295 | I2: ='Consommation du 01.04 au 30.04'!Y10*1000 -> 12970 | J2: 0.53 | K2: ='Consommation du 01.04 au 30.04'!D10 -> 342 | L2: 12.67 | M2: ='Consommation du 01.04 au 30.04'!AC10 -> 40 | N2: 40 | O2: =E2*F2+G2*H2+I2*J2+K2*L2 -> 27622.342
A3: Marrakech | B3: =B2+1 -> 2 | C3: 4 | D3: 2021 | E3: ='Consommation du 01.04 au 30.04'!M11 -> 15054 | F3: 1.002 | G3: ='Consommation du 01.04 au 30.04'!U11 -> 148.4 | H3: 9.32295 | I3: ='Consommation du 01.04 au 30.04'!Y11*1000 -> 16410 | J3: 0.53 | K3: ='Consommation du 01.04 au 30.04'!D11 -> 507 | L3: 12.67 | M3: ='Consommation du 01.04 au 30.04'!AC11 -> 82 | N3: 82 | O3: =E3*F3+G3*H3+I3*J3+K3*L3 -> 31588.624
A4: Marrakech | B4: =B3+1 -> 3 | C4: 4 | D4: 2021 | E4: ='Consommation du 01.04 au 30.04'!M12 -> 16320 | F4: 1.002 | G4: ='Consommation du 01.04 au 30.04'!U12 -> 148.4 | H4: 9.32295 | I4: ='Consommation du 01.04 au 30.04'!Y12*1000 -> 18350 | J4: 0.53 | K4: ='Consommation du 01.04 au 30.04'!D12 -> 506 | L4: 12.67 | M4: ='Consommation du 01.04 au 30.04'!AC12 -> 116 | N4: 116 | O4: =E4*F4+G4*H4+I4*J4+K4*L4 -> 33872.686
A5: Marrakech | B5: =B4+1 -> 4 | C5: 4 | D5: 2021 | E5: ='Consommation du 01.04 au 30.04'!M13 -> 15310 | F5: 1.002 | G5: ='Consommation du 01.04 au 30.04'!U13 -> 148.4 | H5: 9.32295 | I5: ='Consommation du 01.04 au 30.04'!Y13*1000 -> 17380 | J5: 0.53 | K5: ='Consommation du 01.04 au 30.04'!D13 -> 528 | L5: 12.67 | M5: ='Consommation du 01.04 au 30.04'!AC13 -> 53 | N5: 53 | O5: =E5*F5+G5*H5+I5*J5+K5*L5 -> 32625.306
A6: Marrakech | B6: =B5+1 -> 5 | C6: 4 | D6: 2021 | E6: ='Consommation du 01.04 au 30.04'!M14 -> 14767 | F6: 1.002 | G6: ='Consommation du 01.04 au 30.04'!U14 -> 333.9 | H6: 9.32295 | I6: ='Consommation du 01.04 au 30.04'!Y14*1000 -> 9030 | J6: 0.53 | K6: ='Consommation du 01.04 au 30.04'!D14 -> 385 | L6: 12.67 | M6: ='Consommation du 01.04 au 30.04'!AC14 -> 29 | N6: 29 | O6: =E6*F6+G6*H6+I6*J6+K6*L6 -> 27573.317
A7: Marrakech | B7: =B6+1 -> 6 | C7: 4 | D7: 2021 | E7: ='Consommation du 01.04 au 30.04'!M15 -> 10898 | F7: 1.002 | G7: ='Consommation du 01.04 au 30.04'!U15 -> 296.8 | H7: 9.32295 | I7: ='Consommation du 01.04 au 30.04'!Y15*1000 -> 14320 | J7: 0.53 | K7: ='Consommation du 01.04 au 30.04'!D15 -> 324 | L7: 12.67 | M7: ='Consommation du 01.04 au 30.04'!AC15 -> 38 | N7: 38 | O7: =E7*F7+G7*H7+I7*J7+K7*L7 -> 25381.528
A8: Marrakech | B8: =B7+1 -> 7 | C8: 4 | D8: 2021 | E8: ='Consommation du 01.04 au 30.04'!M16 -> 10316 | F8: 1.002 | G8: ='Consommation du 01.04 au 30.04'!U16 -> 333.9 | H8: 9.32295 | I8: ='Consommation du 01.04 au 30.04'!Y16*1000 -> 13550 | J8: 0.53 | K8: ='Consommation du 01.04 au 30.04'!D16 -> 361 | L8: 12.67 | M8: ='Consommation du 01.04 au 30.04'!AC16 -> 16 | N8: 16 | O8: =E8*F8+G8*H8+I8*J8+K8*L8 -> 25204.935
A9: Marrakech | B9: =B8+1 -> 8 | C9: 4 | D9: 2021 | E9: ='Consommation du 01.04 au 30.04'!M17 -> 10575 | F9: 1.002 | G9: ='Consommation du 01.04 au 30.04'!U17 -> 185.5 | H9: 9.32295 | I9: ='Consommation du 01.04 au 30.04'!Y17*1000 -> 14770 | J9: 0.53 | K9: ='Consommation du 01.04 au 30.04'!D17 -> 312 | L9: 12.67 | M9: ='Consommation du 01.04 au 30.04'!AC17 -> 28 | N9: 28 | O9: =E9*F9+G9*H9+I9*J9+K9*L9 -> 24106.697
A10: Marrakech | B10: =B9+1 -> 9 | C10: 4 | D10: 2021 | E10: ='Consommation du 01.04 au 30.04'!M18 -> 12986 | F10: 1.002 | G10: ='Consommation du 01.04 au 30.04'!U18 -> 593.6 | H10: 9.32295 | I10: ='Consommation du 01.04 au 30.04'!Y18*1000 -> 13390 | J10: 0.53 | K10: ='Consommation du 01.04 au 30.04'!D18 -> 334 | L10: 12.67 | M10: ='Consommation du 01.04 au 30.04'!AC18 -> 63 | N10: 63 | O10: =E10*F10+G10*H10+I10*J10+K10*L10 -> 29874.555
A11: Marrakech | B11: =B10+1 -> 10 | C11: 4 | D11: 2021 | E11: ='Consommation du 01.04 au 30.04'!M19 -> 11159 | F11: 1.002 | G11: ='Consommation du 01.04 au 30.04'!U19 -> 482.3 | H11: 9.32295 | I11: ='Consommation du 01.04 au 30.04'!Y19*1000 -> 15490 | J11: 0.53 | K11: ='Consommation du 01.04 au 30.04'!D19 -> 425 | L11: 12.67 | M11: ='Consommation du 01.04 au 30.04'!AC19 -> 81 | N11: 81 | O11: =E11*F11+G11*H11+I11*J11+K11*L11 -> 29272.227
A12: Marrakech | B12: =B11+1 -> 11 | C12: 4 | D12: 2021 | E12: ='Consommation du 01.04 au 30.04'!M20 -> 12054 | F12: 1.002 | G12: ='Consommation du 01.04 au 30.04'!U20 -> 445.2 | H12: 9.32295 | I12: ='Consommation du 01.04 au 30.04'!Y20*1000 -> 18630 | J12: 0.53 | K12: ='Consommation du 01.04 au 30.04'!D20 -> 425 | L12: 12.67 | M12: ='Consommation du 01.04 au 30.04'!AC20 -> 18 | N12: 18 | O12: =E12*F12+G12*H12+I12*J12+K12*L12 -> 31487.335
A13: Marrakech | B13: =B12+1 -> 12 | C13: 4 | D13: 2021 | E13: ='Consommation du 01.04 au 30.04'!M21 -> 10491 | F13: 1.002 | G13: ='Consommation du 01.04 au 30.04'!U21 -> 296.8 | H13: 9.32295 | I13: ='Consommation du 01.04 au 30.04'!Y21*1000 -> 11850 | J13: 0.53 | K13: ='Consommation du 01.04 au 30.04'!D21 -> 482 | L13: 12.67 | M13: ='Consommation du 01.04 au 30.04'!AC21 -> 7 | N13: 7 | O13: =E13*F13+G13*H13+I13*J13+K13*L13 -> 25666.474
A14: Marrakech | B14: =B13+1 -> 13 | C14: 4 | D14: 2021 | E14: ='Consommation du 01.04 au 30.04'!M22 -> 10074 | F14: 1.002 | G14: ='Consommation du 01.04 au 30.04'!U22 -> 148.4 | H14: 9.32295 | I14: ='Consommation du 01.04 au 30.04'!Y22*1000 -> 9120 | J14: 0.53 | K14: ='Consommation du 01.04 au 30.04'!D22 -> 268 | L14: 12.67 | M14: ='Consommation du 01.04 au 30.04'!AC22 -> 5 | N14: 5 | O14: =E14*F14+G14*H14+I14*J14+K14*L14 -> 19706.834
... A19: Marrakech | B19: =B18+1 -> 18 | C19: 4 | D19: 2021 | E19: ='Consommation du 01.04 au 30.04'!M27 -> 8677 | F19: 1.002 | G19: ='Consommation du 01.04 au 30.04'!U27 -> 148.4 | H19: 9.32295 | I19: ='Consommation du 01.04 au 30.04'!Y27*1000 -> 9480 | J19: 0.53 | K19: ='Consommation du 01.04 au 30.04'!D27 -> 249 | L19: 12.67 | M19: ='Consommation du 01.04 au 30.04'!AC27 -> 12 | N19: 12 | O19: =E19*F19+G19*H19+I19*J19+K19*L19 -> 18257.11
A20: Marrakech | B20: =B19+1 -> 19 | C20: 4 | D20: 2021 | E20: ='Consommation du 01.04 au 30.04'!M28 -> 0 | F20: 1.002 | G20: ='Consommation du 01.04 au 30.04'!U28 -> 0 | H20: 9.32295 | I20: ='Consommation du 01.04 au 30.04'!Y28*1000 -> 0 | J20: 0.53 | K20: ='Consommation du 01.04 au 30.04'!D28 -> 0 | L20: 12.67 | M20: ='Consommation du 01.04 au 30.04'!AC28 -> 0 | O20: =E20*F20+G20*H20+I20*J20+K20*L20 -> 0
A21: Marrakech | B21: =B20+1 -> 20 | C21: 4 | D21: 2021 | E21: ='Consommation du 01.04 au 30.04'!M29 -> 0 | F21: 1.002 | G21: ='Consommation du 01.04 au 30.04'!U29 -> 0 | H21: 9.32295 | I21: ='Consommation du 01.04 au 30.04'!Y29*1000 -> 0 | J21: 0.53 | K21: ='Consommation du 01.04 au 30.04'!D29 -> 0 | L21: 12.67 | M21: ='Consommation du 01.04 au 30.04'!AC29 -> 0 | O21: =E21*F21+G21*H21+I21*J21+K21*L21 -> 0
A22: Marrakech | B22: =B21+1 -> 21 | C22: 4 | D22: 2021 | E22: ='Consommation du 01.04 au 30.04'!M30 -> 0 | F22: 1.002 | G22: ='Consommation du 01.04 au 30.04'!U30 -> 0 | H22: 9.32295 | I22: ='Consommation du 01.04 au 30.04'!Y30*1000 -> 0 | J22: 0.53 | K22: ='Consommation du 01.04 au 30.04'!D30 -> 0 | L22: 12.67 | M22: ='Consommation du 01.04 au 30.04'!AC30 -> 0 | O22: =E22*F22+G22*H22+I22*J22+K22*L22 -> 0
A23: Marrakech | B23: =B22+1 -> 22 | C23: 4 | D23: 2021 | E23: ='Consommation du 01.04 au 30.04'!M31 -> 0 | F23: 1.002 | G23: ='Consommation du 01.04 au 30.04'!U31 -> 0 | H23: 9.32295 | I23: ='Consommation du 01.04 au 30.04'!Y31*1000 -> 0 | J23: 0.53 | K23: ='Consommation du 01.04 au 30.04'!D31 -> 0 | L23: 12.67 | M23: ='Consommation du 01.04 au 30.04'!AC31 -> 0 | O23: =E23*F23+G23*H23+I23*J23+K23*L23 -> 0
A24: Marrakech | B24: =B23+1 -> 23 | C24: 4 | D24: 2021 | E24: ='Consommation du 01.04 au 30.04'!M32 -> 0 | F24: 1.002 | G24: ='Consommation du 01.04 au 30.04'!U32 -> 0 | H24: 9.32295 | I24: ='Consommation du 01.04 au 30.04'!Y32*1000 -> 0 | J24: 0.53 | K24: ='Consommation du 01.04 au 30.04'!D32 -> 0 | L24: 12.67 | M24: ='Consommation du 01.04 au 30.04'!AC32 -> 0 | O24: =E24*F24+G24*H24+I24*J24+K24*L24 -> 0
A25: Marrakech | B25: =B24+1 -> 24 | C25: 4 | D25: 2021 | E25: ='Consommation du 01.04 au 30.04'!M33 -> 0 | F25: 1.002 | G25: ='Consommation du 01.04 au 30.04'!U33 -> 0 | H25: 9.32295 | I25: ='Consommation du 01.04 au 30.04'!Y33*1000 -> 0 | J25: 0.53 | K25: ='Consommation du 01.04 au 30.04'!D33 -> 0 | L25: 12.67 | M25: ='Consommation du 01.04 au 30.04'!AC33 -> 0 | O25: =E25*F25+G25*H25+I25*J25+K25*L25 -> 0
A26: Marrakech | B26: =B25+1 -> 25 | C26: 4 | D26: 2021 | E26: ='Consommation du 01.04 au 30.04'!M34 -> 0 | F26: 1.002 | G26: ='Consommation du 01.04 au 30.04'!U34 -> 0 | H26: 9.32295 | I26: ='Consommation du 01.04 au 30.04'!Y34*1000 -> 0 | J26: 0.53 | K26: ='Consommation du 01.04 au 30.04'!D34 -> 0 | L26: 12.67 | M26: ='Consommation du 01.04 au 30.04'!AC34 -> 0 | O26: =E26*F26+G26*H26+I26*J26+K26*L26 -> 0
A27: Marrakech | B27: =B26+1 -> 26 | C27: 4 | D27: 2021 | E27: ='Consommation du 01.04 au 30.04'!M35 -> 0 | F27: 1.002 | G27: ='Consommation du 01.04 au 30.04'!U35 -> 0 | H27: 9.32295 | I27: ='Consommation du 01.04 au 30.04'!Y35*1000 -> 0 | J27: 0.53 | K27: ='Consommation du 01.04 au 30.04'!D35 -> 0 | L27: 12.67 | M27: ='Consommation du 01.04 au 30.04'!AC35 -> 0 | O27: =E27*F27+G27*H27+I27*J27+K27*L27 -> 0
A28: Marrakech | B28: =B27+1 -> 27 | C28: 4 | D28: 2021 | E28: ='Consommation du 01.04 au 30.04'!M36 -> 0 | F28: 1.002 | G28: ='Consommation du 01.04 au 30.04'!U36 -> 0 | H28: 9.32295 | I28: ='Consommation du 01.04 au 30.04'!Y36*1000 -> 0 | J28: 0.53 | K28: ='Consommation du 01.04 au 30.04'!D36 -> 0 | L28: 12.67 | M28: ='Consommation du 01.04 au 30.04'!AC36 -> 0 | O28: =E28*F28+G28*H28+I28*J28+K28*L28 -> 0
A29: Marrakech | B29: =B28+1 -> 28 | C29: 4 | D29: 2021 | E29: ='Consommation du 01.04 au 30.04'!M37 -> 0 | F29: 1.002 | G29: ='Consommation du 01.04 au 30.04'!U37 -> 0 | H29: 9.32295 | I29: ='Consommation du 01.04 au 30.04'!Y37*1000 -> 0 | J29: 0.53 | K29: ='Consommation du 01.04 au 30.04'!D37 -> 0 | L29: 12.67 | M29: ='Consommation du 01.04 au 30.04'!AC37 -> 0 | O29: =E29*F29+G29*H29+I29*J29+K29*L29 -> 0
A30: Marrakech | B30: =B29+1 -> 29 | C30: 4 | D30: 2021 | E30: ='Consommation du 01.04 au 30.04'!M38 -> 0 | F30: 1.002 | G30: ='Consommation du 01.04 au 30.04'!U38 -> 0 | H30: 9.32295 | I30: ='Consommation du 01.04 au 30.04'!Y38*1000 -> 0 | J30: 0.53 | K30: ='Consommation du 01.04 au 30.04'!D38 -> 0 | L30: 12.67 | M30: ='Consommation du 01.04 au 30.04'!AC38 -> 0 | O30: =E30*F30+G30*H30+I30*J30+K30*L30 -> 0
A31: Marrakech | B31: =B30+1 -> 30 | C31: 4 | D31: 2021 | E31: ='Consommation du 01.04 au 30.04'!M39 -> 0 | F31: 1.002 | G31: ='Consommation du 01.04 au 30.04'!U39 -> 0 | H31: 9.32295 | I31: ='Consommation du 01.04 au 30.04'!Y39*1000 -> 0 | J31: 0.53 | K31: ='Consommation du 01.04 au 30.04'!D39 -> 0 | L31: 12.67 | M31: ='Consommation du 01.04 au 30.04'!AC39 -> 0 | O31: =E31*F31+G31*H31+I31*J31+K31*L31 -> 0

Sheet Consommation du 01.04 au 30.04
B8: Date | D8: Cons Eau/Hotel | F8: Consommation du jour en DH | M8: total | O8: Consommation du jour en DH | Q8: Cons Elec/Villa | S8: Cons Elec/RIAD | U8: GAZ en Kg | W8: Consommation du jour en DH | X8: Compteur AVEO Mwh | Y8: consommation eau choud en Mwh | Z8: consommation du jour en DH | AB8: Température moyenne du jour °C | AC8: Total Occupation | AD8: % Occupation | AE8: Température Piscine Adulte à 7h00 °C | AF8: Température Piscine Adulte à 15h00 °C | AG8: Température Piscine famille à 07h00 ° C | AH8: Température Piscine famille à 15h00 ° C
J9: creuse 81 | K9: pleine 82 | L9: pointe 83 | AJ9: Consommation totale du jour | AK9: Consommation/Chambre
B10: 44287 | D10: ='Suivi EAU-ELEC'!C16 -> 342 | F10: =D10*12.67 -> 4333.14 | J10: ='Suivi EAU-ELEC'!E16 -> 3753 | K10: ='Suivi EAU-ELEC'!G16 -> 7026 | L10: ='Suivi EAU-ELEC'!I16 -> 3187 | M10: =L10+K10+J10 -> 13966 | O10: =J10*0.99+K10*0.99+L10*0.99 -> 13826.34 | U10: ='Suivi Gaz'!O11 -> 259.7 | W10: =U10*9.32295 -> 2421.1701 | X10: 19563.66 | Y10: =IF(X11<X10,0,X11-X10) -> 12.97 | Z10: =Y10*0.53*1000 -> 6874.1 | AB10: 23 | AC10: 40 | AD10: 0.3101 | AE10: 27 | AF10: 28 | AG10: 26 | AH10: 27 | AJ10: =(F10+O10+W10+Z10) -> 27454.75 | AK10: =AJ10/AC10 -> 686.36875
B11: =(B10+1) -> 44288 | D11: ='Suivi EAU-ELEC'!C17 -> 507 | F11: =D11*12.67 -> 6423.69 | J11: ='Suivi EAU-ELEC'!E17 -> 3377 | K11: ='Suivi EAU-ELEC'!G17 -> 8299 | L11: ='Suivi EAU-ELEC'!I17 -> 3378 | M11: =L11+K11+J11 -> 15054 | O11: =J11*0.99+K11*0.99+L11*0.99 -> 14903.46 | U11: ='Suivi Gaz'!O12 -> 148.4 | W11: =U11*9.32295 -> 1383.5258 | X11: 19576.63 | Y11: =IF(X12<X11,0,X12-X11) -> 16.41 | Z11: =Y11*0.53*1000 -> 8697.3 | AB11: 25 | AC11: 82 | AD11: 0.7321 | AE11: 27 | AF11: 28 | AG11: 26 | AH11: 27 | AJ11: =(F11+O11+W11+Z11) -> 31407.976 | AK11: =AJ11/AC11 -> 383.02409
B12: =(B11+1) -> 44289 | D12: ='Suivi EAU-ELEC'!C18 -> 506 | F12: =D12*12.67 -> 6411.02 | J12: ='Suivi EAU-ELEC'!E18 -> 3827 | K12: ='Suivi EAU-ELEC'!G18 -> 8493 | L12: ='Suivi EAU-ELEC'!I18 -> 4000 | M12: =L12+K12+J12 -> 16320 | O12: =J12*0.99+K12*0.99+L12*0.99 -> 16156.8 | U12: ='Suivi Gaz'!O13 -> 148.4 | W12: =U12*9.32295 -> 1383.5258 | X12: 19593.04 | Y12: =IF(X13<X12,0,X13-X12) -> 18.35 | Z12: =Y12*0.53*1000 -> 9725.5 | AB12: 23 | AC12: 116 | AD12: 0.9748 | AE12: 27.5 | AF12: 28.5 | AG12: 27 | AH12: 28.5 | AJ12: =(F12+O12+W12+Z12) -> 33676.846 | AK12: =AJ12/AC12 -> 290.31764
B13: =(B12+1) -> 44290 | D13: ='Suivi EAU-ELEC'!C19 -> 528 | F13: =D13*12.67 -> 6689.76 | J13: ='Suivi EAU-ELEC'!E19 -> 4272 | K13: ='Suivi EAU-ELEC'!G19 -> 7406 | L13: ='Suivi EAU-ELEC'!I19 -> 3632 | M13: =L13+K13+J13 -> 15310 | O13: =J13*0.99+K13*0.99+L13*0.99 -> 15156.9 | U13: ='Suivi Gaz'!O14 -> 148.4 | W13: =U13*9.32295 -> 1383.5258 | X13: 19611.39 | Y13: =IF(X14<X13,0,X14-X13) -> 17.38 | Z13: =Y13*0.53*1000 -> 9211.4 | AB13: 21 | AC13: 53 | AD13: 0.7361 | AE13: 28.5 | AF13: 29 | AG13: 28 | AH13: 28.5 | AJ13: =(F13+O13+W13+Z13) -> 32441.586 | AK13: =AJ13/AC13 -> 612.10539
B14: =(B13+1) -> 44291 | D14: ='Suivi EAU-ELEC'!C20 -> 385 | F14: =D14*12.67 -> 4877.95 | J14: ='Suivi EAU-ELEC'!E20 -> 4074 | K14: ='Suivi EAU-ELEC'!G20 -> 7007 | L14: ='Suivi EAU-ELEC'!I20 -> 3686 | M14: =L14+K14+J14 -> 14767 | O14: =J14*0.99+K14*0.99+L14*0.99 -> 14619.33 | U14: ='Suivi Gaz'!O15 -> 333.9 | W14: =U14*9.32295 -> 3112.933 | X14: 19628.77 | Y14: =IF(X15<X14,0,X15-X14) -> 9.03 | Z14: =Y14*0.53*1000 -> 4785.9 | AB14: 23 | AC14: 29 | AD14: 0.2929 | AE14: 27.5 | AF14: 28 | AG14: 27 | AH14: 26 | AJ14: =(F14+O14+W14+Z14) -> 27396.113 | AK14: =AJ14/AC14 -> 944.69355
B15: =(B14+1) -> 44292 | D15: ='Suivi EAU-ELEC'!C21 -> 324 | F15: =D15*12.67 -> 4105.08 | J15: ='Suivi EAU-ELEC'!E21 -> 3211 | K15: ='Suivi EAU-ELEC'!G21 -> 5668 | L15: ='Suivi EAU-ELEC'!I21 -> 2019 | M15: =L15+K15+J15 -> 10898 | O15: =J15*0.99+K15*0.99+L15*0.99 -> 10789.02 | U15: ='Suivi Gaz'!O16 -> 296.8 | W15: =U15*9.32295 -> 2767.0516 | X15: 19637.8 | Y15: =IF(X16<X15,0,X16-X15) -> 14.32 | Z15: =Y15*0.53*1000 -> 7589.6 | AB15: 24 | AC15: 38 | AD15: 0.3193 | AE15: 27 | AF15: 28 | AG15: 22 | AH15: 24 | AJ15: =(F15+O15+W15+Z15) -> 25250.752 | AK15: =AJ15/AC15 -> 664.49346
B16: =(B15+1) -> 44293 | D16: ='Suivi EAU-ELEC'!C22 -> 361 | F16: =D16*12.67 -> 4573.87 | J16: ='Suivi EAU-ELEC'!E22 -> 2958 | K16: ='Suivi EAU-ELEC'!G22 -> 5360 | L16: ='Suivi EAU-ELEC'!I22 -> 1998 | M16: =L16+K16+J16 -> 10316 | O16: =J16*0.99+K16*0.99+L16*0.99 -> 10212.84 | U16: ='Suivi Gaz'!O17 -> 333.9 | W16: =U16*9.32295 -> 3112.933 | X16: 19652.12 | Y16: =IF(X17<X16,0,X17-X16) -> 13.55 | Z16: =Y16*0.53*1000 -> 7181.5 | AB16: 22 | AC16: 16 | AD16: 0.1345 | AE16: 27 | AF16: 28 | AG16: 20 | AH16: 20 | AJ16: =(F16+O16+W16+Z16) -> 25081.143 | AK16: =AJ16/AC16 -> 1567.5714
B17: =(B16+1) -> 44294 | D17: ='Suivi EAU-ELEC'!C23 -> 312 | F17: =D17*12.67 -> 3953.04 | J17: ='Suivi EAU-ELEC'!E23 -> 2872 | K17: ='Suivi EAU-ELEC'!G23 -> 5340 | L17: ='Suivi EAU-ELEC'!I23 -> 2363 | M17: =L17+K17+J17 -> 10575 | O17: =J17*0.99+K17*0.99+L17*0.99 -> 10469.25 | U17: ='Suivi Gaz'!O18 -> 185.5 | W17: =U17*9.32295 -> 1729.4072 | X17: 19665.67 | Y17: =IF(X18<X17,0,X18-X17) -> 14.77 | Z17: =Y17*0.53*1000 -> 7828.1 | AB17: 21 | AC17: 28 | AD17: 0.2353 | AE17: 26.5 | AF17: 27.5 | AG17: 23 | AH17: 25 | AJ17: =(F17+O17+W17+Z17) -> 23979.797 | AK17: =AJ17/AC17 -> 856.42133
B18: =(B17+1) -> 44295 | D18: ='Suivi EAU-ELEC'!C24 -> 334 | F18: =D18*12.67 -> 4231.78 | J18: ='Suivi EAU-ELEC'!E24 -> 3589 | K18: ='Suivi EAU-ELEC'!G24 -> 6259 | L18: ='Suivi EAU-ELEC'!I24 -> 3138 | M18: =L18+K18+J18 -> 12986 | O18: =J18*0.99+K18*0.99+L18*0.99 -> 12856.14 | U18: ='Suivi Gaz'!O19 -> 593.6 | W18: =U18*9.32295 -> 5534.1031 | X18: 19680.44 | Y18: =IF(X19<X18,0,X19-X18) -> 13.39 | Z18: =Y18*0.53*1000 -> 7096.7 | AB18: 21 | AC18: 63 | AD18: 0.5294 | AE18: 26.5 | AF18: 27.5 | AG18: 23 | AH18: 25 | AJ18: =(F18+O18+W18+Z18) -> 29718.723 | AK18: =AJ18/AC18 -> 471.72576
B19: =(B18+1) -> 44296 | D19: ='Suivi EAU-ELEC'!C25 -> 425 | F19: =D19*12.67 -> 5384.75 | J19: ='Suivi EAU-ELEC'!E25 -> 3186 | K19: ='Suivi EAU-ELEC'!G25 -> 5731 | L19: ='Suivi EAU-ELEC'!I25 -> 2242 | M19: =L19+K19+J19 -> 11159 | O19: =J19*0.99+K19*0.99+L19*0.99 -> 11047.41 | U19: ='Suivi Gaz'!O20 -> 482.3 | W19: =U19*9.32295 -> 4496.4588 | X19: 19693.83 | Y19: =IF(X20<X19,0,X20-X19) -> 15.49 | Z19: =Y19*0.53*1000 -> 8209.7 | AB19: 22 | AC19: 81 | AD19: 0.6864 | AE19: 28 | AF19: 29 | AG19: 27.5 | AH19: 28 | AJ19: =(F19+O19+W19+Z19) -> 29138.319 | AK19: =AJ19/AC19 -> 359.73233
B20: =(B19+1) -> 44297 | D20: ='Suivi EAU-ELEC'!C26 -> 425 | F20: =D20*12.67 -> 5384.75 | J20: ='Suivi EAU-ELEC'!E26 -> 3853 | K20: ='Suivi EAU-ELEC'!G26 -> 5780 | L20: ='Suivi EAU-ELEC'!I26 -> 2421 | M20: =L20+K20+J20 -> 12054 | O20: =J20*0.99+K20*0.99+L20*0.99 -> 11933.46 | U20: ='Suivi Gaz'!O21 -> 445.2 | W20: =U20*9.32295 -> 4150.5773 | X20: 19709.32 | Y20: =IF(X21<X20,0,X21-X20) -> 18.63 | Z20: =Y20*0.53*1000 -> 9873.9 | AA20: 14 | AB20: 22 | AC20: 18 | AD20: 0.1935 | AE20: 28 | AF20: 29 | AG20: 28 | AH20: 29 | AJ20: =(F20+O20+W20+Z20) -> 31342.687 | AK20: =AJ20/AC20 -> 1741.2604
B21: =(B20+1) -> 44298 | D21: ='Suivi EAU-ELEC'!C27 -> 482 | F21: =D21*12.67 -> 6106.94 | J21: ='Suivi EAU-ELEC'!E27 -> 3036 | K21: ='Suivi EAU-ELEC'!G27 -> 5262 | L21: ='Suivi EAU-ELEC'!I27 -> 2193 | M21: =L21+K21+J21 -> 10491 | O21: =J21*0.99+K21*0.99+L21*0.99 -> 10386.09 | U21: ='Suivi Gaz'!O22 -> 296.8 | W21: =U21*9.32295 -> 2767.0516 | X21: 19727.95 | Y21: =IF(X22<X21,0,X22-X21) -> 11.85 | Z21: =Y21*0.53*1000 -> 6280.5 | AA21: 14 | AB21: 25 | AC21: 7 | AD21: 0.068 | AE21: 28 | AF21: 29 | AG21: 22 | AH21: 24 | AJ21: =(F21+O21+W21+Z21) -> 25540.582 | AK21: =AJ21/AC21 -> 3648.6545
B22: =(B21+1) -> 44299 | D22: ='Suivi EAU-ELEC'!C28 -> 268 | F22: =D22*12.67 -> 3395.56 | J22: ='Suivi EAU-ELEC'!E28 -> 2884 | K22: ='Suivi EAU-ELEC'!G28 -> 5115 | L22: ='Suivi EAU-ELEC'!I28 -> 2075 | M22: =L22+K22+J22 -> 10074 | O22: =J22*0.99+K22*0.99+L22*0.99 -> 9973.26 | U22: ='Suivi Gaz'!O23 -> 148.4 | W22: =U22*9.32295 -> 1383.5258 | X22: 19739.8 | Y22: =IF(X23<X22,0,X23-X22) -> 9.12 | Z22: =Y22*0.53*1000 -> 4833.6 | AB22: 25 | AC22: 5 | AD22: 0.0435 | AE22: 27 | AF22: 28 | AG22: 20 | AH22: 24 | AJ22: =(F22+O22+W22+Z22) -> 19585.946 | AK22: =AJ22/AC22 -> 3917.1892
B23: =(B22+1) -> 44300 | D23: ='Suivi EAU-ELEC'!C29 -> 469 | F23: =D23*12.67 -> 5942.23 | J23: ='Suivi EAU-ELEC'!E29 -> 3083 | K23: ='Suivi EAU-ELEC'!G29 -> 4597 | L23: ='Suivi EAU-ELEC'!I29 -> 2683 | M23: =L23+K23+J23 -> 10363 | O23: =J23*0.99+K23*0.99+L23*0.99 -> 10259.37 | U23: ='Suivi Gaz'!O24 -> 259.7 | W23: =U23*9.32295 -> 2421.1701 | X23: 19748.92 | Y23: =IF(X24<X23,0,X24-X23) -> 6.63 | Z23: =Y23*0.53*1000 -> 3513.9 | AB23: 23 | AC23: 6 | AD23: 0.0517 | AE23: 27 | AF23: 27.5 | AG23: 20 | AH23: 20 | AJ23: =(F23+O23+W23+Z23) -> 22136.67 | AK23: =AJ23/AC23 -> 3689.445
B24: =(B23+1) -> 44301 | D24: ='Suivi EAU-ELEC'!C30 -> 250 | F24: =D24*12.67 -> 3167.5 | J24: ='Suivi EAU-ELEC'!E30 -> 2807 | K24: ='Suivi EAU-ELEC'!G30 -> 6277 | L24: ='Suivi EAU-ELEC'!I30 -> 2866 | M24: =L24+K24+J24 -> 11950 | O24: =J24*0.99+K24*0.99+L24*0.99 -> 11830.5 | U24: ='Suivi Gaz'!O25 -> 148.4 | W24: =U24*9.32295 -> 1383.5258 | X24: 19755.55 | Y24: =IF(X25<X24,0,X25-X24) -> 8.96 | Z24: =Y24*0.53*1000 -> 4748.8 | AB24: 22 | AC24: 3 | AD24: 0.0261 | AE24: 26 | AF24: 26 | AG24: 20 | AH24: 20 | AJ24: =(F24+O24+W24+Z24) -> 21130.326 | AK24: =AJ24/AC24 -> 7043.4419
B25: =(B24+1) -> 44302 | D25: ='Suivi EAU-ELEC'!C31 -> 216 | F25: =D25*12.67 -> 2736.72 | J25: ='Suivi EAU-ELEC'!E31 -> 2272 | K25: ='Suivi EAU-ELEC'!G31 -> 4682 | L25: ='Suivi EAU-ELEC'!I31 -> 1822 | M25: =L25+K25+J25 -> 8776 | O25: =J25*0.99+K25*0.99+L25*0.99 -> 8688.24 | U25: ='Suivi Gaz'!O26 -> 296.8 | W25: =U25*9.32295 -> 2767.0516 | X25: 19764.51 | Y25: =IF(X26<X25,0,X26-X25) -> 11.06 | Z25: =Y25*0.53*1000 -> 5861.8 | AB25: 21 | AC25: 4 | AD25: 0.0345 | AE25: 25 | AF25: 27.5 | AG25: 20 | AH25: 21 | AJ25: =(F25+O25+W25+Z25) -> 20053.812 | AK25: =AJ25/AC25 -> 5013.4529
B26: =(B25+1) -> 44303 | D26: ='Suivi EAU-ELEC'!C32 -> 282 | F26: =D26*12.67 -> 3572.94 | J26: ='Suivi EAU-ELEC'!E32 -> 2297 | K26: ='Suivi EAU-ELEC'!G32 -> 4398 | L26: ='Suivi EAU-ELEC'!I32 -> 2633 | M26: =L26+K26+J26 -> 9328 | O26: =J26*0.99+K26*0.99+L26*0.99 -> 9234.72 | U26: ='Suivi Gaz'!O27 -> 148.4 | W26: =U26*9.32295 -> 1383.5258 | X26: 19775.57 | Y26: =IF(X27<X26,0,X27-X26) -> 9.77 | Z26: =Y26*0.53*1000 -> 5178.1 | AB26: 22 | AC26: 7 | AD26: 0.0593 | AE26: 26 | AF26: 27.5 | AG26: 20 | AH26: 22 | AJ26: =(F26+O26+W26+Z26) -> 19369.286 | AK26: =AJ26/AC26 -> 2767.0408
B27: =(B26+1) -> 44304 | D27: ='Suivi EAU-ELEC'!C33 -> 249 | F27: =D27*12.67 -> 3154.83 | J27: ='Suivi EAU-ELEC'!E33 -> 2285 | K27: ='Suivi EAU-ELEC'!G33 -> 4582 | L27: ='Suivi EAU-ELEC'!I33 -> 1810 | M27: =L27+K27+J27 -> 8677 | O27: =J27*0.99+K27*0.99+L27*0.99 -> 8590.23 | U27: ='Suivi Gaz'!O28 -> 148.4 | W27: =U27*9.32295 -> 1383.5258 | X27: 19785.34 | Y27: =IF(X28<X27,0,X28-X27) -> 9.48 | Z27: =Y27*0.53*1000 -> 5024.4 | AB27: 24 | AC27: 12 | AD27: 0.1017 | AE27: 27 | AF27: 28 | AG27: 20 | AH27: 20 | AJ27: =(F27+O27+W27+Z27) -> 18152.986 | AK27: =AJ27/AC27 -> 1512.7488
B28: =(B27+1) -> 44305 | D28: ='Suivi EAU-ELEC'!C34 -> 0 | F28: =D28*12.67 -> 0 | J28: ='Suivi EAU-ELEC'!E34 -> 0 | K28: ='Suivi EAU-ELEC'!G34 -> 0 | L28: ='Suivi EAU-ELEC'!I34 -> 0 | M28: =L28+K28+J28 -> 0 | O28: =J28*0.99+K28*0.99+L28*0.99 -> 0 | U28: ='Suivi Gaz'!O29 -> 0 | W28: =U28*9.32295 -> 0 | X28: 19794.82 | Y28: =IF(X29<X28,0,X29-X28) -> 0 | Z28: =Y28*0.53*1000 -> 0 | AJ28: =(F28+O28+W28+Z28) -> 0 | AK28: =AJ28/AC28 -> #DIV/0!
B29: =(B28+1) -> 44306 | D29: ='Suivi EAU-ELEC'!C35 -> 0 | F29: =D29*12.67 -> 0 | J29: ='Suivi EAU-ELEC'!E35 -> 0 | K29: ='Suivi EAU-ELEC'!G35 -> 0 | L29: ='Suivi EAU-ELEC'!I35 -> 0 | M29: =L29+K29+J29 -> 0 | O29: =J29*0.99+K29*0.99+L29*0.99 -> 0 | U29: ='Suivi Gaz'!O30 -> 0 | W29: =U29*9.32295 -> 0 | Y29: =IF(X30<X29,0,X30-X29) -> 0 | Z29: =Y29*0.53*1000 -> 0 | AJ29: =(F29+O29+W29+Z29) -> 0 | AK29: =AJ29/AC29 -> #DIV/0!
B30: =(B29+1) -> 44307 | D30: ='Suivi EAU-ELEC'!C36 -> 0 | F30: =D30*12.67 -> 0 | J30: ='Suivi EAU-ELEC'!E36 -> 0 | K30: ='Suivi EAU-ELEC'!G36 -> 0 | L30: ='Suivi EAU-ELEC'!I36 -> 0 | M30: =L30+K30+J30 -> 0 | O30: =J30*0.99+K30*0.99+L30*0.99 -> 0 | U30: ='Suivi Gaz'!O31 -> 0 | W30: =U30*9.32295 -> 0 | Y30: =IF(X31<X30,0,X31-X30) -> 0 | Z30: =Y30*0.53*1000 -> 0 | AJ30: =(F30+O30+W30+Z30) -> 0 | AK30: =AJ30/AC30 -> #DIV/0!
B31: =(B30+1) -> 44308 | D31: ='Suivi EAU-ELEC'!C37 -> 0 | F31: =D31*12.67 -> 0 | J31: ='Suivi EAU-ELEC'!E37 -> 0 | K31: ='Suivi EAU-ELEC'!G37 -> 0 | L31: ='Suivi EAU-ELEC'!I37 -> 0 | M31: =L31+K31+J31 -> 0 | O31: =J31*0.99+K31*0.99+L31*0.99 -> 0 | U31: ='Suivi Gaz'!O32 -> 0 | W31: =U31*9.32295 -> 0 | Y31: =IF(X32<X31,0,X32-X31) -> 0 | Z31: =Y31*0.53*1000 -> 0 | AJ31: =(F31+O31+W31+Z31) -> 0 | AK31: =AJ31/AC31 -> #DIV/0!
B32: =(B31+1) -> 44309 | D32: ='Suivi EAU-ELEC'!C38 -> 0 | F32: =D32*12.67 -> 0 | J32: ='Suivi EAU-ELEC'!E38 -> 0 | K32: ='Suivi EAU-ELEC'!G38 -> 0 | L32: ='Suivi EAU-ELEC'!I38 -> 0 | M32: =L32+K32+J32 -> 0 | O32: =J32*0.99+K32*0.99+L32*0.99 -> 0 | U32: ='Suivi Gaz'!O33 -> 0 | W32: =U32*9.32295 -> 0 | Y32: =IF(X33<X32,0,X33-X32) -> 0 | Z32: =Y32*0.53*1000 -> 0 | AJ32: =(F32+O32+W32+Z32) -> 0 | AK32: =AJ32/AC32 -> #DIV/0!
B33: =(B32+1) -> 44310 | D33: ='Suivi EAU-ELEC'!C39 -> 0 | F33: =D33*12.67 -> 0 | J33: ='Suivi EAU-ELEC'!E39 -> 0 | K33: ='Suivi EAU-ELEC'!G39 -> 0 | L33: ='Suivi EAU-ELEC'!I39 -> 0 | M33: =L33+K33+J33 -> 0 | O33: =J33*0.99+K33*0.99+L33*0.99 -> 0 | U33: ='Suivi Gaz'!O34 -> 0 | W33: =U33*9.32295 -> 0 | Y33: =IF(X34<X33,0,X34-X33) -> 0 | Z33: =Y33*0.53*1000 -> 0 | AJ33: =(F33+O33+W33+Z33) -> 0 | AK33: =AJ33/AC33 -> #DIV/0!
B34: =(B33+1) -> 44311 | D34: ='Suivi EAU-ELEC'!C40 -> 0 | F34: =D34*12.67 -> 0 | J34: ='Suivi EAU-ELEC'!E40 -> 0 | K34: ='Suivi EAU-ELEC'!G40 -> 0 | L34: ='Suivi EAU-ELEC'!I40 -> 0 | M34: =L34+K34+J34 -> 0 | O34: =J34*0.99+K34*0.99+L34*0.99 -> 0 | U34: ='Suivi Gaz'!O35 -> 0 | W34: =U34*9.32295 -> 0 | Y34: =IF(X35<X34,0,X35-X34) -> 0 | Z34: =Y34*0.53*1000 -> 0 | AJ34: =(F34+O34+W34+Z34) -> 0 | AK34: =AJ34/AC34 -> #DIV/0!
B35: =(B34+1) -> 44312 | D35: ='Suivi EAU-ELEC'!C41 -> 0 | F35: =D35*12.67 -> 0 | J35: ='Suivi EAU-ELEC'!E41 -> 0 | K35: ='Suivi EAU-ELEC'!G41 -> 0 | L35: ='Suivi EAU-ELEC'!I41 -> 0 | M35: =L35+K35+J35 -> 0 | O35: =J35*0.99+K35*0.99+L35*0.99 -> 0 | U35: ='Suivi Gaz'!O36 -> 0 | W35: =U35*9.32295 -> 0 | Y35: =IF(X36<X35,0,X36-X35) -> 0 | Z35: =Y35*0.53*1000 -> 0 | AJ35: =(F35+O35+W35+Z35) -> 0 | AK35: =AJ35/AC35 -> #DIV/0!
B36: =(B35+1) -> 44313 | D36: ='Suivi EAU-ELEC'!C42 -> 0 | F36: =D36*12.67 -> 0 | J36: ='Suivi EAU-ELEC'!E42 -> 0 | K36: ='Suivi EAU-ELEC'!G42 -> 0 | L36: ='Suivi EAU-ELEC'!I42 -> 0 | M36: =L36+K36+J36 -> 0 | O36: =J36*0.99+K36*0.99+L36*0.99 -> 0 | U36: ='Suivi Gaz'!O37 -> 0 | W36: =U36*9.32295 -> 0 | Y36: =IF(X37<X36,0,X37-X36) -> 0 | Z36: =Y36*0.53*1000 -> 0 | AJ36: =(F36+O36+W36+Z36) -> 0 | AK36: =AJ36/AC36 -> #DIV/0!
B37: =(B36+1) -> 44314 | D37: ='Suivi EAU-ELEC'!C43 -> 0 | F37: =D37*12.67 -> 0 | J37: ='Suivi EAU-ELEC'!E43 -> 0 | K37: ='Suivi EAU-ELEC'!G43 -> 0 | L37: ='Suivi EAU-ELEC'!I43 -> 0 | M37: =L37+K37+J37 -> 0 | O37: =J37*0.99+K37*0.99+L37*0.99 -> 0 | U37: ='Suivi Gaz'!O38 -> 0 | W37: =U37*9.32295 -> 0 | Y37: =IF(X38<X37,0,X38-X37) -> 0 | Z37: =Y37*0.53*1000 -> 0 | AJ37: =(F37+O37+W37+Z37) -> 0 | AK37: =AJ37/AC37 -> #DIV/0!
B38: =(B37+1) -> 44315 | D38: ='Suivi EAU-ELEC'!C44 -> 0 | F38: =D38*12.67 -> 0 | J38: ='Suivi EAU-ELEC'!E44 -> 0 | K38: ='Suivi EAU-ELEC'!G44 -> 0 | L38: ='Suivi EAU-ELEC'!I44 -> 0 | M38: =L38+K38+J38 -> 0 | O38: =J38*0.99+K38*0.99+L38*0.99 -> 0 | U38: ='Suivi Gaz'!O39 -> 0 | W38: =U38*9.32295 -> 0 | Y38: =IF(X39<X38,0,X39-X38) -> 0 | Z38: =Y38*0.53*1000 -> 0 | AJ38: =(F38+O38+W38+Z38) -> 0 | AK38: =AJ38/AC38 -> #DIV/0!
B39: =(B38+1) -> 44316 | D39: ='Suivi EAU-ELEC'!C45 -> 0 | F39: =D39*12.67 -> 0 | J39: ='Suivi EAU-ELEC'!E45 -> 0 | K39: ='Suivi EAU-ELEC'!G45 -> 0 | L39: ='Suivi EAU-ELEC'!I45 -> 0 | M39: =L39+K39+J39 -> 0 | O39: =J39*0.99+K39*0.99+L39*0.99 -> 0 | U39: ='Suivi Gaz'!O40 -> 0 | W39: =U39*9.32295 -> 0 | Y39: =IF(X40<X39,0,X40-X39) -> 0 | Z39: =Y39*0.53*1000 -> 0 | AJ39: =(F39+O39+W39+Z39) -> 0 | AK39: =AJ39/AC39 -> #DIV/0!
B40: =(B39+1) -> 44317 | D40: ='Suivi EAU-ELEC'!C46 -> 0 | F40: =D40*12.67 -> 0 | J40: ='Suivi EAU-ELEC'!E46 -> 0 | K40: ='Suivi EAU-ELEC'!G46 -> 0 | L40: ='Suivi EAU-ELEC'!I46 -> 0 | M40: =L40+K40+J40 -> 0 | O40: =J40*0.99+K40*0.99+L40*0.99 -> 0 | U40: ='Suivi Gaz'!O41 -> 0 | W40: =U40*9.32295 -> 0 | Y40: =IF(X41<X40,0,X41-X40) -> 0 | Z40: =Y40*0.53*1000 -> 0 | AJ40: =(F40+O40+W40+Z40) -> 0 | AK40: =AJ40/AC40 -> #DIV/0!
D41: =SUM(D10:D39) -> 6665 | F41: =SUM(D10:D39) -> 6665 | J41: =SUM(J10:J39) -> 57636 | K41: =SUM(K10:K39) -> 107282 | L41: =SUM(L10:L39) -> 48146 | M41: =SUM(M10:M39) -> 213064 | O41: =SUM(O10:O39) -> 210933.36 | Q41: =SUM(Q10:Q40) -> 0 | S41: =SUM(S10:S40) -> 0 | U41: =SUM(U10:U39) -> 4823 | W41: =SUM(W10:W39) -> 44964.588 | Y41: =SUM(Y10:Y39) -> 231.16 | Z41: =SUM(Z10:Z39) -> 122514.8 | AJ41: =SUM(AJ10:AJ38) -> 462858.3 | AK41: =SUM(AK10:AK38) -> #DIV/0!
A43: ELECTRICITE / Kw/h | D43: creuse 81 | F43: 0.64895 | G43: =J41 -> 57636 | J43: =G43*F43 -> 37402.882 | L43: =J43+J44+J45 -> 192249.73
D44: pleine 82 | F44: 0.88605 | G44: =K41 -> 107282 | J44: =G44*F44 -> 95057.216
D45: pointe 83 | F45: 1.24184 | G45: =L41 -> 48146 | J45: =G45*F45 -> 59789.629
A46: EAU HOTEL M3 | F46: 12.67 | G46: =D41 -> 6665 | J46: =G46*F46 -> 84445.55 | L46: =J46 -> 84445.55
A47: GAZ Kg | F47: 9.697 | G47: =U41 -> 4823 | J47: =G47*F47 -> 46768.631 | L47: =J47 -> 46768.631

Sheet Suivi Gaz
D1: suivi Gaz
Q2: 803 | T2: 519 | W2: 800 | Z2: 802
B3: Relvé C1 | C3: cons C1 | D3: Relvé C2 | E3: cons C2 | F3: Relvé C3 | G3: cons C3 | H3: Relvé C4 | I3: cons C4 | J3: ∑ des relevés | K3: moyen general % | L3: con.j | M3: ∑ de volume en L | N3: cons./jen L | O3: cons./jen Kg | P3: cons./jen DH | Q3: livraison C1 | R3: %Avant | S3: % Après | T3: livraison C2 | U3: %Avant | V3: % Après | W3: livraison C3 | X3: %Avant | Y3: % Après | Z3: livraison C4 | AA3: %Avant | AB3: % Après | AC3: total livraison | AD3: moyen general % Avant L | AE3: moyen general % Aaprés L
A4: 44280 | B4: 66 | C4: =IF(AC4>0,((B4-R4)+(S4-B5)),IF(B5=0, ,(B4-B5))) -> 1 | D4: 69 | E4: =IF(AC4>0,((D4-U4)+(V4-D5)),IF(D5=0, ,(D4-D5))) -> 2 | F4: 64 | G4: =IF(AC4>0,((F4-X4)+(Y4-F5)),IF(F5=0, ,(F4-F5))) -> 1 | H4: 66 | I4: =IF(AC4>0,((H4-AA4)+(AB4-H5)),IF(H5=0, ,(H4-H5))) -> 1 | J4: =B4+D4+F4+H4 -> 265 | K4: =J4/4 -> 66.25 | L4: =IF(AC4>0,((K4-AD4)+(AE4-K5)),IF(K5=0, ,(K4-K5))) -> 1.25 | M4: =7000*4 -> 28000 | N4: =L4*M4/100 -> 350 | O4: =N4*0.53 -> 185.5 | P4: =O4*9.697 -> 1798.7935 | AC4: =Q4+T4+W4+Z4 -> 0 | AD4: =(R4+U4+X4+AA4)/4 -> 0 | AE4: =(S4+V4+Y4+AB4)/4 -> 0
A5: =(A4+1) -> 44281 | B5: 65 | C5: =IF(AC5>0,((B5-R5)+(S5-B6)),IF(B6=0, ,(B5-B6))) -> 3 | D5: 67 | E5: =IF(AC5>0,((D5-U5)+(V5-D6)),IF(D6=0, ,(D5-D6))) -> 1 | F5: 63 | G5: =IF(AC5>0,((F5-X5)+(Y5-F6)),IF(F6=0, ,(F5-F6))) -> 2 | H5: 65 | I5: =IF(AC5>0,((H5-AA5)+(AB5-H6)),IF(H6=0, ,(H5-H6))) -> 2 | J5: =B5+D5+F5+H5 -> 260 | K5: =J5/4 -> 65 | L5: =IF(AC5>0,((K5-AD5)+(AE5-K6)),IF(K6=0, ,(K5-K6))) -> 2 | M5: =7000*4 -> 28000 | N5: =L5*M5/100 -> 560 | O5: =N5*0.53 -> 296.8 | P5: =O5*9.697 -> 2878.0696 | AC5: =Q5+T5+W5+Z5 -> 0 | AD5: =(R5+U5+X5+AA5)/4 -> 0 | AE5: =(S5+V5+Y5+AB5)/4 -> 0
A6: =(A5+1) -> 44282 | B6: 62 | C6: =IF(AC6>0,((B6-R6)+(S6-B7)),IF(B7=0, ,(B6-B7))) -> 1 | D6: 66 | E6: =IF(AC6>0,((D6-U6)+(V6-D7)),IF(D7=0, ,(D6-D7))) -> 2 | F6: 61 | G6: =IF(AC6>0,((F6-X6)+(Y6-F7)),IF(F7=0, ,(F6-F7))) -> 1 | H6: 63 | I6: =IF(AC6>0,((H6-AA6)+(AB6-H7)),IF(H7=0, ,(H6-H7))) -> 2 | J6: =B6+D6+F6+H6 -> 252 | K6: =J6/4 -> 63 | L6: =IF(AC6>0,((K6-AD6)+(AE6-K7)),IF(K7=0, ,(K6-K7))) -> 1.5 | M6: =7000*4 -> 28000 | N6: =L6*M6/100 -> 420 | O6: =N6*0.53 -> 222.6 | P6: =O6*9.697 -> 2158.5522 | AC6: =Q6+T6+W6+Z6 -> 0 | AD6: =(R6+U6+X6+AA6)/4 -> 0 | AE6: =(S6+V6+Y6+AB6)/4 -> 0
A7: =(A6+1) -> 44283 | B7: 61 | C7: =IF(AC7>0,((B7-R7)+(S7-B8)),IF(B8=0, ,(B7-B8))) -> 1 | D7: 64 | E7: =IF(AC7>0,((D7-U7)+(V7-D8)),IF(D8=0, ,(D7-D8))) -> 3 | F7: 60 | G7: =IF(AC7>0,((F7-X7)+(Y7-F8)),IF(F8=0, ,(F7-F8))) -> 0 | H7: 61 | I7: =IF(AC7>0,((H7-AA7)+(AB7-H8)),IF(H8=0, ,(H7-H8))) -> 1 | J7: =B7+D7+F7+H7 -> 246 | K7: =J7/4 -> 61.5 | L7: =IF(AC7>0,((K7-AD7)+(AE7-K8)),IF(K8=0, ,(K7-K8))) -> 1.25 | M7: =7000*4 -> 28000 | N7: =L7*M7/100 -> 350 | O7: =N7*0.53 -> 185.5 | P7: =O7*9.697 -> 1798.7935 | AC7: =Q7+T7+W7+Z7 -> 0 | AD7: =(R7+U7+X7+AA7)/4 -> 0 | AE7: =(S7+V7+Y7+AB7)/4 -> 0
A8: =(A7+1) -> 44284 | B8: 60 | C8: =IF(AC8>0,((B8-R8)+(S8-B9)),IF(B9=0, ,(B8-B9))) -> 2 | D8: 61 | E8: =IF(AC8>0,((D8-U8)+(V8-D9)),IF(D9=0, ,(D8-D9))) -> 1 | F8: 60 | G8: =IF(AC8>0,((F8-X8)+(Y8-F9)),IF(F9=0, ,(F8-F9))) -> 5 | H8: 60 | I8: =IF(AC8>0,((H8-AA8)+(AB8-H9)),IF(H9=0, ,(H8-H9))) -> 1 | J8: =B8+D8+F8+H8 -> 241 | K8: =J8/4 -> 60.25 | L8: =IF(AC8>0,((K8-AD8)+(AE8-K9)),IF(K9=0, ,(K8-K9))) -> 2.25 | M8: =7000*4 -> 28000 | N8: =L8*M8/100 -> 630 | O8: =N8*0.53 -> 333.9 | P8: =O8*9.697 -> 3237.8283 | AC8: =Q8+T8+W8+Z8 -> 0 | AD8: =(R8+U8+X8+AA8)/4 -> 0 | AE8: =(S8+V8+Y8+AB8)/4 -> 0
A9: =(A8+1) -> 44285 | B9: 58 | C9: =IF(AC9>0,((B9-R9)+(S9-B10)),IF(B10=0, ,(B9-B10))) -> 4 | D9: 60 | E9: =IF(AC9>0,((D9-U9)+(V9-D10)),IF(D10=0, ,(D9-D10))) -> 0 | F9: 55 | G9: =IF(AC9>0,((F9-X9)+(Y9-F10)),IF(F10=0, ,(F9-F10))) -> 4 | H9: 59 | I9: =IF(AC9>0,((H9-AA9)+(AB9-H10)),IF(H10=0, ,(H9-H10))) -> 4 | J9: =B9+D9+F9+H9 -> 232 | K9: =J9/4 -> 58 | L9: =IF(AC9>0,((K9-AD9)+(AE9-K10)),IF(K10=0, ,(K9-K10))) -> 3 | M9: =7000*4 -> 28000 | N9: =L9*M9/100 -> 840 | O9: =N9*0.53 -> 445.2 | P9: =O9*9.697 -> 4317.1044 | AC9: =Q9+T9+W9+Z9 -> 0 | AD9: =(R9+U9+X9+AA9)/4 -> 0 | AE9: =(S9+V9+Y9+AB9)/4 -> 0
A10: =(A9+1) -> 44286 | B10: 54 | C10: =IF(AC10>0,((B10-R10)+(S10-B11)),IF(B11=0, ,(B10-B11))) -> 8 | D10: 60 | E10: =IF(AC10>0,((D10-U10)+(V10-D11)),IF(D11=0, ,(D10-D11))) -> 5 | F10: 51 | G10: =IF(AC10>0,((F10-X10)+(Y10-F11)),IF(F11=0, ,(F10-F11))) -> 17 | H10: 55 | I10: 2 | J10: =B10+D10+F10+H10 -> 220 | K10: =J10/4 -> 55 | L10: =IF(AC10>0,((K10-AD10)+(AE10-K11)),IF(K11=0, ,(K10-K11))) -> 2.25 | M10: =7000*4 -> 28000 | N10: =L10*M10/100 -> 630 | O10: =N10*0.53 -> 333.9 | P10: =O10*9.697 -> 3237.8283 | Q10: 2225 | R10: 50 | S10: 80 | T10: 2057 | U10: 57 | V10: 80 | W10: 2927 | X10: 50 | Y10: 85 | AC10: =Q10+T10+W10+Z10 -> 7209 | AD10: =(R10+U10+X10+AA10)/4 -> 39.25 | AE10: =(S10+V10+Y10+AB10)/4 -> 61.25
A11: =(A10+1) -> 44287 | B11: 76 | C11: =IF(AC11>0,((B11-R11)+(S11-B12)),IF(B12=0, ,(B11-B12))) -> 1 | D11: 78 | E11: =IF(AC11>0,((D11-U11)+(V11-D12)),IF(D12=0, ,(D11-D12))) -> 1 | F11: 69 | G11: =IF(AC11>0,((F11-X11)+(Y11-F12)),IF(F12=0, ,(F11-F12))) -> 2 | H11: 76 | I11: 0 | J11: =B11+D11+F11+H11 -> 299 | K11: =J11/4 -> 74.75 | L11: =IF(AC11>0,((K11-AD11)+(AE11-K12)),IF(K12=0, ,(K11-K12))) -> 1.75 | M11: =7000*4 -> 28000 | N11: =L11*M11/100 -> 490 | O11: =N11*0.53 -> 259.7 | P11: =O11*9.32295 -> 2421.1701 | Q11: 996 | R11: 76 | S11: 86 | T11: 981 | U11: 78 | V11: 85 | W11: 1221 | X11: 68 | Y11: 86 | Z11: 1220 | AA11: 75 | AB11: 86 | AC11: =Q11+T11+W11+Z11 -> 4418 | AD11: =(R11+U11+X11+AA11)/4 -> 74.25 | AE11: =(S11+V11+Y11+AB11)/4 -> 85.75
A12: =(A11+1) -> 44288 | B12: 85 | C12: =IF(AC12>0,((B12-R12)+(S12-B13)),IF(B13=0, ,(B12-B13))) -> 1 | D12: 84 | E12: =IF(AC12>0,((D12-U12)+(V12-D13)),IF(D13=0, ,(D12-D13))) -> 0 | F12: 85 | G12: =IF(AC12>0,((F12-X12)+(Y12-F13)),IF(F13=0, ,(F12-F13))) -> 2 | H12: 84 | I12: =IF(AC12>0,((H12-AA12)+(AB12-H13)),IF(H13=0, ,(H12-H13))) -> 1 | J12: =B12+D12+F12+H12 -> 338 | K12: =J12/4 -> 84.5 | L12: =IF(AC12>0,((K12-AD12)+(AE12-K13)),IF(K13=0, ,(K12-K13))) -> 1 | M12: =7000*4 -> 28000 | N12: =L12*M12/100 -> 280 | O12: =N12*0.53 -> 148.4 | P12: =O12*9.32295 -> 1383.5258 | AC12: =Q12+T12+W12+Z12 -> 0 | AD12: =(R12+U12+X12+AA12)/4 -> 0 | AE12: =(S12+V12+Y12+AB12)/4 -> 0
A13: =(A12+1) -> 44289 | B13: 84 | C13: =IF(AC13>0,((B13-R13)+(S13-B14)),IF(B14=0, ,(B13-B14))) -> 1 | D13: 84 | E13: =IF(AC13>0,((D13-U13)+(V13-D14)),IF(D14=0, ,(D13-D14))) -> 1 | F13: 83 | G13: =IF(AC13>0,((F13-X13)+(Y13-F14)),IF(F14=0, ,(F13-F14))) -> 1 | H13: 83 | I13: 0 | J13: =B13+D13+F13+H13 -> 334 | K13: =J13/4 -> 83.5 | L13: =IF(AC13>0,((K13-AD13)+(AE13-K14)),IF(K14=0, ,(K13-K14))) -> 1 | M13: =7000*4 -> 28000 | N13: =L13*M13/100 -> 280 | O13: =N13*0.53 -> 148.4 | P13: =O13*9.32295 -> 1383.5258 | AC13: =Q13+T13+W13+Z13 -> 0 | AD13: =(R13+U13+X13+AA13)/4 -> 0 | AE13: =(S13+V13+Y13+AB13)/4 -> 0
A14: =(A13+1) -> 44290 | B14: 83 | C14: =IF(AC14>0,((B14-R14)+(S14-B15)),IF(B15=0, ,(B14-B15))) -> 1 | D14: 83 | E14: =IF(AC14>0,((D14-U14)+(V14-D15)),IF(D15=0, ,(D14-D15))) -> 0 | F14: 82 | G14: =IF(AC14>0,((F14-X14)+(Y14-F15)),IF(F15=0, ,(F14-F15))) -> 2 | H14: 82 | I14: =IF(AC14>0,((H14-AA14)+(AB14-H15)),IF(H15=0, ,(H14-H15))) -> 1 | J14: =B14+D14+F14+H14 -> 330 | K14: =J14/4 -> 82.5 | L14: =IF(AC14>0,((K14-AD14)+(AE14-K15)),IF(K15=0, ,(K14-K15))) -> 1 | M14: =7000*4 -> 28000 | N14: =L14*M14/100 -> 280 | O14: =N14*0.53 -> 148.4 | P14: =O14*9.32295 -> 1383.5258 | AC14: =Q14+T14+W14+Z14 -> 0 | AD14: =(R14+U14+X14+AA14)/4 -> 0 | AE14: =(S14+V14+Y14+AB14)/4 -> 0
A15: =(A14+1) -> 44291 | B15: 82 | C15: =IF(AC15>0,((B15-R15)+(S15-B16)),IF(B16=0, ,(B15-B16))) -> 2 | D15: 83 | E15: =IF(AC15>0,((D15-U15)+(V15-D16)),IF(D16=0, ,(D15-D16))) -> 2 | F15: 80 | G15: =IF(AC15>0,((F15-X15)+(Y15-F16)),IF(F16=0, ,(F15-F16))) -> 2 | H15: 81 | I15: 0 | J15: =B15+D15+F15+H15 -> 326 | K15: =J15/4 -> 81.5 | L15: =IF(AC15>0,((K15-AD15)+(AE15-K16)),IF(K16=0, ,(K15-K16))) -> 2.25 | M15: =7000*4 -> 28000 | N15: =L15*M15/100 -> 630 | O15: =N15*0.53 -> 333.9 | P15: =O15*9.32295 -> 3112.933 | AC15: =Q15+T15+W15+Z15 -> 0 | AD15: =(R15+U15+X15+AA15)/4 -> 0 | AE15: =(S15+V15+Y15+AB15)/4 -> 0
A16: =(A15+1) -> 44292 | B16: 80 | C16: =IF(AC16>0,((B16-R16)+(S16-B17)),IF(B17=0, ,(B16-B17))) -> 3 | D16: 81 | E16: =IF(AC16>0,((D16-U16)+(V16-D17)),IF(D17=0, ,(D16-D17))) -> 1 | F16: 78 | G16: =IF(AC16>0,((F16-X16)+(Y16-F17)),IF(F17=0, ,(F16-F17))) -> 3 | H16: 78 | I16: =IF(AC16>0,((H16-AA16)+(AB16-H17)),IF(H17=0, ,(H16-H17))) -> 1 | J16: =B16+D16+F16+H16 -> 317 | K16: =J16/4 -> 79.25 | L16: =IF(AC16>0,((K16-AD16)+(AE16-K17)),IF(K17=0, ,(K16-K17))) -> 2 | M16: =7000*4 -> 28000 | N16: =L16*M16/100 -> 560 | O16: =N16*0.53 -> 296.8 | P16: =O16*9.32295 -> 2767.0516 | AC16: =Q16+T16+W16+Z16 -> 0 | AD16: =(R16+U16+X16+AA16)/4 -> 0 | AE16: =(S16+V16+Y16+AB16)/4 -> 0
A17: =(A16+1) -> 44293 | B17: 77 | C17: =IF(AC17>0,((B17-R17)+(S17-B18)),IF(B18=0, ,(B17-B18))) -> 12 | D17: 80 | E17: =IF(AC17>0,((D17-U17)+(V17-D18)),IF(D18=0, ,(D17-D18))) -> -5 | F17: 75 | G17: =IF(AC17>0,((F17-X17)+(Y17-F18)),IF(F18=0, ,(F17-F18))) -> 0 | H17: 77 | I17: =IF(AC17>0,((H17-AA17)+(AB17-H18)),IF(H18=0, ,(H17-H18))) -> 2 | J17: =B17+D17+F17+H17 -> 309 | K17: =J17/4 -> 77.25 | L17: =IF(AC17>0,((K17-AD17)+(AE17-K18)),IF(K18=0, ,(K17-K18))) -> 2.25 | M17: =7000*4 -> 28000 | N17: =L17*M17/100 -> 630 | O17: =N17*0.53 -> 333.9 | P17: =O17*9.32295 -> 3112.933 | Q17: 1634 | R17: 65 | S17: 85 | W17: 1053 | X17: 75 | Y17: 85 | Z17: 1019 | AA17: 75 | AB17: 85 | AC17: =Q17+T17+W17+Z17 -> 3706 | AD17: =(R17+U17+X17+AA17)/4 -> 53.75 | AE17: =(S17+V17+Y17+AB17)/4 -> 63.75
A18: =(A17+1) -> 44294 | B18: 85 | C18: =IF(AC18>0,((B18-R18)+(S18-B19)),IF(B19=0, ,(B18-B19))) -> 1 | D18: 85 | E18: =IF(AC18>0,((D18-U18)+(V18-D19)),IF(D19=0, ,(D18-D19))) -> 0 | F18: 85 | G18: =IF(AC18>0,((F18-X18)+(Y18-F19)),IF(F19=0, ,(F18-F19))) -> 3 | H18: 85 | I18: =IF(AC18>0,((H18-AA18)+(AB18-H19)),IF(H19=0, ,(H18-H19))) -> 1 | J18: =B18+D18+F18+H18 -> 340 | K18: =J18/4 -> 85 | L18: =IF(AC18>0,((K18-AD18)+(AE18-K19)),IF(K19=0, ,(K18-K19))) -> 1.25 | M18: =7000*4 -> 28000 | N18: =L18*M18/100 -> 350 | O18: =N18*0.53 -> 185.5 | P18: =O18*9.32295 -> 1729.4072 | AC18: =Q18+T18+W18+Z18 -> 0 | AD18: =(R18+U18+X18+AA18)/4 -> 0 | AE18: =(S18+V18+Y18+AB18)/4 -> 0
A19: =(A18+1) -> 44295 | B19: 84 | C19: =IF(AC19>0,((B19-R19)+(S19-B20)),IF(B20=0, ,(B19-B20))) -> 4 | D19: 85 | E19: =IF(AC19>0,((D19-U19)+(V19-D20)),IF(D20=0, ,(D19-D20))) -> 5 | F19: 82 | G19: =IF(AC19>0,((F19-X19)+(Y19-F20)),IF(F20=0, ,(F19-F20))) -> 4 | H19: 84 | I19: =IF(AC19>0,((H19-AA19)+(AB19-H20)),IF(H20=0, ,(H19-H20))) -> 3 | J19: =B19+D19+F19+H19 -> 335 | K19: =J19/4 -> 83.75 | L19: =IF(AC19>0,((K19-AD19)+(AE19-K20)),IF(K20=0, ,(K19-K20))) -> 4 | M19: =7000*4 -> 28000 | N19: =L19*M19/100 -> 1120 | O19: =N19*0.53 -> 593.6 | P19: =O19*9.32295 -> 5534.1031 | AC19: =Q19+T19+W19+Z19 -> 0 | AD19: =(R19+U19+X19+AA19)/4 -> 0 | AE19: =(S19+V19+Y19+AB19)/4 -> 0
A20: =(A19+1) -> 44296 | B20: 80 | C20: =IF(AC20>0,((B20-R20)+(S20-B21)),IF(B21=0, ,(B20-B21))) -> 3 | D20: 80 | E20: =IF(AC20>0,((D20-U20)+(V20-D21)),IF(D21=0, ,(D20-D21))) -> 1 | F20: 78 | G20: =IF(AC20>0,((F20-X20)+(Y20-F21)),IF(F21=0, ,(F20-F21))) -> 4 | H20: 81 | I20: =IF(AC20>0,((H20-AA20)+(AB20-H21)),IF(H21=0, ,(H20-H21))) -> 5 | J20: =B20+D20+F20+H20 -> 319 | K20: =J20/4 -> 79.75 | L20: =IF(AC20>0,((K20-AD20)+(AE20-K21)),IF(K21=0, ,(K20-K21))) -> 3.25 | M20: =7000*4 -> 28000 | N20: =L20*M20/100 -> 910 | O20: =N20*0.53 -> 482.3 | P20: =O20*9.32295 -> 4496.4588 | AC20: =Q20+T20+W20+Z20 -> 0 | AD20: =(R20+U20+X20+AA20)/4 -> 0 | AE20: =(S20+V20+Y20+AB20)/4 -> 0
A21: =(A20+1) -> 44297 | B21: 77 | C21: =IF(AC21>0,((B21-R21)+(S21-B22)),IF(B22=0, ,(B21-B22))) -> 4 | D21: 79 | E21: =IF(AC21>0,((D21-U21)+(V21-D22)),IF(D22=0, ,(D21-D22))) -> 3 | F21: 74 | G21: =IF(AC21>0,((F21-X21)+(Y21-F22)),IF(F22=0, ,(F21-F22))) -> 2 | H21: 76 | I21: =IF(AC21>0,((H21-AA21)+(AB21-H22)),IF(H22=0, ,(H21-H22))) -> 3 | J21: =B21+D21+F21+H21 -> 306 | K21: =J21/4 -> 76.5 | L21: =IF(AC21>0,((K21-AD21)+(AE21-K22)),IF(K22=0, ,(K21-K22))) -> 3 | M21: =7000*4 -> 28000 | N21: =L21*M21/100 -> 840 | O21: =N21*0.53 -> 445.2 | P21: =O21*9.32295 -> 4150.5773 | AC21: =Q21+T21+W21+Z21 -> 0 | AD21: =(R21+U21+X21+AA21)/4 -> 0 | AE21: =(S21+V21+Y21+AB21)/4 -> 0
A22: =(A21+1) -> 44298 | B22: 73 | C22: =IF(AC22>0,((B22-R22)+(S22-B23)),IF(B23=0, ,(B22-B23))) -> 1 | D22: 76 | E22: =IF(AC22>0,((D22-U22)+(V22-D23)),IF(D23=0, ,(D22-D23))) -> 3 | F22: 72 | G22: =IF(AC22>0,((F22-X22)+(Y22-F23)),IF(F23=0, ,(F22-F23))) -> 3 | H22: 73 | I22: =IF(AC22>0,((H22-AA22)+(AB22-H23)),IF(H23=0, ,(H22-H23))) -> 1 | J22: =B22+D22+F22+H22 -> 294 | K22: =J22/4 -> 73.5 | L22: =IF(AC22>0,((K22-AD22)+(AE22-K23)),IF(K23=0, ,(K22-K23))) -> 2 | M22: =7000*4 -> 28000 | N22: =L22*M22/100 -> 560 | O22: =N22*0.53 -> 296.8 | P22: =O22*9.32295 -> 2767.0516 | AC22: =Q22+T22+W22+Z22 -> 0 | AD22: =(R22+U22+X22+AA22)/4 -> 0 | AE22: =(S22+V22+Y22+AB22)/4 -> 0
A23: =(A22+1) -> 44299 | B23: 72 | C23: =IF(AC23>0,((B23-R23)+(S23-B24)),IF(B24=0, ,(B23-B24))) -> 1 | D23: 73 | E23: =IF(AC23>0,((D23-U23)+(V23-D24)),IF(D24=0, ,(D23-D24))) -> 1 | F23: 69 | G23: =IF(AC23>0,((F23-X23)+(Y23-F24)),IF(F24=0, ,(F23-F24))) -> 0 | H23: 72 | I23: =IF(AC23>0,((H23-AA23)+(AB23-H24)),IF(H24=0, ,(H23-H24))) -> 2 | J23: =B23+D23+F23+H23 -> 286 | K23: =J23/4 -> 71.5 | L23: =IF(AC23>0,((K23-AD23)+(AE23-K24)),IF(K24=0, ,(K23-K24))) -> 1 | M23: =7000*4 -> 28000 | N23: =L23*M23/100 -> 280 | O23: =N23*0.53 -> 148.4 | P23: =O23*9.32295 -> 1383.5258 | AC23: =Q23+T23+W23+Z23 -> 0 | AD23: =(R23+U23+X23+AA23)/4 -> 0 | AE23: =(S23+V23+Y23+AB23)/4 -> 0
A24: =(A23+1) -> 44300 | B24: 71 | C24: =IF(AC24>0,((B24-R24)+(S24-B25)),IF(B25=0, ,(B24-B25))) -> 1 | D24: 72 | E24: =IF(AC24>0,((D24-U24)+(V24-D25)),IF(D25=0, ,(D24-D25))) -> 2 | F24: 69 | G24: =IF(AC24>0,((F24-X24)+(Y24-F25)),IF(F25=0, ,(F24-F25))) -> 3 | H24: 70 | I24: =IF(AC24>0,((H24-AA24)+(AB24-H25)),IF(H25=0, ,(H24-H25))) -> 1 | J24: =B24+D24+F24+H24 -> 282 | K24: =J24/4 -> 70.5 | L24: =IF(AC24>0,((K24-AD24)+(AE24-K25)),IF(K25=0, ,(K24-K25))) -> 1.75 | M24: =7000*4 -> 28000 | N24: =L24*M24/100 -> 490 | O24: =N24*0.53 -> 259.7 | P24: =O24*9.32295 -> 2421.1701 | AC24: =Q24+T24+W24+Z24 -> 0 | AD24: =(R24+U24+X24+AA24)/4 -> 0 | AE24: =(S24+V24+Y24+AB24)/4 -> 0
A25: =(A24+1) -> 44301 | B25: 70 | C25: =IF(AC25>0,((B25-R25)+(S25-B26)),IF(B26=0, ,(B25-B26))) -> 2 | D25: 70 | E25: =IF(AC25>0,((D25-U25)+(V25-D26)),IF(D26=0, ,(D25-D26))) -> 0 | F25: 66 | G25: =IF(AC25>0,((F25-X25)+(Y25-F26)),IF(F26=0, ,(F25-F26))) -> 1 | H25: 69 | I25: =IF(AC25>0,((H25-AA25)+(AB25-H26)),IF(H26=0, ,(H25-H26))) -> 1 | J25: =B25+D25+F25+H25 -> 275 | K25: =J25/4 -> 68.75 | L25: =IF(AC25>0,((K25-AD25)+(AE25-K26)),IF(K26=0, ,(K25-K26))) -> 1 | M25: =7000*4 -> 28000 | N25: =L25*M25/100 -> 280 | O25: =N25*0.53 -> 148.4 | P25: =O25*9.32295 -> 1383.5258 | AC25: =Q25+T25+W25+Z25 -> 0 | AD25: =(R25+U25+X25+AA25)/4 -> 0 | AE25: =(S25+V25+Y25+AB25)/4 -> 0
A26: =(A25+1) -> 44302 | B26: 68 | C26: =IF(AC26>0,((B26-R26)+(S26-B27)),IF(B27=0, ,(B26-B27))) -> 0 | D26: 70 | E26: =IF(AC26>0,((D26-U26)+(V26-D27)),IF(D27=0, ,(D26-D27))) -> 5 | F26: 65 | G26: =IF(AC26>0,((F26-X26)+(Y26-F27)),IF(F27=0, ,(F26-F27))) -> 0 | H26: 68 | I26: =IF(AC26>0,((H26-AA26)+(AB26-H27)),IF(H27=0, ,(H26-H27))) -> 3 | J26: =B26+D26+F26+H26 -> 271 | K26: =J26/4 -> 67.75 | L26: =IF(AC26>0,((K26-AD26)+(AE26-K27)),IF(K27=0, ,(K26-K27))) -> 2 | M26: =7000*4 -> 28000 | N26: =L26*M26/100 -> 560 | O26: =N26*0.53 -> 296.8 | P26: =O26*9.32295 -> 2767.0516 | Q26: 859 | R26: 68 | S26: 85 | T26: 860 | U26: 65 | V26: 85 | W26: 917 | X26: 65 | Y26: 85 | Z26: 1043 | AA26: 65 | AB26: 85 | AC26: =Q26+T26+W26+Z26 -> 3679 | AD26: =(R26+U26+X26+AA26)/4 -> 65.75 | AE26: =(S26+V26+Y26+AB26)/4 -> 85
A27: =(A26+1) -> 44303 | B27: 85 | C27: =IF(AC27>0,((B27-R27)+(S27-B28)),IF(B28=0, ,(B27-B28))) -> 1 | D27: 85 | E27: =IF(AC27>0,((D27-U27)+(V27-D28)),IF(D28=0, ,(D27-D28))) -> 1 | F27: 85 | G27: =IF(AC27>0,((F27-X27)+(Y27-F28)),IF(F28=0, ,(F27-F28))) -> 1 | H27: 85 | I27: =IF(AC27>0,((H27-AA27)+(AB27-H28)),IF(H28=0, ,(H27-H28))) -> 1 | J27: =B27+D27+F27+H27 -> 340 | K27: =J27/4 -> 85 | L27: =IF(AC27>0,((K27-AD27)+(AE27-K28)),IF(K28=0, ,(K27-K28))) -> 1 | M27: =7000*4 -> 28000 | N27: =L27*M27/100 -> 280 | O27: =N27*0.53 -> 148.4 | P27: =O27*9.32295 -> 1383.5258 | AC27: =Q27+T27+W27+Z27 -> 0 | AD27: =(R27+U27+X27+AA27)/4 -> 0 | AE27: =(S27+V27+Y27+AB27)/4 -> 0
A28: =(A27+1) -> 44304 | B28: 84 | C28: =IF(AC28>0,((B28-R28)+(S28-B29)),IF(B29=0, ,(B28-B29))) -> 1 | D28: 84 | E28: =IF(AC28>0,((D28-U28)+(V28-D29)),IF(D29=0, ,(D28-D29))) -> 1 | F28: 84 | G28: =IF(AC28>0,((F28-X28)+(Y28-F29)),IF(F29=0, ,(F28-F29))) -> 1 | H28: 84 | I28: =IF(AC28>0,((H28-AA28)+(AB28-H29)),IF(H29=0, ,(H28-H29))) -> 1 | J28: =B28+D28+F28+H28 -> 336 | K28: =J28/4 -> 84 | L28: =IF(AC28>0,((K28-AD28)+(AE28-K29)),IF(K29=0, ,(K28-K29))) -> 1 | M28: =7000*4 -> 28000 | N28: =L28*M28/100 -> 280 | O28: =N28*0.53 -> 148.4 | P28: =O28*9.32295 -> 1383.5258 | AC28: =Q28+T28+W28+Z28 -> 0 | AD28: =(R28+U28+X28+AA28)/4 -> 0 | AE28: =(S28+V28+Y28+AB28)/4 -> 0
A29: =(A28+1) -> 44305 | B29: 83 | C29: =IF(AC29>0,((B29-R29)+(S29-B30)),IF(B30=0, ,(B29-B30))) -> 0 | D29: 83 | E29: =IF(AC29>0,((D29-U29)+(V29-D30)),IF(D30=0, ,(D29-D30))) -> 0 | F29: 83 | G29: =IF(AC29>0,((F29-X29)+(Y29-F30)),IF(F30=0, ,(F29-F30))) -> 0 | H29: 83 | I29: =IF(AC29>0,((H29-AA29)+(AB29-H30)),IF(H30=0, ,(H29-H30))) -> 0 | J29: =B29+D29+F29+H29 -> 332 | K29: =J29/4 -> 83 | L29: =IF(AC29>0,((K29-AD29)+(AE29-K30)),IF(K30=0, ,(K29-K30))) -> 0 | M29: =7000*4 -> 28000 | N29: =L29*M29/100 -> 0 | O29: =N29*0.53 -> 0 | P29: =O29*9.32295 -> 0 | AC29: =Q29+T29+W29+Z29 -> 0 | AD29: =(R29+U29+X29+AA29)/4 -> 0 | AE29: =(S29+V29+Y29+AB29)/4 -> 0
A30: =(A29+1) -> 44306 | C30: =IF(AC30>0,((B30-R30)+(S30-B31)),IF(B31=0, ,(B30-B31))) -> 0 | E30: =IF(AC30>0,((D30-U30)+(V30-D31)),IF(D31=0, ,(D30-D31))) -> 0 | G30: =IF(AC30>0,((F30-X30)+(Y30-F31)),IF(F31=0, ,(F30-F31))) -> 0 | I30: =IF(AC30>0,((H30-AA30)+(AB30-H31)),IF(H31=0, ,(H30-H31))) -> 0 | J30: =B30+D30+F30+H30 -> 0 | K30: =J30/4 -> 0 | L30: =IF(AC30>0,((K30-AD30)+(AE30-K31)),IF(K31=0, ,(K30-K31))) -> 0 | M30: =7000*4 -> 28000 | N30: =L30*M30/100 -> 0 | O30: =N30*0.53 -> 0 | P30: =O30*9.32295 -> 0 | AC30: =Q30+T30+W30+Z30 -> 0 | AD30: =(R30+U30+X30+AA30)/4 -> 0 | AE30: =(S30+V30+Y30+AB30)/4 -> 0
A31: =(A30+1) -> 44307 | C31: =IF(AC31>0,((B31-R31)+(S31-B32)),IF(B32=0, ,(B31-B32))) -> 0 | E31: =IF(AC31>0,((D31-U31)+(V31-D32)),IF(D32=0, ,(D31-D32))) -> 0 | G31: =IF(AC31>0,((F31-X31)+(Y31-F32)),IF(F32=0, ,(F31-F32))) -> 0 | I31: =IF(AC31>0,((H31-AA31)+(AB31-H32)),IF(H32=0, ,(H31-H32))) -> 0 | J31: =B31+D31+F31+H31 -> 0 | K31: =J31/4 -> 0 | L31: =IF(AC31>0,((K31-AD31)+(AE31-K32)),IF(K32=0, ,(K31-K32))) -> 0 | M31: =7000*4 -> 28000 | N31: =L31*M31/100 -> 0 | O31: =N31*0.53 -> 0 | P31: =O31*9.32295 -> 0 | AC31: =Q31+T31+W31+Z31 -> 0 | AD31: =(R31+U31+X31+AA31)/4 -> 0 | AE31: =(S31+V31+Y31+AB31)/4 -> 0
A32: =(A31+1) -> 44308 | C32: =IF(AC32>0,((B32-R32)+(S32-B33)),IF(B33=0, ,(B32-B33))) -> 0 | E32: =IF(AC32>0,((D32-U32)+(V32-D33)),IF(D33=0, ,(D32-D33))) -> 0 | G32: =IF(AC32>0,((F32-X32)+(Y32-F33)),IF(F33=0, ,(F32-F33))) -> 0 | I32: =IF(AC32>0,((H32-AA32)+(AB32-H33)),IF(H33=0, ,(H32-H33))) -> 0 | J32: =B32+D32+F32+H32 -> 0 | K32: =J32/4 -> 0 | L32: =IF(AC32>0,((K32-AD32)+(AE32-K33)),IF(K33=0, ,(K32-K33))) -> 0 | M32: =7000*4 -> 28000 | N32: =L32*M32/100 -> 0 | O32: =N32*0.53 -> 0 | P32: =O32*9.32295 -> 0 | AC32: =Q32+T32+W32+Z32 -> 0 | AD32: =(R32+U32+X32+AA32)/4 -> 0 | AE32: =(S32+V32+Y32+AB32)/4 -> 0
A33: =(A32+1) -> 44309 | C33: =IF(AC33>0,((B33-R33)+(S33-B34)),IF(B34=0, ,(B33-B34))) -> 0 | E33: =IF(AC33>0,((D33-U33)+(V33-D34)),IF(D34=0, ,(D33-D34))) -> 0 | G33: =IF(AC33>0,((F33-X33)+(Y33-F34)),IF(F34=0, ,(F33-F34))) -> 0 | I33: =IF(AC33>0,((H33-AA33)+(AB33-H34)),IF(H34=0, ,(H33-H34))) -> 0 | J33: =B33+D33+F33+H33 -> 0 | K33: =J33/4 -> 0 | L33: =IF(AC33>0,((K33-AD33)+(AE33-K34)),IF(K34=0, ,(K33-K34))) -> 0 | M33: =7000*4 -> 28000 | N33: =L33*M33/100 -> 0 | O33: =N33*0.53 -> 0 | P33: =O33*9.32295 -> 0 | AC33: =Q33+T33+W33+Z33 -> 0 | AD33: =(R33+U33+X33+AA33)/4 -> 0 | AE33: =(S33+V33+Y33+AB33)/4 -> 0
A34: =(A33+1) -> 44310 | C34: =IF(AC34>0,((B34-R34)+(S34-B35)),IF(B35=0, ,(B34-B35))) -> 0 | E34: =IF(AC34>0,((D34-U34)+(V34-D35)),IF(D35=0, ,(D34-D35))) -> 0 | G34: =IF(AC34>0,((F34-X34)+(Y34-F35)),IF(F35=0, ,(F34-F35))) -> 0 | I34: =IF(AC34>0,((H34-AA34)+(AB34-H35)),IF(H35=0, ,(H34-H35))) -> 0 | J34: =B34+D34+F34+H34 -> 0 | K34: =J34/4 -> 0 | L34: =IF(AC34>0,((K34-AD34)+(AE34-K35)),IF(K35=0, ,(K34-K35))) -> 0 | M34: =7000*4 -> 28000 | N34: =L34*M34/100 -> 0 | O34: =N34*0.53 -> 0 | P34: =O34*9.32295 -> 0 | AC34: =Q34+T34+W34+Z34 -> 0 | AD34: =(R34+U34+X34+AA34)/4 -> 0 | AE34: =(S34+V34+Y34+AB34)/4 -> 0
A35: =(A34+1) -> 44311 | C35: =IF(AC35>0,((B35-R35)+(S35-B36)),IF(B36=0, ,(B35-B36))) -> 0 | E35: =IF(AC35>0,((D35-U35)+(V35-D36)),IF(D36=0, ,(D35-D36))) -> 0 | G35: =IF(AC35>0,((F35-X35)+(Y35-F36)),IF(F36=0, ,(F35-F36))) -> 0 | I35: =IF(AC35>0,((H35-AA35)+(AB35-H36)),IF(H36=0, ,(H35-H36))) -> 0 | J35: =B35+D35+F35+H35 -> 0 | K35: =J35/4 -> 0 | L35: =IF(AC35>0,((K35-AD35)+(AE35-K36)),IF(K36=0, ,(K35-K36))) -> 0 | M35: =7000*4 -> 28000 | N35: =L35*M35/100 -> 0 | O35: =N35*0.53 -> 0 | P35: =O35*9.32295 -> 0 | AC35: =Q35+T35+W35+Z35 -> 0 | AD35: =(R35+U35+X35+AA35)/4 -> 0 | AE35: =(S35+V35+Y35+AB35)/4 -> 0
A36: =(A35+1) -> 44312 | C36: =IF(AC36>0,((B36-R36)+(S36-B37)),IF(B37=0, ,(B36-B37))) -> 0 | E36: =IF(AC36>0,((D36-U36)+(V36-D37)),IF(D37=0, ,(D36-D37))) -> 0 | G36: =IF(AC36>0,((F36-X36)+(Y36-F37)),IF(F37=0, ,(F36-F37))) -> 0 | I36: =IF(AC36>0,((H36-AA36)+(AB36-H37)),IF(H37=0, ,(H36-H37))) -> 0 | J36: =B36+D36+F36+H36 -> 0 | K36: =J36/4 -> 0 | L36: =IF(AC36>0,((K36-AD36)+(AE36-K37)),IF(K37=0, ,(K36-K37))) -> 0 | M36: =7000*4 -> 28000 | N36: =L36*M36/100 -> 0 | O36: =N36*0.53 -> 0 | P36: =O36*9.32295 -> 0 | AC36: =Q36+T36+W36+Z36 -> 0 | AD36: =(R36+U36+X36+AA36)/4 -> 0 | AE36: =(S36+V36+Y36+AB36)/4 -> 0
A37: =(A36+1) -> 44313 | C37: =IF(AC37>0,((B37-R37)+(S37-B38)),IF(B38=0, ,(B37-B38))) -> 0 | E37: =IF(AC37>0,((D37-U37)+(V37-D38)),IF(D38=0, ,(D37-D38))) -> 0 | G37: =IF(AC37>0,((F37-X37)+(Y37-F38)),IF(F38=0, ,(F37-F38))) -> 0 | I37: =IF(AC37>0,((H37-AA37)+(AB37-H38)),IF(H38=0, ,(H37-H38))) -> 0 | J37: =B37+D37+F37+H37 -> 0 | K37: =J37/4 -> 0 | L37: =IF(AC37>0,((K37-AD37)+(AE37-K38)),IF(K38=0, ,(K37-K38))) -> 0 | M37: =7000*4 -> 28000 | N37: =L37*M37/100 -> 0 | O37: =N37*0.53 -> 0 | P37: =O37*9.32295 -> 0 | AC37: =Q37+T37+W37+Z37 -> 0 | AD37: =(R37+U37+X37+AA37)/4 -> 0 | AE37: =(S37+V37+Y37+AB37)/4 -> 0
A38: =(A37+1) -> 44314 | C38: =IF(AC38>0,((B38-R38)+(S38-B39)),IF(B39=0, ,(B38-B39))) -> 0 | E38: =IF(AC38>0,((D38-U38)+(V38-D39)),IF(D39=0, ,(D38-D39))) -> 0 | G38: =IF(AC38>0,((F38-X38)+(Y38-F39)),IF(F39=0, ,(F38-F39))) -> 0 | I38: 2 | J38: =B38+D38+F38+H38 -> 0 | K38: =J38/4 -> 0 | L38: =IF(AC38>0,((K38-AD38)+(AE38-K39)),IF(K39=0, ,(K38-K39))) -> 0 | M38: =7000*4 -> 28000 | N38: =L38*M38/100 -> 0 | O38: =N38*0.53 -> 0 | P38: =O38*9.32295 -> 0 | AC38: =Q38+T38+W38+Z38 -> 0 | AD38: =(R38+U38+X38+AA38)/4 -> 0 | AE38: =(S38+V38+Y38+AB38)/4 -> 0
A39: =(A38+1) -> 44315 | C39: =IF(AC39>0,((B39-R39)+(S39-B40)),IF(B40=0, ,(B39-B40))) -> 0 | E39: =IF(AC39>0,((D39-U39)+(V39-D40)),IF(D40=0, ,(D39-D40))) -> 0 | G39: =IF(AC39>0,((F39-X39)+(Y39-F40)),IF(F40=0, ,(F39-F40))) -> 0 | I39: 0 | J39: =B39+D39+F39+H39 -> 0 | K39: =J39/4 -> 0 | L39: =IF(AC39>0,((K39-AD39)+(AE39-K40)),IF(K40=0, ,(K39-K40))) -> 0 | M39: =7000*4 -> 28000 | N39: =L39*M39/100 -> 0 | O39: =N39*0.53 -> 0 | P39: =O39*9.32295 -> 0 | AC39: =Q39+T39+W39+Z39 -> 0 | AD39: =(R39+U39+X39+AA39)/4 -> 0 | AE39: =(S39+V39+Y39+AB39)/4 -> 0
A40: =(A39+1) -> 44316 | C40: =IF(AC40>0,((B40-R40)+(S40-B41)),IF(B41=0, ,(B40-B41))) -> 0 | E40: =IF(AC40>0,((D40-U40)+(V40-D41)),IF(D41=0, ,(D40-D41))) -> 0 | G40: =IF(AC40>0,((F40-X40)+(Y40-F41)),IF(F41=0, ,(F40-F41))) -> 0 | I40: =IF(AC40>0,((H40-AA40)+(AB40-H41)),IF(H41=0, ,(H40-H41))) -> 0 | J40: =B40+D40+F40+H40 -> 0 | K40: =J40/4 -> 0 | L40: =IF(AC40>0,((K40-AD40)+(AE40-K41)),IF(K41=0, ,(K40-K41))) -> 0 | M40: =7000*4 -> 28000 | N40: =L40*M40/100 -> 0 | O40: =N40*0.53 -> 0 | P40: =O40*9.32295 -> 0 | AC40: =Q40+T40+W40+Z40 -> 0 | AD40: =(R40+U40+X40+AA40)/4 -> 0 | AE40: =(S40+V40+Y40+AB40)/4 -> 0
...

Sheet Suivi EAU-ELEC
C1: Suivi Compteur d'Eau- électricité RADEEMA -
D5: =SUM(C16:C45) -> 6665
A7: Date | B7: Eau m3 | D7: Electricité Kw/h
B8: Compteur | C8: Consommation | D8: Compteur H.Creuse | E8: Consommation H.Creuse | F8: Compteur H.Pleine | G8: Consommation H.Pleine | H8: Compteur H.Pointe | I8: Consommation H.Pointe
A9: 44280 | B9: 17913 | C9: =IF(B10<B9,0,B10-B9) -> 357 | D9: 19194962 | E9: =IF(D10<D9,0,D10-D9) -> 3709 | F9: 34325286 | G9: =IF(F10<F9,0,F10-F9) -> 5852 | H9: 15201513 | I9: =IF(H10<H9,0,H10-H9) -> 2867
A10: =(A9+1) -> 44281 | B10: 18270 | C10: =IF(B11<B10,0,B11-B10) -> 370 | D10: 19198671 | E10: =IF(D11<D10,0,D11-D10) -> 3393 | F10: 34331138 | G10: =IF(F11<F10,0,F11-F10) -> 4998 | H10: 15204380 | I10: =IF(H11<H10,0,H11-H10) -> 2128
A11: =(A10+1) -> 44282 | B11: 18640 | C11: =IF(B12<B11,0,B12-B11) -> 237 | D11: 19202064 | E11: =IF(D12<D11,0,D12-D11) -> 3816 | F11: 34336136 | G11: =IF(F12<F11,0,F12-F11) -> 5175 | H11: 15206508 | I11: =IF(H12<H11,0,H12-H11) -> 2913
A12: =(A11+1) -> 44283 | B12: 18877 | C12: =IF(B13<B12,0,B13-B12) -> 337 | D12: 19205880 | E12: =IF(D13<D12,0,D13-D12) -> 3408 | F12: 34341311 | G12: =IF(F13<F12,0,F13-F12) -> 5300 | H12: 15209421 | I12: =IF(H13<H12,0,H13-H12) -> 2287
A13: =(A12+1) -> 44284 | B13: 19214 | C13: =IF(B14<B13,0,B14-B13) -> 368 | D13: 19209288 | E13: =IF(D14<D13,0,D14-D13) -> 3790 | F13: 34346611 | G13: =IF(F14<F13,0,F14-F13) -> 7080 | H13: 15211708 | I13: =IF(H14<H13,0,H14-H13) -> 2570
A14: =(A13+1) -> 44285 | B14: 19582 | C14: =IF(B15<B14,0,B15-B14) -> 336 | D14: 19213078 | E14: =IF(D15<D14,0,D15-D14) -> 3614 | F14: 34353691 | G14: =IF(F15<F14,0,F15-F14) -> 6102 | H14: 15214278 | I14: =IF(H15<H14,0,H15-H14) -> 2513
A15: =(A14+1) -> 44286 | B15: 19918 | C15: =IF(B16<B15,0,B16-B15) -> 297 | D15: 19216692 | E15: =IF(D16<D15,0,D16-D15) -> 3830 | F15: 34359793 | G15: =IF(F16<F15,0,F16-F15) -> 6590 | H15: 15216791 | I15: =IF(H16<H15,0,H16-H15) -> 2838
A16: =(A15+1) -> 44287 | B16: 20215 | C16: =IF(B17<B16,0,B17-B16) -> 342 | D16: 19220522 | E16: =IF(D17<D16,0,D17-D16) -> 3753 | F16: 34366383 | G16: =IF(F17<F16,0,F17-F16) -> 7026 | H16: 15219629 | I16: =IF(H17<H16,0,H17-H16) -> 3187
A17: =(A16+1) -> 44288 | B17: 20557 | C17: =IF(B18<B17,0,B18-B17) -> 507 | D17: 19224275 | E17: =IF(D18<D17,0,D18-D17) -> 3377 | F17: 34373409 | G17: =IF(F18<F17,0,F18-F17) -> 8299 | H17: 15222816 | I17: =IF(H18<H17,0,H18-H17) -> 3378
A18: =(A17+1) -> 44289 | B18: 21064 | C18: =IF(B19<B18,0,B19-B18) -> 506 | D18: 19227652 | E18: =IF(D19<D18,0,D19-D18) -> 3827 | F18: 34381708 | G18: =IF(F19<F18,0,F19-F18) -> 8493 | H18: 15226194 | I18: =IF(H19<H18,0,H19-H18) -> 4000
A19: =(A18+1) -> 44290 | B19: 21570 | C19: =IF(B20<B19,0,B20-B19) -> 528 | D19: 19231479 | E19: =IF(D20<D19,0,D20-D19) -> 4272 | F19: 34390201 | G19: =IF(F20<F19,0,F20-F19) -> 7406 | H19: 15230194 | I19: =IF(H20<H19,0,H20-H19) -> 3632
A20: =(A19+1) -> 44291 | B20: 22098 | C20: =IF(B21<B20,0,B21-B20) -> 385 | D20: 19235751 | E20: =IF(D21<D20,0,D21-D20) -> 4074 | F20: 34397607 | G20: =IF(F21<F20,0,F21-F20) -> 7007 | H20: 15233826 | I20: =IF(H21<H20,0,H21-H20) -> 3686
A21: =(A20+1) -> 44292 | B21: 22483 | C21: =IF(B22<B21,0,B22-B21) -> 324 | D21: 19239825 | E21: =IF(D22<D21,0,D22-D21) -> 3211 | F21: 34404614 | G21: =IF(F22<F21,0,F22-F21) -> 5668 | H21: 15237512 | I21: =IF(H22<H21,0,H22-H21) -> 2019
... A34: =(A33+1) -> 44305 | B34: 26880 | C34: =IF(B35<B34,0,B35-B34) -> 0 | D34: 19278158 | E34: =IF(D35<D34,0,D35-D34) -> 0 | F34: 34473665 | G34: =IF(F35<F34,0,F35-F34) -> 0 | H34: 15267775 | I34: =IF(H35<H34,0,H35-H34) -> 0
A35: =(A34+1) -> 44306 | C35: =IF(B36<B35,0,B36-B35) -> 0 | E35: =IF(D36<D35,0,D36-D35) -> 0 | G35: =IF(F36<F35,0,F36-F35) -> 0 | I35: =IF(H36<H35,0,H36-H35) -> 0
A36: =(A35+1) -> 44307 | C36: =IF(B37<B36,0,B37-B36) -> 0 | E36: =IF(D37<D36,0,D37-D36) -> 0 | G36: =IF(F37<F36,0,F37-F36) -> 0 | I36: =IF(H37<H36,0,H37-H36) -> 0
A37: =(A36+1) -> 44308 | C37: =IF(B38<B37,0,B38-B37) -> 0 | E37: =IF(D38<D37,0,D38-D37) -> 0 | G37: =IF(F38<F37,0,F38-F37) -> 0 | I37: =IF(H38<H37,0,H38-H37) -> 0
A38: =(A37+1) -> 44309 | C38: =IF(B39<B38,0,B39-B38) -> 0 | E38: =IF(D39<D38,0,D39-D38) -> 0 | G38: =IF(F39<F38,0,F39-F38) -> 0 | I38: =IF(H39<H38,0,H39-H38) -> 0
A39: =(A38+1) -> 44310 | C39: =IF(B40<B39,0,B40-B39) -> 0 | E39: =IF(D40<D39,0,D40-D39) -> 0 | G39: =IF(F40<F39,0,F40-F39) -> 0 | I39: =IF(H40<H39,0,H40-H39) -> 0
A40: =(A39+1) -> 44311 | C40: =IF(B41<B40,0,B41-B40) -> 0 | E40: =IF(D41<D40,0,D41-D40) -> 0 | G40: =IF(F41<F40,0,F41-F40) -> 0 | I40: =IF(H41<H40,0,H41-H40) -> 0
A41: =(A40+1) -> 44312 | C41: =IF(B42<B41,0,B42-B41) -> 0 | E41: =IF(D42<D41,0,D42-D41) -> 0 | G41: =IF(F42<F41,0,F42-F41) -> 0 | I41: =IF(H42<H41,0,H42-H41) -> 0
A42: =(A41+1) -> 44313 | C42: =IF(B43<B42,0,B43-B42) -> 0 | E42: =IF(D43<D42,0,D43-D42) -> 0 | G42: =IF(F43<F42,0,F43-F42) -> 0 | I42: =IF(H43<H42,0,H43-H42) -> 0
A43: =(A42+1) -> 44314 | C43: =IF(B44<B43,0,B44-B43) -> 0 | E43: =IF(D44<D43,0,D44-D43) -> 0 | G43: =IF(F44<F43,0,F44-F43) -> 0 | I43: =IF(H44<H43,0,H44-H43) -> 0
A44: =(A43+1) -> 44315 | C44: =IF(B45<B44,0,B45-B44) -> 0 | E44: =IF(D45<D44,0,D45-D44) -> 0 | G44: =IF(F45<F44,0,F45-F44) -> 0 | I44: =IF(H45<H44,0,H45-H44) -> 0
A45: =(A44+1) -> 44316 | C45: =IF(B46<B45,0,B46-B45) -> 0 | E45: =IF(D46<D45,0,D46-D45) -> 0 | G45: =IF(F46<F45,0,F46-F45) -> 0 | I45: =IF(H46<H45,0,H46-H45) -> 0
A46: =(A45+1) -> 44317 | C46: =IF(B47<B46,0,B47-B46) -> 0 | E46: =IF(D47<D46,0,D47-D46) -> 0 | G46: =IF(F47<F46,0,F47-F46) -> 0 | I46: =IF(H47<H46,0,H47-H46) -> 0
A47: =(A46+1) -> 44318 | C47: =IF(B48<B47,0,B48-B47) -> 0 | E47: =IF(D48<D47,0,D48-D47) -> 0 | G47: =IF(F48<F47,0,F48-F47) -> 0 | I47: =IF(H48<H47,0,H48-H47) -> 0
C48: =SUM(C16:C45) -> 6665 | E48: =SUM(E16:E45) -> 57636 | G48: =SUM(G16:G45) -> 107282 | I48: =SUM(I16:I45) -> 48146

Sheet Feuil1
