Workbook

Sheet TOTAL
A1: Site Name | B1: Day | C1: Month | D1: Year | E1: Total Electricity Kwh | F1: Electricity Tariff ($/Kwh) | G1: Natual Gas (m3) | H1: Natural Gas $/m3 | I1: Water Utility Supply (m3) m3 | J1: Water Utility Supply (m3) $/m3 | K1: Room Nights
A2: Cairo at Nile Plaza | B2: 1 | C2: 4 | D2: 2021 | E2: =(((Submetering!O2+Submetering!P2)*0.842284+Submetering!Q2+(Submetering!M2+Submetering!N2+Submetering!Y2)*0.7362)+(Submetering!O2+Submetering!P2+Submetering!Q2)*0.1488+(Submetering!M2+Submetering!N2+Submetering!Y2)*0.1167+(Submetering!K2+Submetering!L2-Submetering!Z2-Submetering!AA2-Submetering!AB2-Submetering!AC2-Submetering!Q2)+(Submetering!M2+Submetering!N2+Submetering!Y2)*0.1139) -> 51030.146 | F2: 0 | G2: =Gas!C3*0.9147 -> 1723.2948 | H2: 0 | I2: 0 | J2: 0 | K2: =ELECT.!B3 -> 160
A3: Cairo at Nile Plaza | B3: =B2+1 -> 2 | C3: 4 | D3: 2021 | E3: =(((Submetering!O3+Submetering!P3)*0.842284+Submetering!Q3+(Submetering!M3+Submetering!N3+Submetering!Y3)*0.7362)+(Submetering!O3+Submetering!P3+Submetering!Q3)*0.1488+(Submetering!M3+Submetering!N3+Submetering!Y3)*0.1167+(Submetering!K3+Submetering!L3-Submetering!Z3-Submetering!AA3-Submetering!AB3-Submetering!AC3-Submetering!Q3)+(Submetering!M3+Submetering!N3+Submetering!Y3)*0.1139) -> 33778.837 | F3: 0 | G3: =Gas!C4*0.9147 -> 2328.8262 | H3: 0 | I3: 0 | J3: 0 | K3: =ELECT.!B4 -> 182
A4: Cairo at Nile Plaza | B4: =B3+1 -> 3 | C4: 4 | D4: 2021 | E4: =(((Submetering!O4+Submetering!P4)*0.842284+Submetering!Q4+(Submetering!M4+Submetering!N4+Submetering!Y4)*0.7362)+(Submetering!O4+Submetering!P4+Submetering!Q4)*0.1488+(Submetering!M4+Submetering!N4+Submetering!Y4)*0.1167+(Submetering!K4+Submetering!L4-Submetering!Z4-Submetering!AA4-Submetering!AB4-Submetering!AC4-Submetering!Q4)+(Submetering!M4+Submetering!N4+Submetering!Y4)*0.1139) -> 54012.192 | F4: 0 | G4: =Gas!C5*0.9147 -> 2069.0514 | H4: 0 | I4: 0 | J4: 0 | K4: =ELECT.!B5 -> 183
A5: Cairo at Nile Plaza | B5: =B4+1 -> 4 | C5: 4 | D5: 2021 | E5: =(((Submetering!O5+Submetering!P5)*0.842284+Submetering!Q5+(Submetering!M5+Submetering!N5+Submetering!Y5)*0.7362)+(Submetering!O5+Submetering!P5+Submetering!Q5)*0.1488+(Submetering!M5+Submetering!N5+Submetering!Y5)*0.1167+(Submetering!K5+Submetering!L5-Submetering!Z5-Submetering!AA5-Submetering!AB5-Submetering!AC5-Submetering!Q5)+(Submetering!M5+Submetering!N5+Submetering!Y5)*0.1139) -> 43419.317 | F5: 0 | G5: =Gas!C6*0.9147 -> 2009.5959 | H5: 0 | I5: 0 | J5: 0 | K5: =ELECT.!B6 -> 168
A6: Cairo at Nile Plaza | B6: =B5+1 -> 5 | C6: 4 | D6: 2021 | E6: =(((Submetering!O6+Submetering!P6)*0.842284+Submetering!Q6+(Submetering!M6+Submetering!N6+Submetering!Y6)*0.7362)+(Submetering!O6+Submetering!P6+Submetering!Q6)*0.1488+(Submetering!M6+Submetering!N6+Submetering!Y6)*0.1167+(Submetering!K6+Submetering!L6-Submetering!Z6-Submetering!AA6-Submetering!AB6-Submetering!AC6-Submetering!Q6)+(Submetering!M6+Submetering!N6+Submetering!Y6)*0.1139) -> 57575.567 | F6: 0 | G6: =Gas!C7*0.9147 -> 2364.4995 | H6: 0 | I6: 0 | J6: 0 | K6: =ELECT.!B7 -> 138
A7: Cairo at Nile Plaza | B7: =B6+1 -> 6 | C7: 4 | D7: 2021 | E7: =(((Submetering!O7+Submetering!P7)*0.842284+Submetering!Q7+(Submetering!M7+Submetering!N7+Submetering!Y7)*0.7362)+(Submetering!O7+Submetering!P7+Submetering!Q7)*0.1488+(Submetering!M7+Submetering!N7+Submetering!Y7)*0.1167+(Submetering!K7+Submetering!L7-Submetering!Z7-Submetering!AA7-Submetering!AB7-Submetering!AC7-Submetering!Q7)+(Submetering!M7+Submetering!N7+Submetering!Y7)*0.1139) -> 39153.974 | F7: 0 | G7: =Gas!C8*0.9147 -> 2071.7955 | H7: 0 | I7: 0 | J7: 0 | K7: =ELECT.!B8 -> 146
A8: Cairo at Nile Plaza | B8: =B7+1 -> 7 | C8: 4 | D8: 2021 | E8: =(((Submetering!O8+Submetering!P8)*0.842284+Submetering!Q8+(Submetering!M8+Submetering!N8+Submetering!Y8)*0.7362)+(Submetering!O8+Submetering!P8+Submetering!Q8)*0.1488+(Submetering!M8+Submetering!N8+Submetering!Y8)*0.1167+(Submetering!K8+Submetering!L8-Submetering!Z8-Submetering!AA8-Submetering!AB8-Submetering!AC8-Submetering!Q8)+(Submetering!M8+Submetering!N8+Submetering!Y8)*0.1139) -> 57611.489 | F8: 0 | G8: =Gas!C9*0.9147 -> 1940.9934 | H8: 0 | I8: 0 | J8: 0 | K8: =ELECT.!B9 -> 154
A9: Cairo at Nile Plaza | B9: =B8+1 -> 8 | C9: 4 | D9: 2021 | E9: =(((Submetering!O9+Submetering!P9)*0.842284+Submetering!Q9+(Submetering!M9+Submetering!N9+Submetering!Y9)*0.7362)+(Submetering!O9+Submetering!P9+Submetering!Q9)*0.1488+(Submetering!M9+Submetering!N9+Submetering!Y9)*0.1167+(Submetering!K9+Submetering!L9-Submetering!Z9-Submetering!AA9-Submetering!AB9-Submetering!AC9-Submetering!Q9)+(Submetering!M9+Submetering!N9+Submetering!Y9)*0.1139) -> 52074.496 | F9: 0 | G9: =Gas!C10*0.9147 -> 1865.988 | H9: 0 | I9: 0 | J9: 0 | K9: =ELECT.!B10 -> 148
A10: Cairo at Nile Plaza | B10: =B9+1 -> 9 | C10: 4 | D10: 2021 | E10: =(((Submetering!O10+Submetering!P10)*0.842284+Submetering!Q10+(Submetering!M10+Submetering!N10+Submetering!Y10)*0.7362)+(Submetering!O10+Submetering!P10+Submetering!Q10)*0.1488+(Submetering!M10+Submetering!N10+Submetering!Y10)*0.1167+(Submetering!K10+Submetering!L10-Submetering!Z10-Submetering!AA10-Submetering!AB10-Submetering!AC10-Submetering!Q10)+(Submetering!M10+Submetering!N10+Submetering!Y10)*0.1139) -> 48628.163 | F10: 0 | G10: =Gas!C11*0.9147 -> 1976.6667 | H10: 0 | I10: 0 | J10: 0 | K10: =ELECT.!B11 -> 144
A11: Cairo at Nile Plaza | B11: =B10+1 -> 10 | C11: 4 | D11: 2021 | E11: =(((Submetering!O11+Submetering!P11)*0.842284+Submetering!Q11+(Submetering!M11+Submetering!N11+Submetering!Y11)*0.7362)+(Submetering!O11+Submetering!P11+Submetering!Q11)*0.1488+(Submetering!M11+Submetering!N11+Submetering!Y11)*0.1167+(Submetering!K11+Submetering!L11-Submetering!Z11-Submetering!AA11-Submetering!AB11-Submetering!AC11-Submetering!Q11)+(Submetering!M11+Submetering!N11+Submetering!Y11)*0.1139) -> 67860.506 | F11: 0 | G11: =Gas!C12*0.9147 -> 1992.2166 | H11: 0 | I11: 0 | J11: 0 | K11: =ELECT.!B12 -> 141
A12: Cairo at Nile Plaza | B12: =B11+1 -> 11 | C12: 4 | D12: 2021 | E12: =(((Submetering!O12+Submetering!P12)*0.842284+Submetering!Q12+(Submetering!M12+Submetering!N12+Submetering!Y12)*0.7362)+(Submetering!O12+Submetering!P12+Submetering!Q12)*0.1488+(Submetering!M12+Submetering!N12+Submetering!Y12)*0.1167+(Submetering!K12+Submetering!L12-Submetering!Z12-Submetering!AA12-Submetering!AB12-Submetering!AC12-Submetering!Q12)+(Submetering!M12+Submetering!N12+Submetering!Y12)*0.1139) -> 83131.751 | F12: 0 | G12: =Gas!C13*0.9147 -> 2600.4921 | H12: 0 | I12: 0 | J12: 0 | K12: =ELECT.!B13 -> 138
A13: Cairo at Nile Plaza | B13: =B12+1 -> 12 | C13: 4 | D13: 2021 | E13: =(((Submetering!O13+Submetering!P13)*0.842284+Submetering!Q13+(Submetering!M13+Submetering!N13+Submetering!Y13)*0.7362)+(Submetering!O13+Submetering!P13+Submetering!Q13)*0.1488+(Submetering!M13+Submetering!N13+Submetering!Y13)*0.1167+(Submetering!K13+Submetering!L13-Submetering!Z13-Submetering!AA13-Submetering!AB13-Submetering!AC13-Submetering!Q13)+(Submetering!M13+Submetering!N13+Submetering!Y13)*0.1139) -> 11254.241 | F13: 0 | G13: =Gas!C14*0.9147 -> 2040.6957 | H13: 0 | I13: 0 | J13: 0 | K13: =ELECT.!B14 -> 123
A14: Cairo at Nile Plaza | B14: =B13+1 -> 13 | C14: 4 | D14: 2021 | E14: =(((Submetering!O14+Submetering!P14)*0.842284+Submetering!Q14+(Submetering!M14+Submetering!N14+Submetering!Y14)*0.7362)+(Submetering!O14+Submetering!P14+Submetering!Q14)*0.1488+(Submetering!M14+Submetering!N14+Submetering!Y14)*0.1167+(Submetering!K14+Submetering!L14-Submetering!Z14-Submetering!AA14-Submetering!AB14-Submetering!AC14-Submetering!Q14)+(Submetering!M14+Submetering!N14+Submetering!Y14)*0.1139) -> 47979.68 | F14: 0 | G14: =Gas!C15*0.9147 -> 1922.6994 | H14: 0 | I14: 0 | J14: 0 | K14: =ELECT.!B15 -> 0
... A31: Cairo at Nile Plaza | B31: =B30+1 -> 30 | C31: 4 | D31: 2021 | E31: =(((Submetering!O31+Submetering!P31)*0.842284+Submetering!Q31+(Submetering!M31+Submetering!N31+Submetering!Y31)*0.7362)+(Submetering!O31+Submetering!P31+Submetering!Q31)*0.1488+(Submetering!M31+Submetering!N31+Submetering!Y31)*0.1167+(Submetering!K31+Submetering!L31-Submetering!Z31-Submetering!AA31-Submetering!AB31-Submetering!AC31-Submetering!Q31)+(Submetering!M31+Submetering!N31+Submetering!Y31)*0.1139) -> 0 | F31: 0 | G31: =Gas!C32*0.9147 -> 0 | H31: 0 | I31: 0 | J31: 0 | K31: =ELECT.!B32 -> 0

Sheet Submetering
A1: Site Name | B1: Day | C1: Month | D1: Year | E1: Main (m3) | F1: Podium (m3) | G1: Hotel (m3) | H1: Large (m3) | I1: Feeder 1 (KWh) | J1: Feeder 2 (KWh) | K1: T1 (KWh) | L1: T2 (KWh) | M1: T3 (KWh) | N1: T4 (KWh) | O1: T5 (KWh) | P1: T7 (KWh) | Q1: New Chiller (KWh) | R1: Hotel (BTU) | S1: B.S (BTU) | T1: LS (BTU) | U1: Mall (BTU) | V1: AHU#25 (BTU) | W1: AHU#9 (BTU) | X1: Room Nights | Y1: Loss (KWH) | Z1: Mall (KWH) | AA1: Citadel (KWH) | AB1: Rotana (KWH) | AC1: CIB (KWH) | AD1: Plaza suits water consumption (M3) | AE1: Hotel water consumption (M3)
A2: Cairo at Nile Plaza | B2: 1 | C2: 4 | D2: 2021 | E2: =Water!C3 -> 740 | F2: =Water!E3 -> 359.1 | G2: =Water!G3 -> 191.7 | H2: =Water!I3 -> 3.348 | I2: =ELECT.!F3 -> 8893 | J2: =ELECT.!H3 -> 45508 | K2: =ELECT.!K3 -> 4854 | L2: =ELECT.!M3 -> 6261 | M2: =ELECT.!O3 -> 2466 | N2: =ELECT.!Q3 -> 8474 | O2: =ELECT.!S3 -> 9775 | P2: =ELECT.!W3*2 -> 21300 | Q2: =ELECT.!D3 -> 320 | R2: =BTU!C3 -> 4.125 | S2: =BTU!F3 -> 1.291 | T2: =BTU!I3 -> 5 | U2: =BTU!O3 -> 1.172 | V2: =BTU!L3 -> 0.81 | W2: =BTU!R3 -> 0.115 | X2: =ELECT.!B3 -> 160 | Y2: =I2+J2-(K2+L2+M2+N2+O2+P2) -> 1271 | Z2: ='Mall, Citadel, Rotana'!C3+'Mall, Citadel, Rotana'!E3+'Mall, Citadel, Rotana'!G3+'Mall, Citadel, Rotana'!I3 -> 1712 | AA2: ='Mall, Citadel, Rotana'!K3+'Mall, Citadel, Rotana'!M3 -> 800 | AB2: ='Mall, Citadel, Rotana'!O3 -> 163 | AC2: ='Mall, Citadel, Rotana'!Q3+'Mall, Citadel, Rotana'!S3 -> 61 | AD2: =(E2-H2-194)*0.1318 -> 71.521534 | AE2: =E2-H2-AD2-194 -> 471.13047
A3: Cairo at Nile Plaza | B3: =B2+1 -> 2 | C3: 4 | D3: 2021 | E3: =Water!C4 -> 240 | F3: =Water!E4 -> 332.1 | G3: =Water!G4 -> 353.7 | H3: =Water!I4 -> 3.726 | I3: =ELECT.!F4 -> 5807 | J3: =ELECT.!H4 -> 30588 | K3: =ELECT.!K4 -> 3392 | L3: =ELECT.!M4 -> 3820 | M3: =ELECT.!O4 -> 1866 | N3: =ELECT.!Q4 -> 5778 | O3: =ELECT.!S4 -> 6487 | P3: =ELECT.!W4*2 -> 14246 | Q3: =ELECT.!D4 -> 640 | R3: =BTU!C4 -> 4.225 | S3: =BTU!F4 -> 1.029 | T3: =BTU!I4 -> 5 | U3: =BTU!O4 -> 1.369 | V3: =BTU!L4 -> 0.63 | W3: =BTU!R4 -> 0.62 | X3: =ELECT.!B4 -> 182 | Y3: =I3+J3-(K3+L3+M3+N3+O3+P3) -> 806 | Z3: ='Mall, Citadel, Rotana'!C4+'Mall, Citadel, Rotana'!E4+'Mall, Citadel, Rotana'!G4+'Mall, Citadel, Rotana'!I4 -> 1539 | AA3: ='Mall, Citadel, Rotana'!K4+'Mall, Citadel, Rotana'!M4 -> 480 | AB3: ='Mall, Citadel, Rotana'!O4 -> 207 | AC3: ='Mall, Citadel, Rotana'!Q4+'Mall, Citadel, Rotana'!S4 -> 20 | AD3: =(E3-H3-194)*0.1318 -> 5.5717132 | AE3: =E3-H3-AD3-194 -> 36.702287
A4: Cairo at Nile Plaza | B4: =B3+1 -> 3 | C4: 4 | D4: 2021 | E4: =Water!C5 -> 1240 | F4: =Water!E5 -> 329.4 | G4: =Water!G5 -> 229.5 | H4: =Water!I5 -> 5.049 | I4: =ELECT.!F5 -> 8458 | J4: =ELECT.!H5 -> 47825 | K4: =ELECT.!K5 -> 4721 | L4: =ELECT.!M5 -> 5582 | M4: =ELECT.!O5 -> 2690 | N4: =ELECT.!Q5 -> 8747 | O4: =ELECT.!S5 -> 10416 | P4: =ELECT.!W5*2 -> 22936 | Q4: =ELECT.!D5 -> 160 | R4: =BTU!C5 -> 4.83 | S4: =BTU!F5 -> 0.557 | T4: =BTU!I5 -> 5 | U4: =BTU!O5 -> 1.25 | V4: =BTU!L5 -> 0.22 | W4: =BTU!R5 -> 0.99 | X4: =ELECT.!B5 -> 183 | Y4: =I4+J4-(K4+L4+M4+N4+O4+P4) -> 1191 | Z4: ='Mall, Citadel, Rotana'!C5+'Mall, Citadel, Rotana'!E5+'Mall, Citadel, Rotana'!G5+'Mall, Citadel, Rotana'!I5 -> 1201 | AA4: ='Mall, Citadel, Rotana'!K5+'Mall, Citadel, Rotana'!M5 -> 320 | AB4: ='Mall, Citadel, Rotana'!O5 -> 8 | AC4: ='Mall, Citadel, Rotana'!Q5+'Mall, Citadel, Rotana'!S5 -> 49 | AD4: =(E4-H4-194)*0.1318 -> 137.19734 | AE4: =E4-H4-AD4-194 -> 903.75366
A5: Cairo at Nile Plaza | B5: =B4+1 -> 4 | C5: 4 | D5: 2021 | E5: =Water!C6 -> 820 | F5: =Water!E6 -> 345.6 | G5: =Water!G6 -> 256.5 | H5: =Water!I6 -> 5.049 | I5: =ELECT.!F6 -> 6940 | J5: =ELECT.!H6 -> 38969 | K5: =ELECT.!K6 -> 4001 | L5: =ELECT.!M6 -> 4511 | M5: =ELECT.!O6 -> 2296 | N5: =ELECT.!Q6 -> 7259 | O5: =ELECT.!S6 -> 8558 | P5: =ELECT.!W6*2 -> 18434 | Q5: =ELECT.!D6 -> 480 | R5: =BTU!C6 -> 3.3 | S5: =BTU!F6 -> 0.449 | T5: =BTU!I6 -> 4 | U5: =BTU!O6 -> 0.866 | V5: =BTU!L6 -> 0 | W5: =BTU!R6 -> 0.86 | X5: =ELECT.!B6 -> 168 | Y5: =I5+J5-(K5+L5+M5+N5+O5+P5) -> 850 | Z5: ='Mall, Citadel, Rotana'!C6+'Mall, Citadel, Rotana'!E6+'Mall, Citadel, Rotana'!G6+'Mall, Citadel, Rotana'!I6 -> 1359 | AA5: ='Mall, Citadel, Rotana'!K6+'Mall, Citadel, Rotana'!M6 -> 480 | AB5: ='Mall, Citadel, Rotana'!O6 -> 56 | AC5: ='Mall, Citadel, Rotana'!Q6+'Mall, Citadel, Rotana'!S6 -> 80 | AD5: =(E5-H5-194)*0.1318 -> 81.841342 | AE5: =E5-H5-AD5-194 -> 539.10966
A6: Cairo at Nile Plaza | B6: =B5+1 -> 5 | C6: 4 | D6: 2021 | E6: =Water!C7 -> 750 | F6: =Water!E7 -> 324 | G6: =Water!G7 -> 259.2 | H6: =Water!I7 -> 4.428 | I6: =ELECT.!F7 -> 8713 | J6: =ELECT.!H7 -> 51895 | K6: =ELECT.!K7 -> 5767 | L6: =ELECT.!M7 -> 5757 | M6: =ELECT.!O7 -> 2766 | N6: =ELECT.!Q7 -> 10485 | O6: =ELECT.!S7 -> 10869 | P6: =ELECT.!W7*2 -> 23538 | Q6: =ELECT.!D7 -> 320 | R6: =BTU!C7 -> 4.718 | S6: =BTU!F7 -> 1.001 | T6: =BTU!I7 -> 6 | U6: =BTU!O7 -> 1.268 | V6: =BTU!L7 -> 0 | W6: =BTU!R7 -> 0.3 | X6: =ELECT.!B7 -> 138 | Y6: =I6+J6-(K6+L6+M6+N6+O6+P6) -> 1426 | Z6: ='Mall, Citadel, Rotana'!C7+'Mall, Citadel, Rotana'!E7+'Mall, Citadel, Rotana'!G7+'Mall, Citadel, Rotana'!I7 -> 1369 | AA6: ='Mall, Citadel, Rotana'!K7+'Mall, Citadel, Rotana'!M7 -> 640 | AB6: ='Mall, Citadel, Rotana'!O7 -> 114 | AC6: ='Mall, Citadel, Rotana'!Q7+'Mall, Citadel, Rotana'!S7 -> 163 | AD6: =(E6-H6-194)*0.1318 -> 72.69719 | AE6: =E6-H6-AD6-194 -> 478.87481
A7: Cairo at Nile Plaza | B7: =B6+1 -> 6 | C7: 4 | D7: 2021 | E7: =Water!C8 -> 1170 | F7: =Water!E8 -> 340.2 | G7: =Water!G8 -> 318.6 | H7: =Water!I8 -> 3.78 | I7: =ELECT.!F8 -> 6869 | J7: =ELECT.!H8 -> 35406 | K7: =ELECT.!K8 -> 4378 | L7: =ELECT.!M8 -> 4452 | M7: =ELECT.!O8 -> 2302 | N7: =ELECT.!Q8 -> 7666 | O7: =ELECT.!S8 -> 6792 | P7: =ELECT.!W8*2 -> 15928 | Q7: =ELECT.!D8 -> 320 | R7: =BTU!C8 -> 4.433 | S7: =BTU!F8 -> 1.406 | T7: =BTU!I8 -> 5 | U7: =BTU!O8 -> 1.387 | V7: =BTU!L8 -> 0 | W7: =BTU!R8 -> 0.4 | X7: =ELECT.!B8 -> 146 | Y7: =I7+J7-(K7+L7+M7+N7+O7+P7) -> 757 | Z7: ='Mall, Citadel, Rotana'!C8+'Mall, Citadel, Rotana'!E8+'Mall, Citadel, Rotana'!G8+'Mall, Citadel, Rotana'!I8 -> 1542 | AA7: ='Mall, Citadel, Rotana'!K8+'Mall, Citadel, Rotana'!M8 -> 800 | AB7: ='Mall, Citadel, Rotana'!O8 -> 140 | AC7: ='Mall, Citadel, Rotana'!Q8+'Mall, Citadel, Rotana'!S8 -> 128 | AD7: =(E7-H7-194)*0.1318 -> 128.1386 | AE7: =E7-H7-AD7-194 -> 844.0814
A8: Cairo at Nile Plaza | B8: =B7+1 -> 7 | C8: 4 | D8: 2021 | E8: =Water!C9 -> 560 | F8: =Water!E9 -> 337.5 | G8: =Water!G9 -> 297 | H8: =Water!I9 -> 3.402 | I8: =ELECT.!F9 -> 9751 | J8: =ELECT.!H9 -> 50539 | K8: =ELECT.!K9 -> 6262 | L8: =ELECT.!M9 -> 6262 | M8: =ELECT.!O9 -> 4070 | N8: =ELECT.!Q9 -> 11031 | O8: =ELECT.!S9 -> 9398 | P8: =ELECT.!W9*2 -> 22800 | Q8: =ELECT.!D9 -> 480 | R8: =BTU!C9 -> 5.363 | S8: =BTU!F9 -> 1.548 | T8: =BTU!I9 -> 5 | U8: =BTU!O9 -> 1.419 | V8: =BTU!L9 -> 0.82 | W8: =BTU!R9 -> 0.35 | X8: =ELECT.!B9 -> 154 | Y8: =I8+J8-(K8+L8+M8+N8+O8+P8) -> 467 | Z8: ='Mall, Citadel, Rotana'!C9+'Mall, Citadel, Rotana'!E9+'Mall, Citadel, Rotana'!G9+'Mall, Citadel, Rotana'!I9 -> 1221 | AA8: ='Mall, Citadel, Rotana'!K9+'Mall, Citadel, Rotana'!M9 -> 480 | AB8: ='Mall, Citadel, Rotana'!O9 -> 115 | AC8: ='Mall, Citadel, Rotana'!Q9+'Mall, Citadel, Rotana'!S9 -> 130 | AD8: =(E8-H8-194)*0.1318 -> 47.790416 | AE8: =E8-H8-AD8-194 -> 314.80758
A9: Cairo at Nile Plaza | B9: =B8+1 -> 8 | C9: 4 | D9: 2021 | E9: =Water!C10 -> 500 | F9: =Water!E10 -> 375.3 | G9: =Water!G10 -> 375.3 | H9: =Water!I10 -> 4.05 | I9: =ELECT.!F10 -> 8764 | J9: =ELECT.!H10 -> 46300 | K9: =ELECT.!K10 -> 6002 | L9: =ELECT.!M10 -> 4933 | M9: =ELECT.!O10 -> 2946 | N9: =ELECT.!Q10 -> 9787 | O9: =ELECT.!S10 -> 9006 | P9: =ELECT.!W10*2 -> 20526 | Q9: =ELECT.!D10 -> 480 | R9: =BTU!C10 -> 6.356 | S9: =BTU!F10 -> 1.731 | T9: =BTU!I10 -> 6 | U9: =BTU!O10 -> 1.541 | V9: =BTU!L10 -> 1.63 | W9: =BTU!R10 -> 1.53 | X9: =ELECT.!B10 -> 148 | Y9: =I9+J9-(K9+L9+M9+N9+O9+P9) -> 1864 | Z9: ='Mall, Citadel, Rotana'!C10+'Mall, Citadel, Rotana'!E10+'Mall, Citadel, Rotana'!G10+'Mall, Citadel, Rotana'!I10 -> 1408 | AA9: ='Mall, Citadel, Rotana'!K10+'Mall, Citadel, Rotana'!M10 -> 640 | AB9: ='Mall, Citadel, Rotana'!O10 -> 115 | AC9: ='Mall, Citadel, Rotana'!Q10+'Mall, Citadel, Rotana'!S10 -> 150 | AD9: =(E9-H9-194)*0.1318 -> 39.79701 | AE9: =E9-H9-AD9-194 -> 262.15299
A10: Cairo at Nile Plaza | B10: =B9+1 -> 9 | C10: 4 | D10: 2021 | E10: =Water!C11 -> 550 | F10: =Water!E11 -> 321.3 | G10: =Water!G11 -> 356.4 | H10: =Water!I11 -> 4.59 | I10: =ELECT.!F11 -> 7221 | J10: =ELECT.!H11 -> 44359 | K10: =ELECT.!K11 -> 5428 | L10: =ELECT.!M11 -> 4453 | M10: =ELECT.!O11 -> 2628 | N10: =ELECT.!Q11 -> 9136 | O10: =ELECT.!S11 -> 8657 | P10: =ELECT.!W11*2 -> 20306 | Q10: =ELECT.!D11 -> 640 | R10: =BTU!C11 -> 6.575 | S10: =BTU!F11 -> 1.812 | T10: =BTU!I11 -> 7 | U10: =BTU!O11 -> 1.96 | V10: =BTU!L11 -> 1.68 | W10: =BTU!R11 -> 1.067 | X10: =ELECT.!B11 -> 144 | Y10: =I10+J10-(K10+L10+M10+N10+O10+P10) -> 972 | Z10: ='Mall, Citadel, Rotana'!C11+'Mall, Citadel, Rotana'!E11+'Mall, Citadel, Rotana'!G11+'Mall, Citadel, Rotana'!I11 -> 1419 | AA10: ='Mall, Citadel, Rotana'!K11+'Mall, Citadel, Rotana'!M11 -> 640 | AB10: ='Mall, Citadel, Rotana'!O11 -> 127 | AC10: ='Mall, Citadel, Rotana'!Q11+'Mall, Citadel, Rotana'!S11 -> 180 | AD10: =(E10-H10-194)*0.1318 -> 46.315838 | AE10: =E10-H10-AD10-194 -> 305.09416
A11: Cairo at Nile Plaza | B11: =B10+1 -> 10 | C11: 4 | D11: 2021 | E11: =Water!C12 -> 1660 | F11: =Water!E12 -> 369.9 | G11: =Water!G12 -> 194.4 | H11: =Water!I12 -> 2.538 | I11: =ELECT.!F12 -> 10215 | J11: =ELECT.!H12 -> 60635 | K11: =ELECT.!K12 -> 6841 | L11: =ELECT.!M12 -> 6803 | M11: =ELECT.!O12 -> 3216 | N11: =ELECT.!Q12 -> 11893 | O11: =ELECT.!S12 -> 12357 | P11: =ELECT.!W12*2 -> 28210 | Q11: =ELECT.!D12 -> 320 | R11: =BTU!C12 -> 5.518 | S11: =BTU!F12 -> 0.914 | T11: =BTU!I12 -> 5 | U11: =BTU!O12 -> 1.553 | V11: =BTU!L12 -> 1.2 | W11: =BTU!R12 -> 1.043 | X11: =ELECT.!B12 -> 141 | Y11: =I11+J11-(K11+L11+M11+N11+O11+P11) -> 1530 | Z11: ='Mall, Citadel, Rotana'!C12+'Mall, Citadel, Rotana'!E12+'Mall, Citadel, Rotana'!G12+'Mall, Citadel, Rotana'!I12 -> 1392 | AA11: ='Mall, Citadel, Rotana'!K12+'Mall, Citadel, Rotana'!M12 -> 480 | AB11: ='Mall, Citadel, Rotana'!O12 -> 82 | AC11: ='Mall, Citadel, Rotana'!Q12+'Mall, Citadel, Rotana'!S12 -> 169 | AD11: =(E11-H11-194)*0.1318 -> 192.88429 | AE11: =E11-H11-AD11-194 -> 1270.5777
A12: Cairo at Nile Plaza | B12: =B11+1 -> 11 | C12: 4 | D12: 2021 | E12: =Water!C13 -> 1660 | F12: =Water!E13 -> 318.6 | G12: =Water!G13 -> 251.1 | H12: =Water!I13 -> 3.294 | I12: =ELECT.!F13 -> 5041 | J12: =ELECT.!H13 -> 82666 | K12: =ELECT.!K13 -> 4501 | L12: =ELECT.!M13 -> 3452 | M12: =ELECT.!O13 -> 1478 | N12: =ELECT.!Q13 -> 6911 | O12: =ELECT.!S13 -> 7800 | P12: =ELECT.!W13*2 -> 17524 | Q12: =ELECT.!D13 -> 320 | R12: =BTU!C13 -> 5.697 | S12: =BTU!F13 -> 1.015 | T12: =BTU!I13 -> 7 | U12: =BTU!O13 -> 1.613 | V12: =BTU!L13 -> 1.57 | W12: =BTU!R13 -> 1.32 | X12: =ELECT.!B13 -> 138 | Y12: =I12+J12-(K12+L12+M12+N12+O12+P12) -> 46041 | Z12: ='Mall, Citadel, Rotana'!C13+'Mall, Citadel, Rotana'!E13+'Mall, Citadel, Rotana'!G13+'Mall, Citadel, Rotana'!I13 -> 1024 | AA12: ='Mall, Citadel, Rotana'!K13+'Mall, Citadel, Rotana'!M13 -> 1440 | AB12: ='Mall, Citadel, Rotana'!O13 -> 116 | AC12: ='Mall, Citadel, Rotana'!Q13+'Mall, Citadel, Rotana'!S13 -> 10 | AD12: =(E12-H12-194)*0.1318 -> 192.78465 | AE12: =E12-H12-AD12-194 -> 1269.9213
A13: Cairo at Nile Plaza | B13: =B12+1 -> 12 | C13: 4 | D13: 2021 | E13: =Water!C14 -> 480 | F13: =Water!E14 -> 324 | G13: =Water!G14 -> 213.3 | H13: =Water!I14 -> 3.402 | I13: =ELECT.!F14 -> 6965 | J13: =ELECT.!H14 -> 6005 | K13: =ELECT.!K14 -> 6344 | L13: =ELECT.!M14 -> 4827 | M13: =ELECT.!O14 -> 1964 | N13: =ELECT.!Q14 -> 9255 | O13: =ELECT.!S14 -> 10912 | P13: =ELECT.!W14*2 -> 23454 | Q13: =ELECT.!D14 -> 480 | R13: =BTU!C14 -> 3.92 | S13: =BTU!F14 -> 0.907 | T13: =BTU!I14 -> 4 | U13: =BTU!O14 -> 1.302 | V13: =BTU!L14 -> 1.19 | W13: =BTU!R14 -> 0.04 | X13: =ELECT.!B14 -> 123 | Y13: =I13+J13-(K13+L13+M13+N13+O13+P13) -> -43786 | Z13: ='Mall, Citadel, Rotana'!C14+'Mall, Citadel, Rotana'!E14+'Mall, Citadel, Rotana'!G14+'Mall, Citadel, Rotana'!I14 -> 1527 | AA13: ='Mall, Citadel, Rotana'!K14+'Mall, Citadel, Rotana'!M14 -> 800 | AB13: ='Mall, Citadel, Rotana'!O14 -> 140 | AC13: ='Mall, Citadel, Rotana'!Q14+'Mall, Citadel, Rotana'!S14 -> 95 | AD13: =(E13-H13-194)*0.1318 -> 37.246416 | AE13: =E13-H13-AD13-194 -> 245.35158
A14: Cairo at Nile Plaza | B14: =B13+1 -> 13 | C14: 4 | D14: 2021 | E14: =Water!C15 -> 140 | F14: =Water!E15 -> 359.1 | G14: =Water!G15 -> 256.5 | H14: =Water!I15 -> 4.671 | I14: =ELECT.!F15 -> 5806 | J14: =ELECT.!H15 -> 43536 | K14: =ELECT.!K15 -> 5340 | L14: =ELECT.!M15 -> 4176 | M14: =ELECT.!O15 -> 1508 | N14: =ELECT.!Q15 -> 8171 | O14: =ELECT.!S15 -> 8628 | P14: =ELECT.!W15*2 -> 20382 | Q14: =ELECT.!D15 -> 480 | R14: =BTU!C15 -> 5.318 | S14: =BTU!F15 -> 1.707 | T14: =BTU!I15 -> 6 | U14: =BTU!O15 -> 1.628 | V14: =BTU!L15 -> 1.43 | W14: =BTU!R15 -> 0 | X14: =ELECT.!B15 -> 0 | Y14: =I14+J14-(K14+L14+M14+N14+O14+P14) -> 1137 | Z14: ='Mall, Citadel, Rotana'!C15+'Mall, Citadel, Rotana'!E15+'Mall, Citadel, Rotana'!G15+'Mall, Citadel, Rotana'!I15 -> 1232 | AA14: ='Mall, Citadel, Rotana'!K15+'Mall, Citadel, Rotana'!M15 -> -640 | AB14: ='Mall, Citadel, Rotana'!O15 -> 135 | AC14: ='Mall, Citadel, Rotana'!Q15+'Mall, Citadel, Rotana'!S15 -> 89 | AD14: =(E14-H14-194)*0.1318 -> -7.7328378 | AE14: =E14-H14-AD14-194 -> -50.938162
... A29: Cairo at Nile Plaza | B29: =B28+1 -> 28 | C29: 4 | D29: 2021 | E29: =Water!C30 -> 0 | F29: =Water!E30 -> 0 | G29: =Water!G30 -> 0 | H29: =Water!I30 -> 0 | I29: =ELECT.!F30 -> 0 | J29: =ELECT.!H30 -> 0 | K29: =ELECT.!K30 -> 0 | L29: =ELECT.!M30 -> 0 | M29: =ELECT.!O30 -> 0 | N29: =ELECT.!Q30 -> 0 | O29: =ELECT.!S30 -> 0 | P29: =ELECT.!W30*2 -> 0 | Q29: =ELECT.!D30 -> 0 | R29: =BTU!C30 -> 0 | S29: =BTU!F30 -> 0 | T29: =BTU!I30 -> 0 | U29: =BTU!O30 -> 0 | V29: =BTU!L30 -> 0 | W29: =BTU!R30 -> 0 | X29: =ELECT.!B30 -> 0 | Y29: =I29+J29-(K29+L29+M29+N29+O29+P29) -> 0 | Z29: ='Mall, Citadel, Rotana'!C30+'Mall, Citadel, Rotana'!E30+'Mall, Citadel, Rotana'!G30+'Mall, Citadel, Rotana'!I30 -> 0 | AA29: ='Mall, Citadel, Rotana'!K30+'Mall, Citadel, Rotana'!M30 -> 0 | AB29: ='Mall, Citadel, Rotana'!O30 -> 0 | AC29: ='Mall, Citadel, Rotana'!Q30+'Mall, Citadel, Rotana'!S30 -> 0 | AD29: =(E29-H29-194)*0.1318 -> -25.5692 | AE29: =E29-H29-AD29-194 -> -168.4308
A30: Cairo at Nile Plaza | B30: =B29+1 -> 29 | C30: 4 | D30: 2021 | E30: =Water!C31 -> 0 | F30: =Water!E31 -> 0 | G30: =Water!E31 -> 0 | H30: =Water!I31 -> 0 | I30: =Water!G31 -> 0 | J30: =ELECT.!H31 -> 0 | K30: =Water!I31 -> 0 | L30: =Water!J31 -> 0 | M30: =Water!K31 -> 0 | N30: =Water!L31 -> 0 | O30: =Water!M31 -> 0 | P30: =Water!N31 -> 0 | Q30: =Water!O31 -> 0 | R30: =BTU!C31 -> 0 | S30: =BTU!F31 -> 0 | T30: =BTU!I31 -> 0 | U30: =BTU!O31 -> 0 | V30: =BTU!L31 -> 0 | W30: =BTU!R31 -> 0 | X30: =ELECT.!B31 -> 0 | Y30: =I30+J30-(K30+L30+M30+N30+O30+P30) -> 0 | Z30: ='Mall, Citadel, Rotana'!C31+'Mall, Citadel, Rotana'!E31+'Mall, Citadel, Rotana'!G31+'Mall, Citadel, Rotana'!I31 -> 0 | AA30: ='Mall, Citadel, Rotana'!K31+'Mall, Citadel, Rotana'!M31 -> 0 | AB30: ='Mall, Citadel, Rotana'!O31 -> 0 | AC30: ='Mall, Citadel, Rotana'!Q31+'Mall, Citadel, Rotana'!S31 -> 0 | AD30: =(E30-H30-194)*0.1318 -> -25.5692 | AE30: =E30-H30-AD30-194 -> -168.4308
A31: Cairo at Nile Plaza | B31: =B30+1 -> 30 | C31: 4 | D31: 2021 | E31: =Water!C32 -> 0 | F31: =Water!E32 -> 0 | G31: =Water!E32 -> 0 | H31: =Water!I32 -> 0 | I31: =Water!G32 -> 0 | J31: =ELECT.!H32 -> 0 | K31: =Water!I32 -> 0 | L31: =Water!J32 -> 0 | M31: =Water!K32 -> 0 | N31: =Water!L32 -> 0 | O31: =Water!M32 -> 0 | P31: =Water!N32 -> 0 | Q31: =Water!O32 -> 0 | R31: =BTU!C32 -> 0 | S31: =BTU!F32 -> 0 | T31: =BTU!I32 -> 0 | U31: =BTU!O32 -> 0 | V31: =BTU!L32 -> 0 | W31: =BTU!R32 -> 0 | X31: =ELECT.!B32 -> 0 | Y31: =I31+J31-(K31+L31+M31+N31+O31+P31) -> 0 | Z31: ='Mall, Citadel, Rotana'!C32+'Mall, Citadel, Rotana'!E32+'Mall, Citadel, Rotana'!G32+'Mall, Citadel, Rotana'!I32 -> 0 | AA31: ='Mall, Citadel, Rotana'!K32+'Mall, Citadel, Rotana'!M32 -> 0 | AB31: ='Mall, Citadel, Rotana'!O32 -> 0 | AC31: ='Mall, Citadel, Rotana'!Q32+'Mall, Citadel, Rotana'!S32 -> 0 | AD31: =(E31-H31-194)*0.1318 -> -25.5692 | AE31: =E31-H31-AD31-194 -> -168.4308

Sheet Mall, Citadel, Rotana
A1: Day | B1: R1 | C1: Cons | D1: R2 | E1: Cons | F1: R3 | G1: Cons | H1: R4 | I1: Cons | J1: RO1 | K1: Cons | L1: RO2 | M1: Cons | N1: ROE | O1: Cons | P1: CIB. 1 | Q1: Cons | R1: CIB. E | S1: Cons | T1: Co | U1: Cons
A2: Last | B2: 45039 | C2: 0 | D2: 39393 | E2: 0 | F2: 20221 | G2: 0 | H2: 239849 | I2: 0 | J2: 303517 | K2: 0 | L2: 24778 | M2: 0 | N2: 212904 | O2: 0 | P2: 98110 | Q2: 0 | R2: 55047 | S2: 0 | T2: 3580 | U2: 0
A3: 44286 | B3: 45047 | C3: 1280 | D3: 39395 | E3: 320 | F3: 20224 | G3: 60 | H3: 239901 | I3: 52 | J3: 303517 | K3: 0 | L3: 24783 | M3: 800 | N3: 213067 | O3: 163 | P3: 98351 | Q3: 61 | R3: 55047 | S3: 0 | T3: 3583 | U3: 160
A4: 44287 | B4: 45053 | C4: =(B4-B3)*800/5 -> 960 | D4: 39398 | E4: =(D4-D3)*800/5 -> 480 | F4: 20228 | G4: =(F4-F3)*100/5 -> 80 | H4: 239920 | I4: =(H4-H3) -> 19 | J4: =J3 -> 303517 | K4: =(J4-J3)*800/5 -> 0 | L4: 24786 | M4: =(L4-L3)*800/5 -> 480 | N4: 213274 | O4: =N4-N3 -> 207 | P4: 98371 | Q4: =P4-P3 -> 20 | R4: =R3 -> 55047 | S4: =R4-R3 -> 0 | T4: 3585 | U4: =(T4-T3)*800/5 -> 320
A5: 44288 | B5: 45057 | C5: =(B5-B4)*800/5 -> 640 | D5: 39401 | E5: =(D5-D4)*800/5 -> 480 | F5: 20231 | G5: =(F5-F4)*100/5 -> 60 | H5: 239941 | I5: =(H5-H4) -> 21 | J5: =J4 -> 303517 | K5: =(J5-J4)*800/5 -> 0 | L5: 24788 | M5: =(L5-L4)*800/5 -> 320 | N5: 213282 | O5: =N5-N4 -> 8 | P5: 98420 | Q5: =P5-P4 -> 49 | R5: =R4 -> 55047 | S5: =R5-R4 -> 0 | T5: 3586 | U5: =(T5-T4)*800/5 -> 160
A6: 44289 | B6: 45062 | C6: =(B6-B5)*800/5 -> 800 | D6: 39404 | E6: =(D6-D5)*800/5 -> 480 | F6: 20234 | G6: =(F6-F5)*100/5 -> 60 | H6: 239960 | I6: =(H6-H5) -> 19 | J6: =J5 -> 303517 | K6: =(J6-J5)*800/5 -> 0 | L6: 24791 | M6: =(L6-L5)*800/5 -> 480 | N6: 213338 | O6: =N6-N5 -> 56 | P6: 98500 | Q6: =P6-P5 -> 80 | R6: =R5 -> 55047 | S6: =R30-R5 -> 0 | T6: 3587 | U6: =(T6-T5)*800/5 -> 160
A7: 44290 | B7: 45067 | C7: =(B7-B6)*800/5 -> 800 | D7: 39407 | E7: =(D7-D6)*800/5 -> 480 | F7: 20237 | G7: =(F7-F6)*100/5 -> 60 | H7: 239989 | I7: =(H7-H6) -> 29 | J7: =J6 -> 303517 | K7: =(J7-J6)*800/5 -> 0 | L7: 24795 | M7: =(L7-L6)*800/5 -> 640 | N7: 213452 | O7: =N7-N6 -> 114 | P7: 98663 | Q7: =P7-P6 -> 163 | R7: =R6 -> 55047 | S7: =R7-R30 -> 0 | T7: 3588 | U7: =(T7-T6)*800/5 -> 160
A8: 44291 | B8: 45073 | C8: =(B8-B7)*800/5 -> 960 | D8: 39410 | E8: =(D8-D7)*800/5 -> 480 | F8: 20241 | G8: =(F8-F7)*100/5 -> 80 | H8: 240011 | I8: =(H8-H7) -> 22 | J8: 303517 | K8: =(J8-J7)*800/5 -> 0 | L8: 24800 | M8: =(L8-L7)*800/5 -> 800 | N8: 213592 | O8: =N8-N7 -> 140 | P8: 98791 | Q8: =P8-P7 -> 128 | R8: =R7 -> 55047 | S8: =R8-R7 -> 0 | T8: 3590 | U8: =(T8-T7)*800/5 -> 320
A9: 44292 | B9: 45078 | C9: =(B9-B8)*800/5 -> 800 | D9: 39412 | E9: =(D9-D8)*800/5 -> 320 | F9: 20244 | G9: =(F9-F8)*100/5 -> 60 | H9: 240052 | I9: =(H9-H8) -> 41 | J9: 303517 | K9: =(J9-J8)*800/5 -> 0 | L9: 24803 | M9: =(L9-L8)*800/5 -> 480 | N9: 213707 | O9: =N9-N8 -> 115 | P9: 98921 | Q9: =P9-P8 -> 130 | R9: =R8 -> 55047 | S9: =R9-R8 -> 0 | T9: 3591 | U9: =(T9-T8)*800/5 -> 160
A10: 44293 | B10: 45083 | C10: =(B10-B9)*800/5 -> 800 | D10: 39415 | E10: =(D10-D9)*800/5 -> 480 | F10: 20248 | G10: =(F10-F9)*100/5 -> 80 | H10: 240100 | I10: =(H10-H9) -> 48 | J10: =J9 -> 303517 | K10: =(J10-J9)*800/5 -> 0 | L10: 24807 | M10: =(L10-L9)*800/5 -> 640 | N10: 213822 | O10: =N10-N9 -> 115 | P10: 99071 | Q10: =P10-P9 -> 150 | R10: =R9 -> 55047 | S10: =R10-R9 -> 0 | T10: 3592 | U10: =(T10-T9)*800/5 -> 160
A11: 44294 | B11: 45088 | C11: =(B11-B10)*800/5 -> 800 | D11: 39418 | E11: =(D11-D10)*800/5 -> 480 | F11: 20252 | G11: =(F11-F10)*100/5 -> 80 | H11: 240159 | I11: =(H11-H10) -> 59 | J11: =J10 -> 303517 | K11: =(J11-J10)*800/5 -> 0 | L11: 24811 | M11: =(L11-L10)*800/5 -> 640 | N11: 213949 | O11: =N11-N10 -> 127 | P11: 99251 | Q11: =P11-P10 -> 180 | R11: =R10 -> 55047 | S11: =R11-R10 -> 0 | T11: 3594 | U11: =(T11-T10)*800/5 -> 320
A12: 44295 | B12: 45093 | C12: =(B12-B11)*800/5 -> 800 | D12: 39421 | E12: =(D12-D11)*800/5 -> 480 | F12: 20255 | G12: =(F12-F11)*100/5 -> 60 | H12: 240211 | I12: =(H12-H11) -> 52 | J12: =J11 -> 303517 | K12: =(J12-J11)*800/5 -> 0 | L12: 24814 | M12: =(L12-L11)*800/5 -> 480 | N12: 214031 | O12: =N12-N11 -> 82 | P12: 99420 | Q12: =P12-P11 -> 169 | R12: =R11 -> 55047 | S12: =R12-R11 -> 0 | T12: 3595 | U12: =(T12-T11)*800/5 -> 160
A13: 44296 | B13: 45097 | C13: =(B13-B12)*800/5 -> 640 | D13: 39423 | E13: =(D13-D12)*800/5 -> 320 | F13: 20257 | G13: =(F13-F12)*100/5 -> 40 | H13: 240235 | I13: =(H13-H12) -> 24 | J13: 303517 | K13: =(J13-J12)*800/5 -> 0 | L13: 24823 | M13: =(L13-L12)*800/5 -> 1440 | N13: 214147 | O13: =N13-N12 -> 116 | P13: 99430 | Q13: =P13-P12 -> 10 | R13: 55047 | S13: =R13-R12 -> 0 | T13: 3596 | U13: =(T13-T12)*800/5 -> 160
A14: 44297 | B14: 45102 | C14: =(B14-B13)*800/5 -> 800 | D14: 39426 | E14: =(D14-D13)*800/5 -> 480 | F14: 20268 | G14: =(F14-F13)*100/5 -> 220 | H14: 240262 | I14: =(H14-H13) -> 27 | J14: 303517 | K14: =(J14-J13)*800/5 -> 0 | L14: 24828 | M14: =(L14-L13)*800/5 -> 800 | N14: 214287 | O14: =N14-N13 -> 140 | P14: 99525 | Q14: =P14-P13 -> 95 | R14: 55047 | S14: =R14-R13 -> 0 | T14: 3598 | U14: =(T14-T13)*800/5 -> 320
A15: 44298 | B15: 45107 | C15: =(B15-B14)*800/5 -> 800 | D15: 39429 | E15: =(D15-D14)*800/5 -> 480 | F15: 20264 | G15: =(F15-F14)*100/5 -> -80 | H15: 240294 | I15: =(H15-H14) -> 32 | J15: 303517 | K15: =(J15-J14)*800/5 -> 0 | L15: 24824 | M15: =(L15-L14)*800/5 -> -640 | N15: 214422 | O15: =N15-N14 -> 135 | P15: 99614 | Q15: =P15-P14 -> 89 | R15: 55047 | S15: =R15-R14 -> 0 | T15: 3599 | U15: =(T15-T14)*800/5 -> 160
A16: 44299 | B16: 45112 | C16: =(B16-B15)*800/5 -> 800 | D16: 39431 | E16: =(D16-D15)*800/5 -> 320 | F16: 20267 | G16: =(F16-F15)*100/5 -> 60 | H16: 240308 | I16: =(H16-H15) -> 14 | J16: 303517 | K16: =(J16-J15)*800/5 -> 0 | L16: 24827 | M16: =(L16-L15)*800/5 -> 480 | N16: 214537 | O16: =N16-N15 -> 115 | P16: =P15 -> 99614 | Q16: =P16-P15 -> 0 | R16: =R15 -> 55047 | S16: =R16-R15 -> 0 | T16: 3601 | U16: =(T16-T15)*800/5 -> 320
A17: 44300 | B17: 45116 | C17: =(B17-B16)*800/5 -> 640 | D17: 39434 | E17: =(D17-D16)*800/5 -> 480 | F17: 20270 | G17: =(F17-F16)*100/5 -> 60 | H17: 240328 | I17: =(H17-H16) -> 20 | J17: =J16 -> 303517 | K17: =(J17-J16)*800/5 -> 0 | L17: 24831 | M17: =(L17-L16)*800/5 -> 640 | N17: 214656 | O17: =N17-N16 -> 119 | P17: =P16 -> 99614 | Q17: =P17-P16 -> 0 | R17: =R16 -> 55047 | S17: =S16 -> 0 | T17: 3602 | U17: =(T17-T16)*800/5 -> 160
A18: 44301 | B18: 45120 | C18: =(B18-B17)*800/5 -> 640 | D18: 39436 | E18: =(D18-D17)*800/5 -> 320 | F18: 20273 | G18: =(F18-F17)*100/5 -> 60 | H18: 240340 | I18: =(H18-H17) -> 12 | J18: =J17 -> 303517 | K18: =(J18-J17)*800/5 -> 0 | L18: 24834 | M18: =(L18-L17)*800/5 -> 480 | N18: 214752 | O18: =N18-N17 -> 96 | P18: 99983 | Q18: =P18-P17 -> 369 | R18: 55047 | S18: =R18-R17 -> 0 | T18: 3603 | U18: =(T18-T17)*800/5 -> 160
A19: 44302 | B19: 45124 | C19: =(B19-B18)*800/5 -> 640 | D19: 39438 | E19: =(D19-D18)*800/5 -> 320 | F19: 20276 | G19: =(F19-F18)*100/5 -> 60 | H19: 240352 | I19: =(H19-H18) -> 12 | J19: =J18 -> 303517 | K19: =(J19-J18)*800/5 -> 0 | L19: 24837 | M19: =(L19-L18)*800/5 -> 480 | N19: 214831 | O19: =N19-N18 -> 79 | P19: 100084 | Q19: =P19-P18 -> 101 | R19: =R18 -> 55047 | S19: =R19-R18 -> 0 | T19: 3604 | U19: =(T19-T18)*800/5 -> 160
A20: 44303 | B20: 45128 | C20: =(B20-B19)*800/5 -> 640 | D20: 39441 | E20: =(D20-D19)*800/5 -> 480 | F20: 20279 | G20: =(F20-F19)*100/5 -> 60 | H20: 240379 | I20: =(H20-H19) -> 27 | J20: =J19 -> 303517 | K20: 0 | L20: 24840 | M20: =(L20-L19)*800/5 -> 480 | N20: 214936 | O20: =N20-N19 -> 105 | P20: 100180 | Q20: =P20-P19 -> 96 | R20: =R19 -> 55047 | S20: =R20-R19 -> 0 | T20: 3605 | U20: =(T20-T19)*800/5 -> 160
A21: 44304 | B21: 45133 | C21: =(B21-B20)*800/5 -> 800 | D21: 39443 | E21: =(D21-D20)*800/5 -> 320 | F21: 20282 | G21: =(F21-F20)*100/5 -> 60 | H21: 240405 | I21: =(H21-H20) -> 26 | J21: =J20 -> 303517 | K21: =(J21-J20)*800/5 -> 0 | L21: 24843 | M21: =(L21-L20)*800/5 -> 480 | N21: 215068 | O21: =N21-N20 -> 132 | P21: 100338 | Q21: =P21-P20 -> 158 | R21: =R20 -> 55047 | S21: =R21-R20 -> 0 | T21: 3606 | U21: =(T21-T20)*800/5 -> 160
A22: 44305 | B22: 45138 | C22: =(B22-B21)*800/5 -> 800 | D22: 39446 | E22: =(D22-D21)*800/5 -> 480 | F22: 20285 | G22: =(F22-F21)*100/5 -> 60 | H22: 240447 | I22: =(H22-H21) -> 42 | J22: =J21 -> 303517 | K22: =(J22-J21)*800/5 -> 0 | L22: 24847 | M22: =(L22-L21)*800/5 -> 640 | N22: 215185 | O22: =N22-N21 -> 117 | P22: 100485 | Q22: =P22-P21 -> 147 | R22: =R21 -> 55047 | S22: =R22-R21 -> 0 | T22: 3608 | U22: =(T22-T21)*800/5 -> 320
A23: 44306 | B23: 45142 | C23: =(B23-B22)*800/5 -> 640 | D23: 39449 | E23: =(D23-D22)*800/5 -> 480 | F23: 20288 | G23: =(F23-F22)*100/5 -> 60 | H23: 240487 | I23: =(H23-H22) -> 40 | J23: 303517 | K23: =(J23-J22)*800/5 -> 0 | L23: 24852 | M23: =(L23-L22)*800/5 -> 800 | N23: 215302 | O23: =N23-N22 -> 117 | P23: 100632 | Q23: =P23-P22 -> 147 | R23: 55047 | S23: =R23-R22 -> 0 | T23: 3609 | U23: =(T23-T22)*800/5 -> 160
A24: 44307 | B24: 45147 | C24: =(B24-B23)*800/5 -> 800 | D24: 39451 | E24: =(D24-D23)*800/5 -> 320 | F24: 20290 | G24: =(F24-F23)*100/5 -> 40 | H24: 240497 | I24: =(H24-H23) -> 10 | J24: 303517 | K24: =(J24-J23)*800/5 -> 0 | L24: 24854 | M24: =(L24-L23)*800/5 -> 320 | N24: 215411 | O24: =N24-N23 -> 109 | P24: 100781 | Q24: =P24-P23 -> 149 | R24: 55047 | S24: =R24-R23 -> 0 | T24: 3610 | U24: =(T24-T23)*800/5 -> 160
A25: 44308 | B25: 45151 | C25: =(B25-B24)*800/5 -> 640 | D25: 39453 | E25: =(D25-D24)*800/5 -> 320 | F25: 20293 | G25: =(F25-F24)*100/5 -> 60 | H25: 240534 | I25: =(H25-H24) -> 37 | J25: 303517 | K25: =(J25-J24)*800/5 -> 0 | L25: 24857 | M25: =(L25-L24)*800/5 -> 480 | N25: 215422 | O25: =N25-N24 -> 11 | P25: 100868 | Q25: =P25-P24 -> 87 | R25: =R24 -> 55047 | S25: =R25-R24 -> 0 | T25: 3611 | U25: =(T25-T24)*800/5 -> 160
A26: 44309 | B26: 45155 | C26: =(B26-B25)*800/5 -> 640 | D26: 39455 | E26: =(D26-D25)*800/5 -> 320 | F26: 20296 | G26: =(F26-F25)*100/5 -> 60 | H26: 240560 | I26: =(H26-H25) -> 26 | J26: 303517 | K26: =(J26-J25)*800/5 -> 0 | L26: 24860 | M26: =(L26-L25)*800/5 -> 480 | N26: 215425 | O26: =N26-N25 -> 3 | P26: 100952 | Q26: =P26-P25 -> 84 | R26: 55047 | S26: =R26-R25 -> 0 | T26: 3613 | U26: =(T26-T25)*800/5 -> 320
A27: 44310 | B27: 45159 | C27: =(B27-B26)*800/5 -> 640 | D27: 39457 | E27: =(D27-D26)*800/5 -> 320 | F27: 20299 | G27: =(F27-F26)*100/5 -> 60 | H27: 240584 | I27: =(H27-H26) -> 24 | J27: 303517 | K27: =(J27-J26)*800/5 -> 0 | L27: 24863 | M27: =(L27-L26)*800/5 -> 480 | N27: 215434 | O27: =N27-N26 -> 9 | P27: 101029 | Q27: =P27-P26 -> 77 | R27: 55047 | S27: =R27-R26 -> 0 | T27: 3615 | U27: =(T27-T26)*800/5 -> 320
A28: 44311 | B28: =B27 -> 45159 | C28: =(B28-B27)*800/5 -> 0 | D28: =D27 -> 39457 | E28: =(D28-D27)*800/5 -> 0 | F28: =F27 -> 20299 | G28: =(F28-F27)*100/5 -> 0 | H28: =H27 -> 240584 | I28: =(H28-H27) -> 0 | J28: =J27 -> 303517 | K28: =(J28-J27)*800/5 -> 0 | L28: =L27 -> 24863 | M28: =(L28-L27)*800/5 -> 0 | N28: =N27 -> 215434 | O28: =N28-N27 -> 0 | P28: =P27 -> 101029 | Q28: =P28-P27 -> 0 | R28: 55047 | S28: =R28-R27 -> 0 | T28: =T27 -> 3615 | U28: =(T28-T27)*800/5 -> 0
A29: 44312 | B29: =B28 -> 45159 | C29: =(B29-B28)*800/5 -> 0 | D29: =D28 -> 39457 | E29: =(D29-D28)*800/5 -> 0 | F29: =F28 -> 20299 | G29: =(F29-F28)*100/5 -> 0 | H29: =H28 -> 240584 | I29: =(H29-H28) -> 0 | J29: =J28 -> 303517 | K29: =(J29-J28)*800/5 -> 0 | L29: =L28 -> 24863 | M29: =(L29-L28)*800/5 -> 0 | N29: =N28 -> 215434 | O29: =N29-N28 -> 0 | P29: =P28 -> 101029 | Q29: =P29-P28 -> 0 | R29: =R28 -> 55047 | S29: =R29-R28 -> 0 | T29: =T28 -> 3615 | U29: =(T29-T28)*800/5 -> 0
A30: 44313 | B30: =B29 -> 45159 | C30: =(B30-B29)*800/5 -> 0 | D30: =D29 -> 39457 | E30: =(D30-D29)*800/5 -> 0 | F30: =F29 -> 20299 | G30: =(F30-F29)*100/5 -> 0 | H30: =H29 -> 240584 | I30: =(H30-H29) -> 0 | J30: =J29 -> 303517 | K30: =(J30-J29)*800/5 -> 0 | L30: =L29 -> 24863 | M30: =(L30-L29)*800/5 -> 0 | N30: =N29 -> 215434 | O30: =N30-N29 -> 0 | P30: =P29 -> 101029 | Q30: =P30-P29 -> 0 | R30: 55047 | S30: =R30-R29 -> 0 | T30: =T29 -> 3615 | U30: =(T30-T29)*800/5 -> 0
A31: 44314 | B31: =B30 -> 45159 | C31: =(B31-B30)*800/5 -> 0 | D31: =D30 -> 39457 | E31: =(D31-D30)*800/5 -> 0 | F31: =F30 -> 20299 | G31: =(F31-F30)*100/5 -> 0 | H31: =H30 -> 240584 | I31: =(H31-H30) -> 0 | J31: =J30 -> 303517 | K31: =(J31-J30)*800/5 -> 0 | L31: =L30 -> 24863 | M31: =(L31-L30)*800/5 -> 0 | N31: =N30 -> 215434 | O31: =N31-N30 -> 0 | P31: =P30 -> 101029 | Q31: =P31-P30 -> 0 | R31: =R30 -> 55047 | S31: =R31-R30 -> 0 | T31: =T30 -> 3615 | U31: =(T31-T30)*800/5 -> 0
A32: 44315 | B32: =B31 -> 45159 | C32: =(B32-B31)*800/5 -> 0 | D32: =D31 -> 39457 | E32: =(D32-D31)*800/5 -> 0 | F32: =F31 -> 20299 | G32: =(F32-F31)*100/5 -> 0 | H32: =H31 -> 240584 | I32: =(H32-H31) -> 0 | J32: =J31 -> 303517 | K32: =(J32-J31)*800/5 -> 0 | L32: =L31 -> 24863 | M32: =(L32-L31)*800/5 -> 0 | N32: =N31 -> 215434 | O32: =N32-N31 -> 0 | P32: =P31 -> 101029 | Q32: =P32-P31 -> 0 | R32: 55047 | S32: =R32-R31 -> 0 | T32: =T31 -> 3615 | U32: =(T32-T31)*800/5 -> 0
A33: 44316 | B33: =B32 -> 45159 | C33: =(B33-B32)*800/5 -> 0 | D33: =D32 -> 39457 | E33: =(D33-D32)*800/5 -> 0 | F33: =F32 -> 20299 | G33: =(F33-F32)*100/5 -> 0 | H33: =H32 -> 240584 | I33: =(H33-H32) -> 0 | J33: =J32 -> 303517 | K33: =(J33-J32)*800/5 -> 0 | L33: =L32 -> 24863 | M33: =(L33-L32)*800/5 -> 0 | N33: =N32 -> 215434 | O33: =N33-N32 -> 0 | P33: =P32 -> 101029 | Q33: =P33-P32 -> 0 | R33: =R32 -> 55047 | S33: =R33-R32 -> 0 | T33: =T32 -> 3615 | U33: =(T33-T32)*800/5 -> 0
A34: Total | C34: =SUM(C3:C33) -> 19200 | E34: =SUM(E3:E33) -> 10240 | G34: =SUM(G3:G33) -> 1560 | I34: =SUM(I3:I33) -> 735 | K34: =SUM(K3:K33) -> 0 | M34: =SUM(M3:M33) -> 13600 | O34: =SUM(O3:O33) -> 2530 | Q34: =SUM(Q3:Q33) -> 2739 | S34: =SUM(S3:S33) -> 0 | U34: =SUM(U3:U33) -> 5280

Sheet Water
A1: Day | B1: Main Reading | C1: Cons. | D1: Podium | E1: Cons. | F1: Hotel | G1: Cons. | H1: Large | I1: Cons. | J1: Total | K1: cost.LE
A2: Last | B2: 407443 | C2: 0 | D2: 3767800 | E2: 0 | F2: 2454800 | G2: 0 | H2: 726024
A3: 44286 | B3: 407517 | C3: 740 | D3: 3781100 | E3: 359.1 | F3: 2534500 | G3: 191.7 | H3: 726148 | I3: 3.348 | J3: 1294.148 | K3: 7583.7073
A4: 44287 | B4: 407541 | C4: =(IF((B4-B3)<0,"0",(B4-B3)))*10 -> 240 | D4: 3793400 | E4: =(IF((D4-D3)<0,"0",(D4-D3)))*0.027 -> 332.1 | F4: 2547600 | G4: =(IF((F4-F3)<0,"0",(F4-F3)))*0.027 -> 353.7 | H4: 726286 | I4: =(IF((H4-H3)<0,"0",(H4-H3)))*0.027 -> 3.726 | J4: =C4+E4+G4+I4 -> 929.526 | K4: =J4*5.86 -> 5447.0224
A5: 44288 | B5: 407665 | C5: =(IF((B5-B4)<0,"0",(B5-B4)))*10 -> 1240 | D5: 3805600 | E5: =(IF((D5-D4)<0,"0",(D5-D4)))*0.027 -> 329.4 | F5: 2556100 | G5: =(IF((F5-F4)<0,"0",(F5-F4)))*0.027 -> 229.5 | H5: 726473 | I5: =(IF((H5-H4)<0,"0",(H5-H4)))*0.027 -> 5.049 | J5: =C5+E5+G5+I5 -> 1803.949 | K5: =J5*5.86 -> 10571.141
A6: 44289 | B6: 407747 | C6: =(IF((B6-B5)<0,"0",(B6-B5)))*10 -> 820 | D6: 3818400 | E6: =(IF((D6-D5)<0,"0",(D6-D5)))*0.027 -> 345.6 | F6: 2565600 | G6: =(IF((F6-F5)<0,"0",(F6-F5)))*0.027 -> 256.5 | H6: 726660 | I6: =(IF((H6-H5)<0,"0",(H6-H5)))*0.027 -> 5.049 | J6: =C6+E6+G6+I6 -> 1427.149 | K6: =J6*5.86 -> 8363.0931
A7: 44290 | B7: 407822 | C7: =(IF((B7-B6)<0,"0",(B7-B6)))*10 -> 750 | D7: 3830400 | E7: =(IF((D7-D6)<0,"0",(D7-D6)))*0.027 -> 324 | F7: 2575200 | G7: =(IF((F7-F6)<0,"0",(F7-F6)))*0.027 -> 259.2 | H7: 726824 | I7: =(IF((H7-H6)<0,"0",(H7-H6)))*0.027 -> 4.428 | J7: =C7+E7+G7+I7 -> 1337.628 | K7: =J7*5.86 -> 7838.5001
A8: 44291 | B8: 407939 | C8: =(IF((B8-B7)<0,"0",(B8-B7)))*10 -> 1170 | D8: 3843000 | E8: =(IF((D8-D7)<0,"0",(D8-D7)))*0.027 -> 340.2 | F8: 2587000 | G8: =(IF((F8-F7)<0,"0",(F8-F7)))*0.027 -> 318.6 | H8: 726964 | I8: =(IF((H8-H7)<0,"0",(H8-H7)))*0.027 -> 3.78 | J8: =C8+E8+G8+I8 -> 1832.58 | K8: =J8*5.86 -> 10738.919
A9: 44292 | B9: 407995 | C9: =(IF((B9-B8)<0,"0",(B9-B8)))*10 -> 560 | D9: 3855500 | E9: =(IF((D9-D8)<0,"0",(D9-D8)))*0.027 -> 337.5 | F9: 2598000 | G9: =(IF((F9-F8)<0,"0",(F9-F8)))*0.027 -> 297 | H9: 727090 | I9: =(IF((H9-H8)<0,"0",(H9-H8)))*0.027 -> 3.402 | J9: =C9+E9+G9+I9 -> 1197.902 | K9: =J9*5.86 -> 7019.7057
A10: 44293 | B10: 408045 | C10: =(IF((B10-B9)<0,"0",(B10-B9)))*10 -> 500 | D10: 3869400 | E10: =(IF((D10-D9)<0,"0",(D10-D9)))*0.027 -> 375.3 | F10: 2611900 | G10: =(IF((F10-F9)<0,"0",(F10-F9)))*0.027 -> 375.3 | H10: 727240 | I10: =(IF((H10-H9)<0,"0",(H10-H9)))*0.027 -> 4.05 | J10: =C10+E10+G10+I10 -> 1254.65 | K10: =J10*5.86 -> 7352.249
A11: 44294 | B11: 408100 | C11: =(IF((B11-B10)<0,"0",(B11-B10)))*10 -> 550 | D11: 3881300 | E11: =(IF((D11-D10)<0,"0",(D11-D10)))*0.027 -> 321.3 | F11: 2625100 | G11: =(IF((F11-F10)<0,"0",(F11-F10)))*0.027 -> 356.4 | H11: 727410 | I11: =(IF((H11-H10)<0,"0",(H11-H10)))*0.027 -> 4.59 | J11: =C11+E11+G11+I11 -> 1232.29 | K11: =J11*5.86 -> 7221.2194
A12: 44295 | B12: 408266 | C12: =(IF((B12-B11)<0,"0",(B12-B11)))*10 -> 1660 | D12: 3895000 | E12: =(IF((D12-D11)<0,"0",(D12-D11)))*0.027 -> 369.9 | F12: 2632300 | G12: =(IF((F12-F11)<0,"0",(F12-F11)))*0.027 -> 194.4 | H12: 727504 | I12: =(IF((H12-H11)<0,"0",(H12-H11)))*0.027 -> 2.538 | J12: =C12+E12+G12+I12 -> 2226.838 | K12: =J12*5.86 -> 13049.271
A13: 44296 | B13: 408432 | C13: =(IF((B13-B12)<0,"0",(B13-B12)))*10 -> 1660 | D13: 3906800 | E13: =(IF((D13-D12)<0,"0",(D13-D12)))*0.027 -> 318.6 | F13: 2641600 | G13: =(IF((F13-F12)<0,"0",(F13-F12)))*0.027 -> 251.1 | H13: 727626 | I13: =(IF((H13-H12)<0,"0",(H13-H12)))*0.027 -> 3.294 | J13: =C13+E13+G13+I13 -> 2232.994 | K13: =J13*5.86 -> 13085.345
A14: 44297 | B14: 408480 | C14: =(IF((B14-B13)<0,"0",(B14-B13)))*10 -> 480 | D14: 3918800 | E14: =(IF((D14-D13)<0,"0",(D14-D13)))*0.027 -> 324 | F14: 2649500 | G14: =(IF((F14-F13)<0,"0",(F14-F13)))*0.027 -> 213.3 | H14: 727752 | I14: =(IF((H14-H13)<0,"0",(H14-H13)))*0.027 -> 3.402 | J14: =C14+E14+G14+I14 -> 1020.702 | K14: =J14*5.86 -> 5981.3137
A15: 44298 | B15: 408494 | C15: =(IF((B15-B14)<0,"0",(B15-B14)))*10 -> 140 | D15: 3932100 | E15: =(IF((D15-D14)<0,"0",(D15-D14)))*0.027 -> 359.1 | F15: 2659000 | G15: =(IF((F15-F14)<0,"0",(F15-F14)))*0.027 -> 256.5 | H15: 727925 | I15: =(IF((H15-H14)<0,"0",(H15-H14)))*0.027 -> 4.671 | J15: =C15+E15+G15+I15 -> 760.271 | K15: =J15*5.86 -> 4455.1881
... A17: 44300 | B17: 408580 | C17: =(IF((B17-B16)<0,"0",(B17-B16)))*10 -> 700 | D17: 3957400 | E17: =(IF((D17-D16)<0,"0",(D17-D16)))*0.027 -> 383.4 | F17: 2674300 | G17: =(IF((F17-F16)<0,"0",(F17-F16)))*0.027 -> 218.7 | H17: 728198 | I17: =(IF((H17-H16)<0,"0",(H17-H16)))*0.027 -> 4.077 | J17: =C17+E17+G17+I17 -> 1306.177 | K17: =J17*5.86 -> 7654.1972
A18: 44301 | B18: 408655 | C18: =(IF((B18-B17)<0,"0",(B18-B17)))*10 -> 750 | D18: 3972200 | E18: =(IF((D18-D17)<0,"0",(D18-D17)))*0.027 -> 399.6 | F18: 2684000 | G18: =(IF((F18-F17)<0,"0",(F18-F17)))*0.027 -> 261.9 | H18: 728348 | I18: =(IF((H18-H17)<0,"0",(H18-H17)))*0.027 -> 4.05 | J18: =C18+E18+G18+I18 -> 1415.55 | K18: =J18*5.86 -> 8295.123 | Q18: `
A19: 44302 | B19: 408724 | C19: =(IF((B19-B18)<0,"0",(B19-B18)))*10 -> 690 | D19: 3985200 | E19: =(IF((D19-D18)<0,"0",(D19-D18)))*0.027 -> 351 | F19: 2693000 | G19: =(IF((F19-F18)<0,"0",(F19-F18)))*0.027 -> 243 | H19: 728464 | I19: =(IF((H19-H18)<0,"0",(H19-H18)))*0.027 -> 3.132 | J19: =C19+E19+G19+I19 -> 1287.132 | K19: =J19*5.86 -> 7542.5935
A20: 44303 | B20: 408789 | C20: =(IF((B20-B19)<0,"0",(B20-B19)))*10 -> 650 | D20: 3997000 | E20: =(IF((D20-D19)<0,"0",(D20-D19)))*0.027 -> 318.6 | F20: 2702100 | G20: =(IF((F20-F19)<0,"0",(F20-F19)))*0.027 -> 245.7 | H20: 728593 | I20: =(IF((H20-H19)<0,"0",(H20-H19)))*0.027 -> 3.483 | J20: =C20+E20+G20+I20 -> 1217.783 | K20: =J20*5.86 -> 7136.2084
A21: 44304 | B21: 408852 | C21: =(IF((B21-B20)<0,"0",(B21-B20)))*10 -> 630 | D21: 4010500 | E21: =(IF((D21-D20)<0,"0",(D21-D20)))*0.027 -> 364.5 | F21: 2713100 | G21: =(IF((F21-F20)<0,"0",(F21-F20)))*0.027 -> 297 | H21: 728751 | I21: =(IF((H21-H20)<0,"0",(H21-H20)))*0.027 -> 4.266 | J21: =C21+E21+G21+I21 -> 1295.766 | K21: =J21*5.86 -> 7593.1888
A22: 44305 | B22: 408963 | C22: =(IF((B22-B21)<0,"0",(B22-B21)))*10 -> 1110 | D22: 4025200 | E22: =(IF((D22-D21)<0,"0",(D22-D21)))*0.027 -> 396.9 | F22: 2725100 | G22: =(IF((F22-F21)<0,"0",(F22-F21)))*0.027 -> 324 | H22: 728880 | I22: =(IF((H22-H21)<0,"0",(H22-H21)))*0.027 -> 3.483 | J22: =C22+E22+G22+I22 -> 1834.383 | K22: =J22*5.86 -> 10749.484
A23: 44306 | B23: 409046 | C23: =(IF((B23-B22)<0,"0",(B23-B22)))*10 -> 830 | D23: 4037800 | E23: =(IF((D23-D22)<0,"0",(D23-D22)))*0.027 -> 340.2 | F23: 2735700 | G23: =(IF((F23-F22)<0,"0",(F23-F22)))*0.027 -> 286.2 | H23: 729015 | I23: =(IF((H23-H22)<0,"0",(H23-H22)))*0.027 -> 3.645 | J23: =C23+E23+G23+I23 -> 1460.045 | K23: =J23*5.86 -> 8555.8637
A24: 44307 | B24: 409096 | C24: =(IF((B24-B23)<0,"0",(B24-B23)))*10 -> 500 | D24: 4052000 | E24: =(IF((D24-D23)<0,"0",(D24-D23)))*0.027 -> 383.4 | F24: 2747200 | G24: =(IF((F24-F23)<0,"0",(F24-F23)))*0.027 -> 310.5 | H24: 729154 | I24: =(IF((H24-H23)<0,"0",(H24-H23)))*0.027 -> 3.753 | J24: =C24+E24+G24+I24 -> 1197.653 | K24: =J24*5.86 -> 7018.2466
A25: 44308 | B25: 409188 | C25: =(IF((B25-B24)<0,"0",(B25-B24)))*10 -> 920 | D25: 4065900 | E25: =(IF((D25-D24)<0,"0",(D25-D24)))*0.027 -> 375.3 | F25: 2757300 | G25: =F25-F24 -> 10100 | H25: 729292 | I25: =(IF((H25-H24)<0,"0",(H25-H24)))*0.027 -> 3.726 | J25: =C25+E25+G25+I25 -> 11399.026 | K25: =J25*5.86 -> 66798.292
A26: 44309 | B26: 409257 | C26: =(IF((B26-B25)<0,"0",(B26-B25)))*10 -> 690 | D26: 4080100 | E26: =(IF((D26-D25)<0,"0",(D26-D25)))*0.027 -> 383.4 | F26: 2766300 | G26: =(IF((F26-F25)<0,"0",(F26-F25)))*0.027 -> 243 | H26: 729419 | I26: =(IF((H26-H25)<0,"0",(H26-H25)))*0.027 -> 3.429 | J26: =C26+E26+G26+I26 -> 1319.829 | K26: =J26*5.86 -> 7734.1979
A27: 44310 | B27: 409257 | C27: =(IF((B27-B26)<0,"0",(B27-B26)))*10 -> 0 | D27: 4080100 | E27: =(IF((D27-D26)<0,"0",(D27-D26)))*0.027 -> 0 | F27: 2766300 | G27: =(IF((F27-F26)<0,"0",(F27-F26)))*0.027 -> 0 | H27: =H26 -> 729419 | I27: =(IF((H27-H26)<0,"0",(H27-H26)))*0.027 -> 0 | J27: =C27+E27+G27+I27 -> 0 | K27: =J27*5.86 -> 0
A28: 44311 | B28: =B27 -> 409257 | C28: =(IF((B28-B27)<0,"0",(B28-B27)))*10 -> 0 | D28: =D27 -> 4080100 | E28: =(IF((D28-D27)<0,"0",(D28-D27)))*0.027 -> 0 | F28: =F27 -> 2766300 | G28: =(IF((F28-F27)<0,"0",(F28-F27)))*0.027 -> 0 | H28: =H27 -> 729419 | I28: =(IF((H28-H27)<0,"0",(H28-H27)))*0.027 -> 0 | J28: =C28+E28+G28+I28 -> 0 | K28: =J28*5.86 -> 0
A29: 44312 | B29: =B28 -> 409257 | C29: =(IF((B29-B28)<0,"0",(B29-B28)))*10 -> 0 | D29: =D28 -> 4080100 | E29: =(IF((D29-D28)<0,"0",(D29-D28)))*0.027 -> 0 | F29: =F28 -> 2766300 | G29: =(IF((F29-F28)<0,"0",(F29-F28)))*0.027 -> 0 | H29: =H28 -> 729419 | I29: =(IF((H29-H28)<0,"0",(H29-H28)))*0.027 -> 0 | J29: =C29+E29+G29+I29 -> 0 | K29: =J29*5.86 -> 0
A30: 44313 | B30: =B29 -> 409257 | C30: =(IF((B30-B29)<0,"0",(B30-B29)))*10 -> 0 | D30: =D29 -> 4080100 | E30: =(IF((D30-D29)<0,"0",(D30-D29)))*0.027 -> 0 | F30: =F29 -> 2766300 | G30: =(IF((F30-F29)<0,"0",(F30-F29)))*0.027 -> 0 | H30: =H29 -> 729419 | I30: =(IF((H30-H29)<0,"0",(H30-H29)))*0.027 -> 0 | J30: =C30+E30+G30+I30 -> 0 | K30: =J30*5.86 -> 0
A31: 44314 | B31: =B30 -> 409257 | C31: =(IF((B31-B30)<0,"0",(B31-B30)))*10 -> 0 | D31: =D30 -> 4080100 | E31: =(IF((D31-D30)<0,"0",(D31-D30)))*0.027 -> 0 | F31: =F30 -> 2766300 | G31: =(IF((F31-F30)<0,"0",(F31-F30)))*0.027 -> 0 | H31: =H30 -> 729419 | I31: =(IF((H31-H30)<0,"0",(H31-H30)))*0.027 -> 0 | J31: =C31+E31+G31+I31 -> 0 | K31: =J31*5.86 -> 0
A32: 44315 | B32: =B31 -> 409257 | C32: =(IF((B32-B31)<0,"0",(B32-B31)))*10 -> 0 | D32: =D31 -> 4080100 | E32: =(IF((D32-D31)<0,"0",(D32-D31)))*0.027 -> 0 | F32: =F31 -> 2766300 | G32: =(IF((F32-F31)<0,"0",(F32-F31)))*0.027 -> 0 | H32: =H31 -> 729419 | I32: =(IF((H32-H31)<0,"0",(H32-H31)))*0.027 -> 0 | J32: =C32+E32+G32+I32 -> 0 | K32: =J32*5.86 -> 0
A33: 44316 | B33: =B32 -> 409257 | C33: =(IF((B33-B32)<0,"0",(B33-B32)))*10 -> 0 | D33: =D32 -> 4080100 | E33: =(IF((D33-D32)<0,"0",(D33-D32)))*0.027 -> 0 | F33: =F32 -> 2766300 | G33: =(IF((F33-F32)<0,"0",(F33-F32)))*0.027 -> 0 | H33: =H32 -> 729419 | I33: =(IF((H33-H32)<0,"0",(H33-H32)))*0.027 -> 0 | J33: =C33+E33+G33+I33 -> 0 | K33: =J33*5.86 -> 0
A34: Total | C34: =SUM(C3:C33) -> 18140 | E34: =SUM(E3:E33) -> 8432.1 | G34: =SUM(G3:G33) -> 16277.6 | I34: =SUM(I3:I33) -> 91.665 | J34: =SUM(J3:J33) -> 42941.365 | K34: =SUM(K3:K33) -> 251636.4

Sheet ELECT.
A1: Day | B1: Rooms Sold | C1: New Chillers | D1: Cons | E1: F-1 | F1: Cons. | G1: F-2 | H1: Cons. | I1: Total | J1: T-1 | K1: Cons. | L1: T-2 | M1: Cons. | N1: T-3 | O1: Cons. | P1: T-4 | Q1: Cons. | R1: T-5 | S1: Cons. | T1: T-6 | U1: Cons. | V1: T-7 | W1: Cons. | X1: Total | Y1: Diff | Z1: Daily Money Value | AA1: MTD Total Money
A2: Last | C2: 18067 | E2: 25433539 | G2: 79837635 | I2: =F2+H2 -> 0 | J2: 7752235 | L2: 7774835 | N2: 5008835 | P2: 2893394 | R2: 16985908 | T2: 0 | V2: 4578564 | Y2: =I2-X2 -> 0 | Z2: =(0.93352*(W2+S2)+0.5568*(Q2+O2))*0.26 -> 0
A3: 44286 | B3: 160 | C3: 18069 | D3: 320 | E3: 25442432 | F3: 8893 | G3: 79883133 | H3: 45508 | I3: 54401 | J3: 7757089 | K3: 4854 | L3: 7781096 | M3: 6261 | N3: 5010068 | O3: 2466 | P3: 2901868 | Q3: 8474 | R3: 16995683 | S3: 9775 | T3: 0 | V3: 4589219 | W3: 10650 | X3: 42480 | Y3: 11921 | Z3: 6541.2199 | AA3: 24533.201
A4: 44287 | B4: 182 | C4: 18073 | D4: =IF((C4-C3)<0,"0",(C4-C3))*160 -> 640 | E4: 25448239 | F4: =IF((E4-E3)<0,"0",(E4-E3)) -> 5807 | G4: 79913721 | H4: =IF((G4-G3)<0,"0",(G4-G3)) -> 30588 | I4: =F4+H4 -> 36395 | J4: 7760481 | K4: =IF((J4-J3)<0,"0",(J4-J3)) -> 3392 | L4: 7784916 | M4: =IF((L4-L3)<0,"0",(L4-L3)) -> 3820 | N4: 5011001 | O4: =(IF((N4-N3)<P96,"0",(N4-N3)))*2 -> 1866 | P4: 2907646 | Q4: =IF((P4-P3)<0,"0",(P4-P3)) -> 5778 | R4: 17002170 | S4: =IF((R4-R3)<0,"0",(R4-R3)) -> 6487 | T4: 0 | V4: 4596342 | W4: =IF((V4-V3)<0,"0",(V4-V3)) -> 7123 | X4: =K4+M4+O4+Q4+S4+U4+W4 -> 28466 | Y4: =I4-X4 -> 7929 | Z4: =(0.93352*(W4+S4)+0.5568*(Q4+O4))*0.26 -> 4409.9605 | AA4: =SUM(Z2:Z4) -> 10951.18
A5: 44288 | B5: 183 | C5: 18074 | D5: =IF((C5-C4)<0,"0",(C5-C4))*160 -> 160 | E5: 25456697 | F5: =IF((E5-E4)<0,"0",(E5-E4)) -> 8458 | G5: 79961546 | H5: =IF((G5-G4)<0,"0",(G5-G4)) -> 47825 | I5: =F5+H5 -> 56283 | J5: 7765202 | K5: =IF((J5-J4)<0,"0",(J5-J4)) -> 4721 | L5: 7790498 | M5: =IF((L5-L4)<0,"0",(L5-L4)) -> 5582 | N5: 5012346 | O5: =(IF((N5-N4)<0,"0",(N5-N4)))*2 -> 2690 | P5: 2916393 | Q5: =IF((P5-P4)<0,"0",(P5-P4)) -> 8747 | R5: 17012586 | S5: =IF((R5-R4)<0,"0",(R5-R4)) -> 10416 | T5: 0 | V5: 4607810 | W5: =IF((V5-V4)<0,"0",(V5-V4)) -> 11468 | X5: =K5+M5+O5+Q5+S5+U5+W5 -> 43624 | Y5: =I5-X5 -> 12659 | Z5: =(0.93352*(W5+S5)+0.5568*(Q5+O5))*0.26 -> 6967.2911 | AA5: =SUM(Z3:Z5) -> 17918.471
A6: 44289 | B6: 168 | C6: 18077 | D6: =IF((C6-C5)<0,"0",(C6-C5))*160 -> 480 | E6: 25463637 | F6: =IF((E6-E5)<0,"0",(E6-E5)) -> 6940 | G6: 80000515 | H6: =IF((G6-G5)<0,"0",(G6-G5)) -> 38969 | I6: 7769203 | J6: 7769203 | K6: =IF((J6-J5)<0,"0",(J6-J5)) -> 4001 | L6: 7795009 | M6: =IF((L6-L5)<0,"0",(L6-L5)) -> 4511 | N6: 5013494 | O6: =(IF((N6-N5)<0,"0",(N6-N5)))*2 -> 2296 | P6: 2923652 | Q6: =IF((P6-P5)<0,"0",(P6-P5)) -> 7259 | R6: 17021144 | S6: =IF((R6-R5)<0,"0",(R6-R5)) -> 8558 | T6: 0 | V6: 4617027 | W6: =IF((V6-V5)<0,"0",(V6-V5)) -> 9217 | X6: =K6+M6+O6+Q6+S6+U6+W6 -> 35842 | Y6: =I6-X6 -> 7733361 | Z6: =(0.93352*(W6+S6)+0.5568*(Q6+O6))*0.26 -> 5697.5209 | AA6: =SUM(Z4:Z6) -> 17074.772
A7: 44290 | B7: 138 | C7: 18079 | D7: =IF((C7-C6)<0,"0",(C7-C6))*160 -> 320 | E7: 25472350 | F7: =IF((E7-E6)<0,"0",(E7-E6)) -> 8713 | G7: 80052410 | H7: =IF((G7-G6)<0,"0",(G7-G6)) -> 51895 | I7: =F7+H7 -> 60608 | J7: 7774970 | K7: =IF((J7-J6)<0,"0",(J7-J6)) -> 5767 | L7: 7800766 | M7: =IF((L7-L6)<0,"0",(L7-L6)) -> 5757 | N7: 5014877 | O7: =(IF((N7-N6)<0,"0",(N7-N6)))*2 -> 2766 | P7: 2934137 | Q7: =IF((P7-P6)<0,"0",(P7-P6)) -> 10485 | R7: 17032013 | S7: =IF((R7-R6)<0,"0",(R7-R6)) -> 10869 | T7: 0 | V7: 4628796 | W7: =IF((V7-V6)<0,"0",(V7-V6)) -> 11769 | X7: =K7+M7+O7+Q7+S7+U7+W7 -> 47413 | Y7: =I7-X7 -> 13195 | Z7: =(0.93352*(W7+S7)+0.5568*(Q7+O7))*0.26 -> 7412.9075 | AA7: =SUM(Z4:Z7) -> 24487.68
A8: 44291 | B8: 146 | C8: 18081 | D8: =IF((C8-C7)<0,"0",(C8-C7))*160 -> 320 | E8: 25479219 | F8: =IF((E8-E7)<0,"0",(E8-E7)) -> 6869 | G8: 80087816 | H8: =IF((G8-G7)<0,"0",(G8-G7)) -> 35406 | I8: =F8+H8 -> 42275 | J8: 7779348 | K8: =IF((J8-J7)<0,"0",(J8-J7)) -> 4378 | L8: 7805218 | M8: =IF((L8-L7)<0,"0",(L8-L7)) -> 4452 | N8: 5016028 | O8: =(IF((N8-N7)<0,"0",(N8-N7)))*2 -> 2302 | P8: 2941803 | Q8: =IF((P8-P7)<0,"0",(P8-P7)) -> 7666 | R8: 17038805 | S8: =IF((R8-R7)<0,"0",(R8-R7)) -> 6792 | T8: 0 | V8: 4636760 | W8: =IF((V8-V7)<0,"0",(V8-V7)) -> 7964 | X8: =K8+M8+O8+Q8+S8+U8+W8 -> 33554 | Y8: =I8-X8 -> 8721 | Z8: =(0.93352*(W8+S8)+0.5568*(Q8+O8))*0.26 -> 5024.5529 | AA8: =SUM(Z5:Z8) -> 25102.272
A9: 44292 | B9: 154 | C9: 18084 | D9: =IF((C9-C8)<0,"0",(C9-C8))*160 -> 480 | E9: 25488970 | F9: =IF((E9-E8)<0,"0",(E9-E8)) -> 9751 | G9: 80138355 | H9: =IF((G9-G8)<0,"0",(G9-G8)) -> 50539 | I9: =F9+H9 -> 60290 | J9: 7785610 | K9: =IF((J9-J8)<0,"0",(J9-J8)) -> 6262 | L9: 7811480 | M9: =IF((L9-L8)<0,"0",(L9-L8)) -> 6262 | N9: 5018063 | O9: =(IF((N9-N8)<0,"0",(N9-N8)))*2 -> 4070 | P9: 2952834 | Q9: =IF((P9-P8)<0,"0",(P9-P8)) -> 11031 | R9: 17048203 | S9: =IF((R9-R8)<0,"0",(R9-R8)) -> 9398 | T9: 0 | V9: 4648160 | W9: =IF((V9-V8)<0,"0",(V9-V8)) -> 11400 | X9: =K9+M9+O9+Q9+S9+U9+W9 -> 48423 | Y9: =I9-X9 -> 11867 | Z9: =(0.93352*(W9+S9)+0.5568*(Q9+O9))*0.26 -> 7234.1323 | AA9: =SUM(Z6:Z9) -> 25369.114
A10: 44293 | B10: 148 | C10: 18087 | D10: =IF((C10-C9)<0,"0",(C10-C9))*160 -> 480 | E10: 25497734 | F10: =IF((E10-E9)<0,"0",(E10-E9)) -> 8764 | G10: 80184655 | H10: =IF((G10-G9)<0,"0",(G10-G9)) -> 46300 | I10: =F10+H10 -> 55064 | J10: 7791612 | K10: =IF((J10-J9)<0,"0",(J10-J9)) -> 6002 | L10: 7816413 | M10: =IF((L10-L9)<0,"0",(L10-L9)) -> 4933 | N10: 5019536 | O10: =(IF((N10-N9)<0,"0",(N10-N9)))*2 -> 2946 | P10: 2962621 | Q10: =IF((P10-P9)<0,"0",(P10-P9)) -> 9787 | R10: 17057209 | S10: =IF((R10-R9)<0,"0",(R10-R9)) -> 9006 | T10: 0 | V10: 4658423 | W10: =IF((V10-V9)<0,"0",(V10-V9)) -> 10263 | X10: =K10+M10+O10+Q10+S10+U10+W10 -> 42937 | Y10: =I10-X10 -> 12127 | Z10: =(0.93352*(W10+S10)+0.5568*(Q10+O10))*0.26 -> 6520.2101 | AA10: =SUM(Z7:Z10) -> 26191.803
A11: 44294 | B11: 144 | C11: 18091 | D11: =IF((C11-C10)<0,"0",(C11-C10))*160 -> 640 | E11: 25504955 | F11: =IF((E11-E10)<0,"0",(E11-E10)) -> 7221 | G11: 80229014 | H11: =IF((G11-G10)<0,"0",(G11-G10)) -> 44359 | I11: =F11+H11 -> 51580 | J11: 7797040 | K11: =IF((J11-J10)<0,"0",(J11-J10)) -> 5428 | L11: 7820866 | M11: =IF((L11-L10)<0,"0",(L11-L10)) -> 4453 | N11: 5020850 | O11: =(IF((N11-N10)<0,"0",(N11-N10)))*2 -> 2628 | P11: 2971757 | Q11: =IF((P11-P10)<0,"0",(P11-P10)) -> 9136 | R11: 17065866 | S11: =IF((R11-R10)<0,"0",(R11-R10)) -> 8657 | T11: 0 | V11: 4668576 | W11: =IF((V11-V10)<0,"0",(V11-V10)) -> 10153 | X11: =K11+M11+O11+Q11+S11+U11+W11 -> 40455 | Y11: =I11-X11 -> 11125 | Z11: =(0.93352*(W11+S11)+0.5568*(Q11+O11))*0.26 -> 6268.5237 | AA11: =SUM(Z8:Z11) -> 25047.419
A12: 44295 | B12: 141 | C12: 18093 | D12: =IF((C12-C11)<0,"0",(C12-C11))*160 -> 320 | E12: 25515170 | F12: =IF((E12-E11)<0,"0",(E12-E11)) -> 10215 | G12: 80289649 | H12: =IF((G12-G11)<0,"0",(G12-G11)) -> 60635 | I12: =F12+H12 -> 70850 | J12: 7803881 | K12: =IF((J12-J11)<0,"0",(J12-J11)) -> 6841 | L12: 7827669 | M12: =IF((L12-L11)<0,"0",(L12-L11)) -> 6803 | N12: 5022458 | O12: =(IF((N12-N11)<0,"0",(N12-N11)))*2 -> 3216 | P12: 2983650 | Q12: =IF((P12-P11)<0,"0",(P12-P11)) -> 11893 | R12: 17078223 | S12: =IF((R12-R11)<0,"0",(R12-R11)) -> 12357 | T12: 0 | V12: 4682681 | W12: =IF((V12-V11)<0,"0",(V12-V11)) -> 14105 | X12: =K12+M12+O12+Q12+S12+U12+W12 -> 55215 | Y12: =I12-X12 -> 15635 | Z12: =(0.93352*(W12+S12)+0.5568*(Q12+O12))*0.26 -> 8610.0293 | AA12: =SUM(Z9:Z12) -> 28632.895
A13: 44296 | B13: 138 | C13: 18095 | D13: =IF((C13-C12)<0,"0",(C13-C12))*160 -> 320 | E13: 25520211 | F13: =IF((E13-E12)<0,"0",(E13-E12)) -> 5041 | G13: 80372315 | H13: =IF((G13-G12)<0,"0",(G13-G12)) -> 82666 | I13: =F13+H13 -> 87707 | J13: 7808382 | K13: =IF((J13-J12)<0,"0",(J13-J12)) -> 4501 | L13: 7831121 | M13: =IF((L13-L12)<0,"0",(L13-L12)) -> 3452 | N13: 5023197 | O13: =(IF((N13-N12)<0,"0",(N13-N12)))*2 -> 1478 | P13: 2990561 | Q13: =IF((P13-P12)<0,"0",(P13-P12)) -> 6911 | R13: 17086023 | S13: =IF((R13-R12)<0,"0",(R13-R12)) -> 7800 | T13: 0 | V13: 4691443 | W13: =IF((V13-V12)<0,"0",(V13-V12)) -> 8762 | X13: =K13+M13+O13+Q13+S13+U13+W13 -> 32904 | Y13: =I13-X13 -> 54803 | Z13: =(0.93352*(W13+S13)+0.5568*(Q13+O13))*0.26 -> 5234.3079 | AA13: =SUM(Z10:Z13) -> 26633.071
A14: 44297 | B14: 123 | C14: 18098 | D14: =IF((C14-C13)<0,"0",(C14-C13))*160 -> 480 | E14: 25527176 | F14: =IF((E14-E13)<0,"0",(E14-E13)) -> 6965 | G14: 80378320 | H14: =IF((G14-G13)<0,"0",(G14-G13)) -> 6005 | I14: =F14+H14 -> 12970 | J14: 7814726 | K14: =IF((J14-J13)<0,"0",(J14-J13)) -> 6344 | L14: 7835948 | M14: =IF((L14-L13)<0,"0",(L14-L13)) -> 4827 | N14: 5024179 | O14: =(IF((N14-N13)<0,"0",(N14-N13)))*2 -> 1964 | P14: 2999816 | Q14: =IF((P14-P13)<0,"0",(P14-P13)) -> 9255 | R14: 17096935 | S14: =IF((R14-R13)<0,"0",(R14-R13)) -> 10912 | T14: 0 | V14: 4703170 | W14: =IF((V14-V13)<0,"0",(V14-V13)) -> 11727 | X14: =K14+M14+O14+Q14+S14+U14+W14 -> 45029 | Y14: =I14-X14 -> -32059 | Z14: =(0.93352*(W14+S14)+0.5568*(Q14+O14))*0.26 -> 7118.9816 | AA14: =SUM(Z11:Z14) -> 27231.842
A15: 44298 | C15: 18101 | D15: =IF((C15-C14)<0,"0",(C15-C14))*160 -> 480 | E15: 25532982 | F15: =IF((E15-E14)<0,"0",(E15-E14)) -> 5806 | G15: 80421856 | H15: =IF((G15-G14)<0,"0",(G15-G14)) -> 43536 | I15: =F15+H15 -> 49342 | J15: 7820066 | K15: =IF((J15-J14)<0,"0",(J15-J14)) -> 5340 | L15: 7840124 | M15: =IF((L15-L14)<0,"0",(L15-L14)) -> 4176 | N15: 5024933 | O15: =(IF((N15-N14)<0,"0",(N15-N14)))*2 -> 1508 | P15: 3007987 | Q15: =IF((P15-P14)<0,"0",(P15-P14)) -> 8171 | R15: 17105563 | S15: =IF((R15-R14)<0,"0",(R15-R14)) -> 8628 | T15: 0 | V15: 4713361 | W15: =IF((V15-V14)<0,"0",(V15-V14)) -> 10191 | X15: =K15+M15+O15+Q15+S15+U15+W15 -> 38014 | Y15: =I15-X15 -> 11328 | Z15: =(0.93352*(W15+S15)+0.5568*(Q15+O15))*0.26 -> 5968.8668 | AA15: =SUM(Z12:Z15) -> 26932.186
A16: 44299 | C16: 18103 | D16: =IF((C16-C15)<0,"0",(C16-C15))*160 -> 320 | E16: 25537459 | F16: =IF((E16-E15)<0,"0",(E16-E15)) -> 4477 | G16: 80454776 | H16: =IF((G16-G15)<0,"0",(G16-G15)) -> 32920 | I16: =F16+H16 -> 37397 | J16: 7823827 | K16: =IF((J16-J15)<0,"0",(J16-J15)) -> 3761 | L16: 7843029 | M16: =IF((L16-L15)<0,"0",(L16-L15)) -> 2905 | N16: 5025659 | O16: =(IF((N16-N15)<0,"0",(N16-N15)))*2 -> 1452 | P16: 3014394 | Q16: =IF((P16-P15)<0,"0",(P16-P15)) -> 6407 | R16: 17112457 | S16: =IF((R16-R15)<0,"0",(R16-R15)) -> 6894 | T16: 0 | V16: 4720895 | W16: =IF((V16-V15)<0,"0",(V16-V15)) -> 7534 | X16: =K16+M16+O16+Q16+S16+U16+W16 -> 28953 | Y16: =I16-X16 -> 8444 | Z16: =(0.93352*(W16+S16)+0.5568*(Q16+O16))*0.26 -> 4639.6266 | AA16: =SUM(Z13:Z16) -> 22961.783
