Workbook

Sheet Total
A1: Site Name | B1: Day | C1: Month | D1: Year | E1: Total Electricity Kwh | F1: Electricity Tariff ($/Kwh) | G1: Total Fuel Oil (Liters) | H1: Fuel Oil $/Liter | I1: LPG (Kg) | J1: LPG $/Kg | K1: Water Utility Supply (m3) m3 | L1: Water Utility Supply (m3) $/m3 | M1: Irrigation Water (m3) m3 | N1: Irrigation water $/m3 | O1: Room Nights
A2: Beirut | B2: 1 | C2: 5 | D2: 2021 | E2: =ELEC!N3 -> 8346 | F2: =SUM('EDl log'!T4) -> 0.19591976 | G2: =-tanks!AW6 -> 195 | H2: =SUM(tanks!AV6) -> 0.92 | I2: =('B5'!AU5)*0.51 -> 0 | J2: ='B5'!AX5/0.51 -> 1.5686275 | K2: =WATER!I6 -> 7 | L2: =SUM(WATER!J6) -> 34.562212 | M2: =WATER!Q6 -> 0 | N2: 0.6 | O2: =ELEC!B3 -> 0
A3: Beirut | B3: =B2+1 -> 2 | C3: 5 | D3: 2021 | E3: =ELEC!N4 -> 6548 | F3: =SUM('EDl log'!T5) -> 0.15499849 | G3: =-tanks!AW7 -> 153 | H3: =SUM(tanks!AV7) -> 0.92 | I3: =('B5'!AU6)*0.51 -> 0 | J3: ='B5'!AX6/0.51 -> 1.5686275 | K3: =WATER!I7 -> 0 | L3: =SUM(WATER!J7) -> 0 | M3: =WATER!Q7 -> 0 | N3: 0.6 | O3: =ELEC!B4 -> 0
A4: Beirut | B4: =B3+1 -> 3 | C4: 5 | D4: 2021 | E4: =ELEC!N5 -> 7179 | F4: =SUM('EDl log'!T6) -> 0.15992607 | G4: =-tanks!AW8 -> 141 | H4: =SUM(tanks!AV8) -> 0.92 | I4: =('B5'!AU7)*0.51 -> 0 | J4: ='B5'!AX7/0.51 -> 1.5686275 | K4: =WATER!I8 -> 289 | L4: =SUM(WATER!J8) -> 0.837147 | M4: =WATER!Q8 -> 0 | N4: 0.6 | O4: =ELEC!B5 -> 0
A5: Beirut | B5: =B4+1 -> 4 | C5: 5 | D5: 2021 | E5: =ELEC!N6 -> 8383 | F5: =SUM('EDl log'!T7) -> 0.22229999 | G5: =-tanks!AW9 -> 95 | H5: =SUM(tanks!AV9) -> 0.92 | I5: =('B5'!AU8)*0.51 -> 0 | J5: ='B5'!AX8/0.51 -> 1.5686275 | K5: =WATER!I9 -> 0 | L5: =SUM(WATER!J9) -> 0 | M5: =WATER!Q9 -> 0 | N5: 0.6 | O5: =ELEC!B6 -> 0
A6: Beirut | B6: =B5+1 -> 5 | C6: 5 | D6: 2021 | E6: =ELEC!N7 -> 4768 | F6: =SUM('EDl log'!T8) -> 0.41641378 | G6: =-tanks!AW10 -> 164 | H6: =SUM(tanks!AV10) -> 0.92 | I6: =('B5'!AU9)*0.51 -> 0 | J6: ='B5'!AX9/0.51 -> 1.5686275 | K6: =WATER!I10 -> 295 | L6: =SUM(WATER!J10) -> 0.82012028 | M6: =WATER!Q10 -> 0 | N6: 0.6 | O6: =ELEC!B7 -> 0
A7: Beirut | B7: =B6+1 -> 6 | C7: 5 | D7: 2021 | E7: =ELEC!N8 -> 3912 | F7: =SUM('EDl log'!T9) -> 0.32267671 | G7: =-tanks!AW11 -> 155 | H7: =SUM(tanks!AV11) -> 0.92 | I7: =('B5'!AU10)*0.51 -> 0 | J7: ='B5'!AX10/0.51 -> 1.5686275 | K7: =WATER!I11 -> 0 | L7: =SUM(WATER!J11) -> 0 | M7: =WATER!Q11 -> 0 | N7: 0.6 | O7: =ELEC!B8 -> 0
A8: Beirut | B8: =B7+1 -> 7 | C8: 5 | D8: 2021 | E8: =ELEC!N9 -> 8995.4 | F8: =SUM('EDl log'!T10) -> 0.23986728 | G8: =-tanks!AW12 -> 166 | H8: =SUM(tanks!AV12) -> 0.92 | I8: =('B5'!AU11)*0.51 -> 0 | J8: ='B5'!AX11/0.51 -> 1.5686275 | K8: =WATER!I12 -> 293 | L8: =SUM(WATER!J12) -> 0.82571837 | M8: =WATER!Q12 -> 0 | N8: 0.6 | O8: =ELEC!B9 -> 0
A9: Beirut | B9: =B8+1 -> 8 | C9: 5 | D9: 2021 | E9: =ELEC!N10 -> 8249.8 | F9: =SUM('EDl log'!T11) -> 0.25935974 | G9: =-tanks!AW13 -> 156 | H9: =SUM(tanks!AV13) -> 0.92 | I9: =('B5'!AU12)*0.51 -> 0 | J9: ='B5'!AX12/0.51 -> 1.5686275 | K9: =WATER!I13 -> 0 | L9: =SUM(WATER!J13) -> 0 | M9: =WATER!Q13 -> 0 | N9: 0.6 | O9: =ELEC!B10 -> 0
A10: Beirut | B10: =B9+1 -> 9 | C10: 5 | D10: 2021 | E10: =ELEC!N11 -> 9025.8 | F10: =SUM('EDl log'!T12) -> 0.21968385 | G10: =-tanks!AW14 -> 112 | H10: =SUM(tanks!AV14) -> 0.92 | I10: =('B5'!AU13)*0.51 -> 0 | J10: ='B5'!AX13/0.51 -> 1.5686275 | K10: =WATER!I14 -> 0 | L10: =SUM(WATER!J14) -> 0 | M10: =WATER!Q14 -> 0 | N10: 0.6 | O10: =ELEC!B11 -> 0
A11: Beirut | B11: =B10+1 -> 10 | C11: 5 | D11: 2021 | E11: =ELEC!N12 -> 9481 | F11: =SUM('EDl log'!T13) -> 0.25199309 | G11: =-tanks!AW15 -> 82 | H11: =SUM(tanks!AV15) -> 0.92 | I11: =('B5'!AU14)*0.51 -> 0 | J11: ='B5'!AX14/0.51 -> 1.5686275 | K11: =WATER!I15 -> 0 | L11: =SUM(WATER!J15) -> 0 | M11: =WATER!Q15 -> 0 | N11: 0.6 | O11: =ELEC!B12 -> 0
A12: Beirut | B12: =B11+1 -> 11 | C12: 5 | D12: 2021 | E12: =ELEC!N13 -> 9028 | F12: =SUM('EDl log'!T14) -> -0.057144375 | G12: =-tanks!AW16 -> 137 | H12: =SUM(tanks!AV16) -> 0.94 | I12: =('B5'!AU15)*0.51 -> 0 | J12: ='B5'!AX15/0.51 -> 1.5686275 | K12: =WATER!I16 -> 0 | L12: =SUM(WATER!J16) -> 0 | M12: =WATER!Q16 -> 0 | N12: 0.6 | O12: =ELEC!B13 -> 0
A13: Beirut | B13: =B12+1 -> 12 | C13: 5 | D13: 2021 | E13: =ELEC!N14 -> 9411 | F13: =SUM('EDl log'!T15) -> 0.2885114 | G13: =-tanks!AW17 -> 154 | H13: =SUM(tanks!AV17) -> 0.94 | I13: =('B5'!AU16)*0.51 -> 0 | J13: ='B5'!AX16/0.51 -> 1.5686275 | K13: =WATER!I17 -> 0 | L13: =SUM(WATER!J17) -> 0 | M13: =WATER!Q17 -> 0 | N13: 0.6 | O13: =ELEC!B14 -> 0
A14: Beirut | B14: =B13+1 -> 13 | C14: 5 | D14: 2021 | E14: =ELEC!N15 -> 9646 | F14: =SUM('EDl log'!T16) -> 0.23476721 | G14: =-tanks!AW18 -> 115 | H14: =SUM(tanks!AV18) -> 0.94 | I14: =('B5'!AU17)*0.51 -> 0 | J14: ='B5'!AX17/0.51 -> 1.5686275 | K14: =WATER!I18 -> 341 | L14: =SUM(WATER!J18) -> 0.70948822 | M14: =WATER!Q18 -> 0 | N14: 0.6 | O14: =ELEC!B15 -> 0
... A32: Beirut | B32: =B31+1 -> 31 | C32: 5 | D32: 2022 | E32: =ELEC!N33 -> 0 | F32: =SUM('EDl log'!T34) -> 0 | G32: =-tanks!AW36 -> 0 | H32: =SUM(tanks!AV36) -> 0.94 | I32: =('B5'!AU35)*0.51 -> 0 | J32: ='B5'!AX35/0.51 -> 1.5686275 | K32: =WATER!I36 -> 0 | L32: =SUM(WATER!J36) -> 0 | M32: =WATER!Q36 -> 0 | N32: 1.6 | O32: =ELEC!B33 -> 0

Sheet Submetering
A1: Site Name | B1: Day | C1: Month | D1: Year | E1: ATS1 Kwh | F1: ATS2 Kwh | G1: ATS3 Kwh | H1: ATS4 Kwh | I1: ATS5 Kwh | J1: Guest (m3) | K1: Kitchen & Laundry (m3) | L1: Room Nights
A2: Beirut | B2: 1 | C2: 5 | D2: 2021 | E2: =ELEC!M3 -> 2194 | F2: =ELEC!K3 -> 1280 | G2: =ELEC!I3 -> 882 | H2: =ELEC!E3 -> 3356 | I2: =ELEC!G3 -> 634 | J2: =WATER!Y6 -> 0 | K2: =WATER!AJ6 -> 0 | L2: =ELEC!B3 -> 0
A3: Beirut | B3: =B2+1 -> 2 | C3: 5 | D3: 2021 | E3: =ELEC!M4 -> 1698 | F3: =ELEC!K4 -> 912 | G3: =ELEC!I4 -> 692 | H3: =ELEC!E4 -> 2632 | I3: =ELEC!G4 -> 614 | J3: =WATER!Y7 -> 0 | K3: =WATER!AJ7 -> 0 | L3: =ELEC!B4 -> 0
A4: Beirut | B4: =B3+1 -> 3 | C4: 5 | D4: 2021 | E4: =ELEC!M5 -> 1276 | F4: =ELEC!K5 -> 920 | G4: =ELEC!I5 -> 804 | H4: =ELEC!E5 -> 3588 | I4: =ELEC!G5 -> 591 | J4: =WATER!Y8 -> 82 | K4: =WATER!AJ8 -> 36 | L4: =ELEC!B5 -> 0
A5: Beirut | B5: =B4+1 -> 4 | C5: 5 | D5: 2021 | E5: =ELEC!M6 -> 1652 | F5: =ELEC!K6 -> 2336 | G5: =ELEC!I6 -> 788 | H5: =ELEC!E6 -> 2984 | I5: =ELEC!G6 -> 623 | J5: =WATER!Y9 -> 1 | K5: =WATER!AJ9 -> 0 | L5: =ELEC!B6 -> 0
A6: Beirut | B6: =B5+1 -> 5 | C6: 5 | D6: 2021 | E6: =ELEC!M7 -> 1880 | F6: =ELEC!K7 -> 1312 | G6: =ELEC!I7 -> 912 | H6: =ELEC!E7 -> 0 | I6: =ELEC!G7 -> 664 | J6: =WATER!Y10 -> 105 | K6: =WATER!AJ10 -> 0 | L6: =ELEC!B7 -> 0
A7: Beirut | B7: =B6+1 -> 6 | C7: 5 | D7: 2021 | E7: =ELEC!M8 -> 1498 | F7: =ELEC!K8 -> 924 | G7: =ELEC!I8 -> 792 | H7: =ELEC!AO8 -> 5767 | I7: =ELEC!G8 -> 698 | J7: =WATER!Y11 -> 0 | K7: =WATER!AJ11 -> 0 | L7: =ELEC!B8 -> 0
A8: Beirut | B8: =B7+1 -> 7 | C8: 5 | D8: 2021 | E8: =ELEC!M9 -> 1848 | F8: =ELEC!K9 -> 1228 | G8: =ELEC!I9 -> 968 | H8: =ELEC!AO9 -> 4201 | I8: =ELEC!G9 -> 750.4 | J8: =WATER!Y12 -> 145 | K8: =WATER!AJ12 -> 0 | L8: =ELEC!B9 -> 0
A9: Beirut | B9: =B8+1 -> 8 | C9: 5 | D9: 2021 | E9: =ELEC!M10 -> 1638 | F9: =ELEC!K10 -> 1186 | G9: =ELEC!I10 -> 792 | H9: =ELEC!AO10 -> 3953 | I9: =ELEC!G10 -> 680.8 | J9: =WATER!Y13 -> 0 | K9: =WATER!AJ13 -> 32 | L9: =ELEC!B10 -> 0
A10: Beirut | B10: =B9+1 -> 9 | C10: 5 | D10: 2021 | E10: =ELEC!M11 -> 1780 | F10: =ELEC!K11 -> 1272 | G10: =ELEC!I11 -> 796 | H10: =ELEC!AO11 -> 4500 | I10: =ELEC!G11 -> 677.8 | J10: =WATER!Y14 -> 26 | K10: =WATER!AJ14 -> 11 | L10: =ELEC!B11 -> 0
A11: Beirut | B11: =B10+1 -> 10 | C11: 5 | D11: 2021 | E11: =ELEC!M12 -> 1812 | F11: =ELEC!K12 -> 3382 | G11: =ELEC!I12 -> 836 | H11: =ELEC!AO12 -> 2791 | I11: =ELEC!G12 -> 660 | J11: =WATER!Y15 -> 0 | K11: =WATER!AJ15 -> 0 | L11: =ELEC!B12 -> 0
A12: Beirut | B12: =B11+1 -> 11 | C12: 5 | D12: 2021 | E12: =ELEC!M13 -> 1774 | F12: =ELEC!K13 -> 2956 | G12: =ELEC!I13 -> 906 | H12: =ELEC!AO13 -> 2692 | I12: =ELEC!G13 -> 700 | J12: =WATER!Y16 -> 0 | K12: =WATER!AJ16 -> 0 | L12: =ELEC!B13 -> 0
A13: Beirut | B13: =B12+1 -> 12 | C13: 5 | D13: 2021 | E13: =ELEC!M14 -> 1894 | F13: =ELEC!K14 -> 3444 | G13: =ELEC!I14 -> 910 | H13: =ELEC!AO14 -> 2489 | I13: =ELEC!G14 -> 674 | J13: =WATER!Y17 -> 0 | K13: =WATER!AJ17 -> 0 | L13: =ELEC!B14 -> 0
A14: Beirut | B14: =B13+1 -> 13 | C14: 5 | D14: 2021 | E14: =ELEC!M15 -> 1736 | F14: =ELEC!K15 -> 4104 | G14: =ELEC!I15 -> 788 | H14: =ELEC!AO15 -> 2415 | I14: =ELEC!G15 -> 603 | J14: =WATER!Y18 -> 0 | K14: =WATER!AJ18 -> 0 | L14: =ELEC!B15 -> 0
A15: Beirut | B15: =B14+1 -> 14 | C15: 5 | D15: 2021 | E15: =ELEC!M16 -> 1296 | F15: =ELEC!K16 -> 3042 | G15: =ELEC!I16 -> 748 | H15: =ELEC!AO16 -> 3136 | I15: =ELEC!G16 -> 646 | J15: =WATER!Y19 -> 0 | K15: =WATER!AJ19 -> 0 | L15: =ELEC!B16 -> 0
A16: Beirut | B16: =B15+1 -> 15 | C16: 5 | D16: 2021 | E16: =ELEC!M17 -> 1584 | F16: =ELEC!K17 -> 2474 | G16: =ELEC!I17 -> 836 | H16: =ELEC!AO17 -> 2032 | I16: =ELEC!G17 -> 661 | J16: =WATER!Y20 -> 0 | K16: =WATER!AJ20 -> 0 | L16: =ELEC!B17 -> 0
A17: Beirut | B17: =B16+1 -> 16 | C17: 5 | D17: 2021 | E17: =ELEC!M18 -> 2340 | F17: =ELEC!K18 -> 5432 | G17: =ELEC!I18 -> 1032 | H17: =ELEC!AO18 -> 3443 | I17: =ELEC!G18 -> 592 | J17: =WATER!Y21 -> 0 | K17: =WATER!AJ21 -> 0 | L17: =ELEC!B18 -> 0
A18: Beirut | B18: =B17+1 -> 17 | C18: 5 | D18: 2021 | E18: =ELEC!M19 -> 2048 | F18: =ELEC!K19 -> 2824 | G18: =ELEC!I19 -> 836 | H18: =ELEC!AO19 -> 3701 | I18: =ELEC!G19 -> 680 | J18: =WATER!Y22 -> 0 | K18: =WATER!AJ22 -> 0 | L18: =ELEC!B19 -> 0
... A32: Beirut | B32: =B31+1 -> 31 | C32: 5 | D32: 2021 | E32: =ELEC!M33 -> 0 | F32: =ELEC!K33 -> 0 | G32: =ELEC!I33 -> 0 | H32: =ELEC!AO33 -> 0 | I32: =ELEC!G33 -> 0 | J32: =WATER!Y36 -> 0 | K32: =WATER!AJ36 -> 0 | L32: =ELEC!B33 -> 0
D46: .

Sheet ELEC
A1: OOC | B1: Room OCC | D1: MDB3 | E1: MDB3/day | F1: EMDB2 | G1: EMDB2/day | H1: EMDB1 | I1: EMDB1/day | J1: MDB2 | K1: mdb2/day | L1: MDB1 | M1: MDB1/Day | N1: Total KWH | O1: KWH/Rooc | P1: Gen MHW | Q1: Gen/Day KWH | R1: EDL KWH | S1: CH1 RH | T1: RH | U1: C1h1 power | V1: CH1 Con KWH | W1: CH2 RH | X1: RH | Y1: Ch2 power | Z1: CH2 Con KWH | AA1: CH3 RH | AB1: RH | AC1: Ch3 power | AD1: CH3 Con KWH | AE1: RH total | AF1: KWH total | AG1: AVG chiller KW/Hr
A2: ='General information '!F5 -> 0 | B2: =SUM(230*A2) -> 0 | C2: 44316 | D2: 32819750 | E2: 3108 | F2: 4009734 | G2: 304 | H2: 17856136 | I2: 765 | J2: 29011666 | K2: 1972 | L2: 24175590 | M2: 1724 | N2: 7873 | O2: 0 | P2: 16972.836 | Q2: 4977 | R2: 2896 | S2: 10175 | T2: 0 | U2: 429166 | V2: 0 | W2: 32312 | X2: 5 | Y2: 721364 | Z2: 825 | AA2: 35884 | AB2: 3 | AC2: 949998 | AD2: 560 | AE2: 8 | AF2: 1385 | AG2: 173.125 | AI2: -999706
A3: ='General information '!F6 -> 0 | B3: =SUM(230*A3) -> 0 | C3: 44317 | D3: 32823106 | E3: =D3-D2 -> 3356 | F3: 4010368 | G3: =F3-F2 -> 634 | H3: 17857018 | I3: =H3-H2 -> 882 | J3: 29012946 | K3: =J3-J2 -> 1280 | L3: 24177784 | M3: =L3-L2 -> 2194 | N3: =M3+K3+I3+G3+E3 -> 8346 | O3: =IF(B3>0,N3/B3,0) -> 0 | P3: 16976.763 | Q3: =(P3-P2)*1000 -> 3927 | R3: =+N3-Q3 -> 4419 | S3: =S2 -> 10175 | T3: =S3-S2 -> 0 | U3: 429166 | V3: =U3-U2 -> 0 | W3: 32312 | X3: =W3-W2 -> 0 | Y3: =Y2 -> 721364 | Z3: =Y3-Y2 -> 0 | AA3: 35889 | AB3: =AA3-AA2 -> 5 | AC3: 951030 | AD3: =AC3-AC2 -> 1032 | AE3: =AB3+X3+T3 -> 5 | AF3: =V3+Z3+AD3 -> 1032 | AG3: =IF(AE3>0,AF3/AE3,0) -> 206.4
A4: ='General information '!F7 -> 0 | B4: =SUM(230*A4) -> 0 | C4: 44318 | D4: 32825738 | E4: =D4-D3 -> 2632 | F4: 4010982 | G4: =F4-F3 -> 614 | H4: 17857710 | I4: =H4-H3 -> 692 | J4: 29013858 | K4: =J4-J3 -> 912 | L4: 24179482 | M4: =L4-L3 -> 1698 | N4: =M4+K4+I4+G4+E4 -> 6548 | O4: =IF(B4>0,N4/B4,0) -> 0 | P4: 16978.759 | Q4: =(P4-P3)*1000 -> 1996 | R4: =N4-Q4 -> 4552 | S4: =S3 -> 10175 | T4: =S4-S3 -> 0 | U4: =U3 -> 429166 | V4: =U4-U3 -> 0 | W4: =W3 -> 32312 | X4: =W4-W3 -> 0 | Y4: =Y3 -> 721364 | Z4: =Y4-Y3 -> 0 | AA4: 35891 | AB4: =AA4-AA3 -> 2 | AC4: 951609 | AD4: =AC4-AC3 -> 579 | AE4: =AB4+X4+T4 -> 2 | AF4: =V4+Z4+AD4 -> 579 | AG4: =IF(AE4>0,AF4/AE4,0) -> 289.5 | AL4: ATS 4 till power meter is for MDB 3 is replaced
A5: ='General information '!F8 -> 0 | B5: =SUM(230*A5) -> 0 | C5: 44319 | D5: 32829326 | E5: =D5-D4 -> 3588 | F5: 4011573 | G5: =F5-F4 -> 591 | H5: 17858514 | I5: =H5-H4 -> 804 | J5: 29014778 | K5: =J5-J4 -> 920 | L5: 24180758 | M5: =L5-L4 -> 1276 | N5: =M5+K5+I5+G5+E5 -> 7179 | O5: =IF(B5>0,N5/B5,0) -> 0 | P5: 16981.779 | Q5: =(P5-P4)*1000 -> 3020 | R5: =N5-Q5 -> 4159 | S5: =S4 -> 10175 | T5: =S5-S4 -> 0 | U5: =U4 -> 429166 | V5: =U5-U4 -> 0 | W5: =W4 -> 32312 | X5: =W5-W4 -> 0 | Y5: =Y4 -> 721364 | Z5: =Y5-Y4 -> 0 | AA5: 35896 | AB5: =AA5-AA4 -> 5 | AC5: 952602 | AD5: =AC5-AC4 -> 993 | AE5: =AB5+X5+T5 -> 5 | AF5: =V5+Z5+AD5 -> 993 | AG5: =IF(AE5>0,AF5/AE5,0) -> 198.6 | AI5: =R5-'EDl log'!B3 -> -1004651 | AL5: Emergency | AM5: Normal | AN5: Total | AO5: Deference
A6: ='General information '!F9 -> 0 | B6: =SUM(230*A6) -> 0 | C6: 44320 | D6: 32832310 | E6: =D6-D5 -> 2984 | F6: 4012196 | G6: =F6-F5 -> 623 | H6: 17859302 | I6: =H6-H5 -> 788 | J6: 29017114 | K6: =J6-J5 -> 2336 | L6: 24182410 | M6: =L6-L5 -> 1652 | N6: =M6+K6+I6+G6+E6 -> 8383 | O6: =IF(B6>0,N6/B6,0) -> 0 | P6: 16985.99 | Q6: =(P6-P5)*1000 -> 4211 | R6: =N6-Q6 -> 4172 | S6: =S5 -> 10175 | T6: =S6-S5 -> 0 | U6: =U5 -> 429166 | V6: =U6-U5 -> 0 | W6: 32317 | X6: =W6-W5 -> 5 | Y6: 722633 | Z6: =Y6-Y5 -> 1269 | AA6: 35896 | AB6: =AA6-AA5 -> 0 | AC6: =AC5 -> 952602 | AD6: =AC6-AC5 -> 0 | AE6: =AB6+X6+T6 -> 5 | AF6: =V6+Z6+AD6 -> 1269 | AG6: =IF(AE6>0,AF6/AE6,0) -> 253.8 | AI6: =R6-'EDl log'!B4 -> -1007025 | AK6: 44320 | AL6: 270643 | AM6: 409413 | AN6: =AM6+AL6 -> 680056
A7: ='General information '!F10 -> 0 | B7: =SUM(230*A7) -> 0 | C7: 44321 | D7: 32832310 | E7: =D7-D6 -> 0 | F7: 4012860 | G7: =F7-F6 -> 664 | H7: 17860214 | I7: =H7-H6 -> 912 | J7: 29018426 | K7: =J7-J6 -> 1312 | L7: 24184290 | M7: =L7-L6 -> 1880 | N7: =M7+K7+I7+G7+E7 -> 4768 | O7: =IF(B7>0,N7/B7,0) -> 0 | P7: 16991.6 | Q7: =(P7-P6)*1000 -> 5610 | R7: =N7-Q7 -> -842 | S7: =S6 -> 10175 | T7: =S7-S6 -> 0 | U7: =U6 -> 429166 | V7: =U7-U6 -> 0 | W7: 32317 | X7: =W7-W6 -> 0 | Y7: 722652 | Z7: =Y7-Y6 -> 19 | AA7: 35905 | AB7: =AA7-AA6 -> 9 | AC7: 954371 | AD7: =AC7-AC6 -> 1769 | AE7: =AB7+X7+T7 -> 9 | AF7: =V7+Z7+AD7 -> 1788 | AG7: =IF(AE7>0,AF7/AE7,0) -> 198.66667 | AI7: =R7-'EDl log'!B5 -> -1014456 | AK7: 44321 | AL7: 270643 | AM7: 409413 | AN7: =AM7+AL7 -> 680056 | AO7: =AN7-AN6 -> 0
A8: ='General information '!F11 -> 0 | B8: =SUM(230*A8) -> 0 | C8: 44322 | D8: 32832310 | E8: =D8-D7 -> 0 | F8: 4013558 | G8: =F8-F7 -> 698 | H8: 17861006 | I8: =H8-H7 -> 792 | J8: 29019350 | K8: =J8-J7 -> 924 | L8: 24185788 | M8: =L8-L7 -> 1498 | N8: =M8+K8+I8+G8+E8 -> 3912 | O8: =IF(B8>0,N8/B8,0) -> 0 | P8: 16995.082 | Q8: =(P8-P7)*1000 -> 3482 | R8: =N8-Q8 -> 430 | S8: 10175 | T8: =S8-S7 -> 0 | U8: =U7 -> 429166 | V8: =U8-U7 -> 0 | W8: =W7 -> 32317 | X8: =W8-W7 -> 0 | Y8: =Y7 -> 722652 | Z8: =Y8-Y7 -> 0 | AA8: 35909 | AB8: =AA8-AA7 -> 4 | AC8: 955297 | AD8: =AC8-AC7 -> 926 | AE8: =AB8+X8+T8 -> 4 | AF8: =V8+Z8+AD8 -> 926 | AG8: =IF(AE8>0,AF8/AE8,0) -> 231.5 | AI8: =R8-'EDl log'!B6 -> -1015450 | AK8: 44322 | AL8: 274499 | AM8: 411324 | AN8: =AM8+AL8 -> 685823 | AO8: =AN8-AN7 -> 5767
A9: ='General information '!F12 -> 0 | B9: =SUM(230*A9) -> 0 | C9: 44323 | D9: =D8+AO9 -> 32836511 | E9: =D9-D8 -> 4201 | F9: 4014308.4 | G9: =F9-F8 -> 750.4 | H9: 17861974 | I9: =H9-H8 -> 968 | J9: 29020578 | K9: =J9-J8 -> 1228 | L9: 24187636 | M9: =L9-L8 -> 1848 | N9: =M9+K9+I9+G9+E9 -> 8995.4 | O9: =IF(B9>0,N9/B9,0) -> 0 | P9: 17000.937 | Q9: =(P9-P8)*1000 -> 5855 | R9: =N9-Q9 -> 3140.4 | S9: =S8 -> 10175 | T9: =S9-S8 -> 0 | U9: =U8 -> 429166 | V9: =U9-U8 -> 0 | W9: =W8 -> 32317 | X9: =W9-W8 -> 0 | Y9: =Y8 -> 722652 | Z9: =Y9-Y8 -> 0 | AA9: 35917 | AB9: =AA9-AA8 -> 8 | AC9: 956869 | AD9: =AC9-AC8 -> 1572 | AE9: =AB9+X9+T9 -> 8 | AF9: =V9+Z9+AD9 -> 1572 | AG9: =IF(AE9>0,AF9/AE9,0) -> 196.5 | AI9: =R9-'EDl log'!B7 -> -1014626.6 | AK9: 44323 | AL9: 277740 | AM9: 412284 | AN9: =AM9+AL9 -> 690024 | AO9: =AN9-AN8 -> 4201
A10: ='General information '!F13 -> 0 | B10: =SUM(230*A10) -> 0 | C10: 44324 | D10: =D9+AO10 -> 32840464 | E10: =D10-D9 -> 3953 | F10: 4014989.2 | G10: =F10-F9 -> 680.8 | H10: 17862766 | I10: =H10-H9 -> 792 | J10: 29021764 | K10: =J10-J9 -> 1186 | L10: 24189274 | M10: =L10-L9 -> 1638 | N10: =M10+K10+I10+G10+E10 -> 8249.8 | O10: =IF(B10>0,N10/B10,0) -> 0 | P10: 17006.446 | Q10: =(P10-P9)*1000 -> 5509 | R10: =N10-Q10 -> 2740.8 | S10: =S9 -> 10175 | T10: =S10-S9 -> 0 | U10: =U9 -> 429166 | V10: =U10-U9 -> 0 | W10: =W9 -> 32317 | X10: =W10-W9 -> 0 | Y10: =Y9 -> 722652 | Z10: =Y10-Y9 -> 0 | AA10: 35924 | AB10: =AA10-AA9 -> 7 | AC10: 958420 | AD10: =AC10-AC9 -> 1551 | AE10: =AB10+X10+T10 -> 7 | AF10: =V10+Z10+AD10 -> 1551 | AG10: =IF(AE10>0,AF10/AE10,0) -> 221.57143 | AI10: =R10-'EDl log'!B8 -> -1017112.2 | AK10: 44324 | AL10: 280877 | AM10: 413100 | AN10: =AM10+AL10 -> 693977 | AO10: =AN10-AN9 -> 3953
A11: ='General information '!F14 -> 0 | B11: =SUM(230*A11) -> 0 | C11: 44325 | D11: =D10+AO11 -> 32844964 | E11: =D11-D10 -> 4500 | F11: 4015667 | G11: =F11-F10 -> 677.8 | H11: 17863562 | I11: =H11-H10 -> 796 | J11: 29023036 | K11: =J11-J10 -> 1272 | L11: 24191054 | M11: =L11-L10 -> 1780 | N11: =M11+K11+I11+G11+E11 -> 9025.8 | O11: =IF(B11>0,N11/B11,0) -> 0 | P11: 17012.749 | Q11: =(P11-P10)*1000 -> 6303 | R11: =N11-Q11 -> 2722.8 | S11: =S10 -> 10175 | T11: =S11-S10 -> 0 | U11: =U10 -> 429166 | V11: =U11-U10 -> 0 | W11: =W10 -> 32317 | X11: =W11-W10 -> 0 | Y11: =Y10 -> 722652 | Z11: =Y11-Y10 -> 0 | AA11: 35932 | AB11: =AA11-AA10 -> 8 | AC11: 960238 | AD11: =AC11-AC10 -> 1818 | AE11: =AB11+X11+T11 -> 8 | AF11: =V11+Z11+AD11 -> 1818 | AG11: =IF(AE11>0,AF11/AE11,0) -> 227.25 | AI11: =R11-'EDl log'!B9 -> -1019084.2 | AK11: 44325 | AL11: 284469 | AM11: 414008 | AN11: =AM11+AL11 -> 698477 | AO11: =AN11-AN10 -> 4500
A12: ='General information '!F15 -> 0 | B12: =SUM(230*A12) -> 0 | C12: 44326 | D12: =D11+AO12 -> 32847755 | E12: =D12-D11 -> 2791 | F12: 4016327 | G12: =F12-F11 -> 660 | H12: 17864398 | I12: =H12-H11 -> 836 | J12: 29026418 | K12: =J12-J11 -> 3382 | L12: 24192866 | M12: =L12-L11 -> 1812 | N12: =M12+K12+I12+G12+E12 -> 9481 | O12: =IF(B12>0,N12/B12,0) -> 0 | P12: 17019.087 | Q12: =(P12-P11)*1000 -> 6338 | R12: =N12-Q12 -> 3143 | S12: =S11 -> 10175 | T12: =S12-S11 -> 0 | U12: =U11 -> 429166 | V12: =U12-U11 -> 0 | W12: 32325 | X12: =W12-W11 -> 8 | Y12: 724713 | Z12: =Y12-Y11 -> 2061 | AA12: =AA11 -> 35932 | AB12: =AA12-AA11 -> 0 | AC12: =AC11 -> 960238 | AD12: =AC12-AC11 -> 0 | AE12: =AB12+X12+T12 -> 8 | AF12: =V12+Z12+AD12 -> 2061 | AG12: =IF(AE12>0,AF12/AE12,0) -> 257.625 | AI12: =R12-'EDl log'!B10 -> -1020410 | AK12: 44326 | AL12: 286090 | AM12: 415178 | AN12: =AM12+AL12 -> 701268 | AO12: =AN12-AN11 -> 2791
A13: ='General information '!F16 -> 0 | B13: =SUM(230*A13) -> 0 | C13: 44327 | D13: =D12+AO13 -> 32850447 | E13: =D13-D12 -> 2692 | F13: 4017027 | G13: =F13-F12 -> 700 | H13: 17865304 | I13: =H13-H12 -> 906 | J13: 29029374 | K13: =J13-J12 -> 2956 | L13: 24194640 | M13: =L13-L12 -> 1774 | N13: =M13+K13+I13+G13+E13 -> 9028 | O13: =IF(B13>0,N13/B13,0) -> 0 | P13: 17024.831 | Q13: =(P13-P12)*1000 -> 5744 | R13: =N13-Q13 -> 3284 | S13: =S12 -> 10175 | T13: =S13-S12 -> 0 | U13: =U12 -> 429166 | V13: =U13-U12 -> 0 | W13: 32332 | X13: =W13-W12 -> 7 | Y13: 726135 | Z13: =Y13-Y12 -> 1422 | AA13: =AA12 -> 35932 | AB13: =AA13-AA12 -> 0 | AC13: =AC12 -> 960238 | AD13: =AC13-AC12 -> 0 | AE13: =AB13+X13+T13 -> 7 | AF13: =V13+Z13+AD13 -> 1422 | AG13: =IF(AE13>0,AF13/AE13,0) -> 203.14286 | AI13: =R13-'EDl log'!B11 -> -1021853 | AK13: 44327 | AL13: 287725 | AM13: 416235 | AN13: =AM13+AL13 -> 703960 | AO13: =AN13-AN12 -> 2692
A14: ='General information '!F17 -> 0 | B14: =SUM(230*A14) -> 0 | C14: 44328 | D14: =D13+AO14 -> 32852936 | E14: =D14-D13 -> 2489 | F14: 4017701 | G14: =F14-F13 -> 674 | H14: 17866214 | I14: =H14-H13 -> 910 | J14: 29032818 | K14: =J14-J13 -> 3444 | L14: 24196534 | M14: =L14-L13 -> 1894 | N14: =M14+K14+I14+G14+E14 -> 9411 | O14: =IF(B14>0,N14/B14,0) -> 0 | P14: 17032.1 | Q14: =(P14-P13)*1000 -> 7269 | R14: =N14-Q14 -> 2142 | S14: =S13 -> 10175 | T14: =S14-S13 -> 0 | U14: =U13 -> 429166 | V14: =U14-U13 -> 0 | W14: 32341 | X14: =W14-W13 -> 9 | Y14: 728306 | Z14: =Y14-Y13 -> 2171 | AA14: =AA13 -> 35932 | AB14: =AA14-AA13 -> 0 | AC14: =AC13 -> 960238 | AD14: =AC14-AC13 -> 0 | AE14: =AB14+X14+T14 -> 9 | AF14: =V14+Z14+AD14 -> 2171 | AG14: =IF(AE14>0,AF14/AE14,0) -> 241.22222 | AI14: =R14-'EDl log'!B12 -> -1024547 | AK14: 44328 | AL14: 289550 | AM14: 416899 | AN14: =AM14+AL14 -> 706449 | AO14: =AN14-AN13 -> 2489
A15: ='General information '!F18 -> 0 | B15: =SUM(230*A15) -> 0 | C15: 44329 | D15: =D14+AO15 -> 32855351 | E15: =D15-D14 -> 2415 | F15: 4018304 | G15: =F15-F14 -> 603 | H15: 17867002 | I15: =H15-H14 -> 788 | J15: 29036922 | K15: =J15-J14 -> 4104 | L15: 24198270 | M15: =L15-L14 -> 1736 | N15: =M15+K15+I15+G15+E15 -> 9646 | O15: =IF(B15>0,N15/B15,0) -> 0 | P15: 17038.805 | Q15: =(P15-P14)*1000 -> 6705 | R15: =N15-Q15 -> 2941 | S15: =S14 -> 10175 | T15: =S15-S14 -> 0 | U15: =U14 -> 429166 | V15: =U15-U14 -> 0 | W15: 32349 | X15: =W15-W14 -> 8 | Y15: 730287 | Z15: =Y15-Y14 -> 1981 | AA15: =AA14 -> 35932 | AB15: =AA15-AA14 -> 0 | AC15: =AC14 -> 960238 | AD15: =AC15-AC14 -> 0 | AE15: =AB15+X15+T15 -> 8 | AF15: =V15+Z15+AD15 -> 1981 | AG15: =IF(AE15>0,AF15/AE15,0) -> 247.625 | AI15: =R15-'EDl log'!B13 -> -1025522 | AK15: 44329 | AL15: 291124 | AM15: 417740 | AN15: =AM15+AL15 -> 708864 | AO15: =AN15-AN14 -> 2415
A16: ='General information '!F19 -> 0 | B16: =SUM(230*A16) -> 0 | C16: 44330 | D16: =D15+AO16 -> 32858487 | E16: =D16-D15 -> 3136 | F16: 4018950 | G16: =F16-F15 -> 646 | H16: 17867750 | I16: =H16-H15 -> 748 | J16: 29039964 | K16: =J16-J15 -> 3042 | L16: 24199566 | M16: =L16-L15 -> 1296 | N16: =M16+K16+I16+G16+E16 -> 8868 | O16: =IF(B16>0,N16/B16,0) -> 0 | P16: 17044.19 | Q16: =(P16-P15)*1000 -> 5385 | R16: =N16-Q16 -> 3483 | S16: =S15 -> 10175 | T16: =S16-S15 -> 0 | U16: =U15 -> 429166 | V16: =U16-U15 -> 0 | W16: 32354 | X16: =W16-W15 -> 5 | Y16: 731328 | Z16: =Y16-Y15 -> 1041 | AA16: 35935 | AB16: =AA16-AA15 -> 3 | AC16: 960881 | AD16: =AC16-AC15 -> 643 | AE16: =AB16+X16+T16 -> 8 | AF16: =V16+Z16+AD16 -> 1684 | AG16: =IF(AE16>0,AF16/AE16,0) -> 210.5 | AI16: =R16-'EDl log'!B14 -> -1026783 | AK16: 44330 | AL16: 292977 | AM16: 419023 | AN16: =AM16+AL16 -> 712000 | AO16: =AN16-AN15 -> 3136
A17: ='General information '!F20 -> 0 | B17: =SUM(230*A17) -> 0 | C17: 44331 | D17: =D16+AO17 -> 32860519 | E17: =D17-D16 -> 2032 | F17: 4019611 | G17: =F17-F16 -> 661 | H17: 17868586 | I17: =H17-H16 -> 836 | J17: 29042438 | K17: =J17-J16 -> 2474 | L17: 24201150 | M17: =L17-L16 -> 1584 | N17: =M17+K17+I17+G17+E17 -> 7587 | O17: =IF(B17>0,N17/B17,0) -> 0 | P17: 17050.586 | Q17: =(P17-P16)*1000 -> 6396 | R17: =N17-Q17 -> 1191 | S17: =S16 -> 10175 | T17: =S17-S16 -> 0 | U17: =U16 -> 429166 | V17: =U17-U16 -> 0 | W17: 32359 | X17: =W17-W16 -> 5 | Y17: 732497 | Z17: =Y17-Y16 -> 1169 | AA17: =AA16 -> 35935 | AB17: =AA17-AA16 -> 0 | AC17: =AC16 -> 960881 | AD17: =AC17-AC16 -> 0 | AE17: =AB17+X17+T17 -> 5 | AF17: =V17+Z17+AD17 -> 1169 | AG17: =IF(AE17>0,AF17/AE17,0) -> 233.8 | AI17: =R17-'EDl log'!B15 -> -1030324 | AK17: 44331 | AL17: 294108 | AM17: 419924 | AN17: =AM17+AL17 -> 714032 | AO17: =AN17-AN16 -> 2032
A18: ='General information '!F21 -> 0 | B18: =SUM(230*A18) -> 0 | C18: 44332 | D18: =D17+AO18 -> 32863962 | E18: =D18-D17 -> 3443 | F18: 4020203 | G18: =F18-F17 -> 592 | H18: 17869618 | I18: =H18-H17 -> 1032 | J18: 29047870 | K18: =J18-J17 -> 5432 | L18: 24203490 | M18: =L18-L17 -> 2340 | N18: =M18+K18+I18+G18+E18 -> 12839 | O18: =IF(B18>0,N18/B18,0) -> 0 | P18: 17055.611 | Q18: =(P18-P17)*1000 -> 5025 | R18: =N18-Q18 -> 7814 | S18: =S17 -> 10175 | T18: =S18-S17 -> 0 | U18: =U17 -> 429166 | V18: =U18-U17 -> 0 | W18: 32370 | X18: =W18-W17 -> 11 | Y18: 735160 | Z18: =Y18-Y17 -> 2663 | AA18: =AA17 -> 35935 | AB18: =AA18-AA17 -> 0 | AC18: =AC17 -> 960881 | AD18: =AC18-AC17 -> 0 | AE18: =AB18+X18+T18 -> 11 | AF18: =V18+Z18+AD18 -> 2663 | AG18: =IF(AE18>0,AF18/AE18,0) -> 242.09091 | AI18: =R18-'EDl log'!B16 -> -1025368 | AK18: 44332 | AL18: 296883 | AM18: 420592 | AN18: =AM18+AL18 -> 717475 | AO18: =AN18-AN17 -> 3443
A19: ='General information '!F22 -> 0 | B19: =SUM(230*A19) -> 0 | C19: 44333 | D19: =D18+AO19 -> 32867663 | E19: =D19-D18 -> 3701 | F19: 4020883 | G19: =F19-F18 -> 680 | H19: 17870454 | I19: =H19-H18 -> 836 | J19: 29050694 | K19: =J19-J18 -> 2824 | L19: 24205538 | M19: =L19-L18 -> 2048 | N19: =M19+K19+I19+G19+E19 -> 10089 | O19: =IF(B19>0,N19/B19,0) -> 0 | P19: 17066.045 | Q19: =(P19-P18)*1000 -> 10434 | R19: =N19-Q19 -> -345 | S19: =S18 -> 10175 | T19: =S19-S18 -> 0 | U19: =U18 -> 429166 | V19: =U19-U18 -> 0 | W19: 32376 | X19: =W19-W18 -> 6 | Y19: 736671 | Z19: =Y19-Y18 -> 1511 | AA19: 35939 | AB19: =AA19-AA18 -> 4 | AC19: 961645 | AD19: =AC19-AC18 -> 764 | AE19: =AB19+X19+T19 -> 10 | AF19: =V19+Z19+AD19 -> 2275 | AG19: =IF(AE19>0,AF19/AE19,0) -> 227.5 | AI19: =R19-'EDl log'!B17 -> -1035454 | AK19: 44333 | AL19: 299259 | AM19: 421917 | AN19: =AM19+AL19 -> 721176 | AO19: =AN19-AN18 -> 3701
A20: ='General information '!F23 -> 0 | B20: =SUM(230*A20) -> 0 | C20: 44334 | D20: =D19+AO20 -> 32870113 | E20: =D20-D19 -> 2450 | F20: 4021684 | G20: =F20-F19 -> 801 | H20: 17872138 | I20: =H20-H19 -> 1684 | J20: 29054174 | K20: =J20-J19 -> 3480 | L20: 24207420 | M20: =L20-L19 -> 1882 | N20: =M20+K20+I20+G20+E20 -> 10297 | O20: =IF(B20>0,N20/B20,0) -> 0 | P20: 17073.79 | Q20: =(P20-P19)*1000 -> 7745 | R20: =N20-Q20 -> 2552 | S20: =S19 -> 10175 | T20: =S20-S19 -> 0 | U20: =U19 -> 429166 | V20: =U20-U19 -> 0 | W20: 32387 | X20: =W20-W19 -> 11 | Y20: 738782 | Z20: =Y20-Y19 -> 2111 | AA20: =AA19 -> 35939 | AB20: =AA20-AA19 -> 0 | AC20: =AC19 -> 961645 | AD20: =AC20-AC19 -> 0 | AE20: =AB20+X20+T20 -> 11 | AF20: =V20+Z20+AD20 -> 2111 | AG20: =IF(AE20>0,AF20/AE20,0) -> 191.90909 | AI20: =R20-'EDl log'!B18 -> -1034253 | AK20: 44334 | AL20: 301110 | AM20: 422516 | AN20: =AM20+AL20 -> 723626 | AO20: =AN20-AN19 -> 2450
A21: ='General information '!F24 -> 0 | B21: =SUM(230*A21) -> 0 | C21: 44335 | D21: =D20+AO21 -> 32874062 | E21: =D21-D20 -> 3949 | F21: 4022730 | G21: =F21-F20 -> 1046 | H21: 17873314 | I21: =H21-H20 -> 1176 | J21: 29060818 | K21: =J21-J20 -> 6644 | L21: 24209944 | M21: =L21-L20 -> 2524 | N21: =M21+K21+I21+G21+E21 -> 15339 | O21: =IF(B21>0,N21/B21,0) -> 0 | P21: 17086.036 | Q21: =(P21-P20)*1000 -> 12246 | R21: =N21-Q21 -> 3093 | S21: =S20 -> 10175 | T21: =S21-S20 -> 0 | U21: =U20 -> 429166 | V21: =U21-U20 -> 0 | W21: 32397 | X21: =W21-W20 -> 10 | Y21: 740914 | Z21: =Y21-Y20 -> 2132 | AA21: =AA20 -> 35939 | AB21: =AA21-AA20 -> 0 | AC21: =AC20 -> 961645 | AD21: =AC21-AC20 -> 0 | AE21: =AB21+X21+T21 -> 10 | AF21: =V21+Z21+AD21 -> 2132 | AG21: =IF(AE21>0,AF21/AE21,0) -> 213.2 | AI21: =R21-'EDl log'!B19 -> -1033712 | AK21: 44335 | AL21: 304137 | AM21: 423438 | AN21: =AM21+AL21 -> 727575 | AO21: =AN21-AN20 -> 3949
A22: ='General information '!F25 -> 0 | B22: =SUM(230*A22) -> 0 | C22: 44336 | D22: =D21+AO22 -> 32874062 | E22: =D22-D21 -> 0 | F22: =F21 -> 4022730 | G22: =F22-F21 -> 0 | H22: =H21 -> 17873314 | I22: =H22-H21 -> 0 | J22: =J21 -> 29060818 | K22: =J22-J21 -> 0 | L22: =L21 -> 24209944 | M22: =L22-L21 -> 0 | N22: =M22+K22+I22+G22+E22 -> 0 | O22: =IF(B22>0,N22/B22,0) -> 0 | P22: =P21 -> 17086.036 | Q22: =(P22-P21)*1000 -> 0 | R22: =N22-Q22 -> 0 | S22: =S21 -> 10175 | T22: =S22-S21 -> 0 | U22: =U21 -> 429166 | V22: =U22-U21 -> 0 | W22: =W21 -> 32397 | X22: =W22-W21 -> 0 | Y22: =Y21 -> 740914 | Z22: =Y22-Y21 -> 0 | AA22: =AA21 -> 35939 | AB22: =AA22-AA21 -> 0 | AC22: =AC21 -> 961645 | AD22: =AC22-AC21 -> 0 | AE22: =AB22+X22+T22 -> 0 | AF22: =V22+Z22+AD22 -> 0 | AG22: =IF(AE22>0,AF22/AE22,0) -> 0 | AI22: =R22-'EDl log'!B20 -> -1039767 | AK22: 44336 | AL22: =AL21 -> 304137 | AM22: =AM21 -> 423438 | AN22: =AM22+AL22 -> 727575 | AO22: =AN22-AN21 -> 0
A23: ='General information '!F26 -> 0 | B23: =SUM(230*A23) -> 0 | C23: 44337 | D23: =D22+AO23 -> 32874062 | E23: =D23-D22 -> 0 | F23: =F22 -> 4022730 | G23: =F23-F22 -> 0 | H23: =H22 -> 17873314 | I23: =H23-H22 -> 0 | J23: =J22 -> 29060818 | K23: =J23-J22 -> 0 | L23: =L22 -> 24209944 | M23: =L23-L22 -> 0 | N23: =M23+K23+I23+G23+E23 -> 0 | O23: =IF(B23>0,N23/B23,0) -> 0 | P23: =P22 -> 17086.036 | Q23: =(P23-P22)*1000 -> 0 | R23: =N23-Q23 -> 0 | S23: =S22 -> 10175 | T23: =S23-S22 -> 0 | U23: =U22 -> 429166 | V23: =U23-U22 -> 0 | W23: =W22 -> 32397 | X23: =W23-W22 -> 0 | Y23: =Y22 -> 740914 | Z23: =Y23-Y22 -> 0 | AA23: =AA22 -> 35939 | AB23: =AA23-AA22 -> 0 | AC23: =AC22 -> 961645 | AD23: =AC23-AC22 -> 0 | AE23: =AB23+X23+T23 -> 0 | AF23: =V23+Z23+AD23 -> 0 | AG23: =IF(AE23>0,AF23/AE23,0) -> 0 | AI23: =R23-'EDl log'!B21 -> -1041509 | AK23: 44337 | AL23: =AL22 -> 304137 | AM23: =AM22 -> 423438 | AN23: =AM23+AL23 -> 727575 | AO23: =AN23-AN22 -> 0
A24: ='General information '!F27 -> 0 | B24: =SUM(230*A24) -> 0 | C24: 44338 | D24: =D23+AO24 -> 32874062 | E24: =D24-D23 -> 0 | F24: =F23 -> 4022730 | G24: =F24-F23 -> 0 | H24: =H23 -> 17873314 | I24: =H24-H23 -> 0 | J24: =J23 -> 29060818 | K24: =J24-J23 -> 0 | L24: =L23 -> 24209944 | M24: =L24-L23 -> 0 | N24: =M24+K24+I24+G24+E24 -> 0 | O24: =IF(B24>0,N24/B24,0) -> 0 | P24: =P23 -> 17086.036 | Q24: =(P24-P23)*1000 -> 0 | R24: =N24-Q24 -> 0 | S24: =S23 -> 10175 | T24: =S24-S23 -> 0 | U24: =U23 -> 429166 | V24: =U24-U23 -> 0 | W24: =W23 -> 32397 | X24: =W24-W23 -> 0 | Y24: =Y23 -> 740914 | Z24: =Y24-Y23 -> 0 | AA24: =AA23 -> 35939 | AB24: =AA24-AA23 -> 0 | AC24: =AC23 -> 961645 | AD24: =AC24-AC23 -> 0 | AE24: =AB24+X24+T24 -> 0 | AF24: =V24+Z24+AD24 -> 0 | AG24: =IF(AE24>0,AF24/AE24,0) -> 0 | AI24: =R24-'EDl log'!B22 -> -1043337 | AK24: 44338 | AL24: =AL23 -> 304137 | AM24: =AM23 -> 423438 | AN24: =AM24+AL24 -> 727575 | AO24: =AN24-AN23 -> 0
A25: ='General information '!F28 -> 0 | B25: =SUM(230*A25) -> 0 | C25: 44339 | D25: =D24+AO25 -> 32874062 | E25: =D25-D24 -> 0 | F25: =F24 -> 4022730 | G25: =F25-F24 -> 0 | H25: =H24 -> 17873314 | I25: =H25-H24 -> 0 | J25: =J24 -> 29060818 | K25: =J25-J24 -> 0 | L25: =L24 -> 24209944 | M25: =L25-L24 -> 0 | N25: =M25+K25+I25+G25+E25 -> 0 | O25: =IF(B25>0,N25/B25,0) -> 0 | P25: =P24 -> 17086.036 | Q25: =(P25-P24)*1000 -> 0 | R25: =N25-Q25 -> 0 | S25: =S24 -> 10175 | T25: =S25-S24 -> 0 | U25: =U24 -> 429166 | V25: =U25-U24 -> 0 | W25: =W24 -> 32397 | X25: =W25-W24 -> 0 | Y25: =Y24 -> 740914 | Z25: =Y25-Y24 -> 0 | AA25: =AA24 -> 35939 | AB25: =AA25-AA24 -> 0 | AC25: =AC24 -> 961645 | AD25: =AC25-AC24 -> 0 | AE25: =AB25+X25+T25 -> 0 | AF25: =V25+Z25+AD25 -> 0 | AG25: =IF(AE25>0,AF25/AE25,0) -> 0 | AI25: =R25-'EDl log'!B23 -> -1043337 | AK25: 44339 | AL25: =AL24 -> 304137 | AM25: =AM24 -> 423438 | AN25: =AM25+AL25 -> 727575 | AO25: =AN25-AN24 -> 0
A26: ='General information '!F29 -> 0 | B26: =SUM(230*A26) -> 0 | C26: 44340 | D26: =D25+AO26 -> 32874062 | E26: =D26-D25 -> 0 | F26: =F25 -> 4022730 | G26: =F26-F25 -> 0 | H26: =H25 -> 17873314 | I26: =H26-H25 -> 0 | J26: =J25 -> 29060818 | K26: =J26-J25 -> 0 | L26: =L25 -> 24209944 | M26: =L26-L25 -> 0 | N26: =M26+K26+I26+G26+E26 -> 0 | O26: =IF(B26>0,N26/B26,0) -> 0 | P26: =P25 -> 17086.036 | Q26: =(P26-P25)*1000 -> 0 | R26: =N26-Q26 -> 0 | S26: =S25 -> 10175 | T26: =S26-S25 -> 0 | U26: =U25 -> 429166 | V26: =U26-U25 -> 0 | W26: =W25 -> 32397 | X26: =W26-W25 -> 0 | Y26: =Y25 -> 740914 | Z26: =Y26-Y25 -> 0 | AA26: =AA25 -> 35939 | AB26: =AA26-AA25 -> 0 | AC26: =AC25 -> 961645 | AD26: =AC26-AC25 -> 0 | AE26: =AB26+X26+T26 -> 0 | AF26: =V26+Z26+AD26 -> 0 | AG26: =IF(AE26>0,AF26/AE26,0) -> 0 | AI26: =R26-'EDl log'!B24 -> -1043337 | AK26: 44340 | AL26: =AL25 -> 304137 | AM26: =AM25 -> 423438 | AN26: =AM26+AL26 -> 727575 | AO26: =AN26-AN25 -> 0
A27: ='General information '!F30 -> 0 | B27: =SUM(230*A27) -> 0 | C27: 44341 | D27: =D26+AO27 -> 32874062 | E27: =D27-D26 -> 0 | F27: =F26 -> 4022730 | G27: =F27-F26 -> 0 | H27: =H26 -> 17873314 | I27: =H27-H26 -> 0 | J27: =J26 -> 29060818 | K27: =J27-J26 -> 0 | L27: =L26 -> 24209944 | M27: =L27-L26 -> 0 | N27: =M27+K27+I27+G27+E27 -> 0 | O27: =IF(B27>0,N27/B27,0) -> 0 | P27: =P26 -> 17086.036 | Q27: =(P27-P26)*1000 -> 0 | R27: =N27-Q27 -> 0 | S27: =S26 -> 10175 | T27: =S27-S26 -> 0 | U27: =U26 -> 429166 | V27: =U27-U26 -> 0 | W27: =W26 -> 32397 | X27: =W27-W26 -> 0 | Y27: =Y26 -> 740914 | Z27: =Y27-Y26 -> 0 | AA27: =AA26 -> 35939 | AB27: =AA27-AA26 -> 0 | AC27: =AC26 -> 961645 | AD27: =AC27-AC26 -> 0 | AE27: =AB27+X27+T27 -> 0 | AF27: =V27+Z27+AD27 -> 0 | AG27: =IF(AE27>0,AF27/AE27,0) -> 0 | AI27: =R27-'EDl log'!B25 -> -1043337 | AK27: 44341 | AL27: =AL26 -> 304137 | AM27: =AM26 -> 423438 | AN27: =AM27+AL27 -> 727575 | AO27: =AN27-AN26 -> 0
A28: ='General information '!F31 -> 0 | B28: =SUM(230*A28) -> 0 | C28: 44342 | D28: =D27+AO28 -> 32874062 | E28: =D28-D27 -> 0 | F28: =F27 -> 4022730 | G28: =F28-F27 -> 0 | H28: =H27 -> 17873314 | I28: =H28-H27 -> 0 | J28: =J27 -> 29060818 | K28: =J28-J27 -> 0 | L28: =L27 -> 24209944 | M28: =L28-L27 -> 0 | N28: =M28+K28+I28+G28+E28 -> 0 | O28: =IF(B28>0,N28/B28,0) -> 0 | P28: =P27 -> 17086.036 | Q28: =(P28-P27)*1000 -> 0 | R28: =N28-Q28 -> 0 | S28: =S27 -> 10175 | T28: =S28-S27 -> 0 | U28: =U27 -> 429166 | V28: =U28-U27 -> 0 | W28: =W27 -> 32397 | X28: =W28-W27 -> 0 | Y28: =Y27 -> 740914 | Z28: =Y28-Y27 -> 0 | AA28: =AA27 -> 35939 | AB28: =AA28-AA27 -> 0 | AC28: =AC27 -> 961645 | AD28: =AC28-AC27 -> 0 | AE28: =AB28+X28+T28 -> 0 | AF28: =V28+Z28+AD28 -> 0 | AG28: =IF(AE28>0,AF28/AE28,0) -> 0 | AI28: =R28-'EDl log'!B26 -> -1043337 | AK28: 44342 | AL28: =AL27 -> 304137 | AM28: =AM27 -> 423438 | AN28: =AM28+AL28 -> 727575 | AO28: =AN28-AN27 -> 0
A29: ='General information '!F32 -> 0 | B29: =SUM(230*A29) -> 0 | C29: 44343 | D29: =D28+AO29 -> 32874062 | E29: =D29-D28 -> 0 | F29: =F28 -> 4022730 | G29: =F29-F28 -> 0 | H29: =H28 -> 17873314 | I29: =H29-H28 -> 0 | J29: =J28 -> 29060818 | K29: =J29-J28 -> 0 | L29: =L28 -> 24209944 | M29: =L29-L28 -> 0 | N29: =M29+K29+I29+G29+E29 -> 0 | O29: =IF(B29>0,N29/B29,0) -> 0 | P29: =P28 -> 17086.036 | Q29: =(P29-P28)*1000 -> 0 | R29: =N29-Q29 -> 0 | S29: =S28 -> 10175 | T29: =S29-S28 -> 0 | U29: =U28 -> 429166 | V29: =U29-U28 -> 0 | W29: =W28 -> 32397 | X29: =W29-W28 -> 0 | Y29: =Y28 -> 740914 | Z29: =Y29-Y28 -> 0 | AA29: =AA28 -> 35939 | AB29: =AA29-AA28 -> 0 | AC29: =AC28 -> 961645 | AD29: =AC29-AC28 -> 0 | AE29: =AB29+X29+T29 -> 0 | AF29: =V29+Z29+AD29 -> 0 | AG29: =IF(AE29>0,AF29/AE29,0) -> 0 | AI29: =R29-'EDl log'!B27 -> -1043337 | AK29: 44343 | AL29: =AL28 -> 304137 | AM29: =AM28 -> 423438 | AN29: =AM29+AL29 -> 727575 | AO29: =AN29-AN28 -> 0
A30: ='General information '!F33 -> 0 | B30: =SUM(230*A30) -> 0 | C30: 44344 | D30: =D29+AO30 -> 32874062 | E30: =D30-D29 -> 0 | F30: =F29 -> 4022730 | G30: =F30-F29 -> 0 | H30: =H29 -> 17873314 | I30: =H30-H29 -> 0 | J30: =J29 -> 29060818 | K30: =J30-J29 -> 0 | L30: =L29 -> 24209944 | M30: =L30-L29 -> 0 | N30: =M30+K30+I30+G30+E30 -> 0 | O30: =IF(B30>0,N30/B30,0) -> 0 | P30: =P29 -> 17086.036 | Q30: =(P30-P29)*1000 -> 0 | R30: =N30-Q30 -> 0 | S30: =S29 -> 10175 | T30: =S30-S29 -> 0 | U30: =U29 -> 429166 | V30: =U30-U29 -> 0 | W30: =W29 -> 32397 | X30: =W30-W29 -> 0 | Y30: =Y29 -> 740914 | Z30: =Y30-Y29 -> 0 | AA30: =AA29 -> 35939 | AB30: =AA30-AA29 -> 0 | AC30: =AC29 -> 961645 | AD30: =AC30-AC29 -> 0 | AE30: =AB30+X30+T30 -> 0 | AF30: =V30+Z30+AD30 -> 0 | AG30: =IF(AE30>0,AF30/AE30,0) -> 0 | AI30: =R30-'EDl log'!B28 -> -1043337 | AK30: 44344 | AL30: =AL29 -> 304137 | AM30: =AM29 -> 423438 | AN30: =AM30+AL30 -> 727575 | AO30: =AN30-AN29 -> 0
A31: ='General information '!F34 -> 0 | B31: =SUM(230*A31) -> 0 | C31: 44345 | D31: =D30+AO31 -> 32874062 | E31: =D31-D30 -> 0 | F31: =F30 -> 4022730 | G31: =F31-F30 -> 0 | H31: =H30 -> 17873314 | I31: =H31-H30 -> 0 | J31: =J30 -> 29060818 | K31: =J31-J30 -> 0 | L31: =L30 -> 24209944 | M31: =L31-L30 -> 0 | N31: =M31+K31+I31+G31+E31 -> 0 | O31: =IF(B31>0,N31/B31,0) -> 0 | P31: =P30 -> 17086.036 | Q31: =(P31-P30)*1000 -> 0 | R31: =N31-Q31 -> 0 | S31: =S30 -> 10175 | T31: =S31-S30 -> 0 | U31: =U30 -> 429166 | V31: =U31-U30 -> 0 | W31: =W30 -> 32397 | X31: =W31-W30 -> 0 | Y31: =Y30 -> 740914 | Z31: =Y31-Y30 -> 0 | AA31: =AA30 -> 35939 | AB31: =AA31-AA30 -> 0 | AC31: =AC30 -> 961645 | AD31: =AC31-AC30 -> 0 | AE31: =AB31+X31+T31 -> 0 | AF31: =V31+Z31+AD31 -> 0 | AG31: =IF(AE31>0,AF31/AE31,0) -> 0 | AI31: =R31-'EDl log'!B29 -> -1043337 | AK31: 44345 | AL31: =AL30 -> 304137 | AM31: =AM30 -> 423438 | AN31: =AM31+AL31 -> 727575 | AO31: =AN31-AN30 -> 0
A32: ='General information '!F35 -> 0 | B32: =SUM(230*A32) -> 0 | C32: 44346 | D32: =D31+AO32 -> 32874062 | E32: =D32-D31 -> 0 | F32: =F31 -> 4022730 | G32: =F32-F31 -> 0 | H32: =H31 -> 17873314 | I32: =H32-H31 -> 0 | J32: =J31 -> 29060818 | K32: =J32-J31 -> 0 | L32: =L31 -> 24209944 | M32: =L32-L31 -> 0 | N32: =M32+K32+I32+G32+E32 -> 0 | O32: =IF(B32>0,N32/B32,0) -> 0 | P32: =P31 -> 17086.036 | Q32: =(P32-P31)*1000 -> 0 | R32: =N32-Q32 -> 0 | S32: =S31 -> 10175 | T32: =S32-S31 -> 0 | U32: =U31 -> 429166 | V32: =U32-U31 -> 0 | W32: =W31 -> 32397 | X32: =W32-W31 -> 0 | Y32: =Y31 -> 740914 | Z32: =Y32-Y31 -> 0 | AA32: =AA31 -> 35939 | AB32: =AA32-AA31 -> 0 | AC32: =AC31 -> 961645 | AD32: =AC32-AC31 -> 0 | AE32: =AB32+X32+T32 -> 0 | AF32: =V32+Z32+AD32 -> 0 | AG32: =IF(AE32>0,AF32/AE32,0) -> 0 | AI32: =R32-'EDl log'!B30 -> -1043337 | AK32: 44346 | AL32: =AL31 -> 304137 | AM32: =AM31 -> 423438 | AN32: =AM32+AL32 -> 727575 | AO32: =AN32-AN31 -> 0
A33: ='General information '!F36 -> 0 | B33: =SUM(230*A33) -> 0 | C33: 44347 | D33: =D32+AO33 -> 32874062 | E33: =D33-D32 -> 0 | F33: =F32 -> 4022730 | G33: =F33-F32 -> 0 | H33: =H32 -> 17873314 | I33: =H33-H32 -> 0 | J33: =J32 -> 29060818 | K33: =J33-J32 -> 0 | L33: =L32 -> 24209944 | M33: =L33-L32 -> 0 | N33: =M33+K33+I33+G33+E33 -> 0 | O33: =IF(B33>0,N33/B33,0) -> 0 | P33: =P32 -> 17086.036 | Q33: =(P33-P32)*1000 -> 0 | R33: =N33-Q33 -> 0 | S33: =S32 -> 10175 | T33: =S33-S32 -> 0 | U33: =U32 -> 429166 | V33: =U33-U32 -> 0 | W33: =W32 -> 32397 | X33: =W33-W32 -> 0 | Y33: =Y32 -> 740914 | Z33: =Y33-Y32 -> 0 | AA33: =AA32 -> 35939 | AB33: =AA33-AA32 -> 0 | AC33: =AC32 -> 961645 | AD33: =AC33-AC32 -> 0 | AE33: =AB33+X33+T33 -> 0 | AF33: =V33+Z33+AD33 -> 0 | AG33: =IF(AE33>0,AF33/AE33,0) -> 0 | AI33: =R33-'EDl log'!B31 -> -1043337 | AK33: 44347 | AL33: =AL32 -> 304137 | AM33: =AM32 -> 423438 | AN33: =AM33+AL33 -> 727575 | AO33: =AN33-AN32 -> 0

Sheet B5
F1: Boiler A | J1: =J36 -> 64.777778 | K1: Boiler B | P1: Boiler C | V1: Boiler | X1: SteamA | AC1: SteamB | AH1: Steam | AI1: Boiler & steam | AL1: Total Boiler Runing H | AM1: Total Steam Runing H | AN1: GAS1 % | AO1: GAS1/L | AP1: GAS2% | AQ1: Gas2/L | AR1: GAS3% | AS1: GAS3/L | AU1: Gas Cons | AV1: Delivery | AW1: Cost/L
B2: Level Tank Gen | C2: Level tank Boiler | D2: Daily Cons Bo. | E2: Boiler litter | F2: Boiler A | G2: Run Hr a | H2: Boiler A fuel | I2: Daily consumption | J2: AVG | K2: index Run H | L2: Run Hrb | M2: Boiler B Fuel | O2: Daily consumption | P2: Boiler C | S2: Run C | U2: Total RH | V2: Total Fuel | X2: SteamA | Y2: Run SA | Z2: Steam A Conter | AA2: Liters | AC2: SteamB | AD2: Run SteamB | AE2: Steam B Conter | AF2: SB Litters | AG2: Avg | AH2: Total Fuel | AI2: Total Fuel
S3: 0
A4: =ELEC!C2 -> 44316 | B4: 239 | C4: 245 | D4: 6 | E4: 50.28 | F4: 1825 | G4: 1 | H4: 12185 | I4: 98 | J4: 98 | K4: 2315 | L4: 0 | M4: 170600 | N4: 0 | O4: 1869 | P4: 2079 | Q4: 174883 | R4: 71 | S4: 1 | T4: 0 | U4: 2 | V4: 169 | X4: 2467 | Y4: 0 | Z4: 138841 | AA4: 0 | AB4: 0 | AC4: 1936 | AD4: 0 | AE4: 365520.8 | AF4: 0 | AG4: 0 | AH4: 0 | AI4: 169 | AJ4: 169 | AK4: 0 | AL4: 2 | AM4: 0 | AN4: 67 | AO4: 2010 | AP4: 55 | AQ4: 1650 | AR4: 61 | AS4: 1830 | AT4: 5490 | AU4: 0 | AX4: =[1]B5!AX35 -> 0.8
A5: =ELEC!C3 -> 44317 | B5: 234 | C5: 240 | D5: =C4-C5 -> 5 | E5: =D5*8.38 -> 41.9 | F5: 1825 | G5: =F5-F4 -> 0 | H5: 12220 | I5: =SUM(H5-H4) -> 35 | J5: 1 | K5: 2315 | L5: =K5-K4 -> 0 | M5: 170650 | N5: =M5-M4 -> 50 | O5: =O4 -> 1869 | P5: 2080 | Q5: 174993 | R5: =Q5-Q4 -> 110 | S5: =SUM(P5-P4) -> 1 | T5: =SUM(S5*$T$2) -> 0 | U5: =SUM(G5+L5+S5) -> 1 | V5: =R5+N5+I5:I5 -> 195 | W5: =SUM(V5/U5) -> 195 | X5: =X4 -> 2467 | Y5: =X5-X4 -> 0 | Z5: =Z4 -> 138841 | AA5: =Z5-Z4 -> 0 | AB5: =SUM(Y5*$AB$2) -> 0 | AC5: =AC4 -> 1936 | AD5: =AC5-AC4 -> 0 | AE5: =AE4 -> 365520.8 | AF5: =AE5-AE4 -> 0 | AG5: =IF(AD5>0,AF5/AD5,0) -> 0 | AH5: =AF5+AA5 -> 0 | AI5: =SUM(AH5+V5) -> 195 | AJ5: =-tanks!AW6 -> 195 | AK5: =SUM(AJ5-AI5) -> 0 | AL5: =S5+L5+G5 -> 1 | AM5: =Y5+AD5 -> 0 | AN5: =AN4 -> 67 | AO5: =(AN5/100)*3000 -> 2010 | AP5: =AP4 -> 55 | AQ5: =(AP5/100)*3000 -> 1650 | AR5: =AR4 -> 61 | AS5: =(AR5/100)*3000 -> 1830 | AT5: =SUM(AO5+AQ5+AS5) -> 5490 | AU5: =AT4-AT5+AV5 -> 0 | AX5: =IF(AV5>0,AW5,AX4) -> 0.8
A6: =ELEC!C4 -> 44318 | B6: 231 | C6: 238 | D6: =C5-C6 -> 2 | E6: =D6*8.38 -> 16.76 | F6: =F5 -> 1825 | G6: =F6-F5 -> 0 | H6: =H5 -> 12220 | I6: =SUM(H6-H5) -> 0 | J6: =IF(G6>0,I6/G6,0) -> 0 | K6: 2316 | L6: =K6-K5 -> 1 | M6: 170693 | N6: =M6-M5 -> 43 | O6: =O5 -> 1869 | P6: 2081 | Q6: 175103 | R6: =Q6-Q5 -> 110 | S6: =SUM(P6-P5) -> 1 | T6: =SUM(S6*$T$2) -> 0 | U6: =SUM(G6+L6+S6) -> 2 | V6: =R6+N6+I6:I6 -> 153 | W6: =SUM(V6/U6) -> 76.5 | X6: =X5 -> 2467 | Y6: =X6-X5 -> 0 | Z6: =Z5 -> 138841 | AA6: =Z6-Z5 -> 0 | AB6: =SUM(Y6*$AB$2) -> 0 | AC6: =AC5 -> 1936 | AD6: =AC6-AC5 -> 0 | AE6: =AE5 -> 365520.8 | AF6: =AE6-AE5 -> 0 | AG6: =IF(AD6>0,AF6/AD6,0) -> 0 | AH6: =AF6+AA6 -> 0 | AI6: =SUM(AH6+V6) -> 153 | AJ6: =-tanks!AW7 -> 153 | AK6: =SUM(AJ6-AI6) -> 0 | AL6: =S6+L6+G6 -> 2 | AM6: =Y6+AD6 -> 0 | AN6: =AN5 -> 67 | AO6: =(AN6/100)*3000 -> 2010 | AP6: =AP5 -> 55 | AQ6: =(AP6/100)*3000 -> 1650 | AR6: =AR5 -> 61 | AS6: =(AR6/100)*3000 -> 1830 | AT6: =SUM(AO6+AQ6+AS6) -> 5490 | AU6: =AT5-AT6+AV6 -> 0 | AX6: =IF(AV6>0,AW6,AX5) -> 0.8
A7: =ELEC!C5 -> 44319 | B7: 228 | C7: 234 | D7: =C6-C7 -> 4 | E7: =D7*8.38 -> 33.52 | F7: 1827 | G7: =F7-F6 -> 2 | H7: 12328 | I7: =SUM(H7-H6) -> 108 | J7: =IF(G7>0,I7/G7,0) -> 54 | K7: =K6 -> 2316 | L7: =K7-K6 -> 0 | M7: =M6 -> 170693 | N7: =M7-M6 -> 0 | O7: =O6 -> 1869 | P7: 2082 | Q7: 175136 | R7: =Q7-Q6 -> 33 | S7: =SUM(P7-P6) -> 1 | T7: =SUM(S7*$T$2) -> 0 | U7: =SUM(G7+L7+S7) -> 3 | V7: =R7+N7+I7:I7 -> 141 | W7: =SUM(V7/U7) -> 47 | X7: =X6 -> 2467 | Y7: =X7-X6 -> 0 | Z7: =Z6 -> 138841 | AA7: =Z7-Z6 -> 0 | AB7: =SUM(Y7*$AB$2) -> 0 | AC7: =AC6 -> 1936 | AD7: =AC7-AC6 -> 0 | AE7: =AE6 -> 365520.8 | AF7: =AE7-AE6 -> 0 | AG7: =IF(AD7>0,AF7/AD7,0) -> 0 | AH7: =AF7+AA7 -> 0 | AI7: =SUM(AH7+V7) -> 141 | AJ7: =-tanks!AW8 -> 141 | AK7: =SUM(AJ7-AI7) -> 0 | AL7: =S7+L7+G7 -> 3 | AM7: =Y7+AD7 -> 0 | AN7: =AN6 -> 67 | AO7: =(AN7/100)*3000 -> 2010 | AP7: =AP6 -> 55 | AQ7: =(AP7/100)*3000 -> 1650 | AR7: =AR6 -> 61 | AS7: =(AR7/100)*3000 -> 1830 | AT7: =SUM(AO7+AQ7+AS7) -> 5490 | AU7: =AT6-AT7+AV7 -> 0 | AX7: =IF(AV7>0,AW7,AX6) -> 0.8
A8: =ELEC!C6 -> 44320 | B8: 222 | C8: 229 | D8: =C7-C8 -> 5 | E8: =D8*8.38 -> 41.9 | F8: =F7 -> 1827 | G8: =F8-F7 -> 0 | H8: =H7 -> 12328 | I8: =SUM(H8-H7) -> 0 | J8: =IF(G8>0,I8/G8,0) -> 0 | K8: 2317 | L8: =K8-K7 -> 1 | M8: 170788 | N8: =M8-M7 -> 95 | O8: =O7 -> 1869 | P8: =P7 -> 2082 | Q8: =Q7 -> 175136 | R8: =Q8-Q7 -> 0 | S8: =SUM(P8-P7) -> 0 | T8: =SUM(S8*$T$2) -> 0 | U8: =SUM(G8+L8+S8) -> 1 | V8: =R8+N8+I8:I8 -> 95 | W8: =SUM(V8/U8) -> 95 | X8: =X7 -> 2467 | Y8: =X8-X7 -> 0 | Z8: =Z7 -> 138841 | AA8: =Z8-Z7 -> 0 | AB8: =SUM(Y8*$AB$2) -> 0 | AC8: =AC7 -> 1936 | AD8: =AC8-AC7 -> 0 | AE8: =AE7 -> 365520.8 | AF8: =AE8-AE7 -> 0 | AG8: =IF(AD8>0,AF8/AD8,0) -> 0 | AH8: =AF8+AA8 -> 0 | AI8: =SUM(AH8+V8) -> 95 | AJ8: =-tanks!AW9 -> 95 | AK8: =SUM(AJ8-AI8) -> 0 | AL8: =S8+L8+G8 -> 1 | AM8: =Y8+AD8 -> 0 | AN8: =AN7 -> 67 | AO8: =(AN8/100)*3000 -> 2010 | AP8: =AP7 -> 55 | AQ8: =(AP8/100)*3000 -> 1650 | AR8: =AR7 -> 61 | AS8: =(AR8/100)*3000 -> 1830 | AT8: =SUM(AO8+AQ8+AS8) -> 5490 | AU8: =AT7-AT8+AV8 -> 0 | AX8: =IF(AV8>0,AW8,AX7) -> 0.8
A9: =ELEC!C7 -> 44321 | B9: 216 | C9: 222 | D9: =C8-C9 -> 7 | E9: =D9*8.38 -> 58.66 | F9: =F8 -> 1827 | G9: =F9-F8 -> 0 | H9: =H8 -> 12328 | I9: =SUM(H9-H8) -> 0 | J9: =IF(G9>0,I9/G9,0) -> 0 | K9: 2318 | L9: =K9-K8 -> 1 | M9: 170851 | N9: =M9-M8 -> 63 | O9: =O8 -> 1869 | P9: 2083 | Q9: 175237 | R9: =Q9-Q8 -> 101 | S9: =SUM(P9-P8) -> 1 | T9: =SUM(S9*$T$2) -> 0 | U9: =SUM(G9+L9+S9) -> 2 | V9: =R9+N9+I9:I9 -> 164 | W9: =SUM(V9/U9) -> 82 | X9: =X8 -> 2467 | Y9: =X9-X8 -> 0 | Z9: =Z8 -> 138841 | AA9: =Z9-Z8 -> 0 | AB9: =SUM(Y9*$AB$2) -> 0 | AC9: =AC8 -> 1936 | AD9: =AC9-AC8 -> 0 | AE9: =AE8 -> 365520.8 | AF9: =AE9-AE8 -> 0 | AG9: =IF(AD9>0,AF9/AD9,0) -> 0 | AH9: =AF9+AA9 -> 0 | AI9: =SUM(AH9+V9) -> 164 | AJ9: =-tanks!AW10 -> 164 | AK9: =SUM(AJ9-AI9) -> 0 | AL9: =S9+L9+G9 -> 2 | AM9: =Y9+AD9 -> 0 | AN9: =AN8 -> 67 | AO9: =(AN9/100)*3000 -> 2010 | AP9: =AP8 -> 55 | AQ9: =(AP9/100)*3000 -> 1650 | AR9: =AR8 -> 61 | AS9: =(AR9/100)*3000 -> 1830 | AT9: =SUM(AO9+AQ9+AS9) -> 5490 | AU9: =AT8-AT9+AV9 -> 0 | AX9: =IF(AV9>0,AW9,AX8) -> 0.8
A10: =ELEC!C8 -> 44322 | B10: 212 | C10: 219 | D10: =C9-C10 -> 3 | E10: =D10*8.38 -> 25.14 | F10: 1828 | G10: =F10-F9 -> 1 | H10: 12442 | I10: =SUM(H10-H9) -> 114 | J10: =IF(G10>0,I10/G10,0) -> 114 | K10: =K9 -> 2318 | L10: =K10-K9 -> 0 | M10: =M9 -> 170851 | N10: =M10-M9 -> 0 | O10: =O9 -> 1869 | P10: 2084 | Q10: 175278 | R10: =Q10-Q9 -> 41 | S10: =SUM(P10-P9) -> 1 | T10: =SUM(S10*$T$2) -> 0 | U10: =SUM(G10+L10+S10) -> 2 | V10: =R10+N10+I10:I10 -> 155 | W10: =SUM(V10/U10) -> 77.5 | X10: =X9 -> 2467 | Y10: =X10-X9 -> 0 | Z10: =Z9 -> 138841 | AA10: =Z10-Z9 -> 0 | AB10: =SUM(Y10*$AB$2) -> 0 | AC10: =AC9 -> 1936 | AD10: =AC10-AC9 -> 0 | AE10: =AE9 -> 365520.8 | AF10: =AE10-AE9 -> 0 | AG10: =IF(AD10>0,AF10/AD10,0) -> 0 | AH10: =AF10+AA10 -> 0 | AI10: =SUM(AH10+V10) -> 155 | AJ10: =-tanks!AW11 -> 155 | AK10: =SUM(AJ10-AI10) -> 0 | AL10: =S10+L10+G10 -> 2 | AM10: =Y10+AD10 -> 0 | AN10: =AN9 -> 67 | AO10: =(AN10/100)*3000 -> 2010 | AP10: =AP9 -> 55 | AQ10: =(AP10/100)*3000 -> 1650 | AR10: =AR9 -> 61 | AS10: =(AR10/100)*3000 -> 1830 | AT10: =SUM(AO10+AQ10+AS10) -> 5490 | AU10: =AT9-AT10+AV10 -> 0 | AX10: =IF(AV10>0,AW10,AX9) -> 0.8
A11: =ELEC!C9 -> 44323 | B11: 205 | C11: 212 | D11: =C10-C11 -> 7 | E11: =D11*8.38 -> 58.66 | F11: 1829 | G11: =F11-F10 -> 1 | H11: 12491 | I11: =SUM(H11-H10) -> 49 | J11: =IF(G11>0,I11/G11,0) -> 49 | K11: 2319 | L11: =K11-K10 -> 1 | M11: 170968 | N11: =M11-M10 -> 117 | O11: =O10 -> 1869 | P11: =P10 -> 2084 | Q11: =Q10 -> 175278 | R11: =Q11-Q10 -> 0 | S11: =SUM(P11-P10) -> 0 | T11: =SUM(S11*$T$2) -> 0 | U11: =SUM(G11+L11+S11) -> 2 | V11: =R11+N11+I11:I11 -> 166 | W11: =SUM(V11/U11) -> 83 | X11: =X10 -> 2467 | Y11: =X11-X10 -> 0 | Z11: =Z10 -> 138841 | AA11: =Z11-Z10 -> 0 | AB11: =SUM(Y11*$AB$2) -> 0 | AC11: =AC10 -> 1936 | AD11: =AC11-AC10 -> 0 | AE11: =AE10 -> 365520.8 | AF11: =AE11-AE10 -> 0 | AG11: =IF(AD11>0,AF11/AD11,0) -> 0 | AH11: =AF11+AA11 -> 0 | AI11: =SUM(AH11+V11) -> 166 | AJ11: =-tanks!AW12 -> 166 | AK11: =SUM(AJ11-AI11) -> 0 | AL11: =S11+L11+G11 -> 2 | AM11: =Y11+AD11 -> 0 | AN11: =AN10 -> 67 | AO11: =(AN11/100)*3000 -> 2010 | AP11: =AP10 -> 55 | AQ11: =(AP11/100)*3000 -> 1650 | AR11: =AR10 -> 61 | AS11: =(AR11/100)*3000 -> 1830 | AT11: =SUM(AO11+AQ11+AS11) -> 5490 | AU11: =AT10-AT11+AV11 -> 0 | AX11: =IF(AV11>0,AW11,AX10) -> 0.8
A12: =ELEC!C10 -> 44324 | B12: 198 | C12: 205 | D12: =C11-C12 -> 7 | E12: =D12*8.38 -> 58.66 | F12: =F11 -> 1829 | G12: =F12-F11 -> 0 | H12: =H11 -> 12491 | I12: =SUM(H12-H11) -> 0 | J12: =IF(G12>0,I12/G12,0) -> 0 | K12: 2320 | L12: =K12-K11 -> 1 | M12: 171004 | N12: =M12-M11 -> 36 | O12: =O11 -> 1869 | P12: 2085 | Q12: 175398 | R12: =Q12-Q11 -> 120 | S12: =SUM(P12-P11) -> 1 | T12: =SUM(S12*$T$2) -> 0 | U12: =SUM(G12+L12+S12) -> 2 | V12: =R12+N12+I12:I12 -> 156 | W12: =SUM(V12/U12) -> 78 | X12: =X11 -> 2467 | Y12: =X12-X11 -> 0 | Z12: =Z11 -> 138841 | AA12: =Z12-Z11 -> 0 | AB12: =SUM(Y12*$AB$2) -> 0 | AC12: =AC11 -> 1936 | AD12: =AC12-AC11 -> 0 | AE12: =AE11 -> 365520.8 | AF12: =AE12-AE11 -> 0 | AG12: =IF(AD12>0,AF12/AD12,0) -> 0 | AH12: =AF12+AA12 -> 0 | AI12: =SUM(AH12+V12) -> 156 | AJ12: =-tanks!AW13 -> 156 | AK12: =SUM(AJ12-AI12) -> 0 | AL12: =S12+L12+G12 -> 2 | AM12: =Y12+AD12 -> 0 | AN12: =AN11 -> 67 | AO12: =(AN12/100)*3000 -> 2010 | AP12: =AP11 -> 55 | AQ12: =(AP12/100)*3000 -> 1650 | AR12: =AR11 -> 61 | AS12: =(AR12/100)*3000 -> 1830 | AT12: =SUM(AO12+AQ12+AS12) -> 5490 | AU12: =AT11-AT12+AV12 -> 0 | AX12: =IF(AV12>0,AW12,AX11) -> 0.8
A13: =ELEC!C11 -> 44325 | B13: 192 | C13: 198 | D13: =C12-C13 -> 7 | E13: =D13*8.38 -> 58.66 | F13: 1830 | G13: =F13-F12 -> 1 | H13: 12563 | I13: =SUM(H13-H12) -> 72 | J13: =IF(G13>0,I13/G13,0) -> 72 | K13: =K12 -> 2320 | L13: =K13-K12 -> 0 | M13: =M12 -> 171004 | N13: =M13-M12 -> 0 | O13: =O12 -> 1869 | P13: 2086 | Q13: 175438 | R13: =Q13-Q12 -> 40 | S13: =SUM(P13-P12) -> 1 | T13: =SUM(S13*$T$2) -> 0 | U13: =SUM(G13+L13+S13) -> 2 | V13: =R13+N13+I13:I13 -> 112 | W13: =SUM(V13/U13) -> 56 | X13: =X12 -> 2467 | Y13: =X13-X12 -> 0 | Z13: =Z12 -> 138841 | AA13: =Z13-Z12 -> 0 | AB13: =SUM(Y13*$AB$2) -> 0 | AC13: =AC12 -> 1936 | AD13: =AC13-AC12 -> 0 | AE13: =AE12 -> 365520.8 | AF13: =AE13-AE12 -> 0 | AG13: =IF(AD13>0,AF13/AD13,0) -> 0 | AH13: =AF13+AA13 -> 0 | AI13: =SUM(AH13+V13) -> 112 | AJ13: =-tanks!AW14 -> 112 | AK13: =SUM(AJ13-AI13) -> 0 | AL13: =S13+L13+G13 -> 2 | AM13: =Y13+AD13 -> 0 | AN13: =AN12 -> 67 | AO13: =(AN13/100)*3000 -> 2010 | AP13: =AP12 -> 55 | AQ13: =(AP13/100)*3000 -> 1650 | AR13: =AR12 -> 61 | AS13: =(AR13/100)*3000 -> 1830 | AT13: =SUM(AO13+AQ13+AS13) -> 5490 | AU13: =AT12-AT13+AV13 -> 0 | AX13: =IF(AV13>0,AW13,AX12) -> 0.8
A14: =ELEC!C12 -> 44326 | B14: 184 | C14: 192 | D14: =C13-C14 -> 6 | E14: =D14*8.38 -> 50.28 | F14: =F13 -> 1830 | G14: =F14-F13 -> 0 | H14: =H13 -> 12563 | I14: =SUM(H14-H13) -> 0 | J14: =IF(G14>0,I14/G14,0) -> 0 | K14: 2321 | L14: =K14-K13 -> 1 | M14: 171086 | N14: =M14-M13 -> 82 | O14: =O13 -> 1869 | P14: =P13 -> 2086 | Q14: =Q13 -> 175438 | R14: =Q14-Q13 -> 0 | S14: =SUM(P14-P13) -> 0 | T14: =SUM(S14*$T$2) -> 0 | U14: =SUM(G14+L14+S14) -> 1 | V14: =R14+N14+I14:I14 -> 82 | W14: =SUM(V14/U14) -> 82 | X14: =X13 -> 2467 | Y14: =X14-X13 -> 0 | Z14: =Z13 -> 138841 | AA14: =Z14-Z13 -> 0 | AB14: =SUM(Y14*$AB$2) -> 0 | AC14: =AC13 -> 1936 | AD14: =AC14-AC13 -> 0 | AE14: =AE13 -> 365520.8 | AF14: =AE14-AE13 -> 0 | AG14: =IF(AD14>0,AF14/AD14,0) -> 0 | AH14: =AF14+AA14 -> 0 | AI14: =SUM(AH14+V14) -> 82 | AJ14: =-tanks!AW15 -> 82 | AK14: =SUM(AJ14-AI14) -> 0 | AL14: =S14+L14+G14 -> 1 | AM14: =Y14+AD14 -> 0 | AN14: =AN13 -> 67 | AO14: =(AN14/100)*3000 -> 2010 | AP14: =AP13 -> 55 | AQ14: =(AP14/100)*3000 -> 1650 | AR14: =AR13 -> 61 | AS14: =(AR14/100)*3000 -> 1830 | AT14: =SUM(AO14+AQ14+AS14) -> 5490 | AU14: =AT13-AT14+AV14 -> 0 | AX14: =IF(AV14>0,AW14,AX13) -> 0.8
A15: =ELEC!C13 -> 44327 | B15: 234 | C15: 241 | D15: =C14-C15 -> -49 | E15: =D15*8.38 -> -410.62 | F15: 1831 | G15: =F15-F14 -> 1 | H15: 12644 | I15: =SUM(H15-H14) -> 81 | J15: =IF(G15>0,I15/G15,0) -> 81 | K15: =K14 -> 2321 | L15: =K15-K14 -> 0 | M15: =M14 -> 171086 | N15: =M15-M14 -> 0 | O15: =O14 -> 1869 | P15: =P14 -> 2086 | Q15: =Q14 -> 175438 | R15: =Q15-Q14 -> 0 | S15: =SUM(P15-P14) -> 0 | T15: =SUM(S15*$T$2) -> 0 | U15: =SUM(G15+L15+S15) -> 1 | V15: =R15+N15+I15:I15 -> 81 | W15: =SUM(V15/U15) -> 81 | X15: =X14 -> 2467 | Y15: =X15-X14 -> 0 | Z15: 138897 | AA15: =Z15-Z14 -> 56 | AB15: =SUM(Y15*$AB$2) -> 0 | AC15: =AC14 -> 1936 | AD15: =AC15-AC14 -> 0 | AE15: =AE14 -> 365520.8 | AF15: =AE15-AE14 -> 0 | AG15: =IF(AD15>0,AF15/AD15,0) -> 0 | AH15: =AF15+AA15 -> 56 | AI15: =SUM(AH15+V15) -> 137 | AJ15: =-tanks!AW16 -> 137 | AK15: =SUM(AJ15-AI15) -> 0 | AL15: =S15+L15+G15 -> 1 | AM15: =Y15+AD15 -> 0 | AN15: =AN14 -> 67 | AO15: =(AN15/100)*3000 -> 2010 | AP15: =AP14 -> 55 | AQ15: =(AP15/100)*3000 -> 1650 | AR15: =AR14 -> 61 | AS15: =(AR15/100)*3000 -> 1830 | AT15: =SUM(AO15+AQ15+AS15) -> 5490 | AU15: =AT14-AT15+AV15 -> 0 | AX15: =IF(AV15>0,AW15,AX14) -> 0.8
A16: =ELEC!C14 -> 44328 | B16: 225 | C16: 232 | D16: =C15-C16 -> 9 | E16: =D16*8.38 -> 75.42 | F16: 1832 | G16: =F16-F15 -> 1 | H16: 12721 | I16: =SUM(H16-H15) -> 77 | J16: =IF(G16>0,I16/G16,0) -> 77 | K16: =K15 -> 2321 | L16: =K16-K15 -> 0 | M16: =M15 -> 171086 | N16: =M16-M15 -> 0 | O16: =O15 -> 1869 | P16: 2087 | Q16: 175515 | R16: =Q16-Q15 -> 77 | S16: =SUM(P16-P15) -> 1 | T16: =SUM(S16*$T$2) -> 0 | U16: =SUM(G16+L16+S16) -> 2 | V16: =R16+N16+I16:I16 -> 154 | W16: =SUM(V16/U16) -> 77 | X16: =X15 -> 2467 | Y16: =X16-X15 -> 0 | Z16: =Z15 -> 138897 | AA16: =Z16-Z15 -> 0 | AB16: =SUM(Y16*$AB$2) -> 0 | AC16: =AC15 -> 1936 | AD16: =AC16-AC15 -> 0 | AE16: =AE15 -> 365520.8 | AF16: =AE16-AE15 -> 0 | AG16: =IF(AD16>0,AF16/AD16,0) -> 0 | AH16: =AF16+AA16 -> 0 | AI16: =SUM(AH16+V16) -> 154 | AJ16: =-tanks!AW17 -> 154 | AK16: =SUM(AJ16-AI16) -> 0 | AL16: =S16+L16+G16 -> 2 | AM16: =Y16+AD16 -> 0 | AN16: =AN15 -> 67 | AO16: =(AN16/100)*3000 -> 2010 | AP16: =AP15 -> 55 | AQ16: =(AP16/100)*3000 -> 1650 | AR16: =AR15 -> 61 | AS16: =(AR16/100)*3000 -> 1830 | AT16: =SUM(AO16+AQ16+AS16) -> 5490 | AU16: =AT15-AT16+AV16 -> 0 | AX16: =IF(AV16>0,AW16,AX15) -> 0.8
A17: =ELEC!C15 -> 44329 | B17: 218 | C17: 224 | D17: =C16-C17 -> 8 | E17: =D17*8.38 -> 67.04 | F17: =F16 -> 1832 | G17: =F17-F16 -> 0 | H17: =H16 -> 12721 | I17: =SUM(H17-H16) -> 0 | J17: =IF(G17>0,I17/G17,0) -> 0 | K17: 2322 | L17: =K17-K16 -> 1 | M17: 171201 | N17: =M17-M16 -> 115 | O17: =O16 -> 1869 | P17: =P16 -> 2087 | Q17: =Q16 -> 175515 | R17: =Q17-Q16 -> 0 | S17: =SUM(P17-P16) -> 0 | T17: =SUM(S17*$T$2) -> 0 | U17: =SUM(G17+L17+S17) -> 1 | V17: =R17+N17+I17:I17 -> 115 | X17: =X16 -> 2467 | Y17: =X17-X16 -> 0 | Z17: =Z16 -> 138897 | AA17: =Z17-Z16 -> 0 | AB17: =SUM(Y17*$AB$2) -> 0 | AC17: =AC16 -> 1936 | AD17: =AC17-AC16 -> 0 | AE17: =AE16 -> 365520.8 | AF17: =AE17-AE16 -> 0 | AG17: =IF(AD17>0,AF17/AD17,0) -> 0 | AH17: =AF17+AA17 -> 0 | AI17: =SUM(AH17+V17) -> 115 | AJ17: =-tanks!AW18 -> 115 | AK17: =SUM(AJ17-AI17) -> 0 | AL17: =S17+L17+G17 -> 1 | AM17: =Y17+AD17 -> 0 | AN17: =AN16 -> 67 | AO17: =(AN17/100)*3000 -> 2010 | AP17: =AP16 -> 55 | AQ17: =(AP17/100)*3000 -> 1650 | AR17: =AR16 -> 61 | AS17: =(AR17/100)*3000 -> 1830 | AT17: =SUM(AO17+AQ17+AS17) -> 5490 | AU17: =AT16-AT17+AV17 -> 0 | AX17: =IF(AV17>0,AW17,AX16) -> 0.8
A18: =ELEC!C16 -> 44330 | B18: 212 | C18: 218 | D18: =C17-C18 -> 6 | E18: =D18*8.38 -> 50.28 | F18: =F17 -> 1832 | G18: =F18-F17 -> 0 | H18: =H17 -> 12721 | I18: =SUM(H18-H17) -> 0 | J18: =IF(G18>0,I18/G18,0) -> 0 | K18: =K17 -> 2322 | L18: =K18-K17 -> 0 | M18: =M17 -> 171201 | N18: =M18-M17 -> 0 | O18: 1869 | P18: 2088 | Q18: 175604 | R18: =Q18-Q17 -> 89 | S18: =SUM(P18-P17) -> 1 | T18: =SUM(S18*$T$2) -> 0 | U18: =SUM(G18+L18+S18) -> 1 | V18: =R18+N18+I18:I18 -> 89 | X18: =X17 -> 2467 | Y18: =X18-X17 -> 0 | Z18: =Z17 -> 138897 | AA18: =Z18-Z17 -> 0 | AB18: =SUM(Y18*$AB$2) -> 0 | AC18: =AC17 -> 1936 | AD18: =AC18-AC17 -> 0 | AE18: =AE17 -> 365520.8 | AF18: =AE18-AE17 -> 0 | AG18: =IF(AD18>0,AF18/AD18,0) -> 0 | AH18: =AF18+AA18 -> 0 | AI18: =SUM(AH18+V18) -> 89 | AJ18: =-tanks!AW19 -> 89 | AK18: =SUM(AJ18-AI18) -> 0 | AL18: =S18+L18+G18 -> 1 | AM18: =Y18+AD18 -> 0 | AN18: =AN17 -> 67 | AO18: =(AN18/100)*3000 -> 2010 | AP18: =AP17 -> 55 | AQ18: =(AP18/100)*3000 -> 1650 | AR18: =AR17 -> 61 | AS18: =(AR18/100)*3000 -> 1830 | AT18: =SUM(AO18+AQ18+AS18) -> 5490 | AU18: =AT17-AT18+AV18 -> 0 | AX18: =IF(AV18>0,AW18,AX17) -> 0.8
A19: =ELEC!C17 -> 44331 | B19: 206 | C19: 213 | D19: =C18-C19 -> 5 | E19: =D19*8.38 -> 41.9 | F19: 1833 | G19: =F19-F18 -> 1 | H19: 12810 | I19: =SUM(H19-H18) -> 89 | J19: =IF(G19>0,I19/G19,0) -> 89 | K19: =K18 -> 2322 | L19: =K19-K18 -> 0 | M19: =M18 -> 171201 | N19: =M19-M18 -> 0 | O19: =O18 -> 1869 | P19: 2089 | Q19: 175654 | R19: =Q19-Q18 -> 50 | S19: =SUM(P19-P18) -> 1 | T19: =SUM(S19*$T$2) -> 0 | U19: =SUM(G19+L19+S19) -> 2 | V19: =R19+N19+I19:I19 -> 139 | X19: =X18 -> 2467 | Y19: =X19-X18 -> 0 | Z19: =Z18 -> 138897 | AA19: =Z19-Z18 -> 0 | AB19: =SUM(Y19*$AB$2) -> 0 | AC19: =AC18 -> 1936 | AD19: =AC19-AC18 -> 0 | AE19: =AE18 -> 365520.8 | AF19: =AE19-AE18 -> 0 | AG19: =IF(AD19>0,AF19/AD19,0) -> 0 | AH19: =AF19+AA19 -> 0 | AI19: =SUM(AH19+V19) -> 139 | AJ19: =-tanks!AW20 -> 139 | AK19: =SUM(AJ19-AI19) -> 0 | AL19: =S19+L19+G19 -> 2 | AM19: =Y19+AD19 -> 0 | AN19: =AN18 -> 67 | AO19: =(AN19/100)*3000 -> 2010 | AP19: =AP18 -> 55 | AQ19: =(AP19/100)*3000 -> 1650 | AR19: =AR18 -> 61 | AS19: =(AR19/100)*3000 -> 1830 | AT19: =SUM(AO19+AQ19+AS19) -> 5490 | AU19: =AT18-AT19+AV19 -> 0 | AX19: =IF(AV19>0,AW19,AX18) -> 0.8
A20: =ELEC!C18 -> 44332 | B20: 195 | C20: 201 | D20: =C19-C20 -> 12 | E20: =D20*8.38 -> 100.56 | F20: =F19 -> 1833 | G20: =F20-F19 -> 0 | H20: 12841 | I20: =SUM(H20-H19) -> 31 | J20: =IF(G20>0,I20/G20,0) -> 0 | K20: 2323 | L20: =K20-K19 -> 1 | M20: 171285 | N20: =M20-M19 -> 84 | O20: =O19 -> 1869 | P20: =P19 -> 2089 | Q20: =Q19 -> 175654 | R20: =Q20-Q19 -> 0 | S20: =SUM(P20-P19) -> 0 | T20: =SUM(S20*$T$2) -> 0 | U20: =SUM(G20+L20+S20) -> 1 | V20: =R20+N20+I20:I20 -> 115 | X20: =X19 -> 2467 | Y20: =X20-X19 -> 0 | Z20: =Z19 -> 138897 | AA20: =Z20-Z19 -> 0 | AB20: =SUM(Y20*$AB$2) -> 0 | AC20: =AC19 -> 1936 | AD20: =AC20-AC19 -> 0 | AE20: =AE19 -> 365520.8 | AF20: =AE20-AE19 -> 0 | AG20: =IF(AD20>0,AF20/AD20,0) -> 0 | AH20: =AF20+AA20 -> 0 | AI20: =SUM(AH20+V20) -> 115 | AJ20: =-tanks!AW21 -> 115 | AK20: =SUM(AJ20-AI20) -> 0 | AL20: =S20+L20+G20 -> 1 | AM20: =Y20+AD20 -> 0 | AN20: =AN19 -> 67 | AO20: =(AN20/100)*3000 -> 2010 | AP20: =AP19 -> 55 | AQ20: =(AP20/100)*3000 -> 1650 | AR20: =AR19 -> 61 | AS20: =(AR20/100)*3000 -> 1830 | AT20: =SUM(AO20+AQ20+AS20) -> 5490 | AU20: =AT19-AT20+AV20 -> 0 | AX20: =IF(AV20>0,AW20,AX19) -> 0.8
A21: =ELEC!C19 -> 44333 | B21: 188 | C21: 194 | D21: =C20-C21 -> 7 | E21: =D21*8.38 -> 58.66 | F21: =F20 -> 1833 | G21: =F21-F20 -> 0 | H21: =H20 -> 12841 | I21: =SUM(H21-H20) -> 0 | J21: =IF(G21>0,I21/G21,0) -> 0 | K21: 2324 | L21: =K21-K20 -> 1 | M21: 171322 | N21: =M21-M20 -> 37 | O21: =O20 -> 1869 | P21: =P20 -> 2089 | Q21: 175710 | R21: =Q21-Q20 -> 56 | S21: =SUM(P21-P20) -> 0 | T21: =SUM(S21*$T$2) -> 0 | U21: =SUM(G21+L21+S21) -> 1 | V21: =R21+N21+I21:I21 -> 93 | X21: =X20 -> 2467 | Y21: =X21-X20 -> 0 | Z21: =Z20 -> 138897 | AA21: =Z21-Z20 -> 0 | AB21: =SUM(Y21*$AB$2) -> 0 | AC21: =AC20 -> 1936 | AD21: =AC21-AC20 -> 0 | AE21: =AE20 -> 365520.8 | AF21: =AE21-AE20 -> 0 | AG21: =IF(AD21>0,AF21/AD21,0) -> 0 | AH21: =AF21+AA21 -> 0 | AI21: =SUM(AH21+V21) -> 93 | AJ21: =-tanks!AW22 -> 93 | AK21: =SUM(AJ21-AI21) -> 0 | AL21: =S21+L21+G21 -> 1 | AM21: =Y21+AD21 -> 0 | AN21: =AN20 -> 67 | AO21: =(AN21/100)*3000 -> 2010 | AP21: =AP20 -> 55 | AQ21: =(AP21/100)*3000 -> 1650 | AR21: =AR20 -> 61 | AS21: =(AR21/100)*3000 -> 1830 | AT21: =SUM(AO21+AQ21+AS21) -> 5490 | AU21: =AT20-AT21+AV21 -> 0 | AX21: =IF(AV21>0,AW21,AX20) -> 0.8
A22: =ELEC!C20 -> 44334 | B22: 179 | C22: 186 | D22: =C21-C22 -> 8 | E22: =D22*8.38 -> 67.04 | F22: 1835 | G22: =F22-F21 -> 2 | H22: 12933 | I22: =SUM(H22-H21) -> 92 | J22: =IF(G22>0,I22/G22,0) -> 46 | K22: =K21 -> 2324 | L22: =K22-K21 -> 0 | M22: =M21 -> 171322 | N22: =M22-M21 -> 0 | O22: =O21 -> 1869 | P22: 2090 | Q22: 175754 | R22: =Q22-Q21 -> 44 | S22: =SUM(P22-P21) -> 1 | T22: =SUM(S22*$T$2) -> 0 | U22: =SUM(G22+L22+S22) -> 3 | V22: =R22+N22+I22:I22 -> 136 | X22: =X21 -> 2467 | Y22: =X22-X21 -> 0 | Z22: =Z21 -> 138897 | AA22: =Z22-Z21 -> 0 | AB22: =SUM(Y22*$AB$2) -> 0 | AC22: =AC21 -> 1936 | AD22: =AC22-AC21 -> 0 | AE22: =AE21 -> 365520.8 | AF22: =AE22-AE21 -> 0 | AG22: =IF(AD22>0,AF22/AD22,0) -> 0 | AH22: =AF22+AA22 -> 0 | AI22: =SUM(AH22+V22) -> 136 | AJ22: =-tanks!AW23 -> 136 | AK22: =SUM(AJ22-AI22) -> 0 | AL22: =S22+L22+G22 -> 3 | AM22: =Y22+AD22 -> 0 | AN22: =AN21 -> 67 | AO22: =(AN22/100)*3000 -> 2010 | AP22: =AP21 -> 55 | AQ22: =(AP22/100)*3000 -> 1650 | AR22: =AR21 -> 61 | AS22: =(AR22/100)*3000 -> 1830 | AT22: =SUM(AO22+AQ22+AS22) -> 5490 | AU22: =AT21-AT22+AV22 -> 0 | AX22: =IF(AV22>0,AW22,AX21) -> 0.8
