Workbook

Sheet TOTAL
A1: Site Name | B1: Day | C1: Month | D1: Year | E1: Total Electricity Kwh | F1: Electricity Tariff ($/Kwh) | G1: LPG (Kg) | H1: LPG $/Kg | I1: Water Utility Supply (m3) m3 | J1: Water Utility Supply (m3) $/m3 | K1: Room Nights | L1: Food Covers
A2: Maldives at Landaa Giraavaru | B2: 1 | C2: 5 | D2: 2021 | E2: ='Maldives at LG Daily'!D5 -> 30133 | F2: 0.93 | G2: ='Maldives at LG Daily'!F5 -> 225 | H2: 1.24 | I2: ='Maldives at LG Daily'!H5 -> 418 | J2: 2.16 | K2: ='Maldives at LG Daily'!I5 -> 45 | L2: ='Maldives at LG Daily'!J5 -> 318
A3: Maldives at Landaa Giraavaru | B3: =B2+1 -> 2 | C3: 5 | D3: 2021 | E3: ='Maldives at LG Daily'!D6 -> 31397 | F3: 0.93 | G3: ='Maldives at LG Daily'!F6 -> 0 | H3: 1.24 | I3: ='Maldives at LG Daily'!H6 -> 361 | J3: 2.16 | K3: ='Maldives at LG Daily'!I6 -> 48 | L3: ='Maldives at LG Daily'!J6 -> 391
A4: Maldives at Landaa Giraavaru | B4: =B3+1 -> 3 | C4: 5 | D4: 2021 | E4: ='Maldives at LG Daily'!D7 -> 30147 | F4: 0.93 | G4: ='Maldives at LG Daily'!F7 -> 90 | H4: 1.24 | I4: ='Maldives at LG Daily'!H7 -> 385 | J4: 2.16 | K4: ='Maldives at LG Daily'!I7 -> 34 | L4: ='Maldives at LG Daily'!J7 -> 252
A5: Maldives at Landaa Giraavaru | B5: =B4+1 -> 4 | C5: 5 | D5: 2021 | E5: ='Maldives at LG Daily'!D8 -> 28804 | F5: 0.93 | G5: ='Maldives at LG Daily'!F8 -> 45 | H5: 1.24 | I5: ='Maldives at LG Daily'!H8 -> 368 | J5: 2.16 | K5: ='Maldives at LG Daily'!I8 -> 54 | L5: ='Maldives at LG Daily'!J8 -> 379
A6: Maldives at Landaa Giraavaru | B6: =B5+1 -> 5 | C6: 5 | D6: 2021 | E6: ='Maldives at LG Daily'!D9 -> 30365 | F6: 0.93 | G6: ='Maldives at LG Daily'!F9 -> 0 | H6: 1.24 | I6: ='Maldives at LG Daily'!H9 -> 356 | J6: 2.16 | K6: ='Maldives at LG Daily'!I9 -> 53 | L6: ='Maldives at LG Daily'!J9 -> 402
A7: Maldives at Landaa Giraavaru | B7: =B6+1 -> 6 | C7: 5 | D7: 2021 | E7: ='Maldives at LG Daily'!D10 -> 29900 | F7: 0.93 | G7: ='Maldives at LG Daily'!F10 -> 0 | H7: 1.24 | I7: ='Maldives at LG Daily'!H10 -> 379 | J7: 2.16 | K7: ='Maldives at LG Daily'!I10 -> 45 | L7: ='Maldives at LG Daily'!J10 -> 427
A8: Maldives at Landaa Giraavaru | B8: =B7+1 -> 7 | C8: 5 | D8: 2021 | E8: ='Maldives at LG Daily'!D11 -> 30587 | F8: 0.93 | G8: ='Maldives at LG Daily'!F11 -> 0 | H8: 1.24 | I8: ='Maldives at LG Daily'!H11 -> 417 | J8: 2.16 | K8: ='Maldives at LG Daily'!I11 -> 48 | L8: ='Maldives at LG Daily'!J11 -> 376
A9: Maldives at Landaa Giraavaru | B9: =B8+1 -> 8 | C9: 5 | D9: 2021 | E9: ='Maldives at LG Daily'!D12 -> 30219 | F9: 0.93 | G9: ='Maldives at LG Daily'!F12 -> 45 | H9: 1.24 | I9: ='Maldives at LG Daily'!H12 -> 390 | J9: 2.16 | K9: ='Maldives at LG Daily'!I12 -> 47 | L9: ='Maldives at LG Daily'!J12 -> 351
A10: Maldives at Landaa Giraavaru | B10: =B9+1 -> 9 | C10: 5 | D10: 2021 | E10: ='Maldives at LG Daily'!D13 -> 30190 | F10: 0.93 | G10: ='Maldives at LG Daily'!F13 -> 0 | H10: 1.24 | I10: ='Maldives at LG Daily'!H13 -> 381 | J10: 2.16 | K10: ='Maldives at LG Daily'!I13 -> 47 | L10: ='Maldives at LG Daily'!J13 -> 391
A11: Maldives at Landaa Giraavaru | B11: =B10+1 -> 10 | C11: 5 | D11: 2021 | E11: ='Maldives at LG Daily'!D14 -> 30007 | F11: 0.93 | G11: ='Maldives at LG Daily'!F14 -> 0 | H11: 1.24 | I11: ='Maldives at LG Daily'!H14 -> 353 | J11: 2.16 | K11: ='Maldives at LG Daily'!I14 -> 46 | L11: ='Maldives at LG Daily'!J14 -> 342
A12: Maldives at Landaa Giraavaru | B12: =B11+1 -> 11 | C12: 5 | D12: 2021 | E12: ='Maldives at LG Daily'!D15 -> 29374 | F12: 0.93 | G12: ='Maldives at LG Daily'!F15 -> 0 | H12: 1.24 | I12: ='Maldives at LG Daily'!H15 -> 387 | J12: 2.16 | K12: ='Maldives at LG Daily'!I15 -> 46 | L12: ='Maldives at LG Daily'!J15 -> 343
A13: Maldives at Landaa Giraavaru | B13: =B12+1 -> 12 | C13: 5 | D13: 2021 | E13: ='Maldives at LG Daily'!D16 -> 29062 | F13: 0.93 | G13: ='Maldives at LG Daily'!F16 -> 0 | H13: 1.24 | I13: ='Maldives at LG Daily'!H16 -> 328 | J13: 2.16 | K13: ='Maldives at LG Daily'!I16 -> 45 | L13: ='Maldives at LG Daily'!J16 -> 350
A14: Maldives at Landaa Giraavaru | B14: =B13+1 -> 13 | C14: 5 | D14: 2021 | E14: ='Maldives at LG Daily'!D17 -> 28176 | F14: 0.93 | G14: ='Maldives at LG Daily'!F17 -> 0 | H14: 1.24 | I14: ='Maldives at LG Daily'!H17 -> 408 | J14: 2.16 | K14: ='Maldives at LG Daily'!I17 -> 48 | L14: ='Maldives at LG Daily'!J17 -> 422
... A30: Maldives at Landaa Giraavaru | B30: =B29+1 -> 29 | C30: 5 | D30: 2021 | E30: ='Maldives at LG Daily'!D33 -> 0 | F30: 0.93 | G30: ='Maldives at LG Daily'!F33 -> 0 | H30: 2.24 | I30: ='Maldives at LG Daily'!H33 -> 0 | J30: 2.16 | K30: ='Maldives at LG Daily'!I33 -> 0 | L30: ='Maldives at LG Daily'!J33 -> 0
A31: Maldives at Landaa Giraavaru | B31: 30 | C31: 5 | D31: 2021 | E31: ='Maldives at LG Daily'!D34 -> 0 | F31: 1.93 | G31: ='Maldives at LG Daily'!F34 -> 0 | H31: 3.24 | I31: ='Maldives at LG Daily'!H34 -> 0 | J31: 2.16 | K31: ='Maldives at LG Daily'!I34 -> 0 | L31: ='Maldives at LG Daily'!J34 -> 0
A32: Maldives at Landaa Giraavaru | B32: 31 | C32: 5 | D32: 2021 | E32: ='Maldives at LG Daily'!D35 -> 0 | F32: 2.93 | G32: ='Maldives at LG Daily'!F35 -> 0 | H32: 4.24 | I32: ='Maldives at LG Daily'!H35 -> 0 | J32: 2.16 | K32: ='Maldives at LG Daily'!I35 -> 0 | L32: ='Maldives at LG Daily'!J35 -> 0

Sheet Maldives at LG Daily
A2: Days | C2: Electricity Meter (KWh) | E2: Gas Kg | G2: Water m3
A3: Date | C3: Reading KWH | D3: Difference KWH | E3: Reading Kg | F3: Difference Kg | G3: Reading m³ | H3: Daily Consumption m³ | I3: ROOM NIGHTS | J3: TOTAL GUESTS
A4: 44316 | C4: =SUM('GENSET #1'!B10+'GENSET #2'!B10+'GENSET #3'!B10+'GENSET #4'!B10+'GENSET #5'!B10) -> 89581707 | D4: 30577 | E4: ='Gas-2'!G5 -> 0 | F4: 90 | G4: =SUM(WATER!G6,WATER!L6,WATER!Q6,WATER!B6) -> 946438 | H4: 423
A5: =A4+1 -> 44317 | C5: =SUM('GENSET #1'!C10+'GENSET #2'!C10+'GENSET #3'!C10+'GENSET #4'!C10+'GENSET #5'!C10) -> 89611840 | D5: =IF((C5-C4<0), "0",C5-C4) -> 30133 | E5: ='Gas-2'!G6 -> 225 | F5: =IF((E5-E4<0), "0",E5-E4) -> 225 | G5: =SUM(WATER!C6,WATER!H6,WATER!M6,WATER!R6) -> 946813 | H5: 418 | I5: 45 | J5: 318
A6: =A5+1 -> 44318 | C6: =SUM('GENSET #1'!C11+'GENSET #2'!C11+'GENSET #3'!C11+'GENSET #4'!C11+'GENSET #5'!C11) -> 89643237 | D6: =IF((C6-C5<0), "0",C6-C5) -> 31397 | E6: ='Gas-2'!G7 -> 180 | F6: =IF((E6-E5<0), "0",E6-E5) -> 0 | G6: =SUM(WATER!C7,WATER!H7,WATER!M7,WATER!R7) -> 947174 | H6: =IF((G6-G5<0), "0",G6-G5) -> 361 | I6: 48 | J6: 391
A7: =A6+1 -> 44319 | C7: =SUM('GENSET #1'!C12+'GENSET #2'!C12+'GENSET #3'!C12+'GENSET #4'!C12+'GENSET #5'!C12) -> 89673384 | D7: =IF((C7-C6<0), "0",C7-C6) -> 30147 | E7: ='Gas-2'!G8 -> 270 | F7: =IF((E7-E6<0), "0",E7-E6) -> 90 | G7: =SUM(WATER!C8,WATER!H8,WATER!M8,WATER!R8) -> 947559 | H7: =IF((G7-G6<0), "0",G7-G6) -> 385 | I7: 34 | J7: 252
A8: =A7+1 -> 44320 | C8: =SUM('GENSET #1'!C13+'GENSET #2'!C13+'GENSET #3'!C13+'GENSET #4'!C13+'GENSET #5'!C13) -> 89702188 | D8: =IF((C8-C7<0), "0",C8-C7) -> 28804 | E8: ='Gas-2'!G9 -> 315 | F8: =IF((E8-E7<0), "0",E8-E7) -> 45 | G8: =SUM(WATER!C9,WATER!H9,WATER!M9,WATER!R9) -> 947927 | H8: =IF((G8-G7<0), "0",G8-G7) -> 368 | I8: 54 | J8: 379
A9: =A8+1 -> 44321 | C9: =SUM('GENSET #1'!C14+'GENSET #2'!C14+'GENSET #3'!C14+'GENSET #4'!C14+'GENSET #5'!C14) -> 89732553 | D9: =IF((C9-C8<0), "0",C9-C8) -> 30365 | E9: ='Gas-2'!G10 -> 270 | F9: =IF((E9-E8<0), "0",E9-E8) -> 0 | G9: =SUM(WATER!C10,WATER!H10,WATER!M10,WATER!R10) -> 948283 | H9: =IF((G9-G8<0), "0",G9-G8) -> 356 | I9: 53 | J9: 402
A10: =A9+1 -> 44322 | C10: =SUM('GENSET #1'!C15+'GENSET #2'!C15+'GENSET #3'!C15+'GENSET #4'!C15+'GENSET #5'!C15) -> 89762453 | D10: =IF((C10-C9<0), "0",C10-C9) -> 29900 | E10: ='Gas-2'!G11 -> 270 | F10: =IF((E10-E9<0), "0",E10-E9) -> 0 | G10: =SUM(WATER!C11,WATER!H11,WATER!M11,WATER!R11) -> 948662 | H10: =IF((G10-G9<0), "0",G10-G9) -> 379 | I10: 45 | J10: 427
A11: =A10+1 -> 44323 | C11: =SUM('GENSET #1'!C16+'GENSET #2'!C16+'GENSET #3'!C16+'GENSET #4'!C16+'GENSET #5'!C16) -> 89793040 | D11: =IF((C11-C10<0), "0",C11-C10) -> 30587 | E11: ='Gas-2'!G12 -> 270 | F11: =IF((E11-E10<0), "0",E11-E10) -> 0 | G11: =SUM(WATER!C12,WATER!H12,WATER!M12,WATER!R12) -> 949079 | H11: =IF((G11-G10<0), "0",G11-G10) -> 417 | I11: 48 | J11: 376
A12: =A11+1 -> 44324 | C12: =SUM('GENSET #1'!C17+'GENSET #2'!C17+'GENSET #3'!C17+'GENSET #4'!C17+'GENSET #5'!C17) -> 89823259 | D12: =IF((C12-C11<0), "0",C12-C11) -> 30219 | E12: ='Gas-2'!G13 -> 315 | F12: =IF((E12-E11<0), "0",E12-E11) -> 45 | G12: =SUM(WATER!C13,WATER!H13,WATER!M13,WATER!R13) -> 949469 | H12: =IF((G12-G11<0), "0",G12-G11) -> 390 | I12: 47 | J12: 351
A13: =A12+1 -> 44325 | C13: =SUM('GENSET #1'!C18+'GENSET #2'!C18+'GENSET #3'!C18+'GENSET #4'!C18+'GENSET #5'!C18) -> 89853449 | D13: =IF((C13-C12<0), "0",C13-C12) -> 30190 | E13: ='Gas-2'!G14 -> 315 | F13: =IF((E13-E12<0), "0",E13-E12) -> 0 | G13: =SUM(WATER!C14,WATER!H14,WATER!M14,WATER!R14) -> 949850 | H13: =IF((G13-G12<0), "0",G13-G12) -> 381 | I13: 47 | J13: 391
A14: =A13+1 -> 44326 | C14: =SUM('GENSET #1'!C19+'GENSET #2'!C19+'GENSET #3'!C19+'GENSET #4'!C19+'GENSET #5'!C19) -> 89883456 | D14: =IF((C14-C13<0), "0",C14-C13) -> 30007 | E14: ='Gas-2'!G15 -> 270 | F14: =IF((E14-E13<0), "0",E14-E13) -> 0 | G14: =SUM(WATER!C15,WATER!H15,WATER!M15,WATER!R15) -> 950203 | H14: =IF((G14-G13<0), "0",G14-G13) -> 353 | I14: 46 | J14: 342
A15: =A14+1 -> 44327 | C15: =SUM('GENSET #1'!C20+'GENSET #2'!C20+'GENSET #3'!C20+'GENSET #4'!C20+'GENSET #5'!C20) -> 89912830 | D15: =IF((C15-C14<0), "0",C15-C14) -> 29374 | E15: ='Gas-2'!G16 -> 270 | F15: =IF((E15-E14<0), "0",E15-E14) -> 0 | G15: =SUM(WATER!C16,WATER!H16,WATER!M16,WATER!R16) -> 950590 | H15: =IF((G15-G14<0), "0",G15-G14) -> 387 | I15: 46 | J15: 343
A16: =A15+1 -> 44328 | C16: =SUM('GENSET #1'!C21+'GENSET #2'!C21+'GENSET #3'!C21+'GENSET #4'!C21+'GENSET #5'!C21) -> 89941892 | D16: =IF((C16-C15<0), "0",C16-C15) -> 29062 | E16: ='Gas-2'!G17 -> 225 | F16: =IF((E16-E15<0), "0",E16-E15) -> 0 | G16: =SUM(WATER!C17,WATER!H17,WATER!M17,WATER!R17) -> 950918 | H16: =IF((G16-G15<0), "0",G16-G15) -> 328 | I16: 45 | J16: 350
A17: =A16+1 -> 44329 | C17: =SUM('GENSET #1'!C22+'GENSET #2'!C22+'GENSET #3'!C22+'GENSET #4'!C22+'GENSET #5'!C22) -> 89970068 | D17: =IF((C17-C16<0), "0",C17-C16) -> 28176 | E17: ='Gas-2'!G18 -> 180 | F17: =IF((E17-E16<0), "0",E17-E16) -> 0 | G17: =SUM(WATER!C18,WATER!H18,WATER!M18,WATER!R18) -> 951326 | H17: =IF((G17-G16<0), "0",G17-G16) -> 408 | I17: 48 | J17: 422
... A23: =A22+1 -> 44335 | C23: =SUM('GENSET #1'!C28+'GENSET #2'!C28+'GENSET #3'!C28+'GENSET #4'!C28+'GENSET #5'!C28) -> 90150529 | D23: =IF((C23-C22<0), "0",C23-C22) -> 30366 | E23: ='Gas-2'!G24 -> 405 | F23: =IF((E23-E22<0), "0",E23-E22) -> 135 | G23: =SUM(WATER!C24,WATER!H24,WATER!M24,WATER!R24) -> 953458 | H23: =IF((G23-G22<0), "0",G23-G22) -> 367 | I23: 36 | J23: 304
A24: =A23+1 -> 44336 | C24: =SUM('GENSET #1'!C29+'GENSET #2'!C29+'GENSET #3'!C29+'GENSET #4'!C29+'GENSET #5'!C29) -> 90179769 | D24: =IF((C24-C23<0), "0",C24-C23) -> 29240 | E24: ='Gas-2'!G25 -> 0 | F24: =IF((E24-E23<0), "0",E24-E23) -> 0 | G24: =SUM(WATER!C25,WATER!H25,WATER!M25,WATER!R25) -> 953814 | H24: =IF((G24-G23<0), "0",G24-G23) -> 356
A25: =A24+1 -> 44337 | C25: =SUM('GENSET #1'!C30+'GENSET #2'!C30+'GENSET #3'!C30+'GENSET #4'!C30+'GENSET #5'!C30) -> 0 | D25: =IF((C25-C24<0), "0",C25-C24) -> 0 | E25: ='Gas-2'!G26 -> 0 | F25: =IF((E25-E24<0), "0",E25-E24) -> 0 | G25: =SUM(WATER!C26,WATER!H26,WATER!M26,WATER!R26) -> 954134 | H25: =IF((G25-G24<0), "0",G25-G24) -> 320
A26: =A25+1 -> 44338 | C26: =SUM('GENSET #1'!C31+'GENSET #2'!C31+'GENSET #3'!C31+'GENSET #4'!C31+'GENSET #5'!C31) -> 0 | D26: =IF((C26-C25<0), "0",C26-C25) -> 0 | E26: ='Gas-2'!G27 -> 0 | F26: =IF((E26-E25<0), "0",E26-E25) -> 0 | G26: =SUM(WATER!C27,WATER!H27,WATER!M27,WATER!R27) -> 0 | H26: =IF((G26-G25<0), "0",G26-G25) -> 0
A27: =A26+1 -> 44339 | C27: =SUM('GENSET #1'!C32+'GENSET #2'!C32+'GENSET #3'!C32+'GENSET #4'!C32+'GENSET #5'!C32) -> 0 | D27: =IF((C27-C26<0), "0",C27-C26) -> 0 | E27: ='Gas-2'!G28 -> 0 | F27: =IF((E27-E26<0), "0",E27-E26) -> 0 | G27: =SUM(WATER!C28,WATER!H28,WATER!M28,WATER!R28) -> 0 | H27: =IF((G27-G26<0), "0",G27-G26) -> 0
A28: =A27+1 -> 44340 | C28: =SUM('GENSET #1'!C33+'GENSET #2'!C33+'GENSET #3'!C33+'GENSET #4'!C33+'GENSET #5'!C33) -> 0 | D28: =IF((C28-C27<0), "0",C28-C27) -> 0 | E28: ='Gas-2'!G29 -> 0 | F28: =IF((E28-E27<0), "0",E28-E27) -> 0 | G28: =SUM(WATER!C29,WATER!H29,WATER!M29,WATER!R29) -> 0 | H28: =IF((G28-G27<0), "0",G28-G27) -> 0
A29: =A28+1 -> 44341 | C29: =SUM('GENSET #1'!C34+'GENSET #2'!C34+'GENSET #3'!C34+'GENSET #4'!C34+'GENSET #5'!C34) -> 0 | D29: =IF((C29-C28<0), "0",C29-C28) -> 0 | E29: ='Gas-2'!G30 -> 0 | F29: =IF((E29-E28<0), "0",E29-E28) -> 0 | G29: =SUM(WATER!C30,WATER!H30,WATER!M30,WATER!R30) -> 0 | H29: =IF((G29-G28<0), "0",G29-G28) -> 0
A30: =A29+1 -> 44342 | C30: =SUM('GENSET #1'!C35+'GENSET #2'!C35+'GENSET #3'!C35+'GENSET #4'!C35+'GENSET #5'!C35) -> 0 | D30: =IF((C30-C29<0), "0",C30-C29) -> 0 | E30: ='Gas-2'!G31 -> 0 | F30: =IF((E30-E29<0), "0",E30-E29) -> 0 | G30: =SUM(WATER!C31,WATER!H31,WATER!M31,WATER!R31) -> 0 | H30: =IF((G30-G29<0), "0",G30-G29) -> 0
A31: =A30+1 -> 44343 | C31: =SUM('GENSET #1'!C36+'GENSET #2'!C36+'GENSET #3'!C36+'GENSET #4'!C36+'GENSET #5'!C36) -> 0 | D31: =IF((C31-C30<0), "0",C31-C30) -> 0 | E31: ='Gas-2'!G32 -> 0 | F31: =IF((E31-E30<0), "0",E31-E30) -> 0 | G31: =SUM(WATER!C32,WATER!H32,WATER!M32,WATER!R32) -> 0 | H31: =IF((G31-G30<0), "0",G31-G30) -> 0
A32: =A31+1 -> 44344 | C32: =SUM('GENSET #1'!C37+'GENSET #2'!C37+'GENSET #3'!C37+'GENSET #4'!C37+'GENSET #5'!C37) -> 0 | D32: =IF((C32-C31<0), "0",C32-C31) -> 0 | E32: ='Gas-2'!G33 -> 0 | F32: =IF((E32-E31<0), "0",E32-E31) -> 0 | G32: =SUM(WATER!C33,WATER!H33,WATER!M33,WATER!R33) -> 0 | H32: =IF((G32-G31<0), "0",G32-G31) -> 0
A33: =A32+1 -> 44345 | C33: =SUM('GENSET #1'!C38+'GENSET #2'!C38+'GENSET #3'!C38+'GENSET #4'!C38+'GENSET #5'!C38) -> 0 | D33: =IF((C33-C32<0), "0",C33-C32) -> 0 | E33: ='Gas-2'!G34 -> 0 | F33: =IF((E33-E32<0), "0",E33-E32) -> 0 | G33: =SUM(WATER!C34,WATER!H34,WATER!M34,WATER!R34) -> 0 | H33: =IF((G33-G32<0), "0",G33-G32) -> 0
A34: =A33+1 -> 44346 | C34: =SUM('GENSET #1'!C39+'GENSET #2'!C39+'GENSET #3'!C39+'GENSET #4'!C39+'GENSET #5'!C39) -> 0 | D34: =IF((C34-C33<0), "0",C34-C33) -> 0 | E34: ='Gas-2'!G35 -> 0 | F34: =IF((E34-E33<0), "0",E34-E33) -> 0 | G34: =SUM(WATER!C35,WATER!H35,WATER!M35,WATER!R35) -> 0 | H34: =IF((G34-G33<0), "0",G34-G33) -> 0
A35: =A34+1 -> 44347 | C35: =SUM('GENSET #1'!C40+'GENSET #2'!C40+'GENSET #3'!C40+'GENSET #4'!C40+'GENSET #5'!C40) -> 0 | D35: =IF((C35-C34<0), "0",C35-C34) -> 0 | E35: ='Gas-2'!G36 -> 0 | F35: =IF((E35-E34<0), "0",E35-E34) -> 0 | G35: =SUM(WATER!C36,WATER!H36,WATER!M36,WATER!R36) -> 0 | H35: =IF((G35-G34<0), "0",G35-G34) -> 0

Sheet Finance Only
A1: Four Seasons Landaa Giraavaru
A3: Property | B3: MLG
A4: Month | B4: May
A5: Year | B5: 2021
A7: DAY | B7: Electricity Consumption ( kwh) | C7: Diesel Consumption (Liters) | D7: Solar Power Consumption(kwh) | E7: Gas Consumption (kg) | F7: Water Consumption ( m3) | G7: Occupancy | H7: Weather
A8: 1 | B8: =SUM('GENSET #1:GENSET #5'!D10) -> 30133 | C8: ='Diesel consumption'!D5 -> 8220 | D8: ='SOLAR METER READING'!D9 -> 3180 | E8: ='Gas-2'!G6 -> 225 | F8: =WATER!V6 -> 291 | G8: =WATER!W6 -> 45 | H8: ='SOLAR METER READING'!E9 -> partly sunny
A9: 2 | B9: =SUM('GENSET #1:GENSET #5'!D11) -> 31397 | C9: ='Diesel consumption'!D6 -> 8710 | D9: ='SOLAR METER READING'!D10 -> 3214 | E9: ='Gas-2'!G7 -> 180 | F9: =WATER!V7 -> 361 | G9: =WATER!W7 -> 48 | H9: ='SOLAR METER READING'!E10 -> partly sunny
A10: 3 | B10: =SUM('GENSET #1:GENSET #5'!D12) -> 30147 | C10: ='Diesel consumption'!D7 -> 8430 | D10: ='SOLAR METER READING'!D11 -> 2336 | E10: ='Gas-2'!G8 -> 270 | F10: =WATER!V8 -> 385 | G10: =WATER!W8 -> 34 | H10: ='SOLAR METER READING'!E11 -> partly cloudy
A11: 4 | B11: =SUM('GENSET #1:GENSET #5'!D13) -> 28804 | C11: ='Diesel consumption'!D8 -> 8070 | D11: ='SOLAR METER READING'!D12 -> 3076 | E11: ='Gas-2'!G9 -> 315 | F11: =WATER!V9 -> 368 | G11: =WATER!W9 -> 54 | H11: ='SOLAR METER READING'!E12 -> partly sunny
A12: 5 | B12: =SUM('GENSET #1:GENSET #5'!D14) -> 30365 | C12: ='Diesel consumption'!D9 -> 8200 | D12: ='SOLAR METER READING'!D13 -> 3178 | E12: ='Gas-2'!G10 -> 270 | F12: =WATER!V10 -> 356 | G12: =WATER!W10 -> 53 | H12: ='SOLAR METER READING'!E13 -> partly sunny
A13: 6 | B13: =SUM('GENSET #1:GENSET #5'!D15) -> 29900 | C13: ='Diesel consumption'!D10 -> 8570 | D13: ='SOLAR METER READING'!D14 -> 2974 | E13: ='Gas-2'!G11 -> 270 | F13: =WATER!V11 -> 379 | G13: =WATER!W11 -> 45 | H13: ='SOLAR METER READING'!E14 -> partlu cloudly
A14: 7 | B14: =SUM('GENSET #1:GENSET #5'!D16) -> 30587 | C14: ='Diesel consumption'!D11 -> 8380 | D14: ='SOLAR METER READING'!D15 -> 2854 | E14: ='Gas-2'!G12 -> 270 | F14: =WATER!V12 -> 417 | G14: =WATER!W12 -> 48 | H14: ='SOLAR METER READING'!E15 -> partly cloudy
A15: 8 | B15: =SUM('GENSET #1:GENSET #5'!D17) -> 30219 | C15: ='Diesel consumption'!D12 -> 8650 | D15: ='SOLAR METER READING'!D16 -> 2674 | E15: ='Gas-2'!G13 -> 315 | F15: =WATER!V13 -> 390 | G15: =WATER!W13 -> 47 | H15: ='SOLAR METER READING'!E16 -> partly cloudy
A16: 9 | B16: =SUM('GENSET #1:GENSET #5'!D18) -> 30190 | C16: ='Diesel consumption'!D13 -> 8350 | D16: ='SOLAR METER READING'!D17 -> 3112 | E16: ='Gas-2'!G14 -> 315 | F16: =WATER!V14 -> 381 | G16: =WATER!W14 -> 47 | H16: ='SOLAR METER READING'!E17 -> sunny
A17: 10 | B17: =SUM('GENSET #1:GENSET #5'!D19) -> 30007 | C17: ='Diesel consumption'!D14 -> 8460 | D17: ='SOLAR METER READING'!D18 -> 2430 | E17: ='Gas-2'!G15 -> 270 | F17: =WATER!V15 -> 353 | G17: =WATER!W15 -> 46 | H17: ='SOLAR METER READING'!E18 -> cloudy
A18: 11 | B18: =SUM('GENSET #1:GENSET #5'!D20) -> 29374 | C18: ='Diesel consumption'!D15 -> 8140 | D18: ='SOLAR METER READING'!D19 -> 1801 | E18: ='Gas-2'!G16 -> 270 | F18: =WATER!V16 -> 387 | G18: =WATER!W16 -> 46 | H18: ='SOLAR METER READING'!E19 -> rainy
A19: 12 | B19: =SUM('GENSET #1:GENSET #5'!D21) -> 29062 | C19: ='Diesel consumption'!D16 -> 8070 | D19: ='SOLAR METER READING'!D20 -> 1981 | E19: ='Gas-2'!G17 -> 225 | F19: =WATER!V17 -> 328 | G19: =WATER!W17 -> 45 | H19: ='SOLAR METER READING'!E20 -> rainy
... A37: 30 | B37: =SUM('GENSET #1:GENSET #5'!D39) -> 0 | C37: ='Diesel consumption'!D34 -> 0 | D37: ='SOLAR METER READING'!D38 -> 0 | E37: ='Gas-2'!G35 -> 0 | F37: =WATER!V35 -> 0 | G37: =WATER!W35 -> 0 | H37: ='SOLAR METER READING'!E38 -> 0
A38: Total | B38: =SUM(B8:B37) -> -89581707 | C38: =SUM(C8:C37) -> -43850220 | D38: =SUM(D8:D37) -> -2596702 | E38: =SUM(E8:E37) -> 5085 | F38: =SUM(F8:F37) -> -946522 | G38: =SUM(G8:G37)/30 -> 27.8
A39: Avg | B39: =B38/30 -> -2986056.9 | C39: =C38/30 -> -1461674 | D39: =D38/30 -> -86556.733 | E39: =E38/30 -> 169.5 | F39: =F38/31 -> -30532.968

Sheet GENSET #1
C1: 1000 KVA
C3: NO#1
A6: 44317
B8: GENSET NO 1
A9: DAY | B9: YESTARDAY | C9: TODAY | D9: Final Electricity Consumption( KWh)
A10: 1 | B10: 17082256 | C10: 17082256 | D10: =C10-B10 -> 0
A11: 2 | B11: =C10 -> 17082256 | C11: 17082256 | D11: =C11-B11 -> 0
A12: 3 | B12: =C11 -> 17082256 | C12: 17082256 | D12: =C12-B12 -> 0
A13: 4 | B13: =C12 -> 17082256 | C13: 17082256 | D13: =C13-B13 -> 0
A14: 5 | B14: =C13 -> 17082256 | C14: 17083389 | D14: =C14-B14 -> 1133
A15: 6 | B15: =C14 -> 17083389 | C15: 17086149 | D15: =C15-B15 -> 2760
A16: 7 | B16: =C15 -> 17086149 | C16: 17086941 | D16: =C16-B16 -> 792
A17: 8 | B17: =C16 -> 17086941 | C17: 17095994 | D17: =C17-B17 -> 9053
A18: 9 | B18: =C17 -> 17095994 | C18: 17095994 | D18: =C18-B18 -> 0
A19: 10 | B19: =C18 -> 17095994 | C19: 17099926 | D19: =C19-B19 -> 3932
A20: 11 | B20: =C19 -> 17099926 | C20: 17103659 | D20: =C20-B20 -> 3733
A21: 12 | B21: =C20 -> 17103659 | C21: 17107039 | D21: =C21-B21 -> 3380
A22: 13 | B22: =C21 -> 17107039 | C22: 17115559 | D22: =C22-B22 -> 8520
... A29: 20 | B29: =C28 -> 17155529 | C29: 17163352 | D29: =C29-B29 -> 7823
A30: 21 | B30: =C29 -> 17163352 | D30: =C30-B30 -> -17163352
A31: 22 | B31: =C30 -> 0 | D31: =C31-B31 -> 0
A32: 23 | B32: =C31 -> 0 | D32: =C32-B32 -> 0
A33: 24 | B33: =C32 -> 0 | D33: =C33-B33 -> 0
A34: 25 | B34: =C33 -> 0 | D34: =C34-B34 -> 0
A35: 26 | B35: =C34 -> 0 | D35: =C35-B35 -> 0
A36: 27 | B36: =C35 -> 0 | D36: =C36-B36 -> 0
A37: 28 | B37: =C36 -> 0 | D37: =C37-B37 -> 0
A38: 29 | B38: =C37 -> 0 | D38: =C38-B38 -> 0
A39: 30 | B39: =C38 -> 0 | D39: =C39-B39 -> 0 | G39: NEW ENGINE PURCHASED FROM UK
A40: 31 | B40: =C39 -> 0 | D40: =C40-B40 -> 0
A41: Total | D41: =SUM(D10:D39) -> -17082256 | G41: INSTALLED: NOV 30 2013

Sheet GENSET #2
C1: 1600 KVA
C3: NO#2
A6: 44317
B8: GENSET NO 2
A9: DAY | B9: YESTARDAY | C9: TODAY | D9: Final Electricity Consumption( KW h)
A10: 1 | B10: 29671872 | C10: 29685141 | D10: =C10-B10 -> 13269
A11: 2 | B11: =C10 -> 29685141 | C11: 29698820 | D11: =C11-B11 -> 13679
A12: 3 | B12: =C11 -> 29698820 | C12: 29712638 | D12: =C12-B12 -> 13818
A13: 4 | B13: =C12 -> 29712638 | C13: 29724999 | D13: =C13-B13 -> 12361
A14: 5 | B14: =C13 -> 29724999 | C14: 29736711 | D14: =C14-B14 -> 11712
A15: 6 | B15: =C14 -> 29736711 | C15: 29747996 | D15: =C15-B15 -> 11285
A16: 7 | B16: =C15 -> 29747996 | C16: 29759772 | D16: =C16-B16 -> 11776
A17: 8 | B17: =C16 -> 29759772 | C17: 29770905 | D17: =C17-B17 -> 11133
A18: 9 | B18: =C17 -> 29770905 | C18: 29782326 | D18: =C18-B18 -> 11421
A19: 10 | B19: =C18 -> 29782326 | C19: 29794460 | D19: =C19-B19 -> 12134
A20: 11 | B20: =C19 -> 29794460 | C20: 29807543 | D20: =C20-B20 -> 13083
A21: 12 | B21: =C20 -> 29807543 | C21: 29819893 | D21: =C21-B21 -> 12350
A22: 13 | B22: =C21 -> 29819893 | C22: 29832611 | D22: =C22-B22 -> 12718
... A29: 20 | B29: =C28 -> 29914882 | C29: 29928357 | D29: =C29-B29 -> 13475
A30: 21 | B30: =C29 -> 29928357 | D30: =C30-B30 -> -29928357
A31: 22 | B31: =C30 -> 0 | D31: =C31-B31 -> 0
A32: 23 | B32: =C31 -> 0 | D32: =C32-B32 -> 0
A33: 24 | B33: =C32 -> 0 | D33: =C33-B33 -> 0
A34: 25 | B34: =C33 -> 0 | D34: =C34-B34 -> 0
A35: 26 | B35: =C34 -> 0 | D35: =C35-B35 -> 0
A36: 27 | B36: =C35 -> 0 | D36: =C36-B36 -> 0
A37: 28 | B37: =C36 -> 0 | D37: =C37-B37 -> 0
A38: 29 | B38: =C37 -> 0 | D38: =C38-B38 -> 0
A39: 30 | B39: =C38 -> 0 | D39: =C39-B39 -> 0
A40: 31 | B40: =C39 -> 0 | D40: =C40-B40 -> 0
A41: Total | B41: =#REF! -> #REF! | D41: =SUM(D10:D39) -> -29671872

Sheet GENSET #3
C1: 900 KVA
C3: NO#3
A6: 44317
B8: GENSET NO 3
A9: DAY | B9: YESTARDAY | C9: TODAY | D9: Final Electricity Consumption( KW h)
A10: 1 | B10: 13036646 | C10: 13046723 | D10: =C10-B10 -> 10077
A11: 2 | B11: =C10 -> 13046723 | C11: 13050027 | D11: =C11-B11 -> 3304
A12: 3 | B12: =C11 -> 13050027 | C12: 13060064 | D12: =C12-B12 -> 10037
A13: 4 | B13: =C12 -> 13060064 | C13: 13065269 | D13: =C13-B13 -> 5205
A14: 5 | B14: =C13 -> 13065269 | C14: 13072553 | D14: =C14-B14 -> 7284
A15: 6 | B15: =C14 -> 13072553 | C15: 13076609 | D15: =C15-B15 -> 4056
A16: 7 | B16: =C15 -> 13076609 | C16: 13087086 | D16: =C16-B16 -> 10477
A17: 8 | B17: =C16 -> 13087086 | C17: 13087232 | D17: =C17-B17 -> 146
A18: 9 | B18: =C17 -> 13087232 | C18: 13097423 | D18: =C18-B18 -> 10191
A19: 10 | B19: =C18 -> 13097423 | C19: 13097895 | D19: =C19-B19 -> 472
A20: 11 | B20: =C19 -> 13097895 | C20: 13101261 | D20: =C20-B20 -> 3366
A21: 12 | B21: =C20 -> 13101261 | C21: 13108418 | D21: =C21-B21 -> 7157
A22: 13 | B22: =C21 -> 13108418 | C22: 13112001 | D22: =C22-B22 -> 3583
... A29: 20 | B29: =C28 -> 13127906 | C29: 13134204 | D29: =C29-B29 -> 6298
A30: 21 | B30: =C29 -> 13134204 | D30: =C30-B30 -> -13134204
A31: 22 | B31: =C30 -> 0 | D31: =C31-B31 -> 0
A32: 23 | B32: =C31 -> 0 | D32: =C32-B32 -> 0
A33: 24 | B33: =C32 -> 0 | D33: =C33-B33 -> 0
A34: 25 | B34: =C33 -> 0 | D34: =C34-B34 -> 0
A35: 26 | B35: =C34 -> 0 | D35: =C35-B35 -> 0
A36: 27 | B36: =C35 -> 0 | D36: =C36-B36 -> 0
A37: 28 | B37: =C36 -> 0 | D37: =C37-B37 -> 0
A38: 29 | B38: =C37 -> 0 | D38: =C38-B38 -> 0
A39: 30 | B39: =C38 -> 0 | D39: =C39-B39 -> 0
A40: 31 | B40: =C39 -> 0 | D40: =C40-B40 -> 0
A41: Total | B41: =#REF! -> #REF! | D41: =SUM(D10:D39) -> -13036646

Sheet GENSET #4
C1: 500 KVA
C3: NO#4
A6: 44317
B8: GENSET NO 4
A9: DAY | B9: YESTARDAY | C9: TODAY | D9: Final Electricity Consumption( KW h)
A10: 1 | B10: 11639934 | C10: 11643159 | D10: =C10-B10 -> 3225
A11: 2 | B11: =C10 -> 11643159 | C11: 11645947 | D11: =C11-B11 -> 2788
A12: 3 | B12: =C11 -> 11645947 | C12: 11649082 | D12: =C12-B12 -> 3135
A13: 4 | B13: =C12 -> 11649082 | C13: 11651119 | D13: =C13-B13 -> 2037
A14: 5 | B14: =C13 -> 11651119 | C14: 11654066 | D14: =C14-B14 -> 2947
A15: 6 | B15: =C14 -> 11654066 | C15: 11656700 | D15: =C15-B15 -> 2634
A16: 7 | B16: =C15 -> 11656700 | C16: 11660022 | D16: =C16-B16 -> 3322
A17: 8 | B17: =C16 -> 11660022 | C17: 11663033 | D17: =C17-B17 -> 3011
A18: 9 | B18: =C17 -> 11663033 | C18: 11667340 | D18: =C18-B18 -> 4307
A19: 10 | B19: =C18 -> 11667340 | C19: 11669968 | D19: =C19-B19 -> 2628
A20: 11 | B20: =C19 -> 11669968 | C20: 11671066 | D20: =C20-B20 -> 1098
A21: 12 | B21: =C20 -> 11671066 | C21: 11673429 | D21: =C21-B21 -> 2363
A22: 13 | B22: =C21 -> 11673429 | C22: 11673429 | D22: =C22-B22 -> 0
... A29: 20 | B29: =C28 -> 11691520 | C29: 11693164 | D29: =C29-B29 -> 1644
A30: 21 | B30: =C29 -> 11693164 | D30: =C30-B30 -> -11693164
A31: 22 | B31: =C30 -> 0 | D31: =C31-B31 -> 0
A32: 23 | B32: =C31 -> 0 | D32: =C32-B32 -> 0
A33: 24 | B33: =C32 -> 0 | D33: =C33-B33 -> 0
A34: 25 | B34: =C33 -> 0 | D34: =C34-B34 -> 0
A35: 26 | B35: =C34 -> 0 | D35: =C35-B35 -> 0
A36: 27 | B36: =C35 -> 0 | D36: =C36-B36 -> 0
A37: 28 | B37: =C36 -> 0 | D37: =C37-B37 -> 0
A38: 29 | B38: =C37 -> 0 | D38: =C38-B38 -> 0
A39: 30 | B39: =C38 -> 0 | D39: =C39-B39 -> 0
A40: 31 | B40: =C39 -> 0 | D40: =C40-B40 -> 0
A41: Total | B41: =#REF! -> #REF! | D41: =SUM(D10:D39) -> -11639934

Sheet GENSET #5
C1: 1000 KVA
C3: NO#5
A6: 44317
B8: GENSET NO 5
A9: DAY | B9: YESTARDAY | C9: TODAY | D9: Final Electricity Consumption( KWh)
A10: 1 | B10: 18150999 | C10: 18154561 | D10: =C10-B10 -> 3562
A11: 2 | B11: =C10 -> 18154561 | C11: 18166187 | D11: =C11-B11 -> 11626
A12: 3 | B12: =C11 -> 18166187 | C12: 18169344 | D12: =C12-B12 -> 3157
A13: 4 | B13: =C12 -> 18169344 | C13: 18178545 | D13: =C13-B13 -> 9201
A14: 5 | B14: =C13 -> 18178545 | C14: 18185834 | D14: =C14-B14 -> 7289
A15: 6 | B15: =C14 -> 18185834 | C15: 18194999 | D15: =C15-B15 -> 9165
A16: 7 | B16: =C15 -> 18194999 | C16: 18199219 | D16: =C16-B16 -> 4220
A17: 8 | B17: =C16 -> 18199219 | C17: 18206095 | D17: =C17-B17 -> 6876
A18: 9 | B18: =C17 -> 18206095 | C18: 18210366 | D18: =C18-B18 -> 4271
A19: 10 | B19: =C18 -> 18210366 | C19: 18221207 | D19: =C19-B19 -> 10841
A20: 11 | B20: =C19 -> 18221207 | C20: 18229301 | D20: =C20-B20 -> 8094
A21: 12 | B21: =C20 -> 18229301 | C21: 18233113 | D21: =C21-B21 -> 3812
A22: 13 | B22: =C21 -> 18233113 | C22: 18236468 | D22: =C22-B22 -> 3355
... A29: 20 | B29: =C28 -> 18260692 | C29: 18260692 | D29: =C29-B29 -> 0
A30: 21 | B30: =C29 -> 18260692 | D30: =C30-B30 -> -18260692
A31: 22 | B31: =C30 -> 0 | D31: =C31-B31 -> 0
A32: 23 | B32: =C31 -> 0 | D32: =C32-B32 -> 0
A33: 24 | B33: =C32 -> 0 | D33: =C33-B33 -> 0
A34: 25 | B34: =C33 -> 0 | D34: =C34-B34 -> 0
A35: 26 | B35: =C34 -> 0 | D35: =C35-B35 -> 0
A36: 27 | B36: =C35 -> 0 | D36: =C36-B36 -> 0
A37: 28 | B37: =C36 -> 0 | D37: =C37-B37 -> 0
A38: 29 | B38: =C37 -> 0 | D38: =C38-B38 -> 0
A39: 30 | B39: =C38 -> 0 | D39: =C39-B39 -> 0
A40: 31 | B40: =C39 -> 0 | D40: =C40-B40 -> 0
A41: Total | D41: =SUM(D10:D39) -> -18150999

Sheet Diesel consumption
A1: Diesel Consumption - Powerhouse | F1: Diesel usage by Boats
A2: 44317
D3: Liters | F3: Boat meter Reading
A4: Date | B4: Yesterday | C4: Today | D4: ConsumptionIn 24 hrs | F4: Yesterday | G4: Today | H4: Consumption (Liters) | J4: In Barrels | L4: Carbon Emmision
A5: 1 | B5: 43850220 | C5: 43858440 | D5: =C5-B5 -> 8220 | F5: 360610 | G5: 361070 | H5: =G5-F5 -> 460 | J5: =D5/200 -> 41.1 | L5: =2.68*D5 -> 22029.6 | M5: =L5/1000 -> 22.0296
A6: 2 | B6: =C5 -> 43858440 | C6: 43867150 | D6: =C6-B6 -> 8710 | F6: =G5 -> 361070 | G6: 361480 | H6: =G6-F6 -> 410 | J6: =D6/200 -> 43.55 | L6: =2.68*D6 -> 23342.8 | M6: =L6/1000 -> 23.3428
A7: 3 | B7: =C6 -> 43867150 | C7: 43875580 | D7: =C7-B7 -> 8430 | F7: =G6 -> 361480 | G7: 361980 | H7: =G7-F7 -> 500 | J7: =D7/200 -> 42.15 | L7: =2.68*D7 -> 22592.4 | M7: =L7/1000 -> 22.5924
A8: 4 | B8: =C7 -> 43875580 | C8: 43883650 | D8: =C8-B8 -> 8070 | F8: =G7 -> 361980 | G8: 362430 | H8: =G8-F8 -> 450 | J8: =D8/200 -> 40.35 | L8: =2.68*D8 -> 21627.6 | M8: =L8/1000 -> 21.6276
A9: 5 | B9: =C8 -> 43883650 | C9: 43891850 | D9: =C9-B9 -> 8200 | F9: =G8 -> 362430 | G9: 362860 | H9: =G9-F9 -> 430 | J9: =D9/200 -> 41 | L9: =2.68*D9 -> 21976 | M9: =L9/1000 -> 21.976
A10: 6 | B10: =C9 -> 43891850 | C10: 43900420 | D10: =C10-B10 -> 8570 | F10: =G9 -> 362860 | G10: 363310 | H10: =G10-F10 -> 450 | J10: =D10/200 -> 42.85 | L10: =2.68*D10 -> 22967.6 | M10: =L10/1000 -> 22.9676
A11: 7 | B11: =C10 -> 43900420 | C11: 43908800 | D11: =C11-B11 -> 8380 | F11: =G10 -> 363310 | G11: 363740 | H11: =G11-F11 -> 430 | J11: =D11/200 -> 41.9 | L11: =2.68*D11 -> 22458.4 | M11: =L11/1000 -> 22.4584
A12: 8 | B12: =C11 -> 43908800 | C12: 43917450 | D12: =C12-B12 -> 8650 | F12: =G11 -> 363740 | G12: 364230 | H12: =G12-F12 -> 490 | J12: =D12/200 -> 43.25 | L12: =2.68*D12 -> 23182 | M12: =L12/1000 -> 23.182
A13: 9 | B13: =C12 -> 43917450 | C13: 43925800 | D13: =C13-B13 -> 8350 | F13: =G12 -> 364230 | G13: 364630 | H13: =G13-F13 -> 400 | J13: =D13/200 -> 41.75 | L13: =2.68*D13 -> 22378 | M13: =L13/1000 -> 22.378
A14: 10 | B14: =C13 -> 43925800 | C14: 43934260 | D14: =C14-B14 -> 8460 | F14: =G13 -> 364630 | G14: 365130 | H14: =G14-F14 -> 500 | J14: =D14/200 -> 42.3 | L14: =2.68*D14 -> 22672.8 | M14: =L14/1000 -> 22.6728
A15: 11 | B15: =C14 -> 43934260 | C15: 43942400 | D15: =C15-B15 -> 8140 | F15: =G14 -> 365130 | G15: 365620 | H15: =G15-F15 -> 490 | J15: =D15/200 -> 40.7 | L15: =2.68*D15 -> 21815.2 | M15: =L15/1000 -> 21.8152
A16: 12 | B16: =C15 -> 43942400 | C16: 43950470 | D16: =C16-B16 -> 8070 | F16: =G15 -> 365620 | G16: 366050 | H16: =G16-F16 -> 430 | J16: =D16/200 -> 40.35 | L16: =2.68*D16 -> 21627.6 | M16: =L16/1000 -> 21.6276
A17: 13 | B17: =C16 -> 43950470 | C17: 43958430 | D17: =C17-B17 -> 7960 | F17: =G16 -> 366050 | G17: 366530 | H17: =G17-F17 -> 480 | J17: =D17/200 -> 39.8 | L17: =2.68*D17 -> 21332.8 | M17: =L17/1000 -> 21.3328
... A24: 20 | B24: =C23 -> 44009420 | C24: 44017890 | D24: =C24-B24 -> 8470 | F24: =G23 -> 368950 | G24: 369380 | H24: =G24-F24 -> 430 | J24: =D24/200 -> 42.35 | L24: =2.68*D24 -> 22699.6 | M24: =L24/1000 -> 22.6996
A25: 21 | B25: =C24 -> 44017890 | D25: =C25-B25 -> -44017890 | F25: =G24 -> 369380 | H25: =G25-F25 -> -369380 | J25: =D25/200 -> -220089.45 | L25: =2.68*D25 -> -1.1796795e+08 | M25: =L25/1000 -> -117967.95
A26: 22 | B26: =C25 -> 0 | D26: =C26-B26 -> 0 | F26: =G25 -> 0 | H26: =G26-F26 -> 0 | J26: =D26/200 -> 0 | L26: =2.68*D26 -> 0 | M26: =L26/1000 -> 0
A27: 23 | B27: =C26 -> 0 | D27: =C27-B27 -> 0 | F27: =G26 -> 0 | H27: =G27-F27 -> 0 | J27: =D27/200 -> 0 | L27: =2.68*D27 -> 0 | M27: =L27/1000 -> 0
A28: 24 | B28: =C27 -> 0 | D28: =C28-B28 -> 0 | F28: =G27 -> 0 | H28: =G28-F28 -> 0 | J28: =D28/200 -> 0 | L28: =2.68*D28 -> 0 | M28: =L28/1000 -> 0
A29: 25 | B29: =C28 -> 0 | D29: =C29-B29 -> 0 | F29: =G28 -> 0 | H29: =G29-F29 -> 0 | J29: =D29/200 -> 0 | L29: =2.68*D29 -> 0 | M29: =L29/1000 -> 0
A30: 26 | B30: =C29 -> 0 | D30: =C30-B30 -> 0 | F30: =G29 -> 0 | H30: =G30-F30 -> 0 | J30: =D30/200 -> 0 | L30: =2.68*D30 -> 0 | M30: =L30/1000 -> 0
A31: 27 | B31: =C30 -> 0 | D31: =C31-B31 -> 0 | F31: =G30 -> 0 | H31: =G31-F31 -> 0 | J31: =D31/200 -> 0 | L31: =2.68*D31 -> 0 | M31: =L31/1000 -> 0
A32: 28 | B32: =C31 -> 0 | D32: =C32-B32 -> 0 | F32: =G31 -> 0 | H32: =G32-F32 -> 0 | J32: =D32/200 -> 0 | L32: =2.68*D32 -> 0 | M32: =L32/1000 -> 0
A33: 29 | B33: =C32 -> 0 | D33: =C33-B33 -> 0 | F33: =G32 -> 0 | H33: =G33-F33 -> 0 | J33: =D33/200 -> 0 | L33: =2.68*D33 -> 0 | M33: =L33/1000 -> 0
A34: 30 | B34: =C33 -> 0 | D34: =C34-B34 -> 0 | F34: =G33 -> 0 | H34: =G34-F34 -> 0 | J34: =D34/200 -> 0 | L34: =2.68*D34 -> 0 | M34: =L34/1000 -> 0
D35: =SUM(D5:D34) -> -43850220 | J35: =SUM(J5:J34) -> -219251.1 | L35: =2.68*D35 -> -1.1751859e+08 | M35: =L35/1000 -> -117518.59

Sheet SOLAR METER READING
C3: solar reading
B5: 44317
B7: solar meter reading
A8: DAY | B8: YESTARDAY | C8: TODAY | D8: Final Electricity Consumption( KW h) | E8: Weather Condition
A9: 1 | B9: 2596702 | C9: 2599882 | D9: =C9-B9 -> 3180 | E9: partly sunny
A10: 2 | B10: =C9 -> 2599882 | C10: 2603096 | D10: =C10-B10 -> 3214 | E10: partly sunny
A11: 3 | B11: =C10 -> 2603096 | C11: 2605432 | D11: =C11-B11 -> 2336 | E11: partly cloudy
A12: 4 | B12: =C11 -> 2605432 | C12: 2608508 | D12: =C12-B12 -> 3076 | E12: partly sunny
A13: 5 | B13: =C12 -> 2608508 | C13: 2611686 | D13: =C13-B13 -> 3178 | E13: partly sunny | J13: 1 liter diesel | K13: 11.1 kwh
A14: 6 | B14: =C13 -> 2611686 | C14: 2614660 | D14: =C14-B14 -> 2974 | E14: partlu cloudly | J14: 212.88 diesel | K14: 2363 kwh
A15: 7 | B15: =C14 -> 2614660 | C15: 2617514 | D15: =C15-B15 -> 2854 | E15: partly cloudy
A16: 8 | B16: =C15 -> 2617514 | C16: 2620188 | D16: =C16-B16 -> 2674 | E16: partly cloudy
A17: 9 | B17: =C16 -> 2620188 | C17: 2623300 | D17: =C17-B17 -> 3112 | E17: sunny
A18: 10 | B18: =C17 -> 2623300 | C18: 2625730 | D18: =C18-B18 -> 2430 | E18: cloudy
A19: 11 | B19: =C18 -> 2625730 | C19: 2627531 | D19: =C19-B19 -> 1801 | E19: rainy
A20: 12 | B20: =C19 -> 2627531 | C20: 2629512 | D20: =C20-B20 -> 1981 | E20: rainy
A21: 13 | B21: =C20 -> 2629512 | C21: 2630510 | D21: =C21-B21 -> 998 | E21: heavy rain
A22: 14 | B22: =C21 -> 2630510 | C22: 2631046 | D22: =C22-B22 -> 536 | E22: heavy rain
A23: 15 | B23: =C22 -> 2631046 | C23: 2632696 | D23: =C23-B23 -> 1650 | E23: rainy
A24: 16 | B24: =C23 -> 2632696 | C24: 2635837 | D24: =C24-B24 -> 3141 | E24: partly sunny
A25: 17 | B25: =C24 -> 2635837 | C25: 2639105 | D25: =C25-B25 -> 3268 | E25: sunny
A26: 18 | B26: =C25 -> 2639105 | C26: 2642373 | D26: =C26-B26 -> 3268 | E26: sunny
... A28: 20 | B28: =C27 -> 2645683 | C28: 2648567 | D28: =C28-B28 -> 2884 | E28: cloudy
A29: 21 | B29: =C28 -> 2648567 | D29: =C29-B29 -> -2648567
A30: 22 | B30: =C29 -> 0 | D30: =C30-B30 -> 0
A31: 23 | B31: =C30 -> 0 | D31: =C31-B31 -> 0
A32: 24 | B32: =C31 -> 0 | D32: =C32-B32 -> 0
A33: 25 | B33: =C32 -> 0 | D33: =C33-B33 -> 0
A34: 26 | B34: =C33 -> 0 | D34: =C34-B34 -> 0
A35: 27 | B35: =C34 -> 0 | D35: =C35-B35 -> 0
A36: 28 | B36: =C35 -> 0 | D36: =C36-B36 -> 0
A37: 29 | B37: =C36 -> 0 | D37: =C37-B37 -> 0
A38: 30 | B38: =C37 -> 0 | D38: =C38-B38 -> 0
A39: Total | D39: =SUM(D9:D38) -> -2596702

Sheet FEEDER Consumption 
A1: 44317
A2: POWER HOUSE FEEDER READING
B3: BLU FEEDER PANEL 1 | G3: BLU FEEDER PANEL 2 | L3: POWER HOUSE FEEDER PANEL NO:3 | Q3: Main Kitchen -7 | V3: Main Kitchen -10 | AA3: Water treatment Plant | AF3: Sewage treatment Plant | AK3: Laundry--8SSB | AP3: Laundry-9 | AU3: New staff accomodation (E0) | AZ3: Staff block-16(E2-E3) | BE3: Staff Block Feeder-3(E4-E5) | BJ3: Management block-5 | BO3: SNR STAFF BLOCK | BT3: RECEPTION | BY3: DIVE CENTER | CD3: DIESEL TANK JETTY METER | CI3: 301-307 | CN3: 308-314 | CS3: 315-320 | CX3: 401-407 | DC3: 408-414 | DH3: 415-420 | DM3: SPA - 1 | DR3: SPA - 2 | DW3: BLU KITCHEN - 1 | EB3: BLU KITCHEN - 2 | EG3: AL BARAKATH | EL3: STAFF KITCHEN | EQ3: MANAGR BLOCK GARDEN
A4: DAY | B4: Yesterday | C4: Today | D4: Consumption | E4: Variance (Tdy vs Ystdy) | F4: % | G4: Yesterday | H4: Today | I4: Consumption | J4: Var(Tdy vs Ystdy) | K4: % | L4: Yesterday | M4: Today | N4: Consumption | O4: Var (Tdy vs Ystdy) | P4: % | Q4: Yesterday | R4: Today | S4: Consumption | T4: Var(Tdy vs Ystdy) | U4: % | V4: Yesterday | W4: Today | X4: Consumption | Y4: Var(Tdy vs Ystdy) | Z4: % | AA4: Yesterday | AB4: Today | AC4: Consumption | AD4: Var(Tdy vs Ystdy) | AE4: % | AF4: Yesterday | AG4: Today | AH4: Consumption | AI4: Var(Tdy vs Ystdy) | AJ4: % | AK4: Yesterday | AL4: Today | AM4: Consumption | AN4: Var(Tdy vs Ystdy) | AO4: % | AP4: Yesterday | AQ4: Today | AR4: Consumption | AS4: Var(Tdy vs Ystdy) | AT4: % | AU4: Yesterday | AV4: Today | AW4: Consumption | AX4: Var(Tdy vs Ystdy) | AY4: % | AZ4: Yesterday | BA4: Today | BB4: Consumption | BC4: Var(Tdy vs Ystdy) | BD4: % | BE4: Yesterday | BF4: Today | BG4: Consumption | BH4: Var(Tdy vs Ystdy) | BI4: % | BJ4: Yesterday | BK4: Today | BL4: Consumption | BM4: Var(Tdy vs Ystdy) | BN4: % | BO4: Yesterday | BP4: Today | BQ4: Consumption | BR4: Var(Tdy vs Ystdy) | BS4: % | BT4: Yesterday | BU4: Today | BV4: Consumption | BW4: Var(Tdy vs Ystdy) | BX4: % | BY4: Yesterday | BZ4: Today | CA4: Consumption | CB4: Var(Tdy vs Ystdy) | CC4: % | CD4: Yesterday | CE4: Today | CF4: Consumption | CG4: Var(Tdy vs Ystdy) | CH4: % | CI4: Yesterday | CJ4: Today | CK4: Consumption | CL4: Var(Tdy vs Ystdy) | CM4: % | CN4: Yesterday | CO4: Today | CP4: Consumption | CQ4: Var(Tdy vs Ystdy) | CR4: % | CS4: Yesterday | CT4: Today | CU4: Consumption | CV4: Var(Tdy vs Ystdy) | CW4: % | CX4: Yesterday | CY4: Today | CZ4: Consumption | DA4: Var(Tdy vs Ystdy) | DB4: % | DC4: Yesterday | DD4: Today | DE4: Consumption | DF4: Var(Tdy vs Ystdy) | DG4: % | DH4: Yesterday | DI4: Today | DJ4: Consumption | DK4: Var(Tdy vs Ystdy) | DL4: % | DM4: Yesterday | DN4: Today | DO4: Consumption | DP4: Var(Tdy vs Ystdy) | DQ4: % | DR4: Yesterday | DS4: Today | DT4: Consumption | DU4: Var(Tdy vs Ystdy) | DV4: % | DW4: Yesterday | DX4: Today | DY4: Consumption | DZ4: Var(Tdy vs Ystdy) | EA4: % | EB4: Yesterday | EC4: Today | ED4: Consumption | EE4: Var(Tdy vs Ystdy) | EF4: % | EG4: Yesterday | EH4: Today | EI4: Consumption | EJ4: Var(Tdy vs Ystdy) | EK4: % | EL4: Yesterday | EM4: Today | EN4: Consumption | EO4: Var(Tdy vs Ystdy) | EP4: % | EQ4: Yesterday | ER4: Today | ES4: Consumption | ET4: Var(Tdy vs Ystdy) | EU4: %
A5: 1 | B5: 25532712 | C5: 25536808 | D5: =C5-B5 -> 4096 | G5: 22576918 | H5: 22582098 | I5: =H5-G5 -> 5180 | L5: 85421095 | M5: 85436113 | N5: =M5-L5 -> 15018 | Q5: 1966900 | R5: 1968900 | S5: =R5-Q5 -> 2000 | V5: 2662097 | W5: 2664993 | X5: =W5-V5 -> 2896 | AA5: 1618900 | AB5: 1620600 | AC5: =AB5-AA5 -> 1700 | AF5: 734522 | AG5: 735223 | AH5: =AG5-AF5 -> 701 | AK5: 7600100 | AL5: 7607100 | AM5: =AL5-AK5 -> 7000 | AP5: 1732600 | AQ5: 1733800 | AR5: =AQ5-AP5 -> 1200 | AU5: 494210 | AV5: 494652 | AW5: =AV5-AU5 -> 442 | AZ5: 628570 | BA5: 629570 | BB5: =BA5-AZ5 -> 1000 | BE5: 725910 | BF5: 727000 | BG5: =BF5-BE5 -> 1090 | BJ5: 1136100 | BK5: 1137600 | BL5: =BK5-BJ5 -> 1500 | BO5: 596350 | BP5: 598180 | BQ5: =BP5-BO5 -> 1830 | BT5: 457080 | BU5: 458360 | BV5: =BU5-BT5 -> 1280 | BY5: 1326100 | BZ5: 1331000 | CA5: =BZ5-BY5 -> 4900 | CD5: 626490 | CE5: 626890 | CF5: =CE5-CD5 -> 400 | CI5: 29873 | CJ5: 30083 | CK5: =CJ5-CI5 -> 210 | CN5: 23966 | CO5: 24227 | CP5: =CO5-CN5 -> 261 | CS5: 21609 | CT5: 21760 | CU5: =CT5-CS5 -> 151 | CX5: 33989 | CY5: 34228 | CZ5: =CY5-CX5 -> 239 | DC5: 25598 | DD5: 25857 | DE5: =DD5-DC5 -> 259 | DH5: 24150 | DI5: 24309 | DJ5: =DI5-DH5 -> 159 | DM5: 16546 | DN5: 16640 | DO5: =DN5-DM5 -> 94 | DR5: 44409 | DS5: 44672 | DT5: =DS5-DR5 -> 263 | DW5: 32323 | DX5: 32462 | DY5: =DX5-DW5 -> 139 | EB5: 97564 | EC5: 98073 | ED5: =EC5-EB5 -> 509 | EG5: 77254 | EH5: 78016 | EI5: =EH5-EG5 -> 762 | EL5: 16706 | EM5: 16803 | EN5: =EM5-EL5 -> 97 | EQ5: 202860 | ER5: 210970 | ES5: =ER5-EQ5 -> 8110
A6: 2 | B6: =C5 -> 25536808 | C6: 25540997 | D6: =C6-B6 -> 4189 | E6: =D6-D5 -> 93 | F6: =(D6/'Finance Only'!B9)*100 -> 13.342039 | G6: =H5 -> 22582098 | H6: 22587381 | I6: =H6-G6 -> 5283 | J6: =I6-I5 -> 103 | K6: =(I6/'Finance Only'!B9)*100 -> 16.826448 | L6: =M5 -> 85436113 | M6: 85452122 | N6: =M6-L6 -> 16009 | O6: =N6-N5 -> 991 | P6: =(N6/'Finance Only'!B9)*100 -> 50.988948 | Q6: =R5 -> 1968900 | R6: 1971000 | S6: =R6-Q6 -> 2100 | T6: =S6-S5 -> 100 | U6: =(S6/'Finance Only'!B9)*100 -> 6.6885371 | V6: =W5 -> 2664993 | W6: 2667886 | X6: =W6-V6 -> 2893 | Y6: =X6-X5 -> -3 | Z6: =(X6/'Finance Only'!B9)*100 -> 9.2142561 | AA6: =AB5 -> 1620600 | AB6: 1622400 | AC6: =AB6-AA6 -> 1800 | AD6: =AC6-AC5 -> 100 | AE6: =(AC6/'Finance Only'!B9)*100 -> 5.7330318 | AF6: =AG5 -> 735223 | AG6: 736018 | AH6: =AG6-AF6 -> 795 | AI6: =AH6-AH5 -> 94 | AJ6: =(AH6/'Finance Only'!B9)*100 -> 2.5320891 | AK6: =AL5 -> 7607100 | AL6: 7614500 | AM6: =AL6-AK6 -> 7400 | AN6: =AM6-AM5 -> 400 | AO6: =(AM6/'Finance Only'!B9)*100 -> 23.569131 | AP6: =AQ5 -> 1733800 | AQ6: 1735100 | AR6: =AQ6-AP6 -> 1300 | AS6: =AR6-AR5 -> 100 | AT6: =(AR6/'Finance Only'!B9)*100 -> 4.140523 | AU6: =AV5 -> 494652 | AV6: 495105 | AW6: =AV6-AU6 -> 453 | AX6: =AW6-AW5 -> 11 | AY6: =(AW6/'Finance Only'!B9)*100 -> 1.442813 | AZ6: =BA5 -> 629570 | BA6: 630630 | BB6: =BA6-AZ6 -> 1060 | BC6: =BB6-BB5 -> 60 | BD6: =(BB6/'Finance Only'!B9)*100 -> 3.3761187 | BE6: =BF5 -> 727000 | BF6: 728130 | BG6: =BF6-BE6 -> 1130 | BH6: =BG6-BG5 -> 40 | BI6: =(BG6/'Finance Only'!B9)*100 -> 3.59907 | BJ6: =BK5 -> 1137600 | BK6: 1139200 | BL6: =BK6-BJ6 -> 1600 | BM6: =BL6-BL5 -> 100 | BN6: =(BL6/'Finance Only'!B9)*100 -> 5.0960283 | BO6: =BP5 -> 598180 | BP6: 599950 | BQ6: =BP6-BO6 -> 1770 | BR6: =BQ6-BQ5 -> -60 | BS6: =(BQ6/'Finance Only'!B9)*100 -> 5.6374813 | BT6: =BU5 -> 458360 | BU6: 459700 | BV6: =BU6-BT6 -> 1340 | BW6: =BV6-BV5 -> 60 | BX6: =(BV6/'Finance Only'!B9)*100 -> 4.2679237 | BY6: =BZ5 -> 1331000 | BZ6: 1336100 | CA6: =BZ6-BY6 -> 5100 | CB6: =CA6-CA5 -> 200 | CC6: =(CA6/'Finance Only'!B9)*100 -> 16.24359 | CD6: =CE5 -> 626890 | CE6: 627530 | CF6: =CE6-CD6 -> 640 | CG6: =CF6-CF5 -> 240 | CH6: =(CF6/'Finance Only'!B9)*100 -> 2.0384113 | CI6: =CJ5 -> 30083 | CJ6: 30182 | CK6: =CJ6-CI6 -> 99 | CL6: =CK6-CK5 -> -111 | CM6: =(CK6/'Finance Only'!B9)*100 -> 0.31531675 | CN6: =CO5 -> 24227 | CO6: 24304 | CP6: =CO6-CN6 -> 77 | CQ6: =CP6-CP5 -> -184 | CR6: =(CP6/'Finance Only'!B9)*100 -> 0.24524636 | CS6: =CT5 -> 21760 | CT6: 21822 | CU6: =CT6-CS6 -> 62 | CV6: =CU6-CU5 -> -89 | CW6: =(CU6/'Finance Only'!B9)*100 -> 0.1974711 | CX6: =CY5 -> 34228 | CY6: 34346 | CZ6: =CY6-CX6 -> 118 | DA6: =CZ6-CZ5 -> -121 | DB6: =(CZ6/'Finance Only'!B9)*100 -> 0.37583209 | DC6: =DD5 -> 25857 | DD6: 25979 | DE6: =DD6-DC6 -> 122 | DF6: =DE6-DE5 -> -137 | DG6: =(DE6/'Finance Only'!B9)*100 -> 0.38857216 | DH6: =DI5 -> 24309 | DI6: 24384 | DJ6: =DI6-DH6 -> 75 | DK6: =DJ6-DJ5 -> -84 | DL6: =(DJ6/'Finance Only'!B9)*100 -> 0.23887633 | DM6: =DN5 -> 16640 | DN6: 16686 | DO6: =DN6-DM6 -> 46 | DP6: =DO6-DO5 -> -48 | DQ6: =(DO6/'Finance Only'!B9)*100 -> 0.14651081 | DR6: =DS5 -> 44672 | DS6: 44781 | DT6: =DS6-DR6 -> 109 | DU6: =DT6-DT5 -> -154 | DV6: =(DT6/'Finance Only'!B9)*100 -> 0.34716693 | DW6: =DX5 -> 32462 | DX6: 32528 | DY6: =DX6-DW6 -> 66 | DZ6: =DY6-DY5 -> -73 | EA6: =(DY6/'Finance Only'!B9)*100 -> 0.21021117 | EB6: =EC5 -> 98073 | EC6: 98334 | ED6: =EC6-EB6 -> 261 | EE6: =ED6-ED5 -> -248 | EF6: =(ED6/'Finance Only'!B9)*100 -> 0.83128961 | EG6: =EH5 -> 78016 | EH6: 78413 | EI6: =EH6-EG6 -> 397 | EJ6: =EI6-EI5 -> -365 | EK6: =(EI6/'Finance Only'!B9)*100 -> 1.264452 | EL6: =EM5 -> 16803 | EM6: 16841 | EN6: =EM6-EL6 -> 38 | EO6: =EN6-EN5 -> -59 | EP6: =(EN6/'Finance Only'!B9)*100 -> 0.12103067 | EQ6: =ER5 -> 210970 | ER6: 215130 | ES6: =ER6-EQ6 -> 4160 | ET6: =ES6-ES5 -> -3950 | EU6: =(ES6/'Finance Only'!B9)*100 -> 13.249674
A7: 3 | B7: =C6 -> 25540997 | C7: 25544804 | D7: =C7-B7 -> 3807 | E7: =D7-D6 -> -382 | F7: =(D7/'Finance Only'!B10)*100 -> 12.628122 | G7: =H6 -> 22587381 | H7: 22592255 | I7: =H7-G7 -> 4874 | J7: =I7-I6 -> -409 | K7: =(I7/'Finance Only'!B10)*100 -> 16.167446 | L7: =M6 -> 85452122 | M7: 85467711 | N7: =M7-L7 -> 15589 | O7: =N7-N6 -> -420 | P7: =(N7/'Finance Only'!B10)*100 -> 51.709955 | Q7: =R6 -> 1971000 | R7: 1973000 | S7: =R7-Q7 -> 2000 | T7: =S7-S6 -> -100 | U7: =(S7/'Finance Only'!B10)*100 -> 6.6341593 | V7: =W6 -> 2667886 | W7: 2670757 | X7: =W7-V7 -> 2871 | Y7: =X7-X6 -> -22 | Z7: =(X7/'Finance Only'!B10)*100 -> 9.5233357 | AA7: =AB6 -> 1622400 | AB7: 1624200 | AC7: =AB7-AA7 -> 1800 | AD7: =AC7-AC6 -> 0 | AE7: =(AC7/'Finance Only'!B10)*100 -> 5.9707434 | AF7: =AG6 -> 736018 | AG7: 736831 | AH7: =AG7-AF7 -> 813 | AI7: =AH7-AH6 -> 18 | AJ7: =(AH7/'Finance Only'!B10)*100 -> 2.6967857 | AK7: =AL6 -> 7614500 | AL7: 7621100 | AM7: =AL7-AK7 -> 6600 | AN7: =AM7-AM6 -> -800 | AO7: =(AM7/'Finance Only'!B10)*100 -> 21.892726 | AP7: =AQ6 -> 1735100 | AQ7: 1736500 | AR7: =AQ7-AP7 -> 1400 | AS7: =AR7-AR6 -> 100 | AT7: =(AR7/'Finance Only'!B10)*100 -> 4.6439115 | AU7: =AV6 -> 495105 | AV7: 495543 | AW7: =AV7-AU7 -> 438 | AX7: =AW7-AW6 -> -15 | AY7: =(AW7/'Finance Only'!B10)*100 -> 1.4528809 | AZ7: =BA6 -> 630630 | BA7: 631730 | BB7: =BA7-AZ7 -> 1100 | BC7: =BB7-BB6 -> 40 | BD7: =(BB7/'Finance Only'!B10)*100 -> 3.6487876 | BE7: =BF6 -> 728130 | BF7: 729280 | BG7: =BF7-BE7 -> 1150 | BH7: =BG7-BG6 -> 20 | BI7: =(BG7/'Finance Only'!B10)*100 -> 3.8146416 | BJ7: =BK6 -> 1139200 | BK7: 1140800 | BL7: =BK7-BJ7 -> 1600 | BM7: =BL7-BL6 -> 0 | BN7: =(BL7/'Finance Only'!B10)*100 -> 5.3073274 | BO7: =BP6 -> 599950 | BP7: 601740 | BQ7: =BP7-BO7 -> 1790 | BR7: =BQ7-BQ6 -> 20 | BS7: =(BQ7/'Finance Only'!B10)*100 -> 5.9375726 | BT7: =BU6 -> 459700 | BU7: 460950 | BV7: =BU7-BT7 -> 1250 | BW7: =BV7-BV6 -> -90 | BX7: =(BV7/'Finance Only'!B10)*100 -> 4.1463496 | BY7: =BZ6 -> 1336100 | BZ7: 1340800 | CA7: =BZ7-BY7 -> 4700 | CB7: =CA7-CA6 -> -400 | CC7: =(CA7/'Finance Only'!B10)*100 -> 15.590274 | CD7: =CE6 -> 627530 | CE7: 631240 | CF7: =CE7-CD7 -> 3710 | CG7: =CF7-CF6 -> 3070 | CH7: =(CF7/'Finance Only'!B10)*100 -> 12.306365 | CI7: =CJ6 -> 30182 | CJ7: 30268 | CK7: =CJ7-CI7 -> 86 | CL7: =CK7-CK6 -> -13 | CM7: =(CK7/'Finance Only'!B10)*100 -> 0.28526885 | CN7: =CO6 -> 24304 | CO7: 24381 | CP7: =CO7-CN7 -> 77 | CQ7: =CP7-CP6 -> 0 | CR7: =(CP7/'Finance Only'!B10)*100 -> 0.25541513 | CS7: =CT6 -> 21822 | CT7: 21878 | CU7: =CT7-CS7 -> 56 | CV7: =CU7-CU6 -> -6 | CW7: =(CU7/'Finance Only'!B10)*100 -> 0.18575646 | CX7: =CY6 -> 34346 | CY7: 34463 | CZ7: =CY7-CX7 -> 117 | DA7: =CZ7-CZ6 -> -1 | DB7: =(CZ7/'Finance Only'!B10)*100 -> 0.38809832 | DC7: =DD6 -> 25979 | DD7: 26091 | DE7: =DD7-DC7 -> 112 | DF7: =DE7-DE6 -> -10 | DG7: =(DE7/'Finance Only'!B10)*100 -> 0.37151292 | DH7: =DI6 -> 24384 | DI7: 24465 | DJ7: =DI7-DH7 -> 81 | DK7: =DJ7-DJ6 -> 6 | DL7: =(DJ7/'Finance Only'!B10)*100 -> 0.26868345 | DM7: =DN6 -> 16686 | DN7: 16732 | DO7: =DN7-DM7 -> 46 | DP7: =DO7-DO6 -> 0 | DQ7: =(DO7/'Finance Only'!B10)*100 -> 0.15258566 | DR7: =DS6 -> 44781 | DS7: 44913 | DT7: =DS7-DR7 -> 132 | DU7: =DT7-DT6 -> 23 | DV7: =(DT7/'Finance Only'!B10)*100 -> 0.43785451 | DW7: =DX6 -> 32528 | DX7: 32594 | DY7: =DX7-DW7 -> 66 | DZ7: =DY7-DY6 -> 0 | EA7: =(DY7/'Finance Only'!B10)*100 -> 0.21892726 | EB7: =EC6 -> 98334 | EC7: 98598 | ED7: =EC7-EB7 -> 264 | EE7: =ED7-ED6 -> 3 | EF7: =(ED7/'Finance Only'!B10)*100 -> 0.87570903 | EG7: =EH6 -> 78413 | EH7: 78841 | EI7: =EH7-EG7 -> 428 | EJ7: =EI7-EI6 -> 31 | EK7: =(EI7/'Finance Only'!B10)*100 -> 1.4197101 | EL7: =EM6 -> 16841 | EM7: 16898 | EN7: =EM7-EL7 -> 57 | EO7: =EN7-EN6 -> 19 | EP7: =(EN7/'Finance Only'!B10)*100 -> 0.18907354 | EQ7: =ER6 -> 215130 | ER7: 218430 | ES7: =ER7-EQ7 -> 3300 | ET7: =ES7-ES6 -> -860 | EU7: =(ES7/'Finance Only'!B10)*100 -> 10.946363
A8: 4 | B8: =C7 -> 25544804 | C8: 25548484 | D8: =C8-B8 -> 3680 | E8: =D8-D7 -> -127 | F8: =(D8/'Finance Only'!B11)*100 -> 12.776003 | G8: =H7 -> 22592255 | H8: 22596872 | I8: =H8-G8 -> 4617 | J8: =I8-I7 -> -257 | K8: =(I8/'Finance Only'!B11)*100 -> 16.029024 | L8: =M7 -> 85467711 | M8: 85482286 | N8: =M8-L8 -> 14575 | O8: =N8-N7 -> -1014 | P8: =(N8/'Finance Only'!B11)*100 -> 50.600611 | Q8: =R7 -> 1973000 | R8: 1975100 | S8: =R8-Q8 -> 2100 | T8: =S8-S7 -> 100 | U8: =(S8/'Finance Only'!B11)*100 -> 7.2906541 | V8: =W7 -> 2670757 | W8: 2673580 | X8: =W8-V8 -> 2823 | Y8: =X8-X7 -> -48 | Z8: =(X8/'Finance Only'!B11)*100 -> 9.8007221 | AA8: =AB7 -> 1624200 | AB8: 1625700 | AC8: =AB8-AA8 -> 1500 | AD8: =AC8-AC7 -> -300 | AE8: =(AC8/'Finance Only'!B11)*100 -> 5.2076101 | AF8: =AG7 -> 736831 | AG8: 737577 | AH8: =AG8-AF8 -> 746 | AI8: =AH8-AH7 -> -67 | AJ8: =(AH8/'Finance Only'!B11)*100 -> 2.5899181 | AK8: =AL7 -> 7621100 | AL8: 7627400 | AM8: =AL8-AK8 -> 6300 | AN8: =AM8-AM7 -> -300 | AO8: =(AM8/'Finance Only'!B11)*100 -> 21.871962 | AP8: =AQ7 -> 1736500 | AQ8: 1738000 | AR8: =AQ8-AP8 -> 1500 | AS8: =AR8-AR7 -> 100 | AT8: =(AR8/'Finance Only'!B11)*100 -> 5.2076101 | AU8: =AV7 -> 495543 | AV8: 495952 | AW8: =AV8-AU8 -> 409 | AX8: =AW8-AW7 -> -29 | AY8: =(AW8/'Finance Only'!B11)*100 -> 1.4199417 | AZ8: =BA7 -> 631730 | BA8: 632650 | BB8: =BA8-AZ8 -> 920 | BC8: =BB8-BB7 -> -180 | BD8: =(BB8/'Finance Only'!B11)*100 -> 3.1940008 | BE8: =BF7 -> 729280 | BF8: 730280 | BG8: =BF8-BE8 -> 1000 | BH8: =BG8-BG7 -> -150 | BI8: =(BG8/'Finance Only'!B11)*100 -> 3.47174 | BJ8: =BK7 -> 1140800 | BK8: 1142200 | BL8: =BK8-BJ8 -> 1400 | BM8: =BL8-BL7 -> -200 | BN8: =(BL8/'Finance Only'!B11)*100 -> 4.8604361 | BO8: =BP7 -> 601740 | BP8: 603270 | BQ8: =BP8-BO8 -> 1530 | BR8: =BQ8-BQ7 -> -260 | BS8: =(BQ8/'Finance Only'!B11)*100 -> 5.3117623 | BT8: =BU7 -> 460950 | BU8: 462230 | BV8: =BU8-BT8 -> 1280 | BW8: =BV8-BV7 -> 30 | BX8: =(BV8/'Finance Only'!B11)*100 -> 4.4438272 | BY8: =BZ7 -> 1340800 | BZ8: 1345100 | CA8: =BZ8-BY8 -> 4300 | CB8: =CA8-CA7 -> -400 | CC8: =(CA8/'Finance Only'!B11)*100 -> 14.928482 | CD8: =CE7 -> 631240 | CE8: 631740 | CF8: =CE8-CD8 -> 500 | CG8: =CF8-CF7 -> -3210 | CH8: =(CF8/'Finance Only'!B11)*100 -> 1.73587 | CI8: =CJ7 -> 30268 | CJ8: 30380 | CK8: =CJ8-CI8 -> 112 | CL8: =CK8-CK7 -> 26 | CM8: =(CK8/'Finance Only'!B11)*100 -> 0.38883488 | CN8: =CO7 -> 24381 | CO8: 24472 | CP8: =CO8-CN8 -> 91 | CQ8: =CP8-CP7 -> 14 | CR8: =(CP8/'Finance Only'!B11)*100 -> 0.31592834 | CS8: =CT7 -> 21878 | CT8: 21948 | CU8: =CT8-CS8 -> 70 | CV8: =CU8-CU7 -> 14 | CW8: =(CU8/'Finance Only'!B11)*100 -> 0.2430218 | CX8: =CY7 -> 34463 | CY8: 34578 | CZ8: =CY8-CX8 -> 115 | DA8: =CZ8-CZ7 -> -2 | DB8: =(CZ8/'Finance Only'!B11)*100 -> 0.3992501 | DC8: =DD7 -> 26091 | DD8: 26216 | DE8: =DD8-DC8 -> 125 | DF8: =DE8-DE7 -> 13 | DG8: =(DE8/'Finance Only'!B11)*100 -> 0.4339675 | DH8: =DI7 -> 24465 | DI8: 24549 | DJ8: =DI8-DH8 -> 84 | DK8: =DJ8-DJ7 -> 3 | DL8: =(DJ8/'Finance Only'!B11)*100 -> 0.29162616 | DM8: =DN7 -> 16732 | DN8: 16777 | DO8: =DN8-DM8 -> 45 | DP8: =DO8-DO7 -> -1 | DQ8: =(DO8/'Finance Only'!B11)*100 -> 0.1562283 | DR8: =DS7 -> 44913 | DS8: 45198 | DT8: =DS8-DR8 -> 285 | DU8: =DT8-DT7 -> 153 | DV8: =(DT8/'Finance Only'!B11)*100 -> 0.98944591 | DW8: =DX7 -> 32594 | DX8: 32668 | DY8: =DX8-DW8 -> 74 | DZ8: =DY8-DY7 -> 8 | EA8: =(DY8/'Finance Only'!B11)*100 -> 0.25690876 | EB8: =EC7 -> 98598 | EC8: 98881 | ED8: =EC8-EB8 -> 283 | EE8: =ED8-ED7 -> 19 | EF8: =(ED8/'Finance Only'!B11)*100 -> 0.98250243 | EG8: =EH7 -> 78841 | EH8: 79248 | EI8: =EH8-EG8 -> 407 | EJ8: =EI8-EI7 -> -21 | EK8: =(EI8/'Finance Only'!B11)*100 -> 1.4129982 | EL8: =EM7 -> 16898 | EM8: 16949 | EN8: =EM8-EL8 -> 51 | EO8: =EN8-EN7 -> -6 | EP8: =(EN8/'Finance Only'!B11)*100 -> 0.17705874 | EQ8: =ER7 -> 218430 | ER8: 221950 | ES8: =ER8-EQ8 -> 3520 | ET8: =ES8-ES7 -> 220 | EU8: =(ES8/'Finance Only'!B11)*100 -> 12.220525
A9: 5 | B9: =C8 -> 25548484 | C9: 25552440 | D9: =C9-B9 -> 3956 | E9: =D9-D8 -> 276 | F9: =(D9/'Finance Only'!B12)*100 -> 13.028157 | G9: =H8 -> 22596872 | H9: 22601861 | I9: =H9-G9 -> 4989 | J9: =I9-I8 -> 372 | K9: =(I9/'Finance Only'!B12)*100 -> 16.4301 | L9: =M8 -> 85482286 | M9: 85497398 | N9: =M9-L9 -> 15112 | O9: =N9-N8 -> 537 | P9: =(N9/'Finance Only'!B12)*100 -> 49.767825 | Q9: =R8 -> 1975100 | R9: 1977100 | S9: =R9-Q9 -> 2000 | T9: =S9-S8 -> -100 | U9: =(S9/'Finance Only'!B12)*100 -> 6.5865305 | V9: =W8 -> 2673580 | W9: 2676481 | X9: =W9-V9 -> 2901 | Y9: =X9-X8 -> 78 | Z9: =(X9/'Finance Only'!B12)*100 -> 9.5537626 | AA9: =AB8 -> 1625700 | AB9: 1627500 | AC9: =AB9-AA9 -> 1800 | AD9: =AC9-AC8 -> 300 | AE9: =(AC9/'Finance Only'!B12)*100 -> 5.9278775 | AF9: =AG8 -> 737577 | AG9: 738347 | AH9: =AG9-AF9 -> 770 | AI9: =AH9-AH8 -> 24 | AJ9: =(AH9/'Finance Only'!B12)*100 -> 2.5358143 | AK9: =AL8 -> 7627400 | AL9: 7634400 | AM9: =AL9-AK9 -> 7000 | AN9: =AM9-AM8 -> 700 | AO9: =(AM9/'Finance Only'!B12)*100 -> 23.052857 | AP9: =AQ8 -> 1738000 | AQ9: 1739400 | AR9: =AQ9-AP9 -> 1400 | AS9: =AR9-AR8 -> -100 | AT9: =(AR9/'Finance Only'!B12)*100 -> 4.6105714 | AU9: =AV8 -> 495952 | AV9: 496399 | AW9: =AV9-AU9 -> 447 | AX9: =AW9-AW8 -> 38 | AY9: =(AW9/'Finance Only'!B12)*100 -> 1.4720896 | AZ9: =BA8 -> 632650 | BA9: 633580 | BB9: =BA9-AZ9 -> 930 | BC9: =BB9-BB8 -> 10 | BD9: =(BB9/'Finance Only'!B12)*100 -> 3.0627367 | BE9: =BF8 -> 730280 | BF9: 731310 | BG9: =BF9-BE9 -> 1030 | BH9: =BG9-BG8 -> 30 | BI9: =(BG9/'Finance Only'!B12)*100 -> 3.3920632 | BJ9: =BK8 -> 1142200 | BK9: 1143700 | BL9: =BK9-BJ9 -> 1500 | BM9: =BL9-BL8 -> 100 | BN9: =(BL9/'Finance Only'!B12)*100 -> 4.9398979 | BO9: =BP8 -> 603270 | BP9: 605040 | BQ9: =BP9-BO9 -> 1770 | BR9: =BQ9-BQ8 -> 240 | BS9: =(BQ9/'Finance Only'!B12)*100 -> 5.8290795 | BT9: =BU8 -> 462230 | BU9: 463460 | BV9: =BU9-BT9 -> 1230 | BW9: =BV9-BV8 -> -50 | BX9: =(BV9/'Finance Only'!B12)*100 -> 4.0507163 | BY9: =BZ8 -> 1345100 | BZ9: 1349400 | CA9: =BZ9-BY9 -> 4300 | CB9: =CA9-CA8 -> 0 | CC9: =(CA9/'Finance Only'!B12)*100 -> 14.161041 | CD9: =CE8 -> 631740 | CE9: 632940 | CF9: =CE9-CD9 -> 1200 | CG9: =CF9-CF8 -> 700 | CH9: =(CF9/'Finance Only'!B12)*100 -> 3.9519183 | CI9: =CJ8 -> 30380 | CJ9: 30401 | CK9: =CJ9-CI9 -> 21 | CL9: =CK9-CK8 -> -91 | CM9: =(CK9/'Finance Only'!B12)*100 -> 0.069158571 | CN9: =CO8 -> 24472 | CO9: 24511 | CP9: =CO9-CN9 -> 39 | CQ9: =CP9-CP8 -> -52 | CR9: =(CP9/'Finance Only'!B12)*100 -> 0.12843735 | CS9: =CT8 -> 21948 | CT9: 22001 | CU9: =CT9-CS9 -> 53 | CV9: =CU9-CU8 -> -17 | CW9: =(CU9/'Finance Only'!B12)*100 -> 0.17454306 | CX9: =CY8 -> 34578 | CY9: 34612 | CZ9: =CY9-CX9 -> 34 | DA9: =CZ9-CZ8 -> -81 | DB9: =(CZ9/'Finance Only'!B12)*100 -> 0.11197102 | DC9: =DD8 -> 26216 | DD9: 26291 | DE9: =DD9-DC9 -> 75 | DF9: =DE9-DE8 -> -50 | DG9: =(DE9/'Finance Only'!B12)*100 -> 0.2469949 | DH9: =DI8 -> 24549 | DI9: 24612 | DJ9: =DI9-DH9 -> 63 | DK9: =DJ9-DJ8 -> -21 | DL9: =(DJ9/'Finance Only'!B12)*100 -> 0.20747571 | DM9: =DN8 -> 16777 | DN9: 16801 | DO9: =DN9-DM9 -> 24 | DP9: =DO9-DO8 -> -21 | DQ9: =(DO9/'Finance Only'!B12)*100 -> 0.079038367 | DR9: =DS8 -> 45198 | DS9: =45198+132 -> 45330 | DT9: =DS9-DR9 -> 132 | DU9: =DT9-DT8 -> -153 | DV9: =(DT9/'Finance Only'!B12)*100 -> 0.43471102 | DW9: =DX8 -> 32668 | DX9: 32600 | DY9: =DX9-DW9 -> -68 | DZ9: =DY9-DY8 -> -142 | EA9: =(DY9/'Finance Only'!B12)*100 -> -0.22394204 | EB9: =EC8 -> 98881 | EC9: 98991 | ED9: =EC9-EB9 -> 110 | EE9: =ED9-ED8 -> -173 | EF9: =(ED9/'Finance Only'!B12)*100 -> 0.36225918 | EG9: =EH8 -> 79248 | EH9: 79615 | EI9: =EH9-EG9 -> 367 | EJ9: =EI9-EI8 -> -40 | EK9: =(EI9/'Finance Only'!B12)*100 -> 1.2086284 | EL9: =EM8 -> 16949 | EM9: 16991 | EN9: =EM9-EL9 -> 42 | EO9: =EN9-EN8 -> -9 | EP9: =(EN9/'Finance Only'!B12)*100 -> 0.13831714 | EQ9: =ER8 -> 221950 | ER9: 224110 | ES9: =ER9-EQ9 -> 2160 | ET9: =ES9-ES8 -> -1360 | EU9: =(ES9/'Finance Only'!B12)*100 -> 7.113453
A10: 6 | B10: =C9 -> 25552440 | C10: 25556240 | D10: =C10-B10 -> 3800 | E10: =D10-D9 -> -156 | F10: =(D10/'Finance Only'!B13)*100 -> 12.70903 | G10: =H9 -> 22601861 | H10: 22606998 | I10: =H10-G10 -> 5137 | J10: =I10-I9 -> 148 | K10: =(I10/'Finance Only'!B13)*100 -> 17.180602 | L10: =M9 -> 85497398 | M10: 85512707 | N10: =M10-L10 -> 15309 | O10: =N10-N9 -> 197 | P10: =(N10/'Finance Only'!B13)*100 -> 51.200669 | Q10: =R9 -> 1977100 | R10: 1979200 | S10: =R10-Q10 -> 2100 | T10: =S10-S9 -> 100 | U10: =(S10/'Finance Only'!B13)*100 -> 7.0234114 | V10: =W9 -> 2676481 | W10: 2679281 | X10: =W10-V10 -> 2800 | Y10: =X10-X9 -> -101 | Z10: =(X10/'Finance Only'!B13)*100 -> 9.3645485 | AA10: =AB9 -> 1627500 | AB10: 1629400 | AC10: =AB10-AA10 -> 1900 | AD10: =AC10-AC9 -> 100 | AE10: =(AC10/'Finance Only'!B13)*100 -> 6.3545151 | AF10: =AG9 -> 738347 | AG10: 739125 | AH10: =AG10-AF10 -> 778 | AI10: =AH10-AH9 -> 8 | AJ10: =(AH10/'Finance Only'!B13)*100 -> 2.6020067 | AK10: =AL9 -> 7634400 | AL10: 7641300 | AM10: =AL10-AK10 -> 6900 | AN10: =AM10-AM9 -> -100 | AO10: =(AM10/'Finance Only'!B13)*100 -> 23.076923 | AP10: =AQ9 -> 1739400 | AQ10: 1740800 | AR10: =AQ10-AP10 -> 1400 | AS10: =AR10-AR9 -> 0 | AT10: =(AR10/'Finance Only'!B13)*100 -> 4.6822742 | AU10: =AV9 -> 496399 | AV10: 496808 | AW10: =AV10-AU10 -> 409 | AX10: =AW10-AW9 -> -38 | AY10: =(AW10/'Finance Only'!B13)*100 -> 1.367893 | AZ10: =BA9 -> 633580 | BA10: 634570 | BB10: =BA10-AZ10 -> 990 | BC10: =BB10-BB9 -> 60 | BD10: =(BB10/'Finance Only'!B13)*100 -> 3.3110368 | BE10: =BF9 -> 731310 | BF10: 732360 | BG10: =BF10-BE10 -> 1050 | BH10: =BG10-BG9 -> 20 | BI10: =(BG10/'Finance Only'!B13)*100 -> 3.5117057 | BJ10: =BK9 -> 1143700 | BK10: 1145200 | BL10: =BK10-BJ10 -> 1500 | BM10: =BL10-BL9 -> 0 | BN10: =(BL10/'Finance Only'!B13)*100 -> 5.0167224 | BO10: =BP9 -> 605040 | BP10: 607010 | BQ10: =BP10-BO10 -> 1970 | BR10: =BQ10-BQ9 -> 200 | BS10: =(BQ10/'Finance Only'!B13)*100 -> 6.5886288 | BT10: =BU9 -> 463460 | BU10: 464770 | BV10: =BU10-BT10 -> 1310 | BW10: =BV10-BV9 -> 80 | BX10: =(BV10/'Finance Only'!B13)*100 -> 4.3812709 | BY10: =BZ9 -> 1349400 | BZ10: 1354100 | CA10: =BZ10-BY10 -> 4700 | CB10: =CA10-CA9 -> 400 | CC10: =(CA10/'Finance Only'!B13)*100 -> 15.719064 | CD10: =CE9 -> 632940 | CE10: 634840 | CF10: =CE10-CD10 -> 1900 | CG10: =CF10-CF9 -> 700 | CH10: =(CF10/'Finance Only'!B13)*100 -> 6.3545151 | CI10: =CJ9 -> 30401 | CJ10: 30480 | CK10: =CJ10-CI10 -> 79 | CL10: =CK10-CK9 -> 58 | CM10: =(CK10/'Finance Only'!B13)*100 -> 0.26421405 | CN10: =CO9 -> 24511 | CO10: 24556 | CP10: =CO10-CN10 -> 45 | CQ10: =CP10-CP9 -> 6 | CR10: =(CP10/'Finance Only'!B13)*100 -> 0.15050167 | CS10: =CT9 -> 22001 | CT10: 22043 | CU10: =CT10-CS10 -> 42 | CV10: =CU10-CU9 -> -11 | CW10: =(CU10/'Finance Only'!B13)*100 -> 0.14046823 | CX10: =CY9 -> 34612 | CY10: 34700 | CZ10: =CY10-CX10 -> 88 | DA10: =CZ10-CZ9 -> 54 | DB10: =(CZ10/'Finance Only'!B13)*100 -> 0.29431438 | DC10: =DD9 -> 26291 | DD10: 26347 | DE10: =DD10-DC10 -> 56 | DF10: =DE10-DE9 -> -19 | DG10: =(DE10/'Finance Only'!B13)*100 -> 0.18729097 | DH10: =DI9 -> 24612 | DI10: 24643 | DJ10: =DI10-DH10 -> 31 | DK10: =DJ10-DJ9 -> -32 | DL10: =(DJ10/'Finance Only'!B13)*100 -> 0.10367893 | DM10: =DN9 -> 16801 | DN10: 16825 | DO10: =DN10-DM10 -> 24 | DP10: =DO10-DO9 -> 0 | DQ10: =(DO10/'Finance Only'!B13)*100 -> 0.080267559 | DR10: =DS9 -> 45330 | DS10: =45330+132 -> 45462 | DT10: =DS10-DR10 -> 132 | DU10: =DT10-DT9 -> 0 | DV10: =(DT10/'Finance Only'!B13)*100 -> 0.44147157 | DW10: =DX9 -> 32600 | DX10: 32736 | DY10: =DX10-DW10 -> 136 | DZ10: =DY10-DY9 -> 204 | EA10: =(DY10/'Finance Only'!B13)*100 -> 0.4548495 | EB10: =EC9 -> 98991 | EC10: 99138 | ED10: =EC10-EB10 -> 147 | EE10: =ED10-ED9 -> 37 | EF10: =(ED10/'Finance Only'!B13)*100 -> 0.4916388 | EG10: =EH9 -> 79615 | EH10: 79611 | EI10: =EH10-EG10 -> -4 | EJ10: =EI10-EI9 -> -371 | EK10: =(EI10/'Finance Only'!B13)*100 -> -0.013377926 | EL10: =EM9 -> 16991 | EM10: 16999 | EN10: =EM10-EL10 -> 8 | EO10: =EN10-EN9 -> -34 | EP10: =(EN10/'Finance Only'!B13)*100 -> 0.026755853 | EQ10: =ER9 -> 224110 | ER10: 225370 | ES10: =ER10-EQ10 -> 1260 | ET10: =ES10-ES9 -> -900 | EU10: =(ES10/'Finance Only'!B13)*100 -> 4.2140468
