Workbook

Sheet TOTAL
A1: Site Name | B1: Day | C1: Month | D1: Year | E1: Total Electricity Kwh | F1: Electricity Tariff ($/Kwh) | G1: Natual Gas (m3) | H1: Natural Gas $/m3 | I1: Water Utility Supply (m3) m3 | J1: Water Utility Supply (m3) $/m3 | K1: Room Nights
A2: Cairo at Nile Plaza | B2: 1 | C2: 5 | D2: 2021 | E2: =(((Submetering!O2+Submetering!P2)*0.842284+Submetering!Q2+(Submetering!M2+Submetering!N2+Submetering!Y2)*0.7362)+(Submetering!O2+Submetering!P2+Submetering!Q2)*0.1488+(Submetering!M2+Submetering!N2+Submetering!Y2)*0.1167+(Submetering!K2+Submetering!L2-Submetering!Z2-Submetering!AA2-Submetering!AB2-Submetering!AC2-Submetering!Q2)+(Submetering!M2+Submetering!N2+Submetering!Y2)*0.1139) -> 46519.885 | F2: 1.27 | G2: =Gas!C3*0.9147 -> 1407.7233 | H2: 3.65 | I2: =Submetering!H2+Submetering!AD2+Submetering!AE2 -> 326 | J2: 10.03 | K2: =ELECT.!B3 -> 78
A3: Cairo at Nile Plaza | B3: =B2+1 -> 2 | C3: 5 | D3: 2021 | E3: =(((Submetering!O3+Submetering!P3)*0.842284+Submetering!Q3+(Submetering!M3+Submetering!N3+Submetering!Y3)*0.7362)+(Submetering!O3+Submetering!P3+Submetering!Q3)*0.1488+(Submetering!M3+Submetering!N3+Submetering!Y3)*0.1167+(Submetering!K3+Submetering!L3-Submetering!Z3-Submetering!AA3-Submetering!AB3-Submetering!AC3-Submetering!Q3)+(Submetering!M3+Submetering!N3+Submetering!Y3)*0.1139) -> 45073.243 | F3: 1.27 | G3: =Gas!C4*0.9147 -> 1737.93 | H3: 3.65 | I3: =Submetering!H3+Submetering!AD3+Submetering!AE3 -> 496 | J3: 10.03 | K3: =ELECT.!B4 -> 79
A4: Cairo at Nile Plaza | B4: =B3+1 -> 3 | C4: 5 | D4: 2021 | E4: =(((Submetering!O4+Submetering!P4)*0.842284+Submetering!Q4+(Submetering!M4+Submetering!N4+Submetering!Y4)*0.7362)+(Submetering!O4+Submetering!P4+Submetering!Q4)*0.1488+(Submetering!M4+Submetering!N4+Submetering!Y4)*0.1167+(Submetering!K4+Submetering!L4-Submetering!Z4-Submetering!AA4-Submetering!AB4-Submetering!AC4-Submetering!Q4)+(Submetering!M4+Submetering!N4+Submetering!Y4)*0.1139) -> 48301.209 | F4: 1.27 | G4: =Gas!C5*0.9147 -> 1943.7375 | H4: 3.65 | I4: =Submetering!H4+Submetering!AD4+Submetering!AE4 -> 506 | J4: 10.03 | K4: =ELECT.!B5 -> 92
A5: Cairo at Nile Plaza | B5: =B4+1 -> 4 | C5: 5 | D5: 2021 | E5: =(((Submetering!O5+Submetering!P5)*0.842284+Submetering!Q5+(Submetering!M5+Submetering!N5+Submetering!Y5)*0.7362)+(Submetering!O5+Submetering!P5+Submetering!Q5)*0.1488+(Submetering!M5+Submetering!N5+Submetering!Y5)*0.1167+(Submetering!K5+Submetering!L5-Submetering!Z5-Submetering!AA5-Submetering!AB5-Submetering!AC5-Submetering!Q5)+(Submetering!M5+Submetering!N5+Submetering!Y5)*0.1139) -> 66452.334 | F5: 1.27 | G5: =Gas!C6*0.9147 -> 1794.6414 | H5: 3.65 | I5: =Submetering!H5+Submetering!AD5+Submetering!AE5 -> 556 | J5: 10.03 | K5: =ELECT.!B6 -> 68
A6: Cairo at Nile Plaza | B6: =B5+1 -> 5 | C6: 5 | D6: 2021 | E6: =(((Submetering!O6+Submetering!P6)*0.842284+Submetering!Q6+(Submetering!M6+Submetering!N6+Submetering!Y6)*0.7362)+(Submetering!O6+Submetering!P6+Submetering!Q6)*0.1488+(Submetering!M6+Submetering!N6+Submetering!Y6)*0.1167+(Submetering!K6+Submetering!L6-Submetering!Z6-Submetering!AA6-Submetering!AB6-Submetering!AC6-Submetering!Q6)+(Submetering!M6+Submetering!N6+Submetering!Y6)*0.1139) -> 53853.099 | F6: 1.27 | G6: =Gas!C7*0.9147 -> 1842.2058 | H6: 3.65 | I6: =Submetering!H6+Submetering!AD6+Submetering!AE6 -> 686 | J6: 10.03 | K6: =ELECT.!B7 -> 93
A7: Cairo at Nile Plaza | B7: =B6+1 -> 6 | C7: 5 | D7: 2021 | E7: =(((Submetering!O7+Submetering!P7)*0.842284+Submetering!Q7+(Submetering!M7+Submetering!N7+Submetering!Y7)*0.7362)+(Submetering!O7+Submetering!P7+Submetering!Q7)*0.1488+(Submetering!M7+Submetering!N7+Submetering!Y7)*0.1167+(Submetering!K7+Submetering!L7-Submetering!Z7-Submetering!AA7-Submetering!AB7-Submetering!AC7-Submetering!Q7)+(Submetering!M7+Submetering!N7+Submetering!Y7)*0.1139) -> 67567.259 | F7: 1.27 | G7: =Gas!C8*0.9147 -> 1943.7375 | H7: 3.65 | I7: =Submetering!H7+Submetering!AD7+Submetering!AE7 -> 456 | J7: 10.03 | K7: =ELECT.!B8 -> 65
A8: Cairo at Nile Plaza | B8: =B7+1 -> 7 | C8: 5 | D8: 2021 | E8: =(((Submetering!O8+Submetering!P8)*0.842284+Submetering!Q8+(Submetering!M8+Submetering!N8+Submetering!Y8)*0.7362)+(Submetering!O8+Submetering!P8+Submetering!Q8)*0.1488+(Submetering!M8+Submetering!N8+Submetering!Y8)*0.1167+(Submetering!K8+Submetering!L8-Submetering!Z8-Submetering!AA8-Submetering!AB8-Submetering!AC8-Submetering!Q8)+(Submetering!M8+Submetering!N8+Submetering!Y8)*0.1139) -> 48348.876 | F8: 1.27 | G8: =Gas!C9*0.9147 -> 1806.5325 | H8: 3.65 | I8: =Submetering!H8+Submetering!AD8+Submetering!AE8 -> 456 | J8: 10.03 | K8: =ELECT.!B9 -> 71
A9: Cairo at Nile Plaza | B9: =B8+1 -> 8 | C9: 5 | D9: 2021 | E9: =(((Submetering!O9+Submetering!P9)*0.842284+Submetering!Q9+(Submetering!M9+Submetering!N9+Submetering!Y9)*0.7362)+(Submetering!O9+Submetering!P9+Submetering!Q9)*0.1488+(Submetering!M9+Submetering!N9+Submetering!Y9)*0.1167+(Submetering!K9+Submetering!L9-Submetering!Z9-Submetering!AA9-Submetering!AB9-Submetering!AC9-Submetering!Q9)+(Submetering!M9+Submetering!N9+Submetering!Y9)*0.1139) -> 65945.19 | F9: 1.27 | G9: =Gas!C10*0.9147 -> 957.6909 | H9: 3.65 | I9: =Submetering!H9+Submetering!AD9+Submetering!AE9 -> 416 | J9: 10.03 | K9: =ELECT.!B10 -> 72
A10: Cairo at Nile Plaza | B10: =B9+1 -> 9 | C10: 5 | D10: 2021 | E10: =(((Submetering!O10+Submetering!P10)*0.842284+Submetering!Q10+(Submetering!M10+Submetering!N10+Submetering!Y10)*0.7362)+(Submetering!O10+Submetering!P10+Submetering!Q10)*0.1488+(Submetering!M10+Submetering!N10+Submetering!Y10)*0.1167+(Submetering!K10+Submetering!L10-Submetering!Z10-Submetering!AA10-Submetering!AB10-Submetering!AC10-Submetering!Q10)+(Submetering!M10+Submetering!N10+Submetering!Y10)*0.1139) -> 60596.906 | F10: 1.27 | G10: =Gas!C11*0.9147 -> 923.847 | H10: 3.65 | I10: =Submetering!H10+Submetering!AD10+Submetering!AE10 -> 416 | J10: 10.03 | K10: =ELECT.!B11 -> 85
A11: Cairo at Nile Plaza | B11: =B10+1 -> 10 | C11: 5 | D11: 2021 | E11: =(((Submetering!O11+Submetering!P11)*0.842284+Submetering!Q11+(Submetering!M11+Submetering!N11+Submetering!Y11)*0.7362)+(Submetering!O11+Submetering!P11+Submetering!Q11)*0.1488+(Submetering!M11+Submetering!N11+Submetering!Y11)*0.1167+(Submetering!K11+Submetering!L11-Submetering!Z11-Submetering!AA11-Submetering!AB11-Submetering!AC11-Submetering!Q11)+(Submetering!M11+Submetering!N11+Submetering!Y11)*0.1139) -> 55434.119 | F11: 1.27 | G11: =Gas!C12*0.9147 -> 2097.4071 | H11: 3.65 | I11: =Submetering!H11+Submetering!AD11+Submetering!AE11 -> 486 | J11: 10.03 | K11: =ELECT.!B12 -> 80
A12: Cairo at Nile Plaza | B12: =B11+1 -> 11 | C12: 5 | D12: 2021 | E12: =(((Submetering!O12+Submetering!P12)*0.842284+Submetering!Q12+(Submetering!M12+Submetering!N12+Submetering!Y12)*0.7362)+(Submetering!O12+Submetering!P12+Submetering!Q12)*0.1488+(Submetering!M12+Submetering!N12+Submetering!Y12)*0.1167+(Submetering!K12+Submetering!L12-Submetering!Z12-Submetering!AA12-Submetering!AB12-Submetering!AC12-Submetering!Q12)+(Submetering!M12+Submetering!N12+Submetering!Y12)*0.1139) -> 58152.603 | F12: 1.27 | G12: =Gas!C13*0.9147 -> 1965.6903 | H12: 3.65 | I12: =Submetering!H12+Submetering!AD12+Submetering!AE12 -> 416 | J12: 10.03 | K12: =ELECT.!B13 -> 81
A13: Cairo at Nile Plaza | B13: =B12+1 -> 12 | C13: 5 | D13: 2021 | E13: =(((Submetering!O13+Submetering!P13)*0.842284+Submetering!Q13+(Submetering!M13+Submetering!N13+Submetering!Y13)*0.7362)+(Submetering!O13+Submetering!P13+Submetering!Q13)*0.1488+(Submetering!M13+Submetering!N13+Submetering!Y13)*0.1167+(Submetering!K13+Submetering!L13-Submetering!Z13-Submetering!AA13-Submetering!AB13-Submetering!AC13-Submetering!Q13)+(Submetering!M13+Submetering!N13+Submetering!Y13)*0.1139) -> 68352.745 | F13: 1.27 | G13: =Gas!C14*0.9147 -> 1005.2553 | H13: 3.65 | I13: =Submetering!H13+Submetering!AD13+Submetering!AE13 -> 416 | J13: 10.03 | K13: =ELECT.!B14 -> 0
A14: Cairo at Nile Plaza | B14: =B13+1 -> 13 | C14: 5 | D14: 2021 | E14: =(((Submetering!O14+Submetering!P14)*0.842284+Submetering!Q14+(Submetering!M14+Submetering!N14+Submetering!Y14)*0.7362)+(Submetering!O14+Submetering!P14+Submetering!Q14)*0.1488+(Submetering!M14+Submetering!N14+Submetering!Y14)*0.1167+(Submetering!K14+Submetering!L14-Submetering!Z14-Submetering!AA14-Submetering!AB14-Submetering!AC14-Submetering!Q14)+(Submetering!M14+Submetering!N14+Submetering!Y14)*0.1139) -> 60880.377 | F14: 1.27 | G14: =Gas!C15*0.9147 -> 1573.284 | H14: 3.65 | I14: =Submetering!H14+Submetering!AD14+Submetering!AE14 -> 416 | J14: 10.03 | K14: =ELECT.!B15 -> 98
... A32: Cairo at Nile Plaza | B32: =B31+1 -> 31 | C32: 5 | D32: 2021 | E32: =(((Submetering!O32+Submetering!P32)*0.842284+Submetering!Q32+(Submetering!M32+Submetering!N32+Submetering!Y32)*0.7362)+(Submetering!O32+Submetering!P32+Submetering!Q32)*0.1488+(Submetering!M32+Submetering!N32+Submetering!Y32)*0.1167+(Submetering!K32+Submetering!L32-Submetering!Z32-Submetering!AA32-Submetering!AB32-Submetering!AC32-Submetering!Q32)+(Submetering!M32+Submetering!N32+Submetering!Y32)*0.1139) -> 0 | F32: 1.27 | G32: =Gas!C33*0.9147 -> 0 | H32: 3.65 | I32: =Submetering!H32+Submetering!AD32+Submetering!AE32 -> -194 | J32: 10.03 | K32: =ELECT.!B33 -> 0

Sheet Submetering
A1: Site Name | B1: Day | C1: Month | D1: Year | E1: Main (m3) | F1: Podium (m3) | G1: Hotel (m3) | H1: Large (m3) | I1: Feeder 1 (KWh) | J1: Feeder 2 (KWh) | K1: T1 (KWh) | L1: T2 (KWh) | M1: T3 (KWh) | N1: T4 (KWh) | O1: T5 (KWh) | P1: T7 (KWh) | Q1: New Chiller (KWh) | R1: Hotel (BTU) | S1: B.S (BTU) | T1: LS (BTU) | U1: Mall (BTU) | V1: AHU#25 (BTU) | W1: AHU#9 (BTU) | X1: Room Nights | Y1: Loss (KWH) | Z1: Mall (KWH) | AA1: Citadel (KWH) | AB1: Rotana (KWH) | AC1: CIB (KWH) | AD1: Plaza suits water consumption (M3) | AE1: Hotel water consumption (M3)
A2: Cairo at Nile Plaza | B2: 1 | C2: 5 | D2: 2021 | E2: =Water!C3 -> 520 | F2: =Water!E3 -> 288.9 | G2: =Water!G3 -> 270 | H2: =Water!I3 -> 2.808 | I2: =ELECT.!F3 -> 5933 | J2: =ELECT.!H3 -> 43187 | K2: =ELECT.!K3 -> 4797 | L2: =ELECT.!M3 -> 3630 | M2: =ELECT.!O3 -> 1986 | N2: =ELECT.!Q3 -> 10626 | O2: =ELECT.!S3 -> 7902 | P2: =ELECT.!W3*2 -> 18876 | Q2: =ELECT.!D3 -> 320 | R2: =BTU!C3 -> 7.244 | S2: =BTU!F3 -> 0.879 | T2: =BTU!I3 -> 8 | U2: =BTU!O3 -> 1.361 | V2: =BTU!L3 -> 2.6 | W2: =BTU!R3 -> 0.5 | X2: =ELECT.!B3 -> 78 | Y2: =I2+J2-(K2+L2+M2+N2+O2+P2) -> 1303 | Z2: ='Mall, Citadel, Rotana'!C3+'Mall, Citadel, Rotana'!E3+'Mall, Citadel, Rotana'!G3+'Mall, Citadel, Rotana'!I3 -> 1355 | AA2: ='Mall, Citadel, Rotana'!K3+'Mall, Citadel, Rotana'!M3 -> 480 | AB2: ='Mall, Citadel, Rotana'!O3 -> 3 | AC2: ='Mall, Citadel, Rotana'!Q3+'Mall, Citadel, Rotana'!S3 -> 109 | AD2: =(E2-H2-194)*0.1318 -> 42.596706 | AE2: =E2-H2-AD2-194 -> 280.59529
A3: Cairo at Nile Plaza | B3: =B2+1 -> 2 | C3: 5 | D3: 2021 | E3: =Water!C4 -> 690 | F3: =Water!E4 -> 394.2 | G3: =Water!G4 -> 297 | H3: =Water!I4 -> 3.564 | I3: =ELECT.!F4 -> 5534 | J3: =ELECT.!H4 -> 41635 | K3: =ELECT.!K4 -> 4668 | L3: =ELECT.!M4 -> 3359 | M3: =ELECT.!O4 -> 2258 | N3: =ELECT.!Q4 -> 10158 | O3: =ELECT.!S4 -> 7744 | P3: =ELECT.!W4*2 -> 18048 | Q3: =ELECT.!D4 -> 480 | R3: =BTU!C4 -> 8.355 | S3: =BTU!F4 -> 0.959 | T3: =BTU!I4 -> 7 | U3: =BTU!O4 -> 1.401 | V3: =BTU!L4 -> 2.82 | W3: =BTU!R4 -> 0.52 | X3: =ELECT.!B4 -> 79 | Y3: =I3+J3-(K3+L3+M3+N3+O3+P3) -> 934 | Z3: ='Mall, Citadel, Rotana'!C4+'Mall, Citadel, Rotana'!E4+'Mall, Citadel, Rotana'!G4+'Mall, Citadel, Rotana'!I4 -> 1063 | AA3: ='Mall, Citadel, Rotana'!K4+'Mall, Citadel, Rotana'!M4 -> 320 | AB3: ='Mall, Citadel, Rotana'!O4 -> 3 | AC3: ='Mall, Citadel, Rotana'!Q4+'Mall, Citadel, Rotana'!S4 -> 108 | AD3: =(E3-H3-194)*0.1318 -> 64.903065 | AE3: =E3-H3-AD3-194 -> 427.53294
A4: Cairo at Nile Plaza | B4: =B3+1 -> 3 | C4: 5 | D4: 2021 | E4: =Water!C5 -> 700 | F4: =Water!E5 -> 351 | G4: =Water!G5 -> 394.2 | H4: =Water!I5 -> 3.186 | I4: =ELECT.!F5 -> 6247 | J4: =ELECT.!H5 -> 44712 | K4: =ELECT.!K5 -> 4862 | L4: =ELECT.!M5 -> 3823 | M4: =ELECT.!O5 -> 2296 | N4: =ELECT.!Q5 -> 11595 | O4: =ELECT.!S5 -> 8162 | P4: =ELECT.!W5*2 -> 19028 | Q4: =ELECT.!D5 -> 480 | R4: =BTU!C5 -> 9.334 | S4: =BTU!F5 -> 0.943 | T4: =BTU!I5 -> 9 | U4: =BTU!O5 -> 0.877 | V4: =BTU!L5 -> 2.76 | W4: =BTU!R5 -> 4.13 | X4: =ELECT.!B5 -> 92 | Y4: =I4+J4-(K4+L4+M4+N4+O4+P4) -> 1193 | Z4: ='Mall, Citadel, Rotana'!C5+'Mall, Citadel, Rotana'!E5+'Mall, Citadel, Rotana'!G5+'Mall, Citadel, Rotana'!I5 -> 1247 | AA4: ='Mall, Citadel, Rotana'!K5+'Mall, Citadel, Rotana'!M5 -> 640 | AB4: ='Mall, Citadel, Rotana'!O5 -> 3 | AC4: ='Mall, Citadel, Rotana'!Q5+'Mall, Citadel, Rotana'!S5 -> 96 | AD4: =(E4-H4-194)*0.1318 -> 66.270885 | AE4: =E4-H4-AD4-194 -> 436.54311
A5: Cairo at Nile Plaza | B5: =B4+1 -> 4 | C5: 5 | D5: 2021 | E5: =Water!C6 -> 750 | F5: =Water!E6 -> 321.3 | G5: =Water!G6 -> 475.2 | H5: =Water!I6 -> 4.023 | I5: =ELECT.!F6 -> 11275 | J5: =ELECT.!H6 -> 57947 | K5: =ELECT.!K6 -> 6781 | L5: =ELECT.!M6 -> 5120 | M5: =ELECT.!O6 -> 5992 | N5: =ELECT.!Q6 -> 14337 | O5: =ELECT.!S6 -> 10434 | P5: =ELECT.!W6*2 -> 25028 | Q5: =ELECT.!D6 -> 640 | R5: =BTU!C6 -> 9.684 | S5: =BTU!F6 -> 1.791 | T5: =BTU!I6 -> 9 | U5: =BTU!O6 -> 1.416 | V5: =BTU!L6 -> 2.52 | W5: =BTU!R6 -> 1.62 | X5: =ELECT.!B6 -> 68 | Y5: =I5+J5-(K5+L5+M5+N5+O5+P5) -> 1530 | Z5: ='Mall, Citadel, Rotana'!C6+'Mall, Citadel, Rotana'!E6+'Mall, Citadel, Rotana'!G6+'Mall, Citadel, Rotana'!I6 -> 1234 | AA5: ='Mall, Citadel, Rotana'!K6+'Mall, Citadel, Rotana'!M6 -> 480 | AB5: ='Mall, Citadel, Rotana'!O6 -> 3 | AC5: ='Mall, Citadel, Rotana'!Q6+'Mall, Citadel, Rotana'!S6 -> 106 | AD5: =(E5-H5-194)*0.1318 -> 72.750569 | AE5: =E5-H5-AD5-194 -> 479.22643
A6: Cairo at Nile Plaza | B6: =B5+1 -> 5 | C6: 5 | D6: 2021 | E6: =Water!C7 -> 880 | F6: =Water!E7 -> 318.6 | G6: =Water!G7 -> 353.7 | H6: =Water!I7 -> 3.483 | I6: =ELECT.!F7 -> 11918 | J6: =ELECT.!H7 -> 44756 | K6: =ELECT.!K7 -> 5530 | L6: =ELECT.!M7 -> 3535 | M6: =ELECT.!O7 -> 8216 | N6: =ELECT.!Q7 -> 10354 | O6: =ELECT.!S7 -> 8515 | P6: =ELECT.!W7*2 -> 19252 | Q6: =ELECT.!D7 -> 480 | R6: =BTU!C7 -> 10.014 | S6: =BTU!F7 -> 2.658 | T6: =BTU!I7 -> 9 | U6: =BTU!O7 -> 1.051 | V6: =BTU!L7 -> 2.15 | W6: =BTU!R7 -> 2.48 | X6: =ELECT.!B7 -> 93 | Y6: =I6+J6-(K6+L6+M6+N6+O6+P6) -> 1272 | Z6: ='Mall, Citadel, Rotana'!C7+'Mall, Citadel, Rotana'!E7+'Mall, Citadel, Rotana'!G7+'Mall, Citadel, Rotana'!I7 -> 1231 | AA6: ='Mall, Citadel, Rotana'!K7+'Mall, Citadel, Rotana'!M7 -> 640 | AB6: ='Mall, Citadel, Rotana'!O7 -> 5 | AC6: ='Mall, Citadel, Rotana'!Q7+'Mall, Citadel, Rotana'!S7 -> 110 | AD6: =(E6-H6-194)*0.1318 -> 89.955741 | AE6: =E6-H6-AD6-194 -> 592.56126
A7: Cairo at Nile Plaza | B7: =B6+1 -> 6 | C7: 5 | D7: 2021 | E7: =Water!C8 -> 650 | F7: =Water!E8 -> 264.6 | G7: =Water!G8 -> 334.8 | H7: =Water!I8 -> 3.456 | I7: =ELECT.!F8 -> 15069 | J7: =ELECT.!H8 -> 55195 | K7: =ELECT.!K8 -> 6541 | L7: =ELECT.!M8 -> 4739 | M7: =ELECT.!O8 -> 10104 | N7: =ELECT.!Q8 -> 6193 | O7: =ELECT.!S8 -> 10940 | P7: =ELECT.!W8*2 -> 24100 | Q7: =ELECT.!D8 -> 320 | R7: =BTU!C8 -> 10.733 | S7: =BTU!F8 -> 2.343 | T7: =BTU!I8 -> 9 | U7: =BTU!O8 -> 1.046 | V7: =BTU!L8 -> 2.16 | W7: =BTU!R8 -> 1.57 | X7: =ELECT.!B8 -> 65 | Y7: =I7+J7-(K7+L7+M7+N7+O7+P7) -> 7647 | Z7: ='Mall, Citadel, Rotana'!C8+'Mall, Citadel, Rotana'!E8+'Mall, Citadel, Rotana'!G8+'Mall, Citadel, Rotana'!I8 -> 1058 | AA7: ='Mall, Citadel, Rotana'!K8+'Mall, Citadel, Rotana'!M8 -> 480 | AB7: ='Mall, Citadel, Rotana'!O8 -> 1 | AC7: ='Mall, Citadel, Rotana'!Q8+'Mall, Citadel, Rotana'!S8 -> 98 | AD7: =(E7-H7-194)*0.1318 -> 59.645299 | AE7: =E7-H7-AD7-194 -> 392.8987
A8: Cairo at Nile Plaza | B8: =B7+1 -> 7 | C8: 5 | D8: 2021 | E8: =Water!C9 -> 650 | F8: =Water!E9 -> 275.4 | G8: =Water!G9 -> 337.5 | H8: =Water!I9 -> 4.077 | I8: =ELECT.!F9 -> 10835 | J8: =ELECT.!H9 -> 40128 | K8: =ELECT.!K9 -> 0 | L8: =ELECT.!M9 -> 0 | M8: =ELECT.!O9 -> 7452 | N8: =ELECT.!Q9 -> 14757 | O8: =ELECT.!S9 -> 8000 | P8: =ELECT.!W9*2 -> 18084 | Q8: =ELECT.!D9 -> 480 | R8: =BTU!C9 -> 12.183 | S8: =BTU!F9 -> 1.757 | T8: =BTU!I9 -> 9 | U8: =BTU!O9 -> 1.212 | V8: =BTU!L9 -> 1.35 | W8: =BTU!R9 -> 3.34 | X8: =ELECT.!B9 -> 71 | Y8: =I8+J8-(K8+L8+M8+N8+O8+P8) -> 2670 | Z8: ='Mall, Citadel, Rotana'!C9+'Mall, Citadel, Rotana'!E9+'Mall, Citadel, Rotana'!G9+'Mall, Citadel, Rotana'!I9 -> 1232 | AA8: ='Mall, Citadel, Rotana'!K9+'Mall, Citadel, Rotana'!M9 -> 0 | AB8: ='Mall, Citadel, Rotana'!O9 -> 3 | AC8: ='Mall, Citadel, Rotana'!Q9+'Mall, Citadel, Rotana'!S9 -> 392 | AD8: =(E8-H8-194)*0.1318 -> 59.563451 | AE8: =E8-H8-AD8-194 -> 392.35955
A9: Cairo at Nile Plaza | B9: =B8+1 -> 8 | C9: 5 | D9: 2021 | E9: =Water!C10 -> 610 | F9: =Water!E10 -> 275.4 | G9: =Water!G10 -> 394.2 | H9: =Water!I10 -> 3.942 | I9: =ELECT.!F10 -> 13433 | J9: =ELECT.!H10 -> 52431 | K9: =ELECT.!K10 -> 55992 | L9: =ELECT.!M10 -> 53582 | M9: =ELECT.!O10 -> 9680 | N9: =ELECT.!Q10 -> 11482 | O9: =ELECT.!S10 -> 10346 | P9: =ELECT.!W10*2 -> 23322 | Q9: =ELECT.!D10 -> 480 | R9: =BTU!C10 -> 10.615 | S9: =BTU!F10 -> 1.736 | T9: =BTU!I10 -> 9 | U9: =BTU!O10 -> 1.32 | V9: =BTU!L10 -> 0 | W9: =BTU!R10 -> 0.94 | X9: =ELECT.!B10 -> 72 | Y9: =I9+J9-(K9+L9+M9+N9+O9+P9) -> -98540 | Z9: ='Mall, Citadel, Rotana'!C10+'Mall, Citadel, Rotana'!E10+'Mall, Citadel, Rotana'!G10+'Mall, Citadel, Rotana'!I10 -> 1224 | AA9: ='Mall, Citadel, Rotana'!K10+'Mall, Citadel, Rotana'!M10 -> 960 | AB9: ='Mall, Citadel, Rotana'!O10 -> 4 | AC9: ='Mall, Citadel, Rotana'!Q10+'Mall, Citadel, Rotana'!S10 -> 71 | AD9: =(E9-H9-194)*0.1318 -> 54.309244 | AE9: =E9-H9-AD9-194 -> 357.74876
A10: Cairo at Nile Plaza | B10: =B9+1 -> 9 | C10: 5 | D10: 2021 | E10: =Water!C11 -> 610 | F10: =Water!E11 -> 234.9 | G10: =Water!G11 -> 305.1 | H10: =Water!I11 -> 3.564 | I10: =ELECT.!F11 -> 14110 | J10: =ELECT.!H11 -> 49247 | K10: =ELECT.!K11 -> 5817 | L10: =ELECT.!M11 -> 4630 | M10: =ELECT.!O11 -> 9292 | N10: =ELECT.!Q11 -> 11694 | O10: =ELECT.!S11 -> 10812 | P10: =ELECT.!W11*2 -> 20702 | Q10: =ELECT.!D11 -> 640 | R10: =BTU!C11 -> 16.434 | S10: =BTU!F11 -> 2.96 | T10: =BTU!I11 -> 13 | U10: =BTU!O11 -> 2.002 | V10: =BTU!L11 -> 2.26 | W10: =BTU!R11 -> 0.89 | X10: =ELECT.!B11 -> 85 | Y10: =I10+J10-(K10+L10+M10+N10+O10+P10) -> 410 | Z10: ='Mall, Citadel, Rotana'!C11+'Mall, Citadel, Rotana'!E11+'Mall, Citadel, Rotana'!G11+'Mall, Citadel, Rotana'!I11 -> 1223 | AA10: ='Mall, Citadel, Rotana'!K11+'Mall, Citadel, Rotana'!M11 -> 480 | AB10: ='Mall, Citadel, Rotana'!O11 -> 3 | AC10: ='Mall, Citadel, Rotana'!Q11+'Mall, Citadel, Rotana'!S11 -> 158 | AD10: =(E10-H10-194)*0.1318 -> 54.359065 | AE10: =E10-H10-AD10-194 -> 358.07694
A11: Cairo at Nile Plaza | B11: =B10+1 -> 10 | C11: 5 | D11: 2021 | E11: =Water!C12 -> 680 | F11: =Water!E12 -> 345.6 | G11: =Water!G12 -> 388.8 | H11: =Water!I12 -> 3.834 | I11: =ELECT.!F12 -> 13321 | J11: =ELECT.!H12 -> 45004 | K11: =ELECT.!K12 -> 5408 | L11: =ELECT.!M12 -> 4494 | M11: =ELECT.!O12 -> 8654 | N11: =ELECT.!Q12 -> 10692 | O11: =ELECT.!S12 -> 8138 | P11: =ELECT.!W12*2 -> 18576 | Q11: =ELECT.!D12 -> 800 | R11: =BTU!C12 -> 9.035 | S11: =BTU!F12 -> 2.343 | T11: =BTU!I12 -> 7 | U11: =BTU!O12 -> 0.932 | V11: =BTU!L12 -> 1.42 | W11: =BTU!R12 -> 0.6 | X11: =ELECT.!B12 -> 80 | Y11: =I11+J11-(K11+L11+M11+N11+O11+P11) -> 2363 | Z11: ='Mall, Citadel, Rotana'!C12+'Mall, Citadel, Rotana'!E12+'Mall, Citadel, Rotana'!G12+'Mall, Citadel, Rotana'!I12 -> 1240 | AA11: ='Mall, Citadel, Rotana'!K12+'Mall, Citadel, Rotana'!M12 -> 640 | AB11: ='Mall, Citadel, Rotana'!O12 -> 3 | AC11: ='Mall, Citadel, Rotana'!Q12+'Mall, Citadel, Rotana'!S12 -> 168 | AD11: =(E11-H11-194)*0.1318 -> 63.549479 | AE11: =E11-H11-AD11-194 -> 418.61652
A12: Cairo at Nile Plaza | B12: =B11+1 -> 11 | C12: 5 | D12: 2021 | E12: =Water!C13 -> 610 | F12: =Water!E13 -> 291.6 | G12: =Water!G13 -> 345.6 | H12: =Water!I13 -> 3.105 | I12: =ELECT.!F13 -> 16445 | J12: =ELECT.!H13 -> 44157 | K12: =ELECT.!K13 -> 5384 | L12: =ELECT.!M13 -> 5757 | M12: =ELECT.!O13 -> 10512 | N12: =ELECT.!Q13 -> 10208 | O12: =ELECT.!S13 -> 8842 | P12: =ELECT.!W13*2 -> 18554 | Q12: =ELECT.!D13 -> 480 | R12: =BTU!C13 -> 12.122 | S12: =BTU!F13 -> 2.709 | T12: =BTU!I13 -> 10 | U12: =BTU!O13 -> 1.021 | V12: =BTU!L13 -> 2.45 | W12: =BTU!R13 -> 2.98 | X12: =ELECT.!B13 -> 81 | Y12: =I12+J12-(K12+L12+M12+N12+O12+P12) -> 1345 | Z12: ='Mall, Citadel, Rotana'!C13+'Mall, Citadel, Rotana'!E13+'Mall, Citadel, Rotana'!G13+'Mall, Citadel, Rotana'!I13 -> 1061 | AA12: ='Mall, Citadel, Rotana'!K13+'Mall, Citadel, Rotana'!M13 -> 480 | AB12: ='Mall, Citadel, Rotana'!O13 -> 3 | AC12: ='Mall, Citadel, Rotana'!Q13+'Mall, Citadel, Rotana'!S13 -> 0 | AD12: =(E12-H12-194)*0.1318 -> 54.419561 | AE12: =E12-H12-AD12-194 -> 358.47544
A13: Cairo at Nile Plaza | B13: =B12+1 -> 12 | C13: 5 | D13: 2021 | E13: =Water!C14 -> 610 | F13: =Water!E14 -> 267.3 | G13: =Water!G14 -> 310.5 | H13: =Water!I14 -> 3.591 | I13: =ELECT.!F14 -> 19410 | J13: =ELECT.!H14 -> 52219 | K13: =ELECT.!K14 -> 5976 | L13: =ELECT.!M14 -> 6101 | M13: =ELECT.!O14 -> 13104 | N13: =ELECT.!Q14 -> 11629 | O13: =ELECT.!S14 -> 10289 | P13: =ELECT.!W14*2 -> 22920 | Q13: =ELECT.!D14 -> 480 | R13: =BTU!C14 -> 8.079 | S13: =BTU!F14 -> 1.354 | T13: =BTU!I14 -> 7 | U13: =BTU!O14 -> 1 | V13: =BTU!L14 -> 1.89 | W13: =BTU!R14 -> 5 | X13: =ELECT.!B14 -> 0 | Y13: =I13+J13-(K13+L13+M13+N13+O13+P13) -> 1610 | Z13: ='Mall, Citadel, Rotana'!C14+'Mall, Citadel, Rotana'!E14+'Mall, Citadel, Rotana'!G14+'Mall, Citadel, Rotana'!I14 -> 1389 | AA13: ='Mall, Citadel, Rotana'!K14+'Mall, Citadel, Rotana'!M14 -> 480 | AB13: ='Mall, Citadel, Rotana'!O14 -> 3 | AC13: ='Mall, Citadel, Rotana'!Q14+'Mall, Citadel, Rotana'!S14 -> 305 | AD13: =(E13-H13-194)*0.1318 -> 54.355506 | AE13: =E13-H13-AD13-194 -> 358.05349
A14: Cairo at Nile Plaza | B14: =B13+1 -> 13 | C14: 5 | D14: 2021 | E14: =Water!C15 -> 610 | F14: =Water!E15 -> 318.6 | G14: =Water!G15 -> 310.5 | H14: =Water!I15 -> 1.782 | I14: =ELECT.!F15 -> 17810 | J14: =ELECT.!H15 -> 45905 | K14: =ELECT.!K15 -> 5037 | L14: =ELECT.!M15 -> 5454 | M14: =ELECT.!O15 -> 12118 | N14: =ELECT.!Q15 -> 10117 | O14: =ELECT.!S15 -> 9218 | P14: =ELECT.!W15*2 -> 20266 | Q14: =ELECT.!D15 -> 480 | R14: =BTU!C15 -> 8.477 | S14: =BTU!F15 -> 0.805 | T14: =BTU!I15 -> 8 | U14: =BTU!O15 -> 1.279 | V14: =BTU!L15 -> 2.21 | W14: =BTU!R15 -> 0 | X14: =ELECT.!B15 -> 98 | Y14: =I14+J14-(K14+L14+M14+N14+O14+P14) -> 1505 | Z14: ='Mall, Citadel, Rotana'!C15+'Mall, Citadel, Rotana'!E15+'Mall, Citadel, Rotana'!G15+'Mall, Citadel, Rotana'!I15 -> 1263 | AA14: ='Mall, Citadel, Rotana'!K15+'Mall, Citadel, Rotana'!M15 -> 480 | AB14: ='Mall, Citadel, Rotana'!O15 -> 4 | AC14: ='Mall, Citadel, Rotana'!Q15+'Mall, Citadel, Rotana'!S15 -> 108 | AD14: =(E14-H14-194)*0.1318 -> 54.593932 | AE14: =E14-H14-AD14-194 -> 359.62407
... A29: Cairo at Nile Plaza | B29: =B28+1 -> 28 | C29: 5 | D29: 2021 | E29: =Water!C30 -> 0 | F29: =Water!E30 -> 0 | G29: =Water!G30 -> 0 | H29: =Water!I30 -> 0 | I29: =ELECT.!F30 -> 0 | J29: =ELECT.!H30 -> 0 | K29: =ELECT.!K30 -> 0 | L29: =ELECT.!M30 -> 0 | M29: =ELECT.!O30 -> 0 | N29: =ELECT.!Q30 -> 0 | O29: =ELECT.!S30 -> 0 | P29: =ELECT.!W30*2 -> 0 | Q29: =ELECT.!D30 -> 0 | R29: =BTU!C30 -> 0 | S29: =BTU!F30 -> 0 | T29: =BTU!I30 -> 0 | U29: =BTU!O30 -> 0 | V29: =BTU!L30 -> 0 | W29: =BTU!R30 -> 0 | X29: =ELECT.!B30 -> 0 | Y29: =I29+J29-(K29+L29+M29+N29+O29+P29) -> 0 | Z29: ='Mall, Citadel, Rotana'!C30+'Mall, Citadel, Rotana'!E30+'Mall, Citadel, Rotana'!G30+'Mall, Citadel, Rotana'!I30 -> 0 | AA29: ='Mall, Citadel, Rotana'!K30+'Mall, Citadel, Rotana'!M30 -> 0 | AB29: ='Mall, Citadel, Rotana'!O30 -> 0 | AC29: ='Mall, Citadel, Rotana'!Q30+'Mall, Citadel, Rotana'!S30 -> 0 | AD29: =(E29-H29-194)*0.1318 -> -25.5692 | AE29: =E29-H29-AD29-194 -> -168.4308
A30: Cairo at Nile Plaza | B30: =B29+1 -> 29 | C30: 5 | D30: 2021 | E30: =Water!C31 -> 0 | F30: =Water!E31 -> 0 | G30: =Water!E31 -> 0 | H30: =Water!I31 -> 0 | I30: =Water!G31 -> 0 | J30: =ELECT.!H31 -> 0 | K30: =Water!I31 -> 0 | L30: =Water!J31 -> 0 | M30: =Water!K31 -> 0 | N30: =Water!L31 -> 0 | O30: =Water!M31 -> 0 | P30: =Water!N31 -> 0 | Q30: =Water!O31 -> 0 | R30: =BTU!C31 -> 0 | S30: =BTU!F31 -> 0 | T30: =BTU!I31 -> 0 | U30: =BTU!O31 -> 0 | V30: =BTU!L31 -> 0 | W30: =BTU!R31 -> 0 | X30: =ELECT.!B31 -> 0 | Y30: =I30+J30-(K30+L30+M30+N30+O30+P30) -> 0 | Z30: ='Mall, Citadel, Rotana'!C31+'Mall, Citadel, Rotana'!E31+'Mall, Citadel, Rotana'!G31+'Mall, Citadel, Rotana'!I31 -> 0 | AA30: ='Mall, Citadel, Rotana'!K31+'Mall, Citadel, Rotana'!M31 -> 0 | AB30: ='Mall, Citadel, Rotana'!O31 -> 0 | AC30: ='Mall, Citadel, Rotana'!Q31+'Mall, Citadel, Rotana'!S31 -> 0 | AD30: =(E30-H30-194)*0.1318 -> -25.5692 | AE30: =E30-H30-AD30-194 -> -168.4308
A31: Cairo at Nile Plaza | B31: =B30+1 -> 30 | C31: 5 | D31: 2021 | E31: =Water!C32 -> 0 | F31: =Water!E32 -> 0 | G31: =Water!E32 -> 0 | H31: =Water!I32 -> 0 | I31: =Water!G32 -> 0 | J31: =ELECT.!H32 -> 0 | K31: =Water!I32 -> 0 | L31: =Water!J32 -> 0 | M31: =Water!K32 -> 0 | N31: =Water!L32 -> 0 | O31: =Water!M32 -> 0 | P31: =Water!N32 -> 0 | Q31: =Water!O32 -> 0 | R31: =BTU!C32 -> 0 | S31: =BTU!F32 -> 0 | T31: =BTU!I32 -> 0 | U31: =BTU!O32 -> 0 | V31: =BTU!L32 -> 0 | W31: =BTU!R32 -> 0 | X31: =ELECT.!B32 -> 0 | Y31: =I31+J31-(K31+L31+M31+N31+O31+P31) -> 0 | Z31: ='Mall, Citadel, Rotana'!C32+'Mall, Citadel, Rotana'!E32+'Mall, Citadel, Rotana'!G32+'Mall, Citadel, Rotana'!I32 -> 0 | AA31: ='Mall, Citadel, Rotana'!K32+'Mall, Citadel, Rotana'!M32 -> 0 | AB31: ='Mall, Citadel, Rotana'!O32 -> 0 | AC31: ='Mall, Citadel, Rotana'!Q32+'Mall, Citadel, Rotana'!S32 -> 0 | AD31: =(E31-H31-194)*0.1318 -> -25.5692 | AE31: =E31-H31-AD31-194 -> -168.4308
A32: Cairo at Nile Plaza | B32: =B31+1 -> 31 | C32: 5 | D32: 2021 | E32: =Water!C33 -> 0 | F32: =Water!E33 -> 0 | G32: =Water!E33 -> 0 | H32: =Water!I33 -> 0 | I32: =Water!G33 -> 0 | J32: =ELECT.!H33 -> 0 | K32: =Water!I33 -> 0 | L32: =Water!J33 -> 0 | M32: =Water!K33 -> 0 | N32: =Water!L33 -> 0 | O32: =Water!M33 -> 0 | P32: =Water!N33 -> 0 | Q32: =Water!O33 -> 0 | R32: =BTU!C33 -> 0 | S32: =BTU!F33 -> 0 | T32: =BTU!I33 -> 0 | U32: =BTU!O33 -> 0 | V32: =BTU!L33 -> 0 | W32: =BTU!R33 -> 0 | X32: =ELECT.!B33 -> 0 | Y32: =I32+J32-(K32+L32+M32+N32+O32+P32) -> 0 | Z32: ='Mall, Citadel, Rotana'!C33+'Mall, Citadel, Rotana'!E33+'Mall, Citadel, Rotana'!G33+'Mall, Citadel, Rotana'!I33 -> 0 | AA32: ='Mall, Citadel, Rotana'!K33+'Mall, Citadel, Rotana'!M33 -> 0 | AB32: ='Mall, Citadel, Rotana'!O33 -> 0 | AC32: ='Mall, Citadel, Rotana'!Q33+'Mall, Citadel, Rotana'!S33 -> 0 | AD32: =(E32-H32-194)*0.1318 -> -25.5692 | AE32: =E32-H32-AD32-194 -> -168.4308

Sheet Mall, Citadel, Rotana
A1: Day | B1: R1 | C1: Cons | D1: R2 | E1: Cons | F1: R3 | G1: Cons | H1: R4 | I1: Cons | J1: RO1 | K1: Cons | L1: RO2 | M1: Cons | N1: ROE | O1: Cons | P1: CIB. 1 | Q1: Cons | R1: CIB. E | S1: Cons | T1: Co | U1: Cons
A2: 44316 | B2: 45185 | D2: 39472 | F2: 20316 | H2: 240785 | J2: 303517 | L2: 24882 | N2: 215446 | P2: 101751 | R2: 55047 | S2: =R2-R1 -> #VALUE! | T2: 3620
A3: 44317 | B3: 45190 | C3: =(B3-B2)*800/5 -> 800 | D3: 39475 | E3: =(D3-D2)*800/5 -> 480 | F3: 20319 | G3: =(F3-F2)*100/5 -> 60 | H3: 240800 | I3: =(H3-H2) -> 15 | J3: 303517 | K3: =(J3-J2)*800/5 -> 0 | L3: 24885 | M3: =(L3-L2)*800/5 -> 480 | N3: 215449 | O3: =N3-N2 -> 3 | P3: 101860 | Q3: =P3-P2 -> 109 | R3: 55047 | S3: =R3-R2 -> 0 | T3: 3621 | U3: =(T3-T2)*800/5 -> 160
A4: 44318 | B4: 45194 | C4: =(B4-B3)*800/5 -> 640 | D4: 39477 | E4: =(D4-D3)*800/5 -> 320 | F4: 20322 | G4: =(F4-F3)*100/5 -> 60 | H4: 240843 | I4: =(H4-H3) -> 43 | J4: 303517 | K4: =(J4-J3)*800/5 -> 0 | L4: 24887 | M4: =(L4-L3)*800/5 -> 320 | N4: 215452 | O4: =N4-N3 -> 3 | P4: 101968 | Q4: =P4-P3 -> 108 | R4: =R3 -> 55047 | S4: =R4-R3 -> 0 | T4: 3622 | U4: =(T4-T3)*800/5 -> 160
A5: 44319 | B5: 45198 | C5: =(B5-B4)*800/5 -> 640 | D5: 39480 | E5: =(D5-D4)*800/5 -> 480 | F5: 20325 | G5: =(F5-F4)*100/5 -> 60 | H5: 240910 | I5: =(H5-H4) -> 67 | J5: 303517 | K5: =(J5-J4)*800/5 -> 0 | L5: 24891 | M5: =(L5-L4)*800/5 -> 640 | N5: 215455 | O5: =N5-N4 -> 3 | P5: 102064 | Q5: =P5-P4 -> 96 | R5: =R4 -> 55047 | S5: =R5-R4 -> 0 | T5: 3622 | U5: =(T5-T4)*800/5 -> 0
A6: 44320 | B6: 45203 | C6: =(B6-B5)*800/5 -> 800 | D6: 39482 | E6: =(D6-D5)*800/5 -> 320 | F6: 20328 | G6: =(F6-F5)*100/5 -> 60 | H6: 240964 | I6: =(H6-H5) -> 54 | J6: 303517 | K6: =(J6-J5)*800/5 -> 0 | L6: 24894 | M6: =(L6-L5)*800/5 -> 480 | N6: 215458 | O6: =N6-N5 -> 3 | P6: 102170 | Q6: =P6-P5 -> 106 | R6: =R5 -> 55047 | S6: =R30-R5 -> 0 | T6: 3623 | U6: =(T6-T5)*800/5 -> 160
A7: 44321 | B7: 45208 | C7: =(B7-B6)*800/5 -> 800 | D7: 39484 | E7: =(D7-D6)*800/5 -> 320 | F7: 20331 | G7: =(F7-F6)*100/5 -> 60 | H7: 241015 | I7: =(H7-H6) -> 51 | J7: 303517 | K7: =(J7-J6)*800/5 -> 0 | L7: 24898 | M7: =(L7-L6)*800/5 -> 640 | N7: 215463 | O7: =N7-N6 -> 5 | P7: 102280 | Q7: =P7-P6 -> 110 | R7: =R6 -> 55047 | S7: =R7-R30 -> 0 | T7: 3624 | U7: =(T7-T6)*800/5 -> 160
A8: 44322 | B8: 45211 | C8: =(B8-B7)*800/5 -> 480 | D8: 39487 | E8: =(D8-D7)*800/5 -> 480 | F8: 20334 | G8: =(F8-F7)*100/5 -> 60 | H8: 241053 | I8: =(H8-H7) -> 38 | J8: 303517 | K8: =(J8-J7)*800/5 -> 0 | L8: 24901 | M8: =(L8-L7)*800/5 -> 480 | N8: 215464 | O8: =N8-N7 -> 1 | P8: 102378 | Q8: =P8-P7 -> 98 | R8: =R7 -> 55047 | S8: =R8-R7 -> 0 | T8: 3625 | U8: =(T8-T7)*800/5 -> 160
A9: 44323 | B9: 45215 | C9: =(B9-B8)*800/5 -> 640 | D9: 39490 | E9: =(D9-D8)*800/5 -> 480 | F9: 20337 | G9: =(F9-F8)*100/5 -> 60 | H9: 241105 | I9: =(H9-H8) -> 52 | J9: 303517 | K9: =(J9-J8)*800/5 -> 0 | L9: =L8 -> 24901 | M9: =(L9-L8)*800/5 -> 0 | N9: 215467 | O9: =N9-N8 -> 3 | P9: 102770 | Q9: =P9-P8 -> 392 | R9: 55047 | S9: =R9-R8 -> 0 | T9: 3626 | U9: =(T9-T8)*800/5 -> 160
A10: 44324 | B10: 45220 | C10: =(B10-B9)*800/5 -> 800 | D10: 39492 | E10: =(D10-D9)*800/5 -> 320 | F10: 20340 | G10: =(F10-F9)*100/5 -> 60 | H10: 241149 | I10: =(H10-H9) -> 44 | J10: 303517 | K10: =(J10-J9)*800/5 -> 0 | L10: 24907 | M10: =(L10-L9)*800/5 -> 960 | N10: 215471 | O10: =N10-N9 -> 4 | P10: 102841 | Q10: =P10-P9 -> 71 | R10: 55047 | S10: =R10-R9 -> 0 | T10: 3627 | U10: =(T10-T9)*800/5 -> 160
A11: 44325 | B11: 45224 | C11: =(B11-B10)*800/5 -> 640 | D11: 39495 | E11: =(D11-D10)*800/5 -> 480 | F11: 20343 | G11: =(F11-F10)*100/5 -> 60 | H11: 241192 | I11: =(H11-H10) -> 43 | J11: 303517 | K11: =(J11-J10)*800/5 -> 0 | L11: 24910 | M11: =(L11-L10)*800/5 -> 480 | N11: 215474 | O11: =N11-N10 -> 3 | P11: 102999 | Q11: =P11-P10 -> 158 | R11: 55047 | S11: =R11-R10 -> 0 | T11: 3628 | U11: =(T11-T10)*800/5 -> 160
A12: 44326 | B12: 45229 | C12: =(B12-B11)*800/5 -> 800 | D12: 39497 | E12: =(D12-D11)*800/5 -> 320 | F12: 20346 | G12: =(F12-F11)*100/5 -> 60 | H12: 241252 | I12: =(H12-H11) -> 60 | J12: 303517 | K12: =(J12-J11)*800/5 -> 0 | L12: 24914 | M12: =(L12-L11)*800/5 -> 640 | N12: 215477 | O12: =N12-N11 -> 3 | P12: 103167 | Q12: =P12-P11 -> 168 | R12: 55047 | S12: =R12-R11 -> 0 | T12: 3629 | U12: =(T12-T11)*800/5 -> 160
A13: 44327 | B13: 45233 | C13: =(B13-B12)*800/5 -> 640 | D13: 39499 | E13: =(D13-D12)*800/5 -> 320 | F13: 20349 | G13: =(F13-F12)*100/5 -> 60 | H13: 241293 | I13: =(H13-H12) -> 41 | J13: 303517 | K13: =(J13-J12)*800/5 -> 0 | L13: 24917 | M13: =(L13-L12)*800/5 -> 480 | N13: 215480 | O13: =N13-N12 -> 3 | P13: =P12 -> 103167 | Q13: =P13-P12 -> 0 | R13: 55047 | S13: =R13-R12 -> 0 | T13: 3629 | U13: =(T13-T12)*800/5 -> 0
A14: 44328 | B14: 45238 | C14: =(B14-B13)*800/5 -> 800 | D14: 39502 | E14: =(D14-D13)*800/5 -> 480 | F14: 20352 | G14: =(F14-F13)*100/5 -> 60 | H14: 241342 | I14: =(H14-H13) -> 49 | J14: 303517 | K14: =(J14-J13)*800/5 -> 0 | L14: 24920 | M14: =(L14-L13)*800/5 -> 480 | N14: 215483 | O14: =N14-N13 -> 3 | P14: 103472 | Q14: =P14-P13 -> 305 | R14: 55047 | S14: =R14-R13 -> 0 | T14: 3630 | U14: =(T14-T13)*800/5 -> 160
A15: 44329 | B15: 45242 | C15: =(B15-B14)*800/5 -> 640 | D15: 39505 | E15: =(D15-D14)*800/5 -> 480 | F15: 20356 | G15: =(F15-F14)*100/5 -> 80 | H15: 241405 | I15: =(H15-H14) -> 63 | J15: 303517 | K15: =(J15-J14)*800/5 -> 0 | L15: 24923 | M15: =(L15-L14)*800/5 -> 480 | N15: 215487 | O15: =N15-N14 -> 4 | P15: 103580 | Q15: =P15-P14 -> 108 | R15: 55047 | S15: =R15-R14 -> 0 | T15: 3631 | U15: =(T15-T14)*800/5 -> 160
A16: 44330 | B16: 45247 | C16: =(B16-B15)*800/5 -> 800 | D16: 39507 | E16: =(D16-D15)*800/5 -> 320 | F16: 20359 | G16: =(F16-F15)*100/5 -> 60 | H16: 241466 | I16: =(H16-H15) -> 61 | J16: 303517 | K16: =(J16-J15)*800/5 -> 0 | L16: 24926 | M16: =(L16-L15)*800/5 -> 480 | N16: 215490 | O16: =N16-N15 -> 3 | P16: 103646 | Q16: =P16-P15 -> 66 | R16: =R15 -> 55047 | S16: =R16-R15 -> 0 | T16: 3632 | U16: =(T16-T15)*800/5 -> 160
A17: 44331 | B17: 45251 | C17: =(B17-B16)*800/5 -> 640 | D17: 39509 | E17: =(D17-D16)*800/5 -> 320 | F17: 20362 | G17: =(F17-F16)*100/5 -> 60 | H17: 241510 | I17: =(H17-H16) -> 44 | J17: =J16 -> 303517 | K17: =(J17-J16)*800/5 -> 0 | L17: 24928 | M17: =(L17-L16)*800/5 -> 320 | N17: 215493 | O17: =N17-N16 -> 3 | P17: 103738 | Q17: =P17-P16 -> 92 | R17: =R16 -> 55047 | S17: =S16 -> 0 | T17: 3633 | U17: =(T17-T16)*800/5 -> 160
A18: 44332 | B18: 45257 | C18: =(B18-B17)*800/5 -> 960 | D18: 39513 | E18: =(D18-D17)*800/5 -> 640 | F18: 20365 | G18: =(F18-F17)*100/5 -> 60 | H18: 241586 | I18: =(H18-H17) -> 76 | J18: =J17 -> 303517 | K18: =(J18-J17)*800/5 -> 0 | L18: 24932 | M18: =(L18-L17)*800/5 -> 640 | N18: 215497 | O18: =N18-N17 -> 4 | P18: 103933 | Q18: =P18-P17 -> 195 | R18: 55047 | S18: =R18-R17 -> 0 | T18: 3634 | U18: =(T18-T17)*800/5 -> 160
A19: 44333 | B19: 45261 | C19: =(B19-B18)*800/5 -> 640 | D19: 39514 | E19: =(D19-D18)*800/5 -> 160 | F19: 20368 | G19: =(F19-F18)*100/5 -> 60 | H19: 241651 | I19: =(H19-H18) -> 65 | J19: =J18 -> 303517 | K19: =(J19-J18)*800/5 -> 0 | L19: 24935 | M19: =(L19-L18)*800/5 -> 480 | N19: 215500 | O19: =N19-N18 -> 3 | P19: 104132 | Q19: =P19-P18 -> 199 | R19: =R18 -> 55047 | S19: =R19-R18 -> 0 | T19: 3635 | U19: =(T19-T18)*800/5 -> 160
A20: 44334 | B20: 45267 | C20: =(B20-B19)*800/5 -> 960 | D20: 39517 | E20: =(D20-D19)*800/5 -> 480 | F20: 20371 | G20: =(F20-F19)*100/5 -> 60 | H20: 241718 | I20: =(H20-H19) -> 67 | J20: =J19 -> 303517 | K20: 0 | L20: 24939 | M20: =(L20-L19)*800/5 -> 640 | N20: 215504 | O20: =N20-N19 -> 4 | P20: 104329 | Q20: =P20-P19 -> 197 | R20: =R19 -> 55047 | S20: =R20-R19 -> 0 | T20: 3636 | U20: =(T20-T19)*800/5 -> 160
A21: 44335 | B21: 45272 | C21: =(B21-B20)*800/5 -> 800 | D21: 39521 | E21: =(D21-D20)*800/5 -> 640 | F21: 20374 | G21: =(F21-F20)*100/5 -> 60 | H21: 241785 | I21: =(H21-H20) -> 67 | J21: 303517 | K21: =(J21-J20)*800/5 -> 0 | L21: 24943 | M21: =(L21-L20)*800/5 -> 640 | N21: 215506 | O21: =N21-N20 -> 2 | P21: 104524 | Q21: =P21-P20 -> 195 | R21: 55247 | S21: =R21-R20 -> 200 | T21: 3638 | U21: =(T21-T20)*800/5 -> 320
A22: 44336 | B22: 45277 | C22: =(B22-B21)*800/5 -> 800 | D22: 39522 | E22: =(D22-D21)*800/5 -> 160 | F22: 20377 | G22: =(F22-F21)*100/5 -> 60 | H22: 241840 | I22: =(H22-H21) -> 55 | J22: 303517 | K22: =(J22-J21)*800/5 -> 0 | L22: 24946 | M22: =(L22-L21)*800/5 -> 480 | N22: 215510 | O22: =N22-N21 -> 4 | Q22: =P22-P21 -> -104524 | R22: 55047 | S22: =R22-R21 -> -200 | T22: 3639 | U22: =(T22-T21)*800/5 -> 160
A23: 44337 | B23: 45281 | C23: =(B23-B22)*800/5 -> 640 | D23: 39528 | E23: =(D23-D22)*800/5 -> 960 | F23: 20380 | G23: =(F23-F22)*100/5 -> 60 | H23: 241910 | I23: =(H23-H22) -> 70 | J23: 303517 | K23: =(J23-J22)*800/5 -> 0 | L23: 24949 | M23: =(L23-L22)*800/5 -> 480 | N23: 215513 | O23: =N23-N22 -> 3 | Q23: =P23-P22 -> 0 | R23: 55047 | S23: =R23-R22 -> 0 | T23: 3640 | U23: =(T23-T22)*800/5 -> 160
A24: 44338 | B24: 45285 | C24: =(B24-B23)*800/5 -> 640 | D24: 39537 | E24: =(D24-D23)*800/5 -> 1440 | F24: 20382 | G24: =(F24-F23)*100/5 -> 40 | H24: 241975 | I24: =(H24-H23) -> 65 | J24: 303517 | K24: =(J24-J23)*800/5 -> 0 | L24: 24952 | M24: =(L24-L23)*800/5 -> 480 | N24: 215516 | O24: =N24-N23 -> 3 | P24: =P23 -> 0 | Q24: =P24-P23 -> 0 | R24: 55097 | S24: =R24-R23 -> 50 | T24: 3641 | U24: =(T24-T23)*800/5 -> 160
A25: 44339 | B25: =B24 -> 45285 | C25: =(B25-B24)*800/5 -> 0 | D25: =D24 -> 39537 | E25: =(D25-D24)*800/5 -> 0 | F25: =F24 -> 20382 | G25: =(F25-F24)*100/5 -> 0 | H25: =H24 -> 241975 | I25: =(H25-H24) -> 0 | J25: 303517 | K25: =(J25-J24)*800/5 -> 0 | L25: =L24 -> 24952 | M25: =(L25-L24)*800/5 -> 0 | N25: =N24 -> 215516 | O25: =N25-N24 -> 0 | P25: =P24 -> 0 | Q25: =P25-P24 -> 0 | R25: =R24 -> 55097 | S25: =R25-R24 -> 0 | T25: =T24 -> 3641 | U25: =(T25-T24)*800/5 -> 0
A26: 44340 | B26: =B25 -> 45285 | C26: =(B26-B25)*800/5 -> 0 | D26: =D25 -> 39537 | E26: =(D26-D25)*800/5 -> 0 | F26: =F25 -> 20382 | G26: =(F26-F25)*100/5 -> 0 | H26: =H25 -> 241975 | I26: =(H26-H25) -> 0 | J26: 303517 | K26: =(J26-J25)*800/5 -> 0 | L26: =L25 -> 24952 | M26: =(L26-L25)*800/5 -> 0 | N26: =N25 -> 215516 | O26: =N26-N25 -> 0 | P26: =P25 -> 0 | Q26: =P26-P25 -> 0 | R26: 55047 | S26: =R26-R25 -> -50 | T26: =T25 -> 3641 | U26: =(T26-T25)*800/5 -> 0
A27: 44341 | B27: =B26 -> 45285 | C27: =(B27-B26)*800/5 -> 0 | D27: =D26 -> 39537 | E27: =(D27-D26)*800/5 -> 0 | F27: =F26 -> 20382 | G27: =(F27-F26)*100/5 -> 0 | H27: =H26 -> 241975 | I27: =(H27-H26) -> 0 | J27: 303517 | K27: =(J27-J26)*800/5 -> 0 | L27: =L26 -> 24952 | M27: =(L27-L26)*800/5 -> 0 | N27: =N26 -> 215516 | O27: =N27-N26 -> 0 | P27: =P26 -> 0 | Q27: =P27-P26 -> 0 | R27: 55047 | S27: =R27-R26 -> 0 | T27: =T26 -> 3641 | U27: =(T27-T26)*800/5 -> 0
A28: 44342 | B28: =B27 -> 45285 | C28: =(B28-B27)*800/5 -> 0 | D28: =D27 -> 39537 | E28: =(D28-D27)*800/5 -> 0 | F28: =F27 -> 20382 | G28: =(F28-F27)*100/5 -> 0 | H28: =H27 -> 241975 | I28: =(H28-H27) -> 0 | J28: 303517 | K28: =(J28-J27)*800/5 -> 0 | L28: =L27 -> 24952 | M28: =(L28-L27)*800/5 -> 0 | N28: =N27 -> 215516 | O28: =N28-N27 -> 0 | P28: =P27 -> 0 | Q28: =P28-P27 -> 0 | R28: 55047 | S28: =R28-R27 -> 0 | T28: =T27 -> 3641 | U28: =(T28-T27)*800/5 -> 0
A29: 44343 | B29: =B28 -> 45285 | C29: =(B29-B28)*800/5 -> 0 | D29: =D28 -> 39537 | E29: =(D29-D28)*800/5 -> 0 | F29: =F28 -> 20382 | G29: =(F29-F28)*100/5 -> 0 | H29: =H28 -> 241975 | I29: =(H29-H28) -> 0 | J29: 303517 | K29: =(J29-J28)*800/5 -> 0 | L29: =L28 -> 24952 | M29: =(L29-L28)*800/5 -> 0 | N29: =N28 -> 215516 | O29: =N29-N28 -> 0 | P29: =P28 -> 0 | Q29: =P29-P28 -> 0 | R29: 55047 | S29: =R29-R28 -> 0 | T29: =T28 -> 3641 | U29: =(T29-T28)*800/5 -> 0
A30: 44344 | B30: =B29 -> 45285 | C30: =(B30-B29)*800/5 -> 0 | D30: =D29 -> 39537 | E30: =(D30-D29)*800/5 -> 0 | F30: =F29 -> 20382 | G30: =(F30-F29)*100/5 -> 0 | H30: =H29 -> 241975 | I30: =(H30-H29) -> 0 | J30: =J29 -> 303517 | K30: =(J30-J29)*800/5 -> 0 | L30: =L29 -> 24952 | M30: =(L30-L29)*800/5 -> 0 | N30: =N29 -> 215516 | O30: =N30-N29 -> 0 | P30: =P29 -> 0 | Q30: =P30-P29 -> 0 | R30: 55047 | S30: =R30-R29 -> 0 | T30: =T29 -> 3641 | U30: =(T30-T29)*800/5 -> 0
A31: 44345 | B31: =B30 -> 45285 | C31: =(B31-B30)*800/5 -> 0 | D31: =D30 -> 39537 | E31: =(D31-D30)*800/5 -> 0 | F31: =F30 -> 20382 | G31: =(F31-F30)*100/5 -> 0 | H31: =H30 -> 241975 | I31: =(H31-H30) -> 0 | J31: =J30 -> 303517 | K31: =(J31-J30)*800/5 -> 0 | L31: =L30 -> 24952 | M31: =(L31-L30)*800/5 -> 0 | N31: =N30 -> 215516 | O31: =N31-N30 -> 0 | P31: =P30 -> 0 | Q31: =P31-P30 -> 0 | R31: =R30 -> 55047 | S31: =R31-R30 -> 0 | T31: =T30 -> 3641 | U31: =(T31-T30)*800/5 -> 0
A32: 44346 | B32: =B31 -> 45285 | C32: =(B32-B31)*800/5 -> 0 | D32: =D31 -> 39537 | E32: =(D32-D31)*800/5 -> 0 | F32: =F31 -> 20382 | G32: =(F32-F31)*100/5 -> 0 | H32: =H31 -> 241975 | I32: =(H32-H31) -> 0 | J32: =J31 -> 303517 | K32: =(J32-J31)*800/5 -> 0 | L32: =L31 -> 24952 | M32: =(L32-L31)*800/5 -> 0 | N32: =N31 -> 215516 | O32: =N32-N31 -> 0 | P32: =P31 -> 0 | Q32: =P32-P31 -> 0 | R32: 55047 | S32: =R32-R31 -> 0 | T32: =T31 -> 3641 | U32: =(T32-T31)*800/5 -> 0
A33: 44347 | B33: =B32 -> 45285 | C33: =(B33-B32)*800/5 -> 0 | D33: =D32 -> 39537 | E33: =(D33-D32)*800/5 -> 0 | F33: =F32 -> 20382 | G33: =(F33-F32)*100/5 -> 0 | H33: =H32 -> 241975 | I33: =(H33-H32) -> 0 | J33: =J32 -> 303517 | K33: =(J33-J32)*800/5 -> 0 | L33: =L32 -> 24952 | M33: =(L33-L32)*800/5 -> 0 | N33: =N32 -> 215516 | O33: =N33-N32 -> 0 | P33: =P32 -> 0 | Q33: =P33-P32 -> 0 | R33: 55047 | S33: =R33-R32 -> 0 | T33: =T32 -> 3641 | U33: =(T33-T32)*800/5 -> 0
A34: Total | C34: =SUM(C3:C33) -> 16000 | E34: =SUM(E3:E33) -> 10400 | G34: =SUM(G3:G33) -> 1320 | I34: =SUM(I3:I33) -> 1190 | K34: =SUM(K3:K33) -> 0 | M34: =SUM(M3:M33) -> 11200 | O34: =SUM(O3:O33) -> 70 | Q34: =SUM(Q3:Q33) -> -101751 | S34: =SUM(S3:S33) -> 0 | U34: =SUM(U3:U33) -> 3360

Sheet Water
A1: Day | B1: Main Reading | C1: Cons. | D1: Podium | E1: Cons. | F1: Hotel | G1: Cons. | H1: Large | I1: Cons. | J1: Total | K1: cost.LE
A2: 44316 | B2: 409858 | D2: 4167000 | F2: 2826800 | H2: 730558
A3: 44317 | B3: 409910 | C3: =(IF((B3-B2)<0,"0",(B3-B2)))*10 -> 520 | D3: 4177700 | E3: =(IF((D3-D2)<0,"0",(D3-D2)))*0.027 -> 288.9 | F3: 2836800 | G3: =(IF((F3-F2)<0,"0",(F3-F2)))*0.027 -> 270 | H3: 730662 | I3: =(IF((H3-H2)<0,"0",(H3-H2)))*0.027 -> 2.808 | J3: 1294.148 | K3: 7583.7073
A4: 44318 | B4: 409979 | C4: =(IF((B4-B3)<0,"0",(B4-B3)))*10 -> 690 | D4: 4192300 | E4: =(IF((D4-D3)<0,"0",(D4-D3)))*0.027 -> 394.2 | F4: 2847800 | G4: =(IF((F4-F3)<0,"0",(F4-F3)))*0.027 -> 297 | H4: 730794 | I4: =(IF((H4-H3)<0,"0",(H4-H3)))*0.027 -> 3.564 | J4: =C4+E4+G4+I4 -> 1384.764 | K4: =J4*5.86 -> 8114.717
A5: 44319 | B5: 410049 | C5: =(IF((B5-B4)<0,"0",(B5-B4)))*10 -> 700 | D5: 4205300 | E5: =(IF((D5-D4)<0,"0",(D5-D4)))*0.027 -> 351 | F5: 2862400 | G5: =(IF((F5-F4)<0,"0",(F5-F4)))*0.027 -> 394.2 | H5: 730912 | I5: =(IF((H5-H4)<0,"0",(H5-H4)))*0.027 -> 3.186 | J5: =C5+E5+G5+I5 -> 1448.386 | K5: =J5*5.86 -> 8487.542
A6: 44320 | B6: 410124 | C6: =(IF((B6-B5)<0,"0",(B6-B5)))*10 -> 750 | D6: 4217200 | E6: =(IF((D6-D5)<0,"0",(D6-D5)))*0.027 -> 321.3 | F6: 2880000 | G6: =(IF((F6-F5)<0,"0",(F6-F5)))*0.027 -> 475.2 | H6: 731061 | I6: =(IF((H6-H5)<0,"0",(H6-H5)))*0.027 -> 4.023 | J6: =C6+E6+G6+I6 -> 1550.523 | K6: =J6*5.86 -> 9086.0648
A7: 44321 | B7: 410212 | C7: =(IF((B7-B6)<0,"0",(B7-B6)))*10 -> 880 | D7: 4229000 | E7: =(IF((D7-D6)<0,"0",(D7-D6)))*0.027 -> 318.6 | F7: 2893100 | G7: =(IF((F7-F6)<0,"0",(F7-F6)))*0.027 -> 353.7 | H7: 731190 | I7: =(IF((H7-H6)<0,"0",(H7-H6)))*0.027 -> 3.483 | J7: =C7+E7+G7+I7 -> 1555.783 | K7: =J7*5.86 -> 9116.8884
A8: 44322 | B8: 410277 | C8: =(IF((B8-B7)<0,"0",(B8-B7)))*10 -> 650 | D8: 4238800 | E8: =(IF((D8-D7)<0,"0",(D8-D7)))*0.027 -> 264.6 | F8: 2905500 | G8: =(IF((F8-F7)<0,"0",(F8-F7)))*0.027 -> 334.8 | H8: 731318 | I8: =(IF((H8-H7)<0,"0",(H8-H7)))*0.027 -> 3.456 | J8: =C8+E8+G8+I8 -> 1252.856 | K8: =J8*5.86 -> 7341.7362
A9: 44323 | B9: 410342 | C9: =(IF((B9-B8)<0,"0",(B9-B8)))*10 -> 650 | D9: 4249000 | E9: =(IF((D9-D8)<0,"0",(D9-D8)))*0.027 -> 275.4 | F9: 2918000 | G9: =(IF((F9-F8)<0,"0",(F9-F8)))*0.027 -> 337.5 | H9: 731469 | I9: =(IF((H9-H8)<0,"0",(H9-H8)))*0.027 -> 4.077 | J9: =C9+E9+G9+I9 -> 1266.977 | K9: =J9*5.86 -> 7424.4852
A10: 44324 | B10: 410403 | C10: =(IF((B10-B9)<0,"0",(B10-B9)))*10 -> 610 | D10: 4259200 | E10: =(IF((D10-D9)<0,"0",(D10-D9)))*0.027 -> 275.4 | F10: 2932600 | G10: =(IF((F10-F9)<0,"0",(F10-F9)))*0.027 -> 394.2 | H10: 731615 | I10: =(IF((H10-H9)<0,"0",(H10-H9)))*0.027 -> 3.942 | J10: =C10+E10+G10+I10 -> 1283.542 | K10: =J10*5.86 -> 7521.5561
A11: 44325 | B11: 410464 | C11: =(IF((B11-B10)<0,"0",(B11-B10)))*10 -> 610 | D11: 4267900 | E11: =(IF((D11-D10)<0,"0",(D11-D10)))*0.027 -> 234.9 | F11: 2943900 | G11: =(IF((F11-F10)<0,"0",(F11-F10)))*0.027 -> 305.1 | H11: 731747 | I11: =(IF((H11-H10)<0,"0",(H11-H10)))*0.027 -> 3.564 | J11: =C11+E11+G11+I11 -> 1153.564 | K11: =J11*5.86 -> 6759.885
A12: 44326 | B12: 410532 | C12: =(IF((B12-B11)<0,"0",(B12-B11)))*10 -> 680 | D12: 4280700 | E12: =(IF((D12-D11)<0,"0",(D12-D11)))*0.027 -> 345.6 | F12: 2958300 | G12: =(IF((F12-F11)<0,"0",(F12-F11)))*0.027 -> 388.8 | H12: 731889 | I12: =(IF((H12-H11)<0,"0",(H12-H11)))*0.027 -> 3.834 | J12: =C12+E12+G12+I12 -> 1418.234 | K12: =J12*5.86 -> 8310.8512
A13: 44327 | B13: 410593 | C13: =(IF((B13-B12)<0,"0",(B13-B12)))*10 -> 610 | D13: 4291500 | E13: =(IF((D13-D12)<0,"0",(D13-D12)))*0.027 -> 291.6 | F13: 2971100 | G13: =(IF((F13-F12)<0,"0",(F13-F12)))*0.027 -> 345.6 | H13: 732004 | I13: =(IF((H13-H12)<0,"0",(H13-H12)))*0.027 -> 3.105 | J13: =C13+E13+G13+I13 -> 1250.305 | K13: =J13*5.86 -> 7326.7873
A14: 44328 | B14: 410654 | C14: =(IF((B14-B13)<0,"0",(B14-B13)))*10 -> 610 | D14: 4301400 | E14: =(IF((D14-D13)<0,"0",(D14-D13)))*0.027 -> 267.3 | F14: 2982600 | G14: =(IF((F14-F13)<0,"0",(F14-F13)))*0.027 -> 310.5 | H14: 732137 | I14: =(IF((H14-H13)<0,"0",(H14-H13)))*0.027 -> 3.591 | J14: =C14+E14+G14+I14 -> 1191.391 | K14: =J14*5.86 -> 6981.5513
A15: 44329 | B15: 410715 | C15: =(IF((B15-B14)<0,"0",(B15-B14)))*10 -> 610 | D15: 4313200 | E15: =(IF((D15-D14)<0,"0",(D15-D14)))*0.027 -> 318.6 | F15: 2994100 | G15: =(IF((F15-F14)<0,"0",(F15-F14)))*0.027 -> 310.5 | H15: 732203 | I15: =(IF((H15-H14)<0,"0",(H15-H14)))*0.027 -> 1.782 | J15: =C15+E15+G15+I15 -> 1240.882 | K15: =J15*5.86 -> 7271.5685
... A17: 44331 | B17: 410837 | C17: =(IF((B17-B16)<0,"0",(B17-B16)))*10 -> 610 | D17: 4337200 | E17: =(IF((D17-D16)<0,"0",(D17-D16)))*0.027 -> 340.2 | F17: 3022100 | G17: =(IF((F17-F16)<0,"0",(F17-F16)))*0.027 -> 575.1 | H17: 732341 | I17: =(IF((H17-H16)<0,"0",(H17-H16)))*0.027 -> 2.133 | J17: =C17+E17+G17+I17 -> 1527.433 | K17: =J17*5.86 -> 8950.7574
A18: 44332 | B18: 410890 | C18: =(IF((B18-B17)<0,"0",(B18-B17)))*10 -> 530 | D18: 4349600 | E18: =(IF((D18-D17)<0,"0",(D18-D17)))*0.027 -> 334.8 | F18: 3038600 | G18: =(IF((F18-F17)<0,"0",(F18-F17)))*0.027 -> 445.5 | H18: 732442 | I18: =(IF((H18-H17)<0,"0",(H18-H17)))*0.027 -> 2.727 | J18: =C18+E18+G18+I18 -> 1313.027 | K18: =J18*5.86 -> 7694.3382 | Q18: `
A19: 44333 | B19: 411015 | C19: =(IF((B19-B18)<0,"0",(B19-B18)))*10 -> 1250 | D19: 4363600 | E19: =(IF((D19-D18)<0,"0",(D19-D18)))*0.027 -> 378 | F19: 3061600 | G19: =(IF((F19-F18)<0,"0",(F19-F18)))*0.027 -> 621 | H19: 732585 | I19: =(IF((H19-H18)<0,"0",(H19-H18)))*0.027 -> 3.861 | J19: =C19+E19+G19+I19 -> 2252.861 | K19: =J19*5.86 -> 13201.765
A20: 44334 | B20: 411098 | C20: =(IF((B20-B19)<0,"0",(B20-B19)))*10 -> 830 | D20: 4377900 | E20: =(IF((D20-D19)<0,"0",(D20-D19)))*0.027 -> 386.1 | F20: 3064800 | G20: =(IF((F20-F19)<0,"0",(F20-F19)))*0.027 -> 86.4 | H20: 732722 | I20: =(IF((H20-H19)<0,"0",(H20-H19)))*0.027 -> 3.699 | J20: =C20+E20+G20+I20 -> 1306.199 | K20: =J20*5.86 -> 7654.3261
A21: 44335 | B21: 411218 | C21: =(IF((B21-B20)<0,"0",(B21-B20)))*10 -> 1200 | D21: 4377900 | E21: =(IF((D21-D20)<0,"0",(D21-D20)))*0.027 -> 0 | F21: 3080100 | G21: =(IF((F21-F20)<0,"0",(F21-F20)))*0.027 -> 413.1 | H21: 732838 | I21: =(IF((H21-H20)<0,"0",(H21-H20)))*0.027 -> 3.132 | J21: =C21+E21+G21+I21 -> 1616.232 | K21: =J21*5.86 -> 9471.1195
A22: 44336 | B22: 411265 | C22: =(IF((B22-B21)<0,"0",(B22-B21)))*10 -> 470 | D22: 4377900 | E22: =(IF((D22-D21)<0,"0",(D22-D21)))*0.027 -> 0 | F22: 3095800 | G22: =(IF((F22-F21)<0,"0",(F22-F21)))*0.027 -> 423.9 | H22: 732984 | I22: =(IF((H22-H21)<0,"0",(H22-H21)))*0.027 -> 3.942 | J22: =C22+E22+G22+I22 -> 897.842 | K22: =J22*5.86 -> 5261.3541
A23: 44337 | B23: 411340 | C23: =(IF((B23-B22)<0,"0",(B23-B22)))*10 -> 750 | D23: 4377900 | E23: =(IF((D23-D22)<0,"0",(D23-D22)))*0.027 -> 0 | F23: 3110100 | G23: =(IF((F23-F22)<0,"0",(F23-F22)))*0.027 -> 386.1 | H23: 733103 | I23: =(IF((H23-H22)<0,"0",(H23-H22)))*0.027 -> 3.213 | J23: =C23+E23+G23+I23 -> 1139.313 | K23: =J23*5.86 -> 6676.3742
A24: 44338 | B24: 411529 | C24: =(IF((B24-B23)<0,"0",(B24-B23)))*10 -> 1890 | D24: =D23 -> 4377900 | E24: =(IF((D24-D23)<0,"0",(D24-D23)))*0.027 -> 0 | F24: 3122800 | G24: =(IF((F24-F23)<0,"0",(F24-F23)))*0.027 -> 342.9 | H24: 733217 | I24: =(IF((H24-H23)<0,"0",(H24-H23)))*0.027 -> 3.078 | J24: =C24+E24+G24+I24 -> 2235.978 | K24: =J24*5.86 -> 13102.831
A25: 44339 | B25: =B24 -> 411529 | C25: =(IF((B25-B24)<0,"0",(B25-B24)))*10 -> 0 | D25: =D24 -> 4377900 | E25: =(IF((D25-D24)<0,"0",(D25-D24)))*0.027 -> 0 | F25: =F24 -> 3122800 | G25: =F25-F24 -> 0 | H25: =H24 -> 733217 | I25: =(IF((H25-H24)<0,"0",(H25-H24)))*0.027 -> 0 | J25: =C25+E25+G25+I25 -> 0 | K25: =J25*5.86 -> 0
A26: 44340 | B26: =B25 -> 411529 | C26: =(IF((B26-B25)<0,"0",(B26-B25)))*10 -> 0 | D26: =D25 -> 4377900 | E26: =(IF((D26-D25)<0,"0",(D26-D25)))*0.027 -> 0 | F26: =F25 -> 3122800 | G26: =(IF((F26-F25)<0,"0",(F26-F25)))*0.027 -> 0 | H26: =H25 -> 733217 | I26: =(IF((H26-H25)<0,"0",(H26-H25)))*0.027 -> 0 | J26: =C26+E26+G26+I26 -> 0 | K26: =J26*5.86 -> 0
A27: 44341 | B27: =B26 -> 411529 | C27: =(IF((B27-B26)<0,"0",(B27-B26)))*10 -> 0 | D27: =D26 -> 4377900 | E27: =(IF((D27-D26)<0,"0",(D27-D26)))*0.027 -> 0 | F27: =F26 -> 3122800 | G27: =(IF((F27-F26)<0,"0",(F27-F26)))*0.027 -> 0 | H27: =H26 -> 733217 | I27: =(IF((H27-H26)<0,"0",(H27-H26)))*0.027 -> 0 | J27: =C27+E27+G27+I27 -> 0 | K27: =J27*5.86 -> 0
A28: 44342 | B28: =B27 -> 411529 | C28: =(IF((B28-B27)<0,"0",(B28-B27)))*10 -> 0 | D28: =D27 -> 4377900 | E28: =(IF((D28-D27)<0,"0",(D28-D27)))*0.027 -> 0 | F28: =F27 -> 3122800 | G28: =(IF((F28-F27)<0,"0",(F28-F27)))*0.027 -> 0 | H28: =H27 -> 733217 | I28: =(IF((H28-H27)<0,"0",(H28-H27)))*0.027 -> 0 | J28: =C28+E28+G28+I28 -> 0 | K28: =J28*5.86 -> 0
A29: 44343 | B29: =B28 -> 411529 | C29: =(IF((B29-B28)<0,"0",(B29-B28)))*10 -> 0 | D29: =D28 -> 4377900 | E29: =(IF((D29-D28)<0,"0",(D29-D28)))*0.027 -> 0 | F29: =F28 -> 3122800 | G29: =(IF((F29-F28)<0,"0",(F29-F28)))*0.027 -> 0 | H29: =H28 -> 733217 | I29: =(IF((H29-H28)<0,"0",(H29-H28)))*0.027 -> 0 | J29: =C29+E29+G29+I29 -> 0 | K29: =J29*5.86 -> 0
A30: 44344 | B30: =B29 -> 411529 | C30: =(IF((B30-B29)<0,"0",(B30-B29)))*10 -> 0 | D30: =D29 -> 4377900 | E30: =(IF((D30-D29)<0,"0",(D30-D29)))*0.027 -> 0 | F30: =F29 -> 3122800 | G30: =(IF((F30-F29)<0,"0",(F30-F29)))*0.027 -> 0 | H30: =H29 -> 733217 | I30: =(IF((H30-H29)<0,"0",(H30-H29)))*0.027 -> 0 | J30: =C30+E30+G30+I30 -> 0 | K30: =J30*5.86 -> 0
A31: 44345 | B31: =B30 -> 411529 | C31: =(IF((B31-B30)<0,"0",(B31-B30)))*10 -> 0 | D31: =D30 -> 4377900 | E31: =(IF((D31-D30)<0,"0",(D31-D30)))*0.027 -> 0 | F31: =F30 -> 3122800 | G31: =(IF((F31-F30)<0,"0",(F31-F30)))*0.027 -> 0 | H31: =H30 -> 733217 | I31: =(IF((H31-H30)<0,"0",(H31-H30)))*0.027 -> 0 | J31: =C31+E31+G31+I31 -> 0 | K31: =J31*5.86 -> 0
A32: 44346 | B32: =B31 -> 411529 | C32: =(IF((B32-B31)<0,"0",(B32-B31)))*10 -> 0 | D32: =D31 -> 4377900 | E32: =(IF((D32-D31)<0,"0",(D32-D31)))*0.027 -> 0 | F32: =F31 -> 3122800 | G32: =(IF((F32-F31)<0,"0",(F32-F31)))*0.027 -> 0 | H32: =H31 -> 733217 | I32: =(IF((H32-H31)<0,"0",(H32-H31)))*0.027 -> 0 | J32: =C32+E32+G32+I32 -> 0 | K32: =J32*5.86 -> 0
A33: 44347 | B33: =B32 -> 411529 | C33: =(IF((B33-B32)<0,"0",(B33-B32)))*10 -> 0 | D33: =D32 -> 4377900 | E33: =(IF((D33-D32)<0,"0",(D33-D32)))*0.027 -> 0 | F33: =F32 -> 3122800 | G33: =(IF((F33-F32)<0,"0",(F33-F32)))*0.027 -> 0 | H33: =H32 -> 733217 | I33: =(IF((H33-H32)<0,"0",(H33-H32)))*0.027 -> 0 | J33: =C33+E33+G33+I33 -> 0 | K33: =J33*5.86 -> 0
A34: Total | C34: =SUM(C3:C33) -> 16710 | E34: =SUM(E3:E33) -> 5694.3 | G34: =SUM(G3:G33) -> 7992 | I34: =SUM(I3:I33) -> 71.793 | J34: =SUM(J3:J33) -> 30680.533 | K34: =SUM(K3:K33) -> 179787.92

Sheet ELECT.
A1: Day | B1: Rooms Sold | C1: New Chillers | D1: Cons | E1: F-1 | F1: Cons. | G1: F-2 | H1: Cons. | I1: Total | J1: T-1 | K1: Cons. | L1: T-2 | M1: Cons. | N1: T-3 | O1: Cons. | P1: T-4 | Q1: Cons. | R1: T-5 | S1: Cons. | T1: T-6 | U1: Cons. | V1: T-7 | W1: Cons. | X1: Total | Y1: Diff | Z1: Daily Money Value | AA1: MTD Total Money
A2: 44316 | C2: 18151 | E2: 25714262 | G2: 81240726 | I2: =F2+H2 -> 0 | J2: 7916972 | L2: 7931158 | N2: 5068618 | P2: 3187872 | R2: 17259708 | T2: 0 | V2: 4897522
A3: 44317 | B3: 78 | C3: 18153 | D3: =IF((C3-C2)<0,"0",(C3-C2))*160 -> 320 | E3: 25720195 | F3: =IF((E3-E2)<0,"0",(E3-E2)) -> 5933 | G3: 81283913 | H3: =IF((G3-G2)<0,"0",(G3-G2)) -> 43187 | I3: =F3+H3 -> 49120 | J3: 7921769 | K3: =IF((J3-J2)<0,"0",(J3-J2)) -> 4797 | L3: 7934788 | M3: =IF((L3-L2)<0,"0",(L3-L2)) -> 3630 | N3: 5069611 | O3: =(IF((N3-N2)<P95,"0",(N3-N2)))*2 -> 1986 | P3: 3198498 | Q3: =IF((P3-P2)<0,"0",(P3-P2)) -> 10626 | R3: 17267610 | S3: =IF((R3-R2)<0,"0",(R3-R2)) -> 7902 | T3: 0 | V3: 4906960 | W3: =IF((V3-V2)<0,"0",(V3-V2)) -> 9438 | X3: =K3+M3+O3+Q3+S3+U3+W3 -> 38379 | Y3: =I3-X3 -> 10741 | Z3: =(0.93352*(W3+S3)+0.5568*(Q3+O3))*0.26 -> 6034.4956 | AA3: =SUM(Z1:Z3) -> 6034.4956
A4: 44318 | B4: 79 | C4: 18156 | D4: =IF((C4-C3)<0,"0",(C4-C3))*160 -> 480 | E4: 25725729 | F4: =IF((E4-E3)<0,"0",(E4-E3)) -> 5534 | G4: 81325548 | H4: =IF((G4-G3)<0,"0",(G4-G3)) -> 41635 | I4: =F4+H4 -> 47169 | J4: 7926437 | K4: =IF((J4-J3)<0,"0",(J4-J3)) -> 4668 | L4: 7938147 | M4: =IF((L4-L3)<0,"0",(L4-L3)) -> 3359 | N4: 5070740 | O4: =(IF((N4-N3)<P96,"0",(N4-N3)))*2 -> 2258 | P4: 3208656 | Q4: =IF((P4-P3)<0,"0",(P4-P3)) -> 10158 | R4: 17275354 | S4: =IF((R4-R3)<0,"0",(R4-R3)) -> 7744 | T4: 0 | V4: 4915984 | W4: =IF((V4-V3)<0,"0",(V4-V3)) -> 9024 | X4: =K4+M4+O4+Q4+S4+U4+W4 -> 37211 | Y4: =I4-X4 -> 9958 | Z4: =(0.93352*(W4+S4)+0.5568*(Q4+O4))*0.26 -> 5867.288 | AA4: =SUM(Z2:Z4) -> 11901.784
A5: 44319 | B5: 92 | C5: 18159 | D5: =IF((C5-C4)<0,"0",(C5-C4))*160 -> 480 | E5: 25731976 | F5: =IF((E5-E4)<0,"0",(E5-E4)) -> 6247 | G5: 81370260 | H5: =IF((G5-G4)<0,"0",(G5-G4)) -> 44712 | I5: =F5+H5 -> 50959 | J5: 7931299 | K5: =IF((J5-J4)<0,"0",(J5-J4)) -> 4862 | L5: 7941970 | M5: =IF((L5-L4)<0,"0",(L5-L4)) -> 3823 | N5: 5071888 | O5: =(IF((N5-N4)<0,"0",(N5-N4)))*2 -> 2296 | P5: 3220251 | Q5: =IF((P5-P4)<0,"0",(P5-P4)) -> 11595 | R5: 17283516 | S5: =IF((R5-R4)<0,"0",(R5-R4)) -> 8162 | T5: 0 | V5: 4925498 | W5: =IF((V5-V4)<0,"0",(V5-V4)) -> 9514 | X5: =K5+M5+O5+Q5+S5+U5+W5 -> 40252 | Y5: =I5-X5 -> 10707 | Z5: =(0.93352*(W5+S5)+0.5568*(Q5+O5))*0.26 -> 6301.2062 | AA5: =SUM(Z3:Z5) -> 18202.99
A6: 44320 | B6: 68 | C6: 18163 | D6: =IF((C6-C5)<0,"0",(C6-C5))*160 -> 640 | E6: 25743251 | F6: =IF((E6-E5)<0,"0",(E6-E5)) -> 11275 | G6: 81428207 | H6: =IF((G6-G5)<0,"0",(G6-G5)) -> 57947 | I6: =F6+H6 -> 69222 | J6: 7938080 | K6: =IF((J6-J5)<0,"0",(J6-J5)) -> 6781 | L6: 7947090 | M6: =IF((L6-L5)<0,"0",(L6-L5)) -> 5120 | N6: 5074884 | O6: =(IF((N6-N5)<0,"0",(N6-N5)))*2 -> 5992 | P6: 3234588 | Q6: =IF((P6-P5)<0,"0",(P6-P5)) -> 14337 | R6: 17293950 | S6: =IF((R6-R5)<0,"0",(R6-R5)) -> 10434 | T6: 0 | V6: 4938012 | W6: =IF((V6-V5)<0,"0",(V6-V5)) -> 12514 | X6: =K6+M6+O6+Q6+S6+U6+W6 -> 55178 | Y6: =I6-X6 -> 14044 | Z6: =(0.93352*(W6+S6)+0.5568*(Q6+O6))*0.26 -> 8512.8171 | AA6: =SUM(Z4:Z6) -> 20681.311
A7: 44321 | B7: 93 | C7: 18166 | D7: =IF((C7-C6)<0,"0",(C7-C6))*160 -> 480 | E7: 25755169 | F7: =IF((E7-E6)<0,"0",(E7-E6)) -> 11918 | G7: 81472963 | H7: =IF((G7-G6)<0,"0",(G7-G6)) -> 44756 | I7: =F7+H7 -> 56674 | J7: 7943610 | K7: =IF((J7-J6)<0,"0",(J7-J6)) -> 5530 | L7: 7950625 | M7: =IF((L7-L6)<0,"0",(L7-L6)) -> 3535 | N7: 5078992 | O7: =(IF((N7-N6)<0,"0",(N7-N6)))*2 -> 8216 | P7: 3244942 | Q7: =IF((P7-P6)<0,"0",(P7-P6)) -> 10354 | R7: 17302465 | S7: =IF((R7-R6)<0,"0",(R7-R6)) -> 8515 | T7: 0 | V7: 4947638 | W7: =IF((V7-V6)<0,"0",(V7-V6)) -> 9626 | X7: =K7+M7+O7+Q7+S7+U7+W7 -> 45776 | Y7: =I7-X7 -> 10898 | Z7: =(0.93352*(W7+S7)+0.5568*(Q7+O7))*0.26 -> 7091.4382 | AA7: =SUM(Z4:Z7) -> 27772.749
A8: 44322 | B8: 65 | C8: 18168 | D8: =IF((C8-C7)<0,"0",(C8-C7))*160 -> 320 | E8: 25770238 | F8: =IF((E8-E7)<0,"0",(E8-E7)) -> 15069 | G8: 81528158 | H8: =IF((G8-G7)<0,"0",(G8-G7)) -> 55195 | I8: =F8+H8 -> 70264 | J8: 7950151 | K8: =IF((J8-J7)<0,"0",(J8-J7)) -> 6541 | L8: 7955364 | M8: =IF((L8-L7)<0,"0",(L8-L7)) -> 4739 | N8: 5084044 | O8: =(IF((N8-N7)<0,"0",(N8-N7)))*2 -> 10104 | P8: 3251135 | Q8: =IF((P8-P7)<0,"0",(P8-P7)) -> 6193 | R8: 17313405 | S8: =IF((R8-R7)<0,"0",(R8-R7)) -> 10940 | T8: 0 | V8: 4959688 | W8: =IF((V8-V7)<0,"0",(V8-V7)) -> 12050 | X8: =K8+M8+O8+Q8+S8+U8+W8 -> 50567 | Y8: =I8-X8 -> 19697 | Z8: =(0.93352*(W8+S8)+0.5568*(Q8+O8))*0.26 -> 7939.3065 | AA8: =SUM(Z5:Z8) -> 29844.768
A9: 44323 | B9: 71 | C9: 18171 | D9: =IF((C9-C8)<0,"0",(C9-C8))*160 -> 480 | E9: 25781073 | F9: =IF((E9-E8)<0,"0",(E9-E8)) -> 10835 | G9: 81568286 | H9: =IF((G9-G8)<0,"0",(G9-G8)) -> 40128 | I9: =F9+H9 -> 50963 | J9: 7904613 | K9: =IF((J9-J8)<0,"0",(J9-J8)) -> 0 | L9: 7908626 | M9: =IF((L9-L8)<0,"0",(L9-L8)) -> 0 | N9: 5087770 | O9: =(IF((N9-N8)<0,"0",(N9-N8)))*2 -> 7452 | P9: 3265892 | Q9: =IF((P9-P8)<0,"0",(P9-P8)) -> 14757 | R9: 17321405 | S9: =IF((R9-R8)<0,"0",(R9-R8)) -> 8000 | T9: 0 | V9: 4968730 | W9: =IF((V9-V8)<0,"0",(V9-V8)) -> 9042 | X9: =K9+M9+O9+Q9+S9+U9+W9 -> 39251 | Y9: =I9-X9 -> 11712 | Z9: =(0.93352*(W9+S9)+0.5568*(Q9+O9))*0.26 -> 7351.505 | AA9: =SUM(Z6:Z9) -> 30895.067
A10: 44324 | B10: 72 | C10: 18174 | D10: =IF((C10-C9)<0,"0",(C10-C9))*160 -> 480 | E10: 25794506 | F10: =IF((E10-E9)<0,"0",(E10-E9)) -> 13433 | G10: 81620717 | H10: =IF((G10-G9)<0,"0",(G10-G9)) -> 52431 | I10: =F10+H10 -> 65864 | J10: 7960605 | K10: =IF((J10-J9)<0,"0",(J10-J9)) -> 55992 | L10: 7962208 | M10: =IF((L10-L9)<0,"0",(L10-L9)) -> 53582 | N10: 5092610 | O10: =(IF((N10-N9)<0,"0",(N10-N9)))*2 -> 9680 | P10: 3277374 | Q10: =IF((P10-P9)<0,"0",(P10-P9)) -> 11482 | R10: 17331751 | S10: =IF((R10-R9)<0,"0",(R10-R9)) -> 10346 | T10: 0 | V10: 4980391 | W10: =IF((V10-V9)<0,"0",(V10-V9)) -> 11661 | X10: =K10+M10+O10+Q10+S10+U10+W10 -> 152743 | Y10: =I10-X10 -> -86879 | Z10: =(0.93352*(W10+S10)+0.5568*(Q10+O10))*0.26 -> 8405.0138 | AA10: =SUM(Z7:Z10) -> 30787.264
A11: 44325 | B11: 85 | C11: 18178 | D11: =IF((C11-C10)<0,"0",(C11-C10))*160 -> 640 | E11: 25808616 | F11: =IF((E11-E10)<0,"0",(E11-E10)) -> 14110 | G11: 81669964 | H11: =IF((G11-G10)<0,"0",(G11-G10)) -> 49247 | I11: =F11+H11 -> 63357 | J11: 7966422 | K11: =IF((J11-J10)<0,"0",(J11-J10)) -> 5817 | L11: 7966838 | M11: =IF((L11-L10)<0,"0",(L11-L10)) -> 4630 | N11: 5097256 | O11: =(IF((N11-N10)<0,"0",(N11-N10)))*2 -> 9292 | P11: 3289068 | Q11: =IF((P11-P10)<0,"0",(P11-P10)) -> 11694 | R11: 17342563 | S11: =IF((R11-R10)<0,"0",(R11-R10)) -> 10812 | T11: 0 | V11: 4990742 | W11: =IF((V11-V10)<0,"0",(V11-V10)) -> 10351 | X11: =K11+M11+O11+Q11+S11+U11+W11 -> 52596 | Y11: =I11-X11 -> 10761 | Z11: =(0.93352*(W11+S11)+0.5568*(Q11+O11))*0.26 -> 8174.683 | AA11: =SUM(Z8:Z11) -> 31870.508
A12: 44326 | B12: 80 | C12: 18183 | D12: =IF((C12-C11)<0,"0",(C12-C11))*160 -> 800 | E12: 25821937 | F12: =IF((E12-E11)<0,"0",(E12-E11)) -> 13321 | G12: 81714968 | H12: =IF((G12-G11)<0,"0",(G12-G11)) -> 45004 | I12: =F12+H12 -> 58325 | J12: 7971830 | K12: =IF((J12-J11)<0,"0",(J12-J11)) -> 5408 | L12: 7971332 | M12: =IF((L12-L11)<0,"0",(L12-L11)) -> 4494 | N12: 5101583 | O12: =(IF((N12-N11)<0,"0",(N12-N11)))*2 -> 8654 | P12: 3299760 | Q12: =IF((P12-P11)<0,"0",(P12-P11)) -> 10692 | R12: 17350701 | S12: =IF((R12-R11)<0,"0",(R12-R11)) -> 8138 | T12: 0 | V12: 5000030 | W12: =IF((V12-V11)<0,"0",(V12-V11)) -> 9288 | X12: =K12+M12+O12+Q12+S12+U12+W12 -> 46674 | Y12: =I12-X12 -> 11651 | Z12: =(0.93352*(W12+S12)+0.5568*(Q12+O12))*0.26 -> 7030.2368 | AA12: =SUM(Z9:Z12) -> 30961.439
A13: 44327 | B13: 81 | C13: 18186 | D13: =IF((C13-C12)<0,"0",(C13-C12))*160 -> 480 | E13: 25838382 | F13: =IF((E13-E12)<0,"0",(E13-E12)) -> 16445 | G13: 81759125 | H13: =IF((G13-G12)<0,"0",(G13-G12)) -> 44157 | I13: =F13+H13 -> 60602 | J13: 7977214 | K13: =IF((J13-J12)<0,"0",(J13-J12)) -> 5384 | L13: 7977089 | M13: =IF((L13-L12)<0,"0",(L13-L12)) -> 5757 | N13: 5106839 | O13: =(IF((N13-N12)<0,"0",(N13-N12)))*2 -> 10512 | P13: 3309968 | Q13: =IF((P13-P12)<0,"0",(P13-P12)) -> 10208 | R13: 17359543 | S13: =IF((R13-R12)<0,"0",(R13-R12)) -> 8842 | T13: 0 | V13: 5009307 | W13: =IF((V13-V12)<0,"0",(V13-V12)) -> 9277 | X13: =K13+M13+O13+Q13+S13+U13+W13 -> 49980 | Y13: =I13-X13 -> 10622 | Z13: =(0.93352*(W13+S13)+0.5568*(Q13+O13))*0.26 -> 7397.3497 | AA13: =SUM(Z10:Z13) -> 31007.283
