Workbook

Sheet TOTAL
A1: Site Name | B1: Day | C1: Month | D1: Year | E1: Total Electricity Kwh | F1: Electricity Tariff ($/Kwh) | G1: Natual Gas (m3) | H1: Natural Gas $/m3 | I1: Water Utility Supply (m3) m3 | J1: Water Utility Supply (m3) $/m3 | K1: Room Nights | L1: Total Guests | M1: Utilities day cost dh
A2: Mumbai | B2: 1 | C2: 5 | D2: 2020 | E2: =366799.64/31 -> 11832.246 | F2: ='Daily HLP'!J4 -> 9.5 | G2: =8431/31 -> 271.96774 | H2: 28 | I2: =1828/31 -> 58.967742 | J2: 129.27 | K2: =3058/31 -> 98.645161 | L2: 0 | M2: =E2*F2+G2*H2+#REF!*#REF!+I2*J2 -> #REF!
A3: Mumbai | B3: =B2+1 -> 2 | C3: 5 | D3: 2020 | E3: =366799.64/31 -> 11832.246 | F3: =F2 -> 9.5 | G3: =8431/31 -> 271.96774 | H3: 28 | I3: =1828/31 -> 58.967742 | J3: =J2 -> 129.27 | K3: =3058/31 -> 98.645161 | L3: 0 | M3: =E3*F3+G3*H3+#REF!*#REF!+I3*J3 -> #REF!
A4: Mumbai | B4: =B3+1 -> 3 | C4: 5 | D4: 2020 | E4: =366799.64/31 -> 11832.246 | F4: =F3 -> 9.5 | G4: =8431/31 -> 271.96774 | H4: 28 | I4: =1828/31 -> 58.967742 | J4: =J3 -> 129.27 | K4: =3058/31 -> 98.645161 | L4: 0 | M4: =E4*F4+G4*H4+#REF!*#REF!+I4*J4 -> #REF!
A5: Mumbai | B5: =B4+1 -> 4 | C5: 5 | D5: 2020 | E5: =366799.64/31 -> 11832.246 | F5: =F4 -> 9.5 | G5: =8431/31 -> 271.96774 | H5: 28 | I5: =1828/31 -> 58.967742 | J5: =J4 -> 129.27 | K5: =3058/31 -> 98.645161 | L5: 0 | M5: =E5*F5+G5*H5+#REF!*#REF!+I5*J5 -> #REF!
A6: Mumbai | B6: =B5+1 -> 5 | C6: 5 | D6: 2020 | E6: =366799.64/31 -> 11832.246 | F6: =F5 -> 9.5 | G6: =8431/31 -> 271.96774 | H6: 28 | I6: =1828/31 -> 58.967742 | J6: =J5 -> 129.27 | K6: =3058/31 -> 98.645161 | L6: 0 | M6: =E6*F6+G6*H6+#REF!*#REF!+I6*J6 -> #REF!
A7: Mumbai | B7: =B6+1 -> 6 | C7: 5 | D7: 2020 | E7: =366799.64/31 -> 11832.246 | F7: =F6 -> 9.5 | G7: =8431/31 -> 271.96774 | H7: 28 | I7: =1828/31 -> 58.967742 | J7: =J6 -> 129.27 | K7: =3058/31 -> 98.645161 | L7: 0 | M7: =E7*F7+G7*H7+#REF!*#REF!+I7*J7 -> #REF!
A8: Mumbai | B8: =B7+1 -> 7 | C8: 5 | D8: 2020 | E8: =366799.64/31 -> 11832.246 | F8: =F7 -> 9.5 | G8: =8431/31 -> 271.96774 | H8: 28 | I8: =1828/31 -> 58.967742 | J8: =J7 -> 129.27 | K8: =3058/31 -> 98.645161 | L8: 0 | M8: =E8*F8+G8*H8+#REF!*#REF!+I8*J8 -> #REF!
A9: Mumbai | B9: =B8+1 -> 8 | C9: 5 | D9: 2020 | E9: =366799.64/31 -> 11832.246 | F9: =F8 -> 9.5 | G9: =8431/31 -> 271.96774 | H9: 28 | I9: =1828/31 -> 58.967742 | J9: =J8 -> 129.27 | K9: =3058/31 -> 98.645161 | L9: 0 | M9: =E9*F9+G9*H9+#REF!*#REF!+I9*J9 -> #REF!
A10: Mumbai | B10: =B9+1 -> 9 | C10: 5 | D10: 2020 | E10: =366799.64/31 -> 11832.246 | F10: =F9 -> 9.5 | G10: =8431/31 -> 271.96774 | H10: 28 | I10: =1828/31 -> 58.967742 | J10: =J9 -> 129.27 | K10: =3058/31 -> 98.645161 | L10: 0 | M10: =E10*F10+G10*H10+#REF!*#REF!+I10*J10 -> #REF!
A11: Mumbai | B11: =B10+1 -> 10 | C11: 5 | D11: 2020 | E11: =366799.64/31 -> 11832.246 | F11: =F10 -> 9.5 | G11: =8431/31 -> 271.96774 | H11: 28 | I11: =1828/31 -> 58.967742 | J11: =J10 -> 129.27 | K11: =3058/31 -> 98.645161 | L11: 0 | M11: =E11*F11+G11*H11+#REF!*#REF!+I11*J11 -> #REF!
A12: Mumbai | B12: =B11+1 -> 11 | C12: 5 | D12: 2020 | E12: =366799.64/31 -> 11832.246 | F12: =F11 -> 9.5 | G12: =8431/31 -> 271.96774 | H12: 28 | I12: =1828/31 -> 58.967742 | J12: =J11 -> 129.27 | K12: =3058/31 -> 98.645161 | L12: 0 | M12: =E12*F12+G12*H12+#REF!*#REF!+I12*J12 -> #REF!
A13: Mumbai | B13: =B12+1 -> 12 | C13: 5 | D13: 2020 | E13: =366799.64/31 -> 11832.246 | F13: =F12 -> 9.5 | G13: =8431/31 -> 271.96774 | H13: 28 | I13: =1828/31 -> 58.967742 | J13: =J12 -> 129.27 | K13: =3058/31 -> 98.645161 | L13: 0 | M13: =E13*F13+G13*H13+#REF!*#REF!+I13*J13 -> #REF!
A14: Mumbai | B14: =B13+1 -> 13 | C14: 5 | D14: 2020 | E14: =366799.64/31 -> 11832.246 | F14: =F13 -> 9.5 | G14: =8431/31 -> 271.96774 | H14: 28 | I14: =1828/31 -> 58.967742 | J14: =J13 -> 129.27 | K14: =3058/31 -> 98.645161 | L14: 0 | M14: =E14*F14+G14*H14+#REF!*#REF!+I14*J14 -> #REF!
... A31: Mumbai | B31: =B30+1 -> 30 | C31: 5 | D31: 2020 | E31: =366799.64/31 -> 11832.246 | F31: =F30 -> 9.5 | G31: =8431/31 -> 271.96774 | H31: 28 | I31: =1828/31 -> 58.967742 | J31: =J30 -> 129.27 | K31: =3058/31 -> 98.645161 | L31: 0 | M31: =E31*F31+G31*H31+#REF!*#REF!+I31*J31 -> #REF!
A32: Mumbai | B32: =B31+1 -> 31 | C32: 5 | D32: 2020 | E32: =366799.64/31 -> 11832.246 | F32: =F31 -> 9.5 | G32: =8431/31 -> 271.96774 | H32: 28 | I32: =1828/31 -> 58.967742 | J32: =J31 -> 129.27 | K32: =3058/31 -> 98.645161 | L32: 0

Sheet Daily HLP
A2: Date | B2: Date | C2: Min.Tem (Degee) | D2: Avg.Temp (Degree) | E2: Hum % | F2: Occu. | G2: KWAH | I2: Electricity | M2: Gas | P2: Water | S2: Water per occiped room | T2: Diesel | W2: Water Consumption Zone | AA2: Chiller Running Hrs | AF2: Chiller Total | AG2: Chiller Avg. Laod | AH2: Boiler Running Hrs | AK2: Total boiler | AL2: Hot Water Generator | AO2: Total HWG RH | AP2: HWG Gas consumption | AQ2: Transformer -1 | BA2: Transformer -2 | BO2: Total HLP Cost | BQ2: Chiller lock at 70%
F3: % | H3: KVAH | I3: Units (Kwh) | J3: Rate | K3: Total Cost(Rs) | L3: Per room | M3: Total Units(CuM) | N3: Rate | O3: Total Cost(Rs) | P3: Units(KL) | Q3: Rate | R3: Total Cost(Rs) | T3: Ltrs | U3: Rate | V3: Total Cost(Rs) | W3: Zone-1 | X3: Zone-2 | Y3: Zone-3 | AA3: CH1 | AB3: CH2 | AC3: CH3 | AD3: CH4 | AE3: Total chiller | AH3: Boiler1 | AI3: Boiler2 | AJ3: Boiler3 | AL3: HWG1 | AM3: HWG2 | AQ3: HVAC-1 | AR3: FPP-1 | AS3: MPP | AT3: Lighting-1 | AU3: Cap bank 1100KVAR-1 | AV3: CH-1 | AW3: CH-2 | AX3: Chilled water Pump | AY3: Co Generator | AZ3: Ball Room-2 | BA3: HVAC-2 | BB3: FPP-2 | BC3: MPP | BD3: Lighting-2 | BE3: Cap bank 1200KVAR-2 | BF3: CH-3 | BG3: CH-4 | BH3: Chilled water Pump | BI3: Ball Room-1 | BK3: Cooling Tower consumption | BL3: HVAC% | BM3: Lighting% | BN3: Power% | BP3: Chiller Plant IKW
A4: 1 | B4: 1 | D4: ='1'!D3 -> 30 | E4: ='1'!D4 -> 0.8 | G4: ='1'!G8 -> 19444 | H4: ='1'!G8 -> 19444 | I4: ='1'!G7 -> 19245 | J4: ='1'!F27 -> 9.5 | K4: =H4*J4 -> 184718 | L4: =I4/202 -> 95.272277 | M4: ='1'!G15 -> 510.757 | N4: 35 | O4: =M4*N4 -> 17876.495 | P4: ='1'!G20 -> 223 | Q4: 134 | R4: =P4*Q4 -> 29882 | S4: =P4/(F4*202/100) -> #DIV/0! | T4: ='1'!G24 -> 0 | U4: 69 | V4: =T4*U4 -> 0 | W4: ='1'!G95 -> 47 | X4: ='1'!G96 -> 33 | Y4: ='1'!G97 -> 35 | Z4: =W4+X4+Y4 -> 115 | AA4: ='1'!G132 -> 0 | AB4: ='1'!G133 -> 0 | AC4: ='1'!G134 -> 0 | AD4: ='1'!G135 -> 24.02 | AE4: =AA4+AB4+AC4+AD4 -> 24.02 | AF4: =AV4+AW4+BF4+BG4 -> 4735.89 | AG4: =AF4/AE4 -> 197.16445 | AH4: ='1'!G136 -> 0 | AI4: ='1'!G137 -> 0 | AJ4: ='1'!G138 -> 8.09 | AK4: =AH4+AI4+AJ4 -> 8.09 | AL4: ='1'!G139 -> 5.89 | AM4: ='1'!G140 -> 0 | AO4: =AL4+AM4 -> 5.89 | AP4: ='1'!G123 -> 212.69 | AQ4: ='1'!G35 -> -0.4 | AR4: ='1'!G37 -> 0 | AS4: ='1'!G38 -> 0 | AT4: ='1'!G39 -> 0 | AU4: ='1'!G40 -> 0 | AV4: ='1'!G41 -> 0.02 | AW4: ='1'!G42 -> 0 | AX4: ='1'!G43 -> 1842.16 | AY4: ='1'!G44 -> 0 | AZ4: ='1'!G36 -> 1551.2 | BA4: ='1'!G49 -> 2722.5 | BB4: ='1'!G51 -> 1437.182 | BC4: ='1'!G52 -> 1880.84 | BD4: ='1'!G53 -> 4233.764 | BE4: ='1'!G54 -> 53.89 | BF4: ='1'!G55 -> -0.37 | BG4: ='1'!G56 -> 4736.24 | BH4: ='1'!G57 -> 0 | BI4: ='1'!G50 -> 1072.8 | BJ4: =SUM(AV4,AW4,BF4,BG4) -> 4735.89 | BK4: ='1'!G84 -> 564 | BL4: =SUM(AQ4,AV4,AW4,AX4,BA4,BF4,BG4,BH4)/I4% -> 48.325019 | BM4: =SUM(AT4,BD4)/I4% -> 21.999293 | BN4: =(AS4+BC4)/I4 -> 0.097731359 | BO4: =K4+O4+R4+V4 -> 232476.49 | BP4: =SUM(AV4,AW4,AX4,BF4,BG4,BH4,BK4) -> 7142.05 | BQ4: =BP4/(AE4*280) -> 1.0619201 | BR4: =SUM(AV4,AW4,BF4,BG4)/(AE4*400) -> 0.49291112
A5: 2 | B5: 2 | D5: ='2'!D3 -> 30 | E5: ='2'!D4 -> 0.8 | G5: ='2'!G8 -> 19688 | H5: ='2'!G8 -> 19688 | I5: ='2'!G7 -> 19450 | J5: 10 | K5: =H5*J5 -> 196880 | L5: =I5/202 -> 96.287129 | M5: ='2'!G15 -> 605.862 | N5: 35 | O5: =M5*N5 -> 21205.17 | P5: ='2'!G20 -> 133 | Q5: 134 | R5: =P5*Q5 -> 17822 | S5: =P5/(F5*202/100) -> #DIV/0! | T5: ='2'!G24 -> 0 | U5: 69 | V5: =T5*U5 -> 0 | W5: ='2'!G95 -> 59 | X5: ='2'!G96 -> 31 | Y5: ='2'!G97 -> 14 | Z5: =W5+X5+Y5 -> 104 | AA5: ='2'!G132 -> 0 | AB5: ='2'!G133 -> 0 | AC5: ='2'!G134 -> 0 | AD5: ='2'!G135 -> 23.55 | AE5: =AA5+AB5+AC5+AD5 -> 23.55 | AF5: =AV5+AW5+BF5+BG5 -> 4681.15 | AG5: =AF5/AE5 -> 198.77495 | AH5: ='2'!G136 -> 5.81 | AI5: ='2'!G137 -> 0 | AJ5: ='2'!G138 -> 0 | AK5: =AH5+AI5+AJ5 -> 5.81 | AL5: ='2'!G139 -> 5.45 | AM5: ='2'!G140 -> 0.08 | AO5: =AL5+AM5 -> 5.53 | AP5: ='2'!G123 -> 194.656 | AQ5: ='2'!G35 -> 0.4 | AR5: ='2'!G37 -> 0 | AS5: ='2'!G38 -> 0 | AT5: ='2'!G39 -> 0 | AU5: ='2'!G40 -> 0 | AV5: ='2'!G41 -> -0.07 | AW5: ='2'!G42 -> 0 | AX5: ='2'!G43 -> 2165.68 | AY5: ='2'!G44 -> 0 | AZ5: ='2'!G36 -> 696.92 | BA5: ='2'!G49 -> 2702.463 | BB5: ='2'!G51 -> 1394.541 | BC5: ='2'!G52 -> 1803.32 | BD5: ='2'!G53 -> 4163.956 | BE5: ='2'!G54 -> 59.09 | BF5: ='2'!G55 -> 0.1 | BG5: ='2'!G56 -> 4681.12 | BH5: ='2'!G57 -> 0 | BI5: ='2'!G50 -> 1111.86 | BJ5: =SUM(AV5,AW5,BF5,BG5) -> 4681.15 | BK5: ='2'!G84 -> 542 | BL5: =SUM(AQ5,AV5,AW5,AX5,BA5,BF5,BG5,BH5)/I5% -> 49.098679 | BM5: =SUM(AT5,BD5)/I5% -> 21.408514 | BN5: =(AS5+BC5)/I5 -> 0.092715681 | BO5: =K5+O5+R5+V5 -> 235907.17 | BP5: =SUM(AV5,AW5,AX5,BF5,BG5,BH5,BK5) -> 7388.83 | BQ5: =BP5/(AE5*280) -> 1.1205384
A6: 3 | B6: 3 | D6: ='3'!D3 -> 31 | E6: ='3'!D4 -> 0.8 | G6: ='3'!G8 -> 18908 | H6: ='3'!G8 -> 18908 | I6: ='3'!G7 -> 18679 | J6: 10 | K6: =H6*J6 -> 189080 | L6: =I6/202 -> 92.470297 | M6: ='3'!G15 -> 518.451 | N6: 35 | O6: =M6*N6 -> 18145.785 | P6: ='3'!G20 -> 133 | Q6: 134 | R6: =P6*Q6 -> 17822 | S6: =P6/(F6*202/100) -> #DIV/0! | T6: ='3'!G24 -> 0 | U6: 69 | V6: =T6*U6 -> 0 | W6: ='3'!G95 -> 45 | X6: ='3'!G96 -> 22 | Y6: ='3'!G97 -> 16 | Z6: =W6+X6+Y6 -> 83 | AA6: ='3'!G132 -> 0 | AB6: ='3'!G133 -> 0 | AC6: ='3'!G134 -> 0 | AD6: ='3'!G135 -> 24 | AE6: =AA6+AB6+AC6+AD6 -> 24 | AF6: =AV6+AW6+BF6+BG6 -> 4174.28 | AG6: =AF6/AE6 -> 173.92833 | AH6: ='3'!G136 -> 0 | AI6: ='3'!G137 -> -0.01 | AJ6: ='3'!G138 -> 9.04 | AK6: =AH6+AI6+AJ6 -> 9.03 | AL6: ='3'!G139 -> 5.32 | AM6: ='3'!G140 -> 0 | AO6: =AL6+AM6 -> 5.32 | AP6: ='3'!G123 -> 211.774 | AQ6: ='3'!G35 -> 0 | AR6: ='3'!G37 -> 0 | AS6: ='3'!G38 -> 0 | AT6: ='3'!G39 -> 0 | AU6: ='3'!G40 -> 0 | AV6: ='3'!G41 -> 0 | AW6: ='3'!G42 -> 0 | AX6: ='3'!G43 -> 2304.12 | AY6: ='3'!G44 -> 0 | AZ6: ='3'!G36 -> 666.82 | BA6: ='3'!G49 -> 2711.409 | BB6: ='3'!G51 -> 1372.169 | BC6: ='3'!G52 -> 1727.68 | BD6: ='3'!G53 -> 4015.398 | BE6: ='3'!G54 -> 43.24 | BF6: ='3'!G55 -> 0 | BG6: ='3'!G56 -> 4174.28 | BH6: ='3'!G57 -> 0 | BI6: ='3'!G50 -> 1089.04 | BJ6: =SUM(AV6,AW6,BF6,BG6) -> 4174.28 | BK6: ='3'!G84 -> 541 | BL6: =SUM(AQ6,AV6,AW6,AX6,BA6,BF6,BG6,BH6)/I6% -> 49.198613 | BM6: =SUM(AT6,BD6)/I6% -> 21.496857 | BN6: =(AS6+BC6)/I6 -> 0.092493174 | BO6: =K6+O6+R6+V6 -> 225047.79 | BP6: =SUM(AV6,AW6,AX6,BF6,BG6,BH6,BK6) -> 7019.4 | BQ6: =BP6/(AE6*280) -> 1.0445536
A7: 4 | B7: 4 | D7: ='4'!D3 -> 31 | E7: ='4'!D4 -> 0.8 | G7: ='4'!G8 -> 19846 | H7: ='4'!G8 -> 19846 | I7: ='4'!G7 -> 19611 | J7: 10 | K7: =H7*J7 -> 198460 | L7: =I7/202 -> 97.084158 | M7: ='4'!G15 -> 691.176 | N7: 35 | O7: =M7*N7 -> 24191.16 | P7: ='4'!G20 -> 153 | Q7: 134 | R7: =P7*Q7 -> 20502 | S7: =P7/(F7*202/100) -> #DIV/0! | T7: ='4'!G24 -> 0 | U7: 69 | V7: =T7*U7 -> 0 | W7: ='4'!G95 -> 59 | X7: ='4'!G96 -> 25 | Y7: ='4'!G97 -> 15 | Z7: =W7+X7+Y7 -> 99 | AA7: ='4'!G132 -> 0 | AB7: ='4'!G133 -> 20.3 | AC7: ='4'!G134 -> 0 | AD7: ='4'!G135 -> 4 | AE7: =AA7+AB7+AC7+AD7 -> 24.3 | AF7: =AV7+AW7+BF7+BG7 -> 4263.34 | AG7: =AF7/AE7 -> 175.44609 | AH7: ='4'!G136 -> 5.77 | AI7: ='4'!G137 -> 0.01 | AJ7: ='4'!G138 -> 0 | AK7: =AH7+AI7+AJ7 -> 5.78 | AL7: ='4'!G139 -> 6.39 | AM7: ='4'!G140 -> 0 | AO7: =AL7+AM7 -> 6.39 | AP7: ='4'!G123 -> 207.006 | AQ7: ='4'!G35 -> 0 | AR7: ='4'!G37 -> 0 | AS7: ='4'!G38 -> 0.2 | AT7: ='4'!G39 -> 0 | AU7: ='4'!G40 -> 0 | AV7: ='4'!G41 -> 0 | AW7: ='4'!G42 -> 3678.9 | AX7: ='4'!G43 -> 2374.92 | AY7: ='4'!G44 -> 0 | AZ7: ='4'!G36 -> 735.56 | BA7: ='4'!G49 -> 2847.441 | BB7: ='4'!G51 -> 1417.011 | BC7: ='4'!G52 -> 1816.92 | BD7: ='4'!G53 -> 4209.545 | BE7: ='4'!G54 -> 44.96 | BF7: ='4'!G55 -> 0 | BG7: ='4'!G56 -> 584.44 | BH7: ='4'!G57 -> 0 | BI7: ='4'!G50 -> 1208.4 | BJ7: =SUM(AV7,AW7,BF7,BG7) -> 4263.34 | BK7: ='3'!G84 -> 541 | BL7: =SUM(AQ7,AV7,AW7,AX7,BA7,BF7,BG7,BH7)/I7% -> 48.369288 | BM7: =SUM(AT7,BD7)/I7% -> 21.465224 | BN7: =(AS7+BC7)/I7 -> 0.092658202 | BO7: =K7+O7+R7+V7 -> 243153.16 | BP7: =SUM(AV7,AW7,AX7,BF7,BG7,BH7,BK7) -> 7179.26 | BQ7: =BP7/(AE7*280) -> 1.0551529
A8: 5 | B8: 5 | D8: ='5'!D3 -> 28 | E8: ='5'!D4 -> 0.76 | G8: ='5'!G8 -> 19340 | H8: ='5'!G8 -> 19340 | I8: ='5'!G7 -> 19138 | J8: 10 | K8: =H8*J8 -> 193400 | L8: =I8/202 -> 94.742574 | M8: ='5'!G15 -> 640.456 | N8: 35 | O8: =M8*N8 -> 22415.96 | P8: ='5'!G20 -> 172 | Q8: 134 | R8: =P8*Q8 -> 23048 | S8: =P8/(F8*202/100) -> #DIV/0! | T8: ='5'!G24 -> 0 | U8: 69 | V8: =T8*U8 -> 0 | W8: ='5'!G95 -> 56 | X8: ='5'!G96 -> 27 | Y8: ='5'!G97 -> 20 | Z8: =W8+X8+Y8 -> 103 | AA8: ='5'!G132 -> 0 | AB8: ='5'!G133 -> 23.7 | AC8: ='5'!G134 -> 0 | AD8: ='5'!G135 -> 0 | AE8: =AA8+AB8+AC8+AD8 -> 23.7 | AF8: =AV8+AW8+BF8+BG8 -> 4126.87 | AG8: =AF8/AE8 -> 174.12954 | AH8: ='5'!G136 -> 3.27 | AI8: ='5'!G137 -> 0 | AJ8: ='5'!G138 -> 4.13 | AK8: =AH8+AI8+AJ8 -> 7.4 | AL8: ='5'!G139 -> 5.67 | AM8: ='5'!G140 -> 0 | AO8: =AL8+AM8 -> 5.67 | AP8: ='5'!G123 -> 200.365 | AQ8: ='5'!G35 -> 0 | AR8: ='5'!G37 -> 0 | AS8: ='5'!G38 -> 0 | AT8: ='5'!G39 -> 0 | AU8: ='5'!G40 -> 0 | AV8: ='5'!G41 -> 0 | AW8: ='5'!G42 -> 4126.87 | AX8: ='5'!G43 -> 2267.92 | AY8: ='5'!G44 -> 0 | AZ8: ='5'!G36 -> 657.22 | BA8: ='5'!G49 -> 2720.39 | BB8: ='5'!G51 -> 1393.51 | BC8: ='5'!G52 -> 1825.76 | BD8: ='5'!G53 -> 4092.525 | BE8: ='5'!G54 -> 71.68 | BF8: ='5'!G55 -> 0 | BG8: ='5'!G56 -> 0 | BH8: ='5'!G57 -> 0 | BI8: ='5'!G50 -> 1440.76 | BJ8: =SUM(AV8,AW8,BF8,BG8) -> 4126.87 | BK8: ='5'!G84 -> 611 | BL8: =SUM(AQ8,AV8,AW8,AX8,BA8,BF8,BG8,BH8)/I8% -> 47.628697 | BM8: =SUM(AT8,BD8)/I8% -> 21.384288 | BN8: =(AS8+BC8)/I8 -> 0.095399728 | BO8: =K8+O8+R8+V8 -> 238863.96 | BP8: =SUM(AV8,AW8,AX8,BF8,BG8,BH8,BK8) -> 7005.79 | BQ8: =BP8/(AE8*280) -> 1.0557248
A9: 6 | B9: 6 | D9: ='6'!D3 -> 35 | E9: ='6'!D4 -> 0.8 | G9: ='6'!G8 -> 19877 | H9: ='6'!G8 -> 19877 | I9: ='6'!G7 -> 19631 | J9: 10 | K9: =H9*J9 -> 198770 | L9: =I9/202 -> 97.183168 | M9: ='6'!G15 -> 745.697 | N9: 35 | O9: =M9*N9 -> 26099.395 | P9: ='6'!G20 -> 168 | Q9: 134 | R9: =P9*Q9 -> 22512 | S9: =P9/(F9*202/100) -> #DIV/0! | T9: ='6'!G24 -> 0 | U9: 69 | V9: =T9*U9 -> 0 | W9: ='6'!G95 -> 57 | X9: ='6'!G96 -> 36 | Y9: ='6'!G97 -> 21 | Z9: =W9+X9+Y9 -> 114 | AA9: ='6'!G132 -> 0 | AB9: ='6'!G133 -> 24.27 | AC9: ='6'!G134 -> 0 | AD9: ='6'!G135 -> 0 | AE9: =AA9+AB9+AC9+AD9 -> 24.27 | AF9: =AV9+AW9+BF9+BG9 -> 3798.09 | AG9: =AF9/AE9 -> 156.4932 | AH9: ='6'!G136 -> 6.98 | AI9: ='6'!G137 -> 0 | AJ9: ='6'!G138 -> 0 | AK9: =AH9+AI9+AJ9 -> 6.98 | AL9: ='6'!G139 -> 5.78 | AM9: ='6'!G140 -> 0 | AO9: =AL9+AM9 -> 5.78 | AP9: ='6'!G123 -> 206.989 | AQ9: ='6'!G35 -> 0 | AR9: ='6'!G37 -> 0 | AS9: ='6'!G38 -> 0.18 | AT9: ='6'!G39 -> 0 | AU9: ='6'!G40 -> 0 | AV9: ='6'!G41 -> 0 | AW9: ='6'!G42 -> 3798.09 | AX9: ='6'!G43 -> 2346.04 | AY9: ='6'!G44 -> 0 | AZ9: ='6'!G36 -> 652.32 | BA9: ='6'!G49 -> 2793.25 | BB9: ='6'!G51 -> 1494.99 | BC9: ='6'!G52 -> 1949.48 | BD9: ='6'!G53 -> 4280.105 | BE9: ='6'!G54 -> 55.18 | BF9: ='6'!G55 -> 0 | BG9: ='6'!G56 -> 0 | BH9: ='6'!G57 -> 0 | BI9: ='6'!G50 -> 1621.44 | BJ9: =SUM(AV9,AW9,BF9,BG9) -> 3798.09 | BK9: ='6'!G84 -> 553 | BL9: =SUM(AQ9,AV9,AW9,AX9,BA9,BF9,BG9,BH9)/I9% -> 45.526871 | BM9: =SUM(AT9,BD9)/I9% -> 21.802786 | BN9: =(AS9+BC9)/I9 -> 0.099315369 | BO9: =K9+O9+R9+V9 -> 247381.39 | BP9: =SUM(AV9,AW9,AX9,BF9,BG9,BH9,BK9) -> 6697.13 | BQ9: =BP9/(AE9*280) -> 0.98550974
A10: 7 | B10: 7 | D10: ='7'!D3 -> 28 | E10: ='7'!D4 -> 0.78 | G10: ='7'!G8 -> 21859 | H10: ='7'!G8 -> 21859 | I10: ='7'!G7 -> 21704 | J10: 10 | K10: =H10*J10 -> 218590 | L10: =I10/202 -> 107.44554 | M10: ='7'!G15 -> 709 | N10: 35 | O10: =M10*N10 -> 24815 | P10: ='7'!G20 -> 137 | Q10: 134 | R10: =P10*Q10 -> 18358 | S10: =P10/(F10*202/100) -> #DIV/0! | T10: ='7'!G24 -> 0 | U10: 69 | V10: =T10*U10 -> 0 | W10: ='7'!G95 -> 76 | X10: ='7'!G96 -> 35 | Y10: ='7'!G97 -> 23 | Z10: =W10+X10+Y10 -> 134 | AA10: ='7'!G132 -> 0 | AB10: ='7'!G133 -> 24 | AC10: ='7'!G134 -> 0 | AD10: ='7'!G135 -> 0 | AE10: =AA10+AB10+AC10+AD10 -> 24 | AF10: =AV10+AW10+BF10+BG10 -> 4547.98 | AG10: =AF10/AE10 -> 189.49917 | AH10: ='7'!G136 -> 3.89 | AI10: ='7'!G137 -> 0 | AJ10: ='7'!G138 -> 6.46 | AK10: =AH10+AI10+AJ10 -> 10.35 | AL10: ='7'!G139 -> 5.2 | AM10: ='7'!G140 -> 0 | AO10: =AL10+AM10 -> 5.2 | AP10: ='7'!G123 -> 181.95 | AQ10: ='7'!G35 -> 0 | AR10: ='7'!G37 -> 0 | AS10: ='7'!G38 -> -0.38 | AT10: ='7'!G39 -> 0 | AU10: ='7'!G40 -> 0 | AV10: ='7'!G41 -> 0 | AW10: ='7'!G42 -> 4547.98 | AX10: ='7'!G43 -> 2375.88 | AY10: ='7'!G44 -> 0 | AZ10: ='7'!G36 -> 1199.06 | BA10: ='7'!G49 -> 2918.16 | BB10: ='7'!G51 -> 1541.21 | BC10: ='7'!G52 -> 2074.28 | BD10: ='7'!G53 -> 4516.17 | BE10: ='7'!G54 -> 42.67 | BF10: ='7'!G55 -> 0 | BG10: ='7'!G56 -> 0 | BH10: ='7'!G57 -> 0 | BI10: ='7'!G50 -> 1784.02 | BJ10: =SUM(AV10,AW10,BF10,BG10) -> 4547.98 | BK10: ='7'!G84 -> 531 | BL10: =SUM(AQ10,AV10,AW10,AX10,BA10,BF10,BG10,BH10)/I10% -> 45.346572 | BM10: =SUM(AT10,BD10)/I10% -> 20.808008 | BN10: =(AS10+BC10)/I10 -> 0.095553815 | BO10: =K10+O10+R10+V10 -> 261763 | BP10: =SUM(AV10,AW10,AX10,BF10,BG10,BH10,BK10) -> 7454.86 | BQ10: =BP10/(AE10*280) -> 1.1093542
A11: 8 | B11: 8 | D11: ='8'!D3 -> 29 | E11: ='8'!D4 -> 0.79 | G11: ='8'!G8 -> 19619 | H11: ='8'!G8 -> 19619 | I11: ='8'!G7 -> 19409 | J11: 10 | K11: =H11*J11 -> 196190 | L11: =I11/202 -> 96.084158 | M11: ='8'!G15 -> 776.34 | N11: 35 | O11: =M11*N11 -> 27171.9 | P11: ='8'!G20 -> 213 | Q11: 134 | R11: =P11*Q11 -> 28542 | S11: =P11/(F11*202/100) -> #DIV/0! | T11: ='8'!G24 -> 0 | U11: 69 | V11: =T11*U11 -> 0 | W11: ='8'!G95 -> 70 | X11: ='8'!G96 -> 33 | Y11: ='8'!G97 -> 30 | Z11: =W11+X11+Y11 -> 133 | AA11: ='8'!G132 -> 0 | AB11: ='8'!G133 -> 23.95 | AC11: ='8'!G134 -> 0 | AD11: ='8'!G135 -> 0 | AE11: =AA11+AB11+AC11+AD11 -> 23.95 | AF11: =AV11+AW11+BF11+BG11 -> 3950.74 | AG11: =AF11/AE11 -> 164.95783 | AH11: ='8'!G136 -> 9.24 | AI11: ='8'!G137 -> 0 | AJ11: ='8'!G138 -> 0 | AK11: =AH11+AI11+AJ11 -> 9.24 | AL11: ='8'!G139 -> 5.31 | AM11: ='8'!G140 -> 0 | AO11: =AL11+AM11 -> 5.31 | AP11: ='8'!G123 -> 187.08 | AQ11: ='8'!G35 -> 0 | AR11: ='8'!G37 -> 0 | AS11: ='8'!G38 -> 0 | AT11: ='8'!G39 -> 0 | AU11: ='8'!G40 -> 0 | AV11: ='8'!G41 -> 0 | AW11: ='8'!G42 -> 3950.74 | AX11: ='8'!G43 -> 2311.92 | AY11: ='8'!G44 -> 0 | AZ11: ='8'!G36 -> 749.88 | BA11: ='8'!G49 -> 2685.67 | BB11: ='8'!G51 -> 1480.21 | BC11: ='8'!G52 -> 2140.28 | BD11: ='8'!G53 -> 4105.07 | BE11: ='8'!G54 -> 44.79 | BF11: ='8'!G55 -> 0 | BG11: ='8'!G56 -> 0 | BH11: ='8'!G57 -> 0 | BI11: ='8'!G50 -> 1267.06 | BJ11: =SUM(AV11,AW11,BF11,BG11) -> 3950.74 | BK11: ='8'!G84 -> 579 | BL11: =SUM(AQ11,AV11,AW11,AX11,BA11,BF11,BG11,BH11)/I11% -> 46.104024 | BM11: =SUM(AT11,BD11)/I11% -> 21.150343 | BN11: =(AS11+BC11)/I11 -> 0.11027255 | BO11: =K11+O11+R11+V11 -> 251903.9 | BP11: =SUM(AV11,AW11,AX11,BF11,BG11,BH11,BK11) -> 6841.66 | BQ11: =BP11/(AE11*280) -> 1.0202296
A12: 9 | B12: 9 | D12: ='9'!D3 -> 30 | E12: ='9'!D4 -> 0.8 | G12: ='9'!G8 -> 21847 | H12: ='9'!G8 -> 21847 | I12: ='9'!G7 -> 21703 | J12: 10 | K12: =H12*J12 -> 218470 | L12: =I12/202 -> 107.44059 | M12: ='9'!G15 -> 820.59 | N12: 35 | O12: =M12*N12 -> 28720.65 | P12: ='9'!G20 -> 212 | Q12: 134 | R12: =P12*Q12 -> 28408 | S12: =P12/(F12*202/100) -> #DIV/0! | T12: ='9'!G24 -> 0 | U12: 69 | V12: =T12*U12 -> 0 | W12: ='9'!G95 -> 54 | X12: ='9'!G96 -> 25 | Y12: ='9'!G97 -> 24 | Z12: =W12+X12+Y12 -> 103 | AA12: ='9'!G132 -> 0 | AB12: ='9'!G133 -> 23.86 | AC12: ='9'!G134 -> 0 | AD12: ='9'!G135 -> 0 | AE12: =AA12+AB12+AC12+AD12 -> 23.86 | AF12: =AV12+AW12+BF12+BG12 -> 4804.79 | AG12: =AF12/AE12 -> 201.37427 | AH12: ='9'!G136 -> 8.82 | AI12: ='9'!G137 -> 0 | AJ12: ='9'!G138 -> 0 | AK12: =AH12+AI12+AJ12 -> 8.82 | AL12: ='9'!G139 -> 5.19 | AM12: ='9'!G140 -> 0 | AO12: =AL12+AM12 -> 5.19 | AP12: ='9'!G123 -> 185.25 | AQ12: ='9'!G35 -> 0 | AR12: ='9'!G37 -> 0 | AS12: ='9'!G38 -> 0 | AT12: ='9'!G39 -> 0 | AU12: ='9'!G40 -> 0 | AV12: ='9'!G41 -> 0 | AW12: ='9'!G42 -> 4804.79 | AX12: ='9'!G43 -> 2318.28 | AY12: ='9'!G44 -> 0 | AZ12: ='9'!G36 -> 1137.42 | BA12: ='9'!G49 -> 3050.99 | BB12: ='9'!G51 -> 1578.2 | BC12: ='9'!G52 -> 2091.36 | BD12: ='9'!G53 -> 4334.64 | BE12: ='9'!G54 -> 51.04 | BF12: ='9'!G55 -> 0 | BG12: ='9'!G56 -> 0 | BH12: ='9'!G57 -> 0 | BI12: ='9'!G50 -> 1557.7 | BJ12: =SUM(AV12,AW12,BF12,BG12) -> 4804.79 | BK12: ='8'!G84 -> 579 | BL12: =SUM(AQ12,AV12,AW12,AX12,BA12,BF12,BG12,BH12)/I12% -> 46.878588 | BM12: =SUM(AT12,BD12)/I12% -> 19.972538 | BN12: =(AS12+BC12)/I12 -> 0.096362715 | BO12: =K12+O12+R12+V12 -> 275598.65 | BP12: =SUM(AV12,AW12,AX12,BF12,BG12,BH12,BK12) -> 7702.07 | BQ12: =BP12/(AE12*280) -> 1.1528664
A13: 10 | B13: 10 | D13: ='10'!D3 -> 31 | E13: ='10'!D4 -> 0.82 | G13: ='10'!G8 -> 22721 | H13: ='10'!G8 -> 22721 | I13: ='10'!G7 -> 22555 | J13: 10 | K13: =H13*J13 -> 227210 | L13: =I13/202 -> 111.65842 | M13: ='10'!G15 -> 827.65 | N13: 35 | O13: =M13*N13 -> 28967.75 | P13: ='10'!G20 -> 253 | Q13: 134 | R13: =P13*Q13 -> 33902 | S13: =P13/(F13*202/100) -> #DIV/0! | T13: ='10'!G24 -> 0 | U13: 69 | V13: =T13*U13 -> 0 | W13: ='10'!G95 -> 140 | X13: ='10'!G96 -> 37 | Y13: ='10'!G97 -> 20 | Z13: =W13+X13+Y13 -> 197 | AA13: ='10'!G132 -> 0 | AB13: ='10'!G133 -> 24.19 | AC13: ='10'!G134 -> 0 | AD13: ='10'!G135 -> 3.15 | AE13: =AA13+AB13+AC13+AD13 -> 27.34 | AF13: =AV13+AW13+BF13+BG13 -> 5685.05 | AG13: =AF13/AE13 -> 207.93892 | AH13: ='10'!G136 -> 8.37 | AI13: ='10'!G137 -> 0 | AJ13: ='10'!G138 -> 0.04 | AK13: =AH13+AI13+AJ13 -> 8.41 | AL13: ='10'!G139 -> 6.01 | AM13: ='10'!G140 -> 0 | AO13: =AL13+AM13 -> 6.01 | AP13: ='10'!G123 -> 213.99 | AQ13: ='10'!G35 -> 0 | AR13: ='10'!G37 -> 0 | AS13: ='10'!G38 -> 0 | AT13: ='10'!G39 -> 0 | AU13: ='10'!G40 -> 0 | AV13: ='10'!G41 -> 0 | AW13: ='10'!G42 -> 4991.61 | AX13: ='10'!G43 -> 2521.56 | AY13: ='10'!G44 -> 0 | AZ13: ='10'!G36 -> 955.72 | BA13: ='10'!G49 -> 3096.25 | BB13: ='10'!G51 -> 1546.48 | BC13: ='10'!G52 -> 2233.36 | BD13: ='10'!G53 -> 4326.1 | BE13: ='10'!G54 -> 45.61 | BF13: ='10'!G55 -> 0 | BG13: ='10'!G56 -> 693.44 | BH13: ='10'!G57 -> 0 | BI13: ='10'!G50 -> 1440.44 | BJ13: =SUM(AV13,AW13,BF13,BG13) -> 5685.05 | BK13: ='8'!G84 -> 579 | BL13: =SUM(AQ13,AV13,AW13,AX13,BA13,BF13,BG13,BH13)/I13% -> 50.112436 | BM13: =SUM(AT13,BD13)/I13% -> 19.180226 | BN13: =(AS13+BC13)/I13 -> 0.099018399 | BO13: =K13+O13+R13+V13 -> 290079.75 | BP13: =SUM(AV13,AW13,AX13,BF13,BG13,BH13,BK13) -> 8785.61 | BQ13: =BP13/(AE13*280) -> 1.1476656
A14: 11 | B14: 11 | D14: ='11'!D3 -> 31 | E14: ='11'!D4 -> 0.82 | G14: ='11'!G8 -> 22721 | H14: ='11'!G8 -> 22721 | I14: ='11'!G7 -> 22555 | J14: 10 | K14: =H14*J14 -> 227210 | L14: =I14/202 -> 111.65842 | M14: ='11'!G15 -> 827.65 | N14: 35 | O14: =M14*N14 -> 28967.75 | P14: ='11'!G20 -> 253 | Q14: 134 | R14: =P14*Q14 -> 33902 | S14: =P14/(F14*202/100) -> #DIV/0! | T14: ='11'!G24 -> 0 | U14: 69 | V14: =T14*U14 -> 0 | W14: ='11'!G95 -> 140 | X14: ='11'!G96 -> 37 | Y14: ='11'!G97 -> 20 | Z14: =W14+X14+Y14 -> 197 | AA14: ='11'!G132 -> 0 | AB14: ='11'!G133 -> 24.19 | AC14: ='11'!G134 -> 0 | AD14: ='11'!G135 -> 3.15 | AE14: =AA14+AB14+AC14+AD14 -> 27.34 | AF14: =AV14+AW14+BF14+BG14 -> 5685.05 | AG14: =AF14/AE14 -> 207.93892 | AH14: ='11'!G136 -> 8.37 | AI14: ='11'!G137 -> 0 | AJ14: ='11'!G138 -> 0.04 | AK14: =AH14+AI14+AJ14 -> 8.41 | AL14: ='11'!G139 -> 6.01 | AM14: ='11'!G140 -> 0 | AO14: =AL14+AM14 -> 6.01 | AP14: ='11'!G123 -> 213.99 | AQ14: ='11'!G35 -> 0 | AR14: ='11'!G37 -> 0 | AS14: ='11'!G38 -> 0 | AT14: ='11'!G39 -> 0 | AU14: ='11'!G40 -> 0 | AV14: ='11'!G41 -> 0 | AW14: ='11'!G42 -> 4991.61 | AX14: ='11'!G43 -> 2521.56 | AY14: ='11'!G44 -> 0 | AZ14: ='11'!G36 -> 955.72 | BA14: ='11'!G49 -> 3096.25 | BB14: ='11'!G51 -> 1546.48 | BC14: ='11'!G52 -> 2233.36 | BD14: ='11'!G53 -> 4326.1 | BE14: ='11'!G54 -> 45.61 | BF14: ='11'!G55 -> 0 | BG14: ='11'!G56 -> 693.44 | BH14: ='11'!G57 -> 0 | BI14: ='11'!G50 -> 1440.44 | BJ14: =SUM(AV14,AW14,BF14,BG14) -> 5685.05 | BK14: ='11'!G84 -> 554 | BL14: =SUM(AQ14,AV14,AW14,AX14,BA14,BF14,BG14,BH14)/I14% -> 50.112436 | BM14: =SUM(AT14,BD14)/I14% -> 19.180226 | BN14: =(AS14+BC14)/I14 -> 0.099018399 | BO14: =K14+O14+R14+V14 -> 290079.75 | BP14: =SUM(AV14,AW14,AX14,BF14,BG14,BH14,BK14) -> 8760.61 | BQ14: =BP14/(AE14*280) -> 1.1443999
A15: 12 | B15: 12 | D15: ='12'!D3 -> 31 | E15: ='12'!D4 -> 0.82 | G15: ='12'!G8 -> 21800 | H15: ='12'!G8 -> 21800 | I15: ='12'!G7 -> 21691 | J15: 10 | K15: =H15*J15 -> 218000 | L15: =I15/202 -> 107.38119 | M15: ='12'!G15 -> 790.01 | N15: 35 | O15: =M15*N15 -> 27650.35 | P15: ='12'!G20 -> 276 | Q15: 134 | R15: =P15*Q15 -> 36984 | S15: =P15/(F15*202/100) -> #DIV/0! | T15: ='12'!G24 -> 0 | U15: 69 | V15: =T15*U15 -> 0 | W15: ='12'!G95 -> 75 | X15: ='12'!G96 -> 37 | Y15: ='12'!G97 -> 47 | Z15: =W15+X15+Y15 -> 159 | AA15: ='12'!G132 -> 0 | AB15: ='12'!G133 -> 24.09 | AC15: ='12'!G134 -> 0 | AD15: ='12'!G135 -> 0 | AE15: =AA15+AB15+AC15+AD15 -> 24.09 | AF15: =AV15+AW15+BF15+BG15 -> 5451.27 | AG15: =AF15/AE15 -> 226.28767 | AH15: ='12'!G136 -> 8.1 | AI15: ='12'!G137 -> 0 | AJ15: ='12'!G138 -> 0.88 | AK15: =AH15+AI15+AJ15 -> 8.98 | AL15: ='12'!G139 -> 5.65 | AM15: ='12'!G140 -> 0 | AO15: =AL15+AM15 -> 5.65 | AP15: ='12'!G123 -> 199.63 | AQ15: ='12'!G35 -> 0 | AR15: ='12'!G37 -> 0 | AS15: ='12'!G38 -> 0 | AT15: ='12'!G39 -> 0 | AU15: ='12'!G40 -> 0 | AV15: ='12'!G41 -> 0 | AW15: ='12'!G42 -> 5451.54 | AX15: ='12'!G43 -> 2456.04 | AY15: ='12'!G44 -> 0 | AZ15: ='12'!G36 -> 692.86 | BA15: ='12'!G49 -> 2850.02 | BB15: ='12'!G51 -> 1546.26 | BC15: ='12'!G52 -> 2338.4 | BD15: ='12'!G53 -> 4438.87 | BE15: ='12'!G54 -> 47.61 | BF15: ='12'!G55 -> -0.27 | BG15: ='12'!G56 -> 0 | BH15: ='12'!G57 -> 0 | BI15: ='12'!G50 -> 1152.02 | BJ15: =SUM(AV15,AW15,BF15,BG15) -> 5451.27 | BK15: ='12'!G84 -> 523 | BL15: =SUM(AQ15,AV15,AW15,AX15,BA15,BF15,BG15,BH15)/I15% -> 49.593518 | BM15: =SUM(AT15,BD15)/I15% -> 20.46411 | BN15: =(AS15+BC15)/I15 -> 0.10780508 | BO15: =K15+O15+R15+V15 -> 282634.35 | BP15: =SUM(AV15,AW15,AX15,BF15,BG15,BH15,BK15) -> 8430.31 | BQ15: =BP15/(AE15*280) -> 1.2498236
A16: 13 | B16: 13 | D16: ='13'!D3 -> 28 | E16: ='13'!D4 -> 0.78 | G16: ='13'!G8 -> 20114 | H16: ='13'!G8 -> 20114 | I16: ='13'!G7 -> 19954 | J16: 10 | K16: =H16*J16 -> 201140 | L16: =I16/202 -> 98.782178 | M16: ='13'!G15 -> 787 | N16: 35 | O16: =M16*N16 -> 27545 | P16: ='13'!G20 -> 236 | Q16: 134 | R16: =P16*Q16 -> 31624 | S16: =P16/(F16*202/100) -> #DIV/0! | T16: ='13'!G24 -> 0 | U16: 69 | V16: =T16*U16 -> 0 | W16: ='13'!G95 -> 71 | X16: ='13'!G96 -> 39 | Y16: ='13'!G97 -> 36 | Z16: =W16+X16+Y16 -> 146 | AA16: ='13'!G132 -> 0 | AB16: ='13'!G133 -> 23.88 | AC16: ='13'!G134 -> 0 | AD16: ='13'!G135 -> 0 | AE16: =AA16+AB16+AC16+AD16 -> 23.88 | AF16: =AV16+AW16+BF16+BG16 -> 4618.27 | AG16: =AF16/AE16 -> 193.39489 | AH16: ='13'!G136 -> 8.07 | AI16: ='13'!G137 -> 0 | AJ16: ='13'!G138 -> 0 | AK16: =AH16+AI16+AJ16 -> 8.07 | AL16: ='13'!G139 -> 5.89 | AM16: ='13'!G140 -> 0 | AO16: =AL16+AM16 -> 5.89 | AP16: ='13'!G123 -> 211.22 | AQ16: ='13'!G35 -> 0 | AR16: ='13'!G37 -> 0 | AS16: ='13'!G38 -> 0 | AT16: ='13'!G39 -> 0 | AU16: ='13'!G40 -> 0 | AV16: ='13'!G41 -> 0.05 | AW16: ='13'!G42 -> 4618.33 | AX16: ='13'!G43 -> 2427.88 | AY16: ='13'!G44 -> 0 | AZ16: ='13'!G36 -> 632.56 | BA16: ='13'!G49 -> 2829.87 | BB16: ='13'!G51 -> 1445.18 | BC16: ='13'!G52 -> 2134.12 | BD16: ='13'!G53 -> 4114.55 | BE16: ='13'!G54 -> 37.75 | BF16: ='13'!G55 -> 0 | BG16: ='13'!G56 -> -0.11 | BH16: ='13'!G57 -> 0 | BI16: ='13'!G50 -> 1071.21 | BJ16: =SUM(AV16,AW16,BF16,BG16) -> 4618.27 | BK16: ='13'!G84 -> 550 | BL16: =SUM(AQ16,AV16,AW16,AX16,BA16,BF16,BG16,BH16)/I16% -> 49.493936 | BM16: =SUM(AT16,BD16)/I16% -> 20.620176 | BN16: =(AS16+BC16)/I16 -> 0.10695199 | BO16: =K16+O16+R16+V16 -> 260309 | BP16: =SUM(AV16,AW16,AX16,BF16,BG16,BH16,BK16) -> 7596.15 | BQ16: =BP16/(AE16*280) -> 1.1360598
A17: 14 | B17: 14 | D17: ='14'!D3 -> 28 | E17: ='14'!D4 -> 0.72 | G17: ='14'!G8 -> 20289 | H17: ='14'!G8 -> 20289 | I17: ='14'!G7 -> 20124 | J17: 10 | K17: =H17*J17 -> 202890 | L17: =I17/202 -> 99.623762 | M17: ='14'!G15 -> 786 | N17: 35 | O17: =M17*N17 -> 27510 | P17: ='14'!G20 -> 179 | Q17: 134 | R17: =P17*Q17 -> 23986 | S17: =P17/(F17*202/100) -> #DIV/0! | T17: ='14'!G24 -> 0 | U17: 69 | V17: =T17*U17 -> 0 | W17: ='14'!G95 -> 62 | X17: ='14'!G96 -> 23 | Y17: ='14'!G97 -> 25 | Z17: =W17+X17+Y17 -> 110 | AA17: ='14'!G132 -> 0 | AB17: ='14'!G133 -> 23.78 | AC17: ='14'!G134 -> 0 | AD17: ='14'!G135 -> 0 | AE17: =AA17+AB17+AC17+AD17 -> 23.78 | AF17: =AV17+AW17+BF17+BG17 -> 4912.52 | AG17: =AF17/AE17 -> 206.582 | AH17: ='14'!G136 -> 8.71 | AI17: ='14'!G137 -> 0.06 | AJ17: ='14'!G138 -> 0 | AK17: =AH17+AI17+AJ17 -> 8.77 | AL17: ='14'!G139 -> 5.96 | AM17: ='14'!G140 -> 0 | AO17: =AL17+AM17 -> 5.96 | AP17: ='14'!G123 -> 213 | AQ17: ='14'!G35 -> 0 | AR17: ='14'!G37 -> 0 | AS17: ='14'!G38 -> 0 | AT17: ='14'!G39 -> 0 | AU17: ='14'!G40 -> 0 | AV17: ='14'!G41 -> 0 | AW17: ='14'!G42 -> 4912.52 | AX17: ='14'!G43 -> 2391.53 | AY17: ='14'!G44 -> 0 | AZ17: ='14'!G36 -> 672.37 | BA17: ='14'!G49 -> 2672 | BB17: ='14'!G51 -> 1433.43 | BC17: ='14'!G52 -> 2025.09 | BD17: ='14'!G53 -> 4090 | BE17: ='14'!G54 -> 37.46 | BF17: ='14'!G55 -> 0 | BG17: ='14'!G56 -> 0 | BH17: ='14'!G57 -> 0 | BI17: ='14'!G50 -> 1235 | BJ17: =SUM(AV17,AW17,BF17,BG17) -> 4912.52 | BK17: ='14'!G84 -> 535 | BL17: =SUM(AQ17,AV17,AW17,AX17,BA17,BF17,BG17,BH17)/I17% -> 49.572898 | BM17: =SUM(AT17,BD17)/I17% -> 20.323991 | BN17: =(AS17+BC17)/I17 -> 0.10063059 | BO17: =K17+O17+R17+V17 -> 254386 | BP17: =SUM(AV17,AW17,AX17,BF17,BG17,BH17,BK17) -> 7839.05 | BQ17: =BP17/(AE17*280) -> 1.1773174
A18: 15 | B18: 15 | D18: ='15'!D3 -> 29 | E18: ='15'!D4 -> 0.76 | G18: ='15'!G8 -> 20148 | H18: ='15'!G8 -> 20148 | I18: ='15'!G7 -> 19945 | J18: 10 | K18: =H18*J18 -> 201480 | L18: =I18/202 -> 98.737624 | M18: ='15'!G15 -> 719 | N18: 35 | O18: =M18*N18 -> 25165 | P18: ='15'!G20 -> 196 | Q18: 134 | R18: =P18*Q18 -> 26264 | S18: =P18/(F18*202/100) -> #DIV/0! | T18: ='15'!G24 -> 0 | U18: 69 | V18: =T18*U18 -> 0 | W18: ='15'!G95 -> 51 | X18: ='15'!G96 -> 17 | Y18: ='15'!G97 -> 26 | Z18: =W18+X18+Y18 -> 94 | AA18: ='15'!G132 -> 0 | AB18: ='15'!G133 -> 24 | AC18: ='15'!G134 -> 0 | AD18: ='15'!G135 -> 0 | AE18: =AA18+AB18+AC18+AD18 -> 24 | AF18: =AV18+AW18+BF18+BG18 -> 5101 | AG18: =AF18/AE18 -> 212.54167 | AH18: ='15'!G136 -> 7.49 | AI18: ='15'!G137 -> 0 | AJ18: ='15'!G138 -> 0 | AK18: =AH18+AI18+AJ18 -> 7.49 | AL18: ='15'!G139 -> 6.07 | AM18: ='15'!G140 -> 0 | AO18: =AL18+AM18 -> 6.07 | AP18: ='15'!G123 -> 236 | AQ18: ='15'!G35 -> 0 | AR18: ='15'!G37 -> 0 | AS18: ='15'!G38 -> 0 | AT18: ='15'!G39 -> 0 | AU18: ='15'!G40 -> 0 | AV18: ='15'!G41 -> 0 | AW18: ='15'!G42 -> 5101 | AX18: ='15'!G43 -> 2231 | AY18: ='15'!G44 -> 0 | AZ18: ='15'!G36 -> 633 | BA18: ='15'!G49 -> 2739 | BB18: ='15'!G51 -> 1416 | BC18: ='15'!G52 -> 1866 | BD18: ='15'!G53 -> 4210 | BE18: ='15'!G54 -> 46 | BF18: ='15'!G55 -> 0 | BG18: ='15'!G56 -> 0 | BH18: ='15'!G57 -> 0 | BI18: ='15'!G50 -> 1106 | BJ18: =SUM(AV18,AW18,BF18,BG18) -> 5101 | BK18: ='15'!G84 -> 562 | BL18: =SUM(AQ18,AV18,AW18,AX18,BA18,BF18,BG18,BH18)/I18% -> 50.493858 | BM18: =SUM(AT18,BD18)/I18% -> 21.108047 | BN18: =(AS18+BC18)/I18 -> 0.093557283 | BO18: =K18+O18+R18+V18 -> 252909 | BP18: =SUM(AV18,AW18,AX18,BF18,BG18,BH18,BK18) -> 7894 | BQ18: =BP18/(AE18*280) -> 1.1747024
A19: 16 | B19: 16 | D19: ='16'!D3 -> 29 | E19: ='16'!D4 -> 0.76 | G19: ='16'!G8 -> 19830 | H19: ='16'!G8 -> 19830 | I19: ='16'!G7 -> 19650 | J19: 10 | K19: =H19*J19 -> 198300 | L19: =I19/202 -> 97.277228 | M19: ='16'!G15 -> 410 | N19: 35 | O19: =M19*N19 -> 14350 | P19: ='16'!G20 -> 155 | Q19: 134 | R19: =P19*Q19 -> 20770 | S19: =P19/(F19*202/100) -> #DIV/0! | T19: ='16'!G24 -> 0 | U19: 69 | V19: =T19*U19 -> 0 | W19: ='16'!G95 -> 38 | X19: ='16'!G96 -> 17 | Y19: ='16'!G97 -> 15 | Z19: =W19+X19+Y19 -> 70 | AA19: ='16'!G132 -> 0 | AB19: ='16'!G133 -> 15 | AC19: ='16'!G134 -> 0 | AD19: ='16'!G135 -> 8.76 | AE19: =AA19+AB19+AC19+AD19 -> 23.76 | AF19: =AV19+AW19+BF19+BG19 -> 5166 | AG19: =AF19/AE19 -> 217.42424 | AH19: ='16'!G136 -> 0.05 | AI19: ='16'!G137 -> 0 | AJ19: ='16'!G138 -> 0 | AK19: =AH19+AI19+AJ19 -> 0.05 | AL19: ='16'!G139 -> 6.71 | AM19: ='16'!G140 -> 0 | AO19: =AL19+AM19 -> 6.71 | AP19: ='16'!G123 -> 216 | AQ19: ='16'!G35 -> 0 | AR19: ='16'!G37 -> 0 | AS19: ='16'!G38 -> 0 | AT19: ='16'!G39 -> 0 | AU19: ='16'!G40 -> 0 | AV19: ='16'!G41 -> 0 | AW19: ='16'!G42 -> 3045 | AX19: ='16'!G43 -> 2154 | AY19: ='16'!G44 -> 0 | AZ19: ='16'!G36 -> 628 | BA19: ='16'!G49 -> 2627 | BB19: ='16'!G51 -> 1407 | BC19: ='16'!G52 -> 1727 | BD19: ='16'!G53 -> 4203 | BE19: ='16'!G54 -> 0 | BF19: ='16'!G55 -> 0 | BG19: ='16'!G56 -> 2121 | BH19: ='16'!G57 -> 0 | BI19: ='16'!G50 -> 1043 | BJ19: =SUM(AV19,AW19,BF19,BG19) -> 5166 | BK19: ='16'!G84 -> 447 | BL19: =SUM(AQ19,AV19,AW19,AX19,BA19,BF19,BG19,BH19)/I19% -> 50.620865 | BM19: =SUM(AT19,BD19)/I19% -> 21.389313 | BN19: =(AS19+BC19)/I19 -> 0.087888041 | BO19: =K19+O19+R19+V19 -> 233420 | BP19: =SUM(AV19,AW19,AX19,BF19,BG19,BH19,BK19) -> 7767 | BQ19: =BP19/(AE19*280) -> 1.1674784
A20: 17 | B20: 17 | D20: ='17'!D3 -> 28 | E20: ='17'!D4 -> 0.76 | G20: ='17'!G8 -> 20101 | H20: ='17'!G8 -> 20101 | I20: ='17'!G7 -> 19937 | J20: 10 | K20: =H20*J20 -> 201010 | L20: =I20/202 -> 98.69802 | M20: ='17'!G15 -> 787 | N20: 35 | O20: =M20*N20 -> 27545 | P20: ='17'!G20 -> 198 | Q20: 134 | R20: =P20*Q20 -> 26532 | S20: =P20/(F20*202/100) -> #DIV/0! | T20: ='17'!G24 -> 0 | U20: 69 | V20: =T20*U20 -> 0 | W20: ='17'!G95 -> 63 | X20: ='17'!G96 -> 18 | Y20: ='17'!G97 -> 19 | Z20: =W20+X20+Y20 -> 100 | AA20: ='17'!G132 -> 0 | AB20: ='17'!G133 -> 0 | AC20: ='17'!G134 -> 0 | AD20: ='17'!G135 -> 24 | AE20: =AA20+AB20+AC20+AD20 -> 24 | AF20: =AV20+AW20+BF20+BG20 -> 4799 | AG20: =AF20/AE20 -> 199.95833 | AH20: ='17'!G136 -> 0 | AI20: ='17'!G137 -> 8.19 | AJ20: ='17'!G138 -> 2.33 | AK20: =AH20+AI20+AJ20 -> 10.52 | AL20: ='17'!G139 -> 5.39 | AM20: ='17'!G140 -> 0 | AO20: =AL20+AM20 -> 5.39 | AP20: ='17'!G123 -> 193 | AQ20: ='17'!G35 -> 0 | AR20: ='17'!G37 -> 0 | AS20: ='17'!G38 -> 0 | AT20: ='17'!G39 -> 0 | AU20: ='17'!G40 -> 0 | AV20: ='17'!G41 -> 0 | AW20: ='17'!G42 -> 0 | AX20: ='17'!G43 -> 2102 | AY20: ='17'!G44 -> 0 | AZ20: ='17'!G36 -> 864 | BA20: ='17'!G49 -> 2798 | BB20: ='17'!G51 -> 1495 | BC20: ='17'!G52 -> 1867 | BD20: ='17'!G53 -> 4175 | BE20: ='17'!G54 -> 109 | BF20: ='17'!G55 -> 0 | BG20: ='17'!G56 -> 4799 | BH20: ='17'!G57 -> 0 | BI20: ='17'!G50 -> 1110 | BJ20: =SUM(AV20,AW20,BF20,BG20) -> 4799 | BK20: ='17'!G84 -> 516 | BL20: =SUM(AQ20,AV20,AW20,AX20,BA20,BF20,BG20,BH20)/I20% -> 48.648242 | BM20: =SUM(AT20,BD20)/I20% -> 20.940964 | BN20: =(AS20+BC20)/I20 -> 0.093644982 | BO20: =K20+O20+R20+V20 -> 255087 | BP20: =SUM(AV20,AW20,AX20,BF20,BG20,BH20,BK20) -> 7417 | BQ20: =BP20/(AE20*280) -> 1.1037202
A21: 18 | B21: 18 | D21: ='18'!D3 -> 28 | E21: ='18'!D4 -> 0.76 | G21: ='18'!G8 -> 20294 | H21: ='18'!G8 -> 20294 | I21: ='18'!G7 -> 20158 | J21: 10 | K21: =H21*J21 -> 202940 | L21: =I21/202 -> 99.792079 | M21: ='18'!G15 -> 539 | N21: 35 | O21: =M21*N21 -> 18865 | P21: ='18'!G20 -> 175 | Q21: 134 | R21: =P21*Q21 -> 23450 | S21: =P21/(F21*202/100) -> #DIV/0! | T21: ='18'!G24 -> 0 | U21: 69 | V21: =T21*U21 -> 0 | W21: ='18'!G95 -> 68 | X21: ='18'!G96 -> 18 | Y21: ='18'!G97 -> 25 | Z21: =W21+X21+Y21 -> 111 | AA21: ='18'!G132 -> 0 | AB21: ='18'!G133 -> 0 | AC21: ='18'!G134 -> 0 | AD21: ='18'!G135 -> 24 | AE21: =AA21+AB21+AC21+AD21 -> 24 | AF21: =AV21+AW21+BF21+BG21 -> 4838 | AG21: =AF21/AE21 -> 201.58333 | AH21: ='18'!G136 -> -0.05 | AI21: ='18'!G137 -> 0 | AJ21: ='18'!G138 -> 6.14 | AK21: =AH21+AI21+AJ21 -> 6.09 | AL21: ='18'!G139 -> 6.08 | AM21: ='18'!G140 -> 0 | AO21: =AL21+AM21 -> 6.08 | AP21: ='18'!G123 -> 206 | AQ21: ='18'!G35 -> 0 | AR21: ='18'!G37 -> 0 | AS21: ='18'!G38 -> 0 | AT21: ='18'!G39 -> 0 | AU21: ='18'!G40 -> 0 | AV21: ='18'!G41 -> 0 | AW21: ='18'!G42 -> 0 | AX21: ='18'!G43 -> 2092 | AY21: ='18'!G44 -> 0 | AZ21: ='18'!G36 -> 944 | BA21: ='18'!G49 -> 2822 | BB21: ='18'!G51 -> 1508 | BC21: ='18'!G52 -> 1825 | BD21: ='18'!G53 -> 4194 | BE21: ='18'!G54 -> 65 | BF21: ='18'!G55 -> 0 | BG21: ='18'!G56 -> 4838 | BH21: ='18'!G57 -> 0 | BI21: ='18'!G50 -> 1184 | BJ21: =SUM(AV21,AW21,BF21,BG21) -> 4838 | BK21: ='18'!G84 -> 483 | BL21: =SUM(AQ21,AV21,AW21,AX21,BA21,BF21,BG21,BH21)/I21% -> 48.377815 | BM21: =SUM(AT21,BD21)/I21% -> 20.805635 | BN21: =(AS21+BC21)/I21 -> 0.090534775 | BO21: =K21+O21+R21+V21 -> 245255 | BP21: =SUM(AV21,AW21,AX21,BF21,BG21,BH21,BK21) -> 7413 | BQ21: =BP21/(AE21*280) -> 1.103125
A22: 19 | B22: 19 | D22: ='19'!D3 -> 29 | E22: ='19'!D4 -> 0.76 | G22: ='19'!G8 -> 19507 | H22: ='19'!G8 -> 19507 | I22: ='19'!G7 -> 19378 | J22: 10 | K22: =H22*J22 -> 195070 | L22: =I22/202 -> 95.930693 | M22: ='19'!G15 -> 547.31 | N22: 35 | O22: =M22*N22 -> 19155.85 | P22: ='19'!G20 -> 194 | Q22: 134 | R22: =P22*Q22 -> 25996 | S22: =P22/(F22*202/100) -> #DIV/0! | T22: ='19'!G24 -> 0 | U22: 69 | V22: =T22*U22 -> 0 | W22: ='19'!G95 -> 55 | X22: ='19'!G96 -> 29 | Y22: ='19'!G97 -> 30 | Z22: =W22+X22+Y22 -> 114 | AA22: ='19'!G132 -> 0 | AB22: ='19'!G133 -> 0 | AC22: ='19'!G134 -> 0 | AD22: ='19'!G135 -> 23.75 | AE22: =AA22+AB22+AC22+AD22 -> 23.75 | AF22: =AV22+AW22+BF22+BG22 -> 3914 | AG22: =AF22/AE22 -> 164.8 | AH22: ='19'!G136 -> 0 | AI22: ='19'!G137 -> 0 | AJ22: ='19'!G138 -> 5.51 | AK22: =AH22+AI22+AJ22 -> 5.51 | AL22: ='19'!G139 -> 5.92 | AM22: ='19'!G140 -> 0 | AO22: =AL22+AM22 -> 5.92 | AP22: ='19'!G123 -> 231 | AQ22: ='19'!G35 -> 0 | AR22: ='19'!G37 -> 0 | AS22: ='19'!G38 -> 0 | AT22: ='19'!G39 -> 0 | AU22: ='19'!G40 -> 0 | AV22: ='19'!G41 -> 0 | AW22: ='19'!G42 -> 0 | AX22: ='19'!G43 -> 2021 | AY22: ='19'!G44 -> 0 | AZ22: ='19'!G36 -> 856 | BA22: ='19'!G49 -> 3026 | BB22: ='19'!G51 -> 1440 | BC22: ='19'!G52 -> 2050 | BD22: ='19'!G53 -> 4054 | BE22: ='19'!G54 -> 64.75 | BF22: ='19'!G55 -> 0 | BG22: ='19'!G56 -> 3914 | BH22: ='19'!G57 -> 0 | BI22: ='19'!G50 -> 1186 | BJ22: =SUM(AV22,AW22,BF22,BG22) -> 3914 | BK22: ='19'!G84 -> 456 | BL22: =SUM(AQ22,AV22,AW22,AX22,BA22,BF22,BG22,BH22)/I22% -> 46.243162 | BM22: =SUM(AT22,BD22)/I22% -> 20.920632 | BN22: =(AS22+BC22)/I22 -> 0.10579007 | BO22: =K22+O22+R22+V22 -> 240221.85 | BP22: =SUM(AV22,AW22,AX22,BF22,BG22,BH22,BK22) -> 6391 | BQ22: =BP22/(AE22*280) -> 0.96105263
A23: 20 | B23: 20 | D23: ='20'!D3 -> 29 | E23: ='20'!D4 -> 0.76 | G23: ='20'!G8 -> 19507 | H23: ='20'!G8 -> 19507 | I23: ='20'!G7 -> 19378 | J23: 10 | K23: =H23*J23 -> 195070 | L23: =I23/202 -> 95.930693 | M23: ='20'!G15 -> 547.31 | N23: 35 | O23: =M23*N23 -> 19155.85 | P23: ='20'!G20 -> 194 | Q23: 134 | R23: =P23*Q23 -> 25996 | S23: =P23/(F23*202/100) -> #DIV/0! | T23: ='20'!G24 -> 0 | U23: 69 | V23: =T23*U23 -> 0 | W23: ='20'!G95 -> 55 | X23: ='20'!G96 -> 29 | Y23: ='20'!G97 -> 30 | Z23: =W23+X23+Y23 -> 114 | AA23: ='20'!G132 -> 0 | AB23: ='20'!G133 -> 0 | AC23: ='20'!G134 -> 0 | AD23: ='20'!G135 -> 23.75 | AE23: =AA23+AB23+AC23+AD23 -> 23.75 | AF23: =AV23+AW23+BF23+BG23 -> 3914 | AG23: =AF23/AE23 -> 164.8 | AH23: ='20'!G136 -> 0 | AI23: ='20'!G137 -> 0 | AJ23: ='20'!G138 -> 5.51 | AK23: =AH23+AI23+AJ23 -> 5.51 | AL23: ='20'!G139 -> 5.92 | AM23: ='20'!G140 -> 0 | AO23: =AL23+AM23 -> 5.92 | AP23: ='20'!G123 -> 231 | AQ23: ='20'!G35 -> 0 | AR23: ='20'!G37 -> 0 | AS23: ='20'!G38 -> 0 | AT23: ='20'!G39 -> 0 | AU23: ='20'!G40 -> 0 | AV23: ='20'!G41 -> 0 | AW23: ='20'!G42 -> 0 | AX23: ='20'!G43 -> 2021 | AY23: ='20'!G44 -> 0 | AZ23: ='20'!G36 -> 856 | BA23: ='20'!G49 -> 3026 | BB23: ='20'!G51 -> 1440 | BC23: ='20'!G52 -> 2050 | BD23: ='20'!G576 -> 0 | BE23: ='20'!G54 -> 64.75 | BF23: ='20'!G55 -> 0 | BG23: ='20'!G56 -> 3914 | BH23: ='20'!G57 -> 0 | BI23: ='20'!G50 -> 1186 | BJ23: =SUM(AV23,AW23,BF23,BG23) -> 3914 | BK23: ='20'!G84 -> 456 | BL23: =SUM(AQ23,AV23,AW23,AX23,BA23,BF23,BG23,BH23)/I23% -> 46.243162 | BM23: =SUM(AT23,BD23)/I23% -> 0 | BN23: =(AS23+BC23)/I23 -> 0.10579007 | BO23: =K23+O23+R23+V23 -> 240221.85 | BP23: =SUM(AV23,AW23,AX23,BF23,BG23,BH23,BK23) -> 6391 | BQ23: =BP23/(AE23*280) -> 0.96105263
A24: 21 | B24: 21 | D24: 21 | E24: ='21'!D4 -> 0.76 | G24: ='21'!G8 -> 19140 | H24: ='21'!G8 -> 19140 | I24: ='21'!G7 -> 18976 | J24: 10 | K24: =H24*J24 -> 191400 | L24: =I24/202 -> 93.940594 | M24: ='21'!G15 -> 812 | N24: 35 | O24: =M24*N24 -> 28420 | P24: ='21'!G20 -> 175 | Q24: 134 | R24: =P24*Q24 -> 23450 | S24: =P24/(F24*202/100) -> #DIV/0! | T24: ='21'!G24 -> 0 | U24: 69 | V24: =T24*U24 -> 0 | W24: ='21'!G95 -> 72 | X24: ='21'!G96 -> 17 | Y24: ='21'!G97 -> 18 | Z24: =W24+X24+Y24 -> 107 | AA24: ='21'!G132 -> 0 | AB24: ='21'!G133 -> 0 | AC24: ='21'!G134 -> 0 | AD24: ='21'!G135 -> 24 | AE24: =AA24+AB24+AC24+AD24 -> 24 | AF24: =AV24+AW24+BF24+BG24 -> 3571 | AG24: =AF24/AE24 -> 148.79167 | AH24: ='21'!G136 -> 0 | AI24: ='21'!G137 -> 9.82 | AJ24: ='21'!G138 -> 2 | AK24: =AH24+AI24+AJ24 -> 11.82 | AL24: ='21'!G139 -> 6.11 | AM24: ='21'!G140 -> 0 | AO24: =AL24+AM24 -> 6.11 | AP24: ='21'!G123 -> 196 | AQ24: ='21'!G35 -> 0 | AR24: ='21'!G37 -> 0 | AS24: ='21'!G38 -> 0.38 | AT24: ='21'!G39 -> 0 | AU24: ='21'!G40 -> 0 | AV24: ='21'!G41 -> 0 | AW24: ='21'!G42 -> 0 | AX24: ='21'!G43 -> 2080 | AY24: ='21'!G44 -> 0 | AZ24: ='21'!G36 -> 745 | BA24: ='21'!G49 -> 2699 | BB24: ='21'!G51 -> 1421 | BC24: ='21'!G52 -> 1840 | BD24: ='21'!G53 -> 4396 | BE24: ='21'!G54 -> 0 | BF24: ='21'!G55 -> 0 | BG24: ='21'!G56 -> 3571 | BH24: ='21'!G57 -> 0 | BI24: ='21'!G50 -> 1523 | BJ24: =SUM(AV24,AW24,BF24,BG24) -> 3571 | BK24: ='21'!G84 -> 504 | BL24: =SUM(AQ24,AV24,AW24,AX24,BA24,BF24,BG24,BH24)/I24% -> 44.002951 | BM24: =SUM(AT24,BD24)/I24% -> 23.166105 | BN24: =(AS24+BC24)/I24 -> 0.096984612 | BO24: =K24+O24+R24+V24 -> 243270 | BP24: =SUM(AV24,AW24,AX24,BF24,BG24,BH24,BK24) -> 6155 | BQ24: =BP24/(AE24*280) -> 0.91592262
A25: 22 | B25: 22 | D25: ='22'!D3 -> 29 | E25: ='22'!D4 -> 0.76 | G25: ='22'!G8 -> 18059 | H25: ='22'!G8 -> 18059 | I25: ='22'!G7 -> 17828 | J25: 10 | K25: =H25*J25 -> 180590 | L25: =I25/202 -> 88.257426 | M25: ='22'!G15 -> 691 | N25: 35 | O25: =M25*N25 -> 24185 | P25: ='22'!G20 -> 155 | Q25: 134 | R25: =P25*Q25 -> 20770 | S25: =P25/(F25*202/100) -> #DIV/0! | T25: ='22'!G24 -> 0 | U25: 69 | V25: =T25*U25 -> 0 | W25: ='22'!G95 -> 59 | X25: ='22'!G96 -> 19 | Y25: ='22'!G97 -> 19 | Z25: =W25+X25+Y25 -> 97 | AA25: ='22'!G132 -> 0 | AB25: ='22'!G133 -> 0 | AC25: ='22'!G134 -> 0 | AD25: ='22'!G135 -> 24 | AE25: =AA25+AB25+AC25+AD25 -> 24 | AF25: =AV25+AW25+BF25+BG25 -> 3106 | AG25: =AF25/AE25 -> 129.41667 | AH25: ='22'!G136 -> 7.12 | AI25: ='22'!G137 -> -0.01 | AJ25: ='22'!G138 -> 0 | AK25: =AH25+AI25+AJ25 -> 7.11 | AL25: ='22'!G139 -> 0 | AM25: ='22'!G140 -> 7.28 | AO25: =AL25+AM25 -> 7.28 | AP25: ='22'!G123 -> 218 | AQ25: ='22'!G35 -> 0 | AR25: ='22'!G37 -> 0 | AS25: ='22'!G38 -> 0 | AT25: ='22'!G39 -> 0 | AU25: ='22'!G40 -> 0 | AV25: ='22'!G41 -> 0 | AW25: ='22'!G42 -> 0 | AX25: ='22'!G43 -> 2054 | AY25: ='22'!G44 -> 0 | AZ25: ='22'!G36 -> 725 | BA25: ='22'!G49 -> 2635 | BB25: ='22'!G51 -> 1431 | BC25: ='22'!G52 -> 1810 | BD25: ='22'!G53 -> 4199 | BE25: ='22'!G54 -> 96 | BF25: ='22'!G55 -> 0 | BG25: ='22'!G56 -> 3106 | BH25: ='22'!G57 -> 0 | BI25: ='22'!G50 -> 1096 | BJ25: =SUM(AV25,AW25,BF25,BG25) -> 3106 | BK25: ='22'!G84 -> 510 | BL25: =SUM(AQ25,AV25,AW25,AX25,BA25,BF25,BG25,BH25)/I25% -> 43.723357 | BM25: =SUM(AT25,BD25)/I25% -> 23.552838 | BN25: =(AS25+BC25)/I25 -> 0.10152569 | BO25: =K25+O25+R25+V25 -> 225545 | BP25: =SUM(AV25,AW25,AX25,BF25,BG25,BH25,BK25) -> 5670 | BQ25: =BP25/(AE25*280) -> 0.84375
A26: 23 | B26: 23 | D26: ='23'!D3 -> 29 | E26: ='23'!D4 -> 0.76 | G26: ='23'!G8 -> 18888 | H26: ='23'!G8 -> 18888 | I26: ='23'!G7 -> 18710 | J26: 10 | K26: =H26*J26 -> 188880 | L26: =I26/202 -> 92.623762 | M26: ='23'!G15 -> 725 | N26: 35 | O26: =M26*N26 -> 25375 | P26: ='23'!G20 -> 169 | Q26: 134 | R26: =P26*Q26 -> 22646 | S26: =P26/(F26*202/100) -> #DIV/0! | T26: ='23'!G24 -> 0 | U26: 69 | V26: =T26*U26 -> 0 | W26: ='23'!G95 -> 62 | X26: ='23'!G96 -> 21 | Y26: ='23'!G97 -> 17 | Z26: =W26+X26+Y26 -> 100 | AA26: ='23'!G132 -> 0 | AB26: ='23'!G133 -> 0 | AC26: ='23'!G134 -> 0 | AD26: ='23'!G135 -> 24 | AE26: =AA26+AB26+AC26+AD26 -> 24 | AF26: =AV26+AW26+BF26+BG26 -> 3549 | AG26: =AF26/AE26 -> 147.875 | AH26: ='23'!G136 -> 0 | AI26: ='23'!G137 -> 8.09 | AJ26: ='23'!G138 -> 0 | AK26: =AH26+AI26+AJ26 -> 8.09 | AL26: ='23'!G139 -> 0 | AM26: ='23'!G140 -> 6.5 | AO26: =AL26+AM26 -> 6.5 | AP26: ='23'!G123 -> 195 | AQ26: ='23'!G35 -> 0 | AR26: ='23'!G37 -> 0 | AS26: ='23'!G38 -> 0 | AT26: ='23'!G39 -> 0 | AU26: ='23'!G40 -> 0 | AV26: ='23'!G41 -> 0 | AW26: ='23'!G42 -> 0 | AX26: ='23'!G43 -> 2047 | AY26: ='23'!G44 -> 0 | AZ26: ='23'!G36 -> 768 | BA26: ='23'!G49 -> 2777 | BB26: ='23'!G51 -> 1468 | BC26: ='23'!G52 -> 1979 | BD26: ='23'!G53 -> 4188 | BE26: ='23'!G54 -> 57 | BF26: ='23'!G55 -> 0 | BG26: ='23'!G56 -> 3549 | BH26: ='23'!G57 -> 0 | BI26: ='23'!G50 -> 1169 | BJ26: =SUM(AV26,AW26,BF26,BG26) -> 3549 | BK26: ='23'!G84 -> 464 | BL26: =SUM(AQ26,AV26,AW26,AX26,BA26,BF26,BG26,BH26)/I26% -> 44.75147 | BM26: =SUM(AT26,BD26)/I26% -> 22.383752 | BN26: =(AS26+BC26)/I26 -> 0.10577231 | BO26: =K26+O26+R26+V26 -> 236901 | BP26: =SUM(AV26,AW26,AX26,BF26,BG26,BH26,BK26) -> 6060 | BQ26: =BP26/(AE26*280) -> 0.90178571
A27: 24 | B27: 24 | D27: ='24'!D3 -> 30 | E27: ='24'!D4 -> 0.76 | G27: ='24'!G8 -> 19227 | H27: ='24'!G8 -> 19227 | I27: ='24'!G7 -> 19068 | J27: 10 | K27: =H27*J27 -> 192270 | L27: =I27/202 -> 94.39604 | M27: ='24'!G15 -> 719 | N27: 35 | O27: =M27*N27 -> 25165 | P27: ='24'!G20 -> 214 | Q27: 134 | R27: =P27*Q27 -> 28676 | S27: =P27/(F27*202/100) -> #DIV/0! | T27: ='24'!G24 -> 0 | U27: 69 | V27: =T27*U27 -> 0 | W27: ='24'!G95 -> 64 | X27: ='24'!G96 -> 26 | Y27: ='24'!G97 -> 20 | Z27: =W27+X27+Y27 -> 110 | AA27: ='24'!G132 -> 0 | AB27: ='24'!G133 -> 0 | AC27: ='24'!G134 -> 0 | AD27: ='24'!G135 -> 24 | AE27: =AA27+AB27+AC27+AD27 -> 24 | AF27: =AV27+AW27+BF27+BG27 -> 3839 | AG27: =AF27/AE27 -> 159.95833 | AH27: ='24'!G136 -> 3.05 | AI27: ='24'!G137 -> 1 | AJ27: ='24'!G138 -> 3.15 | AK27: =AH27+AI27+AJ27 -> 7.2 | AL27: ='24'!G139 -> 0 | AM27: ='24'!G140 -> 7.15 | AO27: =AL27+AM27 -> 7.15 | AP27: ='24'!G123 -> 215 | AQ27: ='24'!G35 -> 0 | AR27: ='24'!G37 -> 0 | AS27: ='24'!G38 -> 0 | AT27: ='24'!G39 -> 0 | AU27: ='24'!G40 -> 0 | AV27: ='24'!G41 -> 0 | AW27: ='24'!G42 -> 0 | AX27: ='24'!G43 -> 2059 | AY27: ='24'!G44 -> 0 | AZ27: ='24'!G36 -> 730 | BA27: ='24'!G49 -> 3000 | BB27: ='24'!G51 -> 1465 | BC27: ='24'!G52 -> 1948 | BD27: ='24'!G53 -> 4231 | BE27: ='24'!G54 -> 68 | BF27: ='24'!G55 -> 0 | BG27: ='24'!G56 -> 3839 | BH27: ='24'!G57 -> 0 | BI27: ='24'!G50 -> 1120 | BJ27: =SUM(AV27,AW27,BF27,BG27) -> 3839 | BK27: ='24'!G84 -> 477 | BL27: =SUM(AQ27,AV27,AW27,AX27,BA27,BF27,BG27,BH27)/I27% -> 46.664569 | BM27: =SUM(AT27,BD27)/I27% -> 22.189008 | BN27: =(AS27+BC27)/I27 -> 0.10216069 | BO27: =K27+O27+R27+V27 -> 246111 | BP27: =SUM(AV27,AW27,AX27,BF27,BG27,BH27,BK27) -> 6375 | BQ27: =BP27/(AE27*280) -> 0.94866071
A28: 25 | B28: 25 | D28: ='25'!D3 -> 31 | E28: ='25'!D4 -> 0.8 | G28: ='25'!G8 -> 20290 | H28: ='25'!G8 -> 20290 | I28: ='25'!G7 -> 20166 | J28: 10 | K28: =H28*J28 -> 202900 | L28: =I28/202 -> 99.831683 | M28: ='25'!G15 -> 712.52 | N28: 35 | O28: =M28*N28 -> 24938.2 | P28: ='25'!G20 -> 174 | Q28: 134 | R28: =P28*Q28 -> 23316 | S28: =P28/(F28*202/100) -> #DIV/0! | T28: ='25'!G24 -> 0 | U28: 69 | V28: =T28*U28 -> 0 | W28: ='25'!G95 -> 75 | X28: ='25'!G96 -> 31 | Y28: ='25'!G97 -> 30 | Z28: =W28+X28+Y28 -> 136 | AA28: ='25'!G132 -> 0 | AB28: ='25'!G133 -> 0 | AC28: ='25'!G134 -> 0 | AD28: ='25'!G135 -> 23.58 | AE28: =AA28+AB28+AC28+AD28 -> 23.58 | AF28: =AV28+AW28+BF28+BG28 -> 4515.35 | AG28: =AF28/AE28 -> 191.49067 | AH28: ='24'!G136 -> 3.05 | AI28: ='24'!G137 -> 1 | AJ28: ='24'!G138 -> 3.15 | AK28: =AH28+AI28+AJ28 -> 7.2 | AL28: ='23'!G139 -> 0 | AM28: ='24'!G140 -> 7.15 | AO28: =AL28+AM28 -> 7.15 | AP28: ='25'!G123 -> 243.08 | AQ28: ='25'!G35 -> 0 | AR28: ='25'!G37 -> 0 | AS28: ='25'!G38 -> 0 | AT28: ='25'!G39 -> 0 | AU28: ='25'!G40 -> 0 | AV28: ='25'!G41 -> 0 | AX28: ='25'!G43 -> 1994.67 | AY28: ='25'!G44 -> 0 | AZ28: ='25'!G36 -> 963.05 | BA28: ='25'!G49 -> 3116.04 | BB28: ='25'!G51 -> 1481.55 | BC28: ='25'!G52 -> 2098.43 | BD28: ='25'!G53 -> 4052.44 | BE28: ='24'!G54 -> 68 | BF28: ='25'!G55 -> 0 | BG28: ='25'!G56 -> 4515.35 | BH28: ='25'!G57 -> 0 | BI28: ='25'!G50 -> 1112.51 | BJ28: =SUM(AV28,AW28,BF28,BG28) -> 4515.35 | BK28: ='25'!G84 -> 454 | BL28: =SUM(AQ28,AV28,AW28,AX28,BA28,BF28,BG28,BH28)/I28% -> 47.734107 | BM28: =SUM(AT28,BD28)/I28% -> 20.095408 | BN28: =(AS28+BC28)/I28 -> 0.10405782 | BO28: =K28+O28+R28+V28 -> 251154.2 | BP28: =SUM(AV28,AW28,AX28,BF28,BG28,BH28,BK28) -> 6964.02 | BQ28: =BP28/(AE28*280) -> 1.054771
A29: 26 | B29: 26 | D29: ='26'!D3 -> 28 | E29: ='26'!D4 -> 0.85 | G29: ='26'!G8 -> 21716 | H29: ='26'!G8 -> 21716 | I29: ='26'!G7 -> 21593 | J29: 10 | K29: =H29*J29 -> 217160 | L29: =I29/202 -> 106.89604 | M29: ='26'!G15 -> 822.59 | N29: 35 | O29: =M29*N29 -> 28790.65 | P29: ='26'!G20 -> 275 | Q29: 134 | R29: =P29*Q29 -> 36850 | S29: =P29/(F29*202/100) -> #DIV/0! | T29: ='26'!G24 -> 0 | U29: 69 | V29: =T29*U29 -> 0 | W29: ='26'!G95 -> 93 | X29: ='26'!G96 -> 36 | Y29: ='26'!G97 -> 45 | Z29: =W29+X29+Y29 -> 174 | AA29: ='26'!G132 -> 0 | AB29: ='26'!G133 -> 0 | AC29: ='26'!G134 -> 0 | AD29: ='26'!G135 -> 24.49 | AE29: =AA29+AB29+AC29+AD29 -> 24.49 | AF29: =AV29+AW29+BF29+BG29 -> 4787.2 | AG29: =AF29/AE29 -> 195.4757 | AH29: ='26'!G136 -> 8.06 | AI29: ='26'!G137 -> 0 | AJ29: ='26'!G138 -> 0 | AK29: =AH29+AI29+AJ29 -> 8.06 | AL29: ='26'!G139 -> 0 | AM29: ='26'!G140 -> 7.47 | AO29: =AL29+AM29 -> 7.47 | AP29: ='26'!G123 -> 225.62 | AQ29: ='26'!G35 -> 0 | AR29: ='26'!G37 -> 0 | AS29: ='26'!G38 -> -0.38 | AT29: ='26'!G39 -> 0 | AU29: ='26'!G40 -> 0 | AV29: ='26'!G41 -> 0 | AW29: ='26'!G42 -> 0 | AX29: ='26'!G43 -> 1988.96 | AY29: ='26'!G44 -> 0 | AZ29: ='26'!G36 -> 1127.78 | BA29: ='26'!G49 -> 2995.5 | BB29: ='26'!G51 -> 1514.8 | BC29: ='26'!G52 -> 2310.76 | BD29: ='26'!G53 -> 4399.46 | BE29: ='26'!G54 -> 67.15 | BF29: ='26'!G55 -> 0 | BG29: ='26'!G56 -> 4787.2 | BH29: ='26'!G57 -> 0 | BI29: ='26'!G50 -> 1597.76 | BJ29: =SUM(AV29,AW29,BF29,BG29) -> 4787.2 | BK29: ='26'!G84 -> 515 | BL29: =SUM(AQ29,AV29,AW29,AX29,BA29,BF29,BG29,BH29)/I29% -> 45.253832 | BM29: =SUM(AT29,BD29)/I29% -> 20.374473 | BN29: =(AS29+BC29)/I29 -> 0.10699671 | BO29: =K29+O29+R29+V29 -> 282800.65 | BP29: =SUM(AV29,AW29,AX29,BF29,BG29,BH29,BK29) -> 7291.16 | BQ29: =BP29/(AE29*280) -> 1.0632853
A30: 27 | B30: 27 | D30: ='27'!D3 -> 28 | E30: ='27'!D4 -> 0.82 | G30: ='27'!G8 -> 22239 | H30: ='27'!G8 -> 22239 | I30: ='27'!G7 -> 22134 | J30: 10 | K30: =H30*J30 -> 222390 | L30: =I30/202 -> 109.57426 | M30: ='27'!G15 -> 702.03 | N30: 35 | O30: =M30*N30 -> 24571.05 | P30: ='27'!G20 -> 185 | Q30: 134 | R30: =P30*Q30 -> 24790 | S30: =P30/(F30*202/100) -> #DIV/0! | T30: ='27'!G24 -> 0 | U30: 69 | V30: =T30*U30 -> 0 | W30: ='27'!G95 -> 75 | X30: ='27'!G96 -> 28 | Y30: ='27'!G97 -> 32 | Z30: =W30+X30+Y30 -> 135 | AA30: ='27'!G132 -> 0 | AB30: ='27'!G133 -> 0 | AC30: ='27'!G134 -> 0 | AD30: ='27'!G135 -> 24.08 | AE30: =AA30+AB30+AC30+AD30 -> 24.08 | AF30: =AV30+AW30+BF30+BG30 -> 5269.24 | AG30: =AF30/AE30 -> 218.82226 | AH30: ='27'!G136 -> 0 | AI30: ='27'!G137 -> 6.1 | AJ30: ='27'!G138 -> 0 | AK30: =AH30+AI30+AJ30 -> 6.1 | AL30: ='27'!G139 -> 0 | AM30: ='27'!G140 -> 7.35 | AO30: =AL30+AM30 -> 7.35 | AP30: ='27'!G123 -> 220.97 | AQ30: ='27'!G35 -> 0 | AR30: ='27'!G37 -> 0 | AS30: ='27'!G38 -> 0 | AT30: ='27'!G39 -> 0 | AU30: ='27'!G40 -> 0 | AV30: ='27'!G41 -> 0 | AW30: ='27'!G42 -> 0 | AX30: ='27'!G43 -> 1996.64 | AY30: ='27'!G44 -> 0 | AZ30: ='27'!G36 -> 1091.52 | BA30: ='27'!G49 -> 3200.4 | BB30: ='27'!G51 -> 1517.27 | BC30: ='27'!G52 -> 2251.56 | BD30: ='27'!G53 -> 4508.84 | BE30: ='27'!G54 -> 70.49 | BF30: ='27'!G55 -> 0 | BG30: ='27'!G56 -> 5269.24 | BH30: ='27'!G57 -> 0 | BI30: ='27'!G50 -> 1399.04 | BJ30: =SUM(AV30,AW30,BF30,BG30) -> 5269.24 | BK30: ='27'!G84 -> 464 | BL30: =SUM(AQ30,AV30,AW30,AX30,BA30,BF30,BG30,BH30)/I30% -> 47.285985 | BM30: =SUM(AT30,BD30)/I30% -> 20.370651 | BN30: =(AS30+BC30)/I30 -> 0.10172404 | BO30: =K30+O30+R30+V30 -> 271751.05 | BP30: =SUM(AV30,AW30,AX30,BF30,BG30,BH30,BK30) -> 7729.88 | BQ30: =BP30/(AE30*280) -> 1.1464582
A31: 28 | B31: 28 | D31: ='28'!D3 -> 28 | E31: ='28'!D4 -> 0.82 | G31: ='28'!G8 -> 18910 | H31: ='28'!G8 -> 18910 | I31: ='28'!G7 -> 18760 | J31: 10 | K31: =H31*J31 -> 189100 | L31: =I31/202 -> 92.871287 | M31: ='28'!G15 -> 776.81 | N31: 35 | O31: =M31*N31 -> 27188.35 | P31: ='28'!G20 -> 216 | Q31: 134 | R31: =P31*Q31 -> 28944 | S31: =P31/(F31*202/100) -> #DIV/0! | T31: ='28'!G24 -> 0 | U31: 69 | V31: =T31*U31 -> 0 | W31: ='28'!G95 -> 81 | X31: ='28'!G96 -> 33 | Y31: ='28'!G97 -> 31 | Z31: =W31+X31+Y31 -> 145 | AA31: ='28'!G132 -> 0 | AB31: ='28'!G133 -> 0 | AC31: ='28'!G134 -> 0 | AD31: ='28'!G135 -> 24.03 | AE31: =AA31+AB31+AC31+AD31 -> 24.03 | AF31: =AV31+AW31+BF31+BG31 -> 3442.39 | AG31: =AF31/AE31 -> 143.25385 | AH31: ='28'!G136 -> 0 | AI31: ='28'!G137 -> 8.74 | AJ31: ='28'!G138 -> 0 | AK31: =AH31+AI31+AJ31 -> 8.74 | AL31: ='28'!G139 -> 0.37 | AM31: ='28'!G140 -> 6.9 | AO31: =AL31+AM31 -> 7.27 | AP31: ='28'!G123 -> 210.76 | AQ31: ='28'!G35 -> 0 | AR31: ='28'!G37 -> 0 | AS31: ='28'!G38 -> 0 | AT31: ='28'!G39 -> 0 | AU31: ='28'!G40 -> 0 | AV31: ='28'!G41 -> 0 | AW31: ='28'!G42 -> -0.09 | AX31: ='28'!G43 -> 1982.56 | AY31: ='28'!G44 -> 0 | AZ31: ='28'!G36 -> 701.65 | BA31: ='28'!G49 -> 2902.72 | BB31: ='28'!G51 -> 1436.37 | BC31: ='28'!G52 -> 2101.56 | BD31: ='28'!G53 -> 4191.42 | BE31: ='28'!G54 -> 69.83 | BF31: ='28'!G55 -> 0.27 | BG31: ='28'!G56 -> 3442.21 | BH31: ='28'!G57 -> 0 | BI31: ='28'!G50 -> 1225.69 | BJ31: =SUM(AV31,AW31,BF31,BG31) -> 3442.39 | BK31: ='28'!G84 -> 482 | BL31: =SUM(AQ31,AV31,AW31,AX31,BA31,BF31,BG31,BH31)/I31% -> 44.390565 | BM31: =SUM(AT31,BD31)/I31% -> 22.342324 | BN31: =(AS31+BC31)/I31 -> 0.11202345 | BO31: =K31+O31+R31+V31 -> 245232.35 | BP31: =SUM(AV31,AW31,AX31,BF31,BG31,BH31,BK31) -> 5906.95 | BQ31: =BP31/(AE31*280) -> 0.87791303
A32: 29 | B32: 29 | D32: ='29'!D3 -> 30 | E32: ='29'!D4 -> 0.8 | G32: ='29'!G8 -> 17693 | H32: ='29'!G8 -> 17693 | I32: ='29'!G7 -> 17471 | J32: 10 | K32: =H32*J32 -> 176930 | L32: =I32/202 -> 86.490099 | M32: ='29'!G15 -> 690.05 | N32: 35 | O32: =M32*N32 -> 24151.75 | P32: ='29'!G20 -> 165 | Q32: 134 | R32: =P32*Q32 -> 22110 | S32: =P32/(F32*202/100) -> #DIV/0! | T32: ='29'!G24 -> 0 | U32: 69 | V32: =T32*U32 -> 0 | W32: ='29'!G95 -> 70 | X32: ='29'!G96 -> 15 | Y32: ='29'!G97 -> 6 | Z32: =W32+X32+Y32 -> 91 | AA32: ='29'!G132 -> 0 | AB32: ='29'!G133 -> 0 | AC32: ='29'!G134 -> 0 | AD32: ='29'!G135 -> 24.08 | AE32: =AA32+AB32+AC32+AD32 -> 24.08 | AF32: =AV32+AW32+BF32+BG32 -> 3152.2 | AG32: =AF32/AE32 -> 130.90532 | AH32: ='29'!G136 -> 5.82 | AI32: ='29'!G137 -> 0 | AJ32: ='29'!G138 -> 0 | AK32: =AH32+AI32+AJ32 -> 5.82 | AL32: ='29'!G139 -> 0 | AM32: ='29'!G140 -> 8.2 | AO32: =AL32+AM32 -> 8.2 | AP32: ='29'!G123 -> 248.57 | AQ32: ='29'!G35 -> 0 | AR32: ='29'!G37 -> 0 | AS32: ='29'!G38 -> 0 | AT32: ='29'!G39 -> 0 | AU32: ='29'!G40 -> 0 | AV32: ='29'!G41 -> 0 | AW32: ='29'!G42 -> 0 | AX32: ='29'!G43 -> 1977.12 | AY32: ='29'!G44 -> 0 | AZ32: ='29'!G36 -> 659.81 | BA32: ='29'!G49 -> 2827.32 | BB32: ='29'!G51 -> 1368.01 | BC32: ='29'!G52 -> 1860.56 | BD32: ='29'!G53 -> 3995.21 | BE32: ='29'!G54 -> 68.93 | BF32: ='29'!G55 -> -0.27 | BG32: ='29'!G56 -> 3152.47 | BH32: ='29'!G57 -> 0 | BI32: ='29'!G50 -> 934 | BJ32: =SUM(AV32,AW32,BF32,BG32) -> 3152.2 | BK32: ='29'!G84 -> 481 | BL32: =SUM(AQ32,AV32,AW32,AX32,BA32,BF32,BG32,BH32)/I32% -> 45.541984 | BM32: =SUM(AT32,BD32)/I32% -> 22.867666 | BN32: =(AS32+BC32)/I32 -> 0.10649419 | BO32: =K32+O32+R32+V32 -> 223191.75 | BP32: =SUM(AV32,AW32,AX32,BF32,BG32,BH32,BK32) -> 5610.32 | BQ32: =BP32/(AE32*280) -> 0.8320954
A33: 30 | B33: 30 | D33: ='30'!D33 -> 0 | E33: ='30'!D4 -> 0.8 | G33: ='30'!G8 -> 18092 | H33: ='30'!G8 -> 18092 | I33: ='30'!G7 -> 17884 | J33: 10 | K33: =H33*J33 -> 180920 | L33: =I33/202 -> 88.534653 | M33: ='30'!G15 -> 786 | N33: 35 | O33: =M33*N33 -> 27510 | P33: ='30'!G20 -> 174 | Q33: 134 | R33: =P33*Q33 -> 23316 | S33: =P33/(F33*202/100) -> #DIV/0! | T33: ='30'!G24 -> 0 | U33: 69 | V33: =T33*U33 -> 0 | W33: ='30'!G95 -> 77 | X33: ='30'!G96 -> 13 | Y33: ='30'!G97 -> 10 | Z33: =W33+X33+Y33 -> 100 | AA33: ='30'!G132 -> 0 | AB33: ='30'!G133 -> 0 | AC33: ='30'!G134 -> 0 | AD33: ='30'!G135 -> 24.21 | AE33: =AA33+AB33+AC33+AD33 -> 24.21 | AF33: =AV33+AW33+BF33+BG33 -> 0 | AG33: =AF33/AE33 -> 0 | AH33: ='30'!G136 -> 0 | AI33: ='30'!G137 -> 7.74 | AJ33: ='30'!G138 -> 0 | AK33: =AH33+AI33+AJ33 -> 7.74 | AL33: ='30'!G139 -> 0 | AM33: ='30'!G140 -> 8.72 | AO33: =AL33+AM33 -> 8.72 | AP33: ='30'!G123 -> 264.7 | AQ33: ='30'!G35 -> 0 | AR33: ='30'!G37 -> 0 | AS33: ='30'!G38 -> 0 | AT33: ='30'!G39 -> 0 | AU33: ='30'!G40 -> 0 | AV33: ='30'!G41 -> 0 | AW33: ='30'!G42 -> 0 | AX33: ='30'!G43 -> 1981.76 | AY33: ='30'!G44 -> 0 | AZ33: ='30'!G36 -> 708.68 | BA33: ='30'!BA33 -> 0 | BB33: ='30'!BA4 -> 0 | BC33: ='30'!BA2 -> 0 | BD33: ='30'!BD8 -> 0 | BE33: ='30'!BC7 -> 0 | BF33: ='30'!BD7 -> 0 | BG33: ='30'!G57 -> 0 | BH33: ='30'!H57 -> 0 | BI33: =BF33/202 -> 0 | BJ33: =SUM(AV33,AW33,BF33,BG33) -> 0 | BK33: ='31'!G84 -> -59904 | BL33: =SUM(AQ33,AV33,AW33,AX33,BA33,BF33,BG33,BH33)/I33% -> 11.08119 | BM33: =SUM(AT33,BD33)/I33% -> 0 | BN33: =(AS33+BC33)/I33 -> 0 | BO33: =K33+O33+R33+V33 -> 231746 | BP33: =SUM(AV33,AW33,AX33,BF33,BG33,BH33,BK33) -> -57922.24 | BQ33: =BP33/(AE33*280) -> -8.5446156
A34: 31 | B34: 31 | D34: ='[1]30'!D34 -> 0 | E34: ='[1]31'!D5 -> Unit | F34: ='[1]31'!D3 -> 30 | G34: ='[1]31'!G8 -> 19595 | H34: ='[1]31'!G8 -> 19595 | I34: ='[1]31'!G7 -> 19398 | J34: 10 | K34: =H34*J34 -> 195950 | L34: =I34/202 -> 96.029703 | M34: ='[1]10'!G15 -> 827.65 | N34: 35 | O34: =M34*N34 -> 28967.75 | P34: ='[1]31'!G20 -> 184 | Q34: 134 | R34: =P34*Q34 -> 24656 | S34: =P34/(F34*202/100) -> 3.0363036 | T34: ='[1]31'!G24 -> 0 | U34: 69 | V34: =T34*U34 -> 0 | W34: ='[1]31'!G95 -> 63 | X34: ='[1]31'!G96 -> 15 | Y34: ='[1]31'!G97 -> 22 | Z34: =W34+X34+Y34 -> 100 | AA34: ='[1]31'!G132 -> 0 | AB34: ='[1]31'!G133 -> 0 | AC34: ='[1]31'!G134 -> 0 | AD34: ='[1]31'!G135 -> 23.92 | AE34: =AA34+AB34+AC34+AD34 -> 23.92 | AF34: =AV34+AW34+BF34+BG34 -> 4263.21 | AG34: =AF34/AE34 -> 178.22784 | AH34: ='[1]31'!G136 -> 6.33 | AI34: ='[1]31'!G137 -> 0 | AJ34: ='[1]31'!G138 -> 0 | AK34: =AH34+AI34+AJ34 -> 6.33 | AL34: ='[1]31'!G139 -> 0 | AM34: ='[1]31'!G140 -> 7.92 | AO34: =AL34+AM34 -> 7.92 | AP34: ='[1]31'!G123 -> 241.35 | AQ34: ='[1]31'!G35 -> 0 | AR34: ='[1]31'!G37 -> 0 | AS34: ='[1]31'!G38 -> 0 | AT34: ='[1]31'!G39 -> 0 | AU34: ='[1]31'!G40 -> 0 | AV34: ='[1]31'!G41 -> 0 | AW34: ='[1]31'!G42 -> 0.09 | AX34: ='[1]31'!G43 -> 1972.72 | AY34: ='[1]31'!G44 -> 0 | AZ34: ='[1]31'!G36 -> 668.58 | BA34: ='[1]31'!G49 -> 2791.39 | BB34: ='[1]31'!G51 -> 1472.34 | BC34: ='[1]31'!G52 -> 2047.28 | BD34: ='[1]31'!G53 -> 4400.97 | BE34: ='[1]31'!G54 -> 79.99 | BF34: ='[1]31'!BD7 -> 0 | BG34: ='[1]31'!G56 -> 4263.12 | BH34: ='[1]31'!H57 -> 0 | BI34: ='[1]31'!G50 -> 1070.44 | BJ34: =SUM(AV34,AW34,BF34,BG34) -> 4263.21 | BK34: ='[1]31'!G84 -> 377 | BL34: =SUM(AQ34,AV34,AW34,AX34,BA34,BF34,BG34,BH34)/I34% -> 46.537375 | BM34: =SUM(AT34,BD34)/I34% -> 22.687751 | BN34: =(AS34+BC34)/I34 -> 0.10554078 | BO34: =K34+O34+R34+V34 -> 249573.75 | BP34: =SUM(AV34,AW34,AX34,BF34,BG34,BH34,BK34) -> 6612.93 | BQ34: =BP34/(AE34*280) -> 0.98735816
