Workbook

Sheet Total
A1: Site Name | B1: Day | C1: Month | D1: Year | E1: Total Electricity Kwh | F1: Electricity Tariff ($/Kwh) | G1: LPG (Kg) | H1: LPG $/Kg | I1: Water Utility Supply (m3) m3 | J1: Water Utility Supply (m3) $/m3 | K1: Room Nights | L1: Utilities day cost dh
A2: Serengeti | B2: 1 | C2: 5 | D2: 2021 | E2: ='UTILITY REPORT 1'!F3 -> 2650 | F2: =('UTILITY REPORT 1'!E3*'UTILITY REPORT 1'!D3)/'UTILITY REPORT 1'!F3 -> 0.41193585 | G2: =IF('Utility summery'!M6<0,"0",'Utility summery'!M6) -> 0 | H2: 0 | I2: =IF('UTILITY REPORT 1'!G3<0,"0",'UTILITY REPORT 1'!G3) -> 41 | J2: 0 | K2: ='UTILITY REPORT 1'!C3 -> 0 | L2: =E2*F2+G2*H2+#REF!*#REF!+I2*J2 -> #REF!
A3: Serengeti | B3: =B2+1 -> 2 | C3: 5 | D3: 2021 | E3: ='UTILITY REPORT 1'!F4 -> 2697 | F3: =('UTILITY REPORT 1'!E4*'UTILITY REPORT 1'!D4)/'UTILITY REPORT 1'!F4 -> 0.41311086 | G3: =IF('Utility summery'!M7<0,"0",'Utility summery'!M7) -> 49.632 | H3: 0 | I3: =IF('UTILITY REPORT 1'!G4<0,"0",'UTILITY REPORT 1'!G4) -> 50 | J3: 0 | K3: ='UTILITY REPORT 1'!C4 -> 0 | L3: =E3*F3+G3*H3+#REF!*#REF!+I3*J3 -> #REF!
A4: Serengeti | B4: =B3+1 -> 3 | C4: 5 | D4: 2021 | E4: ='UTILITY REPORT 1'!F5 -> 2639 | F4: =('UTILITY REPORT 1'!E5*'UTILITY REPORT 1'!D5)/'UTILITY REPORT 1'!F5 -> 0.41249337 | G4: =IF('Utility summery'!M8<0,"0",'Utility summery'!M8) -> 42.768 | H4: 0 | I4: =IF('UTILITY REPORT 1'!G5<0,"0",'UTILITY REPORT 1'!G5) -> 50 | J4: 0 | K4: ='UTILITY REPORT 1'!C5 -> 0 | L4: =E4*F4+G4*H4+#REF!*#REF!+I4*J4 -> #REF!
A5: Serengeti | B5: =B4+1 -> 4 | C5: 5 | D5: 2021 | E5: ='UTILITY REPORT 1'!F6 -> 2826 | F5: =('UTILITY REPORT 1'!E6*'UTILITY REPORT 1'!D6)/'UTILITY REPORT 1'!F6 -> 0.41276362 | G5: =IF('Utility summery'!M9<0,"0",'Utility summery'!M9) -> 55.22 | H5: 0 | I5: =IF('UTILITY REPORT 1'!G6<0,"0",'UTILITY REPORT 1'!G6) -> 50 | J5: 0 | K5: ='UTILITY REPORT 1'!C6 -> 0 | L5: =E5*F5+G5*H5+#REF!*#REF!+I5*J5 -> #REF!
A6: Serengeti | B6: =B5+1 -> 5 | C6: 5 | D6: 2021 | E6: ='UTILITY REPORT 1'!F7 -> 2780 | F6: =('UTILITY REPORT 1'!E7*'UTILITY REPORT 1'!D7)/'UTILITY REPORT 1'!F7 -> 0.40473022 | G6: =IF('Utility summery'!M10<0,"0",'Utility summery'!M10) -> 65.296 | H6: 0 | I6: =IF('UTILITY REPORT 1'!G7<0,"0",'UTILITY REPORT 1'!G7) -> 67 | J6: 0 | K6: ='UTILITY REPORT 1'!C7 -> 0 | L6: =E6*F6+G6*H6+#REF!*#REF!+I6*J6 -> #REF!
A7: Serengeti | B7: =B6+1 -> 6 | C7: 5 | D7: 2021 | E7: ='UTILITY REPORT 1'!F8 -> 2900 | F7: =('UTILITY REPORT 1'!E8*'UTILITY REPORT 1'!D8)/'UTILITY REPORT 1'!F8 -> 0.4066931 | G7: =IF('Utility summery'!M11<0,"0",'Utility summery'!M11) -> 64.988 | H7: 0 | I7: =IF('UTILITY REPORT 1'!G8<0,"0",'UTILITY REPORT 1'!G8) -> 70 | J7: 0 | K7: ='UTILITY REPORT 1'!C8 -> 0 | L7: =E7*F7+G7*H7+#REF!*#REF!+I7*J7 -> #REF!
A8: Serengeti | B8: =B7+1 -> 7 | C8: 5 | D8: 2021 | E8: ='UTILITY REPORT 1'!F9 -> 2734 | F8: =('UTILITY REPORT 1'!E9*'UTILITY REPORT 1'!D9)/'UTILITY REPORT 1'!F9 -> 0.41198244 | G8: =IF('Utility summery'!M12<0,"0",'Utility summery'!M12) -> 62.392 | H8: 0 | I8: =IF('UTILITY REPORT 1'!G9<0,"0",'UTILITY REPORT 1'!G9) -> 50 | J8: 0 | K8: ='UTILITY REPORT 1'!C9 -> 0 | L8: =E8*F8+G8*H8+#REF!*#REF!+I8*J8 -> #REF!
A9: Serengeti | B9: =B8+1 -> 8 | C9: 5 | D9: 2021 | E9: ='UTILITY REPORT 1'!F10 -> 2996 | F9: =('UTILITY REPORT 1'!E10*'UTILITY REPORT 1'!D10)/'UTILITY REPORT 1'!F10 -> 0.41156542 | G9: =IF('Utility summery'!M13<0,"0",'Utility summery'!M13) -> 68.904 | H9: 0 | I9: =IF('UTILITY REPORT 1'!G10<0,"0",'UTILITY REPORT 1'!G10) -> 51 | J9: 0 | K9: ='UTILITY REPORT 1'!C10 -> 0 | L9: =E9*F9+G9*H9+#REF!*#REF!+I9*J9 -> #REF!
A10: Serengeti | B10: =B9+1 -> 9 | C10: 5 | D10: 2021 | E10: ='UTILITY REPORT 1'!F11 -> 2627 | F10: =('UTILITY REPORT 1'!E11*'UTILITY REPORT 1'!D11)/'UTILITY REPORT 1'!F11 -> 0.40277503 | G10: =IF('Utility summery'!M14<0,"0",'Utility summery'!M14) -> 66 | H10: 0 | I10: =IF('UTILITY REPORT 1'!G11<0,"0",'UTILITY REPORT 1'!G11) -> 76 | J10: 0 | K10: ='UTILITY REPORT 1'!C11 -> 0 | L10: =E10*F10+G10*H10+#REF!*#REF!+I10*J10 -> #REF!
A11: Serengeti | B11: =B10+1 -> 10 | C11: 5 | D11: 2021 | E11: ='UTILITY REPORT 1'!F12 -> 2619 | F11: =('UTILITY REPORT 1'!E12*'UTILITY REPORT 1'!D12)/'UTILITY REPORT 1'!F12 -> 0.41490645 | G11: =IF('Utility summery'!M15<0,"0",'Utility summery'!M15) -> 79.068 | H11: 0 | I11: =IF('UTILITY REPORT 1'!G12<0,"0",'UTILITY REPORT 1'!G12) -> 20 | J11: 0 | K11: ='UTILITY REPORT 1'!C12 -> 0 | L11: =E11*F11+G11*H11+#REF!*#REF!+I11*J11 -> #REF!
A12: Serengeti | B12: =B11+1 -> 11 | C12: 5 | D12: 2021 | E12: ='UTILITY REPORT 1'!F13 -> 2525 | F12: =('UTILITY REPORT 1'!E13*'UTILITY REPORT 1'!D13)/'UTILITY REPORT 1'!F13 -> 0.41942574 | G12: =IF('Utility summery'!M16<0,"0",'Utility summery'!M16) -> 71.28 | H12: 0 | I12: =IF('UTILITY REPORT 1'!G13<0,"0",'UTILITY REPORT 1'!G13) -> 54 | J12: 0 | K12: ='UTILITY REPORT 1'!C13 -> 0 | L12: =E12*F12+G12*H12+#REF!*#REF!+I12*J12 -> #REF!
A13: Serengeti | B13: =B12+1 -> 12 | C13: 5 | D13: 2021 | E13: ='UTILITY REPORT 1'!F14 -> 2428 | F13: =('UTILITY REPORT 1'!E14*'UTILITY REPORT 1'!D14)/'UTILITY REPORT 1'!F14 -> 0.43087315 | G13: =IF('Utility summery'!M17<0,"0",'Utility summery'!M17) -> 52.36 | H13: 0 | I13: =IF('UTILITY REPORT 1'!G14<0,"0",'UTILITY REPORT 1'!G14) -> 51 | J13: 0 | K13: ='UTILITY REPORT 1'!C14 -> 0 | L13: =E13*F13+G13*H13+#REF!*#REF!+I13*J13 -> #REF!
A14: Serengeti | B14: =B13+1 -> 13 | C14: 5 | D14: 2021 | E14: ='UTILITY REPORT 1'!F15 -> 2512 | F14: =('UTILITY REPORT 1'!E15*'UTILITY REPORT 1'!D15)/'UTILITY REPORT 1'!F15 -> 0.40042197 | G14: =IF('Utility summery'!M18<0,"0",'Utility summery'!M18) -> 51.788 | H14: 0 | I14: =IF('UTILITY REPORT 1'!G15<0,"0",'UTILITY REPORT 1'!G15) -> 54 | J14: 0 | K14: ='UTILITY REPORT 1'!C15 -> 0 | L14: =E14*F14+G14*H14+#REF!*#REF!+I14*J14 -> #REF!
... A30: Serengeti | B30: =B29+1 -> 29 | C30: 5 | D30: 2021 | E30: ='UTILITY REPORT 1'!F31 -> 0 | F30: =('UTILITY REPORT 1'!E31*'UTILITY REPORT 1'!D31)/'UTILITY REPORT 1'!F31 -> #DIV/0! | G30: =IF('Utility summery'!M34<0,"0",'Utility summery'!M34) -> 0 | H30: 0 | I30: =IF('UTILITY REPORT 1'!G31<0,"0",'UTILITY REPORT 1'!G31) -> 0 | J30: 0 | K30: ='UTILITY REPORT 1'!C31 -> 0 | L30: =E30*F30+G30*H30+#REF!*#REF!+I30*J30 -> #DIV/0!
A31: Serengeti | B31: 30 | C31: 5 | D31: 2021 | E31: ='UTILITY REPORT 1'!F32 -> 0 | F31: =('UTILITY REPORT 1'!E32*'UTILITY REPORT 1'!D32)/'UTILITY REPORT 1'!F32 -> #DIV/0! | G31: =IF('Utility summery'!M35<0,"0",'Utility summery'!M35) -> 0 | H31: 0 | I31: =IF('UTILITY REPORT 1'!G32<0,"0",'UTILITY REPORT 1'!G32) -> 0 | J31: 0 | K31: ='UTILITY REPORT 1'!C32 -> 0 | L31: =E31*F31+G31*H31+#REF!*#REF!+I31*J31 -> #DIV/0!
A32: Serengeti | B32: 31 | C32: 5 | D32: 2021 | E32: ='UTILITY REPORT 1'!F33 -> 0 | F32: =('UTILITY REPORT 1'!E33*'UTILITY REPORT 1'!D33)/'UTILITY REPORT 1'!F33 -> #DIV/0! | G32: =IF('Utility summery'!M36<0,"0",'Utility summery'!M36) -> 0 | H32: 0 | I32: =IF('UTILITY REPORT 1'!G33<0,"0",'UTILITY REPORT 1'!G33) -> 0 | J32: 0 | K32: ='UTILITY REPORT 1'!C33 -> 0

Sheet Submetering
A1: Site Name | B1: Day | C1: Month | D1: Year | E1: Transport Consumption (LT) | F1: Generators Consumption (LT) | G1: Total Electricity Kwh | H1: Kitchen (KWh) | I1: Laundry (KWh) | J1: STP (M3) | K1: RO prodution (M3) | L1: Amani Restaurant (M3) | M1: Kitchen (M3) | N1: Laundry (M3) | O1: Laundry (M3) | P1: Total water Consumption (M3) | Q1: Borehole #1 (M3) | R1: Borehole #2 (M3) | S1: Borehole #3 (M3) | T1: Borehole #4 (M3) | U1: Borehole #5 (M3) | V1: Borehole #6 (M3) | W1: Total Bore holes production (M3) | X1: Room Nights
A2: Serengeti | B2: 1 | C2: 5 | D2: 2021 | E2: ='UTILITY REPORT 1'!I3 -> 88.75 | F2: ='UTILITY REPORT 1'!E3 -> 1091.63 | G2: ='UTILITY REPORT 1'!F3 -> 2650 | H2: =IF('Kit report'!F4<0,"0",'Kit report'!F4) -> 264 | I2: =IF('Kit report'!X4<0,"0",'Kit report'!X4) -> 140 | J2: =IF('Utility summery'!H6<0,"0",'Utility summery'!H6) -> 66 | K2: =IF('UTILITY REPORT 1'!H3<0,"0",'UTILITY REPORT 1'!H3) -> 118 | L2: ='Water-Meter'!K6 -> 4 | M2: ='Water-Meter'!H6 -> 0 | N2: ='Water-Meter'!Q6 -> 3 | O2: =K2*E2+H2*I2+#REF!*#REF!+J2*L2 -> #REF! | P2: ='Water-Meter'!E6 -> 41 | Q2: =IF('Water-Meter'!U6<0,"0",'Water-Meter'!U6) -> 88 | R2: =IF('Water-Meter'!X6<0,"0",'Water-Meter'!X6) -> 0 | S2: =IF('Water-Meter'!AA6<0,"0",'Water-Meter'!AA6) -> 0 | T2: =IF('Water-Meter'!AD6<0,"0",'Water-Meter'!AD6) -> 15 | U2: =IF('Water-Meter'!AG6<0,"0",'Water-Meter'!AG6) -> 0 | V2: =IF('Water-Meter'!AJ6<0,"0",'Water-Meter'!AJ6) -> 27 | W2: ='Water-Meter'!AN6 -> 130 | X2: =Total!K2 -> 0
A3: Serengeti | B3: =B2+1 -> 2 | C3: 5 | D3: 2021 | E3: ='UTILITY REPORT 1'!I4 -> 0 | F3: ='UTILITY REPORT 1'!E4 -> 1114.16 | G3: ='UTILITY REPORT 1'!F4 -> 2697 | H3: =IF('Kit report'!F5<0,"0",'Kit report'!F5) -> 264 | I3: =IF('Kit report'!X5<0,"0",'Kit report'!X5) -> 300 | J3: =IF('Utility summery'!H7<0,"0",'Utility summery'!H7) -> 50 | K3: =IF('UTILITY REPORT 1'!H4<0,"0",'UTILITY REPORT 1'!H4) -> 38 | L3: ='Water-Meter'!K7 -> 1 | M3: ='Water-Meter'!H7 -> 0 | N3: ='Water-Meter'!Q7 -> 4 | O3: =K3*E3+H3*I3+#REF!*#REF!+J3*L3 -> #REF! | P3: ='Water-Meter'!E7 -> 50 | Q3: =IF('Water-Meter'!U7<0,"0",'Water-Meter'!U7) -> 82 | R3: =IF('Water-Meter'!X7<0,"0",'Water-Meter'!X7) -> 0 | S3: =IF('Water-Meter'!AA7<0,"0",'Water-Meter'!AA7) -> 0 | T3: =IF('Water-Meter'!AD7<0,"0",'Water-Meter'!AD7) -> 17 | U3: =IF('Water-Meter'!AG7<0,"0",'Water-Meter'!AG7) -> 0 | V3: =IF('Water-Meter'!AJ7<0,"0",'Water-Meter'!AJ7) -> 27 | W3: ='Water-Meter'!AN7 -> 126 | X3: =Total!K3 -> 0
A4: Serengeti | B4: =B3+1 -> 3 | C4: 5 | D4: 2021 | E4: ='UTILITY REPORT 1'!I5 -> 29.76 | F4: ='UTILITY REPORT 1'!E5 -> 1088.57 | G4: ='UTILITY REPORT 1'!F5 -> 2639 | H4: =IF('Kit report'!F6<0,"0",'Kit report'!F6) -> 288 | I4: =IF('Kit report'!X6<0,"0",'Kit report'!X6) -> 220 | J4: =IF('Utility summery'!H8<0,"0",'Utility summery'!H8) -> 44 | K4: =IF('UTILITY REPORT 1'!H5<0,"0",'UTILITY REPORT 1'!H5) -> 37 | L4: ='Water-Meter'!K8 -> 1 | M4: ='Water-Meter'!H8 -> 0 | N4: ='Water-Meter'!Q8 -> 5 | O4: =K4*E4+H4*I4+#REF!*#REF!+J4*L4 -> #REF! | P4: ='Water-Meter'!E8 -> 50 | Q4: =IF('Water-Meter'!U8<0,"0",'Water-Meter'!U8) -> 82 | R4: =IF('Water-Meter'!X8<0,"0",'Water-Meter'!X8) -> 0 | S4: =IF('Water-Meter'!AA8<0,"0",'Water-Meter'!AA8) -> 0 | T4: =IF('Water-Meter'!AD8<0,"0",'Water-Meter'!AD8) -> 16 | U4: =IF('Water-Meter'!AG8<0,"0",'Water-Meter'!AG8) -> 0 | V4: =IF('Water-Meter'!AJ8<0,"0",'Water-Meter'!AJ8) -> 28 | W4: ='Water-Meter'!AN8 -> 126 | X4: =Total!K4 -> 0
A5: Serengeti | B5: =B4+1 -> 4 | C5: 5 | D5: 2021 | E5: ='UTILITY REPORT 1'!I6 -> 38.13 | F5: ='UTILITY REPORT 1'!E6 -> 1166.47 | G5: ='UTILITY REPORT 1'!F6 -> 2826 | H5: =IF('Kit report'!F7<0,"0",'Kit report'!F7) -> 300 | I5: =IF('Kit report'!X7<0,"0",'Kit report'!X7) -> 320 | J5: =IF('Utility summery'!H9<0,"0",'Utility summery'!H9) -> 56 | K5: =IF('UTILITY REPORT 1'!H6<0,"0",'UTILITY REPORT 1'!H6) -> 32 | L5: ='Water-Meter'!K9 -> 2 | M5: ='Water-Meter'!H9 -> 0 | N5: ='Water-Meter'!Q9 -> 3 | O5: =K5*E5+H5*I5+#REF!*#REF!+J5*L5 -> #REF! | P5: ='Water-Meter'!E9 -> 50 | Q5: =IF('Water-Meter'!U9<0,"0",'Water-Meter'!U9) -> 24 | R5: =IF('Water-Meter'!X9<0,"0",'Water-Meter'!X9) -> 0 | S5: =IF('Water-Meter'!AA9<0,"0",'Water-Meter'!AA9) -> 0 | T5: =IF('Water-Meter'!AD9<0,"0",'Water-Meter'!AD9) -> 16 | U5: =IF('Water-Meter'!AG9<0,"0",'Water-Meter'!AG9) -> 0 | V5: =IF('Water-Meter'!AJ9<0,"0",'Water-Meter'!AJ9) -> 29 | W5: ='Water-Meter'!AN9 -> 69 | X5: =Total!K5 -> 0
A6: Serengeti | B6: =B5+1 -> 5 | C6: 5 | D6: 2021 | E6: ='UTILITY REPORT 1'!I7 -> 0 | F6: ='UTILITY REPORT 1'!E7 -> 1125.15 | G6: ='UTILITY REPORT 1'!F7 -> 2780 | H6: =IF('Kit report'!F8<0,"0",'Kit report'!F8) -> 264 | I6: =IF('Kit report'!X8<0,"0",'Kit report'!X8) -> 260 | J6: =IF('Utility summery'!H10<0,"0",'Utility summery'!H10) -> 50 | K6: =IF('UTILITY REPORT 1'!H7<0,"0",'UTILITY REPORT 1'!H7) -> 38 | L6: ='Water-Meter'!K10 -> 1 | M6: ='Water-Meter'!H10 -> 0 | N6: ='Water-Meter'!Q10 -> 4 | O6: =K6*E6+H6*I6+#REF!*#REF!+J6*L6 -> #REF! | P6: ='Water-Meter'!E10 -> 67 | Q6: =IF('Water-Meter'!U10<0,"0",'Water-Meter'!U10) -> 0 | R6: =IF('Water-Meter'!X10<0,"0",'Water-Meter'!X10) -> 0 | S6: =IF('Water-Meter'!AA10<0,"0",'Water-Meter'!AA10) -> 0 | T6: =IF('Water-Meter'!AD10<0,"0",'Water-Meter'!AD10) -> 16 | U6: =IF('Water-Meter'!AG10<0,"0",'Water-Meter'!AG10) -> 0 | V6: =IF('Water-Meter'!AJ10<0,"0",'Water-Meter'!AJ10) -> 29 | W6: ='Water-Meter'!AN10 -> 45 | X6: =Total!K6 -> 0
A7: Serengeti | B7: =B6+1 -> 6 | C7: 5 | D7: 2021 | E7: ='UTILITY REPORT 1'!I8 -> 500.13 | F7: ='UTILITY REPORT 1'!E8 -> 1179.41 | G7: ='UTILITY REPORT 1'!F8 -> 2900 | H7: =IF('Kit report'!F9<0,"0",'Kit report'!F9) -> 264 | I7: =IF('Kit report'!X9<0,"0",'Kit report'!X9) -> 320 | J7: =IF('Utility summery'!H11<0,"0",'Utility summery'!H11) -> 53 | K7: =IF('UTILITY REPORT 1'!H8<0,"0",'UTILITY REPORT 1'!H8) -> 34 | L7: ='Water-Meter'!K11 -> 1 | M7: ='Water-Meter'!H11 -> 0 | N7: ='Water-Meter'!Q11 -> 7 | O7: =K7*E7+H7*I7+#REF!*#REF!+J7*L7 -> #REF! | P7: ='Water-Meter'!E11 -> 70 | Q7: =IF('Water-Meter'!U11<0,"0",'Water-Meter'!U11) -> 0 | R7: =IF('Water-Meter'!X11<0,"0",'Water-Meter'!X11) -> 0 | S7: =IF('Water-Meter'!AA11<0,"0",'Water-Meter'!AA11) -> 0 | T7: =IF('Water-Meter'!AD11<0,"0",'Water-Meter'!AD11) -> 16 | U7: =IF('Water-Meter'!AG11<0,"0",'Water-Meter'!AG11) -> 0 | V7: =IF('Water-Meter'!AJ11<0,"0",'Water-Meter'!AJ11) -> 28 | W7: ='Water-Meter'!AN11 -> 44 | X7: =Total!K7 -> 0
A8: Serengeti | B8: =B7+1 -> 7 | C8: 5 | D8: 2021 | E8: ='UTILITY REPORT 1'!I9 -> 0 | F8: ='UTILITY REPORT 1'!E9 -> 1126.36 | G8: ='UTILITY REPORT 1'!F9 -> 2734 | H8: =IF('Kit report'!F10<0,"0",'Kit report'!F10) -> 240 | I8: =IF('Kit report'!X10<0,"0",'Kit report'!X10) -> 180 | J8: =IF('Utility summery'!H12<0,"0",'Utility summery'!H12) -> 45 | K8: =IF('UTILITY REPORT 1'!H9<0,"0",'UTILITY REPORT 1'!H9) -> 88 | L8: ='Water-Meter'!K12 -> 2 | M8: ='Water-Meter'!H12 -> 0 | N8: ='Water-Meter'!Q12 -> 3 | O8: =K8*E8+H8*I8+#REF!*#REF!+J8*L8 -> #REF! | P8: ='Water-Meter'!E12 -> 50 | Q8: =IF('Water-Meter'!U12<0,"0",'Water-Meter'!U12) -> 0 | R8: =IF('Water-Meter'!X12<0,"0",'Water-Meter'!X12) -> 0 | S8: =IF('Water-Meter'!AA12<0,"0",'Water-Meter'!AA12) -> 0 | T8: =IF('Water-Meter'!AD12<0,"0",'Water-Meter'!AD12) -> 17 | U8: =IF('Water-Meter'!AG12<0,"0",'Water-Meter'!AG12) -> 0 | V8: =IF('Water-Meter'!AJ12<0,"0",'Water-Meter'!AJ12) -> 29 | W8: ='Water-Meter'!AN12 -> 46 | X8: =Total!K8 -> 0
A9: Serengeti | B9: =B8+1 -> 8 | C9: 5 | D9: 2021 | E9: ='UTILITY REPORT 1'!I10 -> 248 | F9: ='UTILITY REPORT 1'!E10 -> 1233.05 | G9: ='UTILITY REPORT 1'!F10 -> 2996 | H9: =IF('Kit report'!F11<0,"0",'Kit report'!F11) -> 276 | I9: =IF('Kit report'!X11<0,"0",'Kit report'!X11) -> 100 | J9: =IF('Utility summery'!H13<0,"0",'Utility summery'!H13) -> 44 | K9: =IF('UTILITY REPORT 1'!H10<0,"0",'UTILITY REPORT 1'!H10) -> 150 | L9: ='Water-Meter'!K13 -> 2 | M9: ='Water-Meter'!H13 -> 0 | N9: ='Water-Meter'!Q13 -> 2 | O9: =K9*E9+H9*I9+#REF!*#REF!+J9*L9 -> #REF! | P9: ='Water-Meter'!E13 -> 51 | Q9: =IF('Water-Meter'!U13<0,"0",'Water-Meter'!U13) -> 87 | R9: =IF('Water-Meter'!X13<0,"0",'Water-Meter'!X13) -> 0 | S9: =IF('Water-Meter'!AA13<0,"0",'Water-Meter'!AA13) -> 0 | T9: =IF('Water-Meter'!AD13<0,"0",'Water-Meter'!AD13) -> 16 | U9: =IF('Water-Meter'!AG13<0,"0",'Water-Meter'!AG13) -> 0 | V9: =IF('Water-Meter'!AJ13<0,"0",'Water-Meter'!AJ13) -> 28 | W9: ='Water-Meter'!AN13 -> 131 | X9: =Total!K9 -> 0
A10: Serengeti | B10: =B9+1 -> 9 | C10: 5 | D10: 2021 | E10: ='UTILITY REPORT 1'!I11 -> 146.15 | F10: ='UTILITY REPORT 1'!E11 -> 1058.09 | G10: ='UTILITY REPORT 1'!F11 -> 2627 | H10: =IF('Kit report'!F12<0,"0",'Kit report'!F12) -> 204 | I10: =IF('Kit report'!X12<0,"0",'Kit report'!X12) -> 340 | J10: =IF('Utility summery'!H14<0,"0",'Utility summery'!H14) -> 66 | K10: =IF('UTILITY REPORT 1'!H11<0,"0",'UTILITY REPORT 1'!H11) -> 22 | L10: ='Water-Meter'!K14 -> 1 | M10: ='Water-Meter'!H14 -> 0 | N10: ='Water-Meter'!Q14 -> 4 | O10: =K10*E10+H10*I10+#REF!*#REF!+J10*L10 -> #REF! | P10: ='Water-Meter'!E14 -> 76 | Q10: =IF('Water-Meter'!U14<0,"0",'Water-Meter'!U14) -> 81 | R10: =IF('Water-Meter'!X14<0,"0",'Water-Meter'!X14) -> 0 | S10: =IF('Water-Meter'!AA14<0,"0",'Water-Meter'!AA14) -> 0 | T10: =IF('Water-Meter'!AD14<0,"0",'Water-Meter'!AD14) -> 15 | U10: =IF('Water-Meter'!AG14<0,"0",'Water-Meter'!AG14) -> 0 | V10: =IF('Water-Meter'!AJ14<0,"0",'Water-Meter'!AJ14) -> 29 | W10: ='Water-Meter'!AN14 -> 125 | X10: =Total!K10 -> 0
A11: Serengeti | B11: =B10+1 -> 10 | C11: 5 | D11: 2021 | E11: ='UTILITY REPORT 1'!I12 -> 140.33 | F11: ='UTILITY REPORT 1'!E12 -> 1086.64 | G11: ='UTILITY REPORT 1'!F12 -> 2619 | H11: =IF('Kit report'!F13<0,"0",'Kit report'!F13) -> 228 | I11: =IF('Kit report'!X13<0,"0",'Kit report'!X13) -> 260 | J11: =IF('Utility summery'!H15<0,"0",'Utility summery'!H15) -> 53 | K11: =IF('UTILITY REPORT 1'!H12<0,"0",'UTILITY REPORT 1'!H12) -> 33 | L11: ='Water-Meter'!K15 -> 2 | M11: ='Water-Meter'!H15 -> 0 | N11: ='Water-Meter'!Q15 -> 6 | O11: =K11*E11+H11*I11+#REF!*#REF!+J11*L11 -> #REF! | P11: ='Water-Meter'!E15 -> 20 | Q11: =IF('Water-Meter'!U15<0,"0",'Water-Meter'!U15) -> 25 | R11: =IF('Water-Meter'!X15<0,"0",'Water-Meter'!X15) -> 0 | S11: =IF('Water-Meter'!AA15<0,"0",'Water-Meter'!AA15) -> 0 | T11: =IF('Water-Meter'!AD15<0,"0",'Water-Meter'!AD15) -> 17 | U11: =IF('Water-Meter'!AG15<0,"0",'Water-Meter'!AG15) -> 0 | V11: =IF('Water-Meter'!AJ15<0,"0",'Water-Meter'!AJ15) -> 29 | W11: ='Water-Meter'!AN15 -> 71 | X11: =Total!K11 -> 0
A12: Serengeti | B12: =B11+1 -> 11 | C12: 5 | D12: 2021 | E12: ='UTILITY REPORT 1'!I13 -> 647 | F12: ='UTILITY REPORT 1'!E13 -> 1059.05 | G12: ='UTILITY REPORT 1'!F13 -> 2525 | H12: =IF('Kit report'!F14<0,"0",'Kit report'!F14) -> 228 | I12: =IF('Kit report'!X14<0,"0",'Kit report'!X14) -> 200 | J12: =IF('Utility summery'!H16<0,"0",'Utility summery'!H16) -> 51 | K12: =IF('UTILITY REPORT 1'!H13<0,"0",'UTILITY REPORT 1'!H13) -> 33 | L12: ='Water-Meter'!K16 -> 1 | M12: ='Water-Meter'!H16 -> 0 | N12: ='Water-Meter'!Q16 -> 2 | O12: =K12*E12+H12*I12+#REF!*#REF!+J12*L12 -> #REF! | P12: ='Water-Meter'!E16 -> 54 | Q12: =IF('Water-Meter'!U16<0,"0",'Water-Meter'!U16) -> 0 | R12: =IF('Water-Meter'!X16<0,"0",'Water-Meter'!X16) -> 0 | S12: =IF('Water-Meter'!AA16<0,"0",'Water-Meter'!AA16) -> 89 | T12: =IF('Water-Meter'!AD16<0,"0",'Water-Meter'!AD16) -> 16 | U12: =IF('Water-Meter'!AG16<0,"0",'Water-Meter'!AG16) -> 0 | V12: =IF('Water-Meter'!AJ16<0,"0",'Water-Meter'!AJ16) -> 28 | W12: ='Water-Meter'!AN16 -> 133 | X12: =Total!K12 -> 0
A13: Serengeti | B13: =B12+1 -> 12 | C13: 5 | D13: 2021 | E13: ='UTILITY REPORT 1'!I14 -> 0 | F13: ='UTILITY REPORT 1'!E14 -> 1046.16 | G13: ='UTILITY REPORT 1'!F14 -> 2428 | H13: =IF('Kit report'!F15<0,"0",'Kit report'!F15) -> 228 | I13: =IF('Kit report'!X15<0,"0",'Kit report'!X15) -> 160 | J13: =IF('Utility summery'!H17<0,"0",'Utility summery'!H17) -> 48 | K13: =IF('UTILITY REPORT 1'!H14<0,"0",'UTILITY REPORT 1'!H14) -> 31 | L13: ='Water-Meter'!K17 -> 1 | M13: ='Water-Meter'!H17 -> 0 | N13: ='Water-Meter'!Q17 -> 2 | O13: =K13*E13+H13*I13+#REF!*#REF!+J13*L13 -> #REF! | P13: ='Water-Meter'!E17 -> 51 | Q13: =IF('Water-Meter'!U17<0,"0",'Water-Meter'!U17) -> 0 | R13: =IF('Water-Meter'!X17<0,"0",'Water-Meter'!X17) -> 0 | S13: =IF('Water-Meter'!AA17<0,"0",'Water-Meter'!AA17) -> 0 | T13: =IF('Water-Meter'!AD17<0,"0",'Water-Meter'!AD17) -> 17 | U13: =IF('Water-Meter'!AG17<0,"0",'Water-Meter'!AG17) -> 0 | V13: =IF('Water-Meter'!AJ17<0,"0",'Water-Meter'!AJ17) -> 29 | W13: ='Water-Meter'!AN17 -> 46 | X13: =Total!K13 -> 0
A14: Serengeti | B14: =B13+1 -> 13 | C14: 5 | D14: 2021 | E14: ='UTILITY REPORT 1'!I15 -> 249.48 | F14: ='UTILITY REPORT 1'!E15 -> 1005.86 | G14: ='UTILITY REPORT 1'!F15 -> 2512 | H14: =IF('Kit report'!F16<0,"0",'Kit report'!F16) -> 228 | I14: =IF('Kit report'!X16<0,"0",'Kit report'!X16) -> 200 | J14: =IF('Utility summery'!H18<0,"0",'Utility summery'!H18) -> 56 | K14: =IF('UTILITY REPORT 1'!H15<0,"0",'UTILITY REPORT 1'!H15) -> 85 | L14: ='Water-Meter'!K18 -> 2 | M14: ='Water-Meter'!H18 -> 0 | N14: ='Water-Meter'!Q18 -> 8 | O14: =K14*E14+H14*I14+#REF!*#REF!+J14*L14 -> #REF! | P14: ='Water-Meter'!E18 -> 54 | Q14: =IF('Water-Meter'!U18<0,"0",'Water-Meter'!U18) -> 0 | R14: =IF('Water-Meter'!X18<0,"0",'Water-Meter'!X18) -> 0 | S14: =IF('Water-Meter'!AA18<0,"0",'Water-Meter'!AA18) -> 0 | T14: =IF('Water-Meter'!AD18<0,"0",'Water-Meter'!AD18) -> 16 | U14: =IF('Water-Meter'!AG18<0,"0",'Water-Meter'!AG18) -> 0 | V14: =IF('Water-Meter'!AJ18<0,"0",'Water-Meter'!AJ18) -> 31 | W14: ='Water-Meter'!AN18 -> 47 | X14: =Total!K14 -> 0
... A30: Serengeti | B30: =B29+1 -> 29 | C30: 5 | D30: 2021 | E30: ='UTILITY REPORT 1'!I31 -> 0 | F30: ='UTILITY REPORT 1'!E31 -> 0 | G30: ='UTILITY REPORT 1'!F31 -> 0 | H30: =IF('Kit report'!F32<0,"0",'Kit report'!F32) -> 0 | I30: =IF('Kit report'!X32<0,"0",'Kit report'!X32) -> 0 | J30: =IF('Utility summery'!H34<0,"0",'Utility summery'!H34) -> 0 | K30: =IF('UTILITY REPORT 1'!H31<0,"0",'UTILITY REPORT 1'!H31) -> 0 | L30: ='Water-Meter'!K34 -> 0 | M30: ='Water-Meter'!H34 -> 0 | N30: ='Water-Meter'!Q34 -> 0 | O30: =K30*E30+H30*I30+#REF!*#REF!+J30*L30 -> #REF! | P30: ='Water-Meter'!E34 -> 0 | Q30: =IF('Water-Meter'!U34<0,"0",'Water-Meter'!U34) -> 0 | R30: =IF('Water-Meter'!X34<0,"0",'Water-Meter'!X34) -> 0 | S30: =IF('Water-Meter'!AA34<0,"0",'Water-Meter'!AA34) -> 0 | T30: =IF('Water-Meter'!AD34<0,"0",'Water-Meter'!AD34) -> 0 | U30: =IF('Water-Meter'!AG34<0,"0",'Water-Meter'!AG34) -> 0 | V30: =IF('Water-Meter'!AJ34<0,"0",'Water-Meter'!AJ34) -> 0 | W30: ='Water-Meter'!AN34 -> 0 | X30: =Total!K30 -> 0
A31: Serengeti | B31: 30 | C31: 5 | D31: 2021 | E31: ='UTILITY REPORT 1'!I32 -> 0 | F31: ='UTILITY REPORT 1'!E32 -> 0 | G31: ='UTILITY REPORT 1'!F32 -> 0 | H31: =IF('Kit report'!F33<0,"0",'Kit report'!F33) -> 0 | I31: =IF('Kit report'!X33<0,"0",'Kit report'!X33) -> 0 | J31: =IF('Utility summery'!H35<0,"0",'Utility summery'!H35) -> 0 | K31: =IF('UTILITY REPORT 1'!H32<0,"0",'UTILITY REPORT 1'!H32) -> 0 | L31: ='Water-Meter'!K35 -> 0 | M31: ='Water-Meter'!H35 -> 0 | N31: ='Water-Meter'!Q35 -> 0 | O31: =K31*E31+H31*I31+#REF!*#REF!+J31*L31 -> #REF! | P31: ='Water-Meter'!E35 -> 0 | Q31: =IF('Water-Meter'!U35<0,"0",'Water-Meter'!U35) -> 0 | R31: =IF('Water-Meter'!X35<0,"0",'Water-Meter'!X35) -> 0 | S31: =IF('Water-Meter'!AA35<0,"0",'Water-Meter'!AA35) -> 0 | T31: =IF('Water-Meter'!AD35<0,"0",'Water-Meter'!AD35) -> 0 | U31: =IF('Water-Meter'!AG35<0,"0",'Water-Meter'!AG35) -> 0 | V31: =IF('Water-Meter'!AJ35<0,"0",'Water-Meter'!AJ35) -> 0 | W31: ='Water-Meter'!AN35 -> 0 | X31: =Total!K31 -> 0
A32: Serengeti | B32: 31 | C32: 5 | D32: 2021 | E32: ='UTILITY REPORT 1'!I33 -> 0 | F32: ='UTILITY REPORT 1'!E33 -> 0 | G32: ='UTILITY REPORT 1'!F33 -> 0 | H32: =IF('Kit report'!F34<0,"0",'Kit report'!F34) -> 0 | I32: =IF('Kit report'!X34<0,"0",'Kit report'!X34) -> 0 | J32: =IF('Utility summery'!H36<0,"0",'Utility summery'!H36) -> 0 | K32: =IF('UTILITY REPORT 1'!H33<0,"0",'UTILITY REPORT 1'!H33) -> 0 | L32: ='Water-Meter'!K36 -> 0 | M32: ='Water-Meter'!H36 -> 0 | N32: ='Water-Meter'!Q36 -> 0 | P32: ='Water-Meter'!E36 -> 0 | Q32: =IF('Water-Meter'!U36<0,"0",'Water-Meter'!U36) -> 0 | R32: =IF('Water-Meter'!X36<0,"0",'Water-Meter'!X36) -> 0 | S32: =IF('Water-Meter'!AA36<0,"0",'Water-Meter'!AA36) -> 0 | T32: =IF('Water-Meter'!AD36<0,"0",'Water-Meter'!AD36) -> 0 | U32: =IF('Water-Meter'!AG36<0,"0",'Water-Meter'!AG36) -> 0 | V32: =IF('Water-Meter'!AJ36<0,"0",'Water-Meter'!AJ36) -> 0 | W32: ='Water-Meter'!AN36 -> 0 | X32: =Total!K32 -> 0

Sheet UTILITY REPORT 1
A1: UTILITY REPORT
A2: Date | B2: % | C2: Guest Rooms Occupied | D2: Diesel cost Per Liter ($) | E2: Diesel consumption (LT) | F2: Power production (KW) | G2: Water consumption (M3) | H2: RO prodution (M3) | I2: Transport Consupmtion (LT)
A3: =Gen!A11 -> 44317 | B3: =Gen!B11 -> 0.01 | C3: ='Summery Report'!E5 -> 0 | D3: 1 | E3: =Gen!S11 -> 1091.63 | F3: =Gen!T11 -> 2650 | G3: ='Water-Meter'!E6 -> 41 | H3: ='Utility report '!AC6 -> 118 | I3: =Gen!AJ11 -> 88.75
A4: =Gen!A12 -> 44318 | B4: =Gen!B12 -> 0 | C4: ='Summery Report'!E6 -> 0 | D4: 1 | E4: =Gen!S12 -> 1114.16 | F4: =Gen!T12 -> 2697 | G4: ='Water-Meter'!E7 -> 50 | H4: ='Utility report '!AC7 -> 38 | I4: =Gen!AJ12 -> 0
A5: =Gen!A13 -> 44319 | B5: =Gen!B13 -> 0.039 | C5: ='Summery Report'!E7 -> 0 | D5: 1 | E5: =Gen!S13 -> 1088.57 | F5: =Gen!T13 -> 2639 | G5: ='Water-Meter'!E8 -> 50 | H5: ='Utility report '!AC8 -> 37 | I5: =Gen!AJ13 -> 29.76
A6: =Gen!A14 -> 44320 | B6: =Gen!B14 -> 0.052 | C6: ='Summery Report'!E8 -> 0 | D6: 1 | E6: =Gen!S14 -> 1166.47 | F6: =Gen!T14 -> 2826 | G6: ='Water-Meter'!E9 -> 50 | H6: ='Utility report '!AC9 -> 32 | I6: =Gen!AJ14 -> 38.13
A7: =Gen!A15 -> 44321 | B7: =Gen!B15 -> 0.056 | C7: ='Summery Report'!E9 -> 0 | D7: 1 | E7: =Gen!S15 -> 1125.15 | F7: =Gen!T15 -> 2780 | G7: ='Water-Meter'!E10 -> 67 | H7: ='Utility report '!AC10 -> 38 | I7: =Gen!AJ15 -> 0
A8: =Gen!A16 -> 44322 | B8: =Gen!B16 -> 0.056 | C8: ='Summery Report'!E10 -> 0 | D8: 1 | E8: =Gen!S16 -> 1179.41 | F8: =Gen!T16 -> 2900 | G8: ='Water-Meter'!E11 -> 70 | H8: ='Utility report '!AC11 -> 34 | I8: =Gen!AJ16 -> 500.13
A9: =Gen!A17 -> 44323 | B9: =Gen!B17 -> 0 | C9: ='Summery Report'!E11 -> 0 | D9: 1 | E9: =Gen!S17 -> 1126.36 | F9: =Gen!T17 -> 2734 | G9: ='Water-Meter'!E12 -> 50 | H9: ='Utility report '!AC12 -> 88 | I9: =Gen!AJ17 -> 0
A10: =Gen!A18 -> 44324 | B10: =Gen!B18 -> 0 | C10: ='Summery Report'!E12 -> 0 | D10: 1 | E10: =Gen!S18 -> 1233.05 | F10: =Gen!T18 -> 2996 | G10: ='Water-Meter'!E13 -> 51 | H10: ='Utility report '!AC13 -> 150 | I10: =Gen!AJ18 -> 248
A11: =Gen!A19 -> 44325 | B11: =Gen!B19 -> 0 | C11: ='Summery Report'!E13 -> 0 | D11: 1 | E11: =Gen!S19 -> 1058.09 | F11: =Gen!T19 -> 2627 | G11: ='Water-Meter'!E14 -> 76 | H11: ='Utility report '!AC14 -> 22 | I11: =Gen!AJ19 -> 146.15
A12: =Gen!A20 -> 44326 | B12: =Gen!B20 -> 0 | C12: ='Summery Report'!E14 -> 0 | D12: 1 | E12: =Gen!S20 -> 1086.64 | F12: =Gen!T20 -> 2619 | G12: ='Water-Meter'!E15 -> 20 | H12: ='Utility report '!AC15 -> 33 | I12: =Gen!AJ20 -> 140.33
A13: =Gen!A21 -> 44327 | B13: =Gen!B21 -> 0 | C13: ='Summery Report'!E15 -> 0 | D13: 1 | E13: =Gen!S21 -> 1059.05 | F13: =Gen!T21 -> 2525 | G13: ='Water-Meter'!E16 -> 54 | H13: ='Utility report '!AC16 -> 33 | I13: =Gen!AJ21 -> 647
A14: =Gen!A22 -> 44328 | B14: =Gen!B22 -> 0 | C14: ='Summery Report'!E16 -> 0 | D14: 1 | E14: =Gen!S22 -> 1046.16 | F14: =Gen!T22 -> 2428 | G14: ='Water-Meter'!E17 -> 51 | H14: ='Utility report '!AC17 -> 31 | I14: =Gen!AJ22 -> 0
... A33: =Gen!A41 -> 44347 | B33: =Gen!B41 -> 0 | C33: ='Summery Report'!E35 -> 0 | D33: 1 | E33: =Gen!S41 -> 0 | F33: =Gen!T41 -> 0 | G33: ='Water-Meter'!E36 -> 0 | H33: ='Utility report '!AC36 -> 0 | I33: =Gen!AJ41 -> 0
B34: =Gen!B42 -> 0 | C34: ='Summery Report'!E36 -> 0 | D34: 2 | E34: =Gen!S42 -> 0 | F34: =Gen!T42 -> 0 | G34: ='Water-Meter'!E37 -> 0 | H34: ='Utility report '!AC37 -> 0 | I34: =Gen!AK42 -> 0

Sheet Utility summery
A4: Date | B4: Room Occupied | C4: Electricity Units Generated KW | D4: Diseal | G4: Water | J4: Gas | N4: Cost of utilites
D5: Generator | E5: Transport | F5: Total | G5: RO | H5: STP | I5: Total Consumption | J5: 2 ton | K5: 1 Ton | L5: 1 Ton | M5: Total consumption | N5: Electricity /1.4$/liter | O5: Diseal for Transport | P5: Gas /2.38$/Kg | Q5: Total HLP Cost | R5: Electricity Cost/Room $ | S5: cost/Room $
A6: =Gen!A11 -> 44317 | B6: ='Summery Report'!E5 -> 0 | C6: =Gen!U11 -> 0.41193585 | D6: =Gen!T11 -> 2650 | E6: =Gen!AK11 -> 0 | F6: =Gen!AS11 -> 0 | G6: ='Utility report '!AC6 -> 118 | H6: ='Utility report '!AE6 -> 66 | I6: ='Water-Meter'!E6 -> 41 | J6: ='Lpg (2)'!B10 -> 85 | K6: ='Lpg (2)'!C10 -> 85 | L6: ='Lpg (2)'!D10 -> 1 | M6: ='Lpg (2)'!G10 -> 0 | O6: =E6 -> 0 | P6: ='[1]Lpg (2)'!#REF! -> #REF! | Q6: ='[1]Summery Report'!#REF! -> #REF! | R6: =N6/B6 -> #DIV/0! | S6: =Q6/B6 -> #REF!
A7: =Gen!A12 -> 44318 | B7: ='Summery Report'!E6 -> 0 | C7: =Gen!U12 -> 0.41311086 | D7: =Gen!T12 -> 2697 | E7: =Gen!AK12 -> 0 | F7: =Gen!AS12 -> 0 | G7: ='Utility report '!AC7 -> 38 | H7: ='Utility report '!AE7 -> 50 | I7: ='Water-Meter'!E7 -> 50 | J7: ='Lpg (2)'!B11 -> 85 | K7: ='Lpg (2)'!C11 -> 85 | L7: ='Lpg (2)'!D11 -> 1 | M7: ='Lpg (2)'!G11 -> 49.632 | N7: =D7*1.4 -> 3775.8 | O7: =E7*1.4 -> 0 | P7: ='[1]Lpg (2)'!#REF! -> #REF! | Q7: ='[1]Summery Report'!#REF! -> #REF! | R7: =N7/B7 -> #DIV/0! | S7: =Q7/B7 -> #REF!
A8: =Gen!A13 -> 44319 | B8: ='Summery Report'!E7 -> 0 | C8: =Gen!U13 -> 0.41249337 | D8: =Gen!T13 -> 2639 | E8: =Gen!AK13 -> 0 | F8: =Gen!AS13 -> 0 | G8: ='Utility report '!AC8 -> 37 | H8: ='Utility report '!AE8 -> 44 | I8: ='Water-Meter'!E8 -> 50 | J8: ='Lpg (2)'!B12 -> 85 | K8: ='Lpg (2)'!C12 -> 85 | L8: ='Lpg (2)'!D12 -> 0 | M8: ='Lpg (2)'!G12 -> 42.768 | N8: =D8*1.4 -> 3694.6 | O8: =E8*1.4 -> 0 | P8: ='[1]Lpg (2)'!#REF! -> #REF! | Q8: ='[1]Summery Report'!#REF! -> #REF! | R8: =N8/B8 -> #DIV/0! | S8: =Q8/B8 -> #REF!
A9: =Gen!A14 -> 44320 | B9: ='Summery Report'!E8 -> 0 | C9: =Gen!U14 -> 0.41276362 | D9: =Gen!T14 -> 2826 | E9: =Gen!AK14 -> 0 | F9: =Gen!AS14 -> 0 | G9: ='Utility report '!AC9 -> 32 | H9: ='Utility report '!AE9 -> 56 | I9: ='Water-Meter'!E9 -> 50 | J9: ='Lpg (2)'!B13 -> 85 | K9: ='Lpg (2)'!C13 -> 85 | L9: ='Lpg (2)'!D13 -> 0 | M9: ='Lpg (2)'!G13 -> 55.22 | N9: =D9*1.4 -> 3956.4 | O9: =E9*1.4 -> 0 | P9: ='[1]Lpg (2)'!#REF! -> #REF! | Q9: ='[1]Summery Report'!#REF! -> #REF! | R9: =N9/B9 -> #DIV/0! | S9: =Q9/B9 -> #REF!
A10: =Gen!A15 -> 44321 | B10: ='Summery Report'!E9 -> 0 | C10: =Gen!U15 -> 0.40473022 | D10: =Gen!T15 -> 2780 | E10: =Gen!AK15 -> 0 | F10: =Gen!AS15 -> 0 | G10: ='Utility report '!AC10 -> 38 | H10: ='Utility report '!AE10 -> 50 | I10: ='Water-Meter'!E10 -> 67 | J10: ='Lpg (2)'!B14 -> 85 | K10: ='Lpg (2)'!C14 -> 85 | L10: ='Lpg (2)'!D14 -> 0 | M10: ='Lpg (2)'!G14 -> 65.296 | N10: =D10*1.4 -> 3892 | O10: =E10*1.4 -> 0 | P10: ='[1]Lpg (2)'!#REF! -> #REF! | Q10: ='[1]Summery Report'!#REF! -> #REF! | R10: =N10/B10 -> #DIV/0! | S10: =Q10/B10 -> #REF!
A11: =Gen!A16 -> 44322 | B11: ='Summery Report'!E10 -> 0 | C11: =Gen!U16 -> 0.4066931 | D11: =Gen!T16 -> 2900 | E11: =Gen!AK16 -> 0 | F11: =Gen!AS16 -> 0 | G11: ='Utility report '!AC11 -> 34 | H11: ='Utility report '!AE11 -> 53 | I11: ='Water-Meter'!E11 -> 70 | J11: ='Lpg (2)'!B15 -> 85 | K11: ='Lpg (2)'!C15 -> 84 | L11: ='Lpg (2)'!D15 -> 0 | M11: ='Lpg (2)'!G15 -> 64.988 | N11: =D11*1.4 -> 4060 | O11: =E11*1.4 -> 0 | P11: ='[1]Lpg (2)'!#REF! -> #REF! | Q11: ='[1]Summery Report'!#REF! -> #REF! | R11: =N11/B11 -> #DIV/0! | S11: =Q11/B11 -> #REF!
A12: =Gen!A17 -> 44323 | B12: ='Summery Report'!E11 -> 0 | C12: =Gen!U17 -> 0.41198244 | D12: =Gen!T17 -> 2734 | E12: =Gen!AK17 -> 0 | F12: =Gen!AS17 -> 0 | G12: ='Utility report '!AC12 -> 88 | H12: ='Utility report '!AE12 -> 45 | I12: ='Water-Meter'!E12 -> 50 | J12: ='Lpg (2)'!B16 -> 85 | K12: ='Lpg (2)'!C16 -> 75 | L12: ='Lpg (2)'!D16 -> 0 | M12: ='Lpg (2)'!G16 -> 62.392 | N12: =D12*1.4 -> 3827.6 | O12: =E12*1.4 -> 0 | P12: ='[1]Lpg (2)'!#REF! -> #REF! | Q12: ='[1]Summery Report'!#REF! -> #REF! | R12: =N12/B12 -> #DIV/0! | S12: =Q12/B12 -> #REF!
A13: =Gen!A18 -> 44324 | B13: ='Summery Report'!E12 -> 0 | C13: =Gen!U18 -> 0.41156542 | D13: =Gen!T18 -> 2996 | E13: =Gen!AK18 -> 0 | F13: =Gen!AS18 -> 0 | G13: ='Utility report '!AC13 -> 150 | H13: ='Utility report '!AE13 -> 44 | I13: ='Water-Meter'!E13 -> 51 | J13: ='Lpg (2)'!B17 -> 85 | K13: ='Lpg (2)'!C17 -> 70 | L13: ='Lpg (2)'!D17 -> 0 | M13: ='Lpg (2)'!G17 -> 68.904 | N13: =D13*1.4 -> 4194.4 | O13: =E13*1.4 -> 0 | P13: ='[1]Lpg (2)'!#REF! -> #REF! | Q13: ='[1]Summery Report'!#REF! -> #REF! | R13: =N13/B13 -> #DIV/0! | S13: =Q13/B13 -> #REF!
A14: =Gen!A19 -> 44325 | B14: ='Summery Report'!E13 -> 0 | C14: =Gen!U19 -> 0.40277503 | D14: =Gen!T19 -> 2627 | E14: =Gen!AK19 -> 0 | F14: =Gen!AS19 -> 0 | G14: ='Utility report '!AC14 -> 22 | H14: ='Utility report '!AE14 -> 66 | I14: ='Water-Meter'!E14 -> 76 | J14: ='Lpg (2)'!B18 -> 85 | K14: ='Lpg (2)'!C18 -> 68 | L14: ='Lpg (2)'!D18 -> 0 | M14: ='Lpg (2)'!G18 -> 66 | N14: =D14*1.4 -> 3677.8 | O14: =E14*1.4 -> 0 | P14: ='[1]Lpg (2)'!#REF! -> #REF! | Q14: ='[1]Summery Report'!#REF! -> #REF! | R14: =N14/B14 -> #DIV/0! | S14: =Q14/B14 -> #REF!
A15: =Gen!A20 -> 44326 | B15: ='Summery Report'!E14 -> 0 | C15: =Gen!U20 -> 0.41490645 | D15: =Gen!T20 -> 2619 | E15: =Gen!AK20 -> 0 | F15: =Gen!AS20 -> 0 | G15: ='Utility report '!AC15 -> 33 | H15: ='Utility report '!AE15 -> 53 | I15: ='Water-Meter'!E15 -> 20 | J15: ='Lpg (2)'!B19 -> 85 | K15: ='Lpg (2)'!C19 -> 65 | L15: ='Lpg (2)'!D19 -> 0 | M15: ='Lpg (2)'!G19 -> 79.068 | N15: =D15*1.4 -> 3666.6 | O15: =E15*1.4 -> 0 | P15: ='[1]Lpg (2)'!#REF! -> #REF! | Q15: ='[1]Summery Report'!#REF! -> #REF! | R15: =N15/B15 -> #DIV/0! | S15: =Q15/B15 -> #REF!
A16: =Gen!A21 -> 44327 | B16: ='Summery Report'!E15 -> 0 | C16: =Gen!U21 -> 0.41942574 | D16: =Gen!T21 -> 2525 | E16: =Gen!AK21 -> 0 | F16: =Gen!AS21 -> 0 | G16: ='Utility report '!AC16 -> 33 | H16: ='Utility report '!AE16 -> 51 | I16: ='Water-Meter'!E16 -> 54 | J16: ='Lpg (2)'!B20 -> 85 | K16: ='Lpg (2)'!C20 -> 60 | L16: ='Lpg (2)'!D20 -> 0 | M16: ='Lpg (2)'!G20 -> 71.28 | N16: =D16*1.4 -> 3535 | O16: =E16*1.4 -> 0 | P16: ='[1]Lpg (2)'!#REF! -> #REF! | Q16: ='[1]Summery Report'!#REF! -> #REF! | R16: =N16/B16 -> #DIV/0! | S16: =Q16/B16 -> #REF!
A17: =Gen!A22 -> 44328 | B17: ='Summery Report'!E16 -> 0 | C17: =Gen!U22 -> 0.43087315 | D17: =Gen!T22 -> 2428 | E17: =Gen!AK22 -> 0 | F17: =Gen!AS22 -> 0 | G17: ='Utility report '!AC17 -> 31 | H17: ='Utility report '!AE17 -> 48 | I17: ='Water-Meter'!E17 -> 51 | J17: ='Lpg (2)'!B21 -> 85 | K17: ='Lpg (2)'!C22 -> 51 | L17: ='Lpg (2)'!D21 -> 0 | M17: ='Lpg (2)'!G21 -> 52.36 | N17: =D17*1.4 -> 3399.2 | O17: =E17*1.4 -> 0 | P17: ='[1]Lpg (2)'!#REF! -> #REF! | Q17: ='[1]Summery Report'!#REF! -> #REF! | R17: =N17/B17 -> #DIV/0! | S17: =Q17/B17 -> #REF!
A18: =Gen!A23 -> 44329 | B18: ='Summery Report'!E17 -> 0 | C18: =Gen!U23 -> 0.40042197 | D18: =Gen!T23 -> 2512 | E18: =Gen!AK23 -> 0 | F18: =Gen!AS23 -> 0 | G18: ='Utility report '!AC18 -> 85 | H18: ='Utility report '!AE18 -> 56 | I18: ='Water-Meter'!E18 -> 54 | J18: ='Lpg (2)'!B22 -> 85 | K18: ='Lpg (2)'!C23 -> 48 | L18: ='Lpg (2)'!D22 -> 0 | M18: ='Lpg (2)'!G22 -> 51.788 | N18: =D18*1.4 -> 3516.8 | O18: =E18*1.4 -> 0 | P18: ='[1]Lpg (2)'!#REF! -> #REF! | Q18: ='[1]Summery Report'!#REF! -> #REF! | R18: =N18/B18 -> #DIV/0! | S18: =Q18/B18 -> #REF!
A19: =Gen!A24 -> 44330 | B19: ='Summery Report'!E18 -> 0 | C19: =Gen!U24 -> 0.41580904 | D19: =Gen!T24 -> 2744 | E19: =Gen!AK24 -> 0 | F19: =Gen!AS24 -> 0 | G19: ='Utility report '!AC19 -> 89 | H19: ='Utility report '!AE19 -> 53 | I19: ='Water-Meter'!E19 -> 42 | J19: ='Lpg (2)'!B23 -> 85 | K19: ='Lpg (2)'!C24 -> 40 | L19: ='Lpg (2)'!D23 -> 0 | M19: ='Lpg (2)'!G23 -> 75.02 | N19: =D19*1.4 -> 3841.6 | O19: =E19*1.4 -> 0 | P19: ='[1]Lpg (2)'!#REF! -> #REF! | Q19: ='[1]Summery Report'!#REF! -> #REF! | R19: =N19/B19 -> #DIV/0! | S19: =Q19/B19 -> #REF!
A20: =Gen!A25 -> 44331 | B20: ='Summery Report'!E19 -> 0 | C20: =Gen!U25 -> 0.42675335 | D20: =Gen!T25 -> 2461 | E20: =Gen!AK25 -> 0 | F20: =Gen!AS25 -> 0 | G20: ='Utility report '!AC20 -> 10 | H20: ='Utility report '!AE20 -> 53 | I20: ='Water-Meter'!E20 -> 46 | J20: ='Lpg (2)'!B24 -> 85 | K20: ='Lpg (2)'!C25 -> 37 | L20: ='Lpg (2)'!D24 -> 0 | M20: ='Lpg (2)'!G24 -> 62.524 | N20: =D20*1.4 -> 3445.4 | O20: =E20*1.4 -> 0 | P20: ='[1]Lpg (2)'!#REF! -> #REF! | Q20: ='[1]Summery Report'!#REF! -> #REF! | R20: =N20/B20 -> #DIV/0! | S20: =Q20/B20 -> #REF!
A21: =Gen!A26 -> 44332 | B21: ='Summery Report'!E20 -> 0 | C21: =Gen!U26 -> 0.4227837 | D21: =Gen!T26 -> 2626 | E21: =Gen!AK26 -> 0 | F21: =Gen!AS26 -> 0 | G21: ='Utility report '!AC21 -> 70 | H21: ='Utility report '!AE21 -> 53 | I21: ='Water-Meter'!E21 -> 45 | J21: ='Lpg (2)'!B25 -> 85 | K21: ='Lpg (2)'!C25 -> 37 | L21: ='Lpg (2)'!D25 -> 0 | M21: ='Lpg (2)'!G25 -> 72.16 | N21: =D21*1.4 -> 3676.4 | O21: =E21*1.4 -> 0 | P21: ='[1]Lpg (2)'!#REF! -> #REF! | Q21: ='[1]Summery Report'!#REF! -> #REF! | R21: =N21/B21 -> #DIV/0! | S21: =Q21/B21 -> #REF!
A22: =Gen!A27 -> 44333 | B22: ='Summery Report'!E21 -> 0 | C22: =Gen!U27 -> 0.40053735 | D22: =Gen!T27 -> 3052 | E22: =Gen!AK27 -> 0 | F22: =Gen!AS27 -> 0 | G22: ='Utility report '!AC22 -> 79 | H22: ='Utility report '!AE22 -> 53 | I22: ='Water-Meter'!E22 -> 57 | J22: ='Lpg (2)'!B26 -> 85 | K22: ='Lpg (2)'!C26 -> 34 | L22: ='Lpg (2)'!D26 -> 0 | M22: ='Lpg (2)'!G26 -> 64.636 | N22: =D22*1.4 -> 4272.8 | O22: =E22*1.4 -> 0 | P22: ='[1]Lpg (2)'!#REF! -> #REF! | Q22: ='[1]Summery Report'!#REF! -> #REF! | R22: =N22/B22 -> #DIV/0! | S22: =Q22/B22 -> #REF!
A23: =Gen!A28 -> 44334 | B23: ='Summery Report'!E22 -> 0 | C23: =Gen!U28 -> 0.41726186 | D23: =Gen!T28 -> 2929 | E23: =Gen!AK28 -> 0 | F23: =Gen!AS28 -> 0 | G23: ='Utility report '!AC23 -> 36 | H23: ='Utility report '!AE23 -> 54 | I23: ='Water-Meter'!E23 -> 47 | J23: ='Lpg (2)'!B27 -> 85 | K23: ='Lpg (2)'!C27 -> 31 | L23: ='Lpg (2)'!D27 -> 0 | M23: ='Lpg (2)'!G27 -> 80.212 | N23: =D23*1.4 -> 4100.6 | O23: =E23*1.4 -> 0 | P23: ='[1]Lpg (2)'!#REF! -> #REF! | Q23: ='[1]Summery Report'!#REF! -> #REF! | R23: =N23/B23 -> #DIV/0! | S23: =Q23/B23 -> #REF!
A24: =Gen!A29 -> 44335 | B24: ='Summery Report'!E23 -> 0 | C24: =Gen!U29 -> 0.41349381 | D24: =Gen!T29 -> 2825 | E24: =Gen!AK29 -> 0 | F24: =Gen!AS29 -> 0 | G24: ='Utility report '!AC24 -> 35 | H24: ='Utility report '!AE24 -> 54 | I24: ='Water-Meter'!E24 -> 45 | J24: ='Lpg (2)'!B28 -> 85 | K24: ='Lpg (2)'!C28 -> 29 | L24: ='Lpg (2)'!D28 -> 0 | M24: ='Lpg (2)'!G28 -> 79.904 | N24: =D24*1.4 -> 3955 | O24: =E24*1.4 -> 0 | P24: ='[1]Lpg (2)'!#REF! -> #REF! | Q24: ='[1]Summery Report'!#REF! -> #REF! | R24: =N24/B24 -> #DIV/0! | S24: =Q24/B24 -> #REF!
A25: =Gen!A30 -> 44336 | B25: ='Summery Report'!E24 -> 0 | C25: =Gen!U30 -> 0.40979031 | D25: =Gen!T30 -> 2766 | E25: =Gen!AK30 -> 0 | F25: =Gen!AS30 -> 0 | G25: ='Utility report '!AC25 -> 34 | H25: ='Utility report '!AE25 -> 55 | I25: ='Water-Meter'!E25 -> 49 | J25: ='Lpg (2)'!B29 -> 85 | K25: ='Lpg (2)'!C29 -> 85 | L25: ='Lpg (2)'!D29 -> 85 | M25: ='Lpg (2)'!G29 -> 72.996 | N25: =D25*1.4 -> 3872.4 | O25: =E25*1.4 -> 0 | P25: ='[1]Lpg (2)'!#REF! -> #REF! | Q25: ='[1]Summery Report'!#REF! -> #REF! | R25: =N25/B25 -> #DIV/0! | S25: =Q25/B25 -> #REF!
A26: =Gen!A31 -> 44337 | B26: ='Summery Report'!E25 -> 0 | C26: =Gen!U31 -> 0.40506007 | D26: =Gen!T31 -> 2747 | E26: =Gen!AK31 -> 0 | F26: =Gen!AS31 -> 0 | G26: ='Utility report '!AC26 -> 31 | H26: ='Utility report '!AE26 -> 56 | I26: ='Water-Meter'!E26 -> 45 | J26: ='Lpg (2)'!B30 -> 85 | K26: ='Lpg (2)'!C30 -> 82 | L26: ='Lpg (2)'!D30 -> 85 | M26: ='Lpg (2)'!G30 -> 59.62 | N26: =D26*1.4 -> 3845.8 | O26: =E26*1.4 -> 0 | P26: ='[1]Lpg (2)'!#REF! -> #REF! | Q26: ='[1]Summery Report'!#REF! -> #REF! | R26: =N26/B26 -> #DIV/0! | S26: =Q26/B26 -> #REF!
A27: =Gen!A32 -> 44338 | B27: ='Summery Report'!E26 -> 0 | C27: =Gen!U32 -> 0.41389831 | D27: =Gen!T32 -> 2714 | E27: =Gen!AK32 -> 0 | F27: =Gen!AS32 -> 0 | G27: ='Utility report '!AC27 -> 19 | H27: ='Utility report '!AE27 -> 54 | I27: ='Water-Meter'!E27 -> 63 | J27: ='Lpg (2)'!B31 -> 85 | K27: ='Lpg (2)'!C31 -> 79 | L27: ='Lpg (2)'!D31 -> 85 | M27: ='Lpg (2)'!G31 -> 43.34 | N27: =D27*1.4 -> 3799.6 | O27: =E27*1.4 -> 0 | P27: ='[1]Lpg (2)'!#REF! -> #REF! | Q27: ='[1]Summery Report'!#REF! -> #REF! | R27: =N27/B27 -> #DIV/0! | S27: =Q27/B27 -> #REF!
A28: =Gen!A33 -> 44339 | B28: ='Summery Report'!E27 -> 0 | C28: =Gen!U33 -> 0.41595382 | D28: =Gen!T33 -> 2815 | E28: =Gen!AK33 -> 0 | F28: =Gen!AS33 -> 0 | G28: ='Utility report '!AC28 -> 25 | H28: ='Utility report '!AE28 -> 56 | I28: ='Water-Meter'!E28 -> 47 | J28: ='Lpg (2)'!B32 -> 85 | K28: ='Lpg (2)'!C32 -> 70 | L28: ='Lpg (2)'!D32 -> 85 | M28: ='Lpg (2)'!G32 -> 68.684 | N28: =D28*1.4 -> 3941 | O28: =E28*1.4 -> 0 | P28: ='[1]Lpg (2)'!#REF! -> #REF! | Q28: ='[1]Summery Report'!#REF! -> #REF! | R28: =N28/B28 -> #DIV/0! | S28: =Q28/B28 -> #REF!
A29: =Gen!A34 -> 44340 | B29: ='Summery Report'!E28 -> 0 | C29: =Gen!U34 -> 0.41536697 | D29: =Gen!T34 -> 2616 | E29: =Gen!AK34 -> 0 | F29: =Gen!AS34 -> 0 | G29: ='Utility report '!AC29 -> 162 | H29: ='Utility report '!AE29 -> 47 | I29: ='Water-Meter'!E29 -> 46 | J29: ='Lpg (2)'!B33 -> 85 | K29: ='Lpg (2)'!C33 -> 65 | L29: ='Lpg (2)'!D33 -> 85 | M29: ='Lpg (2)'!G33 -> -171.644 | N29: =D29*1.4 -> 3662.4 | O29: =E29*1.4 -> 0 | P29: ='[1]Lpg (2)'!#REF! -> #REF! | Q29: ='[1]Summery Report'!#REF! -> #REF! | R29: =N29/B29 -> #DIV/0! | S29: =Q29/B29 -> #REF!
A30: =Gen!A35 -> 44341 | B30: ='Summery Report'!E29 -> 0 | C30: =Gen!U35 -> 0.40613057 | D30: =Gen!T35 -> 2941 | E30: =Gen!AK35 -> 0 | F30: =Gen!AS35 -> 0 | G30: ='Utility report '!AC30 -> 75 | H30: ='Utility report '!AE30 -> 24 | I30: ='Water-Meter'!E30 -> 51 | J30: ='Lpg (2)'!B34 -> 85 | K30: ='Lpg (2)'!C34 -> 60 | L30: ='Lpg (2)'!D34 -> 85 | M30: ='Lpg (2)'!G34 -> 289.256 | N30: =D30*1.4 -> 4117.4 | O30: =E30*1.4 -> 0 | P30: ='[1]Lpg (2)'!#REF! -> #REF! | Q30: ='[1]Summery Report'!#REF! -> #REF! | R30: =N30/B30 -> #DIV/0! | S30: =Q30/B30 -> #REF!
A31: =Gen!A36 -> 44342 | B31: ='Summery Report'!E30 -> 0 | C31: =Gen!U36 -> 0.41911135 | D31: =Gen!T36 -> 2802 | E31: =Gen!AK36 -> 0 | F31: =Gen!AS36 -> 0 | G31: ='Utility report '!AC31 -> 55 | H31: ='Utility report '!AE31 -> 21 | I31: ='Water-Meter'!E31 -> 56 | J31: ='Lpg (2)'!B35 -> 85 | K31: ='Lpg (2)'!C35 -> 57 | L31: ='Lpg (2)'!D35 -> 85 | M31: ='Lpg (2)'!G35 -> 122.232 | N31: =D31*1.4 -> 3922.8 | O31: =E31*1.4 -> 0 | P31: ='[1]Lpg (2)'!#REF! -> #REF! | Q31: ='[1]Summery Report'!#REF! -> #REF! | R31: =N31/B31 -> #DIV/0! | S31: =Q31/B31 -> #REF!
A32: =Gen!A37 -> 44343 | B32: ='Summery Report'!E31 -> 0 | C32: =Gen!U37 -> #DIV/0! | D32: =Gen!T37 -> 0 | E32: =Gen!AK37 -> 0 | F32: =Gen!AS37 -> 0 | G32: ='Utility report '!AC32 -> -2436 | H32: ='Utility report '!AE32 -> -217003 | I32: ='Water-Meter'!E32 -> 0 | J32: ='Lpg (2)'!B36 -> 0 | K32: ='Lpg (2)'!C36 -> 0 | L32: ='Lpg (2)'!D36 -> 0 | M32: ='Lpg (2)'!G36 -> -337131.04 | N32: =D32*1.4 -> 0 | O32: =E32*1.4 -> 0 | P32: ='[1]Lpg (2)'!#REF! -> #REF! | Q32: ='[1]Summery Report'!#REF! -> #REF! | R32: =N32/B32 -> #DIV/0! | S32: =Q32/B32 -> #REF!
... A36: =Gen!A41 -> 44347 | B36: ='Summery Report'!E35 -> 0 | C36: =Gen!U41 -> #DIV/0! | D36: =Gen!T41 -> 0 | E36: =Gen!AK41 -> 0 | F36: =Gen!AS41 -> 0 | G36: ='Utility report '!AC36 -> 0 | H36: ='Utility report '!AE36 -> 0 | I36: ='Water-Meter'!E36 -> 0 | J36: ='Lpg (2)'!B40 -> 0 | K36: ='Lpg (2)'!C40 -> 0 | L36: ='Lpg (2)'!D40 -> 0 | M36: ='Lpg (2)'!G40 -> 0 | N36: =D36*1.4 -> 0 | O36: =E36*1.4 -> 0 | P36: ='[1]Lpg (2)'!#REF! -> #REF! | Q36: ='[1]Summery Report'!#REF! -> #REF! | R36: =N36/B36 -> #DIV/0! | S36: =Q36/B36 -> #REF!
B37: ='Summery Report'!E36 -> 0 | C37: =Gen!U42 -> 0 | D37: =Gen!T42 -> 0 | E37: =Gen!AK42 -> 0 | F37: =Gen!AS42 -> 0 | G37: ='Utility report '!AC37 -> 0 | H37: ='Utility report '!AE37 -> 0 | I37: ='Water-Meter'!E37 -> 0 | J37: ='Lpg (2)'!B41 -> 0 | K37: ='Lpg (2)'!C41 -> 0 | L37: ='Lpg (2)'!D41 -> 0 | M37: ='Lpg (2)'!G41 -> 0 | Q37: ='[1]Summery Report'!#REF! -> #REF! | R37: =N37/B37 -> #DIV/0! | S37: =Q37/B37 -> #REF!
A39: Total | B39: =SUM(B7:B37) -> 0 | C39: =SUM(C7:C35) -> #DIV/0! | D39: =SUM(D7:D35) -> 68321 | E39: =SUM(E7:E35) -> 0 | F39: =SUM(F7:F35) -> 0 | G39: =SUM(G7:G35) -> -1095 | H39: =SUM(H7:H35) -> -215754 | I39: =SUM(I7:I35) -> 1282 | J39: =SUM(J7:J35) -> 2125 | ... S39: =SUM(S7:S35) -> #REF!

Sheet Utility report 
A1: =A6 -> 44317
A2: Date | B2: Total occupancy | H2: Diesel balance LTS | I2: Diesel Deliveries | J2: Gen.Diesel consumption LTS | L2: Total Diesel consumption LTS | M2: Water Meter reading | N2: Water consumption m³ | O2: R.O WATER PRODUCTION LTRS + TIME | AA2: Total RO production | AB2: RO Meter reading | AD2: 0 | AE2: STP | AF2: GAS TANK A | AG2: GAS TANK B | AH2: GAS TANK C | AI2: Total Gas Tanks | AJ2: Kg /day | AK2: TOTAL GAS cons.
A3: Rate Tsh /$ | B3: 1640 | C3: Diesel cost / lits | D3: 2175 | F3: =SUM(D3/B3) -> 1.3262195 | H3: =Gen!C11 -> 27860.56 | K3: Transport consumption | M3: Balance | O3: PLANT NO 1 | S3: PLANT NO 2 | W3: PLANT NO 3 | AA3: /day | AB3: Balance | AD3: 0 | AE3: Production | AF3: Capacity | AG3: Capacity | AH3: Capacity | AI3: Kg | AJ3: /day | AK3: /day
B4: Rooms OCC | C4: % | D4: Guest Rooms Occ | F4: Electricity Production Cost /Room Occ by guest | G4: All Cost /Room Occ by guest | O4: Flow M3 | P4: Reading Hours Meter | Q4: Hrs | R4: total production M3 | S4: Flow M3 | T4: Reading Hours Meter | U4: Hrs | V4: total production M3 | W4: Flow M3 | X4: READING HOURS METER | Y4: Hrs | Z4: total production M3 | AA4: M3 | AC4: M3 | AE4: M3 | AF4: 2000 | AG4: 1000 | AH4: 1000 | AI4: =SUM([2]Sheet1!$AA$36) -> 950 | AJ4: Kg | AK4: M3
O5: 1.9 | P5: 19038 | S5: 6.2 | T5: 17942 | W5: 1.7 | X5: 28101 | AB5: 977 | AD5: 215688 | AF5: 0.85 | AG5: 0.85 | AH5: 0.85
A6: =Gen!A11 -> 44317 | B6: ='Summery Report'!E5 -> 0 | C6: =Gen!B11 -> 0.01 | D6: ='Summery Report'!E5 -> 0 | E6: =SUM(F3) -> 1.3262195 | F6: =SUM(J6*E6)/D6 -> #DIV/0! | G6: =SUM(L6*E6)/D6 -> #DIV/0! | H6: =Gen!C11 -> 27860.56 | I6: =Gen!E11 -> 15000 | J6: =Gen!T11 -> 2650 | K6: =Gen!AK11 -> 0 | L6: =SUM(J6:K6) -> 2650 | M6: ='Water-Meter'!K46 -> 356.09027 | N6: ='Water-Meter'!E6 -> 41 | O6: 1.9 | P6: 19038 | Q6: =SUM(P6-P5) -> 0 | R6: =SUM(Q6*O6) -> 0 | S6: 6.2 | T6: 17958 | U6: =T6-T5 -> 16 | V6: - | W6: 1.7 | X6: 28101 | Y6: =X6-X5 -> 0 | Z6: =Y6-Y5 -> 0 | AA6: =Z6-Z5 -> 0 | AB6: 1095 | AC6: =AB6-AB5 -> 118 | AD6: 215754 | AE6: =AD6-AD5 -> 66 | AF6: ='Lpg (2)'!B10*2000/85 -> 2000 | AG6: ='Lpg (2)'!C10*1000/85 -> 1000 | AH6: ='Lpg (2)'!D10*1000/85 -> 11.764706 | AI6: =SUM(AF6*2000)+(AG6*1000)+(AH6*1000) -> 5011764.7 | AJ6: =SUM(AI5-AI6) -> -5011764.7
A7: =Gen!A12 -> 44318 | B7: ='Summery Report'!E6 -> 0 | C7: =Gen!B12 -> 0 | D7: ='Summery Report'!E6 -> 0 | E7: =SUM(E6) -> 1.3262195 | F7: =SUM(J7*E7)/D7 -> #DIV/0! | G7: =SUM(L7*E7)/D7 -> #DIV/0! | H7: =Gen!C12 -> 26680.18 | I7: =Gen!E12 -> 0 | J7: =Gen!T12 -> 2697 | K7: =Gen!AK12 -> 0 | L7: =SUM(J7:K7) -> 2697 | M7: ='Water-Meter'!K47 -> 425.02402 | N7: ='Water-Meter'!E7 -> 50 | O7: 1.9 | P7: 19038 | Q7: =SUM(P7-P6) -> 0 | R7: =SUM(Q7*O7) -> 0 | S7: 6.2 | T7: 17958 | U7: =T7-T6 -> 0 | V7: =SUM(U7*S7) -> 0 | W7: 1.7 | X7: 28128 | Y7: =X7-X6 -> 27 | Z7: =SUM(Y7*W7) -> 45.9 | AA7: =SUM(Z7*X9) -> 1293278.4 | AB7: 1133 | AC7: =AB7-AB6 -> 38 | AD7: 215804 | AE7: =AD7-AD6 -> 50 | AF7: ='Lpg (2)'!B11*2000/85 -> 2000 | AG7: ='Lpg (2)'!C11*1000/85 -> 1000 | AH7: ='Lpg (2)'!D11*1000/85 -> 11.764706 | AI7: =SUM(AF6*2000)+(AG7*1000)+(AH7*1000) -> 5011764.7 | AJ7: =SUM(AI6-AI7) -> 0
A8: =Gen!A13 -> 44319 | B8: ='Summery Report'!E7 -> 0 | C8: =Gen!B13 -> 0.039 | D8: ='Summery Report'!E7 -> 0 | E8: =SUM(E7) -> 1.3262195 | F8: =SUM(J8*E8)/D8 -> #DIV/0! | G8: =SUM(L8*E8)/D8 -> #DIV/0! | H8: =Gen!C13 -> 40466.02 | I8: =Gen!E13 -> 0 | J8: =Gen!T13 -> 2639 | K8: =Gen!AK13 -> 0 | L8: =SUM(J8:K8) -> 2639 | M8: ='Water-Meter'!K48 -> 483.24621 | N8: ='Water-Meter'!E8 -> 50 | O8: 1.9 | P8: 19038 | Q8: =SUM(P8-P7) -> 0 | R8: =SUM(Q8*O8) -> 0 | S8: 6.2 | T8: 17958 | U8: =T8-T7 -> 0 | V8: =SUM(U8*S8) -> 0 | W8: 1.7 | X8: 28152 | Y8: =X8-X7 -> 24 | Z8: =SUM(Y8*W8) -> 40.8 | AA8: =SUM(Z8*X10) -> 1150560 | AB8: 1170 | AC8: =AB8-AB7 -> 37 | AD8: 215848 | AE8: =AD8-AD7 -> 44 | AF8: ='Lpg (2)'!B12*2000/85 -> 2000 | AG8: ='Lpg (2)'!C12*1000/85 -> 1000 | AH8: ='Lpg (2)'!D12*1000/85 -> 0 | AI8: =SUM(AF7*2000)+(AG8*1000)+(AH8*1000) -> 5000000 | AJ8: =SUM(AI7-AI8) -> 11764.706
A9: =Gen!A14 -> 44320 | B9: ='Summery Report'!E8 -> 0 | C9: =Gen!B14 -> 0.052 | D9: ='Summery Report'!E8 -> 0 | E9: =SUM(E8) -> 1.3262195 | F9: =SUM(J9*E9)/D9 -> #DIV/0! | G9: =SUM(L9*E9)/D9 -> #DIV/0! | H9: =Gen!C14 -> 39347.69 | I9: =Gen!E14 -> 0 | J9: =Gen!T14 -> 2826 | K9: =Gen!AK14 -> 0 | L9: =SUM(J9:K9) -> 2826 | M9: ='Water-Meter'!K49 -> 530.87796 | N9: ='Water-Meter'!E9 -> 50 | O9: 1.9 | P9: 19038 | Q9: =SUM(P9-P8) -> 0 | R9: =SUM(Q9*O9) -> 0 | S9: 6.2 | T9: 17958 | U9: =T9-T8 -> 0 | V9: =SUM(U9*S10) -> 0 | W9: 1.7 | X9: 28176 | Y9: =X9-X8 -> 24 | Z9: =SUM(Y9*W11) -> 40.8 | AA9: =SUM(Z9*X11) -> 1151539.2 | AB9: 1202 | AC9: =AB9-AB8 -> 32 | AD9: 215904 | AE9: =AD9-AD8 -> 56 | AF9: ='Lpg (2)'!B13*2000/85 -> 2000 | AG9: ='Lpg (2)'!C13*1000/85 -> 1000 | AH9: ='Lpg (2)'!D13*1000/85 -> 0 | AI9: =SUM(AF8*2000)+(AG9*1000)+(AH9*1000) -> 5000000 | AJ9: =SUM(AI8-AI9) -> 0
A10: =Gen!A15 -> 44321 | B10: ='Summery Report'!E9 -> 0 | C10: =Gen!B15 -> 0.056 | D10: ='Summery Report'!E9 -> 0 | E10: =SUM(E9) -> 1.3262195 | F10: =SUM(J10*E10)/D10 -> #DIV/0! | G10: =SUM(L10*E10)/D10 -> #DIV/0! | H10: =Gen!C15 -> 38143.09 | I10: =Gen!E15 -> 0 | J10: =Gen!T15 -> 2780 | K10: =Gen!AK15 -> 0 | L10: =SUM(J10:K10) -> 2780 | M10: ='Water-Meter'!K50 -> 520.23189 | N10: ='Water-Meter'!E10 -> 67 | O10: 1.9 | P10: 19038 | Q10: =SUM(P10-P9) -> 0 | R10: =SUM(Q10*O10) -> 0 | S10: 6.2 | T10: 17958 | U10: =T10-T9 -> 0 | V10: =SUM(U10*#REF!) -> #REF! | W10: 1.7 | X10: 28200 | Y10: =X10-X9 -> 24 | Z10: =SUM(Y10*W10) -> 40.8 | AA10: =SUM(Z10*X12) -> 1152151.2 | AB10: 1240 | AC10: =AB10-AB9 -> 38 | AD10: 215954 | AE10: =AD10-AD9 -> 50 | AF10: ='Lpg (2)'!B14*2000/85 -> 2000 | AG10: ='Lpg (2)'!C14*1000/85 -> 1000 | AH10: ='Lpg (2)'!D14*1000/85 -> 0 | AI10: =SUM(AF9*2000)+(AG10*1000)+(AH10*1000) -> 5000000 | AJ10: =SUM(AI9-AI10) -> 0
A11: =Gen!A16 -> 44322 | B11: ='Summery Report'!E10 -> 0 | C11: =Gen!B16 -> 0.056 | D11: ='Summery Report'!E10 -> 0 | E11: =SUM(E10) -> 1.3262195 | F11: =SUM(J11*E11)/D11 -> #DIV/0! | G11: =SUM(L11*E11)/D11 -> #DIV/0! | H11: =Gen!C16 -> 37017.94 | I11: =Gen!E16 -> 0 | J11: =Gen!T16 -> 2900 | K11: =Gen!AK16 -> 0 | L11: =SUM(J11:K11) -> 2900 | M11: ='Water-Meter'!K51 -> 509.27934 | N11: ='Water-Meter'!E11 -> 70 | O11: 1.9 | P11: 19038 | Q11: =SUM(P11-P10) -> 0 | R11: =SUM(Q11*O11) -> 0 | S11: 6.2 | T11: 17958 | U11: =T11-T10 -> 0 | V11: =SUM(U11*S11) -> 0 | W11: 1.7 | X11: 28224 | Y11: =X11-X10 -> 24 | Z11: =SUM(Y11*#REF!) -> #REF! | AA11: =SUM(Z11*X13) -> #REF! | AB11: 1274 | AC11: =AB11-AB10 -> 34 | AD11: 216007 | AE11: =AD11-AD10 -> 53 | AF11: ='Lpg (2)'!B15*2000/85 -> 2000 | AG11: ='Lpg (2)'!C15*1000/85 -> 988.23529 | AH11: ='Lpg (2)'!D15*1000/85 -> 0 | AI11: =SUM(AF10*2000)+(AG11*1000)+(AH11*1000) -> 4988235.3 | AJ11: =SUM(AI10-AI11) -> 11764.706
A12: =Gen!A17 -> 44323 | B12: ='Summery Report'!E11 -> 0 | C12: =Gen!B17 -> 0 | D12: ='Summery Report'!E11 -> 0 | E12: =SUM(E11) -> 1.3262195 | F12: =SUM(J12*E12)/D12 -> #DIV/0! | G12: =SUM(L12*E12)/D12 -> #DIV/0! | H12: =Gen!C17 -> 35338.4 | I12: =Gen!E17 -> 0 | J12: =Gen!T17 -> 2734 | K12: =Gen!AK17 -> 0 | L12: =SUM(J12:K12) -> 2734 | M12: ='Water-Meter'!K52 -> 430.60261 | N12: ='Water-Meter'!E12 -> 50 | O12: 1.9 | P12: 19038 | Q12: =SUM(P12-P11) -> 0 | R12: =SUM(Q12*O12) -> 0 | S12: 6.2 | T12: 17968 | U12: =T12-T11 -> 10 | V12: =SUM(U12*S12) -> 62 | W12: 1.7 | X12: 28239 | Y12: =X12-X11 -> 15 | Z12: =SUM(Y12*W12) -> 25.5 | AA12: =SUM(Z12*X14) -> 720477 | AB12: 1362 | AC12: =AB12-AB11 -> 88 | AD12: 216052 | AE12: =AD12-AD11 -> 45 | AF12: ='Lpg (2)'!B16*2000/85 -> 2000 | AG12: ='Lpg (2)'!C16*1000/85 -> 882.35294 | AH12: ='Lpg (2)'!D16*1000/85 -> 0 | AI12: =SUM(AF11*2000)+(AG12*1000)+(AH12*1000) -> 4882352.9 | AJ12: =SUM(AI11-AI12) -> 105882.35
A13: =Gen!A18 -> 44324 | B13: ='Summery Report'!E12 -> 0 | C13: =Gen!B18 -> 0 | D13: ='Summery Report'!E12 -> 0 | E13: =SUM(E12) -> 1.3262195 | F13: =SUM(J13*E13)/D13 -> #DIV/0! | G13: =SUM(L13*E13)/D13 -> #DIV/0! | H13: =Gen!C18 -> 49212.04 | I13: =Gen!E18 -> 0 | J13: =Gen!T18 -> 2996 | K13: =Gen!AK18 -> 0 | L13: =SUM(J13:K13) -> 2996 | M13: ='Water-Meter'!K53 -> 436.71662 | N13: ='Water-Meter'!E13 -> 51 | O13: 1.9 | P13: 19038 | Q13: =SUM(P13-P12) -> 0 | R13: =SUM(Q13*O13) -> 0 | S13: 6.2 | T13: 17989 | U13: =T13-T12 -> 21 | V13: =SUM(U13*S13) -> 130.2 | W13: 1.7 | X13: 28239 | Y13: =X13-X12 -> 0 | Z13: =SUM(Y13*W13) -> 0 | AA13: =SUM(Z13*X15) -> 0 | AB13: 1512 | AC13: =AB13-AB12 -> 150 | AD13: 216096 | AE13: =AD13-AD12 -> 44 | AF13: ='Lpg (2)'!B17*2000/85 -> 2000 | AG13: ='Lpg (2)'!C17*1000/85 -> 823.52941 | AH13: ='Lpg (2)'!D17*1000/85 -> 0 | AI13: =SUM(AF12*2000)+(AG13*1000)+(AH13*1000) -> 4823529.4 | AJ13: =SUM(AI12-AI13) -> 58823.529
A14: =Gen!A19 -> 44325 | B14: ='Summery Report'!E13 -> 0 | C14: =Gen!B19 -> 0 | D14: ='Summery Report'!E13 -> 0 | E14: =SUM(E13) -> 1.3262195 | F14: =SUM(J14*E14)/D14 -> #DIV/0! | G14: =SUM(L14*E14)/D14 -> #DIV/0! | H14: =Gen!C19 -> 47730.99 | I14: =Gen!E19 -> 0 | J14: =Gen!T19 -> 2627 | K14: =Gen!AK19 -> 0 | L14: =SUM(J14:K14) -> 2627 | M14: ='Water-Meter'!K54 -> 523.50956 | N14: ='Water-Meter'!E14 -> 76 | O14: 1.9 | P14: 19038 | Q14: =SUM(P14-P13) -> 0 | R14: =SUM(Q14*O14) -> 0 | S14: 6.2 | T14: 17989 | U14: =T14-T13 -> 0 | V14: =SUM(U14*S14) -> 0 | W14: 1.7 | X14: 28254 | Y14: =X14-X13 -> 15 | Z14: =SUM(Y14*W14) -> 25.5 | AA14: =SUM(Z14*X16) -> 721675.5 | AB14: 1534 | AC14: =AB14-AB13 -> 22 | AD14: 216162 | AE14: =AD14-AD13 -> 66 | AF14: ='Lpg (2)'!B18*2000/85 -> 2000 | AG14: ='Lpg (2)'!C18*1000/85 -> 800 | AH14: ='Lpg (2)'!D18*1000/85 -> 0 | AI14: =SUM(AF13*2000)+(AG14*1000)+(AH14*1000) -> 4800000 | AJ14: =SUM(AI13-AI14) -> 23529.412
A15: =Gen!A20 -> 44326 | B15: ='Summery Report'!E14 -> 0 | C15: =Gen!B20 -> 0 | D15: ='Summery Report'!E14 -> 0 | E15: =SUM(E14) -> 1.3262195 | F15: =SUM(J15*E15)/D15 -> #DIV/0! | G15: =SUM(L15*E15)/D15 -> #DIV/0! | H15: =Gen!C20 -> 46526.75 | I15: =Gen!E20 -> 0 | J15: =Gen!T20 -> 2619 | K15: =Gen!AK20 -> 0 | L15: =SUM(J15:K15) -> 2619 | M15: ='Water-Meter'!K55 -> 593.5082 | N15: ='Water-Meter'!E15 -> 20 | O15: 1.9 | P15: 19038 | Q15: =SUM(P15-P14) -> 0 | R15: =SUM(Q15*O15) -> 0 | S15: 6.2 | T15: 17989 | U15: =T15-T14 -> 0 | V15: =SUM(U15*S15) -> 0 | W15: 1.4 | X15: 28277 | Y15: =X15-X14 -> 23 | Z15: =SUM(Y15*W15) -> 32.2 | AA15: =SUM(Z15*X17) -> 912065 | AB15: 1567 | AC15: =AB15-AB14 -> 33 | AD15: 216215 | AE15: =AD15-AD14 -> 53 | AF15: ='Lpg (2)'!B19*2000/85 -> 2000 | AG15: ='Lpg (2)'!C19*1000/85 -> 764.70588 | AH15: ='Lpg (2)'!D19*1000/85 -> 0 | AI15: =SUM(AF15*2000)+(AG15*1000)+(AH15*1000) -> 4764705.9 | AJ15: =SUM(AI14-AI15) -> 35294.118
A16: =Gen!A21 -> 44327 | B16: ='Summery Report'!E15 -> 0 | C16: =Gen!B21 -> 0 | D16: ='Summery Report'!E15 -> 0 | E16: =SUM(E15) -> 1.3262195 | F16: =SUM(J16*E16)/D16 -> #DIV/0! | G16: =SUM(L16*E16)/D16 -> #DIV/0! | H16: =Gen!C21 -> 45299.78 | I16: =Gen!E21 -> 0 | J16: =Gen!T21 -> 2525 | K16: =Gen!AK21 -> 0 | L16: =SUM(J16:K16) -> 2525 | M16: ='Water-Meter'!K56 -> 567.07692 | N16: ='Water-Meter'!E16 -> 54 | O16: 1.9 | P16: 19038 | Q16: =SUM(P16-P15) -> 0 | R16: =SUM(Q16*O16) -> 0 | S16: 6.2 | T16: 17989 | U16: =T16-T15 -> 0 | V16: =SUM(U16*S16) -> 0 | W16: 1.4 | X16: 28301 | Y16: =X16-X15 -> 24 | Z16: =SUM(Y16*W16) -> 33.6 | AA16: =SUM(Z16*X18) -> 951720 | AB16: 1600 | AC16: =AB16-AB15 -> 33 | AD16: 216266 | AE16: =AD16-AD15 -> 51 | AF16: ='Lpg (2)'!B20*2000/85 -> 2000 | AG16: ='Lpg (2)'!C20*1000/85 -> 705.88235 | AH16: ='Lpg (2)'!D20*1000/85 -> 0 | AI16: =SUM(AF16*2000)+(AG16*1000)+(AH16*1000) -> 4705882.4 | AJ16: =SUM(AI15-AI16) -> 58823.529
A17: =Gen!A22 -> 44328 | B17: ='Summery Report'!E16 -> 0 | C17: =Gen!B22 -> 0 | D17: ='Summery Report'!E16 -> 0 | E17: =SUM(E16) -> 1.3262195 | F17: =SUM(J17*E17)/D17 -> #DIV/0! | G17: =SUM(L17*E17)/D17 -> #DIV/0! | H17: =Gen!C22 -> 43593.73 | I17: =Gen!E22 -> 0 | J17: =Gen!T22 -> 2428 | K17: =Gen!AK22 -> 0 | L17: =SUM(J17:K17) -> 2428 | M17: ='Water-Meter'!K57 -> 520.13348 | N17: ='Water-Meter'!E17 -> 51 | O17: 1.9 | P17: 19038 | Q17: =SUM(P18-P16) -> 0 | R17: =SUM(Q17*O17) -> 0 | S17: 6.2 | T17: 17989 | U17: =T17-T16 -> 0 | V17: =SUM(U17*S17) -> 0 | W17: 1.4 | X17: 28325 | Y17: =X17-X16 -> 24 | Z17: =SUM(Y17*W17) -> 33.6 | AA17: =SUM(Z17*X19) -> 951720 | AB17: 1631 | AC17: =AB17-AB16 -> 31 | AD17: 216314 | AE17: =AD17-AD16 -> 48 | AF17: ='Lpg (2)'!B21*2000/85 -> 2000 | AG17: ='Lpg (2)'!C21*1000/85 -> 658.82353 | AH17: ='Lpg (2)'!D21*1000/85 -> 0 | AI17: =SUM(AF17*2000)+(AG17*1000)+(AH17*1000) -> 4658823.5 | AJ17: =SUM(AI16-AI17) -> 47058.824
A18: =Gen!A23 -> 44329 | B18: ='Summery Report'!E17 -> 0 | C18: =Gen!B23 -> 0 | D18: ='Summery Report'!E17 -> 0 | E18: =SUM(E17) -> 1.3262195 | F18: =SUM(J18*E18)/D18 -> #DIV/0! | G18: =SUM(L18*E18)/D18 -> #DIV/0! | H18: =Gen!C23 -> 42547.57 | I18: =Gen!E23 -> 15000 | J18: =Gen!T23 -> 2512 | K18: =Gen!AK23 -> 0 | L18: =SUM(J18:K18) -> 2512 | M18: ='Water-Meter'!K58 -> 510.42352 | N18: ='Water-Meter'!E18 -> 54 | O18: 1.9 | P18: 19038 | R18: =SUM(Q18*O18) -> 0 | S18: 6.2 | T18: 18000 | U18: =T18-T17 -> 11 | V18: =SUM(U18*S18) -> 68.2 | W18: 1.4 | X18: 28325 | Y18: =X18-X17 -> 0 | Z18: =SUM(Y18*W18) -> 0 | AA18: =SUM(Z18*X20) -> 0 | AB18: 1716 | AC18: =AB18-AB17 -> 85 | AD18: 216370 | AE18: =AD18-AD17 -> 56 | AF18: ='Lpg (2)'!B22*2000/85 -> 2000 | AG18: ='Lpg (2)'!C22*1000/85 -> 600 | AH18: ='Lpg (2)'!D22*1000/85 -> 0 | AI18: =SUM(AF18*2000)+(AG18*1000)+(AH18*1000) -> 4600000 | AJ18: =SUM(AI17-AI18) -> 58823.529
A19: =Gen!A24 -> 44330 | B19: ='Summery Report'!E18 -> 0 | C19: =Gen!B24 -> 0 | D19: ='Summery Report'!E18 -> 0 | E19: =SUM(E18) -> 1.3262195 | F19: =SUM(J19*E19)/D19 -> #DIV/0! | G19: =SUM(L19*E19)/D19 -> #DIV/0! | H19: =Gen!C24 -> 41292.23 | I19: =Gen!E24 -> 0 | J19: =Gen!T24 -> 2744 | K19: =Gen!AK24 -> 0 | L19: =SUM(J19:K19) -> 2744 | M19: ='Water-Meter'!K59 -> 384.10642 | N19: ='Water-Meter'!E19 -> 42 | O19: 1.9 | P19: 19038 | R19: =SUM(Q19*O19) -> 0 | S19: 6.2 | T19: 18013 | U19: =T19-T18 -> 13 | V19: =SUM(U19*S19) -> 80.6 | W19: 1.4 | X19: 28325 | Y19: =X19-X18 -> 0 | Z19: =SUM(Y19*W19) -> 0 | AA19: =SUM(Z19*X21) -> 0 | AB19: 1805 | AC19: =AB19-AB18 -> 89 | AD19: 216423 | AE19: =AD19-AD18 -> 53 | AF19: ='Lpg (2)'!B23*2000/85 -> 2000 | AG19: ='Lpg (2)'!C23*1000/85 -> 564.70588 | AH19: ='Lpg (2)'!D23*1000/85 -> 0 | AI19: =SUM(AF19*2000)+(AG19*1000)+(AH19*1000) -> 4564705.9 | AJ19: =SUM(AI18-AI19) -> 35294.118
A20: =Gen!A25 -> 44331 | B20: ='Summery Report'!E19 -> 0 | C20: =Gen!B25 -> 0 | D20: ='Summery Report'!E19 -> 0 | E20: =SUM(E19) -> 1.3262195 | F20: =SUM(J20*E20)/D20 -> #DIV/0! | G20: =SUM(L20*E20)/D20 -> #DIV/0! | H20: =Gen!C25 -> 40057.83 | I20: =Gen!E25 -> 0 | J20: =Gen!T25 -> 2461 | K20: =Gen!AK25 -> 0 | L20: =SUM(J20:K20) -> 2461 | M20: ='Water-Meter'!K60 -> 456.77054 | N20: ='Water-Meter'!E20 -> 46 | O20: 1.9 | P20: 19038 | Q20: =SUM(P20-P19) -> 0 | R20: =SUM(Q20*O20) -> 0 | S20: 6.2 | T20: 1815 | U20: =T20-T19 -> -16198 | V20: =SUM(U20*S20) -> -100427.6 | W20: 1.4 | X20: 28325 | Y20: =X20-X19 -> 0 | Z20: =SUM(Y20*W20) -> 0 | AA20: =SUM(Z20*X22) -> 0 | AB20: 1815 | AC20: =AB20-AB19 -> 10 | AD20: 216476 | AE20: =AD20-AD19 -> 53 | AF20: ='Lpg (2)'!B24*2000/85 -> 2000 | AG20: ='Lpg (2)'!C24*1000/85 -> 470.58824 | AH20: ='Lpg (2)'!D24*1000/85 -> 0 | AI20: =SUM(AF20*2000)+(AG20*1000)+(AH20*1000) -> 4470588.2 | AJ20: =SUM(AI19-AI20) -> 94117.647
A21: =Gen!A26 -> 44332 | B21: ='Summery Report'!E20 -> 0 | C21: =Gen!B26 -> 0 | D21: ='Summery Report'!E20 -> 0 | E21: =SUM(E20) -> 1.3262195 | F21: =SUM(J21*E21)/D21 -> #DIV/0! | G21: =SUM(L21*E21)/D21 -> #DIV/0! | H21: =Gen!C26 -> 38851.35 | I21: =Gen!E26 -> 0 | J21: =Gen!T26 -> 2626 | K21: =Gen!AK26 -> 0 | L21: =SUM(J21:K21) -> 2626 | M21: ='Water-Meter'!K61 -> 459.20376 | N21: ='Water-Meter'!E21 -> 45 | O21: 1.9 | P21: 19038 | Q21: =SUM(P21-P20) -> 0 | R21: =SUM(Q21*O21) -> 0 | S21: 6.2 | T21: 18025 | U21: =T22-T20 -> 16217 | V21: =SUM(U21*S21) -> 100545.4 | W21: 1.4 | X21: 28325 | Y21: =X21-X20 -> 0 | Z21: =SUM(Y21*W21) -> 0 | AA21: =SUM(Z21*X23) -> 0 | AB21: 1885 | AC21: =AB21-AB20 -> 70 | AD21: 216529 | AE21: =AD21-AD20 -> 53 | AF21: ='Lpg (2)'!B25*2000/85 -> 2000 | AG21: ='Lpg (2)'!C25*1000/85 -> 435.29412 | AH21: ='Lpg (2)'!D25*1000/85 -> 0 | AI21: =SUM(AF21*2000)+(AG21*1000)+(AH21*1000) -> 4435294.1 | AJ21: =SUM(AI20-AI21) -> 35294.118
