Workbook

Sheet Sheet1
A1: Site Name | B1: Day | C1: Month | D1: Year | E1: Total Electricity Kwh | F1: Electricity Tariff ($/Kwh) | G1: LPG (Kg) | H1: LPG $/Kg | I1: District Energy Cooling Kwh | J1: District Energy Cooling $/Kwh | K1: Water Utility Supply (m3) m3 | L1: Water Utility Supply (m3) $/m3 | M1: Irrigation Water (m3) m3 | N1: Irrigation water $/m3 | O1: Room Nights | P1: Total Guests
A2: Bahrain Bay | B2: 1 | C2: 5 | D2: 2021 | E2: ='May 2021'!E5 -> 29354 | F2: 0.029 | G2: ='May 2021'!J5 -> 0 | H2: 0.112 | I2: ='May 2021'!G5*1000 -> 100000 | J2: 0.0361 | K2: ='May 2021'!I5 -> 223 | L2: 0.75 | M2: ='May 2021'!L5 -> 131 | N2: 0.563 | O2: ='May 2021'!D5 -> 46
A3: Bahrain Bay | B3: =B2+1 -> 2 | C3: 5 | D3: 2021 | E3: ='May 2021'!E6 -> 31897 | F3: 0.029 | G3: ='May 2021'!J6 -> 0 | H3: 0.112 | I3: ='May 2021'!G6*1000 -> 48000 | J3: 0.0361 | K3: ='May 2021'!I6 -> 255 | L3: 0.75 | M3: ='May 2021'!L6 -> 174 | N3: 0.563 | O3: ='May 2021'!D6 -> 48
A4: Bahrain Bay | B4: =B3+1 -> 3 | C4: 5 | D4: 2021 | E4: ='May 2021'!E7 -> 29812 | F4: 0.029 | G4: ='May 2021'!J7 -> 0 | H4: 0.112 | I4: ='May 2021'!G7*1000 -> 48000 | J4: 0.0361 | K4: ='May 2021'!I7 -> 273 | L4: 0.75 | M4: ='May 2021'!L7 -> 145 | N4: 0.563 | O4: ='May 2021'!D7 -> 56
A5: Bahrain Bay | B5: =B4+1 -> 4 | C5: 5 | D5: 2021 | E5: ='May 2021'!E8 -> 28976 | F5: 0.029 | G5: ='May 2021'!J8 -> 2970 | H5: 0.112 | I5: ='May 2021'!G8*1000 -> 51000 | J5: 0.0361 | K5: ='May 2021'!I8 -> 221 | L5: 0.75 | M5: ='May 2021'!L8 -> 204 | N5: 0.563 | O5: ='May 2021'!D8 -> 60
A6: Bahrain Bay | B6: =B5+1 -> 5 | C6: 5 | D6: 2021 | E6: ='May 2021'!E9 -> 30198 | F6: 0.029 | G6: ='May 2021'!J9 -> 0 | H6: 0.112 | I6: ='May 2021'!G9*1000 -> 53000 | J6: 0.0361 | K6: ='May 2021'!I9 -> 229 | L6: 0.75 | M6: ='May 2021'!L9 -> 101 | N6: 0.563 | O6: ='May 2021'!D9 -> 57
A7: Bahrain Bay | B7: =B6+1 -> 6 | C7: 5 | D7: 2021 | E7: ='May 2021'!E10 -> 29789 | F7: 0.029 | G7: 0 | H7: 0.112 | I7: ='May 2021'!G10*1000 -> 56000 | J7: 0.0361 | K7: ='May 2021'!I10 -> 213 | L7: 0.75 | M7: ='May 2021'!L10 -> 170 | N7: 0.563 | O7: ='May 2021'!D10 -> 55
A8: Bahrain Bay | B8: =B7+1 -> 7 | C8: 5 | D8: 2021 | E8: ='May 2021'!E11 -> 28999 | F8: 0.029 | G8: ='May 2021'!J11 -> 0 | H8: 0.112 | I8: ='May 2021'!G11*1000 -> 56000 | J8: 0.0361 | K8: ='May 2021'!I11 -> 318 | L8: 0.75 | M8: ='May 2021'!L11 -> 69 | N8: 0.563 | O8: ='May 2021'!D11 -> 55
A9: Bahrain Bay | B9: =B8+1 -> 8 | C9: 5 | D9: 2021 | E9: ='May 2021'!E12 -> 29076 | F9: 0.029 | G9: ='May 2021'!J12 -> 0 | H9: 0.112 | I9: ='May 2021'!G12*1000 -> 58000 | J9: 0.0361 | K9: ='May 2021'!I12 -> 202 | L9: 0.75 | M9: ='May 2021'!L12 -> 200 | N9: 0.563 | O9: ='May 2021'!D12 -> 56
A10: Bahrain Bay | B10: =B9+1 -> 9 | C10: 5 | D10: 2021 | E10: ='May 2021'!E13 -> 29399 | F10: 0.029 | G10: ='May 2021'!J13 -> 0 | H10: 0.112 | I10: ='May 2021'!G13*1000 -> 45000 | J10: 0.0361 | K10: ='May 2021'!I13 -> 311 | L10: 0.75 | M10: ='May 2021'!L13 -> 176 | N10: 0.563 | O10: ='May 2021'!D13 -> 56
A11: Bahrain Bay | B11: =B10+1 -> 10 | C11: 5 | D11: 2021 | E11: ='May 2021'!E14 -> 29202 | F11: 0.029 | G11: ='May 2021'!J14 -> 2970 | H11: 0.112 | I11: ='May 2021'!G14*1000 -> 45000 | J11: 0.0361 | K11: ='May 2021'!I14 -> 225 | L11: 0.75 | M11: ='May 2021'!L14 -> 173 | N11: 0.563 | O11: ='May 2021'!D14 -> 58
A12: Bahrain Bay | B12: =B11+1 -> 11 | C12: 5 | D12: 2021 | E12: ='May 2021'!E15 -> 31237 | F12: 0.029 | G12: ='May 2021'!J15 -> 0 | H12: 0.112 | I12: ='May 2021'!G15*1000 -> 14000 | J12: 0.0361 | K12: ='May 2021'!I15 -> 297 | L12: 0.75 | M12: ='May 2021'!L15 -> 0 | N12: 0.563 | O12: ='May 2021'!D15 -> 72
A13: Bahrain Bay | B13: =B12+1 -> 12 | C13: 5 | D13: 2021 | E13: ='May 2021'!E16 -> 34541 | F13: 0.029 | G13: ='May 2021'!J16 -> 0 | H13: 0.112 | I13: ='May 2021'!G16*1000 -> 58000 | J13: 0.0361 | K13: ='May 2021'!I16 -> 296 | L13: 0.75 | M13: ='May 2021'!L16 -> 218 | N13: 0.563 | O13: ='May 2021'!D16 -> 114
A14: Bahrain Bay | B14: =B13+1 -> 13 | C14: 5 | D14: 2021 | E14: ='May 2021'!E17 -> 35413 | F14: 0.029 | G14: ='May 2021'!J17 -> 2970 | H14: 0.112 | I14: ='May 2021'!G17*1000 -> 65000 | J14: 0.0361 | K14: ='May 2021'!I17 -> 311 | L14: 0.75 | M14: ='May 2021'!L17 -> 297 | N14: 0.563 | O14: ='May 2021'!D17 -> 162
A15: Bahrain Bay | B15: =B14+1 -> 14 | C15: 5 | D15: 2021 | E15: ='May 2021'!E18 -> 36691 | F15: 0.029 | G15: ='May 2021'!J18 -> 0 | H15: 0.112 | I15: ='May 2021'!G18*1000 -> 65000 | J15: 0.0361 | K15: ='May 2021'!I18 -> 343 | L15: 0.75 | M15: ='May 2021'!L18 -> 161 | N15: 0.563 | O15: ='May 2021'!D18 -> 196
A16: Bahrain Bay | B16: =B15+1 -> 15 | C16: 5 | D16: 2021 | E16: ='May 2021'!E19 -> 37100 | F16: 0.029 | G16: ='May 2021'!J19 -> 2970 | H16: 0.112 | I16: ='May 2021'!G20*1000 -> 70000 | J16: 0.0361 | K16: ='May 2021'!I19 -> 415 | L16: 0.75 | M16: ='May 2021'!L19 -> 208 | N16: 0.563 | O16: ='May 2021'!D19 -> 191
A17: Bahrain Bay | B17: =B16+1 -> 16 | C17: 5 | D17: 2021 | E17: ='May 2021'!E20 -> 36541 | F17: 0.029 | G17: ='May 2021'!J20 -> 0 | H17: 0.112 | I17: ='May 2021'!G21*1000 -> 68000 | J17: 0.0361 | K17: ='May 2021'!I20 -> 415 | L17: 0.75 | M17: ='May 2021'!L20 -> 292 | N17: 0.563 | O17: ='May 2021'!D20 -> 166
A18: Bahrain Bay | B18: =B17+1 -> 17 | C18: 5 | D18: 2021 | E18: ='May 2021'!E21 -> 37500 | F18: 0.029 | G18: ='May 2021'!J21 -> 2970 | H18: 0.112 | I18: ='May 2021'!G22*1000 -> 73000 | J18: 0.0361 | K18: ='May 2021'!I21 -> 515 | L18: 0.75 | M18: ='May 2021'!L21 -> 274 | N18: 0.563 | O18: ='May 2021'!D21 -> 110
A19: Bahrain Bay | B19: =B18+1 -> 18 | C19: 5 | D19: 2021 | E19: ='May 2021'!E22 -> 34849 | F19: 0.029 | G19: ='May 2021'!J22 -> 0 | H19: 0.112 | I19: ='May 2021'!G23*1000 -> 80000 | J19: 0.0361 | K19: ='May 2021'!I22 -> 519 | L19: 0.75 | M19: ='May 2021'!L22 -> 220 | N19: 0.563 | O19: ='May 2021'!D22 -> 117
A20: Bahrain Bay | B20: =B19+1 -> 19 | C20: 5 | D20: 2021 | E20: ='May 2021'!E23 -> 34373 | F20: 0.029 | G20: ='May 2021'!J23 -> 0 | H20: 0.112 | I20: ='May 2021'!G24*1000 -> 77000 | J20: 0.0361 | K20: ='May 2021'!I23 -> 321 | L20: 0.75 | M20: ='May 2021'!L23 -> 212 | N20: 0.563 | O20: ='May 2021'!D23 -> 101
A21: Bahrain Bay | B21: =B20+1 -> 20 | C21: 5 | D21: 2021 | E21: ='May 2021'!E24 -> 34522 | F21: 0.029 | G21: ='May 2021'!J23 -> 0 | H21: 0.112 | I21: ='May 2021'!G25*1000 -> 78000 | J21: 0.0361 | K21: ='May 2021'!I23 -> 321 | L21: 0.75 | M21: ='May 2021'!L24 -> 279 | N21: 0.563 | O21: ='May 2021'!D24 -> 101
A22: Bahrain Bay | B22: =B21+1 -> 21 | C22: 5 | D22: 2021 | E22: ='May 2021'!E25 -> 34000 | F22: 0.029 | G22: ='May 2021'!J24 -> 2970 | H22: 0.112 | I22: ='May 2021'!G26*1000 -> 70000 | J22: 0.0361 | K22: ='May 2021'!I24 -> 241 | L22: 0.75 | M22: ='May 2021'!L25 -> 145 | N22: 0.563 | O22: ='May 2021'!D25 -> 121
A23: Bahrain Bay | B23: =B22+1 -> 22 | C23: 5 | D23: 2021 | E23: ='May 2021'!E26 -> 34567 | F23: 0.029 | G23: ='May 2021'!J25 -> 0 | H23: 0.112 | I23: ='May 2021'!G27*1000 -> 67000 | J23: 0.0361 | K23: ='May 2021'!I26 -> 484 | L23: 0.75 | M23: ='May 2021'!L26 -> 235 | N23: 0.563 | O23: ='May 2021'!D26 -> 102
A24: Bahrain Bay | B24: =B23+1 -> 23 | C24: 5 | D24: 2021 | E24: ='May 2021'!E27 -> 32814 | F24: 0.029 | G24: ='May 2021'!J27 -> 2970 | H24: 0.112 | I24: ='May 2021'!G27*1000 -> 67000 | J24: 0.0361 | K24: ='May 2021'!I27 -> 215 | L24: 0.75 | M24: ='May 2021'!L27 -> 240 | N24: 0.563 | O24: ='May 2021'!D27 -> 100
A25: Bahrain Bay | B25: =B24+1 -> 24 | C25: 5 | D25: 2021 | E25: ='May 2021'!E28 -> 35440 | F25: 0.029 | G25: ='May 2021'!J28 -> 0 | H25: 0.112 | I25: ='May 2021'!G28*1000 -> 77000 | J25: 0.0361 | K25: ='May 2021'!I28 -> 191 | L25: 0.75 | M25: ='May 2021'!L28 -> 267 | N25: 0.563 | O25: ='May 2021'!D28 -> 107
A26: Bahrain Bay | B26: =B25+1 -> 25 | C26: 5 | D26: 2021 | E26: ='May 2021'!E29 -> 34074 | F26: 0.029 | G26: ='May 2021'!J29 -> 2970 | H26: 0.112 | I26: ='May 2021'!G29*1000 -> 83000 | J26: 0.0361 | K26: ='May 2021'!I29 -> 509 | L26: 0.75 | M26: ='May 2021'!L29 -> 228 | N26: 0.563 | O26: ='May 2021'!D29 -> 97
A27: Bahrain Bay | B27: =B26+1 -> 26 | C27: 5 | D27: 2021 | E27: ='May 2021'!E30 -> 29876 | F27: 0.029 | G27: ='May 2021'!J30 -> 2970 | H27: 0.112 | I27: ='May 2021'!G30*1000 -> 79000 | J27: 0.0361 | K27: ='May 2021'!I30 -> 224 | L27: 0.75 | M27: ='May 2021'!L30 -> 241 | N27: 0.563 | O27: ='May 2021'!D30 -> 70
A28: Bahrain Bay | B28: =B27+1 -> 27 | C28: 5 | D28: 2021 | E28: ='May 2021'!E31 -> 24654 | F28: 0.029 | G28: ='May 2021'!J31 -> 2970 | H28: 0.112 | I28: ='May 2021'!G31*1000 -> 71000 | J28: 0.0361 | K28: ='May 2021'!I31 -> 482 | L28: 0.75 | M28: ='May 2021'!L31 -> 373 | N28: 0.563 | O28: ='May 2021'!D31 -> 49
A29: Bahrain Bay | B29: =B28+1 -> 28 | C29: 5 | D29: 2021 | E29: ='May 2021'!E32 -> 27654 | F29: 0.029 | G29: ='May 2021'!J32 -> 0 | H29: 0.112 | I29: ='May 2021'!G32*1000 -> 53000 | J29: 0.0361 | K29: ='May 2021'!I32 -> 157 | L29: 0.75 | M29: ='May 2021'!L32 -> 144 | N29: 0.563 | O29: ='May 2021'!D32 -> 31
A30: Bahrain Bay | B30: 29 | C30: 5 | D30: 2021 | E30: ='May 2021'!E33 -> 23387 | F30: 0.029 | G30: ='May 2021'!J33 -> 2970 | H30: 0.112 | I30: ='May 2021'!G33*1000 -> 49000 | J30: 0.0361 | K30: ='May 2021'!I33 -> 81 | L30: 0.75 | M30: ='May 2021'!L33 -> 306 | N30: 0.563 | O30: ='May 2021'!D33 -> 25
A31: Bahrain Bay | B31: 30 | C31: 5 | D31: 2021 | E31: ='May 2021'!E34 -> 0 | F31: 0.029 | G31: ='May 2021'!J34 -> 0 | H31: 0.112 | I31: ='May 2021'!G34*1000 -> 0 | J31: 0.0361 | K31: ='May 2021'!I34 -> 0 | L31: 0.75 | M31: ='May 2021'!L34 -> 0 | N31: 0.563 | O31: ='May 2021'!D34 -> 0
A32: Bahrain Bay | D32: 2021 | E32: ='May 2021'!E35 -> 0 | F32: 0.029 | G32: ='May 2021'!J35 -> 0 | H32: 0.112 | I32: ='May 2021'!G35*1000 -> 0 | J32: 0.0361 | K32: ='May 2021'!I35 -> 0 | L32: 0.75 | M32: ='May 2021'!L35 -> 0 | N32: 0.563 | O32: ='May 2021'!D35 -> 0

Sheet May 2021
B2: Electricity and Utilities Reading
B3: S. No. | C3: Date | E3: Electricity Consumption kWh | F3: Chilled H2O Consumption Reading | G3: Consumption MWh | H3: Potable Water Consumption Reading | I3: Consumption m3 | K3: Irrigation Water Consumption Reading | L3: Consumption m3
D4: RoomNights | J4: LPG (Kg)
B5: 1 | C5: 44317 | D5: 46 | E5: 29354 | F5: 187170 | G5: =F6-F5 -> 100 | H5: 473121 | I5: =H6-H5 -> 223 | J5: 0 | K5: 279449 | L5: =K6-K5 -> 131
B6: 2 | C6: 44318 | D6: 48 | E6: 31897 | F6: 187270 | G6: =F7-F6 -> 48 | H6: 473344 | I6: =H7-H6 -> 255 | J6: 0 | K6: 279580 | L6: =K7-K6 -> 174
B7: 3 | C7: 44319 | D7: 56 | E7: 29812 | F7: 187318 | G7: =F8-F7 -> 48 | H7: 473599 | I7: =H8-H7 -> 273 | J7: 0 | K7: 279754 | L7: =K8-K7 -> 145
B8: 4 | C8: 44320 | D8: 60 | E8: 28976 | F8: 187366 | G8: =F9-F8 -> 51 | H8: 473872 | I8: =H9-H8 -> 221 | J8: 2970 | K8: 279899 | L8: =K9-K8 -> 204
B9: 5 | C9: 44321 | D9: 57 | E9: 30198 | F9: 187417 | G9: =F10-F9 -> 53 | H9: 474093 | I9: =H10-H9 -> 229 | J9: 0 | K9: 280103 | L9: =K10-K9 -> 101
B10: 6 | C10: 44322 | D10: 55 | E10: 29789 | F10: 187470 | G10: =F11-F10 -> 56 | H10: 474322 | I10: =H11-H10 -> 213 | J10: 2970 | K10: 280204 | L10: =K11-K10 -> 170
B11: 7 | C11: 44323 | D11: 55 | E11: 28999 | F11: 187526 | G11: =F12-F11 -> 56 | H11: 474535 | I11: =H12-H11 -> 318 | J11: 0 | K11: 280374 | L11: =K12-K11 -> 69
B12: 8 | C12: 44324 | D12: 56 | E12: 29076 | F12: 187582 | G12: =F13-F12 -> 58 | H12: 474853 | I12: =H13-H12 -> 202 | J12: 0 | K12: 280443 | L12: =K13-K12 -> 200
B13: 9 | C13: 44325 | D13: 56 | E13: 29399 | F13: 187640 | G13: =F14-F13 -> 45 | H13: 475055 | I13: =H14-H13 -> 311 | J13: 0 | K13: 280643 | L13: =K14-K13 -> 176
B14: 10 | C14: 44326 | D14: 58 | E14: 29202 | F14: 187685 | G14: =F15-F14 -> 45 | H14: 475366 | I14: =H15-H14 -> 225 | J14: 2970 | K14: 280819 | L14: =K15-K14 -> 173
B15: 11 | C15: 44327 | D15: 72 | E15: 31237 | F15: 187730 | G15: =F16-F15 -> 14 | H15: 475591 | I15: =H16-H15 -> 297 | J15: 0 | K15: 280992 | L15: =K16-K15 -> 0
A16: 1 | B16: 12 | C16: 44328 | D16: 114 | E16: 34541 | F16: 187744 | G16: =F17-F16 -> 58 | H16: 475888 | I16: =H17-H16 -> 296 | J16: 0 | K16: 280992 | L16: =K17-K16 -> 218
B17: 13 | C17: 44329 | D17: 162 | E17: 35413 | F17: 187802 | G17: =F18-F17 -> 65 | H17: 476184 | I17: =H18-H17 -> 311 | J17: 2970 | K17: 281210 | L17: =K18-K17 -> 297
B18: 14 | C18: 44330 | D18: 196 | E18: 36691 | F18: 187867 | G18: =F19-F18 -> 65 | H18: 476495 | I18: =H19-H18 -> 343 | J18: 0 | K18: 281507 | L18: =K19-K18 -> 161
B19: 15 | C19: 44331 | D19: 191 | E19: 37100 | F19: 187932 | G19: =F20-F19 -> 64 | H19: 476838 | I19: =H20-H19 -> 415 | J19: 2970 | K19: 281668 | L19: =K20-K19 -> 208
B20: 16 | C20: 44332 | D20: 166 | E20: 36541 | F20: 187996 | G20: =F21-F20 -> 70 | H20: 477253 | I20: =H21-H20 -> 415 | J20: 0 | K20: 281876 | L20: =K21-K20 -> 292
B21: 17 | C21: 44333 | D21: 110 | E21: 37500 | F21: 188066 | G21: =F22-F21 -> 68 | H21: 477668 | I21: =H22-H21 -> 515 | J21: 2970 | K21: 282168 | L21: =K22-K21 -> 274
B22: 18 | C22: 44334 | D22: 117 | E22: 34849 | F22: 188134 | G22: =F23-F22 -> 73 | H22: 478183 | I22: =H23-H22 -> 519 | J22: 0 | K22: 282442 | L22: =K23-K22 -> 220
B23: 19 | C23: 44335 | D23: 101 | E23: 34373 | F23: 188207 | G23: =F24-F23 -> 80 | H23: 478702 | I23: =H24-H23 -> 321 | J23: 0 | K23: 282662 | L23: =K24-K23 -> 212
B24: 20 | C24: 44336 | D24: 101 | E24: 34522 | F24: 188287 | G24: =F25-F24 -> 77 | H24: 479023 | I24: =H25-H24 -> 241 | J24: 2970 | K24: 282874 | L24: =K25-K24 -> 279
B25: 21 | C25: 44337 | D25: 121 | E25: 34000 | F25: 188364 | G25: =F26-F25 -> 78 | H25: 479264 | I25: =H26-H25 -> 413 | J25: 0 | K25: 283153 | L25: =K26-K25 -> 145
B26: 22 | C26: 44338 | D26: 102 | E26: 34567 | F26: 188442 | G26: =F27-F26 -> 70 | H26: 479677 | I26: =H27-H26 -> 484 | J26: 0 | K26: 283298 | L26: =K27-K26 -> 235
B27: 23 | C27: 44339 | D27: 100 | E27: 32814 | F27: 188512 | G27: =F28-F27 -> 67 | H27: 480161 | I27: =H28-H27 -> 215 | J27: 2970 | K27: 283533 | L27: =K28-K27 -> 240
B28: 24 | C28: 44340 | D28: 107 | E28: 35440 | F28: 188579 | G28: =F29-F28 -> 77 | H28: 480376 | I28: =H29-H28 -> 191 | J28: 0 | K28: 283773 | L28: =K29-K28 -> 267
A29: v | B29: 25 | C29: 44341 | D29: 97 | E29: 34074 | F29: 188656 | G29: =F30-F29 -> 83 | H29: 480567 | I29: =H30-H29 -> 509 | J29: 2970 | K29: 284040 | L29: =K30-K29 -> 228
B30: 26 | C30: 44342 | D30: 70 | E30: 29876 | F30: 188739 | G30: =F31-F30 -> 79 | H30: 481076 | I30: =H31-H30 -> 224 | J30: 2970 | K30: 284268 | L30: =K31-K30 -> 241
B31: 27 | C31: 44343 | D31: 49 | E31: 24654 | F31: 188818 | G31: =F32-F31 -> 71 | H31: 481300 | I31: =H32-H31 -> 482 | J31: 2970 | K31: 284509 | L31: =K32-K31 -> 373
B32: 28 | C32: 44344 | D32: 31 | E32: 27654 | F32: 188889 | G32: =F33-F32 -> 53 | H32: 481782 | I32: =H33-H32 -> 157 | J32: 0 | K32: 284882 | L32: =K33-K32 -> 144
B33: 29 | C33: 44345 | D33: 25 | E33: 23387 | F33: 188942 | G33: =F34-F33 -> 49 | H33: 481939 | I33: =H34-H33 -> 81 | J33: 2970 | K33: 285026 | L33: =K34-K33 -> 306
B34: 30 | C34: 44346 | F34: 188991 | H34: 482020 | J34: 0 | K34: 285332
B35: 31 | C35: 44347
F40: Good morning,
F42: Meeting invitation is sent out for a general discussion regarding the AMC services.
F44: It will be a virtual meeting over teams. Kindly confirm your availability.
F46: Thank you.
F48: Sincere Regards,
F49: Nabeela Awan
...
