Workbook

Sheet Total
A1: Site Name | B1: Day | C1: Month | D1: Year | E1: Total Electricity Kwh | F1: Electricity Tariff ($/Kwh) | G1: Total Fuel Oil (Liters) | H1: Fuel Oil $/Liter | I1: LPG (Kg) | J1: LPG $/Kg | K1: Water Utility Supply (m3) m3 | L1: Water Utility Supply (m3) $/m3 | M1: Irrigation Water (m3) m3 | N1: Irrigation water $/m3 | O1: Room Nights
A2: Beirut | B2: 1 | C2: 6 | D2: 2021 | E2: =ELEC!N4 -> 9940 | F2: =SUM('EDl log'!T4) -> #DIV/0! | G2: =-tanks!AW6 -> 0 | H2: =SUM(tanks!AV6) -> 1.003 | I2: =('B5'!AU5)*0.51 -> 0 | J2: ='B5'!AX5/0.51 -> 1.5686275 | K2: =WATER!I6 -> 0 | L2: =SUM(WATER!J6) -> 0 | M2: =WATER!Q6 -> 0 | N2: 0.6 | O2: =ELEC!B4 -> 0
A3: Beirut | B3: =B2+1 -> 2 | C3: 6 | D3: 2021 | E3: =ELEC!N5 -> 0 | F3: =SUM('EDl log'!T5) -> 0 | G3: =-tanks!AW7 -> 0 | H3: =SUM(tanks!AV7) -> 1.003 | I3: =('B5'!AU6)*0.51 -> 0 | J3: ='B5'!AX6/0.51 -> 1.5686275 | K3: =WATER!I7 -> 0 | L3: =SUM(WATER!J7) -> 0 | M3: =WATER!Q7 -> 0 | N3: 0.6 | O3: =ELEC!B5 -> 0
A4: Beirut | B4: =B3+1 -> 3 | C4: 6 | D4: 2021 | E4: =ELEC!N6 -> 0 | F4: =SUM('EDl log'!T6) -> 0 | G4: =-tanks!AW8 -> 0 | H4: =SUM(tanks!AV8) -> 1.003 | I4: =('B5'!AU7)*0.51 -> 0 | J4: ='B5'!AX7/0.51 -> 1.5686275 | K4: =WATER!I8 -> 0 | L4: =SUM(WATER!J8) -> 0 | M4: =WATER!Q8 -> 0 | N4: 0.6 | O4: =ELEC!B6 -> 0
A5: Beirut | B5: =B4+1 -> 4 | C5: 6 | D5: 2021 | E5: =ELEC!N7 -> 0 | F5: =SUM('EDl log'!T7) -> 0 | G5: =-tanks!AW9 -> 0 | H5: =SUM(tanks!AV9) -> 1.003 | I5: =('B5'!AU8)*0.51 -> 0 | J5: ='B5'!AX8/0.51 -> 1.5686275 | K5: =WATER!I9 -> 0 | L5: =SUM(WATER!J9) -> 0 | M5: =WATER!Q9 -> 0 | N5: 0.6 | O5: =ELEC!B7 -> 0
A6: Beirut | B6: =B5+1 -> 5 | C6: 6 | D6: 2021 | E6: =ELEC!N8 -> 0 | F6: =SUM('EDl log'!T8) -> 0 | G6: =-tanks!AW10 -> 0 | H6: =SUM(tanks!AV10) -> 1.003 | I6: =('B5'!AU9)*0.51 -> 0 | J6: ='B5'!AX9/0.51 -> 1.5686275 | K6: =WATER!I10 -> 0 | L6: =SUM(WATER!J10) -> 0 | M6: =WATER!Q10 -> 0 | N6: 0.6 | O6: =ELEC!B8 -> 0
A7: Beirut | B7: =B6+1 -> 6 | C7: 6 | D7: 2021 | E7: =ELEC!N9 -> 0 | F7: =SUM('EDl log'!T9) -> 0 | G7: =-tanks!AW11 -> 0 | H7: =SUM(tanks!AV11) -> 1.003 | I7: =('B5'!AU10)*0.51 -> 0 | J7: ='B5'!AX10/0.51 -> 1.5686275 | K7: =WATER!I11 -> 0 | L7: =SUM(WATER!J11) -> 0 | M7: =WATER!Q11 -> 0 | N7: 0.6 | O7: =ELEC!B9 -> 0
A8: Beirut | B8: =B7+1 -> 7 | C8: 6 | D8: 2021 | E8: =ELEC!N10 -> 0 | F8: =SUM('EDl log'!T10) -> 0 | G8: =-tanks!AW12 -> 0 | H8: =SUM(tanks!AV12) -> 1.003 | I8: =('B5'!AU11)*0.51 -> 0 | J8: ='B5'!AX11/0.51 -> 1.5686275 | K8: =WATER!I12 -> 0 | L8: =SUM(WATER!J12) -> 0 | M8: =WATER!Q12 -> 0 | N8: 0.6 | O8: =ELEC!B10 -> 0
A9: Beirut | B9: =B8+1 -> 8 | C9: 6 | D9: 2021 | E9: =ELEC!N11 -> 0 | F9: =SUM('EDl log'!T11) -> 0 | G9: =-tanks!AW13 -> 0 | H9: =SUM(tanks!AV13) -> 1.003 | I9: =('B5'!AU12)*0.51 -> 0 | J9: ='B5'!AX12/0.51 -> 1.5686275 | K9: =WATER!I13 -> 0 | L9: =SUM(WATER!J13) -> 0 | M9: =WATER!Q13 -> 0 | N9: 0.6 | O9: =ELEC!B11 -> 0
A10: Beirut | B10: =B9+1 -> 9 | C10: 6 | D10: 2021 | E10: =ELEC!N12 -> 0 | F10: =SUM('EDl log'!T12) -> 0 | G10: =-tanks!AW14 -> 0 | H10: =SUM(tanks!AV14) -> 1.003 | I10: =('B5'!AU13)*0.51 -> 0 | J10: ='B5'!AX13/0.51 -> 1.5686275 | K10: =WATER!I14 -> 0 | L10: =SUM(WATER!J14) -> 0 | M10: =WATER!Q14 -> 0 | N10: 0.6 | O10: =ELEC!B12 -> 0
A11: Beirut | B11: =B10+1 -> 10 | C11: 6 | D11: 2021 | E11: =ELEC!N13 -> 0 | F11: =SUM('EDl log'!T13) -> 0 | G11: =-tanks!AW15 -> 0 | H11: =SUM(tanks!AV15) -> 1.003 | I11: =('B5'!AU14)*0.51 -> 0 | J11: ='B5'!AX14/0.51 -> 1.5686275 | K11: =WATER!I15 -> 0 | L11: =SUM(WATER!J15) -> 0 | M11: =WATER!Q15 -> 0 | N11: 0.6 | O11: =ELEC!B13 -> 0
A12: Beirut | B12: =B11+1 -> 11 | C12: 6 | D12: 2021 | E12: =ELEC!N14 -> 0 | F12: =SUM('EDl log'!T14) -> 0 | G12: =-tanks!AW16 -> 0 | H12: =SUM(tanks!AV16) -> 1.003 | I12: =('B5'!AU15)*0.51 -> 0 | J12: ='B5'!AX15/0.51 -> 1.5686275 | K12: =WATER!I16 -> 0 | L12: =SUM(WATER!J16) -> 0 | M12: =WATER!Q16 -> 0 | N12: 0.6 | O12: =ELEC!B14 -> 0
A13: Beirut | B13: =B12+1 -> 12 | C13: 6 | D13: 2021 | E13: =ELEC!N15 -> 0 | F13: =SUM('EDl log'!T15) -> 0 | G13: =-tanks!AW17 -> 0 | H13: =SUM(tanks!AV17) -> 1.003 | I13: =('B5'!AU16)*0.51 -> 0 | J13: ='B5'!AX16/0.51 -> 1.5686275 | K13: =WATER!I17 -> 0 | L13: =SUM(WATER!J17) -> 0 | M13: =WATER!Q17 -> 0 | N13: 0.6 | O13: =ELEC!B15 -> 0
A14: Beirut | B14: =B13+1 -> 13 | C14: 6 | D14: 2021 | E14: =ELEC!N16 -> 0 | F14: =SUM('EDl log'!T16) -> 0 | G14: =-tanks!AW18 -> 0 | H14: =SUM(tanks!AV18) -> 1.003 | I14: =('B5'!AU17)*0.51 -> 0 | J14: ='B5'!AX17/0.51 -> 1.5686275 | K14: =WATER!I18 -> 0 | L14: =SUM(WATER!J18) -> 0 | M14: =WATER!Q18 -> 0 | N14: 0.6 | O14: =ELEC!B16 -> 0
... A31: Beirut | B31: =B30+1 -> 30 | C31: 6 | D31: 2021 | E31: =ELEC!N33 -> 0 | F31: =SUM('EDl log'!T33) -> 0 | G31: =-tanks!AW35 -> 0 | H31: =SUM(tanks!AV35) -> 1.003 | I31: =('B5'!AU34)*0.51 -> 0 | J31: ='B5'!AX34/0.51 -> 1.5686275 | K31: =WATER!I35 -> 0 | L31: =SUM(WATER!J35) -> 0 | M31: =WATER!Q35 -> 0 | N31: 0.6 | O31: =ELEC!B33 -> 0

Sheet Submetering
A1: Site Name | B1: Day | C1: Month | D1: Year | E1: ATS1 Kwh | F1: ATS2 Kwh | G1: ATS3 Kwh | H1: ATS4 Kwh | I1: ATS5 Kwh | J1: Guest (m3) | K1: Kitchen & Laundry (m3) | L1: Room Nights
A2: Beirut | B2: 1 | C2: 6 | D2: 2021 | E2: =ELEC!M4 -> 1550 | F2: =ELEC!K4 -> 4758 | G2: =ELEC!I4 -> 742 | H2: =ELEC!E4 -> 2415 | I2: =ELEC!G4 -> 475 | J2: =WATER!Y6 -> 0 | K2: =WATER!AJ6 -> 0 | L2: =ELEC!B4 -> 0
A3: Beirut | B3: =B2+1 -> 2 | C3: 6 | D3: 2021 | E3: =ELEC!M5 -> 0 | F3: =ELEC!K5 -> 0 | G3: =ELEC!I5 -> 0 | H3: =ELEC!E5 -> 0 | I3: =ELEC!G5 -> 0 | J3: =WATER!Y7 -> 0 | K3: =WATER!AJ7 -> 0 | L3: =ELEC!B5 -> 0
A4: Beirut | B4: =B3+1 -> 3 | C4: 6 | D4: 2021 | E4: =ELEC!M6 -> 0 | F4: =ELEC!K6 -> 0 | G4: =ELEC!I6 -> 0 | H4: =ELEC!E6 -> 0 | I4: =ELEC!G6 -> 0 | J4: =WATER!Y8 -> 0 | K4: =WATER!AJ8 -> 0 | L4: =ELEC!B6 -> 0
A5: Beirut | B5: =B4+1 -> 4 | C5: 6 | D5: 2021 | E5: =ELEC!M7 -> 0 | F5: =ELEC!K7 -> 0 | G5: =ELEC!I7 -> 0 | H5: =ELEC!E7 -> 0 | I5: =ELEC!G7 -> 0 | J5: =WATER!Y9 -> 0 | K5: =WATER!AJ9 -> 0 | L5: =ELEC!B7 -> 0
A6: Beirut | B6: =B5+1 -> 5 | C6: 6 | D6: 2021 | E6: =ELEC!M8 -> 0 | F6: =ELEC!K8 -> 0 | G6: =ELEC!I8 -> 0 | H6: =ELEC!E8 -> 0 | I6: =ELEC!G8 -> 0 | J6: =WATER!Y10 -> 0 | K6: =WATER!AJ10 -> 0 | L6: =ELEC!B8 -> 0
A7: Beirut | B7: =B6+1 -> 6 | C7: 6 | D7: 2021 | E7: =ELEC!M9 -> 0 | F7: =ELEC!K9 -> 0 | G7: =ELEC!I9 -> 0 | H7: =ELEC!AO9 -> 0 | I7: =ELEC!G9 -> 0 | J7: =WATER!Y11 -> 0 | K7: =WATER!AJ11 -> 0 | L7: =ELEC!B9 -> 0
A8: Beirut | B8: =B7+1 -> 7 | C8: 6 | D8: 2021 | E8: =ELEC!M10 -> 0 | F8: =ELEC!K10 -> 0 | G8: =ELEC!I10 -> 0 | H8: =ELEC!AO10 -> 0 | I8: =ELEC!G10 -> 0 | J8: =WATER!Y12 -> 0 | K8: =WATER!AJ12 -> 0 | L8: =ELEC!B10 -> 0
A9: Beirut | B9: =B8+1 -> 8 | C9: 6 | D9: 2021 | E9: =ELEC!M11 -> 0 | F9: =ELEC!K11 -> 0 | G9: =ELEC!I11 -> 0 | H9: =ELEC!AO11 -> 0 | I9: =ELEC!G11 -> 0 | J9: =WATER!Y13 -> 0 | K9: =WATER!AJ13 -> 0 | L9: =ELEC!B11 -> 0
A10: Beirut | B10: =B9+1 -> 9 | C10: 6 | D10: 2021 | E10: =ELEC!M12 -> 0 | F10: =ELEC!K12 -> 0 | G10: =ELEC!I12 -> 0 | H10: =ELEC!AO12 -> 0 | I10: =ELEC!G12 -> 0 | J10: =WATER!Y14 -> 0 | K10: =WATER!AJ14 -> 0 | L10: =ELEC!B12 -> 0
A11: Beirut | B11: =B10+1 -> 10 | C11: 6 | D11: 2021 | E11: =ELEC!M13 -> 0 | F11: =ELEC!K13 -> 0 | G11: =ELEC!I13 -> 0 | H11: =ELEC!AO13 -> 0 | I11: =ELEC!G13 -> 0 | J11: =WATER!Y15 -> 0 | K11: =WATER!AJ15 -> 0 | L11: =ELEC!B13 -> 0
A12: Beirut | B12: =B11+1 -> 11 | C12: 6 | D12: 2021 | E12: =ELEC!M14 -> 0 | F12: =ELEC!K14 -> 0 | G12: =ELEC!I14 -> 0 | H12: =ELEC!AO14 -> 0 | I12: =ELEC!G14 -> 0 | J12: =WATER!Y16 -> 0 | K12: =WATER!AJ16 -> 0 | L12: =ELEC!B14 -> 0
A13: Beirut | B13: =B12+1 -> 12 | C13: 6 | D13: 2021 | E13: =ELEC!M15 -> 0 | F13: =ELEC!K15 -> 0 | G13: =ELEC!I15 -> 0 | H13: =ELEC!AO15 -> 0 | I13: =ELEC!G15 -> 0 | J13: =WATER!Y17 -> 0 | K13: =WATER!AJ17 -> 0 | L13: =ELEC!B15 -> 0
A14: Beirut | B14: =B13+1 -> 13 | C14: 6 | D14: 2021 | E14: =ELEC!M16 -> 0 | F14: =ELEC!K16 -> 0 | G14: =ELEC!I16 -> 0 | H14: =ELEC!AO16 -> 0 | I14: =ELEC!G16 -> 0 | J14: =WATER!Y18 -> 0 | K14: =WATER!AJ18 -> 0 | L14: =ELEC!B16 -> 0
A15: Beirut | B15: =B14+1 -> 14 | C15: 6 | D15: 2021 | E15: =ELEC!M17 -> 0 | F15: =ELEC!K17 -> 0 | G15: =ELEC!I17 -> 0 | H15: =ELEC!AO17 -> 0 | I15: =ELEC!G17 -> 0 | J15: =WATER!Y19 -> 0 | K15: =WATER!AJ19 -> 0 | L15: =ELEC!B17 -> 0
A16: Beirut | B16: =B15+1 -> 15 | C16: 6 | D16: 2021 | E16: =ELEC!M18 -> 0 | F16: =ELEC!K18 -> 0 | G16: =ELEC!I18 -> 0 | H16: =ELEC!AO18 -> 0 | I16: =ELEC!G18 -> 0 | J16: =WATER!Y20 -> 0 | K16: =WATER!AJ20 -> 0 | L16: =ELEC!B18 -> 0
A17: Beirut | B17: =B16+1 -> 16 | C17: 6 | D17: 2021 | E17: =ELEC!M19 -> 0 | F17: =ELEC!K19 -> 0 | G17: =ELEC!I19 -> 0 | H17: =ELEC!AO19 -> 0 | I17: =ELEC!G19 -> 0 | J17: =WATER!Y21 -> 0 | K17: =WATER!AJ21 -> 0 | L17: =ELEC!B19 -> 0
A18: Beirut | B18: =B17+1 -> 17 | C18: 6 | D18: 2021 | E18: =ELEC!M20 -> 0 | F18: =ELEC!K20 -> 0 | G18: =ELEC!I20 -> 0 | H18: =ELEC!AO20 -> 0 | I18: =ELEC!G20 -> 0 | J18: =WATER!Y22 -> 0 | K18: =WATER!AJ22 -> 0 | L18: =ELEC!B20 -> 0
... A31: Beirut | B31: =B30+1 -> 30 | C31: 6 | D31: 2021 | E31: =ELEC!M33 -> 0 | F31: =ELEC!K33 -> 0 | G31: =ELEC!I33 -> 0 | H31: =ELEC!AO33 -> 0 | I31: =ELEC!G33 -> 0 | J31: =WATER!Y35 -> 0 | K31: =WATER!AJ35 -> 0 | L31: =ELEC!B33 -> 0
D45: .

Sheet ELEC
AK1: ATS 4 till power meter is for MDB 3 is replaced
A2: OOC | B2: Room OCC | D2: MDB3 | E2: MDB3/day | F2: EMDB2 | G2: EMDB2/day | H2: EMDB1 | I2: EMDB1/day | J2: MDB2 | K2: mdb2/day | L2: MDB1 | M2: MDB1/Day | N2: Total KWH | O2: KWH/Rooc | P2: Gen MHW | Q2: Gen/Day KWH | R2: EDL KWH | S2: CH1 RH | T2: RH | U2: C1h1 power | V2: CH1 Con KWH | W2: CH2 RH | X2: RH | Y2: Ch2 power | Z2: CH2 Con KWH | AA2: CH3 RH | AB2: RH | AC2: Ch3 power | AD2: CH3 Con KWH | AE2: RH total | AF2: KWH total | AG2: AVG chiller KW/Hr | AK2: Emergency | AL2: Normal | AM2: Total | AN2: Difference
A3: =[1]ELEC!$A$33 -> 0 | B3: =[1]ELEC!$B$33 -> 0 | C3: 44347 | D3: =[2]ELEC!D33 -> 32911138 | E3: =[2]ELEC!E33 -> 4709 | F3: =[2]ELEC!F33 -> 4031450 | G3: =[2]ELEC!G33 -> 1057 | H3: =[2]ELEC!H33 -> 17884320 | I3: =[2]ELEC!I33 -> 1442 | J3: =[2]ELEC!J33 -> 29123928 | K3: =[2]ELEC!K33 -> 9050 | ... AG3: =[2]ELEC!AG33 -> 236.41667 | AI3: -999706 | AK3: 44347 | AL3: =[3]ELEC!AL33 -> 333631 | AM3: =[3]ELEC!AM33 -> 431020 | AN3: =[3]ELEC!AN33 -> 764651 | AO3: =[3]ELEC!AO33 -> 4709
A4: ='General information '!F6 -> 0 | B4: =SUM(230*A4) -> 0 | C4: 44348 | D4: =D3 -> 32911138 | E4: =AO4 -> 2415 | F4: 4031925 | G4: =F4-F3 -> 475 | H4: 17885062 | I4: =H4-H3 -> 742 | J4: 29128686 | K4: =J4-J3 -> 4758 | L4: 24237542 | M4: =L4-L3 -> 1550 | N4: =M4+K4+I4+G4+E4 -> 9940 | O4: =IF(B4>0,N4/B4,0) -> 0 | P4: 17216.967 | Q4: =(P4-P3)*1000 -> 9515 | R4: =+N4-Q4 -> 425 | S4: =S3 -> 10175 | T4: =S4-S3 -> 0 | U4: =U3 -> 429166 | V4: =U4-U3 -> 0 | W4: 32562 | X4: =W4-W3 -> 20 | Y4: 775030 | Z4: =Y4-Y3 -> 4098 | AA4: =AA3 -> 35939 | AB4: =AA4-AA3 -> 0 | AC4: =AC3 -> 961645 | AD4: =AC4-AC3 -> 0 | AE4: =AB4+X4+T4 -> 20 | AF4: =V4+Z4+AD4 -> 4098 | AG4: =IF(AE4>0,AF4/AE4,0) -> 204.9 | AI4: =R4-'EDl log'!B4 -> -1057750 | AK4: 44348 | AL4: 335894 | AM4: 431172 | AN4: =AM4+AL4 -> 767066 | AO4: =AN4-AN3 -> 2415
A5: ='General information '!F7 -> 0 | B5: =SUM(230*A5) -> 0 | C5: 44349 | D5: =D4 -> 32911138 | E5: =AO5 -> 0 | F5: =F4 -> 4031925 | G5: =F5-F4 -> 0 | H5: =H4 -> 17885062 | I5: =H5-H4 -> 0 | J5: =J4 -> 29128686 | K5: =J5-J4 -> 0 | L5: =L4 -> 24237542 | M5: =L5-L4 -> 0 | N5: =M5+K5+I5+G5+E5 -> 0 | O5: =IF(B5>0,N5/B5,0) -> 0 | P5: =P4 -> 17216.967 | Q5: =(P5-P4)*1000 -> 0 | R5: =N5-Q5 -> 0 | S5: =S4 -> 10175 | T5: =S5-S4 -> 0 | U5: =U4 -> 429166 | V5: =U5-U4 -> 0 | W5: =W4 -> 32562 | X5: =W5-W4 -> 0 | Y5: =Y4 -> 775030 | Z5: =Y5-Y4 -> 0 | AA5: =AA4 -> 35939 | AB5: =AA5-AA4 -> 0 | AC5: =AC4 -> 961645 | AD5: =AC5-AC4 -> 0 | AE5: =AB5+X5+T5 -> 0 | AF5: =V5+Z5+AD5 -> 0 | AG5: =IF(AE5>0,AF5/AE5,0) -> 0 | AI5: =R5-'EDl log'!B5 -> -1058175 | AK5: 44349 | AL5: =AL4 -> 335894 | AM5: =AM4 -> 431172 | AN5: =AM5+AL5 -> 767066 | AO5: =AN5-AN4 -> 0
A6: ='General information '!F8 -> 0 | B6: =SUM(230*A6) -> 0 | C6: 44350 | D6: =D5 -> 32911138 | E6: =AO6 -> 0 | F6: =F5 -> 4031925 | G6: =F6-F5 -> 0 | H6: =H5 -> 17885062 | I6: =H6-H5 -> 0 | J6: =J5 -> 29128686 | K6: =J6-J5 -> 0 | L6: =L5 -> 24237542 | M6: =L6-L5 -> 0 | N6: =M6+K6+I6+G6+E6 -> 0 | O6: =IF(B6>0,N6/B6,0) -> 0 | P6: =P5 -> 17216.967 | Q6: =(P6-P5)*1000 -> 0 | R6: =N6-Q6 -> 0 | S6: =S5 -> 10175 | T6: =S6-S5 -> 0 | U6: =U5 -> 429166 | V6: =U6-U5 -> 0 | W6: =W5 -> 32562 | X6: =W6-W5 -> 0 | Y6: =Y5 -> 775030 | Z6: =Y6-Y5 -> 0 | AA6: =AA5 -> 35939 | AB6: =AA6-AA5 -> 0 | AC6: =AC5 -> 961645 | AD6: =AC6-AC5 -> 0 | AE6: =AB6+X6+T6 -> 0 | AF6: =V6+Z6+AD6 -> 0 | AG6: =IF(AE6>0,AF6/AE6,0) -> 0 | AI6: =R6-'EDl log'!B6 -> -1058175 | AK6: 44350 | AL6: =AL5 -> 335894 | AM6: =AM5 -> 431172 | AN6: =AM6+AL6 -> 767066 | AO6: =AN6-AN5 -> 0
A7: ='General information '!F9 -> 0 | B7: =SUM(230*A7) -> 0 | C7: 44351 | D7: =D6 -> 32911138 | E7: =AO7 -> 0 | F7: =F6 -> 4031925 | G7: =F7-F6 -> 0 | H7: =H6 -> 17885062 | I7: =H7-H6 -> 0 | J7: =J6 -> 29128686 | K7: =J7-J6 -> 0 | L7: =L6 -> 24237542 | M7: =L7-L6 -> 0 | N7: =M7+K7+I7+G7+E7 -> 0 | O7: =IF(B7>0,N7/B7,0) -> 0 | P7: =P6 -> 17216.967 | Q7: =(P7-P6)*1000 -> 0 | R7: =N7-Q7 -> 0 | S7: =S6 -> 10175 | T7: =S7-S6 -> 0 | U7: =U6 -> 429166 | V7: =U7-U6 -> 0 | W7: =W6 -> 32562 | X7: =W7-W6 -> 0 | Y7: =Y6 -> 775030 | Z7: =Y7-Y6 -> 0 | AA7: =AA6 -> 35939 | AB7: =AA7-AA6 -> 0 | AC7: =AC6 -> 961645 | AD7: =AC7-AC6 -> 0 | AE7: =AB7+X7+T7 -> 0 | AF7: =V7+Z7+AD7 -> 0 | AG7: =IF(AE7>0,AF7/AE7,0) -> 0 | AI7: =R7-'EDl log'!B7 -> -1058175 | AK7: 44351 | AL7: =AL6 -> 335894 | AM7: =AM6 -> 431172 | AN7: =AM7+AL7 -> 767066 | AO7: =AN7-AN6 -> 0
A8: ='General information '!F10 -> 0 | B8: =SUM(230*A8) -> 0 | C8: 44352 | D8: =D7 -> 32911138 | E8: =AO8 -> 0 | F8: =F7 -> 4031925 | G8: =F8-F7 -> 0 | H8: =H7 -> 17885062 | I8: =H8-H7 -> 0 | J8: =J7 -> 29128686 | K8: =J8-J7 -> 0 | L8: =L7 -> 24237542 | M8: =L8-L7 -> 0 | N8: =M8+K8+I8+G8+E8 -> 0 | O8: =IF(B8>0,N8/B8,0) -> 0 | P8: =P7 -> 17216.967 | Q8: =(P8-P7)*1000 -> 0 | R8: =N8-Q8 -> 0 | S8: =S7 -> 10175 | T8: =S8-S7 -> 0 | U8: =U7 -> 429166 | V8: =U8-U7 -> 0 | W8: =W7 -> 32562 | X8: =W8-W7 -> 0 | Y8: =Y7 -> 775030 | Z8: =Y8-Y7 -> 0 | AA8: =AA7 -> 35939 | AB8: =AA8-AA7 -> 0 | AC8: =AC7 -> 961645 | AD8: =AC8-AC7 -> 0 | AE8: =AB8+X8+T8 -> 0 | AF8: =V8+Z8+AD8 -> 0 | AG8: =IF(AE8>0,AF8/AE8,0) -> 0 | AI8: =R8-'EDl log'!B8 -> -1058175 | AK8: 44352 | AL8: =AL7 -> 335894 | AM8: =AM7 -> 431172 | AN8: =AM8+AL8 -> 767066 | AO8: =AN8-AN7 -> 0
A9: ='General information '!F11 -> 0 | B9: =SUM(230*A9) -> 0 | C9: 44353 | D9: =D8 -> 32911138 | E9: =AO9 -> 0 | F9: =F8 -> 4031925 | G9: =F9-F8 -> 0 | H9: =H8 -> 17885062 | I9: =H9-H8 -> 0 | J9: =J8 -> 29128686 | K9: =J9-J8 -> 0 | L9: =L8 -> 24237542 | M9: =L9-L8 -> 0 | N9: =M9+K9+I9+G9+E9 -> 0 | O9: =IF(B9>0,N9/B9,0) -> 0 | P9: =P8 -> 17216.967 | Q9: =(P9-P8)*1000 -> 0 | R9: =N9-Q9 -> 0 | S9: =S8 -> 10175 | T9: =S9-S8 -> 0 | U9: =U8 -> 429166 | V9: =U9-U8 -> 0 | W9: =W8 -> 32562 | X9: =W9-W8 -> 0 | Y9: =Y8 -> 775030 | Z9: =Y9-Y8 -> 0 | AA9: =AA8 -> 35939 | AB9: =AA9-AA8 -> 0 | AC9: =AC8 -> 961645 | AD9: =AC9-AC8 -> 0 | AE9: =AB9+X9+T9 -> 0 | AF9: =V9+Z9+AD9 -> 0 | AG9: =IF(AE9>0,AF9/AE9,0) -> 0 | AI9: =R9-'EDl log'!B9 -> -1058175 | AK9: 44353 | AL9: =AL8 -> 335894 | AM9: =AM8 -> 431172 | AN9: =AM9+AL9 -> 767066 | AO9: =AN9-AN8 -> 0
A10: ='General information '!F12 -> 0 | B10: =SUM(230*A10) -> 0 | C10: 44354 | D10: =D9 -> 32911138 | E10: =AO10 -> 0 | F10: =F9 -> 4031925 | G10: =F10-F9 -> 0 | H10: =H9 -> 17885062 | I10: =H10-H9 -> 0 | J10: =J9 -> 29128686 | K10: =J10-J9 -> 0 | L10: =L9 -> 24237542 | M10: =L10-L9 -> 0 | N10: =M10+K10+I10+G10+E10 -> 0 | O10: =IF(B10>0,N10/B10,0) -> 0 | P10: =P9 -> 17216.967 | Q10: =(P10-P9)*1000 -> 0 | R10: =N10-Q10 -> 0 | S10: =S9 -> 10175 | T10: =S10-S9 -> 0 | U10: =U9 -> 429166 | V10: =U10-U9 -> 0 | W10: =W9 -> 32562 | X10: =W10-W9 -> 0 | Y10: =Y9 -> 775030 | Z10: =Y10-Y9 -> 0 | AA10: =AA9 -> 35939 | AB10: =AA10-AA9 -> 0 | AC10: =AC9 -> 961645 | AD10: =AC10-AC9 -> 0 | AE10: =AB10+X10+T10 -> 0 | AF10: =V10+Z10+AD10 -> 0 | AG10: =IF(AE10>0,AF10/AE10,0) -> 0 | AI10: =R10-'EDl log'!B10 -> -1058175 | AK10: 44354 | AL10: =AL9 -> 335894 | AM10: =AM9 -> 431172 | AN10: =AM10+AL10 -> 767066 | AO10: =AN10-AN9 -> 0
A11: ='General information '!F13 -> 0 | B11: =SUM(230*A11) -> 0 | C11: 44355 | D11: =D10 -> 32911138 | E11: =AO11 -> 0 | F11: =F10 -> 4031925 | G11: =F11-F10 -> 0 | H11: =H10 -> 17885062 | I11: =H11-H10 -> 0 | J11: =J10 -> 29128686 | K11: =J11-J10 -> 0 | L11: =L10 -> 24237542 | M11: =L11-L10 -> 0 | N11: =M11+K11+I11+G11+E11 -> 0 | O11: =IF(B11>0,N11/B11,0) -> 0 | P11: =P10 -> 17216.967 | Q11: =(P11-P10)*1000 -> 0 | R11: =N11-Q11 -> 0 | S11: =S10 -> 10175 | T11: =S11-S10 -> 0 | U11: =U10 -> 429166 | V11: =U11-U10 -> 0 | W11: =W10 -> 32562 | X11: =W11-W10 -> 0 | Y11: =Y10 -> 775030 | Z11: =Y11-Y10 -> 0 | AA11: =AA10 -> 35939 | AB11: =AA11-AA10 -> 0 | AC11: =AC10 -> 961645 | AD11: =AC11-AC10 -> 0 | AE11: =AB11+X11+T11 -> 0 | AF11: =V11+Z11+AD11 -> 0 | AG11: =IF(AE11>0,AF11/AE11,0) -> 0 | AI11: =R11-'EDl log'!B11 -> -1058175 | AK11: 44355 | AL11: =AL10 -> 335894 | AM11: =AM10 -> 431172 | AN11: =AM11+AL11 -> 767066 | AO11: =AN11-AN10 -> 0
A12: ='General information '!F14 -> 0 | B12: =SUM(230*A12) -> 0 | C12: 44356 | D12: =D11 -> 32911138 | E12: =AO12 -> 0 | F12: =F11 -> 4031925 | G12: =F12-F11 -> 0 | H12: =H11 -> 17885062 | I12: =H12-H11 -> 0 | J12: =J11 -> 29128686 | K12: =J12-J11 -> 0 | L12: =L11 -> 24237542 | M12: =L12-L11 -> 0 | N12: =M12+K12+I12+G12+E12 -> 0 | O12: =IF(B12>0,N12/B12,0) -> 0 | P12: =P11 -> 17216.967 | Q12: =(P12-P11)*1000 -> 0 | R12: =N12-Q12 -> 0 | S12: =S11 -> 10175 | T12: =S12-S11 -> 0 | U12: =U11 -> 429166 | V12: =U12-U11 -> 0 | W12: =W11 -> 32562 | X12: =W12-W11 -> 0 | Y12: =Y11 -> 775030 | Z12: =Y12-Y11 -> 0 | AA12: =AA11 -> 35939 | AB12: =AA12-AA11 -> 0 | AC12: =AC11 -> 961645 | AD12: =AC12-AC11 -> 0 | AE12: =AB12+X12+T12 -> 0 | AF12: =V12+Z12+AD12 -> 0 | AG12: =IF(AE12>0,AF12/AE12,0) -> 0 | AI12: =R12-'EDl log'!B12 -> -1058175 | AK12: 44356 | AL12: =AL11 -> 335894 | AM12: =AM11 -> 431172 | AN12: =AM12+AL12 -> 767066 | AO12: =AN12-AN11 -> 0
A13: ='General information '!F15 -> 0 | B13: =SUM(230*A13) -> 0 | C13: 44357 | D13: =D12 -> 32911138 | E13: =AO13 -> 0 | F13: =F12 -> 4031925 | G13: =F13-F12 -> 0 | H13: =H12 -> 17885062 | I13: =H13-H12 -> 0 | J13: =J12 -> 29128686 | K13: =J13-J12 -> 0 | L13: =L12 -> 24237542 | M13: =L13-L12 -> 0 | N13: =M13+K13+I13+G13+E13 -> 0 | O13: =IF(B13>0,N13/B13,0) -> 0 | P13: =P12 -> 17216.967 | Q13: =(P13-P12)*1000 -> 0 | R13: =N13-Q13 -> 0 | S13: =S12 -> 10175 | T13: =S13-S12 -> 0 | U13: =U12 -> 429166 | V13: =U13-U12 -> 0 | W13: =W12 -> 32562 | X13: =W13-W12 -> 0 | Y13: =Y12 -> 775030 | Z13: =Y13-Y12 -> 0 | AA13: =AA12 -> 35939 | AB13: =AA13-AA12 -> 0 | AC13: =AC12 -> 961645 | AD13: =AC13-AC12 -> 0 | AE13: =AB13+X13+T13 -> 0 | AF13: =V13+Z13+AD13 -> 0 | AG13: =IF(AE13>0,AF13/AE13,0) -> 0 | AI13: =R13-'EDl log'!B13 -> -1058175 | AK13: 44357 | AL13: =AL12 -> 335894 | AM13: =AM12 -> 431172 | AN13: =AM13+AL13 -> 767066 | AO13: =AN13-AN12 -> 0
A14: ='General information '!F16 -> 0 | B14: =SUM(230*A14) -> 0 | C14: 44358 | D14: =D13 -> 32911138 | E14: =AO14 -> 0 | F14: =F13 -> 4031925 | G14: =F14-F13 -> 0 | H14: =H13 -> 17885062 | I14: =H14-H13 -> 0 | J14: =J13 -> 29128686 | K14: =J14-J13 -> 0 | L14: =L13 -> 24237542 | M14: =L14-L13 -> 0 | N14: =M14+K14+I14+G14+E14 -> 0 | O14: =IF(B14>0,N14/B14,0) -> 0 | P14: =P13 -> 17216.967 | Q14: =(P14-P13)*1000 -> 0 | R14: =N14-Q14 -> 0 | S14: =S13 -> 10175 | T14: =S14-S13 -> 0 | U14: =U13 -> 429166 | V14: =U14-U13 -> 0 | W14: =W13 -> 32562 | X14: =W14-W13 -> 0 | Y14: =Y13 -> 775030 | Z14: =Y14-Y13 -> 0 | AA14: =AA13 -> 35939 | AB14: =AA14-AA13 -> 0 | AC14: =AC13 -> 961645 | AD14: =AC14-AC13 -> 0 | AE14: =AB14+X14+T14 -> 0 | AF14: =V14+Z14+AD14 -> 0 | AG14: =IF(AE14>0,AF14/AE14,0) -> 0 | AI14: =R14-'EDl log'!B14 -> -1058175 | AK14: 44358 | AL14: =AL13 -> 335894 | AM14: =AM13 -> 431172 | AN14: =AM14+AL14 -> 767066 | AO14: =AN14-AN13 -> 0
A15: ='General information '!F17 -> 0 | B15: =SUM(230*A15) -> 0 | C15: 44359 | D15: =D14 -> 32911138 | E15: =AO15 -> 0 | F15: =F14 -> 4031925 | G15: =F15-F14 -> 0 | H15: =H14 -> 17885062 | I15: =H15-H14 -> 0 | J15: =J14 -> 29128686 | K15: =J15-J14 -> 0 | L15: =L14 -> 24237542 | M15: =L15-L14 -> 0 | N15: =M15+K15+I15+G15+E15 -> 0 | O15: =IF(B15>0,N15/B15,0) -> 0 | P15: =P14 -> 17216.967 | Q15: =(P15-P14)*1000 -> 0 | R15: =N15-Q15 -> 0 | S15: =S14 -> 10175 | T15: =S15-S14 -> 0 | U15: =U14 -> 429166 | V15: =U15-U14 -> 0 | W15: =W14 -> 32562 | X15: =W15-W14 -> 0 | Y15: =Y14 -> 775030 | Z15: =Y15-Y14 -> 0 | AA15: =AA14 -> 35939 | AB15: =AA15-AA14 -> 0 | AC15: =AC14 -> 961645 | AD15: =AC15-AC14 -> 0 | AE15: =AB15+X15+T15 -> 0 | AF15: =V15+Z15+AD15 -> 0 | AG15: =IF(AE15>0,AF15/AE15,0) -> 0 | AI15: =R15-'EDl log'!B15 -> -1058175 | AK15: 44359 | AL15: =AL14 -> 335894 | AM15: =AM14 -> 431172 | AN15: =AM15+AL15 -> 767066 | AO15: =AN15-AN14 -> 0
A16: ='General information '!F18 -> 0 | B16: =SUM(230*A16) -> 0 | C16: 44360 | D16: =D15 -> 32911138 | E16: =AO16 -> 0 | F16: =F15 -> 4031925 | G16: =F16-F15 -> 0 | H16: =H15 -> 17885062 | I16: =H16-H15 -> 0 | J16: =J15 -> 29128686 | K16: =J16-J15 -> 0 | L16: =L15 -> 24237542 | M16: =L16-L15 -> 0 | N16: =M16+K16+I16+G16+E16 -> 0 | O16: =IF(B16>0,N16/B16,0) -> 0 | P16: =P15 -> 17216.967 | Q16: =(P16-P15)*1000 -> 0 | R16: =N16-Q16 -> 0 | S16: =S15 -> 10175 | T16: =S16-S15 -> 0 | U16: =U15 -> 429166 | V16: =U16-U15 -> 0 | W16: =W15 -> 32562 | X16: =W16-W15 -> 0 | Y16: =Y15 -> 775030 | Z16: =Y16-Y15 -> 0 | AA16: =AA15 -> 35939 | AB16: =AA16-AA15 -> 0 | AC16: =AC15 -> 961645 | AD16: =AC16-AC15 -> 0 | AE16: =AB16+X16+T16 -> 0 | AF16: =V16+Z16+AD16 -> 0 | AG16: =IF(AE16>0,AF16/AE16,0) -> 0 | AI16: =R16-'EDl log'!B16 -> -1058175 | AK16: 44360 | AL16: =AL15 -> 335894 | AM16: =AM15 -> 431172 | AN16: =AM16+AL16 -> 767066 | AO16: =AN16-AN15 -> 0
... A33: ='General information '!F35 -> 0 | B33: =SUM(230*A33) -> 0 | C33: 44377 | D33: =D32 -> 32911138 | E33: =AO33 -> 0 | F33: =F32 -> 4031925 | G33: =F33-F32 -> 0 | H33: =H32 -> 17885062 | I33: =H33-H32 -> 0 | J33: =J32 -> 29128686 | K33: =J33-J32 -> 0 | L33: =L32 -> 24237542 | M33: =L33-L32 -> 0 | N33: =M33+K33+I33+G33+E33 -> 0 | O33: =IF(B33>0,N33/B33,0) -> 0 | P33: =P32 -> 17216.967 | Q33: =(P33-P32)*1000 -> 0 | R33: =N33-Q33 -> 0 | S33: =S32 -> 10175 | T33: =S33-S32 -> 0 | U33: =U32 -> 429166 | V33: =U33-U32 -> 0 | W33: =W32 -> 32562 | X33: =W33-W32 -> 0 | Y33: =Y32 -> 775030 | Z33: =Y33-Y32 -> 0 | AA33: =AA32 -> 35939 | AB33: =AA33-AA32 -> 0 | AC33: =AC32 -> 961645 | AD33: =AC33-AC32 -> 0 | AE33: =AB33+X33+T33 -> 0 | AF33: =V33+Z33+AD33 -> 0 | AG33: =IF(AE33>0,AF33/AE33,0) -> 0 | AI33: =R33-'EDl log'!B33 -> -1058175 | AK33: 44377 | AL33: =AL32 -> 335894 | AM33: =AM32 -> 431172 | AN33: =AM33+AL33 -> 767066 | AO33: =AN33-AN32 -> 0

Sheet B5
F1: Boiler A | J1: =J35 -> 1 | K1: Boiler B | P1: Boiler C | V1: Boiler | X1: SteamA | AC1: SteamB | AH1: Steam | AI1: Boiler & steam | AL1: Total Boiler Runing H | AM1: Total Steam Runing H | AN1: GAS1 % | AO1: GAS1/L | AP1: GAS2% | AQ1: Gas2/L | AR1: GAS3% | AS1: GAS3/L | AU1: Gas Cons | AV1: Delivery | AW1: Cost/L
B2: Level Tank Gen | C2: Level tank Boiler | D2: Daily Cons Bo. | E2: Boiler litter | F2: Boiler A | G2: Run Hr a | H2: Boiler A fuel | I2: Daily consumption | J2: AVG | K2: index Run H | L2: Run Hrb | M2: Boiler B Fuel | O2: Daily consumption | P2: Boiler C | S2: Run C | U2: Total RH | V2: Total Fuel | X2: SteamA | Y2: Run SA | Z2: Steam A Conter | AA2: Liters | AC2: SteamB | AD2: Run SteamB | AE2: Steam B Conter | AF2: SB Litters | AG2: Avg | AH2: Total Fuel | AI2: Total Fuel
S3: 0
A4: =ELEC!C3 -> 44347 | B4: =[2]B5!B35 -> 207 | C4: =[2]B5!C35 -> 214 | D4: =[2]B5!D35 -> -27 | E4: =[2]B5!E35 -> -226.26 | F4: =[2]B5!F35 -> 1841 | G4: =[2]B5!G35 -> 1 | H4: =[2]B5!H35 -> 13408 | I4: =[2]B5!I35 -> 96 | ... AX4: =[2]B5!AX35 -> 0.8
A5: =ELEC!C4 -> 44348 | B5: 191 | C5: 204 | D5: =C4-C5 -> 10 | E5: =D5*8.38 -> 83.8 | F5: =F4 -> 1841 | G5: =F5-F4 -> 0 | H5: =H4 -> 13408 | I5: =SUM(H5-H4) -> 0 | J5: 1 | K5: =K4 -> 2331 | L5: =K5-K4 -> 0 | M5: =M4 -> 171898 | N5: =M5-M4 -> 0 | O5: =O4 -> 1869 | P5: =P4 -> 2096 | Q5: =Q4 -> 176206 | R5: =Q5-Q4 -> 0 | S5: =SUM(P5-P4) -> 0 | T5: =SUM(S5*$T$2) -> 0 | U5: =SUM(G5+L5+S5) -> 0 | V5: =R5+N5+I5:I5 -> 0 | W5: =SUM(V5/U5) -> #DIV/0! | X5: =X4 -> 2469 | Y5: =X5-X4 -> 0 | Z5: =Z4 -> 138993 | AA5: =Z5-Z4 -> 0 | AB5: =SUM(Y5*$AB$2) -> 0 | AC5: =AC4 -> 1937 | AD5: =AC5-AC4 -> 0 | AE5: =AE4 -> 365590 | AF5: =AE5-AE4 -> 0 | AG5: =IF(AD5>0,AF5/AD5,0) -> 0 | AH5: =AF5+AA5 -> 0 | AI5: =SUM(AH5+V5) -> 0 | AJ5: =-tanks!AW6 -> 0 | AK5: =SUM(AJ5-AI5) -> 0 | AL5: =S5+L5+G5 -> 0 | AM5: =Y5+AD5 -> 0 | AN5: =AN4 -> 67 | AO5: =(AN5/100)*3000 -> 2010 | AP5: =AP4 -> 55 | AQ5: =(AP5/100)*3000 -> 1650 | AR5: =AR4 -> 61 | AS5: =(AR5/100)*3000 -> 1830 | AT5: =SUM(AO5+AQ5+AS5) -> 5490 | AU5: =AT4-AT5+AV5 -> 0 | AX5: =IF(AV5>0,AW5,AX4) -> 0.8
A6: =ELEC!C5 -> 44349 | B6: =B5 -> 191 | C6: =C5 -> 204 | D6: =C5-C6 -> 0 | E6: =D6*8.38 -> 0 | F6: =F5 -> 1841 | G6: =F6-F5 -> 0 | H6: =H5 -> 13408 | I6: =SUM(H6-H5) -> 0 | J6: =IF(G6>0,I6/G6,0) -> 0 | K6: =K5 -> 2331 | L6: =K6-K5 -> 0 | M6: =M5 -> 171898 | N6: =M6-M5 -> 0 | O6: =O5 -> 1869 | P6: =P5 -> 2096 | Q6: =Q5 -> 176206 | R6: =Q6-Q5 -> 0 | S6: =SUM(P6-P5) -> 0 | T6: =SUM(S6*$T$2) -> 0 | U6: =SUM(G6+L6+S6) -> 0 | V6: =R6+N6+I6:I6 -> 0 | W6: =SUM(V6/U6) -> #DIV/0! | X6: =X5 -> 2469 | Y6: =X6-X5 -> 0 | Z6: =Z5 -> 138993 | AA6: =Z6-Z5 -> 0 | AB6: =SUM(Y6*$AB$2) -> 0 | AC6: =AC5 -> 1937 | AD6: =AC6-AC5 -> 0 | AE6: =AE5 -> 365590 | AF6: =AE6-AE5 -> 0 | AG6: =IF(AD6>0,AF6/AD6,0) -> 0 | AH6: =AF6+AA6 -> 0 | AI6: =SUM(AH6+V6) -> 0 | AJ6: =-tanks!AW7 -> 0 | AK6: =SUM(AJ6-AI6) -> 0 | AL6: =S6+L6+G6 -> 0 | AM6: =Y6+AD6 -> 0 | AN6: =AN5 -> 67 | AO6: =(AN6/100)*3000 -> 2010 | AP6: =AP5 -> 55 | AQ6: =(AP6/100)*3000 -> 1650 | AR6: =AR5 -> 61 | AS6: =(AR6/100)*3000 -> 1830 | AT6: =SUM(AO6+AQ6+AS6) -> 5490 | AU6: =AT5-AT6+AV6 -> 0 | AX6: =IF(AV6>0,AW6,AX5) -> 0.8
A7: =ELEC!C6 -> 44350 | B7: =B6 -> 191 | C7: =C6 -> 204 | D7: =C6-C7 -> 0 | E7: =D7*8.38 -> 0 | F7: =F6 -> 1841 | G7: =F7-F6 -> 0 | H7: =H6 -> 13408 | I7: =SUM(H7-H6) -> 0 | J7: =IF(G7>0,I7/G7,0) -> 0 | K7: =K6 -> 2331 | L7: =K7-K6 -> 0 | M7: =M6 -> 171898 | N7: =M7-M6 -> 0 | O7: =O6 -> 1869 | P7: =P6 -> 2096 | Q7: =Q6 -> 176206 | R7: =Q7-Q6 -> 0 | S7: =SUM(P7-P6) -> 0 | T7: =SUM(S7*$T$2) -> 0 | U7: =SUM(G7+L7+S7) -> 0 | V7: =R7+N7+I7:I7 -> 0 | W7: =SUM(V7/U7) -> #DIV/0! | X7: =X6 -> 2469 | Y7: =X7-X6 -> 0 | Z7: =Z6 -> 138993 | AA7: =Z7-Z6 -> 0 | AB7: =SUM(Y7*$AB$2) -> 0 | AC7: =AC6 -> 1937 | AD7: =AC7-AC6 -> 0 | AE7: =AE6 -> 365590 | AF7: =AE7-AE6 -> 0 | AG7: =IF(AD7>0,AF7/AD7,0) -> 0 | AH7: =AF7+AA7 -> 0 | AI7: =SUM(AH7+V7) -> 0 | AJ7: =-tanks!AW8 -> 0 | AK7: =SUM(AJ7-AI7) -> 0 | AL7: =S7+L7+G7 -> 0 | AM7: =Y7+AD7 -> 0 | AN7: =AN6 -> 67 | AO7: =(AN7/100)*3000 -> 2010 | AP7: =AP6 -> 55 | AQ7: =(AP7/100)*3000 -> 1650 | AR7: =AR6 -> 61 | AS7: =(AR7/100)*3000 -> 1830 | AT7: =SUM(AO7+AQ7+AS7) -> 5490 | AU7: =AT6-AT7+AV7 -> 0 | AX7: =IF(AV7>0,AW7,AX6) -> 0.8
A8: =ELEC!C7 -> 44351 | B8: =B7 -> 191 | C8: =C7 -> 204 | D8: =C7-C8 -> 0 | E8: =D8*8.38 -> 0 | F8: =F7 -> 1841 | G8: =F8-F7 -> 0 | H8: =H7 -> 13408 | I8: =SUM(H8-H7) -> 0 | J8: =IF(G8>0,I8/G8,0) -> 0 | K8: =K7 -> 2331 | L8: =K8-K7 -> 0 | M8: =M7 -> 171898 | N8: =M8-M7 -> 0 | O8: =O7 -> 1869 | P8: =P7 -> 2096 | Q8: =Q7 -> 176206 | R8: =Q8-Q7 -> 0 | S8: =SUM(P8-P7) -> 0 | T8: =SUM(S8*$T$2) -> 0 | U8: =SUM(G8+L8+S8) -> 0 | V8: =R8+N8+I8:I8 -> 0 | W8: =SUM(V8/U8) -> #DIV/0! | X8: =X7 -> 2469 | Y8: =X8-X7 -> 0 | Z8: =Z7 -> 138993 | AA8: =Z8-Z7 -> 0 | AB8: =SUM(Y8*$AB$2) -> 0 | AC8: =AC7 -> 1937 | AD8: =AC8-AC7 -> 0 | AE8: =AE7 -> 365590 | AF8: =AE8-AE7 -> 0 | AG8: =IF(AD8>0,AF8/AD8,0) -> 0 | AH8: =AF8+AA8 -> 0 | AI8: =SUM(AH8+V8) -> 0 | AJ8: =-tanks!AW9 -> 0 | AK8: =SUM(AJ8-AI8) -> 0 | AL8: =S8+L8+G8 -> 0 | AM8: =Y8+AD8 -> 0 | AN8: =AN7 -> 67 | AO8: =(AN8/100)*3000 -> 2010 | AP8: =AP7 -> 55 | AQ8: =(AP8/100)*3000 -> 1650 | AR8: =AR7 -> 61 | AS8: =(AR8/100)*3000 -> 1830 | AT8: =SUM(AO8+AQ8+AS8) -> 5490 | AU8: =AT7-AT8+AV8 -> 0 | AX8: =IF(AV8>0,AW8,AX7) -> 0.8
A9: =ELEC!C8 -> 44352 | B9: =B8 -> 191 | C9: =C8 -> 204 | D9: =C8-C9 -> 0 | E9: =D9*8.38 -> 0 | F9: =F8 -> 1841 | G9: =F9-F8 -> 0 | H9: =H8 -> 13408 | I9: =SUM(H9-H8) -> 0 | J9: =IF(G9>0,I9/G9,0) -> 0 | K9: =K8 -> 2331 | L9: =K9-K8 -> 0 | M9: =M8 -> 171898 | N9: =M9-M8 -> 0 | O9: =O8 -> 1869 | P9: =P8 -> 2096 | Q9: =Q8 -> 176206 | R9: =Q9-Q8 -> 0 | S9: =SUM(P9-P8) -> 0 | T9: =SUM(S9*$T$2) -> 0 | U9: =SUM(G9+L9+S9) -> 0 | V9: =R9+N9+I9:I9 -> 0 | W9: =SUM(V9/U9) -> #DIV/0! | X9: =X8 -> 2469 | Y9: =X9-X8 -> 0 | Z9: =Z8 -> 138993 | AA9: =Z9-Z8 -> 0 | AB9: =SUM(Y9*$AB$2) -> 0 | AC9: =AC8 -> 1937 | AD9: =AC9-AC8 -> 0 | AE9: =AE8 -> 365590 | AF9: =AE9-AE8 -> 0 | AG9: =IF(AD9>0,AF9/AD9,0) -> 0 | AH9: =AF9+AA9 -> 0 | AI9: =SUM(AH9+V9) -> 0 | AJ9: =-tanks!AW10 -> 0 | AK9: =SUM(AJ9-AI9) -> 0 | AL9: =S9+L9+G9 -> 0 | AM9: =Y9+AD9 -> 0 | AN9: =AN8 -> 67 | AO9: =(AN9/100)*3000 -> 2010 | AP9: =AP8 -> 55 | AQ9: =(AP9/100)*3000 -> 1650 | AR9: =AR8 -> 61 | AS9: =(AR9/100)*3000 -> 1830 | AT9: =SUM(AO9+AQ9+AS9) -> 5490 | AU9: =AT8-AT9+AV9 -> 0 | AX9: =IF(AV9>0,AW9,AX8) -> 0.8
A10: =ELEC!C9 -> 44353 | B10: =B9 -> 191 | C10: =C9 -> 204 | D10: =C9-C10 -> 0 | E10: =D10*8.38 -> 0 | F10: =F9 -> 1841 | G10: =F10-F9 -> 0 | H10: =H9 -> 13408 | I10: =SUM(H10-H9) -> 0 | J10: =IF(G10>0,I10/G10,0) -> 0 | K10: =K9 -> 2331 | L10: =K10-K9 -> 0 | M10: =M9 -> 171898 | N10: =M10-M9 -> 0 | O10: =O9 -> 1869 | P10: =P9 -> 2096 | Q10: =Q9 -> 176206 | R10: =Q10-Q9 -> 0 | S10: =SUM(P10-P9) -> 0 | T10: =SUM(S10*$T$2) -> 0 | U10: =SUM(G10+L10+S10) -> 0 | V10: =R10+N10+I10:I10 -> 0 | W10: =SUM(V10/U10) -> #DIV/0! | X10: =X9 -> 2469 | Y10: =X10-X9 -> 0 | Z10: =Z9 -> 138993 | AA10: =Z10-Z9 -> 0 | AB10: =SUM(Y10*$AB$2) -> 0 | AC10: =AC9 -> 1937 | AD10: =AC10-AC9 -> 0 | AE10: =AE9 -> 365590 | AF10: =AE10-AE9 -> 0 | AG10: =IF(AD10>0,AF10/AD10,0) -> 0 | AH10: =AF10+AA10 -> 0 | AI10: =SUM(AH10+V10) -> 0 | AJ10: =-tanks!AW11 -> 0 | AK10: =SUM(AJ10-AI10) -> 0 | AL10: =S10+L10+G10 -> 0 | AM10: =Y10+AD10 -> 0 | AN10: =AN9 -> 67 | AO10: =(AN10/100)*3000 -> 2010 | AP10: =AP9 -> 55 | AQ10: =(AP10/100)*3000 -> 1650 | AR10: =AR9 -> 61 | AS10: =(AR10/100)*3000 -> 1830 | AT10: =SUM(AO10+AQ10+AS10) -> 5490 | AU10: =AT9-AT10+AV10 -> 0 | AX10: =IF(AV10>0,AW10,AX9) -> 0.8
A11: =ELEC!C10 -> 44354 | B11: =B10 -> 191 | C11: =C10 -> 204 | D11: =C10-C11 -> 0 | E11: =D11*8.38 -> 0 | F11: =F10 -> 1841 | G11: =F11-F10 -> 0 | H11: =H10 -> 13408 | I11: =SUM(H11-H10) -> 0 | J11: =IF(G11>0,I11/G11,0) -> 0 | K11: =K10 -> 2331 | L11: =K11-K10 -> 0 | M11: =M10 -> 171898 | N11: =M11-M10 -> 0 | O11: =O10 -> 1869 | P11: =P10 -> 2096 | Q11: =Q10 -> 176206 | R11: =Q11-Q10 -> 0 | S11: =SUM(P11-P10) -> 0 | T11: =SUM(S11*$T$2) -> 0 | U11: =SUM(G11+L11+S11) -> 0 | V11: =R11+N11+I11:I11 -> 0 | W11: =SUM(V11/U11) -> #DIV/0! | X11: =X10 -> 2469 | Y11: =X11-X10 -> 0 | Z11: =Z10 -> 138993 | AA11: =Z11-Z10 -> 0 | AB11: =SUM(Y11*$AB$2) -> 0 | AC11: =AC10 -> 1937 | AD11: =AC11-AC10 -> 0 | AE11: =AE10 -> 365590 | AF11: =AE11-AE10 -> 0 | AG11: =IF(AD11>0,AF11/AD11,0) -> 0 | AH11: =AF11+AA11 -> 0 | AI11: =SUM(AH11+V11) -> 0 | AJ11: =-tanks!AW12 -> 0 | AK11: =SUM(AJ11-AI11) -> 0 | AL11: =S11+L11+G11 -> 0 | AM11: =Y11+AD11 -> 0 | AN11: =AN10 -> 67 | AO11: =(AN11/100)*3000 -> 2010 | AP11: =AP10 -> 55 | AQ11: =(AP11/100)*3000 -> 1650 | AR11: =AR10 -> 61 | AS11: =(AR11/100)*3000 -> 1830 | AT11: =SUM(AO11+AQ11+AS11) -> 5490 | AU11: =AT10-AT11+AV11 -> 0 | AX11: =IF(AV11>0,AW11,AX10) -> 0.8
A12: =ELEC!C11 -> 44355 | B12: =B11 -> 191 | C12: =C11 -> 204 | D12: =C11-C12 -> 0 | E12: =D12*8.38 -> 0 | F12: =F11 -> 1841 | G12: =F12-F11 -> 0 | H12: =H11 -> 13408 | I12: =SUM(H12-H11) -> 0 | J12: =IF(G12>0,I12/G12,0) -> 0 | K12: =K11 -> 2331 | L12: =K12-K11 -> 0 | M12: =M11 -> 171898 | N12: =M12-M11 -> 0 | O12: =O11 -> 1869 | P12: =P11 -> 2096 | Q12: =Q11 -> 176206 | R12: =Q12-Q11 -> 0 | S12: =SUM(P12-P11) -> 0 | T12: =SUM(S12*$T$2) -> 0 | U12: =SUM(G12+L12+S12) -> 0 | V12: =R12+N12+I12:I12 -> 0 | W12: =SUM(V12/U12) -> #DIV/0! | X12: =X11 -> 2469 | Y12: =X12-X11 -> 0 | Z12: =Z11 -> 138993 | AA12: =Z12-Z11 -> 0 | AB12: =SUM(Y12*$AB$2) -> 0 | AC12: =AC11 -> 1937 | AD12: =AC12-AC11 -> 0 | AE12: =AE11 -> 365590 | AF12: =AE12-AE11 -> 0 | AG12: =IF(AD12>0,AF12/AD12,0) -> 0 | AH12: =AF12+AA12 -> 0 | AI12: =SUM(AH12+V12) -> 0 | AJ12: =-tanks!AW13 -> 0 | AK12: =SUM(AJ12-AI12) -> 0 | AL12: =S12+L12+G12 -> 0 | AM12: =Y12+AD12 -> 0 | AN12: =AN11 -> 67 | AO12: =(AN12/100)*3000 -> 2010 | AP12: =AP11 -> 55 | AQ12: =(AP12/100)*3000 -> 1650 | AR12: =AR11 -> 61 | AS12: =(AR12/100)*3000 -> 1830 | AT12: =SUM(AO12+AQ12+AS12) -> 5490 | AU12: =AT11-AT12+AV12 -> 0 | AX12: =IF(AV12>0,AW12,AX11) -> 0.8
A13: =ELEC!C12 -> 44356 | B13: =B12 -> 191 | C13: =C12 -> 204 | D13: =C12-C13 -> 0 | E13: =D13*8.38 -> 0 | F13: =F12 -> 1841 | G13: =F13-F12 -> 0 | H13: =H12 -> 13408 | I13: =SUM(H13-H12) -> 0 | J13: =IF(G13>0,I13/G13,0) -> 0 | K13: =K12 -> 2331 | L13: =K13-K12 -> 0 | M13: =M12 -> 171898 | N13: =M13-M12 -> 0 | O13: =O12 -> 1869 | P13: =P12 -> 2096 | Q13: =Q12 -> 176206 | R13: =Q13-Q12 -> 0 | S13: =SUM(P13-P12) -> 0 | T13: =SUM(S13*$T$2) -> 0 | U13: =SUM(G13+L13+S13) -> 0 | V13: =R13+N13+I13:I13 -> 0 | W13: =SUM(V13/U13) -> #DIV/0! | X13: =X12 -> 2469 | Y13: =X13-X12 -> 0 | Z13: =Z12 -> 138993 | AA13: =Z13-Z12 -> 0 | AB13: =SUM(Y13*$AB$2) -> 0 | AC13: =AC12 -> 1937 | AD13: =AC13-AC12 -> 0 | AE13: =AE12 -> 365590 | AF13: =AE13-AE12 -> 0 | AG13: =IF(AD13>0,AF13/AD13,0) -> 0 | AH13: =AF13+AA13 -> 0 | AI13: =SUM(AH13+V13) -> 0 | AJ13: =-tanks!AW14 -> 0 | AK13: =SUM(AJ13-AI13) -> 0 | AL13: =S13+L13+G13 -> 0 | AM13: =Y13+AD13 -> 0 | AN13: =AN12 -> 67 | AO13: =(AN13/100)*3000 -> 2010 | AP13: =AP12 -> 55 | AQ13: =(AP13/100)*3000 -> 1650 | AR13: =AR12 -> 61 | AS13: =(AR13/100)*3000 -> 1830 | AT13: =SUM(AO13+AQ13+AS13) -> 5490 | AU13: =AT12-AT13+AV13 -> 0 | AX13: =IF(AV13>0,AW13,AX12) -> 0.8
A14: =ELEC!C13 -> 44357 | B14: =B13 -> 191 | C14: =C13 -> 204 | D14: =C13-C14 -> 0 | E14: =D14*8.38 -> 0 | F14: =F13 -> 1841 | G14: =F14-F13 -> 0 | H14: =H13 -> 13408 | I14: =SUM(H14-H13) -> 0 | J14: =IF(G14>0,I14/G14,0) -> 0 | K14: =K13 -> 2331 | L14: =K14-K13 -> 0 | M14: =M13 -> 171898 | N14: =M14-M13 -> 0 | O14: =O13 -> 1869 | P14: =P13 -> 2096 | Q14: =Q13 -> 176206 | R14: =Q14-Q13 -> 0 | S14: =SUM(P14-P13) -> 0 | T14: =SUM(S14*$T$2) -> 0 | U14: =SUM(G14+L14+S14) -> 0 | V14: =R14+N14+I14:I14 -> 0 | W14: =SUM(V14/U14) -> #DIV/0! | X14: =X13 -> 2469 | Y14: =X14-X13 -> 0 | Z14: =Z13 -> 138993 | AA14: =Z14-Z13 -> 0 | AB14: =SUM(Y14*$AB$2) -> 0 | AC14: =AC13 -> 1937 | AD14: =AC14-AC13 -> 0 | AE14: =AE13 -> 365590 | AF14: =AE14-AE13 -> 0 | AG14: =IF(AD14>0,AF14/AD14,0) -> 0 | AH14: =AF14+AA14 -> 0 | AI14: =SUM(AH14+V14) -> 0 | AJ14: =-tanks!AW15 -> 0 | AK14: =SUM(AJ14-AI14) -> 0 | AL14: =S14+L14+G14 -> 0 | AM14: =Y14+AD14 -> 0 | AN14: =AN13 -> 67 | AO14: =(AN14/100)*3000 -> 2010 | AP14: =AP13 -> 55 | AQ14: =(AP14/100)*3000 -> 1650 | AR14: =AR13 -> 61 | AS14: =(AR14/100)*3000 -> 1830 | AT14: =SUM(AO14+AQ14+AS14) -> 5490 | AU14: =AT13-AT14+AV14 -> 0 | AX14: =IF(AV14>0,AW14,AX13) -> 0.8
A15: =ELEC!C14 -> 44358 | B15: =B14 -> 191 | C15: =C14 -> 204 | D15: =C14-C15 -> 0 | E15: =D15*8.38 -> 0 | F15: =F14 -> 1841 | G15: =F15-F14 -> 0 | H15: =H14 -> 13408 | I15: =SUM(H15-H14) -> 0 | J15: =IF(G15>0,I15/G15,0) -> 0 | K15: =K14 -> 2331 | L15: =K15-K14 -> 0 | M15: =M14 -> 171898 | N15: =M15-M14 -> 0 | O15: =O14 -> 1869 | P15: =P14 -> 2096 | Q15: =Q14 -> 176206 | R15: =Q15-Q14 -> 0 | S15: =SUM(P15-P14) -> 0 | T15: =SUM(S15*$T$2) -> 0 | U15: =SUM(G15+L15+S15) -> 0 | V15: =R15+N15+I15:I15 -> 0 | W15: =SUM(V15/U15) -> #DIV/0! | X15: =X14 -> 2469 | Y15: =X15-X14 -> 0 | Z15: =Z14 -> 138993 | AA15: =Z15-Z14 -> 0 | AB15: =SUM(Y15*$AB$2) -> 0 | AC15: =AC14 -> 1937 | AD15: =AC15-AC14 -> 0 | AE15: =AE14 -> 365590 | AF15: =AE15-AE14 -> 0 | AG15: =IF(AD15>0,AF15/AD15,0) -> 0 | AH15: =AF15+AA15 -> 0 | AI15: =SUM(AH15+V15) -> 0 | AJ15: =-tanks!AW16 -> 0 | AK15: =SUM(AJ15-AI15) -> 0 | AL15: =S15+L15+G15 -> 0 | AM15: =Y15+AD15 -> 0 | AN15: =AN14 -> 67 | AO15: =(AN15/100)*3000 -> 2010 | AP15: =AP14 -> 55 | AQ15: =(AP15/100)*3000 -> 1650 | AR15: =AR14 -> 61 | AS15: =(AR15/100)*3000 -> 1830 | AT15: =SUM(AO15+AQ15+AS15) -> 5490 | AU15: =AT14-AT15+AV15 -> 0 | AX15: =IF(AV15>0,AW15,AX14) -> 0.8
A16: =ELEC!C15 -> 44359 | B16: =B15 -> 191 | C16: =C15 -> 204 | D16: =C15-C16 -> 0 | E16: =D16*8.38 -> 0 | F16: =F15 -> 1841 | G16: =F16-F15 -> 0 | H16: =H15 -> 13408 | I16: =SUM(H16-H15) -> 0 | J16: =IF(G16>0,I16/G16,0) -> 0 | K16: =K15 -> 2331 | L16: =K16-K15 -> 0 | M16: =M15 -> 171898 | N16: =M16-M15 -> 0 | O16: =O15 -> 1869 | P16: =P15 -> 2096 | Q16: =Q15 -> 176206 | R16: =Q16-Q15 -> 0 | S16: =SUM(P16-P15) -> 0 | T16: =SUM(S16*$T$2) -> 0 | U16: =SUM(G16+L16+S16) -> 0 | V16: =R16+N16+I16:I16 -> 0 | W16: =SUM(V16/U16) -> #DIV/0! | X16: =X15 -> 2469 | Y16: =X16-X15 -> 0 | Z16: =Z15 -> 138993 | AA16: =Z16-Z15 -> 0 | AB16: =SUM(Y16*$AB$2) -> 0 | AC16: =AC15 -> 1937 | AD16: =AC16-AC15 -> 0 | AE16: =AE15 -> 365590 | AF16: =AE16-AE15 -> 0 | AG16: =IF(AD16>0,AF16/AD16,0) -> 0 | AH16: =AF16+AA16 -> 0 | AI16: =SUM(AH16+V16) -> 0 | AJ16: =-tanks!AW17 -> 0 | AK16: =SUM(AJ16-AI16) -> 0 | AL16: =S16+L16+G16 -> 0 | AM16: =Y16+AD16 -> 0 | AN16: =AN15 -> 67 | AO16: =(AN16/100)*3000 -> 2010 | AP16: =AP15 -> 55 | AQ16: =(AP16/100)*3000 -> 1650 | AR16: =AR15 -> 61 | AS16: =(AR16/100)*3000 -> 1830 | AT16: =SUM(AO16+AQ16+AS16) -> 5490 | AU16: =AT15-AT16+AV16 -> 0 | AX16: =IF(AV16>0,AW16,AX15) -> 0.8
A17: =ELEC!C16 -> 44360 | B17: =B16 -> 191 | C17: =C16 -> 204 | D17: =C16-C17 -> 0 | E17: =D17*8.38 -> 0 | F17: =F16 -> 1841 | G17: =F17-F16 -> 0 | H17: =H16 -> 13408 | I17: =SUM(H17-H16) -> 0 | J17: =IF(G17>0,I17/G17,0) -> 0 | K17: =K16 -> 2331 | L17: =K17-K16 -> 0 | M17: =M16 -> 171898 | N17: =M17-M16 -> 0 | O17: =O16 -> 1869 | P17: =P16 -> 2096 | Q17: =Q16 -> 176206 | R17: =Q17-Q16 -> 0 | S17: =SUM(P17-P16) -> 0 | T17: =SUM(S17*$T$2) -> 0 | U17: =SUM(G17+L17+S17) -> 0 | V17: =R17+N17+I17:I17 -> 0 | X17: =X16 -> 2469 | Y17: =X17-X16 -> 0 | Z17: =Z16 -> 138993 | AA17: =Z17-Z16 -> 0 | AB17: =SUM(Y17*$AB$2) -> 0 | AC17: =AC16 -> 1937 | AD17: =AC17-AC16 -> 0 | AE17: =AE16 -> 365590 | AF17: =AE17-AE16 -> 0 | AG17: =IF(AD17>0,AF17/AD17,0) -> 0 | AH17: =AF17+AA17 -> 0 | AI17: =SUM(AH17+V17) -> 0 | AJ17: =-tanks!AW18 -> 0 | AK17: =SUM(AJ17-AI17) -> 0 | AL17: =S17+L17+G17 -> 0 | AM17: =Y17+AD17 -> 0 | AN17: =AN16 -> 67 | AO17: =(AN17/100)*3000 -> 2010 | AP17: =AP16 -> 55 | AQ17: =(AP17/100)*3000 -> 1650 | AR17: =AR16 -> 61 | AS17: =(AR17/100)*3000 -> 1830 | AT17: =SUM(AO17+AQ17+AS17) -> 5490 | AU17: =AT16-AT17+AV17 -> 0 | AX17: =IF(AV17>0,AW17,AX16) -> 0.8
A18: =ELEC!C17 -> 44361 | B18: =B17 -> 191 | C18: =C17 -> 204 | D18: =C17-C18 -> 0 | E18: =D18*8.38 -> 0 | F18: =F17 -> 1841 | G18: =F18-F17 -> 0 | H18: =H17 -> 13408 | I18: =SUM(H18-H17) -> 0 | J18: =IF(G18>0,I18/G18,0) -> 0 | K18: =K17 -> 2331 | L18: =K18-K17 -> 0 | M18: =M17 -> 171898 | N18: =M18-M17 -> 0 | O18: 1869 | P18: =P17 -> 2096 | Q18: =Q17 -> 176206 | R18: =Q18-Q17 -> 0 | S18: =SUM(P18-P17) -> 0 | T18: =SUM(S18*$T$2) -> 0 | U18: =SUM(G18+L18+S18) -> 0 | V18: =R18+N18+I18:I18 -> 0 | X18: =X17 -> 2469 | Y18: =X18-X17 -> 0 | Z18: =Z17 -> 138993 | AA18: =Z18-Z17 -> 0 | AB18: =SUM(Y18*$AB$2) -> 0 | AC18: =AC17 -> 1937 | AD18: =AC18-AC17 -> 0 | AE18: =AE17 -> 365590 | AF18: =AE18-AE17 -> 0 | AG18: =IF(AD18>0,AF18/AD18,0) -> 0 | AH18: =AF18+AA18 -> 0 | AI18: =SUM(AH18+V18) -> 0 | AJ18: =-tanks!AW19 -> 0 | AK18: =SUM(AJ18-AI18) -> 0 | AL18: =S18+L18+G18 -> 0 | AM18: =Y18+AD18 -> 0 | AN18: =AN17 -> 67 | AO18: =(AN18/100)*3000 -> 2010 | AP18: =AP17 -> 55 | AQ18: =(AP18/100)*3000 -> 1650 | AR18: =AR17 -> 61 | AS18: =(AR18/100)*3000 -> 1830 | AT18: =SUM(AO18+AQ18+AS18) -> 5490 | AU18: =AT17-AT18+AV18 -> 0 | AX18: =IF(AV18>0,AW18,AX17) -> 0.8
A19: =ELEC!C18 -> 44362 | B19: =B18 -> 191 | C19: =C18 -> 204 | D19: =C18-C19 -> 0 | E19: =D19*8.38 -> 0 | F19: =F18 -> 1841 | G19: =F19-F18 -> 0 | H19: =H18 -> 13408 | I19: =SUM(H19-H18) -> 0 | J19: =IF(G19>0,I19/G19,0) -> 0 | K19: =K18 -> 2331 | L19: =K19-K18 -> 0 | M19: =M18 -> 171898 | N19: =M19-M18 -> 0 | O19: =O18 -> 1869 | P19: =P18 -> 2096 | Q19: =Q18 -> 176206 | R19: =Q19-Q18 -> 0 | S19: =SUM(P19-P18) -> 0 | T19: =SUM(S19*$T$2) -> 0 | U19: =SUM(G19+L19+S19) -> 0 | V19: =R19+N19+I19:I19 -> 0 | X19: =X18 -> 2469 | Y19: =X19-X18 -> 0 | Z19: =Z18 -> 138993 | AA19: =Z19-Z18 -> 0 | AB19: =SUM(Y19*$AB$2) -> 0 | AC19: =AC18 -> 1937 | AD19: =AC19-AC18 -> 0 | AE19: =AE18 -> 365590 | AF19: =AE19-AE18 -> 0 | AG19: =IF(AD19>0,AF19/AD19,0) -> 0 | AH19: =AF19+AA19 -> 0 | AI19: =SUM(AH19+V19) -> 0 | AJ19: =-tanks!AW20 -> 0 | AK19: =SUM(AJ19-AI19) -> 0 | AL19: =S19+L19+G19 -> 0 | AM19: =Y19+AD19 -> 0 | AN19: =AN18 -> 67 | AO19: =(AN19/100)*3000 -> 2010 | AP19: =AP18 -> 55 | AQ19: =(AP19/100)*3000 -> 1650 | AR19: =AR18 -> 61 | AS19: =(AR19/100)*3000 -> 1830 | AT19: =SUM(AO19+AQ19+AS19) -> 5490 | AU19: =AT18-AT19+AV19 -> 0 | AX19: =IF(AV19>0,AW19,AX18) -> 0.8
A20: =ELEC!C19 -> 44363 | B20: =B19 -> 191 | C20: =C19 -> 204 | D20: =C19-C20 -> 0 | E20: =D20*8.38 -> 0 | F20: =F19 -> 1841 | G20: =F20-F19 -> 0 | H20: =H19 -> 13408 | I20: =SUM(H20-H19) -> 0 | J20: =IF(G20>0,I20/G20,0) -> 0 | K20: =K19 -> 2331 | L20: =K20-K19 -> 0 | M20: =M19 -> 171898 | N20: =M20-M19 -> 0 | O20: =O19 -> 1869 | P20: =P19 -> 2096 | Q20: =Q19 -> 176206 | R20: =Q20-Q19 -> 0 | S20: =SUM(P20-P19) -> 0 | T20: =SUM(S20*$T$2) -> 0 | U20: =SUM(G20+L20+S20) -> 0 | V20: =R20+N20+I20:I20 -> 0 | X20: =X19 -> 2469 | Y20: =X20-X19 -> 0 | Z20: =Z19 -> 138993 | AA20: =Z20-Z19 -> 0 | AB20: =SUM(Y20*$AB$2) -> 0 | AC20: =AC19 -> 1937 | AD20: =AC20-AC19 -> 0 | AE20: =AE19 -> 365590 | AF20: =AE20-AE19 -> 0 | AG20: =IF(AD20>0,AF20/AD20,0) -> 0 | AH20: =AF20+AA20 -> 0 | AI20: =SUM(AH20+V20) -> 0 | AJ20: =-tanks!AW21 -> 0 | AK20: =SUM(AJ20-AI20) -> 0 | AL20: =S20+L20+G20 -> 0 | AM20: =Y20+AD20 -> 0 | AN20: =AN19 -> 67 | AO20: =(AN20/100)*3000 -> 2010 | AP20: =AP19 -> 55 | AQ20: =(AP20/100)*3000 -> 1650 | AR20: =AR19 -> 61 | AS20: =(AR20/100)*3000 -> 1830 | AT20: =SUM(AO20+AQ20+AS20) -> 5490 | AU20: =AT19-AT20+AV20 -> 0 | AX20: =IF(AV20>0,AW20,AX19) -> 0.8
A21: =ELEC!C20 -> 44364 | B21: =B20 -> 191 | C21: =C20 -> 204 | D21: =C20-C21 -> 0 | E21: =D21*8.38 -> 0 | F21: =F20 -> 1841 | G21: =F21-F20 -> 0 | H21: =H20 -> 13408 | I21: =SUM(H21-H20) -> 0 | J21: =IF(G21>0,I21/G21,0) -> 0 | K21: =K20 -> 2331 | L21: =K21-K20 -> 0 | M21: =M20 -> 171898 | N21: =M21-M20 -> 0 | O21: =O20 -> 1869 | P21: =P20 -> 2096 | Q21: =Q20 -> 176206 | R21: =Q21-Q20 -> 0 | S21: =SUM(P21-P20) -> 0 | T21: =SUM(S21*$T$2) -> 0 | U21: =SUM(G21+L21+S21) -> 0 | V21: =R21+N21+I21:I21 -> 0 | X21: =X20 -> 2469 | Y21: =X21-X20 -> 0 | Z21: =Z20 -> 138993 | AA21: =Z21-Z20 -> 0 | AB21: =SUM(Y21*$AB$2) -> 0 | AC21: =AC20 -> 1937 | AD21: =AC21-AC20 -> 0 | AE21: =AE20 -> 365590 | AF21: =AE21-AE20 -> 0 | AG21: =IF(AD21>0,AF21/AD21,0) -> 0 | AH21: =AF21+AA21 -> 0 | AI21: =SUM(AH21+V21) -> 0 | AJ21: =-tanks!AW22 -> 0 | AK21: =SUM(AJ21-AI21) -> 0 | AL21: =S21+L21+G21 -> 0 | AM21: =Y21+AD21 -> 0 | AN21: =AN20 -> 67 | AO21: =(AN21/100)*3000 -> 2010 | AP21: =AP20 -> 55 | AQ21: =(AP21/100)*3000 -> 1650 | AR21: =AR20 -> 61 | AS21: =(AR21/100)*3000 -> 1830 | AT21: =SUM(AO21+AQ21+AS21) -> 5490 | AU21: =AT20-AT21+AV21 -> 0 | AX21: =IF(AV21>0,AW21,AX20) -> 0.8
A22: =ELEC!C21 -> 44365 | B22: =B21 -> 191 | C22: =C21 -> 204 | D22: =C21-C22 -> 0 | E22: =D22*8.38 -> 0 | F22: =F21 -> 1841 | G22: =F22-F21 -> 0 | H22: =H21 -> 13408 | I22: =SUM(H22-H21) -> 0 | J22: =IF(G22>0,I22/G22,0) -> 0 | K22: =K21 -> 2331 | L22: =K22-K21 -> 0 | M22: =M21 -> 171898 | N22: =M22-M21 -> 0 | O22: =O21 -> 1869 | P22: =P21 -> 2096 | Q22: =Q21 -> 176206 | R22: =Q22-Q21 -> 0 | S22: =SUM(P22-P21) -> 0 | T22: =SUM(S22*$T$2) -> 0 | U22: =SUM(G22+L22+S22) -> 0 | V22: =R22+N22+I22:I22 -> 0 | X22: =X21 -> 2469 | Y22: =X22-X21 -> 0 | Z22: =Z21 -> 138993 | AA22: =Z22-Z21 -> 0 | AB22: =SUM(Y22*$AB$2) -> 0 | AC22: =AC21 -> 1937 | AD22: =AC22-AC21 -> 0 | AE22: =AE21 -> 365590 | AF22: =AE22-AE21 -> 0 | AG22: =IF(AD22>0,AF22/AD22,0) -> 0 | AH22: =AF22+AA22 -> 0 | AI22: =SUM(AH22+V22) -> 0 | AJ22: =-tanks!AW23 -> 0 | AK22: =SUM(AJ22-AI22) -> 0 | AL22: =S22+L22+G22 -> 0 | AM22: =Y22+AD22 -> 0 | AN22: =AN21 -> 67 | AO22: =(AN22/100)*3000 -> 2010 | AP22: =AP21 -> 55 | AQ22: =(AP22/100)*3000 -> 1650 | AR22: =AR21 -> 61 | AS22: =(AR22/100)*3000 -> 1830 | AT22: =SUM(AO22+AQ22+AS22) -> 5490 | AU22: =AT21-AT22+AV22 -> 0 | AX22: =IF(AV22>0,AW22,AX21) -> 0.8
A23: =ELEC!C22 -> 44366 | B23: =B22 -> 191 | C23: =C22 -> 204 | D23: =C22-C23 -> 0 | E23: =D23*8.38 -> 0 | F23: =F22 -> 1841 | G23: =F23-F22 -> 0 | H23: =H22 -> 13408 | I23: =SUM(H23-H22) -> 0 | J23: =IF(G23>0,I23/G23,0) -> 0 | K23: =K22 -> 2331 | L23: =K23-K22 -> 0 | M23: =M22 -> 171898 | N23: =M23-M22 -> 0 | O23: =O22 -> 1869 | P23: =P22 -> 2096 | Q23: =Q22 -> 176206 | R23: =Q23-Q22 -> 0 | S23: =SUM(P23-P22) -> 0 | T23: =SUM(S23*$T$2) -> 0 | U23: =SUM(G23+L23+S23) -> 0 | V23: =R23+N23+I23:I23 -> 0 | X23: =X22 -> 2469 | Y23: =X23-X22 -> 0 | Z23: =Z22 -> 138993 | AA23: =Z23-Z22 -> 0 | AB23: =SUM(Y23*$AB$2) -> 0 | AC23: =AC22 -> 1937 | AD23: =AC23-AC22 -> 0 | AE23: =AE22 -> 365590 | AF23: =AE23-AE22 -> 0 | AG23: =IF(AD23>0,AF23/AD23,0) -> 0 | AH23: =AF23+AA23 -> 0 | AI23: =SUM(AH23+V23) -> 0 | AJ23: =-tanks!AW24 -> 0 | AK23: =SUM(AJ23-AI23) -> 0 | AL23: =S23+L23+G23 -> 0 | AM23: =Y23+AD23 -> 0 | AN23: =AN22 -> 67 | AO23: =(AN23/100)*3000 -> 2010 | AP23: =AP22 -> 55 | AQ23: =(AP23/100)*3000 -> 1650 | AR23: =AR22 -> 61 | AS23: =(AR23/100)*3000 -> 1830 | AT23: =SUM(AO23+AQ23+AS23) -> 5490 | AU23: =AT22-AT23+AV23 -> 0 | AX23: =IF(AV23>0,AW23,AX22) -> 0.8
A24: =ELEC!C23 -> 44367 | B24: =B23 -> 191 | C24: =C23 -> 204 | D24: =C23-C24 -> 0 | E24: =D24*8.38 -> 0 | F24: =F23 -> 1841 | G24: =F24-F23 -> 0 | H24: =H23 -> 13408 | I24: =SUM(H24-H23) -> 0 | J24: =IF(G24>0,I24/G24,0) -> 0 | K24: =K23 -> 2331 | L24: =K24-K23 -> 0 | M24: =M23 -> 171898 | N24: =M24-M23 -> 0 | O24: =O23 -> 1869 | P24: =P23 -> 2096 | Q24: =Q23 -> 176206 | R24: =Q24-Q23 -> 0 | S24: =SUM(P24-P23) -> 0 | T24: =SUM(S24*$T$2) -> 0 | U24: =SUM(G24+L24+S24) -> 0 | V24: =R24+N24+I24:I24 -> 0 | X24: =X23 -> 2469 | Y24: =X24-X23 -> 0 | Z24: =Z23 -> 138993 | AA24: =Z24-Z23 -> 0 | AB24: =SUM(Y24*$AB$2) -> 0 | AC24: =AC23 -> 1937 | AD24: =AC24-AC23 -> 0 | AE24: =AE23 -> 365590 | AF24: =AE24-AE23 -> 0 | AG24: =IF(AD24>0,AF24/AD24,0) -> 0 | AH24: =AF24+AA24 -> 0 | AI24: =SUM(AH24+V24) -> 0 | AJ24: =-tanks!AW25 -> 0 | AK24: =SUM(AJ24-AI24) -> 0 | AL24: =S24+L24+G24 -> 0 | AM24: =Y24+AD24 -> 0 | AN24: =AN23 -> 67 | AO24: =(AN24/100)*3000 -> 2010 | AP24: =AP23 -> 55 | AQ24: =(AP24/100)*3000 -> 1650 | AR24: =AR23 -> 61 | AS24: =(AR24/100)*3000 -> 1830 | AT24: =SUM(AO24+AQ24+AS24) -> 5490 | AU24: =AT23-AT24+AV24 -> 0 | AX24: =IF(AV24>0,AW24,AX23) -> 0.8
A25: =ELEC!C24 -> 44368 | B25: =B24 -> 191 | C25: =C24 -> 204 | D25: =C24-C25 -> 0 | E25: =D25*8.38 -> 0 | F25: =F24 -> 1841 | G25: =F25-F24 -> 0 | H25: =H24 -> 13408 | I25: =SUM(H25-H24) -> 0 | J25: =IF(G25>0,I25/G25,0) -> 0 | K25: =K24 -> 2331 | L25: =K25-K24 -> 0 | M25: =M24 -> 171898 | N25: =M25-M24 -> 0 | O25: =O24 -> 1869 | P25: =P24 -> 2096 | Q25: =Q24 -> 176206 | R25: =Q25-Q24 -> 0 | S25: =SUM(P25-P24) -> 0 | T25: =SUM(S25*$T$2) -> 0 | U25: =SUM(G25+L25+S25) -> 0 | V25: =R25+N25+I25:I25 -> 0 | X25: =X24 -> 2469 | Y25: =X25-X24 -> 0 | Z25: =Z24 -> 138993 | AA25: =Z25-Z24 -> 0 | AB25: =SUM(Y25*$AB$2) -> 0 | AC25: =AC24 -> 1937 | AD25: =AC25-AC24 -> 0 | AE25: =AE24 -> 365590 | AF25: =AE25-AE24 -> 0 | AG25: =IF(AD25>0,AF25/AD25,0) -> 0 | AH25: =AF25+AA25 -> 0 | AI25: =SUM(AH25+V25) -> 0 | AJ25: =-tanks!AW26 -> 0 | AK25: =SUM(AJ25-AI25) -> 0 | AL25: =S25+L25+G25 -> 0 | AM25: =Y25+AD25 -> 0 | AN25: =AN24 -> 67 | AO25: =(AN25/100)*3000 -> 2010 | AP25: =AP24 -> 55 | AQ25: =(AP25/100)*3000 -> 1650 | AR25: =AR24 -> 61 | AS25: =(AR25/100)*3000 -> 1830 | AT25: =SUM(AO25+AQ25+AS25) -> 5490 | AU25: =AT24-AT25+AV25 -> 0 | AX25: =IF(AV25>0,AW25,AX24) -> 0.8
A26: =ELEC!C25 -> 44369 | B26: =B25 -> 191 | C26: =C25 -> 204 | D26: =C25-C26 -> 0 | E26: =D26*8.38 -> 0 | F26: =F25 -> 1841 | G26: =F26-F25 -> 0 | H26: =H25 -> 13408 | I26: =SUM(H26-H25) -> 0 | J26: =IF(G26>0,I26/G26,0) -> 0 | K26: =K25 -> 2331 | L26: =K26-K25 -> 0 | M26: =M25 -> 171898 | N26: =M26-M25 -> 0 | O26: =O25 -> 1869 | P26: =P25 -> 2096 | Q26: =Q25 -> 176206 | R26: =Q26-Q25 -> 0 | S26: =SUM(P26-P25) -> 0 | T26: =SUM(S26*$T$2) -> 0 | U26: =SUM(G26+L26+S26) -> 0 | V26: =R26+N26+I26:I26 -> 0 | X26: =X25 -> 2469 | Y26: =X26-X25 -> 0 | Z26: =Z25 -> 138993 | AA26: =Z26-Z25 -> 0 | AB26: =SUM(Y26*$AB$2) -> 0 | AC26: =AC25 -> 1937 | AD26: =AC26-AC25 -> 0 | AE26: =AE25 -> 365590 | AF26: =AE26-AE25 -> 0 | AG26: =IF(AD26>0,AF26/AD26,0) -> 0 | AH26: =AF26+AA26 -> 0 | AI26: =SUM(AH26+V26) -> 0 | AJ26: =-tanks!AW27 -> 0 | AK26: =SUM(AJ26-AI26) -> 0 | AL26: =S26+L26+G26 -> 0 | AM26: =Y26+AD26 -> 0 | AN26: =AN25 -> 67 | AO26: =(AN26/100)*3000 -> 2010 | AP26: =AP25 -> 55 | AQ26: =(AP26/100)*3000 -> 1650 | AR26: =AR25 -> 61 | AS26: =(AR26/100)*3000 -> 1830 | AT26: =SUM(AO26+AQ26+AS26) -> 5490 | AU26: =AT25-AT26+AV26 -> 0 | AX26: =IF(AV26>0,AW26,AX25) -> 0.8
A27: =ELEC!C26 -> 44370 | B27: =B26 -> 191 | C27: =C26 -> 204 | D27: =C26-C27 -> 0 | E27: =D27*8.38 -> 0 | F27: =F26 -> 1841 | G27: =F27-F26 -> 0 | H27: =H26 -> 13408 | I27: =SUM(H27-H26) -> 0 | J27: =IF(G27>0,I27/G27,0) -> 0 | K27: =K26 -> 2331 | L27: =K27-K26 -> 0 | M27: =M26 -> 171898 | N27: =M27-M26 -> 0 | O27: =O26 -> 1869 | P27: =P26 -> 2096 | Q27: =Q26 -> 176206 | R27: =Q27-Q26 -> 0 | S27: =SUM(P27-P26) -> 0 | T27: =SUM(S27*$T$2) -> 0 | U27: =SUM(G27+L27+S27) -> 0 | V27: =R27+N27+I27:I27 -> 0 | X27: =X26 -> 2469 | Y27: =X27-X26 -> 0 | Z27: =Z26 -> 138993 | AA27: =Z27-Z26 -> 0 | AB27: =SUM(Y27*$AB$2) -> 0 | AC27: =AC26 -> 1937 | AD27: =AC27-AC26 -> 0 | AE27: =AE26 -> 365590 | AF27: =AE27-AE26 -> 0 | AG27: =IF(AD27>0,AF27/AD27,0) -> 0 | AH27: =AF27+AA27 -> 0 | AI27: =SUM(AH27+V27) -> 0 | AJ27: =-tanks!AW28 -> 0 | AK27: =SUM(AJ27-AI27) -> 0 | AL27: =S27+L27+G27 -> 0 | AM27: =Y27+AD27 -> 0 | AN27: =AN26 -> 67 | AO27: =(AN27/100)*3000 -> 2010 | AP27: =AP26 -> 55 | AQ27: =(AP27/100)*3000 -> 1650 | AR27: =AR26 -> 61 | AS27: =(AR27/100)*3000 -> 1830 | AT27: =SUM(AO27+AQ27+AS27) -> 5490 | AU27: =AT26-AT27+AV27 -> 0 | AX27: =IF(AV27>0,AW27,AX26) -> 0.8
A28: =ELEC!C27 -> 44371 | B28: =B27 -> 191 | C28: =C27 -> 204 | D28: =C27-C28 -> 0 | E28: =D28*8.38 -> 0 | F28: =F27 -> 1841 | G28: =F28-F27 -> 0 | H28: =H27 -> 13408 | I28: =SUM(H28-H27) -> 0 | J28: =IF(G28>0,I28/G28,0) -> 0 | K28: =K27 -> 2331 | L28: =K28-K27 -> 0 | M28: =M27 -> 171898 | N28: =M28-M27 -> 0 | O28: =O27 -> 1869 | P28: =P27 -> 2096 | Q28: =Q27 -> 176206 | R28: =Q28-Q27 -> 0 | S28: =SUM(P28-P27) -> 0 | T28: =SUM(S28*$T$2) -> 0 | U28: =SUM(G28+L28+S28) -> 0 | V28: =R28+N28+I28:I28 -> 0 | X28: =X27 -> 2469 | Y28: =X28-X27 -> 0 | Z28: =Z27 -> 138993 | AA28: =Z28-Z27 -> 0 | AB28: =SUM(Y28*$AB$2) -> 0 | AC28: =AC27 -> 1937 | AD28: =AC28-AC27 -> 0 | AE28: =AE27 -> 365590 | AF28: =AE28-AE27 -> 0 | AG28: =IF(AD28>0,AF28/AD28,0) -> 0 | AH28: =AF28+AA28 -> 0 | AI28: =SUM(AH28+V28) -> 0 | AJ28: =-tanks!AW29 -> 0 | AK28: =SUM(AJ28-AI28) -> 0 | AL28: =S28+L28+G28 -> 0 | AM28: =Y28+AD28 -> 0 | AN28: =AN27 -> 67 | AO28: =(AN28/100)*3000 -> 2010 | AP28: =AP27 -> 55 | AQ28: =(AP28/100)*3000 -> 1650 | AR28: =AR27 -> 61 | AS28: =(AR28/100)*3000 -> 1830 | AT28: =SUM(AO28+AQ28+AS28) -> 5490 | AU28: =AT27-AT28+AV28 -> 0 | AX28: =IF(AV28>0,AW28,AX27) -> 0.8
A29: =ELEC!C28 -> 44372 | B29: =B28 -> 191 | C29: =C28 -> 204 | D29: =C28-C29 -> 0 | E29: =D29*8.38 -> 0 | F29: =F28 -> 1841 | G29: =F29-F28 -> 0 | H29: =H28 -> 13408 | I29: =SUM(H29-H28) -> 0 | J29: =IF(G29>0,I29/G29,0) -> 0 | K29: =K28 -> 2331 | L29: =K29-K28 -> 0 | M29: =M28 -> 171898 | N29: =M29-M28 -> 0 | O29: =O28 -> 1869 | P29: =P28 -> 2096 | Q29: =Q28 -> 176206 | R29: =Q29-Q28 -> 0 | S29: =SUM(P29-P28) -> 0 | T29: =SUM(S29*$T$2) -> 0 | U29: =SUM(G29+L29+S29) -> 0 | V29: =R29+N29+I29:I29 -> 0 | X29: =X28 -> 2469 | Y29: =X29-X28 -> 0 | Z29: =Z28 -> 138993 | AA29: =Z29-Z28 -> 0 | AB29: =SUM(Y29*$AB$2) -> 0 | AC29: =AC28 -> 1937 | AD29: =AC29-AC28 -> 0 | AE29: =AE28 -> 365590 | AF29: =AE29-AE28 -> 0 | AG29: =IF(AD29>0,AF29/AD29,0) -> 0 | AH29: =AF29+AA29 -> 0 | AI29: =SUM(AH29+V29) -> 0 | AJ29: =-tanks!AW30 -> 0 | AK29: =SUM(AJ29-AI29) -> 0 | AL29: =S29+L29+G29 -> 0 | AM29: =Y29+AD29 -> 0 | AN29: =AN28 -> 67 | AO29: =(AN29/100)*3000 -> 2010 | AP29: =AP28 -> 55 | AQ29: =(AP29/100)*3000 -> 1650 | AR29: =AR28 -> 61 | AS29: =(AR29/100)*3000 -> 1830 | AT29: =SUM(AO29+AQ29+AS29) -> 5490 | AU29: =AT28-AT29+AV29 -> 0 | AX29: =IF(AV29>0,AW29,AX28) -> 0.8
A30: =ELEC!C29 -> 44373 | B30: =B29 -> 191 | C30: =C29 -> 204 | D30: =C29-C30 -> 0 | E30: =D30*8.38 -> 0 | F30: =F29 -> 1841 | G30: =F30-F29 -> 0 | H30: =H29 -> 13408 | I30: =SUM(H30-H29) -> 0 | J30: =IF(G30>0,I30/G30,0) -> 0 | K30: =K29 -> 2331 | L30: =K30-K29 -> 0 | M30: =M29 -> 171898 | N30: =M30-M29 -> 0 | O30: =O29 -> 1869 | P30: =P29 -> 2096 | Q30: =Q29 -> 176206 | R30: =Q30-Q29 -> 0 | S30: =SUM(P30-P29) -> 0 | T30: =SUM(S30*$T$2) -> 0 | U30: =SUM(G30+L30+S30) -> 0 | V30: =R30+N30+I30:I30 -> 0 | X30: =X29 -> 2469 | Y30: =X30-X29 -> 0 | Z30: =Z29 -> 138993 | AA30: =Z30-Z29 -> 0 | AB30: =SUM(Y30*$AB$2) -> 0 | AC30: =AC29 -> 1937 | AD30: =AC30-AC29 -> 0 | AE30: =AE29 -> 365590 | AF30: =AE30-AE29 -> 0 | AG30: =IF(AD30>0,AF30/AD30,0) -> 0 | AH30: =AF30+AA30 -> 0 | AI30: =SUM(AH30+V30) -> 0 | AJ30: =-tanks!AW31 -> 0 | AK30: =SUM(AJ30-AI30) -> 0 | AL30: =S30+L30+G30 -> 0 | AM30: =Y30+AD30 -> 0 | AN30: =AN29 -> 67 | AO30: =(AN30/100)*3000 -> 2010 | AP30: =AP29 -> 55 | AQ30: =(AP30/100)*3000 -> 1650 | AR30: =AR29 -> 61 | AS30: =(AR30/100)*3000 -> 1830 | AT30: =SUM(AO30+AQ30+AS30) -> 5490 | AU30: =AT29-AT30+AV30 -> 0 | AX30: =IF(AV30>0,AW30,AX29) -> 0.8
... A34: =ELEC!C33 -> 44377 | B34: =B33 -> 191 | C34: =C33 -> 204 | D34: =C33-C34 -> 0 | E34: =D34*8.38 -> 0 | F34: =F33 -> 1841 | G34: =F34-F33 -> 0 | H34: =H33 -> 13408 | I34: =SUM(H34-H33) -> 0 | J34: =IF(G34>0,I34/G34,0) -> 0 | K34: =K33 -> 2331 | L34: =K34-K33 -> 0 | M34: =M33 -> 171898 | N34: =M34-M33 -> 0 | O34: =O33 -> 1869 | P34: =P33 -> 2096 | Q34: =Q33 -> 176206 | R34: =Q34-Q33 -> 0 | S34: =SUM(P34-P33) -> 0 | T34: =SUM(S34*$T$2) -> 0 | U34: =SUM(G34+L34+S34) -> 0 | V34: =R34+N34+I34:I34 -> 0 | X34: =X33 -> 2469 | Y34: =X34-X33 -> 0 | Z34: =Z33 -> 138993 | AA34: =Z34-Z33 -> 0 | AB34: =SUM(Y34*$AB$2) -> 0 | AC34: =AC33 -> 1937 | AD34: =AC34-AC33 -> 0 | AE34: =AE33 -> 365590 | AF34: =AE34-AE33 -> 0 | AG34: =IF(AD34>0,AF34/AD34,0) -> 0 | AH34: =AF34+AA34 -> 0 | AI34: =SUM(AH34+V34) -> 0 | AJ34: =-tanks!AW35 -> 0 | AK34: =SUM(AJ34-AI34) -> 0 | AL34: =S34+L34+G34 -> 0 | AM34: =Y34+AD34 -> 0 | AN34: =AN33 -> 67 | AO34: =(AN34/100)*3000 -> 2010 | AP34: =AP33 -> 55 | AQ34: =(AP34/100)*3000 -> 1650 | AR34: =AR33 -> 61 | AS34: =(AR34/100)*3000 -> 1830 | AT34: =SUM(AO34+AQ34+AS34) -> 5490 | AU34: =AT33-AT34+AV34 -> 0 | AX34: =IF(AV34>0,AW34,AX33) -> 0.8
J35: =SUM(J5:J32)/(COUNT(J5:J32)-COUNTIF(J5:J32,0)) -> 1 | V35: =SUM(V5:V34) -> 0 | AE35: . | AH35: =SUM(AH5:AH34) -> 0 | AL35: =SUM(AL5:AL34) -> 0 | AM35: =SUM(AM5:AM34) -> 0 | AR35: Nb Delivery | AS35: =COUNT(AW5:AW32) -> 0 | AU35: =SUM(AU5:AU32) -> 0 | AV35: =SUM(AV5:AV32) -> 0 | AW35: =SUM(AW5:AW32)/AS35 -> #DIV/0!
AH36: =AF36+AA36 -> 0 | AI36: =SUM(AI5:AI34) -> 0
AH37: =AF37+AA37 -> 0 | AU37: =AU35*0.51 -> 0 | AV37: =AV35/0.51 -> 0 | AW37: =SUM(AW5:AW32)/AS35 -> #DIV/0!
AV38: =AV35*0.51 -> 0

Sheet WATER
D1: =SUM(G21:G33) -> 8065473 | AR1: Entrance | AT1: Tank 1 | AV1: Tank 2
AR2: Level | AW2: Quantity CM3 | AZ2: Var
A3: Date | B3: Truck | C3: Truck M3/day | D3: N0. Trucks | F3: REQ. # of trucks | G3: City | H3: City/day | I3: Total water delivery | K3: SW | L3: Cosum SW/day | M3: RO Guest/ Liter | O3: RO K&L/ Liter | Q3: TOTAL RO Production | R3: RO 1 RH | S3: RO 2 RH | T3: RO water counter | U3: RO Cons m3 | V3: Steam Boiler | W3: Steam Boiler/day | X3: Softener Guest | Y3: Guest Sotf/day | Z3: Softener K&L | AA3: K&L Soft/Day | AB3: Fire Tank Level | AC3: Fire Tank Counter | AE3: Laundry Hot Water Counter | AF3: Hot Water Cons/day | AG3: Laundry Cold Water Counter | AH3: Cold Water Cons/day | AI3: Laundry Water Total Cons | AJ3: K&L Sotf/day | AK3: Guest / day | AL3: K&L /day | AM3: Avg Outside Temp | AN3: Banquet Activity | AR3: Date | AT3: MainI | AV3: Kitchen and Laundry | AX3: Guest | AY3: Main Tank | AZ3: Kitchen and Laundry | BA3: Guest | BB3: Kitchen and Laundry | BC3: Main | BD3: Guest | BE3: Total VAR | BF3: Hotel Consumption
E4: 1.66 | AN4: Ball R | AO4: Meeting | AP4: outlet | AT4: 180 | AV4: 220 | AX4: 580 | AY4: =SUM(AT4) -> 180 | AZ4: =SUM(AV4) -> 220 | BA4: =SUM(AX4) -> 580
A5: 44347 | B5: =[2]WATER!B36 -> 109443 | C5: =[2]WATER!C36 -> 0 | D5: =[2]WATER!D36 -> 0 | E5: =[2]WATER!E36 -> 241.93548 | F5: =[2]WATER!F36 -> 0 | G5: =[2]WATER!G36 -> 620421 | H5: =[2]WATER!H36 -> 148 | I5: =[2]WATER!I36 -> 148 | ... AP5: =[2]WATER!AP36 -> 0 | AR5: =[2]WATER!$AR$36 -> 44347 | AS5: =[2]WATER!AS36 -> 0.9 | AT5: =[2]WATER!AT36 -> 156 | AU5: =[2]WATER!AU36 -> 1.1 | AV5: =[2]WATER!AV36 -> 162 | AW5: =[2]WATER!AW36 -> 2.9 | AX5: =[2]WATER!AX36 -> 106 | AY5: =[2]WATER!AY36 -> 140.4 | AZ5: =[2]WATER!AZ36 -> 178.2 | ... BG5: =[2]WATER!BG36 -> 0
A6: =ELEC!C4 -> 44348 | B6: =B5 -> 109443 | C6: =B6-B5 -> 0 | D6: =C6/27 -> 0 | E6: =SUM((C6*$E$4)+(7500/'EDl log'!$A$37)) -> 250 | G6: =G5 -> 620421 | H6: =G6-G5 -> 0 | I6: =C6+H6 -> 0 | J6: =IF(I6>0,E6/I6,0) -> 0 | K6: ='Swimming Pool quality check '!H6 -> 6775 | L6: 0 | M6: =M5 -> 457.44 | N6: =SUM(M6-M5) -> 0 | O6: =O5 -> 529.52 | P6: =SUM(O6-O5) -> 0 | Q6: =P6+N6 -> 0 | T6: 5172 | U6: =SUM(T6-T5) -> 1 | V6: =V5 -> 474 | W6: =+V6-V5 -> 0 | X6: =X5 -> 152036 | Y6: =SUM(X6-X5) -> 0 | Z6: =Z5 -> 98847 | AA6: =Z6-Z5 -> 0 | AB6: =AB5 -> 261 | AC6: =AC5 -> 731 | AD6: 0 | AE6: =AE5 -> 229.81 | AF6: =AE6-AE5 -> 0 | AG6: =AG5 -> 2205.98 | AH6: =AG6-AG5 -> 0 | AI6: =AF6+AH6 -> 0 | AJ6: =+Z6-Z5 -> 0 | AK6: =SUM(Y6-L6) -> 0 | AL6: =SUM(AJ6-W6) -> 0 | AM6: ='General information '!D6 -> 24 | AN6: ='General information '!H6 -> 0 | AP6: ='General information '!J6 -> 0 | AR6: =A6 -> 44348 | AS6: =AS5 -> 0.9 | AT6: 90 | AU6: =AU5 -> 1.1 | AV6: 159 | AW6: 2.9 | AX6: 97 | AY6: =AS6*AT6 -> 81 | AZ6: =AU6*AV6 -> 174.9 | BA6: =AW6*AX6 -> 281.3 | BB6: =AY6-AY5 -> -59.4 | BC6: =AZ6-AZ5 -> -3.3 | BD6: =BA6-BA5 -> -26.1 | BE6: =SUM(BB6:BD6) -> -88.8 | BF6: =SUM(I6-BE6) -> 88.8 | BG6: =SUM(I6-BF6) -> -88.8
A7: =ELEC!C5 -> 44349 | B7: =B6 -> 109443 | C7: =B7-B6 -> 0 | D7: =C7/27 -> 0 | E7: =SUM((C7*$E$4)+(7500/'EDl log'!$A$37)) -> 250 | G7: =G6 -> 620421 | H7: =G7-G6 -> 0 | I7: =C7+H7 -> 0 | J7: =IF(I7>0,E7/I7,0) -> 0 | K7: ='Swimming Pool quality check '!H7 -> 6775 | L7: =K7-K6 -> 0 | M7: =M6 -> 457.44 | N7: =SUM(M7-M6) -> 0 | O7: =O6 -> 529.52 | P7: =SUM(O7-O6) -> 0 | Q7: =P7+N7 -> 0 | T7: =T6 -> 5172 | U7: =SUM(T7-T6) -> 0 | V7: =V6 -> 474 | W7: =+V7-V6 -> 0 | X7: =X6 -> 152036 | Y7: =SUM(X7-X6) -> 0 | Z7: =Z6 -> 98847 | AA7: =Z7-Z6 -> 0 | AB7: =AB6 -> 261 | AC7: =AC6 -> 731 | AD7: =AC7-AC6 -> 0 | AE7: =AE6 -> 229.81 | AF7: =AE7-AE6 -> 0 | AG7: =AG6 -> 2205.98 | AH7: =AG7-AG6 -> 0 | AI7: =AF7+AH7 -> 0 | AJ7: =+Z7-Z6 -> 0 | AK7: =SUM(Y7-L7) -> 0 | AL7: =SUM(AJ7-W7) -> 0 | AM7: ='General information '!D7 -> 0 | AN7: ='General information '!H7 -> 0 | AP7: ='General information '!J7 -> 0 | AR7: =A7 -> 44349 | AS7: =AS6 -> 0.9 | AT7: =AT6 -> 90 | AU7: =AU6 -> 1.1 | AV7: =AV6 -> 159 | AW7: 2.9 | AX7: =AX6 -> 97 | AY7: =AS7*AT7 -> 81 | AZ7: =AU7*AV7 -> 174.9 | BA7: =AW7*AX7 -> 281.3 | BB7: =AY7-AY6 -> 0 | BC7: =AZ7-AZ6 -> 0 | BD7: =BA7-BA6 -> 0 | BE7: =SUM(BB7:BD7) -> 0 | BF7: =SUM(I7-BE7) -> 0 | BG7: =SUM(I7-BF7) -> 0
