Workbook

Sheet TOTAL
A1: Site Name | B1: Day | C1: Month | D1: Year | E1: Total Electricity Kwh | F1: Electricity Tariff ($/Kwh) | G1: Natual Gas (m3) | H1: Natural Gas $/m3 | I1: Water Utility Supply (m3) m3 | J1: Water Utility Supply (m3) $/m3 | K1: Room Nights | L1: Total Guests | M1: Utilities day cost dh
A2: Mumbai | B2: 1 | C2: 6 | D2: 2021 | E2: =(IF('Daily HLP'!I4>0,'Daily HLP'!H4,0)) -> 16655 | F2: 9 | G2: =(IF('Daily HLP'!M4>0,'Daily HLP'!M4,0)) -> 267 | H2: 52 | I2: =(IF('Daily HLP'!P4>0,'Daily HLP'!P4,0)) -> 80 | J2: 118 | K2: =Occupancy!G2 -> 57 | L2: =Occupancy!F2 -> 57 | M2: =E2*F2+G2*H2+#REF!*#REF!+I2*J2 -> #REF!
A3: Mumbai | B3: =B2+1 -> 2 | C3: 6 | D3: 2021 | E3: =(IF('Daily HLP'!I5>0,'Daily HLP'!H5,0)) -> 16620.27 | F3: 9 | G3: =(IF('Daily HLP'!M5>0,'Daily HLP'!M5,0)) -> 436.7 | H3: 52 | I3: =(IF('Daily HLP'!P5>0,'Daily HLP'!P5,0)) -> 112 | J3: 118 | K3: =Occupancy!G3 -> 68 | L3: =Occupancy!F3 -> 69 | M3: =E3*F3+G3*H3+#REF!*#REF!+I3*J3 -> #REF!
A4: Mumbai | B4: =B3+1 -> 3 | C4: 6 | D4: 2021 | E4: =(IF('Daily HLP'!I6>0,'Daily HLP'!H6,0)) -> 16135.81 | F4: 9 | G4: =(IF('Daily HLP'!M6>0,'Daily HLP'!M6,0)) -> 615.804 | H4: 52 | I4: =(IF('Daily HLP'!P6>0,'Daily HLP'!P6,0)) -> 143 | J4: 118 | K4: =Occupancy!G4 -> 60 | L4: =Occupancy!F4 -> 97 | M4: =E4*F4+G4*H4+#REF!*#REF!+I4*J4 -> #REF!
A5: Mumbai | B5: =B4+1 -> 4 | C5: 6 | D5: 2021 | E5: =(IF('Daily HLP'!I7>0,'Daily HLP'!H7,0)) -> 16478.79 | F5: 9 | G5: =(IF('Daily HLP'!M7>0,'Daily HLP'!M7,0)) -> 302.904 | H5: 52 | I5: =(IF('Daily HLP'!P7>0,'Daily HLP'!P7,0)) -> 101 | J5: 118 | K5: =Occupancy!G5 -> 92 | L5: =Occupancy!F5 -> 209 | M5: =E5*F5+G5*H5+#REF!*#REF!+I5*J5 -> #REF!
A6: Mumbai | B6: =B5+1 -> 5 | C6: 6 | D6: 2021 | E6: =(IF('Daily HLP'!I8>0,'Daily HLP'!H8,0)) -> 20105.28 | F6: 9 | G6: =(IF('Daily HLP'!M8>0,'Daily HLP'!M8,0)) -> 453.902 | H6: 52 | I6: =(IF('Daily HLP'!P8>0,'Daily HLP'!P8,0)) -> 102 | J6: 118 | K6: =Occupancy!G6 -> 159 | L6: =Occupancy!F6 -> 433 | M6: =E6*F6+G6*H6+#REF!*#REF!+I6*J6 -> #REF!
A7: Mumbai | B7: =B6+1 -> 6 | C7: 6 | D7: 2021 | E7: =(IF('Daily HLP'!I9>0,'Daily HLP'!H9,0)) -> 18422.64 | F7: 9 | G7: =(IF('Daily HLP'!M9>0,'Daily HLP'!M9,0)) -> 556.87 | H7: 52 | I7: =(IF('Daily HLP'!P9>0,'Daily HLP'!P9,0)) -> 175 | J7: 118 | K7: =Occupancy!G7 -> 78 | L7: =Occupancy!F7 -> 220 | M7: =E7*F7+G7*H7+#REF!*#REF!+I7*J7 -> #REF!
A8: Mumbai | B8: =B7+1 -> 7 | C8: 6 | D8: 2021 | E8: =(IF('Daily HLP'!I10>0,'Daily HLP'!H10,0)) -> 17315.96 | F8: 9 | G8: =(IF('Daily HLP'!M10>0,'Daily HLP'!M10,0)) -> 563.65 | H8: 52 | I8: =(IF('Daily HLP'!P10>0,'Daily HLP'!P10,0)) -> 122 | J8: 118 | K8: =Occupancy!G8 -> 63 | L8: =Occupancy!F8 -> 115 | M8: =E8*F8+G8*H8+#REF!*#REF!+I8*J8 -> #REF!
A9: Mumbai | B9: =B8+1 -> 8 | C9: 6 | D9: 2021 | E9: =(IF('Daily HLP'!I11>0,'Daily HLP'!H11,0)) -> 17288.56 | F9: 9 | G9: =(IF('Daily HLP'!M11>0,'Daily HLP'!M11,0)) -> 406.12 | H9: 52 | I9: =(IF('Daily HLP'!P11>0,'Daily HLP'!P11,0)) -> 159 | J9: 118 | K9: =Occupancy!G9 -> 73 | L9: =Occupancy!F9 -> 140 | M9: =E9*F9+G9*H9+#REF!*#REF!+I9*J9 -> #REF!
A10: Mumbai | B10: =B9+1 -> 9 | C10: 6 | D10: 2021 | E10: =(IF('Daily HLP'!I12>0,'Daily HLP'!H12,0)) -> 16891.69 | F10: 9 | G10: =(IF('Daily HLP'!M12>0,'Daily HLP'!M12,0)) -> 345.05 | H10: 52 | I10: =(IF('Daily HLP'!P12>0,'Daily HLP'!P12,0)) -> 78 | J10: 118 | K10: =Occupancy!G10 -> 83 | L10: =Occupancy!F10 -> 159 | M10: =E10*F10+G10*H10+#REF!*#REF!+I10*J10 -> #REF!
A11: Mumbai | B11: =B10+1 -> 10 | C11: 6 | D11: 2021 | E11: =(IF('Daily HLP'!I13>0,'Daily HLP'!H13,0)) -> 17110 | F11: 9 | G11: =(IF('Daily HLP'!M13>0,'Daily HLP'!M13,0)) -> 665 | H11: 52 | I11: =(IF('Daily HLP'!P13>0,'Daily HLP'!P13,0)) -> 86 | J11: 118 | K11: =Occupancy!G11 -> 86 | L11: =Occupancy!F11 -> 182 | M11: =E11*F11+G11*H11+#REF!*#REF!+I11*J11 -> #REF!
A12: Mumbai | B12: =B11+1 -> 11 | C12: 6 | D12: 2021 | E12: =(IF('Daily HLP'!I14>0,'Daily HLP'!H14,0)) -> 17188 | F12: 9 | G12: =(IF('Daily HLP'!M14>0,'Daily HLP'!M14,0)) -> 498 | H12: 52 | I12: =(IF('Daily HLP'!P14>0,'Daily HLP'!P14,0)) -> 103 | J12: 118 | K12: =Occupancy!G12 -> 0 | L12: =Occupancy!F12 -> 0 | M12: =E12*F12+G12*H12+#REF!*#REF!+I12*J12 -> #REF!
A13: Mumbai | B13: =B12+1 -> 12 | C13: 6 | D13: 2021 | E13: =(IF('Daily HLP'!I15>0,'Daily HLP'!H15,0)) -> 18830 | F13: 9 | G13: =(IF('Daily HLP'!M15>0,'Daily HLP'!M15,0)) -> 460 | H13: 52 | I13: =(IF('Daily HLP'!P15>0,'Daily HLP'!P15,0)) -> 125 | J13: 118 | K13: =Occupancy!G13 -> 0 | L13: =Occupancy!F13 -> 0 | M13: =E13*F13+G13*H13+#REF!*#REF!+I13*J13 -> #REF!
A14: Mumbai | B14: =B13+1 -> 13 | C14: 6 | D14: 2021 | E14: =(IF('Daily HLP'!I16>0,'Daily HLP'!H16,0)) -> 20443 | F14: 9 | G14: =(IF('Daily HLP'!M16>0,'Daily HLP'!M16,0)) -> 737 | H14: 52 | I14: =(IF('Daily HLP'!P16>0,'Daily HLP'!P16,0)) -> 194 | J14: 118 | K14: =Occupancy!G14 -> 0 | L14: =Occupancy!F14 -> 0 | M14: =E14*F14+G14*H14+#REF!*#REF!+I14*J14 -> #REF!
... A31: Mumbai | B31: =B30+1 -> 30 | C31: 6 | D31: 2021 | E31: =(IF('Daily HLP'!I33>0,'Daily HLP'!H33,0)) -> 17150 | F31: 9 | G31: =(IF('Daily HLP'!M33>0,'Daily HLP'!M33,0)) -> 550 | H31: 52 | I31: =(IF('Daily HLP'!P33>0,'Daily HLP'!P33,0)) -> 138 | J31: 118 | K31: =Occupancy!G31 -> 0 | L31: =Occupancy!F31 -> 0 | M31: =E31*F31+G31*H31+#REF!*#REF!+I31*J31 -> #REF!
A32: Mumbai | B32: =B31+1 -> 31 | C32: 6 | D32: 2021 | E32: =(IF('Daily HLP'!I34>0,'Daily HLP'!H34,0)) -> 17150 | F32: 10 | G32: =(IF('Daily HLP'!M34>0,'Daily HLP'!M34,0)) -> 550 | H32: 52 | I32: =(IF('Daily HLP'!P34>0,'Daily HLP'!P34,0)) -> 121 | J32: 118 | K32: =Occupancy!G32 -> 0 | L32: =Occupancy!F32 -> 0

Sheet Submetering
A1: Site Name | B1: Day | C1: Month | D1: Year | E1: ='Section Load'!F4 -> HVAC | F1: ='Section Load'!G4 -> Fire & Emergency PP | G1: ='Section Load'!H4 -> Main PP | H1: ='Section Load'!I4 -> Lighting PP | I1: ='Section Load'!J4 -> CH-1+ CH2+CH3+CH4 | J1: ='Section Load'!K4 -> Chilled water Pump | K1: ='Section Load'!L4 -> Ball Room-1 | L1: ='Section Load'!M4 -> Ball Room-2 | ... AL1: ='Section Load'!AM4 -> Cooling Tower | AM1: R.o.plant | AN1: STP Water Prod | AO1: Domestic Zone-1 | AP1: Domestic Zone-2 | AQ1: Domestic Zone-3 | AR1: Flush Zone -1 | AS1: Flush Zone -2 | AT1: Flush Zone -3 | AU1: Swimming pool | AV1: B2 Laundry | AW1: Boiler Feed Water | AX1: cooling tower filling water | AY1: STP flush(new water meter) | AZ1: Garden Water Pump | BA1: Flush Zone 2 pump meter | BB1: Flush Zone 3 Pump Meter (wtp transfer ) | BC1: Flush Tanker-Zone-1 | BD1: Total Domestic Water (Tanker (R.O) +BMC) | BE1: Total Domestic Consumption | BF1: Total STP Consumption | BG1: ='Section Load'!AN4 -> MGL | BH1: ='Section Load'!AO4 -> HWG | BI1: ='Section Load'!AP4 -> Prato | BJ1: ='Section Load'!AQ4 -> BR-1 | BK1: ='Section Load'!AR4 -> SanQi IND | BL1: ='Section Load'!AS4 -> SanQi JPN | BM1: ='Section Load'!AT4 -> Boiler
A2: Mumbai | B2: 1 | C2: 6 | D2: 2021 | E2: =(IF('Section Load'!F5>0,'Section Load'!F5,0)) -> 2344 | F2: =(IF('Section Load'!G5>0,'Section Load'!G5,0)) -> 1278 | G2: =(IF('Section Load'!H5>0,'Section Load'!H5,0)) -> 1170 | H2: =(IF('Section Load'!I5>0,'Section Load'!I5,0)) -> 2546 | I2: =(IF('Section Load'!J5>0,'Section Load'!J5,0)) -> 5306.51 | J2: =(IF('Section Load'!K5>0,'Section Load'!K5,0)) -> 2272 | K2: =(IF('Section Load'!L5>0,'Section Load'!L5,0)) -> 814 | L2: =(IF('Section Load'!M5>0,'Section Load'!M5,0)) -> 446 | ... AL2: =(IF('Section Load'!AM5>0,'Section Load'!AM5,0)) -> 827 | AM2: =(IF('Water Report'!$D$7>0,'Water Report'!$D$7,0)) -> 18 | AN2: =(IF('Water Report'!$D$8>0,'Water Report'!$D$8,0)) -> 58 | AO2: =(IF('Water Report'!$D$9>0,'Water Report'!$D$9,0)) -> 40 | AP2: =(IF('Water Report'!$D$10>0,'Water Report'!$D$10,0)) -> 13 | AQ2: =(IF('Water Report'!$D$11>0,'Water Report'!$D$11,0)) -> 15 | AR2: =(IF('Water Report'!$D$13>0,'Water Report'!$D$13,0)) -> 7 | AS2: =(IF('Water Report'!$D$14>0,'Water Report'!$D$14,0)) -> 12 | AT2: =(IF('Water Report'!$D$15>0,'Water Report'!$D$15,0)) -> 5 | AU2: =(IF('Water Report'!$D$17>0,'Water Report'!$D$17,0)) -> 0 | AV2: =(IF('Water Report'!$D$18>0,'Water Report'!$D$18,0)) -> 0 | AW2: =(IF('Water Report'!$D$19>0,'Water Report'!$D$19,0)) -> 0 | AX2: =(IF('Water Report'!$D$21>0,'Water Report'!$D$21,0)) -> 63 | AY2: =(IF('Water Report'!$D$22>0,'Water Report'!$D$22,0)) -> 0 | AZ2: =(IF('Water Report'!$D$23>0,'Water Report'!$D$23,0)) -> 16 | BA2: =(IF('Water Report'!$D$14>0,'Water Report'!$D$14,0)) -> 12 | BB2: =(IF('Water Report'!$D$15>0,'Water Report'!$D$15,0)) -> 5 | BC2: =(IF('Water Report'!$D$13>0,'Water Report'!$D$13,0)) -> 7 | BD2: =(IF('Water Report'!$D$24>0,'Water Report'!$D$24,0)) -> 80 | BE2: =(IF('Water Report'!$D$25>0,'Water Report'!$D$25,0)) -> 85 | BF2: =(IF('Water Report'!$D$27>0,'Water Report'!$D$27,0)) -> 86 | BG2: =(IF('Section Load'!AN5>0,'Section Load'!AN5,0)) -> 267 | BH2: =(IF('Section Load'!AO5>0,'Section Load'!AO5,0)) -> 175 | BI2: =(IF('Section Load'!AP5>0,'Section Load'!AP5,0)) -> 0 | BJ2: =(IF('Section Load'!AQ5>0,'Section Load'!AQ5,0)) -> 52 | BK2: =(IF('Section Load'!AR5>0,'Section Load'!AR5,0)) -> 0 | BL2: =(IF('Section Load'!AS5>0,'Section Load'!AS5,0)) -> 0 | BM2: =(IF('Section Load'!AT5>0,'Section Load'!AT5,0)) -> 40
A3: Mumbai | B3: =B2+1 -> 2 | C3: 6 | D3: 2021 | E3: =(IF('Section Load'!F6>0,'Section Load'!F6,0)) -> 2408.12 | F3: =(IF('Section Load'!G6>0,'Section Load'!G6,0)) -> 1249.57 | G3: =(IF('Section Load'!H6>0,'Section Load'!H6,0)) -> 1246.69 | H3: =(IF('Section Load'!I6>0,'Section Load'!I6,0)) -> 2516.56 | I3: =(IF('Section Load'!J6>0,'Section Load'!J6,0)) -> 4924.37 | J3: =(IF('Section Load'!K6>0,'Section Load'!K6,0)) -> 2270.4 | K3: =(IF('Section Load'!L6>0,'Section Load'!L6,0)) -> 854.71 | L3: =(IF('Section Load'!M6>0,'Section Load'!M6,0)) -> 488.123 | ... AL3: =(IF('Section Load'!AM6>0,'Section Load'!AM6,0)) -> 821 | AM3: =(IF('Water Report'!$E$7>0,'Water Report'!$E$7,0)) -> 42 | AN3: =(IF('Water Report'!$E$8>0,'Water Report'!$E$8,0)) -> 61 | AO3: =(IF('Water Report'!$E$9>0,'Water Report'!$E$9,0)) -> 36 | AP3: =(IF('Water Report'!$E$10>0,'Water Report'!$E$10,0)) -> 9 | AQ3: =(IF('Water Report'!$E$11>0,'Water Report'!$E$11,0)) -> 10 | AR3: =(IF('Water Report'!$E$13>0,'Water Report'!$E$13,0)) -> 4 | AS3: =(IF('Water Report'!$E$14>0,'Water Report'!$E$14,0)) -> 37 | AT3: =(IF('Water Report'!$E$15>0,'Water Report'!$E$15,0)) -> 3 | AU3: =(IF('Water Report'!$E$17>0,'Water Report'!$E$17,0)) -> 0 | AV3: =(IF('Water Report'!$E$18>0,'Water Report'!$E$18,0)) -> 0 | AW3: =(IF('Water Report'!$E$19>0,'Water Report'!$E$19,0)) -> 3 | AX3: =(IF('Water Report'!$E$21>0,'Water Report'!$E$21,0)) -> 42 | AY3: =(IF('Water Report'!$E$22>0,'Water Report'!$E$22,0)) -> 0 | AZ3: =(IF('Water Report'!$E$23>0,'Water Report'!$E$23,0)) -> 0 | BA3: =(IF('Water Report'!$E$14>0,'Water Report'!$E$14,0)) -> 37 | BB3: =(IF('Water Report'!$E$15>0,'Water Report'!$E$15,0)) -> 3 | BC3: =(IF('Water Report'!$E$13>0,'Water Report'!$E$13,0)) -> 4 | BD3: =(IF('Water Report'!$E$24>0,'Water Report'!$E$24,0)) -> 112 | BE3: =(IF('Water Report'!$E$25>0,'Water Report'!$E$25,0)) -> 95 | BF3: =(IF('Water Report'!$E$27>0,'Water Report'!$E$27,0)) -> 46 | BG3: =(IF('Section Load'!AN6>0,'Section Load'!AN6,0)) -> 436.7 | BH3: =(IF('Section Load'!AO6>0,'Section Load'!AO6,0)) -> 170.85 | BI3: =(IF('Section Load'!AP6>0,'Section Load'!AP6,0)) -> 0 | BJ3: =(IF('Section Load'!AQ6>0,'Section Load'!AQ6,0)) -> 63.33 | BK3: =(IF('Section Load'!AR6>0,'Section Load'!AR6,0)) -> 0.2 | BL3: =(IF('Section Load'!AS6>0,'Section Load'!AS6,0)) -> 0 | BM3: =(IF('Section Load'!AT6>0,'Section Load'!AT6,0)) -> 202.62
A4: Mumbai | B4: =B3+1 -> 3 | C4: 6 | D4: 2021 | E4: =(IF('Section Load'!F7>0,'Section Load'!F7,0)) -> 2425.2 | F4: =(IF('Section Load'!G7>0,'Section Load'!G7,0)) -> 1251.05 | G4: =(IF('Section Load'!H7>0,'Section Load'!H7,0)) -> 1277.9 | H4: =(IF('Section Load'!I7>0,'Section Load'!I7,0)) -> 2426.52 | I4: =(IF('Section Load'!J7>0,'Section Load'!J7,0)) -> 4328.24 | J4: =(IF('Section Load'!K7>0,'Section Load'!K7,0)) -> 2314.3 | K4: =(IF('Section Load'!L7>0,'Section Load'!L7,0)) -> 869.24 | L4: =(IF('Section Load'!M7>0,'Section Load'!M7,0)) -> 475.357 | ... AL4: =(IF('Section Load'!AM7>0,'Section Load'!AM7,0)) -> 756 | AM4: =(IF('Water Report'!$F$7>0,'Water Report'!$F$7,0)) -> 56 | AN4: =(IF('Water Report'!$F$8>0,'Water Report'!$F$8,0)) -> 99 | AO4: =(IF('Water Report'!$F$9>0,'Water Report'!$G$9,0)) -> 27 | AP4: =(IF('Water Report'!$F$10>0,'Water Report'!$F$10,0)) -> 10 | AQ4: =(IF('Water Report'!$F$11>0,'Water Report'!$F$11,0)) -> 11 | AR4: =(IF('Water Report'!$F$13>0,'Water Report'!$F$13,0)) -> 7 | AS4: =(IF('Water Report'!$F$14>0,'Water Report'!$F$14,0)) -> 23 | AT4: =(IF('Water Report'!$F$15>0,'Water Report'!$F$15,0)) -> 3 | AU4: =(IF('Water Report'!$F$17>0,'Water Report'!$F$17,0)) -> 0 | AV4: =(IF('Water Report'!$F$18>0,'Water Report'!$F$18,0)) -> 13 | AW4: =(IF('Water Report'!$F$19>0,'Water Report'!$F$19,0)) -> 0 | AX4: =(IF('Water Report'!$F$21>0,'Water Report'!$F$21,0)) -> 87 | AY4: =(IF('Water Report'!$F$22>0,'Water Report'!$F$22,0)) -> 0 | AZ4: =(IF('Water Report'!$F$23>0,'Water Report'!$F$23,0)) -> 14 | BA4: =(IF('Water Report'!$F$14>0,'Water Report'!$F$14,0)) -> 23 | BB4: =(IF('Water Report'!$F$15>0,'Water Report'!$F$15,0)) -> 3 | BC4: =(IF('Water Report'!$F$13>0,'Water Report'!$F$13,0)) -> 7 | BD4: =(IF('Water Report'!$F$24>0,'Water Report'!$F$24,0)) -> 143 | BE4: =(IF('Water Report'!$F$25>0,'Water Report'!$F$25,0)) -> 118 | BF4: =(IF('Water Report'!$F$27>0,'Water Report'!$F$27,0)) -> 108 | BG4: =(IF('Section Load'!AN7>0,'Section Load'!AN7,0)) -> 615.804 | BH4: =(IF('Section Load'!AO7>0,'Section Load'!AO7,0)) -> 178.45 | BI4: =(IF('Section Load'!AP7>0,'Section Load'!AP7,0)) -> 0 | BJ4: =(IF('Section Load'!AQ7>0,'Section Load'!AQ7,0)) -> 62.69 | BK4: =(IF('Section Load'!AR7>0,'Section Load'!AR7,0)) -> 0 | BL4: =(IF('Section Load'!AS7>0,'Section Load'!AS7,0)) -> 0 | BM4: =(IF('Section Load'!AT7>0,'Section Load'!AT7,0)) -> 374.664
A5: Mumbai | B5: =B4+1 -> 4 | C5: 6 | D5: 2021 | E5: =(IF('Section Load'!F8>0,'Section Load'!F8,0)) -> 2421.52 | F5: =(IF('Section Load'!G8>0,'Section Load'!G8,0)) -> 1305.7 | G5: =(IF('Section Load'!H8>0,'Section Load'!H8,0)) -> 1089.37 | H5: =(IF('Section Load'!I8>0,'Section Load'!I8,0)) -> 2762.94 | I5: =(IF('Section Load'!J8>0,'Section Load'!J8,0)) -> 4466.56 | J5: =(IF('Section Load'!K8>0,'Section Load'!K8,0)) -> 2358.8 | K5: =(IF('Section Load'!L8>0,'Section Load'!L8,0)) -> 1026.2 | L5: =(IF('Section Load'!M8>0,'Section Load'!M8,0)) -> 520.79 | ... AL5: =(IF('Section Load'!AM8>0,'Section Load'!AM8,0)) -> 790 | AM5: =(IF('Water Report'!$G$7>0,'Water Report'!$F$7,0)) -> 56 | AN5: =(IF('Water Report'!$G$8>0,'Water Report'!$F$8,0)) -> 99 | AO5: =(IF('Water Report'!$G$9>0,'Water Report'!$H$9,0)) -> 50 | AP5: =(IF('Water Report'!$G$10>0,'Water Report'!$G$10,0)) -> 9 | AQ5: =(IF('Water Report'!$G$11>0,'Water Report'!$G$11,0)) -> 15 | AR5: =(IF('Water Report'!$G$13>0,'Water Report'!$G$13,0)) -> 10 | AS5: =(IF('Water Report'!$G$14>0,'Water Report'!$G$14,0)) -> 9 | AT5: =(IF('Water Report'!$G$15>0,'Water Report'!$G$15,0)) -> 5 | AU5: =(IF('Water Report'!$G$17>0,'Water Report'!$G$17,0)) -> 0 | AV5: =(IF('Water Report'!$G$18>0,'Water Report'!$G$18,0)) -> 0 | AW5: =(IF('Water Report'!$G$19>0,'Water Report'!$G$19,0)) -> 6 | AX5: =(IF('Water Report'!$G$21>0,'Water Report'!$G$21,0)) -> 65 | AY5: =(IF('Water Report'!$G$22>0,'Water Report'!$G$22,0)) -> 10 | AZ5: =(IF('Water Report'!$G$23>0,'Water Report'!$G$23,0)) -> 0 | BA5: =(IF('Water Report'!$G$14>0,'Water Report'!$G$14,0)) -> 9 | BB5: =(IF('Water Report'!$G$15>0,'Water Report'!$G$15,0)) -> 5 | BC5: =(IF('Water Report'!$G$13>0,'Water Report'!$G$13,0)) -> 10 | BD5: =(IF('Water Report'!$G$24>0,'Water Report'!$G$24,0)) -> 101 | BE5: =(IF('Water Report'!$G$25>0,'Water Report'!$G$25,0)) -> 65 | BF5: =(IF('Water Report'!$G$27>0,'Water Report'!$G$27,0)) -> 75 | BG5: =(IF('Section Load'!AN8>0,'Section Load'!AN8,0)) -> 302.904 | BH5: =(IF('Section Load'!AO8>0,'Section Load'!AO8,0)) -> 179.53 | BI5: =(IF('Section Load'!AP8>0,'Section Load'!AP8,0)) -> 0 | BJ5: =(IF('Section Load'!AQ8>0,'Section Load'!AQ8,0)) -> 68.4 | BK5: =(IF('Section Load'!AR8>0,'Section Load'!AR8,0)) -> 0 | BL5: =(IF('Section Load'!AS8>0,'Section Load'!AS8,0)) -> 0 | BM5: =(IF('Section Load'!AT8>0,'Section Load'!AT8,0)) -> 55.374
A6: Mumbai | B6: =B5+1 -> 5 | C6: 6 | D6: 2021 | E6: =(IF('Section Load'!F9>0,'Section Load'!F9,0)) -> 2427.44 | F6: =(IF('Section Load'!G9>0,'Section Load'!G9,0)) -> 1382.55 | G6: =(IF('Section Load'!H9>0,'Section Load'!H9,0)) -> 1403.78 | H6: =(IF('Section Load'!I9>0,'Section Load'!I9,0)) -> 3287.44 | I6: =(IF('Section Load'!J9>0,'Section Load'!J9,0)) -> 5836.54 | J6: =(IF('Section Load'!K9>0,'Section Load'!K9,0)) -> 2676.2 | K6: =(IF('Section Load'!L9>0,'Section Load'!L9,0)) -> 1410.52 | L6: =(IF('Section Load'!M9>0,'Section Load'!M9,0)) -> 927.5 | ... AL6: =(IF('Section Load'!AM9>0,'Section Load'!AM9,0)) -> 877 | AM6: =(IF('Water Report'!$H$7>0,'Water Report'!$H$7,0)) -> 51 | AN6: =(IF('Water Report'!$H$8>0,'Water Report'!$H$8,0)) -> 108 | AO6: =(IF('Water Report'!$H$9>0,'Water Report'!$H$9,0)) -> 50 | AP6: =(IF('Water Report'!$H$10>0,'Water Report'!$H$10,0)) -> 14 | AQ6: =(IF('Water Report'!$H$11>0,'Water Report'!$H$11,0)) -> 29 | AR6: =(IF('Water Report'!$H$13>0,'Water Report'!$H$13,0)) -> 5 | AS6: =(IF('Water Report'!$H$14>0,'Water Report'!$H$14,0)) -> 12 | AT6: =(IF('Water Report'!$H$15>0,'Water Report'!$H$15,0)) -> 8 | AU6: =(IF('Water Report'!$H$17>0,'Water Report'!$H$17,0)) -> 0 | AV6: =(IF('Water Report'!$H$18>0,'Water Report'!$H$18,0)) -> 1 | AW6: =(IF('Water Report'!$H$19>0,'Water Report'!$H$19,0)) -> 3 | AX6: =(IF('Water Report'!$H$21>0,'Water Report'!$H$21,0)) -> 88 | AY6: =(IF('Water Report'!$H$22>0,'Water Report'!$H$22,0)) -> 17 | AZ6: =(IF('Water Report'!$H$23>0,'Water Report'!$H$23,0)) -> 15 | BA6: =(IF('Water Report'!$H$14>0,'Water Report'!$H$14,0)) -> 12 | BB6: =(IF('Water Report'!$H$15>0,'Water Report'!$H$15,0)) -> 8 | BC6: =(IF('Water Report'!$H$13>0,'Water Report'!$H$13,0)) -> 5 | BD6: =(IF('Water Report'!$H$24>0,'Water Report'!$H$24,0)) -> 102 | BE6: =(IF('Water Report'!$H$25>0,'Water Report'!$H$25,0)) -> 113 | BF6: =(IF('Water Report'!$H$27>0,'Water Report'!$H$27,0)) -> 108 | BG6: =(IF('Section Load'!AN9>0,'Section Load'!AN9,0)) -> 453.902 | BH6: =(IF('Section Load'!AO9>0,'Section Load'!AO9,0)) -> 181.65 | BI6: =(IF('Section Load'!AP9>0,'Section Load'!AP9,0)) -> 0 | BJ6: =(IF('Section Load'!AQ9>0,'Section Load'!AQ9,0)) -> 61.13 | BK6: =(IF('Section Load'!AR9>0,'Section Load'!AR9,0)) -> 2.9 | BL6: =(IF('Section Load'!AS9>0,'Section Load'!AS9,0)) -> 0.2 | BM6: =(IF('Section Load'!AT9>0,'Section Load'!AT9,0)) -> 208.022
A7: Mumbai | B7: =B6+1 -> 6 | C7: 6 | D7: 2021 | E7: =(IF('Section Load'!F10>0,'Section Load'!F10,0)) -> 2676.4 | F7: =(IF('Section Load'!G10>0,'Section Load'!G10,0)) -> 1373 | G7: =(IF('Section Load'!H10>0,'Section Load'!H10,0)) -> 1420.21 | H7: =(IF('Section Load'!I10>0,'Section Load'!I10,0)) -> 3169.64 | I7: =(IF('Section Load'!J10>0,'Section Load'!J10,0)) -> 5049.8 | J7: =(IF('Section Load'!K10>0,'Section Load'!K10,0)) -> 2410.1 | K7: =(IF('Section Load'!L10>0,'Section Load'!L10,0)) -> 1017.04 | L7: =(IF('Section Load'!M10>0,'Section Load'!M10,0)) -> 502.36 | ... AL7: =(IF('Section Load'!AM10>0,'Section Load'!AM10,0)) -> 918 | AM7: =(IF('Water Report'!$I$7>0,'Water Report'!$I$7,0)) -> 85 | AN7: =(IF('Water Report'!$I$8>0,'Water Report'!$I$8,0)) -> 124 | AO7: =(IF('Water Report'!$I$9>0,'Water Report'!$I$9,0)) -> 73 | AP7: =(IF('Water Report'!$I$10>0,'Water Report'!$I$10,0)) -> 21 | AQ7: =(IF('Water Report'!$I$11>0,'Water Report'!$I$11,0)) -> 30 | AR7: =(IF('Water Report'!$I$13>0,'Water Report'!$I$13,0)) -> 18 | AS7: =(IF('Water Report'!$I$14>0,'Water Report'!$I$14,0)) -> 12 | AT7: =(IF('Water Report'!$I$15>0,'Water Report'!$I$15,0)) -> 13 | AU7: =(IF('Water Report'!$I$17>0,'Water Report'!$I$17,0)) -> 0 | AV7: =(IF('Water Report'!$I$18>0,'Water Report'!$I$18,0)) -> 10 | AW7: =(IF('Water Report'!$I$19>0,'Water Report'!$I$19,0)) -> 5 | AX7: =(IF('Water Report'!$I$21>0,'Water Report'!$I$21,0)) -> 63 | AY7: =(IF('Water Report'!$I$22>0,'Water Report'!$I$22,0)) -> 10 | AZ7: =(IF('Water Report'!$I$23>0,'Water Report'!$I$23,0)) -> 0 | BA7: =(IF('Water Report'!$I$14>0,'Water Report'!$I$14,0)) -> 12 | BB7: =(IF('Water Report'!$I$15>0,'Water Report'!$I$15,0)) -> 13 | BC7: =(IF('Water Report'!$I$13>0,'Water Report'!$I$13,0)) -> 18 | BD7: =(IF('Water Report'!$I$24>0,'Water Report'!$I$24,0)) -> 175 | BE7: =(IF('Water Report'!$I$25>0,'Water Report'!$I$25,0)) -> 149 | BF7: =(IF('Water Report'!$I$27>0,'Water Report'!$I$27,0)) -> 81 | BG7: =(IF('Section Load'!AN10>0,'Section Load'!AN10,0)) -> 556.87 | BH7: =(IF('Section Load'!AO10>0,'Section Load'!AO10,0)) -> 189.3 | BI7: =(IF('Section Load'!AP10>0,'Section Load'!AP10,0)) -> 0.4 | BJ7: =(IF('Section Load'!AQ10>0,'Section Load'!AQ10,0)) -> 71.57 | BK7: =(IF('Section Load'!AR10>0,'Section Load'!AR10,0)) -> 0 | BL7: =(IF('Section Load'!AS10>0,'Section Load'!AS10,0)) -> 0 | BM7: =(IF('Section Load'!AT10>0,'Section Load'!AT10,0)) -> 295.6
A8: Mumbai | B8: =B7+1 -> 7 | C8: 6 | D8: 2021 | E8: =(IF('Section Load'!F11>0,'Section Load'!F11,0)) -> 2464.96 | F8: =(IF('Section Load'!G11>0,'Section Load'!G11,0)) -> 1289.62 | G8: =(IF('Section Load'!H11>0,'Section Load'!H11,0)) -> 1221.4 | H8: =(IF('Section Load'!I11>0,'Section Load'!I11,0)) -> 2961.66 | I8: =(IF('Section Load'!J11>0,'Section Load'!J11,0)) -> 4822.74 | J8: =(IF('Section Load'!K11>0,'Section Load'!K11,0)) -> 2436.9 | K8: =(IF('Section Load'!L11>0,'Section Load'!L11,0)) -> 844.48 | L8: =(IF('Section Load'!M11>0,'Section Load'!M11,0)) -> 523.93 | ... AL8: =(IF('Section Load'!AM11>0,'Section Load'!AM11,0)) -> 763 | AM8: =(IF('Water Report'!$J$7>0,'Water Report'!$J$7,0)) -> 57 | AN8: =(IF('Water Report'!$J$8>0,'Water Report'!$J$8,0)) -> 80 | AO8: =(IF('Water Report'!$J$9>0,'Water Report'!$J$9,0)) -> 67 | AP8: =(IF('Water Report'!$J$10>0,'Water Report'!$J$10,0)) -> 7 | AQ8: =(IF('Water Report'!$J$11>0,'Water Report'!$J$11,0)) -> 19 | AR8: =(IF('Water Report'!$J$13>0,'Water Report'!$J$13,0)) -> 2 | AS8: =(IF('Water Report'!$J$14>0,'Water Report'!$J$14,0)) -> 14 | AT8: =(IF('Water Report'!$J$15>0,'Water Report'!$J$15,0)) -> 7 | AU8: =(IF('Water Report'!$J$17>0,'Water Report'!$J$17,0)) -> 0 | AV8: =(IF('Water Report'!$J$18>0,'Water Report'!$J$18,0)) -> 12 | AW8: =(IF('Water Report'!$J$19>0,'Water Report'!$J$19,0)) -> 4 | AX8: =(IF('Water Report'!$J$21>0,'Water Report'!$J$21,0)) -> 63 | AY8: =(IF('Water Report'!$J$22>0,'Water Report'!$J$22,0)) -> 0 | AZ8: =(IF('Water Report'!$J$23>0,'Water Report'!$J$23,0)) -> 0 | BA8: =(IF('Water Report'!$J$14>0,'Water Report'!$J$14,0)) -> 14 | BB8: =(IF('Water Report'!$J$15>0,'Water Report'!$J$15,0)) -> 7 | BC8: =(IF('Water Report'!$J$13>0,'Water Report'!$J$13,0)) -> 2 | BD8: =(IF('Water Report'!$J$24>0,'Water Report'!$J$24,0)) -> 122 | BE8: =(IF('Water Report'!$J$25>0,'Water Report'!$J$25,0)) -> 114 | BF8: =(IF('Water Report'!$J$27>0,'Water Report'!$J$27,0)) -> 65 | BG8: =(IF('Section Load'!AN11>0,'Section Load'!AN11,0)) -> 563.65 | BH8: =(IF('Section Load'!AO11>0,'Section Load'!AO11,0)) -> 182.22 | BI8: =(IF('Section Load'!AP11>0,'Section Load'!AP11,0)) -> 0 | BJ8: =(IF('Section Load'!AQ11>0,'Section Load'!AQ11,0)) -> 49.88 | BK8: =(IF('Section Load'!AR11>0,'Section Load'!AR11,0)) -> 0 | BL8: =(IF('Section Load'!AS11>0,'Section Load'!AS11,0)) -> 0 | BM8: =(IF('Section Load'!AT11>0,'Section Load'!AT11,0)) -> 332.05
A9: Mumbai | B9: =B8+1 -> 8 | C9: 6 | D9: 2021 | E9: =(IF('Section Load'!F12>0,'Section Load'!F12,0)) -> 2459.68 | F9: =(IF('Section Load'!G12>0,'Section Load'!G12,0)) -> 1347.64 | G9: =(IF('Section Load'!H12>0,'Section Load'!H12,0)) -> 1148.87 | H9: =(IF('Section Load'!I12>0,'Section Load'!I12,0)) -> 2920.2 | I9: =(IF('Section Load'!J12>0,'Section Load'!J12,0)) -> 5104.14 | J9: =(IF('Section Load'!K12>0,'Section Load'!K12,0)) -> 2446.8 | K9: =(IF('Section Load'!L12>0,'Section Load'!L12,0)) -> 832.4 | L9: =(IF('Section Load'!M12>0,'Section Load'!M12,0)) -> 596.12 | ... AL9: =(IF('Section Load'!AM12>0,'Section Load'!AM12,0)) -> 696 | AM9: =(IF('Water Report'!$K$7>0,'Water Report'!$K$7,0)) -> 40 | AN9: =(IF('Water Report'!$K$8>0,'Water Report'!$K$8,0)) -> 88 | AO9: =(IF('Water Report'!$K$9>0,'Water Report'!$K$9,0)) -> 34 | AP9: =(IF('Water Report'!$K$10>0,'Water Report'!$K$10,0)) -> 9 | AQ9: =(IF('Water Report'!$K$11>0,'Water Report'!$K$11,0)) -> 15 | AR9: =(IF('Water Report'!$K$13>0,'Water Report'!$K$13,0)) -> 5 | AS9: =(IF('Water Report'!$K$14>0,'Water Report'!$K$14,0)) -> 31 | AT9: =(IF('Water Report'!$K$15>0,'Water Report'!$K$15,0)) -> 6 | AU9: =(IF('Water Report'!$K$17>0,'Water Report'!$K$17,0)) -> 0 | AV9: =(IF('Water Report'!$K$18>0,'Water Report'!$K$18,0)) -> 0 | AW9: =(IF('Water Report'!$K$19>0,'Water Report'!$K$19,0)) -> 3 | AX9: =(IF('Water Report'!$K$21>0,'Water Report'!$K$21,0)) -> 45 | AY9: =(IF('Water Report'!$K$22>0,'Water Report'!$K$22,0)) -> 17 | AZ9: =(IF('Water Report'!$K$23>0,'Water Report'!$K$23,0)) -> 0 | BA9: =(IF('Water Report'!$K$14>0,'Water Report'!$K$14,0)) -> 31 | BB9: =(IF('Water Report'!$K$15>0,'Water Report'!$K$15,0)) -> 6 | BC9: =(IF('Water Report'!$K$13>0,'Water Report'!$K$13,0)) -> 5 | BD9: =(IF('Water Report'!$K$24>0,'Water Report'!$K$24,0)) -> 159 | BE9: =(IF('Water Report'!$K$25>0,'Water Report'!$K$25,0)) -> 95 | BF9: =(IF('Water Report'!$K$27>0,'Water Report'!$K$27,0)) -> 50 | BG9: =(IF('Section Load'!AN12>0,'Section Load'!AN12,0)) -> 406.12 | BH9: =(IF('Section Load'!AO12>0,'Section Load'!AO12,0)) -> 178.89 | BI9: =(IF('Section Load'!AP12>0,'Section Load'!AP12,0)) -> 0.4 | BJ9: =(IF('Section Load'!AQ12>0,'Section Load'!AQ12,0)) -> 58 | BK9: =(IF('Section Load'!AR12>0,'Section Load'!AR12,0)) -> 0 | BL9: =(IF('Section Load'!AS12>0,'Section Load'!AS12,0)) -> 0.1 | BM9: =(IF('Section Load'!AT12>0,'Section Load'!AT12,0)) -> 168.73
A10: Mumbai | B10: =B9+1 -> 9 | C10: 6 | D10: 2021 | E10: =(IF('Section Load'!F13>0,'Section Load'!F13,0)) -> 2245.81 | F10: =(IF('Section Load'!G13>0,'Section Load'!G13,0)) -> 1379.74 | G10: =(IF('Section Load'!H13>0,'Section Load'!H13,0)) -> 1004.85 | H10: =(IF('Section Load'!I13>0,'Section Load'!I13,0)) -> 3069.71 | I10: =(IF('Section Load'!J13>0,'Section Load'!J13,0)) -> 4917.26 | J10: =(IF('Section Load'!K13>0,'Section Load'!K13,0)) -> 2440.5 | K10: =(IF('Section Load'!L13>0,'Section Load'!L13,0)) -> 877.41 | L10: =(IF('Section Load'!M13>0,'Section Load'!M13,0)) -> 614.82 | ... AL10: =(IF('Section Load'!AM13>0,'Section Load'!AM13,0)) -> 558 | AM10: =(IF('Water Report'!$L$7>0,'Water Report'!$L$7,0)) -> 0 | AN10: =(IF('Water Report'!$L$8>0,'Water Report'!$L$8,0)) -> 84 | AO10: =(IF('Water Report'!$L$9>0,'Water Report'!$L$9,0)) -> 24 | AP10: =(IF('Water Report'!$L$10>0,'Water Report'!$L$10,0)) -> 10 | AQ10: =(IF('Water Report'!$L$11>0,'Water Report'!$L$11,0)) -> 15 | AR10: =(IF('Water Report'!$L$13>0,'Water Report'!$L$13,0)) -> 4 | AS10: =(IF('Water Report'!$L$14>0,'Water Report'!$L$14,0)) -> 4 | AT10: =(IF('Water Report'!$L$15>0,'Water Report'!$L$15,0)) -> 4 | AU10: =(IF('Water Report'!$L$17>0,'Water Report'!$L$17,0)) -> 0 | AV10: =(IF('Water Report'!$L$18>0,'Water Report'!$L$18,0)) -> 0 | AW10: =(IF('Water Report'!$L$19>0,'Water Report'!$L$19,0)) -> 0 | AX10: =(IF('Water Report'!$L$21>0,'Water Report'!$L$21,0)) -> 77 | AY10: =(IF('Water Report'!$L$22>0,'Water Report'!$L$22,0)) -> 0 | AZ10: =(IF('Water Report'!$L$23>0,'Water Report'!$L$23,0)) -> 0 | BA10: =(IF('Water Report'!$L$14>0,'Water Report'!$L$14,0)) -> 4 | BB10: =(IF('Water Report'!$L$15>0,'Water Report'!$L$15,0)) -> 4 | BC10: =(IF('Water Report'!$L$13>0,'Water Report'!$L$13,0)) -> 4 | BD10: =(IF('Water Report'!$L$24>0,'Water Report'!$L$24,0)) -> 78 | BE10: =(IF('Water Report'!$L$25>0,'Water Report'!$L$25,0)) -> 57 | BF10: =(IF('Water Report'!$L$27>0,'Water Report'!$L$27,0)) -> 81 | BG10: =(IF('Section Load'!AN13>0,'Section Load'!AN13,0)) -> 345.05 | BH10: =(IF('Section Load'!AO13>0,'Section Load'!AO13,0)) -> 206.11 | BI10: =(IF('Section Load'!AP13>0,'Section Load'!AP13,0)) -> 0 | BJ10: =(IF('Section Load'!AQ13>0,'Section Load'!AQ13,0)) -> 75 | BK10: =(IF('Section Load'!AR13>0,'Section Load'!AR13,0)) -> 0 | BL10: =(IF('Section Load'!AS13>0,'Section Load'!AS13,0)) -> 0 | BM10: =(IF('Section Load'!AT13>0,'Section Load'!AT13,0)) -> 63.94
A11: Mumbai | B11: =B10+1 -> 10 | C11: 6 | D11: 2021 | E11: =(IF('Section Load'!F14>0,'Section Load'!F14,0)) -> 2172 | F11: =(IF('Section Load'!G14>0,'Section Load'!G14,0)) -> 1349 | G11: =(IF('Section Load'!H14>0,'Section Load'!H14,0)) -> 1210 | H11: =(IF('Section Load'!I14>0,'Section Load'!I14,0)) -> 3175.33 | I11: =(IF('Section Load'!J14>0,'Section Load'!J14,0)) -> 4704.39 | J11: =(IF('Section Load'!K14>0,'Section Load'!K14,0)) -> 2439 | K11: =(IF('Section Load'!L14>0,'Section Load'!L14,0)) -> 890 | L11: =(IF('Section Load'!M14>0,'Section Load'!M14,0)) -> 564 | ... AL11: =(IF('Section Load'!AM14>0,'Section Load'!AM14,0)) -> 592 | AM11: =(IF('Water Report'!$M$7>0,'Water Report'!$M$7,0)) -> 41 | AN11: =(IF('Water Report'!$M$8>0,'Water Report'!$M$8,0)) -> 116 | AO11: =(IF('Water Report'!$M$9>0,'Water Report'!$M$9,0)) -> 59 | AP11: =(IF('Water Report'!$M$10>0,'Water Report'!$M$10,0)) -> 11 | AQ11: =(IF('Water Report'!$M$11>0,'Water Report'!$M$11,0)) -> 16 | AR11: =(IF('Water Report'!$M$13>0,'Water Report'!$M$13,0)) -> 4 | AS11: =(IF('Water Report'!$M$14>0,'Water Report'!$M$14,0)) -> 10 | AT11: =(IF('Water Report'!$M$15>0,'Water Report'!$M$15,0)) -> 5 | AU11: =(IF('Water Report'!$M$17>0,'Water Report'!$M$17,0)) -> 0 | AV11: =(IF('Water Report'!$M$18>0,'Water Report'!$M$18,0)) -> 17 | AW11: =(IF('Water Report'!$M$19>0,'Water Report'!$M$19,0)) -> 7 | AX11: =(IF('Water Report'!$M$21>0,'Water Report'!$M$21,0)) -> 62 | AY11: =(IF('Water Report'!$M$22>0,'Water Report'!$M$22,0)) -> 13 | AZ11: =(IF('Water Report'!$M$23>0,'Water Report'!$M$23,0)) -> 0 | BA11: =(IF('Water Report'!$M$14>0,'Water Report'!$M$14,0)) -> 10 | BB11: =(IF('Water Report'!$M$15>0,'Water Report'!$M$15,0)) -> 5 | BC11: =(IF('Water Report'!$M$13>0,'Water Report'!$M$13,0)) -> 4 | BD11: =(IF('Water Report'!$M$24>0,'Water Report'!$M$24,0)) -> 86 | BE11: =(IF('Water Report'!$M$25>0,'Water Report'!$M$25,0)) -> 101 | BF11: =(IF('Water Report'!$M$27>0,'Water Report'!$M$27,0)) -> 66 | BG11: =(IF('Section Load'!AN14>0,'Section Load'!AN14,0)) -> 665 | BH11: =(IF('Section Load'!AO14>0,'Section Load'!AO14,0)) -> 211 | BI11: =(IF('Section Load'!AP14>0,'Section Load'!AP14,0)) -> 0 | BJ11: =(IF('Section Load'!AQ14>0,'Section Load'!AQ14,0)) -> 66 | BK11: =(IF('Section Load'!AR14>0,'Section Load'!AR14,0)) -> 0 | BL11: =(IF('Section Load'!AS14>0,'Section Load'!AS14,0)) -> 0 | BM11: =(IF('Section Load'!AT14>0,'Section Load'!AT14,0)) -> 388
A12: Mumbai | B12: =B11+1 -> 11 | C12: 6 | D12: 2021 | E12: =(IF('Section Load'!F15>0,'Section Load'!F15,0)) -> 2190 | F12: =(IF('Section Load'!G15>0,'Section Load'!G15,0)) -> 1386 | G12: =(IF('Section Load'!H15>0,'Section Load'!H15,0)) -> 1184 | H12: =(IF('Section Load'!I15>0,'Section Load'!I15,0)) -> 3233 | I12: =(IF('Section Load'!J15>0,'Section Load'!J15,0)) -> 4819 | J12: =(IF('Section Load'!K15>0,'Section Load'!K15,0)) -> 2435 | K12: =(IF('Section Load'!L15>0,'Section Load'!L15,0)) -> 897 | L12: =(IF('Section Load'!M15>0,'Section Load'!M15,0)) -> 578 | ... AL12: =(IF('Section Load'!AM15>0,'Section Load'!AM15,0)) -> 564 | AM12: =(IF('Water Report'!$N$7>0,'Water Report'!$N$7,0)) -> 18 | AN12: =(IF('Water Report'!$N$8>0,'Water Report'!$N$8,0)) -> 114 | AO12: =(IF('Water Report'!$N$9>0,'Water Report'!$N$9,0)) -> 46 | AP12: =(IF('Water Report'!$N$10>0,'Water Report'!$N$10,0)) -> 9 | AQ12: =(IF('Water Report'!$N$11>0,'Water Report'!$N$11,0)) -> 26 | AR12: =(IF('Water Report'!$N$13>0,'Water Report'!$N$13,0)) -> 19 | AS12: =(IF('Water Report'!$N$14>0,'Water Report'!$N$14,0)) -> 5 | AT12: =(IF('Water Report'!$N$15>0,'Water Report'!$N$15,0)) -> 5 | AU12: =(IF('Water Report'!$N$17>0,'Water Report'!$N$17,0)) -> 0 | AV12: =(IF('Water Report'!$N$18>0,'Water Report'!$N$18,0)) -> 0 | AW12: =(IF('Water Report'!$N$19>0,'Water Report'!$N$19,0)) -> 3 | AX12: =(IF('Water Report'!$N$21>0,'Water Report'!$N$21,0)) -> 27 | AY12: =(IF('Water Report'!$N$22>0,'Water Report'!$N$22,0)) -> 30 | AZ12: =(IF('Water Report'!$N$23>0,'Water Report'!$N$23,0)) -> 0 | BA12: =(IF('Water Report'!$N$14>0,'Water Report'!$N$14,0)) -> 5 | BB12: =(IF('Water Report'!$N$15>0,'Water Report'!$N$15,0)) -> 5 | BC12: =(IF('Water Report'!$N$13>0,'Water Report'!$N$13,0)) -> 19 | BD12: =(IF('Water Report'!$N$24>0,'Water Report'!$N$24,0)) -> 103 | BE12: =(IF('Water Report'!$N$25>0,'Water Report'!$N$25,0)) -> 91 | BF12: =(IF('Water Report'!$N$27>0,'Water Report'!$N$27,0)) -> 46 | BG12: =(IF('Section Load'!AN15>0,'Section Load'!AN15,0)) -> 498 | BH12: =(IF('Section Load'!AO15>0,'Section Load'!AO15,0)) -> 230 | BI12: =(IF('Section Load'!AP15>0,'Section Load'!AP15,0)) -> 0 | BJ12: =(IF('Section Load'!AQ15>0,'Section Load'!AQ15,0)) -> 66 | BK12: =(IF('Section Load'!AR15>0,'Section Load'!AR15,0)) -> 0 | BL12: =(IF('Section Load'!AS15>0,'Section Load'!AS15,0)) -> 0 | BM12: =(IF('Section Load'!AT15>0,'Section Load'!AT15,0)) -> 202
A13: Mumbai | B13: =B12+1 -> 12 | C13: 6 | D13: 2021 | E13: =(IF('Section Load'!F16>0,'Section Load'!F16,0)) -> 2554 | F13: =(IF('Section Load'!G16>0,'Section Load'!G16,0)) -> 1461 | G13: =(IF('Section Load'!H16>0,'Section Load'!H16,0)) -> 1383 | H13: =(IF('Section Load'!I16>0,'Section Load'!I16,0)) -> 3517 | I13: =(IF('Section Load'!J16>0,'Section Load'!J16,0)) -> 5598 | J13: =(IF('Section Load'!K16>0,'Section Load'!K16,0)) -> 2382 | K13: =(IF('Section Load'!L16>0,'Section Load'!L16,0)) -> 939 | L13: =(IF('Section Load'!M16>0,'Section Load'!M16,0)) -> 544 | ... AL13: =(IF('Section Load'!AM16>0,'Section Load'!AM16,0)) -> 596 | AM13: =(IF('Water Report'!$O$7>0,'Water Report'!$O$7,0)) -> 55 | AN13: =(IF('Water Report'!$O$8>0,'Water Report'!$O$8,0)) -> 154 | AO13: =(IF('Water Report'!$O$9>0,'Water Report'!$O$9,0)) -> 36 | AP13: =(IF('Water Report'!$O$10>0,'Water Report'!$O$10,0)) -> 16 | AQ13: =(IF('Water Report'!$O$11>0,'Water Report'!$O$11,0)) -> 37 | AR13: =(IF('Water Report'!$O$13>0,'Water Report'!$O$13,0)) -> 20 | AS13: =(IF('Water Report'!$O$14>0,'Water Report'!$O$14,0)) -> 11 | AT13: =(IF('Water Report'!$O$15>0,'Water Report'!$O$15,0)) -> 21 | AU13: =(IF('Water Report'!$O$17>0,'Water Report'!$O$17,0)) -> 0 | AV13: =(IF('Water Report'!$O$18>0,'Water Report'!$O$18,0)) -> 0 | AW13: =(IF('Water Report'!$O$19>0,'Water Report'!$O$19,0)) -> 4 | AX13: =(IF('Water Report'!$O$21>0,'Water Report'!$O$21,0)) -> 33 | AY13: =(IF('Water Report'!$O$22>0,'Water Report'!$O$22,0)) -> 22 | AZ13: =(IF('Water Report'!$O$23>0,'Water Report'!$O$23,0)) -> 0 | BA13: =(IF('Water Report'!$O$14>0,'Water Report'!$O$14,0)) -> 11 | BB13: =(IF('Water Report'!$O$15>0,'Water Report'!$O$15,0)) -> 21 | BC13: =(IF('Water Report'!$O$13>0,'Water Report'!$O$13,0)) -> 20 | BD13: =(IF('Water Report'!$O$24>0,'Water Report'!$O$24,0)) -> 125 | BE13: =(IF('Water Report'!$O$25>0,'Water Report'!$O$25,0)) -> 121 | BF13: =(IF('Water Report'!$O$27>0,'Water Report'!$O$27,0)) -> 53 | BG13: =(IF('Section Load'!AN16>0,'Section Load'!AN16,0)) -> 460 | BH13: =(IF('Section Load'!AO16>0,'Section Load'!AO16,0)) -> 238 | BI13: =(IF('Section Load'!AP16>0,'Section Load'!AP16,0)) -> 0 | BJ13: =(IF('Section Load'!AQ16>0,'Section Load'!AQ16,0)) -> 62 | BK13: =(IF('Section Load'!AR16>0,'Section Load'!AR16,0)) -> 0 | BL13: =(IF('Section Load'!AS16>0,'Section Load'!AS16,0)) -> 0 | BM13: =(IF('Section Load'!AT16>0,'Section Load'!AT16,0)) -> 160.4
A14: Mumbai | B14: =B13+1 -> 13 | C14: 6 | D14: 2021 | E14: =(IF('Section Load'!F17>0,'Section Load'!F17,0)) -> 2615 | F14: =(IF('Section Load'!G17>0,'Section Load'!G17,0)) -> 1413 | G14: =(IF('Section Load'!H17>0,'Section Load'!H17,0)) -> 1494 | H14: =(IF('Section Load'!I17>0,'Section Load'!I17,0)) -> 3369 | I14: =(IF('Section Load'!J17>0,'Section Load'!J17,0)) -> 6701.48 | J14: =(IF('Section Load'!K17>0,'Section Load'!K17,0)) -> 2647.33 | K14: =(IF('Section Load'!L17>0,'Section Load'!L17,0)) -> 1050 | L14: =(IF('Section Load'!M17>0,'Section Load'!M17,0)) -> 557 | ... AL14: =(IF('Section Load'!AM17>0,'Section Load'!AM17,0)) -> 687 | AM14: =(IF('Water Report'!$P$7>0,'Water Report'!$P$7,0)) -> 124 | AN14: =(IF('Water Report'!$P$8>0,'Water Report'!$P$8,0)) -> 109 | AO14: =(IF('Water Report'!$P$9>0,'Water Report'!$P$9,0)) -> 64 | AP14: =(IF('Water Report'!$P$10>0,'Water Report'!$P$10,0)) -> 34 | AQ14: =(IF('Water Report'!$P$11>0,'Water Report'!$P$11,0)) -> 47 | AR14: =(IF('Water Report'!$P$13>0,'Water Report'!$P$13,0)) -> 8 | AS14: =(IF('Water Report'!$P$14>0,'Water Report'!$P$14,0)) -> 16 | AT14: =(IF('Water Report'!$P$15>0,'Water Report'!$P$15,0)) -> 15 | AU14: =(IF('Water Report'!$P$17>0,'Water Report'!$P$17,0)) -> 0 | AV14: =(IF('Water Report'!$P$18>0,'Water Report'!$P$18,0)) -> 13 | AW14: =(IF('Water Report'!$P$19>0,'Water Report'!$P$19,0)) -> 5 | AX14: =(IF('Water Report'!$P$21>0,'Water Report'!$P$21,0)) -> 63 | AY14: =(IF('Water Report'!$P$22>0,'Water Report'!$P$22,0)) -> 0 | AZ14: =(IF('Water Report'!$P$23>0,'Water Report'!$P$23,0)) -> 0 | BA14: =(IF('Water Report'!$P$14>0,'Water Report'!$P$14,0)) -> 16 | BB14: =(IF('Water Report'!$P$15>0,'Water Report'!$P$15,0)) -> 15 | BC14: =(IF('Water Report'!$P$13>0,'Water Report'!$P$13,0)) -> 8 | BD14: =(IF('Water Report'!$P$24>0,'Water Report'!$P$24,0)) -> 194 | BE14: =(IF('Water Report'!$P$25>0,'Water Report'!$P$25,0)) -> 176 | BF14: =(IF('Water Report'!$P$27>0,'Water Report'!$P$27,0)) -> 71 | BG14: =(IF('Section Load'!AN17>0,'Section Load'!AN17,0)) -> 737 | BH14: =(IF('Section Load'!AO17>0,'Section Load'!AO17,0)) -> 245 | BI14: =(IF('Section Load'!AP17>0,'Section Load'!AP17,0)) -> 0 | BJ14: =(IF('Section Load'!AQ17>0,'Section Load'!AQ17,0)) -> 60 | BK14: =(IF('Section Load'!AR17>0,'Section Load'!AR17,0)) -> 68 | BL14: =(IF('Section Load'!AS17>0,'Section Load'!AS17,0)) -> 2 | BM14: =(IF('Section Load'!AT17>0,'Section Load'!AT17,0)) -> 362
A15: Mumbai | B15: =B14+1 -> 14 | C15: 6 | D15: 2021 | E15: =(IF('Section Load'!F18>0,'Section Load'!F18,0)) -> 0 | F15: =(IF('Section Load'!G18>0,'Section Load'!G18,0)) -> 0 | G15: =(IF('Section Load'!H18>0,'Section Load'!H18,0)) -> 0 | H15: =(IF('Section Load'!I18>0,'Section Load'!I18,0)) -> 0 | I15: =(IF('Section Load'!J18>0,'Section Load'!J18,0)) -> 0 | J15: =(IF('Section Load'!K18>0,'Section Load'!K18,0)) -> 0 | K15: =(IF('Section Load'!L18>0,'Section Load'!L18,0)) -> 0 | L15: =(IF('Section Load'!M18>0,'Section Load'!M18,0)) -> 339554 | ... AL15: =(IF('Section Load'!AM18>0,'Section Load'!AM18,0)) -> 0 | AM15: =(IF('Water Report'!$Q$7>0,'Water Report'!$Q$7,0)) -> 0 | AN15: =(IF('Water Report'!$Q$8>0,'Water Report'!$Q$8,0)) -> 0 | AO15: =(IF('Water Report'!$Q$9>0,'Water Report'!$Q$9,0)) -> 0 | AP15: =(IF('Water Report'!$Q$10>0,'Water Report'!$Q$10,0)) -> 0 | AQ15: =(IF('Water Report'!$Q$11>0,'Water Report'!$Q$11,0)) -> 0 | AR15: =(IF('Water Report'!$Q$13>0,'Water Report'!$Q$13,0)) -> 0 | AS15: =(IF('Water Report'!$Q$14>0,'Water Report'!$Q$14,0)) -> 0 | AT15: =(IF('Water Report'!$Q$15>0,'Water Report'!$Q$15,0)) -> 0 | AU15: =(IF('Water Report'!$Q$17>0,'Water Report'!$Q$17,0)) -> 0 | AV15: =(IF('Water Report'!$Q$18>0,'Water Report'!$Q$18,0)) -> 0 | AW15: =(IF('Water Report'!$Q$19>0,'Water Report'!$Q$19,0)) -> 0 | AX15: =(IF('Water Report'!$Q$21>0,'Water Report'!$Q$21,0)) -> 0 | AY15: =(IF('Water Report'!$Q$22>0,'Water Report'!$Q$22,0)) -> 0 | AZ15: =(IF('Water Report'!$Q$23>0,'Water Report'!$Q$23,0)) -> 0 | BA15: =(IF('Water Report'!$Q$14>0,'Water Report'!$Q$14,0)) -> 0 | BB15: =(IF('Water Report'!$Q$15>0,'Water Report'!$Q$15,0)) -> 0 | BC15: =(IF('Water Report'!$Q$13>0,'Water Report'!$Q$13,0)) -> 0 | BD15: =(IF('Water Report'!$Q$24>0,'Water Report'!$Q$24,0)) -> 0 | BE15: =(IF('Water Report'!$Q$25>0,'Water Report'!$Q$25,0)) -> 0 | BF15: =(IF('Water Report'!$Q$27>0,'Water Report'!$Q$27,0)) -> 0 | BG15: =(IF('Section Load'!AN18>0,'Section Load'!AN18,0)) -> 550 | BH15: =(IF('Section Load'!AO18>0,'Section Load'!AO18,0)) -> 0 | BI15: =(IF('Section Load'!AP18>0,'Section Load'!AP18,0)) -> 0 | BJ15: =(IF('Section Load'!AQ18>0,'Section Load'!AQ18,0)) -> 0 | BK15: =(IF('Section Load'!AR18>0,'Section Load'!AR18,0)) -> 0 | BL15: =(IF('Section Load'!AS18>0,'Section Load'!AS18,0)) -> 0 | BM15: =(IF('Section Load'!AT18>0,'Section Load'!AT18,0)) -> 8445.91
A16: Mumbai | B16: =B15+1 -> 15 | C16: 6 | D16: 2021 | E16: =(IF('Section Load'!F19>0,'Section Load'!F19,0)) -> 2006.92 | F16: =(IF('Section Load'!G19>0,'Section Load'!G19,0)) -> 1297.09 | G16: =(IF('Section Load'!H19>0,'Section Load'!H19,0)) -> 1315.96 | H16: =(IF('Section Load'!I19>0,'Section Load'!I19,0)) -> 2647.82 | I16: =(IF('Section Load'!J19>0,'Section Load'!J19,0)) -> 5855.14 | J16: =(IF('Section Load'!K19>0,'Section Load'!K19,0)) -> 2074.8 | K16: =(IF('Section Load'!L19>0,'Section Load'!L19,0)) -> 895.01 | L16: =(IF('Section Load'!M19>0,'Section Load'!M19,0)) -> 0 | ... AL16: =(IF('Section Load'!AM19>0,'Section Load'!AM19,0)) -> 599 | AM16: =(IF('Water Report'!$R$7>0,'Water Report'!$R$7,0)) -> 153 | AN16: =(IF('Water Report'!$R$8>0,'Water Report'!$R$8,0)) -> 131 | AO16: =(IF('Water Report'!$R$9>0,'Water Report'!$R$9,0)) -> 42 | AP16: =(IF('Water Report'!$R$10>0,'Water Report'!$R$10,0)) -> 10 | AQ16: =(IF('Water Report'!$R$11>0,'Water Report'!$R$11,0)) -> 33 | AR16: =(IF('Water Report'!$R$13>0,'Water Report'!$R$13,0)) -> 23 | AS16: =(IF('Water Report'!$R$14>0,'Water Report'!$R$14,0)) -> 7 | AT16: =(IF('Water Report'!$R$15>0,'Water Report'!$R$15,0)) -> 1 | AU16: =(IF('Water Report'!$R$17>0,'Water Report'!$R$17,0)) -> 0 | AV16: =(IF('Water Report'!$R$18>0,'Water Report'!$R$18,0)) -> 0 | AW16: =(IF('Water Report'!$R$19>0,'Water Report'!$R$19,0)) -> 3 | AX16: =(IF('Water Report'!$R$21>0,'Water Report'!$R$21,0)) -> 42 | AY16: =(IF('Water Report'!$R$22>0,'Water Report'!$R$22,0)) -> 30 | AZ16: =(IF('Water Report'!$R$23>0,'Water Report'!$R$23,0)) -> 17 | BA16: =(IF('Water Report'!$R$14>0,'Water Report'!$R$14,0)) -> 7 | BB16: =(IF('Water Report'!$R$15>0,'Water Report'!$R$15,0)) -> 1 | BC16: =(IF('Water Report'!$R$13>0,'Water Report'!$R$13,0)) -> 23 | BD16: =(IF('Water Report'!$R$24>0,'Water Report'!$R$24,0)) -> 116 | BE16: =(IF('Water Report'!$R$25>0,'Water Report'!$R$25,0)) -> 93 | BF16: =(IF('Water Report'!$R$27>0,'Water Report'!$R$27,0)) -> 82 | BG16: =(IF('Section Load'!AN19>0,'Section Load'!AN19,0)) -> 550 | BH16: =(IF('Section Load'!AO19>0,'Section Load'!AO19,0)) -> 200.91 | BI16: =(IF('Section Load'!AP19>0,'Section Load'!AP19,0)) -> 0.4 | BJ16: =(IF('Section Load'!AQ19>0,'Section Load'!AQ19,0)) -> 45 | BK16: =(IF('Section Load'!AR19>0,'Section Load'!AR19,0)) -> 0 | BL16: =(IF('Section Load'!AS19>0,'Section Load'!AS19,0)) -> 0 | BM16: =(IF('Section Load'!AT19>0,'Section Load'!AT19,0)) -> 303.69
A17: Mumbai | B17: =B16+1 -> 16 | C17: 6 | D17: 2021 | E17: =(IF('Section Load'!F20>0,'Section Load'!F20,0)) -> 1926.13 | F17: =(IF('Section Load'!G20>0,'Section Load'!G20,0)) -> 1239 | G17: =(IF('Section Load'!H20>0,'Section Load'!H20,0)) -> 1097 | H17: =(IF('Section Load'!I20>0,'Section Load'!I20,0)) -> 2608 | I17: =(IF('Section Load'!J20>0,'Section Load'!J20,0)) -> 4448 | J17: =(IF('Section Load'!K20>0,'Section Load'!K20,0)) -> 2126 | K17: =(IF('Section Load'!L20>0,'Section Load'!L20,0)) -> 821 | L17: =(IF('Section Load'!M20>0,'Section Load'!M20,0)) -> 0 | ... AL17: =(IF('Section Load'!AM20>0,'Section Load'!AM20,0)) -> 511 | AM17: =(IF('Water Report'!$S$7>0,'Water Report'!$S$7,0)) -> 45 | AN17: =(IF('Water Report'!$S$8>0,'Water Report'!$S$8,0)) -> 29 | AO17: =(IF('Water Report'!$S$9>0,'Water Report'!$S$9,0)) -> 27 | AP17: =(IF('Water Report'!$S$10>0,'Water Report'!$D$10,0)) -> 13 | AQ17: =(IF('Water Report'!$S$11>0,'Water Report'!$D$11,0)) -> 15 | AR17: =(IF('Water Report'!$S$13>0,'Water Report'!$D$13,0)) -> 7 | AS17: =(IF('Water Report'!$S$14>0,'Water Report'!$D$14,0)) -> 12 | AT17: =(IF('Water Report'!$S$15>0,'Water Report'!$D$15,0)) -> 5 | AU17: =(IF('Water Report'!$S$17>0,'Water Report'!$D$17,0)) -> 0 | AV17: =(IF('Water Report'!$S$18>0,'Water Report'!$D$18,0)) -> 0 | AW17: =(IF('Water Report'!$S$19>0,'Water Report'!$D$19,0)) -> 0 | AX17: =(IF('Water Report'!$S$21>0,'Water Report'!$D$21,0)) -> 63 | AY17: =(IF('Water Report'!$S$22>0,'Water Report'!$D$22,0)) -> 0 | AZ17: =(IF('Water Report'!$S$23>0,'Water Report'!$D$23,0)) -> 0 | BA17: =(IF('Water Report'!$S$14>0,'Water Report'!$D$14,0)) -> 12 | BB17: =(IF('Water Report'!$S$15>0,'Water Report'!$D$15,0)) -> 5 | BC17: =(IF('Water Report'!$S$13>0,'Water Report'!$D$13,0)) -> 7 | BD17: =(IF('Water Report'!$S$24>0,'Water Report'!$D$24,0)) -> 80 | BE17: =(IF('Water Report'!$S$25>0,'Water Report'!$D$25,0)) -> 85 | BF17: =(IF('Water Report'!$S$27>0,'Water Report'!$D$27,0)) -> 86 | BG17: =(IF('Section Load'!AN20>0,'Section Load'!AN20,0)) -> 550 | BH17: =(IF('Section Load'!AO20>0,'Section Load'!AO20,0)) -> 209 | BI17: =(IF('Section Load'!AP20>0,'Section Load'!AP20,0)) -> 0 | BJ17: =(IF('Section Load'!AQ20>0,'Section Load'!AQ20,0)) -> 57 | BK17: =(IF('Section Load'!AR20>0,'Section Load'!AR20,0)) -> 0 | BL17: =(IF('Section Load'!AS20>0,'Section Load'!AS20,0)) -> 0 | BM17: =(IF('Section Load'!AT20>0,'Section Load'!AT20,0)) -> 284
A18: Mumbai | B18: =B17+1 -> 17 | C18: 6 | D18: 2021 | E18: =(IF('Section Load'!F21>0,'Section Load'!F21,0)) -> 1602 | F18: =(IF('Section Load'!G21>0,'Section Load'!G21,0)) -> 1338.13 | G18: =(IF('Section Load'!H21>0,'Section Load'!H21,0)) -> 1050 | H18: =(IF('Section Load'!I21>0,'Section Load'!I21,0)) -> 2646 | I18: =(IF('Section Load'!J21>0,'Section Load'!J21,0)) -> 4494 | J18: =(IF('Section Load'!K21>0,'Section Load'!K21,0)) -> 2036 | K18: =(IF('Section Load'!L21>0,'Section Load'!L21,0)) -> 762 | L18: =(IF('Section Load'!M21>0,'Section Load'!M21,0)) -> 0 | ... AL18: =(IF('Section Load'!AM21>0,'Section Load'!AM21,0)) -> 419 | AM18: =(IF('Water Report'!$T$7>0,'Water Report'!$T$7,0)) -> 0 | AN18: =(IF('Water Report'!$T$8>0,'Water Report'!$T$8,0)) -> 93 | AO18: =(IF('Water Report'!$T$9>0,'Water Report'!$T$9,0)) -> 45 | AP18: =(IF('Water Report'!$T$10>0,'Water Report'!$T$10,0)) -> 7 | AQ18: =(IF('Water Report'!$T$11>0,'Water Report'!$T$11,0)) -> 6 | AR18: =(IF('Water Report'!$T$13>0,'Water Report'!$T$13,0)) -> 2 | AS18: =(IF('Water Report'!$T$14>0,'Water Report'!$T$14,0)) -> 22 | AT18: =(IF('Water Report'!$T$15>0,'Water Report'!$T$15,0)) -> 8 | AU18: =(IF('Water Report'!$T$17>0,'Water Report'!$T$17,0)) -> 0 | AV18: =(IF('Water Report'!$T$18>0,'Water Report'!$T$18,0)) -> 14 | AW18: =(IF('Water Report'!$T$19>0,'Water Report'!$T$19,0)) -> 6 | AX18: =(IF('Water Report'!$T$21>0,'Water Report'!$T$21,0)) -> 20 | AY18: =(IF('Water Report'!$T$22>0,'Water Report'!$T$22,0)) -> 0 | AZ18: =(IF('Water Report'!$T$23>0,'Water Report'!$T$23,0)) -> 0 | BA18: =(IF('Water Report'!$T$14>0,'Water Report'!$T$14,0)) -> 22 | BB18: =(IF('Water Report'!$T$15>0,'Water Report'!$T$15,0)) -> 8 | BC18: =(IF('Water Report'!$T$13>0,'Water Report'!$T$13,0)) -> 2 | BD18: =(IF('Water Report'!$T$24>0,'Water Report'!$T$24,0)) -> 76 | BE18: =(IF('Water Report'!$T$25>0,'Water Report'!$T$25,0)) -> 88 | BF18: =(IF('Water Report'!$T$27>0,'Water Report'!$T$27,0)) -> 22 | BG18: =(IF('Section Load'!AN21>0,'Section Load'!AN21,0)) -> 550 | BH18: =(IF('Section Load'!AO21>0,'Section Load'!AO21,0)) -> 214 | BI18: =(IF('Section Load'!AP21>0,'Section Load'!AP21,0)) -> 0 | BJ18: =(IF('Section Load'!AQ21>0,'Section Load'!AQ21,0)) -> 46 | BK18: =(IF('Section Load'!AR21>0,'Section Load'!AR21,0)) -> 0 | BL18: =(IF('Section Load'!AS21>0,'Section Load'!AS21,0)) -> 0 | BM18: =(IF('Section Load'!AT21>0,'Section Load'!AT21,0)) -> 290
A19: Mumbai | B19: =B18+1 -> 18 | C19: 6 | D19: 2021 | E19: =(IF('Section Load'!F22>0,'Section Load'!F22,0)) -> 1530 | F19: =(IF('Section Load'!G22>0,'Section Load'!G22,0)) -> 1254 | G19: =(IF('Section Load'!H22>0,'Section Load'!H22,0)) -> 1081 | H19: =(IF('Section Load'!I22>0,'Section Load'!I22,0)) -> 2625 | I19: =(IF('Section Load'!J22>0,'Section Load'!J22,0)) -> 5084.54 | J19: =(IF('Section Load'!K22>0,'Section Load'!K22,0)) -> 2115 | K19: =(IF('Section Load'!L22>0,'Section Load'!L22,0)) -> 802 | L19: =(IF('Section Load'!M22>0,'Section Load'!M22,0)) -> 0 | ... AL19: =(IF('Section Load'!AM22>0,'Section Load'!AM22,0)) -> 353 | AM19: =(IF('Water Report'!$U$7>0,'Water Report'!$U$7,0)) -> 0 | AN19: =(IF('Water Report'!$U$8>0,'Water Report'!$U$8,0)) -> 146 | AO19: =(IF('Water Report'!$U$9>0,'Water Report'!$U$9,0)) -> 29 | AP19: =(IF('Water Report'!$U$10>0,'Water Report'!$U$10,0)) -> 12 | AQ19: =(IF('Water Report'!$U$11>0,'Water Report'!$U$11,0)) -> 8 | AR19: =(IF('Water Report'!$U$13>0,'Water Report'!$U$13,0)) -> 4 | AS19: =(IF('Water Report'!$U$14>0,'Water Report'!$U$14,0)) -> 10 | AT19: =(IF('Water Report'!$U$15>0,'Water Report'!$U$15,0)) -> 0 | AU19: =(IF('Water Report'!$U$17>0,'Water Report'!$U$17,0)) -> 0 | AV19: =(IF('Water Report'!$U$18>0,'Water Report'!$U$18,0)) -> 0 | AW19: =(IF('Water Report'!$U$19>0,'Water Report'!$U$19,0)) -> 2 | AX19: =(IF('Water Report'!$U$21>0,'Water Report'!$U$21,0)) -> 73 | AY19: =(IF('Water Report'!$U$22>0,'Water Report'!$U$22,0)) -> 0 | AZ19: =(IF('Water Report'!$U$23>0,'Water Report'!$U$23,0)) -> 4 | BA19: =(IF('Water Report'!$U$14>0,'Water Report'!$U$14,0)) -> 10 | BB19: =(IF('Water Report'!$U$15>0,'Water Report'!$U$15,0)) -> 0 | BC19: =(IF('Water Report'!$U$13>0,'Water Report'!$U$13,0)) -> 4 | BD19: =(IF('Water Report'!$U$24>0,'Water Report'!$U$24,0)) -> 105 | BE19: =(IF('Water Report'!$U$25>0,'Water Report'!$U$25,0)) -> 59 | BF19: =(IF('Water Report'!$U$27>0,'Water Report'!$U$27,0)) -> 81 | BG19: =(IF('Section Load'!AN22>0,'Section Load'!AN22,0)) -> 550 | BH19: =(IF('Section Load'!AO22>0,'Section Load'!AO22,0)) -> 195 | BI19: =(IF('Section Load'!AP22>0,'Section Load'!AP22,0)) -> 0 | BJ19: =(IF('Section Load'!AQ22>0,'Section Load'!AQ22,0)) -> 45 | BK19: =(IF('Section Load'!AR22>0,'Section Load'!AR22,0)) -> 0 | BL19: =(IF('Section Load'!AS22>0,'Section Load'!AS22,0)) -> 0 | BM19: =(IF('Section Load'!AT22>0,'Section Load'!AT22,0)) -> 310
A20: Mumbai | B20: =B19+1 -> 19 | C20: 6 | D20: 2021 | E20: =(IF('Section Load'!F23>0,'Section Load'!F23,0)) -> 1650.87 | F20: =(IF('Section Load'!G23>0,'Section Load'!G23,0)) -> 1200 | G20: =(IF('Section Load'!H23>0,'Section Load'!H23,0)) -> 999 | H20: =(IF('Section Load'!I23>0,'Section Load'!I23,0)) -> 2579 | I20: =(IF('Section Load'!J23>0,'Section Load'!J23,0)) -> 4451.99 | J20: =(IF('Section Load'!K23>0,'Section Load'!K23,0)) -> 2088.67 | K20: =(IF('Section Load'!L23>0,'Section Load'!L23,0)) -> 793 | L20: =(IF('Section Load'!M23>0,'Section Load'!M23,0)) -> 0 | ... AL20: =(IF('Section Load'!AM23>0,'Section Load'!AM23,0)) -> 355 | AM20: =(IF('Water Report'!$V$7>0,'Water Report'!$V$7,0)) -> 0 | AN20: =(IF('Water Report'!$V$8>0,'Water Report'!$V$8,0)) -> 75 | AO20: =(IF('Water Report'!$V$9>0,'Water Report'!$V$9,0)) -> 23 | AP20: =(IF('Water Report'!$V$10>0,'Water Report'!$V$10,0)) -> 7 | AQ20: =(IF('Water Report'!$V$11>0,'Water Report'!$V$11,0)) -> 12 | AR20: =(IF('Water Report'!$V$13>0,'Water Report'!$V$13,0)) -> 11 | AS20: =(IF('Water Report'!$V$14>0,'Water Report'!$V$14,0)) -> 7 | AT20: =(IF('Water Report'!$V$15>0,'Water Report'!$V$15,0)) -> 2 | AU20: =(IF('Water Report'!$V$17>0,'Water Report'!$V$17,0)) -> 0 | AV20: =(IF('Water Report'!$V$18>0,'Water Report'!$V$18,0)) -> 0 | AW20: =(IF('Water Report'!$V$19>0,'Water Report'!$V$19,0)) -> 0 | AX20: =(IF('Water Report'!$V$21>0,'Water Report'!$V$21,0)) -> 40 | AY20: =(IF('Water Report'!$V$22>0,'Water Report'!$V$22,0)) -> 11 | AZ20: =(IF('Water Report'!$V$23>0,'Water Report'!$V$23,0)) -> 0 | BA20: =(IF('Water Report'!$V$14>0,'Water Report'!$V$14,0)) -> 7 | BB20: =(IF('Water Report'!$V$15>0,'Water Report'!$V$15,0)) -> 2 | BC20: =(IF('Water Report'!$V$13>0,'Water Report'!$V$13,0)) -> 11 | BD20: =(IF('Water Report'!$V$24>0,'Water Report'!$V$24,0)) -> 60 | BE20: =(IF('Water Report'!$V$25>0,'Water Report'!$V$25,0)) -> 51 | BF20: =(IF('Water Report'!$V$27>0,'Water Report'!$V$27,0)) -> 51 | BG20: =(IF('Section Load'!AN23>0,'Section Load'!AN23,0)) -> 550 | BH20: =(IF('Section Load'!AO23>0,'Section Load'!AO23,0)) -> 173 | BI20: =(IF('Section Load'!AP23>0,'Section Load'!AP23,0)) -> 0 | BJ20: =(IF('Section Load'!AQ23>0,'Section Load'!AQ23,0)) -> 42 | BK20: =(IF('Section Load'!AR23>0,'Section Load'!AR23,0)) -> 0 | BL20: =(IF('Section Load'!AS23>0,'Section Load'!AS23,0)) -> 0 | BM20: =(IF('Section Load'!AT23>0,'Section Load'!AT23,0)) -> 335
A21: Mumbai | B21: =B20+1 -> 20 | C21: 6 | D21: 2021 | E21: =(IF('Section Load'!F24>0,'Section Load'!F24,0)) -> 1818 | F21: =(IF('Section Load'!G24>0,'Section Load'!G24,0)) -> 1255 | G21: =(IF('Section Load'!H24>0,'Section Load'!H24,0)) -> 978 | H21: =(IF('Section Load'!I24>0,'Section Load'!I24,0)) -> 2517 | I21: =(IF('Section Load'!J24>0,'Section Load'!J24,0)) -> 4744 | J21: =(IF('Section Load'!K24>0,'Section Load'!K24,0)) -> 2118 | K21: =(IF('Section Load'!L24>0,'Section Load'!L24,0)) -> 870 | L21: =(IF('Section Load'!M24>0,'Section Load'!M24,0)) -> 0 | ... AL21: =(IF('Section Load'!AM24>0,'Section Load'!AM24,0)) -> 365 | AM21: =(IF('Water Report'!$W$7>0,'Water Report'!$W$7,0)) -> 22 | AN21: =(IF('Water Report'!$W$8>0,'Water Report'!$W$8,0)) -> 34 | AO21: =(IF('Water Report'!$W$9>0,'Water Report'!$W$9,0)) -> 27 | AP21: =(IF('Water Report'!$W$10>0,'Water Report'!$W$10,0)) -> 11 | AQ21: =(IF('Water Report'!$W$11>0,'Water Report'!$W$11,0)) -> 16 | AR21: =(IF('Water Report'!$W$13>0,'Water Report'!$W$13,0)) -> 10 | AS21: =(IF('Water Report'!$W$14>0,'Water Report'!$W$14,0)) -> 14 | AT21: =(IF('Water Report'!$W$15>0,'Water Report'!$W$15,0)) -> 3 | AU21: =(IF('Water Report'!$W$17>0,'Water Report'!$W$17,0)) -> 0 | AV21: =(IF('Water Report'!$W$18>0,'Water Report'!$W$18,0)) -> 0 | AW21: =(IF('Water Report'!$W$19>0,'Water Report'!$W$19,0)) -> 0 | AX21: =(IF('Water Report'!$W$21>0,'Water Report'!$W$21,0)) -> 39 | AY21: =(IF('Water Report'!$W$22>0,'Water Report'!$W$22,0)) -> 18 | AZ21: =(IF('Water Report'!$W$23>0,'Water Report'!$W$23,0)) -> 0 | BA21: =(IF('Water Report'!$W$14>0,'Water Report'!$W$14,0)) -> 14 | BB21: =(IF('Water Report'!$W$15>0,'Water Report'!$W$15,0)) -> 3 | BC21: =(IF('Water Report'!$W$13>0,'Water Report'!$W$13,0)) -> 10 | BD21: =(IF('Water Report'!$W$24>0,'Water Report'!$W$24,0)) -> 57 | BE21: =(IF('Water Report'!$W$25>0,'Water Report'!$W$25,0)) -> 71 | BF21: =(IF('Water Report'!$W$27>0,'Water Report'!$W$27,0)) -> 49 | BG21: =(IF('Section Load'!AN24>0,'Section Load'!AN24,0)) -> 550 | BH21: =(IF('Section Load'!AO24>0,'Section Load'!AO24,0)) -> 204 | BI21: =(IF('Section Load'!AP24>0,'Section Load'!AP24,0)) -> 0 | BJ21: =(IF('Section Load'!AQ24>0,'Section Load'!AQ24,0)) -> 48 | BK21: =(IF('Section Load'!AR24>0,'Section Load'!AR24,0)) -> 0 | BL21: =(IF('Section Load'!AS24>0,'Section Load'!AS24,0)) -> 0 | BM21: =(IF('Section Load'!AT24>0,'Section Load'!AT24,0)) -> 298
A22: Mumbai | B22: =B21+1 -> 21 | C22: 6 | D22: 2021 | E22: =(IF('Section Load'!F25>0,'Section Load'!F25,0)) -> 1843.13 | F22: =(IF('Section Load'!G25>0,'Section Load'!G25,0)) -> 1333 | G22: =(IF('Section Load'!H25>0,'Section Load'!H25,0)) -> 1150.07 | H22: =(IF('Section Load'!I25>0,'Section Load'!I25,0)) -> 2103 | I22: =(IF('Section Load'!J25>0,'Section Load'!J25,0)) -> 5144 | J22: =(IF('Section Load'!K25>0,'Section Load'!K25,0)) -> 2133 | K22: =(IF('Section Load'!L25>0,'Section Load'!L25,0)) -> 800 | L22: =(IF('Section Load'!M25>0,'Section Load'!M25,0)) -> 0 | ... AL22: =(IF('Section Load'!AM25>0,'Section Load'!AM25,0)) -> 379 | AM22: =(IF('Water Report'!$X$7>0,'Water Report'!$X$7,0)) -> 37 | AN22: =(IF('Water Report'!$X$8>0,'Water Report'!$X$8,0)) -> 83 | AO22: =(IF('Water Report'!$X$9>0,'Water Report'!$X$9,0)) -> 49 | AP22: =(IF('Water Report'!$X$10>0,'Water Report'!$X$10,0)) -> 9 | AQ22: =(IF('Water Report'!$X$11>0,'Water Report'!$X$11,0)) -> 20 | AR22: =(IF('Water Report'!$X$13>0,'Water Report'!$X$13,0)) -> 6 | AS22: =(IF('Water Report'!$X$14>0,'Water Report'!$X$14,0)) -> 4 | AT22: =(IF('Water Report'!$X$15>0,'Water Report'!$X$15,0)) -> 7 | AU22: =(IF('Water Report'!$X$17>0,'Water Report'!$X$17,0)) -> 7 | AV22: =(IF('Water Report'!$X$18>0,'Water Report'!$X$18,0)) -> 4 | AW22: =(IF('Water Report'!$X$19>0,'Water Report'!$X$19,0)) -> 5 | AX22: =(IF('Water Report'!$X$21>0,'Water Report'!$X$21,0)) -> 39 | AY22: =(IF('Water Report'!$X$22>0,'Water Report'!$X$22,0)) -> 3 | AZ22: =(IF('Water Report'!$X$23>0,'Water Report'!$X$23,0)) -> 0 | BA22: =(IF('Water Report'!$X$14>0,'Water Report'!$X$14,0)) -> 4 | BB22: =(IF('Water Report'!$X$15>0,'Water Report'!$X$15,0)) -> 7 | BC22: =(IF('Water Report'!$X$13>0,'Water Report'!$X$13,0)) -> 6 | BD22: =(IF('Water Report'!$X$24>0,'Water Report'!$X$24,0)) -> 96 | BE22: =(IF('Water Report'!$X$25>0,'Water Report'!$X$25,0)) -> 89 | BF22: =(IF('Water Report'!$X$27>0,'Water Report'!$X$27,0)) -> 45 | BG22: =(IF('Section Load'!AN25>0,'Section Load'!AN25,0)) -> 550 | BH22: =(IF('Section Load'!AO25>0,'Section Load'!AO25,0)) -> 194 | BI22: =(IF('Section Load'!AP25>0,'Section Load'!AP25,0)) -> 0 | BJ22: =(IF('Section Load'!AQ25>0,'Section Load'!AQ25,0)) -> 67 | BK22: =(IF('Section Load'!AR25>0,'Section Load'!AR25,0)) -> 0 | BL22: =(IF('Section Load'!AS25>0,'Section Load'!AS25,0)) -> 0 | BM22: =(IF('Section Load'!AT25>0,'Section Load'!AT25,0)) -> 289
A23: Mumbai | B23: =B22+1 -> 22 | C23: 6 | D23: 2021 | E23: =(IF('Section Load'!F26>0,'Section Load'!F26,0)) -> 1920 | F23: =(IF('Section Load'!G26>0,'Section Load'!G26,0)) -> 1372 | G23: =(IF('Section Load'!H26>0,'Section Load'!H26,0)) -> 1280 | H23: =(IF('Section Load'!I26>0,'Section Load'!I26,0)) -> 3496 | I23: =(IF('Section Load'!J26>0,'Section Load'!J26,0)) -> 6030 | J23: =(IF('Section Load'!K26>0,'Section Load'!K26,0)) -> 2210 | K23: =(IF('Section Load'!L26>0,'Section Load'!L26,0)) -> 918 | L23: =(IF('Section Load'!M26>0,'Section Load'!M26,0)) -> 0 | ... AL23: =(IF('Section Load'!AM26>0,'Section Load'!AM26,0)) -> 451 | AM23: =(IF('Water Report'!$Y$7>0,'Water Report'!$Y$7,0)) -> 63 | AN23: =(IF('Water Report'!$Y$8>0,'Water Report'!$Y$8,0)) -> 101 | AO23: =(IF('Water Report'!$Y$9>0,'Water Report'!$Y$9,0)) -> 80 | AP23: =(IF('Water Report'!$Y$10>0,'Water Report'!$Y$10,0)) -> 9 | AQ23: =(IF('Water Report'!$Y$11>0,'Water Report'!$Y$11,0)) -> 25 | AR23: =(IF('Water Report'!$Y$13>0,'Water Report'!$Y$13,0)) -> 13 | AS23: =(IF('Water Report'!$Y$14>0,'Water Report'!$Y$14,0)) -> 10 | AT23: =(IF('Water Report'!$Y$15>0,'Water Report'!$Y$15,0)) -> 17 | AU23: =(IF('Water Report'!$Y$17>0,'Water Report'!$Y$17,0)) -> 4 | AV23: =(IF('Water Report'!$Y$18>0,'Water Report'!$Y$18,0)) -> 13 | AW23: =(IF('Water Report'!$Y$19>0,'Water Report'!$Y$19,0)) -> 4 | AX23: =(IF('Water Report'!$Y$21>0,'Water Report'!$Y$21,0)) -> 40 | AY23: =(IF('Water Report'!$Y$22>0,'Water Report'!$Y$22,0)) -> 26 | AZ23: =(IF('Water Report'!$Y$23>0,'Water Report'!$Y$23,0)) -> 14 | BA23: =(IF('Water Report'!$Y$14>0,'Water Report'!$Y$14,0)) -> 10 | BB23: =(IF('Water Report'!$Y$15>0,'Water Report'!$Y$15,0)) -> 17 | BC23: =(IF('Water Report'!$Y$13>0,'Water Report'!$Y$13,0)) -> 13 | BD23: =(IF('Water Report'!$Y$24>0,'Water Report'!$Y$24,0)) -> 150 | BE23: =(IF('Water Report'!$Y$25>0,'Water Report'!$Y$25,0)) -> 141 | BF23: =(IF('Water Report'!$Y$27>0,'Water Report'!$Y$27,0)) -> 67 | BG23: =(IF('Section Load'!AN26>0,'Section Load'!AN26,0)) -> 550 | BH23: =(IF('Section Load'!AO26>0,'Section Load'!AO26,0)) -> 194 | BI23: =(IF('Section Load'!AP26>0,'Section Load'!AP26,0)) -> 0 | BJ23: =(IF('Section Load'!AQ26>0,'Section Load'!AQ26,0)) -> 64 | BK23: =(IF('Section Load'!AR26>0,'Section Load'!AR26,0)) -> 0 | BL23: =(IF('Section Load'!AS26>0,'Section Load'!AS26,0)) -> 0 | BM23: =(IF('Section Load'!AT26>0,'Section Load'!AT26,0)) -> 292
