Workbook

Sheet Total
A1: Site Name | B1: Day | C1: Month | D1: Year | E1: Total Electricity Kwh | F1: Electricity Tariff ($/Kwh) | G1: Total Fuel Oil (Liters) | H1: Fuel Oil $/Liter | I1: LPG (Kg) | J1: LPG $/Kg | K1: Water Utility Supply (m3) m3 | L1: Water Utility Supply (m3) $/m3 | M1: Irrigation Water (m3) m3 | N1: Irrigation water $/m3 | O1: Room Nights
A2: Beirut | B2: 1 | C2: 6 | D2: 2021 | E2: =ELEC!N4 -> 10480.6 | F2: =SUM('EDl log'!T4) -> 0.44676948 | G2: =-tanks!AW6 -> 107 | H2: =SUM(tanks!AV6) -> 1.003 | I2: =('B5'!AU5)*0.51 -> 0 | J2: ='B5'!AX5/0.51 -> 1.5686275 | K2: =WATER!I6 -> 0 | L2: =SUM(WATER!J6) -> 0 | M2: =WATER!Q6 -> 0 | N2: 0.6 | O2: =ELEC!B4 -> 0
A3: Beirut | B3: =B2+1 -> 2 | C3: 6 | D3: 2021 | E3: =ELEC!N5 -> 12363.8 | F3: =SUM('EDl log'!T5) -> 0.19803241 | G3: =-tanks!AW7 -> 128 | H3: =SUM(tanks!AV7) -> 1.003 | I3: =('B5'!AU6)*0.51 -> 0 | J3: ='B5'!AX6/0.51 -> 1.5686275 | K3: =WATER!I7 -> 109 | L3: =SUM(WATER!J7) -> 2.293578 | M3: =WATER!Q7 -> 0 | N3: 0.6 | O3: =ELEC!B5 -> 0
A4: Beirut | B4: =B3+1 -> 3 | C4: 6 | D4: 2021 | E4: =ELEC!N6 -> 15101 | F4: =SUM('EDl log'!T6) -> 0.1465717 | G4: =-tanks!AW8 -> 125 | H4: =SUM(tanks!AV8) -> 1.003 | I4: =('B5'!AU7)*0.51 -> 0 | J4: ='B5'!AX7/0.51 -> 1.5686275 | K4: =WATER!I8 -> 0 | L4: =SUM(WATER!J8) -> 0 | M4: =WATER!Q8 -> 0 | N4: 0.6 | O4: =ELEC!B6 -> 0
A5: Beirut | B5: =B4+1 -> 4 | C5: 6 | D5: 2021 | E5: =ELEC!N7 -> 16108.6 | F5: =SUM('EDl log'!T7) -> 0.19955771 | G5: =-tanks!AW9 -> 91 | H5: =SUM(tanks!AV9) -> 1.003 | I5: =('B5'!AU8)*0.51 -> 0 | J5: ='B5'!AX8/0.51 -> 1.5686275 | K5: =WATER!I9 -> 0 | L5: =SUM(WATER!J9) -> 0 | M5: =WATER!Q9 -> 0 | N5: 0.6 | O5: =ELEC!B7 -> 0
A6: Beirut | B6: =B5+1 -> 5 | C6: 6 | D6: 2021 | E6: =ELEC!N8 -> 12066 | F6: =SUM('EDl log'!T8) -> 0.44758356 | G6: =-tanks!AW10 -> 242 | H6: =SUM(tanks!AV10) -> 1.003 | I6: =('B5'!AU9)*0.51 -> 0 | J6: ='B5'!AX9/0.51 -> 1.5686275 | K6: =WATER!I10 -> 0 | L6: =SUM(WATER!J10) -> 0 | M6: =WATER!Q10 -> 0 | N6: 0.6 | O6: =ELEC!B8 -> 0
A7: Beirut | B7: =B6+1 -> 6 | C7: 6 | D7: 2021 | E7: =ELEC!N9 -> 11919 | F7: =SUM('EDl log'!T9) -> 0.35022596 | G7: =-tanks!AW11 -> 192 | H7: =SUM(tanks!AV11) -> 1.003 | I7: =('B5'!AU10)*0.51 -> 0 | J7: ='B5'!AX10/0.51 -> 1.5686275 | K7: =WATER!I11 -> 0 | L7: =SUM(WATER!J11) -> 0 | M7: =WATER!Q11 -> 0 | N7: 0.6 | O7: =ELEC!B9 -> 0
A8: Beirut | B8: =B7+1 -> 7 | C8: 6 | D8: 2021 | E8: =ELEC!N10 -> 15761 | F8: =SUM('EDl log'!T10) -> 0.16054063 | G8: =-tanks!AW12 -> 54 | H8: =SUM(tanks!AV12) -> 1.003 | I8: =('B5'!AU11)*0.51 -> 0 | J8: ='B5'!AX11/0.51 -> 1.5686275 | K8: =WATER!I12 -> 0 | L8: =SUM(WATER!J12) -> 0 | M8: =WATER!Q12 -> 0 | N8: 0.6 | O8: =ELEC!B10 -> 0
A9: Beirut | B9: =B8+1 -> 8 | C9: 6 | D9: 2021 | E9: =ELEC!N11 -> 11896 | F9: =SUM('EDl log'!T11) -> 0.31853204 | G9: =-tanks!AW13 -> 158 | H9: =SUM(tanks!AV13) -> 1.003 | I9: =('B5'!AU12)*0.51 -> 0 | J9: ='B5'!AX12/0.51 -> 1.5686275 | K9: =WATER!I13 -> 0 | L9: =SUM(WATER!J13) -> 0 | M9: =WATER!Q13 -> 0 | N9: 0.6 | O9: =ELEC!B11 -> 0
A10: Beirut | B10: =B9+1 -> 9 | C10: 6 | D10: 2021 | E10: =ELEC!N12 -> 13733 | F10: =SUM('EDl log'!T12) -> 0.36711189 | G10: =-tanks!AW14 -> 110 | H10: =SUM(tanks!AV14) -> 1.003 | I10: =('B5'!AU13)*0.51 -> 0 | J10: ='B5'!AX13/0.51 -> 1.5686275 | K10: =WATER!I14 -> 0 | L10: =SUM(WATER!J14) -> 0 | M10: =WATER!Q14 -> 0 | N10: 0.6 | O10: =ELEC!B12 -> 0
A11: Beirut | B11: =B10+1 -> 10 | C11: 6 | D11: 2021 | E11: =ELEC!N13 -> 14893 | F11: =SUM('EDl log'!T13) -> 0.1097534 | G11: =-tanks!AW15 -> 115 | H11: =SUM(tanks!AV15) -> 1.05 | I11: =('B5'!AU14)*0.51 -> 0 | J11: ='B5'!AX14/0.51 -> 1.5686275 | K11: =WATER!I15 -> 0 | L11: =SUM(WATER!J15) -> 0 | M11: =WATER!Q15 -> 0 | N11: 0.6 | O11: =ELEC!B13 -> 0
A12: Beirut | B12: =B11+1 -> 11 | C12: 6 | D12: 2021 | E12: =ELEC!N14 -> 14674 | F12: =SUM('EDl log'!T14) -> 0.35841243 | G12: =-tanks!AW16 -> 135 | H12: =SUM(tanks!AV16) -> 1.05 | I12: =('B5'!AU15)*0.51 -> 0 | J12: ='B5'!AX15/0.51 -> 1.5686275 | K12: =WATER!I16 -> 0 | L12: =SUM(WATER!J16) -> 0 | M12: =WATER!Q16 -> 0 | N12: 0.6 | O12: =ELEC!B14 -> 0
A13: Beirut | B13: =B12+1 -> 12 | C13: 6 | D13: 2021 | E13: =ELEC!N15 -> 12497 | F13: =SUM('EDl log'!T15) -> 0.25953867 | G13: =-tanks!AW17 -> 200 | H13: =SUM(tanks!AV17) -> 1.05 | I13: =('B5'!AU16)*0.51 -> 0 | J13: ='B5'!AX16/0.51 -> 1.5686275 | K13: =WATER!I17 -> 0 | L13: =SUM(WATER!J17) -> 0 | M13: =WATER!Q17 -> 0 | N13: 0.6 | O13: =ELEC!B15 -> 0
A14: Beirut | B14: =B13+1 -> 13 | C14: 6 | D14: 2021 | E14: =ELEC!N16 -> 12554 | F14: =SUM('EDl log'!T16) -> 0.38243213 | G14: =-tanks!AW18 -> 48 | H14: =SUM(tanks!AV18) -> 1.05 | I14: =('B5'!AU17)*0.51 -> 0 | J14: ='B5'!AX17/0.51 -> 1.5686275 | K14: =WATER!I18 -> 0 | L14: =SUM(WATER!J18) -> 0 | M14: =WATER!Q18 -> 0 | N14: 0.6 | O14: =ELEC!B16 -> 0
... A31: Beirut | B31: =B30+1 -> 30 | C31: 6 | D31: 2021 | E31: =ELEC!N33 -> 0 | F31: =SUM('EDl log'!T33) -> 0 | G31: =-tanks!AW35 -> 0 | H31: =SUM(tanks!AV35) -> 1.05 | I31: =('B5'!AU34)*0.51 -> 0 | J31: ='B5'!AX34/0.51 -> 1.5686275 | K31: =WATER!I35 -> 0 | L31: =SUM(WATER!J35) -> 0 | M31: =WATER!Q35 -> 0 | N31: 0.6 | O31: =ELEC!B33 -> 0

Sheet Submetering
A1: Site Name | B1: Day | C1: Month | D1: Year | E1: ATS1 Kwh | F1: ATS2 Kwh | G1: ATS3 Kwh | H1: ATS4 Kwh | I1: ATS5 Kwh | J1: Guest (m3) | K1: Kitchen & Laundry (m3) | L1: Room Nights
A2: Beirut | B2: 1 | C2: 6 | D2: 2021 | E2: =ELEC!M4 -> 1550 | F2: =ELEC!K4 -> 4758 | G2: =ELEC!I4 -> 742 | H2: =ELEC!E4 -> 2955 | I2: =ELEC!G4 -> 475.6 | J2: =WATER!Y6 -> 0 | K2: =WATER!AJ6 -> 0 | L2: =ELEC!B4 -> 0
A3: Beirut | B3: =B2+1 -> 2 | C3: 6 | D3: 2021 | E3: =ELEC!M5 -> 2160 | F3: =ELEC!K5 -> 5676 | G3: =ELEC!I5 -> 1106 | H3: =ELEC!E5 -> 2595 | I3: =ELEC!G5 -> 826.8 | J3: =WATER!Y7 -> 0 | K3: =WATER!AJ7 -> 0 | L3: =ELEC!B5 -> 0
A4: Beirut | B4: =B3+1 -> 3 | C4: 6 | D4: 2021 | E4: =ELEC!M6 -> 2288 | F4: =ELEC!K6 -> 7130 | G4: =ELEC!I6 -> 1112 | H4: =ELEC!E6 -> 3813 | I4: =ELEC!G6 -> 758 | J4: =WATER!Y8 -> 0 | K4: =WATER!AJ8 -> 0 | L4: =ELEC!B6 -> 0
A5: Beirut | B5: =B4+1 -> 4 | C5: 6 | D5: 2021 | E5: =ELEC!M7 -> 2664 | F5: =ELEC!K7 -> 7574 | G5: =ELEC!I7 -> 1174 | H5: =ELEC!E7 -> 3811 | I5: =ELEC!G7 -> 885.6 | J5: =WATER!Y9 -> 0 | K5: =WATER!AJ9 -> 0 | L5: =ELEC!B7 -> 0
A6: Beirut | B6: =B5+1 -> 5 | C6: 6 | D6: 2021 | E6: =ELEC!M8 -> 2118 | F6: =ELEC!K8 -> 5928 | G6: =ELEC!I8 -> 836 | H6: =ELEC!E8 -> 2604 | I6: =ELEC!G8 -> 580 | J6: =WATER!Y10 -> 0 | K6: =WATER!AJ10 -> 0 | L6: =ELEC!B8 -> 0
A7: Beirut | B7: =B6+1 -> 6 | C7: 6 | D7: 2021 | E7: =ELEC!M9 -> 2196 | F7: =ELEC!K9 -> 5372 | G7: =ELEC!I9 -> 790 | H7: =ELEC!E9 -> 2885 | I7: =ELEC!G9 -> 676 | J7: =WATER!Y11 -> 0 | K7: =WATER!AJ11 -> 0 | L7: =ELEC!B9 -> 0
A8: Beirut | B8: =B7+1 -> 7 | C8: 6 | D8: 2021 | E8: =ELEC!M10 -> 2410 | F8: =ELEC!K10 -> 7914 | G8: =ELEC!I10 -> 946 | H8: =ELEC!E10 -> 3742 | I8: =ELEC!G10 -> 749 | J8: =WATER!Y12 -> 0 | K8: =WATER!AJ12 -> 0 | L8: =ELEC!B10 -> 0
A9: Beirut | B9: =B8+1 -> 8 | C9: 6 | D9: 2021 | E9: =ELEC!M11 -> 2102 | F9: =ELEC!K11 -> 5162 | G9: =ELEC!I11 -> 880 | H9: =ELEC!E11 -> 3014 | I9: =ELEC!G11 -> 738 | J9: =WATER!Y13 -> 0 | K9: =WATER!AJ13 -> 0 | L9: =ELEC!B11 -> 0
A10: Beirut | B10: =B9+1 -> 9 | C10: 6 | D10: 2021 | E10: =ELEC!M12 -> 2354 | F10: =ELEC!K12 -> 6288 | G10: =ELEC!I12 -> 1038 | H10: =ELEC!E12 -> 3346 | I10: =ELEC!G12 -> 707 | J10: =WATER!Y14 -> 0 | K10: =WATER!AJ14 -> 0 | L10: =ELEC!B12 -> 0
A11: Beirut | B11: =B10+1 -> 10 | C11: 6 | D11: 2021 | E11: =ELEC!M13 -> 2492 | F11: =ELEC!K13 -> 4428 | G11: =ELEC!I13 -> 1016 | H11: =ELEC!E13 -> 6244 | I11: =ELEC!G13 -> 713 | J11: =WATER!Y15 -> 0 | K11: =WATER!AJ15 -> 0 | L11: =ELEC!B13 -> 0
A12: Beirut | B12: =B11+1 -> 11 | C12: 6 | D12: 2021 | E12: =ELEC!M14 -> 2600 | F12: =ELEC!K14 -> 2772 | G12: =ELEC!I14 -> 966 | H12: =ELEC!E14 -> 7647 | I12: =ELEC!G14 -> 689 | J12: =WATER!Y16 -> 0 | K12: =WATER!AJ16 -> 0 | L12: =ELEC!B14 -> 0
A13: Beirut | B13: =B12+1 -> 12 | C13: 6 | D13: 2021 | E13: =ELEC!M15 -> 2178 | F13: =ELEC!K15 -> 2518 | G13: =ELEC!I15 -> 940 | H13: =ELEC!E15 -> 6192 | I13: =ELEC!G15 -> 669 | J13: =WATER!Y17 -> 0 | K13: =WATER!AJ17 -> 0 | L13: =ELEC!B15 -> 0
A14: Beirut | B14: =B13+1 -> 13 | C14: 6 | D14: 2021 | E14: =ELEC!M16 -> 2500 | F14: =ELEC!K16 -> 2238 | G14: =ELEC!I16 -> 1014 | H14: =ELEC!E16 -> 6129 | I14: =ELEC!G16 -> 673 | J14: =WATER!Y18 -> 0 | K14: =WATER!AJ18 -> 0 | L14: =ELEC!B16 -> 0
... A31: Beirut | B31: =B30+1 -> 30 | C31: 6 | D31: 2021 | E31: =ELEC!M33 -> 0 | F31: =ELEC!K33 -> 0 | G31: =ELEC!I33 -> 0 | H31: =ELEC!E33 -> 0 | I31: =ELEC!G33 -> 0 | J31: =WATER!Y35 -> 0 | K31: =WATER!AJ35 -> 0 | L31: =ELEC!B33 -> 0
D45: .

Sheet ELEC
AK1: ATS 4 till power meter is for MDB 3 is replaced
A2: OOC | B2: Room OCC | D2: MDB3 | E2: MDB3/day | F2: EMDB2 | G2: EMDB2/day | H2: EMDB1 | I2: EMDB1/day | J2: MDB2 | K2: mdb2/day | L2: MDB1 | M2: MDB1/Day | N2: Total KWH | O2: KWH/Rooc | P2: Gen MHW | Q2: Gen/Day KWH | R2: EDL KWH | S2: CH1 RH | T2: RH | U2: C1h1 power | V2: CH1 Con KWH | W2: CH2 RH | X2: RH | Y2: Ch2 power | Z2: CH2 Con KWH | AA2: CH3 RH | AB2: RH | AC2: Ch3 power | AD2: CH3 Con KWH | AE2: RH total | AF2: KWH total | AG2: AVG chiller KW/Hr | AK2: Emergency | AL2: Normal | AM2: Total | AN2: Difference
A3: =[1]ELEC!$A$33 -> 0 | B3: =[1]ELEC!$B$33 -> 0 | C3: 44347 | D3: =[2]ELEC!D33 -> 32911138 | E3: =[2]ELEC!E33 -> 4709 | F3: =[2]ELEC!F33 -> 4031450 | G3: =[2]ELEC!G33 -> 1057 | H3: =[2]ELEC!H33 -> 17884320 | I3: =[2]ELEC!I33 -> 1442 | J3: =[2]ELEC!J33 -> 29123928 | K3: =[2]ELEC!K33 -> 9050 | ... AG3: =[2]ELEC!AG33 -> 236.41667 | AI3: =[2]ELEC!AI33 -> -1051635 | AJ3: 44347 | AK3: 333631 | AL3: 431020 | AM3: =AK3+AL3 -> 764651 | AN3: 4709
A4: ='General information '!F6 -> 0 | B4: =SUM(230*A4) -> 0 | C4: 44348 | D4: =D3 -> 32911138 | E4: =AN4 -> 2955 | F4: 4031925.6 | G4: =F4-F3 -> 475.6 | H4: 17885062 | I4: =H4-H3 -> 742 | J4: 29128686 | K4: =J4-J3 -> 4758 | L4: 24237542 | M4: =L4-L3 -> 1550 | N4: =M4+K4+I4+G4+E4 -> 10480.6 | O4: =IF(B4>0,N4/B4,0) -> 0 | P4: 17216.967 | Q4: =(P4-P3)*1000 -> 9515 | R4: =+N4-Q4 -> 965.6 | S4: =S3 -> 10175 | T4: =S4-S3 -> 0 | U4: =U3 -> 429166 | V4: =U4-U3 -> 0 | W4: 32562 | X4: =W4-W3 -> 20 | Y4: 775030 | Z4: =Y4-Y3 -> 4098 | AA4: =AA3 -> 35939 | AB4: =AA4-AA3 -> 0 | AC4: =AC3 -> 961645 | AD4: =AC4-AC3 -> 0 | AE4: =AB4+X4+T4 -> 20 | AF4: =V4+Z4+AD4 -> 4098 | AG4: =IF(AE4>0,AF4/AE4,0) -> 204.9 | AI4: =R4-'EDl log'!B4 -> -1057209.4 | AJ4: 44348 | AK4: 335894 | AL4: 431712 | AM4: =AK4+AL4 -> 767606 | AN4: =AM4-AM3 -> 2955
A5: ='General information '!F7 -> 0 | B5: =SUM(230*A5) -> 0 | C5: 44349 | D5: =D4 -> 32911138 | E5: =AN5 -> 2595 | F5: 4032752.4 | G5: =F5-F4 -> 826.8 | H5: 17886168 | I5: =H5-H4 -> 1106 | J5: 29134362 | K5: =J5-J4 -> 5676 | L5: 24239702 | M5: =L5-L4 -> 2160 | N5: =M5+K5+I5+G5+E5 -> 12363.8 | O5: =IF(B5>0,N5/B5,0) -> 0 | P5: 17227.848 | Q5: =(P5-P4)*1000 -> 10881 | R5: =N5-Q5 -> 1482.8 | S5: =S4 -> 10175 | T5: =S5-S4 -> 0 | U5: =U4 -> 429166 | V5: =U5-U4 -> 0 | W5: 32576 | X5: =W5-W4 -> 14 | Y5: 777894 | Z5: =Y5-Y4 -> 2864 | AA5: =AA4 -> 35939 | AB5: =AA5-AA4 -> 0 | AC5: =AC4 -> 961645 | AD5: =AC5-AC4 -> 0 | AE5: =AB5+X5+T5 -> 14 | AF5: =V5+Z5+AD5 -> 2864 | AG5: =IF(AE5>0,AF5/AE5,0) -> 204.57143 | AI5: =R5-'EDl log'!B5 -> -1057880.2 | AJ5: 44349 | AK5: 338482 | AL5: 431719 | AM5: =AK5+AL5 -> 770201 | AN5: =AM5-AM4 -> 2595
A6: ='General information '!F8 -> 0 | B6: =SUM(230*A6) -> 0 | C6: 44350 | D6: =D5 -> 32911138 | E6: =AN6 -> 3813 | F6: 4033510.4 | G6: =F6-F5 -> 758 | H6: 17887280 | I6: =H6-H5 -> 1112 | J6: 29141492 | K6: =J6-J5 -> 7130 | L6: 24241990 | M6: =L6-L5 -> 2288 | N6: =M6+K6+I6+G6+E6 -> 15101 | O6: =IF(B6>0,N6/B6,0) -> 0 | P6: 17242.466 | Q6: =(P6-P5)*1000 -> 14618 | R6: =N6-Q6 -> 483 | S6: =S5 -> 10175 | T6: =S6-S5 -> 0 | U6: =U5 -> 429166 | V6: =U6-U5 -> 0 | W6: 32593 | X6: =W6-W5 -> 17 | Y6: 781232 | Z6: =Y6-Y5 -> 3338 | AA6: =AA5 -> 35939 | AB6: =AA6-AA5 -> 0 | AC6: =AC5 -> 961645 | AD6: =AC6-AC5 -> 0 | AE6: =AB6+X6+T6 -> 17 | AF6: =V6+Z6+AD6 -> 3338 | AG6: =IF(AE6>0,AF6/AE6,0) -> 196.35294 | AI6: =R6-'EDl log'!B6 -> -1059322 | AJ6: 44350 | AK6: 342095 | AL6: 431919 | AM6: =AK6+AL6 -> 774014 | AN6: =AM6-AM5 -> 3813
A7: ='General information '!F9 -> 0 | B7: =SUM(230*A7) -> 0 | C7: 44351 | D7: =D6 -> 32911138 | E7: =AN7 -> 3811 | F7: 4034396 | G7: =F7-F6 -> 885.6 | H7: 17888454 | I7: =H7-H6 -> 1174 | J7: 29149066 | K7: =J7-J6 -> 7574 | L7: 24244654 | M7: =L7-L6 -> 2664 | N7: =M7+K7+I7+G7+E7 -> 16108.6 | O7: =IF(B7>0,N7/B7,0) -> 0 | P7: 17256.524 | Q7: =(P7-P6)*1000 -> 14058 | R7: =N7-Q7 -> 2050.6 | S7: =S6 -> 10175 | T7: =S7-S6 -> 0 | U7: =U6 -> 429166 | V7: =U7-U6 -> 0 | W7: 32605 | X7: =W7-W6 -> 12 | Y7: 783620 | Z7: =Y7-Y6 -> 2388 | AA7: =AA6 -> 35939 | AB7: =AA7-AA6 -> 0 | AC7: =AC6 -> 961645 | AD7: =AC7-AC6 -> 0 | AE7: =AB7+X7+T7 -> 12 | AF7: =V7+Z7+AD7 -> 2388 | AG7: =IF(AE7>0,AF7/AE7,0) -> 199 | AI7: =R7-'EDl log'!B7 -> -1057754.4 | AJ7: 44351 | AK7: 345431 | AL7: 432394 | AM7: =AK7+AL7 -> 777825 | AN7: =AM7-AM6 -> 3811
A8: ='General information '!F10 -> 0 | B8: =SUM(230*A8) -> 0 | C8: 44352 | D8: =D7 -> 32911138 | E8: =AN8 -> 2604 | F8: 4034976 | G8: =F8-F7 -> 580 | H8: 17889290 | I8: =H8-H7 -> 836 | J8: 29154994 | K8: =J8-J7 -> 5928 | L8: 24246772 | M8: =L8-L7 -> 2118 | N8: =M8+K8+I8+G8+E8 -> 12066 | O8: =IF(B8>0,N8/B8,0) -> 0 | P8: 17268.334 | Q8: =(P8-P7)*1000 -> 11810 | R8: =N8-Q8 -> 256 | S8: =S7 -> 10175 | T8: =S8-S7 -> 0 | U8: =U7 -> 429166 | V8: =U8-U7 -> 0 | W8: 32623 | X8: =W8-W7 -> 18 | Y8: 787323 | Z8: =Y8-Y7 -> 3703 | AA8: =AA7 -> 35939 | AB8: =AA8-AA7 -> 0 | AC8: =AC7 -> 961645 | AD8: =AC8-AC7 -> 0 | AE8: =AB8+X8+T8 -> 18 | AF8: =V8+Z8+AD8 -> 3703 | AG8: =IF(AE8>0,AF8/AE8,0) -> 205.72222 | AI8: =R8-'EDl log'!B8 -> -1061198 | AJ8: 44352 | AK8: 348088 | AL8: 432341 | AM8: =AK8+AL8 -> 780429 | AN8: =AM8-AM7 -> 2604
A9: ='General information '!F11 -> 0 | B9: =SUM(230*A9) -> 0 | C9: 44353 | D9: =D8 -> 32911138 | E9: =AN9 -> 2885 | F9: 4035652 | G9: =F9-F8 -> 676 | H9: 17890080 | I9: =H9-H8 -> 790 | J9: 29160366 | K9: =J9-J8 -> 5372 | L9: 24248968 | M9: =L9-L8 -> 2196 | N9: =M9+K9+I9+G9+E9 -> 11919 | O9: =IF(B9>0,N9/B9,0) -> 0 | P9: 17279.31 | Q9: =(P9-P8)*1000 -> 10976 | R9: =N9-Q9 -> 943 | S9: =S8 -> 10175 | T9: =S9-S8 -> 0 | U9: =U8 -> 429166 | V9: =U9-U8 -> 0 | W9: 32636 | X9: =W9-W8 -> 13 | Y9: 789812 | Z9: =Y9-Y8 -> 2489 | AA9: =AA8 -> 35939 | AB9: =AA9-AA8 -> 0 | AC9: =AC8 -> 961645 | AD9: =AC9-AC8 -> 0 | AE9: =AB9+X9+T9 -> 13 | AF9: =V9+Z9+AD9 -> 2489 | AG9: =IF(AE9>0,AF9/AE9,0) -> 191.46154 | AI9: =R9-'EDl log'!B9 -> -1061021 | AJ9: 44353 | AK9: 350597 | AL9: 432717 | AM9: =AK9+AL9 -> 783314 | AN9: =AM9-AM8 -> 2885
A10: ='General information '!F12 -> 0 | B10: =SUM(230*A10) -> 0 | C10: 44354 | D10: =D9 -> 32911138 | E10: =AN10 -> 3742 | F10: 4036401 | G10: =F10-F9 -> 749 | H10: 17891026 | I10: =H10-H9 -> 946 | J10: 29168280 | K10: =J10-J9 -> 7914 | L10: 24251378 | M10: =L10-L9 -> 2410 | N10: =M10+K10+I10+G10+E10 -> 15761 | O10: =IF(B10>0,N10/B10,0) -> 0 | P10: 17294.434 | Q10: =(P10-P9)*1000 -> 15124 | R10: =N10-Q10 -> 637 | S10: =S9 -> 10175 | T10: =S10-S9 -> 0 | U10: =U9 -> 429166 | V10: =U10-U9 -> 0 | W10: 32655 | X10: =W10-W9 -> 19 | Y10: 794074 | Z10: =Y10-Y9 -> 4262 | AA10: =AA9 -> 35939 | AB10: =AA10-AA9 -> 0 | AC10: =AC9 -> 961645 | AD10: =AC10-AC9 -> 0 | AE10: =AB10+X10+T10 -> 19 | AF10: =V10+Z10+AD10 -> 4262 | AG10: =IF(AE10>0,AF10/AE10,0) -> 224.31579 | AI10: =R10-'EDl log'!B10 -> -1061805 | AJ10: 44354 | AK10: 354127 | AL10: 432929 | AM10: =AK10+AL10 -> 787056 | AN10: =AM10-AM9 -> 3742
A11: ='General information '!F13 -> 0 | B11: =SUM(230*A11) -> 0 | C11: 44355 | D11: =D10 -> 32911138 | E11: =AN11 -> 3014 | F11: 4037139 | G11: =F11-F10 -> 738 | H11: 17891906 | I11: =H11-H10 -> 880 | J11: 29173442 | K11: =J11-J10 -> 5162 | L11: 24253480 | M11: =L11-L10 -> 2102 | N11: =M11+K11+I11+G11+E11 -> 11896 | O11: =IF(B11>0,N11/B11,0) -> 0 | P11: 17304.765 | Q11: =(P11-P10)*1000 -> 10331 | R11: =N11-Q11 -> 1565 | S11: =S10 -> 10175 | T11: =S11-S10 -> 0 | U11: =U10 -> 429166 | V11: =U11-U10 -> 0 | W11: 32669 | X11: =W11-W10 -> 14 | Y11: 796836 | Z11: =Y11-Y10 -> 2762 | AA11: =AA10 -> 35939 | AB11: =AA11-AA10 -> 0 | AC11: =AC10 -> 961645 | AD11: =AC11-AC10 -> 0 | AE11: =AB11+X11+T11 -> 14 | AF11: =V11+Z11+AD11 -> 2762 | AG11: =IF(AE11>0,AF11/AE11,0) -> 197.28571 | AI11: =R11-'EDl log'!B11 -> -1061837 | AJ11: 44355 | AK11: 356725 | AL11: 433345 | AM11: =AK11+AL11 -> 790070 | AN11: =AM11-AM10 -> 3014
A12: ='General information '!F14 -> 0 | B12: =SUM(230*A12) -> 0 | C12: 44356 | D12: =D11 -> 32911138 | E12: =AN12 -> 3346 | F12: 4037846 | G12: =F12-F11 -> 707 | H12: 17892944 | I12: =H12-H11 -> 1038 | J12: 29179730 | K12: =J12-J11 -> 6288 | L12: 24255834 | M12: =L12-L11 -> 2354 | N12: =M12+K12+I12+G12+E12 -> 13733 | O12: =IF(B12>0,N12/B12,0) -> 0 | P12: 17318.005 | Q12: =(P12-P11)*1000 -> 13240 | R12: =N12-Q12 -> 493 | S12: =S11 -> 10175 | T12: =S12-S11 -> 0 | U12: =U11 -> 429166 | V12: =U12-U11 -> 0 | W12: 32684 | X12: =W12-W11 -> 15 | Y12: 800305 | Z12: =Y12-Y11 -> 3469 | AA12: =AA11 -> 35939 | AB12: =AA12-AA11 -> 0 | AC12: =AC11 -> 961645 | AD12: =AC12-AC11 -> 0 | AE12: =AB12+X12+T12 -> 15 | AF12: =V12+Z12+AD12 -> 3469 | AG12: =IF(AE12>0,AF12/AE12,0) -> 231.26667 | AI12: =R12-'EDl log'!B12 -> -1063311 | AJ12: 44356 | AK12: 359901 | AL12: 433515 | AM12: =AK12+AL12 -> 793416 | AN12: =AM12-AM11 -> 3346
A13: ='General information '!F15 -> 0 | B13: =SUM(230*A13) -> 0 | C13: 44357 | D13: =D12 -> 32911138 | E13: =AN13 -> 6244 | F13: 4038559 | G13: =F13-F12 -> 713 | H13: 17893960 | I13: =H13-H12 -> 1016 | J13: 29184158 | K13: =J13-J12 -> 4428 | L13: 24258326 | M13: =L13-L12 -> 2492 | N13: =M13+K13+I13+G13+E13 -> 14893 | O13: =IF(B13>0,N13/B13,0) -> 0 | P13: 17331.902 | Q13: =(P13-P12)*1000 -> 13897 | R13: =N13-Q13 -> 996 | S13: =S12 -> 10175 | T13: =S13-S12 -> 0 | U13: =U12 -> 429166 | V13: =U13-U12 -> 0 | W13: 32691 | X13: =W13-W12 -> 7 | Y13: 801841 | Z13: =Y13-Y12 -> 1536 | AA13: 35950 | AB13: =AA13-AA12 -> 11 | AC13: 964432 | AD13: =AC13-AC12 -> 2787 | AE13: =AB13+X13+T13 -> 18 | AF13: =V13+Z13+AD13 -> 4323 | AG13: =IF(AE13>0,AF13/AE13,0) -> 240.16667 | AI13: =R13-'EDl log'!B13 -> -1063501 | AJ13: 44357 | AK13: 365855 | AL13: 433805 | AM13: =AK13+AL13 -> 799660 | AN13: =AM13-AM12 -> 6244
A14: ='General information '!F16 -> 0 | B14: =SUM(230*A14) -> 0 | C14: 44358 | D14: =D13 -> 32911138 | E14: =AN14 -> 7647 | F14: 4039248 | G14: =F14-F13 -> 689 | H14: 17894926 | I14: =H14-H13 -> 966 | J14: 29186930 | K14: =J14-J13 -> 2772 | L14: 24260926 | M14: =L14-L13 -> 2600 | N14: =M14+K14+I14+G14+E14 -> 14674 | O14: =IF(B14>0,N14/B14,0) -> 0 | P14: 17345.992 | Q14: =(P14-P13)*1000 -> 14090 | R14: =N14-Q14 -> 584 | S14: =S13 -> 10175 | T14: =S14-S13 -> 0 | U14: =U13 -> 429166 | V14: =U14-U13 -> 0 | W14: =W13 -> 32691 | X14: =W14-W13 -> 0 | Y14: =Y13 -> 801841 | Z14: =Y14-Y13 -> 0 | AA14: 35967 | AB14: =AA14-AA13 -> 17 | AC14: 968167 | AD14: =AC14-AC13 -> 3735 | AE14: =AB14+X14+T14 -> 17 | AF14: =V14+Z14+AD14 -> 3735 | AG14: =IF(AE14>0,AF14/AE14,0) -> 219.70588 | AI14: =R14-'EDl log'!B14 -> -1064389 | AJ14: 44358 | AK14: 373315 | AL14: 433992 | AM14: =AK14+AL14 -> 807307 | AN14: =AM14-AM13 -> 7647
A15: ='General information '!F17 -> 0 | B15: =SUM(230*A15) -> 0 | C15: 44359 | D15: =D14 -> 32911138 | E15: =AN15 -> 6192 | F15: 4039917 | G15: =F15-F14 -> 669 | H15: 17895866 | I15: =H15-H14 -> 940 | J15: 29189448 | K15: =J15-J14 -> 2518 | L15: 24263104 | M15: =L15-L14 -> 2178 | N15: =M15+K15+I15+G15+E15 -> 12497 | O15: =IF(B15>0,N15/B15,0) -> 0 | P15: 17357.442 | Q15: =(P15-P14)*1000 -> 11450 | R15: =N15-Q15 -> 1047 | S15: =S14 -> 10175 | T15: =S15-S14 -> 0 | U15: =U14 -> 429166 | V15: =U15-U14 -> 0 | W15: =W14 -> 32691 | X15: =W15-W14 -> 0 | Y15: =Y14 -> 801841 | Z15: =Y15-Y14 -> 0 | AA15: 35982 | AB15: =AA15-AA14 -> 15 | AC15: 971276 | AD15: =AC15-AC14 -> 3109 | AE15: =AB15+X15+T15 -> 15 | AF15: =V15+Z15+AD15 -> 3109 | AG15: =IF(AE15>0,AF15/AE15,0) -> 207.26667 | AI15: =R15-'EDl log'!B15 -> -1064651 | AJ15: 44359 | AK15: 379256 | AL15: 434243 | AM15: =AK15+AL15 -> 813499 | AN15: =AM15-AM14 -> 6192
A16: ='General information '!F18 -> 0 | B16: =SUM(230*A16) -> 0 | C16: 44360 | D16: =D15 -> 32911138 | E16: =AN16 -> 6129 | F16: 4040590 | G16: =F16-F15 -> 673 | H16: 17896880 | I16: =H16-H15 -> 1014 | J16: 29191686 | K16: =J16-J15 -> 2238 | L16: 24265604 | M16: =L16-L15 -> 2500 | N16: =M16+K16+I16+G16+E16 -> 12554 | O16: =IF(B16>0,N16/B16,0) -> 0 | P16: 17370.71 | Q16: =(P16-P15)*1000 -> 13268 | R16: =N16-Q16 -> -714 | S16: =S15 -> 10175 | T16: =S16-S15 -> 0 | U16: =U15 -> 429166 | V16: =U16-U15 -> 0 | W16: 32691 | X16: =W16-W15 -> 0 | Y16: =Y15 -> 801841 | Z16: =Y16-Y15 -> 0 | AA16: 35999 | AB16: =AA16-AA15 -> 17 | AC16: 974628 | AD16: =AC16-AC15 -> 3352 | AE16: =AB16+X16+T16 -> 17 | AF16: =V16+Z16+AD16 -> 3352 | AG16: =IF(AE16>0,AF16/AE16,0) -> 197.17647 | AI16: =R16-'EDl log'!B16 -> -1066998 | AJ16: 44360 | AK16: 385143 | AL16: 434485 | AM16: =AK16+AL16 -> 819628 | AN16: =AM16-AM15 -> 6129
A17: ='General information '!F19 -> 0 | B17: =SUM(230*A17) -> 0 | C17: 44361 | D17: =D16 -> 32911138 | E17: =AN17 -> 5834 | F17: 4041248 | G17: =F17-F16 -> 658 | H17: 17897710 | I17: =H17-H16 -> 830 | J17: 29193802 | K17: =J17-J16 -> 2116 | L17: 24267546 | M17: =L17-L16 -> 1942 | N17: =M17+K17+I17+G17+E17 -> 11380 | O17: =IF(B17>0,N17/B17,0) -> 0 | P17: 17379.304 | Q17: =(P17-P16)*1000 -> 8594 | R17: =N17-Q17 -> 2786 | S17: =S16 -> 10175 | T17: =S17-S16 -> 0 | U17: =U16 -> 429166 | V17: =U17-U16 -> 0 | W17: 32691 | X17: =W17-W16 -> 0 | Y17: =Y16 -> 801841 | Z17: =Y17-Y16 -> 0 | AA17: 36014 | AB17: =AA17-AA16 -> 15 | AC17: 977695 | AD17: =AC17-AC16 -> 3067 | AE17: =AB17+X17+T17 -> 15 | AF17: =V17+Z17+AD17 -> 3067 | AG17: =IF(AE17>0,AF17/AE17,0) -> 204.46667 | AI17: =R17-'EDl log'!B17 -> -1064217 | AJ17: 44361 | AK17: 390620 | AL17: 434842 | AM17: =AK17+AL17 -> 825462 | AN17: =AM17-AM16 -> 5834
A18: ='General information '!F20 -> 0 | B18: =SUM(230*A18) -> 0 | C18: 44362 | D18: =D17 -> 32911138 | E18: =AN18 -> 4340 | F18: 4041954 | G18: =F18-F17 -> 706 | H18: 17898706 | I18: =H18-H17 -> 996 | J18: 29198626 | K18: =J18-J17 -> 4824 | L18: 24269870 | M18: =L18-L17 -> 2324 | N18: =M18+K18+I18+G18+E18 -> 13190 | O18: =IF(B18>0,N18/B18,0) -> 0 | P18: 17391.748 | Q18: =(P18-P17)*1000 -> 12444 | R18: =N18-Q18 -> 746 | S18: =S17 -> 10175 | T18: =S18-S17 -> 0 | U18: =U17 -> 429166 | V18: =U18-U17 -> 0 | W18: 32702 | X18: =W18-W17 -> 11 | Y18: 804179 | Z18: =Y18-Y17 -> 2338 | AA18: 36020 | AB18: =AA18-AA17 -> 6 | AC18: 978935 | AD18: =AC18-AC17 -> 1240 | AE18: =AB18+X18+T18 -> 17 | AF18: =V18+Z18+AD18 -> 3578 | AG18: =IF(AE18>0,AF18/AE18,0) -> 210.47059 | AI18: =R18-'EDl log'!B18 -> -1066782 | AJ18: 44362 | AK18: 394712 | AL18: 435090 | AM18: =AK18+AL18 -> 829802 | AN18: =AM18-AM17 -> 4340
A19: ='General information '!F21 -> 0 | B19: =SUM(230*A19) -> 0 | C19: 44363 | D19: =D18 -> 32911138 | E19: =AN19 -> 4710 | F19: 4042661 | G19: =F19-F18 -> 707 | H19: 17899744 | I19: =H19-H18 -> 1038 | J19: 29202094 | K19: =J19-J18 -> 3468 | L19: 24272214 | M19: =L19-L18 -> 2344 | N19: =M19+K19+I19+G19+E19 -> 12267 | O19: =IF(B19>0,N19/B19,0) -> 0 | P19: 17405.023 | Q19: =(P19-P18)*1000 -> 13275 | R19: =N19-Q19 -> -1008 | S19: =S18 -> 10175 | T19: =S19-S18 -> 0 | U19: =U18 -> 429166 | V19: =U19-U18 -> 0 | W19: 32709 | X19: =W19-W18 -> 7 | Y19: 805616 | Z19: =Y19-Y18 -> 1437 | AA19: 36028 | AB19: =AA19-AA18 -> 8 | AC19: 980604 | AD19: =AC19-AC18 -> 1669 | AE19: =AB19+X19+T19 -> 15 | AF19: =V19+Z19+AD19 -> 3106 | AG19: =IF(AE19>0,AF19/AE19,0) -> 207.06667 | AI19: =R19-'EDl log'!B19 -> -1069350 | AJ19: 44363 | AK19: 399112 | AL19: 435400 | AM19: =AK19+AL19 -> 834512 | AN19: =AM19-AM18 -> 4710
A20: ='General information '!F22 -> 0 | B20: =SUM(230*A20) -> 0 | C20: 44364 | D20: =D19 -> 32911138 | E20: =AN20 -> 6488 | F20: 4043434 | G20: =F20-F19 -> 773 | H20: 17900838 | I20: =H20-H19 -> 1094 | J20: 29204422 | K20: =J20-J19 -> 2328 | L20: 24274486 | M20: =L20-L19 -> 2272 | N20: =M20+K20+I20+G20+E20 -> 12955 | O20: =IF(B20>0,N20/B20,0) -> 0 | P20: 17415.1 | Q20: =(P20-P19)*1000 -> 10077 | R20: =N20-Q20 -> 2878 | S20: =S19 -> 10175 | T20: =S20-S19 -> 0 | U20: =U19 -> 429166 | V20: =U20-U19 -> 0 | W20: 32709 | X20: =W20-W19 -> 0 | Y20: =Y19 -> 805616 | Z20: =Y20-Y19 -> 0 | AA20: 36044 | AB20: =AA20-AA19 -> 16 | AC20: 983863 | AD20: =AC20-AC19 -> 3259 | AE20: =AB20+X20+T20 -> 16 | AF20: =V20+Z20+AD20 -> 3259 | AG20: =IF(AE20>0,AF20/AE20,0) -> 203.6875 | AI20: =R20-'EDl log'!B20 -> -1065945 | AJ20: 44364 | AK20: 405216 | AL20: 435784 | AM20: =AK20+AL20 -> 841000 | AN20: =AM20-AM19 -> 6488
A21: ='General information '!F23 -> 0 | B21: =SUM(230*A21) -> 0 | C21: 44365 | D21: =D20 -> 32911138 | E21: =AN21 -> 0 | F21: =F20 -> 4043434 | G21: =F21-F20 -> 0 | H21: =H20 -> 17900838 | I21: =H21-H20 -> 0 | J21: =J20 -> 29204422 | K21: =J21-J20 -> 0 | L21: =L20 -> 24274486 | M21: =L21-L20 -> 0 | N21: =M21+K21+I21+G21+E21 -> 0 | O21: =IF(B21>0,N21/B21,0) -> 0 | P21: =P20 -> 17415.1 | Q21: =(P21-P20)*1000 -> 0 | R21: =N21-Q21 -> 0 | S21: =S20 -> 10175 | T21: =S21-S20 -> 0 | U21: =U20 -> 429166 | V21: =U21-U20 -> 0 | W21: =W20 -> 32709 | X21: =W21-W20 -> 0 | Y21: =Y20 -> 805616 | Z21: =Y21-Y20 -> 0 | AA21: =AA20 -> 36044 | AB21: =AA21-AA20 -> 0 | AC21: =AC20 -> 983863 | AD21: =AC21-AC20 -> 0 | AE21: =AB21+X21+T21 -> 0 | AF21: =V21+Z21+AD21 -> 0 | AG21: =IF(AE21>0,AF21/AE21,0) -> 0 | AI21: =R21-'EDl log'!B21 -> -1068823 | AJ21: 44365 | AK21: =AK20 -> 405216 | AL21: =AL20 -> 435784 | AM21: =AK21+AL21 -> 841000 | AN21: =AM21-AM20 -> 0
A22: ='General information '!F24 -> 0 | B22: =SUM(230*A22) -> 0 | C22: 44366 | D22: =D21 -> 32911138 | E22: =AN22 -> 0 | F22: =F21 -> 4043434 | G22: =F22-F21 -> 0 | H22: =H21 -> 17900838 | I22: =H22-H21 -> 0 | J22: =J21 -> 29204422 | K22: =J22-J21 -> 0 | L22: =L21 -> 24274486 | M22: =L22-L21 -> 0 | N22: =M22+K22+I22+G22+E22 -> 0 | O22: =IF(B22>0,N22/B22,0) -> 0 | P22: =P21 -> 17415.1 | Q22: =(P22-P21)*1000 -> 0 | R22: =N22-Q22 -> 0 | S22: =S21 -> 10175 | T22: =S22-S21 -> 0 | U22: =U21 -> 429166 | V22: =U22-U21 -> 0 | W22: =W21 -> 32709 | X22: =W22-W21 -> 0 | Y22: =Y21 -> 805616 | Z22: =Y22-Y21 -> 0 | AA22: =AA21 -> 36044 | AB22: =AA22-AA21 -> 0 | AC22: =AC21 -> 983863 | AD22: =AC22-AC21 -> 0 | AE22: =AB22+X22+T22 -> 0 | AF22: =V22+Z22+AD22 -> 0 | AG22: =IF(AE22>0,AF22/AE22,0) -> 0 | AI22: =R22-'EDl log'!B22 -> -1068823 | AJ22: 44366 | AK22: =AK21 -> 405216 | AL22: =AL21 -> 435784 | AM22: =AK22+AL22 -> 841000 | AN22: =AM22-AM21 -> 0
A23: ='General information '!F25 -> 0 | B23: =SUM(230*A23) -> 0 | C23: 44367 | D23: =D22 -> 32911138 | E23: =AN23 -> 0 | F23: =F22 -> 4043434 | G23: =F23-F22 -> 0 | H23: =H22 -> 17900838 | I23: =H23-H22 -> 0 | J23: =J22 -> 29204422 | K23: =J23-J22 -> 0 | L23: =L22 -> 24274486 | M23: =L23-L22 -> 0 | N23: =M23+K23+I23+G23+E23 -> 0 | O23: =IF(B23>0,N23/B23,0) -> 0 | P23: =P22 -> 17415.1 | Q23: =(P23-P22)*1000 -> 0 | R23: =N23-Q23 -> 0 | S23: =S22 -> 10175 | T23: =S23-S22 -> 0 | U23: =U22 -> 429166 | V23: =U23-U22 -> 0 | W23: =W22 -> 32709 | X23: =W23-W22 -> 0 | Y23: =Y22 -> 805616 | Z23: =Y23-Y22 -> 0 | AA23: =AA22 -> 36044 | AB23: =AA23-AA22 -> 0 | AC23: =AC22 -> 983863 | AD23: =AC23-AC22 -> 0 | AE23: =AB23+X23+T23 -> 0 | AF23: =V23+Z23+AD23 -> 0 | AG23: =IF(AE23>0,AF23/AE23,0) -> 0 | AI23: =R23-'EDl log'!B23 -> -1068823 | AJ23: 44367 | AK23: =AK22 -> 405216 | AL23: =AL22 -> 435784 | AM23: =AK23+AL23 -> 841000 | AN23: =AM23-AM22 -> 0
A24: ='General information '!F26 -> 0 | B24: =SUM(230*A24) -> 0 | C24: 44368 | D24: =D23 -> 32911138 | E24: =AN24 -> 0 | F24: =F23 -> 4043434 | G24: =F24-F23 -> 0 | H24: =H23 -> 17900838 | I24: =H24-H23 -> 0 | J24: =J23 -> 29204422 | K24: =J24-J23 -> 0 | L24: =L23 -> 24274486 | M24: =L24-L23 -> 0 | N24: =M24+K24+I24+G24+E24 -> 0 | O24: =IF(B24>0,N24/B24,0) -> 0 | P24: =P23 -> 17415.1 | Q24: =(P24-P23)*1000 -> 0 | R24: =N24-Q24 -> 0 | S24: =S23 -> 10175 | T24: =S24-S23 -> 0 | U24: =U23 -> 429166 | V24: =U24-U23 -> 0 | W24: =W23 -> 32709 | X24: =W24-W23 -> 0 | Y24: =Y23 -> 805616 | Z24: =Y24-Y23 -> 0 | AA24: =AA23 -> 36044 | AB24: =AA24-AA23 -> 0 | AC24: =AC23 -> 983863 | AD24: =AC24-AC23 -> 0 | AE24: =AB24+X24+T24 -> 0 | AF24: =V24+Z24+AD24 -> 0 | AG24: =IF(AE24>0,AF24/AE24,0) -> 0 | AI24: =R24-'EDl log'!B24 -> -1068823 | AJ24: 44368 | AK24: =AK23 -> 405216 | AL24: =AL23 -> 435784 | AM24: =AK24+AL24 -> 841000 | AN24: =AM24-AM23 -> 0
A25: ='General information '!F27 -> 0 | B25: =SUM(230*A25) -> 0 | C25: 44369 | D25: =D24 -> 32911138 | E25: =AN25 -> 0 | F25: =F24 -> 4043434 | G25: =F25-F24 -> 0 | H25: =H24 -> 17900838 | I25: =H25-H24 -> 0 | J25: =J24 -> 29204422 | K25: =J25-J24 -> 0 | L25: =L24 -> 24274486 | M25: =L25-L24 -> 0 | N25: =M25+K25+I25+G25+E25 -> 0 | O25: =IF(B25>0,N25/B25,0) -> 0 | P25: =P24 -> 17415.1 | Q25: =(P25-P24)*1000 -> 0 | R25: =N25-Q25 -> 0 | S25: =S24 -> 10175 | T25: =S25-S24 -> 0 | U25: =U24 -> 429166 | V25: =U25-U24 -> 0 | W25: =W24 -> 32709 | X25: =W25-W24 -> 0 | Y25: =Y24 -> 805616 | Z25: =Y25-Y24 -> 0 | AA25: =AA24 -> 36044 | AB25: =AA25-AA24 -> 0 | AC25: =AC24 -> 983863 | AD25: =AC25-AC24 -> 0 | AE25: =AB25+X25+T25 -> 0 | AF25: =V25+Z25+AD25 -> 0 | AG25: =IF(AE25>0,AF25/AE25,0) -> 0 | AI25: =R25-'EDl log'!B25 -> -1068823 | AJ25: 44369 | AK25: =AK24 -> 405216 | AL25: =AL24 -> 435784 | AM25: =AK25+AL25 -> 841000 | AN25: =AM25-AM24 -> 0
A26: ='General information '!F28 -> 0 | B26: =SUM(230*A26) -> 0 | C26: 44370 | D26: =D25 -> 32911138 | E26: =AN26 -> 0 | F26: =F25 -> 4043434 | G26: =F26-F25 -> 0 | H26: =H25 -> 17900838 | I26: =H26-H25 -> 0 | J26: =J25 -> 29204422 | K26: =J26-J25 -> 0 | L26: =L25 -> 24274486 | M26: =L26-L25 -> 0 | N26: =M26+K26+I26+G26+E26 -> 0 | O26: =IF(B26>0,N26/B26,0) -> 0 | P26: =P25 -> 17415.1 | Q26: =(P26-P25)*1000 -> 0 | R26: =N26-Q26 -> 0 | S26: =S25 -> 10175 | T26: =S26-S25 -> 0 | U26: =U25 -> 429166 | V26: =U26-U25 -> 0 | W26: =W25 -> 32709 | X26: =W26-W25 -> 0 | Y26: =Y25 -> 805616 | Z26: =Y26-Y25 -> 0 | AA26: =AA25 -> 36044 | AB26: =AA26-AA25 -> 0 | AC26: =AC25 -> 983863 | AD26: =AC26-AC25 -> 0 | AE26: =AB26+X26+T26 -> 0 | AF26: =V26+Z26+AD26 -> 0 | AG26: =IF(AE26>0,AF26/AE26,0) -> 0 | AI26: =R26-'EDl log'!B26 -> -1068823 | AJ26: 44370 | AK26: =AK25 -> 405216 | AL26: =AL25 -> 435784 | AM26: =AK26+AL26 -> 841000 | AN26: =AM26-AM25 -> 0
A27: ='General information '!F29 -> 0 | B27: =SUM(230*A27) -> 0 | C27: 44371 | D27: =D26 -> 32911138 | E27: =AN27 -> 0 | F27: =F26 -> 4043434 | G27: =F27-F26 -> 0 | H27: =H26 -> 17900838 | I27: =H27-H26 -> 0 | J27: =J26 -> 29204422 | K27: =J27-J26 -> 0 | L27: =L26 -> 24274486 | M27: =L27-L26 -> 0 | N27: =M27+K27+I27+G27+E27 -> 0 | O27: =IF(B27>0,N27/B27,0) -> 0 | P27: =P26 -> 17415.1 | Q27: =(P27-P26)*1000 -> 0 | R27: =N27-Q27 -> 0 | S27: =S26 -> 10175 | T27: =S27-S26 -> 0 | U27: =U26 -> 429166 | V27: =U27-U26 -> 0 | W27: =W26 -> 32709 | X27: =W27-W26 -> 0 | Y27: =Y26 -> 805616 | Z27: =Y27-Y26 -> 0 | AA27: =AA26 -> 36044 | AB27: =AA27-AA26 -> 0 | AC27: =AC26 -> 983863 | AD27: =AC27-AC26 -> 0 | AE27: =AB27+X27+T27 -> 0 | AF27: =V27+Z27+AD27 -> 0 | AG27: =IF(AE27>0,AF27/AE27,0) -> 0 | AI27: =R27-'EDl log'!B27 -> -1068823 | AJ27: 44371 | AK27: =AK26 -> 405216 | AL27: =AL26 -> 435784 | AM27: =AK27+AL27 -> 841000 | AN27: =AM27-AM26 -> 0
A28: ='General information '!F30 -> 0 | B28: =SUM(230*A28) -> 0 | C28: 44372 | D28: =D27 -> 32911138 | E28: =AN28 -> 0 | F28: =F27 -> 4043434 | G28: =F28-F27 -> 0 | H28: =H27 -> 17900838 | I28: =H28-H27 -> 0 | J28: =J27 -> 29204422 | K28: =J28-J27 -> 0 | L28: =L27 -> 24274486 | M28: =L28-L27 -> 0 | N28: =M28+K28+I28+G28+E28 -> 0 | O28: =IF(B28>0,N28/B28,0) -> 0 | P28: =P27 -> 17415.1 | Q28: =(P28-P27)*1000 -> 0 | R28: =N28-Q28 -> 0 | S28: =S27 -> 10175 | T28: =S28-S27 -> 0 | U28: =U27 -> 429166 | V28: =U28-U27 -> 0 | W28: =W27 -> 32709 | X28: =W28-W27 -> 0 | Y28: =Y27 -> 805616 | Z28: =Y28-Y27 -> 0 | AA28: =AA27 -> 36044 | AB28: =AA28-AA27 -> 0 | AC28: =AC27 -> 983863 | AD28: =AC28-AC27 -> 0 | AE28: =AB28+X28+T28 -> 0 | AF28: =V28+Z28+AD28 -> 0 | AG28: =IF(AE28>0,AF28/AE28,0) -> 0 | AI28: =R28-'EDl log'!B28 -> -1068823 | AJ28: 44372 | AK28: =AK27 -> 405216 | AL28: =AL27 -> 435784 | AM28: =AK28+AL28 -> 841000 | AN28: =AM28-AM27 -> 0
A29: ='General information '!F31 -> 0 | B29: =SUM(230*A29) -> 0 | C29: 44373 | D29: =D28 -> 32911138 | E29: =AN29 -> 0 | F29: =F28 -> 4043434 | G29: =F29-F28 -> 0 | H29: =H28 -> 17900838 | I29: =H29-H28 -> 0 | J29: =J28 -> 29204422 | K29: =J29-J28 -> 0 | L29: =L28 -> 24274486 | M29: =L29-L28 -> 0 | N29: =M29+K29+I29+G29+E29 -> 0 | O29: =IF(B29>0,N29/B29,0) -> 0 | P29: =P28 -> 17415.1 | Q29: =(P29-P28)*1000 -> 0 | R29: =N29-Q29 -> 0 | S29: =S28 -> 10175 | T29: =S29-S28 -> 0 | U29: =U28 -> 429166 | V29: =U29-U28 -> 0 | W29: =W28 -> 32709 | X29: =W29-W28 -> 0 | Y29: =Y28 -> 805616 | Z29: =Y29-Y28 -> 0 | AA29: =AA28 -> 36044 | AB29: =AA29-AA28 -> 0 | AC29: =AC28 -> 983863 | AD29: =AC29-AC28 -> 0 | AE29: =AB29+X29+T29 -> 0 | AF29: =V29+Z29+AD29 -> 0 | AG29: =IF(AE29>0,AF29/AE29,0) -> 0 | AI29: =R29-'EDl log'!B29 -> -1068823 | AJ29: 44373 | AK29: =AK28 -> 405216 | AL29: =AL28 -> 435784 | AM29: =AK29+AL29 -> 841000 | AN29: =AM29-AM28 -> 0
A30: ='General information '!F32 -> 0 | B30: =SUM(230*A30) -> 0 | C30: 44374 | D30: =D29 -> 32911138 | E30: =AN30 -> 0 | F30: =F29 -> 4043434 | G30: =F30-F29 -> 0 | H30: =H29 -> 17900838 | I30: =H30-H29 -> 0 | J30: =J29 -> 29204422 | K30: =J30-J29 -> 0 | L30: =L29 -> 24274486 | M30: =L30-L29 -> 0 | N30: =M30+K30+I30+G30+E30 -> 0 | O30: =IF(B30>0,N30/B30,0) -> 0 | P30: =P29 -> 17415.1 | Q30: =(P30-P29)*1000 -> 0 | R30: =N30-Q30 -> 0 | S30: =S29 -> 10175 | T30: =S30-S29 -> 0 | U30: =U29 -> 429166 | V30: =U30-U29 -> 0 | W30: =W29 -> 32709 | X30: =W30-W29 -> 0 | Y30: =Y29 -> 805616 | Z30: =Y30-Y29 -> 0 | AA30: =AA29 -> 36044 | AB30: =AA30-AA29 -> 0 | AC30: =AC29 -> 983863 | AD30: =AC30-AC29 -> 0 | AE30: =AB30+X30+T30 -> 0 | AF30: =V30+Z30+AD30 -> 0 | AG30: =IF(AE30>0,AF30/AE30,0) -> 0 | AI30: =R30-'EDl log'!B30 -> -1068823 | AJ30: 44374 | AK30: =AK29 -> 405216 | AL30: =AL29 -> 435784 | AM30: =AK30+AL30 -> 841000 | AN30: =AM30-AM29 -> 0
A31: ='General information '!F33 -> 0 | B31: =SUM(230*A31) -> 0 | C31: 44375 | D31: =D30 -> 32911138 | E31: =AN31 -> 0 | F31: =F30 -> 4043434 | G31: =F31-F30 -> 0 | H31: =H30 -> 17900838 | I31: =H31-H30 -> 0 | J31: =J30 -> 29204422 | K31: =J31-J30 -> 0 | L31: =L30 -> 24274486 | M31: =L31-L30 -> 0 | N31: =M31+K31+I31+G31+E31 -> 0 | O31: =IF(B31>0,N31/B31,0) -> 0 | P31: =P30 -> 17415.1 | Q31: =(P31-P30)*1000 -> 0 | R31: =N31-Q31 -> 0 | S31: =S30 -> 10175 | T31: =S31-S30 -> 0 | U31: =U30 -> 429166 | V31: =U31-U30 -> 0 | W31: =W30 -> 32709 | X31: =W31-W30 -> 0 | Y31: =Y30 -> 805616 | Z31: =Y31-Y30 -> 0 | AA31: =AA30 -> 36044 | AB31: =AA31-AA30 -> 0 | AC31: =AC30 -> 983863 | AD31: =AC31-AC30 -> 0 | AE31: =AB31+X31+T31 -> 0 | AF31: =V31+Z31+AD31 -> 0 | AG31: =IF(AE31>0,AF31/AE31,0) -> 0 | AI31: =R31-'EDl log'!B31 -> -1068823 | AJ31: 44375 | AK31: =AK30 -> 405216 | AL31: =AL30 -> 435784 | AM31: =AK31+AL31 -> 841000 | AN31: =AM31-AM30 -> 0
A32: ='General information '!F34 -> 0 | B32: =SUM(230*A32) -> 0 | C32: 44376 | D32: =D31 -> 32911138 | E32: =AN32 -> 0 | F32: =F31 -> 4043434 | G32: =F32-F31 -> 0 | H32: =H31 -> 17900838 | I32: =H32-H31 -> 0 | J32: =J31 -> 29204422 | K32: =J32-J31 -> 0 | L32: =L31 -> 24274486 | M32: =L32-L31 -> 0 | N32: =M32+K32+I32+G32+E32 -> 0 | O32: =IF(B32>0,N32/B32,0) -> 0 | P32: =P31 -> 17415.1 | Q32: =(P32-P31)*1000 -> 0 | R32: =N32-Q32 -> 0 | S32: =S31 -> 10175 | T32: =S32-S31 -> 0 | U32: =U31 -> 429166 | V32: =U32-U31 -> 0 | W32: =W31 -> 32709 | X32: =W32-W31 -> 0 | Y32: =Y31 -> 805616 | Z32: =Y32-Y31 -> 0 | AA32: =AA31 -> 36044 | AB32: =AA32-AA31 -> 0 | AC32: =AC31 -> 983863 | AD32: =AC32-AC31 -> 0 | AE32: =AB32+X32+T32 -> 0 | AF32: =V32+Z32+AD32 -> 0 | AG32: =IF(AE32>0,AF32/AE32,0) -> 0 | AI32: =R32-'EDl log'!B32 -> -1068823 | AJ32: 44376 | AK32: =AK31 -> 405216 | AL32: =AL31 -> 435784 | AM32: =AK32+AL32 -> 841000 | AN32: =AM32-AM31 -> 0
A33: ='General information '!F35 -> 0 | B33: =SUM(230*A33) -> 0 | C33: 44377 | D33: =D32 -> 32911138 | E33: =AN33 -> 0 | F33: =F32 -> 4043434 | G33: =F33-F32 -> 0 | H33: =H32 -> 17900838 | I33: =H33-H32 -> 0 | J33: =J32 -> 29204422 | K33: =J33-J32 -> 0 | L33: =L32 -> 24274486 | M33: =L33-L32 -> 0 | N33: =M33+K33+I33+G33+E33 -> 0 | O33: =IF(B33>0,N33/B33,0) -> 0 | P33: =P32 -> 17415.1 | Q33: =(P33-P32)*1000 -> 0 | R33: =N33-Q33 -> 0 | S33: =S32 -> 10175 | T33: =S33-S32 -> 0 | U33: =U32 -> 429166 | V33: =U33-U32 -> 0 | W33: =W32 -> 32709 | X33: =W33-W32 -> 0 | Y33: =Y32 -> 805616 | Z33: =Y33-Y32 -> 0 | AA33: =AA32 -> 36044 | AB33: =AA33-AA32 -> 0 | AC33: =AC32 -> 983863 | AD33: =AC33-AC32 -> 0 | AE33: =AB33+X33+T33 -> 0 | AF33: =V33+Z33+AD33 -> 0 | AG33: =IF(AE33>0,AF33/AE33,0) -> 0 | AI33: =R33-'EDl log'!B33 -> -1068823 | AJ33: 44377 | AK33: =AK32 -> 405216 | AL33: =AL32 -> 435784 | AM33: =AK33+AL33 -> 841000 | AN33: =AM33-AM32 -> 0

Sheet B5
F1: Boiler A | J1: =J35 -> 63.722222 | K1: Boiler B | P1: Boiler C | V1: Boiler | X1: SteamA | AC1: SteamB | AH1: Steam | AI1: Boiler & steam | AL1: Total Boiler Runing H | AM1: Total Steam Runing H | AN1: GAS1 % | AO1: GAS1/L | AP1: GAS2% | AQ1: Gas2/L | AR1: GAS3% | AS1: GAS3/L | AU1: Gas Cons | AV1: Delivery | AW1: Cost/L
B2: Level Tank Gen | C2: Level tank Boiler | D2: Daily Cons Bo. | E2: Boiler litter | F2: Boiler A | G2: Run Hr a | H2: Boiler A fuel | I2: Daily consumption | J2: AVG | K2: index Run H | L2: Run Hrb | M2: Boiler B Fuel | O2: Daily consumption | P2: Boiler C | S2: Run C | U2: Total RH | V2: Total Fuel | X2: SteamA | Y2: Run SA | Z2: Steam A Conter | AA2: Liters | AC2: SteamB | AD2: Run SteamB | AE2: Steam B Conter | AF2: SB Litters | AG2: Avg | AH2: Total Fuel | AI2: Total Fuel
S3: 0
A4: =ELEC!C3 -> 44347 | B4: =[3]B5!B35 -> 207 | C4: =[3]B5!C35 -> 214 | D4: =[3]B5!D35 -> -27 | E4: =[3]B5!E35 -> -226.26 | F4: =[3]B5!F35 -> 1841 | G4: =[3]B5!G35 -> 1 | H4: =[3]B5!H35 -> 13408 | I4: =[3]B5!I35 -> 96 | ... AX4: =[3]B5!AX35 -> 0.8
A5: =ELEC!C4 -> 44348 | B5: 191 | C5: 204 | D5: =C4-C5 -> 10 | E5: =D5*8.38 -> 83.8 | F5: =F4 -> 1841 | G5: =F5-F4 -> 0 | H5: 13425 | I5: =SUM(H5-H4) -> 17 | J5: 1 | K5: =K4 -> 2331 | L5: =K5-K4 -> 0 | M5: =M4 -> 171898 | N5: =M5-M4 -> 0 | O5: =O4 -> 1869 | P5: =P4 -> 2096 | Q5: 176252 | R5: =Q5-Q4 -> 46 | S5: =SUM(P5-P4) -> 0 | T5: =SUM(S5*$T$2) -> 0 | U5: =SUM(G5+L5+S5) -> 0 | V5: =R5+N5+I5:I5 -> 63 | W5: =SUM(V5/U5) -> #DIV/0! | X5: 2469 | Y5: =X5-X4 -> 0 | Z5: 138993 | AA5: =Z5-Z4 -> 0 | AB5: =SUM(Y5*$AB$2) -> 0 | AC5: =AC4 -> 1937 | AD5: =AC5-AC4 -> 0 | AE5: 365634 | AF5: =AE5-AE4 -> 44 | AG5: =IF(AD5>0,AF5/AD5,0) -> 0 | AH5: =AF5+AA5 -> 44 | AI5: =SUM(AH5+V5) -> 107 | AJ5: =-tanks!AW6 -> 107 | AK5: =SUM(AJ5-AI5) -> 0 | AL5: =S5+L5+G5 -> 0 | AM5: =Y5+AD5 -> 0 | AN5: =AN4 -> 67 | AO5: =(AN5/100)*3000 -> 2010 | AP5: =AP4 -> 55 | AQ5: =(AP5/100)*3000 -> 1650 | AR5: =AR4 -> 61 | AS5: =(AR5/100)*3000 -> 1830 | AT5: =SUM(AO5+AQ5+AS5) -> 5490 | AU5: =AT4-AT5+AV5 -> 0 | AX5: =IF(AV5>0,AW5,AX4) -> 0.8
A6: =ELEC!C5 -> 44349 | B6: 185 | C6: 192 | D6: =C5-C6 -> 12 | E6: =D6*8.38 -> 100.56 | F6: 1842 | G6: =F6-F5 -> 1 | H6: 13519 | I6: =SUM(H6-H5) -> 94 | J6: =IF(G6>0,I6/G6,0) -> 94 | K6: =K5 -> 2331 | L6: =K6-K5 -> 0 | M6: =M5 -> 171898 | N6: =M6-M5 -> 0 | O6: =O5 -> 1869 | P6: 2097 | Q6: 176286 | R6: =Q6-Q5 -> 34 | S6: =SUM(P6-P5) -> 1 | T6: =SUM(S6*$T$2) -> 0 | U6: =SUM(G6+L6+S6) -> 2 | V6: =R6+N6+I6:I6 -> 128 | W6: =SUM(V6/U6) -> 64 | X6: =X5 -> 2469 | Y6: =X6-X5 -> 0 | Z6: =Z5 -> 138993 | AA6: =Z6-Z5 -> 0 | AB6: =SUM(Y6*$AB$2) -> 0 | AC6: =AC5 -> 1937 | AD6: =AC6-AC5 -> 0 | AE6: =AE5 -> 365634 | AF6: =AE6-AE5 -> 0 | AG6: =IF(AD6>0,AF6/AD6,0) -> 0 | AH6: =AF6+AA6 -> 0 | AI6: =SUM(AH6+V6) -> 128 | AJ6: =-tanks!AW7 -> 128 | AK6: =SUM(AJ6-AI6) -> 0 | AL6: =S6+L6+G6 -> 2 | AM6: =Y6+AD6 -> 0 | AN6: =AN5 -> 67 | AO6: =(AN6/100)*3000 -> 2010 | AP6: =AP5 -> 55 | AQ6: =(AP6/100)*3000 -> 1650 | AR6: =AR5 -> 61 | AS6: =(AR6/100)*3000 -> 1830 | AT6: =SUM(AO6+AQ6+AS6) -> 5490 | AU6: =AT5-AT6+AV6 -> 0 | AX6: =IF(AV6>0,AW6,AX5) -> 0.8
A7: =ELEC!C6 -> 44350 | B7: 228 | C7: 235 | D7: =C6-C7 -> -43 | E7: =D7*8.38 -> -360.34 | F7: 1843 | G7: =F7-F6 -> 1 | H7: 13578 | I7: =SUM(H7-H6) -> 59 | J7: =IF(G7>0,I7/G7,0) -> 59 | K7: 2332 | L7: =K7-K6 -> 1 | M7: 171964 | N7: =M7-M6 -> 66 | O7: =O6 -> 1869 | P7: =P6 -> 2097 | Q7: =Q6 -> 176286 | R7: =Q7-Q6 -> 0 | S7: =SUM(P7-P6) -> 0 | T7: =SUM(S7*$T$2) -> 0 | U7: =SUM(G7+L7+S7) -> 2 | V7: =R7+N7+I7:I7 -> 125 | W7: =SUM(V7/U7) -> 62.5 | X7: =X6 -> 2469 | Y7: =X7-X6 -> 0 | Z7: =Z6 -> 138993 | AA7: =Z7-Z6 -> 0 | AB7: =SUM(Y7*$AB$2) -> 0 | AC7: =AC6 -> 1937 | AD7: =AC7-AC6 -> 0 | AE7: =AE6 -> 365634 | AF7: =AE7-AE6 -> 0 | AG7: =IF(AD7>0,AF7/AD7,0) -> 0 | AH7: =AF7+AA7 -> 0 | AI7: =SUM(AH7+V7) -> 125 | AJ7: =-tanks!AW8 -> 125 | AK7: =SUM(AJ7-AI7) -> 0 | AL7: =S7+L7+G7 -> 2 | AM7: =Y7+AD7 -> 0 | AN7: =AN6 -> 67 | AO7: =(AN7/100)*3000 -> 2010 | AP7: =AP6 -> 55 | AQ7: =(AP7/100)*3000 -> 1650 | AR7: =AR6 -> 61 | AS7: =(AR7/100)*3000 -> 1830 | AT7: =SUM(AO7+AQ7+AS7) -> 5490 | AU7: =AT6-AT7+AV7 -> 0 | AX7: =IF(AV7>0,AW7,AX6) -> 0.8
A8: =ELEC!C7 -> 44351 | B8: 218 | C8: 225 | D8: =C7-C8 -> 10 | E8: =D8*8.38 -> 83.8 | F8: =F7 -> 1843 | G8: =F8-F7 -> 0 | H8: =H7 -> 13578 | I8: =SUM(H8-H7) -> 0 | J8: =IF(G8>0,I8/G8,0) -> 0 | K8: 2332 | L8: =K8-K7 -> 0 | M8: 171994 | N8: =M8-M7 -> 30 | O8: =O7 -> 1869 | P8: 2098 | Q8: 176347 | R8: =Q8-Q7 -> 61 | S8: =SUM(P8-P7) -> 1 | T8: =SUM(S8*$T$2) -> 0 | U8: =SUM(G8+L8+S8) -> 1 | V8: =R8+N8+I8:I8 -> 91 | W8: =SUM(V8/U8) -> 91 | X8: =X7 -> 2469 | Y8: =X8-X7 -> 0 | Z8: =Z7 -> 138993 | AA8: =Z8-Z7 -> 0 | AB8: =SUM(Y8*$AB$2) -> 0 | AC8: =AC7 -> 1937 | AD8: =AC8-AC7 -> 0 | AE8: =AE7 -> 365634 | AF8: =AE8-AE7 -> 0 | AG8: =IF(AD8>0,AF8/AD8,0) -> 0 | AH8: =AF8+AA8 -> 0 | AI8: =SUM(AH8+V8) -> 91 | AJ8: =-tanks!AW9 -> 91 | AK8: =SUM(AJ8-AI8) -> 0 | AL8: =S8+L8+G8 -> 1 | AM8: =Y8+AD8 -> 0 | AN8: =AN7 -> 67 | AO8: =(AN8/100)*3000 -> 2010 | AP8: =AP7 -> 55 | AQ8: =(AP8/100)*3000 -> 1650 | AR8: =AR7 -> 61 | AS8: =(AR8/100)*3000 -> 1830 | AT8: =SUM(AO8+AQ8+AS8) -> 5490 | AU8: =AT7-AT8+AV8 -> 0 | AX8: =IF(AV8>0,AW8,AX7) -> 0.8
A9: =ELEC!C8 -> 44352 | B9: 201 | C9: 208 | D9: =C8-C9 -> 17 | E9: =D9*8.38 -> 142.46 | F9: 1844 | G9: =F9-F8 -> 1 | H9: 13635 | I9: =SUM(H9-H8) -> 57 | J9: =IF(G9>0,I9/G9,0) -> 57 | K9: =K8 -> 2332 | L9: =K9-K8 -> 0 | M9: =M8 -> 171994 | N9: =M9-M8 -> 0 | O9: =O8 -> 1869 | P9: 2099 | Q9: 176465 | R9: =Q9-Q8 -> 118 | S9: =SUM(P9-P8) -> 1 | T9: =SUM(S9*$T$2) -> 0 | U9: =SUM(G9+L9+S9) -> 2 | V9: =R9+N9+I9:I9 -> 175 | W9: =SUM(V9/U9) -> 87.5 | X9: =X8 -> 2469 | Y9: =X9-X8 -> 0 | Z9: =Z8 -> 138993 | AA9: =Z9-Z8 -> 0 | AB9: =SUM(Y9*$AB$2) -> 0 | AC9: 1938 | AD9: =AC9-AC8 -> 1 | AE9: 365701 | AF9: =AE9-AE8 -> 67 | AG9: =IF(AD9>0,AF9/AD9,0) -> 67 | AH9: =AF9+AA9 -> 67 | AI9: =SUM(AH9+V9) -> 242 | AJ9: =-tanks!AW10 -> 242 | AK9: =SUM(AJ9-AI9) -> 0 | AL9: =S9+L9+G9 -> 2 | AM9: =Y9+AD9 -> 1 | AN9: =AN8 -> 67 | AO9: =(AN9/100)*3000 -> 2010 | AP9: =AP8 -> 55 | AQ9: =(AP9/100)*3000 -> 1650 | AR9: =AR8 -> 61 | AS9: =(AR9/100)*3000 -> 1830 | AT9: =SUM(AO9+AQ9+AS9) -> 5490 | AU9: =AT8-AT9+AV9 -> 0 | AX9: =IF(AV9>0,AW9,AX8) -> 0.8
A10: =ELEC!C9 -> 44353 | B10: 188 | C10: 194 | D10: =C9-C10 -> 14 | E10: =D10*8.38 -> 117.32 | F10: =F9 -> 1844 | G10: =F10-F9 -> 0 | H10: 13664 | I10: =SUM(H10-H9) -> 29 | J10: =IF(G10>0,I10/G10,0) -> 0 | K10: 2333 | L10: =K10-K9 -> 1 | M10: 172051 | N10: =M10-M9 -> 57 | O10: =O9 -> 1869 | P10: =P9 -> 2099 | Q10: 176481 | R10: =Q10-Q9 -> 16 | S10: =SUM(P10-P9) -> 0 | T10: =SUM(S10*$T$2) -> 0 | U10: =SUM(G10+L10+S10) -> 1 | V10: =R10+N10+I10:I10 -> 102 | W10: =SUM(V10/U10) -> 102 | X10: 2470 | Y10: =X10-X9 -> 1 | Z10: 139083 | AA10: =Z10-Z9 -> 90 | AB10: =SUM(Y10*$AB$2) -> 0 | AC10: =AC9 -> 1938 | AD10: =AC10-AC9 -> 0 | AE10: =AE9 -> 365701 | AF10: =AE10-AE9 -> 0 | AG10: =IF(AD10>0,AF10/AD10,0) -> 0 | AH10: =AF10+AA10 -> 90 | AI10: =SUM(AH10+V10) -> 192 | AJ10: =-tanks!AW11 -> 192 | AK10: =SUM(AJ10-AI10) -> 0 | AL10: =S10+L10+G10 -> 1 | AM10: =Y10+AD10 -> 1 | AN10: =AN9 -> 67 | AO10: =(AN10/100)*3000 -> 2010 | AP10: =AP9 -> 55 | AQ10: =(AP10/100)*3000 -> 1650 | AR10: =AR9 -> 61 | AS10: =(AR10/100)*3000 -> 1830 | AT10: =SUM(AO10+AQ10+AS10) -> 5490 | AU10: =AT9-AT10+AV10 -> 0 | AX10: =IF(AV10>0,AW10,AX9) -> 0.8
A11: =ELEC!C10 -> 44354 | B11: 228 | C11: 234 | D11: =C10-C11 -> -40 | E11: =D11*8.38 -> -335.2 | F11: =F10 -> 1844 | G11: =F11-F10 -> 0 | H11: =H10 -> 13664 | I11: =SUM(H11-H10) -> 0 | J11: =IF(G11>0,I11/G11,0) -> 0 | K11: =K10 -> 2333 | L11: =K11-K10 -> 0 | M11: =M10 -> 172051 | N11: =M11-M10 -> 0 | O11: =O10 -> 1869 | P11: 2100 | Q11: 176535 | R11: =Q11-Q10 -> 54 | S11: =SUM(P11-P10) -> 1 | T11: =SUM(S11*$T$2) -> 0 | U11: =SUM(G11+L11+S11) -> 1 | V11: =R11+N11+I11:I11 -> 54 | W11: =SUM(V11/U11) -> 54 | X11: =X10 -> 2470 | Y11: =X11-X10 -> 0 | Z11: =Z10 -> 139083 | AA11: =Z11-Z10 -> 0 | AB11: =SUM(Y11*$AB$2) -> 0 | AC11: =AC10 -> 1938 | AD11: =AC11-AC10 -> 0 | AE11: =AE10 -> 365701 | AF11: =AE11-AE10 -> 0 | AG11: =IF(AD11>0,AF11/AD11,0) -> 0 | AH11: =AF11+AA11 -> 0 | AI11: =SUM(AH11+V11) -> 54 | AJ11: =-tanks!AW12 -> 54 | AK11: =SUM(AJ11-AI11) -> 0 | AL11: =S11+L11+G11 -> 1 | AM11: =Y11+AD11 -> 0 | AN11: =AN10 -> 67 | AO11: =(AN11/100)*3000 -> 2010 | AP11: =AP10 -> 55 | AQ11: =(AP11/100)*3000 -> 1650 | AR11: =AR10 -> 61 | AS11: =(AR11/100)*3000 -> 1830 | AT11: =SUM(AO11+AQ11+AS11) -> 5490 | AU11: =AT10-AT11+AV11 -> 0 | AX11: =IF(AV11>0,AW11,AX10) -> 0.8
A12: =ELEC!C11 -> 44355 | B12: 216 | C12: 223 | D12: =C11-C12 -> 11 | E12: =D12*8.38 -> 92.18 | F12: 1845 | G12: =F12-F11 -> 1 | H12: 13720 | I12: =SUM(H12-H11) -> 56 | J12: =IF(G12>0,I12/G12,0) -> 56 | K12: =K11 -> 2333 | L12: =K12-K11 -> 0 | M12: =M11 -> 172051 | N12: =M12-M11 -> 0 | O12: =O11 -> 1869 | P12: 2101 | Q12: 176637 | R12: =Q12-Q11 -> 102 | S12: =SUM(P12-P11) -> 1 | T12: =SUM(S12*$T$2) -> 0 | U12: =SUM(G12+L12+S12) -> 2 | V12: =R12+N12+I12:I12 -> 158 | W12: =SUM(V12/U12) -> 79 | X12: =X11 -> 2470 | Y12: =X12-X11 -> 0 | Z12: =Z11 -> 139083 | AA12: =Z12-Z11 -> 0 | AB12: =SUM(Y12*$AB$2) -> 0 | AC12: =AC11 -> 1938 | AD12: =AC12-AC11 -> 0 | AE12: =AE11 -> 365701 | AF12: =AE12-AE11 -> 0 | AG12: =IF(AD12>0,AF12/AD12,0) -> 0 | AH12: =AF12+AA12 -> 0 | AI12: =SUM(AH12+V12) -> 158 | AJ12: =-tanks!AW13 -> 158 | AK12: =SUM(AJ12-AI12) -> 0 | AL12: =S12+L12+G12 -> 2 | AM12: =Y12+AD12 -> 0 | AN12: =AN11 -> 67 | AO12: =(AN12/100)*3000 -> 2010 | AP12: =AP11 -> 55 | AQ12: =(AP12/100)*3000 -> 1650 | AR12: =AR11 -> 61 | AS12: =(AR12/100)*3000 -> 1830 | AT12: =SUM(AO12+AQ12+AS12) -> 5490 | AU12: =AT11-AT12+AV12 -> 0 | AX12: =IF(AV12>0,AW12,AX11) -> 0.8
A13: =ELEC!C12 -> 44356 | B13: 200 | C13: 208 | D13: =C12-C13 -> 15 | E13: =D13*8.38 -> 125.7 | F13: =F12 -> 1845 | G13: =F13-F12 -> 0 | H13: =H12 -> 13720 | I13: =SUM(H13-H12) -> 0 | J13: =IF(G13>0,I13/G13,0) -> 0 | K13: 2334 | L13: =K13-K12 -> 1 | M13: 172161 | N13: =M13-M12 -> 110 | O13: =O12 -> 1869 | P13: =P12 -> 2101 | Q13: =Q12 -> 176637 | R13: =Q13-Q12 -> 0 | S13: =SUM(P13-P12) -> 0 | T13: =SUM(S13*$T$2) -> 0 | U13: =SUM(G13+L13+S13) -> 1 | V13: =R13+N13+I13:I13 -> 110 | W13: =SUM(V13/U13) -> 110 | X13: =X12 -> 2470 | Y13: =X13-X12 -> 0 | Z13: =Z12 -> 139083 | AA13: =Z13-Z12 -> 0 | AB13: =SUM(Y13*$AB$2) -> 0 | AC13: =AC12 -> 1938 | AD13: =AC13-AC12 -> 0 | AE13: =AE12 -> 365701 | AF13: =AE13-AE12 -> 0 | AG13: =IF(AD13>0,AF13/AD13,0) -> 0 | AH13: =AF13+AA13 -> 0 | AI13: =SUM(AH13+V13) -> 110 | AJ13: =-tanks!AW14 -> 110 | AK13: =SUM(AJ13-AI13) -> 0 | AL13: =S13+L13+G13 -> 1 | AM13: =Y13+AD13 -> 0 | AN13: =AN12 -> 67 | AO13: =(AN13/100)*3000 -> 2010 | AP13: =AP12 -> 55 | AQ13: =(AP13/100)*3000 -> 1650 | AR13: =AR12 -> 61 | AS13: =(AR13/100)*3000 -> 1830 | AT13: =SUM(AO13+AQ13+AS13) -> 5490 | AU13: =AT12-AT13+AV13 -> 0 | AX13: =IF(AV13>0,AW13,AX12) -> 0.8
A14: =ELEC!C13 -> 44357 | B14: 246 | C14: 251 | D14: =C13-C14 -> -43 | E14: =D14*8.38 -> -360.34 | F14: =F13 -> 1845 | G14: =F14-F13 -> 0 | H14: =H13 -> 13720 | I14: =SUM(H14-H13) -> 0 | J14: =IF(G14>0,I14/G14,0) -> 0 | K14: 2335 | L14: =K14-K13 -> 1 | M14: 172230 | N14: =M14-M13 -> 69 | O14: =O13 -> 1869 | P14: 2102 | Q14: 176683 | R14: =Q14-Q13 -> 46 | S14: =SUM(P14-P13) -> 1 | T14: =SUM(S14*$T$2) -> 0 | U14: =SUM(G14+L14+S14) -> 2 | V14: =R14+N14+I14:I14 -> 115 | W14: =SUM(V14/U14) -> 57.5 | X14: =X13 -> 2470 | Y14: =X14-X13 -> 0 | Z14: =Z13 -> 139083 | AA14: =Z14-Z13 -> 0 | AB14: =SUM(Y14*$AB$2) -> 0 | AC14: =AC13 -> 1938 | AD14: =AC14-AC13 -> 0 | AE14: =AE13 -> 365701 | AF14: =AE14-AE13 -> 0 | AG14: =IF(AD14>0,AF14/AD14,0) -> 0 | AH14: =AF14+AA14 -> 0 | AI14: =SUM(AH14+V14) -> 115 | AJ14: =-tanks!AW15 -> 115 | AK14: =SUM(AJ14-AI14) -> 0 | AL14: =S14+L14+G14 -> 2 | AM14: =Y14+AD14 -> 0 | AN14: =AN13 -> 67 | AO14: =(AN14/100)*3000 -> 2010 | AP14: =AP13 -> 55 | AQ14: =(AP14/100)*3000 -> 1650 | AR14: =AR13 -> 61 | AS14: =(AR14/100)*3000 -> 1830 | AT14: =SUM(AO14+AQ14+AS14) -> 5490 | AU14: =AT13-AT14+AV14 -> 0 | AX14: =IF(AV14>0,AW14,AX13) -> 0.8
A15: =ELEC!C14 -> 44358 | B15: 229 | C15: 236 | D15: =C14-C15 -> 15 | E15: =D15*8.38 -> 125.7 | F15: 1846 | G15: =F15-F14 -> 1 | H15: 13830 | I15: =SUM(H15-H14) -> 110 | J15: =IF(G15>0,I15/G15,0) -> 110 | K15: =K14 -> 2335 | L15: =K15-K14 -> 0 | M15: =M14 -> 172230 | N15: =M15-M14 -> 0 | O15: =O14 -> 1869 | P15: =P14 -> 2102 | Q15: 176708 | R15: =Q15-Q14 -> 25 | S15: =SUM(P15-P14) -> 0 | T15: =SUM(S15*$T$2) -> 0 | U15: =SUM(G15+L15+S15) -> 1 | V15: =R15+N15+I15:I15 -> 135 | W15: =SUM(V15/U15) -> 135 | X15: =X14 -> 2470 | Y15: =X15-X14 -> 0 | Z15: =Z14 -> 139083 | AA15: =Z15-Z14 -> 0 | AB15: =SUM(Y15*$AB$2) -> 0 | AC15: =AC14 -> 1938 | AD15: =AC15-AC14 -> 0 | AE15: =AE14 -> 365701 | AF15: =AE15-AE14 -> 0 | AG15: =IF(AD15>0,AF15/AD15,0) -> 0 | AH15: =AF15+AA15 -> 0 | AI15: =SUM(AH15+V15) -> 135 | AJ15: =-tanks!AW16 -> 135 | AK15: =SUM(AJ15-AI15) -> 0 | AL15: =S15+L15+G15 -> 1 | AM15: =Y15+AD15 -> 0 | AN15: =AN14 -> 67 | AO15: =(AN15/100)*3000 -> 2010 | AP15: =AP14 -> 55 | AQ15: =(AP15/100)*3000 -> 1650 | AR15: =AR14 -> 61 | AS15: =(AR15/100)*3000 -> 1830 | AT15: =SUM(AO15+AQ15+AS15) -> 5490 | AU15: =AT14-AT15+AV15 -> 0 | AX15: =IF(AV15>0,AW15,AX14) -> 0.8
A16: =ELEC!C15 -> 44359 | B16: 219 | C16: 225 | D16: =C15-C16 -> 11 | E16: =D16*8.38 -> 92.18 | F16: 1847 | G16: =F16-F15 -> 1 | H16: 13919 | I16: =SUM(H16-H15) -> 89 | J16: =IF(G16>0,I16/G16,0) -> 89 | K16: 2336 | L16: =K16-K15 -> 1 | M16: 172287 | N16: =M16-M15 -> 57 | O16: =O15 -> 1869 | P16: =P15 -> 2102 | Q16: =Q15 -> 176708 | R16: =Q16-Q15 -> 0 | S16: =SUM(P16-P15) -> 0 | T16: =SUM(S16*$T$2) -> 0 | U16: =SUM(G16+L16+S16) -> 2 | V16: =R16+N16+I16:I16 -> 146 | W16: =SUM(V16/U16) -> 73 | X16: =X15 -> 2470 | Y16: =X16-X15 -> 0 | Z16: =Z15 -> 139083 | AA16: =Z16-Z15 -> 0 | AB16: =SUM(Y16*$AB$2) -> 0 | AC16: =AC15 -> 1938 | AD16: =AC16-AC15 -> 0 | AE16: 365755 | AF16: =AE16-AE15 -> 54 | AG16: =IF(AD16>0,AF16/AD16,0) -> 0 | AH16: =AF16+AA16 -> 54 | AI16: =SUM(AH16+V16) -> 200 | AJ16: =-tanks!AW17 -> 200 | AK16: =SUM(AJ16-AI16) -> 0 | AL16: =S16+L16+G16 -> 2 | AM16: =Y16+AD16 -> 0 | AN16: =AN15 -> 67 | AO16: =(AN16/100)*3000 -> 2010 | AP16: =AP15 -> 55 | AQ16: =(AP16/100)*3000 -> 1650 | AR16: =AR15 -> 61 | AS16: =(AR16/100)*3000 -> 1830 | AT16: =SUM(AO16+AQ16+AS16) -> 5490 | AU16: =AT15-AT16+AV16 -> 0 | AX16: =IF(AV16>0,AW16,AX15) -> 0.8
A17: =ELEC!C16 -> 44360 | B17: 204 | C17: 211 | D17: =C16-C17 -> 14 | E17: =D17*8.38 -> 117.32 | F17: =F16 -> 1847 | G17: =F17-F16 -> 0 | H17: =H16 -> 13919 | I17: =SUM(H17-H16) -> 0 | J17: =IF(G17>0,I17/G17,0) -> 0 | K17: =K16 -> 2336 | L17: =K17-K16 -> 0 | M17: =M16 -> 172287 | N17: =M17-M16 -> 0 | O17: =O16 -> 1869 | P17: 2103 | Q17: 176756 | R17: =Q17-Q16 -> 48 | S17: =SUM(P17-P16) -> 1 | T17: =SUM(S17*$T$2) -> 0 | U17: =SUM(G17+L17+S17) -> 1 | V17: =R17+N17+I17:I17 -> 48 | X17: =X16 -> 2470 | Y17: =X17-X16 -> 0 | Z17: =Z16 -> 139083 | AA17: =Z17-Z16 -> 0 | AB17: =SUM(Y17*$AB$2) -> 0 | AC17: =AC16 -> 1938 | AD17: =AC17-AC16 -> 0 | AE17: =AE16 -> 365755 | AF17: =AE17-AE16 -> 0 | AG17: =IF(AD17>0,AF17/AD17,0) -> 0 | AH17: =AF17+AA17 -> 0 | AI17: =SUM(AH17+V17) -> 48 | AJ17: =-tanks!AW18 -> 48 | AK17: =SUM(AJ17-AI17) -> 0 | AL17: =S17+L17+G17 -> 1 | AM17: =Y17+AD17 -> 0 | AN17: =AN16 -> 67 | AO17: =(AN17/100)*3000 -> 2010 | AP17: =AP16 -> 55 | AQ17: =(AP17/100)*3000 -> 1650 | AR17: =AR16 -> 61 | AS17: =(AR17/100)*3000 -> 1830 | AT17: =SUM(AO17+AQ17+AS17) -> 5490 | AU17: =AT16-AT17+AV17 -> 0 | AX17: =IF(AV17>0,AW17,AX16) -> 0.8
A18: =ELEC!C17 -> 44361 | B18: 193 | C18: 199 | D18: =C17-C18 -> 12 | E18: =D18*8.38 -> 100.56 | F18: 1848 | G18: =F18-F17 -> 1 | H18: 13976 | I18: =SUM(H18-H17) -> 57 | J18: =IF(G18>0,I18/G18,0) -> 57 | K18: =K17 -> 2336 | L18: =K18-K17 -> 0 | M18: =M17 -> 172287 | N18: =M18-M17 -> 0 | O18: 1869 | P18: =P17 -> 2103 | Q18: =Q17 -> 176756 | R18: =Q18-Q17 -> 0 | S18: =SUM(P18-P17) -> 0 | T18: =SUM(S18*$T$2) -> 0 | U18: =SUM(G18+L18+S18) -> 1 | V18: =R18+N18+I18:I18 -> 57 | X18: =X17 -> 2470 | Y18: =X18-X17 -> 0 | Z18: =Z17 -> 139083 | AA18: =Z18-Z17 -> 0 | AB18: =SUM(Y18*$AB$2) -> 0 | AC18: =AC17 -> 1938 | AD18: =AC18-AC17 -> 0 | AE18: =AE17 -> 365755 | AF18: =AE18-AE17 -> 0 | AG18: =IF(AD18>0,AF18/AD18,0) -> 0 | AH18: =AF18+AA18 -> 0 | AI18: =SUM(AH18+V18) -> 57 | AJ18: =-tanks!AW19 -> 57 | AK18: =SUM(AJ18-AI18) -> 0 | AL18: =S18+L18+G18 -> 1 | AM18: =Y18+AD18 -> 0 | AN18: =AN17 -> 67 | AO18: =(AN18/100)*3000 -> 2010 | AP18: =AP17 -> 55 | AQ18: =(AP18/100)*3000 -> 1650 | AR18: =AR17 -> 61 | AS18: =(AR18/100)*3000 -> 1830 | AT18: =SUM(AO18+AQ18+AS18) -> 5490 | AU18: =AT17-AT18+AV18 -> 0 | AX18: =IF(AV18>0,AW18,AX17) -> 0.8
A19: =ELEC!C18 -> 44362 | B19: 225 | C19: 231 | D19: =C18-C19 -> -32 | E19: =D19*8.38 -> -268.16 | F19: 1850 | G19: =F19-F18 -> 2 | H19: 14077 | I19: =SUM(H19-H18) -> 101 | J19: =IF(G19>0,I19/G19,0) -> 50.5 | K19: 2337 | L19: =K19-K18 -> 1 | M19: 172370 | N19: =M19-M18 -> 83 | O19: =O18 -> 1869 | P19: =P18 -> 2103 | Q19: =Q18 -> 176756 | R19: =Q19-Q18 -> 0 | S19: =SUM(P19-P18) -> 0 | T19: =SUM(S19*$T$2) -> 0 | U19: =SUM(G19+L19+S19) -> 3 | V19: =R19+N19+I19:I19 -> 184 | X19: =X18 -> 2470 | Y19: =X19-X18 -> 0 | Z19: =Z18 -> 139083 | AA19: =Z19-Z18 -> 0 | AB19: =SUM(Y19*$AB$2) -> 0 | AC19: =AC18 -> 1938 | AD19: =AC19-AC18 -> 0 | AE19: =AE18 -> 365755 | AF19: =AE19-AE18 -> 0 | AG19: =IF(AD19>0,AF19/AD19,0) -> 0 | AH19: =AF19+AA19 -> 0 | AI19: =SUM(AH19+V19) -> 184 | AJ19: =-tanks!AW20 -> 184 | AK19: =SUM(AJ19-AI19) -> 0 | AL19: =S19+L19+G19 -> 3 | AM19: =Y19+AD19 -> 0 | AN19: =AN18 -> 67 | AO19: =(AN19/100)*3000 -> 2010 | AP19: =AP18 -> 55 | AQ19: =(AP19/100)*3000 -> 1650 | AR19: =AR18 -> 61 | AS19: =(AR19/100)*3000 -> 1830 | AT19: =SUM(AO19+AQ19+AS19) -> 5490 | AU19: =AT18-AT19+AV19 -> 0 | AX19: =IF(AV19>0,AW19,AX18) -> 0.8
A20: =ELEC!C19 -> 44363 | B20: 213 | C20: 219 | D20: =C19-C20 -> 12 | E20: =D20*8.38 -> 100.56 | F20: =F19 -> 1850 | G20: =F20-F19 -> 0 | H20: =H19 -> 14077 | I20: =SUM(H20-H19) -> 0 | J20: =IF(G20>0,I20/G20,0) -> 0 | K20: =K19 -> 2337 | L20: =K20-K19 -> 0 | M20: =M19 -> 172370 | N20: =M20-M19 -> 0 | O20: =O19 -> 1869 | P20: 2104 | Q20: 176838 | R20: =Q20-Q19 -> 82 | S20: =SUM(P20-P19) -> 1 | T20: =SUM(S20*$T$2) -> 0 | U20: =SUM(G20+L20+S20) -> 1 | V20: =R20+N20+I20:I20 -> 82 | X20: =X19 -> 2470 | Y20: =X20-X19 -> 0 | Z20: =Z19 -> 139083 | AA20: =Z20-Z19 -> 0 | AB20: =SUM(Y20*$AB$2) -> 0 | AC20: =AC19 -> 1938 | AD20: =AC20-AC19 -> 0 | AE20: =AE19 -> 365755 | AF20: =AE20-AE19 -> 0 | AG20: =IF(AD20>0,AF20/AD20,0) -> 0 | AH20: =AF20+AA20 -> 0 | AI20: =SUM(AH20+V20) -> 82 | AJ20: =-tanks!AW21 -> 82 | AK20: =SUM(AJ20-AI20) -> 0 | AL20: =S20+L20+G20 -> 1 | AM20: =Y20+AD20 -> 0 | AN20: =AN19 -> 67 | AO20: =(AN20/100)*3000 -> 2010 | AP20: =AP19 -> 55 | AQ20: =(AP20/100)*3000 -> 1650 | AR20: =AR19 -> 61 | AS20: =(AR20/100)*3000 -> 1830 | AT20: =SUM(AO20+AQ20+AS20) -> 5490 | AU20: =AT19-AT20+AV20 -> 0 | AX20: =IF(AV20>0,AW20,AX19) -> 0.8
A21: =ELEC!C20 -> 44364 | B21: 199 | C21: 206 | D21: =C20-C21 -> 13 | E21: =D21*8.38 -> 108.94 | F21: =F20 -> 1850 | G21: =F21-F20 -> 0 | H21: 14125 | I21: =SUM(H21-H20) -> 48 | J21: =IF(G21>0,I21/G21,0) -> 0 | K21: =K20 -> 2337 | L21: =K21-K20 -> 0 | M21: =M20 -> 172370 | N21: =M21-M20 -> 0 | O21: =O20 -> 1869 | P21: 2105 | Q21: 176929 | R21: =Q21-Q20 -> 91 | S21: =SUM(P21-P20) -> 1 | T21: =SUM(S21*$T$2) -> 0 | U21: =SUM(G21+L21+S21) -> 1 | V21: =R21+N21+I21:I21 -> 139 | X21: =X20 -> 2470 | Y21: =X21-X20 -> 0 | Z21: =Z20 -> 139083 | AA21: =Z21-Z20 -> 0 | AB21: =SUM(Y21*$AB$2) -> 0 | AC21: =AC20 -> 1938 | AD21: =AC21-AC20 -> 0 | AE21: =AE20 -> 365755 | AF21: =AE21-AE20 -> 0 | AG21: =IF(AD21>0,AF21/AD21,0) -> 0 | AH21: =AF21+AA21 -> 0 | AI21: =SUM(AH21+V21) -> 139 | AJ21: =-tanks!AW22 -> 139 | AK21: =SUM(AJ21-AI21) -> 0 | AL21: =S21+L21+G21 -> 1 | AM21: =Y21+AD21 -> 0 | AN21: =AN20 -> 67 | AO21: =(AN21/100)*3000 -> 2010 | AP21: =AP20 -> 55 | AQ21: =(AP21/100)*3000 -> 1650 | AR21: =AR20 -> 61 | AS21: =(AR21/100)*3000 -> 1830 | AT21: =SUM(AO21+AQ21+AS21) -> 5490 | AU21: =AT20-AT21+AV21 -> 0 | AX21: =IF(AV21>0,AW21,AX20) -> 0.8
A22: =ELEC!C21 -> 44365 | B22: =B21 -> 199 | C22: =C21 -> 206 | D22: =C21-C22 -> 0 | E22: =D22*8.38 -> 0 | F22: =F21 -> 1850 | G22: =F22-F21 -> 0 | H22: =H21 -> 14125 | I22: =SUM(H22-H21) -> 0 | J22: =IF(G22>0,I22/G22,0) -> 0 | K22: =K21 -> 2337 | L22: =K22-K21 -> 0 | M22: =M21 -> 172370 | N22: =M22-M21 -> 0 | O22: =O21 -> 1869 | P22: =P21 -> 2105 | Q22: =Q21 -> 176929 | R22: =Q22-Q21 -> 0 | S22: =SUM(P22-P21) -> 0 | T22: =SUM(S22*$T$2) -> 0 | U22: =SUM(G22+L22+S22) -> 0 | V22: =R22+N22+I22:I22 -> 0 | X22: =X21 -> 2470 | Y22: =X22-X21 -> 0 | Z22: =Z21 -> 139083 | AA22: =Z22-Z21 -> 0 | AB22: =SUM(Y22*$AB$2) -> 0 | AC22: =AC21 -> 1938 | AD22: =AC22-AC21 -> 0 | AE22: =AE21 -> 365755 | AF22: =AE22-AE21 -> 0 | AG22: =IF(AD22>0,AF22/AD22,0) -> 0 | AH22: =AF22+AA22 -> 0 | AI22: =SUM(AH22+V22) -> 0 | AJ22: =-tanks!AW23 -> 0 | AK22: =SUM(AJ22-AI22) -> 0 | AL22: =S22+L22+G22 -> 0 | AM22: =Y22+AD22 -> 0 | AN22: =AN21 -> 67 | AO22: =(AN22/100)*3000 -> 2010 | AP22: =AP21 -> 55 | AQ22: =(AP22/100)*3000 -> 1650 | AR22: =AR21 -> 61 | AS22: =(AR22/100)*3000 -> 1830 | AT22: =SUM(AO22+AQ22+AS22) -> 5490 | AU22: =AT21-AT22+AV22 -> 0 | AX22: =IF(AV22>0,AW22,AX21) -> 0.8
A23: =ELEC!C22 -> 44366 | B23: =B22 -> 199 | C23: =C22 -> 206 | D23: =C22-C23 -> 0 | E23: =D23*8.38 -> 0 | F23: =F22 -> 1850 | G23: =F23-F22 -> 0 | H23: =H22 -> 14125 | I23: =SUM(H23-H22) -> 0 | J23: =IF(G23>0,I23/G23,0) -> 0 | K23: =K22 -> 2337 | L23: =K23-K22 -> 0 | M23: =M22 -> 172370 | N23: =M23-M22 -> 0 | O23: =O22 -> 1869 | P23: =P22 -> 2105 | Q23: =Q22 -> 176929 | R23: =Q23-Q22 -> 0 | S23: =SUM(P23-P22) -> 0 | T23: =SUM(S23*$T$2) -> 0 | U23: =SUM(G23+L23+S23) -> 0 | V23: =R23+N23+I23:I23 -> 0 | X23: =X22 -> 2470 | Y23: =X23-X22 -> 0 | Z23: =Z22 -> 139083 | AA23: =Z23-Z22 -> 0 | AB23: =SUM(Y23*$AB$2) -> 0 | AC23: =AC22 -> 1938 | AD23: =AC23-AC22 -> 0 | AE23: =AE22 -> 365755 | AF23: =AE23-AE22 -> 0 | AG23: =IF(AD23>0,AF23/AD23,0) -> 0 | AH23: =AF23+AA23 -> 0 | AI23: =SUM(AH23+V23) -> 0 | AJ23: =-tanks!AW24 -> 0 | AK23: =SUM(AJ23-AI23) -> 0 | AL23: =S23+L23+G23 -> 0 | AM23: =Y23+AD23 -> 0 | AN23: =AN22 -> 67 | AO23: =(AN23/100)*3000 -> 2010 | AP23: =AP22 -> 55 | AQ23: =(AP23/100)*3000 -> 1650 | AR23: =AR22 -> 61 | AS23: =(AR23/100)*3000 -> 1830 | AT23: =SUM(AO23+AQ23+AS23) -> 5490 | AU23: =AT22-AT23+AV23 -> 0 | AX23: =IF(AV23>0,AW23,AX22) -> 0.8
