Workbook

Sheet TOTAL
A1: Site Name | B1: Day | C1: Month | D1: Year | E1: Total Electricity Kwh | F1: Electricity Tariff ($/Kwh) | G1: Water Utility Supply (m3) m3 | H1: Water Utility Supply (m3) $/m3 | I1: Room Nights | J1: Total Guests | K1: Food Covers
A2: Maldives at Kuda Huraa | B2: 1 | C2: 6 | D2: 2021 | E2: 22750 | F2: 0.14 | G2: 428 | H2: 0.4 | I2: 20 | J2: 46 | K2: 141
A3: Maldives at Kuda Huraa | B3: =B2+1 -> 2 | C3: 6 | D3: 2021 | E3: 23170 | F3: 0.14 | G3: 334 | H3: 0.4 | I3: 20 | J3: 47 | K3: 130
A4: Maldives at Kuda Huraa | B4: =B3+1 -> 3 | C4: 6 | D4: 2021 | E4: 22990 | F4: 0.14 | G4: 346 | H4: 0.4 | I4: 19 | J4: 46 | K4: 130
A5: Maldives at Kuda Huraa | B5: =B4+1 -> 4 | C5: 6 | D5: 2021 | E5: 22280 | F5: 0.14 | G5: 292 | H5: 0.4 | I5: 16 | J5: 40 | K5: 99
A6: Maldives at Kuda Huraa | B6: =B5+1 -> 5 | C6: 6 | D6: 2021 | E6: 22610 | F6: 0.14 | G6: 347 | H6: 0.4 | I6: 14 | J6: 36 | K6: 137
A7: Maldives at Kuda Huraa | B7: =B6+1 -> 6 | C7: 6 | D7: 2021 | E7: 22650 | F7: 0.14 | G7: 328 | H7: 0.4 | I7: 9 | J7: 24 | K7: 51
A8: Maldives at Kuda Huraa | B8: =B7+1 -> 7 | C8: 6 | D8: 2021 | E8: 23300 | F8: 0.14 | G8: 314 | H8: 0.4 | I8: 10 | J8: 26 | K8: 125
A9: Maldives at Kuda Huraa | B9: =B8+1 -> 8 | C9: 6 | D9: 2021 | E9: 22610 | F9: 0.14 | G9: 387 | H9: 0.4 | I9: 13 | J9: 32 | K9: 80
A10: Maldives at Kuda Huraa | B10: =B9+1 -> 9 | C10: 6 | D10: 2021 | E10: 23510 | F10: 0.14 | G10: 254 | H10: 0.4 | I10: 17 | J10: 39 | K10: 140
A11: Maldives at Kuda Huraa | B11: =B10+1 -> 10 | C11: 6 | D11: 2021 | E11: 23330 | F11: 0.14 | G11: 343 | H11: 0.4 | I11: 16 | J11: 40 | K11: 112
A12: Maldives at Kuda Huraa | B12: =B11+1 -> 11 | C12: 6 | D12: 2021 | E12: 22710 | F12: 0.14 | G12: 257 | H12: 0.4 | I12: 19 | J12: 44 | K12: 116
A13: Maldives at Kuda Huraa | B13: =B12+1 -> 12 | C13: 6 | D13: 2021 | E13: 22700 | F13: 0.14 | G13: 273 | H13: 0.4 | I13: 20 | J13: 50 | K13: 151
A14: Maldives at Kuda Huraa | B14: =B13+1 -> 13 | C14: 6 | D14: 2021 | E14: 23750 | F14: 0.14 | G14: 291 | H14: 0.4 | I14: 18 | J14: 49 | K14: 144
... A24: Maldives at Kuda Huraa | B24: =B23+1 -> 23 | C24: 6 | D24: 2021 | E24: 22890 | F24: 0.14 | G24: 273 | H24: 0.4 | I24: 17 | J24: 50 | K24: 104
A25: Maldives at Kuda Huraa | B25: =B24+1 -> 24 | C25: 6 | D25: 2021 | F25: 0.14 | H25: 0.4
A26: Maldives at Kuda Huraa | B26: =B25+1 -> 25 | C26: 6 | D26: 2021 | F26: 0.14 | H26: 0.4
A27: Maldives at Kuda Huraa | B27: =B26+1 -> 26 | C27: 6 | D27: 2021 | F27: 0.14 | H27: 0.4
A28: Maldives at Kuda Huraa | B28: =B27+1 -> 27 | C28: 6 | D28: 2021 | F28: 0.14 | H28: 0.4
A29: Maldives at Kuda Huraa | B29: =B28+1 -> 28 | C29: 6 | D29: 2021 | F29: 0.14 | H29: 0.4
A30: Maldives at Kuda Huraa | B30: =B29+1 -> 29 | C30: 6 | D30: 2021 | F30: 0.14 | H30: 0.4
A31: Maldives at Kuda Huraa | B31: =B30+1 -> 30 | C31: 6 | D31: 2021 | F31: 0.14 | H31: 0.4
A32: Maldives at Kuda Huraa | B32: =B31+1 -> 31 | C32: 6 | D32: 2021 | F32: 0.14 | H32: 0.4
A33: Total | E33: =SUM(E2:E32) -> 530650 | F33: 0 | G33: =SUM(G2:G32) -> 7199 | H33: 0 | I33: =SUM(I2:I32) -> 365 | J33: =SUM(J2:J32) -> 938 | K33: =SUM(K2:K32) -> 2696

Sheet Submetering
A1: Site Name | B1: Day | C1: Month | D1: Year | E1: BOH-1/ B&C Block MWH | F1: Pastry MWH | G1: Feeder 401-419 KWH | H1: Feeder 301-319 KWH | I1: Kitchen GWH | J1: Feeder 201-208 MWH | K1: Feeder 113-123 | L1: M - Block /PC MWH | M1: Laundry MWH A | N1: Laundry MWH B | O1: Laundry MWH C | P1: Feeder 101-112 MWH | Q1: Feeder 217-224 | R1: Spa MWH | S1: Feeder 124-134 | T1: Feeder 209-216 | U1: STP -1 &2 MWH | V1: STP -3 MWH | W1: Reef Club MWH | X1: STP -3 KWH | Y1: M - Block /PC KWH | Z1: B&C Block KWH | AA1: Feeder -101-112 | AB1: Feeder -113-123 | AC1: Feeder -124-134 | AD1: Feeder -201-208 | AE1: Feeder -209-216 | AF1: Feeder -217-224 | AG1: Feeder -301-319 | AH1: Feeder 401-419 | AI1: Spa KWH | AJ1: Others KWH | AK1: Reef Club Kitchen KWH | AL1: Main Kitchen KWH | AM1: Pastry Kitchen KWH | AN1: Laundry KWH | AO1: STP KWH | AP1: Kuda Huraa Accomodation KWH | AQ1: Guest Room Beach Pavilion & Beach Bungalow KWH | AR1: Guest Room Water Bungalow KWH | AS1: Spa KWH | AT1: Others KWH | AU1: Main Meter 1 | AV1: Main Meter 2 | AW1: Beach Bunglow | AX1: Kuda Huraa staff | AY1: Bodu hura staff | AZ1: Laundry | BA1: Water Bunglow | BB1: Main Kitchen | BC1: Second stage | BD1: Supply jetty | BE1: Staff housing A | BF1: Staff housing B | BG1: Spa | BH1: Staff jetty | BI1: Main pool | BJ1: Reef club pool | BK1: Reef club kitchen | BL1: Total Fuel Oil (Liters)
A2: Maldives at Kuda Huraa | B2: 1 | C2: 6 | D2: 2021 | E2: ='Kwh Reading'!B3 -> 941.59 | F2: ='Kwh Reading'!C3 -> 222.83 | G2: ='Kwh Reading'!D3 -> 7406516.4 | H2: ='Kwh Reading'!E3 -> 8087986.4 | I2: ='Kwh Reading'!F3 -> 2.3081 | J2: ='Kwh Reading'!G3 -> 719.09 | K2: ='Kwh Reading'!H3 -> 608.01 | L2: ='Kwh Reading'!I3 -> 226.28 | ... W2: ='Kwh Reading'!T3 -> 407.66 | X2: ='Kwh Consumption'!J4 -> 120 | Y2: ='Kwh Consumption'!K4 -> 310 | Z2: ='Kwh Consumption'!L4 -> 1180 | AA2: ='Kwh Consumption'!M4 -> 780 | AB2: ='Kwh Consumption'!N4 -> 510 | AC2: ='Kwh Consumption'!O4 -> 1090 | AD2: ='Kwh Consumption'!P4 -> 930 | AE2: ='Kwh Consumption'!Q4 -> 670 | ... AJ2: ='Kwh Consumption'!V4 -> 9668.28 | AK2: ='Kwh area wise '!C3 -> 480 | AL2: ='Kwh area wise '!D3 -> 2000 | AM2: ='Kwh area wise '!E3 -> 210 | AN2: ='Kwh area wise '!F3 -> 550 | AO2: ='Kwh area wise '!G3 -> 450 | AP2: ='Kwh area wise '!H3 -> 1490 | AQ2: ='Kwh area wise '!I3 -> 4750 | AR2: ='Kwh area wise '!J3 -> 5661.72 | ... AT2: ='Kwh area wise '!L3 -> 6898.28 | AU2: ='Water Reading'!B3 -> 160897 | AV2: ='Water Reading'!C3 -> 121531 | AW2: ='Water Reading'!D3 -> 204645 | AX2: ='Water Reading'!E3 -> 245992 | AY2: ='Water Reading'!F3 -> 66906 | AZ2: ='Water Reading'!G3 -> 111170 | BA2: ='Water Reading'!H3 -> 51028 | BB2: ='Water Reading'!I3 -> 62884 | ... BK2: ='Water Reading'!R3 -> 6107 | BL2: ='Kwh Reading'!U3 -> 6559
A3: Maldives at Kuda Huraa | B3: =B2+1 -> 2 | C3: 6 | D3: 2021 | E3: ='Kwh Reading'!B4 -> 942.77 | F3: ='Kwh Reading'!C4 -> 223.04 | G3: ='Kwh Reading'!D4 -> 7409069 | H3: ='Kwh Reading'!E4 -> 8091095.5 | I3: ='Kwh Reading'!F4 -> 2.3101 | J3: ='Kwh Reading'!G4 -> 720.02 | K3: ='Kwh Reading'!H4 -> 608.52 | L3: ='Kwh Reading'!I4 -> 226.59 | ... W3: ='Kwh Reading'!T4 -> 408.14 | X3: ='Kwh Consumption'!J5 -> 150 | Y3: ='Kwh Consumption'!K5 -> 330 | Z3: ='Kwh Consumption'!L5 -> 1240 | AA3: ='Kwh Consumption'!M5 -> 770 | AB3: ='Kwh Consumption'!N5 -> 580 | AC3: ='Kwh Consumption'!O5 -> 1150 | AD3: ='Kwh Consumption'!P5 -> 990 | AE3: ='Kwh Consumption'!Q5 -> 730 | ... AJ3: ='Kwh Consumption'!V5 -> 6415.08 | AK3: ='Kwh area wise '!C4 -> 500 | AL3: ='Kwh area wise '!D4 -> 2300 | AM3: ='Kwh area wise '!E4 -> 210 | AN3: ='Kwh area wise '!F4 -> 580 | AO3: ='Kwh area wise '!G4 -> 480 | AP3: ='Kwh area wise '!H4 -> 1570 | AQ3: ='Kwh area wise '!I4 -> 5040 | AR3: ='Kwh area wise '!J4 -> 5804.92 | ... AT3: ='Kwh area wise '!L4 -> 6415.08 | AU3: ='Water Reading'!B4 -> 161062 | AV3: ='Water Reading'!C4 -> 121808 | AW3: ='Water Reading'!D4 -> 204812 | AX3: ='Water Reading'!E4 -> 246049 | AY3: ='Water Reading'!F4 -> 66907 | AZ3: ='Water Reading'!G4 -> 111184 | BA3: ='Water Reading'!H4 -> 51123 | BB3: ='Water Reading'!I4 -> 63020 | ... BK3: ='Water Reading'!R4 -> 6111 | BL3: ='Kwh Reading'!U4 -> 6159
A4: Maldives at Kuda Huraa | B4: =B3+1 -> 3 | C4: 6 | D4: 2021 | E4: ='Kwh Reading'!B5 -> 944.01 | F4: ='Kwh Reading'!C5 -> 223.25 | G4: ='Kwh Reading'!D5 -> 7411692.1 | H4: ='Kwh Reading'!E5 -> 8094277.3 | I4: ='Kwh Reading'!F5 -> 2.3124 | J4: ='Kwh Reading'!G5 -> 721.01 | K4: ='Kwh Reading'!H5 -> 609.1 | L4: ='Kwh Reading'!I5 -> 226.92 | ... W4: ='Kwh Reading'!T5 -> 408.64 | X4: ='Kwh Consumption'!J6 -> 120 | Y4: ='Kwh Consumption'!K6 -> 360 | Z4: ='Kwh Consumption'!L6 -> 1290 | AA4: ='Kwh Consumption'!M6 -> 790 | AB4: ='Kwh Consumption'!N6 -> 570 | AC4: ='Kwh Consumption'!O6 -> 1140 | AD4: ='Kwh Consumption'!P6 -> 970 | AE4: ='Kwh Consumption'!Q6 -> 670 | ... AJ4: ='Kwh Consumption'!V6 -> 6062.31 | AK4: ='Kwh area wise '!C5 -> 520 | AL4: ='Kwh area wise '!D5 -> 2400 | AM4: ='Kwh area wise '!E5 -> 220 | AN4: ='Kwh area wise '!F5 -> 600 | AO4: ='Kwh area wise '!G5 -> 460 | AP4: ='Kwh area wise '!H5 -> 1650 | AQ4: ='Kwh area wise '!I5 -> 5020 | AR4: ='Kwh area wise '!J5 -> 5827.69 | ... AT4: ='Kwh area wise '!L5 -> 6062.31 | AU4: ='Water Reading'!B5 -> 161221 | AV4: ='Water Reading'!C5 -> 121993 | AW4: ='Water Reading'!D5 -> 205001 | AX4: ='Water Reading'!E5 -> 246104 | AY4: ='Water Reading'!F5 -> 66907 | AZ4: ='Water Reading'!G5 -> 111198 | BA4: ='Water Reading'!H5 -> 51231 | BB4: ='Water Reading'!I5 -> 63032 | ... BK4: ='Water Reading'!R5 -> 6116 | BL4: ='Kwh Reading'!U5 -> 6405
A5: Maldives at Kuda Huraa | B5: =B4+1 -> 4 | C5: 6 | D5: 2021 | E5: ='Kwh Reading'!B6 -> 945.3 | F5: ='Kwh Reading'!C6 -> 223.47 | G5: ='Kwh Reading'!D6 -> 7414329 | H5: ='Kwh Reading'!E6 -> 8097468.1 | I5: ='Kwh Reading'!F6 -> 2.3148 | J5: ='Kwh Reading'!G6 -> 721.98 | K5: ='Kwh Reading'!H6 -> 609.67 | L5: ='Kwh Reading'!I6 -> 227.28 | ... W5: ='Kwh Reading'!T6 -> 409.16 | X5: ='Kwh Consumption'!J7 -> 120 | Y5: ='Kwh Consumption'!K7 -> 330 | Z5: ='Kwh Consumption'!L7 -> 1270 | AA5: ='Kwh Consumption'!M7 -> 800 | AB5: ='Kwh Consumption'!N7 -> 530 | AC5: ='Kwh Consumption'!O7 -> 1070 | AD5: ='Kwh Consumption'!P7 -> 1000 | AE5: ='Kwh Consumption'!Q7 -> 710 | ... AJ5: ='Kwh Consumption'!V7 -> 6067.06 | AK5: ='Kwh area wise '!C6 -> 290 | AL5: ='Kwh area wise '!D6 -> 2300 | AM5: ='Kwh area wise '!E6 -> 250 | AN5: ='Kwh area wise '!F6 -> 660 | AO5: ='Kwh area wise '!G6 -> 420 | AP5: ='Kwh area wise '!H6 -> 1600 | AQ5: ='Kwh area wise '!I6 -> 4960 | AR5: ='Kwh area wise '!J6 -> 5502.94 | ... AT5: ='Kwh area wise '!L6 -> 6067.06 | AU5: ='Water Reading'!B6 -> 161337 | AV5: ='Water Reading'!C6 -> 122122 | AW5: ='Water Reading'!D6 -> 205144 | AX5: ='Water Reading'!E6 -> 246168 | AY5: ='Water Reading'!F6 -> 66908 | AZ5: ='Water Reading'!G6 -> 111214 | BA5: ='Water Reading'!H6 -> 51312 | BB5: ='Water Reading'!I6 -> 63057 | ... BK5: ='Water Reading'!R6 -> 6122 | BL5: ='Kwh Reading'!U6 -> 6004
A6: Maldives at Kuda Huraa | B6: =B5+1 -> 5 | C6: 6 | D6: 2021 | E6: ='Kwh Reading'!B7 -> 946.57 | F6: ='Kwh Reading'!C7 -> 223.72 | G6: ='Kwh Reading'!D7 -> 7416934.1 | H6: ='Kwh Reading'!E7 -> 8100365.9 | I6: ='Kwh Reading'!F7 -> 2.3171 | J6: ='Kwh Reading'!G7 -> 722.98 | K6: ='Kwh Reading'!H7 -> 610.2 | L6: ='Kwh Reading'!I7 -> 227.61 | ... W6: ='Kwh Reading'!T7 -> 409.45 | X6: ='Kwh Consumption'!J8 -> 140 | Y6: ='Kwh Consumption'!K8 -> 300 | Z6: ='Kwh Consumption'!L8 -> 1190 | AA6: ='Kwh Consumption'!M8 -> 770 | AB6: ='Kwh Consumption'!N8 -> 490 | AC6: ='Kwh Consumption'!O8 -> 1070 | AD6: ='Kwh Consumption'!P8 -> 970 | AE6: ='Kwh Consumption'!Q8 -> 670 | ... AJ6: ='Kwh Consumption'!V8 -> 6705.39 | AK6: ='Kwh area wise '!C7 -> 480 | AL6: ='Kwh area wise '!D7 -> 2300 | AM6: ='Kwh area wise '!E7 -> 260 | AN6: ='Kwh area wise '!F7 -> 290 | AO6: ='Kwh area wise '!G7 -> 470 | AP6: ='Kwh area wise '!H7 -> 1490 | AQ6: ='Kwh area wise '!I7 -> 4930 | AR6: ='Kwh area wise '!J7 -> 5444.61 | ... AT6: ='Kwh area wise '!L7 -> 6705.39 | AU6: ='Water Reading'!B7 -> 161532 | AV6: ='Water Reading'!C7 -> 122374 | AW6: ='Water Reading'!D7 -> 205336 | AX6: ='Water Reading'!E7 -> 246233 | AY6: ='Water Reading'!F7 -> 66908 | AZ6: ='Water Reading'!G7 -> 111227 | BA6: ='Water Reading'!H7 -> 51318 | BB6: ='Water Reading'!I7 -> 63066 | ... BK6: ='Water Reading'!R7 -> 6124 | BL6: ='Kwh Reading'!U7 -> 5993
A7: Maldives at Kuda Huraa | B7: =B6+1 -> 6 | C7: 6 | D7: 2021 | E7: ='Kwh Reading'!B8 -> 947.76 | F7: ='Kwh Reading'!C8 -> 223.98 | G7: ='Kwh Reading'!D8 -> 7419302.4 | H7: ='Kwh Reading'!E8 -> 8103442.3 | I7: ='Kwh Reading'!F8 -> 2.3194 | J7: ='Kwh Reading'!G8 -> 723.95 | K7: ='Kwh Reading'!H8 -> 610.69 | L7: ='Kwh Reading'!I8 -> 227.91 | ... W7: ='Kwh Reading'!T8 -> 409.93 | X7: ='Kwh Consumption'!J9 -> 110 | Y7: ='Kwh Consumption'!K9 -> 320 | Z7: ='Kwh Consumption'!L9 -> 1350 | AA7: ='Kwh Consumption'!M9 -> 860 | AB7: ='Kwh Consumption'!N9 -> 540 | AC7: ='Kwh Consumption'!O9 -> 1090 | AD7: ='Kwh Consumption'!P9 -> 940 | AE7: ='Kwh Consumption'!Q9 -> 820 | ... AJ7: ='Kwh Consumption'!V9 -> 6220.33 | AK7: ='Kwh area wise '!C8 -> 420 | AL7: ='Kwh area wise '!D8 -> 2600 | AM7: ='Kwh area wise '!E8 -> 170 | AN7: ='Kwh area wise '!F8 -> 690 | AO7: ='Kwh area wise '!G8 -> 280 | AP7: ='Kwh area wise '!H8 -> 1670 | AQ7: ='Kwh area wise '!I8 -> 4830 | AR7: ='Kwh area wise '!J8 -> 5509.67 | ... AT7: ='Kwh area wise '!L8 -> 6220.33 | AU7: ='Water Reading'!B8 -> 161708 | AV7: ='Water Reading'!C8 -> 122553 | AW7: ='Water Reading'!D8 -> 205574 | AX7: ='Water Reading'!E8 -> 246298 | AY7: ='Water Reading'!F8 -> 66909 | AZ7: ='Water Reading'!G8 -> 111235 | BA7: ='Water Reading'!H8 -> 51441 | BB7: ='Water Reading'!I8 -> 63089 | ... BK7: ='Water Reading'!R8 -> 6128 | BL7: ='Kwh Reading'!U8 -> 6523
A8: Maldives at Kuda Huraa | B8: =B7+1 -> 7 | C8: 6 | D8: 2021 | E8: ='Kwh Reading'!B9 -> 949.11 | F8: ='Kwh Reading'!C9 -> 224.15 | G8: ='Kwh Reading'!D9 -> 7421777.6 | H8: ='Kwh Reading'!E9 -> 8106476.7 | I8: ='Kwh Reading'!F9 -> 2.322 | J8: ='Kwh Reading'!G9 -> 724.89 | K8: ='Kwh Reading'!H9 -> 611.23 | L8: ='Kwh Reading'!I9 -> 228.23 | ... W8: ='Kwh Reading'!T9 -> 410.35 | X8: ='Kwh Consumption'!J10 -> 120 | Y8: ='Kwh Consumption'!K10 -> 320 | Z8: ='Kwh Consumption'!L10 -> 1340 | AA8: ='Kwh Consumption'!M10 -> 910 | AB8: ='Kwh Consumption'!N10 -> 530 | AC8: ='Kwh Consumption'!O10 -> 1050 | AD8: ='Kwh Consumption'!P10 -> 910 | AE8: ='Kwh Consumption'!Q10 -> 820 | ... AJ8: ='Kwh Consumption'!V10 -> 6880.87 | AK8: ='Kwh area wise '!C9 -> 410 | AL8: ='Kwh area wise '!D9 -> 2300 | AM8: ='Kwh area wise '!E9 -> 200 | AN8: ='Kwh area wise '!F9 -> 600 | AO8: ='Kwh area wise '!G9 -> 430 | AP8: ='Kwh area wise '!H9 -> 1660 | AQ8: ='Kwh area wise '!I9 -> 5000 | AR8: ='Kwh area wise '!J9 -> 5529.13 | ... AT8: ='Kwh area wise '!L9 -> 6880.87 | AU8: ='Water Reading'!B9 -> 162036 | AV8: ='Water Reading'!C9 -> 122867 | AW8: ='Water Reading'!D9 -> 205728 | AX8: ='Water Reading'!E9 -> 246365 | AY8: ='Water Reading'!F9 -> 66910 | AZ8: ='Water Reading'!G9 -> 111253 | BA8: ='Water Reading'!H9 -> 51517 | BB8: ='Water Reading'!I9 -> 63119 | ... BK8: ='Water Reading'!R9 -> 6131 | BL8: ='Kwh Reading'!U9 -> 6177
A9: Maldives at Kuda Huraa | B9: =B8+1 -> 8 | C9: 6 | D9: 2021 | E9: ='Kwh Reading'!B10 -> 950.45 | F9: ='Kwh Reading'!C10 -> 224.35 | G9: ='Kwh Reading'!D10 -> 7424119.7 | H9: ='Kwh Reading'!E10 -> 8109663.8 | I9: ='Kwh Reading'!F10 -> 2.3243 | J9: ='Kwh Reading'!G10 -> 725.8 | K9: ='Kwh Reading'!H10 -> 611.76 | L9: ='Kwh Reading'!I10 -> 228.55 | ... W9: ='Kwh Reading'!T10 -> 410.76 | X9: ='Kwh Consumption'!J11 -> 150 | Y9: ='Kwh Consumption'!K11 -> 320 | Z9: ='Kwh Consumption'!L11 -> 1240 | AA9: ='Kwh Consumption'!M11 -> 900 | AB9: ='Kwh Consumption'!N11 -> 470 | AC9: ='Kwh Consumption'!O11 -> 1040 | AD9: ='Kwh Consumption'!P11 -> 960 | AE9: ='Kwh Consumption'!Q11 -> 700 | ... AJ9: ='Kwh Consumption'!V11 -> 6272.64 | AK9: ='Kwh area wise '!C10 -> 410 | AL9: ='Kwh area wise '!D10 -> 2300 | AM9: ='Kwh area wise '!E10 -> 220 | AN9: ='Kwh area wise '!F10 -> 590 | AO9: ='Kwh area wise '!G10 -> 460 | AP9: ='Kwh area wise '!H10 -> 1560 | AQ9: ='Kwh area wise '!I10 -> 4890 | AR9: ='Kwh area wise '!J10 -> 5617.36 | ... AT9: ='Kwh area wise '!L10 -> 6272.64 | AU9: ='Water Reading'!B10 -> 162367 | AV9: ='Water Reading'!C10 -> 123131 | AW9: ='Water Reading'!D10 -> 205904 | AX9: ='Water Reading'!E10 -> 246437 | AY9: ='Water Reading'!F10 -> 66911 | AZ9: ='Water Reading'!G10 -> 111266 | BA9: ='Water Reading'!H10 -> 51598 | BB9: ='Water Reading'!I10 -> 63140 | ... BK9: ='Water Reading'!R10 -> 6135 | BL9: ='Kwh Reading'!U10 -> 6181
A10: Maldives at Kuda Huraa | B10: =B9+1 -> 9 | C10: 6 | D10: 2021 | E10: ='Kwh Reading'!B11 -> 951.69 | F10: ='Kwh Reading'!C11 -> 224.57 | G10: ='Kwh Reading'!D11 -> 7426484.5 | H10: ='Kwh Reading'!E11 -> 8112916.3 | I10: ='Kwh Reading'!F11 -> 2.3266 | J10: ='Kwh Reading'!G11 -> 726.76 | K10: ='Kwh Reading'!H11 -> 612.23 | L10: ='Kwh Reading'!I11 -> 228.87 | ... W10: ='Kwh Reading'!T11 -> 411.17 | X10: ='Kwh Consumption'!J12 -> 140 | Y10: ='Kwh Consumption'!K12 -> 330 | Z10: ='Kwh Consumption'!L12 -> 1280 | AA10: ='Kwh Consumption'!M12 -> 920 | AB10: ='Kwh Consumption'!N12 -> 430 | AC10: ='Kwh Consumption'!O12 -> 1150 | AD10: ='Kwh Consumption'!P12 -> 950 | AE10: ='Kwh Consumption'!Q12 -> 1060 | ... AJ10: ='Kwh Consumption'!V12 -> 6276.55 | AK10: ='Kwh area wise '!C11 -> 470 | AL10: ='Kwh area wise '!D11 -> 2400 | AM10: ='Kwh area wise '!E11 -> 220 | AN10: ='Kwh area wise '!F11 -> 530 | AO10: ='Kwh area wise '!G11 -> 480 | AP10: ='Kwh area wise '!H11 -> 1610 | AQ10: ='Kwh area wise '!I11 -> 5350 | AR10: ='Kwh area wise '!J11 -> 5893.45 | ... AT10: ='Kwh area wise '!L11 -> 6276.55 | AU10: ='Water Reading'!B11 -> 162677 | AV10: ='Water Reading'!C11 -> 123466 | AW10: ='Water Reading'!D11 -> 206120 | AX10: ='Water Reading'!E11 -> 246505 | AY10: ='Water Reading'!F11 -> 66912 | AZ10: ='Water Reading'!G11 -> 111278 | BA10: ='Water Reading'!H11 -> 51665 | BB10: ='Water Reading'!I11 -> 63148 | ... BK10: ='Water Reading'!R11 -> 6138 | BL10: ='Kwh Reading'!U11 -> 6746
A11: Maldives at Kuda Huraa | B11: =B10+1 -> 10 | C11: 6 | D11: 2021 | E11: ='Kwh Reading'!B12 -> 952.97 | F11: ='Kwh Reading'!C12 -> 224.79 | G11: ='Kwh Reading'!D12 -> 7428945.2 | H11: ='Kwh Reading'!E12 -> 8116349.1 | I11: ='Kwh Reading'!F12 -> 2.329 | J11: ='Kwh Reading'!G12 -> 727.71 | K11: ='Kwh Reading'!H12 -> 612.66 | L11: ='Kwh Reading'!I12 -> 229.2 | ... W11: ='Kwh Reading'!T12 -> 411.64 | X11: ='Kwh Consumption'!J13 -> 120 | Y11: ='Kwh Consumption'!K13 -> 320 | Z11: ='Kwh Consumption'!L13 -> 1310 | AA11: ='Kwh Consumption'!M13 -> 890 | AB11: ='Kwh Consumption'!N13 -> 450 | AC11: ='Kwh Consumption'!O13 -> 1120 | AD11: ='Kwh Consumption'!P13 -> 1020 | AE11: ='Kwh Consumption'!Q13 -> 590 | ... AJ11: ='Kwh Consumption'!V13 -> 6558.64 | AK11: ='Kwh area wise '!C12 -> 460 | AL11: ='Kwh area wise '!D12 -> 2500 | AM11: ='Kwh area wise '!E12 -> 220 | AN11: ='Kwh area wise '!F12 -> 590 | AO11: ='Kwh area wise '!G12 -> 380 | AP11: ='Kwh area wise '!H12 -> 1630 | AQ11: ='Kwh area wise '!I12 -> 4920 | AR11: ='Kwh area wise '!J12 -> 5851.36 | ... AT11: ='Kwh area wise '!L12 -> 6558.64 | AU11: ='Water Reading'!B12 -> 162883 | AV11: ='Water Reading'!C12 -> 123604 | AW11: ='Water Reading'!D12 -> 206277 | AX11: ='Water Reading'!E12 -> 246570 | AY11: ='Water Reading'!F12 -> 66913 | AZ11: ='Water Reading'!G12 -> 111291 | BA11: ='Water Reading'!H12 -> 51724 | BB11: ='Water Reading'!I12 -> 63173 | ... BK11: ='Water Reading'!R12 -> 6142 | BL11: ='Kwh Reading'!U12 -> 6041
A12: Maldives at Kuda Huraa | B12: =B11+1 -> 11 | C12: 6 | D12: 2021 | E12: ='Kwh Reading'!B13 -> 954.28 | F12: ='Kwh Reading'!C13 -> 225.01 | G12: ='Kwh Reading'!D13 -> 7431482.3 | H12: ='Kwh Reading'!E13 -> 8119663.3 | I12: ='Kwh Reading'!F13 -> 2.3315 | J12: ='Kwh Reading'!G13 -> 728.73 | K12: ='Kwh Reading'!H13 -> 613.11 | L12: ='Kwh Reading'!I13 -> 229.52 | ... W12: ='Kwh Reading'!T13 -> 412.1 | X12: ='Kwh Consumption'!J14 -> 110 | Y12: ='Kwh Consumption'!K14 -> 330 | Z12: ='Kwh Consumption'!L14 -> 1410 | AA12: ='Kwh Consumption'!M14 -> 810 | AB12: ='Kwh Consumption'!N14 -> 420 | AC12: ='Kwh Consumption'!O14 -> 1170 | AD12: ='Kwh Consumption'!P14 -> 1010 | AE12: ='Kwh Consumption'!Q14 -> 760 | ... AJ12: ='Kwh Consumption'!V14 -> 5840.82 | AK12: ='Kwh area wise '!C13 -> 270 | AL12: ='Kwh area wise '!D13 -> 2600 | AM12: ='Kwh area wise '!E13 -> 250 | AN12: ='Kwh area wise '!F13 -> 620 | AO12: ='Kwh area wise '!G13 -> 410 | AP12: ='Kwh area wise '!H13 -> 1740 | AQ12: ='Kwh area wise '!I13 -> 5140 | AR12: ='Kwh area wise '!J13 -> 5539.18 | ... AT12: ='Kwh area wise '!L13 -> 5840.82 | AU12: ='Water Reading'!B13 -> 163035 | AV12: ='Water Reading'!C13 -> 123927 | AW12: ='Water Reading'!D13 -> 206400 | AX12: ='Water Reading'!E13 -> 246636 | AY12: ='Water Reading'!F13 -> 66913 | AZ12: ='Water Reading'!G13 -> 111309 | BA12: ='Water Reading'!H13 -> 51793 | BB12: ='Water Reading'!I13 -> 63197 | ... BK12: ='Water Reading'!R13 -> 6146 | BL12: ='Kwh Reading'!U13 -> 5988
A13: Maldives at Kuda Huraa | B13: =B12+1 -> 12 | C13: 6 | D13: 2021 | E13: ='Kwh Reading'!B14 -> 955.69 | F13: ='Kwh Reading'!C14 -> 225.26 | G13: ='Kwh Reading'!D14 -> 7433993 | H13: ='Kwh Reading'!E14 -> 8122691.8 | I13: ='Kwh Reading'!F14 -> 2.3341 | J13: ='Kwh Reading'!G14 -> 729.74 | K13: ='Kwh Reading'!H14 -> 613.53 | L13: ='Kwh Reading'!I14 -> 229.85 | ... W13: ='Kwh Reading'!T14 -> 412.37 | X13: ='Kwh Consumption'!J15 -> 110 | Y13: ='Kwh Consumption'!K15 -> 300 | Z13: ='Kwh Consumption'!L15 -> 1330 | AA13: ='Kwh Consumption'!M15 -> 700 | AB13: ='Kwh Consumption'!N15 -> 390 | AC13: ='Kwh Consumption'!O15 -> 1120 | AD13: ='Kwh Consumption'!P15 -> 920 | AE13: ='Kwh Consumption'!Q15 -> 730 | ... AJ13: ='Kwh Consumption'!V15 -> 6208.39 | AK13: ='Kwh area wise '!C14 -> 480 | AL13: ='Kwh area wise '!D14 -> 2400 | AM13: ='Kwh area wise '!E14 -> 210 | AN13: ='Kwh area wise '!F14 -> 580 | AO13: ='Kwh area wise '!G14 -> 440 | AP13: ='Kwh area wise '!H14 -> 1630 | AQ13: ='Kwh area wise '!I14 -> 4790 | AR13: ='Kwh area wise '!J14 -> 5691.61 | ... AT13: ='Kwh area wise '!L14 -> 6208.39 | AU13: ='Water Reading'!B14 -> 163126 | AV13: ='Water Reading'!C14 -> 124130 | AW13: ='Water Reading'!D14 -> 206514 | AX13: ='Water Reading'!E14 -> 246698 | AY13: ='Water Reading'!F14 -> 66914 | AZ13: ='Water Reading'!G14 -> 111326 | BA13: ='Water Reading'!H14 -> 51856 | BB13: ='Water Reading'!I14 -> 63216 | ... BK13: ='Water Reading'!R14 -> 6147 | BL13: ='Kwh Reading'!U14 -> 6353
A14: Maldives at Kuda Huraa | B14: =B13+1 -> 13 | C14: 6 | D14: 2021 | E14: ='Kwh Reading'!B15 -> 957.02 | F14: ='Kwh Reading'!C15 -> 225.47 | G14: ='Kwh Reading'!D15 -> 7436505.1 | H14: ='Kwh Reading'!E15 -> 8125871.3 | I14: ='Kwh Reading'!F15 -> 2.3365 | J14: ='Kwh Reading'!G15 -> 730.66 | K14: ='Kwh Reading'!H15 -> 613.92 | L14: ='Kwh Reading'!I15 -> 230.15 | ... W14: ='Kwh Reading'!T15 -> 412.85 | X14: ='Kwh Consumption'!J16 -> 160 | Y14: ='Kwh Consumption'!K16 -> 530 | Z14: ='Kwh Consumption'!L16 -> 1300 | AA14: ='Kwh Consumption'!M16 -> 740 | AB14: ='Kwh Consumption'!N16 -> 410 | AC14: ='Kwh Consumption'!O16 -> 1200 | AD14: ='Kwh Consumption'!P16 -> 970 | AE14: ='Kwh Consumption'!Q16 -> 650 | ... AJ14: ='Kwh Consumption'!V16 -> 6376.67 | AK14: ='Kwh area wise '!C15 -> 490 | AL14: ='Kwh area wise '!D15 -> 2500 | AM14: ='Kwh area wise '!E15 -> 240 | AN14: ='Kwh area wise '!F15 -> 590 | AO14: ='Kwh area wise '!G15 -> 470 | AP14: ='Kwh area wise '!H15 -> 1830 | AQ14: ='Kwh area wise '!I15 -> 4950 | AR14: ='Kwh area wise '!J15 -> 6003.33 | ... AT14: ='Kwh area wise '!L15 -> 6376.67 | AU14: ='Water Reading'!B15 -> 164135 | AV14: ='Water Reading'!C15 -> 124437 | AW14: ='Water Reading'!D15 -> 206612 | AX14: ='Water Reading'!E15 -> 246756 | AY14: ='Water Reading'!F15 -> 66915 | AZ14: ='Water Reading'!G15 -> 111340 | BA14: ='Water Reading'!H15 -> 51921 | BB14: ='Water Reading'!I15 -> 63243 | ... BK14: ='Water Reading'!R15 -> 6153 | BL14: ='Kwh Reading'!U15 -> 6542
... A31: Maldives at Kuda Huraa | B31: =B30+1 -> 30 | C31: 6 | D31: 2021 | E31: ='Kwh Reading'!B32 -> 0 | F31: ='Kwh Reading'!C32 -> 0 | G31: ='Kwh Reading'!D32 -> 0 | H31: ='Kwh Reading'!E32 -> 0 | I31: ='Kwh Reading'!F32 -> 0 | J31: ='Kwh Reading'!G32 -> 0 | K31: ='Kwh Reading'!H32 -> 0 | L31: ='Kwh Reading'!I32 -> 0 | ... W31: ='Kwh Reading'!T32 -> 0 | X31: ='Kwh Consumption'!J33 -> 0 | Y31: ='Kwh Consumption'!K33 -> 0 | Z31: ='Kwh Consumption'!L33 -> 0 | AA31: ='Kwh Consumption'!M33 -> 0 | AB31: ='Kwh Consumption'!N33 -> 0 | AC31: ='Kwh Consumption'!O33 -> 0 | AD31: ='Kwh Consumption'!P33 -> 0 | AE31: ='Kwh Consumption'!Q33 -> 0 | ... AJ31: ='Kwh Consumption'!V33 -> 0 | AK31: ='Kwh area wise '!C32 -> 0 | AL31: ='Kwh area wise '!D32 -> 0 | AM31: ='Kwh area wise '!E32 -> 0 | AN31: ='Kwh area wise '!F32 -> 0 | AO31: ='Kwh area wise '!G32 -> 0 | AP31: ='Kwh area wise '!H32 -> 0 | AQ31: ='Kwh area wise '!I32 -> 0 | AR31: ='Kwh area wise '!J32 -> 0 | ... AT31: ='Kwh area wise '!L32 -> 0 | AU31: ='Water Reading'!B32 -> 0 | AV31: ='Water Reading'!C32 -> 0 | AW31: ='Water Reading'!D32 -> 0 | AX31: ='Water Reading'!E32 -> 0 | AY31: ='Water Reading'!F32 -> 0 | AZ31: ='Water Reading'!G32 -> 0 | BA31: ='Water Reading'!H32 -> 0 | BB31: ='Water Reading'!I32 -> 0 | ... BK31: ='Water Reading'!R32 -> 0 | BL31: ='Kwh Reading'!U32 -> 0

Sheet Kwh Reading
A1: Month | B1: BOH-1/ B&C Block MWH | C1: Pastry MWH | D1: Feeder 401-419 KWH | E1: Feeder 301-319 KWH | F1: Kitchen GWH | G1: Feeder 201-208 MWH | H1: Feeder 113-123 | I1: M - Block /PC MWH | J1: Laundry MWH A | K1: Laundry MWH B | L1: Laundry MWH C | M1: Feeder 101-112 MWH | N1: Feeder 217-224 | O1: Spa MWH | P1: Feeder 124-134 | Q1: Feeder 209-216 | R1: STP -1 &2 MWH | S1: STP -3 MWH | T1: Reef Club MWH | U1: Total Fuel Oil (Liters) | X1: Room Nights | Y1: Total Guests | Z1: Food Covers
A3: 44348 | B3: 941.59 | C3: 222.83 | D3: 7406516.4 | E3: 8087986.4 | F3: 2.3081 | G3: 719.09 | H3: 608.01 | I3: 226.28 | J3: 310.55 | K3: 333.63 | L3: 228.43 | M3: 494.46 | N3: 448.54 | O3: 144.04 | P3: 586.59 | Q3: 439.13 | R3: 148.64 | S3: 111.34 | T3: 407.66 | U3: 6559 | X3: 20 | Y3: 46 | Z3: 141
A4: 44349 | B4: 942.77 | C4: 223.04 | D4: 7409069 | E4: 8091095.5 | F4: 2.3101 | G4: 720.02 | H4: 608.52 | I4: 226.59 | J4: 310.7 | K4: 333.86 | L4: 228.6 | M4: 495.24 | N4: 449.31 | O4: 144.3 | P4: 587.68 | Q4: 439.8 | R4: 148.97 | S4: 111.46 | T4: 408.14 | U4: 6159 | X4: 20 | Y4: 47 | Z4: 130
A5: 44350 | B5: 944.01 | C5: 223.25 | D5: 7411692.1 | E5: 8094277.3 | F5: 2.3124 | G5: 721.01 | H5: 609.1 | I5: 226.92 | J5: 310.87 | K5: 334.11 | L5: 228.76 | M5: 496.01 | N5: 450.13 | O5: 144.57 | P5: 588.83 | Q5: 440.53 | R5: 149.3 | S5: 111.61 | T5: 408.64 | U5: 6405 | X5: 19 | Y5: 46 | Z5: 130
A6: 44351 | B6: 945.3 | C6: 223.47 | D6: 7414329 | E6: 8097468.1 | F6: 2.3148 | G6: 721.98 | H6: 609.67 | I6: 227.28 | J6: 311.05 | K6: 334.35 | L6: 228.94 | M6: 496.8 | N6: 451.01 | O6: 144.8 | P6: 589.97 | Q6: 441.2 | R6: 149.64 | S6: 111.73 | T6: 409.16 | U6: 6004 | X6: 16 | Y6: 40 | Z6: 99
A7: 44352 | B7: 946.57 | C7: 223.72 | D7: 7416934.1 | E7: 8100365.9 | F7: 2.3171 | G7: 722.98 | H7: 610.2 | I7: 227.61 | J7: 311.28 | K7: 334.56 | L7: 229.16 | M7: 497.6 | N7: 451.86 | O7: 145.03 | P7: 591.04 | Q7: 441.91 | R7: 149.94 | S7: 111.85 | T7: 409.45 | U7: 5993 | X7: 14 | Y7: 36 | Z7: 137
A8: 44353 | B8: 947.76 | C8: 223.98 | D8: 7419302.4 | E8: 8103442.3 | F8: 2.3194 | G8: 723.95 | H8: 610.69 | I8: 227.91 | J8: 311.38 | K8: 334.65 | L8: 229.26 | M8: 498.37 | N8: 452.82 | O8: 145.27 | P8: 592.11 | Q8: 442.58 | R8: 150.27 | S8: 111.99 | T8: 409.93 | U8: 6523 | X8: 9 | Y8: 24 | Z8: 51
A9: 44354 | B9: 949.11 | C9: 224.15 | D9: 7421777.6 | E9: 8106476.7 | F9: 2.322 | G9: 724.89 | H9: 611.23 | I9: 228.23 | J9: 311.59 | K9: 334.94 | L9: 229.45 | M9: 499.23 | N9: 453.4 | O9: 145.53 | P9: 593.2 | Q9: 443.4 | R9: 150.44 | S9: 112.1 | T9: 410.35 | U9: 6177 | X9: 10 | Y9: 26 | Z9: 125
A10: 44355 | B10: 950.45 | C10: 224.35 | D10: 7424119.7 | E10: 8109663.8 | F10: 2.3243 | G10: 725.8 | H10: 611.76 | I10: 228.55 | J10: 311.78 | K10: 335.16 | L10: 229.64 | M10: 500.14 | N10: 454.18 | O10: 145.82 | P10: 594.25 | Q10: 444.22 | R10: 150.75 | S10: 112.22 | T10: 410.76 | U10: 6181 | X10: 13 | Y10: 32 | Z10: 80
A11: 44356 | B11: 951.69 | C11: 224.57 | D11: 7426484.5 | E11: 8112916.3 | F11: 2.3266 | G11: 726.76 | H11: 612.23 | I11: 228.87 | J11: 311.99 | K11: 335.38 | L11: 229.8 | M11: 501.04 | N11: 455 | O11: 146.11 | P11: 595.29 | Q11: 444.92 | R11: 151.06 | S11: 112.37 | T11: 411.17 | U11: 6746 | X11: 17 | Y11: 39 | Z11: 140
A12: 44357 | B12: 952.97 | C12: 224.79 | D12: 7428945.2 | E12: 8116349.1 | F12: 2.329 | G12: 727.71 | H12: 612.66 | I12: 229.2 | J12: 312.19 | K12: 335.54 | L12: 229.97 | M12: 501.96 | N12: 455.84 | O12: 146.39 | P12: 596.44 | Q12: 445.98 | R12: 151.4 | S12: 112.51 | T12: 411.64 | U12: 6041 | X12: 16 | Y12: 40 | Z12: 112
A13: 44358 | B13: 954.28 | C13: 225.01 | D13: 7431482.3 | E13: 8119663.3 | F13: 2.3315 | G13: 728.73 | H13: 613.11 | I13: 229.52 | J13: 312.34 | K13: 335.8 | L13: 230.15 | M13: 502.85 | N13: 456.69 | O13: 146.61 | P13: 597.56 | Q13: 446.57 | R13: 151.66 | S13: 112.63 | T13: 412.1 | U13: 5988 | X13: 19 | Y13: 44 | Z13: 116
A14: 44359 | B14: 955.69 | C14: 225.26 | D14: 7433993 | E14: 8122691.8 | F14: 2.3341 | G14: 729.74 | H14: 613.53 | I14: 229.85 | J14: 312.52 | K14: 336.06 | L14: 230.33 | M14: 503.66 | N14: 457.66 | O14: 146.91 | P14: 598.73 | Q14: 447.33 | R14: 151.96 | S14: 112.74 | T14: 412.37 | U14: 6353 | X14: 20 | Y14: 50 | Z14: 151
... A25: 44370 | B25: 970.73 | C25: 227.74 | D25: 7462669.1 | E25: 8159919.3 | F25: 2.3614 | G25: 739.94 | H25: 618.35 | I25: 233.57 | J25: 314.63 | K25: 338.7 | L25: 232.38 | M25: 512.54 | N25: 466.72 | O25: 149.67 | P25: 610.7 | Q25: 455.65 | R25: 155.36 | S25: 114.2 | T25: 417.3 | U25: 6383 | X25: 17 | Y25: 50 | Z25: 104
A26: 44371 | B26: 972.07 | C26: 227.98 | D26: 7464948.9 | E26: 8163578.8 | F26: 2.2639 | G26: 740.81 | H26: 618.85 | I26: 233.93 | J26: 314.87 | K26: 338.97 | L26: 232.57 | M26: 513.29 | N26: 467.48 | O26: 149.97 | P26: 611.8 | Q26: 456.39 | R26: 155.69 | S26: 114.33 | T26: 417.75
A27: 44372
A28: 44373
A29: 44374
A30: 44375
A31: 44376
A32: 44377
A33: 44378
X34: =SUM(X3:X33) -> 365 | Y34: =SUM(Y3:Y33) -> 938 | Z34: =SUM(Z3:Z33) -> 2696
T41: ……..

Sheet Kwh Consumption
A2: Date | B2: Total KWH | C2: Reef Club KWH | D2: Kitchen KWH | E2: Pastry KWH | F2: Laundry KWH | I2: STP -1 &2 KWH | J2: STP -3 KWH | K2: M - Block /PC KWH | L2: B&C Block KWH | M2: Guest Room Beach Pavilion & Beach Bungalow KWH | S2: Guest Room Water Bungalow KWH | U2: Spa KWH | V2: Others KWH
F3: A | G3: B | H3: C | M3: Feeder -101-112 | N3: Feeder -113-123 | O3: Feeder -124-134 | P3: Feeder -201-208 | Q3: Feeder -209-216 | R3: Feeder -217-224 | S3: Feeder -301-319 | T3: Feeder 401-419
A4: ='Kwh Reading'!A3 -> 44348 | B4: 25520 | C4: =('Kwh Reading'!T4-'Kwh Reading'!T3)*1000 -> 480 | D4: =('Kwh Reading'!F4-'Kwh Reading'!F3)*1000000 -> 2000 | E4: =('Kwh Reading'!C4-'Kwh Reading'!C3)*1000 -> 210 | F4: =('Kwh Reading'!J4-'Kwh Reading'!J3)*1000 -> 150 | G4: =('Kwh Reading'!K4-'Kwh Reading'!K3)*1000 -> 230 | H4: =('Kwh Reading'!L4-'Kwh Reading'!L3)*1000 -> 170 | I4: =('Kwh Reading'!R4-'Kwh Reading'!R3)*1000 -> 330 | J4: =('Kwh Reading'!S4-'Kwh Reading'!S3)*1000 -> 120 | K4: =('Kwh Reading'!I4-'Kwh Reading'!I3)*1000 -> 310 | L4: =('Kwh Reading'!B4-'Kwh Reading'!B3)*1000 -> 1180 | M4: =('Kwh Reading'!M4-'Kwh Reading'!M3)*1000 -> 780 | N4: =('Kwh Reading'!H4-'Kwh Reading'!H3)*1000 -> 510 | O4: =('Kwh Reading'!P4-'Kwh Reading'!P3)*1000 -> 1090 | P4: =('Kwh Reading'!G4-'Kwh Reading'!G3)*1000 -> 930 | Q4: =('Kwh Reading'!Q4-'Kwh Reading'!Q3)*1000 -> 670 | R4: =('Kwh Reading'!N4-'Kwh Reading'!N3)*1000 -> 770 | S4: ='Kwh Reading'!E4-'Kwh Reading'!E3 -> 3109.16 | T4: ='Kwh Reading'!D4-'Kwh Reading'!D3 -> 2552.56 | U4: =('Kwh Reading'!O4-'Kwh Reading'!O3)*1000 -> 260 | V4: =B4-(SUM(C4:U4)) -> 9668.28
A5: ='Kwh Reading'!A4 -> 44349 | B5: =TOTAL!E3 -> 23170 | C5: =('Kwh Reading'!T5-'Kwh Reading'!T4)*1000 -> 500 | D5: =('Kwh Reading'!F5-'Kwh Reading'!F4)*1000000 -> 2300 | E5: =('Kwh Reading'!C5-'Kwh Reading'!C4)*1000 -> 210 | F5: =('Kwh Reading'!J5-'Kwh Reading'!J4)*1000 -> 170 | G5: =('Kwh Reading'!K5-'Kwh Reading'!K4)*1000 -> 250 | H5: =('Kwh Reading'!L5-'Kwh Reading'!L4)*1000 -> 160 | I5: =('Kwh Reading'!R5-'Kwh Reading'!R4)*1000 -> 330 | J5: =('Kwh Reading'!S5-'Kwh Reading'!S4)*1000 -> 150 | K5: =('Kwh Reading'!I5-'Kwh Reading'!I4)*1000 -> 330 | L5: =('Kwh Reading'!B5-'Kwh Reading'!B4)*1000 -> 1240 | M5: =('Kwh Reading'!M5-'Kwh Reading'!M4)*1000 -> 770 | N5: =('Kwh Reading'!H5-'Kwh Reading'!H4)*1000 -> 580 | O5: =('Kwh Reading'!P5-'Kwh Reading'!P4)*1000 -> 1150 | P5: =('Kwh Reading'!G5-'Kwh Reading'!G4)*1000 -> 990 | Q5: =('Kwh Reading'!Q5-'Kwh Reading'!Q4)*1000 -> 730 | R5: =('Kwh Reading'!N5-'Kwh Reading'!N4)*1000 -> 820 | S5: ='Kwh Reading'!E5-'Kwh Reading'!E4 -> 3181.79 | T5: ='Kwh Reading'!D5-'Kwh Reading'!D4 -> 2623.13 | U5: =('Kwh Reading'!O5-'Kwh Reading'!O4)*1000 -> 270 | V5: =B5-(SUM(C5:U5)) -> 6415.08
A6: ='Kwh Reading'!A5 -> 44350 | B6: =TOTAL!E4 -> 22990 | C6: =('Kwh Reading'!T6-'Kwh Reading'!T5)*1000 -> 520 | D6: =('Kwh Reading'!F6-'Kwh Reading'!F5)*1000000 -> 2400 | E6: =('Kwh Reading'!C6-'Kwh Reading'!C5)*1000 -> 220 | F6: =('Kwh Reading'!J6-'Kwh Reading'!J5)*1000 -> 180 | G6: =('Kwh Reading'!K6-'Kwh Reading'!K5)*1000 -> 240 | H6: =('Kwh Reading'!L6-'Kwh Reading'!L5)*1000 -> 180 | I6: =('Kwh Reading'!R6-'Kwh Reading'!R5)*1000 -> 340 | J6: =('Kwh Reading'!S6-'Kwh Reading'!S5)*1000 -> 120 | K6: =('Kwh Reading'!I6-'Kwh Reading'!I5)*1000 -> 360 | L6: =('Kwh Reading'!B6-'Kwh Reading'!B5)*1000 -> 1290 | M6: =('Kwh Reading'!M6-'Kwh Reading'!M5)*1000 -> 790 | N6: =('Kwh Reading'!H6-'Kwh Reading'!H5)*1000 -> 570 | O6: =('Kwh Reading'!P6-'Kwh Reading'!P5)*1000 -> 1140 | P6: =('Kwh Reading'!G6-'Kwh Reading'!G5)*1000 -> 970 | Q6: =('Kwh Reading'!Q6-'Kwh Reading'!Q5)*1000 -> 670 | R6: =('Kwh Reading'!N6-'Kwh Reading'!N5)*1000 -> 880 | S6: ='Kwh Reading'!E6-'Kwh Reading'!E5 -> 3190.78 | T6: ='Kwh Reading'!D6-'Kwh Reading'!D5 -> 2636.91 | U6: =('Kwh Reading'!O6-'Kwh Reading'!O5)*1000 -> 230 | V6: =B6-(SUM(C6:U6)) -> 6062.31
A7: ='Kwh Reading'!A6 -> 44351 | B7: =TOTAL!E5 -> 22280 | C7: =('Kwh Reading'!T7-'Kwh Reading'!T6)*1000 -> 290 | D7: =('Kwh Reading'!F7-'Kwh Reading'!F6)*1000000 -> 2300 | E7: =('Kwh Reading'!C7-'Kwh Reading'!C6)*1000 -> 250 | F7: =('Kwh Reading'!J7-'Kwh Reading'!J6)*1000 -> 230 | G7: =('Kwh Reading'!K7-'Kwh Reading'!K6)*1000 -> 210 | H7: =('Kwh Reading'!L7-'Kwh Reading'!L6)*1000 -> 220 | I7: =('Kwh Reading'!R7-'Kwh Reading'!R6)*1000 -> 300 | J7: =('Kwh Reading'!S7-'Kwh Reading'!S6)*1000 -> 120 | K7: =('Kwh Reading'!I7-'Kwh Reading'!I6)*1000 -> 330 | L7: =('Kwh Reading'!B7-'Kwh Reading'!B6)*1000 -> 1270 | M7: =('Kwh Reading'!M7-'Kwh Reading'!M6)*1000 -> 800 | N7: =('Kwh Reading'!H7-'Kwh Reading'!H6)*1000 -> 530 | O7: =('Kwh Reading'!P7-'Kwh Reading'!P6)*1000 -> 1070 | P7: =('Kwh Reading'!G7-'Kwh Reading'!G6)*1000 -> 1000 | Q7: =('Kwh Reading'!Q7-'Kwh Reading'!Q6)*1000 -> 710 | R7: =('Kwh Reading'!N7-'Kwh Reading'!N6)*1000 -> 850 | S7: ='Kwh Reading'!E7-'Kwh Reading'!E6 -> 2897.82 | T7: ='Kwh Reading'!D7-'Kwh Reading'!D6 -> 2605.12 | U7: =('Kwh Reading'!O7-'Kwh Reading'!O6)*1000 -> 230 | V7: =B7-(SUM(C7:U7)) -> 6067.06
A8: ='Kwh Reading'!A7 -> 44352 | B8: =TOTAL!E6 -> 22610 | C8: =('Kwh Reading'!T8-'Kwh Reading'!T7)*1000 -> 480 | D8: =('Kwh Reading'!F8-'Kwh Reading'!F7)*1000000 -> 2300 | E8: =('Kwh Reading'!C8-'Kwh Reading'!C7)*1000 -> 260 | F8: =('Kwh Reading'!J8-'Kwh Reading'!J7)*1000 -> 100 | G8: =('Kwh Reading'!K8-'Kwh Reading'!K7)*1000 -> 90 | H8: =('Kwh Reading'!L8-'Kwh Reading'!L7)*1000 -> 100 | I8: =('Kwh Reading'!R8-'Kwh Reading'!R7)*1000 -> 330 | J8: =('Kwh Reading'!S8-'Kwh Reading'!S7)*1000 -> 140 | K8: =('Kwh Reading'!I8-'Kwh Reading'!I7)*1000 -> 300 | L8: =('Kwh Reading'!B8-'Kwh Reading'!B7)*1000 -> 1190 | M8: =('Kwh Reading'!M8-'Kwh Reading'!M7)*1000 -> 770 | N8: =('Kwh Reading'!H8-'Kwh Reading'!H7)*1000 -> 490 | O8: =('Kwh Reading'!P8-'Kwh Reading'!P7)*1000 -> 1070 | P8: =('Kwh Reading'!G8-'Kwh Reading'!G7)*1000 -> 970 | Q8: =('Kwh Reading'!Q8-'Kwh Reading'!Q7)*1000 -> 670 | R8: =('Kwh Reading'!N8-'Kwh Reading'!N7)*1000 -> 960 | S8: ='Kwh Reading'!E8-'Kwh Reading'!E7 -> 3076.36 | T8: ='Kwh Reading'!D8-'Kwh Reading'!D7 -> 2368.25 | U8: =('Kwh Reading'!O8-'Kwh Reading'!O7)*1000 -> 240 | V8: =B8-(SUM(C8:U8)) -> 6705.39
A9: ='Kwh Reading'!A8 -> 44353 | B9: =TOTAL!E7 -> 22650 | C9: =('Kwh Reading'!T9-'Kwh Reading'!T8)*1000 -> 420 | D9: =('Kwh Reading'!F9-'Kwh Reading'!F8)*1000000 -> 2600 | E9: =('Kwh Reading'!C9-'Kwh Reading'!C8)*1000 -> 170 | F9: =('Kwh Reading'!J9-'Kwh Reading'!J8)*1000 -> 210 | G9: =('Kwh Reading'!K9-'Kwh Reading'!K8)*1000 -> 290 | H9: =('Kwh Reading'!L9-'Kwh Reading'!L8)*1000 -> 190 | I9: =('Kwh Reading'!R9-'Kwh Reading'!R8)*1000 -> 170 | J9: =('Kwh Reading'!S9-'Kwh Reading'!S8)*1000 -> 110 | K9: =('Kwh Reading'!I9-'Kwh Reading'!I8)*1000 -> 320 | L9: =('Kwh Reading'!B9-'Kwh Reading'!B8)*1000 -> 1350 | M9: =('Kwh Reading'!M9-'Kwh Reading'!M8)*1000 -> 860 | N9: =('Kwh Reading'!H9-'Kwh Reading'!H8)*1000 -> 540 | O9: =('Kwh Reading'!P9-'Kwh Reading'!P8)*1000 -> 1090 | P9: =('Kwh Reading'!G9-'Kwh Reading'!G8)*1000 -> 940 | Q9: =('Kwh Reading'!Q9-'Kwh Reading'!Q8)*1000 -> 820 | R9: =('Kwh Reading'!N9-'Kwh Reading'!N8)*1000 -> 580 | S9: ='Kwh Reading'!E9-'Kwh Reading'!E8 -> 3034.4 | T9: ='Kwh Reading'!D9-'Kwh Reading'!D8 -> 2475.27 | U9: =('Kwh Reading'!O9-'Kwh Reading'!O8)*1000 -> 260 | V9: =B9-(SUM(C9:U9)) -> 6220.33
A10: ='Kwh Reading'!A9 -> 44354 | B10: =TOTAL!E8 -> 23300 | C10: =('Kwh Reading'!T10-'Kwh Reading'!T9)*1000 -> 410 | D10: =('Kwh Reading'!F10-'Kwh Reading'!F9)*1000000 -> 2300 | E10: =('Kwh Reading'!C10-'Kwh Reading'!C9)*1000 -> 200 | F10: =('Kwh Reading'!J10-'Kwh Reading'!J9)*1000 -> 190 | G10: =('Kwh Reading'!K10-'Kwh Reading'!K9)*1000 -> 220 | H10: =('Kwh Reading'!L10-'Kwh Reading'!L9)*1000 -> 190 | I10: =('Kwh Reading'!R10-'Kwh Reading'!R9)*1000 -> 310 | J10: =('Kwh Reading'!S10-'Kwh Reading'!S9)*1000 -> 120 | K10: =('Kwh Reading'!I10-'Kwh Reading'!I9)*1000 -> 320 | L10: =('Kwh Reading'!B10-'Kwh Reading'!B9)*1000 -> 1340 | M10: =('Kwh Reading'!M10-'Kwh Reading'!M9)*1000 -> 910 | N10: =('Kwh Reading'!H10-'Kwh Reading'!H9)*1000 -> 530 | O10: =('Kwh Reading'!P10-'Kwh Reading'!P9)*1000 -> 1050 | P10: =('Kwh Reading'!G10-'Kwh Reading'!G9)*1000 -> 910 | Q10: =('Kwh Reading'!Q10-'Kwh Reading'!Q9)*1000 -> 820 | R10: =('Kwh Reading'!N10-'Kwh Reading'!N9)*1000 -> 780 | S10: ='Kwh Reading'!E10-'Kwh Reading'!E9 -> 3187.08 | T10: ='Kwh Reading'!D10-'Kwh Reading'!D9 -> 2342.05 | U10: =('Kwh Reading'!O10-'Kwh Reading'!O9)*1000 -> 290 | V10: =B10-(SUM(C10:U10)) -> 6880.87
A11: ='Kwh Reading'!A10 -> 44355 | B11: =TOTAL!E9 -> 22610 | C11: =('Kwh Reading'!T11-'Kwh Reading'!T10)*1000 -> 410 | D11: =('Kwh Reading'!F11-'Kwh Reading'!F10)*1000000 -> 2300 | E11: =('Kwh Reading'!C11-'Kwh Reading'!C10)*1000 -> 220 | F11: =('Kwh Reading'!J11-'Kwh Reading'!J10)*1000 -> 210 | G11: =('Kwh Reading'!K11-'Kwh Reading'!K10)*1000 -> 220 | H11: =('Kwh Reading'!L11-'Kwh Reading'!L10)*1000 -> 160 | I11: =('Kwh Reading'!R11-'Kwh Reading'!R10)*1000 -> 310 | J11: =('Kwh Reading'!S11-'Kwh Reading'!S10)*1000 -> 150 | K11: =('Kwh Reading'!I11-'Kwh Reading'!I10)*1000 -> 320 | L11: =('Kwh Reading'!B11-'Kwh Reading'!B10)*1000 -> 1240 | M11: =('Kwh Reading'!M11-'Kwh Reading'!M10)*1000 -> 900 | N11: =('Kwh Reading'!H11-'Kwh Reading'!H10)*1000 -> 470 | O11: =('Kwh Reading'!P11-'Kwh Reading'!P10)*1000 -> 1040 | P11: =('Kwh Reading'!G11-'Kwh Reading'!G10)*1000 -> 960 | Q11: =('Kwh Reading'!Q11-'Kwh Reading'!Q10)*1000 -> 700 | R11: =('Kwh Reading'!N11-'Kwh Reading'!N10)*1000 -> 820 | S11: ='Kwh Reading'!E11-'Kwh Reading'!E10 -> 3252.57 | T11: ='Kwh Reading'!D11-'Kwh Reading'!D10 -> 2364.79 | U11: =('Kwh Reading'!O11-'Kwh Reading'!O10)*1000 -> 290 | V11: =B11-(SUM(C11:U11)) -> 6272.64
A12: ='Kwh Reading'!A11 -> 44356 | B12: =TOTAL!E10 -> 23510 | C12: =('Kwh Reading'!T12-'Kwh Reading'!T11)*1000 -> 470 | D12: =('Kwh Reading'!F12-'Kwh Reading'!F11)*1000000 -> 2400 | E12: =('Kwh Reading'!C12-'Kwh Reading'!C11)*1000 -> 220 | F12: =('Kwh Reading'!J12-'Kwh Reading'!J11)*1000 -> 200 | G12: =('Kwh Reading'!K12-'Kwh Reading'!K11)*1000 -> 160 | H12: =('Kwh Reading'!L12-'Kwh Reading'!L11)*1000 -> 170 | I12: =('Kwh Reading'!R12-'Kwh Reading'!R11)*1000 -> 340 | J12: =('Kwh Reading'!S12-'Kwh Reading'!S11)*1000 -> 140 | K12: =('Kwh Reading'!I12-'Kwh Reading'!I11)*1000 -> 330 | L12: =('Kwh Reading'!B12-'Kwh Reading'!B11)*1000 -> 1280 | M12: =('Kwh Reading'!M12-'Kwh Reading'!M11)*1000 -> 920 | N12: =('Kwh Reading'!H12-'Kwh Reading'!H11)*1000 -> 430 | O12: =('Kwh Reading'!P12-'Kwh Reading'!P11)*1000 -> 1150 | P12: =('Kwh Reading'!G12-'Kwh Reading'!G11)*1000 -> 950 | Q12: =('Kwh Reading'!Q12-'Kwh Reading'!Q11)*1000 -> 1060 | R12: =('Kwh Reading'!N12-'Kwh Reading'!N11)*1000 -> 840 | S12: ='Kwh Reading'!E12-'Kwh Reading'!E11 -> 3432.75 | T12: ='Kwh Reading'!D12-'Kwh Reading'!D11 -> 2460.7 | U12: =('Kwh Reading'!O12-'Kwh Reading'!O11)*1000 -> 280 | V12: =B12-(SUM(C12:U12)) -> 6276.55
A13: ='Kwh Reading'!A12 -> 44357 | B13: =TOTAL!E11 -> 23330 | C13: =('Kwh Reading'!T13-'Kwh Reading'!T12)*1000 -> 460 | D13: =('Kwh Reading'!F13-'Kwh Reading'!F12)*1000000 -> 2500 | E13: =('Kwh Reading'!C13-'Kwh Reading'!C12)*1000 -> 220 | F13: =('Kwh Reading'!J13-'Kwh Reading'!J12)*1000 -> 150 | G13: =('Kwh Reading'!K13-'Kwh Reading'!K12)*1000 -> 260 | H13: =('Kwh Reading'!L13-'Kwh Reading'!L12)*1000 -> 180 | I13: =('Kwh Reading'!R13-'Kwh Reading'!R12)*1000 -> 260 | J13: =('Kwh Reading'!S13-'Kwh Reading'!S12)*1000 -> 120 | K13: =('Kwh Reading'!I13-'Kwh Reading'!I12)*1000 -> 320 | L13: =('Kwh Reading'!B13-'Kwh Reading'!B12)*1000 -> 1310 | M13: =('Kwh Reading'!M13-'Kwh Reading'!M12)*1000 -> 890 | N13: =('Kwh Reading'!H13-'Kwh Reading'!H12)*1000 -> 450 | O13: =('Kwh Reading'!P13-'Kwh Reading'!P12)*1000 -> 1120 | P13: =('Kwh Reading'!G13-'Kwh Reading'!G12)*1000 -> 1020 | Q13: =('Kwh Reading'!Q13-'Kwh Reading'!Q12)*1000 -> 590 | R13: =('Kwh Reading'!N13-'Kwh Reading'!N12)*1000 -> 850 | S13: ='Kwh Reading'!E13-'Kwh Reading'!E12 -> 3314.23 | T13: ='Kwh Reading'!D13-'Kwh Reading'!D12 -> 2537.13 | U13: =('Kwh Reading'!O13-'Kwh Reading'!O12)*1000 -> 220 | V13: =B13-(SUM(C13:U13)) -> 6558.64
A14: ='Kwh Reading'!A13 -> 44358 | B14: =TOTAL!E12 -> 22710 | C14: =('Kwh Reading'!T14-'Kwh Reading'!T13)*1000 -> 270 | D14: =('Kwh Reading'!F14-'Kwh Reading'!F13)*1000000 -> 2600 | E14: =('Kwh Reading'!C14-'Kwh Reading'!C13)*1000 -> 250 | F14: =('Kwh Reading'!J14-'Kwh Reading'!J13)*1000 -> 180 | G14: =('Kwh Reading'!K14-'Kwh Reading'!K13)*1000 -> 260 | H14: =('Kwh Reading'!L14-'Kwh Reading'!L13)*1000 -> 180 | I14: =('Kwh Reading'!R14-'Kwh Reading'!R13)*1000 -> 300 | J14: =('Kwh Reading'!S14-'Kwh Reading'!S13)*1000 -> 110 | K14: =('Kwh Reading'!I14-'Kwh Reading'!I13)*1000 -> 330 | L14: =('Kwh Reading'!B14-'Kwh Reading'!B13)*1000 -> 1410 | M14: =('Kwh Reading'!M14-'Kwh Reading'!M13)*1000 -> 810 | N14: =('Kwh Reading'!H14-'Kwh Reading'!H13)*1000 -> 420 | O14: =('Kwh Reading'!P14-'Kwh Reading'!P13)*1000 -> 1170 | P14: =('Kwh Reading'!G14-'Kwh Reading'!G13)*1000 -> 1010 | Q14: =('Kwh Reading'!Q14-'Kwh Reading'!Q13)*1000 -> 760 | R14: =('Kwh Reading'!N14-'Kwh Reading'!N13)*1000 -> 970 | S14: ='Kwh Reading'!E14-'Kwh Reading'!E13 -> 3028.54 | T14: ='Kwh Reading'!D14-'Kwh Reading'!D13 -> 2510.64 | U14: =('Kwh Reading'!O14-'Kwh Reading'!O13)*1000 -> 300 | V14: =B14-(SUM(C14:U14)) -> 5840.82
A15: ='Kwh Reading'!A14 -> 44359 | B15: =TOTAL!E13 -> 22700 | C15: =('Kwh Reading'!T15-'Kwh Reading'!T14)*1000 -> 480 | D15: =('Kwh Reading'!F15-'Kwh Reading'!F14)*1000000 -> 2400 | E15: =('Kwh Reading'!C15-'Kwh Reading'!C14)*1000 -> 210 | F15: =('Kwh Reading'!J15-'Kwh Reading'!J14)*1000 -> 180 | G15: =('Kwh Reading'!K15-'Kwh Reading'!K14)*1000 -> 230 | H15: =('Kwh Reading'!L15-'Kwh Reading'!L14)*1000 -> 170 | I15: =('Kwh Reading'!R15-'Kwh Reading'!R14)*1000 -> 330 | J15: =('Kwh Reading'!S15-'Kwh Reading'!S14)*1000 -> 110 | K15: =('Kwh Reading'!I15-'Kwh Reading'!I14)*1000 -> 300 | L15: =('Kwh Reading'!B15-'Kwh Reading'!B14)*1000 -> 1330 | M15: =('Kwh Reading'!M15-'Kwh Reading'!M14)*1000 -> 700 | N15: =('Kwh Reading'!H15-'Kwh Reading'!H14)*1000 -> 390 | O15: =('Kwh Reading'!P15-'Kwh Reading'!P14)*1000 -> 1120 | P15: =('Kwh Reading'!G15-'Kwh Reading'!G14)*1000 -> 920 | Q15: =('Kwh Reading'!Q15-'Kwh Reading'!Q14)*1000 -> 730 | R15: =('Kwh Reading'!N15-'Kwh Reading'!N14)*1000 -> 930 | S15: ='Kwh Reading'!E15-'Kwh Reading'!E14 -> 3179.46 | T15: ='Kwh Reading'!D15-'Kwh Reading'!D14 -> 2512.15 | U15: =('Kwh Reading'!O15-'Kwh Reading'!O14)*1000 -> 270 | V15: =B15-(SUM(C15:U15)) -> 6208.39
A16: ='Kwh Reading'!A15 -> 44360 | B16: =TOTAL!E14 -> 23750 | C16: =('Kwh Reading'!T16-'Kwh Reading'!T15)*1000 -> 490 | D16: =('Kwh Reading'!F16-'Kwh Reading'!F15)*1000000 -> 2500 | E16: =('Kwh Reading'!C16-'Kwh Reading'!C15)*1000 -> 240 | F16: =('Kwh Reading'!J16-'Kwh Reading'!J15)*1000 -> 170 | G16: =('Kwh Reading'!K16-'Kwh Reading'!K15)*1000 -> 240 | H16: =('Kwh Reading'!L16-'Kwh Reading'!L15)*1000 -> 180 | I16: =('Kwh Reading'!R16-'Kwh Reading'!R15)*1000 -> 310 | J16: =('Kwh Reading'!S16-'Kwh Reading'!S15)*1000 -> 160 | K16: =('Kwh Reading'!I16-'Kwh Reading'!I15)*1000 -> 530 | L16: =('Kwh Reading'!B16-'Kwh Reading'!B15)*1000 -> 1300 | M16: =('Kwh Reading'!M16-'Kwh Reading'!M15)*1000 -> 740 | N16: =('Kwh Reading'!H16-'Kwh Reading'!H15)*1000 -> 410 | O16: =('Kwh Reading'!P16-'Kwh Reading'!P15)*1000 -> 1200 | P16: =('Kwh Reading'!G16-'Kwh Reading'!G15)*1000 -> 970 | Q16: =('Kwh Reading'!Q16-'Kwh Reading'!Q15)*1000 -> 650 | R16: =('Kwh Reading'!N16-'Kwh Reading'!N15)*1000 -> 980 | S16: ='Kwh Reading'!E16-'Kwh Reading'!E15 -> 3381.55 | T16: ='Kwh Reading'!D16-'Kwh Reading'!D15 -> 2621.78 | U16: =('Kwh Reading'!O16-'Kwh Reading'!O15)*1000 -> 300 | V16: =B16-(SUM(C16:U16)) -> 6376.67
... A34: ='Kwh Reading'!A33 -> 44378 | B34: =TOTAL!E32 -> 0 | C34: =('Kwh Reading'!T34-'Kwh Reading'!T33)*1000 -> 0 | D34: =('Kwh Reading'!F34-'Kwh Reading'!F33)*1000000 -> 0 | E34: =('Kwh Reading'!C34-'Kwh Reading'!C33)*1000 -> 0 | F34: =('Kwh Reading'!J34-'Kwh Reading'!J33)*1000 -> 0 | G34: =('Kwh Reading'!K34-'Kwh Reading'!K33)*1000 -> 0 | H34: =('Kwh Reading'!L34-'Kwh Reading'!L33)*1000 -> 0 | I34: =('Kwh Reading'!R34-'Kwh Reading'!R33)*1000 -> 0 | J34: =('Kwh Reading'!S34-'Kwh Reading'!S33)*1000 -> 0 | K34: =('Kwh Reading'!I34-'Kwh Reading'!I33)*1000 -> 0 | L34: =('Kwh Reading'!B34-'Kwh Reading'!B33)*1000 -> 0 | M34: =('Kwh Reading'!M34-'Kwh Reading'!M33)*1000 -> 0 | N34: =('Kwh Reading'!H34-'Kwh Reading'!H33)*1000 -> 0 | O34: =('Kwh Reading'!P34-'Kwh Reading'!P33)*1000 -> 0 | P34: =('Kwh Reading'!G34-'Kwh Reading'!G33)*1000 -> 0 | Q34: =('Kwh Reading'!Q34-'Kwh Reading'!Q33)*1000 -> 0 | R34: =('Kwh Reading'!N34-'Kwh Reading'!N33)*1000 -> 0 | S34: ='Kwh Reading'!E34-'Kwh Reading'!E33 -> 0 | T34: ='Kwh Reading'!D34-'Kwh Reading'!D33 -> 0 | U34: =('Kwh Reading'!O34-'Kwh Reading'!O33)*1000 -> 0 | V34: =B34-(SUM(C34:U34)) -> 0
A35: Total | B35: =SUM(B4:B34) -> 533420 | C35: =SUM(C4:C34) -> -407660 | D35: =SUM(D4:D34) -> -2308100 | E35: =SUM(E4:E34) -> -222830 | F35: =SUM(F4:F34) -> -310550 | G35: =SUM(G4:G34) -> -333630 | H35: =SUM(H4:H34) -> -228430 | I35: =SUM(I4:I34) -> -148640 | ... V35: =SUM(V4:V34) -> 24706833

Sheet Kwh area wise 
A2: Month | B2: Total KWH | C2: Reef Club Kitchen KWH | D2: Main Kitchen KWH | E2: Pastry Kitchen KWH | F2: Laundry KWH | G2: STP KWH | H2: Kuda Huraa Accomodation KWH | I2: Guest Room Beach Pavilion & Beach Bungalow KWH | J2: Guest Room Water Bungalow KWH | K2: Spa KWH | L2: Others KWH
A3: ='Kwh Reading'!A3 -> 44348 | B3: =TOTAL!E2 -> 22750 | C3: ='Kwh Consumption'!C4 -> 480 | D3: ='Kwh Consumption'!D4 -> 2000 | E3: ='Kwh Consumption'!E4 -> 210 | F3: =('Kwh Consumption'!F4+'Kwh Consumption'!G4+'Kwh Consumption'!H4) -> 550 | G3: =('Kwh Consumption'!I4+'Kwh Consumption'!J4) -> 450 | H3: =('Kwh Consumption'!K4+'Kwh Consumption'!L4) -> 1490 | I3: =('Kwh Consumption'!M4+'Kwh Consumption'!N4+'Kwh Consumption'!O4+'Kwh Consumption'!P4+'Kwh Consumption'!Q4+'Kwh Consumption'!R4) -> 4750 | J3: =('Kwh Consumption'!S4+'Kwh Consumption'!T4) -> 5661.72 | K3: ='Kwh Consumption'!U4 -> 260 | L3: =B3-C3-D3-E3-F3-G3-H3-I3-J3-K3 -> 6898.28
A4: ='Kwh Reading'!A4 -> 44349 | B4: =TOTAL!E3 -> 23170 | C4: ='Kwh Consumption'!C5 -> 500 | D4: ='Kwh Consumption'!D5 -> 2300 | E4: ='Kwh Consumption'!E5 -> 210 | F4: =('Kwh Consumption'!F5+'Kwh Consumption'!G5+'Kwh Consumption'!H5) -> 580 | G4: =('Kwh Consumption'!I5+'Kwh Consumption'!J5) -> 480 | H4: =('Kwh Consumption'!K5+'Kwh Consumption'!L5) -> 1570 | I4: =('Kwh Consumption'!M5+'Kwh Consumption'!N5+'Kwh Consumption'!O5+'Kwh Consumption'!P5+'Kwh Consumption'!Q5+'Kwh Consumption'!R5) -> 5040 | J4: =('Kwh Consumption'!S5+'Kwh Consumption'!T5) -> 5804.92 | K4: ='Kwh Consumption'!U5 -> 270 | L4: =B4-C4-D4-E4-F4-G4-H4-I4-J4-K4 -> 6415.08
A5: ='Kwh Reading'!A5 -> 44350 | B5: =TOTAL!E4 -> 22990 | C5: ='Kwh Consumption'!C6 -> 520 | D5: ='Kwh Consumption'!D6 -> 2400 | E5: ='Kwh Consumption'!E6 -> 220 | F5: =('Kwh Consumption'!F6+'Kwh Consumption'!G6+'Kwh Consumption'!H6) -> 600 | G5: =('Kwh Consumption'!I6+'Kwh Consumption'!J6) -> 460 | H5: =('Kwh Consumption'!K6+'Kwh Consumption'!L6) -> 1650 | I5: =('Kwh Consumption'!M6+'Kwh Consumption'!N6+'Kwh Consumption'!O6+'Kwh Consumption'!P6+'Kwh Consumption'!Q6+'Kwh Consumption'!R6) -> 5020 | J5: =('Kwh Consumption'!S6+'Kwh Consumption'!T6) -> 5827.69 | K5: ='Kwh Consumption'!U6 -> 230 | L5: =B5-C5-D5-E5-F5-G5-H5-I5-J5-K5 -> 6062.31
A6: ='Kwh Reading'!A6 -> 44351 | B6: =TOTAL!E5 -> 22280 | C6: ='Kwh Consumption'!C7 -> 290 | D6: ='Kwh Consumption'!D7 -> 2300 | E6: ='Kwh Consumption'!E7 -> 250 | F6: =('Kwh Consumption'!F7+'Kwh Consumption'!G7+'Kwh Consumption'!H7) -> 660 | G6: =('Kwh Consumption'!I7+'Kwh Consumption'!J7) -> 420 | H6: =('Kwh Consumption'!K7+'Kwh Consumption'!L7) -> 1600 | I6: =('Kwh Consumption'!M7+'Kwh Consumption'!N7+'Kwh Consumption'!O7+'Kwh Consumption'!P7+'Kwh Consumption'!Q7+'Kwh Consumption'!R7) -> 4960 | J6: =('Kwh Consumption'!S7+'Kwh Consumption'!T7) -> 5502.94 | K6: ='Kwh Consumption'!U7 -> 230 | L6: =B6-C6-D6-E6-F6-G6-H6-I6-J6-K6 -> 6067.06
A7: ='Kwh Reading'!A7 -> 44352 | B7: =TOTAL!E6 -> 22610 | C7: ='Kwh Consumption'!C8 -> 480 | D7: ='Kwh Consumption'!D8 -> 2300 | E7: ='Kwh Consumption'!E8 -> 260 | F7: =('Kwh Consumption'!F8+'Kwh Consumption'!G8+'Kwh Consumption'!H8) -> 290 | G7: =('Kwh Consumption'!I8+'Kwh Consumption'!J8) -> 470 | H7: =('Kwh Consumption'!K8+'Kwh Consumption'!L8) -> 1490 | I7: =('Kwh Consumption'!M8+'Kwh Consumption'!N8+'Kwh Consumption'!O8+'Kwh Consumption'!P8+'Kwh Consumption'!Q8+'Kwh Consumption'!R8) -> 4930 | J7: =('Kwh Consumption'!S8+'Kwh Consumption'!T8) -> 5444.61 | K7: ='Kwh Consumption'!U8 -> 240 | L7: =B7-C7-D7-E7-F7-G7-H7-I7-J7-K7 -> 6705.39
A8: ='Kwh Reading'!A8 -> 44353 | B8: =TOTAL!E7 -> 22650 | C8: ='Kwh Consumption'!C9 -> 420 | D8: ='Kwh Consumption'!D9 -> 2600 | E8: ='Kwh Consumption'!E9 -> 170 | F8: =('Kwh Consumption'!F9+'Kwh Consumption'!G9+'Kwh Consumption'!H9) -> 690 | G8: =('Kwh Consumption'!I9+'Kwh Consumption'!J9) -> 280 | H8: =('Kwh Consumption'!K9+'Kwh Consumption'!L9) -> 1670 | I8: =('Kwh Consumption'!M9+'Kwh Consumption'!N9+'Kwh Consumption'!O9+'Kwh Consumption'!P9+'Kwh Consumption'!Q9+'Kwh Consumption'!R9) -> 4830 | J8: =('Kwh Consumption'!S9+'Kwh Consumption'!T9) -> 5509.67 | K8: ='Kwh Consumption'!U9 -> 260 | L8: =B8-C8-D8-E8-F8-G8-H8-I8-J8-K8 -> 6220.33
A9: ='Kwh Reading'!A9 -> 44354 | B9: =TOTAL!E8 -> 23300 | C9: ='Kwh Consumption'!C10 -> 410 | D9: ='Kwh Consumption'!D10 -> 2300 | E9: ='Kwh Consumption'!E10 -> 200 | F9: =('Kwh Consumption'!F10+'Kwh Consumption'!G10+'Kwh Consumption'!H10) -> 600 | G9: =('Kwh Consumption'!I10+'Kwh Consumption'!J10) -> 430 | H9: =('Kwh Consumption'!K10+'Kwh Consumption'!L10) -> 1660 | I9: =('Kwh Consumption'!M10+'Kwh Consumption'!N10+'Kwh Consumption'!O10+'Kwh Consumption'!P10+'Kwh Consumption'!Q10+'Kwh Consumption'!R10) -> 5000 | J9: =('Kwh Consumption'!S10+'Kwh Consumption'!T10) -> 5529.13 | K9: ='Kwh Consumption'!U10 -> 290 | L9: =B9-C9-D9-E9-F9-G9-H9-I9-J9-K9 -> 6880.87
A10: ='Kwh Reading'!A10 -> 44355 | B10: =TOTAL!E9 -> 22610 | C10: ='Kwh Consumption'!C11 -> 410 | D10: ='Kwh Consumption'!D11 -> 2300 | E10: ='Kwh Consumption'!E11 -> 220 | F10: =('Kwh Consumption'!F11+'Kwh Consumption'!G11+'Kwh Consumption'!H11) -> 590 | G10: =('Kwh Consumption'!I11+'Kwh Consumption'!J11) -> 460 | H10: =('Kwh Consumption'!K11+'Kwh Consumption'!L11) -> 1560 | I10: =('Kwh Consumption'!M11+'Kwh Consumption'!N11+'Kwh Consumption'!O11+'Kwh Consumption'!P11+'Kwh Consumption'!Q11+'Kwh Consumption'!R11) -> 4890 | J10: =('Kwh Consumption'!S11+'Kwh Consumption'!T11) -> 5617.36 | K10: ='Kwh Consumption'!U11 -> 290 | L10: =B10-C10-D10-E10-F10-G10-H10-I10-J10-K10 -> 6272.64
A11: ='Kwh Reading'!A11 -> 44356 | B11: =TOTAL!E10 -> 23510 | C11: ='Kwh Consumption'!C12 -> 470 | D11: ='Kwh Consumption'!D12 -> 2400 | E11: ='Kwh Consumption'!E12 -> 220 | F11: =('Kwh Consumption'!F12+'Kwh Consumption'!G12+'Kwh Consumption'!H12) -> 530 | G11: =('Kwh Consumption'!I12+'Kwh Consumption'!J12) -> 480 | H11: =('Kwh Consumption'!K12+'Kwh Consumption'!L12) -> 1610 | I11: =('Kwh Consumption'!M12+'Kwh Consumption'!N12+'Kwh Consumption'!O12+'Kwh Consumption'!P12+'Kwh Consumption'!Q12+'Kwh Consumption'!R12) -> 5350 | J11: =('Kwh Consumption'!S12+'Kwh Consumption'!T12) -> 5893.45 | K11: ='Kwh Consumption'!U12 -> 280 | L11: =B11-C11-D11-E11-F11-G11-H11-I11-J11-K11 -> 6276.55
A12: ='Kwh Reading'!A12 -> 44357 | B12: =TOTAL!E11 -> 23330 | C12: ='Kwh Consumption'!C13 -> 460 | D12: ='Kwh Consumption'!D13 -> 2500 | E12: ='Kwh Consumption'!E13 -> 220 | F12: =('Kwh Consumption'!F13+'Kwh Consumption'!G13+'Kwh Consumption'!H13) -> 590 | G12: =('Kwh Consumption'!I13+'Kwh Consumption'!J13) -> 380 | H12: =('Kwh Consumption'!K13+'Kwh Consumption'!L13) -> 1630 | I12: =('Kwh Consumption'!M13+'Kwh Consumption'!N13+'Kwh Consumption'!O13+'Kwh Consumption'!P13+'Kwh Consumption'!Q13+'Kwh Consumption'!R13) -> 4920 | J12: =('Kwh Consumption'!S13+'Kwh Consumption'!T13) -> 5851.36 | K12: ='Kwh Consumption'!U13 -> 220 | L12: =B12-C12-D12-E12-F12-G12-H12-I12-J12-K12 -> 6558.64
A13: ='Kwh Reading'!A13 -> 44358 | B13: =TOTAL!E12 -> 22710 | C13: ='Kwh Consumption'!C14 -> 270 | D13: ='Kwh Consumption'!D14 -> 2600 | E13: ='Kwh Consumption'!E14 -> 250 | F13: =('Kwh Consumption'!F14+'Kwh Consumption'!G14+'Kwh Consumption'!H14) -> 620 | G13: =('Kwh Consumption'!I14+'Kwh Consumption'!J14) -> 410 | H13: =('Kwh Consumption'!K14+'Kwh Consumption'!L14) -> 1740 | I13: =('Kwh Consumption'!M14+'Kwh Consumption'!N14+'Kwh Consumption'!O14+'Kwh Consumption'!P14+'Kwh Consumption'!Q14+'Kwh Consumption'!R14) -> 5140 | J13: =('Kwh Consumption'!S14+'Kwh Consumption'!T14) -> 5539.18 | K13: ='Kwh Consumption'!U14 -> 300 | L13: =B13-C13-D13-E13-F13-G13-H13-I13-J13-K13 -> 5840.82
A14: ='Kwh Reading'!A14 -> 44359 | B14: =TOTAL!E13 -> 22700 | C14: ='Kwh Consumption'!C15 -> 480 | D14: ='Kwh Consumption'!D15 -> 2400 | E14: ='Kwh Consumption'!E15 -> 210 | F14: =('Kwh Consumption'!F15+'Kwh Consumption'!G15+'Kwh Consumption'!H15) -> 580 | G14: =('Kwh Consumption'!I15+'Kwh Consumption'!J15) -> 440 | H14: =('Kwh Consumption'!K15+'Kwh Consumption'!L15) -> 1630 | I14: =('Kwh Consumption'!M15+'Kwh Consumption'!N15+'Kwh Consumption'!O15+'Kwh Consumption'!P15+'Kwh Consumption'!Q15+'Kwh Consumption'!R15) -> 4790 | J14: =('Kwh Consumption'!S15+'Kwh Consumption'!T15) -> 5691.61 | K14: ='Kwh Consumption'!U15 -> 270 | L14: =B14-C14-D14-E14-F14-G14-H14-I14-J14-K14 -> 6208.39
... A33: ='Kwh Reading'!A33 -> 44378 | B33: =TOTAL!E32 -> 0 | C33: ='Kwh Consumption'!C34 -> 0 | D33: ='Kwh Consumption'!D34 -> 0 | E33: ='Kwh Consumption'!E34 -> 0 | F33: =('Kwh Consumption'!F34+'Kwh Consumption'!G34+'Kwh Consumption'!H34) -> 0 | G33: =('Kwh Consumption'!I34+'Kwh Consumption'!J34) -> 0 | H33: =('Kwh Consumption'!K34+'Kwh Consumption'!L34) -> 0 | I33: =('Kwh Consumption'!M34+'Kwh Consumption'!N34+'Kwh Consumption'!O34+'Kwh Consumption'!P34+'Kwh Consumption'!Q34+'Kwh Consumption'!R34) -> 0 | J33: =('Kwh Consumption'!S34+'Kwh Consumption'!T34) -> 0 | K33: ='Kwh Consumption'!U34 -> 0 | L33: =B33-C33-D33-E33-F33-G33-H33-I33-J33-K33 -> 0
A34: Total kwh | B34: =SUM(B3:B33) -> 530650 | C34: =SUM(C3:C33) -> -407660 | D34: =SUM(D3:D33) -> -2308100 | E34: =SUM(E3:E33) -> -222830 | F34: =SUM(F3:F33) -> -872610 | G34: =SUM(G3:G33) -> -259980 | H34: =SUM(H3:H33) -> -1167870 | I34: =SUM(I3:I33) -> -3295820 | ... L34: =SUM(L3:L33) -> 24704063 | M34: =C34+D34+E34+F34+G34+H34+I34+J34+K34+L34 -> 530650
A36: Total $ | B36: =TOTAL!F2 -> 0.14 | C36: =C34*B36 -> -57072.4 | D36: =D34*B36 -> -323134 | E36: =E34*B36 -> -31196.2 | F36: =F34*B36 -> -122165.4 | G36: =G34*B36 -> -36397.2 | H36: =H34*B36 -> -163501.8 | I36: =I34*B36 -> -461414.8 | J36: =J34*B36 -> -2169230.4 | K36: =K34*B36 -> -20165.6 | L36: =L34*B36 -> 3458568.8 | M36: =C36+D36+E36+F36+G36+H36+I36+J36+K36+L36 -> 74291

Sheet  Kwh area wise $ 
A2: Month | B2: $ /Per KWH | C2: Total $ | D2: Reef Club $ | E2: Kitchen $ | F2: Pastry $ | G2: Laundry $ | H2: STP $ | I2: Kuda Huraa Accomodation $ | J2: Guest Room Beach Pavilion & Beach Bungalow $ | K2: Guest Room Water Bungalow $ | L2: Spa $ | M2: Others $
A3: ='Kwh Reading'!A3 -> 44348 | B3: =TOTAL!F2 -> 0.14 | C3: ='Kwh Consumption'!B4*' Kwh area wise $ '!B3 -> 3572.8 | D3: ='Kwh Consumption'!C4*' Kwh area wise $ '!B3 -> 67.2 | E3: ='Kwh Consumption'!D4*' Kwh area wise $ '!B3 -> 280 | F3: ='Kwh Consumption'!E4*' Kwh area wise $ '!B3 -> 29.4 | G3: =('Kwh Consumption'!F4+'Kwh Consumption'!G4+'Kwh Consumption'!H4)*' Kwh area wise $ '!B3 -> 77 | H3: =('Kwh Consumption'!I4+'Kwh Consumption'!J4)*' Kwh area wise $ '!B3 -> 63 | I3: =('Kwh Consumption'!K4+'Kwh Consumption'!L4)*' Kwh area wise $ '!B3 -> 208.6 | J3: =('Kwh Consumption'!M4+'Kwh Consumption'!N4+'Kwh Consumption'!O4+'Kwh Consumption'!P4+'Kwh Consumption'!Q4+'Kwh Consumption'!R4)*' Kwh area wise $ '!B3 -> 665 | K3: =('Kwh Consumption'!S4+'Kwh Consumption'!T4)*' Kwh area wise $ '!B3 -> 792.6408 | L3: ='Kwh Consumption'!U4*' Kwh area wise $ '!B3 -> 36.4 | M3: ='Kwh Consumption'!V4*' Kwh area wise $ '!B3 -> 1353.5592
A4: ='Kwh Reading'!A4 -> 44349 | B4: =TOTAL!F3 -> 0.14 | C4: ='Kwh Consumption'!B5*' Kwh area wise $ '!B4 -> 3243.8 | D4: ='Kwh Consumption'!C5*' Kwh area wise $ '!B4 -> 70 | E4: ='Kwh Consumption'!D5*' Kwh area wise $ '!B4 -> 322 | F4: ='Kwh Consumption'!E5*' Kwh area wise $ '!B4 -> 29.4 | G4: =('Kwh Consumption'!F5+'Kwh Consumption'!G5+'Kwh Consumption'!H5)*' Kwh area wise $ '!B4 -> 81.2 | H4: =('Kwh Consumption'!I5+'Kwh Consumption'!J5)*' Kwh area wise $ '!B4 -> 67.2 | I4: =('Kwh Consumption'!K5+'Kwh Consumption'!L5)*' Kwh area wise $ '!B4 -> 219.8 | J4: =('Kwh Consumption'!M5+'Kwh Consumption'!N5+'Kwh Consumption'!O5+'Kwh Consumption'!P5+'Kwh Consumption'!Q5+'Kwh Consumption'!R5)*' Kwh area wise $ '!B4 -> 705.6 | K4: =('Kwh Consumption'!S5+'Kwh Consumption'!T5)*' Kwh area wise $ '!B4 -> 812.6888 | L4: ='Kwh Consumption'!U5*' Kwh area wise $ '!B4 -> 37.8 | M4: ='Kwh Consumption'!V5*' Kwh area wise $ '!B4 -> 898.1112
A5: ='Kwh Reading'!A5 -> 44350 | B5: =TOTAL!F4 -> 0.14 | C5: ='Kwh Consumption'!B6*' Kwh area wise $ '!B5 -> 3218.6 | D5: ='Kwh Consumption'!C6*' Kwh area wise $ '!B5 -> 72.8 | E5: ='Kwh Consumption'!D6*' Kwh area wise $ '!B5 -> 336 | F5: ='Kwh Consumption'!E6*' Kwh area wise $ '!B5 -> 30.8 | G5: =('Kwh Consumption'!F6+'Kwh Consumption'!G6+'Kwh Consumption'!H6)*' Kwh area wise $ '!B5 -> 84 | H5: =('Kwh Consumption'!I6+'Kwh Consumption'!J6)*' Kwh area wise $ '!B5 -> 64.4 | I5: =('Kwh Consumption'!K6+'Kwh Consumption'!L6)*' Kwh area wise $ '!B5 -> 231 | J5: =('Kwh Consumption'!M6+'Kwh Consumption'!N6+'Kwh Consumption'!O6+'Kwh Consumption'!P6+'Kwh Consumption'!Q6+'Kwh Consumption'!R6)*' Kwh area wise $ '!B5 -> 702.8 | K5: =('Kwh Consumption'!S6+'Kwh Consumption'!T6)*' Kwh area wise $ '!B5 -> 815.8766 | L5: ='Kwh Consumption'!U6*' Kwh area wise $ '!B5 -> 32.2 | M5: ='Kwh Consumption'!V6*' Kwh area wise $ '!B5 -> 848.7234
