Workbook

Sheet TOTAL
A1: Site Name | B1: Day | C1: Month | D1: Year | E1: Total Electricity Kwh | F1: Electricity Tariff ($/Kwh) | G1: LPG (Kg) | H1: LPG $/Kg | I1: Water Utility Supply (m3) m3 | J1: Water Utility Supply (m3) $/m3 | K1: Room Nights | L1: Food Covers
A2: Maldives at Landaa Giraavaru | B2: 1 | C2: 7 | D2: 2021 | E2: ='Maldives at LG Daily'!D5 -> 91326074 | F2: 0.93 | G2: ='Maldives at LG Daily'!F5 -> 225 | H2: 1.24 | I2: ='Maldives at LG Daily'!H5 -> 418 | J2: 2.16 | K2: ='Maldives at LG Daily'!I5 -> 18.4 | L2: ='Maldives at LG Daily'!J5 -> 160
A3: Maldives at Landaa Giraavaru | B3: =B2+1 -> 2 | C3: 7 | D3: 2021 | E3: ='Maldives at LG Daily'!D6 -> 26846 | F3: 0.93 | G3: ='Maldives at LG Daily'!F6 -> 0 | H3: 1.24 | I3: ='Maldives at LG Daily'!H6 -> 316 | J3: 2.16 | K3: ='Maldives at LG Daily'!I6 -> 12.7 | L3: ='Maldives at LG Daily'!J6 -> 181
A4: Maldives at Landaa Giraavaru | B4: =B3+1 -> 3 | C4: 7 | D4: 2021 | E4: ='Maldives at LG Daily'!D7 -> 27330 | F4: 0.93 | G4: ='Maldives at LG Daily'!F7 -> 0 | H4: 1.24 | I4: ='Maldives at LG Daily'!H7 -> 330 | J4: 2.16 | K4: ='Maldives at LG Daily'!I7 -> 12.6 | L4: ='Maldives at LG Daily'!J7 -> 134
A5: Maldives at Landaa Giraavaru | B5: =B4+1 -> 4 | C5: 7 | D5: 2021 | E5: ='Maldives at LG Daily'!D8 -> 27327 | F5: 0.93 | G5: ='Maldives at LG Daily'!F8 -> 90 | H5: 1.24 | I5: ='Maldives at LG Daily'!H8 -> 326 | J5: 2.16 | K5: ='Maldives at LG Daily'!I8 -> 15.5 | L5: ='Maldives at LG Daily'!J8 -> 169
A6: Maldives at Landaa Giraavaru | B6: =B5+1 -> 5 | C6: 7 | D6: 2021 | E6: ='Maldives at LG Daily'!D9 -> 26205 | F6: 0.93 | G6: ='Maldives at LG Daily'!F9 -> 0 | H6: 1.24 | I6: ='Maldives at LG Daily'!H9 -> 306 | J6: 2.16 | K6: ='Maldives at LG Daily'!I9 -> 13.6 | L6: ='Maldives at LG Daily'!J9 -> 140
A7: Maldives at Landaa Giraavaru | B7: =B6+1 -> 6 | C7: 7 | D7: 2021 | E7: ='Maldives at LG Daily'!D10 -> 27166 | F7: 0.93 | G7: ='Maldives at LG Daily'!F10 -> 0 | H7: 1.24 | I7: ='Maldives at LG Daily'!H10 -> 375 | J7: 2.16 | K7: ='Maldives at LG Daily'!I10 -> 15.5 | L7: ='Maldives at LG Daily'!J10 -> 145
A8: Maldives at Landaa Giraavaru | B8: =B7+1 -> 7 | C8: 7 | D8: 2021 | E8: ='Maldives at LG Daily'!D11 -> 24691 | F8: 0.93 | G8: ='Maldives at LG Daily'!F11 -> 0 | H8: 1.24 | I8: ='Maldives at LG Daily'!H11 -> 380 | J8: 2.16 | K8: ='Maldives at LG Daily'!I11 -> 17.5 | L8: ='Maldives at LG Daily'!J11 -> 198
A9: Maldives at Landaa Giraavaru | B9: =B8+1 -> 8 | C9: 7 | D9: 2021 | E9: ='Maldives at LG Daily'!D12 -> 25450 | F9: 0.93 | G9: ='Maldives at LG Daily'!F12 -> 0 | H9: 1.24 | I9: ='Maldives at LG Daily'!H12 -> 283 | J9: 2.16 | K9: ='Maldives at LG Daily'!I12 -> 16.5 | L9: ='Maldives at LG Daily'!J12 -> 191
A10: Maldives at Landaa Giraavaru | B10: =B9+1 -> 9 | C10: 7 | D10: 2021 | E10: ='Maldives at LG Daily'!D13 -> 22674 | F10: 0.93 | G10: ='Maldives at LG Daily'!F13 -> 0 | H10: 1.24 | I10: ='Maldives at LG Daily'!H13 -> 318 | J10: 2.16 | K10: ='Maldives at LG Daily'!I13 -> 16.5 | L10: ='Maldives at LG Daily'!J13 -> 162
A11: Maldives at Landaa Giraavaru | B11: =B10+1 -> 10 | C11: 7 | D11: 2021 | E11: ='Maldives at LG Daily'!D14 -> 23356 | F11: 0.93 | G11: ='Maldives at LG Daily'!F14 -> 45 | H11: 1.24 | I11: ='Maldives at LG Daily'!H14 -> 376 | J11: 2.16 | K11: ='Maldives at LG Daily'!I14 -> 13.6 | L11: ='Maldives at LG Daily'!J14 -> 164
A12: Maldives at Landaa Giraavaru | B12: =B11+1 -> 11 | C12: 7 | D12: 2021 | E12: ='Maldives at LG Daily'!D15 -> 23328 | F12: 0.93 | G12: ='Maldives at LG Daily'!F15 -> 0 | H12: 1.24 | I12: ='Maldives at LG Daily'!H15 -> 286 | J12: 2.16 | K12: ='Maldives at LG Daily'!I15 -> 11.7 | L12: ='Maldives at LG Daily'!J15 -> 127
A13: Maldives at Landaa Giraavaru | B13: =B12+1 -> 12 | C13: 7 | D13: 2021 | E13: ='Maldives at LG Daily'!D16 -> 25504 | F13: 0.93 | G13: ='Maldives at LG Daily'!F16 -> 0 | H13: 1.24 | I13: ='Maldives at LG Daily'!H16 -> 300 | J13: 2.16 | K13: ='Maldives at LG Daily'!I16 -> 11.7 | L13: ='Maldives at LG Daily'!J16 -> 149
A14: Maldives at Landaa Giraavaru | B14: =B13+1 -> 13 | C14: 7 | D14: 2021 | E14: ='Maldives at LG Daily'!D17 -> 24640 | F14: 0.93 | G14: ='Maldives at LG Daily'!F17 -> 0 | H14: 1.24 | I14: ='Maldives at LG Daily'!H17 -> 319 | J14: 2.16 | K14: ='Maldives at LG Daily'!I17 -> 12.6 | L14: ='Maldives at LG Daily'!J17 -> 159
... A30: Maldives at Landaa Giraavaru | B30: =B29+1 -> 29 | C30: 7 | D30: 2021 | E30: ='Maldives at LG Daily'!D33 -> 0 | F30: 0.93 | G30: ='Maldives at LG Daily'!F33 -> 0 | H30: 1.24 | I30: ='Maldives at LG Daily'!H33 -> 0 | J30: 2.16 | K30: ='Maldives at LG Daily'!I33 -> 0 | L30: ='Maldives at LG Daily'!J33 -> 0
A31: Maldives at Landaa Giraavaru | B31: 30 | C31: 7 | D31: 2021 | E31: ='Maldives at LG Daily'!D34 -> 0 | F31: 0.93 | G31: ='Maldives at LG Daily'!F34 -> 0 | H31: 1.24 | I31: ='Maldives at LG Daily'!H34 -> 0 | J31: 2.16 | K31: ='Maldives at LG Daily'!I34 -> 0 | L31: ='Maldives at LG Daily'!J34 -> 0
A32: Maldives at Landaa Giraavaru | B32: 31 | C32: 7 | D32: 2021 | E32: ='Maldives at LG Daily'!D35 -> 0 | F32: 0.93 | G32: ='Maldives at LG Daily'!F35 -> 0 | H32: 1.24 | I32: ='Maldives at LG Daily'!H35 -> 0 | J32: 2.16 | K32: ='Maldives at LG Daily'!I35 -> 0 | L32: ='Maldives at LG Daily'!J35 -> 0

Sheet Maldives at LG Daily
A2: Days | C2: Electricity Meter (KWh) | E2: Gas Kg | G2: Water m3
A3: Date | C3: Reading KWH | D3: Difference KWH | E3: Reading Kg | F3: Difference Kg | G3: Reading m³ | H3: Daily Consumption m³ | I3: ROOM NIGHTS | J3: TOTAL GUESTS
A4: 44377 | C4: =C35 -> 0 | D4: =D35 -> 0 | E4: ='Gas-2'!G5 -> 0 | F4: 90 | G4: =SUM(WATER!G6,WATER!L6,WATER!Q6,WATER!B6) -> 969007 | H4: 423
A5: =A4+1 -> 44378 | C5: =SUM('GENSET #1'!C10+'GENSET #2'!C10+'GENSET #3'!C10+'GENSET #4'!C10+'GENSET #5'!C10) -> 91326074 | D5: =IF((C5-C4<0), "0",C5-C4) -> 91326074 | E5: ='Gas-2'!G6 -> 225 | F5: =IF((E5-E4<0), "0",E5-E4) -> 225 | G5: =SUM(WATER!C6,WATER!H6,WATER!M6,WATER!R6) -> 969322 | H5: 418 | I5: 18.4 | J5: 160
A6: =A5+1 -> 44379 | C6: =SUM('GENSET #1'!C11+'GENSET #2'!C11+'GENSET #3'!C11+'GENSET #4'!C11+'GENSET #5'!C11) -> 91352920 | D6: =IF((C6-C5<0), "0",C6-C5) -> 26846 | E6: ='Gas-2'!G7 -> 225 | F6: =IF((E6-E5<0), "0",E6-E5) -> 0 | G6: =SUM(WATER!C7,WATER!H7,WATER!M7,WATER!R7) -> 969638 | H6: =IF((G6-G5<0), "0",G6-G5) -> 316 | I6: 12.7 | J6: 181
A7: =A6+1 -> 44380 | C7: =SUM('GENSET #1'!C12+'GENSET #2'!C12+'GENSET #3'!C12+'GENSET #4'!C12+'GENSET #5'!C12) -> 91380250 | D7: =IF((C7-C6<0), "0",C7-C6) -> 27330 | E7: ='Gas-2'!G8 -> 180 | F7: =IF((E7-E6<0), "0",E7-E6) -> 0 | G7: =SUM(WATER!C8,WATER!H8,WATER!M8,WATER!R8) -> 969968 | H7: =IF((G7-G6<0), "0",G7-G6) -> 330 | I7: 12.6 | J7: 134
A8: =A7+1 -> 44381 | C8: =SUM('GENSET #1'!C13+'GENSET #2'!C13+'GENSET #3'!C13+'GENSET #4'!C13+'GENSET #5'!C13) -> 91407577 | D8: =IF((C8-C7<0), "0",C8-C7) -> 27327 | E8: ='Gas-2'!G9 -> 270 | F8: =IF((E8-E7<0), "0",E8-E7) -> 90 | G8: =SUM(WATER!C9,WATER!H9,WATER!M9,WATER!R9) -> 970294 | H8: =IF((G8-G7<0), "0",G8-G7) -> 326 | I8: 15.5 | J8: 169
A9: =A8+1 -> 44382 | C9: =SUM('GENSET #1'!C14+'GENSET #2'!C14+'GENSET #3'!C14+'GENSET #4'!C14+'GENSET #5'!C14) -> 91433782 | D9: =IF((C9-C8<0), "0",C9-C8) -> 26205 | E9: ='Gas-2'!G10 -> 270 | F9: =IF((E9-E8<0), "0",E9-E8) -> 0 | G9: =SUM(WATER!C10,WATER!H10,WATER!M10,WATER!R10) -> 970600 | H9: =IF((G9-G8<0), "0",G9-G8) -> 306 | I9: 13.6 | J9: 140
A10: =A9+1 -> 44383 | C10: =SUM('GENSET #1'!C15+'GENSET #2'!C15+'GENSET #3'!C15+'GENSET #4'!C15+'GENSET #5'!C15) -> 91460948 | D10: =IF((C10-C9<0), "0",C10-C9) -> 27166 | E10: ='Gas-2'!G11 -> 225 | F10: =IF((E10-E9<0), "0",E10-E9) -> 0 | G10: =SUM(WATER!C11,WATER!H11,WATER!M11,WATER!R11) -> 970975 | H10: =IF((G10-G9<0), "0",G10-G9) -> 375 | I10: 15.5 | J10: 145
A11: =A10+1 -> 44384 | C11: =SUM('GENSET #1'!C16+'GENSET #2'!C16+'GENSET #3'!C16+'GENSET #4'!C16+'GENSET #5'!C16) -> 91485639 | D11: =IF((C11-C10<0), "0",C11-C10) -> 24691 | E11: ='Gas-2'!G12 -> 225 | F11: =IF((E11-E10<0), "0",E11-E10) -> 0 | G11: =SUM(WATER!C12,WATER!H12,WATER!M12,WATER!R12) -> 971355 | H11: =IF((G11-G10<0), "0",G11-G10) -> 380 | I11: 17.5 | J11: 198
A12: =A11+1 -> 44385 | C12: =SUM('GENSET #1'!C17+'GENSET #2'!C17+'GENSET #3'!C17+'GENSET #4'!C17+'GENSET #5'!C17) -> 91511089 | D12: =IF((C12-C11<0), "0",C12-C11) -> 25450 | E12: ='Gas-2'!G13 -> 225 | F12: =IF((E12-E11<0), "0",E12-E11) -> 0 | G12: =SUM(WATER!C13,WATER!H13,WATER!M13,WATER!R13) -> 971638 | H12: =IF((G12-G11<0), "0",G12-G11) -> 283 | I12: 16.5 | J12: 191
A13: =A12+1 -> 44386 | C13: =SUM('GENSET #1'!C18+'GENSET #2'!C18+'GENSET #3'!C18+'GENSET #4'!C18+'GENSET #5'!C18) -> 91533763 | D13: =IF((C13-C12<0), "0",C13-C12) -> 22674 | E13: ='Gas-2'!G14 -> 225 | F13: =IF((E13-E12<0), "0",E13-E12) -> 0 | G13: =SUM(WATER!C14,WATER!H14,WATER!M14,WATER!R14) -> 971956 | H13: =IF((G13-G12<0), "0",G13-G12) -> 318 | I13: 16.5 | J13: 162
A14: =A13+1 -> 44387 | C14: =SUM('GENSET #1'!C19+'GENSET #2'!C19+'GENSET #3'!C19+'GENSET #4'!C19+'GENSET #5'!C19) -> 91557119 | D14: =IF((C14-C13<0), "0",C14-C13) -> 23356 | E14: ='Gas-2'!G15 -> 270 | F14: =IF((E14-E13<0), "0",E14-E13) -> 45 | G14: =SUM(WATER!C15,WATER!H15,WATER!M15,WATER!R15) -> 972332 | H14: =IF((G14-G13<0), "0",G14-G13) -> 376 | I14: 13.6 | J14: 164
A15: =A14+1 -> 44388 | C15: =SUM('GENSET #1'!C20+'GENSET #2'!C20+'GENSET #3'!C20+'GENSET #4'!C20+'GENSET #5'!C20) -> 91580447 | D15: =IF((C15-C14<0), "0",C15-C14) -> 23328 | E15: ='Gas-2'!G16 -> 225 | F15: =IF((E15-E14<0), "0",E15-E14) -> 0 | G15: =SUM(WATER!C16,WATER!H16,WATER!M16,WATER!R16) -> 972618 | H15: =IF((G15-G14<0), "0",G15-G14) -> 286 | I15: 11.7 | J15: 127
A16: =A15+1 -> 44389 | C16: =SUM('GENSET #1'!C21+'GENSET #2'!C21+'GENSET #3'!C21+'GENSET #4'!C21+'GENSET #5'!C21) -> 91605951 | D16: =IF((C16-C15<0), "0",C16-C15) -> 25504 | E16: ='Gas-2'!G17 -> 225 | F16: =IF((E16-E15<0), "0",E16-E15) -> 0 | G16: =SUM(WATER!C17,WATER!H17,WATER!M17,WATER!R17) -> 972918 | H16: =IF((G16-G15<0), "0",G16-G15) -> 300 | I16: 11.7 | J16: 149
A17: =A16+1 -> 44390 | C17: =SUM('GENSET #1'!C22+'GENSET #2'!C22+'GENSET #3'!C22+'GENSET #4'!C22+'GENSET #5'!C22) -> 91630591 | D17: =IF((C17-C16<0), "0",C17-C16) -> 24640 | E17: ='Gas-2'!G18 -> 225 | F17: =IF((E17-E16<0), "0",E17-E16) -> 0 | G17: =SUM(WATER!C18,WATER!H18,WATER!M18,WATER!R18) -> 973237 | H17: =IF((G17-G16<0), "0",G17-G16) -> 319 | I17: 12.6 | J17: 159
... A20: =A19+1 -> 44393 | C20: =SUM('GENSET #1'!C25+'GENSET #2'!C25+'GENSET #3'!C25+'GENSET #4'!C25+'GENSET #5'!C25) -> 91706008 | D20: =IF((C20-C19<0), "0",C20-C19) -> 25655 | E20: ='Gas-2'!G21 -> 180 | F20: =IF((E20-E19<0), "0",E20-E19) -> 0 | G20: =SUM(WATER!C21,WATER!H21,WATER!M21,WATER!R21) -> 974230 | H20: =IF((G20-G19<0), "0",G20-G19) -> 337 | I20: 21 | J20: 204
A21: =A20+1 -> 44394 | C21: =SUM('GENSET #1'!C26+'GENSET #2'!C26+'GENSET #3'!C26+'GENSET #4'!C26+'GENSET #5'!C26) -> 91731072 | D21: =IF((C21-C20<0), "0",C21-C20) -> 25064 | E21: ='Gas-2'!G22 -> 225 | F21: =IF((E21-E20<0), "0",E21-E20) -> 45 | G21: =SUM(WATER!C22,WATER!H22,WATER!M22,WATER!R22) -> 974566 | H21: =IF((G21-G20<0), "0",G21-G20) -> 336
A22: =A21+1 -> 44395 | C22: =SUM('GENSET #1'!C27+'GENSET #2'!C27+'GENSET #3'!C27+'GENSET #4'!C27+'GENSET #5'!C27) -> 0 | D22: =IF((C22-C21<0), "0",C22-C21) -> 0 | E22: ='Gas-2'!G23 -> 0 | F22: =IF((E22-E21<0), "0",E22-E21) -> 0 | G22: =SUM(WATER!C23,WATER!H23,WATER!M23,WATER!R23) -> 974876 | H22: =IF((G22-G21<0), "0",G22-G21) -> 310
A23: =A22+1 -> 44396 | C23: =SUM('GENSET #1'!C28+'GENSET #2'!C28+'GENSET #3'!C28+'GENSET #4'!C28+'GENSET #5'!C28) -> 0 | D23: =IF((C23-C22<0), "0",C23-C22) -> 0 | E23: ='Gas-2'!G24 -> 0 | F23: =IF((E23-E22<0), "0",E23-E22) -> 0 | G23: =SUM(WATER!C24,WATER!H24,WATER!M24,WATER!R24) -> 0 | H23: =IF((G23-G22<0), "0",G23-G22) -> 0
A24: =A23+1 -> 44397 | C24: =SUM('GENSET #1'!C29+'GENSET #2'!C29+'GENSET #3'!C29+'GENSET #4'!C29+'GENSET #5'!C29) -> 0 | D24: =IF((C24-C23<0), "0",C24-C23) -> 0 | E24: ='Gas-2'!G25 -> 0 | F24: =IF((E24-E23<0), "0",E24-E23) -> 0 | G24: =SUM(WATER!C25,WATER!H25,WATER!M25,WATER!R25) -> 0 | H24: =IF((G24-G23<0), "0",G24-G23) -> 0
A25: =A24+1 -> 44398 | C25: =SUM('GENSET #1'!C30+'GENSET #2'!C30+'GENSET #3'!C30+'GENSET #4'!C30+'GENSET #5'!C30) -> 0 | D25: =IF((C25-C24<0), "0",C25-C24) -> 0 | E25: ='Gas-2'!G26 -> 0 | F25: =IF((E25-E24<0), "0",E25-E24) -> 0 | G25: =SUM(WATER!C26,WATER!H26,WATER!M26,WATER!R26) -> 0 | H25: =IF((G25-G24<0), "0",G25-G24) -> 0
A26: =A25+1 -> 44399 | C26: =SUM('GENSET #1'!C31+'GENSET #2'!C31+'GENSET #3'!C31+'GENSET #4'!C31+'GENSET #5'!C31) -> 0 | D26: =IF((C26-C25<0), "0",C26-C25) -> 0 | E26: ='Gas-2'!G27 -> 0 | F26: =IF((E26-E25<0), "0",E26-E25) -> 0 | G26: =SUM(WATER!C27,WATER!H27,WATER!M27,WATER!R27) -> 0 | H26: =IF((G26-G25<0), "0",G26-G25) -> 0
A27: =A26+1 -> 44400 | C27: =SUM('GENSET #1'!C32+'GENSET #2'!C32+'GENSET #3'!C32+'GENSET #4'!C32+'GENSET #5'!C32) -> 0 | D27: =IF((C27-C26<0), "0",C27-C26) -> 0 | E27: ='Gas-2'!G28 -> 0 | F27: =IF((E27-E26<0), "0",E27-E26) -> 0 | G27: =SUM(WATER!C28,WATER!H28,WATER!M28,WATER!R28) -> 0 | H27: =IF((G27-G26<0), "0",G27-G26) -> 0
A28: =A27+1 -> 44401 | C28: =SUM('GENSET #1'!C33+'GENSET #2'!C33+'GENSET #3'!C33+'GENSET #4'!C33+'GENSET #5'!C33) -> 0 | D28: =IF((C28-C27<0), "0",C28-C27) -> 0 | E28: ='Gas-2'!G29 -> 0 | F28: =IF((E28-E27<0), "0",E28-E27) -> 0 | G28: =SUM(WATER!C29,WATER!H29,WATER!M29,WATER!R29) -> 0 | H28: =IF((G28-G27<0), "0",G28-G27) -> 0
A29: =A28+1 -> 44402 | C29: =SUM('GENSET #1'!C34+'GENSET #2'!C34+'GENSET #3'!C34+'GENSET #4'!C34+'GENSET #5'!C34) -> 0 | D29: =IF((C29-C28<0), "0",C29-C28) -> 0 | E29: ='Gas-2'!G30 -> 0 | F29: =IF((E29-E28<0), "0",E29-E28) -> 0 | G29: =SUM(WATER!C30,WATER!H30,WATER!M30,WATER!R30) -> 0 | H29: =IF((G29-G28<0), "0",G29-G28) -> 0
A30: =A29+1 -> 44403 | C30: =SUM('GENSET #1'!C35+'GENSET #2'!C35+'GENSET #3'!C35+'GENSET #4'!C35+'GENSET #5'!C35) -> 0 | D30: =IF((C30-C29<0), "0",C30-C29) -> 0 | E30: ='Gas-2'!G31 -> 0 | F30: =IF((E30-E29<0), "0",E30-E29) -> 0 | G30: =SUM(WATER!C31,WATER!H31,WATER!M31,WATER!R31) -> 0 | H30: =IF((G30-G29<0), "0",G30-G29) -> 0
A31: =A30+1 -> 44404 | C31: =SUM('GENSET #1'!C36+'GENSET #2'!C36+'GENSET #3'!C36+'GENSET #4'!C36+'GENSET #5'!C36) -> 0 | D31: =IF((C31-C30<0), "0",C31-C30) -> 0 | E31: ='Gas-2'!G32 -> 0 | F31: =IF((E31-E30<0), "0",E31-E30) -> 0 | G31: =SUM(WATER!C32,WATER!H32,WATER!M32,WATER!R32) -> 0 | H31: =IF((G31-G30<0), "0",G31-G30) -> 0
A32: =A31+1 -> 44405 | C32: =SUM('GENSET #1'!C37+'GENSET #2'!C37+'GENSET #3'!C37+'GENSET #4'!C37+'GENSET #5'!C37) -> 0 | D32: =IF((C32-C31<0), "0",C32-C31) -> 0 | E32: ='Gas-2'!G33 -> 0 | F32: =IF((E32-E31<0), "0",E32-E31) -> 0 | G32: =SUM(WATER!C33,WATER!H33,WATER!M33,WATER!R33) -> 0 | H32: =IF((G32-G31<0), "0",G32-G31) -> 0
... A35: =A34+1 -> 44408 | C35: =SUM('GENSET #1'!C40+'GENSET #2'!C40+'GENSET #3'!C40+'GENSET #4'!C40+'GENSET #5'!C40) -> 0 | D35: =IF((C35-C34<0), "0",C35-C34) -> 0 | E35: ='Gas-2'!G36 -> 0 | F35: =IF((E35-E34<0), "0",E35-E34) -> 0 | G35: =SUM(WATER!C36,WATER!H36,WATER!M36,WATER!R36) -> 0 | H35: =IF((G35-G34<0), "0",G35-G34) -> 0

Sheet Finance Only
A1: Four Seasons Landaa Giraavaru
A3: Property | B3: MLG
A4: Month | B4: July
A5: Year | B5: 2021
A7: DAY | B7: Electricity Consumption ( kwh) | C7: Diesel Consumption (Liters) | D7: Solar Power Consumption(kwh) | E7: Gas Consumption (kg) | F7: Water Consumption ( m3) | G7: Occupancy | H7: Weather | I7: Electricity Variance (Today vs Yesterday)
A8: 1 | B8: =SUM('GENSET #1:GENSET #5'!D10) -> 25932 | C8: ='Diesel consumption'!D5 -> 7200 | D8: ='SOLAR METER READING'!D9 -> 2740 | E8: ='Gas-2'!G6 -> 225 | F8: =WATER!V6 -> 275 | G8: =WATER!W6 -> 18.4 | H8: ='SOLAR METER READING'!E9 -> 0
A9: 2 | B9: =SUM('GENSET #1:GENSET #5'!D11) -> 26846 | C9: ='Diesel consumption'!D6 -> 7510 | D9: ='SOLAR METER READING'!D10 -> 3146 | E9: ='Gas-2'!G7 -> 225 | F9: =WATER!V7 -> 316 | G9: =WATER!W7 -> 12.7 | H9: ='SOLAR METER READING'!E10 -> 0 | I9: =B9-B8 -> 914
A10: 3 | B10: =SUM('GENSET #1:GENSET #5'!D12) -> 27330 | C10: ='Diesel consumption'!D7 -> 7520 | D10: ='SOLAR METER READING'!D11 -> 2802 | E10: ='Gas-2'!G8 -> 180 | F10: =WATER!V8 -> 330 | G10: =WATER!W8 -> 12.6 | H10: ='SOLAR METER READING'!E11 -> 0 | I10: =B10-B9 -> 484
A11: 4 | B11: =SUM('GENSET #1:GENSET #5'!D13) -> 27327 | C11: ='Diesel consumption'!D8 -> 7520 | D11: ='SOLAR METER READING'!D12 -> 2142 | E11: ='Gas-2'!G9 -> 270 | F11: =WATER!V9 -> 326 | G11: =WATER!W9 -> 15.5 | H11: ='SOLAR METER READING'!E12 -> 0 | I11: =B11-B10 -> -3
A12: 5 | B12: =SUM('GENSET #1:GENSET #5'!D14) -> 26205 | C12: ='Diesel consumption'!D9 -> 6980 | D12: ='SOLAR METER READING'!D13 -> 2063 | E12: ='Gas-2'!G10 -> 270 | F12: =WATER!V10 -> 306 | G12: =WATER!W10 -> 13.6 | H12: ='SOLAR METER READING'!E13 -> 0 | I12: =B12-B11 -> -1122
A13: 6 | B13: =SUM('GENSET #1:GENSET #5'!D15) -> 27166 | C13: ='Diesel consumption'!D10 -> 7630 | D13: ='SOLAR METER READING'!D14 -> 3029 | E13: ='Gas-2'!G11 -> 225 | F13: =WATER!V11 -> 375 | G13: =WATER!W11 -> 15.5 | H13: ='SOLAR METER READING'!E14 -> 0 | I13: =B13-B12 -> 961
A14: 7 | B14: =SUM('GENSET #1:GENSET #5'!D16) -> 24691 | C14: ='Diesel consumption'!D11 -> 6480 | D14: ='SOLAR METER READING'!D15 -> 2160 | E14: ='Gas-2'!G12 -> 225 | F14: =WATER!V12 -> 380 | G14: =WATER!W12 -> 17.5 | H14: ='SOLAR METER READING'!E15 -> 0 | I14: =B14-B13 -> -2475
A15: 8 | B15: =SUM('GENSET #1:GENSET #5'!D17) -> 25450 | C15: ='Diesel consumption'!D12 -> 7140 | D15: ='SOLAR METER READING'!D16 -> 2878 | E15: ='Gas-2'!G13 -> 225 | F15: =WATER!V13 -> 283 | G15: =WATER!W13 -> 16.5 | H15: ='SOLAR METER READING'!E16 -> 0 | I15: =B15-B14 -> 759
A16: 9 | B16: =SUM('GENSET #1:GENSET #5'!D18) -> 22674 | C16: ='Diesel consumption'!D13 -> 6290 | D16: ='SOLAR METER READING'!D17 -> 1357 | E16: ='Gas-2'!G14 -> 225 | F16: =WATER!V14 -> 318 | G16: =WATER!W14 -> 16.5 | H16: ='SOLAR METER READING'!E17 -> 0 | I16: =B16-B15 -> -2776
A17: 10 | B17: =SUM('GENSET #1:GENSET #5'!D19) -> 23356 | C17: ='Diesel consumption'!D14 -> 6340 | D17: ='SOLAR METER READING'!D18 -> 1886 | E17: ='Gas-2'!G15 -> 270 | F17: =WATER!V15 -> 376 | G17: =WATER!W15 -> 13.6 | H17: ='SOLAR METER READING'!E18 -> 0 | I17: =B17-B16 -> 682
A18: 11 | B18: =SUM('GENSET #1:GENSET #5'!D20) -> 23328 | C18: ='Diesel consumption'!D15 -> 6440 | D18: ='SOLAR METER READING'!D19 -> 3046 | E18: ='Gas-2'!G16 -> 225 | F18: =WATER!V16 -> 286 | G18: =WATER!W16 -> 11.7 | H18: ='SOLAR METER READING'!E19 -> 0 | I18: =B18-B17 -> -28
A19: 12 | B19: =SUM('GENSET #1:GENSET #5'!D21) -> 25504 | C19: ='Diesel consumption'!D16 -> 6930 | D19: ='SOLAR METER READING'!D20 -> 3076 | E19: ='Gas-2'!G17 -> 225 | F19: =WATER!V17 -> 300 | G19: =WATER!W17 -> 11.7 | H19: ='SOLAR METER READING'!E20 -> 0 | I19: =B19-B18 -> 2176
A20: 13 | B20: =SUM('GENSET #1:GENSET #5'!D22) -> 24640 | C20: ='Diesel consumption'!D17 -> 7030 | D20: ='SOLAR METER READING'!D21 -> 2917 | E20: ='Gas-2'!G18 -> 225 | F20: =WATER!V18 -> 319 | G20: =WATER!W18 -> 12.6 | H20: ='SOLAR METER READING'!E21 -> 0 | I20: =B20-B19 -> -864
... A37: 30 | B37: =SUM('GENSET #1:GENSET #5'!D39) -> 0 | C37: ='Diesel consumption'!D34 -> 0 | D37: ='SOLAR METER READING'!D38 -> 0 | E37: ='Gas-2'!G35 -> 0 | F37: =WATER!V35 -> 0 | G37: =WATER!W35 -> 0 | H37: ='SOLAR METER READING'!E38 -> 0 | I37: =B37-B36 -> 0
A38: 31 | H38: ='SOLAR METER READING'!E39 -> 0 | I38: =B38-B37 -> 0
A39: Total | B39: =SUM(B8:B38) -> -91300142 | C39: =SUM(C8:C38) -> -44329360 | D39: =SUM(D8:D38) -> -2764195 | E39: =SUM(E8:E38) -> 3915 | F39: =SUM(F8:F38) -> -969047 | G39: =SUM(G8:G37)/30 -> 7.9833333
A40: Avg | B40: =B39/30 -> -3043338.1 | C40: =C39/30 -> -1477645.3 | D40: =D39/30 -> -92139.833 | E40: =E39/30 -> 130.5 | F40: =F39/31 -> -31259.581

Sheet GENSET #1
C1: 1000 KVA
C3: NO#1
A6: 44378
B8: GENSET NO 1
A9: DAY | B9: YESTARDAY | C9: TODAY | D9: Final Electricity Consumption( KWh)
A10: 1 | B10: 17388477 | C10: 17398518 | D10: =C10-B10 -> 10041
A11: 2 | B11: =C10 -> 17398518 | C11: 17406657 | D11: =C11-B11 -> 8139
A12: 3 | B12: =C11 -> 17406657 | C12: 17418372 | D12: =C12-B12 -> 11715
A13: 4 | B13: =C12 -> 17418372 | C13: 17426569 | D13: =C13-B13 -> 8197
A14: 5 | B14: =C13 -> 17426569 | C14: 17429586 | D14: =C14-B14 -> 3017
A15: 6 | B15: =C14 -> 17429586 | C15: 17441352 | D15: =C15-B15 -> 11766
A16: 7 | B16: =C15 -> 17441352 | C16: 17442048 | D16: =C16-B16 -> 696
A17: 8 | B17: =C16 -> 17442048 | C17: 17452919 | D17: =C17-B17 -> 10871
A18: 9 | B18: =C17 -> 17452919 | C18: 17461253 | D18: =C18-B18 -> 8334
A19: 10 | B19: =C18 -> 17461253 | C19: 17469221 | D19: =C19-B19 -> 7968
A20: 11 | B20: =C19 -> 17469221 | C20: 17478279 | D20: =C20-B20 -> 9058
A21: 12 | B21: =C20 -> 17478279 | C21: 17482929 | D21: =C21-B21 -> 4650
A22: 13 | B22: =C21 -> 17482929 | C22: 17494214 | D22: =C22-B22 -> 11285
... A26: 17 | B26: =C25 -> 17512912 | C26: 17524368 | D26: =C26-B26 -> 11456
A27: 18 | B27: =C26 -> 17524368 | D27: =C27-B27 -> -17524368
A28: 19 | B28: =C27 -> 0 | D28: =C28-B28 -> 0
A29: 20 | B29: =C28 -> 0 | D29: =C29-B29 -> 0
A30: 21 | B30: =C29 -> 0 | D30: =C30-B30 -> 0
A31: 22 | B31: =C30 -> 0 | D31: =C31-B31 -> 0
A32: 23 | B32: =C31 -> 0 | D32: =C32-B32 -> 0
A33: 24 | B33: =C32 -> 0 | D33: =C33-B33 -> 0
A34: 25 | B34: =C33 -> 0 | D34: =C34-B34 -> 0
A35: 26 | B35: =C34 -> 0 | D35: =C35-B35 -> 0
A36: 27 | B36: =C35 -> 0 | D36: =C36-B36 -> 0
A37: 28 | B37: =C36 -> 0 | D37: =C37-B37 -> 0
A38: 29 | B38: =C37 -> 0 | D38: =C38-B38 -> 0
A39: 30 | B39: =C38 -> 0 | D39: =C39-B39 -> 0 | G39: NEW ENGINE PURCHASED FROM UK
A40: 31 | B40: =C39 -> 0 | D40: =C40-B40 -> 0
A41: Total | D41: =SUM(D10:D40) -> -17388477 | G41: INSTALLED: NOV 30 2013

Sheet GENSET #2
C1: 1600 KVA
C3: NO#2
A6: 44378
B8: GENSET NO 2
A9: DAY | B9: YESTARDAY | C9: TODAY | D9: Final Electricity Consumption( KW h)
A10: 1 | B10: 30372736 | C10: 30372736 | D10: =C10-B10 -> 0
A11: 2 | B11: =C10 -> 30372736 | C11: 30372736 | D11: =C11-B11 -> 0
A12: 3 | B12: =C11 -> 30372736 | C12: 30373162 | D12: =C12-B12 -> 426
A13: 4 | B13: =C12 -> 30373162 | C13: 30373162 | D13: =C13-B13 -> 0
A14: 5 | B14: =C13 -> 30373162 | C14: 30373162 | D14: =C14-B14 -> 0
A15: 6 | B15: =C14 -> 30373162 | C15: 30373162 | D15: =C15-B15 -> 0
A16: 7 | B16: =C15 -> 30373162 | C16: 30373162 | D16: =C16-B16 -> 0
A17: 8 | B17: =C16 -> 30373162 | C17: 30373162 | D17: =C17-B17 -> 0
A18: 9 | B18: =C17 -> 30373162 | C18: 30373162 | D18: =C18-B18 -> 0
A19: 10 | B19: =C18 -> 30373162 | C19: 30373162 | D19: =C19-B19 -> 0
A20: 11 | B20: =C19 -> 30373162 | C20: 30373162 | D20: =C20-B20 -> 0
A21: 12 | B21: =C20 -> 30373162 | C21: 30373162 | D21: =C21-B21 -> 0
A22: 13 | B22: =C21 -> 30373162 | C22: 30373162 | D22: =C22-B22 -> 0
... A26: 17 | B26: =C25 -> 30373162 | C26: 30373162 | D26: =C26-B26 -> 0
A27: 18 | B27: =C26 -> 30373162 | D27: =C27-B27 -> -30373162
A28: 19 | B28: =C27 -> 0 | D28: =C28-B28 -> 0
A29: 20 | B29: =C28 -> 0 | D29: =C29-B29 -> 0
A30: 21 | B30: =C29 -> 0 | D30: =C30-B30 -> 0
A31: 22 | B31: =C30 -> 0 | D31: =C31-B31 -> 0
A32: 23 | B32: =C31 -> 0 | D32: =C32-B32 -> 0
A33: 24 | B33: =C32 -> 0 | D33: =C33-B33 -> 0
A34: 25 | B34: =C33 -> 0 | D34: =C34-B34 -> 0
A35: 26 | B35: =C34 -> 0 | D35: =C35-B35 -> 0
A36: 27 | B36: =C35 -> 0 | D36: =C36-B36 -> 0
A37: 28 | B37: =C36 -> 0 | D37: =C37-B37 -> 0
A38: 29 | B38: =C37 -> 0 | D38: =C38-B38 -> 0
... A40: 31 | B40: =C39 -> 0 | D40: =C40-B40 -> 0
A41: Total | B41: =#REF! -> #REF! | D41: =SUM(D10:D40) -> -30372736

Sheet GENSET #3
C1: 900 KVA
C3: NO#3
A6: 44378
B8: GENSET NO 3
A9: DAY | B9: YESTARDAY | C9: TODAY | D9: Final Electricity Consumption( KW h)
A10: 1 | B10: 13358393 | C10: 13364464 | D10: =C10-B10 -> 6071
A11: 2 | B11: =C10 -> 13364464 | C11: 13374739 | D11: =C11-B11 -> 10275
A12: 3 | B12: =C11 -> 13374739 | C12: 13378296 | D12: =C12-B12 -> 3557
A13: 4 | B13: =C12 -> 13378296 | C13: 13384311 | D13: =C13-B13 -> 6015
A14: 5 | B14: =C13 -> 13384311 | C14: 13392118 | D14: =C14-B14 -> 7807
A15: 6 | B15: =C14 -> 13392118 | C15: 13399568 | D15: =C15-B15 -> 7450
A16: 7 | B16: =C15 -> 13399568 | C16: 13409417 | D16: =C16-B16 -> 9849
A17: 8 | B17: =C16 -> 13409417 | C17: 13412948 | D17: =C17-B17 -> 3531
A18: 9 | B18: =C17 -> 13412948 | C18: 13423108 | D18: =C18-B18 -> 10160
A19: 10 | B19: =C18 -> 13423108 | C19: 13426986 | D19: =C19-B19 -> 3878
A20: 11 | B20: =C19 -> 13426986 | C20: 13435160 | D20: =C20-B20 -> 8174
A21: 12 | B21: =C20 -> 13435160 | C21: 13441544 | D21: =C21-B21 -> 6384
A22: 13 | B22: =C21 -> 13441544 | C22: 13449085 | D22: =C22-B22 -> 7541
... A26: 17 | B26: =C25 -> 13471256 | C26: 13479184 | D26: =C26-B26 -> 7928
A27: 18 | B27: =C26 -> 13479184 | D27: =C27-B27 -> -13479184
A28: 19 | B28: =C27 -> 0 | D28: =C28-B28 -> 0
A29: 20 | B29: =C28 -> 0 | D29: =C29-B29 -> 0
A30: 21 | B30: =C29 -> 0 | D30: =C30-B30 -> 0
A31: 22 | B31: =C30 -> 0 | D31: =C31-B31 -> 0
A32: 23 | B32: =C31 -> 0 | D32: =C32-B32 -> 0
A33: 24 | B33: =C32 -> 0 | D33: =C33-B33 -> 0
A34: 25 | B34: =C33 -> 0 | D34: =C34-B34 -> 0
A35: 26 | B35: =C34 -> 0 | D35: =C35-B35 -> 0
A36: 27 | B36: =C35 -> 0 | D36: =C36-B36 -> 0
A37: 28 | B37: =C36 -> 0 | D37: =C37-B37 -> 0
A38: 29 | B38: =C37 -> 0 | D38: =C38-B38 -> 0
... A40: 31 | B40: =C39 -> 0 | D40: =C40-B40 -> 0
A41: Total | B41: =#REF! -> #REF! | D41: =SUM(D10:D40) -> -13358393

Sheet GENSET #4
C1: 500 KVA
C3: NO#4
A6: 44378
B8: GENSET NO 4
A9: DAY | B9: YESTARDAY | C9: TODAY | D9: Final Electricity Consumption( KW h)
A10: 1 | B10: 11748091 | C10: 11749888 | D10: =C10-B10 -> 1797
A11: 2 | B11: =C10 -> 11749888 | C11: 11752891 | D11: =C11-B11 -> 3003
A12: 3 | B12: =C11 -> 11752891 | C12: 11756821 | D12: =C12-B12 -> 3930
A13: 4 | B13: =C12 -> 11756821 | C13: 11761512 | D13: =C13-B13 -> 4691
A14: 5 | B14: =C13 -> 11761512 | C14: 11765267 | D14: =C14-B14 -> 3755
A15: 6 | B15: =C14 -> 11765267 | C15: 11769629 | D15: =C15-B15 -> 4362
A16: 7 | B16: =C15 -> 11769629 | C16: 11772194 | D16: =C16-B16 -> 2565
A17: 8 | B17: =C16 -> 11772194 | C17: 11774640 | D17: =C17-B17 -> 2446
A18: 9 | B18: =C17 -> 11774640 | C18: 11775784 | D18: =C18-B18 -> 1144
A19: 10 | B19: =C18 -> 11775784 | C19: 11778703 | D19: =C19-B19 -> 2919
A20: 11 | B20: =C19 -> 11778703 | C20: 11782254 | D20: =C20-B20 -> 3551
A21: 12 | B21: =C20 -> 11782254 | C21: 11785655 | D21: =C21-B21 -> 3401
A22: 13 | B22: =C21 -> 11785655 | C22: 11787982 | D22: =C22-B22 -> 2327
... A26: 17 | B26: =C25 -> 11797070 | C26: 11799998 | D26: =C26-B26 -> 2928
A27: 18 | B27: =C26 -> 11799998 | D27: =C27-B27 -> -11799998
A28: 19 | B28: =C27 -> 0 | D28: =C28-B28 -> 0
A29: 20 | B29: =C28 -> 0 | D29: =C29-B29 -> 0
A30: 21 | B30: =C29 -> 0 | D30: =C30-B30 -> 0
A31: 22 | B31: =C30 -> 0 | D31: =C31-B31 -> 0
A32: 23 | B32: =C31 -> 0 | D32: =C32-B32 -> 0
A33: 24 | B33: =C32 -> 0 | D33: =C33-B33 -> 0
A34: 25 | B34: =C33 -> 0 | D34: =C34-B34 -> 0
A35: 26 | B35: =C34 -> 0 | D35: =C35-B35 -> 0
A36: 27 | B36: =C35 -> 0 | D36: =C36-B36 -> 0
A37: 28 | B37: =C36 -> 0 | D37: =C37-B37 -> 0
A38: 29 | B38: =C37 -> 0 | D38: =C38-B38 -> 0
... A40: 31 | B40: =C39 -> 0 | D40: =C40-B40 -> 0
A41: Total | B41: =#REF! -> #REF! | D41: =SUM(D10:D40) -> -11748091

Sheet GENSET #5
C1: 1000 KVA
C3: NO#5
A6: 44378
B8: GENSET NO 5
A9: DAY | B9: YESTARDAY | C9: TODAY | D9: Final Electricity Consumption( KWh)
A10: 1 | B10: 18432445 | C10: 18440468 | D10: =C10-B10 -> 8023
A11: 2 | B11: =C10 -> 18440468 | C11: 18445897 | D11: =C11-B11 -> 5429
A12: 3 | B12: =C11 -> 18445897 | C12: 18453599 | D12: =C12-B12 -> 7702
A13: 4 | B13: =C12 -> 18453599 | C13: 18462023 | D13: =C13-B13 -> 8424
A14: 5 | B14: =C13 -> 18462023 | C14: 18473649 | D14: =C14-B14 -> 11626
A15: 6 | B15: =C14 -> 18473649 | C15: 18477237 | D15: =C15-B15 -> 3588
A16: 7 | B16: =C15 -> 18477237 | C16: 18488818 | D16: =C16-B16 -> 11581
A17: 8 | B17: =C16 -> 18488818 | C17: 18497420 | D17: =C17-B17 -> 8602
A18: 9 | B18: =C17 -> 18497420 | C18: 18500456 | D18: =C18-B18 -> 3036
A19: 10 | B19: =C18 -> 18500456 | C19: 18509047 | D19: =C19-B19 -> 8591
A20: 11 | B20: =C19 -> 18509047 | C20: 18511592 | D20: =C20-B20 -> 2545
A21: 12 | B21: =C20 -> 18511592 | C21: 18522661 | D21: =C21-B21 -> 11069
A22: 13 | B22: =C21 -> 18522661 | C22: 18526148 | D22: =C22-B22 -> 3487
... A26: 17 | B26: =C25 -> 18551608 | C26: 18554360 | D26: =C26-B26 -> 2752
A27: 18 | B27: =C26 -> 18554360 | D27: =C27-B27 -> -18554360
A28: 19 | B28: =C27 -> 0 | D28: =C28-B28 -> 0
A29: 20 | B29: =C28 -> 0 | D29: =C29-B29 -> 0
A30: 21 | B30: =C29 -> 0 | D30: =C30-B30 -> 0
A31: 22 | B31: =C30 -> 0 | D31: =C31-B31 -> 0
A32: 23 | B32: =C31 -> 0 | D32: =C32-B32 -> 0
A33: 24 | B33: =C32 -> 0 | D33: =C33-B33 -> 0
A34: 25 | B34: =C33 -> 0 | D34: =C34-B34 -> 0
A35: 26 | B35: =C34 -> 0 | D35: =C35-B35 -> 0
A36: 27 | B36: =C35 -> 0 | D36: =C36-B36 -> 0
A37: 28 | B37: =C36 -> 0 | D37: =C37-B37 -> 0
A38: 29 | B38: =C37 -> 0 | D38: =C38-B38 -> 0
... A40: 31 | B40: =C39 -> 0 | D40: =C40-B40 -> 0
A41: Total | D41: =SUM(D10:D40) -> -18432445

Sheet Diesel consumption
A1: Diesel Consumption - Powerhouse | F1: Diesel Tank Jetty Meter
A2: 44378
D3: Liters | F3: Boat meter Reading
A4: Date | B4: Yesterday | C4: Today | D4: ConsumptionIn 24 hrs | F4: Yesterday | G4: Today | H4: Consumption (Liters) | J4: In Barrels | L4: Carbon Emmision
A5: 1 | B5: 44329360 | C5: 44336560 | D5: =C5-B5 -> 7200 | F5: 689210 | G5: 693940 | H5: =G5-F5 -> 4730 | J5: =D5/200 -> 36 | L5: =2.68*D5 -> 19296 | M5: =L5/1000 -> 19.296
A6: 2 | B6: =C5 -> 44336560 | C6: 44344070 | D6: =C6-B6 -> 7510 | F6: =G5 -> 693940 | G6: 694690 | H6: =G6-F6 -> 750 | J6: =D6/200 -> 37.55 | L6: =2.68*D6 -> 20126.8 | M6: =L6/1000 -> 20.1268
A7: 3 | B7: =C6 -> 44344070 | C7: 44351590 | D7: =C7-B7 -> 7520 | F7: =G6 -> 694690 | G7: 694690 | H7: =G7-F7 -> 0 | J7: =D7/200 -> 37.6 | L7: =2.68*D7 -> 20153.6 | M7: =L7/1000 -> 20.1536
A8: 4 | B8: =C7 -> 44351590 | C8: 44359110 | D8: =C8-B8 -> 7520 | F8: =G7 -> 694690 | G8: 694810 | H8: =G8-F8 -> 120 | J8: =D8/200 -> 37.6 | L8: =2.68*D8 -> 20153.6 | M8: =L8/1000 -> 20.1536
A9: 5 | B9: =C8 -> 44359110 | C9: 44366090 | D9: =C9-B9 -> 6980 | F9: =G8 -> 694810 | G9: 696810 | H9: =G9-F9 -> 2000 | J9: =D9/200 -> 34.9 | L9: =2.68*D9 -> 18706.4 | M9: =L9/1000 -> 18.7064
A10: 6 | B10: =C9 -> 44366090 | C10: 44373720 | D10: =C10-B10 -> 7630 | F10: =G9 -> 696810 | G10: 697470 | H10: =G10-F10 -> 660 | J10: =D10/200 -> 38.15 | L10: =2.68*D10 -> 20448.4 | M10: =L10/1000 -> 20.4484
A11: 7 | B11: =C10 -> 44373720 | C11: 44380200 | D11: =C11-B11 -> 6480 | F11: =G10 -> 697470 | G11: 697590 | H11: =G11-F11 -> 120 | J11: =D11/200 -> 32.4 | L11: =2.68*D11 -> 17366.4 | M11: =L11/1000 -> 17.3664
A12: 8 | B12: =C11 -> 44380200 | C12: 44387340 | D12: =C12-B12 -> 7140 | F12: =G11 -> 697590 | G12: 699490 | H12: =G12-F12 -> 1900 | J12: =D12/200 -> 35.7 | L12: =2.68*D12 -> 19135.2 | M12: =L12/1000 -> 19.1352
A13: 9 | B13: =C12 -> 44387340 | C13: 44393630 | D13: =C13-B13 -> 6290 | F13: =G12 -> 699490 | G13: 699890 | H13: =G13-F13 -> 400 | J13: =D13/200 -> 31.45 | L13: =2.68*D13 -> 16857.2 | M13: =L13/1000 -> 16.8572
A14: 10 | B14: =C13 -> 44393630 | C14: 44399970 | D14: =C14-B14 -> 6340 | F14: =G13 -> 699890 | G14: 700010 | H14: =G14-F14 -> 120 | J14: =D14/200 -> 31.7 | L14: =2.68*D14 -> 16991.2 | M14: =L14/1000 -> 16.9912
A15: 11 | B15: =C14 -> 44399970 | C15: 44406410 | D15: =C15-B15 -> 6440 | F15: =G14 -> 700010 | G15: 700010 | H15: =G15-F15 -> 0 | J15: =D15/200 -> 32.2 | L15: =2.68*D15 -> 17259.2 | M15: =L15/1000 -> 17.2592
A16: 12 | B16: =C15 -> 44406410 | C16: 44413340 | D16: =C16-B16 -> 6930 | F16: =G15 -> 700010 | G16: 701990 | H16: =G16-F16 -> 1980 | J16: =D16/200 -> 34.65 | L16: =2.68*D16 -> 18572.4 | M16: =L16/1000 -> 18.5724
A17: 13 | B17: =C16 -> 44413340 | C17: 44420370 | D17: =C17-B17 -> 7030 | F17: =G16 -> 701990 | G17: 702930 | H17: =G17-F17 -> 940 | J17: =D17/200 -> 35.15 | L17: =2.68*D17 -> 18840.4 | M17: =L17/1000 -> 18.8404
... A21: 17 | B21: =C20 -> 44440750 | C21: 44447810 | D21: =C21-B21 -> 7060 | F21: =G20 -> 708760 | G21: 708760 | H21: =G21-F21 -> 0 | J21: =D21/200 -> 35.3 | L21: =2.68*D21 -> 18920.8 | M21: =L21/1000 -> 18.9208
A22: 18 | B22: =C21 -> 44447810 | D22: =C22-B22 -> -44447810 | F22: =G21 -> 708760 | H22: =G22-F22 -> -708760 | J22: =D22/200 -> -222239.05 | L22: =2.68*D22 -> -1.1912013e+08 | M22: =L22/1000 -> -119120.13
A23: 19 | B23: =C22 -> 0 | D23: =C23-B23 -> 0 | F23: =G22 -> 0 | H23: =G23-F23 -> 0 | J23: =D23/200 -> 0 | L23: =2.68*D23 -> 0 | M23: =L23/1000 -> 0
A24: 20 | B24: =C23 -> 0 | D24: =C24-B24 -> 0 | F24: =G23 -> 0 | H24: =G24-F24 -> 0 | J24: =D24/200 -> 0 | L24: =2.68*D24 -> 0 | M24: =L24/1000 -> 0
A25: 21 | B25: =C24 -> 0 | D25: =C25-B25 -> 0 | F25: =G24 -> 0 | H25: =G25-F25 -> 0 | J25: =D25/200 -> 0 | L25: =2.68*D25 -> 0 | M25: =L25/1000 -> 0
A26: 22 | B26: =C25 -> 0 | D26: =C26-B26 -> 0 | F26: =G25 -> 0 | H26: =G26-F26 -> 0 | J26: =D26/200 -> 0 | L26: =2.68*D26 -> 0 | M26: =L26/1000 -> 0
A27: 23 | B27: =C26 -> 0 | D27: =C27-B27 -> 0 | F27: =G26 -> 0 | H27: =G27-F27 -> 0 | J27: =D27/200 -> 0 | L27: =2.68*D27 -> 0 | M27: =L27/1000 -> 0
A28: 24 | B28: =C27 -> 0 | D28: =C28-B28 -> 0 | F28: =G27 -> 0 | H28: =G28-F28 -> 0 | J28: =D28/200 -> 0 | L28: =2.68*D28 -> 0 | M28: =L28/1000 -> 0
A29: 25 | B29: =C28 -> 0 | D29: =C29-B29 -> 0 | F29: =G28 -> 0 | H29: =G29-F29 -> 0 | J29: =D29/200 -> 0 | L29: =2.68*D29 -> 0 | M29: =L29/1000 -> 0
A30: 26 | B30: =C29 -> 0 | D30: =C30-B30 -> 0 | F30: =G29 -> 0 | H30: =G30-F30 -> 0 | J30: =D30/200 -> 0 | L30: =2.68*D30 -> 0 | M30: =L30/1000 -> 0
A31: 27 | B31: =C30 -> 0 | D31: =C31-B31 -> 0 | F31: =G30 -> 0 | H31: =G31-F31 -> 0 | J31: =D31/200 -> 0 | L31: =2.68*D31 -> 0 | M31: =L31/1000 -> 0
A32: 28 | B32: =C31 -> 0 | D32: =C32-B32 -> 0 | F32: =G31 -> 0 | H32: =G32-F32 -> 0 | J32: =D32/200 -> 0 | L32: =2.68*D32 -> 0 | M32: =L32/1000 -> 0
A33: 29 | B33: =C32 -> 0 | D33: =C33-B33 -> 0 | F33: =G32 -> 0 | H33: =G33-F33 -> 0 | J33: =D33/200 -> 0 | L33: =2.68*D33 -> 0 | M33: =L33/1000 -> 0
A34: 30 | B34: =C33 -> 0 | D34: =C34-B34 -> 0 | F34: =G33 -> 0 | H34: =G34-F34 -> 0 | J34: =D34/200 -> 0 | L34: =2.68*D34 -> 0 | M34: =L34/1000 -> 0
A35: 31 | B35: =C34 -> 0 | D35: =C35-B35 -> 0 | F35: =G34 -> 0 | H35: =G35-F35 -> 0
D36: =SUM(D5:D35) -> -44329360 | J36: =SUM(J5:J34) -> -221646.8 | L36: =2.68*D36 -> -1.1880268e+08 | M36: =L36/1000 -> -118802.68

Sheet SOLAR METER READING
C3: solar reading
B5: 44378
B7: solar meter reading
A8: DAY | B8: YESTARDAY | C8: TODAY | D8: Final Electricity Consumption( KW h) | E8: Weather Condition
A9: 1 | B9: 2764195 | C9: 2766935 | D9: =C9-B9 -> 2740
A10: 2 | B10: =C9 -> 2766935 | C10: 2770081 | D10: =C10-B10 -> 3146
A11: 3 | B11: =C10 -> 2770081 | C11: 2772883 | D11: =C11-B11 -> 2802
A12: 4 | B12: =C11 -> 2772883 | C12: 2775025 | D12: =C12-B12 -> 2142
A13: 5 | B13: =C12 -> 2775025 | C13: 2777088 | D13: =C13-B13 -> 2063 | J13: 1 liter diesel | K13: 11.1 kwh
A14: 6 | B14: =C13 -> 2777088 | C14: 2780117 | D14: =C14-B14 -> 3029 | J14: 212.88 diesel | K14: 2363 kwh
A15: 7 | B15: =C14 -> 2780117 | C15: 2782277 | D15: =C15-B15 -> 2160
A16: 8 | B16: =C15 -> 2782277 | C16: 2785155 | D16: =C16-B16 -> 2878
A17: 9 | B17: =C16 -> 2785155 | C17: 2786512 | D17: =C17-B17 -> 1357
A18: 10 | B18: =C17 -> 2786512 | C18: 2788398 | D18: =C18-B18 -> 1886
A19: 11 | B19: =C18 -> 2788398 | C19: 2791444 | D19: =C19-B19 -> 3046
A20: 12 | B20: =C19 -> 2791444 | C20: 2794520 | D20: =C20-B20 -> 3076
A21: 13 | B21: =C20 -> 2794520 | C21: 2797437 | D21: =C21-B21 -> 2917
A22: 14 | B22: =C21 -> 2797437 | C22: 2800684 | D22: =C22-B22 -> 3247
A23: 15 | B23: =C22 -> 2800684 | C23: 2803561 | D23: =C23-B23 -> 2877
A24: 16 | B24: =C23 -> 2803561 | C24: 2806694 | D24: =C24-B24 -> 3133
A25: 17 | B25: =C24 -> 2806694 | C25: 2809644 | D25: =C25-B25 -> 2950
A26: 18 | B26: =C25 -> 2809644 | D26: =C26-B26 -> -2809644
A27: 19 | B27: =C26 -> 0 | D27: =C27-B27 -> 0
A28: 20 | B28: =C27 -> 0 | D28: =C28-B28 -> 0
A29: 21 | B29: =C28 -> 0 | D29: =C29-B29 -> 0
A30: 22 | B30: =C29 -> 0 | D30: =C30-B30 -> 0
A31: 23 | B31: =C30 -> 0 | D31: =C31-B31 -> 0
A32: 24 | B32: =C31 -> 0 | D32: =C32-B32 -> 0
A33: 25 | B33: =C32 -> 0 | D33: =C33-B33 -> 0
A34: 26 | B34: =C33 -> 0 | D34: =C34-B34 -> 0
A35: 27 | B35: =C34 -> 0 | D35: =C35-B35 -> 0
A36: 28 | B36: =C35 -> 0 | D36: =C36-B36 -> 0
A37: 29 | B37: =C36 -> 0 | D37: =C37-B37 -> 0
... A39: 31 | B39: =C38 -> 0 | D39: =C39-B39 -> 0
A40: Total | D40: =SUM(D9:D39) -> -2764195

Sheet FEEDER Consumption 
A1: 44378
A2: POWER HOUSE FEEDER READING
C3: BLU FEEDER PANEL 1 | H3: BLU FEEDER PANEL 2 | M3: POWER HOUSE FEEDER PANEL NO:3 | R3: Main Kitchen -7 | W3: Main Kitchen -10 | AB3: Water treatment Plant | AG3: Sewage treatment Plant | AL3: Laundry--8SSB | AQ3: Laundry-9 | AV3: New staff accomodation (E0) | BA3: Staff block-16(E2-E3) | BF3: Staff Block Feeder-3(E4-E5) | BK3: Management block-5 | BP3: SNR STAFF BLOCK | BU3: BOAT DOCK FEEDER - 22 | BZ3: RECEPTION | CE3: DIVE CENTER | CJ3: 301-307 | CO3: 308-314 | CT3: 315-320 | CY3: 401-407 | DD3: 408-414 | DI3: 415-420 | DN3: SPA - 1 | DS3: SPA - 2 | DX3: BLU KITCHEN - 1 | EC3: BLU KITCHEN - 2 | EH3: AL BARAKATH | EM3: STAFF KITCHEN | ER3: MANAGR BLOCK GARDEN
A4: DAY | B4: Occupancy | C4: Yesterday | D4: Today | E4: Consumption | F4: Variance (Tdy vs Ystdy) | G4: % | H4: Yesterday | I4: Today | J4: Consumption | K4: Var(Tdy vs Ystdy) | L4: % | M4: Yesterday | N4: Today | O4: Consumption | P4: Var (Tdy vs Ystdy) | Q4: % | R4: Yesterday | S4: Today | T4: Consumption | U4: Var(Tdy vs Ystdy) | V4: % | W4: Yesterday | X4: Today | Y4: Consumption | Z4: Var(Tdy vs Ystdy) | AA4: % | AB4: Yesterday | AC4: Today | AD4: Consumption | AE4: Var(Tdy vs Ystdy) | AF4: % | AG4: Yesterday | AH4: Today | AI4: Consumption | AJ4: Var(Tdy vs Ystdy) | AK4: % | AL4: Yesterday | AM4: Today | AN4: Consumption | AO4: Var(Tdy vs Ystdy) | AP4: % | AQ4: Yesterday | AR4: Today | AS4: Consumption | AT4: Var(Tdy vs Ystdy) | AU4: % | AV4: Yesterday | AW4: Today | AX4: Consumption | AY4: Var(Tdy vs Ystdy) | AZ4: % | BA4: Yesterday | BB4: Today | BC4: Consumption | BD4: Var(Tdy vs Ystdy) | BE4: % | BF4: Yesterday | BG4: Today | BH4: Consumption | BI4: Var(Tdy vs Ystdy) | BJ4: % | BK4: Yesterday | BL4: Today | BM4: Consumption | BN4: Var(Tdy vs Ystdy) | BO4: % | BP4: Yesterday | BQ4: Today | BR4: Consumption | BS4: Var(Tdy vs Ystdy) | BT4: % | BU4: Yesterday | BV4: Today | BW4: Consumption | BX4: Var(Tdy vs Ystdy) | BY4: % | BZ4: Yesterday | CA4: Today | CB4: Consumption | CC4: Var(Tdy vs Ystdy) | CD4: % | CE4: Yesterday | CF4: Today | CG4: Consumption | CH4: Var(Tdy vs Ystdy) | CI4: % | CJ4: Yesterday | CK4: Today | CL4: Consumption | CM4: Var(Tdy vs Ystdy) | CN4: % | CO4: Yesterday | CP4: Today | CQ4: Consumption | CR4: Var(Tdy vs Ystdy) | CS4: % | CT4: Yesterday | CU4: Today | CV4: Consumption | CW4: Var(Tdy vs Ystdy) | CX4: % | CY4: Yesterday | CZ4: Today | DA4: Consumption | DB4: Var(Tdy vs Ystdy) | DC4: % | DD4: Yesterday | DE4: Today | DF4: Consumption | DG4: Var(Tdy vs Ystdy) | DH4: % | DI4: Yesterday | DJ4: Today | DK4: Consumption | DL4: Var(Tdy vs Ystdy) | DM4: % | DN4: Yesterday | DO4: Today | DP4: Consumption | DQ4: Var(Tdy vs Ystdy) | DR4: % | DS4: Yesterday | DT4: Today | DU4: Consumption | DV4: Var(Tdy vs Ystdy) | DW4: % | DX4: Yesterday | DY4: Today | DZ4: Consumption | EA4: Var(Tdy vs Ystdy) | EB4: % | EC4: Yesterday | ED4: Today | EE4: Consumption | EF4: Var(Tdy vs Ystdy) | EG4: % | EH4: Yesterday | EI4: Today | EJ4: Consumption | EK4: Var(Tdy vs Ystdy) | EL4: % | EM4: Yesterday | EN4: Today | EO4: Consumption | EP4: Var(Tdy vs Ystdy) | EQ4: % | ER4: Yesterday | ES4: Today | ET4: Consumption | EU4: Var(Tdy vs Ystdy) | EV4: %
A5: 1 | B5: ='Finance Only'!G8 -> 18.4 | C5: 25725099 | D5: 25727421 | E5: =D5-C5 -> 2322 | H5: 22880065 | I5: 22884764 | J5: =I5-H5 -> 4699 | M5: 86299457 | N5: 86313000 | O5: =N5-M5 -> 13543 | R5: 20899 | S5: 20919 | T5: =S5-R5 -> 20 | W5: 2829237 | X5: 2831913 | Y5: =X5-W5 -> 2676 | AB5: 17304 | AC5: 17321 | AD5: =AC5-AB5 -> 17 | AG5: 771494 | AH5: 771917 | AI5: =AH5-AG5 -> 423 | AL5: 79920 | AM5: 79981 | AN5: =AM5-AL5 -> 61 | AQ5: 18111 | AR5: 18119 | AS5: =AR5-AQ5 -> 8 | AV5: 520127 | AW5: 520580 | AX5: =AW5-AV5 -> 453 | BA5: 68608 | BB5: 68698 | BC5: =BB5-BA5 -> 90 | BF5: 78563 | BG5: 78649 | BH5: =BG5-BF5 -> 86 | BK5: 12247 | BL5: 12260 | BM5: =BL5-BK5 -> 13 | BP5: 69843 | BQ5: 70001 | BR5: =BQ5-BP5 -> 158 | BU5: 38520 | BV5: 38559 | BW5: =BV5-BU5 -> 39 | BZ5: 53178 | CA5: 53301 | CB5: =CA5-BZ5 -> 123 | CE5: 15858 | CF5: 15898 | CG5: =CF5-CE5 -> 40 | CJ5: 36130 | CK5: 36246 | CL5: =CK5-CJ5 -> 116 | CO5: 28858 | CP5: 28930 | CQ5: =CP5-CO5 -> 72 | CT5: 25486 | CU5: 25545 | CV5: =CU5-CT5 -> 59 | CY5: 42103 | CZ5: 42225 | DA5: =CZ5-CY5 -> 122 | DD5: 31530 | DE5: 31635 | DF5: =DE5-DD5 -> 105 | DI5: 29237 | DJ5: 29319 | DK5: =DJ5-DI5 -> 82 | DN5: 19542 | DO5: 19596 | DP5: =DO5-DN5 -> 54 | DS5: 52606 | DT5: 52717 | DU5: =DT5-DS5 -> 111 | DX5: 36398 | DY5: 36463 | DZ5: =DY5-DX5 -> 65 | EC5: 11211 | ED5: 11237 | EE5: =ED5-EC5 -> 26 | EH5: 98396 | EI5: 98800 | EJ5: =EI5-EH5 -> 404 | EM5: 19790 | EN5: 19842 | EO5: =EN5-EM5 -> 52 | ER5: 39170 | ES5: 39493 | ET5: =ES5-ER5 -> 323
A6: 2 | B6: ='Finance Only'!G9 -> 12.7 | C6: =D5 -> 25727421 | D6: 25729835 | E6: =D6-C6 -> 2414 | F6: =E6-E5 -> 92 | G6: =(E6/'Finance Only'!B9)*100 -> 8.9920286 | H6: =I5 -> 22884764 | I6: 22890036 | J6: =I6-H6 -> 5272 | K6: =J6-J5 -> 573 | L6: =(J6/'Finance Only'!B9)*100 -> 19.637935 | M6: =N5 -> 86313000 | N6: 86326159 | O6: =N6-M6 -> 13159 | P6: =O6-O5 -> -384 | Q6: =(O6/'Finance Only'!B9)*100 -> 49.016613 | R6: =S5 -> 20919 | S6: 20939 | T6: =S6-R6 -> 20 | U6: =T6-T5 -> 0 | V6: =(T6/'Finance Only'!B9)*100 -> 0.074498994 | W6: =X5 -> 2831913 | X6: 2834631 | Y6: =X6-W6 -> 2718 | Z6: =Y6-Y5 -> 42 | AA6: =(Y6/'Finance Only'!B9)*100 -> 10.124413 | AB6: =AC5 -> 17321 | AC6: 17336 | AD6: =AC6-AB6 -> 15 | AE6: =AD6-AD5 -> -2 | AF6: =(AD6/'Finance Only'!B9)*100 -> 0.055874246 | AG6: =AH5 -> 771917 | AH6: 772307 | AI6: =AH6-AG6 -> 390 | AJ6: =AI6-AI5 -> -33 | AK6: =(AI6/'Finance Only'!B9)*100 -> 1.4527304 | AL6: =AM5 -> 79981 | AM6: 80047 | AN6: =AM6-AL6 -> 66 | AO6: =AN6-AN5 -> 5 | AP6: =(AN6/'Finance Only'!B9)*100 -> 0.24584668 | AQ6: =AR5 -> 18119 | AR6: 18133 | AS6: =AR6-AQ6 -> 14 | AT6: =AS6-AS5 -> 6 | AU6: =(AS6/'Finance Only'!B9)*100 -> 0.052149296 | AV6: =AW5 -> 520580 | AW6: 520995 | AX6: =AW6-AV6 -> 415 | AY6: =AX6-AX5 -> -38 | AZ6: =(AX6/'Finance Only'!B9)*100 -> 1.5458541 | BA6: =BB5 -> 68698 | BB6: 68781 | BC6: =BB6-BA6 -> 83 | BD6: =BC6-BC5 -> -7 | BE6: =(BC6/'Finance Only'!B9)*100 -> 0.30917083 | BF6: =BG5 -> 78649 | BG6: 78733 | BH6: =BG6-BF6 -> 84 | BI6: =BH6-BH5 -> -2 | BJ6: =(BH6/'Finance Only'!B9)*100 -> 0.31289578 | BK6: =BL5 -> 12260 | BL6: 12274 | BM6: =BL6-BK6 -> 14 | BN6: =BM6-BM5 -> 1 | BO6: =(BM6/'Finance Only'!B9)*100 -> 0.052149296 | BP6: =BQ5 -> 70001 | BQ6: 70183 | BR6: =BQ6-BP6 -> 182 | BS6: =BR6-BR5 -> 24 | BT6: =(BR6/'Finance Only'!B9)*100 -> 0.67794085 | BU6: =BV5 -> 38559 | BV6: 38597 | BW6: =BV6-BU6 -> 38 | BX6: =BW6-BW5 -> -1 | BY6: =(BW6/'Finance Only'!B9)*100 -> 0.14154809 | BZ6: =CA5 -> 53301 | CA6: 53423 | CB6: =CA6-BZ6 -> 122 | CC6: =CB6-CB5 -> -1 | CD6: =(CB6/'Finance Only'!B9)*100 -> 0.45444387 | CE6: =CF5 -> 15898 | CF6: 15937 | CG6: =CF6-CE6 -> 39 | CH6: =CG6-CG5 -> -1 | CI6: =(CG6/'Finance Only'!B9)*100 -> 0.14527304 | CJ6: =CK5 -> 36246 | CK6: 36352 | CL6: =CK6-CJ6 -> 106 | CM6: =CL6-CL5 -> -10 | CN6: =(CL6/'Finance Only'!B9)*100 -> 0.39484467 | CO6: =CP5 -> 28930 | CP6: 29004 | CQ6: =CP6-CO6 -> 74 | CR6: =CQ6-CQ5 -> 2 | CS6: =(CQ6/'Finance Only'!B9)*100 -> 0.27564628 | CT6: =CU5 -> 25545 | CU6: 25609 | CV6: =CU6-CT6 -> 64 | CW6: =CV6-CV5 -> 5 | CX6: =(CV6/'Finance Only'!B9)*100 -> 0.23839678 | CY6: =CZ5 -> 42225 | CZ6: 42350 | DA6: =CZ6-CY6 -> 125 | DB6: =DA6-DA5 -> 3 | DC6: =(DA6/'Finance Only'!B9)*100 -> 0.46561871 | DD6: =DE5 -> 31635 | DE6: 31732 | DF6: =DE6-DD6 -> 97 | DG6: =DF6-DF5 -> -8 | DH6: =(DF6/'Finance Only'!B9)*100 -> 0.36132012 | DI6: =DJ5 -> 29319 | DJ6: 29420 | DK6: =DJ6-DI6 -> 101 | DL6: =DK6-DK5 -> 19 | DM6: =(DK6/'Finance Only'!B9)*100 -> 0.37621992 | DN6: =DO5 -> 19596 | DO6: 19646 | DP6: =DO6-DN6 -> 50 | DQ6: =DP6-DP5 -> -4 | DR6: =(DP6/'Finance Only'!B9)*100 -> 0.18624749 | DS6: =DT5 -> 52717 | DT6: 52807 | DU6: =DT6-DS6 -> 90 | DV6: =DU6-DU5 -> -21 | DW6: =(DU6/'Finance Only'!B9)*100 -> 0.33524547 | DX6: =DY5 -> 36463 | DY6: 36526 | DZ6: =DY6-DX6 -> 63 | EA6: =DZ6-DZ5 -> -2 | EB6: =(DZ6/'Finance Only'!B9)*100 -> 0.23467183 | EC6: =ED5 -> 11237 | ED6: 11260 | EE6: =ED6-EC6 -> 23 | EF6: =EE6-EE5 -> -3 | EG6: =(EE6/'Finance Only'!B9)*100 -> 0.085673843 | EH6: =EI5 -> 98800 | EI6: 99009 | EJ6: =EI6-EH6 -> 209 | EK6: =EJ6-EJ5 -> -195 | EL6: =(EJ6/'Finance Only'!B9)*100 -> 0.77851449 | EM6: =EN5 -> 19842 | EN6: 19891 | EO6: =EN6-EM6 -> 49 | EP6: =EO6-EO5 -> -3 | EQ6: =(EO6/'Finance Only'!B9)*100 -> 0.18252254 | ER6: =ES5 -> 39493 | ES6: 39787 | ET6: =ES6-ER6 -> 294 | EU6: =ET6-ET5 -> -29 | EV6: =(ET6/'Finance Only'!B9)*100 -> 1.0951352
A7: 3 | B7: ='Finance Only'!G10 -> 12.6 | C7: =D6 -> 25729835 | D7: 25732330 | E7: =D7-C7 -> 2495 | F7: =E7-E6 -> 81 | G7: =(E7/'Finance Only'!B10)*100 -> 9.1291621 | H7: =I6 -> 22890036 | I7: 22895094 | J7: =I7-H7 -> 5058 | K7: =J7-J6 -> -214 | L7: =(J7/'Finance Only'!B10)*100 -> 18.507135 | M7: =N6 -> 86326159 | N7: 86340540 | O7: =N7-M7 -> 14381 | P7: =O7-O6 -> 1222 | Q7: =(O7/'Finance Only'!B10)*100 -> 52.619832 | R7: =S6 -> 20939 | S7: 20959 | T7: =S7-R7 -> 20 | U7: =T7-T6 -> 0 | V7: =(T7/'Finance Only'!B10)*100 -> 0.073179656 | W7: =X6 -> 2834631 | X7: 2837321 | Y7: =X7-W7 -> 2690 | Z7: =Y7-Y6 -> -28 | AA7: =(Y7/'Finance Only'!B10)*100 -> 9.8426637 | AB7: =AC6 -> 17336 | AC7: 17353 | AD7: =AC7-AB7 -> 17 | AE7: =AD7-AD6 -> 2 | AF7: =(AD7/'Finance Only'!B10)*100 -> 0.062202708 | AG7: =AH6 -> 772307 | AH7: 772719 | AI7: =AH7-AG7 -> 412 | AJ7: =AI7-AI6 -> 22 | AK7: =(AI7/'Finance Only'!B10)*100 -> 1.5075009 | AL7: =AM6 -> 80047 | AM7: 80113 | AN7: =AM7-AL7 -> 66 | AO7: =AN7-AN6 -> 0 | AP7: =(AN7/'Finance Only'!B10)*100 -> 0.24149286 | AQ7: =AR6 -> 18133 | AR7: 18141 | AS7: =AR7-AQ7 -> 8 | AT7: =AS7-AS6 -> -6 | AU7: =(AS7/'Finance Only'!B10)*100 -> 0.029271862 | AV7: =AW6 -> 520995 | AW7: 521383 | AX7: =AW7-AV7 -> 388 | AY7: =AX7-AX6 -> -27 | AZ7: =(AX7/'Finance Only'!B10)*100 -> 1.4196853 | BA7: =BB6 -> 68781 | BB7: 68875 | BC7: =BB7-BA7 -> 94 | BD7: =BC7-BC6 -> 11 | BE7: =(BC7/'Finance Only'!B10)*100 -> 0.34394438 | BF7: =BG6 -> 78733 | BG7: 78829 | BH7: =BG7-BF7 -> 96 | BI7: =BH7-BH6 -> 12 | BJ7: =(BH7/'Finance Only'!B10)*100 -> 0.35126235 | BK7: =BL6 -> 12274 | BL7: 12288 | BM7: =BL7-BK7 -> 14 | BN7: =BM7-BM6 -> 0 | BO7: =(BM7/'Finance Only'!B10)*100 -> 0.051225759 | BP7: =BQ6 -> 70183 | BQ7: 70421 | BR7: =BQ7-BP7 -> 238 | BS7: =BR7-BR6 -> 56 | BT7: =(BR7/'Finance Only'!B10)*100 -> 0.87083791 | BU7: =BV6 -> 38597 | BV7: 38636 | BW7: =BV7-BU7 -> 39 | BX7: =BW7-BW6 -> 1 | BY7: =(BW7/'Finance Only'!B10)*100 -> 0.14270033 | BZ7: =CA6 -> 53423 | CA7: 53547 | CB7: =CA7-BZ7 -> 124 | CC7: =CB7-CB6 -> 2 | CD7: =(CB7/'Finance Only'!B10)*100 -> 0.45371387 | CE7: =CF6 -> 15937 | CF7: 15984 | CG7: =CF7-CE7 -> 47 | CH7: =CG7-CG6 -> 8 | CI7: =(CG7/'Finance Only'!B10)*100 -> 0.17197219 | CJ7: =CK6 -> 36352 | CK7: 36463 | CL7: =CK7-CJ7 -> 111 | CM7: =CL7-CL6 -> 5 | CN7: =(CL7/'Finance Only'!B10)*100 -> 0.40614709 | CO7: =CP6 -> 29004 | CP7: 29083 | CQ7: =CP7-CO7 -> 79 | CR7: =CQ7-CQ6 -> 5 | CS7: =(CQ7/'Finance Only'!B10)*100 -> 0.28905964 | CT7: =CU6 -> 25609 | CU7: 25682 | CV7: =CU7-CT7 -> 73 | CW7: =CV7-CV6 -> 9 | CX7: =(CV7/'Finance Only'!B10)*100 -> 0.26710574 | CY7: =CZ6 -> 42350 | CZ7: 42463 | DA7: =CZ7-CY7 -> 113 | DB7: =DA7-DA6 -> -12 | DC7: =(DA7/'Finance Only'!B10)*100 -> 0.41346506 | DD7: =DE6 -> 31732 | DE7: 31808 | DF7: =DE7-DD7 -> 76 | DG7: =DF7-DF6 -> -21 | DH7: =(DF7/'Finance Only'!B10)*100 -> 0.27808269 | DI7: =DJ6 -> 29420 | DJ7: 29519 | DK7: =DJ7-DI7 -> 99 | DL7: =DK7-DK6 -> -2 | DM7: =(DK7/'Finance Only'!B10)*100 -> 0.3622393 | DN7: =DO6 -> 19646 | DO7: 19699 | DP7: =DO7-DN7 -> 53 | DQ7: =DP7-DP6 -> 3 | DR7: =(DP7/'Finance Only'!B10)*100 -> 0.19392609 | DS7: =DT6 -> 52807 | DT7: 52889 | DU7: =DT7-DS7 -> 82 | DV7: =DU7-DU6 -> -8 | DW7: =(DU7/'Finance Only'!B10)*100 -> 0.30003659 | DX7: =DY6 -> 36526 | DY7: 36589 | DZ7: =DY7-DX7 -> 63 | EA7: =DZ7-DZ6 -> 0 | EB7: =(DZ7/'Finance Only'!B10)*100 -> 0.23051592 | EC7: =ED6 -> 11260 | ED7: 11283 | EE7: =ED7-EC7 -> 23 | EF7: =EE7-EE6 -> 0 | EG7: =(EE7/'Finance Only'!B10)*100 -> 0.084156604 | EH7: =EI6 -> 99009 | EI7: 99323 | EJ7: =EI7-EH7 -> 314 | EK7: =EJ7-EJ6 -> 105 | EL7: =(EJ7/'Finance Only'!B10)*100 -> 1.1489206 | EM7: =EN6 -> 19891 | EN7: 19940 | EO7: =EN7-EM7 -> 49 | EP7: =EO7-EO6 -> 0 | EQ7: =(EO7/'Finance Only'!B10)*100 -> 0.17929016 | ER7: =ES6 -> 39787 | ES7: 40095 | ET7: =ES7-ER7 -> 308 | EU7: =ET7-ET6 -> 14 | EV7: =(ET7/'Finance Only'!B10)*100 -> 1.1269667
A8: 4 | B8: ='Finance Only'!G11 -> 15.5 | C8: =D7 -> 25732330 | D8: 25734686 | E8: =D8-C8 -> 2356 | F8: =E8-E7 -> -139 | G8: =(E8/'Finance Only'!B11)*100 -> 8.6215099 | H8: =I7 -> 22895094 | I8: 22899591 | J8: =I8-H8 -> 4497 | K8: =J8-J7 -> -561 | L8: =(J8/'Finance Only'!B11)*100 -> 16.456252 | M8: =N7 -> 86340540 | N8: 86355077 | O8: =N8-M8 -> 14537 | P8: =O8-O7 -> 156 | Q8: =(O8/'Finance Only'!B11)*100 -> 53.196472 | R8: =S7 -> 20959 | S8: 20979 | T8: =S8-R8 -> 20 | U8: =T8-T7 -> 0 | V8: =(T8/'Finance Only'!B11)*100 -> 0.07318769 | W8: =X7 -> 2837321 | X8: 2840164 | Y8: =X8-W8 -> 2843 | Z8: =Y8-Y7 -> 153 | AA8: =(Y8/'Finance Only'!B11)*100 -> 10.40363 | AB8: =AC7 -> 17353 | AC8: 17372 | AD8: =AC8-AB8 -> 19 | AE8: =AD8-AD7 -> 2 | AF8: =(AD8/'Finance Only'!B11)*100 -> 0.069528305 | AG8: =AH7 -> 772719 | AH8: 773152 | AI8: =AH8-AG8 -> 433 | AJ8: =AI8-AI7 -> 21 | AK8: =(AI8/'Finance Only'!B11)*100 -> 1.5845135 | AL8: =AM7 -> 80113 | AM8: 80178 | AN8: =AM8-AL8 -> 65 | AO8: =AN8-AN7 -> -1 | AP8: =(AN8/'Finance Only'!B11)*100 -> 0.23785999 | AQ8: =AR7 -> 18141 | AR8: 18155 | AS8: =AR8-AQ8 -> 14 | AT8: =AS8-AS7 -> 6 | AU8: =(AS8/'Finance Only'!B11)*100 -> 0.051231383 | AV8: =AW7 -> 521383 | AW8: 521795 | AX8: =AW8-AV8 -> 412 | AY8: =AX8-AX7 -> 24 | AZ8: =(AX8/'Finance Only'!B11)*100 -> 1.5076664 | BA8: =BB7 -> 68875 | BB8: 68975 | BC8: =BB8-BA8 -> 100 | BD8: =BC8-BC7 -> 6 | BE8: =(BC8/'Finance Only'!B11)*100 -> 0.36593845 | BF8: =BG7 -> 78829 | BG8: 78932 | BH8: =BG8-BF8 -> 103 | BI8: =BH8-BH7 -> 7 | BJ8: =(BH8/'Finance Only'!B11)*100 -> 0.3769166 | BK8: =BL7 -> 12288 | BL8: 12304 | BM8: =BL8-BK8 -> 16 | BN8: =BM8-BM7 -> 2 | BO8: =(BM8/'Finance Only'!B11)*100 -> 0.058550152 | BP8: =BQ7 -> 70421 | BQ8: 70634 | BR8: =BQ8-BP8 -> 213 | BS8: =BR8-BR7 -> -25 | BT8: =(BR8/'Finance Only'!B11)*100 -> 0.7794489 | BU8: =BV7 -> 38636 | BV8: 38680 | BW8: =BV8-BU8 -> 44 | BX8: =BW8-BW7 -> 5 | BY8: =(BW8/'Finance Only'!B11)*100 -> 0.16101292 | BZ8: =CA7 -> 53547 | CA8: 53670 | CB8: =CA8-BZ8 -> 123 | CC8: =CB8-CB7 -> -1 | CD8: =(CB8/'Finance Only'!B11)*100 -> 0.45010429 | CE8: =CF7 -> 15984 | CF8: 16024 | CG8: =CF8-CE8 -> 40 | CH8: =CG8-CG7 -> -7 | CI8: =(CG8/'Finance Only'!B11)*100 -> 0.14637538 | CJ8: =CK7 -> 36463 | CK8: 36565 | CL8: =CK8-CJ8 -> 102 | CM8: =CL8-CL7 -> -9 | CN8: =(CL8/'Finance Only'!B11)*100 -> 0.37325722 | CO8: =CP7 -> 29083 | CP8: 29156 | CQ8: =CP8-CO8 -> 73 | CR8: =CQ8-CQ7 -> -6 | CS8: =(CQ8/'Finance Only'!B11)*100 -> 0.26713507 | CT8: =CU7 -> 25682 | CU8: 25735 | CV8: =CU8-CT8 -> 53 | CW8: =CV8-CV7 -> -20 | CX8: =(CV8/'Finance Only'!B11)*100 -> 0.19394738 | CY8: =CZ7 -> 42463 | CZ8: 42555 | DA8: =CZ8-CY8 -> 92 | DB8: =DA8-DA7 -> -21 | DC8: =(DA8/'Finance Only'!B11)*100 -> 0.33666337 | DD8: =DE7 -> 31808 | DE8: 31895 | DF8: =DE8-DD8 -> 87 | DG8: =DF8-DF7 -> 11 | DH8: =(DF8/'Finance Only'!B11)*100 -> 0.31836645 | DI8: =DJ7 -> 29519 | DJ8: 29603 | DK8: =DJ8-DI8 -> 84 | DL8: =DK8-DK7 -> -15 | DM8: =(DK8/'Finance Only'!B11)*100 -> 0.3073883 | DN8: =DO7 -> 19699 | DO8: 19751 | DP8: =DO8-DN8 -> 52 | DQ8: =DP8-DP7 -> -1 | DR8: =(DP8/'Finance Only'!B11)*100 -> 0.19028799 | DS8: =DT7 -> 52889 | DT8: 52993 | DU8: =DT8-DS8 -> 104 | DV8: =DU8-DU7 -> 22 | DW8: =(DU8/'Finance Only'!B11)*100 -> 0.38057599 | DX8: =DY7 -> 36589 | DY8: 36655 | DZ8: =DY8-DX8 -> 66 | EA8: =DZ8-DZ7 -> 3 | EB8: =(DZ8/'Finance Only'!B11)*100 -> 0.24151938 | EC8: =ED7 -> 11283 | ED8: 11306 | EE8: =ED8-EC8 -> 23 | EF8: =EE8-EE7 -> 0 | EG8: =(EE8/'Finance Only'!B11)*100 -> 0.084165843 | EH8: =EI7 -> 99323 | EI8: 99671 | EJ8: =EI8-EH8 -> 348 | EK8: =EJ8-EJ7 -> 34 | EL8: =(EJ8/'Finance Only'!B11)*100 -> 1.2734658 | EM8: =EN7 -> 19940 | EN8: 19992 | EO8: =EN8-EM8 -> 52 | EP8: =EO8-EO7 -> 3 | EQ8: =(EO8/'Finance Only'!B11)*100 -> 0.19028799 | ER8: =ES7 -> 40095 | ES8: 40391 | ET8: =ES8-ER8 -> 296 | EU8: =ET8-ET7 -> -12 | EV8: =(ET8/'Finance Only'!B11)*100 -> 1.0831778
A9: 5 | B9: ='Finance Only'!G12 -> 13.6 | C9: =D8 -> 25734686 | D9: 25737038 | E9: =D9-C9 -> 2352 | F9: =E9-E8 -> -4 | G9: =(E9/'Finance Only'!B12)*100 -> 8.9753864 | H9: =I8 -> 22899591 | I9: 22904113 | J9: =I9-H9 -> 4522 | K9: =J9-J8 -> 25 | L9: =(J9/'Finance Only'!B12)*100 -> 17.256249 | M9: =N8 -> 86355077 | N9: 86368980 | O9: =N9-M9 -> 13903 | P9: =O9-O8 -> -634 | Q9: =(O9/'Finance Only'!B12)*100 -> 53.054761 | R9: =S8 -> 20979 | S9: 20998 | T9: =S9-R9 -> 19 | U9: =T9-T8 -> -1 | V9: =(T9/'Finance Only'!B12)*100 -> 0.072505247 | W9: =X8 -> 2840164 | X9: 2842892 | Y9: =X9-W9 -> 2728 | Z9: =Y9-Y8 -> -115 | AA9: =(Y9/'Finance Only'!B12)*100 -> 10.410227 | AB9: =AC8 -> 17372 | AC9: 17387 | AD9: =AC9-AB9 -> 15 | AE9: =AD9-AD8 -> -4 | AF9: =(AD9/'Finance Only'!B12)*100 -> 0.057240985 | AG9: =AH8 -> 773152 | AH9: 773538 | AI9: =AH9-AG9 -> 386 | AJ9: =AI9-AI8 -> -47 | AK9: =(AI9/'Finance Only'!B12)*100 -> 1.4730013 | AL9: =AM8 -> 80178 | AM9: 80239 | AN9: =AM9-AL9 -> 61 | AO9: =AN9-AN8 -> -4 | AP9: =(AN9/'Finance Only'!B12)*100 -> 0.23278 | AQ9: =AR8 -> 18155 | AR9: 18164 | AS9: =AR9-AQ9 -> 9 | AT9: =AS9-AS8 -> -5 | AU9: =(AS9/'Finance Only'!B12)*100 -> 0.034344591 | AV9: =AW8 -> 521795 | AW9: 522186 | AX9: =AW9-AV9 -> 391 | AY9: =AX9-AX8 -> -21 | AZ9: =(AX9/'Finance Only'!B12)*100 -> 1.4920817 | BA9: =BB8 -> 68975 | BB9: 69077 | BC9: =BB9-BA9 -> 102 | BD9: =BC9-BC8 -> 2 | BE9: =(BC9/'Finance Only'!B12)*100 -> 0.38923869 | BF9: =BG8 -> 78932 | BG9: 79031 | BH9: =BG9-BF9 -> 99 | BI9: =BH9-BH8 -> -4 | BJ9: =(BH9/'Finance Only'!B12)*100 -> 0.3777905 | BK9: =BL8 -> 12304 | BL9: 12319 | BM9: =BL9-BK9 -> 15 | BN9: =BM9-BM8 -> -1 | BO9: =(BM9/'Finance Only'!B12)*100 -> 0.057240985 | BP9: =BQ8 -> 70634 | BQ9: 70821 | BR9: =BQ9-BP9 -> 187 | BS9: =BR9-BR8 -> -26 | BT9: =(BR9/'Finance Only'!B12)*100 -> 0.71360427 | BU9: =BV8 -> 38680 | BV9: 38723 | BW9: =BV9-BU9 -> 43 | BX9: =BW9-BW8 -> -1 | BY9: =(BW9/'Finance Only'!B12)*100 -> 0.16409082 | BZ9: =CA8 -> 53670 | CA9: 53790 | CB9: =CA9-BZ9 -> 120 | CC9: =CB9-CB8 -> -3 | CD9: =(CB9/'Finance Only'!B12)*100 -> 0.45792788 | CE9: =CF8 -> 16024 | CF9: 16065 | CG9: =CF9-CE9 -> 41 | CH9: =CG9-CG8 -> 1 | CI9: =(CG9/'Finance Only'!B12)*100 -> 0.15645869 | CJ9: =CK8 -> 36565 | CK9: 36673 | CL9: =CK9-CJ9 -> 108 | CM9: =CL9-CL8 -> 6 | CN9: =(CL9/'Finance Only'!B12)*100 -> 0.41213509 | CO9: =CP8 -> 29156 | CP9: 29232 | CQ9: =CP9-CO9 -> 76 | CR9: =CQ9-CQ8 -> 3 | CS9: =(CQ9/'Finance Only'!B12)*100 -> 0.29002099 | CT9: =CU8 -> 25735 | CU9: 25770 | CV9: =CU9-CT9 -> 35 | CW9: =CV9-CV8 -> -18 | CX9: =(CV9/'Finance Only'!B12)*100 -> 0.1335623 | CY9: =CZ8 -> 42555 | CZ9: 42652 | DA9: =CZ9-CY9 -> 97 | DB9: =DA9-DA8 -> 5 | DC9: =(DA9/'Finance Only'!B12)*100 -> 0.37015837 | DD9: =DE8 -> 31895 | DE9: 32016 | DF9: =DE9-DD9 -> 121 | DG9: =DF9-DF8 -> 34 | DH9: =(DF9/'Finance Only'!B12)*100 -> 0.46174394 | DI9: =DJ8 -> 29603 | DJ9: 29683 | DK9: =DJ9-DI9 -> 80 | DL9: =DK9-DK8 -> -4 | DM9: =(DK9/'Finance Only'!B12)*100 -> 0.30528525 | DN9: =DO8 -> 19751 | DO9: 19802 | DP9: =DO9-DN9 -> 51 | DQ9: =DP9-DP8 -> -1 | DR9: =(DP9/'Finance Only'!B12)*100 -> 0.19461935 | DS9: =DT8 -> 52993 | DT9: 53084 | DU9: =DT9-DS9 -> 91 | DV9: =DU9-DU8 -> -13 | DW9: =(DU9/'Finance Only'!B12)*100 -> 0.34726197 | DX9: =DY8 -> 36655 | DY9: 36721 | DZ9: =DY9-DX9 -> 66 | EA9: =DZ9-DZ8 -> 0 | EB9: =(DZ9/'Finance Only'!B12)*100 -> 0.25186033 | EC9: =ED8 -> 11306 | ED9: 11329 | EE9: =ED9-EC9 -> 23 | EF9: =EE9-EE8 -> 0 | EG9: =(EE9/'Finance Only'!B12)*100 -> 0.08776951 | EH9: =EI8 -> 99671 | EI9: 100002 | EJ9: =EI9-EH9 -> 331 | EK9: =EJ9-EJ8 -> -17 | EL9: =(EJ9/'Finance Only'!B12)*100 -> 1.2631177 | EM9: =EN8 -> 19992 | EN9: 20041 | EO9: =EN9-EM9 -> 49 | EP9: =EO9-EO8 -> -3 | EQ9: =(EO9/'Finance Only'!B12)*100 -> 0.18698722 | ER9: =ES8 -> 40391 | ES9: 40685 | ET9: =ES9-ER9 -> 294 | EU9: =ET9-ET8 -> -2 | EV9: =(ET9/'Finance Only'!B12)*100 -> 1.1219233
