Workbook

Sheet TOTAL
A1: Site Name | B1: Day | C1: Month | D1: Year | E1: Total Electricity Kwh | F1: Electricity Tariff ($/Kwh) | G1: Natual Gas (m3) | H1: Natural Gas $/m3 | I1: Water Utility Supply (m3) m3 | J1: Water Utility Supply (m3) $/m3 | K1: Room Nights | L1: Total Guests | M1: Utilities day cost dh
A2: Mumbai | B2: 1 | C2: 7 | D2: 2021 | E2: =(IF('Daily HLP'!I4>0,'Daily HLP'!I4,0)) -> 23260.79 | F2: 9 | G2: =(IF('Daily HLP'!M4>0,'Daily HLP'!M4,0)) -> 918.378 | H2: 52 | I2: =(IF('Daily HLP'!P4>0,'Daily HLP'!P4,0)) -> 154 | J2: 118 | K2: =Occupancy!G2 -> 93 | L2: =Occupancy!F2 -> 467 | M2: =E2*F2+G2*H2+#REF!*#REF!+I2*J2 -> #REF!
A3: Mumbai | B3: =B2+1 -> 2 | C3: 7 | D3: 2021 | E3: =(IF('Daily HLP'!I5>0,'Daily HLP'!I5,0)) -> 21035.12 | F3: 9 | G3: =(IF('Daily HLP'!M5>0,'Daily HLP'!M5,0)) -> 510.874 | H3: 52 | I3: =(IF('Daily HLP'!P5>0,'Daily HLP'!P5,0)) -> 162 | J3: 118 | K3: =Occupancy!G3 -> 144 | L3: =Occupancy!F3 -> 417 | M3: =E3*F3+G3*H3+#REF!*#REF!+I3*J3 -> #REF!
A4: Mumbai | B4: =B3+1 -> 3 | C4: 7 | D4: 2021 | E4: =(IF('Daily HLP'!I6>0,'Daily HLP'!I6,0)) -> 22104.09 | F4: 9 | G4: =(IF('Daily HLP'!M6>0,'Daily HLP'!M6,0)) -> 940.268 | H4: 52 | I4: =(IF('Daily HLP'!P6>0,'Daily HLP'!P6,0)) -> 210 | J4: 118 | K4: =Occupancy!G4 -> 187 | L4: =Occupancy!F4 -> 483 | M4: =E4*F4+G4*H4+#REF!*#REF!+I4*J4 -> #REF!
A5: Mumbai | B5: =B4+1 -> 4 | C5: 7 | D5: 2021 | E5: =(IF('Daily HLP'!I7>0,'Daily HLP'!I7,0)) -> 21866.6 | F5: 9 | G5: =(IF('Daily HLP'!M7>0,'Daily HLP'!M7,0)) -> 786.88 | H5: 52 | I5: =(IF('Daily HLP'!P7>0,'Daily HLP'!P7,0)) -> 271 | J5: 118 | K5: =Occupancy!G5 -> 92 | L5: =Occupancy!F5 -> 378 | M5: =E5*F5+G5*H5+#REF!*#REF!+I5*J5 -> #REF!
A6: Mumbai | B6: =B5+1 -> 5 | C6: 7 | D6: 2021 | E6: =(IF('Daily HLP'!I8>0,'Daily HLP'!I8,0)) -> 20992.61 | F6: 9 | G6: =(IF('Daily HLP'!M8>0,'Daily HLP'!M8,0)) -> 925.06 | H6: 52 | I6: =(IF('Daily HLP'!P8>0,'Daily HLP'!P8,0)) -> 241 | J6: 118 | K6: =Occupancy!G6 -> 111 | L6: =Occupancy!F6 -> 252 | M6: =E6*F6+G6*H6+#REF!*#REF!+I6*J6 -> #REF!
A7: Mumbai | B7: =B6+1 -> 6 | C7: 7 | D7: 2021 | E7: =(IF('Daily HLP'!I9>0,'Daily HLP'!I9,0)) -> 19837.63 | F7: 9 | G7: =(IF('Daily HLP'!M9>0,'Daily HLP'!M9,0)) -> 430.96 | H7: 52 | I7: =(IF('Daily HLP'!P9>0,'Daily HLP'!P9,0)) -> 149 | J7: 118 | K7: =Occupancy!G7 -> 122 | L7: =Occupancy!F7 -> 292 | M7: =E7*F7+G7*H7+#REF!*#REF!+I7*J7 -> #REF!
A8: Mumbai | B8: =B7+1 -> 7 | C8: 7 | D8: 2021 | E8: =(IF('Daily HLP'!I10>0,'Daily HLP'!I10,0)) -> 21913.78 | F8: 9 | G8: =(IF('Daily HLP'!M10>0,'Daily HLP'!M10,0)) -> 850.19 | H8: 52 | I8: =(IF('Daily HLP'!P10>0,'Daily HLP'!P10,0)) -> 168 | J8: 118 | K8: =Occupancy!G8 -> 136.27 | L8: =Occupancy!F8 -> 402 | M8: =E8*F8+G8*H8+#REF!*#REF!+I8*J8 -> #REF!
A9: Mumbai | B9: =B8+1 -> 8 | C9: 7 | D9: 2021 | E9: =(IF('Daily HLP'!I11>0,'Daily HLP'!I11,0)) -> 21721.17 | F9: 9 | G9: =(IF('Daily HLP'!M11>0,'Daily HLP'!M11,0)) -> 821.55 | H9: 52 | I9: =(IF('Daily HLP'!P11>0,'Daily HLP'!P11,0)) -> 161 | J9: 118 | K9: =Occupancy!G9 -> 127 | L9: =Occupancy!F9 -> 318 | M9: =E9*F9+G9*H9+#REF!*#REF!+I9*J9 -> #REF!
A10: Mumbai | B10: =B9+1 -> 9 | C10: 7 | D10: 2021 | E10: =(IF('Daily HLP'!I12>0,'Daily HLP'!I12,0)) -> 22673.21 | F10: 9 | G10: =(IF('Daily HLP'!M12>0,'Daily HLP'!M12,0)) -> 830.84 | H10: 52 | I10: =(IF('Daily HLP'!P12>0,'Daily HLP'!P12,0)) -> 191 | J10: 118 | K10: =Occupancy!G10 -> 151 | L10: =Occupancy!F10 -> 464 | M10: =E10*F10+G10*H10+#REF!*#REF!+I10*J10 -> #REF!
A11: Mumbai | B11: =B10+1 -> 10 | C11: 7 | D11: 2021 | E11: =(IF('Daily HLP'!I13>0,'Daily HLP'!I13,0)) -> 21102 | F11: 9 | G11: =(IF('Daily HLP'!M13>0,'Daily HLP'!M13,0)) -> 829 | H11: 52 | I11: =(IF('Daily HLP'!P13>0,'Daily HLP'!P13,0)) -> 218 | J11: 118 | K11: =Occupancy!G11 -> 188 | L11: =Occupancy!F11 -> 520 | M11: =E11*F11+G11*H11+#REF!*#REF!+I11*J11 -> #REF!
A12: Mumbai | B12: =B11+1 -> 11 | C12: 7 | D12: 2021 | E12: =(IF('Daily HLP'!I14>0,'Daily HLP'!I14,0)) -> 22829.97 | F12: 9 | G12: =(IF('Daily HLP'!M14>0,'Daily HLP'!M14,0)) -> 986.41 | H12: 52 | I12: =(IF('Daily HLP'!P14>0,'Daily HLP'!P14,0)) -> 240 | J12: 118 | K12: =Occupancy!G12 -> 150 | L12: =Occupancy!F12 -> 668 | M12: =E12*F12+G12*H12+#REF!*#REF!+I12*J12 -> #REF!
A13: Mumbai | B13: =B12+1 -> 12 | C13: 7 | D13: 2021 | E13: =(IF('Daily HLP'!I15>0,'Daily HLP'!I15,0)) -> 21239.9 | F13: 9 | G13: =(IF('Daily HLP'!M15>0,'Daily HLP'!M15,0)) -> 914.79 | H13: 52 | I13: =(IF('Daily HLP'!P15>0,'Daily HLP'!P15,0)) -> 186 | J13: 118 | K13: =Occupancy!G13 -> 126 | L13: =Occupancy!F13 -> 391 | M13: =E13*F13+G13*H13+#REF!*#REF!+I13*J13 -> #REF!
A14: Mumbai | B14: =B13+1 -> 13 | C14: 7 | D14: 2021 | E14: =(IF('Daily HLP'!I16>0,'Daily HLP'!I16,0)) -> 21611.4 | F14: 9 | G14: =(IF('Daily HLP'!M16>0,'Daily HLP'!M16,0)) -> 943.8 | H14: 52 | I14: =(IF('Daily HLP'!P16>0,'Daily HLP'!P16,0)) -> 202 | J14: 118 | K14: =Occupancy!G14 -> 134 | L14: =Occupancy!F14 -> 583 | M14: =E14*F14+G14*H14+#REF!*#REF!+I14*J14 -> #REF!
... A31: Mumbai | B31: =B30+1 -> 30 | C31: 7 | D31: 2021 | E31: =(IF('Daily HLP'!I33>0,'Daily HLP'!I33,0)) -> 21500 | F31: 9 | G31: =(IF('Daily HLP'!M33>0,'Daily HLP'!M33,0)) -> 700 | H31: 52 | I31: =(IF('Daily HLP'!P33>0,'Daily HLP'!P33,0)) -> 134 | J31: 118 | K31: =Occupancy!G31 -> 0 | L31: =Occupancy!F31 -> 0 | M31: =E31*F31+G31*H31+#REF!*#REF!+I31*J31 -> #REF!
A32: Mumbai | B32: =B31+1 -> 31 | C32: 7 | D32: 2021 | E32: =(IF('Daily HLP'!I34>0,'Daily HLP'!I34,0)) -> 21500 | F32: 10 | G32: =(IF('Daily HLP'!M34>0,'Daily HLP'!M34,0)) -> 700 | H32: 52 | I32: =(IF('Daily HLP'!P34>0,'Daily HLP'!P34,0)) -> 0 | J32: 118 | K32: =Occupancy!G32 -> 0 | L32: =Occupancy!F32 -> 0

Sheet Submetering
A1: Site Name | B1: Day | C1: Month | D1: Year | E1: ='Section Load'!F4 -> HVAC | F1: ='Section Load'!G4 -> Fire & Emergency PP | G1: ='Section Load'!H4 -> Main PP | H1: ='Section Load'!I4 -> Lighting PP | I1: ='Section Load'!J4 -> CH-1+ CH2+CH3+CH4 | J1: ='Section Load'!K4 -> Chilled water Pump | K1: ='Section Load'!L4 -> Ball Room-1 | L1: ='Section Load'!M4 -> Ball Room-2 | ... AL1: ='Section Load'!AM4 -> Cooling Tower | AM1: R.o.plant | AN1: STP Water Prod | AO1: Domestic Zone-1 | AP1: Domestic Zone-2 | AQ1: Domestic Zone-3 | AR1: Flush Zone -1 | AS1: Flush Zone -2 | AT1: Flush Zone -3 | AU1: Swimming pool | AV1: B2 Laundry | AW1: Boiler Feed Water | AX1: cooling tower filling water | AY1: STP flush(new water meter) | AZ1: Garden Water Pump | BA1: Flush Zone 2 pump meter | BB1: Flush Zone 3 Pump Meter (wtp transfer ) | BC1: Flush Tanker-Zone-1 | BD1: Total Domestic Water (Tanker (R.O) +BMC) | BE1: Total Domestic Consumption | BF1: Total STP Consumption | BG1: ='Section Load'!AN4 -> MGL | BH1: ='Section Load'!AO4 -> HWG | BI1: ='Section Load'!AP4 -> Prato | BJ1: ='Section Load'!AQ4 -> BR-1 | BK1: ='Section Load'!AR4 -> SanQi IND | BL1: ='Section Load'!AS4 -> SanQi JPN | BM1: ='Section Load'!AT4 -> Boiler
A2: Mumbai | B2: 1 | C2: 7 | D2: 2021 | E2: =(IF('Section Load'!F5>0,'Section Load'!F5,0)) -> 2908.23 | F2: =(IF('Section Load'!G5>0,'Section Load'!G5,0)) -> 1476.32 | G2: =(IF('Section Load'!H5>0,'Section Load'!H5,0)) -> 1714.99 | H2: =(IF('Section Load'!I5>0,'Section Load'!I5,0)) -> 3790.02 | I2: =(IF('Section Load'!J5>0,'Section Load'!J5,0)) -> 7659.86 | J2: =(IF('Section Load'!K5>0,'Section Load'!K5,0)) -> 2635 | K2: =(IF('Section Load'!L5>0,'Section Load'!L5,0)) -> 1429.35 | L2: =(IF('Section Load'!M5>0,'Section Load'!M5,0)) -> 947.75 | ... AL2: =(IF('Section Load'!AM5>0,'Section Load'!AM5,0)) -> 816 | AM2: =(IF('Water Report'!$D$7>0,'Water Report'!$D$7,0)) -> 89 | AN2: =(IF('Water Report'!$D$8>0,'Water Report'!$D$8,0)) -> 97 | AO2: =(IF('Water Report'!$D$9>0,'Water Report'!$D$9,0)) -> 86 | AP2: =(IF('Water Report'!$D$10>0,'Water Report'!$D$10,0)) -> 17 | AQ2: =(IF('Water Report'!$D$11>0,'Water Report'!$D$11,0)) -> 18 | AR2: =(IF('Water Report'!$D$13>0,'Water Report'!$D$13,0)) -> 50 | AS2: =(IF('Water Report'!$D$14>0,'Water Report'!$D$14,0)) -> 6 | AT2: =(IF('Water Report'!$D$15>0,'Water Report'!$D$15,0)) -> 6 | AU2: =(IF('Water Report'!$D$17>0,'Water Report'!$D$17,0)) -> 0 | AV2: =(IF('Water Report'!$D$18>0,'Water Report'!$D$18,0)) -> 12 | AW2: =(IF('Water Report'!$D$19>0,'Water Report'!$D$19,0)) -> 5 | AX2: =(IF('Water Report'!$D$21>0,'Water Report'!$D$21,0)) -> 98 | AY2: =(IF('Water Report'!$D$22>0,'Water Report'!$D$22,0)) -> 40 | AZ2: =(IF('Water Report'!$D$23>0,'Water Report'!$D$23,0)) -> 0 | BA2: =(IF('Water Report'!$D$14>0,'Water Report'!$D$14,0)) -> 6 | BB2: =(IF('Water Report'!$D$15>0,'Water Report'!$D$15,0)) -> 6 | BC2: =(IF('Water Report'!$D$13>0,'Water Report'!$D$13,0)) -> 50 | BD2: =(IF('Water Report'!$D$24>0,'Water Report'!$D$24,0)) -> 154 | BE2: =(IF('Water Report'!$D$25>0,'Water Report'!$D$25,0)) -> 133 | BF2: =(IF('Water Report'!$D$27>0,'Water Report'!$D$27,0)) -> 148 | BG2: =(IF('Section Load'!AN5>0,'Section Load'!AN5,0)) -> 918.378 | BH2: =(IF('Section Load'!AO5>0,'Section Load'!AO5,0)) -> 269.55 | BI2: =(IF('Section Load'!AP5>0,'Section Load'!AP5,0)) -> 0 | BJ2: =(IF('Section Load'!AQ5>0,'Section Load'!AQ5,0)) -> 95.69 | BK2: =(IF('Section Load'!AR5>0,'Section Load'!AR5,0)) -> 33.2 | BL2: =(IF('Section Load'!AS5>0,'Section Load'!AS5,0)) -> 4.3 | BM2: =(IF('Section Load'!AT5>0,'Section Load'!AT5,0)) -> 515.638
A3: Mumbai | B3: =B2+1 -> 2 | C3: 7 | D3: 2021 | E3: =(IF('Section Load'!F6>0,'Section Load'!F6,0)) -> 2899.4 | F3: =(IF('Section Load'!G6>0,'Section Load'!G6,0)) -> 1439.88 | G3: =(IF('Section Load'!H6>0,'Section Load'!H6,0)) -> 1509.84 | H3: =(IF('Section Load'!I6>0,'Section Load'!I6,0)) -> 3743.48 | I3: =(IF('Section Load'!J6>0,'Section Load'!J6,0)) -> 6559.91 | J3: =(IF('Section Load'!K6>0,'Section Load'!K6,0)) -> 2514.4 | K3: =(IF('Section Load'!L6>0,'Section Load'!L6,0)) -> 1047.92 | L3: =(IF('Section Load'!M6>0,'Section Load'!M6,0)) -> 884.9 | ... AL3: =(IF('Section Load'!AM6>0,'Section Load'!AM6,0)) -> 846 | AM3: =(IF('Water Report'!$E$7>0,'Water Report'!$E$7,0)) -> 88 | AN3: =(IF('Water Report'!$E$8>0,'Water Report'!$E$8,0)) -> 122 | AO3: =(IF('Water Report'!$E$9>0,'Water Report'!$E$9,0)) -> 100 | AP3: =(IF('Water Report'!$E$10>0,'Water Report'!$E$10,0)) -> 15 | AQ3: =(IF('Water Report'!$E$11>0,'Water Report'!$E$11,0)) -> 19 | AR3: =(IF('Water Report'!$E$13>0,'Water Report'!$E$13,0)) -> 40 | AS3: =(IF('Water Report'!$E$14>0,'Water Report'!$E$14,0)) -> 8 | AT3: =(IF('Water Report'!$E$15>0,'Water Report'!$E$15,0)) -> 5 | AU3: =(IF('Water Report'!$E$17>0,'Water Report'!$E$17,0)) -> 60 | AV3: =(IF('Water Report'!$E$18>0,'Water Report'!$E$18,0)) -> 0 | AW3: =(IF('Water Report'!$E$19>0,'Water Report'!$E$19,0)) -> 0 | AX3: =(IF('Water Report'!$E$21>0,'Water Report'!$E$21,0)) -> 64 | AY3: =(IF('Water Report'!$E$22>0,'Water Report'!$E$22,0)) -> 83 | AZ3: =(IF('Water Report'!$E$23>0,'Water Report'!$E$23,0)) -> 0 | BA3: =(IF('Water Report'!$E$14>0,'Water Report'!$E$14,0)) -> 8 | BB3: =(IF('Water Report'!$E$15>0,'Water Report'!$E$15,0)) -> 5 | BC3: =(IF('Water Report'!$E$13>0,'Water Report'!$E$13,0)) -> 40 | BD3: =(IF('Water Report'!$E$24>0,'Water Report'!$E$24,0)) -> 162 | BE3: =(IF('Water Report'!$E$25>0,'Water Report'!$E$25,0)) -> 147 | BF3: =(IF('Water Report'!$E$27>0,'Water Report'!$E$27,0)) -> 104 | BG3: =(IF('Section Load'!AN6>0,'Section Load'!AN6,0)) -> 510.874 | BH3: =(IF('Section Load'!AO6>0,'Section Load'!AO6,0)) -> 259.2 | BI3: =(IF('Section Load'!AP6>0,'Section Load'!AP6,0)) -> 0 | BJ3: =(IF('Section Load'!AQ6>0,'Section Load'!AQ6,0)) -> 98.73 | BK3: =(IF('Section Load'!AR6>0,'Section Load'!AR6,0)) -> 36.3 | BL3: =(IF('Section Load'!AS6>0,'Section Load'!AS6,0)) -> 2.6 | BM3: =(IF('Section Load'!AT6>0,'Section Load'!AT6,0)) -> 114.044
A4: Mumbai | B4: =B3+1 -> 3 | C4: 7 | D4: 2021 | E4: =(IF('Section Load'!F7>0,'Section Load'!F7,0)) -> 3065.4 | F4: =(IF('Section Load'!G7>0,'Section Load'!G7,0)) -> 1600.14 | G4: =(IF('Section Load'!H7>0,'Section Load'!H7,0)) -> 1669.24 | H4: =(IF('Section Load'!I7>0,'Section Load'!I7,0)) -> 3847.84 | I4: =(IF('Section Load'!J7>0,'Section Load'!J7,0)) -> 6902.29 | J4: =(IF('Section Load'!K7>0,'Section Load'!K7,0)) -> 2589.8 | K4: =(IF('Section Load'!L7>0,'Section Load'!L7,0)) -> 1085.8 | L4: =(IF('Section Load'!M7>0,'Section Load'!M7,0)) -> 680.22 | ... AL4: =(IF('Section Load'!AM7>0,'Section Load'!AM7,0)) -> 817 | AM4: =(IF('Water Report'!$F$7>0,'Water Report'!$F$7,0)) -> 123 | AN4: =(IF('Water Report'!$F$8>0,'Water Report'!$F$8,0)) -> 85 | AO4: =(IF('Water Report'!$F$9>0,'Water Report'!$G$9,0)) -> 147 | AP4: =(IF('Water Report'!$F$10>0,'Water Report'!$F$10,0)) -> 30 | AQ4: =(IF('Water Report'!$F$11>0,'Water Report'!$F$11,0)) -> 31 | AR4: =(IF('Water Report'!$F$13>0,'Water Report'!$F$13,0)) -> 32 | AS4: =(IF('Water Report'!$F$14>0,'Water Report'!$F$14,0)) -> 17 | AT4: =(IF('Water Report'!$F$15>0,'Water Report'!$F$15,0)) -> 7 | AU4: =(IF('Water Report'!$F$17>0,'Water Report'!$F$17,0)) -> 0 | AV4: =(IF('Water Report'!$F$18>0,'Water Report'!$F$18,0)) -> 12 | AW4: =(IF('Water Report'!$F$19>0,'Water Report'!$F$19,0)) -> 6 | AX4: =(IF('Water Report'!$F$21>0,'Water Report'!$F$21,0)) -> 43 | AY4: =(IF('Water Report'!$F$22>0,'Water Report'!$F$22,0)) -> 0 | AZ4: =(IF('Water Report'!$F$23>0,'Water Report'!$F$23,0)) -> 0.3 | BA4: =(IF('Water Report'!$F$14>0,'Water Report'!$F$14,0)) -> 17 | BB4: =(IF('Water Report'!$F$15>0,'Water Report'!$F$15,0)) -> 7 | BC4: =(IF('Water Report'!$F$13>0,'Water Report'!$F$13,0)) -> 32 | BD4: =(IF('Water Report'!$F$24>0,'Water Report'!$F$24,0)) -> 210 | BE4: =(IF('Water Report'!$F$25>0,'Water Report'!$F$25,0)) -> 187 | BF4: =(IF('Water Report'!$F$27>0,'Water Report'!$F$27,0)) -> 75.3 | BG4: =(IF('Section Load'!AN7>0,'Section Load'!AN7,0)) -> 940.268 | BH4: =(IF('Section Load'!AO7>0,'Section Load'!AO7,0)) -> 301.72 | BI4: =(IF('Section Load'!AP7>0,'Section Load'!AP7,0)) -> 0 | BJ4: =(IF('Section Load'!AQ7>0,'Section Load'!AQ7,0)) -> 76.54 | BK4: =(IF('Section Load'!AR7>0,'Section Load'!AR7,0)) -> 41.7 | BL4: =(IF('Section Load'!AS7>0,'Section Load'!AS7,0)) -> 5.5 | BM4: =(IF('Section Load'!AT7>0,'Section Load'!AT7,0)) -> 514.808
A5: Mumbai | B5: =B4+1 -> 4 | C5: 7 | D5: 2021 | E5: =(IF('Section Load'!F8>0,'Section Load'!F8,0)) -> 2968.9 | F5: =(IF('Section Load'!G8>0,'Section Load'!G8,0)) -> 1478.64 | G5: =(IF('Section Load'!H8>0,'Section Load'!H8,0)) -> 1792.89 | H5: =(IF('Section Load'!I8>0,'Section Load'!I8,0)) -> 3681.6 | I5: =(IF('Section Load'!J8>0,'Section Load'!J8,0)) -> 6765.84 | J5: =(IF('Section Load'!K8>0,'Section Load'!K8,0)) -> 2614 | K5: =(IF('Section Load'!L8>0,'Section Load'!L8,0)) -> 1085.93 | L5: =(IF('Section Load'!M8>0,'Section Load'!M8,0)) -> 713.35 | ... AL5: =(IF('Section Load'!AM8>0,'Section Load'!AM8,0)) -> 844 | AM5: =(IF('Water Report'!$G$7>0,'Water Report'!$F$7,0)) -> 123 | AN5: =(IF('Water Report'!$G$8>0,'Water Report'!$F$8,0)) -> 85 | AO5: =(IF('Water Report'!$G$9>0,'Water Report'!$H$9,0)) -> 120 | AP5: =(IF('Water Report'!$G$10>0,'Water Report'!$G$10,0)) -> 39 | AQ5: =(IF('Water Report'!$G$11>0,'Water Report'!$G$11,0)) -> 32 | AR5: =(IF('Water Report'!$G$13>0,'Water Report'!$G$13,0)) -> 38 | AS5: =(IF('Water Report'!$G$14>0,'Water Report'!$G$14,0)) -> 28 | AT5: =(IF('Water Report'!$G$15>0,'Water Report'!$G$15,0)) -> 10 | AU5: =(IF('Water Report'!$G$17>0,'Water Report'!$G$17,0)) -> 0 | AV5: =(IF('Water Report'!$G$18>0,'Water Report'!$G$18,0)) -> 11 | AW5: =(IF('Water Report'!$G$19>0,'Water Report'!$G$19,0)) -> 5 | AX5: =(IF('Water Report'!$G$21>0,'Water Report'!$G$21,0)) -> 52 | AY5: =(IF('Water Report'!$G$22>0,'Water Report'!$G$22,0)) -> 50 | AZ5: =(IF('Water Report'!$G$23>0,'Water Report'!$G$23,0)) -> 0 | BA5: =(IF('Water Report'!$G$14>0,'Water Report'!$G$14,0)) -> 28 | BB5: =(IF('Water Report'!$G$15>0,'Water Report'!$G$15,0)) -> 10 | BC5: =(IF('Water Report'!$G$13>0,'Water Report'!$G$13,0)) -> 38 | BD5: =(IF('Water Report'!$G$24>0,'Water Report'!$G$24,0)) -> 271 | BE5: =(IF('Water Report'!$G$25>0,'Water Report'!$G$25,0)) -> 256 | BF5: =(IF('Water Report'!$G$27>0,'Water Report'!$G$27,0)) -> 90 | BG5: =(IF('Section Load'!AN8>0,'Section Load'!AN8,0)) -> 786.88 | BH5: =(IF('Section Load'!AO8>0,'Section Load'!AO8,0)) -> 327.73 | BI5: =(IF('Section Load'!AP8>0,'Section Load'!AP8,0)) -> 0 | BJ5: =(IF('Section Load'!AQ8>0,'Section Load'!AQ8,0)) -> 79.53 | BK5: =(IF('Section Load'!AR8>0,'Section Load'!AR8,0)) -> 37.4 | BL5: =(IF('Section Load'!AS8>0,'Section Load'!AS8,0)) -> 1.5 | BM5: =(IF('Section Load'!AT8>0,'Section Load'!AT8,0)) -> 340.72
A6: Mumbai | B6: =B5+1 -> 5 | C6: 7 | D6: 2021 | E6: =(IF('Section Load'!F9>0,'Section Load'!F9,0)) -> 2828.7 | F6: =(IF('Section Load'!G9>0,'Section Load'!G9,0)) -> 1447.68 | G6: =(IF('Section Load'!H9>0,'Section Load'!H9,0)) -> 1640.5 | H6: =(IF('Section Load'!I9>0,'Section Load'!I9,0)) -> 3669.36 | I6: =(IF('Section Load'!J9>0,'Section Load'!J9,0)) -> 6521.66 | J6: =(IF('Section Load'!K9>0,'Section Load'!K9,0)) -> 2554.7 | K6: =(IF('Section Load'!L9>0,'Section Load'!L9,0)) -> 1002.13 | L6: =(IF('Section Load'!M9>0,'Section Load'!M9,0)) -> 728.13 | ... AL6: =(IF('Section Load'!AM9>0,'Section Load'!AM9,0)) -> 825 | AM6: =(IF('Water Report'!$H$7>0,'Water Report'!$H$7,0)) -> 123 | AN6: =(IF('Water Report'!$H$8>0,'Water Report'!$H$8,0)) -> 124 | AO6: =(IF('Water Report'!$H$9>0,'Water Report'!$H$9,0)) -> 120 | AP6: =(IF('Water Report'!$H$10>0,'Water Report'!$H$10,0)) -> 12 | AQ6: =(IF('Water Report'!$H$11>0,'Water Report'!$H$11,0)) -> 18 | AR6: =(IF('Water Report'!$H$13>0,'Water Report'!$H$13,0)) -> 31 | AS6: =(IF('Water Report'!$H$14>0,'Water Report'!$H$14,0)) -> 8 | AT6: =(IF('Water Report'!$H$15>0,'Water Report'!$H$15,0)) -> 3 | AU6: =(IF('Water Report'!$H$17>0,'Water Report'!$H$17,0)) -> 40 | AV6: =(IF('Water Report'!$H$18>0,'Water Report'!$H$18,0)) -> 10 | AW6: =(IF('Water Report'!$H$19>0,'Water Report'!$H$19,0)) -> 5 | AX6: =(IF('Water Report'!$H$21>0,'Water Report'!$H$21,0)) -> 155 | AY6: =(IF('Water Report'!$H$22>0,'Water Report'!$H$22,0)) -> 25 | AZ6: =(IF('Water Report'!$H$23>0,'Water Report'!$H$23,0)) -> 0 | BA6: =(IF('Water Report'!$H$14>0,'Water Report'!$H$14,0)) -> 8 | BB6: =(IF('Water Report'!$H$15>0,'Water Report'!$H$15,0)) -> 3 | BC6: =(IF('Water Report'!$H$13>0,'Water Report'!$H$13,0)) -> 31 | BD6: =(IF('Water Report'!$H$24>0,'Water Report'!$H$24,0)) -> 241 | BE6: =(IF('Water Report'!$H$25>0,'Water Report'!$H$25,0)) -> 161 | BF6: =(IF('Water Report'!$H$27>0,'Water Report'!$H$27,0)) -> 186 | BG6: =(IF('Section Load'!AN9>0,'Section Load'!AN9,0)) -> 925.06 | BH6: =(IF('Section Load'!AO9>0,'Section Load'!AO9,0)) -> 265.82 | BI6: =(IF('Section Load'!AP9>0,'Section Load'!AP9,0)) -> 0 | BJ6: =(IF('Section Load'!AQ9>0,'Section Load'!AQ9,0)) -> 61.29 | BK6: =(IF('Section Load'!AR9>0,'Section Load'!AR9,0)) -> 27 | BL6: =(IF('Section Load'!AS9>0,'Section Load'!AS9,0)) -> 0.9 | BM6: =(IF('Section Load'!AT9>0,'Section Load'!AT9,0)) -> 570.05
A7: Mumbai | B7: =B6+1 -> 6 | C7: 7 | D7: 2021 | E7: =(IF('Section Load'!F10>0,'Section Load'!F10,0)) -> 2786.2 | F7: =(IF('Section Load'!G10>0,'Section Load'!G10,0)) -> 1525.26 | G7: =(IF('Section Load'!H10>0,'Section Load'!H10,0)) -> 1382.5 | H7: =(IF('Section Load'!I10>0,'Section Load'!I10,0)) -> 3628.76 | I7: =(IF('Section Load'!J10>0,'Section Load'!J10,0)) -> 5789.63 | J7: =(IF('Section Load'!K10>0,'Section Load'!K10,0)) -> 2584.9 | K7: =(IF('Section Load'!L10>0,'Section Load'!L10,0)) -> 959.02 | L7: =(IF('Section Load'!M10>0,'Section Load'!M10,0)) -> 727.79 | ... AL7: =(IF('Section Load'!AM10>0,'Section Load'!AM10,0)) -> 809 | AM7: =(IF('Water Report'!$I$7>0,'Water Report'!$I$7,0)) -> 44 | AN7: =(IF('Water Report'!$I$8>0,'Water Report'!$I$8,0)) -> 91 | AO7: =(IF('Water Report'!$I$9>0,'Water Report'!$I$9,0)) -> 59 | AP7: =(IF('Water Report'!$I$10>0,'Water Report'!$I$10,0)) -> 18 | AQ7: =(IF('Water Report'!$I$11>0,'Water Report'!$I$11,0)) -> 21 | AR7: =(IF('Water Report'!$I$13>0,'Water Report'!$I$13,0)) -> 36 | AS7: =(IF('Water Report'!$I$14>0,'Water Report'!$I$14,0)) -> 11 | AT7: =(IF('Water Report'!$I$15>0,'Water Report'!$I$15,0)) -> 5 | AU7: =(IF('Water Report'!$I$17>0,'Water Report'!$I$17,0)) -> 30 | AV7: =(IF('Water Report'!$I$18>0,'Water Report'!$I$18,0)) -> 0 | AW7: =(IF('Water Report'!$I$19>0,'Water Report'!$I$19,0)) -> 0 | AX7: =(IF('Water Report'!$I$21>0,'Water Report'!$I$21,0)) -> 65 | AY7: =(IF('Water Report'!$I$22>0,'Water Report'!$I$22,0)) -> 22 | AZ7: =(IF('Water Report'!$I$23>0,'Water Report'!$I$23,0)) -> 0 | BA7: =(IF('Water Report'!$I$14>0,'Water Report'!$I$14,0)) -> 11 | BB7: =(IF('Water Report'!$I$15>0,'Water Report'!$I$15,0)) -> 5 | BC7: =(IF('Water Report'!$I$13>0,'Water Report'!$I$13,0)) -> 36 | BD7: =(IF('Water Report'!$I$24>0,'Water Report'!$I$24,0)) -> 149 | BE7: =(IF('Water Report'!$I$25>0,'Water Report'!$I$25,0)) -> 114 | BF7: =(IF('Water Report'!$I$27>0,'Water Report'!$I$27,0)) -> 101 | BG7: =(IF('Section Load'!AN10>0,'Section Load'!AN10,0)) -> 430.96 | BH7: =(IF('Section Load'!AO10>0,'Section Load'!AO10,0)) -> 261.84 | BI7: =(IF('Section Load'!AP10>0,'Section Load'!AP10,0)) -> 0 | BJ7: =(IF('Section Load'!AQ10>0,'Section Load'!AQ10,0)) -> 67.13 | BK7: =(IF('Section Load'!AR10>0,'Section Load'!AR10,0)) -> 35.2 | BL7: =(IF('Section Load'!AS10>0,'Section Load'!AS10,0)) -> 1 | BM7: =(IF('Section Load'!AT10>0,'Section Load'!AT10,0)) -> 65.79
A8: Mumbai | B8: =B7+1 -> 7 | C8: 7 | D8: 2021 | E8: =(IF('Section Load'!F11>0,'Section Load'!F11,0)) -> 2919.2 | F8: =(IF('Section Load'!G11>0,'Section Load'!G11,0)) -> 1587.74 | G8: =(IF('Section Load'!H11>0,'Section Load'!H11,0)) -> 1549.24 | H8: =(IF('Section Load'!I11>0,'Section Load'!I11,0)) -> 3603.4 | I8: =(IF('Section Load'!J11>0,'Section Load'!J11,0)) -> 6831.79 | J8: =(IF('Section Load'!K11>0,'Section Load'!K11,0)) -> 2722.7 | K8: =(IF('Section Load'!L11>0,'Section Load'!L11,0)) -> 1261.92 | L8: =(IF('Section Load'!M11>0,'Section Load'!M11,0)) -> 820.85 | ... AL8: =(IF('Section Load'!AM11>0,'Section Load'!AM11,0)) -> 792 | AM8: =(IF('Water Report'!$J$7>0,'Water Report'!$J$7,0)) -> 77 | AN8: =(IF('Water Report'!$J$8>0,'Water Report'!$J$8,0)) -> 113 | AO8: =(IF('Water Report'!$J$9>0,'Water Report'!$J$9,0)) -> 76 | AP8: =(IF('Water Report'!$J$10>0,'Water Report'!$J$10,0)) -> 15 | AQ8: =(IF('Water Report'!$J$11>0,'Water Report'!$J$11,0)) -> 22 | AR8: =(IF('Water Report'!$J$13>0,'Water Report'!$J$13,0)) -> 18 | AS8: =(IF('Water Report'!$J$14>0,'Water Report'!$J$14,0)) -> 10 | AT8: =(IF('Water Report'!$J$15>0,'Water Report'!$J$15,0)) -> 12 | AU8: =(IF('Water Report'!$J$17>0,'Water Report'!$J$17,0)) -> 0 | AV8: =(IF('Water Report'!$J$18>0,'Water Report'!$J$18,0)) -> 11 | AW8: =(IF('Water Report'!$J$19>0,'Water Report'!$J$19,0)) -> 5 | AX8: =(IF('Water Report'!$J$21>0,'Water Report'!$J$21,0)) -> 74 | AY8: =(IF('Water Report'!$J$22>0,'Water Report'!$J$22,0)) -> 25 | AZ8: =(IF('Water Report'!$J$23>0,'Water Report'!$J$23,0)) -> 0 | BA8: =(IF('Water Report'!$J$14>0,'Water Report'!$J$14,0)) -> 10 | BB8: =(IF('Water Report'!$J$15>0,'Water Report'!$J$15,0)) -> 12 | BC8: =(IF('Water Report'!$J$13>0,'Water Report'!$J$13,0)) -> 18 | BD8: =(IF('Water Report'!$J$24>0,'Water Report'!$J$24,0)) -> 168 | BE8: =(IF('Water Report'!$J$25>0,'Water Report'!$J$25,0)) -> 135 | BF8: =(IF('Water Report'!$J$27>0,'Water Report'!$J$27,0)) -> 92 | BG8: =(IF('Section Load'!AN11>0,'Section Load'!AN11,0)) -> 850.19 | BH8: =(IF('Section Load'!AO11>0,'Section Load'!AO11,0)) -> 259.98 | BI8: =(IF('Section Load'!AP11>0,'Section Load'!AP11,0)) -> 0 | BJ8: =(IF('Section Load'!AQ11>0,'Section Load'!AQ11,0)) -> 79.42 | BK8: =(IF('Section Load'!AR11>0,'Section Load'!AR11,0)) -> 36.7 | BL8: =(IF('Section Load'!AS11>0,'Section Load'!AS11,0)) -> 1.4 | BM8: =(IF('Section Load'!AT11>0,'Section Load'!AT11,0)) -> 473.09
A9: Mumbai | B9: =B8+1 -> 8 | C9: 7 | D9: 2021 | E9: =(IF('Section Load'!F12>0,'Section Load'!F12,0)) -> 3141.7 | F9: =(IF('Section Load'!G12>0,'Section Load'!G12,0)) -> 1563.22 | G9: =(IF('Section Load'!H12>0,'Section Load'!H12,0)) -> 1545.16 | H9: =(IF('Section Load'!I12>0,'Section Load'!I12,0)) -> 3552.4 | I9: =(IF('Section Load'!J12>0,'Section Load'!J12,0)) -> 6741.32 | J9: =(IF('Section Load'!K12>0,'Section Load'!K12,0)) -> 2769 | K9: =(IF('Section Load'!L12>0,'Section Load'!L12,0)) -> 1089.63 | L9: =(IF('Section Load'!M12>0,'Section Load'!M12,0)) -> 674.63 | ... AL9: =(IF('Section Load'!AM12>0,'Section Load'!AM12,0)) -> 809 | AM9: =(IF('Water Report'!$K$7>0,'Water Report'!$K$7,0)) -> 81 | AN9: =(IF('Water Report'!$K$8>0,'Water Report'!$K$8,0)) -> 121 | AO9: =(IF('Water Report'!$K$9>0,'Water Report'!$K$9,0)) -> 80 | AP9: =(IF('Water Report'!$K$10>0,'Water Report'!$K$10,0)) -> 17 | AQ9: =(IF('Water Report'!$K$11>0,'Water Report'!$K$11,0)) -> 24 | AR9: =(IF('Water Report'!$K$13>0,'Water Report'!$K$13,0)) -> 20 | AS9: =(IF('Water Report'!$K$14>0,'Water Report'!$K$14,0)) -> 11 | AT9: =(IF('Water Report'!$K$15>0,'Water Report'!$K$15,0)) -> 8 | AU9: =(IF('Water Report'!$K$17>0,'Water Report'!$K$17,0)) -> 0 | AV9: =(IF('Water Report'!$K$18>0,'Water Report'!$K$18,0)) -> 7 | AW9: =(IF('Water Report'!$K$19>0,'Water Report'!$K$19,0)) -> 5 | AX9: =(IF('Water Report'!$K$21>0,'Water Report'!$K$21,0)) -> 79 | AY9: =(IF('Water Report'!$K$22>0,'Water Report'!$K$22,0)) -> 21 | AZ9: =(IF('Water Report'!$K$23>0,'Water Report'!$K$23,0)) -> 0 | BA9: =(IF('Water Report'!$K$14>0,'Water Report'!$K$14,0)) -> 11 | BB9: =(IF('Water Report'!$K$15>0,'Water Report'!$K$15,0)) -> 8 | BC9: =(IF('Water Report'!$K$13>0,'Water Report'!$K$13,0)) -> 20 | BD9: =(IF('Water Report'!$K$24>0,'Water Report'!$K$24,0)) -> 161 | BE9: =(IF('Water Report'!$K$25>0,'Water Report'!$K$25,0)) -> 140 | BF9: =(IF('Water Report'!$K$27>0,'Water Report'!$K$27,0)) -> 99 | BG9: =(IF('Section Load'!AN12>0,'Section Load'!AN12,0)) -> 821.55 | BH9: =(IF('Section Load'!AO12>0,'Section Load'!AO12,0)) -> 251.29 | BI9: =(IF('Section Load'!AP12>0,'Section Load'!AP12,0)) -> 0.4 | BJ9: =(IF('Section Load'!AQ12>0,'Section Load'!AQ12,0)) -> 86.58 | BK9: =(IF('Section Load'!AR12>0,'Section Load'!AR12,0)) -> 35.7 | BL9: =(IF('Section Load'!AS12>0,'Section Load'!AS12,0)) -> 2 | BM9: =(IF('Section Load'!AT12>0,'Section Load'!AT12,0)) -> 445.58
A10: Mumbai | B10: =B9+1 -> 9 | C10: 7 | D10: 2021 | E10: =(IF('Section Load'!F13>0,'Section Load'!F13,0)) -> 3259.27 | F10: =(IF('Section Load'!G13>0,'Section Load'!G13,0)) -> 1605.99 | G10: =(IF('Section Load'!H13>0,'Section Load'!H13,0)) -> 1594.71 | H10: =(IF('Section Load'!I13>0,'Section Load'!I13,0)) -> 3607.81 | I10: =(IF('Section Load'!J13>0,'Section Load'!J13,0)) -> 7248.81 | J10: =(IF('Section Load'!K13>0,'Section Load'!K13,0)) -> 2915.5 | K10: =(IF('Section Load'!L13>0,'Section Load'!L13,0)) -> 981.3 | L10: =(IF('Section Load'!M13>0,'Section Load'!M13,0)) -> 812.38 | ... AL10: =(IF('Section Load'!AM13>0,'Section Load'!AM13,0)) -> 856 | AM10: =(IF('Water Report'!$L$7>0,'Water Report'!$L$7,0)) -> 87 | AN10: =(IF('Water Report'!$L$8>0,'Water Report'!$L$8,0)) -> 91 | AO10: =(IF('Water Report'!$L$9>0,'Water Report'!$L$9,0)) -> 93 | AP10: =(IF('Water Report'!$L$10>0,'Water Report'!$L$10,0)) -> 19 | AQ10: =(IF('Water Report'!$L$11>0,'Water Report'!$L$11,0)) -> 24 | AR10: =(IF('Water Report'!$L$13>0,'Water Report'!$L$13,0)) -> 14 | AS10: =(IF('Water Report'!$L$14>0,'Water Report'!$L$14,0)) -> 12 | AT10: =(IF('Water Report'!$L$15>0,'Water Report'!$L$15,0)) -> 6 | AU10: =(IF('Water Report'!$L$17>0,'Water Report'!$L$17,0)) -> 0 | AV10: =(IF('Water Report'!$L$18>0,'Water Report'!$L$18,0)) -> 7 | AW10: =(IF('Water Report'!$L$19>0,'Water Report'!$L$19,0)) -> 6 | AX10: =(IF('Water Report'!$L$21>0,'Water Report'!$L$21,0)) -> 89 | AY10: =(IF('Water Report'!$L$22>0,'Water Report'!$L$22,0)) -> 26 | AZ10: =(IF('Water Report'!$L$23>0,'Water Report'!$L$23,0)) -> 0 | BA10: =(IF('Water Report'!$L$14>0,'Water Report'!$L$14,0)) -> 12 | BB10: =(IF('Water Report'!$L$15>0,'Water Report'!$L$15,0)) -> 6 | BC10: =(IF('Water Report'!$L$13>0,'Water Report'!$L$13,0)) -> 14 | BD10: =(IF('Water Report'!$L$24>0,'Water Report'!$L$24,0)) -> 191 | BE10: =(IF('Water Report'!$L$25>0,'Water Report'!$L$25,0)) -> 154 | BF10: =(IF('Water Report'!$L$27>0,'Water Report'!$L$27,0)) -> 103 | BG10: =(IF('Section Load'!AN13>0,'Section Load'!AN13,0)) -> 830.84 | BH10: =(IF('Section Load'!AO13>0,'Section Load'!AO13,0)) -> 315.87 | BI10: =(IF('Section Load'!AP13>0,'Section Load'!AP13,0)) -> 0 | BJ10: =(IF('Section Load'!AQ13>0,'Section Load'!AQ13,0)) -> 98.09 | BK10: =(IF('Section Load'!AR13>0,'Section Load'!AR13,0)) -> 37.8 | BL10: =(IF('Section Load'!AS13>0,'Section Load'!AS13,0)) -> 2.8 | BM10: =(IF('Section Load'!AT13>0,'Section Load'!AT13,0)) -> 376.28
A11: Mumbai | B11: =B10+1 -> 10 | C11: 7 | D11: 2021 | E11: =(IF('Section Load'!F14>0,'Section Load'!F14,0)) -> 3138 | F11: =(IF('Section Load'!G14>0,'Section Load'!G14,0)) -> 1601 | G11: =(IF('Section Load'!H14>0,'Section Load'!H14,0)) -> 1644 | H11: =(IF('Section Load'!I14>0,'Section Load'!I14,0)) -> 3580.33 | I11: =(IF('Section Load'!J14>0,'Section Load'!J14,0)) -> 6097 | J11: =(IF('Section Load'!K14>0,'Section Load'!K14,0)) -> 2543 | K11: =(IF('Section Load'!L14>0,'Section Load'!L14,0)) -> 1093 | L11: =(IF('Section Load'!M14>0,'Section Load'!M14,0)) -> 769 | ... AL11: =(IF('Section Load'!AM14>0,'Section Load'!AM14,0)) -> 785 | AM11: =(IF('Water Report'!$M$7>0,'Water Report'!$M$7,0)) -> 121 | AN11: =(IF('Water Report'!$M$8>0,'Water Report'!$M$8,0)) -> 96 | AO11: =(IF('Water Report'!$M$9>0,'Water Report'!$M$9,0)) -> 76 | AP11: =(IF('Water Report'!$M$10>0,'Water Report'!$M$10,0)) -> 26 | AQ11: =(IF('Water Report'!$M$11>0,'Water Report'!$M$11,0)) -> 35 | AR11: =(IF('Water Report'!$M$13>0,'Water Report'!$M$13,0)) -> 25 | AS11: =(IF('Water Report'!$M$14>0,'Water Report'!$M$14,0)) -> 22 | AT11: =(IF('Water Report'!$M$15>0,'Water Report'!$M$15,0)) -> 22 | AU11: =(IF('Water Report'!$M$17>0,'Water Report'!$M$17,0)) -> 0 | AV11: =(IF('Water Report'!$M$18>0,'Water Report'!$M$18,0)) -> 11 | AW11: =(IF('Water Report'!$M$19>0,'Water Report'!$M$19,0)) -> 5 | AX11: =(IF('Water Report'!$M$21>0,'Water Report'!$M$21,0)) -> 87 | AY11: =(IF('Water Report'!$M$22>0,'Water Report'!$M$22,0)) -> 14 | AZ11: =(IF('Water Report'!$M$23>0,'Water Report'!$M$23,0)) -> 0 | BA11: =(IF('Water Report'!$M$14>0,'Water Report'!$M$14,0)) -> 22 | BB11: =(IF('Water Report'!$M$15>0,'Water Report'!$M$15,0)) -> 22 | BC11: =(IF('Water Report'!$M$13>0,'Water Report'!$M$13,0)) -> 25 | BD11: =(IF('Water Report'!$M$24>0,'Water Report'!$M$24,0)) -> 218 | BE11: =(IF('Water Report'!$M$25>0,'Water Report'!$M$25,0)) -> 181 | BF11: =(IF('Water Report'!$M$27>0,'Water Report'!$M$27,0)) -> 112 | BG11: =(IF('Section Load'!AN14>0,'Section Load'!AN14,0)) -> 829 | BH11: =(IF('Section Load'!AO14>0,'Section Load'!AO14,0)) -> 223 | BI11: =(IF('Section Load'!AP14>0,'Section Load'!AP14,0)) -> 0 | BJ11: =(IF('Section Load'!AQ14>0,'Section Load'!AQ14,0)) -> 102 | BK11: =(IF('Section Load'!AR14>0,'Section Load'!AR14,0)) -> 44 | BL11: =(IF('Section Load'!AS14>0,'Section Load'!AS14,0)) -> 8 | BM11: =(IF('Section Load'!AT14>0,'Section Load'!AT14,0)) -> 452
A12: Mumbai | B12: =B11+1 -> 11 | C12: 7 | D12: 2021 | E12: =(IF('Section Load'!F15>0,'Section Load'!F15,0)) -> 2956.03 | F12: =(IF('Section Load'!G15>0,'Section Load'!G15,0)) -> 1589.75 | G12: =(IF('Section Load'!H15>0,'Section Load'!H15,0)) -> 1661.79 | H12: =(IF('Section Load'!I15>0,'Section Load'!I15,0)) -> 3609.26 | I12: =(IF('Section Load'!J15>0,'Section Load'!J15,0)) -> 7134.06 | J12: =(IF('Section Load'!K15>0,'Section Load'!K15,0)) -> 2942.4 | K12: =(IF('Section Load'!L15>0,'Section Load'!L15,0)) -> 1216.55 | L12: =(IF('Section Load'!M15>0,'Section Load'!M15,0)) -> 1013.21 | ... AL12: =(IF('Section Load'!AM15>0,'Section Load'!AM15,0)) -> 784 | AM12: =(IF('Water Report'!$N$7>0,'Water Report'!$N$7,0)) -> 129 | AN12: =(IF('Water Report'!$N$8>0,'Water Report'!$N$8,0)) -> 163 | AO12: =(IF('Water Report'!$N$9>0,'Water Report'!$N$9,0)) -> 77 | AP12: =(IF('Water Report'!$N$10>0,'Water Report'!$N$10,0)) -> 32 | AQ12: =(IF('Water Report'!$N$11>0,'Water Report'!$N$11,0)) -> 41 | AR12: =(IF('Water Report'!$N$13>0,'Water Report'!$N$13,0)) -> 17 | AS12: =(IF('Water Report'!$N$14>0,'Water Report'!$N$14,0)) -> 17 | AT12: =(IF('Water Report'!$N$15>0,'Water Report'!$N$15,0)) -> 9 | AU12: =(IF('Water Report'!$N$17>0,'Water Report'!$N$17,0)) -> 0 | AV12: =(IF('Water Report'!$N$18>0,'Water Report'!$N$18,0)) -> 12 | AW12: =(IF('Water Report'!$N$19>0,'Water Report'!$N$19,0)) -> 5 | AX12: =(IF('Water Report'!$N$21>0,'Water Report'!$N$21,0)) -> 65 | AY12: =(IF('Water Report'!$N$22>0,'Water Report'!$N$22,0)) -> 24 | AZ12: =(IF('Water Report'!$N$23>0,'Water Report'!$N$23,0)) -> 0 | BA12: =(IF('Water Report'!$N$14>0,'Water Report'!$N$14,0)) -> 17 | BB12: =(IF('Water Report'!$N$15>0,'Water Report'!$N$15,0)) -> 9 | BC12: =(IF('Water Report'!$N$13>0,'Water Report'!$N$13,0)) -> 17 | BD12: =(IF('Water Report'!$N$24>0,'Water Report'!$N$24,0)) -> 240 | BE12: =(IF('Water Report'!$N$25>0,'Water Report'!$N$25,0)) -> 176 | BF12: =(IF('Water Report'!$N$27>0,'Water Report'!$N$27,0)) -> 82 | BG12: =(IF('Section Load'!AN15>0,'Section Load'!AN15,0)) -> 986.41 | BH12: =(IF('Section Load'!AO15>0,'Section Load'!AO15,0)) -> 295.88 | BI12: =(IF('Section Load'!AP15>0,'Section Load'!AP15,0)) -> 0 | BJ12: =(IF('Section Load'!AQ15>0,'Section Load'!AQ15,0)) -> 89.91 | BK12: =(IF('Section Load'!AR15>0,'Section Load'!AR15,0)) -> 46.8 | BL12: =(IF('Section Load'!AS15>0,'Section Load'!AS15,0)) -> 4.7 | BM12: =(IF('Section Load'!AT15>0,'Section Load'!AT15,0)) -> 549.12
A13: Mumbai | B13: =B12+1 -> 12 | C13: 7 | D13: 2021 | E13: =(IF('Section Load'!F16>0,'Section Load'!F16,0)) -> 3001.4 | F13: =(IF('Section Load'!G16>0,'Section Load'!G16,0)) -> 1595.12 | G13: =(IF('Section Load'!H16>0,'Section Load'!H16,0)) -> 1595.2 | H13: =(IF('Section Load'!I16>0,'Section Load'!I16,0)) -> 3711.74 | I13: =(IF('Section Load'!J16>0,'Section Load'!J16,0)) -> 6204.24 | J13: =(IF('Section Load'!K16>0,'Section Load'!K16,0)) -> 2563.2 | K13: =(IF('Section Load'!L16>0,'Section Load'!L16,0)) -> 1103.56 | L13: =(IF('Section Load'!M16>0,'Section Load'!M16,0)) -> 695.77 | ... AL13: =(IF('Section Load'!AM16>0,'Section Load'!AM16,0)) -> 767 | AM13: =(IF('Water Report'!$O$7>0,'Water Report'!$O$7,0)) -> 95 | AN13: =(IF('Water Report'!$O$8>0,'Water Report'!$O$8,0)) -> 131 | AO13: =(IF('Water Report'!$O$9>0,'Water Report'!$O$9,0)) -> 91 | AP13: =(IF('Water Report'!$O$10>0,'Water Report'!$O$10,0)) -> 22 | AQ13: =(IF('Water Report'!$O$11>0,'Water Report'!$O$11,0)) -> 21 | AR13: =(IF('Water Report'!$O$13>0,'Water Report'!$O$13,0)) -> 71 | AS13: =(IF('Water Report'!$O$14>0,'Water Report'!$O$14,0)) -> 16 | AT13: =(IF('Water Report'!$O$15>0,'Water Report'!$O$15,0)) -> 11 | AU13: =(IF('Water Report'!$O$17>0,'Water Report'!$O$17,0)) -> 0 | AV13: =(IF('Water Report'!$O$18>0,'Water Report'!$O$18,0)) -> 14 | AW13: =(IF('Water Report'!$O$19>0,'Water Report'!$O$19,0)) -> 5 | AX13: =(IF('Water Report'!$O$21>0,'Water Report'!$O$21,0)) -> 64 | AY13: =(IF('Water Report'!$O$22>0,'Water Report'!$O$22,0)) -> 70 | AZ13: =(IF('Water Report'!$O$23>0,'Water Report'!$O$23,0)) -> 0 | BA13: =(IF('Water Report'!$O$14>0,'Water Report'!$O$14,0)) -> 16 | BB13: =(IF('Water Report'!$O$15>0,'Water Report'!$O$15,0)) -> 11 | BC13: =(IF('Water Report'!$O$13>0,'Water Report'!$O$13,0)) -> 71 | BD13: =(IF('Water Report'!$O$24>0,'Water Report'!$O$24,0)) -> 186 | BE13: =(IF('Water Report'!$O$25>0,'Water Report'!$O$25,0)) -> 161 | BF13: =(IF('Water Report'!$O$27>0,'Water Report'!$O$27,0)) -> 135 | BG13: =(IF('Section Load'!AN16>0,'Section Load'!AN16,0)) -> 914.79 | BH13: =(IF('Section Load'!AO16>0,'Section Load'!AO16,0)) -> 267.13 | BI13: =(IF('Section Load'!AP16>0,'Section Load'!AP16,0)) -> 0 | BJ13: =(IF('Section Load'!AQ16>0,'Section Load'!AQ16,0)) -> 104.32 | BK13: =(IF('Section Load'!AR16>0,'Section Load'!AR16,0)) -> 35.4 | BL13: =(IF('Section Load'!AS16>0,'Section Load'!AS16,0)) -> 4.2 | BM13: =(IF('Section Load'!AT16>0,'Section Load'!AT16,0)) -> 504.14
A14: Mumbai | B14: =B13+1 -> 13 | C14: 7 | D14: 2021 | E14: =(IF('Section Load'!F17>0,'Section Load'!F17,0)) -> 2899.57 | F14: =(IF('Section Load'!G17>0,'Section Load'!G17,0)) -> 1577.13 | G14: =(IF('Section Load'!H17>0,'Section Load'!H17,0)) -> 1632.01 | H14: =(IF('Section Load'!I17>0,'Section Load'!I17,0)) -> 3726 | I14: =(IF('Section Load'!J17>0,'Section Load'!J17,0)) -> 6191.81 | J14: =(IF('Section Load'!K17>0,'Section Load'!K17,0)) -> 2552.73 | K14: =(IF('Section Load'!L17>0,'Section Load'!L17,0)) -> 1162.89 | L14: =(IF('Section Load'!M17>0,'Section Load'!M17,0)) -> 969.02 | ... AL14: =(IF('Section Load'!AM17>0,'Section Load'!AM17,0)) -> 787 | AM14: =(IF('Water Report'!$P$7>0,'Water Report'!$P$7,0)) -> 91 | AN14: =(IF('Water Report'!$P$8>0,'Water Report'!$P$8,0)) -> 106 | AO14: =(IF('Water Report'!$P$9>0,'Water Report'!$P$9,0)) -> 101 | AP14: =(IF('Water Report'!$P$10>0,'Water Report'!$P$10,0)) -> 15 | AQ14: =(IF('Water Report'!$P$11>0,'Water Report'!$P$11,0)) -> 24 | AR14: =(IF('Water Report'!$P$13>0,'Water Report'!$P$13,0)) -> 17 | AS14: =(IF('Water Report'!$P$14>0,'Water Report'!$P$14,0)) -> 11 | AT14: =(IF('Water Report'!$P$15>0,'Water Report'!$P$15,0)) -> 4 | AU14: =(IF('Water Report'!$P$17>0,'Water Report'!$P$17,0)) -> 0 | AV14: =(IF('Water Report'!$P$18>0,'Water Report'!$P$18,0)) -> 23 | AW14: =(IF('Water Report'!$P$19>0,'Water Report'!$P$19,0)) -> 5 | AX14: =(IF('Water Report'!$P$21>0,'Water Report'!$P$21,0)) -> 65 | AY14: =(IF('Water Report'!$P$22>0,'Water Report'!$P$22,0)) -> 26 | AZ14: =(IF('Water Report'!$P$23>0,'Water Report'!$P$23,0)) -> 0 | BA14: =(IF('Water Report'!$P$14>0,'Water Report'!$P$14,0)) -> 11 | BB14: =(IF('Water Report'!$P$15>0,'Water Report'!$P$15,0)) -> 4 | BC14: =(IF('Water Report'!$P$13>0,'Water Report'!$P$13,0)) -> 17 | BD14: =(IF('Water Report'!$P$24>0,'Water Report'!$P$24,0)) -> 202 | BE14: =(IF('Water Report'!$P$25>0,'Water Report'!$P$25,0)) -> 155 | BF14: =(IF('Water Report'!$P$27>0,'Water Report'!$P$27,0)) -> 82 | BG14: =(IF('Section Load'!AN17>0,'Section Load'!AN17,0)) -> 943.8 | BH14: =(IF('Section Load'!AO17>0,'Section Load'!AO17,0)) -> 254.99 | BI14: =(IF('Section Load'!AP17>0,'Section Load'!AP17,0)) -> 0 | BJ14: =(IF('Section Load'!AQ17>0,'Section Load'!AQ17,0)) -> 94.77 | BK14: =(IF('Section Load'!AR17>0,'Section Load'!AR17,0)) -> 41.8 | BL14: =(IF('Section Load'!AS17>0,'Section Load'!AS17,0)) -> 6.1 | BM14: =(IF('Section Load'!AT17>0,'Section Load'!AT17,0)) -> 546.14
A15: Mumbai | B15: =B14+1 -> 14 | C15: 7 | D15: 2021 | E15: =(IF('Section Load'!F18>0,'Section Load'!F18,0)) -> 2878.47 | F15: =(IF('Section Load'!G18>0,'Section Load'!G18,0)) -> 1649.35 | G15: =(IF('Section Load'!H18>0,'Section Load'!H18,0)) -> 1585.79 | H15: =(IF('Section Load'!I18>0,'Section Load'!I18,0)) -> 3716.46 | I15: =(IF('Section Load'!J18>0,'Section Load'!J18,0)) -> 6122.54 | J15: =(IF('Section Load'!K18>0,'Section Load'!K18,0)) -> 2640.3 | K15: =(IF('Section Load'!L18>0,'Section Load'!L18,0)) -> 1781.57 | L15: =(IF('Section Load'!M18>0,'Section Load'!M18,0)) -> 950.38 | ... AL15: =(IF('Section Load'!AM18>0,'Section Load'!AM18,0)) -> 765 | AM15: =(IF('Water Report'!$Q$7>0,'Water Report'!$Q$7,0)) -> 87 | AN15: =(IF('Water Report'!$Q$8>0,'Water Report'!$Q$8,0)) -> 99 | AO15: =(IF('Water Report'!$Q$9>0,'Water Report'!$Q$9,0)) -> 74 | AP15: =(IF('Water Report'!$Q$10>0,'Water Report'!$Q$10,0)) -> 24 | AQ15: =(IF('Water Report'!$Q$11>0,'Water Report'!$Q$11,0)) -> 22 | AR15: =(IF('Water Report'!$Q$13>0,'Water Report'!$Q$13,0)) -> 22 | AS15: =(IF('Water Report'!$Q$14>0,'Water Report'!$Q$14,0)) -> 10 | AT15: =(IF('Water Report'!$Q$15>0,'Water Report'!$Q$15,0)) -> 16 | AU15: =(IF('Water Report'!$Q$17>0,'Water Report'!$Q$17,0)) -> 0 | AV15: =(IF('Water Report'!$Q$18>0,'Water Report'!$Q$18,0)) -> 10 | AW15: =(IF('Water Report'!$Q$19>0,'Water Report'!$Q$19,0)) -> 4 | AX15: =(IF('Water Report'!$Q$21>0,'Water Report'!$Q$21,0)) -> 65 | AY15: =(IF('Water Report'!$Q$22>0,'Water Report'!$Q$22,0)) -> 13 | AZ15: =(IF('Water Report'!$Q$23>0,'Water Report'!$Q$23,0)) -> 0 | BA15: =(IF('Water Report'!$Q$14>0,'Water Report'!$Q$14,0)) -> 10 | BB15: =(IF('Water Report'!$Q$15>0,'Water Report'!$Q$15,0)) -> 16 | BC15: =(IF('Water Report'!$Q$13>0,'Water Report'!$Q$13,0)) -> 22 | BD15: =(IF('Water Report'!$Q$24>0,'Water Report'!$Q$24,0)) -> 205 | BE15: =(IF('Water Report'!$Q$25>0,'Water Report'!$Q$25,0)) -> 146 | BF15: =(IF('Water Report'!$Q$27>0,'Water Report'!$Q$27,0)) -> 87 | BG15: =(IF('Section Load'!AN18>0,'Section Load'!AN18,0)) -> 797.81 | BH15: =(IF('Section Load'!AO18>0,'Section Load'!AO18,0)) -> 251.74 | BI15: =(IF('Section Load'!AP18>0,'Section Load'!AP18,0)) -> 0.4 | BJ15: =(IF('Section Load'!AQ18>0,'Section Load'!AQ18,0)) -> 119.19 | BK15: =(IF('Section Load'!AR18>0,'Section Load'!AR18,0)) -> 45.3 | BL15: =(IF('Section Load'!AS18>0,'Section Load'!AS18,0)) -> 3.7 | BM15: =(IF('Section Load'!AT18>0,'Section Load'!AT18,0)) -> 377.48
A16: Mumbai | B16: =B15+1 -> 15 | C16: 7 | D16: 2021 | E16: =(IF('Section Load'!F19>0,'Section Load'!F19,0)) -> 2947.52 | F16: =(IF('Section Load'!G19>0,'Section Load'!G19,0)) -> 1595.38 | G16: =(IF('Section Load'!H19>0,'Section Load'!H19,0)) -> 1645.37 | H16: =(IF('Section Load'!I19>0,'Section Load'!I19,0)) -> 3733.81 | I16: =(IF('Section Load'!J19>0,'Section Load'!J19,0)) -> 6384.17 | J16: =(IF('Section Load'!K19>0,'Section Load'!K19,0)) -> 2774.3 | K16: =(IF('Section Load'!L19>0,'Section Load'!L19,0)) -> 1449.7 | L16: =(IF('Section Load'!M19>0,'Section Load'!M19,0)) -> 1106.87 | ... AL16: =(IF('Section Load'!AM19>0,'Section Load'!AM19,0)) -> 743 | AM16: =(IF('Water Report'!$R$7>0,'Water Report'!$R$7,0)) -> 75 | AN16: =(IF('Water Report'!$R$8>0,'Water Report'!$R$8,0)) -> 147 | AO16: =(IF('Water Report'!$R$9>0,'Water Report'!$R$9,0)) -> 78 | AP16: =(IF('Water Report'!$R$10>0,'Water Report'!$R$10,0)) -> 21 | AQ16: =(IF('Water Report'!$R$11>0,'Water Report'!$R$11,0)) -> 26 | AR16: =(IF('Water Report'!$R$13>0,'Water Report'!$R$13,0)) -> 36 | AS16: =(IF('Water Report'!$R$14>0,'Water Report'!$R$14,0)) -> 14 | AT16: =(IF('Water Report'!$R$15>0,'Water Report'!$R$15,0)) -> 8 | AU16: =(IF('Water Report'!$R$17>0,'Water Report'!$R$17,0)) -> 0 | AV16: =(IF('Water Report'!$R$18>0,'Water Report'!$R$18,0)) -> 8 | AW16: =(IF('Water Report'!$R$19>0,'Water Report'!$R$19,0)) -> 4 | AX16: =(IF('Water Report'!$R$21>0,'Water Report'!$R$21,0)) -> 65 | AY16: =(IF('Water Report'!$R$22>0,'Water Report'!$R$22,0)) -> 7 | AZ16: =(IF('Water Report'!$R$23>0,'Water Report'!$R$23,0)) -> 0 | BA16: =(IF('Water Report'!$R$14>0,'Water Report'!$R$14,0)) -> 14 | BB16: =(IF('Water Report'!$R$15>0,'Water Report'!$R$15,0)) -> 8 | BC16: =(IF('Water Report'!$R$13>0,'Water Report'!$R$13,0)) -> 36 | BD16: =(IF('Water Report'!$R$24>0,'Water Report'!$R$24,0)) -> 184 | BE16: =(IF('Water Report'!$R$25>0,'Water Report'!$R$25,0)) -> 147 | BF16: =(IF('Water Report'!$R$27>0,'Water Report'!$R$27,0)) -> 101 | BG16: =(IF('Section Load'!AN19>0,'Section Load'!AN19,0)) -> 947.813 | BH16: =(IF('Section Load'!AO19>0,'Section Load'!AO19,0)) -> 253.43 | BI16: =(IF('Section Load'!AP19>0,'Section Load'!AP19,0)) -> 0 | BJ16: =(IF('Section Load'!AQ19>0,'Section Load'!AQ19,0)) -> 122.16 | BK16: =(IF('Section Load'!AR19>0,'Section Load'!AR19,0)) -> 37.9 | BL16: =(IF('Section Load'!AS19>0,'Section Load'!AS19,0)) -> 5.7 | BM16: =(IF('Section Load'!AT19>0,'Section Load'!AT19,0)) -> 528.623
A17: Mumbai | B17: =B16+1 -> 16 | C17: 7 | D17: 2021 | E17: =(IF('Section Load'!F20>0,'Section Load'!F20,0)) -> 3155.48 | F17: =(IF('Section Load'!G20>0,'Section Load'!G20,0)) -> 1642.17 | G17: =(IF('Section Load'!H20>0,'Section Load'!H20,0)) -> 1628.41 | H17: =(IF('Section Load'!I20>0,'Section Load'!I20,0)) -> 3776.22 | I17: =(IF('Section Load'!J20>0,'Section Load'!J20,0)) -> 6367.01 | J17: =(IF('Section Load'!K20>0,'Section Load'!K20,0)) -> 2623.9 | K17: =(IF('Section Load'!L20>0,'Section Load'!L20,0)) -> 1102.16 | L17: =(IF('Section Load'!M20>0,'Section Load'!M20,0)) -> 1003.58 | ... AL17: =(IF('Section Load'!AM20>0,'Section Load'!AM20,0)) -> 734 | AM17: =(IF('Water Report'!$S$7>0,'Water Report'!$S$7,0)) -> 103 | AN17: =(IF('Water Report'!$S$8>0,'Water Report'!$S$8,0)) -> 71 | AO17: =(IF('Water Report'!$S$9>0,'Water Report'!$S$9,0)) -> 96 | AP17: =(IF('Water Report'!$S$10>0,'Water Report'!$D$10,0)) -> 17 | AQ17: =(IF('Water Report'!$S$11>0,'Water Report'!$D$11,0)) -> 18 | AR17: =(IF('Water Report'!$S$13>0,'Water Report'!$D$13,0)) -> 50 | AS17: =(IF('Water Report'!$S$14>0,'Water Report'!$D$14,0)) -> 6 | AT17: =(IF('Water Report'!$S$15>0,'Water Report'!$D$15,0)) -> 6 | AU17: =(IF('Water Report'!$S$17>0,'Water Report'!$D$17,0)) -> 0 | AV17: =(IF('Water Report'!$S$18>0,'Water Report'!$D$18,0)) -> 12 | AW17: =(IF('Water Report'!$S$19>0,'Water Report'!$D$19,0)) -> 5 | AX17: =(IF('Water Report'!$S$21>0,'Water Report'!$D$21,0)) -> 98 | AY17: =(IF('Water Report'!$S$22>0,'Water Report'!$D$22,0)) -> 40 | AZ17: =(IF('Water Report'!$S$23>0,'Water Report'!$D$23,0)) -> 0 | BA17: =(IF('Water Report'!$S$14>0,'Water Report'!$D$14,0)) -> 6 | BB17: =(IF('Water Report'!$S$15>0,'Water Report'!$D$15,0)) -> 6 | BC17: =(IF('Water Report'!$S$13>0,'Water Report'!$D$13,0)) -> 50 | BD17: =(IF('Water Report'!$S$24>0,'Water Report'!$D$24,0)) -> 154 | BE17: =(IF('Water Report'!$S$25>0,'Water Report'!$D$25,0)) -> 133 | BF17: =(IF('Water Report'!$S$27>0,'Water Report'!$D$27,0)) -> 148 | BG17: =(IF('Section Load'!AN20>0,'Section Load'!AN20,0)) -> 837.257 | BH17: =(IF('Section Load'!AO20>0,'Section Load'!AO20,0)) -> 265.34 | BI17: =(IF('Section Load'!AP20>0,'Section Load'!AP20,0)) -> 0 | BJ17: =(IF('Section Load'!AQ20>0,'Section Load'!AQ20,0)) -> 99.18 | BK17: =(IF('Section Load'!AR20>0,'Section Load'!AR20,0)) -> 41 | BL17: =(IF('Section Load'!AS20>0,'Section Load'!AS20,0)) -> 7 | BM17: =(IF('Section Load'!AT20>0,'Section Load'!AT20,0)) -> 424.737
A18: Mumbai | B18: =B17+1 -> 17 | C18: 7 | D18: 2021 | E18: =(IF('Section Load'!F21>0,'Section Load'!F21,0)) -> 3270.42 | F18: =(IF('Section Load'!G21>0,'Section Load'!G21,0)) -> 1656.55 | G18: =(IF('Section Load'!H21>0,'Section Load'!H21,0)) -> 1759.92 | H18: =(IF('Section Load'!I21>0,'Section Load'!I21,0)) -> 3718.93 | I18: =(IF('Section Load'!J21>0,'Section Load'!J21,0)) -> 8133.4 | J18: =(IF('Section Load'!K21>0,'Section Load'!K21,0)) -> 3097.4 | K18: =(IF('Section Load'!L21>0,'Section Load'!L21,0)) -> 1300.44 | L18: =(IF('Section Load'!M21>0,'Section Load'!M21,0)) -> 1131.82 | ... AL18: =(IF('Section Load'!AM21>0,'Section Load'!AM21,0)) -> 678 | AM18: =(IF('Water Report'!$T$7>0,'Water Report'!$T$7,0)) -> 101 | AN18: =(IF('Water Report'!$T$8>0,'Water Report'!$T$8,0)) -> 190 | AO18: =(IF('Water Report'!$T$9>0,'Water Report'!$T$9,0)) -> 89 | AP18: =(IF('Water Report'!$T$10>0,'Water Report'!$T$10,0)) -> 30 | AQ18: =(IF('Water Report'!$T$11>0,'Water Report'!$T$11,0)) -> 30 | AR18: =(IF('Water Report'!$T$13>0,'Water Report'!$T$13,0)) -> 23 | AS18: =(IF('Water Report'!$T$14>0,'Water Report'!$T$14,0)) -> 16 | AT18: =(IF('Water Report'!$T$15>0,'Water Report'!$T$15,0)) -> 8 | AU18: =(IF('Water Report'!$T$17>0,'Water Report'!$T$17,0)) -> 0 | AV18: =(IF('Water Report'!$T$18>0,'Water Report'!$T$18,0)) -> 11 | AW18: =(IF('Water Report'!$T$19>0,'Water Report'!$T$19,0)) -> 4 | AX18: =(IF('Water Report'!$T$21>0,'Water Report'!$T$21,0)) -> 66 | AY18: =(IF('Water Report'!$T$22>0,'Water Report'!$T$22,0)) -> 26 | AZ18: =(IF('Water Report'!$T$23>0,'Water Report'!$T$23,0)) -> 0 | BA18: =(IF('Water Report'!$T$14>0,'Water Report'!$T$14,0)) -> 16 | BB18: =(IF('Water Report'!$T$15>0,'Water Report'!$T$15,0)) -> 8 | BC18: =(IF('Water Report'!$T$13>0,'Water Report'!$T$13,0)) -> 23 | BD18: =(IF('Water Report'!$T$24>0,'Water Report'!$T$24,0)) -> 201 | BE18: =(IF('Water Report'!$T$25>0,'Water Report'!$T$25,0)) -> 173 | BF18: =(IF('Water Report'!$T$27>0,'Water Report'!$T$27,0)) -> 89 | BG18: =(IF('Section Load'!AN21>0,'Section Load'!AN21,0)) -> 981.661 | BH18: =(IF('Section Load'!AO21>0,'Section Load'!AO21,0)) -> 289.02 | BI18: =(IF('Section Load'!AP21>0,'Section Load'!AP21,0)) -> 0 | BJ18: =(IF('Section Load'!AQ21>0,'Section Load'!AQ21,0)) -> 114.2 | BK18: =(IF('Section Load'!AR21>0,'Section Load'!AR21,0)) -> 41 | BL18: =(IF('Section Load'!AS21>0,'Section Load'!AS21,0)) -> 6.7 | BM18: =(IF('Section Load'!AT21>0,'Section Load'!AT21,0)) -> 530.741
A19: Mumbai | B19: =B18+1 -> 18 | C19: 7 | D19: 2021 | E19: =(IF('Section Load'!F22>0,'Section Load'!F22,0)) -> 3484.808 | F19: =(IF('Section Load'!G22>0,'Section Load'!G22,0)) -> 1846.52 | G19: =(IF('Section Load'!H22>0,'Section Load'!H22,0)) -> 1840.98 | H19: =(IF('Section Load'!I22>0,'Section Load'!I22,0)) -> 3750.84 | I19: =(IF('Section Load'!J22>0,'Section Load'!J22,0)) -> 8129.57 | J19: =(IF('Section Load'!K22>0,'Section Load'!K22,0)) -> 3145.2 | K19: =(IF('Section Load'!L22>0,'Section Load'!L22,0)) -> 1712.2 | L19: =(IF('Section Load'!M22>0,'Section Load'!M22,0)) -> 1191.63 | ... AL19: =(IF('Section Load'!AM22>0,'Section Load'!AM22,0)) -> 823 | AM19: =(IF('Water Report'!$U$7>0,'Water Report'!$U$7,0)) -> 163 | AN19: =(IF('Water Report'!$U$8>0,'Water Report'!$U$8,0)) -> 160 | AO19: =(IF('Water Report'!$U$9>0,'Water Report'!$U$9,0)) -> 90 | AP19: =(IF('Water Report'!$U$10>0,'Water Report'!$U$10,0)) -> 30 | AQ19: =(IF('Water Report'!$U$11>0,'Water Report'!$U$11,0)) -> 29 | AR19: =(IF('Water Report'!$U$13>0,'Water Report'!$U$13,0)) -> 27 | AS19: =(IF('Water Report'!$U$14>0,'Water Report'!$U$14,0)) -> 19 | AT19: =(IF('Water Report'!$U$15>0,'Water Report'!$U$15,0)) -> 9 | AU19: =(IF('Water Report'!$U$17>0,'Water Report'!$U$17,0)) -> 0 | AV19: =(IF('Water Report'!$U$18>0,'Water Report'!$U$18,0)) -> 10 | AW19: =(IF('Water Report'!$U$19>0,'Water Report'!$U$19,0)) -> 5 | AX19: =(IF('Water Report'!$U$21>0,'Water Report'!$U$21,0)) -> 65 | AY19: =(IF('Water Report'!$U$22>0,'Water Report'!$U$22,0)) -> 12 | AZ19: =(IF('Water Report'!$U$23>0,'Water Report'!$U$23,0)) -> 0 | BA19: =(IF('Water Report'!$U$14>0,'Water Report'!$U$14,0)) -> 19 | BB19: =(IF('Water Report'!$U$15>0,'Water Report'!$U$15,0)) -> 9 | BC19: =(IF('Water Report'!$U$13>0,'Water Report'!$U$13,0)) -> 27 | BD19: =(IF('Water Report'!$U$24>0,'Water Report'!$U$24,0)) -> 179 | BE19: =(IF('Water Report'!$U$25>0,'Water Report'!$U$25,0)) -> 177 | BF19: =(IF('Water Report'!$U$27>0,'Water Report'!$U$27,0)) -> 92 | BG19: =(IF('Section Load'!AN22>0,'Section Load'!AN22,0)) -> 908.879 | BH19: =(IF('Section Load'!AO22>0,'Section Load'!AO22,0)) -> 295.74 | BI19: =(IF('Section Load'!AP22>0,'Section Load'!AP22,0)) -> 0 | BJ19: =(IF('Section Load'!AQ22>0,'Section Load'!AQ22,0)) -> 107.8 | BK19: =(IF('Section Load'!AR22>0,'Section Load'!AR22,0)) -> 45.1 | BL19: =(IF('Section Load'!AS22>0,'Section Load'!AS22,0)) -> 4.9 | BM19: =(IF('Section Load'!AT22>0,'Section Load'!AT22,0)) -> 455.339
A20: Mumbai | B20: =B19+1 -> 19 | C20: 7 | D20: 2021 | E20: =(IF('Section Load'!F23>0,'Section Load'!F23,0)) -> 3252.302 | F20: =(IF('Section Load'!G23>0,'Section Load'!G23,0)) -> 1591.16 | G20: =(IF('Section Load'!H23>0,'Section Load'!H23,0)) -> 1606.46 | H20: =(IF('Section Load'!I23>0,'Section Load'!I23,0)) -> 3770.33 | I20: =(IF('Section Load'!J23>0,'Section Load'!J23,0)) -> 6446.2 | J20: =(IF('Section Load'!K23>0,'Section Load'!K23,0)) -> 2549.57 | K20: =(IF('Section Load'!L23>0,'Section Load'!L23,0)) -> 1093.93 | L20: =(IF('Section Load'!M23>0,'Section Load'!M23,0)) -> 815.72 | ... AL20: =(IF('Section Load'!AM23>0,'Section Load'!AM23,0)) -> 776 | AM20: =(IF('Water Report'!$V$7>0,'Water Report'!$V$7,0)) -> 100 | AN20: =(IF('Water Report'!$V$8>0,'Water Report'!$V$8,0)) -> 154 | AO20: =(IF('Water Report'!$V$9>0,'Water Report'!$V$9,0)) -> 76 | AP20: =(IF('Water Report'!$V$10>0,'Water Report'!$V$10,0)) -> 18 | AQ20: =(IF('Water Report'!$V$11>0,'Water Report'!$V$11,0)) -> 23 | AR20: =(IF('Water Report'!$V$13>0,'Water Report'!$V$13,0)) -> 35 | AS20: =(IF('Water Report'!$V$14>0,'Water Report'!$V$14,0)) -> 11 | AT20: =(IF('Water Report'!$V$15>0,'Water Report'!$V$15,0)) -> 6 | AU20: =(IF('Water Report'!$V$17>0,'Water Report'!$V$17,0)) -> 0 | AV20: =(IF('Water Report'!$V$18>0,'Water Report'!$V$18,0)) -> 10 | AW20: =(IF('Water Report'!$V$19>0,'Water Report'!$V$19,0)) -> 6 | AX20: =(IF('Water Report'!$V$21>0,'Water Report'!$V$21,0)) -> 66 | AY20: =(IF('Water Report'!$V$22>0,'Water Report'!$V$22,0)) -> 40 | AZ20: =(IF('Water Report'!$V$23>0,'Water Report'!$V$23,0)) -> 0 | BA20: =(IF('Water Report'!$V$14>0,'Water Report'!$V$14,0)) -> 11 | BB20: =(IF('Water Report'!$V$15>0,'Water Report'!$V$15,0)) -> 6 | BC20: =(IF('Water Report'!$V$13>0,'Water Report'!$V$13,0)) -> 35 | BD20: =(IF('Water Report'!$V$24>0,'Water Report'!$V$24,0)) -> 257 | BE20: =(IF('Water Report'!$V$25>0,'Water Report'!$V$25,0)) -> 134 | BF20: =(IF('Water Report'!$V$27>0,'Water Report'!$V$27,0)) -> 101 | BG20: =(IF('Section Load'!AN23>0,'Section Load'!AN23,0)) -> 880.58 | BH20: =(IF('Section Load'!AO23>0,'Section Load'!AO23,0)) -> 267.73 | BI20: =(IF('Section Load'!AP23>0,'Section Load'!AP23,0)) -> 0 | BJ20: =(IF('Section Load'!AQ23>0,'Section Load'!AQ23,0)) -> 68.47 | BK20: =(IF('Section Load'!AR23>0,'Section Load'!AR23,0)) -> 31.7 | BL20: =(IF('Section Load'!AS23>0,'Section Load'!AS23,0)) -> 0 | BM20: =(IF('Section Load'!AT23>0,'Section Load'!AT23,0)) -> 512.68
A21: Mumbai | B21: =B20+1 -> 20 | C21: 7 | D21: 2021 | E21: =(IF('Section Load'!F24>0,'Section Load'!F24,0)) -> 2573.21 | F21: =(IF('Section Load'!G24>0,'Section Load'!G24,0)) -> 1586.97 | G21: =(IF('Section Load'!H24>0,'Section Load'!H24,0)) -> 1448.93 | H21: =(IF('Section Load'!I24>0,'Section Load'!I24,0)) -> 3767.43 | I21: =(IF('Section Load'!J24>0,'Section Load'!J24,0)) -> 7204.54 | J21: =(IF('Section Load'!K24>0,'Section Load'!K24,0)) -> 2710.7 | K21: =(IF('Section Load'!L24>0,'Section Load'!L24,0)) -> 1063.75 | L21: =(IF('Section Load'!M24>0,'Section Load'!M24,0)) -> 1166.52 | ... AL21: =(IF('Section Load'!AM24>0,'Section Load'!AM24,0)) -> 727 | AM21: =(IF('Water Report'!$W$7>0,'Water Report'!$W$7,0)) -> 35 | AN21: =(IF('Water Report'!$W$8>0,'Water Report'!$W$8,0)) -> 151 | AO21: =(IF('Water Report'!$W$9>0,'Water Report'!$W$9,0)) -> 51 | AP21: =(IF('Water Report'!$W$10>0,'Water Report'!$W$10,0)) -> 15 | AQ21: =(IF('Water Report'!$W$11>0,'Water Report'!$W$11,0)) -> 17 | AR21: =(IF('Water Report'!$W$13>0,'Water Report'!$W$13,0)) -> 10 | AS21: =(IF('Water Report'!$W$14>0,'Water Report'!$W$14,0)) -> 15 | AT21: =(IF('Water Report'!$W$15>0,'Water Report'!$W$15,0)) -> 4 | AU21: =(IF('Water Report'!$W$17>0,'Water Report'!$W$17,0)) -> 0 | AV21: =(IF('Water Report'!$W$18>0,'Water Report'!$W$18,0)) -> 0 | AW21: =(IF('Water Report'!$W$19>0,'Water Report'!$W$19,0)) -> 0 | AX21: =(IF('Water Report'!$W$21>0,'Water Report'!$W$21,0)) -> 66 | AY21: =(IF('Water Report'!$W$22>0,'Water Report'!$W$22,0)) -> 33 | AZ21: =(IF('Water Report'!$W$23>0,'Water Report'!$W$23,0)) -> 0 | BA21: =(IF('Water Report'!$W$14>0,'Water Report'!$W$14,0)) -> 15 | BB21: =(IF('Water Report'!$W$15>0,'Water Report'!$W$15,0)) -> 4 | BC21: =(IF('Water Report'!$W$13>0,'Water Report'!$W$13,0)) -> 10 | BD21: =(IF('Water Report'!$W$24>0,'Water Report'!$W$24,0)) -> 143 | BE21: =(IF('Water Report'!$W$25>0,'Water Report'!$W$25,0)) -> 102 | BF21: =(IF('Water Report'!$W$27>0,'Water Report'!$W$27,0)) -> 76 | BG21: =(IF('Section Load'!AN24>0,'Section Load'!AN24,0)) -> 465 | BH21: =(IF('Section Load'!AO24>0,'Section Load'!AO24,0)) -> 260.45 | BI21: =(IF('Section Load'!AP24>0,'Section Load'!AP24,0)) -> 0 | BJ21: =(IF('Section Load'!AQ24>0,'Section Load'!AQ24,0)) -> 81.23 | BK21: =(IF('Section Load'!AR24>0,'Section Load'!AR24,0)) -> 37 | BL21: =(IF('Section Load'!AS24>0,'Section Load'!AS24,0)) -> 1.7 | BM21: =(IF('Section Load'!AT24>0,'Section Load'!AT24,0)) -> 84.62
A22: Mumbai | B22: =B21+1 -> 21 | C22: 7 | D22: 2021 | E22: =(IF('Section Load'!F25>0,'Section Load'!F25,0)) -> 2837.54 | F22: =(IF('Section Load'!G25>0,'Section Load'!G25,0)) -> 1602.92 | G22: =(IF('Section Load'!H25>0,'Section Load'!H25,0)) -> 1578.05 | H22: =(IF('Section Load'!I25>0,'Section Load'!I25,0)) -> 3741.52 | I22: =(IF('Section Load'!J25>0,'Section Load'!J25,0)) -> 6289.11 | J22: =(IF('Section Load'!K25>0,'Section Load'!K25,0)) -> 2552.6 | K22: =(IF('Section Load'!L25>0,'Section Load'!L25,0)) -> 1014.92 | L22: =(IF('Section Load'!M25>0,'Section Load'!M25,0)) -> 759.4 | ... AL22: =(IF('Section Load'!AM25>0,'Section Load'!AM25,0)) -> 697 | AM22: =(IF('Water Report'!$X$7>0,'Water Report'!$X$7,0)) -> 79 | AN22: =(IF('Water Report'!$X$8>0,'Water Report'!$X$8,0)) -> 118 | AO22: =(IF('Water Report'!$X$9>0,'Water Report'!$X$9,0)) -> 79 | AP22: =(IF('Water Report'!$X$10>0,'Water Report'!$X$10,0)) -> 18 | AQ22: =(IF('Water Report'!$X$11>0,'Water Report'!$X$11,0)) -> 23 | AR22: =(IF('Water Report'!$X$13>0,'Water Report'!$X$13,0)) -> 18 | AS22: =(IF('Water Report'!$X$14>0,'Water Report'!$X$14,0)) -> 19 | AT22: =(IF('Water Report'!$X$15>0,'Water Report'!$X$15,0)) -> 11 | AU22: =(IF('Water Report'!$X$17>0,'Water Report'!$X$17,0)) -> 0 | AV22: =(IF('Water Report'!$X$18>0,'Water Report'!$X$18,0)) -> 12 | AW22: =(IF('Water Report'!$X$19>0,'Water Report'!$X$19,0)) -> 6 | AX22: =(IF('Water Report'!$X$21>0,'Water Report'!$X$21,0)) -> 66 | AY22: =(IF('Water Report'!$X$22>0,'Water Report'!$X$22,0)) -> 4 | AZ22: =(IF('Water Report'!$X$23>0,'Water Report'!$X$23,0)) -> 0 | BA22: =(IF('Water Report'!$X$14>0,'Water Report'!$X$14,0)) -> 19 | BB22: =(IF('Water Report'!$X$15>0,'Water Report'!$X$15,0)) -> 11 | BC22: =(IF('Water Report'!$X$13>0,'Water Report'!$X$13,0)) -> 18 | BD22: =(IF('Water Report'!$X$24>0,'Water Report'!$X$24,0)) -> 175 | BE22: =(IF('Water Report'!$X$25>0,'Water Report'!$X$25,0)) -> 150 | BF22: =(IF('Water Report'!$X$27>0,'Water Report'!$X$27,0)) -> 84 | BG22: =(IF('Section Load'!AN25>0,'Section Load'!AN25,0)) -> 926.72 | BH22: =(IF('Section Load'!AO25>0,'Section Load'!AO25,0)) -> 269.23 | BI22: =(IF('Section Load'!AP25>0,'Section Load'!AP25,0)) -> 0 | BJ22: =(IF('Section Load'!AQ25>0,'Section Load'!AQ25,0)) -> 85.07 | BK22: =(IF('Section Load'!AR25>0,'Section Load'!AR25,0)) -> 39.6 | BL22: =(IF('Section Load'!AS25>0,'Section Load'!AS25,0)) -> 1.3 | BM22: =(IF('Section Load'!AT25>0,'Section Load'!AT25,0)) -> 531.52
