Workbook

Sheet TOTAL
A1: Site Name | B1: Day | C1: Month | D1: Year | E1: Electricty 1 (Peak) | F1: Peak Tariff ($/Kwh) | G1: Electricity 2 (Shoulder) | H1: Shoulder Tariff ($/Kwh) | I1: Electricty 3 (Off-Peak) | J1: Off-Peak Tariff ($/Kwh) | K1: Total Electricity Kwh | L1: Natual Gas (m3) | M1: Natural Gas $/m3 | N1: Water Utility Supply (m3) m3 | O1: Water Utility Supply (m3) $/m3 | P1: Room Nights | Q1: Total Guests
A2: Sydney | B2: 1 | C2: 1 | D2: 2021 | E2: =(K2/100)*15 -> 2580 | F2: 0.106418 | G2: =(K2/100)*31 -> 5332 | H2: 0.106418 | I2: =(K2/100)*54 -> 9288 | J2: 0.071933 | K2: =Electric!H11*400 -> 17200 | L2: =Gas!F8 -> 515 | M2: 0.99 | N2: =Water!F8 -> 142 | O2: 2.35 | P2: 145 | Q2: 286
A3: Sydney | B3: =B2+1 -> 2 | C3: 1 | D3: 2021 | E3: =(K3/100)*15 -> 1896 | F3: 0.106418 | G3: =(K3/100)*31 -> 3918.4 | H3: 0.106418 | I3: =(K3/100)*54 -> 6825.6 | J3: 0.071933 | K3: =Electric!H12*400 -> 12640 | L3: =Gas!F9 -> 387 | M3: 0.99 | N3: =Water!F9 -> 129 | O3: 2.35 | P3: 150 | Q3: 296
A4: Sydney | B4: =B3+1 -> 3 | C4: 1 | D4: 2021 | E4: =(K4/100)*15 -> 2340 | F4: 0.106418 | G4: =(K4/100)*31 -> 4836 | H4: 0.106418 | I4: =(K4/100)*54 -> 8424 | J4: 0.071933 | K4: =Electric!H13*400 -> 15600 | L4: =Gas!F10 -> 430 | M4: 0.99 | N4: =Water!F10 -> 105 | O4: 2.35 | P4: 155 | Q4: 333
A5: Sydney | B5: =B4+1 -> 4 | C5: 1 | D5: 2021 | E5: =(K5/100)*15 -> 2742 | F5: 0.106418 | G5: =(K5/100)*31 -> 5666.8 | H5: 0.106418 | I5: =(K5/100)*54 -> 9871.2 | J5: 0.071933 | K5: =Electric!H14*400 -> 18280 | L5: =Gas!F11 -> 478 | M5: 0.99 | N5: =Water!F11 -> 170 | O5: 2.35 | P5: 151 | Q5: 323
A6: Sydney | B6: =B5+1 -> 5 | C6: 1 | D6: 2021 | E6: =(K6/100)*15 -> 2580 | F6: 0.106418 | G6: =(K6/100)*31 -> 5332 | H6: 0.106418 | I6: =(K6/100)*54 -> 9288 | J6: 0.071933 | K6: =Electric!H15*400 -> 17200 | L6: =Gas!F12 -> 416 | M6: 0.99 | N6: =Water!F12 -> 147 | O6: 2.35 | P6: 167 | Q6: 353
A7: Sydney | B7: =B6+1 -> 6 | C7: 1 | D7: 2021 | E7: =(K7/100)*15 -> 2418 | F7: 0.106418 | G7: =(K7/100)*31 -> 4997.2 | H7: 0.106418 | I7: =(K7/100)*54 -> 8704.8 | J7: 0.071933 | K7: =Electric!H16*400 -> 16120 | L7: =Gas!F13 -> 446 | M7: 0.99 | N7: =Water!F13 -> 123 | O7: 2.35 | P7: 166 | Q7: 340
A8: Sydney | B8: =B7+1 -> 7 | C8: 1 | D8: 2021 | E8: =(K8/100)*15 -> 2046 | F8: 0.106418 | G8: =(K8/100)*31 -> 4228.4 | H8: 0.106418 | I8: =(K8/100)*54 -> 7365.6 | J8: 0.071933 | K8: =Electric!H17*400 -> 13640 | L8: =Gas!F14 -> 394 | M8: 0.99 | N8: =Water!F14 -> 128 | O8: 2.35 | P8: 154 | Q8: 306
A9: Sydney | B9: =B8+1 -> 8 | C9: 1 | D9: 2021 | E9: =(K9/100)*15 -> 2226 | F9: 0.106418 | G9: =(K9/100)*31 -> 4600.4 | H9: 0.106418 | I9: =(K9/100)*54 -> 8013.6 | J9: 0.071933 | K9: =Electric!H18*400 -> 14840 | L9: =Gas!F15 -> 443 | M9: 0.99 | N9: =Water!F15 -> 149 | O9: 2.35 | P9: 239 | Q9: 482
A10: Sydney | B10: =B9+1 -> 9 | C10: 1 | D10: 2021 | E10: =(K10/100)*15 -> 2688 | F10: 0.106418 | G10: =(K10/100)*31 -> 5555.2 | H10: 0.106418 | I10: =(K10/100)*54 -> 9676.8 | J10: 0.071933 | K10: =Electric!H19*400 -> 17920 | L10: =Gas!F16 -> 500 | M10: 0.99 | N10: =Water!F16 -> 147 | O10: 2.35 | P10: 318 | Q10: 647
A11: Sydney | B11: =B10+1 -> 10 | C11: 1 | D11: 2021 | E11: =(K11/100)*15 -> 2556 | F11: 0.106418 | G11: =(K11/100)*31 -> 5282.4 | H11: 0.106418 | I11: =(K11/100)*54 -> 9201.6 | J11: 0.071933 | K11: =Electric!H20*400 -> 17040 | L11: =Gas!F17 -> 463 | M11: 0.99 | N11: =Water!F17 -> 138 | O11: 2.35 | P11: 110 | Q11: 223
A12: Sydney | B12: =B11+1 -> 11 | C12: 1 | D12: 2021 | E12: =(K12/100)*15 -> 2010 | F12: 0.106418 | G12: =(K12/100)*31 -> 4154 | H12: 0.106418 | I12: =(K12/100)*54 -> 7236 | J12: 0.071933 | K12: =Electric!H21*400 -> 13400 | L12: =Gas!F18 -> 356 | M12: 0.99 | N12: =Water!F18 -> 98 | O12: 2.35 | P12: 83 | Q12: 167
A13: Sydney | B13: =B12+1 -> 12 | C13: 1 | D13: 2021 | E13: =(K13/100)*15 -> 2232 | F13: 0.106418 | G13: =(K13/100)*31 -> 4612.8 | H13: 0.106418 | I13: =(K13/100)*54 -> 8035.2 | J13: 0.071933 | K13: =Electric!H22*400 -> 14880 | L13: =Gas!F19 -> 376 | M13: 0.99 | N13: =Water!F19 -> 117 | O13: 2.35 | P13: 80 | Q13: 155
A14: Sydney | B14: =B13+1 -> 13 | C14: 1 | D14: 2021 | E14: =(K14/100)*15 -> 2712 | F14: 0.106418 | G14: =(K14/100)*31 -> 5604.8 | H14: 0.106418 | I14: =(K14/100)*54 -> 9763.2 | J14: 0.071933 | K14: =Electric!H23*400 -> 18080 | L14: =Gas!F20 -> 427 | M14: 0.99 | N14: =Water!F20 -> 124 | O14: 2.35 | P14: 110 | Q14: 217
... A32: Sydney | B32: =B31+1 -> 31 | C32: 1 | D32: 2021 | E32: =(K32/100)*15 -> 2454 | F32: 0.106418 | G32: =(K32/100)*31 -> 5071.6 | H32: 0.106418 | I32: =(K32/100)*54 -> 8834.4 | J32: 0.071933 | K32: =Electric!H41*400 -> 16360 | L32: =Gas!F38 -> 429 | M32: 0.99 | N32: =Water!F38 -> 101 | O32: 2.35 | P32: 71 | Q32: 131
A33: Sydney | B33: 1 | C33: 2 | D33: 2021 | E33: =(K33/100)*15 -> 2856 | F33: 0.106418 | G33: =(K33/100)*31 -> 5902.4 | H33: 0.106418 | I33: =(K33/100)*54 -> 10281.6 | J33: 0.071933 | K33: =Electric!M11*400 -> 19040 | L33: =Gas!I8 -> 482 | M33: 0.99 | N33: =Water!I8 -> 178 | O33: 2.35 | P33: 63 | Q33: 105
A34: Sydney | B34: 2 | C34: 2 | D34: 2021 | E34: =(K34/100)*15 -> 2160 | F34: 0.106418 | G34: =(K34/100)*31 -> 4464 | H34: 0.106418 | I34: =(K34/100)*54 -> 7776 | J34: 0.071933 | K34: =Electric!M12*400 -> 14400 | L34: =Gas!I9 -> 401 | M34: 0.99 | N34: =Water!I9 -> 105 | O34: 2.35 | P34: 90 | Q34: 128
A35: Sydney | B35: 3 | C35: 2 | D35: 2021 | E35: =(K35/100)*15 -> 2034 | F35: 0.106418 | G35: =(K35/100)*31 -> 4203.6 | H35: 0.106418 | I35: =(K35/100)*54 -> 7322.4 | J35: 0.071933 | K35: =Electric!M13*400 -> 13560 | L35: =Gas!I10 -> 378 | M35: 0.99 | N35: =Water!I10 -> 109 | O35: 2.35 | P35: 118 | Q35: 171
A36: Sydney | B36: 4 | C36: 2 | D36: 2021 | E36: =(K36/100)*15 -> 2202 | F36: 0.106418 | G36: =(K36/100)*31 -> 4550.8 | H36: 0.106418 | I36: =(K36/100)*54 -> 7927.2 | J36: 0.071933 | K36: =Electric!M14*400 -> 14680 | L36: =Gas!I11 -> 356 | M36: 0.99 | N36: =Water!I11 -> 117 | O36: 2.35 | P36: 94 | Q36: 138
A37: Sydney | B37: 5 | C37: 2 | D37: 2021 | E37: =(K37/100)*15 -> 2952 | F37: 0.106418 | G37: =(K37/100)*31 -> 6100.8 | H37: 0.106418 | I37: =(K37/100)*54 -> 10627.2 | J37: 0.071933 | K37: =Electric!M15*400 -> 19680 | L37: =Gas!I12 -> 499 | M37: 0.99 | N37: =Water!I12 -> 144 | O37: 2.35 | P37: 173 | Q37: 311
A38: Sydney | B38: 6 | C38: 2 | D38: 2021 | E38: =(K38/100)*15 -> 2292 | F38: 0.106418 | G38: =(K38/100)*31 -> 4736.8 | H38: 0.106418 | I38: =(K38/100)*54 -> 8251.2 | J38: 0.071933 | K38: =Electric!M16*400 -> 15280 | L38: =Gas!I13 -> 392 | M38: 0.99 | N38: =Water!I13 -> 160 | O38: 2.35 | P38: 390 | Q38: 758
A39: Sydney | B39: 7 | C39: 2 | D39: 2021 | E39: =(K39/100)*15 -> 2610 | F39: 0.106418 | G39: =(K39/100)*31 -> 5394 | H39: 0.106418 | I39: =(K39/100)*54 -> 9396 | J39: 0.071933 | K39: =Electric!M17*400 -> 17400 | L39: =Gas!I14 -> 458 | M39: 0.99 | N39: =Water!I14 -> 147 | O39: 2.35 | P39: 89 | Q39: 157
A40: Sydney | B40: 8 | C40: 2 | D40: 2021 | E40: =(K40/100)*15 -> 2460 | F40: 0.106418 | G40: =(K40/100)*31 -> 5084 | H40: 0.106418 | I40: =(K40/100)*54 -> 8856 | J40: 0.071933 | K40: =Electric!M18*400 -> 16400 | L40: =Gas!I15 -> 454 | M40: 0.99 | N40: =Water!I15 -> 143 | O40: 2.35 | P40: 63 | Q40: 94
A41: Sydney | B41: 9 | C41: 2 | D41: 2021 | E41: =(K41/100)*15 -> 1956 | F41: 0.106418 | G41: =(K41/100)*31 -> 4042.4 | H41: 0.106418 | I41: =(K41/100)*54 -> 7041.6 | J41: 0.071933 | K41: =Electric!M19*400 -> 13040 | L41: =Gas!I16 -> 371 | M41: 0.99 | N41: =Water!I16 -> 108 | O41: 2.35 | P41: 109 | Q41: 162
A42: Sydney | B42: 10 | C42: 2 | D42: 2021 | E42: =(K42/100)*15 -> 2700 | F42: 0.106418 | G42: =(K42/100)*31 -> 5580 | H42: 0.106418 | I42: =(K42/100)*54 -> 9720 | J42: 0.071933 | K42: =Electric!M20*400 -> 18000 | L42: =Gas!I17 -> 489 | M42: 0.99 | N42: =Water!I17 -> 154 | O42: 2.35 | P42: 123 | Q42: 167
A43: Sydney | B43: 11 | C43: 2 | D43: 2021 | E43: =(K43/100)*15 -> 2718 | F43: 0.106418 | G43: =(K43/100)*31 -> 5617.2 | H43: 0.106418 | I43: =(K43/100)*54 -> 9784.8 | J43: 0.071933 | K43: =Electric!M21*400 -> 18120 | L43: =Gas!I18 -> 476 | M43: 0.99 | N43: =Water!I18 -> 88 | O43: 2.35 | P43: 139 | Q43: 233
A44: Sydney | B44: 12 | C44: 2 | D44: 2021 | E44: =(K44/100)*15 -> 2208 | F44: 0.106418 | G44: =(K44/100)*31 -> 4563.2 | H44: 0.106418 | I44: =(K44/100)*54 -> 7948.8 | J44: 0.071933 | K44: =Electric!M22*400 -> 14720 | L44: =Gas!I19 -> 367 | M44: 0.99 | N44: =Water!I19 -> 154 | O44: 2.35 | P44: 293 | Q44: 566
... A60: Sydney | B60: 28 | C60: 2 | D60: 2021 | E60: =(K60/100)*15 -> 2538 | F60: 0.106418 | G60: =(K60/100)*31 -> 5245.2 | H60: 0.106418 | I60: =(K60/100)*54 -> 9136.8 | J60: 0.071933 | K60: =Electric!M38*400 -> 16920 | L60: =Gas!I35 -> 432 | M60: 0.99 | N60: =Water!I35 -> 191 | O60: 2.35 | P60: 146 | Q60: 256
A61: Sydney | B61: 1 | C61: 3 | D61: 2021 | E61: =(K61/100)*15 -> 2928 | F61: 0.106418 | G61: =(K61/100)*31 -> 6051.2 | H61: 0.106418 | I61: =(K61/100)*54 -> 10540.8 | J61: 0.071933 | K61: =Electric!R11*400 -> 19520 | L61: =Gas!L8 -> 443 | M61: 0.99 | N61: =Water!L8 -> 177 | O61: 2.35 | P61: 181 | Q61: 263
A62: Sydney | B62: 2 | C62: 3 | D62: 2021 | E62: =(K62/100)*15 -> 2382 | F62: 0.106418 | G62: =(K62/100)*31 -> 4922.8 | H62: 0.106418 | I62: =(K62/100)*54 -> 8575.2 | J62: 0.071933 | K62: =Electric!R12*400 -> 15880 | L62: =Gas!L9 -> 416 | M62: 0.99 | N62: =Water!L9 -> 112 | O62: 2.35 | P62: 200 | Q62: 278
A63: Sydney | B63: 3 | C63: 3 | D63: 2021 | E63: =(K63/100)*15 -> 2664 | F63: 0.106418 | G63: =(K63/100)*31 -> 5505.6 | H63: 0.106418 | I63: =(K63/100)*54 -> 9590.4 | J63: 0.071933 | K63: =Electric!R13*400 -> 17760 | L63: =Gas!L10 -> 473 | M63: 0.99 | N63: =Water!L10 -> 161 | O63: 2.35 | P63: 238 | Q63: 336
A64: Sydney | B64: 4 | C64: 3 | D64: 2021 | E64: =(K64/100)*15 -> 1932 | F64: 0.106418 | G64: =(K64/100)*31 -> 3992.8 | H64: 0.106418 | I64: =(K64/100)*54 -> 6955.2 | J64: 0.071933 | K64: =Electric!R14*400 -> 12880 | L64: =Gas!L11 -> 339 | M64: 0.99 | N64: =Water!L11 -> 158 | O64: 2.35 | P64: 249 | Q64: 371
A65: Sydney | B65: 5 | C65: 3 | D65: 2021 | E65: =(K65/100)*15 -> 2436 | F65: 0.106418 | G65: =(K65/100)*31 -> 5034.4 | H65: 0.106418 | I65: =(K65/100)*54 -> 8769.6 | J65: 0.071933 | K65: =Electric!R15*400 -> 16240 | L65: =Gas!L12 -> 432 | M65: 0.99 | N65: =Water!L12 -> 154 | O65: 2.35 | P65: 349 | Q65: 660
A66: Sydney | B66: 6 | C66: 3 | D66: 2021 | E66: =(K66/100)*15 -> 2520 | F66: 0.106418 | G66: =(K66/100)*31 -> 5208 | H66: 0.106418 | I66: =(K66/100)*54 -> 9072 | J66: 0.071933 | K66: =Electric!R16*400 -> 16800 | L66: =Gas!L13 -> 464 | M66: 0.99 | N66: =Water!L13 -> 163 | O66: 2.35 | P66: 498 | Q66: 991
A67: Sydney | B67: 7 | C67: 3 | D67: 2021 | E67: =(K67/100)*15 -> 2484 | F67: 0.106418 | G67: =(K67/100)*31 -> 5133.6 | H67: 0.106418 | I67: =(K67/100)*54 -> 8942.4 | J67: 0.071933 | K67: =Electric!R17*400 -> 16560 | L67: =Gas!L14 -> 454 | M67: 0.99 | N67: =Water!L14 -> 185 | O67: 2.35 | P67: 258 | Q67: 478
A68: Sydney | B68: 8 | C68: 3 | D68: 2021 | E68: =(K68/100)*15 -> 2580 | F68: 0.106418 | G68: =(K68/100)*31 -> 5332 | H68: 0.106418 | I68: =(K68/100)*54 -> 9288 | J68: 0.071933 | K68: =Electric!R18*400 -> 17200 | L68: =Gas!L15 -> 426 | M68: 0.99 | N68: =Water!L15 -> 182 | O68: 2.35 | P68: 182 | Q68: 287
A69: Sydney | B69: 9 | C69: 3 | D69: 2021 | E69: =(K69/100)*15 -> 2652 | F69: 0.106418 | G69: =(K69/100)*31 -> 5480.8 | H69: 0.106418 | I69: =(K69/100)*54 -> 9547.2 | J69: 0.071933 | K69: =Electric!R19*400 -> 17680 | L69: =Gas!L16 -> 424 | M69: 0.99 | N69: =Water!L16 -> 138 | O69: 2.35 | P69: 209 | Q69: 290
A70: Sydney | B70: 10 | C70: 3 | D70: 2021 | E70: =(K70/100)*15 -> 2496 | F70: 0.106418 | G70: =(K70/100)*31 -> 5158.4 | H70: 0.106418 | I70: =(K70/100)*54 -> 8985.6 | J70: 0.071933 | K70: =Electric!R20*400 -> 16640 | L70: =Gas!L17 -> 411 | M70: 0.99 | N70: =Water!L17 -> 150 | O70: 2.35 | P70: 251 | Q70: 338
A71: Sydney | B71: 11 | C71: 3 | D71: 2021 | E71: =(K71/100)*15 -> 2724 | F71: 0.106418 | G71: =(K71/100)*31 -> 5629.6 | H71: 0.106418 | I71: =(K71/100)*54 -> 9806.4 | J71: 0.071933 | K71: =Electric!R21*400 -> 18160 | L71: =Gas!L18 -> 460 | M71: 0.99 | N71: =Water!L18 -> 157 | O71: 2.35 | P71: 205 | Q71: 323
A72: Sydney | B72: 12 | C72: 3 | D72: 2021 | E72: =(K72/100)*15 -> 2754 | F72: 0.106418 | G72: =(K72/100)*31 -> 5691.6 | H72: 0.106418 | I72: =(K72/100)*54 -> 9914.4 | J72: 0.071933 | K72: =Electric!R22*400 -> 18360 | L72: =Gas!L19 -> 466 | M72: 0.99 | N72: =Water!L19 -> 166 | O72: 2.35 | P72: 324 | Q72: 618
...

Sheet Gas
B2: December 31st
B3: 823730
B5: Meter Readings
D7: Jan | F7: m3 | G7: Feb | I7: m3 | J7: Mar | L7: m3 | M7: Apr | O7: m3 | P7: May | R7: m3 | S7: Jun | U7: m3 | V7: Jul | X7: m3 | Y7: Aug | AA7: m3 | AB7: Sep | AD7: m3 | AE7: Oct | AG7: m3 | AH7: Nov | AJ7: m3 | AK7: Dec | AM7: m3
B8: 1st | D8: 824245 | F8: =IF(COUNT(B3,D8)=2,D8-B3,"") -> 515 | G8: 837388 | I8: =IF(COUNT(D38,G8)=2,G8-D38,"") -> 482 | J8: 849479 | L8: =IF(COUNT(G35,J8)=2,J8-G35,"") -> 443 | M8: 863677 | O8: =IF(COUNT(J38,M8)=2,M8-J38,"") -> 473 | P8: 879545 | R8: =IF(COUNT(M37,P8)=2,P8-M37,"") -> 513 | S8: 899583 | U8: =IF(COUNT(P38,S8)=2,S8-P38,"") -> 713 | V8: 920936 | X8: =IF(COUNT(S37,V8)=2,V8-S37,"") -> 551 | Y8: 934893 | AA8: =IF(COUNT(V38,Y8)=2,Y8-V38,"") -> 260 | AD8: =IF(COUNT(Y38,AB8)=2,AB8-Y38,"") | AG8: =IF(COUNT(AB37,AE8)=2,AE8-AB37,"") | AJ8: =IF(COUNT(AE38,AH8)=2,AH8-AE38,"") | AM8: =IF(COUNT(AH37,AK8)=2,AK8-AH37,"")
B9: 2nd | D9: 824632 | F9: =IF(COUNT(D8,D9)=2,D9-D8,"") -> 387 | G9: 837789 | I9: =IF(COUNT(G8,G9)=2,G9-G8,"") -> 401 | J9: 849895 | L9: =IF(COUNT(J9,J8)=2,J9-J8,"") -> 416 | M9: 864158 | O9: =IF(COUNT(M8,M9)=2,M9-M8,"") -> 481 | P9: 880060 | R9: =IF(COUNT(P8,P9)=2,P9-P8,"") -> 515 | S9: 900300 | U9: =IF(COUNT(S8,S9)=2,S9-S8,"") -> 717 | V9: 921422 | X9: =IF(COUNT(V9,V8)=2,V9-V8,"") -> 486 | AA9: =IF(COUNT(Y8,Y9)=2,Y9-Y8,"") | AD9: =IF(COUNT(AB8,AB9)=2,AB9-AB8,"") | AG9: =IF(COUNT(AE9,AE8)=2,AE9-AE8,"") | AJ9: =IF(COUNT(AH9,AH8)=2,AH9-AH8,"") | AM9: =IF(COUNT(AK9,AK8)=2,AK9-AK8,"")
B10: 3rd | D10: 825062 | F10: =IF(COUNT(D9,D10)=2,D10-D9,"") -> 430 | G10: 838167 | I10: =IF(COUNT(G9,G10)=2,G10-G9,"") -> 378 | J10: 850368 | L10: =IF(COUNT(J10,J9)=2,J10-J9,"") -> 473 | M10: 864686 | O10: =IF(COUNT(M9,M10)=2,M10-M9,"") -> 528 | P10: 880548 | R10: =IF(COUNT(P9,P10)=2,P10-P9,"") -> 488 | S10: 901112 | U10: =IF(COUNT(S9,S10)=2,S10-S9,"") -> 812 | V10: 921924 | X10: =IF(COUNT(V10,V9)=2,V10-V9,"") -> 502 | AA10: =IF(COUNT(Y9,Y10)=2,Y10-Y9,"") | AD10: =IF(COUNT(AB9,AB10)=2,AB10-AB9,"") | AG10: =IF(COUNT(AE10,AE9)=2,AE10-AE9,"") | AJ10: =IF(COUNT(AH10,AH9)=2,AH10-AH9,"") | AM10: =IF(COUNT(AK10,AK9)=2,AK10-AK9,"")
B11: 4th | D11: 825540 | F11: =IF(COUNT(D10,D11)=2,D11-D10,"") -> 478 | G11: 838523 | I11: =IF(COUNT(G10,G11)=2,G11-G10,"") -> 356 | J11: 850707 | L11: =IF(COUNT(J11,J10)=2,J11-J10,"") -> 339 | M11: 865215 | O11: =IF(COUNT(M10,M11)=2,M11-M10,"") -> 529 | P11: 881084 | R11: =IF(COUNT(P10,P11)=2,P11-P10,"") -> 536 | S11: 901839 | U11: =IF(COUNT(S10,S11)=2,S11-S10,"") -> 727 | V11: 922605 | X11: =IF(COUNT(V11,V10)=2,V11-V10,"") -> 681 | AA11: =IF(COUNT(Y10,Y11)=2,Y11-Y10,"") | AD11: =IF(COUNT(AB10,AB11)=2,AB11-AB10,"") | AG11: =IF(COUNT(AE11,AE10)=2,AE11-AE10,"") | AJ11: =IF(COUNT(AH11,AH10)=2,AH11-AH10,"") | AM11: =IF(COUNT(AK11,AK10)=2,AK11-AK10,"")
B12: 5th | D12: 825956 | F12: =IF(COUNT(D11,D12)=2,D12-D11,"") -> 416 | G12: 839022 | I12: =IF(COUNT(G11,G12)=2,G12-G11,"") -> 499 | J12: 851139 | L12: =IF(COUNT(J12,J11)=2,J12-J11,"") -> 432 | M12: 865653 | O12: =IF(COUNT(M11,M12)=2,M12-M11,"") -> 438 | P12: 881681 | R12: =IF(COUNT(P11,P12)=2,P12-P11,"") -> 597 | S12: 902539 | U12: =IF(COUNT(S11,S12)=2,S12-S11,"") -> 700 | V12: 923335 | X12: =IF(COUNT(V12,V11)=2,V12-V11,"") -> 730 | AA12: =IF(COUNT(Y11,Y12)=2,Y12-Y11,"") | AD12: =IF(COUNT(AB11,AB12)=2,AB12-AB11,"") | AG12: =IF(COUNT(AE12,AE11)=2,AE12-AE11,"") | AJ12: =IF(COUNT(AH12,AH11)=2,AH12-AH11,"") | AM12: =IF(COUNT(AK12,AK11)=2,AK12-AK11,"")
B13: 6th | D13: 826402 | F13: =IF(COUNT(D12,D13)=2,D13-D12,"") -> 446 | G13: 839414 | I13: =IF(COUNT(G12,G13)=2,G13-G12,"") -> 392 | J13: 851603 | L13: =IF(COUNT(J13,J12)=2,J13-J12,"") -> 464 | M13: 866229 | O13: =IF(COUNT(M12,M13)=2,M13-M12,"") -> 576 | P13: 882217 | R13: =IF(COUNT(P12,P13)=2,P13-P12,"") -> 536 | S13: 903239 | U13: =IF(COUNT(S12,S13)=2,S13-S12,"") -> 700 | V13: 924043 | X13: =IF(COUNT(V13,V12)=2,V13-V12,"") -> 708 | AA13: =IF(COUNT(Y12,Y13)=2,Y13-Y12,"") | AD13: =IF(COUNT(AB12,AB13)=2,AB13-AB12,"") | AG13: =IF(COUNT(AE13,AE12)=2,AE13-AE12,"") | AJ13: =IF(COUNT(AH13,AH12)=2,AH13-AH12,"") | AM13: =IF(COUNT(AK13,AK12)=2,AK13-AK12,"")
B14: 7th | D14: 826796 | F14: =IF(COUNT(D13,D14)=2,D14-D13,"") -> 394 | G14: 839872 | I14: =IF(COUNT(G13,G14)=2,G14-G13,"") -> 458 | J14: 852057 | L14: =IF(COUNT(J14,J13)=2,J14-J13,"") -> 454 | M14: 866690 | O14: =IF(COUNT(M13,M14)=2,M14-M13,"") -> 461 | P14: 882688 | R14: =IF(COUNT(P13,P14)=2,P14-P13,"") -> 471 | S14: 903997 | U14: =IF(COUNT(S13,S14)=2,S14-S13,"") -> 758 | V14: 924740 | X14: =IF(COUNT(V14,V13)=2,V14-V13,"") -> 697 | AA14: =IF(COUNT(Y13,Y14)=2,Y14-Y13,"") | AD14: =IF(COUNT(AB13,AB14)=2,AB14-AB13,"") | AG14: =IF(COUNT(AE14,AE13)=2,AE14-AE13,"") | AJ14: =IF(COUNT(AH14,AH13)=2,AH14-AH13,"") | AM14: =IF(COUNT(AK14,AK13)=2,AK14-AK13,"")
B15: 8th | D15: 827239 | F15: =IF(COUNT(D14,D15)=2,D15-D14,"") -> 443 | G15: 840326 | I15: =IF(COUNT(G14,G15)=2,G15-G14,"") -> 454 | J15: 852483 | L15: =IF(COUNT(J15,J14)=2,J15-J14,"") -> 426 | M15: 867181 | O15: =IF(COUNT(M14,M15)=2,M15-M14,"") -> 491 | P15: 883212 | R15: =IF(COUNT(P14,P15)=2,P15-P14,"") -> 524 | S15: 904606 | U15: =IF(COUNT(S14,S15)=2,S15-S14,"") -> 609 | V15: 925415 | X15: =IF(COUNT(V15,V14)=2,V15-V14,"") -> 675 | AA15: =IF(COUNT(Y14,Y15)=2,Y15-Y14,"") | AD15: =IF(COUNT(AB14,AB15)=2,AB15-AB14,"") | AG15: =IF(COUNT(AE15,AE14)=2,AE15-AE14,"") | AJ15: =IF(COUNT(AH15,AH14)=2,AH15-AH14,"") | AM15: =IF(COUNT(AK15,AK14)=2,AK15-AK14,"")
B16: 9th | D16: 827739 | F16: =IF(COUNT(D15,D16)=2,D16-D15,"") -> 500 | G16: 840697 | I16: =IF(COUNT(G15,G16)=2,G16-G15,"") -> 371 | J16: 852907 | L16: =IF(COUNT(J16,J15)=2,J16-J15,"") -> 424 | M16: 867671 | O16: =IF(COUNT(M15,M16)=2,M16-M15,"") -> 490 | P16: 883714 | R16: =IF(COUNT(P15,P16)=2,P16-P15,"") -> 502 | S16: 905299 | U16: =IF(COUNT(S15,S16)=2,S16-S15,"") -> 693 | V16: 926031 | X16: =IF(COUNT(V16,V15)=2,V16-V15,"") -> 616 | AA16: =IF(COUNT(Y15,Y16)=2,Y16-Y15,"") | AD16: =IF(COUNT(AB15,AB16)=2,AB16-AB15,"") | AG16: =IF(COUNT(AE16,AE15)=2,AE16-AE15,"") | AJ16: =IF(COUNT(AH16,AH15)=2,AH16-AH15,"") | AM16: =IF(COUNT(AK16,AK15)=2,AK16-AK15,"")
B17: 10th | D17: 828202 | F17: =IF(COUNT(D16,D17)=2,D17-D16,"") -> 463 | G17: 841186 | I17: =IF(COUNT(G16,G17)=2,G17-G16,"") -> 489 | J17: 853318 | L17: =IF(COUNT(J17,J16)=2,J17-J16,"") -> 411 | M17: 868124 | O17: 490 | P17: 884202 | R17: =IF(COUNT(P16,P17)=2,P17-P16,"") -> 488 | S17: 906180 | U17: =IF(COUNT(S16,S17)=2,S17-S16,"") -> 881 | V17: 926591 | X17: =IF(COUNT(V17,V16)=2,V17-V16,"") -> 560 | AA17: =IF(COUNT(Y16,Y17)=2,Y17-Y16,"") | AD17: =IF(COUNT(AB16,AB17)=2,AB17-AB16,"") | AG17: =IF(COUNT(AE17,AE16)=2,AE17-AE16,"") | AJ17: =IF(COUNT(AH17,AH16)=2,AH17-AH16,"") | AM17: =IF(COUNT(AK17,AK16)=2,AK17-AK16,"")
B18: 11th | D18: 828558 | F18: =IF(COUNT(D17,D18)=2,D18-D17,"") -> 356 | G18: 841662 | I18: =IF(COUNT(G17,G18)=2,G18-G17,"") -> 476 | J18: 853778 | L18: =IF(COUNT(J18,J17)=2,J18-J17,"") -> 460 | M18: 868746 | O18: 491 | P18: 884703 | R18: =IF(COUNT(P17,P18)=2,P18-P17,"") -> 501 | S18: 907050 | U18: =IF(COUNT(S17,S18)=2,S18-S17,"") -> 870 | V18: 927161 | X18: =IF(COUNT(V18,V17)=2,V18-V17,"") -> 570 | AA18: =IF(COUNT(Y17,Y18)=2,Y18-Y17,"") | AD18: =IF(COUNT(AB17,AB18)=2,AB18-AB17,"") | AG18: =IF(COUNT(AE18,AE17)=2,AE18-AE17,"") | AJ18: =IF(COUNT(AH18,AH17)=2,AH18-AH17,"") | AM18: =IF(COUNT(AK18,AK17)=2,AK18-AK17,"")
B19: 12th | D19: 828934 | F19: =IF(COUNT(D18,D19)=2,D19-D18,"") -> 376 | G19: 842029 | I19: =IF(COUNT(G18,G19)=2,G19-G18,"") -> 367 | J19: 854244 | L19: =IF(COUNT(J19,J18)=2,J19-J18,"") -> 466 | M19: 869379 | O19: =IF(COUNT(M18,M19)=2,M19-M18,"") -> 633 | P19: 885240 | R19: =IF(COUNT(P18,P19)=2,P19-P18,"") -> 537 | S19: 907743 | U19: =IF(COUNT(S18,S19)=2,S19-S18,"") -> 693 | V19: 927591 | X19: =IF(COUNT(V19,V18)=2,V19-V18,"") -> 430 | AA19: =IF(COUNT(Y18,Y19)=2,Y19-Y18,"") | AD19: =IF(COUNT(AB18,AB19)=2,AB19-AB18,"") | AG19: =IF(COUNT(AE19,AE18)=2,AE19-AE18,"") | AJ19: =IF(COUNT(AH19,AH18)=2,AH19-AH18,"") | AM19: =IF(COUNT(AK19,AK18)=2,AK19-AK18,"")
B20: 13th | D20: 829361 | F20: =IF(COUNT(D19,D20)=2,D20-D19,"") -> 427 | G20: 842524 | I20: =IF(COUNT(G19,G20)=2,G20-G19,"") -> 495 | J20: 854688 | L20: =IF(COUNT(J20,J19)=2,J20-J19,"") -> 444 | M20: 869977 | O20: =IF(COUNT(M19,M20)=2,M20-M19,"") -> 598 | P20: 885745 | R20: =IF(COUNT(P19,P20)=2,P20-P19,"") -> 505 | S20: 908575 | U20: =IF(COUNT(S19,S20)=2,S20-S19,"") -> 832 | V20: 927994 | X20: =IF(COUNT(V20,V19)=2,V20-V19,"") -> 403 | AA20: =IF(COUNT(Y19,Y20)=2,Y20-Y19,"") | AD20: =IF(COUNT(AB19,AB20)=2,AB20-AB19,"") | AG20: =IF(COUNT(AE20,AE19)=2,AE20-AE19,"") | AJ20: =IF(COUNT(AH20,AH19)=2,AH20-AH19,"") | AM20: =IF(COUNT(AK20,AK19)=2,AK20-AK19,"")
B21: 14th | D21: 829737 | F21: =IF(COUNT(D20,D21)=2,D21-D20,"") -> 376 | G21: 843016 | I21: =IF(COUNT(G20,G21)=2,G21-G20,"") -> 492 | J21: 855215 | L21: =IF(COUNT(J21,J20)=2,J21-J20,"") -> 527 | M21: 870448 | O21: =IF(COUNT(M20,M21)=2,M21-M20,"") -> 471 | P21: 886338 | R21: =IF(COUNT(P20,P21)=2,P21-P20,"") -> 593 | S21: 909386 | U21: =IF(COUNT(S20,S21)=2,S21-S20,"") -> 811 | V21: 928331 | X21: =IF(COUNT(V21,V20)=2,V21-V20,"") -> 337 | AA21: =IF(COUNT(Y20,Y21)=2,Y21-Y20,"") | AD21: =IF(COUNT(AB20,AB21)=2,AB21-AB20,"") | AG21: =IF(COUNT(AE21,AE20)=2,AE21-AE20,"") | AJ21: =IF(COUNT(AH21,AH20)=2,AH21-AH20,"") | AM21: =IF(COUNT(AK21,AK20)=2,AK21-AK20,"")
B22: 15th | D22: 830132 | F22: =IF(COUNT(D21,D22)=2,D22-D21,"") -> 395 | G22: 843498 | I22: =IF(COUNT(G21,G22)=2,G22-G21,"") -> 482 | J22: 855729 | L22: =IF(COUNT(J22,J21)=2,J22-J21,"") -> 514 | M22: 870887 | O22: =IF(COUNT(M21,M22)=2,M22-M21,"") -> 439 | P22: 887067 | R22: =IF(COUNT(P21,P22)=2,P22-P21,"") -> 729 | S22: 910142 | U22: =IF(COUNT(S21,S22)=2,S22-S21,"") -> 756 | V22: 928642 | X22: =IF(COUNT(V22,V21)=2,V22-V21,"") -> 311 | AA22: =IF(COUNT(Y21,Y22)=2,Y22-Y21,"") | AD22: =IF(COUNT(AB21,AB22)=2,AB22-AB21,"") | AG22: =IF(COUNT(AE22,AE21)=2,AE22-AE21,"") | AJ22: =IF(COUNT(AH22,AH21)=2,AH22-AH21,"") | AM22: =IF(COUNT(AK22,AK21)=2,AK22-AK21,"")
B23: 16th | D23: 830674 | F23: =IF(COUNT(D22,D23)=2,D23-D22,"") -> 542 | G23: 843841 | I23: =IF(COUNT(G22,G23)=2,G23-G22,"") -> 343 | J23: 856156 | L23: =IF(COUNT(J23,J22)=2,J23-J22,"") -> 427 | M23: 871379 | O23: =IF(COUNT(M22,M23)=2,M23-M22,"") -> 492 | P23: 887880 | R23: =IF(COUNT(P22,P23)=2,P23-P22,"") -> 813 | S23: 910852 | U23: =IF(COUNT(S22,S23)=2,S23-S22,"") -> 710 | V23: 929009 | X23: =IF(COUNT(V23,V22)=2,V23-V22,"") -> 367 | AA23: =IF(COUNT(Y22,Y23)=2,Y23-Y22,"") | AD23: =IF(COUNT(AB22,AB23)=2,AB23-AB22,"") | AG23: =IF(COUNT(AE23,AE22)=2,AE23-AE22,"") | AJ23: =IF(COUNT(AH23,AH22)=2,AH23-AH22,"") | AM23: =IF(COUNT(AK23,AK22)=2,AK23-AK22,"")
B24: 17th | D24: 831026 | F24: =IF(COUNT(D23,D24)=2,D24-D23,"") -> 352 | G24: 844245 | I24: =IF(COUNT(G23,G24)=2,G24-G23,"") -> 404 | J24: 856575 | L24: =IF(COUNT(J24,J23)=2,J24-J23,"") -> 419 | M24: 871872 | O24: =IF(COUNT(M23,M24)=2,M24-M23,"") -> 493 | P24: 888629 | R24: =IF(COUNT(P23,P24)=2,P24-P23,"") -> 749 | S24: 911543 | U24: =IF(COUNT(S23,S24)=2,S24-S23,"") -> 691 | V24: 929361 | X24: =IF(COUNT(V24,V23)=2,V24-V23,"") -> 352 | AA24: =IF(COUNT(Y23,Y24)=2,Y24-Y23,"") | AD24: =IF(COUNT(AB23,AB24)=2,AB24-AB23,"") | AG24: =IF(COUNT(AE24,AE23)=2,AE24-AE23,"") | AJ24: =IF(COUNT(AH24,AH23)=2,AH24-AH23,"") | AM24: =IF(COUNT(AK24,AK23)=2,AK24-AK23,"")
B25: 18th | D25: 831417 | F25: =IF(COUNT(D24,D25)=2,D25-D24,"") -> 391 | G25: 844710 | I25: =IF(COUNT(G24,G25)=2,G25-G24,"") -> 465 | J25: 857020 | L25: =IF(COUNT(J25,J24)=2,J25-J24,"") -> 445 | M25: 872489 | O25: =IF(COUNT(M24,M25)=2,M25-M24,"") -> 617 | P25: 889300 | R25: =IF(COUNT(P24,P25)=2,P25-P24,"") -> 671 | S25: 912245 | U25: =IF(COUNT(S24,S25)=2,S25-S24,"") -> 702 | V25: 929818 | X25: =IF(COUNT(V25,V24)=2,V25-V24,"") -> 457 | AA25: =IF(COUNT(Y24,Y25)=2,Y25-Y24,"") | AD25: =IF(COUNT(AB24,AB25)=2,AB25-AB24,"") | AG25: =IF(COUNT(AE25,AE24)=2,AE25-AE24,"") | AJ25: =IF(COUNT(AH25,AH24)=2,AH25-AH24,"") | AM25: =IF(COUNT(AK25,AK24)=2,AK25-AK24,"")
B26: 19th | D26: 831810 | F26: =IF(COUNT(D25,D26)=2,D26-D25,"") -> 393 | G26: 845119 | I26: =IF(COUNT(G25,G26)=2,G26-G25,"") -> 409 | J26: 857501 | L26: =IF(COUNT(J26,J25)=2,J26-J25,"") -> 481 | M26: 872987 | O26: =IF(COUNT(M25,M26)=2,M26-M25,"") -> 498 | P26: 890051 | R26: =IF(COUNT(P25,P26)=2,P26-P25,"") -> 751 | S26: 913059 | U26: =IF(COUNT(S25,S26)=2,S26-S25,"") -> 814 | V26: 930316 | X26: =IF(COUNT(V26,V25)=2,V26-V25,"") -> 498 | AA26: =IF(COUNT(Y25,Y26)=2,Y26-Y25,"") | AD26: =IF(COUNT(AB25,AB26)=2,AB26-AB25,"") | AG26: =IF(COUNT(AE26,AE25)=2,AE26-AE25,"") | AJ26: =IF(COUNT(AH26,AH25)=2,AH26-AH25,"") | AM26: =IF(COUNT(AK26,AK25)=2,AK26-AK25,"")
B27: 20th | D27: 832209 | F27: =IF(COUNT(D26,D27)=2,D27-D26,"") -> 399 | G27: 845601 | I27: =IF(COUNT(G26,G27)=2,G27-G26,"") -> 482 | J27: 857947 | L27: =IF(COUNT(J27,J26)=2,J27-J26,"") -> 446 | M27: 873439 | O27: =IF(COUNT(M26,M27)=2,M27-M26,"") -> 452 | P27: 890782 | R27: =IF(COUNT(P26,P27)=2,P27-P26,"") -> 731 | S27: 913935 | U27: =IF(COUNT(S26,S27)=2,S27-S26,"") -> 876 | V27: 930741 | X27: =IF(COUNT(V27,V26)=2,V27-V26,"") -> 425 | AA27: =IF(COUNT(Y26,Y27)=2,Y27-Y26,"") | AD27: =IF(COUNT(AB26,AB27)=2,AB27-AB26,"") | AG27: =IF(COUNT(AE27,AE26)=2,AE27-AE26,"") | AJ27: =IF(COUNT(AH27,AH26)=2,AH27-AH26,"") | AM27: =IF(COUNT(AK27,AK26)=2,AK27-AK26,"")
B28: 21st | D28: 832605 | F28: =IF(COUNT(D27,D28)=2,D28-D27,"") -> 396 | G28: 846051 | I28: =IF(COUNT(G27,G28)=2,G28-G27,"") -> 450 | J28: 858435 | L28: =IF(COUNT(J28,J27)=2,J28-J27,"") -> 488 | M28: 873963 | O28: =IF(COUNT(M27,M28)=2,M28-M27,"") -> 524 | P28: 891580 | R28: =IF(COUNT(P27,P28)=2,P28-P27,"") -> 798 | S28: 914860 | U28: =IF(COUNT(S27,S28)=2,S28-S27,"") -> 925 | V28: 931282 | X28: =IF(COUNT(V28,V27)=2,V28-V27,"") -> 541 | AA28: =IF(COUNT(Y27,Y28)=2,Y28-Y27,"") | AD28: =IF(COUNT(AB27,AB28)=2,AB28-AB27,"") | AG28: =IF(COUNT(AE28,AE27)=2,AE28-AE27,"") | AJ28: =IF(COUNT(AH28,AH27)=2,AH28-AH27,"") | AM28: =IF(COUNT(AK28,AK27)=2,AK28-AK27,"")
B29: 22nd | D29: 833020 | F29: =IF(COUNT(D28,D29)=2,D29-D28,"") -> 415 | G29: 846402 | I29: =IF(COUNT(G28,G29)=2,G29-G28,"") -> 351 | J29: 858935 | L29: =IF(COUNT(J29,J28)=2,J29-J28,"") -> 500 | M29: 874633 | O29: =IF(COUNT(M28,M29)=2,M29-M28,"") -> 670 | P29: 892283 | R29: =IF(COUNT(P28,P29)=2,P29-P28,"") -> 703 | S29: 915621 | U29: =IF(COUNT(S28,S29)=2,S29-S28,"") -> 761 | V29: 931694 | X29: =IF(COUNT(V29,V28)=2,V29-V28,"") -> 412 | AA29: =IF(COUNT(Y28,Y29)=2,Y29-Y28,"") | AD29: =IF(COUNT(AB28,AB29)=2,AB29-AB28,"") | AG29: =IF(COUNT(AE29,AE28)=2,AE29-AE28,"") | AJ29: =IF(COUNT(AH29,AH28)=2,AH29-AH28,"") | AM29: =IF(COUNT(AK29,AK28)=2,AK29-AK28,"")
B30: 23rd | D30: 833501 | F30: =IF(COUNT(D29,D30)=2,D30-D29,"") -> 481 | G30: 846816 | I30: =IF(COUNT(G29,G30)=2,G30-G29,"") -> 414 | J30: 859426 | L30: =IF(COUNT(J30,J29)=2,J30-J29,"") -> 491 | M30: 875259 | O30: =IF(COUNT(M29,M30)=2,M30-M29,"") -> 626 | P30: 892999 | R30: =IF(COUNT(P29,P30)=2,P30-P29,"") -> 716 | S30: 916202 | U30: =IF(COUNT(S29,S30)=2,S30-S29,"") -> 581 | V30: 932014 | X30: =IF(COUNT(V30,V29)=2,V30-V29,"") -> 320 | AA30: =IF(COUNT(Y29,Y30)=2,Y30-Y29,"") | AD30: =IF(COUNT(AB29,AB30)=2,AB30-AB29,"") | AG30: =IF(COUNT(AE30,AE29)=2,AE30-AE29,"") | AJ30: =IF(COUNT(AH30,AH29)=2,AH30-AH29,"") | AM30: =IF(COUNT(AK30,AK29)=2,AK30-AK29,"")
... B35: 28th | D35: 835612 | F35: =IF(COUNT(D34,D35)=2,D35-D34,"") -> 324 | G35: 849036 | I35: =IF(COUNT(G34,G35)=2,G35-G34,"") -> 432 | J35: 861840 | L35: =IF(COUNT(J35,J34)=2,J35-J34,"") -> 462 | M35: 877967 | O35: =IF(COUNT(M34,M35)=2,M35-M34,"") -> 478 | P35: 896472 | R35: =IF(COUNT(P34,P35)=2,P35-P34,"") -> 902 | S35: 919239 | U35: =IF(COUNT(S34,S35)=2,S35-S34,"") -> 1036 | V35: 933555 | X35: =IF(COUNT(V35,V34)=2,V35-V34,"") -> 245 | AA35: =IF(COUNT(Y34,Y35)=2,Y35-Y34,"") | AD35: =IF(COUNT(AB34,AB35)=2,AB35-AB34,"") | AG35: =IF(COUNT(AE35,AE34)=2,AE35-AE34,"") | AJ35: =IF(COUNT(AH35,AH34)=2,AH35-AH34,"") | AM35: =IF(COUNT(AK35,AK34)=2,AK35-AK34,"")
B36: 29th | D36: 836092 | F36: =IF(COUNT(D35,D36)=2,D36-D35,"") -> 480 | I36: =IF(COUNT(G35,G36)=2,G36-G35,"") | J36: 862301 | L36: =IF(COUNT(J36,J35)=2,J36-J35,"") -> 461 | M36: 878502 | O36: =IF(COUNT(M35,M36)=2,M36-M35,"") -> 535 | P36: 897388 | R36: =IF(COUNT(P35,P36)=2,P36-P35,"") -> 916 | S36: 919787 | U36: =IF(COUNT(S35,S36)=2,S36-S35,"") -> 548 | V36: 933935 | X36: =IF(COUNT(V36,V35)=2,V36-V35,"") -> 380 | AA36: =IF(COUNT(Y35,Y36)=2,Y36-Y35,"") | AD36: =IF(COUNT(AB35,AB36)=2,AB36-AB35,"") | AG36: =IF(COUNT(AE36,AE35)=2,AE36-AE35,"") | AJ36: =IF(COUNT(AH36,AH35)=2,AH36-AH35,"") | AM36: =IF(COUNT(AK36,AK35)=2,AK36-AK35,"")
B37: 30th | D37: 836477 | F37: =IF(COUNT(D36,D37)=2,D37-D36,"") -> 385 | J37: 862746 | L37: =IF(COUNT(J37,J36)=2,J37-J36,"") -> 445 | M37: 879032 | O37: =IF(COUNT(M36,M37)=2,M37-M36,"") -> 530 | P37: 898184 | R37: =IF(COUNT(P36,P37)=2,P37-P36,"") -> 796 | S37: 920385 | U37: =IF(COUNT(S36,S37)=2,S37-S36,"") -> 598 | V37: 934319 | X37: =IF(COUNT(V37,V36)=2,V37-V36,"") -> 384 | AA37: =IF(COUNT(Y36,Y37)=2,Y37-Y36,"") | AD37: =IF(COUNT(AB36,AB37)=2,AB37-AB36,"") | AG37: =IF(COUNT(AE37,AE36)=2,AE37-AE36,"") | AJ37: =IF(COUNT(AH37,AH36)=2,AH37-AH36,"") | AM37: =IF(COUNT(AK37,AK36)=2,AK37-AK36,"")
B38: 31st | D38: 836906 | F38: =IF(COUNT(D37,D38)=2,D38-D37,"") -> 429 | J38: 863204 | L38: =IF(COUNT(J38,J37)=2,J38-J37,"") -> 458 | P38: 898870 | R38: =IF(COUNT(P37,P38)=2,P38-P37,"") -> 686 | V38: 934633 | X38: =IF(COUNT(V38,V37)=2,V38-V37,"") -> 314 | AA38: =IF(COUNT(Y37,Y38)=2,Y38-Y37,"") | AG38: =IF(COUNT(AE38,AE37)=2,AE38-AE37,"") | AM38: =IF(COUNT(AK38,AK37)=2,AK38-AK37,"")
B39: Total for Month (m3) | F39: =SUM(F8:F38) -> 13176 | I39: =SUM(I8:I36) -> 12130 | L39: =SUM(L8:L38) -> 14168 | O39: =SUM(O8:O37) -> 15734 | R39: =SUM(R8:R38) -> 19838 | U39: =SUM(U8:U37) -> 21515 | X39: =SUM(X8:X38) -> 14248 | AA39: =SUM(AA8:AA38) -> 260 | AD39: =SUM(AD8:AD37) -> 0 | AG39: =SUM(AG8:AG38) -> 0 | AJ39: =SUM(AJ8:AJ37) -> 0 | AM39: =SUM(AM8:AM38) -> 0

Sheet Electric
B3: December 31st
B4: Meter 1 | D4: Meter 2
B5: 5914.3 | D5: 2312.9
B7: Meter Readings
B9: Date | D9: Jan | H9: kwh | I9: Feb | M9: kwh | N9: Mar | R9: kwh | S9: Apr | W9: kwh | X9: May | AB9: kwh | AC9: Jun | AG9: kwh | AH9: Jul | AL9: kwh | AM9: Aug | AQ9: kwh | AR9: Sep | AV9: kwh | AW9: Oct | BA9: kwh | BB9: Nov | BF9: kwh | BG9: Dec | BK9: kwh
D10: Meter 1 | F10: Meter 2 | I10: Meter 1 | K10: Meter 2 | N10: Meter 1 | P10: Meter 2 | S10: Meter 1 | U10: Meter 2 | X10: Meter 1 | Z10: Meter 2 | AC10: Meter 1 | AE10: Meter 2 | AH10: Meter 1 | AJ10: Meter 2 | AM10: Meter 1 | AO10: Meter 2 | AR10: Meter 1 | AT10: Meter 2 | AW10: Meter 1 | AY10: Meter 2 | BB10: Meter 1 | BD10: Meter 2 | BG10: Meter 1 | BI10: Meter 2
B11: 1st | D11: 5944.1 | F11: 2326.1 | H11: =IF(COUNT(B5,D5,D11,F11)=4,(D11+F11)-(B5+D5),"") -> 43 | I11: 6726.5 | K11: 2817.5 | M11: =IF(COUNT(D41,F41,I11,K11)=4,(I11+K11)-(D41+F41),"") -> 47.6 | N11: 7455.8 | P11: 3271.5 | R11: =IF(COUNT(I38,K38,N11,P11)=4,(N11+P11)-(I38+K38),"") -> 48.8 | S11: 8279.2 | U11: 3727.5 | W11: =IF(COUNT(N41,P41,S11,U11)=4,(S11+U11)-(N41+P41),"") -> 40.3 | X11: 9080.9 | Z11: 4121.1 | AB11: =IF(COUNT(S40,U40,X11,Z11)=4,(X11+Z11)-(S40+U40),"") -> 38.2 | AC11: 9931.9 | AE11: 4454.1 | AG11: =IF(COUNT(X41,Z41,AC11,AE11)=4,(AC11+AE11)-(X41+Z41),"") -> 27.4 | AH11: 10700.8 | AJ11: 4700.5 | AL11: =IF(COUNT(AC40,AE40,AH11,AJ11)=4,(AH11+AJ11)-(AC40+AE40),"") -> 26.3 | AM11: 11214.7 | AO11: 4850.3 | AQ11: =IF(COUNT(AH41,AJ41,AM11,AO11)=4,(AM11+AO11)-(AH41+AJ41),"") -> 16.9 | AV11: =IF(COUNT(AM41,AO41,AR11,AT11)=4,(AR11+AT11)-(AM41+AO41),"") | BA11: =IF(COUNT(AR40,AT40,AW11,AY11)=4,(AW11+AY11)-(AR40+AT40),"") | BF11: =IF(COUNT(AW41,AY41,BB11,BD11)=4,(BB11+BD11)-(AW41+AY41),"") | BK11: =IF(COUNT(BB40,BD40,BG11,BI11)=4,(BG11+BI11)-(BB40+BD40),"")
B12: 2nd | D12: 5966.2 | F12: 2335.6 | H12: =IF(COUNT(D11,D12,F11,F12)=4,(D12+F12)-(D11+F11),"") -> 31.6 | I12: 6750.3 | K12: 2829.7 | M12: =IF(COUNT(I11,I12,K11,K12)=4,(I12+K12)-(I11+K11),"") -> 36 | N12: 7481 | P12: 3286 | R12: =IF(COUNT(N11,N12,P11,P12)=4,(N12+P12)-(N11+P11),"") -> 39.7 | S12: 8304.9 | U12: 3742.5 | W12: =IF(COUNT(S11,S12,U11,U12)=4,(S12+U12)-(S11+U11),"") -> 40.7 | X12: 9108.1 | Z12: 4134.2 | AB12: =IF(COUNT(X11,X12,Z11,Z12)=4,(X12+Z12)-(X11+Z11),"") -> 40.3 | AC12: 9958.4 | AE12: 4463.5 | AG12: =IF(COUNT(AC11,AC12,AE11,AE12)=4,(AC12+AE12)-(AC11+AE11),"") -> 35.9 | AH12: 10721.1 | AJ12: 4706.9 | AL12: =IF(COUNT(AH11,AH12,AJ11,AJ12)=4,(AH12+AJ12)-(AH11+AJ11),"") -> 26.7 | AQ12: =IF(COUNT(AM11,AM12,AO11,AO12)=4,(AM12+AO12)-(AM11+AO11),"") | AV12: =IF(COUNT(AR11,AR12,AT11,AT12)=4,(AR12+AT12)-(AR11+AT11),"") | BA12: =IF(COUNT(AW11,AW12,AY11,AY12)=4,(AW12+AY12)-(AW11+AY11),"") | BF12: =IF(COUNT(BB11,BB12,BD11,BD12)=4,(BB12+BD12)-(BB11+BD11),"") | BK12: =IF(COUNT(BG11,BG12,BI11,BI12)=4,(BG12+BI12)-(BG11+BI11),"")
B13: 3rd | D13: 5991.2 | F13: 2349.6 | H13: =IF(COUNT(D12,D13,F12,F13)=4,(D13+F13)-(D12+F12),"") -> 39 | I13: 6772.8 | K13: 2841.1 | M13: =IF(COUNT(I12,I13,K12,K13)=4,(I13+K13)-(I12+K12),"") -> 33.9 | N13: 7511 | P13: 3300.4 | R13: =IF(COUNT(N12,N13,P12,P13)=4,(N13+P13)-(N12+P12),"") -> 44.4 | S13: 8331.4 | U13: 3758.8 | W13: =IF(COUNT(S12,S13,U12,U13)=4,(S13+U13)-(S12+U12),"") -> 42.8 | X13: 9134.8 | Z13: 4146.4 | AB13: =IF(COUNT(X12,X13,Z12,Z13)=4,(X13+Z13)-(X12+Z12),"") -> 38.9 | AC13: 9985.5 | AE13: 4472.8 | AG13: =IF(COUNT(AC12,AC13,AE12,AE13)=4,(AC13+AE13)-(AC12+AE12),"") -> 36.4 | AH13: 10741 | AJ13: 4713.1 | AL13: =IF(COUNT(AH12,AH13,AJ12,AJ13)=4,(AH13+AJ13)-(AH12+AJ12),"") -> 26.1 | AQ13: =IF(COUNT(AM12,AM13,AO12,AO13)=4,(AM13+AO13)-(AM12+AO12),"") | AV13: =IF(COUNT(AR12,AR13,AT12,AT13)=4,(AR13+AT13)-(AR12+AT12),"") | BA13: =IF(COUNT(AW12,AW13,AY12,AY13)=4,(AW13+AY13)-(AW12+AY12),"") | BF13: =IF(COUNT(BB12,BB13,BD12,BD13)=4,(BB13+BD13)-(BB12+BD12),"") | BK13: =IF(COUNT(BG12,BG13,BI12,BI13)=4,(BG13+BI13)-(BG12+BI12),"")
B14: 4th | D14: 6019.5 | F14: 2367 | H14: =IF(COUNT(D13,D14,F13,F14)=4,(D14+F14)-(D13+F13),"") -> 45.7 | I14: 6794.5 | K14: 2856.1 | M14: =IF(COUNT(I13,I14,K13,K14)=4,(I14+K14)-(I13+K13),"") -> 36.7 | N14: 7531.3 | P14: 3312.3 | R14: =IF(COUNT(N13,N14,P13,P14)=4,(N14+P14)-(N13+P13),"") -> 32.2 | S14: 8359.8 | U14: 3777 | W14: =IF(COUNT(S13,S14,U13,U14)=4,(S14+U14)-(S13+U13),"") -> 46.6 | X14: 9162.7 | Z14: 4157.4 | AB14: =IF(COUNT(X13,X14,Z13,Z14)=4,(X14+Z14)-(X13+Z13),"") -> 38.9 | AC14: 10012.7 | AE14: 4482.1 | AG14: =IF(COUNT(AC13,AC14,AE13,AE14)=4,(AC14+AE14)-(AC13+AE13),"") -> 36.5 | AH14: 10762.9 | AJ14: 4719.8 | AL14: =IF(COUNT(AH13,AH14,AJ13,AJ14)=4,(AH14+AJ14)-(AH13+AJ13),"") -> 28.6 | AQ14: =IF(COUNT(AM13,AM14,AO13,AO14)=4,(AM14+AO14)-(AM13+AO13),"") | AV14: =IF(COUNT(AR13,AR14,AT13,AT14)=4,(AR14+AT14)-(AR13+AT13),"") | BA14: =IF(COUNT(AW13,AW14,AY13,AY14)=4,(AW14+AY14)-(AW13+AY13),"") | BF14: =IF(COUNT(BB13,BB14,BD13,BD14)=4,(BB14+BD14)-(BB13+BD13),"") | BK14: =IF(COUNT(BG13,BG14,BI13,BI14)=4,(BG14+BI14)-(BG13+BI13),"")
B15: 5th | D15: 6045.7 | F15: 2383.8 | H15: =IF(COUNT(D14,D15,F14,F15)=4,(D15+F15)-(D14+F14),"") -> 43 | I15: 6822.1 | K15: 2877.7 | M15: =IF(COUNT(I14,I15,K14,K15)=4,(I15+K15)-(I14+K14),"") -> 49.2 | N15: 7557.7 | P15: 3326.5 | R15: =IF(COUNT(N14,N15,P14,P15)=4,(N15+P15)-(N14+P14),"") -> 40.6 | S15: 8383.4 | U15: 3792.9 | W15: =IF(COUNT(S14,S15,U14,U15)=4,(S15+U15)-(S14+U14),"") -> 39.5 | X15: 9190.2 | Z15: 4168.9 | AB15: =IF(COUNT(X14,X15,Z14,Z15)=4,(X15+Z15)-(X14+Z14),"") -> 39 | AC15: 10038.4 | AE15: 4490.7 | AG15: =IF(COUNT(AC14,AC15,AE14,AE15)=4,(AC15+AE15)-(AC14+AE14),"") -> 34.3 | AH15: 10783.7 | AJ15: 4726.2 | AL15: =IF(COUNT(AH14,AH15,AJ14,AJ15)=4,(AH15+AJ15)-(AH14+AJ14),"") -> 27.2 | AQ15: =IF(COUNT(AM14,AM15,AO14,AO15)=4,(AM15+AO15)-(AM14+AO14),"") | AV15: =IF(COUNT(AR14,AR15,AT14,AT15)=4,(AR15+AT15)-(AR14+AT14),"") | BA15: =IF(COUNT(AW14,AW15,AY14,AY15)=4,(AW15+AY15)-(AW14+AY14),"") | BF15: =IF(COUNT(BB14,BB15,BD14,BD15)=4,(BB15+BD15)-(BB14+BD14),"") | BK15: =IF(COUNT(BG14,BG15,BI14,BI15)=4,(BG15+BI15)-(BG14+BI14),"")
B16: 6th | D16: 6071.2 | F16: 2398.6 | H16: =IF(COUNT(D15,D16,F15,F16)=4,(D16+F16)-(D15+F15),"") -> 40.3 | I16: 6846.2 | K16: 2891.8 | M16: =IF(COUNT(I15,I16,K15,K16)=4,(I16+K16)-(I15+K15),"") -> 38.2 | N16: 7585.6 | P16: 3340.6 | R16: =IF(COUNT(N15,N16,P15,P16)=4,(N16+P16)-(N15+P15),"") -> 42 | S16: 8413.9 | U16: 3814.5 | W16: =IF(COUNT(S15,S16,U15,U16)=4,(S16+U16)-(S15+U15),"") -> 52.1 | X16: 9217.6 | Z16: 4182.6 | AB16: =IF(COUNT(X15,X16,Z15,Z16)=4,(X16+Z16)-(X15+Z15),"") -> 41.1 | AC16: 10063.7 | AE16: 4499.1 | AG16: =IF(COUNT(AC15,AC16,AE15,AE16)=4,(AC16+AE16)-(AC15+AE15),"") -> 33.7 | AH16: 10804.4 | AJ16: 4732.4 | AL16: =IF(COUNT(AH15,AH16,AJ15,AJ16)=4,(AH16+AJ16)-(AH15+AJ15),"") -> 26.9 | AQ16: =IF(COUNT(AM15,AM16,AO15,AO16)=4,(AM16+AO16)-(AM15+AO15),"") | AV16: =IF(COUNT(AR15,AR16,AT15,AT16)=4,(AR16+AT16)-(AR15+AT15),"") | BA16: =IF(COUNT(AW15,AW16,AY15,AY16)=4,(AW16+AY16)-(AW15+AY15),"") | BF16: =IF(COUNT(BB15,BB16,BD15,BD16)=4,(BB16+BD16)-(BB15+BD15),"") | BK16: =IF(COUNT(BG15,BG16,BI15,BI16)=4,(BG16+BI16)-(BG15+BI15),"")
B17: 7th | D17: 6094.4 | F17: 2409.5 | H17: =IF(COUNT(D16,D17,F16,F17)=4,(D17+F17)-(D16+F16),"") -> 34.1 | I17: 6872.3 | K17: 2909.2 | M17: =IF(COUNT(I16,I17,K16,K17)=4,(I17+K17)-(I16+K16),"") -> 43.5 | N17: 7612 | P17: 3355.6 | R17: =IF(COUNT(N16,N17,P16,P17)=4,(N17+P17)-(N16+P16),"") -> 41.4 | S17: 8439.6 | U17: 3831.6 | W17: =IF(COUNT(S16,S17,U16,U17)=4,(S17+U17)-(S16+U16),"") -> 42.8 | X17: 9242.7 | Z17: 4195.6 | AB17: =IF(COUNT(X16,X17,Z16,Z17)=4,(X17+Z17)-(X16+Z16),"") -> 38.1 | AC17: 10092.5 | AE17: 4508.3 | AG17: =IF(COUNT(AC16,AC17,AE16,AE17)=4,(AC17+AE17)-(AC16+AE16),"") -> 38 | AH17: 10824.7 | AJ17: 4738.4 | AL17: =IF(COUNT(AH16,AH17,AJ16,AJ17)=4,(AH17+AJ17)-(AH16+AJ16),"") -> 26.3 | AQ17: =IF(COUNT(AM16,AM17,AO16,AO17)=4,(AM17+AO17)-(AM16+AO16),"") | AV17: =IF(COUNT(AR16,AR17,AT16,AT17)=4,(AR17+AT17)-(AR16+AT16),"") | BA17: =IF(COUNT(AW16,AW17,AY16,AY17)=4,(AW17+AY17)-(AW16+AY16),"") | BF17: =IF(COUNT(BB16,BB17,BD16,BD17)=4,(BB17+BD17)-(BB16+BD16),"") | BK17: =IF(COUNT(BG16,BG17,BI16,BI17)=4,(BG17+BI17)-(BG16+BI16),"")
B18: 8th | D18: 6120.4 | F18: 2420.6 | H18: =IF(COUNT(D17,D18,F17,F18)=4,(D18+F18)-(D17+F17),"") -> 37.1 | I18: 6899.1 | K18: 2923.4 | M18: =IF(COUNT(I17,I18,K17,K18)=4,(I18+K18)-(I17+K17),"") -> 41 | N18: 7638.1 | P18: 3372.5 | R18: =IF(COUNT(N17,N18,P17,P18)=4,(N18+P18)-(N17+P17),"") -> 43 | S18: 8466.8 | U18: 3850.1 | W18: =IF(COUNT(S17,S18,U17,U18)=4,(S18+U18)-(S17+U17),"") -> 45.7 | X18: 9269.7 | Z18: 4208.9 | AB18: =IF(COUNT(X17,X18,Z17,Z18)=4,(X18+Z18)-(X17+Z17),"") -> 40.3 | AC18: 10118.4 | AE18: 4516.6 | AG18: =IF(COUNT(AC17,AC18,AE17,AE18)=4,(AC18+AE18)-(AC17+AE17),"") -> 34.2 | AH18: 10845.9 | AJ18: 4744.8 | AL18: =IF(COUNT(AH17,AH18,AJ17,AJ18)=4,(AH18+AJ18)-(AH17+AJ17),"") -> 27.6 | AQ18: =IF(COUNT(AM17,AM18,AO17,AO18)=4,(AM18+AO18)-(AM17+AO17),"") | AV18: =IF(COUNT(AR17,AR18,AT17,AT18)=4,(AR18+AT18)-(AR17+AT17),"") | BA18: =IF(COUNT(AW17,AW18,AY17,AY18)=4,(AW18+AY18)-(AW17+AY17),"") | BF18: =IF(COUNT(BB17,BB18,BD17,BD18)=4,(BB18+BD18)-(BB17+BD17),"") | BK18: =IF(COUNT(BG17,BG18,BI17,BI18)=4,(BG18+BI18)-(BG17+BI17),"")
B19: 9th | D19: 6150.1 | F19: 2435.7 | H19: =IF(COUNT(D18,D19,F18,F19)=4,(D19+F19)-(D18+F18),"") -> 44.8 | I19: 6920.3 | K19: 2934.8 | M19: =IF(COUNT(I18,I19,K18,K19)=4,(I19+K19)-(I18+K18),"") -> 32.6 | N19: 7664.7 | P19: 3390.1 | R19: =IF(COUNT(N18,N19,P18,P19)=4,(N19+P19)-(N18+P18),"") -> 44.2 | S19: 8494.1 | U19: 3866.2 | W19: =IF(COUNT(S18,S19,U18,U19)=4,(S19+U19)-(S18+U18),"") -> 43.4 | X19: 9295.6 | Z19: 4219.7 | AB19: =IF(COUNT(X18,X19,Z18,Z19)=4,(X19+Z19)-(X18+Z18),"") -> 36.7 | AC19: 10146.1 | AE19: 4525.1 | AG19: =IF(COUNT(AC18,AC19,AE18,AE19)=4,(AC19+AE19)-(AC18+AE18),"") -> 36.2 | AH19: 10864.1 | AJ19: 4750.2 | AL19: =IF(COUNT(AH18,AH19,AJ18,AJ19)=4,(AH19+AJ19)-(AH18+AJ18),"") -> 23.6 | AQ19: =IF(COUNT(AM18,AM19,AO18,AO19)=4,(AM19+AO19)-(AM18+AO18),"") | AV19: =IF(COUNT(AR18,AR19,AT18,AT19)=4,(AR19+AT19)-(AR18+AT18),"") | BA19: =IF(COUNT(AW18,AW19,AY18,AY19)=4,(AW19+AY19)-(AW18+AY18),"") | BF19: =IF(COUNT(BB18,BB19,BD18,BD19)=4,(BB19+BD19)-(BB18+BD18),"") | BK19: =IF(COUNT(BG18,BG19,BI18,BI19)=4,(BG19+BI19)-(BG18+BI18),"")
B20: 10th | D20: 6177.3 | F20: 2451.1 | H20: =IF(COUNT(D19,D20,F19,F20)=4,(D20+F20)-(D19+F19),"") -> 42.6 | I20: 6949.3 | K20: 2950.8 | M20: =IF(COUNT(I19,I20,K19,K20)=4,(I20+K20)-(I19+K19),"") -> 45 | N20: 7690.3 | P20: 3406.1 | R20: =IF(COUNT(N19,N20,P19,P20)=4,(N20+P20)-(N19+P19),"") -> 41.6 | S20: 8518.8 | U20: 3878.5 | W20: =IF(COUNT(S19,S20,U19,U20)=4,(S20+U20)-(S19+U19),"") -> 37 | X20: 9321.1 | Z20: 4231.2 | AB20: =IF(COUNT(X19,X20,Z19,Z20)=4,(X20+Z20)-(X19+Z19),"") -> 37 | AC20: 10173.8 | AE20: 4532.6 | AG20: =IF(COUNT(AC19,AC20,AE19,AE20)=4,(AC20+AE20)-(AC19+AE19),"") -> 35.2 | AH20: 10881.7 | AJ20: 4755.5 | AL20: =IF(COUNT(AH19,AH20,AJ19,AJ20)=4,(AH20+AJ20)-(AH19+AJ19),"") -> 22.9 | AQ20: =IF(COUNT(AM19,AM20,AO19,AO20)=4,(AM20+AO20)-(AM19+AO19),"") | AV20: =IF(COUNT(AR19,AR20,AT19,AT20)=4,(AR20+AT20)-(AR19+AT19),"") | BA20: =IF(COUNT(AW19,AW20,AY19,AY20)=4,(AW20+AY20)-(AW19+AY19),"") | BF20: =IF(COUNT(BB19,BB20,BD19,BD20)=4,(BB20+BD20)-(BB19+BD19),"") | BK20: =IF(COUNT(BG19,BG20,BI19,BI20)=4,(BG20+BI20)-(BG19+BI19),"")
B21: 11th | D21: 6198.3 | F21: 2463.6 | H21: =IF(COUNT(D20,D21,F20,F21)=4,(D21+F21)-(D20+F20),"") -> 33.5 | I21: 6977.8 | K21: 2967.6 | M21: =IF(COUNT(I20,I21,K20,K21)=4,(I21+K21)-(I20+K20),"") -> 45.3 | N21: 7717.7 | P21: 3424.1 | R21: =IF(COUNT(N20,N21,P20,P21)=4,(N21+P21)-(N20+P20),"") -> 45.4 | S21: 8548.2 | U21: 3890.4 | W21: =IF(COUNT(S20,S21,U20,U21)=4,(S21+U21)-(S20+U20),"") -> 41.3 | X21: 9347.5 | Z21: 4242.5 | AB21: =IF(COUNT(X20,X21,Z20,Z21)=4,(X21+Z21)-(X20+Z20),"") -> 37.7 | AC21: 10202.7 | AE21: 4541.1 | AG21: =IF(COUNT(AC20,AC21,AE20,AE21)=4,(AC21+AE21)-(AC20+AE20),"") -> 37.4 | AH21: 10899.9 | AJ21: 4761.2 | AL21: =IF(COUNT(AH20,AH21,AJ20,AJ21)=4,(AH21+AJ21)-(AH20+AJ20),"") -> 23.9 | AQ21: =IF(COUNT(AM20,AM21,AO20,AO21)=4,(AM21+AO21)-(AM20+AO20),"") | AV21: =IF(COUNT(AR20,AR21,AT20,AT21)=4,(AR21+AT21)-(AR20+AT20),"") | BA21: =IF(COUNT(AW20,AW21,AY20,AY21)=4,(AW21+AY21)-(AW20+AY20),"") | BF21: =IF(COUNT(BB20,BB21,BD20,BD21)=4,(BB21+BD21)-(BB20+BD20),"") | BK21: =IF(COUNT(BG20,BG21,BI20,BI21)=4,(BG21+BI21)-(BG20+BI20),"")
B22: 12th | D22: 6220.5 | F22: 2478.6 | H22: =IF(COUNT(D21,D22,F21,F22)=4,(D22+F22)-(D21+F21),"") -> 37.2 | I22: 6999.6 | K22: 2982.6 | M22: =IF(COUNT(I21,I22,K21,K22)=4,(I22+K22)-(I21+K21),"") -> 36.8 | N22: 7744.6 | P22: 3443.1 | R22: =IF(COUNT(N21,N22,P21,P22)=4,(N22+P22)-(N21+P21),"") -> 45.9 | S22: 8574.6 | U22: 3901.3 | W22: =IF(COUNT(S21,S22,U21,U22)=4,(S22+U22)-(S21+U21),"") -> 37.3 | X22: 9372.7 | Z22: 4253.1 | AB22: =IF(COUNT(X21,X22,Z21,Z22)=4,(X22+Z22)-(X21+Z21),"") -> 35.8 | AC22: 10229.1 | AE22: 4549 | AG22: =IF(COUNT(AC21,AC22,AE21,AE22)=4,(AC22+AE22)-(AC21+AE21),"") -> 34.3 | AH22: 10916.1 | AJ22: 4766.1 | AL22: =IF(COUNT(AH21,AH22,AJ21,AJ22)=4,(AH22+AJ22)-(AH21+AJ21),"") -> 21.1 | AQ22: =IF(COUNT(AM21,AM22,AO21,AO22)=4,(AM22+AO22)-(AM21+AO21),"") | AV22: =IF(COUNT(AR21,AR22,AT21,AT22)=4,(AR22+AT22)-(AR21+AT21),"") | BA22: =IF(COUNT(AW21,AW22,AY21,AY22)=4,(AW22+AY22)-(AW21+AY21),"") | BF22: =IF(COUNT(BB21,BB22,BD21,BD22)=4,(BB22+BD22)-(BB21+BD21),"") | BK22: =IF(COUNT(BG21,BG22,BI21,BI22)=4,(BG22+BI22)-(BG21+BI21),"")
B23: 13th | D23: 6246.7 | F23: 2497.6 | H23: =IF(COUNT(D22,D23,F22,F23)=4,(D23+F23)-(D22+F22),"") -> 45.2 | I23: 7030.2 | K23: 3001.8 | M23: =IF(COUNT(I22,I23,K22,K23)=4,(I23+K23)-(I22+K22),"") -> 49.8 | N23: 7769.3 | P23: 3463 | R23: =IF(COUNT(N22,N23,P22,P23)=4,(N23+P23)-(N22+P22),"") -> 44.6 | S23: 8601.8 | U23: 3913.1 | W23: =IF(COUNT(S22,S23,U22,U23)=4,(S23+U23)-(S22+U22),"") -> 39 | X23: 9397.5 | Z23: 4264 | AB23: =IF(COUNT(X22,X23,Z22,Z23)=4,(X23+Z23)-(X22+Z22),"") -> 35.7 | AC23: 10260.4 | AE23: 4558.3 | AG23: =IF(COUNT(AC22,AC23,AE22,AE23)=4,(AC23+AE23)-(AC22+AE22),"") -> 40.6 | AH23: 10933.9 | AJ23: 4771.5 | AL23: =IF(COUNT(AH22,AH23,AJ22,AJ23)=4,(AH23+AJ23)-(AH22+AJ22),"") -> 23.2 | AQ23: =IF(COUNT(AM22,AM23,AO22,AO23)=4,(AM23+AO23)-(AM22+AO22),"") | AV23: =IF(COUNT(AR22,AR23,AT22,AT23)=4,(AR23+AT23)-(AR22+AT22),"") | BA23: =IF(COUNT(AW22,AW23,AY22,AY23)=4,(AW23+AY23)-(AW22+AY22),"") | BF23: =IF(COUNT(BB22,BB23,BD22,BD23)=4,(BB23+BD23)-(BB22+BD22),"") | BK23: =IF(COUNT(BG22,BG23,BI22,BI23)=4,(BG23+BI23)-(BG22+BI22),"")
... B38: 28th | D38: 6621.2 | F38: 2748.8 | H38: =IF(COUNT(D37,D38,F37,F38)=4,(D38+F38)-(D37+F37),"") -> 32.2 | I38: 7428.4 | K38: 3250.1 | M38: =IF(COUNT(I37,I38,K37,K38)=4,(I38+K38)-(I37+K37),"") -> 42.3 | N38: 8175.1 | P38: 3676.5 | R38: =IF(COUNT(N37,N38,P37,P38)=4,(N38+P38)-(N37+P37),"") -> 40.2 | S38: 8999.4 | U38: 4085.1 | W38: =IF(COUNT(S37,S38,U37,U38)=4,(S38+U38)-(S37+U37),"") -> 39.9 | X38: 9822.4 | Z38: 4418.9 | AB38: =IF(COUNT(X37,X38,Z37,Z38)=4,(X38+Z38)-(X37+Z37),"") -> 40.8 | AC38: 10642.3 | AE38: 4682.5 | AG38: =IF(COUNT(AC37,AC38,AE37,AE38)=4,(AC38+AE38)-(AC37+AE37),"") -> 37.4 | AH38: 11158.9 | AJ38: 4834.2 | AL38: =IF(COUNT(AH37,AH38,AJ37,AJ38)=4,(AH38+AJ38)-(AH37+AJ37),"") -> 17.6 | AQ38: =IF(COUNT(AM37,AM38,AO37,AO38)=4,(AM38+AO38)-(AM37+AO37),"") | AV38: =IF(COUNT(AR37,AR38,AT37,AT38)=4,(AR38+AT38)-(AR37+AT37),"") | BA38: =IF(COUNT(AW37,AW38,AY37,AY38)=4,(AW38+AY38)-(AW37+AY37),"") | BF38: =IF(COUNT(BB37,BB38,BD37,BD38)=4,(BB38+BD38)-(BB37+BD37),"") | BK38: =IF(COUNT(BG37,BG38,BI37,BI38)=4,(BG38+BI38)-(BG37+BI37),"")
B39: 29th | D39: 6651.2 | F39: 2766.3 | H39: =IF(COUNT(D38,D39,F38,F39)=4,(D39+F39)-(D38+F38),"") -> 47.5 | M39: =IF(COUNT(I38,I39,K38,K39)=4,(I39+K39)-(I38+K38),"") | N39: 8201.1 | P39: 3691 | R39: =IF(COUNT(N38,N39,P38,P39)=4,(N39+P39)-(N38+P38),"") -> 40.5 | S39: 9026.8 | U39: 4096.4 | W39: =IF(COUNT(S38,S39,U38,U39)=4,(S39+U39)-(S38+U38),"") -> 38.7 | X39: 9852.9 | Z39: 4428.5 | AB39: =IF(COUNT(X38,X39,Z38,Z39)=4,(X39+Z39)-(X38+Z38),"") -> 40.1 | AC39: 10659.2 | AE39: 4687.7 | AG39: =IF(COUNT(AC38,AC39,AE38,AE39)=4,(AC39+AE39)-(AC38+AE38),"") -> 22.1 | AH39: 11172.4 | AJ39: 4838 | AL39: =IF(COUNT(AH38,AH39,AJ38,AJ39)=4,(AH39+AJ39)-(AH38+AJ38),"") -> 17.3 | AQ39: =IF(COUNT(AM38,AM39,AO38,AO39)=4,(AM39+AO39)-(AM38+AO38),"") | AV39: =IF(COUNT(AR38,AR39,AT38,AT39)=4,(AR39+AT39)-(AR38+AT38),"") | BA39: =IF(COUNT(AW38,AW39,AY38,AY39)=4,(AW39+AY39)-(AW38+AY38),"") | BF39: =IF(COUNT(BB38,BB39,BD38,BD39)=4,(BB39+BD39)-(BB38+BD38),"") | BK39: =IF(COUNT(BG38,BG39,BI38,BI39)=4,(BG39+BI39)-(BG38+BI38),"")
B40: 30th | D40: 6672.9 | F40: 2782.6 | H40: =IF(COUNT(D39,D40,F39,F40)=4,(D40+F40)-(D39+F39),"") -> 38 | M40: =IF(COUNT(I39,I40)=2,I40-I39,"") | N40: 8225.8 | P40: 3702.3 | R40: =IF(COUNT(N39,N40,P39,P40)=4,(N40+P40)-(N39+P39),"") -> 36 | S40: 9055.2 | U40: 4108.6 | W40: =IF(COUNT(S39,S40,U39,U40)=4,(S40+U40)-(S39+U39),"") -> 40.6 | X40: 9878.8 | Z40: 4436.9 | AB40: =IF(COUNT(X39,X40,Z39,Z40)=4,(X40+Z40)-(X39+Z39),"") -> 34.3 | AC40: 10680.8 | AE40: 4694.2 | AG40: =IF(COUNT(AC39,AC40,AE39,AE40)=4,(AC40+AE40)-(AC39+AE39),"") -> 28.1 | AH40: 11186.2 | AJ40: 4841.8 | AL40: =IF(COUNT(AH39,AH40,AJ39,AJ40)=4,(AH40+AJ40)-(AH39+AJ39),"") -> 17.6 | AQ40: =IF(COUNT(AM39,AM40,AO39,AO40)=4,(AM40+AO40)-(AM39+AO39),"") | AV40: =IF(COUNT(AR39,AR40,AT39,AT40)=4,(AR40+AT40)-(AR39+AT39),"") | BA40: =IF(COUNT(AW39,AW40,AY39,AY40)=4,(AW40+AY40)-(AW39+AY39),"") | BF40: =IF(COUNT(BB39,BB40,BD39,BD40)=4,(BB40+BD40)-(BB39+BD39),"") | BK40: =IF(COUNT(BG39,BG40,BI39,BI40)=4,(BG40+BI40)-(BG39+BI39),"")
B41: 31st | D41: 6697.7 | F41: 2798.7 | H41: =IF(COUNT(D40,D41,F40,F41)=4,(D41+F41)-(D40+F40),"") -> 40.9 | M41: =IF(COUNT(I40,I41)=2,I41-I40,"") | N41: 8252.3 | P41: 3714.1 | R41: =IF(COUNT(N40,N41,P40,P41)=4,(N41+P41)-(N40+P40),"") -> 38.3 | X41: 9904.6 | Z41: 4454 | AB41: =IF(COUNT(X40,X41,Z40,Z41)=4,(X41+Z41)-(X40+Z40),"") -> 42.9 | AH41: 11201.9 | AJ41: 4846.2 | AL41: =IF(COUNT(AH40,AH41,AJ40,AJ41)=4,(AH41+AJ41)-(AH40+AJ40),"") -> 20.1 | AQ41: =IF(COUNT(AM40,AM41,AO40,AO41)=4,(AM41+AO41)-(AM40+AO40),"") | BA41: =IF(COUNT(AW40,AW41,AY40,AY41)=4,(AW41+AY41)-(AW40+AY40),"") | BK41: =IF(COUNT(BG40,BG41,BI40,BI41)=4,(BG41+BI41)-(BG40+BI40),"")
B42: Total for Month (kwh) | H42: =SUM(H11:H41)*400 -> 507680 | M42: =SUM(M11:M41)*400 -> 472840 | R42: =SUM(R10:R41)*400 -> 515160 | W42: =SUM(W11:W40)*400 -> 478960 | AB42: =SUM(AB11:AB41)*400 -> 477920 | AG42: =SUM(AG11:AG40)*400 -> 406560 | AL42: =SUM(AL11:AL41)*400 -> 269240 | AQ42: =SUM(AQ11:AQ41)*400 -> 6760 | AV42: =SUM(AV11:AV40)*400 -> 0 | BA42: =SUM(BA11:BA41)*400 -> 0 | BF42: =SUM(BF11:BF40)*400 -> 0 | BK42: =SUM(BK11:BK41)*400 -> 0

Sheet Water
B2: December 31st
B3: 356738
B5: Meter Readings
D7: Jan | F7: kL | G7: Feb | I7: kL | J7: Mar | L7: kL | M7: Apr | O7: kL | P7: May | R7: kL | S7: Jun | U7: kL | V7: Jul | X7: kL | Y7: Aug | AA7: kL | AB7: Sep | AD7: kL | AE7: Oct | AG7: kL | AH7: Nov | AJ7: kL | AK7: Dec | AM7: kL
B8: 1st | D8: 356880 | F8: =IF(COUNT(B3,D8)=2,D8-B3,"") -> 142 | G8: 361145 | I8: =IF(COUNT(D38,G8)=2,G8-D38,"") -> 178 | J8: 365466 | L8: =IF(COUNT(G35,J8)=2,J8-G35,"") -> 177 | M8: 370243 | O8: =IF(COUNT(J38,M8)=2,M8-J38,"") -> 136 | P8: 375422 | R8: =IF(COUNT(M37,P8)=2,P8-M37,"") -> 200 | S8: 379952 | U8: =IF(COUNT(P38,S8)=2,S8-P38,"") -> 102 | V8: 382874 | X8: =IF(COUNT(S37,V8)=2,V8-S37,"") -> 28 | Y8: 383764 | AA8: =IF(COUNT(V38,Y8)=2,Y8-V38,"") -> 21 | AD8: =IF(COUNT(Y38,AB8)=2,AB8-Y38,"") | AG8: =IF(COUNT(AB37,AE8)=2,AE8-AB37,"") | AJ8: =IF(COUNT(AE38,AH8)=2,AH8-AE38,"") | AM8: =IF(COUNT(AH37,AK8)=2,AK8-AH37,"")
B9: 2nd | D9: 357009 | F9: =IF(COUNT(D8,D9)=2,D9-D8,"") -> 129 | G9: 361250 | I9: =IF(COUNT(G8,G9)=2,G9-G8,"") -> 105 | J9: 365578 | L9: =IF(COUNT(J8,J9)=2,J9-J8,"") -> 112 | M9: 370435 | O9: =IF(COUNT(M8,M9)=2,M9-M8,"") -> 192 | P9: 375602 | R9: =IF(COUNT(P8,P9)=2,P9-P8,"") -> 180 | S9: 380061 | U9: =IF(COUNT(S8,S9)=2,S9-S8,"") -> 109 | V9: 382905 | X9: =IF(COUNT(V8,V9)=2,V9-V8,"") -> 31 | AA9: =IF(COUNT(Y8,Y9)=2,Y9-Y8,"") | AD9: =IF(COUNT(AB8,AB9)=2,AB9-AB8,"") | AG9: =IF(COUNT(AE8,AE9)=2,AE9-AE8,"") | AJ9: =IF(COUNT(AH8,AH9)=2,AH9-AH8,"") | AM9: =IF(COUNT(AK8,AK9)=2,AK9-AK8,"")
B10: 3rd | D10: 357114 | F10: =IF(COUNT(D9,D10)=2,D10-D9,"") -> 105 | G10: 361359 | I10: =IF(COUNT(G9,G10)=2,G10-G9,"") -> 109 | J10: 365739 | L10: =IF(COUNT(J9,J10)=2,J10-J9,"") -> 161 | M10: 370660 | O10: =IF(COUNT(M9,M10)=2,M10-M9,"") -> 225 | P10: 375734 | R10: =IF(COUNT(P9,P10)=2,P10-P9,"") -> 132 | S10: 380162 | U10: =IF(COUNT(S9,S10)=2,S10-S9,"") -> 101 | V10: 382932 | X10: =IF(COUNT(V9,V10)=2,V10-V9,"") -> 27 | AA10: =IF(COUNT(Y9,Y10)=2,Y10-Y9,"") | AD10: =IF(COUNT(AB9,AB10)=2,AB10-AB9,"") | AG10: =IF(COUNT(AE9,AE10)=2,AE10-AE9,"") | AJ10: =IF(COUNT(AH9,AH10)=2,AH10-AH9,"") | AM10: =IF(COUNT(AK9,AK10)=2,AK10-AK9,"")
B11: 4th | D11: 357284 | F11: =IF(COUNT(D10,D11)=2,D11-D10,"") -> 170 | G11: 361476 | I11: =IF(COUNT(G10,G11)=2,G11-G10,"") -> 117 | J11: 365897 | L11: =IF(COUNT(J10,J11)=2,J11-J10,"") -> 158 | M11: 370900 | O11: =IF(COUNT(M10,M11)=2,M11-M10,"") -> 240 | P11: 375883 | R11: =IF(COUNT(P10,P11)=2,P11-P10,"") -> 149 | S11: 380279 | U11: =IF(COUNT(S10,S11)=2,S11-S10,"") -> 117 | V11: 382960 | X11: =IF(COUNT(V10,V11)=2,V11-V10,"") -> 28 | AA11: =IF(COUNT(Y10,Y11)=2,Y11-Y10,"") | AD11: =IF(COUNT(AB10,AB11)=2,AB11-AB10,"") | AG11: =IF(COUNT(AE10,AE11)=2,AE11-AE10,"") | AJ11: =IF(COUNT(AH10,AH11)=2,AH11-AH10,"") | AM11: =IF(COUNT(AK10,AK11)=2,AK11-AK10,"")
B12: 5th | D12: 357431 | F12: =IF(COUNT(D11,D12)=2,D12-D11,"") -> 147 | G12: 361620 | I12: =IF(COUNT(G11,G12)=2,G12-G11,"") -> 144 | J12: 366051 | L12: =IF(COUNT(J11,J12)=2,J12-J11,"") -> 154 | M12: 371062 | O12: 162 | P12: 376020 | R12: =IF(COUNT(P11,P12)=2,P12-P11,"") -> 137 | S12: 380406 | U12: =IF(COUNT(S11,S12)=2,S12-S11,"") -> 127 | V12: 383010 | X12: =IF(COUNT(V11,V12)=2,V12-V11,"") -> 50 | AA12: =IF(COUNT(Y11,Y12)=2,Y12-Y11,"") | AD12: =IF(COUNT(AB11,AB12)=2,AB12-AB11,"") | AG12: =IF(COUNT(AE11,AE12)=2,AE12-AE11,"") | AJ12: =IF(COUNT(AH11,AH12)=2,AH12-AH11,"") | AM12: =IF(COUNT(AK11,AK12)=2,AK12-AK11,"")
B13: 6th | D13: 357554 | F13: =IF(COUNT(D12,D13)=2,D13-D12,"") -> 123 | G13: 361780 | I13: =IF(COUNT(G12,G13)=2,G13-G12,"") -> 160 | J13: 366214 | L13: =IF(COUNT(J12,J13)=2,J13-J12,"") -> 163 | M13: 371229 | O13: =IF(COUNT(M12,M13)=2,M13-M12,"") -> 167 | P13: 376184 | R13: =IF(COUNT(P12,P13)=2,P13-P12,"") -> 164 | S13: 380545 | U13: =IF(COUNT(S12,S13)=2,S13-S12,"") -> 139 | V13: 383055 | X13: =IF(COUNT(V12,V13)=2,V13-V12,"") -> 45 | AA13: =IF(COUNT(Y12,Y13)=2,Y13-Y12,"") | AD13: =IF(COUNT(AB12,AB13)=2,AB13-AB12,"") | AG13: =IF(COUNT(AE12,AE13)=2,AE13-AE12,"") | AJ13: =IF(COUNT(AH12,AH13)=2,AH13-AH12,"") | AM13: =IF(COUNT(AK12,AK13)=2,AK13-AK12,"")
B14: 7th | D14: 357682 | F14: =IF(COUNT(D13,D14)=2,D14-D13,"") -> 128 | G14: 361927 | I14: =IF(COUNT(G13,G14)=2,G14-G13,"") -> 147 | J14: 366399 | L14: =IF(COUNT(J13,J14)=2,J14-J13,"") -> 185 | M14: 371460 | O14: =IF(COUNT(M13,M14)=2,M14-M13,"") -> 231 | P14: 376325 | R14: =IF(COUNT(P13,P14)=2,P14-P13,"") -> 141 | S14: 380660 | U14: =IF(COUNT(S13,S14)=2,S14-S13,"") -> 115 | V14: 383093 | X14: =IF(COUNT(V13,V14)=2,V14-V13,"") -> 38 | AA14: =IF(COUNT(Y13,Y14)=2,Y14-Y13,"") | AD14: =IF(COUNT(AB13,AB14)=2,AB14-AB13,"") | AG14: =IF(COUNT(AE13,AE14)=2,AE14-AE13,"") | AJ14: =IF(COUNT(AH13,AH14)=2,AH14-AH13,"") | AM14: =IF(COUNT(AK13,AK14)=2,AK14-AK13,"")
B15: 8th | D15: 357831 | F15: =IF(COUNT(D14,D15)=2,D15-D14,"") -> 149 | G15: 362070 | I15: =IF(COUNT(G14,G15)=2,G15-G14,"") -> 143 | J15: 366581 | L15: =IF(COUNT(J14,J15)=2,J15-J14,"") -> 182 | M15: 371634 | O15: =IF(COUNT(M14,M15)=2,M15-M14,"") -> 174 | P15: 376500 | R15: =IF(COUNT(P14,P15)=2,P15-P14,"") -> 175 | S15: 380761 | U15: =IF(COUNT(S14,S15)=2,S15-S14,"") -> 101 | V15: 383139 | X15: =IF(COUNT(V14,V15)=2,V15-V14,"") -> 46 | AA15: =IF(COUNT(Y14,Y15)=2,Y15-Y14,"") | AD15: =IF(COUNT(AB14,AB15)=2,AB15-AB14,"") | AG15: =IF(COUNT(AE14,AE15)=2,AE15-AE14,"") | AJ15: =IF(COUNT(AH14,AH15)=2,AH15-AH14,"") | AM15: =IF(COUNT(AK14,AK15)=2,AK15-AK14,"")
B16: 9th | D16: 357978 | F16: =IF(COUNT(D15,D16)=2,D16-D15,"") -> 147 | G16: 362178 | I16: =IF(COUNT(G15,G16)=2,G16-G15,"") -> 108 | J16: 366719 | L16: =IF(COUNT(J15,J16)=2,J16-J15,"") -> 138 | M16: 371840 | O16: =IF(COUNT(M15,M16)=2,M16-M15,"") -> 206 | P16: 376645 | R16: =IF(COUNT(P15,P16)=2,P16-P15,"") -> 145 | S16: 380862 | U16: =IF(COUNT(S15,S16)=2,S16-S15,"") -> 101 | V16: 383162 | X16: =IF(COUNT(V15,V16)=2,V16-V15,"") -> 23 | AA16: =IF(COUNT(Y15,Y16)=2,Y16-Y15,"") | AD16: =IF(COUNT(AB15,AB16)=2,AB16-AB15,"") | AG16: =IF(COUNT(AE15,AE16)=2,AE16-AE15,"") | AJ16: =IF(COUNT(AH15,AH16)=2,AH16-AH15,"") | AM16: =IF(COUNT(AK15,AK16)=2,AK16-AK15,"")
B17: 10th | D17: 358116 | F17: =IF(COUNT(D16,D17)=2,D17-D16,"") -> 138 | G17: 362332 | I17: =IF(COUNT(G16,G17)=2,G17-G16,"") -> 154 | J17: 366869 | L17: =IF(COUNT(J16,J17)=2,J17-J16,"") -> 150 | M17: 372022 | O17: =IF(COUNT(M16,M17)=2,M17-M16,"") -> 182 | P17: 376803 | R17: =IF(COUNT(P16,P17)=2,P17-P16,"") -> 158 | S17: 380949 | U17: =IF(COUNT(S16,S17)=2,S17-S16,"") -> 87 | V17: 383187 | X17: =IF(COUNT(V16,V17)=2,V17-V16,"") -> 25 | AA17: =IF(COUNT(Y16,Y17)=2,Y17-Y16,"") | AD17: =IF(COUNT(AB16,AB17)=2,AB17-AB16,"") | AG17: =IF(COUNT(AE16,AE17)=2,AE17-AE16,"") | AJ17: =IF(COUNT(AH16,AH17)=2,AH17-AH16,"") | AM17: =IF(COUNT(AK16,AK17)=2,AK17-AK16,"")
B18: 11th | D18: 358214 | F18: =IF(COUNT(D17,D18)=2,D18-D17,"") -> 98 | G18: 362420 | I18: =IF(COUNT(G17,G18)=2,G18-G17,"") -> 88 | J18: 367026 | L18: =IF(COUNT(J17,J18)=2,J18-J17,"") -> 157 | M18: 372230 | O18: =IF(COUNT(M17,M18)=2,M18-M17,"") -> 208 | P18: 376911 | R18: =IF(COUNT(P17,P18)=2,P18-P17,"") -> 108 | S18: 381065 | U18: =IF(COUNT(S17,S18)=2,S18-S17,"") -> 116 | V18: 383211 | X18: =IF(COUNT(V17,V18)=2,V18-V17,"") -> 24 | AA18: =IF(COUNT(Y17,Y18)=2,Y18-Y17,"") | AD18: =IF(COUNT(AB17,AB18)=2,AB18-AB17,"") | AG18: =IF(COUNT(AE17,AE18)=2,AE18-AE17,"") | AJ18: =IF(COUNT(AH17,AH18)=2,AH18-AH17,"") | AM18: =IF(COUNT(AK17,AK18)=2,AK18-AK17,"")
B19: 12th | D19: 358331 | F19: =IF(COUNT(D18,D19)=2,D19-D18,"") -> 117 | G19: 362574 | I19: =IF(COUNT(G18,G19)=2,G19-G18,"") -> 154 | J19: 367192 | L19: =IF(COUNT(J18,J19)=2,J19-J18,"") -> 166 | M19: 372401 | O19: =IF(COUNT(M18,M19)=2,M19-M18,"") -> 171 | P19: 377033 | R19: =IF(COUNT(P18,P19)=2,P19-P18,"") -> 122 | S19: 381215 | U19: =IF(COUNT(S18,S19)=2,S19-S18,"") -> 150 | V19: 383234 | X19: =IF(COUNT(V18,V19)=2,V19-V18,"") -> 23 | AA19: =IF(COUNT(Y18,Y19)=2,Y19-Y18,"") | AD19: =IF(COUNT(AB18,AB19)=2,AB19-AB18,"") | AG19: =IF(COUNT(AE18,AE19)=2,AE19-AE18,"") | AJ19: =IF(COUNT(AH18,AH19)=2,AH19-AH18,"") | AM19: =IF(COUNT(AK18,AK19)=2,AK19-AK18,"")
B20: 13th | D20: 358455 | F20: =IF(COUNT(D19,D20)=2,D20-D19,"") -> 124 | G20: 362804 | I20: =IF(COUNT(G19,G20)=2,G20-G19,"") -> 230 | J20: 367401 | L20: =IF(COUNT(J19,J20)=2,J20-J19,"") -> 209 | M20: 372530 | O20: =IF(COUNT(M19,M20)=2,M20-M19,"") -> 129 | P20: 377144 | R20: =IF(COUNT(P19,P20)=2,P20-P19,"") -> 111 | S20: 381383 | U20: =IF(COUNT(S19,S20)=2,S20-S19,"") -> 168 | V20: 383259 | X20: =IF(COUNT(V19,V20)=2,V20-V19,"") -> 25 | AA20: =IF(COUNT(Y19,Y20)=2,Y20-Y19,"") | AD20: =IF(COUNT(AB19,AB20)=2,AB20-AB19,"") | AG20: =IF(COUNT(AE19,AE20)=2,AE20-AE19,"") | AJ20: =IF(COUNT(AH19,AH20)=2,AH20-AH19,"") | AM20: =IF(COUNT(AK19,AK20)=2,AK20-AK19,"")
B21: 14th | D21: 358581 | F21: =IF(COUNT(D20,D21)=2,D21-D20,"") -> 126 | G21: 363016 | I21: =IF(COUNT(G20,G21)=2,G21-G20,"") -> 212 | J21: 367590 | L21: =IF(COUNT(J20,J21)=2,J21-J20,"") -> 189 | M21: 372699 | O21: =IF(COUNT(M20,M21)=2,M21-M20,"") -> 169 | P21: 377297 | R21: =IF(COUNT(P20,P21)=2,P21-P20,"") -> 153 | S21: 381531 | U21: =IF(COUNT(S20,S21)=2,S21-S20,"") -> 148 | V21: 383315 | X21: =IF(COUNT(V20,V21)=2,V21-V20,"") -> 56 | AA21: =IF(COUNT(Y20,Y21)=2,Y21-Y20,"") | AD21: =IF(COUNT(AB20,AB21)=2,AB21-AB20,"") | AG21: =IF(COUNT(AE20,AE21)=2,AE21-AE20,"") | AJ21: =IF(COUNT(AH20,AH21)=2,AH21-AH20,"") | AM21: =IF(COUNT(AK20,AK21)=2,AK21-AK20,"")
B22: 15th | D22: 358706 | F22: =IF(COUNT(D21,D22)=2,D22-D21,"") -> 125 | G22: 363204 | I22: =IF(COUNT(G21,G22)=2,G22-G21,"") -> 188 | J22: 367719 | L22: =IF(COUNT(J21,J22)=2,J22-J21,"") -> 129 | M22: 372868 | O22: =IF(COUNT(M21,M22)=2,M22-M21,"") -> 169 | P22: 377472 | R22: =IF(COUNT(P21,P22)=2,P22-P21,"") -> 175 | S22: 381630 | U22: =IF(COUNT(S21,S22)=2,S22-S21,"") -> 99 | V22: 383371 | X22: =IF(COUNT(V21,V22)=2,V22-V21,"") -> 56 | AA22: =IF(COUNT(Y21,Y22)=2,Y22-Y21,"") | AD22: =IF(COUNT(AB21,AB22)=2,AB22-AB21,"") | AG22: =IF(COUNT(AE21,AE22)=2,AE22-AE21,"") | AJ22: =IF(COUNT(AH21,AH22)=2,AH22-AH21,"") | AM22: =IF(COUNT(AK21,AK22)=2,AK22-AK21,"")
B23: 16th | D23: 358867 | F23: =IF(COUNT(D22,D23)=2,D23-D22,"") -> 161 | G23: 363322 | I23: =IF(COUNT(G22,G23)=2,G23-G22,"") -> 118 | J23: 367837 | L23: =IF(COUNT(J22,J23)=2,J23-J22,"") -> 118 | M23: 373037 | O23: =IF(COUNT(M22,M23)=2,M23-M22,"") -> 169 | P23: 377635 | R23: =IF(COUNT(P22,P23)=2,P23-P22,"") -> 163 | S23: 381728 | U23: =IF(COUNT(S22,S23)=2,S23-S22,"") -> 98 | V23: 383418 | X23: =IF(COUNT(V22,V23)=2,V23-V22,"") -> 47 | AA23: =IF(COUNT(Y22,Y23)=2,Y23-Y22,"") | AD23: =IF(COUNT(AB22,AB23)=2,AB23-AB22,"") | AG23: =IF(COUNT(AE22,AE23)=2,AE23-AE22,"") | AJ23: =IF(COUNT(AH22,AH23)=2,AH23-AH22,"") | AM23: =IF(COUNT(AK22,AK23)=2,AK23-AK22,"")
