Workbook

Sheet Dec 19
B1: Water | I1: Cooling Towers | N1: Gas | T1: Georgia Power | Y1: City Water | AF1: Cooling Towers | AK1: Natural Gas
B2: Meter | I2: Hotel Chillers | K2: Apartment Loop | N2: Meter | Q2: MEZ | T2: Electrical Vault at P1 | Y2: Sidewalk Meter | AF2: Hotel Chillers | AH2: Apartment Loop | AK2: Gas Room at P1 | AN2: MEZ
A3: Date | B3: Bldg Main Meter #1 (CCF) | C3: Meter #2 (CCF) | D3: Fire Main Meter #3 (CCF) | E3: Pump Rm. Gall * 100 | F3: Offices at Level 20 Gall * 100 | G3: Offices at Level 30 Gall * 100 | I3: Make Up Gall * 100 | J3: Blow Down | K3: Make Up Gall * 100 | L3: Blow Down | N3: Corrected CCF *10 | O3: Not Corrected | P3: Engine | Q3: Tower Htg CCF *10 | T3: KWH (*4800) | U3: KW | V3: KQH | X3: Date | Y3: Bldg Main Meter #1 (CCF) | Z3: Meter #2 (CCF) | AA3: Fire Main Meter #3 (CCF) | AB3: Pump Rm. Gall * 100 | AC3: Offices at Level 20 Gall * 100 | AD3: Offices at Level 30 Gall * 100 | AF3: Make Up Gall * 100 | AG3: Blow Down | AH3: Make Up Gall * 100 | AI3: Blow Down | AK3: Corrected CCF *10 | AL3: Not Corrected | AM3: Engine | AN3: Tower Htg CCF *10
A5: LR | B5: =[1]Dec!B5 -> 640188 | C5: 0 | D5: 0 | E5: 0 | F5: 0 | G5: 0 | I5: =[1]Dec!I5 -> 18784 | J5: =[1]Dec!J5 -> 1418 | K5: 0 | L5: 0 | N5: =[1]Dec!N5 -> 216460 | O5: 0 | P5: 0 | Q5: 0 | T5: 0 | U5: 0 | V5: 0
A6: 1 | B6: =[1]Dec!B6 -> 640199 | I6: =[1]Dec!I6 -> 18816 | J6: =[1]Dec!J6 -> 1422 | N6: =[1]Dec!N6 -> 216540 | R6: =Q6-Q5 -> 0 | T6: 0 | U6: 0 | V6: 0 | W6: x | X6: 1 | Y6: =B6-B5 -> 11 | Z6: =C6-C5 -> 0 | AA6: =D6-D5 -> 0 | AB6: =E6-E5 -> 0 | AC6: =F6-F5 -> 0 | AD6: =G6-G5 -> 0 | AF6: =I6-I5 -> 32 | AG6: =J6-J5 -> 4 | AH6: =K6-K5 -> 0 | AI6: =L6-L5 -> 0 | AK6: =N6-N5 -> 80 | AL6: =O6-O5 -> 0 | AM6: =P6-P5 -> 0 | AN6: =Q6-Q5 -> 0
A7: 2 | R7: =Q7-Q6 -> 0 | W7: x | X7: 2 | Y7: =B7-B6 -> -640199 | Z7: =C7-C6 -> 0 | AA7: =D7-D6 -> 0 | AB7: =E7-E6 -> 0 | AC7: =F7-F6 -> 0 | AD7: =G7-G6 -> 0 | AF7: =I7-I6 -> -18816 | AG7: =J7-J6 -> -1422 | AH7: =K7-K6 -> 0 | AI7: =L7-L6 -> 0 | AK7: =N7-N6 -> -216540 | AL7: =O7-O6 -> 0 | AM7: =P7-P6 -> 0 | AN7: =Q7-Q6 -> 0
A8: 3 | R8: =Q8-Q7 -> 0 | W8: x | X8: 3 | Y8: =B8-B7 -> 0 | Z8: =C8-C7 -> 0 | AA8: =D8-D7 -> 0 | AB8: =E8-E7 -> 0 | AC8: =F8-F7 -> 0 | AD8: =G8-G7 -> 0 | AF8: =I8-I7 -> 0 | AG8: =J8-J7 -> 0 | AH8: =K8-K7 -> 0 | AI8: =L8-L7 -> 0 | AK8: =N8-N7 -> 0 | AL8: =O8-O7 -> 0 | AM8: =P8-P7 -> 0 | AN8: =Q8-Q7 -> 0
A9: 4 | R9: =Q9-Q8 -> 0 | W9: x | X9: 4 | Y9: =B9-B8 -> 0 | Z9: =C9-C8 -> 0 | AA9: =D9-D8 -> 0 | AB9: =E9-E8 -> 0 | AC9: =F9-F8 -> 0 | AD9: =G9-G8 -> 0 | AF9: =I9-I8 -> 0 | AG9: =J9-J8 -> 0 | AH9: =K9-K8 -> 0 | AI9: =L9-L8 -> 0 | AK9: =N9-N8 -> 0 | AL9: =O9-O8 -> 0 | AM9: =P9-P8 -> 0 | AN9: =Q9-Q8 -> 0
A10: 5 | R10: =Q10-Q9 -> 0 | W10: x | X10: 5 | Y10: =B10-B9 -> 0 | Z10: =C10-C9 -> 0 | AA10: =D10-D9 -> 0 | AB10: =E10-E9 -> 0 | AC10: =F10-F9 -> 0 | AD10: =G10-G9 -> 0 | AF10: =I10-I9 -> 0 | AG10: =J10-J9 -> 0 | AH10: =K10-K9 -> 0 | AI10: =L10-L9 -> 0 | AK10: =N10-N9 -> 0 | AL10: =O10-O9 -> 0 | AM10: =P10-P9 -> 0 | AN10: =Q10-Q9 -> 0
A11: 6 | R11: =Q11-Q10 -> 0 | W11: x | X11: 6 | Y11: =B11-B10 -> 0 | Z11: =C11-C10 -> 0 | AA11: =D11-D10 -> 0 | AB11: =E11-E10 -> 0 | AC11: =F11-F10 -> 0 | AD11: =G11-G10 -> 0 | AF11: =I11-I10 -> 0 | AG11: =J11-J10 -> 0 | AH11: =K11-K10 -> 0 | AI11: =L11-L10 -> 0 | AK11: =N11-N10 -> 0 | AL11: =O11-O10 -> 0 | AM11: =P11-P10 -> 0 | AN11: =Q11-Q10 -> 0
A12: 7 | R12: =Q12-Q11 -> 0 | W12: x | X12: 7 | Y12: =B12-B11 -> 0 | Z12: =C12-C11 -> 0 | AA12: =D12-D11 -> 0 | AB12: =E12-E11 -> 0 | AC12: =F12-F11 -> 0 | AD12: =G12-G11 -> 0 | AF12: =I12-I11 -> 0 | AG12: =J12-J11 -> 0 | AH12: =K12-K11 -> 0 | AI12: =L12-L11 -> 0 | AK12: =N12-N11 -> 0 | AL12: =O12-O11 -> 0 | AM12: =P12-P11 -> 0 | AN12: =Q12-Q11 -> 0
A13: 8 | R13: =Q13-Q12 -> 0 | W13: x | X13: 8 | Y13: =B13-B12 -> 0 | Z13: =C13-C12 -> 0 | AA13: =D13-D12 -> 0 | AB13: =E13-E12 -> 0 | AC13: =F13-F12 -> 0 | AD13: =G13-G12 -> 0 | AF13: =I13-I12 -> 0 | AG13: =J13-J12 -> 0 | AH13: =K13-K12 -> 0 | AI13: =L13-L12 -> 0 | AK13: =N13-N12 -> 0 | AL13: =O13-O12 -> 0 | AM13: =P13-P12 -> 0 | AN13: =Q13-Q12 -> 0
A14: 9 | R14: =Q14-Q13 -> 0 | W14: x | X14: 9 | Y14: =B14-B13 -> 0 | Z14: =C14-C13 -> 0 | AA14: =D14-D13 -> 0 | AB14: =E14-E13 -> 0 | AC14: =F14-F13 -> 0 | AD14: =G14-G13 -> 0 | AF14: =I14-I13 -> 0 | AG14: =J14-J13 -> 0 | AH14: =K14-K13 -> 0 | AI14: =L14-L13 -> 0 | AK14: =N14-N13 -> 0 | AL14: =O14-O13 -> 0 | AM14: =P14-P13 -> 0 | AN14: =Q14-Q13 -> 0
A15: 10 | R15: =Q15-Q14 -> 0 | W15: x | X15: 10 | Y15: =B15-B14 -> 0 | Z15: =C15-C14 -> 0 | AA15: =D15-D14 -> 0 | AB15: =E15-E14 -> 0 | AC15: =F15-F14 -> 0 | AD15: =G15-G14 -> 0 | AF15: =I15-I14 -> 0 | AG15: =J15-J14 -> 0 | AH15: =K15-K14 -> 0 | AI15: =L15-L14 -> 0 | AK15: =N15-N14 -> 0 | AL15: =O15-O14 -> 0 | AM15: =P15-P14 -> 0 | AN15: =Q15-Q14 -> 0
A16: 11 | R16: =Q16-Q15 -> 0 | W16: x | X16: 11 | Y16: =B16-B15 -> 0 | Z16: =C16-C15 -> 0 | AA16: =D16-D15 -> 0 | AB16: =E16-E15 -> 0 | AC16: =F16-F15 -> 0 | AD16: =G16-G15 -> 0 | AF16: =I16-I15 -> 0 | AG16: =J16-J15 -> 0 | AH16: =K16-K15 -> 0 | AI16: =L16-L15 -> 0 | AK16: =N16-N15 -> 0 | AL16: =O16-O15 -> 0 | AM16: =P16-P15 -> 0 | AN16: =Q16-Q15 -> 0
A17: 12 | R17: =Q17-Q16 -> 0 | W17: x | X17: 12 | Y17: =B17-B16 -> 0 | Z17: =C17-C16 -> 0 | AA17: =D17-D16 -> 0 | AB17: =E17-E16 -> 0 | AC17: =F17-F16 -> 0 | AD17: =G17-G16 -> 0 | AF17: =I17-I16 -> 0 | AG17: =J17-J16 -> 0 | AH17: =K17-K16 -> 0 | AI17: =L17-L16 -> 0 | AK17: =N17-N16 -> 0 | AL17: =O17-O16 -> 0 | AM17: =P17-P16 -> 0 | AN17: =Q17-Q16 -> 0
A18: 13 | R18: =Q18-Q17 -> 0 | W18: x | X18: 13 | Y18: =B18-B17 -> 0 | Z18: =C18-C17 -> 0 | AA18: =D18-D17 -> 0 | AB18: =E18-E17 -> 0 | AC18: =F18-F17 -> 0 | AD18: =G18-G17 -> 0 | AF18: =I18-I17 -> 0 | AG18: =J18-J17 -> 0 | AH18: =K18-K17 -> 0 | AI18: =L18-L17 -> 0 | AK18: =N18-N17 -> 0 | AL18: =O18-O17 -> 0 | AM18: =P18-P17 -> 0 | AN18: =Q18-Q17 -> 0
... A35: 30 | R35: =Q35-Q34 -> 0 | W35: x | X35: 30 | Y35: =B35-B34 -> 0 | Z35: =C35-C34 -> 0 | AA35: =D35-D34 -> 0 | AB35: =E35-E34 -> 0 | AC35: =F35-F34 -> 0 | AD35: =G35-G34 -> 0 | AF35: =I35-I34 -> 0 | AG35: =J35-J34 -> 0 | AH35: =K35-K34 -> 0 | AI35: =L35-L34 -> 0 | AK35: =N35-N34 -> 0 | AL35: =O35-O34 -> 0 | AM35: =P35-P34 -> 0 | AN35: =Q35-Q34 -> 0
A36: 31 | B36: =[1]Dec!B36 -> 641288 | I36: =[1]Dec!I36 -> 19163 | J36: =[1]Dec!J36 -> 1474 | N36: =[1]Dec!N36 -> 218830 | R36: =Q36-Q35 -> 0 | T36: 0 | U36: 0 | V36: 0 | W36: x | X36: 31 | Y36: =B36-B35 -> 641288 | Z36: =C36-C35 -> 0 | AA36: =D36-D35 -> 0 | AB36: =E36-E35 -> 0 | AC36: =F36-F35 -> 0 | AD36: =G36-G35 -> 0 | AF36: =I36-I35 -> 19163 | AG36: =J36-J35 -> 1474 | AH36: =K36-K35 -> 0 | AI36: =L36-L35 -> 0 | AK36: =N36-N35 -> 218830 | AL36: =O36-O35 -> 0 | AM36: =P36-P35 -> 0 | AN36: =Q36-Q35 -> 0
B37: (6 Digits) | E37: (6 Digits) | F37: (5 Digits) | G37: (5 Digits) | I37: (5 Digits) | J37: (4 Digits) | K37: (5 Digits) | L37: (4 Digits) | N37: (6 Digits) | O37: (6 Digits) | P37: (6 Digits) | Q37: (5 Digits)
A39: LD | B39: =LARGE(B5:B36, 1) -> 641288 | C39: =LARGE(C5:C36, 1) -> 0 | D39: =LARGE(D5:D36, 1) -> 0 | E39: =LARGE(E5:E36, 1) -> 0 | F39: =LARGE(F5:F36, 1) -> 0 | G39: =LARGE(G5:G36, 1) -> 0 | I39: =LARGE(I5:I36, 1) -> 19163 | J39: =LARGE(J5:J36, 1) -> 1474 | K39: =LARGE(K5:K36, 1) -> 0 | L39: =LARGE(L5:L36, 1) -> 0 | N39: =LARGE(N5:N36, 1) -> 218830 | O39: =LARGE(O5:O36, 1) -> 0 | P39: =LARGE(P5:P36, 1) -> 0 | Q39: =LARGE(Q5:Q36, 1) -> 0 | T39: =LARGE(T5:T36, 1) -> 0 | U39: =LARGE(U5:U36, 1) -> 0 | V39: =LARGE(V5:V36, 1) -> 0 | X39: AVG | Y39: =AVERAGE(Y6:Y36) -> 35.483871 | Z39: =AVERAGE(Z6:Z36) -> 0 | AA39: =AVERAGE(AA6:AA36) -> 0 | AB39: =AVERAGE(AB6:AB36) -> 0 | AC39: =AVERAGE(AC6:AC36) -> 0 | AD39: =AVERAGE(AD6:AD36) -> 0 | AF39: =AVERAGE(AF6:AF36) -> 12.225806 | AG39: =AVERAGE(AG6:AG36) -> 1.8064516 | AH39: =AVERAGE(AH6:AH36) -> 0 | AI39: =AVERAGE(AI6:AI36) -> 0 | AK39: =AVERAGE(AK6:AK36) -> 76.451613 | AL39: =AVERAGE(AL6:AL36) -> 0 | AM39: =AVERAGE(AM6:AM36) -> 0 | AN39: =AVERAGE(AN6:AN36) -> 0
B41: Consumption: | X41: PRV AVG
B42: =B39-B5 -> 1100 | C42: =C39-C5 -> 0 | D42: =D39-D5 -> 0 | E42: =E39-E5 -> 0 | F42: =F39-F5 -> 0 | G42: =G39-G5 -> 0 | I42: =I39-I5 -> 379 | J42: =J39-J5 -> 56 | K42: =K39-K5 -> 0 | L42: =L39-L5 -> 0 | N42: =N39-N5 -> 2370 | O42: =O39-O5 -> 0 | P42: =P39-P5 -> 0 | Q42: =Q39-Q5 -> 0 | T42: =T39-T5 -> 0 | U42: =U39-U5 -> 0 | V42: =V39-V5 -> 0 | Y42: ='Dec 19'!Y39 -> 35.483871 | Z42: ='Dec 19'!Z39 -> 0 | AA42: ='Dec 19'!AA39 -> 0 | AB42: ='Dec 19'!AB39 -> 0 | AC42: ='Dec 19'!AC39 -> 0 | AD42: ='Dec 19'!AD39 -> 0 | AF42: ='Dec 19'!AF39 -> 12.225806 | AG42: ='Dec 19'!AG39 -> 1.8064516 | AH42: ='Dec 19'!AH39 -> 0 | AI42: ='Dec 19'!AI39 -> 0 | AK42: ='Dec 19'!AK39 -> 76.451613 | AL42: ='Dec 19'!AL39 -> 0 | AM42: ='Dec 19'!AM39 -> 0 | AN42: ='Dec 19'!AN39 -> 0
X43: 1.5 | Y43: =Y42*$X$43 -> 53.225806 | Z43: =Z42*$X$43 -> 0 | AA43: =AA42*$X$43 -> 0 | AB43: =AB42*$X$43 -> 0 | AC43: =AC42*$X$43 -> 0 | AD43: =AD42*$X$43 -> 0 | AF43: =AF42*$X$43 -> 18.33871 | AG43: =AG42*$X$43 -> 2.7096774 | AH43: =AH42*$X$43 -> 0 | AI43: =AI42*$X$43 -> 0 | AK43: =AK42*$X$43 -> 114.67742 | AL43: =AL42*$X$43 -> 0 | AM43: =AM42*$X$43 -> 0 | AN43: =AN42*$X$43 -> 0
R44: AVG | X44: 0.5 | Y44: =Y42*$X$44 -> 17.741935 | Z44: =Z42*$X$44 -> 0 | AA44: =AA42*$X$44 -> 0 | AB44: =AB42*$X$44 -> 0 | AC44: =AC42*$X$44 -> 0 | AD44: =AD42*$X$44 -> 0 | AF44: =AF42*$X$44 -> 6.1129032 | AG44: =AG42*$X$44 -> 0.90322581 | AH44: =AH42*$X$44 -> 0 | AI44: =AI42*$X$44 -> 0 | AK44: =AK42*$X$44 -> 38.225806 | AL44: =AL42*$X$44 -> 0 | AM44: =AM42*$X$44 -> 0 | AN44: =AN42*$X$44 -> 0
R45: =AVERAGE(R6:R36) -> 0
Y46: Note 1 | Z46: Normal formating for cells where the daily average consumption is within range from the previous month's average range noted above.
Y47: Note 2 | Z47: Indicates the daily average for that day is outside the average range for that meter, based on the previous month's averages. Not necessarily a problem, just something to keeep an eye on.
X48: ! | Y48: Note 3 | Z48: This RED FLAG should be brought to Management for further review as to why it is more than twice the monthly average. Still can be explained, depending on the meter, but warrants immediate review to minimize impact to utilities and/or billing.
Y49: Note 4 | Z49: This is the same calculation as the RED FLAG, but is a known non-issue (example: Emergency Generator run once a week, plus bi-monthly inspections)
X50: ! | Y50: Note 5 | Z50: THIS IS AN ISSUE. METERS DO NOT RUN BACKWARDS, THUS NO NEGATIVE READINGS ALLOWED. Check for a simple typo or transposed number in the reading and/or verify the meter reading logged is correct by physically checking meter again.
R51: =AVERAGE(R6:R36) -> 0

Sheet Annual Consumption
J1: Cooling Towers
C2: Water | J2: Hotel Chillers | L2: Apartment Loop | O2: Gas | T2: Georgia Power
B3: Monthly Average Consumption | C3: Bldg Main Meter #1 (CCF) | D3: Meter #2 (CCF) | E3: Fire Main Meter #3 (CCF) | F3: Pump Rm. Gall * 100 | G3: Offices at Level 20 Gall * 100 | H3: Offices at Level 30 Gall * 100 | J3: Make Up Gall * 100 | K3: Blow Down | L3: Make Up Gall * 100 | M3: Blow Down | O3: Corrected CCF *10 | P3: Not Corrected | Q3: Engine | R3: Tower Htg CCF *10 | T3: KWH (*4800) | U3: KW | V3: KQH | X3: Tower Htg CCF Daily Consumption AVG | Y3: Water Savings | Z3: Gas Savings
A4: x | B4: JAN | C4: =Jan!B42 -> 2446 | D4: =Jan!C42 -> 0 | E4: =Jan!D42 -> 0 | F4: =Jan!E42 -> 0 | G4: =Jan!F42 -> 0 | H4: =Jan!G42 -> 0 | I4: =Jan!H42 -> 0 | J4: =Jan!I42 -> 362 | ... R4: =Jan!Q42 -> 457 | S4: =Jan!S42 -> 0 | T4: =Jan!T42 -> 0 | U4: =Jan!U42 -> 0 | V4: =Jan!V42 -> 0 | X4: =Jan!$R$51 -> -693.22581
A5: x | B5: FEB | C5: =Feb!B42 -> 1834 | D5: =Feb!C42 -> 0 | E5: =Feb!D42 -> 0 | F5: =Feb!E42 -> 0 | G5: =Feb!F42 -> 0 | H5: =Feb!G42 -> 0 | I5: =Feb!H42 -> 0 | J5: =Feb!I42 -> 345 | ... R5: =Feb!Q42 -> 0 | S5: =Feb!S42 -> 0 | T5: =Feb!T42 -> 0 | U5: =Feb!U42 -> 0 | V5: =Feb!V42 -> 0 | X5: =Feb!$R$51 -> -783.82143 | Y5: =IF(C5=0,0,1-(C5/C4)) -> 0.25020442 | Z5: =IF(O5=0,0,1-(O5/O4)) -> 0.089255642 | AC5: April | AD5: April | AE5: April
A6: x | B6: MAR | C6: =Mar!B42 -> 1478 | D6: =Mar!C42 -> 0 | E6: =Mar!D42 -> 0 | F6: =Mar!E42 -> 0 | G6: =Mar!F42 -> 0 | H6: =Mar!G42 -> 0 | I6: =Mar!H42 -> 0 | J6: =Mar!I42 -> 591 | ... R6: =Mar!Q42 -> 0 | S6: =Mar!S42 -> 0 | T6: =Mar!T42 -> 0 | U6: =Mar!U42 -> 0 | V6: =Mar!V42 -> 0 | X6: =Mar!$R$51 -> -707.96774 | Y6: =IF(C6=0,0,1-(C6/C5)) -> 0.19411123 | Z6: =IF(O6=0,0,1-(O6/O5)) -> 0.33579882 | AC6: 2019 | AD6: 2020 | AE6: Savings | AF6: Consumption
A7: x | B7: APR | C7: =Apr!B42 -> 777 | D7: =Apr!C42 -> 0 | E7: =Apr!D42 -> 0 | F7: =Apr!E42 -> 0 | G7: =Apr!F42 -> 0 | H7: =Apr!G42 -> 0 | I7: =Apr!H42 -> 0 | J7: =Apr!I42 -> 398 | ... R7: =Apr!Q42 -> 0 | S7: =Apr!S42 -> 0 | T7: =Apr!T42 -> 0 | U7: =Apr!U42 -> 0 | V7: =Apr!V42 -> 0 | X7: =Apr!$R$45 -> -731.56667 | Y7: =IF(C7=0,0,1-(C7/C6)) -> 0.47428958 | Z7: =IF(O7=0,0,1-(O7/O6)) -> 0.66536748 | AB7: Electric | AC7: 792022 | AD7: 503820 | AE7: =1-(AD7/AC7) -> 0.36388131 | AF7: =AD7/AC7 -> 0.63611869 | AG7: =AE7+AF7 -> 1 | AH7: COVID-19 Impact to Renovation/Hotel
A8: x | B8: MAY | C8: =May!B42 -> 1042 | D8: =May!C42 -> 0 | E8: =May!D42 -> 0 | F8: =May!E42 -> 0 | G8: =May!F42 -> 0 | H8: =May!G42 -> 0 | I8: =May!H42 -> 0 | J8: =May!I42 -> 501 | ... R8: =May!Q42 -> 0 | S8: =May!S42 -> 0 | T8: =May!T42 -> 0 | U8: =May!U42 -> 0 | V8: =May!V42 -> 0 | X8: =May!$R$51 -> -707.96774 | Y8: =IF(C8=0,0,1-(C8/C7)) -> -0.34105534 | Z8: =IF(O8=0,0,1-(O8/O7)) -> 0.034941764 | AB8: Gas | AC8: 1279 | AD8: 601 | AE8: =1-(AD8/AC8) -> 0.53010164 | AF8: =AD8/AC8 -> 0.46989836 | AG8: =AE8+AF8 -> 1
B9: JUN | C9: =Jun!B42 -> 1085 | D9: =Jun!C42 -> 0 | E9: =Jun!D42 -> 0 | F9: =Jun!E42 -> 0 | G9: =Jun!F42 -> 0 | H9: =Jun!G42 -> 0 | I9: =Jun!H42 -> 0 | J9: =Jun!I42 -> 636 | ... R9: =Jun!Q42 -> 0 | S9: =Jun!S42 -> 0 | T9: =Jun!T42 -> 0 | U9: =Jun!U42 -> 0 | V9: =Jun!V42 -> 0 | X9: =Jun!$R$51 -> -707.96774 | Y9: =IF(C9=0,0,1-(C9/C8)) -> -0.041266795 | Z9: =IF(O9=0,0,1-(O9/O8)) -> -0.067241379 | AB9: Water | AC9: 2472 | AD9: 777 | AE9: =1-(AD9/AC9) -> 0.68567961 | AF9: =AD9/AC9 -> 0.31432039 | AG9: =AE9+AF9 -> 1
B10: JUL | C10: =Jul!B42 -> 0 | D10: =Jul!#REF! -> #REF! | E10: =Jul!#REF! -> #REF! | F10: =Jul!#REF! -> #REF! | G10: =Jul!#REF! -> #REF! | H10: =Jul!#REF! -> #REF! | I10: =Jul!C42 -> 0 | J10: =Jul!D42 -> 0 | K10: =Jul!E42 -> 0 | L10: =Jul!#REF! -> #REF! | M10: =Jul!#REF! -> #REF! | N10: =Jul!F42 -> 0 | O10: =Jul!G42 -> 0 | P10: =Jul!#REF! -> #REF! | Q10: =Jul!#REF! -> #REF! | R10: =Jul!#REF! -> #REF! | S10: =Jul!I42 -> 0 | T10: =Jul!J42 -> 0 | U10: =Jul!K42 -> 0 | V10: =Jul!L42 -> 0 | X10: =Jul!$H$51 -> #REF! | Y10: =IF(C10=0,0,1-(C10/C9)) -> 0 | Z10: =IF(O10=0,0,1-(O10/O9)) -> 0
B11: AUG | C11: =Aug!B42 -> #NUM! | D11: =Aug!#REF! -> #REF! | E11: =Aug!#REF! -> #REF! | F11: =Aug!#REF! -> #REF! | G11: =Aug!#REF! -> #REF! | H11: =Aug!#REF! -> #REF! | I11: =Aug!C42 -> 0 | J11: =Aug!D42 -> #NUM! | K11: =Aug!E42 -> #NUM! | L11: =Aug!#REF! -> #REF! | M11: =Aug!#REF! -> #REF! | N11: =Aug!F42 -> 0 | O11: =Aug!G42 -> #NUM! | P11: =Aug!#REF! -> #REF! | Q11: =Aug!#REF! -> #REF! | R11: =Aug!#REF! -> #REF! | S11: =Aug!I42 -> 0 | T11: =Aug!J42 -> 0 | U11: =Aug!K42 -> 0 | V11: =Aug!L42 -> 0 | X11: =Aug!$H$51 -> #REF! | Y11: =IF(C11=0,0,1-(C11/C10)) -> #NUM! | Z11: =IF(O11=0,0,1-(O11/O10)) -> #NUM!
B12: SEP | C12: =Sep!B42 -> 605 | D12: =Sep!#REF! -> #REF! | E12: =Sep!#REF! -> #REF! | F12: =Sep!#REF! -> #REF! | G12: =Sep!#REF! -> #REF! | H12: =Sep!#REF! -> #REF! | I12: =Sep!C42 -> 0 | J12: =Sep!D42 -> 592 | K12: =Sep!E42 -> 68 | L12: =Sep!#REF! -> #REF! | M12: =Sep!#REF! -> #REF! | N12: =Sep!F42 -> 0 | O12: =Sep!G42 -> 532 | P12: =Sep!#REF! -> #REF! | Q12: =Sep!#REF! -> #REF! | R12: =Sep!#REF! -> #REF! | S12: =Sep!I42 -> 0 | T12: =Sep!J42 -> 0 | U12: =Sep!K42 -> 0 | V12: =Sep!L42 -> 0 | X12: =Sep!$H$51 -> #REF! | Y12: =IF(C12=0,0,1-(C12/C11)) -> #NUM! | Z12: =IF(O12=0,0,1-(O12/O11)) -> #NUM!
B13: OCT | C13: =Oct!B42 -> 1597 | D13: =Oct!#REF! -> #REF! | E13: =Oct!#REF! -> #REF! | F13: =Oct!#REF! -> #REF! | G13: =Oct!#REF! -> #REF! | H13: =Oct!#REF! -> #REF! | I13: =Oct!C42 -> 0 | J13: =Oct!D42 -> 24763 | K13: =Oct!E42 -> 2656 | L13: =Oct!#REF! -> #REF! | M13: =Oct!#REF! -> #REF! | N13: =Oct!F42 -> 0 | O13: =Oct!G42 -> 230589 | P13: =Oct!#REF! -> #REF! | Q13: =Oct!#REF! -> #REF! | R13: =Oct!#REF! -> #REF! | S13: =Oct!I42 -> 0 | T13: =Oct!J42 -> 0 | U13: =Oct!K42 -> 0 | V13: =Oct!L42 -> 0 | X13: =Oct!$H$51 -> #REF! | Y13: =IF(C13=0,0,1-(C13/C12)) -> -1.6396694 | Z13: =IF(O13=0,0,1-(O13/O12)) -> -432.43797
B14: NOV | C14: =Nov!B42 -> 945 | D14: =Nov!#REF! -> #REF! | E14: =Nov!#REF! -> #REF! | F14: =Nov!#REF! -> #REF! | G14: =Nov!#REF! -> #REF! | H14: =Nov!#REF! -> #REF! | I14: =Nov!C42 -> 0 | J14: =Nov!D42 -> 400 | K14: =Nov!E42 -> 78 | L14: =Nov!#REF! -> #REF! | M14: =Nov!#REF! -> #REF! | N14: =Nov!F42 -> 0 | O14: =Nov!G42 -> 1122 | P14: =Nov!#REF! -> #REF! | Q14: =Nov!#REF! -> #REF! | R14: =Nov!#REF! -> #REF! | S14: =Nov!I42 -> 0 | T14: =Nov!J42 -> 0 | U14: =Nov!K42 -> 0 | V14: =Nov!L42 -> 0 | X14: =Nov!$H$51 -> #REF! | Y14: =IF(C14=0,0,1-(C14/C13)) -> 0.4082655 | Z14: =IF(O14=0,0,1-(O14/O13)) -> 0.9951342
B15: DEC | C15: =Dec!B42 -> 816 | D15: =Dec!#REF! -> #REF! | E15: =Dec!#REF! -> #REF! | F15: =Dec!#REF! -> #REF! | G15: =Dec!#REF! -> #REF! | H15: =Dec!#REF! -> #REF! | I15: =Dec!C42 -> 0 | J15: =Dec!D42 -> 214 | K15: =Dec!E42 -> 36 | L15: =Dec!#REF! -> #REF! | M15: =Dec!#REF! -> #REF! | N15: =Dec!F42 -> 0 | O15: =Dec!G42 -> 1917 | P15: =Dec!#REF! -> #REF! | Q15: =Dec!#REF! -> #REF! | R15: =Dec!#REF! -> #REF! | S15: =Dec!I42 -> 0 | T15: =Dec!J42 -> 0 | U15: =Dec!K42 -> 0 | V15: =Dec!L42 -> 0 | X15: =Dec!$H$51 -> #REF! | Y15: =IF(C15=0,0,1-(C15/C14)) -> 0.13650794 | Z15: =IF(O15=0,0,1-(O15/O14)) -> -0.70855615
B16: JAN 19 | C16: =#REF! -> #REF! | D16: =#REF! -> #REF! | E16: =#REF! -> #REF! | F16: =#REF! -> #REF! | G16: =#REF! -> #REF! | H16: =#REF! -> #REF! | I16: =#REF! -> #REF! | J16: =#REF! -> #REF! | ... V16: =#REF! -> #REF!
B18: AVG (YTD) | C18: =AVERAGEIF($A$4:$A$16, "x", C4:C16) -> 1515.4 | D18: =AVERAGEIF($A$4:$A$16, "x", D4:D16) -> 0 | E18: =AVERAGEIF($A$4:$A$16, "x", E4:E16) -> 0 | F18: =AVERAGEIF($A$4:$A$16, "x", F4:F16) -> 0 | G18: =AVERAGEIF($A$4:$A$16, "x", G4:G16) -> 0 | H18: =AVERAGEIF($A$4:$A$16, "x", H4:H16) -> 0 | J18: =AVERAGEIF($A$4:$A$16, "x", J4:J16) -> 439.4 | K18: =AVERAGEIF($A$4:$A$16, "x", K4:K16) -> 94.4 | L18: =AVERAGEIF($A$4:$A$16, "x", L4:L16) -> 0 | M18: =AVERAGEIF($A$4:$A$16, "x", M4:M16) -> 0 | O18: =AVERAGEIF($A$4:$A$16, "x", O4:O16) -> 1730 | P18: =AVERAGEIF($A$4:$A$16, "x", P4:P16) -> 126.2 | Q18: =AVERAGEIF($A$4:$A$16, "x", Q4:Q16) -> 18.8 | R18: =AVERAGEIF($A$4:$A$16, "x", R4:R16) -> 91.4 | T18: =AVERAGEIF($A$4:$A$16, "x", T4:T16) -> 0 | U18: =AVERAGEIF($A$4:$A$16, "x", U4:U16) -> 0 | V18: =AVERAGEIF($A$4:$A$16, "x", V4:V16) -> 0 | AC18: YTD | AD18: YTD | AE18: YTD | AF18: JAN - APR
B19: 1.5 | C19: =C18*$B$19 -> 2273.1 | D19: =D18*$B$19 -> 0 | E19: =E18*$B$19 -> 0 | F19: =F18*$B$19 -> 0 | G19: =G18*$B$19 -> 0 | H19: =H18*$B$19 -> 0 | J19: =J18*$B$19 -> 659.1 | K19: =K18*$B$19 -> 141.6 | L19: =L18*$B$19 -> 0 | M19: =M18*$B$19 -> 0 | O19: =O18*$B$19 -> 2595 | P19: =P18*$B$19 -> 189.3 | Q19: =Q18*$B$19 -> 28.2 | R19: =R18*$B$19 -> 137.1 | T19: =T18*$B$19 -> 0 | U19: =U18*$B$19 -> 0 | V19: =V18*$B$19 -> 0 | AC19: 2019 | AD19: 2020 | AE19: Savings | AF19: Consumption
B20: 0.5 | C20: =C18*$B$20 -> 757.7 | D20: =D18*$B$20 -> 0 | E20: =E18*$B$20 -> 0 | F20: =F18*$B$20 -> 0 | G20: =G18*$B$20 -> 0 | H20: =H18*$B$20 -> 0 | J20: =J18*$B$20 -> 219.7 | K20: =K18*$B$20 -> 47.2 | L20: =L18*$B$20 -> 0 | M20: =M18*$B$20 -> 0 | O20: =O18*$B$20 -> 865 | P20: =P18*$B$20 -> 63.1 | Q20: =Q18*$B$20 -> 9.4 | R20: =R18*$B$20 -> 45.7 | T20: =T18*$B$20 -> 0 | U20: =U18*$B$20 -> 0 | V20: =V18*$B$20 -> 0 | AB20: Electric | AC20: 2937149 | AD20: 2674360 | AE20: =1-(AD20/AC20) -> 0.089470776 | AF20: =AD20/AC20 -> 0.91052922 | AG20: =AE20+AF20 -> 1 | AH20: (Jan - Mar = 0.5% to 1.5% over 2019)
AB21: Gas | AC21: 10821 | AD21: 8070 | AE21: =1-(AD21/AC21) -> 0.25422789 | AF21: =AD21/AC21 -> 0.74577211 | AG21: =AE21+AF21 -> 1
J22: Cooling Towers | AB22: Water | AC22: 8805 | AD22: 6535 | AE22: =1-(AD22/AC22) -> 0.25780806 | AF22: =AD22/AC22 -> 0.74219194 | AG22: =AE22+AF22 -> 1 | AH22: (Jan - Mar = 11.3% under 2019)
C23: Water | J23: Hotel Chillers | L23: Apartment Loop | O23: Gas | T23: Georgia Power
B24: Daily Average Consumption | C24: Bldg Main Meter #1 (CCF) | D24: Meter #2 (CCF) | E24: Fire Main Meter #3 (CCF) | F24: Pump Rm. Gall * 100 | G24: Offices at Level 20 Gall * 100 | H24: Offices at Level 30 Gall * 100 | J24: Make Up Gall * 100 | K24: Blow Down | L24: Make Up Gall * 100 | M24: Blow Down | O24: Corrected CCF *10 | P24: Not Corrected | Q24: Engine | R24: Tower Htg CCF *10 | T24: KWH (*4800) | U24: KW | V24: KQH | X24: Water Savings | Y24: Gas Savings
A25: =IF(A4="","",A4) -> x | B25: JAN | C25: =Jan!Y39 -> 78.903226 | D25: =Jan!Z39 -> 0 | E25: =Jan!AA39 -> 0 | F25: =Jan!AB39 -> -31397.677 | G25: =Jan!AC39 -> -2518.7097 | H25: =Jan!AD39 -> -704.19355 | I25: =Jan!AE39 -> 0 | J25: =Jan!AF39 -> 11.677419 | ... R25: =Jan!AN39 -> -693.22581 | S25: 0 | T25: 0 | U25: 0 | V25: 0 | W25: 0 | AC25: May | AD25: May | AE25: May
A26: =IF(A5="","",A5) -> x | B26: FEB | C26: =Feb!Y39 -> 63.241379 | D26: =Feb!Z39 -> 0 | E26: =Feb!AA39 -> 0 | F26: =Feb!AB39 -> -33563.034 | G26: =Feb!AC39 -> -2692.4138 | H26: =Feb!AD39 -> -752.75862 | I26: =Feb!AE39 -> 0 | J26: =Feb!AF39 -> 11.896552 | ... R26: =Feb!AN39 -> -756.7931 | X26: =IF(C26<=0,0,1-(C26/C25)) -> 0.19849438 | Y26: =IF(O26<=0,0,1-(O26/O25)) -> 0.026445686 | AC26: 2019 | AD26: 2020 | AE26: Savings | AF26: Consumption
A27: =IF(A6="","",A6) -> x | B27: MAR | C27: =Mar!Y39 -> 47.677419 | D27: =Mar!Z39 -> 0 | E27: =Mar!AA39 -> 0 | F27: =Mar!AB39 -> -31397.677 | G27: =Mar!AC39 -> -2518.7097 | H27: =Mar!AD39 -> -704.19355 | I27: =Mar!AE39 -> 0 | J27: =Mar!AF39 -> 19.064516 | ... R27: =Mar!AN39 -> -707.96774 | X27: =IF(C27<=0,0,1-(C27/C26)) -> 0.24610406 | Y27: =IF(O27<=0,0,1-(O27/O26)) -> 0.37865051 | AB27: Electric | AC27: 800427 | AD27: =(AD20/121)*31 -> 685166.61 | AE27: =1-(AD27/AC27) -> 0.14399863 | AF27: =AD27/AC27 -> 0.85600137 | AG27: =AE27+AF27 -> 1 | AH27: MAY Daily AVG = 22102 * 31 days
A28: =IF(A7="","",A7) -> x | B28: APR | C28: =Apr!Y39 -> 25.9 | D28: =Apr!Z39 -> 0 | E28: =Apr!AA39 -> 0 | F28: =Apr!AB39 -> -32444.267 | G28: =Apr!AC39 -> -2602.6667 | H28: =Apr!AD39 -> -727.66667 | I28: =Apr!AE39 -> 0 | J28: =Apr!AF39 -> 13.266667 | ... R28: =Apr!AN39 -> -731.56667 | X28: =IF(C28<=0,0,1-(C28/C27)) -> 0.4567659 | Y28: =IF(O28<=0,0,1-(O28/O27)) -> 0.65421307 | AB28: Gas | AC28: 1279 | AD28: =O29*31 -> 580 | AE28: =1-(AD28/AC28) -> 0.54652072 | AF28: =AD28/AC28 -> 0.45347928 | AG28: =AE28+AF28 -> 1 | AH28: MAY Daily AVG = 18 * 31 days
A29: =IF(A8="","",A8) -> x | B29: MAY | C29: =May!Y39 -> 33.612903 | D29: =May!Z39 -> 0 | E29: =May!AA39 -> 0 | F29: =May!AB39 -> -31397.677 | G29: =May!AC39 -> -2518.7097 | H29: =May!AD39 -> -704.19355 | I29: =May!AE39 -> 0 | J29: =May!AF39 -> 16.16129 | ... R29: =May!AN39 -> -707.96774 | X29: =IF(C29<=0,0,1-(C29/C28)) -> -0.29779549 | Y29: =IF(O29<=0,0,1-(O29/O28)) -> 0.066072675 | AB29: Water | AC29: 2684 | AD29: =C29*31 -> 1042 | AE29: =1-(AD29/AC29) -> 0.61177347 | AF29: =AD29/AC29 -> 0.38822653 | AG29: =AE29+AF29 -> 1 | AH29: MAY Daily AVG = 34 * 31 days
A30: =IF(A9="","",A9) | B30: JUN | C30: =Jun!Y39 -> 32.888889 | D30: =Jun!Z39 -> 0 | E30: =Jun!AA39 -> 0 | F30: =Jun!AB39 -> -108147.56 | G30: =Jun!AC39 -> -8675.5556 | H30: =Jun!AD39 -> -2425.5556 | I30: =Jun!AE39 -> 0 | J30: =Jun!AF39 -> 15.555556 | ... R30: =Jun!AN39 -> -2438.5556 | X30: =IF(C30<=0,0,1-(C30/C29)) -> 0.021539774 | Y30: =IF(O30<=0,0,1-(O30/O29)) -> -0.021455939 | AD30: Electric AVG based on billing cycle (invoice)
A31: =IF(A10="","",A10) | B31: JUL | C31: =Jul!O39 -> -649950 | D31: =Jul!#REF! -> #REF! | E31: =Jul!#REF! -> #REF! | F31: =Jul!#REF! -> #REF! | G31: =Jul!#REF! -> #REF! | H31: =Jul!#REF! -> #REF! | I31: =Jul!P39 -> 0 | J31: =Jul!Q39 -> -21996 | K31: =Jul!R39 -> -2112 | L31: =Jul!#REF! -> #REF! | M31: =Jul!#REF! -> #REF! | N31: =Jul!S39 -> 0 | O31: =Jul!T39 -> -228099 | P31: =Jul!#REF! -> #REF! | Q31: =Jul!#REF! -> #REF! | R31: =Jul!#REF! -> #REF! | X31: =IF(C31<=0,0,1-(C31/C30)) -> 0 | Y31: =IF(O31<=0,0,1-(O31/O30)) -> 0 | AD31: Gas & Water based on meter readings
A32: =IF(A11="","",A11) | B32: AUG | C32: =Aug!O39 -> 0 | D32: =Aug!#REF! -> #REF! | E32: =Aug!#REF! -> #REF! | F32: =Aug!#REF! -> #REF! | G32: =Aug!#REF! -> #REF! | H32: =Aug!#REF! -> #REF! | I32: =Aug!P39 -> 0 | J32: =Aug!Q39 -> 0 | K32: =Aug!R39 -> 0 | L32: =Aug!#REF! -> #REF! | M32: =Aug!#REF! -> #REF! | N32: =Aug!S39 -> 0 | O32: =Aug!T39 -> 0 | P32: =Aug!#REF! -> #REF! | Q32: =Aug!#REF! -> #REF! | R32: =Aug!#REF! -> #REF! | X32: =IF(C32<=0,0,1-(C32/C31)) -> 0 | Y32: =IF(O32<=0,0,1-(O32/O31)) -> 0
A33: =IF(A12="","",A12) | B33: SEP | C33: =Sep!O39 -> 54 | D33: =Sep!#REF! -> #REF! | E33: =Sep!#REF! -> #REF! | F33: =Sep!#REF! -> #REF! | G33: =Sep!#REF! -> #REF! | H33: =Sep!#REF! -> #REF! | I33: =Sep!P39 -> 0 | J33: =Sep!Q39 -> 32 | K33: =Sep!R39 -> 10 | L33: =Sep!#REF! -> #REF! | M33: =Sep!#REF! -> #REF! | N33: =Sep!S39 -> 0 | O33: =Sep!T39 -> 17 | P33: =Sep!#REF! -> #REF! | Q33: =Sep!#REF! -> #REF! | R33: =Sep!#REF! -> #REF! | X33: =IF(C33<=0,0,1-(C33/C32)) -> #DIV/0! | Y33: =IF(O33<=0,0,1-(O33/O32)) -> #DIV/0!
A34: =IF(A13="","",A13) | B34: OCT | C34: =Oct!O39 -> 552 | D34: =Oct!#REF! -> #REF! | E34: =Oct!#REF! -> #REF! | F34: =Oct!#REF! -> #REF! | G34: =Oct!#REF! -> #REF! | H34: =Oct!#REF! -> #REF! | I34: =Oct!P39 -> 0 | J34: =Oct!Q39 -> 24283 | K34: =Oct!R39 -> 2583 | L34: =Oct!#REF! -> #REF! | M34: =Oct!#REF! -> #REF! | N34: =Oct!S39 -> 0 | O34: =Oct!T39 -> 229598 | P34: =Oct!#REF! -> #REF! | Q34: =Oct!#REF! -> #REF! | R34: =Oct!#REF! -> #REF! | X34: =IF(C34<=0,0,1-(C34/C33)) -> -9.2222222 | Y34: =IF(O34<=0,0,1-(O34/O33)) -> -13504.765
A35: =IF(A14="","",A14) | B35: NOV | C35: =Nov!O39 -> 34 | D35: =Nov!#REF! -> #REF! | E35: =Nov!#REF! -> #REF! | F35: =Nov!#REF! -> #REF! | G35: =Nov!#REF! -> #REF! | H35: =Nov!#REF! -> #REF! | I35: =Nov!P39 -> 0 | J35: =Nov!Q39 -> 11 | K35: =Nov!R39 -> 1 | L35: =Nov!#REF! -> #REF! | M35: =Nov!#REF! -> #REF! | N35: =Nov!S39 -> 0 | O35: =Nov!T39 -> 39 | P35: =Nov!#REF! -> #REF! | Q35: =Nov!#REF! -> #REF! | R35: =Nov!#REF! -> #REF! | X35: =IF(C35<=0,0,1-(C35/C34)) -> 0.9384058 | Y35: =IF(O35<=0,0,1-(O35/O34)) -> 0.99983014
A36: =IF(A15="","",A15) | B36: DEC | C36: =Dec!O39 -> 23 | D36: =Dec!#REF! -> #REF! | E36: =Dec!#REF! -> #REF! | F36: =Dec!#REF! -> #REF! | G36: =Dec!#REF! -> #REF! | H36: =Dec!#REF! -> #REF! | I36: =Dec!P39 -> 0 | J36: =Dec!Q39 -> 7 | K36: =Dec!R39 -> 0 | L36: =Dec!#REF! -> #REF! | M36: =Dec!#REF! -> #REF! | N36: =Dec!S39 -> 0 | O36: =Dec!T39 -> 89 | P36: =Dec!#REF! -> #REF! | Q36: =Dec!#REF! -> #REF! | R36: =Dec!#REF! -> #REF! | X36: =IF(C36<=0,0,1-(C36/C35)) -> 0.32352941 | Y36: =IF(O36<=0,0,1-(O36/O35)) -> -1.2820513
B37: JAN 21 | C37: ='Jan 21'!Y39 -> 29 | D37: 0 | E37: 0 | F37: -972052 | G37: -78043 | H37: -21758 | I37: 0 | J37: ='Jan 21'!AF39 -> 6 | K37: ='Jan 21'!AG39 -> 1 | L37: -25018 | M37: -103 | N37: 0 | O37: ='Jan 21'!AK39 -> 73 | P37: -410800 | Q37: -584400 | R37: -21490 | X37: =IF(C37<=0,0,1-(C37/C36)) -> -0.26086957 | Y37: =IF(O37<=0,0,1-(O37/O36)) -> 0.17977528
B39: AVG (YTD) | C39: =AVERAGEIF($A$4:$A$16, "x", C25:C37) -> 49.866986 | D39: =AVERAGEIF($A$4:$A$16, "x", D25:D37) -> 0 | E39: =AVERAGEIF($A$4:$A$16, "x", E25:E37) -> 0 | F39: =AVERAGEIF($A$4:$A$16, "x", F25:F37) -> -32040.067 | G39: =AVERAGEIF($A$4:$A$16, "x", G25:G37) -> -2570.2419 | H39: =AVERAGEIF($A$4:$A$16, "x", H25:H37) -> -718.60119 | J39: =AVERAGEIF($A$4:$A$16, "x", J25:J37) -> 14.413289 | K39: =AVERAGEIF($A$4:$A$16, "x", K25:K37) -> 3.0925399 | L39: =AVERAGEIF($A$4:$A$16, "x", L25:L37) -> -829.56796 | M39: =AVERAGEIF($A$4:$A$16, "x", M25:M37) -> -3.7526585 | O39: =AVERAGEIF($A$4:$A$16, "x", O25:O37) -> 57.138813 | P39: =AVERAGEIF($A$4:$A$16, "x", P25:P37) -> -13572.521 | Q39: =AVERAGEIF($A$4:$A$16, "x", Q25:Q37) -> -19245.792 | R39: =AVERAGEIF($A$4:$A$16, "x", R25:R37) -> -719.50421
B40: 1.5 | C40: =C39*$B$40 -> 74.800478 | D40: =D39*$B$40 -> 0 | E40: =E39*$B$40 -> 0 | F40: =F39*$B$40 -> -48060.1 | G40: =G39*$B$40 -> -3855.3628 | H40: =H39*$B$40 -> -1077.9018 | J40: =J39*$B$40 -> 21.619933 | K40: =K39*$B$40 -> 4.6388098 | L40: =L39*$B$40 -> -1244.3519 | M40: =M39*$B$40 -> -5.6289878 | O40: =O39*$B$40 -> 85.70822 | P40: =P39*$B$40 -> -20358.781 | Q40: =Q39*$B$40 -> -28868.687 | R40: =R39*$B$40 -> -1079.2563
B41: 0.5 | C41: =C39*$B$41 -> 24.933493 | D41: =D39*$B$41 -> 0 | E41: =E39*$B$41 -> 0 | F41: =F39*$B$41 -> -16020.033 | G41: =G39*$B$41 -> -1285.1209 | H41: =H39*$B$41 -> -359.30059 | J41: =J39*$B$41 -> 7.2066444 | K41: =K39*$B$41 -> 1.5462699 | L41: =L39*$B$41 -> -414.78398 | M41: =M39*$B$41 -> -1.8763293 | O41: =O39*$B$41 -> 28.569407 | P41: =P39*$B$41 -> -6786.2604 | Q41: 0 | R41: 0

Sheet Jan
B1: Water | I1: Cooling Towers | N1: Gas | T1: Georgia Power | Y1: Water | AF1: Cooling Towers | AK1: Gas
B2: Meter | I2: Hotel Chillers | K2: Apartment Loop | N2: Meter | Q2: MEZ | T2: Electrical Vault at P1 | Y2: Meter | AF2: Hotel Chillers | AH2: Apartment Loop | AK2: Meter | AN2: MEZ
A3: Date | B3: Bldg Main Meter #1 (CCF) | C3: Meter #2 (CCF) | D3: Fire Main Meter #3 (CCF) | E3: Pump Rm. Gall * 100 | F3: Offices at Level 20 Gall * 100 | G3: Offices at Level 30 Gall * 100 | I3: Make Up Gall * 100 | J3: Blow Down | K3: Make Up Gall * 100 | L3: Blow Down | N3: Corrected CCF *10 | O3: Not Corrected | P3: Engine | Q3: Tower Htg CCF *10 | T3: KWH (*4800) | U3: KW | V3: KQH | X3: Date | Y3: Bldg Main Meter #1 (CCF) | Z3: Meter #2 (CCF) | AA3: Fire Main Meter #3 (CCF) | AB3: Pump Rm. Gall * 100 | AC3: Offices at Level 20 Gall * 100 | AD3: Offices at Level 30 Gall * 100 | AF3: Make Up Gall * 100 | AG3: Blow Down | AH3: Make Up Gall * 100 | AI3: Blow Down | AK3: Corrected CCF *10 | AL3: Not Corrected | AM3: Engine | AN3: Tower Htg CCF *10
A5: LR | B5: ='Dec 19'!B39 -> 641288 | C5: 0 | D5: 0 | E5: 973328 | F5: 78080 | G5: 21830 | I5: ='Dec 19'!I39 -> 19163 | J5: ='Dec 19'!J39 -> 1474 | K5: 25201 | L5: 114 | N5: ='Dec 19'!N39 -> 218830 | O5: 411805 | P5: 584582 | Q5: 21490 | T5: ='Dec 19'!T39 -> 0 | U5: ='Dec 19'!U39 -> 0 | V5: ='Dec 19'!V39 -> 0
A6: 1 | B6: 642279 | I6: 19168 | J6: 1479 | N6: 219107 | O6: 411859 | P6: 584582 | Q6: 21490 | R6: =Q6-Q5 -> 0 | T6: 0 | U6: 0 | V6: 0 | W6: x | X6: 1 | Y6: =B6-B5 -> 991 | Z6: 0 | AA6: 0 | AB6: =E6-E5 -> -973328 | AC6: =F6-F5 -> -78080 | AD6: =G6-G5 -> -21830 | AF6: =I6-I5 -> 5 | AG6: =J6-J5 -> 5 | AH6: =K6-K5 -> -25201 | AI6: =L6-L5 -> -114 | AK6: =N6-N5 -> 277 | AL6: =O6-O5 -> 54 | AM6: =P6-P5 -> 0 | AN6: =Q6-Q5 -> 0 | AQ6: 5006
A7: 2 | B7: 642368 | I7: 19173 | J7: 1479 | N7: 219273 | O7: 411917 | P7: 584582 | Q7: 21490 | R7: =Q7-Q6 -> 0 | T7: 0 | U7: 0 | V7: 0 | W7: x | X7: 2 | Y7: =B7-B6 -> 89 | Z7: 0 | AA7: 0 | AB7: =E7-E6 -> 0 | AC7: =F7-F6 -> 0 | AD7: =G7-G6 -> 0 | AF7: =I7-I6 -> 5 | AG7: =J7-J6 -> 0 | AH7: =K7-K6 -> 0 | AI7: =L7-L6 -> 0 | AK7: =N7-N6 -> 166 | AL7: =O7-O6 -> 58 | AM7: =P7-P6 -> 0 | AN7: =Q7-Q6 -> 0 | AQ7: 5286
A8: 3 | B8: 642438 | I8: 19202 | J8: 1481 | N8: 219349 | O8: 411979 | P8: 584582 | Q8: 21490 | R8: =Q8-Q7 -> 0 | T8: 0 | U8: 0 | V8: 0 | W8: x | X8: 3 | Y8: =B8-B7 -> 70 | Z8: 0 | AA8: 0 | AB8: =E8-E7 -> 0 | AC8: =F8-F7 -> 0 | AD8: =G8-G7 -> 0 | AF8: =I8-I7 -> 29 | AG8: =J8-J7 -> 2 | AH8: =K8-K7 -> 0 | AI8: =L8-L7 -> 0 | AK8: =N8-N7 -> 76 | AL8: =O8-O7 -> 62 | AM8: =P8-P7 -> 0 | AN8: =Q8-Q7 -> 0 | AQ8: 5562
A9: 4 | B9: 642499 | I9: 19213 | J9: 1483 | N9: 219439 | O9: 412047 | P9: 584582 | Q9: 21490 | R9: =Q9-Q8 -> 0 | T9: 0 | U9: 0 | V9: 0 | W9: x | X9: 4 | Y9: =B9-B8 -> 61 | Z9: 0 | AA9: 0 | AB9: =E9-E8 -> 0 | AC9: =F9-F8 -> 0 | AD9: =G9-G8 -> 0 | AF9: =I9-I8 -> 11 | AG9: =J9-J8 -> 2 | AH9: =K9-K8 -> 0 | AI9: =L9-L8 -> 0 | AK9: =N9-N8 -> 90 | AL9: =O9-O8 -> 68 | AM9: =P9-P8 -> 0 | AN9: =Q9-Q8 -> 0 | AQ9: 5856
A10: 5 | B10: 642598 | I10: 19224 | J10: 1483 | N10: 219470 | O10: 412144 | P10: 584676 | Q10: 21490 | R10: =Q10-Q9 -> 0 | T10: 0 | U10: 0 | V10: 0 | W10: x | X10: 5 | Y10: =B10-B9 -> 99 | Z10: 0 | AA10: 0 | AB10: =E10-E9 -> 0 | AC10: =F10-F9 -> 0 | AD10: =G10-G9 -> 0 | AF10: =I10-I9 -> 11 | AG10: =J10-J9 -> 0 | AH10: =K10-K9 -> 0 | AI10: =L10-L9 -> 0 | AK10: =N10-N9 -> 31 | AL10: =O10-O9 -> 97 | AM10: =P10-P9 -> 94 | AN10: =Q10-Q9 -> 0 | AQ10: 6090
A11: 6 | B11: 642258 | I11: 19237 | J11: 1486 | N11: 219606 | O11: 412219 | P11: 584676 | Q11: 21585 | R11: =Q11-Q10 -> 95 | T11: 0 | U11: 0 | V11: 0 | W11: x | X11: 6 | Y11: =B11-B10 -> -340 | Z11: 0 | AA11: 0 | AB11: =E11-E10 -> 0 | AC11: =F11-F10 -> 0 | AD11: =G11-G10 -> 0 | AF11: =I11-I10 -> 13 | AG11: =J11-J10 -> 3 | AH11: =K11-K10 -> 0 | AI11: =L11-L10 -> 0 | AK11: =N11-N10 -> 136 | AL11: =O11-O10 -> 75 | AM11: =P11-P10 -> 0 | AN11: =Q11-Q10 -> 95 | AQ11: 6354
A12: 7 | B12: 642301 | I12: 19257 | J12: 1488 | N12: 219674 | O12: 412326 | P12: 584676 | Q12: 21754 | R12: =Q12-Q11 -> 169 | T12: 0 | U12: 0 | V12: 0 | W12: x | X12: 7 | Y12: =B12-B11 -> 43 | Z12: 0 | AA12: 0 | AB12: =E12-E11 -> 0 | AC12: =F12-F11 -> 0 | AD12: =G12-G11 -> 0 | AF12: =I12-I11 -> 20 | AG12: =J12-J11 -> 2 | AH12: =K12-K11 -> 0 | AI12: =L12-L11 -> 0 | AK12: =N12-N11 -> 68 | AL12: =O12-O11 -> 107 | AM12: =P12-P11 -> 0 | AN12: =Q12-Q11 -> 169 | AQ12: 6723
A13: 8 | B13: 642399 | I13: 19258 | J13: 1488 | N13: 219763 | O13: 412436 | P13: 584676 | Q13: 21947 | R13: =Q13-Q12 -> 193 | T13: 0 | U13: 0 | V13: 0 | W13: x | X13: 8 | Y13: =B13-B12 -> 98 | Z13: 0 | AA13: 0 | AB13: =E13-E12 -> 0 | AC13: =F13-F12 -> 0 | AD13: =G13-G12 -> 0 | AF13: =I13-I12 -> 1 | AG13: =J13-J12 -> 0 | AH13: =K13-K12 -> 0 | AI13: =L13-L12 -> 0 | AK13: =N13-N12 -> 89 | AL13: =O13-O12 -> 110 | AM13: =P13-P12 -> 0 | AN13: =Q13-Q12 -> 193 | AQ13: 7089
A14: 9 | B14: 642497 | I14: 19273 | J14: 1490 | N14: 219838 | R14: =Q14-Q13 -> -21947 | T14: 0 | U14: 0 | V14: 0 | W14: x | X14: 9 | Y14: =B14-B13 -> 98 | Z14: 0 | AA14: 0 | AB14: =E14-E13 -> 0 | AC14: =F14-F13 -> 0 | AD14: =G14-G13 -> 0 | AF14: =I14-I13 -> 15 | AG14: =J14-J13 -> 2 | AH14: =K14-K13 -> 0 | AI14: =L14-L13 -> 0 | AK14: =N14-N13 -> 75 | AL14: =O14-O13 -> -412436 | AM14: =P14-P13 -> -584676 | AN14: =Q14-Q13 -> -21947 | AQ14: 7139
A15: 10 | B15: 642590 | I15: 19286 | J15: 1491 | N15: 219870 | R15: =Q15-Q14 -> 0 | T15: 0 | U15: 0 | V15: 0 | W15: x | X15: 10 | Y15: =B15-B14 -> 93 | Z15: 0 | AA15: 0 | AB15: =E15-E14 -> 0 | AC15: =F15-F14 -> 0 | AD15: =G15-G14 -> 0 | AF15: =I15-I14 -> 13 | AG15: =J15-J14 -> 1 | AH15: =K15-K14 -> 0 | AI15: =L15-L14 -> 0 | AK15: =N15-N14 -> 32 | AL15: =O15-O14 -> 0 | AM15: =P15-P14 -> 0 | AN15: =Q15-Q14 -> 0 | AQ15: 7538
A16: 11 | B16: 642688 | I16: 19311 | J16: 1500 | N16: 219970 | R16: =Q16-Q15 -> 0 | T16: 0 | U16: 0 | V16: 0 | W16: x | X16: 11 | Y16: =B16-B15 -> 98 | Z16: 0 | AA16: 0 | AB16: =E16-E15 -> 0 | AC16: =F16-F15 -> 0 | AD16: =G16-G15 -> 0 | AF16: =I16-I15 -> 25 | AG16: =J16-J15 -> 9 | AH16: =K16-K15 -> 0 | AI16: =L16-L15 -> 0 | AK16: =N16-N15 -> 100 | AL16: =O16-O15 -> 0 | AM16: =P16-P15 -> 0 | AN16: =Q16-Q15 -> 0 | AQ16: 7411
A17: 12 | B17: 642585 | I17: 19324 | J17: 1500 | N17: 220109 | R17: =Q17-Q16 -> 0 | T17: 0 | U17: 0 | V17: 0 | W17: x | X17: 12 | Y17: =B17-B16 -> -103 | Z17: 0 | AA17: 0 | AB17: =E17-E16 -> 0 | AC17: =F17-F16 -> 0 | AD17: =G17-G16 -> 0 | AF17: =I17-I16 -> 13 | AG17: =J17-J16 -> 0 | AH17: =K17-K16 -> 0 | AI17: =L17-L16 -> 0 | AK17: =N17-N16 -> 139 | AL17: =O17-O16 -> 0 | AM17: =P17-P16 -> 0 | AN17: =Q17-Q16 -> 0 | AQ17: 7466
A18: 13 | B18: 642645 | I18: 19344 | J18: 1500 | N18: 220190 | R18: =Q18-Q17 -> 0 | T18: 0 | U18: 0 | V18: 0 | W18: x | X18: 13 | Y18: =B18-B17 -> 60 | Z18: 0 | AA18: 0 | AB18: =E18-E17 -> 0 | AC18: =F18-F17 -> 0 | AD18: =G18-G17 -> 0 | AF18: =I18-I17 -> 20 | AG18: =J18-J17 -> 0 | AH18: =K18-K17 -> 0 | AI18: =L18-L17 -> 0 | AK18: =N18-N17 -> 81 | AL18: =O18-O17 -> 0 | AM18: =P18-P17 -> 0 | AN18: =Q18-Q17 -> 0 | AQ18: 7442
A19: 14 | B19: 642701 | I19: 19358 | J19: 1503 | N19: 220272 | R19: =Q19-Q18 -> 0 | T19: 0 | U19: 0 | V19: 0 | W19: x | X19: 14 | Y19: =B19-B18 -> 56 | Z19: 0 | AA19: 0 | AB19: =E19-E18 -> 0 | AC19: =F19-F18 -> 0 | AD19: =G19-G18 -> 0 | AF19: =I19-I18 -> 14 | AG19: =J19-J18 -> 3 | AH19: =K19-K18 -> 0 | AI19: =L19-L18 -> 0 | AK19: =N19-N18 -> 82 | AL19: =O19-O18 -> 0 | AM19: =P19-P18 -> 0 | AN19: =Q19-Q18 -> 0 | AQ19: 7568
A20: 15 | B20: 642778 | I20: 19366 | J20: 1507 | N20: 220299 | R20: =Q20-Q19 -> 0 | T20: 0 | U20: 0 | V20: 0 | W20: x | X20: 15 | Y20: =B20-B19 -> 77 | Z20: 0 | AA20: 0 | AB20: =E20-E19 -> 0 | AC20: =F20-F19 -> 0 | AD20: =G20-G19 -> 0 | AF20: =I20-I19 -> 8 | AG20: =J20-J19 -> 4 | AH20: =K20-K19 -> 0 | AI20: =L20-L19 -> 0 | AK20: =N20-N19 -> 27 | AL20: =O20-O19 -> 0 | AM20: =P20-P19 -> 0 | AN20: =Q20-Q19 -> 0 | AQ20: 7677
A21: 16 | B21: 642868 | I21: 19374 | J21: 1511 | N21: 220396 | R21: =Q21-Q20 -> 0 | T21: 0 | U21: 0 | V21: 0 | W21: x | X21: 16 | Y21: =B21-B20 -> 90 | Z21: 0 | AA21: 0 | AB21: =E21-E20 -> 0 | AC21: =F21-F20 -> 0 | AD21: =G21-G20 -> 0 | AF21: =I21-I20 -> 8 | AG21: =J21-J20 -> 4 | AH21: =K21-K20 -> 0 | AI21: =L21-L20 -> 0 | AK21: =N21-N20 -> 97 | AL21: =O21-O20 -> 0 | AM21: =P21-P20 -> 0 | AN21: =Q21-Q20 -> 0 | AQ21: 7813
A22: 17 | B22: 642918 | I22: 19389 | J22: 1512 | N22: 220456 | R22: =Q22-Q21 -> 0 | T22: 0 | U22: 0 | V22: 0 | W22: x | X22: 17 | Y22: =B22-B21 -> 50 | Z22: 0 | AA22: 0 | AB22: =E22-E21 -> 0 | AC22: =F22-F21 -> 0 | AD22: =G22-G21 -> 0 | AF22: =I22-I21 -> 15 | AG22: =J22-J21 -> 1 | AH22: =K22-K21 -> 0 | AI22: =L22-L21 -> 0 | AK22: =N22-N21 -> 60 | AL22: =O22-O21 -> 0 | AM22: =P22-P21 -> 0 | AN22: =Q22-Q21 -> 0 | AQ22: 7919
A23: 18 | B23: 642955 | I23: 19392 | J23: 1514 | N23: 220489 | R23: =Q23-Q22 -> 0 | T23: 0 | U23: 0 | V23: 0 | W23: x | X23: 18 | Y23: =B23-B22 -> 37 | Z23: 0 | AA23: 0 | AB23: =E23-E22 -> 0 | AC23: =F23-F22 -> 0 | AD23: =G23-G22 -> 0 | AF23: =I23-I22 -> 3 | AG23: =J23-J22 -> 2 | AH23: =K23-K22 -> 0 | AI23: =L23-L22 -> 0 | AK23: =N23-N22 -> 33 | AL23: =O23-O22 -> 0 | AM23: =P23-P22 -> 0 | AN23: =Q23-Q22 -> 0 | AQ23: 8102
A24: 19 | B24: 643049 | I24: 19417 | J24: 1517 | N24: 220610 | R24: =Q24-Q23 -> 0 | T24: 0 | U24: 0 | V24: 0 | W24: x | X24: 19 | Y24: =B24-B23 -> 94 | Z24: 0 | AA24: 0 | AB24: =E24-E23 -> 0 | AC24: =F24-F23 -> 0 | AD24: =G24-G23 -> 0 | AF24: =I24-I23 -> 25 | AG24: =J24-J23 -> 3 | AH24: =K24-K23 -> 0 | AI24: =L24-L23 -> 0 | AK24: =N24-N23 -> 121 | AL24: =O24-O23 -> 0 | AM24: =P24-P23 -> 0 | AN24: =Q24-Q23 -> 0 | AQ24: 8282
A25: 20 | B25: 643115 | I25: 19425 | J25: 1517 | N25: 220716 | R25: =Q25-Q24 -> 0 | T25: 0 | U25: 0 | V25: 0 | W25: x | X25: 20 | Y25: =B25-B24 -> 66 | Z25: 0 | AA25: 0 | AB25: =E25-E24 -> 0 | AC25: =F25-F24 -> 0 | AD25: =G25-G24 -> 0 | AF25: =I25-I24 -> 8 | AG25: =J25-J24 -> 0 | AH25: =K25-K24 -> 0 | AI25: =L25-L24 -> 0 | AK25: =N25-N24 -> 106 | AL25: =O25-O24 -> 0 | AM25: =P25-P24 -> 0 | AN25: =Q25-Q24 -> 0 | AQ25: 8490
... A36: 31 | B36: 643734 | I36: 19525 | J36: 1530 | N36: 221799 | R36: =Q36-Q35 -> 0 | T36: 0 | U36: 0 | V36: 0 | W36: x | X36: 31 | Y36: =B36-B35 -> 66 | Z36: 0 | AA36: 0 | AB36: =E36-E35 -> 0 | AC36: =F36-F35 -> 0 | AD36: =G36-G35 -> 0 | AF36: =I36-I35 -> 1 | AG36: =J36-J35 -> 1 | AH36: =K36-K35 -> 0 | AI36: =L36-L35 -> 0 | AK36: =N36-N35 -> 139 | AL36: =O36-O35 -> 0 | AM36: =P36-P35 -> 0 | AN36: =Q36-Q35 -> 0 | AQ36: 10273
B37: (5 Digits) | E37: (6 Digits) | F37: (5 Digits) | G37: (5 Digits) | I37: (5 Digits) | J37: (4 Digits) | K37: (4 Digits) | L37: (4 Digits) | N37: (6 Digits) | O37: (6 Digits) | P37: (6 Digits) | Q37: (5 Digits)
A39: LD | B39: =LARGE(B5:B36, 1) -> 643734 | C39: =LARGE(C5:C36, 1) -> 0 | D39: =LARGE(D5:D36, 1) -> 0 | E39: =LARGE(E5:E36, 1) -> 973328 | F39: =LARGE(F5:F36, 1) -> 78080 | G39: =LARGE(G5:G36, 1) -> 21830 | I39: =LARGE(I5:I36, 1) -> 19525 | J39: =LARGE(J5:J36, 1) -> 1530 | K39: =LARGE(K5:K36, 1) -> 25201 | L39: =LARGE(L5:L36, 1) -> 114 | N39: =LARGE(N5:N36, 1) -> 221799 | O39: =LARGE(O5:O36, 1) -> 412436 | P39: =LARGE(P5:P36, 1) -> 584676 | Q39: =LARGE(Q5:Q36, 1) -> 21947 | T39: =LARGE(T5:T36, 1) -> 0 | U39: =LARGE(U5:U36, 1) -> 0 | V39: =LARGE(V5:V36, 1) -> 0 | X39: AVG | Y39: =AVERAGEIF($W$6:$W$36, "x",Y6:Y36) -> 78.903226 | Z39: =AVERAGEIF($W$6:$W$36, "x",Z6:Z36) -> 0 | AA39: =AVERAGEIF($W$6:$W$36, "x",AA6:AA36) -> 0 | AB39: =AVERAGEIF($W$6:$W$36, "x",AB6:AB36) -> -31397.677 | AC39: =AVERAGEIF($W$6:$W$36, "x",AC6:AC36) -> -2518.7097 | AD39: =AVERAGEIF($W$6:$W$36, "x",AD6:AD36) -> -704.19355 | AF39: =AVERAGEIF($W$6:$W$36, "x",AF6:AF36) -> 11.677419 | AG39: =AVERAGEIF($W$6:$W$36, "x",AG6:AG36) -> 1.8064516 | AH39: =AVERAGEIF($W$6:$W$36, "x",AH6:AH36) -> -812.93548 | AI39: =AVERAGEIF($W$6:$W$36, "x",AI6:AI36) -> -3.6774194 | AK39: =AVERAGEIF($W$6:$W$36, "x",AK6:AK36) -> 95.774194 | AL39: =AVERAGEIF($W$6:$W$36, "x",AL6:AL36) -> -13284.032 | AM39: =AVERAGEIF($W$6:$W$36, "x",AM6:AM36) -> -18857.484 | AN39: =AVERAGEIF($W$6:$W$36, "x",AN6:AN36) -> -693.22581
B41: Consumption: | X41: PRV AVG
B42: =B39-B5 -> 2446 | C42: =C39-C5 -> 0 | D42: =D39-D5 -> 0 | E42: =E39-E5 -> 0 | F42: =F39-F5 -> 0 | G42: =G39-G5 -> 0 | I42: =I39-I5 -> 362 | J42: =J39-J5 -> 56 | K42: =K39-K5 -> 0 | L42: =L39-L5 -> 0 | N42: =N39-N5 -> 2969 | O42: =O39-O5 -> 631 | P42: =P39-P5 -> 94 | Q42: =Q39-Q5 -> 457 | T42: =T39-T5 -> 0 | U42: =U39-U5 -> 0 | V42: =V39-V5 -> 0 | Y42: ='Dec 19'!Y39 -> 35.483871 | Z42: ='Dec 19'!Z39 -> 0 | AA42: ='Dec 19'!AA39 -> 0 | AB42: ='Dec 19'!AB39 -> 0 | AC42: ='Dec 19'!AC39 -> 0 | AD42: ='Dec 19'!AD39 -> 0 | AF42: ='Dec 19'!AF39 -> 12.225806 | AG42: ='Dec 19'!AG39 -> 1.8064516 | AH42: ='Dec 19'!AH39 -> 0 | AI42: ='Dec 19'!AI39 -> 0 | AK42: ='Dec 19'!AK39 -> 76.451613 | AL42: ='Dec 19'!AL39 -> 0 | AM42: ='Dec 19'!AM39 -> 0 | AN42: ='Dec 19'!AN39 -> 0
X43: 1.5 | Y43: =Y42*$X$43 -> 53.225806 | Z43: =Z42*$X$43 -> 0 | AA43: =AA42*$X$43 -> 0 | AB43: =AB42*$X$43 -> 0 | AC43: =AC42*$X$43 -> 0 | AD43: =AD42*$X$43 -> 0 | AF43: =AF42*$X$43 -> 18.33871 | AG43: =AG42*$X$43 -> 2.7096774 | AH43: =AH42*$X$43 -> 0 | AI43: =AI42*$X$43 -> 0 | AK43: =AK42*$X$43 -> 114.67742 | AL43: =AL42*$X$43 -> 0 | AM43: =AM42*$X$43 -> 0 | AN43: =AN42*$X$43 -> 0
R44: AVG | X44: 0.5 | Y44: =Y42*$X$44 -> 17.741935 | Z44: =Z42*$X$44 -> 0 | AA44: =AA42*$X$44 -> 0 | AB44: =AB42*$X$44 -> 0 | AC44: =AC42*$X$44 -> 0 | AD44: =AD42*$X$44 -> 0 | AF44: =AF42*$X$44 -> 6.1129032 | AG44: =AG42*$X$44 -> 0.90322581 | AH44: =AH42*$X$44 -> 0 | AI44: =AI42*$X$44 -> 0 | AK44: =AK42*$X$44 -> 38.225806 | AL44: =AL42*$X$44 -> 0 | AM44: =AM42*$X$44 -> 0 | AN44: =AN42*$X$44 -> 0
R45: =AVERAGE(R6:R36) -> -693.22581
Y46: Note 1 | Z46: Normal formating for cells where the daily average consumption is within range from the previous month's average range noted above.
Y47: Note 2 | Z47: Indicates the daily average for that day is outside the average range for that meter, based on the previous month's averages. Not necessarily a problem, just something to keeep an eye on.
X48: ! | Y48: Note 3 | Z48: This RED FLAG should be brought to Management for further review as to why it is more than twice the monthly average. Still can be explained, depending on the meter, but warrants immediate review to minimize impact to utilities and/or billing.
Y49: Note 4 | Z49: This is the same calculation as the RED FLAG, but is a known non-issue (example: Emergency Generator run once a week, plus bi-monthly inspections)
X50: ! | Y50: Note 5 | Z50: THIS IS AN ISSUE. METERS DO NOT RUN BACKWARDS, THUS NO NEGATIVE READINGS ALLOWED. Check for a simple typo or transposed number in the reading and/or verify the meter reading logged is correct by physically checking meter again.
R51: =AVERAGE(R6:R36) -> -693.22581

Sheet Feb
B1: Water | I1: Cooling Towers | N1: Gas | T1: Georgia Power | Y1: Water | AF1: Cooling Towers | AK1: Gas
B2: Meter | I2: Hotel Chillers | K2: Apartment Loop | N2: Meter | Q2: MEZ | T2: Electrical Vault at P1 | Y2: Meter | AF2: Hotel Chillers | AH2: Apartment Loop | AK2: Meter | AN2: MEZ
A3: Date | B3: Bldg Main Meter #1 (CCF) | C3: Meter #2 (CCF) | D3: Fire Main Meter #3 (CCF) | E3: Pump Rm. Gall * 100 | F3: Offices at Level 20 Gall * 100 | G3: Offices at Level 30 Gall * 100 | I3: Make Up Gall * 100 | J3: Blow Down | K3: Make Up Gall * 100 | L3: Blow Down | N3: Corrected CCF *10 | O3: Not Corrected | P3: Engine | Q3: Tower Htg CCF *10 | T3: KWH (*4800) | U3: KW | V3: KQH | X3: Date | Y3: Bldg Main Meter #1 (CCF) | Z3: Meter #2 (CCF) | AA3: Fire Main Meter #3 (CCF) | AB3: Pump Rm. Gall * 100 | AC3: Offices at Level 20 Gall * 100 | AD3: Offices at Level 30 Gall * 100 | AF3: Make Up Gall * 100 | AG3: Blow Down | AH3: Make Up Gall * 100 | AI3: Blow Down | AK3: Corrected CCF *10 | AL3: Not Corrected | AM3: Engine | AN3: Tower Htg CCF *10
A5: LR | B5: =Jan!B39 -> 643734 | C5: =Jan!C39 -> 0 | D5: =Jan!D39 -> 0 | E5: =Jan!E39 -> 973328 | F5: =Jan!F39 -> 78080 | G5: =Jan!G39 -> 21830 | I5: =Jan!I39 -> 19525 | J5: =Jan!J39 -> 1530 | K5: =Jan!K39 -> 25201 | L5: =Jan!L39 -> 114 | N5: =Jan!N39 -> 221799 | O5: =Jan!O39 -> 412436 | P5: =Jan!P39 -> 584676 | Q5: =Jan!Q39 -> 21947 | T5: =Jan!T39 -> 0 | U5: =Jan!U39 -> 0 | V5: =Jan!V39 -> 0
A6: 1 | B6: 643799 | I6: 19528 | J6: 1531 | N6: 221915 | R6: =Q6-Q5 -> -21947 | T6: 0 | U6: 0 | V6: 0 | W6: x | X6: 1 | Y6: =B6-B5 -> 65 | Z6: =C6-C5 -> 0 | AA6: =D6-D5 -> 0 | AB6: =E6-E5 -> -973328 | AC6: =F6-F5 -> -78080 | AD6: =G6-G5 -> -21830 | AF6: =I6-I5 -> 3 | AG6: =J6-J5 -> 1 | AH6: =K6-K5 -> -25201 | AI6: =L6-L5 -> -114 | AK6: =N6-N5 -> 116 | AL6: =O6-O5 -> -412436 | AM6: =P6-P5 -> -584676 | AN6: =Q6-Q5 -> -21947
A7: 2 | B7: 643899 | I7: 19550 | J7: 1532 | N7: 221965 | R7: =Q7-Q6 -> 0 | T7: 0 | U7: 0 | V7: 0 | W7: x | X7: 2 | Y7: =B7-B6 -> 100 | Z7: =C7-C6 -> 0 | AA7: =D7-D6 -> 0 | AB7: =E7-E6 -> 0 | AC7: =F7-F6 -> 0 | AD7: =G7-G6 -> 0 | AF7: =I7-I6 -> 22 | AG7: =J7-J6 -> 1 | AH7: =K7-K6 -> 0 | AI7: =L7-L6 -> 0 | AK7: =N7-N6 -> 50 | AL7: =O7-O6 -> 0 | AM7: =P7-P6 -> 0 | AN7: =Q7-Q6 -> 0
A8: 3 | B8: 643957 | I8: 19565 | J8: 1540 | N8: 222096 | R8: =Q8-Q7 -> 0 | T8: 0 | U8: 0 | V8: 0 | W8: x | X8: 3 | Y8: =B8-B7 -> 58 | Z8: =C8-C7 -> 0 | AA8: =D8-D7 -> 0 | AB8: =E8-E7 -> 0 | AC8: =F8-F7 -> 0 | AD8: =G8-G7 -> 0 | AF8: =I8-I7 -> 15 | AG8: =J8-J7 -> 8 | AH8: =K8-K7 -> 0 | AI8: =L8-L7 -> 0 | AK8: =N8-N7 -> 131 | AL8: =O8-O7 -> 0 | AM8: =P8-P7 -> 0 | AN8: =Q8-Q7 -> 0
A9: 4 | B9: 644016 | I9: 19577 | J9: 1545 | N9: 222163 | R9: =Q9-Q8 -> 0 | T9: 0 | U9: 0 | V9: 0 | W9: x | X9: 4 | Y9: =B9-B8 -> 59 | Z9: =C9-C8 -> 0 | AA9: =D9-D8 -> 0 | AB9: =E9-E8 -> 0 | AC9: =F9-F8 -> 0 | AD9: =G9-G8 -> 0 | AF9: =I9-I8 -> 12 | AG9: =J9-J8 -> 5 | AH9: =K9-K8 -> 0 | AI9: =L9-L8 -> 0 | AK9: =N9-N8 -> 67 | AL9: =O9-O8 -> 0 | AM9: =P9-P8 -> 0 | AN9: =Q9-Q8 -> 0
A10: 5 | B10: 644099 | I10: 19583 | J10: 1546 | N10: 222231 | R10: =Q10-Q9 -> 0 | T10: 0 | U10: 0 | V10: 0 | W10: x | X10: 5 | Y10: =B10-B9 -> 83 | Z10: =C10-C9 -> 0 | AA10: =D10-D9 -> 0 | AB10: =E10-E9 -> 0 | AC10: =F10-F9 -> 0 | AD10: =G10-G9 -> 0 | AF10: =I10-I9 -> 6 | AG10: =J10-J9 -> 1 | AH10: =K10-K9 -> 0 | AI10: =L10-L9 -> 0 | AK10: =N10-N9 -> 68 | AL10: =O10-O9 -> 0 | AM10: =P10-P9 -> 0 | AN10: =Q10-Q9 -> 0
A11: 6 | B11: 644186 | I11: 19588 | J11: 1551 | N11: 222364 | R11: =Q11-Q10 -> 0 | T11: 0 | U11: 0 | V11: 0 | W11: x | X11: 6 | Y11: =B11-B10 -> 87 | Z11: =C11-C10 -> 0 | AA11: =D11-D10 -> 0 | AB11: =E11-E10 -> 0 | AC11: =F11-F10 -> 0 | AD11: =G11-G10 -> 0 | AF11: =I11-I10 -> 5 | AG11: =J11-J10 -> 5 | AH11: =K11-K10 -> 0 | AI11: =L11-L10 -> 0 | AK11: =N11-N10 -> 133 | AL11: =O11-O10 -> 0 | AM11: =P11-P10 -> 0 | AN11: =Q11-Q10 -> 0
A12: 7 | B12: 644278 | I12: 19594 | J12: 1552 | N12: 222503 | R12: =Q12-Q11 -> 0 | T12: 0 | U12: 0 | V12: 0 | W12: x | X12: 7 | Y12: =B12-B11 -> 92 | Z12: =C12-C11 -> 0 | AA12: =D12-D11 -> 0 | AB12: =E12-E11 -> 0 | AC12: =F12-F11 -> 0 | AD12: =G12-G11 -> 0 | AF12: =I12-I11 -> 6 | AG12: =J12-J11 -> 1 | AH12: =K12-K11 -> 0 | AI12: =L12-L11 -> 0 | AK12: =N12-N11 -> 139 | AL12: =O12-O11 -> 0 | AM12: =P12-P11 -> 0 | AN12: =Q12-Q11 -> 0
A13: 8 | B13: 644367 | I13: 19625 | J13: 1553 | N13: 222587 | R13: =Q13-Q12 -> 0 | T13: 0 | U13: 0 | V13: 0 | W13: x | X13: 8 | Y13: =B13-B12 -> 89 | Z13: =C13-C12 -> 0 | AA13: =D13-D12 -> 0 | AB13: =E13-E12 -> 0 | AC13: =F13-F12 -> 0 | AD13: =G13-G12 -> 0 | AF13: =I13-I12 -> 31 | AG13: =J13-J12 -> 1 | AH13: =K13-K12 -> 0 | AI13: =L13-L12 -> 0 | AK13: =N13-N12 -> 84 | AL13: =O13-O12 -> 0 | AM13: =P13-P12 -> 0 | AN13: =Q13-Q12 -> 0
A14: 9 | B14: 644396 | I14: 19639 | J14: 1554 | N14: 222662 | R14: =Q14-Q13 -> 0 | T14: 0 | U14: 0 | V14: 0 | W14: x | X14: 9 | Y14: =B14-B13 -> 29 | Z14: =C14-C13 -> 0 | AA14: =D14-D13 -> 0 | AB14: =E14-E13 -> 0 | AC14: =F14-F13 -> 0 | AD14: =G14-G13 -> 0 | AF14: =I14-I13 -> 14 | AG14: =J14-J13 -> 1 | AH14: =K14-K13 -> 0 | AI14: =L14-L13 -> 0 | AK14: =N14-N13 -> 75 | AL14: =O14-O13 -> 0 | AM14: =P14-P13 -> 0 | AN14: =Q14-Q13 -> 0
A15: 10 | B15: 644436 | I15: 19660 | J15: 1563 | N15: 222721 | R15: =Q15-Q14 -> 0 | T15: 0 | U15: 0 | V15: 0 | W15: x | X15: 10 | Y15: =B15-B14 -> 40 | Z15: =C15-C14 -> 0 | AA15: =D15-D14 -> 0 | AB15: =E15-E14 -> 0 | AC15: =F15-F14 -> 0 | AD15: =G15-G14 -> 0 | AF15: =I15-I14 -> 21 | AG15: =J15-J14 -> 9 | AH15: =K15-K14 -> 0 | AI15: =L15-L14 -> 0 | AK15: =N15-N14 -> 59 | AL15: =O15-O14 -> 0 | AM15: =P15-P14 -> 0 | AN15: =Q15-Q14 -> 0
A16: 11 | B16: 644513 | I16: 19675 | J16: 1568 | N16: 222789 | R16: =Q16-Q15 -> 0 | T16: 0 | U16: 0 | V16: 0 | W16: x | X16: 11 | Y16: =B16-B15 -> 77 | Z16: =C16-C15 -> 0 | AA16: =D16-D15 -> 0 | AB16: =E16-E15 -> 0 | AC16: =F16-F15 -> 0 | AD16: =G16-G15 -> 0 | AF16: =I16-I15 -> 15 | AG16: =J16-J15 -> 5 | AH16: =K16-K15 -> 0 | AI16: =L16-L15 -> 0 | AK16: =N16-N15 -> 68 | AL16: =O16-O15 -> 0 | AM16: =P16-P15 -> 0 | AN16: =Q16-Q15 -> 0
A17: 12 | B17: 644599 | I17: 19676 | J17: 1568 | N17: 222826 | R17: =Q17-Q16 -> 0 | T17: 0 | U17: 0 | V17: 0 | W17: x | X17: 12 | Y17: =B17-B16 -> 86 | Z17: =C17-C16 -> 0 | AA17: =D17-D16 -> 0 | AB17: =E17-E16 -> 0 | AC17: =F17-F16 -> 0 | AD17: =G17-G16 -> 0 | AF17: =I17-I16 -> 1 | AG17: =J17-J16 -> 0 | AH17: =K17-K16 -> 0 | AI17: =L17-L16 -> 0 | AK17: =N17-N16 -> 37 | AL17: =O17-O16 -> 0 | AM17: =P17-P16 -> 0 | AN17: =Q17-Q16 -> 0
... A33: 28 | B33: 645493 | I33: 19859 | J33: 1605 | N33: 224407 | R33: =Q33-Q32 -> 0 | T33: 0 | U33: 0 | V33: 0 | W33: x | X33: 28 | Y33: =B33-B32 -> 75 | Z33: =C33-C32 -> 0 | AA33: =D33-D32 -> 0 | AB33: =E33-E32 -> 0 | AC33: =F33-F32 -> 0 | AD33: =G33-G32 -> 0 | AF33: =I33-I32 -> 10 | AG33: =J33-J32 -> 2 | AH33: =K33-K32 -> 0 | AI33: =L33-L32 -> 0 | AK33: =N33-N32 -> 96 | AL33: =O33-O32 -> 0 | AM33: =P33-P32 -> 0 | AN33: =Q33-Q32 -> 0
A34: 29 | B34: 645568 | I34: 19870 | J34: 1607 | N34: 224503 | T34: 0 | U34: 0 | V34: 0 | W34: x | X34: 29 | Y34: =B34-B33 -> 75 | Z34: =C34-C33 -> 0 | AA34: =D34-D33 -> 0 | AB34: =E34-E33 -> 0 | AC34: =F34-F33 -> 0 | AD34: =G34-G33 -> 0 | AF34: =I34-I33 -> 11 | AG34: =J34-J33 -> 2 | AH34: =K34-K33 -> 0 | AI34: =L34-L33 -> 0 | AK34: =N34-N33 -> 96 | AL34: =O34-O33 -> 0 | AM34: =P34-P33 -> 0 | AN34: =Q34-Q33 -> 0
A35: 30 | T35: 0 | U35: 0 | V35: 0 | X35: 30 | Y35: =B35-B34 -> -645568 | Z35: =C35-C34 -> 0 | AA35: =D35-D34 -> 0 | AB35: =E35-E34 -> 0 | AC35: =F35-F34 -> 0 | AD35: =G35-G34 -> 0 | AF35: =I35-I34 -> -19870 | AG35: =J35-J34 -> -1607 | AH35: =K35-K34 -> 0 | AI35: =L35-L34 -> 0 | AK35: =N35-N34 -> -224503 | AL35: =O35-O34 -> 0 | AM35: =P35-P34 -> 0 | AN35: =Q35-Q34 -> 0
A36: 31 | T36: 0 | U36: 0 | V36: 0 | X36: 31 | Y36: =B36-B35 -> 0 | Z36: =C36-C35 -> 0 | AA36: =D36-D35 -> 0 | AB36: =E36-E35 -> 0 | AC36: =F36-F35 -> 0 | AD36: =G36-G35 -> 0 | AF36: =I36-I35 -> 0 | AG36: =J36-J35 -> 0 | AH36: =K36-K35 -> 0 | AI36: =L36-L35 -> 0 | AK36: =N36-N35 -> 0 | AL36: =O36-O35 -> 0 | AM36: =P36-P35 -> 0 | AN36: =Q36-Q35 -> 0
B37: (6 Digits) | E37: (6 Digits) | F37: (5 Digits) | G37: (5 Digits) | I37: (5 Digits) | J37: (4 Digits) | K37: (4 Digits) | L37: (4 Digits) | N37: (6 Digits) | O37: (6 Digits) | P37: (6 Digits) | Q37: (5 Digits)
A39: LD | B39: =LARGE(B5:B36, 1) -> 645568 | C39: =LARGE(C5:C36, 1) -> 0 | D39: =LARGE(D5:D36, 1) -> 0 | E39: =LARGE(E5:E36, 1) -> 973328 | F39: =LARGE(F5:F36, 1) -> 78080 | G39: =LARGE(G5:G36, 1) -> 21830 | I39: =LARGE(I5:I36, 1) -> 19870 | J39: =LARGE(J5:J36, 1) -> 1607 | K39: =LARGE(K5:K36, 1) -> 25201 | L39: =LARGE(L5:L36, 1) -> 114 | N39: =LARGE(N5:N36, 1) -> 224503 | O39: =LARGE(O5:O36, 1) -> 412436 | P39: =LARGE(P5:P36, 1) -> 584676 | Q39: =LARGE(Q5:Q36, 1) -> 21947 | T39: =LARGE(T5:T36, 1) -> 0 | U39: =LARGE(U5:U36, 1) -> 0 | V39: =LARGE(V5:V36, 1) -> 0 | X39: AVG | Y39: =AVERAGEIF($W$6:$W$36, "x",Y6:Y36) -> 63.241379 | Z39: =AVERAGEIF($W$6:$W$36, "x",Z6:Z36) -> 0 | AA39: =AVERAGEIF($W$6:$W$36, "x",AA6:AA36) -> 0 | AB39: =AVERAGEIF($W$6:$W$36, "x",AB6:AB36) -> -33563.034 | AC39: =AVERAGEIF($W$6:$W$36, "x",AC6:AC36) -> -2692.4138 | AD39: =AVERAGEIF($W$6:$W$36, "x",AD6:AD36) -> -752.75862 | AF39: =AVERAGEIF($W$6:$W$36, "x",AF6:AF36) -> 11.896552 | AG39: =AVERAGEIF($W$6:$W$36, "x",AG6:AG36) -> 2.6551724 | AH39: =AVERAGEIF($W$6:$W$36, "x",AH6:AH36) -> -869 | AI39: =AVERAGEIF($W$6:$W$36, "x",AI6:AI36) -> -3.9310345 | AK39: =AVERAGEIF($W$6:$W$36, "x",AK6:AK36) -> 93.241379 | AL39: =AVERAGEIF($W$6:$W$36, "x",AL6:AL36) -> -14221.931 | AM39: =AVERAGEIF($W$6:$W$36, "x",AM6:AM36) -> -20161.241 | AN39: =AVERAGEIF($W$6:$W$36, "x",AN6:AN36) -> -756.7931
B41: Consumption: | X41: PRV AVG
B42: =B39-B5 -> 1834 | C42: =C39-C5 -> 0 | D42: =D39-D5 -> 0 | E42: =E39-E5 -> 0 | F42: =F39-F5 -> 0 | G42: =G39-G5 -> 0 | I42: =I39-I5 -> 345 | J42: =J39-J5 -> 77 | K42: =K39-K5 -> 0 | L42: =L39-L5 -> 0 | N42: =N39-N5 -> 2704 | O42: =O39-O5 -> 0 | P42: =P39-P5 -> 0 | Q42: =Q39-Q5 -> 0 | T42: =T39-T5 -> 0 | U42: =U39-U5 -> 0 | V42: =V39-V5 -> 0 | Y42: =Jan!Y39 -> 78.903226 | Z42: =Jan!Z39 -> 0 | AA42: =Jan!AA39 -> 0 | AB42: =Jan!AB39 -> -31397.677 | AC42: =Jan!AC39 -> -2518.7097 | AD42: =Jan!AD39 -> -704.19355 | AF42: =Jan!AF39 -> 11.677419 | AG42: =Jan!AG39 -> 1.8064516 | AH42: =Jan!AH39 -> -812.93548 | AI42: =Jan!AI39 -> -3.6774194 | AK42: =Jan!AK39 -> 95.774194 | AL42: =Jan!AL39 -> -13284.032 | AM42: =Jan!AM39 -> -18857.484 | AN42: =Jan!AN39 -> -693.22581
X43: 1.5 | Y43: =Y42*$X$43 -> 118.35484 | Z43: =Z42*$X$43 -> 0 | AA43: =AA42*$X$43 -> 0 | AB43: =AB42*$X$43 -> -47096.516 | AC43: =AC42*$X$43 -> -3778.0645 | AD43: =AD42*$X$43 -> -1056.2903 | AF43: =AF42*$X$43 -> 17.516129 | AG43: =AG42*$X$43 -> 2.7096774 | AH43: =AH42*$X$43 -> -1219.4032 | AI43: =AI42*$X$43 -> -5.516129 | AK43: =AK42*$X$43 -> 143.66129 | AL43: =AL42*$X$43 -> -19926.048 | AM43: =AM42*$X$43 -> -28286.226 | AN43: =AN42*$X$43 -> -1039.8387
R44: AVG | X44: 0.5 | Y44: =Y42*$X$44 -> 39.451613 | Z44: =Z42*$X$44 -> 0 | AA44: =AA42*$X$44 -> 0 | AB44: =AB42*$X$44 -> -15698.839 | AC44: =AC42*$X$44 -> -1259.3548 | AD44: =AD42*$X$44 -> -352.09677 | AF44: =AF42*$X$44 -> 5.8387097 | AG44: =AG42*$X$44 -> 0.90322581 | AH44: =AH42*$X$44 -> -406.46774 | AI44: =AI42*$X$44 -> -1.8387097 | AK44: =AK42*$X$44 -> 47.887097 | AL44: =AL42*$X$44 -> -6642.0161 | AM44: 0 | AN44: 0
R45: =AVERAGE(R6:R36) -> -783.82143
Y46: Note 1 | Z46: Normal formating for cells where the daily average consumption is within range from the previous month's average range noted above.
Y47: Note 2 | Z47: Indicates the daily average for that day is outside the average range for that meter, based on the previous month's averages. Not necessarily a problem, just something to keeep an eye on.
X48: ! | Y48: Note 3 | Z48: This RED FLAG should be brought to Management for further review as to why it is more than twice the monthly average. Still can be explained, depending on the meter, but warrants immediate review to minimize impact to utilities and/or billing.
Y49: Note 4 | Z49: This is the same calculation as the RED FLAG, but is a known non-issue (example: Emergency Generator run once a week, plus bi-monthly inspections)
X50: ! | Y50: Note 5 | Z50: THIS IS AN ISSUE. METERS DO NOT RUN BACKWARDS, THUS NO NEGATIVE READINGS ALLOWED. Check for a simple typo or transposed number in the reading and/or verify the meter reading logged is correct by physically checking meter again.
R51: =AVERAGE(R6:R36) -> -783.82143

Sheet Mar
B1: Water | I1: Cooling Towers | N1: Gas | T1: Georgia Power | Y1: Water | AF1: Cooling Towers | AK1: Gas
B2: Meter | I2: Hotel Chillers | K2: Apartment Loop | N2: Meter | Q2: MEZ | T2: Electrical Vault at P1 | Y2: Meter | AF2: Hotel Chillers | AH2: Apartment Loop | AK2: Meter | AN2: MEZ
A3: Date | B3: Bldg Main Meter #1 (CCF) | C3: Meter #2 (CCF) | D3: Fire Main Meter #3 (CCF) | E3: Pump Rm. Gall * 100 | F3: Offices at Level 20 Gall * 100 | G3: Offices at Level 30 Gall * 100 | I3: Make Up Gall * 100 | J3: Blow Down | K3: Make Up Gall * 100 | L3: Blow Down | N3: Corrected CCF *10 | O3: Not Corrected | P3: Engine | Q3: Tower Htg CCF *10 | T3: KWH (*4800) | U3: KW | V3: KQH | X3: Date | Y3: Bldg Main Meter #1 (CCF) | Z3: Meter #2 (CCF) | AA3: Fire Main Meter #3 (CCF) | AB3: Pump Rm. Gall * 100 | AC3: Offices at Level 20 Gall * 100 | AD3: Offices at Level 30 Gall * 100 | AF3: Make Up Gall * 100 | AG3: Blow Down | AH3: Make Up Gall * 100 | AI3: Blow Down | AK3: Corrected CCF *10 | AL3: Not Corrected | AM3: Engine | AN3: Tower Htg CCF *10
A5: LR | B5: =Feb!B39 -> 645568 | C5: =Feb!C39 -> 0 | D5: =Feb!D39 -> 0 | E5: =Feb!E39 -> 973328 | F5: =Feb!F39 -> 78080 | G5: =Feb!G39 -> 21830 | I5: =Feb!I39 -> 19870 | J5: =Feb!J39 -> 1607 | K5: =Feb!K39 -> 25201 | L5: =Feb!L39 -> 114 | N5: =Feb!N39 -> 224503 | O5: =Feb!O39 -> 412436 | P5: =Feb!P39 -> 584676 | Q5: =Feb!Q39 -> 21947 | T5: =Feb!T39 -> 0 | U5: =Feb!U39 -> 0 | V5: =Feb!V39 -> 0
A6: 1 | B6: 645555 | I6: 19878 | J6: 1611 | N6: 224555 | R6: =Q6-Q5 -> -21947 | T6: 0 | U6: 0 | V6: 0 | W6: x | X6: 1 | Y6: =B6-B5 -> -13 | Z6: =C6-C5 -> 0 | AA6: =D6-D5 -> 0 | AB6: =E6-E5 -> -973328 | AC6: =F6-F5 -> -78080 | AD6: =G6-G5 -> -21830 | AF6: =I6-I5 -> 8 | AG6: =J6-J5 -> 4 | AH6: =K6-K5 -> -25201 | AI6: =L6-L5 -> -114 | AK6: =N6-N5 -> 52 | AL6: =O6-O5 -> -412436 | AM6: =P6-P5 -> -584676 | AN6: =Q6-Q5 -> -21947
A7: 2 | B7: 645622 | I7: 19903 | J7: 1616 | N7: 224651 | R7: =Q7-Q6 -> 0 | T7: 0 | U7: 0 | V7: 0 | W7: x | X7: 2 | Y7: =B7-B6 -> 67 | Z7: =C7-C6 -> 0 | AA7: =D7-D6 -> 0 | AB7: =E7-E6 -> 0 | AC7: =F7-F6 -> 0 | AD7: =G7-G6 -> 0 | AF7: =I7-I6 -> 25 | AG7: =J7-J6 -> 5 | AH7: =K7-K6 -> 0 | AI7: =L7-L6 -> 0 | AK7: =N7-N6 -> 96 | AL7: =O7-O6 -> 0 | AM7: =P7-P6 -> 0 | AN7: =Q7-Q6 -> 0
A8: 3 | B8: 645692 | I8: 19926 | J8: 1623 | N8: 224718 | R8: =Q8-Q7 -> 0 | T8: 0 | U8: 0 | V8: 0 | W8: x | X8: 3 | Y8: =B8-B7 -> 70 | Z8: =C8-C7 -> 0 | AA8: =D8-D7 -> 0 | AB8: =E8-E7 -> 0 | AC8: =F8-F7 -> 0 | AD8: =G8-G7 -> 0 | AF8: =I8-I7 -> 23 | AG8: =J8-J7 -> 7 | AH8: =K8-K7 -> 0 | AI8: =L8-L7 -> 0 | AK8: =N8-N7 -> 67 | AL8: =O8-O7 -> 0 | AM8: =P8-P7 -> 0 | AN8: =Q8-Q7 -> 0
A9: 4 | B9: 645699 | I9: 19949 | J9: 1623 | N9: 224792 | R9: =Q9-Q8 -> 0 | T9: 0 | U9: 0 | V9: 0 | W9: x | X9: 4 | Y9: =B9-B8 -> 7 | Z9: =C9-C8 -> 0 | AA9: =D9-D8 -> 0 | AB9: =E9-E8 -> 0 | AC9: =F9-F8 -> 0 | AD9: =G9-G8 -> 0 | AF9: =I9-I8 -> 23 | AG9: =J9-J8 -> 0 | AH9: =K9-K8 -> 0 | AI9: =L9-L8 -> 0 | AK9: =N9-N8 -> 74 | AL9: =O9-O8 -> 0 | AM9: =P9-P8 -> 0 | AN9: =Q9-Q8 -> 0
A10: 5 | B10: 645851 | I10: 19965 | J10: 1630 | N10: 224869 | R10: =Q10-Q9 -> 0 | T10: 0 | U10: 0 | V10: 0 | W10: x | X10: 5 | Y10: =B10-B9 -> 152 | Z10: =C10-C9 -> 0 | AA10: =D10-D9 -> 0 | AB10: =E10-E9 -> 0 | AC10: =F10-F9 -> 0 | AD10: =G10-G9 -> 0 | AF10: =I10-I9 -> 16 | AG10: =J10-J9 -> 7 | AH10: =K10-K9 -> 0 | AI10: =L10-L9 -> 0 | AK10: =N10-N9 -> 77 | AL10: =O10-O9 -> 0 | AM10: =P10-P9 -> 0 | AN10: =Q10-Q9 -> 0
