Workbook

Sheet TOTAL
A1: Site Name | B1: Day | C1: Month | D1: Year | E1: Total Electricity Kwh | F1: Electricity Tariff ($/Kwh) | G1: Total Fuel Oil (Liters) | H1: Fuel Oil $/Liter | I1: Water Utility Supply (m3) m3 | J1: Water Utility Supply (m3) $/m3 | K1: LPG (Kg) | L1: LPG $/Kg | M1: Room Nights | N1: Total Guests | O1: Food Covers
A2: Maldives at Kuda Huraa | B2: 1 | C2: 8 | D2: 2021 | E2: 21470 | F2: 0.14 | G2: 5872 | H2: 0.45 | I2: 320 | J2: 0.4 | M2: 20 | N2: 42 | O2: 125
A3: Maldives at Kuda Huraa | B3: =B2+1 -> 2 | C3: 8 | D3: 2021 | E3: 20730 | F3: 0.14 | G3: 5616 | H3: 0.45 | I3: 269 | J3: 0.4 | M3: 23 | N3: 49 | O3: 152
A4: Maldives at Kuda Huraa | B4: =B3+1 -> 3 | C4: 8 | D4: 2021 | E4: 22650 | F4: 0.14 | G4: 6176 | H4: 0.45 | I4: 435 | J4: 0.4 | M4: 29 | N4: 73 | O4: 192
A5: Maldives at Kuda Huraa | B5: =B4+1 -> 4 | C5: 8 | D5: 2021 | E5: 23440 | F5: 0.14 | G5: 6476 | H5: 0.45 | I5: 400 | J5: 0.4 | M5: 27 | N5: 71 | O5: 218
A6: Maldives at Kuda Huraa | B6: =B5+1 -> 5 | C6: 8 | D6: 2021 | E6: 16620 | F6: 0.14 | G6: 6218 | H6: 0.45 | I6: 371 | J6: 0.4 | M6: 34 | N6: 89 | O6: 226
A7: Maldives at Kuda Huraa | B7: =B6+1 -> 6 | C7: 8 | D7: 2021 | E7: 27350 | F7: 0.14 | G7: 5743 | H7: 0.45 | I7: 256 | J7: 0.4 | M7: 25 | N7: 78 | O7: 189
A8: Maldives at Kuda Huraa | B8: =B7+1 -> 7 | C8: 8 | D8: 2021 | E8: 23490 | F8: 0.14 | G8: 6796 | H8: 0.45 | I8: 366 | J8: 0.4
A9: Maldives at Kuda Huraa | B9: =B8+1 -> 8 | C9: 8 | D9: 2021 | F9: 0.14 | H9: 0.45 | J9: 0.4
A10: Maldives at Kuda Huraa | B10: =B9+1 -> 9 | C10: 8 | D10: 2021 | F10: 0.14 | H10: 0.45 | J10: 0.4
A11: Maldives at Kuda Huraa | B11: =B10+1 -> 10 | C11: 8 | D11: 2021 | F11: 0.14 | H11: 0.45 | J11: 0.4
A12: Maldives at Kuda Huraa | B12: =B11+1 -> 11 | C12: 8 | D12: 2021 | F12: 0.14 | H12: 0.45 | J12: 0.4
A13: Maldives at Kuda Huraa | B13: =B12+1 -> 12 | C13: 8 | D13: 2021 | F13: 0.14 | H13: 0.45 | J13: 0.4
A14: Maldives at Kuda Huraa | B14: =B13+1 -> 13 | C14: 8 | D14: 2021 | F14: 0.14 | H14: 0.45 | J14: 0.4
A15: Maldives at Kuda Huraa | B15: =B14+1 -> 14 | C15: 8 | D15: 2021 | F15: 0.14 | H15: 0.45 | J15: 0.4
A16: Maldives at Kuda Huraa | B16: =B15+1 -> 15 | C16: 8 | D16: 2021 | F16: 0.14 | H16: 0.45 | J16: 0.4
A17: Maldives at Kuda Huraa | B17: =B16+1 -> 16 | C17: 8 | D17: 2021 | F17: 0.14 | H17: 0.45 | J17: 0.4
A18: Maldives at Kuda Huraa | B18: =B17+1 -> 17 | C18: 8 | D18: 2021 | F18: 0.14 | H18: 0.45 | J18: 0.4
A19: Maldives at Kuda Huraa | B19: =B18+1 -> 18 | C19: 8 | D19: 2021 | F19: 0.14 | H19: 0.45 | J19: 0.4
A20: Maldives at Kuda Huraa | B20: =B19+1 -> 19 | C20: 8 | D20: 2021 | F20: 0.14 | H20: 0.45 | J20: 0.4
... A32: Maldives at Kuda Huraa | B32: =B31+1 -> 31 | C32: 8 | D32: 2021 | F32: 0.14 | H32: 0.45 | J32: 0.4
A33: Total | E33: =SUM(E2:E32) -> 155750 | F33: 0 | G33: =SUM(G2:G32) -> 42897 | H33: 0 | I33: =SUM(I2:I32) -> 2417 | J33: 0 | K33: 0 | L33: 0 | M33: =SUM(M2:M32) -> 158 | N33: =SUM(N2:N32) -> 402 | O33: =SUM(O2:O32) -> 1102

Sheet Kwh Reading
A1: Electric Consumption Record (4pm)
A2: Month | B2: BOH-1/ B&C Block MWH | C2: Pastry MWH | D2: Feeder 401-419 KWH | E2: Feeder 301-319 KWH | F2: Kitchen GWH | G2: Feeder 201-208 MWH | H2: Feeder 113-123 | I2: M - Block /PC MWH | J2: Laundry MWH | M2: Feeder 101-112 MWH | N2: Feeder 217-224 | O2: Spa MWH | P2: Feeder 124-134 | Q2: Feeder 209-216 | R2: STP -1 &2 MWH | S2: STP -3 MWH | T2: Reef Club MWH | V2: Room Nights | W2: Total Guests | X2: Food Covers
J3: A | K3: B | L3: C
A4: 44409 | B4: 1023.1 | C4: 237.01 | D4: 7554935.1 | E4: 8284704 | F4: 2.456 | G4: 771.87 | H4: 635.87 | I4: 246.18 | J4: 324.2 | K4: 349.56 | L4: 240.12 | M4: 542.35 | N4: 494.99 | O4: 158.49 | P4: 651.11 | Q4: 483.18 | R4: 166.73 | S4: 119.01 | T4: 434.94 | V4: 20 | W4: 42 | X4: 125
A5: 44410 | B5: 1024.5 | C5: 237.25 | D5: 7557399.6 | E5: 8287643.3 | F5: 2.4585 | G5: 772.79 | H5: 636.23 | I5: 246.53 | J5: 324.5 | K5: 349.9 | L5: 240.33 | M5: 543.1 | N5: 495.48 | O5: 158.7 | P5: 652.04 | Q5: 483.92 | R5: 166.94 | S5: 119.14 | T5: 435.39 | V5: 23 | W5: 49 | X5: 152
A6: 44411 | B6: 1025.9 | C6: 237.5 | D6: 7559464.7 | E6: 8290370 | F6: 2.4609 | G6: 773.67 | H6: 636.62 | I6: 246.85 | J6: 324.68 | K6: 350.14 | L6: 240.51 | M6: 543.77 | N6: 496.11 | O6: 158.95 | P6: 652.86 | Q6: 484.61 | R6: 167.13 | S6: 119.24 | T6: 435.85 | V6: 29 | W6: 73 | X6: 192
A7: 44412 | B7: 1027.4 | C7: 237.77 | D7: 7561611.1 | E7: 8293057.8 | F7: 2.4632 | G7: 774.59 | H7: 637.03 | I7: 247.17 | J7: 324.93 | K7: 350.37 | L7: 240.67 | M7: 544.42 | N7: 496.83 | O7: 159.15 | P7: 653.73 | Q7: 485.32 | R7: 167.31 | S7: 119.36 | T7: 436.34 | V7: 27 | W7: 71 | X7: 218
A8: 44413 | B8: 1028.9 | C8: 237.99 | D8: 7564005.7 | E8: 8295948.1 | F8: 2.4657 | G8: 775.52 | H8: 637.56 | I8: 247.5 | J8: 325.2 | K8: 350.65 | L8: 240.85 | M8: 545.11 | N8: 497.58 | O8: 159.4 | P8: 654.69 | Q8: 486.07 | R8: 167.48 | S8: 119.48 | T8: 436.86 | V8: 34 | W8: 89 | X8: 226
A9: 44414 | B9: 1030.3 | C9: 238.23 | D9: 7566321.6 | E9: 8298966.6 | F9: 2.4682 | G9: 776.47 | H9: 638.12 | I9: 247.83 | J9: 325.49 | K9: 350.93 | L9: 241.04 | M9: 545.8 | N9: 498.29 | O9: 159.66 | P9: 655.6 | Q9: 486.72 | R9: 167.68 | S9: 119.6 | T9: 437.37 | V9: 25 | W9: 78 | X9: 189
A10: 44415 | B10: 1031.5 | C10: 238.5 | D10: 7568583 | E10: 8302063.7 | F10: 2.4709 | G10: 777.34 | H10: 638.67 | I10: 248.16 | J10: 325.84 | K10: 351.25 | L10: 241.28 | M10: 546.44 | N10: 498.94 | O10: 159.96 | P10: 655.65 | Q10: 487.36 | R10: 167.87 | S10: 119.73 | T10: 437.63
A11: 44416 | B11: 1032.9 | C11: 238.72 | D11: 7571014.6 | E11: 8305701.1 | F11: 2.4734 | G11: 778.21 | H11: 639.25 | I11: 248.49 | J11: 326.08 | K11: 351.54 | L11: 241.48 | M11: 547.09 | N11: 499.7 | O11: 160.17 | P11: 657.81 | Q11: 488 | R11: 168.06 | S11: 119.85 | T11: 438.12
A12: 44417
A13: 44418
A14: 44419
A15: 44420
A16: 44421
A17: 44422
A18: 44423
A19: 44424
A20: 44425
A21: 44426
A22: 44427
A23: 44428
... A34: 44439
A35: 44440 | V35: =SUM(V4:V34) -> 158 | W35: =SUM(W4:W34) -> 402 | X35: =SUM(X4:X34) -> 1102
T42: ……..

Sheet Kwh Consumption
A2: Date | B2: Total KWH | C2: Reef Club KWH | D2: Kitchen KWH | E2: Pastry KWH | F2: Laundry KWH | I2: STP -1 &2 KWH | J2: STP -3 KWH | K2: M - Block /PC KWH | L2: B&C Block KWH | M2: Guest Room Beach Pavilion & Beach Bungalow KWH | S2: Guest Room Water Bungalow KWH | U2: Spa KWH | V2: Others KWH
F3: A | G3: B | H3: C | M3: Feeder -101-112 | N3: Feeder -113-123 | O3: Feeder -124-134 | P3: Feeder -201-208 | Q3: Feeder -209-216 | R3: Feeder -217-224 | S3: Feeder -301-319 | T3: Feeder 401-419
A4: ='Kwh Reading'!A4 -> 44409 | B4: 25520 | C4: =('Kwh Reading'!T5-'Kwh Reading'!T4)*1000 -> 450 | D4: =('Kwh Reading'!F5-'Kwh Reading'!F4)*1000000 -> 2500 | E4: =('Kwh Reading'!C5-'Kwh Reading'!C4)*1000 -> 240 | F4: =('Kwh Reading'!J5-'Kwh Reading'!J4)*1000 -> 300 | G4: =('Kwh Reading'!K5-'Kwh Reading'!K4)*1000 -> 340 | H4: =('Kwh Reading'!L5-'Kwh Reading'!L4)*1000 -> 210 | I4: =('Kwh Reading'!R5-'Kwh Reading'!R4)*1000 -> 210 | J4: =('Kwh Reading'!S5-'Kwh Reading'!S4)*1000 -> 130 | K4: =('Kwh Reading'!I5-'Kwh Reading'!I4)*1000 -> 350 | L4: =('Kwh Reading'!B5-'Kwh Reading'!B4)*1000 -> 1400 | M4: =('Kwh Reading'!M5-'Kwh Reading'!M4)*1000 -> 750 | N4: =('Kwh Reading'!H5-'Kwh Reading'!H4)*1000 -> 360 | O4: =('Kwh Reading'!P5-'Kwh Reading'!P4)*1000 -> 930 | P4: =('Kwh Reading'!G5-'Kwh Reading'!G4)*1000 -> 920 | Q4: =('Kwh Reading'!Q5-'Kwh Reading'!Q4)*1000 -> 740 | R4: =('Kwh Reading'!N5-'Kwh Reading'!N4)*1000 -> 490 | S4: ='Kwh Reading'!E5-'Kwh Reading'!E4 -> 2939.3 | T4: ='Kwh Reading'!D5-'Kwh Reading'!D4 -> 2464.53 | U4: =('Kwh Reading'!O5-'Kwh Reading'!O4)*1000 -> 210 | V4: =B4-(SUM(C4:U4)) -> 9586.17
A5: ='Kwh Reading'!A5 -> 44410 | B5: =TOTAL!E3 -> 20730 | C5: =('Kwh Reading'!T6-'Kwh Reading'!T5)*1000 -> 460 | D5: =('Kwh Reading'!F6-'Kwh Reading'!F5)*1000000 -> 2400 | E5: =('Kwh Reading'!C6-'Kwh Reading'!C5)*1000 -> 250 | F5: =('Kwh Reading'!J6-'Kwh Reading'!J5)*1000 -> 180 | G5: =('Kwh Reading'!K6-'Kwh Reading'!K5)*1000 -> 240 | H5: =('Kwh Reading'!L6-'Kwh Reading'!L5)*1000 -> 180 | I5: =('Kwh Reading'!R6-'Kwh Reading'!R5)*1000 -> 190 | J5: =('Kwh Reading'!S6-'Kwh Reading'!S5)*1000 -> 100 | K5: =('Kwh Reading'!I6-'Kwh Reading'!I5)*1000 -> 320 | L5: =('Kwh Reading'!B6-'Kwh Reading'!B5)*1000 -> 1400 | M5: =('Kwh Reading'!M6-'Kwh Reading'!M5)*1000 -> 670 | N5: =('Kwh Reading'!H6-'Kwh Reading'!H5)*1000 -> 390 | O5: =('Kwh Reading'!P6-'Kwh Reading'!P5)*1000 -> 820 | P5: =('Kwh Reading'!G6-'Kwh Reading'!G5)*1000 -> 880 | Q5: =('Kwh Reading'!Q6-'Kwh Reading'!Q5)*1000 -> 690 | R5: =('Kwh Reading'!N6-'Kwh Reading'!N5)*1000 -> 630 | S5: ='Kwh Reading'!E6-'Kwh Reading'!E5 -> 2726.65 | T5: ='Kwh Reading'!D6-'Kwh Reading'!D5 -> 2065.14 | U5: =('Kwh Reading'!O6-'Kwh Reading'!O5)*1000 -> 250 | V5: =B5-(SUM(C5:U5)) -> 5888.21
A6: ='Kwh Reading'!A6 -> 44411 | B6: =TOTAL!E4 -> 22650 | C6: =('Kwh Reading'!T7-'Kwh Reading'!T6)*1000 -> 490 | D6: =('Kwh Reading'!F7-'Kwh Reading'!F6)*1000000 -> 2300 | E6: =('Kwh Reading'!C7-'Kwh Reading'!C6)*1000 -> 270 | F6: =('Kwh Reading'!J7-'Kwh Reading'!J6)*1000 -> 250 | G6: =('Kwh Reading'!K7-'Kwh Reading'!K6)*1000 -> 230 | H6: =('Kwh Reading'!L7-'Kwh Reading'!L6)*1000 -> 160 | I6: =('Kwh Reading'!R7-'Kwh Reading'!R6)*1000 -> 180 | J6: =('Kwh Reading'!S7-'Kwh Reading'!S6)*1000 -> 120 | K6: =('Kwh Reading'!I7-'Kwh Reading'!I6)*1000 -> 320 | L6: =('Kwh Reading'!B7-'Kwh Reading'!B6)*1000 -> 1500 | M6: =('Kwh Reading'!M7-'Kwh Reading'!M6)*1000 -> 650 | N6: =('Kwh Reading'!H7-'Kwh Reading'!H6)*1000 -> 410 | O6: =('Kwh Reading'!P7-'Kwh Reading'!P6)*1000 -> 870 | P6: =('Kwh Reading'!G7-'Kwh Reading'!G6)*1000 -> 920 | Q6: =('Kwh Reading'!Q7-'Kwh Reading'!Q6)*1000 -> 710 | R6: =('Kwh Reading'!N7-'Kwh Reading'!N6)*1000 -> 720 | S6: ='Kwh Reading'!E7-'Kwh Reading'!E6 -> 2687.8 | T6: ='Kwh Reading'!D7-'Kwh Reading'!D6 -> 2146.37 | U6: =('Kwh Reading'!O7-'Kwh Reading'!O6)*1000 -> 200 | V6: =B6-(SUM(C6:U6)) -> 7515.83
A7: ='Kwh Reading'!A7 -> 44412 | B7: =TOTAL!E5 -> 23440 | C7: =('Kwh Reading'!T8-'Kwh Reading'!T7)*1000 -> 520 | D7: =('Kwh Reading'!F8-'Kwh Reading'!F7)*1000000 -> 2500 | E7: =('Kwh Reading'!C8-'Kwh Reading'!C7)*1000 -> 220 | F7: =('Kwh Reading'!J8-'Kwh Reading'!J7)*1000 -> 270 | G7: =('Kwh Reading'!K8-'Kwh Reading'!K7)*1000 -> 280 | H7: =('Kwh Reading'!L8-'Kwh Reading'!L7)*1000 -> 180 | I7: =('Kwh Reading'!R8-'Kwh Reading'!R7)*1000 -> 170 | J7: =('Kwh Reading'!S8-'Kwh Reading'!S7)*1000 -> 120 | K7: =('Kwh Reading'!I8-'Kwh Reading'!I7)*1000 -> 330 | L7: =('Kwh Reading'!B8-'Kwh Reading'!B7)*1000 -> 1500 | M7: =('Kwh Reading'!M8-'Kwh Reading'!M7)*1000 -> 690 | N7: =('Kwh Reading'!H8-'Kwh Reading'!H7)*1000 -> 530 | O7: =('Kwh Reading'!P8-'Kwh Reading'!P7)*1000 -> 960 | P7: =('Kwh Reading'!G8-'Kwh Reading'!G7)*1000 -> 930 | Q7: =('Kwh Reading'!Q8-'Kwh Reading'!Q7)*1000 -> 750 | R7: =('Kwh Reading'!N8-'Kwh Reading'!N7)*1000 -> 750 | S7: ='Kwh Reading'!E8-'Kwh Reading'!E7 -> 2890.34 | T7: ='Kwh Reading'!D8-'Kwh Reading'!D7 -> 2394.58 | U7: =('Kwh Reading'!O8-'Kwh Reading'!O7)*1000 -> 250 | V7: =B7-(SUM(C7:U7)) -> 7205.08
A8: ='Kwh Reading'!A8 -> 44413 | B8: =TOTAL!E6 -> 16620 | C8: =('Kwh Reading'!T9-'Kwh Reading'!T8)*1000 -> 510 | D8: =('Kwh Reading'!F9-'Kwh Reading'!F8)*1000000 -> 2500 | E8: =('Kwh Reading'!C9-'Kwh Reading'!C8)*1000 -> 240 | F8: =('Kwh Reading'!J9-'Kwh Reading'!J8)*1000 -> 290 | G8: =('Kwh Reading'!K9-'Kwh Reading'!K8)*1000 -> 280 | H8: =('Kwh Reading'!L9-'Kwh Reading'!L8)*1000 -> 190 | I8: =('Kwh Reading'!R9-'Kwh Reading'!R8)*1000 -> 200 | J8: =('Kwh Reading'!S9-'Kwh Reading'!S8)*1000 -> 120 | K8: =('Kwh Reading'!I9-'Kwh Reading'!I8)*1000 -> 330 | L8: =('Kwh Reading'!B9-'Kwh Reading'!B8)*1000 -> 1400 | M8: =('Kwh Reading'!M9-'Kwh Reading'!M8)*1000 -> 690 | N8: =('Kwh Reading'!H9-'Kwh Reading'!H8)*1000 -> 560 | O8: =('Kwh Reading'!P9-'Kwh Reading'!P8)*1000 -> 910 | P8: =('Kwh Reading'!G9-'Kwh Reading'!G8)*1000 -> 950 | Q8: =('Kwh Reading'!Q9-'Kwh Reading'!Q8)*1000 -> 650 | R8: =('Kwh Reading'!N9-'Kwh Reading'!N8)*1000 -> 710 | S8: ='Kwh Reading'!E9-'Kwh Reading'!E8 -> 3018.47 | T8: ='Kwh Reading'!D9-'Kwh Reading'!D8 -> 2315.92 | U8: =('Kwh Reading'!O9-'Kwh Reading'!O8)*1000 -> 260 | V8: =B8-(SUM(C8:U8)) -> 495.61
A9: ='Kwh Reading'!A9 -> 44414 | B9: =TOTAL!E7 -> 27350 | C9: =('Kwh Reading'!T10-'Kwh Reading'!T9)*1000 -> 260 | D9: =('Kwh Reading'!F10-'Kwh Reading'!F9)*1000000 -> 2700 | E9: =('Kwh Reading'!C10-'Kwh Reading'!C9)*1000 -> 270 | F9: =('Kwh Reading'!J10-'Kwh Reading'!J9)*1000 -> 350 | G9: =('Kwh Reading'!K10-'Kwh Reading'!K9)*1000 -> 320 | H9: =('Kwh Reading'!L10-'Kwh Reading'!L9)*1000 -> 240 | I9: =('Kwh Reading'!R10-'Kwh Reading'!R9)*1000 -> 190 | J9: =('Kwh Reading'!S10-'Kwh Reading'!S9)*1000 -> 130 | K9: =('Kwh Reading'!I10-'Kwh Reading'!I9)*1000 -> 330 | L9: =('Kwh Reading'!B10-'Kwh Reading'!B9)*1000 -> 1200 | M9: =('Kwh Reading'!M10-'Kwh Reading'!M9)*1000 -> 640 | N9: =('Kwh Reading'!H10-'Kwh Reading'!H9)*1000 -> 550 | O9: =('Kwh Reading'!P10-'Kwh Reading'!P9)*1000 -> 50 | P9: =('Kwh Reading'!G10-'Kwh Reading'!G9)*1000 -> 870 | Q9: =('Kwh Reading'!Q10-'Kwh Reading'!Q9)*1000 -> 640 | R9: =('Kwh Reading'!N10-'Kwh Reading'!N9)*1000 -> 650 | S9: ='Kwh Reading'!E10-'Kwh Reading'!E9 -> 3097.08 | T9: ='Kwh Reading'!D10-'Kwh Reading'!D9 -> 2261.39 | U9: =('Kwh Reading'!O10-'Kwh Reading'!O9)*1000 -> 300 | V9: =B9-(SUM(C9:U9)) -> 12301.53
A10: ='Kwh Reading'!A10 -> 44415 | B10: =TOTAL!E8 -> 23490 | C10: =('Kwh Reading'!T11-'Kwh Reading'!T10)*1000 -> 490 | D10: =('Kwh Reading'!F11-'Kwh Reading'!F10)*1000000 -> 2500 | E10: =('Kwh Reading'!C11-'Kwh Reading'!C10)*1000 -> 220 | F10: =('Kwh Reading'!J11-'Kwh Reading'!J10)*1000 -> 240 | G10: =('Kwh Reading'!K11-'Kwh Reading'!K10)*1000 -> 290 | H10: =('Kwh Reading'!L11-'Kwh Reading'!L10)*1000 -> 200 | I10: =('Kwh Reading'!R11-'Kwh Reading'!R10)*1000 -> 190 | J10: =('Kwh Reading'!S11-'Kwh Reading'!S10)*1000 -> 120 | K10: =('Kwh Reading'!I11-'Kwh Reading'!I10)*1000 -> 330 | L10: =('Kwh Reading'!B11-'Kwh Reading'!B10)*1000 -> 1400 | M10: =('Kwh Reading'!M11-'Kwh Reading'!M10)*1000 -> 650 | N10: =('Kwh Reading'!H11-'Kwh Reading'!H10)*1000 -> 580 | O10: =('Kwh Reading'!P11-'Kwh Reading'!P10)*1000 -> 2160 | P10: =('Kwh Reading'!G11-'Kwh Reading'!G10)*1000 -> 870 | Q10: =('Kwh Reading'!Q11-'Kwh Reading'!Q10)*1000 -> 640 | R10: =('Kwh Reading'!N11-'Kwh Reading'!N10)*1000 -> 760 | S10: ='Kwh Reading'!E11-'Kwh Reading'!E10 -> 3637.39 | T10: ='Kwh Reading'!D11-'Kwh Reading'!D10 -> 2431.61 | U10: =('Kwh Reading'!O11-'Kwh Reading'!O10)*1000 -> 210 | V10: =B10-(SUM(C10:U10)) -> 5571
A11: ='Kwh Reading'!A11 -> 44416 | B11: =TOTAL!E9 -> 0 | C11: =('Kwh Reading'!T12-'Kwh Reading'!T11)*1000 -> -438120 | D11: =('Kwh Reading'!F12-'Kwh Reading'!F11)*1000000 -> -2473400 | E11: =('Kwh Reading'!C12-'Kwh Reading'!C11)*1000 -> -238720 | F11: =('Kwh Reading'!J12-'Kwh Reading'!J11)*1000 -> -326080 | G11: =('Kwh Reading'!K12-'Kwh Reading'!K11)*1000 -> -351540 | H11: =('Kwh Reading'!L12-'Kwh Reading'!L11)*1000 -> -241480 | I11: =('Kwh Reading'!R12-'Kwh Reading'!R11)*1000 -> -168060 | J11: =('Kwh Reading'!S12-'Kwh Reading'!S11)*1000 -> -119850 | K11: =('Kwh Reading'!I12-'Kwh Reading'!I11)*1000 -> -248490 | L11: =('Kwh Reading'!B12-'Kwh Reading'!B11)*1000 -> -1032900 | M11: =('Kwh Reading'!M12-'Kwh Reading'!M11)*1000 -> -547090 | N11: =('Kwh Reading'!H12-'Kwh Reading'!H11)*1000 -> -639250 | O11: =('Kwh Reading'!P12-'Kwh Reading'!P11)*1000 -> -657810 | P11: =('Kwh Reading'!G12-'Kwh Reading'!G11)*1000 -> -778210 | Q11: =('Kwh Reading'!Q12-'Kwh Reading'!Q11)*1000 -> -488000 | R11: =('Kwh Reading'!N12-'Kwh Reading'!N11)*1000 -> -499700 | S11: ='Kwh Reading'!E12-'Kwh Reading'!E11 -> -8305701.1 | T11: ='Kwh Reading'!D12-'Kwh Reading'!D11 -> -7571014.6 | U11: =('Kwh Reading'!O12-'Kwh Reading'!O11)*1000 -> -160170 | V11: =B11-(SUM(C11:U11)) -> 25285586
A12: ='Kwh Reading'!A12 -> 44417 | B12: =TOTAL!E10 -> 0 | C12: =('Kwh Reading'!T13-'Kwh Reading'!T12)*1000 -> 0 | D12: =('Kwh Reading'!F13-'Kwh Reading'!F12)*1000000 -> 0 | E12: =('Kwh Reading'!C13-'Kwh Reading'!C12)*1000 -> 0 | F12: =('Kwh Reading'!J13-'Kwh Reading'!J12)*1000 -> 0 | G12: =('Kwh Reading'!K13-'Kwh Reading'!K12)*1000 -> 0 | H12: =('Kwh Reading'!L13-'Kwh Reading'!L12)*1000 -> 0 | I12: =('Kwh Reading'!R13-'Kwh Reading'!R12)*1000 -> 0 | J12: =('Kwh Reading'!S13-'Kwh Reading'!S12)*1000 -> 0 | K12: =('Kwh Reading'!I13-'Kwh Reading'!I12)*1000 -> 0 | L12: =('Kwh Reading'!B13-'Kwh Reading'!B12)*1000 -> 0 | M12: =('Kwh Reading'!M13-'Kwh Reading'!M12)*1000 -> 0 | N12: =('Kwh Reading'!H13-'Kwh Reading'!H12)*1000 -> 0 | O12: =('Kwh Reading'!P13-'Kwh Reading'!P12)*1000 -> 0 | P12: =('Kwh Reading'!G13-'Kwh Reading'!G12)*1000 -> 0 | Q12: =('Kwh Reading'!Q13-'Kwh Reading'!Q12)*1000 -> 0 | R12: =('Kwh Reading'!N13-'Kwh Reading'!N12)*1000 -> 0 | S12: ='Kwh Reading'!E13-'Kwh Reading'!E12 -> 0 | T12: ='Kwh Reading'!D13-'Kwh Reading'!D12 -> 0 | U12: =('Kwh Reading'!O13-'Kwh Reading'!O12)*1000 -> 0 | V12: =B12-(SUM(C12:U12)) -> 0
A13: ='Kwh Reading'!A13 -> 44418 | B13: =TOTAL!E11 -> 0 | C13: =('Kwh Reading'!T14-'Kwh Reading'!T13)*1000 -> 0 | D13: =('Kwh Reading'!F14-'Kwh Reading'!F13)*1000000 -> 0 | E13: =('Kwh Reading'!C14-'Kwh Reading'!C13)*1000 -> 0 | F13: =('Kwh Reading'!J14-'Kwh Reading'!J13)*1000 -> 0 | G13: =('Kwh Reading'!K14-'Kwh Reading'!K13)*1000 -> 0 | H13: =('Kwh Reading'!L14-'Kwh Reading'!L13)*1000 -> 0 | I13: =('Kwh Reading'!R14-'Kwh Reading'!R13)*1000 -> 0 | J13: =('Kwh Reading'!S14-'Kwh Reading'!S13)*1000 -> 0 | K13: =('Kwh Reading'!I14-'Kwh Reading'!I13)*1000 -> 0 | L13: =('Kwh Reading'!B14-'Kwh Reading'!B13)*1000 -> 0 | M13: =('Kwh Reading'!M14-'Kwh Reading'!M13)*1000 -> 0 | N13: =('Kwh Reading'!H14-'Kwh Reading'!H13)*1000 -> 0 | O13: =('Kwh Reading'!P14-'Kwh Reading'!P13)*1000 -> 0 | P13: =('Kwh Reading'!G14-'Kwh Reading'!G13)*1000 -> 0 | Q13: =('Kwh Reading'!Q14-'Kwh Reading'!Q13)*1000 -> 0 | R13: =('Kwh Reading'!N14-'Kwh Reading'!N13)*1000 -> 0 | S13: ='Kwh Reading'!E14-'Kwh Reading'!E13 -> 0 | T13: ='Kwh Reading'!D14-'Kwh Reading'!D13 -> 0 | U13: =('Kwh Reading'!O14-'Kwh Reading'!O13)*1000 -> 0 | V13: =B13-(SUM(C13:U13)) -> 0
A14: ='Kwh Reading'!A14 -> 44419 | B14: =TOTAL!E12 -> 0 | C14: =('Kwh Reading'!T15-'Kwh Reading'!T14)*1000 -> 0 | D14: =('Kwh Reading'!F15-'Kwh Reading'!F14)*1000000 -> 0 | E14: =('Kwh Reading'!C15-'Kwh Reading'!C14)*1000 -> 0 | F14: =('Kwh Reading'!J15-'Kwh Reading'!J14)*1000 -> 0 | G14: =('Kwh Reading'!K15-'Kwh Reading'!K14)*1000 -> 0 | H14: =('Kwh Reading'!L15-'Kwh Reading'!L14)*1000 -> 0 | I14: =('Kwh Reading'!R15-'Kwh Reading'!R14)*1000 -> 0 | J14: =('Kwh Reading'!S15-'Kwh Reading'!S14)*1000 -> 0 | K14: =('Kwh Reading'!I15-'Kwh Reading'!I14)*1000 -> 0 | L14: =('Kwh Reading'!B15-'Kwh Reading'!B14)*1000 -> 0 | M14: =('Kwh Reading'!M15-'Kwh Reading'!M14)*1000 -> 0 | N14: =('Kwh Reading'!H15-'Kwh Reading'!H14)*1000 -> 0 | O14: =('Kwh Reading'!P15-'Kwh Reading'!P14)*1000 -> 0 | P14: =('Kwh Reading'!G15-'Kwh Reading'!G14)*1000 -> 0 | Q14: =('Kwh Reading'!Q15-'Kwh Reading'!Q14)*1000 -> 0 | R14: =('Kwh Reading'!N15-'Kwh Reading'!N14)*1000 -> 0 | S14: ='Kwh Reading'!E15-'Kwh Reading'!E14 -> 0 | T14: ='Kwh Reading'!D15-'Kwh Reading'!D14 -> 0 | U14: =('Kwh Reading'!O15-'Kwh Reading'!O14)*1000 -> 0 | V14: =B14-(SUM(C14:U14)) -> 0
A15: ='Kwh Reading'!A15 -> 44420 | B15: =TOTAL!E13 -> 0 | C15: =('Kwh Reading'!T16-'Kwh Reading'!T15)*1000 -> 0 | D15: =('Kwh Reading'!F16-'Kwh Reading'!F15)*1000000 -> 0 | E15: =('Kwh Reading'!C16-'Kwh Reading'!C15)*1000 -> 0 | F15: =('Kwh Reading'!J16-'Kwh Reading'!J15)*1000 -> 0 | G15: =('Kwh Reading'!K16-'Kwh Reading'!K15)*1000 -> 0 | H15: =('Kwh Reading'!L16-'Kwh Reading'!L15)*1000 -> 0 | I15: =('Kwh Reading'!R16-'Kwh Reading'!R15)*1000 -> 0 | J15: =('Kwh Reading'!S16-'Kwh Reading'!S15)*1000 -> 0 | K15: =('Kwh Reading'!I16-'Kwh Reading'!I15)*1000 -> 0 | L15: =('Kwh Reading'!B16-'Kwh Reading'!B15)*1000 -> 0 | M15: =('Kwh Reading'!M16-'Kwh Reading'!M15)*1000 -> 0 | N15: =('Kwh Reading'!H16-'Kwh Reading'!H15)*1000 -> 0 | O15: =('Kwh Reading'!P16-'Kwh Reading'!P15)*1000 -> 0 | P15: =('Kwh Reading'!G16-'Kwh Reading'!G15)*1000 -> 0 | Q15: =('Kwh Reading'!Q16-'Kwh Reading'!Q15)*1000 -> 0 | R15: =('Kwh Reading'!N16-'Kwh Reading'!N15)*1000 -> 0 | S15: ='Kwh Reading'!E16-'Kwh Reading'!E15 -> 0 | T15: ='Kwh Reading'!D16-'Kwh Reading'!D15 -> 0 | U15: =('Kwh Reading'!O16-'Kwh Reading'!O15)*1000 -> 0 | V15: =B15-(SUM(C15:U15)) -> 0
A16: ='Kwh Reading'!A16 -> 44421 | B16: =TOTAL!E14 -> 0 | C16: =('Kwh Reading'!T17-'Kwh Reading'!T16)*1000 -> 0 | D16: =('Kwh Reading'!F17-'Kwh Reading'!F16)*1000000 -> 0 | E16: =('Kwh Reading'!C17-'Kwh Reading'!C16)*1000 -> 0 | F16: =('Kwh Reading'!J17-'Kwh Reading'!J16)*1000 -> 0 | G16: =('Kwh Reading'!K17-'Kwh Reading'!K16)*1000 -> 0 | H16: =('Kwh Reading'!L17-'Kwh Reading'!L16)*1000 -> 0 | I16: =('Kwh Reading'!R17-'Kwh Reading'!R16)*1000 -> 0 | J16: =('Kwh Reading'!S17-'Kwh Reading'!S16)*1000 -> 0 | K16: =('Kwh Reading'!I17-'Kwh Reading'!I16)*1000 -> 0 | L16: =('Kwh Reading'!B17-'Kwh Reading'!B16)*1000 -> 0 | M16: =('Kwh Reading'!M17-'Kwh Reading'!M16)*1000 -> 0 | N16: =('Kwh Reading'!H17-'Kwh Reading'!H16)*1000 -> 0 | O16: =('Kwh Reading'!P17-'Kwh Reading'!P16)*1000 -> 0 | P16: =('Kwh Reading'!G17-'Kwh Reading'!G16)*1000 -> 0 | Q16: =('Kwh Reading'!Q17-'Kwh Reading'!Q16)*1000 -> 0 | R16: =('Kwh Reading'!N17-'Kwh Reading'!N16)*1000 -> 0 | S16: ='Kwh Reading'!E17-'Kwh Reading'!E16 -> 0 | T16: ='Kwh Reading'!D17-'Kwh Reading'!D16 -> 0 | U16: =('Kwh Reading'!O17-'Kwh Reading'!O16)*1000 -> 0 | V16: =B16-(SUM(C16:U16)) -> 0
... A34: ='Kwh Reading'!A34 -> 44439 | B34: =TOTAL!E32 -> 0 | C34: =('Kwh Reading'!T35-'Kwh Reading'!T34)*1000 -> 0 | D34: =('Kwh Reading'!F35-'Kwh Reading'!F34)*1000000 -> 0 | E34: =('Kwh Reading'!C35-'Kwh Reading'!C34)*1000 -> 0 | F34: =('Kwh Reading'!J35-'Kwh Reading'!J34)*1000 -> 0 | G34: =('Kwh Reading'!K35-'Kwh Reading'!K34)*1000 -> 0 | H34: =('Kwh Reading'!L35-'Kwh Reading'!L34)*1000 -> 0 | I34: =('Kwh Reading'!R35-'Kwh Reading'!R34)*1000 -> 0 | J34: =('Kwh Reading'!S35-'Kwh Reading'!S34)*1000 -> 0 | K34: =('Kwh Reading'!I35-'Kwh Reading'!I34)*1000 -> 0 | L34: =('Kwh Reading'!B35-'Kwh Reading'!B34)*1000 -> 0 | M34: =('Kwh Reading'!M35-'Kwh Reading'!M34)*1000 -> 0 | N34: =('Kwh Reading'!H35-'Kwh Reading'!H34)*1000 -> 0 | O34: =('Kwh Reading'!P35-'Kwh Reading'!P34)*1000 -> 0 | P34: =('Kwh Reading'!G35-'Kwh Reading'!G34)*1000 -> 0 | Q34: =('Kwh Reading'!Q35-'Kwh Reading'!Q34)*1000 -> 0 | R34: =('Kwh Reading'!N35-'Kwh Reading'!N34)*1000 -> 0 | S34: ='Kwh Reading'!E35-'Kwh Reading'!E34 -> 0 | T34: ='Kwh Reading'!D35-'Kwh Reading'!D34 -> 0 | U34: =('Kwh Reading'!O35-'Kwh Reading'!O34)*1000 -> 0 | V34: =B34-(SUM(C34:U34)) -> 0
A35: Total | B35: =SUM(B4:B34) -> 159800 | C35: =SUM(C4:C34) -> -434940 | D35: =SUM(D4:D34) -> -2456000 | E35: =SUM(E4:E34) -> -237010 | F35: =SUM(F4:F34) -> -324200 | G35: =SUM(G4:G34) -> -349560 | H35: =SUM(H4:H34) -> -240120 | I35: =SUM(I4:I34) -> -166730 | ... V35: =SUM(V4:V34) -> 25334149

Sheet Kwh area wise 
A2: Month | B2: Total KWH | C2: Reef Club Kitchen KWH | D2: Main Kitchen KWH | E2: Pastry Kitchen KWH | F2: Laundry KWH | G2: STP KWH | H2: Kuda Huraa Accomodation KWH | I2: Guest Room Beach Pavilion & Beach Bungalow KWH | J2: Guest Room Water Bungalow KWH | K2: Spa KWH | L2: Others KWH
A3: ='Kwh Reading'!A4 -> 44409 | B3: =TOTAL!E2 -> 21470 | C3: ='Kwh Consumption'!C4 -> 450 | D3: ='Kwh Consumption'!D4 -> 2500 | E3: ='Kwh Consumption'!E4 -> 240 | F3: =('Kwh Consumption'!F4+'Kwh Consumption'!G4+'Kwh Consumption'!H4) -> 850 | G3: =('Kwh Consumption'!I4+'Kwh Consumption'!J4) -> 340 | H3: =('Kwh Consumption'!K4+'Kwh Consumption'!L4) -> 1750 | I3: =('Kwh Consumption'!M4+'Kwh Consumption'!N4+'Kwh Consumption'!O4+'Kwh Consumption'!P4+'Kwh Consumption'!Q4+'Kwh Consumption'!R4) -> 4190 | J3: =('Kwh Consumption'!S4+'Kwh Consumption'!T4) -> 5403.83 | K3: ='Kwh Consumption'!U4 -> 210 | L3: =B3-C3-D3-E3-F3-G3-H3-I3-J3-K3 -> 5536.17
A4: ='Kwh Reading'!A5 -> 44410 | B4: =TOTAL!E3 -> 20730 | C4: ='Kwh Consumption'!C5 -> 460 | D4: ='Kwh Consumption'!D5 -> 2400 | E4: ='Kwh Consumption'!E5 -> 250 | F4: =('Kwh Consumption'!F5+'Kwh Consumption'!G5+'Kwh Consumption'!H5) -> 600 | G4: =('Kwh Consumption'!I5+'Kwh Consumption'!J5) -> 290 | H4: =('Kwh Consumption'!K5+'Kwh Consumption'!L5) -> 1720 | I4: =('Kwh Consumption'!M5+'Kwh Consumption'!N5+'Kwh Consumption'!O5+'Kwh Consumption'!P5+'Kwh Consumption'!Q5+'Kwh Consumption'!R5) -> 4080 | J4: =('Kwh Consumption'!S5+'Kwh Consumption'!T5) -> 4791.79 | K4: ='Kwh Consumption'!U5 -> 250 | L4: =B4-C4-D4-E4-F4-G4-H4-I4-J4-K4 -> 5888.21
A5: ='Kwh Reading'!A6 -> 44411 | B5: =TOTAL!E4 -> 22650 | C5: ='Kwh Consumption'!C6 -> 490 | D5: ='Kwh Consumption'!D6 -> 2300 | E5: ='Kwh Consumption'!E6 -> 270 | F5: =('Kwh Consumption'!F6+'Kwh Consumption'!G6+'Kwh Consumption'!H6) -> 640 | G5: =('Kwh Consumption'!I6+'Kwh Consumption'!J6) -> 300 | H5: =('Kwh Consumption'!K6+'Kwh Consumption'!L6) -> 1820 | I5: =('Kwh Consumption'!M6+'Kwh Consumption'!N6+'Kwh Consumption'!O6+'Kwh Consumption'!P6+'Kwh Consumption'!Q6+'Kwh Consumption'!R6) -> 4280 | J5: =('Kwh Consumption'!S6+'Kwh Consumption'!T6) -> 4834.17 | K5: ='Kwh Consumption'!U6 -> 200 | L5: =B5-C5-D5-E5-F5-G5-H5-I5-J5-K5 -> 7515.83
A6: ='Kwh Reading'!A7 -> 44412 | B6: =TOTAL!E5 -> 23440 | C6: ='Kwh Consumption'!C7 -> 520 | D6: ='Kwh Consumption'!D7 -> 2500 | E6: ='Kwh Consumption'!E7 -> 220 | F6: =('Kwh Consumption'!F7+'Kwh Consumption'!G7+'Kwh Consumption'!H7) -> 730 | G6: =('Kwh Consumption'!I7+'Kwh Consumption'!J7) -> 290 | H6: =('Kwh Consumption'!K7+'Kwh Consumption'!L7) -> 1830 | I6: =('Kwh Consumption'!M7+'Kwh Consumption'!N7+'Kwh Consumption'!O7+'Kwh Consumption'!P7+'Kwh Consumption'!Q7+'Kwh Consumption'!R7) -> 4610 | J6: =('Kwh Consumption'!S7+'Kwh Consumption'!T7) -> 5284.92 | K6: ='Kwh Consumption'!U7 -> 250 | L6: =B6-C6-D6-E6-F6-G6-H6-I6-J6-K6 -> 7205.08
A7: ='Kwh Reading'!A8 -> 44413 | B7: =TOTAL!E6 -> 16620 | C7: ='Kwh Consumption'!C8 -> 510 | D7: ='Kwh Consumption'!D8 -> 2500 | E7: ='Kwh Consumption'!E8 -> 240 | F7: =('Kwh Consumption'!F8+'Kwh Consumption'!G8+'Kwh Consumption'!H8) -> 760 | G7: =('Kwh Consumption'!I8+'Kwh Consumption'!J8) -> 320 | H7: =('Kwh Consumption'!K8+'Kwh Consumption'!L8) -> 1730 | I7: =('Kwh Consumption'!M8+'Kwh Consumption'!N8+'Kwh Consumption'!O8+'Kwh Consumption'!P8+'Kwh Consumption'!Q8+'Kwh Consumption'!R8) -> 4470 | J7: =('Kwh Consumption'!S8+'Kwh Consumption'!T8) -> 5334.39 | K7: ='Kwh Consumption'!U8 -> 260 | L7: =B7-C7-D7-E7-F7-G7-H7-I7-J7-K7 -> 495.61
A8: ='Kwh Reading'!A9 -> 44414 | B8: =TOTAL!E7 -> 27350 | C8: ='Kwh Consumption'!C9 -> 260 | D8: ='Kwh Consumption'!D9 -> 2700 | E8: ='Kwh Consumption'!E9 -> 270 | F8: =('Kwh Consumption'!F9+'Kwh Consumption'!G9+'Kwh Consumption'!H9) -> 910 | G8: =('Kwh Consumption'!I9+'Kwh Consumption'!J9) -> 320 | H8: =('Kwh Consumption'!K9+'Kwh Consumption'!L9) -> 1530 | I8: =('Kwh Consumption'!M9+'Kwh Consumption'!N9+'Kwh Consumption'!O9+'Kwh Consumption'!P9+'Kwh Consumption'!Q9+'Kwh Consumption'!R9) -> 3400 | J8: =('Kwh Consumption'!S9+'Kwh Consumption'!T9) -> 5358.47 | K8: ='Kwh Consumption'!U9 -> 300 | L8: =B8-C8-D8-E8-F8-G8-H8-I8-J8-K8 -> 12301.53
A9: ='Kwh Reading'!A10 -> 44415 | B9: =TOTAL!E8 -> 23490 | C9: ='Kwh Consumption'!C10 -> 490 | D9: ='Kwh Consumption'!D10 -> 2500 | E9: ='Kwh Consumption'!E10 -> 220 | F9: =('Kwh Consumption'!F10+'Kwh Consumption'!G10+'Kwh Consumption'!H10) -> 730 | G9: =('Kwh Consumption'!I10+'Kwh Consumption'!J10) -> 310 | H9: =('Kwh Consumption'!K10+'Kwh Consumption'!L10) -> 1730 | I9: =('Kwh Consumption'!M10+'Kwh Consumption'!N10+'Kwh Consumption'!O10+'Kwh Consumption'!P10+'Kwh Consumption'!Q10+'Kwh Consumption'!R10) -> 5660 | J9: =('Kwh Consumption'!S10+'Kwh Consumption'!T10) -> 6069 | K9: ='Kwh Consumption'!U10 -> 210 | L9: =B9-C9-D9-E9-F9-G9-H9-I9-J9-K9 -> 5571
A10: ='Kwh Reading'!A11 -> 44416 | B10: =TOTAL!E9 -> 0 | C10: ='Kwh Consumption'!C11 -> -438120 | D10: ='Kwh Consumption'!D11 -> -2473400 | E10: ='Kwh Consumption'!E11 -> -238720 | F10: =('Kwh Consumption'!F11+'Kwh Consumption'!G11+'Kwh Consumption'!H11) -> -919100 | G10: =('Kwh Consumption'!I11+'Kwh Consumption'!J11) -> -287910 | H10: =('Kwh Consumption'!K11+'Kwh Consumption'!L11) -> -1281390 | I10: =('Kwh Consumption'!M11+'Kwh Consumption'!N11+'Kwh Consumption'!O11+'Kwh Consumption'!P11+'Kwh Consumption'!Q11+'Kwh Consumption'!R11) -> -3610060 | J10: =('Kwh Consumption'!S11+'Kwh Consumption'!T11) -> -15876716 | K10: ='Kwh Consumption'!U11 -> -160170 | L10: =B10-C10-D10-E10-F10-G10-H10-I10-J10-K10 -> 25285586
A11: ='Kwh Reading'!A12 -> 44417 | B11: =TOTAL!E10 -> 0 | C11: ='Kwh Consumption'!C12 -> 0 | D11: ='Kwh Consumption'!D12 -> 0 | E11: ='Kwh Consumption'!E12 -> 0 | F11: =('Kwh Consumption'!F12+'Kwh Consumption'!G12+'Kwh Consumption'!H12) -> 0 | G11: =('Kwh Consumption'!I12+'Kwh Consumption'!J12) -> 0 | H11: =('Kwh Consumption'!K12+'Kwh Consumption'!L12) -> 0 | I11: =('Kwh Consumption'!M12+'Kwh Consumption'!N12+'Kwh Consumption'!O12+'Kwh Consumption'!P12+'Kwh Consumption'!Q12+'Kwh Consumption'!R12) -> 0 | J11: =('Kwh Consumption'!S12+'Kwh Consumption'!T12) -> 0 | K11: ='Kwh Consumption'!U12 -> 0 | L11: =B11-C11-D11-E11-F11-G11-H11-I11-J11-K11 -> 0
A12: ='Kwh Reading'!A13 -> 44418 | B12: =TOTAL!E11 -> 0 | C12: ='Kwh Consumption'!C13 -> 0 | D12: ='Kwh Consumption'!D13 -> 0 | E12: ='Kwh Consumption'!E13 -> 0 | F12: =('Kwh Consumption'!F13+'Kwh Consumption'!G13+'Kwh Consumption'!H13) -> 0 | G12: =('Kwh Consumption'!I13+'Kwh Consumption'!J13) -> 0 | H12: =('Kwh Consumption'!K13+'Kwh Consumption'!L13) -> 0 | I12: =('Kwh Consumption'!M13+'Kwh Consumption'!N13+'Kwh Consumption'!O13+'Kwh Consumption'!P13+'Kwh Consumption'!Q13+'Kwh Consumption'!R13) -> 0 | J12: =('Kwh Consumption'!S13+'Kwh Consumption'!T13) -> 0 | K12: ='Kwh Consumption'!U13 -> 0 | L12: =B12-C12-D12-E12-F12-G12-H12-I12-J12-K12 -> 0
A13: ='Kwh Reading'!A14 -> 44419 | B13: =TOTAL!E12 -> 0 | C13: ='Kwh Consumption'!C14 -> 0 | D13: ='Kwh Consumption'!D14 -> 0 | E13: ='Kwh Consumption'!E14 -> 0 | F13: =('Kwh Consumption'!F14+'Kwh Consumption'!G14+'Kwh Consumption'!H14) -> 0 | G13: =('Kwh Consumption'!I14+'Kwh Consumption'!J14) -> 0 | H13: =('Kwh Consumption'!K14+'Kwh Consumption'!L14) -> 0 | I13: =('Kwh Consumption'!M14+'Kwh Consumption'!N14+'Kwh Consumption'!O14+'Kwh Consumption'!P14+'Kwh Consumption'!Q14+'Kwh Consumption'!R14) -> 0 | J13: =('Kwh Consumption'!S14+'Kwh Consumption'!T14) -> 0 | K13: ='Kwh Consumption'!U14 -> 0 | L13: =B13-C13-D13-E13-F13-G13-H13-I13-J13-K13 -> 0
A14: ='Kwh Reading'!A15 -> 44420 | B14: =TOTAL!E13 -> 0 | C14: ='Kwh Consumption'!C15 -> 0 | D14: ='Kwh Consumption'!D15 -> 0 | E14: ='Kwh Consumption'!E15 -> 0 | F14: =('Kwh Consumption'!F15+'Kwh Consumption'!G15+'Kwh Consumption'!H15) -> 0 | G14: =('Kwh Consumption'!I15+'Kwh Consumption'!J15) -> 0 | H14: =('Kwh Consumption'!K15+'Kwh Consumption'!L15) -> 0 | I14: =('Kwh Consumption'!M15+'Kwh Consumption'!N15+'Kwh Consumption'!O15+'Kwh Consumption'!P15+'Kwh Consumption'!Q15+'Kwh Consumption'!R15) -> 0 | J14: =('Kwh Consumption'!S15+'Kwh Consumption'!T15) -> 0 | K14: ='Kwh Consumption'!U15 -> 0 | L14: =B14-C14-D14-E14-F14-G14-H14-I14-J14-K14 -> 0
... A33: ='Kwh Reading'!A34 -> 44439 | B33: =TOTAL!E32 -> 0 | C33: ='Kwh Consumption'!C34 -> 0 | D33: ='Kwh Consumption'!D34 -> 0 | E33: ='Kwh Consumption'!E34 -> 0 | F33: =('Kwh Consumption'!F34+'Kwh Consumption'!G34+'Kwh Consumption'!H34) -> 0 | G33: =('Kwh Consumption'!I34+'Kwh Consumption'!J34) -> 0 | H33: =('Kwh Consumption'!K34+'Kwh Consumption'!L34) -> 0 | I33: =('Kwh Consumption'!M34+'Kwh Consumption'!N34+'Kwh Consumption'!O34+'Kwh Consumption'!P34+'Kwh Consumption'!Q34+'Kwh Consumption'!R34) -> 0 | J33: =('Kwh Consumption'!S34+'Kwh Consumption'!T34) -> 0 | K33: ='Kwh Consumption'!U34 -> 0 | L33: =B33-C33-D33-E33-F33-G33-H33-I33-J33-K33 -> 0
A34: Total kwh | B34: =SUM(B3:B33) -> 155750 | C34: =SUM(C3:C33) -> -434940 | D34: =SUM(D3:D33) -> -2456000 | E34: =SUM(E3:E33) -> -237010 | F34: =SUM(F3:F33) -> -913880 | G34: =SUM(G3:G33) -> -285740 | H34: =SUM(H3:H33) -> -1269280 | I34: =SUM(I3:I33) -> -3579370 | ... L34: =SUM(L3:L33) -> 25330099 | M34: =C34+D34+E34+F34+G34+H34+I34+J34+K34+L34 -> 155750
A36: Total $ | B36: =TOTAL!F2 -> 0.14 | C36: =C34*B36 -> -60891.6 | D36: =D34*B36 -> -343840 | E36: =E34*B36 -> -33181.4 | F36: =F34*B36 -> -127943.2 | G36: =G34*B36 -> -40003.6 | H36: =H34*B36 -> -177699.2 | I36: =I34*B36 -> -501111.8 | J36: =J34*B36 -> -2217549.5 | K36: =K34*B36 -> -22188.6 | L36: =L34*B36 -> 3546213.9 | M36: =C36+D36+E36+F36+G36+H36+I36+J36+K36+L36 -> 21805

Sheet  Kwh area wise $ 
A2: Month | B2: $ /Per KWH | C2: Total $ | D2: Reef Club $ | E2: Kitchen $ | F2: Pastry $ | G2: Laundry $ | H2: STP $ | I2: Kuda Huraa Accomodation $ | J2: Guest Room Beach Pavilion & Beach Bungalow $ | K2: Guest Room Water Bungalow $ | L2: Spa $ | M2: Others $
A3: ='Kwh Reading'!A4 -> 44409 | B3: =TOTAL!F2 -> 0.14 | C3: ='Kwh Consumption'!B4*' Kwh area wise $ '!B3 -> 3572.8 | D3: ='Kwh Consumption'!C4*' Kwh area wise $ '!B3 -> 63 | E3: ='Kwh Consumption'!D4*' Kwh area wise $ '!B3 -> 350 | F3: ='Kwh Consumption'!E4*' Kwh area wise $ '!B3 -> 33.6 | G3: =('Kwh Consumption'!F4+'Kwh Consumption'!G4+'Kwh Consumption'!H4)*' Kwh area wise $ '!B3 -> 119 | H3: =('Kwh Consumption'!I4+'Kwh Consumption'!J4)*' Kwh area wise $ '!B3 -> 47.6 | I3: =('Kwh Consumption'!K4+'Kwh Consumption'!L4)*' Kwh area wise $ '!B3 -> 245 | J3: =('Kwh Consumption'!M4+'Kwh Consumption'!N4+'Kwh Consumption'!O4+'Kwh Consumption'!P4+'Kwh Consumption'!Q4+'Kwh Consumption'!R4)*' Kwh area wise $ '!B3 -> 586.6 | K3: =('Kwh Consumption'!S4+'Kwh Consumption'!T4)*' Kwh area wise $ '!B3 -> 756.5362 | L3: ='Kwh Consumption'!U4*' Kwh area wise $ '!B3 -> 29.4 | M3: ='Kwh Consumption'!V4*' Kwh area wise $ '!B3 -> 1342.0638
A4: ='Kwh Reading'!A5 -> 44410 | B4: =TOTAL!F3 -> 0.14 | C4: ='Kwh Consumption'!B5*' Kwh area wise $ '!B4 -> 2902.2 | D4: ='Kwh Consumption'!C5*' Kwh area wise $ '!B4 -> 64.4 | E4: ='Kwh Consumption'!D5*' Kwh area wise $ '!B4 -> 336 | F4: ='Kwh Consumption'!E5*' Kwh area wise $ '!B4 -> 35 | G4: =('Kwh Consumption'!F5+'Kwh Consumption'!G5+'Kwh Consumption'!H5)*' Kwh area wise $ '!B4 -> 84 | H4: =('Kwh Consumption'!I5+'Kwh Consumption'!J5)*' Kwh area wise $ '!B4 -> 40.6 | I4: =('Kwh Consumption'!K5+'Kwh Consumption'!L5)*' Kwh area wise $ '!B4 -> 240.8 | J4: =('Kwh Consumption'!M5+'Kwh Consumption'!N5+'Kwh Consumption'!O5+'Kwh Consumption'!P5+'Kwh Consumption'!Q5+'Kwh Consumption'!R5)*' Kwh area wise $ '!B4 -> 571.2 | K4: =('Kwh Consumption'!S5+'Kwh Consumption'!T5)*' Kwh area wise $ '!B4 -> 670.8506 | L4: ='Kwh Consumption'!U5*' Kwh area wise $ '!B4 -> 35 | M4: ='Kwh Consumption'!V5*' Kwh area wise $ '!B4 -> 824.3494
A5: ='Kwh Reading'!A6 -> 44411 | B5: =TOTAL!F4 -> 0.14 | C5: ='Kwh Consumption'!B6*' Kwh area wise $ '!B5 -> 3171 | D5: ='Kwh Consumption'!C6*' Kwh area wise $ '!B5 -> 68.6 | E5: ='Kwh Consumption'!D6*' Kwh area wise $ '!B5 -> 322 | F5: ='Kwh Consumption'!E6*' Kwh area wise $ '!B5 -> 37.8 | G5: =('Kwh Consumption'!F6+'Kwh Consumption'!G6+'Kwh Consumption'!H6)*' Kwh area wise $ '!B5 -> 89.6 | H5: =('Kwh Consumption'!I6+'Kwh Consumption'!J6)*' Kwh area wise $ '!B5 -> 42 | I5: =('Kwh Consumption'!K6+'Kwh Consumption'!L6)*' Kwh area wise $ '!B5 -> 254.8 | J5: =('Kwh Consumption'!M6+'Kwh Consumption'!N6+'Kwh Consumption'!O6+'Kwh Consumption'!P6+'Kwh Consumption'!Q6+'Kwh Consumption'!R6)*' Kwh area wise $ '!B5 -> 599.2 | K5: =('Kwh Consumption'!S6+'Kwh Consumption'!T6)*' Kwh area wise $ '!B5 -> 676.7838 | L5: ='Kwh Consumption'!U6*' Kwh area wise $ '!B5 -> 28 | M5: ='Kwh Consumption'!V6*' Kwh area wise $ '!B5 -> 1052.2162
A6: ='Kwh Reading'!A7 -> 44412 | B6: =TOTAL!F5 -> 0.14 | C6: ='Kwh Consumption'!B7*' Kwh area wise $ '!B6 -> 3281.6 | D6: ='Kwh Consumption'!C7*' Kwh area wise $ '!B6 -> 72.8 | E6: ='Kwh Consumption'!D7*' Kwh area wise $ '!B6 -> 350 | F6: ='Kwh Consumption'!E7*' Kwh area wise $ '!B6 -> 30.8 | G6: =('Kwh Consumption'!F7+'Kwh Consumption'!G7+'Kwh Consumption'!H7)*' Kwh area wise $ '!B6 -> 102.2 | H6: =('Kwh Consumption'!I7+'Kwh Consumption'!J7)*' Kwh area wise $ '!B6 -> 40.6 | I6: =('Kwh Consumption'!K7+'Kwh Consumption'!L7)*' Kwh area wise $ '!B6 -> 256.2 | J6: =('Kwh Consumption'!M7+'Kwh Consumption'!N7+'Kwh Consumption'!O7+'Kwh Consumption'!P7+'Kwh Consumption'!Q7+'Kwh Consumption'!R7)*' Kwh area wise $ '!B6 -> 645.4 | K6: =('Kwh Consumption'!S7+'Kwh Consumption'!T7)*' Kwh area wise $ '!B6 -> 739.8888 | L6: ='Kwh Consumption'!U7*' Kwh area wise $ '!B6 -> 35 | M6: ='Kwh Consumption'!V7*' Kwh area wise $ '!B6 -> 1008.7112
A7: ='Kwh Reading'!A8 -> 44413 | B7: =TOTAL!F6 -> 0.14 | C7: ='Kwh Consumption'!B8*' Kwh area wise $ '!B7 -> 2326.8 | D7: ='Kwh Consumption'!C8*' Kwh area wise $ '!B7 -> 71.4 | E7: ='Kwh Consumption'!D8*' Kwh area wise $ '!B7 -> 350 | F7: ='Kwh Consumption'!E8*' Kwh area wise $ '!B7 -> 33.6 | G7: =('Kwh Consumption'!F8+'Kwh Consumption'!G8+'Kwh Consumption'!H8)*' Kwh area wise $ '!B7 -> 106.4 | H7: =('Kwh Consumption'!I8+'Kwh Consumption'!J8)*' Kwh area wise $ '!B7 -> 44.8 | I7: =('Kwh Consumption'!K8+'Kwh Consumption'!L8)*' Kwh area wise $ '!B7 -> 242.2 | J7: =('Kwh Consumption'!M8+'Kwh Consumption'!N8+'Kwh Consumption'!O8+'Kwh Consumption'!P8+'Kwh Consumption'!Q8+'Kwh Consumption'!R8)*' Kwh area wise $ '!B7 -> 625.8 | K7: =('Kwh Consumption'!S8+'Kwh Consumption'!T8)*' Kwh area wise $ '!B7 -> 746.8146 | L7: ='Kwh Consumption'!U8*' Kwh area wise $ '!B7 -> 36.4 | M7: ='Kwh Consumption'!V8*' Kwh area wise $ '!B7 -> 69.3854
A8: ='Kwh Reading'!A9 -> 44414 | B8: =TOTAL!F7 -> 0.14 | C8: ='Kwh Consumption'!B9*' Kwh area wise $ '!B8 -> 3829 | D8: ='Kwh Consumption'!C9*' Kwh area wise $ '!B8 -> 36.4 | E8: ='Kwh Consumption'!D9*' Kwh area wise $ '!B8 -> 378 | F8: ='Kwh Consumption'!E9*' Kwh area wise $ '!B8 -> 37.8 | G8: =('Kwh Consumption'!F9+'Kwh Consumption'!G9+'Kwh Consumption'!H9)*' Kwh area wise $ '!B8 -> 127.4 | H8: =('Kwh Consumption'!I9+'Kwh Consumption'!J9)*' Kwh area wise $ '!B8 -> 44.8 | I8: =('Kwh Consumption'!K9+'Kwh Consumption'!L9)*' Kwh area wise $ '!B8 -> 214.2 | J8: =('Kwh Consumption'!M9+'Kwh Consumption'!N9+'Kwh Consumption'!O9+'Kwh Consumption'!P9+'Kwh Consumption'!Q9+'Kwh Consumption'!R9)*' Kwh area wise $ '!B8 -> 476 | K8: =('Kwh Consumption'!S9+'Kwh Consumption'!T9)*' Kwh area wise $ '!B8 -> 750.1858 | L8: ='Kwh Consumption'!U9*' Kwh area wise $ '!B8 -> 42 | M8: ='Kwh Consumption'!V9*' Kwh area wise $ '!B8 -> 1722.2142
A9: ='Kwh Reading'!A10 -> 44415 | B9: =TOTAL!F8 -> 0.14 | C9: ='Kwh Consumption'!B10*' Kwh area wise $ '!B9 -> 3288.6 | D9: ='Kwh Consumption'!C10*' Kwh area wise $ '!B9 -> 68.6 | E9: ='Kwh Consumption'!D10*' Kwh area wise $ '!B9 -> 350 | F9: ='Kwh Consumption'!E10*' Kwh area wise $ '!B9 -> 30.8 | G9: =('Kwh Consumption'!F10+'Kwh Consumption'!G10+'Kwh Consumption'!H10)*' Kwh area wise $ '!B9 -> 102.2 | H9: =('Kwh Consumption'!I10+'Kwh Consumption'!J10)*' Kwh area wise $ '!B9 -> 43.4 | I9: =('Kwh Consumption'!K10+'Kwh Consumption'!L10)*' Kwh area wise $ '!B9 -> 242.2 | J9: =('Kwh Consumption'!M10+'Kwh Consumption'!N10+'Kwh Consumption'!O10+'Kwh Consumption'!P10+'Kwh Consumption'!Q10+'Kwh Consumption'!R10)*' Kwh area wise $ '!B9 -> 792.4 | K9: =('Kwh Consumption'!S10+'Kwh Consumption'!T10)*' Kwh area wise $ '!B9 -> 849.66 | L9: ='Kwh Consumption'!U10*' Kwh area wise $ '!B9 -> 29.4 | M9: ='Kwh Consumption'!V10*' Kwh area wise $ '!B9 -> 779.94
A10: ='Kwh Reading'!A11 -> 44416 | B10: =TOTAL!F9 -> 0.14 | C10: ='Kwh Consumption'!B11*' Kwh area wise $ '!B10 -> 0 | D10: ='Kwh Consumption'!C11*' Kwh area wise $ '!B10 -> -61336.8 | E10: ='Kwh Consumption'!D11*' Kwh area wise $ '!B10 -> -346276 | F10: ='Kwh Consumption'!E11*' Kwh area wise $ '!B10 -> -33420.8 | G10: =('Kwh Consumption'!F11+'Kwh Consumption'!G11+'Kwh Consumption'!H11)*' Kwh area wise $ '!B10 -> -128674 | H10: =('Kwh Consumption'!I11+'Kwh Consumption'!J11)*' Kwh area wise $ '!B10 -> -40307.4 | I10: =('Kwh Consumption'!K11+'Kwh Consumption'!L11)*' Kwh area wise $ '!B10 -> -179394.6 | J10: =('Kwh Consumption'!M11+'Kwh Consumption'!N11+'Kwh Consumption'!O11+'Kwh Consumption'!P11+'Kwh Consumption'!Q11+'Kwh Consumption'!R11)*' Kwh area wise $ '!B10 -> -505408.4 | K10: =('Kwh Consumption'!S11+'Kwh Consumption'!T11)*' Kwh area wise $ '!B10 -> -2222740.2 | L10: ='Kwh Consumption'!U11*' Kwh area wise $ '!B10 -> -22423.8 | M10: ='Kwh Consumption'!V11*' Kwh area wise $ '!B10 -> 3539982
A11: ='Kwh Reading'!A12 -> 44417 | B11: =TOTAL!F10 -> 0.14 | C11: ='Kwh Consumption'!B12*' Kwh area wise $ '!B11 -> 0 | D11: ='Kwh Consumption'!C12*' Kwh area wise $ '!B11 -> 0 | E11: ='Kwh Consumption'!D12*' Kwh area wise $ '!B11 -> 0 | F11: ='Kwh Consumption'!E12*' Kwh area wise $ '!B11 -> 0 | G11: =('Kwh Consumption'!F12+'Kwh Consumption'!G12+'Kwh Consumption'!H12)*' Kwh area wise $ '!B11 -> 0 | H11: =('Kwh Consumption'!I12+'Kwh Consumption'!J12)*' Kwh area wise $ '!B11 -> 0 | I11: =('Kwh Consumption'!K12+'Kwh Consumption'!L12)*' Kwh area wise $ '!B11 -> 0 | J11: =('Kwh Consumption'!M12+'Kwh Consumption'!N12+'Kwh Consumption'!O12+'Kwh Consumption'!P12+'Kwh Consumption'!Q12+'Kwh Consumption'!R12)*' Kwh area wise $ '!B11 -> 0 | K11: =('Kwh Consumption'!S12+'Kwh Consumption'!T12)*' Kwh area wise $ '!B11 -> 0 | L11: ='Kwh Consumption'!U12*' Kwh area wise $ '!B11 -> 0 | M11: ='Kwh Consumption'!V12*' Kwh area wise $ '!B11 -> 0
A12: ='Kwh Reading'!A13 -> 44418 | B12: =TOTAL!F11 -> 0.14 | C12: ='Kwh Consumption'!B13*' Kwh area wise $ '!B12 -> 0 | D12: ='Kwh Consumption'!C13*' Kwh area wise $ '!B12 -> 0 | E12: ='Kwh Consumption'!D13*' Kwh area wise $ '!B12 -> 0 | F12: ='Kwh Consumption'!E13*' Kwh area wise $ '!B12 -> 0 | G12: =('Kwh Consumption'!F13+'Kwh Consumption'!G13+'Kwh Consumption'!H13)*' Kwh area wise $ '!B12 -> 0 | H12: =('Kwh Consumption'!I13+'Kwh Consumption'!J13)*' Kwh area wise $ '!B12 -> 0 | I12: =('Kwh Consumption'!K13+'Kwh Consumption'!L13)*' Kwh area wise $ '!B12 -> 0 | J12: =('Kwh Consumption'!M13+'Kwh Consumption'!N13+'Kwh Consumption'!O13+'Kwh Consumption'!P13+'Kwh Consumption'!Q13+'Kwh Consumption'!R13)*' Kwh area wise $ '!B12 -> 0 | K12: =('Kwh Consumption'!S13+'Kwh Consumption'!T13)*' Kwh area wise $ '!B12 -> 0 | L12: ='Kwh Consumption'!U13*' Kwh area wise $ '!B12 -> 0 | M12: ='Kwh Consumption'!V13*' Kwh area wise $ '!B12 -> 0
A13: ='Kwh Reading'!A14 -> 44419 | B13: =TOTAL!F12 -> 0.14 | C13: ='Kwh Consumption'!B14*' Kwh area wise $ '!B13 -> 0 | D13: ='Kwh Consumption'!C14*' Kwh area wise $ '!B13 -> 0 | E13: ='Kwh Consumption'!D14*' Kwh area wise $ '!B13 -> 0 | F13: ='Kwh Consumption'!E14*' Kwh area wise $ '!B13 -> 0 | G13: =('Kwh Consumption'!F14+'Kwh Consumption'!G14+'Kwh Consumption'!H14)*' Kwh area wise $ '!B13 -> 0 | H13: =('Kwh Consumption'!I14+'Kwh Consumption'!J14)*' Kwh area wise $ '!B13 -> 0 | I13: =('Kwh Consumption'!K14+'Kwh Consumption'!L14)*' Kwh area wise $ '!B13 -> 0 | J13: =('Kwh Consumption'!M14+'Kwh Consumption'!N14+'Kwh Consumption'!O14+'Kwh Consumption'!P14+'Kwh Consumption'!Q14+'Kwh Consumption'!R14)*' Kwh area wise $ '!B13 -> 0 | K13: =('Kwh Consumption'!S14+'Kwh Consumption'!T14)*' Kwh area wise $ '!B13 -> 0 | L13: ='Kwh Consumption'!U14*' Kwh area wise $ '!B13 -> 0 | M13: ='Kwh Consumption'!V14*' Kwh area wise $ '!B13 -> 0
A14: ='Kwh Reading'!A15 -> 44420 | B14: =TOTAL!F13 -> 0.14 | C14: ='Kwh Consumption'!B15*' Kwh area wise $ '!B14 -> 0 | D14: ='Kwh Consumption'!C15*' Kwh area wise $ '!B14 -> 0 | E14: ='Kwh Consumption'!D15*' Kwh area wise $ '!B14 -> 0 | F14: ='Kwh Consumption'!E15*' Kwh area wise $ '!B14 -> 0 | G14: =('Kwh Consumption'!F15+'Kwh Consumption'!G15+'Kwh Consumption'!H15)*' Kwh area wise $ '!B14 -> 0 | H14: =('Kwh Consumption'!I15+'Kwh Consumption'!J15)*' Kwh area wise $ '!B14 -> 0 | I14: =('Kwh Consumption'!K15+'Kwh Consumption'!L15)*' Kwh area wise $ '!B14 -> 0 | J14: =('Kwh Consumption'!M15+'Kwh Consumption'!N15+'Kwh Consumption'!O15+'Kwh Consumption'!P15+'Kwh Consumption'!Q15+'Kwh Consumption'!R15)*' Kwh area wise $ '!B14 -> 0 | K14: =('Kwh Consumption'!S15+'Kwh Consumption'!T15)*' Kwh area wise $ '!B14 -> 0 | L14: ='Kwh Consumption'!U15*' Kwh area wise $ '!B14 -> 0 | M14: ='Kwh Consumption'!V15*' Kwh area wise $ '!B14 -> 0
... A33: ='Kwh Reading'!A34 -> 44439 | B33: =TOTAL!F32 -> 0.14 | C33: ='Kwh Consumption'!B34*' Kwh area wise $ '!B33 -> 0 | D33: ='Kwh Consumption'!C34*' Kwh area wise $ '!B33 -> 0 | E33: ='Kwh Consumption'!D34*' Kwh area wise $ '!B33 -> 0 | F33: ='Kwh Consumption'!E34*' Kwh area wise $ '!B33 -> 0 | G33: =('Kwh Consumption'!F34+'Kwh Consumption'!G34+'Kwh Consumption'!H34)*' Kwh area wise $ '!B33 -> 0 | H33: =('Kwh Consumption'!I34+'Kwh Consumption'!J34)*' Kwh area wise $ '!B33 -> 0 | I33: =('Kwh Consumption'!K34+'Kwh Consumption'!L34)*' Kwh area wise $ '!B33 -> 0 | J33: =('Kwh Consumption'!M34+'Kwh Consumption'!N34+'Kwh Consumption'!O34+'Kwh Consumption'!P34+'Kwh Consumption'!Q34+'Kwh Consumption'!R34)*' Kwh area wise $ '!B33 -> 0 | K33: =('Kwh Consumption'!S34+'Kwh Consumption'!T34)*' Kwh area wise $ '!B33 -> 0 | L33: ='Kwh Consumption'!U34*' Kwh area wise $ '!B33 -> 0 | M33: ='Kwh Consumption'!V34*' Kwh area wise $ '!B33 -> 0
A34: Total | C34: =SUM(C3:C33) -> 22372 | D34: =SUM(D3:D33) -> -60891.6 | E34: =SUM(E3:E33) -> -343840 | F34: =SUM(F3:F33) -> -33181.4 | G34: =SUM(G3:G33) -> -127943.2 | H34: =SUM(H3:H33) -> -40003.6 | I34: =SUM(I3:I33) -> -177699.2 | J34: =SUM(J3:J33) -> -501111.8 | ... M34: =SUM(M3:M33) -> 3546780.9 | N34: =D34+E34+F34+G34+H34+I34+J34+K34+L34+M34 -> 22372

Sheet Water Reading
B1: Meter 1 | C1: Meter 2 | D1: Meter 6 | E1: Meter 8 | F1: Meter 7 | G1: Meter 9 | H1: Meter 3 | I1: Meter 5 | J1: Meter 10 | K1: Meter 13 | L1: Meter 16 | M1: Meter 17 | N1: Meter 15 | O1: Meter 14 | P1: Meter 4 | Q1: Meter 11 | R1: Meter 12
A2: Date | B2: Main Meter 1 | C2: Main Meter 2 | D2: Beach Bunglow | E2: Kuda Huraa staff | F2: Bodu hura staff | G2: Laundry | H2: Water Bunglow | I2: Main Kitchen | J2: Second stage | K2: Supply jetty | L2: Staff housing A | M2: Staff housing B | N2: Spa | O2: Staff jetty | P2: Main pool | Q2: Reef club pool | R2: Reef club kitchen
A3: 44409 | B3: 173617 | C3: 135457 | D3: 213833 | E3: 249696 | F3: 66956 | G3: 112190 | H3: 54328 | I3: 64440 | J3: 20665 | K3: 1024 | L3: 17468 | M3: 24658 | N3: 7431 | O3: 1701 | P3: 27288 | Q3: 775 | R3: 6394
A4: 44410 | B4: 173926 | C4: 135692 | D4: 214035 | E4: 249756 | F4: 66957 | G4: 112211 | H4: 54356 | I4: 64466 | J4: 20676 | K4: 1024 | L4: 17476 | M4: 24676 | N4: 7433 | O4: 1703 | P4: 27298 | Q4: 781 | R4: 6401
A5: 44411 | B5: 174440 | C5: 135835 | D5: 214208 | E5: 249814 | F5: 66958 | G5: 112227 | H5: 54382 | I5: 64497 | J5: 20687 | K5: 1024 | L5: 17485 | M5: 24689 | N5: 7436 | O5: 1703 | P5: 27312 | Q5: 788 | R5: 6407
A6: 44412 | B6: 174637 | C6: 136167 | D6: 214461 | E6: 249867 | F6: 66959 | G6: 112241 | H6: 54403 | I6: 64526 | J6: 20697 | K6: 1024 | L6: 17491 | M6: 24704 | N6: 7438 | O6: 1704 | P6: 27323 | Q6: 793 | R6: 6412
A7: 44413 | B7: 174832 | C7: 136408 | D7: 214710 | E7: 249917 | F7: 66959 | G7: 112258 | H7: 54445 | I7: 64545 | J7: 20708 | K7: 1024 | L7: 17498 | M7: 24718 | N7: 7440 | O7: 1704 | P7: 27323 | Q7: 799 | R7: 6423
A8: 44414 | B8: 175055 | C8: 136523 | D8: 214910 | E8: 249977 | F8: 66960 | G8: 112275 | H8: 54491 | I8: 64581 | J8: 20720 | K8: 1024 | L8: 17505 | M8: 24736 | N8: 7445 | O8: 1705 | P8: 27339 | Q8: 804 | R8: 6430
A9: 44415 | B9: 175231 | C9: 136455 | D9: 215100 | E9: 250037 | F9: 66961 | G9: 112297 | H9: 54530 | I9: 64601 | J9: 20731 | K9: 1024 | L9: 17514 | M9: 24751 | N9: 7449 | O9: 1707 | P9: 27339 | Q9: 806 | R9: 6433
A10: 44416 | B10: 175406 | C10: 137129 | D10: 215366 | E10: 250094 | F10: 66961 | G10: 112313 | H10: 54560 | I10: 64634 | J10: 20742 | K10: 1024 | L10: 17521 | M10: 24767 | N10: 7453 | O10: 1708 | P10: 27351 | Q10: 815 | R10: 6440
A11: 44417
A12: 44418
A13: 44419
A14: 44420
A15: 44421
A16: 44422
A17: 44423
A18: 44424
A19: 44425
A20: 44426
A21: 44427
A22: 44428
... A34: 44440

Sheet Water consumption
A2: Date | B2: RO production (Ro 1 : 4) | C2: Total Consumption M3 (Meter 1 : 2) | E2: Water Bunglow | G2: Beach bunglow | I2: Main Pool | K2: Main kitchen | M2: Reef club kitchen | O2: Reef club pool | Q2: Bodu Huraa staff | S2: Kuda Huraa staff | U2: Laundry | W2: Second stage | Y2: Total
C3: M3 | D3: % of Total production | E3: M3 | F3: % | G3: M3 | H3: % | I3: M3 | J3: % | K3: M3 | L3: % | M3: M3 | N3: % | O3: M3 | P3: % | Q3: M3 | R3: % | S3: M3 | T3: % | U3: M3 | V3: % | W3: M3 | X3: % | Y3: M3 | Z3: %
A4: ='Water Reading'!A3 -> 44409 | B4: 469 | C4: =('Water Reading'!B4-'Water Reading'!B3)+('Water Reading'!C4-'Water Reading'!C3) -> 544 | D4: =C4/B4 -> 1.1599147 | E4: ='Water Reading'!H4-'Water Reading'!H3 -> 28 | F4: =E4/C4 -> 0.051470588 | G4: =('Water Reading'!D4-'Water Reading'!D3)-('Water Reading'!R4-'Water Reading'!R3)-('Water Reading'!Q4-'Water Reading'!Q3) -> 189 | H4: =G4/C4 -> 0.34742647 | I4: ='Water Reading'!P4-'Water Reading'!P3 -> 10 | J4: =I4/C4 -> 0.018382353 | K4: =('Water Reading'!I4-'Water Reading'!I3)-('Water Reading'!P4-'Water Reading'!P3) -> 16 | L4: =K4/C4 -> 0.029411765 | M4: ='Water Reading'!R4-'Water Reading'!R3 -> 7 | N4: =M4/C4 -> 0.012867647 | O4: ='Water Reading'!Q4-'Water Reading'!Q3 -> 6 | P4: =O4/C4 -> 0.011029412 | Q4: ='Water Reading'!F4-'Water Reading'!F3 -> 1 | R4: =Q4/C4 -> 0.0018382353 | S4: ='Water Reading'!E4-'Water Reading'!E3 -> 60 | T4: =S4/C4 -> 0.11029412 | U4: ='Water Reading'!G4-'Water Reading'!G3 -> 21 | V4: =U4/C4 -> 0.038602941 | W4: ='Water Reading'!J4-'Water Reading'!J3 -> 11 | X4: =W4/C4 -> 0.020220588 | Y4: =E4+I4+K4+M4+O4+G4+Q4+S4+U4+W4 -> 349 | Z4: =Y4/B4 -> 0.74413646
A5: ='Water Reading'!A4 -> 44410 | B5: =TOTAL!I3 -> 269 | C5: =('Water Reading'!B5-'Water Reading'!B4)+('Water Reading'!C5-'Water Reading'!C4) -> 657 | D5: =C5/B5 -> 2.4423792 | E5: ='Water Reading'!H5-'Water Reading'!H4 -> 26 | F5: =E5/C5 -> 0.03957382 | G5: =('Water Reading'!D5-'Water Reading'!D4)-('Water Reading'!R5-'Water Reading'!R4)-('Water Reading'!Q5-'Water Reading'!Q4) -> 160 | H5: =G5/C5 -> 0.2435312 | I5: ='Water Reading'!P5-'Water Reading'!P4 -> 14 | J5: =I5/C5 -> 0.02130898 | K5: =('Water Reading'!I5-'Water Reading'!I4)-('Water Reading'!P5-'Water Reading'!P4) -> 17 | L5: =K5/C5 -> 0.02587519 | M5: ='Water Reading'!R5-'Water Reading'!R4 -> 6 | N5: =M5/C5 -> 0.0091324201 | O5: ='Water Reading'!Q5-'Water Reading'!Q4 -> 7 | P5: =O5/C5 -> 0.01065449 | Q5: ='Water Reading'!F5-'Water Reading'!F4 -> 1 | R5: =Q5/C5 -> 0.00152207 | S5: ='Water Reading'!E5-'Water Reading'!E4 -> 58 | T5: =S5/C5 -> 0.088280061 | U5: ='Water Reading'!G5-'Water Reading'!G4 -> 16 | V5: =U5/C5 -> 0.02435312 | W5: ='Water Reading'!J5-'Water Reading'!J4 -> 11 | X5: =W5/C5 -> 0.01674277 | Y5: =E5+I5+K5+M5+O5+G5+Q5+S5+U5+W5 -> 316 | Z5: =Y5/B5 -> 1.1747212
A6: ='Water Reading'!A5 -> 44411 | B6: =TOTAL!I4 -> 435 | C6: =('Water Reading'!B6-'Water Reading'!B5)+('Water Reading'!C6-'Water Reading'!C5) -> 529 | D6: =C6/B6 -> 1.216092 | E6: ='Water Reading'!H6-'Water Reading'!H5 -> 21 | F6: =E6/C6 -> 0.039697543 | G6: =('Water Reading'!D6-'Water Reading'!D5)-('Water Reading'!R6-'Water Reading'!R5)-('Water Reading'!Q6-'Water Reading'!Q5) -> 243 | H6: =G6/C6 -> 0.45935728 | I6: ='Water Reading'!P6-'Water Reading'!P5 -> 11 | J6: =I6/C6 -> 0.020793951 | K6: =('Water Reading'!I6-'Water Reading'!I5)-('Water Reading'!P6-'Water Reading'!P5) -> 18 | L6: =K6/C6 -> 0.034026465 | M6: ='Water Reading'!R6-'Water Reading'!R5 -> 5 | N6: =M6/C6 -> 0.0094517958 | O6: ='Water Reading'!Q6-'Water Reading'!Q5 -> 5 | P6: =O6/C6 -> 0.0094517958 | Q6: ='Water Reading'!F6-'Water Reading'!F5 -> 1 | R6: =Q6/C6 -> 0.0018903592 | S6: ='Water Reading'!E6-'Water Reading'!E5 -> 53 | T6: =S6/C6 -> 0.10018904 | U6: ='Water Reading'!G6-'Water Reading'!G5 -> 14 | V6: =U6/C6 -> 0.026465028 | W6: ='Water Reading'!J6-'Water Reading'!J5 -> 10 | X6: =W6/C6 -> 0.018903592 | Y6: =E6+I6+K6+M6+O6+G6+Q6+S6+U6+W6 -> 381 | Z6: =Y6/B6 -> 0.87586207
A7: ='Water Reading'!A6 -> 44412 | B7: =TOTAL!I5 -> 400 | C7: =('Water Reading'!B7-'Water Reading'!B6)+('Water Reading'!C7-'Water Reading'!C6) -> 436 | D7: =C7/B7 -> 1.09 | E7: ='Water Reading'!H7-'Water Reading'!H6 -> 42 | F7: =E7/C7 -> 0.096330275 | G7: =('Water Reading'!D7-'Water Reading'!D6)-('Water Reading'!R7-'Water Reading'!R6)-('Water Reading'!Q7-'Water Reading'!Q6) -> 232 | H7: =G7/C7 -> 0.53211009 | I7: ='Water Reading'!P7-'Water Reading'!P6 -> 0 | J7: =I7/C7 -> 0 | K7: =('Water Reading'!I7-'Water Reading'!I6)-('Water Reading'!P7-'Water Reading'!P6) -> 19 | L7: =K7/C7 -> 0.043577982 | M7: ='Water Reading'!R7-'Water Reading'!R6 -> 11 | N7: =M7/C7 -> 0.025229358 | O7: ='Water Reading'!Q7-'Water Reading'!Q6 -> 6 | P7: =O7/C7 -> 0.013761468 | Q7: ='Water Reading'!F7-'Water Reading'!F6 -> 0 | R7: =Q7/C7 -> 0 | S7: ='Water Reading'!E7-'Water Reading'!E6 -> 50 | T7: =S7/C7 -> 0.1146789 | U7: ='Water Reading'!G7-'Water Reading'!G6 -> 17 | V7: =U7/C7 -> 0.038990826 | W7: ='Water Reading'!J7-'Water Reading'!J6 -> 11 | X7: =W7/C7 -> 0.025229358 | Y7: =E7+I7+K7+M7+O7+G7+Q7+S7+U7+W7 -> 388 | Z7: =Y7/B7 -> 0.97
A8: ='Water Reading'!A7 -> 44413 | B8: =TOTAL!I6 -> 371 | C8: =('Water Reading'!B8-'Water Reading'!B7)+('Water Reading'!C8-'Water Reading'!C7) -> 338 | D8: =C8/B8 -> 0.91105121 | E8: ='Water Reading'!H8-'Water Reading'!H7 -> 46 | F8: =E8/C8 -> 0.13609467 | G8: =('Water Reading'!D8-'Water Reading'!D7)-('Water Reading'!R8-'Water Reading'!R7)-('Water Reading'!Q8-'Water Reading'!Q7) -> 188 | H8: =G8/C8 -> 0.55621302 | I8: ='Water Reading'!P8-'Water Reading'!P7 -> 16 | J8: =I8/C8 -> 0.047337278 | K8: =('Water Reading'!I8-'Water Reading'!I7)-('Water Reading'!P8-'Water Reading'!P7) -> 20 | L8: =K8/C8 -> 0.059171598 | M8: ='Water Reading'!R8-'Water Reading'!R7 -> 7 | N8: =M8/C8 -> 0.020710059 | O8: ='Water Reading'!Q8-'Water Reading'!Q7 -> 5 | P8: =O8/C8 -> 0.014792899 | Q8: ='Water Reading'!F8-'Water Reading'!F7 -> 1 | R8: =Q8/C8 -> 0.0029585799 | S8: ='Water Reading'!E8-'Water Reading'!E7 -> 60 | T8: =S8/C8 -> 0.17751479 | U8: ='Water Reading'!G8-'Water Reading'!G7 -> 17 | V8: =U8/C8 -> 0.050295858 | W8: ='Water Reading'!J8-'Water Reading'!J7 -> 12 | X8: =W8/C8 -> 0.035502959 | Y8: =E8+I8+K8+M8+O8+G8+Q8+S8+U8+W8 -> 372 | Z8: =Y8/B8 -> 1.0026954
A9: ='Water Reading'!A8 -> 44414 | B9: =TOTAL!I7 -> 256 | C9: =('Water Reading'!B9-'Water Reading'!B8)+('Water Reading'!C9-'Water Reading'!C8) -> 108 | D9: =C9/B9 -> 0.421875 | E9: ='Water Reading'!H9-'Water Reading'!H8 -> 39 | F9: =E9/C9 -> 0.36111111 | G9: =('Water Reading'!D9-'Water Reading'!D8)-('Water Reading'!R9-'Water Reading'!R8)-('Water Reading'!Q9-'Water Reading'!Q8) -> 185 | H9: =G9/C9 -> 1.712963 | I9: ='Water Reading'!P9-'Water Reading'!P8 -> 0 | J9: =I9/C9 -> 0 | K9: =('Water Reading'!I9-'Water Reading'!I8)-('Water Reading'!P9-'Water Reading'!P8) -> 20 | L9: =K9/C9 -> 0.18518519 | M9: ='Water Reading'!R9-'Water Reading'!R8 -> 3 | N9: =M9/C9 -> 0.027777778 | O9: ='Water Reading'!Q9-'Water Reading'!Q8 -> 2 | P9: =O9/C9 -> 0.018518519 | Q9: ='Water Reading'!F9-'Water Reading'!F8 -> 1 | R9: =Q9/C9 -> 0.0092592593 | S9: ='Water Reading'!E9-'Water Reading'!E8 -> 60 | T9: =S9/C9 -> 0.55555556 | U9: ='Water Reading'!G9-'Water Reading'!G8 -> 22 | V9: =U9/C9 -> 0.2037037 | W9: ='Water Reading'!J9-'Water Reading'!J8 -> 11 | X9: =W9/C9 -> 0.10185185 | Y9: =E9+I9+K9+M9+O9+G9+Q9+S9+U9+W9 -> 343 | Z9: =Y9/B9 -> 1.3398438
A10: ='Water Reading'!A9 -> 44415 | B10: =TOTAL!I8 -> 366 | C10: =('Water Reading'!B10-'Water Reading'!B9)+('Water Reading'!C10-'Water Reading'!C9) -> 849 | D10: =C10/B10 -> 2.3196721 | E10: ='Water Reading'!H10-'Water Reading'!H9 -> 30 | F10: =E10/C10 -> 0.035335689 | G10: =('Water Reading'!D10-'Water Reading'!D9)-('Water Reading'!R10-'Water Reading'!R9)-('Water Reading'!Q10-'Water Reading'!Q9) -> 250 | H10: =G10/C10 -> 0.29446408 | I10: ='Water Reading'!P10-'Water Reading'!P9 -> 12 | J10: =I10/C10 -> 0.014134276 | K10: =('Water Reading'!I10-'Water Reading'!I9)-('Water Reading'!P10-'Water Reading'!P9) -> 21 | L10: =K10/C10 -> 0.024734982 | M10: ='Water Reading'!R10-'Water Reading'!R9 -> 7 | N10: =M10/C10 -> 0.0082449941 | O10: ='Water Reading'!Q10-'Water Reading'!Q9 -> 9 | P10: =O10/C10 -> 0.010600707 | Q10: ='Water Reading'!F10-'Water Reading'!F9 -> 0 | R10: =Q10/C10 -> 0 | S10: ='Water Reading'!E10-'Water Reading'!E9 -> 57 | T10: =S10/C10 -> 0.067137809 | U10: ='Water Reading'!G10-'Water Reading'!G9 -> 16 | V10: =U10/C10 -> 0.018845701 | W10: ='Water Reading'!J10-'Water Reading'!J9 -> 11 | X10: =W10/C10 -> 0.012956419 | Y10: =E10+I10+K10+M10+O10+G10+Q10+S10+U10+W10 -> 413 | Z10: =Y10/B10 -> 1.1284153
A11: ='Water Reading'!A10 -> 44416 | B11: =TOTAL!I9 -> 0 | C11: =('Water Reading'!B11-'Water Reading'!B10)+('Water Reading'!C11-'Water Reading'!C10) -> -312535 | D11: =C11/B11 -> #DIV/0! | E11: ='Water Reading'!H11-'Water Reading'!H10 -> -54560 | F11: =E11/C11 -> 0.17457245 | G11: =('Water Reading'!D11-'Water Reading'!D10)-('Water Reading'!R11-'Water Reading'!R10)-('Water Reading'!Q11-'Water Reading'!Q10) -> -208111 | H11: =G11/C11 -> 0.66588062 | I11: ='Water Reading'!P11-'Water Reading'!P10 -> -27351 | J11: =I11/C11 -> 0.087513398 | K11: =('Water Reading'!I11-'Water Reading'!I10)-('Water Reading'!P11-'Water Reading'!P10) -> -37283 | L11: =K11/C11 -> 0.11929224 | M11: ='Water Reading'!R11-'Water Reading'!R10 -> -6440 | N11: =M11/C11 -> 0.020605692 | O11: ='Water Reading'!Q11-'Water Reading'!Q10 -> -815 | P11: =O11/C11 -> 0.0026077079 | Q11: ='Water Reading'!F11-'Water Reading'!F10 -> -66961 | R11: =Q11/C11 -> 0.2142512 | S11: ='Water Reading'!E11-'Water Reading'!E10 -> -250094 | T11: =S11/C11 -> 0.80021118 | U11: ='Water Reading'!G11-'Water Reading'!G10 -> -112313 | V11: =U11/C11 -> 0.35936135 | W11: ='Water Reading'!J11-'Water Reading'!J10 -> -20742 | X11: =W11/C11 -> 0.066366967 | Y11: =E11+I11+K11+M11+O11+G11+Q11+S11+U11+W11 -> -784670 | Z11: =Y11/B11 -> #DIV/0!
A12: ='Water Reading'!A11 -> 44417 | B12: =TOTAL!I10 -> 0 | C12: =('Water Reading'!B12-'Water Reading'!B11)+('Water Reading'!C12-'Water Reading'!C11) -> 0 | D12: =C12/B12 -> #DIV/0! | E12: ='Water Reading'!H12-'Water Reading'!H11 -> 0 | F12: =E12/C12 -> #DIV/0! | G12: =('Water Reading'!D12-'Water Reading'!D11)-('Water Reading'!R12-'Water Reading'!R11)-('Water Reading'!Q12-'Water Reading'!Q11) -> 0 | H12: =G12/C12 -> #DIV/0! | I12: ='Water Reading'!P12-'Water Reading'!P11 -> 0 | J12: =I12/C12 -> #DIV/0! | K12: =('Water Reading'!I12-'Water Reading'!I11)-('Water Reading'!P12-'Water Reading'!P11) -> 0 | L12: =K12/C12 -> #DIV/0! | M12: ='Water Reading'!R12-'Water Reading'!R11 -> 0 | N12: =M12/C12 -> #DIV/0! | O12: ='Water Reading'!Q12-'Water Reading'!Q11 -> 0 | P12: =O12/C12 -> #DIV/0! | Q12: ='Water Reading'!F12-'Water Reading'!F11 -> 0 | R12: =Q12/C12 -> #DIV/0! | S12: ='Water Reading'!E12-'Water Reading'!E11 -> 0 | T12: =S12/C12 -> #DIV/0! | U12: ='Water Reading'!G12-'Water Reading'!G11 -> 0 | V12: =U12/C12 -> #DIV/0! | W12: ='Water Reading'!J12-'Water Reading'!J11 -> 0 | X12: =W12/C12 -> #DIV/0! | Y12: =E12+I12+K12+M12+O12+G12+Q12+S12+U12+W12 -> 0 | Z12: =Y12/B12 -> #DIV/0!
