Workbook

Sheet Total
A1: Site Name | B1: Day | C1: Month | D1: Year | E1: Total Electricity Kwh | F1: Electricity Tariff ($/Kwh) | G1: LPG (Kg) | H1: LPG $/Kg | I1: Water Utility Supply (m3) m3 | J1: Water Utility Supply (m3) $/m3 | K1: Room Nights | L1: Utilities day cost dh
A2: Serengeti | B2: 1 | C2: 7 | D2: 2021 | E2: ='UTILITY REPORT 1'!F3 -> 4264 | F2: =('UTILITY REPORT 1'!E3*'UTILITY REPORT 1'!D3)/'UTILITY REPORT 1'!F3 -> 0.42204034 | G2: =IF('Utility summery'!M6<0,"0",'Utility summery'!M6) -> 130.68 | H2: 0 | I2: =IF('UTILITY REPORT 1'!G3<0,"0",'UTILITY REPORT 1'!G3) -> 109 | J2: 2.165 | K2: ='UTILITY REPORT 1'!C3 -> 23 | L2: =E2*F2+G2*H2+#REF!*#REF!+I2*J2 -> #REF!
A3: Serengeti | B3: =B2+1 -> 2 | C3: 7 | D3: 2021 | E3: ='UTILITY REPORT 1'!F4 -> 4274 | F3: =('UTILITY REPORT 1'!E4*'UTILITY REPORT 1'!D4)/'UTILITY REPORT 1'!F4 -> 0.39586336 | G3: =IF('Utility summery'!M7<0,"0",'Utility summery'!M7) -> 124.52 | H3: 0 | I3: =IF('UTILITY REPORT 1'!G4<0,"0",'UTILITY REPORT 1'!G4) -> 101 | J3: 2.165 | K3: ='UTILITY REPORT 1'!C4 -> 27 | L3: =E3*F3+G3*H3+#REF!*#REF!+I3*J3 -> #REF!
A4: Serengeti | B4: =B3+1 -> 3 | C4: 7 | D4: 2021 | E4: ='UTILITY REPORT 1'!F5 -> 4467 | F4: =('UTILITY REPORT 1'!E5*'UTILITY REPORT 1'!D5)/'UTILITY REPORT 1'!F5 -> 0.40530557 | G4: =IF('Utility summery'!M8<0,"0",'Utility summery'!M8) -> 44 | H4: 0 | I4: =IF('UTILITY REPORT 1'!G5<0,"0",'UTILITY REPORT 1'!G5) -> 94 | J4: 2.165 | K4: ='UTILITY REPORT 1'!C5 -> 20 | L4: =E4*F4+G4*H4+#REF!*#REF!+I4*J4 -> #REF!
A5: Serengeti | B5: =B4+1 -> 4 | C5: 7 | D5: 2021 | E5: ='UTILITY REPORT 1'!F6 -> 4106 | F5: =('UTILITY REPORT 1'!E6*'UTILITY REPORT 1'!D6)/'UTILITY REPORT 1'!F6 -> 0.40242085 | G5: =IF('Utility summery'!M9<0,"0",'Utility summery'!M9) -> 89.364 | H5: 0 | I5: =IF('UTILITY REPORT 1'!G6<0,"0",'UTILITY REPORT 1'!G6) -> 98 | J5: 2.165 | K5: ='UTILITY REPORT 1'!C6 -> 14 | L5: =E5*F5+G5*H5+#REF!*#REF!+I5*J5 -> #REF!
A6: Serengeti | B6: =B5+1 -> 5 | C6: 7 | D6: 2021 | E6: ='UTILITY REPORT 1'!F7 -> 4026 | F6: =('UTILITY REPORT 1'!E7*'UTILITY REPORT 1'!D7)/'UTILITY REPORT 1'!F7 -> 0.40842524 | G6: =IF('Utility summery'!M10<0,"0",'Utility summery'!M10) -> 112.42 | H6: 0 | I6: =IF('UTILITY REPORT 1'!G7<0,"0",'UTILITY REPORT 1'!G7) -> 135 | J6: 2.165 | K6: ='UTILITY REPORT 1'!C7 -> 11 | L6: =E6*F6+G6*H6+#REF!*#REF!+I6*J6 -> #REF!
A7: Serengeti | B7: =B6+1 -> 6 | C7: 7 | D7: 2021 | E7: ='UTILITY REPORT 1'!F8 -> 4145 | F7: =('UTILITY REPORT 1'!E8*'UTILITY REPORT 1'!D8)/'UTILITY REPORT 1'!F8 -> 0.40270929 | G7: =IF('Utility summery'!M11<0,"0",'Utility summery'!M11) -> 116.776 | H7: 0 | I7: =IF('UTILITY REPORT 1'!G8<0,"0",'UTILITY REPORT 1'!G8) -> 124 | J7: 2.165 | K7: ='UTILITY REPORT 1'!C8 -> 14 | L7: =E7*F7+G7*H7+#REF!*#REF!+I7*J7 -> #REF!
A8: Serengeti | B8: =B7+1 -> 7 | C8: 7 | D8: 2021 | E8: ='UTILITY REPORT 1'!F9 -> 4675 | F8: =('UTILITY REPORT 1'!E9*'UTILITY REPORT 1'!D9)/'UTILITY REPORT 1'!F9 -> 0.40618396 | G8: =IF('Utility summery'!M12<0,"0",'Utility summery'!M12) -> 108.328 | H8: 0 | I8: =IF('UTILITY REPORT 1'!G9<0,"0",'UTILITY REPORT 1'!G9) -> 114 | J8: 2.165 | K8: ='UTILITY REPORT 1'!C9 -> 29 | L8: =E8*F8+G8*H8+#REF!*#REF!+I8*J8 -> #REF!
A9: Serengeti | B9: =B8+1 -> 8 | C9: 7 | D9: 2021 | E9: ='UTILITY REPORT 1'!F10 -> 4550 | F9: =('UTILITY REPORT 1'!E10*'UTILITY REPORT 1'!D10)/'UTILITY REPORT 1'!F10 -> 0.41006374 | G9: =IF('Utility summery'!M13<0,"0",'Utility summery'!M13) -> 112.376 | H9: 0 | I9: =IF('UTILITY REPORT 1'!G10<0,"0",'UTILITY REPORT 1'!G10) -> 94 | J9: 2.165 | K9: ='UTILITY REPORT 1'!C10 -> 35 | L9: =E9*F9+G9*H9+#REF!*#REF!+I9*J9 -> #REF!
A10: Serengeti | B10: =B9+1 -> 9 | C10: 7 | D10: 2021 | E10: ='UTILITY REPORT 1'!F11 -> 4263 | F10: =('UTILITY REPORT 1'!E11*'UTILITY REPORT 1'!D11)/'UTILITY REPORT 1'!F11 -> 0.4239315 | G10: =IF('Utility summery'!M14<0,"0",'Utility summery'!M14) -> 103.4 | H10: 0 | I10: =IF('UTILITY REPORT 1'!G11<0,"0",'UTILITY REPORT 1'!G11) -> 108 | J10: 2.165 | K10: ='UTILITY REPORT 1'!C11 -> 39 | L10: =E10*F10+G10*H10+#REF!*#REF!+I10*J10 -> #REF!
A11: Serengeti | B11: =B10+1 -> 10 | C11: 7 | D11: 2021 | E11: ='UTILITY REPORT 1'!F12 -> 4506 | F11: =('UTILITY REPORT 1'!E12*'UTILITY REPORT 1'!D12)/'UTILITY REPORT 1'!F12 -> 0.41897026 | G11: =IF('Utility summery'!M15<0,"0",'Utility summery'!M15) -> 117.304 | H11: 0 | I11: =IF('UTILITY REPORT 1'!G12<0,"0",'UTILITY REPORT 1'!G12) -> 116 | J11: 2.165 | K11: ='UTILITY REPORT 1'!C12 -> 32 | L11: =E11*F11+G11*H11+#REF!*#REF!+I11*J11 -> #REF!
A12: Serengeti | B12: =B11+1 -> 11 | C12: 7 | D12: 2021 | E12: ='UTILITY REPORT 1'!F13 -> 4459 | F12: =('UTILITY REPORT 1'!E13*'UTILITY REPORT 1'!D13)/'UTILITY REPORT 1'!F13 -> 0.41547432 | G12: =IF('Utility summery'!M16<0,"0",'Utility summery'!M16) -> 115.676 | H12: 0 | I12: =IF('UTILITY REPORT 1'!G13<0,"0",'UTILITY REPORT 1'!G13) -> 116 | J12: 2.165 | K12: ='UTILITY REPORT 1'!C13 -> 31 | L12: =E12*F12+G12*H12+#REF!*#REF!+I12*J12 -> #REF!
A13: Serengeti | B13: =B12+1 -> 12 | C13: 7 | D13: 2021 | E13: ='UTILITY REPORT 1'!F14 -> 4438 | F13: =('UTILITY REPORT 1'!E14*'UTILITY REPORT 1'!D14)/'UTILITY REPORT 1'!F14 -> 0.37453132 | G13: =IF('Utility summery'!M17<0,"0",'Utility summery'!M17) -> 126.984 | H13: 0 | I13: =IF('UTILITY REPORT 1'!G14<0,"0",'UTILITY REPORT 1'!G14) -> 109 | J13: 2.165 | K13: ='UTILITY REPORT 1'!C14 -> 32 | L13: =E13*F13+G13*H13+#REF!*#REF!+I13*J13 -> #REF!
A14: Serengeti | B14: =B13+1 -> 13 | C14: 7 | D14: 2021 | E14: ='UTILITY REPORT 1'!F15 -> 4300 | F14: =('UTILITY REPORT 1'!E15*'UTILITY REPORT 1'!D15)/'UTILITY REPORT 1'!F15 -> 0.42904884 | G14: =IF('Utility summery'!M18<0,"0",'Utility summery'!M18) -> 117.876 | H14: 0 | I14: =IF('UTILITY REPORT 1'!G15<0,"0",'UTILITY REPORT 1'!G15) -> 105 | J14: 2.165 | K14: ='UTILITY REPORT 1'!C15 -> 19 | L14: =E14*F14+G14*H14+#REF!*#REF!+I14*J14 -> #REF!
... A30: Serengeti | B30: =B29+1 -> 29 | C30: 7 | D30: 2021 | E30: ='UTILITY REPORT 1'!F31 -> 3985 | F30: =('UTILITY REPORT 1'!E31*'UTILITY REPORT 1'!D31)/'UTILITY REPORT 1'!F31 -> 0.49988959 | G30: =IF('Utility summery'!M34<0,"0",'Utility summery'!M34) -> 175.648 | H30: 0 | I30: =IF('UTILITY REPORT 1'!G31<0,"0",'UTILITY REPORT 1'!G31) -> 111 | J30: 2.165 | K30: ='UTILITY REPORT 1'!C31 -> 0 | L30: =E30*F30+G30*H30+#REF!*#REF!+I30*J30 -> #REF!
A31: Serengeti | B31: 30 | C31: 7 | D31: 2021 | E31: ='UTILITY REPORT 1'!F32 -> 4484 | F31: =('UTILITY REPORT 1'!E32*'UTILITY REPORT 1'!D32)/'UTILITY REPORT 1'!F32 -> 0.40646075 | G31: =IF('Utility summery'!M35<0,"0",'Utility summery'!M35) -> 171.292 | H31: 0 | I31: =IF('UTILITY REPORT 1'!G32<0,"0",'UTILITY REPORT 1'!G32) -> 105 | J31: 2.165 | K31: ='UTILITY REPORT 1'!C32 -> 0 | L31: =E31*F31+G31*H31+#REF!*#REF!+I31*J31 -> #REF!
A32: Serengeti | B32: 31 | C32: 7 | D32: 2021 | E32: ='UTILITY REPORT 1'!F33 -> 4015 | F32: =('UTILITY REPORT 1'!E33*'UTILITY REPORT 1'!D33)/'UTILITY REPORT 1'!F33 -> 0.41843587 | G32: =IF('Utility summery'!M36<0,"0",'Utility summery'!M36) -> 111.232 | H32: 0 | I32: =IF('UTILITY REPORT 1'!G33<0,"0",'UTILITY REPORT 1'!G33) -> 99 | J32: 2.165 | K32: ='UTILITY REPORT 1'!C33 -> 0

Sheet Submetering
A1: Site Name | B1: Day | C1: Month | D1: Year | E1: Transport Consumption (LT) | F1: Generators Consumption (LT) | G1: Total Electricity Kwh | H1: Kitchen (KWh) | I1: Laundry (KWh) | J1: STP (M3) | K1: RO prodution (M3) | L1: Amani Restaurant (M3) | M1: Kitchen (M3) | N1: Laundry (M3) | O1: Laundry (M3) | P1: Total water Consumption (M3) | Q1: Borehole #1 (M3) | R1: Borehole #2 (M3) | S1: Borehole #3 (M3) | T1: Borehole #4 (M3) | U1: Borehole #5 (M3) | V1: Borehole #6 (M3) | W1: Total Bore holes production (M3) | X1: Room Nights
A2: Serengeti | B2: 1 | C2: 7 | D2: 2021 | E2: ='UTILITY REPORT 1'!I3 -> 0 | F2: ='UTILITY REPORT 1'!E3 -> 1799.58 | G2: ='UTILITY REPORT 1'!F3 -> 4264 | H2: =IF('Kit report'!F4<0,"0",'Kit report'!F4) -> 1128180 | I2: =IF('Kit report'!X4<0,"0",'Kit report'!X4) -> 1647280 | J2: =IF('Utility summery'!H6<0,"0",'Utility summery'!H6) -> 33 | K2: =IF('UTILITY REPORT 1'!H3<0,"0",'UTILITY REPORT 1'!H3) -> 80 | L2: ='Water-Meter'!K6 -> 2 | M2: ='Water-Meter'!H6 -> 0 | N2: ='Water-Meter'!Q6 -> 3 | O2: =K2*E2+H2*I2+#REF!*#REF!+J2*L2 -> #REF! | P2: ='Water-Meter'!E6 -> 109 | Q2: =IF('Water-Meter'!U6<0,"0",'Water-Meter'!U6) -> 48 | R2: =IF('Water-Meter'!X6<0,"0",'Water-Meter'!X6) -> 0 | S2: =IF('Water-Meter'!AA6<0,"0",'Water-Meter'!AA6) -> 35 | T2: =IF('Water-Meter'!AD6<0,"0",'Water-Meter'!AD6) -> 16 | U2: =IF('Water-Meter'!AG6<0,"0",'Water-Meter'!AG6) -> 0 | V2: =IF('Water-Meter'!AJ6<0,"0",'Water-Meter'!AJ6) -> 32 | W2: ='Water-Meter'!AN6 -> 131 | X2: =Total!K2 -> 23
A3: Serengeti | B3: =B2+1 -> 2 | C3: 7 | D3: 2021 | E3: ='UTILITY REPORT 1'!I4 -> 324.81 | F3: ='UTILITY REPORT 1'!E4 -> 1691.92 | G3: ='UTILITY REPORT 1'!F4 -> 4274 | H3: =IF('Kit report'!F5<0,"0",'Kit report'!F5) -> 324 | I3: =IF('Kit report'!X5<0,"0",'Kit report'!X5) -> 560 | J3: =IF('Utility summery'!H7<0,"0",'Utility summery'!H7) -> 35 | K3: =IF('UTILITY REPORT 1'!H4<0,"0",'UTILITY REPORT 1'!H4) -> 60 | L3: ='Water-Meter'!K7 -> 2 | M3: ='Water-Meter'!H7 -> 0 | N3: ='Water-Meter'!Q7 -> 7 | O3: =K3*E3+H3*I3+#REF!*#REF!+J3*L3 -> #REF! | P3: ='Water-Meter'!E7 -> 101 | Q3: =IF('Water-Meter'!U7<0,"0",'Water-Meter'!U7) -> 79 | R3: =IF('Water-Meter'!X7<0,"0",'Water-Meter'!X7) -> 0 | S3: =IF('Water-Meter'!AA7<0,"0",'Water-Meter'!AA7) -> 33 | T3: =IF('Water-Meter'!AD7<0,"0",'Water-Meter'!AD7) -> 15 | U3: =IF('Water-Meter'!AG7<0,"0",'Water-Meter'!AG7) -> 0 | V3: =IF('Water-Meter'!AJ7<0,"0",'Water-Meter'!AJ7) -> 29 | W3: ='Water-Meter'!AN7 -> 156 | X3: =Total!K3 -> 27
A4: Serengeti | B4: =B3+1 -> 3 | C4: 7 | D4: 2021 | E4: ='UTILITY REPORT 1'!I5 -> 0 | F4: ='UTILITY REPORT 1'!E5 -> 1810.5 | G4: ='UTILITY REPORT 1'!F5 -> 4467 | H4: =IF('Kit report'!F6<0,"0",'Kit report'!F6) -> 360 | I4: =IF('Kit report'!X6<0,"0",'Kit report'!X6) -> 540 | J4: =IF('Utility summery'!H8<0,"0",'Utility summery'!H8) -> 10 | K4: =IF('UTILITY REPORT 1'!H5<0,"0",'UTILITY REPORT 1'!H5) -> 55 | L4: ='Water-Meter'!K8 -> 3 | M4: ='Water-Meter'!H8 -> 0 | N4: ='Water-Meter'!Q8 -> 8 | O4: =K4*E4+H4*I4+#REF!*#REF!+J4*L4 -> #REF! | P4: ='Water-Meter'!E8 -> 94 | Q4: =IF('Water-Meter'!U8<0,"0",'Water-Meter'!U8) -> 89 | R4: =IF('Water-Meter'!X8<0,"0",'Water-Meter'!X8) -> 0 | S4: =IF('Water-Meter'!AA8<0,"0",'Water-Meter'!AA8) -> 37 | T4: =IF('Water-Meter'!AD8<0,"0",'Water-Meter'!AD8) -> 17 | U4: =IF('Water-Meter'!AG8<0,"0",'Water-Meter'!AG8) -> 0 | V4: =IF('Water-Meter'!AJ8<0,"0",'Water-Meter'!AJ8) -> 32 | W4: ='Water-Meter'!AN8 -> 175 | X4: =Total!K4 -> 20
A5: Serengeti | B5: =B4+1 -> 4 | C5: 7 | D5: 2021 | E5: ='UTILITY REPORT 1'!I6 -> 233.22 | F5: ='UTILITY REPORT 1'!E6 -> 1652.34 | G5: ='UTILITY REPORT 1'!F6 -> 4106 | H5: =IF('Kit report'!F7<0,"0",'Kit report'!F7) -> 324 | I5: =IF('Kit report'!X7<0,"0",'Kit report'!X7) -> 660 | J5: =IF('Utility summery'!H9<0,"0",'Utility summery'!H9) -> 58 | K5: =IF('UTILITY REPORT 1'!H6<0,"0",'UTILITY REPORT 1'!H6) -> 48 | L5: ='Water-Meter'!K9 -> 2 | M5: ='Water-Meter'!H9 -> 0 | N5: ='Water-Meter'!Q9 -> 10 | O5: =K5*E5+H5*I5+#REF!*#REF!+J5*L5 -> #REF! | P5: ='Water-Meter'!E9 -> 98 | Q5: =IF('Water-Meter'!U9<0,"0",'Water-Meter'!U9) -> 80 | R5: =IF('Water-Meter'!X9<0,"0",'Water-Meter'!X9) -> 0 | S5: =IF('Water-Meter'!AA9<0,"0",'Water-Meter'!AA9) -> 33 | T5: =IF('Water-Meter'!AD9<0,"0",'Water-Meter'!AD9) -> 15 | U5: =IF('Water-Meter'!AG9<0,"0",'Water-Meter'!AG9) -> 0 | V5: =IF('Water-Meter'!AJ9<0,"0",'Water-Meter'!AJ9) -> 30 | W5: ='Water-Meter'!AN9 -> 158 | X5: =Total!K5 -> 14
A6: Serengeti | B6: =B5+1 -> 5 | C6: 7 | D6: 2021 | E6: ='UTILITY REPORT 1'!I7 -> 148.61 | F6: ='UTILITY REPORT 1'!E7 -> 1644.32 | G6: ='UTILITY REPORT 1'!F7 -> 4026 | H6: =IF('Kit report'!F8<0,"0",'Kit report'!F8) -> 264 | I6: =IF('Kit report'!X8<0,"0",'Kit report'!X8) -> 660 | J6: =IF('Utility summery'!H10<0,"0",'Utility summery'!H10) -> 44 | K6: =IF('UTILITY REPORT 1'!H7<0,"0",'UTILITY REPORT 1'!H7) -> 50 | L6: ='Water-Meter'!K10 -> 1 | M6: ='Water-Meter'!H10 -> 0 | N6: ='Water-Meter'!Q10 -> 7 | O6: =K6*E6+H6*I6+#REF!*#REF!+J6*L6 -> #REF! | P6: ='Water-Meter'!E10 -> 135 | Q6: =IF('Water-Meter'!U10<0,"0",'Water-Meter'!U10) -> 49 | R6: =IF('Water-Meter'!X10<0,"0",'Water-Meter'!X10) -> 0 | S6: =IF('Water-Meter'!AA10<0,"0",'Water-Meter'!AA10) -> 34 | T6: =IF('Water-Meter'!AD10<0,"0",'Water-Meter'!AD10) -> 17 | U6: =IF('Water-Meter'!AG10<0,"0",'Water-Meter'!AG10) -> 0 | V6: =IF('Water-Meter'!AJ10<0,"0",'Water-Meter'!AJ10) -> 31 | W6: ='Water-Meter'!AN10 -> 131 | X6: =Total!K6 -> 11
A7: Serengeti | B7: =B6+1 -> 6 | C7: 7 | D7: 2021 | E7: ='UTILITY REPORT 1'!I8 -> 199.93 | F7: ='UTILITY REPORT 1'!E8 -> 1669.23 | G7: ='UTILITY REPORT 1'!F8 -> 4145 | H7: =IF('Kit report'!F9<0,"0",'Kit report'!F9) -> 276 | I7: =IF('Kit report'!X9<0,"0",'Kit report'!X9) -> 600 | J7: =IF('Utility summery'!H11<0,"0",'Utility summery'!H11) -> 52 | K7: =IF('UTILITY REPORT 1'!H8<0,"0",'UTILITY REPORT 1'!H8) -> 113 | L7: ='Water-Meter'!K11 -> 2 | M7: ='Water-Meter'!H11 -> 0 | N7: ='Water-Meter'!Q11 -> 10 | O7: =K7*E7+H7*I7+#REF!*#REF!+J7*L7 -> #REF! | P7: ='Water-Meter'!E11 -> 124 | Q7: =IF('Water-Meter'!U11<0,"0",'Water-Meter'!U11) -> 0 | R7: =IF('Water-Meter'!X11<0,"0",'Water-Meter'!X11) -> 0 | S7: =IF('Water-Meter'!AA11<0,"0",'Water-Meter'!AA11) -> 35 | T7: =IF('Water-Meter'!AD11<0,"0",'Water-Meter'!AD11) -> 16 | U7: =IF('Water-Meter'!AG11<0,"0",'Water-Meter'!AG11) -> 0 | V7: =IF('Water-Meter'!AJ11<0,"0",'Water-Meter'!AJ11) -> 31 | W7: ='Water-Meter'!AN11 -> 82 | X7: =Total!K7 -> 14
A8: Serengeti | B8: =B7+1 -> 7 | C8: 7 | D8: 2021 | E8: ='UTILITY REPORT 1'!I9 -> 168.95 | F8: ='UTILITY REPORT 1'!E9 -> 1898.91 | G8: ='UTILITY REPORT 1'!F9 -> 4675 | H8: =IF('Kit report'!F10<0,"0",'Kit report'!F10) -> 264 | I8: =IF('Kit report'!X10<0,"0",'Kit report'!X10) -> 800 | J8: =IF('Utility summery'!H12<0,"0",'Utility summery'!H12) -> 52 | K8: =IF('UTILITY REPORT 1'!H9<0,"0",'UTILITY REPORT 1'!H9) -> 121 | L8: ='Water-Meter'!K12 -> 2 | M8: ='Water-Meter'!H12 -> 0 | N8: ='Water-Meter'!Q12 -> 11 | O8: =K8*E8+H8*I8+#REF!*#REF!+J8*L8 -> #REF! | P8: ='Water-Meter'!E12 -> 114 | Q8: =IF('Water-Meter'!U12<0,"0",'Water-Meter'!U12) -> 86 | R8: =IF('Water-Meter'!X12<0,"0",'Water-Meter'!X12) -> 0 | S8: =IF('Water-Meter'!AA12<0,"0",'Water-Meter'!AA12) -> 33 | T8: =IF('Water-Meter'!AD12<0,"0",'Water-Meter'!AD12) -> 16 | U8: =IF('Water-Meter'!AG12<0,"0",'Water-Meter'!AG12) -> 0 | V8: =IF('Water-Meter'!AJ12<0,"0",'Water-Meter'!AJ12) -> 32 | W8: ='Water-Meter'!AN12 -> 167 | X8: =Total!K8 -> 29
A9: Serengeti | B9: =B8+1 -> 8 | C9: 7 | D9: 2021 | E9: ='UTILITY REPORT 1'!I10 -> 47 | F9: ='UTILITY REPORT 1'!E10 -> 1865.79 | G9: ='UTILITY REPORT 1'!F10 -> 4550 | H9: =IF('Kit report'!F11<0,"0",'Kit report'!F11) -> 252 | I9: =IF('Kit report'!X11<0,"0",'Kit report'!X11) -> 760 | J9: =IF('Utility summery'!H13<0,"0",'Utility summery'!H13) -> 57 | K9: =IF('UTILITY REPORT 1'!H10<0,"0",'UTILITY REPORT 1'!H10) -> 201 | L9: ='Water-Meter'!K13 -> 1 | M9: ='Water-Meter'!H13 -> 0 | N9: ='Water-Meter'!Q13 -> 9 | O9: =K9*E9+H9*I9+#REF!*#REF!+J9*L9 -> #REF! | P9: ='Water-Meter'!E13 -> 94 | Q9: =IF('Water-Meter'!U13<0,"0",'Water-Meter'!U13) -> 82 | R9: =IF('Water-Meter'!X13<0,"0",'Water-Meter'!X13) -> 0 | S9: =IF('Water-Meter'!AA13<0,"0",'Water-Meter'!AA13) -> 33 | T9: =IF('Water-Meter'!AD13<0,"0",'Water-Meter'!AD13) -> 16 | U9: =IF('Water-Meter'!AG13<0,"0",'Water-Meter'!AG13) -> 0 | V9: =IF('Water-Meter'!AJ13<0,"0",'Water-Meter'!AJ13) -> 33 | W9: ='Water-Meter'!AN13 -> 164 | X9: =Total!K9 -> 35
A10: Serengeti | B10: =B9+1 -> 9 | C10: 7 | D10: 2021 | E10: ='UTILITY REPORT 1'!I11 -> 456 | F10: ='UTILITY REPORT 1'!E11 -> 1807.22 | G10: ='UTILITY REPORT 1'!F11 -> 4263 | H10: =IF('Kit report'!F12<0,"0",'Kit report'!F12) -> 288 | I10: =IF('Kit report'!X12<0,"0",'Kit report'!X12) -> 880 | J10: =IF('Utility summery'!H14<0,"0",'Utility summery'!H14) -> 59 | K10: =IF('UTILITY REPORT 1'!H11<0,"0",'UTILITY REPORT 1'!H11) -> 1 | L10: ='Water-Meter'!K14 -> 2 | M10: ='Water-Meter'!H14 -> 0 | N10: ='Water-Meter'!Q14 -> 10 | O10: =K10*E10+H10*I10+#REF!*#REF!+J10*L10 -> #REF! | P10: ='Water-Meter'!E14 -> 108 | Q10: =IF('Water-Meter'!U14<0,"0",'Water-Meter'!U14) -> 83 | R10: =IF('Water-Meter'!X14<0,"0",'Water-Meter'!X14) -> 0 | S10: =IF('Water-Meter'!AA14<0,"0",'Water-Meter'!AA14) -> 34 | T10: =IF('Water-Meter'!AD14<0,"0",'Water-Meter'!AD14) -> 17 | U10: =IF('Water-Meter'!AG14<0,"0",'Water-Meter'!AG14) -> 0 | V10: =IF('Water-Meter'!AJ14<0,"0",'Water-Meter'!AJ14) -> 33 | W10: ='Water-Meter'!AN14 -> 167 | X10: =Total!K10 -> 39
A11: Serengeti | B11: =B10+1 -> 10 | C11: 7 | D11: 2021 | E11: ='UTILITY REPORT 1'!I12 -> 644.97 | F11: ='UTILITY REPORT 1'!E12 -> 1887.88 | G11: ='UTILITY REPORT 1'!F12 -> 4506 | H11: =IF('Kit report'!F13<0,"0",'Kit report'!F13) -> 240 | I11: =IF('Kit report'!X13<0,"0",'Kit report'!X13) -> 820 | J11: =IF('Utility summery'!H15<0,"0",'Utility summery'!H15) -> 56 | K11: =IF('UTILITY REPORT 1'!H12<0,"0",'UTILITY REPORT 1'!H12) -> 70 | L11: ='Water-Meter'!K15 -> 2 | M11: ='Water-Meter'!H15 -> 0 | N11: ='Water-Meter'!Q15 -> 11 | O11: =K11*E11+H11*I11+#REF!*#REF!+J11*L11 -> #REF! | P11: ='Water-Meter'!E15 -> 116 | Q11: =IF('Water-Meter'!U15<0,"0",'Water-Meter'!U15) -> 81 | R11: =IF('Water-Meter'!X15<0,"0",'Water-Meter'!X15) -> 0 | S11: =IF('Water-Meter'!AA15<0,"0",'Water-Meter'!AA15) -> 40 | T11: =IF('Water-Meter'!AD15<0,"0",'Water-Meter'!AD15) -> 16 | U11: =IF('Water-Meter'!AG15<0,"0",'Water-Meter'!AG15) -> 0 | V11: =IF('Water-Meter'!AJ15<0,"0",'Water-Meter'!AJ15) -> 35 | W11: ='Water-Meter'!AN15 -> 172 | X11: =Total!K11 -> 32
A12: Serengeti | B12: =B11+1 -> 11 | C12: 7 | D12: 2021 | E12: ='UTILITY REPORT 1'!I13 -> 608.62 | F12: ='UTILITY REPORT 1'!E13 -> 1852.6 | G12: ='UTILITY REPORT 1'!F13 -> 4459 | H12: =IF('Kit report'!F14<0,"0",'Kit report'!F14) -> 276 | I12: =IF('Kit report'!X14<0,"0",'Kit report'!X14) -> 900 | J12: =IF('Utility summery'!H16<0,"0",'Utility summery'!H16) -> 0 | K12: =IF('UTILITY REPORT 1'!H13<0,"0",'UTILITY REPORT 1'!H13) -> 41 | L12: ='Water-Meter'!K16 -> 6 | M12: ='Water-Meter'!H16 -> 0 | N12: ='Water-Meter'!Q16 -> 11 | O12: =K12*E12+H12*I12+#REF!*#REF!+J12*L12 -> #REF! | P12: ='Water-Meter'!E16 -> 116 | Q12: =IF('Water-Meter'!U16<0,"0",'Water-Meter'!U16) -> 82 | R12: =IF('Water-Meter'!X16<0,"0",'Water-Meter'!X16) -> 0 | S12: =IF('Water-Meter'!AA16<0,"0",'Water-Meter'!AA16) -> 34 | T12: =IF('Water-Meter'!AD16<0,"0",'Water-Meter'!AD16) -> 14 | U12: =IF('Water-Meter'!AG16<0,"0",'Water-Meter'!AG16) -> 0 | V12: =IF('Water-Meter'!AJ16<0,"0",'Water-Meter'!AJ16) -> 24 | W12: ='Water-Meter'!AN16 -> 154 | X12: =Total!K12 -> 31
A13: Serengeti | B13: =B12+1 -> 12 | C13: 7 | D13: 2021 | E13: ='UTILITY REPORT 1'!I14 -> 677.99 | F13: ='UTILITY REPORT 1'!E14 -> 1662.17 | G13: ='UTILITY REPORT 1'!F14 -> 4438 | H13: =IF('Kit report'!F15<0,"0",'Kit report'!F15) -> 264 | I13: =IF('Kit report'!X15<0,"0",'Kit report'!X15) -> 1020 | J13: =IF('Utility summery'!H17<0,"0",'Utility summery'!H17) -> 1 | K13: =IF('UTILITY REPORT 1'!H14<0,"0",'UTILITY REPORT 1'!H14) -> 40 | L13: ='Water-Meter'!K17 -> 2 | M13: ='Water-Meter'!H17 -> 0 | N13: ='Water-Meter'!Q17 -> 10 | O13: =K13*E13+H13*I13+#REF!*#REF!+J13*L13 -> #REF! | P13: ='Water-Meter'!E17 -> 109 | Q13: =IF('Water-Meter'!U17<0,"0",'Water-Meter'!U17) -> 86 | R13: =IF('Water-Meter'!X17<0,"0",'Water-Meter'!X17) -> 0 | S13: =IF('Water-Meter'!AA17<0,"0",'Water-Meter'!AA17) -> 37 | T13: =IF('Water-Meter'!AD17<0,"0",'Water-Meter'!AD17) -> 15 | U13: =IF('Water-Meter'!AG17<0,"0",'Water-Meter'!AG17) -> 0 | V13: =IF('Water-Meter'!AJ17<0,"0",'Water-Meter'!AJ17) -> 33 | W13: ='Water-Meter'!AN17 -> 171 | X13: =Total!K13 -> 32
A14: Serengeti | B14: =B13+1 -> 13 | C14: 7 | D14: 2021 | E14: ='UTILITY REPORT 1'!I15 -> 204.13 | F14: ='UTILITY REPORT 1'!E15 -> 1844.91 | G14: ='UTILITY REPORT 1'!F15 -> 4300 | H14: =IF('Kit report'!F16<0,"0",'Kit report'!F16) -> 276 | I14: =IF('Kit report'!X16<0,"0",'Kit report'!X16) -> 960 | J14: =IF('Utility summery'!H18<0,"0",'Utility summery'!H18) -> 60 | K14: =IF('UTILITY REPORT 1'!H15<0,"0",'UTILITY REPORT 1'!H15) -> 37 | L14: ='Water-Meter'!K18 -> 2 | M14: ='Water-Meter'!H18 -> 0 | N14: ='Water-Meter'!Q18 -> 12 | O14: =K14*E14+H14*I14+#REF!*#REF!+J14*L14 -> #REF! | P14: ='Water-Meter'!E18 -> 105 | Q14: =IF('Water-Meter'!U18<0,"0",'Water-Meter'!U18) -> 83 | R14: =IF('Water-Meter'!X18<0,"0",'Water-Meter'!X18) -> 0 | S14: =IF('Water-Meter'!AA18<0,"0",'Water-Meter'!AA18) -> 36 | T14: =IF('Water-Meter'!AD18<0,"0",'Water-Meter'!AD18) -> 15 | U14: =IF('Water-Meter'!AG18<0,"0",'Water-Meter'!AG18) -> 0 | V14: =IF('Water-Meter'!AJ18<0,"0",'Water-Meter'!AJ18) -> 31 | W14: ='Water-Meter'!AN18 -> 165 | X14: =Total!K14 -> 19
... A25: Serengeti | B25: =B24+1 -> 24 | C25: 7 | D25: 2021 | E25: ='UTILITY REPORT 1'!I26 -> 442.98 | F25: ='UTILITY REPORT 1'!E26 -> 2014.73 | G25: ='UTILITY REPORT 1'!F26 -> 4879 | H25: =IF('Kit report'!F27<0,"0",'Kit report'!F27) -> 348 | I25: =IF('Kit report'!X27<0,"0",'Kit report'!X27) -> 740 | J25: =IF('Utility summery'!H29<0,"0",'Utility summery'!H29) -> 67 | K25: =IF('UTILITY REPORT 1'!H26<0,"0",'UTILITY REPORT 1'!H26) -> 0 | L25: ='Water-Meter'!K29 -> 2 | M25: ='Water-Meter'!H29 -> 0 | N25: ='Water-Meter'!Q29 -> 11 | O25: =K25*E25+H25*I25+#REF!*#REF!+J25*L25 -> #REF! | P25: ='Water-Meter'!E29 -> 106 | Q25: =IF('Water-Meter'!U29<0,"0",'Water-Meter'!U29) -> 79 | R25: =IF('Water-Meter'!X29<0,"0",'Water-Meter'!X29) -> 0 | S25: =IF('Water-Meter'!AA29<0,"0",'Water-Meter'!AA29) -> 33 | T25: =IF('Water-Meter'!AD29<0,"0",'Water-Meter'!AD29) -> 17 | U25: =IF('Water-Meter'!AG29<0,"0",'Water-Meter'!AG29) -> 0 | V25: =IF('Water-Meter'!AJ29<0,"0",'Water-Meter'!AJ29) -> 29 | W25: ='Water-Meter'!AN29 -> 158 | X25: =Total!K25 -> 0
A26: Serengeti | B26: =B25+1 -> 25 | C26: 7 | D26: 2021 | E26: ='UTILITY REPORT 1'!I27 -> 259.79 | F26: ='UTILITY REPORT 1'!E27 -> 1869.09 | G26: ='UTILITY REPORT 1'!F27 -> 4599 | H26: =IF('Kit report'!F28<0,"0",'Kit report'!F28) -> 360 | I26: =IF('Kit report'!X28<0,"0",'Kit report'!X28) -> 800 | J26: =IF('Utility summery'!H30<0,"0",'Utility summery'!H30) -> 64 | K26: =IF('UTILITY REPORT 1'!H27<0,"0",'UTILITY REPORT 1'!H27) -> 81 | L26: ='Water-Meter'!K30 -> 2 | M26: ='Water-Meter'!H30 -> 0 | N26: ='Water-Meter'!Q30 -> 10 | O26: =K26*E26+H26*I26+#REF!*#REF!+J26*L26 -> #REF! | P26: ='Water-Meter'!E30 -> 106 | Q26: =IF('Water-Meter'!U30<0,"0",'Water-Meter'!U30) -> 82 | R26: =IF('Water-Meter'!X30<0,"0",'Water-Meter'!X30) -> 0 | S26: =IF('Water-Meter'!AA31<0,"0",'Water-Meter'!AA31) -> 35 | T26: =IF('Water-Meter'!AD30<0,"0",'Water-Meter'!AD30) -> 19 | U26: =IF('Water-Meter'!AG30<0,"0",'Water-Meter'!AG30) -> 0 | V26: =IF('Water-Meter'!AJ30<0,"0",'Water-Meter'!AJ30) -> 33 | W26: ='Water-Meter'!AN30 -> 169 | X26: =Total!K26 -> 0
A27: Serengeti | B27: =B26+1 -> 26 | C27: 7 | D27: 2021 | E27: ='UTILITY REPORT 1'!I28 -> 70.92 | F27: ='UTILITY REPORT 1'!E28 -> 1888.8 | G27: ='UTILITY REPORT 1'!F28 -> 4415 | H27: =IF('Kit report'!F29<0,"0",'Kit report'!F29) -> 276 | I27: =IF('Kit report'!X29<0,"0",'Kit report'!X29) -> 860 | J27: =IF('Utility summery'!H31<0,"0",'Utility summery'!H31) -> 58 | K27: =IF('UTILITY REPORT 1'!H28<0,"0",'UTILITY REPORT 1'!H28) -> 25 | L27: ='Water-Meter'!K31 -> 3 | M27: ='Water-Meter'!H31 -> 0 | N27: ='Water-Meter'!Q31 -> 10 | O27: =K27*E27+H27*I27+#REF!*#REF!+J27*L27 -> #REF! | P27: ='Water-Meter'!E31 -> 96 | Q27: =IF('Water-Meter'!U31<0,"0",'Water-Meter'!U31) -> 81 | R27: =IF('Water-Meter'!X31<0,"0",'Water-Meter'!X31) -> 0 | S27: =IF('Water-Meter'!#REF!<0,"0",'Water-Meter'!#REF!) -> #REF! | T27: =IF('Water-Meter'!AD31<0,"0",'Water-Meter'!AD31) -> 17 | U27: =IF('Water-Meter'!AG31<0,"0",'Water-Meter'!AG31) -> 0 | V27: =IF('Water-Meter'!AJ31<0,"0",'Water-Meter'!AJ31) -> 31 | W27: ='Water-Meter'!AN31 -> 164 | X27: =Total!K27 -> 0
A28: Serengeti | B28: =B27+1 -> 27 | C28: 7 | D28: 2021 | E28: ='UTILITY REPORT 1'!I29 -> 491.89 | F28: ='UTILITY REPORT 1'!E29 -> 1921.29 | G28: ='UTILITY REPORT 1'!F29 -> 4607 | H28: =IF('Kit report'!F30<0,"0",'Kit report'!F30) -> 300 | I28: =IF('Kit report'!X30<0,"0",'Kit report'!X30) -> 700 | J28: =IF('Utility summery'!H32<0,"0",'Utility summery'!H32) -> 47 | K28: =IF('UTILITY REPORT 1'!H29<0,"0",'UTILITY REPORT 1'!H29) -> 93 | L28: ='Water-Meter'!K32 -> 2 | M28: ='Water-Meter'!H32 -> 0 | N28: ='Water-Meter'!Q32 -> 8 | O28: =K28*E28+H28*I28+#REF!*#REF!+J28*L28 -> #REF! | P28: ='Water-Meter'!E32 -> 103 | Q28: =IF('Water-Meter'!U32<0,"0",'Water-Meter'!U32) -> 80 | R28: =IF('Water-Meter'!X32<0,"0",'Water-Meter'!X32) -> 0 | S28: =IF('Water-Meter'!AA32<0,"0",'Water-Meter'!AA32) -> 35 | T28: =IF('Water-Meter'!AD32<0,"0",'Water-Meter'!AD32) -> 17 | U28: =IF('Water-Meter'!AG32<0,"0",'Water-Meter'!AG32) -> 0 | V28: =IF('Water-Meter'!AJ32<0,"0",'Water-Meter'!AJ32) -> 31 | W28: ='Water-Meter'!AN32 -> 163 | X28: =Total!K28 -> 0
A29: Serengeti | B29: =B28+1 -> 28 | C29: 7 | D29: 2021 | E29: ='UTILITY REPORT 1'!I30 -> 147.47 | F29: ='UTILITY REPORT 1'!E30 -> 1696.62 | G29: ='UTILITY REPORT 1'!F30 -> 4642 | H29: =IF('Kit report'!F31<0,"0",'Kit report'!F31) -> 324 | I29: =IF('Kit report'!X31<0,"0",'Kit report'!X31) -> 680 | J29: =IF('Utility summery'!H33<0,"0",'Utility summery'!H33) -> 53 | K29: =IF('UTILITY REPORT 1'!H30<0,"0",'UTILITY REPORT 1'!H30) -> 161 | L29: ='Water-Meter'!K33 -> 3 | M29: ='Water-Meter'!H33 -> 0 | N29: ='Water-Meter'!Q33 -> 9 | O29: =K29*E29+H29*I29+#REF!*#REF!+J29*L29 -> #REF! | P29: ='Water-Meter'!E33 -> 115 | Q29: =IF('Water-Meter'!U33<0,"0",'Water-Meter'!U33) -> 13 | R29: =IF('Water-Meter'!X33<0,"0",'Water-Meter'!X33) -> 0 | S29: =IF('Water-Meter'!AA33<0,"0",'Water-Meter'!AA33) -> 34 | T29: =IF('Water-Meter'!AD33<0,"0",'Water-Meter'!AD33) -> 17 | U29: =IF('Water-Meter'!AG33<0,"0",'Water-Meter'!AG33) -> 0 | V29: =IF('Water-Meter'!AJ33<0,"0",'Water-Meter'!AJ33) -> 32 | W29: ='Water-Meter'!AN33 -> 96 | X29: =Total!K29 -> 0
A30: Serengeti | B30: =B29+1 -> 29 | C30: 7 | D30: 2021 | E30: ='UTILITY REPORT 1'!I31 -> 246.95 | F30: ='UTILITY REPORT 1'!E31 -> 1992.06 | G30: ='UTILITY REPORT 1'!F31 -> 3985 | H30: =IF('Kit report'!F32<0,"0",'Kit report'!F32) -> 336 | I30: =IF('Kit report'!X32<0,"0",'Kit report'!X32) -> 600 | J30: =IF('Utility summery'!H34<0,"0",'Utility summery'!H34) -> 51 | K30: =IF('UTILITY REPORT 1'!H31<0,"0",'UTILITY REPORT 1'!H31) -> 109 | L30: ='Water-Meter'!K34 -> 2 | M30: ='Water-Meter'!H34 -> 0 | N30: ='Water-Meter'!Q34 -> 10 | O30: =K30*E30+H30*I30+#REF!*#REF!+J30*L30 -> #REF! | P30: ='Water-Meter'!E34 -> 111 | Q30: =IF('Water-Meter'!U34<0,"0",'Water-Meter'!U34) -> 72 | R30: =IF('Water-Meter'!X34<0,"0",'Water-Meter'!X34) -> 0 | S30: =IF('Water-Meter'!AA34<0,"0",'Water-Meter'!AA34) -> 34 | T30: =IF('Water-Meter'!AD34<0,"0",'Water-Meter'!AD34) -> 16 | U30: =IF('Water-Meter'!AG34<0,"0",'Water-Meter'!AG34) -> 0 | V30: =IF('Water-Meter'!AJ34<0,"0",'Water-Meter'!AJ34) -> 31 | W30: ='Water-Meter'!AN34 -> 153 | X30: =Total!K30 -> 0
A31: Serengeti | B31: 30 | C31: 7 | D31: 2021 | E31: ='UTILITY REPORT 1'!I32 -> 369 | F31: ='UTILITY REPORT 1'!E32 -> 1822.57 | G31: ='UTILITY REPORT 1'!F32 -> 4484 | H31: =IF('Kit report'!F33<0,"0",'Kit report'!F33) -> 300 | I31: =IF('Kit report'!X33<0,"0",'Kit report'!X33) -> 660 | J31: =IF('Utility summery'!H35<0,"0",'Utility summery'!H35) -> 47 | K31: =IF('UTILITY REPORT 1'!H32<0,"0",'UTILITY REPORT 1'!H32) -> 64 | L31: ='Water-Meter'!K35 -> 3 | M31: ='Water-Meter'!H35 -> 0 | N31: ='Water-Meter'!Q35 -> 10 | O31: =K31*E31+H31*I31+#REF!*#REF!+J31*L31 -> #REF! | P31: ='Water-Meter'!E35 -> 105 | Q31: =IF('Water-Meter'!U35<0,"0",'Water-Meter'!U35) -> 81 | R31: =IF('Water-Meter'!X35<0,"0",'Water-Meter'!X35) -> 0 | S31: =IF('Water-Meter'!AA35<0,"0",'Water-Meter'!AA35) -> 35 | T31: =IF('Water-Meter'!AD35<0,"0",'Water-Meter'!AD35) -> 20 | U31: =IF('Water-Meter'!AG35<0,"0",'Water-Meter'!AG35) -> 0 | V31: =IF('Water-Meter'!AJ35<0,"0",'Water-Meter'!AJ35) -> 31 | W31: ='Water-Meter'!AN35 -> 167 | X31: =Total!K31 -> 0
A32: Serengeti | B32: 31 | C32: 7 | D32: 2021 | E32: ='UTILITY REPORT 1'!I33 -> 376.24 | F32: ='UTILITY REPORT 1'!E33 -> 1680.02 | G32: ='UTILITY REPORT 1'!F33 -> 4015 | H32: =IF('Kit report'!F34<0,"0",'Kit report'!F34) -> 336 | I32: =IF('Kit report'!X34<0,"0",'Kit report'!X34) -> 760 | J32: =IF('Utility summery'!H36<0,"0",'Utility summery'!H36) -> 50 | K32: =IF('UTILITY REPORT 1'!H33<0,"0",'UTILITY REPORT 1'!H33) -> 65 | L32: ='Water-Meter'!K36 -> 2 | M32: ='Water-Meter'!H36 -> 0 | N32: ='Water-Meter'!Q36 -> 11 | P32: ='Water-Meter'!E36 -> 99 | Q32: =IF('Water-Meter'!U36<0,"0",'Water-Meter'!U36) -> 80 | R32: =IF('Water-Meter'!X36<0,"0",'Water-Meter'!X36) -> 0 | S32: =IF('Water-Meter'!AA36<0,"0",'Water-Meter'!AA36) -> 33 | T32: =IF('Water-Meter'!AD36<0,"0",'Water-Meter'!AD36) -> 16 | U32: =IF('Water-Meter'!AG36<0,"0",'Water-Meter'!AG36) -> 0 | V32: =IF('Water-Meter'!AJ36<0,"0",'Water-Meter'!AJ36) -> 20 | W32: ='Water-Meter'!AN36 -> 149 | X32: =Total!K32 -> 0

Sheet UTILITY REPORT 1
A1: UTILITY REPORT
A2: Date | B2: % | C2: Guest Rooms Occupied | D2: Diesel cost Per Liter ($) | E2: Diesel consumption (LT) | F2: Power production (KW) | G2: Water consumption (M3) | H2: RO prodution (M3) | I2: Transport Consupmtion (LT)
A3: =Gen!A11 -> 44378 | B3: =Gen!B11 -> 0.3 | C3: ='Summery Report'!E5 -> 23 | D3: 1 | E3: =Gen!S11 -> 1799.58 | F3: =Gen!T11 -> 4264 | G3: ='Water-Meter'!E6 -> 109 | H3: ='Utility report '!AC6 -> 80 | I3: =Gen!AJ11 -> 0
A4: =Gen!A12 -> 44379 | B4: =Gen!B12 -> 0.35 | C4: ='Summery Report'!E6 -> 27 | D4: 1 | E4: =Gen!S12 -> 1691.92 | F4: =Gen!T12 -> 4274 | G4: ='Water-Meter'!E7 -> 101 | H4: ='Utility report '!AC7 -> 60 | I4: =Gen!AJ12 -> 324.81
A5: =Gen!A13 -> 44380 | B5: =Gen!B13 -> 0.2609 | C5: ='Summery Report'!E7 -> 20 | D5: 1 | E5: =Gen!S13 -> 1810.5 | F5: =Gen!T13 -> 4467 | G5: ='Water-Meter'!E8 -> 94 | H5: ='Utility report '!AC8 -> 55 | I5: =Gen!AJ13 -> 0
A6: =Gen!A14 -> 44381 | B6: =Gen!B14 -> 0.18 | C6: ='Summery Report'!E8 -> 14 | D6: 1 | E6: =Gen!S14 -> 1652.34 | F6: =Gen!T14 -> 4106 | G6: ='Water-Meter'!E9 -> 98 | H6: ='Utility report '!AC9 -> 48 | I6: =Gen!AJ14 -> 233.22
A7: =Gen!A15 -> 44382 | B7: =Gen!B15 -> 0.14 | C7: ='Summery Report'!E9 -> 11 | D7: 1 | E7: =Gen!S15 -> 1644.32 | F7: =Gen!T15 -> 4026 | G7: ='Water-Meter'!E10 -> 135 | H7: ='Utility report '!AC10 -> 50 | I7: =Gen!AJ15 -> 148.61
A8: =Gen!A16 -> 44383 | B8: =Gen!B16 -> 0.169 | C8: ='Summery Report'!E10 -> 14 | D8: 1 | E8: =Gen!S16 -> 1669.23 | F8: =Gen!T16 -> 4145 | G8: ='Water-Meter'!E11 -> 124 | H8: ='Utility report '!AC11 -> 113 | I8: =Gen!AJ16 -> 199.93
A9: =Gen!A17 -> 44384 | B9: =Gen!B17 -> 0.364 | C9: ='Summery Report'!E11 -> 29 | D9: 1 | E9: =Gen!S17 -> 1898.91 | F9: =Gen!T17 -> 4675 | G9: ='Water-Meter'!E12 -> 114 | H9: ='Utility report '!AC12 -> 121 | I9: =Gen!AJ17 -> 168.95
A10: =Gen!A18 -> 44385 | B10: =Gen!B18 -> 0.455 | C10: ='Summery Report'!E12 -> 35 | D10: 1 | E10: =Gen!S18 -> 1865.79 | F10: =Gen!T18 -> 4550 | G10: ='Water-Meter'!E13 -> 94 | H10: ='Utility report '!AC13 -> 201 | I10: =Gen!AJ18 -> 47
A11: =Gen!A19 -> 44386 | B11: =Gen!B19 -> 0.468 | C11: ='Summery Report'!E13 -> 39 | D11: 1 | E11: =Gen!S19 -> 1807.22 | F11: =Gen!T19 -> 4263 | G11: ='Water-Meter'!E14 -> 108 | H11: ='Utility report '!AC14 -> 1 | I11: =Gen!AJ19 -> 456
A12: =Gen!A20 -> 44387 | B12: =Gen!B20 -> 0.39 | C12: ='Summery Report'!E14 -> 32 | D12: 1 | E12: =Gen!S20 -> 1887.88 | F12: =Gen!T20 -> 4506 | G12: ='Water-Meter'!E15 -> 116 | H12: ='Utility report '!AC15 -> 70 | I12: =Gen!AJ20 -> 644.97
A13: =Gen!A21 -> 44388 | B13: =Gen!B21 -> 0.403 | C13: ='Summery Report'!E15 -> 31 | D13: 1 | E13: =Gen!S21 -> 1852.6 | F13: =Gen!T21 -> 4459 | G13: ='Water-Meter'!E16 -> 116 | H13: ='Utility report '!AC16 -> 41 | I13: =Gen!AJ21 -> 608.62
A14: =Gen!A22 -> 44389 | B14: =Gen!B22 -> 0.39 | C14: ='Summery Report'!E16 -> 32 | D14: 1 | E14: =Gen!S22 -> 1662.17 | F14: =Gen!T22 -> 4438 | G14: ='Water-Meter'!E17 -> 109 | H14: ='Utility report '!AC17 -> 40 | I14: =Gen!AJ22 -> 677.99
... A33: =Gen!A41 -> 44408 | B33: =Gen!B41 -> 0.15 | C33: ='Summery Report'!E35 -> 0 | D33: 1 | E33: =Gen!S41 -> 1680.02 | F33: =Gen!T41 -> 4015 | G33: ='Water-Meter'!E36 -> 99 | H33: ='Utility report '!AC36 -> 65 | I33: =Gen!AJ41 -> 376.24
B34: =Gen!B42 -> 0 | C34: ='Summery Report'!E36 -> 0 | D34: 2 | E34: =Gen!S42 -> 0 | F34: =Gen!T42 -> 0 | G34: ='Water-Meter'!E37 -> 0 | H34: ='Utility report '!AC37 -> -7713 | I34: =Gen!AK42 -> 0

Sheet Utility summery
A4: Date | B4: Room Occupied | C4: Electricity Units Generated KW | D4: Diseal | G4: Water | J4: Gas | N4: Cost of utilites
D5: Generator | E5: Transport | F5: Total | G5: RO | H5: STP | I5: Total Consumption | J5: 2 ton | K5: 1 Ton | L5: 1 Ton | M5: Total consumption | N5: Electricity /1.4$/liter | O5: Diseal for Transport | P5: Gas /2.38$/Kg | Q5: Total HLP Cost | R5: Electricity Cost/Room $ | S5: cost/Room $
A6: =Gen!A11 -> 44378 | B6: ='Summery Report'!E5 -> 23 | C6: =Gen!U11 -> 0.42204034 | D6: =Gen!S11 -> 1799.58 | E6: =Gen!AJ11 -> 0 | F6: =Gen!AS11 -> 0 | G6: ='Utility report '!AC6 -> 80 | H6: ='Utility report '!AE6 -> 33 | I6: ='Water-Meter'!E6 -> 109 | J6: ='Lpg (2)'!B10 -> 85 | K6: ='Lpg (2)'!C10 -> 37 | L6: ='Lpg (2)'!D10 -> 85 | M6: ='Lpg (2)'!G10 -> 130.68 | N6: =D6*1.4 -> 2519.412 | O6: =E6*1.4 -> 0 | P6: =('Lpg (2)'!G10)*2.38 -> 311.0184 | Q6: #REF! | R6: =N6/B6 -> 109.53965 | S6: =Q6/B6 -> #REF!
A7: =Gen!A12 -> 44379 | B7: ='Summery Report'!E6 -> 27 | C7: =Gen!U12 -> 0.39586336 | D7: =Gen!S12 -> 1691.92 | E7: =Gen!AJ12 -> 324.81 | F7: =Gen!AS12 -> 0 | G7: ='Utility report '!AC7 -> 60 | H7: ='Utility report '!AE7 -> 35 | I7: ='Water-Meter'!E7 -> 101 | J7: ='Lpg (2)'!B11 -> 85 | K7: ='Lpg (2)'!C11 -> 35 | L7: ='Lpg (2)'!D11 -> 85 | M7: ='Lpg (2)'!G11 -> 124.52 | N7: =D7*1.4 -> 2368.688 | O7: =E7*1.4 -> 454.734 | P7: =('Lpg (2)'!G11)*2.38 -> 296.3576 | Q7: #REF! | R7: =N7/B7 -> 87.729185 | S7: =Q7/B7 -> #REF!
A8: =Gen!A13 -> 44380 | B8: ='Summery Report'!E7 -> 20 | C8: =Gen!U13 -> 0.40530557 | D8: =Gen!S13 -> 1810.5 | E8: =Gen!AJ13 -> 0 | F8: =Gen!AS13 -> 0 | G8: ='Utility report '!AC8 -> 55 | H8: ='Utility report '!AE8 -> 10 | I8: ='Water-Meter'!E8 -> 94 | J8: ='Lpg (2)'!B12 -> 85 | K8: ='Lpg (2)'!C12 -> 30 | L8: ='Lpg (2)'!D12 -> 85 | M8: ='Lpg (2)'!G12 -> 44 | N8: =D8*1.4 -> 2534.7 | O8: =E8*1.4 -> 0 | P8: =('Lpg (2)'!G12)*2.38 -> 104.72 | Q8: #REF! | R8: =N8/B8 -> 126.735 | S8: =Q8/B8 -> #REF!
A9: =Gen!A14 -> 44381 | B9: ='Summery Report'!E8 -> 14 | C9: =Gen!U14 -> 0.40242085 | D9: =Gen!S14 -> 1652.34 | E9: =Gen!AJ14 -> 233.22 | F9: =Gen!AS14 -> 0 | G9: ='Utility report '!AC9 -> 48 | H9: ='Utility report '!AE9 -> 58 | I9: ='Water-Meter'!E9 -> 98 | J9: ='Lpg (2)'!B13 -> 85 | K9: ='Lpg (2)'!C13 -> 20 | L9: ='Lpg (2)'!D13 -> 85 | M9: ='Lpg (2)'!G13 -> 89.364 | N9: =D9*1.4 -> 2313.276 | O9: =E9*1.4 -> 326.508 | P9: =('Lpg (2)'!G13)*2.38 -> 212.68632 | Q9: #REF! | R9: =N9/B9 -> 165.234 | S9: =Q9/B9 -> #REF!
A10: =Gen!A15 -> 44382 | B10: ='Summery Report'!E9 -> 11 | C10: =Gen!U15 -> 0.40842524 | D10: =Gen!S15 -> 1644.32 | E10: =Gen!AJ15 -> 148.61 | F10: =Gen!AS15 -> 0 | G10: ='Utility report '!AC10 -> 50 | H10: ='Utility report '!AE10 -> 44 | I10: ='Water-Meter'!E10 -> 135 | J10: ='Lpg (2)'!B14 -> 85 | K10: ='Lpg (2)'!C14 -> 15 | L10: ='Lpg (2)'!D14 -> 85 | M10: ='Lpg (2)'!G14 -> 112.42 | N10: =D10*1.4 -> 2302.048 | O10: =E10*1.4 -> 208.054 | P10: =('Lpg (2)'!G14)*2.38 -> 267.5596 | Q10: #REF! | R10: =N10/B10 -> 209.27709 | S10: =Q10/B10 -> #REF!
A11: =Gen!A16 -> 44383 | B11: ='Summery Report'!E10 -> 14 | C11: =Gen!U16 -> 0.40270929 | D11: =Gen!S16 -> 1669.23 | E11: =Gen!AJ16 -> 199.93 | F11: =Gen!AS16 -> 0 | G11: ='Utility report '!AC11 -> 113 | H11: ='Utility report '!AE11 -> 52 | I11: ='Water-Meter'!E11 -> 124 | J11: ='Lpg (2)'!B15 -> 85 | K11: ='Lpg (2)'!C15 -> 10 | L11: ='Lpg (2)'!D15 -> 85 | M11: ='Lpg (2)'!G15 -> 116.776 | N11: =D11*1.4 -> 2336.922 | O11: =E11*1.4 -> 279.902 | P11: =('Lpg (2)'!G15)*2.38 -> 277.92688 | Q11: #REF! | R11: =N11/B11 -> 166.923 | S11: =Q11/B11 -> #REF!
A12: =Gen!A17 -> 44384 | B12: ='Summery Report'!E11 -> 29 | C12: =Gen!U17 -> 0.40618396 | D12: =Gen!S17 -> 1898.91 | E12: =Gen!AJ17 -> 168.95 | F12: =Gen!AS17 -> 0 | G12: ='Utility report '!AC12 -> 121 | H12: ='Utility report '!AE12 -> 52 | I12: ='Water-Meter'!E12 -> 114 | J12: ='Lpg (2)'!B16 -> 85 | K12: ='Lpg (2)'!C16 -> 4 | L12: ='Lpg (2)'!D16 -> 85 | M12: ='Lpg (2)'!G16 -> 108.328 | N12: =D12*1.4 -> 2658.474 | O12: =E12*1.4 -> 236.53 | P12: =('Lpg (2)'!G16)*2.38 -> 257.82064 | Q12: #REF! | R12: =N12/B12 -> 91.671517 | S12: =Q12/B12 -> #REF!
A13: =Gen!A18 -> 44385 | B13: ='Summery Report'!E12 -> 35 | C13: =Gen!U18 -> 0.41006374 | D13: =Gen!S18 -> 1865.79 | E13: =Gen!AJ18 -> 47 | F13: =Gen!AS18 -> 0 | G13: ='Utility report '!AC13 -> 201 | H13: ='Utility report '!AE13 -> 57 | I13: ='Water-Meter'!E13 -> 94 | J13: ='Lpg (2)'!B17 -> 85 | K13: ='Lpg (2)'!C17 -> 3 | L13: ='Lpg (2)'!D17 -> 85 | M13: ='Lpg (2)'!G17 -> 112.376 | N13: =D13*1.4 -> 2612.106 | O13: =E13*1.4 -> 65.8 | P13: =('Lpg (2)'!G17)*2.38 -> 267.45488 | Q13: #REF! | R13: =N13/B13 -> 74.6316 | S13: =Q13/B13 -> #REF!
A14: =Gen!A19 -> 44386 | B14: ='Summery Report'!E13 -> 39 | C14: =Gen!U19 -> 0.4239315 | D14: =Gen!S19 -> 1807.22 | E14: =Gen!AJ19 -> 456 | F14: =Gen!AS19 -> 0 | G14: ='Utility report '!AC14 -> 1 | H14: ='Utility report '!AE14 -> 59 | I14: ='Water-Meter'!E14 -> 108 | J14: ='Lpg (2)'!B18 -> 85 | K14: ='Lpg (2)'!C18 -> 2 | L14: ='Lpg (2)'!D18 -> 85 | M14: ='Lpg (2)'!G18 -> 103.4 | N14: =D14*1.4 -> 2530.108 | O14: =E14*1.4 -> 638.4 | P14: =('Lpg (2)'!G18)*2.38 -> 246.092 | Q14: #REF! | R14: =N14/B14 -> 64.874564 | S14: =Q14/B14 -> #REF!
A15: =Gen!A20 -> 44387 | B15: ='Summery Report'!E14 -> 32 | C15: =Gen!U20 -> 0.41897026 | D15: =Gen!S20 -> 1887.88 | E15: =Gen!AJ20 -> 644.97 | F15: =Gen!AS20 -> 0 | G15: ='Utility report '!AC15 -> 70 | H15: ='Utility report '!AE15 -> 56 | I15: ='Water-Meter'!E15 -> 116 | J15: ='Lpg (2)'!B19 -> 85 | K15: ='Lpg (2)'!C19 -> 1 | L15: ='Lpg (2)'!D19 -> 85 | M15: ='Lpg (2)'!G19 -> 117.304 | N15: =D15*1.4 -> 2643.032 | O15: =E15*1.4 -> 902.958 | P15: =('Lpg (2)'!G19)*2.38 -> 279.18352 | Q15: #REF! | R15: =N15/B15 -> 82.59475 | S15: =Q15/B15 -> #REF!
A16: =Gen!A21 -> 44388 | B16: ='Summery Report'!E15 -> 31 | C16: =Gen!U21 -> 0.41547432 | D16: =Gen!S21 -> 1852.6 | E16: =Gen!AJ21 -> 608.62 | F16: =Gen!AS21 -> 0 | G16: ='Utility report '!AC16 -> 41 | H16: ='Utility report '!AE16 -> 0 | I16: ='Water-Meter'!E16 -> 116 | J16: ='Lpg (2)'!B20 -> 85 | K16: ='Lpg (2)'!C20 -> 0 | L16: ='Lpg (2)'!D20 -> 85 | M16: ='Lpg (2)'!G20 -> 115.676 | N16: =D16*1.4 -> 2593.64 | O16: =E16*1.4 -> 852.068 | P16: =('Lpg (2)'!G20)*2.38 -> 275.30888 | Q16: #REF! | R16: =N16/B16 -> 83.665806 | S16: =Q16/B16 -> #REF!
A17: =Gen!A22 -> 44389 | B17: ='Summery Report'!E16 -> 32 | C17: =Gen!U22 -> 0.37453132 | D17: =Gen!S22 -> 1662.17 | E17: =Gen!AJ22 -> 677.99 | F17: =Gen!AS22 -> 0 | G17: ='Utility report '!AC17 -> 40 | H17: ='Utility report '!AE17 -> 1 | I17: ='Water-Meter'!E17 -> 109 | J17: ='Lpg (2)'!B21 -> 85 | K17: ='Lpg (2)'!C22 -> 0 | L17: ='Lpg (2)'!D21 -> 80 | M17: ='Lpg (2)'!G21 -> 126.984 | N17: =D17*1.4 -> 2327.038 | O17: =E17*1.4 -> 949.186 | P17: =('Lpg (2)'!G21)*2.38 -> 302.22192 | Q17: #REF! | R17: =N17/B17 -> 72.719938 | S17: =Q17/B17 -> #REF!
A18: =Gen!A23 -> 44390 | B18: ='Summery Report'!E17 -> 19 | C18: =Gen!U23 -> 0.42904884 | D18: =Gen!S23 -> 1844.91 | E18: =Gen!AJ23 -> 204.13 | F18: =Gen!AS23 -> 0 | G18: ='Utility report '!AC18 -> 37 | H18: ='Utility report '!AE18 -> 60 | I18: ='Water-Meter'!E18 -> 105 | J18: ='Lpg (2)'!B22 -> 85 | K18: ='Lpg (2)'!C23 -> 0 | L18: ='Lpg (2)'!D22 -> 76 | M18: ='Lpg (2)'!G22 -> 117.876 | N18: =D18*1.4 -> 2582.874 | O18: =E18*1.4 -> 285.782 | P18: =('Lpg (2)'!G22)*2.38 -> 280.54488 | Q18: #REF! | R18: =N18/B18 -> 135.94074 | S18: =Q18/B18 -> #REF!
A19: =Gen!A24 -> 44391 | B19: ='Summery Report'!E18 -> 14 | C19: =Gen!U24 -> 0.42290364 | D19: =Gen!S24 -> 1650.17 | E19: =Gen!AJ24 -> 1434.84 | F19: =Gen!AS24 -> 0 | G19: ='Utility report '!AC19 -> 38 | H19: ='Utility report '!AE19 -> 58 | I19: ='Water-Meter'!E19 -> 105 | J19: ='Lpg (2)'!B23 -> 85 | K19: ='Lpg (2)'!C24 -> 0 | L19: ='Lpg (2)'!D23 -> 70 | M19: ='Lpg (2)'!G23 -> 127.776 | N19: =D19*1.4 -> 2310.238 | O19: =E19*1.4 -> 2008.776 | P19: =('Lpg (2)'!G23)*2.38 -> 304.10688 | Q19: #REF! | R19: =N19/B19 -> 165.017 | S19: =Q19/B19 -> #REF!
A20: =Gen!A25 -> 44392 | B20: ='Summery Report'!E19 -> 16 | C20: =Gen!U25 -> 0.4287138 | D20: =Gen!S25 -> 1643.26 | E20: =Gen!AJ25 -> 155.98 | F20: =Gen!AS25 -> 0 | G20: ='Utility report '!AC20 -> 36 | H20: ='Utility report '!AE20 -> 53 | I20: ='Water-Meter'!E20 -> 83 | J20: ='Lpg (2)'!B24 -> 85 | K20: ='Lpg (2)'!C25 -> 0 | L20: ='Lpg (2)'!D24 -> 65 | M20: ='Lpg (2)'!G24 -> 124.74 | N20: =D20*1.4 -> 2300.564 | O20: =E20*1.4 -> 218.372 | P20: =('Lpg (2)'!G24)*2.38 -> 296.8812 | Q20: #REF! | R20: =N20/B20 -> 143.78525 | S20: =Q20/B20 -> #REF!
A21: =Gen!A26 -> 44393 | B21: ='Summery Report'!E20 -> 0 | C21: =Gen!U26 -> 0.42469118 | D21: =Gen!S26 -> 1732.74 | E21: =Gen!AJ26 -> 85.68 | F21: =Gen!AS26 -> 0 | G21: ='Utility report '!AC21 -> 21 | H21: ='Utility report '!AE21 -> 58 | I21: ='Water-Meter'!E21 -> 103 | J21: ='Lpg (2)'!B25 -> 85 | K21: ='Lpg (2)'!C25 -> 0 | L21: ='Lpg (2)'!D25 -> 45 | M21: ='Lpg (2)'!G25 -> 119.064 | N21: =D21*1.4 -> 2425.836 | O21: =E21*1.4 -> 119.952 | P21: =('Lpg (2)'!G25)*2.38 -> 283.37232 | Q21: #REF! | R21: =N21/B21 -> #DIV/0! | S21: =Q21/B21 -> #REF!
A22: =Gen!A27 -> 44394 | B22: ='Summery Report'!E21 -> 0 | C22: =Gen!U27 -> 0.43173021 | D22: =Gen!S27 -> 1766.64 | E22: =Gen!AJ27 -> 496.38 | F22: =Gen!AS27 -> 0 | G22: ='Utility report '!AC22 -> 35 | H22: ='Utility report '!AE22 -> 58 | I22: ='Water-Meter'!E22 -> 107 | J22: ='Lpg (2)'!B26 -> 85 | K22: ='Lpg (2)'!C26 -> 0 | L22: ='Lpg (2)'!D26 -> 38 | M22: ='Lpg (2)'!G26 -> 114.444 | N22: =D22*1.4 -> 2473.296 | O22: =E22*1.4 -> 694.932 | P22: =('Lpg (2)'!G26)*2.38 -> 272.37672 | Q22: #REF! | R22: =N22/B22 -> #DIV/0! | S22: =Q22/B22 -> #REF!
A23: =Gen!A28 -> 44395 | B23: ='Summery Report'!E22 -> 0 | C23: =Gen!U28 -> 0.40179326 | D23: =Gen!S28 -> 1787.98 | E23: =Gen!AJ28 -> 374.23 | F23: =Gen!AS28 -> 0 | G23: ='Utility report '!AC23 -> 42 | H23: ='Utility report '!AE23 -> 22 | I23: ='Water-Meter'!E23 -> 128 | J23: ='Lpg (2)'!B27 -> 85 | K23: ='Lpg (2)'!C27 -> 0 | L23: ='Lpg (2)'!D27 -> 30 | M23: ='Lpg (2)'!G27 -> 104.324 | N23: =D23*1.4 -> 2503.172 | O23: =E23*1.4 -> 523.922 | P23: =('Lpg (2)'!G27)*2.38 -> 248.29112 | Q23: #REF! | R23: =N23/B23 -> #DIV/0! | S23: =Q23/B23 -> #REF!
A24: =Gen!A29 -> 44396 | B24: ='Summery Report'!E23 -> 0 | C24: =Gen!U29 -> 0.39119145 | D24: =Gen!S29 -> 1812.39 | E24: =Gen!AJ29 -> 224 | F24: =Gen!AS29 -> 0 | G24: ='Utility report '!AC24 -> 101 | H24: ='Utility report '!AE24 -> 47 | I24: ='Water-Meter'!E24 -> 115 | J24: ='Lpg (2)'!B28 -> 85 | K24: ='Lpg (2)'!C28 -> 0 | L24: ='Lpg (2)'!D28 -> 27 | M24: ='Lpg (2)'!G28 -> 113.652 | N24: =D24*1.4 -> 2537.346 | O24: =E24*1.4 -> 313.6 | P24: =('Lpg (2)'!G28)*2.38 -> 270.49176 | Q24: #REF! | R24: =N24/B24 -> #DIV/0! | S24: =Q24/B24 -> #REF!
A25: =Gen!A30 -> 44397 | B25: ='Summery Report'!E24 -> 0 | C25: =Gen!U30 -> 0.4251673 | D25: =Gen!S30 -> 2007.64 | E25: =Gen!AJ30 -> 49.26 | F25: =Gen!AS30 -> 0 | G25: ='Utility report '!AC25 -> 155 | H25: ='Utility report '!AE25 -> 25 | I25: ='Water-Meter'!E25 -> 113 | J25: ='Lpg (2)'!B29 -> 85 | K25: ='Lpg (2)'!C29 -> 0 | L25: ='Lpg (2)'!D29 -> 20 | M25: ='Lpg (2)'!G29 -> 111.892 | N25: =D25*1.4 -> 2810.696 | O25: =E25*1.4 -> 68.964 | P25: =('Lpg (2)'!G29)*2.38 -> 266.30296 | Q25: #REF! | R25: =N25/B25 -> #DIV/0! | S25: =Q25/B25 -> #REF!
A26: =Gen!A31 -> 44398 | B26: ='Summery Report'!E25 -> 0 | C26: =Gen!U31 -> 0.40577886 | D26: =Gen!S31 -> 1992.78 | E26: =Gen!AJ31 -> 556.39 | F26: =Gen!AS31 -> 0 | G26: ='Utility report '!AC26 -> 0 | H26: ='Utility report '!AE26 -> 43 | I26: ='Water-Meter'!E26 -> 133 | J26: ='Lpg (2)'!B30 -> 85 | K26: ='Lpg (2)'!C30 -> 0 | L26: ='Lpg (2)'!D30 -> 15 | M26: ='Lpg (2)'!G30 -> 336.116 | N26: =D26*1.4 -> 2789.892 | O26: =E26*1.4 -> 778.946 | P26: =('Lpg (2)'!G30)*2.38 -> 799.95608 | Q26: #REF! | R26: =N26/B26 -> #DIV/0! | S26: =Q26/B26 -> #REF!
A27: =Gen!A32 -> 44399 | B27: ='Summery Report'!E26 -> 0 | C27: =Gen!U32 -> 0.4272656 | D27: =Gen!S32 -> 2232.89 | E27: =Gen!AJ32 -> 494.65 | F27: =Gen!AS32 -> 0 | G27: ='Utility report '!AC27 -> 167 | H27: ='Utility report '!AE27 -> 57 | I27: ='Water-Meter'!E27 -> 113 | J27: ='Lpg (2)'!B31 -> 85 | K27: ='Lpg (2)'!C31 -> 0 | L27: ='Lpg (2)'!D31 -> 9 | M27: ='Lpg (2)'!G31 -> -106.612 | N27: =D27*1.4 -> 3126.046 | O27: =E27*1.4 -> 692.51 | P27: =('Lpg (2)'!G31)*2.38 -> -253.73656 | Q27: #REF! | R27: =N27/B27 -> #DIV/0! | S27: =Q27/B27 -> #REF!
A28: =Gen!A33 -> 44400 | B28: ='Summery Report'!E27 -> 0 | C28: =Gen!U33 -> 0.44202748 | D28: =Gen!S33 -> 2090.79 | E28: =Gen!AJ33 -> 228.3 | F28: =Gen!AS33 -> 0 | G28: ='Utility report '!AC28 -> 163 | H28: ='Utility report '!AE28 -> 23 | I28: ='Water-Meter'!E28 -> 108 | J28: ='Lpg (2)'!B32 -> 85 | K28: ='Lpg (2)'!C32 -> 0 | L28: ='Lpg (2)'!D32 -> 5 | M28: ='Lpg (2)'!G32 -> 98.296 | N28: =D28*1.4 -> 2927.106 | O28: =E28*1.4 -> 319.62 | P28: =('Lpg (2)'!G32)*2.38 -> 233.94448 | Q28: #REF! | R28: =N28/B28 -> #DIV/0! | S28: =Q28/B28 -> #REF!
A29: =Gen!A34 -> 44401 | B29: ='Summery Report'!E28 -> 0 | C29: =Gen!U34 -> 0.41293913 | D29: =Gen!S34 -> 2014.73 | E29: =Gen!AJ34 -> 442.98 | F29: =Gen!AS34 -> 0 | G29: ='Utility report '!AC29 -> 0 | H29: ='Utility report '!AE29 -> 67 | I29: ='Water-Meter'!E29 -> 106 | J29: ='Lpg (2)'!B33 -> 85 | K29: ='Lpg (2)'!C33 -> 0 | L29: ='Lpg (2)'!D33 -> 2 | M29: ='Lpg (2)'!G33 -> 98.868 | N29: =D29*1.4 -> 2820.622 | O29: =E29*1.4 -> 620.172 | P29: =('Lpg (2)'!G33)*2.38 -> 235.30584 | Q29: #REF! | R29: =N29/B29 -> #DIV/0! | S29: =Q29/B29 -> #REF!
A30: =Gen!A35 -> 44402 | B30: ='Summery Report'!E29 -> 0 | C30: =Gen!U35 -> 0.40641226 | D30: =Gen!S35 -> 1869.09 | E30: =Gen!AJ35 -> 259.79 | F30: =Gen!AS35 -> 0 | G30: ='Utility report '!AC30 -> 81 | H30: ='Utility report '!AE30 -> 64 | I30: ='Water-Meter'!E30 -> 106 | J30: ='Lpg (2)'!B34 -> 85 | K30: ='Lpg (2)'!C34 -> 0 | L30: ='Lpg (2)'!D34 -> 1 | M30: ='Lpg (2)'!G34 -> 106.392 | N30: =D30*1.4 -> 2616.726 | O30: =E30*1.4 -> 363.706 | P30: =('Lpg (2)'!G34)*2.38 -> 253.21296 | Q30: #REF! | R30: =N30/B30 -> #DIV/0! | S30: =Q30/B30 -> #REF!
A31: =Gen!A36 -> 44403 | B31: ='Summery Report'!E30 -> 0 | C31: =Gen!U36 -> 0.42781427 | D31: =Gen!S36 -> 1888.8 | E31: =Gen!AJ36 -> 70.92 | F31: =Gen!AS36 -> 0 | G31: ='Utility report '!AC31 -> 25 | H31: ='Utility report '!AE31 -> 58 | I31: ='Water-Meter'!E31 -> 96 | J31: ='Lpg (2)'!B35 -> 85 | K31: ='Lpg (2)'!C35 -> 0 | L31: ='Lpg (2)'!D35 -> 1 | M31: ='Lpg (2)'!G35 -> 93.324 | N31: =D31*1.4 -> 2644.32 | O31: =E31*1.4 -> 99.288 | P31: =('Lpg (2)'!G35)*2.38 -> 222.11112 | Q31: #REF! | R31: =N31/B31 -> #DIV/0! | S31: =Q31/B31 -> #REF!
A32: =Gen!A37 -> 44404 | B32: ='Summery Report'!E31 -> 0 | C32: =Gen!U37 -> 0.41703712 | D32: =Gen!S37 -> 1921.29 | E32: =Gen!AJ37 -> 491.89 | F32: =Gen!AS37 -> 0 | G32: ='Utility report '!AC32 -> 93 | H32: ='Utility report '!AE32 -> 47 | I32: ='Water-Meter'!E32 -> 103 | J32: ='Lpg (2)'!B36 -> 85 | K32: ='Lpg (2)'!C36 -> 0 | L32: ='Lpg (2)'!D36 -> 0 | M32: ='Lpg (2)'!G36 -> 74.228 | N32: =D32*1.4 -> 2689.806 | O32: =E32*1.4 -> 688.646 | P32: =('Lpg (2)'!G36)*2.38 -> 176.66264 | Q32: #REF! | R32: =N32/B32 -> #DIV/0! | S32: =Q32/B32 -> #REF!
... A36: =Gen!A41 -> 44408 | B36: ='Summery Report'!E35 -> 0 | C36: =Gen!U41 -> 0.41843587 | D36: =Gen!S41 -> 1680.02 | E36: =Gen!AJ41 -> 376.24 | F36: =Gen!AS41 -> 0 | G36: ='Utility report '!AC36 -> 65 | H36: ='Utility report '!AE36 -> 50 | I36: ='Water-Meter'!E36 -> 99 | J36: ='Lpg (2)'!B40 -> 76 | K36: ='Lpg (2)'!C40 -> 0 | L36: ='Lpg (2)'!D40 -> 0 | M36: ='Lpg (2)'!G40 -> 111.232 | N36: =D36*1.4 -> 2352.028 | O36: =E36*1.4 -> 526.736 | P36: =('Lpg (2)'!G40)*2.38 -> 264.73216 | Q36: #REF! | R36: =N36/B36 -> #DIV/0! | S36: =Q36/B36 -> #REF!
B37: ='Summery Report'!E36 -> 0 | C37: =Gen!U42 -> 0 | D37: =Gen!S42 -> 0 | E37: =Gen!AJ42 -> 0 | F37: =Gen!AS42 -> 0 | I37: ='Water-Meter'!E37 -> 0 | J37: ='Lpg (2)'!B41 -> 0 | K37: ='Lpg (2)'!C41 -> 0 | L37: ='Lpg (2)'!D41 -> 0 | Q37: #REF! | R37: =N37/B37 -> #DIV/0! | S37: =Q37/B37 -> #REF!
A39: Total | B39: =SUM(B7:B37) -> 333 | C39: =AVERAGE(C6:C36) -> 0.41518431 | D39: =SUM(D7:D35) -> 53210.23 | E39: =SUM(E7:E36) -> 10219.18 | F39: =SUM(F7:F35) -> 0 | G39: =SUM(G7:G36) -> 2193 | H39: =SUM(H7:H36) -> 1365 | I39: =SUM(I7:I36) -> 3263 | J39: =SUM(J7:J36) -> 2535 | K39: =SUM(K7:K36) -> 120 | L39: =SUM(L7:L36) -> 1334 | M39: =SUM(M7:M36) -> 3342.9 | N39: =SUM(N7:N36) -> 76846.35 | O39: =SUM(O7:O36) -> 14306.852 | P39: =SUM(P7:P35) -> 7691.3698 | Q39: =SUM(Q7:Q35) -> #REF! | R39: =SUM(R7:R35) -> #DIV/0! | S39: =SUM(S7:S35) -> #REF!

Sheet Utility report 
A1: =A6 -> 44378
A2: Date | B2: Total occupancy | H2: Diesel balance LTS | I2: Diesel Deliveries | J2: Gen.Diesel consumption LTS | L2: Total Diesel consumption LTS | M2: Water Meter reading | N2: Water consumption m³ | O2: R.O WATER PRODUCTION LTRS + TIME | AA2: Total RO production | AB2: RO Meter reading | AD2: 0 | AE2: STP | AF2: GAS TANK A | AG2: GAS TANK B | AH2: GAS TANK C | AI2: Total Gas Tanks | AJ2: Kg /day | AK2: TOTAL GAS cons.
A3: Rate Tsh /$ | B3: 1640 | C3: Diesel cost / lits | D3: 2175 | F3: =SUM(D3/B3) -> 1.3262195 | H3: =Gen!C11 -> 29939.14 | K3: Transport consumption | M3: Balance | O3: PLANT NO 1 | S3: PLANT NO 2 | W3: PLANT NO 3 | AA3: /day | AB3: Balance | AD3: 0 | AE3: Production | AF3: Capacity | AG3: Capacity | AH3: Capacity | AI3: Kg | AJ3: /day | AK3: /day
B4: Rooms OCC | C4: % | D4: Guest Rooms Occ | F4: Electricity Production Cost /Room Occ by guest | G4: All Cost /Room Occ by guest | O4: Flow M3 | P4: Reading Hours Meter | Q4: Hrs | R4: total production M3 | S4: Flow M3 | T4: Reading Hours Meter | U4: Hrs | V4: total production M3 | W4: Flow M3 | X4: READING HOURS METER | Y4: Hrs | Z4: total production M3 | AA4: M3 | AC4: M3 | AE4: M3 | AF4: 2000 | AG4: 1000 | AH4: 1000 | AI4: #VALUE! | AJ4: Kg | AK4: M3
P5: 19038 | T5: 18452 | X5: 28673 | AB5: 5440 | AD5: 218871 | AF5: 0.85 | AG5: 0.85 | AH5: 0.85
A6: =Gen!A11 -> 44378 | B6: ='Summery Report'!E5 -> 23 | C6: =Gen!B11 -> 0.3 | D6: ='Summery Report'!E5 -> 23 | E6: =SUM(F3) -> 1.3262195 | F6: =SUM(J6*E6)/D6 -> 245.86957 | G6: =SUM(L6*E6)/D6 -> 245.86957 | H6: =Gen!C11 -> 29939.14 | I6: =Gen!E11 -> 0 | J6: =Gen!T11 -> 4264 | K6: =Gen!AK11 -> 0 | L6: =SUM(J6:K6) -> 4264 | M6: ='Water-Meter'!K46 -> 486.19483 | N6: ='Water-Meter'!E6 -> 109 | P6: 19038 | Q6: =SUM(P6-P5) -> 0 | R6: =SUM(Q6*O6) -> 0 | S6: 7.2 | T6: 18471 | U6: =T6-T5 -> 19 | V6: - | W6: 1.6 | X6: 28673 | Y6: =X6-X5 -> 0 | Z6: =Y6-Y5 -> 0 | AA6: =Z6-Z5 -> 0 | AB6: 5520 | AC6: =AB6-AB5 -> 80 | AD6: 218904 | AE6: =AD6-AD5 -> 33 | AF6: ='Lpg (2)'!B10*2000/85 -> 2000 | AG6: ='Lpg (2)'!C10*1000/85 -> 435.29412 | AH6: ='Lpg (2)'!D10*1000/85 -> 1000 | AI6: =SUM(AF6*2000)+(AG6*1000)+(AH6*1000) -> 5435294.1 | AJ6: =SUM(AI5-AI6) -> -5435294.1
A7: =Gen!A12 -> 44379 | B7: ='Summery Report'!E6 -> 27 | C7: =Gen!B12 -> 0.35 | D7: ='Summery Report'!E6 -> 27 | E7: =SUM(E6) -> 1.3262195 | F7: =SUM(J7*E7)/D7 -> 209.93564 | G7: =SUM(L7*E7)/D7 -> 209.93564 | H7: =Gen!C12 -> 28139.56 | I7: =Gen!E12 -> 0 | J7: =Gen!T12 -> 4274 | K7: =Gen!AK12 -> 0 | L7: =SUM(J7:K7) -> 4274 | M7: ='Water-Meter'!K47 -> 486.2234 | N7: ='Water-Meter'!E7 -> 101 | P7: 19038 | Q7: =SUM(P7-P6) -> 0 | R7: =SUM(Q7*O7) -> 0 | S7: 7.2 | T7: 18494 | U7: =T7-T6 -> 23 | V7: =SUM(U7*S7) -> 165.6 | W7: 1.6 | X7: 28673 | Y7: =X7-X6 -> 0 | Z7: =SUM(Y7*W7) -> 0 | AA7: =SUM(Z7*X9) -> 0 | AB7: 5580 | AC7: =AB7-AB6 -> 60 | AD7: 218939 | AE7: =AD7-AD6 -> 35 | AF7: ='Lpg (2)'!B11*2000/85 -> 2000 | AG7: ='Lpg (2)'!C11*1000/85 -> 411.76471 | AH7: ='Lpg (2)'!D11*1000/85 -> 1000 | AI7: =SUM(AF6*2000)+(AG7*1000)+(AH7*1000) -> 5411764.7 | AJ7: =SUM(AI6-AI7) -> 23529.412
A8: =Gen!A13 -> 44380 | B8: ='Summery Report'!E7 -> 20 | C8: =Gen!B13 -> 0.2609 | D8: ='Summery Report'!E7 -> 20 | E8: =SUM(E7) -> 1.3262195 | F8: =SUM(J8*E8)/D8 -> 296.21113 | G8: =SUM(L8*E8)/D8 -> 296.21113 | H8: =Gen!C13 -> 44122.83 | I8: =Gen!E13 -> 18000 | J8: =Gen!T13 -> 4467 | K8: =Gen!AK13 -> 0 | L8: =SUM(J8:K8) -> 4467 | M8: ='Water-Meter'!K48 -> 535.73281 | N8: ='Water-Meter'!E8 -> 94 | P8: 19038 | Q8: =SUM(P8-P7) -> 0 | R8: =SUM(Q8*O8) -> 0 | S8: 7.1 | T8: 18500 | U8: =T8-T7 -> 6 | V8: =SUM(U8*S8) -> 42.6 | W8: 1.6 | X8: 28673 | Y8: =X8-X7 -> 0 | Z8: =SUM(Y8*W8) -> 0 | AA8: =SUM(Z8*X10) -> 0 | AB8: 5635 | AC8: =AB8-AB7 -> 55 | AD8: 218949 | AE8: =AD8-AD7 -> 10 | AF8: ='Lpg (2)'!B12*2000/85 -> 2000 | AG8: ='Lpg (2)'!C12*1000/85 -> 352.94118 | AH8: ='Lpg (2)'!D12*1000/85 -> 1000 | AI8: =SUM(AF7*2000)+(AG8*1000)+(AH8*1000) -> 5352941.2 | AJ8: =SUM(AI7-AI8) -> 58823.529
A9: =Gen!A14 -> 44381 | B9: ='Summery Report'!E8 -> 14 | C9: =Gen!B14 -> 0.18 | D9: ='Summery Report'!E8 -> 14 | E9: =SUM(E8) -> 1.3262195 | F9: =SUM(J9*E9)/D9 -> 388.96124 | G9: =SUM(L9*E9)/D9 -> 388.96124 | H9: =Gen!C14 -> 42312.33 | I9: =Gen!E14 -> 0 | J9: =Gen!T14 -> 4106 | K9: =Gen!AK14 -> 0 | L9: =SUM(J9:K9) -> 4106 | M9: ='Water-Meter'!K49 -> 571.29614 | N9: ='Water-Meter'!E9 -> 98 | P9: 19038 | Q9: =SUM(P9-P8) -> 0 | R9: =SUM(Q9*O9) -> 0 | S9: 6.9 | T9: 18501 | U9: =T9-T8 -> 1 | V9: =SUM(U9*S10) -> 6.9 | W9: 1.6 | X9: 28673 | Y9: =X9-X8 -> 0 | Z9: =SUM(Y9*W11) -> 0 | AA9: =SUM(Z9*X11) -> 0 | AB9: 5683 | AC9: =AB9-AB8 -> 48 | AD9: 219007 | AE9: =AD9-AD8 -> 58 | AF9: ='Lpg (2)'!B13*2000/85 -> 2000 | AG9: ='Lpg (2)'!C13*1000/85 -> 235.29412 | AH9: ='Lpg (2)'!D13*1000/85 -> 1000 | AI9: =SUM(AF8*2000)+(AG9*1000)+(AH9*1000) -> 5235294.1 | AJ9: =SUM(AI8-AI9) -> 117647.06
A10: =Gen!A15 -> 44382 | B10: ='Summery Report'!E9 -> 11 | C10: =Gen!B15 -> 0.14 | D10: ='Summery Report'!E9 -> 11 | E10: =SUM(E9) -> 1.3262195 | F10: =SUM(J10*E10)/D10 -> 485.39634 | G10: =SUM(L10*E10)/D10 -> 485.39634 | H10: =Gen!C15 -> 40426.77 | I10: =Gen!E15 -> 0 | J10: =Gen!T15 -> 4026 | K10: =Gen!AK15 -> 0 | L10: =SUM(J10:K10) -> 4026 | M10: ='Water-Meter'!K50 -> 565.93234 | N10: ='Water-Meter'!E10 -> 135 | P10: 19038 | Q10: =SUM(P10-P9) -> 0 | R10: =SUM(Q10*O10) -> 0 | S10: 6.9 | T10: 18502 | U10: =T10-T9 -> 1 | V10: =SUM(U10*S11) -> 6.9 | W10: 1.6 | X10: 28695 | Y10: =X10-X9 -> 22 | Z10: =SUM(Y10*W10) -> 35.2 | AA10: =SUM(Z10*X12) -> 1010908.8 | AB10: 5733 | AC10: =AB10-AB9 -> 50 | AD10: 219051 | AE10: =AD10-AD9 -> 44 | AF10: ='Lpg (2)'!B14*2000/85 -> 2000 | AG10: ='Lpg (2)'!C14*1000/85 -> 176.47059 | AH10: ='Lpg (2)'!D14*1000/85 -> 1000 | AI10: =SUM(AF9*2000)+(AG10*1000)+(AH10*1000) -> 5176470.6 | AJ10: =SUM(AI9-AI10) -> 58823.529
A11: =Gen!A16 -> 44383 | B11: ='Summery Report'!E10 -> 14 | C11: =Gen!B16 -> 0.169 | D11: ='Summery Report'!E10 -> 14 | E11: =SUM(E10) -> 1.3262195 | F11: =SUM(J11*E11)/D11 -> 392.65571 | G11: =SUM(L11*E11)/D11 -> 392.65571 | H11: =Gen!C16 -> 38633.84 | I11: =Gen!E16 -> 0 | J11: =Gen!T16 -> 4145 | K11: =Gen!AK16 -> 0 | L11: =SUM(J11:K11) -> 4145 | M11: ='Water-Meter'!K51 -> 459.57978 | N11: ='Water-Meter'!E11 -> 124 | P11: 19038 | Q11: =SUM(P11-P10) -> 0 | R11: =SUM(Q11*O11) -> 0 | S11: 6.9 | T11: 18504 | U11: =T11-T10 -> 2 | V11: =SUM(U11*S12) -> 14.2 | W11: 1.6 | X11: 28695 | Y11: =X11-X10 -> 0 | Z11: =SUM(Y11*W11) -> 0 | AA11: =SUM(Z11*X13) -> 0 | AB11: 5846 | AC11: =AB11-AB10 -> 113 | AD11: 219103 | AE11: =AD11-AD10 -> 52 | AF11: ='Lpg (2)'!B15*2000/85 -> 2000 | AG11: ='Lpg (2)'!C15*1000/85 -> 117.64706 | AH11: ='Lpg (2)'!D15*1000/85 -> 1000 | AI11: =SUM(AF10*2000)+(AG11*1000)+(AH11*1000) -> 5117647.1 | AJ11: =SUM(AI10-AI11) -> 58823.529
A12: =Gen!A17 -> 44384 | B12: ='Summery Report'!E11 -> 29 | C12: =Gen!B17 -> 0.364 | D12: ='Summery Report'!E11 -> 29 | E12: =SUM(E11) -> 1.3262195 | F12: =SUM(J12*E12)/D12 -> 213.79573 | G12: =SUM(L12*E12)/D12 -> 213.79573 | H12: =Gen!C17 -> 36764.68 | I12: =Gen!E17 -> 0 | J12: =Gen!T17 -> 4675 | K12: =Gen!AK17 -> 0 | L12: =SUM(J12:K12) -> 4675 | M12: ='Water-Meter'!K52 -> 384.44269 | N12: ='Water-Meter'!E12 -> 114 | P12: 19038 | Q12: =SUM(P12-P11) -> 0 | R12: =SUM(Q12*O12) -> 0 | S12: 7.1 | T12: 18516 | U12: =T12-T11 -> 12 | V12: =SUM(U12*S12) -> 85.2 | W12: 1.6 | X12: 28719 | Y12: =X12-X11 -> 24 | Z12: =SUM(Y12*W12) -> 38.4 | AA12: =SUM(Z12*X14) -> 1103769.6 | AB12: 5967 | AC12: =AB12-AB11 -> 121 | AD12: 219155 | AE12: =AD12-AD11 -> 52 | AF12: ='Lpg (2)'!B16*2000/85 -> 2000 | AG12: ='Lpg (2)'!C16*1000/85 -> 47.058824 | AH12: ='Lpg (2)'!D16*1000/85 -> 1000 | AI12: =SUM(AF11*2000)+(AG12*1000)+(AH12*1000) -> 5047058.8 | AJ12: =SUM(AI11-AI12) -> 70588.235
A13: =Gen!A18 -> 44385 | B13: ='Summery Report'!E12 -> 35 | C13: =Gen!B18 -> 0.455 | D13: ='Summery Report'!E12 -> 35 | E13: =SUM(E12) -> 1.3262195 | F13: =SUM(J13*E13)/D13 -> 172.40854 | G13: =SUM(L13*E13)/D13 -> 172.40854 | H13: =Gen!C18 -> 34696.82 | I13: =Gen!E18 -> 0 | J13: =Gen!T18 -> 4550 | K13: =Gen!AK18 -> 0 | L13: =SUM(J13:K13) -> 4550 | M13: ='Water-Meter'!K53 -> 353.8128 | N13: ='Water-Meter'!E13 -> 94 | P13: 19038 | Q13: =SUM(P13-P12) -> 0 | R13: =SUM(Q13*O13) -> 0 | S13: 7.2 | T13: 18539 | U13: =T13-T12 -> 23 | V13: =SUM(U13*S13) -> 165.6 | W13: 1.7 | X13: 28743 | Y13: =X13-X12 -> 24 | Z13: =SUM(Y13*W13) -> 40.8 | AA13: =SUM(Z13*X15) -> 1172755.2 | AB13: 6168 | AC13: =AB13-AB12 -> 201 | AD13: 219212 | AE13: =AD13-AD12 -> 57 | AF13: ='Lpg (2)'!B17*2000/85 -> 2000 | AG13: ='Lpg (2)'!C17*1000/85 -> 35.294118 | AH13: ='Lpg (2)'!D17*1000/85 -> 1000 | AI13: =SUM(AF12*2000)+(AG13*1000)+(AH13*1000) -> 5035294.1 | AJ13: =SUM(AI12-AI13) -> 11764.706
A14: =Gen!A19 -> 44386 | B14: ='Summery Report'!E13 -> 39 | C14: =Gen!B19 -> 0.468 | D14: ='Summery Report'!E13 -> 39 | E14: =SUM(E13) -> 1.3262195 | F14: =SUM(J14*E14)/D14 -> 144.96599 | G14: =SUM(L14*E14)/D14 -> 144.96599 | H14: =Gen!C19 -> 32784.03 | I14: =Gen!E19 -> 0 | J14: =Gen!T19 -> 4263 | K14: =Gen!AK19 -> 0 | L14: =SUM(J14:K14) -> 4263 | M14: ='Water-Meter'!K54 -> 427.30401 | N14: ='Water-Meter'!E14 -> 108 | P14: 19038 | Q14: =SUM(P14-P13) -> 0 | R14: =SUM(Q14*O14) -> 0 | S14: 7.1 | T14: 18540 | U14: =T14-T13 -> 1 | V14: =SUM(U14*S14) -> 7.1 | W14: 1.6 | X14: 28744 | Y14: =X14-X13 -> 1 | Z14: =SUM(Y14*W14) -> 1.6 | AA14: =SUM(Z14*X16) -> 46051.2 | AB14: 6169 | AC14: =AB14-AB13 -> 1 | AD14: 219271 | AE14: =AD14-AD13 -> 59 | AF14: ='Lpg (2)'!B18*2000/85 -> 2000 | AG14: ='Lpg (2)'!C18*1000/85 -> 23.529412 | AH14: ='Lpg (2)'!D18*1000/85 -> 1000 | AI14: =SUM(AF13*2000)+(AG14*1000)+(AH14*1000) -> 5023529.4 | AJ14: =SUM(AI13-AI14) -> 11764.706
A15: =Gen!A20 -> 44387 | B15: ='Summery Report'!E14 -> 32 | C15: =Gen!B20 -> 0.39 | D15: ='Summery Report'!E14 -> 32 | E15: =SUM(E14) -> 1.3262195 | F15: =SUM(J15*E15)/D15 -> 186.74829 | G15: =SUM(L15*E15)/D15 -> 186.74829 | H15: =Gen!C20 -> 30520.81 | I15: =Gen!E20 -> 0 | J15: =Gen!T20 -> 4506 | K15: =Gen!AK20 -> 0 | L15: =SUM(J15:K15) -> 4506 | M15: ='Water-Meter'!K55 -> 433.33688 | N15: ='Water-Meter'!E15 -> 116 | P15: 19038 | Q15: =SUM(P15-P14) -> 0 | R15: =SUM(Q15*O15) -> 0 | S15: 7.1 | T15: 18548 | U15: =T15-T14 -> 8 | V15: =SUM(U15*S15) -> 56.8 | X15: 28744 | Y15: =X15-X14 -> 0 | Z15: =SUM(Y15*W15) -> 0 | AA15: =SUM(Z15*X17) -> 0 | AB15: 6239 | AC15: =AB15-AB14 -> 70 | AD15: 219327 | AE15: =AD15-AD14 -> 56 | AF15: ='Lpg (2)'!B19*2000/85 -> 2000 | AG15: ='Lpg (2)'!C19*1000/85 -> 11.764706 | AH15: ='Lpg (2)'!D19*1000/85 -> 1000 | AI15: =SUM(AF15*2000)+(AG15*1000)+(AH15*1000) -> 5011764.7 | AJ15: =SUM(AI14-AI15) -> 11764.706
