Workbook

Sheet TOTAL
A1: Site Name | B1: Day | C1: Month | D1: Year | E1: Total Electricity Kwh | F1: Electricity Tariff ($/Kwh) | G1: LPG (Kg) | H1: LPG $/Kg | I1: Water Utility Supply (m3) m3 | J1: Water Utility Supply (m3) $/m3 | K1: Room Nights | L1: Food Covers
A2: Maldives at Landaa Giraavaru | B2: 1 | C2: 7 | D2: 2021 | E2: ='Maldives at LG Daily'!D5 -> 25744 | F2: 0.93 | G2: ='Maldives at LG Daily'!F5 -> 225 | H2: 1.24 | I2: ='Maldives at LG Daily'!H5 -> 418 | J2: 2.16 | K2: ='Maldives at LG Daily'!I5 -> 18 | L2: ='Maldives at LG Daily'!J5 -> 196
A3: Maldives at Landaa Giraavaru | B3: =B2+1 -> 2 | C3: 7 | D3: 2021 | E3: ='Maldives at LG Daily'!D6 -> 26606 | F3: 0.93 | G3: ='Maldives at LG Daily'!F6 -> 0 | H3: 1.24 | I3: ='Maldives at LG Daily'!H6 -> 390 | J3: 2.16 | K3: ='Maldives at LG Daily'!I6 -> 23 | L3: ='Maldives at LG Daily'!J6 -> 225
A4: Maldives at Landaa Giraavaru | B4: =B3+1 -> 3 | C4: 7 | D4: 2021 | E4: ='Maldives at LG Daily'!D7 -> 26843 | F4: 0.93 | G4: ='Maldives at LG Daily'!F7 -> 90 | H4: 1.24 | I4: ='Maldives at LG Daily'!H7 -> 429 | J4: 2.16 | K4: ='Maldives at LG Daily'!I7 -> 26 | L4: ='Maldives at LG Daily'!J7 -> 243
A5: Maldives at Landaa Giraavaru | B5: =B4+1 -> 4 | C5: 7 | D5: 2021 | E5: ='Maldives at LG Daily'!D8 -> 27285 | F5: 0.93 | G5: ='Maldives at LG Daily'!F8 -> 0 | H5: 1.24 | I5: ='Maldives at LG Daily'!H8 -> 416 | J5: 2.16 | K5: ='Maldives at LG Daily'!I8 -> 33 | L5: ='Maldives at LG Daily'!J8 -> 295
A6: Maldives at Landaa Giraavaru | B6: =B5+1 -> 5 | C6: 7 | D6: 2021 | E6: ='Maldives at LG Daily'!D9 -> 29505 | F6: 0.93 | G6: ='Maldives at LG Daily'!F9 -> 90 | H6: 1.24 | I6: ='Maldives at LG Daily'!H9 -> 387 | J6: 2.16 | K6: ='Maldives at LG Daily'!I9 -> 30 | L6: ='Maldives at LG Daily'!J9 -> 256
A7: Maldives at Landaa Giraavaru | B7: =B6+1 -> 6 | C7: 7 | D7: 2021 | E7: ='Maldives at LG Daily'!D10 -> 24509 | F7: 0.93 | G7: ='Maldives at LG Daily'!F10 -> 0 | H7: 1.24 | I7: ='Maldives at LG Daily'!H10 -> 409 | J7: 2.16 | K7: ='Maldives at LG Daily'!I10 -> 33 | L7: ='Maldives at LG Daily'!J10 -> 272
A8: Maldives at Landaa Giraavaru | B8: =B7+1 -> 7 | C8: 7 | D8: 2021 | E8: ='Maldives at LG Daily'!D11 -> 27353 | F8: 0.93 | G8: ='Maldives at LG Daily'!F11 -> 0 | H8: 1.24 | I8: ='Maldives at LG Daily'!H11 -> 328 | J8: 2.16 | K8: ='Maldives at LG Daily'!I11 -> 36 | L8: ='Maldives at LG Daily'!J11 -> 308
A9: Maldives at Landaa Giraavaru | B9: =B8+1 -> 8 | C9: 7 | D9: 2021 | E9: ='Maldives at LG Daily'!D12 -> 28127 | F9: 0.93 | G9: ='Maldives at LG Daily'!F12 -> 0 | H9: 1.24 | I9: ='Maldives at LG Daily'!H12 -> 398 | J9: 2.16 | K9: ='Maldives at LG Daily'!I12 -> 45 | L9: ='Maldives at LG Daily'!J12 -> 311
A10: Maldives at Landaa Giraavaru | B10: =B9+1 -> 9 | C10: 7 | D10: 2021 | E10: ='Maldives at LG Daily'!D13 -> 27718 | F10: 0.93 | G10: ='Maldives at LG Daily'!F13 -> 0 | H10: 1.24 | I10: ='Maldives at LG Daily'!H13 -> 364 | J10: 2.16 | K10: ='Maldives at LG Daily'!I13 -> 41 | L10: ='Maldives at LG Daily'!J13 -> 281
A11: Maldives at Landaa Giraavaru | B11: =B10+1 -> 10 | C11: 7 | D11: 2021 | E11: ='Maldives at LG Daily'!D14 -> 28349 | F11: 0.93 | G11: ='Maldives at LG Daily'!F14 -> 45 | H11: 1.24 | I11: ='Maldives at LG Daily'!H14 -> 362 | J11: 2.16 | K11: ='Maldives at LG Daily'!I14 -> 37 | L11: ='Maldives at LG Daily'!J14 -> 255
A12: Maldives at Landaa Giraavaru | B12: =B11+1 -> 11 | C12: 7 | D12: 2021 | E12: ='Maldives at LG Daily'!D15 -> 28217 | F12: 0.93 | G12: ='Maldives at LG Daily'!F15 -> 0 | H12: 1.24 | I12: ='Maldives at LG Daily'!H15 -> 405 | J12: 2.16 | K12: ='Maldives at LG Daily'!I15 -> 36 | L12: ='Maldives at LG Daily'!J15 -> 327
A13: Maldives at Landaa Giraavaru | B13: =B12+1 -> 12 | C13: 7 | D13: 2021 | E13: ='Maldives at LG Daily'!D16 -> 28423 | F13: 0.93 | G13: ='Maldives at LG Daily'!F16 -> 0 | H13: 1.24 | I13: ='Maldives at LG Daily'!H16 -> 415 | J13: 2.16 | K13: ='Maldives at LG Daily'!I16 -> 0 | L13: ='Maldives at LG Daily'!J16 -> 0
A14: Maldives at Landaa Giraavaru | B14: =B13+1 -> 13 | C14: 7 | D14: 2021 | E14: ='Maldives at LG Daily'!D17 -> 0 | F14: 0.93 | G14: ='Maldives at LG Daily'!F17 -> 0 | H14: 1.24 | I14: ='Maldives at LG Daily'!H17 -> 406 | J14: 2.16 | K14: ='Maldives at LG Daily'!I17 -> 0 | L14: ='Maldives at LG Daily'!J17 -> 0
... A30: Maldives at Landaa Giraavaru | B30: =B29+1 -> 29 | C30: 7 | D30: 2021 | E30: ='Maldives at LG Daily'!D33 -> 0 | F30: 0.93 | G30: ='Maldives at LG Daily'!F33 -> 0 | H30: 1.24 | I30: ='Maldives at LG Daily'!H33 -> 0 | J30: 2.16 | K30: ='Maldives at LG Daily'!I33 -> 0 | L30: ='Maldives at LG Daily'!J33 -> 0
A31: Maldives at Landaa Giraavaru | B31: 30 | C31: 7 | D31: 2021 | E31: ='Maldives at LG Daily'!D34 -> 0 | F31: 0.93 | G31: ='Maldives at LG Daily'!F34 -> 0 | H31: 1.24 | I31: ='Maldives at LG Daily'!H34 -> 0 | J31: 2.16 | K31: ='Maldives at LG Daily'!I34 -> 0 | L31: ='Maldives at LG Daily'!J34 -> 0
A32: Maldives at Landaa Giraavaru | B32: 31 | C32: 7 | D32: 2021 | E32: ='Maldives at LG Daily'!D35 -> 0 | F32: 0.93 | G32: ='Maldives at LG Daily'!F35 -> 0 | H32: 1.24 | I32: ='Maldives at LG Daily'!H35 -> 0 | J32: 2.16 | K32: ='Maldives at LG Daily'!I35 -> 0 | L32: ='Maldives at LG Daily'!J35 -> 0

Sheet Maldives at LG Daily
A2: Days | C2: Electricity Meter (KWh) | E2: Gas Kg | G2: Water m3
A3: Date | C3: Reading KWH | D3: Difference KWH | E3: Reading Kg | F3: Difference Kg | G3: Reading m³ | H3: Daily Consumption m³ | I3: ROOM NIGHTS | J3: TOTAL GUESTS
A4: 44408 | C4: ='[1]Maldives at LG Daily'!$C$35 -> 92090395 | D4: =D35 -> 0 | E4: ='Gas-2'!G5 -> 0 | F4: 90 | G4: =SUM(WATER!G6,WATER!L6,WATER!Q6,WATER!B6) -> 979486 | H4: 423 | I4: 23 | J4: 251
A5: =A4+1 -> 44409 | C5: =SUM('GENSET #1'!C10+'GENSET #2'!C10+'GENSET #3'!C10+'GENSET #4'!C10+'GENSET #5'!C10) -> 92116139 | D5: =IF((C5-C4<0), "0",C5-C4) -> 25744 | E5: ='Gas-2'!G6 -> 225 | F5: =IF((E5-E4<0), "0",E5-E4) -> 225 | G5: =SUM(WATER!C6,WATER!H6,WATER!M6,WATER!R6) -> 979861 | H5: 418 | I5: 18 | J5: 196
A6: =A5+1 -> 44410 | C6: =SUM('GENSET #1'!C11+'GENSET #2'!C11+'GENSET #3'!C11+'GENSET #4'!C11+'GENSET #5'!C11) -> 92142745 | D6: =IF((C6-C5<0), "0",C6-C5) -> 26606 | E6: ='Gas-2'!G7 -> 180 | F6: =IF((E6-E5<0), "0",E6-E5) -> 0 | G6: =SUM(WATER!C7,WATER!H7,WATER!M7,WATER!R7) -> 980251 | H6: =IF((G6-G5<0), "0",G6-G5) -> 390 | I6: 23 | J6: 225
A7: =A6+1 -> 44411 | C7: =SUM('GENSET #1'!C12+'GENSET #2'!C12+'GENSET #3'!C12+'GENSET #4'!C12+'GENSET #5'!C12) -> 92169588 | D7: =IF((C7-C6<0), "0",C7-C6) -> 26843 | E7: ='Gas-2'!G8 -> 270 | F7: =IF((E7-E6<0), "0",E7-E6) -> 90 | G7: =SUM(WATER!C8,WATER!H8,WATER!M8,WATER!R8) -> 980680 | H7: =IF((G7-G6<0), "0",G7-G6) -> 429 | I7: 26 | J7: 243
A8: =A7+1 -> 44412 | C8: =SUM('GENSET #1'!C13+'GENSET #2'!C13+'GENSET #3'!C13+'GENSET #4'!C13+'GENSET #5'!C13) -> 92196873 | D8: =IF((C8-C7<0), "0",C8-C7) -> 27285 | E8: ='Gas-2'!G9 -> 180 | F8: =IF((E8-E7<0), "0",E8-E7) -> 0 | G8: =SUM(WATER!C9,WATER!H9,WATER!M9,WATER!R9) -> 981096 | H8: =IF((G8-G7<0), "0",G8-G7) -> 416 | I8: 33 | J8: 295
A9: =A8+1 -> 44413 | C9: =SUM('GENSET #1'!C14+'GENSET #2'!C14+'GENSET #3'!C14+'GENSET #4'!C14+'GENSET #5'!C14) -> 92226378 | D9: =IF((C9-C8<0), "0",C9-C8) -> 29505 | E9: ='Gas-2'!G10 -> 270 | F9: =IF((E9-E8<0), "0",E9-E8) -> 90 | G9: =SUM(WATER!C10,WATER!H10,WATER!M10,WATER!R10) -> 981483 | H9: =IF((G9-G8<0), "0",G9-G8) -> 387 | I9: 30 | J9: 256
A10: =A9+1 -> 44414 | C10: =SUM('GENSET #1'!C15+'GENSET #2'!C15+'GENSET #3'!C15+'GENSET #4'!C15+'GENSET #5'!C15) -> 92250887 | D10: =IF((C10-C9<0), "0",C10-C9) -> 24509 | E10: ='Gas-2'!G11 -> 225 | F10: =IF((E10-E9<0), "0",E10-E9) -> 0 | G10: =SUM(WATER!C11,WATER!H11,WATER!M11,WATER!R11) -> 981892 | H10: =IF((G10-G9<0), "0",G10-G9) -> 409 | I10: 33 | J10: 272
A11: =A10+1 -> 44415 | C11: =SUM('GENSET #1'!C16+'GENSET #2'!C16+'GENSET #3'!C16+'GENSET #4'!C16+'GENSET #5'!C16) -> 92278240 | D11: =IF((C11-C10<0), "0",C11-C10) -> 27353 | E11: ='Gas-2'!G12 -> 225 | F11: =IF((E11-E10<0), "0",E11-E10) -> 0 | G11: =SUM(WATER!C12,WATER!H12,WATER!M12,WATER!R12) -> 982220 | H11: =IF((G11-G10<0), "0",G11-G10) -> 328 | I11: 36 | J11: 308
A12: =A11+1 -> 44416 | C12: =SUM('GENSET #1'!C17+'GENSET #2'!C17+'GENSET #3'!C17+'GENSET #4'!C17+'GENSET #5'!C17) -> 92306367 | D12: =IF((C12-C11<0), "0",C12-C11) -> 28127 | E12: ='Gas-2'!G13 -> 225 | F12: =IF((E12-E11<0), "0",E12-E11) -> 0 | G12: =SUM(WATER!C13,WATER!H13,WATER!M13,WATER!R13) -> 982618 | H12: =IF((G12-G11<0), "0",G12-G11) -> 398 | I12: 45 | J12: 311
A13: =A12+1 -> 44417 | C13: =SUM('GENSET #1'!C18+'GENSET #2'!C18+'GENSET #3'!C18+'GENSET #4'!C18+'GENSET #5'!C18) -> 92334085 | D13: =IF((C13-C12<0), "0",C13-C12) -> 27718 | E13: ='Gas-2'!G14 -> 225 | F13: =IF((E13-E12<0), "0",E13-E12) -> 0 | G13: =SUM(WATER!C14,WATER!H14,WATER!M14,WATER!R14) -> 982982 | H13: =IF((G13-G12<0), "0",G13-G12) -> 364 | I13: 41 | J13: 281
A14: =A13+1 -> 44418 | C14: =SUM('GENSET #1'!C19+'GENSET #2'!C19+'GENSET #3'!C19+'GENSET #4'!C19+'GENSET #5'!C19) -> 92362434 | D14: =IF((C14-C13<0), "0",C14-C13) -> 28349 | E14: ='Gas-2'!G15 -> 270 | F14: =IF((E14-E13<0), "0",E14-E13) -> 45 | G14: =SUM(WATER!C15,WATER!H15,WATER!M15,WATER!R15) -> 983344 | H14: =IF((G14-G13<0), "0",G14-G13) -> 362 | I14: 37 | J14: 255
A15: =A14+1 -> 44419 | C15: =SUM('GENSET #1'!C20+'GENSET #2'!C20+'GENSET #3'!C20+'GENSET #4'!C20+'GENSET #5'!C20) -> 92390651 | D15: =IF((C15-C14<0), "0",C15-C14) -> 28217 | E15: ='Gas-2'!G16 -> 270 | F15: =IF((E15-E14<0), "0",E15-E14) -> 0 | G15: =SUM(WATER!C16,WATER!H16,WATER!M16,WATER!R16) -> 983749 | H15: =IF((G15-G14<0), "0",G15-G14) -> 405 | I15: 36 | J15: 327
A16: =A15+1 -> 44420 | C16: =SUM('GENSET #1'!C21+'GENSET #2'!C21+'GENSET #3'!C21+'GENSET #4'!C21+'GENSET #5'!C21) -> 92419074 | D16: =IF((C16-C15<0), "0",C16-C15) -> 28423 | E16: ='Gas-2'!G17 -> 135 | F16: =IF((E16-E15<0), "0",E16-E15) -> 0 | G16: =SUM(WATER!C17,WATER!H17,WATER!M17,WATER!R17) -> 984164 | H16: =IF((G16-G15<0), "0",G16-G15) -> 415
A17: =A16+1 -> 44421 | C17: =SUM('GENSET #1'!C22+'GENSET #2'!C22+'GENSET #3'!C22+'GENSET #4'!C22+'GENSET #5'!C22) -> 0 | D17: =IF((C17-C16<0), "0",C17-C16) -> 0 | E17: ='Gas-2'!G18 -> 0 | F17: =IF((E17-E16<0), "0",E17-E16) -> 0 | G17: =SUM(WATER!C18,WATER!H18,WATER!M18,WATER!R18) -> 984570 | H17: =IF((G17-G16<0), "0",G17-G16) -> 406
A18: =A17+1 -> 44422 | C18: =SUM('GENSET #1'!C23+'GENSET #2'!C23+'GENSET #3'!C23+'GENSET #4'!C23+'GENSET #5'!C23) -> 0 | D18: =IF((C18-C17<0), "0",C18-C17) -> 0 | E18: ='Gas-2'!G19 -> 0 | F18: =IF((E18-E17<0), "0",E18-E17) -> 0 | G18: =SUM(WATER!C19,WATER!H19,WATER!M19,WATER!R19) -> 0 | H18: =IF((G18-G17<0), "0",G18-G17) -> 0
A19: =A18+1 -> 44423 | C19: =SUM('GENSET #1'!C24+'GENSET #2'!C24+'GENSET #3'!C24+'GENSET #4'!C24+'GENSET #5'!C24) -> 0 | D19: =IF((C19-C18<0), "0",C19-C18) -> 0 | E19: ='Gas-2'!G20 -> 0 | F19: =IF((E19-E18<0), "0",E19-E18) -> 0 | G19: =SUM(WATER!C20,WATER!H20,WATER!M20,WATER!R20) -> 0 | H19: =IF((G19-G18<0), "0",G19-G18) -> 0
A20: =A19+1 -> 44424 | C20: =SUM('GENSET #1'!C25+'GENSET #2'!C25+'GENSET #3'!C25+'GENSET #4'!C25+'GENSET #5'!C25) -> 0 | D20: =IF((C20-C19<0), "0",C20-C19) -> 0 | E20: ='Gas-2'!G21 -> 0 | F20: =IF((E20-E19<0), "0",E20-E19) -> 0 | G20: =SUM(WATER!C21,WATER!H21,WATER!M21,WATER!R21) -> 0 | H20: =IF((G20-G19<0), "0",G20-G19) -> 0
A21: =A20+1 -> 44425 | C21: =SUM('GENSET #1'!C26+'GENSET #2'!C26+'GENSET #3'!C26+'GENSET #4'!C26+'GENSET #5'!C26) -> 0 | D21: =IF((C21-C20<0), "0",C21-C20) -> 0 | E21: ='Gas-2'!G22 -> 0 | F21: =IF((E21-E20<0), "0",E21-E20) -> 0 | G21: =SUM(WATER!C22,WATER!H22,WATER!M22,WATER!R22) -> 0 | H21: =IF((G21-G20<0), "0",G21-G20) -> 0
A22: =A21+1 -> 44426 | C22: =SUM('GENSET #1'!C27+'GENSET #2'!C27+'GENSET #3'!C27+'GENSET #4'!C27+'GENSET #5'!C27) -> 0 | D22: =IF((C22-C21<0), "0",C22-C21) -> 0 | E22: ='Gas-2'!G23 -> 0 | F22: =IF((E22-E21<0), "0",E22-E21) -> 0 | G22: =SUM(WATER!C23,WATER!H23,WATER!M23,WATER!R23) -> 0 | H22: =IF((G22-G21<0), "0",G22-G21) -> 0
A23: =A22+1 -> 44427 | C23: =SUM('GENSET #1'!C28+'GENSET #2'!C28+'GENSET #3'!C28+'GENSET #4'!C28+'GENSET #5'!C28) -> 0 | D23: =IF((C23-C22<0), "0",C23-C22) -> 0 | E23: ='Gas-2'!G24 -> 0 | F23: =IF((E23-E22<0), "0",E23-E22) -> 0 | G23: =SUM(WATER!C24,WATER!H24,WATER!M24,WATER!R24) -> 0 | H23: =IF((G23-G22<0), "0",G23-G22) -> 0
A24: =A23+1 -> 44428 | C24: =SUM('GENSET #1'!C29+'GENSET #2'!C29+'GENSET #3'!C29+'GENSET #4'!C29+'GENSET #5'!C29) -> 0 | D24: =IF((C24-C23<0), "0",C24-C23) -> 0 | E24: ='Gas-2'!G25 -> 0 | F24: =IF((E24-E23<0), "0",E24-E23) -> 0 | G24: =SUM(WATER!C25,WATER!H25,WATER!M25,WATER!R25) -> 0 | H24: =IF((G24-G23<0), "0",G24-G23) -> 0
A25: =A24+1 -> 44429 | C25: =SUM('GENSET #1'!C30+'GENSET #2'!C30+'GENSET #3'!C30+'GENSET #4'!C30+'GENSET #5'!C30) -> 0 | D25: =IF((C25-C24<0), "0",C25-C24) -> 0 | E25: ='Gas-2'!G26 -> 0 | F25: =IF((E25-E24<0), "0",E25-E24) -> 0 | G25: =SUM(WATER!C26,WATER!H26,WATER!M26,WATER!R26) -> 0 | H25: =IF((G25-G24<0), "0",G25-G24) -> 0
A26: =A25+1 -> 44430 | C26: =SUM('GENSET #1'!C31+'GENSET #2'!C31+'GENSET #3'!C31+'GENSET #4'!C31+'GENSET #5'!C31) -> 0 | D26: =IF((C26-C25<0), "0",C26-C25) -> 0 | E26: ='Gas-2'!G27 -> 0 | F26: =IF((E26-E25<0), "0",E26-E25) -> 0 | G26: =SUM(WATER!C27,WATER!H27,WATER!M27,WATER!R27) -> 0 | H26: =IF((G26-G25<0), "0",G26-G25) -> 0
A27: =A26+1 -> 44431 | C27: =SUM('GENSET #1'!C32+'GENSET #2'!C32+'GENSET #3'!C32+'GENSET #4'!C32+'GENSET #5'!C32) -> 0 | D27: =IF((C27-C26<0), "0",C27-C26) -> 0 | E27: ='Gas-2'!G28 -> 0 | F27: =IF((E27-E26<0), "0",E27-E26) -> 0 | G27: =SUM(WATER!C28,WATER!H28,WATER!M28,WATER!R28) -> 0 | H27: =IF((G27-G26<0), "0",G27-G26) -> 0
... A35: =A34+1 -> 44439 | C35: =SUM('GENSET #1'!C40+'GENSET #2'!C40+'GENSET #3'!C40+'GENSET #4'!C40+'GENSET #5'!C40) -> 0 | D35: =IF((C35-C34<0), "0",C35-C34) -> 0 | E35: ='Gas-2'!G36 -> 0 | F35: =IF((E35-E34<0), "0",E35-E34) -> 0 | G35: =SUM(WATER!C36,WATER!H36,WATER!M36,WATER!R36) -> 0 | H35: =IF((G35-G34<0), "0",G35-G34) -> 0

Sheet Finance Only
A1: Four Seasons Landaa Giraavaru
A3: Property | B3: MLG
A4: Month | B4: August
A5: Year | B5: 2021
A7: DAY | B7: Electricity Consumption ( kwh) | C7: Diesel Consumption (Liters) | D7: Solar Power Consumption(kwh) | E7: Gas Consumption (kg) | F7: Water Consumption ( m3) | G7: Occupancy | H7: Weather | I7: Electricity Variance (Today vs Yesterday)
A8: 1 | B8: =SUM('GENSET #1:GENSET #5'!D10) -> 25744 | C8: ='Diesel consumption'!D5 -> 7390 | D8: ='SOLAR METER READING'!D9 -> 3215 | E8: ='Gas-2'!G6 -> 225 | F8: =WATER!V6 -> 375 | G8: =WATER!W6 -> 18 | H8: ='SOLAR METER READING'!E9 -> SUNNY
A9: 2 | B9: =SUM('GENSET #1:GENSET #5'!D11) -> 26606 | C9: ='Diesel consumption'!D6 -> 7010 | D9: ='SOLAR METER READING'!D10 -> 3103 | E9: ='Gas-2'!G7 -> 180 | F9: =WATER!V7 -> 390 | G9: =WATER!W7 -> 23 | H9: ='SOLAR METER READING'!E10 -> SUNNY | I9: =B9-B8 -> 862
A10: 3 | B10: =SUM('GENSET #1:GENSET #5'!D12) -> 26843 | C10: ='Diesel consumption'!D7 -> 7590 | D10: ='SOLAR METER READING'!D11 -> 3081 | E10: ='Gas-2'!G8 -> 270 | F10: =WATER!V8 -> 429 | G10: =WATER!W8 -> 26 | H10: ='SOLAR METER READING'!E11 -> SUNNY | I10: =B10-B9 -> 237
A11: 4 | B11: =SUM('GENSET #1:GENSET #5'!D13) -> 27285 | C11: ='Diesel consumption'!D8 -> 7480 | D11: ='SOLAR METER READING'!D12 -> 3158 | E11: ='Gas-2'!G9 -> 180 | F11: =WATER!V9 -> 416 | G11: =WATER!W9 -> 33 | H11: ='SOLAR METER READING'!E12 -> SUNNY | I11: =B11-B10 -> 442
A12: 5 | B12: =SUM('GENSET #1:GENSET #5'!D14) -> 29505 | C12: ='Diesel consumption'!D9 -> 7780 | D12: ='SOLAR METER READING'!D13 -> 2492 | E12: ='Gas-2'!G10 -> 270 | F12: =WATER!V10 -> 387 | G12: =WATER!W10 -> 30 | H12: ='SOLAR METER READING'!E13 -> CLOUDY | I12: =B12-B11 -> 2220
A13: 6 | B13: =SUM('GENSET #1:GENSET #5'!D15) -> 24509 | C13: ='Diesel consumption'!D10 -> 7410 | D13: ='SOLAR METER READING'!D14 -> 1206 | E13: ='Gas-2'!G11 -> 225 | F13: =WATER!V11 -> 409 | G13: =WATER!W11 -> 33 | H13: ='SOLAR METER READING'!E14 -> CLOUDY | I13: =B13-B12 -> -4996
A14: 7 | B14: =SUM('GENSET #1:GENSET #5'!D16) -> 27353 | C14: ='Diesel consumption'!D11 -> 7520 | D14: ='SOLAR METER READING'!D15 -> 2441 | E14: ='Gas-2'!G12 -> 225 | F14: =WATER!V12 -> 328 | G14: =WATER!W12 -> 36 | H14: ='SOLAR METER READING'!E15 -> CLOUDY | I14: =B14-B13 -> 2844
A15: 8 | B15: =SUM('GENSET #1:GENSET #5'!D17) -> 28127 | C15: ='Diesel consumption'!D12 -> 7700 | D15: ='SOLAR METER READING'!D16 -> 1599 | E15: ='Gas-2'!G13 -> 225 | F15: =WATER!V13 -> 398 | G15: =WATER!W13 -> 45 | H15: ='SOLAR METER READING'!E16 -> CLOUDY | I15: =B15-B14 -> 774
A16: 9 | B16: =SUM('GENSET #1:GENSET #5'!D18) -> 27718 | C16: ='Diesel consumption'!D13 -> 7850 | D16: ='SOLAR METER READING'!D17 -> 3321 | E16: ='Gas-2'!G14 -> 225 | F16: =WATER!V14 -> 364 | G16: =WATER!W14 -> 41 | H16: ='SOLAR METER READING'!E17 -> SUNNY | I16: =B16-B15 -> -409
A17: 10 | B17: =SUM('GENSET #1:GENSET #5'!D19) -> 28349 | C17: ='Diesel consumption'!D14 -> 7650 | D17: ='SOLAR METER READING'!D18 -> 2286 | E17: ='Gas-2'!G15 -> 270 | F17: =WATER!V15 -> 362 | G17: =WATER!W15 -> 37 | H17: ='SOLAR METER READING'!E18 -> CLOUDY | I17: =B17-B16 -> 631
A18: 11 | B18: =SUM('GENSET #1:GENSET #5'!D20) -> 28217 | C18: ='Diesel consumption'!D15 -> 7720 | D18: ='SOLAR METER READING'!D19 -> 2952 | E18: ='Gas-2'!G16 -> 270 | F18: =WATER!V16 -> 405 | G18: =WATER!W16 -> 36 | H18: ='SOLAR METER READING'!E19 -> SUNNY | I18: =B18-B17 -> -132
A19: 12 | B19: =SUM('GENSET #1:GENSET #5'!D21) -> 28423 | C19: ='Diesel consumption'!D16 -> 8010 | D19: ='SOLAR METER READING'!D20 -> 2946 | E19: ='Gas-2'!G17 -> 135 | F19: =WATER!V17 -> 415 | G19: =WATER!W17 -> 0 | H19: ='SOLAR METER READING'!E20 -> SUNNY | I19: =B19-B18 -> 206
A20: 13 | B20: =SUM('GENSET #1:GENSET #5'!D22) -> -92419074 | C20: ='Diesel consumption'!D17 -> -44637690 | D20: ='SOLAR METER READING'!D21 -> -2881555 | E20: ='Gas-2'!G18 -> 0 | F20: =WATER!V18 -> 406 | G20: =WATER!W18 -> 0 | H20: ='SOLAR METER READING'!E21 -> 0 | I20: =B20-B19 -> -92447497
... A38: 31 | B38: =SUM('GENSET #1:GENSET #5'!D40) -> 0 | C38: ='Diesel consumption'!D35 -> 0 | D38: ='SOLAR METER READING'!D39 -> 0 | E38: ='Gas-2'!G36 -> 0 | F38: =WATER!V36 -> 0 | G38: =WATER!W36 -> 0 | H38: ='SOLAR METER READING'!E39 -> 0 | I38: =B38-B37 -> 0
A39: Total | B39: =SUM(B8:B38) -> -92090395 | C39: =SUM(C8:C38) -> -44546580 | D39: =SUM(D8:D38) -> -2849755 | E39: =SUM(E8:E38) -> 2700 | F39: =SUM(F8:F38) -> -979486 | G39: =SUM(G8:G37)/30 -> 11.933333
A40: Avg | B40: =B39/30 -> -3069679.8 | C40: =C39/30 -> -1484886 | D40: =D39/30 -> -94991.833 | E40: =E39/30 -> 90 | F40: =F39/31 -> -31596.323

Sheet GENSET #1
C1: 1000 KVA
C3: NO#1
A6: 44409
B8: GENSET NO 1
A9: DAY | B9: YESTARDAY | C9: TODAY | D9: Final Electricity Consumption( KWh)
A10: 1 | B10: 17618058 | C10: 17619819 | D10: =C10-B10 -> 1761
A11: 2 | B11: =C10 -> 17619819 | C11: 17626689 | D11: =C11-B11 -> 6870
A12: 3 | B12: =C11 -> 17626689 | C12: 17634252 | D12: =C12-B12 -> 7563
A13: 4 | B13: =C12 -> 17634252 | C13: 17636770 | D13: =C13-B13 -> 2518
A14: 5 | B14: =C13 -> 17636770 | C14: 17645771 | D14: =C14-B14 -> 9001
A15: 6 | B15: =C14 -> 17645771 | C15: 17651070 | D15: =C15-B15 -> 5299
A16: 7 | B16: =C15 -> 17651070 | C16: 17653380 | D16: =C16-B16 -> 2310
A17: 8 | B17: =C16 -> 17653380 | C17: 17659940 | D17: =C17-B17 -> 6560
A18: 9 | B18: =C17 -> 17659940 | C18: 17666513 | D18: =C18-B18 -> 6573
A19: 10 | B19: =C18 -> 17666513 | C19: 17672810 | D19: =C19-B19 -> 6297
A20: 11 | B20: =C19 -> 17672810 | C20: 17672843 | D20: =C20-B20 -> 33
A21: 12 | B21: =C20 -> 17672843 | C21: 17683136 | D21: =C21-B21 -> 10293
A22: 13 | B22: =C21 -> 17683136 | D22: =C22-B22 -> -17683136
A23: 14 | B23: =C22 -> 0 | D23: =C23-B23 -> 0
A24: 15 | B24: =C23 -> 0 | D24: =C24-B24 -> 0
A25: 16 | B25: =C24 -> 0 | D25: =C25-B25 -> 0
A26: 17 | B26: =C25 -> 0 | D26: =C26-B26 -> 0
A27: 18 | B27: =C26 -> 0 | D27: =C27-B27 -> 0
A28: 19 | B28: =C27 -> 0 | D28: =C28-B28 -> 0
A29: 20 | B29: =C28 -> 0 | D29: =C29-B29 -> 0
A30: 21 | B30: =C29 -> 0 | D30: =C30-B30 -> 0
A31: 22 | B31: =C30 -> 0 | D31: =C31-B31 -> 0
A32: 23 | B32: =C31 -> 0 | D32: =C32-B32 -> 0
A33: 24 | B33: =C32 -> 0 | D33: =C33-B33 -> 0
... A38: 29 | B38: =C37 -> 0 | D38: =C38-B38 -> 0
A39: 30 | B39: =C38 -> 0 | D39: =C39-B39 -> 0 | G39: NEW ENGINE PURCHASED FROM UK
A40: 31 | B40: =C39 -> 0 | D40: =C40-B40 -> 0
A41: Total | D41: =SUM(D10:D40) -> -17618058 | G41: INSTALLED: NOV 30 2013

Sheet GENSET #2
C1: 1600 KVA
C3: NO#2
A6: 44409
B8: GENSET NO 2
A9: DAY | B9: YESTARDAY | C9: TODAY | D9: Final Electricity Consumption( KW h)
A10: 1 | B10: 30410715 | C10: 30421989 | D10: =C10-B10 -> 11274
A11: 2 | B11: =C10 -> 30421989 | C11: 30428295 | D11: =C11-B11 -> 6306
A12: 3 | B12: =C11 -> 30428295 | C12: 30438498 | D12: =C12-B12 -> 10203
A13: 4 | B13: =C12 -> 30438498 | C13: 30448299 | D13: =C13-B13 -> 9801
A14: 5 | B14: =C13 -> 30448299 | C14: 30457686 | D14: =C14-B14 -> 9387
A15: 6 | B15: =C14 -> 30457686 | C15: 30465066 | D15: =C15-B15 -> 7380
A16: 7 | B16: =C15 -> 30465066 | C16: 30480334 | D16: =C16-B16 -> 15268
A17: 8 | B17: =C16 -> 30480334 | C17: 30490840 | D17: =C17-B17 -> 10506
A18: 9 | B18: =C17 -> 30490840 | C18: 30501479 | D18: =C18-B18 -> 10639
A19: 10 | B19: =C18 -> 30501479 | C19: 30508204 | D19: =C19-B19 -> 6725
A20: 11 | B20: =C19 -> 30508204 | C20: 30524196 | D20: =C20-B20 -> 15992
A21: 12 | B21: =C20 -> 30524196 | C21: 30532099 | D21: =C21-B21 -> 7903
A22: 13 | B22: =C21 -> 30532099 | D22: =C22-B22 -> -30532099
A23: 14 | B23: =C22 -> 0 | D23: =C23-B23 -> 0
A24: 15 | B24: =C23 -> 0 | D24: =C24-B24 -> 0
A25: 16 | B25: =C24 -> 0 | D25: =C25-B25 -> 0
A26: 17 | B26: =C25 -> 0 | D26: =C26-B26 -> 0
A27: 18 | B27: =C26 -> 0 | D27: =C27-B27 -> 0
A28: 19 | B28: =C27 -> 0 | D28: =C28-B28 -> 0
A29: 20 | B29: =C28 -> 0 | D29: =C29-B29 -> 0
A30: 21 | B30: =C29 -> 0 | D30: =C30-B30 -> 0
A31: 22 | B31: =C30 -> 0 | D31: =C31-B31 -> 0
A32: 23 | B32: =C31 -> 0 | D32: =C32-B32 -> 0
A33: 24 | B33: =C32 -> 0 | D33: =C33-B33 -> 0
... A40: 31 | B40: =C39 -> 0 | D40: =C40-B40 -> 0
A41: Total | B41: =#REF! -> #REF! | D41: =SUM(D10:D40) -> -30410715

Sheet GENSET #3
C1: 900 KVA
C3: NO#3
A6: 44409
B8: GENSET NO 3
A9: DAY | B9: YESTARDAY | C9: TODAY | D9: Final Electricity Consumption( KW h)
A10: 1 | B10: 13572734 | C10: 13581250 | D10: =C10-B10 -> 8516
A11: 2 | B11: =C10 -> 13581250 | C11: 13584756 | D11: =C11-B11 -> 3506
A12: 3 | B12: =C11 -> 13584756 | C12: 13586563 | D12: =C12-B12 -> 1807
A13: 4 | B13: =C12 -> 13586563 | C13: 13591915 | D13: =C13-B13 -> 5352
A14: 5 | B14: =C13 -> 13591915 | C14: 13597734 | D14: =C14-B14 -> 5819
A15: 6 | B15: =C14 -> 13597734 | C15: 13600008 | D15: =C15-B15 -> 2274
A16: 7 | B16: =C15 -> 13600008 | C16: 13606173 | D16: =C16-B16 -> 6165
A17: 8 | B17: =C16 -> 13606173 | C17: 13610643 | D17: =C17-B17 -> 4470
A18: 9 | B18: =C17 -> 13610643 | C18: 13615260 | D18: =C18-B18 -> 4617
A19: 10 | B19: =C18 -> 13615260 | C19: 13621687 | D19: =C19-B19 -> 6427
A20: 11 | B20: =C19 -> 13621687 | C20: 13623732 | D20: =C20-B20 -> 2045
A21: 12 | B21: =C20 -> 13623732 | C21: 13629927 | D21: =C21-B21 -> 6195
A22: 13 | B22: =C21 -> 13629927 | D22: =C22-B22 -> -13629927
A23: 14 | B23: =C22 -> 0 | D23: =C23-B23 -> 0
A24: 15 | B24: =C23 -> 0 | D24: =C24-B24 -> 0
A25: 16 | B25: =C24 -> 0 | D25: =C25-B25 -> 0
A26: 17 | B26: =C25 -> 0 | D26: =C26-B26 -> 0
A27: 18 | B27: =C26 -> 0 | D27: =C27-B27 -> 0
A28: 19 | B28: =C27 -> 0 | D28: =C28-B28 -> 0
A29: 20 | B29: =C28 -> 0 | D29: =C29-B29 -> 0
A30: 21 | B30: =C29 -> 0 | D30: =C30-B30 -> 0
A31: 22 | B31: =C30 -> 0 | D31: =C31-B31 -> 0
A32: 23 | B32: =C31 -> 0 | D32: =C32-B32 -> 0
A33: 24 | B33: =C32 -> 0 | D33: =C33-B33 -> 0
... A40: 31 | B40: =C39 -> 0 | D40: =C40-B40 -> 0
A41: Total | B41: =#REF! -> #REF! | D41: =SUM(D10:D40) -> -13572734

Sheet GENSET #4
C1: 500 KVA
C3: NO#4
A6: 44409
B8: GENSET NO 4
A9: DAY | B9: YESTARDAY | C9: TODAY | D9: Final Electricity Consumption( KW h)
A10: 1 | B10: 11841888 | C10: 11841888 | D10: =C10-B10 -> 0
A11: 2 | B11: =C10 -> 11841888 | C11: 11844915 | D11: =C11-B11 -> 3027
A12: 3 | B12: =C11 -> 11844915 | C12: 11846904 | D12: =C12-B12 -> 1989
A13: 4 | B13: =C12 -> 11846904 | C13: 11850611 | D13: =C13-B13 -> 3707
A14: 5 | B14: =C13 -> 11850611 | C14: 11850611 | D14: =C14-B14 -> 0
A15: 6 | B15: =C14 -> 11850611 | C15: 11853072 | D15: =C15-B15 -> 2461
A16: 7 | B16: =C15 -> 11853072 | C16: 11854373 | D16: =C16-B16 -> 1301
A17: 8 | B17: =C16 -> 11854373 | C17: 11855921 | D17: =C17-B17 -> 1548
A18: 9 | B18: =C17 -> 11855921 | C18: 11856656 | D18: =C18-B18 -> 735
A19: 10 | B19: =C18 -> 11856656 | C19: 11858413 | D19: =C19-B19 -> 1757
A20: 11 | B20: =C19 -> 11858413 | C20: 11860306 | D20: =C20-B20 -> 1893
A21: 12 | B21: =C20 -> 11860306 | C21: 11863519 | D21: =C21-B21 -> 3213
A22: 13 | B22: =C21 -> 11863519 | D22: =C22-B22 -> -11863519
A23: 14 | B23: =C22 -> 0 | D23: =C23-B23 -> 0
A24: 15 | B24: =C23 -> 0 | D24: =C24-B24 -> 0
A25: 16 | B25: =C24 -> 0 | D25: =C25-B25 -> 0
A26: 17 | B26: =C25 -> 0 | D26: =C26-B26 -> 0
A27: 18 | B27: =C26 -> 0 | D27: =C27-B27 -> 0
A28: 19 | B28: =C27 -> 0 | D28: =C28-B28 -> 0
A29: 20 | B29: =C28 -> 0 | D29: =C29-B29 -> 0
A30: 21 | B30: =C29 -> 0 | D30: =C30-B30 -> 0
A31: 22 | B31: =C30 -> 0 | D31: =C31-B31 -> 0
A32: 23 | B32: =C31 -> 0 | D32: =C32-B32 -> 0
A33: 24 | B33: =C32 -> 0 | D33: =C33-B33 -> 0
... A40: 31 | B40: =C39 -> 0 | D40: =C40-B40 -> 0
A41: Total | B41: =#REF! -> #REF! | D41: =SUM(D10:D40) -> -11841888

Sheet GENSET #5
C1: 1000 KVA
C3: NO#5
A6: 44409
B8: GENSET NO 5
A9: DAY | B9: YESTARDAY | C9: TODAY | D9: Final Electricity Consumption( KWh)
A10: 1 | B10: 18647000 | C10: 18651193 | D10: =C10-B10 -> 4193
A11: 2 | B11: =C10 -> 18651193 | C11: 18658090 | D11: =C11-B11 -> 6897
A12: 3 | B12: =C11 -> 18658090 | C12: 18663371 | D12: =C12-B12 -> 5281
A13: 4 | B13: =C12 -> 18663371 | C13: 18669278 | D13: =C13-B13 -> 5907
A14: 5 | B14: =C13 -> 18669278 | C14: 18674576 | D14: =C14-B14 -> 5298
A15: 6 | B15: =C14 -> 18674576 | C15: 18681671 | D15: =C15-B15 -> 7095
A16: 7 | B16: =C15 -> 18681671 | C16: 18683980 | D16: =C16-B16 -> 2309
A17: 8 | B17: =C16 -> 18683980 | C17: 18689023 | D17: =C17-B17 -> 5043
A18: 9 | B18: =C17 -> 18689023 | C18: 18694177 | D18: =C18-B18 -> 5154
A19: 10 | B19: =C18 -> 18694177 | C19: 18701320 | D19: =C19-B19 -> 7143
A20: 11 | B20: =C19 -> 18701320 | C20: 18709574 | D20: =C20-B20 -> 8254
A21: 12 | B21: =C20 -> 18709574 | C21: 18710393 | D21: =C21-B21 -> 819
A22: 13 | B22: =C21 -> 18710393 | D22: =C22-B22 -> -18710393
A23: 14 | B23: =C22 -> 0 | D23: =C23-B23 -> 0
A24: 15 | B24: =C23 -> 0 | D24: =C24-B24 -> 0
A25: 16 | B25: =C24 -> 0 | D25: =C25-B25 -> 0
A26: 17 | B26: =C25 -> 0 | D26: =C26-B26 -> 0
A27: 18 | B27: =C26 -> 0 | D27: =C27-B27 -> 0
A28: 19 | B28: =C27 -> 0 | D28: =C28-B28 -> 0
A29: 20 | B29: =C28 -> 0 | D29: =C29-B29 -> 0
A30: 21 | B30: =C29 -> 0 | D30: =C30-B30 -> 0
A31: 22 | B31: =C30 -> 0 | D31: =C31-B31 -> 0
A32: 23 | B32: =C31 -> 0 | D32: =C32-B32 -> 0
A33: 24 | B33: =C32 -> 0 | D33: =C33-B33 -> 0
... A40: 31 | B40: =C39 -> 0 | D40: =C40-B40 -> 0
A41: Total | D41: =SUM(D10:D40) -> -18647000

Sheet Diesel consumption
A1: Diesel Consumption - Powerhouse | F1: Diesel Tank Jetty Meter
A2: 44409
D3: Liters | F3: Boat meter Reading
A4: Date | B4: Yesterday | C4: Today | D4: ConsumptionIn 24 hrs | F4: Yesterday | G4: Today | H4: Consumption (Liters) | J4: In Barrels | L4: Carbon Emmision
A5: 1 | B5: 44546580 | C5: 44553970 | D5: =C5-B5 -> 7390 | F5: 726690 | G5: 727310 | H5: =G5-F5 -> 620 | J5: =D5/200 -> 36.95 | L5: =2.68*D5 -> 19805.2 | M5: =L5/1000 -> 19.8052
A6: 2 | B6: =C5 -> 44553970 | C6: 44560980 | D6: =C6-B6 -> 7010 | F6: =G5 -> 727310 | G6: 729120 | H6: =G6-F6 -> 1810 | J6: =D6/200 -> 35.05 | L6: =2.68*D6 -> 18786.8 | M6: =L6/1000 -> 18.7868
A7: 3 | B7: =C6 -> 44560980 | C7: 44568570 | D7: =C7-B7 -> 7590 | F7: =G6 -> 729120 | G7: 729740 | H7: =G7-F7 -> 620 | J7: =D7/200 -> 37.95 | L7: =2.68*D7 -> 20341.2 | M7: =L7/1000 -> 20.3412
A8: 4 | B8: =C7 -> 44568570 | C8: 44576050 | D8: =C8-B8 -> 7480 | F8: =G7 -> 729740 | G8: 729940 | H8: =G8-F8 -> 200 | J8: =D8/200 -> 37.4 | L8: =2.68*D8 -> 20046.4 | M8: =L8/1000 -> 20.0464
A9: 5 | B9: =C8 -> 44576050 | C9: 44583830 | D9: =C9-B9 -> 7780 | F9: =G8 -> 729940 | G9: 731930 | H9: =G9-F9 -> 1990 | J9: =D9/200 -> 38.9 | L9: =2.68*D9 -> 20850.4 | M9: =L9/1000 -> 20.8504
A10: 6 | B10: =C9 -> 44583830 | C10: 44591240 | D10: =C10-B10 -> 7410 | F10: =G9 -> 731930 | G10: 733150 | H10: =G10-F10 -> 1220 | J10: =D10/200 -> 37.05 | L10: =2.68*D10 -> 19858.8 | M10: =L10/1000 -> 19.8588
A11: 7 | B11: =C10 -> 44591240 | C11: 44598760 | D11: =C11-B11 -> 7520 | F11: =G10 -> 733150 | G11: 733150 | H11: =G11-F11 -> 0 | J11: =D11/200 -> 37.6 | L11: =2.68*D11 -> 20153.6 | M11: =L11/1000 -> 20.1536
A12: 8 | B12: =C11 -> 44598760 | C12: 44606460 | D12: =C12-B12 -> 7700 | F12: =G11 -> 733150 | G12: 733410 | H12: =G12-F12 -> 260 | J12: =D12/200 -> 38.5 | L12: =2.68*D12 -> 20636 | M12: =L12/1000 -> 20.636
A13: 9 | B13: =C12 -> 44606460 | C13: 44614310 | D13: =C13-B13 -> 7850 | F13: =G12 -> 733410 | G13: 735440 | H13: =G13-F13 -> 2030 | J13: =D13/200 -> 39.25 | L13: =2.68*D13 -> 21038 | M13: =L13/1000 -> 21.038
A14: 10 | B14: =C13 -> 44614310 | C14: 44621960 | D14: =C14-B14 -> 7650 | F14: =G13 -> 735440 | G14: 735640 | H14: =G14-F14 -> 200 | J14: =D14/200 -> 38.25 | L14: =2.68*D14 -> 20502 | M14: =L14/1000 -> 20.502
A15: 11 | B15: =C14 -> 44621960 | C15: 44629680 | D15: =C15-B15 -> 7720 | F15: =G14 -> 735640 | G15: 736740 | H15: =G15-F15 -> 1100 | J15: =D15/200 -> 38.6 | L15: =2.68*D15 -> 20689.6 | M15: =L15/1000 -> 20.6896
A16: 12 | B16: =C15 -> 44629680 | C16: 44637690 | D16: =C16-B16 -> 8010 | F16: =G15 -> 736740 | G16: 740760 | H16: =G16-F16 -> 4020 | J16: =D16/200 -> 40.05 | L16: =2.68*D16 -> 21466.8 | M16: =L16/1000 -> 21.4668
A17: 13 | B17: =C16 -> 44637690 | D17: =C17-B17 -> -44637690 | F17: =G16 -> 740760 | H17: =G17-F17 -> -740760 | J17: =D17/200 -> -223188.45 | L17: =2.68*D17 -> -1.1962901e+08 | M17: =L17/1000 -> -119629.01
A18: 14 | B18: =C17 -> 0 | D18: =C18-B18 -> 0 | F18: =G17 -> 0 | H18: =G18-F18 -> 0 | J18: =D18/200 -> 0 | L18: =2.68*D18 -> 0 | M18: =L18/1000 -> 0
A19: 15 | B19: =C18 -> 0 | D19: =C19-B19 -> 0 | F19: =G18 -> 0 | H19: =G19-F19 -> 0 | J19: =D19/200 -> 0 | L19: =2.68*D19 -> 0 | M19: =L19/1000 -> 0
A20: 16 | B20: =C19 -> 0 | D20: =C20-B20 -> 0 | F20: =G19 -> 0 | H20: =G20-F20 -> 0 | J20: =D20/200 -> 0 | L20: =2.68*D20 -> 0 | M20: =L20/1000 -> 0
A21: 17 | B21: =C20 -> 0 | D21: =C21-B21 -> 0 | F21: =G20 -> 0 | H21: =G21-F21 -> 0 | J21: =D21/200 -> 0 | L21: =2.68*D21 -> 0 | M21: =L21/1000 -> 0
A22: 18 | B22: =C21 -> 0 | D22: =C22-B22 -> 0 | F22: =G21 -> 0 | H22: =G22-F22 -> 0 | J22: =D22/200 -> 0 | L22: =2.68*D22 -> 0 | M22: =L22/1000 -> 0
A23: 19 | B23: =C22 -> 0 | D23: =C23-B23 -> 0 | F23: =G22 -> 0 | H23: =G23-F23 -> 0 | J23: =D23/200 -> 0 | L23: =2.68*D23 -> 0 | M23: =L23/1000 -> 0
A24: 20 | B24: =C23 -> 0 | D24: =C24-B24 -> 0 | F24: =G23 -> 0 | H24: =G24-F24 -> 0 | J24: =D24/200 -> 0 | L24: =2.68*D24 -> 0 | M24: =L24/1000 -> 0
A25: 21 | B25: =C24 -> 0 | D25: =C25-B25 -> 0 | F25: =G24 -> 0 | H25: =G25-F25 -> 0 | J25: =D25/200 -> 0 | L25: =2.68*D25 -> 0 | M25: =L25/1000 -> 0
A26: 22 | B26: =C25 -> 0 | D26: =C26-B26 -> 0 | F26: =G25 -> 0 | H26: =G26-F26 -> 0 | J26: =D26/200 -> 0 | L26: =2.68*D26 -> 0 | M26: =L26/1000 -> 0
A27: 23 | B27: =C26 -> 0 | D27: =C27-B27 -> 0 | F27: =G26 -> 0 | H27: =G27-F27 -> 0 | J27: =D27/200 -> 0 | L27: =2.68*D27 -> 0 | M27: =L27/1000 -> 0
A28: 24 | B28: =C27 -> 0 | D28: =C28-B28 -> 0 | F28: =G27 -> 0 | H28: =G28-F28 -> 0 | J28: =D28/200 -> 0 | L28: =2.68*D28 -> 0 | M28: =L28/1000 -> 0
... A34: 30 | B34: =C33 -> 0 | D34: =C34-B34 -> 0 | F34: =G33 -> 0 | H34: =G34-F34 -> 0 | J34: =D34/200 -> 0 | L34: =2.68*D34 -> 0 | M34: =L34/1000 -> 0
A35: 31 | B35: =C34 -> 0 | D35: =C35-B35 -> 0 | F35: =G34 -> 0 | H35: =G35-F35 -> 0
D36: =SUM(D5:D35) -> -44546580 | J36: =SUM(J5:J34) -> -222732.9 | L36: =2.68*D36 -> -1.1938483e+08 | M36: =L36/1000 -> -119384.83

Sheet SOLAR METER READING
C3: solar reading
B5: 44409
B7: solar meter reading
A8: DAY | B8: YESTARDAY | C8: TODAY | D8: Final Electricity Consumption( KW h) | E8: Weather Condition
A9: 1 | B9: 2849755 | C9: 2852970 | D9: =C9-B9 -> 3215 | E9: SUNNY
A10: 2 | B10: =C9 -> 2852970 | C10: 2856073 | D10: =C10-B10 -> 3103 | E10: SUNNY
A11: 3 | B11: =C10 -> 2856073 | C11: 2859154 | D11: =C11-B11 -> 3081 | E11: SUNNY
A12: 4 | B12: =C11 -> 2859154 | C12: 2862312 | D12: =C12-B12 -> 3158 | E12: SUNNY
A13: 5 | B13: =C12 -> 2862312 | C13: 2864804 | D13: =C13-B13 -> 2492 | E13: CLOUDY | J13: 1 liter diesel | K13: 11.1 kwh
A14: 6 | B14: =C13 -> 2864804 | C14: 2866010 | D14: =C14-B14 -> 1206 | E14: CLOUDY | J14: 212.88 diesel | K14: 2363 kwh
A15: 7 | B15: =C14 -> 2866010 | C15: 2868451 | D15: =C15-B15 -> 2441 | E15: CLOUDY
A16: 8 | B16: =C15 -> 2868451 | C16: 2870050 | D16: =C16-B16 -> 1599 | E16: CLOUDY
A17: 9 | B17: =C16 -> 2870050 | C17: 2873371 | D17: =C17-B17 -> 3321 | E17: SUNNY
A18: 10 | B18: =C17 -> 2873371 | C18: 2875657 | D18: =C18-B18 -> 2286 | E18: CLOUDY
A19: 11 | B19: =C18 -> 2875657 | C19: 2878609 | D19: =C19-B19 -> 2952 | E19: SUNNY
A20: 12 | B20: =C19 -> 2878609 | C20: 2881555 | D20: =C20-B20 -> 2946 | E20: SUNNY
A21: 13 | B21: =C20 -> 2881555 | D21: =C21-B21 -> -2881555
A22: 14 | B22: =C21 -> 0 | D22: =C22-B22 -> 0
A23: 15 | B23: =C22 -> 0 | D23: =C23-B23 -> 0
A24: 16 | B24: =C23 -> 0 | D24: =C24-B24 -> 0
A25: 17 | B25: =C24 -> 0 | D25: =C25-B25 -> 0
A26: 18 | B26: =C25 -> 0 | D26: =C26-B26 -> 0
A27: 19 | B27: =C26 -> 0 | D27: =C27-B27 -> 0
A28: 20 | B28: =C27 -> 0 | D28: =C28-B28 -> 0
A29: 21 | B29: =C28 -> 0 | D29: =C29-B29 -> 0
A30: 22 | B30: =C29 -> 0 | D30: =C30-B30 -> 0
A31: 23 | B31: =C30 -> 0 | D31: =C31-B31 -> 0
A32: 24 | B32: =C31 -> 0 | D32: =C32-B32 -> 0
... A39: 31 | B39: =C38 -> 0 | D39: =C39-B39 -> 0
A40: Total | D40: =SUM(D9:D39) -> -2849755

Sheet FEEDER Consumption 
A1: 44409
A2: POWER HOUSE FEEDER READING
C3: BLU FEEDER PANEL 1 | H3: BLU FEEDER PANEL 2 | M3: POWER HOUSE FEEDER PANEL NO:3 | R3: Main Kitchen -7 | W3: Main Kitchen -10 | AB3: Water treatment Plant | AG3: Sewage treatment Plant | AL3: Laundry--8SSB | AQ3: Laundry-9 | AV3: New staff accomodation (E0) | BA3: Staff block-16(E2-E3) | BF3: Staff Block Feeder-3(E4-E5) | BK3: Management block-5 | BP3: SNR STAFF BLOCK | BU3: BOAT DOCK FEEDER - 22 | BZ3: RECEPTION | CE3: DIVE CENTER | CJ3: 301-307 | CO3: 308-314 | CT3: 315-320 | CY3: 401-407 | DD3: 408-414 | DI3: 415-420 | DN3: SPA - 1 | DS3: SPA - 2 | DX3: BLU KITCHEN - 1 | EC3: BLU KITCHEN - 2 | EH3: AL BARAKATH | EM3: STAFF KITCHEN | ER3: MANAGR BLOCK GARDEN | EW3: 121-131 | FB3: 113-120
A4: DAY | B4: Occupancy | C4: Yesterday | D4: Today | E4: Consumption | F4: Variance (Tdy vs Ystdy) | G4: % | H4: Yesterday | I4: Today | J4: Consumption | K4: Var(Tdy vs Ystdy) | L4: % | M4: Yesterday | N4: Today | O4: Consumption | P4: Var (Tdy vs Ystdy) | Q4: % | R4: Yesterday | S4: Today | T4: Consumption | U4: Var(Tdy vs Ystdy) | V4: % | W4: Yesterday | X4: Today | Y4: Consumption | Z4: Var(Tdy vs Ystdy) | AA4: % | AB4: Yesterday | AC4: Today | AD4: Consumption | AE4: Var(Tdy vs Ystdy) | AF4: % | AG4: Yesterday | AH4: Today | AI4: Consumption | AJ4: Var(Tdy vs Ystdy) | AK4: % | AL4: Yesterday | AM4: Today | AN4: Consumption | AO4: Var(Tdy vs Ystdy) | AP4: % | AQ4: Yesterday | AR4: Today | AS4: Consumption | AT4: Var(Tdy vs Ystdy) | AU4: % | AV4: Yesterday | AW4: Today | AX4: Consumption | AY4: Var(Tdy vs Ystdy) | AZ4: % | BA4: Yesterday | BB4: Today | BC4: Consumption | BD4: Var(Tdy vs Ystdy) | BE4: % | BF4: Yesterday | BG4: Today | BH4: Consumption | BI4: Var(Tdy vs Ystdy) | BJ4: % | BK4: Yesterday | BL4: Today | BM4: Consumption | BN4: Var(Tdy vs Ystdy) | BO4: % | BP4: Yesterday | BQ4: Today | BR4: Consumption | BS4: Var(Tdy vs Ystdy) | BT4: % | BU4: Yesterday | BV4: Today | BW4: Consumption | BX4: Var(Tdy vs Ystdy) | BY4: % | BZ4: Yesterday | CA4: Today | CB4: Consumption | CC4: Var(Tdy vs Ystdy) | CD4: % | CE4: Yesterday | CF4: Today | CG4: Consumption | CH4: Var(Tdy vs Ystdy) | CI4: % | CJ4: Yesterday | CK4: Today | CL4: Consumption | CM4: Var(Tdy vs Ystdy) | CN4: % | CO4: Yesterday | CP4: Today | CQ4: Consumption | CR4: Var(Tdy vs Ystdy) | CS4: % | CT4: Yesterday | CU4: Today | CV4: Consumption | CW4: Var(Tdy vs Ystdy) | CX4: % | CY4: Yesterday | CZ4: Today | DA4: Consumption | DB4: Var(Tdy vs Ystdy) | DC4: % | DD4: Yesterday | DE4: Today | DF4: Consumption | DG4: Var(Tdy vs Ystdy) | DH4: % | DI4: Yesterday | DJ4: Today | DK4: Consumption | DL4: Var(Tdy vs Ystdy) | DM4: % | DN4: Yesterday | DO4: Today | DP4: Consumption | DQ4: Var(Tdy vs Ystdy) | DR4: % | DS4: Yesterday | DT4: Today | DU4: Consumption | DV4: Var(Tdy vs Ystdy) | DW4: % | DX4: Yesterday | DY4: Today | DZ4: Consumption | EA4: Var(Tdy vs Ystdy) | EB4: % | EC4: Yesterday | ED4: Today | EE4: Consumption | EF4: Var(Tdy vs Ystdy) | EG4: % | EH4: Yesterday | EI4: Today | EJ4: Consumption | EK4: Var(Tdy vs Ystdy) | EL4: % | EM4: Yesterday | EN4: Today | EO4: Consumption | EP4: Var(Tdy vs Ystdy) | EQ4: % | ER4: Yesterday | ES4: Today | ET4: Consumption | EU4: Var(Tdy vs Ystdy) | EV4: % | EW4: Yesterday | EX4: Today | EY4: Consumption | EZ4: Var(Tdy vs Ystdy) | FA4: % | FB4: Yesterday | FC4: Today | FD4: Consumption | FE4: Var(Tdy vs Ystdy) | FF4: %
A5: 1 | B5: ='Finance Only'!G8 -> 18 | C5: 25797276 | D5: 25799595 | E5: =D5-C5 -> 2319 | H5: 23012686 | I5: 23016925 | J5: =I5-H5 -> 4239 | M5: 86714172 | N5: 86727618 | O5: =N5-M5 -> 13446 | R5: 21516 | S5: 21536 | T5: =S5-R5 -> 20 | W5: 2910539 | X5: 2913286 | Y5: =X5-W5 -> 2747 | AB5: 17818 | AC5: 17835 | AD5: =AC5-AB5 -> 17 | AG5: 790459 | AH5: 791118 | AI5: =AH5-AG5 -> 659 | AL5: 81890 | AM5: 81955 | AN5: =AM5-AL5 -> 65 | AQ5: 18457 | AR5: 18469 | AS5: =AR5-AQ5 -> 12 | AV5: 532676 | AW5: 533093 | AX5: =AW5-AV5 -> 417 | BA5: 71411 | BB5: 71496 | BC5: =BB5-BA5 -> 85 | BF5: 81256 | BG5: 81351 | BH5: =BG5-BF5 -> 95 | BK5: 12670 | BL5: 12684 | BM5: =BL5-BK5 -> 14 | BP5: 74596 | BQ5: 74736 | BR5: =BQ5-BP5 -> 140 | BU5: 39682 | BV5: 39717 | BW5: =BV5-BU5 -> 35 | BZ5: 56881 | CA5: 57003 | CB5: =CA5-BZ5 -> 122 | CE5: 17093 | CF5: 17131 | CG5: =CF5-CE5 -> 38 | CJ5: 39028 | CK5: 39121 | CL5: =CK5-CJ5 -> 93 | CO5: 30715 | CP5: 30786 | CQ5: =CP5-CO5 -> 71 | CT5: 27021 | CU5: 27070 | CV5: =CU5-CT5 -> 49 | CY5: 45440 | CZ5: 45536 | DA5: =CZ5-CY5 -> 96 | DD5: 34215 | DE5: 34304 | DF5: =DE5-DD5 -> 89 | DI5: 31620 | DJ5: 31699 | DK5: =DJ5-DI5 -> 79 | DN5: 21040 | DO5: 21087 | DP5: =DO5-DN5 -> 47 | DS5: 55671 | DT5: 55757 | DU5: =DT5-DS5 -> 86 | DX5: 38361 | DY5: 38427 | DZ5: =DY5-DX5 -> 66 | EC5: 11921 | ED5: 11943 | EE5: =ED5-EC5 -> 22 | EH5: 10828 | EI5: 10862 | EJ5: =EI5-EH5 -> 34 | EM5: 21268 | EN5: 21321 | EO5: =EN5-EM5 -> 53 | ER5: 50280 | ES5: 50705 | ET5: =ES5-ER5 -> 425 | EW5: 22069 | EX5: 24737 | EY5: =EX5-EW5 -> 2668 | FB5: 9736 | FC5: 10619 | FD5: =FC5-FB5 -> 883
A6: 2 | B6: ='Finance Only'!G9 -> 23 | C6: =D5 -> 25799595 | D6: 25801940 | E6: =D6-C6 -> 2345 | F6: =E6-E5 -> 26 | G6: =(E6/'Finance Only'!B9)*100 -> 8.8138014 | H6: =I5 -> 23016925 | I6: 23021371 | J6: =I6-H6 -> 4446 | K6: =J6-J5 -> 207 | L6: =(J6/'Finance Only'!B9)*100 -> 16.710516 | M6: =N5 -> 86727618 | N6: 86741582 | O6: =N6-M6 -> 13964 | P6: =O6-O5 -> 518 | Q6: =(O6/'Finance Only'!B9)*100 -> 52.484402 | R6: =S5 -> 21536 | S6: 21556 | T6: =S6-R6 -> 20 | U6: =T6-T5 -> 0 | V6: =(T6/'Finance Only'!B9)*100 -> 0.075171014 | W6: =X5 -> 2913286 | X6: 2916024 | Y6: =X6-W6 -> 2738 | Z6: =Y6-Y5 -> -9 | AA6: =(Y6/'Finance Only'!B9)*100 -> 10.290912 | AB6: =AC5 -> 17835 | AC6: 17854 | AD6: =AC6-AB6 -> 19 | AE6: =AD6-AD5 -> 2 | AF6: =(AD6/'Finance Only'!B9)*100 -> 0.071412463 | AG6: =AH5 -> 791118 | AH6: 791787 | AI6: =AH6-AG6 -> 669 | AJ6: =AI6-AI5 -> 10 | AK6: =(AI6/'Finance Only'!B9)*100 -> 2.5144704 | AL6: =AM5 -> 81955 | AM6: 82020 | AN6: =AM6-AL6 -> 65 | AO6: =AN6-AN5 -> 0 | AP6: =(AN6/'Finance Only'!B9)*100 -> 0.2443058 | AQ6: =AR5 -> 18469 | AR6: 18478 | AS6: =AR6-AQ6 -> 9 | AT6: =AS6-AS5 -> -3 | AU6: =(AS6/'Finance Only'!B9)*100 -> 0.033826956 | AV6: =AW5 -> 533093 | AW6: 533492 | AX6: =AW6-AV6 -> 399 | AY6: =AX6-AX5 -> -18 | AZ6: =(AX6/'Finance Only'!B9)*100 -> 1.4996617 | BA6: =BB5 -> 71496 | BB6: 71585 | BC6: =BB6-BA6 -> 89 | BD6: =BC6-BC5 -> 4 | BE6: =(BC6/'Finance Only'!B9)*100 -> 0.33451101 | BF6: =BG5 -> 81351 | BG6: 81434 | BH6: =BG6-BF6 -> 83 | BI6: =BH6-BH5 -> -12 | BJ6: =(BH6/'Finance Only'!B9)*100 -> 0.31195971 | BK6: =BL5 -> 12684 | BL6: 12698 | BM6: =BL6-BK6 -> 14 | BN6: =BM6-BM5 -> 0 | BO6: =(BM6/'Finance Only'!B9)*100 -> 0.05261971 | BP6: =BQ5 -> 74736 | BQ6: 74854 | BR6: =BQ6-BP6 -> 118 | BS6: =BR6-BR5 -> -22 | BT6: =(BR6/'Finance Only'!B9)*100 -> 0.44350898 | BU6: =BV5 -> 39717 | BV6: 39757 | BW6: =BV6-BU6 -> 40 | BX6: =BW6-BW5 -> 5 | BY6: =(BW6/'Finance Only'!B9)*100 -> 0.15034203 | BZ6: =CA5 -> 57003 | CA6: 57124 | CB6: =CA6-BZ6 -> 121 | CC6: =CB6-CB5 -> -1 | CD6: =(CB6/'Finance Only'!B9)*100 -> 0.45478464 | CE6: =CF5 -> 17131 | CF6: 17169 | CG6: =CF6-CE6 -> 38 | CH6: =CG6-CG5 -> 0 | CI6: =(CG6/'Finance Only'!B9)*100 -> 0.14282493 | CJ6: =CK5 -> 39121 | CK6: 39209 | CL6: =CK6-CJ6 -> 88 | CM6: =CL6-CL5 -> -5 | CN6: =(CL6/'Finance Only'!B9)*100 -> 0.33075246 | CO6: =CP5 -> 30786 | CP6: 30856 | CQ6: =CP6-CO6 -> 70 | CR6: =CQ6-CQ5 -> -1 | CS6: =(CQ6/'Finance Only'!B9)*100 -> 0.26309855 | CT6: =CU5 -> 27070 | CU6: 27125 | CV6: =CU6-CT6 -> 55 | CW6: =CV6-CV5 -> 6 | CX6: =(CV6/'Finance Only'!B9)*100 -> 0.20672029 | CY6: =CZ5 -> 45536 | CZ6: 45644 | DA6: =CZ6-CY6 -> 108 | DB6: =DA6-DA5 -> 12 | DC6: =(DA6/'Finance Only'!B9)*100 -> 0.40592348 | DD6: =DE5 -> 34304 | DE6: 34388 | DF6: =DE6-DD6 -> 84 | DG6: =DF6-DF5 -> -5 | DH6: =(DF6/'Finance Only'!B9)*100 -> 0.31571826 | DI6: =DJ5 -> 31699 | DJ6: 31785 | DK6: =DJ6-DI6 -> 86 | DL6: =DK6-DK5 -> 7 | DM6: =(DK6/'Finance Only'!B9)*100 -> 0.32323536 | DN6: =DO5 -> 21087 | DO6: 21135 | DP6: =DO6-DN6 -> 48 | DQ6: =DP6-DP5 -> 1 | DR6: =(DP6/'Finance Only'!B9)*100 -> 0.18041043 | DS6: =DT5 -> 55757 | DT6: 55843 | DU6: =DT6-DS6 -> 86 | DV6: =DU6-DU5 -> 0 | DW6: =(DU6/'Finance Only'!B9)*100 -> 0.32323536 | DX6: =DY5 -> 38427 | DY6: 38493 | DZ6: =DY6-DX6 -> 66 | EA6: =DZ6-DZ5 -> 0 | EB6: =(DZ6/'Finance Only'!B9)*100 -> 0.24806435 | EC6: =ED5 -> 11943 | ED6: 11966 | EE6: =ED6-EC6 -> 23 | EF6: =EE6-EE5 -> 1 | EG6: =(EE6/'Finance Only'!B9)*100 -> 0.086446666 | EH6: =EI5 -> 10862 | EI6: 10895 | EJ6: =EI6-EH6 -> 33 | EK6: =EJ6-EJ5 -> -1 | EL6: =(EJ6/'Finance Only'!B9)*100 -> 0.12403217 | EM6: =EN5 -> 21321 | EN6: 21367 | EO6: =EN6-EM6 -> 46 | EP6: =EO6-EO5 -> -7 | EQ6: =(EO6/'Finance Only'!B9)*100 -> 0.17289333 | ER6: =ES5 -> 50705 | ES6: 50705 | ET6: =ES6-ER6 -> 0 | EU6: =ET6-ET5 -> -425 | EV6: =(ET6/'Finance Only'!B9)*100 -> 0 | EW6: =EX5 -> 24737 | EX6: 27191 | EY6: =EX6-EW6 -> 2454 | EZ6: =EY6-EY5 -> -214 | FA6: =(EY6/'Finance Only'!G9)*100 -> 10669.565 | FB6: =FC5 -> 10619 | FC6: 12389 | FD6: =FC6-FB6 -> 1770 | FE6: =FD6-FD5 -> 887 | FF6: =(FD6/'Finance Only'!L9)*100 -> #DIV/0!
A7: 3 | B7: ='Finance Only'!G10 -> 26 | C7: =D6 -> 25801940 | D7: 25804235 | E7: =D7-C7 -> 2295 | F7: =E7-E6 -> -50 | G7: =(E7/'Finance Only'!B10)*100 -> 8.549715 | H7: =I6 -> 23021371 | I7: 23025911 | J7: =I7-H7 -> 4540 | K7: =J7-J6 -> 94 | L7: =(J7/'Finance Only'!B10)*100 -> 16.913162 | M7: =N6 -> 86741582 | N7: 86755303 | O7: =N7-M7 -> 13721 | P7: =O7-O6 -> -243 | Q7: =(O7/'Finance Only'!B10)*100 -> 51.115747 | R7: =S6 -> 21556 | S7: 21577 | T7: =S7-R7 -> 21 | U7: =T7-T6 -> 1 | V7: =(T7/'Finance Only'!B10)*100 -> 0.078232686 | W7: =X6 -> 2916024 | X7: 2918746 | Y7: =X7-W7 -> 2722 | Z7: =Y7-Y6 -> -16 | AA7: =(Y7/'Finance Only'!B10)*100 -> 10.140446 | AB7: =AC6 -> 17854 | AC7: 17871 | AD7: =AC7-AB7 -> 17 | AE7: =AD7-AD6 -> -2 | AF7: =(AD7/'Finance Only'!B10)*100 -> 0.063331222 | AG7: =AH6 -> 791787 | AH7: 792504 | AI7: =AH7-AG7 -> 717 | AJ7: =AI7-AI6 -> 48 | AK7: =(AI7/'Finance Only'!B10)*100 -> 2.6710874 | AL7: =AM6 -> 82020 | AM7: 82085 | AN7: =AM7-AL7 -> 65 | AO7: =AN7-AN6 -> 0 | AP7: =(AN7/'Finance Only'!B10)*100 -> 0.24214879 | AQ7: =AR6 -> 18478 | AR7: 18492 | AS7: =AR7-AQ7 -> 14 | AT7: =AS7-AS6 -> 5 | AU7: =(AS7/'Finance Only'!B10)*100 -> 0.052155124 | AV7: =AW6 -> 533492 | AW7: 533892 | AX7: =AW7-AV7 -> 400 | AY7: =AX7-AX6 -> 1 | AZ7: =(AX7/'Finance Only'!B10)*100 -> 1.4901464 | BA7: =BB6 -> 71585 | BB7: 71676 | BC7: =BB7-BA7 -> 91 | BD7: =BC7-BC6 -> 2 | BE7: =(BC7/'Finance Only'!B10)*100 -> 0.33900831 | BF7: =BG6 -> 81434 | BG7: 81519 | BH7: =BG7-BF7 -> 85 | BI7: =BH7-BH6 -> 2 | BJ7: =(BH7/'Finance Only'!B10)*100 -> 0.31665611 | BK7: =BL6 -> 12698 | BL7: 12712 | BM7: =BL7-BK7 -> 14 | BN7: =BM7-BM6 -> 0 | BO7: =(BM7/'Finance Only'!B10)*100 -> 0.052155124 | BP7: =BQ6 -> 74854 | BQ7: 74959 | BR7: =BQ7-BP7 -> 105 | BS7: =BR7-BR6 -> -13 | BT7: =(BR7/'Finance Only'!B10)*100 -> 0.39116343 | BU7: =BV6 -> 39757 | BV7: 39796 | BW7: =BV7-BU7 -> 39 | BX7: =BW7-BW6 -> -1 | BY7: =(BW7/'Finance Only'!B10)*100 -> 0.14528927 | BZ7: =CA6 -> 57124 | CA7: 57249 | CB7: =CA7-BZ7 -> 125 | CC7: =CB7-CB6 -> 4 | CD7: =(CB7/'Finance Only'!B10)*100 -> 0.46567075 | CE7: =CF6 -> 17169 | CF7: 17207 | CG7: =CF7-CE7 -> 38 | CH7: =CG7-CG6 -> 0 | CI7: =(CG7/'Finance Only'!B10)*100 -> 0.14156391 | CJ7: =CK6 -> 39209 | CK7: 39308 | CL7: =CK7-CJ7 -> 99 | CM7: =CL7-CL6 -> 11 | CN7: =(CL7/'Finance Only'!B10)*100 -> 0.36881124 | CO7: =CP6 -> 30856 | CP7: 30925 | CQ7: =CP7-CO7 -> 69 | CR7: =CQ7-CQ6 -> -1 | CS7: =(CQ7/'Finance Only'!B10)*100 -> 0.25705026 | CT7: =CU6 -> 27125 | CU7: 27171 | CV7: =CU7-CT7 -> 46 | CW7: =CV7-CV6 -> -9 | CX7: =(CV7/'Finance Only'!B10)*100 -> 0.17136684 | CY7: =CZ6 -> 45644 | CZ7: 45747 | DA7: =CZ7-CY7 -> 103 | DB7: =DA7-DA6 -> -5 | DC7: =(DA7/'Finance Only'!B10)*100 -> 0.3837127 | DD7: =DE6 -> 34388 | DE7: 34484 | DF7: =DE7-DD7 -> 96 | DG7: =DF7-DF6 -> 12 | DH7: =(DF7/'Finance Only'!B10)*100 -> 0.35763514 | DI7: =DJ6 -> 31785 | DJ7: 31875 | DK7: =DJ7-DI7 -> 90 | DL7: =DK7-DK6 -> 4 | DM7: =(DK7/'Finance Only'!B10)*100 -> 0.33528294 | DN7: =DO6 -> 21135 | DO7: 21181 | DP7: =DO7-DN7 -> 46 | DQ7: =DP7-DP6 -> -2 | DR7: =(DP7/'Finance Only'!B10)*100 -> 0.17136684 | DS7: =DT6 -> 55843 | DT7: 55929 | DU7: =DT7-DS7 -> 86 | DV7: =DU7-DU6 -> 0 | DW7: =(DU7/'Finance Only'!B10)*100 -> 0.32038148 | DX7: =DY6 -> 38493 | DY7: 38558 | DZ7: =DY7-DX7 -> 65 | EA7: =DZ7-DZ6 -> -1 | EB7: =(DZ7/'Finance Only'!B10)*100 -> 0.24214879 | EC7: =ED6 -> 11966 | ED7: 11990 | EE7: =ED7-EC7 -> 24 | EF7: =EE7-EE6 -> 1 | EG7: =(EE7/'Finance Only'!B10)*100 -> 0.089408784 | EH7: =EI6 -> 10895 | EI7: 10928 | EJ7: =EI7-EH7 -> 33 | EK7: =EJ7-EJ6 -> 0 | EL7: =(EJ7/'Finance Only'!B10)*100 -> 0.12293708 | EM7: =EN6 -> 21367 | EN7: 21417 | EO7: =EN7-EM7 -> 50 | EP7: =EO7-EO6 -> 4 | EQ7: =(EO7/'Finance Only'!B10)*100 -> 0.1862683 | ER7: =ES6 -> 50705 | ES7: 51536 | ET7: =ES7-ER7 -> 831 | EU7: =ET7-ET6 -> 831 | EV7: =(ET7/'Finance Only'!B10)*100 -> 3.0957792 | EW7: =EX6 -> 27191 | EX7: 31137 | EY7: =EX7-EW7 -> 3946 | EZ7: =EY7-EY6 -> 1492 | FA7: =(EY7/'Finance Only'!G10)*100 -> 15176.923 | FB7: =FC6 -> 12389 | FC7: 14242 | FD7: =FC7-FB7 -> 1853 | FE7: =FD7-FD6 -> 83 | FF7: =(FD7/'Finance Only'!L10)*100 -> #DIV/0!
A8: 4 | B8: ='Finance Only'!G11 -> 33 | C8: =D7 -> 25804235 | D8: 25806502 | E8: =D8-C8 -> 2267 | F8: =E8-E7 -> -28 | G8: =(E8/'Finance Only'!B11)*100 -> 8.3085945 | H8: =I7 -> 23025911 | I8: 23030729 | J8: =I8-H8 -> 4818 | K8: =J8-J7 -> 278 | L8: =(J8/'Finance Only'!B11)*100 -> 17.658054 | M8: =N7 -> 86755303 | N8: 86769827 | O8: =N8-M8 -> 14524 | P8: =O8-O7 -> 803 | Q8: =(O8/'Finance Only'!B11)*100 -> 53.230713 | R8: =S7 -> 21577 | S8: 21599 | T8: =S8-R8 -> 22 | U8: =T8-T7 -> 1 | V8: =(T8/'Finance Only'!B11)*100 -> 0.080630383 | W8: =X7 -> 2918746 | X8: 2921641 | Y8: =X8-W8 -> 2895 | Z8: =Y8-Y7 -> 173 | AA8: =(Y8/'Finance Only'!B11)*100 -> 10.610225 | AB8: =AC7 -> 17871 | AC8: 17890 | AD8: =AC8-AB8 -> 19 | AE8: =AD8-AD7 -> 2 | AF8: =(AD8/'Finance Only'!B11)*100 -> 0.069635331 | AG8: =AH7 -> 792504 | AH8: 793121 | AI8: =AH8-AG8 -> 617 | AJ8: =AI8-AI7 -> -100 | AK8: =(AI8/'Finance Only'!B11)*100 -> 2.2613157 | AL8: =AM7 -> 82085 | AM8: 82152 | AN8: =AM8-AL8 -> 67 | AO8: =AN8-AN7 -> 2 | AP8: =(AN8/'Finance Only'!B11)*100 -> 0.24555617 | AQ8: =AR7 -> 18492 | AR8: 18502 | AS8: =AR8-AQ8 -> 10 | AT8: =AS8-AS7 -> -4 | AU8: =(AS8/'Finance Only'!B11)*100 -> 0.036650174 | AV8: =AW7 -> 533892 | AW8: 534281 | AX8: =AW8-AV8 -> 389 | AY8: =AX8-AX7 -> -11 | AZ8: =(AX8/'Finance Only'!B11)*100 -> 1.4256918 | BA8: =BB7 -> 71676 | BB8: 71767 | BC8: =BB8-BA8 -> 91 | BD8: =BC8-BC7 -> 0 | BE8: =(BC8/'Finance Only'!B11)*100 -> 0.33351658 | BF8: =BG7 -> 81519 | BG8: 81606 | BH8: =BG8-BF8 -> 87 | BI8: =BH8-BH7 -> 2 | BJ8: =(BH8/'Finance Only'!B11)*100 -> 0.31885651 | BK8: =BL7 -> 12712 | BL8: 12725 | BM8: =BL8-BK8 -> 13 | BN8: =BM8-BM7 -> -1 | BO8: =(BM8/'Finance Only'!B11)*100 -> 0.047645226 | BP8: =BQ7 -> 74959 | BQ8: 75087 | BR8: =BQ8-BP8 -> 128 | BS8: =BR8-BR7 -> 23 | BT8: =(BR8/'Finance Only'!B11)*100 -> 0.46912223 | BU8: =BV7 -> 39796 | BV8: 39834 | BW8: =BV8-BU8 -> 38 | BX8: =BW8-BW7 -> -1 | BY8: =(BW8/'Finance Only'!B11)*100 -> 0.13927066 | BZ8: =CA7 -> 57249 | CA8: 57377 | CB8: =CA8-BZ8 -> 128 | CC8: =CB8-CB7 -> 3 | CD8: =(CB8/'Finance Only'!B11)*100 -> 0.46912223 | CE8: =CF7 -> 17207 | CF8: 17247 | CG8: =CF8-CE8 -> 40 | CH8: =CG8-CG7 -> 2 | CI8: =(CG8/'Finance Only'!B11)*100 -> 0.1466007 | CJ8: =CK7 -> 39308 | CK8: 39411 | CL8: =CK8-CJ8 -> 103 | CM8: =CL8-CL7 -> 4 | CN8: =(CL8/'Finance Only'!B11)*100 -> 0.37749679 | CO8: =CP7 -> 30925 | CP8: 30999 | CQ8: =CP8-CO8 -> 74 | CR8: =CQ8-CQ7 -> 5 | CS8: =(CQ8/'Finance Only'!B11)*100 -> 0.27121129 | CT8: =CU7 -> 27171 | CU8: 27241 | CV8: =CU8-CT8 -> 70 | CW8: =CV8-CV7 -> 24 | CX8: =(CV8/'Finance Only'!B11)*100 -> 0.25655122 | CY8: =CZ7 -> 45747 | CZ8: 45858 | DA8: =CZ8-CY8 -> 111 | DB8: =DA8-DA7 -> 8 | DC8: =(DA8/'Finance Only'!B11)*100 -> 0.40681693 | DD8: =DE7 -> 34484 | DE8: 34577 | DF8: =DE8-DD8 -> 93 | DG8: =DF8-DF7 -> -3 | DH8: =(DF8/'Finance Only'!B11)*100 -> 0.34084662 | DI8: =DJ7 -> 31875 | DJ8: 31978 | DK8: =DJ8-DI8 -> 103 | DL8: =DK8-DK7 -> 13 | DM8: =(DK8/'Finance Only'!B11)*100 -> 0.37749679 | DN8: =DO7 -> 21181 | DO8: 21230 | DP8: =DO8-DN8 -> 49 | DQ8: =DP8-DP7 -> 3 | DR8: =(DP8/'Finance Only'!B11)*100 -> 0.17958585 | DS8: =DT7 -> 55929 | DT8: 56011 | DU8: =DT8-DS8 -> 82 | DV8: =DU8-DU7 -> -4 | DW8: =(DU8/'Finance Only'!B11)*100 -> 0.30053143 | DX8: =DY7 -> 38558 | DY8: 38625 | DZ8: =DY8-DX8 -> 67 | EA8: =DZ8-DZ7 -> 2 | EB8: =(DZ8/'Finance Only'!B11)*100 -> 0.24555617 | EC8: =ED7 -> 11990 | ED8: 12012 | EE8: =ED8-EC8 -> 22 | EF8: =EE8-EE7 -> -2 | EG8: =(EE8/'Finance Only'!B11)*100 -> 0.080630383 | EH8: =EI7 -> 10928 | EI8: 10964 | EJ8: =EI8-EH8 -> 36 | EK8: =EJ8-EJ7 -> 3 | EL8: =(EJ8/'Finance Only'!B11)*100 -> 0.13194063 | EM8: =EN7 -> 21417 | EN8: 21476 | EO8: =EN8-EM8 -> 59 | EP8: =EO8-EO7 -> 9 | EQ8: =(EO8/'Finance Only'!B11)*100 -> 0.21623603 | ER8: =ES7 -> 51536 | ES8: 52102 | ET8: =ES8-ER8 -> 566 | EU8: =ET8-ET7 -> -265 | EV8: =(ET8/'Finance Only'!B11)*100 -> 2.0743999 | EW8: =EX7 -> 31137 | EX8: 33324 | EY8: =EX8-EW8 -> 2187 | EZ8: =EY8-EY7 -> -1759 | FA8: =(EY8/'Finance Only'!G11)*100 -> 6627.2727 | FB8: =FC7 -> 14242 | FC8: 16013 | FD8: =FC8-FB8 -> 1771 | FE8: =FD8-FD7 -> -82 | FF8: =(FD8/'Finance Only'!L11)*100 -> #DIV/0!
A9: 5 | B9: ='Finance Only'!G12 -> 30 | C9: =D8 -> 25806502 | D9: 25808743 | E9: =D9-C9 -> 2241 | F9: =E9-E8 -> -26 | G9: =(E9/'Finance Only'!B12)*100 -> 7.5953228 | H9: =I8 -> 23030729 | I9: 23035583 | J9: =I9-H9 -> 4854 | K9: =J9-J8 -> 36 | L9: =(J9/'Finance Only'!B12)*100 -> 16.451449 | M9: =N8 -> 86769827 | N9: 86780802 | O9: =N9-M9 -> 10975 | P9: =O9-O8 -> -3549 | Q9: =(O9/'Finance Only'!B12)*100 -> 37.197085 | R9: =S8 -> 21599 | S9: 21619 | T9: =S9-R9 -> 20 | U9: =T9-T8 -> -2 | V9: =(T9/'Finance Only'!B12)*100 -> 0.067785121 | W9: =X8 -> 2921641 | X9: 2924453 | Y9: =X9-W9 -> 2812 | Z9: =Y9-Y8 -> -83 | AA9: =(Y9/'Finance Only'!B12)*100 -> 9.530588 | AB9: =AC8 -> 17890 | AC9: 17908 | AD9: =AC9-AB9 -> 18 | AE9: =AD9-AD8 -> -1 | AF9: =(AD9/'Finance Only'!B12)*100 -> 0.061006609 | AG9: =AH8 -> 793121 | AH9: 793857 | AI9: =AH9-AG9 -> 736 | AJ9: =AI9-AI8 -> 119 | AK9: =(AI9/'Finance Only'!B12)*100 -> 2.4944925 | AL9: =AM8 -> 82152 | AM9: 82216 | AN9: =AM9-AL9 -> 64 | AO9: =AN9-AN8 -> -3 | AP9: =(AN9/'Finance Only'!B12)*100 -> 0.21691239 | AQ9: =AR8 -> 18502 | AR9: 18518 | AS9: =AR9-AQ9 -> 16 | AT9: =AS9-AS8 -> 6 | AU9: =(AS9/'Finance Only'!B12)*100 -> 0.054228097 | AV9: =AW8 -> 534281 | AW9: 534677 | AX9: =AW9-AV9 -> 396 | AY9: =AX9-AX8 -> 7 | AZ9: =(AX9/'Finance Only'!B12)*100 -> 1.3421454 | BA9: =BB8 -> 71767 | BB9: 71864 | BC9: =BB9-BA9 -> 97 | BD9: =BC9-BC8 -> 6 | BE9: =(BC9/'Finance Only'!B12)*100 -> 0.32875784 | BF9: =BG8 -> 81606 | BG9: 81696 | BH9: =BG9-BF9 -> 90 | BI9: =BH9-BH8 -> 3 | BJ9: =(BH9/'Finance Only'!B12)*100 -> 0.30503305 | BK9: =BL8 -> 12725 | BL9: 12740 | BM9: =BL9-BK9 -> 15 | BN9: =BM9-BM8 -> 2 | BO9: =(BM9/'Finance Only'!B12)*100 -> 0.050838841 | BP9: =BQ8 -> 75087 | BQ9: 75235 | BR9: =BQ9-BP9 -> 148 | BS9: =BR9-BR8 -> 20 | BT9: =(BR9/'Finance Only'!B12)*100 -> 0.5016099 | BU9: =BV8 -> 39834 | BV9: 39877 | BW9: =BV9-BU9 -> 43 | BX9: =BW9-BW8 -> 5 | BY9: =(BW9/'Finance Only'!B12)*100 -> 0.14573801 | BZ9: =CA8 -> 57377 | CA9: 57500 | CB9: =CA9-BZ9 -> 123 | CC9: =CB9-CB8 -> -5 | CD9: =(CB9/'Finance Only'!B12)*100 -> 0.4168785 | CE9: =CF8 -> 17247 | CF9: 17287 | CG9: =CF9-CE9 -> 40 | CH9: =CG9-CG8 -> 0 | CI9: =(CG9/'Finance Only'!B12)*100 -> 0.13557024 | CJ9: =CK8 -> 39411 | CK9: 39506 | CL9: =CK9-CJ9 -> 95 | CM9: =CL9-CL8 -> -8 | CN9: =(CL9/'Finance Only'!B12)*100 -> 0.32197933 | CO9: =CP8 -> 30999 | CP9: 31073 | CQ9: =CP9-CO9 -> 74 | CR9: =CQ9-CQ8 -> 0 | CS9: =(CQ9/'Finance Only'!B12)*100 -> 0.25080495 | CT9: =CU8 -> 27241 | CU9: 27306 | CV9: =CU9-CT9 -> 65 | CW9: =CV9-CV8 -> -5 | CX9: =(CV9/'Finance Only'!B12)*100 -> 0.22030164 | CY9: =CZ8 -> 45858 | CZ9: 45975 | DA9: =CZ9-CY9 -> 117 | DB9: =DA9-DA8 -> 6 | DC9: =(DA9/'Finance Only'!B12)*100 -> 0.39654296 | DD9: =DE8 -> 34577 | DE9: 34681 | DF9: =DE9-DD9 -> 104 | DG9: =DF9-DF8 -> 11 | DH9: =(DF9/'Finance Only'!B12)*100 -> 0.35248263 | DI9: =DJ8 -> 31978 | DJ9: 32087 | DK9: =DJ9-DI9 -> 109 | DL9: =DK9-DK8 -> 6 | DM9: =(DK9/'Finance Only'!B12)*100 -> 0.36942891 | DN9: =DO8 -> 21230 | DO9: 21280 | DP9: =DO9-DN9 -> 50 | DQ9: =DP9-DP8 -> 1 | DR9: =(DP9/'Finance Only'!B12)*100 -> 0.1694628 | DS9: =DT8 -> 56011 | DT9: 56113 | DU9: =DT9-DS9 -> 102 | DV9: =DU9-DU8 -> 20 | DW9: =(DU9/'Finance Only'!B12)*100 -> 0.34570412 | DX9: =DY8 -> 38625 | DY9: 38692 | DZ9: =DY9-DX9 -> 67 | EA9: =DZ9-DZ8 -> 0 | EB9: =(DZ9/'Finance Only'!B12)*100 -> 0.22708016 | EC9: =ED8 -> 12012 | ED9: 12036 | EE9: =ED9-EC9 -> 24 | EF9: =EE9-EE8 -> 2 | EG9: =(EE9/'Finance Only'!B12)*100 -> 0.081342145 | EH9: =EI8 -> 10964 | EI9: 10999 | EJ9: =EI9-EH9 -> 35 | EK9: =EJ9-EJ8 -> -1 | EL9: =(EJ9/'Finance Only'!B12)*100 -> 0.11862396 | EM9: =EN8 -> 21476 | EN9: 21515 | EO9: =EN9-EM9 -> 39 | EP9: =EO9-EO8 -> -20 | EQ9: =(EO9/'Finance Only'!B12)*100 -> 0.13218099 | ER9: =ES8 -> 52102 | ES9: 52416 | ET9: =ES9-ER9 -> 314 | EU9: =ET9-ET8 -> -252 | EV9: =(ET9/'Finance Only'!B12)*100 -> 1.0642264 | EW9: =EX8 -> 33324 | EX9: 35233 | EY9: =EX9-EW9 -> 1909 | EZ9: =EY9-EY8 -> -278 | FA9: =(EY9/'Finance Only'!G12)*100 -> 6363.3333 | FB9: =FC8 -> 16013 | FC9: 17437 | FD9: =FC9-FB9 -> 1424 | FE9: =FD9-FD8 -> -347 | FF9: =(FD9/'Finance Only'!L12)*100 -> #DIV/0!
A10: 6 | B10: ='Finance Only'!G13 -> 33 | C10: =D9 -> 25808743 | D10: 25810837 | E10: =D10-C10 -> 2094 | F10: =E10-E9 -> -147 | G10: =(E10/'Finance Only'!B13)*100 -> 8.5438002 | H10: =I9 -> 23035583 | I10: 23039995 | J10: =I10-H10 -> 4412 | K10: =J10-J9 -> -442 | L10: =(J10/'Finance Only'!B13)*100 -> 18.00155 | M10: =N9 -> 86780802 | N10: 86798102 | O10: =N10-M10 -> 17300 | P10: =O10-O9 -> 6325 | Q10: =(O10/'Finance Only'!B13)*100 -> 70.586315 | R10: =S9 -> 21619 | S10: 21639 | T10: =S10-R10 -> 20 | U10: =T10-T9 -> 0 | V10: =(T10/'Finance Only'!B13)*100 -> 0.081602677 | W10: =X9 -> 2924453 | X10: 2927074 | Y10: =X10-W10 -> 2621 | Z10: =Y10-Y9 -> -191 | AA10: =(Y10/'Finance Only'!B13)*100 -> 10.694031 | AB10: =AC9 -> 17908 | AC10: 17925 | AD10: =AC10-AB10 -> 17 | AE10: =AD10-AD9 -> -1 | AF10: =(AD10/'Finance Only'!B13)*100 -> 0.069362275 | AG10: =AH9 -> 793857 | AH10: 794594 | AI10: =AH10-AG10 -> 737 | AJ10: =AI10-AI9 -> 1 | AK10: =(AI10/'Finance Only'!B13)*100 -> 3.0070586 | AL10: =AM9 -> 82216 | AM10: 82275 | AN10: =AM10-AL10 -> 59 | AO10: =AN10-AN9 -> -5 | AP10: =(AN10/'Finance Only'!B13)*100 -> 0.2407279 | AQ10: =AR9 -> 18518 | AR10: 18534 | AS10: =AR10-AQ10 -> 16 | AT10: =AS10-AS9 -> 0 | AU10: =(AS10/'Finance Only'!B13)*100 -> 0.065282141 | AV10: =AW9 -> 534677 | AW10: 535066 | AX10: =AW10-AV10 -> 389 | AY10: =AX10-AX9 -> -7 | AZ10: =(AX10/'Finance Only'!B13)*100 -> 1.5871721 | BA10: =BB9 -> 71864 | BB10: 71961 | BC10: =BB10-BA10 -> 97 | BD10: =BC10-BC9 -> 0 | BE10: =(BC10/'Finance Only'!B13)*100 -> 0.39577298 | BF10: =BG9 -> 81696 | BG10: 81789 | BH10: =BG10-BF10 -> 93 | BI10: =BH10-BH9 -> 3 | BJ10: =(BH10/'Finance Only'!B13)*100 -> 0.37945245 | BK10: =BL9 -> 12740 | BL10: 12755 | BM10: =BL10-BK10 -> 15 | BN10: =BM10-BM9 -> 0 | BO10: =(BM10/'Finance Only'!B13)*100 -> 0.061202007 | BP10: =BQ9 -> 75235 | BQ10: 75357 | BR10: =BQ10-BP10 -> 122 | BS10: =BR10-BR9 -> -26 | BT10: =(BR10/'Finance Only'!B13)*100 -> 0.49777633 | BU10: =BV9 -> 39877 | BV10: 39920 | BW10: =BV10-BU10 -> 43 | BX10: =BW10-BW9 -> 0 | BY10: =(BW10/'Finance Only'!B13)*100 -> 0.17544575 | BZ10: =CA9 -> 57500 | CA10: 57622 | CB10: =CA10-BZ10 -> 122 | CC10: =CB10-CB9 -> -1 | CD10: =(CB10/'Finance Only'!B13)*100 -> 0.49777633 | CE10: =CF9 -> 17287 | CF10: 17324 | CG10: =CF10-CE10 -> 37 | CH10: =CG10-CG9 -> -3 | CI10: =(CG10/'Finance Only'!B13)*100 -> 0.15096495 | CJ10: =CK9 -> 39506 | CK10: 39574 | CL10: =CK10-CJ10 -> 68 | CM10: =CL10-CL9 -> -27 | CN10: =(CL10/'Finance Only'!B13)*100 -> 0.2774491 | CO10: =CP9 -> 31073 | CP10: 31146 | CQ10: =CP10-CO10 -> 73 | CR10: =CQ10-CQ9 -> -1 | CS10: =(CQ10/'Finance Only'!B13)*100 -> 0.29784977 | CT10: =CU9 -> 27306 | CU10: 27361 | CV10: =CU10-CT10 -> 55 | CW10: =CV10-CV9 -> -10 | CX10: =(CV10/'Finance Only'!B13)*100 -> 0.22440736 | CY10: =CZ9 -> 45975 | CZ10: 46056 | DA10: =CZ10-CY10 -> 81 | DB10: =DA10-DA9 -> -36 | DC10: =(DA10/'Finance Only'!B13)*100 -> 0.33049084 | DD10: =DE9 -> 34681 | DE10: 34754 | DF10: =DE10-DD10 -> 73 | DG10: =DF10-DF9 -> -31 | DH10: =(DF10/'Finance Only'!B13)*100 -> 0.29784977 | DI10: =DJ9 -> 32087 | DJ10: 32171 | DK10: =DJ10-DI10 -> 84 | DL10: =DK10-DK9 -> -25 | DM10: =(DK10/'Finance Only'!B13)*100 -> 0.34273124 | DN10: =DO9 -> 21280 | DO10: 21326 | DP10: =DO10-DN10 -> 46 | DQ10: =DP10-DP9 -> -4 | DR10: =(DP10/'Finance Only'!B13)*100 -> 0.18768616 | DS10: =DT9 -> 56113 | DT10: 56198 | DU10: =DT10-DS10 -> 85 | DV10: =DU10-DU9 -> -17 | DW10: =(DU10/'Finance Only'!B13)*100 -> 0.34681138 | DX10: =DY9 -> 38692 | DY10: 38749 | DZ10: =DY10-DX10 -> 57 | EA10: =DZ10-DZ9 -> -10 | EB10: =(DZ10/'Finance Only'!B13)*100 -> 0.23256763 | EC10: =ED9 -> 12036 | ED10: 12057 | EE10: =ED10-EC10 -> 21 | EF10: =EE10-EE9 -> -3 | EG10: =(EE10/'Finance Only'!B13)*100 -> 0.08568281 | EH10: =EI9 -> 10999 | EI10: 11018 | EJ10: =EI10-EH10 -> 19 | EK10: =EJ10-EJ9 -> -16 | EL10: =(EJ10/'Finance Only'!B13)*100 -> 0.077522543 | EM10: =EN9 -> 21515 | EN10: 21564 | EO10: =EN10-EM10 -> 49 | EP10: =EO10-EO9 -> 10 | EQ10: =(EO10/'Finance Only'!B13)*100 -> 0.19992656 | ER10: =ES9 -> 52416 | ES10: 52724 | ET10: =ES10-ER10 -> 308 | EU10: =ET10-ET9 -> -6 | EV10: =(ET10/'Finance Only'!B13)*100 -> 1.2566812 | EW10: =EX9 -> 35233 | EX10: 36503 | EY10: =EX10-EW10 -> 1270 | EZ10: =EY10-EY9 -> -639 | FA10: =(EY10/'Finance Only'!G13)*100 -> 3848.4848 | FB10: =FC9 -> 17437 | FC10: 18418 | FD10: =FC10-FB10 -> 981 | FE10: =FD10-FD9 -> -443 | FF10: =(FD10/'Finance Only'!L13)*100 -> #DIV/0!
