Workbook

Sheet TOTAL
A1: Site Name | B1: Day | C1: Month | D1: Year | E1: Total Electricity Kwh | F1: Electricity Tariff ($/Kwh) | G1: Natual Gas (m3) | H1: Natural Gas $/m3 | I1: Water Utility Supply (m3) m3 | J1: Water Utility Supply (m3) $/m3 | K1: Room Nights | L1: Total Guests | M1: Utilities day cost dh
A2: Mumbai | B2: 1 | C2: 8 | D2: 2021 | E2: =(IF('Daily HLP'!I4>0,'Daily HLP'!I4,0)) -> 22540.07 | F2: 9 | G2: =(IF('Daily HLP'!M4>0,'Daily HLP'!M4,0)) -> 776 | H2: 52 | I2: =(IF('Daily HLP'!P4>0,'Daily HLP'!P4,0)) -> 243 | J2: 118 | K2: =Occupancy!G2 -> 149 | L2: =Occupancy!F2 -> 519 | M2: =E2*F2+G2*H2+#REF!*#REF!+I2*J2 -> #REF!
A3: Mumbai | B3: =B2+1 -> 2 | C3: 8 | D3: 2021 | E3: =(IF('Daily HLP'!I5>0,'Daily HLP'!I5,0)) -> 21861.68 | F3: 9 | G3: =(IF('Daily HLP'!M5>0,'Daily HLP'!M5,0)) -> 924.25 | H3: 52 | I3: =(IF('Daily HLP'!P5>0,'Daily HLP'!P5,0)) -> 244 | J3: 118 | K3: =Occupancy!G3 -> 136 | L3: =Occupancy!F3 -> 427 | M3: =E3*F3+G3*H3+#REF!*#REF!+I3*J3 -> #REF!
A4: Mumbai | B4: =B3+1 -> 3 | C4: 8 | D4: 2021 | E4: =(IF('Daily HLP'!I6>0,'Daily HLP'!I6,0)) -> 21488.82 | F4: 9 | G4: =(IF('Daily HLP'!M6>0,'Daily HLP'!M6,0)) -> 755.885 | H4: 52 | I4: =(IF('Daily HLP'!P6>0,'Daily HLP'!P6,0)) -> 196 | J4: 118 | K4: =Occupancy!G4 -> 153 | L4: =Occupancy!F4 -> 458 | M4: =E4*F4+G4*H4+#REF!*#REF!+I4*J4 -> #REF!
A5: Mumbai | B5: =B4+1 -> 4 | C5: 8 | D5: 2021 | E5: =(IF('Daily HLP'!I7>0,'Daily HLP'!I7,0)) -> 24881.14 | F5: 9 | G5: =(IF('Daily HLP'!M7>0,'Daily HLP'!M7,0)) -> 889.057 | H5: 52 | I5: =(IF('Daily HLP'!P7>0,'Daily HLP'!P7,0)) -> 191 | J5: 118 | K5: =Occupancy!G5 -> 161 | L5: =Occupancy!F5 -> 632 | M5: =E5*F5+G5*H5+#REF!*#REF!+I5*J5 -> #REF!
A6: Mumbai | B6: =B5+1 -> 5 | C6: 8 | D6: 2021 | E6: =(IF('Daily HLP'!I8>0,'Daily HLP'!I8,0)) -> 23183.28 | F6: 9 | G6: =(IF('Daily HLP'!M8>0,'Daily HLP'!M8,0)) -> 738.088 | H6: 52 | I6: =(IF('Daily HLP'!P8>0,'Daily HLP'!P8,0)) -> 242 | J6: 118 | K6: =Occupancy!G6 -> 182 | L6: =Occupancy!F6 -> 430 | M6: =E6*F6+G6*H6+#REF!*#REF!+I6*J6 -> #REF!
A7: Mumbai | B7: =B6+1 -> 6 | C7: 8 | D7: 2021 | E7: =(IF('Daily HLP'!I9>0,'Daily HLP'!I9,0)) -> 24216.64 | F7: 9 | G7: =(IF('Daily HLP'!M9>0,'Daily HLP'!M9,0)) -> 968.18 | H7: 52 | I7: =(IF('Daily HLP'!P9>0,'Daily HLP'!P9,0)) -> 261 | J7: 118 | K7: =Occupancy!G7 -> 174 | L7: =Occupancy!F7 -> 586 | M7: =E7*F7+G7*H7+#REF!*#REF!+I7*J7 -> #REF!
A8: Mumbai | B8: =B7+1 -> 7 | C8: 8 | D8: 2021 | E8: =(IF('Daily HLP'!I10>0,'Daily HLP'!I10,0)) -> 24405.68 | F8: 9 | G8: =(IF('Daily HLP'!M10>0,'Daily HLP'!M10,0)) -> 860.81 | H8: 52 | I8: =(IF('Daily HLP'!P10>0,'Daily HLP'!P10,0)) -> 225 | J8: 118 | K8: =Occupancy!G8 -> 188 | L8: =Occupancy!F8 -> 526 | M8: =E8*F8+G8*H8+#REF!*#REF!+I8*J8 -> #REF!
A9: Mumbai | B9: =B8+1 -> 8 | C9: 8 | D9: 2021 | E9: =(IF('Daily HLP'!I11>0,'Daily HLP'!I11,0)) -> 22435.69 | F9: 9 | G9: =(IF('Daily HLP'!M11>0,'Daily HLP'!M11,0)) -> 902.73 | H9: 52 | I9: =(IF('Daily HLP'!P11>0,'Daily HLP'!P11,0)) -> 275 | J9: 118 | K9: =Occupancy!G9 -> 145 | L9: =Occupancy!F9 -> 436 | M9: =E9*F9+G9*H9+#REF!*#REF!+I9*J9 -> #REF!
A10: Mumbai | B10: =B9+1 -> 9 | C10: 8 | D10: 2021 | E10: =(IF('Daily HLP'!I12>0,'Daily HLP'!I12,0)) -> 20612 | F10: 9 | G10: =(IF('Daily HLP'!M12>0,'Daily HLP'!M12,0)) -> 764 | H10: 52 | I10: =(IF('Daily HLP'!P12>0,'Daily HLP'!P12,0)) -> 224 | J10: 118 | K10: =Occupancy!G10 -> 110 | L10: =Occupancy!F10 -> 313 | M10: =E10*F10+G10*H10+#REF!*#REF!+I10*J10 -> #REF!
A11: Mumbai | B11: =B10+1 -> 10 | C11: 8 | D11: 2021 | E11: =(IF('Daily HLP'!I13>0,'Daily HLP'!I13,0)) -> 21667 | F11: 9 | G11: =(IF('Daily HLP'!M13>0,'Daily HLP'!M13,0)) -> 907 | H11: 52 | I11: =(IF('Daily HLP'!P13>0,'Daily HLP'!P13,0)) -> 197 | J11: 118 | K11: =Occupancy!G11 -> 159 | L11: =Occupancy!F11 -> 340 | M11: =E11*F11+G11*H11+#REF!*#REF!+I11*J11 -> #REF!
A12: Mumbai | B12: =B11+1 -> 11 | C12: 8 | D12: 2021 | E12: =(IF('Daily HLP'!I14>0,'Daily HLP'!I14,0)) -> 21713 | F12: 9 | G12: =(IF('Daily HLP'!M14>0,'Daily HLP'!M14,0)) -> 826 | H12: 52 | I12: =(IF('Daily HLP'!P14>0,'Daily HLP'!P14,0)) -> 224 | J12: 118 | K12: =Occupancy!G12 -> 170 | L12: =Occupancy!F12 -> 469 | M12: =E12*F12+G12*H12+#REF!*#REF!+I12*J12 -> #REF!
A13: Mumbai | B13: =B12+1 -> 12 | C13: 8 | D13: 2021 | E13: =(IF('Daily HLP'!I15>0,'Daily HLP'!I15,0)) -> 23053 | F13: 9 | G13: =(IF('Daily HLP'!M15>0,'Daily HLP'!M15,0)) -> 930 | H13: 52 | I13: =(IF('Daily HLP'!P15>0,'Daily HLP'!P15,0)) -> 240 | J13: 118 | K13: =Occupancy!G13 -> 171 | L13: =Occupancy!F13 -> 638 | M13: =E13*F13+G13*H13+#REF!*#REF!+I13*J13 -> #REF!
A14: Mumbai | B14: =B13+1 -> 13 | C14: 8 | D14: 2021 | E14: =(IF('Daily HLP'!I16>0,'Daily HLP'!I16,0)) -> 22751 | F14: 9 | G14: =(IF('Daily HLP'!M16>0,'Daily HLP'!M16,0)) -> 901 | H14: 52 | I14: =(IF('Daily HLP'!P16>0,'Daily HLP'!P16,0)) -> 251 | J14: 118 | K14: =Occupancy!G14 -> 160 | L14: =Occupancy!F14 -> 496 | M14: =E14*F14+G14*H14+#REF!*#REF!+I14*J14 -> #REF!
... A31: Mumbai | B31: =B30+1 -> 30 | C31: 8 | D31: 2021 | E31: =(IF('Daily HLP'!I33>0,'Daily HLP'!I33,0)) -> 22284 | F31: 9 | G31: =(IF('Daily HLP'!M33>0,'Daily HLP'!M33,0)) -> 950 | H31: 52 | I31: =(IF('Daily HLP'!P33>0,'Daily HLP'!P33,0)) -> 210 | J31: 118 | K31: =Occupancy!G31 -> 0 | L31: =Occupancy!F31 -> 0 | M31: =E31*F31+G31*H31+#REF!*#REF!+I31*J31 -> #REF!
A32: Mumbai | B32: =B31+1 -> 31 | C32: 8 | D32: 2021 | E32: =(IF('Daily HLP'!I34>0,'Daily HLP'!I34,0)) -> 21500 | F32: 9 | G32: =(IF('Daily HLP'!M34>0,'Daily HLP'!M34,0)) -> 950 | H32: 52 | I32: =(IF('Daily HLP'!P34>0,'Daily HLP'!P34,0)) -> 120 | J32: 118 | K32: =Occupancy!G32 -> 0 | L32: =Occupancy!F32 -> 0

Sheet Submetering
A1: Site Name | B1: Day | C1: Month | D1: Year | E1: ='Section Load'!F4 -> HVAC | F1: ='Section Load'!G4 -> Fire & Emergency PP | G1: ='Section Load'!H4 -> Main PP | H1: ='Section Load'!I4 -> Lighting PP | I1: ='Section Load'!J4 -> CH-1+ CH2+CH3+CH4 | J1: ='Section Load'!K4 -> Chilled water Pump | K1: ='Section Load'!L4 -> Ball Room-1 | L1: ='Section Load'!M4 -> Ball Room-2 | ... AL1: ='Section Load'!AM4 -> Cooling Tower | AM1: R.o.plant | AN1: STP Water Prod | AO1: Domestic Zone-1 | AP1: Domestic Zone-2 | AQ1: Domestic Zone-3 | AR1: Flush Zone -1 | AS1: Flush Zone -2 | AT1: Flush Zone -3 | AU1: Swimming pool | AV1: B2 Laundry | AW1: Boiler Feed Water | AX1: cooling tower filling water | AY1: STP flush(new water meter) | AZ1: Garden Water Pump | BA1: Flush Zone 2 pump meter | BB1: Flush Zone 3 Pump Meter (wtp transfer ) | BC1: Flush Tanker-Zone-1 | BD1: Total Domestic Water (Tanker (R.O) +BMC) | BE1: Total Domestic Consumption | BF1: Total STP Consumption | BG1: ='Section Load'!AN4 -> MGL | BH1: ='Section Load'!AO4 -> HWG | BI1: ='Section Load'!AP4 -> Prato | BJ1: ='Section Load'!AQ4 -> BR-1 | BK1: ='Section Load'!AR4 -> SanQi IND | BL1: ='Section Load'!AS4 -> SanQi JPN | BM1: ='Section Load'!AT4 -> Boiler
A2: Mumbai | B2: 1 | C2: 8 | D2: 2021 | E2: =(IF('Section Load'!F5>0,'Section Load'!F5,0)) -> 3081.67 | F2: =(IF('Section Load'!G5>0,'Section Load'!G5,0)) -> 1651.6 | G2: =(IF('Section Load'!H5>0,'Section Load'!H5,0)) -> 1739.37 | H2: =(IF('Section Load'!I5>0,'Section Load'!I5,0)) -> 3756.58 | I2: =(IF('Section Load'!J5>0,'Section Load'!J5,0)) -> 6395.74 | J2: =(IF('Section Load'!K5>0,'Section Load'!K5,0)) -> 2724.7 | K2: =(IF('Section Load'!L5>0,'Section Load'!L5,0)) -> 1556.47 | L2: =(IF('Section Load'!M5>0,'Section Load'!M5,0)) -> 732.6 | ... AL2: =(IF('Section Load'!AM5>0,'Section Load'!AM5,0)) -> 809 | AM2: =(IF('Water Report'!$D$7>0,'Water Report'!$D$7,0)) -> 135 | AN2: =(IF('Water Report'!$D$8>0,'Water Report'!$D$8,0)) -> 171 | AO2: =(IF('Water Report'!$D$9>0,'Water Report'!$D$9,0)) -> 70 | AP2: =(IF('Water Report'!$D$10>0,'Water Report'!$D$10,0)) -> 34 | AQ2: =(IF('Water Report'!$D$11>0,'Water Report'!$D$11,0)) -> 43 | AR2: =(IF('Water Report'!$D$13>0,'Water Report'!$D$13,0)) -> 6 | AS2: =(IF('Water Report'!$D$14>0,'Water Report'!$D$14,0)) -> 28 | AT2: =(IF('Water Report'!$D$15>0,'Water Report'!$D$15,0)) -> 16 | AU2: =(IF('Water Report'!$D$17>0,'Water Report'!$D$17,0)) -> 0 | AV2: =(IF('Water Report'!$D$18>0,'Water Report'!$D$18,0)) -> 11 | AW2: =(IF('Water Report'!$D$19>0,'Water Report'!$D$19,0)) -> 4 | AX2: =(IF('Water Report'!$D$21>0,'Water Report'!$D$21,0)) -> 71 | AY2: =(IF('Water Report'!$D$22>0,'Water Report'!$D$22,0)) -> 0 | AZ2: =(IF('Water Report'!$D$23>0,'Water Report'!$D$23,0)) -> 0 | BA2: =(IF('Water Report'!$D$14>0,'Water Report'!$D$14,0)) -> 28 | BB2: =(IF('Water Report'!$D$15>0,'Water Report'!$D$15,0)) -> 16 | BC2: =(IF('Water Report'!$D$13>0,'Water Report'!$D$13,0)) -> 6 | BD2: =(IF('Water Report'!$D$24>0,'Water Report'!$D$24,0)) -> 243 | BE2: =(IF('Water Report'!$D$25>0,'Water Report'!$D$25,0)) -> 191 | BF2: =(IF('Water Report'!$D$27>0,'Water Report'!$D$27,0)) -> 77 | BG2: =(IF('Section Load'!AN5>0,'Section Load'!AN5,0)) -> 776 | BH2: =(IF('Section Load'!AO5>0,'Section Load'!AO5,0)) -> 269.36 | BI2: =(IF('Section Load'!AP5>0,'Section Load'!AP5,0)) -> 0 | BJ2: =(IF('Section Load'!AQ5>0,'Section Load'!AQ5,0)) -> 77 | BK2: =(IF('Section Load'!AR5>0,'Section Load'!AR5,0)) -> 46 | BL2: =(IF('Section Load'!AS5>0,'Section Load'!AS5,0)) -> 2 | BM2: =(IF('Section Load'!AT5>0,'Section Load'!AT5,0)) -> 381.64
A3: Mumbai | B3: =B2+1 -> 2 | C3: 8 | D3: 2021 | E3: =(IF('Section Load'!F6>0,'Section Load'!F6,0)) -> 3099.88 | F3: =(IF('Section Load'!G6>0,'Section Load'!G6,0)) -> 1604.82 | G3: =(IF('Section Load'!H6>0,'Section Load'!H6,0)) -> 1664.92 | H3: =(IF('Section Load'!I6>0,'Section Load'!I6,0)) -> 3764.68 | I3: =(IF('Section Load'!J6>0,'Section Load'!J6,0)) -> 6598.59 | J3: =(IF('Section Load'!K6>0,'Section Load'!K6,0)) -> 2502.5 | K3: =(IF('Section Load'!L6>0,'Section Load'!L6,0)) -> 1119.48 | L3: =(IF('Section Load'!M6>0,'Section Load'!M6,0)) -> 549.29 | ... AL3: =(IF('Section Load'!AM6>0,'Section Load'!AM6,0)) -> 782 | AM3: =(IF('Water Report'!$E$7>0,'Water Report'!$E$7,0)) -> 82 | AN3: =(IF('Water Report'!$E$8>0,'Water Report'!$E$8,0)) -> 195 | AO3: =(IF('Water Report'!$E$9>0,'Water Report'!$E$9,0)) -> 68 | AP3: =(IF('Water Report'!$E$10>0,'Water Report'!$E$10,0)) -> 26 | AQ3: =(IF('Water Report'!$E$11>0,'Water Report'!$E$11,0)) -> 27 | AR3: =(IF('Water Report'!$E$13>0,'Water Report'!$E$13,0)) -> 45 | AS3: =(IF('Water Report'!$E$14>0,'Water Report'!$E$14,0)) -> 21 | AT3: =(IF('Water Report'!$E$15>0,'Water Report'!$E$15,0)) -> 11 | AU3: =(IF('Water Report'!$E$17>0,'Water Report'!$E$17,0)) -> 0 | AV3: =(IF('Water Report'!$E$18>0,'Water Report'!$E$18,0)) -> 10 | AW3: =(IF('Water Report'!$E$19>0,'Water Report'!$E$19,0)) -> 5 | AX3: =(IF('Water Report'!$E$21>0,'Water Report'!$E$21,0)) -> 73 | AY3: =(IF('Water Report'!$E$22>0,'Water Report'!$E$22,0)) -> 0 | AZ3: =(IF('Water Report'!$E$23>0,'Water Report'!$E$23,0)) -> 37 | BA3: =(IF('Water Report'!$E$14>0,'Water Report'!$E$14,0)) -> 21 | BB3: =(IF('Water Report'!$E$15>0,'Water Report'!$E$15,0)) -> 11 | BC3: =(IF('Water Report'!$E$13>0,'Water Report'!$E$13,0)) -> 45 | BD3: =(IF('Water Report'!$E$24>0,'Water Report'!$E$24,0)) -> 244 | BE3: =(IF('Water Report'!$E$25>0,'Water Report'!$E$25,0)) -> 153 | BF3: =(IF('Water Report'!$E$27>0,'Water Report'!$E$27,0)) -> 155 | BG3: =(IF('Section Load'!AN6>0,'Section Load'!AN6,0)) -> 924.25 | BH3: =(IF('Section Load'!AO6>0,'Section Load'!AO6,0)) -> 267.6 | BI3: =(IF('Section Load'!AP6>0,'Section Load'!AP6,0)) -> 0 | BJ3: =(IF('Section Load'!AQ6>0,'Section Load'!AQ6,0)) -> 79.72 | BK3: =(IF('Section Load'!AR6>0,'Section Load'!AR6,0)) -> 43.7 | BL3: =(IF('Section Load'!AS6>0,'Section Load'!AS6,0)) -> 2.6 | BM3: =(IF('Section Load'!AT6>0,'Section Load'!AT6,0)) -> 530.63
A4: Mumbai | B4: =B3+1 -> 3 | C4: 8 | D4: 2021 | E4: =(IF('Section Load'!F7>0,'Section Load'!F7,0)) -> 2964.9 | F4: =(IF('Section Load'!G7>0,'Section Load'!G7,0)) -> 1599.1 | G4: =(IF('Section Load'!H7>0,'Section Load'!H7,0)) -> 1612.4 | H4: =(IF('Section Load'!I7>0,'Section Load'!I7,0)) -> 3726.28 | I4: =(IF('Section Load'!J7>0,'Section Load'!J7,0)) -> 6846 | J4: =(IF('Section Load'!K7>0,'Section Load'!K7,0)) -> 2671.6 | K4: =(IF('Section Load'!L7>0,'Section Load'!L7,0)) -> 958.92 | L4: =(IF('Section Load'!M7>0,'Section Load'!M7,0)) -> 802.79 | ... AL4: =(IF('Section Load'!AM7>0,'Section Load'!AM7,0)) -> 647 | AM4: =(IF('Water Report'!$F$7>0,'Water Report'!$F$7,0)) -> 72 | AN4: =(IF('Water Report'!$F$8>0,'Water Report'!$F$8,0)) -> 131 | AO4: =(IF('Water Report'!$F$9>0,'Water Report'!$G$9,0)) -> 91 | AP4: =(IF('Water Report'!$F$10>0,'Water Report'!$F$10,0)) -> 21 | AQ4: =(IF('Water Report'!$F$11>0,'Water Report'!$F$11,0)) -> 23 | AR4: =(IF('Water Report'!$F$13>0,'Water Report'!$F$13,0)) -> 7 | AS4: =(IF('Water Report'!$F$14>0,'Water Report'!$F$14,0)) -> 15 | AT4: =(IF('Water Report'!$F$15>0,'Water Report'!$F$15,0)) -> 10 | AU4: =(IF('Water Report'!$F$17>0,'Water Report'!$F$17,0)) -> 0 | AV4: =(IF('Water Report'!$F$18>0,'Water Report'!$F$18,0)) -> 10 | AW4: =(IF('Water Report'!$F$19>0,'Water Report'!$F$19,0)) -> 6 | AX4: =(IF('Water Report'!$F$21>0,'Water Report'!$F$21,0)) -> 76 | AY4: =(IF('Water Report'!$F$22>0,'Water Report'!$F$22,0)) -> 0 | AZ4: =(IF('Water Report'!$F$23>0,'Water Report'!$F$23,0)) -> 0 | BA4: =(IF('Water Report'!$F$14>0,'Water Report'!$F$14,0)) -> 15 | BB4: =(IF('Water Report'!$F$15>0,'Water Report'!$F$15,0)) -> 10 | BC4: =(IF('Water Report'!$F$13>0,'Water Report'!$F$13,0)) -> 7 | BD4: =(IF('Water Report'!$F$24>0,'Water Report'!$F$24,0)) -> 196 | BE4: =(IF('Water Report'!$F$25>0,'Water Report'!$F$25,0)) -> 131 | BF4: =(IF('Water Report'!$F$27>0,'Water Report'!$F$27,0)) -> 83 | BG4: =(IF('Section Load'!AN7>0,'Section Load'!AN7,0)) -> 755.885 | BH4: =(IF('Section Load'!AO7>0,'Section Load'!AO7,0)) -> 252.9 | BI4: =(IF('Section Load'!AP7>0,'Section Load'!AP7,0)) -> 0 | BJ4: =(IF('Section Load'!AQ7>0,'Section Load'!AQ7,0)) -> 84.86 | BK4: =(IF('Section Load'!AR7>0,'Section Load'!AR7,0)) -> 42.1 | BL4: =(IF('Section Load'!AS7>0,'Section Load'!AS7,0)) -> 1.4 | BM4: =(IF('Section Load'!AT7>0,'Section Load'!AT7,0)) -> 374.625
A5: Mumbai | B5: =B4+1 -> 4 | C5: 8 | D5: 2021 | E5: =(IF('Section Load'!F8>0,'Section Load'!F8,0)) -> 3090.55 | F5: =(IF('Section Load'!G8>0,'Section Load'!G8,0)) -> 1605.35 | G5: =(IF('Section Load'!H8>0,'Section Load'!H8,0)) -> 1684.38 | H5: =(IF('Section Load'!I8>0,'Section Load'!I8,0)) -> 3735.05 | I5: =(IF('Section Load'!J8>0,'Section Load'!J8,0)) -> 7495.14 | J5: =(IF('Section Load'!K8>0,'Section Load'!K8,0)) -> 3000.2 | K5: =(IF('Section Load'!L8>0,'Section Load'!L8,0)) -> 1093.13 | L5: =(IF('Section Load'!M8>0,'Section Load'!M8,0)) -> 982.72 | ... AL5: =(IF('Section Load'!AM8>0,'Section Load'!AM8,0)) -> 687 | AM5: =(IF('Water Report'!$G$7>0,'Water Report'!$F$7,0)) -> 72 | AN5: =(IF('Water Report'!$G$8>0,'Water Report'!$F$8,0)) -> 131 | AO5: =(IF('Water Report'!$G$9>0,'Water Report'!$H$9,0)) -> 125 | AP5: =(IF('Water Report'!$G$10>0,'Water Report'!$G$10,0)) -> 22 | AQ5: =(IF('Water Report'!$G$11>0,'Water Report'!$G$11,0)) -> 25 | AR5: =(IF('Water Report'!$G$13>0,'Water Report'!$G$13,0)) -> 24 | AS5: =(IF('Water Report'!$G$14>0,'Water Report'!$G$14,0)) -> 11 | AT5: =(IF('Water Report'!$G$15>0,'Water Report'!$G$15,0)) -> 7 | AU5: =(IF('Water Report'!$G$17>0,'Water Report'!$G$17,0)) -> 199 | AV5: =(IF('Water Report'!$G$18>0,'Water Report'!$G$18,0)) -> 10 | AW5: =(IF('Water Report'!$G$19>0,'Water Report'!$G$19,0)) -> 8 | AX5: =(IF('Water Report'!$G$21>0,'Water Report'!$G$21,0)) -> 101 | AY5: =(IF('Water Report'!$G$22>0,'Water Report'!$G$22,0)) -> 0 | AZ5: =(IF('Water Report'!$G$23>0,'Water Report'!$G$23,0)) -> 5 | BA5: =(IF('Water Report'!$G$14>0,'Water Report'!$G$14,0)) -> 11 | BB5: =(IF('Water Report'!$G$15>0,'Water Report'!$G$15,0)) -> 7 | BC5: =(IF('Water Report'!$G$13>0,'Water Report'!$G$13,0)) -> 24 | BD5: =(IF('Water Report'!$G$24>0,'Water Report'!$G$24,0)) -> 191 | BE5: =(IF('Water Report'!$G$25>0,'Water Report'!$G$25,0)) -> 156 | BF5: =(IF('Water Report'!$G$27>0,'Water Report'!$G$27,0)) -> 130 | BG5: =(IF('Section Load'!AN8>0,'Section Load'!AN8,0)) -> 889.057 | BH5: =(IF('Section Load'!AO8>0,'Section Load'!AO8,0)) -> 262.703 | BI5: =(IF('Section Load'!AP8>0,'Section Load'!AP8,0)) -> 0 | BJ5: =(IF('Section Load'!AQ8>0,'Section Load'!AQ8,0)) -> 75.59 | BK5: =(IF('Section Load'!AR8>0,'Section Load'!AR8,0)) -> 44.9 | BL5: =(IF('Section Load'!AS8>0,'Section Load'!AS8,0)) -> 1.5 | BM5: =(IF('Section Load'!AT8>0,'Section Load'!AT8,0)) -> 504.364
A6: Mumbai | B6: =B5+1 -> 5 | C6: 8 | D6: 2021 | E6: =(IF('Section Load'!F9>0,'Section Load'!F9,0)) -> 3125 | F6: =(IF('Section Load'!G9>0,'Section Load'!G9,0)) -> 1625 | G6: =(IF('Section Load'!H9>0,'Section Load'!H9,0)) -> 1714 | H6: =(IF('Section Load'!I9>0,'Section Load'!I9,0)) -> 3761 | I6: =(IF('Section Load'!J9>0,'Section Load'!J9,0)) -> 7630 | J6: =(IF('Section Load'!K9>0,'Section Load'!K9,0)) -> 2920 | K6: =(IF('Section Load'!L9>0,'Section Load'!L9,0)) -> 1415 | L6: =(IF('Section Load'!M9>0,'Section Load'!M9,0)) -> 758.24 | ... AL6: =(IF('Section Load'!AM9>0,'Section Load'!AM9,0)) -> 781 | AM6: =(IF('Water Report'!$H$7>0,'Water Report'!$H$7,0)) -> 128 | AN6: =(IF('Water Report'!$H$8>0,'Water Report'!$H$8,0)) -> 131 | AO6: =(IF('Water Report'!$H$9>0,'Water Report'!$H$9,0)) -> 125 | AP6: =(IF('Water Report'!$H$10>0,'Water Report'!$H$10,0)) -> 24 | AQ6: =(IF('Water Report'!$H$11>0,'Water Report'!$H$11,0)) -> 30 | AR6: =(IF('Water Report'!$H$13>0,'Water Report'!$H$13,0)) -> 21 | AS6: =(IF('Water Report'!$H$14>0,'Water Report'!$H$14,0)) -> 17 | AT6: =(IF('Water Report'!$H$15>0,'Water Report'!$H$15,0)) -> 16 | AU6: =(IF('Water Report'!$H$17>0,'Water Report'!$H$17,0)) -> 101 | AV6: =(IF('Water Report'!$H$18>0,'Water Report'!$H$18,0)) -> 10 | AW6: =(IF('Water Report'!$H$19>0,'Water Report'!$H$19,0)) -> 6 | AX6: =(IF('Water Report'!$H$21>0,'Water Report'!$H$21,0)) -> 75 | AY6: =(IF('Water Report'!$H$22>0,'Water Report'!$H$22,0)) -> 0 | AZ6: =(IF('Water Report'!$H$23>0,'Water Report'!$H$23,0)) -> 0 | BA6: =(IF('Water Report'!$H$14>0,'Water Report'!$H$14,0)) -> 17 | BB6: =(IF('Water Report'!$H$15>0,'Water Report'!$H$15,0)) -> 16 | BC6: =(IF('Water Report'!$H$13>0,'Water Report'!$H$13,0)) -> 21 | BD6: =(IF('Water Report'!$H$24>0,'Water Report'!$H$24,0)) -> 242 | BE6: =(IF('Water Report'!$H$25>0,'Water Report'!$H$25,0)) -> 212 | BF6: =(IF('Water Report'!$H$27>0,'Water Report'!$H$27,0)) -> 96 | BG6: =(IF('Section Load'!AN9>0,'Section Load'!AN9,0)) -> 738.088 | BH6: =(IF('Section Load'!AO9>0,'Section Load'!AO9,0)) -> 259.917 | BI6: =(IF('Section Load'!AP9>0,'Section Load'!AP9,0)) -> 0 | BJ6: =(IF('Section Load'!AQ9>0,'Section Load'!AQ9,0)) -> 71.4 | BK6: =(IF('Section Load'!AR9>0,'Section Load'!AR9,0)) -> 38.7 | BL6: =(IF('Section Load'!AS9>0,'Section Load'!AS9,0)) -> 1 | BM6: =(IF('Section Load'!AT9>0,'Section Load'!AT9,0)) -> 367.071
A7: Mumbai | B7: =B6+1 -> 6 | C7: 8 | D7: 2021 | E7: =(IF('Section Load'!F10>0,'Section Load'!F10,0)) -> 3208 | F7: =(IF('Section Load'!G10>0,'Section Load'!G10,0)) -> 1613 | G7: =(IF('Section Load'!H10>0,'Section Load'!H10,0)) -> 1713 | H7: =(IF('Section Load'!I10>0,'Section Load'!I10,0)) -> 3750 | I7: =(IF('Section Load'!J10>0,'Section Load'!J10,0)) -> 7934 | J7: =(IF('Section Load'!K10>0,'Section Load'!K10,0)) -> 2980 | K7: =(IF('Section Load'!L10>0,'Section Load'!L10,0)) -> 1519 | L7: =(IF('Section Load'!M10>0,'Section Load'!M10,0)) -> 698.96 | ... AL7: =(IF('Section Load'!AM10>0,'Section Load'!AM10,0)) -> 841 | AM7: =(IF('Water Report'!$I$7>0,'Water Report'!$I$7,0)) -> 114 | AN7: =(IF('Water Report'!$I$8>0,'Water Report'!$I$8,0)) -> 150 | AO7: =(IF('Water Report'!$I$9>0,'Water Report'!$I$9,0)) -> 74 | AP7: =(IF('Water Report'!$I$10>0,'Water Report'!$I$10,0)) -> 23 | AQ7: =(IF('Water Report'!$I$11>0,'Water Report'!$I$11,0)) -> 30 | AR7: =(IF('Water Report'!$I$13>0,'Water Report'!$I$13,0)) -> 13 | AS7: =(IF('Water Report'!$I$14>0,'Water Report'!$I$14,0)) -> 22 | AT7: =(IF('Water Report'!$I$15>0,'Water Report'!$I$15,0)) -> 6 | AU7: =(IF('Water Report'!$I$17>0,'Water Report'!$I$17,0)) -> 0 | AV7: =(IF('Water Report'!$I$18>0,'Water Report'!$I$18,0)) -> 8 | AW7: =(IF('Water Report'!$I$19>0,'Water Report'!$I$19,0)) -> 9 | AX7: =(IF('Water Report'!$I$21>0,'Water Report'!$I$21,0)) -> 77 | AY7: =(IF('Water Report'!$I$22>0,'Water Report'!$I$22,0)) -> 0 | AZ7: =(IF('Water Report'!$I$23>0,'Water Report'!$I$23,0)) -> 13 | BA7: =(IF('Water Report'!$I$14>0,'Water Report'!$I$14,0)) -> 22 | BB7: =(IF('Water Report'!$I$15>0,'Water Report'!$I$15,0)) -> 6 | BC7: =(IF('Water Report'!$I$13>0,'Water Report'!$I$13,0)) -> 13 | BD7: =(IF('Water Report'!$I$24>0,'Water Report'!$I$24,0)) -> 261 | BE7: =(IF('Water Report'!$I$25>0,'Water Report'!$I$25,0)) -> 155 | BF7: =(IF('Water Report'!$I$27>0,'Water Report'!$I$27,0)) -> 103 | BG7: =(IF('Section Load'!AN10>0,'Section Load'!AN10,0)) -> 968.18 | BH7: =(IF('Section Load'!AO10>0,'Section Load'!AO10,0)) -> 266.89 | BI7: =(IF('Section Load'!AP10>0,'Section Load'!AP10,0)) -> 0 | BJ7: =(IF('Section Load'!AQ10>0,'Section Load'!AQ10,0)) -> 107.76 | BK7: =(IF('Section Load'!AR10>0,'Section Load'!AR10,0)) -> 53.4 | BL7: =(IF('Section Load'!AS10>0,'Section Load'!AS10,0)) -> 1.1 | BM7: =(IF('Section Load'!AT10>0,'Section Load'!AT10,0)) -> 539.03
A8: Mumbai | B8: =B7+1 -> 7 | C8: 8 | D8: 2021 | E8: =(IF('Section Load'!F11>0,'Section Load'!F11,0)) -> 3068 | F8: =(IF('Section Load'!G11>0,'Section Load'!G11,0)) -> 1651 | G8: =(IF('Section Load'!H11>0,'Section Load'!H11,0)) -> 1801 | H8: =(IF('Section Load'!I11>0,'Section Load'!I11,0)) -> 3772 | I8: =(IF('Section Load'!J11>0,'Section Load'!J11,0)) -> 8272 | J8: =(IF('Section Load'!K11>0,'Section Load'!K11,0)) -> 3030 | K8: =(IF('Section Load'!L11>0,'Section Load'!L11,0)) -> 1147 | L8: =(IF('Section Load'!M11>0,'Section Load'!M11,0)) -> 743.9 | ... AL8: =(IF('Section Load'!AM11>0,'Section Load'!AM11,0)) -> 785 | AM8: =(IF('Water Report'!$J$7>0,'Water Report'!$J$7,0)) -> 129 | AN8: =(IF('Water Report'!$J$8>0,'Water Report'!$J$8,0)) -> 182 | AO8: =(IF('Water Report'!$J$9>0,'Water Report'!$J$9,0)) -> 86 | AP8: =(IF('Water Report'!$J$10>0,'Water Report'!$J$10,0)) -> 25 | AQ8: =(IF('Water Report'!$J$11>0,'Water Report'!$J$11,0)) -> 36 | AR8: =(IF('Water Report'!$J$13>0,'Water Report'!$J$13,0)) -> 36 | AS8: =(IF('Water Report'!$J$14>0,'Water Report'!$J$14,0)) -> 36 | AT8: =(IF('Water Report'!$J$15>0,'Water Report'!$J$15,0)) -> 1 | AU8: =(IF('Water Report'!$J$17>0,'Water Report'!$J$17,0)) -> 0 | AV8: =(IF('Water Report'!$J$18>0,'Water Report'!$J$18,0)) -> 11 | AW8: =(IF('Water Report'!$J$19>0,'Water Report'!$J$19,0)) -> 7 | AX8: =(IF('Water Report'!$J$21>0,'Water Report'!$J$21,0)) -> 79 | AY8: =(IF('Water Report'!$J$22>0,'Water Report'!$J$22,0)) -> 0 | AZ8: =(IF('Water Report'!$J$23>0,'Water Report'!$J$23,0)) -> 2 | BA8: =(IF('Water Report'!$J$14>0,'Water Report'!$J$14,0)) -> 36 | BB8: =(IF('Water Report'!$J$15>0,'Water Report'!$J$15,0)) -> 1 | BC8: =(IF('Water Report'!$J$13>0,'Water Report'!$J$13,0)) -> 36 | BD8: =(IF('Water Report'!$J$24>0,'Water Report'!$J$24,0)) -> 225 | BE8: =(IF('Water Report'!$J$25>0,'Water Report'!$J$25,0)) -> 184 | BF8: =(IF('Water Report'!$J$27>0,'Water Report'!$J$27,0)) -> 117 | BG8: =(IF('Section Load'!AN11>0,'Section Load'!AN11,0)) -> 860.81 | BH8: =(IF('Section Load'!AO11>0,'Section Load'!AO11,0)) -> 266.65 | BI8: =(IF('Section Load'!AP11>0,'Section Load'!AP11,0)) -> 0 | BJ8: =(IF('Section Load'!AQ11>0,'Section Load'!AQ11,0)) -> 96.31 | BK8: =(IF('Section Load'!AR11>0,'Section Load'!AR11,0)) -> 45.1 | BL8: =(IF('Section Load'!AS11>0,'Section Load'!AS11,0)) -> 3.9 | BM8: =(IF('Section Load'!AT11>0,'Section Load'!AT11,0)) -> 449.25
A9: Mumbai | B9: =B8+1 -> 8 | C9: 8 | D9: 2021 | E9: =(IF('Section Load'!F12>0,'Section Load'!F12,0)) -> 2939.7 | F9: =(IF('Section Load'!G12>0,'Section Load'!G12,0)) -> 1610 | G9: =(IF('Section Load'!H12>0,'Section Load'!H12,0)) -> 1794 | H9: =(IF('Section Load'!I12>0,'Section Load'!I12,0)) -> 3646.08 | I9: =(IF('Section Load'!J12>0,'Section Load'!J12,0)) -> 6557.53 | J9: =(IF('Section Load'!K12>0,'Section Load'!K12,0)) -> 2900 | K9: =(IF('Section Load'!L12>0,'Section Load'!L12,0)) -> 1089 | L9: =(IF('Section Load'!M12>0,'Section Load'!M12,0)) -> 688.5 | ... AL9: =(IF('Section Load'!AM12>0,'Section Load'!AM12,0)) -> 775 | AM9: =(IF('Water Report'!$K$7>0,'Water Report'!$K$7,0)) -> 129 | AN9: =(IF('Water Report'!$K$8>0,'Water Report'!$K$8,0)) -> 189 | AO9: =(IF('Water Report'!$K$9>0,'Water Report'!$K$9,0)) -> 74 | AP9: =(IF('Water Report'!$K$10>0,'Water Report'!$K$10,0)) -> 35 | AQ9: =(IF('Water Report'!$K$11>0,'Water Report'!$K$11,0)) -> 39 | AR9: =(IF('Water Report'!$K$13>0,'Water Report'!$K$13,0)) -> 24 | AS9: =(IF('Water Report'!$K$14>0,'Water Report'!$K$14,0)) -> 35 | AT9: =(IF('Water Report'!$K$15>0,'Water Report'!$K$15,0)) -> 12 | AU9: =(IF('Water Report'!$K$17>0,'Water Report'!$K$17,0)) -> 0 | AV9: =(IF('Water Report'!$K$18>0,'Water Report'!$K$18,0)) -> 8 | AW9: =(IF('Water Report'!$K$19>0,'Water Report'!$K$19,0)) -> 10 | AX9: =(IF('Water Report'!$K$21>0,'Water Report'!$K$21,0)) -> 81 | AY9: =(IF('Water Report'!$K$22>0,'Water Report'!$K$22,0)) -> 0 | AZ9: =(IF('Water Report'!$K$23>0,'Water Report'!$K$23,0)) -> 0 | BA9: =(IF('Water Report'!$K$14>0,'Water Report'!$K$14,0)) -> 35 | BB9: =(IF('Water Report'!$K$15>0,'Water Report'!$K$15,0)) -> 12 | BC9: =(IF('Water Report'!$K$13>0,'Water Report'!$K$13,0)) -> 24 | BD9: =(IF('Water Report'!$K$24>0,'Water Report'!$K$24,0)) -> 275 | BE9: =(IF('Water Report'!$K$25>0,'Water Report'!$K$25,0)) -> 195 | BF9: =(IF('Water Report'!$K$27>0,'Water Report'!$K$27,0)) -> 105 | BG9: =(IF('Section Load'!AN12>0,'Section Load'!AN12,0)) -> 902.73 | BH9: =(IF('Section Load'!AO12>0,'Section Load'!AO12,0)) -> 261.98 | BI9: =(IF('Section Load'!AP12>0,'Section Load'!AP12,0)) -> 0.4 | BJ9: =(IF('Section Load'!AQ12>0,'Section Load'!AQ12,0)) -> 95.36 | BK9: =(IF('Section Load'!AR12>0,'Section Load'!AR12,0)) -> 35.1 | BL9: =(IF('Section Load'!AS12>0,'Section Load'!AS12,0)) -> 1.5 | BM9: =(IF('Section Load'!AT12>0,'Section Load'!AT12,0)) -> 508.39
A10: Mumbai | B10: =B9+1 -> 9 | C10: 8 | D10: 2021 | E10: =(IF('Section Load'!F13>0,'Section Load'!F13,0)) -> 2734 | F10: =(IF('Section Load'!G13>0,'Section Load'!G13,0)) -> 1498 | G10: =(IF('Section Load'!H13>0,'Section Load'!H13,0)) -> 1606 | H10: =(IF('Section Load'!I13>0,'Section Load'!I13,0)) -> 3904 | I10: =(IF('Section Load'!J13>0,'Section Load'!J13,0)) -> 5620 | J10: =(IF('Section Load'!K13>0,'Section Load'!K13,0)) -> 2570 | K10: =(IF('Section Load'!L13>0,'Section Load'!L13,0)) -> 992 | L10: =(IF('Section Load'!M13>0,'Section Load'!M13,0)) -> 659 | ... AL10: =(IF('Section Load'!AM13>0,'Section Load'!AM13,0)) -> 781 | AM10: =(IF('Water Report'!$L$7>0,'Water Report'!$L$7,0)) -> 92 | AN10: =(IF('Water Report'!$L$8>0,'Water Report'!$L$8,0)) -> 158 | AO10: =(IF('Water Report'!$L$9>0,'Water Report'!$L$9,0)) -> 84 | AP10: =(IF('Water Report'!$L$10>0,'Water Report'!$L$10,0)) -> 29 | AQ10: =(IF('Water Report'!$L$11>0,'Water Report'!$L$11,0)) -> 23 | AR10: =(IF('Water Report'!$L$13>0,'Water Report'!$L$13,0)) -> 48 | AS10: =(IF('Water Report'!$L$14>0,'Water Report'!$L$14,0)) -> 16 | AT10: =(IF('Water Report'!$L$15>0,'Water Report'!$L$15,0)) -> 10 | AU10: =(IF('Water Report'!$L$17>0,'Water Report'!$L$17,0)) -> 0 | AV10: =(IF('Water Report'!$L$18>0,'Water Report'!$L$18,0)) -> 12 | AW10: =(IF('Water Report'!$L$19>0,'Water Report'!$L$19,0)) -> 10 | AX10: =(IF('Water Report'!$L$21>0,'Water Report'!$L$21,0)) -> 101 | AY10: =(IF('Water Report'!$L$22>0,'Water Report'!$L$22,0)) -> 0 | AZ10: =(IF('Water Report'!$L$23>0,'Water Report'!$L$23,0)) -> 5 | BA10: =(IF('Water Report'!$L$14>0,'Water Report'!$L$14,0)) -> 16 | BB10: =(IF('Water Report'!$L$15>0,'Water Report'!$L$15,0)) -> 10 | BC10: =(IF('Water Report'!$L$13>0,'Water Report'!$L$13,0)) -> 48 | BD10: =(IF('Water Report'!$L$24>0,'Water Report'!$L$24,0)) -> 224 | BE10: =(IF('Water Report'!$L$25>0,'Water Report'!$L$25,0)) -> 162 | BF10: =(IF('Water Report'!$L$27>0,'Water Report'!$L$27,0)) -> 154 | BG10: =(IF('Section Load'!AN13>0,'Section Load'!AN13,0)) -> 764 | BH10: =(IF('Section Load'!AO13>0,'Section Load'!AO13,0)) -> 262 | BI10: =(IF('Section Load'!AP13>0,'Section Load'!AP13,0)) -> 0 | BJ10: =(IF('Section Load'!AQ13>0,'Section Load'!AQ13,0)) -> 76 | BK10: =(IF('Section Load'!AR13>0,'Section Load'!AR13,0)) -> 32 | BL10: =(IF('Section Load'!AS13>0,'Section Load'!AS13,0)) -> 0.8 | BM10: =(IF('Section Load'!AT13>0,'Section Load'!AT13,0)) -> 393.2
A11: Mumbai | B11: =B10+1 -> 10 | C11: 8 | D11: 2021 | E11: =(IF('Section Load'!F14>0,'Section Load'!F14,0)) -> 2950 | F11: =(IF('Section Load'!G14>0,'Section Load'!G14,0)) -> 1555 | G11: =(IF('Section Load'!H14>0,'Section Load'!H14,0)) -> 1654 | H11: =(IF('Section Load'!I14>0,'Section Load'!I14,0)) -> 3790.33 | I11: =(IF('Section Load'!J14>0,'Section Load'!J14,0)) -> 6540 | J11: =(IF('Section Load'!K14>0,'Section Load'!K14,0)) -> 2950 | K11: =(IF('Section Load'!L14>0,'Section Load'!L14,0)) -> 892 | L11: =(IF('Section Load'!M14>0,'Section Load'!M14,0)) -> 714 | ... AL11: =(IF('Section Load'!AM14>0,'Section Load'!AM14,0)) -> 749 | AM11: =(IF('Water Report'!$M$7>0,'Water Report'!$M$7,0)) -> 87 | AN11: =(IF('Water Report'!$M$8>0,'Water Report'!$M$8,0)) -> 185 | AO11: =(IF('Water Report'!$M$9>0,'Water Report'!$M$9,0)) -> 76 | AP11: =(IF('Water Report'!$M$10>0,'Water Report'!$M$10,0)) -> 23 | AQ11: =(IF('Water Report'!$M$11>0,'Water Report'!$M$11,0)) -> 20 | AR11: =(IF('Water Report'!$M$13>0,'Water Report'!$M$13,0)) -> 18 | AS11: =(IF('Water Report'!$M$14>0,'Water Report'!$M$14,0)) -> 22 | AT11: =(IF('Water Report'!$M$15>0,'Water Report'!$M$15,0)) -> 6 | AU11: =(IF('Water Report'!$M$17>0,'Water Report'!$M$17,0)) -> 0 | AV11: =(IF('Water Report'!$M$18>0,'Water Report'!$M$18,0)) -> 7 | AW11: =(IF('Water Report'!$M$19>0,'Water Report'!$M$19,0)) -> 9 | AX11: =(IF('Water Report'!$M$21>0,'Water Report'!$M$21,0)) -> 78 | AY11: =(IF('Water Report'!$M$22>0,'Water Report'!$M$22,0)) -> 0 | AZ11: =(IF('Water Report'!$M$23>0,'Water Report'!$M$23,0)) -> 3 | BA11: =(IF('Water Report'!$M$14>0,'Water Report'!$M$14,0)) -> 22 | BB11: =(IF('Water Report'!$M$15>0,'Water Report'!$M$15,0)) -> 6 | BC11: =(IF('Water Report'!$M$13>0,'Water Report'!$M$13,0)) -> 18 | BD11: =(IF('Water Report'!$M$24>0,'Water Report'!$M$24,0)) -> 197 | BE11: =(IF('Water Report'!$M$25>0,'Water Report'!$M$25,0)) -> 147 | BF11: =(IF('Water Report'!$M$27>0,'Water Report'!$M$27,0)) -> 99 | BG11: =(IF('Section Load'!AN14>0,'Section Load'!AN14,0)) -> 907 | BH11: =(IF('Section Load'!AO14>0,'Section Load'!AO14,0)) -> 279 | BI11: =(IF('Section Load'!AP14>0,'Section Load'!AP14,0)) -> 0 | BJ11: =(IF('Section Load'!AQ14>0,'Section Load'!AQ14,0)) -> 84 | BK11: =(IF('Section Load'!AR14>0,'Section Load'!AR14,0)) -> 34 | BL11: =(IF('Section Load'!AS14>0,'Section Load'!AS14,0)) -> 2.2 | BM11: =(IF('Section Load'!AT14>0,'Section Load'!AT14,0)) -> 507.8
A12: Mumbai | B12: =B11+1 -> 11 | C12: 8 | D12: 2021 | E12: =(IF('Section Load'!F15>0,'Section Load'!F15,0)) -> 3073 | F12: =(IF('Section Load'!G15>0,'Section Load'!G15,0)) -> 1551 | G12: =(IF('Section Load'!H15>0,'Section Load'!H15,0)) -> 1631 | H12: =(IF('Section Load'!I15>0,'Section Load'!I15,0)) -> 3772.59 | I12: =(IF('Section Load'!J15>0,'Section Load'!J15,0)) -> 6303 | J12: =(IF('Section Load'!K15>0,'Section Load'!K15,0)) -> 2940 | K12: =(IF('Section Load'!L15>0,'Section Load'!L15,0)) -> 1053 | L12: =(IF('Section Load'!M15>0,'Section Load'!M15,0)) -> 691 | ... AL12: =(IF('Section Load'!AM15>0,'Section Load'!AM15,0)) -> 773 | AM12: =(IF('Water Report'!$N$7>0,'Water Report'!$N$7,0)) -> 85 | AN12: =(IF('Water Report'!$N$8>0,'Water Report'!$N$8,0)) -> 133 | AO12: =(IF('Water Report'!$N$9>0,'Water Report'!$N$9,0)) -> 69 | AP12: =(IF('Water Report'!$N$10>0,'Water Report'!$N$10,0)) -> 24 | AQ12: =(IF('Water Report'!$N$11>0,'Water Report'!$N$11,0)) -> 24 | AR12: =(IF('Water Report'!$N$13>0,'Water Report'!$N$13,0)) -> 20 | AS12: =(IF('Water Report'!$N$14>0,'Water Report'!$N$14,0)) -> 17 | AT12: =(IF('Water Report'!$N$15>0,'Water Report'!$N$15,0)) -> 15 | AU12: =(IF('Water Report'!$N$17>0,'Water Report'!$N$17,0)) -> 0 | AV12: =(IF('Water Report'!$N$18>0,'Water Report'!$N$18,0)) -> 8 | AW12: =(IF('Water Report'!$N$19>0,'Water Report'!$N$19,0)) -> 7 | AX12: =(IF('Water Report'!$N$21>0,'Water Report'!$N$21,0)) -> 77 | AY12: =(IF('Water Report'!$N$22>0,'Water Report'!$N$22,0)) -> 0 | AZ12: =(IF('Water Report'!$N$23>0,'Water Report'!$N$23,0)) -> 2 | BA12: =(IF('Water Report'!$N$14>0,'Water Report'!$N$14,0)) -> 17 | BB12: =(IF('Water Report'!$N$15>0,'Water Report'!$N$15,0)) -> 15 | BC12: =(IF('Water Report'!$N$13>0,'Water Report'!$N$13,0)) -> 20 | BD12: =(IF('Water Report'!$N$24>0,'Water Report'!$N$24,0)) -> 224 | BE12: =(IF('Water Report'!$N$25>0,'Water Report'!$N$25,0)) -> 149 | BF12: =(IF('Water Report'!$N$27>0,'Water Report'!$N$27,0)) -> 99 | BG12: =(IF('Section Load'!AN15>0,'Section Load'!AN15,0)) -> 826 | BH12: =(IF('Section Load'!AO15>0,'Section Load'!AO15,0)) -> 281 | BI12: =(IF('Section Load'!AP15>0,'Section Load'!AP15,0)) -> 0 | BJ12: =(IF('Section Load'!AQ15>0,'Section Load'!AQ15,0)) -> 91 | BK12: =(IF('Section Load'!AR15>0,'Section Load'!AR15,0)) -> 50 | BL12: =(IF('Section Load'!AS15>0,'Section Load'!AS15,0)) -> 2 | BM12: =(IF('Section Load'!AT15>0,'Section Load'!AT15,0)) -> 402
A13: Mumbai | B13: =B12+1 -> 12 | C13: 8 | D13: 2021 | E13: =(IF('Section Load'!F16>0,'Section Load'!F16,0)) -> 3146 | F13: =(IF('Section Load'!G16>0,'Section Load'!G16,0)) -> 1629 | G13: =(IF('Section Load'!H16>0,'Section Load'!H16,0)) -> 1686 | H13: =(IF('Section Load'!I16>0,'Section Load'!I16,0)) -> 4025.41 | I13: =(IF('Section Load'!J16>0,'Section Load'!J16,0)) -> 7375 | J13: =(IF('Section Load'!K16>0,'Section Load'!K16,0)) -> 3210 | K13: =(IF('Section Load'!L16>0,'Section Load'!L16,0)) -> 965 | L13: =(IF('Section Load'!M16>0,'Section Load'!M16,0)) -> 837.7 | ... AL13: =(IF('Section Load'!AM16>0,'Section Load'!AM16,0)) -> 746 | AM13: =(IF('Water Report'!$O$7>0,'Water Report'!$O$7,0)) -> 94 | AN13: =(IF('Water Report'!$O$8>0,'Water Report'!$O$8,0)) -> 93 | AO13: =(IF('Water Report'!$O$9>0,'Water Report'!$O$9,0)) -> 87 | AP13: =(IF('Water Report'!$O$10>0,'Water Report'!$O$10,0)) -> 24 | AQ13: =(IF('Water Report'!$O$11>0,'Water Report'!$O$11,0)) -> 26 | AR13: =(IF('Water Report'!$O$13>0,'Water Report'!$O$13,0)) -> 41 | AS13: =(IF('Water Report'!$O$14>0,'Water Report'!$O$14,0)) -> 14 | AT13: =(IF('Water Report'!$O$15>0,'Water Report'!$O$15,0)) -> 9 | AU13: =(IF('Water Report'!$O$17>0,'Water Report'!$O$17,0)) -> 0 | AV13: =(IF('Water Report'!$O$18>0,'Water Report'!$O$18,0)) -> 9 | AW13: =(IF('Water Report'!$O$19>0,'Water Report'!$O$19,0)) -> 8 | AX13: =(IF('Water Report'!$O$21>0,'Water Report'!$O$21,0)) -> 82 | AY13: =(IF('Water Report'!$O$22>0,'Water Report'!$O$22,0)) -> 0 | AZ13: =(IF('Water Report'!$O$23>0,'Water Report'!$O$23,0)) -> 0 | BA13: =(IF('Water Report'!$O$14>0,'Water Report'!$O$14,0)) -> 14 | BB13: =(IF('Water Report'!$O$15>0,'Water Report'!$O$15,0)) -> 9 | BC13: =(IF('Water Report'!$O$13>0,'Water Report'!$O$13,0)) -> 41 | BD13: =(IF('Water Report'!$O$24>0,'Water Report'!$O$24,0)) -> 240 | BE13: =(IF('Water Report'!$O$25>0,'Water Report'!$O$25,0)) -> 160 | BF13: =(IF('Water Report'!$O$27>0,'Water Report'!$O$27,0)) -> 123 | BG13: =(IF('Section Load'!AN16>0,'Section Load'!AN16,0)) -> 930 | BH13: =(IF('Section Load'!AO16>0,'Section Load'!AO16,0)) -> 275 | BI13: =(IF('Section Load'!AP16>0,'Section Load'!AP16,0)) -> 0 | BJ13: =(IF('Section Load'!AQ16>0,'Section Load'!AQ16,0)) -> 80 | BK13: =(IF('Section Load'!AR16>0,'Section Load'!AR16,0)) -> 69 | BL13: =(IF('Section Load'!AS16>0,'Section Load'!AS16,0)) -> 2 | BM13: =(IF('Section Load'!AT16>0,'Section Load'!AT16,0)) -> 504.4
A14: Mumbai | B14: =B13+1 -> 13 | C14: 8 | D14: 2021 | E14: =(IF('Section Load'!F17>0,'Section Load'!F17,0)) -> 3138 | F14: =(IF('Section Load'!G17>0,'Section Load'!G17,0)) -> 1619 | G14: =(IF('Section Load'!H17>0,'Section Load'!H17,0)) -> 1802 | H14: =(IF('Section Load'!I17>0,'Section Load'!I17,0)) -> 3617 | I14: =(IF('Section Load'!J17>0,'Section Load'!J17,0)) -> 6670 | J14: =(IF('Section Load'!K17>0,'Section Load'!K17,0)) -> 2730.33 | K14: =(IF('Section Load'!L17>0,'Section Load'!L17,0)) -> 1196 | L14: =(IF('Section Load'!M17>0,'Section Load'!M17,0)) -> 726.9 | ... AL14: =(IF('Section Load'!AM17>0,'Section Load'!AM17,0)) -> 804 | AM14: =(IF('Water Report'!$P$7>0,'Water Report'!$P$7,0)) -> 105 | AN14: =(IF('Water Report'!$P$8>0,'Water Report'!$P$8,0)) -> 164 | AO14: =(IF('Water Report'!$P$9>0,'Water Report'!$P$9,0)) -> 74 | AP14: =(IF('Water Report'!$P$10>0,'Water Report'!$P$10,0)) -> 25 | AQ14: =(IF('Water Report'!$P$11>0,'Water Report'!$P$11,0)) -> 32 | AR14: =(IF('Water Report'!$P$13>0,'Water Report'!$P$13,0)) -> 31 | AS14: =(IF('Water Report'!$P$14>0,'Water Report'!$P$14,0)) -> 15 | AT14: =(IF('Water Report'!$P$15>0,'Water Report'!$P$15,0)) -> 15 | AU14: =(IF('Water Report'!$P$17>0,'Water Report'!$P$17,0)) -> 0 | AV14: =(IF('Water Report'!$P$18>0,'Water Report'!$P$18,0)) -> 9 | AW14: =(IF('Water Report'!$P$19>0,'Water Report'!$P$19,0)) -> 11 | AX14: =(IF('Water Report'!$P$21>0,'Water Report'!$P$21,0)) -> 96 | AY14: =(IF('Water Report'!$P$22>0,'Water Report'!$P$22,0)) -> 0 | AZ14: =(IF('Water Report'!$P$23>0,'Water Report'!$P$23,0)) -> 3 | BA14: =(IF('Water Report'!$P$14>0,'Water Report'!$P$14,0)) -> 15 | BB14: =(IF('Water Report'!$P$15>0,'Water Report'!$P$15,0)) -> 15 | BC14: =(IF('Water Report'!$P$13>0,'Water Report'!$P$13,0)) -> 31 | BD14: =(IF('Water Report'!$P$24>0,'Water Report'!$P$24,0)) -> 251 | BE14: =(IF('Water Report'!$P$25>0,'Water Report'!$P$25,0)) -> 161 | BF14: =(IF('Water Report'!$P$27>0,'Water Report'!$P$27,0)) -> 130 | BG14: =(IF('Section Load'!AN17>0,'Section Load'!AN17,0)) -> 901 | BH14: =(IF('Section Load'!AO17>0,'Section Load'!AO17,0)) -> 277 | BI14: =(IF('Section Load'!AP17>0,'Section Load'!AP17,0)) -> 0 | BJ14: =(IF('Section Load'!AQ17>0,'Section Load'!AQ17,0)) -> 101 | BK14: =(IF('Section Load'!AR17>0,'Section Load'!AR17,0)) -> 35 | BL14: =(IF('Section Load'!AS17>0,'Section Load'!AS17,0)) -> 2 | BM14: =(IF('Section Load'!AT17>0,'Section Load'!AT17,0)) -> 486
A15: Mumbai | B15: =B14+1 -> 14 | C15: 8 | D15: 2021 | E15: =(IF('Section Load'!F18>0,'Section Load'!F18,0)) -> 3064 | F15: =(IF('Section Load'!G18>0,'Section Load'!G18,0)) -> 1554 | G15: =(IF('Section Load'!H18>0,'Section Load'!H18,0)) -> 1717 | H15: =(IF('Section Load'!I18>0,'Section Load'!I18,0)) -> 3673.59 | I15: =(IF('Section Load'!J18>0,'Section Load'!J18,0)) -> 6022 | J15: =(IF('Section Load'!K18>0,'Section Load'!K18,0)) -> 2490 | K15: =(IF('Section Load'!L18>0,'Section Load'!L18,0)) -> 986 | L15: =(IF('Section Load'!M18>0,'Section Load'!M18,0)) -> 633.4 | ... AL15: =(IF('Section Load'!AM18>0,'Section Load'!AM18,0)) -> 807 | AM15: =(IF('Water Report'!$Q$7>0,'Water Report'!$Q$7,0)) -> 83 | AN15: =(IF('Water Report'!$Q$8>0,'Water Report'!$Q$8,0)) -> 179 | AO15: =(IF('Water Report'!$Q$9>0,'Water Report'!$Q$9,0)) -> 69 | AP15: =(IF('Water Report'!$Q$10>0,'Water Report'!$Q$10,0)) -> 22 | AQ15: =(IF('Water Report'!$Q$11>0,'Water Report'!$Q$11,0)) -> 36 | AR15: =(IF('Water Report'!$Q$13>0,'Water Report'!$Q$13,0)) -> 11 | AS15: =(IF('Water Report'!$Q$14>0,'Water Report'!$Q$14,0)) -> 15 | AT15: =(IF('Water Report'!$Q$15>0,'Water Report'!$Q$15,0)) -> 9 | AU15: =(IF('Water Report'!$Q$17>0,'Water Report'!$Q$17,0)) -> 15 | AV15: =(IF('Water Report'!$Q$18>0,'Water Report'!$Q$18,0)) -> 8 | AW15: =(IF('Water Report'!$Q$19>0,'Water Report'!$Q$19,0)) -> 11 | AX15: =(IF('Water Report'!$Q$21>0,'Water Report'!$Q$21,0)) -> 71 | AY15: =(IF('Water Report'!$Q$22>0,'Water Report'!$Q$22,0)) -> 0 | AZ15: =(IF('Water Report'!$Q$23>0,'Water Report'!$Q$23,0)) -> 0 | BA15: =(IF('Water Report'!$Q$14>0,'Water Report'!$Q$14,0)) -> 15 | BB15: =(IF('Water Report'!$Q$15>0,'Water Report'!$Q$15,0)) -> 9 | BC15: =(IF('Water Report'!$Q$13>0,'Water Report'!$Q$13,0)) -> 11 | BD15: =(IF('Water Report'!$Q$24>0,'Water Report'!$Q$24,0)) -> 223 | BE15: =(IF('Water Report'!$Q$25>0,'Water Report'!$Q$25,0)) -> 151 | BF15: =(IF('Water Report'!$Q$27>0,'Water Report'!$Q$27,0)) -> 82 | BG15: =(IF('Section Load'!AN18>0,'Section Load'!AN18,0)) -> 1092 | BH15: =(IF('Section Load'!AO18>0,'Section Load'!AO18,0)) -> 271 | BI15: =(IF('Section Load'!AP18>0,'Section Load'!AP18,0)) -> 0.4 | BJ15: =(IF('Section Load'!AQ18>0,'Section Load'!AQ18,0)) -> 110 | BK15: =(IF('Section Load'!AR18>0,'Section Load'!AR18,0)) -> 47 | BL15: =(IF('Section Load'!AS18>0,'Section Load'!AS18,0)) -> 4 | BM15: =(IF('Section Load'!AT18>0,'Section Load'!AT18,0)) -> 659.6
A16: Mumbai | B16: =B15+1 -> 15 | C16: 8 | D16: 2021 | E16: =(IF('Section Load'!F19>0,'Section Load'!F19,0)) -> 2975 | F16: =(IF('Section Load'!G19>0,'Section Load'!G19,0)) -> 1554 | G16: =(IF('Section Load'!H19>0,'Section Load'!H19,0)) -> 1841.93 | H16: =(IF('Section Load'!I19>0,'Section Load'!I19,0)) -> 3671.41 | I16: =(IF('Section Load'!J19>0,'Section Load'!J19,0)) -> 6209 | J16: =(IF('Section Load'!K19>0,'Section Load'!K19,0)) -> 2580 | K16: =(IF('Section Load'!L19>0,'Section Load'!L19,0)) -> 1206 | L16: =(IF('Section Load'!M19>0,'Section Load'!M19,0)) -> 823 | ... AL16: =(IF('Section Load'!AM19>0,'Section Load'!AM19,0)) -> 837 | AM16: =(IF('Water Report'!$R$7>0,'Water Report'!$R$7,0)) -> 130 | AN16: =(IF('Water Report'!$R$8>0,'Water Report'!$R$8,0)) -> 168 | AO16: =(IF('Water Report'!$R$9>0,'Water Report'!$R$9,0)) -> 78 | AP16: =(IF('Water Report'!$R$10>0,'Water Report'!$R$10,0)) -> 38 | AQ16: =(IF('Water Report'!$R$11>0,'Water Report'!$R$11,0)) -> 41 | AR16: =(IF('Water Report'!$R$13>0,'Water Report'!$R$13,0)) -> 50 | AS16: =(IF('Water Report'!$R$14>0,'Water Report'!$R$14,0)) -> 20 | AT16: =(IF('Water Report'!$R$15>0,'Water Report'!$R$15,0)) -> 13 | AU16: =(IF('Water Report'!$R$17>0,'Water Report'!$R$17,0)) -> 0 | AV16: =(IF('Water Report'!$R$18>0,'Water Report'!$R$18,0)) -> 11 | AW16: =(IF('Water Report'!$R$19>0,'Water Report'!$R$19,0)) -> 9 | AX16: =(IF('Water Report'!$R$21>0,'Water Report'!$R$21,0)) -> 47 | AY16: =(IF('Water Report'!$R$22>0,'Water Report'!$R$22,0)) -> 0 | AZ16: =(IF('Water Report'!$R$23>0,'Water Report'!$R$23,0)) -> 0 | BA16: =(IF('Water Report'!$R$14>0,'Water Report'!$R$14,0)) -> 20 | BB16: =(IF('Water Report'!$R$15>0,'Water Report'!$R$15,0)) -> 13 | BC16: =(IF('Water Report'!$R$13>0,'Water Report'!$R$13,0)) -> 50 | BD16: =(IF('Water Report'!$R$24>0,'Water Report'!$R$24,0)) -> 254 | BE16: =(IF('Water Report'!$R$25>0,'Water Report'!$R$25,0)) -> 190 | BF16: =(IF('Water Report'!$R$27>0,'Water Report'!$R$27,0)) -> 97 | BG16: =(IF('Section Load'!AN19>0,'Section Load'!AN19,0)) -> 920 | BH16: =(IF('Section Load'!AO19>0,'Section Load'!AO19,0)) -> 304 | BI16: =(IF('Section Load'!AP19>0,'Section Load'!AP19,0)) -> 0 | BJ16: =(IF('Section Load'!AQ19>0,'Section Load'!AQ19,0)) -> 86 | BK16: =(IF('Section Load'!AR19>0,'Section Load'!AR19,0)) -> 57 | BL16: =(IF('Section Load'!AS19>0,'Section Load'!AS19,0)) -> 3 | BM16: =(IF('Section Load'!AT19>0,'Section Load'!AT19,0)) -> 470
A17: Mumbai | B17: =B16+1 -> 16 | C17: 8 | D17: 2021 | E17: =(IF('Section Load'!F20>0,'Section Load'!F20,0)) -> 0 | F17: =(IF('Section Load'!G20>0,'Section Load'!G20,0)) -> 0 | G17: =(IF('Section Load'!H20>0,'Section Load'!H20,0)) -> 0 | H17: =(IF('Section Load'!I20>0,'Section Load'!I20,0)) -> 0 | I17: =(IF('Section Load'!J20>0,'Section Load'!J20,0)) -> 0 | J17: =(IF('Section Load'!K20>0,'Section Load'!K20,0)) -> 0 | K17: =(IF('Section Load'!L20>0,'Section Load'!L20,0)) -> 0 | L17: =(IF('Section Load'!M20>0,'Section Load'!M20,0)) -> 0 | ... AL17: =(IF('Section Load'!AM20>0,'Section Load'!AM20,0)) -> 0 | AM17: =(IF('Water Report'!$S$7>0,'Water Report'!$S$7,0)) -> 0 | AN17: =(IF('Water Report'!$S$8>0,'Water Report'!$S$8,0)) -> 0 | AO17: =(IF('Water Report'!$S$9>0,'Water Report'!$S$9,0)) -> 0 | AP17: =(IF('Water Report'!$S$10>0,'Water Report'!$D$10,0)) -> 0 | AQ17: =(IF('Water Report'!$S$11>0,'Water Report'!$D$11,0)) -> 0 | AR17: =(IF('Water Report'!$S$13>0,'Water Report'!$D$13,0)) -> 0 | AS17: =(IF('Water Report'!$S$14>0,'Water Report'!$D$14,0)) -> 0 | AT17: =(IF('Water Report'!$S$15>0,'Water Report'!$D$15,0)) -> 0 | AU17: =(IF('Water Report'!$S$17>0,'Water Report'!$D$17,0)) -> 0 | AV17: =(IF('Water Report'!$S$18>0,'Water Report'!$D$18,0)) -> 0 | AW17: =(IF('Water Report'!$S$19>0,'Water Report'!$D$19,0)) -> 0 | AX17: =(IF('Water Report'!$S$21>0,'Water Report'!$D$21,0)) -> 0 | AY17: =(IF('Water Report'!$S$22>0,'Water Report'!$D$22,0)) -> 0 | AZ17: =(IF('Water Report'!$S$23>0,'Water Report'!$D$23,0)) -> 0 | BA17: =(IF('Water Report'!$S$14>0,'Water Report'!$D$14,0)) -> 0 | BB17: =(IF('Water Report'!$S$15>0,'Water Report'!$D$15,0)) -> 0 | BC17: =(IF('Water Report'!$S$13>0,'Water Report'!$D$13,0)) -> 0 | BD17: =(IF('Water Report'!$S$24>0,'Water Report'!$D$24,0)) -> 243 | BE17: =(IF('Water Report'!$S$25>0,'Water Report'!$D$25,0)) -> 0 | BF17: =(IF('Water Report'!$S$27>0,'Water Report'!$D$27,0)) -> 0 | BG17: =(IF('Section Load'!AN20>0,'Section Load'!AN20,0)) -> 950 | BH17: =(IF('Section Load'!AO20>0,'Section Load'!AO20,0)) -> 0 | BI17: =(IF('Section Load'!AP20>0,'Section Load'!AP20,0)) -> 0 | BJ17: =(IF('Section Load'!AQ20>0,'Section Load'!AQ20,0)) -> 0 | BK17: =(IF('Section Load'!AR20>0,'Section Load'!AR20,0)) -> 0 | BL17: =(IF('Section Load'!AS20>0,'Section Load'!AS20,0)) -> 0 | BM17: =(IF('Section Load'!AT20>0,'Section Load'!AT20,0)) -> 12891.36
A18: Mumbai | B18: =B17+1 -> 17 | C18: 8 | D18: 2021 | E18: =(IF('Section Load'!F21>0,'Section Load'!F21,0)) -> 3270.42 | F18: =(IF('Section Load'!G21>0,'Section Load'!G21,0)) -> 1656.55 | G18: =(IF('Section Load'!H21>0,'Section Load'!H21,0)) -> 1759.92 | H18: =(IF('Section Load'!I21>0,'Section Load'!I21,0)) -> 3718.93 | I18: =(IF('Section Load'!J21>0,'Section Load'!J21,0)) -> 8133.4 | J18: =(IF('Section Load'!K21>0,'Section Load'!K21,0)) -> 3097.4 | K18: =(IF('Section Load'!L21>0,'Section Load'!L21,0)) -> 1300.44 | L18: =(IF('Section Load'!M21>0,'Section Load'!M21,0)) -> 1131.82 | ... AL18: =(IF('Section Load'!AM21>0,'Section Load'!AM21,0)) -> 678 | AM18: =(IF('Water Report'!$T$7>0,'Water Report'!$T$7,0)) -> 101 | AN18: =(IF('Water Report'!$T$8>0,'Water Report'!$T$8,0)) -> 190 | AO18: =(IF('Water Report'!$T$9>0,'Water Report'!$T$9,0)) -> 89 | AP18: =(IF('Water Report'!$T$10>0,'Water Report'!$T$10,0)) -> 30 | AQ18: =(IF('Water Report'!$T$11>0,'Water Report'!$T$11,0)) -> 30 | AR18: =(IF('Water Report'!$T$13>0,'Water Report'!$T$13,0)) -> 23 | AS18: =(IF('Water Report'!$T$14>0,'Water Report'!$T$14,0)) -> 16 | AT18: =(IF('Water Report'!$T$15>0,'Water Report'!$T$15,0)) -> 8 | AU18: =(IF('Water Report'!$T$17>0,'Water Report'!$T$17,0)) -> 0 | AV18: =(IF('Water Report'!$T$18>0,'Water Report'!$T$18,0)) -> 11 | AW18: =(IF('Water Report'!$T$19>0,'Water Report'!$T$19,0)) -> 4 | AX18: =(IF('Water Report'!$T$21>0,'Water Report'!$T$21,0)) -> 66 | AY18: =(IF('Water Report'!$T$22>0,'Water Report'!$T$22,0)) -> 26 | AZ18: =(IF('Water Report'!$T$23>0,'Water Report'!$T$23,0)) -> 0 | BA18: =(IF('Water Report'!$T$14>0,'Water Report'!$T$14,0)) -> 16 | BB18: =(IF('Water Report'!$T$15>0,'Water Report'!$T$15,0)) -> 8 | BC18: =(IF('Water Report'!$T$13>0,'Water Report'!$T$13,0)) -> 23 | BD18: =(IF('Water Report'!$T$24>0,'Water Report'!$T$24,0)) -> 200 | BE18: =(IF('Water Report'!$T$25>0,'Water Report'!$T$25,0)) -> 173 | BF18: =(IF('Water Report'!$T$27>0,'Water Report'!$T$27,0)) -> 89 | BG18: =(IF('Section Load'!AN21>0,'Section Load'!AN21,0)) -> 950 | BH18: =(IF('Section Load'!AO21>0,'Section Load'!AO21,0)) -> 289.02 | BI18: =(IF('Section Load'!AP21>0,'Section Load'!AP21,0)) -> 0 | BJ18: =(IF('Section Load'!AQ21>0,'Section Load'!AQ21,0)) -> 114.2 | BK18: =(IF('Section Load'!AR21>0,'Section Load'!AR21,0)) -> 41 | BL18: =(IF('Section Load'!AS21>0,'Section Load'!AS21,0)) -> 6.7 | BM18: =(IF('Section Load'!AT21>0,'Section Load'!AT21,0)) -> 499.08
A19: Mumbai | B19: =B18+1 -> 18 | C19: 8 | D19: 2021 | E19: =(IF('Section Load'!F22>0,'Section Load'!F22,0)) -> 3484.808 | F19: =(IF('Section Load'!G22>0,'Section Load'!G22,0)) -> 1846.52 | G19: =(IF('Section Load'!H22>0,'Section Load'!H22,0)) -> 1840.98 | H19: =(IF('Section Load'!I22>0,'Section Load'!I22,0)) -> 3750.84 | I19: =(IF('Section Load'!J22>0,'Section Load'!J22,0)) -> 8129.57 | J19: =(IF('Section Load'!K22>0,'Section Load'!K22,0)) -> 3145.2 | K19: =(IF('Section Load'!L22>0,'Section Load'!L22,0)) -> 1712.2 | L19: =(IF('Section Load'!M22>0,'Section Load'!M22,0)) -> 1191.63 | ... AL19: =(IF('Section Load'!AM22>0,'Section Load'!AM22,0)) -> 823 | AM19: =(IF('Water Report'!$U$7>0,'Water Report'!$U$7,0)) -> 163 | AN19: =(IF('Water Report'!$U$8>0,'Water Report'!$U$8,0)) -> 160 | AO19: =(IF('Water Report'!$U$9>0,'Water Report'!$U$9,0)) -> 90 | AP19: =(IF('Water Report'!$U$10>0,'Water Report'!$U$10,0)) -> 30 | AQ19: =(IF('Water Report'!$U$11>0,'Water Report'!$U$11,0)) -> 29 | AR19: =(IF('Water Report'!$U$13>0,'Water Report'!$U$13,0)) -> 27 | AS19: =(IF('Water Report'!$U$14>0,'Water Report'!$U$14,0)) -> 19 | AT19: =(IF('Water Report'!$U$15>0,'Water Report'!$U$15,0)) -> 9 | AU19: =(IF('Water Report'!$U$17>0,'Water Report'!$U$17,0)) -> 0 | AV19: =(IF('Water Report'!$U$18>0,'Water Report'!$U$18,0)) -> 10 | AW19: =(IF('Water Report'!$U$19>0,'Water Report'!$U$19,0)) -> 5 | AX19: =(IF('Water Report'!$U$21>0,'Water Report'!$U$21,0)) -> 65 | AY19: =(IF('Water Report'!$U$22>0,'Water Report'!$U$22,0)) -> 12 | AZ19: =(IF('Water Report'!$U$23>0,'Water Report'!$U$23,0)) -> 0 | BA19: =(IF('Water Report'!$U$14>0,'Water Report'!$U$14,0)) -> 19 | BB19: =(IF('Water Report'!$U$15>0,'Water Report'!$U$15,0)) -> 9 | BC19: =(IF('Water Report'!$U$13>0,'Water Report'!$U$13,0)) -> 27 | BD19: =(IF('Water Report'!$U$24>0,'Water Report'!$U$24,0)) -> 230 | BE19: =(IF('Water Report'!$U$25>0,'Water Report'!$U$25,0)) -> 177 | BF19: =(IF('Water Report'!$U$27>0,'Water Report'!$U$27,0)) -> 92 | BG19: =(IF('Section Load'!AN22>0,'Section Load'!AN22,0)) -> 950 | BH19: =(IF('Section Load'!AO22>0,'Section Load'!AO22,0)) -> 295.74 | BI19: =(IF('Section Load'!AP22>0,'Section Load'!AP22,0)) -> 0 | BJ19: =(IF('Section Load'!AQ22>0,'Section Load'!AQ22,0)) -> 107.8 | BK19: =(IF('Section Load'!AR22>0,'Section Load'!AR22,0)) -> 45.1 | BL19: =(IF('Section Load'!AS22>0,'Section Load'!AS22,0)) -> 4.9 | BM19: =(IF('Section Load'!AT22>0,'Section Load'!AT22,0)) -> 496.46
A20: Mumbai | B20: =B19+1 -> 19 | C20: 8 | D20: 2021 | E20: =(IF('Section Load'!F23>0,'Section Load'!F23,0)) -> 3252.302 | F20: =(IF('Section Load'!G23>0,'Section Load'!G23,0)) -> 1591.16 | G20: =(IF('Section Load'!H23>0,'Section Load'!H23,0)) -> 1606.46 | H20: =(IF('Section Load'!I23>0,'Section Load'!I23,0)) -> 3770.33 | I20: =(IF('Section Load'!J23>0,'Section Load'!J23,0)) -> 6446.2 | J20: =(IF('Section Load'!K23>0,'Section Load'!K23,0)) -> 2549.57 | K20: =(IF('Section Load'!L23>0,'Section Load'!L23,0)) -> 1093.93 | L20: =(IF('Section Load'!M23>0,'Section Load'!M23,0)) -> 815.72 | ... AL20: =(IF('Section Load'!AM23>0,'Section Load'!AM23,0)) -> 776 | AM20: =(IF('Water Report'!$V$7>0,'Water Report'!$V$7,0)) -> 100 | AN20: =(IF('Water Report'!$V$8>0,'Water Report'!$V$8,0)) -> 154 | AO20: =(IF('Water Report'!$V$9>0,'Water Report'!$V$9,0)) -> 76 | AP20: =(IF('Water Report'!$V$10>0,'Water Report'!$V$10,0)) -> 18 | AQ20: =(IF('Water Report'!$V$11>0,'Water Report'!$V$11,0)) -> 23 | AR20: =(IF('Water Report'!$V$13>0,'Water Report'!$V$13,0)) -> 35 | AS20: =(IF('Water Report'!$V$14>0,'Water Report'!$V$14,0)) -> 11 | AT20: =(IF('Water Report'!$V$15>0,'Water Report'!$V$15,0)) -> 6 | AU20: =(IF('Water Report'!$V$17>0,'Water Report'!$V$17,0)) -> 0 | AV20: =(IF('Water Report'!$V$18>0,'Water Report'!$V$18,0)) -> 10 | AW20: =(IF('Water Report'!$V$19>0,'Water Report'!$V$19,0)) -> 6 | AX20: =(IF('Water Report'!$V$21>0,'Water Report'!$V$21,0)) -> 66 | AY20: =(IF('Water Report'!$V$22>0,'Water Report'!$V$22,0)) -> 40 | AZ20: =(IF('Water Report'!$V$23>0,'Water Report'!$V$23,0)) -> 0 | BA20: =(IF('Water Report'!$V$14>0,'Water Report'!$V$14,0)) -> 11 | BB20: =(IF('Water Report'!$V$15>0,'Water Report'!$V$15,0)) -> 6 | BC20: =(IF('Water Report'!$V$13>0,'Water Report'!$V$13,0)) -> 35 | BD20: =(IF('Water Report'!$V$24>0,'Water Report'!$V$24,0)) -> 260 | BE20: =(IF('Water Report'!$V$25>0,'Water Report'!$V$25,0)) -> 134 | BF20: =(IF('Water Report'!$V$27>0,'Water Report'!$V$27,0)) -> 101 | BG20: =(IF('Section Load'!AN23>0,'Section Load'!AN23,0)) -> 950 | BH20: =(IF('Section Load'!AO23>0,'Section Load'!AO23,0)) -> 267.73 | BI20: =(IF('Section Load'!AP23>0,'Section Load'!AP23,0)) -> 0 | BJ20: =(IF('Section Load'!AQ23>0,'Section Load'!AQ23,0)) -> 68.47 | BK20: =(IF('Section Load'!AR23>0,'Section Load'!AR23,0)) -> 31.7 | BL20: =(IF('Section Load'!AS23>0,'Section Load'!AS23,0)) -> 0 | BM20: =(IF('Section Load'!AT23>0,'Section Load'!AT23,0)) -> 582.1
A21: Mumbai | B21: =B20+1 -> 20 | C21: 8 | D21: 2021 | E21: =(IF('Section Load'!F24>0,'Section Load'!F24,0)) -> 2573.21 | F21: =(IF('Section Load'!G24>0,'Section Load'!G24,0)) -> 1586.97 | G21: =(IF('Section Load'!H24>0,'Section Load'!H24,0)) -> 1448.93 | H21: =(IF('Section Load'!I24>0,'Section Load'!I24,0)) -> 3767.43 | I21: =(IF('Section Load'!J24>0,'Section Load'!J24,0)) -> 7204.54 | J21: =(IF('Section Load'!K24>0,'Section Load'!K24,0)) -> 2710.7 | K21: =(IF('Section Load'!L24>0,'Section Load'!L24,0)) -> 1063.75 | L21: =(IF('Section Load'!M24>0,'Section Load'!M24,0)) -> 1166.52 | ... AL21: =(IF('Section Load'!AM24>0,'Section Load'!AM24,0)) -> 727 | AM21: =(IF('Water Report'!$W$7>0,'Water Report'!$W$7,0)) -> 35 | AN21: =(IF('Water Report'!$W$8>0,'Water Report'!$W$8,0)) -> 151 | AO21: =(IF('Water Report'!$W$9>0,'Water Report'!$W$9,0)) -> 51 | AP21: =(IF('Water Report'!$W$10>0,'Water Report'!$W$10,0)) -> 15 | AQ21: =(IF('Water Report'!$W$11>0,'Water Report'!$W$11,0)) -> 17 | AR21: =(IF('Water Report'!$W$13>0,'Water Report'!$W$13,0)) -> 10 | AS21: =(IF('Water Report'!$W$14>0,'Water Report'!$W$14,0)) -> 15 | AT21: =(IF('Water Report'!$W$15>0,'Water Report'!$W$15,0)) -> 4 | AU21: =(IF('Water Report'!$W$17>0,'Water Report'!$W$17,0)) -> 0 | AV21: =(IF('Water Report'!$W$18>0,'Water Report'!$W$18,0)) -> 0 | AW21: =(IF('Water Report'!$W$19>0,'Water Report'!$W$19,0)) -> 0 | AX21: =(IF('Water Report'!$W$21>0,'Water Report'!$W$21,0)) -> 66 | AY21: =(IF('Water Report'!$W$22>0,'Water Report'!$W$22,0)) -> 33 | AZ21: =(IF('Water Report'!$W$23>0,'Water Report'!$W$23,0)) -> 0 | BA21: =(IF('Water Report'!$W$14>0,'Water Report'!$W$14,0)) -> 15 | BB21: =(IF('Water Report'!$W$15>0,'Water Report'!$W$15,0)) -> 4 | BC21: =(IF('Water Report'!$W$13>0,'Water Report'!$W$13,0)) -> 10 | BD21: =(IF('Water Report'!$W$24>0,'Water Report'!$W$24,0)) -> 140 | BE21: =(IF('Water Report'!$W$25>0,'Water Report'!$W$25,0)) -> 102 | BF21: =(IF('Water Report'!$W$27>0,'Water Report'!$W$27,0)) -> 76 | BG21: =(IF('Section Load'!AN24>0,'Section Load'!AN24,0)) -> 950 | BH21: =(IF('Section Load'!AO24>0,'Section Load'!AO24,0)) -> 260.45 | BI21: =(IF('Section Load'!AP24>0,'Section Load'!AP24,0)) -> 0 | BJ21: =(IF('Section Load'!AQ24>0,'Section Load'!AQ24,0)) -> 81.23 | BK21: =(IF('Section Load'!AR24>0,'Section Load'!AR24,0)) -> 37 | BL21: =(IF('Section Load'!AS24>0,'Section Load'!AS24,0)) -> 1.7 | BM21: =(IF('Section Load'!AT24>0,'Section Load'!AT24,0)) -> 569.62
A22: Mumbai | B22: =B21+1 -> 21 | C22: 8 | D22: 2021 | E22: =(IF('Section Load'!F25>0,'Section Load'!F25,0)) -> 2837.54 | F22: =(IF('Section Load'!G25>0,'Section Load'!G25,0)) -> 1602.92 | G22: =(IF('Section Load'!H25>0,'Section Load'!H25,0)) -> 1578.05 | H22: =(IF('Section Load'!I25>0,'Section Load'!I25,0)) -> 3741.52 | I22: =(IF('Section Load'!J25>0,'Section Load'!J25,0)) -> 6289.11 | J22: =(IF('Section Load'!K25>0,'Section Load'!K25,0)) -> 2552.6 | K22: =(IF('Section Load'!L25>0,'Section Load'!L25,0)) -> 1014.92 | L22: =(IF('Section Load'!M25>0,'Section Load'!M25,0)) -> 759.4 | ... AL22: =(IF('Section Load'!AM25>0,'Section Load'!AM25,0)) -> 697 | AM22: =(IF('Water Report'!$X$7>0,'Water Report'!$X$7,0)) -> 79 | AN22: =(IF('Water Report'!$X$8>0,'Water Report'!$X$8,0)) -> 118 | AO22: =(IF('Water Report'!$X$9>0,'Water Report'!$X$9,0)) -> 79 | AP22: =(IF('Water Report'!$X$10>0,'Water Report'!$X$10,0)) -> 18 | AQ22: =(IF('Water Report'!$X$11>0,'Water Report'!$X$11,0)) -> 23 | AR22: =(IF('Water Report'!$X$13>0,'Water Report'!$X$13,0)) -> 18 | AS22: =(IF('Water Report'!$X$14>0,'Water Report'!$X$14,0)) -> 19 | AT22: =(IF('Water Report'!$X$15>0,'Water Report'!$X$15,0)) -> 11 | AU22: =(IF('Water Report'!$X$17>0,'Water Report'!$X$17,0)) -> 0 | AV22: =(IF('Water Report'!$X$18>0,'Water Report'!$X$18,0)) -> 12 | AW22: =(IF('Water Report'!$X$19>0,'Water Report'!$X$19,0)) -> 6 | AX22: =(IF('Water Report'!$X$21>0,'Water Report'!$X$21,0)) -> 66 | AY22: =(IF('Water Report'!$X$22>0,'Water Report'!$X$22,0)) -> 4 | AZ22: =(IF('Water Report'!$X$23>0,'Water Report'!$X$23,0)) -> 0 | BA22: =(IF('Water Report'!$X$14>0,'Water Report'!$X$14,0)) -> 19 | BB22: =(IF('Water Report'!$X$15>0,'Water Report'!$X$15,0)) -> 11 | BC22: =(IF('Water Report'!$X$13>0,'Water Report'!$X$13,0)) -> 18 | BD22: =(IF('Water Report'!$X$24>0,'Water Report'!$X$24,0)) -> 160 | BE22: =(IF('Water Report'!$X$25>0,'Water Report'!$X$25,0)) -> 150 | BF22: =(IF('Water Report'!$X$27>0,'Water Report'!$X$27,0)) -> 84 | BG22: =(IF('Section Load'!AN25>0,'Section Load'!AN25,0)) -> 950 | BH22: =(IF('Section Load'!AO25>0,'Section Load'!AO25,0)) -> 269.23 | BI22: =(IF('Section Load'!AP25>0,'Section Load'!AP25,0)) -> 0 | BJ22: =(IF('Section Load'!AQ25>0,'Section Load'!AQ25,0)) -> 85.07 | BK22: =(IF('Section Load'!AR25>0,'Section Load'!AR25,0)) -> 39.6 | BL22: =(IF('Section Load'!AS25>0,'Section Load'!AS25,0)) -> 1.3 | BM22: =(IF('Section Load'!AT25>0,'Section Load'!AT25,0)) -> 554.8
