Workbook

Sheet TOTAL
A1: Site Name | B1: Day | C1: Month | D1: Year | E1: Total Electricity Kwh | F1: Electricity Tariff ($/Kwh) | G1: LPG (Kg) | H1: LPG $/Kg | I1: Water Utility Supply (m3) m3 | J1: Water Utility Supply (m3) $/m3 | K1: Room Nights | N1: Water Tanks | O1: Cost of Water Tanks Rs | P1: Water Utility Supply (m3) Rs/m3 | Q1: Electricity Tariff (Rs/Kwh) | R1: LPG Rs/Kg | S1: Exchange Rate | T1: Total LPG Cost | U1: Total Water Cost
A2: Mauritius at Anahita | B2: 1 | C2: 5 | D2: 2021 | E2: =HOTEL!E4 -> 5123 | F2: 6.21 | G2: =HOTEL!CK4 -> 107.75 | H2: 57.45 | I2: =HOTEL!V4+HOTEL!Y4 -> 46 | J2: =P2 -> 99.999203 | K2: =HOTEL!EE4 -> 2 | N2: =HOTEL!X12 -> 152370 | O2: =N2*2500 -> 380925000 | P2: =IFERROR(((((HOTEL!V4*34))+(N2*2500))/(I2+N2*25)),0) -> 99.999203 | Q2: 6.21 | R2: =H2 -> 57.45 | S2: 33.88 | T2: =G2*H2 -> 6190.2375 | U2: =I2*P2 -> 4599.9633
A3: Mauritius at Anahita | B3: =B2+1 -> 2 | C3: 5 | D3: 2021 | E3: =HOTEL!E5 -> 5520 | F3: 6.21 | G3: =HOTEL!CK5 -> 107.75 | H3: 57.45 | I3: =HOTEL!V5+HOTEL!Y5 -> 71 | J3: =P3 -> 99.99877 | K3: =HOTEL!EE5 -> 2 | N3: =HOTEL!X13 -> 152370 | O3: =N3*2500 -> 380925000 | P3: =IFERROR(((((HOTEL!V5*34))+(N3*2500))/(I3+N3*25)),0) -> 99.99877 | Q3: 6.21 | R3: =H3 -> 57.45 | S3: 33.88 | T3: =G3*H3 -> 6190.2375 | U3: =I3*P3 -> 7099.9127
A4: Mauritius at Anahita | B4: =B3+1 -> 3 | C4: 5 | D4: 2021 | E4: =HOTEL!E6 -> 5209 | F4: 6.21 | G4: =HOTEL!CK6 -> 107.75 | H4: 57.45 | I4: =HOTEL!V6+HOTEL!Y6 -> 127 | J4: =P4 -> 99.9978 | K4: =HOTEL!EE6 -> 2 | N4: =HOTEL!X14 -> 152370 | O4: =N4*2500 -> 380925000 | P4: =IFERROR(((((HOTEL!V6*34))+(N4*2500))/(I4+N4*25)),0) -> 99.9978 | Q4: 6.21 | R4: =H4 -> 57.45 | S4: 33.88 | T4: =G4*H4 -> 6190.2375 | U4: =I4*P4 -> 12699.721
A5: Mauritius at Anahita | B5: =B4+1 -> 4 | C5: 5 | D5: 2021 | E5: =HOTEL!E7 -> 5725 | F5: 6.21 | G5: =HOTEL!CK7 -> 215.5 | H5: 57.45 | I5: =HOTEL!V7+HOTEL!Y7 -> 91 | J5: =P5 -> 99.998423 | K5: =HOTEL!EE7 -> 2 | N5: =HOTEL!X15 -> 152370 | O5: =N5*2500 -> 380925000 | P5: =IFERROR(((((HOTEL!V7*34))+(N5*2500))/(I5+N5*25)),0) -> 99.998423 | Q5: 6.21 | R5: =H5 -> 57.45 | S5: 33.88 | T5: =G5*H5 -> 12380.475 | U5: =I5*P5 -> 9099.8565
A6: Mauritius at Anahita | B6: =B5+1 -> 5 | C6: 5 | D6: 2021 | E6: =HOTEL!E8 -> 5621 | F6: 6.21 | G6: =HOTEL!CK8 -> 107.75 | H6: 57.45 | I6: =HOTEL!V8+HOTEL!Y8 -> 109 | J6: =P6 -> 99.998111 | K6: =HOTEL!EE8 -> 2 | N6: =HOTEL!X16 -> 152370 | O6: =N6*2500 -> 380925000 | P6: =IFERROR(((((HOTEL!V8*34))+(N6*2500))/(I6+N6*25)),0) -> 99.998111 | Q6: 6.21 | R6: =H6 -> 57.45 | S6: 33.88 | T6: =G6*H6 -> 6190.2375 | U6: =I6*P6 -> 10899.794
A7: Mauritius at Anahita | B7: =B6+1 -> 6 | C7: 5 | D7: 2021 | E7: =HOTEL!E9 -> 5578 | F7: 6.21 | G7: =HOTEL!CK9 -> 107.75 | H7: 57.45 | I7: =HOTEL!V9+HOTEL!Y9 -> 100 | J7: =P7 -> 99.998267 | K7: =HOTEL!EE9 -> 2 | N7: =HOTEL!X17 -> 152370 | O7: =N7*2500 -> 380925000 | P7: =IFERROR(((((HOTEL!V9*34))+(N7*2500))/(I7+N7*25)),0) -> 99.998267 | Q7: 6.21 | R7: =H7 -> 57.45 | S7: 33.88 | T7: =G7*H7 -> 6190.2375 | U7: =I7*P7 -> 9999.8267
A8: Mauritius at Anahita | B8: =B7+1 -> 7 | C8: 5 | D8: 2021 | E8: =HOTEL!E10 -> 4939 | F8: 6.21 | G8: =HOTEL!CK10 -> 107.75 | H8: 57.45 | I8: =HOTEL!V10+HOTEL!Y10 -> 70 | J8: =P8 -> 99.998787 | K8: =HOTEL!EE10 -> 2 | N8: =HOTEL!X18 -> 152370 | O8: =N8*2500 -> 380925000 | P8: =IFERROR(((((HOTEL!V10*34))+(N8*2500))/(I8+N8*25)),0) -> 99.998787 | Q8: 6.21 | R8: =H8 -> 57.45 | S8: 33.88 | T8: =G8*H8 -> 6190.2375 | U8: =I8*P8 -> 6999.9151
A9: Mauritius at Anahita | B9: =B8+1 -> 8 | C9: 5 | D9: 2021 | E9: =HOTEL!E11 -> 4878 | F9: 6.21 | G9: =HOTEL!CK11 -> 107.75 | H9: 57.45 | I9: =HOTEL!V11+HOTEL!Y11 -> 60 | J9: =P9 -> 99.99896 | K9: =HOTEL!EE11 -> 2 | N9: =HOTEL!X19 -> 152370 | O9: =N9*2500 -> 380925000 | P9: =IFERROR(((((HOTEL!V11*34))+(N9*2500))/(I9+N9*25)),0) -> 99.99896 | Q9: 6.21 | R9: =H9 -> 57.45 | S9: 33.88 | T9: =G9*H9 -> 6190.2375 | U9: =I9*P9 -> 5999.9376
A10: Mauritius at Anahita | B10: =B9+1 -> 9 | C10: 5 | D10: 2021 | E10: =HOTEL!E12 -> 5240 | F10: 6.21 | G10: =HOTEL!CK12 -> 107.75 | H10: 57.45 | I10: =HOTEL!V12+HOTEL!Y12 -> 100 | J10: =P10 -> 95.111111 | K10: =HOTEL!EE12 -> 2 | N10: =HOTEL!W20 -> 50 | O10: =N10*2500 -> 125000 | P10: =IFERROR(((((HOTEL!V12*34))+(N10*2500))/(I10+N10*25)),0) -> 95.111111 | Q10: 6.21 | R10: =H10 -> 57.45 | S10: 33.93 | T10: =G10*H10 -> 6190.2375 | U10: =I10*P10 -> 9511.1111
A11: Mauritius at Anahita | B11: =B10+1 -> 10 | C11: 5 | D11: 2021 | E11: =HOTEL!E13 -> 4995 | F11: 6.21 | G11: =HOTEL!CK13 -> 0 | H11: 57.45 | I11: =HOTEL!V13+HOTEL!Y13 -> 73 | J11: =P11 -> 96.358277 | K11: =HOTEL!EE13 -> 2 | N11: =HOTEL!W21 -> 50 | O11: =N11*2500 -> 125000 | P11: =IFERROR(((((HOTEL!V13*34))+(N11*2500))/(I11+N11*25)),0) -> 96.358277 | Q11: 6.21 | R11: =H11 -> 57.45 | S11: 33.93 | T11: =G11*H11 -> 0 | U11: =I11*P11 -> 7034.1542
A12: Mauritius at Anahita | B12: =B11+1 -> 11 | C12: 5 | D12: 2021 | E12: =HOTEL!E14 -> 5512 | F12: 6.21 | G12: =HOTEL!CK14 -> 107.75 | H12: 57.45 | I12: =HOTEL!V14+HOTEL!Y14 -> 82 | J12: =P12 -> 95.936937 | K12: =HOTEL!EE14 -> 2 | N12: =HOTEL!W22 -> 50 | O12: =N12*2500 -> 125000 | P12: =IFERROR(((((HOTEL!V14*34))+(N12*2500))/(I12+N12*25)),0) -> 95.936937 | Q12: 6.21 | R12: =H12 -> 57.45 | S12: 33.93 | T12: =G12*H12 -> 6190.2375 | U12: =I12*P12 -> 7866.8288
A13: Mauritius at Anahita | B13: =B12+1 -> 12 | C13: 5 | D13: 2021 | E13: =HOTEL!E15 -> 5664 | F13: 6.21 | G13: =HOTEL!CK15 -> 215.5 | H13: 57.45 | I13: =HOTEL!V15+HOTEL!Y15 -> 8 | J13: =P13 -> 99.580286 | K13: =HOTEL!EE15 -> 2 | N13: =HOTEL!W23 -> 50 | O13: =N13*2500 -> 125000 | P13: =IFERROR(((((HOTEL!V15*34))+(N13*2500))/(I13+N13*25)),0) -> 99.580286 | Q13: 6.21 | R13: =H13 -> 57.45 | S13: 33.93 | T13: =G13*H13 -> 12380.475 | U13: =I13*P13 -> 796.64229
A14: Mauritius at Anahita | B14: =B13+1 -> 13 | C14: 5 | D14: 2021 | E14: =HOTEL!E16 -> 4020 | F14: 6.21 | G14: =HOTEL!CK16 -> 107.75 | H14: 57.45 | I14: =HOTEL!V16+HOTEL!Y16 -> 0 | J14: =P14 -> 100 | K14: =HOTEL!EE16 -> 2 | N14: =HOTEL!X24 -> 152641 | O14: =N14*2500 -> 381602500 | P14: =IFERROR(((((HOTEL!V16*34))+(N14*2500))/(I14+N14*25)),0) -> 100 | Q14: 6.21 | R14: =H14 -> 57.45 | S14: 33.93 | T14: =G14*H14 -> 6190.2375 | U14: =I14*P14 -> 0
A15: Mauritius at Anahita | B15: =B14+1 -> 14 | C15: 5 | D15: 2021 | E15: =HOTEL!E17 -> 3633 | F15: 6.21 | G15: =HOTEL!CK17 -> 0 | H15: 57.45 | I15: =HOTEL!V17+HOTEL!Y17 -> 0 | J15: =P15 -> 100 | K15: =HOTEL!EE17 -> 2 | N15: =HOTEL!W25 -> 50 | O15: =N15*2500 -> 125000 | P15: =IFERROR(((((HOTEL!V17*34))+(N15*2500))/(I15+N15*25)),0) -> 100 | Q15: 6.21 | R15: =H15 -> 57.45 | S15: 33.93 | T15: =G15*H15 -> 0 | U15: =I15*P15 -> 0
A16: Mauritius at Anahita | B16: =B15+1 -> 15 | C16: 5 | D16: 2021 | E16: =HOTEL!E18 -> 5338 | F16: 6.21 | G16: =HOTEL!CK18 -> 107.75 | H16: 57.45 | I16: =HOTEL!V18+HOTEL!Y18 -> 0 | J16: =P16 -> 100 | K16: =HOTEL!EE18 -> 2 | N16: =HOTEL!W26 -> 50 | O16: =N16*2500 -> 125000 | P16: =IFERROR(((((HOTEL!V18*34))+(N16*2500))/(I16+N16*25)),0) -> 100 | Q16: 6.21 | R16: =H16 -> 57.45 | S16: 33.93 | T16: =G16*H16 -> 6190.2375 | U16: =I16*P16 -> 0
A17: Mauritius at Anahita | B17: =B16+1 -> 16 | C17: 5 | D17: 2021 | E17: =HOTEL!E19 -> 3769 | F17: 6.21 | G17: =HOTEL!CK19 -> 107.75 | H17: 57.45 | I17: =HOTEL!V19+HOTEL!Y19 -> 112 | J17: =P17 -> 99.998063 | K17: =HOTEL!EE19 -> 2 | N17: =HOTEL!X27 -> 152641 | O17: =N17*2500 -> 381602500 | P17: =IFERROR(((((HOTEL!V19*34))+(N17*2500))/(I17+N17*25)),0) -> 99.998063 | Q17: 6.21 | R17: =H17 -> 57.45 | S17: 33.93 | T17: =G17*H17 -> 6190.2375 | U17: =I17*P17 -> 11199.783
A18: Mauritius at Anahita | B18: =B17+1 -> 17 | C18: 5 | D18: 2021 | E18: =HOTEL!E20 -> 5204 | F18: 6.21 | G18: =HOTEL!CK20 -> 215.5 | H18: 57.45 | I18: =HOTEL!V20+HOTEL!Y20 -> 116 | J18: =P18 -> 99.997994 | K18: =HOTEL!EE20 -> 2 | N18: =HOTEL!X28 -> 152641 | O18: =N18*2500 -> 381602500 | P18: =IFERROR(((((HOTEL!V20*34))+(N18*2500))/(I18+N18*25)),0) -> 99.997994 | Q18: 6.21 | R18: =H18 -> 57.45 | S18: 33.93 | T18: =G18*H18 -> 12380.475 | U18: =I18*P18 -> 11599.767
A19: Mauritius at Anahita | B19: =B18+1 -> 18 | C19: 5 | D19: 2021 | E19: =HOTEL!E21 -> 5390 | F19: 6.21 | G19: =HOTEL!CK21 -> 0 | H19: 57.45 | I19: =HOTEL!V21+HOTEL!Y21 -> 301 | J19: =P19 -> 99.99238 | K19: =HOTEL!EE21 -> 2 | N19: =HOTEL!X29 -> 152641 | O19: =N19*2500 -> 381602500 | P19: =IFERROR(((((HOTEL!V21*34))+(N19*2500))/(I19+N19*25)),0) -> 99.99238 | Q19: 6.21 | R19: =H19 -> 57.45 | S19: 33.93 | T19: =G19*H19 -> 0 | U19: =I19*P19 -> 30097.706
A20: Mauritius at Anahita | B20: =B19+1 -> 19 | C20: 5 | D20: 2021 | E20: =HOTEL!E22 -> 5794 | F20: 6.21 | G20: =HOTEL!CK22 -> 107.75 | H20: 57.45 | I20: =HOTEL!V22+HOTEL!Y22 -> 109 | J20: =P20 -> 99.998115 | K20: =HOTEL!EE22 -> 2 | N20: =HOTEL!X30 -> 152641 | O20: =N20*2500 -> 381602500 | P20: =IFERROR(((((HOTEL!V22*34))+(N20*2500))/(I20+N20*25)),0) -> 99.998115 | Q20: 6.21 | R20: =H20 -> 57.45 | S20: 33.93 | T20: =G20*H20 -> 6190.2375 | U20: =I20*P20 -> 10899.795
A21: Mauritius at Anahita | B21: =B20+1 -> 20 | C21: 5 | D21: 2021 | E21: =HOTEL!E23 -> 5278 | F21: 6.21 | G21: =HOTEL!CK23 -> 323.25 | H21: 57.45 | I21: =HOTEL!V23+HOTEL!Y23 -> 50 | J21: =P21 -> 99.999135 | K21: =HOTEL!EE23 -> 2 | N21: =HOTEL!X31 -> 152641 | O21: =N21*2500 -> 381602500 | P21: =IFERROR(((((HOTEL!V23*34))+(N21*2500))/(I21+N21*25)),0) -> 99.999135 | Q21: 6.21 | R21: =H21 -> 57.45 | S21: 33.93 | T21: =G21*H21 -> 18570.713 | U21: =I21*P21 -> 4999.9568
A22: Mauritius at Anahita | B22: =B21+1 -> 21 | C22: 5 | D22: 2021 | E22: =HOTEL!E24 -> 5749 | F22: 6.21 | G22: =HOTEL!CK24 -> 107.75 | H22: 57.45 | I22: =HOTEL!V24+HOTEL!Y24 -> 97 | J22: =P22 -> 99.998322 | K22: =HOTEL!EE24 -> 2 | N22: =HOTEL!X32 -> 152641 | O22: =N22*2500 -> 381602500 | P22: =IFERROR(((((HOTEL!V24*34))+(N22*2500))/(I22+N22*25)),0) -> 99.998322 | Q22: 6.21 | R22: =H22 -> 57.45 | S22: 33.93 | T22: =G22*H22 -> 6190.2375 | U22: =I22*P22 -> 9699.8373
A23: Mauritius at Anahita | B23: =B22+1 -> 22 | C23: 5 | D23: 2021 | E23: =HOTEL!E25 -> 5414 | F23: 6.21 | G23: =HOTEL!CK25 -> 215.5 | H23: 57.45 | I23: =HOTEL!V25+HOTEL!Y25 -> 68 | J23: =P23 -> 99.998824 | K23: =HOTEL!EE25 -> 2 | N23: =HOTEL!X33 -> 152641 | O23: =N23*2500 -> 381602500 | P23: =IFERROR(((((HOTEL!V25*34))+(N23*2500))/(I23+N23*25)),0) -> 99.998824 | Q23: 6.21 | R23: =H23 -> 57.45 | S23: 33.93 | T23: =G23*H23 -> 12380.475 | U23: =I23*P23 -> 6799.92
A24: Mauritius at Anahita | B24: =B23+1 -> 23 | C24: 5 | D24: 2021 | E24: =HOTEL!E26 -> 5712 | F24: 6.21 | G24: =HOTEL!CK26 -> 107.75 | H24: 57.45 | I24: =HOTEL!V26+HOTEL!Y26 -> 85 | J24: =P24 -> 99.99853 | K24: =HOTEL!EE26 -> 2 | N24: =HOTEL!X34 -> 152641 | O24: =N24*2500 -> 381602500 | P24: =IFERROR(((((HOTEL!V26*34))+(N24*2500))/(I24+N24*25)),0) -> 99.99853 | Q24: 6.21 | R24: =H24 -> 57.45 | S24: 33.93 | T24: =G24*H24 -> 6190.2375 | U24: =I24*P24 -> 8499.875
A25: Mauritius at Anahita | B25: =B24+1 -> 24 | C25: 5 | D25: 2021 | E25: =HOTEL!E27 -> 5501 | F25: 6.21 | G25: =HOTEL!CK27 -> 0 | H25: 57.45 | I25: =HOTEL!V27+HOTEL!Y27 -> 35 | J25: =P25 -> 34 | K25: =HOTEL!EE27 -> 2 | N25: =HOTEL!X35 -> 0 | O25: =N25*2500 -> 0 | P25: =IFERROR(((((HOTEL!V27*34))+(N25*2500))/(I25+N25*25)),0) -> 34 | Q25: 6.21 | R25: =H25 -> 57.45 | S25: 33.93 | T25: =G25*H25 -> 0 | U25: =I25*P25 -> 1190
A26: Mauritius at Anahita | B26: =B25+1 -> 25 | C26: 5 | D26: 2021 | E26: =HOTEL!E28 -> 6146 | F26: 6.21 | G26: =HOTEL!CK28 -> 215.5 | H26: 57.45 | I26: =HOTEL!V28+HOTEL!Y28 -> 4 | J26: =P26 -> 34 | K26: =HOTEL!EE28 -> 2 | N26: =HOTEL!X36 -> 0 | O26: =N26*2500 -> 0 | P26: =IFERROR(((((HOTEL!V28*34))+(N26*2500))/(I26+N26*25)),0) -> 34 | Q26: 6.21 | R26: =H26 -> 57.45 | S26: 33.93 | T26: =G26*H26 -> 12380.475 | U26: =I26*P26 -> 136
A27: Mauritius at Anahita | B27: =B26+1 -> 26 | C27: 5 | D27: 2021 | E27: =HOTEL!E29 -> 6190 | F27: 6.21 | G27: =HOTEL!CK29 -> 107.75 | H27: 57.45 | I27: =HOTEL!V29+HOTEL!Y29 -> 22 | J27: =P27 -> 34 | K27: =HOTEL!EE29 -> 2 | N27: =HOTEL!X37 -> 0 | O27: =N27*2500 -> 0 | P27: =IFERROR(((((HOTEL!V29*34))+(N27*2500))/(I27+N27*25)),0) -> 34 | Q27: 6.21 | R27: =H27 -> 57.45 | S27: 33.93 | T27: =G27*H27 -> 6190.2375 | U27: =I27*P27 -> 748
A28: Mauritius at Anahita | B28: =B27+1 -> 27 | C28: 5 | D28: 2021 | E28: =HOTEL!E30 -> 6333 | F28: 6.21 | G28: =HOTEL!CK30 -> 107.75 | H28: 57.45 | I28: =HOTEL!V30+HOTEL!Y30 -> 53 | J28: =P28 -> 34 | K28: =HOTEL!EE30 -> 2 | N28: =HOTEL!X38 -> 0 | O28: =N28*2500 -> 0 | P28: =IFERROR(((((HOTEL!V30*34))+(N28*2500))/(I28+N28*25)),0) -> 34 | Q28: 6.21 | R28: =H28 -> 57.45 | S28: 33.93 | T28: =G28*H28 -> 6190.2375 | U28: =I28*P28 -> 1802
A29: Mauritius at Anahita | B29: =B28+1 -> 28 | C29: 5 | D29: 2021 | E29: =HOTEL!E31 -> 5744 | F29: 6.21 | G29: =HOTEL!CK31 -> 323.25 | H29: 57.45 | I29: =HOTEL!V31+HOTEL!Y31 -> 69 | J29: =P29 -> 34 | K29: =HOTEL!EE31 -> 2 | N29: =HOTEL!X39 -> 0 | O29: =N29*2500 -> 0 | P29: =IFERROR(((((HOTEL!V31*34))+(N29*2500))/(I29+N29*25)),0) -> 34 | Q29: 6.21 | R29: =H29 -> 57.45 | S29: 33.93 | T29: =G29*H29 -> 18570.713 | U29: =I29*P29 -> 2346
A30: Mauritius at Anahita | B30: =B29+1 -> 29 | C30: 5 | D30: 2021 | E30: =HOTEL!E32 -> 6016 | F30: 6.21 | G30: =HOTEL!CK32 -> 215.5 | H30: 57.45 | I30: =HOTEL!V32+HOTEL!Y32 -> 58 | J30: =P30 -> 34 | K30: =HOTEL!EE32 -> 2 | N30: =HOTEL!X40 -> 0 | O30: =N30*2500 -> 0 | P30: =IFERROR(((((HOTEL!V32*34))+(N30*2500))/(I30+N30*25)),0) -> 34 | Q30: 6.21 | R30: =H30 -> 57.45 | T30: =G30*H30 -> 12380.475 | U30: =I30*P30 -> 1972
A31: Mauritius at Anahita | B31: =B30+1 -> 30 | C31: 5 | D31: 2021 | E31: =HOTEL!E33 -> 6899 | F31: 6.21 | G31: =HOTEL!CK33 -> 0 | H31: 57.45 | I31: =HOTEL!V33+HOTEL!Y33 -> 32 | J31: =P31 -> 34 | K31: =HOTEL!EE33 -> 2 | N31: =HOTEL!X41 -> 0 | O31: =N31*2500 -> 0 | P31: =IFERROR(((((HOTEL!V33*34))+(N31*2500))/(I31+N31*25)),0) -> 34 | Q31: 6.21 | R31: =H31 -> 57.45 | T31: =G31*H31 -> 0 | U31: =I31*P31 -> 1088
A32: Mauritius at Anahita | B32: =B31+1 -> 31 | C32: 5 | D32: 2021 | E32: =HOTEL!E34 -> 6590 | F32: 6.21 | G32: =HOTEL!CK34 -> 215.5 | H32: 57.45 | I32: =HOTEL!V34+HOTEL!Y34 -> 35 | J32: =P32 -> 34 | K32: =HOTEL!EE34 -> 2 | N32: =HOTEL!X42 -> 0 | O32: =N32*2500 -> 0 | P32: =IFERROR(((((HOTEL!V34*34))+(N32*2500))/(I32+N32*25)),0) -> 34 | Q32: 6.21 | R32: =H32 -> 57.45 | T32: =G32*H32 -> 12380.475 | U32: =I32*P32 -> 1190

Sheet Submetering
A1: Site Name | B1: Day | C1: Month | D1: Year | E1: Hotel (KWh) | F1: Vacoas (KWh) | G1: Laundry (KWh) | H1: Villa 145 (KWh) | I1: Villa 146 (KWh) | J1: Villa 111 (KWh) | K1: Villa 128 (KWh) | L1: Hotel (m3) | M1: Bamboo Pool (m3) | N1: Island (m3) | O1: Main Building (m3) | P1: Pantry A (m3) | Q1: Pantry B (m3) | R1: Pantry C (m3) | S1: Pantry D (m3) | T1: Pantry E (m3) | U1: Pantry F (m3) | V1: Pantry G (m3) | W1: North Parcel (m3) | X1: South Parcel (m3) | Y1: Beau champ (Kg) | Z1: Acquapazza (Kg) | AA1: Bamboo (Kg) | AB1: Steam Boiler (Kg) | AC1: Laundry (Kg) | AD1: Pantry A (Kg) | AE1: Pantry B (Kg) | AF1: Pantry C (Kg) | AG1: Pantry D (Kg) | AH1: Pantry E (Kg) | AI1: Pantry F (Kg) | AJ1: Pantry G (Kg) | AK1: Room Nights
A2: Mauritius at Anahita | B2: 1 | C2: 7 | D2: 2021 | E2: =TOTAL!E2 -> 5123 | F2: =HOTEL!R4 -> 40 | G2: =HOTEL!T4 -> 2 | H2: =HOTEL!DX4 -> 0 | I2: =HOTEL!DZ4 -> 0 | J2: =HOTEL!EB4 -> 0 | K2: =HOTEL!ED4 -> 0 | L2: =N2+W2+X2 -> 60 | M2: =HOTEL!AE4 -> 0 | N2: =HOTEL!AI4 -> 10 | O2: =HOTEL!AM4 -> 1 | P2: =HOTEL!AO4 -> 0 | Q2: =HOTEL!AQ4 -> 0 | R2: =HOTEL!AS4 -> 0 | S2: =HOTEL!AU4 -> 0 | T2: =HOTEL!AW4 -> 0 | U2: =HOTEL!AY4 -> 0 | V2: =HOTEL!BA4 -> 0 | W2: =HOTEL!BM4 -> 20 | X2: =HOTEL!BT4 -> 30 | Y2: =HOTEL!CO4 -> 0 | Z2: =HOTEL!CR3 -> 0 | AA2: =HOTEL!CU4 -> 0 | AB2: =HOTEL!CX4 -> 0 | AC2: =HOTEL!DA4 -> 2.39 | AD2: =HOTEL!DD4 -> 0 | AE2: =HOTEL!DG4 -> 2 | AF2: =HOTEL!DJ4 -> 0 | AG2: =HOTEL!DM4 -> 0 | AH2: =HOTEL!DP4 -> 0 | AI2: =HOTEL!DS4 -> 0 | AJ2: =HOTEL!DV4 -> 0 | AK2: =TOTAL!K2 -> 2
A3: Mauritius at Anahita | B3: =B2+1 -> 2 | C3: 7 | D3: 2021 | E3: =TOTAL!E3 -> 5520 | F3: =HOTEL!R5 -> 165 | G3: =HOTEL!T5 -> 3 | H3: =HOTEL!DX5 -> 0 | I3: =HOTEL!DZ5 -> 0 | J3: =HOTEL!EB5 -> 0 | K3: =HOTEL!ED5 -> 0 | L3: =N3+W3+X3 -> 70 | M3: =HOTEL!AE5 -> 0 | N3: =HOTEL!AI5 -> 30 | O3: =HOTEL!AM5 -> 2 | P3: =HOTEL!AO5 -> 0 | Q3: =HOTEL!AQ5 -> 0 | R3: =HOTEL!AS5 -> 0 | S3: =HOTEL!AU5 -> 0 | T3: =HOTEL!AW5 -> 0 | U3: =HOTEL!AY5 -> 0 | V3: =HOTEL!BA5 -> 0 | W3: =HOTEL!BM5 -> 20 | X3: =HOTEL!BT5 -> 20 | Y3: =HOTEL!CO5 -> 14.396 | Z3: =HOTEL!CR4 -> 0 | AA3: =HOTEL!CU5 -> 0 | AB3: =HOTEL!CX5 -> 0 | AC3: =HOTEL!DA5 -> 4.78 | AD3: =HOTEL!DD5 -> 0 | AE3: =HOTEL!DG5 -> 1 | AF3: =HOTEL!DJ5 -> 0 | AG3: =HOTEL!DM5 -> 0 | AH3: =HOTEL!DP5 -> 0 | AI3: =HOTEL!DS5 -> 0 | AJ3: =HOTEL!DV5 -> 0 | AK3: =TOTAL!K3 -> 2
A4: Mauritius at Anahita | B4: =B3+1 -> 3 | C4: 7 | D4: 2021 | E4: =TOTAL!E4 -> 5209 | F4: =HOTEL!R6 -> 129 | G4: =HOTEL!T6 -> 2 | H4: =HOTEL!DX6 -> 0 | I4: =HOTEL!DZ6 -> 0 | J4: =HOTEL!EB6 -> 0 | K4: =HOTEL!ED6 -> 0 | L4: =N4+W4+X4 -> 110 | M4: =HOTEL!AE6 -> 0 | N4: =HOTEL!AI6 -> 30 | O4: =HOTEL!AM6 -> 3 | P4: =HOTEL!AO6 -> 0 | Q4: =HOTEL!AQ6 -> 1 | R4: =HOTEL!AS6 -> 0 | S4: =HOTEL!AU6 -> 0 | T4: =HOTEL!AW6 -> 0 | U4: =HOTEL!AY6 -> 0 | V4: =HOTEL!BA6 -> 0 | W4: =HOTEL!BM6 -> 50 | X4: =HOTEL!BT6 -> 30 | Y4: =HOTEL!CO6 -> 7.32 | Z4: =HOTEL!CR5 -> 0 | AA4: =HOTEL!CU6 -> 0 | AB4: =HOTEL!CX6 -> 0 | AC4: =HOTEL!DA6 -> 7.17 | AD4: =HOTEL!DD6 -> 0 | AE4: =HOTEL!DG6 -> 0 | AF4: =HOTEL!DJ6 -> 0 | AG4: =HOTEL!DM6 -> 0 | AH4: =HOTEL!DP6 -> 0 | AI4: =HOTEL!DS6 -> 0 | AJ4: =HOTEL!DV6 -> 0 | AK4: =TOTAL!K4 -> 2
A5: Mauritius at Anahita | B5: =B4+1 -> 4 | C5: 7 | D5: 2021 | E5: =TOTAL!E5 -> 5725 | F5: =HOTEL!R7 -> 150 | G5: =HOTEL!T7 -> 2 | H5: =HOTEL!DX7 -> 0 | I5: =HOTEL!DZ7 -> 0 | J5: =HOTEL!EB7 -> 0 | K5: =HOTEL!ED7 -> 0 | L5: =N5+W5+X5 -> 100 | M5: =HOTEL!AE7 -> 0 | N5: =HOTEL!AI7 -> 32 | O5: =HOTEL!AM7 -> 4 | P5: =HOTEL!AO7 -> 0 | Q5: =HOTEL!AQ7 -> 0 | R5: =HOTEL!AS7 -> 0 | S5: =HOTEL!AU7 -> 0 | T5: =HOTEL!AW7 -> 0 | U5: =HOTEL!AY7 -> 0 | V5: =HOTEL!BA7 -> 0 | W5: =HOTEL!BM7 -> 40 | X5: =HOTEL!BT7 -> 28 | Y5: =HOTEL!CO7 -> 12.2 | Z5: =HOTEL!CR6 -> 0 | AA5: =HOTEL!CU7 -> 0 | AB5: =HOTEL!CX7 -> 0 | AC5: =HOTEL!DA7 -> 7.17 | AD5: =HOTEL!DD7 -> 0 | AE5: =HOTEL!DG7 -> 0 | AF5: =HOTEL!DJ7 -> 0 | AG5: =HOTEL!DM7 -> 0 | AH5: =HOTEL!DP7 -> 0 | AI5: =HOTEL!DS7 -> 0 | AJ5: =HOTEL!DV7 -> 0 | AK5: =TOTAL!K5 -> 2
A6: Mauritius at Anahita | B6: =B5+1 -> 5 | C6: 7 | D6: 2021 | E6: =TOTAL!E6 -> 5621 | F6: =HOTEL!R8 -> 160 | G6: =HOTEL!T8 -> 163 | H6: =HOTEL!DX8 -> 0 | I6: =HOTEL!DZ8 -> 0 | J6: =HOTEL!EB8 -> 0 | K6: =HOTEL!ED8 -> 0 | L6: =N6+W6+X6 -> 130 | M6: =HOTEL!AE8 -> 0 | N6: =HOTEL!AI8 -> 38 | O6: =HOTEL!AM8 -> 13 | P6: =HOTEL!AO8 -> 0 | Q6: =HOTEL!AQ8 -> 1 | R6: =HOTEL!AS8 -> 0 | S6: =HOTEL!AU8 -> 0 | T6: =HOTEL!AW8 -> 0 | U6: =HOTEL!AY8 -> 0 | V6: =HOTEL!BA8 -> 0 | W6: =HOTEL!BM8 -> 70 | X6: =HOTEL!BT8 -> 22 | Y6: =HOTEL!CO8 -> 7.32 | Z6: =HOTEL!CR7 -> 0 | AA6: =HOTEL!CU8 -> 0 | AB6: =HOTEL!CX8 -> 80.52 | AC6: =HOTEL!DA8 -> 9.56 | AD6: =HOTEL!DD8 -> 0 | AE6: =HOTEL!DG8 -> 3 | AF6: =HOTEL!DJ8 -> 0 | AG6: =HOTEL!DM8 -> 0 | AH6: =HOTEL!DP8 -> 0 | AI6: =HOTEL!DS8 -> 0 | AJ6: =HOTEL!DV8 -> 0 | AK6: =TOTAL!K6 -> 2
A7: Mauritius at Anahita | B7: =B6+1 -> 6 | C7: 7 | D7: 2021 | E7: =TOTAL!E7 -> 5578 | F7: =HOTEL!R9 -> 146 | G7: =HOTEL!T9 -> 6 | H7: =HOTEL!DX9 -> 0 | I7: =HOTEL!DZ9 -> 0 | J7: =HOTEL!EB9 -> 0 | K7: =HOTEL!ED9 -> 0 | L7: =N7+W7+X7 -> 110 | M7: =HOTEL!AE9 -> 0 | N7: =HOTEL!AI9 -> 30 | O7: =HOTEL!AM9 -> 3 | P7: =HOTEL!AO9 -> 0 | Q7: =HOTEL!AQ9 -> 0 | R7: =HOTEL!AS9 -> 0 | S7: =HOTEL!AU9 -> 0 | T7: =HOTEL!AW9 -> 0 | U7: =HOTEL!AY9 -> 0 | V7: =HOTEL!BA9 -> 0 | W7: =HOTEL!BM9 -> 50 | X7: =HOTEL!BT9 -> 30 | Y7: =HOTEL!CO9 -> 9.76 | Z7: =HOTEL!CR8 -> 0 | AA7: =HOTEL!CU9 -> 0 | AB7: =HOTEL!CX9 -> 0 | AC7: =HOTEL!DA9 -> 7.17 | AD7: =HOTEL!DD9 -> 0 | AE7: =HOTEL!DG9 -> 0 | AF7: =HOTEL!DJ9 -> 0 | AG7: =HOTEL!DM9 -> 0 | AH7: =HOTEL!DP9 -> 0 | AI7: =HOTEL!DS9 -> 0 | AJ7: =HOTEL!DV9 -> 0 | AK7: =TOTAL!K7 -> 2
A8: Mauritius at Anahita | B8: =B7+1 -> 7 | C8: 7 | D8: 2021 | E8: =TOTAL!E8 -> 4939 | F8: =HOTEL!R10 -> 122 | G8: =HOTEL!T10 -> 1 | H8: =HOTEL!DX10 -> 0 | I8: =HOTEL!DZ10 -> 0 | J8: =HOTEL!EB10 -> 0 | K8: =HOTEL!ED10 -> 0 | L8: =N8+W8+X8 -> 81 | M8: =HOTEL!AE10 -> 0 | N8: =HOTEL!AI10 -> 40 | O8: =HOTEL!AM10 -> 1 | P8: =HOTEL!AO10 -> 0 | Q8: =HOTEL!AQ10 -> 0 | R8: =HOTEL!AS10 -> 0 | S8: =HOTEL!AU10 -> 0 | T8: =HOTEL!AW10 -> 0 | U8: =HOTEL!AY10 -> 0 | V8: =HOTEL!BA10 -> 0 | W8: =HOTEL!BM10 -> 30 | X8: =HOTEL!BT10 -> 11 | Y8: =HOTEL!CO10 -> 9.76 | Z8: =HOTEL!CR9 -> 0 | AA8: =HOTEL!CU10 -> 0 | AB8: =HOTEL!CX10 -> 0 | AC8: =HOTEL!DA10 -> 0 | AD8: =HOTEL!DD10 -> 0 | AE8: =HOTEL!DG10 -> 4 | AF8: =HOTEL!DJ10 -> 0 | AG8: =HOTEL!DM10 -> 0 | AH8: =HOTEL!DP10 -> 0 | AI8: =HOTEL!DS10 -> 0 | AJ8: =HOTEL!DV10 -> 0 | AK8: =TOTAL!K8 -> 2
A9: Mauritius at Anahita | B9: =B8+1 -> 8 | C9: 7 | D9: 2021 | E9: =TOTAL!E9 -> 4878 | F9: =HOTEL!R11 -> 44 | G9: =HOTEL!T11 -> 2 | H9: =HOTEL!DX11 -> 0 | I9: =HOTEL!DZ11 -> 0 | J9: =HOTEL!EB11 -> 0 | K9: =HOTEL!ED11 -> 0 | L9: =N9+W9+X9 -> 54 | M9: =HOTEL!AE11 -> 0 | N9: =HOTEL!AI11 -> 25 | O9: =HOTEL!AM11 -> 0 | P9: =HOTEL!AO11 -> 0 | Q9: =HOTEL!AQ11 -> 0 | R9: =HOTEL!AS11 -> 0 | S9: =HOTEL!AU11 -> 0 | T9: =HOTEL!AW11 -> 0 | U9: =HOTEL!AY11 -> 0 | V9: =HOTEL!BA11 -> 0 | W9: =HOTEL!BM11 -> 10 | X9: =HOTEL!BT11 -> 19 | Y9: =HOTEL!CO11 -> 4.88 | Z9: =HOTEL!CR10 -> 0 | AA9: =HOTEL!CU11 -> 0 | AB9: =HOTEL!CX11 -> 0 | AC9: =HOTEL!DA11 -> 0 | AD9: =HOTEL!DD11 -> 0 | AE9: =HOTEL!DG11 -> 0 | AF9: =HOTEL!DJ11 -> 0 | AG9: =HOTEL!DM11 -> 0 | AH9: =HOTEL!DP11 -> 0 | AI9: =HOTEL!DS11 -> 0 | AJ9: =HOTEL!DV11 -> 0 | AK9: =TOTAL!K9 -> 2
A10: Mauritius at Anahita | B10: =B9+1 -> 9 | C10: 7 | D10: 2021 | E10: =TOTAL!E10 -> 5240 | F10: =HOTEL!R12 -> 140 | G10: =HOTEL!T12 -> 3 | H10: =HOTEL!DX12 -> 0 | I10: =HOTEL!DZ12 -> 0 | J10: =HOTEL!EB12 -> 0 | K10: =HOTEL!ED12 -> 0 | L10: =N10+W10+X10 -> 95 | M10: =HOTEL!AE12 -> 0 | N10: =HOTEL!AI12 -> 25 | O10: =HOTEL!AM12 -> 4 | P10: =HOTEL!AO12 -> 0 | Q10: =HOTEL!AQ12 -> 0 | R10: =HOTEL!AS12 -> 0 | S10: =HOTEL!AU12 -> 0 | T10: =HOTEL!AW12 -> 0 | U10: =HOTEL!AY12 -> 0 | V10: =HOTEL!BA12 -> 0 | W10: =HOTEL!BM12 -> 50 | X10: =HOTEL!BT12 -> 20 | Y10: =HOTEL!CO12 -> 9.76 | Z10: =HOTEL!CR11 -> 0 | AA10: =HOTEL!CU12 -> 0 | AB10: =HOTEL!CX12 -> 0 | AC10: =HOTEL!DA12 -> 0 | AD10: =HOTEL!DD12 -> 0 | AE10: =HOTEL!DG12 -> 0 | AF10: =HOTEL!DJ12 -> 0 | AG10: =HOTEL!DM12 -> 0 | AH10: =HOTEL!DP12 -> 0 | AI10: =HOTEL!DS12 -> 0 | AJ10: =HOTEL!DV12 -> 6.931 | AK10: =TOTAL!K10 -> 2
A11: Mauritius at Anahita | B11: =B10+1 -> 10 | C11: 7 | D11: 2021 | E11: =TOTAL!E11 -> 4995 | F11: =HOTEL!R13 -> 147 | G11: =HOTEL!T13 -> 1 | H11: =HOTEL!DX13 -> 0 | I11: =HOTEL!DZ13 -> 0 | J11: =HOTEL!EB13 -> 0 | K11: =HOTEL!ED13 -> 0 | L11: =N11+W11+X11 -> 70 | M11: =HOTEL!AE13 -> 0 | N11: =HOTEL!AI13 -> 40 | O11: =HOTEL!AM13 -> 0 | P11: =HOTEL!AO13 -> 0 | Q11: =HOTEL!AQ13 -> 1 | R11: =HOTEL!AS13 -> 0 | S11: =HOTEL!AU13 -> 0 | T11: =HOTEL!AW13 -> 0 | U11: =HOTEL!AY13 -> 0 | V11: =HOTEL!BA13 -> 0 | W11: =HOTEL!BM13 -> 20 | X11: =HOTEL!BT13 -> 10 | Y11: =HOTEL!CO13 -> 9.76 | Z11: =HOTEL!CR12 -> 0 | AA11: =HOTEL!CU13 -> 0 | AB11: =HOTEL!CX13 -> 0 | AC11: =HOTEL!DA13 -> 0 | AD11: =HOTEL!DD13 -> 0 | AE11: =HOTEL!DG13 -> 0 | AF11: =HOTEL!DJ13 -> 0 | AG11: =HOTEL!DM13 -> 0 | AH11: =HOTEL!DP13 -> 0 | AI11: =HOTEL!DS13 -> 0 | AJ11: =HOTEL!DV13 -> 16.73 | AK11: =TOTAL!K11 -> 2
A12: Mauritius at Anahita | B12: =B11+1 -> 11 | C12: 7 | D12: 2021 | E12: =TOTAL!E12 -> 5512 | F12: =HOTEL!R14 -> 164 | G12: =HOTEL!T14 -> 0 | H12: =HOTEL!DX14 -> 0 | I12: =HOTEL!DZ14 -> 0 | J12: =HOTEL!EB14 -> 0 | K12: =HOTEL!ED14 -> 0 | L12: =N12+W12+X12 -> 100 | M12: =HOTEL!AE14 -> 0 | N12: =HOTEL!AI14 -> 30 | O12: =HOTEL!AM14 -> 6 | P12: =HOTEL!AO14 -> 0 | Q12: =HOTEL!AQ14 -> 0 | R12: =HOTEL!AS14 -> 0 | S12: =HOTEL!AU14 -> 0 | T12: =HOTEL!AW14 -> 0 | U12: =HOTEL!AY14 -> 0 | V12: =HOTEL!BA14 -> 0 | W12: =HOTEL!BM14 -> 50 | X12: =HOTEL!BT14 -> 20 | Y12: =HOTEL!CO14 -> 9.76 | Z12: =HOTEL!CR13 -> 0 | AA12: =HOTEL!CU14 -> 0 | AB12: =HOTEL!CX14 -> 0 | AC12: =HOTEL!DA14 -> 0 | AD12: =HOTEL!DD14 -> 0 | AE12: =HOTEL!DG14 -> 1 | AF12: =HOTEL!DJ14 -> 0 | AG12: =HOTEL!DM14 -> 0 | AH12: =HOTEL!DP14 -> 0 | AI12: =HOTEL!DS14 -> 0 | AJ12: =HOTEL!DV14 -> 14.34 | AK12: =TOTAL!K12 -> 2
A13: Mauritius at Anahita | B13: =B12+1 -> 12 | C13: 7 | D13: 2021 | E13: =TOTAL!E13 -> 5664 | F13: =HOTEL!R15 -> 161 | G13: =HOTEL!T15 -> 0 | H13: =HOTEL!DX15 -> 0 | I13: =HOTEL!DZ15 -> 0 | J13: =HOTEL!EB15 -> 0 | K13: =HOTEL!ED15 -> 0 | L13: =N13+W13+X13 -> 80 | M13: =HOTEL!AE15 -> 0 | N13: =HOTEL!AI15 -> 30 | O13: =HOTEL!AM15 -> 4 | P13: =HOTEL!AO15 -> 0 | Q13: =HOTEL!AQ15 -> 0 | R13: =HOTEL!AS15 -> 0 | S13: =HOTEL!AU15 -> 0 | T13: =HOTEL!AW15 -> 0 | U13: =HOTEL!AY15 -> 0 | V13: =HOTEL!BA15 -> 0 | W13: =HOTEL!BM15 -> 40 | X13: =HOTEL!BT15 -> 10 | Y13: =HOTEL!CO15 -> 9.76 | Z13: =HOTEL!CR14 -> 0 | AA13: =HOTEL!CU15 -> 0 | AB13: =HOTEL!CX15 -> 0 | AC13: =HOTEL!DA15 -> 4.78 | AD13: =HOTEL!DD15 -> 0 | AE13: =HOTEL!DG15 -> 0 | AF13: =HOTEL!DJ15 -> 0 | AG13: =HOTEL!DM15 -> 0 | AH13: =HOTEL!DP15 -> 0 | AI13: =HOTEL!DS15 -> 0 | AJ13: =HOTEL!DV15 -> 23.661 | AK13: =TOTAL!K13 -> 2
A14: Mauritius at Anahita | B14: =B13+1 -> 13 | C14: 7 | D14: 2021 | E14: =TOTAL!E14 -> 4020 | F14: =HOTEL!R16 -> 158 | G14: =HOTEL!T16 -> 0 | H14: =HOTEL!DX16 -> 0 | I14: =HOTEL!DZ16 -> 0 | J14: =HOTEL!EB16 -> 0 | K14: =HOTEL!ED16 -> 0 | L14: =N14+W14+X14 -> 120 | M14: =HOTEL!AE16 -> 0 | N14: =HOTEL!AI16 -> 40 | O14: =HOTEL!AM16 -> 3 | P14: =HOTEL!AO16 -> 0 | Q14: =HOTEL!AQ16 -> 1 | R14: =HOTEL!AS16 -> 0 | S14: =HOTEL!AU16 -> 0 | T14: =HOTEL!AW16 -> 0 | U14: =HOTEL!AY16 -> 0 | V14: =HOTEL!BA16 -> 0 | W14: =HOTEL!BM16 -> 60 | X14: =HOTEL!BT16 -> 20 | Y14: =HOTEL!CO16 -> 7.32 | Z14: =HOTEL!CR15 -> 0 | AA14: =HOTEL!CU16 -> 0 | AB14: =HOTEL!CX16 -> 0 | AC14: =HOTEL!DA16 -> 7.17 | AD14: =HOTEL!DD16 -> 0 | AE14: =HOTEL!DG16 -> 2 | AF14: =HOTEL!DJ16 -> 0 | AG14: =HOTEL!DM16 -> 0 | AH14: =HOTEL!DP16 -> 0 | AI14: =HOTEL!DS16 -> 0 | AJ14: =HOTEL!DV16 -> 1.673 | AK14: =TOTAL!K14 -> 2
... A32: Mauritius at Anahita | B32: =B31+1 -> 31 | C32: 7 | D32: 2021 | E32: =TOTAL!E32 -> 6590 | F32: =HOTEL!R34 -> 202 | G32: =HOTEL!T34 -> 0 | H32: =HOTEL!DX34 -> 0 | I32: =HOTEL!DZ34 -> 0 | J32: =HOTEL!EB34 -> 0 | K32: =HOTEL!ED34 -> 0 | L32: =N32+W32+X32 -> 150 | M32: =HOTEL!AE34 -> 0 | N32: =HOTEL!AI34 -> 30 | O32: =HOTEL!AM34 -> 2 | P32: =HOTEL!AO34 -> 0 | Q32: =HOTEL!AQ34 -> 0 | R32: =HOTEL!AS34 -> 0 | S32: =HOTEL!AU34 -> 0 | T32: =HOTEL!AW34 -> 0 | U32: =HOTEL!AY34 -> 0 | V32: =HOTEL!BA34 -> 0 | W32: =HOTEL!BM34 -> 100 | X32: =HOTEL!BT34 -> 20 | Y32: =HOTEL!CO34 -> 9.76 | Z32: =HOTEL!CR33 -> 0 | AA32: =HOTEL!CU34 -> 0 | AB32: =HOTEL!CX34 -> 0 | AC32: =HOTEL!DA34 -> 7.17 | AD32: =HOTEL!DD34 -> 0 | AE32: =HOTEL!DG34 -> 0 | AF32: =HOTEL!DJ34 -> 0 | AG32: =HOTEL!DM34 -> 0 | AH32: =HOTEL!DP34 -> 0 | AI32: =HOTEL!DS34 -> 3.9 | AJ32: =HOTEL!DV34 -> 19.12 | AK32: =TOTAL!K32 -> 2

Sheet HOTEL
B1: Hotel Electricity | I1: Gen 01 | M1: Gen 02 | Q1: Vacoas KW | R1: CONS | S1: Laundry (KWh) | T1: CONS | U1: Hotel | W1: % Water Available | AB1: Water Softener | AD1: bamboo pool | AF1: laundry | AG1: CONS | AH1: Island | AJ1: Island Sub | AL1: Main Building | AN1: Pantry A | AP1: Pantry B | AR1: Pantry C | AT1: Pantry D | AV1: Pantry E | AX1: Pantry F | AZ1: Pantry G | BL1: North | BN1: North Sub | BP1: South | BR1: South Sub | BW1: Diesel | CA1: Gas | CV1: Steam Boiler | CY1: Main Building | DB1: Pantry A | DE1: Pantry B | DH1: Pantry C | DK1: Pantry D | DN1: Pantry E | DQ1: Pantry F | DT1: Pantry G | EH1: Pool Temperature
A2: Date | B2: KVAH | C2: CONS | D2: KWH | E2: CONS | F2: PF | G2: KVA | H2: KVA max | U2: CWA23 | V2: CONS | X2: Truck Meter | Y2: Cons | Z2: UV reading | AB2: chiller | AC2: CONS | AE2: CONS | AH2: island | AI2: cons | AL2: M.Buil | AM2: Cons | AN2: Pantry A | AO2: Cons | AP2: Pantry B | AQ2: Cons | AR2: Pantry C | AS2: cons | AT2: Pantry D | AU2: cons | AV2: Pantry E | AW2: cons | AX2: Pantry F | AY2: Cons | AZ2: Pantry G | BA2: Cons | BB2: Main Kitchen | BC2: Cons | BD2: Bamboo H | BE2: Cons | BF2: Bamboo C | BG2: Cons | BH2: cyclon bridge | BI2: cons | BJ2: Island - Hot | BK2: Island Cold | BL2: north | BM2: cons | BP2: south | BQ2: cons | BT2: south | BU2: Total water consump | BV2: Total HW consump | BW2: DIESEL | BX2: stock | BY2: Del | BZ2: CONS | CA2: Meter | CB2: cons | CC2: Kg | CD2: LPG 1 | CE2: stock | CF2: LPG 2 | CG2: stock | CH2: LPG 3 | CI2: stock | CJ2: total stock | CK2: cons | CL2: del | CM2: Beau champ | CN2: cons(Litres) | CO2: Cons(Kg) | CP2: Acquapazza | CQ2: cons(Litres) | CR2: Cons(Kg) | CS2: Bamboo | CT2: cons(Litres) | CU2: Cons(Kg) | CW2: cons(Litres) | CX2: Cons(Kg) | CZ2: cons(Litres) | DA2: Cons(Kg) | DC2: cons(Litres) | DD2: Cons(Kg) | DF2: cons(Litres) | DG2: Cons(Kg) | DI2: cons(Litres) | DJ2: Cons(Kg) | DL2: cons(Litres) | DM2: Cons(Kg) | DO2: cons(Litres) | DP2: Cons(Kg) | DR2: cons(Litres) | DS2: Cons(Kg) | DU2: cons(Litres) | DV2: Cons(Kg) | DW2: 145 | DX2: CONS | DY2: 146 | DZ2: CONS | EA2: Villa 111 | EB2: CONS | EC2: Villa 128 | ED2: CONS | EE2: Room Nights | EF2: Bed Nights | EG2: % OCC | EH2: California | EI2: Infiniti | EJ2: Fitness
A3: 44408 | B3: 7381782 | C3: 5269 | D3: 6580928 | E3: 4791 | F3: 0.9092807 | G3: 368 | H3: 306 | I3: 288064 | J3: 0 | K3: 776 | L3: 0 | M3: 633954 | N3: 0 | O3: 993 | P3: 0 | Q3: 2558860 | R3: 135 | S3: 2192512 | T3: 3 | U3: 117356 | V3: 73 | W3: 100 | X3: 152370 | Y3: 0 | Z3: 40521 | AA3: 5 | AB3: 1131 | AC3: 0 | AD3: 4605 | AE3: 0 | AH3: 583610 | AI3: 30 | AJ3: 826 | AK3: 1 | AL3: 52423 | AM3: 1 | AN3: 8931 | AO3: 0 | AP3: 10585 | AQ3: 0 | AR3: 14624 | AS3: 0 | AT3: 19369 | AU3: 0 | AV3: 20680 | AW3: 0 | AX3: 13872 | AY3: 0 | AZ3: 6225 | BA3: 0 | BB3: 26587 | BC3: 0 | BD3: 1115 | BE3: 0 | BF3: 4378 | BG3: 0 | BH3: 3636 | BI3: 0 | BJ3: 0 | BK3: 30 | BL3: 603990 | BM3: 20 | BN3: 747 | BO3: 0 | BP3: 784220 | BQ3: 40 | BR3: 7863 | BS3: 23 | BT3: 10 | BU3: 60 | BV3: 1 | BW3: 122 | BX3: 15128.058 | BZ3: 0 | CA3: 207001 | CB3: 5 | CC3: 28.55 | CD3: 51 | CE3: 5495.25 | CF3: 52 | CG3: 5603 | CH3: 55 | CI3: 5926.25 | CJ3: 17024.5 | CK3: 0 | CM3: 34751.1 | CN3: 3.6 | CO3: 8.784 | CP3: 34300 | CQ3: 0 | CR3: 0 | CS3: 10235.6 | CT3: 0 | CU3: 0 | CV3: 832280 | CW3: 0 | CX3: 0 | CY3: 6159 | CZ3: 2 | DA3: 4.78 | DB3: 7420 | DC3: 0 | DD3: 0 | DE3: 4214 | DF3: 2 | DG3: 0 | DH3: 1855.9 | DI3: 0 | DJ3: 0 | DK3: 5081.7 | DL3: 0 | DM3: 0 | DN3: 4454.7 | DO3: 0 | DP3: 0 | DQ3: 5089.6 | DR3: 0 | DS3: 0 | DT3: 5109.1 | DU3: 0 | DV3: 0 | DW3: 12871 | DX3: 0 | DY3: 62789 | DZ3: 0 | EA3: 15588 | EB3: 0 | EC3: 24679 | ED3: 0 | EE3: 2 | EF3: 6 | EG3: 0.015
A4: 44409 | B4: 7387489 | C4: 5707 | D4: 6586051 | E4: 5123 | F4: 0.89766953 | G4: 368 | H4: 306 | I4: 288064 | J4: 0 | K4: 776 | L4: 0 | M4: 633954 | N4: 0 | O4: 993 | P4: 0 | Q4: 2558900 | R4: 40 | S4: 2192514 | T4: 2 | U4: 117402 | V4: 46 | W4: 50 | X4: 152370 | Y4: 0 | Z4: 40527 | AA4: =IF((Z4-Z3)<0,"0",(Z4-Z3)) -> 6 | AB4: 1132 | AC4: 0 | AD4: 4605 | AE4: =(AD4-AD3) -> 0 | AH4: 583620 | AI4: =IF((AH4-AH3)<0,"0",(AH4-AH3)) -> 10 | AJ4: 826 | AK4: =(AJ4-AJ3) -> 0 | AL4: 52424 | AM4: =(AL4-AL3) -> 1 | AN4: 8931 | AO4: 0 | AP4: 10585 | AQ4: =(AP4-AP3) -> 0 | AR4: 14624 | AS4: =(AR4-AR3) -> 0 | AT4: 19369 | AU4: =(AT4-AT3) -> 0 | AV4: 20680 | AW4: =IF((AV4-AV3)<0,"0",(AV4-AV3)) -> 0 | AX4: 13872 | AY4: =IF((AX5-AX3)<0,"0",(AX5-AX3)) -> 0 | AZ4: 6225 | BA4: 0 | BB4: 26587 | BC4: =(BB4-BB3) -> 0 | BD4: 1115 | BE4: =(BD4-BD3) -> 0 | BF4: 4378 | BG4: =(BF4-BF3) -> 0 | BH4: 3636 | BI4: 0 | BJ4: =AY4+AW4+AS4 -> 0 | BK4: =AI4-BJ4 -> 10 | BL4: 604010 | BM4: =IF((BL4-BL3)<0,"0",(BL4-BL3)) -> 20 | BN4: 747 | BO4: =(BN4-BN3) -> 0 | BP4: 784260 | BQ4: =IF((BP4-BP3)<0,"0",(BP4-BP3)) -> 40 | BR4: 7875 | BS4: =IF((BR4-BR3)<0,"0",(BR4-BR3)) -> 12 | BT4: =BQ4-AI4 -> 30 | BU4: =SUM(BM4, BQ4) -> 60 | BV4: =SUM(AM4,AO4,AQ4,AS4,AU4,AW4,AY4,BA4,BE4) -> 1 | BW4: 124 | BX4: =(IF(BW4<=116.4,((116.4*116.4*ACOS((116.4-BW4)/116.4))-((116.4-BW4)*SQRT(2*116.4*BW4-BW4*BW4)))*669.8,((3.1416*116.4*116.4)-((116.4*116.4*ACOS((116.4-(2*116.4-BW4))/116.4))-((116.4-(2*116.4-BW4))*SQRT(2*116.4*(2*116.4-BW4)-((2*116.4-BW4)*(2*116.4-BW4))))))*669.8))/1000 -> 15439.411 | BZ4: =(BY4-BY3) -> 0 | CA4: 207002.1 | CB4: =IF((CA4-CA3)<0,"0",(CA4-CA3)) -> 1.1 | CC4: =CB4*5.71 -> 6.281 | CD4: 51 | CE4: =(CD4*10775)/100 -> 5495.25 | CF4: 51 | CG4: =(CF4*10775)/100 -> 5495.25 | CH4: 55 | CI4: =(CH4*10775)/100 -> 5926.25 | CJ4: =CE4+CG4+CI4 -> 16916.75 | CK4: =IF((CJ3-CJ4+CL3)=CJ3,"0",(CJ3-CJ4+CL3)) -> 107.75 | CM4: 34571.1 | CN4: =IF((CM4-CM3)<0,"0",(CM4-CM3)) -> 0 | CO4: =CN4*2.44 -> 0 | CP4: 34300 | CQ4: =IF((CP4-CP3)<0,"0",(CP4-CP3)) -> 0 | CR4: =CQ4*2.44 -> 0 | CS4: 10235.6 | CT4: 0 | CU4: =CT4*2.44 -> 0 | CV4: 832280 | CW4: =IF((CV4-CV3)<0,"0",(CV4-CV3)) -> 0 | CX4: =CW4*2.44 -> 0 | CY4: 6160 | CZ4: =IF((CY4-CY3)<0,"0",(CY4-CY3)) -> 1 | DA4: =CZ4*2.39 -> 2.39 | DB4: 7420 | DC4: =IF((DB4-DB3)<0,"0",(DB4-DB3)) -> 0 | DD4: =IF((DC4-DC3)<0,"0",(DC4-DC3)) -> 0 | DE4: 4218 | DF4: =IF((DE4-DE3)<0,"0",(DE4-DE3)) -> 4 | DG4: =IF((DF4-DF3)<0,"0",(DF4-DF3)) -> 2 | DH4: 1855.9 | DI4: =IF((DH4-DH3)<0,"0",(DH4-DH3)) -> 0 | DJ4: =IF((DI4-DI3)<0,"0",(DI4-DI3)) -> 0 | DK4: 5081.7 | DL4: =IF((DK4-DK3)<0,"0",(DK4-DK3)) -> 0 | DM4: =IF((DL4-DL3)<0,"0",(DL4-DL3)) -> 0 | DN4: 4454.7 | DO4: =IF((DN4-DN3)<0,"0",(DN4-DN3)) -> 0 | DP4: =IF((DO4-DO3)<0,"0",(DO4-DO3)) -> 0 | DQ4: 5089.6 | DR4: =IF((DQ4-DQ3)<0,"0",(DQ4-DQ3)) -> 0 | DS4: =IF((DR4-DR3)<0,"0",(DR4-DR3)) -> 0 | DT4: 5109.1 | DU4: =IF((DT4-DT3)<0,"0",(DT4-DT3)) -> 0 | DV4: =DU4*2.39 -> 0 | DW4: 12871 | DX4: =(DW4-DW3) -> 0 | DY4: 62789 | DZ4: =(DY4-DY3) -> 0 | EA4: 15588 | EB4: =(EA4-EA3) -> 0 | EC4: 24679 | ED4: =(EC4-EC3) -> 0 | EE4: 2 | EF4: 6 | EG4: 0.015
A5: 44410 | B5: 7393616 | C5: 6127 | D5: 6591571 | E5: 5520 | F5: 0.90093031 | G5: 368 | H5: 316 | I5: 288064 | J5: 0 | K5: 776 | L5: 0 | M5: 633954 | N5: 0 | O5: 993 | P5: 0 | Q5: 2559065 | R5: 165 | S5: 2192517 | T5: 3 | U5: 117473 | V5: 71 | W5: 50 | X5: 152370 | Y5: 0 | Z5: 40536 | AA5: 9 | AB5: 1133 | AC5: 1 | AD5: 4605 | AE5: 0 | AH5: 583650 | AI5: 30 | AJ5: 828 | AK5: 2 | AL5: 52426 | AM5: 2 | AN5: 8931 | AO5: 0 | AP5: 10585 | AQ5: 0 | AR5: 14624 | AS5: 0 | AT5: 19369 | AU5: 0 | AV5: 20680 | AW5: 0 | AX5: 13872 | AY5: 0 | AZ5: 6225 | BA5: 0 | BB5: 26589 | BC5: 2 | BD5: 1115 | BE5: 0 | BF5: 4378 | BG5: 0 | BH5: 3636 | BI5: 0 | BJ5: 0 | BK5: 30 | BL5: 604030 | BM5: 20 | BN5: 747 | BO5: 0 | BP5: 784310 | BQ5: 50 | BR5: 7898 | BS5: 23 | BT5: 20 | BU5: 70 | BV5: 2 | BW5: 124 | BX5: 15439.411 | BZ5: 0 | CA5: 207008 | CB5: 5.9 | CC5: 33.689 | CD5: 51 | CE5: 5495.25 | CF5: 51 | CG5: 5495.25 | CH5: 54 | CI5: 5818.5 | CJ5: 16809 | CK5: 107.75 | CM5: 34757 | CN5: 5.9 | CO5: 14.396 | CP5: 34300 | CQ5: 0 | CR5: 0 | CS5: 10235.6 | CT5: 0 | CU5: 0 | CV5: 832280 | CW5: 0 | CX5: 0 | CY5: 6162 | CZ5: 2 | DA5: 4.78 | DB5: 7420 | DC5: 0 | DD5: 0 | DE5: 4223 | DF5: 5 | DG5: 1 | DH5: 1855.9 | DI5: 0 | DJ5: 0 | DK5: 5081.7 | DL5: 0 | DM5: 0 | DN5: 4454.7 | DO5: 0 | DP5: 0 | DQ5: 5089.6 | DR5: 0 | DS5: 0 | DT5: 5109.1 | DU5: 0 | DV5: 0 | DW5: 12871 | DX5: 0 | DY5: 62789 | DZ5: 0 | EA5: 15588 | EB5: 0 | EC5: 24679 | ED5: 0 | EE5: 2 | EF5: 6 | EG5: 0.015
A6: 44411 | B6: 7399324 | C6: 5708 | D6: 6596780 | E6: 5209 | F6: 0.91257884 | G6: 368 | H6: 316 | I6: 288064 | J6: 0 | K6: 776 | L6: 0 | M6: 633954 | N6: 0 | O6: 993 | P6: 0 | Q6: 2559194 | R6: 129 | S6: 2192519 | T6: 2 | U6: 117600 | V6: 127 | W6: 50 | X6: 152370 | Y6: 0 | Z6: 40547 | AA6: 11 | AB6: 1133 | AC6: 0 | AD6: 4605 | AE6: 0 | AH6: 583680 | AI6: 30 | AJ6: 830 | AK6: 2 | AL6: 52429 | AM6: 3 | AN6: 8931 | AO6: 0 | AP6: 10586 | AQ6: 1 | AR6: 14624 | AS6: 0 | AT6: 19369 | AU6: 0 | AV6: 20680 | AW6: 0 | AX6: 13872 | AY6: 0 | AZ6: 6225 | BA6: 0 | BB6: 26589 | BC6: 0 | BD6: 1115 | BE6: 0 | BF6: 4378 | BG6: 0 | BH6: 3636 | BI6: 0 | BJ6: 0 | BK6: 30 | BL6: 604080 | BM6: 50 | BN6: 747 | BO6: 0 | BP6: 784370 | BQ6: 60 | BR6: 7919 | BS6: 21 | BT6: 30 | BU6: 110 | BV6: 4 | BW6: 124 | BX6: 15439.411 | BZ6: 0 | CA6: 207021 | CB6: 13 | CC6: 74.23 | CD6: 50 | CE6: 5387.5 | CF6: 51 | CG6: 5495.25 | CH6: 54 | CI6: 5818.5 | CJ6: 16701.25 | CK6: 107.75 | CM6: 34760 | CN6: 3 | CO6: 7.32 | CP6: 34300 | CQ6: 0 | CR6: 0 | CS6: 10235.6 | CT6: 0 | CU6: 0 | CV6: 832280 | CW6: 0 | CX6: 0 | CY6: 6165 | CZ6: 3 | DA6: 7.17 | DB6: 7420 | DC6: 0 | DD6: 0 | DE6: 4228 | DF6: 5 | DG6: 0 | DH6: 1855.9 | DI6: 0 | DJ6: 0 | DK6: 5081.7 | DL6: 0 | DM6: 0 | DN6: 4454.7 | DO6: 0 | DP6: 0 | DQ6: 5089.6 | DR6: 0 | DS6: 0 | DT6: 5109.1 | DU6: 0 | DV6: 0 | DW6: 12871 | DX6: 0 | DY6: 62789 | DZ6: 0 | EA6: 15588 | EB6: 0 | EC6: 24679 | ED6: 0 | EE6: 2 | EF6: 6 | EG6: 0.015
A7: 44412 | B7: 7405670 | C7: 6346 | D7: 6602505 | E7: 5725 | F7: 0.90214308 | G7: 368 | H7: 338 | I7: 288064 | J7: 0 | K7: 776 | L7: 0 | M7: 633954 | N7: 0 | O7: 993 | P7: 0 | Q7: 2559344 | R7: 150 | S7: 2192521 | T7: 2 | U7: 117691 | V7: 91 | W7: 50 | X7: 152370 | Y7: 0 | Z7: 40557 | AA7: 10 | AB7: 1133 | AC7: 0 | AD7: 4605 | AE7: 0 | AH7: 583712 | AI7: 32 | AJ7: 831 | AK7: 1 | AL7: 52433 | AM7: 4 | AN7: 8931 | AO7: 0 | AP7: 10586 | AQ7: 0 | AR7: 14624 | AS7: 0 | AT7: 19369 | AU7: 0 | AV7: 20680 | AW7: 0 | AX7: 13872 | AY7: 0 | AZ7: 6225 | BA7: 0 | BB7: 26593 | BC7: 4 | BD7: 1115 | BE7: 0 | BF7: 4378 | BG7: 0 | BH7: 3636 | BI7: 0 | BJ7: 0 | BK7: 32 | BL7: 604120 | BM7: 40 | BN7: 747 | BO7: 0 | BP7: 784430 | BQ7: 60 | BR7: 7938 | BS7: 19 | BT7: 28 | BU7: 100 | BV7: 4 | BW7: 124 | BX7: 15439.411 | BZ7: 0 | CA7: 207026 | CB7: 5 | CC7: 28.55 | CD7: 50 | CE7: 5387.5 | CF7: 50 | CG7: 5387.5 | CH7: 53 | CI7: 5710.75 | CJ7: 16485.75 | CK7: 215.5 | CM7: 34765 | CN7: 5 | CO7: 12.2 | CP7: 34300 | CQ7: 0 | CR7: 0 | CS7: 10235.6 | CT7: 0 | CU7: 0 | CV7: 832280 | CW7: 0 | CX7: 0 | CY7: 6168 | CZ7: 3 | DA7: 7.17 | DB7: 7420 | DC7: 0 | DD7: 0 | DE7: 4233 | DF7: 5 | DG7: 0 | DH7: 1855.9 | DI7: 0 | DJ7: 0 | DK7: 5081.7 | DL7: 0 | DM7: 0 | DN7: 4454.7 | DO7: 0 | DP7: 0 | DQ7: 5089.6 | DR7: 0 | DS7: 0 | DT7: 5109.1 | DU7: 0 | DV7: 0 | DW7: 12871 | DX7: 0 | DY7: 62789 | DZ7: 0 | EA7: 15588 | EB7: 0 | EC7: 24679 | ED7: 0 | EE7: 2 | EF7: 6 | EG7: 0.015
A8: 44413 | B8: 7411859 | C8: 6189 | D8: 6608126 | E8: 5621 | F8: 0.90822427 | G8: 368 | H8: 342 | I8: 288064 | J8: 0 | K8: 776 | L8: 0 | M8: 633954 | N8: 0 | O8: 993 | P8: 0 | Q8: 2559504 | R8: 160 | S8: 2192684 | T8: 163 | U8: 117800 | V8: 109 | W8: 50 | X8: 152370 | Y8: 0 | Z8: 40573 | AA8: 16 | AB8: 1133 | AC8: 0 | AD8: 4605 | AE8: 0 | AH8: 583750 | AI8: 38 | AJ8: 832 | AK8: 1 | AL8: 52446 | AM8: 13 | AN8: 8931 | AO8: 0 | AP8: 10587 | AQ8: 1 | AR8: 14624 | AS8: 0 | AT8: 19369 | AU8: 0 | AV8: 20680 | AW8: 0 | AX8: 13872 | AY8: 0 | AZ8: 6225 | BA8: 0 | BB8: 26596 | BC8: 3 | BD8: 1115 | BE8: 0 | BF8: 4378 | BG8: 0 | BH8: 3636 | BI8: 0 | BJ8: 0 | BK8: 38 | BL8: 604190 | BM8: 70 | BN8: 747 | BO8: 0 | BP8: 784490 | BQ8: 60 | BR8: 7955 | BS8: 17 | BT8: 22 | BU8: 130 | BV8: 14 | BW8: 124 | BX8: 15439.411 | BZ8: 0 | CA8: 207067 | CB8: 41 | CC8: 234.11 | CD8: 50 | CE8: 5387.5 | CF8: 49 | CG8: 5279.75 | CH8: 53 | CI8: 5710.75 | CJ8: 16378 | CK8: 107.75 | CM8: 34768 | CN8: 3 | CO8: 7.32 | CP8: 34300 | CQ8: 0 | CR8: 0 | CS8: 10235.6 | CT8: 0 | CU8: 0 | CV8: 832313 | CW8: 33 | CX8: 80.52 | CY8: 6172 | CZ8: 4 | DA8: 9.56 | DB8: 7420 | DC8: 0 | DD8: 0 | DE8: 4241 | DF8: 8 | DG8: 3 | DH8: 1855.9 | DI8: 0 | DJ8: 0 | DK8: 5081.7 | DL8: 0 | DM8: 0 | DN8: 4454.7 | DO8: 0 | DP8: 0 | DQ8: 5089.6 | DR8: 0 | DS8: 0 | DT8: 5109.1 | DU8: 0 | DV8: 0 | DW8: 12871 | DX8: 0 | DY8: 62789 | DZ8: 0 | EA8: 15588 | EB8: 0 | EC8: 24679 | ED8: 0 | EE8: 2 | EF8: 6 | EG8: 0.015
A9: 44414 | B9: 7418134 | C9: 6275 | D9: 6613704 | E9: 5578 | F9: 0.8889243 | G9: 368 | H9: 342 | I9: 288064 | J9: 0 | K9: 776 | L9: 0 | M9: 633954 | N9: 0 | O9: 993 | P9: 0 | Q9: 2559650 | R9: 146 | S9: 2192690 | T9: 6 | U9: 117900 | V9: 100 | W9: 50 | X9: 152370 | Y9: 0 | Z9: 40581 | AA9: 8 | AB9: 1134 | AC9: 1 | AD9: 4605 | AE9: 0 | AH9: 583780 | AI9: 30 | AJ9: 834 | AK9: 2 | AL9: 52449 | AM9: 3 | AN9: 8931 | AO9: 0 | AP9: 10587 | AQ9: 0 | AR9: 14624 | AS9: 0 | AT9: 19369 | AU9: 0 | AV9: 20680 | AW9: 0 | AX9: 13872 | AY9: 0 | AZ9: 6225 | BA9: 0 | BB9: 26597 | BC9: 1 | BD9: 1115 | BE9: 0 | BF9: 4378 | BG9: 0 | BH9: 3636 | BI9: 0 | BJ9: 0 | BK9: 30 | BL9: 604240 | BM9: 50 | BN9: 751 | BO9: 4 | BP9: 784550 | BQ9: 60 | BR9: 7978 | BS9: 23 | BT9: 30 | BU9: 110 | BV9: 3 | BW9: 123 | BX9: 15283.773 | BZ9: 0 | CA9: 207072 | CB9: 5 | CC9: 28.55 | CD9: 50 | CE9: 5387.5 | CF9: 50 | CG9: 5387.5 | CH9: 51 | CI9: 5495.25 | CJ9: 16270.25 | CK9: 107.75 | CM9: 34772 | CN9: 4 | CO9: 9.76 | CP9: 34300 | CQ9: 0 | CR9: 0 | CS9: 10235.6 | CT9: 0 | CU9: 0 | CV9: 832313 | CW9: 0 | CX9: 0 | CY9: 6175 | CZ9: 3 | DA9: 7.17 | DB9: 7420 | DC9: 0 | DD9: 0 | DE9: 4242 | DF9: 1 | DG9: 0 | DH9: 1855.9 | DI9: 0 | DJ9: 0 | DK9: 5081.7 | DL9: 0 | DM9: 0 | DN9: 4454.7 | DO9: 0 | DP9: 0 | DQ9: 5089.6 | DR9: 0 | DS9: 0 | DT9: 5109.1 | DU9: 0 | DV9: 0 | DW9: 12871 | DX9: 0 | DY9: 62789 | DZ9: 0 | EA9: 15588 | EB9: 0 | EC9: 24679 | ED9: 0 | EE9: 2 | EF9: 6 | EG9: 0.015
A10: 44415 | B10: 7423510 | C10: 5376 | D10: 6618643 | E10: 4939 | F10: 0.9187128 | G10: 368 | H10: 342 | I10: 288064 | J10: 0 | K10: 776 | L10: 0 | M10: 633954 | N10: 0 | O10: 993 | P10: 0 | Q10: 2559772 | R10: 122 | S10: 2192691 | T10: 1 | U10: 117970 | V10: 70 | W10: 50 | X10: 152370 | Y10: 0 | Z10: 40590 | AA10: 9 | AB10: 1136 | AC10: 2 | AD10: 4605 | AE10: 0 | AH10: 583820 | AI10: 40 | AJ10: 834 | AK10: 0 | AL10: 52450 | AM10: 1 | AN10: 8931 | AO10: 0 | AP10: 10587 | AQ10: 0 | AR10: 14624 | AS10: 0 | AT10: 19369 | AU10: 0 | AV10: 20680 | AW10: 0 | AX10: 13872 | AY10: 0 | AZ10: 6225 | BA10: 0 | BB10: 26599 | BC10: 2 | BD10: 1115 | BE10: 0 | BF10: 4378 | BG10: 0 | BH10: 3636 | BI10: 0 | BJ10: 0 | BK10: 40 | BL10: 604270 | BM10: 30 | BN10: 752 | BO10: 1 | BP10: 784601 | BQ10: 51 | BR10: 7991 | BS10: 13 | BT10: 11 | BU10: 81 | BV10: 1 | BW10: 122 | BX10: 15128.058 | BZ10: 0 | CA10: 207075 | CB10: 3 | CC10: 17.13 | CD10: 50 | CE10: 5387.5 | CF10: 49 | CG10: 5279.75 | CH10: 51 | CI10: 5495.25 | CJ10: 16162.5 | CK10: 107.75 | CM10: 34776 | CN10: 4 | CO10: 9.76 | CP10: 34300 | CQ10: 0 | CR10: 0 | CS10: 10235.6 | CT10: 0 | CU10: 0 | CV10: 832313 | CW10: 0 | CX10: 0 | CY10: 6175 | CZ10: 0 | DA10: 0 | DB10: 7420 | DC10: 0 | DD10: 0 | DE10: 4247 | DF10: 5 | DG10: 4 | DH10: 1855.9 | DI10: 0 | DJ10: 0 | DK10: 5081.7 | DL10: 0 | DM10: 0 | DN10: 4454.7 | DO10: 0 | DP10: 0 | DQ10: 5089.6 | DR10: 0 | DS10: 0 | DT10: 5109.1 | DU10: 0 | DV10: 0 | DW10: 12871 | DX10: 0 | DY10: 62789 | DZ10: 0 | EA10: 15588 | EB10: 0 | EC10: 24679 | ED10: 0 | EE10: 2 | EF10: 6 | EG10: 0.015
A11: 44416 | B11: 7428825 | C11: 5315 | D11: 6623521 | E11: 4878 | F11: 0.91777987 | G11: 368 | H11: 342 | I11: 288064 | J11: 0 | K11: 776 | L11: 0 | M11: 633954 | N11: 0 | O11: 993 | P11: 0 | Q11: 2559816 | R11: 44 | S11: 2192693 | T11: 2 | U11: 118030 | V11: 60 | W11: 50 | X11: 152370 | Y11: 0 | Z11: 40596 | AA11: 6 | AB11: 1136 | AC11: 0 | AD11: 4605 | AE11: 0 | AH11: 583845 | AI11: 25 | AJ11: 834 | AK11: 0 | AL11: 52450 | AM11: 0 | AN11: 8931 | AO11: 0 | AP11: 10587 | AQ11: 0 | AR11: 14624 | AS11: 0 | AT11: 19369 | AU11: 0 | AV11: 20680 | AW11: 0 | AX11: 13872 | AY11: 0 | AZ11: 6225 | BA11: 0 | BB11: 26600 | BC11: 1 | BD11: 1115 | BE11: 0 | BF11: 4378 | BG11: 0 | BH11: 3636 | BI11: 0 | BJ11: 0 | BK11: 25 | BL11: 604280 | BM11: 10 | BN11: 752 | BO11: 0 | BP11: 784645 | BQ11: 44 | BR11: 8004 | BS11: 13 | BT11: 19 | BU11: 54 | BV11: 0 | BW11: 122 | BX11: 15128.058 | BZ11: 0 | CA11: 207078 | CB11: 3 | CC11: 17.13 | CD11: 49 | CE11: 5279.75 | CF11: 49 | CG11: 5279.75 | CH11: 51 | CI11: 5495.25 | CJ11: 16054.75 | CK11: 107.75 | CM11: 34778 | CN11: 2 | CO11: 4.88 | CP11: 34300 | CQ11: 0 | CR11: 0 | CS11: 10235.6 | CT11: 0 | CU11: 0 | CV11: 832313 | CW11: 0 | CX11: 0 | CY11: 6175 | CZ11: 0 | DA11: 0 | DB11: 7420 | DC11: 0 | DD11: 0 | DE11: 4252 | DF11: 5 | DG11: 0 | DH11: 1855.9 | DI11: 0 | DJ11: 0 | DK11: 5081.7 | DL11: 0 | DM11: 0 | DN11: 4454.7 | DO11: 0 | DP11: 0 | DQ11: 5089.6 | DR11: 0 | DS11: 0 | DT11: 5109.1 | DU11: 0 | DV11: 0 | DW11: 12871 | DX11: 0 | DY11: 62789 | DZ11: 0 | EA11: 15588 | EB11: 0 | EC11: 24679 | ED11: 0 | EE11: 2 | EF11: 6 | EG11: 0.015
A12: 44417 | B12: 7434627 | C12: 5802 | D12: 6628761 | E12: 5240 | F12: 0.90313685 | G12: 368 | H12: 342 | I12: 288064 | J12: 0 | K12: 776 | L12: 0 | M12: 633954 | N12: 0 | O12: 993 | P12: 0 | Q12: 2559956 | R12: 140 | S12: 2192696 | T12: 3 | U12: 118130 | V12: 100 | W12: 50 | X12: 152370 | Y12: 0 | Z12: 40606 | AA12: 10 | AB12: 1136 | AC12: 0 | AD12: 4605 | AE12: 0 | AH12: 583870 | AI12: 25 | AJ12: 834 | AK12: 0 | AL12: 52454 | AM12: 4 | AN12: 8931 | AO12: 0 | AP12: 10587 | AQ12: 0 | AR12: 14624 | AS12: 0 | AT12: 19369 | AU12: 0 | AV12: 20680 | AW12: 0 | AX12: 13872 | AY12: 0 | AZ12: 6225 | BA12: 0 | BB12: 26602 | BC12: 2 | BD12: 1115 | BE12: 0 | BF12: 4378 | BG12: 0 | BH12: 3636 | BI12: 0 | BJ12: 0 | BK12: 25 | BL12: 604330 | BM12: 50 | BN12: 752 | BO12: 0 | BP12: 784690 | BQ12: 45 | BR12: 8017 | BS12: 13 | BT12: 20 | BU12: 95 | BV12: 4 | BW12: 122 | BX12: 15128.058 | BZ12: 0 | CA12: 207085 | CB12: 7 | CC12: 39.97 | CD12: 49 | CE12: 5279.75 | CF12: 48 | CG12: 5172 | CH12: 51 | CI12: 5495.25 | CJ12: 15947 | CK12: 107.75 | CM12: 34782 | CN12: 4 | CO12: 9.76 | CP12: 34300 | CQ12: 0 | CR12: 0 | CS12: 10235.6 | CT12: 0 | CU12: 0 | CV12: 832313 | CW12: 0 | CX12: 0 | CY12: 6175 | CZ12: 0 | DA12: 0 | DB12: 7420 | DC12: 0 | DD12: 0 | DE12: 4257 | DF12: 5 | DG12: 0 | DH12: 1855.9 | DI12: 0 | DJ12: 0 | DK12: 5081.7 | DL12: 0 | DM12: 0 | DN12: 4454.7 | DO12: 0 | DP12: 0 | DQ12: 5089.6 | DR12: 0 | DS12: 0 | DT12: 5112 | DU12: 2.9 | DV12: 6.931 | DW12: 12871 | DX12: 0 | DY12: 62789 | DZ12: 0 | EA12: 15588 | EB12: 0 | EC12: 24679 | ED12: 0 | EE12: 2 | EF12: 6 | EG12: 0.015
A13: 44418 | B13: 7440145 | C13: 5518 | D13: 6633756 | E13: 4995 | F13: 0.90521928 | G13: 368 | H13: 342 | I13: 288064 | J13: 0 | K13: 776 | L13: 0 | M13: 633954 | N13: 0 | O13: 993 | P13: 0 | Q13: 2560103 | R13: 147 | S13: 2192697 | T13: 1 | U13: 118203 | V13: 73 | W13: 50 | X13: 152370 | Y13: 0 | Z13: 40614 | AA13: 8 | AB13: 1136 | AC13: 0 | AD13: 4605 | AE13: 0 | AH13: 583910 | AI13: 40 | AJ13: 834 | AK13: 0 | AL13: 52454 | AM13: 0 | AN13: 8931 | AO13: 0 | AP13: 10588 | AQ13: 1 | AR13: 14624 | AS13: 0 | AT13: 19369 | AU13: 0 | AV13: 20680 | AW13: 0 | AX13: 13872 | AY13: 0 | AZ13: 6225 | BA13: 0 | BB13: 26604 | BC13: 2 | BD13: 1115 | BE13: 0 | BF13: 4378 | BG13: 0 | BH13: 3636 | BI13: 0 | BJ13: 0 | BK13: 40 | BL13: 604350 | BM13: 20 | BN13: 752 | BO13: 0 | BP13: 784740 | BQ13: 50 | BR13: 8031 | BS13: 14 | BT13: 10 | BU13: 70 | BV13: 1 | BW13: 122 | BX13: 15128.058 | BZ13: 0 | CA13: 207097 | CB13: 12 | CC13: 68.52 | CD13: 49 | CE13: 5279.75 | CF13: 48 | CG13: 5172 | CH13: 51 | CI13: 5495.25 | CJ13: 15947 | CK13: 0 | CM13: 34786 | CN13: 4 | CO13: 9.76 | CP13: 34300 | CQ13: 0 | CR13: 0 | CS13: 10235.6 | CT13: 0 | CU13: 0 | CV13: 832313 | CW13: 0 | CX13: 0 | CY13: 6175 | CZ13: 0 | DA13: 0 | DB13: 7420 | DC13: 0 | DD13: 0 | DE13: 4262 | DF13: 5 | DG13: 0 | DH13: 1855.9 | DI13: 0 | DJ13: 0 | DK13: 5081.7 | DL13: 0 | DM13: 0 | DN13: 4454.7 | DO13: 0 | DP13: 0 | DQ13: 5089.6 | DR13: 0 | DS13: 0 | DT13: 5119 | DU13: 7 | DV13: 16.73 | DW13: 12871 | DX13: 0 | DY13: 62789 | DZ13: 0 | EA13: 15588 | EB13: 0 | EC13: 24679 | ED13: 0 | EE13: 2 | EF13: 6 | EG13: 0.015
A14: 44419 | B14: 7446252 | C14: 6107 | D14: 6639268 | E14: 5512 | F14: 0.90257082 | G14: 368 | H14: 342 | I14: 288064 | J14: 0 | K14: 776 | L14: 0 | M14: 633954 | N14: 0 | O14: 993 | P14: 0 | Q14: 2560267 | R14: 164 | S14: 2192697 | T14: 0 | U14: 118285 | V14: 82 | W14: 50 | X14: 152370 | Y14: 0 | Z14: 40626 | AA14: 12 | AB14: 1136 | AC14: 0 | AD14: 4605 | AE14: 0 | AH14: 583940 | AI14: 30 | AJ14: 834 | AK14: 0 | AL14: 52460 | AM14: 6 | AN14: 8931 | AO14: 0 | AP14: 10588 | AQ14: 0 | AR14: 14624 | AS14: 0 | AT14: 19369 | AU14: 0 | AV14: 20680 | AW14: 0 | AX14: 13872 | AY14: 0 | AZ14: 6225 | BA14: 0 | BB14: 26606 | BC14: 2 | BD14: 1115 | BE14: 0 | BF14: 4378 | BG14: 0 | BH14: 3636 | BI14: 0 | BJ14: 0 | BK14: 30 | BL14: 604400 | BM14: 50 | BN14: 752 | BO14: 0 | BP14: 784790 | BQ14: 50 | BR14: 8045 | BS14: 14 | BT14: 20 | BU14: 100 | BV14: 6 | BW14: 122 | BX14: 15128.058 | BZ14: 0 | CA14: 207111 | CB14: 14 | CC14: 79.94 | CD14: 48 | CE14: 5172 | CF14: 48 | CG14: 5172 | CH14: 51 | CI14: 5495.25 | CJ14: 15839.25 | CK14: 107.75 | CM14: 34790 | CN14: 4 | CO14: 9.76 | CP14: 34300 | CQ14: 0 | CR14: 0 | CS14: 10235.6 | CT14: 0 | CU14: 0 | CV14: 832313 | CW14: 0 | CX14: 0 | CY14: 6175 | CZ14: 0 | DA14: 0 | DB14: 7420 | DC14: 0 | DD14: 0 | DE14: 4268 | DF14: 6 | DG14: 1 | DH14: 1855.9 | DI14: 0 | DJ14: 0 | DK14: 5081.7 | DL14: 0 | DM14: 0 | DN14: 4454.7 | DO14: 0 | DP14: 0 | DQ14: 5089.6 | DR14: 0 | DS14: 0 | DT14: 5125 | DU14: 6 | DV14: 14.34 | DW14: 12871 | DX14: 0 | DY14: 62789 | DZ14: 0 | EA14: 15588 | EB14: 0 | EC14: 24679 | ED14: 0 | EE14: 2 | EF14: 6 | EG14: 0.015
A15: 44420 | B15: 7452499 | C15: 6247 | D15: 6644932 | E15: 5664 | F15: 0.9066752 | G15: 368 | H15: 342 | I15: 288064 | J15: 0 | K15: 776 | L15: 0 | M15: 633954 | N15: 0 | O15: 993 | P15: 0 | Q15: 2560428 | R15: 161 | S15: 2192697 | T15: 0 | U15: 118293 | V15: 8 | W15: 35 | X15: 152370 | Y15: 0 | Z15: 40634 | AA15: 8 | AB15: 1137 | AC15: 1 | AD15: 4605 | AE15: 0 | AH15: 583970 | AI15: 30 | AJ15: 845 | AK15: 11 | AL15: 52464 | AM15: 4 | AN15: 8931 | AO15: 0 | AP15: 10588 | AQ15: 0 | AR15: 14624 | AS15: 0 | AT15: 19369 | AU15: 0 | AV15: 20680 | AW15: 0 | AX15: 13872 | AY15: 0 | AZ15: 6225 | BA15: 0 | BB15: 26610 | BC15: 4 | BD15: 1115 | BE15: 0 | BF15: 4378 | BG15: 0 | BH15: 3636 | BI15: 0 | BJ15: 0 | BK15: 30 | BL15: 604440 | BM15: 40 | BN15: 771 | BO15: 19 | BP15: 784830 | BQ15: 40 | BR15: 8057 | BS15: 12 | BT15: 10 | BU15: 80 | BV15: 4 | BW15: 122 | BX15: 15128.058 | BZ15: 0 | CA15: 207127 | CB15: 16 | CC15: 91.36 | CD15: 48 | CE15: 5172 | CF15: 46 | CG15: 4956.5 | CH15: 51 | CI15: 5495.25 | CJ15: 15623.75 | CK15: 215.5 | CM15: 34794 | CN15: 4 | CO15: 9.76 | CP15: 34300 | CQ15: 0 | CR15: 0 | CS15: 10235.6 | CT15: 0 | CU15: 0 | CV15: 832313 | CW15: 0 | CX15: 0 | CY15: 6177 | CZ15: 2 | DA15: 4.78 | DB15: 7420 | DC15: 0 | DD15: 0 | DE15: 4271 | DF15: 3 | DG15: 0 | DH15: 1855.9 | DI15: 0 | DJ15: 0 | DK15: 5081.7 | DL15: 0 | DM15: 0 | DN15: 4454.7 | DO15: 0 | DP15: 0 | DQ15: 5089.6 | DR15: 0 | DS15: 0 | DT15: 5134.9 | DU15: 9.9 | DV15: 23.661 | DW15: 12871 | DX15: 0 | DY15: 62789 | DZ15: 0 | EA15: 15588 | EB15: 0 | EC15: 24679 | ED15: 0 | EE15: 2 | EF15: 6 | EG15: 0.015
A16: 44421 | B16: 7456835 | C16: 4336 | D16: 6648952 | E16: 4020 | F16: 0.92712177 | G16: 368 | H16: 342 | I16: 288064 | J16: 0 | K16: 776 | L16: 0 | M16: 633954 | N16: 0 | O16: 993 | P16: 0 | Q16: 2560586 | R16: 158 | S16: 2192697 | T16: 0 | U16: 118293 | V16: 0 | W16: 25 | X16: 152370 | Y16: 0 | Z16: 40647 | AA16: 13 | AB16: 1137 | AC16: 0 | AD16: 4605 | AE16: 0 | AH16: 584010 | AI16: 40 | AJ16: 850 | AK16: 5 | AL16: 52467 | AM16: 3 | AN16: 8931 | AO16: 0 | AP16: 10589 | AQ16: 1 | AR16: 14624 | AS16: 0 | AT16: 19369 | AU16: 0 | AV16: 20680 | AW16: 0 | AX16: 13872 | AY16: 0 | AZ16: 6225 | BA16: 0 | BB16: 26611 | BC16: 1 | BD16: 1115 | BE16: 0 | BF16: 4378 | BG16: 0 | BH16: 3636 | BI16: 0 | BJ16: 0 | BK16: 40 | BL16: 604500 | BM16: 60 | BN16: 771 | BO16: 0 | BP16: 784890 | BQ16: 60 | BR16: 8070 | BS16: 13 | BT16: 20 | BU16: 120 | BV16: 4 | BW16: 122 | BX16: 15128.058 | BZ16: 0 | CA16: 207132 | CB16: 5 | CC16: 28.55 | CD16: 48 | CE16: 5172 | CF16: 46 | CG16: 4956.5 | CH16: 50 | CI16: 5387.5 | CJ16: 15516 | CK16: 107.75 | CM16: 34797 | CN16: 3 | CO16: 7.32 | CP16: 34300 | CQ16: 0 | CR16: 0 | CS16: 10235.6 | CT16: 0 | CU16: 0 | CV16: 832313 | CW16: 0 | CX16: 0 | CY16: 6180 | CZ16: 3 | DA16: 7.17 | DB16: 7420 | DC16: 0 | DD16: 0 | DE16: 4276 | DF16: 5 | DG16: 2 | DH16: 1855.9 | DI16: 0 | DJ16: 0 | DK16: 5081.7 | DL16: 0 | DM16: 0 | DN16: 4454.7 | DO16: 0 | DP16: 0 | DQ16: 5089.6 | DR16: 0 | DS16: 0 | DT16: 5135.6 | DU16: 0.7 | DV16: 1.673 | DW16: 12871 | DX16: 0 | DY16: 62789 | DZ16: 0 | EA16: 15588 | EB16: 0 | EC16: 24679 | ED16: 0 | EE16: 2 | EF16: 6 | EG16: 0.015
A17: 44422 | B17: 7460848 | C17: 4013 | D17: 6652585 | E17: 3633 | F17: 0.90530775 | G17: 368 | H17: 342 | I17: 288064 | J17: 0 | K17: 776 | L17: 0 | M17: 633954 | N17: 0 | O17: 993 | P17: 0 | Q17: 2560716 | R17: 130 | S17: 2192697 | T17: 0 | U17: 118293 | V17: 0 | W17: 22 | X17: 152370 | Y17: 0 | Z17: 40655 | AA17: 8 | AB17: 1138 | AC17: 1 | AD17: 4605 | AE17: 0 | AH17: 584050 | AI17: 40 | AJ17: 863 | AK17: 13 | AL17: 52469 | AM17: 2 | AN17: 8931 | AO17: 0 | AP17: 10589 | AQ17: 0 | AR17: 14624 | AS17: 0 | AT17: 19369 | AU17: 0 | AV17: 20680 | AW17: 0 | AX17: 13872 | AY17: 0 | AZ17: 6225 | BA17: 0 | BB17: 26614 | BC17: 3 | BD17: 1115 | BE17: 0 | BF17: 4378 | BG17: 0 | BH17: 3636 | BI17: 0 | BJ17: 0 | BK17: 40 | BL17: 604540 | BM17: 40 | BN17: 772 | BO17: 1 | BP17: 784950 | BQ17: 60 | BR17: 8074 | BS17: 4 | BT17: 20 | BU17: 100 | BV17: 2 | BW17: 122 | BX17: 15128.058 | BZ17: 0 | CA17: 207137 | CB17: 5 | CC17: 28.55 | CD17: 48 | CE17: 5172 | CF17: 46 | CG17: 4956.5 | CH17: 50 | CI17: 5387.5 | CJ17: 15516 | CK17: 0 | CM17: 34799 | CN17: 2 | CO17: 4.88 | CP17: 34300 | CQ17: 0 | CR17: 0 | CS17: 10235.6 | CT17: 0 | CU17: 0 | CV17: 832313 | CW17: 0 | CX17: 0 | CY17: 6183 | CZ17: 3 | DA17: 7.17 | DB17: 7420 | DC17: 0 | DD17: 0 | DE17: 4280 | DF17: 4 | DG17: 0 | DH17: 1855.9 | DI17: 0 | DJ17: 0 | DK17: 5081.7 | DL17: 0 | DM17: 0 | DN17: 4454.7 | DO17: 0 | DP17: 0 | DQ17: 5089.6 | DR17: 0 | DS17: 0 | DT17: 5135.6 | DU17: 0 | DV17: 0 | DW17: 12871 | DX17: 0 | DY17: 62789 | DZ17: 0 | EA17: 15588 | EB17: 0 | EC17: 24679 | ED17: 0 | EE17: 2 | EF17: 6 | EG17: 0.015
A18: 44423 | B18: 7466731 | C18: 5883 | D18: 6657923 | E18: 5338 | F18: 0.90736019 | G18: 368 | H18: 342 | I18: 288064 | J18: 0 | K18: 776 | L18: 0 | M18: 633954 | N18: 0 | O18: 993 | P18: 0 | Q18: 2560764 | R18: 48 | S18: 2192698 | T18: 1 | U18: 118293 | V18: 0 | W18: 30 | X18: 152370 | Y18: 0 | Z18: 40660 | AA18: 5 | AB18: 1140 | AC18: 0 | AD18: 4605 | AE18: 0 | AH18: 584070 | AI18: 20 | AJ18: 869 | AK18: 6 | AL18: 52469 | AM18: 0 | AN18: 8931 | AO18: 0 | AP18: 10589 | AQ18: 0 | AR18: 14624 | AS18: 0 | AT18: 19369 | AU18: 0 | AV18: 20680 | AW18: 0 | AX18: 13872 | AY18: 0 | AZ18: 6225 | BA18: 0 | BB18: 26614 | BC18: 0 | BD18: 1115 | BE18: 0 | BF18: 4378 | BG18: 0 | BH18: 3636 | BI18: 0 | BJ18: 0 | BK18: 20 | BL18: 604560 | BM18: 20 | BN18: 773 | BO18: 1 | BP18: 784970 | BQ18: 20 | BR18: 8074 | BS18: 0 | BT18: 0 | BU18: 40 | BV18: 0 | BW18: 122 | BX18: 15128.058 | BZ18: 0 | CA18: 207138 | CB18: 1 | CC18: 5.71 | CD18: 48 | CE18: 5172 | CF18: 46 | CG18: 4956.5 | CH18: 49 | CI18: 5279.75 | CJ18: 15408.25 | CK18: 107.75 | CM18: 34800 | CN18: 1 | CO18: 2.44 | CP18: 34300 | CQ18: 0 | CR18: 0 | CS18: 10235.6 | CT18: 0 | CU18: 0 | CV18: 832313 | CW18: 0 | CX18: 0 | CY18: 6184 | CZ18: 1 | DA18: 2.39 | DB18: 7420 | DC18: 0 | DD18: 0 | DE18: 4285 | DF18: 5 | DG18: 1 | DH18: 1855.9 | DI18: 0 | DJ18: 0 | DK18: 5081.7 | DL18: 0 | DM18: 0 | DN18: 4454.7 | DO18: 0 | DP18: 0 | DQ18: 5089.6 | DR18: 0 | DS18: 0 | DT18: 5135.6 | DU18: 0 | DV18: 0 | DW18: 12871 | DX18: 0 | DY18: 62789 | DZ18: 0 | EA18: 15588 | EB18: 0 | EC18: 24679 | ED18: 0 | EE18: 2 | EF18: 6 | EG18: 0.015
A19: 44424 | B19: 7470856 | C19: 4125 | D19: 6661692 | E19: 3769 | F19: 0.91369697 | G19: 368 | H19: 342 | I19: 288064 | J19: 0 | K19: 776 | L19: 0 | M19: 633954 | N19: 0 | O19: 993 | P19: 0 | Q19: 2560892 | R19: 128 | S19: 2192742 | T19: 44 | U19: 118405 | V19: 112 | W19: 40 | X19: 152370 | Y19: 0 | Z19: 40669 | AA19: 9 | AB19: 1141 | AC19: 1 | AD19: 4605 | AE19: 0 | AH19: 584110 | AI19: 40 | AJ19: 876 | AK19: 7 | AL19: 52475 | AM19: 6 | AN19: 8931 | AO19: 0 | AP19: 10591 | AQ19: 2 | AR19: 14624 | AS19: 0 | AT19: 19369 | AU19: 0 | AV19: 20680 | AW19: 0 | AX19: 13872 | AY19: 0 | AZ19: 6225 | BA19: 0 | BB19: 26616 | BC19: 2 | BD19: 1115 | BE19: 0 | BF19: 4378 | BG19: 0 | BH19: 3636 | BI19: 0 | BJ19: 0 | BK19: 40 | BL19: 604610 | BM19: 50 | BN19: 775 | BO19: 2 | BP19: 785010 | BQ19: 40 | BR19: 8078 | BS19: 4 | BT19: 0 | BU19: 90 | BV19: 8 | BW19: 122 | BX19: 15128.058 | BZ19: 0 | CA19: 207156 | CB19: 18 | CC19: 102.78 | CD19: 47 | CE19: 5064.25 | CF19: 46 | CG19: 4956.5 | CH19: 49 | CI19: 5279.75 | CJ19: 15300.5 | CK19: 107.75 | CM19: 34804 | CN19: 4 | CO19: 9.76 | CP19: 34300 | CQ19: 0 | CR19: 0 | CS19: 10235.6 | CT19: 0 | CU19: 0 | CV19: 832313 | CW19: 0 | CX19: 0 | CY19: 6187 | CZ19: 3 | DA19: 7.17 | DB19: 7420 | DC19: 0 | DD19: 0 | DE19: 4290 | DF19: 5 | DG19: 0 | DH19: 1855.9 | DI19: 0 | DJ19: 0 | DK19: 5081.7 | DL19: 0 | DM19: 0 | DN19: 4454.7 | DO19: 0 | DP19: 0 | DQ19: 5089.6 | DR19: 0 | DS19: 0 | DT19: 5135.6 | DU19: 0 | DV19: 0 | DW19: 12871 | DX19: 0 | DY19: 62789 | DZ19: 0 | EA19: 15588 | EB19: 0 | EC19: 24679 | ED19: 0 | EE19: 2 | EF19: 6 | EG19: 0.015
A20: 44425 | B20: 7476531 | C20: 5675 | D20: 6666896 | E20: 5204 | F20: 0.91700441 | G20: 368 | H20: 342 | I20: 288064 | J20: 0 | K20: 776 | L20: 0 | M20: 633954 | N20: 0 | O20: 993 | P20: 0 | Q20: 2560990 | R20: 98 | S20: 2192756 | T20: 14 | U20: 118521 | V20: 116 | W20: 50 | X20: 152370 | Y20: 0 | Z20: 40679 | AA20: 10 | AB20: 1142 | AC20: 1 | AD20: 4605 | AE20: 0 | AH20: 584150 | AI20: 40 | AJ20: 882 | AK20: 6 | AL20: 52479 | AM20: 4 | AN20: 8931 | AO20: 0 | AP20: 10591 | AQ20: 0 | AR20: 14624 | AS20: 0 | AT20: 19369 | AU20: 0 | AV20: 20680 | AW20: 0 | AX20: 13872 | AY20: 0 | AZ20: 6225 | BA20: 0 | BB20: 26619 | BC20: 3 | BD20: 1115 | BE20: 0 | BF20: 4378 | BG20: 0 | BH20: 3636 | BI20: 0 | BJ20: 0 | BK20: 40 | BL20: 604650 | BM20: 40 | BN20: 776 | BO20: 1 | BP20: 785060 | BQ20: 50 | BR20: 8084 | BS20: 6 | BT20: 10 | BU20: 90 | BV20: 4 | BW20: 122 | BX20: 15128.058 | BZ20: 0 | CA20: 207163 | CB20: 7 | CC20: 39.97 | CD20: 46 | CE20: 4956.5 | CF20: 45 | CG20: 4848.75 | CH20: 49 | CI20: 5279.75 | CJ20: 15085 | CK20: 215.5 | CM20: 34808 | CN20: 4 | CO20: 9.76 | CP20: 34300 | CQ20: 0 | CR20: 0 | CS20: 10235.6 | CT20: 0 | CU20: 0 | CV20: 832313 | CW20: 0 | CX20: 0 | CY20: 6190 | CZ20: 3 | DA20: 7.17 | DB20: 7420 | DC20: 0 | DD20: 0 | DE20: 4298 | DF20: 8 | DG20: 3 | DH20: 1855.9 | DI20: 0 | DJ20: 0 | DK20: 5081.7 | DL20: 0 | DM20: 0 | DN20: 4454.7 | DO20: 0 | DP20: 0 | DQ20: 5089.6 | DR20: 0 | DS20: 0 | DT20: 5135.6 | DU20: 0 | DV20: 0 | DW20: 12871 | DX20: 0 | DY20: 62789 | DZ20: 0 | EA20: 15588 | EB20: 0 | EC20: 24679 | ED20: 0 | EE20: 2 | EF20: 6 | EG20: 0.015
A21: 44426 | B21: 7482238 | C21: 5707 | D21: 6672286 | E21: 5390 | F21: 0.94445418 | G21: 368 | H21: 342 | I21: 288064 | J21: 0 | K21: 776 | L21: 0 | M21: 633954 | N21: 0 | O21: 993 | P21: 0 | Q21: 2561122 | R21: 132 | S21: 2192890 | T21: 134 | U21: 118551 | V21: 30 | W21: 50 | X21: 152641 | Y21: 271 | Z21: 40689 | AA21: 10 | AB21: 1142 | AC21: 0 | AD21: 4605 | AE21: 0 | AH21: 584180 | AI21: 30 | AJ21: 884 | AK21: 2 | AL21: 52492 | AM21: 13 | AN21: 8931 | AO21: 0 | AP21: 10591 | AQ21: 0 | AR21: 14624 | AS21: 0 | AT21: 19369 | AU21: 0 | AV21: 20680 | AW21: 0 | AX21: 13872 | AY21: 0 | AZ21: 6225 | BA21: 0 | BB21: 26621 | BC21: 2 | BD21: 1115 | BE21: 0 | BF21: 4378 | BG21: 0 | BH21: 3636 | BI21: 0 | BJ21: 0 | BK21: 30 | BL21: 604710 | BM21: 60 | BN21: 778 | BO21: 2 | BP21: 785110 | BQ21: 50 | BR21: 8092 | BS21: 8 | BT21: 20 | BU21: 110 | BV21: 13 | BW21: 122 | BX21: 15128.058 | BZ21: 0 | CA21: 207196 | CB21: 33 | CC21: 188.43 | CD21: 46 | CE21: 4956.5 | CF21: 45 | CG21: 4848.75 | CH21: 49 | CI21: 5279.75 | CJ21: 15085 | CK21: 0 | CM21: 34812 | CN21: 4 | CO21: 9.76 | CP21: 34300 | CQ21: 0 | CR21: 0 | CS21: 10235.6 | CT21: 0 | CU21: 0 | CV21: 832313 | CW21: 0 | CX21: 0 | CY21: 6194 | CZ21: 4 | DA21: 9.56 | DB21: 7420 | DC21: 0 | DD21: 0 | DE21: 4301 | DF21: 3 | DG21: 0 | DH21: 1855.9 | DI21: 0 | DJ21: 0 | DK21: 5081.7 | DL21: 0 | DM21: 0 | DN21: 4454.7 | DO21: 0 | DP21: 0 | DQ21: 5089.6 | DR21: 0 | DS21: 0 | DT21: 5135.6 | DU21: 0 | DV21: 0 | DW21: 12871 | DX21: 0 | DY21: 62789 | DZ21: 0 | EA21: 15588 | EB21: 0 | EC21: 24679 | ED21: 0 | EE21: 2 | EF21: 6 | EG21: 0.015
