Workbook

Sheet TOTAL
A1: Site Name | B1: Day | C1: Month | D1: Year | E1: Total Electricity Kwh | F1: Electricity Tariff ($/Kwh) | G1: Water Utility Supply (m3) m3 | H1: Water Utility Supply (m3) $/m3 | I1: Room Nights | J1: Total Guests | K1: Food Covers
A2: Koh Samui | B2: 1 | C2: 8 | D2: 2021 | E2: =Electricity!E7 -> 6256.28 | F2: =Electricity!I7/Electricity!E7 -> 2.6037006 | G2: =Water!AW9 -> 80 | H2: 60 | I2: =Electricity!L7 -> 2 | J2: =Electricity!M7 -> 17 | K2: =Electricity!N7 -> 49
A3: Koh Samui | B3: =B2+1 -> 2 | C3: 8 | D3: 2021 | E3: =Electricity!E8 -> 6003.19 | F3: =Electricity!I8/Electricity!E8 -> 3.5927765 | G3: =Water!AW10 -> 49 | H3: 60 | I3: =Electricity!L8 -> 1 | J3: =Electricity!M8 -> 7 | K3: =Electricity!N8 -> 29
A4: Koh Samui | B4: =B3+1 -> 3 | C4: 8 | D4: 2021 | E4: =Electricity!E9 -> 5941.71 | F4: =Electricity!I9/Electricity!E9 -> 3.6075305 | G4: =Water!AW11 -> 26 | H4: 60 | I4: =Electricity!L9 -> 1 | J4: =Electricity!M9 -> 7 | K4: =Electricity!N9 -> 13
A5: Koh Samui | B5: =B4+1 -> 4 | C5: 8 | D5: 2021 | E5: =Electricity!E10 -> 5851.83 | F5: =Electricity!I10/Electricity!E10 -> 3.610057 | G5: =Water!AW12 -> 16 | H5: 60 | I5: =Electricity!L10 -> 2 | J5: =Electricity!M10 -> 8 | K5: =Electricity!N10 -> 28
A6: Koh Samui | B6: =B5+1 -> 5 | C6: 8 | D6: 2021 | E6: =Electricity!E11 -> 5452.71 | F6: =Electricity!I11/Electricity!E11 -> 3.5369367 | G6: =Water!AW13 -> 19 | H6: 60 | I6: =Electricity!L11 -> 2 | J6: =Electricity!M11 -> 9 | K6: =Electricity!N11 -> 14
A7: Koh Samui | B7: =B6+1 -> 6 | C7: 8 | D7: 2021 | E7: =Electricity!E12 -> 6024.6 | F7: =Electricity!I12/Electricity!E12 -> 3.6131677 | G7: =Water!AW14 -> 79 | H7: 60 | I7: =Electricity!L12 -> 1 | J7: =Electricity!M12 -> 7 | K7: =Electricity!N12 -> 17
A8: Koh Samui | B8: =B7+1 -> 7 | C8: 8 | D8: 2021 | E8: =Electricity!E13 -> 6388.37 | F8: =Electricity!I13/Electricity!E13 -> 2.6037002 | G8: =Water!AW15 -> 57 | H8: 60 | I8: =Electricity!L13 -> 2 | J8: =Electricity!M13 -> 14 | K8: =Electricity!N13 -> 3
A9: Koh Samui | B9: =B8+1 -> 8 | C9: 8 | D9: 2021 | E9: =Electricity!E14 -> 6579.86 | F9: =Electricity!I14/Electricity!E14 -> 2.6036998 | G9: =Water!AW16 -> 81 | H9: 60 | I9: =Electricity!L14 -> 4 | J9: =Electricity!M14 -> 17 | K9: =Electricity!N14 -> 36
A10: Koh Samui | B10: =B9+1 -> 9 | C10: 8 | D10: 2021 | E10: =Electricity!E15 -> 6719.95 | F10: =Electricity!I15/Electricity!E15 -> 3.6005595 | G10: =Water!AW17 -> 70 | H10: 60 | I10: =Electricity!L15 -> 4 | J10: =Electricity!M15 -> 18 | K10: =Electricity!N15 -> 28
A11: Koh Samui | B11: =B10+1 -> 10 | C11: 8 | D11: 2021 | E11: =Electricity!E16 -> 6595.19 | F11: =Electricity!I16/Electricity!E16 -> 3.5854752 | G11: =Water!AW18 -> 49 | H11: 60 | I11: =Electricity!L16 -> 4 | J11: =Electricity!M16 -> 14 | K11: =Electricity!N16 -> 26
A12: Koh Samui | B12: =B11+1 -> 11 | C12: 8 | D12: 2021 | E12: =Electricity!E17 -> 6533.23 | F12: =Electricity!I17/Electricity!E17 -> 3.6114923 | G12: =Water!AW19 -> 48 | H12: 60 | I12: =Electricity!L17 -> 4 | J12: =Electricity!M17 -> 17 | K12: =Electricity!N17 -> 20
A13: Koh Samui | B13: =B12+1 -> 12 | C13: 8 | D13: 2021 | E13: =Electricity!E18 -> 6681.19 | F13: =Electricity!I18/Electricity!E18 -> 2.6036993 | G13: =Water!AW20 -> 28 | H13: 60 | I13: =Electricity!L18 -> 2 | J13: =Electricity!M18 -> 11 | K13: =Electricity!N18 -> 36
A14: Koh Samui | B14: =B13+1 -> 13 | C14: 8 | D14: 2021 | E14: =Electricity!E19 -> 6770.76 | F14: =Electricity!I19/Electricity!E19 -> 3.637571 | G14: =Water!AW21 -> 112 | H14: 60 | I14: =Electricity!L19 -> 5 | J14: =Electricity!M19 -> 14 | K14: =Electricity!N19 -> 25
... A16: Koh Samui | B16: =B15+1 -> 15 | C16: 8 | D16: 2021 | E16: =Electricity!E21 -> 5822.38 | F16: =Electricity!I21/Electricity!E21 -> 2.6036999 | G16: =Water!AW23 -> 30 | H16: 60 | I16: =Electricity!L21 -> 4 | J16: =Electricity!M21 -> 18 | K16: =Electricity!N21 -> 37
A17: Koh Samui | B17: =B16+1 -> 16 | C17: 8 | D17: 2021 | E17: =Electricity!E22 -> 5773.56 | F17: =Electricity!I22/Electricity!E22 -> 3.6103565 | G17: =Water!AW24 -> 28 | H17: 60 | I17: =Electricity!L22 -> 3 | J17: =Electricity!M21 -> 18 | K17: =Electricity!N22 -> 24
A18: Koh Samui | B18: =B17+1 -> 17 | C18: 8 | D18: 2021 | E18: =Electricity!E23 -> 5975.91 | F18: =Electricity!I23/Electricity!E23 -> 3.6221647 | G18: =Water!AW25 -> 24 | H18: 60 | I18: =Electricity!L23 -> 3 | J18: =Electricity!M23 -> 11 | K18: =Electricity!N23 -> 24
A19: Koh Samui | B19: =B18+1 -> 18 | C19: 8 | D19: 2021 | E19: =Electricity!E24 -> 6438.47 | F19: =Electricity!I24/Electricity!E24 -> 3.6612798 | G19: =Water!AW26 -> 31 | H19: 60 | I19: =Electricity!L24 -> 3 | J19: =Electricity!M24 -> 14 | K19: =Electricity!N24 -> 15
A20: Koh Samui | B20: =B19+1 -> 19 | C20: 8 | D20: 2021 | E20: =Electricity!E25 -> 6152.4 | F20: =Electricity!I25/Electricity!E25 -> 3.61575 | G20: =Water!AW27 -> 47 | H20: 60 | I20: =Electricity!L25 -> 2 | J20: =Electricity!M25 -> 13 | K20: =Electricity!N25 -> 27
A21: Koh Samui | B21: =B20+1 -> 20 | C21: 8 | D21: 2021 | E21: =Electricity!E26 -> 6528.79 | F21: =Electricity!I26/Electricity!E26 -> 3.6399394 | G21: =Water!AW28 -> 67 | H21: 60 | I21: =Electricity!L26 -> 5 | J21: =Electricity!M26 -> 29 | K21: =Electricity!N26 -> 46
A22: Koh Samui | B22: =B21+1 -> 21 | C22: 8 | D22: 2021 | E22: =Electricity!E27 -> 6432.16 | F22: =Electricity!I27/Electricity!E27 -> 2.6036992 | G22: =Water!AW29 -> 50 | H22: 60 | I22: =Electricity!L27 -> 5 | J22: =Electricity!M27 -> 23 | K22: =Electricity!N27 -> 56
A23: Koh Samui | B23: =B22+1 -> 22 | C23: 8 | D23: 2021 | E23: =Electricity!E28 -> 6731.25 | F23: =Electricity!I28/Electricity!E28 -> 2.6037006 | G23: =Water!AW30 -> 71 | H23: 60 | I23: =Electricity!L28 -> 6 | J23: =Electricity!M28 -> 25 | K23: =Electricity!N28 -> 55
A24: Koh Samui | B24: =B23+1 -> 23 | C24: 8 | D24: 2021 | E24: =Electricity!E29 -> 6360.39 | F24: =Electricity!I29/Electricity!E29 -> 3.6338684 | G24: =Water!AW31 -> 59 | H24: 60 | I24: =Electricity!L29 -> 0 | J24: =Electricity!M29 -> 13 | K24: =Electricity!N29 -> 29
A25: Koh Samui | B25: =B24+1 -> 24 | C25: 8 | D25: 2021 | E25: =Electricity!E30 -> 6292.37 | F25: =Electricity!I30/Electricity!E30 -> 3.613087 | G25: =Water!AW32 -> 44 | H25: 60 | I25: =Electricity!L30 -> 0 | J25: =Electricity!M30 -> 7 | K25: =Electricity!N30 -> 19
A26: Koh Samui | B26: =B25+1 -> 25 | C26: 8 | D26: 2021 | E26: =Electricity!E31 -> 5908.67 | F26: =Electricity!I31/Electricity!E31 -> 3.6023251 | G26: =Water!AW33 -> 40 | H26: 60 | I26: =Electricity!L31 -> 1 | J26: =Electricity!M31 -> 8 | K26: =Electricity!N31 -> 17
A27: Koh Samui | B27: =B26+1 -> 26 | C27: 8 | D27: 2021 | E27: =Electricity!E32 -> 5623.02 | F27: =Electricity!I32/Electricity!E32 -> 3.6230833 | G27: =Water!AW34 -> 17 | H27: 60 | I27: =Electricity!L32 -> 1 | J27: =Electricity!M32 -> 8 | K27: =Electricity!N32 -> 14
A28: Koh Samui | B28: =B27+1 -> 27 | C28: 8 | D28: 2021 | E28: =Electricity!E33 -> 5895 | F28: =Electricity!I33/Electricity!E33 -> 3.6205259 | G28: =Water!AW35 -> 39 | H28: 60 | I28: =Electricity!L33 -> 2 | J28: =Electricity!M33 -> 7 | K28: =Electricity!N33 -> 15
A29: Koh Samui | B29: =B28+1 -> 28 | C29: 8 | D29: 2021 | E29: =Electricity!E34 -> 5898.71 | F29: =Electricity!I34/Electricity!E34 -> 2.6037 | G29: =Water!AW36 -> 32 | H29: 60 | I29: =Electricity!L34 -> 1 | J29: =Electricity!M34 -> 5 | K29: =Electricity!N34 -> 9
... A32: Koh Samui | B32: =B31+1 -> 31 | C32: 8 | D32: 2021 | E32: =Electricity!E37 -> 0 | F32: =Electricity!I37/Electricity!E37 -> #DIV/0! | G32: =Water!AW39 -> 43 | H32: 60 | I32: =Electricity!L37 -> 1 | J32: =Electricity!M37 -> 5 | K32: =Electricity!N37 -> 3

Sheet Electricity
A2: Power Distribution log Sheet
A3: 44409 | J3: Villa
A4: Date | B4: Kwh A | C4: Kwh B | D4: Kwh C | E4: Total | F4: Cost A | G4: Cost B | H4: Cost C | I4: Cost/Day | J4: FT.Cost | L4: Room Nights | M4: Total Guests | N4: Food Covers
F5: On Peak | G5: Off Peak | H5: Holiday
E6: Kwh | F6: 4.1839 | G6: 2.6037 | H6: 2.06037 | J6: -0.1243
A7: 1 | D7: 6256.28 | E7: 6256.28 | F7: - | G7: - | H7: 16289.48 | I7: 16289.48 | J7: -777.66 | L7: 2 | M7: 17 | N7: 49
A8: 2 | B8: 3757.51 | C8: 2245.68 | E8: 6003.19 | F8: 15721.05 | G8: 5847.08 | H8: - | I8: 21568.12 | J8: -746.2 | L8: 1 | M8: 7 | N8: 29
A9: 3 | B9: 3774.5 | C9: 2167.21 | E9: 5941.71 | F9: 15792.13 | G9: 5642.76 | H9: - | I9: 21434.9 | J9: -738.55 | L9: 1 | M9: 7 | N9: 13
A10: 4 | B10: 3726.76 | C10: 2125.07 | E10: 5851.83 | F10: 15592.39 | G10: 5533.04 | H10: - | I10: 21125.44 | J10: -727.38 | L10: 2 | M10: 8 | N10: 28
A11: 5 | B11: 3220.27 | C11: 2232.44 | E11: 5452.71 | F11: 13473.29 | G11: 5812.6 | H11: - | I11: 19285.89 | J11: -677.77 | L11: 2 | M11: 9 | N11: 14
A12: 6 | B12: 3848.65 | C12: 2175.95 | E12: 6024.6 | F12: 16102.37 | G12: 5665.52 | H12: - | I12: 21767.89 | J12: -748.86 | L12: 1 | M12: 7 | N12: 17
A13: 7 | D13: 6388.37 | E13: 6388.37 | F13: - | G13: - | H13: 16633.4 | I13: 16633.4 | J13: -794.07 | L13: 2 | M13: 14 | N13: 3
A14: 8 | D14: 6579.86 | E14: 6579.86 | F14: - | G14: - | H14: 17131.98 | I14: 17131.98 | J14: -817.88 | L14: 4 | M14: 17 | N14: 36
A15: 9 | B15: 4239.24 | C15: 2480.71 | E15: 6719.95 | F15: 17736.56 | G15: 6459.02 | H15: - | I15: 24195.58 | J15: -835.29 | L15: 4 | M15: 18 | N15: 28
A16: 10 | B16: 4097.58 | C16: 2497.61 | E16: 6595.19 | F16: 17143.86 | G16: 6503.03 | H16: - | I16: 23646.89 | J16: -819.78 | L16: 4 | M16: 14 | N16: 26
A17: 11 | B17: 4166.65 | C17: 2366.58 | E17: 6533.23 | F17: 17432.85 | G17: 6161.86 | H17: - | I17: 23594.71 | J17: -812.08 | L17: 4 | M17: 17 | N17: 20
A18: 12 | D18: 6681.19 | E18: 6681.19 | F18: - | G18: - | H18: 17395.81 | I18: 17395.81 | J18: -830.47 | L18: 2 | M18: 11 | N18: 36
A19: 13 | B19: 4429.88 | C19: 2340.88 | E19: 6770.76 | F19: 18534.17 | G19: 6094.95 | H19: - | I19: 24629.12 | J19: -841.61 | L19: 5 | M19: 14 | N19: 25
A20: 14 | D20: 6623.27 | E20: 6623.27 | F20: - | G20: - | H20: 17245.01 | I20: 17245.01 | J20: -823.27 | L20: 5 | M20: 14 | N20: 28
A21: 15 | D21: 5822.38 | E21: 5822.38 | F21: - | G21: - | H21: 15159.73 | I21: 15159.73 | J21: -723.72 | L21: 4 | M21: 18 | N21: 37
A22: 16 | B22: 3678.01 | C22: 2095.55 | E22: 5773.56 | F22: 15388.43 | G22: 5456.18 | H22: - | I22: 20844.61 | J22: -717.65 | L22: 3 | M22: 11 | N22: 24
A23: 17 | B23: 3851.57 | C23: 2124.34 | E23: 5975.91 | F23: 16114.58 | G23: 5531.14 | H23: - | I23: 21645.73 | J23: -742.81 | L23: 3 | M23: 11 | N23: 24
A24: 18 | B24: 4309.07 | C24: 2129.4 | E24: 6438.47 | F24: 18028.72 | G24: 5544.32 | H24: - | I24: 23573.04 | J24: -800.3 | L24: 3 | M24: 14 | N24: 15
A25: 19 | B25: 3940.35 | C25: 2212.05 | E25: 6152.4 | F25: 16486.03 | G25: 5759.51 | H25: - | I25: 22245.54 | J25: -764.74 | L25: 2 | M25: 13 | N25: 27
A26: 20 | B26: 4281.35 | C26: 2247.44 | E26: 6528.79 | F26: 17912.74 | G26: 5851.66 | H26: - | I26: 23764.4 | J26: -811.53 | L26: 5 | M26: 29 | N26: 46
A27: 21 | D27: 6432.16 | E27: 6432.16 | F27: - | G27: - | H27: 16747.41 | I27: 16747.41 | J27: -799.52 | L27: 5 | M27: 23 | N27: 56
A28: 22 | D28: 6731.25 | E28: 6731.25 | F28: - | G28: - | H28: 17526.16 | I28: 17526.16 | J28: -836.69 | L28: 6 | M28: 25 | N28: 55
A29: 23 | B29: 4146.48 | C29: 2213.91 | E29: 6360.39 | F29: 17348.46 | G29: 5764.36 | H29: - | I29: 23112.82 | J29: -790.6 | L29: 0 | M29: 13 | N29: 29
A30: 24 | B30: 4019.39 | C30: 2272.98 | E30: 6292.37 | F30: 16816.73 | G30: 5918.16 | H30: - | I30: 22734.88 | J30: -782.14 | L30: 0 | M30: 7 | N30: 19
A31: 25 | B31: 3734.05 | C31: 2174.62 | E31: 5908.67 | F31: 15622.89 | G31: 5662.06 | H31: - | I31: 21284.95 | J31: -734.45 | L31: 1 | M31: 8 | N31: 17
A32: 26 | B32: 3627.4 | C32: 1995.62 | E32: 5623.02 | F32: 15176.68 | G32: 5196 | H32: - | I32: 20372.67 | J32: -698.94 | L32: 1 | M32: 8 | N32: 14
A33: 27 | B33: 3793.31 | C33: 2101.69 | E33: =+B33+C33+D33 -> 5895 | F33: =+B33*4.1839 -> 15870.83 | G33: =+C33*2.6037 -> 5472.1703 | H33: =+D33*2.6037 -> 0 | I33: =F33+G33+H33 -> 21343 | J33: =+E33*-0.1243 -> -732.7485 | L33: 2 | M33: 7 | N33: 15
A34: 28 | D34: 5898.71 | E34: =+B34+C34+D34 -> 5898.71 | F34: =+B34*4.1839 -> 0 | G34: =+C34*2.6037 -> 0 | H34: =+D34*2.6037 -> 15358.471 | I34: =F34+G34+H34 -> 15358.471 | J34: =+E34*-0.1243 -> -733.20965 | L34: 1 | M34: 5 | N34: 9
A35: 29 | D35: 6159.96 | E35: =+B35+C35+D35 -> 6159.96 | F35: =+B35*4.1839 -> 0 | G35: =+C35*2.6037 -> 0 | H35: =+D35*2.6037 -> 16038.688 | I35: =F35+G35+H35 -> 16038.688 | J35: =+E35*-0.1243 -> -765.68303 | L35: 1 | M35: 5 | N35: 35
A36: 30 | E36: =+B36+C36+D36 -> 0 | F36: =+B36*4.1839 -> 0 | G36: =+C36*2.6037 -> 0 | H36: =+D36*2.6037 -> 0 | I36: =F36+G36+H36 -> 0 | J36: =+E36*-0.1243 -> 0 | L36: 1 | M36: 5 | N36: 8
A37: 31 | E37: =+B37+C37+D37 -> 0 | F37: =+B37*4.1839 -> 0 | G37: =+C37*2.6037 -> 0 | H37: =+D37*2.6037 -> 0 | I37: =F37+G37+H37 -> 0 | J37: =+E37*-0.1243 -> 0 | L37: 1 | M37: 5 | N37: 3
A39: Total | B39: =SUM(B7:B37) -> 74642.02 | C39: =SUM(C7:C37) -> 42199.73 | D39: =SUM(D7:D37) -> 63573.43 | E39: =SUM(E7:E37) -> 180415.18 | F39: =SUM(F7:F37) -> 312294.76 | G39: =SUM(G7:G37) -> 109875.42 | H39: =SUM(H7:H37) -> 165526.14 | I39: =SUM(I7:I37) -> 587696.32 | J39: =SUM(J7:J37) -> -22425.601
G40: Peak Demand | I40: =A42*132.93 -> 0
A41: Peak Demand | C41: Date | E41: Time | G41: Service | I41: 312.24
E42: 18.3 | G42: Electric Cost | I42: =SUM(I39:I41) -> 588008.56
...

Sheet Water
D3: Engineering Department
D4: Water Meter Log Sheet Villas Zone | I4: Every Sunday HK Drain all Villas & PA
D6: 44409 | AG6: **new** | AU6: old name coco rum
A7: Date | B7: Main Kit | C7: Unit | D7: Arrival sala | E7: Unit | F7: Soi 100 | G7: Unit | H7: Soi 200 | I7: Unit | J7: Soi 300 | K7: Unit | L7: Soi 400 | M7: Unit | N7: Soi 500 | O7: Unit | P7: Soi 600 | Q7: Unit | R7: Soi 700 | S7: Unit | T7: Soi 800 3 room | U7: Unit | V7: soi 900-901 | W7: Unit | X7: soi 902-907 | Y7: Unit | Z7: soi 908-910 Water supply from Soi 500 | AA7: Unit | AB7: All Soi Consumption M3 | AC7: Pla Pla | AD7: Unit | AE7: Pla Pla2 | AF7: Unit | AG7: (Meter Tag Coco rum ) under CoCoRum for the Bar & MP | AH7: Unit | AI7: Spa | AJ7: Unit | AK7: Beach House & kid club | AL7: Unit | AM7: GM Executive Office | AN7: Unit | AO7: Library Toilets | AP7: Unit | AQ7: Fitness | AR7: Unit | AS7: Retail Shop Toielts | AT7: Unit | AU7: Main Pool | AV7: Unit | AW7: Total Villa Consumption | AX7: Occ%
A8: 31
A9: 1 | B9: 27525 | C9: 1 | D9: 12463 | E9: 1 | F9: 32381 | G9: 2 | H9: 25545 | I9: 3 | J9: 21257 | K9: - | L9: 15666 | M9: 1 | N9: 14218 | O9: 1 | P9: 20924 | Q9: 1 | R9: 25159 | S9: 4 | T9: 1157 | U9: 2 | V9: 3227 | W9: - | X9: 30538 | Y9: 2 | Z9: 12856 | AA9: - | AB9: 14 | AC9: 13039 | AD9: 56 | AE9: 4877 | AF9: - | AG9: 4877 | AH9: - | AI9: 39170 | AJ9: 1 | AK9: 4530 | AL9: 3 | AM9: 1242 | AN9: 2 | AO9: 1470 | AP9: - | AQ9: 525 | AR9: - | AS9: 1374 | AT9: - | AU9: 9640 | AV9: - | AW9: 80 | AX9: Zero | AY9: IXORA
A10: 2 | B10: 27526 | C10: 1 | D10: 12464 | E10: 1 | F10: 32383 | G10: 2 | H10: 25547 | I10: 2 | J10: 21258 | K10: 1 | L10: 15668 | M10: 2 | N10: 14219 | O10: 1 | P10: 20925 | Q10: 1 | R10: 25161 | S10: 2 | T10: 1161 | U10: 4 | V10: 3227 | W10: - | X10: 30539 | Y10: 1 | Z10: 12856 | AA10: - | AB10: 14 | AC10: 13049 | AD10: 10 | AE10: 4881 | AF10: 4 | AG10: 4881 | AH10: 4 | AI10: 39171 | AJ10: 1 | AK10: 4539 | AL10: 9 | AM10: 1245 | AN10: 3 | AO10: 1470 | AP10: - | AQ10: 525 | AR10: - | AS10: 1374 | AT10: - | AU10: 9644 | AV10: 4 | AW10: 49 | AX10: Zero | AY10: IXORA
A11: 3 | B11: 27527 | C11: 1 | D11: 12464 | E11: - | F11: 32383 | G11: - | H11: 25549 | I11: 2 | J11: 21258 | K11: - | L11: 15668 | M11: - | N11: 14222 | O11: 3 | P11: 20926 | Q11: 1 | R11: 25162 | S11: 1 | T11: 1169 | U11: 8 | V11: 3227 | W11: - | X11: 30540 | Y11: 1 | Z11: 12856 | AA11: - | AB11: 16 | AC11: 13054 | AD11: 5 | AE11: 4881 | AF11: - | AG11: 4881 | AH11: - | AI11: 39172 | AJ11: 1 | AK11: 4540 | AL11: 1 | AM11: 1246 | AN11: 1 | AO11: 1470 | AP11: - | AQ11: 525 | AR11: - | AS11: 1374 | AT11: - | AU11: 9645 | AV11: 1 | AW11: 26 | AX11: Zero | AY11: IXORA
A12: 4 | B12: 27529 | C12: 2 | D12: 12465 | E12: 1 | F12: 32384 | G12: 1 | H12: 25551 | I12: 2 | J12: 21258 | K12: - | L12: 15669 | M12: 1 | N12: 14222 | O12: - | P12: 20927 | R12: 25163 | S12: 1 | T12: 1169 | U12: - | V12: 3228 | W12: 1 | X12: 30540 | Y12: - | Z12: 12856 | AA12: - | AB12: 5 | AC12: 13058 | AD12: 4 | AE12: 4881 | AF12: - | AG12: 4881 | AH12: - | AI12: 39174 | AJ12: 2 | AK12: 4540 | AL12: - | AM12: 1247 | AN12: 1 | AO12: 1470 | AP12: - | AQ12: 525 | AR12: - | AS12: 1374 | AT12: - | AU12: 9645 | AV12: - | AW12: 16 | AX12: Zero | AY12: IXORA
A13: 5 | B13: 27529 | C13: =B13-B12 -> 0 | D13: 12465 | E13: =D13-D12 -> 0 | F13: 32384 | G13: =F13-F12 -> 0 | H13: 25551 | I13: 6 | J13: 21258 | K13: =J13-J12 -> 0 | L13: 15669 | M13: =L13-L12 -> 0 | N13: 14222 | O13: =N13-N12 -> 0 | P13: 20927 | Q13: =P13-P12 -> 0 | R13: 25163 | S13: =R13-R12 -> 0 | T13: 1169 | U13: 3 | V13: 3228 | W13: =V13-V12 -> 0 | X13: 30540 | Y13: =X13-X12 -> 0 | Z13: 12856 | AA13: =Z13-Z12 -> 0 | AB13: =I13+K13+M13+O13+Q13+S13+U13+W13+Y13+AA13 -> 9 | AC13: 13058 | AD13: 3 | AE13: 4881 | AF13: 3 | AG13: 39174 | AH13: 1 | AI13: 39174 | AJ13: 1 | AK13: 4540 | AL13: =AK13-AK12 -> 0 | AM13: 1247 | AN13: =AM13-AM12 -> 0 | AO13: 1470 | AP13: =AO13-AO12 -> 0 | AQ13: 525 | AR13: =AQ13-AQ12 -> 0 | AS13: 1374 | AT13: =AS13-AS12 -> 0 | AU13: 9654 | AV13: 3 | AW13: 19 | AX13: Zero | AY13: IXORA
A14: 6 | B14: 27530 | C14: 1 | D14: 12467 | E14: 2 | F14: 32389 | G14: 5 | H14: 25565 | I14: 14 | J14: 21260 | K14: 2 | L14: 15673 | M14: 4 | N14: 14223 | O14: 1 | P14: 20928 | Q14: 1 | R14: 25164 | S14: 1 | T14: 1174 | U14: 5 | V14: 3228 | W14: - | X14: 30547 | Y14: 7 | Z14: 12857 | AA14: 1 | AB14: 36 | AC14: 13078 | AD14: 20 | AE14: 4891 | AF14: 10 | AG14: 4891 | AH14: 10 | AI14: 39176 | AJ14: 2 | AK14: 4541 | AL14: 1 | AM14: 1249 | AN14: 2 | AO14: 1470 | AP14: - | AQ14: 525 | AR14: - | AS14: 1374 | AT14: - | AU14: 9656 | AV14: - | AW14: 79 | AX14: Zero | AY14: IXORA
A15: 7 | B15: 27531 | C15: 1 | D15: 12470 | E15: 3 | F15: 32393 | G15: 4 | H15: 25568 | I15: 3 | J15: 21262 | K15: 2 | L15: 15675 | M15: 2 | N15: 14227 | O15: 4 | P15: 20928 | Q15: - | R15: 25167 | S15: 3 | T15: 1176 | U15: 2 | V15: 3229 | W15: 1 | X15: 30549 | Y15: 2 | Z15: 12858 | AA15: 1 | AB15: 20 | AC15: 13093 | AD15: 15 | AE15: 4900 | AF15: 9 | AG15: 4900 | AH15: 9 | AI15: 39180 | AJ15: 4 | AK15: 4541 | AL15: - | AM15: 1250 | AN15: 1 | AO15: 1470 | AP15: - | AQ15: 525 | AR15: - | AS15: 1374 | AT15: - | AU15: 9667 | AV15: - | AW15: 57 | AX15: Zero | AY15: IXORA
A16: 8 | B16: 27532 | C16: 1 | D16: 12473 | E16: 3 | F16: 32397 | G16: 4 | H16: 25574 | I16: 6 | J16: 21262 | K16: - | L16: 15708 | M16: 33 | N16: 14232 | O16: 5 | P16: 20928 | Q16: - | R16: 25169 | S16: 2 | T16: 1176 | U16: - | V16: 3229 | W16: - | X16: 30552 | Y16: 3 | Z16: 12858 | AA16: - | AB16: 49 | AC16: 13103 | AD16: 10 | AE16: 4906 | AF16: 6 | AG16: 4906 | AH16: 6 | AI16: 39182 | AJ16: 2 | AK16: 4541 | AL16: - | AM16: 1255 | AN16: 5 | AO16: 1471 | AP16: 1 | AQ16: 525 | AR16: - | AS16: 1374 | AT16: - | AU16: 9673 | AV16: - | AW16: 81 | AX16: Zero | AY16: IXORA
A17: 9 | B17: 27533 | C17: 1 | D17: 12476 | E17: 3 | F17: 32403 | G17: 6 | H17: 25578 | I17: 4 | J17: 21263 | K17: 1 | L17: 15714 | M17: 6 | N17: 14241 | O17: 9 | P17: 20930 | Q17: 2 | R17: 25170 | S17: 1 | T17: 1176 | U17: - | V17: 3229 | W17: - | X17: 30556 | Y17: 4 | Z17: 12858 | AA17: - | AB17: 27 | AC17: 13119 | AD17: 16 | AE17: 4912 | AF17: 6 | AG17: 4912 | AH17: 6 | AI17: 39191 | AJ17: 9 | AK17: 4542 | AL17: 1 | AM17: 1256 | AN17: 1 | AO17: 1471 | AP17: - | AQ17: 525 | AR17: - | AS17: 1374 | AT17: - | AU17: 9681 | AV17: - | AW17: 70 | AX17: Zero | AY17: IXORA
A18: 10 | B18: 27534 | C18: 1 | D18: 12479 | E18: 3 | F18: 32409 | G18: 6 | H18: 25582 | I18: 4 | J18: 21265 | K18: 2 | L18: 15717 | M18: 3 | N18: 14250 | O18: 9 | P18: 20930 | Q18: - | R18: 25170 | S18: - | T18: 1177 | U18: 1 | V18: 3229 | W18: - | X18: 30557 | Y18: 1 | Z18: 12858 | AA18: - | AB18: 20 | AC18: 13126 | AD18: 7 | AE18: 4913 | AF18: 1 | AG18: 4913 | AH18: 1 | AI18: 39200 | AJ18: 9 | AK18: 4542 | AL18: - | AM18: 1258 | AN18: 2 | AO18: 1471 | AP18: - | AQ18: 525 | AR18: - | AS18: 1374 | AT18: - | AU18: 9682 | AV18: - | AW18: 49 | AX18: Zero | AY18: IXORA
A19: 11 | B19: 27535 | C19: 1 | D19: 12483 | E19: 4 | F19: 32415 | G19: 6 | H19: 25585 | I19: 3 | J19: 21267 | K19: 2 | L19: 15723 | M19: 6 | N19: 14252 | O19: 2 | P19: 20932 | Q19: 2 | R19: 25174 | S19: 4 | T19: 1179 | U19: 2 | V19: 3229 | W19: - | X19: 30559 | Y19: 2 | Z19: 12858 | AA19: - | AB19: 23 | AC19: 13132 | AD19: 6 | AE19: 4913 | AF19: - | AG19: 4913 | AH19: - | AI19: 39206 | AJ19: 6 | AK19: 4543 | AL19: 1 | AM19: 1259 | AN19: 1 | AO19: 1471 | AP19: - | AQ19: 525 | AR19: - | AS19: 1374 | AT19: - | AU19: 9682 | AV19: - | AW19: 48 | AX19: Zero | AY19: IXORA
A20: 12 | B20: 27536 | C20: 1 | D20: 12485 | E20: 2 | F20: 32418 | G20: 3 | H20: 25588 | I20: 3 | J20: 21269 | K20: 2 | L20: 15726 | M20: 3 | N20: 14256 | O20: 4 | P20: 20932 | Q20: - | R20: 25174 | S20: - | T20: 1180 | U20: 1 | V20: 3229 | W20: - | X20: 30561 | Y20: 2 | Z20: 12858 | AA20: - | AB20: 15 | AC20: 13136 | AD20: 4 | AE20: 4913 | AF20: - | AG20: 4913 | AH20: - | AI20: 39208 | AJ20: 2 | AK20: 4543 | AL20: - | AM20: 1259 | AN20: - | AO20: 1471 | AP20: - | AQ20: 525 | AR20: - | AS20: 1374 | AT20: - | AU20: 9683 | AV20: 1 | AW20: 28 | AX20: Zero | AY20: IXORA
A21: 13 | B21: 27537 | C21: 1 | D21: 12486 | E21: 1 | F21: 32420 | G21: 2 | H21: 25593 | I21: 5 | J21: 21273 | K21: 4 | L21: 15731 | M21: 5 | N21: 14262 | O21: 6 | P21: 20933 | Q21: 1 | R21: 25177 | S21: 3 | T21: 1181 | U21: 1 | V21: 3229 | W21: - | X21: 30634 | Y21: 73 | Z21: 12858 | AA21: - | AB21: 98 | AC21: 13140 | AD21: 4 | AE21: 4913 | AF21: - | AG21: 4913 | AH21: - | AI21: 39209 | AJ21: 1 | AK21: 4544 | AL21: 1 | AM21: 1262 | AN21: 3 | AO21: 1471 | AP21: - | AQ21: 525 | AR21: - | AS21: 1375 | AT21: 1 | AU21: 9683 | AV21: - | AW21: 112 | AX21: Zero | AY21: IXORA
A22: 14 | B22: 27538 | C22: 1 | D22: 12490 | E22: 4 | F22: 32426 | G22: 6 | H22: 25598 | I22: 5 | J22: 21276 | K22: 3 | L22: 15733 | M22: 2 | N22: 14267 | O22: 5 | P22: 20936 | Q22: 3 | R22: 25182 | S22: 5 | T22: 1184 | U22: 3 | V22: 3230 | W22: 1 | X22: 30739 | Y22: 105 | Z22: 12858 | AA22: - | AB22: 132 | AC22: 13146 | AD22: 6 | AE22: 4913 | AF22: - | AG22: 4913 | AH22: - | AI22: 39215 | AJ22: 6 | AK22: 4545 | AL22: 1 | AM22: 1267 | AN22: 5 | AO22: 1471 | AP22: - | AQ22: 525 | AR22: - | AS22: 1375 | AT22: - | AU22: 9683 | AV22: - | AW22: 161 | AX22: Zero | AY22: IXORA
A23: 15 | B23: 27539 | C23: 1 | D23: 12492 | E23: 2 | F23: 32428 | G23: 2 | H23: 25599 | I23: 1 | J23: 21276 | K23: - | L23: 15736 | M23: 3 | N23: 14273 | O23: 6 | P23: 20936 | Q23: - | R23: 25186 | S23: 4 | T23: 1186 | U23: 2 | V23: 3230 | W23: - | X23: 30740 | Y23: 1 | Z23: 12859 | AA23: 1 | AB23: 18 | AC23: 13150 | AD23: 4 | AE23: 4913 | AF23: - | AG23: 4913 | AH23: - | AI23: 39216 | AJ23: 1 | AK23: 4546 | AL23: 1 | AM23: 1267 | AN23: - | AO23: 1471 | AP23: - | AQ23: 525 | AR23: - | AS23: 1375 | AT23: - | AU23: 9684 | AV23: 1 | AW23: 30 | AX23: Zero | AY23: IXORA
A24: 16 | B24: 27541 | C24: 2 | D24: 12493 | E24: 1 | F24: 32429 | G24: 1 | H24: 25600 | I24: 1 | J24: 21276 | K24: - | L24: 15738 | M24: 2 | N24: 14279 | O24: 6 | P24: 20937 | Q24: 1 | R24: 25187 | S24: 1 | T24: 1187 | U24: 1 | V24: 3231 | W24: 1 | X24: 30742 | Y24: 2 | Z24: 12859 | AA24: - | AB24: 15 | AC24: 13157 | AD24: 7 | AE24: 4913 | AF24: - | AG24: 4913 | AH24: - | AI24: 39217 | AJ24: 1 | AK24: 4547 | AL24: 1 | AM24: 1267 | AN24: - | AO24: 1471 | AP24: - | AQ24: 525 | AR24: - | AS24: 1375 | AT24: - | AU24: 9684 | AV24: - | AW24: 28 | AX24: Zero | AY24: IXORA
A25: 17 | B25: 27544 | C25: 3 | D25: 12493 | E25: - | F25: 32430 | G25: 1 | H25: 25602 | I25: 2 | J25: 21276 | K25: - | L25: 15740 | M25: 2 | N25: 14282 | O25: 3 | P25: 20938 | Q25: 1 | R25: 25187 | S25: - | T25: 1189 | U25: 2 | V25: 3231 | W25: - | X25: 30743 | Y25: 1 | Z25: 12859 | AA25: - | AB25: 11 | AC25: 13162 | AD25: 5 | AE25: 4913 | AF25: - | AG25: 4913 | AH25: - | AI25: 39218 | AJ25: 1 | AK25: 4548 | AL25: 1 | AM25: 1269 | AN25: 2 | AO25: 1471 | AP25: - | AQ25: 525 | AR25: - | AS25: 1375 | AT25: - | AU25: 9684 | AV25: - | AW25: 24 | AX25: Zero | AY25: IXORA
A26: 18 | B26: 27547 | C26: 3 | D26: 12494 | E26: 1 | F26: 32432 | G26: 2 | H26: 25603 | I26: 1 | J26: 21278 | K26: 2 | L26: 15742 | M26: 2 | N26: 14285 | O26: 3 | P26: 20939 | Q26: 1 | R26: 25188 | S26: 1 | T26: 1193 | U26: 4 | V26: 3231 | W26: - | X26: 30746 | Y26: 3 | Z26: 12859 | AA26: - | AB26: 17 | AC26: 13167 | AD26: 5 | AE26: 4913 | AF26: - | AG26: 4913 | AH26: - | AI26: 39219 | AJ26: 1 | AK26: 4549 | AL26: 1 | AM26: 1270 | AN26: 1 | AO26: 1471 | AP26: - | AQ26: 525 | AR26: - | AS26: 1375 | AT26: - | AU26: 9684 | AV26: - | AW26: 31 | AX26: Zero | AY26: IXORA
A27: 19 | B27: 27549 | C27: 2 | D27: 12496 | E27: 2 | F27: 32435 | G27: 3 | H27: 25605 | I27: 2 | J27: 21279 | K27: 1 | L27: 15748 | M27: 6 | N27: 14287 | O27: 2 | P27: 20940 | Q27: 1 | R27: 25189 | S27: 1 | T27: 1194 | U27: 1 | V27: 3231 | W27: - | X27: 30746 | Y27: - | Z27: 12859 | AA27: - | AB27: 14 | AC27: 13175 | AD27: 8 | AE27: 4916 | AF27: 3 | AG27: 4916 | AH27: 3 | AI27: 39224 | AJ27: 5 | AK27: 4555 | AL27: 6 | AM27: 1270 | AN27: - | AO27: 1471 | AP27: - | AQ27: 525 | AR27: - | AS27: 1375 | AT27: - | AU27: 9688 | AV27: 4 | AW27: 47 | AX27: Zero | AY27: IXORA
A28: 20 | B28: 27550 | C28: 1 | D28: 12497 | E28: 1 | F28: 32442 | G28: 7 | H28: 25611 | I28: 6 | J28: 21279 | K28: - | L28: 15749 | M28: 1 | N28: 14289 | O28: 2 | P28: 20941 | Q28: 1 | R28: 25190 | S28: 1 | T28: 1195 | U28: 1 | V28: 3231 | W28: - | X28: 30749 | Y28: 3 | Z28: 12859 | AA28: - | AB28: 15 | AC28: 13186 | AD28: 11 | AE28: 4922 | AF28: 6 | AG28: 4922 | AH28: 6 | AI28: 39225 | AJ28: 1 | AK28: 4569 | AL28: 14 | AM28: 1273 | AN28: 3 | AO28: 1472 | AP28: 1 | AQ28: 525 | AR28: - | AS28: 1375 | AT28: - | AU28: 9695 | AV28: 7 | AW28: 67 | AX28: Zero | AY28: IXORA
A29: 21 | B29: 27552 | C29: 2 | D29: 12498 | E29: 1 | F29: 32447 | G29: 5 | H29: 25614 | I29: 3 | J29: 21281 | K29: 2 | L29: 15750 | M29: 1 | N29: 14293 | O29: 4 | P29: 20944 | Q29: 3 | R29: 25193 | S29: 3 | T29: 1197 | U29: 2 | V29: 3234 | W29: 3 | X29: 30750 | Y29: 1 | Z29: 12859 | AA29: - | AB29: 22 | AC29: 13194 | AD29: 8 | AE29: 4926 | AF29: 4 | AG29: 4926 | AH29: 4 | AI29: 39228 | AJ29: 3 | AK29: 4570 | AL29: 1 | AM29: 1273 | AN29: - | AO29: 1472 | AP29: - | AQ29: 525 | AR29: - | AS29: 1375 | AT29: - | AU29: 9699 | AV29: 4 | AW29: 50 | AX29: Zero | AY29: IXORA
A30: 22 | B30: 27553 | C30: 1 | D30: 12499 | E30: 1 | F30: 32450 | G30: 3 | H30: 25622 | I30: 8 | J30: 21281 | K30: - | L30: 15751 | M30: 1 | N30: 14296 | O30: 3 | P30: 20947 | Q30: 3 | R30: 25195 | S30: 2 | T30: 1197 | U30: - | V30: 3234 | W30: - | X30: 30751 | Y30: 1 | Z30: 12877 | AA30: 18 | AB30: 36 | AC30: 13206 | AD30: 12 | AE30: 4931 | AF30: 5 | AG30: 4931 | AH30: 5 | AI30: 39233 | AJ30: 5 | AK30: 4571 | AL30: 1 | AM30: 1274 | AN30: 1 | AO30: 1472 | AP30: - | AQ30: 526 | AR30: 1 | AS30: 1375 | AT30: - | AU30: 9704 | AV30: 5 | AW30: 71 | AX30: Zero | AY30: IXORA
A31: 23 | B31: 27554 | C31: 1 | D31: 12500 | E31: 1 | F31: 32451 | G31: 1 | H31: 25627 | I31: 5 | J31: 21282 | K31: 1 | L31: 15754 | M31: 3 | N31: 14299 | O31: 3 | P31: 20949 | Q31: 2 | R31: 25195 | S31: - | T31: 1198 | U31: 1 | V31: 3235 | W31: 1 | X31: 30752 | Y31: 1 | Z31: 12892 | AA31: 15 | AB31: 32 | AC31: 13218 | AD31: 12 | AE31: 4934 | AF31: 3 | AG31: 4934 | AH31: 3 | AI31: 39236 | AJ31: 3 | AK31: 4571 | AL31: - | AM31: 1276 | AN31: 2 | AO31: 1472 | AP31: - | AQ31: 526 | AR31: - | AS31: 1375 | AT31: - | AU31: 9708 | AV31: 4 | AW31: 59 | AX31: Zero | AY31: IXORA
A32: 24 | B32: 27555 | C32: 1 | D32: 12502 | E32: 2 | F32: 32454 | G32: 3 | H32: 25630 | I32: 3 | J32: 21283 | K32: 1 | L32: 15756 | M32: 2 | N32: 14300 | O32: 1 | P32: 20950 | Q32: 1 | R32: 25197 | S32: 2 | T32: 1199 | U32: 1 | V32: 3236 | W32: 1 | X32: 30752 | Y32: - | Z32: 12892 | AA32: - | AB32: 12 | AC32: 13230 | AD32: 12 | AE32: 4938 | AF32: 4 | AG32: 4938 | AH32: 4 | AI32: 39240 | AJ32: 4 | AK32: 4571 | AL32: - | AM32: 1277 | AN32: 1 | AO32: 1472 | AP32: - | AQ32: 526 | AR32: - | AS32: 1375 | AT32: - | AU32: 9713 | AV32: 5 | AW32: 44 | AX32: Zero | AY32: IXORA
A33: 25 | B33: 27558 | C33: 3 | D33: 12503 | E33: 1 | F33: 32456 | G33: 2 | H33: 25631 | I33: 1 | J33: 21283 | K33: - | L33: 15759 | M33: 3 | N33: 14302 | O33: 2 | P33: 20951 | Q33: 1 | R33: 25198 | S33: 1 | T33: 1201 | U33: 2 | V33: 3236 | W33: - | X33: 30754 | Y33: 2 | Z33: 12892 | AA33: - | AB33: 12 | AC33: 13238 | AD33: 8 | AE33: 4940 | AF33: 2 | AG33: 4940 | AH33: 2 | AI33: 39241 | AJ33: 1 | AK33: 4572 | AL33: 1 | AM33: 1284 | AN33: 7 | AO33: 1472 | AP33: - | AQ33: 526 | AR33: - | AS33: 1376 | AT33: 1 | AU33: 9715 | AV33: 2 | AW33: 40 | AX33: Zero | AY33: IXORA
A34: 26 | B34: 27559 | C34: 1 | D34: 12503 | E34: - | F34: 32456 | G34: - | H34: 25632 | I34: 1 | J34: 21283 | K34: - | L34: 15762 | M34: 3 | N34: 14302 | O34: - | P34: 20951 | Q34: - | R34: 25198 | S34: - | T34: 1202 | U34: 1 | V34: 3236 | W34: - | X34: 30754 | Y34: - | Z34: 12892 | AA34: - | AB34: 5 | AC34: 13245 | AD34: 7 | AE34: 4941 | AF34: 1 | AG34: 4941 | AH34: 1 | AI34: 39241 | AJ34: - | AK34: 4572 | AL34: - | AM34: 1285 | AN34: 1 | AO34: 1472 | AP34: - | AQ34: 526 | AR34: - | AS34: 1376 | AT34: - | AU34: 9717 | AV34: 2 | AW34: 17 | AX34: Zero | AY34: IXORA
A35: 27 | B35: 27560 | C35: =B35-B34 -> 1 | D35: 12505 | E35: =D35-D34 -> 2 | F35: 32459 | G35: =F35-F34 -> 3 | H35: 25633 | I35: =H35-H34 -> 1 | J35: 21284 | K35: =J35-J34 -> 1 | L35: 15765 | M35: =L35-L34 -> 3 | N35: 14303 | O35: =N35-N34 -> 1 | P35: 20952 | Q35: =P35-P34 -> 1 | R35: 25199 | S35: =R35-R34 -> 1 | T35: 1203 | U35: =T35-T34 -> 1 | V35: 3236 | W35: =V35-V34 -> 0 | X35: 30756 | Y35: =X35-X34 -> 2 | Z35: 12892 | AA35: =Z35-Z34 -> 0 | AB35: =I35+K35+M35+O35+Q35+S35+U35+W35+Y35+AA35 -> 11 | AC35: 13256 | AD35: =AC35-AC34 -> 11 | AG35: 4945 | AH35: =AG35-AG34 -> 4 | AI35: 39242 | AJ35: =AI35-AI34 -> 1 | AK35: 4573 | AL35: =AK35-AK34 -> 1 | AM35: 1286 | AN35: =AM35-AM34 -> 1 | AO35: 1472 | AP35: =AO35-AO34 -> 0 | AQ35: 526 | AR35: =AQ35-AQ34 -> 0 | AS35: 1376 | AT35: =AS35-AS34 -> 0 | AU35: 9721 | AV35: =AU35-AU34 -> 4 | AW35: 39 | AX35: Zero | AY35: IXORA
A36: 28 | B36: 27561 | C36: =B36-B35 -> 1 | D36: 12506 | E36: =D36-D35 -> 1 | F36: 32461 | G36: =F36-F35 -> 2 | H36: 25634 | I36: =H36-H35 -> 1 | J36: 21284 | K36: =J36-J35 -> 0 | L36: 15767 | M36: =L36-L35 -> 2 | N36: 14303 | O36: =N36-N35 -> 0 | P36: 20952 | Q36: =P36-P35 -> 0 | R36: 25200 | S36: =R36-R35 -> 1 | T36: 1204 | U36: =T36-T35 -> 1 | V36: 3236 | W36: =V36-V35 -> 0 | X36: 30757 | Y36: =X36-X35 -> 1 | Z36: 12892 | AA36: =Z36-Z35 -> 0 | AB36: =I36+K36+M36+O36+Q36+S36+U36+W36+Y36+AA36 -> 6 | AC36: 13267 | AD36: =AC36-AC35 -> 11 | AG36: 4950 | AH36: =AG36-AG35 -> 5 | AI36: 39243 | AJ36: =AI36-AI35 -> 1 | AK36: 4573 | AL36: =AK36-AK35 -> 0 | AM36: 1286 | AN36: =AM36-AM35 -> 0 | AO36: 1472 | AP36: =AO36-AO35 -> 0 | AQ36: 526 | AR36: =AQ36-AQ35 -> 0 | AS36: 1376 | AT36: =AS36-AS35 -> 0 | AU36: 9726 | AV36: =AU36-AU35 -> 5 | AW36: 32 | AX36: Zero | AY36: IXORA
A37: 29 | B37: 27563 | C37: =B37-B36 -> 2 | D37: 12509 | E37: =D37-D36 -> 3 | F37: 32465 | G37: =F37-F36 -> 4 | H37: 25636 | I37: =H37-H36 -> 2 | J37: 21284 | K37: =J37-J36 -> 0 | L37: 15771 | M37: =L37-L36 -> 4 | N37: 14304 | O37: =N37-N36 -> 1 | P37: 20952 | Q37: =P37-P36 -> 0 | R37: 25200 | S37: =R37-R36 -> 0 | T37: 1206 | U37: =T37-T36 -> 2 | V37: 3237 | W37: =V37-V36 -> 1 | X37: 30757 | Y37: =X37-X36 -> 0 | Z37: 12892 | AA37: =Z37-Z36 -> 0 | AB37: =I37+K37+M37+O37+Q37+S37+U37+W37+Y37+AA37 -> 10 | AC37: 13274 | AD37: =AC37-AC36 -> 7 | AG37: 4953 | AH37: =AG37-AG36 -> 3 | AI37: 39250 | AJ37: =AI37-AI36 -> 7 | AK37: 4573 | AL37: =AK37-AK36 -> 0 | AM37: 1291 | AN37: =AM37-AM36 -> 5 | AO37: 1472 | AP37: =AO37-AO36 -> 0 | AQ37: 526 | AR37: =AQ37-AQ36 -> 0 | AS37: 1376 | AT37: =AS37-AS36 -> 0 | AU37: 9730 | AV37: =AU37-AU36 -> 4 | AW37: 45 | AX37: Zero | AY37: IXORA
A38: 30 | B38: 27565 | C38: =B38-B37 -> 2 | D38: 12511 | E38: =D38-D37 -> 2 | F38: 32470 | G38: =F38-F37 -> 5 | H38: 25642 | I38: =H38-H37 -> 6 | J38: 21288 | K38: =J38-J37 -> 4 | L38: 15777 | M38: =L38-L37 -> 6 | N38: 14307 | O38: =N38-N37 -> 3 | P38: 20956 | Q38: =P38-P37 -> 4 | R38: 25205 | S38: =R38-R37 -> 5 | T38: 1206 | U38: =T38-T37 -> 0 | V38: 3237 | W38: =V38-V37 -> 0 | X38: 30759 | Y38: =X38-X37 -> 2 | Z38: 12892 | AA38: =Z38-Z37 -> 0 | AB38: =I38+K38+M38+O38+Q38+S38+U38+W38+Y38+AA38 -> 30 | AC38: 13286 | AD38: =AC38-AC37 -> 12 | AG38: 4958 | AH38: =AG38-AG37 -> 5 | AI38: 39254 | AJ38: =AI38-AI37 -> 4 | AK38: 4575 | AL38: =AK38-AK37 -> 2 | AM38: 1293 | AN38: =AM38-AM37 -> 2 | AO38: 1472 | AP38: =AO38-AO37 -> 0 | AQ38: 526 | AR38: =AQ38-AQ37 -> 0 | AS38: 1376 | AT38: =AS38-AS37 -> 0 | AU38: 9735 | AV38: =AU38-AU37 -> 5 | AW38: 69 | AX38: Zero | AY38: IXORA
A39: 31 | B39: 27566 | C39: =B39-B38 -> 1 | D39: 12512 | E39: =D39-D38 -> 1 | F39: 32474 | G39: =F39-F38 -> 4 | H39: 25644 | I39: =H39-H38 -> 2 | J39: 21290 | K39: =J39-J38 -> 2 | L39: 15780 | M39: =L39-L38 -> 3 | N39: 14308 | O39: =N39-N38 -> 1 | P39: 20958 | Q39: =P39-P38 -> 2 | R39: 25207 | S39: =R39-R38 -> 2 | T39: 1207 | U39: =T39-T38 -> 1 | V39: 3237 | W39: =V39-V38 -> 0 | X39: 30759 | Y39: =X39-X38 -> 0 | Z39: 12892 | AA39: =Z39-Z38 -> 0 | AB39: =I39+K39+M39+O39+Q39+S39+U39+W39+Y39+AA39 -> 13 | AC39: 13296 | AD39: =AC39-AC38 -> 10 | AG39: 4962 | AH39: =AG39-AG38 -> 4 | AI39: 39258 | AJ39: =AI39-AI38 -> 4 | AK39: 4575 | AL39: =AK39-AK38 -> 0 | AM39: 1294 | AN39: =AM39-AM38 -> 1 | AO39: 1472 | AP39: =AO39-AO38 -> 0 | AQ39: 526 | AR39: =AQ39-AQ38 -> 0 | AS39: 1376 | AT39: =AS39-AS38 -> 0 | AU39: 9740 | AV39: =AU39-AU38 -> 5 | AW39: 43
A40: Total | AW40: =SUM(AW9:AW39) -> 1611 | AX40: Zero | AY40: IXORA
A44: Remark
