Workbook

Sheet Total
A1: Site Name | B1: Day | C1: Month | D1: Year | E1: Total Electricity Kwh | F1: Electricity Tariff ($/Kwh) | G1: Natual Gas (m3) | H1: Natural Gas $/m3 | I1: Water Utility Supply (m3) m3 | J1: Water Utility Supply (m3) $/m3 | K1: Room Nights | L1: Total Guests
A2: Istanbul at the Bosphorus | B2: 1 | C2: 1 | D2: 2021 | E2: ='Electricity '!I3+'Electricity '!O3 -> 20488.86 | F2: 0.55 | G2: ='Gas Water'!M4 -> 2196 | H2: 1.88 | I2: ='Gas Water'!L4 -> 128 | J2: 12.05 | K2: 88 | L2: 175
A3: Istanbul at the Bosphorus | B3: 2 | C3: 1 | D3: 2021 | E3: ='Electricity '!I4+'Electricity '!O4 -> 20646.18 | F3: 0.55 | G3: ='Gas Water'!M5 -> 2142 | H3: 1.88 | I3: ='Gas Water'!L5 -> 105 | J3: 12.05 | K3: 79 | L3: 157
A4: Istanbul at the Bosphorus | B4: 3 | C4: 1 | D4: 2021 | E4: ='Electricity '!I5+'Electricity '!O5 -> 20273.58 | F4: 0.55 | G4: ='Gas Water'!M6 -> 2437 | H4: 1.88 | I4: ='Gas Water'!L6 -> 104 | J4: 12.05 | K4: 65 | L4: 131
A5: Istanbul at the Bosphorus | B5: 4 | C5: 1 | D5: 2021 | E5: ='Electricity '!I6+'Electricity '!O6 -> 19412.46 | F5: 0.55 | G5: ='Gas Water'!M7 -> 2083 | H5: 1.88 | I5: ='Gas Water'!L7 -> 112 | J5: 12.05 | K5: 62 | L5: 118
A6: Istanbul at the Bosphorus | B6: 5 | C6: 1 | D6: 2021 | E6: ='Electricity '!I7+'Electricity '!O7 -> 20414.34 | F6: 0.55 | G6: ='Gas Water'!M8 -> 2135 | H6: 1.88 | I6: ='Gas Water'!L8 -> 100 | J6: 12.05 | K6: 70 | L6: 133
A7: Istanbul at the Bosphorus | B7: 6 | C7: 1 | D7: 2021 | E7: ='Electricity '!I8+'Electricity '!O8 -> 20815.92 | F7: 0.55 | G7: ='Gas Water'!M9 -> 2200 | H7: 1.88 | I7: ='Gas Water'!L9 -> 113 | J7: 12.05 | K7: 81 | L7: 147
A8: Istanbul at the Bosphorus | B8: 7 | C8: 1 | D8: 2021 | E8: ='Electricity '!I9+'Electricity '!O9 -> 21639.78 | F8: 0.55 | G8: ='Gas Water'!M10 -> 2075 | H8: 1.88 | I8: ='Gas Water'!L10 -> 106 | J8: 12.05 | K8: 82 | L8: 142
A9: Istanbul at the Bosphorus | B9: 8 | C9: 1 | D9: 2021 | E9: ='Electricity '!I10+'Electricity '!O10 -> 19259.28 | F9: 0.55 | G9: ='Gas Water'!M11 -> 1785 | H9: 1.88 | I9: ='Gas Water'!L11 -> 114 | J9: 12.05 | K9: 70 | L9: 128
A10: Istanbul at the Bosphorus | B10: 9 | C10: 1 | D10: 2021 | E10: ='Electricity '!I11+'Electricity '!O11 -> 21904.74 | F10: 0.55 | G10: ='Gas Water'!M12 -> 2155 | H10: 1.88 | I10: ='Gas Water'!L12 -> 76 | J10: 12.05 | K10: 50 | L10: 96
A11: Istanbul at the Bosphorus | B11: 10 | C11: 1 | D11: 2021 | E11: ='Electricity '!I12+'Electricity '!O12 -> 19313.1 | F11: 0.55 | G11: ='Gas Water'!M13 -> 2642 | H11: 1.88 | I11: ='Gas Water'!L13 -> 91 | J11: 12.05 | K11: 46 | L11: 86
A12: Istanbul at the Bosphorus | B12: 11 | C12: 1 | D12: 2021 | E12: ='Electricity '!I13+'Electricity '!O13 -> 19097.82 | F12: 0.55 | G12: ='Gas Water'!M14 -> 2005 | H12: 1.88 | I12: ='Gas Water'!L14 -> 111 | J12: 12.05 | K12: 47 | L12: 90
A13: Istanbul at the Bosphorus | B13: 12 | C13: 1 | D13: 2021 | E13: ='Electricity '!I14+'Electricity '!O14 -> 21420.36 | F13: 0.55 | G13: ='Gas Water'!M15 -> 2117 | H13: 1.88 | I13: ='Gas Water'!L15 -> 87 | J13: 12.05 | K13: 55 | L13: 103
... A32: Istanbul at the Bosphorus | B32: 31 | C32: 1 | D32: 2021 | E32: ='Electricity '!I33+'Electricity '!O33 -> 18592.74 | F32: 0.55 | G32: ='Gas Water'!M34 -> 2609 | H32: 1.88 | I32: ='Gas Water'!L34 -> 79 | J32: 12.05 | K32: 42 | L32: 81
A33: Istanbul at the Bosphorus | B33: 1 | C33: 2 | D33: 2021 | E33: ='Electricity '!I34+'Electricity '!O34 -> 20236.32 | F33: =('Electricity '!I34*0.58+'Gas Water'!H35*1.88)/(Total!E33) -> 0.58 | G33: ='Gas Water'!M35 -> 2117 | H33: 1.72 | I33: ='Gas Water'!L35 -> 88 | J33: 12.85 | K33: 43 | L33: 75
A34: Istanbul at the Bosphorus | B34: 2 | C34: 2 | D34: 2021 | E34: ='Electricity '!I35+'Electricity '!O35 -> 19913.4 | F34: =('Electricity '!I35*0.58+'Gas Water'!H36*1.88)/(Total!E34) -> 0.58 | G34: ='Gas Water'!M36 -> 2297 | H34: 1.72 | I34: ='Gas Water'!L36 -> 126 | J34: 12.85 | K34: 59 | L34: 104
A35: Istanbul at the Bosphorus | B35: 3 | C35: 2 | D35: 2021 | E35: ='Electricity '!I36+'Electricity '!O36 -> 20989.8 | F35: =('Electricity '!I36*0.58+'Gas Water'!H37*1.88)/(Total!E35) -> 0.58 | G35: ='Gas Water'!M37 -> 2397 | H35: 1.72 | I35: ='Gas Water'!L37 -> 171 | J35: 12.85 | K35: 84 | L35: 142
A36: Istanbul at the Bosphorus | B36: 4 | C36: 2 | D36: 2021 | E36: ='Electricity '!I37+'Electricity '!O37 -> 20356.38 | F36: =('Electricity '!I37*0.58+'Gas Water'!H38*1.88)/(Total!E36) -> 0.58 | G36: ='Gas Water'!M38 -> 2456 | H36: 1.72 | I36: ='Gas Water'!L38 -> 154 | J36: 12.85 | K36: 90 | L36: 148
A37: Istanbul at the Bosphorus | B37: 5 | C37: 2 | D37: 2021 | E37: ='Electricity '!I38+'Electricity '!O38 -> 20459.88 | F37: =('Electricity '!I38*0.58+'Gas Water'!H39*1.88)/(Total!E37) -> 0.58 | G37: ='Gas Water'!M39 -> 2549 | H37: 1.72 | I37: ='Gas Water'!L39 -> 131 | J37: 12.85 | K37: 103 | L37: 176
A38: Istanbul at the Bosphorus | B38: 6 | C38: 2 | D38: 2021 | E38: ='Electricity '!I39+'Electricity '!O39 -> 18480.96 | F38: =('Electricity '!I39*0.58+'Gas Water'!H40*1.88)/(Total!E38) -> 0.58 | G38: ='Gas Water'!M40 -> 2543 | H38: 1.72 | I38: ='Gas Water'!L40 -> 131 | J38: 12.85 | K38: 99 | L38: 171
A39: Istanbul at the Bosphorus | B39: 7 | C39: 2 | D39: 2021 | E39: ='Electricity '!I40+'Electricity '!O40 -> 19648.44 | F39: =('Electricity '!I40*0.58+'Gas Water'!H41*1.88)/(Total!E39) -> 0.58 | G39: ='Gas Water'!M41 -> 2280 | H39: 1.72 | I39: ='Gas Water'!L41 -> 123 | J39: 12.85 | K39: 64 | L39: 116
A40: Istanbul at the Bosphorus | B40: 8 | C40: 2 | D40: 2021 | E40: ='Electricity '!I41+'Electricity '!O41 -> 19458 | F40: =('Electricity '!I41*0.58+'Gas Water'!H42*1.88)/(Total!E40) -> 0.58 | G40: ='Gas Water'!M42 -> 1872 | H40: 1.72 | I40: ='Gas Water'!L42 -> 95 | J40: 12.85 | K40: 74 | L40: 138
A41: Istanbul at the Bosphorus | B41: 9 | C41: 2 | D41: 2021 | E41: ='Electricity '!I42+'Electricity '!O42 -> 20232.18 | F41: =('Electricity '!I42*0.58+'Gas Water'!H43*1.88)/(Total!E41) -> 0.58 | G41: ='Gas Water'!M43 -> 1976 | H41: 1.72 | I41: ='Gas Water'!L43 -> 99 | J41: 12.85 | K41: 76 | L41: 139
A42: Istanbul at the Bosphorus | B42: 10 | C42: 2 | D42: 2021 | E42: ='Electricity '!I43+'Electricity '!O43 -> 16746.3 | F42: =('Electricity '!I43*0.58+'Gas Water'!H44*1.88)/(Total!E42) -> 0.58 | G42: ='Gas Water'!M44 -> 2160 | H42: 1.72 | I42: ='Gas Water'!L44 -> 102 | J42: 12.85 | K42: 85 | L42: 157
A43: Istanbul at the Bosphorus | B43: 11 | C43: 2 | D43: 2021 | E43: ='Electricity '!I44+'Electricity '!O44 -> 23540.04 | F43: =('Electricity '!I44*0.58+'Gas Water'!H45*1.88)/(Total!E43) -> 0.58 | G43: ='Gas Water'!M45 -> 2024 | H43: 1.72 | I43: ='Gas Water'!L45 -> 172 | J43: 12.85 | K43: 93 | L43: 172
A44: Istanbul at the Bosphorus | B44: 12 | C44: 2 | D44: 2021 | E44: ='Electricity '!I45+'Electricity '!O45 -> 21528 | F44: =('Electricity '!I45*0.58+'Gas Water'!H46*1.88)/(Total!E44) -> 0.58 | G44: ='Gas Water'!M46 -> 3716 | H44: 1.72 | I44: ='Gas Water'!L46 -> 122 | J44: 12.85 | K44: 86 | L44: 164
... A62: Istanbul at the Bosphorus | B62: 2 | C62: 3 | D62: 2021 | E62: ='Electricity '!I63+'Electricity '!O63 -> 22285.62 | F62: =('Electricity '!I63*0.58+'Gas Water'!H64*1.88)/(Total!E62) -> 0.58 | G62: ='Gas Water'!M64 -> 3548 | H62: 1.76 | I62: ='Gas Water'!L64 -> 108 | J62: 12.85 | K62: 72 | L62: 118
A63: Istanbul at the Bosphorus | B63: 3 | C63: 3 | D63: 2021 | E63: ='Electricity '!I64+'Electricity '!O64 -> 22728.6 | F63: =('Electricity '!I64*0.58+'Gas Water'!H65*1.72)/(Total!E63) -> 0.58 | G63: ='Gas Water'!M65 -> 3407 | H63: 1.76 | I63: ='Gas Water'!L65 -> 128 | J63: 12.85 | K63: 102 | L63: 184
A64: Istanbul at the Bosphorus | B64: 4 | C64: 3 | D64: 2021 | E64: ='Electricity '!I65+'Electricity '!O65 -> 21701.88 | F64: =('Electricity '!I65*0.58+'Gas Water'!H66*1.88)/(Total!E64) -> 0.58 | G64: ='Gas Water'!M66 -> 3183 | H64: 1.76 | I64: ='Gas Water'!L66 -> 140 | J64: 12.85 | K64: 115 | L64: 189
A65: Istanbul at the Bosphorus | B65: 5 | C65: 3 | D65: 2021 | E65: ='Electricity '!I66+'Electricity '!O66 -> 20894.58 | F65: =('Electricity '!I66*0.58+'Gas Water'!H67*1.88)/(Total!E65) -> 0.58 | G65: ='Gas Water'!M67 -> 2739 | H65: 1.76 | I65: ='Gas Water'!L67 -> 305 | J65: 12.85 | K65: 131 | L65: 225
A66: Istanbul at the Bosphorus | B66: 6 | C66: 3 | D66: 2021 | E66: ='Electricity '!I67+'Electricity '!O67 -> 20840.76 | F66: =('Electricity '!I67*0.58+'Gas Water'!H68*1.88)/(Total!E66) -> 0.58 | G66: ='Gas Water'!M68 -> 3255 | H66: 1.76 | I66: ='Gas Water'!L68 -> 168 | J66: 12.85 | K66: 129 | L66: 237
A67: Istanbul at the Bosphorus | B67: 7 | C67: 3 | D67: 2021 | E67: ='Electricity '!I68+'Electricity '!O68 -> 21788.82 | F67: =('Electricity '!I68*0.58+'Gas Water'!H69*1.88)/(Total!E67) -> 0.58 | G67: ='Gas Water'!M69 -> 3750 | H67: 1.76 | I67: ='Gas Water'!L69 -> 155 | J67: 12.85 | K67: 107 | L67: 197
A68: Istanbul at the Bosphorus | B68: 8 | C68: 3 | D68: 2021 | E68: ='Electricity '!I69+'Electricity '!O69 -> 22086.9 | F68: =('Electricity '!I69*0.58+'Gas Water'!H70*1.88)/(Total!E68) -> 0.58 | G68: ='Gas Water'!M70 -> 3482 | H68: 1.76 | I68: ='Gas Water'!L70 -> 143 | J68: 12.85 | K68: 89 | L68: 159
A69: Istanbul at the Bosphorus | B69: 9 | C69: 3 | D69: 2021 | E69: ='Electricity '!I70+'Electricity '!O70 -> 22074.48 | F69: =('Electricity '!I70*0.58+'Gas Water'!H71*1.88)/(Total!E69) -> 0.58 | G69: ='Gas Water'!M71 -> 3037 | H69: 1.76 | I69: ='Gas Water'!L71 -> 141 | J69: 12.85 | K69: 115 | L69: 187
A70: Istanbul at the Bosphorus | B70: 10 | C70: 3 | D70: 2021 | E70: ='Electricity '!I71+'Electricity '!O71 -> 22240.08 | F70: =('Electricity '!I71*0.58+'Gas Water'!H72*1.88)/(Total!E70) -> 0.58 | G70: ='Gas Water'!M72 -> 3049 | H70: 1.76 | I70: ='Gas Water'!L72 -> 147 | J70: 12.85 | K70: 121 | L70: 199
A71: Istanbul at the Bosphorus | B71: 11 | C71: 3 | D71: 2021 | E71: ='Electricity '!I72+'Electricity '!O72 -> 23519.34 | F71: =('Electricity '!I72*0.58+'Gas Water'!H73*1.88)/(Total!E71) -> 0.58 | G71: ='Gas Water'!M73 -> 3802 | H71: 1.76 | I71: ='Gas Water'!L73 -> 142 | J71: 12.85 | K71: 107 | L71: 184
A72: Istanbul at the Bosphorus | B72: 12 | C72: 3 | D72: 2021 | E72: ='Electricity '!I73+'Electricity '!O73 -> 21850.92 | F72: =('Electricity '!I73*0.58+'Gas Water'!H74*1.88)/(Total!E72) -> 0.58 | G72: ='Gas Water'!M74 -> 3566 | H72: 1.76 | I72: ='Gas Water'!L74 -> 160 | J72: 12.85 | K72: 115 | L72: 195
A73: Istanbul at the Bosphorus | B73: 13 | C73: 3 | D73: 2021 | E73: ='Electricity '!I74+'Electricity '!O74 -> 22364.28 | F73: =('Electricity '!I74*0.58+'Gas Water'!H75*1.88)/(Total!E73) -> 0.58 | G73: ='Gas Water'!M75 -> 3112 | H73: 1.76 | I73: ='Gas Water'!L75 -> 135 | J73: 12.85 | K73: 117 | L73: 214
A74: Istanbul at the Bosphorus | B74: 14 | C74: 3 | D74: 2021 | E74: ='Electricity '!I75+'Electricity '!O75 -> 20857.32 | F74: =('Electricity '!I75*0.58+'Gas Water'!H76*1.88)/(Total!E74) -> 0.58 | G74: ='Gas Water'!M76 -> 2984 | H74: 1.76 | I74: ='Gas Water'!L76 -> 156 | J74: 12.85 | K74: 88 | L74: 154
A75: Istanbul at the Bosphorus | B75: 15 | C75: 3 | D75: 2021 | E75: ='Electricity '!I76+'Electricity '!O76 -> 22211.1 | F75: =('Electricity '!I76*0.58+'Gas Water'!H77*1.88)/(Total!E75) -> 0.58 | G75: ='Gas Water'!M77 -> 2571 | H75: 1.76 | I75: ='Gas Water'!L77 -> 143 | J75: 12.85 | K75: 91 | L75: 160
...

Sheet Gas Water
B2: Date | C2: CHP Reading m3 | D2: Boiler Reading m3 | E2: Kitchen Reading m3 | F2: Laundry Reading m3 | G2: Water Supplier Credit m3 | H2: CHP Diffenece m3 | I2: Boiler Difference m3 | J2: Kitchen Difference m3 | K2: Laundry Difference m3 | L2: Water Difference m3 | M2: Total Gas Consumption m3
B3: 43830 | C3: 16228333 | D3: 3990997 | E3: 223696 | F3: 521490 | G3: 5647
B4: 44197 | C4: 16228335 | D4: 4463442 | E4: 277482 | F4: 575904 | G4: 225686 | H4: 0 | I4: 1954 | J4: 128 | K4: 114 | L4: 128 | M4: 2196 | Q4: =IF(L4="",1,0) -> 0
B5: 44198 | C5: 16228335 | D5: 4465332 | E5: 277603 | F5: 576035 | G5: 225791 | H5: 0 | I5: 1890 | J5: 121 | K5: 131 | L5: 105 | M5: 2142 | Q5: =IF(L5="",1,0) -> 0
B6: 44199 | C6: 16228335 | D6: 4467510 | E6: 277734 | F6: 576163 | G6: 225895 | H6: 0 | I6: 2178 | J6: 131 | K6: 128 | L6: 104 | M6: 2437 | Q6: =IF(L6="",1,0) -> 0
B7: 44200 | C7: 16228335 | D7: 4469336 | E7: 277851 | F7: 576303 | G7: 226007 | H7: 0 | I7: 1826 | J7: 117 | K7: 140 | L7: 112 | M7: 2083 | Q7: =IF(L7="",1,0) -> 0
B8: 44201 | C8: 16228335 | D8: 4471208 | E8: 277990 | F8: 576427 | G8: 226107 | H8: 0 | I8: 1872 | J8: 139 | K8: 124 | L8: 100 | M8: 2135 | Q8: =IF(L8="",1,0) -> 0
B9: 44202 | C9: 16228335 | D9: 4473169 | E9: 278127 | F9: 576529 | G9: 226220 | H9: 0 | I9: 1961 | J9: 137 | K9: 102 | L9: 113 | M9: 2200 | Q9: =IF(L9="",1,0) -> 0
B10: 44203 | C10: 16228335 | D10: 4474988 | E10: 278259 | F10: 576653 | G10: 226326 | H10: 0 | I10: 1819 | J10: 132 | K10: 124 | L10: 106 | M10: 2075 | Q10: =IF(L10="",1,0) -> 0
B11: 44204 | C11: 16228335 | D11: 4476515 | E11: 278386 | F11: 576784 | G11: 226440 | H11: 0 | I11: 1527 | J11: 127 | K11: 131 | L11: 114 | M11: 1785 | Q11: =IF(L11="",1,0) -> 0
B12: 44205 | C12: 16228335 | D12: 4478432 | E12: 278504 | F12: 576904 | G12: 226516 | H12: 0 | I12: 1917 | J12: 118 | K12: 120 | L12: 76 | M12: 2155 | Q12: =IF(L12="",1,0) -> 0
B13: 44206 | C13: 16228335 | D13: 4480830 | E13: 278634 | F13: 577018 | G13: 226607 | H13: 0 | I13: 2398 | J13: 130 | K13: 114 | L13: 91 | M13: 2642 | Q13: =IF(L13="",1,0) -> 0
B14: 44207 | C14: 16228335 | D14: 4482588 | E14: 278774 | F14: 577125 | G14: 226718 | H14: 0 | I14: 1758 | J14: 140 | K14: 107 | L14: 111 | M14: 2005 | Q14: =IF(L14="",1,0) -> 0
B15: 44208 | C15: 16228335 | D15: 4484455 | E15: 278913 | F15: 577236 | G15: 226805 | H15: 0 | I15: 1867 | J15: 139 | K15: 111 | L15: 87 | M15: 2117 | Q15: =IF(L15="",1,0) -> 0
... B24: 44217 | C24: 16228335 | D24: 4517220 | E24: 280051 | F24: 578160 | G24: 227610 | H24: 0 | I24: 3214 | J24: 134 | K24: 108 | L24: 101 | M24: 3456 | Q24: =IF(L24="",1,0) -> 0
B25: 44218 | C25: 16228335 | D25: 4519533 | E25: 280158 | F25: 578273 | G25: 227717 | H25: 0 | I25: 2313 | J25: 107 | K25: 113 | L25: 107 | M25: 2533 | N25: Total Water m3 | O25: Total Gas m3 | Q25: =IF(L25="",1,0) -> 0
B26: 44219 | C26: 16228335 | D26: 4521970 | E26: 280289 | F26: 578391 | G26: 227832 | H26: 0 | I26: 2437 | J26: 131 | K26: 118 | L26: 115 | M26: 2686 | Q26: =IF(L26="",1,0) -> 0
B27: 44220 | C27: 16228335 | D27: 4524269 | E27: 280407 | F27: 578505 | G27: 227920 | H27: 0 | I27: 2299 | J27: 118 | K27: 114 | L27: 88 | M27: 2531 | Q27: =IF(L27="",1,0) -> 0
B28: 44221 | C28: 16228335 | D28: 4526764 | E28: 280553 | F28: 578615 | G28: 228007 | H28: 0 | I28: 2495 | J28: 146 | K28: 110 | L28: 87 | M28: 2751 | N28: =SUM(L4:L34) -> 3034 | O28: =SUM(M4:M34) -> 90629 | Q28: =IF(L28="",1,0) -> 0
B29: 44222 | C29: 16228335 | D29: 4529086 | E29: 280686 | F29: 578736 | G29: 228111 | H29: 0 | I29: 2322 | J29: 133 | K29: 121 | L29: 104 | M29: 2576 | N29: Daily Average Water Consumption | O29: Daily Average Gas Consumption | Q29: =IF(L29="",1,0) -> 0
B30: 44223 | C30: 16228335 | D30: 4532734 | E30: 280825 | F30: 578859 | G30: 228202 | H30: 0 | I30: 3648 | J30: 139 | K30: 123 | L30: 91 | M30: 3910 | Q30: =IF(L30="",1,0) -> 0
B31: 44224 | C31: 16228335 | D31: 4536383 | E31: 280976 | F31: 578983 | G31: 228316 | H31: 0 | I31: 3649 | J31: 151 | K31: 124 | L31: 114 | M31: 3924 | N31: =AVERAGE(L4:L34) -> 97.870968 | O31: =AVERAGE(M4:M34) -> 2923.5161 | Q31: =IF(L31="",1,0) -> 0
B32: 44225 | C32: 16228335 | D32: 4539594 | E32: 281116 | F32: 579121 | G32: 228427 | H32: 0 | I32: 3211 | J32: 140 | K32: 138 | L32: 111 | M32: 3489 | O32: =IF(L32="",1,0) -> 0
B33: 44226 | C33: 16228335 | D33: 4542176 | E33: 281242 | F33: 579234 | G33: 228513 | H33: 0 | I33: 2582 | J33: 126 | K33: 113 | L33: 86 | M33: 2821 | O33: =IF(L33="",1,0) -> 0
B34: 44227 | C34: 16228335 | D34: 4544555 | E34: 281363 | F34: 579343 | G34: 228592 | H34: 0 | I34: 2379 | J34: 121 | K34: 109 | L34: 79 | M34: 2609 | Q34: =IF(L34="",1,0) -> 0
B35: 44228 | C35: 16228335 | D35: 4546448 | E35: 281482 | F35: 579448 | G35: 228680 | H35: 0 | I35: 1893 | J35: 119 | K35: 105 | L35: 88 | M35: 2117
B36: 44229 | C36: 16228335 | D36: 4548532 | E36: 281601 | F36: 579542 | G36: 228806 | H36: 0 | I36: 2084 | J36: 119 | K36: 94 | L36: 126 | M36: 2297 | Q36: =IF(L36="",1,0) -> 0
B37: 44230 | C37: 16228335 | D37: 4550676 | E37: 281742 | F37: 579654 | G37: 228977 | H37: 0 | I37: 2144 | J37: 141 | K37: 112 | L37: 171 | M37: 2397 | Q37: =IF(L37="",1,0) -> 0
B38: 44231 | C38: 16228335 | D38: 4552886 | E38: 281882 | F38: 579760 | G38: 229131 | H38: 0 | I38: 2210 | J38: 140 | K38: 106 | L38: 154 | M38: 2456 | Q38: =IF(L38="",1,0) -> 0
B39: 44232 | C39: 16228335 | D39: 4555153 | E39: 282033 | F39: 579891 | G39: 229262 | H39: 0 | I39: 2267 | J39: 151 | K39: 131 | L39: 131 | M39: 2549 | Q39: =IF(L39="",1,0) -> 0
B40: 44233 | C40: 16228335 | D40: 4557430 | E40: 282160 | F40: 580030 | G40: 229393 | H40: 0 | I40: 2277 | J40: 127 | K40: 139 | L40: 131 | M40: 2543 | Q40: =IF(L40="",1,0) -> 0
B41: 44234 | C41: 16228335 | D41: 4559442 | E41: 282285 | F41: 580173 | G41: 229516 | H41: 0 | I41: 2012 | J41: 125 | K41: 143 | L41: 123 | M41: 2280 | Q41: =IF(L41="",1,0) -> 0
B42: 44235 | C42: 16228335 | D42: 4561022 | E42: 282439 | F42: 580311 | G42: 229611 | H42: 0 | I42: 1580 | J42: 154 | K42: 138 | L42: 95 | M42: 1872 | Q42: =IF(L42="",1,0) -> 0
B43: 44236 | C43: 16228335 | D43: 4562745 | E43: 282581 | F43: 580422 | G43: 229710 | H43: 0 | I43: 1723 | J43: 142 | K43: 111 | L43: 99 | M43: 1976 | Q43: =IF(L43="",1,0) -> 0
B44: 44237 | C44: 16228335 | D44: 4564656 | E44: 282701 | F44: 580551 | G44: 229812 | H44: 0 | I44: 1911 | J44: 120 | K44: 129 | L44: 102 | M44: 2160 | Q44: =IF(L44="",1,0) -> 0
B45: 44238 | C45: 16228335 | D45: 4566425 | E45: 282827 | F45: 580680 | G45: 229984 | H45: 0 | I45: 1769 | J45: 126 | K45: 129 | L45: 172 | M45: 2024 | Q45: =IF(L45="",1,0) -> 0
B46: 44239 | C46: 16228335 | D46: 4569862 | E46: 282962 | F46: 580824 | G46: 230106 | H46: 0 | I46: 3437 | J46: 135 | K46: 144 | L46: 122 | M46: 3716 | Q46: =IF(L46="",1,0) -> 0
B47: 44240 | C47: 16228335 | D47: 4573447 | E47: 283081 | F47: 580933 | G47: 230295 | H47: 0 | I47: 3585 | J47: 119 | K47: 109 | L47: 189 | M47: 3813 | Q47: =IF(L47="",1,0) -> 0
... B52: 44245 | C52: 16228335 | D52: 4594466 | E52: 283813 | F52: 581645 | G52: 230926 | H52: 0 | I52: 4001 | J52: 167 | K52: 122 | L52: 346 | M52: 4290 | Q52: =IF(L52="",1,0) -> 0
B53: 44246 | C53: 16228335 | D53: 4598082 | E53: 283934 | F53: 581764 | G53: 230946 | H53: 0 | I53: 3616 | J53: 121 | K53: 119 | L53: 20 | M53: 3856 | N53: Total Water m3 | O53: Total Gas m3 | Q53: =IF(L53="",1,0) -> 0
...

Sheet Electricity 
A1: Date | B1: TR1 (bilgisayarda) | C1: TR2 (bilgisayardan) | D1: Meter Reading(Active)KWh | E1: Reactive Reading KWh | F1: Capacitive Reading KWh | G1: Şebekeye | H1: Meter Multipier | I1: Şebekeden (kWh) | J1: Endüktif (kVAr) | K1: Reaktif Endüktif Oranı | L1: Kapasitif (kVAr) | M1: Reaktif Kapasitif Oranı | N1: Kojen Değeri | O1: Kojen (kWh)
A2: 43465 | D2: 4926.457 | E2: 220.02 | F2: 169.75 | N2: 66068309
A3: 44197 | D3: 0.142 | E3: 6807.857 | F3: 322.333 | G3: 183.67 | I3: 20488.86 | J3: 1113.66 | K3: 0.054354415 | L3: 194.58 | M3: 0.0094968681 | N3: 66068309 | O3: 0 | P3: =IF(N3="",0,1) -> 1 | Q3: =IF(N3="",1,0) -> 0
A4: 44198 | D4: 0.142 | E4: 6812.844 | F4: 322.65 | G4: 183.709 | I4: 20646.18 | J4: 1312.38 | K4: 0.06356527 | L4: 161.46 | M4: 0.0078203329 | N4: 66068309 | O4: 0 | P4: =IF(N4="",0,1) -> 1 | Q4: =IF(N4="",1,0) -> 0
A5: 44199 | D5: 0.142 | E5: 6817.741 | F5: 322.855 | G5: 183.741 | I5: 20273.58 | J5: 848.7 | K5: 0.041862365 | L5: 132.48 | M5: 0.006534613 | N5: 66068309 | O5: 0 | P5: =IF(N5="",0,1) -> 1 | Q5: =IF(N5="",1,0) -> 0
A6: 44200 | D6: 0.142 | E6: 6822.43 | F6: 323.131 | G6: 183.781 | I6: 19412.46 | J6: 1142.64 | K6: 0.058861164 | L6: 165.6 | M6: 0.0085306035 | N6: 66068309 | O6: 0 | P6: =IF(N6="",0,1) -> 1 | Q6: =IF(N6="",1,0) -> 0
A7: 44201 | D7: 0.142 | E7: 6827.361 | F7: 323.407 | G7: 183.809 | I7: 20414.34 | J7: 1142.64 | K7: 0.055972419 | L7: 115.92 | M7: 0.0056783614 | N7: 66068309 | O7: 0 | P7: =IF(N7="",0,1) -> 1 | Q7: =IF(N7="",1,0) -> 0
A8: 44202 | D8: 0.142 | E8: 6832.389 | F8: 323.7 | G8: 183.832 | I8: 20815.92 | J8: 1213.02 | K8: 0.058273667 | L8: 95.22 | M8: 0.0045743835 | N8: 66068309 | O8: 0 | R8: =IF(N8="",0,1) -> 1 | S8: =IF(N8="",1,0) -> 0
A9: 44203 | D9: 0.142 | E9: 6837.616 | F9: 323.923 | G9: 183.872 | I9: 21639.78 | J9: 923.22 | K9: 0.042663095 | L9: 165.6 | M9: 0.0076525732 | N9: 66068309 | O9: 0 | R9: =IF(N9="",0,1) -> 1 | S9: =IF(N9="",1,0) -> 0
A10: 44204 | D10: 0.142 | E10: 6842.268 | F10: 324.105 | G10: 183.909 | I10: 19259.28 | J10: 753.48 | K10: 0.039122958 | L10: 153.18 | M10: 0.0079535684 | N10: 66068309 | O10: 0 | R10: =IF(N10="",0,1) -> 1 | S10: =IF(N10="",1,0) -> 0
A11: 44205 | D11: 0.142 | E11: 6847.559 | F11: 324.294 | G11: 183.944 | I11: 21904.74 | J11: 782.46 | K11: 0.035721036 | L11: 144.9 | M11: 0.0066150066 | N11: 66068309 | O11: 0 | R11: =IF(N11="",0,1) -> 1 | S11: =IF(N11="",1,0) -> 0
A12: 44206 | D12: 0.142 | E12: 6852.224 | F12: 324.454 | G12: 183.986 | I12: 19313.1 | J12: 662.4 | K12: 0.034297964 | L12: 173.88 | M12: 0.0090032154 | N12: 66068309 | O12: 0 | R12: =IF(N12="",0,1) -> 1 | S12: =IF(N12="",1,0) -> 0
A13: 44207 | D13: 0.142 | E13: 6856.837 | F13: 324.586 | G13: 184.028 | I13: 19097.82 | J13: 546.48 | K13: 0.028614784 | L13: 173.88 | M13: 0.0091047041 | N13: 66068309 | O13: 0 | R13: =IF(N13="",0,1) -> 1 | S13: =IF(N13="",1,0) -> 0
A14: 44208 | D14: 0.142 | E14: 6862.011 | F14: 324.794 | G14: 184.073 | I14: 21420.36 | J14: 861.12 | K14: 0.040201005 | L14: 186.3 | M14: 0.0086973328 | N14: 66068309 | O14: 0 | R14: =IF(N14="",0,1) -> 1 | S14: =IF(N14="",1,0) -> 0
A15: 44209 | D15: 0.142 | E15: 6867.271 | F15: 325.038 | G15: 184.107 | I15: 21776.4 | J15: 1010.16 | K15: 0.046387833 | L15: 140.76 | M15: 0.0064638783 | N15: 66068309 | O15: 0 | R15: =IF(N15="",0,1) -> 1 | S15: =IF(N15="",1,0) -> 0
A16: 44210 | D16: 0.142 | E16: 6872.249 | F16: 325.252 | G16: 184.131 | I16: 20608.92 | J16: 885.96 | K16: 0.042989152 | L16: 99.36 | M16: 0.0048212133 | N16: 66068309 | O16: 0 | R16: =IF(N16="",0,1) -> 1 | S16: =IF(N16="",1,0) -> 0
A17: 44211 | D17: 0.142 | E17: 6877.206 | F17: 325.474 | G17: 184.166 | I17: 20521.98 | J17: 919.08 | K17: 0.044785152 | L17: 144.9 | M17: 0.0070607222 | N17: 66068309 | O17: 0 | R17: =IF(N17="",0,1) -> 1 | S17: =IF(N17="",1,0) -> 0
A18: 44212 | D18: 0.142 | E18: 6882.08 | F18: 325.661 | G18: 184.206 | I18: 20178.36 | J18: 774.18 | K18: 0.038366844 | L18: 165.6 | M18: 0.0082068117 | N18: 66068309 | O18: 0 | R18: =IF(N18="",0,1) -> 1 | S18: =IF(N18="",1,0) -> 0
A19: 44213 | D19: 0.142 | E19: 6886.78 | F19: 325.87 | G19: 184.245 | I19: 19458 | J19: 865.26 | K19: 0.044468085 | L19: 161.46 | M19: 0.0082978723 | N19: 66068309 | O19: 0 | R19: =IF(N19="",0,1) -> 1 | S19: =IF(N19="",1,0) -> 0
A20: 44214 | D20: 0.142 | E20: 6891.461 | F20: 326.126 | G20: 184.282 | I20: 19379.34 | J20: 1059.84 | K20: 0.054689169 | L20: 153.18 | M20: 0.007904294 | N20: 66068309 | O20: 0 | R20: =IF(N20="",0,1) -> 1 | S20: =IF(N20="",1,0) -> 0
A21: 44215 | D21: 0.142 | E21: 6896.302 | F21: 326.371 | G21: 184.312 | I21: 20041.74 | J21: 1014.3 | K21: 0.050609378 | L21: 124.2 | M21: 0.0061970667 | N21: 66068309 | O21: 0 | P21: Ocak / Jan | R21: =IF(N21="",0,1) -> 1 | S21: =IF(N21="",1,0) -> 0
A22: 44216 | D22: 0.142 | E22: 6901.127 | F22: 326.61 | G22: 184.348 | I22: 19975.5 | J22: 989.46 | K22: 0.049533679 | L22: 149.04 | M22: 0.0074611399 | N22: 66068309 | O22: 0 | R22: =IF(N22="",0,1) -> 1 | S22: =IF(N22="",1,0) -> 0
A23: 44217 | D23: 0.142 | E23: 6906.085 | F23: 326.838 | G23: 184.39 | I23: 20526.12 | J23: 943.92 | K23: 0.045986285 | L23: 173.88 | M23: 0.0084711577 | N23: 66068309 | O23: 0 | P23: End. | Q23: Kap. | R23: =IF(N23="",0,1) -> 1 | S23: =IF(N23="",1,0) -> 0
A24: 44218 | D24: 0.142 | E24: 6910.954 | F24: 327.098 | G24: 184.438 | I24: 20157.66 | J24: 1076.4 | K24: 0.053399055 | L24: 198.72 | M24: 0.0098582871 | N24: 66068309 | O24: 0 | P24: =IF(J3="",0,+SUM(J3:J33)/SUM(I3:I33)) -> 0.046229912 | Q24: =IF(L3="",0,+SUM(L3:L33)/SUM(I3:I33)) -> 0.00812414 | R24: =IF(N24="",0,1) -> 1 | S24: =IF(N24="",1,0) -> 0
A25: 44219 | D25: 0.142 | E25: 6915.616 | F25: 327.345 | G25: 184.483 | I25: 19300.68 | J25: 1022.58 | K25: 0.052981553 | L25: 186.3 | M25: 0.0096525097 | N25: 66068309 | O25: 0 | P25: =IF(J3="",0,+(+(LOOKUP(9.99999999999999E+307,E3:E33)-E2))/(+(LOOKUP(9.99999999999999E+307,D3:D33)-D2))) -> -1.3671032 | Q25: =IF(L3="",0,+(+(LOOKUP(9.99999999999999E+307,F3:F33)-F2))/(+(LOOKUP(9.99999999999999E+307,D3:D33)-D2))) -> -0.032343851 | R25: =IF(N25="",0,1) -> 1 | S25: =IF(N25="",1,0) -> 0
A26: 44220 | D26: 0.142 | E26: 6920.41 | F26: 327.542 | G26: 184.538 | I26: 19847.16 | J26: 815.58 | K26: 0.041093033 | L26: 227.7 | M26: 0.011472674 | N26: 66068309 | O26: 0 | P26: Cat Aylık | Q26: Cat Günlük | R26: =IF(N26="",0,1) -> 1 | S26: =IF(N26="",1,0) -> 0
A27: 44221 | D27: 0.142 | E27: 6925.488 | F27: 327.802 | G27: 184.571 | I27: 21022.92 | J27: 1076.4 | K27: 0.05120126 | L27: 136.62 | M27: 0.0064986215 | N27: 66068309 | O27: 0 | P27: =IF(N2="",0,+(LOOKUP(9.99999999999999E+307,N2:N33)-N2)) -> 0 | Q27: =IF(P27="",0,+P27/SUM(R3:R33)) -> 0 | R27: =IF(N27="",0,1) -> 1 | S27: =IF(N27="",1,0) -> 0
A28: 44222 | D28: 0.142 | E28: 6930.433 | F28: 328.004 | G28: 184.61 | I28: 20472.3 | J28: 836.28 | K28: 0.040849343 | L28: 161.46 | M28: 0.0078867543 | N28: 66068309 | O28: 0 | P28: Bedaş Aylık | Q28: Bedaş Günlük | R28: =IF(N28="",0,1) -> 1 | S28: =IF(N28="",1,0) -> 0
A29: 44223 | D29: 0.142 | E29: 6935.5 | F29: 328.216 | G29: 184.662 | I29: 20977.38 | J29: 877.68 | K29: 0.041839353 | L29: 215.28 | M29: 0.010262483 | N29: 66068309 | O29: 0 | P29: =IF(D3="",0,+(LOOKUP(9.99999999999999E+307,D2:D33)-D2))*4140 -> -20394944 | Q29: =IF(P29="",0,+P29/SUM(R3:R33)) -> -784420.93 | R29: =IF(N29="",0,1) -> 1 | S29: =IF(N29="",1,0) -> 0
A30: 44224 | D30: 0.142 | E30: 6940.439 | F30: 328.416 | G30: 184.722 | I30: 20447.46 | J30: 828 | K30: 0.040494027 | L30: 248.4 | M30: 0.012148208 | N30: 66068309 | O30: 0 | P30: Tüketim TL | Q30: Cat Birim TL | R30: =IF(N30="",0,1) -> 1 | S30: =IF(N30="",1,0) -> 0
A31: 44225 | D31: 0.142 | E31: 6945.526 | F31: 328.657 | G31: 184.769 | I31: 21060.18 | J31: 997.74 | K31: 0.047375663 | L31: 194.58 | M31: 0.0092392373 | N31: 66068309 | O31: 0 | P31: =P29*Q34 -> -11625118 | Q31: =IF(Q34="",0,(SUM('[1]Günlük Tüketim'!H4:H34)*1.62)/SUM(O3:O33)) -> #DIV/0! | R31: =IF(N31="",0,1) -> 1 | S31: =IF(N31="",1,0) -> 0
A32: 44226 | D32: 0.142 | E32: 6950.31 | F32: 328.782 | G32: 184.81 | I32: 19805.76 | J32: 517.5 | K32: 0.026128763 | L32: 169.74 | M32: 0.0085702341 | N32: 66068309 | O32: 0 | P32: Top. Tüketim TL | Q32: Top. Bedaş kWh | R32: =IF(N32="",0,1) -> 1 | S32: =IF(N32="",1,0) -> 0
A33: 44227 | D33: 0.142 | E33: 6954.801 | F33: 329.086 | G33: 184.857 | I33: 18592.74 | J33: 1258.56 | K33: 0.067690937 | L33: 194.58 | M33: 0.010465375 | N33: 66068309 | O33: 0 | P33: =(P31+Q29*SUM(S3:S33)*Q34) -> -11625118 | Q33: =Q29*31 -> -24317049 | R33: =IF(N33="",0,1) -> 1 | S33: =IF(N33="",1,0) -> 0
A34: 44228 | D34: 0.142 | E34: 6959.689 | F34: 329.347 | G34: 184.89 | I34: 20236.32 | J34: 1080.54 | K34: 0.053396072 | L34: 136.62 | M34: 0.0067512275 | N34: 66068309 | O34: 0 | P34: Bedaş Birim | Q34: 0.57 | R34: =IF(N34="",0,1) -> 1 | S34: =IF(N34="",1,0) -> 0
A35: 44229 | D35: 0.142 | E35: 6964.499 | F35: 329.519 | G35: 184.919 | I35: 19913.4 | J35: 712.08 | K35: 0.035758836 | L35: 120.06 | M35: 0.006029106 | N35: 66068309 | O35: 0 | R35: =IF(N35="",0,1) -> 1 | S35: =IF(N35="",1,0) -> 0
A36: 44230 | D36: 0.142 | E36: 6969.569 | F36: 329.829 | G36: 184.967 | I36: 20989.8 | J36: 1283.4 | K36: 0.061143984 | L36: 198.72 | M36: 0.0094674556 | N36: 66068309 | O36: 0 | R36: =IF(N36="",0,1) -> 1 | S36: =IF(N36="",1,0) -> 0
A37: 44231 | D37: 0.142 | E37: 6974.486 | F37: 329.987 | G37: 185.077 | I37: 20356.38 | J37: 654.12 | K37: 0.032133415 | L37: 455.4 | M37: 0.022371365 | N37: 66068309 | O37: 0 | R37: =IF(N37="",0,1) -> 1 | S37: =IF(N37="",1,0) -> 0
A38: 44232 | D38: 0.142 | E38: 6979.428 | F38: 330.244 | G38: 185.119 | I38: 20459.88 | J38: 1063.98 | K38: 0.052003238 | L38: 173.88 | M38: 0.0084985836 | N38: 66068309 | O38: 0 | R38: =IF(N38="",0,1) -> 1 | S38: =IF(N38="",1,0) -> 0
A39: 44233 | D39: 0.142 | E39: 6983.892 | F39: 330.495 | G39: 185.148 | I39: 18480.96 | J39: 1039.14 | K39: 0.056227599 | L39: 120.06 | M39: 0.0064964158 | N39: 66068309 | O39: 0 | R39: =IF(N39="",0,1) -> 1 | S39: =IF(N39="",1,0) -> 0
A40: 44234 | D40: 0.142 | E40: 6988.638 | F40: 330.707 | G40: 185.192 | I40: 19648.44 | J40: 877.68 | K40: 0.044669195 | L40: 182.16 | M40: 0.009270965 | N40: 66068309 | O40: 0 | R40: =IF(N40="",0,1) -> 1 | S40: =IF(N40="",1,0) -> 0
...
