Workbook

Sheet TOTAL
A1: Site Name | B1: Day | C1: Month | D1: Year | E1: Total Electricity Kwh | F1: Electricity Tariff ($/Kwh) | G1: Natual Gas (m3) | H1: Natural Gas $/m3 | I1: Water Utility Supply (m3) m3 | J1: Water Utility Supply (m3) $/m3 | K1: Room Nights | L1: Total Guests | M1: Utilities day cost dh
A2: Mumbai | B2: 1 | C2: 9 | D2: 2021 | E2: =(IF('Daily HLP'!I4>0,'Daily HLP'!I4,0)) -> 24099.41 | F2: 9 | G2: =(IF('Daily HLP'!M4>0,'Daily HLP'!M4,0)) -> 945.49 | H2: 52 | I2: =(IF('Daily HLP'!P4>0,'Daily HLP'!P4,0)) -> 146 | J2: 118 | K2: =Occupancy!G2 -> 167 | L2: =Occupancy!F2 -> 530 | M2: =E2*F2+G2*H2+#REF!*#REF!+I2*J2 -> #REF!
A3: Mumbai | B3: =B2+1 -> 2 | C3: 9 | D3: 2021 | E3: =(IF('Daily HLP'!I5>0,'Daily HLP'!I5,0)) -> 22799.34 | F3: 9 | G3: =(IF('Daily HLP'!M5>0,'Daily HLP'!M5,0)) -> 861.03 | H3: 52 | I3: =(IF('Daily HLP'!P5>0,'Daily HLP'!P5,0)) -> 183 | J3: 118 | K3: =Occupancy!G3 -> 158 | L3: =Occupancy!F3 -> 633 | M3: =E3*F3+G3*H3+#REF!*#REF!+I3*J3 -> #REF!
A4: Mumbai | B4: =B3+1 -> 3 | C4: 9 | D4: 2021 | E4: =(IF('Daily HLP'!I6>0,'Daily HLP'!I6,0)) -> 21890.56 | F4: 9 | G4: =(IF('Daily HLP'!M6>0,'Daily HLP'!M6,0)) -> 866.202 | H4: 52 | I4: =(IF('Daily HLP'!P6>0,'Daily HLP'!P6,0)) -> 241 | J4: 118 | K4: =Occupancy!G4 -> 148 | L4: =Occupancy!F4 -> 505 | M4: =E4*F4+G4*H4+#REF!*#REF!+I4*J4 -> #REF!
A5: Mumbai | B5: =B4+1 -> 4 | C5: 9 | D5: 2021 | E5: =(IF('Daily HLP'!I7>0,'Daily HLP'!I7,0)) -> 21459.68 | F5: 9 | G5: =(IF('Daily HLP'!M7>0,'Daily HLP'!M7,0)) -> 821.238 | H5: 52 | I5: =(IF('Daily HLP'!P7>0,'Daily HLP'!P7,0)) -> 203 | J5: 118 | K5: =Occupancy!G5 -> 166 | L5: =Occupancy!F5 -> 414 | M5: =E5*F5+G5*H5+#REF!*#REF!+I5*J5 -> #REF!
A6: Mumbai | B6: =B5+1 -> 5 | C6: 9 | D6: 2021 | E6: =(IF('Daily HLP'!I8>0,'Daily HLP'!I8,0)) -> 21315.16 | F6: 9 | G6: =(IF('Daily HLP'!M8>0,'Daily HLP'!M8,0)) -> 851.14 | H6: 52 | I6: =(IF('Daily HLP'!P8>0,'Daily HLP'!P8,0)) -> 261 | J6: 118 | K6: =Occupancy!G6 -> 123 | L6: =Occupancy!F6 -> 417 | M6: =E6*F6+G6*H6+#REF!*#REF!+I6*J6 -> #REF!
A7: Mumbai | B7: =B6+1 -> 6 | C7: 9 | D7: 2021 | E7: =(IF('Daily HLP'!I9>0,'Daily HLP'!I9,0)) -> 22055.52 | F7: 9 | G7: =(IF('Daily HLP'!M9>0,'Daily HLP'!M9,0)) -> 920.32 | H7: 52 | I7: =(IF('Daily HLP'!P9>0,'Daily HLP'!P9,0)) -> 163 | J7: 118 | K7: =Occupancy!G7 -> 130 | L7: =Occupancy!F7 -> 356 | M7: =E7*F7+G7*H7+#REF!*#REF!+I7*J7 -> #REF!
A8: Mumbai | B8: =B7+1 -> 7 | C8: 9 | D8: 2021 | E8: =(IF('Daily HLP'!I10>0,'Daily HLP'!I10,0)) -> 20481.92 | F8: 9 | G8: =(IF('Daily HLP'!M10>0,'Daily HLP'!M10,0)) -> 856.76 | H8: 52 | I8: =(IF('Daily HLP'!P10>0,'Daily HLP'!P10,0)) -> 218 | J8: 118 | K8: =Occupancy!G8 -> 145 | L8: =Occupancy!F8 -> 402 | M8: =E8*F8+G8*H8+#REF!*#REF!+I8*J8 -> #REF!
A9: Mumbai | B9: =B8+1 -> 8 | C9: 9 | D9: 2021 | E9: =(IF('Daily HLP'!I11>0,'Daily HLP'!I11,0)) -> 22311.4 | F9: 9 | G9: =(IF('Daily HLP'!M11>0,'Daily HLP'!M11,0)) -> 851.33 | H9: 52 | I9: =(IF('Daily HLP'!P11>0,'Daily HLP'!P11,0)) -> 209 | J9: 118 | K9: =Occupancy!G9 -> 164 | L9: =Occupancy!F9 -> 467 | M9: =E9*F9+G9*H9+#REF!*#REF!+I9*J9 -> #REF!
A10: Mumbai | B10: =B9+1 -> 9 | C10: 9 | D10: 2021 | E10: =(IF('Daily HLP'!I12>0,'Daily HLP'!I12,0)) -> 21965.01 | F10: 9 | G10: =(IF('Daily HLP'!M12>0,'Daily HLP'!M12,0)) -> 851.49 | H10: 52 | I10: =(IF('Daily HLP'!P12>0,'Daily HLP'!P12,0)) -> 200 | J10: 118 | K10: =Occupancy!G10 -> 113 | L10: =Occupancy!F10 -> 444 | M10: =E10*F10+G10*H10+#REF!*#REF!+I10*J10 -> #REF!
A11: Mumbai | B11: =B10+1 -> 10 | C11: 9 | D11: 2021 | E11: =(IF('Daily HLP'!I13>0,'Daily HLP'!I13,0)) -> 21417 | F11: 9 | G11: =(IF('Daily HLP'!M13>0,'Daily HLP'!M13,0)) -> 796 | H11: 52 | I11: =(IF('Daily HLP'!P13>0,'Daily HLP'!P13,0)) -> 197 | J11: 118 | K11: =Occupancy!G11 -> 141 | L11: =Occupancy!F11 -> 327 | M11: =E11*F11+G11*H11+#REF!*#REF!+I11*J11 -> #REF!
A12: Mumbai | B12: =B11+1 -> 11 | C12: 9 | D12: 2021 | E12: =(IF('Daily HLP'!I14>0,'Daily HLP'!I14,0)) -> 21441 | F12: 9 | G12: =(IF('Daily HLP'!M14>0,'Daily HLP'!M14,0)) -> 881 | H12: 52 | I12: =(IF('Daily HLP'!P14>0,'Daily HLP'!P14,0)) -> 211 | J12: 118 | K12: =Occupancy!G12 -> 0 | L12: =Occupancy!F12 -> 0 | M12: =E12*F12+G12*H12+#REF!*#REF!+I12*J12 -> #REF!
A13: Mumbai | B13: =B12+1 -> 12 | C13: 9 | D13: 2021 | E13: =(IF('Daily HLP'!I15>0,'Daily HLP'!I15,0)) -> 22425.27 | F13: 9 | G13: =(IF('Daily HLP'!M15>0,'Daily HLP'!M15,0)) -> 916.831 | H13: 52 | I13: =(IF('Daily HLP'!P15>0,'Daily HLP'!P15,0)) -> 223 | J13: 118 | K13: =Occupancy!G13 -> 0 | L13: =Occupancy!F13 -> 0 | M13: =E13*F13+G13*H13+#REF!*#REF!+I13*J13 -> #REF!
A14: Mumbai | B14: =B13+1 -> 13 | C14: 9 | D14: 2021 | E14: =(IF('Daily HLP'!I16>0,'Daily HLP'!I16,0)) -> 22500 | F14: 9 | G14: =(IF('Daily HLP'!M16>0,'Daily HLP'!M16,0)) -> 0 | H14: 52 | I14: =(IF('Daily HLP'!P16>0,'Daily HLP'!P16,0)) -> 0 | J14: 118 | K14: =Occupancy!G14 -> 0 | L14: =Occupancy!F14 -> 0 | M14: =E14*F14+G14*H14+#REF!*#REF!+I14*J14 -> #REF!
... A31: Mumbai | B31: =B30+1 -> 30 | C31: 9 | D31: 2021 | E31: =(IF('Daily HLP'!I33>0,'Daily HLP'!I33,0)) -> 22500 | F31: 9 | G31: =(IF('Daily HLP'!M33>0,'Daily HLP'!M33,0)) -> 877 | H31: 52 | I31: =(IF('Daily HLP'!P33>0,'Daily HLP'!P33,0)) -> 249 | J31: 118 | K31: =Occupancy!G31 -> 0 | L31: =Occupancy!F31 -> 0 | M31: =E31*F31+G31*H31+#REF!*#REF!+I31*J31 -> #REF!
A32: Mumbai | B32: =B31+1 -> 31 | C32: 9 | D32: 2021 | E32: =(IF('Daily HLP'!I34>0,'Daily HLP'!I34,0)) -> 22500 | F32: 9 | G32: =(IF('Daily HLP'!M34>0,'Daily HLP'!M34,0)) -> 749 | H32: 52 | I32: =(IF('Daily HLP'!P34>0,'Daily HLP'!P34,0)) -> 202 | J32: 118 | K32: =Occupancy!G32 -> 0 | L32: =Occupancy!F32 -> 0

Sheet Submetering
A1: Site Name | B1: Day | C1: Month | D1: Year | E1: ='Section Load'!F4 -> HVAC | F1: ='Section Load'!G4 -> Fire & Emergency PP | G1: ='Section Load'!H4 -> Main PP | H1: ='Section Load'!I4 -> Lighting PP | I1: ='Section Load'!J4 -> CH-1+ CH2+CH3+CH4 | J1: ='Section Load'!K4 -> Chilled water Pump | K1: ='Section Load'!L4 -> Ball Room-1 | L1: ='Section Load'!M4 -> Ball Room-2 | ... AL1: ='Section Load'!AM4 -> Cooling Tower | AM1: R.o.plant | AN1: STP Water Prod | AO1: Domestic Zone-1 | AP1: Domestic Zone-2 | AQ1: Domestic Zone-3 | AR1: Flush Zone -1 | AS1: Flush Zone -2 | AT1: Flush Zone -3 | AU1: Swimming pool | AV1: B2 Laundry | AW1: Boiler Feed Water | AX1: cooling tower filling water | AY1: STP flush(new water meter) | AZ1: Garden Water Pump | BA1: Flush Zone 2 pump meter | BB1: Flush Zone 3 Pump Meter (wtp transfer ) | BC1: Flush Tanker-Zone-1 | BD1: Total Domestic Water (Tanker (R.O) +BMC) | BE1: Total Domestic Consumption | BF1: Total STP Consumption | BG1: ='Section Load'!AN4 -> MGL | BH1: ='Section Load'!AO4 -> HWG | BI1: ='Section Load'!AP4 -> Prato | BJ1: ='Section Load'!AQ4 -> BR-1 | BK1: ='Section Load'!AR4 -> SanQi IND | BL1: ='Section Load'!AS4 -> SanQi JPN | BM1: ='Section Load'!AT4 -> Boiler
A2: Mumbai | B2: 1 | C2: 9 | D2: 2021 | E2: =(IF('Section Load'!F5>0,'Section Load'!F5,0)) -> 3258.13 | F2: =(IF('Section Load'!G5>0,'Section Load'!G5,0)) -> 1523.03 | G2: =(IF('Section Load'!H5>0,'Section Load'!H5,0)) -> 1668.3 | H2: =(IF('Section Load'!I5>0,'Section Load'!I5,0)) -> 3713.96 | I2: =(IF('Section Load'!J5>0,'Section Load'!J5,0)) -> 7992 | J2: =(IF('Section Load'!K5>0,'Section Load'!K5,0)) -> 2885 | K2: =(IF('Section Load'!L5>0,'Section Load'!L5,0)) -> 1444 | L2: =(IF('Section Load'!M5>0,'Section Load'!M5,0)) -> 1101.96 | ... AL2: =(IF('Section Load'!AM5>0,'Section Load'!AM5,0)) -> 740 | AM2: =(IF('Water Report'!$D$7>0,'Water Report'!$D$7,0)) -> 62 | AN2: =(IF('Water Report'!$D$8>0,'Water Report'!$D$8,0)) -> 163 | AO2: =(IF('Water Report'!$D$9>0,'Water Report'!$D$9,0)) -> 66 | AP2: =(IF('Water Report'!$D$10>0,'Water Report'!$D$10,0)) -> 18 | AQ2: =(IF('Water Report'!$D$11>0,'Water Report'!$D$11,0)) -> 24 | AR2: =(IF('Water Report'!$D$13>0,'Water Report'!$D$13,0)) -> 11 | AS2: =(IF('Water Report'!$D$14>0,'Water Report'!$D$14,0)) -> 13 | AT2: =(IF('Water Report'!$D$15>0,'Water Report'!$D$15,0)) -> 7 | AU2: =(IF('Water Report'!$D$17>0,'Water Report'!$D$17,0)) -> 0 | AV2: =(IF('Water Report'!$D$18>0,'Water Report'!$D$18,0)) -> 7 | AW2: =(IF('Water Report'!$D$19>0,'Water Report'!$D$19,0)) -> 10 | AX2: =(IF('Water Report'!$D$21>0,'Water Report'!$D$21,0)) -> 93 | AY2: =(IF('Water Report'!$D$22>0,'Water Report'!$D$22,0)) -> 0 | AZ2: =(IF('Water Report'!$D$23>0,'Water Report'!$D$23,0)) -> 0 | BA2: =(IF('Water Report'!$D$14>0,'Water Report'!$D$14,0)) -> 13 | BB2: =(IF('Water Report'!$D$15>0,'Water Report'!$D$15,0)) -> 7 | BC2: =(IF('Water Report'!$D$13>0,'Water Report'!$D$13,0)) -> 11 | BD2: =(IF('Water Report'!$D$24>0,'Water Report'!$D$24,0)) -> 146 | BE2: =(IF('Water Report'!$D$25>0,'Water Report'!$D$25,0)) -> 128 | BF2: =(IF('Water Report'!$D$27>0,'Water Report'!$D$27,0)) -> 104 | BG2: =(IF('Section Load'!AN5>0,'Section Load'!AN5,0)) -> 945.49 | BH2: =(IF('Section Load'!AO5>0,'Section Load'!AO5,0)) -> 265 | BI2: =(IF('Section Load'!AP5>0,'Section Load'!AP5,0)) -> 0 | BJ2: =(IF('Section Load'!AQ5>0,'Section Load'!AQ5,0)) -> 88.8 | BK2: =(IF('Section Load'!AR5>0,'Section Load'!AR5,0)) -> 44.1 | BL2: =(IF('Section Load'!AS5>0,'Section Load'!AS5,0)) -> 1.9 | BM2: =(IF('Section Load'!AT5>0,'Section Load'!AT5,0)) -> 545.69
A3: Mumbai | B3: =B2+1 -> 2 | C3: 9 | D3: 2021 | E3: =(IF('Section Load'!F6>0,'Section Load'!F6,0)) -> 3230.17 | F3: =(IF('Section Load'!G6>0,'Section Load'!G6,0)) -> 1548.17 | G3: =(IF('Section Load'!H6>0,'Section Load'!H6,0)) -> 1746.07 | H3: =(IF('Section Load'!I6>0,'Section Load'!I6,0)) -> 3969.52 | I3: =(IF('Section Load'!J6>0,'Section Load'!J6,0)) -> 6815.14 | J3: =(IF('Section Load'!K6>0,'Section Load'!K6,0)) -> 2704.9 | K3: =(IF('Section Load'!L6>0,'Section Load'!L6,0)) -> 1424.79 | L3: =(IF('Section Load'!M6>0,'Section Load'!M6,0)) -> 966.12 | ... AL3: =(IF('Section Load'!AM6>0,'Section Load'!AM6,0)) -> 634 | AM3: =(IF('Water Report'!$E$7>0,'Water Report'!$E$7,0)) -> 91 | AN3: =(IF('Water Report'!$E$8>0,'Water Report'!$E$8,0)) -> 144 | AO3: =(IF('Water Report'!$E$9>0,'Water Report'!$E$9,0)) -> 84 | AP3: =(IF('Water Report'!$E$10>0,'Water Report'!$E$10,0)) -> 21 | AQ3: =(IF('Water Report'!$E$11>0,'Water Report'!$E$11,0)) -> 37 | AR3: =(IF('Water Report'!$E$13>0,'Water Report'!$E$13,0)) -> 29 | AS3: =(IF('Water Report'!$E$14>0,'Water Report'!$E$14,0)) -> 11 | AT3: =(IF('Water Report'!$E$15>0,'Water Report'!$E$15,0)) -> 13 | AU3: =(IF('Water Report'!$E$17>0,'Water Report'!$E$17,0)) -> 0 | AV3: =(IF('Water Report'!$E$18>0,'Water Report'!$E$18,0)) -> 9 | AW3: =(IF('Water Report'!$E$19>0,'Water Report'!$E$19,0)) -> 9 | AX3: =(IF('Water Report'!$E$21>0,'Water Report'!$E$21,0)) -> 79 | AY3: =(IF('Water Report'!$E$22>0,'Water Report'!$E$22,0)) -> 0 | AZ3: =(IF('Water Report'!$E$23>0,'Water Report'!$E$23,0)) -> 0 | BA3: =(IF('Water Report'!$E$14>0,'Water Report'!$E$14,0)) -> 11 | BB3: =(IF('Water Report'!$E$15>0,'Water Report'!$E$15,0)) -> 13 | BC3: =(IF('Water Report'!$E$13>0,'Water Report'!$E$13,0)) -> 29 | BD3: =(IF('Water Report'!$E$24>0,'Water Report'!$E$24,0)) -> 183 | BE3: =(IF('Water Report'!$E$25>0,'Water Report'!$E$25,0)) -> 166 | BF3: =(IF('Water Report'!$E$27>0,'Water Report'!$E$27,0)) -> 108 | BG3: =(IF('Section Load'!AN6>0,'Section Load'!AN6,0)) -> 861.03 | BH3: =(IF('Section Load'!AO6>0,'Section Load'!AO6,0)) -> 213.16 | BI3: =(IF('Section Load'!AP6>0,'Section Load'!AP6,0)) -> 0 | BJ3: =(IF('Section Load'!AQ6>0,'Section Load'!AQ6,0)) -> 85.39 | BK3: =(IF('Section Load'!AR6>0,'Section Load'!AR6,0)) -> 47.2 | BL3: =(IF('Section Load'!AS6>0,'Section Load'!AS6,0)) -> 1.3 | BM3: =(IF('Section Load'!AT6>0,'Section Load'!AT6,0)) -> 513.98
A4: Mumbai | B4: =B3+1 -> 3 | C4: 9 | D4: 2021 | E4: =(IF('Section Load'!F7>0,'Section Load'!F7,0)) -> 2702.48 | F4: =(IF('Section Load'!G7>0,'Section Load'!G7,0)) -> 1487.28 | G4: =(IF('Section Load'!H7>0,'Section Load'!H7,0)) -> 1807.5 | H4: =(IF('Section Load'!I7>0,'Section Load'!I7,0)) -> 3782.84 | I4: =(IF('Section Load'!J7>0,'Section Load'!J7,0)) -> 6081.98 | J4: =(IF('Section Load'!K7>0,'Section Load'!K7,0)) -> 2608.6 | K4: =(IF('Section Load'!L7>0,'Section Load'!L7,0)) -> 1619.72 | L4: =(IF('Section Load'!M7>0,'Section Load'!M7,0)) -> 664.27 | ... AL4: =(IF('Section Load'!AM7>0,'Section Load'!AM7,0)) -> 597 | AM4: =(IF('Water Report'!$F$7>0,'Water Report'!$F$7,0)) -> 102 | AN4: =(IF('Water Report'!$F$8>0,'Water Report'!$F$8,0)) -> 123 | AO4: =(IF('Water Report'!$F$9>0,'Water Report'!$G$9,0)) -> 83 | AP4: =(IF('Water Report'!$F$10>0,'Water Report'!$F$10,0)) -> 24 | AQ4: =(IF('Water Report'!$F$11>0,'Water Report'!$F$11,0)) -> 30 | AR4: =(IF('Water Report'!$F$13>0,'Water Report'!$F$13,0)) -> 29 | AS4: =(IF('Water Report'!$F$14>0,'Water Report'!$F$14,0)) -> 13 | AT4: =(IF('Water Report'!$F$15>0,'Water Report'!$F$15,0)) -> 0 | AU4: =(IF('Water Report'!$F$17>0,'Water Report'!$F$17,0)) -> 0 | AV4: =(IF('Water Report'!$F$18>0,'Water Report'!$F$18,0)) -> 8 | AW4: =(IF('Water Report'!$F$19>0,'Water Report'!$F$19,0)) -> 8 | AX4: =(IF('Water Report'!$F$21>0,'Water Report'!$F$21,0)) -> 50 | AY4: =(IF('Water Report'!$F$22>0,'Water Report'!$F$22,0)) -> 0 | AZ4: =(IF('Water Report'!$F$23>0,'Water Report'!$F$23,0)) -> 5 | BA4: =(IF('Water Report'!$F$14>0,'Water Report'!$F$14,0)) -> 13 | BB4: =(IF('Water Report'!$F$15>0,'Water Report'!$F$15,0)) -> 0 | BC4: =(IF('Water Report'!$F$13>0,'Water Report'!$F$13,0)) -> 29 | BD4: =(IF('Water Report'!$F$24>0,'Water Report'!$F$24,0)) -> 241 | BE4: =(IF('Water Report'!$F$25>0,'Water Report'!$F$25,0)) -> 154 | BF4: =(IF('Water Report'!$F$27>0,'Water Report'!$F$27,0)) -> 84 | BG4: =(IF('Section Load'!AN7>0,'Section Load'!AN7,0)) -> 866.202 | BH4: =(IF('Section Load'!AO7>0,'Section Load'!AO7,0)) -> 248.07 | BI4: =(IF('Section Load'!AP7>0,'Section Load'!AP7,0)) -> 0 | BJ4: =(IF('Section Load'!AQ7>0,'Section Load'!AQ7,0)) -> 95.65 | BK4: =(IF('Section Load'!AR7>0,'Section Load'!AR7,0)) -> 49.5 | BL4: =(IF('Section Load'!AS7>0,'Section Load'!AS7,0)) -> 1.2 | BM4: =(IF('Section Load'!AT7>0,'Section Load'!AT7,0)) -> 471.782
A5: Mumbai | B5: =B4+1 -> 4 | C5: 9 | D5: 2021 | E5: =(IF('Section Load'!F8>0,'Section Load'!F8,0)) -> 3147.55 | F5: =(IF('Section Load'!G8>0,'Section Load'!G8,0)) -> 1491.33 | G5: =(IF('Section Load'!H8>0,'Section Load'!H8,0)) -> 1776.73 | H5: =(IF('Section Load'!I8>0,'Section Load'!I8,0)) -> 3801.03 | I5: =(IF('Section Load'!J8>0,'Section Load'!J8,0)) -> 6292.56 | J5: =(IF('Section Load'!K8>0,'Section Load'!K8,0)) -> 2655.6 | K5: =(IF('Section Load'!L8>0,'Section Load'!L8,0)) -> 1085.36 | L5: =(IF('Section Load'!M8>0,'Section Load'!M8,0)) -> 634.54 | ... AL5: =(IF('Section Load'!AM8>0,'Section Load'!AM8,0)) -> 660 | AM5: =(IF('Water Report'!$G$7>0,'Water Report'!$F$7,0)) -> 102 | AN5: =(IF('Water Report'!$G$8>0,'Water Report'!$F$8,0)) -> 123 | AO5: =(IF('Water Report'!$G$9>0,'Water Report'!$H$9,0)) -> 67 | AP5: =(IF('Water Report'!$G$10>0,'Water Report'!$G$10,0)) -> 21 | AQ5: =(IF('Water Report'!$G$11>0,'Water Report'!$G$11,0)) -> 29 | AR5: =(IF('Water Report'!$G$13>0,'Water Report'!$G$13,0)) -> 32 | AS5: =(IF('Water Report'!$G$14>0,'Water Report'!$G$14,0)) -> 14 | AT5: =(IF('Water Report'!$G$15>0,'Water Report'!$G$15,0)) -> 7 | AU5: =(IF('Water Report'!$G$17>0,'Water Report'!$G$17,0)) -> 0 | AV5: =(IF('Water Report'!$G$18>0,'Water Report'!$G$18,0)) -> 9 | AW5: =(IF('Water Report'!$G$19>0,'Water Report'!$G$19,0)) -> 8 | AX5: =(IF('Water Report'!$G$21>0,'Water Report'!$G$21,0)) -> 62 | AY5: =(IF('Water Report'!$G$22>0,'Water Report'!$G$22,0)) -> 0 | AZ5: =(IF('Water Report'!$G$23>0,'Water Report'!$G$23,0)) -> 2 | BA5: =(IF('Water Report'!$G$14>0,'Water Report'!$G$14,0)) -> 14 | BB5: =(IF('Water Report'!$G$15>0,'Water Report'!$G$15,0)) -> 7 | BC5: =(IF('Water Report'!$G$13>0,'Water Report'!$G$13,0)) -> 32 | BD5: =(IF('Water Report'!$G$24>0,'Water Report'!$G$24,0)) -> 203 | BE5: =(IF('Water Report'!$G$25>0,'Water Report'!$G$25,0)) -> 154 | BF5: =(IF('Water Report'!$G$27>0,'Water Report'!$G$27,0)) -> 96 | BG5: =(IF('Section Load'!AN8>0,'Section Load'!AN8,0)) -> 821.238 | BH5: =(IF('Section Load'!AO8>0,'Section Load'!AO8,0)) -> 241.89 | BI5: =(IF('Section Load'!AP8>0,'Section Load'!AP8,0)) -> 0 | BJ5: =(IF('Section Load'!AQ8>0,'Section Load'!AQ8,0)) -> 91.13 | BK5: =(IF('Section Load'!AR8>0,'Section Load'!AR8,0)) -> 35.2 | BL5: =(IF('Section Load'!AS8>0,'Section Load'!AS8,0)) -> 4.7 | BM5: =(IF('Section Load'!AT8>0,'Section Load'!AT8,0)) -> 448.318
A6: Mumbai | B6: =B5+1 -> 5 | C6: 9 | D6: 2021 | E6: =(IF('Section Load'!F9>0,'Section Load'!F9,0)) -> 3023.37 | F6: =(IF('Section Load'!G9>0,'Section Load'!G9,0)) -> 1454.15 | G6: =(IF('Section Load'!H9>0,'Section Load'!H9,0)) -> 1714.86 | H6: =(IF('Section Load'!I9>0,'Section Load'!I9,0)) -> 3765.16 | I6: =(IF('Section Load'!J9>0,'Section Load'!J9,0)) -> 6489.18 | J6: =(IF('Section Load'!K9>0,'Section Load'!K9,0)) -> 2643.4 | K6: =(IF('Section Load'!L9>0,'Section Load'!L9,0)) -> 1139.6 | L6: =(IF('Section Load'!M9>0,'Section Load'!M9,0)) -> 566.8 | ... AL6: =(IF('Section Load'!AM9>0,'Section Load'!AM9,0)) -> 589 | AM6: =(IF('Water Report'!$H$7>0,'Water Report'!$H$7,0)) -> 107 | AN6: =(IF('Water Report'!$H$8>0,'Water Report'!$H$8,0)) -> 155 | AO6: =(IF('Water Report'!$H$9>0,'Water Report'!$H$9,0)) -> 67 | AP6: =(IF('Water Report'!$H$10>0,'Water Report'!$H$10,0)) -> 27 | AQ6: =(IF('Water Report'!$H$11>0,'Water Report'!$H$11,0)) -> 30 | AR6: =(IF('Water Report'!$H$13>0,'Water Report'!$H$13,0)) -> 27 | AS6: =(IF('Water Report'!$H$14>0,'Water Report'!$H$14,0)) -> 22 | AT6: =(IF('Water Report'!$H$15>0,'Water Report'!$H$15,0)) -> 11 | AU6: =(IF('Water Report'!$H$17>0,'Water Report'!$H$17,0)) -> 0 | AV6: =(IF('Water Report'!$H$18>0,'Water Report'!$H$18,0)) -> 6 | AW6: =(IF('Water Report'!$H$19>0,'Water Report'!$H$19,0)) -> 7 | AX6: =(IF('Water Report'!$H$21>0,'Water Report'!$H$21,0)) -> 76 | AY6: =(IF('Water Report'!$H$22>0,'Water Report'!$H$22,0)) -> 0 | AZ6: =(IF('Water Report'!$H$23>0,'Water Report'!$H$23,0)) -> 0 | BA6: =(IF('Water Report'!$H$14>0,'Water Report'!$H$14,0)) -> 22 | BB6: =(IF('Water Report'!$H$15>0,'Water Report'!$H$15,0)) -> 11 | BC6: =(IF('Water Report'!$H$13>0,'Water Report'!$H$13,0)) -> 27 | BD6: =(IF('Water Report'!$H$24>0,'Water Report'!$H$24,0)) -> 261 | BE6: =(IF('Water Report'!$H$25>0,'Water Report'!$H$25,0)) -> 157 | BF6: =(IF('Water Report'!$H$27>0,'Water Report'!$H$27,0)) -> 103 | BG6: =(IF('Section Load'!AN9>0,'Section Load'!AN9,0)) -> 851.14 | BH6: =(IF('Section Load'!AO9>0,'Section Load'!AO9,0)) -> 255.31 | BI6: =(IF('Section Load'!AP9>0,'Section Load'!AP9,0)) -> 0 | BJ6: =(IF('Section Load'!AQ9>0,'Section Load'!AQ9,0)) -> 94.22 | BK6: =(IF('Section Load'!AR9>0,'Section Load'!AR9,0)) -> 40.9 | BL6: =(IF('Section Load'!AS9>0,'Section Load'!AS9,0)) -> 2.8 | BM6: =(IF('Section Load'!AT9>0,'Section Load'!AT9,0)) -> 457.91
A7: Mumbai | B7: =B6+1 -> 6 | C7: 9 | D7: 2021 | E7: =(IF('Section Load'!F10>0,'Section Load'!F10,0)) -> 3085.78 | F7: =(IF('Section Load'!G10>0,'Section Load'!G10,0)) -> 1828.49 | G7: =(IF('Section Load'!H10>0,'Section Load'!H10,0)) -> 1659.62 | H7: =(IF('Section Load'!I10>0,'Section Load'!I10,0)) -> 3883.88 | I7: =(IF('Section Load'!J10>0,'Section Load'!J10,0)) -> 7083.12 | J7: =(IF('Section Load'!K10>0,'Section Load'!K10,0)) -> 2661.8 | K7: =(IF('Section Load'!L10>0,'Section Load'!L10,0)) -> 956.36 | L7: =(IF('Section Load'!M10>0,'Section Load'!M10,0)) -> 685.98 | ... AL7: =(IF('Section Load'!AM10>0,'Section Load'!AM10,0)) -> 601 | AM7: =(IF('Water Report'!$I$7>0,'Water Report'!$I$7,0)) -> 70 | AN7: =(IF('Water Report'!$I$8>0,'Water Report'!$I$8,0)) -> 163 | AO7: =(IF('Water Report'!$I$9>0,'Water Report'!$I$9,0)) -> 71 | AP7: =(IF('Water Report'!$I$10>0,'Water Report'!$I$10,0)) -> 17 | AQ7: =(IF('Water Report'!$I$11>0,'Water Report'!$I$11,0)) -> 27 | AR7: =(IF('Water Report'!$I$13>0,'Water Report'!$I$13,0)) -> 17 | AS7: =(IF('Water Report'!$I$14>0,'Water Report'!$I$14,0)) -> 12 | AT7: =(IF('Water Report'!$I$15>0,'Water Report'!$I$15,0)) -> 9 | AU7: =(IF('Water Report'!$I$17>0,'Water Report'!$I$17,0)) -> 0 | AV7: =(IF('Water Report'!$I$18>0,'Water Report'!$I$18,0)) -> 10 | AW7: =(IF('Water Report'!$I$19>0,'Water Report'!$I$19,0)) -> 8 | AX7: =(IF('Water Report'!$I$21>0,'Water Report'!$I$21,0)) -> 66 | AY7: =(IF('Water Report'!$I$22>0,'Water Report'!$I$22,0)) -> 0 | AZ7: =(IF('Water Report'!$I$23>0,'Water Report'!$I$23,0)) -> 4 | BA7: =(IF('Water Report'!$I$14>0,'Water Report'!$I$14,0)) -> 12 | BB7: =(IF('Water Report'!$I$15>0,'Water Report'!$I$15,0)) -> 9 | BC7: =(IF('Water Report'!$I$13>0,'Water Report'!$I$13,0)) -> 17 | BD7: =(IF('Water Report'!$I$24>0,'Water Report'!$I$24,0)) -> 163 | BE7: =(IF('Water Report'!$I$25>0,'Water Report'!$I$25,0)) -> 136 | BF7: =(IF('Water Report'!$I$27>0,'Water Report'!$I$27,0)) -> 87 | BG7: =(IF('Section Load'!AN10>0,'Section Load'!AN10,0)) -> 920.32 | BH7: =(IF('Section Load'!AO10>0,'Section Load'!AO10,0)) -> 286.57 | BI7: =(IF('Section Load'!AP10>0,'Section Load'!AP10,0)) -> 0 | BJ7: =(IF('Section Load'!AQ10>0,'Section Load'!AQ10,0)) -> 95.09 | BK7: =(IF('Section Load'!AR10>0,'Section Load'!AR10,0)) -> 35.5 | BL7: =(IF('Section Load'!AS10>0,'Section Load'!AS10,0)) -> 1 | BM7: =(IF('Section Load'!AT10>0,'Section Load'!AT10,0)) -> 502.16
A8: Mumbai | B8: =B7+1 -> 7 | C8: 9 | D8: 2021 | E8: =(IF('Section Load'!F11>0,'Section Load'!F11,0)) -> 4524.89 | F8: =(IF('Section Load'!G11>0,'Section Load'!G11,0)) -> 1681.05 | G8: =(IF('Section Load'!H11>0,'Section Load'!H11,0)) -> 1663.89 | H8: =(IF('Section Load'!I11>0,'Section Load'!I11,0)) -> 3792.29 | I8: =(IF('Section Load'!J11>0,'Section Load'!J11,0)) -> 5975 | J8: =(IF('Section Load'!K11>0,'Section Load'!K11,0)) -> 2465.8 | K8: =(IF('Section Load'!L11>0,'Section Load'!L11,0)) -> 928.56 | L8: =(IF('Section Load'!M11>0,'Section Load'!M11,0)) -> 590.48 | ... AL8: =(IF('Section Load'!AM11>0,'Section Load'!AM11,0)) -> 607 | AM8: =(IF('Water Report'!$J$7>0,'Water Report'!$J$7,0)) -> 83 | AN8: =(IF('Water Report'!$J$8>0,'Water Report'!$J$8,0)) -> 100 | AO8: =(IF('Water Report'!$J$9>0,'Water Report'!$J$9,0)) -> 71 | AP8: =(IF('Water Report'!$J$10>0,'Water Report'!$J$10,0)) -> 14 | AQ8: =(IF('Water Report'!$J$11>0,'Water Report'!$J$11,0)) -> 38 | AR8: =(IF('Water Report'!$J$13>0,'Water Report'!$J$13,0)) -> 31 | AS8: =(IF('Water Report'!$J$14>0,'Water Report'!$J$14,0)) -> 12 | AT8: =(IF('Water Report'!$J$15>0,'Water Report'!$J$15,0)) -> 7 | AU8: =(IF('Water Report'!$J$17>0,'Water Report'!$J$17,0)) -> 0 | AV8: =(IF('Water Report'!$J$18>0,'Water Report'!$J$18,0)) -> 7 | AW8: =(IF('Water Report'!$J$19>0,'Water Report'!$J$19,0)) -> 8 | AX8: =(IF('Water Report'!$J$21>0,'Water Report'!$J$21,0)) -> 62 | AY8: =(IF('Water Report'!$J$22>0,'Water Report'!$J$22,0)) -> 0 | AZ8: =(IF('Water Report'!$J$23>0,'Water Report'!$J$23,0)) -> 0 | BA8: =(IF('Water Report'!$J$14>0,'Water Report'!$J$14,0)) -> 12 | BB8: =(IF('Water Report'!$J$15>0,'Water Report'!$J$15,0)) -> 7 | BC8: =(IF('Water Report'!$J$13>0,'Water Report'!$J$13,0)) -> 31 | BD8: =(IF('Water Report'!$J$24>0,'Water Report'!$J$24,0)) -> 218 | BE8: =(IF('Water Report'!$J$25>0,'Water Report'!$J$25,0)) -> 142 | BF8: =(IF('Water Report'!$J$27>0,'Water Report'!$J$27,0)) -> 93 | BG8: =(IF('Section Load'!AN11>0,'Section Load'!AN11,0)) -> 856.76 | BH8: =(IF('Section Load'!AO11>0,'Section Load'!AO11,0)) -> 234.16 | BI8: =(IF('Section Load'!AP11>0,'Section Load'!AP11,0)) -> 0 | BJ8: =(IF('Section Load'!AQ11>0,'Section Load'!AQ11,0)) -> 85.46 | BK8: =(IF('Section Load'!AR11>0,'Section Load'!AR11,0)) -> 51.4 | BL8: =(IF('Section Load'!AS11>0,'Section Load'!AS11,0)) -> 1.2 | BM8: =(IF('Section Load'!AT11>0,'Section Load'!AT11,0)) -> 484.94
A9: Mumbai | B9: =B8+1 -> 8 | C9: 9 | D9: 2021 | E9: =(IF('Section Load'!F12>0,'Section Load'!F12,0)) -> 4765.96 | F9: =(IF('Section Load'!G12>0,'Section Load'!G12,0)) -> 1742.43 | G9: =(IF('Section Load'!H12>0,'Section Load'!H12,0)) -> 1706.96 | H9: =(IF('Section Load'!I12>0,'Section Load'!I12,0)) -> 3944.41 | I9: =(IF('Section Load'!J12>0,'Section Load'!J12,0)) -> 7061.62 | J9: =(IF('Section Load'!K12>0,'Section Load'!K12,0)) -> 2588.6 | K9: =(IF('Section Load'!L12>0,'Section Load'!L12,0)) -> 948.28 | L9: =(IF('Section Load'!M12>0,'Section Load'!M12,0)) -> 730.86 | ... AL9: =(IF('Section Load'!AM12>0,'Section Load'!AM12,0)) -> 637 | AM9: =(IF('Water Report'!$K$7>0,'Water Report'!$K$7,0)) -> 87 | AN9: =(IF('Water Report'!$K$8>0,'Water Report'!$K$8,0)) -> 195 | AO9: =(IF('Water Report'!$K$9>0,'Water Report'!$K$9,0)) -> 69 | AP9: =(IF('Water Report'!$K$10>0,'Water Report'!$K$10,0)) -> 20 | AQ9: =(IF('Water Report'!$K$11>0,'Water Report'!$K$11,0)) -> 25 | AR9: =(IF('Water Report'!$K$13>0,'Water Report'!$K$13,0)) -> 22 | AS9: =(IF('Water Report'!$K$14>0,'Water Report'!$K$14,0)) -> 15 | AT9: =(IF('Water Report'!$K$15>0,'Water Report'!$K$15,0)) -> 6 | AU9: =(IF('Water Report'!$K$17>0,'Water Report'!$K$17,0)) -> 0 | AV9: =(IF('Water Report'!$K$18>0,'Water Report'!$K$18,0)) -> 6 | AW9: =(IF('Water Report'!$K$19>0,'Water Report'!$K$19,0)) -> 7 | AX9: =(IF('Water Report'!$K$21>0,'Water Report'!$K$21,0)) -> 68 | AY9: =(IF('Water Report'!$K$22>0,'Water Report'!$K$22,0)) -> 0 | AZ9: =(IF('Water Report'!$K$23>0,'Water Report'!$K$23,0)) -> 3 | BA9: =(IF('Water Report'!$K$14>0,'Water Report'!$K$14,0)) -> 15 | BB9: =(IF('Water Report'!$K$15>0,'Water Report'!$K$15,0)) -> 6 | BC9: =(IF('Water Report'!$K$13>0,'Water Report'!$K$13,0)) -> 22 | BD9: =(IF('Water Report'!$K$24>0,'Water Report'!$K$24,0)) -> 209 | BE9: =(IF('Water Report'!$K$25>0,'Water Report'!$K$25,0)) -> 135 | BF9: =(IF('Water Report'!$K$27>0,'Water Report'!$K$27,0)) -> 93 | BG9: =(IF('Section Load'!AN12>0,'Section Load'!AN12,0)) -> 851.33 | BH9: =(IF('Section Load'!AO12>0,'Section Load'!AO12,0)) -> 222.19 | BI9: =(IF('Section Load'!AP12>0,'Section Load'!AP12,0)) -> 0.4 | BJ9: =(IF('Section Load'!AQ12>0,'Section Load'!AQ12,0)) -> 91.18 | BK9: =(IF('Section Load'!AR12>0,'Section Load'!AR12,0)) -> 46.2 | BL9: =(IF('Section Load'!AS12>0,'Section Load'!AS12,0)) -> 1.6 | BM9: =(IF('Section Load'!AT12>0,'Section Load'!AT12,0)) -> 489.76
A10: Mumbai | B10: =B9+1 -> 9 | C10: 9 | D10: 2021 | E10: =(IF('Section Load'!F13>0,'Section Load'!F13,0)) -> 4824.67 | F10: =(IF('Section Load'!G13>0,'Section Load'!G13,0)) -> 1716.07 | G10: =(IF('Section Load'!H13>0,'Section Load'!H13,0)) -> 1626.07 | H10: =(IF('Section Load'!I13>0,'Section Load'!I13,0)) -> 3960.91 | I10: =(IF('Section Load'!J13>0,'Section Load'!J13,0)) -> 6865.62 | J10: =(IF('Section Load'!K13>0,'Section Load'!K13,0)) -> 2589.3 | K10: =(IF('Section Load'!L13>0,'Section Load'!L13,0)) -> 930.33 | L10: =(IF('Section Load'!M13>0,'Section Load'!M13,0)) -> 618.99 | ... AL10: =(IF('Section Load'!AM13>0,'Section Load'!AM13,0)) -> 748 | AM10: =(IF('Water Report'!$L$7>0,'Water Report'!$L$7,0)) -> 96 | AN10: =(IF('Water Report'!$L$8>0,'Water Report'!$L$8,0)) -> 127 | AO10: =(IF('Water Report'!$L$9>0,'Water Report'!$L$9,0)) -> 72 | AP10: =(IF('Water Report'!$L$10>0,'Water Report'!$L$10,0)) -> 21 | AQ10: =(IF('Water Report'!$L$11>0,'Water Report'!$L$11,0)) -> 26 | AR10: =(IF('Water Report'!$L$13>0,'Water Report'!$L$13,0)) -> 17 | AS10: =(IF('Water Report'!$L$14>0,'Water Report'!$L$14,0)) -> 20 | AT10: =(IF('Water Report'!$L$15>0,'Water Report'!$L$15,0)) -> 8 | AU10: =(IF('Water Report'!$L$17>0,'Water Report'!$L$17,0)) -> 0 | AV10: =(IF('Water Report'!$L$18>0,'Water Report'!$L$18,0)) -> 10 | AW10: =(IF('Water Report'!$L$19>0,'Water Report'!$L$19,0)) -> 9 | AX10: =(IF('Water Report'!$L$21>0,'Water Report'!$L$21,0)) -> 72 | AY10: =(IF('Water Report'!$L$22>0,'Water Report'!$L$22,0)) -> 0 | AZ10: =(IF('Water Report'!$L$23>0,'Water Report'!$L$23,0)) -> 2 | BA10: =(IF('Water Report'!$L$14>0,'Water Report'!$L$14,0)) -> 20 | BB10: =(IF('Water Report'!$L$15>0,'Water Report'!$L$15,0)) -> 8 | BC10: =(IF('Water Report'!$L$13>0,'Water Report'!$L$13,0)) -> 17 | BD10: =(IF('Water Report'!$L$24>0,'Water Report'!$L$24,0)) -> 200 | BE10: =(IF('Water Report'!$L$25>0,'Water Report'!$L$25,0)) -> 147 | BF10: =(IF('Water Report'!$L$27>0,'Water Report'!$L$27,0)) -> 91 | BG10: =(IF('Section Load'!AN13>0,'Section Load'!AN13,0)) -> 851.49 | BH10: =(IF('Section Load'!AO13>0,'Section Load'!AO13,0)) -> 233.65 | BI10: =(IF('Section Load'!AP13>0,'Section Load'!AP13,0)) -> 0 | BJ10: =(IF('Section Load'!AQ13>0,'Section Load'!AQ13,0)) -> 72.08 | BK10: =(IF('Section Load'!AR13>0,'Section Load'!AR13,0)) -> 34 | BL10: =(IF('Section Load'!AS13>0,'Section Load'!AS13,0)) -> 1.3 | BM10: =(IF('Section Load'!AT13>0,'Section Load'!AT13,0)) -> 510.46
A11: Mumbai | B11: =B10+1 -> 10 | C11: 9 | D11: 2021 | E11: =(IF('Section Load'!F14>0,'Section Load'!F14,0)) -> 4554 | F11: =(IF('Section Load'!G14>0,'Section Load'!G14,0)) -> 1638 | G11: =(IF('Section Load'!H14>0,'Section Load'!H14,0)) -> 1688 | H11: =(IF('Section Load'!I14>0,'Section Load'!I14,0)) -> 3934 | I11: =(IF('Section Load'!J14>0,'Section Load'!J14,0)) -> 6866 | J11: =(IF('Section Load'!K14>0,'Section Load'!K14,0)) -> 2556 | K11: =(IF('Section Load'!L14>0,'Section Load'!L14,0)) -> 920 | L11: =(IF('Section Load'!M14>0,'Section Load'!M14,0)) -> 524 | ... AL11: =(IF('Section Load'!AM14>0,'Section Load'!AM14,0)) -> 689 | AM11: =(IF('Water Report'!$M$7>0,'Water Report'!$M$7,0)) -> 63 | AN11: =(IF('Water Report'!$M$8>0,'Water Report'!$M$8,0)) -> 157 | AO11: =(IF('Water Report'!$M$9>0,'Water Report'!$M$9,0)) -> 56 | AP11: =(IF('Water Report'!$M$10>0,'Water Report'!$M$10,0)) -> 20 | AQ11: =(IF('Water Report'!$M$11>0,'Water Report'!$M$11,0)) -> 26 | AR11: =(IF('Water Report'!$M$13>0,'Water Report'!$M$13,0)) -> 50 | AS11: =(IF('Water Report'!$M$14>0,'Water Report'!$M$14,0)) -> 10 | AT11: =(IF('Water Report'!$M$15>0,'Water Report'!$M$15,0)) -> 12 | AU11: =(IF('Water Report'!$M$17>0,'Water Report'!$M$17,0)) -> 0 | AV11: =(IF('Water Report'!$M$18>0,'Water Report'!$M$18,0)) -> 7 | AW11: =(IF('Water Report'!$M$19>0,'Water Report'!$M$19,0)) -> 6 | AX11: =(IF('Water Report'!$M$21>0,'Water Report'!$M$21,0)) -> 129 | AY11: =(IF('Water Report'!$M$22>0,'Water Report'!$M$22,0)) -> 0 | AZ11: =(IF('Water Report'!$M$23>0,'Water Report'!$M$23,0)) -> 2 | BA11: =(IF('Water Report'!$M$14>0,'Water Report'!$M$14,0)) -> 10 | BB11: =(IF('Water Report'!$M$15>0,'Water Report'!$M$15,0)) -> 12 | BC11: =(IF('Water Report'!$M$13>0,'Water Report'!$M$13,0)) -> 50 | BD11: =(IF('Water Report'!$M$24>0,'Water Report'!$M$24,0)) -> 197 | BE11: =(IF('Water Report'!$M$25>0,'Water Report'!$M$25,0)) -> 124 | BF11: =(IF('Water Report'!$M$27>0,'Water Report'!$M$27,0)) -> 181 | BG11: =(IF('Section Load'!AN14>0,'Section Load'!AN14,0)) -> 796 | BH11: =(IF('Section Load'!AO14>0,'Section Load'!AO14,0)) -> 229 | BI11: =(IF('Section Load'!AP14>0,'Section Load'!AP14,0)) -> 0 | BJ11: =(IF('Section Load'!AQ14>0,'Section Load'!AQ14,0)) -> 90 | BK11: =(IF('Section Load'!AR14>0,'Section Load'!AR14,0)) -> 36 | BL11: =(IF('Section Load'!AS14>0,'Section Load'!AS14,0)) -> 2 | BM11: =(IF('Section Load'!AT14>0,'Section Load'!AT14,0)) -> 439
A12: Mumbai | B12: =B11+1 -> 11 | C12: 9 | D12: 2021 | E12: =(IF('Section Load'!F15>0,'Section Load'!F15,0)) -> 4510 | F12: =(IF('Section Load'!G15>0,'Section Load'!G15,0)) -> 1694 | G12: =(IF('Section Load'!H15>0,'Section Load'!H15,0)) -> 1618 | H12: =(IF('Section Load'!I15>0,'Section Load'!I15,0)) -> 3836 | I12: =(IF('Section Load'!J15>0,'Section Load'!J15,0)) -> 6766 | J12: =(IF('Section Load'!K15>0,'Section Load'!K15,0)) -> 2593 | K12: =(IF('Section Load'!L15>0,'Section Load'!L15,0)) -> 997 | L12: =(IF('Section Load'!M15>0,'Section Load'!M15,0)) -> 553 | ... AL12: =(IF('Section Load'!AM15>0,'Section Load'!AM15,0)) -> 712 | AM12: =(IF('Water Report'!$N$7>0,'Water Report'!$N$7,0)) -> 83 | AN12: =(IF('Water Report'!$N$8>0,'Water Report'!$N$8,0)) -> 190 | AO12: =(IF('Water Report'!$N$9>0,'Water Report'!$N$9,0)) -> 64 | AP12: =(IF('Water Report'!$N$10>0,'Water Report'!$N$10,0)) -> 29 | AQ12: =(IF('Water Report'!$N$11>0,'Water Report'!$N$11,0)) -> 39 | AR12: =(IF('Water Report'!$N$13>0,'Water Report'!$N$13,0)) -> 12 | AS12: =(IF('Water Report'!$N$14>0,'Water Report'!$N$14,0)) -> 0 | AT12: =(IF('Water Report'!$N$15>0,'Water Report'!$N$15,0)) -> 7 | AU12: =(IF('Water Report'!$N$17>0,'Water Report'!$N$17,0)) -> 0 | AV12: =(IF('Water Report'!$N$18>0,'Water Report'!$N$18,0)) -> 7 | AW12: =(IF('Water Report'!$N$19>0,'Water Report'!$N$19,0)) -> 7 | AX12: =(IF('Water Report'!$N$21>0,'Water Report'!$N$21,0)) -> 18 | AY12: =(IF('Water Report'!$N$22>0,'Water Report'!$N$22,0)) -> 0 | AZ12: =(IF('Water Report'!$N$23>0,'Water Report'!$N$23,0)) -> 4 | BA12: =(IF('Water Report'!$N$14>0,'Water Report'!$N$14,0)) -> 0 | BB12: =(IF('Water Report'!$N$15>0,'Water Report'!$N$15,0)) -> 7 | BC12: =(IF('Water Report'!$N$13>0,'Water Report'!$N$13,0)) -> 12 | BD12: =(IF('Water Report'!$N$24>0,'Water Report'!$N$24,0)) -> 211 | BE12: =(IF('Water Report'!$N$25>0,'Water Report'!$N$25,0)) -> 139 | BF12: =(IF('Water Report'!$N$27>0,'Water Report'!$N$27,0)) -> 34 | BG12: =(IF('Section Load'!AN15>0,'Section Load'!AN15,0)) -> 881 | BH12: =(IF('Section Load'!AO15>0,'Section Load'!AO15,0)) -> 270 | BI12: =(IF('Section Load'!AP15>0,'Section Load'!AP15,0)) -> 0 | BJ12: =(IF('Section Load'!AQ15>0,'Section Load'!AQ15,0)) -> 76 | BK12: =(IF('Section Load'!AR15>0,'Section Load'!AR15,0)) -> 47 | BL12: =(IF('Section Load'!AS15>0,'Section Load'!AS15,0)) -> 2 | BM12: =(IF('Section Load'!AT15>0,'Section Load'!AT15,0)) -> 486
A13: Mumbai | B13: =B12+1 -> 12 | C13: 9 | D13: 2021 | E13: =(IF('Section Load'!F16>0,'Section Load'!F16,0)) -> 4641.63 | F13: =(IF('Section Load'!G16>0,'Section Load'!G16,0)) -> 1706.59 | G13: =(IF('Section Load'!H16>0,'Section Load'!H16,0)) -> 1663.35 | H13: =(IF('Section Load'!I16>0,'Section Load'!I16,0)) -> 3783.25 | I13: =(IF('Section Load'!J16>0,'Section Load'!J16,0)) -> 6958.98 | J13: =(IF('Section Load'!K16>0,'Section Load'!K16,0)) -> 2648 | K13: =(IF('Section Load'!L16>0,'Section Load'!L16,0)) -> 1184.99 | L13: =(IF('Section Load'!M16>0,'Section Load'!M16,0)) -> 713.6 | ... AL13: =(IF('Section Load'!AM16>0,'Section Load'!AM16,0)) -> 670 | AM13: =(IF('Water Report'!$O$7>0,'Water Report'!$O$7,0)) -> 105 | AN13: =(IF('Water Report'!$O$8>0,'Water Report'!$O$8,0)) -> 168 | AO13: =(IF('Water Report'!$O$9>0,'Water Report'!$O$9,0)) -> 70 | AP13: =(IF('Water Report'!$O$10>0,'Water Report'!$O$10,0)) -> 35 | AQ13: =(IF('Water Report'!$O$11>0,'Water Report'!$O$11,0)) -> 33 | AR13: =(IF('Water Report'!$O$13>0,'Water Report'!$O$13,0)) -> 25 | AS13: =(IF('Water Report'!$O$14>0,'Water Report'!$O$14,0)) -> 30 | AT13: =(IF('Water Report'!$O$15>0,'Water Report'!$O$15,0)) -> 15 | AU13: =(IF('Water Report'!$O$17>0,'Water Report'!$O$17,0)) -> 0 | AV13: =(IF('Water Report'!$O$18>0,'Water Report'!$O$18,0)) -> 10 | AW13: =(IF('Water Report'!$O$19>0,'Water Report'!$O$19,0)) -> 9 | AX13: =(IF('Water Report'!$O$21>0,'Water Report'!$O$21,0)) -> 57 | AY13: =(IF('Water Report'!$O$22>0,'Water Report'!$O$22,0)) -> 0 | AZ13: =(IF('Water Report'!$O$23>0,'Water Report'!$O$23,0)) -> 5 | BA13: =(IF('Water Report'!$O$14>0,'Water Report'!$O$14,0)) -> 30 | BB13: =(IF('Water Report'!$O$15>0,'Water Report'!$O$15,0)) -> 15 | BC13: =(IF('Water Report'!$O$13>0,'Water Report'!$O$13,0)) -> 25 | BD13: =(IF('Water Report'!$O$24>0,'Water Report'!$O$24,0)) -> 223 | BE13: =(IF('Water Report'!$O$25>0,'Water Report'!$O$25,0)) -> 183 | BF13: =(IF('Water Report'!$O$27>0,'Water Report'!$O$27,0)) -> 87 | BG13: =(IF('Section Load'!AN16>0,'Section Load'!AN16,0)) -> 916.831 | BH13: =(IF('Section Load'!AO16>0,'Section Load'!AO16,0)) -> 282.02 | BI13: =(IF('Section Load'!AP16>0,'Section Load'!AP16,0)) -> 0 | BJ13: =(IF('Section Load'!AQ16>0,'Section Load'!AQ16,0)) -> 85.09 | BK13: =(IF('Section Load'!AR16>0,'Section Load'!AR16,0)) -> 43.6 | BL13: =(IF('Section Load'!AS16>0,'Section Load'!AS16,0)) -> 3.5 | BM13: =(IF('Section Load'!AT16>0,'Section Load'!AT16,0)) -> 503.021
A14: Mumbai | B14: =B13+1 -> 13 | C14: 9 | D14: 2021 | E14: =(IF('Section Load'!F17>0,'Section Load'!F17,0)) -> 305211.37 | F14: =(IF('Section Load'!G17>0,'Section Load'!G17,0)) -> 368339.28 | G14: =(IF('Section Load'!H17>0,'Section Load'!H17,0)) -> 785104.72 | H14: =(IF('Section Load'!I17>0,'Section Load'!I17,0)) -> 953761.75 | I14: =(IF('Section Load'!J17>0,'Section Load'!J17,0)) -> 0 | J14: =(IF('Section Load'!K17>0,'Section Load'!K17,0)) -> 0 | K14: =(IF('Section Load'!L17>0,'Section Load'!L17,0)) -> 0 | L14: =(IF('Section Load'!M17>0,'Section Load'!M17,0)) -> 46200 | ... AL14: =(IF('Section Load'!AM17>0,'Section Load'!AM17,0)) -> 0 | AM14: =(IF('Water Report'!$P$7>0,'Water Report'!$P$7,0)) -> 0 | AN14: =(IF('Water Report'!$P$8>0,'Water Report'!$P$8,0)) -> 0 | AO14: =(IF('Water Report'!$P$9>0,'Water Report'!$P$9,0)) -> 0 | AP14: =(IF('Water Report'!$P$10>0,'Water Report'!$P$10,0)) -> 0 | AQ14: =(IF('Water Report'!$P$11>0,'Water Report'!$P$11,0)) -> 0 | AR14: =(IF('Water Report'!$P$13>0,'Water Report'!$P$13,0)) -> 0 | AS14: =(IF('Water Report'!$P$14>0,'Water Report'!$P$14,0)) -> 0 | AT14: =(IF('Water Report'!$P$15>0,'Water Report'!$P$15,0)) -> 0 | AU14: =(IF('Water Report'!$P$17>0,'Water Report'!$P$17,0)) -> 0 | AV14: =(IF('Water Report'!$P$18>0,'Water Report'!$P$18,0)) -> 9 | AW14: =(IF('Water Report'!$P$19>0,'Water Report'!$P$19,0)) -> 0 | AX14: =(IF('Water Report'!$P$21>0,'Water Report'!$P$21,0)) -> 0 | AY14: =(IF('Water Report'!$P$22>0,'Water Report'!$P$22,0)) -> 0 | AZ14: =(IF('Water Report'!$P$23>0,'Water Report'!$P$23,0)) -> 0 | BA14: =(IF('Water Report'!$P$14>0,'Water Report'!$P$14,0)) -> 0 | BB14: =(IF('Water Report'!$P$15>0,'Water Report'!$P$15,0)) -> 0 | BC14: =(IF('Water Report'!$P$13>0,'Water Report'!$P$13,0)) -> 0 | BD14: =(IF('Water Report'!$P$24>0,'Water Report'!$P$24,0)) -> 0 | BE14: =(IF('Water Report'!$P$25>0,'Water Report'!$P$25,0)) -> 0 | BF14: =(IF('Water Report'!$P$27>0,'Water Report'!$P$27,0)) -> 0 | BG14: =(IF('Section Load'!AN17>0,'Section Load'!AN17,0)) -> 0 | BH14: =(IF('Section Load'!AO17>0,'Section Load'!AO17,0)) -> 0 | BI14: =(IF('Section Load'!AP17>0,'Section Load'!AP17,0)) -> 0 | BJ14: =(IF('Section Load'!AQ17>0,'Section Load'!AQ17,0)) -> 0 | BK14: =(IF('Section Load'!AR17>0,'Section Load'!AR17,0)) -> 0 | BL14: =(IF('Section Load'!AS17>0,'Section Load'!AS17,0)) -> 0 | BM14: =(IF('Section Load'!AT17>0,'Section Load'!AT17,0)) -> 0
A15: Mumbai | B15: =B14+1 -> 14 | C15: 9 | D15: 2021 | E15: =(IF('Section Load'!F18>0,'Section Load'!F18,0)) -> 3064 | F15: =(IF('Section Load'!G18>0,'Section Load'!G18,0)) -> 1554 | G15: =(IF('Section Load'!H18>0,'Section Load'!H18,0)) -> 1717 | H15: =(IF('Section Load'!I18>0,'Section Load'!I18,0)) -> 3673.59 | I15: =(IF('Section Load'!J18>0,'Section Load'!J18,0)) -> 6022 | J15: =(IF('Section Load'!K18>0,'Section Load'!K18,0)) -> 2490 | K15: =(IF('Section Load'!L18>0,'Section Load'!L18,0)) -> 986 | L15: =(IF('Section Load'!M18>0,'Section Load'!M18,0)) -> 633.4 | ... AL15: =(IF('Section Load'!AM18>0,'Section Load'!AM18,0)) -> 807 | AM15: =(IF('Water Report'!$Q$7>0,'Water Report'!$Q$7,0)) -> 83 | AN15: =(IF('Water Report'!$Q$8>0,'Water Report'!$Q$8,0)) -> 179 | AO15: =(IF('Water Report'!$Q$9>0,'Water Report'!$Q$9,0)) -> 69 | AP15: =(IF('Water Report'!$Q$10>0,'Water Report'!$Q$10,0)) -> 22 | AQ15: =(IF('Water Report'!$Q$11>0,'Water Report'!$Q$11,0)) -> 36 | AR15: =(IF('Water Report'!$Q$13>0,'Water Report'!$Q$13,0)) -> 11 | AS15: =(IF('Water Report'!$Q$14>0,'Water Report'!$Q$14,0)) -> 15 | AT15: =(IF('Water Report'!$Q$15>0,'Water Report'!$Q$15,0)) -> 9 | AU15: =(IF('Water Report'!$Q$17>0,'Water Report'!$Q$17,0)) -> 15 | AV15: =(IF('Water Report'!$Q$18>0,'Water Report'!$Q$18,0)) -> 8 | AW15: =(IF('Water Report'!$Q$19>0,'Water Report'!$Q$19,0)) -> 11 | AX15: =(IF('Water Report'!$Q$21>0,'Water Report'!$Q$21,0)) -> 71 | AY15: =(IF('Water Report'!$Q$22>0,'Water Report'!$Q$22,0)) -> 0 | AZ15: =(IF('Water Report'!$Q$23>0,'Water Report'!$Q$23,0)) -> 0 | BA15: =(IF('Water Report'!$Q$14>0,'Water Report'!$Q$14,0)) -> 15 | BB15: =(IF('Water Report'!$Q$15>0,'Water Report'!$Q$15,0)) -> 9 | BC15: =(IF('Water Report'!$Q$13>0,'Water Report'!$Q$13,0)) -> 11 | BD15: =(IF('Water Report'!$Q$24>0,'Water Report'!$Q$24,0)) -> 223 | BE15: =(IF('Water Report'!$Q$25>0,'Water Report'!$Q$25,0)) -> 151 | BF15: =(IF('Water Report'!$Q$27>0,'Water Report'!$Q$27,0)) -> 82 | BG15: =(IF('Section Load'!AN18>0,'Section Load'!AN18,0)) -> 1092 | BH15: =(IF('Section Load'!AO18>0,'Section Load'!AO18,0)) -> 271 | BI15: =(IF('Section Load'!AP18>0,'Section Load'!AP18,0)) -> 0.4 | BJ15: =(IF('Section Load'!AQ18>0,'Section Load'!AQ18,0)) -> 110 | BK15: =(IF('Section Load'!AR18>0,'Section Load'!AR18,0)) -> 47 | BL15: =(IF('Section Load'!AS18>0,'Section Load'!AS18,0)) -> 4 | BM15: =(IF('Section Load'!AT18>0,'Section Load'!AT18,0)) -> 659.6
A16: Mumbai | B16: =B15+1 -> 15 | C16: 9 | D16: 2021 | E16: =(IF('Section Load'!F19>0,'Section Load'!F19,0)) -> 2975 | F16: =(IF('Section Load'!G19>0,'Section Load'!G19,0)) -> 1554 | G16: =(IF('Section Load'!H19>0,'Section Load'!H19,0)) -> 1841.93 | H16: =(IF('Section Load'!I19>0,'Section Load'!I19,0)) -> 3671.41 | I16: =(IF('Section Load'!J19>0,'Section Load'!J19,0)) -> 6209 | J16: =(IF('Section Load'!K19>0,'Section Load'!K19,0)) -> 2580 | K16: =(IF('Section Load'!L19>0,'Section Load'!L19,0)) -> 1206 | L16: =(IF('Section Load'!M19>0,'Section Load'!M19,0)) -> 823 | ... AL16: =(IF('Section Load'!AM19>0,'Section Load'!AM19,0)) -> 837 | AM16: =(IF('Water Report'!$R$7>0,'Water Report'!$R$7,0)) -> 130 | AN16: =(IF('Water Report'!$R$8>0,'Water Report'!$R$8,0)) -> 168 | AO16: =(IF('Water Report'!$R$9>0,'Water Report'!$R$9,0)) -> 78 | AP16: =(IF('Water Report'!$R$10>0,'Water Report'!$R$10,0)) -> 38 | AQ16: =(IF('Water Report'!$R$11>0,'Water Report'!$R$11,0)) -> 41 | AR16: =(IF('Water Report'!$R$13>0,'Water Report'!$R$13,0)) -> 50 | AS16: =(IF('Water Report'!$R$14>0,'Water Report'!$R$14,0)) -> 20 | AT16: =(IF('Water Report'!$R$15>0,'Water Report'!$R$15,0)) -> 13 | AU16: =(IF('Water Report'!$R$17>0,'Water Report'!$R$17,0)) -> 0 | AV16: =(IF('Water Report'!$R$18>0,'Water Report'!$R$18,0)) -> 11 | AW16: =(IF('Water Report'!$R$19>0,'Water Report'!$R$19,0)) -> 9 | AX16: =(IF('Water Report'!$R$21>0,'Water Report'!$R$21,0)) -> 47 | AY16: =(IF('Water Report'!$R$22>0,'Water Report'!$R$22,0)) -> 0 | AZ16: =(IF('Water Report'!$R$23>0,'Water Report'!$R$23,0)) -> 0 | BA16: =(IF('Water Report'!$R$14>0,'Water Report'!$R$14,0)) -> 20 | BB16: =(IF('Water Report'!$R$15>0,'Water Report'!$R$15,0)) -> 13 | BC16: =(IF('Water Report'!$R$13>0,'Water Report'!$R$13,0)) -> 50 | BD16: =(IF('Water Report'!$R$24>0,'Water Report'!$R$24,0)) -> 264 | BE16: =(IF('Water Report'!$R$25>0,'Water Report'!$R$25,0)) -> 190 | BF16: =(IF('Water Report'!$R$27>0,'Water Report'!$R$27,0)) -> 97 | BG16: =(IF('Section Load'!AN19>0,'Section Load'!AN19,0)) -> 920 | BH16: =(IF('Section Load'!AO19>0,'Section Load'!AO19,0)) -> 304 | BI16: =(IF('Section Load'!AP19>0,'Section Load'!AP19,0)) -> 0 | BJ16: =(IF('Section Load'!AQ19>0,'Section Load'!AQ19,0)) -> 86 | BK16: =(IF('Section Load'!AR19>0,'Section Load'!AR19,0)) -> 57 | BL16: =(IF('Section Load'!AS19>0,'Section Load'!AS19,0)) -> 3 | BM16: =(IF('Section Load'!AT19>0,'Section Load'!AT19,0)) -> 470
A17: Mumbai | B17: =B16+1 -> 16 | C17: 9 | D17: 2021 | E17: =(IF('Section Load'!F20>0,'Section Load'!F20,0)) -> 3248.3 | F17: =(IF('Section Load'!G20>0,'Section Load'!G20,0)) -> 1612 | G17: =(IF('Section Load'!H20>0,'Section Load'!H20,0)) -> 1690.07 | H17: =(IF('Section Load'!I20>0,'Section Load'!I20,0)) -> 3911.59 | I17: =(IF('Section Load'!J20>0,'Section Load'!J20,0)) -> 6647 | J17: =(IF('Section Load'!K20>0,'Section Load'!K20,0)) -> 2740 | K17: =(IF('Section Load'!L20>0,'Section Load'!L20,0)) -> 1437 | L17: =(IF('Section Load'!M20>0,'Section Load'!M20,0)) -> 663 | ... AL17: =(IF('Section Load'!AM20>0,'Section Load'!AM20,0)) -> 837 | AM17: =(IF('Water Report'!$S$7>0,'Water Report'!$S$7,0)) -> 84 | AN17: =(IF('Water Report'!$S$8>0,'Water Report'!$S$8,0)) -> 140 | AO17: =(IF('Water Report'!$S$9>0,'Water Report'!$S$9,0)) -> 67 | AP17: =(IF('Water Report'!$S$10>0,'Water Report'!$D$10,0)) -> 18 | AQ17: =(IF('Water Report'!$S$11>0,'Water Report'!$D$11,0)) -> 24 | AR17: =(IF('Water Report'!$S$13>0,'Water Report'!$D$13,0)) -> 11 | AS17: =(IF('Water Report'!$S$14>0,'Water Report'!$D$14,0)) -> 13 | AT17: =(IF('Water Report'!$S$15>0,'Water Report'!$D$15,0)) -> 7 | AU17: =(IF('Water Report'!$S$17>0,'Water Report'!$D$17,0)) -> 0 | AV17: =(IF('Water Report'!$S$18>0,'Water Report'!$D$18,0)) -> 7 | AW17: =(IF('Water Report'!$S$19>0,'Water Report'!$D$19,0)) -> 10 | AX17: =(IF('Water Report'!$S$21>0,'Water Report'!$D$21,0)) -> 93 | AY17: =(IF('Water Report'!$S$22>0,'Water Report'!$D$22,0)) -> 0 | AZ17: =(IF('Water Report'!$S$23>0,'Water Report'!$D$23,0)) -> 0 | BA17: =(IF('Water Report'!$S$14>0,'Water Report'!$D$14,0)) -> 13 | BB17: =(IF('Water Report'!$S$15>0,'Water Report'!$D$15,0)) -> 7 | BC17: =(IF('Water Report'!$S$13>0,'Water Report'!$D$13,0)) -> 11 | BD17: =(IF('Water Report'!$S$24>0,'Water Report'!$D$24,0)) -> 146 | BE17: =(IF('Water Report'!$S$25>0,'Water Report'!$D$25,0)) -> 128 | BF17: =(IF('Water Report'!$S$27>0,'Water Report'!$D$27,0)) -> 104 | BG17: =(IF('Section Load'!AN20>0,'Section Load'!AN20,0)) -> 896.097 | BH17: =(IF('Section Load'!AO20>0,'Section Load'!AO20,0)) -> 250.46 | BI17: =(IF('Section Load'!AP20>0,'Section Load'!AP20,0)) -> 0 | BJ17: =(IF('Section Load'!AQ20>0,'Section Load'!AQ20,0)) -> 75.5 | BK17: =(IF('Section Load'!AR20>0,'Section Load'!AR20,0)) -> 40.3 | BL17: =(IF('Section Load'!AS20>0,'Section Load'!AS20,0)) -> 0.7 | BM17: =(IF('Section Load'!AT20>0,'Section Load'!AT20,0)) -> 529.137
A18: Mumbai | B18: =B17+1 -> 17 | C18: 9 | D18: 2021 | E18: =(IF('Section Load'!F21>0,'Section Load'!F21,0)) -> 3008 | F18: =(IF('Section Load'!G21>0,'Section Load'!G21,0)) -> 1496 | G18: =(IF('Section Load'!H21>0,'Section Load'!H21,0)) -> 1715 | H18: =(IF('Section Load'!I21>0,'Section Load'!I21,0)) -> 3719.4 | I18: =(IF('Section Load'!J21>0,'Section Load'!J21,0)) -> 5807 | J18: =(IF('Section Load'!K21>0,'Section Load'!K21,0)) -> 2430 | K18: =(IF('Section Load'!L21>0,'Section Load'!L21,0)) -> 1453 | L18: =(IF('Section Load'!M21>0,'Section Load'!M21,0)) -> 632.5 | ... AL18: =(IF('Section Load'!AM21>0,'Section Load'!AM21,0)) -> 679 | AM18: =(IF('Water Report'!$T$7>0,'Water Report'!$T$7,0)) -> 79 | AN18: =(IF('Water Report'!$T$8>0,'Water Report'!$T$8,0)) -> 105 | AO18: =(IF('Water Report'!$T$9>0,'Water Report'!$T$9,0)) -> 80 | AP18: =(IF('Water Report'!$T$10>0,'Water Report'!$T$10,0)) -> 18 | AQ18: =(IF('Water Report'!$T$11>0,'Water Report'!$T$11,0)) -> 24 | AR18: =(IF('Water Report'!$T$13>0,'Water Report'!$T$13,0)) -> 36 | AS18: =(IF('Water Report'!$T$14>0,'Water Report'!$T$14,0)) -> 14 | AT18: =(IF('Water Report'!$T$15>0,'Water Report'!$T$15,0)) -> 4 | AU18: =(IF('Water Report'!$T$17>0,'Water Report'!$T$17,0)) -> 0 | AV18: =(IF('Water Report'!$T$18>0,'Water Report'!$T$18,0)) -> 9 | AW18: =(IF('Water Report'!$T$19>0,'Water Report'!$T$19,0)) -> 6 | AX18: =(IF('Water Report'!$T$21>0,'Water Report'!$T$21,0)) -> 74 | AY18: =(IF('Water Report'!$T$22>0,'Water Report'!$T$22,0)) -> 0 | AZ18: =(IF('Water Report'!$T$23>0,'Water Report'!$T$23,0)) -> 0 | BA18: =(IF('Water Report'!$T$14>0,'Water Report'!$T$14,0)) -> 14 | BB18: =(IF('Water Report'!$T$15>0,'Water Report'!$T$15,0)) -> 4 | BC18: =(IF('Water Report'!$T$13>0,'Water Report'!$T$13,0)) -> 36 | BD18: =(IF('Water Report'!$T$24>0,'Water Report'!$T$24,0)) -> 226 | BE18: =(IF('Water Report'!$T$25>0,'Water Report'!$T$25,0)) -> 140 | BF18: =(IF('Water Report'!$T$27>0,'Water Report'!$T$27,0)) -> 110 | BG18: =(IF('Section Load'!AN21>0,'Section Load'!AN21,0)) -> 813.512 | BH18: =(IF('Section Load'!AO21>0,'Section Load'!AO21,0)) -> 296.09 | BI18: =(IF('Section Load'!AP21>0,'Section Load'!AP21,0)) -> 0 | BJ18: =(IF('Section Load'!AQ21>0,'Section Load'!AQ21,0)) -> 76.78 | BK18: =(IF('Section Load'!AR21>0,'Section Load'!AR21,0)) -> 39.9 | BL18: =(IF('Section Load'!AS21>0,'Section Load'!AS21,0)) -> 0.7 | BM18: =(IF('Section Load'!AT21>0,'Section Load'!AT21,0)) -> 400.042
A19: Mumbai | B19: =B18+1 -> 18 | C19: 9 | D19: 2021 | E19: =(IF('Section Load'!F22>0,'Section Load'!F22,0)) -> 2982 | F19: =(IF('Section Load'!G22>0,'Section Load'!G22,0)) -> 1535 | G19: =(IF('Section Load'!H22>0,'Section Load'!H22,0)) -> 1724 | H19: =(IF('Section Load'!I22>0,'Section Load'!I22,0)) -> 3770.6 | I19: =(IF('Section Load'!J22>0,'Section Load'!J22,0)) -> 5978 | J19: =(IF('Section Load'!K22>0,'Section Load'!K22,0)) -> 2570 | K19: =(IF('Section Load'!L22>0,'Section Load'!L22,0)) -> 1651 | L19: =(IF('Section Load'!M22>0,'Section Load'!M22,0)) -> 711.2 | ... AL19: =(IF('Section Load'!AM22>0,'Section Load'!AM22,0)) -> 705 | AM19: =(IF('Water Report'!$U$7>0,'Water Report'!$U$7,0)) -> 103 | AN19: =(IF('Water Report'!$U$8>0,'Water Report'!$U$8,0)) -> 55 | AO19: =(IF('Water Report'!$U$9>0,'Water Report'!$U$9,0)) -> 110 | AP19: =(IF('Water Report'!$U$10>0,'Water Report'!$U$10,0)) -> 20 | AQ19: =(IF('Water Report'!$U$11>0,'Water Report'!$U$11,0)) -> 24 | AR19: =(IF('Water Report'!$U$13>0,'Water Report'!$U$13,0)) -> 46 | AS19: =(IF('Water Report'!$U$14>0,'Water Report'!$U$14,0)) -> 18 | AT19: =(IF('Water Report'!$U$15>0,'Water Report'!$U$15,0)) -> 6 | AU19: =(IF('Water Report'!$U$17>0,'Water Report'!$U$17,0)) -> 16 | AV19: =(IF('Water Report'!$U$18>0,'Water Report'!$U$18,0)) -> 20 | AW19: =(IF('Water Report'!$U$19>0,'Water Report'!$U$19,0)) -> 10 | AX19: =(IF('Water Report'!$U$21>0,'Water Report'!$U$21,0)) -> 49 | AY19: =(IF('Water Report'!$U$22>0,'Water Report'!$U$22,0)) -> 0 | AZ19: =(IF('Water Report'!$U$23>0,'Water Report'!$U$23,0)) -> 0 | BA19: =(IF('Water Report'!$U$14>0,'Water Report'!$U$14,0)) -> 18 | BB19: =(IF('Water Report'!$U$15>0,'Water Report'!$U$15,0)) -> 6 | BC19: =(IF('Water Report'!$U$13>0,'Water Report'!$U$13,0)) -> 46 | BD19: =(IF('Water Report'!$U$24>0,'Water Report'!$U$24,0)) -> 200 | BE19: =(IF('Water Report'!$U$25>0,'Water Report'!$U$25,0)) -> 178 | BF19: =(IF('Water Report'!$U$27>0,'Water Report'!$U$27,0)) -> 95 | BG19: =(IF('Section Load'!AN22>0,'Section Load'!AN22,0)) -> 964.543 | BH19: =(IF('Section Load'!AO22>0,'Section Load'!AO22,0)) -> 293.45 | BI19: =(IF('Section Load'!AP22>0,'Section Load'!AP22,0)) -> 0 | BJ19: =(IF('Section Load'!AQ22>0,'Section Load'!AQ22,0)) -> 99.55 | BK19: =(IF('Section Load'!AR22>0,'Section Load'!AR22,0)) -> 45.6 | BL19: =(IF('Section Load'!AS22>0,'Section Load'!AS22,0)) -> 0 | BM19: =(IF('Section Load'!AT22>0,'Section Load'!AT22,0)) -> 525.943
A20: Mumbai | B20: =B19+1 -> 19 | C20: 9 | D20: 2021 | E20: =(IF('Section Load'!F23>0,'Section Load'!F23,0)) -> 3165.7 | F20: =(IF('Section Load'!G23>0,'Section Load'!G23,0)) -> 1571.13 | G20: =(IF('Section Load'!H23>0,'Section Load'!H23,0)) -> 1830.93 | H20: =(IF('Section Load'!I23>0,'Section Load'!I23,0)) -> 3827 | I20: =(IF('Section Load'!J23>0,'Section Load'!J23,0)) -> 6118 | J20: =(IF('Section Load'!K23>0,'Section Load'!K23,0)) -> 2599.67 | K20: =(IF('Section Load'!L23>0,'Section Load'!L23,0)) -> 1813 | L20: =(IF('Section Load'!M23>0,'Section Load'!M23,0)) -> 962.3 | ... AL20: =(IF('Section Load'!AM23>0,'Section Load'!AM23,0)) -> 778 | AM20: =(IF('Water Report'!$V$7>0,'Water Report'!$V$7,0)) -> 90 | AN20: =(IF('Water Report'!$V$8>0,'Water Report'!$V$8,0)) -> 188 | AO20: =(IF('Water Report'!$V$9>0,'Water Report'!$V$9,0)) -> 74 | AP20: =(IF('Water Report'!$V$10>0,'Water Report'!$V$10,0)) -> 26 | AQ20: =(IF('Water Report'!$V$11>0,'Water Report'!$V$11,0)) -> 29 | AR20: =(IF('Water Report'!$V$13>0,'Water Report'!$V$13,0)) -> 24 | AS20: =(IF('Water Report'!$V$14>0,'Water Report'!$V$14,0)) -> 15 | AT20: =(IF('Water Report'!$V$15>0,'Water Report'!$V$15,0)) -> 8 | AU20: =(IF('Water Report'!$V$17>0,'Water Report'!$V$17,0)) -> 0 | AV20: =(IF('Water Report'!$V$18>0,'Water Report'!$V$18,0)) -> 8 | AW20: =(IF('Water Report'!$V$19>0,'Water Report'!$V$19,0)) -> 6 | AX20: =(IF('Water Report'!$V$21>0,'Water Report'!$V$21,0)) -> 70 | AY20: =(IF('Water Report'!$V$22>0,'Water Report'!$V$22,0)) -> 0 | AZ20: =(IF('Water Report'!$V$23>0,'Water Report'!$V$23,0)) -> 0 | BA20: =(IF('Water Report'!$V$14>0,'Water Report'!$V$14,0)) -> 15 | BB20: =(IF('Water Report'!$V$15>0,'Water Report'!$V$15,0)) -> 8 | BC20: =(IF('Water Report'!$V$13>0,'Water Report'!$V$13,0)) -> 24 | BD20: =(IF('Water Report'!$V$24>0,'Water Report'!$V$24,0)) -> 210 | BE20: =(IF('Water Report'!$V$25>0,'Water Report'!$V$25,0)) -> 152 | BF20: =(IF('Water Report'!$V$27>0,'Water Report'!$V$27,0)) -> 94 | BG20: =(IF('Section Load'!AN23>0,'Section Load'!AN23,0)) -> 837.848 | BH20: =(IF('Section Load'!AO23>0,'Section Load'!AO23,0)) -> 288 | BI20: =(IF('Section Load'!AP23>0,'Section Load'!AP23,0)) -> 0 | BJ20: =(IF('Section Load'!AQ23>0,'Section Load'!AQ23,0)) -> 96.09 | BK20: =(IF('Section Load'!AR23>0,'Section Load'!AR23,0)) -> 42 | BL20: =(IF('Section Load'!AS23>0,'Section Load'!AS23,0)) -> 0 | BM20: =(IF('Section Load'!AT23>0,'Section Load'!AT23,0)) -> 411.998
A21: Mumbai | B21: =B20+1 -> 20 | C21: 9 | D21: 2021 | E21: =(IF('Section Load'!F24>0,'Section Load'!F24,0)) -> 2777 | F21: =(IF('Section Load'!G24>0,'Section Load'!G24,0)) -> 1460 | G21: =(IF('Section Load'!H24>0,'Section Load'!H24,0)) -> 1714 | H21: =(IF('Section Load'!I24>0,'Section Load'!I24,0)) -> 3421 | I21: =(IF('Section Load'!J24>0,'Section Load'!J24,0)) -> 5842.14 | J21: =(IF('Section Load'!K24>0,'Section Load'!K24,0)) -> 2360 | K21: =(IF('Section Load'!L24>0,'Section Load'!L24,0)) -> 1302 | L21: =(IF('Section Load'!M24>0,'Section Load'!M24,0)) -> 802.6 | ... AL21: =(IF('Section Load'!AM24>0,'Section Load'!AM24,0)) -> 673 | AM21: =(IF('Water Report'!$W$7>0,'Water Report'!$W$7,0)) -> 123 | AN21: =(IF('Water Report'!$W$8>0,'Water Report'!$W$8,0)) -> 134 | AO21: =(IF('Water Report'!$W$9>0,'Water Report'!$W$9,0)) -> 111 | AP21: =(IF('Water Report'!$W$10>0,'Water Report'!$W$10,0)) -> 26 | AQ21: =(IF('Water Report'!$W$11>0,'Water Report'!$W$11,0)) -> 32 | AR21: =(IF('Water Report'!$W$13>0,'Water Report'!$W$13,0)) -> 29 | AS21: =(IF('Water Report'!$W$14>0,'Water Report'!$W$14,0)) -> 21 | AT21: =(IF('Water Report'!$W$15>0,'Water Report'!$W$15,0)) -> 11 | AU21: =(IF('Water Report'!$W$17>0,'Water Report'!$W$17,0)) -> 0 | AV21: =(IF('Water Report'!$W$18>0,'Water Report'!$W$18,0)) -> 9 | AW21: =(IF('Water Report'!$W$19>0,'Water Report'!$W$19,0)) -> 9 | AX21: =(IF('Water Report'!$W$21>0,'Water Report'!$W$21,0)) -> 61 | AY21: =(IF('Water Report'!$W$22>0,'Water Report'!$W$22,0)) -> 0 | AZ21: =(IF('Water Report'!$W$23>0,'Water Report'!$W$23,0)) -> 74 | BA21: =(IF('Water Report'!$W$14>0,'Water Report'!$W$14,0)) -> 21 | BB21: =(IF('Water Report'!$W$15>0,'Water Report'!$W$15,0)) -> 11 | BC21: =(IF('Water Report'!$W$13>0,'Water Report'!$W$13,0)) -> 29 | BD21: =(IF('Water Report'!$W$24>0,'Water Report'!$W$24,0)) -> 299 | BE21: =(IF('Water Report'!$W$25>0,'Water Report'!$W$25,0)) -> 201 | BF21: =(IF('Water Report'!$W$27>0,'Water Report'!$W$27,0)) -> 164 | BG21: =(IF('Section Load'!AN24>0,'Section Load'!AN24,0)) -> 900.52 | BH21: =(IF('Section Load'!AO24>0,'Section Load'!AO24,0)) -> 285.7 | BI21: =(IF('Section Load'!AP24>0,'Section Load'!AP24,0)) -> 0 | BJ21: =(IF('Section Load'!AQ24>0,'Section Load'!AQ24,0)) -> 86.58 | BK21: =(IF('Section Load'!AR24>0,'Section Load'!AR24,0)) -> 39.7 | BL21: =(IF('Section Load'!AS24>0,'Section Load'!AS24,0)) -> 0.29 | BM21: =(IF('Section Load'!AT24>0,'Section Load'!AT24,0)) -> 488.25
A22: Mumbai | B22: =B21+1 -> 21 | C22: 9 | D22: 2021 | E22: =(IF('Section Load'!F25>0,'Section Load'!F25,0)) -> 3056 | F22: =(IF('Section Load'!G25>0,'Section Load'!G25,0)) -> 1562 | G22: =(IF('Section Load'!H25>0,'Section Load'!H25,0)) -> 1883.07 | H22: =(IF('Section Load'!I25>0,'Section Load'!I25,0)) -> 3720 | I22: =(IF('Section Load'!J25>0,'Section Load'!J25,0)) -> 6296 | J22: =(IF('Section Load'!K25>0,'Section Load'!K25,0)) -> 2600 | K22: =(IF('Section Load'!L25>0,'Section Load'!L25,0)) -> 1002 | L22: =(IF('Section Load'!M25>0,'Section Load'!M25,0)) -> 674.8 | ... AL22: =(IF('Section Load'!AM25>0,'Section Load'!AM25,0)) -> 661 | AM22: =(IF('Water Report'!$X$7>0,'Water Report'!$X$7,0)) -> 129 | AN22: =(IF('Water Report'!$X$8>0,'Water Report'!$X$8,0)) -> 144 | AO22: =(IF('Water Report'!$X$9>0,'Water Report'!$X$9,0)) -> 78 | AP22: =(IF('Water Report'!$X$10>0,'Water Report'!$X$10,0)) -> 28 | AQ22: =(IF('Water Report'!$X$11>0,'Water Report'!$X$11,0)) -> 33 | AR22: =(IF('Water Report'!$X$13>0,'Water Report'!$X$13,0)) -> 13 | AS22: =(IF('Water Report'!$X$14>0,'Water Report'!$X$14,0)) -> 18 | AT22: =(IF('Water Report'!$X$15>0,'Water Report'!$X$15,0)) -> 25 | AU22: =(IF('Water Report'!$X$17>0,'Water Report'!$X$17,0)) -> 18 | AV22: =(IF('Water Report'!$X$18>0,'Water Report'!$X$18,0)) -> 11 | AW22: =(IF('Water Report'!$X$19>0,'Water Report'!$X$19,0)) -> 8 | AX22: =(IF('Water Report'!$X$21>0,'Water Report'!$X$21,0)) -> 85 | AY22: =(IF('Water Report'!$X$22>0,'Water Report'!$X$22,0)) -> 0 | AZ22: =(IF('Water Report'!$X$23>0,'Water Report'!$X$23,0)) -> 0 | BA22: =(IF('Water Report'!$X$14>0,'Water Report'!$X$14,0)) -> 18 | BB22: =(IF('Water Report'!$X$15>0,'Water Report'!$X$15,0)) -> 25 | BC22: =(IF('Water Report'!$X$13>0,'Water Report'!$X$13,0)) -> 13 | BD22: =(IF('Water Report'!$X$24>0,'Water Report'!$X$24,0)) -> 253 | BE22: =(IF('Water Report'!$X$25>0,'Water Report'!$X$25,0)) -> 182 | BF22: =(IF('Water Report'!$X$27>0,'Water Report'!$X$27,0)) -> 98 | BG22: =(IF('Section Load'!AN25>0,'Section Load'!AN25,0)) -> 890.94 | BH22: =(IF('Section Load'!AO25>0,'Section Load'!AO25,0)) -> 279.3 | BI22: =(IF('Section Load'!AP25>0,'Section Load'!AP25,0)) -> 0 | BJ22: =(IF('Section Load'!AQ25>0,'Section Load'!AQ25,0)) -> 101.12 | BK22: =(IF('Section Load'!AR25>0,'Section Load'!AR25,0)) -> 50.3 | BL22: =(IF('Section Load'!AS25>0,'Section Load'!AS25,0)) -> 12.75 | BM22: =(IF('Section Load'!AT25>0,'Section Load'!AT25,0)) -> 447.47
