Workbook

Sheet TOTAL
A1: Site Name | B1: Day | C1: Month | D1: Year | E1: Total Electricity Kwh | F1: Electricity Tariff ($/Kwh) | G1: Natual Gas (m3) | H1: Natural Gas $/m3 | I1: District Energy Cooling Kwh | J1: District Energy Cooling $/Kwh | K1: Water Utility Supply (m3) m3 | L1: Water Utility Supply (m3) $/m3 | M1: Room Nights | N1: Total Guests
A2: Abu Dhabi | B2: 1 | C2: 3 | D2: 2021 | E2: =Submetering!E2+Submetering!F2+Submetering!G2+Submetering!H2+Submetering!I2+Submetering!J2+Submetering!K2 -> 24704 | F2: 0.2 | G2: =Submetering!P2 -> 623 | H2: 6.47 | I2: =Submetering!T2-Submetering!T2*15%-Submetering!X2 -> 14727.84 | J2: 0.21 | K2: =Submetering!N2-Submetering!O2 -> 43.518 | L2: 7.84 | M2: =Submetering!Y2 -> 71 | N2: =Submetering!Z2 -> 111
A3: Abu Dhabi | B3: =B2+1 -> 2 | C3: 3 | D3: 2021 | E3: =Submetering!E3+Submetering!F3+Submetering!G3+Submetering!H3+Submetering!I3+Submetering!J3+Submetering!K3 -> 25483 | F3: 0.2 | G3: =Submetering!P3 -> 574 | H3: 6.47 | I3: =Submetering!T3-Submetering!T3*15%-Submetering!X3 -> 18452.663 | J3: 0.21 | K3: =Submetering!N3-Submetering!O3 -> 80.823 | L3: 7.84 | M3: =Submetering!Y3 -> 87 | N3: =Submetering!Z3 -> 138
A4: Abu Dhabi | B4: =B3+1 -> 3 | C4: 3 | D4: 2021 | E4: =Submetering!E4+Submetering!F4+Submetering!G4+Submetering!H4+Submetering!I4+Submetering!J4+Submetering!K4 -> 25530 | F4: 0.2 | G4: =Submetering!P4 -> 600 | H4: 6.47 | I4: =Submetering!T4-Submetering!T4*15%-Submetering!X4 -> 22021.398 | J4: 0.21 | K4: =Submetering!N4-Submetering!O4 -> 64.851 | L4: 7.84 | M4: =Submetering!Y4 -> 75 | N4: =Submetering!Z4 -> 122
A5: Abu Dhabi | B5: =B4+1 -> 4 | C5: 3 | D5: 2021 | E5: =Submetering!E5+Submetering!F5+Submetering!G5+Submetering!H5+Submetering!I5+Submetering!J5+Submetering!K5 -> 24816 | F5: 0.2 | G5: =Submetering!P5 -> 601 | H5: 6.47 | I5: =Submetering!T5-Submetering!T5*15%-Submetering!X5 -> 22944.813 | J5: 0.21 | K5: =Submetering!N5-Submetering!O5 -> 74.566 | L5: 7.84 | M5: =Submetering!Y5 -> 80 | N5: =Submetering!Z5 -> 138
A6: Abu Dhabi | B6: =B5+1 -> 5 | C6: 3 | D6: 2021 | E6: =Submetering!E6+Submetering!F6+Submetering!G6+Submetering!H6+Submetering!I6+Submetering!J6+Submetering!K6 -> 24773 | F6: 0.2 | G6: =Submetering!P6 -> 640 | H6: 6.47 | I6: =Submetering!T6-Submetering!T6*15%-Submetering!X6 -> 22847.537 | J6: 0.21 | K6: =Submetering!N6-Submetering!O6 -> 68.365 | L6: 7.84 | M6: =Submetering!Y6 -> 94 | N6: =Submetering!Z6 -> 162
A7: Abu Dhabi | B7: =B6+1 -> 6 | C7: 3 | D7: 2021 | E7: =Submetering!E7+Submetering!F7+Submetering!G7+Submetering!H7+Submetering!I7+Submetering!J7+Submetering!K7 -> 25746 | F7: 0.2 | G7: =Submetering!P7 -> 584 | H7: 6.47 | I7: =Submetering!T7-Submetering!T7*15%-Submetering!X7 -> 19273.373 | J7: 0.21 | K7: =Submetering!N7-Submetering!O7 -> 69.052 | L7: 7.84 | M7: =Submetering!Y7 -> 77 | N7: =Submetering!Z7 -> 117
A8: Abu Dhabi | B8: =B7+1 -> 7 | C8: 3 | D8: 2021 | E8: =Submetering!E8+Submetering!F8+Submetering!G8+Submetering!H8+Submetering!I8+Submetering!J8+Submetering!K8 -> 25287 | F8: 0.2 | G8: =Submetering!P8 -> 575 | H8: 6.47 | I8: =Submetering!T8-Submetering!T8*15%-Submetering!X8 -> 18245.29 | J8: 0.21 | K8: =Submetering!N8-Submetering!O8 -> 65.856 | L8: 7.84 | M8: =Submetering!Y8 -> 72 | N8: =Submetering!Z8 -> 110
A9: Abu Dhabi | B9: =B8+1 -> 8 | C9: 3 | D9: 2021 | E9: =Submetering!E9+Submetering!F9+Submetering!G9+Submetering!H9+Submetering!I9+Submetering!J9+Submetering!K9 -> 24437 | F9: 0.2 | G9: =Submetering!P9 -> 552 | H9: 6.47 | I9: =Submetering!T9-Submetering!T9*15%-Submetering!X9 -> 17277.818 | J9: 0.21 | K9: =Submetering!N9-Submetering!O9 -> 36.837 | L9: 7.84 | M9: =Submetering!Y9 -> 71 | N9: =Submetering!Z9 -> 106
A10: Abu Dhabi | B10: =B9+1 -> 9 | C10: 3 | D10: 2021 | E10: =Submetering!E10+Submetering!F10+Submetering!G10+Submetering!H10+Submetering!I10+Submetering!J10+Submetering!K10 -> 25479 | F10: 0.2 | G10: =Submetering!P10 -> 557 | H10: 6.47 | I10: =Submetering!T10-Submetering!T10*15%-Submetering!X10 -> 18782.091 | J10: 0.21 | K10: =Submetering!N10-Submetering!O10 -> 66.143 | L10: 7.84 | M10: =Submetering!Y10 -> 80 | N10: =Submetering!Z10 -> 121
A11: Abu Dhabi | B11: =B10+1 -> 10 | C11: 3 | D11: 2021 | E11: =Submetering!E11+Submetering!F11+Submetering!G11+Submetering!H11+Submetering!I11+Submetering!J11+Submetering!K11 -> 25564 | F11: 0.2 | G11: =Submetering!P11 -> 572 | H11: 6.47 | I11: =Submetering!T11-Submetering!T11*15%-Submetering!X11 -> 17822.319 | J11: 0.21 | K11: =Submetering!N11-Submetering!O11 -> 60.563 | L11: 7.84 | M11: =Submetering!Y11 -> 83 | N11: =Submetering!Z11 -> 121
A12: Abu Dhabi | B12: =B11+1 -> 11 | C12: 3 | D12: 2021 | E12: =Submetering!E12+Submetering!F12+Submetering!G12+Submetering!H12+Submetering!I12+Submetering!J12+Submetering!K12 -> 26764 | F12: 0.2 | G12: =Submetering!P12 -> 610 | H12: 6.47 | I12: =Submetering!T12-Submetering!T12*15%-Submetering!X12 -> 21185 | J12: 0.21 | K12: =Submetering!N12-Submetering!O12 -> 65.044 | L12: 7.84 | M12: =Submetering!Y12 -> 82 | N12: =Submetering!Z12 -> 129
A13: Abu Dhabi | B13: =B12+1 -> 12 | C13: 3 | D13: 2021 | E13: =Submetering!E13+Submetering!F13+Submetering!G13+Submetering!H13+Submetering!I13+Submetering!J13+Submetering!K13 -> 24534 | F13: 0.2 | G13: =Submetering!P13 -> 623 | H13: 6.47 | I13: =Submetering!T13-Submetering!T13*15%-Submetering!X13 -> 21722.468 | J13: 0.21 | K13: =Submetering!N13-Submetering!O13 -> 61.019 | L13: 7.84 | M13: =Submetering!Y13 -> 75 | N13: =Submetering!Z13 -> 131
A14: Abu Dhabi | B14: =B13+1 -> 13 | C14: 3 | D14: 2021 | E14: =Submetering!E14+Submetering!F14+Submetering!G14+Submetering!H14+Submetering!I14+Submetering!J14+Submetering!K14 -> 26761 | F14: 0.2 | G14: =Submetering!P14 -> 548 | H14: 6.47 | I14: =Submetering!T14-Submetering!T14*15%-Submetering!X14 -> 19926.402 | J14: 0.21 | K14: =Submetering!N14-Submetering!O14 -> 62.877 | L14: 7.84 | M14: =Submetering!Y14 -> 63 | N14: =Submetering!Z14 -> 90
... A32: Abu Dhabi | B32: =B31+1 -> 31 | C32: 3 | D32: 2021 | E32: =Submetering!E32+Submetering!F32+Submetering!G32+Submetering!H32+Submetering!I32+Submetering!J32+Submetering!K32 -> 28419 | F32: 0.2 | G32: =Submetering!P32 -> 581 | H32: 6.47 | I32: =Submetering!T32-Submetering!T32*15%-Submetering!X32 -> 27091.667 | J32: 0.21 | K32: =Submetering!N32-Submetering!O32 -> 86.566 | L32: 7.84 | M32: =Submetering!Y32 -> 131 | N32: =Submetering!Z32 -> 212
I33: =SUM(I2:I32) -> 676349.83 | M33: =SUM(M2:M32) -> 2717 | N33: =SUM(N2:N32) -> 4288

Sheet Submetering
A1: Site Name | B1: Day | C1: Month | D1: Year | E1: LVS-1 SECTION A - KWh | F1: LVS-1 SECTION B - KWh | G1: LVS-2 (CAFE MILANO)- KWh | H1: LVS-3 SECTION A- KWh | I1: LVS-3 SECTION B- KWh | J1: LVS-4 SECTION A- KWh | K1: LVS-4 SECTION B- KWh | L1: LVS-5 (FLOOR 15-32) KWh | M1: LVS-LRLV (RETAIL)KWh | N1: Total Water- m3 | O1: Galleria Water m3 | P1: Main Gas m3 | Q1: HW Boiler Gas - m3 | R1: Steam Boiler Gas- m3 | S1: Total Kitchen- m3 | T1: Main District Cooling- KWh | U1: Podium District Cooling- KWh | V1: Guest Rooms District Cooling- KWh | W1: Residence District Cooling- KWh | X1: Galleria District Cooling KWh | Y1: Room Nights | Z1: Total Guests
A2: Abu Dhabi | B2: 1 | C2: 3 | D2: 2021 | E2: ='FS-AD Daily '!B6 -> 4973 | F2: ='FS-AD Daily '!C6 -> 2139 | G2: ='FS-AD Daily '!D6 -> 858 | H2: ='FS-AD Daily '!E6 -> 4626 | I2: ='FS-AD Daily '!F6 -> 5794 | J2: ='FS-AD Daily '!G6 -> 2725 | K2: ='FS-AD Daily '!H6 -> 3589 | L2: ='FS-AD Daily '!I6 -> 2406 | M2: ='FS-AD Daily '!J6 -> 6925 | N2: ='FS-AD Daily '!T6 -> 108.755 | O2: ='FS-AD Daily '!R6 -> 65.237 | P2: ='FS-AD Daily '!Z6 -> 623 | Q2: ='FS-AD Daily '!V6 -> 303.1 | R2: ='FS-AD Daily '!W6 -> 6.15 | S2: =P2-Q2-R2 -> 313.75 | T2: ='FS-AD Daily '!AD6*3.516 -> 35209.224 | U2: =('FS-AD Daily '!AF6)*1000 -> 16300 | V2: =('FS-AD Daily '!AG6)*1000 -> 7200 | W2: ='FS-AD Daily '!AH6*1000 -> 5400 | X2: =('FS-AD Daily '!AK6)*1000 -> 15200 | Y2: 71 | Z2: 111
A3: Abu Dhabi | B3: =B2+1 -> 2 | C3: 3 | D3: 2021 | E3: ='FS-AD Daily '!B7 -> 5557 | F3: ='FS-AD Daily '!C7 -> 2371 | G3: ='FS-AD Daily '!D7 -> 892 | H3: ='FS-AD Daily '!E7 -> 4689 | I3: ='FS-AD Daily '!F7 -> 5751 | J3: ='FS-AD Daily '!G7 -> 2656 | K3: ='FS-AD Daily '!H7 -> 3567 | L3: ='FS-AD Daily '!I7 -> 2437 | M3: ='FS-AD Daily '!J7 -> 7006 | N3: ='FS-AD Daily '!T7 -> 147.508 | O3: ='FS-AD Daily '!R7 -> 66.685 | P3: ='FS-AD Daily '!Z7 -> 574 | Q3: ='FS-AD Daily '!V7 -> 270.7 | R3: ='FS-AD Daily '!W7 -> 0 | S3: =P3-Q3-R3 -> 303.3 | T3: ='FS-AD Daily '!AD7*3.516 -> 43591.368 | U3: =('FS-AD Daily '!AF7)*1000 -> 20600 | V3: =('FS-AD Daily '!AG7)*1000 -> 8100 | W3: ='FS-AD Daily '!AH7*1000 -> 6300 | X3: =('FS-AD Daily '!AK7)*1000 -> 18600 | Y3: 87 | Z3: 138
A4: Abu Dhabi | B4: =B3+1 -> 3 | C4: 3 | D4: 2021 | E4: ='FS-AD Daily '!B8 -> 4788 | F4: ='FS-AD Daily '!C8 -> 3102 | G4: ='FS-AD Daily '!D8 -> 944 | H4: ='FS-AD Daily '!E8 -> 4708 | I4: ='FS-AD Daily '!F8 -> 5782 | J4: ='FS-AD Daily '!G8 -> 2632 | K4: ='FS-AD Daily '!H8 -> 3574 | L4: ='FS-AD Daily '!I8 -> 2475 | M4: ='FS-AD Daily '!J8 -> 6995 | N4: ='FS-AD Daily '!T8 -> 134.99 | O4: ='FS-AD Daily '!R8 -> 70.139 | P4: ='FS-AD Daily '!Z8 -> 600 | Q4: ='FS-AD Daily '!V8 -> 292.6 | R4: ='FS-AD Daily '!W8 -> 0 | S4: =P4-Q4-R4 -> 307.4 | T4: ='FS-AD Daily '!AD8*3.516 -> 48731.057 | U4: =('FS-AD Daily '!AF8)*1000 -> 22900 | V4: =('FS-AD Daily '!AG8)*1000 -> 8900 | W4: ='FS-AD Daily '!AH8*1000 -> 7300 | X4: =('FS-AD Daily '!AK8)*1000 -> 19400 | Y4: 75 | Z4: 122
A5: Abu Dhabi | B5: =B4+1 -> 4 | C5: 3 | D5: 2021 | E5: ='FS-AD Daily '!B9 -> 4576 | F5: ='FS-AD Daily '!C9 -> 2110 | G5: ='FS-AD Daily '!D9 -> 881 | H5: ='FS-AD Daily '!E9 -> 4717 | I5: ='FS-AD Daily '!F9 -> 6086 | J5: ='FS-AD Daily '!G9 -> 2679 | K5: ='FS-AD Daily '!H9 -> 3767 | L5: ='FS-AD Daily '!I9 -> 2548 | M5: ='FS-AD Daily '!J9 -> 7585 | N5: ='FS-AD Daily '!T9 -> 151.235 | O5: ='FS-AD Daily '!R9 -> 76.669 | P5: ='FS-AD Daily '!Z9 -> 601 | Q5: ='FS-AD Daily '!V9 -> 282.7 | R5: ='FS-AD Daily '!W9 -> 0 | S5: =P5-Q5-R5 -> 318.3 | T5: ='FS-AD Daily '!AD9*3.516 -> 50052.721 | U5: =('FS-AD Daily '!AF9)*1000 -> 22700 | V5: =('FS-AD Daily '!AG9)*1000 -> 9600 | W5: ='FS-AD Daily '!AH9*1000 -> 7700 | X5: =('FS-AD Daily '!AK9)*1000 -> 19600 | Y5: 80 | Z5: 138
A6: Abu Dhabi | B6: =B5+1 -> 5 | C6: 3 | D6: 2021 | E6: ='FS-AD Daily '!B10 -> 4826 | F6: ='FS-AD Daily '!C10 -> 1976 | G6: ='FS-AD Daily '!D10 -> 949 | H6: ='FS-AD Daily '!E10 -> 4713 | I6: ='FS-AD Daily '!F10 -> 5997 | J6: ='FS-AD Daily '!G10 -> 2651 | K6: ='FS-AD Daily '!H10 -> 3661 | L6: ='FS-AD Daily '!I10 -> 2528 | M6: ='FS-AD Daily '!J10 -> 7543 | N6: ='FS-AD Daily '!T10 -> 146.274 | O6: ='FS-AD Daily '!R10 -> 77.909 | P6: ='FS-AD Daily '!Z10 -> 640 | Q6: ='FS-AD Daily '!V10 -> 307.5 | R6: ='FS-AD Daily '!W10 -> 0 | S6: =P6-Q6-R6 -> 332.5 | T6: ='FS-AD Daily '!AD10*3.516 -> 52173.572 | U6: =('FS-AD Daily '!AF10)*1000 -> 23500 | V6: =('FS-AD Daily '!AG10)*1000 -> 9900 | W6: ='FS-AD Daily '!AH10*1000 -> 8300 | X6: =('FS-AD Daily '!AK10)*1000 -> 21500 | Y6: 94 | Z6: 162
A7: Abu Dhabi | B7: =B6+1 -> 6 | C7: 3 | D7: 2021 | E7: ='FS-AD Daily '!B11 -> 5668 | F7: ='FS-AD Daily '!C11 -> 2163 | G7: ='FS-AD Daily '!D11 -> 945 | H7: ='FS-AD Daily '!E11 -> 4693 | I7: ='FS-AD Daily '!F11 -> 5856 | J7: ='FS-AD Daily '!G11 -> 2670 | K7: ='FS-AD Daily '!H11 -> 3751 | L7: ='FS-AD Daily '!I11 -> 1734 | M7: ='FS-AD Daily '!J11 -> 7125 | N7: ='FS-AD Daily '!T11 -> 143.695 | O7: ='FS-AD Daily '!R11 -> 74.643 | P7: ='FS-AD Daily '!Z11 -> 584 | Q7: ='FS-AD Daily '!V11 -> 288.8 | R7: ='FS-AD Daily '!W11 -> 0 | S7: =P7-Q7-R7 -> 295.2 | T7: ='FS-AD Daily '!AD11*3.516 -> 46086.322 | U7: =('FS-AD Daily '!AF11)*1000 -> 20900 | V7: =('FS-AD Daily '!AG11)*1000 -> 7900 | W7: ='FS-AD Daily '!AH11*1000 -> 7400 | X7: =('FS-AD Daily '!AK11)*1000 -> 19900 | Y7: 77 | Z7: 117
A8: Abu Dhabi | B8: =B7+1 -> 7 | C8: 3 | D8: 2021 | E8: ='FS-AD Daily '!B12 -> 5669 | F8: ='FS-AD Daily '!C12 -> 2105 | G8: ='FS-AD Daily '!D12 -> 873 | H8: ='FS-AD Daily '!E12 -> 4431 | I8: ='FS-AD Daily '!F12 -> 5837 | J8: ='FS-AD Daily '!G12 -> 2681 | K8: ='FS-AD Daily '!H12 -> 3691 | L8: ='FS-AD Daily '!I12 -> 3293 | M8: ='FS-AD Daily '!J12 -> 7005 | N8: ='FS-AD Daily '!T12 -> 139.133 | O8: ='FS-AD Daily '!R12 -> 73.277 | P8: ='FS-AD Daily '!Z12 -> 575 | Q8: ='FS-AD Daily '!V12 -> 276.8 | R8: ='FS-AD Daily '!W12 -> 0 | S8: =P8-Q8-R8 -> 298.2 | T8: ='FS-AD Daily '!AD12*3.516 -> 40406.224 | U8: =('FS-AD Daily '!AF12)*1000 -> 18700 | V8: =('FS-AD Daily '!AG12)*1000 -> 8100 | W8: ='FS-AD Daily '!AH12*1000 -> 6600 | X8: =('FS-AD Daily '!AK12)*1000 -> 16100 | Y8: 72 | Z8: 110
A9: Abu Dhabi | B9: =B8+1 -> 8 | C9: 3 | D9: 2021 | E9: ='FS-AD Daily '!B13 -> 4900 | F9: ='FS-AD Daily '!C13 -> 2125 | G9: ='FS-AD Daily '!D13 -> 891 | H9: ='FS-AD Daily '!E13 -> 4411 | I9: ='FS-AD Daily '!F13 -> 5843 | J9: ='FS-AD Daily '!G13 -> 2559 | K9: ='FS-AD Daily '!H13 -> 3708 | L9: ='FS-AD Daily '!I13 -> 3462 | M9: ='FS-AD Daily '!J13 -> 7007 | N9: ='FS-AD Daily '!T13 -> 104.255 | O9: ='FS-AD Daily '!R13 -> 67.418 | P9: ='FS-AD Daily '!Z13 -> 552 | Q9: ='FS-AD Daily '!V13 -> 257 | R9: ='FS-AD Daily '!W13 -> 0 | S9: =P9-Q9-R9 -> 295 | T9: ='FS-AD Daily '!AD13*3.516 -> 39503.315 | U9: =('FS-AD Daily '!AF13)*1000 -> 18100 | V9: =('FS-AD Daily '!AG13)*1000 -> 8100 | W9: ='FS-AD Daily '!AH13*1000 -> 6100 | X9: =('FS-AD Daily '!AK13)*1000 -> 16300 | Y9: 71 | Z9: 106
A10: Abu Dhabi | B10: =B9+1 -> 9 | C10: 3 | D10: 2021 | E10: ='FS-AD Daily '!B14 -> 5184 | F10: ='FS-AD Daily '!C14 -> 2560 | G10: ='FS-AD Daily '!D14 -> 903 | H10: ='FS-AD Daily '!E14 -> 4596 | I10: ='FS-AD Daily '!F14 -> 5825 | J10: ='FS-AD Daily '!G14 -> 2600 | K10: ='FS-AD Daily '!H14 -> 3811 | L10: ='FS-AD Daily '!I14 -> 1475 | M10: ='FS-AD Daily '!J14 -> 6996 | N10: ='FS-AD Daily '!T14 -> 134.164 | O10: ='FS-AD Daily '!R14 -> 68.021 | P10: ='FS-AD Daily '!Z14 -> 557 | Q10: ='FS-AD Daily '!V14 -> 275.5 | R10: ='FS-AD Daily '!W14 -> 0 | S10: =P10-Q10-R10 -> 281.5 | T10: ='FS-AD Daily '!AD14*3.516 -> 41978.93 | U10: =('FS-AD Daily '!AF14)*1000 -> 19700 | V10: =('FS-AD Daily '!AG14)*1000 -> 8600 | W10: ='FS-AD Daily '!AH14*1000 -> 6200 | X10: =('FS-AD Daily '!AK14)*1000 -> 16900 | Y10: 80 | Z10: 121
A11: Abu Dhabi | B11: =B10+1 -> 10 | C11: 3 | D11: 2021 | E11: ='FS-AD Daily '!B15 -> 5085 | F11: ='FS-AD Daily '!C15 -> 2557 | G11: ='FS-AD Daily '!D15 -> 898 | H11: ='FS-AD Daily '!E15 -> 4688 | I11: ='FS-AD Daily '!F15 -> 5898 | J11: ='FS-AD Daily '!G15 -> 2630 | K11: ='FS-AD Daily '!H15 -> 3808 | L11: ='FS-AD Daily '!I15 -> 2391 | M11: ='FS-AD Daily '!J15 -> 6981 | N11: ='FS-AD Daily '!T15 -> 130.631 | O11: ='FS-AD Daily '!R15 -> 70.068 | P11: ='FS-AD Daily '!Z15 -> 572 | Q11: ='FS-AD Daily '!V15 -> 278.7 | R11: ='FS-AD Daily '!W15 -> 0 | S11: =P11-Q11-R11 -> 293.3 | T11: ='FS-AD Daily '!AD15*3.516 -> 41908.61 | U11: =('FS-AD Daily '!AF15)*1000 -> 19800 | V11: =('FS-AD Daily '!AG15)*1000 -> 8900 | W11: ='FS-AD Daily '!AH15*1000 -> 6800 | X11: =('FS-AD Daily '!AK15)*1000 -> 17800 | Y11: 83 | Z11: 121
A12: Abu Dhabi | B12: =B11+1 -> 11 | C12: 3 | D12: 2021 | E12: ='FS-AD Daily '!B16 -> 5610 | F12: ='FS-AD Daily '!C16 -> 2501 | G12: ='FS-AD Daily '!D16 -> 890 | H12: ='FS-AD Daily '!E16 -> 4849 | I12: ='FS-AD Daily '!F16 -> 6191 | J12: ='FS-AD Daily '!G16 -> 2775 | K12: ='FS-AD Daily '!H16 -> 3948 | L12: ='FS-AD Daily '!I16 -> 2559 | M12: ='FS-AD Daily '!J16 -> 6810 | N12: ='FS-AD Daily '!T16 -> 145.599 | O12: ='FS-AD Daily '!R16 -> 80.555 | P12: ='FS-AD Daily '!Z16 -> 610 | Q12: ='FS-AD Daily '!V16 -> 294.7 | R12: ='FS-AD Daily '!W16 -> 0 | S12: =P12-Q12-R12 -> 315.3 | T12: ='FS-AD Daily '!AD16*3.516 -> 48452.941 | U12: =('FS-AD Daily '!AF16)*1000 -> 21900 | V12: =('FS-AD Daily '!AG16)*1000 -> 9100 | W12: ='FS-AD Daily '!AH16*1000 -> 7600 | X12: =('FS-AD Daily '!AK16)*1000 -> 20000 | Y12: 82 | Z12: 129
A13: Abu Dhabi | B13: =B12+1 -> 12 | C13: 3 | D13: 2021 | E13: ='FS-AD Daily '!B17 -> 4774 | F13: ='FS-AD Daily '!C17 -> 2280 | G13: ='FS-AD Daily '!D17 -> 910 | H13: ='FS-AD Daily '!E17 -> 4527 | I13: ='FS-AD Daily '!F17 -> 5893 | J13: ='FS-AD Daily '!G17 -> 2465 | K13: ='FS-AD Daily '!H17 -> 3685 | L13: ='FS-AD Daily '!I17 -> 2419 | M13: ='FS-AD Daily '!J17 -> 6864 | N13: ='FS-AD Daily '!T17 -> 138.346 | O13: ='FS-AD Daily '!R17 -> 77.327 | P13: ='FS-AD Daily '!Z17 -> 623 | Q13: ='FS-AD Daily '!V17 -> 276.9 | R13: ='FS-AD Daily '!W17 -> 0 | S13: =P13-Q13-R13 -> 346.1 | T13: ='FS-AD Daily '!AD17*3.516 -> 49202.904 | U13: =('FS-AD Daily '!AF17)*1000 -> 22200 | V13: =('FS-AD Daily '!AG17)*1000 -> 9700 | W13: ='FS-AD Daily '!AH17*1000 -> 7800 | X13: =('FS-AD Daily '!AK17)*1000 -> 20100 | Y13: 75 | Z13: 131
A14: Abu Dhabi | B14: =B13+1 -> 13 | C14: 3 | D14: 2021 | E14: ='FS-AD Daily '!B18 -> 6500 | F14: ='FS-AD Daily '!C18 -> 2471 | G14: ='FS-AD Daily '!D18 -> 896 | H14: ='FS-AD Daily '!E18 -> 4711 | I14: ='FS-AD Daily '!F18 -> 5845 | J14: ='FS-AD Daily '!G18 -> 2541 | K14: ='FS-AD Daily '!H18 -> 3797 | L14: ='FS-AD Daily '!I18 -> 2531 | M14: ='FS-AD Daily '!J18 -> 6842 | N14: ='FS-AD Daily '!T18 -> 131.909 | O14: ='FS-AD Daily '!R18 -> 69.032 | P14: ='FS-AD Daily '!Z18 -> 548 | Q14: ='FS-AD Daily '!V18 -> 267.4 | R14: ='FS-AD Daily '!W18 -> 0 | S14: =P14-Q14-R14 -> 280.6 | T14: ='FS-AD Daily '!AD18*3.516 -> 50148.708 | U14: =('FS-AD Daily '!AF18)*1000 -> 21900 | V14: =('FS-AD Daily '!AG18)*1000 -> 9000 | W14: ='FS-AD Daily '!AH18*1000 -> 8500 | X14: =('FS-AD Daily '!AK18)*1000 -> 22700 | Y14: 63 | Z14: 90
... A32: Abu Dhabi | B32: =B31+1 -> 31 | C32: 3 | D32: 2021 | E32: ='FS-AD Daily '!B36 -> 5135 | F32: ='FS-AD Daily '!C36 -> 2188 | G32: ='FS-AD Daily '!D36 -> 969 | H32: ='FS-AD Daily '!E36 -> 5513 | I32: ='FS-AD Daily '!F36 -> 5930 | J32: ='FS-AD Daily '!G36 -> 3115 | K32: ='FS-AD Daily '!H36 -> 5569 | L32: ='FS-AD Daily '!I36 -> 2452 | M32: ='FS-AD Daily '!J36 -> 7418 | N32: ='FS-AD Daily '!T36 -> 168.127 | O32: ='FS-AD Daily '!R36 -> 81.561 | P32: ='FS-AD Daily '!Z36 -> 581 | Q32: ='FS-AD Daily '!V36 -> 278 | R32: ='FS-AD Daily '!W36 -> 0 | S32: =P32-Q32-R32 -> 303 | T32: ='FS-AD Daily '!AD36*3.516 -> 60460.784 | U32: =('FS-AD Daily '!AF36)*1000 -> 27100 | V32: =('FS-AD Daily '!AG36)*1000 -> 14700 | W32: ='FS-AD Daily '!AH36*1000 -> 9500 | X32: =('FS-AD Daily '!AK36)*1000 -> 24300 | Y32: 131 | Z32: 212
I33: =SUM(I2:I32) -> 182670 | J33: =SUM(J2:J32) -> 84495 | K33: =SUM(K2:K32) -> 120168 | L33: =SUM(L2:L32) -> 76802 | M33: =SUM(M2:M32) -> 220905 | N33: =SUM(N2:N32) -> 4360.0306 | O33: =SUM(O2:O32) -> 2237.191 | P33: =SUM(P2:P32) -> 18403 | ... W33: =SUM(W2:W32) -> 256400 | X33: ='FS-AD Daily '!U38 -> 16643.062 | Y33: =SUM(Y2:Y32) -> 2717 | Z33: =SUM(Z2:Z32) -> 4288

Sheet FS-AD Daily 
A1: DATE | B1: ELECTRICAL METERS | K1: TOTAL CONSUMPTION (kWh) | L1: ELECTRICITY - TOTAL (AED) | M1: Concrete Tank Meter (Daily Consumption) | N1: Fiber tank Meter Cold Water Podium & Galleria Staff Toilet Section 2 | O1: Galleria Hot water Public Area | P1: Water Bulk 3 Meter Galleria (Daily Consumption) section 1 | Q1: Irrigation Tank Meter (Daily Consumption) | R1: Galleria Consumption m3 | S1: GALLERIA WATER TOTAL COST (AED) | T1: WATER METER (Daily Consumption) m3 | U1: FSH WATER (AED) | V1: Hot Water Boiler (Daily Gas Consumption m 3) | W1: Steam Boiler (Daily Gas Consumption m 3) | X1: GAS METERS (Daily Reading) | Z1: GAS (Daily Consumption m 3) | AA1: Natural GAS (AED) | AB1: CHILLED WATER (Daily Reading) Present HT | AC1: CHILLED WATER (Daily Reading) Previous HT | AD1: CHILLED WATER (Daily Consumption) HT | AE1: CHILLED WATER (AED) | AF1: Podium Chilled Water - MWh | AG1: Guest Room Chilled Water MWh | AH1: Residence Chilled Water MWh | AI1: Galleria chilled water MWH Previous | AJ1: Galleria chilled water MWH Present | AK1: Galleria Chilled Water Total MWH | AL1: Galleria Chilled Water Total HT | AM1: CHILLED WATER (AED) | AN1: OCCUPANCY (Room Night) | AO1: TOTAL (AED) | AQ1: THR AED (0.334529) | AR1: MWH = H.TON (1 = 284.34)
A2: 2021 | B2: 1 | C2: 2 | D2: 3 | E2: 4 | F2: 5 | G2: 6 | H2: 7 | I2: 8 | J2: 9 | K2: TOTAL CONSUMPTION (KWH) | L2: TOTAL AMOUNT (AED) | X2: 1 | Y2: 2 | AA2: (AED. 6.47/m3 + AED. 0.00 Service) | AC2: (K21B2419000) | AE2: AED. 0.333415/Ton | AM2: AED. 0.333415/Ton
B3: 4626096222-E | C3: 6572482789-E | D3: 3190048503-E | E3: 3732963488-E | F3: 4626096253-E | G3: 7651356710-E | H3: 5076351256-E | I3: 8990986529-E | J3: 6057081392-E
B4: LVS-1 SECTION A | C4: LVS-1 SECTION B | D4: LVS-2 (CAFÉ MILANO) | E4: LVS-3 SECTION A | F4: LVS-3 SECTION B | G4: LVS-4 SECTION A | H4: LVS-4 SECTION B | I4: LVS-5 (FLOOR 15-32) | J4: LVS-LRLV (RETAIL) | Y4: 791969 | AB4: 2988990 | AI4: 40910.7 | AP4: 0.333415
A5: TOTAL | E5: Hot water calorifiers L 14 feed 15 - 19 floor | G5: Residence Apartment chilled water pump share feeder | H5: Residence Public Area Electric DB share feeder | I5: Residence apartments Electric DB (individual apartment feeder) | X5: Galleria independent supply | AA5: =SUM(#REF!) -> #REF! | AE5: =SUM(#REF!) -> #REF! | AK5: =SUM(#REF!) -> #REF! | AO5: =SUM(#REF!) -> #REF!
A6: 44256 | B6: =11452140-11447167 -> 4973 | C6: =7317935-7315796 -> 2139 | D6: =1407898-1407040 -> 858 | E6: =10859814-10855188 -> 4626 | F6: =10709914-10704120 -> 5794 | G6: =7918465-7915740 -> 2725 | H6: =7813112-7809523 -> 3589 | I6: =4881299-4878893 -> 2406 | J6: =10630054-10623129 -> 6925 | K6: =SUM(B6:H6) -> 24704 | L6: =K6*0.2 -> 4940.8 | M6: =62546.65-62447.955 -> 98.695 | N6: =4014.606-4013.027 -> 1.579 | O6: =9288.447-9287.673 -> 0.774 | P6: =82024.409-81961.525 -> 62.884 | Q6: =22547.376-22537.316 -> 10.06 | R6: =N6+O6+P6 -> 65.237 | S6: =(N6+O6+P6)*7.84 -> 511.45808 | T6: =M6+Q6 -> 108.755 | U6: =T6*7.84 -> 852.6392 | V6: =327570.6-327267.5 -> 303.1 | W6: =129679.18-129673.03 -> 6.15 | X6: 0001523.20 | Y6: 792592 | Z6: =IF((Y6-Y5<0), "0",Y6-Y4) -> 623 | AA6: =Z6*6.47 -> 4030.81 | AB6: 2999004 | AC6: =AB4 -> 2988990 | AD6: =IF((AB6-AC6<0), "0",AB6-AC6) -> 10014 | AE6: =AD6*0.333415 -> 3338.8178 | AF6: =82841.6-82825.3 -> 16.3 | AG6: =43132.9-43125.7 -> 7.2 | AH6: =26047.7-26042.3 -> 5.4 | AI6: =AI4 -> 40910.7 | AJ6: 40925.9 | AK6: =IF((AJ6-AI6)<0, "0",AJ6-AI6) -> 15.2 | AL6: =AK6*(284.34513609) -> 4322.0461 | AM6: =AL6*0.333415 -> 1441.035 | AN6: 71 | AO6: =L6+U6+AA6+AE6 -> 13163.067
A7: 44257 | B7: =11457697-11452140 -> 5557 | C7: =7320306-7317935 -> 2371 | D7: =1408790-1407898 -> 892 | E7: =10864503-10859814 -> 4689 | F7: =10715665-10709914 -> 5751 | G7: =7921121-7918465 -> 2656 | H7: =7816679-7813112 -> 3567 | I7: =4883736-4881299 -> 2437 | J7: =10637060-10630054 -> 7006 | K7: =SUM(B7:H7) -> 25483 | L7: =K7*0.2 -> 5096.6 | M7: =62683.81-62546.65 -> 137.16 | N7: =4016.39-4014.606 -> 1.784 | O7: =9289.307-9288.447 -> 0.86 | P7: =82088.45-82024.409 -> 64.041 | Q7: =22557.724-22547.376 -> 10.348 | R7: =N7+O7+P7 -> 66.685 | S7: =(N7+O7+P7)*7.84 -> 522.8104 | T7: =M7+Q7 -> 147.508 | U7: =T7*7.84 -> 1156.4627 | V7: =327841.3-327570.6 -> 270.7 | W7: =129679.18-129679.18 -> 0 | X7: 0001523.20 | Y7: 793166 | Z7: =IF((Y7-Y6<0), "0",Y7-Y6) -> 574 | AA7: =Z7*6.47 -> 3713.78 | AB7: 3011402 | AC7: =AB6 -> 2999004 | AD7: =IF((AB7-AC7<0), "0",AB7-AC7) -> 12398 | AE7: =AD7*0.333415 -> 4133.6792 | AF7: =82862.2-82841.6 -> 20.6 | AG7: =43141-43132.9 -> 8.1 | AH7: =26054-26047.7 -> 6.3 | AI7: =AJ6 -> 40925.9 | AJ7: 40944.5 | AK7: =IF((AJ7-AI7)<0, "0",AJ7-AI7) -> 18.6 | AL7: =AK7*(284.34513609) -> 5288.8195 | AM7: =AL7*0.333415 -> 1763.3718 | AN7: 87 | AO7: =L7+U7+AA7+AE7 -> 14100.522
A8: 44258 | B8: =11462485-11457697 -> 4788 | C8: =7323408-7320306 -> 3102 | D8: =1409734-1408790 -> 944 | E8: =10869211-10864503 -> 4708 | F8: =10721447-10715665 -> 5782 | G8: =7923753-7921121 -> 2632 | H8: =7820253-7816679 -> 3574 | I8: =4886211-4883736 -> 2475 | J8: =10644055-10637060 -> 6995 | K8: =SUM(B8:H8) -> 25530 | L8: =K8*0.2 -> 5106 | M8: =62808.464-62683.81 -> 124.654 | N8: =4017.859-4016.39 -> 1.469 | O8: =9290.039-9289.307 -> 0.732 | P8: =82156.388-82088.45 -> 67.938 | Q8: =22568.06-22557.724 -> 10.336 | R8: =N8+O8+P8 -> 70.139 | S8: =(N8+O8+P8)*7.84 -> 549.88976 | T8: =M8+Q8 -> 134.99 | U8: =T8*7.84 -> 1058.3216 | V8: =328133.9-327841.3 -> 292.6 | W8: =129679.18-129679.18 -> 0 | X8: 0001523.20 | Y8: 793766 | Z8: =IF((Y8-Y7<0), "0",Y8-Y7) -> 600 | AA8: =Z8*6.47 -> 3882 | AB8: 3025261.8 | AC8: =AB7 -> 3011402 | AD8: =IF((AB8-AC8<0), "0",AB8-AC8) -> 13859.8 | AE8: =AD8*0.333415 -> 4621.0652 | AF8: =82885.1-82862.2 -> 22.9 | AG8: =43149.9-43141 -> 8.9 | AH8: =26061.3-26054 -> 7.3 | AI8: =AJ7 -> 40944.5 | AJ8: 40963.9 | AK8: =IF((AJ8-AI8)<0, "0",AJ8-AI8) -> 19.4 | AL8: =AK8*(284.34513609) -> 5516.2956 | AM8: =AL8*0.333415 -> 1839.2157 | AN8: 75 | AO8: =L8+U8+AA8+AE8 -> 14667.387
A9: 44259 | B9: =11467061-11462485 -> 4576 | C9: =7325518-7323408 -> 2110 | D9: =1410615-1409734 -> 881 | E9: =10873928-10869211 -> 4717 | F9: =10727533-10721447 -> 6086 | G9: =7926432-7923753 -> 2679 | H9: =7824020-7820253 -> 3767 | I9: =4888759-4886211 -> 2548 | J9: =10651640-10644055 -> 7585 | K9: =SUM(B9:H9) -> 24816 | L9: =K9*0.2 -> 4963.2 | M9: =62949.196-62808.464 -> 140.732 | N9: =4019.175-4017.859 -> 1.316 | O9: =9290.678-9290.039 -> 0.639 | P9: =82231.102-82156.388 -> 74.714 | Q9: =22578.563-22568.06 -> 10.503 | R9: =N9+O9+P9 -> 76.669 | S9: =(N9+O9+P9)*7.84 -> 601.08496 | T9: =M9+Q9 -> 151.235 | U9: =T9*7.84 -> 1185.6824 | V9: =328416.6-328133.9 -> 282.7 | W9: =129679.18-129679.18 -> 0 | X9: 0001523.20 | Y9: 794367 | Z9: =IF((Y9-Y8<0), "0",Y9-Y8) -> 601 | AA9: =Z9*6.47 -> 3888.47 | AB9: 3039497.5 | AC9: =AB8 -> 3025261.8 | AD9: =IF((AB9-AC9<0), "0",AB9-AC9) -> 14235.7 | AE9: =AD9*0.333415 -> 4746.3959 | AF9: =82907.8-82885.1 -> 22.7 | AG9: =43159.5-43149.9 -> 9.6 | AH9: =26069-26061.3 -> 7.7 | AI9: =AJ8 -> 40963.9 | AJ9: 40983.5 | AK9: =IF((AJ9-AI9)<0, "0",AJ9-AI9) -> 19.6 | AL9: =AK9*(284.34513609) -> 5573.1647 | AM9: =AL9*0.333415 -> 1858.1767 | AN9: 80 | AO9: =L9+U9+AA9+AE9 -> 14783.748
A10: 44260 | B10: =11471887-11467061 -> 4826 | C10: =7327494-7325518 -> 1976 | D10: =1411564-1410615 -> 949 | E10: =10878641-10873928 -> 4713 | F10: =10733530-10727533 -> 5997 | G10: =7929083-7926432 -> 2651 | H10: =7827681-7824020 -> 3661 | I10: =4891287-4888759 -> 2528 | J10: =10659183-10651640 -> 7543 | K10: =SUM(B10:H10) -> 24773 | L10: =K10*0.2 -> 4954.6 | M10: =63086.569-62949.196 -> 137.373 | N10: =4020.468-4019.175 -> 1.293 | O10: =9291.22-9290.678 -> 0.542 | P10: =82307.176-82231.102 -> 76.074 | Q10: =22587.464-22578.563 -> 8.901 | R10: =N10+O10+P10 -> 77.909 | S10: =(N10+O10+P10)*7.84 -> 610.80656 | T10: =M10+Q10 -> 146.274 | U10: =T10*7.84 -> 1146.7882 | V10: =328724.1-328416.6 -> 307.5 | W10: =129679.18-129679.18 -> 0 | X10: 0001523.20 | Y10: 795007 | Z10: =IF((Y10-Y9<0), "0",Y10-Y9) -> 640 | AA10: =Z10*6.47 -> 4140.8 | AB10: 3054336.4 | AC10: =AB9 -> 3039497.5 | AD10: =IF((AB10-AC10<0), "0",AB10-AC10) -> 14838.9 | AE10: =AD10*0.333415 -> 4947.5118 | AF10: =82931.3-82907.8 -> 23.5 | AG10: =43169.4-43159.5 -> 9.9 | AH10: =26077.3-26069 -> 8.3 | AI10: =AJ9 -> 40983.5 | AJ10: 41005 | AK10: =IF((AJ10-AI10)<0, "0",AJ10-AI10) -> 21.5 | AL10: =AK10*(284.34513609) -> 6113.4204 | AM10: =AL10*0.333415 -> 2038.3061 | AN10: 94 | AO10: =L10+U10+AA10+AE10 -> 15189.7
A11: 44261 | B11: =11477555-11471887 -> 5668 | C11: =7329657-7327494 -> 2163 | D11: =1412509-1411564 -> 945 | E11: =10883334-10878641 -> 4693 | F11: =10739386-10733530 -> 5856 | G11: =7931753-7929083 -> 2670 | H11: =7831432-7827681 -> 3751 | I11: =4893021-4891287 -> 1734 | J11: =10666308-10659183 -> 7125 | K11: =SUM(B11:H11) -> 25746 | L11: =K11*0.2 -> 5149.2 | M11: =63219.897-63086.569 -> 133.328 | N11: =4023.935-4020.468 -> 3.467 | O11: =9292.737-9291.22 -> 1.517 | P11: =82376.835-82307.176 -> 69.659 | Q11: =22597.831-22587.464 -> 10.367 | R11: =N11+O11+P11 -> 74.643 | S11: =(N11+O11+P11)*7.84 -> 585.20112 | T11: =M11+Q11 -> 143.695 | U11: =T11*7.84 -> 1126.5688 | V11: =329012.9-328724.1 -> 288.8 | W11: =129679.18-129679.18 -> 0 | X11: 0001523.20 | Y11: 795591 | Z11: =IF((Y11-Y10<0), "0",Y11-Y10) -> 584 | AA11: =Z11*6.47 -> 3778.48 | AB11: 3067444 | AC11: =AB10 -> 3054336.4 | AD11: =IF((AB11-AC11<0), "0",AB11-AC11) -> 13107.6 | AE11: =AD11*0.333415 -> 4370.2705 | AF11: =82952.2-82931.3 -> 20.9 | AG11: =43177.3-43169.4 -> 7.9 | AH11: =26084.7-26077.3 -> 7.4 | AI11: =AJ10 -> 41005 | AJ11: 41024.9 | AK11: =IF((AJ11-AI11)<0, "0",AJ11-AI11) -> 19.9 | AL11: =AK11*(284.34513609) -> 5658.4682 | AM11: =AL11*0.333415 -> 1886.6182 | AN11: 77 | AO11: =L11+U11+AA11+AE11 -> 14424.519
A12: 44262 | B12: =11483224-11477555 -> 5669 | C12: =7331762-7329657 -> 2105 | D12: =1413382-1412509 -> 873 | E12: =10887765-10883334 -> 4431 | F12: =10745223-10739386 -> 5837 | G12: =7934434-7931753 -> 2681 | H12: =7835123-7831432 -> 3691 | I12: =4896314-4893021 -> 3293 | J12: =10673313-10666308 -> 7005 | K12: =SUM(B12:H12) -> 25287 | L12: =K12*0.2 -> 5057.4 | M12: =63348.456-63219.897 -> 128.559 | N12: =4025.806-4023.935 -> 1.871 | O12: =9293.326-9292.737 -> 0.589 | P12: =82447.652-82376.835 -> 70.817 | Q12: =22608.405-22597.831 -> 10.574 | R12: =N12+O12+P12 -> 73.277 | S12: =(N12+O12+P12)*7.84 -> 574.49168 | T12: =M12+Q12 -> 139.133 | U12: =T12*7.84 -> 1090.8027 | V12: =329289.7-329012.9 -> 276.8 | W12: =129679.18-129679.18 -> 0 | X12: 0001523.20 | Y12: 796166 | Z12: =IF((Y12-Y11<0), "0",Y12-Y11) -> 575 | AA12: =Z12*6.47 -> 3720.25 | AB12: 3078936.1 | AC12: =AB11 -> 3067444 | AD12: =IF((AB12-AC12<0), "0",AB12-AC12) -> 11492.1 | AE12: =AD12*0.333415 -> 3831.6385 | AF12: =82970.9-82952.2 -> 18.7 | AG12: =43185.4-43177.3 -> 8.1 | AH12: =26091.3-26084.7 -> 6.6 | AI12: =AJ11 -> 41024.9 | AJ12: 41041 | AK12: =IF((AJ12-AI12)<0, "0",AJ12-AI12) -> 16.1 | AL12: =AK12*(284.34513609) -> 4577.9567 | AM12: =AL12*0.333415 -> 1526.3594 | AN12: 72 | AO12: =L12+U12+AA12+AE12 -> 13700.091
A13: 44263 | B13: =11488124-11483224 -> 4900 | C13: =7333887-7331762 -> 2125 | D13: =1414273-1413382 -> 891 | E13: =10892176-10887765 -> 4411 | F13: =10751066-10745223 -> 5843 | G13: =7936993-7934434 -> 2559 | H13: =7838831-7835123 -> 3708 | I13: =4899776-4896314 -> 3462 | J13: =10680320-10673313 -> 7007 | K13: =SUM(B13:H13) -> 24437 | L13: =K13*0.2 -> 4887.4 | M13: =63441.971-63348.456 -> 93.515 | N13: =4027.637-4025.806 -> 1.831 | O13: =9293.975-9293.326 -> 0.649 | P13: =82512.59-82447.652 -> 64.938 | Q13: =22619.145-22608.405 -> 10.74 | R13: =N13+O13+P13 -> 67.418 | S13: =(N13+O13+P13)*7.84 -> 528.55712 | T13: =M13+Q13 -> 104.255 | U13: =T13*7.84 -> 817.3592 | V13: =329546.7-329289.7 -> 257 | W13: =129679.18-129679.18 -> 0 | X13: 0001523.20 | Y13: 796718 | Z13: =IF((Y13-Y12<0), "0",Y13-Y12) -> 552 | AA13: =Z13*6.47 -> 3571.44 | AB13: 3090171.4 | AC13: =AB12 -> 3078936.1 | AD13: =IF((AB13-AC13<0), "0",AB13-AC13) -> 11235.3 | AE13: =AD13*0.333415 -> 3746.0175 | AF13: =82989-82970.9 -> 18.1 | AG13: =43193.5-43185.4 -> 8.1 | AH13: =26097.4-26091.3 -> 6.1 | AI13: =AJ12 -> 41041 | AJ13: 41057.3 | AK13: =IF((AJ13-AI13)<0, "0",AJ13-AI13) -> 16.3 | AL13: =AK13*(284.34513609) -> 4634.8257 | AM13: =AL13*0.333415 -> 1545.3204 | AN13: 71 | AO13: =L13+U13+AA13+AE13 -> 13022.217
A14: 44264 | B14: =11493308-11488124 -> 5184 | C14: =7336447-7333887 -> 2560 | D14: =1415176-1414273 -> 903 | E14: =10896772-10892176 -> 4596 | F14: =10756891-10751066 -> 5825 | G14: =7939593-7936993 -> 2600 | H14: =7842642-7838831 -> 3811 | I14: =4901251-4899776 -> 1475 | J14: =10687316-10680320 -> 6996 | K14: =SUM(B14:H14) -> 25479 | L14: =K14*0.2 -> 5095.8 | M14: =63566.024-63441.971 -> 124.053 | N14: =4029.088-4027.637 -> 1.451 | O14: =9294.673-9293.975 -> 0.698 | P14: =82578.462-82512.59 -> 65.872 | Q14: =22629.256-22619.145 -> 10.111 | R14: =N14+O14+P14 -> 68.021 | S14: =(N14+O14+P14)*7.84 -> 533.28464 | T14: =M14+Q14 -> 134.164 | U14: =T14*7.84 -> 1051.8458 | V14: =329822.2-329546.7 -> 275.5 | W14: =129679.18-129679.18 -> 0 | X14: 0001523.20 | Y14: 797275 | Z14: =IF((Y14-Y13<0), "0",Y14-Y13) -> 557 | AA14: =Z14*6.47 -> 3603.79 | AB14: 3102110.8 | AC14: =AB13 -> 3090171.4 | AD14: =IF((AB14-AC14<0), "0",AB14-AC14) -> 11939.4 | AE14: =AD14*0.333415 -> 3980.7751 | AF14: =83008.7-82989 -> 19.7 | AG14: =43202.1-43193.5 -> 8.6 | AH14: =26103.6-26097.4 -> 6.2 | AI14: =AJ13 -> 41057.3 | AJ14: 41074.2 | AK14: =IF((AJ14-AI14)<0, "0",AJ14-AI14) -> 16.9 | AL14: =AK14*(284.34513609) -> 4805.4328 | AM14: =AL14*0.333415 -> 1602.2034 | AN14: 80 | AO14: =L14+U14+AA14+AE14 -> 13732.211
A15: 44265 | B15: =11498393-11493308 -> 5085 | C15: =7339004-7336447 -> 2557 | D15: =1416074-1415176 -> 898 | E15: =10901460-10896772 -> 4688 | F15: =10762789-10756891 -> 5898 | G15: =7942223-7939593 -> 2630 | H15: =7846450-7842642 -> 3808 | I15: =4903642-4901251 -> 2391 | J15: =10694297-10687316 -> 6981 | K15: =SUM(B15:H15) -> 25564 | L15: =K15*0.2 -> 5112.8 | M15: =63686.7-63566.024 -> 120.676 | N15: =4031.708-4029.088 -> 2.62 | O15: =9295.755-9294.673 -> 1.082 | P15: =82644.828-82578.462 -> 66.366 | Q15: =22639.211-22629.256 -> 9.955 | R15: =N15+O15+P15 -> 70.068 | S15: =(N15+O15+P15)*7.84 -> 549.33312 | T15: =M15+Q15 -> 130.631 | U15: =T15*7.84 -> 1024.147 | V15: =330100.9-329822.2 -> 278.7 | W15: =129679.18-129679.18 -> 0 | X15: 0001523.20 | Y15: 797847 | Z15: =IF((Y15-Y14<0), "0",Y15-Y14) -> 572 | AA15: =Z15*6.47 -> 3700.84 | AB15: 3114030.2 | AC15: =AB14 -> 3102110.8 | AD15: =IF((AB15-AC15<0), "0",AB15-AC15) -> 11919.4 | AE15: =AD15*0.333415 -> 3974.1068 | AF15: =83028.5-83008.7 -> 19.8 | AG15: =43211-43202.1 -> 8.9 | AH15: =26110.4-26103.6 -> 6.8 | AI15: =AJ14 -> 41074.2 | AJ15: 41092 | AK15: =IF((AJ15-AI15)<0, "0",AJ15-AI15) -> 17.8 | AL15: =AK15*(284.34513609) -> 5061.3434 | AM15: =AL15*0.333415 -> 1687.5278 | AN15: 83 | AO15: =L15+U15+AA15+AE15 -> 13811.894
A16: 44266 | B16: =11504003-11498393 -> 5610 | C16: =7341505-7339004 -> 2501 | D16: =1416964-1416074 -> 890 | E16: =10906309-10901460 -> 4849 | F16: =10768980-10762789 -> 6191 | G16: =7944998-7942223 -> 2775 | H16: =7850398-7846450 -> 3948 | I16: =4906201-4903642 -> 2559 | J16: =10701107-10694297 -> 6810 | K16: =SUM(B16:H16) -> 26764 | L16: =K16*0.2 -> 5352.8 | M16: =63821.194-63686.7 -> 134.494 | N16: =4034.41-4031.708 -> 2.702 | O16: =9297.139-9295.755 -> 1.384 | P16: =82721.297-82644.828 -> 76.469 | Q16: =22650.316-22639.211 -> 11.105 | R16: =N16+O16+P16 -> 80.555 | S16: =(N16+O16+P16)*7.84 -> 631.5512 | T16: =M16+Q16 -> 145.599 | U16: =T16*7.84 -> 1141.4962 | V16: =330395.6-330100.9 -> 294.7 | W16: =129679.18-129679.18 -> 0 | X16: 0001523.20 | Y16: 798457 | Z16: =IF((Y16-Y15<0), "0",Y16-Y15) -> 610 | AA16: =Z16*6.47 -> 3946.7 | AB16: 3127810.9 | AC16: =AB15 -> 3114030.2 | AD16: =IF((AB16-AC16<0), "0",AB16-AC16) -> 13780.7 | AE16: =AD16*0.333415 -> 4594.6921 | AF16: =83050.4-83028.5 -> 21.9 | AG16: =43220.1-43211 -> 9.1 | AH16: =26118-26110.4 -> 7.6 | AI16: =AJ15 -> 41092 | AJ16: 41112 | AK16: =IF((AJ16-AI16)<0, "0",AJ16-AI16) -> 20 | AL16: =AK16*(284.34513609) -> 5686.9027 | AM16: =AL16*0.333415 -> 1896.0987 | AN16: 82 | AO16: =L16+U16+AA16+AE16 -> 15035.688
A17: 44267 | B17: =11508777-11504003 -> 4774 | C17: =7343785-7341505 -> 2280 | D17: =1417874-1416964 -> 910 | E17: =10910836-10906309 -> 4527 | F17: =10774873-10768980 -> 5893 | G17: =7947463-7944998 -> 2465 | H17: =7854083-7850398 -> 3685 | I17: =4908620-4906201 -> 2419 | J17: =10707971-10701107 -> 6864 | K17: =SUM(B17:H17) -> 24534 | L17: =K17*0.2 -> 4906.8 | M17: =63950.634-63821.194 -> 129.44 | N17: =4035.924-4034.41 -> 1.514 | O17: =9297.711-9297.139 -> 0.572 | P17: =82796.538-82721.297 -> 75.241 | Q17: =22659.222-22650.316 -> 8.906 | R17: =N17+O17+P17 -> 77.327 | S17: =(N17+O17+P17)*7.84 -> 606.24368 | T17: =M17+Q17 -> 138.346 | U17: =T17*7.84 -> 1084.6326 | V17: =330672.5-330395.6 -> 276.9 | W17: =129679.18-129679.18 -> 0 | X17: 0001523.20 | Y17: 799080 | Z17: =IF((Y17-Y16<0), "0",Y17-Y16) -> 623 | AA17: =Z17*6.47 -> 4030.81 | AB17: 3141804.9 | AC17: =AB16 -> 3127810.9 | AD17: =IF((AB17-AC17<0), "0",AB17-AC17) -> 13994 | AE17: =AD17*0.333415 -> 4665.8095 | AF17: =83072.6-83050.4 -> 22.2 | AG17: =43229.8-43220.1 -> 9.7 | AH17: =26125.8-26118 -> 7.8 | AI17: =AJ16 -> 41112 | AJ17: 41132.1 | AK17: =IF((AJ17-AI17)<0, "0",AJ17-AI17) -> 20.1 | AL17: =AK17*(284.34513609) -> 5715.3372 | AM17: =AL17*0.333415 -> 1905.5792 | AN17: 75 | AO17: =L17+U17+AA17+AE17 -> 14688.052
A18: 44268 | B18: =11515277-11508777 -> 6500 | C18: =7346256-7343785 -> 2471 | D18: =1418770-1417874 -> 896 | E18: =10915547-10910836 -> 4711 | F18: =10780718-10774873 -> 5845 | G18: =7950004-7947463 -> 2541 | H18: =7857880-7854083 -> 3797 | I18: =4911151-4908620 -> 2531 | J18: =10714813-10707971 -> 6842 | K18: =SUM(B18:H18) -> 26761 | L18: =K18*0.2 -> 5352.2 | M18: =64072.039-63950.634 -> 121.405 | N18: =4037.529-4035.924 -> 1.605 | O18: =9298.301-9297.711 -> 0.59 | P18: =82863.375-82796.538 -> 66.837 | Q18: =22669.726-22659.222 -> 10.504 | R18: =N18+O18+P18 -> 69.032 | S18: =(N18+O18+P18)*7.84 -> 541.21088 | T18: =M18+Q18 -> 131.909 | U18: =T18*7.84 -> 1034.1666 | V18: =330939.9-330672.5 -> 267.4 | W18: =129679.18-129679.18 -> 0 | X18: 0001523.20 | Y18: 799628 | Z18: =IF((Y18-Y17<0), "0",Y18-Y17) -> 548 | AA18: =Z18*6.47 -> 3545.56 | AB18: 3156067.9 | AC18: =AB17 -> 3141804.9 | AD18: =IF((AB18-AC18<0), "0",AB18-AC18) -> 14263 | AE18: =AD18*0.333415 -> 4755.4981 | AF18: =83094.5-83072.6 -> 21.9 | AG18: =43238.8-43229.8 -> 9 | AH18: =26134.3-26125.8 -> 8.5 | AI18: =AJ17 -> 41132.1 | AJ18: 41154.8 | AK18: =IF((AJ18-AI18)<0, "0",AJ18-AI18) -> 22.7 | AL18: =AK18*(284.34513609) -> 6454.6346 | AM18: =AL18*0.333415 -> 2152.072 | AN18: 63 | AO18: =L18+U18+AA18+AE18 -> 14687.425
A19: 44269 | B19: =11521291-11515277 -> 6014 | C19: =7348625-7346256 -> 2369 | D19: =1419689-1418770 -> 919 | E19: =10920024-10915547 -> 4477 | F19: =10786528-10780718 -> 5810 | G19: =7952586-7950004 -> 2582 | H19: =7861683-7857880 -> 3803 | I19: =4913585-4911151 -> 2434 | J19: =10722879-10714813 -> 8066 | K19: =SUM(B19:H19) -> 25974 | L19: =K19*0.2 -> 5194.8 | M19: =64174.141-64072.039 -> 102.102 | N19: =4040.102-4037.529 -> 2.573 | O19: =9299.262-9298.301 -> 0.961 | P19: =82926.103-82863.375 -> 62.728 | Q19: =22680.502-22669.726 -> 10.776 | R19: =N19+O19+P19 -> 66.262 | S19: =(N19+O19+P19)*7.84 -> 519.49408 | T19: =M19+Q19 -> 112.878 | U19: =T19*7.84 -> 884.96352 | V19: =331200.7-330939.9 -> 260.8 | W19: =129679.18-129679.18 -> 0 | X19: 0001523.20 | Y19: 800186 | Z19: =IF((Y19-Y18<0), "0",Y19-Y18) -> 558 | AA19: =Z19*6.47 -> 3610.26 | AB19: 3167601.9 | AC19: =AB18 -> 3156067.9 | AD19: =IF((AB19-AC19<0), "0",AB19-AC19) -> 11534 | AE19: =AD19*0.333415 -> 3845.6086 | AF19: =83113.1-83094.5 -> 18.6 | AG19: =43246-43238.8 -> 7.2 | AH19: =26141-26134.3 -> 6.7 | AI19: =AJ18 -> 41154.8 | AJ19: 41173.2 | AK19: =IF((AJ19-AI19)<0, "0",AJ19-AI19) -> 18.4 | AL19: =AK19*(284.34513609) -> 5231.9505 | AM19: =AL19*0.333415 -> 1744.4108 | AN19: 76 | AO19: =L19+U19+AA19+AE19 -> 13535.632
A20: 44270 | B20: =11526575-11521291 -> 5284 | C20: =7350952-7348625 -> 2327 | D20: =1420584-1419689 -> 895 | E20: =10924479-10920024 -> 4455 | F20: =10792218-10786528 -> 5690 | G20: =7955121-7952586 -> 2535 | H20: =7865431-7861683 -> 3748 | I20: =4915967-4913585 -> 2382 | J20: =10729703-10722879 -> 6824 | K20: =SUM(B20:H20) -> 24934 | L20: =K20*0.2 -> 4986.8 | M20: =64287.269-64174.141 -> 113.128 | N20: =4042.68-4040.102 -> 2.578 | O20: =9300.422-9299.262 -> 1.16 | P20: =82992.058-82926.103 -> 65.955 | Q20: =22693.979-22680.502 -> 13.477 | R20: =N20+O20+P20 -> 69.693 | S20: =(N20+O20+P20)*7.84 -> 546.39312 | T20: =M20+Q20 -> 126.605 | U20: =T20*7.84 -> 992.5832 | V20: =331472.6-331200.7 -> 271.9 | W20: =129679.18-129679.18 -> 0 | X20: 0001523.20 | Y20: 800756 | Z20: =IF((Y20-Y19<0), "0",Y20-Y19) -> 570 | AA20: =Z20*6.47 -> 3687.9 | AB20: 3179172.9 | AC20: =AB19 -> 3167601.9 | AD20: =IF((AB20-AC20<0), "0",AB20-AC20) -> 11571 | AE20: =AD20*0.333415 -> 3857.945 | AF20: =83131.8-83113.1 -> 18.7 | AG20: =43253.2-43246 -> 7.2 | AH20: =26147.4-26141 -> 6.4 | AI20: =AJ19 -> 41173.2 | AJ20: 41191.4 | AK20: =IF((AJ20-AI20)<0, "0",AJ20-AI20) -> 18.2 | AL20: =AK20*(284.34513609) -> 5175.0815 | AM20: =AL20*0.333415 -> 1725.4498 | AN20: 74 | AO20: =L20+U20+AA20+AE20 -> 13525.228
A21: 44271 | B21: =11531922-11526575 -> 5347 | C21: =7354028-7350952 -> 3076 | D21: =1421508-1420584 -> 924 | E21: =10929193-10924479 -> 4714 | F21: =10798193-10792218 -> 5975 | G21: =7957777-7955121 -> 2656 | H21: =7869331-7865431 -> 3900 | I21: =4918458-4915967 -> 2491 | J21: =10736685-10729703 -> 6982 | K21: =SUM(B21:H21) -> 26592 | L21: =K21*0.2 -> 5318.4 | M21: =64418.588-64287.27 -> 131.318 | N21: =4044.553-4042.68 -> 1.873 | O21: =9301.236-9300.42 -> 0.816 | P21: =83060.013-82992.06 -> 67.953 | Q21: =22709.621-22693.98 -> 15.641 | R21: =N21+O21+P21 -> 70.642 | S21: =(N21+O21+P21)*7.84 -> 553.83328 | T21: =M21+Q21 -> 146.959 | U21: =T21*7.84 -> 1152.1586 | V21: =331759.3-331472.6 -> 286.7 | W21: =129679.18-129679.18 -> 0 | X21: 0001523.20 | Y21: 801338 | Z21: =IF((Y21-Y20<0), "0",Y21-Y20) -> 582 | AA21: =Z21*6.47 -> 3765.54 | AB21: 3192800 | AC21: =AB20 -> 3179172.9 | AD21: =IF((AB21-AC21<0), "0",AB21-AC21) -> 13627.1 | AE21: =AD21*0.333415 -> 4543.4795 | AF21: =83155.4-83131.8 -> 23.6 | AG21: =43261.3-43253.2 -> 8.1 | AH21: =26154.4-26147.4 -> 7 | AI21: =AJ20 -> 41191.4 | AJ21: 41210.5 | AK21: =IF((AJ21-AI21)<0, "0",AJ21-AI21) -> 19.1 | AL21: =AK21*(284.34513609) -> 5430.9921 | AM21: =AL21*0.333415 -> 1810.7742 | AN21: 76 | AO21: =L21+U21+AA21+AE21 -> 14779.578
A22: 44272 | B22: =11536887-11531922 -> 4965 | C22: =7357324-7354028 -> 3296 | D22: =1422386-1421508 -> 878 | E22: =10934029-10929193 -> 4836 | F22: =10804177-10798193 -> 5984 | G22: =7960315-7957777 -> 2538 | H22: =7873156-7869331 -> 3825 | I22: =4920971-4918458 -> 2513 | J22: =10743691-10736685 -> 7006 | K22: =SUM(B22:H22) -> 26322 | L22: =K22*0.2 -> 5264.4 | M22: =64542.37-64418.588 -> 123.782 | N22: =4046.423-4044.553 -> 1.87 | O22: =9301.956-9301.236 -> 0.72 | P22: =83104.203-83060.013 -> 44.19 | Q22: =22711.054-22709.621 -> 1.433 | R22: =N22+O22+P22 -> 46.78 | S22: =(N22+O22+P22)*7.84 -> 366.7552 | T22: =M22+Q22 -> 125.215 | U22: =T22*7.84 -> 981.6856 | V22: =332028.7-331759.3 -> 269.4 | W22: =129679.18-129679.18 -> 0 | X22: 0001523.20 | Y22: 801921 | Z22: =IF((Y22-Y21<0), "0",Y22-Y21) -> 583 | AA22: =Z22*6.47 -> 3772.01 | AB22: 3207116.9 | AC22: =AB21 -> 3192800 | AD22: =IF((AB22-AC22<0), "0",AB22-AC22) -> 14316.9 | AE22: =AD22*0.333415 -> 4773.4692 | AF22: =83179.3-83155.4 -> 23.9 | AG22: =43270.7-43261.3 -> 9.4 | AH22: =26162.1-26154.4 -> 7.7 | AI22: =AJ21 -> 41210.5 | AJ22: 41230.3 | AK22: =IF((AJ22-AI22)<0, "0",AJ22-AI22) -> 19.8 | AL22: =AK22*(284.34513609) -> 5630.0337 | AM22: =AL22*0.333415 -> 1877.1377 | AN22: 52 | AO22: =L22+U22+AA22+AE22 -> 14791.565
A23: 44273 | B23: =11542112-11536887 -> 5225 | C23: =7359789-7357324 -> 2465 | D23: =1423301-1422386 -> 915 | E23: =10938949-10934029 -> 4920 | F23: =10810161-10804177 -> 5984 | G23: =7962850-7960315 -> 2535 | H23: =7877091-7873156 -> 3935 | I23: =4923543-4920971 -> 2572 | J23: =10750766-10743691 -> 7075 | K23: =SUM(B23:H23) -> 25979 | L23: =K23*0.2 -> 5195.8 | M23: =64677.764-64542.37 -> 135.394 | N23: =4048.432-4046.42 -> 2.012 | O23: =9302.667-9301.96 -> 0.707 | P23: =83198.936-83104.2 -> 94.736 | Q23: =22711.081-22711.05 -> 0.031 | R23: =N23+O23+P23 -> 97.455 | S23: =(N23+O23+P23)*7.84 -> 764.0472 | T23: =M23+Q23 -> 135.425 | U23: =T23*7.84 -> 1061.732 | V23: =332314-332028.7 -> 285.3 | W23: =129679.18-129679.18 -> 0 | X23: 0001523.20 | Y23: 802521 | Z23: =IF((Y23-Y22<0), "0",Y23-Y22) -> 600 | AA23: =Z23*6.47 -> 3882 | AB23: 3221560 | AC23: =AB22 -> 3207116.9 | AD23: =IF((AB23-AC23<0), "0",AB23-AC23) -> 14443.1 | AE23: =AD23*0.333415 -> 4815.5462 | AF23: =83201.7-83179.3 -> 22.4 | AG23: =43281-43270.7 -> 10.3 | AH23: =26170.9-26162.1 -> 8.8 | AI23: =AJ22 -> 41230.3 | AJ23: 41250.7 | AK23: =IF((AJ23-AI23)<0, "0",AJ23-AI23) -> 20.4 | AL23: =AK23*(284.34513609) -> 5800.6408 | AM23: =AL23*0.333415 -> 1934.0206 | AN23: 67 | AO23: =L23+U23+AA23+AE23 -> 14955.078
A24: 44274 | B24: =11547286-11542112 -> 5174 | C24: =7361924-7359789 -> 2135 | D24: =1424194-1423301 -> 893 | E24: =10943670-10938949 -> 4721 | F24: =10816090-10810161 -> 5929 | G24: =7965470-7962850 -> 2620 | H24: =7880907-7877091 -> 3816 | I24: =4926083-4923543 -> 2540 | J24: =10757890-10750766 -> 7124 | K24: =SUM(B24:H24) -> 25288 | L24: =K24*0.2 -> 5057.6 | M24: =64804.297-64677.76 -> 126.537 | N24: =4050.358-4048.43 -> 1.928 | O24: =9303.437-9302.67 -> 0.767 | P24: =83204.645-83198.94 -> 5.705 | Q24: =22711.418-22711.08 -> 0.338 | R24: =N24+O24+P24 -> 8.4 | S24: =(N24+O24+P24)*7.84 -> 65.856 | T24: =M24+Q24 -> 126.875 | U24: =T24*7.84 -> 994.7 | V24: =332599.4-332314 -> 285.4 | W24: =129679.18-129679.18 -> 0 | X24: 0001523.20 | Y24: 803154 | Z24: =IF((Y24-Y23<0), "0",Y24-Y23) -> 633 | AA24: =Z24*6.47 -> 4095.51 | AB24: 3237547 | AC24: =AB23 -> 3221560 | AD24: =IF((AB24-AC24<0), "0",AB24-AC24) -> 15987 | AE24: =AD24*0.333415 -> 5330.3056 | AF24: =83226.8-83201.7 -> 25.1 | AG24: =43292.1-43281 -> 11.1 | AH24: =26180.6-26170.9 -> 9.7 | AI24: =AJ23 -> 41250.7 | AJ24: 41273.3 | AK24: =IF((AJ24-AI24)<0, "0",AJ24-AI24) -> 22.6 | AL24: =AK24*(284.34513609) -> 6426.2001 | AM24: =AL24*0.333415 -> 2142.5915 | AN24: 83 | AO24: =L24+U24+AA24+AE24 -> 15478.116
A25: 44275 | B25: =11552671-11547286 -> 5385 | C25: =7363955-7361924 -> 2031 | D25: =1425113-1424194 -> 919 | E25: =10948587-10943670 -> 4917 | F25: =10821988-10816090 -> 5898 | G25: =7968373-7965470 -> 2903 | H25: =7884803-7880907 -> 3896 | I25: =4928632-4926083 -> 2549 | J25: =10765081-10757890 -> 7191 | K25: =SUM(B25:H25) -> 25949 | L25: =K25*0.2 -> 5189.8 | M25: =64938.114-64804.3 -> 133.814 | N25: =4052.347-4050.36 -> 1.987 | O25: =9304.043-9303.44 -> 0.603 | P25: =83296.895-83204.65 -> 92.245 | Q25: =22724.463-22711.42 -> 13.043 | R25: =N25+O25+P25 -> 94.835 | S25: =(N25+O25+P25)*7.84 -> 743.5064 | T25: =M25+Q25 -> 146.857 | U25: =T25*7.84 -> 1151.3589 | V25: =332879.7-332599.4 -> 280.3 | W25: =129679.18-129679.18 -> 0 | X25: 0001523.20 | Y25: 803723 | Z25: =IF((Y25-Y24<0), "0",Y25-Y24) -> 569 | AA25: =Z25*6.47 -> 3681.43 | AB25: 3254450 | AC25: =AB24 -> 3237547 | AD25: =IF((AB25-AC25<0), "0",AB25-AC25) -> 16903 | AE25: =AD25*0.333415 -> 5635.7137 | AF25: =83253.9-83226.8 -> 27.1 | AG25: =43303.6-43292.1 -> 11.5 | AH25: =26191.1-26180.6 -> 10.5 | AI25: =AJ24 -> 41273.3 | AJ25: 41296.5 | AK25: =IF((AJ25-AI25)<0, "0",AJ25-AI25) -> 23.2 | AL25: =AK25*(284.34513609) -> 6596.8072 | AM25: =AL25*0.333415 -> 2199.4745 | AN25: 78 | AO25: =L25+U25+AA25+AE25 -> 15658.303
A26: 44276 | B26: =11559219-11552671 -> 6548 | C26: =7365996-7363955 -> 2041 | D26: =1425990-1425113 -> 877 | E26: =10953176-10948587 -> 4589 | F26: =10827562-10821988 -> 5574 | G26: =7971154-7968373 -> 2781 | H26: =7888499-7884803 -> 3696 | I26: =4931037-4928632 -> 2405 | J26: =10771823-10765081 -> 6742 | K26: =SUM(B26:H26) -> 26106 | L26: =K26*0.2 -> 5221.2 | M26: =65072.797-64938.114 -> 134.683 | N26: =4054.074-4052.347 -> 1.727 | O26: =9304.608-9304.043 -> 0.565 | P26: =83347.511-83296.895 -> 50.616 | Q26: =22735.025-22724.463 -> 10.562 | R26: =N26+O26+P26 -> 52.908 | S26: =(N26+O26+P26)*7.84 -> 414.79872 | T26: =M26+Q26 -> 145.245 | U26: =T26*7.84 -> 1138.7208 | V26: =333157.3-332879.7 -> 277.6 | W26: =129679.18-129679.18 -> 0 | X26: 0001523.20 | Y26: 804308 | Z26: =IF((Y26-Y25<0), "0",Y26-Y25) -> 585 | AA26: =Z26*6.47 -> 3784.95 | AB26: 3267771.9 | AC26: =AB25 -> 3254450 | AD26: =IF((AB26-AC26<0), "0",AB26-AC26) -> 13321.9 | AE26: =AD26*0.333415 -> 4441.7213 | AF26: =83275.5-83253.9 -> 21.6 | AG26: =43313.1-43303.6 -> 9.5 | AH26: =26199.6-26191.1 -> 8.5 | AI26: =AJ25 -> 41296.5 | AJ26: 41316.3 | AK26: =IF((AJ26-AI26)<0, "0",AJ26-AI26) -> 19.8 | AL26: =AK26*(284.34513609) -> 5630.0337 | AM26: =AL26*0.333415 -> 1877.1377 | AN26: 105 | AO26: =L26+U26+AA26+AE26 -> 14586.592
A27: 44277 | B27: =11566304-11559219 -> 7085 | C27: =7369051-7365996 -> 3055 | D27: =1426856-1425990 -> 866 | E27: =10958020-10953176 -> 4844 | F27: =10833460-10827562 -> 5898 | G27: =7973970-7971154 -> 2816 | H27: =7892335-7888499 -> 3836 | I27: =4933448-4931037 -> 2411 | J27: =10778923-10771823 -> 7100 | K27: =SUM(B27:H27) -> 28400 | L27: =K27*0.2 -> 5680 | M27: =65191.226-65072.797 -> 118.429 | N27: =4055.26-4054.074 -> 1.186 | O27: =9305.168-9304.608 -> 0.56 | P27: =83489.611-83347.511 -> 142.1 | Q27: =22745.995-22735.025 -> 10.97 | R27: =N27+O27+P27 -> 143.846 | S27: =(N27+O27+P27)*7.84 -> 1127.7526 | T27: =M27+Q27 -> 129.399 | U27: =T27*7.84 -> 1014.4882 | V27: =333437.1-333157.3 -> 279.8 | W27: =129679.18-129679.18 -> 0 | X27: 0001523.20 | Y27: 804952 | Z27: =IF((Y27-Y26<0), "0",Y27-Y26) -> 644 | AA27: =Z27*6.47 -> 4166.68 | AB27: 3282170.9 | AC27: =AB26 -> 3267771.9 | AD27: =IF((AB27-AC27<0), "0",AB27-AC27) -> 14399 | AE27: =AD27*0.333415 -> 4800.8426 | AF27: =83299.5-83275.5 -> 24 | AG27: =43323.2-43313.1 -> 10.1 | AH27: =26208.1-26199.6 -> 8.5 | AI27: =AJ26 -> 41316.3 | AJ27: 41337.9 | AK27: =IF((AJ27-AI27)<0, "0",AJ27-AI27) -> 21.6 | AL27: =AK27*(284.34513609) -> 6141.8549 | AM27: =AL27*0.333415 -> 2047.7866 | AN27: 108 | AO27: =L27+U27+AA27+AE27 -> 15662.011
A28: 44278 | B28: =11571597-11566304 -> 5293 | C28: =7372136-7369051 -> 3085 | D28: =1427697-1426856 -> 841 | E28: =10962811-10958020 -> 4791 | F28: =10839297-10833460 -> 5837 | G28: =7976858-7973970 -> 2888 | H28: =7896178-7892335 -> 3843 | I28: =4935850-4933448 -> 2402 | J28: =10785832-10778923 -> 6909 | K28: =SUM(B28:H28) -> 26578 | L28: =K28*0.2 -> 5315.6 | M28: =65328.079-65191.226 -> 136.853 | N28: =4056.666-4055.26 -> 1.406 | O28: =9305.926-9305.168 -> 0.758 | P28: =83553.433-83489.611 -> 63.822 | Q28: =22757.805-22745.995 -> 11.81 | R28: =N28+O28+P28 -> 65.986 | S28: =(N28+O28+P28)*7.84 -> 517.33024 | T28: =M28+Q28 -> 148.663 | U28: =T28*7.84 -> 1165.5179 | V28: =333710.5-333437.1 -> 273.4 | W28: =129771.49-129679.18 -> 92.31 | X28: 0001523.20 | Y28: 805657 | Z28: =IF((Y28-Y27<0), "0",Y28-Y27) -> 705 | AA28: =Z28*6.47 -> 4561.35 | AB28: 3297080.9 | AC28: =AB27 -> 3282170.9 | AD28: =IF((AB28-AC28<0), "0",AB28-AC28) -> 14910 | AE28: =AD28*0.333415 -> 4971.2177 | AF28: =83324.5-83299.5 -> 25 | AG28: =43334.1-43323.2 -> 10.9 | AH28: =26216.8-26208.1 -> 8.7 | AI28: =AJ27 -> 41337.9 | AJ28: 41359.5 | AK28: =IF((AJ28-AI28)<0, "0",AJ28-AI28) -> 21.6 | AL28: =AK28*(284.34513609) -> 6141.8549 | AM28: =AL28*0.333415 -> 2047.7866 | AN28: 118 | AO28: =L28+U28+AA28+AE28 -> 16013.686
A29: 44279 | B29: =11576542-11571597 -> 4945 | C29: =7375637-7372136 -> 3501 | D29: =1428558-1427697 -> 861 | E29: =10967677-10962811 -> 4866 | F29: =10845421-10839297 -> 6124 | G29: =7979704-7976858 -> 2846 | H29: =7900064-7896178 -> 3886 | I29: =4938323-4935850 -> 2473 | J29: =10792952-10785835 -> 7117 | K29: =SUM(B29:H29) -> 27029 | L29: =K29*0.2 -> 5405.8 | M29: =65496.55-65328.079 -> 168.471 | N29: =4058.384-4056.666 -> 1.718 | O29: =9306.839-9305.926 -> 0.913 | P29: =83619.476-83553.433 -> 66.043 | Q29: =22768.145-22757.805 -> 10.34 | R29: =N29+O29+P29 -> 68.674 | S29: =(N29+O29+P29)*7.84 -> 538.40416 | T29: =M29+Q29 -> 178.811 | U29: =T29*7.84 -> 1401.8782 | V29: =334003.8-333710.5 -> 293.3 | W29: =129861.53-129771.49 -> 90.04 | X29: 0001523.20 | Y29: 806360 | Z29: =IF((Y29-Y28<0), "0",Y29-Y28) -> 703 | AA29: =Z29*6.47 -> 4548.41 | AB29: 3314122.9 | AC29: =AB28 -> 3297080.9 | AD29: =IF((AB29-AC29<0), "0",AB29-AC29) -> 17042 | AE29: =AD29*0.333415 -> 5682.0584 | AF29: =83352.7-83324.5 -> 28.2 | AG29: =43346.9-43334.1 -> 12.8 | AH29: =26226.6-26216.8 -> 9.8 | AI29: =AJ28 -> 41359.5 | AJ29: 41383 | AK29: =IF((AJ29-AI29)<0, "0",AJ29-AI29) -> 23.5 | AL29: =AK29*(284.34513609) -> 6682.1107 | AM29: =AL29*0.333415 -> 2227.9159 | AN29: 112 | AO29: =L29+U29+AA29+AE29 -> 17038.147
A30: 44280 | B30: =11581423-11576542 -> 4881 | C30: =7379378-7375637 -> 3741 | D30: =1429507-1428558 -> 949 | E30: =10972999-10967677 -> 5322 | F30: =10851509-10845421 -> 6088 | G30: =7982696-7979704 -> 2992 | H30: =7903986-7900064 -> 3922 | I30: =4940861-4938323 -> 2538 | J30: =10800290-10792952 -> 7338 | K30: =SUM(B30:H30) -> 27895 | L30: =K30*0.2 -> 5579 | M30: =65658.051-65496.55 -> 161.501 | N30: =4059.791-4058.384 -> 1.407 | O30: =9307.851-9306.839 -> 1.012 | P30: =83690.775-83619.476 -> 71.299 | Q30: =22781.187-22768.145 -> 13.042 | R30: =N30+O30+P30 -> 73.718 | S30: =(N30+O30+P30)*7.84 -> 577.94912 | T30: =M30+Q30 -> 174.543 | U30: =T30*7.84 -> 1368.4171 | V30: =334254.2-334003.8 -> 250.4 | W30: =129959.4-129861.53 -> 97.87 | X30: 0001523.20 | Y30: 807059 | Z30: =IF((Y30-Y29<0), "0",Y30-Y29) -> 699 | AA30: =Z30*6.47 -> 4522.53 | AB30: 3331120.9 | AC30: =AB29 -> 3314122.9 | AD30: =IF((AB30-AC30<0), "0",AB30-AC30) -> 16998 | AE30: =AD30*0.333415 -> 5667.3882 | AF30: =83379.5-83352.7 -> 26.8 | AG30: =43361.2-43346.9 -> 14.3 | AH30: =26237.2-26226.6 -> 10.6 | AI30: =AJ29 -> 41383 | AJ30: 41406.5 | AK30: =IF((AJ30-AI30)<0, "0",AJ30-AI30) -> 23.5 | AL30: =AK30*(284.34513609) -> 6682.1107 | AM30: =AL30*0.333415 -> 2227.9159 | AN30: 72 | AO30: =L30+U30+AA30+AE30 -> 17137.335
A31: 44281 | B31: =11586512-11581423 -> 5089 | C31: =7382847-7379378 -> 3469 | D31: =1430471-1429507 -> 964 | E31: =10978050-10972999 -> 5051 | F31: =10857630-10851509 -> 6121 | G31: =7985607-7982696 -> 2911 | H31: =7907843-7903986 -> 3857 | I31: =4943347-4940861 -> 2486 | J31: =10807641-10800290 -> 7351 | K31: =SUM(B31:H31) -> 27462 | L31: =K31*0.2 -> 5492.4 | M31: =65803.733-65658.051 -> 145.682 | N31: =4060.866-4059.791 -> 1.075 | O31: =9308.059-9307.851 -> 0.208 | P31: =83771.196-83690.775 -> 80.421 | Q31: =22791.022-22781.187 -> 9.835 | R31: =N31+O31+P31 -> 81.704 | S31: =(N31+O31+P31)*7.84 -> 640.55936 | T31: =M31+Q31 -> 155.517 | U31: =T31*7.84 -> 1219.2533 | V31: =334522.3-334254.2 -> 268.1 | W31: =129959.4-129959.4 -> 0 | X31: 0001523.20 | Y31: 807682 | Z31: =IF((Y31-Y30<0), "0",Y31-Y30) -> 623 | AA31: =Z31*6.47 -> 4030.81 | AB31: 3348665 | AC31: =AB30 -> 3331120.9 | AD31: =IF((AB31-AC31<0), "0",AB31-AC31) -> 17544.1 | AE31: =AD31*0.333415 -> 5849.4661 | AF31: =83408.3-83379.5 -> 28.8 | AG31: =43374.2-43361.2 -> 13 | AH31: =26248.2-26237.2 -> 11 | AI31: =AJ30 -> 41406.5 | AJ31: 41430.3 | AK31: =IF((AJ31-AI31)<0, "0",AJ31-AI31) -> 23.8 | AL31: =AK31*(284.34513609) -> 6767.4142 | AM31: =AL31*0.333415 -> 2256.3574 | AN31: 98 | AO31: =L31+U31+AA31+AE31 -> 16591.929
A32: 44282 | B32: =11591027-11586512 -> 4515 | C32: =7385804-7382847 -> 2957 | D32: =1431415-1430471 -> 944 | E32: =10983270-10978050 -> 5220 | F32: =10863455-10857630 -> 5825 | G32: =7988416-7985607 -> 2809 | H32: =7911654-7907843 -> 3811 | I32: =4945851-4943347 -> 2504 | J32: =10814851-10807641 -> 7210 | K32: =SUM(B32:H32) -> 26081 | L32: =K32*0.2 -> 5216.2 | M32: =65943.31-65803.733 -> 139.577 | N32: =4062.435-4060.866 -> 1.569 | O32: =9308.664-9308.059 -> 0.605 | P32: =83845.359-83771.196 -> 74.163 | Q32: =22802.87-22791.022 -> 11.848 | R32: =N32+O32+P32 -> 76.337 | S32: =(N32+O32+P32)*7.84 -> 598.48208 | T32: =M32+Q32 -> 151.425 | U32: =T32*7.84 -> 1187.172 | V32: =334751.7-334522.3 -> 229.4 | W32: =129959.4-129959.4 -> 0 | X32: 0001523.20 | Y32: 808230 | Z32: =IF((Y32-Y31<0), "0",Y32-Y31) -> 548 | AA32: =Z32*6.47 -> 3545.56 | AB32: 3365036 | AC32: =AB31 -> 3348665 | AD32: =IF((AB32-AC32<0), "0",AB32-AC32) -> 16371 | AE32: =AD32*0.333415 -> 5458.337 | AF32: =83435.1-83408.3 -> 26.8 | AG32: =43386-43374.2 -> 11.8 | AH32: =26259.5-26248.2 -> 11.3 | AI32: =AJ31 -> 41430.3 | AJ32: 41453.2 | AK32: =IF((AJ32-AI32)<0, "0",AJ32-AI32) -> 22.9 | AL32: =AK32*(284.34513609) -> 6511.5036 | AM32: =AL32*0.333415 -> 2171.033 | AN32: 98 | AO32: =L32+U32+AA32+AE32 -> 15407.269
A33: 44283 | B33: =11596093-11591027 -> 5066 | C33: =7388138-7385804 -> 2334 | D33: =1432349-1431415 -> 934 | E33: =10988608-10983270 -> 5338 | F33: =10869256-10863455 -> 5801 | G33: =7991259-7988416 -> 2843 | H33: =7915527-7911654 -> 3873 | I33: =4948385-4945851 -> 2534 | J33: =10822033-10814851 -> 7182 | K33: =SUM(B33:H33) -> 26189 | L33: =K33*0.2 -> 5237.8 | M33: =66076.3706-65943.31 -> 133.0606 | N33: =4064.214-4062.435 -> 1.779 | O33: =9309.503-9308.664 -> 0.839 | P33: =83913.206-83845.359 -> 67.847 | Q33: =22813.716-22802.87 -> 10.846 | R33: =N33+O33+P33 -> 70.465 | S33: =(N33+O33+P33)*7.84 -> 552.4456 | T33: =M33+Q33 -> 143.9066 | U33: =T33*7.84 -> 1128.2277 | V33: =334974.3-334751.7 -> 222.6 | W33: =129959.4-129959.4 -> 0 | X33: 0001523.20 | Y33: 808737 | Z33: =IF((Y33-Y32<0), "0",Y33-Y32) -> 507 | AA33: =Z33*6.47 -> 3280.29 | AB33: 3381454.1 | AC33: =AB32 -> 3365036 | AD33: =IF((AB33-AC33<0), "0",AB33-AC33) -> 16418.1 | AE33: =AD33*0.333415 -> 5474.0408 | AF33: =83461.2-83435.1 -> 26.1 | AG33: =43396.7-43386 -> 10.7 | AH33: =26270.4-26259.5 -> 10.9 | AI33: =AJ32 -> 41453.2 | AJ33: 41478.4 | AK33: =IF((AJ33-AI33)<0, "0",AJ33-AI33) -> 25.2 | AL33: =AK33*(284.34513609) -> 7165.4974 | AM33: =AL33*0.333415 -> 2389.0843 | AN33: 114 | AO33: =L33+U33+AA33+AE33 -> 15120.359
A34: 44284 | B34: =11602142-11596093 -> 6049 | C34: =7391163-7388138 -> 3025 | D34: =1433289-1432349 -> 940 | E34: =10994091-10988608 -> 5483 | F34: =10874995-10869256 -> 5739 | G34: =7994117-7991259 -> 2858 | H34: =7919560-7915527 -> 4033 | I34: =4950834-4948385 -> 2449 | J34: =10829304-10822033 -> 7271 | K34: =SUM(B34:H34) -> 28127 | L34: =K34*0.2 -> 5625.4 | M34: =66203.084-66076.37 -> 126.714 | N34: =4065.89-4064.214 -> 1.676 | O34: =9310.104-9309.503 -> 0.601 | P34: =83973.861-83913.206 -> 60.655 | Q34: =22825.435-22813.716 -> 11.719 | R34: =N34+O34+P34 -> 62.932 | S34: =(N34+O34+P34)*7.84 -> 493.38688 | T34: =M34+Q34 -> 138.433 | U34: =T34*7.84 -> 1085.3147 | V34: =335198.7-334974.3 -> 224.4 | W34: =129959.4-129959.4 -> 0 | X34: 0001523.20 | Y34: 809262 | Z34: =IF((Y34-Y33<0), "0",Y34-Y33) -> 525 | AA34: =Z34*6.47 -> 3396.75 | AB34: 3396575.1 | AC34: =AB33 -> 3381454.1 | AD34: =IF((AB34-AC34<0), "0",AB34-AC34) -> 15121 | AE34: =AD34*0.333415 -> 5041.5682 | AF34: =83485.3-83461.2 -> 24.1 | AG34: =43407-43396.7 -> 10.3 | AH34: =26279.8-26270.4 -> 9.4 | AI34: =AJ33 -> 41478.4 | AJ34: 41502.9 | AK34: =IF((AJ34-AI34)<0, "0",AJ34-AI34) -> 24.5 | AL34: =AK34*(284.34513609) -> 6966.4558 | AM34: =AL34*0.333415 -> 2322.7209 | AN34: 121 | AO34: =L34+U34+AA34+AE34 -> 15149.033
A35: 44285 | B35: =11607920-11602142 -> 5778 | C35: =7393834-7391163 -> 2671 | D35: =1434202-1433289 -> 913 | E35: =10999459-10994091 -> 5368 | F35: =10880860-10874995 -> 5865 | G35: =7997120-7994117 -> 3003 | H35: =7924122-7919560 -> 4562 | I35: =4953243-4950834 -> 2409 | J35: =10836619-10829304 -> 7315 | K35: =SUM(B35:H35) -> 28160 | L35: =K35*0.2 -> 5632 | M35: =66340.567-66203.084 -> 137.483 | N35: =4067.121-4065.89 -> 1.231 | O35: =9311.143-9310.104 -> 1.039 | P35: =84039.604-83973.861 -> 65.743 | Q35: =22836.605-22825.435 -> 11.17 | R35: =N35+O35+P35 -> 68.013 | S35: =(N35+O35+P35)*7.84 -> 533.22192 | T35: =M35+Q35 -> 148.653 | U35: =T35*7.84 -> 1165.4395 | V35: =335432.2-335198.7 -> 233.5 | W35: =129959.4-129959.4 -> 0 | X35: 0001523.21 | Y35: 809791 | Z35: =IF((Y35-Y34<0), "0",Y35-Y34) -> 529 | AA35: =Z35*6.47 -> 3422.63 | AB35: 3412686.1 | AC35: =AB34 -> 3396575.1 | AD35: =IF((AB35-AC35<0), "0",AB35-AC35) -> 16111 | AE35: =AD35*0.333415 -> 5371.6491 | AF35: =83511.2-83485.3 -> 25.9 | AG35: =43418.6-43407 -> 11.6 | AH35: =26289.2-26279.8 -> 9.4 | AI35: =AJ34 -> 41502.9 | AJ35: 41527.7 | AK35: =IF((AJ35-AI35)<0, "0",AJ35-AI35) -> 24.8 | AL35: =AK35*(284.34513609) -> 7051.7594 | AM35: =AL35*0.333415 -> 2351.1624 | AN35: 124 | AO35: =L35+U35+AA35+AE35 -> 15591.719
