Workbook

Sheet TOTAL
A1: Site Name | B1: Day | C1: Month | D1: Year | E1: Total Electricity Kwh | F1: Electricity Tariff ($/Kwh) | G1: LPG (Kg) | H1: LPG $/Kg | I1: Water Utility Supply (m3) m3 | J1: Water Utility Supply (m3) $/m3 | K1: Irrigation Water (m3) m3 | L1: Irrigation water $/m3 | M1: Room Nights | N1: Total Guests
A2: Dubai at Jumeirah Beach | B2: 1 | C2: 10 | D2: 2021 | E2: =Submetering!M2+Submetering!N2+Submetering!O2+Submetering!P2+Submetering!Q2+Submetering!R2+Submetering!S2+Submetering!T2+Submetering!U2+Submetering!V2 -> 61143.6 | F2: 0.44448 | G2: =Submetering!Z2+Submetering!AA2+Submetering!AB2 -> 330.75 | H2: =1.69/0.52 -> 3.25 | I2: =Submetering!G2 -> 765 | J2: 13.83 | K2: =Submetering!I2 -> 331 | L2: 1.2 | M2: =Submetering!E2 -> 173.01 | N2: =Submetering!F2 -> 276
A3: Dubai at Jumeirah Beach | B3: =B2+1 -> 2 | C3: 10 | D3: 2021 | E3: =Submetering!M3+Submetering!N3+Submetering!O3+Submetering!P3+Submetering!Q3+Submetering!R3+Submetering!S3+Submetering!T3+Submetering!U3+Submetering!V3 -> 59438.4 | F3: 0.44448 | G3: =Submetering!Z3+Submetering!AA3+Submetering!AB3 -> 334.53 | H3: =1.69/0.52 -> 3.25 | I3: =Submetering!G3 -> 697 | J3: 13.83 | K3: =Submetering!I3 -> 489 | L3: 1.2 | M3: =Submetering!E3 -> 144.57 | N3: =Submetering!F3 -> 241
A4: Dubai at Jumeirah Beach | B4: =B3+1 -> 3 | C4: 10 | D4: 2021 | E4: =Submetering!M4+Submetering!N4+Submetering!O4+Submetering!P4+Submetering!Q4+Submetering!R4+Submetering!S4+Submetering!T4+Submetering!U4+Submetering!V4 -> 51204.72 | F4: 0.44448 | G4: =Submetering!Z4+Submetering!AA4+Submetering!AB4 -> 332.64 | H4: =1.69/0.52 -> 3.25 | I4: =Submetering!G4 -> 711 | J4: 13.83 | K4: =Submetering!I4 -> 423 | L4: 1.2 | M4: =Submetering!E4 -> 118.5 | N4: =Submetering!F4 -> 195
A5: Dubai at Jumeirah Beach | B5: =B4+1 -> 4 | C5: 10 | D5: 2021 | E5: =Submetering!M5+Submetering!N5+Submetering!O5+Submetering!P5+Submetering!Q5+Submetering!R5+Submetering!S5+Submetering!T5+Submetering!U5+Submetering!V5 -> 52666.32 | F5: 0.44448 | G5: =Submetering!Z5+Submetering!AA5+Submetering!AB5 -> 340.2 | H5: =1.69/0.52 -> 3.25 | I5: =Submetering!G5 -> 574 | J5: 13.83 | K5: =Submetering!I5 -> 367 | L5: 1.2 | M5: =Submetering!E5 -> 116.13 | N5: =Submetering!F5 -> 177
A6: Dubai at Jumeirah Beach | B6: =B5+1 -> 5 | C6: 10 | D6: 2021 | E6: =Submetering!M6+Submetering!N6+Submetering!O6+Submetering!P6+Submetering!Q6+Submetering!R6+Submetering!S6+Submetering!T6+Submetering!U6+Submetering!V6 -> 54030.48 | F6: 0.44448 | G6: =Submetering!Z6+Submetering!AA6+Submetering!AB6 -> 336.42 | H6: =1.69/0.52 -> 3.25 | I6: =Submetering!G6 -> 810 | J6: 13.83 | K6: =Submetering!I6 -> 478 | L6: 1.2 | M6: =Submetering!E6 -> 132.72 | N6: =Submetering!F6 -> 198
A7: Dubai at Jumeirah Beach | B7: =B6+1 -> 6 | C7: 10 | D7: 2021 | E7: =Submetering!M7+Submetering!N7+Submetering!O7+Submetering!P7+Submetering!Q7+Submetering!R7+Submetering!S7+Submetering!T7+Submetering!U7+Submetering!V7 -> 53104.8 | F7: 0.44448 | G7: =Submetering!Z7+Submetering!AA7+Submetering!AB7 -> 345.87 | H7: =1.69/0.52 -> 3.25 | I7: =Submetering!G7 -> 792 | J7: 13.83 | K7: =Submetering!I7 -> 418 | L7: 1.2 | M7: =Submetering!E7 -> 151.68 | N7: =Submetering!F7 -> 203
A8: Dubai at Jumeirah Beach | B8: =B7+1 -> 7 | C8: 10 | D8: 2021 | E8: =Submetering!M8+Submetering!N8+Submetering!O8+Submetering!P8+Submetering!Q8+Submetering!R8+Submetering!S8+Submetering!T8+Submetering!U8+Submetering!V8 -> 0 | F8: 0.44448 | G8: =Submetering!Z8+Submetering!AA8+Submetering!AB8 -> 0 | H8: =1.69/0.52 -> 3.25 | I8: =Submetering!G8 -> 0 | J8: 13.83 | K8: =Submetering!I8 -> 0 | L8: 1.2 | M8: =Submetering!E8 -> 0 | N8: =Submetering!F8 -> 249
A9: Dubai at Jumeirah Beach | B9: =B8+1 -> 8 | C9: 10 | D9: 2021 | E9: =Submetering!M9+Submetering!N9+Submetering!O9+Submetering!P9+Submetering!Q9+Submetering!R9+Submetering!S9+Submetering!T9+Submetering!U9+Submetering!V9 -> 0 | F9: 0.44448 | G9: =Submetering!Z9+Submetering!AA9+Submetering!AB9 -> 0 | H9: =1.69/0.52 -> 3.25 | I9: =Submetering!G9 -> 0 | J9: 13.83 | K9: =Submetering!I9 -> 0 | L9: 1.2 | M9: =Submetering!E9 -> 0 | N9: =Submetering!F9 -> 0
A10: Dubai at Jumeirah Beach | B10: =B9+1 -> 9 | C10: 10 | D10: 2021 | E10: =Submetering!M10+Submetering!N10+Submetering!O10+Submetering!P10+Submetering!Q10+Submetering!R10+Submetering!S10+Submetering!T10+Submetering!U10+Submetering!V10 -> 0 | F10: 0.44448 | G10: =Submetering!Z10+Submetering!AA10+Submetering!AB10 -> 0 | H10: =1.69/0.52 -> 3.25 | I10: =Submetering!G10 -> 0 | J10: 13.83 | K10: =Submetering!I10 -> 0 | L10: 1.2 | M10: =Submetering!E10 -> 0 | N10: =Submetering!F10 -> 0
A11: Dubai at Jumeirah Beach | B11: =B10+1 -> 10 | C11: 10 | D11: 2021 | E11: =Submetering!M11+Submetering!N11+Submetering!O11+Submetering!P11+Submetering!Q11+Submetering!R11+Submetering!S11+Submetering!T11+Submetering!U11+Submetering!V11 -> 0 | F11: 0.44448 | G11: =Submetering!Z11+Submetering!AA11+Submetering!AB11 -> 0 | H11: =1.69/0.52 -> 3.25 | I11: =Submetering!G11 -> 0 | J11: 13.83 | K11: =Submetering!I11 -> 0 | L11: 1.2 | M11: =Submetering!E11 -> 0 | N11: =Submetering!F11 -> 0
A12: Dubai at Jumeirah Beach | B12: =B11+1 -> 11 | C12: 10 | D12: 2021 | E12: =Submetering!M12+Submetering!N12+Submetering!O12+Submetering!P12+Submetering!Q12+Submetering!R12+Submetering!S12+Submetering!T12+Submetering!U12+Submetering!V12 -> 0 | F12: 0.44448 | G12: =Submetering!Z12+Submetering!AA12+Submetering!AB12 -> 0 | H12: =1.69/0.52 -> 3.25 | I12: =Submetering!G12 -> 0 | J12: 13.83 | K12: =Submetering!I12 -> 0 | L12: 1.2 | M12: =Submetering!E12 -> 0 | N12: =Submetering!F12 -> 0
A13: Dubai at Jumeirah Beach | B13: =B12+1 -> 12 | C13: 10 | D13: 2021 | E13: =Submetering!M13+Submetering!N13+Submetering!O13+Submetering!P13+Submetering!Q13+Submetering!R13+Submetering!S13+Submetering!T13+Submetering!U13+Submetering!V13 -> 0 | F13: 0.44448 | G13: =Submetering!Z13+Submetering!AA13+Submetering!AB13 -> 0 | H13: =1.69/0.52 -> 3.25 | I13: =Submetering!G13 -> 0 | J13: 13.83 | K13: =Submetering!I13 -> 0 | L13: 1.2 | M13: =Submetering!E13 -> 0 | N13: =Submetering!F13 -> 0
A14: Dubai at Jumeirah Beach | B14: =B13+1 -> 13 | C14: 10 | D14: 2021 | E14: =Submetering!M14+Submetering!N14+Submetering!O14+Submetering!P14+Submetering!Q14+Submetering!R14+Submetering!S14+Submetering!T14+Submetering!U14+Submetering!V14 -> 0 | F14: 0.44448 | G14: =Submetering!Z14+Submetering!AA14+Submetering!AB14 -> 0 | H14: =1.69/0.52 -> 3.25 | I14: =Submetering!G14 -> 0 | J14: 13.83 | K14: =Submetering!I14 -> 0 | L14: 1.2 | M14: =Submetering!E14 -> 0 | N14: =Submetering!F14 -> 0
... A31: Dubai at Jumeirah Beach | B31: =B30+1 -> 30 | C31: 10 | D31: 2021 | E31: =Submetering!M31+Submetering!N31+Submetering!O31+Submetering!P31+Submetering!Q31+Submetering!R31+Submetering!S31+Submetering!T31+Submetering!U31+Submetering!V31 -> 0 | F31: 0.44448 | G31: =Submetering!Z31+Submetering!AA31+Submetering!AB31 -> 0 | H31: =1.69/0.52 -> 3.25 | I31: =Submetering!G31 -> 0 | J31: 13.83 | K31: =Submetering!I31 -> 0 | L31: 1.2 | M31: =Submetering!E31 -> 0 | N31: =Submetering!F31 -> 0
A32: Dubai at Jumeirah Beach | B32: 31 | C32: 10 | D32: 2021 | E32: =Submetering!M32+Submetering!N32+Submetering!O32+Submetering!P32+Submetering!Q32+Submetering!R32+Submetering!S32+Submetering!T32+Submetering!U32+Submetering!V32 -> 0 | F32: 0.44448 | G32: =Submetering!Z32+Submetering!AA32+Submetering!AB32 -> 0 | H32: =1.69/0.52 -> 3.25 | I32: =Submetering!G32 -> 0 | J32: 13.83 | K32: =Submetering!I32 -> 0 | L32: 1.2 | M32: =Submetering!E32 -> 0 | N32: =Submetering!F32 -> 0

Sheet Submetering
A1: Site Name | B1: Day | C1: Month | D1: Year | E1: Room Nights | F1: Total Guests | G1: Potable Water -IG (m3) | H1: Resort Water (m3) | I1: Tse Water (m3) | J1: Irrigation (m3) | K1: Cooling Tower Water (m3) | L1: Cooling Tower Blowdown (m3) | M1: EMDB-1 All Pumps (KWh) | N1: EMDB-2 Elevators (KWh) | O1: MDB-1 Chiller #1 (KWh) | P1: MDB-2 Chiller #2 (KWh) | Q1: MDB-3 Chiller #3(KWh) | R1: MDB-4 North Riser (KWh) | S1: MDB-5 North Riser (KWh) | T1: MDB-6 Main Kitchen (KWh) | U1: MDB-7 South Riser (KWh) | V1: MDB-8 F&B (KWh) | W1: Chiller 1 (Kwh cooling) | X1: Chiller 2 (Kwh cooling) | Y1: Chiller 3 (Kwh cooling) | Z1: Steam Boiler LPG (Kg) | AA1: Solar Hot Water Boiler LPG (Kg) | AB1: Low Temp Hot Water Boiler LPG (Kg) | AC1: Steam Boiler Steam (Kg) | AD1: Ird Kitchen (Kg) | AE1: Suq Kitchen (Kg) | AF1: Bakery Kitchen (Kg) | AG1: Shai Saloon Kitchen (kg) | AH1: Banquet Kitchen (Kg) | AI1: Sea Fu Kitchen (Kg) | AJ1: Jean George Cold Water (m³) | AK1: Jean George Hot Water (m³) | AL1: Coya Cold Water (m³) | AM1: Coya Hot Water (m³) | AN1: Nusrat Cold Water (m³) | AO1: Nusrat Hot Water (m³) | AP1: Provocateur Cold Water (m³) | AQ1: Provocateur Hot Water (m³) | AR1: Scalini Cold Water (m³) | AS1: Scalini Hot Water (m³) | AT1: F&B V Irrigation (m³) | AU1: MDB Coya (KWh) | AV1: MDB Jean Georges (KWh) | AW1: MDB Nusrat(KWh) | AX1: SMDB Provocateur (KWh) | AY1: SMDB Scalini (KWh) | AZ1: Common ESMDB (KWh) | BA1: Chilled Water Coya (Kwh) | BB1: Chilled Water Coya Cold Room (Kwh) | BC1: Chilled Water Jean Georges (Kwh) | BD1: Chilled Water Nusrat (Kwh) | BE1: Chilled Water Provocateur A (Kwh) | BF1: Chilled Water Provocateur B (Kwh) | BG1: Coya LPG (Kg) | BH1: Nusrat LPG (Kg) | BI1: Jean Georges LPG (Kg) | BJ1: Provocateur LPG (Kg) | BK1: Scalini LPG (Kg)
A2: Dubai at Jumeirah Beach | B2: 1 | C2: 10 | D2: 2021 | E2: =237*0.73 -> 173.01 | F2: =259+17 -> 276 | G2: ='DJB Daily Readings'!C10-'DJB Daily Readings'!C9 -> 765 | H2: ='DJB Daily Readings'!F10-'DJB Daily Readings'!F9 -> 417 | I2: ='DJB Daily Readings'!K10-'DJB Daily Readings'!K9 -> 331 | J2: ='DJB Daily Readings'!K10-'DJB Daily Readings'!K9 -> 331 | K2: ='DJB Daily Readings'!O10-'DJB Daily Readings'!O9 -> 271.21 | L2: ='DJB Daily Readings'!R10-'DJB Daily Readings'!R9 -> 42 | M2: ='DJB Daily Readings'!U10-'DJB Daily Readings'!U9 -> 4141.2 | N2: ='DJB Daily Readings'!X10-'DJB Daily Readings'!X9 -> 4725.84 | O2: ='DJB Daily Readings'!AA10-'DJB Daily Readings'!AA9 -> 14274.96 | P2: ='DJB Daily Readings'!AD10-'DJB Daily Readings'!AD9 -> 12374.88 | Q2: ='DJB Daily Readings'!AG10-'DJB Daily Readings'!AG9 -> 779.52 | R2: ='DJB Daily Readings'!AJ10-'DJB Daily Readings'!AJ9 -> 6333.6 | S2: ='DJB Daily Readings'!AM10-'DJB Daily Readings'!AM9 -> 4969.44 | T2: ='DJB Daily Readings'!AP10-'DJB Daily Readings'!AP9 -> 4287.36 | U2: ='DJB Daily Readings'!AS10-'DJB Daily Readings'!AS9 -> 3556.56 | V2: ='DJB Daily Readings'!AV10-'DJB Daily Readings'!AV9 -> 5700.24 | W2: ='DJB Daily Readings'!AZ10-'DJB Daily Readings'!AZ9 -> 68600 | X2: ='DJB Daily Readings'!BC10-'DJB Daily Readings'!BC9 -> 65400 | Y2: ='DJB Daily Readings'!BF10-'DJB Daily Readings'!BF9 -> 0 | Z2: =('DJB Daily Readings'!CK10-'DJB Daily Readings'!CK9)*1.89 -> 177.66 | AA2: =('DJB Daily Readings'!CN10-'DJB Daily Readings'!CN9)*1.89 -> 153.09 | AB2: =('DJB Daily Readings'!CQ10-'DJB Daily Readings'!CQ9)*1.89 -> 0 | AC2: ='DJB Daily Readings'!CT10-'DJB Daily Readings'!CT9 -> 195 | AD2: =('DJB Daily Readings'!BY10-'DJB Daily Readings'!BY9)*1.89 -> 34.02 | AE2: =('DJB Daily Readings'!CA10-'DJB Daily Readings'!CA9)*1.89 -> 37.8 | AF2: =('DJB Daily Readings'!CC10-'DJB Daily Readings'!CC9)*1.89 -> 13.23 | AG2: =('DJB Daily Readings'!CE10-'DJB Daily Readings'!CE9)*1.89 -> 18.9 | AH2: =('DJB Daily Readings'!CG10-'DJB Daily Readings'!CG9)*1.89 -> 32.13 | AI2: =('DJB Daily Readings'!CI10-'DJB Daily Readings'!CI9)*1.89 -> 56.7 | AJ2: ='DJB Daily Readings'!CY10-'DJB Daily Readings'!CY9 -> 9 | AK2: ='DJB Daily Readings'!CW10-'DJB Daily Readings'!CW9 -> 9 | AL2: ='DJB Daily Readings'!DC10-'DJB Daily Readings'!DC9 -> 19 | AM2: ='DJB Daily Readings'!DA10-'DJB Daily Readings'!DA9 -> 18 | AN2: ='DJB Daily Readings'!DG10-'DJB Daily Readings'!DG9 -> 11 | AO2: ='DJB Daily Readings'!DE10-'DJB Daily Readings'!DE9 -> 7 | AP2: ='DJB Daily Readings'!DK10-'DJB Daily Readings'!DK9 -> 15 | AQ2: ='DJB Daily Readings'!DI10-'DJB Daily Readings'!DI9 -> 8 | AR2: ='DJB Daily Readings'!DO10-'DJB Daily Readings'!DO9 -> 6 | AS2: ='DJB Daily Readings'!DM10-'DJB Daily Readings'!DM9 -> 10 | AT2: ='DJB Daily Readings'!DQ10-'DJB Daily Readings'!DQ9 -> 0 | AU2: ='DJB Daily Readings'!DT10-'DJB Daily Readings'!DT9 -> 11 | AW2: ='DJB Daily Readings'!DX10-'DJB Daily Readings'!DX9 -> 7.7 | AX2: ='DJB Daily Readings'!DZ10-'DJB Daily Readings'!DZ9 -> 5.9 | AY2: ='DJB Daily Readings'!EB10-'DJB Daily Readings'!EB9 -> 886 | AZ2: ='DJB Daily Readings'!ED10-'DJB Daily Readings'!ED9 -> 155.9 | BA2: ='DJB Daily Readings'!EG10-'DJB Daily Readings'!EG9 -> 11100 | BB2: ='DJB Daily Readings'!EI10-'DJB Daily Readings'!EI9 -> 530 | BC2: ='DJB Daily Readings'!EQ10-'DJB Daily Readings'!EQ9 -> 11800 | BD2: ='DJB Daily Readings'!EK10-'DJB Daily Readings'!EK9 -> 4500 | BE2: ='DJB Daily Readings'!EM10-'DJB Daily Readings'!EM9 -> 2200 | BF2: ='DJB Daily Readings'!EO10-'DJB Daily Readings'!EO9 -> 1220 | BG2: =('DJB Daily Readings'!ET10-'DJB Daily Readings'!ET9)*1.89 -> 30.24 | BH2: =('DJB Daily Readings'!EV10-'DJB Daily Readings'!EV9)*1.89 -> 24.57 | BI2: =('DJB Daily Readings'!EZ10-'DJB Daily Readings'!EZ9)*1.89 -> 34.02 | BJ2: =('DJB Daily Readings'!EX10-'DJB Daily Readings'!EX9)*1.89 -> 30.24 | BK2: =('DJB Daily Readings'!FB10-'DJB Daily Readings'!FB9)*1.89 -> 66.15
A3: Dubai at Jumeirah Beach | B3: =B2+1 -> 2 | C3: 10 | D3: 2021 | E3: =237*0.61 -> 144.57 | F3: =221+20 -> 241 | G3: ='DJB Daily Readings'!C11-'DJB Daily Readings'!C10 -> 697 | H3: ='DJB Daily Readings'!F11-'DJB Daily Readings'!F10 -> 324 | I3: ='DJB Daily Readings'!K11-'DJB Daily Readings'!K10 -> 489 | J3: ='DJB Daily Readings'!K11-'DJB Daily Readings'!K10 -> 489 | K3: ='DJB Daily Readings'!O11-'DJB Daily Readings'!O10 -> 264.55 | L3: ='DJB Daily Readings'!R11-'DJB Daily Readings'!R10 -> 43 | M3: ='DJB Daily Readings'!U11-'DJB Daily Readings'!U10 -> 4189.92 | N3: ='DJB Daily Readings'!X11-'DJB Daily Readings'!X10 -> 4823.28 | O3: ='DJB Daily Readings'!AA11-'DJB Daily Readings'!AA10 -> 11059.44 | P3: ='DJB Daily Readings'!AD11-'DJB Daily Readings'!AD10 -> 12910.8 | Q3: ='DJB Daily Readings'!AG11-'DJB Daily Readings'!AG10 -> 1607.76 | R3: ='DJB Daily Readings'!AJ11-'DJB Daily Readings'!AJ10 -> 6236.16 | S3: ='DJB Daily Readings'!AM11-'DJB Daily Readings'!AM10 -> 4774.56 | T3: ='DJB Daily Readings'!AP11-'DJB Daily Readings'!AP10 -> 4092.48 | U3: ='DJB Daily Readings'!AS11-'DJB Daily Readings'!AS10 -> 3069.36 | V3: ='DJB Daily Readings'!AV11-'DJB Daily Readings'!AV10 -> 6674.64 | W3: ='DJB Daily Readings'!AZ11-'DJB Daily Readings'!AZ10 -> 57600 | X3: ='DJB Daily Readings'!BC11-'DJB Daily Readings'!BC10 -> 69400 | Y3: ='DJB Daily Readings'!BF11-'DJB Daily Readings'!BF10 -> 0 | Z3: =('DJB Daily Readings'!CK11-'DJB Daily Readings'!CK10)*1.89 -> 181.44 | AA3: =('DJB Daily Readings'!CN11-'DJB Daily Readings'!CN10)*1.89 -> 153.09 | AB3: =('DJB Daily Readings'!CQ11-'DJB Daily Readings'!CQ10)*1.89 -> 0 | AC3: ='DJB Daily Readings'!CT11-'DJB Daily Readings'!CT10 -> 190 | AD3: =('DJB Daily Readings'!BY11-'DJB Daily Readings'!BY10)*1.89 -> 34.02 | AE3: =('DJB Daily Readings'!CA11-'DJB Daily Readings'!CA10)*1.89 -> 32.13 | AF3: =('DJB Daily Readings'!CC11-'DJB Daily Readings'!CC10)*1.89 -> 13.23 | AG3: =('DJB Daily Readings'!CE11-'DJB Daily Readings'!CE10)*1.89 -> 18.9 | AH3: =('DJB Daily Readings'!CG11-'DJB Daily Readings'!CG10)*1.89 -> 26.46 | AI3: =('DJB Daily Readings'!CI11-'DJB Daily Readings'!CI10)*1.89 -> 54.81 | AJ3: ='DJB Daily Readings'!CY11-'DJB Daily Readings'!CY10 -> 6 | AK3: ='DJB Daily Readings'!CW11-'DJB Daily Readings'!CW10 -> 7 | AL3: ='DJB Daily Readings'!DC11-'DJB Daily Readings'!DC10 -> 14 | AM3: ='DJB Daily Readings'!DA11-'DJB Daily Readings'!DA10 -> 12 | AN3: ='DJB Daily Readings'!DG11-'DJB Daily Readings'!DG10 -> 7 | AO3: ='DJB Daily Readings'!DE11-'DJB Daily Readings'!DE10 -> 7 | AP3: ='DJB Daily Readings'!DK11-'DJB Daily Readings'!DK10 -> 16 | AQ3: ='DJB Daily Readings'!DI11-'DJB Daily Readings'!DI10 -> 8 | AR3: ='DJB Daily Readings'!DO11-'DJB Daily Readings'!DO10 -> 7 | AS3: ='DJB Daily Readings'!DM11-'DJB Daily Readings'!DM10 -> 8 | AT3: ='DJB Daily Readings'!DQ11-'DJB Daily Readings'!DQ10 -> 0 | AU3: ='DJB Daily Readings'!DT11-'DJB Daily Readings'!DT10 -> 10.1 | AW3: ='DJB Daily Readings'!DX11-'DJB Daily Readings'!DX10 -> 7.7 | AX3: ='DJB Daily Readings'!DZ11-'DJB Daily Readings'!DZ10 -> 12.2 | AY3: ='DJB Daily Readings'!EB11-'DJB Daily Readings'!EB10 -> 768 | AZ3: ='DJB Daily Readings'!ED11-'DJB Daily Readings'!ED10 -> 153 | BA3: ='DJB Daily Readings'!EG11-'DJB Daily Readings'!EG10 -> 8600 | BB3: ='DJB Daily Readings'!EI11-'DJB Daily Readings'!EI10 -> 360 | BC3: ='DJB Daily Readings'!EQ11-'DJB Daily Readings'!EQ10 -> 8000 | BD3: ='DJB Daily Readings'!EK11-'DJB Daily Readings'!EK10 -> 3500 | BE3: ='DJB Daily Readings'!EM11-'DJB Daily Readings'!EM10 -> 1000 | BF3: ='DJB Daily Readings'!EO11-'DJB Daily Readings'!EO10 -> 900 | BG3: =('DJB Daily Readings'!ET11-'DJB Daily Readings'!ET10)*1.89 -> 26.46 | BH3: =('DJB Daily Readings'!EV11-'DJB Daily Readings'!EV10)*1.89 -> 20.79 | BI3: =('DJB Daily Readings'!EZ11-'DJB Daily Readings'!EZ10)*1.89 -> 34.02 | BJ3: =('DJB Daily Readings'!EX11-'DJB Daily Readings'!EX10)*1.89 -> 32.13 | BK3: =('DJB Daily Readings'!FB11-'DJB Daily Readings'!FB10)*1.89 -> 64.26
A4: Dubai at Jumeirah Beach | B4: =B3+1 -> 3 | C4: 10 | D4: 2021 | E4: =237*0.5 -> 118.5 | F4: =179+16 -> 195 | G4: ='DJB Daily Readings'!C12-'DJB Daily Readings'!C11 -> 711 | H4: ='DJB Daily Readings'!F12-'DJB Daily Readings'!F11 -> 314 | I4: ='DJB Daily Readings'!K12-'DJB Daily Readings'!K11 -> 423 | J4: ='DJB Daily Readings'!K12-'DJB Daily Readings'!K11 -> 423 | K4: ='DJB Daily Readings'!O12-'DJB Daily Readings'!O11 -> 234.09 | L4: ='DJB Daily Readings'!R12-'DJB Daily Readings'!R11 -> 50 | M4: ='DJB Daily Readings'!U12-'DJB Daily Readings'!U11 -> 2630.88 | N4: ='DJB Daily Readings'!X12-'DJB Daily Readings'!X11 -> 4628.4 | O4: ='DJB Daily Readings'!AA12-'DJB Daily Readings'!AA11 -> 7941.36 | P4: ='DJB Daily Readings'!AD12-'DJB Daily Readings'!AD11 -> 10572.24 | Q4: ='DJB Daily Readings'!AG12-'DJB Daily Readings'!AG11 -> 1364.16 | R4: ='DJB Daily Readings'!AJ12-'DJB Daily Readings'!AJ11 -> 6138.72 | S4: ='DJB Daily Readings'!AM12-'DJB Daily Readings'!AM11 -> 4579.68 | T4: ='DJB Daily Readings'!AP12-'DJB Daily Readings'!AP11 -> 4043.76 | U4: ='DJB Daily Readings'!AS12-'DJB Daily Readings'!AS11 -> 3069.36 | V4: ='DJB Daily Readings'!AV12-'DJB Daily Readings'!AV11 -> 6236.16 | W4: ='DJB Daily Readings'!AZ12-'DJB Daily Readings'!AZ11 -> 37900 | X4: ='DJB Daily Readings'!BC12-'DJB Daily Readings'!BC11 -> 52900 | Y4: ='DJB Daily Readings'!BF12-'DJB Daily Readings'!BF11 -> 5900 | Z4: =('DJB Daily Readings'!CK12-'DJB Daily Readings'!CK11)*1.89 -> 175.77 | AA4: =('DJB Daily Readings'!CN12-'DJB Daily Readings'!CN11)*1.89 -> 156.87 | AB4: =('DJB Daily Readings'!CQ12-'DJB Daily Readings'!CQ11)*1.89 -> 0 | AC4: ='DJB Daily Readings'!CT12-'DJB Daily Readings'!CT11 -> 192 | AD4: =('DJB Daily Readings'!BY12-'DJB Daily Readings'!BY11)*1.89 -> 34.02 | AE4: =('DJB Daily Readings'!CA12-'DJB Daily Readings'!CA11)*1.89 -> 32.13 | AF4: =('DJB Daily Readings'!CC12-'DJB Daily Readings'!CC11)*1.89 -> 11.34 | AG4: =('DJB Daily Readings'!CE12-'DJB Daily Readings'!CE11)*1.89 -> 17.01 | AH4: =('DJB Daily Readings'!CG12-'DJB Daily Readings'!CG11)*1.89 -> 26.46 | AI4: =('DJB Daily Readings'!CI12-'DJB Daily Readings'!CI11)*1.89 -> 49.14 | AJ4: ='DJB Daily Readings'!CY12-'DJB Daily Readings'!CY11 -> 5 | AK4: ='DJB Daily Readings'!CW12-'DJB Daily Readings'!CW11 -> 4 | AL4: ='DJB Daily Readings'!DC12-'DJB Daily Readings'!DC11 -> 18 | AM4: ='DJB Daily Readings'!DA12-'DJB Daily Readings'!DA11 -> 12 | AN4: ='DJB Daily Readings'!DG12-'DJB Daily Readings'!DG11 -> 7 | AO4: ='DJB Daily Readings'!DE12-'DJB Daily Readings'!DE11 -> 7 | AP4: ='DJB Daily Readings'!DK12-'DJB Daily Readings'!DK11 -> 9 | AQ4: ='DJB Daily Readings'!DI12-'DJB Daily Readings'!DI11 -> 7 | AR4: ='DJB Daily Readings'!DO12-'DJB Daily Readings'!DO11 -> 7 | AS4: ='DJB Daily Readings'!DM12-'DJB Daily Readings'!DM11 -> 4 | AT4: ='DJB Daily Readings'!DQ12-'DJB Daily Readings'!DQ11 -> 0 | AU4: ='DJB Daily Readings'!DT12-'DJB Daily Readings'!DT11 -> 9.8 | AW4: ='DJB Daily Readings'!DX12-'DJB Daily Readings'!DX11 -> 7.5 | AX4: ='DJB Daily Readings'!DZ12-'DJB Daily Readings'!DZ11 -> 11.4 | AY4: ='DJB Daily Readings'!EB12-'DJB Daily Readings'!EB11 -> 704 | AZ4: ='DJB Daily Readings'!ED12-'DJB Daily Readings'!ED11 -> 152.1 | BA4: ='DJB Daily Readings'!EG12-'DJB Daily Readings'!EG11 -> 4100 | BB4: ='DJB Daily Readings'!EI12-'DJB Daily Readings'!EI11 -> 420 | BC4: ='DJB Daily Readings'!EQ12-'DJB Daily Readings'!EQ11 -> 7000 | BD4: ='DJB Daily Readings'!EK12-'DJB Daily Readings'!EK11 -> 1900 | BE4: ='DJB Daily Readings'!EM12-'DJB Daily Readings'!EM11 -> 800 | BF4: ='DJB Daily Readings'!EO12-'DJB Daily Readings'!EO11 -> 620 | BG4: =('DJB Daily Readings'!ET12-'DJB Daily Readings'!ET11)*1.89 -> 24.57 | BH4: =('DJB Daily Readings'!EV12-'DJB Daily Readings'!EV11)*1.89 -> 24.57 | BI4: =('DJB Daily Readings'!EZ12-'DJB Daily Readings'!EZ11)*1.89 -> 32.13 | BJ4: =('DJB Daily Readings'!EX12-'DJB Daily Readings'!EX11)*1.89 -> 22.68 | BK4: =('DJB Daily Readings'!FB12-'DJB Daily Readings'!FB11)*1.89 -> 56.7
A5: Dubai at Jumeirah Beach | B5: =B4+1 -> 4 | C5: 10 | D5: 2021 | E5: =237*0.49 -> 116.13 | F5: =162+15 -> 177 | G5: ='DJB Daily Readings'!C13-'DJB Daily Readings'!C12 -> 574 | H5: ='DJB Daily Readings'!F13-'DJB Daily Readings'!F12 -> 298 | I5: ='DJB Daily Readings'!K13-'DJB Daily Readings'!K12 -> 367 | J5: ='DJB Daily Readings'!K13-'DJB Daily Readings'!K12 -> 367 | K5: ='DJB Daily Readings'!O13-'DJB Daily Readings'!O12 -> 221.29 | L5: ='DJB Daily Readings'!R13-'DJB Daily Readings'!R12 -> 38 | M5: ='DJB Daily Readings'!U13-'DJB Daily Readings'!U12 -> 2582.16 | N5: ='DJB Daily Readings'!X13-'DJB Daily Readings'!X12 -> 4823.28 | O5: ='DJB Daily Readings'!AA13-'DJB Daily Readings'!AA12 -> 8331.12 | P5: ='DJB Daily Readings'!AD13-'DJB Daily Readings'!AD12 -> 11449.2 | Q5: ='DJB Daily Readings'!AG13-'DJB Daily Readings'!AG12 -> 1071.84 | R5: ='DJB Daily Readings'!AJ13-'DJB Daily Readings'!AJ12 -> 6041.28 | S5: ='DJB Daily Readings'!AM13-'DJB Daily Readings'!AM12 -> 4774.56 | T5: ='DJB Daily Readings'!AP13-'DJB Daily Readings'!AP12 -> 4287.36 | U5: ='DJB Daily Readings'!AS13-'DJB Daily Readings'!AS12 -> 3118.08 | V5: ='DJB Daily Readings'!AV13-'DJB Daily Readings'!AV12 -> 6187.44 | W5: ='DJB Daily Readings'!AZ13-'DJB Daily Readings'!AZ12 -> 42700 | X5: ='DJB Daily Readings'!BC13-'DJB Daily Readings'!BC12 -> 57600 | Y5: ='DJB Daily Readings'!BF13-'DJB Daily Readings'!BF12 -> 0 | Z5: =('DJB Daily Readings'!CK13-'DJB Daily Readings'!CK12)*1.89 -> 177.66 | AA5: =('DJB Daily Readings'!CN13-'DJB Daily Readings'!CN12)*1.89 -> 162.54 | AB5: =('DJB Daily Readings'!CQ13-'DJB Daily Readings'!CQ12)*1.89 -> 0 | AC5: ='DJB Daily Readings'!CT13-'DJB Daily Readings'!CT12 -> 201 | AD5: =('DJB Daily Readings'!BY13-'DJB Daily Readings'!BY12)*1.89 -> 34.02 | AE5: =('DJB Daily Readings'!CA13-'DJB Daily Readings'!CA12)*1.89 -> 34.02 | AF5: =('DJB Daily Readings'!CC13-'DJB Daily Readings'!CC12)*1.89 -> 11.34 | AG5: =('DJB Daily Readings'!CE13-'DJB Daily Readings'!CE12)*1.89 -> 18.9 | AH5: =('DJB Daily Readings'!CG13-'DJB Daily Readings'!CG12)*1.89 -> 20.79 | AI5: =('DJB Daily Readings'!CI13-'DJB Daily Readings'!CI12)*1.89 -> 52.92 | AJ5: ='DJB Daily Readings'!CY13-'DJB Daily Readings'!CY12 -> 3 | AK5: ='DJB Daily Readings'!CW13-'DJB Daily Readings'!CW12 -> 6 | AL5: ='DJB Daily Readings'!DC13-'DJB Daily Readings'!DC12 -> 15 | AM5: ='DJB Daily Readings'!DA13-'DJB Daily Readings'!DA12 -> 12 | AN5: ='DJB Daily Readings'!DG13-'DJB Daily Readings'!DG12 -> 7 | AO5: ='DJB Daily Readings'!DE13-'DJB Daily Readings'!DE12 -> 7 | AP5: ='DJB Daily Readings'!DK13-'DJB Daily Readings'!DK12 -> 6 | AQ5: ='DJB Daily Readings'!DI13-'DJB Daily Readings'!DI12 -> 5 | AR5: ='DJB Daily Readings'!DO13-'DJB Daily Readings'!DO12 -> 7 | AS5: ='DJB Daily Readings'!DM13-'DJB Daily Readings'!DM12 -> 3 | AT5: ='DJB Daily Readings'!DQ13-'DJB Daily Readings'!DQ12 -> 10 | AU5: ='DJB Daily Readings'!DT13-'DJB Daily Readings'!DT12 -> 9.7 | AW5: ='DJB Daily Readings'!DX13-'DJB Daily Readings'!DX12 -> 6.8 | AX5: ='DJB Daily Readings'!DZ13-'DJB Daily Readings'!DZ12 -> 10.9 | AY5: ='DJB Daily Readings'!EB13-'DJB Daily Readings'!EB12 -> 638 | AZ5: ='DJB Daily Readings'!ED13-'DJB Daily Readings'!ED12 -> 149.5 | BA5: ='DJB Daily Readings'!EG13-'DJB Daily Readings'!EG12 -> 7500 | BB5: ='DJB Daily Readings'!EI13-'DJB Daily Readings'!EI12 -> 510 | BC5: ='DJB Daily Readings'!EQ13-'DJB Daily Readings'!EQ12 -> 9500 | BD5: ='DJB Daily Readings'!EK13-'DJB Daily Readings'!EK12 -> 3400 | BE5: ='DJB Daily Readings'!EM13-'DJB Daily Readings'!EM12 -> 800 | BF5: ='DJB Daily Readings'!EO13-'DJB Daily Readings'!EO12 -> 880 | BG5: =('DJB Daily Readings'!ET13-'DJB Daily Readings'!ET12)*1.89 -> 28.35 | BH5: =('DJB Daily Readings'!EV13-'DJB Daily Readings'!EV12)*1.89 -> 22.68 | BI5: =('DJB Daily Readings'!EZ13-'DJB Daily Readings'!EZ12)*1.89 -> 30.24 | BJ5: =('DJB Daily Readings'!EX13-'DJB Daily Readings'!EX12)*1.89 -> 20.79 | BK5: =('DJB Daily Readings'!FB13-'DJB Daily Readings'!FB12)*1.89 -> 60.48
A6: Dubai at Jumeirah Beach | B6: =B5+1 -> 5 | C6: 10 | D6: 2021 | E6: =237*0.56 -> 132.72 | F6: =182+16 -> 198 | G6: ='DJB Daily Readings'!C14-'DJB Daily Readings'!C13 -> 810 | H6: ='DJB Daily Readings'!F14-'DJB Daily Readings'!F13 -> 306 | I6: ='DJB Daily Readings'!K14-'DJB Daily Readings'!K13 -> 478 | J6: ='DJB Daily Readings'!K14-'DJB Daily Readings'!K13 -> 478 | K6: ='DJB Daily Readings'!O14-'DJB Daily Readings'!O13 -> 221.84 | L6: ='DJB Daily Readings'!R14-'DJB Daily Readings'!R13 -> 31 | M6: ='DJB Daily Readings'!U14-'DJB Daily Readings'!U13 -> 2533.44 | N6: ='DJB Daily Readings'!X14-'DJB Daily Readings'!X13 -> 4725.84 | O6: ='DJB Daily Readings'!AA14-'DJB Daily Readings'!AA13 -> 8477.28 | P6: ='DJB Daily Readings'!AD14-'DJB Daily Readings'!AD13 -> 12764.64 | Q6: ='DJB Daily Readings'!AG14-'DJB Daily Readings'!AG13 -> 1218 | R6: ='DJB Daily Readings'!AJ14-'DJB Daily Readings'!AJ13 -> 5748.96 | S6: ='DJB Daily Readings'!AM14-'DJB Daily Readings'!AM13 -> 4579.68 | T6: ='DJB Daily Readings'!AP14-'DJB Daily Readings'!AP13 -> 4092.48 | U6: ='DJB Daily Readings'!AS14-'DJB Daily Readings'!AS13 -> 3459.12 | V6: ='DJB Daily Readings'!AV14-'DJB Daily Readings'!AV13 -> 6431.04 | W6: ='DJB Daily Readings'!AZ14-'DJB Daily Readings'!AZ13 -> 43300 | X6: ='DJB Daily Readings'!BC14-'DJB Daily Readings'!BC13 -> 63400 | Y6: ='DJB Daily Readings'!BF14-'DJB Daily Readings'!BF13 -> 0 | Z6: =('DJB Daily Readings'!CK14-'DJB Daily Readings'!CK13)*1.89 -> 179.55 | AA6: =('DJB Daily Readings'!CN14-'DJB Daily Readings'!CN13)*1.89 -> 156.87 | AB6: =('DJB Daily Readings'!CQ14-'DJB Daily Readings'!CQ13)*1.89 -> 0 | AC6: ='DJB Daily Readings'!CT14-'DJB Daily Readings'!CT13 -> 207 | AD6: =('DJB Daily Readings'!BY14-'DJB Daily Readings'!BY13)*1.89 -> 32.13 | AE6: =('DJB Daily Readings'!CA14-'DJB Daily Readings'!CA13)*1.89 -> 34.02 | AF6: =('DJB Daily Readings'!CC14-'DJB Daily Readings'!CC13)*1.89 -> 11.34 | AG6: =('DJB Daily Readings'!CE14-'DJB Daily Readings'!CE13)*1.89 -> 18.9 | AH6: =('DJB Daily Readings'!CG14-'DJB Daily Readings'!CG13)*1.89 -> 24.57 | AI6: =('DJB Daily Readings'!CI14-'DJB Daily Readings'!CI13)*1.89 -> 47.25 | AJ6: ='DJB Daily Readings'!CY14-'DJB Daily Readings'!CY13 -> 7 | AK6: ='DJB Daily Readings'!CW14-'DJB Daily Readings'!CW13 -> 7 | AL6: ='DJB Daily Readings'!DC14-'DJB Daily Readings'!DC13 -> 18 | AM6: ='DJB Daily Readings'!DA14-'DJB Daily Readings'!DA13 -> 13 | AN6: ='DJB Daily Readings'!DG14-'DJB Daily Readings'!DG13 -> 7 | AO6: ='DJB Daily Readings'!DE14-'DJB Daily Readings'!DE13 -> 8 | AP6: ='DJB Daily Readings'!DK14-'DJB Daily Readings'!DK13 -> 6 | AQ6: ='DJB Daily Readings'!DI14-'DJB Daily Readings'!DI13 -> 8 | AR6: ='DJB Daily Readings'!DO14-'DJB Daily Readings'!DO13 -> 7 | AS6: ='DJB Daily Readings'!DM14-'DJB Daily Readings'!DM13 -> 5 | AT6: ='DJB Daily Readings'!DQ14-'DJB Daily Readings'!DQ13 -> 5 | AU6: ='DJB Daily Readings'!DT14-'DJB Daily Readings'!DT13 -> 10 | AW6: ='DJB Daily Readings'!DX14-'DJB Daily Readings'!DX13 -> 7.1 | AX6: ='DJB Daily Readings'!DZ14-'DJB Daily Readings'!DZ13 -> 11.1 | AY6: ='DJB Daily Readings'!EB14-'DJB Daily Readings'!EB13 -> 658 | AZ6: ='DJB Daily Readings'!ED14-'DJB Daily Readings'!ED13 -> 153.3 | BA6: ='DJB Daily Readings'!EG14-'DJB Daily Readings'!EG13 -> 6900 | BB6: ='DJB Daily Readings'!EI14-'DJB Daily Readings'!EI13 -> 460 | BC6: ='DJB Daily Readings'!EQ14-'DJB Daily Readings'!EQ13 -> 8500 | BD6: ='DJB Daily Readings'!EK14-'DJB Daily Readings'!EK13 -> 3000 | BE6: ='DJB Daily Readings'!EM14-'DJB Daily Readings'!EM13 -> 800 | BF6: ='DJB Daily Readings'!EO14-'DJB Daily Readings'!EO13 -> 790 | BG6: =('DJB Daily Readings'!ET14-'DJB Daily Readings'!ET13)*1.89 -> 30.24 | BH6: =('DJB Daily Readings'!EV14-'DJB Daily Readings'!EV13)*1.89 -> 22.68 | BI6: =('DJB Daily Readings'!EZ14-'DJB Daily Readings'!EZ13)*1.89 -> 30.24 | BJ6: =('DJB Daily Readings'!EX14-'DJB Daily Readings'!EX13)*1.89 -> 24.57 | BK6: =('DJB Daily Readings'!FB14-'DJB Daily Readings'!FB13)*1.89 -> 56.7
A7: Dubai at Jumeirah Beach | B7: =B6+1 -> 6 | C7: 10 | D7: 2021 | E7: =237*0.64 -> 151.68 | F7: =186+17 -> 203 | G7: ='DJB Daily Readings'!C15-'DJB Daily Readings'!C14 -> 792 | H7: ='DJB Daily Readings'!F15-'DJB Daily Readings'!F14 -> 330 | I7: ='DJB Daily Readings'!K15-'DJB Daily Readings'!K14 -> 418 | J7: ='DJB Daily Readings'!K15-'DJB Daily Readings'!K14 -> 418 | K7: ='DJB Daily Readings'!O15-'DJB Daily Readings'!O14 -> 224.28 | L7: ='DJB Daily Readings'!R15-'DJB Daily Readings'!R14 -> 39 | M7: ='DJB Daily Readings'!U15-'DJB Daily Readings'!U14 -> 2484.72 | N7: ='DJB Daily Readings'!X15-'DJB Daily Readings'!X14 -> 4774.56 | O7: ='DJB Daily Readings'!AA15-'DJB Daily Readings'!AA14 -> 8720.88 | P7: ='DJB Daily Readings'!AD15-'DJB Daily Readings'!AD14 -> 11595.36 | Q7: ='DJB Daily Readings'!AG15-'DJB Daily Readings'!AG14 -> 1120.56 | R7: ='DJB Daily Readings'!AJ15-'DJB Daily Readings'!AJ14 -> 5992.56 | S7: ='DJB Daily Readings'!AM15-'DJB Daily Readings'!AM14 -> 4579.68 | T7: ='DJB Daily Readings'!AP15-'DJB Daily Readings'!AP14 -> 4189.92 | U7: ='DJB Daily Readings'!AS15-'DJB Daily Readings'!AS14 -> 3507.84 | V7: ='DJB Daily Readings'!AV15-'DJB Daily Readings'!AV14 -> 6138.72 | W7: ='DJB Daily Readings'!AZ15-'DJB Daily Readings'!AZ14 -> 44900 | X7: ='DJB Daily Readings'!BC15-'DJB Daily Readings'!BC14 -> 57500 | Y7: ='DJB Daily Readings'!BF15-'DJB Daily Readings'!BF14 -> 0 | Z7: =('DJB Daily Readings'!CK15-'DJB Daily Readings'!CK14)*1.89 -> 181.44 | AA7: =('DJB Daily Readings'!CN15-'DJB Daily Readings'!CN14)*1.89 -> 164.43 | AB7: =('DJB Daily Readings'!CQ15-'DJB Daily Readings'!CQ14)*1.89 -> 0 | AC7: ='DJB Daily Readings'!CT15-'DJB Daily Readings'!CT14 -> 195 | AD7: =('DJB Daily Readings'!BY15-'DJB Daily Readings'!BY14)*1.89 -> 34.02 | AE7: =('DJB Daily Readings'!CA15-'DJB Daily Readings'!CA14)*1.89 -> 34.02 | AF7: =('DJB Daily Readings'!CC15-'DJB Daily Readings'!CC14)*1.89 -> 11.34 | AG7: =('DJB Daily Readings'!CE15-'DJB Daily Readings'!CE14)*1.89 -> 17.01 | AH7: =('DJB Daily Readings'!CG15-'DJB Daily Readings'!CG14)*1.89 -> 26.46 | AI7: =('DJB Daily Readings'!CI15-'DJB Daily Readings'!CI14)*1.89 -> 51.03 | AJ7: ='DJB Daily Readings'!CY15-'DJB Daily Readings'!CY14 -> 7 | AK7: ='DJB Daily Readings'!CW15-'DJB Daily Readings'!CW14 -> 8 | AL7: ='DJB Daily Readings'!DC15-'DJB Daily Readings'!DC14 -> 17 | AM7: ='DJB Daily Readings'!DA15-'DJB Daily Readings'!DA14 -> 14 | AN7: ='DJB Daily Readings'!DG15-'DJB Daily Readings'!DG14 -> 7 | AO7: ='DJB Daily Readings'!DE15-'DJB Daily Readings'!DE14 -> 7 | AP7: ='DJB Daily Readings'!DK15-'DJB Daily Readings'!DK14 -> 8 | AQ7: ='DJB Daily Readings'!DI15-'DJB Daily Readings'!DI14 -> 9 | AR7: ='DJB Daily Readings'!DO15-'DJB Daily Readings'!DO14 -> 8 | AS7: ='DJB Daily Readings'!DM15-'DJB Daily Readings'!DM14 -> 5 | AT7: ='DJB Daily Readings'!DQ15-'DJB Daily Readings'!DQ14 -> 6 | AU7: ='DJB Daily Readings'!DT15-'DJB Daily Readings'!DT14 -> 10.4 | AW7: ='DJB Daily Readings'!DX15-'DJB Daily Readings'!DX14 -> 7.3 | AX7: ='DJB Daily Readings'!DZ15-'DJB Daily Readings'!DZ14 -> 11.1 | AY7: ='DJB Daily Readings'!EB15-'DJB Daily Readings'!EB14 -> 717 | AZ7: ='DJB Daily Readings'!ED15-'DJB Daily Readings'!ED14 -> 149.8 | BA7: ='DJB Daily Readings'!EG15-'DJB Daily Readings'!EG14 -> 7400 | BB7: ='DJB Daily Readings'!EI15-'DJB Daily Readings'!EI14 -> 490 | BC7: ='DJB Daily Readings'!EQ15-'DJB Daily Readings'!EQ14 -> 9100 | BD7: ='DJB Daily Readings'!EK15-'DJB Daily Readings'!EK14 -> 3200 | BE7: ='DJB Daily Readings'!EM15-'DJB Daily Readings'!EM14 -> 900 | BF7: ='DJB Daily Readings'!EO15-'DJB Daily Readings'!EO14 -> 870 | BG7: =('DJB Daily Readings'!ET15-'DJB Daily Readings'!ET14)*1.89 -> 30.24 | BH7: =('DJB Daily Readings'!EV15-'DJB Daily Readings'!EV14)*1.89 -> 20.79 | BI7: =('DJB Daily Readings'!EZ15-'DJB Daily Readings'!EZ14)*1.89 -> 34.02 | BJ7: =('DJB Daily Readings'!EX15-'DJB Daily Readings'!EX14)*1.89 -> 24.57 | BK7: =('DJB Daily Readings'!FB15-'DJB Daily Readings'!FB14)*1.89 -> 60.48
A8: Dubai at Jumeirah Beach | B8: =B7+1 -> 7 | C8: 10 | D8: 2021 | F8: =221+28 -> 249
A9: Dubai at Jumeirah Beach | B9: =B8+1 -> 8 | C9: 10 | D9: 2021
A10: Dubai at Jumeirah Beach | B10: =B9+1 -> 9 | C10: 10 | D10: 2021
A11: Dubai at Jumeirah Beach | B11: =B10+1 -> 10 | C11: 10 | D11: 2021
A12: Dubai at Jumeirah Beach | B12: =B11+1 -> 11 | C12: 10 | D12: 2021
A13: Dubai at Jumeirah Beach | B13: =B12+1 -> 12 | C13: 10 | D13: 2021
A14: Dubai at Jumeirah Beach | B14: =B13+1 -> 13 | C14: 10 | D14: 2021
A15: Dubai at Jumeirah Beach | B15: =B14+1 -> 14 | C15: 10 | D15: 2021
A16: Dubai at Jumeirah Beach | B16: =B15+1 -> 15 | C16: 10 | D16: 2021
A17: Dubai at Jumeirah Beach | B17: =B16+1 -> 16 | C17: 10 | D17: 2021
A18: Dubai at Jumeirah Beach | B18: =B17+1 -> 17 | C18: 10 | D18: 2021
A19: Dubai at Jumeirah Beach | B19: =B18+1 -> 18 | C19: 10 | D19: 2021
A20: Dubai at Jumeirah Beach | B20: =B19+1 -> 19 | C20: 10 | D20: 2021
... A31: Dubai at Jumeirah Beach | B31: =B30+1 -> 30 | C31: 10 | D31: 2021
A32: Dubai at Jumeirah Beach | B32: 31 | C32: 10 | D32: 2021

Sheet DJB Daily Readings
A6: Daily Water Consumption January 2020 | U6: Electricity Daily Consumption January 2020 | AZ6: Chiller BTU Meter Reading January 2020 | BV6: Lpg Daily Consumption January 2020 | CW6: F& B Village Daily Water Meter Reading 2020 | DT6: F & B Electrical Daily Reading January 2020 | EG6: F & B Village Chilled Water Reading January 2020 | ET6: F & B Village Daily Lpg Reading January 2020
A7: Date | B7: Daily Occupancy % | C7: Potable Water meter Reading -M³ | F7: Resort Water Meter Reading M³ | I7: Tse Water meter Reading M³ | K7: Irrigation Water Meter Reading M³ | M7: Domestic Water For Irrigation M³ | O7: Cooling Tower Meter ReadingM³ | R7: Cooling Tower Blowdown Reading | U7: EMDB-1 All Pumps | X7: EMDB-2 Elevators | AA7: MDB-1 Chiller # 1 | AD7: MDB-2 Chiller # 2 | AG7: MDB-3 Chiller # 3 | AJ7: MDB-4 North Riser Guest Rooms | AM7: MDB-5 North Riser Guest Rooms | AP7: MDB-6 Main Kitchen | AS7: MDB-7 South Riser Guest Rooms | AV7: MDB-8 F & B | AZ7: Chiller 1 | BC7: Chiller 2 | BF7: Chiller 3 | BI7: Active Pool Heat Exchanger Hot Water | BK7: Active Pool Heat Exchanger Chilled Water | BM7: Quiet Pool Heat Exchanger Hot Water | BO7: Quiet Pool Heat Exchanger Chilled Water | BQ7: Sea Fu Restaurant | BS7: cold water heat exchanger | BV7: Lpg Main Tank | BY7: Ird Kitchen | CA7: Suq Kitchen | CC7: Bakery Kitchen | CE7: Shai Saloon Kitchen | CG7: Banquet Kitchen | CI7: Sea Fu Kitchen | CK7: Steam Boiler | CN7: Solar Hot Water Boiler | CQ7: Low Temp Hot Water Boiler | CT7: Steam Boiler Steam Meter Reading | CW7: Verde Water Meter Reading | DA7: Coya Water Meter Reading M³ | DE7: Nusret Water meter Reading M³ | DI7: Provoceteur Meter Reading M³ | DM7: Scalini Meter Reading M³ | DQ7: Irrigation | DT7: MDB - Coya | DV7: MDB Verde | DX7: MDB - Nusret | DZ7: Peovoceteur SMDB | EB7: SMDB - Scalini | ED7: Common ESMDB | EG7: Coya Btu | EI7: Coya Cold Room Btu | EK7: Nusret Btu | EM7: Provocateur- A | EO7: Provocateur- B | EQ7: Verde Btu | ET7: Coya Lpg | EV7: Nusret Lpg | EX7: Provocateur Lpg | EZ7: Verde Lpg | FB7: Scalini
C8: Reading In M³ | D8: Daily consumption M³ 2018 | E8: Daily consumption M³ December-2017 | F8: Reading M³ | G8: Daily Consumption M³ | H8: Daily consumption M³ December-2017 | I8: Reading M³ | J8: Daily consumption M³ | K8: Reading M³ | L8: Daily consumption M³ | M8: Reading M³ | N8: Daily consumption M³ | O8: Reading M³ | P8: Daily Consumption M³ | Q8: Daily consumption M³ December-2017 | R8: Reading M³ | S8: Daily Consumption M³ | U8: Reading KWH | V8: Daily Consumption Kwh 2018 | W8: Daily Consumption Kwh 2017 | X8: Reading KWH | Y8: Daily Consumption Kwh 2018 | Z8: Daily Consumption Kwh 2017 | AA8: Reading KWH | AB8: Daily Consumption Kwh 2018 | AC8: Daily Consumption Kwh 2017 | AD8: Reading KWH | AE8: Daily Consumption Kwh 2018 | AF8: Daily Consumption Kwh 2017 | AG8: Reading KWH | AH8: Daily Consumption Kwh 2018 | AI8: Daily Consumption Kwh 2017 | AJ8: Reading KWH | AK8: Daily Consumption Kwh 2018 | AL8: Daily Consumption Kwh 2017 | AM8: Reading KWH | AN8: Daily Consumption Kwh 2018 | AO8: Daily Consumption Kwh 2017 | AP8: Reading KWH | AQ8: Daily Consumption Kwh 2018 | AR8: Daily Consumption Kwh 2017 | AS8: Reading KWH | AT8: Daily Consumption Kwh 2018 | AU8: Daily Consumption Kwh 2017 | AV8: Reading KWH | AW8: Daily Consumption Kwh 2018 | AX8: Daily Consumption Kwh 2017 | AZ8: Reading Kwh | BA8: Daily Consumption Kwh | BB8: Daily Consumption Kwh 2017 | BC8: Reading Kwh | BD8: Daily Consumption Kwh | BE8: Daily Consumption Kwh 2017 | BF8: Reading Kwh | BG8: Daily Consumption Kwh | BH8: Daily Consumption Kwh 2017 | BI8: Reading Kwh | BJ8: Daily Consumption Kwh | BK8: Reading Kwh | BL8: Daily Consumption Kwh | BM8: Reading Kwh | BN8: Daily Consumption Kwh | BO8: Reading Kwh | BP8: Daily Consumption Kwh | BQ8: Reading Kwh | BR8: Daily Consumption Kwh | BS8: Reading Kwh | BT8: Daily Consumption Kwh | BV8: Reading % | BW8: Reading M³ | BX8: Daily consumption M³ December-2017 | BY8: Reading M³ | BZ8: Daily Consumption M³ | CA8: Reading M³ | CB8: Daily Consumption M³ | CC8: Reading M³ | CD8: Daily Consumption M³ | CE8: Reading M³ | CF8: Daily Consumption M³ | CG8: Reading M³ | CH8: Daily Consumption M³ | CI8: Reading M³ | CJ8: Daily Consumption M³ | CK8: Reading M³ | CL8: Daily Consumption M³ | CM8: Daily consumption M³ December-2017 | CN8: Reading M³ | CO8: Daily Consumption M³ | CP8: Daily consumption M³ December-2017 | CQ8: Reading M³ | CR8: Daily Consumption M³ | CS8: Daily consumption M³ December-2017 | CT8: Reading Kg | CU8: Daily Consumption Kg | CW8: Hot Water M³ | CX8: Daily consumption M³ | CY8: Cold Water M³ | CZ8: Daily consumption M³ | DA8: Hot Water M³ | DB8: Daily Consumption M³ | DC8: Cold Water M³ | DD8: Daily Consumption M³ | DE8: Hot Water M³ | DF8: Daily consumption M³ | DG8: Cold Water M³ | DH8: Daily consumption M³ | DI8: Hot Water M³ | DJ8: Daily Consumption M³ | DK8: Cold Water M³ | DL8: Daily Consumption M³ | DM8: Hot Water M³ | DN8: Daily Consumption M³ | DO8: Cold Water M³ | DP8: Daily Consumption M³ | DQ8: Daily Reading | DR8: Daily Consumption M³ | DT8: Reading KWH | DU8: Difference KWH | DV8: Reading KWH | DW8: Difference KWH | DX8: Reading KWH | DY8: Difference KWH | DZ8: Reading KWH | EA8: Difference KWH | EB8: Reading KWH | EC8: Difference KWH | ED8: Reading KWH | EE8: Difference KWH | EG8: Reading KWH | EH8: Difference KWH | EI8: Reading KWH | EJ8: Difference KWH | EK8: Reading KWH | EL8: Difference KWH | EM8: Reading KWH | EN8: Difference KWH | EO8: Reading KWH | EP8: Difference KWH | EQ8: Reading KWH | ER8: Difference KWH | ET8: Reading M³ | EU8: Daily Consumption M³ | EV8: Reading M³ | EW8: Daily Consumption M³ | EX8: Reading M³ | EY8: Daily Consumption M³ | EZ8: Reading M³ | FA8: Daily Consumption M³ | FB8: Reading M³ | FC8: Daily Consumption M³
A9: 43830 | B9: ='[1]October - 2021'!B9 -> 0.76 | C9: ='[1]October - 2021'!E9 -> 872256 | D9: =C10-C9 -> 765 | E9: ='[1]October - 2021'!G9 -> 582 | F9: ='[1]October - 2021'!H9 -> 61118 | G9: =F10-F9 -> 417 | H9: ='[1]October - 2021'!J9 -> 313 | I9: ='[1]October - 2021'!K9 -> 164625 | J9: =I10-I9 -> 0 | K9: ='[1]October - 2021'!N9 -> 800710 | L9: =K10-K9 -> 331 | M9: ='[1]October - 2021'!Q9 -> 183610 | N9: =M10-M9 -> 46 | O9: ='[1]October - 2021'!S9 -> 41866.07 | P9: =O10-O9 -> 271.21 | Q9: ='[1]October - 2021'!U9 -> 109 | R9: ='[1]October - 2021'!V9 -> 2200 | S9: =R10-R9 -> 42 | U9: ='[1]October - 2021'!AC9 -> 6972903.8 | V9: =U10-U9 -> 4141.2 | W9: ='[1]October - 2021'!AD9 -> 4141.2 | X9: ='[1]October - 2021'!AF9 -> 13421142 | Y9: =X10-X9 -> 4725.84 | Z9: ='[1]October - 2021'!AG9 -> 4725.84 | AA9: ='[1]October - 2021'!AI9 -> 13317271 | AB9: =AA10-AA9 -> 14274.96 | AC9: ='[1]October - 2021'!AJ9 -> 14274.96 | AD9: ='[1]October - 2021'!AL9 -> 16300348 | AE9: =AD10-AD9 -> 12374.88 | AF9: ='[1]October - 2021'!AM9 -> 12374.88 | AG9: ='[1]October - 2021'!AO9 -> 16710570 | AH9: =AG10-AG9 -> 779.52 | AI9: ='[1]October - 2021'!AP9 -> 779.52 | AJ9: ='[1]October - 2021'!AR9 -> 15072750 | AK9: =AJ10-AJ9 -> 6333.6 | AL9: ='[1]October - 2021'!AS9 -> 6333.6 | AM9: ='[1]October - 2021'!AU9 -> 12848000 | AN9: =AM10-AM9 -> 4969.44 | AO9: ='[1]October - 2021'!AV9 -> 4969.44 | AP9: ='[1]October - 2021'!AX9 -> 12368303 | AQ9: =AP10-AP9 -> 4287.36 | AR9: ='[1]October - 2021'!AY9 -> 4287.36 | AS9: ='[1]October - 2021'!BA9 -> 9865361.5 | AT9: =AS10-AS9 -> 3556.56 | AU9: ='[1]October - 2021'!BB9 -> 3556.56 | AV9: ='[1]October - 2021'!BD9 -> 15242783 | AW9: =AV10-AV9 -> 5700.24 | AX9: ='[1]October - 2021'!BE9 -> 5700.24 | AZ9: ='[1]October - 2021'!BK9 -> 66088200 | BA9: =AZ10-AZ9 -> 68600 | BB9: ='[1]October - 2021'!BL9 -> 68600 | BC9: ='[1]October - 2021'!BN9 -> 68499700 | BD9: =BC10-BC9 -> 65400 | BE9: ='[1]October - 2021'!BO9 -> 65400 | BF9: ='[1]October - 2021'!BQ9 -> 63297900 | BG9: =BF10-BF9 -> 0 | BH9: ='[1]October - 2021'!BR9 -> 0 | BS9: ='[1]October - 2021'!BT9 -> 7219090 | BT9: =BS10-BS9 -> 7620 | BV9: ='[1]October - 2021'!BW9 -> 0.79 | BW9: =BV10-BV9 -> -0.04 | BX9: ='[1]October - 2021'!$BX$9:$BX$10 -> 0.04 | BY9: ='[1]October - 2021'!BZ9 -> 55717 | BZ9: =BY10-BY9 -> 18 | CA9: ='[1]October - 2021'!CB9 -> 47253 | CB9: =CA10-CA9 -> 20 | CC9: ='[1]October - 2021'!CD9 -> 16334 | CD9: =CC10-CC9 -> 7 | CE9: ='[1]October - 2021'!CF9 -> 21339 | CF9: =CE10-CE9 -> 10 | CG9: ='[1]October - 2021'!CH9 -> 23108 | CH9: =CG10-CG9 -> 17 | CI9: ='[1]October - 2021'!CJ9 -> 51575 | CJ9: =CI10-CI9 -> 30 | CK9: ='[1]October - 2021'!CL9 -> 227310 | CL9: =CK10-CK9 -> 94 | CM9: ='[1]October - 2021'!CM9 -> 94 | CN9: ='[1]October - 2021'!CO9 -> 173158 | CO9: =CN10-CN9 -> 81 | CP9: ='[1]October - 2021'!CP9 -> 81 | CQ9: ='[1]October - 2021'!CR9 -> 308195 | CR9: =CQ10-CQ9 -> 0 | CS9: ='[1]October - 2021'!CS9 -> 0 | CT9: ='[1]October - 2021'!CU9 -> 604639 | CU9: =CT10-CT9 -> 195 | CW9: ='[1]October - 2021'!CX9 -> 5797 | CX9: =CW10-CW9 -> 9 | CY9: ='[1]October - 2021'!CZ9 -> 3342 | CZ9: =CY10-CY9 -> 9 | DA9: ='[1]October - 2021'!DB9 -> 25655 | DB9: =DA10-DA9 -> 18 | DC9: ='[1]October - 2021'!DD9 -> 26370 | DD9: =DC10-DC9 -> 19 | DE9: ='[1]October - 2021'!DF9 -> 18067 | DF9: =DE10-DE9 -> 7 | DG9: ='[1]October - 2021'!DH9 -> 21176 | DH9: =DG10-DG9 -> 11 | DI9: ='[1]October - 2021'!DJ9 -> 2635 | DJ9: =DI10-DI9 -> 8 | DK9: ='[1]October - 2021'!DL9 -> 5917 | DL9: =DK10-DK9 -> 15 | DM9: ='[1]October - 2021'!DN9 -> 1480 | DN9: =DM10-DM9 -> 10 | DO9: ='[1]October - 2021'!DP9 -> 3034 | DP9: =DO10-DO9 -> 6 | DQ9: ='[1]October - 2021'!DR9 -> 25998 | DR9: =DQ10-DQ9 -> 0 | DT9: ='[1]October - 2021'!DU9 -> 2460.5 | DU9: =DT10-DT9 -> 11 | DV9: ='[1]October - 2021'!DW9 -> 7671.3 | DW9: =DV10-DV9 -> 9.1 | DX9: ='[1]October - 2021'!DY9 -> 1853.5 | DY9: =DX10-DX9 -> 7.7 | DZ9: ='[1]October - 2021'!EA9 -> 1807.6 | EA9: =DZ10-DZ9 -> 5.9 | EB9: ='[1]October - 2021'!EC9 -> 826585 | EC9: =EB10-EB9 -> 886 | ED9: ='[1]October - 2021'!EG9 -> 165661.4 | EE9: =ED10-ED9 -> 155.9 | EG9: ='[1]October - 2021'!EJ9 -> 10069900 | EH9: =EG10-EG9 -> 11100 | EI9: ='[1]October - 2021'!EL9 -> 802400 | EJ9: =EI10-EI9 -> 530 | EK9: ='[1]October - 2021'!EN9 -> 6240100 | EL9: =EK10-EK9 -> 4500 | EM9: ='[1]October - 2021'!EP9 -> 2205300 | EN9: =EM10-EM9 -> 2200 | EO9: ='[1]October - 2021'!ER9 -> 942170 | EP9: =EO10-EO9 -> 1220 | EQ9: ='[1]October - 2021'!ET9 -> 13908000 | ER9: =EQ10-EQ9 -> 11800 | ET9: ='[1]October - 2021'!EW9 -> 36453 | EU9: =ET10-ET9 -> 16 | EV9: ='[1]October - 2021'!EY9 -> 31514 | EW9: =EV10-EV9 -> 13 | EX9: ='[1]October - 2021'!FA9 -> 2629 | EY9: 0 | EZ9: ='[1]October - 2021'!FC9 -> 52872 | FA9: =EZ10-EZ9 -> 18 | FB9: ='[1]October - 2021'!FE9 -> 35506 | FC9: =FB10-FB9 -> 35
A10: 43831 | B10: ='[1]October - 2021'!B10 -> 0.73 | C10: ='[1]October - 2021'!E10 -> 873021 | F10: ='[1]October - 2021'!H10 -> 61535 | I10: ='[1]October - 2021'!K10 -> 164625 | K10: ='[1]October - 2021'!N10 -> 801041 | M10: ='[1]October - 2021'!Q10 -> 183656 | O10: ='[1]October - 2021'!S10 -> 42137.28 | R10: ='[1]October - 2021'!V10 -> 2242 | U10: ='[1]October - 2021'!AC10 -> 6977045 | X10: ='[1]October - 2021'!AF10 -> 13425868 | AA10: ='[1]October - 2021'!AI10 -> 13331546 | AD10: ='[1]October - 2021'!AL10 -> 16312723 | AG10: ='[1]October - 2021'!AO10 -> 16711350 | AJ10: ='[1]October - 2021'!AR10 -> 15079084 | AM10: ='[1]October - 2021'!AU10 -> 12852969 | AP10: ='[1]October - 2021'!AX10 -> 12372590 | AS10: ='[1]October - 2021'!BA10 -> 9868918.1 | AV10: ='[1]October - 2021'!BD10 -> 15248483 | AZ10: ='[1]October - 2021'!BK10 -> 66156800 | BC10: ='[1]October - 2021'!BN10 -> 68565100 | BF10: ='[1]October - 2021'!BQ10 -> 63297900 | BS10: ='[1]October - 2021'!BT10 -> 7226710 | BV10: ='[1]October - 2021'!BW10 -> 0.75 | BY10: ='[1]October - 2021'!BZ10 -> 55735 | CA10: ='[1]October - 2021'!CB10 -> 47273 | CC10: ='[1]October - 2021'!CD10 -> 16341 | CE10: ='[1]October - 2021'!CF10 -> 21349 | CG10: ='[1]October - 2021'!CH10 -> 23125 | CI10: ='[1]October - 2021'!CJ10 -> 51605 | CK10: ='[1]October - 2021'!CL10 -> 227404 | CN10: ='[1]October - 2021'!CO10 -> 173239 | CQ10: ='[1]October - 2021'!CR10 -> 308195 | CT10: ='[1]October - 2021'!CU10 -> 604834 | CW10: ='[1]October - 2021'!CX10 -> 5806 | CY10: ='[1]October - 2021'!CZ10 -> 3351 | DA10: ='[1]October - 2021'!DB10 -> 25673 | DC10: ='[1]October - 2021'!DD10 -> 26389 | DE10: ='[1]October - 2021'!DF10 -> 18074 | DG10: ='[1]October - 2021'!DH10 -> 21187 | DI10: ='[1]October - 2021'!DJ10 -> 2643 | DK10: ='[1]October - 2021'!DL10 -> 5932 | DM10: ='[1]October - 2021'!DN10 -> 1490 | DO10: ='[1]October - 2021'!DP10 -> 3040 | DQ10: ='[1]October - 2021'!DR10 -> 25998 | DT10: ='[1]October - 2021'!DU10 -> 2471.5 | DV10: ='[1]October - 2021'!DW10 -> 7680.4 | DX10: ='[1]October - 2021'!DY10 -> 1861.2 | DZ10: ='[1]October - 2021'!EA10 -> 1813.5 | EB10: ='[1]October - 2021'!EC10 -> 827471 | ED10: ='[1]October - 2021'!EG10 -> 165817.3 | EG10: ='[1]October - 2021'!EJ10 -> 10081000 | EI10: ='[1]October - 2021'!EL10 -> 802930 | EK10: ='[1]October - 2021'!EN10 -> 6244600 | EM10: ='[1]October - 2021'!EP10 -> 2207500 | EO10: ='[1]October - 2021'!ER10 -> 943390 | EQ10: ='[1]October - 2021'!ET10 -> 13919800 | ET10: ='[1]October - 2021'!EW10 -> 36469 | EV10: ='[1]October - 2021'!EY10 -> 31527 | EX10: ='[1]October - 2021'!FA10 -> 2645 | EZ10: ='[1]October - 2021'!FC10 -> 52890 | FB10: ='[1]October - 2021'!FE10 -> 35541
A11: 43832 | B11: ='[1]October - 2021'!B11 -> 0.61 | C11: ='[1]October - 2021'!E11 -> 873718 | D11: ='[1]October - 2021'!F11 -> 697 | E11: ='[1]October - 2021'!G11 -> 554 | F11: ='[1]October - 2021'!H11 -> 61859 | G11: ='[1]October - 2021'!I11 -> 324 | H11: ='[1]October - 2021'!J11 -> 360 | I11: ='[1]October - 2021'!K11 -> 164625 | J11: ='[1]October - 2021'!L11 -> 0 | K11: ='[1]October - 2021'!N11 -> 801530 | L11: ='[1]October - 2021'!O11 -> 489 | M11: ='[1]October - 2021'!Q11 -> 183801 | N11: ='[1]October - 2021'!R11 -> 145 | O11: ='[1]October - 2021'!S11 -> 42401.83 | P11: ='[1]October - 2021'!T11 -> 264.55 | Q11: ='[1]October - 2021'!U11 -> 130 | R11: ='[1]October - 2021'!V11 -> 2285 | S11: ='[1]October - 2021'!W11 -> 43 | U11: ='[1]October - 2021'!AC11 -> 6981235 | V11: ='[1]October - 2021'!AD11 -> 4189.92 | W11: ='[1]October - 2021'!AD11 -> 4189.92 | X11: ='[1]October - 2021'!AF11 -> 13430691 | Y11: ='[1]October - 2021'!AG11 -> 4823.28 | Z11: ='[1]October - 2021'!AG11 -> 4823.28 | AA11: ='[1]October - 2021'!AI11 -> 13342605 | AB11: ='[1]October - 2021'!AJ11 -> 11059.44 | AC11: ='[1]October - 2021'!AJ11 -> 11059.44 | AD11: ='[1]October - 2021'!AL11 -> 16325634 | AE11: ='[1]October - 2021'!AM11 -> 12910.8 | AF11: ='[1]October - 2021'!AM11 -> 12910.8 | AG11: ='[1]October - 2021'!AO11 -> 16712958 | AH11: ='[1]October - 2021'!AP11 -> 1607.76 | AI11: ='[1]October - 2021'!AP11 -> 1607.76 | AJ11: ='[1]October - 2021'!AR11 -> 15085320 | AK11: ='[1]October - 2021'!AS11 -> 6236.16 | AL11: ='[1]October - 2021'!AS11 -> 6236.16 | AM11: ='[1]October - 2021'!AU11 -> 12857744 | AN11: ='[1]October - 2021'!AV11 -> 4774.56 | AO11: ='[1]October - 2021'!AV11 -> 4774.56 | AP11: ='[1]October - 2021'!AX11 -> 12376683 | AQ11: ='[1]October - 2021'!AY11 -> 4092.48 | AR11: ='[1]October - 2021'!AY11 -> 4092.48 | AS11: ='[1]October - 2021'!BA11 -> 9871987.4 | AT11: ='[1]October - 2021'!BB11 -> 3069.36 | AU11: ='[1]October - 2021'!BB11 -> 3069.36 | AV11: ='[1]October - 2021'!BD11 -> 15255158 | AW11: ='[1]October - 2021'!BE11 -> 6674.64 | AX11: ='[1]October - 2021'!BE11 -> 6674.64 | AZ11: ='[1]October - 2021'!BK11 -> 66214400 | BA11: ='[1]October - 2021'!BL11 -> 57600 | BB11: ='[1]October - 2021'!BL11 -> 57600 | BC11: ='[1]October - 2021'!BN11 -> 68634500 | BD11: ='[1]October - 2021'!BO11 -> 69400 | BE11: ='[1]October - 2021'!BO11 -> 69400 | BF11: ='[1]October - 2021'!BQ11 -> 63297900 | BG11: ='[1]October - 2021'!BR11 -> 0 | BH11: ='[1]October - 2021'!BR11 -> 0 | BS11: ='[1]October - 2021'!BT11 -> 7233230 | BT11: ='[1]October - 2021'!BU11 -> 6520 | BV11: ='[1]October - 2021'!BW11 -> 0.82 | BW11: ='[1]October - 2021'!BX11 -> -0.07 | BX11: ='[1]October - 2021'!BX11 -> -0.07 | BY11: ='[1]October - 2021'!BZ11 -> 55753 | BZ11: ='[1]October - 2021'!CA11 -> 18 | CA11: ='[1]October - 2021'!CB11 -> 47290 | CB11: ='[1]October - 2021'!CC11 -> 17 | CC11: ='[1]October - 2021'!CD11 -> 16348 | CD11: ='[1]October - 2021'!CE11 -> 7 | CE11: ='[1]October - 2021'!CF11 -> 21359 | CF11: ='[1]October - 2021'!CG11 -> 10 | ... CL11: ='[1]October - 2021'!CM11 -> 96 | CM11: ='[1]October - 2021'!CM11 -> 96 | CN11: ='[1]October - 2021'!CO11 -> 173320 | CO11: ='[1]October - 2021'!CP11 -> 81 | CP11: ='[1]October - 2021'!CP11 -> 81 | CQ11: ='[1]October - 2021'!CR11 -> 308195 | CR11: ='[1]October - 2021'!CS11 -> 0 | CS11: ='[1]October - 2021'!CS11 -> 0 | CT11: ='[1]October - 2021'!CU11 -> 605024 | CU11: ='[1]October - 2021'!CV11 -> 190 | CW11: ='[1]October - 2021'!CX11 -> 5813 | CX11: ='[1]October - 2021'!CY11 -> 7 | CY11: ='[1]October - 2021'!CZ11 -> 3357 | CZ11: ='[1]October - 2021'!DA11 -> 0 | DA11: ='[1]October - 2021'!DB11 -> 25685 | DB11: ='[1]October - 2021'!DC11 -> 12 | DC11: ='[1]October - 2021'!DD11 -> 26403 | DD11: ='[1]October - 2021'!DE11 -> 14 | ... DR11: ='[1]October - 2021'!DS11 -> 0 | DT11: ='[1]October - 2021'!DU11 -> 2481.6 | DU11: ='[1]October - 2021'!DV11 -> 10.1 | DV11: ='[1]October - 2021'!DW11 -> 7689.4 | DW11: ='[1]October - 2021'!DX11 -> 9 | DX11: ='[1]October - 2021'!DY11 -> 1868.9 | DY11: ='[1]October - 2021'!DZ11 -> 7.7 | DZ11: ='[1]October - 2021'!EA11 -> 1825.7 | EA11: ='[1]October - 2021'!EB11 -> 12.2 | ... EC11: ='[1]October - 2021'!ED11 -> 768 | ED11: ='[1]October - 2021'!EG11 -> 165970.3 | EE11: ='[1]October - 2021'!EH11 -> 153 | EG11: ='[1]October - 2021'!EJ11 -> 10089600 | EH11: ='[1]October - 2021'!EK11 -> 8600 | EI11: ='[1]October - 2021'!EL11 -> 803290 | EJ11: ='[1]October - 2021'!EM11 -> 360 | EK11: ='[1]October - 2021'!EN11 -> 6248100 | EL11: ='[1]October - 2021'!EO11 -> 3500 | EM11: ='[1]October - 2021'!EP11 -> 2208500 | EN11: ='[1]October - 2021'!EQ11 -> 1000 | ... ER11: ='[1]October - 2021'!EU11 -> 8000 | ET11: ='[1]October - 2021'!EW11 -> 36483 | EU11: ='[1]October - 2021'!EX11 -> 14 | EV11: ='[1]October - 2021'!EY11 -> 31538 | EW11: ='[1]October - 2021'!EZ11 -> 11 | EX11: ='[1]October - 2021'!FA11 -> 2662 | EY11: ='[1]October - 2021'!FB11 -> 17 | EZ11: ='[1]October - 2021'!FC11 -> 52908 | FA11: ='[1]October - 2021'!FD11 -> 18 | ... FC11: ='[1]October - 2021'!FF11 -> 34
A12: 43833 | B12: ='[1]October - 2021'!B12 -> 0.5 | C12: ='[1]October - 2021'!E12 -> 874429 | D12: ='[1]October - 2021'!F12 -> 711 | E12: ='[1]October - 2021'!G12 -> 542 | F12: ='[1]October - 2021'!H12 -> 62173 | G12: ='[1]October - 2021'!I12 -> 314 | H12: ='[1]October - 2021'!J12 -> 309 | I12: ='[1]October - 2021'!K12 -> 164625 | J12: ='[1]October - 2021'!L12 -> 0 | K12: ='[1]October - 2021'!N12 -> 801953 | L12: ='[1]October - 2021'!O12 -> 423 | M12: ='[1]October - 2021'!Q12 -> 183937 | N12: ='[1]October - 2021'!R12 -> 136 | O12: ='[1]October - 2021'!S12 -> 42635.92 | P12: ='[1]October - 2021'!T12 -> 234.09 | Q12: ='[1]October - 2021'!U12 -> 146 | R12: ='[1]October - 2021'!V12 -> 2335 | S12: ='[1]October - 2021'!W12 -> 50 | U12: ='[1]October - 2021'!AC12 -> 6983865.8 | V12: ='[1]October - 2021'!AD12 -> 2630.88 | W12: ='[1]October - 2021'!AD12 -> 2630.88 | X12: ='[1]October - 2021'!AF12 -> 13435320 | Y12: ='[1]October - 2021'!AG12 -> 4628.4 | Z12: ='[1]October - 2021'!AG12 -> 4628.4 | AA12: ='[1]October - 2021'!AI12 -> 13350547 | AB12: ='[1]October - 2021'!AJ12 -> 7941.36 | AC12: ='[1]October - 2021'!AJ12 -> 7941.36 | AD12: ='[1]October - 2021'!AL12 -> 16336206 | AE12: ='[1]October - 2021'!AM12 -> 10572.24 | AF12: ='[1]October - 2021'!AM12 -> 10572.24 | AG12: ='[1]October - 2021'!AO12 -> 16714322 | AH12: ='[1]October - 2021'!AP12 -> 1364.16 | AI12: ='[1]October - 2021'!AP12 -> 1364.16 | AJ12: ='[1]October - 2021'!AR12 -> 15091458 | AK12: ='[1]October - 2021'!AS12 -> 6138.72 | AL12: ='[1]October - 2021'!AS12 -> 6138.72 | AM12: ='[1]October - 2021'!AU12 -> 12862324 | AN12: ='[1]October - 2021'!AV12 -> 4579.68 | AO12: ='[1]October - 2021'!AV12 -> 4579.68 | AP12: ='[1]October - 2021'!AX12 -> 12380726 | AQ12: ='[1]October - 2021'!AY12 -> 4043.76 | AR12: ='[1]October - 2021'!AY12 -> 4043.76 | AS12: ='[1]October - 2021'!BA12 -> 9875056.8 | AT12: ='[1]October - 2021'!BB12 -> 3069.36 | AU12: ='[1]October - 2021'!BB12 -> 3069.36 | AV12: ='[1]October - 2021'!BD12 -> 15261394 | AW12: ='[1]October - 2021'!BE12 -> 6236.16 | AX12: ='[1]October - 2021'!BE12 -> 6236.16 | AZ12: ='[1]October - 2021'!BK12 -> 66252300 | BA12: ='[1]October - 2021'!BL12 -> 37900 | BB12: ='[1]October - 2021'!BL12 -> 37900 | BC12: ='[1]October - 2021'!BN12 -> 68687400 | BD12: ='[1]October - 2021'!BO12 -> 52900 | BE12: ='[1]October - 2021'!BO12 -> 52900 | BF12: ='[1]October - 2021'!BQ12 -> 63303800 | BG12: ='[1]October - 2021'!BR12 -> 5900 | BH12: ='[1]October - 2021'!BR12 -> 5900 | BS12: ='[1]October - 2021'!BT12 -> 7239170 | BT12: ='[1]October - 2021'!BU12 -> 5940 | BV12: ='[1]October - 2021'!BW12 -> 0.78 | BW12: ='[1]October - 2021'!BX12 -> 0.04 | BX12: ='[1]October - 2021'!BX12 -> 0.04 | BY12: ='[1]October - 2021'!BZ12 -> 55771 | BZ12: ='[1]October - 2021'!CA12 -> 18 | CA12: ='[1]October - 2021'!CB12 -> 47307 | CB12: ='[1]October - 2021'!CC12 -> 17 | CC12: ='[1]October - 2021'!CD12 -> 16354 | CD12: ='[1]October - 2021'!CE12 -> 6 | CE12: ='[1]October - 2021'!CF12 -> 21368 | CF12: ='[1]October - 2021'!CG12 -> 9 | ... CL12: ='[1]October - 2021'!CM12 -> 93 | CM12: ='[1]October - 2021'!CM12 -> 93 | CN12: ='[1]October - 2021'!CO12 -> 173403 | CO12: ='[1]October - 2021'!CP12 -> 83 | CP12: ='[1]October - 2021'!CP12 -> 83 | CQ12: ='[1]October - 2021'!CR12 -> 308195 | CR12: ='[1]October - 2021'!CS12 -> 0 | CS12: ='[1]October - 2021'!CS12 -> 0 | CT12: ='[1]October - 2021'!CU12 -> 605216 | CU12: ='[1]October - 2021'!CV12 -> 192 | CW12: ='[1]October - 2021'!CX12 -> 5817 | CX12: ='[1]October - 2021'!CY12 -> 4 | CY12: ='[1]October - 2021'!CZ12 -> 3362 | CZ12: ='[1]October - 2021'!DA12 -> 5 | DA12: ='[1]October - 2021'!DB12 -> 25697 | DB12: ='[1]October - 2021'!DC12 -> 12 | DC12: ='[1]October - 2021'!DD12 -> 26421 | DD12: ='[1]October - 2021'!DE12 -> 18 | ... DR12: ='[1]October - 2021'!DS12 -> 0 | DT12: ='[1]October - 2021'!DU12 -> 2491.4 | DU12: ='[1]October - 2021'!DV12 -> 9.8 | DV12: ='[1]October - 2021'!DW12 -> 7697.8 | DW12: ='[1]October - 2021'!DX12 -> 8.4 | DX12: ='[1]October - 2021'!DY12 -> 1876.4 | DY12: ='[1]October - 2021'!DZ12 -> 7.5 | DZ12: ='[1]October - 2021'!EA12 -> 1837.1 | EA12: ='[1]October - 2021'!EB12 -> 11.4 | ... EC12: ='[1]October - 2021'!ED12 -> 704 | ED12: ='[1]October - 2021'!EG12 -> 166122.4 | EE12: ='[1]October - 2021'!EH12 -> 152.1 | EG12: ='[1]October - 2021'!EJ12 -> 10093700 | EH12: ='[1]October - 2021'!EK12 -> 4100 | EI12: ='[1]October - 2021'!EL12 -> 803710 | EJ12: ='[1]October - 2021'!EM12 -> 420 | EK12: ='[1]October - 2021'!EN12 -> 6250000 | EL12: ='[1]October - 2021'!EO12 -> 1900 | EM12: ='[1]October - 2021'!EP12 -> 2209300 | EN12: ='[1]October - 2021'!EQ12 -> 800 | ... ER12: ='[1]October - 2021'!EU12 -> 7000 | ET12: ='[1]October - 2021'!EW12 -> 36496 | EU12: ='[1]October - 2021'!EX12 -> 13 | EV12: ='[1]October - 2021'!EY12 -> 31551 | EW12: ='[1]October - 2021'!EZ12 -> 13 | EX12: ='[1]October - 2021'!FA12 -> 2674 | EY12: ='[1]October - 2021'!FB12 -> 12 | EZ12: ='[1]October - 2021'!FC12 -> 52925 | FA12: ='[1]October - 2021'!FD12 -> 17 | ... FC12: ='[1]October - 2021'!FF12 -> 30
