Workbook

Sheet TOTAL
A1: Site Name | B1: Day | C1: Month | D1: Year | E1: Total Electricity Kwh | F1: Electricity Tariff ($/Kwh) | G1: LPG (Kg) | H1: LPG $/Kg | I1: Water Utility Supply (m3) m3 | J1: Water Utility Supply (m3) $/m3 | K1: Room Nights | L1: Total Guests | M1: Utilities day cost dh
A2: Casablanca | B2: 1 | C2: 10 | D2: 2021 | E2: =submetering!E2+submetering!F2+submetering!G2 -> 15392 | F2: 1.05 | G2: ='Consommation mensuel énergie'!V10 -> 518.42 | H2: 9.965 | I2: ='Consommation mensuel énergie'!F10 -> 111 | J2: 11.4 | K2: ='Consommation mensuel énergie'!D10 -> 68 | L2: ='Consommation mensuel énergie'!E10 -> 110 | M2: =E2*F2+G2*H2+#REF!*#REF!+I2*J2 -> #REF!
A3: Casablanca | B3: =B2+1 -> 2 | C3: 10 | D3: 2021 | E3: =submetering!E3+submetering!F3+submetering!G3 -> 15612 | F3: 1.05 | G3: ='Consommation mensuel énergie'!V11 -> 333.27 | H3: 9.965 | I3: ='Consommation mensuel énergie'!F11 -> 100.1 | J3: 11.4 | K3: ='Consommation mensuel énergie'!D11 -> 72 | L3: ='Consommation mensuel énergie'!E11 -> 113 | M3: =E3*F3+G3*H3+#REF!*#REF!+I3*J3 -> #REF!
A4: Casablanca | B4: =B3+1 -> 3 | C4: 10 | D4: 2021 | E4: =submetering!E4+submetering!F4+submetering!G4 -> 15165 | F4: 1.05 | G4: ='Consommation mensuel énergie'!V12 -> 444.36 | H4: 9.965 | I4: ='Consommation mensuel énergie'!F12 -> 90.8 | J4: 11.4 | K4: ='Consommation mensuel énergie'!D12 -> 76 | L4: ='Consommation mensuel énergie'!E12 -> 107 | M4: =E4*F4+G4*H4+#REF!*#REF!+I4*J4 -> #REF!
A5: Casablanca | B5: =B4+1 -> 4 | C5: 10 | D5: 2021 | E5: =submetering!E5+submetering!F5+submetering!G5 -> 14387 | F5: 1.05 | G5: ='Consommation mensuel énergie'!V13 -> 556.5 | H5: 9.965 | I5: ='Consommation mensuel énergie'!F13 -> 95.1 | J5: 11.4 | K5: ='Consommation mensuel énergie'!D13 -> 99 | L5: ='Consommation mensuel énergie'!E13 -> 128 | M5: =E5*F5+G5*H5+#REF!*#REF!+I5*J5 -> #REF!
A6: Casablanca | B6: =B5+1 -> 5 | C6: 10 | D6: 2021 | E6: =submetering!E6+submetering!F6+submetering!G6 -> 15188 | F6: 1.05 | G6: ='Consommation mensuel énergie'!V14 -> 287.99289 | H6: 9.965 | I6: ='Consommation mensuel énergie'!F14 -> 97.5 | J6: 11.4 | K6: ='Consommation mensuel énergie'!D14 -> 94 | L6: ='Consommation mensuel énergie'!E14 -> 123 | M6: =E6*F6+G6*H6+#REF!*#REF!+I6*J6 -> #REF!
A7: Casablanca | B7: =B6+1 -> 6 | C7: 10 | D7: 2021 | E7: =submetering!E7+submetering!F7+submetering!G7 -> 15500 | F7: 1.05 | G7: ='Consommation mensuel énergie'!V15 -> 159.99605 | H7: 9.965 | I7: ='Consommation mensuel énergie'!F15 -> 130.8 | J7: 11.4 | K7: ='Consommation mensuel énergie'!D15 -> 96 | L7: ='Consommation mensuel énergie'!E15 -> 124 | M7: =E7*F7+G7*H7+#REF!*#REF!+I7*J7 -> #REF!
A8: Casablanca | B8: =B7+1 -> 7 | C8: 10 | D8: 2021 | E8: =submetering!E8+submetering!F8+submetering!G8 -> 15777 | F8: 1.05 | G8: ='Consommation mensuel énergie'!V16 -> 191.99526 | H8: 9.965 | I8: ='Consommation mensuel énergie'!F16 -> 134.4 | J8: 11.4 | K8: ='Consommation mensuel énergie'!D16 -> 80 | L8: ='Consommation mensuel énergie'!E16 -> 103 | M8: =E8*F8+G8*H8+#REF!*#REF!+I8*J8 -> #REF!
A9: Casablanca | B9: =B8+1 -> 8 | C9: 10 | D9: 2021 | E9: =submetering!E9+submetering!F9+submetering!G9 -> 15003 | F9: 1.05 | G9: ='Consommation mensuel énergie'!V17 -> 351.99131 | H9: 9.965 | I9: ='Consommation mensuel énergie'!F17 -> 126.5 | J9: 11.4 | K9: ='Consommation mensuel énergie'!D17 -> 138 | L9: ='Consommation mensuel énergie'!E17 -> 184 | M9: =E9*F9+G9*H9+#REF!*#REF!+I9*J9 -> #REF!
A10: Casablanca | B10: =B9+1 -> 9 | C10: 10 | D10: 2021 | E10: =submetering!E10+submetering!F10+submetering!G10 -> 15020 | F10: 1.05 | G10: ='Consommation mensuel énergie'!V19 -> 415.98973 | H10: 9.965 | I10: ='Consommation mensuel énergie'!F18 -> 108.6 | J10: 11.4 | K10: ='Consommation mensuel énergie'!D18 -> 133 | L10: ='Consommation mensuel énergie'!E18 -> 112 | M10: =E10*F10+G10*H10+#REF!*#REF!+I10*J10 -> #REF!
A11: Casablanca | B11: =B10+1 -> 10 | C11: 10 | D11: 2021 | E11: =submetering!E11+submetering!F11+submetering!G11 -> 16570 | F11: 1.05 | G11: ='Consommation mensuel énergie'!V20 -> 287.99289 | H11: 9.965 | I11: ='Consommation mensuel énergie'!F19 -> 147 | J11: 11.4 | K11: ='Consommation mensuel énergie'!D19 -> 59 | L11: ='Consommation mensuel énergie'!E19 -> 80 | M11: =E11*F11+G11*H11+#REF!*#REF!+I11*J11 -> #REF!
A12: Casablanca | B12: =B11+1 -> 11 | C12: 10 | D12: 2021 | E12: =submetering!E12+submetering!F12+submetering!G12 -> 13862 | F12: 1.05 | G12: ='Consommation mensuel énergie'!V21 -> 287.99289 | H12: 9.965 | I12: ='Consommation mensuel énergie'!F20 -> 97 | J12: 11.4 | K12: ='Consommation mensuel énergie'!D20 -> 69 | L12: ='Consommation mensuel énergie'!E20 -> 87 | M12: =E12*F12+G12*H12+#REF!*#REF!+I12*J12 -> #REF!
A13: Casablanca | B13: =B12+1 -> 12 | C13: 10 | D13: 2021 | E13: =submetering!E13+submetering!F13+submetering!G13 -> 14285 | F13: 1.05 | G13: ='Consommation mensuel énergie'!V22 -> 351.99131 | H13: 9.965 | I13: ='Consommation mensuel énergie'!F21 -> 85.8 | J13: 11.4 | K13: ='Consommation mensuel énergie'!D21 -> 77 | L13: ='Consommation mensuel énergie'!E21 -> 96 | M13: =E13*F13+G13*H13+#REF!*#REF!+I13*J13 -> #REF!
A14: Casablanca | B14: =B13+1 -> 13 | C14: 10 | D14: 2021 | E14: =submetering!E14+submetering!F14+submetering!G14 -> 16115 | F14: 1.05 | G14: ='Consommation mensuel énergie'!V23 -> 63.99842 | H14: 9.965 | I14: ='Consommation mensuel énergie'!F22 -> 95.3 | J14: 11.4 | K14: ='Consommation mensuel énergie'!D22 -> 68 | L14: ='Consommation mensuel énergie'!E22 -> 80 | M14: =E14*F14+G14*H14+#REF!*#REF!+I14*J14 -> #REF!
A15: Casablanca | B15: =B14+1 -> 14 | C15: 10 | D15: 2021 | E15: =submetering!E15+submetering!F15+submetering!G15 -> 14475 | F15: 1.05 | G15: ='Consommation mensuel énergie'!V24 -> 479.98815 | H15: 9.965 | I15: ='Consommation mensuel énergie'!F23 -> 108.6 | J15: 11.4 | K15: ='Consommation mensuel énergie'!D23 -> 70 | L15: ='Consommation mensuel énergie'!E23 -> 95 | M15: =E15*F15+G15*H15+#REF!*#REF!+I15*J15 -> #REF!
A16: Casablanca | B16: =B15+1 -> 15 | C16: 10 | D16: 2021 | E16: =submetering!E16+submetering!F16+submetering!G16 -> 15050 | F16: 1.05 | G16: ='Consommation mensuel énergie'!V25 -> 479.98815 | H16: 9.965 | I16: ='Consommation mensuel énergie'!F24 -> 108.1 | J16: 11.4 | K16: ='Consommation mensuel énergie'!D24 -> 69 | L16: ='Consommation mensuel énergie'!E24 -> 104 | M16: =E16*F16+G16*H16+#REF!*#REF!+I16*J16 -> #REF!
A17: Casablanca | B17: =B16+1 -> 16 | C17: 10 | D17: 2021 | E17: =submetering!E17+submetering!F17+submetering!G17 -> 14495 | F17: 1.05 | G17: ='Consommation mensuel énergie'!V26 -> 543.98657 | H17: 9.965 | I17: ='Consommation mensuel énergie'!F25 -> 88.5 | J17: 11.4 | K17: ='Consommation mensuel énergie'!D25 -> 89 | L17: ='Consommation mensuel énergie'!E25 -> 146 | M17: =E17*F17+G17*H17+#REF!*#REF!+I17*J17 -> #REF!
A18: Casablanca | B18: =B17+1 -> 17 | C18: 10 | D18: 2021 | E18: =submetering!E18+submetering!F18+submetering!G18 -> 14585 | F18: 1.05 | G18: ='Consommation mensuel énergie'!V27 -> 319.9921 | H18: 9.965 | I18: ='Consommation mensuel énergie'!F26 -> 110.7 | J18: 11.4 | K18: ='Consommation mensuel énergie'!D26 -> 77 | L18: ='Consommation mensuel énergie'!E26 -> 107 | M18: =E18*F18+G18*H18+#REF!*#REF!+I18*J18 -> #REF!
A19: Casablanca | B19: =B18+1 -> 18 | C19: 10 | D19: 2021 | E19: =submetering!E19+submetering!F19+submetering!G19 -> 13930 | F19: 1.05 | G19: ='Consommation mensuel énergie'!V28 -> 383.99052 | H19: 9.965 | I19: ='Consommation mensuel énergie'!F27 -> 118 | J19: 11.4 | K19: ='Consommation mensuel énergie'!D27 -> 121 | L19: ='Consommation mensuel énergie'!E27 -> 198 | M19: =E19*F19+G19*H19+#REF!*#REF!+I19*J19 -> #REF!
A20: Casablanca | B20: =B19+1 -> 19 | C20: 10 | D20: 2021 | E20: =submetering!E20+submetering!F20+submetering!G20 -> 15949 | F20: 1.05 | G20: ='Consommation mensuel énergie'!V29 -> 511.98736 | H20: 9.965 | I20: ='Consommation mensuel énergie'!F28 -> 81.6 | J20: 11.4 | K20: ='Consommation mensuel énergie'!D28 -> 87 | L20: ='Consommation mensuel énergie'!E28 -> 138 | M20: =E20*F20+G20*H20+#REF!*#REF!+I20*J20 -> #REF!
A21: Casablanca | B21: =B20+1 -> 20 | C21: 10 | D21: 2021 | E21: =submetering!E21+submetering!F21+submetering!G21 -> 13467 | F21: 1.05 | G21: ='Consommation mensuel énergie'!V30 -> 0 | H21: 9.965 | I21: ='Consommation mensuel énergie'!F29 -> 104.4 | J21: 11.4 | K21: ='Consommation mensuel énergie'!D29 -> 79 | L21: ='Consommation mensuel énergie'!E29 -> 120 | M21: =E21*F21+G21*H21+#REF!*#REF!+I21*J21 -> #REF!
... A26: Casablanca | B26: =B25+1 -> 25 | C26: 10 | D26: 2021 | E26: =submetering!E26+submetering!F26+submetering!G26 -> 13270 | F26: 1.05 | G26: ='Consommation mensuel énergie'!V35 -> 127.99684 | H26: 9.965 | I26: ='Consommation mensuel énergie'!F34 -> 101 | J26: 11.4 | K26: ='Consommation mensuel énergie'!D34 -> 94 | L26: ='Consommation mensuel énergie'!E34 -> 134 | M26: =E26*F26+G26*H26+#REF!*#REF!+I26*J26 -> #REF!
A27: Casablanca | B27: =B26+1 -> 26 | C27: 10 | D27: 2021 | E27: =submetering!E27+submetering!F27+submetering!G27 -> 12443 | F27: 1.05 | G27: ='Consommation mensuel énergie'!V36 -> 447.98894 | H27: 9.965 | I27: ='Consommation mensuel énergie'!F35 -> 91.9 | J27: 11.4 | K27: ='Consommation mensuel énergie'!D35 -> 94 | L27: ='Consommation mensuel énergie'!E35 -> 134
A28: Casablanca | B28: =B27+1 -> 27 | C28: 10 | D28: 2021 | E28: =submetering!E28+submetering!F28+submetering!G28 -> 16898 | F28: 1.05 | G28: ='Consommation mensuel énergie'!V37 -> 255.99368 | H28: 9.965 | I28: ='Consommation mensuel énergie'!F36 -> 100.4 | J28: 11.4 | K28: ='Consommation mensuel énergie'!D36 -> 94 | L28: ='Consommation mensuel énergie'!E36 -> 130
A29: Casablanca | B29: =B28+1 -> 28 | C29: 10 | D29: 2021 | E29: =submetering!E29+submetering!F29+submetering!G29 -> 14450 | F29: 1.05 | G29: ='Consommation mensuel énergie'!V38 -> 0 | H29: 9.965 | I29: ='Consommation mensuel énergie'!F37 -> 100.1 | J29: 11.4 | K29: ='Consommation mensuel énergie'!D37 -> 99 | L29: ='Consommation mensuel énergie'!E37 -> 145
A30: Casablanca | B30: =B29+1 -> 29 | C30: 10 | D30: 2021 | E30: =submetering!E30+submetering!F30+submetering!G30 -> 15853 | F30: 1.05 | G30: ='Consommation mensuel énergie'!V40 -> 0 | H30: 9.965 | I30: ='Consommation mensuel énergie'!F38 -> 111.7 | J30: 11.4 | K30: ='Consommation mensuel énergie'!D38 -> 98 | L30: ='Consommation mensuel énergie'!E38 -> 158 | M30: =E30*F30+G30*H30+#REF!*#REF!+I30*J30 -> #REF!
A31: Casablanca | B31: =B30+1 -> 30 | C31: 10 | D31: 2021 | E31: =submetering!E31+submetering!F31+submetering!G31 -> 13090 | F31: 1.05 | G31: ='Consommation mensuel énergie'!V41 -> 9820.3533 | H31: 9.965 | I31: ='Consommation mensuel énergie'!F39 -> 122.9 | J31: 11.4 | K31: ='Consommation mensuel énergie'!D39 -> 112 | L31: ='Consommation mensuel énergie'!E39 -> 190
A32: Casablanca | B32: =B31+1 -> 31 | C32: 10 | D32: 2021 | E32: =submetering!E32+submetering!F32+submetering!G32 -> 13692 | F32: 1.05 | G32: ='Consommation mensuel énergie'!V42 -> 0 | H32: 9.965 | I32: ='Consommation mensuel énergie'!F40 -> 119.4 | J32: 11.4 | K32: ='Consommation mensuel énergie'!D40 -> 91 | L32: ='Consommation mensuel énergie'!E40 -> 161

Sheet submetering
A1: Site Name | B1: Day | C1: Month | D1: Year | E1: Creuse 81 - KWh | F1: Pleine 82-KWh | G1: Pointe 83 - KWh | H1: Room Nights | I1: Total Guests | J1: Utilities day cost dh
A2: Casablanca | B2: 1 | C2: 10 | D2: 2021 | E2: ='Consommation mensuel énergie'!L10 -> 3908 | F2: ='Consommation mensuel énergie'!M10 -> 8144 | G2: ='Consommation mensuel énergie'!N10 -> 3340 | H2: ='Consommation mensuel énergie'!D10 -> 68 | I2: ='Consommation mensuel énergie'!E10 -> 110 | J2: =E2*F2+G2*#REF!+#REF!*#REF!+#REF!*#REF! -> #REF!
A3: Casablanca | B3: =B2+1 -> 2 | C3: 10 | D3: 2021 | E3: ='Consommation mensuel énergie'!L11 -> 4695 | F3: ='Consommation mensuel énergie'!M11 -> 7577 | G3: ='Consommation mensuel énergie'!N14 -> 3340 | H3: ='Consommation mensuel énergie'!D11 -> 72 | I3: ='Consommation mensuel énergie'!E11 -> 113 | J3: =E3*F3+G3*#REF!+#REF!*#REF!+#REF!*#REF! -> #REF!
A4: Casablanca | B4: =B3+1 -> 3 | C4: 10 | D4: 2021 | E4: ='Consommation mensuel énergie'!L12 -> 4359 | F4: ='Consommation mensuel énergie'!M12 -> 7444 | G4: ='Consommation mensuel énergie'!N12 -> 3362 | H4: ='Consommation mensuel énergie'!D12 -> 76 | I4: ='Consommation mensuel énergie'!E12 -> 107 | J4: =E4*F4+G4*#REF!+#REF!*#REF!+#REF!*#REF! -> #REF!
A5: Casablanca | B5: =B4+1 -> 4 | C5: 10 | D5: 2021 | E5: ='Consommation mensuel énergie'!L13 -> 3927 | F5: ='Consommation mensuel énergie'!M13 -> 7105 | G5: ='Consommation mensuel énergie'!N13 -> 3355 | H5: ='Consommation mensuel énergie'!D13 -> 99 | I5: ='Consommation mensuel énergie'!E13 -> 128 | J5: =E5*F5+G5*#REF!+#REF!*#REF!+#REF!*#REF! -> #REF!
A6: Casablanca | B6: =B5+1 -> 5 | C6: 10 | D6: 2021 | E6: ='Consommation mensuel énergie'!L14 -> 4144 | F6: ='Consommation mensuel énergie'!M14 -> 7704 | G6: ='Consommation mensuel énergie'!N14 -> 3340 | H6: ='Consommation mensuel énergie'!D14 -> 94 | I6: ='Consommation mensuel énergie'!E14 -> 123 | J6: =E6*F6+G6*#REF!+#REF!*#REF!+#REF!*#REF! -> #REF!
A7: Casablanca | B7: =B6+1 -> 6 | C7: 10 | D7: 2021 | E7: ='Consommation mensuel énergie'!L15 -> 4169 | F7: ='Consommation mensuel énergie'!M15 -> 8044 | G7: ='Consommation mensuel énergie'!N15 -> 3287 | H7: ='Consommation mensuel énergie'!D15 -> 96 | I7: ='Consommation mensuel énergie'!E15 -> 124 | J7: =E7*F7+G7*#REF!+#REF!*#REF!+#REF!*#REF! -> #REF!
A8: Casablanca | B8: =B7+1 -> 7 | C8: 10 | D8: 2021 | E8: ='Consommation mensuel énergie'!L16 -> 4218 | F8: ='Consommation mensuel énergie'!M16 -> 8066 | G8: ='Consommation mensuel énergie'!N16 -> 3493 | H8: ='Consommation mensuel énergie'!D16 -> 80 | I8: ='Consommation mensuel énergie'!E16 -> 103 | J8: =E8*F8+G8*#REF!+#REF!*#REF!+#REF!*#REF! -> #REF!
A9: Casablanca | B9: =B8+1 -> 8 | C9: 10 | D9: 2021 | E9: ='Consommation mensuel énergie'!L17 -> 4533 | F9: ='Consommation mensuel énergie'!M17 -> 7295 | G9: ='Consommation mensuel énergie'!N17 -> 3175 | H9: ='Consommation mensuel énergie'!D17 -> 138 | I9: ='Consommation mensuel énergie'!E17 -> 184 | J9: =E9*F9+G9*#REF!+#REF!*#REF!+#REF!*#REF! -> #REF!
A10: Casablanca | B10: =B9+1 -> 9 | C10: 10 | D10: 2021 | E10: ='Consommation mensuel énergie'!L18 -> 4108 | F10: ='Consommation mensuel énergie'!M18 -> 7379 | G10: ='Consommation mensuel énergie'!N18 -> 3533 | H10: ='Consommation mensuel énergie'!D18 -> 133 | I10: ='Consommation mensuel énergie'!E18 -> 112 | J10: =E10*F10+G10*#REF!+#REF!*#REF!+#REF!*#REF! -> #REF!
A11: Casablanca | B11: =B10+1 -> 10 | C11: 10 | D11: 2021 | E11: ='Consommation mensuel énergie'!L19 -> 4360 | F11: ='Consommation mensuel énergie'!M19 -> 8527 | G11: ='Consommation mensuel énergie'!N19 -> 3683 | H11: ='Consommation mensuel énergie'!D19 -> 59 | I11: ='Consommation mensuel énergie'!E19 -> 80 | J11: =E11*F11+G11*#REF!+#REF!*#REF!+#REF!*#REF! -> #REF!
A12: Casablanca | B12: =B11+1 -> 11 | C12: 10 | D12: 2021 | E12: ='Consommation mensuel énergie'!L20 -> 4131 | F12: ='Consommation mensuel énergie'!M20 -> 6943 | G12: ='Consommation mensuel énergie'!N20 -> 2788 | H12: ='Consommation mensuel énergie'!D20 -> 69 | I12: ='Consommation mensuel énergie'!E20 -> 87 | J12: =E12*F12+G12*#REF!+#REF!*#REF!+#REF!*#REF! -> #REF!
A13: Casablanca | B13: =B12+1 -> 12 | C13: 10 | D13: 2021 | E13: ='Consommation mensuel énergie'!L21 -> 4247 | F13: ='Consommation mensuel énergie'!M21 -> 6997 | G13: ='Consommation mensuel énergie'!N21 -> 3041 | H13: ='Consommation mensuel énergie'!D21 -> 77 | I13: ='Consommation mensuel énergie'!E21 -> 96 | J13: =E13*F13+G13*#REF!+#REF!*#REF!+#REF!*#REF! -> #REF!
A14: Casablanca | B14: =B13+1 -> 13 | C14: 10 | D14: 2021 | E14: ='Consommation mensuel énergie'!L22 -> 4560 | F14: ='Consommation mensuel énergie'!M22 -> 8313 | G14: ='Consommation mensuel énergie'!N22 -> 3242 | H14: ='Consommation mensuel énergie'!D22 -> 68 | I14: ='Consommation mensuel énergie'!E22 -> 80 | J14: =E14*F14+G14*#REF!+#REF!*#REF!+#REF!*#REF! -> #REF!
A15: Casablanca | B15: =B14+1 -> 14 | C15: 10 | D15: 2021 | E15: ='Consommation mensuel énergie'!L23 -> 4211 | F15: ='Consommation mensuel énergie'!M23 -> 7254 | G15: ='Consommation mensuel énergie'!N23 -> 3010 | H15: ='Consommation mensuel énergie'!D23 -> 70 | I15: ='Consommation mensuel énergie'!E23 -> 95 | J15: =E15*F15+G15*#REF!+#REF!*#REF!+#REF!*#REF! -> #REF!
... A26: Casablanca | B26: =B25+1 -> 25 | C26: 10 | D26: 2021 | E26: ='Consommation mensuel énergie'!L34 -> 4104 | F26: ='Consommation mensuel énergie'!M34 -> 6344 | G26: ='Consommation mensuel énergie'!N34 -> 2822 | H26: ='Consommation mensuel énergie'!D34 -> 94 | I26: ='Consommation mensuel énergie'!E34 -> 134 | J26: =E26*F26+G26*#REF!+#REF!*#REF!+#REF!*#REF! -> #REF!
A27: Casablanca | B27: =B26+1 -> 26 | C27: 10 | D27: 2021 | E27: ='Consommation mensuel énergie'!L35 -> 2861 | F27: ='Consommation mensuel énergie'!M35 -> 6663 | G27: ='Consommation mensuel énergie'!N35 -> 2919 | H27: ='Consommation mensuel énergie'!D35 -> 94 | I27: ='Consommation mensuel énergie'!E35 -> 134
A28: Casablanca | B28: =B27+1 -> 27 | C28: 10 | D28: 2021 | E28: ='Consommation mensuel énergie'!L36 -> 4256 | F28: ='Consommation mensuel énergie'!M36 -> 9087 | G28: ='Consommation mensuel énergie'!N36 -> 3555 | H28: ='Consommation mensuel énergie'!D36 -> 94 | I28: ='Consommation mensuel énergie'!E36 -> 130
A29: Casablanca | B29: =B28+1 -> 28 | C29: 10 | D29: 2021 | E29: ='Consommation mensuel énergie'!L37 -> 4080 | F29: ='Consommation mensuel énergie'!M37 -> 7395 | G29: ='Consommation mensuel énergie'!N37 -> 2975 | H29: ='Consommation mensuel énergie'!D37 -> 99 | I29: ='Consommation mensuel énergie'!E37 -> 145
A30: Casablanca | B30: =B29+1 -> 29 | C30: 10 | D30: 2021 | E30: ='Consommation mensuel énergie'!L38 -> 5080 | F30: ='Consommation mensuel énergie'!M38 -> 7821 | G30: ='Consommation mensuel énergie'!N38 -> 2952 | H30: ='Consommation mensuel énergie'!D38 -> 98 | I30: ='Consommation mensuel énergie'!E38 -> 158 | J30: =E30*F30+G30*#REF!+#REF!*#REF!+#REF!*#REF! -> #REF!
A31: Casablanca | B31: =B30+1 -> 30 | C31: 10 | D31: 2021 | E31: ='Consommation mensuel énergie'!L39 -> 3965 | F31: ='Consommation mensuel énergie'!M39 -> 6394 | G31: ='Consommation mensuel énergie'!N39 -> 2731 | H31: ='Consommation mensuel énergie'!D39 -> 112 | I31: ='Consommation mensuel énergie'!E39 -> 190
A32: Casablanca | B32: =B31+1 -> 31 | C32: 10 | D32: 2021 | E32: ='Consommation mensuel énergie'!L40 -> 3599 | F32: ='Consommation mensuel énergie'!M40 -> 6910 | G32: ='Consommation mensuel énergie'!N40 -> 3183 | H32: ='Consommation mensuel énergie'!D40 -> 91 | I32: ='Consommation mensuel énergie'!E40 -> 161

Sheet Consommation mensuel énergie
I2: Consommation mensuel Eau /électricité/Gaz
B8: Date | D8: ROOM Nights | E8: Guests | F8: Cons Eau/Hotel | H8: Consommation du jour en DH | K8: date / électr | L8: ELECTRICITE en KWH | O8: total | Q8: Consommation du jour en DH | S8: Cons Elec/Villa | U8: Cons Elec/RIAD | V8: GAZ en Kg | X8: Consommation du jour en DH
L9: creuse 81 | M9: pleine 82 | N9: pointe 83
B10: 44470 | D10: 68 | E10: 110 | F10: ='Suivi EAU-ELEC'!E9 -> 111 | H10: =F10*8.79 -> 975.69 | K10: 42278 | L10: ='Suivi EAU-ELEC'!G9 -> 3908 | M10: ='Suivi EAU-ELEC'!I9 -> 8144 | N10: ='Suivi EAU-ELEC'!K9 -> 3340 | O10: =L10+M10+N10 -> 15392 | Q10: =L10*0.6985+M10*0.9514+N10*1.3304 -> 14921.476 | V10: ='Suvi Gaz'!O4 -> 518.42 | X10: =V10*9.965 -> 5166.0553
B11: 44471 | D11: 72 | E11: 113 | F11: ='Suivi EAU-ELEC'!E10 -> 100.1 | H11: =F11*8.79 -> 879.879 | K11: 42279 | L11: ='Suivi EAU-ELEC'!G10 -> 4695 | M11: ='Suivi EAU-ELEC'!I10 -> 7577 | N11: ='Suivi EAU-ELEC'!K10 -> 3514 | O11: =L11+M11+N11 -> 15786 | Q11: =L11*0.6985+M11*0.9514+N14*1.3304 -> 14931.751 | V11: ='Suvi Gaz'!O5 -> 333.27 | X11: =V11*9.965 -> 3321.0356
B12: 44472 | D12: 76 | E12: 107 | F12: ='Suivi EAU-ELEC'!E11 -> 90.8 | H12: =F12*8.79 -> 798.132 | K12: 42280 | L12: ='Suivi EAU-ELEC'!G11 -> 4359 | M12: ='Suivi EAU-ELEC'!I11 -> 7444 | N12: ='Suivi EAU-ELEC'!K11 -> 3362 | O12: =L12+M12+N12 -> 15165 | Q12: =L12*0.6985+M12*0.9514+N12*1.3304 -> 14599.788 | V12: ='Suvi Gaz'!O6 -> 444.36 | X12: =V12*9.965 -> 4428.0474
B13: 44473 | D13: 99 | E13: 128 | F13: ='Suivi EAU-ELEC'!E12 -> 95.1 | H13: =F13*8.79 -> 835.929 | K13: 42281 | L13: ='Suivi EAU-ELEC'!G12 -> 3927 | M13: ='Suivi EAU-ELEC'!I12 -> 7105 | N13: ='Suivi EAU-ELEC'!K12 -> 3355 | O13: =L13+M13+N13 -> 14387 | Q13: =L13*0.6985+M13*0.9514+N13*1.3304 -> 13966.199 | V13: ='Suvi Gaz'!O7 -> 556.5 | X13: =V13*9.965 -> 5545.5225
B14: 44474 | D14: 94 | E14: 123 | F14: ='Suivi EAU-ELEC'!E13 -> 97.5 | H14: =F14*8.79 -> 857.025 | K14: 42282 | L14: ='Suivi EAU-ELEC'!G13 -> 4144 | M14: ='Suivi EAU-ELEC'!I13 -> 7704 | N14: ='Suivi EAU-ELEC'!K13 -> 3340 | O14: =L14+M14+N14 -> 15188 | Q14: =L14*0.6985+M14*0.9514+N14*1.3304 -> 14667.706 | V14: ='Suvi Gaz'!O8 -> 287.99289 | X14: =V14*9.965 -> 2869.8491
B15: 44475 | D15: 96 | E15: 124 | F15: ='Suivi EAU-ELEC'!E14 -> 130.8 | H15: =F15*8.79 -> 1149.732 | K15: 42283 | L15: ='Suivi EAU-ELEC'!G14 -> 4169 | M15: ='Suivi EAU-ELEC'!I14 -> 8044 | N15: ='Suivi EAU-ELEC'!K14 -> 3287 | O15: =L15+M15+N15 -> 15500 | Q15: =L15*0.6985+M15*0.9514+N15*1.3304 -> 14938.133 | V15: ='Suvi Gaz'!O9 -> 159.99605 | X15: =V15*9.965 -> 1594.3606
B16: 44476 | D16: 80 | E16: 103 | F16: ='Suivi EAU-ELEC'!E15 -> 134.4 | H16: =F16*8.79 -> 1181.376 | K16: 42284 | L16: ='Suivi EAU-ELEC'!G15 -> 4218 | M16: ='Suivi EAU-ELEC'!I15 -> 8066 | N16: ='Suivi EAU-ELEC'!K15 -> 3493 | O16: =L16+M16+N16 -> 15777 | Q16: =L16*0.6985+M16*0.9514+N16*1.3304 -> 15267.353 | V16: ='Suvi Gaz'!O10 -> 191.99526 | X16: =V16*9.965 -> 1913.2328
B17: 44477 | D17: 138 | E17: 184 | F17: ='Suivi EAU-ELEC'!E16 -> 126.5 | H17: =F17*8.79 -> 1111.935 | K17: 42285 | L17: ='Suivi EAU-ELEC'!G16 -> 4533 | M17: ='Suivi EAU-ELEC'!I16 -> 7295 | N17: ='Suivi EAU-ELEC'!K16 -> 3175 | O17: =L17+M17+N17 -> 15003 | Q17: =L17*0.6985+M17*0.9514+N17*1.3304 -> 14330.783 | V17: ='Suvi Gaz'!O11 -> 351.99131 | X17: =V17*9.965 -> 3507.5934
B18: 44478 | D18: 133 | E18: 112 | F18: ='Suivi EAU-ELEC'!E17 -> 108.6 | H18: =F18*8.79 -> 954.594 | K18: 42286 | L18: ='Suivi EAU-ELEC'!G17 -> 4108 | M18: ='Suivi EAU-ELEC'!I17 -> 7379 | N18: ='Suivi EAU-ELEC'!K17 -> 3533 | O18: =L18+M18+N18 -> 15020 | Q18: =L18*0.6985+M18*0.9514+N18*1.3304 -> 14590.122 | V18: ='Suvi Gaz'!O12 -> 191.99526 | X18: =V18*9.965 -> 1913.2328
B19: 44479 | D19: 59 | E19: 80 | F19: ='Suivi EAU-ELEC'!E18 -> 147 | H19: =F19*8.79 -> 1292.13 | K19: 42287 | L19: ='Suivi EAU-ELEC'!G18 -> 4360 | M19: ='Suivi EAU-ELEC'!I18 -> 8527 | N19: ='Suivi EAU-ELEC'!K18 -> 3683 | O19: =L19+M19+N19 -> 16570 | Q19: =L19*0.6985+M19*0.9514+N19*1.3304 -> 16057.911 | V19: ='Suvi Gaz'!O13 -> 415.98973 | X19: =V19*9.965 -> 4145.3377
B20: 44480 | D20: 69 | E20: 87 | F20: ='Suivi EAU-ELEC'!E19 -> 97 | H20: =F20*8.79 -> 852.63 | K20: 42288 | L20: ='Suivi EAU-ELEC'!G19 -> 4131 | M20: ='Suivi EAU-ELEC'!I19 -> 6943 | N20: ='Suivi EAU-ELEC'!K19 -> 2788 | O20: =L20+M20+N20 -> 13862 | Q20: =L20*0.6985+M20*0.9514+N20*1.3304 -> 13200.229 | V20: ='Suvi Gaz'!O14 -> 287.99289 | X20: =V20*9.965 -> 2869.8491
B21: 44481 | D21: 77 | E21: 96 | F21: ='Suivi EAU-ELEC'!E20 -> 85.8 | H21: =F21*8.79 -> 754.182 | K21: 42289 | L21: ='Suivi EAU-ELEC'!G20 -> 4247 | M21: ='Suivi EAU-ELEC'!I20 -> 6997 | N21: ='Suivi EAU-ELEC'!K20 -> 3041 | O21: =L21+M21+N21 -> 14285 | Q21: =L21*0.6985+M21*0.9514+N21*1.3304 -> 13669.222 | V21: ='Suvi Gaz'!O15 -> 287.99289 | X21: =V21*9.965 -> 2869.8491
B22: 44482 | D22: 68 | E22: 80 | F22: ='Suivi EAU-ELEC'!E21 -> 95.3 | H22: =F22*8.79 -> 837.687 | K22: 42290 | L22: ='Suivi EAU-ELEC'!G21 -> 4560 | M22: ='Suivi EAU-ELEC'!I21 -> 8313 | N22: ='Suivi EAU-ELEC'!K21 -> 3242 | O22: =L22+M22+N22 -> 16115 | Q22: =L22*0.6985+M22*0.9514+N22*1.3304 -> 15407.305 | V22: ='Suvi Gaz'!O16 -> 351.99131 | X22: =V22*9.965 -> 3507.5934
B23: 44483 | D23: 70 | E23: 95 | F23: ='Suivi EAU-ELEC'!E22 -> 108.6 | H23: =F23*8.79 -> 954.594 | K23: 42291 | L23: ='Suivi EAU-ELEC'!G22 -> 4211 | M23: ='Suivi EAU-ELEC'!I22 -> 7254 | N23: ='Suivi EAU-ELEC'!K22 -> 3010 | O23: =L23+M23+N23 -> 14475 | Q23: =L23*0.6985+M23*0.9514+N23*1.3304 -> 13847.343 | V23: ='Suvi Gaz'!O17 -> 63.99842 | X23: =V23*9.965 -> 637.74426
... B36: 44496 | D36: 94 | E36: 130 | F36: ='Suivi EAU-ELEC'!E35 -> 100.4 | H36: =F36*8.79 -> 882.516 | K36: 42304 | L36: ='Suivi EAU-ELEC'!G35 -> 4256 | M36: ='Suivi EAU-ELEC'!I35 -> 9087 | N36: ='Suivi EAU-ELEC'!K35 -> 3555 | O36: =L36+M36+N36 -> 16898 | Q36: =L36*0.6985+M36*0.9514+N36*1.3304 -> 16347.76 | V36: ='Suvi Gaz'!O30 -> 447.98894 | X36: =V36*9.965 -> 4464.2098
B37: 44497 | D37: 99 | E37: 145 | F37: ='Suivi EAU-ELEC'!E36 -> 100.1 | H37: =F37*8.79 -> 879.879 | L37: ='Suivi EAU-ELEC'!G36 -> 4080 | M37: ='Suivi EAU-ELEC'!I36 -> 7395 | N37: ='Suivi EAU-ELEC'!K36 -> 2975 | O37: =L37+M37+N37 -> 14450 | Q37: =L37*0.6985+M37*0.9514+N37*1.3304 -> 13843.423 | V37: ='Suvi Gaz'!O31 -> 255.99368 | X37: =V37*9.965 -> 2550.977
B38: 44498 | D38: 98 | E38: 158 | F38: ='Suivi EAU-ELEC'!E37 -> 111.7 | H38: =F38*8.79 -> 981.843 | L38: ='Suivi EAU-ELEC'!G37 -> 5080 | M38: ='Suivi EAU-ELEC'!I37 -> 7821 | N38: ='Suivi EAU-ELEC'!K37 -> 2952 | O38: =L38+M38+N38 -> 15853 | Q38: =L38*0.6985+M38*0.9514+N38*1.3304 -> 14916.62 | X38: =V38*9.965 -> 0
B39: 44499 | D39: 112 | E39: 190 | F39: ='Suivi EAU-ELEC'!E38 -> 122.9 | H39: =F39*8.79 -> 1080.291 | L39: ='Suivi EAU-ELEC'!G38 -> 3965 | M39: ='Suivi EAU-ELEC'!I38 -> 6394 | N39: ='Suivi EAU-ELEC'!K38 -> 2731 | O39: =L39+M39+N39 -> 13090 | Q39: =L39*0.6985+M39*0.9514+N39*1.3304 -> 12486.127 | X39: =V39*9.965 -> 0
B40: 44500 | D40: 91 | E40: 161 | F40: ='Suivi EAU-ELEC'!E39 -> 119.4 | H40: =F40*8.79 -> 1049.526 | L40: ='Suivi EAU-ELEC'!G39 -> 3599 | M40: ='Suivi EAU-ELEC'!I39 -> 6910 | N40: ='Suivi EAU-ELEC'!K39 -> 3183 | O40: =L40+M40+N40 -> 13692 | Q40: =L40*0.6985+M40*0.9514+N40*1.3304 -> 13322.739 | X40: =V40*9.965 -> 0
D41: =SUM(D10:D40) -> 2768 | E41: =SUM(E10:E40) -> 3988 | F41: =SUM(F10:F40) -> 3330.2 | H41: =SUM(H10:H40) -> 29272.458 | L41: =SUM(L10:L40) -> 130171 | M41: =SUM(M10:M40) -> 227807 | N41: =SUM(N10:N40) -> 98925 | O41: =SUM(O10:O40) -> 456903 | Q41: =SUM(Q10:Q40) -> 439038.35 | S41: =SUM(S10:S40) -> 0 | U41: =SUM(U10:U40) -> 0 | V41: =SUM(V10:V40) -> 9820.3533 | X41: =SUM(X10:X40) -> 97859.821
A43: Désignation | H43: COUTS | I43: Consommations | L43: Consommations /DHs | N43: TOTAL Consommations /DHs
A44: ELECTRICITE / Kw/h | D44: creuse 81 | E44: creuse 81 | F44: creuse 81 | H44: 0.6985 | I44: =L41 -> 130171 | L44: =I44*H44 -> 90924.444 | N44: =L44+L45+L46 -> 439269.84
D45: pleine 82 | E45: pleine 82 | F45: pleine 82 | H45: 0.9514 | I45: =M41 -> 227807 | L45: =I45*H45 -> 216735.58
D46: pointe 83 | E46: pointe 83 | F46: pointe 83 | H46: 1.3304 | I46: =N41 -> 98925 | L46: =I46*H46 -> 131609.82
N47: =N44*1.3 -> 571050.8
A48: EAU HOTEL M3 | H48: 8.79 | I48: =F41 -> 3330.2 | L48: =I48*H48 -> 29272.458 | N48: =L48 -> 29272.458
A49: GAZ Kg | H49: 9.965 | I49: =V41 -> 9820.3533 | L49: =I49*H49 -> 97859.821 | N49: =L49 -> 97859.821

Sheet Suivi EAU-ELEC
E1: Suivi Compteur d'Eau- électricité Lydec- Oct 2021 | J1: Département Engineering 2021
A7: Date/électriqie | B7: Incendie | D7: Eau m3 | F7: Electricité Kw/h
B8: Compteur | C8: Consommation | D8: Compteur | E8: Consommation | F8: Compteur H.Creuse | G8: Consommation H.Creuse | H8: Compteur H.Pleine | I8: Consommation H.Pleine | J8: Compteur H.Pointe | K8: Consommation H.Pointe
A9: 44470 | B9: 2560 | C9: 0 | D9: 124345.2 | E9: 111 | F9: 11040400 | G9: 3908 | H9: 18812100 | I9: 8144 | J9: 8253129 | K9: 3340
A10: 44471 | B10: 2560 | C10: =B10-B9 -> 0 | D10: 124445.3 | E10: =D10-D9 -> 100.1 | F10: 11045095 | G10: =F10-F9 -> 4695 | H10: 18819677 | I10: =H10-H9 -> 7577 | J10: 8256643 | K10: =J10-J9 -> 3514
A11: 44472 | B11: 2560 | C11: 0 | D11: 124536.1 | E11: =D11-D10 -> 90.8 | F11: 11049454 | G11: =F11-F10 -> 4359 | H11: 18827121 | I11: =H11-H10 -> 7444 | J11: 8260005 | K11: =J11-J10 -> 3362
A12: 44473 | B12: 2560 | C12: 0 | D12: 124631.2 | E12: =D12-D11 -> 95.1 | F12: 11053381 | G12: =F12-F11 -> 3927 | H12: 18834226 | I12: =H12-H11 -> 7105 | J12: 8263360 | K12: =J12-J11 -> 3355
A13: 44474 | B13: 2560 | C13: 0 | D13: 124728.7 | E13: =D13-D12 -> 97.5 | F13: 11057525 | G13: =F13-F12 -> 4144 | H13: 18841930 | I13: =H13-H12 -> 7704 | J13: 8266700 | K13: =J13-J12 -> 3340
A14: 44475 | B14: 2560 | C14: 0 | D14: 124859.5 | E14: =D14-D13 -> 130.8 | F14: 11061694 | G14: =F14-F13 -> 4169 | H14: 18849974 | I14: =H14-H13 -> 8044 | J14: 8269987 | K14: =J14-J13 -> 3287
A15: 44476 | B15: 2560 | C15: 0 | D15: 124993.9 | E15: =D15-D14 -> 134.4 | F15: 11065912 | G15: =F15-F14 -> 4218 | H15: 18858040 | I15: =H15-H14 -> 8066 | J15: 8273480 | K15: =J15-J14 -> 3493
A16: 44477 | B16: 2560 | C16: 0 | D16: 125120.4 | E16: =D16-D15 -> 126.5 | F16: 11070445 | G16: =F16-F15 -> 4533 | H16: 18865335 | I16: =H16-H15 -> 7295 | J16: 8276655 | K16: =J16-J15 -> 3175
A17: 44478 | B17: 2560 | C17: 0 | D17: 125229 | E17: =D17-D16 -> 108.6 | F17: 11074553 | G17: =F17-F16 -> 4108 | H17: 18872714 | I17: =H17-H16 -> 7379 | J17: 8280188 | K17: =J17-J16 -> 3533
A18: 44479 | B18: 2560 | C18: 0 | D18: 125376 | E18: =D18-D17 -> 147 | F18: 11078913 | G18: =F18-F17 -> 4360 | H18: 18881241 | I18: =H18-H17 -> 8527 | J18: 8283871 | K18: =J18-J17 -> 3683
A19: 44480 | B19: 2560 | C19: 0 | D19: 125473 | E19: =D19-D18 -> 97 | F19: 11083044 | G19: =F19-F18 -> 4131 | H19: 18888184 | I19: =H19-H18 -> 6943 | J19: 8286659 | K19: =J19-J18 -> 2788
A20: 44481 | B20: 2560 | C20: 0 | D20: 125558.8 | E20: =D20-D19 -> 85.8 | F20: 11087291 | G20: =F20-F19 -> 4247 | H20: 18895181 | I20: =H20-H19 -> 6997 | J20: 8289700 | K20: =J20-J19 -> 3041
A21: 44482 | B21: 2560 | C21: 0 | D21: 125654.1 | E21: =D21-D20 -> 95.3 | F21: 11091851 | G21: =F21-F20 -> 4560 | H21: 18903494 | I21: =H21-H20 -> 8313 | J21: 8292942 | K21: =J21-J20 -> 3242
A22: 44483 | B22: 2560 | C22: 0 | D22: 125762.7 | E22: =D22-D21 -> 108.6 | F22: 11096062 | G22: =F22-F21 -> 4211 | H22: 18910748 | I22: =H22-H21 -> 7254 | J22: 8295952 | K22: =J22-J21 -> 3010
... A38: 44499 | B38: 2560 | C38: 0 | D38: 127445 | E38: =D38-D37 -> 122.9 | F38: 11163064 | G38: =F38-F37 -> 3965 | H38: 19024853 | I38: =H38-H37 -> 6394 | J38: 8345531 | K38: =J38-J37 -> 2731
A39: 44500 | B39: 2560 | C39: =B39-B38 -> 0 | D39: 127564.4 | E39: =D39-D38 -> 119.4 | F39: 11166663 | G39: =F39-F38 -> 3599 | H39: 19031763 | I39: =H39-H38 -> 6910 | J39: 8348714 | K39: =J39-J38 -> 3183
A40: 44501 | B40: 2560 | C40: =B40-B39 -> 0 | D40: 127675.7 | E40: =D40-D39 -> 111.3 | F40: 11170397 | G40: =F40-F39 -> 3734 | H40: 19038198 | I40: =H40-H39 -> 6435 | J40: 8351548 | K40: =J40-J39 -> 2834

Sheet Suvi Gaz
F1: suivi Gaz Oct 2021
Q2: 803 | T2: 519 | W2: 800 | Z2: 802
B3: Relvé C1 | C3: cons C1 | D3: Relvé C2 | E3: cons C2 | F3: Relvé C3 | G3: cons C3 | H3: Relvé C4 | I3: cons C4 | J3: ∑ des relevés | K3: moyen general % | L3: con.j | M3: ∑ de volume en L | N3: cons./jen L | O3: cons./jen Kg | P3: cons./jen DH | Q3: livraison C1 | R3: %Avant | S3: % Après | T3: livraison C2 | U3: %Avant | V3: % Après | W3: livraison C3 | X3: %Avant | Y3: % Après | Z3: livraison C4 | AA3: %Avant | AB3: % Après | AC3: total livraison litre | AD3: moyen general % Avant L | AE3: moyen general % Aaprés L
A4: 44470 | B4: 68 | C4: 0 | D4: 70 | E4: 0 | F4: 70 | G4: 0 | H4: 70 | I4: =IF(AC4>0,((H4-AA4)+(AB4-H5)),IF(H5=0, ,(H4-H5))) -> 4 | J4: =B4+D4+F4+H4 -> 278 | K4: =J4/4 -> 69.5 | L4: =IF(AC4>0,((K4-AD4)+(AE4-K5)),IF(K5=0, ,(K4-K5))) -> 3.5 | M4: =7000*4 -> 28000 | N4: =L4*M4/100 -> 980 | O4: =N4*0.529 -> 518.42 | P4: =O4*9.965 -> 5166.0553 | AC4: =Q4+T4+W4+Z4 -> 0 | AD4: =(R4+U4+X4+AA4)/4 -> 0 | AE4: =(S4+V4+Y4+AB4)/4 -> 0
A5: 44471 | B5: 65 | C5: =IF(AC5>0,((B5-R5)+(S5-B6)),IF(B6=0, ,(B5-B6))) -> 2 | D5: 65 | E5: =IF(AC5>0,((D5-U5)+(V5-D6)),IF(D6=0, ,(D5-D6))) -> 2 | F5: 68 | G5: =IF(AC5>0,((F5-X5)+(Y5-F6)),IF(F6=0, ,(F5-F6))) -> 4 | H5: 66 | I5: =IF(AC5>0,((H5-AA5)+(AB5-H6)),IF(H6=0, ,(H5-H6))) -> 1 | J5: =B5+D5+F5+H5 -> 264 | K5: =J5/4 -> 66 | L5: =IF(AC5>0,((K5-AD5)+(AE5-K6)),IF(K6=0, ,(K5-K6))) -> 2.25 | M5: =7000*4 -> 28000 | N5: =L5*M5/100 -> 630 | O5: =N5*0.529 -> 333.27 | P5: =O5*9.965 -> 3321.0356 | AC5: =Q5+T5+W5+Z5 -> 0 | AD5: =(R5+U5+X5+AA5)/4 -> 0 | AE5: =(S5+V5+Y5+AB5)/4 -> 0
A6: 44472 | B6: 63 | C6: =IF(AC6>0,((B6-R6)+(S6-B7)),IF(B7=0, ,(B6-B7))) -> 3 | D6: 63 | E6: =IF(AC6>0,((D6-U6)+(V6-D7)),IF(D7=0, ,(D6-D7))) -> 3 | F6: 64 | G6: =IF(AC6>0,((F6-X6)+(Y6-F7)),IF(F7=0, ,(F6-F7))) -> 2 | H6: 65 | I6: =IF(AC6>0,((H6-AA6)+(AB6-H7)),IF(H7=0, ,(H6-H7))) -> 4 | J6: =B6+D6+F6+H6 -> 255 | K6: =J6/4 -> 63.75 | L6: =IF(AC6>0,((K6-AD6)+(AE6-K7)),IF(K7=0, ,(K6-K7))) -> 3 | M6: =7000*4 -> 28000 | N6: =L6*M6/100 -> 840 | O6: =N6*0.529 -> 444.36 | P6: =O6*9.965 -> 4428.0474 | AC6: =Q6+T6+W6+Z6 -> 0 | AD6: =(R6+U6+X6+AA6)/4 -> 0 | AE6: =(S6+V6+Y6+AB6)/4 -> 0
A7: 44473 | B7: 60 | C7: =IF(AC7>0,((B7-R7)+(S7-B8)),IF(B8=0, ,(B7-B8))) -> 6 | D7: 60 | E7: =IF(AC7>0,((D7-U7)+(V7-D8)),IF(D8=0, ,(D7-D8))) -> 4 | F7: 62 | G7: =IF(AC7>0,((F7-X7)+(Y7-F8)),IF(F8=0, ,(F7-F8))) -> 3 | H7: 61 | I7: =IF(AC7>0,((H7-AA7)+(AB7-H8)),IF(H8=0, ,(H7-H8))) -> 2 | J7: =B7+D7+F7+H7 -> 243 | K7: =J7/4 -> 60.75 | L7: =IF(AC7>0,((K7-AD7)+(AE7-K8)),IF(K8=0, ,(K7-K8))) -> 3.75 | M7: =7000*4 -> 28000 | N7: =L7*M7/100 -> 1050 | O7: =N7*0.53 -> 556.5 | P7: =O7*9.965 -> 5545.5225 | AC7: =Q7+T7+W7+Z7 -> 0 | AD7: =(R7+U7+X7+AA7)/4 -> 0 | AE7: =(S7+V7+Y7+AB7)/4 -> 0
A8: 44474 | B8: 54 | C8: =IF(AC8>0,((B8-R8)+(S8-B9)),IF(B9=0, ,(B8-B9))) -> 0 | D8: 56 | E8: =IF(AC8>0,((D8-U8)+(V8-D9)),IF(D9=0, ,(D8-D9))) -> 3 | F8: 59 | G8: =IF(AC8>0,((F8-X8)+(Y8-F9)),IF(F9=0, ,(F8-F9))) -> 3 | H8: 59 | I8: =IF(AC8>0,((H8-AA8)+(AB8-H9)),IF(H9=0, ,(H8-H9))) -> 3 | J8: =B8+D8+F8+H8 -> 228 | K8: =J8/4 -> 57 | L8: =IF(AC8>0,((K8-AD8)+(AE8-K9)),IF(K9=0, ,(K8-K9))) -> 2.25 | M8: =6049*4 -> 24196 | N8: =L8*M8/100 -> 544.41 | O8: =N8*0.529 -> 287.99289 | P8: =O8*9.965 -> 2869.8491 | AC8: =Q8+T8+W8+Z8 -> 0 | AD8: =(R8+U8+X8+AA8)/4 -> 0 | AE8: =(S8+V8+Y8+AB8)/4 -> 0
A9: 44475 | B9: 54 | C9: =IF(AC9>0,((B9-R9)+(S9-B10)),IF(B10=0, ,(B9-B10))) -> 1 | D9: 53 | E9: =IF(AC9>0,((D9-U9)+(V9-D10)),IF(D10=0, ,(D9-D10))) -> 1 | F9: 56 | G9: =IF(AC9>0,((F9-X9)+(Y9-F10)),IF(F10=0, ,(F9-F10))) -> 1 | H9: 56 | I9: =IF(AC9>0,((H9-AA9)+(AB9-H10)),IF(H10=0, ,(H9-H10))) -> 2 | J9: =B9+D9+F9+H9 -> 219 | K9: =J9/4 -> 54.75 | L9: =IF(AC9>0,((K9-AD9)+(AE9-K10)),IF(K10=0, ,(K9-K10))) -> 1.25 | M9: =6049*4 -> 24196 | N9: =L9*M9/100 -> 302.45 | O9: =N9*0.529 -> 159.99605 | P9: =O9*9.965 -> 1594.3606 | Q9: 2328 | R9: 53 | S9: 85 | T9: 2450 | U9: 52 | V9: 85 | W9: 2300 | X9: 55 | Y9: 85 | Z9: 2200 | AA9: 54 | AB9: 85 | AC9: =Q9+T9+W9+Z9 -> 9278 | AD9: =(R9+U9+X9+AA9)/4 -> 53.5 | AE9: =(S9+V9+Y9+AB9)/4 -> 85
A10: 44476 | B10: 85 | C10: =IF(AC10>0,((B10-R10)+(S10-B11)),IF(B11=0, ,(B10-B11))) -> 0 | D10: 85 | E10: =IF(AC10>0,((D10-U10)+(V10-D11)),IF(D11=0, ,(D10-D11))) -> 2 | F10: 85 | G10: =IF(AC10>0,((F10-X10)+(Y10-F11)),IF(F11=0, ,(F10-F11))) -> 1 | H10: 85 | I10: =IF(AC10>0,((H10-AA10)+(AB10-H11)),IF(H11=0, ,(H10-H11))) -> 3 | J10: =B10+D10+F10+H10 -> 340 | K10: =J10/4 -> 85 | L10: =IF(AC10>0,((K10-AD10)+(AE10-K11)),IF(K11=0, ,(K10-K11))) -> 1.5 | M10: =6049*4 -> 24196 | N10: =L10*M10/100 -> 362.94 | O10: =N10*0.529 -> 191.99526 | P10: =O10*9.965 -> 1913.2328 | AC10: =Q10+T10+W10+Z10 -> 0 | AD10: =(R10+U10+X10+AA10)/4 -> 0 | AE10: =(S10+V10+Y10+AB10)/4 -> 0
A11: 44477 | B11: 85 | C11: =IF(AC11>0,((B11-R11)+(S11-B12)),IF(B12=0, ,(B11-B12))) -> 5 | D11: 83 | E11: =IF(AC11>0,((D11-U11)+(V11-D12)),IF(D12=0, ,(D11-D12))) -> 2 | F11: 84 | G11: =IF(AC11>0,((F11-X11)+(Y11-F12)),IF(F12=0, ,(F11-F12))) -> 2 | H11: 82 | I11: =IF(AC11>0,((H11-AA11)+(AB11-H12)),IF(H12=0, ,(H11-H12))) -> 2 | J11: =B11+D11+F11+H11 -> 334 | K11: =J11/4 -> 83.5 | L11: =IF(AC11>0,((K11-AD11)+(AE11-K12)),IF(K12=0, ,(K11-K12))) -> 2.75 | M11: =6049*4 -> 24196 | N11: =L11*M11/100 -> 665.39 | O11: =N11*0.529 -> 351.99131 | P11: =O11*9.965 -> 3507.5934 | AC11: =Q11+T11+W11+Z11 -> 0 | AD11: =(R11+U11+X11+AA11)/4 -> 0 | AE11: =(S11+V11+Y11+AB11)/4 -> 0
A12: 44478 | B12: 80 | C12: =IF(AC12>0,((B12-R12)+(S12-B13)),IF(B13=0, ,(B12-B13))) -> 1 | D12: 81 | E12: =IF(AC12>0,((D12-U12)+(V12-D13)),IF(D13=0, ,(D12-D13))) -> 1 | F12: 82 | G12: =IF(AC12>0,((F12-X12)+(Y12-F13)),IF(F13=0, ,(F12-F13))) -> 2 | H12: 80 | I12: =IF(AC12>0,((H12-AA12)+(AB12-H13)),IF(H13=0, ,(H12-H13))) -> 2 | J12: =B12+D12+F12+H12 -> 323 | K12: =J12/4 -> 80.75 | L12: =IF(AC12>0,((K12-AD12)+(AE12-K13)),IF(K13=0, ,(K12-K13))) -> 1.5 | M12: =6049*4 -> 24196 | N12: =L12*M12/100 -> 362.94 | O12: =N12*0.529 -> 191.99526 | P12: =O12*9.965 -> 1913.2328 | AC12: =Q12+T12+W12+Z12 -> 0 | AD12: =(R12+U12+X12+AA12)/4 -> 0 | AE12: =(S12+V12+Y12+AB12)/4 -> 0
A13: 44479 | B13: 79 | C13: =IF(AC13>0,((B13-R13)+(S13-B14)),IF(B14=0, ,(B13-B14))) -> 4 | D13: 80 | E13: =IF(AC13>0,((D13-U13)+(V13-D14)),IF(D14=0, ,(D13-D14))) -> 3 | F13: 80 | G13: =IF(AC13>0,((F13-X13)+(Y13-F14)),IF(F14=0, ,(F13-F14))) -> 3 | H13: 78 | I13: =IF(AC13>0,((H13-AA13)+(AB13-H14)),IF(H14=0, ,(H13-H14))) -> 3 | J13: =B13+D13+F13+H13 -> 317 | K13: =J13/4 -> 79.25 | L13: =IF(AC13>0,((K13-AD13)+(AE13-K14)),IF(K14=0, ,(K13-K14))) -> 3.25 | M13: =6049*4 -> 24196 | N13: =L13*M13/100 -> 786.37 | O13: =N13*0.529 -> 415.98973 | P13: =O13*9.965 -> 4145.3377 | AC13: =Q13+T13+W13+Z13 -> 0 | AD13: =(R13+U13+X13+AA13)/4 -> 0 | AE13: =(S13+V13+Y13+AB13)/4 -> 0
A14: 44480 | B14: 75 | C14: =IF(AC14>0,((B14-R14)+(S14-B15)),IF(B15=0, ,(B14-B15))) -> 2 | D14: 77 | E14: =IF(AC14>0,((D14-U14)+(V14-D15)),IF(D15=0, ,(D14-D15))) -> 2 | F14: 77 | G14: =IF(AC14>0,((F14-X14)+(Y14-F15)),IF(F15=0, ,(F14-F15))) -> 3 | H14: 75 | I14: =IF(AC14>0,((H14-AA14)+(AB14-H15)),IF(H15=0, ,(H14-H15))) -> 2 | J14: =B14+D14+F14+H14 -> 304 | K14: =J14/4 -> 76 | L14: =IF(AC14>0,((K14-AD14)+(AE14-K15)),IF(K15=0, ,(K14-K15))) -> 2.25 | M14: =6049*4 -> 24196 | N14: =L14*M14/100 -> 544.41 | O14: =N14*0.529 -> 287.99289 | P14: =O14*9.965 -> 2869.8491 | AC14: =Q14+T14+W14+Z14 -> 0 | AD14: =(R14+U14+X14+AA14)/4 -> 0 | AE14: =(S14+V14+Y14+AB14)/4 -> 0
A15: 44481 | B15: 73 | C15: =IF(AC15>0,((B15-R15)+(S15-B16)),IF(B16=0, ,(B15-B16))) -> 3 | D15: 75 | E15: =IF(AC15>0,((D15-U15)+(V15-D16)),IF(D16=0, ,(D15-D16))) -> 2 | F15: 74 | G15: =IF(AC15>0,((F15-X15)+(Y15-F16)),IF(F16=0, ,(F15-F16))) -> 2 | H15: 73 | I15: =IF(AC15>0,((H15-AA15)+(AB15-H16)),IF(H16=0, ,(H15-H16))) -> 2 | J15: =B15+D15+F15+H15 -> 295 | K15: =J15/4 -> 73.75 | L15: =IF(AC15>0,((K15-AD15)+(AE15-K16)),IF(K16=0, ,(K15-K16))) -> 2.25 | M15: =6049*4 -> 24196 | N15: =L15*M15/100 -> 544.41 | O15: =N15*0.529 -> 287.99289 | P15: =O15*9.965 -> 2869.8491 | AC15: =Q15+T15+W15+Z15 -> 0 | AD15: =(R15+U15+X15+AA15)/4 -> 0 | AE15: =(S15+V15+Y15+AB15)/4 -> 0
A16: 44482 | B16: 70 | C16: =IF(AC16>0,((B16-R16)+(S16-B17)),IF(B17=0, ,(B16-B17))) -> 2 | D16: 73 | E16: =IF(AC16>0,((D16-U16)+(V16-D17)),IF(D17=0, ,(D16-D17))) -> 3 | F16: 72 | G16: =IF(AC16>0,((F16-X16)+(Y16-F17)),IF(F17=0, ,(F16-F17))) -> 3 | H16: 71 | I16: =IF(AC16>0,((H16-AA16)+(AB16-H17)),IF(H17=0, ,(H16-H17))) -> 3 | J16: =B16+D16+F16+H16 -> 286 | K16: =J16/4 -> 71.5 | L16: =IF(AC16>0,((K16-AD16)+(AE16-K17)),IF(K17=0, ,(K16-K17))) -> 2.75 | M16: =6049*4 -> 24196 | N16: =L16*M16/100 -> 665.39 | O16: =N16*0.529 -> 351.99131 | P16: =O16*9.965 -> 3507.5934 | AC16: =Q16+T16+W16+Z16 -> 0 | AD16: =(R16+U16+X16+AA16)/4 -> 0 | AE16: =(S16+V16+Y16+AB16)/4 -> 0
A17: 44483 | B17: 68 | C17: =IF(AC17>0,((B17-R17)+(S17-B18)),IF(B18=0, ,(B17-B18))) -> 2 | D17: 70 | E17: =IF(AC17>0,((D17-U17)+(V17-D18)),IF(D18=0, ,(D17-D18))) -> 0 | F17: 69 | G17: =IF(AC17>0,((F17-X17)+(Y17-F18)),IF(F18=0, ,(F17-F18))) -> 0 | H17: 68 | I17: =IF(AC17>0,((H17-AA17)+(AB17-H18)),IF(H18=0, ,(H17-H18))) -> 0 | J17: =B17+D17+F17+H17 -> 275 | K17: =J17/4 -> 68.75 | L17: =IF(AC17>0,((K17-AD17)+(AE17-K18)),IF(K18=0, ,(K17-K18))) -> 0.5 | M17: =6049*4 -> 24196 | N17: =L17*M17/100 -> 120.98 | O17: =N17*0.529 -> 63.99842 | P17: =O17*9.965 -> 637.74426 | AC17: =Q17+T17+W17+Z17 -> 0 | AD17: =(R17+U17+X17+AA17)/4 -> 0 | AE17: =(S17+V17+Y17+AB17)/4 -> 0
A18: 44484 | B18: 66 | C18: =IF(AC18>0,((B18-R18)+(S18-B19)),IF(B19=0, ,(B18-B19))) -> 2 | D18: 70 | E18: =IF(AC18>0,((D18-U18)+(V18-D19)),IF(D19=0, ,(D18-D19))) -> 5 | F18: 69 | G18: =IF(AC18>0,((F18-X18)+(Y18-F19)),IF(F19=0, ,(F18-F19))) -> 4 | H18: 68 | I18: =IF(AC18>0,((H18-AA18)+(AB18-H19)),IF(H19=0, ,(H18-H19))) -> 4 | J18: =B18+D18+F18+H18 -> 273 | K18: =J18/4 -> 68.25 | L18: =IF(AC18>0,((K18-AD18)+(AE18-K19)),IF(K19=0, ,(K18-K19))) -> 3.75 | M18: =6049*4 -> 24196 | N18: =L18*M18/100 -> 907.35 | O18: =N18*0.529 -> 479.98815 | P18: =O18*9.965 -> 4783.0819 | AC18: =Q18+T18+W18+Z18 -> 0 | AD18: =(R18+U18+X18+AA18)/4 -> 0 | AE18: =(S18+V18+Y18+AB18)/4 -> 0
A19: 44485 | B19: 64 | C19: =IF(AC19>0,((B19-R19)+(S19-B20)),IF(B20=0, ,(B19-B20))) -> 4 | D19: 65 | E19: =IF(AC19>0,((D19-U19)+(V19-D20)),IF(D20=0, ,(D19-D20))) -> 3 | F19: 65 | G19: =IF(AC19>0,((F19-X19)+(Y19-F20)),IF(F20=0, ,(F19-F20))) -> 4 | H19: 64 | I19: =IF(AC19>0,((H19-AA19)+(AB19-H20)),IF(H20=0, ,(H19-H20))) -> 4 | J19: =B19+D19+F19+H19 -> 258 | K19: =J19/4 -> 64.5 | L19: =IF(AC19>0,((K19-AD19)+(AE19-K20)),IF(K20=0, ,(K19-K20))) -> 3.75 | M19: =6049*4 -> 24196 | N19: =L19*M19/100 -> 907.35 | O19: =N19*0.529 -> 479.98815 | P19: =O19*9.965 -> 4783.0819 | AC19: =Q19+T19+W19+Z19 -> 0 | AD19: =(R19+U19+X19+AA19)/4 -> 0 | AE19: =(S19+V19+Y19+AB19)/4 -> 0
A20: 44486 | B20: 60 | C20: =IF(AC20>0,((B20-R20)+(S20-B21)),IF(B21=0, ,(B20-B21))) -> 5 | D20: 62 | E20: =IF(AC20>0,((D20-U20)+(V20-D21)),IF(D21=0, ,(D20-D21))) -> 6 | F20: 61 | G20: =IF(AC20>0,((F20-X20)+(Y20-F21)),IF(F21=0, ,(F20-F21))) -> 4 | H20: 60 | I20: =IF(AC20>0,((H20-AA20)+(AB20-H21)),IF(H21=0, ,(H20-H21))) -> 2 | J20: =B20+D20+F20+H20 -> 243 | K20: =J20/4 -> 60.75 | L20: =IF(AC20>0,((K20-AD20)+(AE20-K21)),IF(K21=0, ,(K20-K21))) -> 4.25 | M20: =6049*4 -> 24196 | N20: =L20*M20/100 -> 1028.33 | O20: =N20*0.529 -> 543.98657 | P20: =O20*9.965 -> 5420.8262 | AC20: =Q20+T20+W20+Z20 -> 0 | AD20: =(R20+U20+X20+AA20)/4 -> 0 | AE20: =(S20+V20+Y20+AB20)/4 -> 0
A21: 44487 | B21: 55 | C21: =IF(AC21>0,((B21-R21)+(S21-B22)),IF(B22=0, ,(B21-B22))) -> 2 | D21: 56 | E21: =IF(AC21>0,((D21-U21)+(V21-D22)),IF(D22=0, ,(D21-D22))) -> 2 | F21: 57 | G21: =IF(AC21>0,((F21-X21)+(Y21-F22)),IF(F22=0, ,(F21-F22))) -> 2 | H21: 58 | I21: =IF(AC21>0,((H21-AA21)+(AB21-H22)),IF(H22=0, ,(H21-H22))) -> 4 | J21: =B21+D21+F21+H21 -> 226 | K21: =J21/4 -> 56.5 | L21: =IF(AC21>0,((K21-AD21)+(AE21-K22)),IF(K22=0, ,(K21-K22))) -> 2.5 | M21: =6049*4 -> 24196 | N21: =L21*M21/100 -> 604.9 | O21: =N21*0.529 -> 319.9921 | P21: =O21*9.965 -> 3188.7213 | AC21: =Q21+T21+W21+Z21 -> 0 | AD21: =(R21+U21+X21+AA21)/4 -> 0 | AE21: =(S21+V21+Y21+AB21)/4 -> 0
A22: 44488 | B22: 53 | C22: =IF(AC22>0,((B22-R22)+(S22-B23)),IF(B23=0, ,(B22-B23))) -> 3 | D22: 54 | E22: =IF(AC22>0,((D22-U22)+(V22-D23)),IF(D23=0, ,(D22-D23))) -> 3 | F22: 55 | G22: =IF(AC22>0,((F22-X22)+(Y22-F23)),IF(F23=0, ,(F22-F23))) -> 3 | H22: 54 | I22: =IF(AC22>0,((H22-AA22)+(AB22-H23)),IF(H23=0, ,(H22-H23))) -> 3 | J22: =B22+D22+F22+H22 -> 216 | K22: =J22/4 -> 54 | L22: =IF(AC22>0,((K22-AD22)+(AE22-K23)),IF(K23=0, ,(K22-K23))) -> 3 | M22: =6049*4 -> 24196 | N22: =L22*M22/100 -> 725.88 | O22: =N22*0.529 -> 383.99052 | P22: =O22*9.965 -> 3826.4655 | AC22: =Q22+T22+W22+Z22 -> 0 | AD22: =(R22+U22+X22+AA22)/4 -> 0 | AE22: =(S22+V22+Y22+AB22)/4 -> 0
A23: 44489 | B23: 50 | C23: =IF(AC23>0,((B23-R23)+(S23-B24)),IF(B24=0, ,(B23-B24))) -> 5 | D23: 51 | E23: =IF(AC23>0,((D23-U23)+(V23-D24)),IF(D24=0, ,(D23-D24))) -> 4 | F23: 52 | G23: =IF(AC23>0,((F23-X23)+(Y23-F24)),IF(F24=0, ,(F23-F24))) -> 4 | H23: 51 | I23: =IF(AC23>0,((H23-AA23)+(AB23-H24)),IF(H24=0, ,(H23-H24))) -> 3 | J23: =B23+D23+F23+H23 -> 204 | K23: =J23/4 -> 51 | L23: =IF(AC23>0,((K23-AD23)+(AE23-K24)),IF(K24=0, ,(K23-K24))) -> 4 | M23: =6049*4 -> 24196 | N23: =L23*M23/100 -> 967.84 | O23: =N23*0.529 -> 511.98736 | P23: =O23*9.965 -> 5101.954 | Q23: 3134 | R23: 45 | S23: 85 | T23: 2986 | U23: 47 | V23: 85 | W23: 2952 | X23: 48 | Y23: 85 | Z23: 2974 | AA23: 48 | AB23: 85 | AC23: =Q23+T23+W23+Z23 -> 12046 | AD23: =(R23+U23+X23+AA23)/4 -> 47 | AE23: =(S23+V23+Y23+AB23)/4 -> 85
A24: 44490 | B24: 85 | C24: =IF(AC24>0,((B24-R24)+(S24-B25)),IF(B25=0, ,(B24-B25))) -> 0 | D24: 85 | E24: =IF(AC24>0,((D24-U24)+(V24-D25)),IF(D25=0, ,(D24-D25))) -> 0 | F24: 85 | G24: =IF(AC24>0,((F24-X24)+(Y24-F25)),IF(F25=0, ,(F24-F25))) -> 0 | H24: 85 | I24: =IF(AC24>0,((H24-AA24)+(AB24-H25)),IF(H25=0, ,(H24-H25))) -> 0 | J24: =B24+D24+F24+H24 -> 340 | K24: =J24/4 -> 85 | L24: =IF(AC24>0,((K24-AD24)+(AE24-K25)),IF(K25=0, ,(K24-K25))) -> 0 | M24: =6049*4 -> 24196 | N24: =L24*M24/100 -> 0 | O24: =N24*0.529 -> 0 | P24: =O24*9.965 -> 0 | AC24: =Q24+T24+W24+Z24 -> 0 | AD24: =(R24+U24+X24+AA24)/4 -> 0 | AE24: =(S24+V24+Y24+AB24)/4 -> 0
A25: 44491 | B25: 85 | C25: =IF(AC25>0,((B25-R25)+(S25-B26)),IF(B26=0, ,(B25-B26))) -> 5 | D25: 85 | E25: =IF(AC25>0,((D25-U25)+(V25-D26)),IF(D26=0, ,(D25-D26))) -> 3 | F25: 85 | G25: =IF(AC25>0,((F25-X25)+(Y25-F26)),IF(F26=0, ,(F25-F26))) -> 2 | H25: 85 | I25: =IF(AC25>0,((H25-AA25)+(AB25-H26)),IF(H26=0, ,(H25-H26))) -> 5 | J25: =B25+D25+F25+H25 -> 340 | K25: =J25/4 -> 85 | L25: =IF(AC25>0,((K25-AD25)+(AE25-K26)),IF(K26=0, ,(K25-K26))) -> 3.75 | M25: =6049*4 -> 24196 | N25: =L25*M25/100 -> 907.35 | O25: =N25*0.529 -> 479.98815 | P25: =O25*9.965 -> 4783.0819 | AC25: =Q25+T25+W25+Z25 -> 0 | AD25: =(R25+U25+X25+AA25)/4 -> 0 | AE25: =(S25+V25+Y25+AB25)/4 -> 0
A26: 44492 | B26: 80 | C26: =IF(AC26>0,((B26-R26)+(S26-B27)),IF(B27=0, ,(B26-B27))) -> 4 | D26: 82 | E26: =IF(AC26>0,((D26-U26)+(V26-D27)),IF(D27=0, ,(D26-D27))) -> 2 | F26: 83 | G26: =IF(AC26>0,((F26-X26)+(Y26-F27)),IF(F27=0, ,(F26-F27))) -> 3 | H26: 80 | I26: =IF(AC26>0,((H26-AA26)+(AB26-H27)),IF(H27=0, ,(H26-H27))) -> 5 | J26: =B26+D26+F26+H26 -> 325 | K26: =J26/4 -> 81.25 | L26: =IF(AC26>0,((K26-AD26)+(AE26-K27)),IF(K27=0, ,(K26-K27))) -> 3.5 | M26: =6049*4 -> 24196 | N26: =L26*M26/100 -> 846.86 | O26: =N26*0.529 -> 447.98894 | P26: =O26*9.965 -> 4464.2098 | AC26: =Q26+T26+W26+Z26 -> 0 | AD26: =(R26+U26+X26+AA26)/4 -> 0 | AE26: =(S26+V26+Y26+AB26)/4 -> 0
A27: 44493 | B27: 76 | C27: =IF(AC27>0,((B27-R27)+(S27-B28)),IF(B28=0, ,(B27-B28))) -> 4 | D27: 80 | E27: =IF(AC27>0,((D27-U27)+(V27-D28)),IF(D28=0, ,(D27-D28))) -> 2 | F27: 80 | G27: =IF(AC27>0,((F27-X27)+(Y27-F28)),IF(F28=0, ,(F27-F28))) -> 3 | H27: 75 | I27: =IF(AC27>0,((H27-AA27)+(AB27-H28)),IF(H28=0, ,(H27-H28))) -> 5 | J27: =B27+D27+F27+H27 -> 311 | K27: =J27/4 -> 77.75 | L27: =IF(AC27>0,((K27-AD27)+(AE27-K28)),IF(K28=0, ,(K27-K28))) -> 3.5 | M27: =6049*4 -> 24196 | N27: =L27*M27/100 -> 846.86 | O27: =N27*0.529 -> 447.98894 | P27: =O27*9.965 -> 4464.2098 | AC27: =Q27+T27+W27+Z27 -> 0 | AD27: =(R27+U27+X27+AA27)/4 -> 0 | AE27: =(S27+V27+Y27+AB27)/4 -> 0
A28: 44494 | B28: 72 | C28: =IF(AC28>0,((B28-R28)+(S28-B29)),IF(B29=0, ,(B28-B29))) -> 2 | D28: 78 | E28: =IF(AC28>0,((D28-U28)+(V28-D29)),IF(D29=0, ,(D28-D29))) -> 7 | F28: 77 | G28: =IF(AC28>0,((F28-X28)+(Y28-F29)),IF(F29=0, ,(F28-F29))) -> 5 | H28: 70 | I28: =IF(AC28>0,((H28-AA28)+(AB28-H29)),IF(H29=0, ,(H28-H29))) -> 0 | J28: =B28+D28+F28+H28 -> 297 | K28: =J28/4 -> 74.25 | L28: =IF(AC28>0,((K28-AD28)+(AE28-K29)),IF(K29=0, ,(K28-K29))) -> 3.5 | M28: =6049*4 -> 24196 | N28: =L28*M28/100 -> 846.86 | O28: =N28*0.529 -> 447.98894 | P28: =O28*9.965 -> 4464.2098 | AC28: =Q28+T28+W28+Z28 -> 0 | AD28: =(R28+U28+X28+AA28)/4 -> 0 | AE28: =(S28+V28+Y28+AB28)/4 -> 0
A29: 44495 | B29: 70 | C29: =IF(AC29>0,((B29-R29)+(S29-B30)),IF(B30=0, ,(B29-B30))) -> 2 | D29: 71 | E29: =IF(AC29>0,((D29-U29)+(V29-D30)),IF(D30=0, ,(D29-D30))) -> 1 | F29: 72 | G29: =IF(AC29>0,((F29-X29)+(Y29-F30)),IF(F30=0, ,(F29-F30))) -> 1 | H29: 70 | I29: =IF(AC29>0,((H29-AA29)+(AB29-H30)),IF(H30=0, ,(H29-H30))) -> 0 | J29: =B29+D29+F29+H29 -> 283 | K29: =J29/4 -> 70.75 | L29: =IF(AC29>0,((K29-AD29)+(AE29-K30)),IF(K30=0, ,(K29-K30))) -> 1 | M29: =6049*4 -> 24196 | N29: =L29*M29/100 -> 241.96 | O29: =N29*0.529 -> 127.99684 | P29: =O29*9.965 -> 1275.4885 | AC29: =Q29+T29+W29+Z29 -> 0 | AD29: =(R29+U29+X29+AA29)/4 -> 0 | AE29: =(S29+V29+Y29+AB29)/4 -> 0
A30: 44496 | B30: 68 | C30: =IF(AC30>0,((B30-R30)+(S30-B31)),IF(B31=0, ,(B30-B31))) -> 3 | D30: 70 | E30: =IF(AC30>0,((D30-U30)+(V30-D31)),IF(D31=0, ,(D30-D31))) -> 3 | F30: 71 | G30: =IF(AC30>0,((F30-X30)+(Y30-F31)),IF(F31=0, ,(F30-F31))) -> 4 | H30: 70 | I30: =IF(AC30>0,((H30-AA30)+(AB30-H31)),IF(H31=0, ,(H30-H31))) -> 4 | J30: =B30+D30+F30+H30 -> 279 | K30: =J30/4 -> 69.75 | L30: =IF(AC30>0,((K30-AD30)+(AE30-K31)),IF(K31=0, ,(K30-K31))) -> 3.5 | M30: =6049*4 -> 24196 | N30: =L30*M30/100 -> 846.86 | O30: =N30*0.529 -> 447.98894 | P30: =O30*9.965 -> 4464.2098 | AC30: =Q30+T30+W30+Z30 -> 0 | AD30: =(R30+U30+X30+AA30)/4 -> 0 | AE30: =(S30+V30+Y30+AB30)/4 -> 0
A31: 44497 | B31: 65 | C31: =IF(AC31>0,((B31-R31)+(S31-B32)),IF(B32=0, ,(B31-B32))) -> 2 | D31: 67 | E31: =IF(AC31>0,((D31-U31)+(V31-D32)),IF(D32=0, ,(D31-D32))) -> 2 | F31: 67 | G31: =IF(AC31>0,((F31-X31)+(Y31-F32)),IF(F32=0, ,(F31-F32))) -> 3 | H31: 66 | I31: =IF(AC31>0,((H31-AA31)+(AB31-H32)),IF(H32=0, ,(H31-H32))) -> 1 | J31: =B31+D31+F31+H31 -> 265 | K31: =J31/4 -> 66.25 | L31: =IF(AC31>0,((K31-AD31)+(AE31-K32)),IF(K32=0, ,(K31-K32))) -> 2 | M31: =6049*4 -> 24196 | N31: =L31*M31/100 -> 483.92 | O31: =N31*0.529 -> 255.99368 | P31: =O31*9.965 -> 2550.977 | AC31: =Q31+T31+W31+Z31 -> 0 | AD31: =(R31+U31+X31+AA31)/4 -> 0 | AE31: =(S31+V31+Y31+AB31)/4 -> 0
A32: 44498 | B32: 63 | C32: =IF(AC32>0,((B32-R32)+(S32-B33)),IF(B33=0, ,(B32-B33))) -> 3 | D32: 65 | E32: =IF(AC32>0,((D32-U32)+(V32-D33)),IF(D33=0, ,(D32-D33))) -> 3 | F32: 64 | G32: =IF(AC32>0,((F32-X32)+(Y32-F33)),IF(F33=0, ,(F32-F33))) -> 3 | H32: 65 | I32: =IF(AC32>0,((H32-AA32)+(AB32-H33)),IF(H33=0, ,(H32-H33))) -> 3 | J32: =B32+D32+F32+H32 -> 257 | K32: =J32/4 -> 64.25 | L32: =IF(AC32>0,((K32-AD32)+(AE32-K33)),IF(K33=0, ,(K32-K33))) -> 3 | M32: =6049*4 -> 24196 | N32: =L32*M32/100 -> 725.88 | O32: =N32*0.529 -> 383.99052 | P32: =O32*9.965 -> 3826.4655 | AC32: =Q32+T32+W32+Z32 -> 0 | AD32: =(R32+U32+X32+AA32)/4 -> 0 | AE32: =(S32+V32+Y32+AB32)/4 -> 0
A33: 44499 | B33: 60 | C33: =IF(AC33>0,((B33-R33)+(S33-B34)),IF(B34=0, ,(B33-B34))) -> 5 | D33: 62 | E33: =IF(AC33>0,((D33-U33)+(V33-D34)),IF(D34=0, ,(D33-D34))) -> 6 | F33: 61 | G33: =IF(AC33>0,((F33-X33)+(Y33-F34)),IF(F34=0, ,(F33-F34))) -> 4 | H33: 62 | I33: =IF(AC33>0,((H33-AA33)+(AB33-H34)),IF(H34=0, ,(H33-H34))) -> 4 | J33: =B33+D33+F33+H33 -> 245 | K33: =J33/4 -> 61.25 | L33: =IF(AC33>0,((K33-AD33)+(AE33-K34)),IF(K34=0, ,(K33-K34))) -> 4.75 | M33: =6049*4 -> 24196 | N33: =L33*M33/100 -> 1149.31 | O33: =N33*0.529 -> 607.98499 | P33: =O33*9.965 -> 6058.5704 | AC33: =Q33+T33+W33+Z33 -> 0 | AD33: =(R33+U33+X33+AA33)/4 -> 0 | AE33: =(S33+V33+Y33+AB33)/4 -> 0
A34: 44500 | B34: 55 | C34: =IF(AC34>0,((B34-R34)+(S34-B35)),IF(B35=0, ,(B34-B35))) -> 3 | D34: 56 | E34: =IF(AC34>0,((D34-U34)+(V34-D35)),IF(D35=0, ,(D34-D35))) -> 3 | F34: 57 | G34: =IF(AC34>0,((F34-X34)+(Y34-F35)),IF(F35=0, ,(F34-F35))) -> 2 | H34: 58 | I34: =IF(AC34>0,((H34-AA34)+(AB34-H35)),IF(H35=0, ,(H34-H35))) -> 3 | J34: =B34+D34+F34+H34 -> 226 | K34: =J34/4 -> 56.5 | L34: =IF(AC34>0,((K34-AD34)+(AE34-K35)),IF(K35=0, ,(K34-K35))) -> 2.75 | M34: =6049*4 -> 24196 | N34: =L34*M34/100 -> 665.39 | O34: =N34*0.529 -> 351.99131 | P34: =O34*9.965 -> 3507.5934 | AC34: =Q34+T34+W34+Z34 -> 0 | AD34: =(R34+U34+X34+AA34)/4 -> 0 | AE34: =(S34+V34+Y34+AB34)/4 -> 0
A35: 44501 | B35: 52 | C35: =IF(AC35>0,((B35-R35)+(S35-B36)),IF(B36=0, ,(B35-B36))) -> 0 | D35: 53 | E35: =IF(AC35>0,((D35-U35)+(V35-D36)),IF(D36=0, ,(D35-D36))) -> 0 | F35: 55 | G35: =IF(AC35>0,((F35-X35)+(Y35-F36)),IF(F36=0, ,(F35-F36))) -> 0 | H35: 55 | I35: =IF(AC35>0,((H35-AA35)+(AB35-H36)),IF(H36=0, ,(H35-H36))) -> 0 | J35: =B35+D35+F35+H35 -> 215 | K35: =J35/4 -> 53.75 | L35: =IF(AC35>0,((K35-AD35)+(AE35-K36)),IF(K36=0, ,(K35-K36))) -> 0 | M35: =6049*4 -> 24196 | N35: =L35*M35/100 -> 0 | O35: =N35*0.529 -> 0 | P35: =O35*9.965 -> 0 | AC35: =Q35+T35+W35+Z35 -> 0 | AD35: =(R35+U35+X35+AA35)/4 -> 0 | AE35: =(S35+V35+Y35+AB35)/4 -> 0
C36: =IF(AC36>0,((B36-R36)+(S36-B37)),IF(B37=0, ,(B36-B37))) -> 0 | E36: =IF(AC36>0,((D36-U36)+(V36-D37)),IF(D37=0, ,(D36-D37))) -> 0 | G36: =IF(AC36>0,((F36-X36)+(Y36-F37)),IF(F37=0, ,(F36-F37))) -> 0 | I36: =IF(AC36>0,((H36-AA36)+(AB36-H37)),IF(H37=0, ,(H36-H37))) -> 0 | J36: =B36+D36+F36+H36 -> 0 | K36: =J36/4 -> 0 | L36: =IF(AC36>0,((K36-AD36)+(AE36-K37)),IF(K37=0, ,(K36-K37))) -> 0 | M36: =6049*4 -> 24196 | N36: =L36*M36/100 -> 0 | O36: =N36*0.529 -> 0 | P36: =O36*9.965 -> 0 | AC36: =Q36+T36+W36+Z36 -> 0 | AD36: =(R36+U36+X36+AA36)/4 -> 0 | AE36: =(S36+V36+Y36+AB36)/4 -> 0
C37: =IF(AC37>0,((B37-R37)+(S37-B38)),IF(B38=0, ,(B37-B38))) -> 0 | E37: =IF(AC37:AC60>0,((D37-U37)+(V37-D38)),IF(D38=0, ,(D37-D38))) -> 0 | G37: =IF(AC37>0,((F37-X37)+(Y37-F38)),IF(F38=0, ,(F37-F38))) -> 0 | I37: =IF(AC37>0,((H37-AA37)+(AB37-H38)),IF(H38=0, ,(H37-H38))) -> 0 | J37: =B37+D37+F37+H37 -> 0 | K37: =J37/4 -> 0 | L37: =IF(AC37>0,((K37-AD37)+(AE37-K38)),IF(K38=0, ,(K37-K38))) -> 0 | M37: =6049*4 -> 24196 | N37: =L37*M37/100 -> 0 | O37: =N37*0.529 -> 0 | P37: =O37*9.965 -> 0 | AC37: =Q37+T37+W37+Z37 -> 0 | AD37: =(R37+U37+X37+AA37)/4 -> 0 | AE37: =(S37+V37+Y37+AB37)/4 -> 0
C38: =IF(AC38>0,((B38-R38)+(S38-B39)),IF(B39=0, ,(B38-B39))) -> 0 | E38: =IF(AC38:AC61>0,((D38-U38)+(V38-D39)),IF(D39=0, ,(D38-D39))) -> 0 | G38: =IF(AC38>0,((F38-X38)+(Y38-F39)),IF(F39=0, ,(F38-F39))) -> 0 | I38: =IF(AC38>0,((H38-AA38)+(AB38-H39)),IF(H39=0, ,(H38-H39))) -> 0 | J38: =B38+D38+F38+H38 -> 0 | K38: =J38/4 -> 0 | L38: =IF(AC38>0,((K38-AD38)+(AE38-K39)),IF(K39=0, ,(K38-K39))) -> 0 | M38: =6049*4 -> 24196 | N38: =L38*M38/100 -> 0 | O38: =N38*0.53 -> 0 | P38: =O38*9.965 -> 0 | AC38: =Q38+T38+W38+Z38 -> 0 | AD38: =(R38+U38+X38+AA38)/4 -> 0 | AE38: =(S38+V38+Y38+AB38)/4 -> 0
C39: =IF(AC39>0,((B39-R39)+(S39-B40)),IF(B40=0, ,(B39-B40))) -> 0 | E39: =IF(AC39>0,((D39-U39)+(V39-D40)),IF(D40=0, ,(D39-D40))) -> 0 | G39: =IF(AC39>0,((F39-X39)+(Y39-F40)),IF(F40=0, ,(F39-F40))) -> 0 | I39: =IF(AC39>0,((H39-AA39)+(AB39-H40)),IF(H40=0, ,(H39-H40))) -> 0 | J39: =B39+D39+F39+H39 -> 0 | K39: =J39/4 -> 0 | L39: =IF(AC39>0,((K39-AD39)+(AE39-K40)),IF(K40=0, ,(K39-K40))) -> 0 | M39: =6049*4 -> 24196 | N39: =L39*M39/100 -> 0 | O39: =N39*0.53 -> 0 | P39: =O39*9.965 -> 0 | AC39: =Q39+T39+W39+Z39 -> 0 | AD39: =(R39+U39+X39+AA39)/4 -> 0 | AE39: =(S39+V39+Y39+AB39)/4 -> 0
C40: =IF(AC40>0,((B40-R40)+(S40-B41)),IF(B41=0, ,(B40-B41))) -> 0 | E40: =IF(AC40>0,((D40-U40)+(V40-D41)),IF(D41=0, ,(D40-D41))) -> 0 | G40: =IF(AC40>0,((F40-X40)+(Y40-F41)),IF(F41=0, ,(F40-F41))) -> 0 | I40: =IF(AC40>0,((H40-AA40)+(AB40-H41)),IF(H41=0, ,(H40-H41))) -> 0 | J40: =B40+D40+F40+H40 -> 0 | K40: =J40/4 -> 0 | L40: =IF(AC40>0,((K40-AD40)+(AE40-K41)),IF(K41=0, ,(K40-K41))) -> 0 | M40: =6049*4 -> 24196 | N40: =L40*M40/100 -> 0 | O40: =N40*0.53 -> 0 | P40: =O40*9.965 -> 0 | AC40: =Q40+T40+W40+Z40 -> 0 | AD40: =(R40+U40+X40+AA40)/4 -> 0 | AE40: =(S40+V40+Y40+AB40)/4 -> 0
...

Sheet facture électricité
C1: Estimation de la consommation électrique Octobre 2021 | H1: Fiche technique
H3: DT fourseasons CBL
A7: N° de compteur | C7: Ancienne date de lecture | E7: Nouvelle date de lecture | F7: N de jours de consommation | G7: Heures pleines | H7: Heures creuses | I7: Heures de pointe
A8: 95670781 | C8: 44467 | E8: 44497 | F8: 30jours
A11: Type de comptage | C11: Puissance installée KVA | E11: Puissance souscrite KVA | G11: Puissance appelée KVA | I11: Dépassement de la puissance souscrite KVA
A12: 4T | C12: 3750 | E12: 1000 | G12: 971
A16: Eléments de relève | C16: Nouvel Index | D16: Ancien Index | E16: Consommation | F16: Energie révaluée | G16: Consommation Compteur démarquant | I16: Energie à facturer
A17: HEURES PLEINE | C17: 19010638 | D17: 18787480 | E17: =MIN(C17-D17) -> 223158 | F17: =+E17 -> 223158 | I17: =+E17 -> 223158
A18: HEURES CREUSES | C18: 11152750 | D18: 11027578 | E18: =MIN(C18-D18) -> 125172 | F18: =+E18 -> 125172 | I18: =+E18 -> 125172
A19: HEURES DE POINTE | C19: 8339848 | D19: 8243979 | E19: =AVERAGE(C19-D19) -> 95869 | F19: =+E19 -> 95869 | I19: =+E19 -> 95869
A20: TOTAL | E20: =SUM(E17:E19) -> 444199
A23: Détail de la facture | D23: Quantité | E23: Prix unitaire | F23: Montant HT | G23: TVA | I23: Montant TTC
G24: Taux % | H24: Montant
A25: ENERGIE ACTIVE H. PLEINES | D25: =+E17 -> 223158 | E25: 0.9514 | F25: =PRODUCT(D25*E25) -> 212312.52 | G25: 14 | H25: =PRODUCT(0.14,F25) -> 29723.753 | I25: =SUM(H25,F25) -> 242036.27
A26: ENERGIE ACTIVE H. CREUSES | D26: =+E18 -> 125172 | E26: 0.6985 | F26: =PRODUCT(D26*E26) -> 87432.642 | G26: 14 | H26: =PRODUCT(0.14,F26) -> 12240.57 | I26: =SUM(H26,F26) -> 99673.212
A27: ENETGIE ACTIVE H. DE POINTE | D27: =+E19 -> 95869 | E27: 1.3304 | F27: =PRODUCT(D27*E27) -> 127544.12 | G27: 14 | H27: =PRODUCT(0.14,F27) -> 17856.176 | I27: =SUM(H27,F27) -> 145400.29
A28: REDEVANCE DE PUISSANCE | D28: 1000 | E28: 43.88167 | F28: =PRODUCT(D28,E28) -> 43881.67 | G28: 14 | H28: =PRODUCT(0.14,F28) -> 6143.4338 | I28: =SUM(H28,F28) -> 50025.104
A29: DEPASSEMENT DE PUISSANCE | D29: 0 | E29: =E28*1.5 -> 65.822505 | F29: =PRODUCT(D29,E29) -> 0 | G29: 14 | H29: =PRODUCT(0.14,F29) -> 0 | I29: =SUM(H29,F29) -> 0
A30: ENTRETIEN COMPTAGE | F30: 841 | G30: 20 | H30: =PRODUCT(F30,0.2) -> 168.2 | I30: =SUM(H30,F30) -> 1009.2
A31: LOCATION COMPTAGE | F31: 1492 | G31: 7 | H31: =PRODUCT(F31,0.07) -> 104.44 | I31: =SUM(H31,F31) -> 1596.44
A32: Total | F32: =SUM(F25:F31) -> 473503.95 | I32: =SUM(I25:J31) -> 539740.52

Sheet Facture journalier D'élect
C1: Estimation de la consommation électrique Oct 2021 | H1: Fiche technique
H3: DT fourseasons CBL
A7: N° de compteur | C7: Ancienne date de lecture | E7: Nouvelle date de lecture | F7: N de jours de consommation | G7: Heures pleines | H7: Heures creuses | I7: Heures de pointe
A8: 95670781 | C8: 44296 | E8: 44326 | F8: 01jours
A11: Type de comptage | C11: Puissance installée KVA | E11: Puissance souscrite KVA | G11: Puissance appelée KVA | I11: Dépassement de la puissance souscrite KVA
A12: 4T | C12: 3750 | E12: 1000 | G12: 712
A16: Eléments de relève | C16: Nouvel Index | D16: Ancien Index | E16: Consommation | F16: Energie révaluée | G16: Consommation Compteur démarquant | I16: Energie à facturer
A17: HEURES PLEINE | C17: 18841930 | D17: 18834226 | E17: =MIN(C17-D17) -> 7704 | F17: =+E17 -> 7704 | I17: =+E17 -> 7704
A18: HEURES CREUSES | C18: 11057525 | D18: 11053381 | E18: =MIN(C18-D18) -> 4144 | F18: =+E18 -> 4144 | I18: =+E18 -> 4144
A19: HEURES DE POINTE | C19: 8266700 | D19: 8263360 | E19: =AVERAGE(C19-D19) -> 3340 | F19: =+E19 -> 3340 | I19: =+E19 -> 3340
A20: TOTAL | E20: =SUM(E17:E19) -> 15188
A23: Détail de la facture | D23: Quantité | E23: Prix unitaire | F23: Montant HT | G23: TVA | I23: Montant TTC
G24: Taux % | H24: Montant
A25: ENERGIE ACTIVE H. PLEINES | D25: =+E17 -> 7704 | E25: 0.9514 | F25: =PRODUCT(D25*E25) -> 7329.5856 | G25: 14 | H25: =PRODUCT(0.14,F25) -> 1026.142 | I25: =SUM(H25,F25) -> 8355.7276
A26: ENERGIE ACTIVE H. CREUSES | D26: =+E18 -> 4144 | E26: 0.6985 | F26: =PRODUCT(D26*E26) -> 2894.584 | G26: 14 | H26: =PRODUCT(0.14,F26) -> 405.24176 | I26: =SUM(H26,F26) -> 3299.8258
A27: ENETGIE ACTIVE H. DE POINTE | D27: =+E19 -> 3340 | E27: 1.3304 | F27: =PRODUCT(D27*E27) -> 4443.536 | G27: 14 | H27: =PRODUCT(0.14,F27) -> 622.09504 | I27: =SUM(H27,F27) -> 5065.631
A28: REDEVANCE DE PUISSANCE | D28: 1000 | E28: 43.88167 | F28: =PRODUCT(D28,E28) -> 43881.67 | G28: 14 | H28: =PRODUCT(0.14,F28) -> 6143.4338 | I28: =SUM(H28,F28) -> 50025.104
A29: DEPASSEMENT DE PUISSANCE | D29: 0 | E29: 48.97249 | F29: =PRODUCT(D29,E29) -> 0 | G29: 14 | H29: =PRODUCT(0.14,F29) -> 0 | I29: =SUM(H29,F29) -> 0
A30: ENTRETIEN COMPTAGE | F30: 841 | G30: 20 | H30: =PRODUCT(F30,0.2) -> 168.2 | I30: =SUM(H30,F30) -> 1009.2
A31: LOCATION COMPTAGE | F31: 1492 | G31: 7 | H31: =PRODUCT(F31,0.07) -> 104.44 | I31: =SUM(H31,F31) -> 1596.44
