Workbook

Sheet TOTAL
A1: Site Name | B1: Day | C1: Month | D1: Year | E1: Total Electricity Kwh | F1: Electricity Tariff ($/Kwh) | G1: Natual Gas (m3) | H1: Natural Gas $/m3 | I1: Water Utility Supply (m3) m3 | J1: Water Utility Supply (m3) $/m3 | K1: Room Nights | L1: Total Guests | M1: Utilities day cost dh
A2: Mumbai | B2: 1 | C2: 10 | D2: 2021 | E2: =(IF('Daily HLP'!H4>0,'Daily HLP'!H4,0)) -> 21808.97 | F2: 9 | G2: =(IF('Daily HLP'!L4>0,'Daily HLP'!L4,0)) -> 1029.03 | H2: 54.6 | I2: =(IF('Daily HLP'!O4>0,'Daily HLP'!O4,0)) -> 237 | J2: 99 | K2: =Occupancy!G2 -> 127 | L2: =Occupancy!F2 -> 514 | M2: =E2*F2+G2*H2+#REF!*#REF!+I2*J2 -> #REF!
A3: Mumbai | B3: =B2+1 -> 2 | C3: 10 | D3: 2021 | E3: =(IF('Daily HLP'!H5>0,'Daily HLP'!H5,0)) -> 22954.08 | F3: 9 | G3: =(IF('Daily HLP'!L5>0,'Daily HLP'!L5,0)) -> 946.85 | H3: 54.6 | I3: =(IF('Daily HLP'!O5>0,'Daily HLP'!O5,0)) -> 270 | J3: 99 | K3: =Occupancy!G3 -> 109 | L3: =Occupancy!F3 -> 502 | M3: =E3*F3+G3*H3+#REF!*#REF!+I3*J3 -> #REF!
A4: Mumbai | B4: =B3+1 -> 3 | C4: 10 | D4: 2021 | E4: =(IF('Daily HLP'!H6>0,'Daily HLP'!H6,0)) -> 22487.75 | F4: 9 | G4: =(IF('Daily HLP'!L6>0,'Daily HLP'!L6,0)) -> 955.49 | H4: 54.6 | I4: =(IF('Daily HLP'!O6>0,'Daily HLP'!O6,0)) -> 279 | J4: 99 | K4: =Occupancy!G4 -> 91 | L4: =Occupancy!F4 -> 363 | M4: =E4*F4+G4*H4+#REF!*#REF!+I4*J4 -> #REF!
A5: Mumbai | B5: =B4+1 -> 4 | C5: 10 | D5: 2021 | E5: =(IF('Daily HLP'!H7>0,'Daily HLP'!H7,0)) -> 20833.41 | F5: 9 | G5: =(IF('Daily HLP'!L7>0,'Daily HLP'!L7,0)) -> 914.75 | H5: 54.6 | I5: =(IF('Daily HLP'!O7>0,'Daily HLP'!O7,0)) -> 239 | J5: 99 | K5: =Occupancy!G5 -> 84 | L5: =Occupancy!F5 -> 386 | M5: =E5*F5+G5*H5+#REF!*#REF!+I5*J5 -> #REF!
A6: Mumbai | B6: =B5+1 -> 5 | C6: 10 | D6: 2021 | E6: =(IF('Daily HLP'!H8>0,'Daily HLP'!H8,0)) -> 24186.89 | F6: 9 | G6: =(IF('Daily HLP'!L8>0,'Daily HLP'!L8,0)) -> 889.92 | H6: 54.6 | I6: =(IF('Daily HLP'!O8>0,'Daily HLP'!O8,0)) -> 159 | J6: 99 | K6: =Occupancy!G6 -> 165 | L6: =Occupancy!F6 -> 675 | M6: =E6*F6+G6*H6+#REF!*#REF!+I6*J6 -> #REF!
A7: Mumbai | B7: =B6+1 -> 6 | C7: 10 | D7: 2021 | E7: =(IF('Daily HLP'!H9>0,'Daily HLP'!H9,0)) -> 22837.55 | F7: 9 | G7: =(IF('Daily HLP'!L9>0,'Daily HLP'!L9,0)) -> 955.68 | H7: 54.6 | I7: =(IF('Daily HLP'!O9>0,'Daily HLP'!O9,0)) -> 291 | J7: 99 | K7: =Occupancy!G7 -> 184 | L7: =Occupancy!F7 -> 588 | M7: =E7*F7+G7*H7+#REF!*#REF!+I7*J7 -> #REF!
A8: Mumbai | B8: =B7+1 -> 7 | C8: 10 | D8: 2021 | E8: =(IF('Daily HLP'!H10>0,'Daily HLP'!H10,0)) -> 21951.04 | F8: 9 | G8: =(IF('Daily HLP'!L10>0,'Daily HLP'!L10,0)) -> 962.49 | H8: 54.6 | I8: =(IF('Daily HLP'!O10>0,'Daily HLP'!O10,0)) -> 259 | J8: 99 | K8: =Occupancy!G8 -> 159 | L8: =Occupancy!F8 -> 525 | M8: =E8*F8+G8*H8+#REF!*#REF!+I8*J8 -> #REF!
A9: Mumbai | B9: =B8+1 -> 8 | C9: 10 | D9: 2021 | E9: =(IF('Daily HLP'!H11>0,'Daily HLP'!H11,0)) -> 21972.24 | F9: 9 | G9: =(IF('Daily HLP'!L11>0,'Daily HLP'!L11,0)) -> 1009.75 | H9: 54.6 | I9: =(IF('Daily HLP'!O11>0,'Daily HLP'!O11,0)) -> 258 | J9: 99 | K9: =Occupancy!G9 -> 117 | L9: =Occupancy!F9 -> 464 | M9: =E9*F9+G9*H9+#REF!*#REF!+I9*J9 -> #REF!
A10: Mumbai | B10: =B9+1 -> 9 | C10: 10 | D10: 2021 | E10: =(IF('Daily HLP'!H12>0,'Daily HLP'!H12,0)) -> 21818.17 | F10: 9 | G10: =(IF('Daily HLP'!L12>0,'Daily HLP'!L12,0)) -> 1028.08 | H10: 54.6 | I10: =(IF('Daily HLP'!O12>0,'Daily HLP'!O12,0)) -> 253 | J10: 99 | K10: =Occupancy!G10 -> 128 | L10: =Occupancy!F10 -> 385 | M10: =E10*F10+G10*H10+#REF!*#REF!+I10*J10 -> #REF!
A11: Mumbai | B11: =B10+1 -> 10 | C11: 10 | D11: 2021 | E11: =(IF('Daily HLP'!H13>0,'Daily HLP'!H13,0)) -> 21010 | F11: 9 | G11: =(IF('Daily HLP'!L13>0,'Daily HLP'!L13,0)) -> 1016 | H11: 54.6 | I11: =(IF('Daily HLP'!O13>0,'Daily HLP'!O13,0)) -> 225 | J11: 99 | K11: =Occupancy!G11 -> 151 | L11: =Occupancy!F11 -> 503 | M11: =E11*F11+G11*H11+#REF!*#REF!+I11*J11 -> #REF!
A12: Mumbai | B12: =B11+1 -> 11 | C12: 10 | D12: 2021 | E12: =(IF('Daily HLP'!H14>0,'Daily HLP'!H14,0)) -> 21500 | F12: 9 | G12: =(IF('Daily HLP'!L14>0,'Daily HLP'!L14,0)) -> 0 | H12: 54.6 | I12: =(IF('Daily HLP'!O14>0,'Daily HLP'!O14,0)) -> 0 | J12: 99 | K12: =Occupancy!G12 -> 0 | L12: =Occupancy!F12 -> 0 | M12: =E12*F12+G12*H12+#REF!*#REF!+I12*J12 -> #REF!
A13: Mumbai | B13: =B12+1 -> 12 | C13: 10 | D13: 2021 | E13: =(IF('Daily HLP'!H15>0,'Daily HLP'!H15,0)) -> 21500 | F13: 9 | G13: =(IF('Daily HLP'!L15>0,'Daily HLP'!L15,0)) -> 959 | H13: 54.6 | I13: =(IF('Daily HLP'!O15>0,'Daily HLP'!O15,0)) -> 248 | J13: 99 | K13: =Occupancy!G13 -> 0 | L13: =Occupancy!F13 -> 0 | M13: =E13*F13+G13*H13+#REF!*#REF!+I13*J13 -> #REF!
A14: Mumbai | B14: =B13+1 -> 13 | C14: 10 | D14: 2021 | E14: =(IF('Daily HLP'!H16>0,'Daily HLP'!H16,0)) -> 21500 | F14: 9 | G14: =(IF('Daily HLP'!L16>0,'Daily HLP'!L16,0)) -> 952 | H14: 54.6 | I14: =(IF('Daily HLP'!O16>0,'Daily HLP'!O16,0)) -> 219 | J14: 99 | K14: =Occupancy!G14 -> 0 | L14: =Occupancy!F14 -> 0 | M14: =E14*F14+G14*H14+#REF!*#REF!+I14*J14 -> #REF!
... A31: Mumbai | B31: =B30+1 -> 30 | C31: 10 | D31: 2021 | E31: =(IF('Daily HLP'!H33>0,'Daily HLP'!H33,0)) -> 21500 | F31: 9 | G31: =(IF('Daily HLP'!L33>0,'Daily HLP'!L33,0)) -> 988 | H31: 54.6 | I31: =(IF('Daily HLP'!O33>0,'Daily HLP'!O33,0)) -> 247 | J31: 99 | K31: =Occupancy!G31 -> 0 | L31: =Occupancy!F31 -> 0 | M31: =E31*F31+G31*H31+#REF!*#REF!+I31*J31 -> #REF!
A32: Mumbai | B32: =B31+1 -> 31 | C32: 10 | D32: 2021 | E32: =(IF('Daily HLP'!H34>0,'Daily HLP'!H34,0)) -> 21500 | F32: 9 | G32: =(IF('Daily HLP'!L34>0,'Daily HLP'!L34,0)) -> 1024.96 | H32: 54.6 | I32: =(IF('Daily HLP'!O34>0,'Daily HLP'!O34,0)) -> 269 | J32: 99 | K32: =Occupancy!G32 -> 0 | L32: =Occupancy!F32 -> 0

Sheet Submetering
A1: Site Name | B1: Day | C1: Month | D1: Year | E1: ='Section Load'!F4 -> HVAC | F1: ='Section Load'!G4 -> Fire & Emergency PP | G1: ='Section Load'!H4 -> Main PP | H1: ='Section Load'!I4 -> Lighting PP | I1: ='Section Load'!J4 -> CH-1+ CH2+CH3+CH4 | J1: ='Section Load'!K4 -> Chilled water Pump | K1: ='Section Load'!L4 -> Ball Room-1 | L1: ='Section Load'!M4 -> Ball Room-2 | ... AL1: ='Section Load'!AM4 -> Cooling Tower | AM1: R.o.plant | AN1: STP Water Prod | AO1: Domestic Zone-1 | AP1: Domestic Zone-2 | AQ1: Domestic Zone-3 | AR1: Flush Zone -1 | AS1: Flush Zone -2 | AT1: Flush Zone -3 | AU1: Swimming pool | AV1: B2 Laundry | AW1: Boiler Feed Water | AX1: cooling tower filling water | AY1: STP flush(new water meter) | AZ1: Garden Water Pump | BA1: Flush Zone 2 pump meter | BB1: Flush Zone 3 Pump Meter (wtp transfer ) | BC1: Flush Tanker-Zone-1 | BD1: Total Domestic Water (Tanker (R.O) +BMC) | BE1: Total Domestic Consumption | BF1: Total STP Consumption | BG1: ='Section Load'!AN4 -> MGL | BH1: ='Section Load'!AO4 -> HWG | BI1: ='Section Load'!AP4 -> Prato | BJ1: ='Section Load'!AQ4 -> BR-1 | BK1: ='Section Load'!AR4 -> SanQi IND | BL1: ='Section Load'!AS4 -> SanQi JPN | BM1: ='Section Load'!AT4 -> Boiler
A2: Mumbai | B2: 1 | C2: 10 | D2: 2021 | E2: =(IF('Section Load'!F5>0,'Section Load'!F5,0)) -> 3192.96 | F2: =(IF('Section Load'!G5>0,'Section Load'!G5,0)) -> 1604.96 | G2: =(IF('Section Load'!H5>0,'Section Load'!H5,0)) -> 1846.14 | H2: =(IF('Section Load'!I5>0,'Section Load'!I5,0)) -> 2900.04 | I2: =(IF('Section Load'!J5>0,'Section Load'!J5,0)) -> 5549.16 | J2: =(IF('Section Load'!K5>0,'Section Load'!K5,0)) -> 2600.9 | K2: =(IF('Section Load'!L5>0,'Section Load'!L5,0)) -> 1026.96 | L2: =(IF('Section Load'!M5>0,'Section Load'!M5,0)) -> 683.28 | ... AL2: =(IF('Section Load'!AM5>0,'Section Load'!AM5,0)) -> 604.29 | AM2: =(IF('Water Report'!$D$7>0,'Water Report'!$D$7,0)) -> 118 | AN2: =(IF('Water Report'!$D$8>0,'Water Report'!$D$8,0)) -> 80 | AO2: =(IF('Water Report'!$D$9>0,'Water Report'!$D$9,0)) -> 97 | AP2: =(IF('Water Report'!$D$10>0,'Water Report'!$D$10,0)) -> 23 | AQ2: =(IF('Water Report'!$D$11>0,'Water Report'!$D$11,0)) -> 30 | AR2: =(IF('Water Report'!$D$13>0,'Water Report'!$D$13,0)) -> 41 | AS2: =(IF('Water Report'!$D$14>0,'Water Report'!$D$14,0)) -> 9 | AT2: =(IF('Water Report'!$D$15>0,'Water Report'!$D$15,0)) -> 7 | AU2: =(IF('Water Report'!$D$17>0,'Water Report'!$D$17,0)) -> 0 | AV2: =(IF('Water Report'!$D$18>0,'Water Report'!$D$18,0)) -> 16 | AW2: =(IF('Water Report'!$D$19>0,'Water Report'!$D$19,0)) -> 11 | AX2: =(IF('Water Report'!$D$21>0,'Water Report'!$D$21,0)) -> 68 | AY2: =(IF('Water Report'!$D$22>0,'Water Report'!$D$22,0)) -> 0 | AZ2: =(IF('Water Report'!$D$23>0,'Water Report'!$D$23,0)) -> 0 | BA2: =(IF('Water Report'!$D$14>0,'Water Report'!$D$14,0)) -> 9 | BB2: =(IF('Water Report'!$D$15>0,'Water Report'!$D$15,0)) -> 7 | BC2: =(IF('Water Report'!$D$13>0,'Water Report'!$D$13,0)) -> 41 | BD2: =(IF('Water Report'!$D$24>0,'Water Report'!$D$24,0)) -> 237 | BE2: =(IF('Water Report'!$D$25>0,'Water Report'!$D$25,0)) -> 166 | BF2: =(IF('Water Report'!$D$27>0,'Water Report'!$D$27,0)) -> 109 | BG2: =(IF('Section Load'!AN5>0,'Section Load'!AN5,0)) -> 1029.03 | BH2: =(IF('Section Load'!AO5>0,'Section Load'!AO5,0)) -> 294.149 | BI2: =(IF('Section Load'!AP5>0,'Section Load'!AP5,0)) -> 0 | BJ2: =(IF('Section Load'!AQ5>0,'Section Load'!AQ5,0)) -> 94.87 | BK2: =(IF('Section Load'!AR5>0,'Section Load'!AR5,0)) -> 35.4 | BL2: =(IF('Section Load'!AS5>0,'Section Load'!AS5,0)) -> 2 | BM2: =(IF('Section Load'!AT5>0,'Section Load'!AT5,0)) -> 602.611
A3: Mumbai | B3: =B2+1 -> 2 | C3: 10 | D3: 2021 | E3: =(IF('Section Load'!F6>0,'Section Load'!F6,0)) -> 3505.37 | F3: =(IF('Section Load'!G6>0,'Section Load'!G6,0)) -> 1550.52 | G3: =(IF('Section Load'!H6>0,'Section Load'!H6,0)) -> 1770.99 | H3: =(IF('Section Load'!I6>0,'Section Load'!I6,0)) -> 2945.4 | I3: =(IF('Section Load'!J6>0,'Section Load'!J6,0)) -> 6250.29 | J3: =(IF('Section Load'!K6>0,'Section Load'!K6,0)) -> 2747.8 | K3: =(IF('Section Load'!L6>0,'Section Load'!L6,0)) -> 1026.48 | L3: =(IF('Section Load'!M6>0,'Section Load'!M6,0)) -> 757.12 | ... AL3: =(IF('Section Load'!AM6>0,'Section Load'!AM6,0)) -> 675.56 | AM3: =(IF('Water Report'!$E$7>0,'Water Report'!$E$7,0)) -> 108 | AN3: =(IF('Water Report'!$E$8>0,'Water Report'!$E$8,0)) -> 89 | AO3: =(IF('Water Report'!$E$9>0,'Water Report'!$E$9,0)) -> 109 | AP3: =(IF('Water Report'!$E$10>0,'Water Report'!$E$10,0)) -> 18 | AQ3: =(IF('Water Report'!$E$11>0,'Water Report'!$E$11,0)) -> 24 | AR3: =(IF('Water Report'!$E$13>0,'Water Report'!$E$13,0)) -> 26 | AS3: =(IF('Water Report'!$E$14>0,'Water Report'!$E$14,0)) -> 6 | AT3: =(IF('Water Report'!$E$15>0,'Water Report'!$E$15,0)) -> 10 | AU3: =(IF('Water Report'!$E$17>0,'Water Report'!$E$17,0)) -> 0 | AV3: =(IF('Water Report'!$E$18>0,'Water Report'!$E$18,0)) -> 12 | AW3: =(IF('Water Report'!$E$19>0,'Water Report'!$E$19,0)) -> 10 | AX3: =(IF('Water Report'!$E$21>0,'Water Report'!$E$21,0)) -> 57 | AY3: =(IF('Water Report'!$E$22>0,'Water Report'!$E$22,0)) -> 0 | AZ3: =(IF('Water Report'!$E$23>0,'Water Report'!$E$23,0)) -> 19 | BA3: =(IF('Water Report'!$E$14>0,'Water Report'!$E$14,0)) -> 6 | BB3: =(IF('Water Report'!$E$15>0,'Water Report'!$E$15,0)) -> 10 | BC3: =(IF('Water Report'!$E$13>0,'Water Report'!$E$13,0)) -> 26 | BD3: =(IF('Water Report'!$E$24>0,'Water Report'!$E$24,0)) -> 270 | BE3: =(IF('Water Report'!$E$25>0,'Water Report'!$E$25,0)) -> 167 | BF3: =(IF('Water Report'!$E$27>0,'Water Report'!$E$27,0)) -> 102 | BG3: =(IF('Section Load'!AN6>0,'Section Load'!AN6,0)) -> 946.85 | BH3: =(IF('Section Load'!AO6>0,'Section Load'!AO6,0)) -> 292.8 | BI3: =(IF('Section Load'!AP6>0,'Section Load'!AP6,0)) -> 0 | BJ3: =(IF('Section Load'!AQ6>0,'Section Load'!AQ6,0)) -> 96.84 | BK3: =(IF('Section Load'!AR6>0,'Section Load'!AR6,0)) -> 37.5 | BL3: =(IF('Section Load'!AS6>0,'Section Load'!AS6,0)) -> 2.9 | BM3: =(IF('Section Load'!AT6>0,'Section Load'!AT6,0)) -> 516.81
A4: Mumbai | B4: =B3+1 -> 3 | C4: 10 | D4: 2021 | E4: =(IF('Section Load'!F7>0,'Section Load'!F7,0)) -> 3774.23 | F4: =(IF('Section Load'!G7>0,'Section Load'!G7,0)) -> 1629.46 | G4: =(IF('Section Load'!H7>0,'Section Load'!H7,0)) -> 1944.71 | H4: =(IF('Section Load'!I7>0,'Section Load'!I7,0)) -> 2961.16 | I4: =(IF('Section Load'!J7>0,'Section Load'!J7,0)) -> 5371.22 | J4: =(IF('Section Load'!K7>0,'Section Load'!K7,0)) -> 2695.4 | K4: =(IF('Section Load'!L7>0,'Section Load'!L7,0)) -> 960.16 | L4: =(IF('Section Load'!M7>0,'Section Load'!M7,0)) -> 684.49 | ... AL4: =(IF('Section Load'!AM7>0,'Section Load'!AM7,0)) -> 815.11 | AM4: =(IF('Water Report'!$F$7>0,'Water Report'!$F$7,0)) -> 128 | AN4: =(IF('Water Report'!$F$8>0,'Water Report'!$F$8,0)) -> 113 | AO4: =(IF('Water Report'!$F$9>0,'Water Report'!$G$9,0)) -> 85 | AP4: =(IF('Water Report'!$F$10>0,'Water Report'!$F$10,0)) -> 17 | AQ4: =(IF('Water Report'!$F$11>0,'Water Report'!$F$11,0)) -> 19 | AR4: =(IF('Water Report'!$F$13>0,'Water Report'!$F$13,0)) -> 35 | AS4: =(IF('Water Report'!$F$14>0,'Water Report'!$F$14,0)) -> 30 | AT4: =(IF('Water Report'!$F$15>0,'Water Report'!$F$15,0)) -> 15 | AU4: =(IF('Water Report'!$F$17>0,'Water Report'!$F$17,0)) -> 0 | AV4: =(IF('Water Report'!$F$18>0,'Water Report'!$F$18,0)) -> 14 | AW4: =(IF('Water Report'!$F$19>0,'Water Report'!$F$19,0)) -> 8 | AX4: =(IF('Water Report'!$F$21>0,'Water Report'!$F$21,0)) -> 60 | AY4: =(IF('Water Report'!$F$22>0,'Water Report'!$F$22,0)) -> 0 | AZ4: =(IF('Water Report'!$F$23>0,'Water Report'!$F$23,0)) -> 14 | BA4: =(IF('Water Report'!$F$14>0,'Water Report'!$F$14,0)) -> 30 | BB4: =(IF('Water Report'!$F$15>0,'Water Report'!$F$15,0)) -> 15 | BC4: =(IF('Water Report'!$F$13>0,'Water Report'!$F$13,0)) -> 35 | BD4: =(IF('Water Report'!$F$24>0,'Water Report'!$F$24,0)) -> 279 | BE4: =(IF('Water Report'!$F$25>0,'Water Report'!$F$25,0)) -> 202 | BF4: =(IF('Water Report'!$F$27>0,'Water Report'!$F$27,0)) -> 109 | BG4: =(IF('Section Load'!AN7>0,'Section Load'!AN7,0)) -> 955.49 | BH4: =(IF('Section Load'!AO7>0,'Section Load'!AO7,0)) -> 291.926 | BI4: =(IF('Section Load'!AP7>0,'Section Load'!AP7,0)) -> 0 | BJ4: =(IF('Section Load'!AQ7>0,'Section Load'!AQ7,0)) -> 114.23 | BK4: =(IF('Section Load'!AR7>0,'Section Load'!AR7,0)) -> 36.1 | BL4: =(IF('Section Load'!AS7>0,'Section Load'!AS7,0)) -> 1 | BM4: =(IF('Section Load'!AT7>0,'Section Load'!AT7,0)) -> 512.234
A5: Mumbai | B5: =B4+1 -> 4 | C5: 10 | D5: 2021 | E5: =(IF('Section Load'!F8>0,'Section Load'!F8,0)) -> 3614.51 | F5: =(IF('Section Load'!G8>0,'Section Load'!G8,0)) -> 1438.9 | G5: =(IF('Section Load'!H8>0,'Section Load'!H8,0)) -> 1642.61 | H5: =(IF('Section Load'!I8>0,'Section Load'!I8,0)) -> 2745.68 | I5: =(IF('Section Load'!J8>0,'Section Load'!J8,0)) -> 5066.5 | J5: =(IF('Section Load'!K8>0,'Section Load'!K8,0)) -> 2524.2 | K5: =(IF('Section Load'!L8>0,'Section Load'!L8,0)) -> 884 | L5: =(IF('Section Load'!M8>0,'Section Load'!M8,0)) -> 640.12 | ... AL5: =(IF('Section Load'!AM8>0,'Section Load'!AM8,0)) -> 752.16 | AM5: =(IF('Water Report'!$G$7>0,'Water Report'!$F$7,0)) -> 128 | AN5: =(IF('Water Report'!$G$8>0,'Water Report'!$F$8,0)) -> 113 | AO5: =(IF('Water Report'!$G$9>0,'Water Report'!$H$9,0)) -> 72 | AP5: =(IF('Water Report'!$G$10>0,'Water Report'!$G$10,0)) -> 17 | AQ5: =(IF('Water Report'!$G$11>0,'Water Report'!$G$11,0)) -> 17 | AR5: =(IF('Water Report'!$G$13>0,'Water Report'!$G$13,0)) -> 40 | AS5: =(IF('Water Report'!$G$14>0,'Water Report'!$G$14,0)) -> 7 | AT5: =(IF('Water Report'!$G$15>0,'Water Report'!$G$15,0)) -> 13 | AU5: =(IF('Water Report'!$G$17>0,'Water Report'!$G$17,0)) -> 0 | AV5: =(IF('Water Report'!$G$18>0,'Water Report'!$G$18,0)) -> 9 | AW5: =(IF('Water Report'!$G$19>0,'Water Report'!$G$19,0)) -> 10 | AX5: =(IF('Water Report'!$G$21>0,'Water Report'!$G$21,0)) -> 65 | AY5: =(IF('Water Report'!$G$22>0,'Water Report'!$G$22,0)) -> 0 | AZ5: =(IF('Water Report'!$G$23>0,'Water Report'!$G$23,0)) -> 1 | BA5: =(IF('Water Report'!$G$14>0,'Water Report'!$G$14,0)) -> 7 | BB5: =(IF('Water Report'!$G$15>0,'Water Report'!$G$15,0)) -> 13 | BC5: =(IF('Water Report'!$G$13>0,'Water Report'!$G$13,0)) -> 40 | BD5: =(IF('Water Report'!$G$24>0,'Water Report'!$G$24,0)) -> 239 | BE5: =(IF('Water Report'!$G$25>0,'Water Report'!$G$25,0)) -> 139 | BF5: =(IF('Water Report'!$G$27>0,'Water Report'!$G$27,0)) -> 106 | BG5: =(IF('Section Load'!AN8>0,'Section Load'!AN8,0)) -> 914.75 | BH5: =(IF('Section Load'!AO8>0,'Section Load'!AO8,0)) -> 278.424 | BI5: =(IF('Section Load'!AP8>0,'Section Load'!AP8,0)) -> 0 | BJ5: =(IF('Section Load'!AQ8>0,'Section Load'!AQ8,0)) -> 85.56 | BK5: =(IF('Section Load'!AR8>0,'Section Load'!AR8,0)) -> 44.5 | BL5: =(IF('Section Load'!AS8>0,'Section Load'!AS8,0)) -> 3.6 | BM5: =(IF('Section Load'!AT8>0,'Section Load'!AT8,0)) -> 502.666
A6: Mumbai | B6: =B5+1 -> 5 | C6: 10 | D6: 2021 | E6: =(IF('Section Load'!F9>0,'Section Load'!F9,0)) -> 3597.87 | F6: =(IF('Section Load'!G9>0,'Section Load'!G9,0)) -> 1602.33 | G6: =(IF('Section Load'!H9>0,'Section Load'!H9,0)) -> 1798.51 | H6: =(IF('Section Load'!I9>0,'Section Load'!I9,0)) -> 2856.67 | I6: =(IF('Section Load'!J9>0,'Section Load'!J9,0)) -> 6887.75 | J6: =(IF('Section Load'!K9>0,'Section Load'!K9,0)) -> 2973.3 | K6: =(IF('Section Load'!L9>0,'Section Load'!L9,0)) -> 1183.09 | L6: =(IF('Section Load'!M9>0,'Section Load'!M9,0)) -> 903.32 | ... AL6: =(IF('Section Load'!AM9>0,'Section Load'!AM9,0)) -> 815.59 | AM6: =(IF('Water Report'!$H$7>0,'Water Report'!$H$7,0)) -> 67 | AN6: =(IF('Water Report'!$H$8>0,'Water Report'!$H$8,0)) -> 95 | AO6: =(IF('Water Report'!$H$9>0,'Water Report'!$H$9,0)) -> 72 | AP6: =(IF('Water Report'!$H$10>0,'Water Report'!$H$10,0)) -> 13 | AQ6: =(IF('Water Report'!$H$11>0,'Water Report'!$H$11,0)) -> 30 | AR6: =(IF('Water Report'!$H$13>0,'Water Report'!$H$13,0)) -> 28 | AS6: =(IF('Water Report'!$H$14>0,'Water Report'!$H$14,0)) -> 9 | AT6: =(IF('Water Report'!$H$15>0,'Water Report'!$H$15,0)) -> 10 | AU6: =(IF('Water Report'!$H$17>0,'Water Report'!$H$17,0)) -> 0 | AV6: =(IF('Water Report'!$H$18>0,'Water Report'!$H$18,0)) -> 8 | AW6: =(IF('Water Report'!$H$19>0,'Water Report'!$H$19,0)) -> 8 | AX6: =(IF('Water Report'!$H$21>0,'Water Report'!$H$21,0)) -> 122 | AY6: =(IF('Water Report'!$H$22>0,'Water Report'!$H$22,0)) -> 0 | AZ6: =(IF('Water Report'!$H$23>0,'Water Report'!$H$23,0)) -> 2 | BA6: =(IF('Water Report'!$H$14>0,'Water Report'!$H$14,0)) -> 9 | BB6: =(IF('Water Report'!$H$15>0,'Water Report'!$H$15,0)) -> 10 | BC6: =(IF('Water Report'!$H$13>0,'Water Report'!$H$13,0)) -> 28 | BD6: =(IF('Water Report'!$H$24>0,'Water Report'!$H$24,0)) -> 159 | BE6: =(IF('Water Report'!$H$25>0,'Water Report'!$H$25,0)) -> 134 | BF6: =(IF('Water Report'!$H$27>0,'Water Report'!$H$27,0)) -> 152 | BG6: =(IF('Section Load'!AN9>0,'Section Load'!AN9,0)) -> 889.92 | BH6: =(IF('Section Load'!AO9>0,'Section Load'!AO9,0)) -> 289.47 | BI6: =(IF('Section Load'!AP9>0,'Section Load'!AP9,0)) -> 0 | BJ6: =(IF('Section Load'!AQ9>0,'Section Load'!AQ9,0)) -> 87 | BK6: =(IF('Section Load'!AR9>0,'Section Load'!AR9,0)) -> 47 | BL6: =(IF('Section Load'!AS9>0,'Section Load'!AS9,0)) -> 2.1 | BM6: =(IF('Section Load'!AT9>0,'Section Load'!AT9,0)) -> 464.35
A7: Mumbai | B7: =B6+1 -> 6 | C7: 10 | D7: 2021 | E7: =(IF('Section Load'!F10>0,'Section Load'!F10,0)) -> 3610.56 | F7: =(IF('Section Load'!G10>0,'Section Load'!G10,0)) -> 1653.71 | G7: =(IF('Section Load'!H10>0,'Section Load'!H10,0)) -> 1902.3 | H7: =(IF('Section Load'!I10>0,'Section Load'!I10,0)) -> 2809.59 | I7: =(IF('Section Load'!J10>0,'Section Load'!J10,0)) -> 5959.01 | J7: =(IF('Section Load'!K10>0,'Section Load'!K10,0)) -> 2754.6 | K7: =(IF('Section Load'!L10>0,'Section Load'!L10,0)) -> 1109.71 | L7: =(IF('Section Load'!M10>0,'Section Load'!M10,0)) -> 875.98 | ... AL7: =(IF('Section Load'!AM10>0,'Section Load'!AM10,0)) -> 804.89 | AM7: =(IF('Water Report'!$I$7>0,'Water Report'!$I$7,0)) -> 144 | AN7: =(IF('Water Report'!$I$8>0,'Water Report'!$I$8,0)) -> 100 | AO7: =(IF('Water Report'!$I$9>0,'Water Report'!$I$9,0)) -> 110 | AP7: =(IF('Water Report'!$I$10>0,'Water Report'!$I$10,0)) -> 32 | AQ7: =(IF('Water Report'!$I$11>0,'Water Report'!$I$11,0)) -> 41 | AR7: =(IF('Water Report'!$I$13>0,'Water Report'!$I$13,0)) -> 14 | AS7: =(IF('Water Report'!$I$14>0,'Water Report'!$I$14,0)) -> 22 | AT7: =(IF('Water Report'!$I$15>0,'Water Report'!$I$15,0)) -> 17 | AU7: =(IF('Water Report'!$I$17>0,'Water Report'!$I$17,0)) -> 23 | AV7: =(IF('Water Report'!$I$18>0,'Water Report'!$I$18,0)) -> 10 | AW7: =(IF('Water Report'!$I$19>0,'Water Report'!$I$19,0)) -> 9 | AX7: =(IF('Water Report'!$I$21>0,'Water Report'!$I$21,0)) -> 129 | AY7: =(IF('Water Report'!$I$22>0,'Water Report'!$I$22,0)) -> 0 | AZ7: =(IF('Water Report'!$I$23>0,'Water Report'!$I$23,0)) -> 15 | BA7: =(IF('Water Report'!$I$14>0,'Water Report'!$I$14,0)) -> 22 | BB7: =(IF('Water Report'!$I$15>0,'Water Report'!$I$15,0)) -> 17 | BC7: =(IF('Water Report'!$I$13>0,'Water Report'!$I$13,0)) -> 14 | BD7: =(IF('Water Report'!$I$24>0,'Water Report'!$I$24,0)) -> 291 | BE7: =(IF('Water Report'!$I$25>0,'Water Report'!$I$25,0)) -> 222 | BF7: =(IF('Water Report'!$I$27>0,'Water Report'!$I$27,0)) -> 158 | BG7: =(IF('Section Load'!AN10>0,'Section Load'!AN10,0)) -> 955.68 | BH7: =(IF('Section Load'!AO10>0,'Section Load'!AO10,0)) -> 308.46 | BI7: =(IF('Section Load'!AP10>0,'Section Load'!AP10,0)) -> 3.4 | BJ7: =(IF('Section Load'!AQ10>0,'Section Load'!AQ10,0)) -> 88.75 | BK7: =(IF('Section Load'!AR10>0,'Section Load'!AR10,0)) -> 47 | BL7: =(IF('Section Load'!AS10>0,'Section Load'!AS10,0)) -> 3 | BM7: =(IF('Section Load'!AT10>0,'Section Load'!AT10,0)) -> 505.07
A8: Mumbai | B8: =B7+1 -> 7 | C8: 10 | D8: 2021 | E8: =(IF('Section Load'!F11>0,'Section Load'!F11,0)) -> 3710.46 | F8: =(IF('Section Load'!G11>0,'Section Load'!G11,0)) -> 1579.82 | G8: =(IF('Section Load'!H11>0,'Section Load'!H11,0)) -> 1893.21 | H8: =(IF('Section Load'!I11>0,'Section Load'!I11,0)) -> 2812.86 | I8: =(IF('Section Load'!J11>0,'Section Load'!J11,0)) -> 5341.64 | J8: =(IF('Section Load'!K11>0,'Section Load'!K11,0)) -> 2609.7 | K8: =(IF('Section Load'!L11>0,'Section Load'!L11,0)) -> 1148.88 | L8: =(IF('Section Load'!M11>0,'Section Load'!M11,0)) -> 701.53 | ... AL8: =(IF('Section Load'!AM11>0,'Section Load'!AM11,0)) -> 832.26 | AM8: =(IF('Water Report'!$J$7>0,'Water Report'!$J$7,0)) -> 133 | AN8: =(IF('Water Report'!$J$8>0,'Water Report'!$J$8,0)) -> 126 | AO8: =(IF('Water Report'!$J$9>0,'Water Report'!$J$9,0)) -> 90 | AP8: =(IF('Water Report'!$J$10>0,'Water Report'!$J$10,0)) -> 31 | AQ8: =(IF('Water Report'!$J$11>0,'Water Report'!$J$11,0)) -> 33 | AR8: =(IF('Water Report'!$J$13>0,'Water Report'!$J$13,0)) -> 25 | AS8: =(IF('Water Report'!$J$14>0,'Water Report'!$J$14,0)) -> 17 | AT8: =(IF('Water Report'!$J$15>0,'Water Report'!$J$15,0)) -> 11 | AU8: =(IF('Water Report'!$J$17>0,'Water Report'!$J$17,0)) -> 0 | AV8: =(IF('Water Report'!$J$18>0,'Water Report'!$J$18,0)) -> 13 | AW8: =(IF('Water Report'!$J$19>0,'Water Report'!$J$19,0)) -> 13 | AX8: =(IF('Water Report'!$J$21>0,'Water Report'!$J$21,0)) -> 89 | AY8: =(IF('Water Report'!$J$22>0,'Water Report'!$J$22,0)) -> 0 | AZ8: =(IF('Water Report'!$J$23>0,'Water Report'!$J$23,0)) -> 2 | BA8: =(IF('Water Report'!$J$14>0,'Water Report'!$J$14,0)) -> 17 | BB8: =(IF('Water Report'!$J$15>0,'Water Report'!$J$15,0)) -> 11 | BC8: =(IF('Water Report'!$J$13>0,'Water Report'!$J$13,0)) -> 25 | BD8: =(IF('Water Report'!$J$24>0,'Water Report'!$J$24,0)) -> 259 | BE8: =(IF('Water Report'!$J$25>0,'Water Report'!$J$25,0)) -> 182 | BF8: =(IF('Water Report'!$J$27>0,'Water Report'!$J$27,0)) -> 116 | BG8: =(IF('Section Load'!AN11>0,'Section Load'!AN11,0)) -> 962.49 | BH8: =(IF('Section Load'!AO11>0,'Section Load'!AO11,0)) -> 288.83 | BI8: =(IF('Section Load'!AP11>0,'Section Load'!AP11,0)) -> 0 | BJ8: =(IF('Section Load'!AQ11>0,'Section Load'!AQ11,0)) -> 86.23 | BK8: =(IF('Section Load'!AR11>0,'Section Load'!AR11,0)) -> 37 | BL8: =(IF('Section Load'!AS11>0,'Section Load'!AS11,0)) -> 1.3 | BM8: =(IF('Section Load'!AT11>0,'Section Load'!AT11,0)) -> 549.13
A9: Mumbai | B9: =B8+1 -> 8 | C9: 10 | D9: 2021 | E9: =(IF('Section Load'!F12>0,'Section Load'!F12,0)) -> 3847.94 | F9: =(IF('Section Load'!G12>0,'Section Load'!G12,0)) -> 1589.14 | G9: =(IF('Section Load'!H12>0,'Section Load'!H12,0)) -> 1785.87 | H9: =(IF('Section Load'!I12>0,'Section Load'!I12,0)) -> 2891.22 | I9: =(IF('Section Load'!J12>0,'Section Load'!J12,0)) -> 5181.82 | J9: =(IF('Section Load'!K12>0,'Section Load'!K12,0)) -> 2607.8 | K9: =(IF('Section Load'!L12>0,'Section Load'!L12,0)) -> 1020.8 | L9: =(IF('Section Load'!M12>0,'Section Load'!M12,0)) -> 823.66 | ... AL9: =(IF('Section Load'!AM12>0,'Section Load'!AM12,0)) -> 780.19 | AM9: =(IF('Water Report'!$K$7>0,'Water Report'!$K$7,0)) -> 118 | AN9: =(IF('Water Report'!$K$8>0,'Water Report'!$K$8,0)) -> 107 | AO9: =(IF('Water Report'!$K$9>0,'Water Report'!$K$9,0)) -> 96 | AP9: =(IF('Water Report'!$K$10>0,'Water Report'!$K$10,0)) -> 27 | AQ9: =(IF('Water Report'!$K$11>0,'Water Report'!$K$11,0)) -> 29 | AR9: =(IF('Water Report'!$K$13>0,'Water Report'!$K$13,0)) -> 30 | AS9: =(IF('Water Report'!$K$14>0,'Water Report'!$K$14,0)) -> 12 | AT9: =(IF('Water Report'!$K$15>0,'Water Report'!$K$15,0)) -> 8 | AU9: =(IF('Water Report'!$K$17>0,'Water Report'!$K$17,0)) -> 0 | AV9: =(IF('Water Report'!$K$18>0,'Water Report'!$K$18,0)) -> 14 | AW9: =(IF('Water Report'!$K$19>0,'Water Report'!$K$19,0)) -> 14 | AX9: =(IF('Water Report'!$K$21>0,'Water Report'!$K$21,0)) -> 50 | AY9: =(IF('Water Report'!$K$22>0,'Water Report'!$K$22,0)) -> 0 | AZ9: =(IF('Water Report'!$K$23>0,'Water Report'!$K$23,0)) -> 11 | BA9: =(IF('Water Report'!$K$14>0,'Water Report'!$K$14,0)) -> 12 | BB9: =(IF('Water Report'!$K$15>0,'Water Report'!$K$15,0)) -> 8 | BC9: =(IF('Water Report'!$K$13>0,'Water Report'!$K$13,0)) -> 30 | BD9: =(IF('Water Report'!$K$24>0,'Water Report'!$K$24,0)) -> 258 | BE9: =(IF('Water Report'!$K$25>0,'Water Report'!$K$25,0)) -> 172 | BF9: =(IF('Water Report'!$K$27>0,'Water Report'!$K$27,0)) -> 91 | BG9: =(IF('Section Load'!AN12>0,'Section Load'!AN12,0)) -> 1009.75 | BH9: =(IF('Section Load'!AO12>0,'Section Load'!AO12,0)) -> 287.15 | BI9: =(IF('Section Load'!AP12>0,'Section Load'!AP12,0)) -> 0 | BJ9: =(IF('Section Load'!AQ12>0,'Section Load'!AQ12,0)) -> 92.42 | BK9: =(IF('Section Load'!AR12>0,'Section Load'!AR12,0)) -> 41 | BL9: =(IF('Section Load'!AS12>0,'Section Load'!AS12,0)) -> 1.4 | BM9: =(IF('Section Load'!AT12>0,'Section Load'!AT12,0)) -> 587.78
A10: Mumbai | B10: =B9+1 -> 9 | C10: 10 | D10: 2021 | E10: =(IF('Section Load'!F13>0,'Section Load'!F13,0)) -> 3457.04 | F10: =(IF('Section Load'!G13>0,'Section Load'!G13,0)) -> 1570.33 | G10: =(IF('Section Load'!H13>0,'Section Load'!H13,0)) -> 1768.62 | H10: =(IF('Section Load'!I13>0,'Section Load'!I13,0)) -> 2928.33 | I10: =(IF('Section Load'!J13>0,'Section Load'!J13,0)) -> 5158.53 | J10: =(IF('Section Load'!K13>0,'Section Load'!K13,0)) -> 2590.9 | K10: =(IF('Section Load'!L13>0,'Section Load'!L13,0)) -> 1069.61 | L10: =(IF('Section Load'!M13>0,'Section Load'!M13,0)) -> 999.83 | ... AL10: =(IF('Section Load'!AM13>0,'Section Load'!AM13,0)) -> 557.66 | AM10: =(IF('Water Report'!$L$7>0,'Water Report'!$L$7,0)) -> 112 | AN10: =(IF('Water Report'!$L$8>0,'Water Report'!$L$8,0)) -> 75 | AO10: =(IF('Water Report'!$L$9>0,'Water Report'!$L$9,0)) -> 106 | AP10: =(IF('Water Report'!$L$10>0,'Water Report'!$L$10,0)) -> 25 | AQ10: =(IF('Water Report'!$L$11>0,'Water Report'!$L$11,0)) -> 23 | AR10: =(IF('Water Report'!$L$13>0,'Water Report'!$L$13,0)) -> 22 | AS10: =(IF('Water Report'!$L$14>0,'Water Report'!$L$14,0)) -> 8 | AT10: =(IF('Water Report'!$L$15>0,'Water Report'!$L$15,0)) -> 9 | AU10: =(IF('Water Report'!$L$17>0,'Water Report'!$L$17,0)) -> 0 | AV10: =(IF('Water Report'!$L$18>0,'Water Report'!$L$18,0)) -> 21 | AW10: =(IF('Water Report'!$L$19>0,'Water Report'!$L$19,0)) -> 14 | AX10: =(IF('Water Report'!$L$21>0,'Water Report'!$L$21,0)) -> 62 | AY10: =(IF('Water Report'!$L$22>0,'Water Report'!$L$22,0)) -> 0 | AZ10: =(IF('Water Report'!$L$23>0,'Water Report'!$L$23,0)) -> 1 | BA10: =(IF('Water Report'!$L$14>0,'Water Report'!$L$14,0)) -> 8 | BB10: =(IF('Water Report'!$L$15>0,'Water Report'!$L$15,0)) -> 9 | BC10: =(IF('Water Report'!$L$13>0,'Water Report'!$L$13,0)) -> 22 | BD10: =(IF('Water Report'!$L$24>0,'Water Report'!$L$24,0)) -> 253 | BE10: =(IF('Water Report'!$L$25>0,'Water Report'!$L$25,0)) -> 171 | BF10: =(IF('Water Report'!$L$27>0,'Water Report'!$L$27,0)) -> 85 | BG10: =(IF('Section Load'!AN13>0,'Section Load'!AN13,0)) -> 1028.08 | BH10: =(IF('Section Load'!AO13>0,'Section Load'!AO13,0)) -> 261.56 | BI10: =(IF('Section Load'!AP13>0,'Section Load'!AP13,0)) -> 0 | BJ10: =(IF('Section Load'!AQ13>0,'Section Load'!AQ13,0)) -> 94.6 | BK10: =(IF('Section Load'!AR13>0,'Section Load'!AR13,0)) -> 34 | BL10: =(IF('Section Load'!AS13>0,'Section Load'!AS13,0)) -> 2.3 | BM10: =(IF('Section Load'!AT13>0,'Section Load'!AT13,0)) -> 635.62
A11: Mumbai | B11: =B10+1 -> 10 | C11: 10 | D11: 2021 | E11: =(IF('Section Load'!F14>0,'Section Load'!F14,0)) -> 3227 | F11: =(IF('Section Load'!G14>0,'Section Load'!G14,0)) -> 1588 | G11: =(IF('Section Load'!H14>0,'Section Load'!H14,0)) -> 1767 | H11: =(IF('Section Load'!I14>0,'Section Load'!I14,0)) -> 2884 | I11: =(IF('Section Load'!J14>0,'Section Load'!J14,0)) -> 4843 | J11: =(IF('Section Load'!K14>0,'Section Load'!K14,0)) -> 2516 | K11: =(IF('Section Load'!L14>0,'Section Load'!L14,0)) -> 1089 | L11: =(IF('Section Load'!M14>0,'Section Load'!M14,0)) -> 882 | ... AL11: =(IF('Section Load'!AM14>0,'Section Load'!AM14,0)) -> 492 | AM11: =(IF('Water Report'!$M$7>0,'Water Report'!$M$7,0)) -> 100 | AN11: =(IF('Water Report'!$M$8>0,'Water Report'!$M$8,0)) -> 96 | AO11: =(IF('Water Report'!$M$9>0,'Water Report'!$M$9,0)) -> 95 | AP11: =(IF('Water Report'!$M$10>0,'Water Report'!$M$10,0)) -> 20 | AQ11: =(IF('Water Report'!$M$11>0,'Water Report'!$M$11,0)) -> 23 | AR11: =(IF('Water Report'!$M$13>0,'Water Report'!$M$13,0)) -> 36 | AS11: =(IF('Water Report'!$M$14>0,'Water Report'!$M$14,0)) -> 11 | AT11: =(IF('Water Report'!$M$15>0,'Water Report'!$M$15,0)) -> 32 | AU11: =(IF('Water Report'!$M$17>0,'Water Report'!$M$17,0)) -> 0 | AV11: =(IF('Water Report'!$M$18>0,'Water Report'!$M$18,0)) -> 11 | AW11: =(IF('Water Report'!$M$19>0,'Water Report'!$M$19,0)) -> 10 | AX11: =(IF('Water Report'!$M$21>0,'Water Report'!$M$21,0)) -> 78 | AY11: =(IF('Water Report'!$M$22>0,'Water Report'!$M$22,0)) -> 0 | AZ11: =(IF('Water Report'!$M$23>0,'Water Report'!$M$23,0)) -> 14 | BA11: =(IF('Water Report'!$M$14>0,'Water Report'!$M$14,0)) -> 11 | BB11: =(IF('Water Report'!$M$15>0,'Water Report'!$M$15,0)) -> 32 | BC11: =(IF('Water Report'!$M$13>0,'Water Report'!$M$13,0)) -> 36 | BD11: =(IF('Water Report'!$M$24>0,'Water Report'!$M$24,0)) -> 225 | BE11: =(IF('Water Report'!$M$25>0,'Water Report'!$M$25,0)) -> 181 | BF11: =(IF('Water Report'!$M$27>0,'Water Report'!$M$27,0)) -> 128 | BG11: =(IF('Section Load'!AN14>0,'Section Load'!AN14,0)) -> 1016 | BH11: =(IF('Section Load'!AO14>0,'Section Load'!AO14,0)) -> 299 | BI11: =(IF('Section Load'!AP14>0,'Section Load'!AP14,0)) -> 0 | BJ11: =(IF('Section Load'!AQ14>0,'Section Load'!AQ14,0)) -> 113 | BK11: =(IF('Section Load'!AR14>0,'Section Load'!AR14,0)) -> 35 | BL11: =(IF('Section Load'!AS14>0,'Section Load'!AS14,0)) -> 1 | BM11: =(IF('Section Load'!AT14>0,'Section Load'!AT14,0)) -> 568
A12: Mumbai | B12: =B11+1 -> 11 | C12: 10 | D12: 2021 | E12: =(IF('Section Load'!F15>0,'Section Load'!F15,0)) -> 0 | F12: =(IF('Section Load'!G15>0,'Section Load'!G15,0)) -> 0 | G12: =(IF('Section Load'!H15>0,'Section Load'!H15,0)) -> 0 | H12: =(IF('Section Load'!I15>0,'Section Load'!I15,0)) -> 0 | I12: =(IF('Section Load'!J15>0,'Section Load'!J15,0)) -> 911974.29 | J12: =(IF('Section Load'!K15>0,'Section Load'!K15,0)) -> 0 | K12: =(IF('Section Load'!L15>0,'Section Load'!L15,0)) -> 0 | L12: =(IF('Section Load'!M15>0,'Section Load'!M15,0)) -> 0 | ... AL12: =(IF('Section Load'!AM15>0,'Section Load'!AM15,0)) -> 0 | AM12: =(IF('Water Report'!$N$7>0,'Water Report'!$N$7,0)) -> 0 | AN12: =(IF('Water Report'!$N$8>0,'Water Report'!$N$8,0)) -> 0 | AO12: =(IF('Water Report'!$N$9>0,'Water Report'!$N$9,0)) -> 0 | AP12: =(IF('Water Report'!$N$10>0,'Water Report'!$N$10,0)) -> 0 | AQ12: =(IF('Water Report'!$N$11>0,'Water Report'!$N$11,0)) -> 0 | AR12: =(IF('Water Report'!$N$13>0,'Water Report'!$N$13,0)) -> 0 | AS12: =(IF('Water Report'!$N$14>0,'Water Report'!$N$14,0)) -> 0 | AT12: =(IF('Water Report'!$N$15>0,'Water Report'!$N$15,0)) -> 0 | AU12: =(IF('Water Report'!$N$17>0,'Water Report'!$N$17,0)) -> 0 | AV12: =(IF('Water Report'!$N$18>0,'Water Report'!$N$18,0)) -> 7 | AW12: =(IF('Water Report'!$N$19>0,'Water Report'!$N$19,0)) -> 0 | AX12: =(IF('Water Report'!$N$21>0,'Water Report'!$N$21,0)) -> 0 | AY12: =(IF('Water Report'!$N$22>0,'Water Report'!$N$22,0)) -> 0 | AZ12: =(IF('Water Report'!$N$23>0,'Water Report'!$N$23,0)) -> 0 | BA12: =(IF('Water Report'!$N$14>0,'Water Report'!$N$14,0)) -> 0 | BB12: =(IF('Water Report'!$N$15>0,'Water Report'!$N$15,0)) -> 0 | BC12: =(IF('Water Report'!$N$13>0,'Water Report'!$N$13,0)) -> 0 | BD12: =(IF('Water Report'!$N$24>0,'Water Report'!$N$24,0)) -> 0 | BE12: =(IF('Water Report'!$N$25>0,'Water Report'!$N$25,0)) -> 0 | BF12: =(IF('Water Report'!$N$27>0,'Water Report'!$N$27,0)) -> 0 | BG12: =(IF('Section Load'!AN15>0,'Section Load'!AN15,0)) -> 0 | BH12: =(IF('Section Load'!AO15>0,'Section Load'!AO15,0)) -> 0 | BI12: =(IF('Section Load'!AP15>0,'Section Load'!AP15,0)) -> 0 | BJ12: =(IF('Section Load'!AQ15>0,'Section Load'!AQ15,0)) -> 0 | BK12: =(IF('Section Load'!AR15>0,'Section Load'!AR15,0)) -> 0 | BL12: =(IF('Section Load'!AS15>0,'Section Load'!AS15,0)) -> 0 | BM12: =(IF('Section Load'!AT15>0,'Section Load'!AT15,0)) -> 0
A13: Mumbai | B13: =B12+1 -> 12 | C13: 10 | D13: 2021 | E13: =(IF('Section Load'!F16>0,'Section Load'!F16,0)) -> 3314 | F13: =(IF('Section Load'!G16>0,'Section Load'!G16,0)) -> 1772 | G13: =(IF('Section Load'!H16>0,'Section Load'!H16,0)) -> 1853 | H13: =(IF('Section Load'!I16>0,'Section Load'!I16,0)) -> 4376 | I13: =(IF('Section Load'!J16>0,'Section Load'!J16,0)) -> 7367 | J13: =(IF('Section Load'!K16>0,'Section Load'!K16,0)) -> 2735 | K13: =(IF('Section Load'!L16>0,'Section Load'!L16,0)) -> 1186 | L13: =(IF('Section Load'!M16>0,'Section Load'!M16,0)) -> 721 | ... AL13: =(IF('Section Load'!AM16>0,'Section Load'!AM16,0)) -> 792 | AM13: =(IF('Water Report'!$O$7>0,'Water Report'!$O$7,0)) -> 76 | AN13: =(IF('Water Report'!$O$8>0,'Water Report'!$O$8,0)) -> 121 | AO13: =(IF('Water Report'!$O$9>0,'Water Report'!$O$9,0)) -> 81 | AP13: =(IF('Water Report'!$O$10>0,'Water Report'!$O$10,0)) -> 17 | AQ13: =(IF('Water Report'!$O$11>0,'Water Report'!$O$11,0)) -> 24 | AR13: =(IF('Water Report'!$O$13>0,'Water Report'!$O$13,0)) -> 41 | AS13: =(IF('Water Report'!$O$14>0,'Water Report'!$O$14,0)) -> 8 | AT13: =(IF('Water Report'!$O$15>0,'Water Report'!$O$15,0)) -> 7 | AU13: =(IF('Water Report'!$O$17>0,'Water Report'!$O$17,0)) -> 0 | AV13: =(IF('Water Report'!$O$18>0,'Water Report'!$O$18,0)) -> 12 | AW13: =(IF('Water Report'!$O$19>0,'Water Report'!$O$19,0)) -> 12 | AX13: =(IF('Water Report'!$O$21>0,'Water Report'!$O$21,0)) -> 27 | AY13: =(IF('Water Report'!$O$22>0,'Water Report'!$O$22,0)) -> 0 | AZ13: =(IF('Water Report'!$O$23>0,'Water Report'!$O$23,0)) -> 8 | BA13: =(IF('Water Report'!$O$14>0,'Water Report'!$O$14,0)) -> 8 | BB13: =(IF('Water Report'!$O$15>0,'Water Report'!$O$15,0)) -> 7 | BC13: =(IF('Water Report'!$O$13>0,'Water Report'!$O$13,0)) -> 41 | BD13: =(IF('Water Report'!$O$24>0,'Water Report'!$O$24,0)) -> 248 | BE13: =(IF('Water Report'!$O$25>0,'Water Report'!$O$25,0)) -> 137 | BF13: =(IF('Water Report'!$O$27>0,'Water Report'!$O$27,0)) -> 76 | BG13: =(IF('Section Load'!AN16>0,'Section Load'!AN16,0)) -> 959 | BH13: =(IF('Section Load'!AO16>0,'Section Load'!AO16,0)) -> 279 | BI13: =(IF('Section Load'!AP16>0,'Section Load'!AP16,0)) -> 0 | BJ13: =(IF('Section Load'!AQ16>0,'Section Load'!AQ16,0)) -> 78 | BK13: =(IF('Section Load'!AR16>0,'Section Load'!AR16,0)) -> 50 | BL13: =(IF('Section Load'!AS16>0,'Section Load'!AS16,0)) -> 2 | BM13: =(IF('Section Load'!AT16>0,'Section Load'!AT16,0)) -> 550
A14: Mumbai | B14: =B13+1 -> 13 | C14: 10 | D14: 2021 | E14: =(IF('Section Load'!F17>0,'Section Load'!F17,0)) -> 3602 | F14: =(IF('Section Load'!G17>0,'Section Load'!G17,0)) -> 1663 | G14: =(IF('Section Load'!H17>0,'Section Load'!H17,0)) -> 1845 | H14: =(IF('Section Load'!I17>0,'Section Load'!I17,0)) -> 4354 | I14: =(IF('Section Load'!J17>0,'Section Load'!J17,0)) -> 7041 | J14: =(IF('Section Load'!K17>0,'Section Load'!K17,0)) -> 2578 | K14: =(IF('Section Load'!L17>0,'Section Load'!L17,0)) -> 1068 | L14: =(IF('Section Load'!M17>0,'Section Load'!M17,0)) -> 639 | ... AL14: =(IF('Section Load'!AM17>0,'Section Load'!AM17,0)) -> 724 | AM14: =(IF('Water Report'!$P$7>0,'Water Report'!$P$7,0)) -> 87 | AN14: =(IF('Water Report'!$P$8>0,'Water Report'!$P$8,0)) -> 96 | AO14: =(IF('Water Report'!$P$9>0,'Water Report'!$P$9,0)) -> 90 | AP14: =(IF('Water Report'!$P$10>0,'Water Report'!$P$10,0)) -> 21 | AQ14: =(IF('Water Report'!$P$11>0,'Water Report'!$P$11,0)) -> 22 | AR14: =(IF('Water Report'!$P$13>0,'Water Report'!$P$13,0)) -> 38 | AS14: =(IF('Water Report'!$P$14>0,'Water Report'!$P$14,0)) -> 10 | AT14: =(IF('Water Report'!$P$15>0,'Water Report'!$P$15,0)) -> 12 | AU14: =(IF('Water Report'!$P$17>0,'Water Report'!$P$17,0)) -> 0 | AV14: =(IF('Water Report'!$P$18>0,'Water Report'!$P$18,0)) -> 22 | AW14: =(IF('Water Report'!$P$19>0,'Water Report'!$P$19,0)) -> 10 | AX14: =(IF('Water Report'!$P$21>0,'Water Report'!$P$21,0)) -> 88 | AY14: =(IF('Water Report'!$P$22>0,'Water Report'!$P$22,0)) -> 0 | AZ14: =(IF('Water Report'!$P$23>0,'Water Report'!$P$23,0)) -> 4 | BA14: =(IF('Water Report'!$P$14>0,'Water Report'!$P$14,0)) -> 10 | BB14: =(IF('Water Report'!$P$15>0,'Water Report'!$P$15,0)) -> 12 | BC14: =(IF('Water Report'!$P$13>0,'Water Report'!$P$13,0)) -> 38 | BD14: =(IF('Water Report'!$P$24>0,'Water Report'!$P$24,0)) -> 219 | BE14: =(IF('Water Report'!$P$25>0,'Water Report'!$P$25,0)) -> 155 | BF14: =(IF('Water Report'!$P$27>0,'Water Report'!$P$27,0)) -> 130 | BG14: =(IF('Section Load'!AN17>0,'Section Load'!AN17,0)) -> 952 | BH14: =(IF('Section Load'!AO17>0,'Section Load'!AO17,0)) -> 296 | BI14: =(IF('Section Load'!AP17>0,'Section Load'!AP17,0)) -> 0 | BJ14: =(IF('Section Load'!AQ17>0,'Section Load'!AQ17,0)) -> 86 | BK14: =(IF('Section Load'!AR17>0,'Section Load'!AR17,0)) -> 43 | BL14: =(IF('Section Load'!AS17>0,'Section Load'!AS17,0)) -> 2 | BM14: =(IF('Section Load'!AT17>0,'Section Load'!AT17,0)) -> 525
A15: Mumbai | B15: =B14+1 -> 14 | C15: 10 | D15: 2021 | E15: =(IF('Section Load'!F18>0,'Section Load'!F18,0)) -> 3657 | F15: =(IF('Section Load'!G18>0,'Section Load'!G18,0)) -> 1696 | G15: =(IF('Section Load'!H18>0,'Section Load'!H18,0)) -> 1962 | H15: =(IF('Section Load'!I18>0,'Section Load'!I18,0)) -> 4269 | I15: =(IF('Section Load'!J18>0,'Section Load'!J18,0)) -> 7906 | J15: =(IF('Section Load'!K18>0,'Section Load'!K18,0)) -> 2705 | K15: =(IF('Section Load'!L18>0,'Section Load'!L18,0)) -> 1042 | L15: =(IF('Section Load'!M18>0,'Section Load'!M18,0)) -> 590 | ... AL15: =(IF('Section Load'!AM18>0,'Section Load'!AM18,0)) -> 751 | AM15: =(IF('Water Report'!$Q$7>0,'Water Report'!$Q$7,0)) -> 92 | AN15: =(IF('Water Report'!$Q$8>0,'Water Report'!$Q$8,0)) -> 127 | AO15: =(IF('Water Report'!$Q$9>0,'Water Report'!$Q$9,0)) -> 89 | AP15: =(IF('Water Report'!$Q$10>0,'Water Report'!$Q$10,0)) -> 18 | AQ15: =(IF('Water Report'!$Q$11>0,'Water Report'!$Q$11,0)) -> 19 | AR15: =(IF('Water Report'!$Q$13>0,'Water Report'!$Q$13,0)) -> 59 | AS15: =(IF('Water Report'!$Q$14>0,'Water Report'!$Q$14,0)) -> 9 | AT15: =(IF('Water Report'!$Q$15>0,'Water Report'!$Q$15,0)) -> 9 | AU15: =(IF('Water Report'!$Q$17>0,'Water Report'!$Q$17,0)) -> 0 | AV15: =(IF('Water Report'!$Q$18>0,'Water Report'!$Q$18,0)) -> 22 | AW15: =(IF('Water Report'!$Q$19>0,'Water Report'!$Q$19,0)) -> 14 | AX15: =(IF('Water Report'!$Q$21>0,'Water Report'!$Q$21,0)) -> 112 | AY15: =(IF('Water Report'!$Q$22>0,'Water Report'!$Q$22,0)) -> 0 | AZ15: =(IF('Water Report'!$Q$23>0,'Water Report'!$Q$23,0)) -> 9 | BA15: =(IF('Water Report'!$Q$14>0,'Water Report'!$Q$14,0)) -> 9 | BB15: =(IF('Water Report'!$Q$15>0,'Water Report'!$Q$15,0)) -> 9 | BC15: =(IF('Water Report'!$Q$13>0,'Water Report'!$Q$13,0)) -> 59 | BD15: =(IF('Water Report'!$Q$24>0,'Water Report'!$Q$24,0)) -> 241 | BE15: =(IF('Water Report'!$Q$25>0,'Water Report'!$Q$25,0)) -> 144 | BF15: =(IF('Water Report'!$Q$27>0,'Water Report'!$Q$27,0)) -> 180 | BG15: =(IF('Section Load'!AN18>0,'Section Load'!AN18,0)) -> 1032 | BH15: =(IF('Section Load'!AO18>0,'Section Load'!AO18,0)) -> 290 | BI15: =(IF('Section Load'!AP18>0,'Section Load'!AP18,0)) -> 0 | BJ15: =(IF('Section Load'!AQ18>0,'Section Load'!AQ18,0)) -> 105 | BK15: =(IF('Section Load'!AR18>0,'Section Load'!AR18,0)) -> 46 | BL15: =(IF('Section Load'!AS18>0,'Section Load'!AS18,0)) -> 2 | BM15: =(IF('Section Load'!AT18>0,'Section Load'!AT18,0)) -> 589
A16: Mumbai | B16: =B15+1 -> 15 | C16: 10 | D16: 2021 | E16: =(IF('Section Load'!F19>0,'Section Load'!F19,0)) -> 3380 | F16: =(IF('Section Load'!G19>0,'Section Load'!G19,0)) -> 1687 | G16: =(IF('Section Load'!H19>0,'Section Load'!H19,0)) -> 1953 | H16: =(IF('Section Load'!I19>0,'Section Load'!I19,0)) -> 4212 | I16: =(IF('Section Load'!J19>0,'Section Load'!J19,0)) -> 6623 | J16: =(IF('Section Load'!K19>0,'Section Load'!K19,0)) -> 2560 | K16: =(IF('Section Load'!L19>0,'Section Load'!L19,0)) -> 1047 | L16: =(IF('Section Load'!M19>0,'Section Load'!M19,0)) -> 935 | ... AL16: =(IF('Section Load'!AM19>0,'Section Load'!AM19,0)) -> 716 | AM16: =(IF('Water Report'!$R$7>0,'Water Report'!$R$7,0)) -> 133 | AN16: =(IF('Water Report'!$R$8>0,'Water Report'!$R$8,0)) -> 150 | AO16: =(IF('Water Report'!$R$9>0,'Water Report'!$R$9,0)) -> 120 | AP16: =(IF('Water Report'!$R$10>0,'Water Report'!$R$10,0)) -> 17 | AQ16: =(IF('Water Report'!$R$11>0,'Water Report'!$R$11,0)) -> 29 | AR16: =(IF('Water Report'!$R$13>0,'Water Report'!$R$13,0)) -> 34 | AS16: =(IF('Water Report'!$R$14>0,'Water Report'!$R$14,0)) -> 9 | AT16: =(IF('Water Report'!$R$15>0,'Water Report'!$R$15,0)) -> 7 | AU16: =(IF('Water Report'!$R$17>0,'Water Report'!$R$17,0)) -> 0 | AV16: =(IF('Water Report'!$R$18>0,'Water Report'!$R$18,0)) -> 20 | AW16: =(IF('Water Report'!$R$19>0,'Water Report'!$R$19,0)) -> 9 | AX16: =(IF('Water Report'!$R$21>0,'Water Report'!$R$21,0)) -> 110 | AY16: =(IF('Water Report'!$R$22>0,'Water Report'!$R$22,0)) -> 0 | AZ16: =(IF('Water Report'!$R$23>0,'Water Report'!$R$23,0)) -> 11 | BA16: =(IF('Water Report'!$R$14>0,'Water Report'!$R$14,0)) -> 9 | BB16: =(IF('Water Report'!$R$15>0,'Water Report'!$R$15,0)) -> 7 | BC16: =(IF('Water Report'!$R$13>0,'Water Report'!$R$13,0)) -> 34 | BD16: =(IF('Water Report'!$R$24>0,'Water Report'!$R$24,0)) -> 269 | BE16: =(IF('Water Report'!$R$25>0,'Water Report'!$R$25,0)) -> 182 | BF16: =(IF('Water Report'!$R$27>0,'Water Report'!$R$27,0)) -> 155 | BG16: =(IF('Section Load'!AN19>0,'Section Load'!AN19,0)) -> 976 | BH16: =(IF('Section Load'!AO19>0,'Section Load'!AO19,0)) -> 288 | BI16: =(IF('Section Load'!AP19>0,'Section Load'!AP19,0)) -> 0 | BJ16: =(IF('Section Load'!AQ19>0,'Section Load'!AQ19,0)) -> 82 | BK16: =(IF('Section Load'!AR19>0,'Section Load'!AR19,0)) -> 53 | BL16: =(IF('Section Load'!AS19>0,'Section Load'!AS19,0)) -> 2 | BM16: =(IF('Section Load'!AT19>0,'Section Load'!AT19,0)) -> 551
A17: Mumbai | B17: =B16+1 -> 16 | C17: 10 | D17: 2021 | E17: =(IF('Section Load'!F20>0,'Section Load'!F20,0)) -> 4287.14 | F17: =(IF('Section Load'!G20>0,'Section Load'!G20,0)) -> 1707.67 | G17: =(IF('Section Load'!H20>0,'Section Load'!H20,0)) -> 1899.88 | H17: =(IF('Section Load'!I20>0,'Section Load'!I20,0)) -> 4126.13 | I17: =(IF('Section Load'!J20>0,'Section Load'!J20,0)) -> 5850.05 | J17: =(IF('Section Load'!K20>0,'Section Load'!K20,0)) -> 2418.5 | K17: =(IF('Section Load'!L20>0,'Section Load'!L20,0)) -> 1115.23 | L17: =(IF('Section Load'!M20>0,'Section Load'!M20,0)) -> 766.8 | ... AL17: =(IF('Section Load'!AM20>0,'Section Load'!AM20,0)) -> 719.4 | AM17: =(IF('Water Report'!$S$7>0,'Water Report'!$S$7,0)) -> 116 | AN17: =(IF('Water Report'!$S$8>0,'Water Report'!$S$8,0)) -> 134 | AO17: =(IF('Water Report'!$S$9>0,'Water Report'!$S$9,0)) -> 89 | AP17: =(IF('Water Report'!$S$10>0,'Water Report'!$D$10,0)) -> 23 | AQ17: =(IF('Water Report'!$S$11>0,'Water Report'!$D$11,0)) -> 30 | AR17: =(IF('Water Report'!$S$13>0,'Water Report'!$D$13,0)) -> 41 | AS17: =(IF('Water Report'!$S$14>0,'Water Report'!$D$14,0)) -> 9 | AT17: =(IF('Water Report'!$S$15>0,'Water Report'!$D$15,0)) -> 7 | AU17: =(IF('Water Report'!$S$17>0,'Water Report'!$D$17,0)) -> 0 | AV17: =(IF('Water Report'!$S$18>0,'Water Report'!$D$18,0)) -> 16 | AW17: =(IF('Water Report'!$S$19>0,'Water Report'!$D$19,0)) -> 11 | AX17: =(IF('Water Report'!$S$21>0,'Water Report'!$D$21,0)) -> 68 | AY17: =(IF('Water Report'!$S$22>0,'Water Report'!$D$22,0)) -> 0 | AZ17: =(IF('Water Report'!$S$23>0,'Water Report'!$D$23,0)) -> 0 | BA17: =(IF('Water Report'!$S$14>0,'Water Report'!$D$14,0)) -> 9 | BB17: =(IF('Water Report'!$S$15>0,'Water Report'!$D$15,0)) -> 7 | BC17: =(IF('Water Report'!$S$13>0,'Water Report'!$D$13,0)) -> 41 | BD17: =(IF('Water Report'!$S$24>0,'Water Report'!$D$24,0)) -> 237 | BE17: =(IF('Water Report'!$S$25>0,'Water Report'!$D$25,0)) -> 166 | BF17: =(IF('Water Report'!$S$27>0,'Water Report'!$D$27,0)) -> 109 | BG17: =(IF('Section Load'!AN20>0,'Section Load'!AN20,0)) -> 978.883 | BH17: =(IF('Section Load'!AO20>0,'Section Load'!AO20,0)) -> 290.61 | BI17: =(IF('Section Load'!AP20>0,'Section Load'!AP20,0)) -> 0 | BJ17: =(IF('Section Load'!AQ20>0,'Section Load'!AQ20,0)) -> 119.178 | BK17: =(IF('Section Load'!AR20>0,'Section Load'!AR20,0)) -> 51.15 | BL17: =(IF('Section Load'!AS20>0,'Section Load'!AS20,0)) -> 3.6 | BM17: =(IF('Section Load'!AT20>0,'Section Load'!AT20,0)) -> 514.345
A18: Mumbai | B18: =B17+1 -> 17 | C18: 10 | D18: 2021 | E18: =(IF('Section Load'!F21>0,'Section Load'!F21,0)) -> 4163.32 | F18: =(IF('Section Load'!G21>0,'Section Load'!G21,0)) -> 1635.2 | G18: =(IF('Section Load'!H21>0,'Section Load'!H21,0)) -> 1880.72 | H18: =(IF('Section Load'!I21>0,'Section Load'!I21,0)) -> 4167.9 | I18: =(IF('Section Load'!J21>0,'Section Load'!J21,0)) -> 6803.13 | J18: =(IF('Section Load'!K21>0,'Section Load'!K21,0)) -> 2564.7 | K18: =(IF('Section Load'!L21>0,'Section Load'!L21,0)) -> 1251.72 | L18: =(IF('Section Load'!M21>0,'Section Load'!M21,0)) -> 742.3 | ... AL18: =(IF('Section Load'!AM21>0,'Section Load'!AM21,0)) -> 772.1 | AM18: =(IF('Water Report'!$T$7>0,'Water Report'!$T$7,0)) -> 121 | AN18: =(IF('Water Report'!$T$8>0,'Water Report'!$T$8,0)) -> 92 | AO18: =(IF('Water Report'!$T$9>0,'Water Report'!$T$9,0)) -> 98 | AP18: =(IF('Water Report'!$T$10>0,'Water Report'!$T$10,0)) -> 27 | AQ18: =(IF('Water Report'!$T$11>0,'Water Report'!$T$11,0)) -> 33 | AR18: =(IF('Water Report'!$T$13>0,'Water Report'!$T$13,0)) -> 50 | AS18: =(IF('Water Report'!$T$14>0,'Water Report'!$T$14,0)) -> 13 | AT18: =(IF('Water Report'!$T$15>0,'Water Report'!$T$15,0)) -> 16 | AU18: =(IF('Water Report'!$T$17>0,'Water Report'!$T$17,0)) -> 0 | AV18: =(IF('Water Report'!$T$18>0,'Water Report'!$T$18,0)) -> 11 | AW18: =(IF('Water Report'!$T$19>0,'Water Report'!$T$19,0)) -> 9 | AX18: =(IF('Water Report'!$T$21>0,'Water Report'!$T$21,0)) -> 106 | AY18: =(IF('Water Report'!$T$22>0,'Water Report'!$T$22,0)) -> 0 | AZ18: =(IF('Water Report'!$T$23>0,'Water Report'!$T$23,0)) -> 0 | BA18: =(IF('Water Report'!$T$14>0,'Water Report'!$T$14,0)) -> 13 | BB18: =(IF('Water Report'!$T$15>0,'Water Report'!$T$15,0)) -> 16 | BC18: =(IF('Water Report'!$T$13>0,'Water Report'!$T$13,0)) -> 50 | BD18: =(IF('Water Report'!$T$24>0,'Water Report'!$T$24,0)) -> 271 | BE18: =(IF('Water Report'!$T$25>0,'Water Report'!$T$25,0)) -> 187 | BF18: =(IF('Water Report'!$T$27>0,'Water Report'!$T$27,0)) -> 156 | BG18: =(IF('Section Load'!AN21>0,'Section Load'!AN21,0)) -> 875 | BH18: =(IF('Section Load'!AO21>0,'Section Load'!AO21,0)) -> 303.26 | BI18: =(IF('Section Load'!AP21>0,'Section Load'!AP21,0)) -> 0 | BJ18: =(IF('Section Load'!AQ21>0,'Section Load'!AQ21,0)) -> 93.742 | BK18: =(IF('Section Load'!AR21>0,'Section Load'!AR21,0)) -> 46.65 | BL18: =(IF('Section Load'!AS21>0,'Section Load'!AS21,0)) -> 2 | BM18: =(IF('Section Load'!AT21>0,'Section Load'!AT21,0)) -> 429.348
A19: Mumbai | B19: =B18+1 -> 18 | C19: 10 | D19: 2021 | E19: =(IF('Section Load'!F22>0,'Section Load'!F22,0)) -> 4594.46 | F19: =(IF('Section Load'!G22>0,'Section Load'!G22,0)) -> 1694.3 | G19: =(IF('Section Load'!H22>0,'Section Load'!H22,0)) -> 1904.47 | H19: =(IF('Section Load'!I22>0,'Section Load'!I22,0)) -> 4381.12 | I19: =(IF('Section Load'!J22>0,'Section Load'!J22,0)) -> 7730.6 | J19: =(IF('Section Load'!K22>0,'Section Load'!K22,0)) -> 2734.6 | K19: =(IF('Section Load'!L22>0,'Section Load'!L22,0)) -> 992.84 | L19: =(IF('Section Load'!M22>0,'Section Load'!M22,0)) -> 866.73 | ... AL19: =(IF('Section Load'!AM22>0,'Section Load'!AM22,0)) -> 869.22 | AM19: =(IF('Water Report'!$U$7>0,'Water Report'!$U$7,0)) -> 119 | AN19: =(IF('Water Report'!$U$8>0,'Water Report'!$U$8,0)) -> 118 | AO19: =(IF('Water Report'!$U$9>0,'Water Report'!$U$9,0)) -> 84 | AP19: =(IF('Water Report'!$U$10>0,'Water Report'!$U$10,0)) -> 22 | AQ19: =(IF('Water Report'!$U$11>0,'Water Report'!$U$11,0)) -> 26 | AR19: =(IF('Water Report'!$U$13>0,'Water Report'!$U$13,0)) -> 33 | AS19: =(IF('Water Report'!$U$14>0,'Water Report'!$U$14,0)) -> 25 | AT19: =(IF('Water Report'!$U$15>0,'Water Report'!$U$15,0)) -> 26 | AU19: =(IF('Water Report'!$U$17>0,'Water Report'!$U$17,0)) -> 13 | AV19: =(IF('Water Report'!$U$18>0,'Water Report'!$U$18,0)) -> 11 | AW19: =(IF('Water Report'!$U$19>0,'Water Report'!$U$19,0)) -> 8 | AX19: =(IF('Water Report'!$U$21>0,'Water Report'!$U$21,0)) -> 107 | AY19: =(IF('Water Report'!$U$22>0,'Water Report'!$U$22,0)) -> 0 | AZ19: =(IF('Water Report'!$U$23>0,'Water Report'!$U$23,0)) -> 0 | BA19: =(IF('Water Report'!$U$14>0,'Water Report'!$U$14,0)) -> 25 | BB19: =(IF('Water Report'!$U$15>0,'Water Report'!$U$15,0)) -> 26 | BC19: =(IF('Water Report'!$U$13>0,'Water Report'!$U$13,0)) -> 33 | BD19: =(IF('Water Report'!$U$24>0,'Water Report'!$U$24,0)) -> 250 | BE19: =(IF('Water Report'!$U$25>0,'Water Report'!$U$25,0)) -> 183 | BF19: =(IF('Water Report'!$U$27>0,'Water Report'!$U$27,0)) -> 140 | BG19: =(IF('Section Load'!AN22>0,'Section Load'!AN22,0)) -> 1093.02 | BH19: =(IF('Section Load'!AO22>0,'Section Load'!AO22,0)) -> 304.83 | BI19: =(IF('Section Load'!AP22>0,'Section Load'!AP22,0)) -> 0 | BJ19: =(IF('Section Load'!AQ22>0,'Section Load'!AQ22,0)) -> 90.9 | BK19: =(IF('Section Load'!AR22>0,'Section Load'!AR22,0)) -> 42.2 | BL19: =(IF('Section Load'!AS22>0,'Section Load'!AS22,0)) -> 2.7 | BM19: =(IF('Section Load'!AT22>0,'Section Load'!AT22,0)) -> 652.39
A20: Mumbai | B20: =B19+1 -> 19 | C20: 10 | D20: 2021 | E20: =(IF('Section Load'!F23>0,'Section Load'!F23,0)) -> 4368.17 | F20: =(IF('Section Load'!G23>0,'Section Load'!G23,0)) -> 1766.17 | G20: =(IF('Section Load'!H23>0,'Section Load'!H23,0)) -> 1891.26 | H20: =(IF('Section Load'!I23>0,'Section Load'!I23,0)) -> 4385.74 | I20: =(IF('Section Load'!J23>0,'Section Load'!J23,0)) -> 7268.88 | J20: =(IF('Section Load'!K23>0,'Section Load'!K23,0)) -> 2872 | K20: =(IF('Section Load'!L23>0,'Section Load'!L23,0)) -> 1594.28 | L20: =(IF('Section Load'!M23>0,'Section Load'!M23,0)) -> 899.3 | ... AL20: =(IF('Section Load'!AM23>0,'Section Load'!AM23,0)) -> 954.45 | AM20: =(IF('Water Report'!$V$7>0,'Water Report'!$V$7,0)) -> 111 | AN20: =(IF('Water Report'!$V$8>0,'Water Report'!$V$8,0)) -> 136 | AO20: =(IF('Water Report'!$V$9>0,'Water Report'!$V$9,0)) -> 92 | AP20: =(IF('Water Report'!$V$10>0,'Water Report'!$V$10,0)) -> 22 | AQ20: =(IF('Water Report'!$V$11>0,'Water Report'!$V$11,0)) -> 27 | AR20: =(IF('Water Report'!$V$13>0,'Water Report'!$V$13,0)) -> 55 | AS20: =(IF('Water Report'!$V$14>0,'Water Report'!$V$14,0)) -> 11 | AT20: =(IF('Water Report'!$V$15>0,'Water Report'!$V$15,0)) -> 15 | AU20: =(IF('Water Report'!$V$17>0,'Water Report'!$V$17,0)) -> 0 | AV20: =(IF('Water Report'!$V$18>0,'Water Report'!$V$18,0)) -> 9 | AW20: =(IF('Water Report'!$V$19>0,'Water Report'!$V$19,0)) -> 11 | AX20: =(IF('Water Report'!$V$21>0,'Water Report'!$V$21,0)) -> 87 | AY20: =(IF('Water Report'!$V$22>0,'Water Report'!$V$22,0)) -> 0 | AZ20: =(IF('Water Report'!$V$23>0,'Water Report'!$V$23,0)) -> 0 | BA20: =(IF('Water Report'!$V$14>0,'Water Report'!$V$14,0)) -> 11 | BB20: =(IF('Water Report'!$V$15>0,'Water Report'!$V$15,0)) -> 15 | BC20: =(IF('Water Report'!$V$13>0,'Water Report'!$V$13,0)) -> 55 | BD20: =(IF('Water Report'!$V$24>0,'Water Report'!$V$24,0)) -> 280 | BE20: =(IF('Water Report'!$V$25>0,'Water Report'!$V$25,0)) -> 167 | BF20: =(IF('Water Report'!$V$27>0,'Water Report'!$V$27,0)) -> 142 | BG20: =(IF('Section Load'!AN23>0,'Section Load'!AN23,0)) -> 1063.547 | BH20: =(IF('Section Load'!AO23>0,'Section Load'!AO23,0)) -> 304.29 | BI20: =(IF('Section Load'!AP23>0,'Section Load'!AP23,0)) -> 0 | BJ20: =(IF('Section Load'!AQ23>0,'Section Load'!AQ23,0)) -> 111.61 | BK20: =(IF('Section Load'!AR23>0,'Section Load'!AR23,0)) -> 29 | BL20: =(IF('Section Load'!AS23>0,'Section Load'!AS23,0)) -> 3.2 | BM20: =(IF('Section Load'!AT23>0,'Section Load'!AT23,0)) -> 615.447
A21: Mumbai | B21: =B20+1 -> 20 | C21: 10 | D21: 2021 | E21: =(IF('Section Load'!F24>0,'Section Load'!F24,0)) -> 2830.61 | F21: =(IF('Section Load'!G24>0,'Section Load'!G24,0)) -> 1761.66 | G21: =(IF('Section Load'!H24>0,'Section Load'!H24,0)) -> 1777.67 | H21: =(IF('Section Load'!I24>0,'Section Load'!I24,0)) -> 4331.11 | I21: =(IF('Section Load'!J24>0,'Section Load'!J24,0)) -> 7185.81 | J21: =(IF('Section Load'!K24>0,'Section Load'!K24,0)) -> 3006.2 | K21: =(IF('Section Load'!L24>0,'Section Load'!L24,0)) -> 1674.93 | L21: =(IF('Section Load'!M24>0,'Section Load'!M24,0)) -> 750.87 | ... AL21: =(IF('Section Load'!AM24>0,'Section Load'!AM24,0)) -> 786.83 | AM21: =(IF('Water Report'!$W$7>0,'Water Report'!$W$7,0)) -> 121 | AN21: =(IF('Water Report'!$W$8>0,'Water Report'!$W$8,0)) -> 146 | AO21: =(IF('Water Report'!$W$9>0,'Water Report'!$W$9,0)) -> 109 | AP21: =(IF('Water Report'!$W$10>0,'Water Report'!$W$10,0)) -> 20 | AQ21: =(IF('Water Report'!$W$11>0,'Water Report'!$W$11,0)) -> 22 | AR21: =(IF('Water Report'!$W$13>0,'Water Report'!$W$13,0)) -> 34 | AS21: =(IF('Water Report'!$W$14>0,'Water Report'!$W$14,0)) -> 10 | AT21: =(IF('Water Report'!$W$15>0,'Water Report'!$W$15,0)) -> 25 | AU21: =(IF('Water Report'!$W$17>0,'Water Report'!$W$17,0)) -> 3 | AV21: =(IF('Water Report'!$W$18>0,'Water Report'!$W$18,0)) -> 10 | AW21: =(IF('Water Report'!$W$19>0,'Water Report'!$W$19,0)) -> 10 | AX21: =(IF('Water Report'!$W$21>0,'Water Report'!$W$21,0)) -> 80 | AY21: =(IF('Water Report'!$W$22>0,'Water Report'!$W$22,0)) -> 0 | AZ21: =(IF('Water Report'!$W$23>0,'Water Report'!$W$23,0)) -> 7 | BA21: =(IF('Water Report'!$W$14>0,'Water Report'!$W$14,0)) -> 10 | BB21: =(IF('Water Report'!$W$15>0,'Water Report'!$W$15,0)) -> 25 | BC21: =(IF('Water Report'!$W$13>0,'Water Report'!$W$13,0)) -> 34 | BD21: =(IF('Water Report'!$W$24>0,'Water Report'!$W$24,0)) -> 260 | BE21: =(IF('Water Report'!$W$25>0,'Water Report'!$W$25,0)) -> 186 | BF21: =(IF('Water Report'!$W$27>0,'Water Report'!$W$27,0)) -> 121 | BG21: =(IF('Section Load'!AN24>0,'Section Load'!AN24,0)) -> 1073.55 | BH21: =(IF('Section Load'!AO24>0,'Section Load'!AO24,0)) -> 281.01 | BI21: =(IF('Section Load'!AP24>0,'Section Load'!AP24,0)) -> 0 | BJ21: =(IF('Section Load'!AQ24>0,'Section Load'!AQ24,0)) -> 112.57 | BK21: =(IF('Section Load'!AR24>0,'Section Load'!AR24,0)) -> 48 | BL21: =(IF('Section Load'!AS24>0,'Section Load'!AS24,0)) -> 2.5 | BM21: =(IF('Section Load'!AT24>0,'Section Load'!AT24,0)) -> 629.47
A22: Mumbai | B22: =B21+1 -> 21 | C22: 10 | D22: 2021 | E22: =(IF('Section Load'!F25>0,'Section Load'!F25,0)) -> 2461.3 | F22: =(IF('Section Load'!G25>0,'Section Load'!G25,0)) -> 1703 | G22: =(IF('Section Load'!H25>0,'Section Load'!H25,0)) -> 1806 | H22: =(IF('Section Load'!I25>0,'Section Load'!I25,0)) -> 2665 | I22: =(IF('Section Load'!J25>0,'Section Load'!J25,0)) -> 5767.53 | J22: =(IF('Section Load'!K25>0,'Section Load'!K25,0)) -> 2731 | K22: =(IF('Section Load'!L25>0,'Section Load'!L25,0)) -> 1412 | L22: =(IF('Section Load'!M25>0,'Section Load'!M25,0)) -> 773 | ... AL22: =(IF('Section Load'!AM25>0,'Section Load'!AM25,0)) -> 809 | AM22: =(IF('Water Report'!$X$7>0,'Water Report'!$X$7,0)) -> 117 | AN22: =(IF('Water Report'!$X$8>0,'Water Report'!$X$8,0)) -> 656 | AO22: =(IF('Water Report'!$X$9>0,'Water Report'!$X$9,0)) -> 98 | AP22: =(IF('Water Report'!$X$10>0,'Water Report'!$X$10,0)) -> 18 | AQ22: =(IF('Water Report'!$X$11>0,'Water Report'!$X$11,0)) -> 27 | AR22: =(IF('Water Report'!$X$13>0,'Water Report'!$X$13,0)) -> 48 | AS22: =(IF('Water Report'!$X$14>0,'Water Report'!$X$14,0)) -> 15 | AT22: =(IF('Water Report'!$X$15>0,'Water Report'!$X$15,0)) -> 20 | AU22: =(IF('Water Report'!$X$17>0,'Water Report'!$X$17,0)) -> 12 | AV22: =(IF('Water Report'!$X$18>0,'Water Report'!$X$18,0)) -> 12 | AW22: =(IF('Water Report'!$X$19>0,'Water Report'!$X$19,0)) -> 13 | AX22: =(IF('Water Report'!$X$21>0,'Water Report'!$X$21,0)) -> 94 | AY22: =(IF('Water Report'!$X$22>0,'Water Report'!$X$22,0)) -> 0 | AZ22: =(IF('Water Report'!$X$23>0,'Water Report'!$X$23,0)) -> 0 | BA22: =(IF('Water Report'!$X$14>0,'Water Report'!$X$14,0)) -> 15 | BB22: =(IF('Water Report'!$X$15>0,'Water Report'!$X$15,0)) -> 20 | BC22: =(IF('Water Report'!$X$13>0,'Water Report'!$X$13,0)) -> 48 | BD22: =(IF('Water Report'!$X$24>0,'Water Report'!$X$24,0)) -> 257 | BE22: =(IF('Water Report'!$X$25>0,'Water Report'!$X$25,0)) -> 178 | BF22: =(IF('Water Report'!$X$27>0,'Water Report'!$X$27,0)) -> 142 | BG22: =(IF('Section Load'!AN25>0,'Section Load'!AN25,0)) -> 1044 | BH22: =(IF('Section Load'!AO25>0,'Section Load'!AO25,0)) -> 277 | BI22: =(IF('Section Load'!AP25>0,'Section Load'!AP25,0)) -> 0 | BJ22: =(IF('Section Load'!AQ25>0,'Section Load'!AQ25,0)) -> 111 | BK22: =(IF('Section Load'!AR25>0,'Section Load'!AR25,0)) -> 46 | BL22: =(IF('Section Load'!AS25>0,'Section Load'!AS25,0)) -> 3 | BM22: =(IF('Section Load'!AT25>0,'Section Load'!AT25,0)) -> 607
