Workbook

Sheet TOTAL
A1: Site Name | B1: Day | C1: Month | D1: Year | E1: Total Electricity Kwh | F1: Electricity Tariff ($/Kwh) | G1: Total Fuel Oil (Liter) | H1: Fuel Oil $/Liter | I1: Water Utility Supply (m3) m3 | J1: Water Utility Supply (m3) $/m3 | K1: LPG (Kg) | L1: LPG $/Kg | M1: Room Nights | N1: Total Guests | O1: Food Covers
A2: Maldives at Kuda Huraa | B2: 1 | C2: 11 | D2: 2021 | E2: 22900 | F2: 0.18 | G2: 5856 | H2: 0.635 | I2: 281 | J2: 1.8 | L2: 0.9 | M2: 45 | N2: 117 | O2: 324
A3: Maldives at Kuda Huraa | B3: =B2+1 -> 2 | C3: 11 | D3: 2021 | E3: 22120 | F3: 0.18 | G3: 6334 | H3: 0.635 | I3: 285 | J3: 1.8 | L3: 0.9 | M3: 49 | N3: 125 | O3: 360
A4: Maldives at Kuda Huraa | B4: =B3+1 -> 3 | C4: 11 | D4: 2021 | E4: 17890 | F4: 0.18 | G4: 4984 | H4: 0.635 | I4: 270 | J4: 1.8 | L4: 0.9 | M4: 51 | N4: 126 | O4: 330
A5: Maldives at Kuda Huraa | B5: =B4+1 -> 4 | C5: 11 | D5: 2021 | E5: 18870 | F5: 0.18 | G5: 5030 | H5: 0.635 | I5: 235 | J5: 1.8 | L5: 0.9 | M5: 50 | N5: 127 | O5: 352
A6: Maldives at Kuda Huraa | B6: =B5+1 -> 5 | C6: 11 | D6: 2021 | E6: 20170 | F6: 0.18 | G6: 5475 | H6: 0.635 | I6: 330 | J6: 1.8 | L6: 0.9 | M6: 52 | N6: 124 | O6: 372
A7: Maldives at Kuda Huraa | B7: =B6+1 -> 6 | C7: 11 | D7: 2021 | E7: 21860 | F7: 0.18 | G7: 5959 | H7: 0.635 | I7: 308 | J7: 1.8 | L7: 0.9 | M7: 47 | N7: 103 | O7: 371
A8: Maldives at Kuda Huraa | B8: =B7+1 -> 7 | C8: 11 | D8: 2021 | E8: 21590 | F8: 0.18 | G8: 5198 | H8: 0.635 | I8: 267 | J8: 1.8 | L8: 0.9 | M8: 44 | N8: 101 | O8: 277
A9: Maldives at Kuda Huraa | B9: =B8+1 -> 8 | C9: 11 | D9: 2021 | E9: 23070 | F9: 0.18 | G9: 6515 | H9: 0.635 | I9: 324 | J9: 1.8 | L9: 0.9 | M9: 38 | N9: 90 | O9: 238
A10: Maldives at Kuda Huraa | B10: =B9+1 -> 9 | C10: 11 | D10: 2021 | E10: 22010 | F10: 0.18 | G10: 5886 | H10: 0.635 | I10: 290 | J10: 1.8 | L10: 0.9 | M10: 39 | N10: 91 | O10: 272
A11: Maldives at Kuda Huraa | B11: =B10+1 -> 10 | C11: 11 | D11: 2021 | E11: 23250 | F11: 0.18 | G11: 6805 | H11: 0.635 | I11: 307 | J11: 1.8 | L11: 0.9 | M11: 48 | N11: 110 | O11: 307
A12: Maldives at Kuda Huraa | B12: =B11+1 -> 11 | C12: 11 | D12: 2021 | E12: 23820 | F12: 0.18 | G12: 6537 | H12: 0.635 | I12: 328 | J12: 1.8 | L12: 0.9 | M12: 49 | N12: 125 | O12: 330
A13: Maldives at Kuda Huraa | B13: =B12+1 -> 12 | C13: 11 | D13: 2021 | F13: 0.18 | H13: 0.635 | J13: 1.8 | L13: 0.9
A14: Maldives at Kuda Huraa | B14: =B13+1 -> 13 | C14: 11 | D14: 2021 | F14: 0.18 | H14: 0.635 | J14: 1.8 | L14: 0.9
A15: Maldives at Kuda Huraa | B15: =B14+1 -> 14 | C15: 11 | D15: 2021 | F15: 0.18 | H15: 0.635 | J15: 1.8 | L15: 0.9
A16: Maldives at Kuda Huraa | B16: =B15+1 -> 15 | C16: 11 | D16: 2021 | F16: 0.18 | H16: 0.635 | J16: 1.8 | L16: 0.9
A17: Maldives at Kuda Huraa | B17: =B16+1 -> 16 | C17: 11 | D17: 2021 | F17: 0.18 | H17: 0.635 | J17: 1.8 | L17: 0.9
A18: Maldives at Kuda Huraa | B18: =B17+1 -> 17 | C18: 11 | D18: 2021 | F18: 0.18 | H18: 0.635 | J18: 1.8 | L18: 0.9
A19: Maldives at Kuda Huraa | B19: =B18+1 -> 18 | C19: 11 | D19: 2021 | F19: 0.18 | H19: 0.635 | J19: 1.8 | L19: 0.9
A20: Maldives at Kuda Huraa | B20: =B19+1 -> 19 | C20: 11 | D20: 2021 | F20: 0.18 | H20: 0.635 | J20: 1.8 | L20: 0.9
A21: Maldives at Kuda Huraa | B21: =B20+1 -> 20 | C21: 11 | D21: 2021 | F21: 0.18 | H21: 0.635 | J21: 1.8 | L21: 0.9
A22: Maldives at Kuda Huraa | B22: =B21+1 -> 21 | C22: 11 | D22: 2021 | F22: 0.18 | H22: 0.635 | J22: 1.8 | L22: 0.9
A23: Maldives at Kuda Huraa | B23: =B22+1 -> 22 | C23: 11 | D23: 2021 | F23: 0.18 | H23: 0.635 | J23: 1.8 | L23: 0.9
A24: Maldives at Kuda Huraa | B24: =B23+1 -> 23 | C24: 11 | D24: 2021 | F24: 0.18 | H24: 0.635 | J24: 1.8 | L24: 0.9
... A32: Maldives at Kuda Huraa | B32: =B31+1 -> 31 | C32: 11 | D32: 2021 | F32: 0.18 | H32: 0.635 | J32: 1.8 | L32: 0.9
A33: Total | E33: =SUM(E2:E32) -> 237550 | F33: 0 | G33: =SUM(G2:G32) -> 64579 | H33: 0 | I33: =SUM(I2:I32) -> 3225 | J33: 0 | K33: =SUM(K2:K32) -> 0 | L33: 0 | M33: =SUM(M2:M32) -> 512 | N33: =SUM(N2:N32) -> 1239 | O33: =SUM(O2:O32) -> 3533

Sheet Kwh Reading
A1: Electric Consumption Record (4pm)
A2: Month | B2: BOH-1/ B&C Block GWH | C2: Pastry MWH | D2: Feeder 401-419 KWH | E2: Feeder 301-319 KWH | F2: Kitchen GWH | G2: Feeder 201-208 MWH | H2: Feeder 113-123 | I2: M - Block /PC MWH | J2: Laundry MWH | M2: Feeder 101-112 MWH | N2: Feeder 217-224 | O2: Spa MWH | P2: Feeder 124-134 | Q2: Feeder 209-216 | R2: STP -1 &2 MWH | S2: STP -3 MWH | T2: Reef Club MWH | V2: Room Nights | W2: Total Guests | X2: Food Covers
J3: A | K3: B | L3: C
A4: 44501 | B4: 1.1428 | C4: 259.91 | D4: 7761780 | E4: 8551552.1 | F4: 2.6822 | G4: 850.09 | H4: 697.49 | I4: 271.94 | J4: 350.57 | K4: 375.97 | L4: 258.67 | M4: 612.53 | N4: 565.23 | O4: 178.93 | P4: 738.09 | Q4: 545.92 | R4: 189.14 | S4: 129.93 | T4: 477.21 | V4: 45 | W4: 117 | X4: 324
A5: 44502 | B5: 1.1439 | C5: 260.19 | D5: 7763758.2 | E5: 8554431.5 | F5: 2.685 | G5: 850.87 | H5: 698.18 | I5: 272.18 | J5: 351.09 | K5: 376.31 | L5: 258.93 | M5: 613.41 | N5: 566.01 | O5: 179.16 | P5: 739.17 | Q5: 546.73 | R5: 189.23 | S5: 130.07 | T5: 477.69 | V5: 49 | W5: 125 | X5: 360
A6: 44503 | B6: 1.145 | C6: 260.43 | D6: 7765747.7 | E6: 8557237.2 | F6: 2.6876 | G6: 851.59 | H6: 698.82 | I6: 272.38 | J6: 351.52 | K6: 376.62 | L6: 259.13 | M6: 614.18 | N6: 566.82 | O6: 179.31 | P6: 740.22 | Q6: 547.42 | R6: 189.45 | S6: 130.2 | T6: 478.27 | V6: 51 | W6: 126 | X6: 330
A7: 44504 | B7: 1.146 | C7: 260.71 | D7: 7767251.9 | E7: 8559521.8 | F7: 2.6902 | G7: 852.28 | H7: 699.27 | I7: 272.55 | J7: 352.04 | K7: 376.94 | L7: 259.36 | M7: 614.82 | N7: 567.43 | O7: 179.47 | P7: 741.04 | Q7: 547.84 | R7: 189.69 | S7: 130.33 | T7: 478.7 | V7: 50 | W7: 127 | X7: 352
A8: 44505 | B8: 1.147 | C8: 260.97 | D8: 7768679.6 | E8: 8561347.8 | F8: 2.6929 | G8: 852.97 | H8: 699.78 | I8: 272.74 | J8: 352.5 | K8: 377.28 | L8: 259.6 | M8: 615.47 | N8: 568.07 | O8: 179.62 | P8: 741.85 | Q8: 548.36 | R8: 189.85 | S8: 130.45 | T8: 478.97 | V8: 52 | W8: 124 | X8: 372
A9: 44506 | B9: 1.1481 | C9: 261.22 | D9: 7770392.8 | E9: 8563716.2 | F9: 2.6954 | G9: 853.71 | H9: 700.45 | I9: 272.91 | J9: 352.94 | K9: 377.6 | L9: 259.82 | M9: 616.15 | N9: 568.84 | O9: 179.77 | P9: 742.72 | Q9: 548.94 | R9: 189.95 | S9: 130.57 | T9: 479.46 | V9: 47 | W9: 103 | X9: 371
A10: 44507 | B10: 1.1491 | C10: 261.51 | D10: 7772120.7 | E10: 8566582.3 | F10: 2.6982 | G10: 854.5 | H10: 701.15 | I10: 273.13 | J10: 353.34 | K10: 377.97 | L10: 260.06 | M10: 616.97 | N10: 569.75 | O10: 179.89 | P10: 743.72 | Q10: 549.68 | R10: 190.05 | S10: 130.69 | T10: 479.98 | V10: 44 | W10: 101 | X10: 277
A11: 44508 | B11: 1.1501 | C11: 261.75 | D11: 7773990.6 | E11: 8569279.7 | F11: 2.7008 | G11: 855.28 | H11: 701.81 | I11: 273.37 | J11: 353.74 | K11: 378.29 | L11: 260.28 | M11: 617.65 | N11: 570.68 | O11: 180.01 | P11: 744.73 | Q11: 550.37 | R11: 190.14 | S11: 130.8 | T11: 480.46 | V11: 38 | W11: 90 | X11: 238
A12: 44509 | B12: 1.1511 | C12: 262 | D12: 7776185.4 | E12: 8572511.1 | F12: 2.7034 | G12: 856.06 | H12: 702.76 | I12: 273.62 | J12: 354.21 | K12: 378.69 | L12: 260.49 | M12: 618.36 | N12: 571.64 | O12: 180.09 | P12: 745.98 | Q12: 551.17 | R12: 190.15 | S12: 130.92 | T12: 480.92 | V12: 39 | W12: 91 | X12: 272
A13: 44510 | B13: 1.1521 | C13: 262.23 | D13: 7778437.5 | E13: 8575634.8 | F13: 2.7057 | G13: 856.97 | H13: 703.69 | I13: 273.86 | J13: 354.58 | K13: 379.04 | L13: 260.71 | M13: 618.98 | N13: 572.51 | O13: 180.17 | P13: 747.13 | Q13: 551.92 | R13: 190.15 | S13: 131.09 | T13: 481.42 | V13: 48 | W13: 110 | X13: 307
A14: 44511 | B14: 1.1531 | C14: 262.48 | D14: 7780769.1 | E14: 8578677.7 | F14: 2.7083 | G14: 857.91 | H14: 704.6 | I14: 274.14 | J14: 354.95 | K14: 379.38 | L14: 260.92 | M14: 619.77 | N14: 573.44 | O14: 180.26 | P14: 748.34 | Q14: 552.77 | R14: 190.15 | S14: 131.23 | T14: 481.92 | V14: 49 | W14: 125 | X14: 330
A15: 44512 | B15: 1.1542 | C15: 262.72 | D15: 7783275.1 | E15: 8581616.4 | F15: 2.7109 | G15: 858.91 | H15: 705.54 | I15: 274.43 | J15: 355.38 | K15: 379.74 | L15: 261.15 | M15: 620.59 | N15: 574.42 | O15: 180.38 | P15: 749.49 | Q15: 553.6 | R15: 190.15 | S15: 131.4 | T15: 482.39
A16: 44513 | B16: 1.1553 | C16: 263 | D16: 7785691.8 | E16: 8584174.5 | F16: 2.7136 | G16: 859.91 | H16: 706.45 | I16: 274.72 | J16: 355.74 | K16: 380.02 | L16: 261.36 | M16: 621.41 | N16: 575.39 | O16: 180.51 | P16: 750.5 | Q16: 554.43 | R16: 190.15 | S16: 131.54 | T16: 482.65
A17: 44514
A18: 44515
A19: 44516
A20: 44517
A21: 44518
A22: 44519
A23: 44520
A24: 44521
A25: 44522
A26: 44523
A27: 44524
A28: 44525
... A34: 44531
V35: =SUM(V4:V34) -> 512 | W35: =SUM(W4:W34) -> 1239 | X35: =SUM(X4:X34) -> 3533
T42: ……..

Sheet Kwh Consumption
A2: Date | B2: Total KWH | C2: Reef Club KWH | D2: Kitchen KWH | E2: Pastry KWH | F2: Laundry KWH | I2: STP -1 &2 KWH | J2: STP -3 KWH | K2: M - Block /PC KWH | L2: B&C Block KWH | M2: Guest Room Beach Pavilion & Beach Bungalow KWH | S2: Guest Room Water Bungalow KWH | U2: Spa KWH | V2: Others KWH
F3: A | G3: B | H3: C | M3: Feeder -101-112 | N3: Feeder -113-123 | O3: Feeder -124-134 | P3: Feeder -201-208 | Q3: Feeder -209-216 | R3: Feeder -217-224 | S3: Feeder -301-319 | T3: Feeder 401-419
A4: ='Kwh Reading'!A4 -> 44501 | B4: 25520 | C4: =('Kwh Reading'!T5-'Kwh Reading'!T4)*1000 -> 480 | D4: =('Kwh Reading'!F5-'Kwh Reading'!F4)*1000000 -> 2800 | E4: =('Kwh Reading'!C5-'Kwh Reading'!C4)*1000 -> 280 | F4: =('Kwh Reading'!J5-'Kwh Reading'!J4)*1000 -> 520 | G4: =('Kwh Reading'!K5-'Kwh Reading'!K4)*1000 -> 340 | H4: =('Kwh Reading'!L5-'Kwh Reading'!L4)*1000 -> 260 | I4: =('Kwh Reading'!R5-'Kwh Reading'!R4)*1000 -> 90 | J4: =('Kwh Reading'!S5-'Kwh Reading'!S4)*1000 -> 140 | K4: =('Kwh Reading'!I5-'Kwh Reading'!I4)*1000 -> 240 | L4: =('Kwh Reading'!B5-'Kwh Reading'!B4)*1000000 -> 1100 | M4: =('Kwh Reading'!M5-'Kwh Reading'!M4)*1000 -> 880 | N4: =('Kwh Reading'!H5-'Kwh Reading'!H4)*1000 -> 690 | O4: =('Kwh Reading'!P5-'Kwh Reading'!P4)*1000 -> 1080 | P4: =('Kwh Reading'!G5-'Kwh Reading'!G4)*1000 -> 780 | Q4: =('Kwh Reading'!Q5-'Kwh Reading'!Q4)*1000 -> 810 | R4: =('Kwh Reading'!N5-'Kwh Reading'!N4)*1000 -> 780 | S4: ='Kwh Reading'!E5-'Kwh Reading'!E4 -> 2879.47 | T4: ='Kwh Reading'!D5-'Kwh Reading'!D4 -> 1978.19 | U4: =('Kwh Reading'!O5-'Kwh Reading'!O4)*1000 -> 230 | V4: =B4-(SUM(C4:U4)) -> 9162.34
A5: ='Kwh Reading'!A5 -> 44502 | B5: =TOTAL!E3 -> 22120 | C5: =('Kwh Reading'!T6-'Kwh Reading'!T5)*1000 -> 580 | D5: =('Kwh Reading'!F6-'Kwh Reading'!F5)*1000000 -> 2600 | E5: =('Kwh Reading'!C6-'Kwh Reading'!C5)*1000 -> 240 | F5: =('Kwh Reading'!J6-'Kwh Reading'!J5)*1000 -> 430 | G5: =('Kwh Reading'!K6-'Kwh Reading'!K5)*1000 -> 310 | H5: =('Kwh Reading'!L6-'Kwh Reading'!L5)*1000 -> 200 | I5: =('Kwh Reading'!R6-'Kwh Reading'!R5)*1000 -> 220 | J5: =('Kwh Reading'!S6-'Kwh Reading'!S5)*1000 -> 130 | K5: =('Kwh Reading'!I6-'Kwh Reading'!I5)*1000 -> 200 | L5: =('Kwh Reading'!B6-'Kwh Reading'!B5)*1000000 -> 1100 | M5: =('Kwh Reading'!M6-'Kwh Reading'!M5)*1000 -> 770 | N5: =('Kwh Reading'!H6-'Kwh Reading'!H5)*1000 -> 640 | O5: =('Kwh Reading'!P6-'Kwh Reading'!P5)*1000 -> 1050 | P5: =('Kwh Reading'!G6-'Kwh Reading'!G5)*1000 -> 720 | Q5: =('Kwh Reading'!Q6-'Kwh Reading'!Q5)*1000 -> 690 | R5: =('Kwh Reading'!N6-'Kwh Reading'!N5)*1000 -> 810 | S5: ='Kwh Reading'!E6-'Kwh Reading'!E5 -> 2805.71 | T5: ='Kwh Reading'!D6-'Kwh Reading'!D5 -> 1989.45 | U5: =('Kwh Reading'!O6-'Kwh Reading'!O5)*1000 -> 150 | V5: =B5-(SUM(C5:U5)) -> 6484.84
A6: ='Kwh Reading'!A6 -> 44503 | B6: =TOTAL!E4 -> 17890 | C6: =('Kwh Reading'!T7-'Kwh Reading'!T6)*1000 -> 430 | D6: =('Kwh Reading'!F7-'Kwh Reading'!F6)*1000000 -> 2600 | E6: =('Kwh Reading'!C7-'Kwh Reading'!C6)*1000 -> 280 | F6: =('Kwh Reading'!J7-'Kwh Reading'!J6)*1000 -> 520 | G6: =('Kwh Reading'!K7-'Kwh Reading'!K6)*1000 -> 320 | H6: =('Kwh Reading'!L7-'Kwh Reading'!L6)*1000 -> 230 | I6: =('Kwh Reading'!R7-'Kwh Reading'!R6)*1000 -> 240 | J6: =('Kwh Reading'!S7-'Kwh Reading'!S6)*1000 -> 130 | K6: =('Kwh Reading'!I7-'Kwh Reading'!I6)*1000 -> 170 | L6: =('Kwh Reading'!B7-'Kwh Reading'!B6)*1000000 -> 1000 | M6: =('Kwh Reading'!M7-'Kwh Reading'!M6)*1000 -> 640 | N6: =('Kwh Reading'!H7-'Kwh Reading'!H6)*1000 -> 450 | O6: =('Kwh Reading'!P7-'Kwh Reading'!P6)*1000 -> 820 | P6: =('Kwh Reading'!G7-'Kwh Reading'!G6)*1000 -> 690 | Q6: =('Kwh Reading'!Q7-'Kwh Reading'!Q6)*1000 -> 420 | R6: =('Kwh Reading'!N7-'Kwh Reading'!N6)*1000 -> 610 | S6: ='Kwh Reading'!E7-'Kwh Reading'!E6 -> 2284.61 | T6: ='Kwh Reading'!D7-'Kwh Reading'!D6 -> 1504.19 | U6: =('Kwh Reading'!O7-'Kwh Reading'!O6)*1000 -> 160 | V6: =B6-(SUM(C6:U6)) -> 4391.2
A7: ='Kwh Reading'!A7 -> 44504 | B7: 18870 | C7: =('Kwh Reading'!T8-'Kwh Reading'!T7)*1000 -> 270 | D7: =('Kwh Reading'!F8-'Kwh Reading'!F7)*1000000 -> 2700 | E7: =('Kwh Reading'!C8-'Kwh Reading'!C7)*1000 -> 260 | F7: =('Kwh Reading'!J8-'Kwh Reading'!J7)*1000 -> 460 | G7: =('Kwh Reading'!K8-'Kwh Reading'!K7)*1000 -> 340 | H7: =('Kwh Reading'!L8-'Kwh Reading'!L7)*1000 -> 240 | I7: =('Kwh Reading'!R8-'Kwh Reading'!R7)*1000 -> 160 | J7: =('Kwh Reading'!S8-'Kwh Reading'!S7)*1000 -> 120 | K7: =('Kwh Reading'!I8-'Kwh Reading'!I7)*1000 -> 190 | L7: =('Kwh Reading'!B8-'Kwh Reading'!B7)*1000000 -> 1000 | M7: =('Kwh Reading'!M8-'Kwh Reading'!M7)*1000 -> 650 | N7: =('Kwh Reading'!H8-'Kwh Reading'!H7)*1000 -> 510 | O7: =('Kwh Reading'!P8-'Kwh Reading'!P7)*1000 -> 810 | P7: =('Kwh Reading'!G8-'Kwh Reading'!G7)*1000 -> 690 | Q7: =('Kwh Reading'!Q8-'Kwh Reading'!Q7)*1000 -> 520 | R7: =('Kwh Reading'!N8-'Kwh Reading'!N7)*1000 -> 640 | S7: ='Kwh Reading'!E8-'Kwh Reading'!E7 -> 1826.01 | T7: ='Kwh Reading'!D8-'Kwh Reading'!D7 -> 1427.73 | U7: =('Kwh Reading'!O8-'Kwh Reading'!O7)*1000 -> 150 | V7: =B7-(SUM(C7:U7)) -> 5906.26
A8: ='Kwh Reading'!A8 -> 44505 | B8: =TOTAL!E6 -> 20170 | C8: =('Kwh Reading'!T9-'Kwh Reading'!T8)*1000 -> 490 | D8: =('Kwh Reading'!F9-'Kwh Reading'!F8)*1000000 -> 2500 | E8: =('Kwh Reading'!C9-'Kwh Reading'!C8)*1000 -> 250 | F8: =('Kwh Reading'!J9-'Kwh Reading'!J8)*1000 -> 440 | G8: =('Kwh Reading'!K9-'Kwh Reading'!K8)*1000 -> 320 | H8: =('Kwh Reading'!L9-'Kwh Reading'!L8)*1000 -> 220 | I8: =('Kwh Reading'!R9-'Kwh Reading'!R8)*1000 -> 100 | J8: =('Kwh Reading'!S9-'Kwh Reading'!S8)*1000 -> 120 | K8: =('Kwh Reading'!I9-'Kwh Reading'!I8)*1000 -> 170 | L8: =('Kwh Reading'!B9-'Kwh Reading'!B8)*1000000 -> 1100 | M8: =('Kwh Reading'!M9-'Kwh Reading'!M8)*1000 -> 680 | N8: =('Kwh Reading'!H9-'Kwh Reading'!H8)*1000 -> 670 | O8: =('Kwh Reading'!P9-'Kwh Reading'!P8)*1000 -> 870 | P8: =('Kwh Reading'!G9-'Kwh Reading'!G8)*1000 -> 740 | Q8: =('Kwh Reading'!Q9-'Kwh Reading'!Q8)*1000 -> 580 | R8: =('Kwh Reading'!N9-'Kwh Reading'!N8)*1000 -> 770 | S8: ='Kwh Reading'!E9-'Kwh Reading'!E8 -> 2368.38 | T8: ='Kwh Reading'!D9-'Kwh Reading'!D8 -> 1713.16 | U8: =('Kwh Reading'!O9-'Kwh Reading'!O8)*1000 -> 150 | V8: =B8-(SUM(C8:U8)) -> 5918.46
A9: ='Kwh Reading'!A9 -> 44506 | B9: =TOTAL!E7 -> 21860 | C9: =('Kwh Reading'!T10-'Kwh Reading'!T9)*1000 -> 520 | D9: =('Kwh Reading'!F10-'Kwh Reading'!F9)*1000000 -> 2800 | E9: =('Kwh Reading'!C10-'Kwh Reading'!C9)*1000 -> 290 | F9: =('Kwh Reading'!J10-'Kwh Reading'!J9)*1000 -> 400 | G9: =('Kwh Reading'!K10-'Kwh Reading'!K9)*1000 -> 370 | H9: =('Kwh Reading'!L10-'Kwh Reading'!L9)*1000 -> 240 | I9: =('Kwh Reading'!R10-'Kwh Reading'!R9)*1000 -> 100 | J9: =('Kwh Reading'!S10-'Kwh Reading'!S9)*1000 -> 120 | K9: =('Kwh Reading'!I10-'Kwh Reading'!I9)*1000 -> 220 | L9: =('Kwh Reading'!B10-'Kwh Reading'!B9)*1000000 -> 1000 | M9: =('Kwh Reading'!M10-'Kwh Reading'!M9)*1000 -> 820 | N9: =('Kwh Reading'!H10-'Kwh Reading'!H9)*1000 -> 700 | O9: =('Kwh Reading'!P10-'Kwh Reading'!P9)*1000 -> 1000 | P9: =('Kwh Reading'!G10-'Kwh Reading'!G9)*1000 -> 790 | Q9: =('Kwh Reading'!Q10-'Kwh Reading'!Q9)*1000 -> 740 | R9: =('Kwh Reading'!N10-'Kwh Reading'!N9)*1000 -> 910 | S9: ='Kwh Reading'!E10-'Kwh Reading'!E9 -> 2866.03 | T9: ='Kwh Reading'!D10-'Kwh Reading'!D9 -> 1727.9 | U9: =('Kwh Reading'!O10-'Kwh Reading'!O9)*1000 -> 120 | V9: =B9-(SUM(C9:U9)) -> 6126.07
A10: ='Kwh Reading'!A10 -> 44507 | B10: =TOTAL!E8 -> 21590 | C10: =('Kwh Reading'!T11-'Kwh Reading'!T10)*1000 -> 480 | D10: =('Kwh Reading'!F11-'Kwh Reading'!F10)*1000000 -> 2600 | E10: =('Kwh Reading'!C11-'Kwh Reading'!C10)*1000 -> 240 | F10: =('Kwh Reading'!J11-'Kwh Reading'!J10)*1000 -> 400 | G10: =('Kwh Reading'!K11-'Kwh Reading'!K10)*1000 -> 320 | H10: =('Kwh Reading'!L11-'Kwh Reading'!L10)*1000 -> 220 | I10: =('Kwh Reading'!R11-'Kwh Reading'!R10)*1000 -> 90 | J10: =('Kwh Reading'!S11-'Kwh Reading'!S10)*1000 -> 110 | K10: =('Kwh Reading'!I11-'Kwh Reading'!I10)*1000 -> 240 | L10: =('Kwh Reading'!B11-'Kwh Reading'!B10)*1000000 -> 1000 | M10: =('Kwh Reading'!M11-'Kwh Reading'!M10)*1000 -> 680 | N10: =('Kwh Reading'!H11-'Kwh Reading'!H10)*1000 -> 660 | O10: =('Kwh Reading'!P11-'Kwh Reading'!P10)*1000 -> 1010 | P10: =('Kwh Reading'!G11-'Kwh Reading'!G10)*1000 -> 780 | Q10: =('Kwh Reading'!Q11-'Kwh Reading'!Q10)*1000 -> 690 | R10: =('Kwh Reading'!N11-'Kwh Reading'!N10)*1000 -> 930 | S10: ='Kwh Reading'!E11-'Kwh Reading'!E10 -> 2697.42 | T10: ='Kwh Reading'!D11-'Kwh Reading'!D10 -> 1869.97 | U10: =('Kwh Reading'!O11-'Kwh Reading'!O10)*1000 -> 120 | V10: =B10-(SUM(C10:U10)) -> 6452.61
A11: ='Kwh Reading'!A11 -> 44508 | B11: =TOTAL!E9 -> 23070 | C11: =('Kwh Reading'!T12-'Kwh Reading'!T11)*1000 -> 460 | D11: =('Kwh Reading'!F12-'Kwh Reading'!F11)*1000000 -> 2600 | E11: =('Kwh Reading'!C12-'Kwh Reading'!C11)*1000 -> 250 | F11: =('Kwh Reading'!J12-'Kwh Reading'!J11)*1000 -> 470 | G11: =('Kwh Reading'!K12-'Kwh Reading'!K11)*1000 -> 400 | H11: =('Kwh Reading'!L12-'Kwh Reading'!L11)*1000 -> 210 | I11: =('Kwh Reading'!R12-'Kwh Reading'!R11)*1000 -> 10 | J11: =('Kwh Reading'!S12-'Kwh Reading'!S11)*1000 -> 120 | K11: =('Kwh Reading'!I12-'Kwh Reading'!I11)*1000 -> 250 | L11: =('Kwh Reading'!B12-'Kwh Reading'!B11)*1000000 -> 1000 | M11: =('Kwh Reading'!M12-'Kwh Reading'!M11)*1000 -> 710 | N11: =('Kwh Reading'!H12-'Kwh Reading'!H11)*1000 -> 950 | O11: =('Kwh Reading'!P12-'Kwh Reading'!P11)*1000 -> 1250 | P11: =('Kwh Reading'!G12-'Kwh Reading'!G11)*1000 -> 780 | Q11: =('Kwh Reading'!Q12-'Kwh Reading'!Q11)*1000 -> 800 | R11: =('Kwh Reading'!N12-'Kwh Reading'!N11)*1000 -> 960 | S11: ='Kwh Reading'!E12-'Kwh Reading'!E11 -> 3231.41 | T11: ='Kwh Reading'!D12-'Kwh Reading'!D11 -> 2194.77 | U11: =('Kwh Reading'!O12-'Kwh Reading'!O11)*1000 -> 80 | V11: =B11-(SUM(C11:U11)) -> 6343.82
A12: ='Kwh Reading'!A12 -> 44509 | B12: =TOTAL!E10 -> 22010 | C12: =('Kwh Reading'!T13-'Kwh Reading'!T12)*1000 -> 500 | D12: =('Kwh Reading'!F13-'Kwh Reading'!F12)*1000000 -> 2300 | E12: =('Kwh Reading'!C13-'Kwh Reading'!C12)*1000 -> 230 | F12: =('Kwh Reading'!J13-'Kwh Reading'!J12)*1000 -> 370 | G12: =('Kwh Reading'!K13-'Kwh Reading'!K12)*1000 -> 350 | H12: =('Kwh Reading'!L13-'Kwh Reading'!L12)*1000 -> 220 | I12: =('Kwh Reading'!R13-'Kwh Reading'!R12)*1000 -> 0 | J12: =('Kwh Reading'!S13-'Kwh Reading'!S12)*1000 -> 170 | K12: =('Kwh Reading'!I13-'Kwh Reading'!I12)*1000 -> 240 | L12: =('Kwh Reading'!B13-'Kwh Reading'!B12)*1000000 -> 1000 | M12: =('Kwh Reading'!M13-'Kwh Reading'!M12)*1000 -> 620 | N12: =('Kwh Reading'!H13-'Kwh Reading'!H12)*1000 -> 930 | O12: =('Kwh Reading'!P13-'Kwh Reading'!P12)*1000 -> 1150 | P12: =('Kwh Reading'!G13-'Kwh Reading'!G12)*1000 -> 910 | Q12: =('Kwh Reading'!Q13-'Kwh Reading'!Q12)*1000 -> 750 | R12: =('Kwh Reading'!N13-'Kwh Reading'!N12)*1000 -> 870 | S12: ='Kwh Reading'!E13-'Kwh Reading'!E12 -> 3123.67 | T12: ='Kwh Reading'!D13-'Kwh Reading'!D12 -> 2252.09 | U12: =('Kwh Reading'!O13-'Kwh Reading'!O12)*1000 -> 80 | V12: =B12-(SUM(C12:U12)) -> 5944.24
A13: ='Kwh Reading'!A13 -> 44510 | B13: =TOTAL!E11 -> 23250 | C13: =('Kwh Reading'!T14-'Kwh Reading'!T13)*1000 -> 500 | D13: =('Kwh Reading'!F14-'Kwh Reading'!F13)*1000000 -> 2600 | E13: =('Kwh Reading'!C14-'Kwh Reading'!C13)*1000 -> 250 | F13: =('Kwh Reading'!J14-'Kwh Reading'!J13)*1000 -> 370 | G13: =('Kwh Reading'!K14-'Kwh Reading'!K13)*1000 -> 340 | H13: =('Kwh Reading'!L14-'Kwh Reading'!L13)*1000 -> 210 | I13: =('Kwh Reading'!R14-'Kwh Reading'!R13)*1000 -> 0 | J13: =('Kwh Reading'!S14-'Kwh Reading'!S13)*1000 -> 140 | K13: =('Kwh Reading'!I14-'Kwh Reading'!I13)*1000 -> 280 | L13: =('Kwh Reading'!B14-'Kwh Reading'!B13)*1000000 -> 1000 | M13: =('Kwh Reading'!M14-'Kwh Reading'!M13)*1000 -> 790 | N13: =('Kwh Reading'!H14-'Kwh Reading'!H13)*1000 -> 910 | O13: =('Kwh Reading'!P14-'Kwh Reading'!P13)*1000 -> 1210 | P13: =('Kwh Reading'!G14-'Kwh Reading'!G13)*1000 -> 940 | Q13: =('Kwh Reading'!Q14-'Kwh Reading'!Q13)*1000 -> 850 | R13: =('Kwh Reading'!N14-'Kwh Reading'!N13)*1000 -> 930 | S13: ='Kwh Reading'!E14-'Kwh Reading'!E13 -> 3042.94 | T13: ='Kwh Reading'!D14-'Kwh Reading'!D13 -> 2331.66 | U13: =('Kwh Reading'!O14-'Kwh Reading'!O13)*1000 -> 90 | V13: =B13-(SUM(C13:U13)) -> 6465.4
A14: ='Kwh Reading'!A14 -> 44511 | B14: =TOTAL!E12 -> 23820 | C14: =('Kwh Reading'!T15-'Kwh Reading'!T14)*1000 -> 470 | D14: =('Kwh Reading'!F15-'Kwh Reading'!F14)*1000000 -> 2600 | E14: =('Kwh Reading'!C15-'Kwh Reading'!C14)*1000 -> 240 | F14: =('Kwh Reading'!J15-'Kwh Reading'!J14)*1000 -> 430 | G14: =('Kwh Reading'!K15-'Kwh Reading'!K14)*1000 -> 360 | H14: =('Kwh Reading'!L15-'Kwh Reading'!L14)*1000 -> 230 | I14: =('Kwh Reading'!R15-'Kwh Reading'!R14)*1000 -> 0 | J14: =('Kwh Reading'!S15-'Kwh Reading'!S14)*1000 -> 170 | K14: =('Kwh Reading'!I15-'Kwh Reading'!I14)*1000 -> 290 | L14: =('Kwh Reading'!B15-'Kwh Reading'!B14)*1000000 -> 1100 | M14: =('Kwh Reading'!M15-'Kwh Reading'!M14)*1000 -> 820 | N14: =('Kwh Reading'!H15-'Kwh Reading'!H14)*1000 -> 940 | O14: =('Kwh Reading'!P15-'Kwh Reading'!P14)*1000 -> 1150 | P14: =('Kwh Reading'!G15-'Kwh Reading'!G14)*1000 -> 1000 | Q14: =('Kwh Reading'!Q15-'Kwh Reading'!Q14)*1000 -> 830 | R14: =('Kwh Reading'!N15-'Kwh Reading'!N14)*1000 -> 980 | S14: ='Kwh Reading'!E15-'Kwh Reading'!E14 -> 2938.67 | T14: ='Kwh Reading'!D15-'Kwh Reading'!D14 -> 2505.99 | U14: =('Kwh Reading'!O15-'Kwh Reading'!O14)*1000 -> 120 | V14: =B14-(SUM(C14:U14)) -> 6645.34
A15: ='Kwh Reading'!A15 -> 44512 | B15: =TOTAL!E13 -> 0 | C15: =('Kwh Reading'!T16-'Kwh Reading'!T15)*1000 -> 260 | D15: =('Kwh Reading'!F16-'Kwh Reading'!F15)*1000000 -> 2700 | E15: =('Kwh Reading'!C16-'Kwh Reading'!C15)*1000 -> 280 | F15: =('Kwh Reading'!J16-'Kwh Reading'!J15)*1000 -> 360 | G15: =('Kwh Reading'!K16-'Kwh Reading'!K15)*1000 -> 280 | H15: =('Kwh Reading'!L16-'Kwh Reading'!L15)*1000 -> 210 | I15: =('Kwh Reading'!R16-'Kwh Reading'!R15)*1000 -> 0 | J15: =('Kwh Reading'!S16-'Kwh Reading'!S15)*1000 -> 140 | K15: =('Kwh Reading'!I16-'Kwh Reading'!I15)*1000 -> 290 | L15: =('Kwh Reading'!B16-'Kwh Reading'!B15)*1000000 -> 1100 | M15: =('Kwh Reading'!M16-'Kwh Reading'!M15)*1000 -> 820 | N15: =('Kwh Reading'!H16-'Kwh Reading'!H15)*1000 -> 910 | O15: =('Kwh Reading'!P16-'Kwh Reading'!P15)*1000 -> 1010 | P15: =('Kwh Reading'!G16-'Kwh Reading'!G15)*1000 -> 1000 | Q15: =('Kwh Reading'!Q16-'Kwh Reading'!Q15)*1000 -> 830 | R15: =('Kwh Reading'!N16-'Kwh Reading'!N15)*1000 -> 970 | S15: ='Kwh Reading'!E16-'Kwh Reading'!E15 -> 2558.09 | T15: ='Kwh Reading'!D16-'Kwh Reading'!D15 -> 2416.64 | U15: =('Kwh Reading'!O16-'Kwh Reading'!O15)*1000 -> 130 | V15: =B15-(SUM(C15:U15)) -> -16264.73
A16: ='Kwh Reading'!A16 -> 44513 | B16: =TOTAL!E14 -> 0 | C16: =('Kwh Reading'!T17-'Kwh Reading'!T16)*1000 -> -482650 | D16: =('Kwh Reading'!F17-'Kwh Reading'!F16)*1000000 -> -2713600 | E16: =('Kwh Reading'!C17-'Kwh Reading'!C16)*1000 -> -263000 | F16: =('Kwh Reading'!J17-'Kwh Reading'!J16)*1000 -> -355740 | G16: =('Kwh Reading'!K17-'Kwh Reading'!K16)*1000 -> -380020 | H16: =('Kwh Reading'!L17-'Kwh Reading'!L16)*1000 -> -261360 | I16: =('Kwh Reading'!R17-'Kwh Reading'!R16)*1000 -> -190150 | J16: =('Kwh Reading'!S17-'Kwh Reading'!S16)*1000 -> -131540 | K16: =('Kwh Reading'!I17-'Kwh Reading'!I16)*1000 -> -274720 | L16: =('Kwh Reading'!B17-'Kwh Reading'!B16)*1000000 -> -1155300 | M16: =('Kwh Reading'!M17-'Kwh Reading'!M16)*1000 -> -621410 | N16: =('Kwh Reading'!H17-'Kwh Reading'!H16)*1000 -> -706450 | O16: =('Kwh Reading'!P17-'Kwh Reading'!P16)*1000 -> -750500 | P16: =('Kwh Reading'!G17-'Kwh Reading'!G16)*1000 -> -859910 | Q16: =('Kwh Reading'!Q17-'Kwh Reading'!Q16)*1000 -> -554430 | R16: =('Kwh Reading'!N17-'Kwh Reading'!N16)*1000 -> -575390 | S16: ='Kwh Reading'!E17-'Kwh Reading'!E16 -> -8584174.5 | T16: ='Kwh Reading'!D17-'Kwh Reading'!D16 -> -7785691.8 | U16: =('Kwh Reading'!O17-'Kwh Reading'!O16)*1000 -> -180510 | V16: =B16-(SUM(C16:U16)) -> 26826546
A17: ='Kwh Reading'!A17 -> 44514 | B17: =TOTAL!E15 -> 0 | C17: =('Kwh Reading'!T18-'Kwh Reading'!T17)*1000 -> 0 | D17: =('Kwh Reading'!F18-'Kwh Reading'!F17)*1000000 -> 0 | E17: =('Kwh Reading'!C18-'Kwh Reading'!C17)*1000 -> 0 | F17: =('Kwh Reading'!J18-'Kwh Reading'!J17)*1000 -> 0 | G17: =('Kwh Reading'!K18-'Kwh Reading'!K17)*1000 -> 0 | H17: =('Kwh Reading'!L18-'Kwh Reading'!L17)*1000 -> 0 | I17: =('Kwh Reading'!R18-'Kwh Reading'!R17)*1000 -> 0 | J17: =('Kwh Reading'!S18-'Kwh Reading'!S17)*1000 -> 0 | K17: =('Kwh Reading'!I18-'Kwh Reading'!I17)*1000 -> 0 | L17: =('Kwh Reading'!B18-'Kwh Reading'!B17)*1000000 -> 0 | M17: =('Kwh Reading'!M18-'Kwh Reading'!M17)*1000 -> 0 | N17: =('Kwh Reading'!H18-'Kwh Reading'!H17)*1000 -> 0 | O17: =('Kwh Reading'!P18-'Kwh Reading'!P17)*1000 -> 0 | P17: =('Kwh Reading'!G18-'Kwh Reading'!G17)*1000 -> 0 | Q17: =('Kwh Reading'!Q18-'Kwh Reading'!Q17)*1000 -> 0 | R17: =('Kwh Reading'!N18-'Kwh Reading'!N17)*1000 -> 0 | S17: ='Kwh Reading'!E18-'Kwh Reading'!E17 -> 0 | T17: ='Kwh Reading'!D18-'Kwh Reading'!D17 -> 0 | U17: =('Kwh Reading'!O18-'Kwh Reading'!O17)*1000 -> 0 | V17: =B17-(SUM(C17:U17)) -> 0
A18: ='Kwh Reading'!A18 -> 44515 | B18: =TOTAL!E16 -> 0 | C18: =('Kwh Reading'!T19-'Kwh Reading'!T18)*1000 -> 0 | D18: =('Kwh Reading'!F19-'Kwh Reading'!F18)*1000000 -> 0 | E18: =('Kwh Reading'!C19-'Kwh Reading'!C18)*1000 -> 0 | F18: =('Kwh Reading'!J19-'Kwh Reading'!J18)*1000 -> 0 | G18: =('Kwh Reading'!K19-'Kwh Reading'!K18)*1000 -> 0 | H18: =('Kwh Reading'!L19-'Kwh Reading'!L18)*1000 -> 0 | I18: =('Kwh Reading'!R19-'Kwh Reading'!R18)*1000 -> 0 | J18: =('Kwh Reading'!S19-'Kwh Reading'!S18)*1000 -> 0 | K18: =('Kwh Reading'!I19-'Kwh Reading'!I18)*1000 -> 0 | L18: =('Kwh Reading'!B19-'Kwh Reading'!B18)*1000000 -> 0 | M18: =('Kwh Reading'!M19-'Kwh Reading'!M18)*1000 -> 0 | N18: =('Kwh Reading'!H19-'Kwh Reading'!H18)*1000 -> 0 | O18: =('Kwh Reading'!P19-'Kwh Reading'!P18)*1000 -> 0 | P18: =('Kwh Reading'!G19-'Kwh Reading'!G18)*1000 -> 0 | Q18: =('Kwh Reading'!Q19-'Kwh Reading'!Q18)*1000 -> 0 | R18: =('Kwh Reading'!N19-'Kwh Reading'!N18)*1000 -> 0 | S18: ='Kwh Reading'!E19-'Kwh Reading'!E18 -> 0 | T18: ='Kwh Reading'!D19-'Kwh Reading'!D18 -> 0 | U18: =('Kwh Reading'!O19-'Kwh Reading'!O18)*1000 -> 0 | V18: =B18-(SUM(C18:U18)) -> 0
A19: ='Kwh Reading'!A19 -> 44516 | B19: =TOTAL!E17 -> 0 | C19: =('Kwh Reading'!T20-'Kwh Reading'!T19)*1000 -> 0 | D19: =('Kwh Reading'!F20-'Kwh Reading'!F19)*1000000 -> 0 | E19: =('Kwh Reading'!C20-'Kwh Reading'!C19)*1000 -> 0 | F19: =('Kwh Reading'!J20-'Kwh Reading'!J19)*1000 -> 0 | G19: =('Kwh Reading'!K20-'Kwh Reading'!K19)*1000 -> 0 | H19: =('Kwh Reading'!L20-'Kwh Reading'!L19)*1000 -> 0 | I19: =('Kwh Reading'!R20-'Kwh Reading'!R19)*1000 -> 0 | J19: =('Kwh Reading'!S20-'Kwh Reading'!S19)*1000 -> 0 | K19: =('Kwh Reading'!I20-'Kwh Reading'!I19)*1000 -> 0 | L19: =('Kwh Reading'!B20-'Kwh Reading'!B19)*1000000 -> 0 | M19: =('Kwh Reading'!M20-'Kwh Reading'!M19)*1000 -> 0 | N19: =('Kwh Reading'!H20-'Kwh Reading'!H19)*1000 -> 0 | O19: =('Kwh Reading'!P20-'Kwh Reading'!P19)*1000 -> 0 | P19: =('Kwh Reading'!G20-'Kwh Reading'!G19)*1000 -> 0 | Q19: =('Kwh Reading'!Q20-'Kwh Reading'!Q19)*1000 -> 0 | R19: =('Kwh Reading'!N20-'Kwh Reading'!N19)*1000 -> 0 | S19: ='Kwh Reading'!E20-'Kwh Reading'!E19 -> 0 | T19: ='Kwh Reading'!D20-'Kwh Reading'!D19 -> 0 | U19: =('Kwh Reading'!O20-'Kwh Reading'!O19)*1000 -> 0 | V19: =B19-(SUM(C19:U19)) -> 0
... A34: ='Kwh Reading'!A34 -> 44531 | B34: =TOTAL!E32 -> 0 | C34: =('Kwh Reading'!T35-'Kwh Reading'!T34)*1000 -> 0 | D34: =('Kwh Reading'!F35-'Kwh Reading'!F34)*1000000 -> 0 | E34: =('Kwh Reading'!C35-'Kwh Reading'!C34)*1000 -> 0 | F34: =('Kwh Reading'!J35-'Kwh Reading'!J34)*1000 -> 0 | G34: =('Kwh Reading'!K35-'Kwh Reading'!K34)*1000 -> 0 | H34: =('Kwh Reading'!L35-'Kwh Reading'!L34)*1000 -> 0 | I34: =('Kwh Reading'!R35-'Kwh Reading'!R34)*1000 -> 0 | J34: =('Kwh Reading'!S35-'Kwh Reading'!S34)*1000 -> 0 | K34: =('Kwh Reading'!I35-'Kwh Reading'!I34)*1000 -> 0 | L34: =('Kwh Reading'!B35-'Kwh Reading'!B34)*1000000 -> 0 | M34: =('Kwh Reading'!M35-'Kwh Reading'!M34)*1000 -> 0 | N34: =('Kwh Reading'!H35-'Kwh Reading'!H34)*1000 -> 0 | O34: =('Kwh Reading'!P35-'Kwh Reading'!P34)*1000 -> 0 | P34: =('Kwh Reading'!G35-'Kwh Reading'!G34)*1000 -> 0 | Q34: =('Kwh Reading'!Q35-'Kwh Reading'!Q34)*1000 -> 0 | R34: =('Kwh Reading'!N35-'Kwh Reading'!N34)*1000 -> 0 | S34: ='Kwh Reading'!E35-'Kwh Reading'!E34 -> 0 | T34: ='Kwh Reading'!D35-'Kwh Reading'!D34 -> 0 | U34: =('Kwh Reading'!O35-'Kwh Reading'!O34)*1000 -> 0 | V34: =B34-(SUM(C34:U34)) -> 0
A35: Total | B35: =SUM(B4:B34) -> 240170 | C35: =SUM(C4:C34) -> -477210 | D35: =SUM(D4:D34) -> -2682200 | E35: =SUM(E4:E34) -> -259910 | F35: =SUM(F4:F34) -> -350570 | G35: =SUM(G4:G34) -> -375970 | H35: =SUM(H4:H34) -> -258670 | I35: =SUM(I4:I34) -> -189140 | ... V35: =SUM(V4:V34) -> 26880122

Sheet Kwh area wise 
A2: Month | B2: Total KWH | C2: Reef Club Kitchen KWH | D2: Main Kitchen KWH | E2: Pastry Kitchen KWH | F2: Laundry KWH | G2: STP KWH | H2: Kuda Huraa Accomodation KWH | I2: Guest Room Beach Pavilion & Beach Bungalow KWH | J2: Guest Room Water Bungalow KWH | K2: Spa KWH | L2: Others KWH
A3: ='Kwh Reading'!A4 -> 44501 | B3: =TOTAL!E2 -> 22900 | C3: ='Kwh Consumption'!C4 -> 480 | D3: ='Kwh Consumption'!D4 -> 2800 | E3: ='Kwh Consumption'!E4 -> 280 | F3: =('Kwh Consumption'!F4+'Kwh Consumption'!G4+'Kwh Consumption'!H4) -> 1120 | G3: =('Kwh Consumption'!I4+'Kwh Consumption'!J4) -> 230 | H3: =('Kwh Consumption'!K4+'Kwh Consumption'!L4) -> 1340 | I3: =('Kwh Consumption'!M4+'Kwh Consumption'!N4+'Kwh Consumption'!O4+'Kwh Consumption'!P4+'Kwh Consumption'!Q4+'Kwh Consumption'!R4) -> 5020 | J3: =('Kwh Consumption'!S4+'Kwh Consumption'!T4) -> 4857.66 | K3: ='Kwh Consumption'!U4 -> 230 | L3: =B3-C3-D3-E3-F3-G3-H3-I3-J3-K3 -> 6542.34
A4: ='Kwh Reading'!A5 -> 44502 | B4: =TOTAL!E3 -> 22120 | C4: ='Kwh Consumption'!C5 -> 580 | D4: ='Kwh Consumption'!D5 -> 2600 | E4: ='Kwh Consumption'!E5 -> 240 | F4: =('Kwh Consumption'!F5+'Kwh Consumption'!G5+'Kwh Consumption'!H5) -> 940 | G4: =('Kwh Consumption'!I5+'Kwh Consumption'!J5) -> 350 | H4: =('Kwh Consumption'!K5+'Kwh Consumption'!L5) -> 1300 | I4: =('Kwh Consumption'!M5+'Kwh Consumption'!N5+'Kwh Consumption'!O5+'Kwh Consumption'!P5+'Kwh Consumption'!Q5+'Kwh Consumption'!R5) -> 4680 | J4: =('Kwh Consumption'!S5+'Kwh Consumption'!T5) -> 4795.16 | K4: ='Kwh Consumption'!U5 -> 150 | L4: =B4-C4-D4-E4-F4-G4-H4-I4-J4-K4 -> 6484.84
A5: ='Kwh Reading'!A6 -> 44503 | B5: =TOTAL!E4 -> 17890 | C5: ='Kwh Consumption'!C6 -> 430 | D5: ='Kwh Consumption'!D6 -> 2600 | E5: ='Kwh Consumption'!E6 -> 280 | F5: =('Kwh Consumption'!F6+'Kwh Consumption'!G6+'Kwh Consumption'!H6) -> 1070 | G5: =('Kwh Consumption'!I6+'Kwh Consumption'!J6) -> 370 | H5: =('Kwh Consumption'!K6+'Kwh Consumption'!L6) -> 1170 | I5: =('Kwh Consumption'!M6+'Kwh Consumption'!N6+'Kwh Consumption'!O6+'Kwh Consumption'!P6+'Kwh Consumption'!Q6+'Kwh Consumption'!R6) -> 3630 | J5: =('Kwh Consumption'!S6+'Kwh Consumption'!T6) -> 3788.8 | K5: ='Kwh Consumption'!U6 -> 160 | L5: =B5-C5-D5-E5-F5-G5-H5-I5-J5-K5 -> 4391.2
A6: ='Kwh Reading'!A7 -> 44504 | B6: =TOTAL!E5 -> 18870 | C6: ='Kwh Consumption'!C7 -> 270 | D6: ='Kwh Consumption'!D7 -> 2700 | E6: ='Kwh Consumption'!E7 -> 260 | F6: =('Kwh Consumption'!F7+'Kwh Consumption'!G7+'Kwh Consumption'!H7) -> 1040 | G6: =('Kwh Consumption'!I7+'Kwh Consumption'!J7) -> 280 | H6: =('Kwh Consumption'!K7+'Kwh Consumption'!L7) -> 1190 | I6: =('Kwh Consumption'!M7+'Kwh Consumption'!N7+'Kwh Consumption'!O7+'Kwh Consumption'!P7+'Kwh Consumption'!Q7+'Kwh Consumption'!R7) -> 3820 | J6: =('Kwh Consumption'!S7+'Kwh Consumption'!T7) -> 3253.74 | K6: ='Kwh Consumption'!U7 -> 150 | L6: =B6-C6-D6-E6-F6-G6-H6-I6-J6-K6 -> 5906.26
A7: ='Kwh Reading'!A8 -> 44505 | B7: =TOTAL!E6 -> 20170 | C7: ='Kwh Consumption'!C8 -> 490 | D7: ='Kwh Consumption'!D8 -> 2500 | E7: ='Kwh Consumption'!E8 -> 250 | F7: =('Kwh Consumption'!F8+'Kwh Consumption'!G8+'Kwh Consumption'!H8) -> 980 | G7: =('Kwh Consumption'!I8+'Kwh Consumption'!J8) -> 220 | H7: =('Kwh Consumption'!K8+'Kwh Consumption'!L8) -> 1270 | I7: =('Kwh Consumption'!M8+'Kwh Consumption'!N8+'Kwh Consumption'!O8+'Kwh Consumption'!P8+'Kwh Consumption'!Q8+'Kwh Consumption'!R8) -> 4310 | J7: =('Kwh Consumption'!S8+'Kwh Consumption'!T8) -> 4081.54 | K7: ='Kwh Consumption'!U8 -> 150 | L7: =B7-C7-D7-E7-F7-G7-H7-I7-J7-K7 -> 5918.46
A8: ='Kwh Reading'!A9 -> 44506 | B8: =TOTAL!E7 -> 21860 | C8: ='Kwh Consumption'!C9 -> 520 | D8: ='Kwh Consumption'!D9 -> 2800 | E8: ='Kwh Consumption'!E9 -> 290 | F8: =('Kwh Consumption'!F9+'Kwh Consumption'!G9+'Kwh Consumption'!H9) -> 1010 | G8: =('Kwh Consumption'!I9+'Kwh Consumption'!J9) -> 220 | H8: =('Kwh Consumption'!K9+'Kwh Consumption'!L9) -> 1220 | I8: =('Kwh Consumption'!M9+'Kwh Consumption'!N9+'Kwh Consumption'!O9+'Kwh Consumption'!P9+'Kwh Consumption'!Q9+'Kwh Consumption'!R9) -> 4960 | J8: =('Kwh Consumption'!S9+'Kwh Consumption'!T9) -> 4593.93 | K8: ='Kwh Consumption'!U9 -> 120 | L8: =B8-C8-D8-E8-F8-G8-H8-I8-J8-K8 -> 6126.07
A9: ='Kwh Reading'!A10 -> 44507 | B9: =TOTAL!E8 -> 21590 | C9: ='Kwh Consumption'!C10 -> 480 | D9: ='Kwh Consumption'!D10 -> 2600 | E9: ='Kwh Consumption'!E10 -> 240 | F9: =('Kwh Consumption'!F10+'Kwh Consumption'!G10+'Kwh Consumption'!H10) -> 940 | G9: =('Kwh Consumption'!I10+'Kwh Consumption'!J10) -> 200 | H9: =('Kwh Consumption'!K10+'Kwh Consumption'!L10) -> 1240 | I9: =('Kwh Consumption'!M10+'Kwh Consumption'!N10+'Kwh Consumption'!O10+'Kwh Consumption'!P10+'Kwh Consumption'!Q10+'Kwh Consumption'!R10) -> 4750 | J9: =('Kwh Consumption'!S10+'Kwh Consumption'!T10) -> 4567.39 | K9: ='Kwh Consumption'!U10 -> 120 | L9: =B9-C9-D9-E9-F9-G9-H9-I9-J9-K9 -> 6452.61
A10: ='Kwh Reading'!A11 -> 44508 | B10: =TOTAL!E9 -> 23070 | C10: ='Kwh Consumption'!C11 -> 460 | D10: ='Kwh Consumption'!D11 -> 2600 | E10: ='Kwh Consumption'!E11 -> 250 | F10: =('Kwh Consumption'!F11+'Kwh Consumption'!G11+'Kwh Consumption'!H11) -> 1080 | G10: =('Kwh Consumption'!I11+'Kwh Consumption'!J11) -> 130 | H10: =('Kwh Consumption'!K11+'Kwh Consumption'!L11) -> 1250 | I10: =('Kwh Consumption'!M11+'Kwh Consumption'!N11+'Kwh Consumption'!O11+'Kwh Consumption'!P11+'Kwh Consumption'!Q11+'Kwh Consumption'!R11) -> 5450 | J10: =('Kwh Consumption'!S11+'Kwh Consumption'!T11) -> 5426.18 | K10: ='Kwh Consumption'!U11 -> 80 | L10: =B10-C10-D10-E10-F10-G10-H10-I10-J10-K10 -> 6343.82
A11: ='Kwh Reading'!A12 -> 44509 | B11: =TOTAL!E10 -> 22010 | C11: ='Kwh Consumption'!C12 -> 500 | D11: ='Kwh Consumption'!D12 -> 2300 | E11: ='Kwh Consumption'!E12 -> 230 | F11: =('Kwh Consumption'!F12+'Kwh Consumption'!G12+'Kwh Consumption'!H12) -> 940 | G11: =('Kwh Consumption'!I12+'Kwh Consumption'!J12) -> 170 | H11: =('Kwh Consumption'!K12+'Kwh Consumption'!L12) -> 1240 | I11: =('Kwh Consumption'!M12+'Kwh Consumption'!N12+'Kwh Consumption'!O12+'Kwh Consumption'!P12+'Kwh Consumption'!Q12+'Kwh Consumption'!R12) -> 5230 | J11: =('Kwh Consumption'!S12+'Kwh Consumption'!T12) -> 5375.76 | K11: ='Kwh Consumption'!U12 -> 80 | L11: =B11-C11-D11-E11-F11-G11-H11-I11-J11-K11 -> 5944.24
A12: ='Kwh Reading'!A13 -> 44510 | B12: =TOTAL!E11 -> 23250 | C12: ='Kwh Consumption'!C13 -> 500 | D12: ='Kwh Consumption'!D13 -> 2600 | E12: ='Kwh Consumption'!E13 -> 250 | F12: =('Kwh Consumption'!F13+'Kwh Consumption'!G13+'Kwh Consumption'!H13) -> 920 | G12: =('Kwh Consumption'!I13+'Kwh Consumption'!J13) -> 140 | H12: =('Kwh Consumption'!K13+'Kwh Consumption'!L13) -> 1280 | I12: =('Kwh Consumption'!M13+'Kwh Consumption'!N13+'Kwh Consumption'!O13+'Kwh Consumption'!P13+'Kwh Consumption'!Q13+'Kwh Consumption'!R13) -> 5630 | J12: =('Kwh Consumption'!S13+'Kwh Consumption'!T13) -> 5374.6 | K12: ='Kwh Consumption'!U13 -> 90 | L12: =B12-C12-D12-E12-F12-G12-H12-I12-J12-K12 -> 6465.4
A13: ='Kwh Reading'!A14 -> 44511 | B13: =TOTAL!E12 -> 23820 | C13: ='Kwh Consumption'!C14 -> 470 | D13: ='Kwh Consumption'!D14 -> 2600 | E13: ='Kwh Consumption'!E14 -> 240 | F13: =('Kwh Consumption'!F14+'Kwh Consumption'!G14+'Kwh Consumption'!H14) -> 1020 | G13: =('Kwh Consumption'!I14+'Kwh Consumption'!J14) -> 170 | H13: =('Kwh Consumption'!K14+'Kwh Consumption'!L14) -> 1390 | I13: =('Kwh Consumption'!M14+'Kwh Consumption'!N14+'Kwh Consumption'!O14+'Kwh Consumption'!P14+'Kwh Consumption'!Q14+'Kwh Consumption'!R14) -> 5720 | J13: =('Kwh Consumption'!S14+'Kwh Consumption'!T14) -> 5444.66 | K13: ='Kwh Consumption'!U14 -> 120 | L13: =B13-C13-D13-E13-F13-G13-H13-I13-J13-K13 -> 6645.34
A14: ='Kwh Reading'!A15 -> 44512 | B14: =TOTAL!E13 -> 0 | C14: ='Kwh Consumption'!C15 -> 260 | D14: ='Kwh Consumption'!D15 -> 2700 | E14: ='Kwh Consumption'!E15 -> 280 | F14: =('Kwh Consumption'!F15+'Kwh Consumption'!G15+'Kwh Consumption'!H15) -> 850 | G14: =('Kwh Consumption'!I15+'Kwh Consumption'!J15) -> 140 | H14: =('Kwh Consumption'!K15+'Kwh Consumption'!L15) -> 1390 | I14: =('Kwh Consumption'!M15+'Kwh Consumption'!N15+'Kwh Consumption'!O15+'Kwh Consumption'!P15+'Kwh Consumption'!Q15+'Kwh Consumption'!R15) -> 5540 | J14: =('Kwh Consumption'!S15+'Kwh Consumption'!T15) -> 4974.73 | K14: ='Kwh Consumption'!U15 -> 130 | L14: =B14-C14-D14-E14-F14-G14-H14-I14-J14-K14 -> -16264.73
... A33: ='Kwh Reading'!A34 -> 44531 | B33: =TOTAL!E32 -> 0 | C33: ='Kwh Consumption'!C34 -> 0 | D33: ='Kwh Consumption'!D34 -> 0 | E33: ='Kwh Consumption'!E34 -> 0 | F33: =('Kwh Consumption'!F34+'Kwh Consumption'!G34+'Kwh Consumption'!H34) -> 0 | G33: =('Kwh Consumption'!I34+'Kwh Consumption'!J34) -> 0 | H33: =('Kwh Consumption'!K34+'Kwh Consumption'!L34) -> 0 | I33: =('Kwh Consumption'!M34+'Kwh Consumption'!N34+'Kwh Consumption'!O34+'Kwh Consumption'!P34+'Kwh Consumption'!Q34+'Kwh Consumption'!R34) -> 0 | J33: =('Kwh Consumption'!S34+'Kwh Consumption'!T34) -> 0 | K33: ='Kwh Consumption'!U34 -> 0 | L33: =B33-C33-D33-E33-F33-G33-H33-I33-J33-K33 -> 0
A34: Total kwh | B34: =SUM(B3:B33) -> 237550 | C34: =SUM(C3:C33) -> -477210 | D34: =SUM(D3:D33) -> -2682200 | E34: =SUM(E3:E33) -> -259910 | F34: =SUM(F3:F33) -> -985210 | G34: =SUM(G3:G33) -> -319070 | H34: =SUM(H3:H33) -> -1414740 | I34: =SUM(I3:I33) -> -4009350 | ... L34: =SUM(L3:L33) -> 26877502 | M34: =C34+D34+E34+F34+G34+H34+I34+J34+K34+L34 -> 237550
A36: Total $ | B36: =TOTAL!F2 -> 0.18 | C36: =C34*B36 -> -85897.8 | D36: =D34*B36 -> -482796 | E36: =E34*B36 -> -46783.8 | F36: =F34*B36 -> -177337.8 | G36: =G34*B36 -> -57432.6 | H36: =H34*B36 -> -254653.2 | I36: =I34*B36 -> -721683 | J36: =J34*B36 -> -2936399.8 | K36: =K34*B36 -> -32207.4 | L36: =L34*B36 -> 4837950.4 | M36: =C36+D36+E36+F36+G36+H36+I36+J36+K36+L36 -> 42759

Sheet  Kwh area wise $ 
A2: Month | B2: $ /Per KWH | C2: Total $ | D2: Reef Club $ | E2: Kitchen $ | F2: Pastry $ | G2: Laundry $ | H2: STP $ | I2: Kuda Huraa Accomodation $ | J2: Guest Room Beach Pavilion & Beach Bungalow $ | K2: Guest Room Water Bungalow $ | L2: Spa $ | M2: Others $
A3: ='Kwh Reading'!A4 -> 44501 | B3: =TOTAL!F2 -> 0.18 | C3: ='Kwh Consumption'!B4*' Kwh area wise $ '!B3 -> 4593.6 | D3: ='Kwh Consumption'!C4*' Kwh area wise $ '!B3 -> 86.4 | E3: ='Kwh Consumption'!D4*' Kwh area wise $ '!B3 -> 504 | F3: ='Kwh Consumption'!E4*' Kwh area wise $ '!B3 -> 50.4 | G3: =('Kwh Consumption'!F4+'Kwh Consumption'!G4+'Kwh Consumption'!H4)*' Kwh area wise $ '!B3 -> 201.6 | H3: =('Kwh Consumption'!I4+'Kwh Consumption'!J4)*' Kwh area wise $ '!B3 -> 41.4 | I3: =('Kwh Consumption'!K4+'Kwh Consumption'!L4)*' Kwh area wise $ '!B3 -> 241.2 | J3: =('Kwh Consumption'!M4+'Kwh Consumption'!N4+'Kwh Consumption'!O4+'Kwh Consumption'!P4+'Kwh Consumption'!Q4+'Kwh Consumption'!R4)*' Kwh area wise $ '!B3 -> 903.6 | K3: =('Kwh Consumption'!S4+'Kwh Consumption'!T4)*' Kwh area wise $ '!B3 -> 874.3788 | L3: ='Kwh Consumption'!U4*' Kwh area wise $ '!B3 -> 41.4 | M3: ='Kwh Consumption'!V4*' Kwh area wise $ '!B3 -> 1649.2212
A4: ='Kwh Reading'!A5 -> 44502 | B4: =TOTAL!F3 -> 0.18 | C4: ='Kwh Consumption'!B5*' Kwh area wise $ '!B4 -> 3981.6 | D4: ='Kwh Consumption'!C5*' Kwh area wise $ '!B4 -> 104.4 | E4: ='Kwh Consumption'!D5*' Kwh area wise $ '!B4 -> 468 | F4: ='Kwh Consumption'!E5*' Kwh area wise $ '!B4 -> 43.2 | G4: =('Kwh Consumption'!F5+'Kwh Consumption'!G5+'Kwh Consumption'!H5)*' Kwh area wise $ '!B4 -> 169.2 | H4: =('Kwh Consumption'!I5+'Kwh Consumption'!J5)*' Kwh area wise $ '!B4 -> 63 | I4: =('Kwh Consumption'!K5+'Kwh Consumption'!L5)*' Kwh area wise $ '!B4 -> 234 | J4: =('Kwh Consumption'!M5+'Kwh Consumption'!N5+'Kwh Consumption'!O5+'Kwh Consumption'!P5+'Kwh Consumption'!Q5+'Kwh Consumption'!R5)*' Kwh area wise $ '!B4 -> 842.4 | K4: =('Kwh Consumption'!S5+'Kwh Consumption'!T5)*' Kwh area wise $ '!B4 -> 863.1288 | L4: ='Kwh Consumption'!U5*' Kwh area wise $ '!B4 -> 27 | M4: ='Kwh Consumption'!V5*' Kwh area wise $ '!B4 -> 1167.2712
A5: ='Kwh Reading'!A6 -> 44503 | B5: =TOTAL!F4 -> 0.18 | C5: ='Kwh Consumption'!B6*' Kwh area wise $ '!B5 -> 3220.2 | D5: ='Kwh Consumption'!C6*' Kwh area wise $ '!B5 -> 77.4 | E5: ='Kwh Consumption'!D6*' Kwh area wise $ '!B5 -> 468 | F5: ='Kwh Consumption'!E6*' Kwh area wise $ '!B5 -> 50.4 | G5: =('Kwh Consumption'!F6+'Kwh Consumption'!G6+'Kwh Consumption'!H6)*' Kwh area wise $ '!B5 -> 192.6 | H5: =('Kwh Consumption'!I6+'Kwh Consumption'!J6)*' Kwh area wise $ '!B5 -> 66.6 | I5: =('Kwh Consumption'!K6+'Kwh Consumption'!L6)*' Kwh area wise $ '!B5 -> 210.6 | J5: =('Kwh Consumption'!M6+'Kwh Consumption'!N6+'Kwh Consumption'!O6+'Kwh Consumption'!P6+'Kwh Consumption'!Q6+'Kwh Consumption'!R6)*' Kwh area wise $ '!B5 -> 653.4 | K5: =('Kwh Consumption'!S6+'Kwh Consumption'!T6)*' Kwh area wise $ '!B5 -> 681.984 | L5: ='Kwh Consumption'!U6*' Kwh area wise $ '!B5 -> 28.8 | M5: ='Kwh Consumption'!V6*' Kwh area wise $ '!B5 -> 790.416
A6: ='Kwh Reading'!A7 -> 44504 | B6: =TOTAL!F5 -> 0.18 | C6: ='Kwh Consumption'!B7*' Kwh area wise $ '!B6 -> 3396.6 | D6: ='Kwh Consumption'!C7*' Kwh area wise $ '!B6 -> 48.6 | E6: ='Kwh Consumption'!D7*' Kwh area wise $ '!B6 -> 486 | F6: ='Kwh Consumption'!E7*' Kwh area wise $ '!B6 -> 46.8 | G6: =('Kwh Consumption'!F7+'Kwh Consumption'!G7+'Kwh Consumption'!H7)*' Kwh area wise $ '!B6 -> 187.2 | H6: =('Kwh Consumption'!I7+'Kwh Consumption'!J7)*' Kwh area wise $ '!B6 -> 50.4 | I6: =('Kwh Consumption'!K7+'Kwh Consumption'!L7)*' Kwh area wise $ '!B6 -> 214.2 | J6: =('Kwh Consumption'!M7+'Kwh Consumption'!N7+'Kwh Consumption'!O7+'Kwh Consumption'!P7+'Kwh Consumption'!Q7+'Kwh Consumption'!R7)*' Kwh area wise $ '!B6 -> 687.6 | K6: =('Kwh Consumption'!S7+'Kwh Consumption'!T7)*' Kwh area wise $ '!B6 -> 585.6732 | L6: ='Kwh Consumption'!U7*' Kwh area wise $ '!B6 -> 27 | M6: ='Kwh Consumption'!V7*' Kwh area wise $ '!B6 -> 1063.1268
A7: ='Kwh Reading'!A8 -> 44505 | B7: =TOTAL!F6 -> 0.18 | C7: ='Kwh Consumption'!B8*' Kwh area wise $ '!B7 -> 3630.6 | D7: ='Kwh Consumption'!C8*' Kwh area wise $ '!B7 -> 88.2 | E7: ='Kwh Consumption'!D8*' Kwh area wise $ '!B7 -> 450 | F7: ='Kwh Consumption'!E8*' Kwh area wise $ '!B7 -> 45 | G7: =('Kwh Consumption'!F8+'Kwh Consumption'!G8+'Kwh Consumption'!H8)*' Kwh area wise $ '!B7 -> 176.4 | H7: =('Kwh Consumption'!I8+'Kwh Consumption'!J8)*' Kwh area wise $ '!B7 -> 39.6 | I7: =('Kwh Consumption'!K8+'Kwh Consumption'!L8)*' Kwh area wise $ '!B7 -> 228.6 | J7: =('Kwh Consumption'!M8+'Kwh Consumption'!N8+'Kwh Consumption'!O8+'Kwh Consumption'!P8+'Kwh Consumption'!Q8+'Kwh Consumption'!R8)*' Kwh area wise $ '!B7 -> 775.8 | K7: =('Kwh Consumption'!S8+'Kwh Consumption'!T8)*' Kwh area wise $ '!B7 -> 734.6772 | L7: ='Kwh Consumption'!U8*' Kwh area wise $ '!B7 -> 27 | M7: ='Kwh Consumption'!V8*' Kwh area wise $ '!B7 -> 1065.3228
A8: ='Kwh Reading'!A9 -> 44506 | B8: =TOTAL!F7 -> 0.18 | C8: ='Kwh Consumption'!B9*' Kwh area wise $ '!B8 -> 3934.8 | D8: ='Kwh Consumption'!C9*' Kwh area wise $ '!B8 -> 93.6 | E8: ='Kwh Consumption'!D9*' Kwh area wise $ '!B8 -> 504 | F8: ='Kwh Consumption'!E9*' Kwh area wise $ '!B8 -> 52.2 | G8: =('Kwh Consumption'!F9+'Kwh Consumption'!G9+'Kwh Consumption'!H9)*' Kwh area wise $ '!B8 -> 181.8 | H8: =('Kwh Consumption'!I9+'Kwh Consumption'!J9)*' Kwh area wise $ '!B8 -> 39.6 | I8: =('Kwh Consumption'!K9+'Kwh Consumption'!L9)*' Kwh area wise $ '!B8 -> 219.6 | J8: =('Kwh Consumption'!M9+'Kwh Consumption'!N9+'Kwh Consumption'!O9+'Kwh Consumption'!P9+'Kwh Consumption'!Q9+'Kwh Consumption'!R9)*' Kwh area wise $ '!B8 -> 892.8 | K8: =('Kwh Consumption'!S9+'Kwh Consumption'!T9)*' Kwh area wise $ '!B8 -> 826.9074 | L8: ='Kwh Consumption'!U9*' Kwh area wise $ '!B8 -> 21.6 | M8: ='Kwh Consumption'!V9*' Kwh area wise $ '!B8 -> 1102.6926
A9: ='Kwh Reading'!A10 -> 44507 | B9: =TOTAL!F8 -> 0.18 | C9: ='Kwh Consumption'!B10*' Kwh area wise $ '!B9 -> 3886.2 | D9: ='Kwh Consumption'!C10*' Kwh area wise $ '!B9 -> 86.4 | E9: ='Kwh Consumption'!D10*' Kwh area wise $ '!B9 -> 468 | F9: ='Kwh Consumption'!E10*' Kwh area wise $ '!B9 -> 43.2 | G9: =('Kwh Consumption'!F10+'Kwh Consumption'!G10+'Kwh Consumption'!H10)*' Kwh area wise $ '!B9 -> 169.2 | H9: =('Kwh Consumption'!I10+'Kwh Consumption'!J10)*' Kwh area wise $ '!B9 -> 36 | I9: =('Kwh Consumption'!K10+'Kwh Consumption'!L10)*' Kwh area wise $ '!B9 -> 223.2 | J9: =('Kwh Consumption'!M10+'Kwh Consumption'!N10+'Kwh Consumption'!O10+'Kwh Consumption'!P10+'Kwh Consumption'!Q10+'Kwh Consumption'!R10)*' Kwh area wise $ '!B9 -> 855 | K9: =('Kwh Consumption'!S10+'Kwh Consumption'!T10)*' Kwh area wise $ '!B9 -> 822.1302 | L9: ='Kwh Consumption'!U10*' Kwh area wise $ '!B9 -> 21.6 | M9: ='Kwh Consumption'!V10*' Kwh area wise $ '!B9 -> 1161.4698
A10: ='Kwh Reading'!A11 -> 44508 | B10: =TOTAL!F9 -> 0.18 | C10: ='Kwh Consumption'!B11*' Kwh area wise $ '!B10 -> 4152.6 | D10: ='Kwh Consumption'!C11*' Kwh area wise $ '!B10 -> 82.8 | E10: ='Kwh Consumption'!D11*' Kwh area wise $ '!B10 -> 468 | F10: ='Kwh Consumption'!E11*' Kwh area wise $ '!B10 -> 45 | G10: =('Kwh Consumption'!F11+'Kwh Consumption'!G11+'Kwh Consumption'!H11)*' Kwh area wise $ '!B10 -> 194.4 | H10: =('Kwh Consumption'!I11+'Kwh Consumption'!J11)*' Kwh area wise $ '!B10 -> 23.4 | I10: =('Kwh Consumption'!K11+'Kwh Consumption'!L11)*' Kwh area wise $ '!B10 -> 225 | J10: =('Kwh Consumption'!M11+'Kwh Consumption'!N11+'Kwh Consumption'!O11+'Kwh Consumption'!P11+'Kwh Consumption'!Q11+'Kwh Consumption'!R11)*' Kwh area wise $ '!B10 -> 981 | K10: =('Kwh Consumption'!S11+'Kwh Consumption'!T11)*' Kwh area wise $ '!B10 -> 976.7124 | L10: ='Kwh Consumption'!U11*' Kwh area wise $ '!B10 -> 14.4 | M10: ='Kwh Consumption'!V11*' Kwh area wise $ '!B10 -> 1141.8876
A11: ='Kwh Reading'!A12 -> 44509 | B11: =TOTAL!F10 -> 0.18 | C11: ='Kwh Consumption'!B12*' Kwh area wise $ '!B11 -> 3961.8 | D11: ='Kwh Consumption'!C12*' Kwh area wise $ '!B11 -> 90 | E11: ='Kwh Consumption'!D12*' Kwh area wise $ '!B11 -> 414 | F11: ='Kwh Consumption'!E12*' Kwh area wise $ '!B11 -> 41.4 | G11: =('Kwh Consumption'!F12+'Kwh Consumption'!G12+'Kwh Consumption'!H12)*' Kwh area wise $ '!B11 -> 169.2 | H11: =('Kwh Consumption'!I12+'Kwh Consumption'!J12)*' Kwh area wise $ '!B11 -> 30.6 | I11: =('Kwh Consumption'!K12+'Kwh Consumption'!L12)*' Kwh area wise $ '!B11 -> 223.2 | J11: =('Kwh Consumption'!M12+'Kwh Consumption'!N12+'Kwh Consumption'!O12+'Kwh Consumption'!P12+'Kwh Consumption'!Q12+'Kwh Consumption'!R12)*' Kwh area wise $ '!B11 -> 941.4 | K11: =('Kwh Consumption'!S12+'Kwh Consumption'!T12)*' Kwh area wise $ '!B11 -> 967.6368 | L11: ='Kwh Consumption'!U12*' Kwh area wise $ '!B11 -> 14.4 | M11: ='Kwh Consumption'!V12*' Kwh area wise $ '!B11 -> 1069.9632
A12: ='Kwh Reading'!A13 -> 44510 | B12: =TOTAL!F11 -> 0.18 | C12: ='Kwh Consumption'!B13*' Kwh area wise $ '!B12 -> 4185 | D12: ='Kwh Consumption'!C13*' Kwh area wise $ '!B12 -> 90 | E12: ='Kwh Consumption'!D13*' Kwh area wise $ '!B12 -> 468 | F12: ='Kwh Consumption'!E13*' Kwh area wise $ '!B12 -> 45 | G12: =('Kwh Consumption'!F13+'Kwh Consumption'!G13+'Kwh Consumption'!H13)*' Kwh area wise $ '!B12 -> 165.6 | H12: =('Kwh Consumption'!I13+'Kwh Consumption'!J13)*' Kwh area wise $ '!B12 -> 25.2 | I12: =('Kwh Consumption'!K13+'Kwh Consumption'!L13)*' Kwh area wise $ '!B12 -> 230.4 | J12: =('Kwh Consumption'!M13+'Kwh Consumption'!N13+'Kwh Consumption'!O13+'Kwh Consumption'!P13+'Kwh Consumption'!Q13+'Kwh Consumption'!R13)*' Kwh area wise $ '!B12 -> 1013.4 | K12: =('Kwh Consumption'!S13+'Kwh Consumption'!T13)*' Kwh area wise $ '!B12 -> 967.428 | L12: ='Kwh Consumption'!U13*' Kwh area wise $ '!B12 -> 16.2 | M12: ='Kwh Consumption'!V13*' Kwh area wise $ '!B12 -> 1163.772
A13: ='Kwh Reading'!A14 -> 44511 | B13: =TOTAL!F12 -> 0.18 | C13: ='Kwh Consumption'!B14*' Kwh area wise $ '!B13 -> 4287.6 | D13: ='Kwh Consumption'!C14*' Kwh area wise $ '!B13 -> 84.6 | E13: ='Kwh Consumption'!D14*' Kwh area wise $ '!B13 -> 468 | F13: ='Kwh Consumption'!E14*' Kwh area wise $ '!B13 -> 43.2 | G13: =('Kwh Consumption'!F14+'Kwh Consumption'!G14+'Kwh Consumption'!H14)*' Kwh area wise $ '!B13 -> 183.6 | H13: =('Kwh Consumption'!I14+'Kwh Consumption'!J14)*' Kwh area wise $ '!B13 -> 30.6 | I13: =('Kwh Consumption'!K14+'Kwh Consumption'!L14)*' Kwh area wise $ '!B13 -> 250.2 | J13: =('Kwh Consumption'!M14+'Kwh Consumption'!N14+'Kwh Consumption'!O14+'Kwh Consumption'!P14+'Kwh Consumption'!Q14+'Kwh Consumption'!R14)*' Kwh area wise $ '!B13 -> 1029.6 | K13: =('Kwh Consumption'!S14+'Kwh Consumption'!T14)*' Kwh area wise $ '!B13 -> 980.0388 | L13: ='Kwh Consumption'!U14*' Kwh area wise $ '!B13 -> 21.6 | M13: ='Kwh Consumption'!V14*' Kwh area wise $ '!B13 -> 1196.1612
A14: ='Kwh Reading'!A15 -> 44512 | B14: =TOTAL!F13 -> 0.18 | C14: ='Kwh Consumption'!B15*' Kwh area wise $ '!B14 -> 0 | D14: ='Kwh Consumption'!C15*' Kwh area wise $ '!B14 -> 46.8 | E14: ='Kwh Consumption'!D15*' Kwh area wise $ '!B14 -> 486 | F14: ='Kwh Consumption'!E15*' Kwh area wise $ '!B14 -> 50.4 | G14: =('Kwh Consumption'!F15+'Kwh Consumption'!G15+'Kwh Consumption'!H15)*' Kwh area wise $ '!B14 -> 153 | H14: =('Kwh Consumption'!I15+'Kwh Consumption'!J15)*' Kwh area wise $ '!B14 -> 25.2 | I14: =('Kwh Consumption'!K15+'Kwh Consumption'!L15)*' Kwh area wise $ '!B14 -> 250.2 | J14: =('Kwh Consumption'!M15+'Kwh Consumption'!N15+'Kwh Consumption'!O15+'Kwh Consumption'!P15+'Kwh Consumption'!Q15+'Kwh Consumption'!R15)*' Kwh area wise $ '!B14 -> 997.2 | K14: =('Kwh Consumption'!S15+'Kwh Consumption'!T15)*' Kwh area wise $ '!B14 -> 895.4514 | L14: ='Kwh Consumption'!U15*' Kwh area wise $ '!B14 -> 23.4 | M14: ='Kwh Consumption'!V15*' Kwh area wise $ '!B14 -> -2927.6514
... A33: ='Kwh Reading'!A34 -> 44531 | B33: =TOTAL!F32 -> 0.18 | C33: ='Kwh Consumption'!B34*' Kwh area wise $ '!B33 -> 0 | D33: ='Kwh Consumption'!C34*' Kwh area wise $ '!B33 -> 0 | E33: ='Kwh Consumption'!D34*' Kwh area wise $ '!B33 -> 0 | F33: ='Kwh Consumption'!E34*' Kwh area wise $ '!B33 -> 0 | G33: =('Kwh Consumption'!F34+'Kwh Consumption'!G34+'Kwh Consumption'!H34)*' Kwh area wise $ '!B33 -> 0 | H33: =('Kwh Consumption'!I34+'Kwh Consumption'!J34)*' Kwh area wise $ '!B33 -> 0 | I33: =('Kwh Consumption'!K34+'Kwh Consumption'!L34)*' Kwh area wise $ '!B33 -> 0 | J33: =('Kwh Consumption'!M34+'Kwh Consumption'!N34+'Kwh Consumption'!O34+'Kwh Consumption'!P34+'Kwh Consumption'!Q34+'Kwh Consumption'!R34)*' Kwh area wise $ '!B33 -> 0 | K33: =('Kwh Consumption'!S34+'Kwh Consumption'!T34)*' Kwh area wise $ '!B33 -> 0 | L33: ='Kwh Consumption'!U34*' Kwh area wise $ '!B33 -> 0 | M33: ='Kwh Consumption'!V34*' Kwh area wise $ '!B33 -> 0
A34: Total | C34: =SUM(C3:C33) -> 43230.6 | D34: =SUM(D3:D33) -> -85897.8 | E34: =SUM(E3:E33) -> -482796 | F34: =SUM(F3:F33) -> -46783.8 | G34: =SUM(G3:G33) -> -177337.8 | H34: =SUM(H3:H33) -> -57432.6 | I34: =SUM(I3:I33) -> -254653.2 | J34: =SUM(J3:J33) -> -721683 | ... M34: =SUM(M3:M33) -> 4838422 | N34: =D34+E34+F34+G34+H34+I34+J34+K34+L34+M34 -> 43230.6

Sheet Water Reading
B1: Meter 1 | C1: Meter 2 | D1: Meter 6 | E1: Meter 8 | F1: Meter 7 | G1: Meter 9 | H1: Meter 3 | I1: Meter 5 | J1: Meter 10 | K1: Meter 13 | L1: Meter 16 | M1: Meter 17 | N1: Meter 15 | O1: Meter 14 | P1: Meter 4 | Q1: Meter 11 | R1: Meter 12
A2: Date | B2: Main Meter 1 | C2: Main Meter 2 | D2: Beach Bunglow | E2: Kuda Huraa staff | F2: Bodu hura staff | G2: Laundry | H2: Water Bunglow | I2: Main Kitchen | J2: Second stage | K2: Supply jetty | L2: Staff housing A | M2: Staff housing B | N2: Spa | O2: Staff jetty | P2: Main pool | Q2: Reef club pool | R2: Reef club kitchen
A3: 44501 | B3: 190269 | C3: 154434 | D3: 227239 | E3: 254920 | F3: 67013 | G3: 113887 | H3: 57642 | I3: 67620 | J3: 21563 | K3: 1024 | L3: 18117 | M3: 25946 | N3: 8025 | O3: 1801 | P3: 28505 | Q3: 1088 | R3: 6919
A4: 44502 | B4: 190418 | C4: 154575 | D4: 227394 | E4: 254989 | F4: 67014 | G4: 113920 | H4: 57662 | I4: 67661 | J4: 21577 | K4: 1024 | L4: 18123 | M4: 25957 | N4: 8028 | O4: 1802 | P4: 28512 | Q4: 1088 | R4: 6925
A5: 44503 | B5: 190522 | C5: 154647 | D5: 227512 | E5: 255039 | F5: 67014 | G5: 113936 | H5: 57708 | I5: 67684 | J5: 21577 | K5: 1024 | L5: 18128 | M5: 25968 | N5: 8029 | O5: 1802 | P5: 28514 | Q5: 1088 | R5: 6932
A6: 44504 | B6: 190645 | C6: 155145 | D6: 227634 | E6: 255103 | F6: 67015 | G6: 113963 | H6: 57742 | I6: 67712 | J6: 21584 | K6: 1024 | L6: 18133 | M6: 25981 | N6: 8031 | O6: 1805 | P6: 28514 | Q6: 1088 | R6: 6939
A7: 44505 | B7: 190759 | C7: 155246 | D7: 227737 | E7: 255160 | F7: 67016 | G7: 113984 | H7: 57775 | I7: 67758 | J7: 21590 | K7: 1024 | L7: 18137 | M7: 25995 | N7: 8033 | O7: 1806 | P7: 28514 | Q7: 1088 | R7: 6940
A8: 44506 | B8: 190895 | C8: 155353 | D8: 227853 | E8: 255261 | F8: 67616 | G8: 114009 | H8: 57801 | I8: 67785 | J8: 21596 | K8: 1024 | L8: 18141 | M8: 26006 | N8: 8034 | O8: 1806 | P8: 28514 | Q8: 1088 | R8: 6946
A9: 44507 | B9: 191018 | C9: 155451 | D9: 227976 | E9: 255318 | F9: 67017 | G9: 114035 | H9: 57842 | I9: 67818 | J9: 21603 | K9: 1024 | L9: 18143 | M9: 26013 | N9: 8044 | O9: 1809 | P9: 28521 | Q9: 1088 | R9: 6952
A10: 44508 | B10: 191150 | C10: 155510 | D10: 228106 | E10: 255386 | F10: 67018 | G10: 114085 | H10: 57881 | I10: 67872 | J10: 21609 | K10: 1024 | L10: 18145 | M10: 26019 | N10: 8078 | O10: 1811 | P10: 28545 | Q10: 1088 | R10: 6958
A11: 44509 | B11: 191296 | C11: 155623 | D11: 228262 | E11: 255446 | F11: 67019 | G11: 114085 | H11: 57945 | I11: 67909 | J11: 21615 | K11: 1024 | L11: 18146 | M11: 26023 | N11: 8078 | O11: 1813 | P11: 28559 | Q11: 1092 | R11: 6964
A12: 44510 | B12: 191420 | C12: 155711 | D12: 228391 | E12: 255507 | F12: 67019 | G12: 114108 | H12: 57993 | I12: 67946 | J12: 21622 | K12: 1024 | L12: 18148 | M12: 26027 | N12: 8078 | O12: 1814 | P12: 28569 | Q12: 1095 | R12: 6970
A13: 44511 | B13: 191566 | C13: 155801 | D13: 228581 | E13: 255547 | F13: 67020 | G13: 114131 | H13: 58042 | I13: 67996 | J13: 21628 | K13: 1024 | L13: 18150 | M13: 26034 | N13: 8078 | O13: 1816 | P13: 28593 | Q13: 1098 | R13: 6977
A14: 44512 | B14: 191715 | C14: 156195 | D14: 228722 | E14: 255640 | F14: 67021 | G14: 114156 | H14: 58091 | I14: 68030 | J14: 21635 | K14: 1024 | L14: 18152 | M14: 26040 | N14: 8083 | O14: 1817 | P14: 28605 | Q14: 1100 | R14: 6983
A15: 44513 | B15: 191849 | C15: 156259 | D15: 228861 | E15: 255709 | F15: 67021 | G15: 114177 | H15: 58147 | I15: 68055 | J15: 21641 | K15: 1024 | L15: 18154 | M15: 26044 | N15: 8086 | O15: 1820 | P15: 28605 | Q15: 1104 | R15: 6984
A16: 44514
A17: 44515
A18: 44516
A19: 44517
A20: 44518
A21: 44519
A22: 44520
A23: 44521 | S23: .
A24: 44522
A25: 44523
A26: 44524
A27: 44525
A28: 44526
A29: 44527
A30: 44528
A31: 44529
A32: 44530
A33: 44531

Sheet Water consumption
A2: Date | B2: RO production (Ro 1 : 4) | C2: Total Consumption M3 (Meter 1 : 2) | E2: Water Bunglow | G2: Beach bunglow | I2: Main Pool | K2: Main kitchen | M2: Reef club kitchen | O2: Reef club pool | Q2: Bodu Huraa staff | S2: Kuda Huraa staff | U2: Laundry | W2: Second stage | Y2: Total
C3: M3 | D3: % of Total production | E3: M3 | F3: % | G3: M3 | H3: % | I3: M3 | J3: % | K3: M3 | L3: % | M3: M3 | N3: % | O3: M3 | P3: % | Q3: M3 | R3: % | S3: M3 | T3: % | U3: M3 | V3: % | W3: M3 | X3: % | Y3: M3 | Z3: %
A4: ='Water Reading'!A3 -> 44501 | B4: 469 | C4: =('Water Reading'!B4-'Water Reading'!B3)+('Water Reading'!C4-'Water Reading'!C3) -> 290 | D4: =C4/B4 -> 0.61833689 | E4: ='Water Reading'!H4-'Water Reading'!H3 -> 20 | F4: =E4/C4 -> 0.068965517 | G4: =('Water Reading'!D4-'Water Reading'!D3)-('Water Reading'!R4-'Water Reading'!R3)-('Water Reading'!Q4-'Water Reading'!Q3) -> 149 | H4: =G4/C4 -> 0.5137931 | I4: ='Water Reading'!P4-'Water Reading'!P3 -> 7 | J4: =I4/C4 -> 0.024137931 | K4: =('Water Reading'!I4-'Water Reading'!I3)-('Water Reading'!P4-'Water Reading'!P3) -> 34 | L4: =K4/C4 -> 0.11724138 | M4: ='Water Reading'!R4-'Water Reading'!R3 -> 6 | N4: =M4/C4 -> 0.020689655 | O4: ='Water Reading'!Q4-'Water Reading'!Q3 -> 0 | P4: =O4/C4 -> 0 | Q4: ='Water Reading'!N4-'Water Reading'!N3 -> 3 | R4: =Q4/C4 -> 0.010344828 | S4: ='Water Reading'!M4-'Water Reading'!M3 -> 11 | T4: =S4/C4 -> 0.037931034 | U4: ='Water Reading'!O4-'Water Reading'!O3 -> 1 | V4: =U4/C4 -> 0.0034482759 | W4: ='Water Reading'!R4-'Water Reading'!R3 -> 6 | X4: =W4/C4 -> 0.020689655 | Y4: =E4+I4+K4+M4+O4+G4+Q4+S4+U4+W4 -> 237 | Z4: =Y4/B4 -> 0.50533049
A5: ='Water Reading'!A4 -> 44502 | B5: =TOTAL!I3 -> 285 | C5: =('Water Reading'!B5-'Water Reading'!B4)+('Water Reading'!C5-'Water Reading'!C4) -> 176 | D5: =C5/B5 -> 0.61754386 | E5: ='Water Reading'!H5-'Water Reading'!H4 -> 46 | F5: =E5/C5 -> 0.26136364 | G5: =('Water Reading'!D5-'Water Reading'!D4)-('Water Reading'!R5-'Water Reading'!R4)-('Water Reading'!Q5-'Water Reading'!Q4) -> 111 | H5: =G5/C5 -> 0.63068182 | I5: ='Water Reading'!P5-'Water Reading'!P4 -> 2 | J5: =I5/C5 -> 0.011363636 | K5: =('Water Reading'!I5-'Water Reading'!I4)-('Water Reading'!P5-'Water Reading'!P4) -> 21 | L5: =K5/C5 -> 0.11931818 | M5: ='Water Reading'!R5-'Water Reading'!R4 -> 7 | N5: =M5/C5 -> 0.039772727 | O5: ='Water Reading'!Q5-'Water Reading'!Q4 -> 0 | P5: =O5/C5 -> 0 | Q5: ='Water Reading'!N5-'Water Reading'!N4 -> 1 | R5: =Q5/C5 -> 0.0056818182 | S5: ='Water Reading'!M5-'Water Reading'!M4 -> 11 | T5: =S5/C5 -> 0.0625 | U5: ='Water Reading'!O5-'Water Reading'!O4 -> 0 | V5: =U5/C5 -> 0 | W5: ='Water Reading'!R5-'Water Reading'!R4 -> 7 | X5: =W5/C5 -> 0.039772727 | Y5: =E5+I5+K5+M5+O5+G5+Q5+S5+U5+W5 -> 206 | Z5: =Y5/B5 -> 0.72280702
A6: ='Water Reading'!A5 -> 44503 | B6: =TOTAL!I4 -> 270 | C6: =('Water Reading'!B6-'Water Reading'!B5)+('Water Reading'!C6-'Water Reading'!C5) -> 621 | D6: =C6/B6 -> 2.3 | E6: ='Water Reading'!H6-'Water Reading'!H5 -> 34 | F6: =E6/C6 -> 0.054750403 | G6: =('Water Reading'!D6-'Water Reading'!D5)-('Water Reading'!R6-'Water Reading'!R5)-('Water Reading'!Q6-'Water Reading'!Q5) -> 115 | H6: =G6/C6 -> 0.18518519 | I6: ='Water Reading'!P6-'Water Reading'!P5 -> 0 | J6: =I6/C6 -> 0 | K6: =('Water Reading'!I6-'Water Reading'!I5)-('Water Reading'!P6-'Water Reading'!P5) -> 28 | L6: =K6/C6 -> 0.045088567 | M6: ='Water Reading'!R6-'Water Reading'!R5 -> 7 | N6: =M6/C6 -> 0.011272142 | O6: ='Water Reading'!Q6-'Water Reading'!Q5 -> 0 | P6: =O6/C6 -> 0 | Q6: ='Water Reading'!N6-'Water Reading'!N5 -> 2 | R6: =Q6/C6 -> 0.0032206119 | S6: ='Water Reading'!M6-'Water Reading'!M5 -> 13 | T6: =S6/C6 -> 0.020933977 | U6: ='Water Reading'!O6-'Water Reading'!O5 -> 3 | V6: =U6/C6 -> 0.0048309179 | W6: ='Water Reading'!R6-'Water Reading'!R5 -> 7 | X6: =W6/C6 -> 0.011272142 | Y6: =E6+I6+K6+M6+O6+G6+Q6+S6+U6+W6 -> 209 | Z6: =Y6/B6 -> 0.77407407
