Workbook

Sheet TOTAL
A1: Site Name | B1: Day | C1: Month | D1: Year | E1: Total Electricity Kwh | F1: Electricity Tariff ($/Kwh) | G1: Natual Gas (m3) | H1: Natural Gas $/m3 | I1: Water Utility Supply (m3) m3 | J1: Water Utility Supply (m3) $/m3 | K1: Room Nights | L1: Total Guests | M1: Utilities day cost dh
A2: Mumbai | B2: 1 | C2: 11 | D2: 2021 | E2: =(IF('Daily HLP'!H4>0,'Daily HLP'!H4,0)) -> 21808.97 | F2: 9 | G2: =(IF('Daily HLP'!L4>0,'Daily HLP'!L4,0)) -> 1029.03 | H2: 65 | I2: =(IF('Daily HLP'!O4>0,'Daily HLP'!O4,0)) -> 237 | J2: 99 | K2: =Occupancy!G2 -> 127 | L2: =Occupancy!F2 -> 514 | M2: =E2*F2+G2*H2+#REF!*#REF!+I2*J2 -> #REF!
A3: Mumbai | B3: =B2+1 -> 2 | C3: 11 | D3: 2021 | E3: =(IF('Daily HLP'!H5>0,'Daily HLP'!H5,0)) -> 22954.08 | F3: 9 | G3: =(IF('Daily HLP'!L5>0,'Daily HLP'!L5,0)) -> 946.85 | H3: 65 | I3: =(IF('Daily HLP'!O5>0,'Daily HLP'!O5,0)) -> 270 | J3: 99 | K3: =Occupancy!G3 -> 109 | L3: =Occupancy!F3 -> 502 | M3: =E3*F3+G3*H3+#REF!*#REF!+I3*J3 -> #REF!
A4: Mumbai | B4: =B3+1 -> 3 | C4: 11 | D4: 2021 | E4: =(IF('Daily HLP'!H6>0,'Daily HLP'!H6,0)) -> 22487.75 | F4: 9 | G4: =(IF('Daily HLP'!L6>0,'Daily HLP'!L6,0)) -> 955.49 | H4: 65 | I4: =(IF('Daily HLP'!O6>0,'Daily HLP'!O6,0)) -> 279 | J4: 99 | K4: =Occupancy!G4 -> 91 | L4: =Occupancy!F4 -> 363 | M4: =E4*F4+G4*H4+#REF!*#REF!+I4*J4 -> #REF!
A5: Mumbai | B5: =B4+1 -> 4 | C5: 11 | D5: 2021 | E5: =(IF('Daily HLP'!H7>0,'Daily HLP'!H7,0)) -> 20833.41 | F5: 9 | G5: =(IF('Daily HLP'!L7>0,'Daily HLP'!L7,0)) -> 914.75 | H5: 65 | I5: =(IF('Daily HLP'!O7>0,'Daily HLP'!O7,0)) -> 239 | J5: 99 | K5: =Occupancy!G5 -> 84 | L5: =Occupancy!F5 -> 386 | M5: =E5*F5+G5*H5+#REF!*#REF!+I5*J5 -> #REF!
A6: Mumbai | B6: =B5+1 -> 5 | C6: 11 | D6: 2021 | E6: =(IF('Daily HLP'!H8>0,'Daily HLP'!H8,0)) -> 24186.89 | F6: 9 | G6: =(IF('Daily HLP'!L8>0,'Daily HLP'!L8,0)) -> 889.92 | H6: 65 | I6: =(IF('Daily HLP'!O8>0,'Daily HLP'!O8,0)) -> 159 | J6: 99 | K6: =Occupancy!G6 -> 165 | L6: =Occupancy!F6 -> 675 | M6: =E6*F6+G6*H6+#REF!*#REF!+I6*J6 -> #REF!
A7: Mumbai | B7: =B6+1 -> 6 | C7: 11 | D7: 2021 | E7: =(IF('Daily HLP'!H9>0,'Daily HLP'!H9,0)) -> 22837.55 | F7: 9 | G7: =(IF('Daily HLP'!L9>0,'Daily HLP'!L9,0)) -> 955.68 | H7: 65 | I7: =(IF('Daily HLP'!O9>0,'Daily HLP'!O9,0)) -> 291 | J7: 99 | K7: =Occupancy!G7 -> 184 | L7: =Occupancy!F7 -> 588 | M7: =E7*F7+G7*H7+#REF!*#REF!+I7*J7 -> #REF!
A8: Mumbai | B8: =B7+1 -> 7 | C8: 11 | D8: 2021 | E8: =(IF('Daily HLP'!H10>0,'Daily HLP'!H10,0)) -> 21951.04 | F8: 9 | G8: =(IF('Daily HLP'!L10>0,'Daily HLP'!L10,0)) -> 962.49 | H8: 65 | I8: =(IF('Daily HLP'!O10>0,'Daily HLP'!O10,0)) -> 259 | J8: 99 | K8: =Occupancy!G8 -> 159 | L8: =Occupancy!F8 -> 525 | M8: =E8*F8+G8*H8+#REF!*#REF!+I8*J8 -> #REF!
A9: Mumbai | B9: =B8+1 -> 8 | C9: 11 | D9: 2021 | E9: =(IF('Daily HLP'!H11>0,'Daily HLP'!H11,0)) -> 21972.24 | F9: 9 | G9: =(IF('Daily HLP'!L11>0,'Daily HLP'!L11,0)) -> 1009.75 | H9: 65 | I9: =(IF('Daily HLP'!O11>0,'Daily HLP'!O11,0)) -> 258 | J9: 99 | K9: =Occupancy!G9 -> 117 | L9: =Occupancy!F9 -> 464 | M9: =E9*F9+G9*H9+#REF!*#REF!+I9*J9 -> #REF!
A10: Mumbai | B10: =B9+1 -> 9 | C10: 11 | D10: 2021 | E10: =(IF('Daily HLP'!H12>0,'Daily HLP'!H12,0)) -> 21818.17 | F10: 9 | G10: =(IF('Daily HLP'!L12>0,'Daily HLP'!L12,0)) -> 1028.08 | H10: 65 | I10: =(IF('Daily HLP'!O12>0,'Daily HLP'!O12,0)) -> 253 | J10: 99 | K10: =Occupancy!G10 -> 128 | L10: =Occupancy!F10 -> 385 | M10: =E10*F10+G10*H10+#REF!*#REF!+I10*J10 -> #REF!
A11: Mumbai | B11: =B10+1 -> 10 | C11: 11 | D11: 2021 | E11: =(IF('Daily HLP'!H13>0,'Daily HLP'!H13,0)) -> 21010 | F11: 9 | G11: =(IF('Daily HLP'!L13>0,'Daily HLP'!L13,0)) -> 1016 | H11: 65 | I11: =(IF('Daily HLP'!O13>0,'Daily HLP'!O13,0)) -> 225 | J11: 99 | K11: =Occupancy!G11 -> 151 | L11: =Occupancy!F11 -> 503 | M11: =E11*F11+G11*H11+#REF!*#REF!+I11*J11 -> #REF!
A12: Mumbai | B12: =B11+1 -> 11 | C12: 11 | D12: 2021 | E12: =(IF('Daily HLP'!H14>0,'Daily HLP'!H14,0)) -> 20585 | F12: 9 | G12: =(IF('Daily HLP'!L14>0,'Daily HLP'!L14,0)) -> 1046 | H12: 65 | I12: =(IF('Daily HLP'!O14>0,'Daily HLP'!O14,0)) -> 233 | J12: 99 | K12: =Occupancy!G12 -> 166 | L12: =Occupancy!F12 -> 521 | M12: =E12*F12+G12*H12+#REF!*#REF!+I12*J12 -> #REF!
A13: Mumbai | B13: =B12+1 -> 12 | C13: 11 | D13: 2021 | E13: =(IF('Daily HLP'!H15>0,'Daily HLP'!H15,0)) -> 22424 | F13: 9 | G13: =(IF('Daily HLP'!L15>0,'Daily HLP'!L15,0)) -> 1060 | H13: 65 | I13: =(IF('Daily HLP'!O15>0,'Daily HLP'!O15,0)) -> 278 | J13: 99 | K13: =Occupancy!G13 -> 166 | L13: =Occupancy!F13 -> 684 | M13: =E13*F13+G13*H13+#REF!*#REF!+I13*J13 -> #REF!
A14: Mumbai | B14: =B13+1 -> 13 | C14: 11 | D14: 2021 | E14: =(IF('Daily HLP'!H16>0,'Daily HLP'!H16,0)) -> 24350 | F14: 9 | G14: =(IF('Daily HLP'!L16>0,'Daily HLP'!L16,0)) -> 1071 | H14: 65 | I14: =(IF('Daily HLP'!O16>0,'Daily HLP'!O16,0)) -> 256 | J14: 99 | K14: =Occupancy!G14 -> 148 | L14: =Occupancy!F14 -> 756 | M14: =E14*F14+G14*H14+#REF!*#REF!+I14*J14 -> #REF!
... A31: Mumbai | B31: =B30+1 -> 30 | C31: 11 | D31: 2021 | E31: =(IF('Daily HLP'!H33>0,'Daily HLP'!H33,0)) -> 21500 | F31: 9 | G31: =(IF('Daily HLP'!L33>0,'Daily HLP'!L33,0)) -> 988 | H31: 65 | I31: =(IF('Daily HLP'!O33>0,'Daily HLP'!O33,0)) -> 247 | J31: 99 | K31: =Occupancy!G31 -> 0 | L31: =Occupancy!F31 -> 0 | M31: =E31*F31+G31*H31+#REF!*#REF!+I31*J31 -> #REF!
A32: Mumbai | B32: =B31+1 -> 31 | C32: 11 | D32: 2021 | E32: =(IF('Daily HLP'!H34>0,'Daily HLP'!H34,0)) -> 21500 | F32: 9 | G32: =(IF('Daily HLP'!L34>0,'Daily HLP'!L34,0)) -> 1024.96 | H32: 65 | I32: =(IF('Daily HLP'!O34>0,'Daily HLP'!O34,0)) -> 269 | J32: 99 | K32: =Occupancy!G32 -> 0 | L32: =Occupancy!F32 -> 0

Sheet Submetering
A1: Site Name | B1: Day | C1: Month | D1: Year | E1: ='Section Load'!F4 -> HVAC | F1: ='Section Load'!G4 -> Fire & Emergency PP | G1: ='Section Load'!H4 -> Main PP | H1: ='Section Load'!I4 -> Lighting PP | I1: ='Section Load'!J4 -> CH-1+ CH2+CH3+CH4 | J1: ='Section Load'!K4 -> Chilled water Pump | K1: ='Section Load'!L4 -> Ball Room-1 | L1: ='Section Load'!M4 -> Ball Room-2 | ... AL1: ='Section Load'!AM4 -> Cooling Tower | AM1: R.o.plant | AN1: STP Water Prod | AO1: Domestic Zone-1 | AP1: Domestic Zone-2 | AQ1: Domestic Zone-3 | AR1: Flush Zone -1 | AS1: Flush Zone -2 | AT1: Flush Zone -3 | AU1: Swimming pool | AV1: B2 Laundry | AW1: Boiler Feed Water | AX1: cooling tower filling water | AY1: STP flush(new water meter) | AZ1: Garden Water Pump | BA1: Flush Zone 2 pump meter | BB1: Flush Zone 3 Pump Meter (wtp transfer ) | BC1: Flush Tanker-Zone-1 | BD1: Total Domestic Water (Tanker (R.O) +BMC) | BE1: Total Domestic Consumption | BF1: Total STP Consumption | BG1: ='Section Load'!AN4 -> MGL | BH1: ='Section Load'!AO4 -> HWG | BI1: ='Section Load'!AP4 -> Prato | BJ1: ='Section Load'!AQ4 -> BR-1 | BK1: ='Section Load'!AR4 -> SanQi IND | BL1: ='Section Load'!AS4 -> SanQi JPN | BM1: ='Section Load'!AT4 -> Boiler
A2: Mumbai | B2: 1 | C2: 11 | D2: 2021 | E2: =(IF('Section Load'!F5>0,'Section Load'!F5,0)) -> 3192.96 | F2: =(IF('Section Load'!G5>0,'Section Load'!G5,0)) -> 1604.96 | G2: =(IF('Section Load'!H5>0,'Section Load'!H5,0)) -> 1846.14 | H2: =(IF('Section Load'!I5>0,'Section Load'!I5,0)) -> 2900.04 | I2: =(IF('Section Load'!J5>0,'Section Load'!J5,0)) -> 5549.16 | J2: =(IF('Section Load'!K5>0,'Section Load'!K5,0)) -> 2600.9 | K2: =(IF('Section Load'!L5>0,'Section Load'!L5,0)) -> 1026.96 | L2: =(IF('Section Load'!M5>0,'Section Load'!M5,0)) -> 683.28 | ... AL2: =(IF('Section Load'!AM5>0,'Section Load'!AM5,0)) -> 604.29 | AM2: =(IF('Water Report'!$D$7>0,'Water Report'!$D$7,0)) -> 118 | AN2: =(IF('Water Report'!$D$8>0,'Water Report'!$D$8,0)) -> 80 | AO2: =(IF('Water Report'!$D$9>0,'Water Report'!$D$9,0)) -> 97 | AP2: =(IF('Water Report'!$D$10>0,'Water Report'!$D$10,0)) -> 23 | AQ2: =(IF('Water Report'!$D$11>0,'Water Report'!$D$11,0)) -> 30 | AR2: =(IF('Water Report'!$D$13>0,'Water Report'!$D$13,0)) -> 41 | AS2: =(IF('Water Report'!$D$14>0,'Water Report'!$D$14,0)) -> 9 | AT2: =(IF('Water Report'!$D$15>0,'Water Report'!$D$15,0)) -> 7 | AU2: =(IF('Water Report'!$D$17>0,'Water Report'!$D$17,0)) -> 0 | AV2: =(IF('Water Report'!$D$18>0,'Water Report'!$D$18,0)) -> 16 | AW2: =(IF('Water Report'!$D$19>0,'Water Report'!$D$19,0)) -> 11 | AX2: =(IF('Water Report'!$D$21>0,'Water Report'!$D$21,0)) -> 68 | AY2: =(IF('Water Report'!$D$22>0,'Water Report'!$D$22,0)) -> 0 | AZ2: =(IF('Water Report'!$D$23>0,'Water Report'!$D$23,0)) -> 0 | BA2: =(IF('Water Report'!$D$14>0,'Water Report'!$D$14,0)) -> 9 | BB2: =(IF('Water Report'!$D$15>0,'Water Report'!$D$15,0)) -> 7 | BC2: =(IF('Water Report'!$D$13>0,'Water Report'!$D$13,0)) -> 41 | BD2: =(IF('Water Report'!$D$24>0,'Water Report'!$D$24,0)) -> 237 | BE2: =(IF('Water Report'!$D$25>0,'Water Report'!$D$25,0)) -> 166 | BF2: =(IF('Water Report'!$D$27>0,'Water Report'!$D$27,0)) -> 109 | BG2: =(IF('Section Load'!AN5>0,'Section Load'!AN5,0)) -> 1029.03 | BH2: =(IF('Section Load'!AO5>0,'Section Load'!AO5,0)) -> 294.149 | BI2: =(IF('Section Load'!AP5>0,'Section Load'!AP5,0)) -> 0 | BJ2: =(IF('Section Load'!AQ5>0,'Section Load'!AQ5,0)) -> 94.87 | BK2: =(IF('Section Load'!AR5>0,'Section Load'!AR5,0)) -> 35.4 | BL2: =(IF('Section Load'!AS5>0,'Section Load'!AS5,0)) -> 2 | BM2: =(IF('Section Load'!AT5>0,'Section Load'!AT5,0)) -> 602.611
A3: Mumbai | B3: =B2+1 -> 2 | C3: 11 | D3: 2021 | E3: =(IF('Section Load'!F6>0,'Section Load'!F6,0)) -> 3505.37 | F3: =(IF('Section Load'!G6>0,'Section Load'!G6,0)) -> 1550.52 | G3: =(IF('Section Load'!H6>0,'Section Load'!H6,0)) -> 1770.99 | H3: =(IF('Section Load'!I6>0,'Section Load'!I6,0)) -> 2945.4 | I3: =(IF('Section Load'!J6>0,'Section Load'!J6,0)) -> 6250.29 | J3: =(IF('Section Load'!K6>0,'Section Load'!K6,0)) -> 2747.8 | K3: =(IF('Section Load'!L6>0,'Section Load'!L6,0)) -> 1026.48 | L3: =(IF('Section Load'!M6>0,'Section Load'!M6,0)) -> 757.12 | ... AL3: =(IF('Section Load'!AM6>0,'Section Load'!AM6,0)) -> 675.56 | AM3: =(IF('Water Report'!$E$7>0,'Water Report'!$E$7,0)) -> 108 | AN3: =(IF('Water Report'!$E$8>0,'Water Report'!$E$8,0)) -> 89 | AO3: =(IF('Water Report'!$E$9>0,'Water Report'!$E$9,0)) -> 109 | AP3: =(IF('Water Report'!$E$10>0,'Water Report'!$E$10,0)) -> 18 | AQ3: =(IF('Water Report'!$E$11>0,'Water Report'!$E$11,0)) -> 24 | AR3: =(IF('Water Report'!$E$13>0,'Water Report'!$E$13,0)) -> 26 | AS3: =(IF('Water Report'!$E$14>0,'Water Report'!$E$14,0)) -> 6 | AT3: =(IF('Water Report'!$E$15>0,'Water Report'!$E$15,0)) -> 10 | AU3: =(IF('Water Report'!$E$17>0,'Water Report'!$E$17,0)) -> 0 | AV3: =(IF('Water Report'!$E$18>0,'Water Report'!$E$18,0)) -> 12 | AW3: =(IF('Water Report'!$E$19>0,'Water Report'!$E$19,0)) -> 10 | AX3: =(IF('Water Report'!$E$21>0,'Water Report'!$E$21,0)) -> 57 | AY3: =(IF('Water Report'!$E$22>0,'Water Report'!$E$22,0)) -> 0 | AZ3: =(IF('Water Report'!$E$23>0,'Water Report'!$E$23,0)) -> 19 | BA3: =(IF('Water Report'!$E$14>0,'Water Report'!$E$14,0)) -> 6 | BB3: =(IF('Water Report'!$E$15>0,'Water Report'!$E$15,0)) -> 10 | BC3: =(IF('Water Report'!$E$13>0,'Water Report'!$E$13,0)) -> 26 | BD3: =(IF('Water Report'!$E$24>0,'Water Report'!$E$24,0)) -> 270 | BE3: =(IF('Water Report'!$E$25>0,'Water Report'!$E$25,0)) -> 167 | BF3: =(IF('Water Report'!$E$27>0,'Water Report'!$E$27,0)) -> 102 | BG3: =(IF('Section Load'!AN6>0,'Section Load'!AN6,0)) -> 946.85 | BH3: =(IF('Section Load'!AO6>0,'Section Load'!AO6,0)) -> 292.8 | BI3: =(IF('Section Load'!AP6>0,'Section Load'!AP6,0)) -> 0 | BJ3: =(IF('Section Load'!AQ6>0,'Section Load'!AQ6,0)) -> 96.84 | BK3: =(IF('Section Load'!AR6>0,'Section Load'!AR6,0)) -> 37.5 | BL3: =(IF('Section Load'!AS6>0,'Section Load'!AS6,0)) -> 2.9 | BM3: =(IF('Section Load'!AT6>0,'Section Load'!AT6,0)) -> 516.81
A4: Mumbai | B4: =B3+1 -> 3 | C4: 11 | D4: 2021 | E4: =(IF('Section Load'!F7>0,'Section Load'!F7,0)) -> 3774.23 | F4: =(IF('Section Load'!G7>0,'Section Load'!G7,0)) -> 1629.46 | G4: =(IF('Section Load'!H7>0,'Section Load'!H7,0)) -> 1944.71 | H4: =(IF('Section Load'!I7>0,'Section Load'!I7,0)) -> 2961.16 | I4: =(IF('Section Load'!J7>0,'Section Load'!J7,0)) -> 5371.22 | J4: =(IF('Section Load'!K7>0,'Section Load'!K7,0)) -> 2695.4 | K4: =(IF('Section Load'!L7>0,'Section Load'!L7,0)) -> 960.16 | L4: =(IF('Section Load'!M7>0,'Section Load'!M7,0)) -> 684.49 | ... AL4: =(IF('Section Load'!AM7>0,'Section Load'!AM7,0)) -> 815.11 | AM4: =(IF('Water Report'!$F$7>0,'Water Report'!$F$7,0)) -> 128 | AN4: =(IF('Water Report'!$F$8>0,'Water Report'!$F$8,0)) -> 113 | AO4: =(IF('Water Report'!$F$9>0,'Water Report'!$G$9,0)) -> 85 | AP4: =(IF('Water Report'!$F$10>0,'Water Report'!$F$10,0)) -> 17 | AQ4: =(IF('Water Report'!$F$11>0,'Water Report'!$F$11,0)) -> 19 | AR4: =(IF('Water Report'!$F$13>0,'Water Report'!$F$13,0)) -> 35 | AS4: =(IF('Water Report'!$F$14>0,'Water Report'!$F$14,0)) -> 30 | AT4: =(IF('Water Report'!$F$15>0,'Water Report'!$F$15,0)) -> 15 | AU4: =(IF('Water Report'!$F$17>0,'Water Report'!$F$17,0)) -> 0 | AV4: =(IF('Water Report'!$F$18>0,'Water Report'!$F$18,0)) -> 14 | AW4: =(IF('Water Report'!$F$19>0,'Water Report'!$F$19,0)) -> 8 | AX4: =(IF('Water Report'!$F$21>0,'Water Report'!$F$21,0)) -> 60 | AY4: =(IF('Water Report'!$F$22>0,'Water Report'!$F$22,0)) -> 0 | AZ4: =(IF('Water Report'!$F$23>0,'Water Report'!$F$23,0)) -> 14 | BA4: =(IF('Water Report'!$F$14>0,'Water Report'!$F$14,0)) -> 30 | BB4: =(IF('Water Report'!$F$15>0,'Water Report'!$F$15,0)) -> 15 | BC4: =(IF('Water Report'!$F$13>0,'Water Report'!$F$13,0)) -> 35 | BD4: =(IF('Water Report'!$F$24>0,'Water Report'!$F$24,0)) -> 279 | BE4: =(IF('Water Report'!$F$25>0,'Water Report'!$F$25,0)) -> 202 | BF4: =(IF('Water Report'!$F$27>0,'Water Report'!$F$27,0)) -> 109 | BG4: =(IF('Section Load'!AN7>0,'Section Load'!AN7,0)) -> 955.49 | BH4: =(IF('Section Load'!AO7>0,'Section Load'!AO7,0)) -> 291.926 | BI4: =(IF('Section Load'!AP7>0,'Section Load'!AP7,0)) -> 0 | BJ4: =(IF('Section Load'!AQ7>0,'Section Load'!AQ7,0)) -> 114.23 | BK4: =(IF('Section Load'!AR7>0,'Section Load'!AR7,0)) -> 36.1 | BL4: =(IF('Section Load'!AS7>0,'Section Load'!AS7,0)) -> 1 | BM4: =(IF('Section Load'!AT7>0,'Section Load'!AT7,0)) -> 512.234
A5: Mumbai | B5: =B4+1 -> 4 | C5: 11 | D5: 2021 | E5: =(IF('Section Load'!F8>0,'Section Load'!F8,0)) -> 3614.51 | F5: =(IF('Section Load'!G8>0,'Section Load'!G8,0)) -> 1438.9 | G5: =(IF('Section Load'!H8>0,'Section Load'!H8,0)) -> 1642.61 | H5: =(IF('Section Load'!I8>0,'Section Load'!I8,0)) -> 2745.68 | I5: =(IF('Section Load'!J8>0,'Section Load'!J8,0)) -> 5066.5 | J5: =(IF('Section Load'!K8>0,'Section Load'!K8,0)) -> 2524.2 | K5: =(IF('Section Load'!L8>0,'Section Load'!L8,0)) -> 884 | L5: =(IF('Section Load'!M8>0,'Section Load'!M8,0)) -> 640.12 | ... AL5: =(IF('Section Load'!AM8>0,'Section Load'!AM8,0)) -> 752.16 | AM5: =(IF('Water Report'!$G$7>0,'Water Report'!$F$7,0)) -> 128 | AN5: =(IF('Water Report'!$G$8>0,'Water Report'!$F$8,0)) -> 113 | AO5: =(IF('Water Report'!$G$9>0,'Water Report'!$H$9,0)) -> 72 | AP5: =(IF('Water Report'!$G$10>0,'Water Report'!$G$10,0)) -> 17 | AQ5: =(IF('Water Report'!$G$11>0,'Water Report'!$G$11,0)) -> 17 | AR5: =(IF('Water Report'!$G$13>0,'Water Report'!$G$13,0)) -> 40 | AS5: =(IF('Water Report'!$G$14>0,'Water Report'!$G$14,0)) -> 7 | AT5: =(IF('Water Report'!$G$15>0,'Water Report'!$G$15,0)) -> 13 | AU5: =(IF('Water Report'!$G$17>0,'Water Report'!$G$17,0)) -> 0 | AV5: =(IF('Water Report'!$G$18>0,'Water Report'!$G$18,0)) -> 9 | AW5: =(IF('Water Report'!$G$19>0,'Water Report'!$G$19,0)) -> 10 | AX5: =(IF('Water Report'!$G$21>0,'Water Report'!$G$21,0)) -> 65 | AY5: =(IF('Water Report'!$G$22>0,'Water Report'!$G$22,0)) -> 0 | AZ5: =(IF('Water Report'!$G$23>0,'Water Report'!$G$23,0)) -> 1 | BA5: =(IF('Water Report'!$G$14>0,'Water Report'!$G$14,0)) -> 7 | BB5: =(IF('Water Report'!$G$15>0,'Water Report'!$G$15,0)) -> 13 | BC5: =(IF('Water Report'!$G$13>0,'Water Report'!$G$13,0)) -> 40 | BD5: =(IF('Water Report'!$G$24>0,'Water Report'!$G$24,0)) -> 239 | BE5: =(IF('Water Report'!$G$25>0,'Water Report'!$G$25,0)) -> 139 | BF5: =(IF('Water Report'!$G$27>0,'Water Report'!$G$27,0)) -> 106 | BG5: =(IF('Section Load'!AN8>0,'Section Load'!AN8,0)) -> 914.75 | BH5: =(IF('Section Load'!AO8>0,'Section Load'!AO8,0)) -> 278.424 | BI5: =(IF('Section Load'!AP8>0,'Section Load'!AP8,0)) -> 0 | BJ5: =(IF('Section Load'!AQ8>0,'Section Load'!AQ8,0)) -> 85.56 | BK5: =(IF('Section Load'!AR8>0,'Section Load'!AR8,0)) -> 44.5 | BL5: =(IF('Section Load'!AS8>0,'Section Load'!AS8,0)) -> 3.6 | BM5: =(IF('Section Load'!AT8>0,'Section Load'!AT8,0)) -> 502.666
A6: Mumbai | B6: =B5+1 -> 5 | C6: 11 | D6: 2021 | E6: =(IF('Section Load'!F9>0,'Section Load'!F9,0)) -> 3597.87 | F6: =(IF('Section Load'!G9>0,'Section Load'!G9,0)) -> 1602.33 | G6: =(IF('Section Load'!H9>0,'Section Load'!H9,0)) -> 1798.51 | H6: =(IF('Section Load'!I9>0,'Section Load'!I9,0)) -> 2856.67 | I6: =(IF('Section Load'!J9>0,'Section Load'!J9,0)) -> 6887.75 | J6: =(IF('Section Load'!K9>0,'Section Load'!K9,0)) -> 2973.3 | K6: =(IF('Section Load'!L9>0,'Section Load'!L9,0)) -> 1183.09 | L6: =(IF('Section Load'!M9>0,'Section Load'!M9,0)) -> 903.32 | ... AL6: =(IF('Section Load'!AM9>0,'Section Load'!AM9,0)) -> 815.59 | AM6: =(IF('Water Report'!$H$7>0,'Water Report'!$H$7,0)) -> 67 | AN6: =(IF('Water Report'!$H$8>0,'Water Report'!$H$8,0)) -> 95 | AO6: =(IF('Water Report'!$H$9>0,'Water Report'!$H$9,0)) -> 72 | AP6: =(IF('Water Report'!$H$10>0,'Water Report'!$H$10,0)) -> 13 | AQ6: =(IF('Water Report'!$H$11>0,'Water Report'!$H$11,0)) -> 30 | AR6: =(IF('Water Report'!$H$13>0,'Water Report'!$H$13,0)) -> 28 | AS6: =(IF('Water Report'!$H$14>0,'Water Report'!$H$14,0)) -> 9 | AT6: =(IF('Water Report'!$H$15>0,'Water Report'!$H$15,0)) -> 10 | AU6: =(IF('Water Report'!$H$17>0,'Water Report'!$H$17,0)) -> 0 | AV6: =(IF('Water Report'!$H$18>0,'Water Report'!$H$18,0)) -> 8 | AW6: =(IF('Water Report'!$H$19>0,'Water Report'!$H$19,0)) -> 8 | AX6: =(IF('Water Report'!$H$21>0,'Water Report'!$H$21,0)) -> 122 | AY6: =(IF('Water Report'!$H$22>0,'Water Report'!$H$22,0)) -> 0 | AZ6: =(IF('Water Report'!$H$23>0,'Water Report'!$H$23,0)) -> 2 | BA6: =(IF('Water Report'!$H$14>0,'Water Report'!$H$14,0)) -> 9 | BB6: =(IF('Water Report'!$H$15>0,'Water Report'!$H$15,0)) -> 10 | BC6: =(IF('Water Report'!$H$13>0,'Water Report'!$H$13,0)) -> 28 | BD6: =(IF('Water Report'!$H$24>0,'Water Report'!$H$24,0)) -> 159 | BE6: =(IF('Water Report'!$H$25>0,'Water Report'!$H$25,0)) -> 134 | BF6: =(IF('Water Report'!$H$27>0,'Water Report'!$H$27,0)) -> 152 | BG6: =(IF('Section Load'!AN9>0,'Section Load'!AN9,0)) -> 889.92 | BH6: =(IF('Section Load'!AO9>0,'Section Load'!AO9,0)) -> 289.47 | BI6: =(IF('Section Load'!AP9>0,'Section Load'!AP9,0)) -> 0 | BJ6: =(IF('Section Load'!AQ9>0,'Section Load'!AQ9,0)) -> 87 | BK6: =(IF('Section Load'!AR9>0,'Section Load'!AR9,0)) -> 47 | BL6: =(IF('Section Load'!AS9>0,'Section Load'!AS9,0)) -> 2.1 | BM6: =(IF('Section Load'!AT9>0,'Section Load'!AT9,0)) -> 464.35
A7: Mumbai | B7: =B6+1 -> 6 | C7: 11 | D7: 2021 | E7: =(IF('Section Load'!F10>0,'Section Load'!F10,0)) -> 3610.56 | F7: =(IF('Section Load'!G10>0,'Section Load'!G10,0)) -> 1653.71 | G7: =(IF('Section Load'!H10>0,'Section Load'!H10,0)) -> 1902.3 | H7: =(IF('Section Load'!I10>0,'Section Load'!I10,0)) -> 2809.59 | I7: =(IF('Section Load'!J10>0,'Section Load'!J10,0)) -> 5959.01 | J7: =(IF('Section Load'!K10>0,'Section Load'!K10,0)) -> 2754.6 | K7: =(IF('Section Load'!L10>0,'Section Load'!L10,0)) -> 1109.71 | L7: =(IF('Section Load'!M10>0,'Section Load'!M10,0)) -> 875.98 | ... AL7: =(IF('Section Load'!AM10>0,'Section Load'!AM10,0)) -> 804.89 | AM7: =(IF('Water Report'!$I$7>0,'Water Report'!$I$7,0)) -> 144 | AN7: =(IF('Water Report'!$I$8>0,'Water Report'!$I$8,0)) -> 100 | AO7: =(IF('Water Report'!$I$9>0,'Water Report'!$I$9,0)) -> 110 | AP7: =(IF('Water Report'!$I$10>0,'Water Report'!$I$10,0)) -> 32 | AQ7: =(IF('Water Report'!$I$11>0,'Water Report'!$I$11,0)) -> 41 | AR7: =(IF('Water Report'!$I$13>0,'Water Report'!$I$13,0)) -> 14 | AS7: =(IF('Water Report'!$I$14>0,'Water Report'!$I$14,0)) -> 22 | AT7: =(IF('Water Report'!$I$15>0,'Water Report'!$I$15,0)) -> 17 | AU7: =(IF('Water Report'!$I$17>0,'Water Report'!$I$17,0)) -> 23 | AV7: =(IF('Water Report'!$I$18>0,'Water Report'!$I$18,0)) -> 10 | AW7: =(IF('Water Report'!$I$19>0,'Water Report'!$I$19,0)) -> 9 | AX7: =(IF('Water Report'!$I$21>0,'Water Report'!$I$21,0)) -> 129 | AY7: =(IF('Water Report'!$I$22>0,'Water Report'!$I$22,0)) -> 0 | AZ7: =(IF('Water Report'!$I$23>0,'Water Report'!$I$23,0)) -> 15 | BA7: =(IF('Water Report'!$I$14>0,'Water Report'!$I$14,0)) -> 22 | BB7: =(IF('Water Report'!$I$15>0,'Water Report'!$I$15,0)) -> 17 | BC7: =(IF('Water Report'!$I$13>0,'Water Report'!$I$13,0)) -> 14 | BD7: =(IF('Water Report'!$I$24>0,'Water Report'!$I$24,0)) -> 291 | BE7: =(IF('Water Report'!$I$25>0,'Water Report'!$I$25,0)) -> 222 | BF7: =(IF('Water Report'!$I$27>0,'Water Report'!$I$27,0)) -> 158 | BG7: =(IF('Section Load'!AN10>0,'Section Load'!AN10,0)) -> 955.68 | BH7: =(IF('Section Load'!AO10>0,'Section Load'!AO10,0)) -> 308.46 | BI7: =(IF('Section Load'!AP10>0,'Section Load'!AP10,0)) -> 3.4 | BJ7: =(IF('Section Load'!AQ10>0,'Section Load'!AQ10,0)) -> 88.75 | BK7: =(IF('Section Load'!AR10>0,'Section Load'!AR10,0)) -> 47 | BL7: =(IF('Section Load'!AS10>0,'Section Load'!AS10,0)) -> 3 | BM7: =(IF('Section Load'!AT10>0,'Section Load'!AT10,0)) -> 505.07
A8: Mumbai | B8: =B7+1 -> 7 | C8: 11 | D8: 2021 | E8: =(IF('Section Load'!F11>0,'Section Load'!F11,0)) -> 3710.46 | F8: =(IF('Section Load'!G11>0,'Section Load'!G11,0)) -> 1579.82 | G8: =(IF('Section Load'!H11>0,'Section Load'!H11,0)) -> 1893.21 | H8: =(IF('Section Load'!I11>0,'Section Load'!I11,0)) -> 2812.86 | I8: =(IF('Section Load'!J11>0,'Section Load'!J11,0)) -> 5341.64 | J8: =(IF('Section Load'!K11>0,'Section Load'!K11,0)) -> 2609.7 | K8: =(IF('Section Load'!L11>0,'Section Load'!L11,0)) -> 1148.88 | L8: =(IF('Section Load'!M11>0,'Section Load'!M11,0)) -> 701.53 | ... AL8: =(IF('Section Load'!AM11>0,'Section Load'!AM11,0)) -> 832.26 | AM8: =(IF('Water Report'!$J$7>0,'Water Report'!$J$7,0)) -> 133 | AN8: =(IF('Water Report'!$J$8>0,'Water Report'!$J$8,0)) -> 126 | AO8: =(IF('Water Report'!$J$9>0,'Water Report'!$J$9,0)) -> 90 | AP8: =(IF('Water Report'!$J$10>0,'Water Report'!$J$10,0)) -> 31 | AQ8: =(IF('Water Report'!$J$11>0,'Water Report'!$J$11,0)) -> 33 | AR8: =(IF('Water Report'!$J$13>0,'Water Report'!$J$13,0)) -> 25 | AS8: =(IF('Water Report'!$J$14>0,'Water Report'!$J$14,0)) -> 17 | AT8: =(IF('Water Report'!$J$15>0,'Water Report'!$J$15,0)) -> 11 | AU8: =(IF('Water Report'!$J$17>0,'Water Report'!$J$17,0)) -> 0 | AV8: =(IF('Water Report'!$J$18>0,'Water Report'!$J$18,0)) -> 13 | AW8: =(IF('Water Report'!$J$19>0,'Water Report'!$J$19,0)) -> 13 | AX8: =(IF('Water Report'!$J$21>0,'Water Report'!$J$21,0)) -> 89 | AY8: =(IF('Water Report'!$J$22>0,'Water Report'!$J$22,0)) -> 0 | AZ8: =(IF('Water Report'!$J$23>0,'Water Report'!$J$23,0)) -> 2 | BA8: =(IF('Water Report'!$J$14>0,'Water Report'!$J$14,0)) -> 17 | BB8: =(IF('Water Report'!$J$15>0,'Water Report'!$J$15,0)) -> 11 | BC8: =(IF('Water Report'!$J$13>0,'Water Report'!$J$13,0)) -> 25 | BD8: =(IF('Water Report'!$J$24>0,'Water Report'!$J$24,0)) -> 259 | BE8: =(IF('Water Report'!$J$25>0,'Water Report'!$J$25,0)) -> 182 | BF8: =(IF('Water Report'!$J$27>0,'Water Report'!$J$27,0)) -> 116 | BG8: =(IF('Section Load'!AN11>0,'Section Load'!AN11,0)) -> 962.49 | BH8: =(IF('Section Load'!AO11>0,'Section Load'!AO11,0)) -> 288.83 | BI8: =(IF('Section Load'!AP11>0,'Section Load'!AP11,0)) -> 0 | BJ8: =(IF('Section Load'!AQ11>0,'Section Load'!AQ11,0)) -> 86.23 | BK8: =(IF('Section Load'!AR11>0,'Section Load'!AR11,0)) -> 37 | BL8: =(IF('Section Load'!AS11>0,'Section Load'!AS11,0)) -> 1.3 | BM8: =(IF('Section Load'!AT11>0,'Section Load'!AT11,0)) -> 549.13
A9: Mumbai | B9: =B8+1 -> 8 | C9: 11 | D9: 2021 | E9: =(IF('Section Load'!F12>0,'Section Load'!F12,0)) -> 3847.94 | F9: =(IF('Section Load'!G12>0,'Section Load'!G12,0)) -> 1589.14 | G9: =(IF('Section Load'!H12>0,'Section Load'!H12,0)) -> 1785.87 | H9: =(IF('Section Load'!I12>0,'Section Load'!I12,0)) -> 2891.22 | I9: =(IF('Section Load'!J12>0,'Section Load'!J12,0)) -> 5181.82 | J9: =(IF('Section Load'!K12>0,'Section Load'!K12,0)) -> 2607.8 | K9: =(IF('Section Load'!L12>0,'Section Load'!L12,0)) -> 1020.8 | L9: =(IF('Section Load'!M12>0,'Section Load'!M12,0)) -> 823.66 | ... AL9: =(IF('Section Load'!AM12>0,'Section Load'!AM12,0)) -> 780.19 | AM9: =(IF('Water Report'!$K$7>0,'Water Report'!$K$7,0)) -> 118 | AN9: =(IF('Water Report'!$K$8>0,'Water Report'!$K$8,0)) -> 107 | AO9: =(IF('Water Report'!$K$9>0,'Water Report'!$K$9,0)) -> 96 | AP9: =(IF('Water Report'!$K$10>0,'Water Report'!$K$10,0)) -> 27 | AQ9: =(IF('Water Report'!$K$11>0,'Water Report'!$K$11,0)) -> 29 | AR9: =(IF('Water Report'!$K$13>0,'Water Report'!$K$13,0)) -> 30 | AS9: =(IF('Water Report'!$K$14>0,'Water Report'!$K$14,0)) -> 12 | AT9: =(IF('Water Report'!$K$15>0,'Water Report'!$K$15,0)) -> 8 | AU9: =(IF('Water Report'!$K$17>0,'Water Report'!$K$17,0)) -> 0 | AV9: =(IF('Water Report'!$K$18>0,'Water Report'!$K$18,0)) -> 14 | AW9: =(IF('Water Report'!$K$19>0,'Water Report'!$K$19,0)) -> 14 | AX9: =(IF('Water Report'!$K$21>0,'Water Report'!$K$21,0)) -> 50 | AY9: =(IF('Water Report'!$K$22>0,'Water Report'!$K$22,0)) -> 0 | AZ9: =(IF('Water Report'!$K$23>0,'Water Report'!$K$23,0)) -> 11 | BA9: =(IF('Water Report'!$K$14>0,'Water Report'!$K$14,0)) -> 12 | BB9: =(IF('Water Report'!$K$15>0,'Water Report'!$K$15,0)) -> 8 | BC9: =(IF('Water Report'!$K$13>0,'Water Report'!$K$13,0)) -> 30 | BD9: =(IF('Water Report'!$K$24>0,'Water Report'!$K$24,0)) -> 258 | BE9: =(IF('Water Report'!$K$25>0,'Water Report'!$K$25,0)) -> 172 | BF9: =(IF('Water Report'!$K$27>0,'Water Report'!$K$27,0)) -> 91 | BG9: =(IF('Section Load'!AN12>0,'Section Load'!AN12,0)) -> 1009.75 | BH9: =(IF('Section Load'!AO12>0,'Section Load'!AO12,0)) -> 287.15 | BI9: =(IF('Section Load'!AP12>0,'Section Load'!AP12,0)) -> 0 | BJ9: =(IF('Section Load'!AQ12>0,'Section Load'!AQ12,0)) -> 92.42 | BK9: =(IF('Section Load'!AR12>0,'Section Load'!AR12,0)) -> 41 | BL9: =(IF('Section Load'!AS12>0,'Section Load'!AS12,0)) -> 1.4 | BM9: =(IF('Section Load'!AT12>0,'Section Load'!AT12,0)) -> 587.78
A10: Mumbai | B10: =B9+1 -> 9 | C10: 11 | D10: 2021 | E10: =(IF('Section Load'!F13>0,'Section Load'!F13,0)) -> 3457.04 | F10: =(IF('Section Load'!G13>0,'Section Load'!G13,0)) -> 1570.33 | G10: =(IF('Section Load'!H13>0,'Section Load'!H13,0)) -> 1768.62 | H10: =(IF('Section Load'!I13>0,'Section Load'!I13,0)) -> 2928.33 | I10: =(IF('Section Load'!J13>0,'Section Load'!J13,0)) -> 5158.53 | J10: =(IF('Section Load'!K13>0,'Section Load'!K13,0)) -> 2590.9 | K10: =(IF('Section Load'!L13>0,'Section Load'!L13,0)) -> 1069.61 | L10: =(IF('Section Load'!M13>0,'Section Load'!M13,0)) -> 999.83 | ... AL10: =(IF('Section Load'!AM13>0,'Section Load'!AM13,0)) -> 557.66 | AM10: =(IF('Water Report'!$L$7>0,'Water Report'!$L$7,0)) -> 112 | AN10: =(IF('Water Report'!$L$8>0,'Water Report'!$L$8,0)) -> 75 | AO10: =(IF('Water Report'!$L$9>0,'Water Report'!$L$9,0)) -> 106 | AP10: =(IF('Water Report'!$L$10>0,'Water Report'!$L$10,0)) -> 25 | AQ10: =(IF('Water Report'!$L$11>0,'Water Report'!$L$11,0)) -> 23 | AR10: =(IF('Water Report'!$L$13>0,'Water Report'!$L$13,0)) -> 22 | AS10: =(IF('Water Report'!$L$14>0,'Water Report'!$L$14,0)) -> 8 | AT10: =(IF('Water Report'!$L$15>0,'Water Report'!$L$15,0)) -> 9 | AU10: =(IF('Water Report'!$L$17>0,'Water Report'!$L$17,0)) -> 0 | AV10: =(IF('Water Report'!$L$18>0,'Water Report'!$L$18,0)) -> 21 | AW10: =(IF('Water Report'!$L$19>0,'Water Report'!$L$19,0)) -> 14 | AX10: =(IF('Water Report'!$L$21>0,'Water Report'!$L$21,0)) -> 62 | AY10: =(IF('Water Report'!$L$22>0,'Water Report'!$L$22,0)) -> 0 | AZ10: =(IF('Water Report'!$L$23>0,'Water Report'!$L$23,0)) -> 1 | BA10: =(IF('Water Report'!$L$14>0,'Water Report'!$L$14,0)) -> 8 | BB10: =(IF('Water Report'!$L$15>0,'Water Report'!$L$15,0)) -> 9 | BC10: =(IF('Water Report'!$L$13>0,'Water Report'!$L$13,0)) -> 22 | BD10: =(IF('Water Report'!$L$24>0,'Water Report'!$L$24,0)) -> 253 | BE10: =(IF('Water Report'!$L$25>0,'Water Report'!$L$25,0)) -> 171 | BF10: =(IF('Water Report'!$L$27>0,'Water Report'!$L$27,0)) -> 85 | BG10: =(IF('Section Load'!AN13>0,'Section Load'!AN13,0)) -> 1028.08 | BH10: =(IF('Section Load'!AO13>0,'Section Load'!AO13,0)) -> 261.56 | BI10: =(IF('Section Load'!AP13>0,'Section Load'!AP13,0)) -> 0 | BJ10: =(IF('Section Load'!AQ13>0,'Section Load'!AQ13,0)) -> 94.6 | BK10: =(IF('Section Load'!AR13>0,'Section Load'!AR13,0)) -> 34 | BL10: =(IF('Section Load'!AS13>0,'Section Load'!AS13,0)) -> 2.3 | BM10: =(IF('Section Load'!AT13>0,'Section Load'!AT13,0)) -> 635.62
A11: Mumbai | B11: =B10+1 -> 10 | C11: 11 | D11: 2021 | E11: =(IF('Section Load'!F14>0,'Section Load'!F14,0)) -> 3227 | F11: =(IF('Section Load'!G14>0,'Section Load'!G14,0)) -> 1588 | G11: =(IF('Section Load'!H14>0,'Section Load'!H14,0)) -> 1767 | H11: =(IF('Section Load'!I14>0,'Section Load'!I14,0)) -> 2884 | I11: =(IF('Section Load'!J14>0,'Section Load'!J14,0)) -> 4843 | J11: =(IF('Section Load'!K14>0,'Section Load'!K14,0)) -> 2516 | K11: =(IF('Section Load'!L14>0,'Section Load'!L14,0)) -> 1089 | L11: =(IF('Section Load'!M14>0,'Section Load'!M14,0)) -> 882 | ... AL11: =(IF('Section Load'!AM14>0,'Section Load'!AM14,0)) -> 492 | AM11: =(IF('Water Report'!$M$7>0,'Water Report'!$M$7,0)) -> 100 | AN11: =(IF('Water Report'!$M$8>0,'Water Report'!$M$8,0)) -> 96 | AO11: =(IF('Water Report'!$M$9>0,'Water Report'!$M$9,0)) -> 95 | AP11: =(IF('Water Report'!$M$10>0,'Water Report'!$M$10,0)) -> 20 | AQ11: =(IF('Water Report'!$M$11>0,'Water Report'!$M$11,0)) -> 23 | AR11: =(IF('Water Report'!$M$13>0,'Water Report'!$M$13,0)) -> 36 | AS11: =(IF('Water Report'!$M$14>0,'Water Report'!$M$14,0)) -> 11 | AT11: =(IF('Water Report'!$M$15>0,'Water Report'!$M$15,0)) -> 12 | AU11: =(IF('Water Report'!$M$17>0,'Water Report'!$M$17,0)) -> 0 | AV11: =(IF('Water Report'!$M$18>0,'Water Report'!$M$18,0)) -> 11 | AW11: =(IF('Water Report'!$M$19>0,'Water Report'!$M$19,0)) -> 10 | AX11: =(IF('Water Report'!$M$21>0,'Water Report'!$M$21,0)) -> 78 | AY11: =(IF('Water Report'!$M$22>0,'Water Report'!$M$22,0)) -> 0 | AZ11: =(IF('Water Report'!$M$23>0,'Water Report'!$M$23,0)) -> 14 | BA11: =(IF('Water Report'!$M$14>0,'Water Report'!$M$14,0)) -> 11 | BB11: =(IF('Water Report'!$M$15>0,'Water Report'!$M$15,0)) -> 12 | BC11: =(IF('Water Report'!$M$13>0,'Water Report'!$M$13,0)) -> 36 | BD11: =(IF('Water Report'!$M$24>0,'Water Report'!$M$24,0)) -> 225 | BE11: =(IF('Water Report'!$M$25>0,'Water Report'!$M$25,0)) -> 161 | BF11: =(IF('Water Report'!$M$27>0,'Water Report'!$M$27,0)) -> 128 | BG11: =(IF('Section Load'!AN14>0,'Section Load'!AN14,0)) -> 1016 | BH11: =(IF('Section Load'!AO14>0,'Section Load'!AO14,0)) -> 299 | BI11: =(IF('Section Load'!AP14>0,'Section Load'!AP14,0)) -> 0 | BJ11: =(IF('Section Load'!AQ14>0,'Section Load'!AQ14,0)) -> 113 | BK11: =(IF('Section Load'!AR14>0,'Section Load'!AR14,0)) -> 35 | BL11: =(IF('Section Load'!AS14>0,'Section Load'!AS14,0)) -> 1 | BM11: =(IF('Section Load'!AT14>0,'Section Load'!AT14,0)) -> 568
A12: Mumbai | B12: =B11+1 -> 11 | C12: 11 | D12: 2021 | E12: =(IF('Section Load'!F15>0,'Section Load'!F15,0)) -> 3327 | F12: =(IF('Section Load'!G15>0,'Section Load'!G15,0)) -> 1567 | G12: =(IF('Section Load'!H15>0,'Section Load'!H15,0)) -> 1740 | H12: =(IF('Section Load'!I15>0,'Section Load'!I15,0)) -> 2887 | I12: =(IF('Section Load'!J15>0,'Section Load'!J15,0)) -> 4864 | J12: =(IF('Section Load'!K15>0,'Section Load'!K15,0)) -> 2425 | K12: =(IF('Section Load'!L15>0,'Section Load'!L15,0)) -> 1114 | L12: =(IF('Section Load'!M15>0,'Section Load'!M15,0)) -> 874 | ... AL12: =(IF('Section Load'!AM15>0,'Section Load'!AM15,0)) -> 490 | AM12: =(IF('Water Report'!$N$7>0,'Water Report'!$N$7,0)) -> 103 | AN12: =(IF('Water Report'!$N$8>0,'Water Report'!$N$8,0)) -> 93 | AO12: =(IF('Water Report'!$N$9>0,'Water Report'!$N$9,0)) -> 95 | AP12: =(IF('Water Report'!$N$10>0,'Water Report'!$N$10,0)) -> 17 | AQ12: =(IF('Water Report'!$N$11>0,'Water Report'!$N$11,0)) -> 24 | AR12: =(IF('Water Report'!$N$13>0,'Water Report'!$N$13,0)) -> 38 | AS12: =(IF('Water Report'!$N$14>0,'Water Report'!$N$14,0)) -> 9 | AT12: =(IF('Water Report'!$N$15>0,'Water Report'!$N$15,0)) -> 11 | AU12: =(IF('Water Report'!$N$17>0,'Water Report'!$N$17,0)) -> 0 | AV12: =(IF('Water Report'!$N$18>0,'Water Report'!$N$18,0)) -> 13 | AW12: =(IF('Water Report'!$N$19>0,'Water Report'!$N$19,0)) -> 14 | AX12: =(IF('Water Report'!$N$21>0,'Water Report'!$N$21,0)) -> 63 | AY12: =(IF('Water Report'!$N$22>0,'Water Report'!$N$22,0)) -> 0 | AZ12: =(IF('Water Report'!$N$23>0,'Water Report'!$N$23,0)) -> 10 | BA12: =(IF('Water Report'!$N$14>0,'Water Report'!$N$14,0)) -> 9 | BB12: =(IF('Water Report'!$N$15>0,'Water Report'!$N$15,0)) -> 11 | BC12: =(IF('Water Report'!$N$13>0,'Water Report'!$N$13,0)) -> 38 | BD12: =(IF('Water Report'!$N$24>0,'Water Report'!$N$24,0)) -> 233 | BE12: =(IF('Water Report'!$N$25>0,'Water Report'!$N$25,0)) -> 156 | BF12: =(IF('Water Report'!$N$27>0,'Water Report'!$N$27,0)) -> 111 | BG12: =(IF('Section Load'!AN15>0,'Section Load'!AN15,0)) -> 1046 | BH12: =(IF('Section Load'!AO15>0,'Section Load'!AO15,0)) -> 293 | BI12: =(IF('Section Load'!AP15>0,'Section Load'!AP15,0)) -> 0 | BJ12: =(IF('Section Load'!AQ15>0,'Section Load'!AQ15,0)) -> 118 | BK12: =(IF('Section Load'!AR15>0,'Section Load'!AR15,0)) -> 39 | BL12: =(IF('Section Load'!AS15>0,'Section Load'!AS15,0)) -> 2 | BM12: =(IF('Section Load'!AT15>0,'Section Load'!AT15,0)) -> 594
A13: Mumbai | B13: =B12+1 -> 12 | C13: 11 | D13: 2021 | E13: =(IF('Section Load'!F16>0,'Section Load'!F16,0)) -> 3413 | F13: =(IF('Section Load'!G16>0,'Section Load'!G16,0)) -> 1617 | G13: =(IF('Section Load'!H16>0,'Section Load'!H16,0)) -> 1852 | H13: =(IF('Section Load'!I16>0,'Section Load'!I16,0)) -> 2962 | I13: =(IF('Section Load'!J16>0,'Section Load'!J16,0)) -> 5360.29 | J13: =(IF('Section Load'!K16>0,'Section Load'!K16,0)) -> 2719 | K13: =(IF('Section Load'!L16>0,'Section Load'!L16,0)) -> 1311 | L13: =(IF('Section Load'!M16>0,'Section Load'!M16,0)) -> 986 | ... AL13: =(IF('Section Load'!AM16>0,'Section Load'!AM16,0)) -> 576 | AM13: =(IF('Water Report'!$O$7>0,'Water Report'!$O$7,0)) -> 120 | AN13: =(IF('Water Report'!$O$8>0,'Water Report'!$O$8,0)) -> 90 | AO13: =(IF('Water Report'!$O$9>0,'Water Report'!$O$9,0)) -> 112 | AP13: =(IF('Water Report'!$O$10>0,'Water Report'!$O$10,0)) -> 21 | AQ13: =(IF('Water Report'!$O$11>0,'Water Report'!$O$11,0)) -> 29 | AR13: =(IF('Water Report'!$O$13>0,'Water Report'!$O$13,0)) -> 47 | AS13: =(IF('Water Report'!$O$14>0,'Water Report'!$O$14,0)) -> 12 | AT13: =(IF('Water Report'!$O$15>0,'Water Report'!$O$15,0)) -> 18 | AU13: =(IF('Water Report'!$O$17>0,'Water Report'!$O$17,0)) -> 0 | AV13: =(IF('Water Report'!$O$18>0,'Water Report'!$O$18,0)) -> 13 | AW13: =(IF('Water Report'!$O$19>0,'Water Report'!$O$19,0)) -> 16 | AX13: =(IF('Water Report'!$O$21>0,'Water Report'!$O$21,0)) -> 84 | AY13: =(IF('Water Report'!$O$22>0,'Water Report'!$O$22,0)) -> 0 | AZ13: =(IF('Water Report'!$O$23>0,'Water Report'!$O$23,0)) -> 0 | BA13: =(IF('Water Report'!$O$14>0,'Water Report'!$O$14,0)) -> 12 | BB13: =(IF('Water Report'!$O$15>0,'Water Report'!$O$15,0)) -> 18 | BC13: =(IF('Water Report'!$O$13>0,'Water Report'!$O$13,0)) -> 47 | BD13: =(IF('Water Report'!$O$24>0,'Water Report'!$O$24,0)) -> 278 | BE13: =(IF('Water Report'!$O$25>0,'Water Report'!$O$25,0)) -> 192 | BF13: =(IF('Water Report'!$O$27>0,'Water Report'!$O$27,0)) -> 131 | BG13: =(IF('Section Load'!AN16>0,'Section Load'!AN16,0)) -> 1060 | BH13: =(IF('Section Load'!AO16>0,'Section Load'!AO16,0)) -> 305 | BI13: =(IF('Section Load'!AP16>0,'Section Load'!AP16,0)) -> 0 | BJ13: =(IF('Section Load'!AQ16>0,'Section Load'!AQ16,0)) -> 120 | BK13: =(IF('Section Load'!AR16>0,'Section Load'!AR16,0)) -> 50 | BL13: =(IF('Section Load'!AS16>0,'Section Load'!AS16,0)) -> 4 | BM13: =(IF('Section Load'!AT16>0,'Section Load'!AT16,0)) -> 581
A14: Mumbai | B14: =B13+1 -> 13 | C14: 11 | D14: 2021 | E14: =(IF('Section Load'!F17>0,'Section Load'!F17,0)) -> 3825 | F14: =(IF('Section Load'!G17>0,'Section Load'!G17,0)) -> 1651 | G14: =(IF('Section Load'!H17>0,'Section Load'!H17,0)) -> 1898 | H14: =(IF('Section Load'!I17>0,'Section Load'!I17,0)) -> 3040 | I14: =(IF('Section Load'!J17>0,'Section Load'!J17,0)) -> 6131 | J14: =(IF('Section Load'!K17>0,'Section Load'!K17,0)) -> 2775 | K14: =(IF('Section Load'!L17>0,'Section Load'!L17,0)) -> 1833 | L14: =(IF('Section Load'!M17>0,'Section Load'!M17,0)) -> 1288 | ... AL14: =(IF('Section Load'!AM17>0,'Section Load'!AM17,0)) -> 783 | AM14: =(IF('Water Report'!$P$7>0,'Water Report'!$P$7,0)) -> 131 | AN14: =(IF('Water Report'!$P$8>0,'Water Report'!$P$8,0)) -> 107 | AO14: =(IF('Water Report'!$P$9>0,'Water Report'!$P$9,0)) -> 110 | AP14: =(IF('Water Report'!$P$10>0,'Water Report'!$P$10,0)) -> 20 | AQ14: =(IF('Water Report'!$P$11>0,'Water Report'!$P$11,0)) -> 33 | AR14: =(IF('Water Report'!$P$13>0,'Water Report'!$P$13,0)) -> 41 | AS14: =(IF('Water Report'!$P$14>0,'Water Report'!$P$14,0)) -> 19 | AT14: =(IF('Water Report'!$P$15>0,'Water Report'!$P$15,0)) -> 10 | AU14: =(IF('Water Report'!$P$17>0,'Water Report'!$P$17,0)) -> 0 | AV14: =(IF('Water Report'!$P$18>0,'Water Report'!$P$18,0)) -> 18 | AW14: =(IF('Water Report'!$P$19>0,'Water Report'!$P$19,0)) -> 17 | AX14: =(IF('Water Report'!$P$21>0,'Water Report'!$P$21,0)) -> 63 | AY14: =(IF('Water Report'!$P$22>0,'Water Report'!$P$22,0)) -> 0 | AZ14: =(IF('Water Report'!$P$23>0,'Water Report'!$P$23,0)) -> 24 | BA14: =(IF('Water Report'!$P$14>0,'Water Report'!$P$14,0)) -> 19 | BB14: =(IF('Water Report'!$P$15>0,'Water Report'!$P$15,0)) -> 10 | BC14: =(IF('Water Report'!$P$13>0,'Water Report'!$P$13,0)) -> 41 | BD14: =(IF('Water Report'!$P$24>0,'Water Report'!$P$24,0)) -> 256 | BE14: =(IF('Water Report'!$P$25>0,'Water Report'!$P$25,0)) -> 192 | BF14: =(IF('Water Report'!$P$27>0,'Water Report'!$P$27,0)) -> 128 | BG14: =(IF('Section Load'!AN17>0,'Section Load'!AN17,0)) -> 1071 | BH14: =(IF('Section Load'!AO17>0,'Section Load'!AO17,0)) -> 303 | BI14: =(IF('Section Load'!AP17>0,'Section Load'!AP17,0)) -> 0 | BJ14: =(IF('Section Load'!AQ17>0,'Section Load'!AQ17,0)) -> 119 | BK14: =(IF('Section Load'!AR17>0,'Section Load'!AR17,0)) -> 45 | BL14: =(IF('Section Load'!AS17>0,'Section Load'!AS17,0)) -> 3 | BM14: =(IF('Section Load'!AT17>0,'Section Load'!AT17,0)) -> 601
A15: Mumbai | B15: =B14+1 -> 14 | C15: 11 | D15: 2021 | E15: =(IF('Section Load'!F18>0,'Section Load'!F18,0)) -> 3440 | F15: =(IF('Section Load'!G18>0,'Section Load'!G18,0)) -> 1518 | G15: =(IF('Section Load'!H18>0,'Section Load'!H18,0)) -> 1821 | H15: =(IF('Section Load'!I18>0,'Section Load'!I18,0)) -> 2824 | I15: =(IF('Section Load'!J18>0,'Section Load'!J18,0)) -> 6179 | J15: =(IF('Section Load'!K18>0,'Section Load'!K18,0)) -> 2571 | K15: =(IF('Section Load'!L18>0,'Section Load'!L18,0)) -> 1194 | L15: =(IF('Section Load'!M18>0,'Section Load'!M18,0)) -> 875 | ... AL15: =(IF('Section Load'!AM18>0,'Section Load'!AM18,0)) -> 769 | AM15: =(IF('Water Report'!$Q$7>0,'Water Report'!$Q$7,0)) -> 141 | AN15: =(IF('Water Report'!$Q$8>0,'Water Report'!$Q$8,0)) -> 117 | AO15: =(IF('Water Report'!$Q$9>0,'Water Report'!$Q$9,0)) -> 101 | AP15: =(IF('Water Report'!$Q$10>0,'Water Report'!$Q$10,0)) -> 26 | AQ15: =(IF('Water Report'!$Q$11>0,'Water Report'!$Q$11,0)) -> 24 | AR15: =(IF('Water Report'!$Q$13>0,'Water Report'!$Q$13,0)) -> 23 | AS15: =(IF('Water Report'!$Q$14>0,'Water Report'!$Q$14,0)) -> 10 | AT15: =(IF('Water Report'!$Q$15>0,'Water Report'!$Q$15,0)) -> 9 | AU15: =(IF('Water Report'!$Q$17>0,'Water Report'!$Q$17,0)) -> 0 | AV15: =(IF('Water Report'!$Q$18>0,'Water Report'!$Q$18,0)) -> 13 | AW15: =(IF('Water Report'!$Q$19>0,'Water Report'!$Q$19,0)) -> 11 | AX15: =(IF('Water Report'!$Q$21>0,'Water Report'!$Q$21,0)) -> 111 | AY15: =(IF('Water Report'!$Q$22>0,'Water Report'!$Q$22,0)) -> 0 | AZ15: =(IF('Water Report'!$Q$23>0,'Water Report'!$Q$23,0)) -> 4 | BA15: =(IF('Water Report'!$Q$14>0,'Water Report'!$Q$14,0)) -> 10 | BB15: =(IF('Water Report'!$Q$15>0,'Water Report'!$Q$15,0)) -> 9 | BC15: =(IF('Water Report'!$Q$13>0,'Water Report'!$Q$13,0)) -> 23 | BD15: =(IF('Water Report'!$Q$24>0,'Water Report'!$Q$24,0)) -> 293 | BE15: =(IF('Water Report'!$Q$25>0,'Water Report'!$Q$25,0)) -> 170 | BF15: =(IF('Water Report'!$Q$27>0,'Water Report'!$Q$27,0)) -> 138 | BG15: =(IF('Section Load'!AN18>0,'Section Load'!AN18,0)) -> 1139.97 | BH15: =(IF('Section Load'!AO18>0,'Section Load'!AO18,0)) -> 280 | BI15: =(IF('Section Load'!AP18>0,'Section Load'!AP18,0)) -> 0 | BJ15: =(IF('Section Load'!AQ18>0,'Section Load'!AQ18,0)) -> 128 | BK15: =(IF('Section Load'!AR18>0,'Section Load'!AR18,0)) -> 41 | BL15: =(IF('Section Load'!AS18>0,'Section Load'!AS18,0)) -> 1 | BM15: =(IF('Section Load'!AT18>0,'Section Load'!AT18,0)) -> 689.97
A16: Mumbai | B16: =B15+1 -> 15 | C16: 11 | D16: 2021 | E16: =(IF('Section Load'!F19>0,'Section Load'!F19,0)) -> 3603.7 | F16: =(IF('Section Load'!G19>0,'Section Load'!G19,0)) -> 1554.88 | G16: =(IF('Section Load'!H19>0,'Section Load'!H19,0)) -> 1735.56 | H16: =(IF('Section Load'!I19>0,'Section Load'!I19,0)) -> 2954.21 | I16: =(IF('Section Load'!J19>0,'Section Load'!J19,0)) -> 7030.51 | J16: =(IF('Section Load'!K19>0,'Section Load'!K19,0)) -> 2788.5 | K16: =(IF('Section Load'!L19>0,'Section Load'!L19,0)) -> 1115.47 | L16: =(IF('Section Load'!M19>0,'Section Load'!M19,0)) -> 840.7 | ... AL16: =(IF('Section Load'!AM19>0,'Section Load'!AM19,0)) -> 740.98 | AM16: =(IF('Water Report'!$R$7>0,'Water Report'!$R$7,0)) -> 107 | AN16: =(IF('Water Report'!$R$8>0,'Water Report'!$R$8,0)) -> 95 | AO16: =(IF('Water Report'!$R$9>0,'Water Report'!$R$9,0)) -> 116 | AP16: =(IF('Water Report'!$R$10>0,'Water Report'!$R$10,0)) -> 21 | AQ16: =(IF('Water Report'!$R$11>0,'Water Report'!$R$11,0)) -> 20 | AR16: =(IF('Water Report'!$R$13>0,'Water Report'!$R$13,0)) -> 28 | AS16: =(IF('Water Report'!$R$14>0,'Water Report'!$R$14,0)) -> 9 | AT16: =(IF('Water Report'!$R$15>0,'Water Report'!$R$15,0)) -> 8 | AU16: =(IF('Water Report'!$R$17>0,'Water Report'!$R$17,0)) -> 0 | AV16: =(IF('Water Report'!$R$18>0,'Water Report'!$R$18,0)) -> 14 | AW16: =(IF('Water Report'!$R$19>0,'Water Report'!$R$19,0)) -> 11 | AX16: =(IF('Water Report'!$R$21>0,'Water Report'!$R$21,0)) -> 77 | AY16: =(IF('Water Report'!$R$22>0,'Water Report'!$R$22,0)) -> 0 | AZ16: =(IF('Water Report'!$R$23>0,'Water Report'!$R$23,0)) -> 9 | BA16: =(IF('Water Report'!$R$14>0,'Water Report'!$R$14,0)) -> 9 | BB16: =(IF('Water Report'!$R$15>0,'Water Report'!$R$15,0)) -> 8 | BC16: =(IF('Water Report'!$R$13>0,'Water Report'!$R$13,0)) -> 28 | BD16: =(IF('Water Report'!$R$24>0,'Water Report'!$R$24,0)) -> 236 | BE16: =(IF('Water Report'!$R$25>0,'Water Report'!$R$25,0)) -> 174 | BF16: =(IF('Water Report'!$R$27>0,'Water Report'!$R$27,0)) -> 114 | BG16: =(IF('Section Load'!AN19>0,'Section Load'!AN19,0)) -> 911.2 | BH16: =(IF('Section Load'!AO19>0,'Section Load'!AO19,0)) -> 252.49 | BI16: =(IF('Section Load'!AP19>0,'Section Load'!AP19,0)) -> 0 | BJ16: =(IF('Section Load'!AQ19>0,'Section Load'!AQ19,0)) -> 110.8 | BK16: =(IF('Section Load'!AR19>0,'Section Load'!AR19,0)) -> 46 | BL16: =(IF('Section Load'!AS19>0,'Section Load'!AS19,0)) -> 1.8 | BM16: =(IF('Section Load'!AT19>0,'Section Load'!AT19,0)) -> 500.11
A17: Mumbai | B17: =B16+1 -> 16 | C17: 11 | D17: 2021 | E17: =(IF('Section Load'!F20>0,'Section Load'!F20,0)) -> 3624.86 | F17: =(IF('Section Load'!G20>0,'Section Load'!G20,0)) -> 1596.44 | G17: =(IF('Section Load'!H20>0,'Section Load'!H20,0)) -> 1865.83 | H17: =(IF('Section Load'!I20>0,'Section Load'!I20,0)) -> 2997.28 | I17: =(IF('Section Load'!J20>0,'Section Load'!J20,0)) -> 7804 | J17: =(IF('Section Load'!K20>0,'Section Load'!K20,0)) -> 2788.9 | K17: =(IF('Section Load'!L20>0,'Section Load'!L20,0)) -> 1347.92 | L17: =(IF('Section Load'!M20>0,'Section Load'!M20,0)) -> 905.24 | ... AL17: =(IF('Section Load'!AM20>0,'Section Load'!AM20,0)) -> 645.72 | AM17: =(IF('Water Report'!$S$7>0,'Water Report'!$S$7,0)) -> 119 | AN17: =(IF('Water Report'!$S$8>0,'Water Report'!$S$8,0)) -> 117 | AO17: =(IF('Water Report'!$S$9>0,'Water Report'!$S$9,0)) -> 102 | AP17: =(IF('Water Report'!$S$10>0,'Water Report'!$D$10,0)) -> 23 | AQ17: =(IF('Water Report'!$S$11>0,'Water Report'!$D$11,0)) -> 30 | AR17: =(IF('Water Report'!$S$13>0,'Water Report'!$D$13,0)) -> 41 | AS17: =(IF('Water Report'!$S$14>0,'Water Report'!$D$14,0)) -> 9 | AT17: =(IF('Water Report'!$S$15>0,'Water Report'!$D$15,0)) -> 7 | AU17: =(IF('Water Report'!$S$17>0,'Water Report'!$D$17,0)) -> 0 | AV17: =(IF('Water Report'!$S$18>0,'Water Report'!$D$18,0)) -> 16 | AW17: =(IF('Water Report'!$S$19>0,'Water Report'!$D$19,0)) -> 11 | AX17: =(IF('Water Report'!$S$21>0,'Water Report'!$D$21,0)) -> 68 | AY17: =(IF('Water Report'!$S$22>0,'Water Report'!$D$22,0)) -> 0 | AZ17: =(IF('Water Report'!$S$23>0,'Water Report'!$D$23,0)) -> 0 | BA17: =(IF('Water Report'!$S$14>0,'Water Report'!$D$14,0)) -> 9 | BB17: =(IF('Water Report'!$S$15>0,'Water Report'!$D$15,0)) -> 7 | BC17: =(IF('Water Report'!$S$13>0,'Water Report'!$D$13,0)) -> 41 | BD17: =(IF('Water Report'!$S$24>0,'Water Report'!$D$24,0)) -> 237 | BE17: =(IF('Water Report'!$S$25>0,'Water Report'!$D$25,0)) -> 166 | BF17: =(IF('Water Report'!$S$27>0,'Water Report'!$D$27,0)) -> 109 | BG17: =(IF('Section Load'!AN20>0,'Section Load'!AN20,0)) -> 794.9 | BH17: =(IF('Section Load'!AO20>0,'Section Load'!AO20,0)) -> 283.48 | BI17: =(IF('Section Load'!AP20>0,'Section Load'!AP20,0)) -> 0 | BJ17: =(IF('Section Load'!AQ20>0,'Section Load'!AQ20,0)) -> 123.5 | BK17: =(IF('Section Load'!AR20>0,'Section Load'!AR20,0)) -> 37 | BL17: =(IF('Section Load'!AS20>0,'Section Load'!AS20,0)) -> 0.6 | BM17: =(IF('Section Load'!AT20>0,'Section Load'!AT20,0)) -> 350.32
A18: Mumbai | B18: =B17+1 -> 17 | C18: 11 | D18: 2021 | E18: =(IF('Section Load'!F21>0,'Section Load'!F21,0)) -> 3829.88 | F18: =(IF('Section Load'!G21>0,'Section Load'!G21,0)) -> 1696.08 | G18: =(IF('Section Load'!H21>0,'Section Load'!H21,0)) -> 1917.7 | H18: =(IF('Section Load'!I21>0,'Section Load'!I21,0)) -> 2980.36 | I18: =(IF('Section Load'!J21>0,'Section Load'!J21,0)) -> 8791.76 | J18: =(IF('Section Load'!K21>0,'Section Load'!K21,0)) -> 3015.6 | K18: =(IF('Section Load'!L21>0,'Section Load'!L21,0)) -> 1503.28 | L18: =(IF('Section Load'!M21>0,'Section Load'!M21,0)) -> 1258.36 | ... AL18: =(IF('Section Load'!AM21>0,'Section Load'!AM21,0)) -> 804.85 | AM18: =(IF('Water Report'!$T$7>0,'Water Report'!$T$7,0)) -> 120 | AN18: =(IF('Water Report'!$T$8>0,'Water Report'!$T$8,0)) -> 78 | AO18: =(IF('Water Report'!$T$9>0,'Water Report'!$T$9,0)) -> 109 | AP18: =(IF('Water Report'!$T$10>0,'Water Report'!$T$10,0)) -> 23 | AQ18: =(IF('Water Report'!$T$11>0,'Water Report'!$T$11,0)) -> 35 | AR18: =(IF('Water Report'!$T$13>0,'Water Report'!$T$13,0)) -> 30 | AS18: =(IF('Water Report'!$T$14>0,'Water Report'!$T$14,0)) -> 4 | AT18: =(IF('Water Report'!$T$15>0,'Water Report'!$T$15,0)) -> 7 | AU18: =(IF('Water Report'!$T$17>0,'Water Report'!$T$17,0)) -> 0 | AV18: =(IF('Water Report'!$T$18>0,'Water Report'!$T$18,0)) -> 30 | AW18: =(IF('Water Report'!$T$19>0,'Water Report'!$T$19,0)) -> 11 | AX18: =(IF('Water Report'!$T$21>0,'Water Report'!$T$21,0)) -> 136 | AY18: =(IF('Water Report'!$T$22>0,'Water Report'!$T$22,0)) -> 0 | AZ18: =(IF('Water Report'!$T$23>0,'Water Report'!$T$23,0)) -> 0 | BA18: =(IF('Water Report'!$T$14>0,'Water Report'!$T$14,0)) -> 4 | BB18: =(IF('Water Report'!$T$15>0,'Water Report'!$T$15,0)) -> 7 | BC18: =(IF('Water Report'!$T$13>0,'Water Report'!$T$13,0)) -> 30 | BD18: =(IF('Water Report'!$T$24>0,'Water Report'!$T$24,0)) -> 255 | BE18: =(IF('Water Report'!$T$25>0,'Water Report'!$T$25,0)) -> 178 | BF18: =(IF('Water Report'!$T$27>0,'Water Report'!$T$27,0)) -> 166 | BG18: =(IF('Section Load'!AN21>0,'Section Load'!AN21,0)) -> 824.4 | BH18: =(IF('Section Load'!AO21>0,'Section Load'!AO21,0)) -> 281.27 | BI18: =(IF('Section Load'!AP21>0,'Section Load'!AP21,0)) -> 0 | BJ18: =(IF('Section Load'!AQ21>0,'Section Load'!AQ21,0)) -> 131.6 | BK18: =(IF('Section Load'!AR21>0,'Section Load'!AR21,0)) -> 41.6 | BL18: =(IF('Section Load'!AS21>0,'Section Load'!AS21,0)) -> 2.3 | BM18: =(IF('Section Load'!AT21>0,'Section Load'!AT21,0)) -> 367.63
A19: Mumbai | B19: =B18+1 -> 18 | C19: 11 | D19: 2021 | E19: =(IF('Section Load'!F22>0,'Section Load'!F22,0)) -> 1697.28 | F19: =(IF('Section Load'!G22>0,'Section Load'!G22,0)) -> 1804.68 | G19: =(IF('Section Load'!H22>0,'Section Load'!H22,0)) -> 1865.97 | H19: =(IF('Section Load'!I22>0,'Section Load'!I22,0)) -> 2891.16 | I19: =(IF('Section Load'!J22>0,'Section Load'!J22,0)) -> 8645.31 | J19: =(IF('Section Load'!K22>0,'Section Load'!K22,0)) -> 2870.4 | K19: =(IF('Section Load'!L22>0,'Section Load'!L22,0)) -> 1613.28 | L19: =(IF('Section Load'!M22>0,'Section Load'!M22,0)) -> 1112.44 | ... AL19: =(IF('Section Load'!AM22>0,'Section Load'!AM22,0)) -> 778.93 | AM19: =(IF('Water Report'!$U$7>0,'Water Report'!$U$7,0)) -> 146 | AN19: =(IF('Water Report'!$U$8>0,'Water Report'!$U$8,0)) -> 0 | AO19: =(IF('Water Report'!$U$9>0,'Water Report'!$U$9,0)) -> 106 | AP19: =(IF('Water Report'!$U$10>0,'Water Report'!$U$10,0)) -> 43 | AQ19: =(IF('Water Report'!$U$11>0,'Water Report'!$U$11,0)) -> 25 | AR19: =(IF('Water Report'!$U$13>0,'Water Report'!$U$13,0)) -> 37 | AS19: =(IF('Water Report'!$U$14>0,'Water Report'!$U$14,0)) -> 9 | AT19: =(IF('Water Report'!$U$15>0,'Water Report'!$U$15,0)) -> 11 | AU19: =(IF('Water Report'!$U$17>0,'Water Report'!$U$17,0)) -> 0 | AV19: =(IF('Water Report'!$U$18>0,'Water Report'!$U$18,0)) -> 14 | AW19: =(IF('Water Report'!$U$19>0,'Water Report'!$U$19,0)) -> 11 | AX19: =(IF('Water Report'!$U$21>0,'Water Report'!$U$21,0)) -> 108 | AY19: =(IF('Water Report'!$U$22>0,'Water Report'!$U$22,0)) -> 0 | AZ19: =(IF('Water Report'!$U$23>0,'Water Report'!$U$23,0)) -> 0 | BA19: =(IF('Water Report'!$U$14>0,'Water Report'!$U$14,0)) -> 9 | BB19: =(IF('Water Report'!$U$15>0,'Water Report'!$U$15,0)) -> 11 | BC19: =(IF('Water Report'!$U$13>0,'Water Report'!$U$13,0)) -> 37 | BD19: =(IF('Water Report'!$U$24>0,'Water Report'!$U$24,0)) -> 337 | BE19: =(IF('Water Report'!$U$25>0,'Water Report'!$U$25,0)) -> 194 | BF19: =(IF('Water Report'!$U$27>0,'Water Report'!$U$27,0)) -> 145 | BG19: =(IF('Section Load'!AN22>0,'Section Load'!AN22,0)) -> 783.8 | BH19: =(IF('Section Load'!AO22>0,'Section Load'!AO22,0)) -> 296.51 | BI19: =(IF('Section Load'!AP22>0,'Section Load'!AP22,0)) -> 0 | BJ19: =(IF('Section Load'!AQ22>0,'Section Load'!AQ22,0)) -> 106.2 | BK19: =(IF('Section Load'!AR22>0,'Section Load'!AR22,0)) -> 38.3 | BL19: =(IF('Section Load'!AS22>0,'Section Load'!AS22,0)) -> 2.1 | BM19: =(IF('Section Load'!AT22>0,'Section Load'!AT22,0)) -> 341.09
A20: Mumbai | B20: =B19+1 -> 19 | C20: 11 | D20: 2021 | E20: =(IF('Section Load'!F23>0,'Section Load'!F23,0)) -> 5620.05 | F20: =(IF('Section Load'!G23>0,'Section Load'!G23,0)) -> 1586.63 | G20: =(IF('Section Load'!H23>0,'Section Load'!H23,0)) -> 1808.79 | H20: =(IF('Section Load'!I23>0,'Section Load'!I23,0)) -> 2926.9 | I20: =(IF('Section Load'!J23>0,'Section Load'!J23,0)) -> 7972.46 | J20: =(IF('Section Load'!K23>0,'Section Load'!K23,0)) -> 2801.2 | K20: =(IF('Section Load'!L23>0,'Section Load'!L23,0)) -> 1761.04 | L20: =(IF('Section Load'!M23>0,'Section Load'!M23,0)) -> 807.42 | ... AL20: =(IF('Section Load'!AM23>0,'Section Load'!AM23,0)) -> 793.15 | AM20: =(IF('Water Report'!$V$7>0,'Water Report'!$V$7,0)) -> 122 | AN20: =(IF('Water Report'!$V$8>0,'Water Report'!$V$8,0)) -> 76 | AO20: =(IF('Water Report'!$V$9>0,'Water Report'!$V$9,0)) -> 95 | AP20: =(IF('Water Report'!$V$10>0,'Water Report'!$V$10,0)) -> 23 | AQ20: =(IF('Water Report'!$V$11>0,'Water Report'!$V$11,0)) -> 33 | AR20: =(IF('Water Report'!$V$13>0,'Water Report'!$V$13,0)) -> 22 | AS20: =(IF('Water Report'!$V$14>0,'Water Report'!$V$14,0)) -> 12 | AT20: =(IF('Water Report'!$V$15>0,'Water Report'!$V$15,0)) -> 8 | AU20: =(IF('Water Report'!$V$17>0,'Water Report'!$V$17,0)) -> 0 | AV20: =(IF('Water Report'!$V$18>0,'Water Report'!$V$18,0)) -> 16 | AW20: =(IF('Water Report'!$V$19>0,'Water Report'!$V$19,0)) -> 12 | AX20: =(IF('Water Report'!$V$21>0,'Water Report'!$V$21,0)) -> 84 | AY20: =(IF('Water Report'!$V$22>0,'Water Report'!$V$22,0)) -> 0 | AZ20: =(IF('Water Report'!$V$23>0,'Water Report'!$V$23,0)) -> 0 | BA20: =(IF('Water Report'!$V$14>0,'Water Report'!$V$14,0)) -> 12 | BB20: =(IF('Water Report'!$V$15>0,'Water Report'!$V$15,0)) -> 8 | BC20: =(IF('Water Report'!$V$13>0,'Water Report'!$V$13,0)) -> 22 | BD20: =(IF('Water Report'!$V$24>0,'Water Report'!$V$24,0)) -> 325 | BE20: =(IF('Water Report'!$V$25>0,'Water Report'!$V$25,0)) -> 171 | BF20: =(IF('Water Report'!$V$27>0,'Water Report'!$V$27,0)) -> 106 | BG20: =(IF('Section Load'!AN23>0,'Section Load'!AN23,0)) -> 785.6 | BH20: =(IF('Section Load'!AO23>0,'Section Load'!AO23,0)) -> 286.02 | BI20: =(IF('Section Load'!AP23>0,'Section Load'!AP23,0)) -> 0.4 | BJ20: =(IF('Section Load'!AQ23>0,'Section Load'!AQ23,0)) -> 125.7 | BK20: =(IF('Section Load'!AR23>0,'Section Load'!AR23,0)) -> 39.9 | BL20: =(IF('Section Load'!AS23>0,'Section Load'!AS23,0)) -> 1.6 | BM20: =(IF('Section Load'!AT23>0,'Section Load'!AT23,0)) -> 331.98
A21: Mumbai | B21: =B20+1 -> 20 | C21: 11 | D21: 2021 | E21: =(IF('Section Load'!F24>0,'Section Load'!F24,0)) -> 3684 | F21: =(IF('Section Load'!G24>0,'Section Load'!G24,0)) -> 1650.31 | G21: =(IF('Section Load'!H24>0,'Section Load'!H24,0)) -> 1897.07 | H21: =(IF('Section Load'!I24>0,'Section Load'!I24,0)) -> 2942.6 | I21: =(IF('Section Load'!J24>0,'Section Load'!J24,0)) -> 8670.22 | J21: =(IF('Section Load'!K24>0,'Section Load'!K24,0)) -> 2977.1 | K21: =(IF('Section Load'!L24>0,'Section Load'!L24,0)) -> 1214.96 | L21: =(IF('Section Load'!M24>0,'Section Load'!M24,0)) -> 1243.59 | ... AL21: =(IF('Section Load'!AM24>0,'Section Load'!AM24,0)) -> 854.41 | AM21: =(IF('Water Report'!$W$7>0,'Water Report'!$W$7,0)) -> 120 | AN21: =(IF('Water Report'!$W$8>0,'Water Report'!$W$8,0)) -> 95 | AO21: =(IF('Water Report'!$W$9>0,'Water Report'!$W$9,0)) -> 102 | AP21: =(IF('Water Report'!$W$10>0,'Water Report'!$W$10,0)) -> 15 | AQ21: =(IF('Water Report'!$W$11>0,'Water Report'!$W$11,0)) -> 31 | AR21: =(IF('Water Report'!$W$13>0,'Water Report'!$W$13,0)) -> 20 | AS21: =(IF('Water Report'!$W$14>0,'Water Report'!$W$14,0)) -> 16 | AT21: =(IF('Water Report'!$W$15>0,'Water Report'!$W$15,0)) -> 14 | AU21: =(IF('Water Report'!$W$17>0,'Water Report'!$W$17,0)) -> 0 | AV21: =(IF('Water Report'!$W$18>0,'Water Report'!$W$18,0)) -> 16 | AW21: =(IF('Water Report'!$W$19>0,'Water Report'!$W$19,0)) -> 12 | AX21: =(IF('Water Report'!$W$21>0,'Water Report'!$W$21,0)) -> 85 | AY21: =(IF('Water Report'!$W$22>0,'Water Report'!$W$22,0)) -> 0 | AZ21: =(IF('Water Report'!$W$23>0,'Water Report'!$W$23,0)) -> 15 | BA21: =(IF('Water Report'!$W$14>0,'Water Report'!$W$14,0)) -> 16 | BB21: =(IF('Water Report'!$W$15>0,'Water Report'!$W$15,0)) -> 14 | BC21: =(IF('Water Report'!$W$13>0,'Water Report'!$W$13,0)) -> 20 | BD21: =(IF('Water Report'!$W$24>0,'Water Report'!$W$24,0)) -> 271 | BE21: =(IF('Water Report'!$W$25>0,'Water Report'!$W$25,0)) -> 178 | BF21: =(IF('Water Report'!$W$27>0,'Water Report'!$W$27,0)) -> 120 | BG21: =(IF('Section Load'!AN24>0,'Section Load'!AN24,0)) -> 1135.28 | BH21: =(IF('Section Load'!AO24>0,'Section Load'!AO24,0)) -> 284.37 | BI21: =(IF('Section Load'!AP24>0,'Section Load'!AP24,0)) -> 0 | BJ21: =(IF('Section Load'!AQ24>0,'Section Load'!AQ24,0)) -> 126.82 | BK21: =(IF('Section Load'!AR24>0,'Section Load'!AR24,0)) -> 65.2 | BL21: =(IF('Section Load'!AS24>0,'Section Load'!AS24,0)) -> 5.6 | BM21: =(IF('Section Load'!AT24>0,'Section Load'!AT24,0)) -> 653.29
A22: Mumbai | B22: =B21+1 -> 21 | C22: 11 | D22: 2021 | E22: =(IF('Section Load'!F25>0,'Section Load'!F25,0)) -> 3680.58 | F22: =(IF('Section Load'!G25>0,'Section Load'!G25,0)) -> 1626.58 | G22: =(IF('Section Load'!H25>0,'Section Load'!H25,0)) -> 1956.14 | H22: =(IF('Section Load'!I25>0,'Section Load'!I25,0)) -> 2957.14 | I22: =(IF('Section Load'!J25>0,'Section Load'!J25,0)) -> 8485.46 | J22: =(IF('Section Load'!K25>0,'Section Load'!K25,0)) -> 3011.8 | K22: =(IF('Section Load'!L25>0,'Section Load'!L25,0)) -> 1735.04 | L22: =(IF('Section Load'!M25>0,'Section Load'!M25,0)) -> 1542.09 | ... AL22: =(IF('Section Load'!AM25>0,'Section Load'!AM25,0)) -> 916.51 | AM22: =(IF('Water Report'!$X$7>0,'Water Report'!$X$7,0)) -> 139 | AN22: =(IF('Water Report'!$X$8>0,'Water Report'!$X$8,0)) -> 134 | AO22: =(IF('Water Report'!$X$9>0,'Water Report'!$X$9,0)) -> 109 | AP22: =(IF('Water Report'!$X$10>0,'Water Report'!$X$10,0)) -> 25 | AQ22: =(IF('Water Report'!$X$11>0,'Water Report'!$X$11,0)) -> 42 | AR22: =(IF('Water Report'!$X$13>0,'Water Report'!$X$13,0)) -> 18 | AS22: =(IF('Water Report'!$X$14>0,'Water Report'!$X$14,0)) -> 13 | AT22: =(IF('Water Report'!$X$15>0,'Water Report'!$X$15,0)) -> 21 | AU22: =(IF('Water Report'!$X$17>0,'Water Report'!$X$17,0)) -> 0 | AV22: =(IF('Water Report'!$X$18>0,'Water Report'!$X$18,0)) -> 14 | AW22: =(IF('Water Report'!$X$19>0,'Water Report'!$X$19,0)) -> 9 | AX22: =(IF('Water Report'!$X$21>0,'Water Report'!$X$21,0)) -> 107 | AY22: =(IF('Water Report'!$X$22>0,'Water Report'!$X$22,0)) -> 0 | AZ22: =(IF('Water Report'!$X$23>0,'Water Report'!$X$23,0)) -> 3 | BA22: =(IF('Water Report'!$X$14>0,'Water Report'!$X$14,0)) -> 13 | BB22: =(IF('Water Report'!$X$15>0,'Water Report'!$X$15,0)) -> 21 | BC22: =(IF('Water Report'!$X$13>0,'Water Report'!$X$13,0)) -> 18 | BD22: =(IF('Water Report'!$X$24>0,'Water Report'!$X$24,0)) -> 276 | BE22: =(IF('Water Report'!$X$25>0,'Water Report'!$X$25,0)) -> 210 | BF22: =(IF('Water Report'!$X$27>0,'Water Report'!$X$27,0)) -> 128 | BG22: =(IF('Section Load'!AN25>0,'Section Load'!AN25,0)) -> 1044.04 | BH22: =(IF('Section Load'!AO25>0,'Section Load'!AO25,0)) -> 288.98 | BI22: =(IF('Section Load'!AP25>0,'Section Load'!AP25,0)) -> 0 | BJ22: =(IF('Section Load'!AQ25>0,'Section Load'!AQ25,0)) -> 113.68 | BK22: =(IF('Section Load'!AR25>0,'Section Load'!AR25,0)) -> 48.1 | BL22: =(IF('Section Load'!AS25>0,'Section Load'!AS25,0)) -> 2.6 | BM22: =(IF('Section Load'!AT25>0,'Section Load'!AT25,0)) -> 590.68
