Workbook

Sheet TOTAL
A1: Site Name | B1: Day | C1: Month | D1: Year | E1: Total Electricity Kwh | F1: Electricity Tariff ($/Kwh) | G1: Natual Gas (m3) | H1: Natural Gas $/m3 | I1: Water Utility Supply (m3) m3 | J1: Water Utility Supply (m3) $/m3 | K1: Room Nights | L1: Total Guests | M1: Utilities day cost dh
A2: Mumbai | B2: 1 | C2: 12 | D2: 2021 | E2: =(IF('Daily HLP'!H4>0,'Daily HLP'!H4,0)) -> 22989 | F2: 9 | G2: =(IF('Daily HLP'!L4>0,'Daily HLP'!L4,0)) -> 1074 | H2: 75 | I2: =(IF('Daily HLP'!O4>0,'Daily HLP'!O4,0)) -> 212 | J2: 99 | K2: =Occupancy!G2 -> 171 | L2: =Occupancy!F2 -> 657 | M2: =E2*F2+G2*H2+#REF!*#REF!+I2*J2 -> #REF!
A3: Mumbai | B3: =B2+1 -> 2 | C3: 12 | D3: 2021 | E3: =(IF('Daily HLP'!H5>0,'Daily HLP'!H5,0)) -> 21667 | F3: 9 | G3: =(IF('Daily HLP'!L5>0,'Daily HLP'!L5,0)) -> 1094.24 | H3: 75 | I3: =(IF('Daily HLP'!O5>0,'Daily HLP'!O5,0)) -> 254 | J3: 99 | K3: =Occupancy!G3 -> 169 | L3: =Occupancy!F3 -> 524 | M3: =E3*F3+G3*H3+#REF!*#REF!+I3*J3 -> #REF!
A4: Mumbai | B4: =B3+1 -> 3 | C4: 12 | D4: 2021 | E4: =(IF('Daily HLP'!H6>0,'Daily HLP'!H6,0)) -> 23640.27 | F4: 9 | G4: =(IF('Daily HLP'!L6>0,'Daily HLP'!L6,0)) -> 1144.15 | H4: 75 | I4: =(IF('Daily HLP'!O6>0,'Daily HLP'!O6,0)) -> 285 | J4: 99 | K4: =Occupancy!G4 -> 178 | L4: =Occupancy!F4 -> 986 | M4: =E4*F4+G4*H4+#REF!*#REF!+I4*J4 -> #REF!
A5: Mumbai | B5: =B4+1 -> 4 | C5: 12 | D5: 2021 | E5: =(IF('Daily HLP'!H7>0,'Daily HLP'!H7,0)) -> 25311.64 | F5: 9 | G5: =(IF('Daily HLP'!L7>0,'Daily HLP'!L7,0)) -> 1192.76 | H5: 75 | I5: =(IF('Daily HLP'!O7>0,'Daily HLP'!O7,0)) -> 254 | J5: 99 | K5: =Occupancy!G5 -> 116 | L5: =Occupancy!F5 -> 562 | M5: =E5*F5+G5*H5+#REF!*#REF!+I5*J5 -> #REF!
A6: Mumbai | B6: =B5+1 -> 5 | C6: 12 | D6: 2021 | E6: =(IF('Daily HLP'!H8>0,'Daily HLP'!H8,0)) -> 23337 | F6: 9 | G6: =(IF('Daily HLP'!L8>0,'Daily HLP'!L8,0)) -> 1192.29 | H6: 75 | I6: =(IF('Daily HLP'!O8>0,'Daily HLP'!O8,0)) -> 253 | J6: 99 | K6: =Occupancy!G6 -> 172 | L6: =Occupancy!F6 -> 1366 | M6: =E6*F6+G6*H6+#REF!*#REF!+I6*J6 -> #REF!
A7: Mumbai | B7: =B6+1 -> 6 | C7: 12 | D7: 2021 | E7: =(IF('Daily HLP'!H9>0,'Daily HLP'!H9,0)) -> 22125.12 | F7: 9 | G7: =(IF('Daily HLP'!L9>0,'Daily HLP'!L9,0)) -> 1123.02 | H7: 75 | I7: =(IF('Daily HLP'!O9>0,'Daily HLP'!O9,0)) -> 253 | J7: 99 | K7: =Occupancy!G7 -> 114 | L7: =Occupancy!F7 -> 550 | M7: =E7*F7+G7*H7+#REF!*#REF!+I7*J7 -> #REF!
A8: Mumbai | B8: =B7+1 -> 7 | C8: 12 | D8: 2021 | E8: =(IF('Daily HLP'!H10>0,'Daily HLP'!H10,0)) -> 25247.52 | F8: 9 | G8: =(IF('Daily HLP'!L10>0,'Daily HLP'!L10,0)) -> 1194.97 | H8: 75 | I8: =(IF('Daily HLP'!O10>0,'Daily HLP'!O10,0)) -> 233 | J8: 99 | K8: =Occupancy!G8 -> 158 | L8: =Occupancy!F8 -> 459 | M8: =E8*F8+G8*H8+#REF!*#REF!+I8*J8 -> #REF!
A9: Mumbai | B9: =B8+1 -> 8 | C9: 12 | D9: 2021 | E9: =(IF('Daily HLP'!H11>0,'Daily HLP'!H11,0)) -> 24742.32 | F9: 9 | G9: =(IF('Daily HLP'!L11>0,'Daily HLP'!L11,0)) -> 1247.37 | H9: 75 | I9: =(IF('Daily HLP'!O11>0,'Daily HLP'!O11,0)) -> 273 | J9: 99 | K9: =Occupancy!G9 -> 143 | L9: =Occupancy!F9 -> 892 | M9: =E9*F9+G9*H9+#REF!*#REF!+I9*J9 -> #REF!
A10: Mumbai | B10: =B9+1 -> 9 | C10: 12 | D10: 2021 | E10: =(IF('Daily HLP'!H12>0,'Daily HLP'!H12,0)) -> 25427.13 | F10: 9 | G10: =(IF('Daily HLP'!L12>0,'Daily HLP'!L12,0)) -> 1195.2 | H10: 75 | I10: =(IF('Daily HLP'!O12>0,'Daily HLP'!O12,0)) -> 295 | J10: 99 | K10: =Occupancy!G10 -> 149 | L10: =Occupancy!F10 -> 1371 | M10: =E10*F10+G10*H10+#REF!*#REF!+I10*J10 -> #REF!
A11: Mumbai | B11: =B10+1 -> 10 | C11: 12 | D11: 2021 | E11: =(IF('Daily HLP'!H13>0,'Daily HLP'!H13,0)) -> 24380 | F11: 9 | G11: =(IF('Daily HLP'!L13>0,'Daily HLP'!L13,0)) -> 1193 | H11: 75 | I11: =(IF('Daily HLP'!O13>0,'Daily HLP'!O13,0)) -> 271 | J11: 99 | K11: =Occupancy!G11 -> 140 | L11: =Occupancy!F11 -> 855 | M11: =E11*F11+G11*H11+#REF!*#REF!+I11*J11 -> #REF!
A12: Mumbai | B12: =B11+1 -> 11 | C12: 12 | D12: 2021 | E12: =(IF('Daily HLP'!H14>0,'Daily HLP'!H14,0)) -> 24441 | F12: 9 | G12: =(IF('Daily HLP'!L14>0,'Daily HLP'!L14,0)) -> 1164 | H12: 75 | I12: =(IF('Daily HLP'!O14>0,'Daily HLP'!O14,0)) -> 274 | J12: 99 | K12: =Occupancy!G12 -> 158 | L12: =Occupancy!F12 -> 2169 | M12: =E12*F12+G12*H12+#REF!*#REF!+I12*J12 -> #REF!
A13: Mumbai | B13: =B12+1 -> 12 | C13: 12 | D13: 2021 | E13: =(IF('Daily HLP'!H15>0,'Daily HLP'!H15,0)) -> 25038 | F13: 9 | G13: =(IF('Daily HLP'!L15>0,'Daily HLP'!L15,0)) -> 1252 | H13: 75 | I13: =(IF('Daily HLP'!O15>0,'Daily HLP'!O15,0)) -> 294 | J13: 99 | K13: =Occupancy!G13 -> 126 | L13: =Occupancy!F13 -> 1260 | M13: =E13*F13+G13*H13+#REF!*#REF!+I13*J13 -> #REF!
A14: Mumbai | B14: =B13+1 -> 13 | C14: 12 | D14: 2021 | E14: =(IF('Daily HLP'!H16>0,'Daily HLP'!H16,0)) -> 23684 | F14: 9 | G14: =(IF('Daily HLP'!L16>0,'Daily HLP'!L16,0)) -> 1211 | H14: 75 | I14: =(IF('Daily HLP'!O16>0,'Daily HLP'!O16,0)) -> 294 | J14: 99 | K14: =Occupancy!G14 -> 138 | L14: =Occupancy!F14 -> 1291 | M14: =E14*F14+G14*H14+#REF!*#REF!+I14*J14 -> #REF!
... A31: Mumbai | B31: =B30+1 -> 30 | C31: 12 | D31: 2021 | E31: =(IF('Daily HLP'!H33>0,'Daily HLP'!H33,0)) -> 24000 | F31: 9 | G31: =(IF('Daily HLP'!L33>0,'Daily HLP'!L33,0)) -> 1100 | H31: 75 | I31: =(IF('Daily HLP'!O33>0,'Daily HLP'!O33,0)) -> 0 | J31: 99 | K31: =Occupancy!G31 -> 0 | L31: =Occupancy!F31 -> 0 | M31: =E31*F31+G31*H31+#REF!*#REF!+I31*J31 -> #REF!
A32: Mumbai | B32: =B31+1 -> 31 | C32: 12 | D32: 2021 | E32: =(IF('Daily HLP'!H34>0,'Daily HLP'!H34,0)) -> 24000 | F32: 9 | G32: =(IF('Daily HLP'!L34>0,'Daily HLP'!L34,0)) -> 1100 | H32: 75 | I32: =(IF('Daily HLP'!O34>0,'Daily HLP'!O34,0)) -> 0 | J32: 99 | K32: =Occupancy!G32 -> 0 | L32: =Occupancy!F32 -> 0

Sheet Submetering
A1: Site Name | B1: Day | C1: Month | D1: Year | E1: ='Section Load'!F4 -> HVAC | F1: ='Section Load'!G4 -> Fire & Emergency PP | G1: ='Section Load'!H4 -> Main PP | H1: ='Section Load'!I4 -> Lighting PP | I1: ='Section Load'!J4 -> CH-1+ CH2+CH3+CH4 | J1: ='Section Load'!K4 -> Chilled water Pump | K1: ='Section Load'!L4 -> Ball Room-1 | L1: ='Section Load'!M4 -> Ball Room-2 | ... AL1: ='Section Load'!AM4 -> Cooling Tower | AM1: R.o.plant | AN1: STP Water Prod | AO1: Domestic Zone-1 | AP1: Domestic Zone-2 | AQ1: Domestic Zone-3 | AR1: Flush Zone -1 | AS1: Flush Zone -2 | AT1: Flush Zone -3 | AU1: Swimming pool | AV1: B2 Laundry | AW1: Boiler Feed Water | AX1: cooling tower filling water | AY1: STP flush(new water meter) | AZ1: Garden Water Pump | BA1: Flush Zone 2 pump meter | BB1: Flush Zone 3 Pump Meter (wtp transfer ) | BC1: Flush Tanker-Zone-1 | BD1: Total Domestic Water (Tanker (R.O) +BMC) | BE1: Total Domestic Consumption | BF1: Total STP Consumption | BG1: ='Section Load'!AN4 -> MGL | BH1: ='Section Load'!AO4 -> HWG | BI1: ='Section Load'!AP4 -> Prato | BJ1: ='Section Load'!AQ4 -> BR-1 | BK1: ='Section Load'!AR4 -> SanQi IND | BL1: ='Section Load'!AS4 -> SanQi JPN | BM1: ='Section Load'!AT4 -> Boiler
A2: Mumbai | B2: 1 | C2: 12 | D2: 2021 | E2: =(IF('Section Load'!F5>0,'Section Load'!F5,0)) -> 3840.04 | F2: =(IF('Section Load'!G5>0,'Section Load'!G5,0)) -> 1702.26 | G2: =(IF('Section Load'!H5>0,'Section Load'!H5,0)) -> 1904.95 | H2: =(IF('Section Load'!I5>0,'Section Load'!I5,0)) -> 2945.71 | I2: =(IF('Section Load'!J5>0,'Section Load'!J5,0)) -> 5399.35 | J2: =(IF('Section Load'!K5>0,'Section Load'!K5,0)) -> 2459.4 | K2: =(IF('Section Load'!L5>0,'Section Load'!L5,0)) -> 1459.81 | L2: =(IF('Section Load'!M5>0,'Section Load'!M5,0)) -> 940.3 | ... AL2: =(IF('Section Load'!AM5>0,'Section Load'!AM5,0)) -> 843.58 | AM2: =(IF('Water Report'!$D$7>0,'Water Report'!$D$7,0)) -> 108 | AN2: =(IF('Water Report'!$D$8>0,'Water Report'!$D$8,0)) -> 94 | AO2: =(IF('Water Report'!$D$9>0,'Water Report'!$D$9,0)) -> 86 | AP2: =(IF('Water Report'!$D$10>0,'Water Report'!$D$10,0)) -> 18 | AQ2: =(IF('Water Report'!$D$11>0,'Water Report'!$D$11,0)) -> 25 | AR2: =(IF('Water Report'!$D$13>0,'Water Report'!$D$13,0)) -> 34 | AS2: =(IF('Water Report'!$D$14>0,'Water Report'!$D$14,0)) -> 10 | AT2: =(IF('Water Report'!$D$15>0,'Water Report'!$D$15,0)) -> 6 | AU2: =(IF('Water Report'!$D$17>0,'Water Report'!$D$17,0)) -> 0 | AV2: =(IF('Water Report'!$D$18>0,'Water Report'!$D$18,0)) -> 15 | AW2: =(IF('Water Report'!$D$19>0,'Water Report'!$D$19,0)) -> 10 | AX2: =(IF('Water Report'!$D$21>0,'Water Report'!$D$21,0)) -> 63 | AY2: =(IF('Water Report'!$D$22>0,'Water Report'!$D$22,0)) -> 0 | AZ2: =(IF('Water Report'!$D$23>0,'Water Report'!$D$23,0)) -> 4 | BA2: =(IF('Water Report'!$D$14>0,'Water Report'!$D$14,0)) -> 10 | BB2: =(IF('Water Report'!$D$15>0,'Water Report'!$D$15,0)) -> 6 | BC2: =(IF('Water Report'!$D$13>0,'Water Report'!$D$13,0)) -> 34 | BD2: =(IF('Water Report'!$D$24>0,'Water Report'!$D$24,0)) -> 212 | BE2: =(IF('Water Report'!$D$25>0,'Water Report'!$D$25,0)) -> 145 | BF2: =(IF('Water Report'!$D$27>0,'Water Report'!$D$27,0)) -> 101 | BG2: =(IF('Section Load'!AN5>0,'Section Load'!AN5,0)) -> 1074 | BH2: =(IF('Section Load'!AO5>0,'Section Load'!AO5,0)) -> 305.951 | BI2: =(IF('Section Load'!AP5>0,'Section Load'!AP5,0)) -> 0 | BJ2: =(IF('Section Load'!AQ5>0,'Section Load'!AQ5,0)) -> 116 | BK2: =(IF('Section Load'!AR5>0,'Section Load'!AR5,0)) -> 45 | BL2: =(IF('Section Load'!AS5>0,'Section Load'!AS5,0)) -> 2 | BM2: =(IF('Section Load'!AT5>0,'Section Load'!AT5,0)) -> 605.049
A3: Mumbai | B3: =B2+1 -> 2 | C3: 12 | D3: 2021 | E3: =(IF('Section Load'!F6>0,'Section Load'!F6,0)) -> 3698.69 | F3: =(IF('Section Load'!G6>0,'Section Load'!G6,0)) -> 1670.59 | G3: =(IF('Section Load'!H6>0,'Section Load'!H6,0)) -> 1896.57 | H3: =(IF('Section Load'!I6>0,'Section Load'!I6,0)) -> 2783 | I3: =(IF('Section Load'!J6>0,'Section Load'!J6,0)) -> 4727.13 | J3: =(IF('Section Load'!K6>0,'Section Load'!K6,0)) -> 2388.4 | K3: =(IF('Section Load'!L6>0,'Section Load'!L6,0)) -> 1486.35 | L3: =(IF('Section Load'!M6>0,'Section Load'!M6,0)) -> 968.7 | ... AL3: =(IF('Section Load'!AM6>0,'Section Load'!AM6,0)) -> 835.4 | AM3: =(IF('Water Report'!$E$7>0,'Water Report'!$E$7,0)) -> 116 | AN3: =(IF('Water Report'!$E$8>0,'Water Report'!$E$8,0)) -> 102 | AO3: =(IF('Water Report'!$E$9>0,'Water Report'!$E$9,0)) -> 98 | AP3: =(IF('Water Report'!$E$10>0,'Water Report'!$E$10,0)) -> 21 | AQ3: =(IF('Water Report'!$E$11>0,'Water Report'!$E$11,0)) -> 29 | AR3: =(IF('Water Report'!$E$13>0,'Water Report'!$E$13,0)) -> 33 | AS3: =(IF('Water Report'!$E$14>0,'Water Report'!$E$14,0)) -> 25 | AT3: =(IF('Water Report'!$E$15>0,'Water Report'!$E$15,0)) -> 21.2 | AU3: =(IF('Water Report'!$E$17>0,'Water Report'!$E$17,0)) -> 0 | AV3: =(IF('Water Report'!$E$18>0,'Water Report'!$E$18,0)) -> 17 | AW3: =(IF('Water Report'!$E$19>0,'Water Report'!$E$19,0)) -> 11 | AX3: =(IF('Water Report'!$E$21>0,'Water Report'!$E$21,0)) -> 62 | AY3: =(IF('Water Report'!$E$22>0,'Water Report'!$E$22,0)) -> 0 | AZ3: =(IF('Water Report'!$E$23>0,'Water Report'!$E$23,0)) -> 1 | BA3: =(IF('Water Report'!$E$14>0,'Water Report'!$E$14,0)) -> 25 | BB3: =(IF('Water Report'!$E$15>0,'Water Report'!$E$15,0)) -> 21.2 | BC3: =(IF('Water Report'!$E$13>0,'Water Report'!$E$13,0)) -> 33 | BD3: =(IF('Water Report'!$E$24>0,'Water Report'!$E$24,0)) -> 254 | BE3: =(IF('Water Report'!$E$25>0,'Water Report'!$E$25,0)) -> 194.2 | BF3: =(IF('Water Report'!$E$27>0,'Water Report'!$E$27,0)) -> 96 | BG3: =(IF('Section Load'!AN6>0,'Section Load'!AN6,0)) -> 1094.24 | BH3: =(IF('Section Load'!AO6>0,'Section Load'!AO6,0)) -> 298.2 | BI3: =(IF('Section Load'!AP6>0,'Section Load'!AP6,0)) -> 0 | BJ3: =(IF('Section Load'!AQ6>0,'Section Load'!AQ6,0)) -> 121.9 | BK3: =(IF('Section Load'!AR6>0,'Section Load'!AR6,0)) -> 49.5 | BL3: =(IF('Section Load'!AS6>0,'Section Load'!AS6,0)) -> 2.4 | BM3: =(IF('Section Load'!AT6>0,'Section Load'!AT6,0)) -> 622.24
A4: Mumbai | B4: =B3+1 -> 3 | C4: 12 | D4: 2021 | E4: =(IF('Section Load'!F7>0,'Section Load'!F7,0)) -> 3864.4 | F4: =(IF('Section Load'!G7>0,'Section Load'!G7,0)) -> 1609.33 | G4: =(IF('Section Load'!H7>0,'Section Load'!H7,0)) -> 2009.46 | H4: =(IF('Section Load'!I7>0,'Section Load'!I7,0)) -> 2891.53 | I4: =(IF('Section Load'!J7>0,'Section Load'!J7,0)) -> 6111.3 | J4: =(IF('Section Load'!K7>0,'Section Load'!K7,0)) -> 2707 | K4: =(IF('Section Load'!L7>0,'Section Load'!L7,0)) -> 1287.52 | L4: =(IF('Section Load'!M7>0,'Section Load'!M7,0)) -> 1025.88 | ... AL4: =(IF('Section Load'!AM7>0,'Section Load'!AM7,0)) -> 845.05 | AM4: =(IF('Water Report'!$F$7>0,'Water Report'!$F$7,0)) -> 128 | AN4: =(IF('Water Report'!$F$8>0,'Water Report'!$F$8,0)) -> 107 | AO4: =(IF('Water Report'!$F$9>0,'Water Report'!$G$9,0)) -> 109 | AP4: =(IF('Water Report'!$F$10>0,'Water Report'!$F$10,0)) -> 27 | AQ4: =(IF('Water Report'!$F$11>0,'Water Report'!$F$11,0)) -> 29 | AR4: =(IF('Water Report'!$F$13>0,'Water Report'!$F$13,0)) -> 39 | AS4: =(IF('Water Report'!$F$14>0,'Water Report'!$F$14,0)) -> 12 | AT4: =(IF('Water Report'!$F$15>0,'Water Report'!$F$15,0)) -> 2.8 | AU4: =(IF('Water Report'!$F$17>0,'Water Report'!$F$17,0)) -> 0 | AV4: =(IF('Water Report'!$F$18>0,'Water Report'!$F$18,0)) -> 14 | AW4: =(IF('Water Report'!$F$19>0,'Water Report'!$F$19,0)) -> 12 | AX4: =(IF('Water Report'!$F$21>0,'Water Report'!$F$21,0)) -> 87 | AY4: =(IF('Water Report'!$F$22>0,'Water Report'!$F$22,0)) -> 0 | AZ4: =(IF('Water Report'!$F$23>0,'Water Report'!$F$23,0)) -> 8 | BA4: =(IF('Water Report'!$F$14>0,'Water Report'!$F$14,0)) -> 12 | BB4: =(IF('Water Report'!$F$15>0,'Water Report'!$F$15,0)) -> 2.8 | BC4: =(IF('Water Report'!$F$13>0,'Water Report'!$F$13,0)) -> 39 | BD4: =(IF('Water Report'!$F$24>0,'Water Report'!$F$24,0)) -> 285 | BE4: =(IF('Water Report'!$F$25>0,'Water Report'!$F$25,0)) -> 159.8 | BF4: =(IF('Water Report'!$F$27>0,'Water Report'!$F$27,0)) -> 134 | BG4: =(IF('Section Load'!AN7>0,'Section Load'!AN7,0)) -> 1144.15 | BH4: =(IF('Section Load'!AO7>0,'Section Load'!AO7,0)) -> 326.73 | BI4: =(IF('Section Load'!AP7>0,'Section Load'!AP7,0)) -> 0 | BJ4: =(IF('Section Load'!AQ7>0,'Section Load'!AQ7,0)) -> 118.5 | BK4: =(IF('Section Load'!AR7>0,'Section Load'!AR7,0)) -> 46 | BL4: =(IF('Section Load'!AS7>0,'Section Load'!AS7,0)) -> 2.8 | BM4: =(IF('Section Load'!AT7>0,'Section Load'!AT7,0)) -> 650.12
A5: Mumbai | B5: =B4+1 -> 4 | C5: 12 | D5: 2021 | E5: =(IF('Section Load'!F8>0,'Section Load'!F8,0)) -> 4121.79 | F5: =(IF('Section Load'!G8>0,'Section Load'!G8,0)) -> 1690.62 | G5: =(IF('Section Load'!H8>0,'Section Load'!H8,0)) -> 2045.22 | H5: =(IF('Section Load'!I8>0,'Section Load'!I8,0)) -> 2998.8 | I5: =(IF('Section Load'!J8>0,'Section Load'!J8,0)) -> 6927.15 | J5: =(IF('Section Load'!K8>0,'Section Load'!K8,0)) -> 2866.5 | K5: =(IF('Section Load'!L8>0,'Section Load'!L8,0)) -> 1403.28 | L5: =(IF('Section Load'!M8>0,'Section Load'!M8,0)) -> 1057.88 | ... AL5: =(IF('Section Load'!AM8>0,'Section Load'!AM8,0)) -> 893.08 | AM5: =(IF('Water Report'!$G$7>0,'Water Report'!$F$7,0)) -> 128 | AN5: =(IF('Water Report'!$G$8>0,'Water Report'!$F$8,0)) -> 107 | AO5: =(IF('Water Report'!$G$9>0,'Water Report'!$H$9,0)) -> 105 | AP5: =(IF('Water Report'!$G$10>0,'Water Report'!$G$10,0)) -> 29 | AQ5: =(IF('Water Report'!$G$11>0,'Water Report'!$G$11,0)) -> 32 | AR5: =(IF('Water Report'!$G$13>0,'Water Report'!$G$13,0)) -> 39 | AS5: =(IF('Water Report'!$G$14>0,'Water Report'!$G$14,0)) -> 12 | AT5: =(IF('Water Report'!$G$15>0,'Water Report'!$G$15,0)) -> 13 | AU5: =(IF('Water Report'!$G$17>0,'Water Report'!$G$17,0)) -> 0 | AV5: =(IF('Water Report'!$G$18>0,'Water Report'!$G$18,0)) -> 17 | AW5: =(IF('Water Report'!$G$19>0,'Water Report'!$G$19,0)) -> 15 | AX5: =(IF('Water Report'!$G$21>0,'Water Report'!$G$21,0)) -> 107 | AY5: =(IF('Water Report'!$G$22>0,'Water Report'!$G$22,0)) -> 0 | AZ5: =(IF('Water Report'!$G$23>0,'Water Report'!$G$23,0)) -> 2 | BA5: =(IF('Water Report'!$G$14>0,'Water Report'!$G$14,0)) -> 12 | BB5: =(IF('Water Report'!$G$15>0,'Water Report'!$G$15,0)) -> 13 | BC5: =(IF('Water Report'!$G$13>0,'Water Report'!$G$13,0)) -> 39 | BD5: =(IF('Water Report'!$G$24>0,'Water Report'!$G$24,0)) -> 254 | BE5: =(IF('Water Report'!$G$25>0,'Water Report'!$G$25,0)) -> 195 | BF5: =(IF('Water Report'!$G$27>0,'Water Report'!$G$27,0)) -> 148 | BG5: =(IF('Section Load'!AN8>0,'Section Load'!AN8,0)) -> 1192.76 | BH5: =(IF('Section Load'!AO8>0,'Section Load'!AO8,0)) -> 297.23 | BI5: =(IF('Section Load'!AP8>0,'Section Load'!AP8,0)) -> 0 | BJ5: =(IF('Section Load'!AQ8>0,'Section Load'!AQ8,0)) -> 135 | BK5: =(IF('Section Load'!AR8>0,'Section Load'!AR8,0)) -> 48.7 | BL5: =(IF('Section Load'!AS8>0,'Section Load'!AS8,0)) -> 2.5 | BM5: =(IF('Section Load'!AT8>0,'Section Load'!AT8,0)) -> 709.33
A6: Mumbai | B6: =B5+1 -> 5 | C6: 12 | D6: 2021 | E6: =(IF('Section Load'!F9>0,'Section Load'!F9,0)) -> 3887.4 | F6: =(IF('Section Load'!G9>0,'Section Load'!G9,0)) -> 1646.24 | G6: =(IF('Section Load'!H9>0,'Section Load'!H9,0)) -> 1984.42 | H6: =(IF('Section Load'!I9>0,'Section Load'!I9,0)) -> 2790.58 | I6: =(IF('Section Load'!J9>0,'Section Load'!J9,0)) -> 6031.67 | J6: =(IF('Section Load'!K9>0,'Section Load'!K9,0)) -> 2729.4 | K6: =(IF('Section Load'!L9>0,'Section Load'!L9,0)) -> 1235.68 | L6: =(IF('Section Load'!M9>0,'Section Load'!M9,0)) -> 864.04 | ... AL6: =(IF('Section Load'!AM9>0,'Section Load'!AM9,0)) -> 857.55 | AM6: =(IF('Water Report'!$H$7>0,'Water Report'!$H$7,0)) -> 133 | AN6: =(IF('Water Report'!$H$8>0,'Water Report'!$H$8,0)) -> 137 | AO6: =(IF('Water Report'!$H$9>0,'Water Report'!$H$9,0)) -> 105 | AP6: =(IF('Water Report'!$H$10>0,'Water Report'!$H$10,0)) -> 26 | AQ6: =(IF('Water Report'!$H$11>0,'Water Report'!$H$11,0)) -> 31 | AR6: =(IF('Water Report'!$H$13>0,'Water Report'!$H$13,0)) -> 37 | AS6: =(IF('Water Report'!$H$14>0,'Water Report'!$H$14,0)) -> 7 | AT6: =(IF('Water Report'!$H$15>0,'Water Report'!$H$15,0)) -> 8 | AU6: =(IF('Water Report'!$H$17>0,'Water Report'!$H$17,0)) -> 0 | AV6: =(IF('Water Report'!$H$18>0,'Water Report'!$H$18,0)) -> 18 | AW6: =(IF('Water Report'!$H$19>0,'Water Report'!$H$19,0)) -> 14 | AX6: =(IF('Water Report'!$H$21>0,'Water Report'!$H$21,0)) -> 65 | AY6: =(IF('Water Report'!$H$22>0,'Water Report'!$H$22,0)) -> 0 | AZ6: =(IF('Water Report'!$H$23>0,'Water Report'!$H$23,0)) -> 3 | BA6: =(IF('Water Report'!$H$14>0,'Water Report'!$H$14,0)) -> 7 | BB6: =(IF('Water Report'!$H$15>0,'Water Report'!$H$15,0)) -> 8 | BC6: =(IF('Water Report'!$H$13>0,'Water Report'!$H$13,0)) -> 37 | BD6: =(IF('Water Report'!$H$24>0,'Water Report'!$H$24,0)) -> 253 | BE6: =(IF('Water Report'!$H$25>0,'Water Report'!$H$25,0)) -> 177 | BF6: =(IF('Water Report'!$H$27>0,'Water Report'!$H$27,0)) -> 105 | BG6: =(IF('Section Load'!AN9>0,'Section Load'!AN9,0)) -> 1192.29 | BH6: =(IF('Section Load'!AO9>0,'Section Load'!AO9,0)) -> 322.71 | BI6: =(IF('Section Load'!AP9>0,'Section Load'!AP9,0)) -> 0 | BJ6: =(IF('Section Load'!AQ9>0,'Section Load'!AQ9,0)) -> 129.82 | BK6: =(IF('Section Load'!AR9>0,'Section Load'!AR9,0)) -> 38.8 | BL6: =(IF('Section Load'!AS9>0,'Section Load'!AS9,0)) -> 5.2 | BM6: =(IF('Section Load'!AT9>0,'Section Load'!AT9,0)) -> 695.76
A7: Mumbai | B7: =B6+1 -> 6 | C7: 12 | D7: 2021 | E7: =(IF('Section Load'!F10>0,'Section Load'!F10,0)) -> 3557.3 | F7: =(IF('Section Load'!G10>0,'Section Load'!G10,0)) -> 1618.55 | G7: =(IF('Section Load'!H10>0,'Section Load'!H10,0)) -> 1899.7 | H7: =(IF('Section Load'!I10>0,'Section Load'!I10,0)) -> 2851.32 | I7: =(IF('Section Load'!J10>0,'Section Load'!J10,0)) -> 5338.64 | J7: =(IF('Section Load'!K10>0,'Section Load'!K10,0)) -> 2429.1 | K7: =(IF('Section Load'!L10>0,'Section Load'!L10,0)) -> 1486.64 | L7: =(IF('Section Load'!M10>0,'Section Load'!M10,0)) -> 769.57 | ... AL7: =(IF('Section Load'!AM10>0,'Section Load'!AM10,0)) -> 842.67 | AM7: =(IF('Water Report'!$I$7>0,'Water Report'!$I$7,0)) -> 107 | AN7: =(IF('Water Report'!$I$8>0,'Water Report'!$I$8,0)) -> 120 | AO7: =(IF('Water Report'!$I$9>0,'Water Report'!$I$9,0)) -> 88 | AP7: =(IF('Water Report'!$I$10>0,'Water Report'!$I$10,0)) -> 16 | AQ7: =(IF('Water Report'!$I$11>0,'Water Report'!$I$11,0)) -> 25 | AR7: =(IF('Water Report'!$I$13>0,'Water Report'!$I$13,0)) -> 42 | AS7: =(IF('Water Report'!$I$14>0,'Water Report'!$I$14,0)) -> 14 | AT7: =(IF('Water Report'!$I$15>0,'Water Report'!$I$15,0)) -> 8 | AU7: =(IF('Water Report'!$I$17>0,'Water Report'!$I$17,0)) -> 0 | AV7: =(IF('Water Report'!$I$18>0,'Water Report'!$I$18,0)) -> 13 | AW7: =(IF('Water Report'!$I$19>0,'Water Report'!$I$19,0)) -> 12 | AX7: =(IF('Water Report'!$I$21>0,'Water Report'!$I$21,0)) -> 58 | AY7: =(IF('Water Report'!$I$22>0,'Water Report'!$I$22,0)) -> 0 | AZ7: =(IF('Water Report'!$I$23>0,'Water Report'!$I$23,0)) -> 18 | BA7: =(IF('Water Report'!$I$14>0,'Water Report'!$I$14,0)) -> 14 | BB7: =(IF('Water Report'!$I$15>0,'Water Report'!$I$15,0)) -> 8 | BC7: =(IF('Water Report'!$I$13>0,'Water Report'!$I$13,0)) -> 42 | BD7: =(IF('Water Report'!$I$24>0,'Water Report'!$I$24,0)) -> 253 | BE7: =(IF('Water Report'!$I$25>0,'Water Report'!$I$25,0)) -> 151 | BF7: =(IF('Water Report'!$I$27>0,'Water Report'!$I$27,0)) -> 118 | BG7: =(IF('Section Load'!AN10>0,'Section Load'!AN10,0)) -> 1123.02 | BH7: =(IF('Section Load'!AO10>0,'Section Load'!AO10,0)) -> 312.49 | BI7: =(IF('Section Load'!AP10>0,'Section Load'!AP10,0)) -> 0 | BJ7: =(IF('Section Load'!AQ10>0,'Section Load'!AQ10,0)) -> 120.58 | BK7: =(IF('Section Load'!AR10>0,'Section Load'!AR10,0)) -> 41.9 | BL7: =(IF('Section Load'!AS10>0,'Section Load'!AS10,0)) -> 2.1 | BM7: =(IF('Section Load'!AT10>0,'Section Load'!AT10,0)) -> 645.95
A8: Mumbai | B8: =B7+1 -> 7 | C8: 12 | D8: 2021 | E8: =(IF('Section Load'!F11>0,'Section Load'!F11,0)) -> 3743.98 | F8: =(IF('Section Load'!G11>0,'Section Load'!G11,0)) -> 1673.29 | G8: =(IF('Section Load'!H11>0,'Section Load'!H11,0)) -> 1948.2 | H8: =(IF('Section Load'!I11>0,'Section Load'!I11,0)) -> 3056.68 | I8: =(IF('Section Load'!J11>0,'Section Load'!J11,0)) -> 6499.34 | J8: =(IF('Section Load'!K11>0,'Section Load'!K11,0)) -> 2942.2 | K8: =(IF('Section Load'!L11>0,'Section Load'!L11,0)) -> 1598.48 | L8: =(IF('Section Load'!M11>0,'Section Load'!M11,0)) -> 1145.69 | ... AL8: =(IF('Section Load'!AM11>0,'Section Load'!AM11,0)) -> 836.87 | AM8: =(IF('Water Report'!$J$7>0,'Water Report'!$J$7,0)) -> 103 | AN8: =(IF('Water Report'!$J$8>0,'Water Report'!$J$8,0)) -> 123 | AO8: =(IF('Water Report'!$J$9>0,'Water Report'!$J$9,0)) -> 102 | AP8: =(IF('Water Report'!$J$10>0,'Water Report'!$J$10,0)) -> 17 | AQ8: =(IF('Water Report'!$J$11>0,'Water Report'!$J$11,0)) -> 31 | AR8: =(IF('Water Report'!$J$13>0,'Water Report'!$J$13,0)) -> 39 | AS8: =(IF('Water Report'!$J$14>0,'Water Report'!$J$14,0)) -> 10 | AT8: =(IF('Water Report'!$J$15>0,'Water Report'!$J$15,0)) -> 13 | AU8: =(IF('Water Report'!$J$17>0,'Water Report'!$J$17,0)) -> 0 | AV8: =(IF('Water Report'!$J$18>0,'Water Report'!$J$18,0)) -> 16 | AW8: =(IF('Water Report'!$J$19>0,'Water Report'!$J$19,0)) -> 12 | AX8: =(IF('Water Report'!$J$21>0,'Water Report'!$J$21,0)) -> 74 | AY8: =(IF('Water Report'!$J$22>0,'Water Report'!$J$22,0)) -> 0 | AZ8: =(IF('Water Report'!$J$23>0,'Water Report'!$J$23,0)) -> 4 | BA8: =(IF('Water Report'!$J$14>0,'Water Report'!$J$14,0)) -> 10 | BB8: =(IF('Water Report'!$J$15>0,'Water Report'!$J$15,0)) -> 13 | BC8: =(IF('Water Report'!$J$13>0,'Water Report'!$J$13,0)) -> 39 | BD8: =(IF('Water Report'!$J$24>0,'Water Report'!$J$24,0)) -> 233 | BE8: =(IF('Water Report'!$J$25>0,'Water Report'!$J$25,0)) -> 173 | BF8: =(IF('Water Report'!$J$27>0,'Water Report'!$J$27,0)) -> 117 | BG8: =(IF('Section Load'!AN11>0,'Section Load'!AN11,0)) -> 1194.97 | BH8: =(IF('Section Load'!AO11>0,'Section Load'!AO11,0)) -> 328.91 | BI8: =(IF('Section Load'!AP11>0,'Section Load'!AP11,0)) -> 0 | BJ8: =(IF('Section Load'!AQ11>0,'Section Load'!AQ11,0)) -> 133.9 | BK8: =(IF('Section Load'!AR11>0,'Section Load'!AR11,0)) -> 46.2 | BL8: =(IF('Section Load'!AS11>0,'Section Load'!AS11,0)) -> 4.7 | BM8: =(IF('Section Load'!AT11>0,'Section Load'!AT11,0)) -> 681.26
A9: Mumbai | B9: =B8+1 -> 8 | C9: 12 | D9: 2021 | E9: =(IF('Section Load'!F12>0,'Section Load'!F12,0)) -> 3948.87 | F9: =(IF('Section Load'!G12>0,'Section Load'!G12,0)) -> 1652.3 | G9: =(IF('Section Load'!H12>0,'Section Load'!H12,0)) -> 1942.2 | H9: =(IF('Section Load'!I12>0,'Section Load'!I12,0)) -> 2854.32 | I9: =(IF('Section Load'!J12>0,'Section Load'!J12,0)) -> 6030.98 | J9: =(IF('Section Load'!K12>0,'Section Load'!K12,0)) -> 2990.9 | K9: =(IF('Section Load'!L12>0,'Section Load'!L12,0)) -> 1320.64 | L9: =(IF('Section Load'!M12>0,'Section Load'!M12,0)) -> 1254.56 | ... AL9: =(IF('Section Load'!AM12>0,'Section Load'!AM12,0)) -> 838.89 | AM9: =(IF('Water Report'!$K$7>0,'Water Report'!$K$7,0)) -> 133 | AN9: =(IF('Water Report'!$K$8>0,'Water Report'!$K$8,0)) -> 110 | AO9: =(IF('Water Report'!$K$9>0,'Water Report'!$K$9,0)) -> 113 | AP9: =(IF('Water Report'!$K$10>0,'Water Report'!$K$10,0)) -> 19 | AQ9: =(IF('Water Report'!$K$11>0,'Water Report'!$K$11,0)) -> 29 | AR9: =(IF('Water Report'!$K$13>0,'Water Report'!$K$13,0)) -> 37 | AS9: =(IF('Water Report'!$K$14>0,'Water Report'!$K$14,0)) -> 9 | AT9: =(IF('Water Report'!$K$15>0,'Water Report'!$K$15,0)) -> 9 | AU9: =(IF('Water Report'!$K$17>0,'Water Report'!$K$17,0)) -> 0 | AV9: =(IF('Water Report'!$K$18>0,'Water Report'!$K$18,0)) -> 18 | AW9: =(IF('Water Report'!$K$19>0,'Water Report'!$K$19,0)) -> 14 | AX9: =(IF('Water Report'!$K$21>0,'Water Report'!$K$21,0)) -> 74 | AY9: =(IF('Water Report'!$K$22>0,'Water Report'!$K$22,0)) -> 0 | AZ9: =(IF('Water Report'!$K$23>0,'Water Report'!$K$23,0)) -> 17 | BA9: =(IF('Water Report'!$K$14>0,'Water Report'!$K$14,0)) -> 9 | BB9: =(IF('Water Report'!$K$15>0,'Water Report'!$K$15,0)) -> 9 | BC9: =(IF('Water Report'!$K$13>0,'Water Report'!$K$13,0)) -> 37 | BD9: =(IF('Water Report'!$K$24>0,'Water Report'!$K$24,0)) -> 273 | BE9: =(IF('Water Report'!$K$25>0,'Water Report'!$K$25,0)) -> 179 | BF9: =(IF('Water Report'!$K$27>0,'Water Report'!$K$27,0)) -> 128 | BG9: =(IF('Section Load'!AN12>0,'Section Load'!AN12,0)) -> 1247.37 | BH9: =(IF('Section Load'!AO12>0,'Section Load'!AO12,0)) -> 325.08 | BI9: =(IF('Section Load'!AP12>0,'Section Load'!AP12,0)) -> 243.89 | BJ9: =(IF('Section Load'!AQ12>0,'Section Load'!AQ12,0)) -> 153.5 | BK9: =(IF('Section Load'!AR12>0,'Section Load'!AR12,0)) -> 55.9 | BL9: =(IF('Section Load'!AS12>0,'Section Load'!AS12,0)) -> 5.3 | BM9: =(IF('Section Load'!AT12>0,'Section Load'!AT12,0)) -> 463.7
A10: Mumbai | B10: =B9+1 -> 9 | C10: 12 | D10: 2021 | E10: =(IF('Section Load'!F13>0,'Section Load'!F13,0)) -> 3842.57 | F10: =(IF('Section Load'!G13>0,'Section Load'!G13,0)) -> 1667.08 | G10: =(IF('Section Load'!H13>0,'Section Load'!H13,0)) -> 2054.23 | H10: =(IF('Section Load'!I13>0,'Section Load'!I13,0)) -> 2940.77 | I10: =(IF('Section Load'!J13>0,'Section Load'!J13,0)) -> 6457.79 | J10: =(IF('Section Load'!K13>0,'Section Load'!K13,0)) -> 2717.5 | K10: =(IF('Section Load'!L13>0,'Section Load'!L13,0)) -> 1723.41 | L10: =(IF('Section Load'!M13>0,'Section Load'!M13,0)) -> 1286.68 | ... AL10: =(IF('Section Load'!AM13>0,'Section Load'!AM13,0)) -> 830.49 | AM10: =(IF('Water Report'!$L$7>0,'Water Report'!$L$7,0)) -> 141 | AN10: =(IF('Water Report'!$L$8>0,'Water Report'!$L$8,0)) -> 80 | AO10: =(IF('Water Report'!$L$9>0,'Water Report'!$L$9,0)) -> 132 | AP10: =(IF('Water Report'!$L$10>0,'Water Report'!$L$10,0)) -> 14 | AQ10: =(IF('Water Report'!$L$11>0,'Water Report'!$L$11,0)) -> 34 | AR10: =(IF('Water Report'!$L$13>0,'Water Report'!$L$13,0)) -> 56 | AS10: =(IF('Water Report'!$L$14>0,'Water Report'!$L$14,0)) -> 15 | AT10: =(IF('Water Report'!$L$15>0,'Water Report'!$L$15,0)) -> 10 | AU10: =(IF('Water Report'!$L$17>0,'Water Report'!$L$17,0)) -> 0 | AV10: =(IF('Water Report'!$L$18>0,'Water Report'!$L$18,0)) -> 15 | AW10: =(IF('Water Report'!$L$19>0,'Water Report'!$L$19,0)) -> 14 | AX10: =(IF('Water Report'!$L$21>0,'Water Report'!$L$21,0)) -> 70 | AY10: =(IF('Water Report'!$L$22>0,'Water Report'!$L$22,0)) -> 2 | AZ10: =(IF('Water Report'!$L$23>0,'Water Report'!$L$23,0)) -> 3 | BA10: =(IF('Water Report'!$L$14>0,'Water Report'!$L$14,0)) -> 15 | BB10: =(IF('Water Report'!$L$15>0,'Water Report'!$L$15,0)) -> 10 | BC10: =(IF('Water Report'!$L$13>0,'Water Report'!$L$13,0)) -> 56 | BD10: =(IF('Water Report'!$L$24>0,'Water Report'!$L$24,0)) -> 295 | BE10: =(IF('Water Report'!$L$25>0,'Water Report'!$L$25,0)) -> 205 | BF10: =(IF('Water Report'!$L$27>0,'Water Report'!$L$27,0)) -> 129 | BG10: =(IF('Section Load'!AN13>0,'Section Load'!AN13,0)) -> 1195.2 | BH10: =(IF('Section Load'!AO13>0,'Section Load'!AO13,0)) -> 315.65 | BI10: =(IF('Section Load'!AP13>0,'Section Load'!AP13,0)) -> 0 | BJ10: =(IF('Section Load'!AQ13>0,'Section Load'!AQ13,0)) -> 119.8 | BK10: =(IF('Section Load'!AR13>0,'Section Load'!AR13,0)) -> 52 | BL10: =(IF('Section Load'!AS13>0,'Section Load'!AS13,0)) -> 4 | BM10: =(IF('Section Load'!AT13>0,'Section Load'!AT13,0)) -> 703.75
A11: Mumbai | B11: =B10+1 -> 10 | C11: 12 | D11: 2021 | E11: =(IF('Section Load'!F14>0,'Section Load'!F14,0)) -> 3989 | F11: =(IF('Section Load'!G14>0,'Section Load'!G14,0)) -> 1651 | G11: =(IF('Section Load'!H14>0,'Section Load'!H14,0)) -> 2011 | H11: =(IF('Section Load'!I14>0,'Section Load'!I14,0)) -> 2918 | I11: =(IF('Section Load'!J14>0,'Section Load'!J14,0)) -> 6306 | J11: =(IF('Section Load'!K14>0,'Section Load'!K14,0)) -> 2734 | K11: =(IF('Section Load'!L14>0,'Section Load'!L14,0)) -> 1333 | L11: =(IF('Section Load'!M14>0,'Section Load'!M14,0)) -> 953 | ... AL11: =(IF('Section Load'!AM14>0,'Section Load'!AM14,0)) -> 842 | AM11: =(IF('Water Report'!$M$7>0,'Water Report'!$M$7,0)) -> 129 | AN11: =(IF('Water Report'!$M$8>0,'Water Report'!$M$8,0)) -> 100 | AO11: =(IF('Water Report'!$M$9>0,'Water Report'!$M$9,0)) -> 106 | AP11: =(IF('Water Report'!$M$10>0,'Water Report'!$M$10,0)) -> 14 | AQ11: =(IF('Water Report'!$M$11>0,'Water Report'!$M$11,0)) -> 29 | AR11: =(IF('Water Report'!$M$13>0,'Water Report'!$M$13,0)) -> 43 | AS11: =(IF('Water Report'!$M$14>0,'Water Report'!$M$14,0)) -> 12 | AT11: =(IF('Water Report'!$M$15>0,'Water Report'!$M$15,0)) -> 15 | AU11: =(IF('Water Report'!$M$17>0,'Water Report'!$M$17,0)) -> 0 | AV11: =(IF('Water Report'!$M$18>0,'Water Report'!$M$18,0)) -> 18 | AW11: =(IF('Water Report'!$M$19>0,'Water Report'!$M$19,0)) -> 14 | AX11: =(IF('Water Report'!$M$21>0,'Water Report'!$M$21,0)) -> 86 | AY11: =(IF('Water Report'!$M$22>0,'Water Report'!$M$22,0)) -> 0 | AZ11: =(IF('Water Report'!$M$23>0,'Water Report'!$M$23,0)) -> 2 | BA11: =(IF('Water Report'!$M$14>0,'Water Report'!$M$14,0)) -> 12 | BB11: =(IF('Water Report'!$M$15>0,'Water Report'!$M$15,0)) -> 15 | BC11: =(IF('Water Report'!$M$13>0,'Water Report'!$M$13,0)) -> 43 | BD11: =(IF('Water Report'!$M$24>0,'Water Report'!$M$24,0)) -> 271 | BE11: =(IF('Water Report'!$M$25>0,'Water Report'!$M$25,0)) -> 176 | BF11: =(IF('Water Report'!$M$27>0,'Water Report'!$M$27,0)) -> 131 | BG11: =(IF('Section Load'!AN14>0,'Section Load'!AN14,0)) -> 1193 | BH11: =(IF('Section Load'!AO14>0,'Section Load'!AO14,0)) -> 322 | BI11: =(IF('Section Load'!AP14>0,'Section Load'!AP14,0)) -> 0 | BJ11: =(IF('Section Load'!AQ14>0,'Section Load'!AQ14,0)) -> 137 | BK11: =(IF('Section Load'!AR14>0,'Section Load'!AR14,0)) -> 52 | BL11: =(IF('Section Load'!AS14>0,'Section Load'!AS14,0)) -> 1 | BM11: =(IF('Section Load'!AT14>0,'Section Load'!AT14,0)) -> 681
A12: Mumbai | B12: =B11+1 -> 11 | C12: 12 | D12: 2021 | E12: =(IF('Section Load'!F15>0,'Section Load'!F15,0)) -> 3866 | F12: =(IF('Section Load'!G15>0,'Section Load'!G15,0)) -> 1605 | G12: =(IF('Section Load'!H15>0,'Section Load'!H15,0)) -> 2162 | H12: =(IF('Section Load'!I15>0,'Section Load'!I15,0)) -> 2960 | I12: =(IF('Section Load'!J15>0,'Section Load'!J15,0)) -> 5467 | J12: =(IF('Section Load'!K15>0,'Section Load'!K15,0)) -> 2753 | K12: =(IF('Section Load'!L15>0,'Section Load'!L15,0)) -> 1517 | L12: =(IF('Section Load'!M15>0,'Section Load'!M15,0)) -> 806 | ... AL12: =(IF('Section Load'!AM15>0,'Section Load'!AM15,0)) -> 857 | AM12: =(IF('Water Report'!$N$7>0,'Water Report'!$N$7,0)) -> 116 | AN12: =(IF('Water Report'!$N$8>0,'Water Report'!$N$8,0)) -> 126 | AO12: =(IF('Water Report'!$N$9>0,'Water Report'!$N$9,0)) -> 104 | AP12: =(IF('Water Report'!$N$10>0,'Water Report'!$N$10,0)) -> 20 | AQ12: =(IF('Water Report'!$N$11>0,'Water Report'!$N$11,0)) -> 34 | AR12: =(IF('Water Report'!$N$13>0,'Water Report'!$N$13,0)) -> 39 | AS12: =(IF('Water Report'!$N$14>0,'Water Report'!$N$14,0)) -> 8 | AT12: =(IF('Water Report'!$N$15>0,'Water Report'!$N$15,0)) -> 11 | AU12: =(IF('Water Report'!$N$17>0,'Water Report'!$N$17,0)) -> 0 | AV12: =(IF('Water Report'!$N$18>0,'Water Report'!$N$18,0)) -> 20 | AW12: =(IF('Water Report'!$N$19>0,'Water Report'!$N$19,0)) -> 14 | AX12: =(IF('Water Report'!$N$21>0,'Water Report'!$N$21,0)) -> 83 | AY12: =(IF('Water Report'!$N$22>0,'Water Report'!$N$22,0)) -> 0 | AZ12: =(IF('Water Report'!$N$23>0,'Water Report'!$N$23,0)) -> 12 | BA12: =(IF('Water Report'!$N$14>0,'Water Report'!$N$14,0)) -> 8 | BB12: =(IF('Water Report'!$N$15>0,'Water Report'!$N$15,0)) -> 11 | BC12: =(IF('Water Report'!$N$13>0,'Water Report'!$N$13,0)) -> 39 | BD12: =(IF('Water Report'!$N$24>0,'Water Report'!$N$24,0)) -> 274 | BE12: =(IF('Water Report'!$N$25>0,'Water Report'!$N$25,0)) -> 177 | BF12: =(IF('Water Report'!$N$27>0,'Water Report'!$N$27,0)) -> 134 | BG12: =(IF('Section Load'!AN15>0,'Section Load'!AN15,0)) -> 1164 | BH12: =(IF('Section Load'!AO15>0,'Section Load'!AO15,0)) -> 309 | BI12: =(IF('Section Load'!AP15>0,'Section Load'!AP15,0)) -> 0 | BJ12: =(IF('Section Load'!AQ15>0,'Section Load'!AQ15,0)) -> 141 | BK12: =(IF('Section Load'!AR15>0,'Section Load'!AR15,0)) -> 44 | BL12: =(IF('Section Load'!AS15>0,'Section Load'!AS15,0)) -> 3 | BM12: =(IF('Section Load'!AT15>0,'Section Load'!AT15,0)) -> 667
A13: Mumbai | B13: =B12+1 -> 12 | C13: 12 | D13: 2021 | E13: =(IF('Section Load'!F16>0,'Section Load'!F16,0)) -> 3898 | F13: =(IF('Section Load'!G16>0,'Section Load'!G16,0)) -> 1688 | G13: =(IF('Section Load'!H16>0,'Section Load'!H16,0)) -> 2175 | H13: =(IF('Section Load'!I16>0,'Section Load'!I16,0)) -> 3054 | I13: =(IF('Section Load'!J16>0,'Section Load'!J16,0)) -> 5511 | J13: =(IF('Section Load'!K16>0,'Section Load'!K16,0)) -> 2634 | K13: =(IF('Section Load'!L16>0,'Section Load'!L16,0)) -> 1046 | L13: =(IF('Section Load'!M16>0,'Section Load'!M16,0)) -> 1141 | ... AL13: =(IF('Section Load'!AM16>0,'Section Load'!AM16,0)) -> 852 | AM13: =(IF('Water Report'!$O$7>0,'Water Report'!$O$7,0)) -> 144 | AN13: =(IF('Water Report'!$O$8>0,'Water Report'!$O$8,0)) -> 130 | AO13: =(IF('Water Report'!$O$9>0,'Water Report'!$O$9,0)) -> 105 | AP13: =(IF('Water Report'!$O$10>0,'Water Report'!$O$10,0)) -> 21 | AQ13: =(IF('Water Report'!$O$11>0,'Water Report'!$O$11,0)) -> 33 | AR13: =(IF('Water Report'!$O$13>0,'Water Report'!$O$13,0)) -> 44 | AS13: =(IF('Water Report'!$O$14>0,'Water Report'!$O$14,0)) -> 7 | AT13: =(IF('Water Report'!$O$15>0,'Water Report'!$O$15,0)) -> 9 | AU13: =(IF('Water Report'!$O$17>0,'Water Report'!$O$17,0)) -> 3 | AV13: =(IF('Water Report'!$O$18>0,'Water Report'!$O$18,0)) -> 19 | AW13: =(IF('Water Report'!$O$19>0,'Water Report'!$O$19,0)) -> 14 | AX13: =(IF('Water Report'!$O$21>0,'Water Report'!$O$21,0)) -> 109 | AY13: =(IF('Water Report'!$O$22>0,'Water Report'!$O$22,0)) -> 0 | AZ13: =(IF('Water Report'!$O$23>0,'Water Report'!$O$23,0)) -> 1 | BA13: =(IF('Water Report'!$O$14>0,'Water Report'!$O$14,0)) -> 7 | BB13: =(IF('Water Report'!$O$15>0,'Water Report'!$O$15,0)) -> 9 | BC13: =(IF('Water Report'!$O$13>0,'Water Report'!$O$13,0)) -> 44 | BD13: =(IF('Water Report'!$O$24>0,'Water Report'!$O$24,0)) -> 294 | BE13: =(IF('Water Report'!$O$25>0,'Water Report'!$O$25,0)) -> 175 | BF13: =(IF('Water Report'!$O$27>0,'Water Report'!$O$27,0)) -> 154 | BG13: =(IF('Section Load'!AN16>0,'Section Load'!AN16,0)) -> 1252 | BH13: =(IF('Section Load'!AO16>0,'Section Load'!AO16,0)) -> 300 | BI13: =(IF('Section Load'!AP16>0,'Section Load'!AP16,0)) -> 0 | BJ13: =(IF('Section Load'!AQ16>0,'Section Load'!AQ16,0)) -> 152 | BK13: =(IF('Section Load'!AR16>0,'Section Load'!AR16,0)) -> 46 | BL13: =(IF('Section Load'!AS16>0,'Section Load'!AS16,0)) -> 5 | BM13: =(IF('Section Load'!AT16>0,'Section Load'!AT16,0)) -> 749
A14: Mumbai | B14: =B13+1 -> 13 | C14: 12 | D14: 2021 | E14: =(IF('Section Load'!F17>0,'Section Load'!F17,0)) -> 3767 | F14: =(IF('Section Load'!G17>0,'Section Load'!G17,0)) -> 1431 | G14: =(IF('Section Load'!H17>0,'Section Load'!H17,0)) -> 2095 | H14: =(IF('Section Load'!I17>0,'Section Load'!I17,0)) -> 3101 | I14: =(IF('Section Load'!J17>0,'Section Load'!J17,0)) -> 5072 | J14: =(IF('Section Load'!K17>0,'Section Load'!K17,0)) -> 2771 | K14: =(IF('Section Load'!L17>0,'Section Load'!L17,0)) -> 1701 | L14: =(IF('Section Load'!M17>0,'Section Load'!M17,0)) -> 1205 | ... AL14: =(IF('Section Load'!AM17>0,'Section Load'!AM17,0)) -> 828 | AM14: =(IF('Water Report'!$P$7>0,'Water Report'!$P$7,0)) -> 146 | AN14: =(IF('Water Report'!$P$8>0,'Water Report'!$P$8,0)) -> 125 | AO14: =(IF('Water Report'!$P$9>0,'Water Report'!$P$9,0)) -> 152 | AP14: =(IF('Water Report'!$P$10>0,'Water Report'!$P$10,0)) -> 19 | AQ14: =(IF('Water Report'!$P$11>0,'Water Report'!$P$11,0)) -> 30 | AR14: =(IF('Water Report'!$P$13>0,'Water Report'!$P$13,0)) -> 46 | AS14: =(IF('Water Report'!$P$14>0,'Water Report'!$P$14,0)) -> 16 | AT14: =(IF('Water Report'!$P$15>0,'Water Report'!$P$15,0)) -> 14 | AU14: =(IF('Water Report'!$P$17>0,'Water Report'!$P$17,0)) -> 0 | AV14: =(IF('Water Report'!$P$18>0,'Water Report'!$P$18,0)) -> 19 | AW14: =(IF('Water Report'!$P$19>0,'Water Report'!$P$19,0)) -> 12 | AX14: =(IF('Water Report'!$P$21>0,'Water Report'!$P$21,0)) -> 68 | AY14: =(IF('Water Report'!$P$22>0,'Water Report'!$P$22,0)) -> 0 | AZ14: =(IF('Water Report'!$P$23>0,'Water Report'!$P$23,0)) -> 3 | BA14: =(IF('Water Report'!$P$14>0,'Water Report'!$P$14,0)) -> 16 | BB14: =(IF('Water Report'!$P$15>0,'Water Report'!$P$15,0)) -> 14 | BC14: =(IF('Water Report'!$P$13>0,'Water Report'!$P$13,0)) -> 46 | BD14: =(IF('Water Report'!$P$24>0,'Water Report'!$P$24,0)) -> 294 | BE14: =(IF('Water Report'!$P$25>0,'Water Report'!$P$25,0)) -> 231 | BF14: =(IF('Water Report'!$P$27>0,'Water Report'!$P$27,0)) -> 117 | BG14: =(IF('Section Load'!AN17>0,'Section Load'!AN17,0)) -> 1211 | BH14: =(IF('Section Load'!AO17>0,'Section Load'!AO17,0)) -> 329 | BI14: =(IF('Section Load'!AP17>0,'Section Load'!AP17,0)) -> 0 | BJ14: =(IF('Section Load'!AQ17>0,'Section Load'!AQ17,0)) -> 139 | BK14: =(IF('Section Load'!AR17>0,'Section Load'!AR17,0)) -> 66 | BL14: =(IF('Section Load'!AS17>0,'Section Load'!AS17,0)) -> 0 | BM14: =(IF('Section Load'!AT17>0,'Section Load'!AT17,0)) -> 677
A15: Mumbai | B15: =B14+1 -> 14 | C15: 12 | D15: 2021 | E15: =(IF('Section Load'!F18>0,'Section Load'!F18,0)) -> 3890 | F15: =(IF('Section Load'!G18>0,'Section Load'!G18,0)) -> 1598 | G15: =(IF('Section Load'!H18>0,'Section Load'!H18,0)) -> 2029 | H15: =(IF('Section Load'!I18>0,'Section Load'!I18,0)) -> 3022 | I15: =(IF('Section Load'!J18>0,'Section Load'!J18,0)) -> 3919 | J15: =(IF('Section Load'!K18>0,'Section Load'!K18,0)) -> 2768 | K15: =(IF('Section Load'!L18>0,'Section Load'!L18,0)) -> 1163 | L15: =(IF('Section Load'!M18>0,'Section Load'!M18,0)) -> 1164 | ... AL15: =(IF('Section Load'!AM18>0,'Section Load'!AM18,0)) -> 833 | AM15: =(IF('Water Report'!$Q$7>0,'Water Report'!$Q$7,0)) -> 143 | AN15: =(IF('Water Report'!$Q$8>0,'Water Report'!$Q$8,0)) -> 82 | AO15: =(IF('Water Report'!$Q$9>0,'Water Report'!$Q$9,0)) -> 105 | AP15: =(IF('Water Report'!$Q$10>0,'Water Report'!$Q$10,0)) -> 18 | AQ15: =(IF('Water Report'!$Q$11>0,'Water Report'!$Q$11,0)) -> 32 | AR15: =(IF('Water Report'!$Q$13>0,'Water Report'!$Q$13,0)) -> 41 | AS15: =(IF('Water Report'!$Q$14>0,'Water Report'!$Q$14,0)) -> 8 | AT15: =(IF('Water Report'!$Q$15>0,'Water Report'!$Q$15,0)) -> 9 | AU15: =(IF('Water Report'!$Q$17>0,'Water Report'!$Q$17,0)) -> 0 | AV15: =(IF('Water Report'!$Q$18>0,'Water Report'!$Q$18,0)) -> 16 | AW15: =(IF('Water Report'!$Q$19>0,'Water Report'!$Q$19,0)) -> 14 | AX15: =(IF('Water Report'!$Q$21>0,'Water Report'!$Q$21,0)) -> 55 | AY15: =(IF('Water Report'!$Q$22>0,'Water Report'!$Q$22,0)) -> 0 | AZ15: =(IF('Water Report'!$Q$23>0,'Water Report'!$Q$23,0)) -> 12 | BA15: =(IF('Water Report'!$Q$14>0,'Water Report'!$Q$14,0)) -> 8 | BB15: =(IF('Water Report'!$Q$15>0,'Water Report'!$Q$15,0)) -> 9 | BC15: =(IF('Water Report'!$Q$13>0,'Water Report'!$Q$13,0)) -> 41 | BD15: =(IF('Water Report'!$Q$24>0,'Water Report'!$Q$24,0)) -> 292 | BE15: =(IF('Water Report'!$Q$25>0,'Water Report'!$Q$25,0)) -> 172 | BF15: =(IF('Water Report'!$Q$27>0,'Water Report'!$Q$27,0)) -> 108 | BG15: =(IF('Section Load'!AN18>0,'Section Load'!AN18,0)) -> 1124 | BH15: =(IF('Section Load'!AO18>0,'Section Load'!AO18,0)) -> 321 | BI15: =(IF('Section Load'!AP18>0,'Section Load'!AP18,0)) -> 0 | BJ15: =(IF('Section Load'!AQ18>0,'Section Load'!AQ18,0)) -> 110 | BK15: =(IF('Section Load'!AR18>0,'Section Load'!AR18,0)) -> 39 | BL15: =(IF('Section Load'!AS18>0,'Section Load'!AS18,0)) -> 0 | BM15: =(IF('Section Load'!AT18>0,'Section Load'!AT18,0)) -> 654
A16: Mumbai | B16: =B15+1 -> 15 | C16: 12 | D16: 2021 | E16: =(IF('Section Load'!F19>0,'Section Load'!F19,0)) -> 3797 | F16: =(IF('Section Load'!G19>0,'Section Load'!G19,0)) -> 1543 | G16: =(IF('Section Load'!H19>0,'Section Load'!H19,0)) -> 1931 | H16: =(IF('Section Load'!I19>0,'Section Load'!I19,0)) -> 2939 | I16: =(IF('Section Load'!J19>0,'Section Load'!J19,0)) -> 5187 | J16: =(IF('Section Load'!K19>0,'Section Load'!K19,0)) -> 2748 | K16: =(IF('Section Load'!L19>0,'Section Load'!L19,0)) -> 1582 | L16: =(IF('Section Load'!M19>0,'Section Load'!M19,0)) -> 1099 | ... AL16: =(IF('Section Load'!AM19>0,'Section Load'!AM19,0)) -> 818 | AM16: =(IF('Water Report'!$R$7>0,'Water Report'!$R$7,0)) -> 106 | AN16: =(IF('Water Report'!$R$8>0,'Water Report'!$R$8,0)) -> 81 | AO16: =(IF('Water Report'!$R$9>0,'Water Report'!$R$9,0)) -> 106 | AP16: =(IF('Water Report'!$R$10>0,'Water Report'!$R$10,0)) -> 13 | AQ16: =(IF('Water Report'!$R$11>0,'Water Report'!$R$11,0)) -> 20 | AR16: =(IF('Water Report'!$R$13>0,'Water Report'!$R$13,0)) -> 38 | AS16: =(IF('Water Report'!$R$14>0,'Water Report'!$R$14,0)) -> 8 | AT16: =(IF('Water Report'!$R$15>0,'Water Report'!$R$15,0)) -> 5 | AU16: =(IF('Water Report'!$R$17>0,'Water Report'!$R$17,0)) -> 0 | AV16: =(IF('Water Report'!$R$18>0,'Water Report'!$R$18,0)) -> 19 | AW16: =(IF('Water Report'!$R$19>0,'Water Report'!$R$19,0)) -> 13 | AX16: =(IF('Water Report'!$R$21>0,'Water Report'!$R$21,0)) -> 80 | AY16: =(IF('Water Report'!$R$22>0,'Water Report'!$R$22,0)) -> 0 | AZ16: =(IF('Water Report'!$R$23>0,'Water Report'!$R$23,0)) -> 6 | BA16: =(IF('Water Report'!$R$14>0,'Water Report'!$R$14,0)) -> 8 | BB16: =(IF('Water Report'!$R$15>0,'Water Report'!$R$15,0)) -> 5 | BC16: =(IF('Water Report'!$R$13>0,'Water Report'!$R$13,0)) -> 38 | BD16: =(IF('Water Report'!$R$24>0,'Water Report'!$R$24,0)) -> 240 | BE16: =(IF('Water Report'!$R$25>0,'Water Report'!$R$25,0)) -> 152 | BF16: =(IF('Water Report'!$R$27>0,'Water Report'!$R$27,0)) -> 124 | BG16: =(IF('Section Load'!AN19>0,'Section Load'!AN19,0)) -> 1178.13 | BH16: =(IF('Section Load'!AO19>0,'Section Load'!AO19,0)) -> 322 | BI16: =(IF('Section Load'!AP19>0,'Section Load'!AP19,0)) -> 0 | BJ16: =(IF('Section Load'!AQ19>0,'Section Load'!AQ19,0)) -> 130.6 | BK16: =(IF('Section Load'!AR19>0,'Section Load'!AR19,0)) -> 45.6 | BL16: =(IF('Section Load'!AS19>0,'Section Load'!AS19,0)) -> 4.7 | BM16: =(IF('Section Load'!AT19>0,'Section Load'!AT19,0)) -> 675.23
A17: Mumbai | B17: =B16+1 -> 16 | C17: 12 | D17: 2021 | E17: =(IF('Section Load'!F20>0,'Section Load'!F20,0)) -> 3731.68 | F17: =(IF('Section Load'!G20>0,'Section Load'!G20,0)) -> 1565.33 | G17: =(IF('Section Load'!H20>0,'Section Load'!H20,0)) -> 1985.61 | H17: =(IF('Section Load'!I20>0,'Section Load'!I20,0)) -> 2949.87 | I17: =(IF('Section Load'!J20>0,'Section Load'!J20,0)) -> 5082.53 | J17: =(IF('Section Load'!K20>0,'Section Load'!K20,0)) -> 2590.2 | K17: =(IF('Section Load'!L20>0,'Section Load'!L20,0)) -> 1041.38 | L17: =(IF('Section Load'!M20>0,'Section Load'!M20,0)) -> 1204.26 | ... AL17: =(IF('Section Load'!AM20>0,'Section Load'!AM20,0)) -> 835.41 | AM17: =(IF('Water Report'!$S$7>0,'Water Report'!$S$7,0)) -> 112 | AN17: =(IF('Water Report'!$S$8>0,'Water Report'!$S$8,0)) -> 88 | AO17: =(IF('Water Report'!$S$9>0,'Water Report'!$S$9,0)) -> 93 | AP17: =(IF('Water Report'!$S$10>0,'Water Report'!$D$10,0)) -> 18 | AQ17: =(IF('Water Report'!$S$11>0,'Water Report'!$D$11,0)) -> 25 | AR17: =(IF('Water Report'!$S$13>0,'Water Report'!$D$13,0)) -> 34 | AS17: =(IF('Water Report'!$S$14>0,'Water Report'!$D$14,0)) -> 10 | AT17: =(IF('Water Report'!$S$15>0,'Water Report'!$D$15,0)) -> 6 | AU17: =(IF('Water Report'!$S$17>0,'Water Report'!$D$17,0)) -> 0 | AV17: =(IF('Water Report'!$S$18>0,'Water Report'!$D$18,0)) -> 15 | AW17: =(IF('Water Report'!$S$19>0,'Water Report'!$D$19,0)) -> 10 | AX17: =(IF('Water Report'!$S$21>0,'Water Report'!$D$21,0)) -> 63 | AY17: =(IF('Water Report'!$S$22>0,'Water Report'!$D$22,0)) -> 0 | AZ17: =(IF('Water Report'!$S$23>0,'Water Report'!$D$23,0)) -> 4 | BA17: =(IF('Water Report'!$S$14>0,'Water Report'!$D$14,0)) -> 10 | BB17: =(IF('Water Report'!$S$15>0,'Water Report'!$D$15,0)) -> 6 | BC17: =(IF('Water Report'!$S$13>0,'Water Report'!$D$13,0)) -> 34 | BD17: =(IF('Water Report'!$S$24>0,'Water Report'!$D$24,0)) -> 212 | BE17: =(IF('Water Report'!$S$25>0,'Water Report'!$D$25,0)) -> 145 | BF17: =(IF('Water Report'!$S$27>0,'Water Report'!$D$27,0)) -> 101 | BG17: =(IF('Section Load'!AN20>0,'Section Load'!AN20,0)) -> 1154.87 | BH17: =(IF('Section Load'!AO20>0,'Section Load'!AO20,0)) -> 330.41 | BI17: =(IF('Section Load'!AP20>0,'Section Load'!AP20,0)) -> 0 | BJ17: =(IF('Section Load'!AQ20>0,'Section Load'!AQ20,0)) -> 136.82 | BK17: =(IF('Section Load'!AR20>0,'Section Load'!AR20,0)) -> 45.5 | BL17: =(IF('Section Load'!AS20>0,'Section Load'!AS20,0)) -> 2.1 | BM17: =(IF('Section Load'!AT20>0,'Section Load'!AT20,0)) -> 640.04
A18: Mumbai | B18: =B17+1 -> 17 | C18: 12 | D18: 2021 | E18: =(IF('Section Load'!F21>0,'Section Load'!F21,0)) -> 3551.81 | F18: =(IF('Section Load'!G21>0,'Section Load'!G21,0)) -> 1583.54 | G18: =(IF('Section Load'!H21>0,'Section Load'!H21,0)) -> 2168.16 | H18: =(IF('Section Load'!I21>0,'Section Load'!I21,0)) -> 3084.48 | I18: =(IF('Section Load'!J21>0,'Section Load'!J21,0)) -> 5645.21 | J18: =(IF('Section Load'!K21>0,'Section Load'!K21,0)) -> 2782.73 | K18: =(IF('Section Load'!L21>0,'Section Load'!L21,0)) -> 1241.5 | L18: =(IF('Section Load'!M21>0,'Section Load'!M21,0)) -> 1285.63 | ... AL18: =(IF('Section Load'!AM21>0,'Section Load'!AM21,0)) -> 869.2 | AM18: =(IF('Water Report'!$T$7>0,'Water Report'!$T$7,0)) -> 126 | AN18: =(IF('Water Report'!$T$8>0,'Water Report'!$T$8,0)) -> 120 | AO18: =(IF('Water Report'!$T$9>0,'Water Report'!$T$9,0)) -> 111 | AP18: =(IF('Water Report'!$T$10>0,'Water Report'!$T$10,0)) -> 19 | AQ18: =(IF('Water Report'!$T$11>0,'Water Report'!$T$11,0)) -> 31 | AR18: =(IF('Water Report'!$T$13>0,'Water Report'!$T$13,0)) -> 49 | AS18: =(IF('Water Report'!$T$14>0,'Water Report'!$T$14,0)) -> 8 | AT18: =(IF('Water Report'!$T$15>0,'Water Report'!$T$15,0)) -> 13 | AU18: =(IF('Water Report'!$T$17>0,'Water Report'!$T$17,0)) -> 0 | AV18: =(IF('Water Report'!$T$18>0,'Water Report'!$T$18,0)) -> 17 | AW18: =(IF('Water Report'!$T$19>0,'Water Report'!$T$19,0)) -> 12 | AX18: =(IF('Water Report'!$T$21>0,'Water Report'!$T$21,0)) -> 115 | AY18: =(IF('Water Report'!$T$22>0,'Water Report'!$T$22,0)) -> 13 | AZ18: =(IF('Water Report'!$T$23>0,'Water Report'!$T$23,0)) -> 2 | BA18: =(IF('Water Report'!$T$14>0,'Water Report'!$T$14,0)) -> 8 | BB18: =(IF('Water Report'!$T$15>0,'Water Report'!$T$15,0)) -> 13 | BC18: =(IF('Water Report'!$T$13>0,'Water Report'!$T$13,0)) -> 49 | BD18: =(IF('Water Report'!$T$24>0,'Water Report'!$T$24,0)) -> 234 | BE18: =(IF('Water Report'!$T$25>0,'Water Report'!$T$25,0)) -> 182 | BF18: =(IF('Water Report'!$T$27>0,'Water Report'!$T$27,0)) -> 166 | BG18: =(IF('Section Load'!AN21>0,'Section Load'!AN21,0)) -> 1138.822 | BH18: =(IF('Section Load'!AO21>0,'Section Load'!AO21,0)) -> 317.42 | BI18: =(IF('Section Load'!AP21>0,'Section Load'!AP21,0)) -> 0 | BJ18: =(IF('Section Load'!AQ21>0,'Section Load'!AQ21,0)) -> 123.58 | BK18: =(IF('Section Load'!AR21>0,'Section Load'!AR21,0)) -> 52.4 | BL18: =(IF('Section Load'!AS21>0,'Section Load'!AS21,0)) -> 2.2 | BM18: =(IF('Section Load'!AT21>0,'Section Load'!AT21,0)) -> 643.222
A19: Mumbai | B19: =B18+1 -> 18 | C19: 12 | D19: 2021 | E19: =(IF('Section Load'!F22>0,'Section Load'!F22,0)) -> 3379.97 | F19: =(IF('Section Load'!G22>0,'Section Load'!G22,0)) -> 1564.6 | G19: =(IF('Section Load'!H22>0,'Section Load'!H22,0)) -> 2082.22 | H19: =(IF('Section Load'!I22>0,'Section Load'!I22,0)) -> 2894.04 | I19: =(IF('Section Load'!J22>0,'Section Load'!J22,0)) -> 5311.51 | J19: =(IF('Section Load'!K22>0,'Section Load'!K22,0)) -> 2787.94 | K19: =(IF('Section Load'!L22>0,'Section Load'!L22,0)) -> 1452.43 | L19: =(IF('Section Load'!M22>0,'Section Load'!M22,0)) -> 1224.04 | ... AL19: =(IF('Section Load'!AM22>0,'Section Load'!AM22,0)) -> 832.87 | AM19: =(IF('Water Report'!$U$7>0,'Water Report'!$U$7,0)) -> 134 | AN19: =(IF('Water Report'!$U$8>0,'Water Report'!$U$8,0)) -> 108 | AO19: =(IF('Water Report'!$U$9>0,'Water Report'!$U$9,0)) -> 125 | AP19: =(IF('Water Report'!$U$10>0,'Water Report'!$U$10,0)) -> 21 | AQ19: =(IF('Water Report'!$U$11>0,'Water Report'!$U$11,0)) -> 30 | AR19: =(IF('Water Report'!$U$13>0,'Water Report'!$U$13,0)) -> 56 | AS19: =(IF('Water Report'!$U$14>0,'Water Report'!$U$14,0)) -> 9 | AT19: =(IF('Water Report'!$U$15>0,'Water Report'!$U$15,0)) -> 19 | AU19: =(IF('Water Report'!$U$17>0,'Water Report'!$U$17,0)) -> 0 | AV19: =(IF('Water Report'!$U$18>0,'Water Report'!$U$18,0)) -> 14 | AW19: =(IF('Water Report'!$U$19>0,'Water Report'!$U$19,0)) -> 13 | AX19: =(IF('Water Report'!$U$21>0,'Water Report'!$U$21,0)) -> 41 | AY19: =(IF('Water Report'!$U$22>0,'Water Report'!$U$22,0)) -> 14 | AZ19: =(IF('Water Report'!$U$23>0,'Water Report'!$U$23,0)) -> 11 | BA19: =(IF('Water Report'!$U$14>0,'Water Report'!$U$14,0)) -> 9 | BB19: =(IF('Water Report'!$U$15>0,'Water Report'!$U$15,0)) -> 19 | BC19: =(IF('Water Report'!$U$13>0,'Water Report'!$U$13,0)) -> 56 | BD19: =(IF('Water Report'!$U$24>0,'Water Report'!$U$24,0)) -> 273 | BE19: =(IF('Water Report'!$U$25>0,'Water Report'!$U$25,0)) -> 204 | BF19: =(IF('Water Report'!$U$27>0,'Water Report'!$U$27,0)) -> 108 | BG19: =(IF('Section Load'!AN22>0,'Section Load'!AN22,0)) -> 1215.284 | BH19: =(IF('Section Load'!AO22>0,'Section Load'!AO22,0)) -> 305.65 | BI19: =(IF('Section Load'!AP22>0,'Section Load'!AP22,0)) -> 0 | BJ19: =(IF('Section Load'!AQ22>0,'Section Load'!AQ22,0)) -> 134.6 | BK19: =(IF('Section Load'!AR22>0,'Section Load'!AR22,0)) -> 55.2 | BL19: =(IF('Section Load'!AS22>0,'Section Load'!AS22,0)) -> 1.9 | BM19: =(IF('Section Load'!AT22>0,'Section Load'!AT22,0)) -> 717.934
A20: Mumbai | B20: =B19+1 -> 19 | C20: 12 | D20: 2021 | E20: =(IF('Section Load'!F23>0,'Section Load'!F23,0)) -> 3420.04 | F20: =(IF('Section Load'!G23>0,'Section Load'!G23,0)) -> 1585.36 | G20: =(IF('Section Load'!H23>0,'Section Load'!H23,0)) -> 2024.94 | H20: =(IF('Section Load'!I23>0,'Section Load'!I23,0)) -> 3077.56 | I20: =(IF('Section Load'!J23>0,'Section Load'!J23,0)) -> 5180.54 | J20: =(IF('Section Load'!K23>0,'Section Load'!K23,0)) -> 2794.76 | K20: =(IF('Section Load'!L23>0,'Section Load'!L23,0)) -> 1631.18 | L20: =(IF('Section Load'!M23>0,'Section Load'!M23,0)) -> 1132.07 | ... AL20: =(IF('Section Load'!AM23>0,'Section Load'!AM23,0)) -> 858.88 | AM20: =(IF('Water Report'!$V$7>0,'Water Report'!$V$7,0)) -> 130 | AN20: =(IF('Water Report'!$V$8>0,'Water Report'!$V$8,0)) -> 86 | AO20: =(IF('Water Report'!$V$9>0,'Water Report'!$V$9,0)) -> 117 | AP20: =(IF('Water Report'!$V$10>0,'Water Report'!$V$10,0)) -> 23 | AQ20: =(IF('Water Report'!$V$11>0,'Water Report'!$V$11,0)) -> 34 | AR20: =(IF('Water Report'!$V$13>0,'Water Report'!$V$13,0)) -> 0 | AS20: =(IF('Water Report'!$V$14>0,'Water Report'!$V$14,0)) -> 28 | AT20: =(IF('Water Report'!$V$15>0,'Water Report'!$V$15,0)) -> 12 | AU20: =(IF('Water Report'!$V$17>0,'Water Report'!$V$17,0)) -> 0 | AV20: =(IF('Water Report'!$V$18>0,'Water Report'!$V$18,0)) -> 15 | AW20: =(IF('Water Report'!$V$19>0,'Water Report'!$V$19,0)) -> 11 | AX20: =(IF('Water Report'!$V$21>0,'Water Report'!$V$21,0)) -> 74 | AY20: =(IF('Water Report'!$V$22>0,'Water Report'!$V$22,0)) -> 0 | AZ20: =(IF('Water Report'!$V$23>0,'Water Report'!$V$23,0)) -> 1 | BA20: =(IF('Water Report'!$V$14>0,'Water Report'!$V$14,0)) -> 28 | BB20: =(IF('Water Report'!$V$15>0,'Water Report'!$V$15,0)) -> 12 | BC20: =(IF('Water Report'!$V$13>0,'Water Report'!$V$13,0)) -> 0 | BD20: =(IF('Water Report'!$V$24>0,'Water Report'!$V$24,0)) -> 273 | BE20: =(IF('Water Report'!$V$25>0,'Water Report'!$V$25,0)) -> 214 | BF20: =(IF('Water Report'!$V$27>0,'Water Report'!$V$27,0)) -> 75 | BG20: =(IF('Section Load'!AN23>0,'Section Load'!AN23,0)) -> 1150.294 | BH20: =(IF('Section Load'!AO23>0,'Section Load'!AO23,0)) -> 312.83 | BI20: =(IF('Section Load'!AP23>0,'Section Load'!AP23,0)) -> 0 | BJ20: =(IF('Section Load'!AQ23>0,'Section Load'!AQ23,0)) -> 149.6 | BK20: =(IF('Section Load'!AR23>0,'Section Load'!AR23,0)) -> 69.6 | BL20: =(IF('Section Load'!AS23>0,'Section Load'!AS23,0)) -> 1.8 | BM20: =(IF('Section Load'!AT23>0,'Section Load'!AT23,0)) -> 616.464
A21: Mumbai | B21: =B20+1 -> 20 | C21: 12 | D21: 2021 | E21: =(IF('Section Load'!F24>0,'Section Load'!F24,0)) -> 3485.58 | F21: =(IF('Section Load'!G24>0,'Section Load'!G24,0)) -> 1629.82 | G21: =(IF('Section Load'!H24>0,'Section Load'!H24,0)) -> 1975.1 | H21: =(IF('Section Load'!I24>0,'Section Load'!I24,0)) -> 2849.68 | I21: =(IF('Section Load'!J24>0,'Section Load'!J24,0)) -> 4532.26 | J21: =(IF('Section Load'!K24>0,'Section Load'!K24,0)) -> 2718.96 | K21: =(IF('Section Load'!L24>0,'Section Load'!L24,0)) -> 1114.71 | L21: =(IF('Section Load'!M24>0,'Section Load'!M24,0)) -> 926.36 | ... AL21: =(IF('Section Load'!AM24>0,'Section Load'!AM24,0)) -> 846.91 | AM21: =(IF('Water Report'!$W$7>0,'Water Report'!$W$7,0)) -> 124 | AN21: =(IF('Water Report'!$W$8>0,'Water Report'!$W$8,0)) -> 119 | AO21: =(IF('Water Report'!$W$9>0,'Water Report'!$W$9,0)) -> 77 | AP21: =(IF('Water Report'!$W$10>0,'Water Report'!$W$10,0)) -> 17 | AQ21: =(IF('Water Report'!$W$11>0,'Water Report'!$W$11,0)) -> 26 | AR21: =(IF('Water Report'!$W$13>0,'Water Report'!$W$13,0)) -> 68 | AS21: =(IF('Water Report'!$W$14>0,'Water Report'!$W$14,0)) -> 7 | AT21: =(IF('Water Report'!$W$15>0,'Water Report'!$W$15,0)) -> 9 | AU21: =(IF('Water Report'!$W$17>0,'Water Report'!$W$17,0)) -> 0 | AV21: =(IF('Water Report'!$W$18>0,'Water Report'!$W$18,0)) -> 17 | AW21: =(IF('Water Report'!$W$19>0,'Water Report'!$W$19,0)) -> 12 | AX21: =(IF('Water Report'!$W$21>0,'Water Report'!$W$21,0)) -> 67 | AY21: =(IF('Water Report'!$W$22>0,'Water Report'!$W$22,0)) -> 0 | AZ21: =(IF('Water Report'!$W$23>0,'Water Report'!$W$23,0)) -> 1 | BA21: =(IF('Water Report'!$W$14>0,'Water Report'!$W$14,0)) -> 7 | BB21: =(IF('Water Report'!$W$15>0,'Water Report'!$W$15,0)) -> 9 | BC21: =(IF('Water Report'!$W$13>0,'Water Report'!$W$13,0)) -> 68 | BD21: =(IF('Water Report'!$W$24>0,'Water Report'!$W$24,0)) -> 273 | BE21: =(IF('Water Report'!$W$25>0,'Water Report'!$W$25,0)) -> 136 | BF21: =(IF('Water Report'!$W$27>0,'Water Report'!$W$27,0)) -> 136 | BG21: =(IF('Section Load'!AN24>0,'Section Load'!AN24,0)) -> 1154.41 | BH21: =(IF('Section Load'!AO24>0,'Section Load'!AO24,0)) -> 318.69 | BI21: =(IF('Section Load'!AP24>0,'Section Load'!AP24,0)) -> 0 | BJ21: =(IF('Section Load'!AQ24>0,'Section Load'!AQ24,0)) -> 127.05 | BK21: =(IF('Section Load'!AR24>0,'Section Load'!AR24,0)) -> 46.7 | BL21: =(IF('Section Load'!AS24>0,'Section Load'!AS24,0)) -> 1.3 | BM21: =(IF('Section Load'!AT24>0,'Section Load'!AT24,0)) -> 660.67
A22: Mumbai | B22: =B21+1 -> 21 | C22: 12 | D22: 2021 | E22: =(IF('Section Load'!F25>0,'Section Load'!F25,0)) -> 3149.21 | F22: =(IF('Section Load'!G25>0,'Section Load'!G25,0)) -> 1625.5 | G22: =(IF('Section Load'!H25>0,'Section Load'!H25,0)) -> 1893.84 | H22: =(IF('Section Load'!I25>0,'Section Load'!I25,0)) -> 2810.6 | I22: =(IF('Section Load'!J25>0,'Section Load'!J25,0)) -> 4666.08 | J22: =(IF('Section Load'!K25>0,'Section Load'!K25,0)) -> 2692.16 | K22: =(IF('Section Load'!L25>0,'Section Load'!L25,0)) -> 1116.68 | L22: =(IF('Section Load'!M25>0,'Section Load'!M25,0)) -> 1038.03 | ... AL22: =(IF('Section Load'!AM25>0,'Section Load'!AM25,0)) -> 706.69 | AM22: =(IF('Water Report'!$X$7>0,'Water Report'!$X$7,0)) -> 117 | AN22: =(IF('Water Report'!$X$8>0,'Water Report'!$X$8,0)) -> 72 | AO22: =(IF('Water Report'!$X$9>0,'Water Report'!$X$9,0)) -> 97 | AP22: =(IF('Water Report'!$X$10>0,'Water Report'!$X$10,0)) -> 17 | AQ22: =(IF('Water Report'!$X$11>0,'Water Report'!$X$11,0)) -> 27 | AR22: =(IF('Water Report'!$X$13>0,'Water Report'!$X$13,0)) -> 35 | AS22: =(IF('Water Report'!$X$14>0,'Water Report'!$X$14,0)) -> 9 | AT22: =(IF('Water Report'!$X$15>0,'Water Report'!$X$15,0)) -> 8 | AU22: =(IF('Water Report'!$X$17>0,'Water Report'!$X$17,0)) -> 0 | AV22: =(IF('Water Report'!$X$18>0,'Water Report'!$X$18,0)) -> 16 | AW22: =(IF('Water Report'!$X$19>0,'Water Report'!$X$19,0)) -> 13 | AX22: =(IF('Water Report'!$X$21>0,'Water Report'!$X$21,0)) -> 60 | AY22: =(IF('Water Report'!$X$22>0,'Water Report'!$X$22,0)) -> 0 | AZ22: =(IF('Water Report'!$X$23>0,'Water Report'!$X$23,0)) -> 11 | BA22: =(IF('Water Report'!$X$14>0,'Water Report'!$X$14,0)) -> 9 | BB22: =(IF('Water Report'!$X$15>0,'Water Report'!$X$15,0)) -> 8 | BC22: =(IF('Water Report'!$X$13>0,'Water Report'!$X$13,0)) -> 35 | BD22: =(IF('Water Report'!$X$24>0,'Water Report'!$X$24,0)) -> 271 | BE22: =(IF('Water Report'!$X$25>0,'Water Report'!$X$25,0)) -> 158 | BF22: =(IF('Water Report'!$X$27>0,'Water Report'!$X$27,0)) -> 106 | BG22: =(IF('Section Load'!AN25>0,'Section Load'!AN25,0)) -> 1115.57 | BH22: =(IF('Section Load'!AO25>0,'Section Load'!AO25,0)) -> 321.21 | BI22: =(IF('Section Load'!AP25>0,'Section Load'!AP25,0)) -> 0 | BJ22: =(IF('Section Load'!AQ25>0,'Section Load'!AQ25,0)) -> 111.48 | BK22: =(IF('Section Load'!AR25>0,'Section Load'!AR25,0)) -> 55 | BL22: =(IF('Section Load'!AS25>0,'Section Load'!AS25,0)) -> 1 | BM22: =(IF('Section Load'!AT25>0,'Section Load'!AT25,0)) -> 626.88
