Workbook

Sheet TOTAL
A1: Site Name | B1: Day | C1: Month | D1: Year | E1: Total Electricity Kwh | F1: Electricity Tariff ($/Kwh) | G1: LPG (Kg) | H1: LPG $/Kg | I1: Water Utility Supply (m3) m3 | J1: Water Utility Supply (m3) $/m3 | K1: Room Nights | L1: Food Covers
A2: Maldives at Landaa Giraavaru | B2: 1 | C2: 12 | D2: 2021 | E2: ='Maldives at LG Daily'!D5 -> 3140352 | F2: 0.93 | G2: ='Maldives at LG Daily'!F5 -> 225 | H2: 1.24 | I2: ='Maldives at LG Daily'!H5 -> 414 | J2: 2.16 | K2: ='Maldives at LG Daily'!I5 -> 37.9 | L2: ='Maldives at LG Daily'!J5 -> 231
A3: Maldives at Landaa Giraavaru | B3: =B2+1 -> 2 | C3: 12 | D3: 2021 | E3: ='Maldives at LG Daily'!D6 -> 26010 | F3: 0.93 | G3: ='Maldives at LG Daily'!F6 -> 0 | H3: 1.24 | I3: ='Maldives at LG Daily'!H6 -> 369 | J3: 2.16 | K3: ='Maldives at LG Daily'!I6 -> 44.7 | L3: ='Maldives at LG Daily'!J6 -> 282
A4: Maldives at Landaa Giraavaru | B4: =B3+1 -> 3 | C4: 12 | D4: 2021 | E4: ='Maldives at LG Daily'!D7 -> 26063 | F4: 0.93 | G4: ='Maldives at LG Daily'!F7 -> 45 | H4: 1.24 | I4: ='Maldives at LG Daily'!H7 -> 438 | J4: 2.16 | K4: ='Maldives at LG Daily'!I7 -> 40.8 | L4: ='Maldives at LG Daily'!J7 -> 289
A5: Maldives at Landaa Giraavaru | B5: =B4+1 -> 4 | C5: 12 | D5: 2021 | E5: ='Maldives at LG Daily'!D8 -> 27067 | F5: 0.93 | G5: ='Maldives at LG Daily'!F8 -> 0 | H5: 1.24 | I5: ='Maldives at LG Daily'!H8 -> 427 | J5: 2.16 | K5: ='Maldives at LG Daily'!I8 -> 36.9 | L5: ='Maldives at LG Daily'!J8 -> 227
A6: Maldives at Landaa Giraavaru | B6: =B5+1 -> 5 | C6: 12 | D6: 2021 | E6: ='Maldives at LG Daily'!D9 -> 25673 | F6: 0.93 | G6: ='Maldives at LG Daily'!F9 -> 0 | H6: 1.24 | I6: ='Maldives at LG Daily'!H9 -> 423 | J6: 2.16 | K6: ='Maldives at LG Daily'!I9 -> 28.2 | L6: ='Maldives at LG Daily'!J9 -> 200
A7: Maldives at Landaa Giraavaru | B7: =B6+1 -> 6 | C7: 12 | D7: 2021 | E7: ='Maldives at LG Daily'!D10 -> 26011 | F7: 0.93 | G7: ='Maldives at LG Daily'!F10 -> 0 | H7: 1.24 | I7: ='Maldives at LG Daily'!H10 -> 347 | J7: 2.16 | K7: ='Maldives at LG Daily'!I10 -> 28.2 | L7: ='Maldives at LG Daily'!J10 -> 192
A8: Maldives at Landaa Giraavaru | B8: =B7+1 -> 7 | C8: 12 | D8: 2021 | E8: ='Maldives at LG Daily'!D11 -> 25920 | F8: 0.93 | G8: ='Maldives at LG Daily'!F11 -> 45 | H8: 1.24 | I8: ='Maldives at LG Daily'!H11 -> 413 | J8: 2.16 | K8: ='Maldives at LG Daily'!I11 -> 27.2 | L8: ='Maldives at LG Daily'!J11 -> 204
A9: Maldives at Landaa Giraavaru | B9: =B8+1 -> 8 | C9: 12 | D9: 2021 | E9: ='Maldives at LG Daily'!D12 -> 27545 | F9: 0.93 | G9: ='Maldives at LG Daily'!F12 -> 0 | H9: 1.24 | I9: ='Maldives at LG Daily'!H12 -> 417 | J9: 2.16 | K9: ='Maldives at LG Daily'!I12 -> 27.2 | L9: ='Maldives at LG Daily'!J12 -> 206
A10: Maldives at Landaa Giraavaru | B10: =B9+1 -> 9 | C10: 12 | D10: 2021 | E10: ='Maldives at LG Daily'!D13 -> 25266 | F10: 0.93 | G10: ='Maldives at LG Daily'!F13 -> 0 | H10: 1.24 | I10: ='Maldives at LG Daily'!H13 -> 434 | J10: 2.16 | K10: ='Maldives at LG Daily'!I13 -> 27.2 | L10: ='Maldives at LG Daily'!J13 -> 206
A11: Maldives at Landaa Giraavaru | B11: =B10+1 -> 10 | C11: 12 | D11: 2021 | E11: ='Maldives at LG Daily'!D14 -> 25058 | F11: 0.93 | G11: ='Maldives at LG Daily'!F14 -> 0 | H11: 1.24 | I11: ='Maldives at LG Daily'!H14 -> 430 | J11: 2.16 | K11: ='Maldives at LG Daily'!I14 -> 21 | L11: ='Maldives at LG Daily'!J14 -> 161
A12: Maldives at Landaa Giraavaru | B12: =B11+1 -> 11 | C12: 12 | D12: 2021 | E12: ='Maldives at LG Daily'!D15 -> 27209 | F12: 0.93 | G12: ='Maldives at LG Daily'!F15 -> 45 | H12: 1.24 | I12: ='Maldives at LG Daily'!H15 -> 419 | J12: 2.16 | K12: ='Maldives at LG Daily'!I15 -> 25.2 | L12: ='Maldives at LG Daily'!J15 -> 195
A13: Maldives at Landaa Giraavaru | B13: =B12+1 -> 12 | C13: 12 | D13: 2021 | E13: ='Maldives at LG Daily'!D16 -> 26285 | F13: 0.93 | G13: ='Maldives at LG Daily'!F16 -> 0 | H13: 1.24 | I13: ='Maldives at LG Daily'!H16 -> 415 | J13: 2.16 | K13: ='Maldives at LG Daily'!I16 -> 29.1 | L13: ='Maldives at LG Daily'!J16 -> 232
A14: Maldives at Landaa Giraavaru | B14: =B13+1 -> 13 | C14: 12 | D14: 2021 | E14: ='Maldives at LG Daily'!D17 -> 25089 | F14: 0.93 | G14: ='Maldives at LG Daily'!F17 -> 0 | H14: 1.24 | I14: ='Maldives at LG Daily'!H17 -> 413 | J14: 2.16 | K14: ='Maldives at LG Daily'!I17 -> 35.9 | L14: ='Maldives at LG Daily'!J17 -> 279
... A30: Maldives at Landaa Giraavaru | B30: =B29+1 -> 29 | C30: 12 | D30: 2021 | E30: ='Maldives at LG Daily'!D33 -> 0 | F30: 0.93 | G30: ='Maldives at LG Daily'!F33 -> 45 | H30: 1.24 | I30: ='Maldives at LG Daily'!H33 -> 0 | J30: 2.16 | K30: ='Maldives at LG Daily'!I33 -> 0 | L30: ='Maldives at LG Daily'!J33 -> 0
A31: Maldives at Landaa Giraavaru | B31: 30 | C31: 12 | D31: 2021 | E31: ='Maldives at LG Daily'!D34 -> 0 | F31: 0.93 | G31: ='Maldives at LG Daily'!F34 -> 0 | H31: 1.24 | I31: ='Maldives at LG Daily'!H34 -> 0 | J31: 2.16 | K31: ='Maldives at LG Daily'!I34 -> 0 | L31: ='Maldives at LG Daily'!J34 -> 0
A32: Maldives at Landaa Giraavaru | B32: 31 | C32: 12 | D32: 2021 | E32: ='Maldives at LG Daily'!D35 -> 0 | F32: 0.93 | G32: ='Maldives at LG Daily'!F35 -> 0 | H32: 1.24 | I32: ='Maldives at LG Daily'!H35 -> 0 | J32: 2.16 | K32: ='Maldives at LG Daily'!I35 -> 0 | L32: ='Maldives at LG Daily'!J35 -> 0

Sheet Maldives at LG Daily
A2: Days | C2: Electricity Meter (KWh) | E2: Gas Kg | G2: Water m3
A3: Date | C3: Reading KWH | D3: Difference KWH | E3: Reading Kg | F3: Difference Kg | G3: Reading m³ | H3: Daily Consumption m³ | I3: ROOM NIGHTS | J3: Total Food Covers
A4: 44530 | C4: ='[1]Maldives at LG Daily'!$C$35 -> 92090395 | D4: 26752 | E4: ='Gas-2'!G5 -> 0 | F4: 90 | G4: =SUM(WATER!G6,WATER!L6,WATER!Q6,WATER!B6) -> 1028310 | H4: 423
A5: =A4+1 -> 44531 | C5: =SUM('GENSET #1'!C10+'GENSET #2'!C10+'GENSET #3'!C10+'GENSET #4'!C10+'GENSET #5'!C10) -> 95230747 | D5: =IF((C5-C4<0), "0",C5-C4) -> 3140352 | E5: ='Gas-2'!G6 -> 225 | F5: =IF((E5-E4<0), "0",E5-E4) -> 225 | G5: =SUM(WATER!C6,WATER!H6,WATER!M6,WATER!R6) -> 1028724 | H5: =IF((G5-G4<0), "0",G5-G4) -> 414 | I5: 37.9 | J5: 231
A6: =A5+1 -> 44532 | C6: =SUM('GENSET #1'!C11+'GENSET #2'!C11+'GENSET #3'!C11+'GENSET #4'!C11+'GENSET #5'!C11) -> 95256757 | D6: =IF((C6-C5<0), "0",C6-C5) -> 26010 | E6: ='Gas-2'!G7 -> 225 | F6: =IF((E6-E5<0), "0",E6-E5) -> 0 | G6: =SUM(WATER!C7,WATER!H7,WATER!M7,WATER!R7) -> 1029093 | H6: =IF((G6-G5<0), "0",G6-G5) -> 369 | I6: 44.7 | J6: 282
A7: =A6+1 -> 44533 | C7: =SUM('GENSET #1'!C12+'GENSET #2'!C12+'GENSET #3'!C12+'GENSET #4'!C12+'GENSET #5'!C12) -> 95282820 | D7: =IF((C7-C6<0), "0",C7-C6) -> 26063 | E7: ='Gas-2'!G8 -> 270 | F7: =IF((E7-E6<0), "0",E7-E6) -> 45 | G7: =SUM(WATER!C8,WATER!H8,WATER!M8,WATER!R8) -> 1029531 | H7: =IF((G7-G6<0), "0",G7-G6) -> 438 | I7: 40.8 | J7: 289
A8: =A7+1 -> 44534 | C8: =SUM('GENSET #1'!C13+'GENSET #2'!C13+'GENSET #3'!C13+'GENSET #4'!C13+'GENSET #5'!C13) -> 95309887 | D8: =IF((C8-C7<0), "0",C8-C7) -> 27067 | E8: ='Gas-2'!G9 -> 270 | F8: =IF((E8-E7<0), "0",E8-E7) -> 0 | G8: =SUM(WATER!C9,WATER!H9,WATER!M9,WATER!R9) -> 1029958 | H8: =IF((G8-G7<0), "0",G8-G7) -> 427 | I8: 36.9 | J8: 227
A9: =A8+1 -> 44535 | C9: =SUM('GENSET #1'!C14+'GENSET #2'!C14+'GENSET #3'!C14+'GENSET #4'!C14+'GENSET #5'!C14) -> 95335560 | D9: =IF((C9-C8<0), "0",C9-C8) -> 25673 | E9: ='Gas-2'!G10 -> 225 | F9: =IF((E9-E8<0), "0",E9-E8) -> 0 | G9: =SUM(WATER!C10,WATER!H10,WATER!M10,WATER!R10) -> 1030381 | H9: =IF((G9-G8<0), "0",G9-G8) -> 423 | I9: 28.2 | J9: 200
A10: =A9+1 -> 44536 | C10: =SUM('GENSET #1'!C15+'GENSET #2'!C15+'GENSET #3'!C15+'GENSET #4'!C15+'GENSET #5'!C15) -> 95361571 | D10: =IF((C10-C9<0), "0",C10-C9) -> 26011 | E10: ='Gas-2'!G11 -> 225 | F10: =IF((E10-E9<0), "0",E10-E9) -> 0 | G10: =SUM(WATER!C11,WATER!H11,WATER!M11,WATER!R11) -> 1030728 | H10: =IF((G10-G9<0), "0",G10-G9) -> 347 | I10: 28.2 | J10: 192
A11: =A10+1 -> 44537 | C11: =SUM('GENSET #1'!C16+'GENSET #2'!C16+'GENSET #3'!C16+'GENSET #4'!C16+'GENSET #5'!C16) -> 95387491 | D11: =IF((C11-C10<0), "0",C11-C10) -> 25920 | E11: ='Gas-2'!G12 -> 270 | F11: =IF((E11-E10<0), "0",E11-E10) -> 45 | G11: =SUM(WATER!C12,WATER!H12,WATER!M12,WATER!R12) -> 1031141 | H11: =IF((G11-G10<0), "0",G11-G10) -> 413 | I11: 27.2 | J11: 204
A12: =A11+1 -> 44538 | C12: =SUM('GENSET #1'!C17+'GENSET #2'!C17+'GENSET #3'!C17+'GENSET #4'!C17+'GENSET #5'!C17) -> 95415036 | D12: =IF((C12-C11<0), "0",C12-C11) -> 27545 | E12: ='Gas-2'!G13 -> 270 | F12: =IF((E12-E11<0), "0",E12-E11) -> 0 | G12: =SUM(WATER!C13,WATER!H13,WATER!M13,WATER!R13) -> 1031558 | H12: =IF((G12-G11<0), "0",G12-G11) -> 417 | I12: 27.2 | J12: 206
A13: =A12+1 -> 44539 | C13: =SUM('GENSET #1'!C18+'GENSET #2'!C18+'GENSET #3'!C18+'GENSET #4'!C18+'GENSET #5'!C18) -> 95440302 | D13: =IF((C13-C12<0), "0",C13-C12) -> 25266 | E13: ='Gas-2'!G14 -> 225 | F13: =IF((E13-E12<0), "0",E13-E12) -> 0 | G13: =SUM(WATER!C14,WATER!H14,WATER!M14,WATER!R14) -> 1031992 | H13: =IF((G13-G12<0), "0",G13-G12) -> 434 | I13: 27.2 | J13: 206
A14: =A13+1 -> 44540 | C14: =SUM('GENSET #1'!C19+'GENSET #2'!C19+'GENSET #3'!C19+'GENSET #4'!C19+'GENSET #5'!C19) -> 95465360 | D14: =IF((C14-C13<0), "0",C14-C13) -> 25058 | E14: ='Gas-2'!G15 -> 225 | F14: =IF((E14-E13<0), "0",E14-E13) -> 0 | G14: =SUM(WATER!C15,WATER!H15,WATER!M15,WATER!R15) -> 1032422 | H14: =IF((G14-G13<0), "0",G14-G13) -> 430 | I14: 21 | J14: 161
A15: =A14+1 -> 44541 | C15: =SUM('GENSET #1'!C20+'GENSET #2'!C20+'GENSET #3'!C20+'GENSET #4'!C20+'GENSET #5'!C20) -> 95492569 | D15: =IF((C15-C14<0), "0",C15-C14) -> 27209 | E15: ='Gas-2'!G16 -> 270 | F15: =IF((E15-E14<0), "0",E15-E14) -> 45 | G15: =SUM(WATER!C16,WATER!H16,WATER!M16,WATER!R16) -> 1032841 | H15: =IF((G15-G14<0), "0",G15-G14) -> 419 | I15: 25.2 | J15: 195
A16: =A15+1 -> 44542 | C16: =SUM('GENSET #1'!C21+'GENSET #2'!C21+'GENSET #3'!C21+'GENSET #4'!C21+'GENSET #5'!C21) -> 95518854 | D16: =IF((C16-C15<0), "0",C16-C15) -> 26285 | E16: ='Gas-2'!G17 -> 225 | F16: =IF((E16-E15<0), "0",E16-E15) -> 0 | G16: =SUM(WATER!C17,WATER!H17,WATER!M17,WATER!R17) -> 1033256 | H16: =IF((G16-G15<0), "0",G16-G15) -> 415 | I16: 29.1 | J16: 232
... A29: =A28+1 -> 44555 | C29: =SUM('GENSET #1'!C34+'GENSET #2'!C34+'GENSET #3'!C34+'GENSET #4'!C34+'GENSET #5'!C34) -> 95889373 | D29: =IF((C29-C28<0), "0",C29-C28) -> 29439 | E29: ='Gas-2'!G30 -> 270 | F29: =IF((E29-E28<0), "0",E29-E28) -> 45 | G29: =SUM(WATER!C30,WATER!H30,WATER!M30,WATER!R30) -> 1038817 | H29: =IF((G29-G28<0), "0",G29-G28) -> 459 | I29: 66 | J29: 555
A30: =A29+1 -> 44556 | C30: =SUM('GENSET #1'!C35+'GENSET #2'!C35+'GENSET #3'!C35+'GENSET #4'!C35+'GENSET #5'!C35) -> 95918012 | D30: =IF((C30-C29<0), "0",C30-C29) -> 28639 | E30: ='Gas-2'!G31 -> 225 | F30: =IF((E30-E29<0), "0",E30-E29) -> 0 | G30: =SUM(WATER!C31,WATER!H31,WATER!M31,WATER!R31) -> 1039271 | H30: =IF((G30-G29<0), "0",G30-G29) -> 454
A31: =A30+1 -> 44557 | C31: =SUM('GENSET #1'!C36+'GENSET #2'!C36+'GENSET #3'!C36+'GENSET #4'!C36+'GENSET #5'!C36) -> 95954351 | D31: =IF((C31-C30<0), "0",C31-C30) -> 36339 | E31: ='Gas-2'!G32 -> 270 | F31: =IF((E31-E30<0), "0",E31-E30) -> 45 | G31: =SUM(WATER!C32,WATER!H32,WATER!M32,WATER!R32) -> 1039720 | H31: =IF((G31-G30<0), "0",G31-G30) -> 449
A32: =A31+1 -> 44558 | C32: =SUM('GENSET #1'!C37+'GENSET #2'!C37+'GENSET #3'!C37+'GENSET #4'!C37+'GENSET #5'!C37) -> 95984752 | D32: =IF((C32-C31<0), "0",C32-C31) -> 30401 | E32: ='Gas-2'!G33 -> 225 | F32: =IF((E32-E31<0), "0",E32-E31) -> 0 | G32: =SUM(WATER!C33,WATER!H33,WATER!M33,WATER!R33) -> 0 | H32: =IF((G32-G31<0), "0",G32-G31) -> 0
A33: =A32+1 -> 44559 | C33: =SUM('GENSET #1'!C38+'GENSET #2'!C38+'GENSET #3'!C38+'GENSET #4'!C38+'GENSET #5'!C38) -> 77595803 | D33: =IF((C33-C32<0), "0",C33-C32) -> 0 | E33: ='Gas-2'!G34 -> 270 | F33: =IF((E33-E32<0), "0",E33-E32) -> 45 | G33: =SUM(WATER!C34,WATER!H34,WATER!M34,WATER!R34) -> 0 | H33: =IF((G33-G32<0), "0",G33-G32) -> 0
A34: =A33+1 -> 44560 | C34: =SUM('GENSET #1'!C39+'GENSET #2'!C39+'GENSET #3'!C39+'GENSET #4'!C39+'GENSET #5'!C39) -> 0 | D34: =IF((C34-C33<0), "0",C34-C33) -> 0 | E34: ='Gas-2'!G35 -> 0 | F34: =IF((E34-E33<0), "0",E34-E33) -> 0 | G34: =SUM(WATER!C35,WATER!H35,WATER!M35,WATER!R35) -> 0 | H34: =IF((G34-G33<0), "0",G34-G33) -> 0
A35: =A34+1 -> 44561 | C35: =SUM('GENSET #1'!C40+'GENSET #2'!C40+'GENSET #3'!C40+'GENSET #4'!C40+'GENSET #5'!C40) -> 0 | D35: =IF((C35-C34<0), "0",C35-C34) -> 0 | E35: ='Gas-2'!G36 -> 0 | F35: =IF((E35-E34<0), "0",E35-E34) -> 0 | G35: =SUM(WATER!C36,WATER!H36,WATER!M36,WATER!R36) -> 0 | H35: =IF((G35-G34<0), "0",G35-G34) -> 0

Sheet Finance Only
A1: Four Seasons Landaa Giraavaru
A3: Property | B3: MLG | G3: 44470 | H3: =NOW() -> 44560.404 | J3: =H3-G3 -> 90.404008
A4: Month | B4: December
A5: Year | B5: 2021
A7: DAY | B7: Electricity Consumption ( kwh) | C7: Diesel Consumption (Liters) | D7: Solar Power Consumption(kwh) | E7: Gas Consumption (kg) | F7: Water Consumption ( m3) | G7: Occupancy | H7: Weather | I7: Ambian Temperature | J7: Electricity Variance (Today vs Yesterday)
A8: 1 | B8: =SUM('GENSET #1:GENSET #5'!D10) -> 25086 | C8: ='Diesel consumption'!D5 -> 7050 | D8: ='SOLAR METER READING'!D9 -> 3086 | E8: ='Gas-2'!G6 -> 225 | F8: =WATER!V6 -> 414 | G8: =WATER!W6 -> 37.9 | H8: ='SOLAR METER READING'!E9 -> sunny | I8: ='SOLAR METER READING'!F9 -> 30
A9: 2 | B9: =SUM('GENSET #1:GENSET #5'!D11) -> 26010 | C9: ='Diesel consumption'!D6 -> 7350 | D9: ='SOLAR METER READING'!D10 -> 3074 | E9: ='Gas-2'!G7 -> 225 | F9: =WATER!V7 -> 369 | G9: =WATER!W7 -> 44.7 | H9: ='SOLAR METER READING'!E10 -> sunny | I9: ='SOLAR METER READING'!F10 -> 30 | J9: =B9-B8 -> 924
A10: 3 | B10: =SUM('GENSET #1:GENSET #5'!D12) -> 26063 | C10: ='Diesel consumption'!D7 -> 7340 | D10: ='SOLAR METER READING'!D11 -> 2942 | E10: ='Gas-2'!G8 -> 270 | F10: =WATER!V8 -> 438 | G10: =WATER!W8 -> 40.8 | H10: ='SOLAR METER READING'!E11 -> cloudy | I10: ='SOLAR METER READING'!F11 -> 27 | J10: =B10-B9 -> 53
A11: 4 | B11: =SUM('GENSET #1:GENSET #5'!D13) -> 27067 | C11: ='Diesel consumption'!D8 -> 7450 | D11: ='SOLAR METER READING'!D12 -> 1782 | E11: ='Gas-2'!G9 -> 270 | F11: =WATER!V9 -> 427 | G11: =WATER!W9 -> 36.9 | H11: ='SOLAR METER READING'!E12 -> cloudy | I11: ='SOLAR METER READING'!F12 -> 27 | J11: =B11-B10 -> 1004
A12: 5 | B12: =SUM('GENSET #1:GENSET #5'!D14) -> 25673 | C12: ='Diesel consumption'!D9 -> 7150 | D12: ='SOLAR METER READING'!D13 -> 3096 | E12: ='Gas-2'!G10 -> 225 | F12: =WATER!V10 -> 423 | G12: =WATER!W10 -> 28.2 | H12: ='SOLAR METER READING'!E13 -> sunny | I12: ='SOLAR METER READING'!F13 -> 30 | J12: =B12-B11 -> -1394
A13: 6 | B13: =SUM('GENSET #1:GENSET #5'!D15) -> 26011 | C13: ='Diesel consumption'!D10 -> 7150 | D13: ='SOLAR METER READING'!D14 -> 3085 | E13: ='Gas-2'!G11 -> 225 | F13: =WATER!V11 -> 347 | G13: =WATER!W11 -> 28.2 | H13: ='SOLAR METER READING'!E14 -> sunny | I13: ='SOLAR METER READING'!F14 -> 29 | J13: =B13-B12 -> 338
A14: 7 | B14: =SUM('GENSET #1:GENSET #5'!D16) -> 25920 | C14: ='Diesel consumption'!D11 -> 7520 | D14: ='SOLAR METER READING'!D15 -> 2827 | E14: ='Gas-2'!G12 -> 270 | F14: =WATER!V12 -> 413 | G14: =WATER!W12 -> 27.2 | H14: ='SOLAR METER READING'!E15 -> cloudy | I14: ='SOLAR METER READING'!F15 -> 28 | J14: =B14-B13 -> -91
A15: 8 | B15: =SUM('GENSET #1:GENSET #5'!D17) -> 27545 | C15: ='Diesel consumption'!D12 -> 7100 | D15: ='SOLAR METER READING'!D16 -> 2904 | E15: ='Gas-2'!G13 -> 270 | F15: =WATER!V13 -> 417 | G15: =WATER!W13 -> 27.2 | H15: ='SOLAR METER READING'!E16 -> partially sunny | I15: ='SOLAR METER READING'!F16 -> 29 | J15: =B15-B14 -> 1625
A16: 9 | B16: =SUM('GENSET #1:GENSET #5'!D18) -> 25266 | C16: ='Diesel consumption'!D13 -> 6720 | D16: ='SOLAR METER READING'!D17 -> 2912 | E16: ='Gas-2'!G14 -> 225 | F16: =WATER!V14 -> 434 | G16: =WATER!W14 -> 27.2 | H16: ='SOLAR METER READING'!E17 -> partially sunny | I16: ='SOLAR METER READING'!F17 -> 27 | J16: =B16-B15 -> -2279
A17: 10 | B17: =SUM('GENSET #1:GENSET #5'!D19) -> 25058 | C17: ='Diesel consumption'!D14 -> 6820 | D17: ='SOLAR METER READING'!D18 -> 1829 | E17: ='Gas-2'!G15 -> 225 | F17: =WATER!V15 -> 430 | G17: =WATER!W15 -> 21 | H17: ='SOLAR METER READING'!E18 -> rainy | I17: ='SOLAR METER READING'!F18 -> 27 | J17: =B17-B16 -> -208
A18: 11 | B18: =SUM('GENSET #1:GENSET #5'!D20) -> 27209 | C18: ='Diesel consumption'!D15 -> 7290 | D18: ='SOLAR METER READING'!D19 -> 2102 | E18: ='Gas-2'!G16 -> 270 | F18: =WATER!V16 -> 419 | G18: =WATER!W16 -> 25.2 | H18: ='SOLAR METER READING'!E19 -> cloudy | I18: ='SOLAR METER READING'!F19 -> 28 | J18: =B18-B17 -> 2151
A19: 12 | B19: =SUM('GENSET #1:GENSET #5'!D21) -> 26285 | C19: ='Diesel consumption'!D16 -> 7180 | D19: ='SOLAR METER READING'!D20 -> 800 | E19: ='Gas-2'!G17 -> 225 | F19: =WATER!V17 -> 415 | G19: =WATER!W17 -> 29.1 | H19: ='SOLAR METER READING'!E20 -> rainy | I19: ='SOLAR METER READING'!F20 -> 27 | J19: =B19-B18 -> -924
A20: 13 | B20: =SUM('GENSET #1:GENSET #5'!D22) -> 25089 | C20: ='Diesel consumption'!D17 -> 7110 | D20: ='SOLAR METER READING'!D21 -> 1149 | E20: ='Gas-2'!G18 -> 225 | F20: =WATER!V18 -> 413 | G20: =WATER!W18 -> 35.9 | H20: ='SOLAR METER READING'!E21 -> cloudy | I20: ='SOLAR METER READING'!F21 -> 27 | J20: =B20-B19 -> -1196
... A37: 30 | B37: =SUM('GENSET #1:GENSET #5'!D39) -> 0 | C37: ='Diesel consumption'!D34 -> 0 | D37: ='SOLAR METER READING'!D38 -> 0 | E37: ='Gas-2'!G35 -> 0 | F37: =WATER!V35 -> 0 | G37: =WATER!W35 -> 0 | H37: ='SOLAR METER READING'!E38 -> 0 | I37: ='SOLAR METER READING'!F38 -> 0 | J37: =B37-B36 -> -21839
A38: Total | B38: =SUM(B8:B37) -> 800930 | C38: =SUM(C8:C37) -> 220280 | D38: =SUM(D8:D37) -> 77659 | E38: =SUM(E8:E37) -> 7380 | F38: =SUM(F8:F37) -> 11410 | G38: =SUM(G8:G37)/30 -> 34.996667 | H38: ='SOLAR METER READING'!E40 -> 0 | I38: ='SOLAR METER READING'!F40 -> 0
A39: Avg | B39: =B38/30 -> 26697.667 | C39: =C38/30 -> 7342.6667 | D39: =D38/30 -> 2588.6333 | E39: =E38/30 -> 246 | F39: =F38/30 -> 380.33333

Sheet GENSET #1
C1: 1000 KVA
C3: NO#1
A6: 44531
B8: GENSET NO 1
A9: DAY | B9: YESTARDAY | C9: TODAY | D9: Final Electricity Consumption( KWh)
A10: 1 | B10: 18250842 | C10: 18252052 | D10: =MAX(0,C10-B10) -> 1210
A11: 2 | B11: =C10 -> 18252052 | C11: 18259708 | D11: =MAX(0,C11-B11) -> 7656
A12: 3 | B12: =C11 -> 18259708 | C12: 18259708 | D12: =MAX(0,C12-B12) -> 0
A13: 4 | B13: =C12 -> 18259708 | C13: 18263379 | D13: =MAX(0,C13-B13) -> 3671
A14: 5 | B14: =C13 -> 18263379 | C14: 18273408 | D14: =MAX(0,C14-B14) -> 10029
A15: 6 | B15: =C14 -> 18273408 | C15: 18279385 | D15: =MAX(0,C15-B15) -> 5977
A16: 7 | B16: =C15 -> 18279385 | C16: 18287381 | D16: =MAX(0,C16-B16) -> 7996
A17: 8 | B17: =C16 -> 18287381 | C17: 18293247 | D17: =MAX(0,C17-B17) -> 5866
A18: 9 | B18: =C17 -> 18293247 | C18: 18293247 | D18: =MAX(0,C18-B18) -> 0
A19: 10 | B19: =C18 -> 18293247 | C19: 18299977 | D19: =MAX(0,C19-B19) -> 6730
A20: 11 | B20: =C19 -> 18299977 | C20: 18305460 | D20: =MAX(0,C20-B20) -> 5483
A21: 12 | B21: =C20 -> 18305460 | C21: 18309548 | D21: =MAX(0,C21-B21) -> 4088
A22: 13 | B22: =C21 -> 18309548 | C22: 18311406 | D22: =MAX(0,C22-B22) -> 1858
... A37: 28 | B37: =C36 -> 18402803 | C37: 18410788 | D37: =MAX(0,C37-B37) -> 7985
A38: 29 | B38: =C37 -> 18410788 | D38: =MAX(0,C38-B38) -> 0
A39: 30 | B39: =C38 -> 0 | D39: =MAX(0,C39-B39) -> 0 | G39: NEW ENGINE PURCHASED FROM UK
A40: 31 | B40: =C39 -> 0 | D40: =MAX(0,C40-B40) -> 0
A41: Total | D41: =SUM(D10:D40) -> 159946 | G41: INSTALLED: NOV 30 2013

Sheet GENSET #2
C1: 1600 KVA
C3: NO#2
A6: ='GENSET #1'!A6 -> 44531
B8: GENSET NO 2
A9: DAY | B9: YESTARDAY | C9: TODAY | D9: Final Electricity Consumption( KW h)
A10: 1 | B10: 31527500 | C10: 31543727 | D10: =MAX(0,C10-B10) -> 16227
A11: 2 | B11: =C10 -> 31543727 | C11: 31548922 | D11: =MAX(0,C11-B11) -> 5195
A12: 3 | B12: =C11 -> 31548922 | C12: 31562067 | D12: =MAX(0,C12-B12) -> 13145
A13: 4 | B13: =C12 -> 31562067 | C13: 31567758 | D13: =MAX(0,C13-B13) -> 5691
A14: 5 | B14: =C13 -> 31567758 | C14: 31570417 | D14: =MAX(0,C14-B14) -> 2659
A15: 6 | B15: =C14 -> 31570417 | C15: 31575633 | D15: =MAX(0,C15-B15) -> 5216
A16: 7 | B16: =C15 -> 31575633 | C16: 31589690 | D16: =MAX(0,C16-B16) -> 14057
A17: 8 | B17: =C16 -> 31589690 | C17: 31590002 | D17: =MAX(0,C17-B17) -> 312
A18: 9 | B18: =C17 -> 31590002 | C18: 31597177 | D18: =MAX(0,C18-B18) -> 7175
A19: 10 | B19: =C18 -> 31597177 | C19: 31604436 | D19: =MAX(0,C19-B19) -> 7259
A20: 11 | B20: =C19 -> 31604436 | C20: 31609004 | D20: =MAX(0,C20-B20) -> 4568
A21: 12 | B21: =C20 -> 31609004 | C21: 31619338 | D21: =MAX(0,C21-B21) -> 10334
A22: 13 | B22: =C21 -> 31619338 | C22: 31625930 | D22: =MAX(0,C22-B22) -> 6592
... A38: 29 | B38: =C37 -> 31748779 | C38: 31756174 | D38: =MAX(0,C38-B38) -> 7395
A39: 30 | B39: =C38 -> 31756174 | D39: =MAX(0,C39-B39) -> 0
A40: 31 | B40: =C39 -> 0 | D40: =MAX(0,C40-B40) -> 0
A41: Total | B41: =#REF! -> #REF! | D41: =SUM(D10:D40) -> 228674

Sheet GENSET #3
C1: 900 KVA
C3: NO#3
A6: ='GENSET #2'!A6 -> 44531
B8: GENSET NO 3
A9: DAY | B9: YESTARDAY | C9: TODAY | D9: Final Electricity Consumption( KW h)
A10: 1 | B10: 14092185 | C10: 14094845 | D10: =MAX(0,C10-B10) -> 2660
A11: 2 | B11: =C10 -> 14094845 | C11: 14101139 | D11: =MAX(0,C11-B11) -> 6294
A12: 3 | B12: =C11 -> 14101139 | C12: 14108482 | D12: =MAX(0,C12-B12) -> 7343
A13: 4 | B13: =C12 -> 14108482 | C13: 14116648 | D13: =MAX(0,C13-B13) -> 8166
A14: 5 | B14: =C13 -> 14116648 | C14: 14117018 | D14: =MAX(0,C14-B14) -> 370
A15: 6 | B15: =C14 -> 14117018 | C15: 14121739 | D15: =MAX(0,C15-B15) -> 4721
A16: 7 | B16: =C15 -> 14121739 | C16: 14121778 | D16: =MAX(0,C16-B16) -> 39
A17: 8 | B17: =C16 -> 14121778 | C17: 14132382 | D17: =MAX(0,C17-B17) -> 10604
A18: 9 | B18: =C17 -> 14132382 | C18: 14138709 | D18: =MAX(0,C18-B18) -> 6327
A19: 10 | B19: =C18 -> 14138709 | C19: 14144814 | D19: =MAX(0,C19-B19) -> 6105
A20: 11 | B20: =C19 -> 14144814 | C20: 14152081 | D20: =MAX(0,C20-B20) -> 7267
A21: 12 | B21: =C20 -> 14152081 | C21: 14158019 | D21: =MAX(0,C21-B21) -> 5938
A22: 13 | B22: =C21 -> 14158019 | C22: 14164187 | D22: =MAX(0,C22-B22) -> 6168
... A38: 29 | B38: =C37 -> 14246048 | C38: 14249619 | D38: =MAX(0,C38-B38) -> 3571
A39: 30 | B39: =C38 -> 14249619 | D39: =MAX(0,C39-B39) -> 0
A40: 31 | B40: =C39 -> 0 | D40: =MAX(0,C40-B40) -> 0
A41: Total | B41: =#REF! -> #REF! | D41: =SUM(D10:D40) -> 157434

Sheet GENSET #4
C1: 500 KVA
C3: NO#4
A6: ='GENSET #3'!A6 -> 44531
B8: GENSET NO 4
A9: DAY | B9: YESTARDAY | C9: TODAY | D9: Final Electricity Consumption( KW h)
A10: 1 | B10: 12064490 | C10: 12067194 | D10: =MAX(0,C10-B10) -> 2704
A11: 2 | B11: =C10 -> 12067194 | C11: 12070026 | D11: =MAX(0,C11-B11) -> 2832
A12: 3 | B12: =C11 -> 12070026 | C12: 12072126 | D12: =MAX(0,C12-B12) -> 2100
A13: 4 | B13: =C12 -> 12072126 | C13: 12073958 | D13: =MAX(0,C13-B13) -> 1832
A14: 5 | B14: =C13 -> 12073958 | C14: 12076480 | D14: =MAX(0,C14-B14) -> 2522
A15: 6 | B15: =C14 -> 12076480 | C15: 12078714 | D15: =MAX(0,C15-B15) -> 2234
A16: 7 | B16: =C15 -> 12078714 | C16: 12079507 | D16: =MAX(0,C16-B16) -> 793
A17: 8 | B17: =C16 -> 12079507 | C17: 12083462 | D17: =MAX(0,C17-B17) -> 3955
A18: 9 | B18: =C17 -> 12083462 | C18: 12088209 | D18: =MAX(0,C18-B18) -> 4747
A19: 10 | B19: =C18 -> 12088209 | C19: 12093130 | D19: =MAX(0,C19-B19) -> 4921
A20: 11 | B20: =C19 -> 12093130 | C20: 12095704 | D20: =MAX(0,C20-B20) -> 2574
A21: 12 | B21: =C20 -> 12095704 | C21: 12097574 | D21: =MAX(0,C21-B21) -> 1870
A22: 13 | B22: =C21 -> 12097574 | C22: 12101283 | D22: =MAX(0,C22-B22) -> 3709
... A38: 29 | B38: =C37 -> 12140620 | C38: 12144212 | D38: =MAX(0,C38-B38) -> 3592
A39: 30 | B39: =C38 -> 12144212 | D39: =MAX(0,C39-B39) -> 0
A40: 31 | B40: =C39 -> 0 | D40: =MAX(0,C40-B40) -> 0
A41: Total | B41: =#REF! -> #REF! | D41: =SUM(D10:D40) -> 79722

Sheet GENSET #5
C1: 1000 KVA
C3: NO#5
A6: ='GENSET #4'!A6 -> 44531
B8: GENSET NO 5
A9: DAY | B9: YESTARDAY | C9: TODAY | D9: Final Electricity Consumption( KWh)
A10: 1 | B10: 19270644 | C10: 19272929 | D10: =MAX(0,C10-B10) -> 2285
A11: 2 | B11: =C10 -> 19272929 | C11: 19276962 | D11: =MAX(0,C11-B11) -> 4033
A12: 3 | B12: =C11 -> 19276962 | C12: 19280437 | D12: =MAX(0,C12-B12) -> 3475
A13: 4 | B13: =C12 -> 19280437 | C13: 19288144 | D13: =MAX(0,C13-B13) -> 7707
A14: 5 | B14: =C13 -> 19288144 | C14: 19298237 | D14: =MAX(0,C14-B14) -> 10093
A15: 6 | B15: =C14 -> 19298237 | C15: 19306100 | D15: =MAX(0,C15-B15) -> 7863
A16: 7 | B16: =C15 -> 19306100 | C16: 19309135 | D16: =MAX(0,C16-B16) -> 3035
A17: 8 | B17: =C16 -> 19309135 | C17: 19315943 | D17: =MAX(0,C17-B17) -> 6808
A18: 9 | B18: =C17 -> 19315943 | C18: 19322960 | D18: =MAX(0,C18-B18) -> 7017
A19: 10 | B19: =C18 -> 19322960 | C19: 19323003 | D19: =MAX(0,C19-B19) -> 43
A20: 11 | B20: =C19 -> 19323003 | C20: 19330320 | D20: =MAX(0,C20-B20) -> 7317
A21: 12 | B21: =C20 -> 19330320 | C21: 19334375 | D21: =MAX(0,C21-B21) -> 4055
A22: 13 | B22: =C21 -> 19334375 | C22: 19341137 | D22: =MAX(0,C22-B22) -> 6762
... A38: 29 | B38: =C37 -> 19438517 | C38: 19445798 | D38: =MAX(0,C38-B38) -> 7281
A39: 30 | B39: =C38 -> 19445798 | D39: =MAX(0,C39-B39) -> 0
A40: 31 | B40: =C39 -> 0 | D40: =MAX(0,C40-B40) -> 0
A41: Total | D41: =SUM(D10:D40) -> 175154

Sheet Diesel consumption
A1: Diesel Consumption - Powerhouse | F1: Diesel Tank Jetty Meter
A2: ='GENSET #5'!A6 -> 44531
D3: Liters | F3: Boat meter Reading
A4: Date | B4: Yesterday | C4: Today | D4: ConsumptionIn 24 hrs | F4: Yesterday | G4: Today | H4: Consumption (Liters) | J4: In Barrels | L4: Carbon Emmision
A5: 1 | B5: 45413760 | C5: 45420810 | D5: =MAX(0,C5-B5) -> 7050 | F5: 910600 | G5: 915450 | H5: =MAX(0,G5-F5) -> 4850 | J5: =D5/200 -> 35.25 | L5: =2.68*D5 -> 18894 | M5: =L5/1000 -> 18.894
A6: 2 | B6: =C5 -> 45420810 | C6: 45428160 | D6: =MAX(0,C6-B6) -> 7350 | F6: =G5 -> 915450 | G6: 917310 | H6: =MAX(0,G6-F6) -> 1860 | J6: =D6/200 -> 36.75 | L6: =2.68*D6 -> 19698 | M6: =L6/1000 -> 19.698
A7: 3 | B7: =C6 -> 45428160 | C7: 45435500 | D7: =MAX(0,C7-B7) -> 7340 | F7: =G6 -> 917310 | G7: 919290 | H7: =MAX(0,G7-F7) -> 1980 | J7: =D7/200 -> 36.7 | L7: =2.68*D7 -> 19671.2 | M7: =L7/1000 -> 19.6712
A8: 4 | B8: =C7 -> 45435500 | C8: 45442950 | D8: =MAX(0,C8-B8) -> 7450 | F8: =G7 -> 919290 | G8: 920190 | H8: =MAX(0,G8-F8) -> 900 | J8: =D8/200 -> 37.25 | L8: =2.68*D8 -> 19966 | M8: =L8/1000 -> 19.966
A9: 5 | B9: =C8 -> 45442950 | C9: 45450100 | D9: =MAX(0,C9-B9) -> 7150 | F9: =G8 -> 920190 | G9: 923100 | H9: =MAX(0,G9-F9) -> 2910 | J9: =D9/200 -> 35.75 | L9: =2.68*D9 -> 19162 | M9: =L9/1000 -> 19.162
A10: 6 | B10: =C9 -> 45450100 | C10: 45457250 | D10: =MAX(0,C10-B10) -> 7150 | F10: =G9 -> 923100 | G10: 925470 | H10: =MAX(0,G10-F10) -> 2370 | J10: =D10/200 -> 35.75 | L10: =2.68*D10 -> 19162 | M10: =L10/1000 -> 19.162
A11: 7 | B11: =C10 -> 45457250 | C11: 45464770 | D11: =MAX(0,C11-B11) -> 7520 | F11: =G10 -> 925470 | G11: 929000 | H11: =MAX(0,G11-F11) -> 3530 | J11: =D11/200 -> 37.6 | L11: =2.68*D11 -> 20153.6 | M11: =L11/1000 -> 20.1536
A12: 8 | B12: =C11 -> 45464770 | C12: 45471870 | D12: =MAX(0,C12-B12) -> 7100 | F12: =G11 -> 929000 | G12: 930040 | H12: =MAX(0,G12-F12) -> 1040 | J12: =D12/200 -> 35.5 | L12: =2.68*D12 -> 19028 | M12: =L12/1000 -> 19.028
A13: 9 | B13: =C12 -> 45471870 | C13: 45478590 | D13: =MAX(0,C13-B13) -> 6720 | F13: =G12 -> 930040 | G13: 933620 | H13: =MAX(0,G13-F13) -> 3580 | J13: =D13/200 -> 33.6 | L13: =2.68*D13 -> 18009.6 | M13: =L13/1000 -> 18.0096
A14: 10 | B14: =C13 -> 45478590 | C14: 45485410 | D14: =MAX(0,C14-B14) -> 6820 | F14: =G13 -> 933620 | G14: 934310 | H14: =MAX(0,G14-F14) -> 690 | J14: =D14/200 -> 34.1 | L14: =2.68*D14 -> 18277.6 | M14: =L14/1000 -> 18.2776
A15: 11 | B15: =C14 -> 45485410 | C15: 45492700 | D15: =MAX(0,C15-B15) -> 7290 | F15: =G14 -> 934310 | G15: 936640 | H15: =MAX(0,G15-F15) -> 2330 | J15: =D15/200 -> 36.45 | L15: =2.68*D15 -> 19537.2 | M15: =L15/1000 -> 19.5372
A16: 12 | B16: =C15 -> 45492700 | C16: 45499880 | D16: =MAX(0,C16-B16) -> 7180 | F16: =G15 -> 936640 | G16: 937180 | H16: =MAX(0,G16-F16) -> 540 | J16: =D16/200 -> 35.9 | L16: =2.68*D16 -> 19242.4 | M16: =L16/1000 -> 19.2424
A17: 13 | B17: =C16 -> 45499880 | C17: 45506990 | D17: =MAX(0,C17-B17) -> 7110 | F17: =G16 -> 937180 | G17: 938486 | H17: =MAX(0,G17-F17) -> 1306 | J17: =D17/200 -> 35.55 | L17: =2.68*D17 -> 19054.8 | M17: =L17/1000 -> 19.0548
... A33: 29 | B33: =C32 -> 45625920 | C33: 45634040 | D33: =MAX(0,C33-B33) -> 8120 | F33: =G32 -> 963820 | G33: 963820 | H33: =MAX(0,G33-F33) -> 0 | J33: =D33/200 -> 40.6 | L33: =2.68*D33 -> 21761.6 | M33: =L33/1000 -> 21.7616
A34: 30 | B34: =C33 -> 45634040 | D34: =MAX(0,C34-B34) -> 0 | F34: =G33 -> 963820 | H34: =MAX(0,G34-F34) -> 0 | J34: =D34/200 -> 0 | L34: =2.68*D34 -> 0 | M34: =L34/1000 -> 0
A35: 31 | B35: =C34 -> 0 | D35: =MAX(0,C35-B35) -> 0 | F35: =G34 -> 0 | H35: =MAX(0,G35-F35) -> 0
D36: =SUM(D5:D35) -> 220280 | J36: =SUM(J5:J34) -> 1101.4 | L36: =2.68*D36 -> 590350.4 | M36: =L36/1000 -> 590.3504

Sheet SOLAR METER READING
C3: solar reading
B5: ='Diesel consumption'!A2 -> 44531
B7: Solar meter reading
A8: DAY | B8: YESTARDAY | C8: TODAY | D8: Final Electricity Consumption( KW h) | E8: Weather Condition | F8: Temperature
A9: 1 | B9: 3182638 | C9: 3185724 | D9: =MAX(0,C9-B9) -> 3086 | E9: sunny | F9: 30
A10: 2 | B10: =C9 -> 3185724 | C10: 3188798 | D10: =MAX(0,C10-B10) -> 3074 | E10: sunny | F10: 30
A11: 3 | B11: =C10 -> 3188798 | C11: 3191740 | D11: =MAX(0,C11-B11) -> 2942 | E11: cloudy | F11: 27
A12: 4 | B12: =C11 -> 3191740 | C12: 3193522 | D12: =MAX(0,C12-B12) -> 1782 | E12: cloudy | F12: 27
A13: 5 | B13: =C12 -> 3193522 | C13: 3196618 | D13: =MAX(0,C13-B13) -> 3096 | E13: sunny | F13: 30 | J13: 1 liter diesel | K13: 11.1 kwh
A14: 6 | B14: =C13 -> 3196618 | C14: 3199703 | D14: =MAX(0,C14-B14) -> 3085 | E14: sunny | F14: 29 | J14: 212.88 diesel | K14: 2363 kwh
A15: 7 | B15: =C14 -> 3199703 | C15: 3202530 | D15: =MAX(0,C15-B15) -> 2827 | E15: cloudy | F15: 28
A16: 8 | B16: =C15 -> 3202530 | C16: 3205434 | D16: =MAX(0,C16-B16) -> 2904 | E16: partially sunny | F16: 29
A17: 9 | B17: =C16 -> 3205434 | C17: 3208346 | D17: =MAX(0,C17-B17) -> 2912 | E17: partially sunny | F17: 27
A18: 10 | B18: =C17 -> 3208346 | C18: 3210175 | D18: =MAX(0,C18-B18) -> 1829 | E18: rainy | F18: 27
A19: 11 | B19: =C18 -> 3210175 | C19: 3212277 | D19: =MAX(0,C19-B19) -> 2102 | E19: cloudy | F19: 28
A20: 12 | B20: =C19 -> 3212277 | C20: 3213077 | D20: =MAX(0,C20-B20) -> 800 | E20: rainy | F20: 27
A21: 13 | B21: =C20 -> 3213077 | C21: 3214226 | D21: =MAX(0,C21-B21) -> 1149 | E21: cloudy | F21: 27
A22: 14 | B22: =C21 -> 3214226 | C22: 3216552 | D22: =MAX(0,C22-B22) -> 2326 | E22: cloudy | F22: 27
A23: 15 | B23: =C22 -> 3216552 | C23: 3219478 | D23: =MAX(0,C23-B23) -> 2926 | E23: cloudy | F23: 27
A24: 16 | B24: =C23 -> 3219478 | C24: 3222444 | D24: =MAX(0,C24-B24) -> 2966 | E24: cloudy | F24: 27
A25: 17 | B25: =C24 -> 3222444 | C25: 3225103 | D25: =MAX(0,C25-B25) -> 2659 | E25: cloudy | F25: 28
A26: 18 | B26: =C25 -> 3225103 | C26: 3228087 | D26: =MAX(0,C26-B26) -> 2984 | E26: cloudy | F26: 28
... A37: 29 | B37: =C36 -> 3257320 | C37: 3260297 | D37: =MAX(0,C37-B37) -> 2977 | E37: sunny | F37: 29
A38: 30 | B38: =C37 -> 3260297 | D38: =MAX(0,C38-B38) -> 0
A39: 31 | B39: =C38 -> 0 | D39: =MAX(0,C39-B39) -> 0
A40: Total | D40: =SUM(D9:D39) -> 77659

Sheet FEEDER Consumption 
A1: ='SOLAR METER READING'!B5 -> 44531 | FH1: Daily Electricity (Kwh) Consumption by Building Categories
A2: POWER HOUSE FEEDER READING
C3: Main BLU FEEDER PANEL 1 | H3: Main BLU FEEDER PANEL 2 | M3: Main POWER HOUSE FEEDER PANEL NO:3 | R3: Main Kitchen -7 | W3: Main Kitchen -10 | AB3: Water treatment Plant | AG3: Sewage treatment Plant | AL3: Laundry--8SSB (HR/Tuck Shop Building) | AQ3: Laundry-9 (Machineries) | AV3: New staff accomodation (E0) | BA3: Staff block-16(E2-E3) | BF3: Staff Block Feeder-3(E4-E5) | BK3: Management block-5 (M1 to M6) | BP3: SNR STAFF BLOCK (PC Block) | BU3: BOAT DOCK FEEDER - 22 | BZ3: RECEPTION Building Full (Finance/Reservation) | CE3: DIVE CENTER (Inc MDC and Recreation) | CJ3: 301-307 | CO3: 308-314 | CT3: 315-320 | CY3: 401-407 | DD3: 408-414 | DI3: 415-420 | DN3: SPA - 1 | DS3: SPA - 2 | DX3: BLU KITCHEN - 1 | EC3: BLU KITCHEN - 2 | EH3: AL BARAKATH | EM3: STAFF KITCHEN | ER3: MANAGR BLOCK GARDEN (White House) | EW3: 121-131 | FB3: 113-120 | FH3: Blu Feeders | FJ3: ALL Kitchens | FL3: Laundry + HR Buidling | FN3: Employee Block | FP3: Managers Block + SNR Block | FR3: HPL Project Team Usage
A4: DAY | B4: Occupancy | C4: Yesterday | D4: Today | E4: Consumption | F4: Variance (Tdy vs Ystdy) | G4: % | H4: Yesterday | I4: Today | J4: Consumption | K4: Var(Tdy vs Ystdy) | L4: % | M4: Yesterday | N4: Today | O4: Consumption | P4: Var (Tdy vs Ystdy) | Q4: % | R4: Yesterday | S4: Today | T4: Consumption | U4: Var(Tdy vs Ystdy) | V4: % | W4: Yesterday | X4: Today | Y4: Consumption | Z4: Var(Tdy vs Ystdy) | AA4: % | AB4: Yesterday | AC4: Today | AD4: Consumption | AE4: Var(Tdy vs Ystdy) | AF4: % | AG4: Yesterday | AH4: Today | AI4: Consumption | AJ4: Var(Tdy vs Ystdy) | AK4: % | AL4: Yesterday | AM4: Today | AN4: Consumption | AO4: Var(Tdy vs Ystdy) | AP4: % | AQ4: Yesterday | AR4: Today | AS4: Consumption | AT4: Var(Tdy vs Ystdy) | AU4: % | AV4: Yesterday | AW4: Today | AX4: Consumption | AY4: Var(Tdy vs Ystdy) | AZ4: % | BA4: Yesterday | BB4: Today | BC4: Consumption | BD4: Var(Tdy vs Ystdy) | BE4: % | BF4: Yesterday | BG4: Today | BH4: Consumption | BI4: Var(Tdy vs Ystdy) | BJ4: % | BK4: Yesterday | BL4: Today | BM4: Consumption | BN4: Var(Tdy vs Ystdy) | BO4: % | BP4: Yesterday | BQ4: Today | BR4: Consumption | BS4: Var(Tdy vs Ystdy) | BT4: % | BU4: Yesterday | BV4: Today | BW4: Consumption | BX4: Var(Tdy vs Ystdy) | BY4: % | BZ4: Yesterday | CA4: Today | CB4: Consumption | CC4: Var(Tdy vs Ystdy) | CD4: % | CE4: Yesterday | CF4: Today | CG4: Consumption | CH4: Var(Tdy vs Ystdy) | CI4: % | CJ4: Yesterday | CK4: Today | CL4: Consumption | CM4: Var(Tdy vs Ystdy) | CN4: % | CO4: Yesterday | CP4: Today | CQ4: Consumption | CR4: Var(Tdy vs Ystdy) | CS4: % | CT4: Yesterday | CU4: Today | CV4: Consumption | CW4: Var(Tdy vs Ystdy) | CX4: % | CY4: Yesterday | CZ4: Today | DA4: Consumption | DB4: Var(Tdy vs Ystdy) | DC4: % | DD4: Yesterday | DE4: Today | DF4: Consumption | DG4: Var(Tdy vs Ystdy) | DH4: % | DI4: Yesterday | DJ4: Today | DK4: Consumption | DL4: Var(Tdy vs Ystdy) | DM4: % | DN4: Yesterday | DO4: Today | DP4: Consumption | DQ4: Var(Tdy vs Ystdy) | DR4: % | DS4: Yesterday | DT4: Today | DU4: Consumption | DV4: Var(Tdy vs Ystdy) | DW4: % | DX4: Yesterday | DY4: Today | DZ4: Consumption | EA4: Var(Tdy vs Ystdy) | EB4: % | EC4: Yesterday | ED4: Today | EE4: Consumption | EF4: Var(Tdy vs Ystdy) | EG4: % | EH4: Yesterday | EI4: Today | EJ4: Consumption | EK4: Var(Tdy vs Ystdy) | EL4: % | EM4: Yesterday | EN4: Today | EO4: Consumption | EP4: Var(Tdy vs Ystdy) | EQ4: % | ER4: Yesterday | ES4: Today | ET4: Consumption | EU4: Var(Tdy vs Ystdy) | EV4: % | EW4: Yesterday | EX4: Today | EY4: Consumption | EZ4: Var(Tdy vs Ystdy) | FA4: % | FB4: Yesterday | FC4: Today | FD4: Consumption | FE4: Var(Tdy vs Ystdy) | FF4: % | FH4: Total (Kwh) | FI4: Avg | FJ4: Total (Kwh) | FK4: Avg | FL4: Total (Kwh) | FM4: Avg | FN4: Total (Kwh) | FO4: Avg | FP4: Total (Kwh) | FQ4: Avg | FR4: Total (Kwh) | FS4: Avg
A5: 1 | B5: ='Finance Only'!G8 -> 37.9 | C5: 26086177 | D5: 26088662 | E5: =MAX(0,D5-C5) -> 2485 | H5: 23532922 | I5: 23537291 | J5: =MAX(0,I5-H5) -> 4369 | M5: 88369570 | N5: 88382762 | O5: =MAX(0,N5-M5) -> 13192 | R5: 2373800 | S5: 2375500 | T5: =MAX(0,S5-R5) -> 1700 | W5: 3245009 | X5: 3247819 | Y5: =MAX(0,X5-W5) -> 2810 | AB5: 2015700 | AC5: 2018200 | AD5: =MAX(0,AC5-AB5) -> 2500 | AG5: 884645 | AH5: 885468 | AI5: =MAX(0,AH5-AG5) -> 823 | AL5: 895790 | AM5: 896500 | AN5: =MAX(0,AM5-AL5) -> 710 | AQ5: 2007400 | AR5: 2008800 | AS5: 785 | AV5: 581443 | AW5: 581814 | AX5: 443 | BA5: 824390 | BB5: 825220 | BC5: 871 | BF5: 910740 | BG5: 911450 | BH5: 865 | BK5: 1413200 | BL5: 1413900 | BM5: 1205 | BP5: 912290 | BQ5: 913550 | BR5: 944 | BU5: 444870 | BV5: 4452300 | BW5: 355 | BZ5: 716380 | CA5: 717600 | CB5: 1250 | CE5: 220350 | CF5: 220760 | CG5: 380 | CJ5: 498220 | CK5: 499280 | CL5: =MAX(0,CK5-CJ5) -> 1060 | CO5: 404940 | CP5: 405640 | CQ5: =MAX(0,CP5-CO5) -> 700 | CT5: 341930 | CU5: 342480 | CV5: =MAX(0,CU5-CT5) -> 550 | CY5: 593290 | CZ5: 594400 | DA5: =MAX(0,CZ5-CY5) -> 1110 | DD5: 445100 | DE5: 446170 | DF5: =MAX(0,DE5-DD5) -> 1070 | DI5: 407270 | DJ5: 408020 | DK5: =MAX(0,DJ5-DI5) -> 750 | DN5: 239310 | DO5: 239500 | DP5: =MAX(0,DO5-DN5) -> 190 | DS5: 71543 | DT5: 71694 | DU5: =MAX(0,DT5-DS5) -> 151 | DX5: 465090 | DY5: 465780 | DZ5: =MAX(0,DY5-DX5) -> 690 | EC5: 148170 | ED5: 148440 | EE5: =MAX(0,ED5-EC5) -> 270 | EH5: 148640 | EI5: 149010 | EJ5: =MAX(0,EI5-EH5) -> 370 | EM5: 273840 | EN5: 274400 | EO5: =MAX(0,EN5-EM5) -> 560 | ER5: 69098 | ET5: =MAX(0,ES5-ER5) -> 0 | EW5: 72361 | EX5: 72640 | EY5: =MAX(0,EX5-EW5) -> 279 | FB5: 721420 | FC5: 725470 | FD5: =MAX(0,FC5-FB5) -> 4050 | FH5: =SUM(E5+J5) -> 6854 | FJ5: =SUM(T5+Y5+DZ5+EE5+EJ5+EO5) -> 6400 | FL5: =SUM(AN5+AS5) -> 1495 | FN5: =SUM(AX5+BC5+BH5) -> 2179 | FP5: =SUM(BM5+BR5+ET5) -> 2149 | FR5: =SUM(EY5+FD5) -> 4329
A6: 2 | B6: ='Finance Only'!G9 -> 44.7 | C6: =D5 -> 26088662 | D6: 26091140 | E6: =MAX(0,D6-C6) -> 2478 | F6: =E6-E5 -> -7 | G6: =(E6/'Finance Only'!B9)*100 -> 9.527105 | H6: =I5 -> 23537291 | I6: 23541584 | J6: =MAX(0,I6-H6) -> 4293 | K6: =J6-J5 -> -76 | L6: =(J6/'Finance Only'!B9)*100 -> 16.50519 | M6: =N5 -> 88382762 | N6: 88396492 | O6: =MAX(0,N6-M6) -> 13730 | P6: =O6-O5 -> 538 | Q6: =(O6/'Finance Only'!B9)*100 -> 52.787389 | R6: =S5 -> 2375500 | S6: 2377400 | T6: =MAX(0,S6-R6) -> 1900 | U6: =T6-T5 -> 200 | V6: =(T6/'Finance Only'!B9)*100 -> 7.3048827 | W6: =X5 -> 3247819 | X6: 3250632 | Y6: =MAX(0,X6-W6) -> 2813 | Z6: =Y6-Y5 -> 3 | AA6: =(Y6/'Finance Only'!B9)*100 -> 10.815071 | AB6: =AC5 -> 2018200 | AC6: 2020600 | AD6: =MAX(0,AC6-AB6) -> 2400 | AE6: =AD6-AD5 -> -100 | AF6: =(AD6/'Finance Only'!B9)*100 -> 9.2272203 | AG6: =AH5 -> 885468 | AH6: 886349 | AI6: =MAX(0,AH6-AG6) -> 881 | AJ6: =AI6-AI5 -> 58 | AK6: =(AI6/'Finance Only'!B9)*100 -> 3.3871588 | AL6: =AM5 -> 896500 | AM6: 897180 | AN6: =MAX(0,AM6-AL6) -> 680 | AO6: =AN6-AN5 -> -30 | AP6: =(AN6/'Finance Only'!B9)*100 -> 2.6143791 | AQ6: =AR5 -> 2008800 | AR6: 2010500 | AS6: =MAX(0,AR6-AQ6) -> 1700 | AT6: =AS6-AS5 -> 915 | AU6: =(AS6/'Finance Only'!B9)*100 -> 6.5359477 | AV6: =AW5 -> 581814 | AW6: 582206 | AX6: =MAX(0,AW6-AV6) -> 392 | AY6: =AX6-AX5 -> -51 | AZ6: =(AX6/'Finance Only'!B9)*100 -> 1.5071126 | BA6: =BB5 -> 825220 | BB6: 826060 | BC6: =MAX(0,BB6-BA6) -> 840 | BD6: =BC6-BC5 -> -31 | BE6: =(BC6/'Finance Only'!B9)*100 -> 3.2295271 | BF6: =BG5 -> 911450 | BG6: 912220 | BH6: =MAX(0,BG6-BF6) -> 770 | BI6: =BH6-BH5 -> -95 | BJ6: =(BH6/'Finance Only'!B9)*100 -> 2.9603998 | BK6: =BL5 -> 1413900 | BL6: 1414700 | BM6: =MAX(0,BL6-BK6) -> 800 | BN6: =BM6-BM5 -> -405 | BO6: =(BM6/'Finance Only'!B9)*100 -> 3.0757401 | BP6: =BQ5 -> 913550 | BQ6: 915030 | BR6: =MAX(0,BQ6-BP6) -> 1480 | BS6: =BR6-BR5 -> 536 | BT6: =(BR6/'Finance Only'!B9)*100 -> 5.6901192 | BU6: =BV5 -> 4452300 | BV6: 4456300 | BW6: =MAX(0,BV6-BU6) -> 4000 | BX6: =BW6-BW5 -> 3645 | BY6: =(BW6/'Finance Only'!B9)*100 -> 15.3787 | BZ6: =CA5 -> 717600 | CA6: 718810 | CB6: =MAX(0,CA6-BZ6) -> 1210 | CC6: =CB6-CB5 -> -40 | CD6: =(CB6/'Finance Only'!B9)*100 -> 4.6520569 | CE6: =CF5 -> 220760 | CF6: 221190 | CG6: =MAX(0,CF6-CE6) -> 430 | CH6: =CG6-CG5 -> 50 | CI6: =(CG6/'Finance Only'!B9)*100 -> 1.6532103 | CJ6: =CK5 -> 499280 | CK6: 500280 | CL6: =MAX(0,CK6-CJ6) -> 1000 | CM6: =CL6-CL5 -> -60 | CN6: =(CL6/'Finance Only'!B9)*100 -> 3.8446751 | CO6: =CP5 -> 405640 | CP6: 406500 | CQ6: =MAX(0,CP6-CO6) -> 860 | CR6: =CQ6-CQ5 -> 160 | CS6: =(CQ6/'Finance Only'!B9)*100 -> 3.3064206 | CT6: =CU5 -> 342480 | CU6: 343090 | CV6: =MAX(0,CU6-CT6) -> 610 | CW6: =CV6-CV5 -> 60 | CX6: =(CV6/'Finance Only'!B9)*100 -> 2.3452518 | CY6: =CZ5 -> 594400 | CZ6: 595430 | DA6: =MAX(0,CZ6-CY6) -> 1030 | DB6: =DA6-DA5 -> -80 | DC6: =(DA6/'Finance Only'!B9)*100 -> 3.9600154 | DD6: =DE5 -> 446170 | DE6: 447060 | DF6: =MAX(0,DE6-DD6) -> 890 | DG6: =DF6-DF5 -> -180 | DH6: =(DF6/'Finance Only'!B9)*100 -> 3.4217609 | DI6: =DJ5 -> 408020 | DJ6: 408790 | DK6: =MAX(0,DJ6-DI6) -> 770 | DL6: =DK6-DK5 -> 20 | DM6: =(DK6/'Finance Only'!B9)*100 -> 2.9603998 | DN6: =DO5 -> 239500 | DO6: 239680 | DP6: =MAX(0,DO6-DN6) -> 180 | DQ6: =DP6-DP5 -> -10 | DR6: =(DP6/'Finance Only'!B9)*100 -> 0.69204152 | DS6: =DT5 -> 71694 | DT6: 71818 | DU6: =MAX(0,DT6-DS6) -> 124 | DV6: =DU6-DU5 -> -27 | DW6: =(DU6/'Finance Only'!B9)*100 -> 0.47673972 | DX6: =DY5 -> 465780 | DY6: 466480 | DZ6: =MAX(0,DY6-DX6) -> 700 | EA6: =DZ6-DZ5 -> 10 | EB6: =(DZ6/'Finance Only'!B9)*100 -> 2.6912726 | EC6: =ED5 -> 148440 | ED6: 148700 | EE6: =MAX(0,ED6-EC6) -> 260 | EF6: =EE6-EE5 -> -10 | EG6: =(EE6/'Finance Only'!B9)*100 -> 0.99961553 | EH6: =EI5 -> 149010 | EI6: 149350 | EJ6: =MAX(0,EI6-EH6) -> 340 | EK6: =EJ6-EJ5 -> -30 | EL6: =(EJ6/'Finance Only'!B9)*100 -> 1.3071895 | EM6: =EN5 -> 274400 | EN6: 274920 | EO6: =MAX(0,EN6-EM6) -> 520 | EP6: =EO6-EO5 -> -40 | EQ6: =(EO6/'Finance Only'!B9)*100 -> 1.9992311 | ER6: =ES5 -> 0 | ET6: =MAX(0,ES6-ER6) -> 0 | EU6: =ET6-ET5 -> 0 | EV6: =(ET6/'Finance Only'!B9)*100 -> 0 | EW6: =EX5 -> 72640 | EX6: 73006 | EY6: =MAX(0,EX6-EW6) -> 366 | EZ6: =EY6-EY5 -> 87 | FA6: =(EY6/'Finance Only'!G9)*100 -> 818.79195 | FB6: =FC5 -> 725470 | FC6: 729940 | FD6: =MAX(0,FC6-FB6) -> 4470 | FE6: =FD6-FD5 -> 420 | FF6: =(FD6/'Finance Only'!M9)*100 -> #DIV/0! | FH6: =SUM(E6+J6) -> 6771 | FJ6: =SUM(T6+Y6+DZ6+EE6+EJ6+EO6) -> 6533 | FL6: =SUM(AN6+AS6) -> 2380 | FN6: =SUM(AX6+BC6+BH6) -> 2002 | FP6: =SUM(BM6+BR6+ET6) -> 2280 | FR6: =SUM(EY6+FD6) -> 4836
A7: 3 | B7: ='Finance Only'!G10 -> 40.8 | C7: =D6 -> 26091140 | D7: 26093621 | E7: =MAX(0,D7-C7) -> 2481 | F7: =E7-E6 -> 3 | G7: =(E7/'Finance Only'!B10)*100 -> 9.5192418 | H7: =I6 -> 23541584 | I7: 23545962 | J7: =MAX(0,I7-H7) -> 4378 | K7: =J7-J6 -> 85 | L7: =(J7/'Finance Only'!B10)*100 -> 16.797759 | M7: =N6 -> 88396492 | N7: 88410629 | O7: =MAX(0,N7-M7) -> 14137 | P7: =O7-O6 -> 407 | Q7: =(O7/'Finance Only'!B10)*100 -> 54.241645 | R7: =S6 -> 2377400 | S7: 2379200 | T7: =MAX(0,S7-R7) -> 1800 | U7: =T7-T6 -> -100 | V7: =(T7/'Finance Only'!B10)*100 -> 6.9063423 | W7: =X6 -> 3250632 | X7: 3253486 | Y7: =MAX(0,X7-W7) -> 2854 | Z7: =Y7-Y6 -> 41 | AA7: =(Y7/'Finance Only'!B10)*100 -> 10.950389 | AB7: =AC6 -> 2020600 | AC7: 2023200 | AD7: =MAX(0,AC7-AB7) -> 2600 | AE7: =AD7-AD6 -> 200 | AF7: =(AD7/'Finance Only'!B10)*100 -> 9.9758278 | AG7: =AH6 -> 886349 | AH7: 887192 | AI7: =MAX(0,AH7-AG7) -> 843 | AJ7: =AI7-AI6 -> -38 | AK7: =(AI7/'Finance Only'!B10)*100 -> 3.2344703 | AL7: =AM6 -> 897180 | AM7: 897860 | AN7: =MAX(0,AM7-AL7) -> 680 | AO7: =AN7-AN6 -> 0 | AP7: =(AN7/'Finance Only'!B10)*100 -> 2.6090627 | AQ7: =AR6 -> 2010500 | AR7: 2011900 | AS7: =MAX(0,AR7-AQ7) -> 1400 | AT7: =AS7-AS6 -> -300 | AU7: =(AS7/'Finance Only'!B10)*100 -> 5.3715996 | AV7: =AW6 -> 582206 | AW7: 582607 | AX7: =MAX(0,AW7-AV7) -> 401 | AY7: =AX7-AX6 -> 9 | AZ7: =(AX7/'Finance Only'!B10)*100 -> 1.5385796 | BA7: =BB6 -> 826060 | BB7: 826970 | BC7: =MAX(0,BB7-BA7) -> 910 | BD7: =BC7-BC6 -> 70 | BE7: =(BC7/'Finance Only'!B10)*100 -> 3.4915397 | BF7: =BG6 -> 912220 | BG7: 913080 | BH7: =MAX(0,BG7-BF7) -> 860 | BI7: =BH7-BH6 -> 90 | BJ7: =(BH7/'Finance Only'!B10)*100 -> 3.2996969 | BK7: =BL6 -> 1414700 | BL7: 1415500 | BM7: =MAX(0,BL7-BK7) -> 800 | BN7: =BM7-BM6 -> 0 | BO7: =(BM7/'Finance Only'!B10)*100 -> 3.0694855 | BP7: =BQ6 -> 915030 | BQ7: 916640 | BR7: =MAX(0,BQ7-BP7) -> 1610 | BS7: =BR7-BR6 -> 130 | BT7: =(BR7/'Finance Only'!B10)*100 -> 6.1773395 | BU7: =BV6 -> 4456300 | BV7: 4460700 | BW7: =MAX(0,BV7-BU7) -> 4400 | BX7: =BW7-BW6 -> 400 | BY7: =(BW7/'Finance Only'!B10)*100 -> 16.88217 | BZ7: =CA6 -> 718810 | CA7: 719990 | CB7: =MAX(0,CA7-BZ7) -> 1180 | CC7: =CB7-CB6 -> -30 | CD7: =(CB7/'Finance Only'!B10)*100 -> 4.5274911 | CE7: =CF6 -> 221190 | CF7: 221640 | CG7: =MAX(0,CF7-CE7) -> 450 | CH7: =CG7-CG6 -> 20 | CI7: =(CG7/'Finance Only'!B10)*100 -> 1.7265856 | CJ7: =CK6 -> 500280 | CK7: 501250 | CL7: =MAX(0,CK7-CJ7) -> 970 | CM7: =CL7-CL6 -> -30 | CN7: =(CL7/'Finance Only'!B10)*100 -> 3.7217511 | CO7: =CP6 -> 406500 | CP7: 407370 | CQ7: =MAX(0,CP7-CO7) -> 870 | CR7: =CQ7-CQ6 -> 10 | CS7: =(CQ7/'Finance Only'!B10)*100 -> 3.3380655 | CT7: =CU6 -> 343090 | CU7: 343700 | CV7: =MAX(0,CU7-CT7) -> 610 | CW7: =CV7-CV6 -> 0 | CX7: =(CV7/'Finance Only'!B10)*100 -> 2.3404827 | CY7: =CZ6 -> 595430 | CZ7: 596480 | DA7: =MAX(0,CZ7-CY7) -> 1050 | DB7: =DA7-DA6 -> 20 | DC7: =(DA7/'Finance Only'!B10)*100 -> 4.0286997 | DD7: =DE6 -> 447060 | DE7: 447880 | DF7: =MAX(0,DE7-DD7) -> 820 | DG7: =DF7-DF6 -> -70 | DH7: =(DF7/'Finance Only'!B10)*100 -> 3.1462226 | DI7: =DJ6 -> 408790 | DJ7: 409530 | DK7: =MAX(0,DJ7-DI7) -> 740 | DL7: =DK7-DK6 -> -30 | DM7: =(DK7/'Finance Only'!B10)*100 -> 2.8392741 | DN7: =DO6 -> 239680 | DO7: 239850 | DP7: =MAX(0,DO7-DN7) -> 170 | DQ7: =DP7-DP6 -> -10 | DR7: =(DP7/'Finance Only'!B10)*100 -> 0.65226566 | DS7: =DT6 -> 71818 | DT7: 71943 | DU7: =MAX(0,DT7-DS7) -> 125 | DV7: =DU7-DU6 -> 1 | DW7: =(DU7/'Finance Only'!B10)*100 -> 0.47960711 | DX7: =DY6 -> 466480 | DY7: 467160 | DZ7: =MAX(0,DY7-DX7) -> 680 | EA7: =DZ7-DZ6 -> -20 | EB7: =(DZ7/'Finance Only'!B10)*100 -> 2.6090627 | EC7: =ED6 -> 148700 | ED7: 148950 | EE7: =MAX(0,ED7-EC7) -> 250 | EF7: =EE7-EE6 -> -10 | EG7: =(EE7/'Finance Only'!B10)*100 -> 0.95921421 | EH7: =EI6 -> 149350 | EI7: 149570 | EJ7: =MAX(0,EI7-EH7) -> 220 | EK7: =EJ7-EJ6 -> -120 | EL7: =(EJ7/'Finance Only'!B10)*100 -> 0.84410851 | EM7: =EN6 -> 274920 | EN7: 278420 | EO7: =MAX(0,EN7-EM7) -> 3500 | EP7: =EO7-EO6 -> 2980 | EQ7: =(EO7/'Finance Only'!B10)*100 -> 13.428999 | ER7: =ES6 -> 0 | ET7: =MAX(0,ES7-ER7) -> 0 | EU7: =ET7-ET6 -> 0 | EV7: =(ET7/'Finance Only'!B10)*100 -> 0 | EW7: =EX6 -> 73006 | EX7: 73218 | EY7: =MAX(0,EX7-EW7) -> 212 | EZ7: =EY7-EY6 -> -154 | FA7: =(EY7/'Finance Only'!G10)*100 -> 519.60784 | FB7: =FC6 -> 729940 | FC7: 731530 | FD7: =MAX(0,FC7-FB7) -> 1590 | FE7: =FD7-FD6 -> -2880 | FF7: =(FD7/'Finance Only'!M10)*100 -> #DIV/0! | FH7: =SUM(E7+J7) -> 6859 | FJ7: =SUM(T7+Y7+DZ7+EE7+EJ7+EO7) -> 9304 | FL7: =SUM(AN7+AS7) -> 2080 | FN7: =SUM(AX7+BC7+BH7) -> 2171 | FP7: =SUM(BM7+BR7+ET7) -> 2410 | FR7: =SUM(EY7+FD7) -> 1802
A8: 4 | B8: ='Finance Only'!G11 -> 36.9 | C8: =D7 -> 26093621 | D8: 26096084 | E8: =MAX(0,D8-C8) -> 2463 | F8: =E8-E7 -> -18 | G8: =(E8/'Finance Only'!B11)*100 -> 9.0996416 | H8: =I7 -> 23545962 | I8: 23550078 | J8: =MAX(0,I8-H8) -> 4116 | K8: =J8-J7 -> -262 | L8: =(J8/'Finance Only'!B11)*100 -> 15.206709 | M8: =N7 -> 88410629 | N8: 88425253 | O8: =MAX(0,N8-M8) -> 14624 | P8: =O8-O7 -> 487 | Q8: =(O8/'Finance Only'!B11)*100 -> 54.028891 | R8: =S7 -> 2379200 | S8: 2381100 | T8: =MAX(0,S8-R8) -> 1900 | U8: =T8-T7 -> 100 | V8: =(T8/'Finance Only'!B11)*100 -> 7.019618 | W8: =X7 -> 3253486 | X8: 3256314 | Y8: =MAX(0,X8-W8) -> 2828 | Z8: =Y8-Y7 -> -26 | AA8: =(Y8/'Finance Only'!B11)*100 -> 10.448147 | AB8: =AC7 -> 2023200 | AC8: 2025700 | AD8: =MAX(0,AC8-AB8) -> 2500 | AE8: =AD8-AD7 -> -100 | AF8: =(AD8/'Finance Only'!B11)*100 -> 9.2363395 | AG8: =AH7 -> 887192 | AH8: 888077 | AI8: =MAX(0,AH8-AG8) -> 885 | AJ8: =AI8-AI7 -> 42 | AK8: =(AI8/'Finance Only'!B11)*100 -> 3.2696642 | AL8: =AM7 -> 897860 | AM8: 898500 | AN8: =MAX(0,AM8-AL8) -> 640 | AO8: =AN8-AN7 -> -40 | AP8: =(AN8/'Finance Only'!B11)*100 -> 2.3645029 | AQ8: =AR7 -> 2011900 | AR8: 2013700 | AS8: =MAX(0,AR8-AQ8) -> 1800 | AT8: =AS8-AS7 -> 400 | AU8: =(AS8/'Finance Only'!B11)*100 -> 6.6501644 | AV8: =AW7 -> 582607 | AW8: 582992 | AX8: =MAX(0,AW8-AV8) -> 385 | AY8: =AX8-AX7 -> -16 | AZ8: =(AX8/'Finance Only'!B11)*100 -> 1.4223963 | BA8: =BB7 -> 826970 | BB8: 827980 | BC8: =MAX(0,BB8-BA8) -> 1010 | BD8: =BC8-BC7 -> 100 | BE8: =(BC8/'Finance Only'!B11)*100 -> 3.7314811 | BF8: =BG7 -> 913080 | BG8: 914040 | BH8: =MAX(0,BG8-BF8) -> 960 | BI8: =BH8-BH7 -> 100 | BJ8: =(BH8/'Finance Only'!B11)*100 -> 3.5467544 | BK8: =BL7 -> 1415500 | BL8: 1416300 | BM8: =MAX(0,BL8-BK8) -> 800 | BN8: =BM8-BM7 -> 0 | BO8: =(BM8/'Finance Only'!B11)*100 -> 2.9556286 | BP8: =BQ7 -> 916640 | BQ8: 918330 | BR8: =MAX(0,BQ8-BP8) -> 1690 | BS8: =BR8-BR7 -> 80 | BT8: =(BR8/'Finance Only'!B11)*100 -> 6.2437655 | BU8: =BV7 -> 4460700 | BV8: 4465400 | BW8: =MAX(0,BV8-BU8) -> 4700 | BX8: =BW8-BW7 -> 300 | BY8: =(BW8/'Finance Only'!B11)*100 -> 17.364318 | BZ8: =CA7 -> 719990 | CA8: 721160 | CB8: =MAX(0,CA8-BZ8) -> 1170 | CC8: =CB8-CB7 -> -10 | CD8: =(CB8/'Finance Only'!B11)*100 -> 4.3226069 | CE8: =CF7 -> 221640 | CF8: 222000 | CG8: =MAX(0,CF8-CE8) -> 360 | CH8: =CG8-CG7 -> -90 | CI8: =(CG8/'Finance Only'!B11)*100 -> 1.3300329 | CJ8: =CK7 -> 501250 | CK8: 502200 | CL8: =MAX(0,CK8-CJ8) -> 950 | CM8: =CL8-CL7 -> -20 | CN8: =(CL8/'Finance Only'!B11)*100 -> 3.509809 | CO8: =CP7 -> 407370 | CP8: 408140 | CQ8: =MAX(0,CP8-CO8) -> 770 | CR8: =CQ8-CQ7 -> -100 | CS8: =(CQ8/'Finance Only'!B11)*100 -> 2.8447926 | CT8: =CU7 -> 343700 | CU8: 344320 | CV8: =MAX(0,CU8-CT8) -> 620 | CW8: =CV8-CV7 -> 10 | CX8: =(CV8/'Finance Only'!B11)*100 -> 2.2906122 | CY8: =CZ7 -> 596480 | CZ8: 597720 | DA8: =MAX(0,CZ8-CY8) -> 1240 | DB8: =DA8-DA7 -> 190 | DC8: =(DA8/'Finance Only'!B11)*100 -> 4.5812244 | DD8: =DE7 -> 447880 | DE8: 448660 | DF8: =MAX(0,DE8-DD8) -> 780 | DG8: =DF8-DF7 -> -40 | DH8: =(DF8/'Finance Only'!B11)*100 -> 2.8817379 | DI8: =DJ7 -> 409530 | DJ8: 410240 | DK8: =MAX(0,DJ8-DI8) -> 710 | DL8: =DK8-DK7 -> -30 | DM8: =(DK8/'Finance Only'!B11)*100 -> 2.6231204 | DN8: =DO7 -> 239850 | DO8: 240030 | DP8: =MAX(0,DO8-DN8) -> 180 | DQ8: =DP8-DP7 -> 10 | DR8: =(DP8/'Finance Only'!B11)*100 -> 0.66501644 | DS8: =DT7 -> 71943 | DT8: 72095 | DU8: =MAX(0,DT8-DS8) -> 152 | DV8: =DU8-DU7 -> 27 | DW8: =(DU8/'Finance Only'!B11)*100 -> 0.56156944 | DX8: =DY7 -> 467160 | DY8: 467920 | DZ8: =MAX(0,DY8-DX8) -> 760 | EA8: =DZ8-DZ7 -> 80 | EB8: =(DZ8/'Finance Only'!B11)*100 -> 2.8078472 | EC8: =ED7 -> 148950 | ED8: 149720 | EE8: =MAX(0,ED8-EC8) -> 770 | EF8: =EE8-EE7 -> 520 | EG8: =(EE8/'Finance Only'!B11)*100 -> 2.8447926 | EH8: =EI7 -> 149570 | EI8: 149910 | EJ8: =MAX(0,EI8-EH8) -> 340 | EK8: =EJ8-EJ7 -> 120 | EL8: =(EJ8/'Finance Only'!B11)*100 -> 1.2561422 | EM8: =EN7 -> 278420 | EN8: 275970 | EO8: =MAX(0,EN8-EM8) -> 0 | EP8: =EO8-EO7 -> -3500 | EQ8: =(EO8/'Finance Only'!B11)*100 -> 0 | ER8: =ES7 -> 0 | ET8: =MAX(0,ES8-ER8) -> 0 | EU8: =ET8-ET7 -> 0 | EV8: =(ET8/'Finance Only'!B11)*100 -> 0 | EW8: =EX7 -> 73218 | EX8: 73619 | EY8: =MAX(0,EX8-EW8) -> 401 | EZ8: =EY8-EY7 -> 189 | FA8: =(EY8/'Finance Only'!G11)*100 -> 1086.7209 | FB8: =FC7 -> 731530 | FC8: 735980 | FD8: =MAX(0,FC8-FB8) -> 4450 | FE8: =FD8-FD7 -> 2860 | FF8: =(FD8/'Finance Only'!M11)*100 -> #DIV/0! | FH8: =SUM(E8+J8) -> 6579 | FJ8: =SUM(T8+Y8+DZ8+EE8+EJ8+EO8) -> 6598 | FL8: =SUM(AN8+AS8) -> 2440 | FN8: =SUM(AX8+BC8+BH8) -> 2355 | FP8: =SUM(BM8+BR8+ET8) -> 2490 | FR8: =SUM(EY8+FD8) -> 4851
A9: 5 | B9: ='Finance Only'!G12 -> 28.2 | C9: =D8 -> 26096084 | D9: 26098701 | E9: =MAX(0,D9-C9) -> 2617 | F9: =E9-E8 -> 154 | G9: =(E9/'Finance Only'!B12)*100 -> 10.193589 | H9: =I8 -> 23550078 | I9: 23554307 | J9: =MAX(0,I9-H9) -> 4229 | K9: =J9-J8 -> 113 | L9: =(J9/'Finance Only'!B12)*100 -> 16.472559 | M9: =N8 -> 88425253 | N9: 88438795 | O9: =MAX(0,N9-M9) -> 13542 | P9: =O9-O8 -> -1082 | Q9: =(O9/'Finance Only'!B12)*100 -> 52.748023 | R9: =S8 -> 2381100 | S9: 2382800 | T9: =MAX(0,S9-R9) -> 1700 | U9: =T9-T8 -> -200 | V9: =(T9/'Finance Only'!B12)*100 -> 6.6217427 | W9: =X8 -> 3256314 | X9: 3259191 | Y9: =MAX(0,X9-W9) -> 2877 | Z9: =Y9-Y8 -> 49 | AA9: =(Y9/'Finance Only'!B12)*100 -> 11.206326 | AB9: =AC8 -> 2025700 | AC9: 2028100 | AD9: =MAX(0,AC9-AB9) -> 2400 | AE9: =AD9-AD8 -> -100 | AF9: =(AD9/'Finance Only'!B12)*100 -> 9.3483426 | AG9: =AH8 -> 888077 | AH9: 888948 | AI9: =MAX(0,AH9-AG9) -> 871 | AJ9: =AI9-AI8 -> -14 | AK9: =(AI9/'Finance Only'!B12)*100 -> 3.3926693 | AL9: =AM8 -> 898500 | AM9: 899190 | AN9: =MAX(0,AM9-AL9) -> 690 | AO9: =AN9-AN8 -> 50 | AP9: =(AN9/'Finance Only'!B12)*100 -> 2.6876485 | AQ9: =AR8 -> 2013700 | AR9: 2015100 | AS9: =MAX(0,AR9-AQ9) -> 1400 | AT9: =AS9-AS8 -> -400 | AU9: =(AS9/'Finance Only'!B12)*100 -> 5.4531999 | AV9: =AW8 -> 582992 | AW9: 583366 | AX9: =MAX(0,AW9-AV9) -> 374 | AY9: =AX9-AX8 -> -11 | AZ9: =(AX9/'Finance Only'!B12)*100 -> 1.4567834 | BA9: =BB8 -> 827980 | BB9: 828810 | BC9: =MAX(0,BB9-BA9) -> 830 | BD9: =BC9-BC8 -> -180 | BE9: =(BC9/'Finance Only'!B12)*100 -> 3.2329685 | BF9: =BG8 -> 914040 | BG9: 914940 | BH9: =MAX(0,BG9-BF9) -> 900 | BI9: =BH9-BH8 -> -60 | BJ9: =(BH9/'Finance Only'!B12)*100 -> 3.5056285 | BK9: =BL8 -> 1416300 | BL9: 1416900 | BM9: =MAX(0,BL9-BK9) -> 600 | BN9: =BM9-BM8 -> -200 | BO9: =(BM9/'Finance Only'!B12)*100 -> 2.3370857 | BP9: =BQ8 -> 918330 | BQ9: 919890 | BR9: =MAX(0,BQ9-BP9) -> 1560 | BS9: =BR9-BR8 -> -130 | BT9: =(BR9/'Finance Only'!B12)*100 -> 6.0764227 | BU9: =BV8 -> 4465400 | BV9: 4469400 | BW9: =MAX(0,BV9-BU9) -> 4000 | BX9: =BW9-BW8 -> -700 | BY9: =(BW9/'Finance Only'!B12)*100 -> 15.580571 | BZ9: =CA8 -> 721160 | CA9: 722370 | CB9: =MAX(0,CA9-BZ9) -> 1210 | CC9: =CB9-CB8 -> 40 | CD9: =(CB9/'Finance Only'!B12)*100 -> 4.7131227 | CE9: =CF8 -> 222000 | CF9: 222370 | CG9: =MAX(0,CF9-CE9) -> 370 | CH9: =CG9-CG8 -> 10 | CI9: =(CG9/'Finance Only'!B12)*100 -> 1.4412028 | CJ9: =CK8 -> 502200 | CK9: 503110 | CL9: =MAX(0,CK9-CJ9) -> 910 | CM9: =CL9-CL8 -> -40 | CN9: =(CL9/'Finance Only'!B12)*100 -> 3.5445799 | CO9: =CP8 -> 408140 | CP9: 408980 | CQ9: =MAX(0,CP9-CO9) -> 840 | CR9: =CQ9-CQ8 -> 70 | CS9: =(CQ9/'Finance Only'!B12)*100 -> 3.2719199 | CT9: =CU8 -> 344320 | CU9: 344930 | CV9: =MAX(0,CU9-CT9) -> 610 | CW9: =CV9-CV8 -> -10 | CX9: =(CV9/'Finance Only'!B12)*100 -> 2.3760371 | CY9: =CZ8 -> 597720 | CZ9: 598800 | DA9: =MAX(0,CZ9-CY9) -> 1080 | DB9: =DA9-DA8 -> -160 | DC9: =(DA9/'Finance Only'!B12)*100 -> 4.2067542 | DD9: =DE8 -> 448660 | DE9: 449530 | DF9: =MAX(0,DE9-DD9) -> 870 | DG9: =DF9-DF8 -> 90 | DH9: =(DF9/'Finance Only'!B12)*100 -> 3.3887742 | DI9: =DJ8 -> 410240 | DJ9: 410980 | DK9: =MAX(0,DJ9-DI9) -> 740 | DL9: =DK9-DK8 -> 30 | DM9: =(DK9/'Finance Only'!B12)*100 -> 2.8824056 | DN9: =DO8 -> 240030 | DO9: 240200 | DP9: =MAX(0,DO9-DN9) -> 170 | DQ9: =DP9-DP8 -> -10 | DR9: =(DP9/'Finance Only'!B12)*100 -> 0.66217427 | DS9: =DT8 -> 72095 | DT9: 72236 | DU9: =MAX(0,DT9-DS9) -> 141 | DV9: =DU9-DU8 -> -11 | DW9: =(DU9/'Finance Only'!B12)*100 -> 0.54921513 | DX9: =DY8 -> 467920 | DY9: 468620 | DZ9: =MAX(0,DY9-DX9) -> 700 | EA9: =DZ9-DZ8 -> -60 | EB9: =(DZ9/'Finance Only'!B12)*100 -> 2.7265999 | EC9: =ED8 -> 149720 | ED9: 149500 | EE9: =MAX(0,ED9-EC9) -> 0 | EF9: =EE9-EE8 -> -770 | EG9: =(EE9/'Finance Only'!B12)*100 -> 0 | EH9: =EI8 -> 149910 | EI9: 150290 | EJ9: =MAX(0,EI9-EH9) -> 380 | EK9: =EJ9-EJ8 -> 40 | EL9: =(EJ9/'Finance Only'!B12)*100 -> 1.4801542 | EM9: =EN8 -> 275970 | EN9: 276490 | EO9: =MAX(0,EN9-EM9) -> 520 | EP9: =EO9-EO8 -> 520 | EQ9: =(EO9/'Finance Only'!B12)*100 -> 2.0254742 | ER9: =ES8 -> 0 | ET9: =MAX(0,ES9-ER9) -> 0 | EU9: =ET9-ET8 -> 0 | EV9: =(ET9/'Finance Only'!B12)*100 -> 0 | EW9: =EX8 -> 73619 | EX9: 74899 | EY9: =MAX(0,EX9-EW9) -> 1280 | EZ9: =EY9-EY8 -> 879 | FA9: =(EY9/'Finance Only'!G12)*100 -> 4539.0071 | FB9: =FC8 -> 735980 | FC9: 740190 | FD9: =MAX(0,FC9-FB9) -> 4210 | FE9: =FD9-FD8 -> -240 | FF9: =(FD9/'Finance Only'!M12)*100 -> #DIV/0! | FH9: =SUM(E9+J9) -> 6846 | FJ9: =SUM(T9+Y9+DZ9+EE9+EJ9+EO9) -> 6177 | FL9: =SUM(AN9+AS9) -> 2090 | FN9: =SUM(AX9+BC9+BH9) -> 2104 | FP9: =SUM(BM9+BR9+ET9) -> 2160 | FR9: =SUM(EY9+FD9) -> 5490
