Workbook

Sheet Submetering
A1: Site Name | B1: Day | C1: Month | D1: Year | E1: Transport Consumption (LT) | F1: Generators Consumption (LT) | G1: Total Electricity Kwh | H1: Kitchen (KWh) | I1: Laundry (KWh) | J1: STP (M3) | K1: RO prodution (M3) | L1: Amani Restaurant (M3) | M1: Kitchen (M3) | N1: Laundry (M3) | O1: Laundry (M3) | P1: Total water Consumption (M3) | Q1: Borehole #1 (M3) | R1: Borehole #2 (M3) | S1: Borehole #3 (M3) | T1: Borehole #4 (M3) | U1: Borehole #5 (M3) | V1: Borehole #6 (M3) | W1: Total Bore holes production (M3) | X1: Room Nights
A2: Serengeti | B2: 1 | C2: 12 | D2: 2021 | E2: ='UTILITY REPORT 1'!I3 -> 55.31 | F2: ='UTILITY REPORT 1'!E3 -> 1340.69 | G2: ='UTILITY REPORT 1'!F3 -> 3130 | H2: =IF('Kit report'!F4<0,"0",'Kit report'!F4) -> 240 | I2: =IF('Kit report'!X4<0,"0",'Kit report'!X4) -> 0 | J2: =IF('Utility summery'!H6<0,"0",'Utility summery'!H6) -> 73 | K2: =IF('UTILITY REPORT 1'!H3<0,"0",'UTILITY REPORT 1'!H3) -> 35 | L2: ='Water-Meter'!K6 -> 1 | M2: ='Water-Meter'!H6 -> 0 | N2: ='Water-Meter'!Q6 -> 7 | O2: =K2*E2+H2*I2+#REF!*#REF!+J2*L2 -> #REF! | P2: ='Water-Meter'!E6 -> 79 | Q2: =IF('Water-Meter'!U6<0,"0",'Water-Meter'!U6) -> 35 | R2: =IF('Water-Meter'!X6<0,"0",'Water-Meter'!X6) -> 0 | S2: =IF('Water-Meter'!AA6<0,"0",'Water-Meter'!AA6) -> 36 | T2: =IF('Water-Meter'!AD6<0,"0",'Water-Meter'!AD6) -> 26 | U2: =IF('Water-Meter'!AG6<0,"0",'Water-Meter'!AG6) -> 0 | V2: =IF('Water-Meter'!AJ6<0,"0",'Water-Meter'!AJ6) -> 35 | W2: ='Water-Meter'!AN6 -> 132 | X2: 6
A3: Serengeti | B3: =B2+1 -> 2 | C3: 12 | D3: 2021 | E3: ='UTILITY REPORT 1'!I4 -> 596.04 | F3: ='UTILITY REPORT 1'!E4 -> 1268.81 | G3: ='UTILITY REPORT 1'!F4 -> 3105 | H3: =IF('Kit report'!F5<0,"0",'Kit report'!F5) -> 240 | I3: =IF('Kit report'!X5<0,"0",'Kit report'!X5) -> 440 | J3: =IF('Utility summery'!H7<0,"0",'Utility summery'!H7) -> 69 | K3: =IF('UTILITY REPORT 1'!H4<0,"0",'UTILITY REPORT 1'!H4) -> 61 | L3: ='Water-Meter'!K7 -> 2 | M3: ='Water-Meter'!H7 -> 0 | N3: ='Water-Meter'!Q7 -> 5 | O3: =K3*E3+H3*I3+#REF!*#REF!+J3*L3 -> #REF! | P3: ='Water-Meter'!E7 -> 67 | Q3: =IF('Water-Meter'!U7<0,"0",'Water-Meter'!U7) -> 0 | R3: =IF('Water-Meter'!X7<0,"0",'Water-Meter'!X7) -> 0 | S3: =IF('Water-Meter'!AA7<0,"0",'Water-Meter'!AA7) -> 37 | T3: =IF('Water-Meter'!AD7<0,"0",'Water-Meter'!AD7) -> 1 | U3: =IF('Water-Meter'!AG7<0,"0",'Water-Meter'!AG7) -> 0 | V3: =IF('Water-Meter'!AJ7<0,"0",'Water-Meter'!AJ7) -> 36 | W3: ='Water-Meter'!AN7 -> 74 | X3: 5
A4: Serengeti | B4: =B3+1 -> 3 | C4: 12 | D4: 2021 | E4: ='UTILITY REPORT 1'!I5 -> 0 | F4: ='UTILITY REPORT 1'!E5 -> 1177.17 | G4: ='UTILITY REPORT 1'!F5 -> 2910 | H4: =IF('Kit report'!F6<0,"0",'Kit report'!F6) -> 252 | I4: =IF('Kit report'!X6<0,"0",'Kit report'!X6) -> 320 | J4: =IF('Utility summery'!H8<0,"0",'Utility summery'!H8) -> 70 | K4: =IF('UTILITY REPORT 1'!H5<0,"0",'UTILITY REPORT 1'!H5) -> 50 | L4: ='Water-Meter'!K8 -> 2 | M4: ='Water-Meter'!H8 -> 0 | N4: ='Water-Meter'!Q8 -> 3 | O4: =K4*E4+H4*I4+#REF!*#REF!+J4*L4 -> #REF! | P4: ='Water-Meter'!E8 -> 83 | Q4: =IF('Water-Meter'!U8<0,"0",'Water-Meter'!U8) -> 0 | R4: =IF('Water-Meter'!X8<0,"0",'Water-Meter'!X8) -> 0 | S4: =IF('Water-Meter'!AA8<0,"0",'Water-Meter'!AA8) -> 38 | T4: =IF('Water-Meter'!AD8<0,"0",'Water-Meter'!AD8) -> 10 | U4: =IF('Water-Meter'!AG8<0,"0",'Water-Meter'!AG8) -> 0 | V4: =IF('Water-Meter'!AJ8<0,"0",'Water-Meter'!AJ8) -> 36 | W4: ='Water-Meter'!AN8 -> 84 | X4: 3
A5: Serengeti | B5: =B4+1 -> 4 | C5: 12 | D5: 2021 | E5: ='UTILITY REPORT 1'!I6 -> 199.51 | F5: ='UTILITY REPORT 1'!E6 -> 1293.22 | G5: ='UTILITY REPORT 1'!F6 -> 3289 | H5: =IF('Kit report'!F7<0,"0",'Kit report'!F7) -> 276 | I5: =IF('Kit report'!X7<0,"0",'Kit report'!X7) -> 340 | J5: =IF('Utility summery'!H9<0,"0",'Utility summery'!H9) -> 63 | K5: =IF('UTILITY REPORT 1'!H6<0,"0",'UTILITY REPORT 1'!H6) -> 89 | L5: ='Water-Meter'!K9 -> 13 | M5: ='Water-Meter'!H9 -> 0 | N5: ='Water-Meter'!Q9 -> 5 | O5: =K5*E5+H5*I5+#REF!*#REF!+J5*L5 -> #REF! | P5: ='Water-Meter'!E9 -> 67 | Q5: =IF('Water-Meter'!U9<0,"0",'Water-Meter'!U9) -> 0 | R5: =IF('Water-Meter'!X9<0,"0",'Water-Meter'!X9) -> 0 | S5: =IF('Water-Meter'!AA9<0,"0",'Water-Meter'!AA9) -> 33 | T5: =IF('Water-Meter'!AD9<0,"0",'Water-Meter'!AD9) -> 15 | U5: =IF('Water-Meter'!AG9<0,"0",'Water-Meter'!AG9) -> 0 | V5: =IF('Water-Meter'!AJ9<0,"0",'Water-Meter'!AJ9) -> 33 | W5: ='Water-Meter'!AN9 -> 81 | X5: 8
A6: Serengeti | B6: =B5+1 -> 5 | C6: 12 | D6: 2021 | E6: ='UTILITY REPORT 1'!I7 -> 53.33 | F6: ='UTILITY REPORT 1'!E7 -> 1246.93 | G6: ='UTILITY REPORT 1'!F7 -> 3146 | H6: =IF('Kit report'!F8<0,"0",'Kit report'!F8) -> 216 | I6: =IF('Kit report'!X8<0,"0",'Kit report'!X8) -> 300 | J6: =IF('Utility summery'!H10<0,"0",'Utility summery'!H10) -> 47 | K6: =IF('UTILITY REPORT 1'!H7<0,"0",'UTILITY REPORT 1'!H7) -> 103 | L6: ='Water-Meter'!K10 -> 6 | M6: ='Water-Meter'!H10 -> 0 | N6: ='Water-Meter'!Q10 -> 4 | O6: =K6*E6+H6*I6+#REF!*#REF!+J6*L6 -> #REF! | P6: ='Water-Meter'!E10 -> 62 | Q6: =IF('Water-Meter'!U10<0,"0",'Water-Meter'!U10) -> 0 | R6: =IF('Water-Meter'!X10<0,"0",'Water-Meter'!X10) -> 0 | S6: =IF('Water-Meter'!AA10<0,"0",'Water-Meter'!AA10) -> 35 | T6: =IF('Water-Meter'!AD10<0,"0",'Water-Meter'!AD10) -> 14 | U6: =IF('Water-Meter'!AG10<0,"0",'Water-Meter'!AG10) -> 0 | V6: =IF('Water-Meter'!AJ10<0,"0",'Water-Meter'!AJ10) -> 35 | W6: ='Water-Meter'!AN10 -> 84 | X6: 6
A7: Serengeti | B7: =B6+1 -> 6 | C7: 12 | D7: 2021 | E7: ='UTILITY REPORT 1'!I8 -> 67.4 | F7: ='UTILITY REPORT 1'!E8 -> 1325.89 | G7: ='UTILITY REPORT 1'!F8 -> 3361 | H7: =IF('Kit report'!F9<0,"0",'Kit report'!F9) -> 228 | I7: =IF('Kit report'!X9<0,"0",'Kit report'!X9) -> 320 | J7: =IF('Utility summery'!H11<0,"0",'Utility summery'!H11) -> 53 | K7: =IF('UTILITY REPORT 1'!H8<0,"0",'UTILITY REPORT 1'!H8) -> 17 | L7: ='Water-Meter'!K11 -> 2 | M7: ='Water-Meter'!H11 -> 0 | N7: ='Water-Meter'!Q11 -> 5 | O7: =K7*E7+H7*I7+#REF!*#REF!+J7*L7 -> #REF! | P7: ='Water-Meter'!E11 -> 57 | Q7: =IF('Water-Meter'!U11<0,"0",'Water-Meter'!U11) -> 0 | R7: =IF('Water-Meter'!X11<0,"0",'Water-Meter'!X11) -> 0 | S7: =IF('Water-Meter'!AA11<0,"0",'Water-Meter'!AA11) -> 35 | T7: =IF('Water-Meter'!AD11<0,"0",'Water-Meter'!AD11) -> 2 | U7: =IF('Water-Meter'!AG11<0,"0",'Water-Meter'!AG11) -> 0 | V7: =IF('Water-Meter'!AJ11<0,"0",'Water-Meter'!AJ11) -> 35 | W7: ='Water-Meter'!AN11 -> 72 | X7: 9
A8: Serengeti | B8: =B7+1 -> 7 | C8: 12 | D8: 2021 | E8: ='UTILITY REPORT 1'!I9 -> 135.94 | F8: ='UTILITY REPORT 1'!E9 -> 1368.94 | G8: ='UTILITY REPORT 1'!F9 -> 3380 | H8: =IF('Kit report'!F10<0,"0",'Kit report'!F10) -> 228 | I8: =IF('Kit report'!X10<0,"0",'Kit report'!X10) -> 320 | J8: =IF('Utility summery'!H12<0,"0",'Utility summery'!H12) -> 50 | K8: =IF('UTILITY REPORT 1'!H9<0,"0",'UTILITY REPORT 1'!H9) -> 121 | L8: ='Water-Meter'!K12 -> 3 | M8: ='Water-Meter'!H12 -> 0 | N8: ='Water-Meter'!Q12 -> 7 | O8: =K8*E8+H8*I8+#REF!*#REF!+J8*L8 -> #REF! | P8: ='Water-Meter'!E12 -> 73 | Q8: =IF('Water-Meter'!U12<0,"0",'Water-Meter'!U12) -> 0 | R8: =IF('Water-Meter'!X12<0,"0",'Water-Meter'!X12) -> 0 | S8: =IF('Water-Meter'!AA12<0,"0",'Water-Meter'!AA12) -> 37 | T8: =IF('Water-Meter'!AD12<0,"0",'Water-Meter'!AD12) -> 0 | U8: =IF('Water-Meter'!AG12<0,"0",'Water-Meter'!AG12) -> 0 | V8: =IF('Water-Meter'!AJ12<0,"0",'Water-Meter'!AJ12) -> 35 | W8: ='Water-Meter'!AN12 -> 72 | X8: 9
A9: Serengeti | B9: =B8+1 -> 8 | C9: 12 | D9: 2021 | E9: ='UTILITY REPORT 1'!I10 -> 83.59 | F9: ='UTILITY REPORT 1'!E10 -> 1527.6 | G9: ='UTILITY REPORT 1'!F10 -> 3662 | H9: =IF('Kit report'!F11<0,"0",'Kit report'!F11) -> 240 | I9: =IF('Kit report'!X11<0,"0",'Kit report'!X11) -> 440 | J9: =IF('Utility summery'!H13<0,"0",'Utility summery'!H13) -> 63 | K9: =IF('UTILITY REPORT 1'!H10<0,"0",'UTILITY REPORT 1'!H10) -> 170 | L9: ='Water-Meter'!K13 -> 3 | M9: ='Water-Meter'!H13 -> 0 | N9: ='Water-Meter'!Q13 -> 6 | O9: =K9*E9+H9*I9+#REF!*#REF!+J9*L9 -> #REF! | P9: ='Water-Meter'!E13 -> 80 | Q9: =IF('Water-Meter'!U13<0,"0",'Water-Meter'!U13) -> 74 | R9: =IF('Water-Meter'!X13<0,"0",'Water-Meter'!X13) -> 0 | S9: =IF('Water-Meter'!AA13<0,"0",'Water-Meter'!AA13) -> 35 | T9: =IF('Water-Meter'!AD13<0,"0",'Water-Meter'!AD13) -> 0 | U9: =IF('Water-Meter'!AG13<0,"0",'Water-Meter'!AG13) -> 0 | V9: =IF('Water-Meter'!AJ13<0,"0",'Water-Meter'!AJ13) -> 35 | W9: ='Water-Meter'!AN13 -> 144 | X9: 12
A10: Serengeti | B10: =B9+1 -> 9 | C10: 12 | D10: 2021 | E10: ='UTILITY REPORT 1'!I11 -> 51.98 | F10: ='UTILITY REPORT 1'!E11 -> 1371.66 | G10: ='UTILITY REPORT 1'!F11 -> 3399 | H10: =IF('Kit report'!F12<0,"0",'Kit report'!F12) -> 240 | I10: =IF('Kit report'!X12<0,"0",'Kit report'!X12) -> 320 | J10: =IF('Utility summery'!H14<0,"0",'Utility summery'!H14) -> 55 | K10: =IF('UTILITY REPORT 1'!H11<0,"0",'UTILITY REPORT 1'!H11) -> 0 | L10: ='Water-Meter'!K14 -> 2 | M10: ='Water-Meter'!H14 -> 0 | N10: ='Water-Meter'!Q14 -> 3 | O10: =K10*E10+H10*I10+#REF!*#REF!+J10*L10 -> #REF! | P10: ='Water-Meter'!E14 -> 65 | Q10: =IF('Water-Meter'!U14<0,"0",'Water-Meter'!U14) -> 68 | R10: =IF('Water-Meter'!X14<0,"0",'Water-Meter'!X14) -> 0 | S10: =IF('Water-Meter'!AA14<0,"0",'Water-Meter'!AA14) -> 34 | T10: =IF('Water-Meter'!AD14<0,"0",'Water-Meter'!AD14) -> 0 | U10: =IF('Water-Meter'!AG14<0,"0",'Water-Meter'!AG14) -> 0 | V10: =IF('Water-Meter'!AJ14<0,"0",'Water-Meter'!AJ14) -> 33 | W10: ='Water-Meter'!AN14 -> 135 | X10: 10
A11: Serengeti | B11: =B10+1 -> 10 | C11: 12 | D11: 2021 | E11: ='UTILITY REPORT 1'!I12 -> 448.65 | F11: ='UTILITY REPORT 1'!E12 -> 1347.33 | G11: ='UTILITY REPORT 1'!F12 -> 3440 | H11: =IF('Kit report'!F13<0,"0",'Kit report'!F13) -> 252 | I11: =IF('Kit report'!X13<0,"0",'Kit report'!X13) -> 380 | J11: =IF('Utility summery'!H15<0,"0",'Utility summery'!H15) -> 54 | K11: =IF('UTILITY REPORT 1'!H12<0,"0",'UTILITY REPORT 1'!H12) -> 167 | L11: ='Water-Meter'!K15 -> 1 | M11: ='Water-Meter'!H15 -> 0 | N11: ='Water-Meter'!Q15 -> 6 | O11: =K11*E11+H11*I11+#REF!*#REF!+J11*L11 -> #REF! | P11: ='Water-Meter'!E15 -> 71 | Q11: =IF('Water-Meter'!U15<0,"0",'Water-Meter'!U15) -> 73 | R11: =IF('Water-Meter'!X15<0,"0",'Water-Meter'!X15) -> 0 | S11: =IF('Water-Meter'!AA15<0,"0",'Water-Meter'!AA15) -> 37 | T11: =IF('Water-Meter'!AD15<0,"0",'Water-Meter'!AD15) -> 0 | U11: =IF('Water-Meter'!AG15<0,"0",'Water-Meter'!AG15) -> 0 | V11: =IF('Water-Meter'!AJ15<0,"0",'Water-Meter'!AJ15) -> 36 | W11: ='Water-Meter'!AN15 -> 146 | X11: 12
A12: Serengeti | B12: =B11+1 -> 11 | C12: 12 | D12: 2021 | E12: ='UTILITY REPORT 1'!I13 -> 37.87 | F12: ='UTILITY REPORT 1'!E13 -> 1512.79 | G12: ='UTILITY REPORT 1'!F13 -> 3696 | H12: =IF('Kit report'!F14<0,"0",'Kit report'!F14) -> 228 | I12: =IF('Kit report'!X14<0,"0",'Kit report'!X14) -> 340 | J12: =IF('Utility summery'!H16<0,"0",'Utility summery'!H16) -> 60 | K12: =IF('UTILITY REPORT 1'!H13<0,"0",'UTILITY REPORT 1'!H13) -> 15 | L12: ='Water-Meter'!K16 -> 2 | M12: ='Water-Meter'!H16 -> 0 | N12: ='Water-Meter'!Q16 -> 4 | O12: =K12*E12+H12*I12+#REF!*#REF!+J12*L12 -> #REF! | P12: ='Water-Meter'!E16 -> 72 | Q12: =IF('Water-Meter'!U16<0,"0",'Water-Meter'!U16) -> 69 | R12: =IF('Water-Meter'!X16<0,"0",'Water-Meter'!X16) -> 0 | S12: =IF('Water-Meter'!AA16<0,"0",'Water-Meter'!AA16) -> 36 | T12: =IF('Water-Meter'!AD16<0,"0",'Water-Meter'!AD16) -> 0 | U12: =IF('Water-Meter'!AG16<0,"0",'Water-Meter'!AG16) -> 0 | V12: =IF('Water-Meter'!AJ16<0,"0",'Water-Meter'!AJ16) -> 35 | W12: ='Water-Meter'!AN16 -> 140 | X12: 12
A13: Serengeti | B13: =B12+1 -> 12 | C13: 12 | D13: 2021 | E13: ='UTILITY REPORT 1'!I14 -> 68.16 | F13: ='UTILITY REPORT 1'!E14 -> 1485.24 | G13: ='UTILITY REPORT 1'!F14 -> 3646 | H13: =IF('Kit report'!F15<0,"0",'Kit report'!F15) -> 264 | I13: =IF('Kit report'!X15<0,"0",'Kit report'!X15) -> 440 | J13: =IF('Utility summery'!H17<0,"0",'Utility summery'!H17) -> 62 | K13: =IF('UTILITY REPORT 1'!H14<0,"0",'UTILITY REPORT 1'!H14) -> 157 | L13: ='Water-Meter'!K17 -> 2 | M13: ='Water-Meter'!H17 -> 0 | N13: ='Water-Meter'!Q17 -> 5 | O13: =K13*E13+H13*I13+#REF!*#REF!+J13*L13 -> #REF! | P13: ='Water-Meter'!E17 -> 65 | Q13: =IF('Water-Meter'!U17<0,"0",'Water-Meter'!U17) -> 69 | R13: =IF('Water-Meter'!X17<0,"0",'Water-Meter'!X17) -> 0 | S13: =IF('Water-Meter'!AA17<0,"0",'Water-Meter'!AA17) -> 37 | T13: =IF('Water-Meter'!AD17<0,"0",'Water-Meter'!AD17) -> 0 | U13: =IF('Water-Meter'!AG17<0,"0",'Water-Meter'!AG17) -> 0 | V13: =IF('Water-Meter'!AJ17<0,"0",'Water-Meter'!AJ17) -> 35 | W13: ='Water-Meter'!AN17 -> 141 | X13: 12
A14: Serengeti | B14: =B13+1 -> 13 | C14: 12 | D14: 2021 | E14: ='UTILITY REPORT 1'!I15 -> 103.25 | F14: ='UTILITY REPORT 1'!E15 -> 1579.63 | G14: ='UTILITY REPORT 1'!F15 -> 3967 | H14: =IF('Kit report'!F16<0,"0",'Kit report'!F16) -> 276 | I14: =IF('Kit report'!X16<0,"0",'Kit report'!X16) -> 560 | J14: =IF('Utility summery'!H18<0,"0",'Utility summery'!H18) -> 66 | K14: =IF('UTILITY REPORT 1'!H15<0,"0",'UTILITY REPORT 1'!H15) -> 44 | L14: ='Water-Meter'!K18 -> 3 | M14: ='Water-Meter'!H18 -> 0 | N14: ='Water-Meter'!Q18 -> 7 | O14: =K14*E14+H14*I14+#REF!*#REF!+J14*L14 -> #REF! | P14: ='Water-Meter'!E18 -> 68 | Q14: =IF('Water-Meter'!U18<0,"0",'Water-Meter'!U18) -> 69 | R14: =IF('Water-Meter'!X18<0,"0",'Water-Meter'!X18) -> 0 | S14: =IF('Water-Meter'!AA18<0,"0",'Water-Meter'!AA18) -> 39 | T14: =IF('Water-Meter'!AD18<0,"0",'Water-Meter'!AD18) -> 0 | U14: =IF('Water-Meter'!AG18<0,"0",'Water-Meter'!AG18) -> 0 | V14: =IF('Water-Meter'!AJ18<0,"0",'Water-Meter'!AJ18) -> 38 | W14: ='Water-Meter'!AN18 -> 146 | X14: 15
... A30: Serengeti | B30: =B29+1 -> 29 | C30: 12 | D30: 2021 | E30: ='UTILITY REPORT 1'!I31 -> 236.12 | F30: ='UTILITY REPORT 1'!E31 -> 2039.95 | G30: ='UTILITY REPORT 1'!F31 -> 4892 | H30: =IF('Kit report'!F32<0,"0",'Kit report'!F32) -> 180 | I30: =IF('Kit report'!X32<0,"0",'Kit report'!X32) -> 840 | J30: =IF('Utility summery'!H34<0,"0",'Utility summery'!H34) -> 63 | K30: =IF('UTILITY REPORT 1'!H31<0,"0",'UTILITY REPORT 1'!H31) -> 101 | L30: ='Water-Meter'!K34 -> 5 | M30: ='Water-Meter'!H34 -> 0 | N30: ='Water-Meter'!Q34 -> 14 | O30: =K30*E30+H30*I30+#REF!*#REF!+J30*L30 -> #REF! | P30: ='Water-Meter'!E34 -> 111 | Q30: =IF('Water-Meter'!U34<0,"0",'Water-Meter'!U34) -> 48 | R30: =IF('Water-Meter'!X34<0,"0",'Water-Meter'!X34) -> 0 | S30: =IF('Water-Meter'!AA34<0,"0",'Water-Meter'!AA34) -> 44 | T30: =IF('Water-Meter'!AD34<0,"0",'Water-Meter'!AD34) -> 15 | U30: =IF('Water-Meter'!AG34<0,"0",'Water-Meter'!AG34) -> 0 | V30: =IF('Water-Meter'!AJ34<0,"0",'Water-Meter'!AJ34) -> 37 | W30: ='Water-Meter'!AN34 -> 144 | X30: 42
A31: Serengeti | B31: 30 | C31: 12 | D31: 2021 | E31: ='UTILITY REPORT 1'!I32 -> 34.26 | F31: ='UTILITY REPORT 1'!E32 -> 2039.77 | G31: ='UTILITY REPORT 1'!F32 -> 4766 | H31: =IF('Kit report'!F33<0,"0",'Kit report'!F33) -> 216 | I31: =IF('Kit report'!X33<0,"0",'Kit report'!X33) -> 900 | J31: =IF('Utility summery'!H35<0,"0",'Utility summery'!H35) -> 49 | K31: =IF('UTILITY REPORT 1'!H32<0,"0",'UTILITY REPORT 1'!H32) -> 149 | L31: ='Water-Meter'!K35 -> 3 | M31: ='Water-Meter'!H35 -> 0 | N31: ='Water-Meter'!Q35 -> 10 | O31: =K31*E31+H31*I31+#REF!*#REF!+J31*L31 -> #REF! | P31: ='Water-Meter'!E35 -> 102 | Q31: =IF('Water-Meter'!U35<0,"0",'Water-Meter'!U35) -> 25 | R31: =IF('Water-Meter'!X35<0,"0",'Water-Meter'!X35) -> 0 | S31: =IF('Water-Meter'!AA35<0,"0",'Water-Meter'!AA35) -> 43 | T31: =IF('Water-Meter'!AD35<0,"0",'Water-Meter'!AD35) -> 14 | U31: =IF('Water-Meter'!AG35<0,"0",'Water-Meter'!AG35) -> 0 | V31: =IF('Water-Meter'!AJ35<0,"0",'Water-Meter'!AJ35) -> 36 | W31: ='Water-Meter'!AN35 -> 118 | X31: 48
A32: Serengeti | B32: 31 | C32: 12 | D32: 2021 | E32: ='UTILITY REPORT 1'!I33 -> 882.87 | F32: ='UTILITY REPORT 1'!E33 -> 1894.18 | G32: ='UTILITY REPORT 1'!F33 -> 4562 | H32: =IF('Kit report'!F34<0,"0",'Kit report'!F34) -> 264 | I32: =IF('Kit report'!X34<0,"0",'Kit report'!X34) -> 800 | J32: =IF('Utility summery'!H36<0,"0",'Utility summery'!H36) -> 51 | K32: =IF('UTILITY REPORT 1'!H33<0,"0",'UTILITY REPORT 1'!H33) -> 156 | L32: ='Water-Meter'!K36 -> 3 | M32: ='Water-Meter'!H36 -> 0 | N32: ='Water-Meter'!Q36 -> 9 | P32: ='Water-Meter'!E36 -> 102 | Q32: =IF('Water-Meter'!U36<0,"0",'Water-Meter'!U36) -> 0 | R32: =IF('Water-Meter'!X36<0,"0",'Water-Meter'!X36) -> 0 | S32: =IF('Water-Meter'!AA36<0,"0",'Water-Meter'!AA36) -> 39 | T32: =IF('Water-Meter'!AD36<0,"0",'Water-Meter'!AD36) -> 11 | U32: =IF('Water-Meter'!AG36<0,"0",'Water-Meter'!AG36) -> 0 | V32: =IF('Water-Meter'!AJ36<0,"0",'Water-Meter'!AJ36) -> 33 | W32: ='Water-Meter'!AN36 -> 83 | X32: 48

Sheet Total
A1: Site Name | B1: Day | C1: Month | D1: Year | E1: Total Electricity Kwh | F1: Electricity Tariff ($/Kwh) | G1: LPG (Kg) | H1: LPG $/Kg | I1: Water Utility Supply (m3) m3 | J1: Water Utility Supply (m3) $/m3 | K1: Room Nights | L1: Utilities day cost dh
A2: Serengeti | B2: 1 | C2: 12 | D2: 2021 | E2: ='UTILITY REPORT 1'!F3 -> 3130 | F2: =('UTILITY REPORT 1'!E3*'UTILITY REPORT 1'!D3)/'UTILITY REPORT 1'!F3 -> 0.42833546 | G2: =IF('Utility summery'!M6<0,"0",'Utility summery'!M6) -> 101.244 | H2: 2.165 | I2: =IF('UTILITY REPORT 1'!G3<0,"0",'UTILITY REPORT 1'!G3) -> 79 | J2: 0 | K2: =Submetering!X2 -> 6 | L2: =E2*F2+G2*H2+#REF!*#REF!+I2*J2 -> #REF!
A3: Serengeti | B3: =B2+1 -> 2 | C3: 12 | D3: 2021 | E3: ='UTILITY REPORT 1'!F4 -> 3105 | F3: =('UTILITY REPORT 1'!E4*'UTILITY REPORT 1'!D4)/'UTILITY REPORT 1'!F4 -> 0.40863446 | G3: =IF('Utility summery'!M7<0,"0",'Utility summery'!M7) -> 70.312 | H3: 2.165 | I3: =IF('UTILITY REPORT 1'!G4<0,"0",'UTILITY REPORT 1'!G4) -> 67 | J3: 0 | K3: =Submetering!X3 -> 5 | L3: =E3*F3+G3*H3+#REF!*#REF!+I3*J3 -> #REF!
A4: Serengeti | B4: =B3+1 -> 3 | C4: 12 | D4: 2021 | E4: ='UTILITY REPORT 1'!F5 -> 2910 | F4: =('UTILITY REPORT 1'!E5*'UTILITY REPORT 1'!D5)/'UTILITY REPORT 1'!F5 -> 0.40452577 | G4: =IF('Utility summery'!M8<0,"0",'Utility summery'!M8) -> 59.576 | H4: 2.165 | I4: =IF('UTILITY REPORT 1'!G5<0,"0",'UTILITY REPORT 1'!G5) -> 83 | J4: 0 | K4: =Submetering!X4 -> 3 | L4: =E4*F4+G4*H4+#REF!*#REF!+I4*J4 -> #REF!
A5: Serengeti | B5: =B4+1 -> 4 | C5: 12 | D5: 2021 | E5: ='UTILITY REPORT 1'!F6 -> 3289 | F5: =('UTILITY REPORT 1'!E6*'UTILITY REPORT 1'!D6)/'UTILITY REPORT 1'!F6 -> 0.3931955 | G5: =IF('Utility summery'!M9<0,"0",'Utility summery'!M9) -> 61.512 | H5: 2.165 | I5: =IF('UTILITY REPORT 1'!G6<0,"0",'UTILITY REPORT 1'!G6) -> 67 | J5: 0 | K5: =Submetering!X5 -> 8 | L5: =E5*F5+G5*H5+#REF!*#REF!+I5*J5 -> #REF!
A6: Serengeti | B6: =B5+1 -> 5 | C6: 12 | D6: 2021 | E6: ='UTILITY REPORT 1'!F7 -> 3146 | F6: =('UTILITY REPORT 1'!E7*'UTILITY REPORT 1'!D7)/'UTILITY REPORT 1'!F7 -> 0.3963541 | G6: =IF('Utility summery'!M10<0,"0",'Utility summery'!M10) -> 87.34 | H6: 2.165 | I6: =IF('UTILITY REPORT 1'!G7<0,"0",'UTILITY REPORT 1'!G7) -> 62 | J6: 0 | K6: =Submetering!X6 -> 6 | L6: =E6*F6+G6*H6+#REF!*#REF!+I6*J6 -> #REF!
A7: Serengeti | B7: =B6+1 -> 6 | C7: 12 | D7: 2021 | E7: ='UTILITY REPORT 1'!F8 -> 3361 | F7: =('UTILITY REPORT 1'!E8*'UTILITY REPORT 1'!D8)/'UTILITY REPORT 1'!F8 -> 0.39449271 | G7: =IF('Utility summery'!M11<0,"0",'Utility summery'!M11) -> 107.492 | H7: 2.165 | I7: =IF('UTILITY REPORT 1'!G8<0,"0",'UTILITY REPORT 1'!G8) -> 57 | J7: 0 | K7: =Submetering!X7 -> 9 | L7: =E7*F7+G7*H7+#REF!*#REF!+I7*J7 -> #REF!
A8: Serengeti | B8: =B7+1 -> 7 | C8: 12 | D8: 2021 | E8: ='UTILITY REPORT 1'!F9 -> 3380 | F8: =('UTILITY REPORT 1'!E9*'UTILITY REPORT 1'!D9)/'UTILITY REPORT 1'!F9 -> 0.40501183 | G8: =IF('Utility summery'!M12<0,"0",'Utility summery'!M12) -> 90.684 | H8: 2.165 | I8: =IF('UTILITY REPORT 1'!G9<0,"0",'UTILITY REPORT 1'!G9) -> 73 | J8: 0 | K8: =Submetering!X8 -> 9 | L8: =E8*F8+G8*H8+#REF!*#REF!+I8*J8 -> #REF!
A9: Serengeti | B9: =B8+1 -> 8 | C9: 12 | D9: 2021 | E9: ='UTILITY REPORT 1'!F10 -> 3662 | F9: =('UTILITY REPORT 1'!E10*'UTILITY REPORT 1'!D10)/'UTILITY REPORT 1'!F10 -> 0.4171491 | G9: =IF('Utility summery'!M13<0,"0",'Utility summery'!M13) -> 99.88 | H9: 2.165 | I9: =IF('UTILITY REPORT 1'!G10<0,"0",'UTILITY REPORT 1'!G10) -> 80 | J9: 0 | K9: =Submetering!X9 -> 12 | L9: =E9*F9+G9*H9+#REF!*#REF!+I9*J9 -> #REF!
A10: Serengeti | B10: =B9+1 -> 9 | C10: 12 | D10: 2021 | E10: ='UTILITY REPORT 1'!F11 -> 3399 | F10: =('UTILITY REPORT 1'!E11*'UTILITY REPORT 1'!D11)/'UTILITY REPORT 1'!F11 -> 0.4035481 | G10: =IF('Utility summery'!M14<0,"0",'Utility summery'!M14) -> 108.988 | H10: 2.165 | I10: =IF('UTILITY REPORT 1'!G11<0,"0",'UTILITY REPORT 1'!G11) -> 65 | J10: 0 | K10: =Submetering!X10 -> 10 | L10: =E10*F10+G10*H10+#REF!*#REF!+I10*J10 -> #REF!
A11: Serengeti | B11: =B10+1 -> 10 | C11: 12 | D11: 2021 | E11: ='UTILITY REPORT 1'!F12 -> 3440 | F11: =('UTILITY REPORT 1'!E12*'UTILITY REPORT 1'!D12)/'UTILITY REPORT 1'!F12 -> 0.3916657 | G11: =IF('Utility summery'!M15<0,"0",'Utility summery'!M15) -> 110 | H11: 2.165 | I11: =IF('UTILITY REPORT 1'!G12<0,"0",'UTILITY REPORT 1'!G12) -> 71 | J11: 0 | K11: =Submetering!X11 -> 12 | L11: =E11*F11+G11*H11+#REF!*#REF!+I11*J11 -> #REF!
A12: Serengeti | B12: =B11+1 -> 11 | C12: 12 | D12: 2021 | E12: ='UTILITY REPORT 1'!F13 -> 3696 | F12: =('UTILITY REPORT 1'!E13*'UTILITY REPORT 1'!D13)/'UTILITY REPORT 1'!F13 -> 0.40930465 | G12: =IF('Utility summery'!M16<0,"0",'Utility summery'!M16) -> 105.38 | H12: 2.165 | I12: =IF('UTILITY REPORT 1'!G13<0,"0",'UTILITY REPORT 1'!G13) -> 72 | J12: 0 | K12: =Submetering!X12 -> 12 | L12: =E12*F12+G12*H12+#REF!*#REF!+I12*J12 -> #REF!
A13: Serengeti | B13: =B12+1 -> 12 | C13: 12 | D13: 2021 | E13: ='UTILITY REPORT 1'!F14 -> 3646 | F13: =('UTILITY REPORT 1'!E14*'UTILITY REPORT 1'!D14)/'UTILITY REPORT 1'!F14 -> 0.40736149 | G13: =IF('Utility summery'!M17<0,"0",'Utility summery'!M17) -> 106.656 | H13: 2.165 | I13: =IF('UTILITY REPORT 1'!G14<0,"0",'UTILITY REPORT 1'!G14) -> 65 | J13: 0 | K13: =Submetering!X13 -> 12 | L13: =E13*F13+G13*H13+#REF!*#REF!+I13*J13 -> #REF!
A14: Serengeti | B14: =B13+1 -> 13 | C14: 12 | D14: 2021 | E14: ='UTILITY REPORT 1'!F15 -> 3967 | F14: =('UTILITY REPORT 1'!E15*'UTILITY REPORT 1'!D15)/'UTILITY REPORT 1'!F15 -> 0.39819259 | G14: =IF('Utility summery'!M18<0,"0",'Utility summery'!M18) -> 108.02 | H14: 2.165 | I14: =IF('UTILITY REPORT 1'!G15<0,"0",'UTILITY REPORT 1'!G15) -> 68 | J14: 0 | K14: =Submetering!X14 -> 15 | L14: =E14*F14+G14*H14+#REF!*#REF!+I14*J14 -> #REF!
... A30: Serengeti | B30: =B29+1 -> 29 | C30: 12 | D30: 2021 | E30: ='UTILITY REPORT 1'!F31 -> 4892 | F30: =('UTILITY REPORT 1'!E31*'UTILITY REPORT 1'!D31)/'UTILITY REPORT 1'!F31 -> 0.41699714 | G30: =IF('Utility summery'!M34<0,"0",'Utility summery'!M34) -> 135.388 | H30: 2.165 | I30: =IF('UTILITY REPORT 1'!G31<0,"0",'UTILITY REPORT 1'!G31) -> 111 | J30: 0 | K30: =Submetering!X30 -> 42 | L30: =E30*F30+G30*H30+#REF!*#REF!+I30*J30 -> #REF!
A31: Serengeti | B31: 30 | C31: 12 | D31: 2021 | E31: ='UTILITY REPORT 1'!F32 -> 4766 | F31: =('UTILITY REPORT 1'!E32*'UTILITY REPORT 1'!D32)/'UTILITY REPORT 1'!F32 -> 0.42798363 | G31: =IF('Utility summery'!M35<0,"0",'Utility summery'!M35) -> 157.3 | H31: 2.165 | I31: =IF('UTILITY REPORT 1'!G32<0,"0",'UTILITY REPORT 1'!G32) -> 102 | J31: 0 | K31: =Submetering!X31 -> 48 | L31: =E31*F31+G31*H31+#REF!*#REF!+I31*J31 -> #REF!
A32: Serengeti | B32: 31 | C32: 12 | D32: 2021 | E32: ='UTILITY REPORT 1'!F33 -> 4562 | F32: =('UTILITY REPORT 1'!E33*'UTILITY REPORT 1'!D33)/'UTILITY REPORT 1'!F33 -> 0.41520824 | G32: =IF('Utility summery'!M36<0,"0",'Utility summery'!M36) -> 163.02 | H32: 2.165 | I32: =IF('UTILITY REPORT 1'!G33<0,"0",'UTILITY REPORT 1'!G33) -> 102 | J32: 0 | K32: =Submetering!X32 -> 48

Sheet Energy Graph
A1: Date | B1: Usage KW | C1: Occ % | D1: Total Occ | E1: Guest Occ
A2: =Gen!B11 -> 44531 | B2: ='Summery Report'!F5 -> 3130 | C2: ='Summery Report'!C5 -> 0.0519 | D2: =E2 -> 6 | E2: =Total!K2 -> 6
A3: =Gen!B12 -> 44532 | B3: ='Summery Report'!F6 -> 3105 | C3: ='Summery Report'!C6 -> 0.05 | D3: =E3 -> 5 | E3: =Total!K3 -> 5
A4: =Gen!B13 -> 44533 | B4: ='Summery Report'!F7 -> 2910 | C4: ='Summery Report'!C7 -> 0.05 | D4: =E4 -> 3 | E4: =Total!K4 -> 3
A5: =Gen!B14 -> 44534 | B5: ='Summery Report'!F8 -> 3289 | C5: ='Summery Report'!C8 -> 0.08 | D5: =E5 -> 8 | E5: =Total!K5 -> 8
A6: =Gen!B15 -> 44535 | B6: ='Summery Report'!F9 -> 3146 | C6: ='Summery Report'!C9 -> 0.05 | D6: =E6 -> 6 | E6: =Total!K6 -> 6
A7: =Gen!B16 -> 44536 | B7: ='Summery Report'!F10 -> 3361 | C7: ='Summery Report'!C10 -> 0.0779 | D7: =E7 -> 9 | E7: =Total!K7 -> 9
A8: =Gen!B17 -> 44537 | B8: ='Summery Report'!F11 -> 3380 | C8: ='Summery Report'!C11 -> 0.0779 | D8: =E8 -> 9 | E8: =Total!K8 -> 9
A9: =Gen!B18 -> 44538 | B9: ='Summery Report'!F12 -> 3662 | C9: ='Summery Report'!C12 -> 0.12 | D9: =E9 -> 12 | E9: =Total!K9 -> 12
A10: =Gen!B19 -> 44539 | B10: ='Summery Report'!F13 -> 3399 | C10: ='Summery Report'!C13 -> 0.09 | D10: =E10 -> 10 | E10: =Total!K10 -> 10
A11: =Gen!B20 -> 44540 | B11: ='Summery Report'!F14 -> 3440 | C11: ='Summery Report'!C14 -> 0.12 | D11: =E11 -> 12 | E11: =Total!K11 -> 12
A12: =Gen!B21 -> 44541 | B12: ='Summery Report'!F15 -> 3696 | C12: ='Summery Report'!C15 -> 0.12 | D12: =E12 -> 12 | E12: =Total!K12 -> 12
A13: =Gen!B22 -> 44542 | B13: ='Summery Report'!F16 -> 3646 | C13: ='Summery Report'!C16 -> 0.12 | D13: =E13 -> 12 | E13: =Total!K13 -> 12
... A31: =Gen!B40 -> 44560 | B31: ='Summery Report'!F34 -> 4766 | C31: ='Summery Report'!C34 -> 0.61 | D31: =E31 -> 48 | E31: =Total!K31 -> 48
A32: =Gen!B41 -> 44561 | B32: ='Summery Report'!F35 -> 4562 | C32: ='Summery Report'!C35 -> 0.61 | D32: =E32 -> 48 | E32: =Total!K32 -> 48 | F32: 0.175
A33: =Gen!B42 -> 0 | B33: 0

Sheet UTILITY REPORT 1
A1: UTILITY REPORT
A2: Date | B2: % | C2: Guest Rooms Occupied | D2: Diesel cost Per Liter ($) | E2: Diesel consumption (LT) | F2: Power production (KW) | G2: Water consumption (M3) | H2: RO prodution (M3) | I2: Transport Consupmtion (LT)
A3: =Gen!B11 -> 44531 | B3: 0.0519 | C3: 6 | D3: 1 | E3: =Gen!T11 -> 1340.69 | F3: =Gen!U11 -> 3130 | G3: ='Water-Meter'!E6 -> 79 | H3: ='Utility report '!AC6 -> 35 | I3: =Gen!AK11 -> 55.31
A4: =Gen!B12 -> 44532 | B4: 0.05 | C4: 5 | D4: 1 | E4: =Gen!T12 -> 1268.81 | F4: =Gen!U12 -> 3105 | G4: ='Water-Meter'!E7 -> 67 | H4: ='Utility report '!AC7 -> 61 | I4: =Gen!AK12 -> 596.04
A5: =Gen!B13 -> 44533 | B5: =Gen!C13 -> 0.05 | C5: 3 | D5: 1 | E5: =Gen!T13 -> 1177.17 | F5: =Gen!U13 -> 2910 | G5: ='Water-Meter'!E8 -> 83 | H5: ='Utility report '!AC8 -> 50 | I5: =Gen!AK13 -> 0
A6: =Gen!B14 -> 44534 | B6: 0.08 | C6: 8 | D6: 1 | E6: =Gen!T14 -> 1293.22 | F6: =Gen!U14 -> 3289 | G6: ='Water-Meter'!E9 -> 67 | H6: ='Utility report '!AC9 -> 89 | I6: =Gen!AK14 -> 199.51
A7: =Gen!B15 -> 44535 | B7: 0.05 | C7: 6 | D7: 1 | E7: =Gen!T15 -> 1246.93 | F7: =Gen!U15 -> 3146 | G7: ='Water-Meter'!E10 -> 62 | H7: ='Utility report '!AC10 -> 103 | I7: =Gen!AK15 -> 53.33
A8: =Gen!B16 -> 44536 | B8: 0.0779 | C8: 9 | D8: 1 | E8: =Gen!T16 -> 1325.89 | F8: =Gen!U16 -> 3361 | G8: ='Water-Meter'!E11 -> 57 | H8: ='Utility report '!AC11 -> 17 | I8: =Gen!AK16 -> 67.4
A9: =Gen!B17 -> 44537 | B9: 0.0779 | C9: 9 | D9: 1 | E9: =Gen!T17 -> 1368.94 | F9: =Gen!U17 -> 3380 | G9: ='Water-Meter'!E12 -> 73 | H9: ='Utility report '!AC12 -> 121 | I9: =Gen!AK17 -> 135.94
A10: =Gen!B18 -> 44538 | B10: 0.12 | C10: 12 | D10: 1 | E10: =Gen!T18 -> 1527.6 | F10: =Gen!U18 -> 3662 | G10: ='Water-Meter'!E13 -> 80 | H10: ='Utility report '!AC13 -> 170 | I10: =Gen!AK18 -> 83.59
A11: =Gen!B19 -> 44539 | B11: 0.09 | C11: 10 | D11: 1 | E11: =Gen!T19 -> 1371.66 | F11: =Gen!U19 -> 3399 | G11: ='Water-Meter'!E14 -> 65 | H11: ='Utility report '!AC14 -> 0 | I11: =Gen!AK19 -> 51.98
A12: =Gen!B20 -> 44540 | B12: 0.12 | C12: 12 | D12: 1 | E12: =Gen!T20 -> 1347.33 | F12: =Gen!U20 -> 3440 | G12: ='Water-Meter'!E15 -> 71 | H12: ='Utility report '!AC15 -> 167 | I12: =Gen!AK20 -> 448.65
A13: =Gen!B21 -> 44541 | B13: 0.12 | C13: 12 | D13: 1 | E13: =Gen!T21 -> 1512.79 | F13: =Gen!U21 -> 3696 | G13: ='Water-Meter'!E16 -> 72 | H13: ='Utility report '!AC16 -> 15 | I13: =Gen!AK21 -> 37.87
A14: =Gen!B22 -> 44542 | B14: 0.12 | C14: 12 | D14: 1 | E14: =Gen!T22 -> 1485.24 | F14: =Gen!U22 -> 3646 | G14: ='Water-Meter'!E17 -> 65 | H14: ='Utility report '!AC17 -> 157 | I14: =Gen!AK22 -> 68.16
A15: =Gen!B23 -> 44543 | B15: 0.16 | C15: 15 | D15: 1 | E15: =Gen!T23 -> 1579.63 | F15: =Gen!U23 -> 3967 | G15: ='Water-Meter'!E18 -> 68 | H15: ='Utility report '!AC18 -> 44 | I15: =Gen!AK23 -> 103.25
A16: =Gen!B24 -> 44544 | B16: 0.17 | C16: 16 | D16: 1 | E16: =Gen!T24 -> 1342.22 | F16: =Gen!U24 -> 3411 | G16: ='Water-Meter'!E19 -> 78 | H16: ='Utility report '!AC19 -> 167 | I16: =Gen!AK24 -> 194.5
A17: =Gen!B25 -> 44545 | B17: 0.18 | C17: 17 | D17: 1 | E17: =Gen!T25 -> 1601.91 | F17: =Gen!U25 -> 3878 | G17: ='Water-Meter'!E20 -> 72 | H17: ='Utility report '!AC20 -> 104 | I17: =Gen!AK25 -> 0
... A33: =Gen!B41 -> 44561 | B33: 0.61 | C33: 48 | D33: 1 | E33: =Gen!T41 -> 1894.18 | F33: =Gen!U41 -> 4562 | G33: ='Water-Meter'!E36 -> 102 | H33: ='Utility report '!AC36 -> 156 | I33: =Gen!AK41 -> 882.87
B34: =Gen!C42 -> 0 | C34: ='Summery Report'!E36 -> 0 | D34: 2 | E34: =Gen!T42 -> 0 | F34: =Gen!U42 -> 0 | G34: ='Water-Meter'!E37 -> 120 | H34: ='Utility report '!AC37 -> -21907 | I34: =Gen!AL42 -> 0

Sheet Kit report
B1: KITCHEN THREE PHASE KWH METER READING | H1: KITCHEN WATER METER READING | M1: AMANI Restaurant WATER METER READING | T1: LAUNDRY THREE PHASE KWH METER READING | Y1: LAUNDRY WATER METER READING
A2: Occ % | B2: DATE | C2: READING TIME | D2: METER READING OPEN | E2: METER READING ClOSE | F2: UNIT USED Kwh | H2: DATE | I2: READING TIME | J2: METER READING OPEN Cbm | K2: METER READING ClOSE Cbm | L2: UNIT USED Cbm | M2: DATE | N2: READING TIME | O2: METER READING OPEN Cbm | P2: METER READING ClOSE Cbm | Q2: UNIT USED Cbm | R2: Cost Per day Elct+Water $ | S2: % as per the total Lodge consumption | T2: DATE | U2: READING TIME | V2: METER READING OPEN (Kwh) | W2: METER READING ClOSE (Kwh) | X2: UNIT USED Kwh | Y2: DATE | Z2: READING TIME | AA2: METER READING OPEN Cbm | AB2: METER READING ClOSE Cbm | AC2: UNIT USED Cbm
A3: =Gen!B11 -> 44531 | B3: Close Last Month | E3: 9756.7 | F3: X120 | H3: Close Last Month | J3: ='Water-Meter'!G5 -> 0 | K3: ='Water-Meter'!G5 -> 0 | M3: Close Last Month | P3: ='Water-Meter'!J5 -> 8871 | T3: Close Last Month | W3: 8710.3 | X3: =(W3-V3)*200 -> 1742060 | Y3: Close Last Month | AB3: ='Water-Meter'!P5 -> 22709
A4: =Gen!C11 -> 0.0519 | B4: =Gen!B11 -> 44531 | D4: =E3 -> 9756.7 | E4: 9756.7 | F4: =SUM(E5-D4)*120 -> 240 | H4: =B4 -> 44531 | J4: ='Water-Meter'!G6 -> 0 | K4: ='Water-Meter'!G6 -> 0 | L4: =SUM(K4-J4) -> 0 | M4: =H4 -> 44531 | P4: ='Water-Meter'!J6 -> 8872 | Q4: =N4-O3 -> 0 | R4: =SUM(Q4/1615) -> 0 | S4: =Gen!U11 -> 3130 | T4: =M4 -> 44531 | V4: =W3 -> 8710.3 | W4: 8710.3 | X4: =(W4-V4)*200 -> 0 | Y4: =T4 -> 44531 | AA4: =AB3 -> 22709 | AB4: ='Water-Meter'!P6 -> 22716 | AC4: =AB4-AA4 -> 7
A5: =Gen!C12 -> 0.05 | B5: =Gen!B12 -> 44532 | D5: =E5 -> 9758.7 | E5: 9758.7 | F5: =SUM(E6-D5)*120 -> 240 | H5: =B5 -> 44532 | J5: ='Water-Meter'!G7 -> 0 | K5: ='Water-Meter'!G7 -> 0 | L5: =SUM(K5-J5) -> 0 | M5: =H5 -> 44532 | P5: ='Water-Meter'!J7 -> 8874 | Q5: =N5-O4 -> 0 | R5: =SUM(Q5/1615) -> 0 | S5: =Gen!U12 -> 3105 | T5: =M5 -> 44532 | V5: =W4 -> 8710.3 | W5: 8712.5 | X5: =(W5-V5)*200 -> 440 | Y5: =T5 -> 44532 | AA5: =AB4 -> 22716 | AB5: ='Water-Meter'!P7 -> 22721 | AC5: =AB5-AA5 -> 5
A6: =Gen!C13 -> 0.05 | B6: =Gen!B13 -> 44533 | D6: =E6 -> 9760.7 | E6: 9760.7 | F6: =SUM(E7-D6)*120 -> 252 | H6: =B6 -> 44533 | J6: ='Water-Meter'!G8 -> 0 | K6: ='Water-Meter'!G8 -> 0 | L6: =SUM(K6-J6) -> 0 | M6: =H6 -> 44533 | P6: ='Water-Meter'!J8 -> 8876 | Q6: =N6-O5 -> 0 | R6: =SUM(Q6/1615) -> 0 | S6: =Gen!U13 -> 2910 | T6: =M6 -> 44533 | V6: =W5 -> 8712.5 | W6: 8714.1 | X6: =(W6-V6)*200 -> 320 | Y6: =T6 -> 44533 | AA6: =AB5 -> 22721 | AB6: ='Water-Meter'!P8 -> 22724 | AC6: =AB6-AA6 -> 3
A7: =Gen!C14 -> 0.08 | B7: =Gen!B14 -> 44534 | D7: =E7 -> 9762.8 | E7: 9762.8 | F7: =SUM(E8-D7)*120 -> 276 | H7: =B7 -> 44534 | J7: ='Water-Meter'!G9 -> 0 | K7: ='Water-Meter'!G9 -> 0 | L7: =SUM(K7-J7) -> 0 | M7: =H7 -> 44534 | P7: ='Water-Meter'!J9 -> 8889 | Q7: =N7-O6 -> 0 | R7: =SUM(Q7/1615) -> 0 | S7: =Gen!U14 -> 3289 | T7: =M7 -> 44534 | V7: =W6 -> 8714.1 | W7: 8715.8 | X7: =(W7-V7)*200 -> 340 | Y7: =T7 -> 44534 | AA7: =AB6 -> 22724 | AB7: ='Water-Meter'!P9 -> 22729 | AC7: =AB7-AA7 -> 5
A8: =Gen!C15 -> 0.05 | B8: =Gen!B15 -> 44535 | D8: =E8 -> 9765.1 | E8: 9765.1 | F8: =SUM(E9-D8)*120 -> 216 | H8: =B8 -> 44535 | J8: ='Water-Meter'!G10 -> 0 | K8: ='Water-Meter'!G10 -> 0 | L8: =SUM(K8-J8) -> 0 | M8: =H8 -> 44535 | P8: ='Water-Meter'!J10 -> 8895 | Q8: =N8-O7 -> 0 | R8: =SUM(Q8/1615) -> 0 | S8: =Gen!U15 -> 3146 | T8: =M8 -> 44535 | V8: =W7 -> 8715.8 | W8: 8717.3 | X8: =(W8-V8)*200 -> 300 | Y8: =T8 -> 44535 | AA8: =AB7 -> 22729 | AB8: ='Water-Meter'!P10 -> 22733 | AC8: =AB8-AA8 -> 4
A9: =Gen!C16 -> 0.0779 | B9: =Gen!B16 -> 44536 | D9: =E9 -> 9766.9 | E9: 9766.9 | F9: =SUM(E10-D9)*120 -> 228 | H9: =B9 -> 44536 | J9: ='Water-Meter'!G11 -> 0 | K9: ='Water-Meter'!G11 -> 0 | L9: =SUM(K9-J9) -> 0 | M9: =H9 -> 44536 | P9: ='Water-Meter'!J11 -> 8897 | Q9: =N9-O8 -> 0 | R9: =SUM(Q9/1615) -> 0 | S9: =Gen!U16 -> 3361 | T9: =M9 -> 44536 | V9: =W8 -> 8717.3 | W9: 8718.9 | X9: =(W9-V9)*200 -> 320 | Y9: =T9 -> 44536 | AA9: =AB8 -> 22733 | AB9: ='Water-Meter'!P11 -> 22738 | AC9: =AB9-AA9 -> 5
A10: =Gen!C17 -> 0.0779 | B10: =Gen!B17 -> 44537 | D10: =E10 -> 9768.8 | E10: 9768.8 | F10: =SUM(E11-D10)*120 -> 228 | H10: =B10 -> 44537 | J10: ='Water-Meter'!G12 -> 0 | K10: ='Water-Meter'!G12 -> 0 | L10: =SUM(K10-J10) -> 0 | M10: =H10 -> 44537 | P10: ='Water-Meter'!J12 -> 8900 | R10: =SUM(Q10/1615) -> 0 | S10: =Gen!U17 -> 3380 | T10: =M10 -> 44537 | V10: =W9 -> 8718.9 | W10: 8720.5 | X10: =(W10-V10)*200 -> 320 | Y10: =T10 -> 44537 | AA10: =AB9 -> 22738 | AB10: ='Water-Meter'!P12 -> 22745 | AC10: =AB10-AA10 -> 7
A11: =Gen!C18 -> 0.12 | B11: =Gen!B18 -> 44538 | D11: =E11 -> 9770.7 | E11: 9770.7 | F11: =SUM(E12-D11)*120 -> 240 | H11: =B11 -> 44538 | J11: ='Water-Meter'!G13 -> 0 | K11: ='Water-Meter'!G13 -> 0 | L11: =SUM(K11-J11) -> 0 | M11: =H11 -> 44538 | P11: ='Water-Meter'!J13 -> 8903 | Q11: =N11-O10 -> 0 | R11: =SUM(Q11/1615) -> 0 | S11: =Gen!U18 -> 3662 | T11: =M11 -> 44538 | V11: =W10 -> 8720.5 | W11: 8722.7 | X11: =(W11-V11)*200 -> 440 | Y11: =T11 -> 44538 | AA11: =AB10 -> 22745 | AB11: ='Water-Meter'!P13 -> 22751 | AC11: =AB11-AA11 -> 6
A12: =Gen!C19 -> 0.09 | B12: =Gen!B19 -> 44539 | D12: =E12 -> 9772.7 | E12: 9772.7 | F12: =SUM(E13-D12)*120 -> 240 | H12: =B12 -> 44539 | J12: ='Water-Meter'!G14 -> 0 | K12: ='Water-Meter'!G14 -> 0 | L12: =SUM(K12-J12) -> 0 | M12: =H12 -> 44539 | P12: ='Water-Meter'!J14 -> 8905 | Q12: =N12-O11 -> 0 | R12: =SUM(Q12/1615) -> 0 | S12: =Gen!U19 -> 3399 | T12: =M12 -> 44539 | V12: =W11 -> 8722.7 | W12: 8724.3 | X12: =(W12-V12)*200 -> 320 | Y12: =T12 -> 44539 | AA12: =AB11 -> 22751 | AB12: ='Water-Meter'!P14 -> 22754 | AC12: =AB12-AA12 -> 3
A13: =Gen!C20 -> 0.12 | B13: =Gen!B20 -> 44540 | D13: =E13 -> 9774.7 | E13: 9774.7 | F13: =SUM(E14-D13)*120 -> 252 | H13: =B13 -> 44540 | J13: ='Water-Meter'!G15 -> 0 | K13: ='Water-Meter'!G15 -> 0 | L13: =SUM(K13-J13) -> 0 | M13: =H13 -> 44540 | P13: ='Water-Meter'!J15 -> 8906 | Q13: =N13-O12 -> 0 | R13: =SUM(Q13/1615) -> 0 | S13: =Gen!U20 -> 3440 | T13: =M13 -> 44540 | V13: =W12 -> 8724.3 | W13: 8726.2 | X13: =(W13-V13)*200 -> 380 | Y13: =T13 -> 44540 | AA13: =AB12 -> 22754 | AB13: ='Water-Meter'!P15 -> 22760 | AC13: =AB13-AA13 -> 6
A14: =Gen!C21 -> 0.12 | B14: =Gen!B21 -> 44541 | D14: =E14 -> 9776.8 | E14: 9776.8 | F14: =SUM(E15-D14)*120 -> 228 | H14: =B14 -> 44541 | J14: ='Water-Meter'!G15 -> 0 | K14: ='Water-Meter'!G15 -> 0 | L14: =SUM(K14-J14) -> 0 | M14: =H14 -> 44541 | P14: ='Water-Meter'!J16 -> 8908 | Q14: =N14-O13 -> 0 | R14: =SUM(Q14/1615) -> 0 | S14: =Gen!U21 -> 3696 | T14: =M14 -> 44541 | V14: =W13 -> 8726.2 | W14: 8727.9 | X14: =(W14-V14)*200 -> 340 | Y14: =T14 -> 44541 | AA14: =AB13 -> 22760 | AB14: ='Water-Meter'!P16 -> 22764 | AC14: =AB14-AA14 -> 4
A15: =Gen!C22 -> 0.12 | B15: =Gen!B22 -> 44542 | D15: =E15 -> 9778.7 | E15: 9778.7 | F15: =SUM(E16-D15)*120 -> 264 | H15: =B15 -> 44542 | J15: ='Water-Meter'!G17 -> 0 | K15: ='Water-Meter'!G17 -> 0 | L15: =SUM(K15-J15) -> 0 | M15: =H15 -> 44542 | P15: ='Water-Meter'!J17 -> 8910 | Q15: =N15-O14 -> 0 | R15: =SUM(Q15/1615) -> 0 | S15: =Gen!U22 -> 3646 | T15: =M15 -> 44542 | V15: =W14 -> 8727.9 | W15: 8730.1 | X15: =(W15-V15)*200 -> 440 | Y15: =T15 -> 44542 | AA15: =AB14 -> 22764 | AB15: ='Water-Meter'!P17 -> 22769 | AC15: =AB15-AA15 -> 5
A16: =Gen!C23 -> 0.16 | B16: =Gen!B23 -> 44543 | D16: =E16 -> 9780.9 | E16: 9780.9 | F16: =SUM(E17-D16)*120 -> 276 | H16: =B16 -> 44543 | J16: ='Water-Meter'!G18 -> 0 | K16: ='Water-Meter'!G18 -> 0 | L16: =SUM(K16-J16) -> 0 | M16: =H16 -> 44543 | P16: ='Water-Meter'!J18 -> 8913 | Q16: =N16-O15 -> 0 | R16: =SUM(Q16/1615) -> 0 | S16: =Gen!U23 -> 3967 | T16: =M16 -> 44543 | V16: =W15 -> 8730.1 | W16: 8732.9 | X16: =(W16-V16)*200 -> 560 | Y16: =T16 -> 44543 | AA16: =AB15 -> 22769 | AB16: ='Water-Meter'!P18 -> 22776 | AC16: =AB16-AA16 -> 7
A17: =Gen!C24 -> 0.17 | B17: =Gen!B24 -> 44544 | D17: =E17 -> 9783.2 | E17: 9783.2 | F17: =SUM(E18-D17)*120 -> 252 | H17: =B17 -> 44544 | J17: ='Water-Meter'!G19 -> 0 | K17: ='Water-Meter'!G19 -> 0 | L17: =SUM(K17-J17) -> 0 | M17: =H17 -> 44544 | P17: ='Water-Meter'!J19 -> 8916 | Q17: =N17-O16 -> 0 | R17: =SUM(Q17/1615) -> 0 | S17: =Gen!U24 -> 3411 | T17: =M17 -> 44544 | V17: =W16 -> 8732.9 | W17: 8735.1 | X17: =(W17-V17)*200 -> 440 | Y17: =T17 -> 44544 | AA17: =AB16 -> 22776 | AB17: ='Water-Meter'!P19 -> 22784 | AC17: =AB17-AA17 -> 8
A18: =Gen!C25 -> 0.18 | B18: =Gen!B25 -> 44545 | D18: =E18 -> 9785.3 | E18: 9785.3 | F18: =SUM(E19-D18)*120 -> 240 | H18: =B18 -> 44545 | J18: ='Water-Meter'!G20 -> 0 | K18: ='Water-Meter'!G20 -> 0 | L18: =SUM(K18-J18) -> 0 | M18: =H18 -> 44545 | P18: ='Water-Meter'!J20 -> 8918 | Q18: =N18-O17 -> 0 | R18: =SUM(Q18/1615) -> 0 | S18: =Gen!U25 -> 3878 | T18: =M18 -> 44545 | V18: =W17 -> 8735.1 | W18: 8736.9 | X18: =(W18-V18)*200 -> 360 | Y18: =T18 -> 44545 | AA18: =AB17 -> 22784 | AB18: ='Water-Meter'!P20 -> 22789 | AC18: =AB18-AA18 -> 5
A19: =Gen!C26 -> 0.16 | B19: =Gen!B26 -> 44546 | D19: =E19 -> 9787.3 | E19: 9787.3 | F19: =SUM(E20-D19)*120 -> 264 | H19: =B19 -> 44546 | J19: ='Water-Meter'!G21 -> 0 | K19: ='Water-Meter'!G21 -> 0 | L19: =SUM(K19-J19) -> 0 | M19: =H19 -> 44546 | P19: ='Water-Meter'!J21 -> 8920 | Q19: =N19-O18 -> 0 | R19: =SUM(Q19/1615) -> 0 | S19: =Gen!U26 -> 3906 | T19: =M19 -> 44546 | V19: =W18 -> 8736.9 | W19: 8739.5 | X19: =(W19-V19)*200 -> 520 | Y19: =T19 -> 44546 | AA19: =AB18 -> 22789 | AB19: ='Water-Meter'!P21 -> 22794 | AC19: =AB19-AA19 -> 5
A20: =Gen!C27 -> 0.16 | B20: =Gen!B27 -> 44547 | D20: =E20 -> 9789.5 | E20: 9789.5 | F20: =SUM(E21-D20)*120 -> 264 | H20: =B20 -> 44547 | J20: ='Water-Meter'!G22 -> 0 | K20: ='Water-Meter'!G22 -> 0 | L20: =SUM(K20-J20) -> 0 | M20: =H20 -> 44547 | P20: ='Water-Meter'!J22 -> 8922 | Q20: =N20-O19 -> 0 | R20: =SUM(Q20/1615) -> 0 | S20: =Gen!U27 -> 3764 | T20: =M20 -> 44547 | V20: =W19 -> 8739.5 | W20: 8741.7 | X20: =(W20-V20)*200 -> 440 | Y20: =T20 -> 44547 | AA20: =AB19 -> 22794 | AB20: ='Water-Meter'!P22 -> 22798 | AC20: =AB20-AA20 -> 4
A21: =Gen!C28 -> 0.13 | B21: =Gen!B28 -> 44548 | D21: =E21 -> 9791.7 | E21: 9791.7 | F21: =SUM(E22-D21)*120 -> 264 | H21: =B21 -> 44548 | J21: ='Water-Meter'!G23 -> 0 | K21: ='Water-Meter'!G23 -> 0 | L21: =SUM(K21-J21) -> 0 | M21: =H21 -> 44548 | P21: ='Water-Meter'!J23 -> 8925 | Q21: =N21-O20 -> 0 | R21: =SUM(Q21/1615) -> 0 | S21: =Gen!U28 -> 3882 | T21: =M21 -> 44548 | V21: =W20 -> 8741.7 | W21: 8744 | X21: =(W21-V21)*200 -> 460 | Y21: =T21 -> 44548 | AA21: =AB20 -> 22798 | AB21: ='Water-Meter'!P23 -> 22806 | AC21: =AB21-AA21 -> 8
A22: =Gen!C29 -> 0.12 | B22: =Gen!B29 -> 44549 | D22: =E22 -> 9793.9 | E22: 9793.9 | F22: =SUM(E23-D22)*120 -> 216 | H22: =B22 -> 44549 | K22: ='Water-Meter'!G24 -> 0 | L22: =SUM(K22-J22) -> 0 | M22: =H22 -> 44549 | P22: ='Water-Meter'!J24 -> 8928 | Q22: =N22-O21 -> 0 | R22: =SUM(Q22/1615) -> 0 | S22: =Gen!U29 -> 3745 | T22: =M22 -> 44549 | V22: =W21 -> 8744 | W22: 8746.7 | X22: =(W22-V22)*200 -> 540 | Y22: =T22 -> 44549 | AA22: =AB21 -> 22806 | AB22: ='Water-Meter'!P24 -> 22812 | AC22: =AB22-AA22 -> 6
A23: =Gen!C30 -> 0.06 | B23: =Gen!B30 -> 44550 | D23: =E23 -> 9795.7 | E23: 9795.7 | F23: =SUM(E24-D23)*120 -> 228 | H23: =B23 -> 44550 | J23: ='Water-Meter'!G25 -> 0 | K23: ='Water-Meter'!G26 -> 0 | L23: =SUM(K23-J23) -> 0 | M23: =H23 -> 44550 | P23: ='Water-Meter'!J25 -> 8930 | Q23: =N23-O22 -> 0 | R23: =SUM(Q23/1615) -> 0 | S23: =Gen!U30 -> 3257 | T23: =M23 -> 44550 | V23: =W22 -> 8746.7 | W23: 8749.7 | X23: =(W23-V23)*200 -> 600 | Y23: =T23 -> 44550 | AA23: =AB22 -> 22812 | AB23: ='Water-Meter'!P25 -> 22817 | AC23: =AB23-AA23 -> 5
A24: =Gen!C31 -> 0.1 | B24: =Gen!B31 -> 44551 | D24: =E24 -> 9797.6 | E24: 9797.6 | F24: =SUM(E25-D24)*120 -> 252 | H24: =B24 -> 44551 | J24: ='Water-Meter'!G26 -> 0 | K24: ='Water-Meter'!G27 -> 0 | L24: =SUM(K24-J24) -> 0 | M24: =H24 -> 44551 | P24: ='Water-Meter'!J26 -> 8932 | Q24: =N24-O23 -> 0 | R24: =SUM(Q24/1615) -> 0 | S24: =Gen!U31 -> 4495 | T24: =M24 -> 44551 | V24: =W23 -> 8749.7 | W24: 8752.7 | X24: =(W24-V24)*200 -> 600 | Y24: =T24 -> 44551 | AA24: =AB23 -> 22817 | AB24: ='Water-Meter'!P26 -> 22822 | AC24: =AB24-AA24 -> 5
A25: =Gen!C32 -> 0.17 | B25: =Gen!B32 -> 44552 | D25: =E25 -> 9799.7 | E25: 9799.7 | F25: =SUM(E26-D25)*120 -> 264 | H25: =B25 -> 44552 | J25: ='Water-Meter'!G27 -> 0 | K25: ='Water-Meter'!G28 -> 0 | L25: =SUM(K25-J25) -> 0 | M25: =H25 -> 44552 | P25: ='Water-Meter'!J27 -> 8936 | Q25: =N25-O24 -> 0 | R25: =SUM(Q25/1615) -> 0 | S25: =Gen!U32 -> 3996 | T25: =M25 -> 44552 | V25: =W24 -> 8752.7 | W25: 8755.6 | X25: =(W25-V25)*200 -> 580 | Y25: =T25 -> 44552 | AA25: =AB24 -> 22822 | AB25: ='Water-Meter'!P27 -> 22829 | AC25: =AB25-AA25 -> 7
A26: =Gen!C33 -> 0.17 | B26: =Gen!B33 -> 44553 | D26: =E26 -> 9801.9 | E26: 9801.9 | F26: =SUM(E27-D26)*120 -> 240 | H26: =B26 -> 44553 | J26: ='Water-Meter'!G28 -> 0 | K26: ='Water-Meter'!G29 -> 0 | L26: =SUM(K26-J26) -> 0 | M26: =H26 -> 44553 | P26: ='Water-Meter'!J28 -> 8938 | Q26: =N26-O25 -> 0 | R26: =SUM(Q26/1615) -> 0 | S26: =Gen!U33 -> 4192 | T26: =M26 -> 44553 | V26: =W25 -> 8755.6 | W26: 8758.7 | X26: =(W26-V26)*200 -> 620 | Y26: =T26 -> 44553 | AA26: =AB25 -> 22829 | AB26: ='Water-Meter'!P28 -> 22839 | AC26: =AB26-AA26 -> 10
A27: =Gen!C34 -> 0.47 | B27: =Gen!B34 -> 44554 | D27: =E27 -> 9803.9 | E27: 9803.9 | F27: =SUM(E28-D27)*120 -> 276 | H27: =B27 -> 44554 | J27: ='Water-Meter'!G29 -> 0 | K27: ='Water-Meter'!G30 -> 0 | L27: =SUM(K27-J27) -> 0 | M27: =H27 -> 44554 | P27: ='Water-Meter'!J29 -> 8941 | Q27: =N27-O26 -> 0 | R27: =SUM(Q27/1615) -> 0 | S27: =Gen!U34 -> 4947 | T27: =M27 -> 44554 | V27: =W26 -> 8758.7 | W27: 8762.7 | X27: =(W27-V27)*200 -> 800 | Y27: =T27 -> 44554 | AA27: =AB26 -> 22839 | AB27: ='Water-Meter'!P29 -> 22848 | AC27: =AB27-AA27 -> 9
A28: =Gen!C35 -> 0.58 | B28: =Gen!B35 -> 44555 | D28: =E28 -> 9806.2 | E28: 9806.2 | F28: =SUM(E29-D28)*120 -> 300 | H28: =B28 -> 44555 | J28: ='Water-Meter'!G30 -> 0 | K28: ='Water-Meter'!G31 -> 0 | L28: =SUM(K28-J28) -> 0 | M28: =H28 -> 44555 | P28: ='Water-Meter'!J30 -> 8944 | Q28: =N28-O27 -> 0 | R28: =SUM(Q28/1615) -> 0 | S28: =Gen!U35 -> 4917 | T28: =M28 -> 44555 | V28: =W27 -> 8762.7 | W28: 8765.6 | X28: =(W28-V28)*200 -> 580 | Y28: =T28 -> 44555 | AA28: =AB27 -> 22848 | AB28: ='Water-Meter'!P30 -> 22861 | AC28: =AB28-AA28 -> 13
A29: =Gen!C36 -> 0.43 | B29: =Gen!B36 -> 44556 | D29: =E29 -> 9808.7 | E29: 9808.7 | F29: =SUM(E30-D29)*120 -> 264 | H29: =B29 -> 44556 | J29: ='Water-Meter'!G31 -> 0 | K29: ='Water-Meter'!G32 -> 0 | L29: =SUM(K29-J29) -> 0 | M29: =H29 -> 44556 | P29: ='Water-Meter'!J31 -> 8947 | Q29: =N29-O28 -> 0 | R29: =SUM(Q29/1615) -> 0 | S29: =Gen!U36 -> 4944 | T29: =M29 -> 44556 | V29: =W28 -> 8765.6 | W29: 8769.5 | X29: =(W29-V29)*200 -> 780 | Y29: =T29 -> 44556 | AA29: =AB28 -> 22861 | AB29: ='Water-Meter'!P31 -> 22873 | AC29: =AB29-AA29 -> 12
A30: =Gen!C37 -> 0.39 | B30: =Gen!B37 -> 44557 | D30: =E30 -> 9810.9 | E30: 9810.9 | F30: =SUM(E31-D30)*120 -> 276 | H30: =B30 -> 44557 | J30: ='Water-Meter'!G32 -> 0 | K30: ='Water-Meter'!G33 -> 0 | L30: =SUM(K30-J30) -> 0 | M30: =H30 -> 44557 | P30: ='Water-Meter'!J32 -> 8951 | Q30: =N30-O29 -> 0 | R30: =SUM(Q30/1615) -> 0 | S30: =Gen!U37 -> 5000 | T30: =M30 -> 44557 | V30: =W29 -> 8769.5 | W30: 8774.3 | X30: =(W30-V30)*200 -> 960 | Y30: =T30 -> 44557 | AA30: =AB29 -> 22873 | AB30: ='Water-Meter'!P32 -> 22886 | AC30: =AB30-AA30 -> 13
A31: =Gen!C38 -> 0.43 | B31: =Gen!B38 -> 44558 | D31: =E31 -> 9813.2 | E31: 9813.2 | F31: =SUM(E32-D31)*120 -> 204 | H31: =B31 -> 44558 | J31: ='Water-Meter'!G33 -> 0 | K31: ='Water-Meter'!G34 -> 0 | L31: =SUM(K31-J31) -> 0 | M31: =H31 -> 44558 | P31: ='Water-Meter'!J33 -> 8954 | Q31: =N31-O30 -> 0 | R31: =SUM(Q31/1615) -> 0 | S31: =Gen!U38 -> 4676 | T31: =M31 -> 44558 | V31: =W30 -> 8774.3 | W31: 8778.5 | X31: =(W31-V31)*200 -> 840 | Y31: =T31 -> 44558 | AA31: =AB30 -> 22886 | AB31: ='Water-Meter'!P33 -> 22895 | AC31: =AB31-AA31 -> 9
A32: =Gen!C39 -> 0.53 | B32: =Gen!B39 -> 44559 | D32: =E32 -> 9814.9 | E32: 9814.9 | F32: =SUM(E33-D32)*120 -> 180 | H32: =B32 -> 44559 | J32: ='Water-Meter'!G34 -> 0 | K32: ='Water-Meter'!G34 -> 0 | L32: =SUM(K32-J32) -> 0 | M32: =H32 -> 44559 | P32: ='Water-Meter'!J34 -> 8959 | Q32: =N32-O31 -> 0 | R32: =SUM(Q32/1615) -> 0 | S32: =Gen!U39 -> 4892 | T32: =M32 -> 44559 | V32: =W31 -> 8778.5 | W32: 8782.7 | X32: =(W32-V32)*200 -> 840 | Y32: =T32 -> 44559 | AA32: =AB31 -> 22895 | AB32: ='Water-Meter'!P34 -> 22909 | AC32: =AB32-AA32 -> 14
A33: =Gen!C40 -> 0.61 | B33: =Gen!B40 -> 44560 | D33: =E33 -> 9816.4 | E33: 9816.4 | F33: =SUM(E34-D33)*120 -> 216 | H33: =B33 -> 44560 | J33: ='Water-Meter'!G35 -> 0 | K33: ='Water-Meter'!G35 -> 0 | L33: =SUM(K33-J33) -> 0 | M33: =H33 -> 44560 | P33: ='Water-Meter'!J35 -> 8962 | Q33: =N33-O32 -> 0 | R33: =SUM(Q33/1615) -> 0 | S33: =Gen!U40 -> 4766 | T33: =M33 -> 44560 | V33: =W32 -> 8782.7 | W33: 8787.2 | X33: =(W33-V33)*200 -> 900 | Y33: =T33 -> 44560 | AA33: =AB32 -> 22909 | AB33: ='Water-Meter'!P35 -> 22919 | AC33: =AB33-AA33 -> 10
A34: =Gen!C41 -> 0.61 | B34: =Gen!B41 -> 44561 | D34: =E34 -> 9818.2 | E34: 9818.2 | F34: =SUM(E35-D34)*120 -> 264 | H34: =E30 -> 9810.9 | J34: ='Water-Meter'!G36 -> 0 | K34: ='Water-Meter'!G36 -> 0 | L34: =SUM(K34-J34) -> 0 | M34: =H34 -> 9810.9 | P34: ='Water-Meter'!J36 -> 8965 | Q34: =N34-O33 -> 0 | R34: =SUM(Q34/1615) -> 0 | S34: =Gen!U41 -> 4562 | T34: =M34 -> 9810.9 | V34: =SUM(W33) -> 8787.2 | W34: 8791.2 | X34: =(W34-V34)*200 -> 800 | Y34: =T34 -> 9810.9 | AA34: =AB33 -> 22919 | AB34: ='Water-Meter'!P36 -> 22928 | AC34: =AA34-AB33 -> 0
A35: #REF! | B35: #REF! | D35: =E35 -> 9820.4 | E35: 9820.4 | F35: =SUM(E36-D35)*120 -> -1178448 | H35: =B35 -> #REF! | J35: =SUM(K34) -> 0 | K35: ='Water-Meter'!G37 -> 0 | L35: =SUM(L5:L34) -> 0 | M35: =H35 -> #REF! | P35: ='Water-Meter'!J37 -> 0 | Q35: =N35-O34 -> 0 | R35: =SUM(Q35/1615) -> 0 | S35: =Gen!U42 -> 0 | T35: =M35 -> #REF! | V35: =SUM(W34) -> 8791.2 | W35: 8794.9 | X35: =(W35-V35)*200 -> 740 | Y35: =T35 -> #REF! | AB35: ='Water-Meter'!P37 -> 0 | AC35: =AA35-AB34 -> -22928
F36: =SUM(E37-D36)*120 -> 0 | X36: =SUM(X4:X6) -> 760

Sheet Utility report 
A1: =A6 -> 44531
A2: Date | B2: Total occupancy | H2: Diesel balance LTS | I2: Diesel Deliveries | J2: Gen.Diesel consumption LTS | L2: Total Diesel consumption LTS | M2: Water Meter reading | N2: Water consumption m³ | O2: R.O WATER PRODUCTION LTRS + TIME | AA2: Total RO production | AB2: RO Meter reading | AD2: 0 | AE2: STP | AF2: GAS TANK A | AG2: GAS TANK B | AH2: GAS TANK C | AI2: Total Gas Tanks | AJ2: Kg /day | AK2: TOTAL GAS cons.
A3: Rate Tsh /$ | B3: 1640 | C3: Diesel cost / lits | D3: 2175 | F3: =SUM(D3/B3) -> 1.3262195 | H3: =Gen!D11 -> 43219.56 | K3: Transport consumption | M3: Balance | O3: PLANT NO 1 | S3: PLANT NO 2 | W3: PLANT NO 3 | AA3: /day | AB3: Balance | AD3: 0 | AE3: Production | AF3: Capacity | AG3: Capacity | AH3: Capacity | AI3: Kg | AJ3: /day | AK3: /day
B4: Rooms OCC | C4: % | D4: Guest Rooms Occ | F4: Electricity Production Cost /Room Occ by guest | G4: All Cost /Room Occ by guest | O4: Flow M3 | P4: Reading Hours Meter | Q4: Hrs | R4: total production M3 | S4: Flow M3 | T4: Reading Hours Meter | U4: Hrs | V4: total production M3 | W4: Flow M3 | X4: READING HOURS METER | Y4: Hrs | Z4: total production M3 | AA4: M3 | AC4: M3 | AE4: M3 | AF4: 2000 | AG4: 1000 | AH4: 1000 | AI4: #VALUE! | AJ4: Kg | AK4: M3
P5: 19136 | T5: 20105 | X5: 29498 | AB5: 19032 | AD5: 226990 | AF5: 0.85 | AG5: 0.85 | AH5: 0.85
A6: =Gen!B11 -> 44531 | B6: ='Summery Report'!E5 -> 6 | C6: =Gen!C11 -> 0.0519 | D6: ='Summery Report'!E5 -> 6 | E6: =SUM(F3) -> 1.3262195 | F6: =SUM(J6*E6)/D6 -> 691.84451 | G6: =SUM(L6*E6)/D6 -> 691.84451 | H6: =Gen!D11 -> 43219.56 | I6: =Gen!F11 -> 0 | J6: =Gen!U11 -> 3130 | K6: =Gen!AL11 -> 0 | L6: =SUM(J6:K6) -> 3130 | M6: ='Water-Meter'!K46 -> 579.88445 | N6: ='Water-Meter'!E6 -> 79 | P6: 19136 | Q6: =SUM(P6-P5) -> 0 | R6: =SUM(Q6*O6) -> 0 | S6: 7 | T6: 20110 | U6: =T6-T5 -> 5 | V6: =SUM(U6*S7) -> 35 | X6: 29498 | Y6: =X6-X5 -> 0 | Z6: =Y6-Y5 -> 0 | AA6: =Z6-Z5 -> 0 | AB6: 19067 | AC6: =AB6-AB5 -> 35 | AD6: 227063 | AE6: =AD6-AD5 -> 73 | AF6: ='Lpg (2)'!B10*2000/85 -> 2000 | AG6: ='Lpg (2)'!C10*1000/85 -> 988.23529 | AH6: ='Lpg (2)'!D10*1000/85 -> 0 | AI6: =SUM(AF6*2000)+(AG6*1000)+(AH6*1000) -> 4988235.3 | AJ6: =SUM(AI5-AI6) -> -4988235.3
A7: =Gen!B12 -> 44532 | B7: ='Summery Report'!E6 -> 5 | C7: =Gen!C12 -> 0.05 | D7: ='Summery Report'!E6 -> 5 | E7: =SUM(E6) -> 1.3262195 | F7: =SUM(J7*E7)/D7 -> 823.58232 | G7: =SUM(L7*E7)/D7 -> 823.58232 | H7: =Gen!D12 -> 41823.56 | I7: =Gen!F12 -> 0 | J7: =Gen!U12 -> 3105 | K7: =Gen!AL12 -> 0 | L7: =SUM(J7:K7) -> 3105 | M7: ='Water-Meter'!K47 -> 574.08186 | N7: ='Water-Meter'!E7 -> 67 | P7: 19136 | Q7: =SUM(P7-P6) -> 0 | R7: =SUM(Q7*O7) -> 0 | S7: 7 | T7: 20119 | U7: =T7-T6 -> 9 | V7: =SUM(U7*S8) -> 63 | X7: 29498 | Y7: =X7-X6 -> 0 | Z7: =SUM(Y7*W7) -> 0 | AA7: =SUM(Z7*X9) -> 0 | AB7: 19128 | AC7: =AB7-AB6 -> 61 | AD7: 227132 | AE7: =AD7-AD6 -> 69 | AF7: ='Lpg (2)'!B11*2000/85 -> 2000 | AG7: ='Lpg (2)'!C11*1000/85 -> 941.17647 | AH7: ='Lpg (2)'!D11*1000/85 -> 0 | AI7: =SUM(AF6*2000)+(AG7*1000)+(AH7*1000) -> 4941176.5 | AJ7: =SUM(AI6-AI7) -> 47058.824
A8: =Gen!B13 -> 44533 | B8: ='Summery Report'!E7 -> 3 | C8: =Gen!C13 -> 0.05 | D8: ='Summery Report'!E7 -> 3 | E8: =SUM(E7) -> 1.3262195 | F8: =SUM(J8*E8)/D8 -> 1286.4329 | G8: =SUM(L8*E8)/D8 -> 1286.4329 | H8: =Gen!D13 -> 39958.71 | I8: =Gen!F13 -> 0 | J8: =Gen!U13 -> 2910 | K8: =Gen!AL13 -> 0 | L8: =SUM(J8:K8) -> 2910 | M8: ='Water-Meter'!K48 -> 554.48732 | N8: ='Water-Meter'!E8 -> 83 | P8: 19136 | Q8: =SUM(P8-P7) -> 0 | R8: =SUM(Q8*O8) -> 0 | S8: 7 | T8: 20126 | U8: =T8-T7 -> 7 | V8: =SUM(U8*S9) -> 49 | X8: 29498 | Y8: =X8-X7 -> 0 | Z8: =SUM(Y8*W8) -> 0 | AA8: =SUM(Z8*X10) -> 0 | AB8: 19178 | AC8: =AB8-AB7 -> 50 | AD8: 227202 | AE8: =AD8-AD7 -> 70 | AF8: ='Lpg (2)'!B12*2000/85 -> 2000 | AG8: ='Lpg (2)'!C12*1000/85 -> 870.58824 | AH8: ='Lpg (2)'!D12*1000/85 -> 0 | AI8: =SUM(AF7*2000)+(AG8*1000)+(AH8*1000) -> 4870588.2 | AJ8: =SUM(AI7-AI8) -> 70588.235
A9: =Gen!B14 -> 44534 | B9: ='Summery Report'!E8 -> 8 | C9: =Gen!C14 -> 0.08 | D9: ='Summery Report'!E8 -> 8 | E9: =SUM(E8) -> 1.3262195 | F9: =SUM(J9*E9)/D9 -> 545.242 | G9: =SUM(L9*E9)/D9 -> 545.242 | H9: =Gen!D14 -> 38781.54 | I9: =Gen!F14 -> 0 | J9: =Gen!U14 -> 3289 | K9: =Gen!AL14 -> 0 | L9: =SUM(J9:K9) -> 3289 | M9: ='Water-Meter'!K49 -> 534.16708 | N9: ='Water-Meter'!E9 -> 67 | P9: 19136 | Q9: =SUM(P9-P7) -> 0 | R9: =SUM(Q9*O9) -> 0 | S9: 7 | T9: 20138 | U9: =T9-T8 -> 12 | V9: =SUM(U9*S10) -> 84 | X9: 29498 | Y9: =X9-X8 -> 0 | Z9: =SUM(Y9*W11) -> 0 | AA9: =SUM(Z9*X11) -> 0 | AB9: 19267 | AC9: =AB9-AB8 -> 89 | AD9: 227265 | AE9: =AD9-AD8 -> 63 | AF9: ='Lpg (2)'!B13*2000/85 -> 2000 | AG9: ='Lpg (2)'!C13*1000/85 -> 764.70588 | AH9: ='Lpg (2)'!D13*1000/85 -> 0 | AI9: =SUM(AF8*2000)+(AG9*1000)+(AH9*1000) -> 4764705.9 | AJ9: =SUM(AI8-AI9) -> 105882.35
A10: =Gen!B15 -> 44535 | B10: ='Summery Report'!E9 -> 6 | C10: =Gen!C15 -> 0.05 | D10: ='Summery Report'!E9 -> 6 | E10: =SUM(E9) -> 1.3262195 | F10: =SUM(J10*E10)/D10 -> 695.3811 | G10: =SUM(L10*E10)/D10 -> 695.3811 | H10: =Gen!D15 -> 37288.81 | I10: =Gen!F15 -> 0 | J10: =Gen!U15 -> 3146 | K10: =Gen!AL15 -> 0 | L10: =SUM(J10:K10) -> 3146 | M10: ='Water-Meter'!K50 -> 517.28554 | N10: ='Water-Meter'!E10 -> 62 | P10: 19136 | Q10: =SUM(P10-P9) -> 0 | R10: =SUM(Q10*O10) -> 0 | S10: 7 | T10: 20154 | U10: =T10-T9 -> 16 | V10: =SUM(U10*S11) -> 112 | X10: 29498 | Y10: =X10-X9 -> 0 | Z10: =SUM(Y10*W10) -> 0 | AA10: =SUM(Z10*X12) -> 0 | AB10: 19370 | AC10: =AB10-AB9 -> 103 | AD10: 227312 | AE10: =AD10-AD9 -> 47 | AF10: ='Lpg (2)'!B14*2000/85 -> 2000 | AG10: ='Lpg (2)'!C14*1000/85 -> 647.05882 | AH10: ='Lpg (2)'!D14*1000/85 -> 0 | AI10: =SUM(AF9*2000)+(AG10*1000)+(AH10*1000) -> 4647058.8 | AJ10: =SUM(AI9-AI10) -> 117647.06
A11: =Gen!B16 -> 44536 | B11: ='Summery Report'!E10 -> 9 | C11: =Gen!C16 -> 0.0779 | D11: ='Summery Report'!E10 -> 9 | E11: =SUM(E10) -> 1.3262195 | F11: =SUM(J11*E11)/D11 -> 495.26931 | G11: =SUM(L11*E11)/D11 -> 495.26931 | H11: =Gen!D16 -> 35988.55 | I11: =Gen!F16 -> 0 | J11: =Gen!U16 -> 3361 | K11: =Gen!AL16 -> 0 | L11: =SUM(J11:K11) -> 3361 | M11: ='Water-Meter'!K51 -> 521.78639 | N11: ='Water-Meter'!E11 -> 57 | P11: 19136 | Q11: =SUM(P11-P10) -> 0 | R11: =SUM(Q11*O11) -> 0 | S11: 7 | T11: 20158 | U11: =T11-T10 -> 4 | V11: =SUM(U11*S12) -> 27.2 | X11: 29498 | Y11: =X11-X10 -> 0 | Z11: =SUM(Y11*W11) -> 0 | AA11: =SUM(Z11*X13) -> 0 | AB11: 19387 | AC11: =AB11-AB10 -> 17 | AD11: 227365 | AE11: =AD11-AD10 -> 53 | AF11: ='Lpg (2)'!B15*2000/85 -> 2000 | AG11: ='Lpg (2)'!C15*1000/85 -> 588.23529 | AH11: ='Lpg (2)'!D15*1000/85 -> 0 | AI11: =SUM(AF10*2000)+(AG11*1000)+(AH11*1000) -> 4588235.3 | AJ11: =SUM(AI10-AI11) -> 58823.529
A12: =Gen!B17 -> 44537 | B12: ='Summery Report'!E11 -> 9 | C12: =Gen!C17 -> 0.0779 | D12: ='Summery Report'!E11 -> 9 | E12: =SUM(E11) -> 1.3262195 | F12: =SUM(J12*E12)/D12 -> 498.06911 | G12: =SUM(L12*E12)/D12 -> 498.06911 | H12: =Gen!D17 -> 34595.26 | I12: =Gen!F17 -> 18000 | J12: =Gen!U17 -> 3380 | K12: =Gen!AL17 -> 0 | L12: =SUM(J12:K12) -> 3380 | M12: ='Water-Meter'!K52 -> 440.4761 | N12: ='Water-Meter'!E12 -> 73 | P12: 19136 | Q12: =SUM(P12-P11) -> 0 | R12: =SUM(Q12*O12) -> 0 | S12: 6.8 | T12: 20174 | U12: =T12-T11 -> 16 | V12: =SUM(U12*S12) -> 108.8 | X12: 29498 | Y12: =X12-X11 -> 0 | Z12: =SUM(Y12*W12) -> 0 | AA12: =SUM(Z12*X14) -> 0 | AB12: 19508 | AC12: =AB12-AB11 -> 121 | AD12: 227415 | AE12: =AD12-AD11 -> 50 | AF12: ='Lpg (2)'!B16*2000/85 -> 2000 | AG12: ='Lpg (2)'!C16*1000/85 -> 529.41176 | AH12: ='Lpg (2)'!D16*1000/85 -> 0 | AI12: =SUM(AF11*2000)+(AG12*1000)+(AH12*1000) -> 4529411.8 | AJ12: =SUM(AI11-AI12) -> 58823.529
A13: =Gen!B18 -> 44538 | B13: ='Summery Report'!E12 -> 12 | C13: =Gen!C18 -> 0.12 | D13: ='Summery Report'!E12 -> 12 | E13: =SUM(E12) -> 1.3262195 | F13: =SUM(J13*E13)/D13 -> 404.71799 | G13: =SUM(L13*E13)/D13 -> 404.71799 | H13: =Gen!D18 -> 33090.38 | I13: =Gen!F18 -> 0 | J13: =Gen!U18 -> 3662 | K13: =Gen!AL18 -> 0 | L13: =SUM(J13:K13) -> 3662 | M13: ='Water-Meter'!K53 -> 541.76567 | N13: ='Water-Meter'!E13 -> 80 | P13: 19136 | Q13: =SUM(P13-P12) -> 0 | R13: =SUM(Q13*O13) -> 0 | S13: 7 | T13: 20198 | U13: =T13-T12 -> 24 | V13: =SUM(U13*S13) -> 168 | X13: 29498 | Y13: =X13-X12 -> 0 | Z13: =SUM(Y13*W13) -> 0 | AA13: =SUM(Z13*X15) -> 0 | AB13: 19678 | AC13: =AB13-AB12 -> 170 | AD13: 227478 | AE13: =AD13-AD12 -> 63 | AF13: ='Lpg (2)'!B17*2000/85 -> 2000 | AG13: ='Lpg (2)'!C17*1000/85 -> 470.58824 | AH13: ='Lpg (2)'!D17*1000/85 -> 0 | AI13: =SUM(AF12*2000)+(AG13*1000)+(AH13*1000) -> 4470588.2 | AJ13: =SUM(AI12-AI13) -> 58823.529
A14: =Gen!B19 -> 44539 | B14: ='Summery Report'!E13 -> 10 | C14: =Gen!C19 -> 0.09 | D14: ='Summery Report'!E13 -> 10 | E14: =SUM(E13) -> 1.3262195 | F14: =SUM(J14*E14)/D14 -> 450.78201 | G14: =SUM(L14*E14)/D14 -> 450.78201 | H14: =Gen!D19 -> 31479.19 | I14: =Gen!F19 -> 0 | J14: =Gen!U19 -> 3399 | K14: =Gen!AL19 -> 0 | L14: =SUM(J14:K14) -> 3399 | M14: ='Water-Meter'!K54 -> 488.20218 | N14: ='Water-Meter'!E14 -> 65 | P14: 19136 | Q14: =SUM(P14-P13) -> 0 | R14: =SUM(Q14*O14) -> 0 | S14: 6.8 | T14: 20198 | U14: =T14-T13 -> 0 | V14: =SUM(U14*S14) -> 0 | X14: 29498 | Y14: =X14-X13 -> 0 | Z14: =SUM(Y14*W14) -> 0 | AA14: =SUM(Z14*X16) -> 0 | AB14: 19678 | AC14: =AB14-AB13 -> 0 | AD14: 227533 | AE14: =AD14-AD13 -> 55 | AF14: ='Lpg (2)'!B18*2000/85 -> 2000 | AG14: ='Lpg (2)'!C18*1000/85 -> 411.76471 | AH14: ='Lpg (2)'!D18*1000/85 -> 0 | AI14: =SUM(AF13*2000)+(AG14*1000)+(AH14*1000) -> 4411764.7 | AJ14: =SUM(AI13-AI14) -> 58823.529
A15: =Gen!B20 -> 44540 | B15: ='Summery Report'!E14 -> 12 | C15: =Gen!C20 -> 0.12 | D15: ='Summery Report'!E14 -> 12 | E15: =SUM(E14) -> 1.3262195 | F15: =SUM(J15*E15)/D15 -> 380.18293 | G15: =SUM(L15*E15)/D15 -> 380.18293 | H15: =Gen!D20 -> 30055.55 | I15: =Gen!F20 -> 0 | J15: =Gen!U20 -> 3440 | K15: =Gen!AL20 -> 0 | L15: =SUM(J15:K15) -> 3440 | M15: ='Water-Meter'!K55 -> 489.96748 | N15: ='Water-Meter'!E15 -> 71 | P15: 19136 | Q15: =SUM(P15-P14) -> 0 | R15: =SUM(Q15*O15) -> 0 | T15: 20222 | U15: =T15-T14 -> 24 | V15: =SUM(U15*S15) -> 0 | X15: 29498 | Y15: =X15-X14 -> 0 | Z15: =SUM(Y15*W15) -> 0 | AA15: =SUM(Z15*X17) -> 0 | AB15: 19845 | AC15: =AB15-AB14 -> 167 | AD15: 227587 | AE15: =AD15-AD14 -> 54 | AF15: ='Lpg (2)'!B19*2000/85 -> 2000 | AG15: ='Lpg (2)'!C19*1000/85 -> 352.94118 | AH15: ='Lpg (2)'!D19*1000/85 -> 0 | AI15: =SUM(AF15*2000)+(AG15*1000)+(AH15*1000) -> 4352941.2 | AJ15: =SUM(AI14-AI15) -> 58823.529
A16: =Gen!B21 -> 44541 | B16: ='Summery Report'!E15 -> 12 | C16: =Gen!C21 -> 0.12 | D16: ='Summery Report'!E15 -> 12 | E16: =SUM(E15) -> 1.3262195 | F16: =SUM(J16*E16)/D16 -> 408.47561 | G16: =SUM(L16*E16)/D16 -> 408.47561 | H16: =Gen!D21 -> 28259.57 | I16: =Gen!F21 -> 0 | J16: =Gen!U21 -> 3696 | K16: =Gen!AL21 -> 0 | L16: =SUM(J16:K16) -> 3696 | M16: ='Water-Meter'!K56 -> 530.64049 | N16: ='Water-Meter'!E16 -> 72 | P16: 19136 | Q16: =SUM(P16-P15) -> 0 | R16: =SUM(Q16*O16) -> 0 | S16: 6.8 | T16: 20224 | U16: =T16-T15 -> 2 | V16: =SUM(U16*S16) -> 13.6 | X16: 29498 | Y16: =X16-X15 -> 0 | Z16: =SUM(Y16*W16) -> 0 | AA16: =SUM(Z16*X18) -> 0 | AB16: 19860 | AC16: =AB16-AB15 -> 15 | AD16: 227647 | AE16: =AD16-AD15 -> 60 | AF16: ='Lpg (2)'!B20*2000/85 -> 2000 | AG16: ='Lpg (2)'!C20*1000/85 -> 258.82353 | AH16: ='Lpg (2)'!D20*1000/85 -> 0 | AI16: =SUM(AF16*2000)+(AG16*1000)+(AH16*1000) -> 4258823.5 | AJ16: =SUM(AI15-AI16) -> 94117.647
A17: =Gen!B22 -> 44542 | B17: ='Summery Report'!E16 -> 12 | C17: =Gen!C22 -> 0.12 | D17: ='Summery Report'!E16 -> 12 | E17: =SUM(E16) -> 1.3262195 | F17: =SUM(J17*E17)/D17 -> 402.9497 | G17: =SUM(L17*E17)/D17 -> 402.9497 | H17: =Gen!D22 -> 26708.91 | I17: =Gen!F22 -> 0 | J17: =Gen!U22 -> 3646 | K17: =Gen!AL22 -> 0 | L17: =SUM(J17:K17) -> 3646 | M17: ='Water-Meter'!K57 -> 548.84013 | N17: ='Water-Meter'!E17 -> 65 | P17: 19136 | Q17: =SUM(P17-P16) -> 0 | R17: =SUM(Q17*O17) -> 0 | S17: 6.8 | T17: 20247 | U17: =T17-T16 -> 23 | V17: =SUM(U17*S17) -> 156.4 | X17: 29498 | Y17: =X17-X16 -> 0 | Z17: =SUM(Y17*W17) -> 0 | AA17: =SUM(Z17*X19) -> 0 | AB17: 20017 | AC17: =AB17-AB16 -> 157 | AD17: 227709 | AE17: =AD17-AD16 -> 62 | AF17: ='Lpg (2)'!B21*2000/85 -> 2000 | AG17: ='Lpg (2)'!C21*1000/85 -> 176.47059 | AH17: ='Lpg (2)'!D21*1000/85 -> 0 | AI17: =SUM(AF17*2000)+(AG17*1000)+(AH17*1000) -> 4176470.6 | AJ17: =SUM(AI16-AI17) -> 82352.941
