Workbook

Sheet TOTAL
A1: Site Name | B1: Day | C1: Month | D1: Year | E1: Total Electricity Kwh | F1: Electricity Tariff ($/Kwh) | G1: Natual Gas (m3) | H1: Natural Gas $/m3 | I1: Water Utility Supply (m3) m3 | J1: Water Utility Supply (m3) $/m3 | K1: Room Nights | L1: Total Guests
A2: Hampshire | B2: 1 | C2: 10 | D2: 2021 | E2: =(Submetering!E2+Submetering!F2) -> 8657 | F2: 0.14 | G2: =Submetering!M2 -> 0 | H2: 0.25 | I2: =Submetering!N2 -> 117 | J2: 2.06 | K2: ='Hampshire Daily'!B5 -> 57 | L2: ='Hampshire Daily'!D5 -> 1012097
A3: Hampshire | B3: =B2+1 -> 2 | C3: 10 | D3: 2021 | E3: =Submetering!E3+Submetering!F3 -> 8380 | F3: 0.14 | G3: =Submetering!M3 -> 79.333333 | H3: 0.25 | I3: =Submetering!N3 -> 0 | J3: 2.06 | K3: ='Hampshire Daily'!B6 -> 62 | L3: ='Hampshire Daily'!D6 -> 1024010
A4: Hampshire | B4: =B3+1 -> 3 | C4: 10 | D4: 2021 | E4: =Submetering!E4+Submetering!F4 -> 8157 | F4: 0.14 | G4: =Submetering!M4 -> 79.333333 | H4: 0.25 | I4: =Submetering!N4 -> 0 | J4: 2.06 | K4: ='Hampshire Daily'!B7 -> 196 | L4: ='Hampshire Daily'!D7 -> 1027039
A5: Hampshire | B5: =B4+1 -> 4 | C5: 10 | D5: 2021 | E5: =Submetering!E5+Submetering!F5 -> 8046 | F5: 0.14 | G5: =Submetering!M5 -> 105 | H5: 0.25 | I5: =Submetering!N5 -> 0 | J5: 2.06 | K5: ='Hampshire Daily'!B8 -> 146 | L5: ='Hampshire Daily'!D8 -> 1030058
A6: Hampshire | B6: =B5+1 -> 5 | C6: 10 | D6: 2021 | E6: =Submetering!E6+Submetering!F6 -> 8448 | F6: 0.14 | G6: =Submetering!M6 -> 97 | H6: 0.25 | I6: =Submetering!N6 -> 0 | J6: 2.06 | K6: ='Hampshire Daily'!B9 -> 74 | L6: ='Hampshire Daily'!D9 -> 1032995
A7: Hampshire | B7: =B6+1 -> 6 | C7: 10 | D7: 2021 | E7: =Submetering!E7+Submetering!F7 -> 7909 | F7: 0.14 | G7: =Submetering!M7 -> 103 | H7: 0.25 | I7: =Submetering!N7 -> 0 | J7: 2.06 | K7: ='Hampshire Daily'!B10 -> 73 | L7: ='Hampshire Daily'!D10 -> 1035888
A8: Hampshire | B8: =B7+1 -> 7 | C8: 10 | D8: 2021 | E8: =Submetering!E8+Submetering!F8 -> 7815 | F8: 0.14 | G8: =Submetering!M8 -> 88 | H8: 0.25 | I8: =Submetering!N8 -> 0 | J8: 2.06 | K8: ='Hampshire Daily'!B11 -> 65 | L8: ='Hampshire Daily'!D11 -> 1038828
A9: Hampshire | B9: =B8+1 -> 8 | C9: 10 | D9: 2021 | E9: =Submetering!E9+Submetering!F9 -> 10623 | F9: 0.14 | G9: =Submetering!M9 -> 80 | H9: 0.25 | I9: =Submetering!N9 -> 0 | J9: 2.06 | K9: ='Hampshire Daily'!B12 -> 58 | L9: ='Hampshire Daily'!D12 -> 1044422
A10: Hampshire | B10: =B9+1 -> 9 | C10: 10 | D10: 2021 | E10: =Submetering!E10+Submetering!F10 -> 8292 | F10: 0.14 | G10: =Submetering!M10 -> 113 | H10: 0.25 | I10: =Submetering!N10 -> 0 | J10: 2.06 | K10: ='Hampshire Daily'!B13 -> 80 | L10: ='Hampshire Daily'!D13 -> 1047736
A11: Hampshire | B11: =B10+1 -> 10 | C11: 10 | D11: 2021 | E11: =Submetering!E11+Submetering!F11 -> 9855 | F11: 0.14 | G11: =Submetering!M11 -> 85 | H11: 0.25 | I11: =Submetering!N11 -> 0 | J11: 2.06 | K11: ='Hampshire Daily'!B14 -> 136 | L11: ='Hampshire Daily'!D14 -> 1052381
A12: Hampshire | B12: =B11+1 -> 11 | C12: 10 | D12: 2021 | E12: =Submetering!E12+Submetering!F12 -> 6753 | F12: 0.14 | G12: =Submetering!M12 -> 125 | H12: 0.25 | I12: =Submetering!N12 -> 0 | J12: 2.06 | K12: ='Hampshire Daily'!B15 -> 149 | L12: ='Hampshire Daily'!D15 -> 1056266
A13: Hampshire | B13: =B12+1 -> 12 | C13: 10 | D13: 2021 | E13: =Submetering!E13+Submetering!F13 -> 4642 | F13: 0.14 | G13: =Submetering!M13 -> 98 | H13: 0.25 | I13: =Submetering!N13 -> 0 | J13: 2.06 | K13: ='Hampshire Daily'!B16 -> 128 | L13: ='Hampshire Daily'!D16 -> 1058994
A14: Hampshire | B14: =B13+1 -> 13 | C14: 10 | D14: 2021 | E14: =Submetering!E14+Submetering!F14 -> 5039 | F14: 0.14 | G14: =Submetering!M14 -> 99 | H14: 0.25 | I14: =Submetering!N14 -> 0 | J14: 2.06 | K14: ='Hampshire Daily'!B17 -> 110 | L14: ='Hampshire Daily'!D17 -> 1061771
... A20: Hampshire | B20: =B19+1 -> 19 | C20: 10 | D20: 2021 | E20: =Submetering!E20+Submetering!F20 -> 8912 | F20: 0.14 | G20: =Submetering!M20 -> 128 | H20: 0.25 | I20: =Submetering!N20 -> 435 | J20: 2.06 | K20: ='Hampshire Daily'!B23 -> 195 | L20: ='Hampshire Daily'!D23 -> 1079348
A21: Hampshire | B21: =B20+1 -> 20 | C21: 10 | D21: 2021 | E21: =Submetering!E21+Submetering!F21 -> 7969 | F21: 0.14 | G21: =Submetering!M21 -> 128 | H21: 0.25 | I21: =Submetering!N21 -> 0 | J21: 2.06 | K21: ='Hampshire Daily'!B24 -> 206 | L21: ='Hampshire Daily'!C24 -> 69
A22: Hampshire | B22: =B21+1 -> 21 | C22: 10 | D22: 2021 | E22: =Submetering!E22+Submetering!F22 -> 9468 | F22: 0.14 | G22: =Submetering!M22 -> 2716 | H22: 0.25 | I22: =Submetering!N22 -> 116.5 | J22: 2.06 | K22: ='Hampshire Daily'!B25 -> 208 | L22: ='Hampshire Daily'!C25 -> 70
A23: Hampshire | B23: =B22+1 -> 22 | C23: 10 | D23: 2021 | E23: =Submetering!E23+Submetering!F23 -> 8251 | F23: 0.14 | G23: =Submetering!M23 -> 2687 | H23: 0.25 | I23: =Submetering!N23 -> 116.5 | J23: 2.06 | K23: ='Hampshire Daily'!B26 -> 185 | L23: ='Hampshire Daily'!C26 -> 64
A24: Hampshire | B24: =B23+1 -> 23 | C24: 10 | D24: 2021 | E24: =Submetering!E24+Submetering!F24 -> 8433 | F24: 0.14 | G24: =Submetering!M24 -> 2703 | H24: 0.25 | I24: =Submetering!N24 -> 124 | J24: 2.06 | K24: ='Hampshire Daily'!B27 -> 194 | L24: ='Hampshire Daily'!C27 -> 77
A25: Hampshire | B25: =B24+1 -> 24 | C25: 10 | D25: 2021 | E25: =Submetering!E25+Submetering!F25 -> 5800 | F25: 0.14 | G25: =Submetering!M25 -> 2909 | H25: 0.25 | I25: =Submetering!N25 -> 123 | J25: 2.06 | K25: ='Hampshire Daily'!B28 -> 233 | L25: ='Hampshire Daily'!C28 -> 96
A26: Hampshire | B26: =B25+1 -> 25 | C26: 10 | D26: 2021 | E26: =Submetering!E26+Submetering!F26 -> 5335 | F26: 0.14 | G26: =Submetering!M26 -> 2812 | H26: 0.25 | I26: =Submetering!N26 -> 156 | J26: 2.06 | K26: ='Hampshire Daily'!B29 -> 233 | L26: ='Hampshire Daily'!C29 -> 99
A27: Hampshire | B27: =B26+1 -> 26 | C27: 10 | D27: 2021 | E27: =Submetering!E27+Submetering!F27 -> 5030 | F27: 0.14 | G27: =Submetering!M27 -> 2857 | H27: 0.25 | I27: =Submetering!N27 -> 110 | J27: 2.06 | K27: ='Hampshire Daily'!B30 -> 217 | L27: ='Hampshire Daily'!C30 -> 89
A28: Hampshire | B28: =B27+1 -> 27 | C28: 10 | D28: 2021 | E28: =Submetering!E28+Submetering!F28 -> 4802 | F28: 0.14 | G28: =Submetering!M28 -> 2730 | H28: 0.25 | I28: =Submetering!N28 -> 186 | J28: 2.06 | K28: ='Hampshire Daily'!B31 -> 198 | L28: ='Hampshire Daily'!C31 -> 75
A29: Hampshire | B29: =B28+1 -> 28 | C29: 10 | D29: 2021 | E29: =Submetering!E29+Submetering!F29 -> 5554 | F29: 0.14 | G29: =Submetering!M29 -> 2760 | H29: 0.25 | I29: =Submetering!N29 -> 124 | J29: 2.06 | K29: ='Hampshire Daily'!B32 -> 206 | L29: ='Hampshire Daily'!C32 -> 78
A30: Hampshire | B30: =B29+1 -> 29 | C30: 10 | D30: 2021 | E30: =Submetering!E30+Submetering!F30 -> 5574 | F30: 0.14 | G30: =Submetering!M30 -> 2850 | H30: 0.25 | I30: =Submetering!N30 -> 112 | J30: 2.06 | K30: ='Hampshire Daily'!B33 -> 209 | L30: ='Hampshire Daily'!C33 -> 75
A31: Hampshire | B31: =B30+1 -> 30 | C31: 10 | D31: 2021 | E31: =Submetering!E31+Submetering!F31 -> 5295 | F31: 0.14 | G31: =Submetering!M31 -> 2522 | H31: 0.25 | I31: =Submetering!N31 -> 110 | J31: 2.06 | K31: ='Hampshire Daily'!B34 -> 224 | L31: ='Hampshire Daily'!C34 -> 80
A32: Hampshire | B32: 31 | C32: 10 | D32: 2021 | E32: =Submetering!E32+Submetering!F32 -> 5706 | F32: 0.14 | G32: =Submetering!M32 -> 2575 | H32: 0.25 | I32: =Submetering!N32 -> 131 | J32: 2.06 | K32: ='Hampshire Daily'!B35 -> 217 | L32: ='Hampshire Daily'!C35 -> 77

Sheet Submetering
A1: Site Name | B1: Day | C1: Month | D1: Year | E1: Meter 1- KWh | F1: Meter 2- KWh | G1: East MCC- KWh | H1: South MCC 1- KWh | I1: South MCC 2- KWh | J1: West MCC- KWh | K1: Kitchen - KWh | L1: SPA - KWh | M1: Gas- KWh | N1: Main Site Water Meter - m3 | O1: Chiller 2- m3 | P1: Chiller 3- m3 | Q1: Chiller 4- m3 | R1: Hard Water Supply- m3 | S1: Pool Supply- m3 | T1: LTHW SPA- m3 | U1: LTHW East- m3 | V1: Chilled make-up- m3 | W1: Orchard irrigation | X1: Kids Pool | Y1: Room Nights | Z1: Total Guests
A2: Hampshire | B2: 1 | C2: 10 | D2: 2021 | E2: =IF(('Hampshire Daily'!E5-'Hampshire Daily'!D4<0),"0",('Hampshire Daily'!E5-'Hampshire Daily'!D4)) -> 4557 | F2: =IF(('Hampshire Daily'!G5-'Hampshire Daily'!F4<0),"0",('Hampshire Daily'!G5-'Hampshire Daily'!F4)) -> 4100 | G2: =IF(('Hampshire Daily'!H5-'Hampshire Daily'!H4<0),"0",('Hampshire Daily'!H5-'Hampshire Daily'!H4)) -> 786 | H2: =IF(('Hampshire Daily'!I5-'Hampshire Daily'!I4<0),"0",('Hampshire Daily'!I5-'Hampshire Daily'!I4)) -> 2367.0968 | I2: =IF(('Hampshire Daily'!J5-'Hampshire Daily'!J4<0),"0",('Hampshire Daily'!J5-'Hampshire Daily'!J4)) -> 0.12903226 | J2: =IF(('Hampshire Daily'!L5-'Hampshire Daily'!K4<0),"0",('Hampshire Daily'!L5-'Hampshire Daily'!K4)) -> 0 | K2: =IF(('Hampshire Daily'!M5-'Hampshire Daily'!L4<0),"0",('Hampshire Daily'!M5-'Hampshire Daily'!L4)) -> 1752971 | L2: =IF(('Hampshire Daily'!N5-'Hampshire Daily'!M4<0),"0",('Hampshire Daily'!N5-'Hampshire Daily'!M4)) -> 0 | M2: =IF(('Hampshire Daily'!O5-'Hampshire Daily'!N4<0),"0",('Hampshire Daily'!O5-'Hampshire Daily'!N4)) -> 0 | N2: 117 | O2: =IF(('Hampshire Daily'!Q5-'Hampshire Daily'!P4<0),"0",('Hampshire Daily'!Q5-'Hampshire Daily'!P4)) -> 0 | P2: =IF(('Hampshire Daily'!R5-'Hampshire Daily'!Q4<0),"0",('Hampshire Daily'!R5-'Hampshire Daily'!Q4)) -> 0 | Q2: =IF(('Hampshire Daily'!S5-'Hampshire Daily'!R4<0),"0",('Hampshire Daily'!S5-'Hampshire Daily'!R4)) -> 343198 | R2: =IF(('Hampshire Daily'!V5-'Hampshire Daily'!U4<0),"0",('Hampshire Daily'!V5-'Hampshire Daily'!U4)) -> 0 | S2: =IF(('Hampshire Daily'!W5-'Hampshire Daily'!V4<0),"0",('Hampshire Daily'!W5-'Hampshire Daily'!V4)) -> 0 | T2: =IF(('Hampshire Daily'!X5-'Hampshire Daily'!W4<0),"0",('Hampshire Daily'!X5-'Hampshire Daily'!W4)) -> 464.481 | U2: =IF(('Hampshire Daily'!Y5-'Hampshire Daily'!X4<0),"0",('Hampshire Daily'!Y5-'Hampshire Daily'!X4)) -> 2934.789 | V2: =IF(('Hampshire Daily'!Z5-'Hampshire Daily'!Y4<0),"0",('Hampshire Daily'!Z5-'Hampshire Daily'!Y4)) -> 508.413 | W2: =IF(('Hampshire Daily'!AA5-'Hampshire Daily'!Z4<0),"0",('Hampshire Daily'!AA5-'Hampshire Daily'!Z4)) -> 0 | X2: =IF(('Hampshire Daily'!AA5-'Hampshire Daily'!AA4<0),"0",('Hampshire Daily'!AA5-'Hampshire Daily'!AA4)) -> 4 | Y2: ='Hampshire Daily'!B5 -> 57 | Z2: ='Hampshire Daily'!C5 -> 29
A3: Hampshire | B3: =B2+1 -> 2 | C3: 10 | D3: 2021 | E3: =IF(('Hampshire Daily'!E6-'Hampshire Daily'!E5<0),"0",('Hampshire Daily'!E6-'Hampshire Daily'!E5)) -> 3055 | F3: =IF(('Hampshire Daily'!G6-'Hampshire Daily'!G5<0),"0",('Hampshire Daily'!G6-'Hampshire Daily'!G5)) -> 5325 | G3: =IF(('Hampshire Daily'!H6-'Hampshire Daily'!H5<0),"0",('Hampshire Daily'!H6-'Hampshire Daily'!H5)) -> 831 | H3: =IF(('Hampshire Daily'!I6-'Hampshire Daily'!I5<0),"0",('Hampshire Daily'!I6-'Hampshire Daily'!I5)) -> 2367.0968 | I3: =IF(('Hampshire Daily'!J6-'Hampshire Daily'!J5<0),"0",('Hampshire Daily'!J6-'Hampshire Daily'!J5)) -> 0.12903226 | J3: =IF(('Hampshire Daily'!L6-'Hampshire Daily'!L5<0),"0",('Hampshire Daily'!L6-'Hampshire Daily'!L5)) -> 0 | K3: =IF(('Hampshire Daily'!M6-'Hampshire Daily'!M5<0),"0",('Hampshire Daily'!M6-'Hampshire Daily'!M5)) -> 0 | L3: =IF(('Hampshire Daily'!N6-'Hampshire Daily'!N5<0),"0",('Hampshire Daily'!N6-'Hampshire Daily'!N5)) -> 2761 | M3: =IF(('Hampshire Daily'!O6-'Hampshire Daily'!O5<0),"0",('Hampshire Daily'!O6-'Hampshire Daily'!O5)) -> 79.333333 | N3: =IF(('Hampshire Daily'!P6-'Hampshire Daily'!P5<0),"0",('Hampshire Daily'!P6-'Hampshire Daily'!P5)) -> 0 | O3: =IF(('Hampshire Daily'!Q6-'Hampshire Daily'!Q5<0),"0",('Hampshire Daily'!Q6-'Hampshire Daily'!Q5)) -> 0 | P3: =IF(('Hampshire Daily'!R6-'Hampshire Daily'!R5<0),"0",('Hampshire Daily'!R6-'Hampshire Daily'!R5)) -> 52 | Q3: =IF(('Hampshire Daily'!S6-'Hampshire Daily'!S5<0),"0",('Hampshire Daily'!S6-'Hampshire Daily'!S5)) -> 45 | R3: =IF(('Hampshire Daily'!V6-'Hampshire Daily'!V5<0),"0",('Hampshire Daily'!V6-'Hampshire Daily'!V5)) -> 2 | S3: =IF(('Hampshire Daily'!W6-'Hampshire Daily'!W5<0),"0",('Hampshire Daily'!W6-'Hampshire Daily'!W5)) -> 0 | T3: =IF(('Hampshire Daily'!X6-'Hampshire Daily'!X5<0),"0",('Hampshire Daily'!X6-'Hampshire Daily'!X5)) -> 0.244 | U3: =IF(('Hampshire Daily'!Y6-'Hampshire Daily'!Y5<0),"0",('Hampshire Daily'!Y6-'Hampshire Daily'!Y5)) -> 0.009 | V3: =IF(('Hampshire Daily'!Z6-'Hampshire Daily'!Z5<0),"0",('Hampshire Daily'!Z6-'Hampshire Daily'!Z5)) -> 0 | W3: =IF(('Hampshire Daily'!AA6-'Hampshire Daily'!AA5<0),"0",('Hampshire Daily'!AA6-'Hampshire Daily'!AA5)) -> 4 | X3: =IF(('Hampshire Daily'!AA6-'Hampshire Daily'!AA5<0),"0",('Hampshire Daily'!AA6-'Hampshire Daily'!AA5)) -> 4 | Y3: ='Hampshire Daily'!B6 -> 62 | Z3: ='Hampshire Daily'!C6 -> 37
A4: Hampshire | B4: =B3+1 -> 3 | C4: 10 | D4: 2021 | E4: =IF(('Hampshire Daily'!E7-'Hampshire Daily'!E6<0),"0",('Hampshire Daily'!E7-'Hampshire Daily'!E6)) -> 3035 | F4: =IF(('Hampshire Daily'!G7-'Hampshire Daily'!G6<0),"0",('Hampshire Daily'!G7-'Hampshire Daily'!G6)) -> 5122 | G4: =IF(('Hampshire Daily'!H7-'Hampshire Daily'!H6<0),"0",('Hampshire Daily'!H7-'Hampshire Daily'!H6)) -> 844 | H4: =IF(('Hampshire Daily'!I7-'Hampshire Daily'!I6<0),"0",('Hampshire Daily'!I7-'Hampshire Daily'!I6)) -> 2367.0968 | I4: =IF(('Hampshire Daily'!J7-'Hampshire Daily'!J6<0),"0",('Hampshire Daily'!J7-'Hampshire Daily'!J6)) -> 0.12903226 | J4: =IF(('Hampshire Daily'!L7-'Hampshire Daily'!L6<0),"0",('Hampshire Daily'!L7-'Hampshire Daily'!L6)) -> 0 | K4: =IF(('Hampshire Daily'!M7-'Hampshire Daily'!M6<0),"0",('Hampshire Daily'!M7-'Hampshire Daily'!M6)) -> 200003 | L4: =IF(('Hampshire Daily'!N7-'Hampshire Daily'!N6<0),"0",('Hampshire Daily'!N7-'Hampshire Daily'!N6)) -> 2847 | M4: =IF(('Hampshire Daily'!O7-'Hampshire Daily'!O6<0),"0",('Hampshire Daily'!O7-'Hampshire Daily'!O6)) -> 79.333333 | N4: =IF(('Hampshire Daily'!P7-'Hampshire Daily'!P6<0),"0",('Hampshire Daily'!P7-'Hampshire Daily'!P6)) -> 0 | O4: =IF(('Hampshire Daily'!Q7-'Hampshire Daily'!Q6<0),"0",('Hampshire Daily'!Q7-'Hampshire Daily'!Q6)) -> 0 | P4: =IF(('Hampshire Daily'!R7-'Hampshire Daily'!R6<0),"0",('Hampshire Daily'!R7-'Hampshire Daily'!R6)) -> 48 | Q4: =IF(('Hampshire Daily'!S7-'Hampshire Daily'!S6<0),"0",('Hampshire Daily'!S7-'Hampshire Daily'!S6)) -> 48 | R4: =IF(('Hampshire Daily'!V7-'Hampshire Daily'!V6<0),"0",('Hampshire Daily'!V7-'Hampshire Daily'!V6)) -> 1 | S4: =IF(('Hampshire Daily'!W7-'Hampshire Daily'!W6<0),"0",('Hampshire Daily'!W7-'Hampshire Daily'!W6)) -> 0 | T4: =IF(('Hampshire Daily'!X7-'Hampshire Daily'!X6<0),"0",('Hampshire Daily'!X7-'Hampshire Daily'!X6)) -> 0.538 | U4: =IF(('Hampshire Daily'!Y7-'Hampshire Daily'!Y6<0),"0",('Hampshire Daily'!Y7-'Hampshire Daily'!Y6)) -> 0.011 | V4: =IF(('Hampshire Daily'!Z7-'Hampshire Daily'!Z6<0),"0",('Hampshire Daily'!Z7-'Hampshire Daily'!Z6)) -> 0 | W4: =IF(('Hampshire Daily'!AA7-'Hampshire Daily'!AA6<0),"0",('Hampshire Daily'!AA7-'Hampshire Daily'!AA6)) -> 4 | X4: =IF(('Hampshire Daily'!AA7-'Hampshire Daily'!AA6<0),"0",('Hampshire Daily'!AA7-'Hampshire Daily'!AA6)) -> 4 | Y4: ='Hampshire Daily'!B7 -> 196 | Z4: ='Hampshire Daily'!C7 -> 108
A5: Hampshire | B5: =B4+1 -> 4 | C5: 10 | D5: 2021 | E5: =IF(('Hampshire Daily'!E8-'Hampshire Daily'!E7<0),"0",('Hampshire Daily'!E8-'Hampshire Daily'!E7)) -> 3024 | F5: =IF(('Hampshire Daily'!G8-'Hampshire Daily'!G7<0),"0",('Hampshire Daily'!G8-'Hampshire Daily'!G7)) -> 5022 | G5: =IF(('Hampshire Daily'!H8-'Hampshire Daily'!H7<0),"0",('Hampshire Daily'!H8-'Hampshire Daily'!H7)) -> 811 | H5: =IF(('Hampshire Daily'!I8-'Hampshire Daily'!I7<0),"0",('Hampshire Daily'!I8-'Hampshire Daily'!I7)) -> 2367.0968 | I5: =IF(('Hampshire Daily'!J8-'Hampshire Daily'!J7<0),"0",('Hampshire Daily'!J8-'Hampshire Daily'!J7)) -> 0.12903226 | J5: =IF(('Hampshire Daily'!L8-'Hampshire Daily'!L7<0),"0",('Hampshire Daily'!L8-'Hampshire Daily'!L7)) -> 0 | K5: =IF(('Hampshire Daily'!M8-'Hampshire Daily'!M7<0),"0",('Hampshire Daily'!M8-'Hampshire Daily'!M7)) -> 3 | L5: =IF(('Hampshire Daily'!N8-'Hampshire Daily'!N7<0),"0",('Hampshire Daily'!N8-'Hampshire Daily'!N7)) -> 2365 | M5: =IF(('Hampshire Daily'!O8-'Hampshire Daily'!O7<0),"0",('Hampshire Daily'!O8-'Hampshire Daily'!O7)) -> 105 | N5: =IF(('Hampshire Daily'!P8-'Hampshire Daily'!P7<0),"0",('Hampshire Daily'!P8-'Hampshire Daily'!P7)) -> 0 | O5: =IF(('Hampshire Daily'!Q8-'Hampshire Daily'!Q7<0),"0",('Hampshire Daily'!Q8-'Hampshire Daily'!Q7)) -> 0 | P5: =IF(('Hampshire Daily'!R8-'Hampshire Daily'!R7<0),"0",('Hampshire Daily'!R8-'Hampshire Daily'!R7)) -> 56 | Q5: =IF(('Hampshire Daily'!S8-'Hampshire Daily'!S7<0),"0",('Hampshire Daily'!S8-'Hampshire Daily'!S7)) -> 70 | R5: =IF(('Hampshire Daily'!V8-'Hampshire Daily'!V7<0),"0",('Hampshire Daily'!V8-'Hampshire Daily'!V7)) -> 1 | S5: =IF(('Hampshire Daily'!W8-'Hampshire Daily'!W7<0),"0",('Hampshire Daily'!W8-'Hampshire Daily'!W7)) -> 0 | T5: =IF(('Hampshire Daily'!X8-'Hampshire Daily'!X7<0),"0",('Hampshire Daily'!X8-'Hampshire Daily'!X7)) -> 0.236 | U5: =IF(('Hampshire Daily'!Y8-'Hampshire Daily'!Y7<0),"0",('Hampshire Daily'!Y8-'Hampshire Daily'!Y7)) -> 0.01 | V5: =IF(('Hampshire Daily'!Z8-'Hampshire Daily'!Z7<0),"0",('Hampshire Daily'!Z8-'Hampshire Daily'!Z7)) -> 0 | W5: =IF(('Hampshire Daily'!AA8-'Hampshire Daily'!AA7<0),"0",('Hampshire Daily'!AA8-'Hampshire Daily'!AA7)) -> 4 | X5: =IF(('Hampshire Daily'!AA8-'Hampshire Daily'!AA7<0),"0",('Hampshire Daily'!AA8-'Hampshire Daily'!AA7)) -> 4 | Y5: ='Hampshire Daily'!B8 -> 146 | Z5: ='Hampshire Daily'!C8 -> 63
A6: Hampshire | B6: =B5+1 -> 5 | C6: 10 | D6: 2021 | E6: =IF(('Hampshire Daily'!E9-'Hampshire Daily'!E8<0),"0",('Hampshire Daily'!E9-'Hampshire Daily'!E8)) -> 2942 | F6: =IF(('Hampshire Daily'!G9-'Hampshire Daily'!G8<0),"0",('Hampshire Daily'!G9-'Hampshire Daily'!G8)) -> 5506 | G6: =IF(('Hampshire Daily'!H9-'Hampshire Daily'!H8<0),"0",('Hampshire Daily'!H9-'Hampshire Daily'!H8)) -> 770 | H6: =IF(('Hampshire Daily'!I9-'Hampshire Daily'!I8<0),"0",('Hampshire Daily'!I9-'Hampshire Daily'!I8)) -> 2367.0968 | I6: =IF(('Hampshire Daily'!J9-'Hampshire Daily'!J8<0),"0",('Hampshire Daily'!J9-'Hampshire Daily'!J8)) -> 0.12903226 | J6: =IF(('Hampshire Daily'!L9-'Hampshire Daily'!L8<0),"0",('Hampshire Daily'!L9-'Hampshire Daily'!L8)) -> 0 | K6: =IF(('Hampshire Daily'!M9-'Hampshire Daily'!M8<0),"0",('Hampshire Daily'!M9-'Hampshire Daily'!M8)) -> 7 | L6: =IF(('Hampshire Daily'!N9-'Hampshire Daily'!N8<0),"0",('Hampshire Daily'!N9-'Hampshire Daily'!N8)) -> 2799 | M6: =IF(('Hampshire Daily'!O9-'Hampshire Daily'!O8<0),"0",('Hampshire Daily'!O9-'Hampshire Daily'!O8)) -> 97 | N6: =IF(('Hampshire Daily'!P9-'Hampshire Daily'!P8<0),"0",('Hampshire Daily'!P9-'Hampshire Daily'!P8)) -> 0 | O6: =IF(('Hampshire Daily'!Q9-'Hampshire Daily'!Q8<0),"0",('Hampshire Daily'!Q9-'Hampshire Daily'!Q8)) -> 0 | P6: =IF(('Hampshire Daily'!R9-'Hampshire Daily'!R8<0),"0",('Hampshire Daily'!R9-'Hampshire Daily'!R8)) -> 55 | Q6: =IF(('Hampshire Daily'!S9-'Hampshire Daily'!S8<0),"0",('Hampshire Daily'!S9-'Hampshire Daily'!S8)) -> 66 | R6: =IF(('Hampshire Daily'!V9-'Hampshire Daily'!V8<0),"0",('Hampshire Daily'!V9-'Hampshire Daily'!V8)) -> 1 | S6: =IF(('Hampshire Daily'!W9-'Hampshire Daily'!W8<0),"0",('Hampshire Daily'!W9-'Hampshire Daily'!W8)) -> 0 | T6: =IF(('Hampshire Daily'!X9-'Hampshire Daily'!X8<0),"0",('Hampshire Daily'!X9-'Hampshire Daily'!X8)) -> 0.164 | U6: =IF(('Hampshire Daily'!Y9-'Hampshire Daily'!Y8<0),"0",('Hampshire Daily'!Y9-'Hampshire Daily'!Y8)) -> 0.009 | V6: =IF(('Hampshire Daily'!Z9-'Hampshire Daily'!Z8<0),"0",('Hampshire Daily'!Z9-'Hampshire Daily'!Z8)) -> 0 | W6: =IF(('Hampshire Daily'!AA9-'Hampshire Daily'!AA8<0),"0",('Hampshire Daily'!AA9-'Hampshire Daily'!AA8)) -> 6 | X6: =IF(('Hampshire Daily'!AA9-'Hampshire Daily'!AA8<0),"0",('Hampshire Daily'!AA9-'Hampshire Daily'!AA8)) -> 6 | Y6: ='Hampshire Daily'!B9 -> 74 | Z6: ='Hampshire Daily'!C9 -> 29
A7: Hampshire | B7: =B6+1 -> 6 | C7: 10 | D7: 2021 | E7: =IF(('Hampshire Daily'!E10-'Hampshire Daily'!E9<0),"0",('Hampshire Daily'!E10-'Hampshire Daily'!E9)) -> 2898 | F7: =IF(('Hampshire Daily'!G10-'Hampshire Daily'!G9<0),"0",('Hampshire Daily'!G10-'Hampshire Daily'!G9)) -> 5011 | G7: =IF(('Hampshire Daily'!H10-'Hampshire Daily'!H9<0),"0",('Hampshire Daily'!H10-'Hampshire Daily'!H9)) -> 810 | H7: =IF(('Hampshire Daily'!I10-'Hampshire Daily'!I9<0),"0",('Hampshire Daily'!I10-'Hampshire Daily'!I9)) -> 2367.0968 | I7: =IF(('Hampshire Daily'!J10-'Hampshire Daily'!J9<0),"0",('Hampshire Daily'!J10-'Hampshire Daily'!J9)) -> 0.12903226 | J7: =IF(('Hampshire Daily'!L10-'Hampshire Daily'!L9<0),"0",('Hampshire Daily'!L10-'Hampshire Daily'!L9)) -> 694229.28 | K7: =IF(('Hampshire Daily'!M10-'Hampshire Daily'!M9<0),"0",('Hampshire Daily'!M10-'Hampshire Daily'!M9)) -> 9 | L7: =IF(('Hampshire Daily'!N10-'Hampshire Daily'!N9<0),"0",('Hampshire Daily'!N10-'Hampshire Daily'!N9)) -> 2678 | M7: =IF(('Hampshire Daily'!O10-'Hampshire Daily'!O9<0),"0",('Hampshire Daily'!O10-'Hampshire Daily'!O9)) -> 103 | N7: =IF(('Hampshire Daily'!P10-'Hampshire Daily'!P9<0),"0",('Hampshire Daily'!P10-'Hampshire Daily'!P9)) -> 0 | O7: =IF(('Hampshire Daily'!Q10-'Hampshire Daily'!Q9<0),"0",('Hampshire Daily'!Q10-'Hampshire Daily'!Q9)) -> 0 | P7: =IF(('Hampshire Daily'!R10-'Hampshire Daily'!R9<0),"0",('Hampshire Daily'!R10-'Hampshire Daily'!R9)) -> 620333 | Q7: =IF(('Hampshire Daily'!S10-'Hampshire Daily'!S9<0),"0",('Hampshire Daily'!S10-'Hampshire Daily'!S9)) -> 106 | R7: =IF(('Hampshire Daily'!V10-'Hampshire Daily'!V9<0),"0",('Hampshire Daily'!V10-'Hampshire Daily'!V9)) -> 6 | S7: =IF(('Hampshire Daily'!W10-'Hampshire Daily'!W9<0),"0",('Hampshire Daily'!W10-'Hampshire Daily'!W9)) -> 0 | T7: =IF(('Hampshire Daily'!X10-'Hampshire Daily'!X9<0),"0",('Hampshire Daily'!X10-'Hampshire Daily'!X9)) -> 0.025 | U7: =IF(('Hampshire Daily'!Y10-'Hampshire Daily'!Y9<0),"0",('Hampshire Daily'!Y10-'Hampshire Daily'!Y9)) -> 0.011 | V7: =IF(('Hampshire Daily'!Z10-'Hampshire Daily'!Z9<0),"0",('Hampshire Daily'!Z10-'Hampshire Daily'!Z9)) -> 0 | W7: =IF(('Hampshire Daily'!AA10-'Hampshire Daily'!AA9<0),"0",('Hampshire Daily'!AA10-'Hampshire Daily'!AA9)) -> 6 | X7: =IF(('Hampshire Daily'!AA10-'Hampshire Daily'!AA9<0),"0",('Hampshire Daily'!AA10-'Hampshire Daily'!AA9)) -> 6 | Y7: ='Hampshire Daily'!B10 -> 73 | Z7: ='Hampshire Daily'!C10 -> 35
A8: Hampshire | B8: =B7+1 -> 7 | C8: 10 | D8: 2021 | E8: =IF(('Hampshire Daily'!E11-'Hampshire Daily'!E10<0),"0",('Hampshire Daily'!E11-'Hampshire Daily'!E10)) -> 2946 | F8: =IF(('Hampshire Daily'!G11-'Hampshire Daily'!G10<0),"0",('Hampshire Daily'!G11-'Hampshire Daily'!G10)) -> 4869 | G8: =IF(('Hampshire Daily'!H11-'Hampshire Daily'!H10<0),"0",('Hampshire Daily'!H11-'Hampshire Daily'!H10)) -> 794 | H8: =IF(('Hampshire Daily'!I11-'Hampshire Daily'!I10<0),"0",('Hampshire Daily'!I11-'Hampshire Daily'!I10)) -> 2367.0968 | I8: =IF(('Hampshire Daily'!J11-'Hampshire Daily'!J10<0),"0",('Hampshire Daily'!J11-'Hampshire Daily'!J10)) -> 0.12903226 | J8: =IF(('Hampshire Daily'!L11-'Hampshire Daily'!L10<0),"0",('Hampshire Daily'!L11-'Hampshire Daily'!L10)) -> 939 | K8: =IF(('Hampshire Daily'!M11-'Hampshire Daily'!M10<0),"0",('Hampshire Daily'!M11-'Hampshire Daily'!M10)) -> 8 | L8: =IF(('Hampshire Daily'!N11-'Hampshire Daily'!N10<0),"0",('Hampshire Daily'!N11-'Hampshire Daily'!N10)) -> 2691 | M8: =IF(('Hampshire Daily'!O11-'Hampshire Daily'!O10<0),"0",('Hampshire Daily'!O11-'Hampshire Daily'!O10)) -> 88 | N8: =IF(('Hampshire Daily'!P11-'Hampshire Daily'!P10<0),"0",('Hampshire Daily'!P11-'Hampshire Daily'!P10)) -> 0 | O8: =IF(('Hampshire Daily'!Q11-'Hampshire Daily'!Q10<0),"0",('Hampshire Daily'!Q11-'Hampshire Daily'!Q10)) -> 0 | P8: =IF(('Hampshire Daily'!R11-'Hampshire Daily'!R10<0),"0",('Hampshire Daily'!R11-'Hampshire Daily'!R10)) -> 489 | Q8: =IF(('Hampshire Daily'!S11-'Hampshire Daily'!S10<0),"0",('Hampshire Daily'!S11-'Hampshire Daily'!S10)) -> 2 | R8: =IF(('Hampshire Daily'!V11-'Hampshire Daily'!V10<0),"0",('Hampshire Daily'!V11-'Hampshire Daily'!V10)) -> 1 | S8: =IF(('Hampshire Daily'!W11-'Hampshire Daily'!W10<0),"0",('Hampshire Daily'!W11-'Hampshire Daily'!W10)) -> 0 | T8: =IF(('Hampshire Daily'!X11-'Hampshire Daily'!X10<0),"0",('Hampshire Daily'!X11-'Hampshire Daily'!X10)) -> 0.256 | U8: =IF(('Hampshire Daily'!Y11-'Hampshire Daily'!Y10<0),"0",('Hampshire Daily'!Y11-'Hampshire Daily'!Y10)) -> 0.01 | V8: =IF(('Hampshire Daily'!Z11-'Hampshire Daily'!Z10<0),"0",('Hampshire Daily'!Z11-'Hampshire Daily'!Z10)) -> 0 | W8: =IF(('Hampshire Daily'!AA11-'Hampshire Daily'!AA10<0),"0",('Hampshire Daily'!AA11-'Hampshire Daily'!AA10)) -> 4 | X8: =IF(('Hampshire Daily'!AA11-'Hampshire Daily'!AA10<0),"0",('Hampshire Daily'!AA11-'Hampshire Daily'!AA10)) -> 4 | Y8: ='Hampshire Daily'!B11 -> 65 | Z8: ='Hampshire Daily'!C11 -> 31
A9: Hampshire | B9: =B8+1 -> 8 | C9: 10 | D9: 2021 | E9: =IF(('Hampshire Daily'!E12-'Hampshire Daily'!E11<0),"0",('Hampshire Daily'!E12-'Hampshire Daily'!E11)) -> 5603 | F9: =IF(('Hampshire Daily'!G12-'Hampshire Daily'!G11<0),"0",('Hampshire Daily'!G12-'Hampshire Daily'!G11)) -> 5020 | G9: =IF(('Hampshire Daily'!H12-'Hampshire Daily'!H11<0),"0",('Hampshire Daily'!H12-'Hampshire Daily'!H11)) -> 897 | H9: =IF(('Hampshire Daily'!I12-'Hampshire Daily'!I11<0),"0",('Hampshire Daily'!I12-'Hampshire Daily'!I11)) -> 2367.0968 | I9: =IF(('Hampshire Daily'!J12-'Hampshire Daily'!J11<0),"0",('Hampshire Daily'!J12-'Hampshire Daily'!J11)) -> 0.12903226 | J9: =IF(('Hampshire Daily'!L12-'Hampshire Daily'!L11<0),"0",('Hampshire Daily'!L12-'Hampshire Daily'!L11)) -> 0.12903226 | K9: =IF(('Hampshire Daily'!M12-'Hampshire Daily'!M11<0),"0",('Hampshire Daily'!M12-'Hampshire Daily'!M11)) -> 829 | L9: =IF(('Hampshire Daily'!N12-'Hampshire Daily'!N11<0),"0",('Hampshire Daily'!N12-'Hampshire Daily'!N11)) -> 0 | M9: =IF(('Hampshire Daily'!O12-'Hampshire Daily'!O11<0),"0",('Hampshire Daily'!O12-'Hampshire Daily'!O11)) -> 80 | N9: =IF(('Hampshire Daily'!P12-'Hampshire Daily'!P11<0),"0",('Hampshire Daily'!P12-'Hampshire Daily'!P11)) -> 0 | O9: =IF(('Hampshire Daily'!Q12-'Hampshire Daily'!Q11<0),"0",('Hampshire Daily'!Q12-'Hampshire Daily'!Q11)) -> 0 | P9: =IF(('Hampshire Daily'!R12-'Hampshire Daily'!R11<0),"0",('Hampshire Daily'!R12-'Hampshire Daily'!R11)) -> 461 | Q9: =IF(('Hampshire Daily'!S12-'Hampshire Daily'!S11<0),"0",('Hampshire Daily'!S12-'Hampshire Daily'!S11)) -> 53 | R9: =IF(('Hampshire Daily'!V12-'Hampshire Daily'!V11<0),"0",('Hampshire Daily'!V12-'Hampshire Daily'!V11)) -> 0 | S9: =IF(('Hampshire Daily'!W12-'Hampshire Daily'!W11<0),"0",('Hampshire Daily'!W12-'Hampshire Daily'!W11)) -> 0 | T9: =IF(('Hampshire Daily'!X12-'Hampshire Daily'!X11<0),"0",('Hampshire Daily'!X12-'Hampshire Daily'!X11)) -> 0.196 | U9: =IF(('Hampshire Daily'!Y12-'Hampshire Daily'!Y11<0),"0",('Hampshire Daily'!Y12-'Hampshire Daily'!Y11)) -> 0.014 | V9: =IF(('Hampshire Daily'!Z12-'Hampshire Daily'!Z11<0),"0",('Hampshire Daily'!Z12-'Hampshire Daily'!Z11)) -> 0 | W9: =IF(('Hampshire Daily'!AA12-'Hampshire Daily'!AA11<0),"0",('Hampshire Daily'!AA12-'Hampshire Daily'!AA11)) -> 4 | X9: =IF(('Hampshire Daily'!AA12-'Hampshire Daily'!AA11<0),"0",('Hampshire Daily'!AA12-'Hampshire Daily'!AA11)) -> 4 | Y9: ='Hampshire Daily'!B12 -> 58 | Z9: ='Hampshire Daily'!C12 -> 24
A10: Hampshire | B10: =B9+1 -> 9 | C10: 10 | D10: 2021 | E10: =IF(('Hampshire Daily'!E13-'Hampshire Daily'!E12<0),"0",('Hampshire Daily'!E13-'Hampshire Daily'!E12)) -> 3320 | F10: =IF(('Hampshire Daily'!G13-'Hampshire Daily'!G12<0),"0",('Hampshire Daily'!G13-'Hampshire Daily'!G12)) -> 4972 | G10: =IF(('Hampshire Daily'!H13-'Hampshire Daily'!H12<0),"0",('Hampshire Daily'!H13-'Hampshire Daily'!H12)) -> 796 | H10: =IF(('Hampshire Daily'!I13-'Hampshire Daily'!I12<0),"0",('Hampshire Daily'!I13-'Hampshire Daily'!I12)) -> 2367.0968 | I10: =IF(('Hampshire Daily'!J13-'Hampshire Daily'!J12<0),"0",('Hampshire Daily'!J13-'Hampshire Daily'!J12)) -> 0.12903226 | J10: =IF(('Hampshire Daily'!L13-'Hampshire Daily'!L12<0),"0",('Hampshire Daily'!L13-'Hampshire Daily'!L12)) -> 0.12903226 | K10: =IF(('Hampshire Daily'!M13-'Hampshire Daily'!M12<0),"0",('Hampshire Daily'!M13-'Hampshire Daily'!M12)) -> 97 | L10: =IF(('Hampshire Daily'!N13-'Hampshire Daily'!N12<0),"0",('Hampshire Daily'!N13-'Hampshire Daily'!N12)) -> 6342 | M10: =IF(('Hampshire Daily'!O13-'Hampshire Daily'!O12<0),"0",('Hampshire Daily'!O13-'Hampshire Daily'!O12)) -> 113 | N10: =IF(('Hampshire Daily'!P13-'Hampshire Daily'!P12<0),"0",('Hampshire Daily'!P13-'Hampshire Daily'!P12)) -> 0 | O10: =IF(('Hampshire Daily'!Q13-'Hampshire Daily'!Q12<0),"0",('Hampshire Daily'!Q13-'Hampshire Daily'!Q12)) -> 0 | P10: =IF(('Hampshire Daily'!R13-'Hampshire Daily'!R12<0),"0",('Hampshire Daily'!R13-'Hampshire Daily'!R12)) -> 503 | Q10: =IF(('Hampshire Daily'!S13-'Hampshire Daily'!S12<0),"0",('Hampshire Daily'!S13-'Hampshire Daily'!S12)) -> 49 | R10: =IF(('Hampshire Daily'!V13-'Hampshire Daily'!V12<0),"0",('Hampshire Daily'!V13-'Hampshire Daily'!V12)) -> 2 | S10: =IF(('Hampshire Daily'!W13-'Hampshire Daily'!W12<0),"0",('Hampshire Daily'!W13-'Hampshire Daily'!W12)) -> 0 | T10: =IF(('Hampshire Daily'!X13-'Hampshire Daily'!X12<0),"0",('Hampshire Daily'!X13-'Hampshire Daily'!X12)) -> 0.289 | U10: =IF(('Hampshire Daily'!Y13-'Hampshire Daily'!Y12<0),"0",('Hampshire Daily'!Y13-'Hampshire Daily'!Y12)) -> 0.013 | V10: =IF(('Hampshire Daily'!Z13-'Hampshire Daily'!Z12<0),"0",('Hampshire Daily'!Z13-'Hampshire Daily'!Z12)) -> 0 | W10: =IF(('Hampshire Daily'!AA13-'Hampshire Daily'!AA12<0),"0",('Hampshire Daily'!AA13-'Hampshire Daily'!AA12)) -> 4 | X10: =IF(('Hampshire Daily'!AA13-'Hampshire Daily'!AA12<0),"0",('Hampshire Daily'!AA13-'Hampshire Daily'!AA12)) -> 4 | Y10: ='Hampshire Daily'!B13 -> 80 | Z10: ='Hampshire Daily'!C13 -> 45
A11: Hampshire | B11: =B10+1 -> 10 | C11: 10 | D11: 2021 | E11: =IF(('Hampshire Daily'!E14-'Hampshire Daily'!E13<0),"0",('Hampshire Daily'!E14-'Hampshire Daily'!E13)) -> 4653 | F11: =IF(('Hampshire Daily'!G14-'Hampshire Daily'!G13<0),"0",('Hampshire Daily'!G14-'Hampshire Daily'!G13)) -> 5202 | G11: =IF(('Hampshire Daily'!H14-'Hampshire Daily'!H13<0),"0",('Hampshire Daily'!H14-'Hampshire Daily'!H13)) -> 838 | H11: =IF(('Hampshire Daily'!I14-'Hampshire Daily'!I13<0),"0",('Hampshire Daily'!I14-'Hampshire Daily'!I13)) -> 2367.0968 | I11: =IF(('Hampshire Daily'!J14-'Hampshire Daily'!J13<0),"0",('Hampshire Daily'!J14-'Hampshire Daily'!J13)) -> 0.12903226 | J11: =IF(('Hampshire Daily'!L14-'Hampshire Daily'!L13<0),"0",('Hampshire Daily'!L14-'Hampshire Daily'!L13)) -> 0.12903226 | K11: =IF(('Hampshire Daily'!M14-'Hampshire Daily'!M13<0),"0",('Hampshire Daily'!M14-'Hampshire Daily'!M13)) -> 391 | L11: =IF(('Hampshire Daily'!N14-'Hampshire Daily'!N13<0),"0",('Hampshire Daily'!N14-'Hampshire Daily'!N13)) -> 2432 | M11: =IF(('Hampshire Daily'!O14-'Hampshire Daily'!O13<0),"0",('Hampshire Daily'!O14-'Hampshire Daily'!O13)) -> 85 | N11: =IF(('Hampshire Daily'!P14-'Hampshire Daily'!P13<0),"0",('Hampshire Daily'!P14-'Hampshire Daily'!P13)) -> 0 | O11: =IF(('Hampshire Daily'!Q14-'Hampshire Daily'!Q13<0),"0",('Hampshire Daily'!Q14-'Hampshire Daily'!Q13)) -> 0 | P11: =IF(('Hampshire Daily'!R14-'Hampshire Daily'!R13<0),"0",('Hampshire Daily'!R14-'Hampshire Daily'!R13)) -> 527 | Q11: =IF(('Hampshire Daily'!S14-'Hampshire Daily'!S13<0),"0",('Hampshire Daily'!S14-'Hampshire Daily'!S13)) -> 65 | R11: =IF(('Hampshire Daily'!V14-'Hampshire Daily'!V13<0),"0",('Hampshire Daily'!V14-'Hampshire Daily'!V13)) -> 1 | S11: =IF(('Hampshire Daily'!W14-'Hampshire Daily'!W13<0),"0",('Hampshire Daily'!W14-'Hampshire Daily'!W13)) -> 0.001 | T11: =IF(('Hampshire Daily'!X14-'Hampshire Daily'!X13<0),"0",('Hampshire Daily'!X14-'Hampshire Daily'!X13)) -> 0.055 | U11: =IF(('Hampshire Daily'!Y14-'Hampshire Daily'!Y13<0),"0",('Hampshire Daily'!Y14-'Hampshire Daily'!Y13)) -> 0.014 | V11: =IF(('Hampshire Daily'!Z14-'Hampshire Daily'!Z13<0),"0",('Hampshire Daily'!Z14-'Hampshire Daily'!Z13)) -> 0 | W11: =IF(('Hampshire Daily'!AA14-'Hampshire Daily'!AA13<0),"0",('Hampshire Daily'!AA14-'Hampshire Daily'!AA13)) -> 4 | X11: =IF(('Hampshire Daily'!AA14-'Hampshire Daily'!AA13<0),"0",('Hampshire Daily'!AA14-'Hampshire Daily'!AA13)) -> 4 | Y11: ='Hampshire Daily'!B14 -> 136 | Z11: ='Hampshire Daily'!C14 -> 54
A12: Hampshire | B12: =B11+1 -> 11 | C12: 10 | D12: 2021 | E12: =IF(('Hampshire Daily'!E15-'Hampshire Daily'!E14<0),"0",('Hampshire Daily'!E15-'Hampshire Daily'!E14)) -> 3891 | F12: =IF(('Hampshire Daily'!G15-'Hampshire Daily'!G14<0),"0",('Hampshire Daily'!G15-'Hampshire Daily'!G14)) -> 2862 | G12: =IF(('Hampshire Daily'!H15-'Hampshire Daily'!H14<0),"0",('Hampshire Daily'!H15-'Hampshire Daily'!H14)) -> 203 | H12: =IF(('Hampshire Daily'!I15-'Hampshire Daily'!I14<0),"0",('Hampshire Daily'!I15-'Hampshire Daily'!I14)) -> 2367.0968 | I12: =IF(('Hampshire Daily'!J15-'Hampshire Daily'!J14<0),"0",('Hampshire Daily'!J15-'Hampshire Daily'!J14)) -> 0.12903226 | J12: =IF(('Hampshire Daily'!L15-'Hampshire Daily'!L14<0),"0",('Hampshire Daily'!L15-'Hampshire Daily'!L14)) -> 0.12903226 | K12: =IF(('Hampshire Daily'!M15-'Hampshire Daily'!M14<0),"0",('Hampshire Daily'!M15-'Hampshire Daily'!M14)) -> 256 | L12: =IF(('Hampshire Daily'!N15-'Hampshire Daily'!N14<0),"0",('Hampshire Daily'!N15-'Hampshire Daily'!N14)) -> 0 | M12: =IF(('Hampshire Daily'!O15-'Hampshire Daily'!O14<0),"0",('Hampshire Daily'!O15-'Hampshire Daily'!O14)) -> 125 | N12: =IF(('Hampshire Daily'!P15-'Hampshire Daily'!P14<0),"0",('Hampshire Daily'!P15-'Hampshire Daily'!P14)) -> 0 | O12: =IF(('Hampshire Daily'!Q15-'Hampshire Daily'!Q14<0),"0",('Hampshire Daily'!Q15-'Hampshire Daily'!Q14)) -> 0 | P12: =IF(('Hampshire Daily'!R15-'Hampshire Daily'!R14<0),"0",('Hampshire Daily'!R15-'Hampshire Daily'!R14)) -> 495 | Q12: =IF(('Hampshire Daily'!S15-'Hampshire Daily'!S14<0),"0",('Hampshire Daily'!S15-'Hampshire Daily'!S14)) -> 66 | R12: =IF(('Hampshire Daily'!V15-'Hampshire Daily'!V14<0),"0",('Hampshire Daily'!V15-'Hampshire Daily'!V14)) -> 1 | S12: =IF(('Hampshire Daily'!W15-'Hampshire Daily'!W14<0),"0",('Hampshire Daily'!W15-'Hampshire Daily'!W14)) -> 0 | T12: =IF(('Hampshire Daily'!X15-'Hampshire Daily'!X14<0),"0",('Hampshire Daily'!X15-'Hampshire Daily'!X14)) -> 0.365 | U12: =IF(('Hampshire Daily'!Y15-'Hampshire Daily'!Y14<0),"0",('Hampshire Daily'!Y15-'Hampshire Daily'!Y14)) -> 0.011 | V12: =IF(('Hampshire Daily'!Z15-'Hampshire Daily'!Z14<0),"0",('Hampshire Daily'!Z15-'Hampshire Daily'!Z14)) -> 0 | W12: =IF(('Hampshire Daily'!AA15-'Hampshire Daily'!AA14<0),"0",('Hampshire Daily'!AA15-'Hampshire Daily'!AA14)) -> 7 | X12: =IF(('Hampshire Daily'!AA15-'Hampshire Daily'!AA14<0),"0",('Hampshire Daily'!AA15-'Hampshire Daily'!AA14)) -> 7 | Y12: ='Hampshire Daily'!B15 -> 149 | Z12: ='Hampshire Daily'!C15 -> 58
A13: Hampshire | B13: =B12+1 -> 12 | C13: 10 | D13: 2021 | E13: =IF(('Hampshire Daily'!E16-'Hampshire Daily'!E15<0),"0",('Hampshire Daily'!E16-'Hampshire Daily'!E15)) -> 2733 | F13: =IF(('Hampshire Daily'!G16-'Hampshire Daily'!G15<0),"0",('Hampshire Daily'!G16-'Hampshire Daily'!G15)) -> 1909 | G13: =IF(('Hampshire Daily'!H16-'Hampshire Daily'!H15<0),"0",('Hampshire Daily'!H16-'Hampshire Daily'!H15)) -> 0 | H13: =IF(('Hampshire Daily'!I16-'Hampshire Daily'!I15<0),"0",('Hampshire Daily'!I16-'Hampshire Daily'!I15)) -> 2367.0968 | I13: =IF(('Hampshire Daily'!J16-'Hampshire Daily'!J15<0),"0",('Hampshire Daily'!J16-'Hampshire Daily'!J15)) -> 0.12903226 | J13: =IF(('Hampshire Daily'!L16-'Hampshire Daily'!L15<0),"0",('Hampshire Daily'!L16-'Hampshire Daily'!L15)) -> 5488.4839 | K13: =IF(('Hampshire Daily'!M16-'Hampshire Daily'!M15<0),"0",('Hampshire Daily'!M16-'Hampshire Daily'!M15)) -> 4 | L13: =IF(('Hampshire Daily'!N16-'Hampshire Daily'!N15<0),"0",('Hampshire Daily'!N16-'Hampshire Daily'!N15)) -> 360816 | M13: =IF(('Hampshire Daily'!O16-'Hampshire Daily'!O15<0),"0",('Hampshire Daily'!O16-'Hampshire Daily'!O15)) -> 98 | N13: =IF(('Hampshire Daily'!P16-'Hampshire Daily'!P15<0),"0",('Hampshire Daily'!P16-'Hampshire Daily'!P15)) -> 0 | O13: =IF(('Hampshire Daily'!Q16-'Hampshire Daily'!Q15<0),"0",('Hampshire Daily'!Q16-'Hampshire Daily'!Q15)) -> 0 | P13: =IF(('Hampshire Daily'!R16-'Hampshire Daily'!R15<0),"0",('Hampshire Daily'!R16-'Hampshire Daily'!R15)) -> 555 | Q13: =IF(('Hampshire Daily'!S16-'Hampshire Daily'!S15<0),"0",('Hampshire Daily'!S16-'Hampshire Daily'!S15)) -> 68 | R13: =IF(('Hampshire Daily'!V16-'Hampshire Daily'!V15<0),"0",('Hampshire Daily'!V16-'Hampshire Daily'!V15)) -> 1 | S13: =IF(('Hampshire Daily'!W16-'Hampshire Daily'!W15<0),"0",('Hampshire Daily'!W16-'Hampshire Daily'!W15)) -> 0 | T13: =IF(('Hampshire Daily'!X16-'Hampshire Daily'!X15<0),"0",('Hampshire Daily'!X16-'Hampshire Daily'!X15)) -> 0.091 | U13: =IF(('Hampshire Daily'!Y16-'Hampshire Daily'!Y15<0),"0",('Hampshire Daily'!Y16-'Hampshire Daily'!Y15)) -> 0.01 | V13: =IF(('Hampshire Daily'!Z16-'Hampshire Daily'!Z15<0),"0",('Hampshire Daily'!Z16-'Hampshire Daily'!Z15)) -> 0 | W13: =IF(('Hampshire Daily'!AA16-'Hampshire Daily'!AA15<0),"0",('Hampshire Daily'!AA16-'Hampshire Daily'!AA15)) -> 6.5 | X13: =IF(('Hampshire Daily'!AA16-'Hampshire Daily'!AA15<0),"0",('Hampshire Daily'!AA16-'Hampshire Daily'!AA15)) -> 6.5 | Y13: ='Hampshire Daily'!B16 -> 128 | Z13: ='Hampshire Daily'!C16 -> 50
A14: Hampshire | B14: =B13+1 -> 13 | C14: 10 | D14: 2021 | E14: =IF(('Hampshire Daily'!E17-'Hampshire Daily'!E16<0),"0",('Hampshire Daily'!E17-'Hampshire Daily'!E16)) -> 2781 | F14: =IF(('Hampshire Daily'!G17-'Hampshire Daily'!G16<0),"0",('Hampshire Daily'!G17-'Hampshire Daily'!G16)) -> 2258 | G14: =IF(('Hampshire Daily'!H17-'Hampshire Daily'!H16<0),"0",('Hampshire Daily'!H17-'Hampshire Daily'!H16)) -> 90 | H14: =IF(('Hampshire Daily'!I17-'Hampshire Daily'!I16<0),"0",('Hampshire Daily'!I17-'Hampshire Daily'!I16)) -> 2367.0968 | I14: =IF(('Hampshire Daily'!J17-'Hampshire Daily'!J16<0),"0",('Hampshire Daily'!J17-'Hampshire Daily'!J16)) -> 0.12903226 | J14: =IF(('Hampshire Daily'!L17-'Hampshire Daily'!L16<0),"0",('Hampshire Daily'!L17-'Hampshire Daily'!L16)) -> 966 | K14: =IF(('Hampshire Daily'!M17-'Hampshire Daily'!M16<0),"0",('Hampshire Daily'!M17-'Hampshire Daily'!M16)) -> 1 | L14: =IF(('Hampshire Daily'!N17-'Hampshire Daily'!N16<0),"0",('Hampshire Daily'!N17-'Hampshire Daily'!N16)) -> 2512 | M14: =IF(('Hampshire Daily'!O17-'Hampshire Daily'!O16<0),"0",('Hampshire Daily'!O17-'Hampshire Daily'!O16)) -> 99 | N14: =IF(('Hampshire Daily'!P17-'Hampshire Daily'!P16<0),"0",('Hampshire Daily'!P17-'Hampshire Daily'!P16)) -> 0 | O14: =IF(('Hampshire Daily'!Q17-'Hampshire Daily'!Q16<0),"0",('Hampshire Daily'!Q17-'Hampshire Daily'!Q16)) -> 0 | P14: =IF(('Hampshire Daily'!R17-'Hampshire Daily'!R16<0),"0",('Hampshire Daily'!R17-'Hampshire Daily'!R16)) -> 674 | Q14: =IF(('Hampshire Daily'!S17-'Hampshire Daily'!S16<0),"0",('Hampshire Daily'!S17-'Hampshire Daily'!S16)) -> 73 | R14: =IF(('Hampshire Daily'!V17-'Hampshire Daily'!V16<0),"0",('Hampshire Daily'!V17-'Hampshire Daily'!V16)) -> 7 | S14: =IF(('Hampshire Daily'!W17-'Hampshire Daily'!W16<0),"0",('Hampshire Daily'!W17-'Hampshire Daily'!W16)) -> 0 | T14: =IF(('Hampshire Daily'!X17-'Hampshire Daily'!X16<0),"0",('Hampshire Daily'!X17-'Hampshire Daily'!X16)) -> 0.11 | U14: =IF(('Hampshire Daily'!Y17-'Hampshire Daily'!Y16<0),"0",('Hampshire Daily'!Y17-'Hampshire Daily'!Y16)) -> 0.011 | V14: =IF(('Hampshire Daily'!Z17-'Hampshire Daily'!Z16<0),"0",('Hampshire Daily'!Z17-'Hampshire Daily'!Z16)) -> 0 | W14: =IF(('Hampshire Daily'!AA17-'Hampshire Daily'!AA16<0),"0",('Hampshire Daily'!AA17-'Hampshire Daily'!AA16)) -> 6.5 | X14: =IF(('Hampshire Daily'!AA17-'Hampshire Daily'!AA16<0),"0",('Hampshire Daily'!AA17-'Hampshire Daily'!AA16)) -> 6.5 | Y14: ='Hampshire Daily'!B17 -> 110 | Z14: ='Hampshire Daily'!C17 -> 39
... A20: Hampshire | B20: =B19+1 -> 19 | C20: 10 | D20: 2021 | E20: =IF(('Hampshire Daily'!E23-'Hampshire Daily'!E22<0),"0",('Hampshire Daily'!E23-'Hampshire Daily'!E22)) -> 2662 | F20: =IF(('Hampshire Daily'!G23-'Hampshire Daily'!G22<0),"0",('Hampshire Daily'!G23-'Hampshire Daily'!G22)) -> 6250 | G20: =IF(('Hampshire Daily'!H23-'Hampshire Daily'!H22<0),"0",('Hampshire Daily'!H23-'Hampshire Daily'!H22)) -> 791 | H20: =IF(('Hampshire Daily'!I23-'Hampshire Daily'!I22<0),"0",('Hampshire Daily'!I23-'Hampshire Daily'!I22)) -> 2367.0968 | I20: =IF(('Hampshire Daily'!J23-'Hampshire Daily'!J22<0),"0",('Hampshire Daily'!J23-'Hampshire Daily'!J22)) -> 0.12903226 | J20: =IF(('Hampshire Daily'!L23-'Hampshire Daily'!L22<0),"0",('Hampshire Daily'!L23-'Hampshire Daily'!L22)) -> 0.12903226 | K20: =IF(('Hampshire Daily'!M23-'Hampshire Daily'!M22<0),"0",('Hampshire Daily'!M23-'Hampshire Daily'!M22)) -> 4 | L20: =IF(('Hampshire Daily'!N23-'Hampshire Daily'!N22<0),"0",('Hampshire Daily'!N23-'Hampshire Daily'!N22)) -> 2430 | M20: =IF(('Hampshire Daily'!O23-'Hampshire Daily'!O22<0),"0",('Hampshire Daily'!O23-'Hampshire Daily'!O22)) -> 128 | N20: =IF(('Hampshire Daily'!P23-'Hampshire Daily'!P22<0),"0",('Hampshire Daily'!P23-'Hampshire Daily'!P22)) -> 435 | O20: =IF(('Hampshire Daily'!Q23-'Hampshire Daily'!Q22<0),"0",('Hampshire Daily'!Q23-'Hampshire Daily'!Q22)) -> 0 | P20: =IF(('Hampshire Daily'!R23-'Hampshire Daily'!R22<0),"0",('Hampshire Daily'!R23-'Hampshire Daily'!R22)) -> 315 | Q20: =IF(('Hampshire Daily'!S23-'Hampshire Daily'!S22<0),"0",('Hampshire Daily'!S23-'Hampshire Daily'!S22)) -> 82 | R20: =IF(('Hampshire Daily'!V23-'Hampshire Daily'!V22<0),"0",('Hampshire Daily'!V23-'Hampshire Daily'!V22)) -> 1 | S20: =IF(('Hampshire Daily'!W23-'Hampshire Daily'!W22<0),"0",('Hampshire Daily'!W23-'Hampshire Daily'!W22)) -> 0 | T20: =IF(('Hampshire Daily'!X23-'Hampshire Daily'!X22<0),"0",('Hampshire Daily'!X23-'Hampshire Daily'!X22)) -> 0.192 | U20: =IF(('Hampshire Daily'!Y23-'Hampshire Daily'!Y22<0),"0",('Hampshire Daily'!Y23-'Hampshire Daily'!Y22)) -> 0.017 | V20: =IF(('Hampshire Daily'!Z23-'Hampshire Daily'!Z22<0),"0",('Hampshire Daily'!Z23-'Hampshire Daily'!Z22)) -> 0 | W20: =IF(('Hampshire Daily'!AA23-'Hampshire Daily'!AA22<0),"0",('Hampshire Daily'!AA23-'Hampshire Daily'!AA22)) -> 6 | X20: =IF(('Hampshire Daily'!AA23-'Hampshire Daily'!AA22<0),"0",('Hampshire Daily'!AA23-'Hampshire Daily'!AA22)) -> 6 | Y20: ='Hampshire Daily'!B23 -> 195 | Z20: ='Hampshire Daily'!C23 -> 66
A21: Hampshire | B21: =B20+1 -> 20 | C21: 10 | D21: 2021 | E21: =IF(('Hampshire Daily'!D24-'Hampshire Daily'!E23<0),"0",('Hampshire Daily'!D24-'Hampshire Daily'!E23)) -> 957 | F21: =IF(('Hampshire Daily'!F24-'Hampshire Daily'!G23<0),"0",('Hampshire Daily'!F24-'Hampshire Daily'!G23)) -> 7012 | G21: =IF(('Hampshire Daily'!H24-'Hampshire Daily'!H23<0),"0",('Hampshire Daily'!H24-'Hampshire Daily'!H23)) -> 818 | H21: =IF(('Hampshire Daily'!I24-'Hampshire Daily'!I23<0),"0",('Hampshire Daily'!I24-'Hampshire Daily'!I23)) -> 2367.0968 | I21: =IF(('Hampshire Daily'!J24-'Hampshire Daily'!J23<0),"0",('Hampshire Daily'!J24-'Hampshire Daily'!J23)) -> 0.12903226 | J21: =IF(('Hampshire Daily'!K24-'Hampshire Daily'!L23<0),"0",('Hampshire Daily'!K24-'Hampshire Daily'!L23)) -> 3910828.7 | K21: =IF(('Hampshire Daily'!L24-'Hampshire Daily'!M23<0),"0",('Hampshire Daily'!L24-'Hampshire Daily'!M23)) -> 0 | L21: =IF(('Hampshire Daily'!M24-'Hampshire Daily'!N23<0),"0",('Hampshire Daily'!M24-'Hampshire Daily'!N23)) -> 1213770 | M21: 128 | N21: =IF(('Hampshire Daily'!O24-'Hampshire Daily'!P23<0),"0",('Hampshire Daily'!O24-'Hampshire Daily'!P23)) -> 0 | O21: =IF(('Hampshire Daily'!P24-'Hampshire Daily'!Q23<0),"0",('Hampshire Daily'!P24-'Hampshire Daily'!Q23)) -> 1528349 | P21: =IF(('Hampshire Daily'!Q24-'Hampshire Daily'!R23<0),"0",('Hampshire Daily'!Q24-'Hampshire Daily'!R23)) -> 0 | Q21: =IF(('Hampshire Daily'!R24-'Hampshire Daily'!S23<0),"0",('Hampshire Daily'!R24-'Hampshire Daily'!S23)) -> 351728 | R21: =IF(('Hampshire Daily'!U24-'Hampshire Daily'!V23<0),"0",('Hampshire Daily'!U24-'Hampshire Daily'!V23)) -> 21739 | S21: =IF(('Hampshire Daily'!V24-'Hampshire Daily'!W23<0),"0",('Hampshire Daily'!V24-'Hampshire Daily'!W23)) -> 30558.669 | T21: =IF(('Hampshire Daily'!W24-'Hampshire Daily'!X23<0),"0",('Hampshire Daily'!W24-'Hampshire Daily'!X23)) -> 0 | U21: =IF(('Hampshire Daily'!X24-'Hampshire Daily'!Y23<0),"0",('Hampshire Daily'!X24-'Hampshire Daily'!Y23)) -> 0 | V21: =IF(('Hampshire Daily'!Y24-'Hampshire Daily'!Z23<0),"0",('Hampshire Daily'!Y24-'Hampshire Daily'!Z23)) -> 0 | W21: =IF(('Hampshire Daily'!Z24-'Hampshire Daily'!AA23<0),"0",('Hampshire Daily'!Z24-'Hampshire Daily'!AA23)) -> 1667 | X21: =IF(('Hampshire Daily'!AA24-'Hampshire Daily'!AA23<0),"0",('Hampshire Daily'!AA24-'Hampshire Daily'!AA23)) -> 6 | Y21: ='Hampshire Daily'!B24 -> 206 | Z21: ='Hampshire Daily'!C24 -> 69
A22: Hampshire | B22: =B21+1 -> 21 | C22: 10 | D22: 2021 | E22: =IF(('Hampshire Daily'!D25-'Hampshire Daily'!D24<0),"0",('Hampshire Daily'!D25-'Hampshire Daily'!D24)) -> 3123 | F22: =IF(('Hampshire Daily'!F25-'Hampshire Daily'!F24<0),"0",('Hampshire Daily'!F25-'Hampshire Daily'!F24)) -> 6345 | G22: =IF(('Hampshire Daily'!H25-'Hampshire Daily'!H24<0),"0",('Hampshire Daily'!H25-'Hampshire Daily'!H24)) -> 841 | H22: =IF(('Hampshire Daily'!I25-'Hampshire Daily'!I24<0),"0",('Hampshire Daily'!I25-'Hampshire Daily'!I24)) -> 2367.0968 | I22: =IF(('Hampshire Daily'!J25-'Hampshire Daily'!J24<0),"0",('Hampshire Daily'!J25-'Hampshire Daily'!J24)) -> 0.12903226 | J22: =IF(('Hampshire Daily'!K25-'Hampshire Daily'!K24<0),"0",('Hampshire Daily'!K25-'Hampshire Daily'!K24)) -> 69539.419 | K22: =IF(('Hampshire Daily'!L25-'Hampshire Daily'!L24<0),"0",('Hampshire Daily'!L25-'Hampshire Daily'!L24)) -> 0.12903226 | L22: =IF(('Hampshire Daily'!M25-'Hampshire Daily'!M24<0),"0",('Hampshire Daily'!M25-'Hampshire Daily'!M24)) -> 7 | M22: =IF(('Hampshire Daily'!N25-'Hampshire Daily'!N24<0),"0",('Hampshire Daily'!N25-'Hampshire Daily'!N24)) -> 2716 | N22: =IF(('Hampshire Daily'!O25-'Hampshire Daily'!O24<0),"0",('Hampshire Daily'!O25-'Hampshire Daily'!O24)) -> 116.5 | ... Q22: =IF(('Hampshire Daily'!R25-'Hampshire Daily'!R24<0),"0",('Hampshire Daily'!R25-'Hampshire Daily'!R24)) -> 402 | R22: =IF(('Hampshire Daily'!U25-'Hampshire Daily'!U24<0),"0",('Hampshire Daily'!U25-'Hampshire Daily'!U24)) -> 14 | S22: =IF(('Hampshire Daily'!V25-'Hampshire Daily'!V24<0),"0",('Hampshire Daily'!V25-'Hampshire Daily'!V24)) -> 0 | T22: =IF(('Hampshire Daily'!W25-'Hampshire Daily'!W24<0),"0",('Hampshire Daily'!W25-'Hampshire Daily'!W24)) -> 0 | U22: =IF(('Hampshire Daily'!X25-'Hampshire Daily'!X24<0),"0",('Hampshire Daily'!X25-'Hampshire Daily'!X24)) -> 0.053 | V22: =IF(('Hampshire Daily'!Y25-'Hampshire Daily'!Y24<0),"0",('Hampshire Daily'!Y25-'Hampshire Daily'!Y24)) -> 0.013 | W22: =IF(('Hampshire Daily'!Z25-'Hampshire Daily'!Z24<0),"0",('Hampshire Daily'!Z25-'Hampshire Daily'!Z24)) -> 0 | X22: =IF(('Hampshire Daily'!AA25-'Hampshire Daily'!AA24<0),"0",('Hampshire Daily'!AA25-'Hampshire Daily'!AA24)) -> 5 | Y22: ='Hampshire Daily'!B25 -> 208 | Z22: ='Hampshire Daily'!C25 -> 70
A23: Hampshire | B23: =B22+1 -> 22 | C23: 10 | D23: 2021 | E23: =IF(('Hampshire Daily'!D26-'Hampshire Daily'!D25<0),"0",('Hampshire Daily'!D26-'Hampshire Daily'!D25)) -> 2937 | F23: =IF(('Hampshire Daily'!F26-'Hampshire Daily'!F25<0),"0",('Hampshire Daily'!F26-'Hampshire Daily'!F25)) -> 5314 | G23: =IF(('Hampshire Daily'!H26-'Hampshire Daily'!H25<0),"0",('Hampshire Daily'!H26-'Hampshire Daily'!H25)) -> 845 | H23: =IF(('Hampshire Daily'!I26-'Hampshire Daily'!I25<0),"0",('Hampshire Daily'!I26-'Hampshire Daily'!I25)) -> 2367.0968 | I23: =IF(('Hampshire Daily'!J26-'Hampshire Daily'!J25<0),"0",('Hampshire Daily'!J26-'Hampshire Daily'!J25)) -> 0.12903226 | J23: =IF(('Hampshire Daily'!K26-'Hampshire Daily'!K25<0),"0",('Hampshire Daily'!K26-'Hampshire Daily'!K25)) -> 69539.419 | K23: =IF(('Hampshire Daily'!L26-'Hampshire Daily'!L25<0),"0",('Hampshire Daily'!L26-'Hampshire Daily'!L25)) -> 9935.0968 | L23: =IF(('Hampshire Daily'!M26-'Hampshire Daily'!M25<0),"0",('Hampshire Daily'!M26-'Hampshire Daily'!M25)) -> 0 | M23: =IF(('Hampshire Daily'!N26-'Hampshire Daily'!N25<0),"0",('Hampshire Daily'!N26-'Hampshire Daily'!N25)) -> 2687 | N23: =IF(('Hampshire Daily'!O26-'Hampshire Daily'!O25<0),"0",('Hampshire Daily'!O26-'Hampshire Daily'!O25)) -> 116.5 | ... Q23: =IF(('Hampshire Daily'!R26-'Hampshire Daily'!R25<0),"0",('Hampshire Daily'!R26-'Hampshire Daily'!R25)) -> 569 | R23: =IF(('Hampshire Daily'!U26-'Hampshire Daily'!U25<0),"0",('Hampshire Daily'!U26-'Hampshire Daily'!U25)) -> 10 | S23: =IF(('Hampshire Daily'!V26-'Hampshire Daily'!V25<0),"0",('Hampshire Daily'!V26-'Hampshire Daily'!V25)) -> 2 | T23: =IF(('Hampshire Daily'!W26-'Hampshire Daily'!W25<0),"0",('Hampshire Daily'!W26-'Hampshire Daily'!W25)) -> 0 | U23: =IF(('Hampshire Daily'!X26-'Hampshire Daily'!X25<0),"0",('Hampshire Daily'!X26-'Hampshire Daily'!X25)) -> 0.427 | V23: =IF(('Hampshire Daily'!Y26-'Hampshire Daily'!Y25<0),"0",('Hampshire Daily'!Y26-'Hampshire Daily'!Y25)) -> 0.01 | W23: =IF(('Hampshire Daily'!Z26-'Hampshire Daily'!Z25<0),"0",('Hampshire Daily'!Z26-'Hampshire Daily'!Z25)) -> 0 | X23: =IF(('Hampshire Daily'!AA26-'Hampshire Daily'!AA25<0),"0",('Hampshire Daily'!AA26-'Hampshire Daily'!AA25)) -> 6 | Y23: ='Hampshire Daily'!B26 -> 185 | Z23: ='Hampshire Daily'!C26 -> 64
A24: Hampshire | B24: =B23+1 -> 23 | C24: 10 | D24: 2021 | E24: =IF(('Hampshire Daily'!D27-'Hampshire Daily'!D26<0),"0",('Hampshire Daily'!D27-'Hampshire Daily'!D26)) -> 3022 | F24: =IF(('Hampshire Daily'!F27-'Hampshire Daily'!F26<0),"0",('Hampshire Daily'!F27-'Hampshire Daily'!F26)) -> 5411 | G24: =IF(('Hampshire Daily'!H27-'Hampshire Daily'!H26<0),"0",('Hampshire Daily'!H27-'Hampshire Daily'!H26)) -> 813 | H24: =IF(('Hampshire Daily'!I27-'Hampshire Daily'!I26<0),"0",('Hampshire Daily'!I27-'Hampshire Daily'!I26)) -> 2367.0968 | I24: =IF(('Hampshire Daily'!J27-'Hampshire Daily'!J26<0),"0",('Hampshire Daily'!J27-'Hampshire Daily'!J26)) -> 0.12903226 | J24: =IF(('Hampshire Daily'!K27-'Hampshire Daily'!K26<0),"0",('Hampshire Daily'!K27-'Hampshire Daily'!K26)) -> 69539.419 | K24: =IF(('Hampshire Daily'!L27-'Hampshire Daily'!L26<0),"0",('Hampshire Daily'!L27-'Hampshire Daily'!L26)) -> 1297 | L24: =IF(('Hampshire Daily'!M27-'Hampshire Daily'!M26<0),"0",('Hampshire Daily'!M27-'Hampshire Daily'!M26)) -> 2009 | M24: =IF(('Hampshire Daily'!N27-'Hampshire Daily'!N26<0),"0",('Hampshire Daily'!N27-'Hampshire Daily'!N26)) -> 2703 | N24: =IF(('Hampshire Daily'!O27-'Hampshire Daily'!O26<0),"0",('Hampshire Daily'!O27-'Hampshire Daily'!O26)) -> 124 | ... Q24: =IF(('Hampshire Daily'!R27-'Hampshire Daily'!R26<0),"0",('Hampshire Daily'!R27-'Hampshire Daily'!R26)) -> 605 | R24: =IF(('Hampshire Daily'!U27-'Hampshire Daily'!U26<0),"0",('Hampshire Daily'!U27-'Hampshire Daily'!U26)) -> 10 | S24: =IF(('Hampshire Daily'!V27-'Hampshire Daily'!V26<0),"0",('Hampshire Daily'!V27-'Hampshire Daily'!V26)) -> 1 | T24: =IF(('Hampshire Daily'!W27-'Hampshire Daily'!W26<0),"0",('Hampshire Daily'!W27-'Hampshire Daily'!W26)) -> #VALUE! | U24: =IF(('Hampshire Daily'!X27-'Hampshire Daily'!X26<0),"0",('Hampshire Daily'!X27-'Hampshire Daily'!X26)) -> 0.24 | V24: =IF(('Hampshire Daily'!Y27-'Hampshire Daily'!Y26<0),"0",('Hampshire Daily'!Y27-'Hampshire Daily'!Y26)) -> 0.033 | W24: =IF(('Hampshire Daily'!Z27-'Hampshire Daily'!Z26<0),"0",('Hampshire Daily'!Z27-'Hampshire Daily'!Z26)) -> 0 | X24: =IF(('Hampshire Daily'!AA27-'Hampshire Daily'!AA26<0),"0",('Hampshire Daily'!AA27-'Hampshire Daily'!AA26)) -> 5 | Y24: ='Hampshire Daily'!B27 -> 194 | Z24: ='Hampshire Daily'!C27 -> 77
A25: Hampshire | B25: =B24+1 -> 24 | C25: 10 | D25: 2021 | E25: =IF(('Hampshire Daily'!D28-'Hampshire Daily'!D27<0),"0",('Hampshire Daily'!D28-'Hampshire Daily'!D27)) -> 3296 | F25: =IF(('Hampshire Daily'!F28-'Hampshire Daily'!F27<0),"0",('Hampshire Daily'!F28-'Hampshire Daily'!F27)) -> 2504 | G25: =IF(('Hampshire Daily'!H28-'Hampshire Daily'!H27<0),"0",('Hampshire Daily'!H28-'Hampshire Daily'!H27)) -> 82 | H25: =IF(('Hampshire Daily'!I28-'Hampshire Daily'!I27<0),"0",('Hampshire Daily'!I28-'Hampshire Daily'!I27)) -> 2367.0968 | I25: =IF(('Hampshire Daily'!J28-'Hampshire Daily'!J27<0),"0",('Hampshire Daily'!J28-'Hampshire Daily'!J27)) -> 0.12903226 | J25: =IF(('Hampshire Daily'!K28-'Hampshire Daily'!K27<0),"0",('Hampshire Daily'!K28-'Hampshire Daily'!K27)) -> 69539.419 | K25: =IF(('Hampshire Daily'!L28-'Hampshire Daily'!L27<0),"0",('Hampshire Daily'!L28-'Hampshire Daily'!L27)) -> 1410 | L25: =IF(('Hampshire Daily'!M28-'Hampshire Daily'!M27<0),"0",('Hampshire Daily'!M28-'Hampshire Daily'!M27)) -> 3 | M25: =IF(('Hampshire Daily'!N28-'Hampshire Daily'!N27<0),"0",('Hampshire Daily'!N28-'Hampshire Daily'!N27)) -> 2909 | N25: =IF(('Hampshire Daily'!O28-'Hampshire Daily'!O27<0),"0",('Hampshire Daily'!O28-'Hampshire Daily'!O27)) -> 123 | ... Q25: =IF(('Hampshire Daily'!R28-'Hampshire Daily'!R27<0),"0",('Hampshire Daily'!R28-'Hampshire Daily'!R27)) -> 696 | R25: =IF(('Hampshire Daily'!U28-'Hampshire Daily'!U27<0),"0",('Hampshire Daily'!U28-'Hampshire Daily'!U27)) -> 11 | S25: =IF(('Hampshire Daily'!V28-'Hampshire Daily'!V27<0),"0",('Hampshire Daily'!V28-'Hampshire Daily'!V27)) -> 1 | T25: =IF(('Hampshire Daily'!W28-'Hampshire Daily'!W27<0),"0",('Hampshire Daily'!W28-'Hampshire Daily'!W27)) -> #VALUE! | U25: =IF(('Hampshire Daily'!X28-'Hampshire Daily'!X27<0),"0",('Hampshire Daily'!X28-'Hampshire Daily'!X27)) -> 0.165 | V25: =IF(('Hampshire Daily'!Y28-'Hampshire Daily'!Y27<0),"0",('Hampshire Daily'!Y28-'Hampshire Daily'!Y27)) -> 0 | W25: =IF(('Hampshire Daily'!Z28-'Hampshire Daily'!Z27<0),"0",('Hampshire Daily'!Z28-'Hampshire Daily'!Z27)) -> 0 | X25: =IF(('Hampshire Daily'!AA28-'Hampshire Daily'!AA27<0),"0",('Hampshire Daily'!AA28-'Hampshire Daily'!AA27)) -> 5 | Y25: ='Hampshire Daily'!B28 -> 233 | Z25: ='Hampshire Daily'!C28 -> 96
A26: Hampshire | B26: =B25+1 -> 25 | C26: 10 | D26: 2021 | E26: =IF(('Hampshire Daily'!D29-'Hampshire Daily'!D28<0),"0",('Hampshire Daily'!D29-'Hampshire Daily'!D28)) -> 3140 | F26: =IF(('Hampshire Daily'!F29-'Hampshire Daily'!F28<0),"0",('Hampshire Daily'!F29-'Hampshire Daily'!F28)) -> 2195 | G26: =IF(('Hampshire Daily'!H29-'Hampshire Daily'!H28<0),"0",('Hampshire Daily'!H29-'Hampshire Daily'!H28)) -> 0 | H26: =IF(('Hampshire Daily'!I29-'Hampshire Daily'!I28<0),"0",('Hampshire Daily'!I29-'Hampshire Daily'!I28)) -> 2367.0968 | I26: =IF(('Hampshire Daily'!J29-'Hampshire Daily'!J28<0),"0",('Hampshire Daily'!J29-'Hampshire Daily'!J28)) -> 0.12903226 | J26: =IF(('Hampshire Daily'!K29-'Hampshire Daily'!K28<0),"0",('Hampshire Daily'!K29-'Hampshire Daily'!K28)) -> 69539.419 | K26: =IF(('Hampshire Daily'!L29-'Hampshire Daily'!L28<0),"0",('Hampshire Daily'!L29-'Hampshire Daily'!L28)) -> 1489 | L26: =IF(('Hampshire Daily'!M29-'Hampshire Daily'!M28<0),"0",('Hampshire Daily'!M29-'Hampshire Daily'!M28)) -> 3 | M26: =IF(('Hampshire Daily'!N29-'Hampshire Daily'!N28<0),"0",('Hampshire Daily'!N29-'Hampshire Daily'!N28)) -> 2812 | N26: =IF(('Hampshire Daily'!O29-'Hampshire Daily'!O28<0),"0",('Hampshire Daily'!O29-'Hampshire Daily'!O28)) -> 156 | ... Q26: =IF(('Hampshire Daily'!R29-'Hampshire Daily'!R28<0),"0",('Hampshire Daily'!R29-'Hampshire Daily'!R28)) -> 176.5 | R26: =IF(('Hampshire Daily'!U29-'Hampshire Daily'!U28<0),"0",('Hampshire Daily'!U29-'Hampshire Daily'!U28)) -> 12 | S26: =IF(('Hampshire Daily'!V29-'Hampshire Daily'!V28<0),"0",('Hampshire Daily'!V29-'Hampshire Daily'!V28)) -> 1 | T26: =IF(('Hampshire Daily'!W29-'Hampshire Daily'!W28<0),"0",('Hampshire Daily'!W29-'Hampshire Daily'!W28)) -> 0 | U26: =IF(('Hampshire Daily'!X29-'Hampshire Daily'!X28<0),"0",('Hampshire Daily'!X29-'Hampshire Daily'!X28)) -> 0.193 | V26: =IF(('Hampshire Daily'!Y29-'Hampshire Daily'!Y28<0),"0",('Hampshire Daily'!Y29-'Hampshire Daily'!Y28)) -> 0.011 | W26: =IF(('Hampshire Daily'!Z29-'Hampshire Daily'!Z28<0),"0",('Hampshire Daily'!Z29-'Hampshire Daily'!Z28)) -> 0 | X26: =IF(('Hampshire Daily'!AA29-'Hampshire Daily'!AA28<0),"0",('Hampshire Daily'!AA29-'Hampshire Daily'!AA28)) -> 6 | Y26: ='Hampshire Daily'!B29 -> 233 | Z26: ='Hampshire Daily'!C29 -> 99
A27: Hampshire | B27: =B26+1 -> 26 | C27: 10 | D27: 2021 | E27: =IF(('Hampshire Daily'!D30-'Hampshire Daily'!D29<0),"0",('Hampshire Daily'!D30-'Hampshire Daily'!D29)) -> 2904 | F27: =IF(('Hampshire Daily'!F30-'Hampshire Daily'!F29<0),"0",('Hampshire Daily'!F30-'Hampshire Daily'!F29)) -> 2126 | G27: =IF(('Hampshire Daily'!H30-'Hampshire Daily'!H29<0),"0",('Hampshire Daily'!H30-'Hampshire Daily'!H29)) -> 0 | H27: =IF(('Hampshire Daily'!I30-'Hampshire Daily'!I29<0),"0",('Hampshire Daily'!I30-'Hampshire Daily'!I29)) -> 2367.0968 | I27: =IF(('Hampshire Daily'!J30-'Hampshire Daily'!J29<0),"0",('Hampshire Daily'!J30-'Hampshire Daily'!J29)) -> 0.12903226 | J27: =IF(('Hampshire Daily'!K30-'Hampshire Daily'!K29<0),"0",('Hampshire Daily'!K30-'Hampshire Daily'!K29)) -> 69539.419 | K27: =IF(('Hampshire Daily'!L30-'Hampshire Daily'!L29<0),"0",('Hampshire Daily'!L30-'Hampshire Daily'!L29)) -> 1434 | L27: =IF(('Hampshire Daily'!M30-'Hampshire Daily'!M29<0),"0",('Hampshire Daily'!M30-'Hampshire Daily'!M29)) -> 1 | M27: =IF(('Hampshire Daily'!N30-'Hampshire Daily'!N29<0),"0",('Hampshire Daily'!N30-'Hampshire Daily'!N29)) -> 2857 | N27: =IF(('Hampshire Daily'!O30-'Hampshire Daily'!O29<0),"0",('Hampshire Daily'!O30-'Hampshire Daily'!O29)) -> 110 | ... Q27: =IF(('Hampshire Daily'!R30-'Hampshire Daily'!R29<0),"0",('Hampshire Daily'!R30-'Hampshire Daily'!R29)) -> 176.5 | R27: =IF(('Hampshire Daily'!U30-'Hampshire Daily'!U29<0),"0",('Hampshire Daily'!U30-'Hampshire Daily'!U29)) -> 11 | S27: =IF(('Hampshire Daily'!V30-'Hampshire Daily'!V29<0),"0",('Hampshire Daily'!V30-'Hampshire Daily'!V29)) -> 1 | T27: =IF(('Hampshire Daily'!W30-'Hampshire Daily'!W29<0),"0",('Hampshire Daily'!W30-'Hampshire Daily'!W29)) -> 0 | U27: =IF(('Hampshire Daily'!X30-'Hampshire Daily'!X29<0),"0",('Hampshire Daily'!X30-'Hampshire Daily'!X29)) -> 0.23 | V27: =IF(('Hampshire Daily'!Y30-'Hampshire Daily'!Y29<0),"0",('Hampshire Daily'!Y30-'Hampshire Daily'!Y29)) -> 0.01 | W27: =IF(('Hampshire Daily'!Z30-'Hampshire Daily'!Z29<0),"0",('Hampshire Daily'!Z30-'Hampshire Daily'!Z29)) -> 0 | X27: =IF(('Hampshire Daily'!AA30-'Hampshire Daily'!AA29<0),"0",('Hampshire Daily'!AA30-'Hampshire Daily'!AA29)) -> 8 | Y27: ='Hampshire Daily'!B30 -> 217 | Z27: ='Hampshire Daily'!C30 -> 89
