Workbook

Sheet Total
A1: Site Name | B1: Day | C1: Month | D1: Year | E1: Total Electricity Kwh | F1: Electricity Tariff ($/Kwh) | G1: Natual Gas (m3) | H1: Natural Gas $/m3 | I1: Water Utility Supply (m3) m3 | J1: Water Utility Supply (m3) $/m3 | K1: Room Nights | L1: Total Guests
A2: Istanbul at the Bosphorus | B2: 1 | C2: 1 | D2: 2022 | E2: ='Electricity '!I4+'Electricity '!O4 -> 24202.44 | F2: 2.06 | G2: ='Gas Water'!M5 -> 2757 | H2: 6.17 | I2: ='Gas Water'!L5 -> 184 | J2: 14.95 | K2: 145 | L2: 294
A3: Istanbul at the Bosphorus | B3: 2 | C3: 1 | D3: 2022 | E3: ='Electricity '!I5+'Electricity '!O5 -> 24239.7 | F3: 2.06 | G3: ='Gas Water'!M6 -> 2787 | H3: 6.17 | I3: ='Gas Water'!L6 -> 202 | J3: 14.95 | K3: 127 | L3: 252
A4: Istanbul at the Bosphorus | B4: 3 | C4: 1 | D4: 2022 | E4: ='Electricity '!I6+'Electricity '!O6 -> 21979.26 | F4: 2.06 | G4: ='Gas Water'!M7 -> 2470 | H4: 6.17 | I4: ='Gas Water'!L7 -> 221 | J4: 14.95 | K4: 143 | L4: 256
A5: Istanbul at the Bosphorus | B5: 4 | C5: 1 | D5: 2022 | E5: ='Electricity '!I7+'Electricity '!O7 -> 21432.78 | F5: 2.06 | G5: ='Gas Water'!M8 -> 2283 | H5: 6.17 | I5: ='Gas Water'!L8 -> 206 | J5: 14.95 | K5: 148 | L5: 255
A6: Istanbul at the Bosphorus | B6: 5 | C6: 1 | D6: 2022 | E6: ='Electricity '!I8+'Electricity '!O8 -> 22736.88 | F6: 2.06 | G6: ='Gas Water'!M9 -> 2077 | H6: 6.17 | I6: ='Gas Water'!L9 -> 183 | J6: 14.95 | K6: 147 | L6: 265
A7: Istanbul at the Bosphorus | B7: 6 | C7: 1 | D7: 2022 | E7: ='Electricity '!I9+'Electricity '!O9 -> 23142.6 | F7: 2.06 | G7: ='Gas Water'!M10 -> 2098 | H7: 6.17 | I7: ='Gas Water'!L10 -> 174 | J7: 14.95 | K7: 152 | L7: 279
A8: Istanbul at the Bosphorus | B8: 7 | C8: 1 | D8: 2022 | E8: ='Electricity '!I10+'Electricity '!O10 -> 23693.22 | F8: 2.06 | G8: ='Gas Water'!M11 -> 2634 | H8: 6.17 | I8: ='Gas Water'!L11 -> 179 | J8: 14.95 | K8: 155 | L8: 296
A9: Istanbul at the Bosphorus | B9: 8 | C9: 1 | D9: 2022 | E9: ='Electricity '!I12+'Electricity '!O11 -> 23763.6 | F9: 2.06 | G9: ='Gas Water'!M12 -> 2711 | H9: 6.17 | I9: ='Gas Water'!L12 -> 190 | J9: 14.95 | K9: 136 | L9: 264
A10: Istanbul at the Bosphorus | B10: 9 | C10: 1 | D10: 2022 | E10: ='Electricity '!I13+'Electricity '!O12 -> #VALUE! | F10: 2.06 | G10: ='Gas Water'!M13 -> 2672 | H10: 6.17 | I10: ='Gas Water'!L13 -> 223 | J10: 14.95 | K10: 125 | L10: 224
A11: Istanbul at the Bosphorus | B11: 10 | C11: 1 | D11: 2022 | E11: ='Electricity '!I14+'Electricity '!O13 -> #VALUE! | F11: 2.06 | G11: ='Gas Water'!M14 | H11: 6.17 | I11: ='Gas Water'!L14 | J11: 14.95
A12: Istanbul at the Bosphorus | B12: 11 | C12: 1 | D12: 2022 | E12: ='Electricity '!I14+'Electricity '!O14 -> #VALUE! | F12: 2.06 | G12: ='Gas Water'!M15 | H12: 6.17 | I12: ='Gas Water'!L15 | J12: 14.95
A13: Istanbul at the Bosphorus | B13: 12 | C13: 1 | D13: 2022 | E13: ='Electricity '!I15+'Electricity '!O15 -> #VALUE! | F13: 2.06 | G13: ='Gas Water'!M16 | H13: 6.17 | I13: ='Gas Water'!L16 | J13: 14.95
A14: Istanbul at the Bosphorus | B14: 13 | C14: 1 | D14: 2022 | E14: ='Electricity '!I16+'Electricity '!O16 -> #VALUE! | F14: 2.06 | G14: ='Gas Water'!M17 | H14: 6.17 | I14: ='Gas Water'!L17 | J14: 14.95
A15: Istanbul at the Bosphorus | B15: 14 | C15: 1 | D15: 2022 | E15: ='Electricity '!I17+'Electricity '!O17 -> #VALUE! | F15: 2.06 | G15: ='Gas Water'!M18 | H15: 6.17 | I15: ='Gas Water'!L18 | J15: 14.95
A16: Istanbul at the Bosphorus | B16: 15 | C16: 1 | D16: 2022 | E16: ='Electricity '!I18+'Electricity '!O18 -> #VALUE! | F16: 2.06 | G16: ='Gas Water'!M19 | H16: 6.17 | I16: ='Gas Water'!L19 | J16: 14.95
A17: Istanbul at the Bosphorus | B17: 16 | C17: 1 | D17: 2022 | E17: ='Electricity '!I19+'Electricity '!O19 -> #VALUE! | F17: 2.06 | G17: ='Gas Water'!M20 | H17: 6.17 | I17: ='Gas Water'!L20 | J17: 14.95
A18: Istanbul at the Bosphorus | B18: 17 | C18: 1 | D18: 2022 | E18: ='Electricity '!I20+'Electricity '!O20 -> #VALUE! | F18: 2.06 | G18: ='Gas Water'!M21 | H18: 6.17 | I18: ='Gas Water'!L21 | J18: 14.95
A19: Istanbul at the Bosphorus | B19: 18 | C19: 1 | D19: 2022 | E19: ='Electricity '!I21+'Electricity '!O21 -> #VALUE! | F19: 2.06 | G19: ='Gas Water'!M22 | H19: 6.17 | I19: ='Gas Water'!L22 | J19: 14.95
A20: Istanbul at the Bosphorus | B20: 19 | C20: 1 | D20: 2022 | E20: ='Electricity '!I22+'Electricity '!O22 -> #VALUE! | F20: 2.06 | G20: ='Gas Water'!M23 | H20: 6.17 | I20: ='Gas Water'!L23 | J20: 14.95
A21: Istanbul at the Bosphorus | B21: 20 | C21: 1 | D21: 2022 | E21: ='Electricity '!I23+'Electricity '!O23 -> #VALUE! | F21: 2.06 | G21: ='Gas Water'!M24 | H21: 6.17 | I21: ='Gas Water'!L24 | J21: 14.95
A22: Istanbul at the Bosphorus | B22: 21 | C22: 1 | D22: 2022 | E22: ='Electricity '!I24+'Electricity '!O24 -> #VALUE! | F22: 2.06 | G22: ='Gas Water'!M25 | H22: 6.17 | I22: ='Gas Water'!L25 | J22: 14.95
A23: Istanbul at the Bosphorus | B23: 22 | C23: 1 | D23: 2022 | E23: ='Electricity '!I25+'Electricity '!O25 -> #VALUE! | F23: 2.06 | G23: ='Gas Water'!M26 | H23: 6.17 | I23: ='Gas Water'!L26 | J23: 14.95
... A32: Istanbul at the Bosphorus | B32: 31 | C32: 1 | D32: 2022 | E32: ='Electricity '!I34+'Electricity '!O34 -> 0 | F32: 2.06 | G32: ='Gas Water'!M35 -> 0 | H32: 6.17 | I32: ='Gas Water'!L35 -> 0 | J32: 14.95
A33: Istanbul at the Bosphorus | B33: 1 | C33: 2 | D33: 2022 | E33: ='Electricity '!I35+'Electricity '!O35 -> 0 | G33: ='Gas Water'!M36 -> 0 | I33: ='Gas Water'!L36 -> 0
A34: Istanbul at the Bosphorus | B34: 2 | C34: 2 | D34: 2022 | E34: ='Electricity '!I36+'Electricity '!O36 -> 0 | G34: ='Gas Water'!M37 -> 0 | I34: ='Gas Water'!L37 -> 0
A35: Istanbul at the Bosphorus | B35: 3 | C35: 2 | D35: 2022 | E35: ='Electricity '!I37+'Electricity '!O37 -> 0 | G35: ='Gas Water'!M38 -> 0 | I35: ='Gas Water'!L38 -> 0
A36: Istanbul at the Bosphorus | B36: 4 | C36: 2 | D36: 2022 | E36: ='Electricity '!I38+'Electricity '!O38 -> 0 | G36: ='Gas Water'!M39 -> 0 | I36: ='Gas Water'!L39 -> 0
A37: Istanbul at the Bosphorus | B37: 5 | C37: 2 | D37: 2022 | E37: ='Electricity '!I39+'Electricity '!O39 -> 0 | G37: ='Gas Water'!M40 -> 0 | I37: ='Gas Water'!L40 -> 0
A38: Istanbul at the Bosphorus | B38: 6 | C38: 2 | D38: 2022 | E38: ='Electricity '!I40+'Electricity '!O40 -> 0 | G38: ='Gas Water'!M41 -> 0 | I38: ='Gas Water'!L41 -> 0
A39: Istanbul at the Bosphorus | B39: 7 | C39: 2 | D39: 2022 | E39: ='Electricity '!I41+'Electricity '!O41 -> 0 | G39: ='Gas Water'!M42 -> 0 | I39: ='Gas Water'!L42 -> 0
A40: Istanbul at the Bosphorus | B40: 8 | C40: 2 | D40: 2022 | E40: ='Electricity '!I42+'Electricity '!O42 -> 0 | G40: ='Gas Water'!M43 -> 0 | I40: ='Gas Water'!L43 -> 0
A41: Istanbul at the Bosphorus | B41: 9 | C41: 2 | D41: 2022 | E41: ='Electricity '!I43+'Electricity '!O43 -> 0 | G41: ='Gas Water'!M44 -> 0 | I41: ='Gas Water'!L44 -> 0
A42: Istanbul at the Bosphorus | B42: 10 | C42: 2 | D42: 2022 | E42: ='Electricity '!I44+'Electricity '!O44 -> 0 | G42: ='Gas Water'!M45 -> 0 | I42: ='Gas Water'!L45 -> 0
A43: Istanbul at the Bosphorus | B43: 11 | C43: 2 | D43: 2022 | E43: ='Electricity '!I45+'Electricity '!O45 -> 0 | G43: ='Gas Water'!M46 -> 0 | I43: ='Gas Water'!L46 -> 0
A44: Istanbul at the Bosphorus | B44: 12 | C44: 2 | D44: 2022 | E44: ='Electricity '!I46+'Electricity '!O46 -> 0 | G44: ='Gas Water'!M47 -> 0 | I44: ='Gas Water'!L47 -> 0
... A77: Istanbul at the Bosphorus | B77: 17 | C77: 3 | D77: 2022 | E77: ='Electricity '!I79+'Electricity '!O79 -> 0 | G77: ='Gas Water'!M80 | I77: ='Gas Water'!L80
A78: Istanbul at the Bosphorus | B78: 18 | C78: 3 | D78: 2022 | E78: ='Electricity '!I80+'Electricity '!O80 -> #VALUE!
A79: Istanbul at the Bosphorus | B79: 19 | C79: 3 | D79: 2022 | E79: ='Electricity '!I81+'Electricity '!O81 -> #VALUE! | G79: ='Gas Water'!M82
A80: Istanbul at the Bosphorus | B80: 20 | C80: 3 | D80: 2022 | E80: ='Electricity '!I82+'Electricity '!O82 -> #VALUE! | G80: ='Gas Water'!M83 | I80: ='Gas Water'!L83
...

Sheet Gas Water
B2: Date | C2: CHP Reading m3 | D2: Boiler Reading m3 | E2: Kitchen Reading m3 | F2: Laundry Reading m3 | G2: Water Supplier Credit m3 | H2: CHP Diffenece m3 | I2: Boiler Difference m3 | J2: Kitchen Difference m3 | K2: Laundry Difference m3 | L2: Water Difference m3 | M2: Total Gas Consumption m3
B3: 43830 | C3: 16228333 | D3: 3990997 | E3: 223696 | F3: 521490 | G3: 5647
B4: 44561 | C4: 16228335 | D4: 5099652 | E4: 243800 | F4: 638972 | G4: 293998 | H4: 0 | I4: 2760 | J4: 190 | K4: 222 | L4: 196 | M4: =IF(H4="","",+(H4+I4+J4+K4)) -> 3172 | O4: =IF(L4="",1,0) -> 0
B5: 44197 | C5: 16228335 | D5: 5101985 | E5: 244004 | F5: 639192 | G5: 294182 | H5: =IF(C5="","",+(C5-C4)) -> 0 | I5: =IF(D5="","",+(D5-D4)) -> 2333 | J5: =IF(E5="","",+(E5-E4)) -> 204 | K5: =IF(F5="","",+(F5-F4)) -> 220 | L5: =IF(G5="","",+(G5-G4)) -> 184 | M5: =IF(H5="","",+(H5+I5+J5+K5)) -> 2757 | Q5: =IF(L5="",1,0) -> 0
B6: 44198 | C6: 16228335 | D6: 5104352 | E6: 244192 | F6: 639424 | G6: 294384 | H6: =IF(C6="","",+(C6-C5)) -> 0 | I6: =IF(D6="","",+(D6-D5)) -> 2367 | J6: =IF(E6="","",+(E6-E5)) -> 188 | K6: =IF(F6="","",+(F6-F5)) -> 232 | L6: =IF(G6="","",+(G6-G5)) -> 202 | M6: =IF(H6="","",+(H6+I6+J6+K6)) -> 2787 | Q6: =IF(L6="",1,0) -> 0
B7: 44199 | C7: 16228335 | D7: 5106445 | E7: 244348 | F7: 639645 | G7: 294605 | H7: =IF(C7="","",+(C7-C6)) -> 0 | I7: =IF(D7="","",+(D7-D6)) -> 2093 | J7: =IF(E7="","",+(E7-E6)) -> 156 | K7: =IF(F7="","",+(F7-F6)) -> 221 | L7: =IF(G7="","",+(G7-G6)) -> 221 | M7: =IF(H7="","",+(H7+I7+J7+K7)) -> 2470 | Q7: =IF(L7="",1,0) -> 0
B8: 44200 | C8: 16228335 | D8: 5108382 | E8: 244496 | F8: 639843 | G8: 294811 | H8: =IF(C8="","",+(C8-C7)) -> 0 | I8: =IF(D8="","",+(D8-D7)) -> 1937 | J8: =IF(E8="","",+(E8-E7)) -> 148 | K8: =IF(F8="","",+(F8-F7)) -> 198 | L8: =IF(G8="","",+(G8-G7)) -> 206 | M8: =IF(H8="","",+(H8+I8+J8+K8)) -> 2283 | Q8: =IF(L8="",1,0) -> 0
B9: 44201 | C9: 16228335 | D9: 5110087 | E9: 244679 | F9: 640032 | G9: 294994 | H9: =IF(C9="","",+(C9-C8)) -> 0 | I9: =IF(D9="","",+(D9-D8)) -> 1705 | J9: =IF(E9="","",+(E9-E8)) -> 183 | K9: =IF(F9="","",+(F9-F8)) -> 189 | L9: =IF(G9="","",+(G9-G8)) -> 183 | M9: =IF(H9="","",+(H9+I9+J9+K9)) -> 2077 | Q9: =IF(L9="",1,0) -> 0
B10: 44202 | C10: 16228335 | D10: 5111788 | E10: 244873 | F10: 640235 | G10: 295168 | H10: =IF(C10="","",+(C10-C9)) -> 0 | I10: =IF(D10="","",+(D10-D9)) -> 1701 | J10: =IF(E10="","",+(E10-E9)) -> 194 | K10: =IF(F10="","",+(F10-F9)) -> 203 | L10: =IF(G10="","",+(G10-G9)) -> 174 | M10: =IF(H10="","",+(H10+I10+J10+K10)) -> 2098 | Q10: =IF(L10="",1,0) -> 0
B11: 44203 | C11: 16228335 | D11: 5114024 | E11: 245070 | F11: 640436 | G11: 295347 | H11: =IF(C11="","",+(C11-C10)) -> 0 | I11: =IF(D11="","",+(D11-D10)) -> 2236 | J11: =IF(E11="","",+(E11-E10)) -> 197 | K11: =IF(F11="","",+(F11-F10)) -> 201 | L11: =IF(G11="","",+(G11-G10)) -> 179 | M11: =IF(H11="","",+(H11+I11+J11+K11)) -> 2634 | Q11: =IF(L11="",1,0) -> 0
B12: 44204 | C12: 16228335 | D12: 5116326 | E12: 245248 | F12: 640667 | G12: 295537 | H12: =IF(C12="","",+(C12-C11)) -> 0 | I12: =IF(D12="","",+(D12-D11)) -> 2302 | J12: =IF(E12="","",+(E12-E11)) -> 178 | K12: =IF(F12="","",+(F12-F11)) -> 231 | L12: =IF(G12="","",+(G12-G11)) -> 190 | M12: =IF(H12="","",+(H12+I12+J12+K12)) -> 2711 | Q12: =IF(L12="",1,0) -> 0
B13: 44205 | C13: 16228335 | D13: 5118633 | E13: 245416 | F13: 640864 | G13: 295760 | H13: =IF(C13="","",+(C13-C12)) -> 0 | I13: =IF(D13="","",+(D13-D12)) -> 2307 | J13: =IF(E13="","",+(E13-E12)) -> 168 | K13: =IF(F13="","",+(F13-F12)) -> 197 | L13: =IF(G13="","",+(G13-G12)) -> 223 | M13: =IF(H13="","",+(H13+I13+J13+K13)) -> 2672 | Q13: =IF(L13="",1,0) -> 0
B14: 44206 | H14: =IF(C14="","",+(C14-C13)) | I14: =IF(D14="","",+(D14-D13)) | J14: =IF(E14="","",+(E14-E13)) | K14: =IF(F14="","",+(F14-F13)) | L14: =IF(G14="","",+(G14-G13)) | M14: =IF(H14="","",+(H14+I14+J14+K14)) | Q14: =IF(L14="",1,0) -> 1
B15: 44207 | H15: =IF(C15="","",+(C15-C14)) | I15: =IF(D15="","",+(D15-D14)) | J15: =IF(E15="","",+(E15-E14)) | K15: =IF(F15="","",+(F15-F14)) | L15: =IF(G15="","",+(G15-G14)) | M15: =IF(H15="","",+(H15+I15+J15+K15)) | Q15: =IF(L15="",1,0) -> 1
B16: 44208 | H16: =IF(C16="","",+(C16-C15)) | I16: =IF(D16="","",+(D16-D15)) | J16: =IF(E16="","",+(E16-E15)) | K16: =IF(F16="","",+(F16-F15)) | L16: =IF(G16="","",+(G16-G15)) | M16: =IF(H16="","",+(H16+I16+J16+K16)) | Q16: =IF(L16="",1,0) -> 1
B17: 44209 | H17: =IF(C17="","",+(C17-C16)) | I17: =IF(D17="","",+(D17-D16)) | J17: =IF(E17="","",+(E17-E16)) | K17: =IF(F17="","",+(F17-F16)) | L17: =IF(G17="","",+(G17-G16)) | M17: =IF(H17="","",+(H17+I17+J17+K17)) | Q17: =IF(L17="",1,0) -> 1
B18: 44210 | H18: =IF(C18="","",+(C18-C17)) | I18: =IF(D18="","",+(D18-D17)) | J18: =IF(E18="","",+(E18-E17)) | K18: =IF(F18="","",+(F18-F17)) | L18: =IF(G18="","",+(G18-G17)) | M18: =IF(H18="","",+(H18+I18+J18+K18)) | Q18: =IF(L18="",1,0) -> 1
B19: 44211 | H19: =IF(C19="","",+(C19-C18)) | I19: =IF(D19="","",+(D19-D18)) | J19: =IF(E19="","",+(E19-E18)) | K19: =IF(F19="","",+(F19-F18)) | L19: =IF(G19="","",+(G19-G18)) | M19: =IF(H19="","",+(H19+I19+J19+K19)) | Q19: =IF(L19="",1,0) -> 1
B20: 44212 | H20: =IF(C20="","",+(C20-C19)) | I20: =IF(D20="","",+(D20-D19)) | J20: =IF(E20="","",+(E20-E19)) | K20: =IF(F20="","",+(F20-F19)) | L20: =IF(G20="","",+(G20-G19)) | M20: =IF(H20="","",+(H20+I20+J20+K20)) | Q20: =IF(L20="",1,0) -> 1
B21: 44213 | H21: =IF(C21="","",+(C21-C20)) | I21: =IF(D21="","",+(D21-D20)) | J21: =IF(E21="","",+(E21-E20)) | K21: =IF(F21="","",+(F21-F20)) | L21: =IF(G21="","",+(G21-G20)) | M21: =IF(H21="","",+(H21+I21+J21+K21)) | Q21: =IF(L21="",1,0) -> 1
B22: 44214 | H22: =IF(C22="","",+(C22-C21)) | I22: =IF(D22="","",+(D22-D21)) | J22: =IF(E22="","",+(E22-E21)) | K22: =IF(F22="","",+(F22-F21)) | L22: =IF(G22="","",+(G22-G21)) | M22: =IF(H22="","",+(H22+I22+J22+K22)) | Q22: =IF(L22="",1,0) -> 1
B23: 44215 | H23: =IF(C23="","",+(C23-C22)) | I23: =IF(D23="","",+(D23-D22)) | J23: =IF(E23="","",+(E23-E22)) | K23: =IF(F23="","",+(F23-F22)) | L23: =IF(G23="","",+(G23-G22)) | M23: =IF(H23="","",+(H23+I23+J23+K23)) | Q23: =IF(L23="",1,0) -> 1
B24: 44216 | H24: =IF(C24="","",+(C24-C23)) | I24: =IF(D24="","",+(D24-D23)) | J24: =IF(E24="","",+(E24-E23)) | K24: =IF(F24="","",+(F24-F23)) | L24: =IF(G24="","",+(G24-G23)) | M24: =IF(H24="","",+(H24+I24+J24+K24)) | Q24: =IF(L24="",1,0) -> 1
B25: 44217 | H25: =IF(C25="","",+(C25-C24)) | I25: =IF(D25="","",+(D25-D24)) | J25: =IF(E25="","",+(E25-E24)) | K25: =IF(F25="","",+(F25-F24)) | L25: =IF(G25="","",+(G25-G24)) | M25: =IF(H25="","",+(H25+I25+J25+K25)) | N25: Total Water m3 | O25: Total Gas m3 | Q25: =IF(L25="",1,0) -> 1
B26: 44218 | H26: =IF(C26="","",+(C26-C25)) | I26: =IF(D26="","",+(D26-D25)) | J26: =IF(E26="","",+(E26-E25)) | K26: =IF(F26="","",+(F26-F25)) | L26: =IF(G26="","",+(G26-G25)) | M26: =IF(H26="","",+(H26+I26+J26+K26)) | Q26: =IF(L26="",1,0) -> 1
B27: 44219 | H27: =IF(C27="","",+(C27-C26)) | I27: =IF(D27="","",+(D27-D26)) | J27: =IF(E27="","",+(E27-E26)) | K27: =IF(F27="","",+(F27-F26)) | L27: =IF(G27="","",+(G27-G26)) | M27: =IF(H27="","",+(H27+I27+J27+K27)) | Q27: =IF(L27="",1,0) -> 1
B28: 44220 | H28: =IF(C28="","",+(C28-C27)) | I28: =IF(D28="","",+(D28-D27)) | J28: =IF(E28="","",+(E28-E27)) | K28: =IF(F28="","",+(F28-F27)) | L28: =IF(G28="","",+(G28-G27)) | M28: =IF(H28="","",+(H28+I28+J28+K28)) | N28: =SUM(L4:L34) -> 1958 | O28: =SUM(M4:M34) -> 25661 | Q28: =IF(L28="",1,0) -> 1
B29: 44221 | H29: =IF(C29="","",+(C29-C28)) | I29: =IF(D29="","",+(D29-D28)) | J29: =IF(E29="","",+(E29-E28)) | K29: =IF(F29="","",+(F29-F28)) | L29: =IF(G29="","",+(G29-G28)) | M29: =IF(H29="","",+(H29+I29+J29+K29)) | N29: Daily Average Water Consumption | O29: Daily Average Gas Consumption | Q29: =IF(L29="",1,0) -> 1
B30: 44222 | H30: =IF(C30="","",+(C30-C29)) | I30: =IF(D30="","",+(D30-D29)) | J30: =IF(E30="","",+(E30-E29)) | K30: =IF(F30="","",+(F30-F29)) | L30: =IF(G30="","",+(G30-G29)) | M30: =IF(H30="","",+(H30+I30+J30+K30)) | Q30: =IF(L30="",1,0) -> 1
B31: 44223 | H31: =IF(C31="","",+(C31-C30)) | I31: =IF(D31="","",+(D31-D30)) | J31: =IF(E31="","",+(E31-E30)) | K31: =IF(F31="","",+(F31-F30)) | L31: =IF(G31="","",+(G31-G30)) | M31: =IF(H31="","",+(H31+I31+J31+K31)) | N31: =AVERAGE(L4:L34) -> 195.8 | O31: =AVERAGE(M4:M34) -> 2566.1 | Q31: =IF(L31="",1,0) -> 1
B32: 44224 | H32: =IF(C32="","",+(C32-C31)) | I32: =IF(D32="","",+(D32-D31)) | J32: =IF(E32="","",+(E32-E31)) | K32: =IF(F32="","",+(F32-F31)) | L32: =IF(G32="","",+(G32-G31)) | M32: =IF(H32="","",+(H32+I32+J32+K32)) | O32: =IF(L32="",1,0) -> 1
B33: 44225 | H33: =IF(C33="","",+(C33-C32)) | I33: =IF(D33="","",+(D33-D32)) | J33: =IF(E33="","",+(E33-E32)) | K33: =IF(F33="","",+(F33-F32)) | L33: =IF(G33="","",+(G33-G32)) | M33: =IF(H33="","",+(H33+I33+J33+K33)) | O33: =IF(L33="",1,0) -> 1
B34: 44226 | Q34: =IF(L34="",1,0) -> 1
B35: 44227
B36: 44228 | Q36: =IF(L36="",1,0) -> 1
B37: 44229 | Q37: =IF(L37="",1,0) -> 1
B38: 44230 | Q38: =IF(L38="",1,0) -> 1
B39: 44231 | Q39: =IF(L39="",1,0) -> 1
B40: 44232 | Q40: =IF(L40="",1,0) -> 1
B41: 44233 | Q41: =IF(L41="",1,0) -> 1
...

Sheet Electricity 
A1: Date | B1: TR1 (bilgisayarda) | C1: TR2 (bilgisayardan) | D1: Meter Reading(Active)KWh | E1: Reactive Reading KWh | F1: Capacitive Reading KWh | G1: Şebekeye | H1: Meter Multipier | I1: Şebekeden (kWh) | J1: Endüktif (kVAr) | K1: Reaktif Endüktif Oranı | L1: Kapasitif (kVAr) | M1: Reaktif Kapasitif Oranı | N1: Kojen Değeri | O1: Kojen (kWh)
A2: 43465 | D2: 4926.457 | E2: 220.02 | F2: 169.75 | N2: 66068309
A3: 44561 | D3: 0.142 | E3: 1877.924 | F3: 61.573 | H3: 4140 | I3: 24293 | J3: 260.82 | K3: =IF(J3="","",+(J3/I3)) -> 0.010736426 | L3: 260.82 | M3: =IF(L3="","",(L3/I3)) -> 0.010736426 | N3: 66068309 | O3: 0 | P3: =IF(N3="",0,1) -> 1 | Q3: =IF(N3="",1,0) -> 0
A4: 44562 | D4: 0.142 | E4: 1883.77 | F4: 61.636 | G4: 183.709 | H4: 4140 | I4: =IF(D4="","",+(E4-E3)*4140) -> 24202.44 | J4: =IF(E4="","",+(F4-F3)*4140) -> 260.82 | K4: =IF(J4="","",+(J4/I4)) -> 0.010776599 | L4: =IF(F4="","",+(F4-F3)*4140) -> 260.82 | M4: =IF(L4="","",(L4/I4)) -> 0.010776599 | N4: 66068309 | O4: 0 | P4: =IF(N4="",0,1) -> 1 | Q4: =IF(N4="",1,0) -> 0
A5: 44563 | D5: 0.142 | E5: 1889.625 | F5: 61.733 | G5: 183.741 | H5: 4140 | I5: =IF(D5="","",+(E5-E4)*4140) -> 24239.7 | J5: =IF(E5="","",+(F5-F4)*4140) -> 401.58 | K5: =IF(J5="","",+(J5/I5)) -> 0.016567037 | L5: =IF(F5="","",+(F5-F4)*4140) -> 401.58 | M5: =IF(L5="","",(L5/I5)) -> 0.016567037 | N5: 66068309 | O5: 0 | P5: =IF(N5="",0,1) -> 1 | Q5: =IF(N5="",1,0) -> 0
A6: 44564 | D6: 0.142 | E6: 1894.934 | F6: 61.826 | G6: 183.781 | H6: 4140 | I6: =IF(D6="","",+(E6-E5)*4140) -> 21979.26 | J6: =IF(E6="","",+(F6-F5)*4140) -> 385.02 | K6: =IF(J6="","",+(J6/I6)) -> 0.017517423 | L6: =IF(F6="","",+(F6-F5)*4140) -> 385.02 | M6: =IF(L6="","",(L6/I6)) -> 0.017517423 | N6: 66068309 | O6: 0 | P6: =IF(N6="",0,1) -> 1 | Q6: =IF(N6="",1,0) -> 0
A7: 44565 | D7: 0.142 | E7: 1900.111 | F7: 61.918 | G7: 183.809 | H7: 4140 | I7: =IF(D7="","",+(E7-E6)*4140) -> 21432.78 | J7: =IF(E7="","",+(F7-F6)*4140) -> 380.88 | K7: =IF(J7="","",+(J7/I7)) -> 0.01777091 | L7: =IF(F7="","",+(F7-F6)*4140) -> 380.88 | M7: =IF(L7="","",(L7/I7)) -> 0.01777091 | N7: 66068309 | O7: 0 | P7: =IF(N7="",0,1) -> 1 | Q7: =IF(N7="",1,0) -> 0
A8: 44566 | D8: 0.142 | E8: 1905.603 | F8: 61.968 | G8: 183.832 | H8: 4140 | I8: =IF(D8="","",+(E8-E7)*4140) -> 22736.88 | J8: =IF(E8="","",+(F8-F7)*4140) -> 207 | K8: =IF(J8="","",+(J8/I8)) -> 0.0091041515 | L8: =IF(F8="","",+(F8-F7)*4140) -> 207 | M8: =IF(L8="","",(L8/I8)) -> 0.0091041515 | N8: 66068309 | O8: 0 | R8: =IF(N8="",0,1) -> 1 | S8: =IF(N8="",1,0) -> 0
A9: 44567 | D9: 0.142 | E9: 1911.193 | F9: 62.044 | G9: 183.872 | H9: 4140 | I9: =IF(D9="","",+(E9-E8)*4140) -> 23142.6 | J9: =IF(E9="","",+(F9-F8)*4140) -> 314.64 | K9: =IF(J9="","",+(J9/I9)) -> 0.013595707 | L9: =IF(F9="","",+(F9-F8)*4140) -> 314.64 | M9: =IF(L9="","",(L9/I9)) -> 0.013595707 | N9: 66068309 | O9: 0 | R9: =IF(N9="",0,1) -> 1 | S9: =IF(N9="",1,0) -> 0
A10: 44568 | D10: 0.142 | E10: 1916.916 | F10: 62.166 | G10: 183.909 | H10: 4140 | I10: =IF(D10="","",+(E10-E9)*4140) -> 23693.22 | J10: =IF(E10="","",+(F10-F9)*4140) -> 505.08 | K10: =IF(J10="","",+(J10/I10)) -> 0.021317491 | L10: =IF(F10="","",+(F10-F9)*4140) -> 505.08 | M10: =IF(L10="","",(L10/I10)) -> 0.021317491 | N10: 66068309 | O10: 0 | R10: =IF(N10="",0,1) -> 1 | S10: =IF(N10="",1,0) -> 0
A11: 44569 | D11: 0.142 | E11: 1922.64 | F11: 62.226 | G11: 183.944 | H11: 4140 | I11: =IF(D11="","",+(E11-E10)*4140) -> 23697.36 | J11: =IF(E11="","",+(F11-F10)*4140) -> 248.4 | K11: =IF(J11="","",+(J11/I11)) -> 0.01048218 | L11: =IF(F11="","",+(F11-F10)*4140) -> 248.4 | M11: =IF(L11="","",(L11/I11)) -> 0.01048218 | N11: 66068309 | O11: 0 | R11: =IF(N11="",0,1) -> 1 | S11: =IF(N11="",1,0) -> 0
A12: 44570 | D12: 0.142 | E12: 1928.38 | F12: 62.285 | G12: 183.986 | H12: 4140 | I12: =IF(D12="","",+(E12-E11)*4140) -> 23763.6 | J12: =IF(E12="","",+(F12-F11)*4140) -> 244.26 | K12: =IF(J12="","",+(J12/I12)) -> 0.010278746 | L12: =IF(F12="","",+(F12-F11)*4140) -> 244.26 | M12: =IF(L12="","",(L12/I12)) -> 0.010278746 | N12: 66068309 | O12: 0 | R12: =IF(N12="",0,1) -> 1 | S12: =IF(N12="",1,0) -> 0
A13: 44571 | G13: 184.028 | H13: 4140 | I13: =IF(D13="","",+(E13-E12)*4140) | J13: =IF(E13="","",+(F13-F12)*4140) | K13: =IF(J13="","",+(J13/I13)) | L13: =IF(F13="","",+(F13-F12)*4140) | M13: =IF(L13="","",(L13/I13)) | N13: 66068309 | O13: 0 | R13: =IF(N13="",0,1) -> 1 | S13: =IF(N13="",1,0) -> 0
A14: 44572 | G14: 184.073 | H14: 4140 | I14: =IF(D14="","",+(E14-E13)*4140) | J14: =IF(E14="","",+(F14-F13)*4140) | K14: =IF(J14="","",+(J14/I14)) | L14: =IF(F14="","",+(F14-F13)*4140) | M14: =IF(L14="","",(L14/I14)) | N14: 66068309 | O14: 0 | R14: =IF(N14="",0,1) -> 1 | S14: =IF(N14="",1,0) -> 0
A15: 44573 | G15: 184.107 | H15: 4140 | I15: =IF(D15="","",+(E15-E14)*4140) | J15: =IF(E15="","",+(F15-F14)*4140) | K15: =IF(J15="","",+(J15/I15)) | L15: =IF(F15="","",+(F15-F14)*4140) | M15: =IF(L15="","",(L15/I15)) | N15: 66068309 | O15: 0 | R15: =IF(N15="",0,1) -> 1 | S15: =IF(N15="",1,0) -> 0
A16: 44574 | G16: 184.131 | H16: 4140 | I16: =IF(D16="","",+(E16-E15)*4140) | J16: =IF(E16="","",+(F16-F15)*4140) | K16: =IF(J16="","",+(J16/I16)) | L16: =IF(F16="","",+(F16-F15)*4140) | M16: =IF(L16="","",(L16/I16)) | N16: 66068309 | O16: 0 | R16: =IF(N16="",0,1) -> 1 | S16: =IF(N16="",1,0) -> 0
A17: 44575 | G17: 184.166 | H17: 4140 | I17: =IF(D17="","",+(E17-E16)*4140) | J17: =IF(E17="","",+(F17-F16)*4140) | K17: =IF(J17="","",+(J17/I17)) | L17: =IF(F17="","",+(F17-F16)*4140) | M17: =IF(L17="","",(L17/I17)) | N17: 66068309 | O17: 0 | R17: =IF(N17="",0,1) -> 1 | S17: =IF(N17="",1,0) -> 0
A18: 44576 | G18: 184.206 | H18: 4140 | I18: =IF(D18="","",+(E18-E17)*4140) | J18: =IF(E18="","",+(F18-F17)*4140) | K18: =IF(J18="","",+(J18/I18)) | L18: =IF(F18="","",+(F18-F17)*4140) | M18: =IF(L18="","",(L18/I18)) | N18: 66068309 | O18: 0 | R18: =IF(N18="",0,1) -> 1 | S18: =IF(N18="",1,0) -> 0
A19: 44577 | G19: 184.245 | H19: 4140 | I19: =IF(D19="","",+(E19-E18)*4140) | J19: =IF(E19="","",+(F19-F18)*4140) | K19: =IF(J19="","",+(J19/I19)) | L19: =IF(F19="","",+(F19-F18)*4140) | M19: =IF(L19="","",(L19/I19)) | N19: 66068309 | O19: 0 | R19: =IF(N19="",0,1) -> 1 | S19: =IF(N19="",1,0) -> 0
A20: 44578 | G20: 184.282 | H20: 4140 | I20: =IF(D20="","",+(E20-E19)*4140) | J20: =IF(E20="","",+(F20-F19)*4140) | K20: =IF(J20="","",+(J20/I20)) | L20: =IF(F20="","",+(F20-F19)*4140) | M20: =IF(L20="","",(L20/I20)) | N20: 66068309 | O20: 0 | R20: =IF(N20="",0,1) -> 1 | S20: =IF(N20="",1,0) -> 0
A21: 44579 | G21: 184.312 | H21: 4140 | I21: =IF(D21="","",+(E21-E20)*4140) | J21: =IF(E21="","",+(F21-F20)*4140) | K21: =IF(J21="","",+(J21/I21)) | L21: =IF(F21="","",+(F21-F20)*4140) | M21: =IF(L21="","",(L21/I21)) | N21: 66068309 | O21: 0 | P21: Ocak / Jan | R21: =IF(N21="",0,1) -> 1 | S21: =IF(N21="",1,0) -> 0
A22: 44580 | G22: 184.348 | H22: 4140 | I22: =IF(D22="","",+(E22-E21)*4140) | J22: =IF(E22="","",+(F22-F21)*4140) | K22: =IF(J22="","",+(J22/I22)) | L22: =IF(F22="","",+(F22-F21)*4140) | M22: =IF(L22="","",(L22/I22)) | N22: 66068309 | O22: 0 | R22: =IF(N22="",0,1) -> 1 | S22: =IF(N22="",1,0) -> 0
A23: 44581 | G23: 184.39 | H23: 4140 | I23: =IF(D23="","",+(E23-E22)*4140) | J23: =IF(E23="","",+(F23-F22)*4140) | K23: =IF(J23="","",+(J23/I23)) | L23: =IF(F23="","",+(F23-F22)*4140) | M23: =IF(L23="","",(L23/I23)) | N23: 66068309 | O23: 0 | P23: End. | Q23: Kap. | R23: =IF(N23="",0,1) -> 1 | S23: =IF(N23="",1,0) -> 0
A24: 44582 | G24: 184.438 | H24: 4140 | I24: =IF(D24="","",+(E24-E23)*4140) | J24: =IF(E24="","",+(F24-F23)*4140) | K24: =IF(J24="","",+(J24/I24)) | L24: =IF(F24="","",+(F24-F23)*4140) | M24: =IF(L24="","",(L24/I24)) | N24: 66068309 | O24: 0 | P24: =IF(J3="",0,+SUM(J3:J33)/SUM(I3:I33)) -> 0.013759707 | Q24: =IF(L3="",0,+SUM(L3:L33)/SUM(I3:I33)) -> 0.013759707 | R24: =IF(N24="",0,1) -> 1 | S24: =IF(N24="",1,0) -> 0
A25: 44583 | G25: 184.483 | H25: 4140 | I25: =IF(D25="","",+(E25-E24)*4140) | J25: =IF(E25="","",+(F25-F24)*4140) | K25: =IF(J25="","",+(J25/I25)) | L25: =IF(F25="","",+(F25-F24)*4140) | M25: =IF(L25="","",(L25/I25)) | N25: 66068309 | O25: 0 | P25: =IF(J3="",0,+(+(LOOKUP(9.99999999999999E+307,E3:E33)-E2))/(+(LOOKUP(9.99999999999999E+307,D3:D33)-D2))) -> -0.34678253 | Q25: =IF(L3="",0,+(+(LOOKUP(9.99999999999999E+307,F3:F33)-F2))/(+(LOOKUP(9.99999999999999E+307,D3:D33)-D2))) -> 0.02181448 | R25: =IF(N25="",0,1) -> 1 | S25: =IF(N25="",1,0) -> 0
A26: 44584 | G26: 184.538 | H26: 4140 | I26: =IF(D26="","",+(E26-E25)*4140) | J26: =IF(E26="","",+(F26-F25)*4140) | K26: =IF(J26="","",+(J26/I26)) | L26: =IF(F26="","",+(F26-F25)*4140) | M26: =IF(L26="","",(L26/I26)) | N26: 66068309 | O26: 0 | P26: Cat Aylık | Q26: Cat Günlük | R26: =IF(N26="",0,1) -> 1 | S26: =IF(N26="",1,0) -> 0
A27: 44585 | G27: 184.571 | H27: 4140 | I27: =IF(D27="","",+(E27-E26)*4140) | J27: =IF(E27="","",+(F27-F26)*4140) | K27: =IF(J27="","",+(J27/I27)) | L27: =IF(F27="","",+(F27-F26)*4140) | M27: =IF(L27="","",(L27/I27)) | N27: 66068309 | O27: 0 | P27: =IF(N2="",0,+(LOOKUP(9.99999999999999E+307,N2:N33)-N2)) -> 0 | Q27: =IF(P27="",0,+P27/SUM(R3:R33)) -> 0 | R27: =IF(N27="",0,1) -> 1 | S27: =IF(N27="",1,0) -> 0
A28: 44586 | G28: 184.61 | H28: 4140 | I28: =IF(D28="","",+(E28-E27)*4140) | J28: =IF(E28="","",+(F28-F27)*4140) | K28: =IF(J28="","",+(J28/I28)) | L28: =IF(F28="","",+(F28-F27)*4140) | M28: =IF(L28="","",(L28/I28)) | N28: 66068309 | O28: 0 | P28: Bedaş Aylık | Q28: Bedaş Günlük | R28: =IF(N28="",0,1) -> 1 | S28: =IF(N28="",1,0) -> 0
A29: 44587 | G29: 184.662 | H29: 4140 | I29: =IF(D29="","",+(E29-E28)*4140) | J29: =IF(E29="","",+(F29-F28)*4140) | K29: =IF(J29="","",+(J29/I29)) | L29: =IF(F29="","",+(F29-F28)*4140) | M29: =IF(L29="","",(L29/I29)) | N29: 66068309 | O29: 0 | P29: =IF(D3="",0,+(LOOKUP(9.99999999999999E+307,D2:D33)-D2))*4140 -> -20394944 | Q29: =IF(P29="",0,+P29/SUM(R3:R33)) -> -784420.93 | R29: =IF(N29="",0,1) -> 1 | S29: =IF(N29="",1,0) -> 0
A30: 44588 | G30: 184.722 | H30: 4140 | I30: =IF(D30="","",+(E30-E29)*4140) | J30: =IF(E30="","",+(F30-F29)*4140) | K30: =IF(J30="","",+(J30/I30)) | L30: =IF(F30="","",+(F30-F29)*4140) | M30: =IF(L30="","",(L30/I30)) | N30: 66068309 | O30: 0 | P30: Tüketim TL | Q30: Cat Birim TL | R30: =IF(N30="",0,1) -> 1 | S30: =IF(N30="",1,0) -> 0
A31: 44589 | G31: 184.769 | H31: 4140 | I31: =IF(D31="","",+(E31-E30)*4140) | J31: =IF(E31="","",+(F31-F30)*4140) | K31: =IF(J31="","",+(J31/I31)) | L31: =IF(F31="","",+(F31-F30)*4140) | M31: =IF(L31="","",(L31/I31)) | N31: 66068309 | O31: 0 | P31: =P29*Q34 -> -11625118 | Q31: =IF(Q34="",0,(SUM('[1]Günlük Tüketim'!H4:H34)*1.62)/SUM(O3:O33)) -> #DIV/0! | R31: =IF(N31="",0,1) -> 1 | S31: =IF(N31="",1,0) -> 0
A32: 44590 | G32: 184.81 | H32: 4140 | I32: =IF(D32="","",+(E32-E31)*4140) | J32: =IF(E32="","",+(F32-F31)*4140) | K32: =IF(J32="","",+(J32/I32)) | L32: =IF(F32="","",+(F32-F31)*4140) | M32: =IF(L32="","",(L32/I32)) | N32: 66068309 | O32: 0 | P32: Top. Tüketim TL | Q32: Top. Bedaş kWh | R32: =IF(N32="",0,1) -> 1 | S32: =IF(N32="",1,0) -> 0
A33: 44591 | G33: 184.857 | H33: 4140 | I33: =IF(D33="","",+(E33-E32)*4140) | N33: 66068309 | O33: 0 | P33: =(P31+Q29*SUM(S3:S33)*Q34) -> -11625118 | Q33: =Q29*31 -> -24317049 | R33: =IF(N33="",0,1) -> 1 | S33: =IF(N33="",1,0) -> 0
A34: 44592 | G34: 184.89 | H34: 4140 | N34: 66068309 | O34: 0 | P34: Bedaş Birim | Q34: 0.57 | R34: =IF(N34="",0,1) -> 1 | S34: =IF(N34="",1,0) -> 0
A35: 44593 | G35: 184.919 | H35: 4140 | N35: 66068309 | O35: 0 | R35: =IF(N35="",0,1) -> 1 | S35: =IF(N35="",1,0) -> 0
A36: 44594 | G36: 184.967 | H36: 4140 | N36: 66068309 | O36: 0 | R36: =IF(N36="",0,1) -> 1 | S36: =IF(N36="",1,0) -> 0
A37: 44595 | G37: 185.077 | H37: 4140 | N37: 66068309 | O37: 0 | R37: =IF(N37="",0,1) -> 1 | S37: =IF(N37="",1,0) -> 0
A38: 44596 | G38: 185.119 | H38: 4140 | N38: 66068309 | O38: 0 | R38: =IF(N38="",0,1) -> 1 | S38: =IF(N38="",1,0) -> 0
A39: 44597 | G39: 185.148 | H39: 4140 | N39: 66068309 | O39: 0 | R39: =IF(N39="",0,1) -> 1 | S39: =IF(N39="",1,0) -> 0
A40: 44598 | G40: 185.192 | H40: 4140 | N40: 66068309 | O40: 0 | R40: =IF(N40="",0,1) -> 1 | S40: =IF(N40="",1,0) -> 0
...
