Workbook

Sheet TOTAL
A1: Site Name | B1: Day | C1: Month | D1: Year | E1: Total Electricity Kwh | F1: Electricity Tariff ($/Kwh) | G1: LPG (Kg) | H1: LPG $/Kg | I1: Water Utility Supply (m3) m3 | J1: Water Utility Supply (m3) $/m3 | K1: Room Nights | N1: Water Tanks | O1: Cost of Water Tanks Rs | P1: Water Utility Supply (m3) Rs/m3 | Q1: Electricity Tariff (Rs/Kwh) | R1: LPG Rs/Kg | S1: Exchange Rate | T1: Total LPG Cost | U1: Total Water Cost
A2: Mauritius at Anahita | B2: 1 | C2: 11 | D2: 2021 | E2: =HOTEL!E4 -> 20103 | F2: 6.21 | G2: =HOTEL!CK4 -> 80 | H2: 57.45 | I2: =HOTEL!V4+HOTEL!Y4 -> 525 | J2: =P2 -> 41.474453 | K2: =HOTEL!EE4 -> 0 | N2: =HOTEL!Y4/25 -> 6.4 | O2: =N2*2500 -> 16000 | P2: =IFERROR(((((HOTEL!V4*34))+(N2*2500))/(I2+N2*25)),0) -> 41.474453 | Q2: 6.21 | R2: =H2 -> 57.45 | S2: 33.88 | T2: =G2*H2 -> 4596 | U2: =I2*P2 -> 21774.088
A3: Mauritius at Anahita | B3: =B2+1 -> 2 | C3: 11 | D3: 2021 | E3: =HOTEL!E5 -> 20249 | F3: 6.21 | G3: =HOTEL!CK5 -> 75 | H3: 57.45 | I3: =HOTEL!V5+HOTEL!Y5 -> 542 | J3: =P3 -> 43.238845 | K3: =HOTEL!EE5 -> 0 | N3: =HOTEL!Y5/25 -> 8.8 | O3: =N3*2500 -> 22000 | P3: =IFERROR(((((HOTEL!V5*34))+(N3*2500))/(I3+N3*25)),0) -> 43.238845 | Q3: 6.21 | R3: =H3 -> 57.45 | S3: 33.88 | T3: =G3*H3 -> 4308.75 | U3: =I3*P3 -> 23435.454
A4: Mauritius at Anahita | B4: =B3+1 -> 3 | C4: 11 | D4: 2021 | E4: =HOTEL!E6 -> 21582 | F4: 6.21 | G4: =HOTEL!CK6 -> 71 | H4: 57.45 | I4: =HOTEL!V6+HOTEL!Y6 -> 602 | J4: =P4 -> 44.15873 | K4: =HOTEL!EE6 -> 0 | N4: =HOTEL!Y6/25 -> 11.2 | O4: =N4*2500 -> 28000 | P4: =IFERROR(((((HOTEL!V6*34))+(N4*2500))/(I4+N4*25)),0) -> 44.15873 | Q4: 6.21 | R4: =H4 -> 57.45 | S4: 33.88 | T4: =G4*H4 -> 4078.95 | U4: =I4*P4 -> 26583.556
A5: Mauritius at Anahita | B5: =B4+1 -> 4 | C5: 11 | D5: 2021 | E5: =HOTEL!E7 -> 21582 | F5: 6.21 | G5: =HOTEL!CK7 -> 67 | H5: 57.45 | I5: =HOTEL!V7+HOTEL!Y7 -> 604 | J5: =P5 -> 46.749004 | K5: =HOTEL!EE7 -> 0 | N5: =HOTEL!Y7/25 -> 16 | O5: =N5*2500 -> 40000 | P5: =IFERROR(((((HOTEL!V7*34))+(N5*2500))/(I5+N5*25)),0) -> 46.749004 | Q5: 6.21 | R5: =H5 -> 57.45 | S5: 33.88 | T5: =G5*H5 -> 3849.15 | U5: =I5*P5 -> 28236.398
A6: Mauritius at Anahita | B6: =B5+1 -> 5 | C6: 11 | D6: 2021 | E6: =HOTEL!E8 -> 22314 | F6: 6.21 | G6: =HOTEL!CK8 -> 85 | H6: 57.45 | I6: =HOTEL!V8+HOTEL!Y8 -> 435 | J6: =P6 -> 48.490566 | K6: =HOTEL!EE8 -> 0 | N6: =HOTEL!Y8/25 -> 14.4 | O6: =N6*2500 -> 36000 | P6: =IFERROR(((((HOTEL!V8*34))+(N6*2500))/(I6+N6*25)),0) -> 48.490566 | Q6: 6.21 | R6: =H6 -> 57.45 | S6: 33.88 | T6: =G6*H6 -> 4883.25 | U6: =I6*P6 -> 21093.396
A7: Mauritius at Anahita | B7: =B6+1 -> 6 | C7: 11 | D7: 2021 | E7: =HOTEL!E9 -> 21744 | F7: 6.21 | G7: =HOTEL!CK9 -> 80 | H7: 57.45 | I7: =HOTEL!V9+HOTEL!Y9 -> 298 | J7: =P7 -> 48.275093 | K7: =HOTEL!EE9 -> 0 | N7: =HOTEL!Y9/25 -> 9.6 | O7: =N7*2500 -> 24000 | P7: =IFERROR(((((HOTEL!V9*34))+(N7*2500))/(I7+N7*25)),0) -> 48.275093 | Q7: 6.21 | R7: =H7 -> 57.45 | S7: 33.88 | T7: =G7*H7 -> 4596 | U7: =I7*P7 -> 14385.978
A8: Mauritius at Anahita | B8: =B7+1 -> 7 | C8: 11 | D8: 2021 | E8: =HOTEL!E10 -> 19925 | F8: 6.21 | G8: =HOTEL!CK10 -> 80 | H8: 57.45 | I8: =HOTEL!V10+HOTEL!Y10 -> 490 | J8: =P8 -> 45.636364 | K8: =HOTEL!EE10 -> 0 | N8: =HOTEL!Y10/25 -> 11.2 | O8: =N8*2500 -> 28000 | P8: =IFERROR(((((HOTEL!V10*34))+(N8*2500))/(I8+N8*25)),0) -> 45.636364 | Q8: 6.21 | R8: =H8 -> 57.45 | S8: 33.88 | T8: =G8*H8 -> 4596 | U8: =I8*P8 -> 22361.818
A9: Mauritius at Anahita | B9: =B8+1 -> 8 | C9: 11 | D9: 2021 | E9: =HOTEL!E11 -> 25533 | F9: 6.21 | G9: =HOTEL!CK11 -> 75 | H9: 57.45 | I9: =HOTEL!V11+HOTEL!Y11 -> 610 | J9: =P9 -> 46.673267 | K9: =HOTEL!EE11 -> 0 | N9: =HOTEL!Y11/25 -> 16 | O9: =N9*2500 -> 40000 | P9: =IFERROR(((((HOTEL!V11*34))+(N9*2500))/(I9+N9*25)),0) -> 46.673267 | Q9: 6.21 | R9: =H9 -> 57.45 | S9: 33.88 | T9: =G9*H9 -> 4308.75 | U9: =I9*P9 -> 28470.693
A10: Mauritius at Anahita | B10: =B9+1 -> 9 | C10: 11 | D10: 2021 | E10: =HOTEL!E12 -> 21694 | F10: 6.21 | G10: =HOTEL!CK12 -> 70 | H10: 57.45 | I10: =HOTEL!V12+HOTEL!Y12 -> 565.55556 | J10: =P10 -> 46.352232 | K10: =HOTEL!EE12 -> 0 | N10: =HOTEL!Y12/25 -> 14.222222 | O10: =N10*2500 -> 35555.556 | P10: =IFERROR(((((HOTEL!V12*34))+(N10*2500))/(I10+N10*25)),0) -> 46.352232 | Q10: 6.21 | R10: =H10 -> 57.45 | S10: 33.93 | T10: =G10*H10 -> 4021.5 | U10: =I10*P10 -> 26214.762
A11: Mauritius at Anahita | B11: =B10+1 -> 10 | C11: 11 | D11: 2021 | E11: =HOTEL!E13 -> 21141 | F11: 6.21 | G11: =HOTEL!CK13 -> 62 | H11: 57.45 | I11: =HOTEL!V13+HOTEL!Y13 -> 502 | J11: =P11 -> 44.350404 | K11: =HOTEL!EE13 -> 0 | N11: =HOTEL!Y13/25 -> 9.6 | O11: =N11*2500 -> 24000 | P11: =IFERROR(((((HOTEL!V13*34))+(N11*2500))/(I11+N11*25)),0) -> 44.350404 | Q11: 6.21 | R11: =H11 -> 57.45 | S11: 33.93 | T11: =G11*H11 -> 3561.9 | U11: =I11*P11 -> 22263.903
A12: Mauritius at Anahita | B12: =B11+1 -> 11 | C12: 11 | D12: 2021 | E12: =HOTEL!E14 -> 21174 | F12: 6.21 | G12: =HOTEL!CK14 -> 66 | H12: 57.45 | I12: =HOTEL!V14+HOTEL!Y14 -> 622 | J12: =P12 -> 45.731161 | K12: =HOTEL!EE14 -> 0 | N12: =HOTEL!Y14/25 -> 14.4 | O12: =N12*2500 -> 36000 | P12: =IFERROR(((((HOTEL!V14*34))+(N12*2500))/(I12+N12*25)),0) -> 45.731161 | Q12: 6.21 | R12: =H12 -> 57.45 | S12: 33.93 | T12: =G12*H12 -> 3791.7 | U12: =I12*P12 -> 28444.782
A13: Mauritius at Anahita | B13: =B12+1 -> 12 | C13: 11 | D13: 2021 | E13: =HOTEL!E15 -> 25715 | F13: 6.21 | G13: =HOTEL!CK15 -> 62 | H13: 57.45 | I13: =HOTEL!V15+HOTEL!Y15 -> 408.22222 | J13: =P13 -> 45.279521 | K13: =HOTEL!EE15 -> 0 | N13: =HOTEL!Y15/25 -> 8.8888889 | O13: =N13*2500 -> 22222.222 | P13: =IFERROR(((((HOTEL!V15*34))+(N13*2500))/(I13+N13*25)),0) -> 45.279521 | Q13: 6.21 | R13: =H13 -> 57.45 | S13: 33.93 | T13: =G13*H13 -> 3561.9 | U13: =I13*P13 -> 18484.107
A14: Mauritius at Anahita | B14: =B13+1 -> 13 | C14: 11 | D14: 2021 | E14: =HOTEL!E16 -> 22601 | F14: 6.21 | G14: =HOTEL!CK16 -> 60 | H14: 57.45 | I14: =HOTEL!V16+HOTEL!Y16 -> 410.22222 | J14: =P14 -> 45.243851 | K14: =HOTEL!EE16 -> 0 | N14: =HOTEL!Y16/25 -> 8.8888889 | O14: =N14*2500 -> 22222.222 | P14: =IFERROR(((((HOTEL!V16*34))+(N14*2500))/(I14+N14*25)),0) -> 45.243851 | Q14: 6.21 | R14: =H14 -> 57.45 | S14: 33.93 | T14: =G14*H14 -> 3447 | U14: =I14*P14 -> 18560.033
... A25: Mauritius at Anahita | B25: =B24+1 -> 24 | C25: 11 | D25: 2021 | E25: =HOTEL!E27 -> 25123 | F25: 6.21 | G25: =HOTEL!CK27 -> 83 | H25: 57.45 | I25: =HOTEL!V27+HOTEL!Y27 -> 547.66667 | J25: =P25 -> 44.478919 | K25: =HOTEL!EE27 -> 0 | N25: =HOTEL!Y27/25 -> 10.666667 | O25: =N25*2500 -> 26666.667 | P25: =IFERROR(((((HOTEL!V27*34))+(N25*2500))/(I25+N25*25)),0) -> 44.478919 | Q25: 6.21 | R25: =H25 -> 57.45 | S25: 33.93 | T25: =G25*H25 -> 4768.35 | U25: =I25*P25 -> 24359.622
A26: Mauritius at Anahita | B26: =B25+1 -> 25 | C26: 11 | D26: 2021 | E26: =HOTEL!E28 -> 23771 | F26: 6.21 | G26: =HOTEL!CK28 -> 80 | H26: 57.45 | I26: =HOTEL!V28+HOTEL!Y28 -> 511.11111 | J26: =P26 -> 13.304348 | K26: =HOTEL!EE28 -> 0 | N26: =HOTEL!X35 -> 0 | O26: =N26*2500 -> 0 | P26: =IFERROR(((((HOTEL!V28*34))+(N26*2500))/(I26+N26*25)),0) -> 13.304348 | Q26: 6.21 | R26: =H26 -> 57.45 | S26: 33.93 | T26: =G26*H26 -> 4596 | U26: =I26*P26 -> 6800
A27: Mauritius at Anahita | B27: =B26+1 -> 26 | C27: 11 | D27: 2021 | E27: =HOTEL!E29 -> 23330 | F27: 6.21 | G27: =HOTEL!CK29 -> 76 | H27: 57.45 | I27: =HOTEL!V29+HOTEL!Y29 -> 378.66667 | J27: =P27 -> 10.056338 | K27: =HOTEL!EE29 -> 0 | N27: =HOTEL!X36 -> 0 | O27: =N27*2500 -> 0 | P27: =IFERROR(((((HOTEL!V29*34))+(N27*2500))/(I27+N27*25)),0) -> 10.056338 | Q27: 6.21 | R27: =H27 -> 57.45 | S27: 33.93 | T27: =G27*H27 -> 4366.2 | U27: =I27*P27 -> 3808
A28: Mauritius at Anahita | B28: =B27+1 -> 27 | C28: 11 | D28: 2021 | E28: =HOTEL!E30 -> 23976 | F28: 6.21 | G28: =HOTEL!CK30 -> 75 | H28: 57.45 | I28: =HOTEL!V30+HOTEL!Y30 -> 742.55556 | J28: =P28 -> 17.719886 | K28: =HOTEL!EE30 -> 0 | N28: =HOTEL!X37 -> 0 | O28: =N28*2500 -> 0 | P28: =IFERROR(((((HOTEL!V30*34))+(N28*2500))/(I28+N28*25)),0) -> 17.719886 | Q28: 6.21 | R28: =H28 -> 57.45 | S28: 33.93 | T28: =G28*H28 -> 4308.75 | U28: =I28*P28 -> 13158
A29: Mauritius at Anahita | B29: =B28+1 -> 28 | C29: 11 | D29: 2021 | E29: =HOTEL!E31 -> 24774 | F29: 6.21 | G29: =HOTEL!CK31 -> 70 | H29: 57.45 | I29: =HOTEL!V31+HOTEL!Y31 -> 778.66667 | J29: =P29 -> 13.623288 | K29: =HOTEL!EE31 -> 0 | N29: =HOTEL!X38 -> 0 | O29: =N29*2500 -> 0 | P29: =IFERROR(((((HOTEL!V31*34))+(N29*2500))/(I29+N29*25)),0) -> 13.623288 | Q29: 6.21 | R29: =H29 -> 57.45 | S29: 33.93 | T29: =G29*H29 -> 4021.5 | U29: =I29*P29 -> 10608
A30: Mauritius at Anahita | B30: =B29+1 -> 29 | C30: 11 | D30: 2021 | E30: =HOTEL!E32 -> 25054 | F30: 6.21 | G30: =HOTEL!CK32 -> 68 | H30: 57.45 | I30: =HOTEL!V32+HOTEL!Y32 -> 623.11111 | J30: =P30 -> 17.024251 | K30: =HOTEL!EE32 -> 0 | N30: =HOTEL!X39 -> 0 | O30: =N30*2500 -> 0 | P30: =IFERROR(((((HOTEL!V32*34))+(N30*2500))/(I30+N30*25)),0) -> 17.024251 | Q30: 6.21 | R30: =H30 -> 57.45 | T30: =G30*H30 -> 3906.6 | U30: =I30*P30 -> 10608
A31: Mauritius at Anahita | B31: =B30+1 -> 30 | C31: 11 | D31: 2021 | E31: =HOTEL!E33 -> 22951 | F31: 6.21 | G31: =HOTEL!CK33 -> 65 | H31: 57.45 | I31: =HOTEL!V33+HOTEL!Y33 -> 470.22222 | J31: =P31 -> 17.931947 | K31: =HOTEL!EE33 -> 0 | N31: =HOTEL!X40 -> 0 | O31: =N31*2500 -> 0 | P31: =IFERROR(((((HOTEL!V33*34))+(N31*2500))/(I31+N31*25)),0) -> 17.931947 | Q31: 6.21 | R31: =H31 -> 57.45 | T31: =G31*H31 -> 3734.25 | U31: =I31*P31 -> 8432

Sheet Submetering
A1: Site Name | B1: Day | C1: Month | D1: Year | E1: Hotel (KWh) | F1: Vacoas (KWh) | G1: Laundry (KWh) | H1: Villa 145 (KWh) | I1: Villa 146 (KWh) | J1: Villa 111 (KWh) | K1: Villa 128 (KWh) | L1: Hotel (m3) | M1: Bamboo Pool (m3) | N1: Island (m3) | O1: Main Building (m3) | P1: Pantry A (m3) | Q1: Pantry B (m3) | R1: Pantry C (m3) | S1: Pantry D (m3) | T1: Pantry E (m3) | U1: Pantry F (m3) | V1: Pantry G (m3) | W1: North Parcel (m3) | X1: South Parcel (m3) | Y1: Beau champ (Kg) | Z1: Acquapazza (Kg) | AA1: Bamboo (Kg) | AB1: Steam Boiler (Kg) | AC1: Laundry (Kg) | AD1: Pantry A (Kg) | AE1: Pantry B (Kg) | AF1: Pantry C (Kg) | AG1: Pantry D (Kg) | AH1: Pantry E (Kg) | AI1: Pantry F (Kg) | AJ1: Pantry G (Kg) | AK1: Room Nights
A2: Mauritius at Anahita | B2: =TOTAL!B2 -> 1 | C2: =TOTAL!C2 -> 11 | D2: 2021 | E2: =TOTAL!E2 -> 20103 | F2: =HOTEL!R4 -> 1286 | G2: =HOTEL!T4 -> 446 | H2: =HOTEL!DX4 -> 7 | I2: =HOTEL!DZ4 -> 0 | J2: =HOTEL!EB4 -> 0 | K2: =HOTEL!ED4 -> 0 | L2: =N2+W2+X2 -> 352 | M2: =HOTEL!AE4 -> 1153 | N2: =HOTEL!AI4 -> 0 | O2: =HOTEL!AM4 -> 1333 | P2: =HOTEL!AO4 -> 53345 | Q2: =HOTEL!AQ4 -> 9005 | R2: =HOTEL!AS4 -> 10684 | S2: =HOTEL!AU4 -> 15197 | T2: =HOTEL!AW4 -> 19580 | U2: =HOTEL!AY4 -> 20766 | V2: =HOTEL!BA4 -> 13975 | W2: =HOTEL!BM4 -> 22 | X2: =HOTEL!BT4 -> 330 | Y2: =HOTEL!CO4 -> 0 | Z2: =HOTEL!CR3 -> #VALUE! | AA2: =HOTEL!CU4 -> 14.64 | AB2: =HOTEL!CX4 -> 53.68 | AC2: =HOTEL!DA4 -> 2037443.9 | AD2: =HOTEL!DD4 -> 23.9 | AE2: =HOTEL!DG4 -> 0 | AF2: =HOTEL!DJ4 -> 0 | AG2: =HOTEL!DM4 -> 0 | AH2: =HOTEL!DP4 -> 0 | AI2: =HOTEL!DS4 -> 0 | AJ2: =HOTEL!DV4 -> 0 | AK2: =TOTAL!K2 -> 0
A3: Mauritius at Anahita | B3: =TOTAL!B3 -> 2 | C3: =TOTAL!C3 -> 11 | D3: 2021 | E3: =TOTAL!E3 -> 20249 | F3: =HOTEL!R5 -> 1016 | G3: =HOTEL!T5 -> 476 | H3: =HOTEL!DX5 -> 6 | I3: =HOTEL!DZ5 -> 0 | J3: =HOTEL!EB5 -> 0 | K3: =HOTEL!ED5 -> 0 | L3: =N3+W3+X3 -> 299 | M3: =HOTEL!AE5 -> 1152 | N3: =HOTEL!AI5 -> 0 | O3: =HOTEL!AM5 -> 1334 | P3: =HOTEL!AO5 -> 53364 | Q3: =HOTEL!AQ5 -> 9006 | R3: =HOTEL!AS5 -> 10688 | S3: =HOTEL!AU5 -> 15212 | T3: =HOTEL!AW5 -> 19598 | U3: =HOTEL!AY5 -> 20767 | V3: =HOTEL!BA5 -> 13978 | W3: =HOTEL!BM5 -> 19 | X3: =HOTEL!BT5 -> 280 | Y3: =HOTEL!CO5 -> 0 | Z3: =HOTEL!CR4 -> 104.92 | AA3: =HOTEL!CU5 -> 14.64 | AB3: =HOTEL!CX5 -> 58.56 | AC3: =HOTEL!DA5 -> 375.76 | AD3: =HOTEL!DD5 -> 19.12 | AE3: =HOTEL!DG5 -> 0 | AF3: =HOTEL!DJ5 -> 0 | AG3: =HOTEL!DM5 -> 0 | AH3: =HOTEL!DP5 -> 0 | AI3: =HOTEL!DS5 -> 4 | AJ3: =HOTEL!DV5 -> 0 | AK3: =TOTAL!K3 -> 0
A4: Mauritius at Anahita | B4: =TOTAL!B4 -> 3 | C4: =TOTAL!C4 -> 11 | D4: 2021 | E4: =TOTAL!E4 -> 21582 | F4: =HOTEL!R6 -> 863 | G4: =HOTEL!T6 -> 476 | H4: =HOTEL!DX6 -> 7 | I4: =HOTEL!DZ6 -> 0 | J4: =HOTEL!EB6 -> 0 | K4: =HOTEL!ED6 -> 0 | L4: =N4+W4+X4 -> 253 | M4: =HOTEL!AE6 -> 1153 | N4: =HOTEL!AI6 -> 0 | O4: =HOTEL!AM6 -> 1335 | P4: =HOTEL!AO6 -> 53383 | Q4: =HOTEL!AQ6 -> 9007 | R4: =HOTEL!AS6 -> 10690 | S4: =HOTEL!AU6 -> 15228 | T4: =HOTEL!AW6 -> 19598 | U4: =HOTEL!AY6 -> 20770 | V4: =HOTEL!BA6 -> 13982 | W4: =HOTEL!BM6 -> 23 | X4: =HOTEL!BT6 -> 230 | Y4: =HOTEL!CO6 -> 0 | Z4: =HOTEL!CR5 -> 97.6 | AA4: =HOTEL!CU6 -> 19.52 | AB4: =HOTEL!CX6 -> 73.2 | AC4: =HOTEL!DA6 -> 375.76 | AD4: =HOTEL!DD6 -> 19.12 | AE4: =HOTEL!DG6 -> 0 | AF4: =HOTEL!DJ6 -> 0 | AG4: =HOTEL!DM6 -> 1 | AH4: =HOTEL!DP6 -> 0 | AI4: =HOTEL!DS6 -> 0 | AJ4: =HOTEL!DV6 -> 0 | AK4: =TOTAL!K4 -> 0
A5: Mauritius at Anahita | B5: =TOTAL!B5 -> 4 | C5: =TOTAL!C5 -> 11 | D5: 2021 | E5: =TOTAL!E5 -> 21582 | F5: =HOTEL!R7 -> 863 | G5: =HOTEL!T7 -> 468 | H5: =HOTEL!DX7 -> 6 | I5: =HOTEL!DZ7 -> 0 | J5: =HOTEL!EB7 -> 0 | K5: =HOTEL!ED7 -> 0 | L5: =N5+W5+X5 -> 249 | M5: =HOTEL!AE7 -> 1153 | N5: =HOTEL!AI7 -> 0 | O5: =HOTEL!AM7 -> 1336 | P5: =HOTEL!AO7 -> 53402 | Q5: =HOTEL!AQ7 -> 9007 | R5: =HOTEL!AS7 -> 10693 | S5: =HOTEL!AU7 -> 15244 | T5: =HOTEL!AW7 -> 19606 | U5: =HOTEL!AY7 -> 20771 | V5: =HOTEL!BA7 -> 13984 | W5: =HOTEL!BM7 -> 19 | X5: =HOTEL!BT7 -> 230 | Y5: =HOTEL!CO7 -> 0 | Z5: =HOTEL!CR6 -> 124.44 | AA5: =HOTEL!CU7 -> 14.64 | AB5: =HOTEL!CX7 -> 0 | AC5: =HOTEL!DA7 -> 0 | AD5: =HOTEL!DD7 -> 21.51 | AE5: =HOTEL!DG7 -> 1 | AF5: =HOTEL!DJ7 -> 1 | AG5: =HOTEL!DM7 -> 0 | AH5: =HOTEL!DP7 -> 1 | AI5: =HOTEL!DS7 -> 0 | AJ5: =HOTEL!DV7 -> 1 | AK5: =TOTAL!K5 -> 0
A6: Mauritius at Anahita | B6: =TOTAL!B6 -> 5 | C6: =TOTAL!C6 -> 11 | D6: 2021 | E6: =TOTAL!E6 -> 22314 | F6: =HOTEL!R8 -> 3669 | G6: =HOTEL!T8 -> 501 | H6: =HOTEL!DX8 -> 6 | I6: =HOTEL!DZ8 -> 0 | J6: =HOTEL!EB8 -> 0 | K6: =HOTEL!ED8 -> 0 | L6: =N6+W6+X6 -> 261 | M6: =HOTEL!AE8 -> 1153 | N6: =HOTEL!AI8 -> 0 | O6: =HOTEL!AM8 -> 1337 | P6: =HOTEL!AO8 -> 53420 | Q6: =HOTEL!AQ8 -> 9007 | R6: =HOTEL!AS8 -> 10695 | S6: =HOTEL!AU8 -> 15260 | T6: =HOTEL!AW8 -> 19617 | U6: =HOTEL!AY8 -> 20773 | V6: =HOTEL!BA8 -> 13987 | W6: =HOTEL!BM8 -> 21 | X6: =HOTEL!BT8 -> 240 | Y6: =HOTEL!CO8 -> 6476 | Z6: =HOTEL!CR7 -> 90.28 | AA6: =HOTEL!CU8 -> 17.08 | AB6: =HOTEL!CX8 -> 0 | AC6: =HOTEL!DA8 -> 24568.36 | AD6: =HOTEL!DD8 -> 19.12 | AE6: =HOTEL!DG8 -> 0 | AF6: =HOTEL!DJ8 -> 0 | AG6: =HOTEL!DM8 -> 0 | AH6: =HOTEL!DP8 -> 0 | AI6: =HOTEL!DS8 -> 2 | AJ6: =HOTEL!DV8 -> 0 | AK6: =TOTAL!K6 -> 0
A7: Mauritius at Anahita | B7: =TOTAL!B7 -> 6 | C7: =TOTAL!C7 -> 11 | D7: 2021 | E7: =TOTAL!E7 -> 21744 | F7: =HOTEL!R9 -> 1198 | G7: =HOTEL!T9 -> 438 | H7: =HOTEL!DX9 -> 6 | I7: =HOTEL!DZ9 -> 0 | J7: =HOTEL!EB9 -> 0 | K7: =HOTEL!ED9 -> 0 | L7: =N7+W7+X7 -> 321 | M7: =HOTEL!AE9 -> 1153 | N7: =HOTEL!AI9 -> 0 | O7: =HOTEL!AM9 -> 1339 | P7: =HOTEL!AO9 -> 53438 | Q7: =HOTEL!AQ9 -> 9008 | R7: =HOTEL!AS9 -> 10697 | S7: =HOTEL!AU9 -> 15275 | T7: =HOTEL!AW9 -> 19621 | U7: =HOTEL!AY9 -> 20775 | V7: =HOTEL!BA9 -> 13991 | W7: =HOTEL!BM9 -> 21 | X7: =HOTEL!BT9 -> 300 | Y7: =HOTEL!CO9 -> 0 | Z7: =HOTEL!CR8 -> 114.68 | AA7: =HOTEL!CU9 -> 14.64 | AB7: =HOTEL!CX9 -> 56.12 | AC7: =HOTEL!DA9 -> 151.28 | AD7: =HOTEL!DD9 -> 16.73 | AE7: =HOTEL!DG9 -> 0 | AF7: =HOTEL!DJ9 -> 0 | AG7: =HOTEL!DM9 -> 0 | AH7: =HOTEL!DP9 -> 0 | AI7: =HOTEL!DS9 -> 0 | AJ7: =HOTEL!DV9 -> 1 | AK7: =TOTAL!K7 -> 0
A8: Mauritius at Anahita | B8: =TOTAL!B8 -> 7 | C8: =TOTAL!C8 -> 11 | D8: 2021 | E8: =TOTAL!E8 -> 19925 | F8: =HOTEL!R10 -> 960 | G8: =HOTEL!T10 -> 436 | H8: =HOTEL!DX10 -> 6 | I8: =HOTEL!DZ10 -> 0 | J8: =HOTEL!EB10 -> 0 | K8: =HOTEL!ED10 -> 0 | L8: =N8+W8+X8 -> 288 | M8: =HOTEL!AE10 -> 1153 | N8: =HOTEL!AI10 -> 0 | O8: =HOTEL!AM10 -> 1339 | P8: =HOTEL!AO10 -> 53452 | Q8: =HOTEL!AQ10 -> 9011 | R8: =HOTEL!AS10 -> 10699 | S8: =HOTEL!AU10 -> 15288 | T8: =HOTEL!AW10 -> 19627 | U8: =HOTEL!AY10 -> 20777 | V8: =HOTEL!BA10 -> 13994 | W8: =HOTEL!BM10 -> 18 | X8: =HOTEL!BT10 -> 270 | Y8: =HOTEL!CO10 -> 0 | Z8: =HOTEL!CR9 -> 97.6 | AA8: =HOTEL!CU10 -> 14.64 | AB8: =HOTEL!CX10 -> 56.12 | AC8: =HOTEL!DA10 -> 129.32 | AD8: =HOTEL!DD10 -> 19.12 | AE8: =HOTEL!DG10 -> 0 | AF8: =HOTEL!DJ10 -> 0 | AG8: =HOTEL!DM10 -> 0 | AH8: =HOTEL!DP10 -> 0 | AI8: =HOTEL!DS10 -> 2 | AJ8: =HOTEL!DV10 -> 0 | AK8: =TOTAL!K8 -> 0
A9: Mauritius at Anahita | B9: =TOTAL!B9 -> 8 | C9: =TOTAL!C9 -> 11 | D9: 2021 | E9: =TOTAL!E9 -> 25533 | F9: =HOTEL!R11 -> 2295 | G9: =HOTEL!T11 -> 462 | H9: =HOTEL!DX11 -> 6 | I9: =HOTEL!DZ11 -> 0 | J9: =HOTEL!EB11 -> 0 | K9: =HOTEL!ED11 -> 0 | L9: =N9+W9+X9 -> 245 | M9: =HOTEL!AE11 -> 1153 | N9: =HOTEL!AI11 -> 0 | O9: =HOTEL!AM11 -> 1319 | P9: =HOTEL!AO11 -> 53476 | Q9: =HOTEL!AQ11 -> 9012 | R9: =HOTEL!AS11 -> 10700 | S9: =HOTEL!AU11 -> 15298 | T9: =HOTEL!AW11 -> 19633 | U9: =HOTEL!AY11 -> 20779 | V9: =HOTEL!BA11 -> 13997 | W9: =HOTEL!BM11 -> 15 | X9: =HOTEL!BT11 -> 230 | Y9: =HOTEL!CO11 -> 0 | Z9: =HOTEL!CR10 -> 102.48 | AA9: =HOTEL!CU11 -> 19.52 | AB9: =HOTEL!CX11 -> 48.8 | AC9: =HOTEL!DA11 -> 158.6 | AD9: =HOTEL!DD11 -> 21.51 | AE9: =HOTEL!DG11 -> 0 | AF9: =HOTEL!DJ11 -> 0 | AG9: =HOTEL!DM11 -> 0 | AH9: =HOTEL!DP11 -> 1 | AI9: =HOTEL!DS11 -> 2 | AJ9: =HOTEL!DV11 -> 0 | AK9: =TOTAL!K9 -> 0
A10: Mauritius at Anahita | B10: =TOTAL!B10 -> 9 | C10: =TOTAL!C10 -> 11 | D10: 2021 | E10: =TOTAL!E10 -> 21694 | F10: =HOTEL!R12 -> 1053 | G10: =HOTEL!T12 -> 436 | H10: =HOTEL!DX12 -> 7 | I10: =HOTEL!DZ12 -> 0 | J10: =HOTEL!EB12 -> 0 | K10: =HOTEL!ED12 -> 0 | L10: =N10+W10+X10 -> 238 | M10: =HOTEL!AE12 -> 1153 | N10: =HOTEL!AI12 -> 0 | O10: =HOTEL!AM12 -> 1343 | P10: =HOTEL!AO12 -> 53496 | Q10: =HOTEL!AQ12 -> 9013 | R10: =HOTEL!AS12 -> 10702 | S10: =HOTEL!AU12 -> 15311 | T10: =HOTEL!AW12 -> 19639 | U10: =HOTEL!AY12 -> 20781 | V10: =HOTEL!BA12 -> 14000 | W10: =HOTEL!BM12 -> 18 | X10: =HOTEL!BT12 -> 220 | Y10: =HOTEL!CO12 -> 0 | Z10: =HOTEL!CR11 -> 107.36 | AA10: =HOTEL!CU12 -> 12.2 | AB10: =HOTEL!CX12 -> 48.8 | AC10: =HOTEL!DA12 -> 134.2 | AD10: =HOTEL!DD12 -> 19.12 | AE10: =HOTEL!DG12 -> 0 | AF10: =HOTEL!DJ12 -> 0 | AG10: =HOTEL!DM12 -> 0 | AH10: =HOTEL!DP12 -> 0 | AI10: =HOTEL!DS12 -> 0 | AJ10: =HOTEL!DV12 -> 0 | AK10: =TOTAL!K10 -> 0
A11: Mauritius at Anahita | B11: =TOTAL!B11 -> 10 | C11: =TOTAL!C11 -> 11 | D11: 2021 | E11: =TOTAL!E11 -> 21141 | F11: =HOTEL!R13 -> 892 | G11: =HOTEL!T13 -> 462 | H11: =HOTEL!DX13 -> 6 | I11: =HOTEL!DZ13 -> 0 | J11: =HOTEL!EB13 -> 0 | K11: =HOTEL!ED13 -> 0 | L11: =N11+W11+X11 -> 258 | M11: =HOTEL!AE13 -> 1153 | N11: =HOTEL!AI13 -> 0 | O11: =HOTEL!AM13 -> 1345 | P11: =HOTEL!AO13 -> 53513 | Q11: =HOTEL!AQ13 -> 9016 | R11: =HOTEL!AS13 -> 10704 | S11: =HOTEL!AU13 -> 15324 | T11: =HOTEL!AW13 -> 19644 | U11: =HOTEL!AY13 -> 20783 | V11: =HOTEL!BA13 -> 14003 | W11: =HOTEL!BM13 -> 18 | X11: =HOTEL!BT13 -> 240 | Y11: =HOTEL!CO13 -> 0 | Z11: =HOTEL!CR12 -> 100.04 | AA11: =HOTEL!CU13 -> 14.64 | AB11: =HOTEL!CX13 -> 46.36 | AC11: =HOTEL!DA13 -> 0 | AD11: =HOTEL!DD13 -> 19.12 | AE11: =HOTEL!DG13 -> 0 | AF11: =HOTEL!DJ13 -> 1 | AG11: =HOTEL!DM13 -> 0 | AH11: =HOTEL!DP13 -> 1 | AI11: =HOTEL!DS13 -> 2 | AJ11: =HOTEL!DV13 -> 0 | AK11: =TOTAL!K11 -> 0
A12: Mauritius at Anahita | B12: =TOTAL!B12 -> 11 | C12: =TOTAL!C12 -> 11 | D12: 2021 | E12: =TOTAL!E12 -> 21174 | F12: =HOTEL!R14 -> 975 | G12: =HOTEL!T14 -> 432 | H12: =HOTEL!DX14 -> 5 | I12: =HOTEL!DZ14 -> 0 | J12: =HOTEL!EB14 -> 0 | K12: =HOTEL!ED14 -> 0 | L12: =N12+W12+X12 -> 257 | M12: =HOTEL!AE14 -> 1153 | N12: =HOTEL!AI14 -> 0 | O12: =HOTEL!AM14 -> 1347 | P12: =HOTEL!AO14 -> 53533 | Q12: =HOTEL!AQ14 -> 9018 | R12: =HOTEL!AS14 -> 10705 | S12: =HOTEL!AU14 -> 15336 | T12: =HOTEL!AW14 -> 19649 | U12: =HOTEL!AY14 -> 20785 | V12: =HOTEL!BA14 -> 14006 | W12: =HOTEL!BM14 -> 17 | X12: =HOTEL!BT14 -> 240 | Y12: =HOTEL!CO14 -> 0 | Z12: =HOTEL!CR13 -> 104.92 | AA12: =HOTEL!CU14 -> 12.2 | AB12: =HOTEL!CX14 -> 48.8 | AC12: =HOTEL!DA14 -> 422.12 | AD12: =HOTEL!DD14 -> 19.12 | AE12: =HOTEL!DG14 -> 1 | AF12: =HOTEL!DJ14 -> 0 | AG12: =HOTEL!DM14 -> 0 | AH12: =HOTEL!DP14 -> 0 | AI12: =HOTEL!DS14 -> 0 | AJ12: =HOTEL!DV14 -> 1 | AK12: =TOTAL!K12 -> 0
A13: Mauritius at Anahita | B13: =TOTAL!B13 -> 12 | C13: =TOTAL!C13 -> 11 | D13: 2021 | E13: =TOTAL!E13 -> 25715 | F13: =HOTEL!R15 -> 1781 | G13: =HOTEL!T15 -> 415 | H13: =HOTEL!DX15 -> 7 | I13: =HOTEL!DZ15 -> 0 | J13: =HOTEL!EB15 -> 0 | K13: =HOTEL!ED15 -> 0 | L13: =N13+W13+X13 -> 328 | M13: =HOTEL!AE15 -> 1153 | N13: =HOTEL!AI15 -> 0 | O13: =HOTEL!AM15 -> 1348 | P13: =HOTEL!AO15 -> 53551 | Q13: =HOTEL!AQ15 -> 9021 | R13: =HOTEL!AS15 -> 10707 | S13: =HOTEL!AU15 -> 15349 | T13: =HOTEL!AW15 -> 19658 | U13: =HOTEL!AY15 -> 20787 | V13: =HOTEL!BA15 -> 14009 | W13: =HOTEL!BM15 -> 18 | X13: =HOTEL!BT15 -> 310 | Y13: =HOTEL!CO15 -> 0 | Z13: =HOTEL!CR14 -> 126.88 | AA13: =HOTEL!CU15 -> 17.08 | AB13: =HOTEL!CX15 -> 51.24 | AC13: =HOTEL!DA15 -> 0 | AD13: =HOTEL!DD15 -> 21.51 | AE13: =HOTEL!DG15 -> 0 | AF13: =HOTEL!DJ15 -> 0 | AG13: =HOTEL!DM15 -> 0 | AH13: =HOTEL!DP15 -> 1 | AI13: =HOTEL!DS15 -> 0 | AJ13: =HOTEL!DV15 -> 0 | AK13: =TOTAL!K13 -> 0
... A31: Mauritius at Anahita | B31: =TOTAL!B31 -> 30 | C31: =TOTAL!C31 -> 11 | D31: 2021 | E31: =TOTAL!E31 -> 22951 | F31: =HOTEL!R33 -> 1501 | G31: =HOTEL!T33 -> 460 | H31: =HOTEL!DX33 -> 6 | I31: =HOTEL!DZ33 -> 0 | J31: =HOTEL!EB33 -> 0 | K31: =HOTEL!ED33 -> 0 | L31: =N31+W31+X31 -> 385 | M31: =HOTEL!AE33 -> 1157 | N31: =HOTEL!AI33 -> 0 | O31: =HOTEL!AM33 -> 1398 | P31: =HOTEL!AO33 -> 53897 | Q31: =HOTEL!AQ33 -> 9069 | R31: =HOTEL!AS33 -> 10744 | S31: =HOTEL!AU33 -> 15587 | T31: =HOTEL!AW33 -> 19786 | U31: =HOTEL!AY33 -> 20821 | V31: =HOTEL!BA33 -> 14063 | W31: =HOTEL!BM33 -> 15 | X31: =HOTEL!BT33 -> 370 | Y31: =HOTEL!CO33 -> 0 | Z31: =HOTEL!CR32 -> 122 | AA31: =HOTEL!CU33 -> 14.64 | AB31: =HOTEL!CX33 -> 51.24 | AC31: =HOTEL!DA33 -> 139.08 | AD31: =HOTEL!DD33 -> 21.51 | AE31: =HOTEL!DG33 -> 2 | AF31: =HOTEL!DJ33 -> 1 | AG31: =HOTEL!DM33 -> 0 | AH31: =HOTEL!DP33 -> 0 | AI31: =HOTEL!DS33 -> 0 | AJ31: =HOTEL!DV33 -> 0 | AK31: =TOTAL!K31 -> 0
A32: Mauritius at Anahita | B32: =TOTAL!B32 -> 0 | C32: =TOTAL!C32 -> 0 | D32: 2021 | E32: =TOTAL!E32 -> 0 | F32: =HOTEL!#REF! -> #REF! | G32: =HOTEL!#REF! -> #REF! | H32: =HOTEL!#REF! -> #REF! | I32: =HOTEL!#REF! -> #REF! | J32: =HOTEL!#REF! -> #REF! | K32: =HOTEL!#REF! -> #REF! | L32: =N32+W32+X32 -> #REF! | M32: =HOTEL!#REF! -> #REF! | N32: =HOTEL!#REF! -> #REF! | O32: =HOTEL!#REF! -> #REF! | P32: =HOTEL!#REF! -> #REF! | Q32: =HOTEL!#REF! -> #REF! | R32: =HOTEL!#REF! -> #REF! | S32: =HOTEL!#REF! -> #REF! | T32: =HOTEL!#REF! -> #REF! | ... Y32: =HOTEL!#REF! -> #REF! | Z32: =HOTEL!CR33 -> 117.12 | AA32: =HOTEL!#REF! -> #REF! | AB32: =HOTEL!#REF! -> #REF! | AC32: =HOTEL!#REF! -> #REF! | AD32: =HOTEL!#REF! -> #REF! | AE32: =HOTEL!#REF! -> #REF! | AF32: =HOTEL!#REF! -> #REF! | AG32: =HOTEL!#REF! -> #REF! | AH32: =HOTEL!#REF! -> #REF! | ... AJ32: =HOTEL!#REF! -> #REF! | AK32: =TOTAL!K32 -> 0

Sheet HOTEL
B1: Hotel Electricity | I1: Gen 01 | M1: Gen 02 | Q1: Vacoas KW | R1: CONS | S1: Laundry (KWh) | T1: CONS | U1: Hotel | W1: % Water Available | AB1: Water Softener | AD1: bamboo pool | AF1: laundry | AG1: CONS | AH1: Island | AJ1: Island Sub | AL1: Main Building | AN1: Pantry A | AP1: Pantry B | AR1: Pantry C | AT1: Pantry D | AV1: Pantry E | AX1: Pantry F | AZ1: Pantry G | BL1: North | BN1: North Sub | BP1: South | BR1: South Sub | BW1: Diesel | CA1: Gas | CV1: Steam Boiler | CY1: Main Building | DB1: Pantry A | DE1: Pantry B | DH1: Pantry C | DK1: Pantry D | DN1: Pantry E | DQ1: Pantry F | DT1: Pantry G | EH1: Pool Temperature
A2: Date | B2: KVAH | C2: CONS | D2: KWH | E2: CONS | F2: PF | G2: KVA | H2: KVA max | U2: CWA23 | V2: CONS | X2: Truck Meter | Y2: Cons | Z2: UV reading | AB2: chiller | AC2: CONS | AE2: CONS | AH2: island | AI2: cons | AL2: M.Buil | AM2: Cons | AN2: Pantry A | AO2: Cons | AP2: Pantry B | AQ2: Cons | AR2: Pantry C | AS2: cons | AT2: Pantry D | AU2: cons | AV2: Pantry E | AW2: cons | AX2: Pantry F | AY2: Cons | AZ2: Pantry G | BA2: Cons | BB2: Main Kitchen | BC2: Cons | BD2: Bamboo H | BE2: Cons | BF2: Bamboo C | BG2: Cons | BH2: cyclon bridge | BI2: cons | BJ2: Island - Hot | BK2: Island Cold | BL2: north | BM2: cons | BP2: south | BQ2: cons | BT2: south | BU2: Total water consump | BV2: Total HW consump | BW2: DIESEL | BX2: stock | BY2: Del | BZ2: CONS | CA2: Meter | CB2: cons | CC2: Kg | CD2: LPG 1 | CE2: stock | CF2: LPG 2 | CG2: stock | CH2: LPG 3 | CI2: stock | CJ2: total stock | CK2: cons | CL2: del | CM2: Beau champ | CN2: cons(Litres) | CO2: Cons(Kg) | CP2: Acquapazza | CQ2: cons(Litres) | CR2: Cons(Kg) | CS2: Bamboo | CT2: cons(Litres) | CU2: Cons(Kg) | CW2: cons(Litres) | CX2: Cons(Kg) | CZ2: cons(Litres) | DA2: Cons(Kg) | DC2: cons(Litres) | DD2: Cons(Kg) | DF2: cons(Litres) | DG2: Cons(Kg) | DI2: cons(Litres) | DJ2: Cons(Kg) | DL2: cons(Litres) | DM2: Cons(Kg) | DO2: cons(Litres) | DP2: Cons(Kg) | DR2: cons(Litres) | DS2: Cons(Kg) | DU2: cons(Litres) | DV2: Cons(Kg) | DW2: 145 | DX2: CONS | DY2: 146 | DZ2: CONS | EA2: Villa 111 | EB2: CONS | EC2: Villa 128 | ED2: CONS | EE2: Room Nights | EF2: Bed Nights | EG2: % OCC | EH2: California | EI2: Infiniti | EJ2: Fitness
A3: 44500 | B3: 8370481 | D3: 7537272 | G3: 552 | H3: 1022 | I3: 289262 | K3: 794 | L3: 0 | M3: 636988 | N3: 0 | O3: 1015 | Q3: 2603482 | S3: 2210856 | U3: 130940 | X3: 0.55555556 | Y3: 222.22222 | AC3: 429580 | AD3: #VALUE! | AE3: 1153 | AF3: #VALUE! | AG3: 4764 | AH3: 4764 | AK3: 593450 | AM3: 1332 | AN3: 1332 | AO3: 53323 | AP3: #VALUE! | AQ3: 9004 | AR3: #VALUE! | AS3: 10683 | AT3: #VALUE! | AU3: 15180 | AV3: #VALUE! | AW3: 19562 | AX3: #VALUE! | AY3: 20763 | AZ3: #VALUE! | BA3: 13973 | BB3: #VALUE! | BC3: 6317 | BD3: #VALUE! | BE3: 26863 | BF3: #VALUE! | BG3: 4529 | BH3: #VALUE! | BI3: 13927 | BJ3: #VALUE! | BK3: 3636 | BL3: #VALUE! | BO3: 612970 | BQ3: 1195 | BR3: 1195 | BS3: 798740 | BU3: 1127 | BV3: 1127 | BZ3: 110 | CA3: 13257.678 | CD3: 215042 | CG3: 81 | CH3: 8727.75 | CI3: 82 | CJ3: 8835.5 | CK3: 80 | CL3: 8620 | CM3: 26183.25 | CN3: #VALUE! | CP3: 36291 | CQ3: #VALUE! | CR3: #VALUE! | CS3: 34550 | CT3: #VALUE! | CU3: #VALUE! | CV3: 10828 | CW3: #VALUE! | CX3: #VALUE! | CY3: 834864 | CZ3: 834864 | DA3: 2037068.2 | DB3: 6631 | DC3: 6631 | DD3: 15848.09 | DE3: 7984 | DF3: 7984 | DG3: #VALUE! | DH3: 4671 | DI3: 4671 | DJ3: 2 | DK3: 1917 | DL3: 1917 | DM3: 1 | DN3: 5348 | DO3: 5348 | DP3: 1 | DQ3: 4909 | DR3: 4909 | DS3: 1 | DT3: 5681 | DU3: 5681 | DW3: 5624 | DX3: 5624 | DY3: 13441.36 | EH3: 111 | EI3: 322 | EJ3: 0.83
A4: 44501 | B4: 8390785 | C4: 20304 | D4: 7557375 | E4: 20103 | F4: 0.99010047 | G4: 970 | H4: 1022 | I4: 289262 | J4: 0 | K4: 794 | L4: 0 | M4: 636988 | N4: 0 | O4: 1015 | P4: 0 | Q4: 2604768 | R4: 1286 | S4: 2211302 | T4: 446 | U4: 131305 | V4: 365 | X4: 0.4 | Y4: 160 | Z4: 6 | AA4: 1580738 | AB4: 1580738 | AC4: 430006 | AD4: 426 | AE4: 1153 | AF4: 0 | AG4: 4764 | AH4: 0 | AK4: 593600 | AL4: 150 | AM4: 1333 | AN4: 1 | AO4: 53345 | AP4: 22 | AQ4: 9005 | AR4: 1 | AS4: 10684 | AT4: 1 | AU4: 15197 | AV4: 17 | AW4: 19580 | AX4: 18 | AY4: 20766 | AZ4: 3 | BA4: 13975 | BB4: 2 | BC4: 6319 | BD4: 2 | BE4: 26866 | BF4: 3 | BG4: 4535 | BH4: 6 | BI4: 14026 | BJ4: 99 | BK4: 3636 | BL4: 0 | BM4: 22 | BN4: 128 | BO4: 613110 | BP4: 140 | BQ4: 1215 | BR4: 20 | BS4: 799070 | BT4: 330 | BU4: 1141 | BV4: 14 | BW4: 180 | BX4: 470 | BY4: 72 | BZ4: 110 | CA4: 13257.678 | CC4: 0 | CD4: 215220 | CE4: 178 | CF4: 1016.38 | CG4: 78 | CH4: 8404.5 | CI4: 78 | CJ4: 8404.5 | CK4: 80 | CL4: 8620 | CM4: 25429 | CN4: 754.25 | CP4: 36334 | CQ4: 43 | CR4: 104.92 | CS4: 34556 | CT4: 6 | CU4: 14.64 | CV4: 10850 | CW4: 22 | CX4: 53.68 | CY4: 835018 | CZ4: 835018 | DA4: 2037443.9 | DB4: 6641 | DC4: 10 | DD4: 23.9 | DE4: 7994 | DF4: 10 | DG4: 0 | DH4: 4679 | DI4: 8 | DJ4: 0 | DK4: 1918 | DL4: 1 | DM4: 0 | DN4: 5359 | DO4: 11 | DP4: 0 | DQ4: 4917 | DR4: 8 | DS4: 0 | DT4: 5692 | DU4: 11 | DV4: 0 | DW4: 5631 | DX4: 7 | DY4: 16.73 | EA4: 0 | EC4: 0 | EE4: 0 | EG4: 0 | EH4: 110 | EI4: 317 | EJ4: 0.83
A5: 44502 | B5: 8411223 | C5: 20438 | D5: 7577624 | E5: 20249 | F5: 0.99075252 | G5: 984 | H5: 1022 | I5: 289262 | J5: 0 | K5: 794 | L5: 0 | M5: 636988 | N5: 0 | O5: 1015 | P5: 0 | Q5: 2605784 | R5: 1016 | S5: 2211778 | T5: 476 | U5: 131627 | V5: 322 | X5: 0.55 | Y5: 220 | Z5: 0 | AA5: 1582330 | AB5: 1592 | AC5: 430490 | AD5: 484 | AE5: 1152 | AF5: 0 | AG5: 4764 | AH5: 0 | AK5: 593720 | AL5: 120 | AM5: 1334 | AN5: 1 | AO5: 53364 | AP5: 19 | AQ5: 9006 | AR5: 1 | AS5: 10688 | AT5: 4 | AU5: 15212 | AV5: 15 | AW5: 19598 | AX5: 18 | AY5: 20767 | AZ5: 1 | BA5: 13978 | BB5: 3 | BC5: 6321 | BD5: 2 | BE5: 26869 | BF5: 3 | BG5: 4541 | BH5: 6 | BI5: 14118 | BJ5: 92 | BK5: 3636 | BL5: 0 | BM5: 19 | BN5: 101 | BO5: 613240 | BP5: 130 | BQ5: 1235 | BR5: 20 | BS5: 799350 | BT5: 280 | BU5: 1231 | BV5: 90 | BW5: 160 | BX5: 410 | BY5: 69 | BZ5: 110 | CA5: 13257.678 | CC5: 0 | CD5: 215394 | CE5: 174 | CF5: 993.54 | CG5: 75 | CH5: 8081.25 | CI5: 70 | CJ5: 7542.5 | CK5: 75 | CL5: 8081.25 | CM5: 23705 | CN5: 1724 | CP5: 36374 | CQ5: 40 | CR5: 97.6 | CS5: 34562 | CT5: 6 | CU5: 14.64 | CV5: 10874 | CW5: 24 | CX5: 58.56 | CY5: 835172 | CZ5: 154 | DA5: 375.76 | DB5: 6649 | DC5: 8 | DD5: 19.12 | DE5: 8004 | DF5: 10 | DG5: 0 | DH5: 4686 | DI5: 7 | DJ5: 0 | DK5: 1919 | DL5: 1 | DM5: 0 | DN5: 5369 | DO5: 10 | DP5: 0 | DQ5: 4929 | DR5: 12 | DS5: 4 | DT5: 5701 | DU5: 9 | DV5: 0 | DW5: 5637 | DX5: 6 | DY5: 14.34 | EA5: 0 | EC5: 0 | EE5: 0 | EG5: 0 | EH5: 108 | EI5: 311 | EJ5: 0.81
A6: 44503 | B6: 8433068 | C6: 21845 | D6: 7599206 | E6: 21582 | F6: 0.98796063 | G6: 1058 | H6: 1022 | I6: 289262 | J6: 0 | K6: 794 | L6: 0 | M6: 636988 | N6: 0 | O6: 1015 | P6: 0 | Q6: 2606647 | R6: 863 | S6: 2212254 | T6: 476 | U6: 131949 | V6: 322 | X6: 0.7 | Y6: 280 | Z6: 8 | AA6: 1585090 | AB6: 2760 | AC6: 430890 | AD6: 400 | AE6: 1153 | AF6: 1 | AG6: 4770 | AH6: 6 | AK6: 593910 | AL6: 190 | AM6: 1335 | AN6: 1 | AO6: 53383 | AP6: 19 | AQ6: 9007 | AR6: 1 | AS6: 10690 | AT6: 2 | AU6: 15228 | AV6: 16 | AW6: 19598 | AX6: 0 | AY6: 20770 | AZ6: 3 | BA6: 13982 | BB6: 4 | BC6: 6324 | BD6: 3 | BE6: 26874 | BF6: 5 | BG6: 4546 | BH6: 5 | BI6: 14210 | BJ6: 92 | BK6: 3636 | BL6: 0 | BM6: 23 | BN6: 167 | BO6: 613390 | BP6: 150 | BQ6: 1250 | BR6: 15 | BS6: 799580 | BT6: 230 | BU6: 1152 | BV6: 0 | BW6: 40 | BX6: 380 | BY6: 53 | BZ6: 110 | CA6: 13257.678 | CC6: 0 | CD6: 215577 | CE6: 183 | CF6: 1044.93 | CG6: 71 | CH6: 7650.25 | CI6: 74 | CJ6: 7973.5 | CK6: 71 | CL6: 7650.25 | CM6: 23274 | CN6: 431 | CP6: 36425 | CQ6: 51 | CR6: 124.44 | CS6: 34570 | CT6: 8 | CU6: 19.52 | CV6: 10892 | CW6: 30 | CX6: 73.2 | CY6: 835326 | CZ6: 154 | DA6: 375.76 | DB6: 6657 | DC6: 8 | DD6: 19.12 | DE6: 8014 | DF6: 10 | DG6: 0 | DH6: 4693 | DI6: 7 | DJ6: 0 | DK6: 1921 | DL6: 2 | DM6: 1 | DN6: 5378 | DO6: 9 | DP6: 0 | DQ6: 4939 | DR6: 10 | DS6: 0 | DT6: 5710 | DU6: 9 | DV6: 0 | DW6: 5644 | DX6: 7 | DY6: 16.73 | EA6: 0 | EC6: 0 | EE6: 0 | EG6: 0 | EH6: 107 | EI6: 312 | EJ6: 0.8
A7: 44504 | B7: 8455185 | C7: 22117 | D7: 7620788 | E7: 21582 | F7: 0.97581046 | G7: 1058 | H7: 1022 | I7: 289262 | J7: 0 | K7: 794 | L7: 0 | M7: 636988 | N7: 0 | O7: 1015 | P7: 0 | Q7: 2607510 | R7: 863 | S7: 2212722 | T7: 468 | U7: 132153 | V7: 204 | X7: 1 | Y7: 400 | Z7: 0 | AA7: 1585980 | AB7: 890 | AC7: 431290 | AD7: 400 | AE7: 1153 | AF7: 0 | AG7: 4774 | AH7: 4 | AK7: 594070 | AL7: 160 | AM7: 1336 | AN7: 1 | AO7: 53402 | AP7: 19 | AQ7: 9007 | AR7: 0 | AS7: 10693 | AT7: 3 | AU7: 15244 | AV7: 16 | AW7: 19606 | AX7: 8 | AY7: 20771 | AZ7: 1 | BA7: 13984 | BB7: 2 | BC7: 6326 | BD7: 2 | BE7: 26878 | BF7: 4 | BG7: 4552 | BH7: 6 | BI7: 14304 | BJ7: 94 | BK7: 3636 | BL7: 0 | BM7: 19 | BN7: 141 | BO7: 613520 | BP7: 130 | BQ7: 1265 | BR7: 15 | BS7: 799810 | BT7: 230 | BU7: 1157 | BV7: 5 | BW7: 70 | BX7: 360 | BY7: 57 | BZ7: 110 | CA7: 13257.678 | CC7: 0 | CD7: 215770 | CE7: 193 | CF7: 1102.03 | CG7: 68 | CH7: 7327 | CI7: 70 | CJ7: 7542.5 | CK7: 67 | CL7: 7219.25 | CM7: 22088.75 | CN7: 1185.25 | CP7: 36462 | CQ7: 37 | CR7: 90.28 | CS7: 34576 | CT7: 6 | CU7: 14.64 | CV7: 10911 | CW7: 0 | CX7: 0 | CY7: 825210 | CZ7: 0 | DA7: 0 | DB7: 6666 | DC7: 9 | DD7: 21.51 | DE7: 8025 | DF7: 11 | DG7: 1 | DH7: 4701 | DI7: 8 | DJ7: 1 | DK7: 1922 | DL7: 1 | DM7: 0 | DN7: 5388 | DO7: 10 | DP7: 1 | DQ7: 4949 | DR7: 10 | DS7: 0 | DT7: 5720 | DU7: 10 | DV7: 1 | DW7: 5650 | DX7: 6 | DY7: 14.34 | EA7: 0 | EC7: 0 | EE7: 0 | EG7: 0 | EH7: 104 | EI7: 292 | EJ7: 0.78
A8: 44505 | B8: 8477456 | C8: 22271 | D8: 7643102 | E8: 22314 | F8: 1.0019308 | G8: 1082 | H8: 1022 | I8: 289262 | J8: 0 | K8: 794 | L8: 0 | M8: 636988 | N8: 0 | O8: 1015 | P8: 0 | Q8: 2611179 | R8: 3669 | S8: 2213223 | T8: 501 | U8: 132228 | V8: 75 | X8: 0.9 | Y8: 360 | Z8: 0 | AA8: 1585980 | AB8: 0 | AC8: 431660 | AD8: 370 | AE8: 1153 | AF8: 0 | AG8: 4780 | AH8: 6 | AK8: 594250 | AL8: 180 | AM8: 1337 | AN8: 1 | AO8: 53420 | AP8: 18 | AQ8: 9007 | AR8: 0 | AS8: 10695 | AT8: 2 | AU8: 15260 | AV8: 16 | AW8: 19617 | AX8: 11 | AY8: 20773 | AZ8: 2 | BA8: 13987 | BB8: 3 | BC8: 6328 | BD8: 2 | BE8: 26883 | BF8: 5 | BG8: 4558 | BH8: 6 | BI8: 14399 | BJ8: 95 | BK8: 3636 | BL8: 0 | BM8: 21 | BN8: 159 | BO8: 613670 | BP8: 150 | BQ8: 1280 | BR8: 15 | BS8: 800050 | BT8: 240 | BU8: 1190 | BV8: 33 | BW8: 60 | BX8: 390 | BY8: 60 | BZ8: 110 | CA8: 13257.678 | CC8: 0 | CD8: 215963 | CE8: 193 | CF8: 1102.03 | CG8: 83 | CH8: 8943.25 | CI8: 82 | CJ8: 8835.5 | CK8: 85 | CL8: 9158.75 | CM8: 26937.5 | CN8: -4848.75 | CO8: 6476 | CP8: 36509 | CQ8: 47 | CR8: 114.68 | CS8: 34583 | CT8: 7 | CU8: 17.08 | CV8: 10933 | CW8: 0 | CX8: 0 | CY8: 835279 | CZ8: 10069 | DA8: 24568.36 | DB8: 6674 | DC8: 8 | DD8: 19.12 | DE8: 8035 | DF8: 10 | DG8: 0 | DH8: 4708 | DI8: 7 | DJ8: 0 | DK8: 1923 | DL8: 1 | DM8: 0 | DN8: 5397 | DO8: 9 | DP8: 0 | DQ8: 4961 | DR8: 12 | DS8: 2 | DT8: 5729 | DU8: 9 | DV8: 0 | DW8: 5656 | DX8: 6 | DY8: 14.34 | EA8: 0 | EC8: 0 | EE8: 0 | EG8: 0 | EH8: 95 | EI8: 261 | EJ8: 0.71
A9: 44506 | B9: 8499859 | C9: 22403 | D9: 7664846 | E9: 21744 | F9: 0.9705843 | G9: 1082 | H9: 1022 | I9: 289262 | J9: 0 | K9: 794 | L9: 0 | M9: 636988 | N9: 0 | O9: 1015 | P9: 0 | Q9: 2612377 | R9: 1198 | S9: 2213661 | T9: 438 | U9: 132286 | V9: 58 | X9: 0.6 | Y9: 240 | Z9: 11 | AA9: 1588090 | AB9: 2110 | AC9: 432090 | AD9: 430 | AE9: 1153 | AF9: 0 | AG9: 4780 | AH9: 0 | AK9: 594480 | AL9: 230 | AM9: 1339 | AN9: 2 | AO9: 53438 | AP9: 18 | AQ9: 9008 | AR9: 1 | AS9: 10697 | AT9: 2 | AU9: 15275 | AV9: 15 | AW9: 19621 | AX9: 4 | AY9: 20775 | AZ9: 2 | BA9: 13991 | BB9: 4 | BC9: 6329 | BD9: 1 | BE9: 26886 | BF9: 3 | BG9: 4564 | BH9: 6 | BI9: 14491 | BJ9: 92 | BK9: 3636 | BL9: 0 | BM9: 21 | BN9: 209 | BO9: 613790 | BP9: 120 | BQ9: 1298 | BR9: 18 | BS9: 800350 | BT9: 300 | BU9: 1164 | BV9: 0 | BW9: 70 | BX9: 420 | BY9: 53 | BZ9: 110 | CA9: 13257.678 | CC9: 0 | CD9: 216123 | CE9: 160 | CF9: 913.6 | CG9: 80 | CH9: 8620 | CI9: 80 | CJ9: 8620 | CK9: 80 | CL9: 8620 | CM9: 25860 | CN9: 7553.5 | CP9: 36549 | CQ9: 40 | CR9: 97.6 | CS9: 34589 | CT9: 6 | CU9: 14.64 | CV9: 10956 | CW9: 23 | CX9: 56.12 | CY9: 835341 | CZ9: 62 | DA9: 151.28 | DB9: 6681 | DC9: 7 | DD9: 16.73 | DE9: 8043 | DF9: 8 | DG9: 0 | DH9: 4715 | DI9: 7 | DJ9: 0 | DK9: 1924 | DL9: 1 | DM9: 0 | DN9: 5406 | DO9: 9 | DP9: 0 | DQ9: 4969 | DR9: 8 | DS9: 0 | DT9: 5739 | DU9: 10 | DV9: 1 | DW9: 5662 | DX9: 6 | DY9: 14.34 | EA9: 0 | EC9: 0 | EE9: 0 | EG9: 0
A10: 44507 | B10: 8522337 | C10: 22478 | D10: 7684771 | E10: 19925 | F10: 0.88642228 | G10: 1082 | H10: 1022 | I10: 289262 | J10: 0 | K10: 794 | L10: 0 | M10: 636988 | N10: 0 | O10: 1015 | P10: 0 | Q10: 2613337 | R10: 960 | S10: 2214097 | T10: 436 | U10: 132496 | V10: 210 | X10: 0.7 | Y10: 280 | Z10: 0 | AA10: 1591950 | AB10: 3860 | AC10: 432530 | AD10: 440 | AE10: 1153 | AF10: 0 | AG10: 4780 | AH10: 0 | AK10: 594690 | AL10: 210 | AM10: 1339 | AN10: 0 | AO10: 53452 | AP10: 14 | AQ10: 9011 | AR10: 3 | AS10: 10699 | AT10: 2 | AU10: 15288 | AV10: 13 | AW10: 19627 | AX10: 6 | AY10: 20777 | AZ10: 2 | BA10: 13994 | BB10: 3 | BC10: 6332 | BD10: 3 | BE10: 26891 | BF10: 5 | BG10: 4568 | BH10: 4 | BI10: 14584 | BJ10: 93 | BK10: 3636 | BL10: 0 | BM10: 18 | BN10: 192 | BO10: 613930 | BP10: 140 | BQ10: 1305 | BR10: 7 | BS10: 800620 | BT10: 270 | BU10: 1168 | BV10: 4 | BW10: 60 | BX10: 410 | BY10: 50 | BZ10: 110 | CA10: 13257.678 | CC10: 0 | CD10: 216282 | CE10: 159 | CF10: 907.89 | CG10: 80 | CH10: 8620 | CI10: 80 | CJ10: 8620 | CK10: 80 | CL10: 8620 | CM10: 25860 | CN10: 0 | CP10: 36591 | CQ10: 42 | CR10: 102.48 | CS10: 34595 | CT10: 6 | CU10: 14.64 | CV10: 10979 | CW10: 23 | CX10: 56.12 | CY10: 835394 | CZ10: 53 | DA10: 129.32 | DB10: 6689 | DC10: 8 | DD10: 19.12 | DE10: 8051 | DF10: 8 | DG10: 0 | DH10: 4722 | DI10: 7 | DJ10: 0 | DK10: 1925 | DL10: 1 | DM10: 0 | DN10: 5414 | DO10: 8 | DP10: 0 | DQ10: 4979 | DR10: 10 | DS10: 2 | DT10: 5748 | DU10: 9 | DV10: 0 | DW10: 5668 | DX10: 6 | DY10: 14.34 | EA10: 0 | EC10: 0 | EE10: 0 | EG10: 0 | EH10: 106 | EI10: 267 | EJ10: 0.8
A11: 44508 | B11: 8544580 | C11: 22243 | D11: 7710304 | E11: 25533 | F11: 1.1479117 | G11: 1082 | H11: 1022 | I11: 289262 | J11: 0 | K11: 794 | L11: 0 | M11: 636988 | N11: 0 | O11: 1015 | P11: 0 | Q11: 2615632 | R11: 2295 | S11: 2214559 | T11: 462 | U11: 132706 | V11: 210 | X11: 1 | Y11: 400 | Z11: 12 | AA11: 1594830 | AB11: 2880 | AC11: 432920 | AD11: 390 | AE11: 1153 | AF11: 0 | AG11: 4780 | AH11: 0 | AK11: 594870 | AL11: 180 | AM11: 1319 | AN11: -20 | AO11: 53476 | AP11: 24 | AQ11: 9012 | AR11: 1 | AS11: 10700 | AT11: 1 | AU11: 15298 | AV11: 10 | AW11: 19633 | AX11: 6 | AY11: 20779 | AZ11: 2 | BA11: 13997 | BB11: 3 | BC11: 6333 | BD11: 1 | BE11: 26895 | BF11: 4 | BG11: 4574 | BH11: 6 | BI11: 14675 | BJ11: 91 | BK11: 3636 | BL11: 0 | BM11: 15 | BN11: 165 | BO11: 614080 | BP11: 150 | BQ11: 1343 | BR11: 38 | BS11: 800850 | BT11: 230 | BU11: 1172 | BV11: 4 | BW11: 50 | BX11: 380 | BY11: 54 | BZ11: 110 | CA11: 13257.678 | CC11: 0 | CD11: 216452 | CE11: 170 | CF11: 970.7 | CG11: 75 | CH11: 8081.25 | CI11: 76 | CJ11: 8189 | CK11: 75 | CL11: 8081.25 | CM11: 24351.5 | CN11: 1508.5 | CP11: 36635 | CQ11: 44 | CR11: 107.36 | CS11: 34603 | CT11: 8 | CU11: 19.52 | CV11: 10999 | CW11: 20 | CX11: 48.8 | CY11: 835459 | CZ11: 65 | DA11: 158.6 | DB11: 6698 | DC11: 9 | DD11: 21.51 | DE11: 8059 | DF11: 8 | DG11: 0 | DH11: 4729 | DI11: 7 | DJ11: 0 | DK11: 1926 | DL11: 1 | DM11: 0 | DN11: 5423 | DO11: 9 | DP11: 1 | DQ11: 4991 | DR11: 12 | DS11: 2 | DT11: 5757 | DU11: 9 | DV11: 0 | DW11: 5674 | DX11: 6 | DY11: 14.34 | EA11: 0 | EC11: 0 | EE11: 0 | EG11: 0 | EH11: 98 | EI11: 217 | EJ11: 0.74
A12: 44509 | B12: 8567390 | C12: 22810 | D12: 7731998 | E12: 21694 | F12: 0.95107409 | G12: 1114 | H12: 1022 | I12: 289262 | J12: 0 | K12: 794 | L12: 0 | M12: 636988 | N12: 0 | O12: 1015 | P12: 0 | Q12: 2616685 | R12: 1053 | S12: 2214995 | T12: 436 | U12: 132916 | V12: 210 | X12: 0.88888889 | Y12: 355.55556 | Z12: 0 | AA12: 1595250 | AB12: 420 | AC12: 433280 | AD12: 360 | AE12: 1153 | AF12: 0 | AG12: 4786 | AH12: 6 | AK12: 595030 | AL12: 160 | AM12: 1343 | AN12: 24 | AO12: 53496 | AP12: 20 | AQ12: 9013 | AR12: 1 | AS12: 10702 | AT12: 2 | AU12: 15311 | AV12: 13 | AW12: 19639 | AX12: 6 | AY12: 20781 | AZ12: 2 | BA12: 14000 | BB12: 3 | BC12: 6334 | BD12: 1 | BE12: 26899 | BF12: 4 | BG12: 4579 | BH12: 5 | BI12: 14762 | BJ12: 87 | BK12: 3636 | BL12: 0 | BM12: 18 | BN12: 142 | BO12: 614210 | BP12: 130 | BQ12: 1329 | BR12: -14 | BS12: 801070 | BT12: 220 | BU12: 1175 | BV12: 3 | BW12: 60 | BX12: 350 | BY12: 53 | BZ12: 110 | CA12: 13257.678 | CC12: 0 | CD12: 216617 | CE12: 165 | CF12: 942.15 | CG12: 74 | CH12: 7973.5 | CI12: 75 | CJ12: 8081.25 | CK12: 70 | CL12: 7542.5 | CM12: 23597.25 | CN12: 754.25 | CP12: 36676 | CQ12: 41 | CR12: 100.04 | CS12: 34608 | CT12: 5 | CU12: 12.2 | CV12: 11019 | CW12: 20 | CX12: 48.8 | CY12: 835514 | CZ12: 55 | DA12: 134.2 | DB12: 6706 | DC12: 8 | DD12: 19.12 | DE12: 8067 | DF12: 8 | DG12: 0 | DH12: 4735 | DI12: 6 | DJ12: 0 | DK12: 1927 | DL12: 1 | DM12: 0 | DN12: 5431 | DO12: 8 | DP12: 0 | DQ12: 4999 | DR12: 8 | DS12: 0 | DT12: 5766 | DU12: 9 | DV12: 0 | DW12: 5681 | DX12: 7 | DY12: 16.73 | EA12: 0 | EC12: 0 | EE12: 0 | EG12: 0 | EH12: 100 | EI12: 225 | EJ12: 0.75
A13: 44510 | B13: 8588801 | C13: 21411 | D13: 7753139 | E13: 21141 | F13: 0.98738966 | G13: 1114 | H13: 1022 | I13: 289262 | J13: 0 | K13: 794 | L13: 0 | M13: 636988 | N13: 0 | O13: 1015 | P13: 0 | Q13: 2617577 | R13: 892 | S13: 2215457 | T13: 462 | U13: 133178 | V13: 262 | X13: 0.6 | Y13: 240 | Z13: 0 | AA13: 1595250 | AB13: 0 | AC13: 433680 | AD13: 400 | AE13: 1153 | AF13: 0 | AG13: 4786 | AH13: 0 | AK13: 595190 | AL13: 160 | AM13: 1345 | AN13: 2 | AO13: 53513 | AP13: 17 | AQ13: 9016 | AR13: 3 | AS13: 10704 | AT13: 2 | AU13: 15324 | AV13: 13 | AW13: 19644 | AX13: 5 | AY13: 20783 | AZ13: 2 | BA13: 14003 | BB13: 3 | BC13: 6334 | BD13: 0 | BE13: 26904 | BF13: 5 | BG13: 4584 | BH13: 5 | BI13: 14858 | BJ13: 96 | BK13: 3636 | BL13: 0 | BM13: 18 | BN13: 142 | BO13: 614350 | BP13: 140 | BQ13: 1345 | BR13: 16 | BS13: 801310 | BT13: 240 | BU13: 1182 | BV13: 7 | BW13: 80 | BX13: 380 | BY13: 50 | BZ13: 109 | CA13: 13102.023 | CC13: 155.65475 | CD13: 216772 | CE13: 155 | CF13: 885.05 | CG13: 70 | CH13: 7542.5 | CI13: 72 | CJ13: 7758 | CK13: 62 | CL13: 6680.5 | CM13: 21981 | CN13: 1616.25 | CP13: 36719 | CQ13: 43 | CR13: 104.92 | CS13: 34614 | CT13: 6 | CU13: 14.64 | CV13: 11038 | CW13: 19 | CX13: 46.36 | CY13: 835463 | CZ13: 0 | DA13: 0 | DB13: 6714 | DC13: 8 | DD13: 19.12 | DE13: 8075 | DF13: 8 | DG13: 0 | DH13: 4742 | DI13: 7 | DJ13: 1 | DK13: 1928 | DL13: 1 | DM13: 0 | DN13: 5440 | DO13: 9 | DP13: 1 | DQ13: 5009 | DR13: 10 | DS13: 2 | DT13: 5774 | DU13: 8 | DV13: 0 | DW13: 5687 | DX13: 6 | DY13: 14.34 | EA13: 0 | EC13: 0 | EE13: 0 | EG13: 0 | EH13: 98 | EI13: 218 | EJ13: 0.74
A14: 44511 | B14: 8610198 | C14: 21397 | D14: 7774313 | E14: 21174 | F14: 0.98957798 | G14: 1114 | H14: 1022 | I14: 289262 | J14: 0 | K14: 794 | L14: 0 | M14: 636988 | N14: 0 | O14: 1015 | P14: 0 | Q14: 2618552 | R14: 975 | S14: 2215889 | T14: 432 | U14: 133440 | V14: 262 | X14: 0.9 | Y14: 360 | Z14: 0 | AA14: 1597000 | AB14: 1750 | AC14: 434070 | AD14: 390 | AE14: 1153 | AF14: 0 | AG14: 4790 | AH14: 4 | AK14: 595370 | AL14: 180 | AM14: 1347 | AN14: 2 | AO14: 53533 | AP14: 20 | AQ14: 9018 | AR14: 2 | AS14: 10705 | AT14: 1 | AU14: 15336 | AV14: 12 | AW14: 19649 | AX14: 5 | AY14: 20785 | AZ14: 2 | BA14: 14006 | BB14: 3 | BC14: 6337 | BD14: 3 | BE14: 26908 | BF14: 4 | BG14: 4589 | BH14: 5 | BI14: 14949 | BJ14: 91 | BK14: 3636 | BL14: 0 | BM14: 17 | BN14: 163 | BO14: 614490 | BP14: 140 | BQ14: 1347 | BR14: 2 | BS14: 801550 | BT14: 240 | BU14: 1187 | BV14: 5 | BW14: 60 | BX14: 380 | BY14: 53 | BZ14: 109 | CA14: 13102.023 | CC14: 0 | CD14: 216959 | CE14: 187 | CF14: 1067.77 | CG14: 65 | CH14: 7003.75 | CI14: 69 | CJ14: 7434.75 | CK14: 66 | CL14: 7111.5 | CM14: 21550 | CN14: 431 | CP14: 36771 | CQ14: 52 | CR14: 126.88 | CS14: 34619 | CT14: 5 | CU14: 12.2 | CV14: 11058 | CW14: 20 | CX14: 48.8 | CY14: 835636 | CZ14: 173 | DA14: 422.12 | DB14: 6722 | DC14: 8 | DD14: 19.12 | DE14: 8084 | DF14: 9 | DG14: 1 | DH14: 4749 | DI14: 7 | DJ14: 0 | DK14: 1929 | DL14: 1 | DM14: 0 | DN14: 5448 | DO14: 8 | DP14: 0 | DQ14: 5019 | DR14: 10 | DS14: 0 | DT14: 5783 | DU14: 9 | DV14: 1 | DW14: 5692 | DX14: 5 | DY14: 11.95 | EA14: 0 | EC14: 0 | EE14: 0 | EG14: 0 | EH14: 99 | EI14: 224 | EJ14: 0.74
A15: 44512 | B15: 8636188 | C15: 25990 | D15: 7800028 | E15: 25715 | F15: 0.98941901 | G15: 1114 | H15: 1022 | I15: 289262 | J15: 0 | K15: 794 | L15: 0 | M15: 636988 | N15: 0 | O15: 1015 | P15: 0 | Q15: 2620333 | R15: 1781 | S15: 2216304 | T15: 415 | U15: 133626 | V15: 186 | X15: 0.55555556 | Y15: 222.22222 | Z15: 0 | AA15: 1598750 | AB15: 1750 | AC15: 434520 | AD15: 450 | AE15: 1153 | AF15: 0 | AG15: 4806 | AH15: 16 | AK15: 595580 | AL15: 210 | AM15: 1348 | AN15: 1 | AO15: 53551 | AP15: 18 | AQ15: 9021 | AR15: 3 | AS15: 10707 | AT15: 2 | AU15: 15349 | AV15: 13 | AW15: 19658 | AX15: 9 | AY15: 20787 | AZ15: 2 | BA15: 14009 | BB15: 3 | BC15: 6339 | BD15: 2 | BE15: 26911 | BF15: 3 | BG15: 4594 | BH15: 5 | BI15: 15042 | BJ15: 93 | BK15: 3636 | BL15: 0 | BM15: 18 | BN15: 192 | BO15: 614620 | BP15: 130 | BQ15: 1348 | BR15: 1 | BS15: 801860 | BT15: 310 | BU15: 1190 | BV15: 3 | BW15: 100 | BX15: 440 | BY15: 57 | BZ15: 109 | CA15: 13102.023 | CC15: 0 | CD15: 217134 | CE15: 175 | CF15: 999.25 | CG15: 62 | CH15: 6680.5 | CI15: 65 | CJ15: 7003.75 | CK15: 62 | CL15: 6680.5 | CM15: 20364.75 | CN15: 1185.25 | CP15: 36815 | CQ15: 44 | CR15: 107.36 | CS15: 34626 | CT15: 7 | CU15: 17.08 | CV15: 11079 | CW15: 21 | CX15: 51.24 | CY15: 835603 | CZ15: 0 | DA15: 0 | DB15: 6731 | DC15: 9 | DD15: 21.51 | DE15: 8092 | DF15: 8 | DG15: 0 | DH15: 4756 | DI15: 7 | DJ15: 0 | DK15: 1930 | DL15: 1 | DM15: 0 | DN15: 5457 | DO15: 9 | DP15: 1 | DQ15: 5029 | DR15: 10 | DS15: 0 | DT15: 5792 | DU15: 9 | DV15: 0 | DW15: 5699 | DX15: 7 | DY15: 16.73 | EA15: 0 | EC15: 0 | EE15: 0 | EG15: 0 | EH15: 92 | EI15: 205 | EJ15: 0.69
A16: 44513 | B16: 8658974 | C16: 22786 | D16: 7822629 | E16: 22601 | F16: 0.99188098 | G16: 1114 | H16: 1022 | I16: 289262 | J16: 0 | K16: 794 | L16: 0 | M16: 636988 | N16: 0 | O16: 1015 | P16: 0 | Q16: 2621475 | R16: 1142 | S16: 2216720 | T16: 416 | U16: 133814 | V16: 188 | X16: 0.55555556 | Y16: 222.22222 | Z16: 9 | AA16: 1599514 | AB16: 764 | AC16: 434980 | AD16: 460 | AE16: 1153 | AF16: 0 | AG16: 4808 | AH16: 2 | AK16: 595830 | AL16: 250 | AM16: 1353 | AN16: 5 | AO16: 53570 | AP16: 19 | AQ16: 9023 | AR16: 2 | AS16: 10709 | AT16: 2 | AU16: 15363 | AV16: 14 | AW16: 19664 | AX16: 6 | AY16: 20789 | AZ16: 2 | BA16: 14012 | BB16: 3 | BC16: 6339 | BD16: 0 | BE16: 26916 | BF16: 5 | BG16: 4600 | BH16: 6 | BI16: 15136 | BJ16: 94 | BK16: 3636 | BL16: 0 | BM16: 19 | BN16: 231 | BO16: 614750 | BP16: 130 | BQ16: 1357 | BR16: 9 | BS16: 802170 | BT16: 310 | BU16: 1194 | BV16: 4 | BW16: 60 | BX16: 440 | BY16: 54 | BZ16: 109 | CA16: 13102.023 | CC16: 0 | CD16: 217305 | CE16: 171 | CF16: 976.41 | CG16: 59 | CH16: 6357.25 | CI16: 64 | CJ16: 6896 | CK16: 60 | CL16: 6465 | CM16: 19718.25 | CN16: 646.5 | CP16: 36856 | CQ16: 41 | CR16: 100.04 | CS16: 34633 | CT16: 7 | CU16: 17.08 | CV16: 11100 | CW16: 21 | CX16: 51.24 | CY16: 835764 | CZ16: 161 | DA16: 392.84 | DB16: 6739 | DC16: 8 | DD16: 19.12 | DE16: 8100 | DF16: 8 | DG16: 0 | DH16: 4764 | DI16: 8 | DJ16: 1 | DK16: 1931 | DL16: 1 | DM16: 0 | DN16: 5466 | DO16: 9 | DP16: 0 | DQ16: 5040 | DR16: 11 | DS16: 1 | DT16: 5800 | DU16: 8 | DV16: 0 | DW16: 5705 | DX16: 6 | DY16: 14.34 | EA16: 0 | EC16: 0 | EE16: 0 | EG16: 0 | EH16: 93 | EI16: 212 | EJ16: 0.7
A17: 44514 | B17: 8680814 | C17: 21840 | D17: 7844096 | E17: 21467 | F17: 0.98292125 | G17: 1114 | H17: 1022 | I17: 289262 | J17: 0 | K17: 794 | L17: 0 | M17: 636988 | N17: 0 | O17: 1015 | P17: 0 | Q17: 2622218 | R17: 743 | S17: 2217144 | T17: 424 | U17: 134002 | V17: 188 | X17: 0.66666667 | Y17: 266.66667 | Z17: 17 | AA17: 1602483 | AB17: 2969 | AC17: 435430 | AD17: 450 | AE17: 1153 | AF17: 0 | AG17: 4825 | AH17: 17 | AK17: 596040 | AL17: 210 | AM17: 1354 | AN17: 1 | AO17: 53587 | AP17: 17 | AQ17: 9025 | AR17: 2 | AS17: 10711 | AT17: 2 | AU17: 15376 | AV17: 13 | AW17: 19670 | AX17: 6 | AY17: 20790 | AZ17: 1 | BA17: 14015 | BB17: 3 | BC17: 6340 | BD17: 1 | BE17: 26920 | BF17: 4 | BG17: 4605 | BH17: 5 | BI17: 15225 | BJ17: 89 | BK17: 3636 | BL17: 0 | BM17: 17 | BN17: 193 | BO17: 614910 | BP17: 160 | BQ17: 1384 | BR17: 27 | BS17: 802450 | BT17: 280 | BU17: 1198 | BV17: 4 | BW17: 70 | BX17: 440 | BY17: 50 | BZ17: 109 | CA17: 13102.023 | CC17: 0 | CD17: 217469 | CE17: 164 | CF17: 936.44 | CG17: 55 | CH17: 5926.25 | CI17: 60 | CJ17: 6465 | CK17: 56 | CL17: 6034 | CM17: 18425.25 | CN17: 1293 | CP17: 36900 | CQ17: 44 | CR17: 107.36 | CS17: 34638 | CT17: 5 | CU17: 12.2 | CV17: 11117 | CW17: 17 | CX17: 41.48 | CY17: 835826 | CZ17: 62 | DA17: 151.28 | DB17: 6747 | DC17: 8 | DD17: 19.12 | DE17: 8108 | DF17: 8 | DG17: 0 | DH17: 4770 | DI17: 6 | DJ17: 0 | DK17: 1931 | DL17: 0 | DM17: 0 | DN17: 5474 | DO17: 8 | DP17: 0 | DQ17: 5050 | DR17: 10 | DS17: 0 | DT17: 5810 | DU17: 10 | DV17: 2 | DW17: 5710 | DX17: 5 | DY17: 11.95 | EA17: 0 | EC17: 0 | EE17: 0 | EG17: 0 | EH17: 86 | EI17: 189 | EJ17: 0.65
A18: 44515 | B18: 8706369 | C18: 25555 | D18: 7860925 | E18: 16829 | F18: 0.6585404 | G18: 1124 | H18: 1022 | I18: 289262 | J18: 0 | K18: 794 | L18: 0 | M18: 636988 | N18: 0 | O18: 1015 | P18: 0 | Q18: 2623294 | R18: 1076 | S18: 2217558 | T18: 414 | U18: 134214 | V18: 212 | X18: 0.66666667 | Y18: 266.66667 | Z18: 0 | AA18: 1604570 | AB18: 2087 | AC18: 435880 | AD18: 450 | AE18: 1154 | AF18: 1 | AG18: 4828 | AH18: 3 | AK18: 596230 | AL18: 190 | AM18: 1355 | AN18: 1 | AO18: 53602 | AP18: 15 | AQ18: 9027 | AR18: 2 | AS18: 10712 | AT18: 1 | AU18: 15388 | AV18: 12 | AW18: 19677 | AX18: 7 | AY18: 20792 | AZ18: 2 | BA18: 14018 | BB18: 3 | BC18: 6342 | BD18: 2 | BE18: 26925 | BF18: 5 | BG18: 4610 | BH18: 5 | BI18: 15320 | BJ18: 95 | BK18: 3636 | BL18: 0 | BM18: 17 | BN18: 173 | BO18: 615070 | BP18: 160 | BQ18: 1412 | BR18: 28 | BS18: 802680 | BT18: 230 | BU18: 1202 | BV18: 4 | BW18: 40 | BX18: 390 | BY18: 49 | BZ18: 109 | CA18: 13102.023 | CC18: 0 | CD18: 217636 | CE18: 167 | CF18: 953.57 | CG18: 85 | CH18: 9158.75 | CI18: 86 | CJ18: 9266.5 | CK18: 86 | CL18: 9266.5 | CM18: 27691.75 | CN18: -9266.5 | CO18: 7043 | CP18: 36946 | CQ18: 46 | CR18: 112.24 | CS18: 34646 | CT18: 8 | CU18: 19.52 | CV18: 11136 | CW18: 19 | CX18: 46.36 | CY18: 835783 | CZ18: 0 | DA18: 0 | DB18: 6754 | DC18: 7 | DD18: 16.73 | DE18: 8117 | DF18: 9 | DG18: 1 | DH18: 4778 | DI18: 8 | DJ18: 2 | DK18: 1932 | DL18: 1 | DM18: 1 | DN18: 5483 | DO18: 9 | DP18: 1 | DQ18: 5059 | DR18: 9 | DS18: 0 | DT18: 5819 | DU18: 9 | DV18: 0 | DW18: 5716 | DX18: 6 | DY18: 14.34 | EA18: 0 | EC18: 0 | EE18: 0 | EG18: 0 | EH18: 94 | EI18: 207 | EJ18: 0.71
A19: 44516 | B19: 8727152 | C19: 20783 | D19: 7889809 | E19: 28884 | F19: 1.3897897 | G19: 1124 | H19: 1022 | I19: 289262 | J19: 0 | K19: 794 | L19: 0 | M19: 636988 | N19: 0 | O19: 1015 | P19: 0 | Q19: 2624910 | R19: 1616 | S19: 2217970 | T19: 412 | U19: 134426 | V19: 212 | X19: 0.77777778 | Y19: 311.11111 | Z19: 0 | AA19: 1606310 | AB19: 1740 | AC19: 436220 | AD19: 340 | AE19: 1156 | AF19: 2 | AG19: 4828 | AH19: 0 | AK19: 596390 | AL19: 160 | AM19: 1356 | AN19: 1 | AO19: 53622 | AP19: 20 | AQ19: 9030 | AR19: 3 | AS19: 10714 | AT19: 2 | AU19: 15400 | AV19: 12 | AW19: 19683 | AX19: 6 | AY19: 20793 | AZ19: 1 | BA19: 14021 | BB19: 3 | BC19: 6343 | BD19: 1 | BE19: 26931 | BF19: 6 | BG19: 4616 | BH19: 6 | BI19: 15408 | BJ19: 88 | BK19: 3636 | BL19: 0 | BM19: 16 | BN19: 144 | BO19: 615210 | BP19: 140 | BQ19: 1421 | BR19: 9 | BS19: 802920 | BT19: 240 | BU19: 1207 | BV19: 5 | BW19: 80 | BX19: 380 | BY19: 54 | BZ19: 109 | CA19: 13102.023 | CC19: 0 | CD19: 217787 | CE19: 151 | CF19: 862.21 | CG19: 82 | CH19: 8835.5 | CI19: 84 | CJ19: 9051 | CK19: 83 | CL19: 8943.25 | CM19: 26829.75 | CN19: 7905 | CP19: 36992 | CQ19: 46 | CR19: 112.24 | CS19: 34653 | CT19: 7 | CU19: 17.08 | CV19: 11157 | CW19: 21 | CX19: 51.24 | CY19: 835936 | CZ19: 153 | DA19: 373.32 | DB19: 6762 | DC19: 8 | DD19: 19.12 | DE19: 8124 | DF19: 7 | DG19: 0 | DH19: 4784 | DI19: 6 | DJ19: 0 | DK19: 1933 | DL19: 1 | DM19: 0 | DN19: 5491 | DO19: 8 | DP19: 0 | DQ19: 5069 | DR19: 10 | DS19: 1 | DT19: 5828 | DU19: 9 | DV19: 0 | DW19: 5719 | DX19: 3 | DY19: 7.17 | EH19: 89 | EI19: 199 | EJ19: 0.67
A20: 44517 | B20: 8751665 | C20: 24513 | D20: 7913926 | E20: 24117 | F20: 0.98384531 | G20: 1124 | H20: 1022 | I20: 289262 | J20: 0 | K20: 794 | L20: 0 | M20: 636988 | N20: 0 | O20: 1015 | P20: 0 | Q20: 2627478 | R20: 2568 | S20: 2218400 | T20: 430 | U20: 134664 | V20: 238 | X20: 0.77777778 | Y20: 311.11111 | Z20: 0 | AA20: 1607792 | AB20: 1482 | AC20: 436610 | AD20: 390 | AE20: 1156 | AF20: 0 | AG20: 4828 | AH20: 0 | AK20: 596560 | AL20: 170 | AM20: 1357 | AN20: 1 | AO20: 53640 | AP20: 18 | AQ20: 9032 | AR20: 2 | AS20: 10716 | AT20: 2 | AU20: 15416 | AV20: 16 | AW20: 19690 | AX20: 7 | AY20: 20796 | AZ20: 3 | BA20: 14025 | BB20: 4 | BC20: 6344 | BD20: 1 | BE20: 26934 | BF20: 3 | BG20: 4622 | BH20: 6 | BI20: 15496 | BJ20: 88 | BK20: 3636 | BL20: #REF! | BM20: 23 | BN20: 147 | BO20: 615330 | BP20: 120 | BQ20: 1423 | BR20: 2 | BS20: 803160 | BT20: 240 | BU20: 1212 | BV20: 5 | BW20: 70 | BX20: 360 | BY20: 59 | BZ20: 109 | CA20: 13102.023 | CC20: 0 | CD20: 217948 | CE20: 161 | CF20: 919.31 | CG20: 80 | CH20: 8620 | CI20: 82 | CJ20: 8835.5 | CK20: 79 | CL20: 8512.25 | CM20: 25967.75 | CN20: 862 | CP20: 37037 | CQ20: 45 | CR20: 109.8 | CS20: 34660 | CT20: 7 | CU20: 17.08 | CV20: 11176 | CW20: 19 | CX20: 46.36 | CY20: 835989 | CZ20: 53 | DA20: 129.32 | DB20: 6770 | DC20: 8 | DD20: 19.12 | DE20: 8132 | DF20: 8 | DG20: 1 | DH20: 4791 | DI20: 7 | DJ20: 1 | DK20: 1934 | DL20: 1 | DM20: 0 | DN20: 5500 | DO20: 9 | DP20: 1 | DQ20: 5079 | DR20: 10 | DS20: 0 | DT20: 5837 | DU20: 9 | DV20: 0 | DW20: 5725 | DX20: 6 | DY20: 14.34 | EA20: 0 | EC20: 0 | EE20: 0 | EG20: 0 | EH20: 89 | EI20: 197 | EJ20: 0.67 | ER20: Fill pool 185 190, bambou pool start filling. Elec consumption: coldrooms on test, pools on, spa and villa ACs on
A21: 44518 | B21: 8773680 | C21: 22015 | D21: 7935598 | E21: 21672 | F21: 0.98441971 | G21: 1124 | H21: 1022 | I21: 289262 | J21: 0 | K21: 794 | L21: 0 | M21: 636988 | N21: 0 | O21: 1015 | P21: #REF! | Q21: 2629132 | R21: 1654 | S21: 2218910 | T21: 510 | U21: 134878 | V21: 214 | X21: 0.77 | Y21: 308 | Z21: 0 | AA21: 1607793 | AB21: 1 | AC21: 437000 | AD21: 390 | AE21: 1156 | AF21: 0 | AG21: 4828 | AH21: 0 | AK21: 596740 | AL21: 180 | AM21: 1360 | AN21: 3 | AO21: 53658 | AP21: 18 | AQ21: 9035 | AR21: 3 | AS21: 10717 | AT21: 1 | AU21: 15425 | AV21: 9 | AW21: 19697 | AX21: 7 | AY21: 20798 | AZ21: 2 | BA21: 14028 | BB21: 3 | BC21: 6345 | BD21: 1 | BE21: 26937 | BF21: 3 | BG21: 4628 | BH21: 6 | BI21: 15592 | BJ21: 96 | BK21: 3636 | BL21: 0 | BM21: 14 | BN21: 166 | BO21: 615460 | BP21: 130 | BQ21: 1435 | BR21: 12 | BS21: 803410 | BT21: 250 | BU21: 1216 | BV21: 4 | BW21: 70 | BX21: 380 | BY21: 50 | BZ21: 109 | CA21: 13102.023 | CC21: 0 | CD21: 218102 | CE21: 154 | CF21: 879.34 | CG21: 76 | CH21: 8189 | CI21: 79 | CJ21: 8512.25 | CK21: 77 | CL21: 8296.75 | CM21: 24998 | CN21: 969.75 | CP21: 37080 | CQ21: 43 | CR21: 104.92 | CS21: 34667 | CT21: 7 | CU21: 17.08 | CV21: 11198 | CW21: 22 | CX21: 53.68 | CY21: 836039 | CZ21: 50 | DA21: 122 | DB21: 6777 | DC21: 7 | DD21: 16.73 | DE21: 8141 | DF21: 9 | DG21: 1 | DH21: 4798 | DI21: 7 | DJ21: 0 | DK21: 1935 | DL21: 1 | DM21: 0 | DN21: 5508 | DO21: 8 | DP21: 0 | DQ21: 5089 | DR21: 10 | DS21: 0 | DT21: 5846 | DU21: 9 | DV21: 0 | DW21: 5731 | DX21: 6 | DY21: 14.34 | EA21: 0 | EC21: 0 | EE21: 0 | EG21: 0 | EH21: 84 | EI21: 188 | EJ21: 0.63
A22: 44519 | B22: 8793704 | C22: 20024 | D22: 7955356 | E22: 19758 | F22: 0.98671594 | G22: 1124 | H22: 1022 | I22: 289262 | J22: 0 | K22: 794 | L22: 0 | M22: 636988 | N22: 0 | O22: 1015 | P22: 0 | Q22: 2629870 | R22: 738 | S22: 2219215 | T22: 305 | U22: 135082 | V22: 204 | X22: 0.55555556 | Y22: 222.22222 | Z22: 7 | AA22: 1608093 | AB22: 300 | AC22: 437420 | AD22: 420 | AE22: 1156 | AF22: 0 | AG22: 4847 | AH22: 19 | AK22: 596950 | AL22: 210 | AM22: 1373 | AN22: 13 | AO22: 53674 | AP22: 16 | AQ22: 9038 | AR22: 3 | AS22: 10718 | AT22: 1 | AU22: 15435 | AV22: 10 | AW22: 19703 | AX22: 6 | AY22: 20800 | AZ22: 2 | BA22: 14031 | BB22: 3 | BC22: 6347 | BD22: 2 | BE22: 26941 | BF22: 4 | BG22: 4633 | BH22: 5 | BI22: 15673 | BJ22: 81 | BK22: 3636 | BL22: 0 | BM22: 15 | BN22: 195 | BO22: 615600 | BP22: 140 | BQ22: 1441 | BR22: 6 | BS22: 803670 | BT22: 260 | BU22: 1220 | BV22: 4 | BW22: 50 | BX22: 400 | BY22: 48 | BZ22: 109 | CA22: 13102.023 | CC22: 0 | CD22: 218233 | CE22: 131 | CF22: 748.01 | CG22: 75 | CH22: 8081.25 | CI22: 77 | CJ22: 8296.75 | CK22: 75 | CL22: 8081.25 | CM22: 24459.25 | CN22: 538.75 | CP22: 37120 | CQ22: 40 | CR22: 97.6 | CS22: 34672 | CT22: 5 | CU22: 12.2 | CV22: 11219 | CW22: 21 | CX22: 51.24 | CY22: 836084 | CZ22: 45 | DA22: 109.8 | DB22: 6784 | DC22: 7 | DD22: 16.73 | DE22: 8148 | DF22: 7 | DG22: 0 | DH22: 4804 | DI22: 6 | DJ22: 0 | DK22: 1936 | DL22: 1 | DM22: 0 | DN22: 5516 | DO22: 8 | DP22: 0 | DQ22: 5098 | DR22: 9 | DS22: 0 | DT22: 5854 | DU22: 8 | DV22: 0 | DW22: 5736 | DX22: 5 | DY22: 11.95 | EA22: 0 | EC22: 0 | EE22: 0 | EG22: 0 | EH22: 92 | EI22: 212 | EJ22: 0.69
A23: 44520 | B23: 8817772 | C23: 24068 | D23: 7979214 | E23: 23858 | F23: 0.99127472 | G23: 1124 | H23: 1022 | I23: 289262 | J23: 0 | K23: 794 | L23: 0 | M23: 636988 | N23: 0 | O23: 1015 | P23: 0 | Q23: 2630950 | R23: 1080 | S23: 2219669 | T23: 454 | U23: 135466 | V23: 384 | X23: 0.88888889 | Y23: 355.55556 | Z23: 5 | AA23: 1608393 | AB23: 300 | AC23: 437840 | AD23: 420 | AE23: 1156 | AF23: 0 | AG23: 4849 | AH23: 2 | AK23: 597170 | AL23: 220 | AM23: 1381 | AN23: 8 | AO23: 53698 | AP23: 24 | AQ23: 9041 | AR23: 3 | AS23: 10720 | AT23: 2 | AU23: 15449 | AV23: 14 | AW23: 19710 | AX23: 7 | AY23: 20802 | AZ23: 2 | BA23: 14034 | BB23: 3 | BC23: 6348 | BD23: 1 | BE23: 26944 | BF23: 3 | BG23: 4638 | BH23: 5 | BI23: 15768 | BJ23: 95 | BK23: 3636 | BL23: 0 | BM23: 19 | BN23: 201 | BO23: 615740 | BP23: 140 | BQ23: 1446 | BR23: 5 | BS23: 803940 | BT23: 270 | BU23: 1223 | BV23: 3 | BW23: 50 | BX23: 410 | BY23: 61 | BZ23: 109 | CA23: 13102.023 | CC23: 0 | CD23: 218383 | CE23: 150 | CF23: 856.5 | CG23: 70 | CH23: 7542.5 | CI23: 75 | CJ23: 8081.25 | CK23: 70 | CL23: 7542.5 | CM23: 23166.25 | CN23: 1293 | CP23: 37151 | CQ23: 31 | CR23: 75.64 | CS23: 34678 | CT23: 6 | CU23: 14.64 | CV23: 11244 | CW23: 25 | CX23: 61 | CY23: 836135 | CZ23: 51 | DA23: 124.44 | DB23: 6792 | DC23: 8 | DD23: 19.12 | DE23: 8156 | DF23: 8 | DG23: 1 | DH23: 4811 | DI23: 7 | DJ23: 1 | DK23: 1937 | DL23: 1 | DM23: 0 | DN23: 5524 | DO23: 8 | DP23: 0 | DQ23: 5108 | DR23: 10 | DS23: 1 | DT23: 5862 | DU23: 8 | DV23: 0 | DW23: 5742 | DX23: 6 | DY23: 14.34 | EA23: 0 | EC23: 0 | EE23: 0 | EG23: 0 | EH23: 98 | EI23: 225 | EJ23: 0.74
A24: 44521 | B24: 8842496 | C24: 24724 | D24: 8003587 | E24: 24373 | F24: 0.98580327 | G24: 1124 | H24: 1022 | I24: 289262 | J24: 0 | K24: 794 | L24: 0 | M24: 636988 | N24: 0 | O24: 1015 | P24: 0 | Q24: 2631852 | R24: 902 | S24: 2220091 | T24: 422 | U24: 135706 | V24: 240 | X24: 0.77777778 | Y24: 311.11111 | Z24: 0 | AA24: 1611680 | AB24: 3287 | AC24: 438270 | AD24: 430 | AE24: 1156 | AF24: 0 | AG24: 4850 | AH24: 1 | AK24: 597360 | AL24: 190 | AM24: 1384 | AN24: 3 | AO24: 53710 | AP24: 12 | AQ24: 9043 | AR24: 2 | AS24: 10725 | AT24: 5 | AU24: 15467 | AV24: 18 | AW24: 19719 | AX24: 9 | AY24: 20805 | AZ24: 3 | BA24: 14037 | BB24: 3 | BC24: 6350 | BD24: 2 | BE24: 26950 | BF24: 6 | BG24: 4646 | BH24: 8 | BI24: 15871 | BJ24: 103 | BK24: 3636 | BL24: 0 | BM24: 24 | BN24: 166 | BO24: 615870 | BP24: 130 | BQ24: 1451 | BR24: 5 | BS24: 804200 | BT24: 260 | BU24: 1228 | BV24: 5 | BW24: 70 | BX24: 390 | BY24: 62 | BZ24: 109 | CA24: 13102.023 | CC24: 0 | CD24: 218563 | CE24: 180 | CF24: 1027.8 | CG24: 69 | CH24: 7434.75 | CI24: 70 | CJ24: 7542.5 | CK24: 69 | CL24: 7434.75 | CM24: 22412 | CN24: 754.25 | CP24: 37205 | CQ24: 54 | CR24: 131.76 | CS24: 34685 | CT24: 7 | CU24: 17.08 | CV24: 11264 | CW24: 20 | CX24: 48.8 | CY24: 836484 | CZ24: 349 | DA24: 851.56 | DB24: 6801 | DC24: 9 | DD24: 21.51 | DE24: 8167 | DF24: 11 | DG24: 3 | DH24: 4820 | DI24: 9 | DJ24: 2 | DK24: 1938 | DL24: 1 | DM24: 0 | DN24: 5535 | DO24: 11 | DP24: 3 | DQ24: 5120 | DR24: 12 | DS24: 2 | DT24: 5873 | DU24: 11 | DV24: 3 | DW24: 5749 | DX24: 7 | DY24: 16.73 | EA24: 0 | EC24: 0 | EE24: 0 | EG24: 0 | EH24: 98 | EI24: 214 | EJ24: 0.72
