Workbook

Sheet TOTAL
A1: Site Name | B1: Day | C1: Month | D1: Year | E1: Total Electricity Kwh | F1: Electricity Tariff ($/Kwh) | G1: Natual Gas (m3) | H1: Natural Gas $/m3 | I1: Water Utility Supply (m3) m3 | J1: Water Utility Supply (m3) $/m3 | K1: Room Nights
A2: Cairo at Nile Plaza | B2: 1 | C2: 1 | D2: 2022 | E2: =(((Submetering!O2+Submetering!P2)*0.842284+Submetering!Q2+(Submetering!M2+Submetering!N2+Submetering!Y2)*0.7362)+(Submetering!O2+Submetering!P2+Submetering!Q2)*0.1488+(Submetering!M2+Submetering!N2+Submetering!Y2)*0.1167+(Submetering!K2+Submetering!L2-Submetering!Z2-Submetering!AA2-Submetering!AB2-Submetering!AC2-Submetering!Q2)+(Submetering!M2+Submetering!N2+Submetering!Y2)*0.1139) -> 47170.881 | F2: 1.27 | G2: =Gas!C3*0.9147 -> 3427.3809 | H2: 3.65 | I2: =Submetering!H2+Submetering!AD2+Submetering!AE2 -> 636 | J2: 10.03 | K2: =ELECT.!B3 -> 226
A3: Cairo at Nile Plaza | B3: =B2+1 -> 2 | C3: 1 | D3: 2022 | E3: =(((Submetering!O3+Submetering!P3)*0.842284+Submetering!Q3+(Submetering!M3+Submetering!N3+Submetering!Y3)*0.7362)+(Submetering!O3+Submetering!P3+Submetering!Q3)*0.1488+(Submetering!M3+Submetering!N3+Submetering!Y3)*0.1167+(Submetering!K3+Submetering!L3-Submetering!Z3-Submetering!AA3-Submetering!AB3-Submetering!AC3-Submetering!Q3)+(Submetering!M3+Submetering!N3+Submetering!Y3)*0.1139) -> 36629.517 | F3: 1.27 | G3: =Gas!C4*0.9147 -> 2148.6303 | H3: 3.65 | I3: =Submetering!H3+Submetering!AD3+Submetering!AE3 -> 586 | J3: 10.03 | K3: =ELECT.!B4 -> 222
A4: Cairo at Nile Plaza | B4: =B3+1 -> 3 | C4: 1 | D4: 2022 | E4: =(((Submetering!O4+Submetering!P4)*0.842284+Submetering!Q4+(Submetering!M4+Submetering!N4+Submetering!Y4)*0.7362)+(Submetering!O4+Submetering!P4+Submetering!Q4)*0.1488+(Submetering!M4+Submetering!N4+Submetering!Y4)*0.1167+(Submetering!K4+Submetering!L4-Submetering!Z4-Submetering!AA4-Submetering!AB4-Submetering!AC4-Submetering!Q4)+(Submetering!M4+Submetering!N4+Submetering!Y4)*0.1139) -> 58788.707 | F4: 1.27 | G4: =Gas!C5*0.9147 -> 3064.245 | H4: 3.65 | I4: =Submetering!H4+Submetering!AD4+Submetering!AE4 -> 526 | J4: 10.03 | K4: =ELECT.!B5 -> 179
A5: Cairo at Nile Plaza | B5: =B4+1 -> 4 | C5: 1 | D5: 2022 | E5: =(((Submetering!O5+Submetering!P5)*0.842284+Submetering!Q5+(Submetering!M5+Submetering!N5+Submetering!Y5)*0.7362)+(Submetering!O5+Submetering!P5+Submetering!Q5)*0.1488+(Submetering!M5+Submetering!N5+Submetering!Y5)*0.1167+(Submetering!K5+Submetering!L5-Submetering!Z5-Submetering!AA5-Submetering!AB5-Submetering!AC5-Submetering!Q5)+(Submetering!M5+Submetering!N5+Submetering!Y5)*0.1139) -> 41093.803 | F5: 1.27 | G5: =Gas!C6*0.9147 -> 3413.6604 | H5: 3.65 | I5: =Submetering!H5+Submetering!AD5+Submetering!AE5 -> 586 | J5: 10.03 | K5: =ELECT.!B6 -> 181
A6: Cairo at Nile Plaza | B6: =B5+1 -> 5 | C6: 1 | D6: 2022 | E6: =(((Submetering!O6+Submetering!P6)*0.842284+Submetering!Q6+(Submetering!M6+Submetering!N6+Submetering!Y6)*0.7362)+(Submetering!O6+Submetering!P6+Submetering!Q6)*0.1488+(Submetering!M6+Submetering!N6+Submetering!Y6)*0.1167+(Submetering!K6+Submetering!L6-Submetering!Z6-Submetering!AA6-Submetering!AB6-Submetering!AC6-Submetering!Q6)+(Submetering!M6+Submetering!N6+Submetering!Y6)*0.1139) -> 52838.818 | F6: 1.27 | G6: =Gas!C7*0.9147 -> 3079.7949 | H6: 3.65 | I6: =Submetering!H6+Submetering!AD6+Submetering!AE6 -> 546 | J6: 10.03 | K6: =ELECT.!B7 -> 190
A7: Cairo at Nile Plaza | B7: =B6+1 -> 6 | C7: 1 | D7: 2022 | E7: =(((Submetering!O7+Submetering!P7)*0.842284+Submetering!Q7+(Submetering!M7+Submetering!N7+Submetering!Y7)*0.7362)+(Submetering!O7+Submetering!P7+Submetering!Q7)*0.1488+(Submetering!M7+Submetering!N7+Submetering!Y7)*0.1167+(Submetering!K7+Submetering!L7-Submetering!Z7-Submetering!AA7-Submetering!AB7-Submetering!AC7-Submetering!Q7)+(Submetering!M7+Submetering!N7+Submetering!Y7)*0.1139) -> 34019.291 | F7: 1.27 | G7: =Gas!C8*0.9147 -> 3168.5208 | H7: 3.65 | I7: =Submetering!H7+Submetering!AD7+Submetering!AE7 -> 546 | J7: 10.03 | K7: =ELECT.!B8 -> 197
A8: Cairo at Nile Plaza | B8: =B7+1 -> 7 | C8: 1 | D8: 2022 | E8: =(((Submetering!O8+Submetering!P8)*0.842284+Submetering!Q8+(Submetering!M8+Submetering!N8+Submetering!Y8)*0.7362)+(Submetering!O8+Submetering!P8+Submetering!Q8)*0.1488+(Submetering!M8+Submetering!N8+Submetering!Y8)*0.1167+(Submetering!K8+Submetering!L8-Submetering!Z8-Submetering!AA8-Submetering!AB8-Submetering!AC8-Submetering!Q8)+(Submetering!M8+Submetering!N8+Submetering!Y8)*0.1139) -> 58468.092 | F8: 1.27 | G8: =Gas!C9*0.9147 -> 2321.5086 | H8: 3.65 | I8: =Submetering!H8+Submetering!AD8+Submetering!AE8 -> 366 | J8: 10.03 | K8: =ELECT.!B9 -> 125
A9: Cairo at Nile Plaza | B9: =B8+1 -> 8 | C9: 1 | D9: 2022 | E9: =(((Submetering!O9+Submetering!P9)*0.842284+Submetering!Q9+(Submetering!M9+Submetering!N9+Submetering!Y9)*0.7362)+(Submetering!O9+Submetering!P9+Submetering!Q9)*0.1488+(Submetering!M9+Submetering!N9+Submetering!Y9)*0.1167+(Submetering!K9+Submetering!L9-Submetering!Z9-Submetering!AA9-Submetering!AB9-Submetering!AC9-Submetering!Q9)+(Submetering!M9+Submetering!N9+Submetering!Y9)*0.1139) -> 42896.241 | F9: 1.27 | G9: =Gas!C10*0.9147 -> 2840.1435 | H9: 3.65 | I9: =Submetering!H9+Submetering!AD9+Submetering!AE9 -> 566 | J9: 10.03 | K9: =ELECT.!B10 -> 125
A10: Cairo at Nile Plaza | B10: =B9+1 -> 9 | C10: 1 | D10: 2022 | E10: =(((Submetering!O10+Submetering!P10)*0.842284+Submetering!Q10+(Submetering!M10+Submetering!N10+Submetering!Y10)*0.7362)+(Submetering!O10+Submetering!P10+Submetering!Q10)*0.1488+(Submetering!M10+Submetering!N10+Submetering!Y10)*0.1167+(Submetering!K10+Submetering!L10-Submetering!Z10-Submetering!AA10-Submetering!AB10-Submetering!AC10-Submetering!Q10)+(Submetering!M10+Submetering!N10+Submetering!Y10)*0.1139) -> 40182.637 | F10: 1.27 | G10: =Gas!C11*0.9147 -> 2599.5774 | H10: 3.65 | I10: =Submetering!H10+Submetering!AD10+Submetering!AE10 -> 616 | J10: 10.03 | K10: =ELECT.!B11 -> 201
A11: Cairo at Nile Plaza | B11: =B10+1 -> 10 | C11: 1 | D11: 2022 | E11: =(((Submetering!O11+Submetering!P11)*0.842284+Submetering!Q11+(Submetering!M11+Submetering!N11+Submetering!Y11)*0.7362)+(Submetering!O11+Submetering!P11+Submetering!Q11)*0.1488+(Submetering!M11+Submetering!N11+Submetering!Y11)*0.1167+(Submetering!K11+Submetering!L11-Submetering!Z11-Submetering!AA11-Submetering!AB11-Submetering!AC11-Submetering!Q11)+(Submetering!M11+Submetering!N11+Submetering!Y11)*0.1139) -> 51949.423 | F11: 1.27 | G11: =Gas!C12*0.9147 -> 2794.4085 | H11: 3.65 | I11: =Submetering!H11+Submetering!AD11+Submetering!AE11 -> 526 | J11: 10.03 | K11: =ELECT.!B12 -> 188
A12: Cairo at Nile Plaza | B12: =B11+1 -> 11 | C12: 1 | D12: 2022 | E12: =(((Submetering!O12+Submetering!P12)*0.842284+Submetering!Q12+(Submetering!M12+Submetering!N12+Submetering!Y12)*0.7362)+(Submetering!O12+Submetering!P12+Submetering!Q12)*0.1488+(Submetering!M12+Submetering!N12+Submetering!Y12)*0.1167+(Submetering!K12+Submetering!L12-Submetering!Z12-Submetering!AA12-Submetering!AB12-Submetering!AC12-Submetering!Q12)+(Submetering!M12+Submetering!N12+Submetering!Y12)*0.1139) -> 32212.81 | F12: 1.27 | G12: =Gas!C13*0.9147 -> 3084.3684 | H12: 3.65 | I12: =Submetering!H12+Submetering!AD12+Submetering!AE12 -> 986 | J12: 10.03 | K12: =ELECT.!B13 -> 203
A13: Cairo at Nile Plaza | B13: =B12+1 -> 12 | C13: 1 | D13: 2022 | E13: =(((Submetering!O13+Submetering!P13)*0.842284+Submetering!Q13+(Submetering!M13+Submetering!N13+Submetering!Y13)*0.7362)+(Submetering!O13+Submetering!P13+Submetering!Q13)*0.1488+(Submetering!M13+Submetering!N13+Submetering!Y13)*0.1167+(Submetering!K13+Submetering!L13-Submetering!Z13-Submetering!AA13-Submetering!AB13-Submetering!AC13-Submetering!Q13)+(Submetering!M13+Submetering!N13+Submetering!Y13)*0.1139) -> 51885.014 | F13: 1.27 | G13: =Gas!C14*0.9147 -> 2057.1603 | H13: 3.65 | I13: =Submetering!H13+Submetering!AD13+Submetering!AE13 -> 886 | J13: 10.03 | K13: =ELECT.!B14 -> 217
A14: Cairo at Nile Plaza | B14: =B13+1 -> 13 | C14: 1 | D14: 2022 | E14: =(((Submetering!O14+Submetering!P14)*0.842284+Submetering!Q14+(Submetering!M14+Submetering!N14+Submetering!Y14)*0.7362)+(Submetering!O14+Submetering!P14+Submetering!Q14)*0.1488+(Submetering!M14+Submetering!N14+Submetering!Y14)*0.1167+(Submetering!K14+Submetering!L14-Submetering!Z14-Submetering!AA14-Submetering!AB14-Submetering!AC14-Submetering!Q14)+(Submetering!M14+Submetering!N14+Submetering!Y14)*0.1139) -> 42818.976 | F14: 1.27 | G14: =Gas!C15*0.9147 -> 1948.311 | H14: 3.65 | I14: =Submetering!H14+Submetering!AD14+Submetering!AE14 -> 886 | J14: 10.03 | K14: =ELECT.!B15 -> 218
... A32: Cairo at Nile Plaza | B32: =B31+1 -> 31 | C32: 1 | D32: 2022 | E32: =(((Submetering!O32+Submetering!P32)*0.842284+Submetering!Q32+(Submetering!M32+Submetering!N32+Submetering!Y32)*0.7362)+(Submetering!O32+Submetering!P32+Submetering!Q32)*0.1488+(Submetering!M32+Submetering!N32+Submetering!Y32)*0.1167+(Submetering!K32+Submetering!L32-Submetering!Z32-Submetering!AA32-Submetering!AB32-Submetering!AC32-Submetering!Q32)+(Submetering!M32+Submetering!N32+Submetering!Y32)*0.1139) -> 0 | F32: 1.27 | G32: =Gas!C33*0.9147 -> 0 | H32: 3.65 | I32: =Submetering!H32+Submetering!AD32+Submetering!AE32 -> -194 | J32: 10.03 | K32: =ELECT.!B33 -> 164

Sheet Submetering
A1: Site Name | B1: Day | C1: Month | D1: Year | E1: Main (m3) | F1: Podium (m3) | G1: Hotel (m3) | H1: Large (m3) | I1: Feeder 1 (KWh) | J1: Feeder 2 (KWh) | K1: T1 (KWh) | L1: T2 (KWh) | M1: T3 (KWh) | N1: T4 (KWh) | O1: T5 (KWh) | P1: T7 (KWh) | Q1: New Chiller (KWh) | R1: Hotel (BTU) | S1: B.S (BTU) | T1: LS (BTU) | U1: Mall (BTU) | V1: AHU#25 (BTU) | W1: AHU#9 (BTU) | X1: Room Nights | Y1: Loss (KWH) | Z1: Mall (KWH) | AA1: Citadel (KWH) | AB1: Rotana (KWH) | AC1: CIB (KWH) | AD1: Plaza suits water consumption (M3) | AE1: Hotel water consumption (M3)
A2: Cairo at Nile Plaza | B2: 1 | C2: 1 | D2: 2022 | E2: =Water!C3 -> 830 | F2: =Water!E3 -> 520 | G2: =Water!G3 -> 310.5 | H2: =Water!I3 -> 4.347 | I2: =ELECT.!F3 -> 12531 | J2: =ELECT.!H3 -> 36806 | K2: =ELECT.!K3 -> 7986 | L2: =ELECT.!M3 -> 6251 | M2: =ELECT.!O3 -> 6132 | N2: =ELECT.!Q3 -> 2370 | O2: =ELECT.!S3 -> 9345 | P2: =ELECT.!W3*2 -> 20040 | Q2: =ELECT.!D3 -> 320 | R2: =BTU!C3 -> 2.163 | S2: =BTU!F3 -> 0.495 | T2: =BTU!I3 -> 4 | U2: =BTU!O3 -> 1.389 | V2: =BTU!L3 -> 0 | W2: =BTU!R3 -> 0.66 | X2: =ELECT.!B3 -> 226 | Y2: =I2+J2-(K2+L2+M2+N2+O2+P2) -> -2787 | Z2: ='Mall, Citadel, Rotana'!C3+'Mall, Citadel, Rotana'!E3+'Mall, Citadel, Rotana'!G3+'Mall, Citadel, Rotana'!I3 -> 1219 | AA2: ='Mall, Citadel, Rotana'!K3+'Mall, Citadel, Rotana'!M3 -> 320 | AB2: ='Mall, Citadel, Rotana'!O3 -> 83 | AC2: ='Mall, Citadel, Rotana'!Q3+'Mall, Citadel, Rotana'!S3 -> 140 | AD2: =(E2-H2-194)*0.1318 -> 83.251865 | AE2: =E2-H2-AD2-194 -> 548.40113
A3: Cairo at Nile Plaza | B3: =B2+1 -> 2 | C3: 1 | D3: 2022 | E3: =Water!C4 -> 780 | F3: =Water!E4 -> 450 | G3: =Water!G4 -> 275.4 | H3: =Water!I4 -> 4.833 | I3: =ELECT.!F4 -> 8910 | J3: =ELECT.!H4 -> 30604 | K3: =ELECT.!K4 -> 7438 | L3: =ELECT.!M4 -> 4336 | M3: =ELECT.!O4 -> 4456 | N3: =ELECT.!Q4 -> 1972 | O3: =ELECT.!S4 -> 7825 | P3: =ELECT.!W4*2 -> 16136 | Q3: =ELECT.!D4 -> 320 | R3: =BTU!C4 -> 2.205 | S3: =BTU!F4 -> 0.705 | T3: =BTU!I4 -> 5 | U3: =BTU!O4 -> 1.23 | V3: =BTU!L4 -> 0.17 | W3: =BTU!R4 -> 0.27 | X3: =ELECT.!B4 -> 222 | Y3: =I3+J3-(K3+L3+M3+N3+O3+P3) -> -2649 | Z3: ='Mall, Citadel, Rotana'!C4+'Mall, Citadel, Rotana'!E4+'Mall, Citadel, Rotana'!G4+'Mall, Citadel, Rotana'!I4 -> 1557 | AA3: ='Mall, Citadel, Rotana'!K4+'Mall, Citadel, Rotana'!M4 -> 800 | AB3: ='Mall, Citadel, Rotana'!O4 -> 119 | AC3: ='Mall, Citadel, Rotana'!Q4+'Mall, Citadel, Rotana'!S4 -> 117 | AD3: =(E3-H3-194)*0.1318 -> 76.597811 | AE3: =E3-H3-AD3-194 -> 504.56919
A4: Cairo at Nile Plaza | B4: =B3+1 -> 3 | C4: 1 | D4: 2022 | E4: =Water!C5 -> 720 | F4: =Water!E5 -> 370 | G4: =Water!G5 -> 261.9 | H4: =Water!I5 -> 4.59 | I4: =ELECT.!F5 -> 14949 | J4: =ELECT.!H5 -> 46304 | K4: =ELECT.!K5 -> 11184 | L4: =ELECT.!M5 -> 7159 | M4: =ELECT.!O5 -> 7618 | N4: =ELECT.!Q5 -> 2981 | O4: =ELECT.!S5 -> 11524 | P4: =ELECT.!W5*2 -> 24784 | Q4: =ELECT.!D5 -> 320 | R4: =BTU!C5 -> 2.357 | S4: =BTU!F5 -> 0.751 | T4: =BTU!I5 -> 4 | U4: =BTU!O5 -> 1.132 | V4: =BTU!L5 -> 1.85 | W4: =BTU!R5 -> 0.63 | X4: =ELECT.!B5 -> 179 | Y4: =I4+J4-(K4+L4+M4+N4+O4+P4) -> -3997 | Z4: ='Mall, Citadel, Rotana'!C5+'Mall, Citadel, Rotana'!E5+'Mall, Citadel, Rotana'!G5+'Mall, Citadel, Rotana'!I5 -> 1359 | AA4: ='Mall, Citadel, Rotana'!K5+'Mall, Citadel, Rotana'!M5 -> 320 | AB4: ='Mall, Citadel, Rotana'!O5 -> 122 | AC4: ='Mall, Citadel, Rotana'!Q5+'Mall, Citadel, Rotana'!S5 -> 168 | AD4: =(E4-H4-194)*0.1318 -> 68.721838 | AE4: =E4-H4-AD4-194 -> 452.68816
A5: Cairo at Nile Plaza | B5: =B4+1 -> 4 | C5: 1 | D5: 2022 | E5: =Water!C6 -> 780 | F5: =Water!E6 -> 420 | G5: =Water!G6 -> 280.8 | H5: =Water!I6 -> 5.886 | I5: =ELECT.!F6 -> 10902 | J5: =ELECT.!H6 -> 32332 | K5: =ELECT.!K6 -> 7824 | L5: =ELECT.!M6 -> 5445 | M5: =ELECT.!O6 -> 5300 | N5: =ELECT.!Q6 -> 2173 | O5: =ELECT.!S6 -> 8172 | P5: =ELECT.!W6*2 -> 17072 | Q5: =ELECT.!D6 -> 320 | R5: =BTU!C6 -> 2.285 | S5: =BTU!F6 -> 0.778 | T5: =BTU!I6 -> 3 | U5: =BTU!O6 -> 1.044 | V5: =BTU!L6 -> 2.22 | W5: =BTU!R6 -> 0 | X5: =ELECT.!B6 -> 181 | Y5: =I5+J5-(K5+L5+M5+N5+O5+P5) -> -2752 | Z5: ='Mall, Citadel, Rotana'!C6+'Mall, Citadel, Rotana'!E6+'Mall, Citadel, Rotana'!G6+'Mall, Citadel, Rotana'!I6 -> 1196 | AA5: ='Mall, Citadel, Rotana'!K6+'Mall, Citadel, Rotana'!M6 -> 480 | AB5: ='Mall, Citadel, Rotana'!O6 -> 130 | AC5: ='Mall, Citadel, Rotana'!Q6+'Mall, Citadel, Rotana'!S6 -> 0 | AD5: =(E5-H5-194)*0.1318 -> 76.459025 | AE5: =E5-H5-AD5-194 -> 503.65497
A6: Cairo at Nile Plaza | B6: =B5+1 -> 5 | C6: 1 | D6: 2022 | E6: =Water!C7 -> 740 | F6: =Water!E7 -> 420 | G6: =Water!G7 -> 272.7 | H6: =Water!I7 -> 4.347 | I6: =ELECT.!F7 -> 12561 | J6: =ELECT.!H7 -> 42519 | K6: =ELECT.!K7 -> 10536 | L6: =ELECT.!M7 -> 5830 | M6: =ELECT.!O7 -> 6598 | N6: =ELECT.!Q7 -> 2732 | O6: =ELECT.!S7 -> 10881 | P6: =ELECT.!W7*2 -> 22454 | Q6: =ELECT.!D7 -> 320 | R6: =BTU!C7 -> 2.767 | S6: =BTU!F7 -> 0.764 | T6: =BTU!I7 -> 6 | U6: =BTU!O7 -> 1.424 | V6: =BTU!L7 -> 2.34 | W6: =BTU!R7 -> 0 | X6: =ELECT.!B7 -> 190 | Y6: =I6+J6-(K6+L6+M6+N6+O6+P6) -> -3951 | Z6: ='Mall, Citadel, Rotana'!C7+'Mall, Citadel, Rotana'!E7+'Mall, Citadel, Rotana'!G7+'Mall, Citadel, Rotana'!I7 -> 1216 | AA6: ='Mall, Citadel, Rotana'!K7+'Mall, Citadel, Rotana'!M7 -> 480 | AB6: ='Mall, Citadel, Rotana'!O7 -> 117 | AC6: ='Mall, Citadel, Rotana'!Q7+'Mall, Citadel, Rotana'!S7 -> 0 | AD6: =(E6-H6-194)*0.1318 -> 71.389865 | AE6: =E6-H6-AD6-194 -> 470.26313
A7: Cairo at Nile Plaza | B7: =B6+1 -> 6 | C7: 1 | D7: 2022 | E7: =Water!C8 -> 740 | F7: =Water!E8 -> 420 | G7: =Water!G8 -> 272.7 | H7: =Water!I8 -> 4.347 | I7: =ELECT.!F8 -> 8427 | J7: =ELECT.!H8 -> 27588 | K7: =ELECT.!K8 -> 6088 | L7: =ELECT.!M8 -> 3900 | M7: =ELECT.!O8 -> 4408 | N7: =ELECT.!Q8 -> 1731 | O7: =ELECT.!S8 -> 7155 | P7: =ELECT.!W8*2 -> 14800 | Q7: =ELECT.!D8 -> 640 | R7: =BTU!C8 -> 2.265 | S7: =BTU!F8 -> 0.362 | T7: =BTU!I8 -> 4 | U7: =BTU!O8 -> 1.193 | V7: =BTU!L8 -> 0.03 | W7: =BTU!R8 -> 0 | X7: =ELECT.!B8 -> 197 | Y7: =I7+J7-(K7+L7+M7+N7+O7+P7) -> -2067 | Z7: ='Mall, Citadel, Rotana'!C8+'Mall, Citadel, Rotana'!E8+'Mall, Citadel, Rotana'!G8+'Mall, Citadel, Rotana'!I8 -> 1357 | AA7: ='Mall, Citadel, Rotana'!K8+'Mall, Citadel, Rotana'!M8 -> 320 | AB7: ='Mall, Citadel, Rotana'!O8 -> 83 | AC7: ='Mall, Citadel, Rotana'!Q8+'Mall, Citadel, Rotana'!S8 -> 0 | AD7: =(E7-H7-194)*0.1318 -> 71.389865 | AE7: =E7-H7-AD7-194 -> 470.26313
A8: Cairo at Nile Plaza | B8: =B7+1 -> 7 | C8: 1 | D8: 2022 | E8: =Water!C9 -> 560 | F8: =Water!E9 -> 340 | G8: =Water!G9 -> 199.8 | H8: =Water!I9 -> 4.752 | I8: =ELECT.!F9 -> 13765 | J8: =ELECT.!H9 -> 46624 | K8: =ELECT.!K9 -> 9748 | L8: =ELECT.!M9 -> 6355 | M8: =ELECT.!O9 -> 7232 | N8: =ELECT.!Q9 -> 4914 | O8: =ELECT.!S9 -> 12213 | P8: =ELECT.!W9*2 -> 25094 | Q8: =ELECT.!D9 -> 480 | R8: =BTU!C9 -> 2.152 | S8: =BTU!F9 -> 0.345 | T8: =BTU!I9 -> 5 | U8: =BTU!O9 -> 1.162 | V8: =BTU!L9 -> 0 | W8: =BTU!R9 -> 0 | X8: =ELECT.!B9 -> 125 | Y8: =I8+J8-(K8+L8+M8+N8+O8+P8) -> -5167 | Z8: ='Mall, Citadel, Rotana'!C9+'Mall, Citadel, Rotana'!E9+'Mall, Citadel, Rotana'!G9+'Mall, Citadel, Rotana'!I9 -> 1035 | AA8: ='Mall, Citadel, Rotana'!K9+'Mall, Citadel, Rotana'!M9 -> 320 | AB8: ='Mall, Citadel, Rotana'!O9 -> 73 | AC8: ='Mall, Citadel, Rotana'!Q9+'Mall, Citadel, Rotana'!S9 -> 0 | AD8: =(E8-H8-194)*0.1318 -> 47.612486 | AE8: =E8-H8-AD8-194 -> 313.63551
A9: Cairo at Nile Plaza | B9: =B8+1 -> 8 | C9: 1 | D9: 2022 | E9: =Water!C10 -> 760 | F9: =Water!E10 -> 400 | G9: =Water!G10 -> 259.2 | H9: =Water!I10 -> 4.32 | I9: =ELECT.!F10 -> 10649 | J9: =ELECT.!H10 -> 34766 | K9: =ELECT.!K10 -> 7880 | L9: =ELECT.!M10 -> 4758 | M9: =ELECT.!O10 -> 5760 | N9: =ELECT.!Q10 -> 236 | O9: =ELECT.!S10 -> 8710 | P9: =ELECT.!W10*2 -> 18914 | Q9: =ELECT.!D10 -> 320 | R9: =BTU!C10 -> 2.259 | S9: =BTU!F10 -> 0.423 | T9: =BTU!I10 -> 4 | U9: =BTU!O10 -> 1.293 | V9: =BTU!L10 -> 0 | W9: =BTU!R10 -> 0 | X9: =ELECT.!B10 -> 125 | Y9: =I9+J9-(K9+L9+M9+N9+O9+P9) -> -843 | Z9: ='Mall, Citadel, Rotana'!C10+'Mall, Citadel, Rotana'!E10+'Mall, Citadel, Rotana'!G10+'Mall, Citadel, Rotana'!I10 -> 1351 | AA9: ='Mall, Citadel, Rotana'!K10+'Mall, Citadel, Rotana'!M10 -> 320 | AB9: ='Mall, Citadel, Rotana'!O10 -> 93 | AC9: ='Mall, Citadel, Rotana'!Q10+'Mall, Citadel, Rotana'!S10 -> 385 | AD9: =(E9-H9-194)*0.1318 -> 74.029424 | AE9: =E9-H9-AD9-194 -> 487.65058
A10: Cairo at Nile Plaza | B10: =B9+1 -> 9 | C10: 1 | D10: 2022 | E10: =Water!C11 -> 810 | F10: =Water!E11 -> 430 | G10: =Water!G11 -> 321.3 | H10: =Water!I11 -> 5.616 | I10: =ELECT.!F11 -> 10085 | J10: =ELECT.!H11 -> 32173 | K10: =ELECT.!K11 -> 9864 | L10: =ELECT.!M11 -> 4715 | M10: =ELECT.!O11 -> 5238 | N10: =ELECT.!Q11 -> 2020 | O10: =ELECT.!S11 -> 8183 | P10: =ELECT.!W11*2 -> 17182 | Q10: =ELECT.!D11 -> 320 | R10: =BTU!C11 -> 1.566 | S10: =BTU!F11 -> 0.407 | T10: =BTU!I11 -> 3 | U10: =BTU!O11 -> 0.696 | V10: =BTU!L11 -> 0 | W10: =BTU!R11 -> 0 | X10: =ELECT.!B11 -> 201 | Y10: =I10+J10-(K10+L10+M10+N10+O10+P10) -> -4944 | Z10: ='Mall, Citadel, Rotana'!C11+'Mall, Citadel, Rotana'!E11+'Mall, Citadel, Rotana'!G11+'Mall, Citadel, Rotana'!I11 -> 1192 | AA10: ='Mall, Citadel, Rotana'!K11+'Mall, Citadel, Rotana'!M11 -> 320 | AB10: ='Mall, Citadel, Rotana'!O11 -> 79 | AC10: ='Mall, Citadel, Rotana'!Q11+'Mall, Citadel, Rotana'!S11 -> 229 | AD10: =(E10-H10-194)*0.1318 -> 80.448611 | AE10: =E10-H10-AD10-194 -> 529.93539
A11: Cairo at Nile Plaza | B11: =B10+1 -> 10 | C11: 1 | D11: 2022 | E11: =Water!C12 -> 720 | F11: =Water!E12 -> 350 | G11: =Water!G12 -> 305.1 | H11: =Water!I12 -> 4.941 | I11: =ELECT.!F12 -> 7718 | J11: =ELECT.!H12 -> 46960 | K11: =ELECT.!K12 -> 8172 | L11: =ELECT.!M12 -> 5628 | M11: =ELECT.!O12 -> 1958 | N11: =ELECT.!Q12 -> 6254 | O11: =ELECT.!S12 -> 11303 | P11: =ELECT.!W12*2 -> 22882 | Q11: =ELECT.!D12 -> 480 | R11: =BTU!C12 -> 2.191 | S11: =BTU!F12 -> 0.577 | T11: =BTU!I12 -> 5 | U11: =BTU!O12 -> 1.085 | V11: =BTU!L12 -> 0 | W11: =BTU!R12 -> 0 | X11: =ELECT.!B12 -> 188 | Y11: =I11+J11-(K11+L11+M11+N11+O11+P11) -> -1519 | Z11: ='Mall, Citadel, Rotana'!C12+'Mall, Citadel, Rotana'!E12+'Mall, Citadel, Rotana'!G12+'Mall, Citadel, Rotana'!I12 -> 1242 | AA11: ='Mall, Citadel, Rotana'!K12+'Mall, Citadel, Rotana'!M12 -> 800 | AB11: ='Mall, Citadel, Rotana'!O12 -> 162 | AC11: ='Mall, Citadel, Rotana'!Q12+'Mall, Citadel, Rotana'!S12 -> 69 | AD11: =(E11-H11-194)*0.1318 -> 68.675576 | AE11: =E11-H11-AD11-194 -> 452.38342
A12: Cairo at Nile Plaza | B12: =B11+1 -> 11 | C12: 1 | D12: 2022 | E12: =Water!C13 -> 1180 | F12: =Water!E13 -> 850 | G12: =Water!G13 -> 267.3 | H12: =Water!I13 -> 5.859 | I12: =ELECT.!F13 -> 4948 | J12: =ELECT.!H13 -> 29711 | K12: =ELECT.!K13 -> 6404 | L12: =ELECT.!M13 -> 3861 | M12: =ELECT.!O13 -> 1010 | N12: =ELECT.!Q13 -> 4544 | O12: =ELECT.!S13 -> 7058 | P12: =ELECT.!W13*2 -> 14078 | Q12: =ELECT.!D13 -> 480 | R12: =BTU!C13 -> 2.935 | S12: =BTU!F13 -> 0.85 | T12: =BTU!I13 -> 6 | U12: =BTU!O13 -> 1.429 | V12: =BTU!L13 -> 0 | W12: =BTU!R13 -> 0 | X12: =ELECT.!B13 -> 203 | Y12: =I12+J12-(K12+L12+M12+N12+O12+P12) -> -2296 | Z12: ='Mall, Citadel, Rotana'!C13+'Mall, Citadel, Rotana'!E13+'Mall, Citadel, Rotana'!G13+'Mall, Citadel, Rotana'!I13 -> 1340 | AA12: ='Mall, Citadel, Rotana'!K13+'Mall, Citadel, Rotana'!M13 -> 640 | AB12: ='Mall, Citadel, Rotana'!O13 -> 114 | AC12: ='Mall, Citadel, Rotana'!Q13+'Mall, Citadel, Rotana'!S13 -> 127 | AD12: =(E12-H12-194)*0.1318 -> 129.18258 | AE12: =E12-H12-AD12-194 -> 850.95842
A13: Cairo at Nile Plaza | B13: =B12+1 -> 12 | C13: 1 | D13: 2022 | E13: =Water!C14 -> 1080 | F13: =Water!E14 -> 690 | G13: =Water!G14 -> 280.8 | H13: =Water!I14 -> 4.725 | I13: =ELECT.!F14 -> 7734 | J13: =ELECT.!H14 -> 46691 | K13: =ELECT.!K14 -> 10482 | L13: =ELECT.!M14 -> 5859 | M13: =ELECT.!O14 -> 1718 | N13: =ELECT.!Q14 -> 7434 | O13: =ELECT.!S14 -> 10872 | P13: =ELECT.!W14*2 -> 21898 | Q13: =ELECT.!D14 -> 320 | R13: =BTU!C14 -> 1.35 | S13: =BTU!F14 -> 0.391 | T13: =BTU!I14 -> 3 | U13: =BTU!O14 -> 0.61 | V13: =BTU!L14 -> 0 | W13: =BTU!R14 -> 0 | X13: =ELECT.!B14 -> 217 | Y13: =I13+J13-(K13+L13+M13+N13+O13+P13) -> -3838 | Z13: ='Mall, Citadel, Rotana'!C14+'Mall, Citadel, Rotana'!E14+'Mall, Citadel, Rotana'!G14+'Mall, Citadel, Rotana'!I14 -> 1358 | AA13: ='Mall, Citadel, Rotana'!K14+'Mall, Citadel, Rotana'!M14 -> 640 | AB13: ='Mall, Citadel, Rotana'!O14 -> 119 | AC13: ='Mall, Citadel, Rotana'!Q14+'Mall, Citadel, Rotana'!S14 -> 2 | AD13: =(E13-H13-194)*0.1318 -> 116.15205 | AE13: =E13-H13-AD13-194 -> 765.12296
A14: Cairo at Nile Plaza | B14: =B13+1 -> 13 | C14: 1 | D14: 2022 | E14: =Water!C15 -> 1080 | F14: =Water!E15 -> 920 | G14: =Water!G15 -> 278.1 | H14: =Water!I15 -> 4.185 | I14: =ELECT.!F15 -> 5856 | J14: =ELECT.!H15 -> 38797 | K14: =ELECT.!K15 -> 8426 | L14: =ELECT.!M15 -> 4544 | M14: =ELECT.!O15 -> 1192 | N14: =ELECT.!Q15 -> 6350 | O14: =ELECT.!S15 -> 9162 | P14: =ELECT.!W15*2 -> 18034 | Q14: =ELECT.!D15 -> 480 | R14: =BTU!C15 -> 2.249 | S14: =BTU!F15 -> 0.624 | T14: =BTU!I15 -> 4 | U14: =BTU!O15 -> 1.007 | V14: =BTU!L15 -> 0 | W14: =BTU!R15 -> 0 | X14: =ELECT.!B15 -> 218 | Y14: =I14+J14-(K14+L14+M14+N14+O14+P14) -> -3055 | Z14: ='Mall, Citadel, Rotana'!C15+'Mall, Citadel, Rotana'!E15+'Mall, Citadel, Rotana'!G15+'Mall, Citadel, Rotana'!I15 -> 1074 | AA14: ='Mall, Citadel, Rotana'!K15+'Mall, Citadel, Rotana'!M15 -> 320 | AB14: ='Mall, Citadel, Rotana'!O15 -> 120 | AC14: ='Mall, Citadel, Rotana'!Q15+'Mall, Citadel, Rotana'!S15 -> 0 | AD14: =(E14-H14-194)*0.1318 -> 116.22322 | AE14: =E14-H14-AD14-194 -> 765.59178
... A29: Cairo at Nile Plaza | B29: =B28+1 -> 28 | C29: 1 | D29: 2022 | E29: =Water!C30 -> 0 | F29: =Water!E30 -> 0 | G29: =Water!G30 -> 0 | H29: =Water!I30 -> 0 | I29: =ELECT.!F30 -> 0 | J29: =ELECT.!H30 -> 0 | K29: =ELECT.!K30 -> 0 | L29: =ELECT.!M30 -> 0 | M29: =ELECT.!O30 -> 0 | N29: =ELECT.!Q30 -> 0 | O29: =ELECT.!S30 -> 0 | P29: =ELECT.!W30*2 -> 0 | Q29: =ELECT.!D30 -> 0 | R29: =BTU!C30 -> 0 | S29: =BTU!F30 -> 0 | T29: =BTU!I30 -> 0 | U29: =BTU!O30 -> 0 | V29: =BTU!L30 -> 0 | W29: =BTU!R30 -> 0 | X29: =ELECT.!B30 -> 164 | Y29: =I29+J29-(K29+L29+M29+N29+O29+P29) -> 0 | Z29: ='Mall, Citadel, Rotana'!C30+'Mall, Citadel, Rotana'!E30+'Mall, Citadel, Rotana'!G30+'Mall, Citadel, Rotana'!I30 -> 0 | AA29: ='Mall, Citadel, Rotana'!K30+'Mall, Citadel, Rotana'!M30 -> 0 | AB29: ='Mall, Citadel, Rotana'!O30 -> 0 | AC29: ='Mall, Citadel, Rotana'!Q30+'Mall, Citadel, Rotana'!S30 -> 0 | AD29: =(E29-H29-194)*0.1318 -> -25.5692 | AE29: =E29-H29-AD29-194 -> -168.4308
A30: Cairo at Nile Plaza | B30: =B29+1 -> 29 | C30: 1 | D30: 2022 | E30: =Water!C31 -> 0 | F30: =Water!E31 -> 0 | G30: =Water!E31 -> 0 | H30: =Water!I31 -> 0 | I30: =Water!G31 -> 0 | J30: =ELECT.!H31 -> 0 | K30: =Water!I31 -> 0 | L30: =Water!J31 -> 0 | M30: =Water!K31 -> 0 | N30: =Water!L31 -> 0 | O30: =Water!M31 -> 0 | P30: =Water!N31 -> 0 | Q30: =Water!O31 -> 0 | R30: =BTU!C31 -> 0 | S30: =BTU!F31 -> 0 | T30: =BTU!I31 -> 0 | U30: =BTU!O31 -> 0 | V30: =BTU!L31 -> 0 | W30: =BTU!R31 -> 0 | X30: =ELECT.!B31 -> 164 | Y30: =I30+J30-(K30+L30+M30+N30+O30+P30) -> 0 | Z30: ='Mall, Citadel, Rotana'!C31+'Mall, Citadel, Rotana'!E31+'Mall, Citadel, Rotana'!G31+'Mall, Citadel, Rotana'!I31 -> 0 | AA30: ='Mall, Citadel, Rotana'!K31+'Mall, Citadel, Rotana'!M31 -> 0 | AB30: ='Mall, Citadel, Rotana'!O31 -> 0 | AC30: ='Mall, Citadel, Rotana'!Q31+'Mall, Citadel, Rotana'!S31 -> 0 | AD30: =(E30-H30-194)*0.1318 -> -25.5692 | AE30: =E30-H30-AD30-194 -> -168.4308
A31: Cairo at Nile Plaza | B31: =B30+1 -> 30 | C31: 1 | D31: 2022 | E31: =Water!C32 -> 0 | F31: =Water!E32 -> 0 | G31: =Water!E32 -> 0 | H31: =Water!I32 -> 0 | I31: =Water!G32 -> 0 | J31: =ELECT.!H32 -> 0 | K31: =Water!I32 -> 0 | L31: =Water!J32 -> 0 | M31: =Water!K32 -> 0 | N31: =Water!L32 -> 0 | O31: =Water!M32 -> 0 | P31: =Water!N32 -> 0 | Q31: =Water!O32 -> 0 | R31: =BTU!C32 -> 0 | S31: =BTU!F32 -> 0 | T31: =BTU!I32 -> 0 | U31: =BTU!O32 -> 0 | V31: =BTU!L32 -> 0 | W31: =BTU!R32 -> 0 | X31: =ELECT.!B32 -> 164 | Y31: =I31+J31-(K31+L31+M31+N31+O31+P31) -> 0 | Z31: ='Mall, Citadel, Rotana'!C32+'Mall, Citadel, Rotana'!E32+'Mall, Citadel, Rotana'!G32+'Mall, Citadel, Rotana'!I32 -> 0 | AA31: ='Mall, Citadel, Rotana'!K32+'Mall, Citadel, Rotana'!M32 -> 0 | AB31: ='Mall, Citadel, Rotana'!O32 -> 0 | AC31: ='Mall, Citadel, Rotana'!Q32+'Mall, Citadel, Rotana'!S32 -> 0 | AD31: =(E31-H31-194)*0.1318 -> -25.5692 | AE31: =E31-H31-AD31-194 -> -168.4308
A32: Cairo at Nile Plaza | B32: =B31+1 -> 31 | C32: 1 | D32: 2022 | E32: =Water!C33 -> 0 | F32: =Water!E33 -> 0 | G32: =Water!E33 -> 0 | H32: =Water!I33 -> 0 | I32: =Water!G33 -> 0 | J32: =ELECT.!H33 -> 0 | K32: =Water!I33 -> 0 | L32: =Water!J33 -> 0 | M32: =Water!K33 -> 0 | N32: =Water!L33 -> 0 | O32: =Water!M33 -> 0 | P32: =Water!N33 -> 0 | Q32: =Water!O33 -> 0 | R32: =BTU!C33 -> 0 | S32: =BTU!F33 -> 0 | T32: =BTU!I33 -> 0 | U32: =BTU!O33 -> 0 | V32: =BTU!L33 -> 0 | W32: =BTU!R33 -> 0 | X32: =ELECT.!B33 -> 164 | Y32: =I32+J32-(K32+L32+M32+N32+O32+P32) -> 0 | Z32: ='Mall, Citadel, Rotana'!C33+'Mall, Citadel, Rotana'!E33+'Mall, Citadel, Rotana'!G33+'Mall, Citadel, Rotana'!I33 -> 0 | AA32: ='Mall, Citadel, Rotana'!K33+'Mall, Citadel, Rotana'!M33 -> 0 | AB32: ='Mall, Citadel, Rotana'!O33 -> 0 | AC32: ='Mall, Citadel, Rotana'!Q33+'Mall, Citadel, Rotana'!S33 -> 0 | AD32: =(E32-H32-194)*0.1318 -> -25.5692 | AE32: =E32-H32-AD32-194 -> -168.4308

Sheet Mall, Citadel, Rotana
A1: Day | B1: R1 | C1: Cons | D1: R2 | E1: Cons | F1: R3 | G1: Cons | H1: R4 | I1: Cons | J1: RO1 | K1: Cons | L1: RO2 | M1: Cons | N1: ROE | O1: Cons | P1: CIB. 1 | Q1: Cons | R1: CIB. E | S1: Cons | T1: Co | U1: Cons
A2: 44561 | B2: 46419 | C2: 0 | D2: 40169 | F2: 21164 | H2: 253097 | J2: 303517 | K2: 0 | L2: 25728 | N2: 218807 | P2: =P1 -> CIB. 1 | R2: 55047 | S2: 0 | T2: 3889
A3: 44562 | B3: 46424 | C3: =(B3-B2)*800/5 -> 800 | D3: 40171 | E3: =(D3-D2)*800/5 -> 320 | F3: 21168 | G3: =(F3-F2)*100/5 -> 80 | H3: 253116 | I3: =(H3-H2) -> 19 | J3: 303517 | K3: 0 | L3: 25730 | M3: =(L3-L2)*800/5 -> 320 | N3: 218890 | O3: =N3-N2 -> 83 | P3: 136382 | Q3: 140 | R3: =R2 -> 55047 | S3: 0 | T3: 3890 | U3: =(T3-T2)*800/5 -> 160
A4: 44563 | B4: 46429 | C4: =(B4-B3)*800/5 -> 800 | D4: 40175 | E4: =(D4-D3)*800/5 -> 640 | F4: 21173 | G4: =(F4-F3)*100/5 -> 100 | H4: 253133 | I4: =(H4-H3) -> 17 | J4: 303517 | K4: 0 | L4: 25735 | M4: =(L4-L3)*800/5 -> 800 | N4: 219009 | O4: =N4-N3 -> 119 | P4: 136499 | Q4: =P4-P3 -> 117 | R4: =R3 -> 55047 | S4: =R4-R3 -> 0 | T4: 3891 | U4: =(T4-T3)*800/5 -> 160
A5: 44564 | B5: 46434 | C5: =(B5-B4)*800/5 -> 800 | D5: 40178 | E5: =(D5-D4)*800/5 -> 480 | F5: 21176 | G5: =(F5-F4)*100/5 -> 60 | H5: 253152 | I5: =(H5-H4) -> 19 | J5: =J4 -> 303517 | K5: 0 | L5: 25737 | M5: =(L5-L4)*800/5 -> 320 | N5: 219131 | O5: =N5-N4 -> 122 | P5: 136667 | Q5: =P5-P4 -> 168 | R5: =R4 -> 55047 | S5: =R5-R4 -> 0 | T5: 3893 | U5: =(T5-T4)*800/5 -> 320
A6: 44565 | B6: 46438 | C6: =(B6-B5)*800/5 -> 640 | D6: 40181 | E6: =(D6-D5)*800/5 -> 480 | F6: 21179 | G6: =(F6-F5)*100/5 -> 60 | H6: 253168 | I6: =(H6-H5) -> 16 | J6: 303517 | K6: 0 | L6: 25740 | M6: =(L6-L5)*800/5 -> 480 | N6: 219261 | O6: =N6-N5 -> 130 | P6: =P5 -> 136667 | Q6: =P6-P5 -> 0 | R6: =R5 -> 55047 | S6: 0 | T6: 3894 | U6: =(T6-T5)*800/5 -> 160
A7: 44566 | B7: 46443 | C7: =(B7-B6)*800/5 -> 800 | D7: 40183 | E7: =(D7-D6)*800/5 -> 320 | F7: 21183 | G7: =(F7-F6)*100/5 -> 80 | H7: 253184 | I7: =(H7-H6) -> 16 | J7: 303517 | K7: 0 | L7: 25743 | M7: =(L7-L6)*800/5 -> 480 | N7: 219378 | O7: =N7-N6 -> 117 | P7: =P6 -> 136667 | Q7: 0 | R7: =R6 -> 55047 | S7: 0 | T7: 3895 | U7: =(T7-T6)*800/5 -> 160
A8: 44567 | B8: 46448 | C8: =(B8-B7)*800/5 -> 800 | D8: 40186 | E8: =(D8-D7)*800/5 -> 480 | F8: 21186 | G8: =(F8-F7)*100/5 -> 60 | H8: 253201 | I8: =(H8-H7) -> 17 | J8: 303517 | K8: 0 | L8: 25745 | M8: =(L8-L7)*800/5 -> 320 | N8: 219461 | O8: =N8-N7 -> 83 | P8: =P7 -> 136667 | Q8: =P8-P7 -> 0 | R8: 55047 | S8: =R8-R7 -> 0 | T8: 3896 | U8: =(T8-T7)*800/5 -> 160
A9: 44568 | B9: 46452 | C9: =(B9-B8)*800/5 -> 640 | D9: 40188 | E9: =(D9-D8)*800/5 -> 320 | F9: 21189 | G9: =(F9-F8)*100/5 -> 60 | H9: 253216 | I9: =(H9-H8) -> 15 | J9: 303517 | K9: 0 | L9: 25747 | M9: =(L9-L8)*800/5 -> 320 | N9: 219534 | O9: =N9-N8 -> 73 | P9: =P8 -> 136667 | Q9: =P9-P8 -> 0 | R9: =R8 -> 55047 | S9: =R9-R8 -> 0 | T9: 3897 | U9: =(T9-T8)*800/5 -> 160
A10: 44569 | B10: 46457 | C10: =(B10-B9)*800/5 -> 800 | D10: 40191 | E10: =(D10-D9)*800/5 -> 480 | F10: 21192 | G10: =(F10-F9)*100/5 -> 60 | H10: 253227 | I10: =(H10-H9) -> 11 | J10: =J9 -> 303517 | K10: 0 | L10: 25749 | M10: =(L10-L9)*800/5 -> 320 | N10: 219627 | O10: =N10-N9 -> 93 | P10: 137052 | Q10: =P10-P9 -> 385 | R10: =R9 -> 55047 | S10: =R10-R9 -> 0 | T10: 3898 | U10: =(T10-T9)*800/5 -> 160
A11: 44570 | B11: 46461 | C11: =(B11-B10)*800/5 -> 640 | D11: 40194 | E11: =(D11-D10)*800/5 -> 480 | F11: 21195 | G11: =(F11-F10)*100/5 -> 60 | H11: 253239 | I11: =(H11-H10) -> 12 | J11: =J10 -> 303517 | K11: 0 | L11: 25751 | M11: =(L11-L10)*800/5 -> 320 | N11: 219706 | O11: =N11-N10 -> 79 | P11: 137281 | Q11: =P11-P10 -> 229 | R11: =R10 -> 55047 | S11: =R11-R10 -> 0 | T11: 3899 | U11: =(T11-T10)*800/5 -> 160
A12: 44571 | B12: 46466 | C12: =(B12-B11)*800/5 -> 800 | D12: 40196 | E12: =(D12-D11)*800/5 -> 320 | F12: 21200 | G12: =(F12-F11)*100/5 -> 100 | H12: 253261 | I12: =(H12-H11) -> 22 | J12: =J11 -> 303517 | K12: 0 | L12: 25756 | M12: =(L12-L11)*800/5 -> 800 | N12: 219868 | O12: =N12-N11 -> 162 | P12: 137350 | Q12: =P12-P11 -> 69 | R12: =R11 -> 55047 | S12: =R12-R11 -> 0 | T12: 3900 | U12: =(T12-T11)*800/5 -> 160
A13: 44572 | B13: 46471 | C13: =(B13-B12)*800/5 -> 800 | D13: 40199 | E13: =(D13-D12)*800/5 -> 480 | F13: 21202 | G13: =(F13-F12)*100/5 -> 40 | H13: 253281 | I13: =(H13-H12) -> 20 | J13: 303517 | K13: 0 | L13: 25760 | M13: =(L13-L12)*800/5 -> 640 | N13: 219982 | O13: =N13-N12 -> 114 | P13: 137477 | Q13: =P13-P12 -> 127 | R13: 55047 | S13: =R13-R12 -> 0 | T13: 3901 | U13: =(T13-T12)*800/5 -> 160
A14: 44573 | B14: 46475 | C14: =(B14-B13)*800/5 -> 640 | D14: 40203 | E14: =(D14-D13)*800/5 -> 640 | F14: 21205 | G14: =(F14-F13)*100/5 -> 60 | H14: 253299 | I14: =(H14-H13) -> 18 | J14: 303517 | K14: 0 | L14: 25764 | M14: =(L14-L13)*800/5 -> 640 | N14: 220101 | O14: =N14-N13 -> 119 | P14: 137479 | Q14: =P14-P13 -> 2 | R14: =R13 -> 55047 | S14: 0 | T14: 3902 | U14: =(T14-T13)*800/5 -> 160
A15: 44574 | B15: 46480 | C15: =(B15-B14)*800/5 -> 800 | D15: 40204 | E15: =(D15-D14)*800/5 -> 160 | F15: 21210 | G15: =(F15-F14)*100/5 -> 100 | H15: 253313 | I15: =(H15-H14) -> 14 | J15: 303517 | K15: 0 | L15: 25766 | M15: =(L15-L14)*800/5 -> 320 | N15: 220221 | O15: =N15-N14 -> 120 | P15: =P14 -> 137479 | Q15: =P15-P14 -> 0 | R15: 55047 | S15: 0 | T15: 3902 | U15: =(T15-T14)*800/5 -> 0
A16: 44575 | B16: 46485 | C16: =(B16-B15)*800/5 -> 800 | D16: 40207 | E16: =(D16-D15)*800/5 -> 480 | F16: 21214 | G16: =(F16-F15)*100/5 -> 80 | H16: 253325 | I16: =(H16-H15) -> 12 | J16: 305317 | K16: 0 | L16: 25769 | M16: =(L16-L15)*800/5 -> 480 | N16: 220328 | O16: =N16-N15 -> 107 | P16: =P15 -> 137479 | Q16: =P16-P15 -> 0 | R16: =R15 -> 55047 | S16: =R16-R15 -> 0 | T16: 3903 | U16: =(T16-T15)*800/5 -> 160
A17: 44576 | B17: 46489 | C17: =(B17-B16)*800/5 -> 640 | D17: 40211 | E17: =(D17-D16)*800/5 -> 640 | F17: 21218 | G17: =(F17-F16)*100/5 -> 80 | H17: 253337 | I17: =(H17-H16) -> 12 | J17: 303517 | K17: 0 | L17: 25772 | M17: =(L17-L16)*800/5 -> 480 | N17: 220412 | O17: =N17-N16 -> 84 | P17: =P16 -> 137479 | Q17: =P17-P16 -> 0 | R17: =R16 -> 55047 | S17: =S16 -> 0 | T17: 3904 | U17: =(T17-T16)*800/5 -> 160
A18: 44577 | B18: 46495 | C18: =(B18-B17)*800/5 -> 960 | D18: 40212 | E18: =(D18-D17)*800/5 -> 160 | F18: 21220 | G18: =(F18-F17)*100/5 -> 40 | H18: 253353 | I18: =(H18-H17) -> 16 | J18: =J17 -> 303517 | K18: 0 | L18: 25774 | M18: =(L18-L17)*800/5 -> 320 | N18: 220542 | O18: =N18-N17 -> 130 | P18: =P17 -> 137479 | Q18: =P18-P17 -> 0 | R18: =R17 -> 55047 | S18: =R18-R17 -> 0 | T18: 3905 | U18: =(T18-T17)*800/5 -> 160
A19: 44578 | B19: 46504 | C19: =(B19-B18)*800/5 -> 1440 | D19: 40217 | E19: =(D19-D18)*800/5 -> 800 | F19: 21227 | G19: =(F19-F18)*100/5 -> 140 | H19: 253382 | I19: =(H19-H18) -> 29 | J19: 303517 | K19: 0 | L19: 25779 | M19: =(L19-L18)*800/5 -> 800 | N19: 220808 | O19: =N19-N18 -> 266 | P19: =P18 -> 137479 | Q19: =P19-P18 -> 0 | R19: =R18 -> 55047 | S19: =R19-R18 -> 0 | T19: 3907 | U19: =(T19-T18)*800/5 -> 320
A20: 44579 | B20: =B19 -> 46504 | C20: =(B20-B19)*800/5 -> 0 | D20: =D19 -> 40217 | E20: =(D20-D19)*800/5 -> 0 | F20: =F19 -> 21227 | G20: =(F20-F19)*100/5 -> 0 | H20: =H19 -> 253382 | I20: =(H20-H19) -> 0 | J20: =J19 -> 303517 | K20: 0 | L20: =L19 -> 25779 | M20: =(L20-L19)*800/5 -> 0 | N20: =N19 -> 220808 | O20: =N20-N19 -> 0 | P20: =P19 -> 137479 | Q20: =P20-P19 -> 0 | R20: =R19 -> 55047 | S20: =R20-R19 -> 0 | T20: =T19 -> 3907 | U20: =(T20-T19)*800/5 -> 0
A21: 44580 | B21: 46509 | C21: =(B21-B20)*800/5 -> 800 | D21: 40219 | E21: =(D21-D20)*800/5 -> 320 | F21: 21231 | G21: =(F21-F20)*100/5 -> 80 | H21: 253394 | I21: =(H21-H20) -> 12 | J21: 303517 | K21: 0 | L21: 25782 | M21: =(L21-L20)*800/5 -> 480 | N21: 220925 | O21: =N21-N20 -> 117 | P21: =P20 -> 137479 | Q21: =P21-P20 -> 0 | R21: =R20 -> 55047 | S21: =R21-R20 -> 0 | T21: 3908 | U21: =(T21-T20)*800/5 -> 160
A22: 44581 | B22: 46514 | C22: =(B22-B21)*800/5 -> 800 | D22: 40222 | E22: =(D22-D21)*800/5 -> 480 | F22: 21235 | G22: =(F22-F21)*100/5 -> 80 | H22: 253409 | I22: =(H22-H21) -> 15 | J22: 303517 | K22: 0 | L22: 25785 | M22: =(L22-L21)*800/5 -> 480 | N22: 221048 | O22: =N22-N21 -> 123 | P22: =P21 -> 137479 | Q22: =P22-P21 -> 0 | R22: =R21 -> 55047 | S22: =R22-R21 -> 0 | T22: 3909 | U22: =(T22-T21)*800/5 -> 160
A23: 44582 | B23: 46519 | C23: =(B23-B22)*800/5 -> 800 | D23: 40226 | E23: =(D23-D22)*800/5 -> 640 | F23: 21240 | G23: =(F23-F22)*100/5 -> 100 | H23: 253427 | I23: =(H23-H22) -> 18 | J23: 303517 | K23: 0 | L23: 25787 | M23: =(L23-L22)*800/5 -> 320 | N23: 221120 | O23: =N23-N22 -> 72 | P23: =P22 -> 137479 | Q23: =P23-P22 -> 0 | R23: =R22 -> 55047 | S23: =R23-R22 -> 0 | T23: 3910 | U23: =(T23-T22)*800/5 -> 160
A24: 44583 | B24: 46523 | C24: =(B24-B23)*800/5 -> 640 | D24: 40228 | E24: =(D24-D23)*800/5 -> 320 | F24: 21243 | G24: =(F24-F23)*100/5 -> 60 | H24: 253439 | I24: =(H24-H23) -> 12 | J24: =J23 -> 303517 | K24: 0 | L24: 25789 | M24: =(L24-L23)*800/5 -> 320 | N24: 221213 | O24: =N24-N23 -> 93 | P24: =P23 -> 137479 | Q24: =P24-P23 -> 0 | R24: =R23 -> 55047 | S24: =R24-R23 -> 0 | T24: 3911 | U24: =(T24-T23)*800/5 -> 160
A25: 44584 | B25: 46528 | C25: =(B25-B24)*800/5 -> 800 | D25: 40231 | E25: =(D25-D24)*800/5 -> 480 | F25: 21247 | G25: =(F25-F24)*100/5 -> 80 | H25: 253452 | I25: =(H25-H24) -> 13 | J25: 303517 | K25: 0 | L25: 25792 | M25: =(L25-L24)*800/5 -> 480 | N25: 221326 | O25: =N25-N24 -> 113 | P25: 137479 | Q25: =P25-P24 -> 0 | R25: 55047 | S25: =R25-R24 -> 0 | T25: 3911 | U25: =(T25-T24)*800/5 -> 0
A26: 44585 | B26: 46533 | C26: =(B26-B25)*800/5 -> 800 | D26: 40234 | E26: =(D26-D25)*800/5 -> 480 | F26: 21250 | G26: =(F26-F25)*100/5 -> 60 | H26: 253464 | I26: =(H26-H25) -> 12 | J26: 303517 | K26: 0 | L26: 25794 | M26: =(L26-L25)*800/5 -> 320 | N26: 221439 | O26: =N26-N25 -> 113 | P26: 138843 | Q26: =P26-P25 -> 1364 | R26: =R25 -> 55047 | S26: =R26-R25 -> 0 | T26: 3912 | U26: =(T26-T25)*800/5 -> 160
A27: 44586 | B27: =B26 -> 46533 | C27: =(B27-B26)*800/5 -> 0 | D27: =D26 -> 40234 | E27: =(D27-D26)*800/5 -> 0 | F27: =F26 -> 21250 | G27: =(F27-F26)*100/5 -> 0 | H27: =H26 -> 253464 | I27: =(H27-H26) -> 0 | J27: =J26 -> 303517 | K27: 0 | L27: =L26 -> 25794 | M27: =(L27-L26)*800/5 -> 0 | N27: =N26 -> 221439 | O27: =N27-N26 -> 0 | P27: =P26 -> 138843 | Q27: =P27-P26 -> 0 | R27: =R26 -> 55047 | S27: =R27-R26 -> 0 | T27: =T26 -> 3912 | U27: =(T27-T26)*800/5 -> 0
A28: 44587 | B28: =B27 -> 46533 | C28: =(B28-B27)*800/5 -> 0 | D28: =D27 -> 40234 | E28: =(D28-D27)*800/5 -> 0 | F28: =F27 -> 21250 | G28: =(F28-F27)*100/5 -> 0 | H28: =H27 -> 253464 | I28: =(H28-H27) -> 0 | J28: =J27 -> 303517 | K28: 0 | L28: =L27 -> 25794 | M28: =(L28-L27)*800/5 -> 0 | N28: =N27 -> 221439 | O28: =N28-N27 -> 0 | P28: =P27 -> 138843 | Q28: =P28-P27 -> 0 | R28: =R27 -> 55047 | S28: =R28-R27 -> 0 | T28: =T27 -> 3912 | U28: =(T28-T27)*800/5 -> 0
A29: 44588 | B29: =B28 -> 46533 | C29: =(B29-B28)*800/5 -> 0 | D29: =D28 -> 40234 | E29: =(D29-D28)*800/5 -> 0 | F29: =F28 -> 21250 | G29: =(F29-F28)*100/5 -> 0 | H29: =H28 -> 253464 | I29: =(H29-H28) -> 0 | J29: =J28 -> 303517 | K29: 0 | L29: =L28 -> 25794 | M29: =(L29-L28)*800/5 -> 0 | N29: =N28 -> 221439 | O29: =N29-N28 -> 0 | P29: =P28 -> 138843 | Q29: =P29-P28 -> 0 | R29: =R28 -> 55047 | S29: =R29-R28 -> 0 | T29: =T28 -> 3912 | U29: =(T29-T28)*800/5 -> 0
A30: 44589 | B30: =B29 -> 46533 | C30: =(B30-B29)*800/5 -> 0 | D30: =D29 -> 40234 | E30: =(D30-D29)*800/5 -> 0 | F30: =F29 -> 21250 | G30: =(F30-F29)*100/5 -> 0 | H30: =H29 -> 253464 | I30: =(H30-H29) -> 0 | J30: =J29 -> 303517 | K30: 0 | L30: =L29 -> 25794 | M30: =(L30-L29)*800/5 -> 0 | N30: =N29 -> 221439 | O30: =N30-N29 -> 0 | P30: =P29 -> 138843 | Q30: =P30-P29 -> 0 | R30: =R29 -> 55047 | S30: =R30-R29 -> 0 | T30: =T29 -> 3912 | U30: =(T30-T29)*800/5 -> 0
A31: 44590 | B31: =B30 -> 46533 | C31: =(B31-B30)*800/5 -> 0 | D31: =D30 -> 40234 | E31: =(D31-D30)*800/5 -> 0 | F31: =F30 -> 21250 | G31: =(F31-F30)*100/5 -> 0 | H31: =H30 -> 253464 | I31: =(H31-H30) -> 0 | J31: =J30 -> 303517 | K31: 0 | L31: =L30 -> 25794 | M31: =(L31-L30)*800/5 -> 0 | N31: =N30 -> 221439 | O31: =N31-N30 -> 0 | P31: =P30 -> 138843 | Q31: =P31-P30 -> 0 | R31: =R30 -> 55047 | S31: =R31-R30 -> 0 | T31: =T30 -> 3912 | U31: =(T31-T30)*800/5 -> 0
A32: 44591 | B32: =B31 -> 46533 | C32: =(B32-B31)*800/5 -> 0 | D32: =D31 -> 40234 | E32: =(D32-D31)*800/5 -> 0 | F32: =F31 -> 21250 | G32: =(F32-F31)*100/5 -> 0 | H32: =H31 -> 253464 | I32: =(H32-H31) -> 0 | J32: =J31 -> 303517 | K32: 0 | L32: =L31 -> 25794 | M32: =(L32-L31)*800/5 -> 0 | N32: =N31 -> 221439 | O32: =N32-N31 -> 0 | P32: =P31 -> 138843 | Q32: =P32-P31 -> 0 | R32: =R31 -> 55047 | S32: 0 | T32: =T31 -> 3912 | U32: =(T32-T31)*800/5 -> 0
A33: 44592 | B33: =B32 -> 46533 | C33: =(B33-B32)*800/5 -> 0 | D33: =D32 -> 40234 | E33: =(D33-D32)*800/5 -> 0 | F33: =F32 -> 21250 | G33: =(F33-F32)*100/5 -> 0 | H33: =H32 -> 253464 | I33: =(H33-H32) -> 0 | J33: 303517 | K33: 0 | L33: =L32 -> 25794 | M33: =(L33-L32)*800/5 -> 0 | N33: =N32 -> 221439 | O33: =N33-N32 -> 0 | P33: =P32 -> 138843 | Q33: =P33-P32 -> 0 | R33: =R32 -> 55047 | S33: 0 | T33: =T32 -> 3912 | U33: =(T33-T32)*800/5 -> 0
A34: Total | C34: =SUM(C4:C33) -> 17440 | E34: =SUM(E4:E33) -> 10080 | G34: =SUM(G4:G33) -> 1640 | I34: =SUM(I4:I33) -> 348 | K34: =SUM(K4:K33) -> 0 | M34: =SUM(M4:M33) -> 10240 | O34: =SUM(O4:O33) -> 2549 | Q34: =SUM(Q4:Q33) -> 2461 | S34: =SUM(S4:S33) -> 0 | U34: =SUM(U4:U33) -> 3520

Sheet ELECT.
A1: Day | B1: Rooms Sold | C1: New Chillers | D1: Cons | E1: F-1 | F1: Cons. | G1: F-2 | H1: Cons. | I1: Total | J1: T-1 | K1: Cons. | L1: T-2 | M1: Cons. | N1: T-3 | O1: Cons. | P1: T-4 | Q1: Cons. | R1: T-5 | S1: Cons. | T1: T-6 | U1: Cons. | V1: T-7 | W1: Cons. | X1: Total | Y1: Diff | Z1: Daily Money Value | AA1: MTD Total Money
A2: 44561 | B2: 286 | C2: 19263 | E2: 29394326 | G2: 93376522 | J2: 9244110 | L2: 9241929 | N2: 6233074 | P2: 5733151 | R2: 19746392 | T2: 0 | V2: 7634077 | X2: =K2+M2+O2+Q2+S2+U2+W2 -> 0 | Z2: =(0.93352*(W2+S2)+0.5568*(Q2+O2))*0.26 -> 0
A3: 44562 | B3: 226 | C3: 19265 | D3: =IF((C3-C2)<0,"0",(C3-C2))*160 -> 320 | E3: 29406857 | F3: =IF((E3-E2)<0,"0",(E3-E2)) -> 12531 | G3: 93413328 | H3: =IF((G3-G2)<0,"0",(G3-G2)) -> 36806 | I3: =F3+H3 -> 49337 | J3: 9248103 | K3: =(IF((J3-J2)<L91,"0",(J3-J2)))*2 -> 7986 | L3: 9248180 | M3: =IF((L3-L2)<0,"0",(L3-L2)) -> 6251 | N3: 6236140 | O3: =(IF((N3-N2)<P91,"0",(N3-N2)))*2 -> 6132 | P3: 5735521 | Q3: =IF((P3-P2)<0,"0",(P3-P2)) -> 2370 | R3: 19755737 | S3: =IF((R3-R2)<0,"0",(R3-R2)) -> 9345 | T3: 0 | V3: 7644097 | W3: =IF((V3-V2)<0,"0",(V3-V2)) -> 10020 | X3: =K3+M3+O3+Q3+S3+U3+W3 -> 42104 | Y3: =I3-X3 -> 7233 | Z3: =(0.93352*(W3+S3)+0.5568*(Q3+O3))*0.26 -> 5930.9974 | AA3: =SUM(Z1:Z3) -> 5930.9974
A4: 44563 | B4: 222 | C4: 19267 | D4: =IF((C4-C3)<0,"0",(C4-C3))*160 -> 320 | E4: 29415767 | F4: =IF((E4-E3)<0,"0",(E4-E3)) -> 8910 | G4: 93443932 | H4: =IF((G4-G3)<0,"0",(G4-G3)) -> 30604 | I4: =F4+H4 -> 39514 | J4: 9251822 | K4: =(IF((J4-J3)<L93,"0",(J4-J3)))*2 -> 7438 | L4: 9252516 | M4: =IF((L4-L3)<0,"0",(L4-L3)) -> 4336 | N4: 6238368 | O4: =(IF((N4-N3)<P93,"0",(N4-N3)))*2 -> 4456 | P4: 5737493 | Q4: =IF((P4-P3)<0,"0",(P4-P3)) -> 1972 | R4: 19763562 | S4: =IF((R4-R3)<0,"0",(R4-R3)) -> 7825 | T4: 0 | V4: 7652165 | W4: =IF((V4-V3)<0,"0",(V4-V3)) -> 8068 | X4: =K4+M4+O4+Q4+S4+U4+W4 -> 34095 | Y4: =I4-X4 -> 5419 | Z4: =(0.93352*(W4+S4)+0.5568*(Q4+O4))*0.26 -> 4788.0414 | AA4: =SUM(Z2:Z4) -> 10719.039
A5: 44564 | B5: 179 | C5: 19269 | D5: =IF((C5-C4)<0,"0",(C5-C4))*160 -> 320 | E5: 29430716 | F5: =IF((E5-E4)<0,"0",(E5-E4)) -> 14949 | G5: 93490236 | H5: =IF((G5-G4)<0,"0",(G5-G4)) -> 46304 | I5: =F5+H5 -> 61253 | J5: 9257414 | K5: =(IF((J5-J4)<0,"0",(J5-J4)))*2 -> 11184 | L5: 9259675 | M5: =IF((L5-L4)<0,"0",(L5-L4)) -> 7159 | N5: 6242177 | O5: =(IF((N5-N4)<0,"0",(N5-N4)))*2 -> 7618 | P5: 5740474 | Q5: =IF((P5-P4)<0,"0",(P5-P4)) -> 2981 | R5: 19775086 | S5: =IF((R5-R4)<0,"0",(R5-R4)) -> 11524 | T5: 0 | V5: 7664557 | W5: =IF((V5-V4)<0,"0",(V5-V4)) -> 12392 | X5: =K5+M5+O5+Q5+S5+U5+W5 -> 52858 | Y5: =I5-X5 -> 8395 | Z5: =(0.93352*(W5+S5)+0.5568*(Q5+O5))*0.26 -> 7339.1728 | AA5: =SUM(Z3:Z5) -> 18058.212
A6: 44565 | B6: 181 | C6: 19271 | D6: =IF((C6-C5)<0,"0",(C6-C5))*160 -> 320 | E6: 29441618 | F6: =IF((E6-E5)<0,"0",(E6-E5)) -> 10902 | G6: 93522568 | H6: =IF((G6-G5)<0,"0",(G6-G5)) -> 32332 | I6: =F6+H6 -> 43234 | J6: 9261326 | K6: =(IF((J6-J5)<0,"0",(J6-J5)))*2 -> 7824 | L6: 9265120 | M6: =IF((L6-L5)<0,"0",(L6-L5)) -> 5445 | N6: 6244827 | O6: =(IF((N6-N5)<0,"0",(N6-N5)))*2 -> 5300 | P6: 5742647 | Q6: =IF((P6-P5)<0,"0",(P6-P5)) -> 2173 | R6: 19783258 | S6: =IF((R6-R5)<0,"0",(R6-R5)) -> 8172 | T6: 0 | V6: 7673093 | W6: =IF((V6-V5)<0,"0",(V6-V5)) -> 8536 | X6: =K6+M6+O6+Q6+S6+U6+W6 -> 37450 | Y6: =I6-X6 -> 5784 | Z6: =(0.93352*(W6+S6)+0.5568*(Q6+O6))*0.26 -> 5137.1368 | AA6: =SUM(Z4:Z6) -> 17264.351
A7: 44566 | B7: 190 | C7: 19273 | D7: =IF((C7-C6)<0,"0",(C7-C6))*160 -> 320 | E7: 29454179 | F7: =IF((E7-E6)<0,"0",(E7-E6)) -> 12561 | G7: 93565087 | H7: =IF((G7-G6)<0,"0",(G7-G6)) -> 42519 | I7: =F7+H7 -> 55080 | J7: 9266594 | K7: =(IF((J7-J6)<0,"0",(J7-J6)))*2 -> 10536 | L7: 9270950 | M7: =IF((L7-L6)<0,"0",(L7-L6)) -> 5830 | N7: 6248126 | O7: =(IF((N7-N6)<0,"0",(N7-N6)))*2 -> 6598 | P7: 5745379 | Q7: =IF((P7-P6)<0,"0",(P7-P6)) -> 2732 | R7: 19794139 | S7: =IF((R7-R6)<0,"0",(R7-R6)) -> 10881 | T7: 0 | V7: 7684320 | W7: =IF((V7-V6)<0,"0",(V7-V6)) -> 11227 | X7: =K7+M7+O7+Q7+S7+U7+W7 -> 47804 | Y7: =I7-X7 -> 7276 | Z7: =(0.93352*(W7+S7)+0.5568*(Q7+O7))*0.26 -> 6716.6331 | AA7: =SUM(Z4:Z7) -> 23980.984
A8: 44567 | B8: 197 | C8: 19277 | D8: =IF((C8-C7)<0,"0",(C8-C7))*160 -> 640 | E8: 29462606 | F8: =IF((E8-E7)<0,"0",(E8-E7)) -> 8427 | G8: 93592675 | H8: =IF((G8-G7)<0,"0",(G8-G7)) -> 27588 | I8: =F8+H8 -> 36015 | J8: 9269638 | K8: =(IF((J8-J7)<0,"0",(J8-J7)))*2 -> 6088 | L8: 9274850 | M8: =IF((L8-L7)<0,"0",(L8-L7)) -> 3900 | N8: 6250330 | O8: =(IF((N8-N7)<0,"0",(N8-N7)))*2 -> 4408 | P8: 5747110 | Q8: =IF((P8-P7)<0,"0",(P8-P7)) -> 1731 | R8: 19801294 | S8: =IF((R8-R7)<0,"0",(R8-R7)) -> 7155 | T8: 0 | V8: 7691720 | W8: =IF((V8-V7)<0,"0",(V8-V7)) -> 7400 | X8: =K8+M8+O8+Q8+S8+U8+W8 -> 30682 | Y8: =I8-X8 -> 5333 | Z8: =(0.93352*(W8+S8)+0.5568*(Q8+O8))*0.26 -> 4421.4505 | AA8: =SUM(Z5:Z8) -> 23614.393
A9: 44568 | B9: 125 | C9: 19280 | D9: =IF((C9-C8)<0,"0",(C9-C8))*160 -> 480 | E9: 29476371 | F9: =IF((E9-E8)<0,"0",(E9-E8)) -> 13765 | G9: 93639299 | H9: =IF((G9-G8)<0,"0",(G9-G8)) -> 46624 | I9: =F9+H9 -> 60389 | J9: 9274512 | K9: =(IF((J9-J8)<0,"0",(J9-J8)))*2 -> 9748 | L9: 9281205 | M9: =IF((L9-L8)<0,"0",(L9-L8)) -> 6355 | N9: 6253946 | O9: =(IF((N9-N8)<0,"0",(N9-N8)))*2 -> 7232 | P9: 5752024 | Q9: =IF((P9-P8)<0,"0",(P9-P8)) -> 4914 | R9: 19813507 | S9: =IF((R9-R8)<0,"0",(R9-R8)) -> 12213 | T9: 0 | V9: 7704267 | W9: =IF((V9-V8)<0,"0",(V9-V8)) -> 12547 | X9: =K9+M9+O9+Q9+S9+U9+W9 -> 53009 | Y9: =I9-X9 -> 7380 | Z9: =(0.93352*(W9+S9)+0.5568*(Q9+O9))*0.26 -> 7767.9805 | AA9: =SUM(Z6:Z9) -> 24043.201
A10: 44569 | B10: =B9 -> 125 | C10: 19282 | D10: =IF((C10-C9)<0,"0",(C10-C9))*160 -> 320 | E10: 29487020 | F10: =IF((E10-E9)<0,"0",(E10-E9)) -> 10649 | G10: 93674065 | H10: =IF((G10-G9)<0,"0",(G10-G9)) -> 34766 | I10: =F10+H10 -> 45415 | J10: 9278452 | K10: =(IF((J10-J9)<0,"0",(J10-J9)))*2 -> 7880 | L10: 9285963 | M10: =IF((L10-L9)<0,"0",(L10-L9)) -> 4758 | N10: 6256826 | O10: =(IF((N10-N9)<0,"0",(N10-N9)))*2 -> 5760 | P10: 5752260 | Q10: =IF((P10-P9)<0,"0",(P10-P9)) -> 236 | R10: 19822217 | S10: =IF((R10-R9)<0,"0",(R10-R9)) -> 8710 | T10: 0 | V10: 7713724 | W10: =IF((V10-V9)<0,"0",(V10-V9)) -> 9457 | X10: =K10+M10+O10+Q10+S10+U10+W10 -> 36801 | Y10: =I10-X10 -> 8614 | Z10: =(0.93352*(W10+S10)+0.5568*(Q10+O10))*0.26 -> 5277.436 | AA10: =SUM(Z7:Z10) -> 24183.5
A11: 44570 | B11: 201 | C11: 19284 | D11: =IF((C11-C10)<0,"0",(C11-C10))*160 -> 320 | E11: 29497105 | F11: =IF((E11-E10)<0,"0",(E11-E10)) -> 10085 | G11: 93706238 | H11: =IF((G11-G10)<0,"0",(G11-G10)) -> 32173 | I11: =F11+H11 -> 42258 | J11: 9283384 | K11: =(IF((J11-J10)<0,"0",(J11-J10)))*2 -> 9864 | L11: 9290678 | M11: =IF((L11-L10)<0,"0",(L11-L10)) -> 4715 | N11: 6259445 | O11: =(IF((N11-N10)<0,"0",(N11-N10)))*2 -> 5238 | P11: 5754280 | Q11: =IF((P11-P10)<0,"0",(P11-P10)) -> 2020 | R11: 19830400 | S11: =IF((R11-R10)<0,"0",(R11-R10)) -> 8183 | T11: 0 | V11: 7722315 | W11: =IF((V11-V10)<0,"0",(V11-V10)) -> 8591 | X11: =K11+M11+O11+Q11+S11+U11+W11 -> 38611 | Y11: =I11-X11 -> 3647 | Z11: =(0.93352*(W11+S11)+0.5568*(Q11+O11))*0.26 -> 5122.0309 | AA11: =SUM(Z8:Z11) -> 22588.898
A12: 44571 | B12: 188 | C12: 19287 | D12: =IF((C12-C11)<0,"0",(C12-C11))*160 -> 480 | E12: 29504823 | F12: =IF((E12-E11)<0,"0",(E12-E11)) -> 7718 | G12: 93753198 | H12: =IF((G12-G11)<0,"0",(G12-G11)) -> 46960 | I12: =F12+H12 -> 54678 | J12: 9287470 | K12: =(IF((J12-J11)<0,"0",(J12-J11)))*2 -> 8172 | L12: 9296306 | M12: =IF((L12-L11)<0,"0",(L12-L11)) -> 5628 | N12: 6260424 | O12: =(IF((N12-N11)<0,"0",(N12-N11)))*2 -> 1958 | P12: 5760534 | Q12: =IF((P12-P11)<0,"0",(P12-P11)) -> 6254 | R12: 19841703 | S12: =IF((R12-R11)<0,"0",(R12-R11)) -> 11303 | T12: 0 | V12: 7733756 | W12: =IF((V12-V11)<0,"0",(V12-V11)) -> 11441 | X12: =K12+M12+O12+Q12+S12+U12+W12 -> 44756 | Y12: =I12-X12 -> 9922 | Z12: =(0.93352*(W12+S12)+0.5568*(Q12+O12))*0.26 -> 6709.1493 | AA12: =SUM(Z9:Z12) -> 24876.597
A13: 44572 | B13: 203 | C13: 19290 | D13: =IF((C13-C12)<0,"0",(C13-C12))*160 -> 480 | E13: 29509771 | F13: =IF((E13-E12)<0,"0",(E13-E12)) -> 4948 | G13: 93782909 | H13: =IF((G13-G12)<0,"0",(G13-G12)) -> 29711 | I13: =F13+H13 -> 34659 | J13: 9290672 | K13: =(IF((J13-J12)<0,"0",(J13-J12)))*2 -> 6404 | L13: 9300167 | M13: =IF((L13-L12)<0,"0",(L13-L12)) -> 3861 | N13: 6260929 | O13: =(IF((N13-N12)<0,"0",(N13-N12)))*2 -> 1010 | P13: 5765078 | Q13: =IF((P13-P12)<0,"0",(P13-P12)) -> 4544 | R13: 19848761 | S13: =IF((R13-R12)<0,"0",(R13-R12)) -> 7058 | T13: 0 | V13: 7740795 | W13: =IF((V13-V12)<0,"0",(V13-V12)) -> 7039 | X13: =K13+M13+O13+Q13+S13+U13+W13 -> 29916 | Y13: =I13-X13 -> 4743 | Z13: =(0.93352*(W13+S13)+0.5568*(Q13+O13))*0.26 -> 4225.5976 | AA13: =SUM(Z10:Z13) -> 21334.214
A14: 44573 | B14: 217 | C14: 19292 | D14: =IF((C14-C13)<0,"0",(C14-C13))*160 -> 320 | E14: 29517505 | F14: =IF((E14-E13)<0,"0",(E14-E13)) -> 7734 | G14: 93829600 | H14: =IF((G14-G13)<0,"0",(G14-G13)) -> 46691 | I14: =F14+H14 -> 54425 | J14: 9295913 | K14: =(IF((J14-J13)<0,"0",(J14-J13)))*2 -> 10482 | L14: 9306026 | M14: =IF((L14-L13)<0,"0",(L14-L13)) -> 5859 | N14: 6261788 | O14: =(IF((N14-N13)<0,"0",(N14-N13)))*2 -> 1718 | P14: 5772512 | Q14: =IF((P14-P13)<0,"0",(P14-P13)) -> 7434 | R14: 19859633 | S14: =IF((R14-R13)<0,"0",(R14-R13)) -> 10872 | T14: 0 | V14: 7751744 | W14: =IF((V14-V13)<0,"0",(V14-V13)) -> 10949 | X14: =K14+M14+O14+Q14+S14+U14+W14 -> 47314 | Y14: =I14-X14 -> 7111 | Z14: =(0.93352*(W14+S14)+0.5568*(Q14+O14))*0.26 -> 6621.2051 | AA14: =SUM(Z11:Z14) -> 22677.983
A15: 44574 | B15: 218 | C15: 19295 | D15: =IF((C15-C14)<0,"0",(C15-C14))*160 -> 480 | E15: 29523361 | F15: =IF((E15-E14)<0,"0",(E15-E14)) -> 5856 | G15: 93868397 | H15: =IF((G15-G14)<0,"0",(G15-G14)) -> 38797 | I15: =F15+H15 -> 44653 | J15: 9300126 | K15: =(IF((J15-J14)<0,"0",(J15-J14)))*2 -> 8426 | L15: 9310570 | M15: =IF((L15-L14)<0,"0",(L15-L14)) -> 4544 | N15: 6262384 | O15: =(IF((N15-N14)<0,"0",(N15-N14)))*2 -> 1192 | P15: 5778862 | Q15: =IF((P15-P14)<0,"0",(P15-P14)) -> 6350 | R15: 19868795 | S15: =IF((R15-R14)<0,"0",(R15-R14)) -> 9162 | T15: 0 | V15: 7760761 | W15: =IF((V15-V14)<0,"0",(V15-V14)) -> 9017 | X15: =K15+M15+O15+Q15+S15+U15+W15 -> 38691 | Y15: =I15-X15 -> 5962 | Z15: =(0.93352*(W15+S15)+0.5568*(Q15+O15))*0.26 -> 5504.1599 | AA15: =SUM(Z12:Z15) -> 23060.112
A16: 44575 | B16: 212 | C16: 19297 | D16: =IF((C16-C15)<0,"0",(C16-C15))*160 -> 320 | E16: 29531355 | F16: =IF((E16-E15)<0,"0",(E16-E15)) -> 7994 | G16: 93921141 | H16: =IF((G16-G15)<0,"0",(G16-G15)) -> 52744 | I16: =F16+H16 -> 60738 | J16: 9305499 | K16: =(IF((J16-J15)<0,"0",(J16-J15)))*2 -> 10746 | L16: 9316719 | M16: =IF((L16-L15)<0,"0",(L16-L15)) -> 6149 | N16: 6263226 | O16: =(IF((N16-N15)<0,"0",(N16-N15)))*2 -> 1684 | P16: 5787510 | Q16: =IF((P16-P15)<0,"0",(P16-P15)) -> 8648 | R16: 19881235 | S16: =IF((R16-R15)<0,"0",(R16-R15)) -> 12440 | T16: 0 | V16: 7773212 | W16: =IF((V16-V15)<0,"0",(V16-V15)) -> 12451 | X16: =K16+M16+O16+Q16+S16+U16+W16 -> 52118 | Y16: =I16-X16 -> 8620 | Z16: =(0.93352*(W16+S16)+0.5568*(Q16+O16))*0.26 -> 7537.167 | AA16: =SUM(Z13:Z16) -> 23888.13
A17: 44576 | B17: 175 | C17: 19299 | D17: =IF((C17-C16)<0,"0",(C17-C16))*160 -> 320 | E17: 29536366 | F17: =IF((E17-E16)<0,"0",(E17-E16)) -> 5011 | G17: 93954613 | H17: =IF((G17-G16)<0,"0",(G17-G16)) -> 33472 | I17: =F17+H17 -> 38483 | J17: 9309109 | K17: =(IF((J17-J16)<0,"0",(J17-J16)))*2 -> 7220 | L17: 9320441 | M17: =IF((L17-L16)<0,"0",(L17-L16)) -> 3722 | N17: 6263819 | O17: =(IF((N17-N16)<0,"0",(N17-N16)))*2 -> 1186 | P17: 5792973 | Q17: =IF((P17-P16)<0,"0",(P17-P16)) -> 5463 | R17: 19889219 | S17: =IF((R17-R16)<0,"0",(R17-R16)) -> 7984 | T17: 0 | V17: 7780936 | W17: =IF((V17-V16)<0,"0",(V17-V16)) -> 7724 | X17: =K17+M17+O17+Q17+S17+U17+W17 -> 33299 | Y17: =I17-X17 -> 5184 | Z17: =(0.93352*(W17+S17)+0.5568*(Q17+O17))*0.26 -> 4775.1328 | AA17: =SUM(Z14:Z17) -> 24437.665
A18: 44577 | B18: 191 | C18: 19302 | D18: =IF((C18-C17)<0,"0",(C18-C17))*160 -> 480 | E18: 29542910 | F18: =IF((E18-E17)<0,"0",(E18-E17)) -> 6544 | G18: 93998424 | H18: =IF((G18-G17)<0,"0",(G18-G17)) -> 43811 | I18: =F18+H18 -> 50355 | J18: 9314010 | K18: =(IF((J18-J17)<0,"0",(J18-J17)))*2 -> 9802 | L18: 9325514 | M18: =IF((L18-L17)<0,"0",(L18-L17)) -> 5073 | N18: 6264482 | O18: =(IF((N18-N17)<0,"0",(N18-N17)))*2 -> 1326 | P18: 5799843 | Q18: =IF((P18-P17)<0,"0",(P18-P17)) -> 6870 | R18: 19899322 | S18: =IF((R18-R17)<0,"0",(R18-R17)) -> 10103 | T18: 0 | V18: 7791275 | W18: =IF((V18-V17)<0,"0",(V18-V17)) -> 10339 | X18: =K18+M18+O18+Q18+S18+U18+W18 -> 43513 | Y18: =I18-X18 -> 6842 | Z18: =(0.93352*(W18+S18)+0.5568*(Q18+O18))*0.26 -> 6148.1026 | AA18: =SUM(Z15:Z18) -> 23964.562
A19: 44578 | B19: 195 | C19: 19304 | D19: =IF((C19-C18)<0,"0",(C19-C18))*160 -> 320 | E19: 29548389 | F19: =IF((E19-E18)<0,"0",(E19-E18)) -> 5479 | G19: 94033585 | H19: =IF((G19-G18)<0,"0",(G19-G18)) -> 35161 | I19: =F19+H19 -> 40640 | J19: 9318060 | K19: =(IF((J19-J18)<0,"0",(J19-J18)))*2 -> 8100 | L19: 9329888 | M19: =IF((L19-L18)<0,"0",(L19-L18)) -> 4374 | N19: 6264987 | O19: =(IF((N19-N18)<0,"0",(N19-N18)))*2 -> 1010 | P19: 5804787 | Q19: =IF((P19-P18)<0,"0",(P19-P18)) -> 4944 | R19: 19907849 | S19: =IF((R19-R18)<0,"0",(R19-R18)) -> 8527 | T19: 0 | V19: 7799675 | W19: =IF((V19-V18)<0,"0",(V19-V18)) -> 8400 | X19: =K19+M19+O19+Q19+S19+U19+W19 -> 35355 | Y19: =I19-X19 -> 5285 | Z19: =(0.93352*(W19+S19)+0.5568*(Q19+O19))*0.26 -> 4970.3889 | AA19: =SUM(Z16:Z19) -> 23430.791
A20: 44579 | B20: 205 | C20: 19305 | D20: =IF((C20-C19)<0,"0",(C20-C19))*160 -> 160 | E20: 29556814 | F20: =IF((E20-E19)<0,"0",(E20-E19)) -> 8425 | G20: 94086434 | H20: =IF((G20-G19)<0,"0",(G20-G19)) -> 52849 | I20: =F20+H20 -> 61274 | J20: 9323982 | K20: =(IF((J20-J19)<0,"0",(J20-J19)))*2 -> 11844 | L20: 9336451 | M20: =IF((L20-L19)<0,"0",(L20-L19)) -> 6563 | N20: 6265843 | O20: =(IF((N20-N19)<0,"0",(N20-N19)))*2 -> 1712 | P20: 5813284 | Q20: =IF((P20-P19)<0,"0",(P20-P19)) -> 8497 | R20: 19920221 | S20: =IF((R20-R19)<0,"0",(R20-R19)) -> 12372 | T20: 0 | V20: 7812026 | W20: =IF((V20-V19)<0,"0",(V20-V19)) -> 12351 | X20: =K20+M20+O20+Q20+S20+U20+W20 -> 53339 | Y20: =I20-X20 -> 7935 | Z20: =(0.93352*(W20+S20)+0.5568*(Q20+O20))*0.26 -> 7478.5844 | AA20: =SUM(Z17:Z20) -> 23372.209
A21: 44580 | B21: 264 | C21: 19307 | D21: =IF((C21-C20)<0,"0",(C21-C20))*160 -> 320 | E21: 29562670 | F21: =IF((E21-E20)<0,"0",(E21-E20)) -> 5856 | G21: 94124042 | H21: =IF((G21-G20)<0,"0",(G21-G20)) -> 37608 | I21: =F21+H21 -> 43464 | J21: 9328341 | K21: =(IF((J21-J20)<0,"0",(J21-J20)))*2 -> 8718 | L21: 9341055 | M21: =IF((L21-L20)<0,"0",(L21-L20)) -> 4604 | N21: 6266411 | O21: =(IF((N21-N20)<0,"0",(N21-N20)))*2 -> 1136 | P21: 5821888 | Q21: =IF((P21-P20)<0,"0",(P21-P20)) -> 8604 | R21: 19929284 | S21: =IF((R21-R20)<0,"0",(R21-R20)) -> 9063 | T21: 0 | V21: 7820888 | W21: =IF((V21-V20)<0,"0",(V21-V20)) -> 8862 | X21: =K21+M21+O21+Q21+S21+U21+W21 -> 40987 | Y21: =I21-X21 -> 2477 | Z21: =(0.93352*(W21+S21)+0.5568*(Q21+O21))*0.26 -> 5760.7103 | AA21: =SUM(Z18:Z21) -> 24357.786
A22: 44581 | B22: =B21 -> 264 | C22: 19310 | D22: =IF((C22-C21)<0,"0",(C22-C21))*160 -> 480 | E22: 29569978 | F22: =IF((E22-E21)<0,"0",(E22-E21)) -> 7308 | G22: 94175393 | H22: =IF((G22-G21)<0,"0",(G22-G21)) -> 51351 | I22: =F22+H22 -> 58659 | J22: 9333554 | K22: =(IF((J22-J21)<0,"0",(J22-J21)))*2 -> 10426 | L22: 9346790 | M22: =IF((L22-L21)<0,"0",(L22-L21)) -> 5735 | N22: 6267128 | O22: =(IF((N22-N21)<0,"0",(N22-N21)))*2 -> 1434 | P22: 5826118 | Q22: =IF((P22-P21)<0,"0",(P22-P21)) -> 4230 | R22: 19941336 | S22: =IF((R22-R21)<0,"0",(R22-R21)) -> 12052 | T22: 0 | V22: 7833708 | W22: =IF((V22-V21)<0,"0",(V22-V21)) -> 12820 | X22: =K22+M22+O22+Q22+S22+U22+W22 -> 46697 | Y22: =I22-X22 -> 11962 | Z22: =(0.93352*(W22+S22)+0.5568*(Q22+O22))*0.26 -> 6856.7784 | AA22: =SUM(Z19:Z22) -> 25066.462
A23: 44582 | B23: 143 | C23: 19313 | D23: =IF((C23-C22)<0,"0",(C23-C22))*160 -> 480 | E23: 29576175 | F23: =IF((E23-E22)<0,"0",(E23-E22)) -> 6197 | G23: 94215391 | H23: =IF((G23-G22)<0,"0",(G23-G22)) -> 39998 | I23: =F23+H23 -> 46195 | J23: 9337190 | K23: =(IF((J23-J22)<0,"0",(J23-J22)))*2 -> 7272 | L23: 9351434 | M23: =IF((L23-L22)<0,"0",(L23-L22)) -> 4644 | N23: 6267836 | O23: =(IF((N23-N22)<0,"0",(N23-N22)))*2 -> 1416 | P23: 5832046 | Q23: =IF((P23-P22)<0,"0",(P23-P22)) -> 5928 | R23: 19950772 | S23: =IF((R23-R22)<0,"0",(R23-R22)) -> 9436 | T23: 0 | V23: 7843535 | W23: =IF((V23-V22)<0,"0",(V23-V22)) -> 9827 | X23: =K23+M23+O23+Q23+S23+U23+W23 -> 38523 | Y23: =I23-X23 -> 7672 | Z23: =(0.93352*(W23+S23)+0.5568*(Q23+O23))*0.26 -> 5738.5991 | AA23: =SUM(Z20:Z23) -> 25834.672
A24: 44583 | B24: 209 | C24: 19315 | D24: =IF((C24-C23)<0,"0",(C24-C23))*160 -> 320 | E24: 29581718 | F24: =IF((E24-E23)<0,"0",(E24-E23)) -> 5543 | G24: 94252053 | H24: =IF((G24-G23)<0,"0",(G24-G23)) -> 36662 | I24: =F24+H24 -> 42205 | J24: 9340897 | K24: =(IF((J24-J23)<0,"0",(J24-J23)))*2 -> 7414 | L24: 9355675 | M24: =IF((L24-L23)<0,"0",(L24-L23)) -> 4241 | N24: 6268469 | O24: =(IF((N24-N23)<0,"0",(N24-N23)))*2 -> 1266 | P24: 5837908 | Q24: =IF((P24-P23)<0,"0",(P24-P23)) -> 5862 | R24: 19959334 | S24: =IF((R24-R23)<0,"0",(R24-R23)) -> 8562 | T24: 0 | V24: 7852380 | W24: =IF((V24-V23)<0,"0",(V24-V23)) -> 8845 | X24: =K24+M24+O24+Q24+S24+U24+W24 -> 36190 | Y24: =I24-X24 -> 6015 | Z24: =(0.93352*(W24+S24)+0.5568*(Q24+O24))*0.26 -> 5256.8498 | AA24: =SUM(Z21:Z24) -> 23612.938
A25: 44584 | B25: 193 | C25: 19315 | D25: =IF((C25-C24)<0,"0",(C25-C24))*160 -> 0 | E25: 29592815 | F25: =IF((E25-E24)<0,"0",(E25-E24)) -> 11097 | G25: 94296571 | H25: =IF((G25-G24)<0,"0",(G25-G24)) -> 44518 | I25: =F25+H25 -> 55615 | J25: 9346141 | K25: =(IF((J25-J24)<0,"0",(J25-J24)))*2 -> 10488 | L25: 9361371 | M25: =IF((L25-L24)<0,"0",(L25-L24)) -> 5696 | N25: 6271064 | O25: =(IF((N25-N24)<0,"0",(N25-N24)))*2 -> 5190 | P25: 5841304 | Q25: =IF((P25-P24)<0,"0",(P25-P24)) -> 3396 | R25: 19970646 | S25: =IF((R25-R24)<0,"0",(R25-R24)) -> 11312 | T25: 0 | V25: 7864022 | W25: =IF((V25-V24)<0,"0",(V25-V24)) -> 11642 | X25: =K25+M25+O25+Q25+S25+U25+W25 -> 47724 | Y25: =I25-X25 -> 7891 | Z25: =(0.93352*(W25+S25)+0.5568*(Q25+O25))*0.26 -> 6814.2627 | AA25: =SUM(Z22:Z25) -> 24666.49
A26: 44585 | B26: 164 | C26: 19316 | D26: =IF((C26-C25)<0,"0",(C26-C25))*160 -> 160 | E26: 29601910 | F26: =IF((E26-E25)<0,"0",(E26-E25)) -> 9095 | G26: 94329025 | H26: =IF((G26-G25)<0,"0",(G26-G25)) -> 32454 | I26: =F26+H26 -> 41549 | J26: 9349942 | K26: =(IF((J26-J25)<0,"0",(J26-J25)))*2 -> 7602 | L26: 9365890 | M26: =IF((L26-L25)<0,"0",(L26-L25)) -> 4519 | N26: 6273290 | O26: =(IF((N26-N25)<0,"0",(N26-N25)))*2 -> 4452 | P26: 5843275 | Q26: =IF((P26-P25)<0,"0",(P26-P25)) -> 1971 | R26: 19979417 | S26: =IF((R26-R25)<0,"0",(R26-R25)) -> 8771 | T26: 0 | V26: 7872526 | W26: =IF((V26-V25)<0,"0",(V26-V25)) -> 8504 | X26: =K26+M26+O26+Q26+S26+U26+W26 -> 35819 | Y26: =I26-X26 -> 5730 | Z26: =(0.93352*(W26+S26)+0.5568*(Q26+O26))*0.26 -> 5122.7499 | AA26: =SUM(Z23:Z26) -> 22932.462
A27: 44586 | B27: =B26 -> 164 | D27: =IF((C27-C26)<0,"0",(C27-C26))*160 -> 0 | F27: =IF((E27-E26)<0,"0",(E27-E26)) -> 0 | H27: =IF((G27-G26)<0,"0",(G27-G26)) -> 0 | I27: =F27+H27 -> 0 | K27: =(IF((J27-J26)<0,"0",(J27-J26)))*2 -> 0 | M27: =IF((L27-L26)<0,"0",(L27-L26)) -> 0 | N27: =N26 -> 6273290 | O27: =(IF((N27-N26)<0,"0",(N27-N26)))*2 -> 0 | P27: =P26 -> 5843275 | Q27: =IF((P27-P26)<0,"0",(P27-P26)) -> 0 | R27: =R26 -> 19979417 | S27: =IF((R27-R26)<0,"0",(R27-R26)) -> 0 | T27: 0 | V27: =V26 -> 7872526 | W27: =IF((V27-V26)<0,"0",(V27-V26)) -> 0 | X27: =K27+M27+O27+Q27+S27+U27+W27 -> 0 | Y27: =I27-X27 -> 0 | Z27: =(0.93352*(W27+S27)+0.5568*(Q27+O27))*0.26 -> 0 | AA27: =SUM(Z24:Z27) -> 17193.862
