Workbook

Sheet Submetering
A1: Site Name | B1: Day | C1: Month | D1: Year | E1: Meter 1- KWh | F1: Meter 2- KWh | G1: East MCC- KWh | H1: South MCC 1- KWh | I1: South MCC 2- KWh | J1: West MCC- KWh | K1: Kitchen - KWh | L1: SPA - KWh | M1: Gas- KWh | N1: Main Site Water Meter - m3 | O1: Chiller 2- m3 | P1: Chiller 3- m3 | Q1: Chiller 4- m3 | R1: Hard Water Supply- m3 | S1: Pool Supply- m3 | T1: LTHW SPA- m3 | U1: LTHW East- m3 | V1: Chilled make-up- m3 | W1: Orchard irrigation | X1: Kids Pool | Y1: Room Nights | Z1: Total Guests
A2: Hampshire | B2: 1 | C2: 10 | D2: 2021 | E2: =IF(('Hampshire Daily'!E5-'Hampshire Daily'!D4<0),"0",('Hampshire Daily'!E5-'Hampshire Daily'!D4)) -> 4055 | F2: =IF(('Hampshire Daily'!G5-'Hampshire Daily'!F4<0),"0",('Hampshire Daily'!G5-'Hampshire Daily'!F4)) -> 2198 | G2: =IF(('Hampshire Daily'!H5-'Hampshire Daily'!H4<0),"0",('Hampshire Daily'!H5-'Hampshire Daily'!H4)) -> 0 | H2: =IF(('Hampshire Daily'!I5-'Hampshire Daily'!I4<0),"0",('Hampshire Daily'!I5-'Hampshire Daily'!I4)) -> 2006.4 | I2: =IF(('Hampshire Daily'!J5-'Hampshire Daily'!J4<0),"0",('Hampshire Daily'!J5-'Hampshire Daily'!J4)) -> 0 | J2: =IF(('Hampshire Daily'!L5-'Hampshire Daily'!K4<0),"0",('Hampshire Daily'!L5-'Hampshire Daily'!K4)) -> 0 | K2: =IF(('Hampshire Daily'!M5-'Hampshire Daily'!L4<0),"0",('Hampshire Daily'!M5-'Hampshire Daily'!L4)) -> 1717577 | L2: =IF(('Hampshire Daily'!N5-'Hampshire Daily'!M4<0),"0",('Hampshire Daily'!N5-'Hampshire Daily'!M4)) -> 0 | M2: =IF(('Hampshire Daily'!O5-'Hampshire Daily'!N4<0),"0",('Hampshire Daily'!O5-'Hampshire Daily'!N4)) -> 0 | N2: =IF(('Hampshire Daily'!P5-'Hampshire Daily'!O4<0),"0",('Hampshire Daily'!P5-'Hampshire Daily'!O4)) -> 1151613 | O2: =IF(('Hampshire Daily'!Q5-'Hampshire Daily'!P4<0),"0",('Hampshire Daily'!Q5-'Hampshire Daily'!P4)) -> 0 | P2: =IF(('Hampshire Daily'!R5-'Hampshire Daily'!Q4<0),"0",('Hampshire Daily'!R5-'Hampshire Daily'!Q4)) -> 600388 | Q2: =IF(('Hampshire Daily'!S5-'Hampshire Daily'!R4<0),"0",('Hampshire Daily'!S5-'Hampshire Daily'!R4)) -> 0 | R2: =IF(('Hampshire Daily'!V5-'Hampshire Daily'!U4<0),"0",('Hampshire Daily'!V5-'Hampshire Daily'!U4)) -> 0 | S2: =IF(('Hampshire Daily'!W5-'Hampshire Daily'!V4<0),"0",('Hampshire Daily'!W5-'Hampshire Daily'!V4)) -> 0 | T2: =IF(('Hampshire Daily'!X5-'Hampshire Daily'!W4<0),"0",('Hampshire Daily'!X5-'Hampshire Daily'!W4)) -> 471.03 | U2: =IF(('Hampshire Daily'!Y5-'Hampshire Daily'!X4<0),"0",('Hampshire Daily'!Y5-'Hampshire Daily'!X4)) -> 2928.619 | V2: =IF(('Hampshire Daily'!Z5-'Hampshire Daily'!Y4<0),"0",('Hampshire Daily'!Z5-'Hampshire Daily'!Y4)) -> 0 | W2: =IF(('Hampshire Daily'!AA5-'Hampshire Daily'!Z4<0),"0",('Hampshire Daily'!AA5-'Hampshire Daily'!Z4)) -> 2801 | X2: =IF(('Hampshire Daily'!AA5-'Hampshire Daily'!AA4<0),"0",('Hampshire Daily'!AA5-'Hampshire Daily'!AA4)) -> 0 | Y2: ='Hampshire Daily'!B5 -> 0 | Z2: ='Hampshire Daily'!D5 -> 1114528
A3: Hampshire | B3: =B2+1 -> 2 | C3: 10 | D3: 2021 | E3: =IF(('Hampshire Daily'!E6-'Hampshire Daily'!E5<0),"0",('Hampshire Daily'!E6-'Hampshire Daily'!E5)) -> 1851 | F3: =IF(('Hampshire Daily'!G6-'Hampshire Daily'!G5<0),"0",('Hampshire Daily'!G6-'Hampshire Daily'!G5)) -> 3574 | G3: =IF(('Hampshire Daily'!H6-'Hampshire Daily'!H5<0),"0",('Hampshire Daily'!H6-'Hampshire Daily'!H5)) -> 86 | H3: =IF(('Hampshire Daily'!I6-'Hampshire Daily'!I5<0),"0",('Hampshire Daily'!I6-'Hampshire Daily'!I5)) -> 2006.4 | I3: =IF(('Hampshire Daily'!J6-'Hampshire Daily'!J5<0),"0",('Hampshire Daily'!J6-'Hampshire Daily'!J5)) -> 0 | J3: =IF(('Hampshire Daily'!L6-'Hampshire Daily'!L5<0),"0",('Hampshire Daily'!L6-'Hampshire Daily'!L5)) -> 1081 | K3: =IF(('Hampshire Daily'!M6-'Hampshire Daily'!M5<0),"0",('Hampshire Daily'!M6-'Hampshire Daily'!M5)) -> 1 | L3: =IF(('Hampshire Daily'!N6-'Hampshire Daily'!N5<0),"0",('Hampshire Daily'!N6-'Hampshire Daily'!N5)) -> 2368 | M3: =IF(('Hampshire Daily'!O6-'Hampshire Daily'!O5<0),"0",('Hampshire Daily'!O6-'Hampshire Daily'!O5)) -> 127 | N3: =IF(('Hampshire Daily'!P6-'Hampshire Daily'!P5<0),"0",('Hampshire Daily'!P6-'Hampshire Daily'!P5)) -> 0 | O3: =IF(('Hampshire Daily'!Q6-'Hampshire Daily'!Q5<0),"0",('Hampshire Daily'!Q6-'Hampshire Daily'!Q5)) -> 0 | P3: =IF(('Hampshire Daily'!R6-'Hampshire Daily'!R5<0),"0",('Hampshire Daily'!R6-'Hampshire Daily'!R5)) -> 0 | Q3: =IF(('Hampshire Daily'!S6-'Hampshire Daily'!S5<0),"0",('Hampshire Daily'!S6-'Hampshire Daily'!S5)) -> 97 | R3: =IF(('Hampshire Daily'!V6-'Hampshire Daily'!V5<0),"0",('Hampshire Daily'!V6-'Hampshire Daily'!V5)) -> 0 | S3: =IF(('Hampshire Daily'!W6-'Hampshire Daily'!W5<0),"0",('Hampshire Daily'!W6-'Hampshire Daily'!W5)) -> 0 | T3: =IF(('Hampshire Daily'!X6-'Hampshire Daily'!X5<0),"0",('Hampshire Daily'!X6-'Hampshire Daily'!X5)) -> 0.124 | U3: =IF(('Hampshire Daily'!Y6-'Hampshire Daily'!Y5<0),"0",('Hampshire Daily'!Y6-'Hampshire Daily'!Y5)) -> 0.011 | V3: =IF(('Hampshire Daily'!Z6-'Hampshire Daily'!Z5<0),"0",('Hampshire Daily'!Z6-'Hampshire Daily'!Z5)) -> 0 | W3: =IF(('Hampshire Daily'!AA6-'Hampshire Daily'!AA5<0),"0",('Hampshire Daily'!AA6-'Hampshire Daily'!AA5)) -> 7 | X3: =IF(('Hampshire Daily'!AA6-'Hampshire Daily'!AA5<0),"0",('Hampshire Daily'!AA6-'Hampshire Daily'!AA5)) -> 7 | Y3: ='Hampshire Daily'!B6 -> 0 | Z3: ='Hampshire Daily'!D6 -> 1116376
A4: Hampshire | B4: =B3+1 -> 3 | C4: 10 | D4: 2021 | E4: =IF(('Hampshire Daily'!E7-'Hampshire Daily'!E6<0),"0",('Hampshire Daily'!E7-'Hampshire Daily'!E6)) -> 2102 | F4: =IF(('Hampshire Daily'!G7-'Hampshire Daily'!G6<0),"0",('Hampshire Daily'!G7-'Hampshire Daily'!G6)) -> 6723 | G4: =IF(('Hampshire Daily'!H7-'Hampshire Daily'!H6<0),"0",('Hampshire Daily'!H7-'Hampshire Daily'!H6)) -> 795 | H4: =IF(('Hampshire Daily'!I7-'Hampshire Daily'!I6<0),"0",('Hampshire Daily'!I7-'Hampshire Daily'!I6)) -> 2006.4 | I4: =IF(('Hampshire Daily'!J7-'Hampshire Daily'!J6<0),"0",('Hampshire Daily'!J7-'Hampshire Daily'!J6)) -> 0 | J4: =IF(('Hampshire Daily'!L7-'Hampshire Daily'!L6<0),"0",('Hampshire Daily'!L7-'Hampshire Daily'!L6)) -> 1051 | K4: =IF(('Hampshire Daily'!M7-'Hampshire Daily'!M6<0),"0",('Hampshire Daily'!M7-'Hampshire Daily'!M6)) -> 2 | L4: =IF(('Hampshire Daily'!N7-'Hampshire Daily'!N6<0),"0",('Hampshire Daily'!N7-'Hampshire Daily'!N6)) -> 2359 | M4: =IF(('Hampshire Daily'!O7-'Hampshire Daily'!O6<0),"0",('Hampshire Daily'!O7-'Hampshire Daily'!O6)) -> 154 | N4: =IF(('Hampshire Daily'!P7-'Hampshire Daily'!P6<0),"0",('Hampshire Daily'!P7-'Hampshire Daily'!P6)) -> 1381662 | O4: =IF(('Hampshire Daily'!Q7-'Hampshire Daily'!Q6<0),"0",('Hampshire Daily'!Q7-'Hampshire Daily'!Q6)) -> 0 | P4: =IF(('Hampshire Daily'!R7-'Hampshire Daily'!R6<0),"0",('Hampshire Daily'!R7-'Hampshire Daily'!R6)) -> 0 | Q4: =IF(('Hampshire Daily'!S7-'Hampshire Daily'!S6<0),"0",('Hampshire Daily'!S7-'Hampshire Daily'!S6)) -> 101 | R4: =IF(('Hampshire Daily'!V7-'Hampshire Daily'!V6<0),"0",('Hampshire Daily'!V7-'Hampshire Daily'!V6)) -> 12 | S4: =IF(('Hampshire Daily'!W7-'Hampshire Daily'!W6<0),"0",('Hampshire Daily'!W7-'Hampshire Daily'!W6)) -> 0 | T4: =IF(('Hampshire Daily'!X7-'Hampshire Daily'!X6<0),"0",('Hampshire Daily'!X7-'Hampshire Daily'!X6)) -> 0.336 | U4: =IF(('Hampshire Daily'!Y7-'Hampshire Daily'!Y6<0),"0",('Hampshire Daily'!Y7-'Hampshire Daily'!Y6)) -> 0.014 | V4: =IF(('Hampshire Daily'!Z7-'Hampshire Daily'!Z6<0),"0",('Hampshire Daily'!Z7-'Hampshire Daily'!Z6)) -> 0 | W4: =IF(('Hampshire Daily'!AA7-'Hampshire Daily'!AA6<0),"0",('Hampshire Daily'!AA7-'Hampshire Daily'!AA6)) -> 6 | X4: =IF(('Hampshire Daily'!AA7-'Hampshire Daily'!AA6<0),"0",('Hampshire Daily'!AA7-'Hampshire Daily'!AA6)) -> 6 | Y4: ='Hampshire Daily'!B7 -> 0 | Z4: ='Hampshire Daily'!D7 -> 1118474
A5: Hampshire | B5: =B4+1 -> 4 | C5: 10 | D5: 2021 | E5: =IF(('Hampshire Daily'!E8-'Hampshire Daily'!E7<0),"0",('Hampshire Daily'!E8-'Hampshire Daily'!E7)) -> 2725 | F5: =IF(('Hampshire Daily'!G8-'Hampshire Daily'!G7<0),"0",('Hampshire Daily'!G8-'Hampshire Daily'!G7)) -> 3536 | G5: =IF(('Hampshire Daily'!H8-'Hampshire Daily'!H7<0),"0",('Hampshire Daily'!H8-'Hampshire Daily'!H7)) -> 85 | H5: =IF(('Hampshire Daily'!I8-'Hampshire Daily'!I7<0),"0",('Hampshire Daily'!I8-'Hampshire Daily'!I7)) -> 2006.4 | I5: =IF(('Hampshire Daily'!J8-'Hampshire Daily'!J7<0),"0",('Hampshire Daily'!J8-'Hampshire Daily'!J7)) -> 0 | J5: =IF(('Hampshire Daily'!L8-'Hampshire Daily'!L7<0),"0",('Hampshire Daily'!L8-'Hampshire Daily'!L7)) -> 1051 | K5: =IF(('Hampshire Daily'!M8-'Hampshire Daily'!M7<0),"0",('Hampshire Daily'!M8-'Hampshire Daily'!M7)) -> 163 | L5: =IF(('Hampshire Daily'!N8-'Hampshire Daily'!N7<0),"0",('Hampshire Daily'!N8-'Hampshire Daily'!N7)) -> 2514 | M5: =IF(('Hampshire Daily'!O8-'Hampshire Daily'!O7<0),"0",('Hampshire Daily'!O8-'Hampshire Daily'!O7)) -> 117.5 | N5: =IF(('Hampshire Daily'!P8-'Hampshire Daily'!P7<0),"0",('Hampshire Daily'!P8-'Hampshire Daily'!P7)) -> 736 | O5: =IF(('Hampshire Daily'!Q8-'Hampshire Daily'!Q7<0),"0",('Hampshire Daily'!Q8-'Hampshire Daily'!Q7)) -> 0 | P5: =IF(('Hampshire Daily'!R8-'Hampshire Daily'!R7<0),"0",('Hampshire Daily'!R8-'Hampshire Daily'!R7)) -> 0 | Q5: =IF(('Hampshire Daily'!S8-'Hampshire Daily'!S7<0),"0",('Hampshire Daily'!S8-'Hampshire Daily'!S7)) -> 104 | R5: =IF(('Hampshire Daily'!V8-'Hampshire Daily'!V7<0),"0",('Hampshire Daily'!V8-'Hampshire Daily'!V7)) -> 0 | S5: =IF(('Hampshire Daily'!W8-'Hampshire Daily'!W7<0),"0",('Hampshire Daily'!W8-'Hampshire Daily'!W7)) -> 0 | T5: =IF(('Hampshire Daily'!X8-'Hampshire Daily'!X7<0),"0",('Hampshire Daily'!X8-'Hampshire Daily'!X7)) -> 0.164 | U5: =IF(('Hampshire Daily'!Y8-'Hampshire Daily'!Y7<0),"0",('Hampshire Daily'!Y8-'Hampshire Daily'!Y7)) -> 0.014 | V5: =IF(('Hampshire Daily'!Z8-'Hampshire Daily'!Z7<0),"0",('Hampshire Daily'!Z8-'Hampshire Daily'!Z7)) -> 0 | W5: =IF(('Hampshire Daily'!AA8-'Hampshire Daily'!AA7<0),"0",('Hampshire Daily'!AA8-'Hampshire Daily'!AA7)) -> 4 | X5: =IF(('Hampshire Daily'!AA8-'Hampshire Daily'!AA7<0),"0",('Hampshire Daily'!AA8-'Hampshire Daily'!AA7)) -> 4 | Y5: ='Hampshire Daily'!B8 -> 0 | Z5: ='Hampshire Daily'!D8 -> 1121194
A6: Hampshire | B6: =B5+1 -> 5 | C6: 10 | D6: 2021 | E6: =IF(('Hampshire Daily'!E9-'Hampshire Daily'!E8<0),"0",('Hampshire Daily'!E9-'Hampshire Daily'!E8)) -> 3730 | F6: =IF(('Hampshire Daily'!G9-'Hampshire Daily'!G8<0),"0",('Hampshire Daily'!G9-'Hampshire Daily'!G8)) -> 5349 | G6: =IF(('Hampshire Daily'!H9-'Hampshire Daily'!H8<0),"0",('Hampshire Daily'!H9-'Hampshire Daily'!H8)) -> 614 | H6: =IF(('Hampshire Daily'!I9-'Hampshire Daily'!I8<0),"0",('Hampshire Daily'!I9-'Hampshire Daily'!I8)) -> 2006.4 | I6: =IF(('Hampshire Daily'!J9-'Hampshire Daily'!J8<0),"0",('Hampshire Daily'!J9-'Hampshire Daily'!J8)) -> 0 | J6: =IF(('Hampshire Daily'!L9-'Hampshire Daily'!L8<0),"0",('Hampshire Daily'!L9-'Hampshire Daily'!L8)) -> 1051 | K6: =IF(('Hampshire Daily'!M9-'Hampshire Daily'!M8<0),"0",('Hampshire Daily'!M9-'Hampshire Daily'!M8)) -> 350 | L6: =IF(('Hampshire Daily'!N9-'Hampshire Daily'!N8<0),"0",('Hampshire Daily'!N9-'Hampshire Daily'!N8)) -> 2953 | M6: =IF(('Hampshire Daily'!O9-'Hampshire Daily'!O8<0),"0",('Hampshire Daily'!O9-'Hampshire Daily'!O8)) -> 117.5 | N6: =IF(('Hampshire Daily'!P9-'Hampshire Daily'!P8<0),"0",('Hampshire Daily'!P9-'Hampshire Daily'!P8)) -> 323 | O6: =IF(('Hampshire Daily'!Q9-'Hampshire Daily'!Q8<0),"0",('Hampshire Daily'!Q9-'Hampshire Daily'!Q8)) -> 0 | P6: =IF(('Hampshire Daily'!R9-'Hampshire Daily'!R8<0),"0",('Hampshire Daily'!R9-'Hampshire Daily'!R8)) -> 322 | Q6: =IF(('Hampshire Daily'!S9-'Hampshire Daily'!S8<0),"0",('Hampshire Daily'!S9-'Hampshire Daily'!S8)) -> 103 | R6: =IF(('Hampshire Daily'!V9-'Hampshire Daily'!V8<0),"0",('Hampshire Daily'!V9-'Hampshire Daily'!V8)) -> 2 | S6: =IF(('Hampshire Daily'!W9-'Hampshire Daily'!W8<0),"0",('Hampshire Daily'!W9-'Hampshire Daily'!W8)) -> 0 | T6: =IF(('Hampshire Daily'!X9-'Hampshire Daily'!X8<0),"0",('Hampshire Daily'!X9-'Hampshire Daily'!X8)) -> 0.295 | U6: =IF(('Hampshire Daily'!Y9-'Hampshire Daily'!Y8<0),"0",('Hampshire Daily'!Y9-'Hampshire Daily'!Y8)) -> 0.015 | V6: =IF(('Hampshire Daily'!Z9-'Hampshire Daily'!Z8<0),"0",('Hampshire Daily'!Z9-'Hampshire Daily'!Z8)) -> 0 | W6: =IF(('Hampshire Daily'!AA9-'Hampshire Daily'!AA8<0),"0",('Hampshire Daily'!AA9-'Hampshire Daily'!AA8)) -> 5 | X6: =IF(('Hampshire Daily'!AA9-'Hampshire Daily'!AA8<0),"0",('Hampshire Daily'!AA9-'Hampshire Daily'!AA8)) -> 5 | Y6: ='Hampshire Daily'!B9 -> 0 | Z6: ='Hampshire Daily'!D9 -> 1124918
A7: Hampshire | B7: =B6+1 -> 6 | C7: 10 | D7: 2021 | E7: =IF(('Hampshire Daily'!E10-'Hampshire Daily'!E9<0),"0",('Hampshire Daily'!E10-'Hampshire Daily'!E9)) -> 4368 | F7: =IF(('Hampshire Daily'!G10-'Hampshire Daily'!G9<0),"0",('Hampshire Daily'!G10-'Hampshire Daily'!G9)) -> 2395 | G7: =IF(('Hampshire Daily'!H10-'Hampshire Daily'!H9<0),"0",('Hampshire Daily'!H10-'Hampshire Daily'!H9)) -> 53 | H7: =IF(('Hampshire Daily'!I10-'Hampshire Daily'!I9<0),"0",('Hampshire Daily'!I10-'Hampshire Daily'!I9)) -> 2006.4 | I7: =IF(('Hampshire Daily'!J10-'Hampshire Daily'!J9<0),"0",('Hampshire Daily'!J10-'Hampshire Daily'!J9)) -> 0 | J7: =IF(('Hampshire Daily'!L10-'Hampshire Daily'!L9<0),"0",('Hampshire Daily'!L10-'Hampshire Daily'!L9)) -> 1051 | K7: =IF(('Hampshire Daily'!M10-'Hampshire Daily'!M9<0),"0",('Hampshire Daily'!M10-'Hampshire Daily'!M9)) -> 373 | L7: =IF(('Hampshire Daily'!N10-'Hampshire Daily'!N9<0),"0",('Hampshire Daily'!N10-'Hampshire Daily'!N9)) -> 3216 | M7: =IF(('Hampshire Daily'!O10-'Hampshire Daily'!O9<0),"0",('Hampshire Daily'!O10-'Hampshire Daily'!O9)) -> 117 | N7: =IF(('Hampshire Daily'!P10-'Hampshire Daily'!P9<0),"0",('Hampshire Daily'!P10-'Hampshire Daily'!P9)) -> 0 | O7: =IF(('Hampshire Daily'!Q10-'Hampshire Daily'!Q9<0),"0",('Hampshire Daily'!Q10-'Hampshire Daily'!Q9)) -> 0 | P7: =IF(('Hampshire Daily'!R10-'Hampshire Daily'!R9<0),"0",('Hampshire Daily'!R10-'Hampshire Daily'!R9)) -> 568 | Q7: =IF(('Hampshire Daily'!S10-'Hampshire Daily'!S9<0),"0",('Hampshire Daily'!S10-'Hampshire Daily'!S9)) -> 88 | R7: =IF(('Hampshire Daily'!V10-'Hampshire Daily'!V9<0),"0",('Hampshire Daily'!V10-'Hampshire Daily'!V9)) -> 1 | S7: =IF(('Hampshire Daily'!W10-'Hampshire Daily'!W9<0),"0",('Hampshire Daily'!W10-'Hampshire Daily'!W9)) -> 0 | T7: =IF(('Hampshire Daily'!X10-'Hampshire Daily'!X9<0),"0",('Hampshire Daily'!X10-'Hampshire Daily'!X9)) -> 0.277 | U7: =IF(('Hampshire Daily'!Y10-'Hampshire Daily'!Y9<0),"0",('Hampshire Daily'!Y10-'Hampshire Daily'!Y9)) -> 0.014 | V7: =IF(('Hampshire Daily'!Z10-'Hampshire Daily'!Z9<0),"0",('Hampshire Daily'!Z10-'Hampshire Daily'!Z9)) -> 0 | W7: =IF(('Hampshire Daily'!AA10-'Hampshire Daily'!AA9<0),"0",('Hampshire Daily'!AA10-'Hampshire Daily'!AA9)) -> 3 | X7: =IF(('Hampshire Daily'!AA10-'Hampshire Daily'!AA9<0),"0",('Hampshire Daily'!AA10-'Hampshire Daily'!AA9)) -> 3 | Y7: ='Hampshire Daily'!B10 -> 0 | Z7: ='Hampshire Daily'!D10 -> 1129278
A8: Hampshire | B8: =B7+1 -> 7 | C8: 10 | D8: 2021 | E8: =IF(('Hampshire Daily'!E11-'Hampshire Daily'!E10<0),"0",('Hampshire Daily'!E11-'Hampshire Daily'!E10)) -> 3130 | F8: =IF(('Hampshire Daily'!G11-'Hampshire Daily'!G10<0),"0",('Hampshire Daily'!G11-'Hampshire Daily'!G10)) -> 2022 | G8: =IF(('Hampshire Daily'!H11-'Hampshire Daily'!H10<0),"0",('Hampshire Daily'!H11-'Hampshire Daily'!H10)) -> 0 | H8: =IF(('Hampshire Daily'!I11-'Hampshire Daily'!I10<0),"0",('Hampshire Daily'!I11-'Hampshire Daily'!I10)) -> 2006.4 | I8: =IF(('Hampshire Daily'!J11-'Hampshire Daily'!J10<0),"0",('Hampshire Daily'!J11-'Hampshire Daily'!J10)) -> 0 | J8: =IF(('Hampshire Daily'!L11-'Hampshire Daily'!L10<0),"0",('Hampshire Daily'!L11-'Hampshire Daily'!L10)) -> 1051 | K8: =IF(('Hampshire Daily'!M11-'Hampshire Daily'!M10<0),"0",('Hampshire Daily'!M11-'Hampshire Daily'!M10)) -> 44 | L8: =IF(('Hampshire Daily'!N11-'Hampshire Daily'!N10<0),"0",('Hampshire Daily'!N11-'Hampshire Daily'!N10)) -> 3496 | M8: =IF(('Hampshire Daily'!O11-'Hampshire Daily'!O10<0),"0",('Hampshire Daily'!O11-'Hampshire Daily'!O10)) -> 114 | N8: =IF(('Hampshire Daily'!P11-'Hampshire Daily'!P10<0),"0",('Hampshire Daily'!P11-'Hampshire Daily'!P10)) -> 0 | O8: =IF(('Hampshire Daily'!Q11-'Hampshire Daily'!Q10<0),"0",('Hampshire Daily'!Q11-'Hampshire Daily'!Q10)) -> 0 | P8: =IF(('Hampshire Daily'!R11-'Hampshire Daily'!R10<0),"0",('Hampshire Daily'!R11-'Hampshire Daily'!R10)) -> 445 | Q8: =IF(('Hampshire Daily'!S11-'Hampshire Daily'!S10<0),"0",('Hampshire Daily'!S11-'Hampshire Daily'!S10)) -> 86 | R8: =IF(('Hampshire Daily'!V11-'Hampshire Daily'!V10<0),"0",('Hampshire Daily'!V11-'Hampshire Daily'!V10)) -> 1 | S8: =IF(('Hampshire Daily'!W11-'Hampshire Daily'!W10<0),"0",('Hampshire Daily'!W11-'Hampshire Daily'!W10)) -> 0 | T8: =IF(('Hampshire Daily'!X11-'Hampshire Daily'!X10<0),"0",('Hampshire Daily'!X11-'Hampshire Daily'!X10)) -> 0.236 | U8: =IF(('Hampshire Daily'!Y11-'Hampshire Daily'!Y10<0),"0",('Hampshire Daily'!Y11-'Hampshire Daily'!Y10)) -> 0.001 | V8: =IF(('Hampshire Daily'!Z11-'Hampshire Daily'!Z10<0),"0",('Hampshire Daily'!Z11-'Hampshire Daily'!Z10)) -> 0 | W8: =IF(('Hampshire Daily'!AA11-'Hampshire Daily'!AA10<0),"0",('Hampshire Daily'!AA11-'Hampshire Daily'!AA10)) -> 3 | X8: =IF(('Hampshire Daily'!AA11-'Hampshire Daily'!AA10<0),"0",('Hampshire Daily'!AA11-'Hampshire Daily'!AA10)) -> 3 | Y8: ='Hampshire Daily'!B11 -> 0 | Z8: ='Hampshire Daily'!D11 -> 1132405
A9: Hampshire | B9: =B8+1 -> 8 | C9: 10 | D9: 2021 | E9: =IF(('Hampshire Daily'!E12-'Hampshire Daily'!E11<0),"0",('Hampshire Daily'!E12-'Hampshire Daily'!E11)) -> 2519 | F9: =IF(('Hampshire Daily'!G12-'Hampshire Daily'!G11<0),"0",('Hampshire Daily'!G12-'Hampshire Daily'!G11)) -> 2493 | G9: =IF(('Hampshire Daily'!H12-'Hampshire Daily'!H11<0),"0",('Hampshire Daily'!H12-'Hampshire Daily'!H11)) -> 30000 | H9: =IF(('Hampshire Daily'!I12-'Hampshire Daily'!I11<0),"0",('Hampshire Daily'!I12-'Hampshire Daily'!I11)) -> 2006.4 | I9: =IF(('Hampshire Daily'!J12-'Hampshire Daily'!J11<0),"0",('Hampshire Daily'!J12-'Hampshire Daily'!J11)) -> 0 | J9: =IF(('Hampshire Daily'!L12-'Hampshire Daily'!L11<0),"0",('Hampshire Daily'!L12-'Hampshire Daily'!L11)) -> 1051 | K9: =IF(('Hampshire Daily'!M12-'Hampshire Daily'!M11<0),"0",('Hampshire Daily'!M12-'Hampshire Daily'!M11)) -> 4 | L9: =IF(('Hampshire Daily'!N12-'Hampshire Daily'!N11<0),"0",('Hampshire Daily'!N12-'Hampshire Daily'!N11)) -> 3460 | M9: =IF(('Hampshire Daily'!O12-'Hampshire Daily'!O11<0),"0",('Hampshire Daily'!O12-'Hampshire Daily'!O11)) -> 112 | N9: =IF(('Hampshire Daily'!P12-'Hampshire Daily'!P11<0),"0",('Hampshire Daily'!P12-'Hampshire Daily'!P11)) -> 247 | O9: =IF(('Hampshire Daily'!Q12-'Hampshire Daily'!Q11<0),"0",('Hampshire Daily'!Q12-'Hampshire Daily'!Q11)) -> 0 | P9: =IF(('Hampshire Daily'!R12-'Hampshire Daily'!R11<0),"0",('Hampshire Daily'!R12-'Hampshire Daily'!R11)) -> 0 | Q9: =IF(('Hampshire Daily'!S12-'Hampshire Daily'!S11<0),"0",('Hampshire Daily'!S12-'Hampshire Daily'!S11)) -> 85 | R9: =IF(('Hampshire Daily'!V12-'Hampshire Daily'!V11<0),"0",('Hampshire Daily'!V12-'Hampshire Daily'!V11)) -> 1 | S9: =IF(('Hampshire Daily'!W12-'Hampshire Daily'!W11<0),"0",('Hampshire Daily'!W12-'Hampshire Daily'!W11)) -> 0 | T9: =IF(('Hampshire Daily'!X12-'Hampshire Daily'!X11<0),"0",('Hampshire Daily'!X12-'Hampshire Daily'!X11)) -> 0.246 | U9: =IF(('Hampshire Daily'!Y12-'Hampshire Daily'!Y11<0),"0",('Hampshire Daily'!Y12-'Hampshire Daily'!Y11)) -> 0 | V9: =IF(('Hampshire Daily'!Z12-'Hampshire Daily'!Z11<0),"0",('Hampshire Daily'!Z12-'Hampshire Daily'!Z11)) -> 0 | W9: =IF(('Hampshire Daily'!AA12-'Hampshire Daily'!AA11<0),"0",('Hampshire Daily'!AA12-'Hampshire Daily'!AA11)) -> 5 | X9: =IF(('Hampshire Daily'!AA12-'Hampshire Daily'!AA11<0),"0",('Hampshire Daily'!AA12-'Hampshire Daily'!AA11)) -> 5 | Y9: ='Hampshire Daily'!B12 -> 0 | Z9: ='Hampshire Daily'!D12 -> 1134919
A10: Hampshire | B10: =B9+1 -> 9 | C10: 10 | D10: 2021 | E10: =IF(('Hampshire Daily'!E13-'Hampshire Daily'!E12<0),"0",('Hampshire Daily'!E13-'Hampshire Daily'!E12)) -> 2478 | F10: =IF(('Hampshire Daily'!G13-'Hampshire Daily'!G12<0),"0",('Hampshire Daily'!G13-'Hampshire Daily'!G12)) -> 2164 | G10: =IF(('Hampshire Daily'!H13-'Hampshire Daily'!H12<0),"0",('Hampshire Daily'!H13-'Hampshire Daily'!H12)) -> 0 | H10: =IF(('Hampshire Daily'!I13-'Hampshire Daily'!I12<0),"0",('Hampshire Daily'!I13-'Hampshire Daily'!I12)) -> 2006.4 | I10: =IF(('Hampshire Daily'!J13-'Hampshire Daily'!J12<0),"0",('Hampshire Daily'!J13-'Hampshire Daily'!J12)) -> 0 | J10: =IF(('Hampshire Daily'!L13-'Hampshire Daily'!L12<0),"0",('Hampshire Daily'!L13-'Hampshire Daily'!L12)) -> 1051 | K10: =IF(('Hampshire Daily'!M13-'Hampshire Daily'!M12<0),"0",('Hampshire Daily'!M13-'Hampshire Daily'!M12)) -> 9 | L10: =IF(('Hampshire Daily'!N13-'Hampshire Daily'!N12<0),"0",('Hampshire Daily'!N13-'Hampshire Daily'!N12)) -> 3069 | M10: =IF(('Hampshire Daily'!O13-'Hampshire Daily'!O12<0),"0",('Hampshire Daily'!O13-'Hampshire Daily'!O12)) -> 115 | N10: =IF(('Hampshire Daily'!P13-'Hampshire Daily'!P12<0),"0",('Hampshire Daily'!P13-'Hampshire Daily'!P12)) -> 0 | O10: =IF(('Hampshire Daily'!Q13-'Hampshire Daily'!Q12<0),"0",('Hampshire Daily'!Q13-'Hampshire Daily'!Q12)) -> 0 | P10: =IF(('Hampshire Daily'!R13-'Hampshire Daily'!R12<0),"0",('Hampshire Daily'!R13-'Hampshire Daily'!R12)) -> 0 | Q10: =IF(('Hampshire Daily'!S13-'Hampshire Daily'!S12<0),"0",('Hampshire Daily'!S13-'Hampshire Daily'!S12)) -> 83 | R10: =IF(('Hampshire Daily'!V13-'Hampshire Daily'!V12<0),"0",('Hampshire Daily'!V13-'Hampshire Daily'!V12)) -> 1 | S10: =IF(('Hampshire Daily'!W13-'Hampshire Daily'!W12<0),"0",('Hampshire Daily'!W13-'Hampshire Daily'!W12)) -> 0 | T10: =IF(('Hampshire Daily'!X13-'Hampshire Daily'!X12<0),"0",('Hampshire Daily'!X13-'Hampshire Daily'!X12)) -> 0.172 | U10: =IF(('Hampshire Daily'!Y13-'Hampshire Daily'!Y12<0),"0",('Hampshire Daily'!Y13-'Hampshire Daily'!Y12)) -> 0 | V10: =IF(('Hampshire Daily'!Z13-'Hampshire Daily'!Z12<0),"0",('Hampshire Daily'!Z13-'Hampshire Daily'!Z12)) -> 0 | W10: =IF(('Hampshire Daily'!AA13-'Hampshire Daily'!AA12<0),"0",('Hampshire Daily'!AA13-'Hampshire Daily'!AA12)) -> 6 | X10: =IF(('Hampshire Daily'!AA13-'Hampshire Daily'!AA12<0),"0",('Hampshire Daily'!AA13-'Hampshire Daily'!AA12)) -> 6 | Y10: ='Hampshire Daily'!B13 -> 0 | Z10: ='Hampshire Daily'!D13 -> 1137393
A11: Hampshire | B11: =B10+1 -> 10 | C11: 10 | D11: 2021 | E11: =IF(('Hampshire Daily'!E14-'Hampshire Daily'!E13<0),"0",('Hampshire Daily'!E14-'Hampshire Daily'!E13)) -> 2355 | F11: =IF(('Hampshire Daily'!G14-'Hampshire Daily'!G13<0),"0",('Hampshire Daily'!G14-'Hampshire Daily'!G13)) -> 1422 | G11: =IF(('Hampshire Daily'!H14-'Hampshire Daily'!H13<0),"0",('Hampshire Daily'!H14-'Hampshire Daily'!H13)) -> 0 | H11: =IF(('Hampshire Daily'!I14-'Hampshire Daily'!I13<0),"0",('Hampshire Daily'!I14-'Hampshire Daily'!I13)) -> 2006.4 | I11: =IF(('Hampshire Daily'!J14-'Hampshire Daily'!J13<0),"0",('Hampshire Daily'!J14-'Hampshire Daily'!J13)) -> 0 | J11: =IF(('Hampshire Daily'!L14-'Hampshire Daily'!L13<0),"0",('Hampshire Daily'!L14-'Hampshire Daily'!L13)) -> 1051 | K11: =IF(('Hampshire Daily'!M14-'Hampshire Daily'!M13<0),"0",('Hampshire Daily'!M14-'Hampshire Daily'!M13)) -> 1 | L11: =IF(('Hampshire Daily'!N14-'Hampshire Daily'!N13<0),"0",('Hampshire Daily'!N14-'Hampshire Daily'!N13)) -> 3159 | M11: =IF(('Hampshire Daily'!O14-'Hampshire Daily'!O13<0),"0",('Hampshire Daily'!O14-'Hampshire Daily'!O13)) -> 136 | N11: =IF(('Hampshire Daily'!P14-'Hampshire Daily'!P13<0),"0",('Hampshire Daily'!P14-'Hampshire Daily'!P13)) -> 0 | O11: =IF(('Hampshire Daily'!Q14-'Hampshire Daily'!Q13<0),"0",('Hampshire Daily'!Q14-'Hampshire Daily'!Q13)) -> 0 | P11: =IF(('Hampshire Daily'!R14-'Hampshire Daily'!R13<0),"0",('Hampshire Daily'!R14-'Hampshire Daily'!R13)) -> 463 | Q11: =IF(('Hampshire Daily'!S14-'Hampshire Daily'!S13<0),"0",('Hampshire Daily'!S14-'Hampshire Daily'!S13)) -> 80 | R11: =IF(('Hampshire Daily'!V14-'Hampshire Daily'!V13<0),"0",('Hampshire Daily'!V14-'Hampshire Daily'!V13)) -> 13 | S11: =IF(('Hampshire Daily'!W14-'Hampshire Daily'!W13<0),"0",('Hampshire Daily'!W14-'Hampshire Daily'!W13)) -> 0 | T11: =IF(('Hampshire Daily'!X14-'Hampshire Daily'!X13<0),"0",('Hampshire Daily'!X14-'Hampshire Daily'!X13)) -> 0.195 | U11: =IF(('Hampshire Daily'!Y14-'Hampshire Daily'!Y13<0),"0",('Hampshire Daily'!Y14-'Hampshire Daily'!Y13)) -> 0 | V11: =IF(('Hampshire Daily'!Z14-'Hampshire Daily'!Z13<0),"0",('Hampshire Daily'!Z14-'Hampshire Daily'!Z13)) -> 0 | W11: =IF(('Hampshire Daily'!AA14-'Hampshire Daily'!AA13<0),"0",('Hampshire Daily'!AA14-'Hampshire Daily'!AA13)) -> 7 | X11: =IF(('Hampshire Daily'!AA14-'Hampshire Daily'!AA13<0),"0",('Hampshire Daily'!AA14-'Hampshire Daily'!AA13)) -> 7 | Y11: ='Hampshire Daily'!B14 -> 0 | Z11: ='Hampshire Daily'!D14 -> 1139745
A12: Hampshire | B12: =B11+1 -> 11 | C12: 10 | D12: 2021 | E12: =IF(('Hampshire Daily'!E15-'Hampshire Daily'!E14<0),"0",('Hampshire Daily'!E15-'Hampshire Daily'!E14)) -> 2833 | F12: =IF(('Hampshire Daily'!G15-'Hampshire Daily'!G14<0),"0",('Hampshire Daily'!G15-'Hampshire Daily'!G14)) -> 2488 | G12: =IF(('Hampshire Daily'!H15-'Hampshire Daily'!H14<0),"0",('Hampshire Daily'!H15-'Hampshire Daily'!H14)) -> 0 | H12: =IF(('Hampshire Daily'!I15-'Hampshire Daily'!I14<0),"0",('Hampshire Daily'!I15-'Hampshire Daily'!I14)) -> 2006.4 | I12: =IF(('Hampshire Daily'!J15-'Hampshire Daily'!J14<0),"0",('Hampshire Daily'!J15-'Hampshire Daily'!J14)) -> 0 | J12: =IF(('Hampshire Daily'!L15-'Hampshire Daily'!L14<0),"0",('Hampshire Daily'!L15-'Hampshire Daily'!L14)) -> 1051 | K12: =IF(('Hampshire Daily'!M15-'Hampshire Daily'!M14<0),"0",('Hampshire Daily'!M15-'Hampshire Daily'!M14)) -> 3 | L12: =IF(('Hampshire Daily'!N15-'Hampshire Daily'!N14<0),"0",('Hampshire Daily'!N15-'Hampshire Daily'!N14)) -> 3022 | M12: =IF(('Hampshire Daily'!O15-'Hampshire Daily'!O14<0),"0",('Hampshire Daily'!O15-'Hampshire Daily'!O14)) -> 79 | N12: =IF(('Hampshire Daily'!P15-'Hampshire Daily'!P14<0),"0",('Hampshire Daily'!P15-'Hampshire Daily'!P14)) -> 0 | O12: =IF(('Hampshire Daily'!Q15-'Hampshire Daily'!Q14<0),"0",('Hampshire Daily'!Q15-'Hampshire Daily'!Q14)) -> 0 | P12: =IF(('Hampshire Daily'!R15-'Hampshire Daily'!R14<0),"0",('Hampshire Daily'!R15-'Hampshire Daily'!R14)) -> 731 | Q12: =IF(('Hampshire Daily'!S15-'Hampshire Daily'!S14<0),"0",('Hampshire Daily'!S15-'Hampshire Daily'!S14)) -> 57 | R12: =IF(('Hampshire Daily'!V15-'Hampshire Daily'!V14<0),"0",('Hampshire Daily'!V15-'Hampshire Daily'!V14)) -> 1 | S12: =IF(('Hampshire Daily'!W15-'Hampshire Daily'!W14<0),"0",('Hampshire Daily'!W15-'Hampshire Daily'!W14)) -> 0 | T12: =IF(('Hampshire Daily'!X15-'Hampshire Daily'!X14<0),"0",('Hampshire Daily'!X15-'Hampshire Daily'!X14)) -> 0.193 | U12: =IF(('Hampshire Daily'!Y15-'Hampshire Daily'!Y14<0),"0",('Hampshire Daily'!Y15-'Hampshire Daily'!Y14)) -> 0 | V12: =IF(('Hampshire Daily'!Z15-'Hampshire Daily'!Z14<0),"0",('Hampshire Daily'!Z15-'Hampshire Daily'!Z14)) -> 0 | W12: =IF(('Hampshire Daily'!AA15-'Hampshire Daily'!AA14<0),"0",('Hampshire Daily'!AA15-'Hampshire Daily'!AA14)) -> 6 | X12: =IF(('Hampshire Daily'!AA15-'Hampshire Daily'!AA14<0),"0",('Hampshire Daily'!AA15-'Hampshire Daily'!AA14)) -> 6 | Y12: ='Hampshire Daily'!B15 -> 0 | Z12: ='Hampshire Daily'!D15 -> 1142574
A13: Hampshire | B13: =B12+1 -> 12 | C13: 10 | D13: 2021 | E13: =IF(('Hampshire Daily'!E16-'Hampshire Daily'!E15<0),"0",('Hampshire Daily'!E16-'Hampshire Daily'!E15)) -> 2958 | F13: =IF(('Hampshire Daily'!G16-'Hampshire Daily'!G15<0),"0",('Hampshire Daily'!G16-'Hampshire Daily'!G15)) -> 1731 | G13: =IF(('Hampshire Daily'!H16-'Hampshire Daily'!H15<0),"0",('Hampshire Daily'!H16-'Hampshire Daily'!H15)) -> 0 | H13: =IF(('Hampshire Daily'!I16-'Hampshire Daily'!I15<0),"0",('Hampshire Daily'!I16-'Hampshire Daily'!I15)) -> 2006.4 | I13: =IF(('Hampshire Daily'!J16-'Hampshire Daily'!J15<0),"0",('Hampshire Daily'!J16-'Hampshire Daily'!J15)) -> 0 | J13: =IF(('Hampshire Daily'!L16-'Hampshire Daily'!L15<0),"0",('Hampshire Daily'!L16-'Hampshire Daily'!L15)) -> 1051 | K13: =IF(('Hampshire Daily'!M16-'Hampshire Daily'!M15<0),"0",('Hampshire Daily'!M16-'Hampshire Daily'!M15)) -> 1 | L13: =IF(('Hampshire Daily'!N16-'Hampshire Daily'!N15<0),"0",('Hampshire Daily'!N16-'Hampshire Daily'!N15)) -> 2999 | M13: =IF(('Hampshire Daily'!O16-'Hampshire Daily'!O15<0),"0",('Hampshire Daily'!O16-'Hampshire Daily'!O15)) -> 54 | N13: =IF(('Hampshire Daily'!P16-'Hampshire Daily'!P15<0),"0",('Hampshire Daily'!P16-'Hampshire Daily'!P15)) -> 0 | O13: =IF(('Hampshire Daily'!Q16-'Hampshire Daily'!Q15<0),"0",('Hampshire Daily'!Q16-'Hampshire Daily'!Q15)) -> 0 | P13: =IF(('Hampshire Daily'!R16-'Hampshire Daily'!R15<0),"0",('Hampshire Daily'!R16-'Hampshire Daily'!R15)) -> 658 | Q13: =IF(('Hampshire Daily'!S16-'Hampshire Daily'!S15<0),"0",('Hampshire Daily'!S16-'Hampshire Daily'!S15)) -> 19 | R13: =IF(('Hampshire Daily'!V16-'Hampshire Daily'!V15<0),"0",('Hampshire Daily'!V16-'Hampshire Daily'!V15)) -> 1 | S13: =IF(('Hampshire Daily'!W16-'Hampshire Daily'!W15<0),"0",('Hampshire Daily'!W16-'Hampshire Daily'!W15)) -> 0 | T13: =IF(('Hampshire Daily'!X16-'Hampshire Daily'!X15<0),"0",('Hampshire Daily'!X16-'Hampshire Daily'!X15)) -> 0.203 | U13: =IF(('Hampshire Daily'!Y16-'Hampshire Daily'!Y15<0),"0",('Hampshire Daily'!Y16-'Hampshire Daily'!Y15)) -> 0 | V13: =IF(('Hampshire Daily'!Z16-'Hampshire Daily'!Z15<0),"0",('Hampshire Daily'!Z16-'Hampshire Daily'!Z15)) -> 0 | W13: =IF(('Hampshire Daily'!AA16-'Hampshire Daily'!AA15<0),"0",('Hampshire Daily'!AA16-'Hampshire Daily'!AA15)) -> 5 | X13: =IF(('Hampshire Daily'!AA16-'Hampshire Daily'!AA15<0),"0",('Hampshire Daily'!AA16-'Hampshire Daily'!AA15)) -> 5 | Y13: ='Hampshire Daily'!B16 -> 0 | Z13: ='Hampshire Daily'!D16 -> 1145527
A14: Hampshire | B14: =B13+1 -> 13 | C14: 10 | D14: 2021 | E14: =IF(('Hampshire Daily'!E17-'Hampshire Daily'!E16<0),"0",('Hampshire Daily'!E17-'Hampshire Daily'!E16)) -> 2814 | F14: =IF(('Hampshire Daily'!G17-'Hampshire Daily'!G16<0),"0",('Hampshire Daily'!G17-'Hampshire Daily'!G16)) -> 5528 | G14: =IF(('Hampshire Daily'!H17-'Hampshire Daily'!H16<0),"0",('Hampshire Daily'!H17-'Hampshire Daily'!H16)) -> 814 | H14: =IF(('Hampshire Daily'!I17-'Hampshire Daily'!I16<0),"0",('Hampshire Daily'!I17-'Hampshire Daily'!I16)) -> 2006.4 | I14: =IF(('Hampshire Daily'!J17-'Hampshire Daily'!J16<0),"0",('Hampshire Daily'!J17-'Hampshire Daily'!J16)) -> 0 | J14: =IF(('Hampshire Daily'!L17-'Hampshire Daily'!L16<0),"0",('Hampshire Daily'!L17-'Hampshire Daily'!L16)) -> 1051 | K14: =IF(('Hampshire Daily'!M17-'Hampshire Daily'!M16<0),"0",('Hampshire Daily'!M17-'Hampshire Daily'!M16)) -> 1 | L14: =IF(('Hampshire Daily'!N17-'Hampshire Daily'!N16<0),"0",('Hampshire Daily'!N17-'Hampshire Daily'!N16)) -> 3075 | M14: =IF(('Hampshire Daily'!O17-'Hampshire Daily'!O16<0),"0",('Hampshire Daily'!O17-'Hampshire Daily'!O16)) -> 62 | N14: =IF(('Hampshire Daily'!P17-'Hampshire Daily'!P16<0),"0",('Hampshire Daily'!P17-'Hampshire Daily'!P16)) -> 236 | O14: =IF(('Hampshire Daily'!Q17-'Hampshire Daily'!Q16<0),"0",('Hampshire Daily'!Q17-'Hampshire Daily'!Q16)) -> 0 | P14: =IF(('Hampshire Daily'!R17-'Hampshire Daily'!R16<0),"0",('Hampshire Daily'!R17-'Hampshire Daily'!R16)) -> 496 | Q14: =IF(('Hampshire Daily'!S17-'Hampshire Daily'!S16<0),"0",('Hampshire Daily'!S17-'Hampshire Daily'!S16)) -> 29 | R14: =IF(('Hampshire Daily'!V17-'Hampshire Daily'!V16<0),"0",('Hampshire Daily'!V17-'Hampshire Daily'!V16)) -> 1 | S14: =IF(('Hampshire Daily'!W17-'Hampshire Daily'!W16<0),"0",('Hampshire Daily'!W17-'Hampshire Daily'!W16)) -> 0 | T14: =IF(('Hampshire Daily'!X17-'Hampshire Daily'!X16<0),"0",('Hampshire Daily'!X17-'Hampshire Daily'!X16)) -> 0.164 | U14: =IF(('Hampshire Daily'!Y17-'Hampshire Daily'!Y16<0),"0",('Hampshire Daily'!Y17-'Hampshire Daily'!Y16)) -> 0 | V14: =IF(('Hampshire Daily'!Z17-'Hampshire Daily'!Z16<0),"0",('Hampshire Daily'!Z17-'Hampshire Daily'!Z16)) -> 0 | W14: =IF(('Hampshire Daily'!AA17-'Hampshire Daily'!AA16<0),"0",('Hampshire Daily'!AA17-'Hampshire Daily'!AA16)) -> 4 | X14: =IF(('Hampshire Daily'!AA17-'Hampshire Daily'!AA16<0),"0",('Hampshire Daily'!AA17-'Hampshire Daily'!AA16)) -> 4 | Y14: ='Hampshire Daily'!B17 -> 0 | Z14: ='Hampshire Daily'!D17 -> 1148337
... A20: Hampshire | B20: =B19+1 -> 19 | C20: 10 | D20: 2021 | E20: =IF(('Hampshire Daily'!E23-'Hampshire Daily'!E22<0),"0",('Hampshire Daily'!E23-'Hampshire Daily'!E22)) -> 3195 | F20: =IF(('Hampshire Daily'!G23-'Hampshire Daily'!G22<0),"0",('Hampshire Daily'!G23-'Hampshire Daily'!G22)) -> 1988 | G20: =IF(('Hampshire Daily'!H23-'Hampshire Daily'!H22<0),"0",('Hampshire Daily'!H23-'Hampshire Daily'!H22)) -> 54 | H20: =IF(('Hampshire Daily'!I23-'Hampshire Daily'!I22<0),"0",('Hampshire Daily'!I23-'Hampshire Daily'!I22)) -> 2006.4 | I20: =IF(('Hampshire Daily'!J23-'Hampshire Daily'!J22<0),"0",('Hampshire Daily'!J23-'Hampshire Daily'!J22)) -> 0 | J20: =IF(('Hampshire Daily'!L23-'Hampshire Daily'!L22<0),"0",('Hampshire Daily'!L23-'Hampshire Daily'!L22)) -> 1051 | K20: =IF(('Hampshire Daily'!M23-'Hampshire Daily'!M22<0),"0",('Hampshire Daily'!M23-'Hampshire Daily'!M22)) -> 78 | L20: =IF(('Hampshire Daily'!N23-'Hampshire Daily'!N22<0),"0",('Hampshire Daily'!N23-'Hampshire Daily'!N22)) -> 3126 | M20: =IF(('Hampshire Daily'!O23-'Hampshire Daily'!O22<0),"0",('Hampshire Daily'!O23-'Hampshire Daily'!O22)) -> 52 | N20: =IF(('Hampshire Daily'!P23-'Hampshire Daily'!P22<0),"0",('Hampshire Daily'!P23-'Hampshire Daily'!P22)) -> 0 | O20: =IF(('Hampshire Daily'!Q23-'Hampshire Daily'!Q22<0),"0",('Hampshire Daily'!Q23-'Hampshire Daily'!Q22)) -> 0 | P20: =IF(('Hampshire Daily'!R23-'Hampshire Daily'!R22<0),"0",('Hampshire Daily'!R23-'Hampshire Daily'!R22)) -> 663 | Q20: =IF(('Hampshire Daily'!S23-'Hampshire Daily'!S22<0),"0",('Hampshire Daily'!S23-'Hampshire Daily'!S22)) -> 25 | R20: =IF(('Hampshire Daily'!V23-'Hampshire Daily'!V22<0),"0",('Hampshire Daily'!V23-'Hampshire Daily'!V22)) -> 2 | S20: =IF(('Hampshire Daily'!W23-'Hampshire Daily'!W22<0),"0",('Hampshire Daily'!W23-'Hampshire Daily'!W22)) -> 0 | T20: =IF(('Hampshire Daily'!X23-'Hampshire Daily'!X22<0),"0",('Hampshire Daily'!X23-'Hampshire Daily'!X22)) -> 0.215 | U20: =IF(('Hampshire Daily'!Y23-'Hampshire Daily'!Y22<0),"0",('Hampshire Daily'!Y23-'Hampshire Daily'!Y22)) -> 0 | V20: =IF(('Hampshire Daily'!Z23-'Hampshire Daily'!Z22<0),"0",('Hampshire Daily'!Z23-'Hampshire Daily'!Z22)) -> 0 | W20: =IF(('Hampshire Daily'!AA23-'Hampshire Daily'!AA22<0),"0",('Hampshire Daily'!AA23-'Hampshire Daily'!AA22)) -> 5 | X20: =IF(('Hampshire Daily'!AA23-'Hampshire Daily'!AA22<0),"0",('Hampshire Daily'!AA23-'Hampshire Daily'!AA22)) -> 5 | Y20: ='Hampshire Daily'!B23 -> 0 | Z20: ='Hampshire Daily'!D23 -> 1165894
A21: Hampshire | B21: =B20+1 -> 20 | C21: 10 | D21: 2021 | E21: =IF(('Hampshire Daily'!D24-'Hampshire Daily'!E23<0),"0",('Hampshire Daily'!D24-'Hampshire Daily'!E23)) -> 1056 | F21: =IF(('Hampshire Daily'!F24-'Hampshire Daily'!G23<0),"0",('Hampshire Daily'!F24-'Hampshire Daily'!G23)) -> 2773 | G21: =IF(('Hampshire Daily'!H24-'Hampshire Daily'!H23<0),"0",('Hampshire Daily'!H24-'Hampshire Daily'!H23)) -> 0 | H21: =IF(('Hampshire Daily'!I24-'Hampshire Daily'!I23<0),"0",('Hampshire Daily'!I24-'Hampshire Daily'!I23)) -> 2006.4 | I21: =IF(('Hampshire Daily'!J24-'Hampshire Daily'!J23<0),"0",('Hampshire Daily'!J24-'Hampshire Daily'!J23)) -> 0 | J21: =IF(('Hampshire Daily'!K24-'Hampshire Daily'!L23<0),"0",('Hampshire Daily'!K24-'Hampshire Daily'!L23)) -> 4672970.4 | K21: =IF(('Hampshire Daily'!L24-'Hampshire Daily'!M23<0),"0",('Hampshire Daily'!L24-'Hampshire Daily'!M23)) -> 0 | L21: =IF(('Hampshire Daily'!M24-'Hampshire Daily'!N23<0),"0",('Hampshire Daily'!M24-'Hampshire Daily'!N23)) -> 1125020 | M21: =IF(('Hampshire Daily'!N24-'Hampshire Daily'!O23<0),"0",('Hampshire Daily'!N24-'Hampshire Daily'!O23)) -> 1139851 | N21: =IF(('Hampshire Daily'!O24-'Hampshire Daily'!P23<0),"0",('Hampshire Daily'!O24-'Hampshire Daily'!P23)) -> 0 | O21: =IF(('Hampshire Daily'!P24-'Hampshire Daily'!Q23<0),"0",('Hampshire Daily'!P24-'Hampshire Daily'!Q23)) -> 1535473 | P21: =IF(('Hampshire Daily'!Q24-'Hampshire Daily'!R23<0),"0",('Hampshire Daily'!Q24-'Hampshire Daily'!R23)) -> 0 | Q21: =IF(('Hampshire Daily'!R24-'Hampshire Daily'!S23<0),"0",('Hampshire Daily'!R24-'Hampshire Daily'!S23)) -> 262134 | R21: =IF(('Hampshire Daily'!U24-'Hampshire Daily'!V23<0),"0",('Hampshire Daily'!U24-'Hampshire Daily'!V23)) -> 22001 | S21: =IF(('Hampshire Daily'!V24-'Hampshire Daily'!W23<0),"0",('Hampshire Daily'!V24-'Hampshire Daily'!W23)) -> 30613.669 | T21: =IF(('Hampshire Daily'!W24-'Hampshire Daily'!X23<0),"0",('Hampshire Daily'!W24-'Hampshire Daily'!X23)) -> 0 | U21: =IF(('Hampshire Daily'!X24-'Hampshire Daily'!Y23<0),"0",('Hampshire Daily'!X24-'Hampshire Daily'!Y23)) -> 0 | V21: =IF(('Hampshire Daily'!Y24-'Hampshire Daily'!Z23<0),"0",('Hampshire Daily'!Y24-'Hampshire Daily'!Z23)) -> 3890.049 | W21: =IF(('Hampshire Daily'!Z24-'Hampshire Daily'!AA23<0),"0",('Hampshire Daily'!Z24-'Hampshire Daily'!AA23)) -> 0 | X21: =IF(('Hampshire Daily'!AA24-'Hampshire Daily'!AA23<0),"0",('Hampshire Daily'!AA24-'Hampshire Daily'!AA23)) -> 5 | Y21: ='Hampshire Daily'!B24 -> 0 | Z21: ='Hampshire Daily'!C24 -> 34
A22: Hampshire | B22: =B21+1 -> 21 | C22: 10 | D22: 2021 | E22: =IF(('Hampshire Daily'!D25-'Hampshire Daily'!D24<0),"0",('Hampshire Daily'!D25-'Hampshire Daily'!D24)) -> 3106 | F22: =IF(('Hampshire Daily'!F25-'Hampshire Daily'!F24<0),"0",('Hampshire Daily'!F25-'Hampshire Daily'!F24)) -> 1719 | G22: =IF(('Hampshire Daily'!H25-'Hampshire Daily'!H24<0),"0",('Hampshire Daily'!H25-'Hampshire Daily'!H24)) -> 0 | H22: =IF(('Hampshire Daily'!I25-'Hampshire Daily'!I24<0),"0",('Hampshire Daily'!I25-'Hampshire Daily'!I24)) -> 2006.4 | I22: =IF(('Hampshire Daily'!J25-'Hampshire Daily'!J24<0),"0",('Hampshire Daily'!J25-'Hampshire Daily'!J24)) -> 0 | J22: =IF(('Hampshire Daily'!K25-'Hampshire Daily'!K24<0),"0",('Hampshire Daily'!K25-'Hampshire Daily'!K24)) -> 2429.4 | K22: =IF(('Hampshire Daily'!L25-'Hampshire Daily'!L24<0),"0",('Hampshire Daily'!L25-'Hampshire Daily'!L24)) -> 1051 | L22: =IF(('Hampshire Daily'!M25-'Hampshire Daily'!M24<0),"0",('Hampshire Daily'!M25-'Hampshire Daily'!M24)) -> 3 | M22: =IF(('Hampshire Daily'!N25-'Hampshire Daily'!N24<0),"0",('Hampshire Daily'!N25-'Hampshire Daily'!N24)) -> 5994 | N22: =IF(('Hampshire Daily'!O25-'Hampshire Daily'!O24<0),"0",('Hampshire Daily'!O25-'Hampshire Daily'!O24)) -> 54 | ... Q22: =IF(('Hampshire Daily'!R25-'Hampshire Daily'!R24<0),"0",('Hampshire Daily'!R25-'Hampshire Daily'!R24)) -> 530 | R22: =IF(('Hampshire Daily'!U25-'Hampshire Daily'!U24<0),"0",('Hampshire Daily'!U25-'Hampshire Daily'!U24)) -> 9 | S22: =IF(('Hampshire Daily'!V25-'Hampshire Daily'!V24<0),"0",('Hampshire Daily'!V25-'Hampshire Daily'!V24)) -> 2 | T22: =IF(('Hampshire Daily'!W25-'Hampshire Daily'!W24<0),"0",('Hampshire Daily'!W25-'Hampshire Daily'!W24)) -> 0 | U22: =IF(('Hampshire Daily'!X25-'Hampshire Daily'!X24<0),"0",('Hampshire Daily'!X25-'Hampshire Daily'!X24)) -> 0.296 | V22: =IF(('Hampshire Daily'!Y25-'Hampshire Daily'!Y24<0),"0",('Hampshire Daily'!Y25-'Hampshire Daily'!Y24)) -> 0 | W22: =IF(('Hampshire Daily'!Z25-'Hampshire Daily'!Z24<0),"0",('Hampshire Daily'!Z25-'Hampshire Daily'!Z24)) -> 0 | X22: =IF(('Hampshire Daily'!AA25-'Hampshire Daily'!AA24<0),"0",('Hampshire Daily'!AA25-'Hampshire Daily'!AA24)) -> 4 | Y22: ='Hampshire Daily'!B25 -> 0 | Z22: ='Hampshire Daily'!C25 -> 148
A23: Hampshire | B23: =B22+1 -> 22 | C23: 10 | D23: 2021 | E23: =IF(('Hampshire Daily'!D26-'Hampshire Daily'!D25<0),"0",('Hampshire Daily'!D26-'Hampshire Daily'!D25)) -> 2718 | F23: =IF(('Hampshire Daily'!F26-'Hampshire Daily'!F25<0),"0",('Hampshire Daily'!F26-'Hampshire Daily'!F25)) -> 1819 | G23: =IF(('Hampshire Daily'!H26-'Hampshire Daily'!H25<0),"0",('Hampshire Daily'!H26-'Hampshire Daily'!H25)) -> 1 | H23: =IF(('Hampshire Daily'!I26-'Hampshire Daily'!I25<0),"0",('Hampshire Daily'!I26-'Hampshire Daily'!I25)) -> 2006.4 | I23: =IF(('Hampshire Daily'!J26-'Hampshire Daily'!J25<0),"0",('Hampshire Daily'!J26-'Hampshire Daily'!J25)) -> 0 | J23: =IF(('Hampshire Daily'!K26-'Hampshire Daily'!K25<0),"0",('Hampshire Daily'!K26-'Hampshire Daily'!K25)) -> 2429.4 | K23: =IF(('Hampshire Daily'!L26-'Hampshire Daily'!L25<0),"0",('Hampshire Daily'!L26-'Hampshire Daily'!L25)) -> 1051 | L23: =IF(('Hampshire Daily'!M26-'Hampshire Daily'!M25<0),"0",('Hampshire Daily'!M26-'Hampshire Daily'!M25)) -> 10 | M23: =IF(('Hampshire Daily'!N26-'Hampshire Daily'!N25<0),"0",('Hampshire Daily'!N26-'Hampshire Daily'!N25)) -> 3361 | N23: =IF(('Hampshire Daily'!O26-'Hampshire Daily'!O25<0),"0",('Hampshire Daily'!O26-'Hampshire Daily'!O25)) -> 75 | ... Q23: =IF(('Hampshire Daily'!R26-'Hampshire Daily'!R25<0),"0",('Hampshire Daily'!R26-'Hampshire Daily'!R25)) -> 56 | R23: =IF(('Hampshire Daily'!U26-'Hampshire Daily'!U25<0),"0",('Hampshire Daily'!U26-'Hampshire Daily'!U25)) -> 11 | S23: =IF(('Hampshire Daily'!V26-'Hampshire Daily'!V25<0),"0",('Hampshire Daily'!V26-'Hampshire Daily'!V25)) -> 1 | T23: =IF(('Hampshire Daily'!W26-'Hampshire Daily'!W25<0),"0",('Hampshire Daily'!W26-'Hampshire Daily'!W25)) -> 0 | U23: =IF(('Hampshire Daily'!X26-'Hampshire Daily'!X25<0),"0",('Hampshire Daily'!X26-'Hampshire Daily'!X25)) -> 0.227 | V23: =IF(('Hampshire Daily'!Y26-'Hampshire Daily'!Y25<0),"0",('Hampshire Daily'!Y26-'Hampshire Daily'!Y25)) -> 0 | W23: =IF(('Hampshire Daily'!Z26-'Hampshire Daily'!Z25<0),"0",('Hampshire Daily'!Z26-'Hampshire Daily'!Z25)) -> 0 | X23: =IF(('Hampshire Daily'!AA26-'Hampshire Daily'!AA25<0),"0",('Hampshire Daily'!AA26-'Hampshire Daily'!AA25)) -> 5 | Y23: ='Hampshire Daily'!B26 -> 0 | Z23: ='Hampshire Daily'!C26 -> 146
A24: Hampshire | B24: =B23+1 -> 23 | C24: 10 | D24: 2021 | E24: =IF(('Hampshire Daily'!D27-'Hampshire Daily'!D26<0),"0",('Hampshire Daily'!D27-'Hampshire Daily'!D26)) -> 2454 | F24: =IF(('Hampshire Daily'!F27-'Hampshire Daily'!F26<0),"0",('Hampshire Daily'!F27-'Hampshire Daily'!F26)) -> 2730 | G24: =IF(('Hampshire Daily'!H27-'Hampshire Daily'!H26<0),"0",('Hampshire Daily'!H27-'Hampshire Daily'!H26)) -> 211 | H24: =IF(('Hampshire Daily'!I27-'Hampshire Daily'!I26<0),"0",('Hampshire Daily'!I27-'Hampshire Daily'!I26)) -> 2006.4 | I24: =IF(('Hampshire Daily'!J27-'Hampshire Daily'!J26<0),"0",('Hampshire Daily'!J27-'Hampshire Daily'!J26)) -> 0 | J24: =IF(('Hampshire Daily'!K27-'Hampshire Daily'!K26<0),"0",('Hampshire Daily'!K27-'Hampshire Daily'!K26)) -> 2429.4 | K24: =IF(('Hampshire Daily'!L27-'Hampshire Daily'!L26<0),"0",('Hampshire Daily'!L27-'Hampshire Daily'!L26)) -> 1051 | L24: =IF(('Hampshire Daily'!M27-'Hampshire Daily'!M26<0),"0",('Hampshire Daily'!M27-'Hampshire Daily'!M26)) -> 9 | M24: =IF(('Hampshire Daily'!N27-'Hampshire Daily'!N26<0),"0",('Hampshire Daily'!N27-'Hampshire Daily'!N26)) -> 2984 | N24: =IF(('Hampshire Daily'!O27-'Hampshire Daily'!O26<0),"0",('Hampshire Daily'!O27-'Hampshire Daily'!O26)) -> 74 | ... Q24: =IF(('Hampshire Daily'!R27-'Hampshire Daily'!R26<0),"0",('Hampshire Daily'!R27-'Hampshire Daily'!R26)) -> 251 | R24: =IF(('Hampshire Daily'!U27-'Hampshire Daily'!U26<0),"0",('Hampshire Daily'!U27-'Hampshire Daily'!U26)) -> 11 | S24: =IF(('Hampshire Daily'!V27-'Hampshire Daily'!V26<0),"0",('Hampshire Daily'!V27-'Hampshire Daily'!V26)) -> 1 | T24: =IF(('Hampshire Daily'!W27-'Hampshire Daily'!W26<0),"0",('Hampshire Daily'!W27-'Hampshire Daily'!W26)) -> 0 | U24: =IF(('Hampshire Daily'!X27-'Hampshire Daily'!X26<0),"0",('Hampshire Daily'!X27-'Hampshire Daily'!X26)) -> 0.245 | V24: =IF(('Hampshire Daily'!Y27-'Hampshire Daily'!Y26<0),"0",('Hampshire Daily'!Y27-'Hampshire Daily'!Y26)) -> 0 | W24: =IF(('Hampshire Daily'!Z27-'Hampshire Daily'!Z26<0),"0",('Hampshire Daily'!Z27-'Hampshire Daily'!Z26)) -> 0 | X24: =IF(('Hampshire Daily'!AA27-'Hampshire Daily'!AA26<0),"0",('Hampshire Daily'!AA27-'Hampshire Daily'!AA26)) -> 7 | Y24: ='Hampshire Daily'!B27 -> 0 | Z24: ='Hampshire Daily'!C27 -> 34
A25: Hampshire | B25: =B24+1 -> 24 | C25: 10 | D25: 2021 | E25: =IF(('Hampshire Daily'!D28-'Hampshire Daily'!D27<0),"0",('Hampshire Daily'!D28-'Hampshire Daily'!D27)) -> 2098 | F25: =IF(('Hampshire Daily'!F28-'Hampshire Daily'!F27<0),"0",('Hampshire Daily'!F28-'Hampshire Daily'!F27)) -> 2134 | G25: =IF(('Hampshire Daily'!H28-'Hampshire Daily'!H27<0),"0",('Hampshire Daily'!H28-'Hampshire Daily'!H27)) -> 36 | H25: =IF(('Hampshire Daily'!I28-'Hampshire Daily'!I27<0),"0",('Hampshire Daily'!I28-'Hampshire Daily'!I27)) -> 2006.4 | I25: =IF(('Hampshire Daily'!J28-'Hampshire Daily'!J27<0),"0",('Hampshire Daily'!J28-'Hampshire Daily'!J27)) -> 0 | J25: =IF(('Hampshire Daily'!K28-'Hampshire Daily'!K27<0),"0",('Hampshire Daily'!K28-'Hampshire Daily'!K27)) -> 2429.4 | K25: =IF(('Hampshire Daily'!L28-'Hampshire Daily'!L27<0),"0",('Hampshire Daily'!L28-'Hampshire Daily'!L27)) -> 1051 | L25: =IF(('Hampshire Daily'!M28-'Hampshire Daily'!M27<0),"0",('Hampshire Daily'!M28-'Hampshire Daily'!M27)) -> 11 | M25: =IF(('Hampshire Daily'!N28-'Hampshire Daily'!N27<0),"0",('Hampshire Daily'!N28-'Hampshire Daily'!N27)) -> 649 | N25: =IF(('Hampshire Daily'!O28-'Hampshire Daily'!O27<0),"0",('Hampshire Daily'!O28-'Hampshire Daily'!O27)) -> 77 | ... Q25: =IF(('Hampshire Daily'!R28-'Hampshire Daily'!R27<0),"0",('Hampshire Daily'!R28-'Hampshire Daily'!R27)) -> 64 | R25: =IF(('Hampshire Daily'!U28-'Hampshire Daily'!U27<0),"0",('Hampshire Daily'!U28-'Hampshire Daily'!U27)) -> 10 | S25: =IF(('Hampshire Daily'!V28-'Hampshire Daily'!V27<0),"0",('Hampshire Daily'!V28-'Hampshire Daily'!V27)) -> 5 | T25: =IF(('Hampshire Daily'!W28-'Hampshire Daily'!W27<0),"0",('Hampshire Daily'!W28-'Hampshire Daily'!W27)) -> 0 | U25: =IF(('Hampshire Daily'!X28-'Hampshire Daily'!X27<0),"0",('Hampshire Daily'!X28-'Hampshire Daily'!X27)) -> 0.188 | V25: =IF(('Hampshire Daily'!Y28-'Hampshire Daily'!Y27<0),"0",('Hampshire Daily'!Y28-'Hampshire Daily'!Y27)) -> 0 | W25: =IF(('Hampshire Daily'!Z28-'Hampshire Daily'!Z27<0),"0",('Hampshire Daily'!Z28-'Hampshire Daily'!Z27)) -> 0 | X25: =IF(('Hampshire Daily'!AA28-'Hampshire Daily'!AA27<0),"0",('Hampshire Daily'!AA28-'Hampshire Daily'!AA27)) -> 7 | Y25: ='Hampshire Daily'!B28 -> 0 | Z25: ='Hampshire Daily'!C28 -> 60
A26: Hampshire | B26: =B25+1 -> 25 | C26: 10 | D26: 2021 | E26: =IF(('Hampshire Daily'!D29-'Hampshire Daily'!D28<0),"0",('Hampshire Daily'!D29-'Hampshire Daily'!D28)) -> 2206 | F26: =IF(('Hampshire Daily'!F29-'Hampshire Daily'!F28<0),"0",('Hampshire Daily'!F29-'Hampshire Daily'!F28)) -> 1559 | G26: =IF(('Hampshire Daily'!H29-'Hampshire Daily'!H28<0),"0",('Hampshire Daily'!H29-'Hampshire Daily'!H28)) -> 36 | H26: =IF(('Hampshire Daily'!I29-'Hampshire Daily'!I28<0),"0",('Hampshire Daily'!I29-'Hampshire Daily'!I28)) -> 2006.4 | I26: =IF(('Hampshire Daily'!J29-'Hampshire Daily'!J28<0),"0",('Hampshire Daily'!J29-'Hampshire Daily'!J28)) -> 0 | J26: =IF(('Hampshire Daily'!K29-'Hampshire Daily'!K28<0),"0",('Hampshire Daily'!K29-'Hampshire Daily'!K28)) -> 2429.4 | K26: =IF(('Hampshire Daily'!L29-'Hampshire Daily'!L28<0),"0",('Hampshire Daily'!L29-'Hampshire Daily'!L28)) -> 1051 | L26: =IF(('Hampshire Daily'!M29-'Hampshire Daily'!M28<0),"0",('Hampshire Daily'!M29-'Hampshire Daily'!M28)) -> 10 | M26: =IF(('Hampshire Daily'!N29-'Hampshire Daily'!N28<0),"0",('Hampshire Daily'!N29-'Hampshire Daily'!N28)) -> 5735 | N26: =IF(('Hampshire Daily'!O29-'Hampshire Daily'!O28<0),"0",('Hampshire Daily'!O29-'Hampshire Daily'!O28)) -> 60 | ... Q26: =IF(('Hampshire Daily'!R29-'Hampshire Daily'!R28<0),"0",('Hampshire Daily'!R29-'Hampshire Daily'!R28)) -> 0 | R26: =IF(('Hampshire Daily'!U29-'Hampshire Daily'!U28<0),"0",('Hampshire Daily'!U29-'Hampshire Daily'!U28)) -> 10 | S26: =IF(('Hampshire Daily'!V29-'Hampshire Daily'!V28<0),"0",('Hampshire Daily'!V29-'Hampshire Daily'!V28)) -> 4 | T26: =IF(('Hampshire Daily'!W29-'Hampshire Daily'!W28<0),"0",('Hampshire Daily'!W29-'Hampshire Daily'!W28)) -> 0 | U26: =IF(('Hampshire Daily'!X29-'Hampshire Daily'!X28<0),"0",('Hampshire Daily'!X29-'Hampshire Daily'!X28)) -> 0.187 | V26: =IF(('Hampshire Daily'!Y29-'Hampshire Daily'!Y28<0),"0",('Hampshire Daily'!Y29-'Hampshire Daily'!Y28)) -> 0 | W26: =IF(('Hampshire Daily'!Z29-'Hampshire Daily'!Z28<0),"0",('Hampshire Daily'!Z29-'Hampshire Daily'!Z28)) -> 0 | X26: =IF(('Hampshire Daily'!AA29-'Hampshire Daily'!AA28<0),"0",('Hampshire Daily'!AA29-'Hampshire Daily'!AA28)) -> 4 | Y26: ='Hampshire Daily'!B29 -> 0 | Z26: ='Hampshire Daily'!C29 -> 68
A27: Hampshire | B27: =B26+1 -> 26 | C27: 10 | D27: 2021 | E27: =IF(('Hampshire Daily'!D30-'Hampshire Daily'!D29<0),"0",('Hampshire Daily'!D30-'Hampshire Daily'!D29)) -> 2256 | F27: =IF(('Hampshire Daily'!F30-'Hampshire Daily'!F29<0),"0",('Hampshire Daily'!F30-'Hampshire Daily'!F29)) -> 2078 | G27: =IF(('Hampshire Daily'!H30-'Hampshire Daily'!H29<0),"0",('Hampshire Daily'!H30-'Hampshire Daily'!H29)) -> 0 | H27: =IF(('Hampshire Daily'!I30-'Hampshire Daily'!I29<0),"0",('Hampshire Daily'!I30-'Hampshire Daily'!I29)) -> 2006.4 | I27: =IF(('Hampshire Daily'!J30-'Hampshire Daily'!J29<0),"0",('Hampshire Daily'!J30-'Hampshire Daily'!J29)) -> 0 | J27: =IF(('Hampshire Daily'!K30-'Hampshire Daily'!K29<0),"0",('Hampshire Daily'!K30-'Hampshire Daily'!K29)) -> 2429.4 | K27: =IF(('Hampshire Daily'!L30-'Hampshire Daily'!L29<0),"0",('Hampshire Daily'!L30-'Hampshire Daily'!L29)) -> 1051 | L27: =IF(('Hampshire Daily'!M30-'Hampshire Daily'!M29<0),"0",('Hampshire Daily'!M30-'Hampshire Daily'!M29)) -> 36 | M27: =IF(('Hampshire Daily'!N30-'Hampshire Daily'!N29<0),"0",('Hampshire Daily'!N30-'Hampshire Daily'!N29)) -> 3197 | N27: =IF(('Hampshire Daily'!O30-'Hampshire Daily'!O29<0),"0",('Hampshire Daily'!O30-'Hampshire Daily'!O29)) -> 59 | ... Q27: =IF(('Hampshire Daily'!R30-'Hampshire Daily'!R29<0),"0",('Hampshire Daily'!R30-'Hampshire Daily'!R29)) -> 0 | R27: =IF(('Hampshire Daily'!U30-'Hampshire Daily'!U29<0),"0",('Hampshire Daily'!U30-'Hampshire Daily'!U29)) -> 9 | S27: =IF(('Hampshire Daily'!V30-'Hampshire Daily'!V29<0),"0",('Hampshire Daily'!V30-'Hampshire Daily'!V29)) -> 1 | T27: =IF(('Hampshire Daily'!W30-'Hampshire Daily'!W29<0),"0",('Hampshire Daily'!W30-'Hampshire Daily'!W29)) -> 0 | U27: =IF(('Hampshire Daily'!X30-'Hampshire Daily'!X29<0),"0",('Hampshire Daily'!X30-'Hampshire Daily'!X29)) -> 0.199 | V27: =IF(('Hampshire Daily'!Y30-'Hampshire Daily'!Y29<0),"0",('Hampshire Daily'!Y30-'Hampshire Daily'!Y29)) -> 0.1 | W27: =IF(('Hampshire Daily'!Z30-'Hampshire Daily'!Z29<0),"0",('Hampshire Daily'!Z30-'Hampshire Daily'!Z29)) -> 0 | X27: =IF(('Hampshire Daily'!AA30-'Hampshire Daily'!AA29<0),"0",('Hampshire Daily'!AA30-'Hampshire Daily'!AA29)) -> 4 | Y27: ='Hampshire Daily'!B30 -> 0 | Z27: ='Hampshire Daily'!C30 -> 52
A28: Hampshire | B28: =B27+1 -> 27 | C28: 10 | D28: 2021 | E28: =IF(('Hampshire Daily'!D31-'Hampshire Daily'!D30<0),"0",('Hampshire Daily'!D31-'Hampshire Daily'!D30)) -> 1926 | F28: =IF(('Hampshire Daily'!F31-'Hampshire Daily'!F30<0),"0",('Hampshire Daily'!F31-'Hampshire Daily'!F30)) -> 2179 | G28: =IF(('Hampshire Daily'!H31-'Hampshire Daily'!H30<0),"0",('Hampshire Daily'!H31-'Hampshire Daily'!H30)) -> 1157 | H28: =IF(('Hampshire Daily'!I31-'Hampshire Daily'!I30<0),"0",('Hampshire Daily'!I31-'Hampshire Daily'!I30)) -> 2006.4 | I28: =IF(('Hampshire Daily'!J31-'Hampshire Daily'!J30<0),"0",('Hampshire Daily'!J31-'Hampshire Daily'!J30)) -> 0 | J28: =IF(('Hampshire Daily'!K31-'Hampshire Daily'!K30<0),"0",('Hampshire Daily'!K31-'Hampshire Daily'!K30)) -> 2429.4 | K28: =IF(('Hampshire Daily'!L31-'Hampshire Daily'!L30<0),"0",('Hampshire Daily'!L31-'Hampshire Daily'!L30)) -> 1051 | L28: =IF(('Hampshire Daily'!M31-'Hampshire Daily'!M30<0),"0",('Hampshire Daily'!M31-'Hampshire Daily'!M30)) -> 1 | M28: =IF(('Hampshire Daily'!N31-'Hampshire Daily'!N30<0),"0",('Hampshire Daily'!N31-'Hampshire Daily'!N30)) -> 2793 | N28: =IF(('Hampshire Daily'!O31-'Hampshire Daily'!O30<0),"0",('Hampshire Daily'!O31-'Hampshire Daily'!O30)) -> 61 | ... Q28: =IF(('Hampshire Daily'!R31-'Hampshire Daily'!R30<0),"0",('Hampshire Daily'!R31-'Hampshire Daily'!R30)) -> 16 | R28: =IF(('Hampshire Daily'!U31-'Hampshire Daily'!U30<0),"0",('Hampshire Daily'!U31-'Hampshire Daily'!U30)) -> 10 | S28: =IF(('Hampshire Daily'!V31-'Hampshire Daily'!V30<0),"0",('Hampshire Daily'!V31-'Hampshire Daily'!V30)) -> 1 | T28: =IF(('Hampshire Daily'!W31-'Hampshire Daily'!W30<0),"0",('Hampshire Daily'!W31-'Hampshire Daily'!W30)) -> 0 | U28: =IF(('Hampshire Daily'!X31-'Hampshire Daily'!X30<0),"0",('Hampshire Daily'!X31-'Hampshire Daily'!X30)) -> 0.18 | V28: =IF(('Hampshire Daily'!Y31-'Hampshire Daily'!Y30<0),"0",('Hampshire Daily'!Y31-'Hampshire Daily'!Y30)) -> 0 | W28: =IF(('Hampshire Daily'!Z31-'Hampshire Daily'!Z30<0),"0",('Hampshire Daily'!Z31-'Hampshire Daily'!Z30)) -> 0 | X28: =IF(('Hampshire Daily'!AA31-'Hampshire Daily'!AA30<0),"0",('Hampshire Daily'!AA31-'Hampshire Daily'!AA30)) -> 6 | Y28: ='Hampshire Daily'!B31 -> 0 | Z28: ='Hampshire Daily'!C31 -> 75
A29: Hampshire | B29: =B28+1 -> 28 | C29: 10 | D29: 2021 | E29: =IF(('Hampshire Daily'!D32-'Hampshire Daily'!D31<0),"0",('Hampshire Daily'!D32-'Hampshire Daily'!D31)) -> 2422 | F29: =IF(('Hampshire Daily'!F32-'Hampshire Daily'!F31<0),"0",('Hampshire Daily'!F32-'Hampshire Daily'!F31)) -> 1449 | G29: =IF(('Hampshire Daily'!H32-'Hampshire Daily'!H31<0),"0",('Hampshire Daily'!H32-'Hampshire Daily'!H31)) -> 5 | H29: =IF(('Hampshire Daily'!I32-'Hampshire Daily'!I31<0),"0",('Hampshire Daily'!I32-'Hampshire Daily'!I31)) -> 2006.4 | I29: =IF(('Hampshire Daily'!J32-'Hampshire Daily'!J31<0),"0",('Hampshire Daily'!J32-'Hampshire Daily'!J31)) -> 0 | J29: =IF(('Hampshire Daily'!K32-'Hampshire Daily'!K31<0),"0",('Hampshire Daily'!K32-'Hampshire Daily'!K31)) -> 2429.4 | K29: =IF(('Hampshire Daily'!L32-'Hampshire Daily'!L31<0),"0",('Hampshire Daily'!L32-'Hampshire Daily'!L31)) -> 1051 | L29: =IF(('Hampshire Daily'!M32-'Hampshire Daily'!M31<0),"0",('Hampshire Daily'!M32-'Hampshire Daily'!M31)) -> 1 | M29: =IF(('Hampshire Daily'!N32-'Hampshire Daily'!N31<0),"0",('Hampshire Daily'!N32-'Hampshire Daily'!N31)) -> 2815 | N29: =IF(('Hampshire Daily'!O32-'Hampshire Daily'!O31<0),"0",('Hampshire Daily'!O32-'Hampshire Daily'!O31)) -> 74 | ... Q29: =IF(('Hampshire Daily'!R32-'Hampshire Daily'!R31<0),"0",('Hampshire Daily'!R32-'Hampshire Daily'!R31)) -> 290 | R29: =IF(('Hampshire Daily'!U32-'Hampshire Daily'!U31<0),"0",('Hampshire Daily'!U32-'Hampshire Daily'!U31)) -> 9 | S29: =IF(('Hampshire Daily'!V32-'Hampshire Daily'!V31<0),"0",('Hampshire Daily'!V32-'Hampshire Daily'!V31)) -> 2 | T29: =IF(('Hampshire Daily'!W32-'Hampshire Daily'!W31<0),"0",('Hampshire Daily'!W32-'Hampshire Daily'!W31)) -> 0 | U29: =IF(('Hampshire Daily'!X32-'Hampshire Daily'!X31<0),"0",('Hampshire Daily'!X32-'Hampshire Daily'!X31)) -> 0.11 | V29: =IF(('Hampshire Daily'!Y32-'Hampshire Daily'!Y31<0),"0",('Hampshire Daily'!Y32-'Hampshire Daily'!Y31)) -> 0 | W29: =IF(('Hampshire Daily'!Z32-'Hampshire Daily'!Z31<0),"0",('Hampshire Daily'!Z32-'Hampshire Daily'!Z31)) -> 0 | X29: =IF(('Hampshire Daily'!AA32-'Hampshire Daily'!AA31<0),"0",('Hampshire Daily'!AA32-'Hampshire Daily'!AA31)) -> 4 | Y29: ='Hampshire Daily'!B32 -> 0 | Z29: ='Hampshire Daily'!C32 -> 90
A30: Hampshire | B30: =B29+1 -> 29 | C30: 10 | D30: 2021 | E30: =IF(('Hampshire Daily'!D33-'Hampshire Daily'!D32<0),"0",('Hampshire Daily'!D33-'Hampshire Daily'!D32)) -> 2205 | F30: =IF(('Hampshire Daily'!F33-'Hampshire Daily'!F32<0),"0",('Hampshire Daily'!F33-'Hampshire Daily'!F32)) -> 4509 | G30: =IF(('Hampshire Daily'!H33-'Hampshire Daily'!H32<0),"0",('Hampshire Daily'!H33-'Hampshire Daily'!H32)) -> 316 | H30: =IF(('Hampshire Daily'!I33-'Hampshire Daily'!I32<0),"0",('Hampshire Daily'!I33-'Hampshire Daily'!I32)) -> 2006.4 | I30: =IF(('Hampshire Daily'!J33-'Hampshire Daily'!J32<0),"0",('Hampshire Daily'!J33-'Hampshire Daily'!J32)) -> 0 | J30: =IF(('Hampshire Daily'!K33-'Hampshire Daily'!K32<0),"0",('Hampshire Daily'!K33-'Hampshire Daily'!K32)) -> 2429.4 | K30: =IF(('Hampshire Daily'!L33-'Hampshire Daily'!L32<0),"0",('Hampshire Daily'!L33-'Hampshire Daily'!L32)) -> 1051 | L30: =IF(('Hampshire Daily'!M33-'Hampshire Daily'!M32<0),"0",('Hampshire Daily'!M33-'Hampshire Daily'!M32)) -> 1 | M30: =IF(('Hampshire Daily'!N33-'Hampshire Daily'!N32<0),"0",('Hampshire Daily'!N33-'Hampshire Daily'!N32)) -> 2663 | N30: =IF(('Hampshire Daily'!O33-'Hampshire Daily'!O32<0),"0",('Hampshire Daily'!O33-'Hampshire Daily'!O32)) -> 62 | ... Q30: =IF(('Hampshire Daily'!R33-'Hampshire Daily'!R32<0),"0",('Hampshire Daily'!R33-'Hampshire Daily'!R32)) -> 18 | R30: =IF(('Hampshire Daily'!U33-'Hampshire Daily'!U32<0),"0",('Hampshire Daily'!U33-'Hampshire Daily'!U32)) -> 9 | S30: =IF(('Hampshire Daily'!V33-'Hampshire Daily'!V32<0),"0",('Hampshire Daily'!V33-'Hampshire Daily'!V32)) -> 1 | T30: =IF(('Hampshire Daily'!W33-'Hampshire Daily'!W32<0),"0",('Hampshire Daily'!W33-'Hampshire Daily'!W32)) -> 0 | U30: =IF(('Hampshire Daily'!X33-'Hampshire Daily'!X32<0),"0",('Hampshire Daily'!X33-'Hampshire Daily'!X32)) -> 0.188 | V30: =IF(('Hampshire Daily'!Y33-'Hampshire Daily'!Y32<0),"0",('Hampshire Daily'!Y33-'Hampshire Daily'!Y32)) -> 0 | W30: =IF(('Hampshire Daily'!Z33-'Hampshire Daily'!Z32<0),"0",('Hampshire Daily'!Z33-'Hampshire Daily'!Z32)) -> 0 | X30: =IF(('Hampshire Daily'!AA33-'Hampshire Daily'!AA32<0),"0",('Hampshire Daily'!AA33-'Hampshire Daily'!AA32)) -> 4 | Y30: ='Hampshire Daily'!B33 -> 0 | Z30: ='Hampshire Daily'!C33 -> 148
A31: Hampshire | B31: =B30+1 -> 30 | C31: 10 | D31: 2021 | E31: =IF(('Hampshire Daily'!D34-'Hampshire Daily'!D33<0),"0",('Hampshire Daily'!D34-'Hampshire Daily'!D33)) -> 2338 | F31: =IF(('Hampshire Daily'!F34-'Hampshire Daily'!F33<0),"0",('Hampshire Daily'!F34-'Hampshire Daily'!F33)) -> 5903 | G31: =IF(('Hampshire Daily'!H34-'Hampshire Daily'!H33<0),"0",('Hampshire Daily'!H34-'Hampshire Daily'!H33)) -> 788 | H31: =IF(('Hampshire Daily'!I34-'Hampshire Daily'!I33<0),"0",('Hampshire Daily'!I34-'Hampshire Daily'!I33)) -> 2006.4 | I31: =IF(('Hampshire Daily'!J34-'Hampshire Daily'!J33<0),"0",('Hampshire Daily'!J34-'Hampshire Daily'!J33)) -> 0 | J31: =IF(('Hampshire Daily'!K34-'Hampshire Daily'!K33<0),"0",('Hampshire Daily'!K34-'Hampshire Daily'!K33)) -> 2429.4 | K31: =IF(('Hampshire Daily'!L34-'Hampshire Daily'!L33<0),"0",('Hampshire Daily'!L34-'Hampshire Daily'!L33)) -> 1051 | L31: =IF(('Hampshire Daily'!M34-'Hampshire Daily'!M33<0),"0",('Hampshire Daily'!M34-'Hampshire Daily'!M33)) -> 2 | M31: =IF(('Hampshire Daily'!N34-'Hampshire Daily'!N33<0),"0",('Hampshire Daily'!N34-'Hampshire Daily'!N33)) -> 2641 | N31: =IF(('Hampshire Daily'!O34-'Hampshire Daily'!O33<0),"0",('Hampshire Daily'!O34-'Hampshire Daily'!O33)) -> 65 | ... Q31: =IF(('Hampshire Daily'!R34-'Hampshire Daily'!R33<0),"0",('Hampshire Daily'!R34-'Hampshire Daily'!R33)) -> 327 | R31: =IF(('Hampshire Daily'!U34-'Hampshire Daily'!U33<0),"0",('Hampshire Daily'!U34-'Hampshire Daily'!U33)) -> 11 | S31: =IF(('Hampshire Daily'!V34-'Hampshire Daily'!V33<0),"0",('Hampshire Daily'!V34-'Hampshire Daily'!V33)) -> 14 | T31: =IF(('Hampshire Daily'!W34-'Hampshire Daily'!W33<0),"0",('Hampshire Daily'!W34-'Hampshire Daily'!W33)) -> 0 | U31: =IF(('Hampshire Daily'!X34-'Hampshire Daily'!X33<0),"0",('Hampshire Daily'!X34-'Hampshire Daily'!X33)) -> 0.209 | V31: =IF(('Hampshire Daily'!Y34-'Hampshire Daily'!Y33<0),"0",('Hampshire Daily'!Y34-'Hampshire Daily'!Y33)) -> 0 | W31: =IF(('Hampshire Daily'!Z34-'Hampshire Daily'!Z33<0),"0",('Hampshire Daily'!Z34-'Hampshire Daily'!Z33)) -> 0 | X31: =IF(('Hampshire Daily'!AA34-'Hampshire Daily'!AA33<0),"0",('Hampshire Daily'!AA34-'Hampshire Daily'!AA33)) -> 5 | Y31: ='Hampshire Daily'!B34 -> 0 | Z31: ='Hampshire Daily'!C34 -> 50
