Workbook

Sheet Total
A1: Site Name | B1: Day | C1: Month | D1: Year | E1: Total Electricity Kwh | F1: Electricity Tariff ($/Kwh) | G1: LPG (Kg) | H1: LPG $/Kg | I1: Water Utility Supply (m3) m3 | J1: Water Utility Supply (m3) $/m3 | K1: Room Nights | L1: Utilities day cost dh
A2: Serengeti | B2: 1 | C2: 1 | D2: =Submetering!D2 -> 2022 | E2: ='UTILITY REPORT 1'!F3 -> 4734 | F2: =('UTILITY REPORT 1'!E3*'UTILITY REPORT 1'!D3)/'UTILITY REPORT 1'!F3 -> 0.41514575 | G2: =IF('Utility summery'!M6<0,"0",'Utility summery'!M6) -> 144.452 | H2: 2.165 | I2: =IF('UTILITY REPORT 1'!G3<0,"0",'UTILITY REPORT 1'!G3) -> 116 | J2: 0 | K2: 89 | L2: =E2*F2+G2*H2+#REF!*#REF!+I2*J2 -> #REF!
A3: Serengeti | B3: =B2+1 -> 2 | C3: 1 | D3: =Submetering!D3 -> 2022 | E3: ='UTILITY REPORT 1'!F4 -> 4563 | F3: =('UTILITY REPORT 1'!E4*'UTILITY REPORT 1'!D4)/'UTILITY REPORT 1'!F4 -> 0.42232742 | G3: =IF('Utility summery'!M7<0,"0",'Utility summery'!M7) -> 150.7 | H3: 2.165 | I3: =IF('UTILITY REPORT 1'!G4<0,"0",'UTILITY REPORT 1'!G4) -> 94 | J3: 0 | K3: 102 | L3: =E3*F3+G3*H3+#REF!*#REF!+I3*J3 -> #REF!
A4: Serengeti | B4: =B3+1 -> 3 | C4: 1 | D4: =Submetering!D4 -> 2022 | E4: ='UTILITY REPORT 1'!F5 -> 4574 | F4: =('UTILITY REPORT 1'!E5*'UTILITY REPORT 1'!D5)/'UTILITY REPORT 1'!F5 -> 0.40662877 | G4: =IF('Utility summery'!M8<0,"0",'Utility summery'!M8) -> 156.948 | H4: 2.165 | I4: =IF('UTILITY REPORT 1'!G5<0,"0",'UTILITY REPORT 1'!G5) -> 110 | J4: 0 | K4: 74 | L4: =E4*F4+G4*H4+#REF!*#REF!+I4*J4 -> #REF!
A5: Serengeti | B5: =B4+1 -> 4 | C5: 1 | D5: =Submetering!D5 -> 2022 | E5: ='UTILITY REPORT 1'!F6 -> 4346 | F5: =('UTILITY REPORT 1'!E6*'UTILITY REPORT 1'!D6)/'UTILITY REPORT 1'!F6 -> 0.43481362 | G5: =IF('Utility summery'!M9<0,"0",'Utility summery'!M9) -> 132.088 | H5: 2.165 | I5: =IF('UTILITY REPORT 1'!G6<0,"0",'UTILITY REPORT 1'!G6) -> 94 | J5: 0 | K5: 68 | L5: =E5*F5+G5*H5+#REF!*#REF!+I5*J5 -> #REF!
A6: Serengeti | B6: =B5+1 -> 5 | C6: 1 | D6: =Submetering!D6 -> 2022 | E6: ='UTILITY REPORT 1'!F7 -> 3969 | F6: =('UTILITY REPORT 1'!E7*'UTILITY REPORT 1'!D7)/'UTILITY REPORT 1'!F7 -> 0.43244898 | G6: =IF('Utility summery'!M10<0,"0",'Utility summery'!M10) -> 122.188 | H6: 2.165 | I6: =IF('UTILITY REPORT 1'!G7<0,"0",'UTILITY REPORT 1'!G7) -> 86 | J6: 0 | K6: 48 | L6: =E6*F6+G6*H6+#REF!*#REF!+I6*J6 -> #REF!
A7: Serengeti | B7: =B6+1 -> 6 | C7: 1 | D7: =Submetering!D7 -> 2022 | E7: ='UTILITY REPORT 1'!F8 -> 4325 | F7: =('UTILITY REPORT 1'!E8*'UTILITY REPORT 1'!D8)/'UTILITY REPORT 1'!F8 -> 0.42292486 | G7: =IF('Utility summery'!M11<0,"0",'Utility summery'!M11) -> 137.72 | H7: 2.165 | I7: =IF('UTILITY REPORT 1'!G8<0,"0",'UTILITY REPORT 1'!G8) -> 90 | J7: 0 | K7: 61 | L7: =E7*F7+G7*H7+#REF!*#REF!+I7*J7 -> #REF!
A8: Serengeti | B8: =B7+1 -> 7 | C8: 1 | D8: =Submetering!D8 -> 2022 | E8: ='UTILITY REPORT 1'!F9 -> 4444 | F8: =('UTILITY REPORT 1'!E9*'UTILITY REPORT 1'!D9)/'UTILITY REPORT 1'!F9 -> 0.41997075 | G8: =IF('Utility summery'!M12<0,"0",'Utility summery'!M12) -> 132.88 | H8: 2.165 | I8: =IF('UTILITY REPORT 1'!G9<0,"0",'UTILITY REPORT 1'!G9) -> 92 | J8: 0 | K8: 46 | L8: =E8*F8+G8*H8+#REF!*#REF!+I8*J8 -> #REF!
A9: Serengeti | B9: =B8+1 -> 8 | C9: 1 | D9: =Submetering!D9 -> 2022 | E9: ='UTILITY REPORT 1'!F10 -> 4291 | F9: =('UTILITY REPORT 1'!E10*'UTILITY REPORT 1'!D10)/'UTILITY REPORT 1'!F10 -> 0.41184805 | G9: =IF('Utility summery'!M13<0,"0",'Utility summery'!M13) -> 112.024 | H9: 2.165 | I9: =IF('UTILITY REPORT 1'!G10<0,"0",'UTILITY REPORT 1'!G10) -> 108 | J9: 0 | K9: 48 | L9: =E9*F9+G9*H9+#REF!*#REF!+I9*J9 -> #REF!
A10: Serengeti | B10: =B9+1 -> 9 | C10: 1 | D10: =Submetering!D10 -> 2022 | E10: ='UTILITY REPORT 1'!F11 -> 4336 | F10: =('UTILITY REPORT 1'!E11*'UTILITY REPORT 1'!D11)/'UTILITY REPORT 1'!F11 -> 0.42574954 | G10: =IF('Utility summery'!M14<0,"0",'Utility summery'!M14) -> 106.084 | H10: 2.165 | I10: =IF('UTILITY REPORT 1'!G11<0,"0",'UTILITY REPORT 1'!G11) -> 101 | J10: 0 | K10: 43 | L10: =E10*F10+G10*H10+#REF!*#REF!+I10*J10 -> #REF!
A11: Serengeti | B11: =B10+1 -> 10 | C11: 1 | D11: =Submetering!D11 -> 2022 | E11: ='UTILITY REPORT 1'!F12 -> 4279 | F11: =('UTILITY REPORT 1'!E12*'UTILITY REPORT 1'!D12)/'UTILITY REPORT 1'!F12 -> 0.41262678 | G11: =IF('Utility summery'!M15<0,"0",'Utility summery'!M15) -> 113.784 | H11: 2.165 | I11: =IF('UTILITY REPORT 1'!G12<0,"0",'UTILITY REPORT 1'!G12) -> 83 | J11: 0 | K11: 39 | L11: =E11*F11+G11*H11+#REF!*#REF!+I11*J11 -> #REF!
A12: Serengeti | B12: =B11+1 -> 11 | C12: 1 | D12: =Submetering!D12 -> 2022 | E12: ='UTILITY REPORT 1'!F13 -> 3862 | F12: =('UTILITY REPORT 1'!E13*'UTILITY REPORT 1'!D13)/'UTILITY REPORT 1'!F13 -> 0.42083894 | G12: =IF('Utility summery'!M16<0,"0",'Utility summery'!M16) -> 116.908 | H12: 2.165 | I12: =IF('UTILITY REPORT 1'!G13<0,"0",'UTILITY REPORT 1'!G13) -> 67 | J12: 0 | K12: 23 | L12: =E12*F12+G12*H12+#REF!*#REF!+I12*J12 -> #REF!
A13: Serengeti | B13: =B12+1 -> 12 | C13: 1 | D13: =Submetering!D13 -> 2022 | E13: ='UTILITY REPORT 1'!F14 -> 3803 | F13: =('UTILITY REPORT 1'!E14*'UTILITY REPORT 1'!D14)/'UTILITY REPORT 1'!F14 -> 0.42066001 | G13: =IF('Utility summery'!M17<0,"0",'Utility summery'!M17) -> 99.484 | H13: 2.165 | I13: =IF('UTILITY REPORT 1'!G14<0,"0",'UTILITY REPORT 1'!G14) -> 133 | J13: 0 | K13: 17 | L13: =E13*F13+G13*H13+#REF!*#REF!+I13*J13 -> #REF!
A14: Serengeti | B14: =B13+1 -> 13 | C14: 1 | D14: =Submetering!D14 -> 2022 | E14: ='UTILITY REPORT 1'!F15 -> 3648 | F14: =('UTILITY REPORT 1'!E15*'UTILITY REPORT 1'!D15)/'UTILITY REPORT 1'!F15 -> 0.41318257 | G14: =IF('Utility summery'!M18<0,"0",'Utility summery'!M18) -> 90.904 | H14: 2.165 | I14: =IF('UTILITY REPORT 1'!G15<0,"0",'UTILITY REPORT 1'!G15) -> 86 | J14: 0 | K14: 29 | L14: =E14*F14+G14*H14+#REF!*#REF!+I14*J14 -> #REF!
... A30: Serengeti | B30: =B29+1 -> 29 | C30: 1 | D30: =Submetering!D30 -> 2022 | E30: ='UTILITY REPORT 1'!F31 -> 3589 | F30: =('UTILITY REPORT 1'!E31*'UTILITY REPORT 1'!D31)/'UTILITY REPORT 1'!F31 -> 0.39403455 | G30: =IF('Utility summery'!M34<0,"0",'Utility summery'!M34) -> 112.816 | H30: 2.165 | I30: =IF('UTILITY REPORT 1'!G31<0,"0",'UTILITY REPORT 1'!G31) -> 80 | J30: 0 | K30: 20 | L30: =E30*F30+G30*H30+#REF!*#REF!+I30*J30 -> #REF!
A31: Serengeti | B31: 30 | C31: 1 | D31: =Submetering!D31 -> 2022 | E31: ='UTILITY REPORT 1'!F32 -> 3575 | F31: =('UTILITY REPORT 1'!E32*'UTILITY REPORT 1'!D32)/'UTILITY REPORT 1'!F32 -> 0.37674685 | G31: =IF('Utility summery'!M35<0,"0",'Utility summery'!M35) -> 103.796 | H31: 2.165 | I31: =IF('UTILITY REPORT 1'!G32<0,"0",'UTILITY REPORT 1'!G32) -> 110 | J31: 0 | K31: 18 | L31: =E31*F31+G31*H31+#REF!*#REF!+I31*J31 -> #REF!
A32: Serengeti | B32: 31 | C32: 1 | D32: =Submetering!D32 -> 2022 | E32: ='UTILITY REPORT 1'!F33 -> 3272 | F32: =('UTILITY REPORT 1'!E33*'UTILITY REPORT 1'!D33)/'UTILITY REPORT 1'!F33 -> 0.39228606 | G32: =IF('Utility summery'!M36<0,"0",'Utility summery'!M36) -> 0 | H32: 2.165 | I32: =IF('UTILITY REPORT 1'!G33<0,"0",'UTILITY REPORT 1'!G33) -> 104 | J32: 0 | K32: 12

Sheet Submetering
A1: Site Name | B1: Day | C1: Month | D1: Year | E1: Transport Consumption (LT) | F1: Generators Consumption (LT) | G1: Total Electricity Kwh | H1: Kitchen (KWh) | I1: Laundry (KWh) | J1: STP (M3) | K1: RO prodution (M3) | L1: Amani Restaurant (M3) | M1: Kitchen (M3) | N1: Laundry (M3) | O1: Laundry (M3) | P1: Total water Consumption (M3) | Q1: Borehole #1 (M3) | R1: Borehole #2 (M3) | S1: Borehole #3 (M3) | T1: Borehole #4 (M3) | U1: Borehole #5 (M3) | V1: Borehole #6 (M3) | W1: Total Bore holes production (M3) | X1: Room Nights
A2: Serengeti | B2: 1 | C2: 1 | D2: 2022 | E2: ='UTILITY REPORT 1'!I3 -> 320.11 | F2: ='UTILITY REPORT 1'!E3 -> 1965.3 | G2: ='UTILITY REPORT 1'!F3 -> 4734 | H2: =IF('Kit report'!F4<0,"0",'Kit report'!F4) -> 564 | I2: =IF('Kit report'!X4<0,"0",'Kit report'!X4) -> 940 | J2: =IF('Utility summery'!H6<0,"0",'Utility summery'!H6) -> 56 | K2: =IF('UTILITY REPORT 1'!H3<0,"0",'UTILITY REPORT 1'!H3) -> 102 | L2: ='Water-Meter'!K6 -> 3 | M2: ='Water-Meter'!H6 -> 0 | N2: ='Water-Meter'!Q6 -> 11 | O2: =K2*E2+H2*I2+#REF!*#REF!+J2*L2 -> #REF! | P2: ='Water-Meter'!E6 -> 116 | Q2: =IF('Water-Meter'!U6<0,"0",'Water-Meter'!U6) -> 69 | R2: =IF('Water-Meter'!X6<0,"0",'Water-Meter'!X6) -> 0 | S2: =IF('Water-Meter'!AA6<0,"0",'Water-Meter'!AA6) -> 36 | T2: =IF('Water-Meter'!AD6<0,"0",'Water-Meter'!AD6) -> 17 | U2: =IF('Water-Meter'!AG6<0,"0",'Water-Meter'!AG6) -> 0 | V2: =IF('Water-Meter'!AJ6<0,"0",'Water-Meter'!AJ6) -> 35 | W2: ='Water-Meter'!AN6 -> 157 | X2: =Total!K2 -> 89
A3: Serengeti | B3: =B2+1 -> 2 | C3: 1 | D3: 2022 | E3: ='UTILITY REPORT 1'!I4 -> 237.31 | F3: ='UTILITY REPORT 1'!E4 -> 1927.08 | G3: ='UTILITY REPORT 1'!F4 -> 4563 | H3: =IF('Kit report'!F5<0,"0",'Kit report'!F5) -> 204 | I3: =IF('Kit report'!X5<0,"0",'Kit report'!X5) -> 1040 | J3: =IF('Utility summery'!H7<0,"0",'Utility summery'!H7) -> 55 | K3: =IF('UTILITY REPORT 1'!H4<0,"0",'UTILITY REPORT 1'!H4) -> 64 | L3: ='Water-Meter'!K7 -> 3 | M3: ='Water-Meter'!H7 -> 0 | N3: ='Water-Meter'!Q7 -> 9 | O3: =K3*E3+H3*I3+#REF!*#REF!+J3*L3 -> #REF! | P3: ='Water-Meter'!E7 -> 94 | Q3: =IF('Water-Meter'!U7<0,"0",'Water-Meter'!U7) -> 70 | R3: =IF('Water-Meter'!X7<0,"0",'Water-Meter'!X7) -> 0 | S3: =IF('Water-Meter'!AA7<0,"0",'Water-Meter'!AA7) -> 36 | T3: =IF('Water-Meter'!AD7<0,"0",'Water-Meter'!AD7) -> 18 | U3: =IF('Water-Meter'!AG7<0,"0",'Water-Meter'!AG7) -> 0 | V3: =IF('Water-Meter'!AJ7<0,"0",'Water-Meter'!AJ7) -> 35 | W3: ='Water-Meter'!AN7 -> 159 | X3: =Total!K3 -> 102
A4: Serengeti | B4: =B3+1 -> 3 | C4: 1 | D4: 2022 | E4: ='UTILITY REPORT 1'!I5 -> 231 | F4: ='UTILITY REPORT 1'!E5 -> 1859.92 | G4: ='UTILITY REPORT 1'!F5 -> 4574 | H4: =IF('Kit report'!F6<0,"0",'Kit report'!F6) -> 276 | I4: =IF('Kit report'!X6<0,"0",'Kit report'!X6) -> 920 | J4: =IF('Utility summery'!H8<0,"0",'Utility summery'!H8) -> 56 | K4: =IF('UTILITY REPORT 1'!H5<0,"0",'UTILITY REPORT 1'!H5) -> 105 | L4: ='Water-Meter'!K8 -> 4 | M4: ='Water-Meter'!H8 -> 0 | N4: ='Water-Meter'!Q8 -> 12 | O4: =K4*E4+H4*I4+#REF!*#REF!+J4*L4 -> #REF! | P4: ='Water-Meter'!E8 -> 110 | Q4: =IF('Water-Meter'!U8<0,"0",'Water-Meter'!U8) -> 67 | R4: =IF('Water-Meter'!X8<0,"0",'Water-Meter'!X8) -> 0 | S4: =IF('Water-Meter'!AA8<0,"0",'Water-Meter'!AA8) -> 36 | T4: =IF('Water-Meter'!AD8<0,"0",'Water-Meter'!AD8) -> 18 | U4: =IF('Water-Meter'!AG8<0,"0",'Water-Meter'!AG8) -> 0 | V4: =IF('Water-Meter'!AJ8<0,"0",'Water-Meter'!AJ8) -> 36 | W4: ='Water-Meter'!AG17 -> 0 | X4: =Total!K4 -> 74
A5: Serengeti | B5: =B4+1 -> 4 | C5: 1 | D5: 2022 | E5: ='UTILITY REPORT 1'!I6 -> 247.48 | F5: ='UTILITY REPORT 1'!E6 -> 1889.7 | G5: ='UTILITY REPORT 1'!F6 -> 4346 | H5: =IF('Kit report'!F7<0,"0",'Kit report'!F7) -> 228 | I5: =IF('Kit report'!X7<0,"0",'Kit report'!X7) -> 740 | J5: =IF('Utility summery'!H9<0,"0",'Utility summery'!H9) -> 59 | K5: =IF('UTILITY REPORT 1'!H6<0,"0",'UTILITY REPORT 1'!H6) -> 147 | L5: ='Water-Meter'!K9 -> 3 | M5: ='Water-Meter'!H9 -> 0 | N5: ='Water-Meter'!Q9 -> 9 | O5: =K5*E5+H5*I5+#REF!*#REF!+J5*L5 -> #REF! | P5: ='Water-Meter'!E9 -> 94 | Q5: =IF('Water-Meter'!U9<0,"0",'Water-Meter'!U9) -> 69 | R5: =IF('Water-Meter'!X9<0,"0",'Water-Meter'!X9) -> 0 | S5: =IF('Water-Meter'!AA9<0,"0",'Water-Meter'!AA9) -> 38 | T5: =IF('Water-Meter'!AD9<0,"0",'Water-Meter'!AD9) -> 18 | U5: =IF('Water-Meter'!AG9<0,"0",'Water-Meter'!AG9) -> 0 | V5: =IF('Water-Meter'!AJ9<0,"0",'Water-Meter'!AJ9) -> 38 | W5: ='Water-Meter'!AN9 -> 163 | X5: =Total!K5 -> 68
A6: Serengeti | B6: =B5+1 -> 5 | C6: 1 | D6: 2022 | E6: ='UTILITY REPORT 1'!I7 -> 110 | F6: ='UTILITY REPORT 1'!E7 -> 1716.39 | G6: ='UTILITY REPORT 1'!F7 -> 3969 | H6: =IF('Kit report'!F8<0,"0",'Kit report'!F8) -> 204 | I6: =IF('Kit report'!X8<0,"0",'Kit report'!X8) -> 740 | J6: =IF('Utility summery'!H10<0,"0",'Utility summery'!H10) -> 49 | K6: =IF('UTILITY REPORT 1'!H7<0,"0",'UTILITY REPORT 1'!H7) -> 0 | L6: ='Water-Meter'!K10 -> 3 | M6: ='Water-Meter'!H10 -> 0 | N6: ='Water-Meter'!Q10 -> 9 | O6: =K6*E6+H6*I6+#REF!*#REF!+J6*L6 -> #REF! | P6: ='Water-Meter'!E10 -> 86 | Q6: =IF('Water-Meter'!U10<0,"0",'Water-Meter'!U10) -> 69 | R6: =IF('Water-Meter'!X10<0,"0",'Water-Meter'!X10) -> 0 | S6: =IF('Water-Meter'!AA10<0,"0",'Water-Meter'!AA10) -> 38 | T6: =IF('Water-Meter'!AD10<0,"0",'Water-Meter'!AD10) -> 16 | U6: =IF('Water-Meter'!AG10<0,"0",'Water-Meter'!AG10) -> 0 | V6: =IF('Water-Meter'!AJ10<0,"0",'Water-Meter'!AJ10) -> 33 | W6: ='Water-Meter'!AN10 -> 156 | X6: =Total!K6 -> 48
A7: Serengeti | B7: =B6+1 -> 6 | C7: 1 | D7: 2022 | E7: ='UTILITY REPORT 1'!I8 -> 299.04 | F7: ='UTILITY REPORT 1'!E8 -> 1829.15 | G7: ='UTILITY REPORT 1'!F8 -> 4325 | H7: =IF('Kit report'!F9<0,"0",'Kit report'!F9) -> 228 | I7: =IF('Kit report'!X9<0,"0",'Kit report'!X9) -> 660 | J7: =IF('Utility summery'!H11<0,"0",'Utility summery'!H11) -> 54 | K7: =IF('UTILITY REPORT 1'!H8<0,"0",'UTILITY REPORT 1'!H8) -> 148 | L7: ='Water-Meter'!K11 -> -1 | M7: ='Water-Meter'!H11 -> 0 | N7: ='Water-Meter'!Q11 -> 34 | O7: =K7*E7+H7*I7+#REF!*#REF!+J7*L7 -> #REF! | P7: ='Water-Meter'!E11 -> 90 | Q7: =IF('Water-Meter'!U11<0,"0",'Water-Meter'!U11) -> 67 | R7: =IF('Water-Meter'!X11<0,"0",'Water-Meter'!X11) -> 0 | S7: =IF('Water-Meter'!AA11<0,"0",'Water-Meter'!AA11) -> 32 | T7: =IF('Water-Meter'!AD11<0,"0",'Water-Meter'!AD11) -> 17 | U7: =IF('Water-Meter'!AG11<0,"0",'Water-Meter'!AG11) -> 0 | V7: =IF('Water-Meter'!AJ11<0,"0",'Water-Meter'!AJ11) -> 36 | W7: ='Water-Meter'!AN11 -> 152 | X7: =Total!K7 -> 61
A8: Serengeti | B8: =B7+1 -> 7 | C8: 1 | D8: 2022 | E8: ='UTILITY REPORT 1'!I9 -> 133 | F8: ='UTILITY REPORT 1'!E9 -> 1866.35 | G8: ='UTILITY REPORT 1'!F9 -> 4444 | H8: =IF('Kit report'!F10<0,"0",'Kit report'!F10) -> 216 | I8: =IF('Kit report'!X10<0,"0",'Kit report'!X10) -> 740 | J8: =IF('Utility summery'!H12<0,"0",'Utility summery'!H12) -> 0 | K8: =IF('UTILITY REPORT 1'!H9<0,"0",'UTILITY REPORT 1'!H9) -> 0 | L8: ='Water-Meter'!K12 -> 2 | M8: ='Water-Meter'!H12 -> 0 | N8: ='Water-Meter'!Q12 -> 8 | O8: =K8*E8+H8*I8+#REF!*#REF!+J8*L8 -> #REF! | P8: ='Water-Meter'!E12 -> 92 | Q8: =IF('Water-Meter'!U12<0,"0",'Water-Meter'!U12) -> 66 | R8: =IF('Water-Meter'!X12<0,"0",'Water-Meter'!X12) -> 0 | S8: =IF('Water-Meter'!AA12<0,"0",'Water-Meter'!AA12) -> 38 | T8: =IF('Water-Meter'!AD12<0,"0",'Water-Meter'!AD12) -> 16 | U8: =IF('Water-Meter'!AG12<0,"0",'Water-Meter'!AG12) -> 0 | V8: =IF('Water-Meter'!AJ12<0,"0",'Water-Meter'!AJ12) -> 37 | W8: ='Water-Meter'!AN12 -> 157 | X8: =Total!K8 -> 46
A9: Serengeti | B9: =B8+1 -> 8 | C9: 1 | D9: 2022 | E9: ='UTILITY REPORT 1'!I10 -> 162.47 | F9: ='UTILITY REPORT 1'!E10 -> 1767.24 | G9: ='UTILITY REPORT 1'!F10 -> 4291 | H9: =IF('Kit report'!F11<0,"0",'Kit report'!F11) -> 240 | I9: =IF('Kit report'!X11<0,"0",'Kit report'!X11) -> 700 | J9: =IF('Utility summery'!H13<0,"0",'Utility summery'!H13) -> 229265 | K9: =IF('UTILITY REPORT 1'!H10<0,"0",'UTILITY REPORT 1'!H10) -> 22575 | L9: ='Water-Meter'!K13 -> 2 | M9: ='Water-Meter'!H13 -> 0 | N9: ='Water-Meter'!Q13 -> 6 | O9: =K9*E9+H9*I9+#REF!*#REF!+J9*L9 -> #REF! | P9: ='Water-Meter'!E13 -> 108 | Q9: =IF('Water-Meter'!U13<0,"0",'Water-Meter'!U13) -> 72 | R9: =IF('Water-Meter'!X13<0,"0",'Water-Meter'!X13) -> 0 | S9: =IF('Water-Meter'!AA13<0,"0",'Water-Meter'!AA13) -> 35 | T9: =IF('Water-Meter'!AD13<0,"0",'Water-Meter'!AD13) -> 16 | U9: =IF('Water-Meter'!AG13<0,"0",'Water-Meter'!AG13) -> 0 | V9: =IF('Water-Meter'!AJ13<0,"0",'Water-Meter'!AJ13) -> 35 | W9: ='Water-Meter'!AN13 -> 158 | X9: =Total!K9 -> 48
A10: Serengeti | B10: =B9+1 -> 9 | C10: 1 | D10: 2022 | E10: ='UTILITY REPORT 1'!I11 -> 109.74 | F10: ='UTILITY REPORT 1'!E11 -> 1846.05 | G10: ='UTILITY REPORT 1'!F11 -> 4336 | H10: =IF('Kit report'!F12<0,"0",'Kit report'!F12) -> 252 | I10: =IF('Kit report'!X12<0,"0",'Kit report'!X12) -> 780 | J10: =IF('Utility summery'!H14<0,"0",'Utility summery'!H14) -> 56 | K10: =IF('UTILITY REPORT 1'!H11<0,"0",'UTILITY REPORT 1'!H11) -> 128 | L10: ='Water-Meter'!K14 -> 3 | M10: ='Water-Meter'!H14 -> 0 | N10: ='Water-Meter'!Q14 -> 4 | O10: =K10*E10+H10*I10+#REF!*#REF!+J10*L10 -> #REF! | P10: ='Water-Meter'!E14 -> 101 | Q10: =IF('Water-Meter'!U14<0,"0",'Water-Meter'!U14) -> 67 | R10: =IF('Water-Meter'!X14<0,"0",'Water-Meter'!X14) -> 0 | S10: =IF('Water-Meter'!AA14<0,"0",'Water-Meter'!AA14) -> 39 | T10: =IF('Water-Meter'!AD14<0,"0",'Water-Meter'!AD14) -> 13 | U10: =IF('Water-Meter'!AG14<0,"0",'Water-Meter'!AG14) -> 0 | V10: =IF('Water-Meter'!AJ14<0,"0",'Water-Meter'!AJ14) -> 35 | W10: ='Water-Meter'!AN14 -> 154 | X10: =Total!K10 -> 43
A11: Serengeti | B11: =B10+1 -> 10 | C11: 1 | D11: 2022 | E11: ='UTILITY REPORT 1'!I12 -> 79.83 | F11: ='UTILITY REPORT 1'!E12 -> 1765.63 | G11: ='UTILITY REPORT 1'!F12 -> 4279 | H11: =IF('Kit report'!F13<0,"0",'Kit report'!F13) -> 288 | I11: =IF('Kit report'!X13<0,"0",'Kit report'!X13) -> 640 | J11: =IF('Utility summery'!H15<0,"0",'Utility summery'!H15) -> 3 | K11: =IF('UTILITY REPORT 1'!H12<0,"0",'UTILITY REPORT 1'!H12) -> 77 | L11: ='Water-Meter'!K15 -> 2 | M11: ='Water-Meter'!H15 -> 0 | N11: ='Water-Meter'!Q15 -> 17 | O11: =K11*E11+H11*I11+#REF!*#REF!+J11*L11 -> #REF! | P11: ='Water-Meter'!E15 -> 83 | Q11: =IF('Water-Meter'!U15<0,"0",'Water-Meter'!U15) -> 0 | R11: =IF('Water-Meter'!X15<0,"0",'Water-Meter'!X15) -> 0 | S11: =IF('Water-Meter'!AA15<0,"0",'Water-Meter'!AA15) -> 38 | T11: =IF('Water-Meter'!AD15<0,"0",'Water-Meter'!AD15) -> 14 | U11: =IF('Water-Meter'!AG15<0,"0",'Water-Meter'!AG15) -> 0 | V11: =IF('Water-Meter'!AJ15<0,"0",'Water-Meter'!AJ15) -> 36 | W11: ='Water-Meter'!AN15 -> 88 | X11: =Total!K11 -> 39
A12: Serengeti | B12: =B11+1 -> 11 | C12: 1 | D12: 2022 | E12: ='UTILITY REPORT 1'!I13 -> 386.46 | F12: ='UTILITY REPORT 1'!E13 -> 1625.28 | G12: ='UTILITY REPORT 1'!F13 -> 3862 | H12: =IF('Kit report'!F14<0,"0",'Kit report'!F14) -> 288 | I12: =IF('Kit report'!X14<0,"0",'Kit report'!X14) -> 500 | J12: =IF('Utility summery'!H16<0,"0",'Utility summery'!H16) -> 3 | K12: =IF('UTILITY REPORT 1'!H13<0,"0",'UTILITY REPORT 1'!H13) -> 114 | L12: ='Water-Meter'!K16 -> 2 | M12: ='Water-Meter'!H16 -> 0 | N12: ='Water-Meter'!Q16 -> 8 | O12: =K12*E12+H12*I12+#REF!*#REF!+J12*L12 -> #REF! | P12: ='Water-Meter'!E16 -> 67 | Q12: =IF('Water-Meter'!U16<0,"0",'Water-Meter'!U16) -> 0 | R12: =IF('Water-Meter'!X16<0,"0",'Water-Meter'!X16) -> 0 | S12: =IF('Water-Meter'!AA16<0,"0",'Water-Meter'!AA16) -> 42 | T12: =IF('Water-Meter'!AD16<0,"0",'Water-Meter'!AD16) -> 11 | U12: =IF('Water-Meter'!AG16<0,"0",'Water-Meter'!AG16) -> 0 | V12: =IF('Water-Meter'!AJ16<0,"0",'Water-Meter'!AJ16) -> 34 | W12: ='Water-Meter'!AN16 -> 87 | X12: =Total!K12 -> 23
A13: Serengeti | B13: =B12+1 -> 12 | C13: 1 | D13: 2022 | E13: ='UTILITY REPORT 1'!I14 -> 0 | F13: ='UTILITY REPORT 1'!E14 -> 1599.77 | G13: ='UTILITY REPORT 1'!F14 -> 3803 | H13: =IF('Kit report'!F15<0,"0",'Kit report'!F15) -> 240 | I13: =IF('Kit report'!X15<0,"0",'Kit report'!X15) -> 540 | J13: =IF('Utility summery'!H17<0,"0",'Utility summery'!H17) -> 0 | K13: =IF('UTILITY REPORT 1'!H14<0,"0",'UTILITY REPORT 1'!H14) -> 112 | L13: ='Water-Meter'!K17 -> 3 | M13: ='Water-Meter'!H17 -> 0 | N13: ='Water-Meter'!Q17 -> 9 | O13: =K13*E13+H13*I13+#REF!*#REF!+J13*L13 -> #REF! | P13: ='Water-Meter'!E17 -> 133 | Q13: =IF('Water-Meter'!U17<0,"0",'Water-Meter'!U17) -> 0 | R13: =IF('Water-Meter'!X17<0,"0",'Water-Meter'!X17) -> 0 | S13: =IF('Water-Meter'!AA17<0,"0",'Water-Meter'!AA17) -> 38 | T13: =IF('Water-Meter'!AD17<0,"0",'Water-Meter'!AD17) -> 13 | U13: =IF('Water-Meter'!AG17<0,"0",'Water-Meter'!AG17) -> 0 | V13: =IF('Water-Meter'!AJ17<0,"0",'Water-Meter'!AJ17) -> 35 | W13: ='Water-Meter'!AN17 -> 86 | X13: =Total!K13 -> 17
A14: Serengeti | B14: =B13+1 -> 13 | C14: 1 | D14: 2022 | E14: ='UTILITY REPORT 1'!I15 -> 66.31 | F14: ='UTILITY REPORT 1'!E15 -> 1507.29 | G14: ='UTILITY REPORT 1'!F15 -> 3648 | H14: =IF('Kit report'!F16<0,"0",'Kit report'!F16) -> 288 | I14: =IF('Kit report'!X16<0,"0",'Kit report'!X16) -> 500 | J14: =IF('Utility summery'!H18<0,"0",'Utility summery'!H18) -> 0 | K14: =IF('UTILITY REPORT 1'!H15<0,"0",'UTILITY REPORT 1'!H15) -> 111 | L14: ='Water-Meter'!K18 -> 2 | M14: ='Water-Meter'!H18 -> 0 | N14: ='Water-Meter'!Q18 -> 6 | O14: =K14*E14+H14*I14+#REF!*#REF!+J14*L14 -> #REF! | P14: ='Water-Meter'!E18 -> 86 | Q14: =IF('Water-Meter'!U18<0,"0",'Water-Meter'!U18) -> 0 | R14: =IF('Water-Meter'!X18<0,"0",'Water-Meter'!X18) -> 0 | S14: =IF('Water-Meter'!AA18<0,"0",'Water-Meter'!AA18) -> 39 | T14: =IF('Water-Meter'!AD18<0,"0",'Water-Meter'!AD18) -> 14 | U14: =IF('Water-Meter'!AG18<0,"0",'Water-Meter'!AG18) -> 0 | V14: =IF('Water-Meter'!AJ18<0,"0",'Water-Meter'!AJ18) -> 33 | W14: ='Water-Meter'!AN18 -> 86 | X14: =Total!K14 -> 29
A15: Serengeti | B15: =B14+1 -> 14 | C15: 1 | D15: 2022 | E15: ='UTILITY REPORT 1'!I16 -> 288.08 | F15: ='UTILITY REPORT 1'!E16 -> 1511.92 | G15: ='UTILITY REPORT 1'!F16 -> 3795 | H15: =IF('Kit report'!F17<0,"0",'Kit report'!F17) -> 276 | I15: =IF('Kit report'!X17<0,"0",'Kit report'!X17) -> 500 | J15: =IF('Utility summery'!H19<0,"0",'Utility summery'!H19) -> 43 | K15: =IF('UTILITY REPORT 1'!H16<0,"0",'UTILITY REPORT 1'!H16) -> 92 | L15: ='Water-Meter'!K19 -> 2 | M15: ='Water-Meter'!H19 -> 0 | N15: ='Water-Meter'!Q19 -> 8 | O15: =K15*E15+H15*I15+#REF!*#REF!+J15*L15 -> #REF! | P15: ='Water-Meter'!E19 -> 92 | Q15: =IF('Water-Meter'!U19<0,"0",'Water-Meter'!U19) -> 0 | R15: =IF('Water-Meter'!X19<0,"0",'Water-Meter'!X19) -> 0 | S15: =IF('Water-Meter'!AA19<0,"0",'Water-Meter'!AA19) -> 40 | T15: =IF('Water-Meter'!AD19<0,"0",'Water-Meter'!AD19) -> 18 | U15: =IF('Water-Meter'!AG19<0,"0",'Water-Meter'!AG19) -> 0 | V15: =IF('Water-Meter'!AJ19<0,"0",'Water-Meter'!AJ19) -> 33 | W15: ='Water-Meter'!AN19 -> 91 | X15: =Total!K15 -> 37
A16: Serengeti | B16: =B15+1 -> 15 | C16: 1 | D16: 2022 | E16: ='UTILITY REPORT 1'!I17 -> 0 | F16: ='UTILITY REPORT 1'!E17 -> 1442 | G16: ='UTILITY REPORT 1'!F17 -> 3648 | H16: =IF('Kit report'!F18<0,"0",'Kit report'!F18) -> 276 | I16: =IF('Kit report'!X18<0,"0",'Kit report'!X18) -> 580 | J16: =IF('Utility summery'!H20<0,"0",'Utility summery'!H20) -> 26 | K16: =IF('UTILITY REPORT 1'!H17<0,"0",'UTILITY REPORT 1'!H17) -> 58 | L16: ='Water-Meter'!K20 -> 2 | M16: ='Water-Meter'!H20 -> 0 | N16: ='Water-Meter'!Q20 -> 10 | O16: =K16*E16+H16*I16+#REF!*#REF!+J16*L16 -> #REF! | P16: ='Water-Meter'!E20 -> 102 | Q16: =IF('Water-Meter'!U20<0,"0",'Water-Meter'!U20) -> 0 | R16: =IF('Water-Meter'!X20<0,"0",'Water-Meter'!X20) -> 0 | S16: =IF('Water-Meter'!AA20<0,"0",'Water-Meter'!AA20) -> 39 | T16: =IF('Water-Meter'!AD20<0,"0",'Water-Meter'!AD20) -> 27 | U16: =IF('Water-Meter'!AG20<0,"0",'Water-Meter'!AG20) -> 0 | V16: =IF('Water-Meter'!AJ20<0,"0",'Water-Meter'!AJ20) -> 0 | W16: ='Water-Meter'!AN20 -> 66 | X16: =Total!K16 -> 31
... A18: Serengeti | B18: =B17+1 -> 17 | C18: 1 | D18: 2022 | E18: ='UTILITY REPORT 1'!I19 -> 0 | F18: ='UTILITY REPORT 1'!E19 -> 1220.47 | G18: ='UTILITY REPORT 1'!F19 -> 2977 | H18: =IF('Kit report'!F20<0,"0",'Kit report'!F20) -> 204 | I18: =IF('Kit report'!X20<0,"0",'Kit report'!X20) -> 600 | J18: =IF('Utility summery'!H22<0,"0",'Utility summery'!H22) -> 36 | K18: =IF('UTILITY REPORT 1'!H19<0,"0",'UTILITY REPORT 1'!H19) -> 78 | L18: ='Water-Meter'!K22 -> 2 | M18: ='Water-Meter'!H22 -> 0 | N18: ='Water-Meter'!Q22 -> 7 | O18: =K18*E18+H18*I18+#REF!*#REF!+J18*L18 -> #REF! | P18: ='Water-Meter'!E22 -> 68 | Q18: =IF('Water-Meter'!U22<0,"0",'Water-Meter'!U22) -> 0 | R18: =IF('Water-Meter'!X22<0,"0",'Water-Meter'!X22) -> 0 | S18: =IF('Water-Meter'!AA22<0,"0",'Water-Meter'!AA22) -> 36 | T18: =IF('Water-Meter'!AD22<0,"0",'Water-Meter'!AD22) -> 25 | U18: =IF('Water-Meter'!AG22<0,"0",'Water-Meter'!AG22) -> 0 | V18: =IF('Water-Meter'!AJ22<0,"0",'Water-Meter'!AJ22) -> 0 | W18: ='Water-Meter'!AN22 -> 61 | X18: =Total!K18 -> 15
A19: Serengeti | B19: =B18+1 -> 18 | C19: 1 | D19: 2022 | E19: ='UTILITY REPORT 1'!I20 -> 221.01 | F19: ='UTILITY REPORT 1'!E20 -> 1382.64 | G19: ='UTILITY REPORT 1'!F20 -> 3443 | H19: =IF('Kit report'!F21<0,"0",'Kit report'!F21) -> 276 | I19: =IF('Kit report'!X21<0,"0",'Kit report'!X21) -> 540 | J19: =IF('Utility summery'!H23<0,"0",'Utility summery'!H23) -> 0 | K19: =IF('UTILITY REPORT 1'!H20<0,"0",'UTILITY REPORT 1'!H20) -> 0 | L19: ='Water-Meter'!K23 -> 2 | M19: ='Water-Meter'!H23 -> 0 | N19: ='Water-Meter'!Q23 -> 8 | O19: =K19*E19+H19*I19+#REF!*#REF!+J19*L19 -> #REF! | P19: ='Water-Meter'!E23 -> 62 | Q19: =IF('Water-Meter'!U23<0,"0",'Water-Meter'!U23) -> 0 | R19: =IF('Water-Meter'!X23<0,"0",'Water-Meter'!X23) -> 0 | S19: =IF('Water-Meter'!AA23<0,"0",'Water-Meter'!AA23) -> 37 | T19: =IF('Water-Meter'!AD23<0,"0",'Water-Meter'!AD23) -> 26 | U19: =IF('Water-Meter'!AG27<0,"0",'Water-Meter'!AG27) -> 0 | V19: =IF('Water-Meter'!AJ23<0,"0",'Water-Meter'!AJ23) -> 0 | W19: ='Water-Meter'!AN23 -> 63 | X19: =Total!K19 -> 25
A20: Serengeti | B20: =B19+1 -> 19 | C20: 1 | D20: 2022 | E20: ='UTILITY REPORT 1'!I21 -> 127.84 | F20: ='UTILITY REPORT 1'!E21 -> 1252.71 | G20: ='UTILITY REPORT 1'!F21 -> 3010 | H20: =IF('Kit report'!F22<0,"0",'Kit report'!F22) -> 192 | I20: =IF('Kit report'!X22<0,"0",'Kit report'!X22) -> 520 | J20: =IF('Utility summery'!H24<0,"0",'Utility summery'!H24) -> 1 | K20: =IF('UTILITY REPORT 1'!H21<0,"0",'UTILITY REPORT 1'!H21) -> 144 | L20: ='Water-Meter'!K24 -> 2 | M20: ='Water-Meter'!H24 -> 0 | N20: ='Water-Meter'!Q24 -> 6 | O20: =K20*E20+H20*I20+#REF!*#REF!+J20*L20 -> #REF! | P20: ='Water-Meter'!E24 -> 70 | Q20: =IF('Water-Meter'!U24<0,"0",'Water-Meter'!U24) -> 0 | R20: =IF('Water-Meter'!X24<0,"0",'Water-Meter'!X24) -> 0 | S20: =IF('Water-Meter'!AA24<0,"0",'Water-Meter'!AA24) -> 39 | T20: =IF('Water-Meter'!AD24<0,"0",'Water-Meter'!AD24) -> 13 | U20: =IF('Water-Meter'!AG24<0,"0",'Water-Meter'!AG24) -> 0 | V20: =IF('Water-Meter'!AJ24<0,"0",'Water-Meter'!AJ24) -> 0 | W20: ='Water-Meter'!AN24 -> 52 | X20: =Total!K20 -> 28
A21: Serengeti | B21: =B20+1 -> 20 | C21: 1 | D21: 2022 | E21: ='UTILITY REPORT 1'!I22 -> 238.02 | F21: ='UTILITY REPORT 1'!E22 -> 1370.45 | G21: ='UTILITY REPORT 1'!F22 -> 3323 | H21: =IF('Kit report'!F23<0,"0",'Kit report'!F23) -> 240 | I21: =IF('Kit report'!X23<0,"0",'Kit report'!X23) -> 500 | J21: =IF('Utility summery'!H25<0,"0",'Utility summery'!H25) -> 0 | K21: =IF('UTILITY REPORT 1'!H22<0,"0",'UTILITY REPORT 1'!H22) -> 45 | L21: ='Water-Meter'!K25 -> 2 | M21: ='Water-Meter'!H25 -> 0 | N21: ='Water-Meter'!Q25 -> 7 | O21: =K21*E21+H21*I21+#REF!*#REF!+J21*L21 -> #REF! | P21: ='Water-Meter'!E25 -> 88 | Q21: =IF('Water-Meter'!U25<0,"0",'Water-Meter'!U25) -> 80 | R21: =IF('Water-Meter'!X25<0,"0",'Water-Meter'!X25) -> 0 | S21: =IF('Water-Meter'!AA25<0,"0",'Water-Meter'!AA25) -> 39 | T21: =IF('Water-Meter'!AD25<0,"0",'Water-Meter'!AD25) -> 14 | U21: =IF('Water-Meter'!AG25<0,"0",'Water-Meter'!AG25) -> 0 | V21: =IF('Water-Meter'!AJ25<0,"0",'Water-Meter'!AJ25) -> 0 | W21: ='Water-Meter'!AN25 -> 133 | X21: =Total!K21 -> 29
A22: Serengeti | B22: =B21+1 -> 21 | C22: 1 | D22: 2022 | E22: ='UTILITY REPORT 1'!I23 -> 15 | F22: ='UTILITY REPORT 1'!E23 -> 1280.31 | G22: ='UTILITY REPORT 1'!F23 -> 3113 | H22: =IF('Kit report'!F24<0,"0",'Kit report'!F24) -> 228 | I22: =IF('Kit report'!X24<0,"0",'Kit report'!X24) -> 520 | J22: =IF('Utility summery'!H26<0,"0",'Utility summery'!H26) -> 30 | K22: =IF('UTILITY REPORT 1'!H23<0,"0",'UTILITY REPORT 1'!H23) -> 139 | L22: ='Water-Meter'!K26 -> 2 | M22: ='Water-Meter'!H26 -> 0 | N22: ='Water-Meter'!Q26 -> 8 | O22: =K22*E22+H22*I22+#REF!*#REF!+J22*L22 -> #REF! | P22: ='Water-Meter'!E26 -> 81 | Q22: =IF('Water-Meter'!U26<0,"0",'Water-Meter'!U26) -> 78 | R22: =IF('Water-Meter'!X26<0,"0",'Water-Meter'!X26) -> 0 | S22: =IF('Water-Meter'!AA26<0,"0",'Water-Meter'!AA26) -> 39 | T22: =IF('Water-Meter'!AD26<0,"0",'Water-Meter'!AD26) -> 13 | U22: =IF('Water-Meter'!AG26<0,"0",'Water-Meter'!AG26) -> 0 | V22: =IF('Water-Meter'!AJ26<0,"0",'Water-Meter'!AJ26) -> 8 | W22: ='Water-Meter'!AN26 -> 138 | X22: =Total!K22 -> 13
A23: Serengeti | B23: =B22+1 -> 22 | C23: 1 | D23: 2022 | E23: ='UTILITY REPORT 1'!I24 -> 264.82 | F23: ='UTILITY REPORT 1'!E24 -> 1286.26 | G23: ='UTILITY REPORT 1'!F24 -> 3124 | H23: =IF('Kit report'!F25<0,"0",'Kit report'!F25) -> 1183860 | I23: =IF('Kit report'!X25<0,"0",'Kit report'!X25) -> 460 | J23: =IF('Utility summery'!H27<0,"0",'Utility summery'!H27) -> 43 | K23: =IF('UTILITY REPORT 1'!H24<0,"0",'UTILITY REPORT 1'!H24) -> 100 | L23: ='Water-Meter'!K27 -> 2 | M23: ='Water-Meter'!H27 -> 0 | N23: ='Water-Meter'!Q27 -> 4 | O23: =K23*E23+H23*I23+#REF!*#REF!+J23*L23 -> #REF! | P23: ='Water-Meter'!E27 -> 71 | Q23: =IF('Water-Meter'!U27<0,"0",'Water-Meter'!U27) -> 80 | R23: =IF('Water-Meter'!X27<0,"0",'Water-Meter'!X27) -> 0 | S23: =IF('Water-Meter'!AA27<0,"0",'Water-Meter'!AA27) -> 37 | T23: =IF('Water-Meter'!AD27<0,"0",'Water-Meter'!AD27) -> 14 | U23: =IF('Water-Meter'!AG27<0,"0",'Water-Meter'!AG27) -> 0 | V23: =IF('Water-Meter'!AJ27<0,"0",'Water-Meter'!AJ27) -> 0 | W23: ='Water-Meter'!AN27 -> 131 | X23: =Total!K23 -> 11
A24: Serengeti | B24: =B23+1 -> 23 | C24: 1 | D24: 2022 | E24: ='UTILITY REPORT 1'!I25 -> 253.24 | F24: ='UTILITY REPORT 1'!E25 -> 1199.28 | G24: ='UTILITY REPORT 1'!F25 -> 2797 | H24: =IF('Kit report'!F26<0,"0",'Kit report'!F26) -> 204 | I24: =IF('Kit report'!X26<0,"0",'Kit report'!X26) -> 400 | J24: =IF('Utility summery'!H28<0,"0",'Utility summery'!H28) -> 93 | K24: =IF('UTILITY REPORT 1'!H25<0,"0",'UTILITY REPORT 1'!H25) -> 74 | L24: ='Water-Meter'!K28 -> 2 | M24: ='Water-Meter'!H28 -> 0 | N24: ='Water-Meter'!Q28 -> 3 | O24: =K24*E24+H24*I24+#REF!*#REF!+J24*L24 -> #REF! | P24: ='Water-Meter'!E28 -> 62 | Q24: =IF('Water-Meter'!U28<0,"0",'Water-Meter'!U28) -> 34 | R24: =IF('Water-Meter'!X28<0,"0",'Water-Meter'!X28) -> 0 | S24: =IF('Water-Meter'!AA28<0,"0",'Water-Meter'!AA28) -> 39 | T24: =IF('Water-Meter'!AD28<0,"0",'Water-Meter'!AD28) -> 18 | U24: =IF('Water-Meter'!AG28<0,"0",'Water-Meter'!AG28) -> 0 | V24: =IF('Water-Meter'!AJ28<0,"0",'Water-Meter'!AJ28) -> 0 | W24: ='Water-Meter'!AN28 -> 91 | X24: =Total!K24 -> 5
A25: Serengeti | B25: =B24+1 -> 24 | C25: 1 | D25: 2022 | E25: ='UTILITY REPORT 1'!I26 -> 237.04 | F25: ='UTILITY REPORT 1'!E26 -> 1340.81 | G25: ='UTILITY REPORT 1'!F26 -> 3295 | H25: =IF('Kit report'!F27<0,"0",'Kit report'!F27) -> 240 | I25: =IF('Kit report'!X27<0,"0",'Kit report'!X27) -> 480 | J25: =IF('Utility summery'!H29<0,"0",'Utility summery'!H29) -> 61 | K25: =IF('UTILITY REPORT 1'!H26<0,"0",'UTILITY REPORT 1'!H26) -> 17 | L25: ='Water-Meter'!K29 -> 3 | M25: ='Water-Meter'!H29 -> 0 | N25: ='Water-Meter'!Q29 -> 9 | O25: =K25*E25+H25*I25+#REF!*#REF!+J25*L25 -> #REF! | P25: ='Water-Meter'!E29 -> 75 | Q25: =IF('Water-Meter'!U29<0,"0",'Water-Meter'!U29) -> 0 | R25: =IF('Water-Meter'!X29<0,"0",'Water-Meter'!X29) -> 0 | S25: =IF('Water-Meter'!AA29<0,"0",'Water-Meter'!AA29) -> 39 | T25: =IF('Water-Meter'!AD29<0,"0",'Water-Meter'!AD29) -> 16 | U25: =IF('Water-Meter'!AG29<0,"0",'Water-Meter'!AG29) -> 0 | V25: =IF('Water-Meter'!AJ29<0,"0",'Water-Meter'!AJ29) -> 0 | W25: ='Water-Meter'!AN29 -> 55 | X25: =Total!K25 -> 15
A26: Serengeti | B26: =B25+1 -> 25 | C26: 1 | D26: 2022 | E26: ='UTILITY REPORT 1'!I27 -> 118.03 | F26: ='UTILITY REPORT 1'!E27 -> 1255.47 | G26: ='UTILITY REPORT 1'!F27 -> 3205 | H26: =IF('Kit report'!F28<0,"0",'Kit report'!F28) -> 264 | I26: =IF('Kit report'!X28<0,"0",'Kit report'!X28) -> 7000 | J26: =IF('Utility summery'!H30<0,"0",'Utility summery'!H30) -> 65 | K26: =IF('UTILITY REPORT 1'!H27<0,"0",'UTILITY REPORT 1'!H27) -> 133 | L26: ='Water-Meter'!K30 -> 2 | M26: ='Water-Meter'!H30 -> 0 | N26: ='Water-Meter'!Q30 -> 7 | O26: =K26*E26+H26*I26+#REF!*#REF!+J26*L26 -> #REF! | P26: ='Water-Meter'!E30 -> 160 | Q26: =IF('Water-Meter'!U30<0,"0",'Water-Meter'!U30) -> 0 | R26: =IF('Water-Meter'!X30<0,"0",'Water-Meter'!X30) -> 0 | S26: =IF('Water-Meter'!AA30<0,"0",'Water-Meter'!AA30) -> 36 | T26: =IF('Water-Meter'!AD30<0,"0",'Water-Meter'!AD30) -> 17 | U26: =IF('Water-Meter'!AG30<0,"0",'Water-Meter'!AG30) -> 0 | V26: =IF('Water-Meter'!AJ30<0,"0",'Water-Meter'!AJ30) -> 0 | W26: ='Water-Meter'!AN30 -> 53 | X26: =Total!K26 -> 23
A27: Serengeti | B27: =B26+1 -> 26 | C27: 1 | D27: 2022 | E27: ='UTILITY REPORT 1'!I28 -> 73.37 | F27: ='UTILITY REPORT 1'!E28 -> 1351.98 | G27: ='UTILITY REPORT 1'!F28 -> 3575 | H27: =IF('Kit report'!F29<0,"0",'Kit report'!F29) -> 264 | I27: =IF('Kit report'!X29<0,"0",'Kit report'!X29) -> 480 | J27: =IF('Utility summery'!H31<0,"0",'Utility summery'!H31) -> 67 | K27: =IF('UTILITY REPORT 1'!H28<0,"0",'UTILITY REPORT 1'!H28) -> 12 | L27: ='Water-Meter'!K31 -> 2 | M27: ='Water-Meter'!H31 -> 0 | N27: ='Water-Meter'!Q31 -> 5 | O27: =K27*E27+H27*I27+#REF!*#REF!+J27*L27 -> #REF! | P27: ='Water-Meter'!E31 -> 66 | Q27: =IF('Water-Meter'!U31<0,"0",'Water-Meter'!U31) -> 71 | R27: =IF('Water-Meter'!X31<0,"0",'Water-Meter'!X31) -> 0 | S27: =IF('Water-Meter'!AA31<0,"0",'Water-Meter'!AA31) -> 36 | T27: =IF('Water-Meter'!AD31<0,"0",'Water-Meter'!AD31) -> 16 | U27: =IF('Water-Meter'!AG31<0,"0",'Water-Meter'!AG31) -> 0 | V27: =IF('Water-Meter'!AJ31<0,"0",'Water-Meter'!AJ31) -> 0 | W27: ='Water-Meter'!AN31 -> 123 | X27: =Total!K27 -> 24
A28: Serengeti | B28: =B27+1 -> 27 | C28: 1 | D28: 2022 | E28: ='UTILITY REPORT 1'!I29 -> 353.88 | F28: ='UTILITY REPORT 1'!E29 -> 1411.45 | G28: ='UTILITY REPORT 1'!F29 -> 3610 | H28: =IF('Kit report'!F30<0,"0",'Kit report'!F30) -> 228 | I28: =IF('Kit report'!X30<0,"0",'Kit report'!X30) -> 520 | J28: =IF('Utility summery'!H32<0,"0",'Utility summery'!H32) -> 76 | K28: =IF('UTILITY REPORT 1'!H29<0,"0",'UTILITY REPORT 1'!H29) -> 184 | L28: ='Water-Meter'!K32 -> 2 | M28: ='Water-Meter'!H32 -> 0 | N28: ='Water-Meter'!Q32 -> 6 | O28: =K28*E28+H28*I28+#REF!*#REF!+J28*L28 -> #REF! | P28: ='Water-Meter'!E32 -> 75 | Q28: =IF('Water-Meter'!U32<0,"0",'Water-Meter'!U32) -> 69 | R28: =IF('Water-Meter'!X32<0,"0",'Water-Meter'!X32) -> 0 | S28: =IF('Water-Meter'!AA32<0,"0",'Water-Meter'!AA32) -> 42 | T28: =IF('Water-Meter'!AD32<0,"0",'Water-Meter'!AD32) -> 17 | U28: =IF('Water-Meter'!AG32<0,"0",'Water-Meter'!AG32) -> 0 | V28: =IF('Water-Meter'!AJ32<0,"0",'Water-Meter'!AJ32) -> 49 | W28: ='Water-Meter'!AN32 -> 177 | X28: =Total!K28 -> 22
A29: Serengeti | B29: =B28+1 -> 28 | C29: 1 | D29: 2022 | E29: ='UTILITY REPORT 1'!I30 -> 0 | F29: ='UTILITY REPORT 1'!E30 -> 1429.2 | G29: ='UTILITY REPORT 1'!F30 -> 3593 | H29: =IF('Kit report'!F31<0,"0",'Kit report'!F31) -> 264 | I29: =IF('Kit report'!X31<0,"0",'Kit report'!X31) -> 480 | J29: =IF('Utility summery'!H33<0,"0",'Utility summery'!H33) -> 61 | K29: =IF('UTILITY REPORT 1'!H30<0,"0",'UTILITY REPORT 1'!H30) -> 66 | L29: ='Water-Meter'!K33 -> 2 | M29: ='Water-Meter'!H33 -> 0 | N29: ='Water-Meter'!Q33 -> 5 | O29: =K29*E29+H29*I29+#REF!*#REF!+J29*L29 -> #REF! | P29: ='Water-Meter'!E33 -> 64 | Q29: =IF('Water-Meter'!U33<0,"0",'Water-Meter'!U33) -> 69 | R29: =IF('Water-Meter'!X33<0,"0",'Water-Meter'!X33) -> 0 | S29: =IF('Water-Meter'!AA33<0,"0",'Water-Meter'!AA33) -> 37 | T29: =IF('Water-Meter'!AD33<0,"0",'Water-Meter'!AD33) -> 15 | U29: =IF('Water-Meter'!AG33<0,"0",'Water-Meter'!AG33) -> 0 | V29: =IF('Water-Meter'!AJ33<0,"0",'Water-Meter'!AJ33) -> 38 | W29: ='Water-Meter'!AN33 -> 159 | X29: =Total!K29 -> 18
A30: Serengeti | B30: =B29+1 -> 29 | C30: 1 | D30: 2022 | E30: ='UTILITY REPORT 1'!I31 -> 48.59 | F30: ='UTILITY REPORT 1'!E31 -> 1414.19 | G30: ='UTILITY REPORT 1'!F31 -> 3589 | H30: =IF('Kit report'!F32<0,"0",'Kit report'!F32) -> 264 | I30: =IF('Kit report'!X32<0,"0",'Kit report'!X32) -> 560 | J30: =IF('Utility summery'!H34<0,"0",'Utility summery'!H34) -> 67 | K30: =IF('UTILITY REPORT 1'!H31<0,"0",'UTILITY REPORT 1'!H31) -> 135 | L30: ='Water-Meter'!K34 -> 6 | M30: ='Water-Meter'!H34 -> 0 | N30: ='Water-Meter'!Q34 -> 6 | O30: =K30*E30+H30*I30+#REF!*#REF!+J30*L30 -> #REF! | P30: ='Water-Meter'!E34 -> 80 | Q30: =IF('Water-Meter'!U34<0,"0",'Water-Meter'!U34) -> 68 | R30: =IF('Water-Meter'!X34<0,"0",'Water-Meter'!X34) -> 0 | S30: =IF('Water-Meter'!AA34<0,"0",'Water-Meter'!AA34) -> 36 | T30: =IF('Water-Meter'!AD34<0,"0",'Water-Meter'!AD34) -> 15 | U30: =IF('Water-Meter'!AG34<0,"0",'Water-Meter'!AG34) -> 0 | V30: =IF('Water-Meter'!AJ34<0,"0",'Water-Meter'!AJ34) -> 36 | W30: ='Water-Meter'!AN34 -> 155 | X30: =Total!K30 -> 20
A31: Serengeti | B31: 30 | C31: 1 | D31: 2022 | E31: ='UTILITY REPORT 1'!I32 -> 96 | F31: ='UTILITY REPORT 1'!E32 -> 1346.87 | G31: ='UTILITY REPORT 1'!F32 -> 3575 | H31: =IF('Kit report'!F33<0,"0",'Kit report'!F33) -> 216 | I31: =IF('Kit report'!X33<0,"0",'Kit report'!X33) -> 400 | J31: =IF('Utility summery'!H35<0,"0",'Utility summery'!H35) -> 68 | K31: =IF('UTILITY REPORT 1'!H32<0,"0",'UTILITY REPORT 1'!H32) -> 11 | L31: ='Water-Meter'!K35 -> 3 | M31: ='Water-Meter'!H35 -> 0 | N31: ='Water-Meter'!Q35 -> 8 | O31: =K31*E31+H31*I31+#REF!*#REF!+J31*L31 -> #REF! | P31: ='Water-Meter'!E35 -> 110 | Q31: =IF('Water-Meter'!U35<0,"0",'Water-Meter'!U35) -> 67 | R31: =IF('Water-Meter'!X35<0,"0",'Water-Meter'!X35) -> 0 | S31: =IF('Water-Meter'!AA35<0,"0",'Water-Meter'!AA35) -> 36 | T31: =IF('Water-Meter'!AD35<0,"0",'Water-Meter'!AD35) -> 14 | U31: =IF('Water-Meter'!AG35<0,"0",'Water-Meter'!AG35) -> 0 | V31: =IF('Water-Meter'!AJ35<0,"0",'Water-Meter'!AJ35) -> 36 | W31: ='Water-Meter'!AN35 -> 153 | X31: =Total!K31 -> 18
A32: Serengeti | B32: 31 | C32: 1 | D32: 2022 | E32: ='UTILITY REPORT 1'!I33 -> 511.7 | F32: ='UTILITY REPORT 1'!E33 -> 1283.56 | G32: ='UTILITY REPORT 1'!F33 -> 3272 | H32: =IF('Kit report'!F34<0,"0",'Kit report'!F34) -> 180 | I32: =IF('Kit report'!X34<0,"0",'Kit report'!X34) -> 460 | J32: =IF('Utility summery'!H36<0,"0",'Utility summery'!H36) -> 66 | K32: =IF('UTILITY REPORT 1'!H33<0,"0",'UTILITY REPORT 1'!H33) -> 135 | L32: ='Water-Meter'!K36 -> 3 | M32: ='Water-Meter'!H36 -> 0 | N32: ='Water-Meter'!Q36 -> 9 | P32: ='Water-Meter'!E36 -> 104 | Q32: =IF('Water-Meter'!U36<0,"0",'Water-Meter'!U36) -> 63 | R32: =IF('Water-Meter'!X36<0,"0",'Water-Meter'!X36) -> 0 | S32: =IF('Water-Meter'!AA36<0,"0",'Water-Meter'!AA36) -> 36 | T32: =IF('Water-Meter'!AD36<0,"0",'Water-Meter'!AD36) -> 15 | U32: =IF('Water-Meter'!AG36<0,"0",'Water-Meter'!AG36) -> 0 | V32: =IF('Water-Meter'!AJ36<0,"0",'Water-Meter'!AJ36) -> 37 | W32: ='Water-Meter'!AN36 -> 151 | X32: =Total!K32 -> 12

Sheet Energy Graph
A1: Date | B1: Usage KW | C1: Occ % | D1: Total Occ | E1: Guest Occ
A2: =Gen!B11 -> 44562 | B2: ='Summery Report'!F5 -> 4734 | C2: ='Summery Report'!C5 -> 0.4156 | D2: 34 | E2: =D2 -> 34
A3: =Gen!B12 -> 44563 | B3: ='Summery Report'!F6 -> 4563 | C3: ='Summery Report'!C6 -> 0.53 | D3: 42 | E3: =D3 -> 42
A4: =Gen!B13 -> 44564 | B4: ='Summery Report'!F7 -> 4574 | C4: ='Summery Report'!C7 -> 0.36 | D4: 29 | E4: =D4 -> 29
A5: =Gen!B14 -> 44565 | B5: ='Summery Report'!F8 -> 4346 | C5: ='Summery Report'!C8 -> 0.35 | D5: 28 | E5: =D5 -> 28
A6: =Gen!B15 -> 44566 | B6: ='Summery Report'!F9 -> 3969 | C6: ='Summery Report'!C9 -> 0.26 | D6: 21 | E6: =D6 -> 21
A7: =Gen!B16 -> 44567 | B7: ='Summery Report'!F10 -> 4325 | C7: ='Summery Report'!C10 -> 0.31 | D7: 25 | E7: =D7 -> 25
A8: =Gen!B17 -> 44568 | B8: ='Summery Report'!F11 -> 4444 | C8: ='Summery Report'!C11 -> 0.2468 | D8: 20 | E8: =D8 -> 20
A9: =Gen!B18 -> 44569 | B9: ='Summery Report'!F12 -> 4291 | C9: ='Summery Report'!C12 -> 0.23 | D9: 19 | E9: =D9 -> 19
A10: =Gen!B19 -> 44570 | B10: ='Summery Report'!F13 -> 4336 | C10: ='Summery Report'!C13 -> 0.2078 | D10: 17 | E10: =D10 -> 17
A11: =Gen!B20 -> 44571 | B11: ='Summery Report'!F14 -> 4279 | C11: ='Summery Report'!C14 -> 0.17 | D11: 16 | E11: =D11 -> 16
A12: =Gen!B21 -> 44572 | B12: ='Summery Report'!F15 -> 3862 | C12: ='Summery Report'!C15 -> 0.1 | D12: 11 | E12: =D12 -> 11
A13: =Gen!B22 -> 44573 | B13: ='Summery Report'!F16 -> 3803 | C13: ='Summery Report'!C16 -> 0.0649 | D13: 8 | E13: =D13 -> 8
... A32: =Gen!B41 -> 44592 | B32: ='Summery Report'!F35 -> 3272 | C32: ='Summery Report'!C35 -> 0.05 | D32: 5 | E32: =D32 -> 5
A33: =Gen!B42 -> 0 | B33: 0

Sheet UTILITY REPORT 1
A1: UTILITY REPORT
A2: Date | B2: % | C2: Guest Rooms Occupied | D2: Diesel cost Per Liter ($) | E2: Diesel consumption (LT) | F2: Power production (KW) | G2: Water consumption (M3) | H2: RO prodution (M3) | I2: Transport Consupmtion (LT)
A3: =Gen!B11 -> 44562 | B3: =Gen!C11 -> 0.4156 | C3: ='Energy Graph'!E2 -> 34 | D3: 1 | E3: =Gen!T11 -> 1965.3 | F3: =Gen!U11 -> 4734 | G3: ='Water-Meter'!E6 -> 116 | H3: ='Utility report '!AC6 -> 102 | I3: =Gen!AK11 -> 320.11
A4: =Gen!B12 -> 44563 | B4: =Gen!C12 -> 0.53 | C4: ='Energy Graph'!E3 -> 42 | D4: 1 | E4: =Gen!T12 -> 1927.08 | F4: =Gen!U12 -> 4563 | G4: ='Water-Meter'!E7 -> 94 | H4: ='Utility report '!AC7 -> 64 | I4: =Gen!AK12 -> 237.31
A5: =Gen!B13 -> 44564 | B5: =Gen!C13 -> 0.36 | C5: ='Energy Graph'!E4 -> 29 | D5: 1 | E5: =Gen!T13 -> 1859.92 | F5: =Gen!U13 -> 4574 | G5: ='Water-Meter'!E8 -> 110 | H5: ='Utility report '!AC8 -> 105 | I5: =Gen!AK13 -> 231
A6: =Gen!B14 -> 44565 | B6: =Gen!C14 -> 0.35 | C6: ='Energy Graph'!E5 -> 28 | D6: 1 | E6: =Gen!T14 -> 1889.7 | F6: =Gen!U14 -> 4346 | G6: ='Water-Meter'!E9 -> 94 | H6: ='Utility report '!AC9 -> 147 | I6: =Gen!AK14 -> 247.48
A7: =Gen!B15 -> 44566 | B7: =Gen!C15 -> 0.26 | C7: ='Energy Graph'!E6 -> 21 | D7: 1 | E7: =Gen!T15 -> 1716.39 | F7: =Gen!U15 -> 3969 | G7: ='Water-Meter'!E10 -> 86 | H7: ='Utility report '!AC10 -> 0 | I7: =Gen!AK15 -> 110
A8: =Gen!B16 -> 44567 | B8: =Gen!C16 -> 0.31 | C8: ='Energy Graph'!E7 -> 25 | D8: 1 | E8: =Gen!T16 -> 1829.15 | F8: =Gen!U16 -> 4325 | G8: ='Water-Meter'!E11 -> 90 | H8: ='Utility report '!AC11 -> 148 | I8: =Gen!AK16 -> 299.04
A9: =Gen!B17 -> 44568 | B9: =Gen!C17 -> 0.2468 | C9: ='Energy Graph'!E8 -> 20 | D9: 1 | E9: =Gen!T17 -> 1866.35 | F9: =Gen!U17 -> 4444 | G9: ='Water-Meter'!E12 -> 92 | H9: ='Utility report '!AC12 -> -22473 | I9: =Gen!AK17 -> 133
A10: =Gen!B18 -> 44569 | B10: =Gen!C18 -> 0.23 | C10: ='Energy Graph'!E9 -> 19 | D10: 1 | E10: =Gen!T18 -> 1767.24 | F10: =Gen!U18 -> 4291 | G10: ='Water-Meter'!E13 -> 108 | H10: ='Utility report '!AC13 -> 22575 | I10: =Gen!AK18 -> 162.47
A11: =Gen!B19 -> 44570 | B11: =Gen!C19 -> 0.2078 | C11: ='Energy Graph'!E10 -> 17 | D11: 1 | E11: =Gen!T19 -> 1846.05 | F11: =Gen!U19 -> 4336 | G11: ='Water-Meter'!E14 -> 101 | H11: ='Utility report '!AC14 -> 128 | I11: =Gen!AK19 -> 109.74
A12: =Gen!B20 -> 44571 | B12: =Gen!C20 -> 0.17 | C12: ='Energy Graph'!E11 -> 16 | D12: 1 | E12: =Gen!T20 -> 1765.63 | F12: =Gen!U20 -> 4279 | G12: ='Water-Meter'!E15 -> 83 | H12: ='Utility report '!AC15 -> 77 | I12: =Gen!AK20 -> 79.83
A13: =Gen!B21 -> 44572 | B13: =Gen!C21 -> 0.1 | C13: ='Energy Graph'!E12 -> 11 | D13: 1 | E13: =Gen!T21 -> 1625.28 | F13: =Gen!U21 -> 3862 | G13: ='Water-Meter'!E16 -> 67 | H13: ='Utility report '!AC16 -> 114 | I13: =Gen!AK21 -> 386.46
A14: =Gen!B22 -> 44573 | B14: =Gen!C22 -> 0.0649 | C14: ='Energy Graph'!E13 -> 8 | D14: 1 | E14: =Gen!T22 -> 1599.77 | F14: =Gen!U22 -> 3803 | G14: ='Water-Meter'!E17 -> 133 | H14: ='Utility report '!AC17 -> 112 | I14: =Gen!AK22 -> 0
... A33: =Gen!B41 -> 44592 | B33: =Gen!C41 -> 0.05 | C33: ='Energy Graph'!E32 -> 5 | D33: 1 | E33: =Gen!T41 -> 1283.56 | F33: =Gen!U41 -> 3272 | G33: ='Water-Meter'!E36 -> 104 | H33: ='Utility report '!AC36 -> 135 | I33: =Gen!AK41 -> 511.7
B34: =Gen!C42 -> 0 | C34: ='Energy Graph'!E33 -> 0

Sheet Utility report 
A1: =A6 -> 44562
A2: Date | B2: Total occupancy | H2: Diesel balance LTS | I2: Diesel Deliveries | J2: Gen.Diesel consumption LTS | L2: Total Diesel consumption LTS | M2: Water Meter reading | N2: Water consumption m³ | O2: R.O WATER PRODUCTION LTRS + TIME | AA2: Total RO production | AB2: RO Meter reading | AD2: 0 | AE2: STP | AF2: GAS TANK A | AG2: GAS TANK B | AH2: GAS TANK C | AI2: Total Gas Tanks | AJ2: Kg /day | AK2: TOTAL GAS cons.
A3: Rate Tsh /$ | B3: 1640 | C3: Diesel cost / lits | D3: 2175 | F3: =SUM(D3/B3) -> 1.3262195 | H3: =Gen!D11 -> 39200.63 | K3: Transport consumption | M3: Balance | O3: PLANT NO 1 | S3: PLANT NO 2 | W3: PLANT NO 3 | AA3: /day | AB3: Balance | AD3: 0 | AE3: Production | AF3: Capacity | AG3: Capacity | AH3: Capacity | AI3: Kg | AJ3: /day | AK3: /day
B4: Rooms OCC | C4: % | D4: Guest Rooms Occ | F4: Electricity Production Cost /Room Occ by guest | G4: All Cost /Room Occ by guest | O4: Flow M3 | P4: Reading Hours Meter | Q4: Hrs | R4: total production M3 | S4: Flow M3 | T4: Reading Hours Meter | U4: Hrs | V4: total production M3 | W4: Flow M3 | X4: READING HOURS METER | Y4: Hrs | Z4: total production M3 | AA4: M3 | AC4: M3 | AE4: M3 | AF4: 2000 | AG4: 1000 | AH4: 1000 | AI4: #VALUE! | AJ4: Kg | AK4: M3
T5: 20528 | AB5: 21907 | AD5: 228878 | AF5: 0.85 | AG5: 0.85 | AH5: 0.85
A6: =Gen!B11 -> 44562 | B6: ='UTILITY REPORT 1'!C3 -> 34 | D6: =B6 -> 34 | E6: =SUM(F3) -> 1.3262195 | F6: =SUM(J6*E6)/D6 -> 184.65656 | G6: =SUM(L6*E6)/D6 -> 184.65656 | H6: =Gen!D11 -> 39200.63 | I6: =Gen!F11 -> 0 | J6: =Gen!U11 -> 4734 | K6: =Gen!AL11 -> 0 | L6: =SUM(J6:K6) -> 4734 | M6: ='Water-Meter'!K46 -> 452.068 | N6: ='Water-Meter'!E6 -> 116 | P6: 19044 | Q6: =SUM(P6-P5) -> 19044 | R6: =SUM(Q6*O6) -> 0 | S6: 6.7 | T6: 20544 | U6: =T6-T5 -> 16 | V6: =SUM(U6*S7) -> 107.2 | X6: 29498 | Y6: =X6-X5 -> 29498 | Z6: =Y6-Y5 -> 29498 | AA6: =Z6-Z5 -> 29498 | AB6: 22009 | AC6: =AB6-AB5 -> 102 | AD6: 228934 | AE6: =AD6-AD5 -> 56 | AF6: ='Lpg (2)'!B10*2000/85 -> 1176.4706 | AG6: ='Lpg (2)'!C10*1000/85 -> 0 | AH6: ='Lpg (2)'!D10*1000/85 -> 0 | AI6: =SUM(AF6*2000)+(AG6*1000)+(AH6*1000) -> 2352941.2 | AJ6: =SUM(AI5-AI6) -> -2352941.2
A7: =Gen!B12 -> 44563 | B7: ='UTILITY REPORT 1'!C4 -> 42 | D7: =B7 -> 42 | E7: =SUM(E6) -> 1.3262195 | F7: =SUM(J7*E7)/D7 -> 144.08428 | G7: =SUM(L7*E7)/D7 -> 144.08428 | H7: =Gen!D12 -> 36915.22 | I7: =Gen!F12 -> 0 | J7: =Gen!U12 -> 4563 | K7: =Gen!AL12 -> 0 | L7: =SUM(J7:K7) -> 4563 | M7: ='Water-Meter'!K47 -> 449.21462 | N7: ='Water-Meter'!E7 -> 94 | P7: 19044 | Q7: =SUM(P7-P6) -> 0 | R7: =SUM(Q7*O7) -> 0 | S7: 6.7 | T7: 20544 | U7: =T7-T6 -> 0 | V7: =SUM(U7*S8) -> 0 | X7: 29498 | Y7: =X7-X6 -> 0 | Z7: =Y7-Y6 -> -29498 | AA7: =Z7-Z6 -> -58996 | AB7: 22073 | AC7: =AB7-AB6 -> 64 | AD7: 228989 | AE7: =AD7-AD6 -> 55 | AF7: ='Lpg (2)'!B11*2000/85 -> 1058.8235 | AG7: ='Lpg (2)'!C11*1000/85 -> 0 | AH7: ='Lpg (2)'!D11*1000/85 -> 0 | AI7: =SUM(AF6*2000)+(AG7*1000)+(AH7*1000) -> 2352941.2 | AJ7: =SUM(AI6-AI7) -> 0
A8: =Gen!B13 -> 44564 | B8: ='UTILITY REPORT 1'!C5 -> 29 | D8: =B8 -> 29 | E8: =SUM(E7) -> 1.3262195 | F8: =SUM(J8*E8)/D8 -> 209.17683 | G8: =SUM(L8*E8)/D8 -> 209.17683 | H8: =Gen!D13 -> 34750.83 | I8: =Gen!F13 -> 0 | J8: =Gen!U13 -> 4574 | K8: =Gen!AL13 -> 0 | L8: =SUM(J8:K8) -> 4574 | M8: ='Water-Meter'!K48 -> 474.25283 | N8: ='Water-Meter'!E8 -> 110 | P8: 19044 | Q8: =SUM(P8-P7) -> 0 | R8: =SUM(Q8*O8) -> 0 | S8: 6.7 | T8: 20554 | U8: =T8-T7 -> 10 | V8: =SUM(U8*S9) -> 68 | X8: 29498 | Y8: =X8-X7 -> 0 | Z8: =Y8-Y7 -> 0 | AA8: =Z8-Z7 -> 29498 | AB8: 22178 | AC8: =AB8-AB7 -> 105 | AD8: 229045 | AE8: =AD8-AD7 -> 56 | AF8: ='Lpg (2)'!B12*2000/85 -> 964.70588 | AG8: ='Lpg (2)'!C12*1000/85 -> 0 | AH8: ='Lpg (2)'!D12*1000/85 -> 0 | AI8: =SUM(AF7*2000)+(AG8*1000)+(AH8*1000) -> 2117647.1 | AJ8: =SUM(AI7-AI8) -> 235294.12
A9: =Gen!B14 -> 44565 | B9: ='UTILITY REPORT 1'!C6 -> 28 | D9: =B9 -> 28 | E9: =SUM(E8) -> 1.3262195 | F9: =SUM(J9*E9)/D9 -> 205.84821 | G9: =SUM(L9*E9)/D9 -> 205.84821 | H9: =Gen!D14 -> 32659.91 | I9: =Gen!F14 -> 0 | J9: =Gen!U14 -> 4346 | K9: =Gen!AL14 -> 0 | L9: =SUM(J9:K9) -> 4346 | M9: ='Water-Meter'!K49 -> 536.57201 | N9: ='Water-Meter'!E9 -> 94 | P9: 19044 | Q9: =SUM(P9-P7) -> 0 | R9: =SUM(Q9*O9) -> 0 | S9: 6.8 | T9: 20595 | U9: =T9-T8 -> 41 | V9: =SUM(U9*S10) -> 278.8 | X9: 29498 | Y9: =X9-X8 -> 0 | Z9: =Y9-Y8 -> 0 | AA9: =Z9-Z8 -> 0 | AB9: 22325 | AC9: =AB9-AB8 -> 147 | AD9: 229104 | AE9: =AD9-AD8 -> 59 | AF9: ='Lpg (2)'!B13*2000/85 -> 941.17647 | AG9: ='Lpg (2)'!C13*1000/85 -> 0 | AH9: ='Lpg (2)'!D13*1000/85 -> 0 | AI9: =SUM(AF8*2000)+(AG9*1000)+(AH9*1000) -> 1929411.8 | AJ9: =SUM(AI8-AI9) -> 188235.29
A10: =Gen!B15 -> 44566 | B10: ='UTILITY REPORT 1'!C7 -> 21 | D10: =B10 -> 21 | E10: =SUM(E9) -> 1.3262195 | F10: =SUM(J10*E10)/D10 -> 250.65549 | G10: =SUM(L10*E10)/D10 -> 250.65549 | H10: =Gen!D15 -> 30522.73 | I10: =Gen!F15 -> 0 | J10: =Gen!U15 -> 3969 | K10: =Gen!AL15 -> 0 | L10: =SUM(J10:K10) -> 3969 | M10: ='Water-Meter'!K50 -> 525.16541 | N10: ='Water-Meter'!E10 -> 86 | P10: 19044 | Q10: =SUM(P10-P9) -> 0 | R10: =SUM(Q10*O10) -> 0 | S10: 6.8 | T10: 20595 | U10: =T10-T9 -> 0 | V10: =SUM(U10*S11) -> 0 | X10: 29498 | Y10: =X10-X9 -> 0 | Z10: =SUM(Y10*W10) -> 0 | AA10: =Z10-Z9 -> 0 | AB10: 22325 | AC10: =AB10-AB9 -> 0 | AD10: 229153 | AE10: =AD10-AD9 -> 49 | AF10: ='Lpg (2)'!B14*2000/85 -> 894.11765 | AG10: ='Lpg (2)'!C14*1000/85 -> 0 | AH10: ='Lpg (2)'!D14*1000/85 -> 0 | AI10: =SUM(AF9*2000)+(AG10*1000)+(AH10*1000) -> 1882352.9 | AJ10: =SUM(AI9-AI10) -> 47058.824
A11: =Gen!B16 -> 44567 | B11: ='UTILITY REPORT 1'!C8 -> 25 | D11: =B11 -> 25 | E11: =SUM(E10) -> 1.3262195 | F11: =SUM(J11*E11)/D11 -> 229.43598 | G11: =SUM(L11*E11)/D11 -> 229.43598 | H11: =Gen!D16 -> 28696.34 | I11: =Gen!F16 -> 0 | J11: =Gen!U16 -> 4325 | K11: =Gen!AL16 -> 0 | L11: =SUM(J11:K11) -> 4325 | M11: ='Water-Meter'!K51 -> 534.09828 | N11: ='Water-Meter'!E11 -> 90 | P11: 19044 | Q11: =SUM(P11-P10) -> 0 | R11: =SUM(Q11*O11) -> 0 | S11: 6.8 | T11: 20618 | U11: =T11-T10 -> 23 | V11: =SUM(U11*S12) -> 156.4 | X11: 29498 | Y11: =X11-X10 -> 0 | Z11: =SUM(Y11*W11) -> 0 | AA11: =SUM(Z11*X13) -> 0 | AB11: 22473 | AC11: =AB11-AB10 -> 148 | AD11: 229207 | AE11: =AD11-AD10 -> 54 | AF11: ='Lpg (2)'!B15*2000/85 -> 1694.1176 | AG11: ='Lpg (2)'!C15*1000/85 -> 1000 | AH11: ='Lpg (2)'!D15*1000/85 -> 1000 | AI11: =SUM(AF10*2000)+(AG11*1000)+(AH11*1000) -> 3788235.3 | AJ11: =SUM(AI10-AI11) -> -1905882.4
A12: =Gen!B17 -> 44568 | B12: ='UTILITY REPORT 1'!C9 -> 20 | D12: =B12 -> 20 | E12: =SUM(E11) -> 1.3262195 | F12: =SUM(J12*E12)/D12 -> 294.68598 | G12: =SUM(L12*E12)/D12 -> 294.68598 | H12: =Gen!D17 -> 26568.15 | I12: =Gen!F17 -> 18000 | J12: =Gen!U17 -> 4444 | K12: =Gen!AL17 -> 0 | L12: =SUM(J12:K12) -> 4444 | M12: ='Water-Meter'!K52 -> 568.9489 | N12: ='Water-Meter'!E12 -> 92 | P12: 19044 | Q12: =SUM(P12-P11) -> 0 | R12: =SUM(Q12*O12) -> 0 | S12: 6.8 | T12: 20634 | U12: =T12-T11 -> 16 | V12: =SUM(U12*S12) -> 108.8 | X12: 29498 | Y12: =X12-X11 -> 0 | Z12: =SUM(Y12*W12) -> 0 | AA12: =SUM(Z12*X14) -> 0 | AC12: =AB12-AB11 -> -22473 | AE12: =AD12-AD11 -> -229207 | AF12: ='Lpg (2)'!B16*2000/85 -> 1647.0588 | AG12: ='Lpg (2)'!C16*1000/85 -> 1000 | AH12: ='Lpg (2)'!D16*1000/85 -> 1000 | AI12: =SUM(AF11*2000)+(AG12*1000)+(AH12*1000) -> 5388235.3 | AJ12: =SUM(AI11-AI12) -> -1600000
A13: =Gen!B18 -> 44569 | B13: ='UTILITY REPORT 1'!C10 -> 19 | D13: =B13 -> 19 | E13: =SUM(E12) -> 1.3262195 | F13: =SUM(J13*E13)/D13 -> 299.51621 | G13: =SUM(L13*E13)/D13 -> 299.51621 | H13: =Gen!D18 -> 24568.8 | I13: =Gen!F18 -> 0 | J13: =Gen!U18 -> 4291 | K13: =Gen!AL18 -> 0 | L13: =SUM(J13:K13) -> 4291 | M13: ='Water-Meter'!K53 -> 571.96529 | N13: ='Water-Meter'!E13 -> 108 | P13: 19044 | Q13: =SUM(P13-P12) -> 0 | R13: =SUM(Q13*O13) -> 0 | S13: 6.8 | T13: 20634 | U13: =T13-T12 -> 0 | V13: =SUM(U13*S13) -> 0 | X13: 29498 | Y13: =X13-X12 -> 0 | Z13: =SUM(Y13*W13) -> 0 | AA13: =SUM(Z13*X15) -> 0 | AB13: 22575 | AC13: =AB13-AB12 -> 22575 | AD13: 229265 | AE13: =AD13-AD12 -> 229265 | AF13: ='Lpg (2)'!B17*2000/85 -> 1647.0588 | AG13: ='Lpg (2)'!C17*1000/85 -> 1000 | AH13: ='Lpg (2)'!D17*1000/85 -> 1000 | AI13: =SUM(AF12*2000)+(AG13*1000)+(AH13*1000) -> 5294117.6 | AJ13: =SUM(AI12-AI13) -> 94117.647
A14: =Gen!B19 -> 44570 | B14: ='UTILITY REPORT 1'!C11 -> 17 | D14: =B14 -> 17 | E14: =SUM(E13) -> 1.3262195 | F14: =SUM(J14*E14)/D14 -> 338.26399 | G14: =SUM(L14*E14)/D14 -> 338.26399 | H14: =Gen!D19 -> 40639.09 | I14: =Gen!F19 -> 0 | J14: =Gen!U19 -> 4336 | K14: =Gen!AL19 -> 0 | L14: =SUM(J14:K14) -> 4336 | M14: ='Water-Meter'!K54 -> 575.97264 | N14: ='Water-Meter'!E14 -> 101 | P14: 19044 | Q14: =SUM(P14-P13) -> 0 | R14: =SUM(Q14*O14) -> 0 | S14: 6.8 | T14: 20655 | U14: =T14-T13 -> 21 | V14: =SUM(U14*S14) -> 142.8 | X14: 29498 | Y14: =X14-X13 -> 0 | Z14: =SUM(Y14*W14) -> 0 | AA14: =SUM(Z14*X16) -> 0 | AB14: 22703 | AC14: =AB14-AB13 -> 128 | AD14: 229321 | AE14: =AD14-AD13 -> 56 | AF14: ='Lpg (2)'!B18*2000/85 -> 1529.4118 | AG14: ='Lpg (2)'!C18*1000/85 -> 1000 | AH14: ='Lpg (2)'!D18*1000/85 -> 1000 | AI14: =SUM(AF13*2000)+(AG14*1000)+(AH14*1000) -> 5294117.6 | AJ14: =SUM(AI13-AI14) -> 0
A15: =Gen!B20 -> 44571 | B15: ='UTILITY REPORT 1'!C12 -> 16 | D15: =B15 -> 16 | E15: =SUM(E14) -> 1.3262195 | F15: =SUM(J15*E15)/D15 -> 354.68083 | G15: =SUM(L15*E15)/D15 -> 354.68083 | H15: =Gen!D20 -> 38683.3 | I15: =Gen!F20 -> 0 | J15: =Gen!U20 -> 4279 | K15: =Gen!AL20 -> 0 | L15: =SUM(J15:K15) -> 4279 | M15: ='Water-Meter'!K55 -> 615.62824 | N15: ='Water-Meter'!E15 -> 83 | P15: 19044 | Q15: =SUM(P15-P14) -> 0 | R15: =SUM(Q15*O15) -> 0 | S15: 6.8 | T15: 20667 | U15: =T15-T14 -> 12 | V15: =SUM(U15*S15) -> 81.6 | X15: 29498 | Y15: =X15-X14 -> 0 | Z15: =SUM(Y15*W15) -> 0 | AA15: =SUM(Z15*X17) -> 0 | AB15: 22780 | AC15: =AB15-AB14 -> 77 | AD15: 229324 | AE15: =AD15-AD14 -> 3 | AF15: ='Lpg (2)'!B19*2000/85 -> 1458.8235 | AG15: ='Lpg (2)'!C19*1000/85 -> 1000 | AH15: ='Lpg (2)'!D19*1000/85 -> 1000 | AI15: =SUM(AF15*2000)+(AG15*1000)+(AH15*1000) -> 4917647.1 | AJ15: =SUM(AI14-AI15) -> 376470.59
A16: =Gen!B21 -> 44572 | B16: ='UTILITY REPORT 1'!C13 -> 11 | D16: =B16 -> 11 | E16: =SUM(E15) -> 1.3262195 | F16: =SUM(J16*E16)/D16 -> 465.62361 | G16: =SUM(L16*E16)/D16 -> 465.62361 | H16: =Gen!D21 -> 36837.84 | I16: =Gen!F21 -> 0 | J16: =Gen!U21 -> 3862 | K16: =Gen!AL21 -> 0 | L16: =SUM(J16:K16) -> 3862 | M16: ='Water-Meter'!K56 -> 590.0892 | N16: ='Water-Meter'!E16 -> 67 | P16: 19044 | Q16: =SUM(P16-P15) -> 0 | R16: =SUM(Q16*O16) -> 0 | S16: 6.8 | T16: 20685 | U16: =T16-T15 -> 18 | V16: =SUM(U16*S16) -> 122.4 | X16: 29498 | Y16: =X16-X15 -> 0 | Z16: =SUM(Y16*W16) -> 0 | AA16: =SUM(Z16*X18) -> 0 | AB16: 22894 | AC16: =AB16-AB15 -> 114 | AD16: 229327 | AE16: =AD16-AD15 -> 3 | AF16: ='Lpg (2)'!B20*2000/85 -> 1411.7647 | AG16: ='Lpg (2)'!C20*1000/85 -> 682.35294 | AH16: ='Lpg (2)'!D20*1000/85 -> 1000 | AI16: =SUM(AF16*2000)+(AG16*1000)+(AH16*1000) -> 4505882.4 | AJ16: =SUM(AI15-AI16) -> 411764.71
A17: =Gen!B22 -> 44573 | B17: ='UTILITY REPORT 1'!C14 -> 8 | D17: =B17 -> 8 | E17: =SUM(E16) -> 1.3262195 | F17: =SUM(J17*E17)/D17 -> 630.4516 | G17: =SUM(L17*E17)/D17 -> 630.4516 | H17: =Gen!D22 -> 34826.1 | I17: =Gen!F22 -> 0 | J17: =Gen!U22 -> 3803 | K17: =Gen!AL22 -> 0 | L17: =SUM(J17:K17) -> 3803 | M17: ='Water-Meter'!K57 -> 581.09751 | N17: ='Water-Meter'!E17 -> 133 | P17: 19044 | Q17: =SUM(P17-P16) -> 0 | R17: =SUM(Q17*O17) -> 0 | S17: 6.8 | T17: 20702 | U17: =T17-T16 -> 17 | V17: =SUM(U17*S17) -> 115.6 | X17: 29498 | Y17: =X17-X16 -> 0 | Z17: =SUM(Y17*W17) -> 0 | AA17: =SUM(Z17*X19) -> 0 | AB17: 23006 | AC17: =AB17-AB16 -> 112 | AD17: 229327 | AE17: =AD17-AD16 -> 0 | AF17: ='Lpg (2)'!B21*2000/85 -> 1364.7059 | AG17: ='Lpg (2)'!C21*1000/85 -> 1000 | AH17: ='Lpg (2)'!D21*1000/85 -> 1000 | AI17: =SUM(AF17*2000)+(AG17*1000)+(AH17*1000) -> 4729411.8 | AJ17: =SUM(AI16-AI17) -> -223529.41
A18: =Gen!B23 -> 44574 | B18: ='UTILITY REPORT 1'!C15 -> 13 | D18: =B18 -> 13 | E18: =SUM(E17) -> 1.3262195 | F18: =SUM(J18*E18)/D18 -> 372.1576 | G18: =SUM(L18*E18)/D18 -> 372.1576 | H18: =Gen!D23 -> 33226.33 | I18: =Gen!F23 -> 0 | J18: =Gen!U23 -> 3648 | K18: =Gen!AL23 -> 0 | L18: =SUM(J18:K18) -> 3648 | M18: ='Water-Meter'!K58 -> 590.0892 | N18: ='Water-Meter'!E18 -> 86 | P18: 19044 | Q18: =SUM(P18-P17) -> 0 | R18: =SUM(Q18*O18) -> 0 | S18: 6.8 | T18: 20720 | U18: =T18-T17 -> 18 | V18: =SUM(U18*S18) -> 122.4 | X18: 29498 | Y18: =X18-X17 -> 0 | Z18: =SUM(Y18*W18) -> 0 | AA18: =SUM(Z18*X20) -> 0 | AB18: 23117 | AC18: =AB18-AB17 -> 111 | AD18: 229327 | AE18: =AD18-AD17 -> 0 | AF18: ='Lpg (2)'!B22*2000/85 -> 1294.1176 | AG18: ='Lpg (2)'!C22*1000/85 -> 1000 | AH18: ='Lpg (2)'!D22*1000/85 -> 1000 | AI18: =SUM(AF18*2000)+(AG18*1000)+(AH18*1000) -> 4588235.3 | AJ18: =SUM(AI17-AI18) -> 141176.47
A19: =Gen!B24 -> 44575 | B19: ='UTILITY REPORT 1'!C16 -> 17 | D19: =B19 -> 17 | E19: =SUM(E18) -> 1.3262195 | F19: =SUM(J19*E19)/D19 -> 296.059 | G19: =SUM(L19*E19)/D19 -> 296.059 | H19: =Gen!D24 -> 31652.73 | I19: =Gen!F24 -> 0 | J19: =Gen!U24 -> 3795 | K19: =Gen!AL24 -> 0 | L19: =SUM(J19:K19) -> 3795 | M19: ='Water-Meter'!K59 -> 594.5225 | N19: ='Water-Meter'!E19 -> 92 | P19: 19044 | Q19: =SUM(P19-P18) -> 0 | R19: =SUM(Q19*O19) -> 0 | S19: 6.8 | T19: 20734 | U19: =T19-T18 -> 14 | V19: =SUM(U19*S19) -> 95.2 | X19: 29498 | Y19: =X19-X18 -> 0 | Z19: =SUM(Y19*W19) -> 0 | AA19: =SUM(Z19*X21) -> 0 | AB19: 23209 | AC19: =AB19-AB18 -> 92 | AD19: 229370 | AE19: =AD19-AD18 -> 43 | AF19: ='Lpg (2)'!B23*2000/85 -> 1223.5294 | AG19: ='Lpg (2)'!C23*1000/85 -> 1000 | AH19: ='Lpg (2)'!D23*1000/85 -> 1000 | AI19: =SUM(AF19*2000)+(AG19*1000)+(AH19*1000) -> 4447058.8 | AJ19: =SUM(AI18-AI19) -> 141176.47
A20: =Gen!B25 -> 44576 | B20: ='UTILITY REPORT 1'!C17 -> 15 | D20: =B20 -> 15 | E20: =SUM(E19) -> 1.3262195 | F20: =SUM(J20*E20)/D20 -> 322.53659 | G20: =SUM(L20*E20)/D20 -> 322.53659 | H20: =Gen!D25 -> 29852.73 | I20: =Gen!F25 -> 0 | J20: =Gen!U25 -> 3648 | K20: =Gen!AL25 -> 0 | L20: =SUM(J20:K20) -> 3648 | M20: ='Water-Meter'!K60 -> 566.29314 | N20: ='Water-Meter'!E20 -> 102 | P20: 19044 | Q20: =SUM(P20-P18) -> 0 | R20: =SUM(Q20*O20) -> 0 | S20: 6.8 | T20: 20743 | U20: =T20-T19 -> 9 | V20: =SUM(U20*S20) -> 61.2 | X20: 29498 | Y20: =X20-X19 -> 0 | Z20: =SUM(Y20*W20) -> 0 | AA20: =SUM(Z20*X22) -> 0 | AB20: 23267 | AC20: =AB20-AB19 -> 58 | AD20: 229396 | AE20: =AD20-AD19 -> 26 | AF20: ='Lpg (2)'!B24*2000/85 -> 1176.4706 | AG20: ='Lpg (2)'!C24*1000/85 -> 1000 | AH20: ='Lpg (2)'!D24*1000/85 -> 1000 | AI20: =SUM(AF20*2000)+(AG20*1000)+(AH20*1000) -> 4352941.2 | AJ20: =SUM(AI19-AI20) -> 94117.647
A21: =Gen!B26 -> 44577 | B21: ='UTILITY REPORT 1'!C18 -> 17 | D21: =B21 -> 17 | E21: =SUM(E20) -> 1.3262195 | F21: =SUM(J21*E21)/D21 -> 264.69781 | G21: =SUM(L21*E21)/D21 -> 264.69781 | H21: =Gen!D26 -> 28410.73 | I21: =Gen!F26 -> 0 | J21: =Gen!U26 -> 3393 | K21: =Gen!AL26 -> 0 | L21: =SUM(J21:K21) -> 3393 | M21: ='Water-Meter'!K61 -> 550.85724 | N21: ='Water-Meter'!E21 -> 74 | P21: 19044 | Q21: =SUM(P21-P20) -> 0 | R21: =SUM(Q21*O21) -> 0 | S21: 6.8 | T21: 20758 | U21: =T21-T20 -> 15 | V21: =SUM(U21*S21) -> 102 | X21: 29498 | Y21: =X21-X20 -> 0 | Z21: =SUM(Y21*W21) -> 0 | AA21: =SUM(Z21*X23) -> 0 | AB21: 23358 | AC21: =AB21-AB20 -> 91 | AD21: 229459 | AE21: =AD21-AD20 -> 63 | AF21: ='Lpg (2)'!B25*2000/85 -> 1105.8824 | AG21: ='Lpg (2)'!C25*1000/85 -> 1000 | AH21: ='Lpg (2)'!D25*1000/85 -> 1000 | AI21: =SUM(AF21*2000)+(AG21*1000)+(AH21*1000) -> 4211764.7 | AJ21: =SUM(AI20-AI21) -> 141176.47
A22: =Gen!B27 -> 44578 | B22: ='UTILITY REPORT 1'!C19 -> 10 | D22: =B22 -> 10 | E22: =SUM(E21) -> 1.3262195 | F22: =SUM(J22*E22)/D22 -> 394.81555 | G22: =SUM(L22*E22)/D22 -> 394.81555 | H22: =Gen!D27 -> 26609.35 | I22: =Gen!F27 -> 18000 | J22: =Gen!U27 -> 2977 | K22: =Gen!AL27 -> 0 | L22: =SUM(J22:K22) -> 2977 | M22: ='Water-Meter'!K62 -> 575.40819 | N22: ='Water-Meter'!E22 -> 68 | P22: 19044 | Q22: =SUM(P22-P21) -> 0 | R22: =SUM(Q22*O22) -> 0 | S22: 6.8 | T22: 20771 | U22: =T22-T21 -> 13 | V22: =SUM(U22*S22) -> 88.4 | X22: 29498 | Y22: =X22-X21 -> 0 | Z22: =SUM(Y22*W22) -> 0 | AA22: =SUM(Z22*X24) -> 0 | AB22: 23436 | AC22: =AB22-AB21 -> 78 | AD22: 229495 | AE22: =AD22-AD21 -> 36 | AF22: ='Lpg (2)'!B26*2000/85 -> 1035.2941 | AG22: ='Lpg (2)'!C26*1000/85 -> 1000 | AH22: ='Lpg (2)'!D26*1000/85 -> 1000 | AI22: =SUM(AF22*2000)+(AG22*1000)+(AH22*1000) -> 4070588.2 | AJ22: =SUM(AI21-AI22) -> 141176.47
