Workbook

Sheet TOTAL
A1: Site Name | B1: Day | C1: Month | D1: Year | E1: Total Electricity Kwh | F1: Electricity Tariff ($/Kwh) | G1: Natual Gas (m3) | H1: Natural Gas $/m3 | I1: Water Utility Supply (m3) m3 | J1: Water Utility Supply (m3) $/m3 | K1: Room Nights
A2: Orlando | B2: 31 | C2: 1 | D2: 2018 | E2: =Submetering!F2+Submetering!H2+Submetering!J2+Submetering!L2+Submetering!N2+Submetering!P2+Submetering!R2+Submetering!T2+Submetering!V2+Submetering!X2+Submetering!Z2+Submetering!AB2+Submetering!AC2+Submetering!AD2+Submetering!AE2 -> 1249823 | F2: =((((Submetering!E2+Submetering!AD2)*0.13773+(Submetering!E2+Submetering!AD2)*0.02095)*1.09+(2.85/30)*2)+(((Submetering!F2+Submetering!H2+Submetering!J2+Submetering!L2+Submetering!N2+Submetering!P2+Submetering!R2+Submetering!T2+Submetering!V2+Submetering!X2+Submetering!Z2+Submetering!AB2+Submetering!AC2+Submetering!AE2)*0.05155)+((Submetering!F2+Submetering!H2+Submetering!J2+Submetering!L2+Submetering!N2+Submetering!P2+Submetering!R2+Submetering!T2+Submetering!V2+Submetering!X2+Submetering!Z2+Submetering!AB2+Submetering!AC2+Submetering!AE2)*0.02095)+(20/30)*15)*1.1048)/E2 -> 0.080817384 | G2: =Submetering!AK2+Submetering!AL2+Submetering!AU2 -> 40649.653 | H2: 0.8166 | I2: =Submetering!AF2+Submetering!AG2+Submetering!AV2+Submetering!AY2+Submetering!AZ2 -> 21136.527 | J2: =((Submetering!AG2+Submetering!BA2)*0.8868+(1712.96+1070.52)/30+(Submetering!AF2+Submetering!AY2+Submetering!AV2+Submetering!AZ2)*1.1251+(2076.11+129.67+207.57+207.57)/30+(11680.53+56.61)/30)/I2 -> 1.1368635 | K2: =Occupancy!H4 -> 10446.876
A3: Orlando | B3: 28 | C3: 2 | D3: 2018 | E3: =Submetering!F3+Submetering!H3+Submetering!J3+Submetering!L3+Submetering!N3+Submetering!P3+Submetering!R3+Submetering!T3+Submetering!V3+Submetering!X3+Submetering!Z3+Submetering!AB3+Submetering!AC3+Submetering!AD3+Submetering!AE3 -> 1263709 | F3: =((((Submetering!E3+Submetering!AD3)*0.13773+(Submetering!E3+Submetering!AD3)*0.02095)*1.09+(2.85/30)*2)+(((Submetering!F3+Submetering!H3+Submetering!J3+Submetering!L3+Submetering!N3+Submetering!P3+Submetering!R3+Submetering!T3+Submetering!V3+Submetering!X3+Submetering!Z3+Submetering!AB3+Submetering!AC3+Submetering!AE3)*0.05155)+((Submetering!F3+Submetering!H3+Submetering!J3+Submetering!L3+Submetering!N3+Submetering!P3+Submetering!R3+Submetering!T3+Submetering!V3+Submetering!X3+Submetering!Z3+Submetering!AB3+Submetering!AC3+Submetering!AE3)*0.02095)+(20/30)*15)*1.1048)/E3 -> 0.080714784 | G3: =Submetering!AK3+Submetering!AL3+Submetering!AU3 -> 20461.415 | H3: 0.8166 | I3: =Submetering!AF3+Submetering!AG3+Submetering!AV3+Submetering!AY3+Submetering!AZ3 -> 20976.209 | J3: =((Submetering!AG3+Submetering!BA3)*0.8868+(1712.96+1070.52)/30+(Submetering!AF3+Submetering!AY3+Submetering!AV3+Submetering!AZ3)*1.1251+(2076.11+129.67+207.57+207.57)/30+(11680.53+56.61)/30)/I3 -> 1.2217889 | K3: =Occupancy!H5 -> 9721.824
A4: Orlando | B4: 31 | C4: 3 | D4: 2018 | E4: =Submetering!F4+Submetering!H4+Submetering!J4+Submetering!L4+Submetering!N4+Submetering!P4+Submetering!R4+Submetering!T4+Submetering!V4+Submetering!X4+Submetering!Z4+Submetering!AB4+Submetering!AC4+Submetering!AD4+Submetering!AE4 -> 1362044 | F4: =((((Submetering!E4+Submetering!AD4)*0.13773+(Submetering!E4+Submetering!AD4)*0.02095)*1.09+(2.85/30)*2)+(((Submetering!F4+Submetering!H4+Submetering!J4+Submetering!L4+Submetering!N4+Submetering!P4+Submetering!R4+Submetering!T4+Submetering!V4+Submetering!X4+Submetering!Z4+Submetering!AB4+Submetering!AC4+Submetering!AE4)*0.05155)+((Submetering!F4+Submetering!H4+Submetering!J4+Submetering!L4+Submetering!N4+Submetering!P4+Submetering!R4+Submetering!T4+Submetering!V4+Submetering!X4+Submetering!Z4+Submetering!AB4+Submetering!AC4+Submetering!AE4)*0.02095)+(20/30)*15)*1.1048)/E4 -> 0.080743323 | G4: =Submetering!AK4+Submetering!AL4+Submetering!AU4 -> 29630.059 | H4: 0.8166 | I4: =Submetering!AF4+Submetering!AG4+Submetering!AV4+Submetering!AY4+Submetering!AZ4 -> 28058.584 | J4: =((Submetering!AG4+Submetering!BA4)*0.8868+(1712.96+1070.52)/30+(Submetering!AF4+Submetering!AY4+Submetering!AV4+Submetering!AZ4)*1.1251+(2076.11+129.67+207.57+207.57)/30+(11680.53+56.61)/30)/I4 -> 1.3905453 | K4: =Occupancy!H6 -> 11781.984
A5: Orlando | B5: 31 | C5: 4 | D5: 2018 | E5: =Submetering!F5+Submetering!H5+Submetering!J5+Submetering!L5+Submetering!N5+Submetering!P5+Submetering!R5+Submetering!T5+Submetering!V5+Submetering!X5+Submetering!Z5+Submetering!AB5+Submetering!AC5+Submetering!AD5+Submetering!AE5 -> 1275720 | F5: =((((Submetering!E5+Submetering!AD5)*0.13773+(Submetering!E5+Submetering!AD5)*0.02095)*1.09+(2.85/30)*2)+(((Submetering!F5+Submetering!H5+Submetering!J5+Submetering!L5+Submetering!N5+Submetering!P5+Submetering!R5+Submetering!T5+Submetering!V5+Submetering!X5+Submetering!Z5+Submetering!AB5+Submetering!AC5+Submetering!AE5)*0.05155)+((Submetering!F5+Submetering!H5+Submetering!J5+Submetering!L5+Submetering!N5+Submetering!P5+Submetering!R5+Submetering!T5+Submetering!V5+Submetering!X5+Submetering!Z5+Submetering!AB5+Submetering!AC5+Submetering!AE5)*0.02095)+(20/30)*15)*1.1048)/E5 -> 0.080452536 | G5: =Submetering!AK5+Submetering!AL5+Submetering!AU5 -> 18215.38 | H5: 0.8166 | I5: =Submetering!AF5+Submetering!AG5+Submetering!AV5+Submetering!AY5+Submetering!AZ5 -> 26028.062 | J5: =((Submetering!AG5+Submetering!BA5)*0.8868+(1712.96+1070.52)/30+(Submetering!AF5+Submetering!AY5+Submetering!AV5+Submetering!AZ5)*1.1251+(2076.11+129.67+207.57+207.57)/30+(11680.53+56.61)/30)/I5 -> 1.2143969 | K5: =Occupancy!H7 -> 11148.84
A6: Orlando | B6: 31 | C6: 5 | D6: 2018 | E6: =Submetering!F6+Submetering!H6+Submetering!J6+Submetering!L6+Submetering!N6+Submetering!P6+Submetering!R6+Submetering!T6+Submetering!V6+Submetering!X6+Submetering!Z6+Submetering!AB6+Submetering!AC6+Submetering!AD6+Submetering!AE6 -> 1569920 | F6: =((((Submetering!E6+Submetering!AD6)*0.13773+(Submetering!E6+Submetering!AD6)*0.02095)*1.09+(2.85/30)*2)+(((Submetering!F6+Submetering!H6+Submetering!J6+Submetering!L6+Submetering!N6+Submetering!P6+Submetering!R6+Submetering!T6+Submetering!V6+Submetering!X6+Submetering!Z6+Submetering!AB6+Submetering!AC6+Submetering!AE6)*0.05155)+((Submetering!F6+Submetering!H6+Submetering!J6+Submetering!L6+Submetering!N6+Submetering!P6+Submetering!R6+Submetering!T6+Submetering!V6+Submetering!X6+Submetering!Z6+Submetering!AB6+Submetering!AC6+Submetering!AE6)*0.02095)+(20/30)*15)*1.1048)/E6 -> 0.080409674 | G6: =Submetering!AK6+Submetering!AL6+Submetering!AU6 -> 14477.384 | H6: 0.8166 | I6: =Submetering!AF6+Submetering!AG6+Submetering!AV6+Submetering!AY6+Submetering!AZ6 -> 26394.04 | J6: =((Submetering!AG6+Submetering!BA6)*0.8868+(1712.96+1070.52)/30+(Submetering!AF6+Submetering!AY6+Submetering!AV6+Submetering!AZ6)*1.1251+(2076.11+129.67+207.57+207.57)/30+(11680.53+56.61)/30)/I6 -> 1.2634591 | K6: =Occupancy!H8 -> 10446.876
A7: Orlando | B7: 30 | C7: 6 | D7: 2018 | E7: =Submetering!F7+Submetering!H7+Submetering!J7+Submetering!L7+Submetering!N7+Submetering!P7+Submetering!R7+Submetering!T7+Submetering!V7+Submetering!X7+Submetering!Z7+Submetering!AB7+Submetering!AC7+Submetering!AD7+Submetering!AE7 -> 1807824 | F7: =((((Submetering!E7+Submetering!AD7)*0.13773+(Submetering!E7+Submetering!AD7)*0.02095)*1.09+(2.85/30)*2)+(((Submetering!F7+Submetering!H7+Submetering!J7+Submetering!L7+Submetering!N7+Submetering!P7+Submetering!R7+Submetering!T7+Submetering!V7+Submetering!X7+Submetering!Z7+Submetering!AB7+Submetering!AC7+Submetering!AE7)*0.05155)+((Submetering!F7+Submetering!H7+Submetering!J7+Submetering!L7+Submetering!N7+Submetering!P7+Submetering!R7+Submetering!T7+Submetering!V7+Submetering!X7+Submetering!Z7+Submetering!AB7+Submetering!AC7+Submetering!AE7)*0.02095)+(20/30)*15)*1.1048)/E7 -> 0.084892021 | G7: =Submetering!AK7+Submetering!AL7+Submetering!AU7 -> 6695.79 | H7: 0.8166 | I7: =Submetering!AF7+Submetering!AG7+Submetering!AV7+Submetering!AY7+Submetering!AZ7 -> 24519.538 | J7: =((Submetering!AG7+Submetering!BA7)*0.8868+(1712.96+1070.52)/30+(Submetering!AF7+Submetering!AY7+Submetering!AV7+Submetering!AZ7)*1.1251+(2076.11+129.67+207.57+207.57)/30+(11680.53+56.61)/30)/I7 -> 1.2303144 | K7: =Occupancy!H9 -> 9923.4
A8: Orlando | B8: 31 | C8: 7 | D8: 2018 | E8: =Submetering!F8+Submetering!H8+Submetering!J8+Submetering!L8+Submetering!N8+Submetering!P8+Submetering!R8+Submetering!T8+Submetering!V8+Submetering!X8+Submetering!Z8+Submetering!AB8+Submetering!AC8+Submetering!AD8+Submetering!AE8 -> 1854374 | F8: =((((Submetering!E8+Submetering!AD8)*0.13773+(Submetering!E8+Submetering!AD8)*0.02095)*1.09+(2.85/30)*2)+(((Submetering!F8+Submetering!H8+Submetering!J8+Submetering!L8+Submetering!N8+Submetering!P8+Submetering!R8+Submetering!T8+Submetering!V8+Submetering!X8+Submetering!Z8+Submetering!AB8+Submetering!AC8+Submetering!AE8)*0.05155)+((Submetering!F8+Submetering!H8+Submetering!J8+Submetering!L8+Submetering!N8+Submetering!P8+Submetering!R8+Submetering!T8+Submetering!V8+Submetering!X8+Submetering!Z8+Submetering!AB8+Submetering!AC8+Submetering!AE8)*0.02095)+(20/30)*15)*1.1048)/E8 -> 0.084779606 | G8: =Submetering!AK8+Submetering!AL8+Submetering!AU8 -> 6965.9054 | H8: 0.8166 | I8: =Submetering!AF8+Submetering!AG8+Submetering!AV8+Submetering!AY8+Submetering!AZ8 -> 23937.302 | J8: =((Submetering!AG8+Submetering!BA8)*0.8868+(1712.96+1070.52)/30+(Submetering!AF8+Submetering!AY8+Submetering!AV8+Submetering!AZ8)*1.1251+(2076.11+129.67+207.57+207.57)/30+(11680.53+56.61)/30)/I8 -> 1.2029528 | K8: =Occupancy!H10 -> 9744.912
A9: Orlando | B9: 31 | C9: 8 | D9: 2018 | E9: =Submetering!F9+Submetering!H9+Submetering!J9+Submetering!L9+Submetering!N9+Submetering!P9+Submetering!R9+Submetering!T9+Submetering!V9+Submetering!X9+Submetering!Z9+Submetering!AB9+Submetering!AC9+Submetering!AD9+Submetering!AE9 -> 3227940 | F9: =((((Submetering!E9+Submetering!AD9)*0.13773+(Submetering!E9+Submetering!AD9)*0.02095)*1.09+(2.85/30)*2)+(((Submetering!F9+Submetering!H9+Submetering!J9+Submetering!L9+Submetering!N9+Submetering!P9+Submetering!R9+Submetering!T9+Submetering!V9+Submetering!X9+Submetering!Z9+Submetering!AB9+Submetering!AC9+Submetering!AE9)*0.05155)+((Submetering!F9+Submetering!H9+Submetering!J9+Submetering!L9+Submetering!N9+Submetering!P9+Submetering!R9+Submetering!T9+Submetering!V9+Submetering!X9+Submetering!Z9+Submetering!AB9+Submetering!AC9+Submetering!AE9)*0.02095)+(20/30)*15)*1.1048)/E9 -> 0.080376413 | G9: =Submetering!AK9+Submetering!AL9+Submetering!AU9 -> 8445.1428 | H9: 0.8166 | I9: =Submetering!AF9+Submetering!AG9+Submetering!AV9+Submetering!AY9+Submetering!AZ9 -> 13087.694 | J9: =((Submetering!AG9+Submetering!BA9)*0.8868+(1712.96+1070.52)/30+(Submetering!AF9+Submetering!AY9+Submetering!AV9+Submetering!AZ9)*1.1251+(2076.11+129.67+207.57+207.57)/30+(11680.53+56.61)/30)/I9 -> 1.1804275 | K9: =Occupancy!H11 -> 9882.552
A10: Orlando | B10: 30 | C10: 9 | D10: 2018 | E10: =Submetering!F10+Submetering!H10+Submetering!J10+Submetering!L10+Submetering!N10+Submetering!P10+Submetering!R10+Submetering!T10+Submetering!V10+Submetering!X10+Submetering!Z10+Submetering!AB10+Submetering!AC10+Submetering!AD10+Submetering!AE10 -> 346720 | F10: =((((Submetering!E10+Submetering!AD10)*0.13773+(Submetering!E10+Submetering!AD10)*0.02095)*1.09+(2.85/30)*2)+(((Submetering!F10+Submetering!H10+Submetering!J10+Submetering!L10+Submetering!N10+Submetering!P10+Submetering!R10+Submetering!T10+Submetering!V10+Submetering!X10+Submetering!Z10+Submetering!AB10+Submetering!AC10+Submetering!AE10)*0.05155)+((Submetering!F10+Submetering!H10+Submetering!J10+Submetering!L10+Submetering!N10+Submetering!P10+Submetering!R10+Submetering!T10+Submetering!V10+Submetering!X10+Submetering!Z10+Submetering!AB10+Submetering!AC10+Submetering!AE10)*0.02095)+(20/30)*15)*1.1048)/E10 -> 0.080432216 | G10: =Submetering!AK10+Submetering!AL10+Submetering!AU10 -> 1253.487 | H10: 0.8166 | I10: =Submetering!AF10+Submetering!AG10+Submetering!AV10+Submetering!AY10+Submetering!AZ10 -> 7083.9524 | J10: =((Submetering!AG10+Submetering!BA10)*0.8868+(1712.96+1070.52)/30+(Submetering!AF10+Submetering!AY10+Submetering!AV10+Submetering!AZ10)*1.1251+(2076.11+129.67+207.57+207.57)/30+(11680.53+56.61)/30)/I10 -> 1.4709521 | K10: =Occupancy!H12 -> 7858.8
A11: Orlando | B11: 31 | C11: 10 | D11: 2018 | E11: =Submetering!F11+Submetering!H11+Submetering!J11+Submetering!L11+Submetering!N11+Submetering!P11+Submetering!R11+Submetering!T11+Submetering!V11+Submetering!X11+Submetering!Z11+Submetering!AB11+Submetering!AC11+Submetering!AD11+Submetering!AE11 -> 1143320 | F11: =((((Submetering!E11+Submetering!AD11)*0.13773+(Submetering!E11+Submetering!AD11)*0.02095)*1.09+(2.85/30)*2)+(((Submetering!F11+Submetering!H11+Submetering!J11+Submetering!L11+Submetering!N11+Submetering!P11+Submetering!R11+Submetering!T11+Submetering!V11+Submetering!X11+Submetering!Z11+Submetering!AB11+Submetering!AC11+Submetering!AE11)*0.05155)+((Submetering!F11+Submetering!H11+Submetering!J11+Submetering!L11+Submetering!N11+Submetering!P11+Submetering!R11+Submetering!T11+Submetering!V11+Submetering!X11+Submetering!Z11+Submetering!AB11+Submetering!AC11+Submetering!AE11)*0.02095)+(20/30)*15)*1.1048)/E11 -> 0.08043777 | G11: =Submetering!AK11+Submetering!AL11+Submetering!AU11 -> 9816.464 | H11: 0.8166 | I11: =Submetering!AF11+Submetering!AG11+Submetering!AV11+Submetering!AY11+Submetering!AZ11 -> 19604.816 | J11: =((Submetering!AG11+Submetering!BA11)*0.8868+(1712.96+1070.52)/30+(Submetering!AF11+Submetering!AY11+Submetering!AV11+Submetering!AZ11)*1.1251+(2076.11+129.67+207.57+207.57)/30+(11680.53+56.61)/30)/I11 -> 1.3229947 | K11: =Occupancy!H13 -> 9676.092
A12: Orlando | B12: 4 | C12: 11 | D12: 2018 | E12: =Submetering!F12+Submetering!H12+Submetering!J12+Submetering!L12+Submetering!N12+Submetering!P12+Submetering!R12+Submetering!T12+Submetering!V12+Submetering!X12+Submetering!Z12+Submetering!AB12+Submetering!AC12+Submetering!AD12+Submetering!AE12 -> 159060 | F12: =((((Submetering!E12+Submetering!AD12)*0.13773+(Submetering!E12+Submetering!AD12)*0.02095)*1.09+(2.85/30)*2)+(((Submetering!F12+Submetering!H12+Submetering!J12+Submetering!L12+Submetering!N12+Submetering!P12+Submetering!R12+Submetering!T12+Submetering!V12+Submetering!X12+Submetering!Z12+Submetering!AB12+Submetering!AC12+Submetering!AE12)*0.05155)+((Submetering!F12+Submetering!H12+Submetering!J12+Submetering!L12+Submetering!N12+Submetering!P12+Submetering!R12+Submetering!T12+Submetering!V12+Submetering!X12+Submetering!Z12+Submetering!AB12+Submetering!AC12+Submetering!AE12)*0.02095)+(20/30)*15)*1.1048)/E12 -> 0.080554678 | G12: =Submetering!AK12+Submetering!AL12+Submetering!AU12 -> 2077.688 | H12: 0.8166 | I12: =Submetering!AF12+Submetering!AG12+Submetering!AV12+Submetering!AY12+Submetering!AZ12 -> 2708.792 | J12: =((Submetering!AG12+Submetering!BA12)*0.8868+(1712.96+1070.52)/30+(Submetering!AF12+Submetering!AY12+Submetering!AV12+Submetering!AZ12)*1.1251+(2076.11+129.67+207.57+207.57)/30+(11680.53+56.61)/30)/I12 -> 1.3118173
A13: Orlando | B13: 11 | C13: 11 | D13: 2018 | E13: =Submetering!F13+Submetering!H13+Submetering!J13+Submetering!L13+Submetering!N13+Submetering!P13+Submetering!R13+Submetering!T13+Submetering!V13+Submetering!X13+Submetering!Z13+Submetering!AB13+Submetering!AC13+Submetering!AD13+Submetering!AE13 -> 322860 | F13: =((((Submetering!E13+Submetering!AD13)*0.13773+(Submetering!E13+Submetering!AD13)*0.02095)*1.09+(2.85/30)*2)+(((Submetering!F13+Submetering!H13+Submetering!J13+Submetering!L13+Submetering!N13+Submetering!P13+Submetering!R13+Submetering!T13+Submetering!V13+Submetering!X13+Submetering!Z13+Submetering!AB13+Submetering!AC13+Submetering!AE13)*0.05155)+((Submetering!F13+Submetering!H13+Submetering!J13+Submetering!L13+Submetering!N13+Submetering!P13+Submetering!R13+Submetering!T13+Submetering!V13+Submetering!X13+Submetering!Z13+Submetering!AB13+Submetering!AC13+Submetering!AE13)*0.02095)+(20/30)*15)*1.1048)/E13 -> 0.08047888 | G13: =Submetering!AK13+Submetering!AL13+Submetering!AU13 -> 2667.904 | H13: 0.8166 | I13: =Submetering!AF13+Submetering!AG13+Submetering!AV13+Submetering!AY13+Submetering!AZ13 -> 5559.21 | J13: =((Submetering!AG13+Submetering!BA13)*0.8868+(1712.96+1070.52)/30+(Submetering!AF13+Submetering!AY13+Submetering!AV13+Submetering!AZ13)*1.1251+(2076.11+129.67+207.57+207.57)/30+(11680.53+56.61)/30)/I13 -> 1.2040296
A14: Orlando | B14: 18 | C14: 11 | D14: 2018 | E14: =Submetering!F14+Submetering!H14+Submetering!J14+Submetering!L14+Submetering!N14+Submetering!P14+Submetering!R14+Submetering!T14+Submetering!V14+Submetering!X14+Submetering!Z14+Submetering!AB14+Submetering!AC14+Submetering!AD14+Submetering!AE14 -> 305500 | F14: =((((Submetering!E14+Submetering!AD14)*0.13773+(Submetering!E14+Submetering!AD14)*0.02095)*1.09+(2.85/30)*2)+(((Submetering!F14+Submetering!H14+Submetering!J14+Submetering!L14+Submetering!N14+Submetering!P14+Submetering!R14+Submetering!T14+Submetering!V14+Submetering!X14+Submetering!Z14+Submetering!AB14+Submetering!AC14+Submetering!AE14)*0.05155)+((Submetering!F14+Submetering!H14+Submetering!J14+Submetering!L14+Submetering!N14+Submetering!P14+Submetering!R14+Submetering!T14+Submetering!V14+Submetering!X14+Submetering!Z14+Submetering!AB14+Submetering!AC14+Submetering!AE14)*0.02095)+(20/30)*15)*1.1048)/E14 -> 0.080505619 | G14: =Submetering!AK14+Submetering!AL14+Submetering!AU14 -> 4731.798 | H14: 0.8166 | I14: =Submetering!AF14+Submetering!AG14+Submetering!AV14+Submetering!AY14+Submetering!AZ14 -> 5688.486 | J14: =((Submetering!AG14+Submetering!BA14)*0.8868+(1712.96+1070.52)/30+(Submetering!AF14+Submetering!AY14+Submetering!AV14+Submetering!AZ14)*1.1251+(2076.11+129.67+207.57+207.57)/30+(11680.53+56.61)/30)/I14 -> 1.2009624
A15: Orlando | B15: 25 | C15: 11 | D15: 2018 | E15: =Submetering!F15+Submetering!H15+Submetering!J15+Submetering!L15+Submetering!N15+Submetering!P15+Submetering!R15+Submetering!T15+Submetering!V15+Submetering!X15+Submetering!Z15+Submetering!AB15+Submetering!AC15+Submetering!AD15+Submetering!AE15 -> 291040 | F15: =((((Submetering!E15+Submetering!AD15)*0.13773+(Submetering!E15+Submetering!AD15)*0.02095)*1.09+(2.85/30)*2)+(((Submetering!F15+Submetering!H15+Submetering!J15+Submetering!L15+Submetering!N15+Submetering!P15+Submetering!R15+Submetering!T15+Submetering!V15+Submetering!X15+Submetering!Z15+Submetering!AB15+Submetering!AC15+Submetering!AE15)*0.05155)+((Submetering!F15+Submetering!H15+Submetering!J15+Submetering!L15+Submetering!N15+Submetering!P15+Submetering!R15+Submetering!T15+Submetering!V15+Submetering!X15+Submetering!Z15+Submetering!AB15+Submetering!AC15+Submetering!AE15)*0.02095)+(20/30)*15)*1.1048)/E15 -> 0.080525871 | G15: =Submetering!AK15+Submetering!AL15+Submetering!AU15 -> 4946.536 | H15: 0.8166 | I15: =Submetering!AF15+Submetering!AG15+Submetering!AV15+Submetering!AY15+Submetering!AZ15 -> 5835.014 | J15: =((Submetering!AG15+Submetering!BA15)*0.8868+(1712.96+1070.52)/30+(Submetering!AF15+Submetering!AY15+Submetering!AV15+Submetering!AZ15)*1.1251+(2076.11+129.67+207.57+207.57)/30+(11680.53+56.61)/30)/I15 -> 1.1976917
A16: Orlando | B16: 31 | C16: 11 | D16: 2018 | E16: =Submetering!F16+Submetering!H16+Submetering!J16+Submetering!L16+Submetering!N16+Submetering!P16+Submetering!R16+Submetering!T16+Submetering!V16+Submetering!X16+Submetering!Z16+Submetering!AB16+Submetering!AC16+Submetering!AD16+Submetering!AE16 -> 273140 | F16: =((((Submetering!E16+Submetering!AD16)*0.13773+(Submetering!E16+Submetering!AD16)*0.02095)*1.09+(2.85/30)*2)+(((Submetering!F16+Submetering!H16+Submetering!J16+Submetering!L16+Submetering!N16+Submetering!P16+Submetering!R16+Submetering!T16+Submetering!V16+Submetering!X16+Submetering!Z16+Submetering!AB16+Submetering!AC16+Submetering!AE16)*0.05155)+((Submetering!F16+Submetering!H16+Submetering!J16+Submetering!L16+Submetering!N16+Submetering!P16+Submetering!R16+Submetering!T16+Submetering!V16+Submetering!X16+Submetering!Z16+Submetering!AB16+Submetering!AC16+Submetering!AE16)*0.02095)+(20/30)*15)*1.1048)/E16 -> 0.080554544 | G16: =Submetering!AK16+Submetering!AL16+Submetering!AU16 -> 6540.8982 | H16: 0.8166 | I16: =Submetering!AF16+Submetering!AG16+Submetering!AV16+Submetering!AY16+Submetering!AZ16 -> 5842.994 | J16: =((Submetering!AG16+Submetering!BA16)*0.8868+(1712.96+1070.52)/30+(Submetering!AF16+Submetering!AY16+Submetering!AV16+Submetering!AZ16)*1.1251+(2076.11+129.67+207.57+207.57)/30+(11680.53+56.61)/30)/I16 -> 1.6693973 | K16: =Occupancy!H14 -> 9923.4
A17: Orlando | B17: 9 | C17: 12 | D17: 2018 | E17: =Submetering!F17+Submetering!H17+Submetering!J17+Submetering!L17+Submetering!N17+Submetering!P17+Submetering!R17+Submetering!T17+Submetering!V17+Submetering!X17+Submetering!Z17+Submetering!AB17+Submetering!AC17+Submetering!AD17+Submetering!AE17 -> 281920 | F17: =((((Submetering!E17+Submetering!AD17)*0.13773+(Submetering!E17+Submetering!AD17)*0.02095)*1.09+(2.85/30)*2)+(((Submetering!F17+Submetering!H17+Submetering!J17+Submetering!L17+Submetering!N17+Submetering!P17+Submetering!R17+Submetering!T17+Submetering!V17+Submetering!X17+Submetering!Z17+Submetering!AB17+Submetering!AC17+Submetering!AE17)*0.05155)+((Submetering!F17+Submetering!H17+Submetering!J17+Submetering!L17+Submetering!N17+Submetering!P17+Submetering!R17+Submetering!T17+Submetering!V17+Submetering!X17+Submetering!Z17+Submetering!AB17+Submetering!AC17+Submetering!AE17)*0.02095)+(20/30)*15)*1.1048)/E17 -> 0.080544007 | G17: =Submetering!AK17+Submetering!AL17+Submetering!AU17 -> 6359.642 | H17: 0.8166 | I17: =Submetering!AF17+Submetering!AG17+Submetering!AV17+Submetering!AY17+Submetering!AZ17 -> 5029.414 | J17: =((Submetering!AG17+Submetering!BA17)*0.8868+(1712.96+1070.52)/30+(Submetering!AF17+Submetering!AY17+Submetering!AV17+Submetering!AZ17)*1.1251+(2076.11+129.67+207.57+207.57)/30+(11680.53+56.61)/30)/I17 -> 1.2117067
A18: Orlando | B18: 16 | C18: 12 | D18: 2018 | E18: =Submetering!F18+Submetering!H18+Submetering!J18+Submetering!L18+Submetering!N18+Submetering!P18+Submetering!R18+Submetering!T18+Submetering!V18+Submetering!X18+Submetering!Z18+Submetering!AB18+Submetering!AC18+Submetering!AD18+Submetering!AE18 -> 264140 | F18: =((((Submetering!E18+Submetering!AD18)*0.13773+(Submetering!E18+Submetering!AD18)*0.02095)*1.09+(2.85/30)*2)+(((Submetering!F18+Submetering!H18+Submetering!J18+Submetering!L18+Submetering!N18+Submetering!P18+Submetering!R18+Submetering!T18+Submetering!V18+Submetering!X18+Submetering!Z18+Submetering!AB18+Submetering!AC18+Submetering!AE18)*0.05155)+((Submetering!F18+Submetering!H18+Submetering!J18+Submetering!L18+Submetering!N18+Submetering!P18+Submetering!R18+Submetering!T18+Submetering!V18+Submetering!X18+Submetering!Z18+Submetering!AB18+Submetering!AC18+Submetering!AE18)*0.02095)+(20/30)*15)*1.1048)/E18 -> 0.080563552 | G18: =Submetering!AK18+Submetering!AL18+Submetering!AU18 -> 7138.034 | H18: 0.8166 | I18: =Submetering!AF18+Submetering!AG18+Submetering!AV18+Submetering!AY18+Submetering!AZ18 -> 4050.762 | J18: =((Submetering!AG18+Submetering!BA18)*0.8868+(1712.96+1070.52)/30+(Submetering!AF18+Submetering!AY18+Submetering!AV18+Submetering!AZ18)*1.1251+(2076.11+129.67+207.57+207.57)/30+(11680.53+56.61)/30)/I18 -> 1.2505368
A19: Orlando | B19: 31 | C19: 12 | D19: 2018 | E19: =Submetering!F19+Submetering!H19+Submetering!J19+Submetering!L19+Submetering!N19+Submetering!P19+Submetering!R19+Submetering!T19+Submetering!V19+Submetering!X19+Submetering!Z19+Submetering!AB19+Submetering!AC19+Submetering!AD19+Submetering!AE19 -> 1395848 | F19: =((((Submetering!E19+Submetering!AD19)*0.13773+(Submetering!E19+Submetering!AD19)*0.02095)*1.09+(2.85/30)*2)+(((Submetering!F19+Submetering!H19+Submetering!J19+Submetering!L19+Submetering!N19+Submetering!P19+Submetering!R19+Submetering!T19+Submetering!V19+Submetering!X19+Submetering!Z19+Submetering!AB19+Submetering!AC19+Submetering!AE19)*0.05155)+((Submetering!F19+Submetering!H19+Submetering!J19+Submetering!L19+Submetering!N19+Submetering!P19+Submetering!R19+Submetering!T19+Submetering!V19+Submetering!X19+Submetering!Z19+Submetering!AB19+Submetering!AC19+Submetering!AE19)*0.02095)+(20/30)*15)*1.1048)/E19 -> 0.075801292 | G19: =Submetering!AK19+Submetering!AL19+Submetering!AU19 -> 13785.446 | H19: 0.8166 | I19: =Submetering!AF19+Submetering!AG19+Submetering!AV19+Submetering!AY19+Submetering!AZ19 -> 11279.377 | J19: =((Submetering!AG19+Submetering!BA19)*0.8868+(1712.96+1070.52)/30+(Submetering!AF19+Submetering!AY19+Submetering!AV19+Submetering!AZ19)*1.1251+(2076.11+129.67+207.57+207.57)/30+(11680.53+56.61)/30)/I19 -> 1.2189458 | K19: =Occupancy!H15 -> 8795.196

Sheet Submetering
A1: Site Name | B1: Day | C1: Month | D1: Year | E1: 90 630 431 (KWh) | F1: 68 425 010 (KWh) | G1: T2392 (KWh) | H1: 68 425 008 (KWh) | I1: T7384 (KWh) | J1: 68 425 060 (KWh) | K1: T7380 (KWh) | L1: 68 425 097 (KWh) | M1: T7281 (KWh) | N1: 68 425 059 (KWh) | O1: T2390 (KWh) | P1: 68 425 077 (KWh) | Q1: T2395 (KWh) | R1: 68 425 078 (KWh) | S1: T2393 (KWh) | T1: 68 425 071 (KWh) | U1: T7285 (KWh) | V1: 68 425 093 (KWh) | W1: T7382 (KWh) | X1: 68 425 094 (KWh) | Y1: T2391 (KWh) | Z1: 90 625 242 (KWh) | AA1: T7283 (KWh) | AB1: 672 73 163 (KWh) | AC1: 676 62 513 (KWh) | AD1: 61 979 920 (KWh) | AE1: 56 253 208 (KWh) | AF1: Domestic Water from RCES 74860172 (m3) | AG1: Re-use Water from RCES 74860173 (m3) | AH1: Building A Fire Sprinkler System Make-up 44553004 (m3) | AI1: Building A Potable Water Feed 70275191 (m3) | AJ1: Steam Boilers Make-up Water 2130521 (m3) | AK1: Resort Natural Gas Meter 12C004186-C1 (m3) | AL1: Out Buildings Natural Gas Meter 93477704 (m3) | AM1: Cooling Tower Make-up Water 79177804 (m3) | AN1: Cooling Tower Blowdown Line Deduct 79305675 (m3) | AO1: Building E Potable Water Meter 79190041 (m3) | AP1: 7919004D | AQ1: Building J Irrigation Water Meter 79190039 (m3) | AR1: Lazy Pool River Make-up Water 79324776 (m3) | AS1: Pool Hydraunic Boiler Water Make-up 112014001775 (m3) | AT1: SPA Jacuzzi Water Make-up 112014001771 (m3) | AU1: Golf Clubhouse Natural Gas Meter 82SJ729151 (m3) | AV1: 73337589 - 1387142 | AW1: Golf Clubhouse Flushing Valve Deduct 65956268 (m3) | AX1: Clubhouse | AY1: Golf Maintenance Facility 1334021 (m3) | AZ1: Golf Course Comfort Stations 63265094 (m3) | BA1: Golf Course Re-use Irrigation 67327447 (m3)
A2: Orlando | B2: 31 | C2: 1 | D2: 2018 | E2: =Elect!AW5 -> 3070 | F2: =Elect!I5 -> 196480 | G2: =Elect!H5 -> 2.155 | H2: =Elect!E5 -> 190400 | I2: =Elect!D5 -> 2.054 | J2: =Elect!Y5 -> 164400 | K2: =Elect!X5 -> 1.848 | L2: =Elect!AS5 -> 9200 | M2: =Elect!AR5 -> 0.448 | N2: =Elect!AC5 -> 145500 | O2: =Elect!AB5 -> 1.945 | P2: =Elect!Q5 -> 58000 | Q2: =Elect!P5 -> 2.79 | R2: =Elect!M5 -> 58000 | S2: =Elect!L5 -> 2.92 | T2: =Elect!U5 -> 63200 | U2: =Elect!T5 -> 2.91 | V2: =Elect!AG5 -> 33440 | W2: =Elect!AF5 -> 5.23 | X2: =Elect!AK5 -> 20480 | Y2: =Elect!AJ5 -> 3.31 | Z2: =Elect!AO5 -> 229400 | AA2: =Elect!AN5 -> 2.174 | AB2: =Elect!BJ5 -> 9200 | AC2: =Elect!BG5 -> 60200 | AD2: =Elect!BM5 -> 3843 | AE2: =Elect!BP5 -> 8080 | AF2: =('Wtr-Gas'!E5)*0.0038 -> 18347.844 | AG2: =('Wtr-Gas'!H5)*0.0038 -> 1645.59 | AH2: ='Wtr-Gas'!K5*0.0038 -> 93.86 | AI2: ='Wtr-Gas'!N5*0.0038 -> 13262 | AJ2: ='Wtr-Gas'!Q5*0.0038 -> 167.2 | AK2: ='Wtr-Gas'!U5*0.0038 -> 3954.964 | AL2: ='Wtr-Gas'!X5*0.0038 -> 36692.914 | AM2: ='Wtr-Gas'!AB5*0.0038 -> 1193.2 | AN2: ='Wtr-Gas'!AD5*0.0038 -> 30996.231 | AO2: ='Wtr-Gas'!AF5*0.0038 -> 26.6 | AP2: ='Wtr-Gas'!AH5*0.0038 -> 1417.4 | AQ2: ='Wtr-Gas'!AJ5*0.0038 -> 179.5272 | AR2: ='Wtr-Gas'!AL5*0.0038 -> 2405.4 | AS2: ='Wtr-Gas'!AN5*0.0038 -> 0.038 | AT2: ='Wtr-Gas'!AP5*0.0038 -> 8.74 | AU2: ='Wtr-Gas'!AT5*0.0038 -> 1.7746 | AV2: ='Wtr-Gas'!AW5*0.0038 -> 1043.5332 | AW2: ='Wtr-Gas'!AY5*0.0038 -> 55.556 | AX2: ='Wtr-Gas'!AZ5*0.0038 -> 987.9772 | AY2: ='Wtr-Gas'!BB5*0.0038 -> 58.9 | AZ2: ='Wtr-Gas'!BD5*0.0038 -> 40.66 | BA2: ='Wtr-Gas'!BF5*0.0038 -> 78.2572
A3: Orlando | B3: 28 | C3: 2 | D3: 2018 | E3: =Elect!AW6 -> 2740 | F3: =Elect!I6 -> 180160 | G3: =Elect!H6 -> 2.118 | H3: =Elect!E6 -> 174720 | I3: =Elect!D6 -> 1.981 | J3: =Elect!Y6 -> 190200 | K3: =Elect!X6 -> 2.238 | L3: =Elect!AS6 -> 8480 | M3: =Elect!AR6 -> 0.42 | N3: =Elect!AC6 -> 204000 | O3: =Elect!AB6 -> 1.889 | P3: =Elect!Q6 -> 48000 | Q3: =Elect!P6 -> 2.25 | R3: =Elect!M6 -> 47600 | S3: =Elect!L6 -> 2.49 | T3: =Elect!U6 -> 50800 | U3: =Elect!T6 -> 2.58 | V3: =Elect!AG6 -> 31520 | W3: =Elect!AF6 -> 4.37 | X3: =Elect!AK6 -> 19840 | Y3: =Elect!AJ6 -> 3.53 | Z3: =Elect!AO6 -> 221800 | AA3: =Elect!AN6 -> 2.222 | AB3: =Elect!BJ6 -> 7800 | AC3: =Elect!BG6 -> 61300 | AD3: =Elect!BM6 -> 3169 | AE3: =Elect!BP6 -> 14320 | AF3: =('Wtr-Gas'!E6)*0.0038 -> 18519.718 | AG3: =('Wtr-Gas'!H6)*0.0038 -> 1462.506 | AH3: ='Wtr-Gas'!K6*0.0038 -> 63.08 | AI3: ='Wtr-Gas'!N6*0.0038 -> 13607.8 | AJ3: ='Wtr-Gas'!Q6*0.0038 -> 167.2 | AK3: ='Wtr-Gas'!U6*0.0038 -> 3161.182 | AL3: ='Wtr-Gas'!X6*0.0038 -> 17297.486 | AM3: ='Wtr-Gas'!AB6*0.0038 -> 1193.2 | AN3: ='Wtr-Gas'!AD6*0.0038 -> 58473.731 | AO3: ='Wtr-Gas'!AF6*0.0038 -> 26.6 | AP3: ='Wtr-Gas'!AH6*0.0038 -> 194974.2 | AQ3: ='Wtr-Gas'!AJ6*0.0038 -> 142.8154 | AR3: ='Wtr-Gas'!AL6*0.0038 -> 2287.6 | AS3: ='Wtr-Gas'!AN6*0.0038 -> 0.798 | AT3: ='Wtr-Gas'!AP6*0.0038 -> 5.928 | AU3: ='Wtr-Gas'!AT6*0.0038 -> 2.7474 | AV3: ='Wtr-Gas'!AW6*0.0038 -> 876.945 | AW3: ='Wtr-Gas'!AY6*0.0038 -> 28.766 | AX3: ='Wtr-Gas'!AZ6*0.0038 -> 848.179 | AY3: ='Wtr-Gas'!BB6*0.0038 -> 73.34 | AZ3: ='Wtr-Gas'!BD6*0.0038 -> 43.7 | BA3: ='Wtr-Gas'!BF6*0.0038 -> 2035.7436
A4: Orlando | B4: 1 | C4: 4 | D4: 2018 | E4: =Elect!AW7 -> 2953 | F4: =Elect!I7 -> 210560 | G4: =Elect!H7 -> 2.318 | H4: =Elect!E7 -> 200160 | I4: =Elect!D7 -> 2.043 | J4: =Elect!Y7 -> 209100 | K4: =Elect!X7 -> 1.983 | L4: =Elect!AS7 -> 9480 | M4: =Elect!AR7 -> 0.437 | N4: =Elect!AC7 -> 156600 | O4: =Elect!AB7 -> 1.552 | P4: =Elect!Q7 -> 56400 | Q4: =Elect!P7 -> 2.54 | R4: =Elect!M7 -> 56400 | S4: =Elect!L7 -> 2.61 | T4: =Elect!U7 -> 61200 | U4: =Elect!T7 -> 2.76 | V4: =Elect!AG7 -> 33600 | W4: =Elect!AF7 -> 3.8 | X4: =Elect!AK7 -> 19840 | Y4: =Elect!AJ7 -> 2.44 | Z4: =Elect!AO7 -> 252000 | AA4: =Elect!AN7 -> 2.301 | AB4: =Elect!BJ7 -> 8600 | AC4: =Elect!BG7 -> 64900 | AD4: =Elect!BM7 -> 3844 | AE4: =Elect!BP7 -> 19360 | AF4: =('Wtr-Gas'!E7)*0.0038 -> 21941.96 | AG4: =('Wtr-Gas'!H7)*0.0038 -> 4941.672 | AH4: ='Wtr-Gas'!K7*0.0038 -> 71.06 | AI4: ='Wtr-Gas'!N7*0.0038 -> 16362.8 | AJ4: ='Wtr-Gas'!Q7*0.0038 -> 462.84 | AK4: ='Wtr-Gas'!U7*0.0038 -> 3541.182 | AL4: ='Wtr-Gas'!X7*0.0038 -> 26087 | AM4: ='Wtr-Gas'!AB7*0.0038 -> 1820.2 | AN4: ='Wtr-Gas'!AD7*0.0038 -> 48358.249 | AO4: ='Wtr-Gas'!AF7*0.0038 -> 1227.4 | AP4: ='Wtr-Gas'!AH7*0.0038 -> 19494 | AQ4: ='Wtr-Gas'!AJ7*0.0038 -> 151.7036 | AR4: ='Wtr-Gas'!AL7*0.0038 -> 2641 | AS4: ='Wtr-Gas'!AN7*0.0038 -> 2.242 | AT4: ='Wtr-Gas'!AP7*0.0038 -> 13.338 | AU4: ='Wtr-Gas'!AT7*0.0038 -> 1.8772 | AV4: ='Wtr-Gas'!AW7*0.0038 -> 1034.3524 | AW4: ='Wtr-Gas'!AY7*0.0038 -> 58.824 | AX4: ='Wtr-Gas'!AZ7*0.0038 -> 975.5284 | AY4: ='Wtr-Gas'!BB7*0.0038 -> 71.82 | AZ4: ='Wtr-Gas'!BD7*0.0038 -> 68.78 | BA4: ='Wtr-Gas'!BF7*0.0038 -> 9082.3572
A5: Orlando | B5: 1 | C5: 5 | D5: 2018 | E5: =Elect!AW8 -> 2550 | F5: =Elect!I8 -> 194240 | G5: =Elect!H8 -> 2.226 | H5: =Elect!E8 -> 190720 | I5: =Elect!D8 -> 2.033 | J5: =Elect!Y8 -> 233400 | K5: =Elect!X8 -> 2.214 | L5: =Elect!AS8 -> 8280 | M5: =Elect!AR8 -> 0.39 | N5: =Elect!AC8 -> 228600 | O5: =Elect!AB8 -> 1.957 | P5: =Elect!Q8 -> 49600 | Q5: =Elect!P8 -> 2.25 | R5: =Elect!M8 -> 51600 | S5: =Elect!L8 -> 2.43 | T5: =Elect!U8 -> 55600 | U5: =Elect!T8 -> 2.65 | V5: =Elect!AG8 -> 31520 | W5: =Elect!AF8 -> 4.11 | X5: =Elect!AK8 -> 20960 | Y5: =Elect!AJ8 -> 3.54 | Z5: =Elect!AO8 -> 211200 | AA5: =Elect!AN8 -> 2.109 | AB5: =Elect!BJ8 -> 0 | AC5: =Elect!BG8 -> 0 | AD5: =Elect!BM8 -> 0 | AE5: =Elect!BP8 -> 0 | AF5: =('Wtr-Gas'!E8)*0.0038 -> 22782.596 | AG5: =('Wtr-Gas'!H8)*0.0038 -> 2506.214 | AH5: ='Wtr-Gas'!K8*0.0038 -> 53.58 | AI5: ='Wtr-Gas'!N8*0.0038 -> 15735.8 | AJ5: ='Wtr-Gas'!Q8*0.0038 -> 443.08 | AK5: ='Wtr-Gas'!U8*0.0038 -> 3665.974 | AL5: ='Wtr-Gas'!X8*0.0038 -> 14547.16 | AM5: ='Wtr-Gas'!AB8*0.0038 -> 2333.2 | AN5: ='Wtr-Gas'!AD8*0.0038 -> 66531.935 | AO5: ='Wtr-Gas'!AF8*0.0038 -> 748.6 | AP5: ='Wtr-Gas'!AH8*0.0038 -> 18148.8 | AQ5: ='Wtr-Gas'!AJ8*0.0038 -> 133.0988 | AR5: ='Wtr-Gas'!AL8*0.0038 -> 2135.6 | AS5: ='Wtr-Gas'!AN8*0.0038 -> 2.204 | AT5: ='Wtr-Gas'!AP8*0.0038 -> 5.168 | AU5: ='Wtr-Gas'!AT8*0.0038 -> 2.2458 | AV5: ='Wtr-Gas'!AW8*0.0038 -> 673.892 | AW5: ='Wtr-Gas'!AY8*0.0038 -> 0 | AX5: ='Wtr-Gas'!AZ8*0.0038 -> 673.892 | AY5: ='Wtr-Gas'!BB8*0.0038 -> 0 | AZ5: ='Wtr-Gas'!BD8*0.0038 -> 65.36 | BA5: ='Wtr-Gas'!BF8*0.0038 -> 2650.0592
A6: Orlando | B6: 4 | C6: 6 | D6: 2018 | E6: =Elect!AW9 -> 2764 | F6: =Elect!I9 -> 218080 | G6: =Elect!H9 -> 2.19 | H6: =Elect!E9 -> 214560 | I6: =Elect!D9 -> 2.061 | J6: =Elect!Y9 -> 327900 | K6: =Elect!X9 -> 2.833 | L6: =Elect!AS9 -> 9480 | M6: =Elect!AR9 -> 0.408 | N6: =Elect!AC9 -> 306900 | O6: =Elect!AB9 -> 2.257 | P6: =Elect!Q9 -> 59200 | Q6: =Elect!P9 -> 2.5 | R6: =Elect!M9 -> 60800 | S6: =Elect!L9 -> 2.86 | T6: =Elect!U9 -> 66400 | U6: =Elect!T9 -> 2.77 | V6: =Elect!AG9 -> 39840 | W6: =Elect!AF9 -> 8.67 | X6: =Elect!AK9 -> 23360 | Y6: =Elect!AJ9 -> 3.26 | Z6: =Elect!AO9 -> 243400 | AA6: =Elect!AN9 -> 2.244 | AB6: =Elect!BJ9 -> 0 | AC6: =Elect!BG9 -> 0 | AD6: =Elect!BM9 -> 0 | AE6: =Elect!BP9 -> 0 | AF6: =('Wtr-Gas'!E9)*0.0038 -> 22633.142 | AG6: =('Wtr-Gas'!H9)*0.0038 -> 2556.298 | AH6: ='Wtr-Gas'!K9*0.0038 -> 62.7 | AI6: ='Wtr-Gas'!N9*0.0038 -> 18316 | AJ6: ='Wtr-Gas'!Q9*0.0038 -> 186.2 | AK6: ='Wtr-Gas'!U9*0.0038 -> 3815.998 | AL6: ='Wtr-Gas'!X9*0.0038 -> 10658.544 | AM6: ='Wtr-Gas'!AB9*0.0038 -> 2040.6 | AN6: ='Wtr-Gas'!AD9*0.0038 -> 101274.45 | AO6: ='Wtr-Gas'!AF9*0.0038 -> 851.2 | AP6: ='Wtr-Gas'!AH9*0.0038 -> 13721.8 | AQ6: ='Wtr-Gas'!AJ9*0.0038 -> 86.9478 | AR6: ='Wtr-Gas'!AL9*0.0038 -> 988 | AS6: ='Wtr-Gas'!AN9*0.0038 -> 2.166 | AT6: ='Wtr-Gas'!AP9*0.0038 -> 11.552 | AU6: ='Wtr-Gas'!AT9*0.0038 -> 2.8424 | AV6: ='Wtr-Gas'!AW9*0.0038 -> 1151.4 | AW6: ='Wtr-Gas'!AY9*0.0038 -> 0 | AX6: ='Wtr-Gas'!AZ9*0.0038 -> 1151.4 | AY6: ='Wtr-Gas'!BB9*0.0038 -> 0 | AZ6: ='Wtr-Gas'!BD9*0.0038 -> 53.2 | BA6: ='Wtr-Gas'!BF9*0.0038 -> 4160.62
A7: Orlando | B7: 30 | C7: 6 | D7: 2018 | E7: =Elect!AW10 -> 2160 | F7: =Elect!I10 -> 178240 | G7: =Elect!H10 -> 2.309 | H7: =Elect!E10 -> 174080 | I7: =Elect!D10 -> 2.002 | J7: =Elect!Y10 -> 324600 | K7: =Elect!X10 -> 2.662 | L7: =Elect!AS10 -> 7720 | M7: =Elect!AR10 -> 0.423 | N7: =Elect!AC10 -> 303000 | O7: =Elect!AB10 -> 2.171 | P7: =Elect!Q10 -> 52000 | Q7: =Elect!P10 -> 2.54 | R7: =Elect!M10 -> 52800 | S7: =Elect!L10 -> 2.79 | T7: =Elect!U10 -> 51600 | U7: =Elect!T10 -> 2.9 | V7: =Elect!AG10 -> 29760 | W7: =Elect!AF10 -> 4.98 | X7: =Elect!AK10 -> 18080 | Y7: =Elect!AJ10 -> 3.78 | Z7: =Elect!AO10 -> 227800 | AA7: =Elect!AN10 -> 2.348 | AB7: =Elect!BJ10 -> 27500 | AC7: =Elect!BG10 -> 227900 | AD7: =Elect!BM10 -> 89184 | AE7: =Elect!BP10 -> 43560 | AF7: =('Wtr-Gas'!E10)*0.0038 -> 21164.48 | AG7: =('Wtr-Gas'!H10)*0.0038 -> 2265.218 | AH7: ='Wtr-Gas'!K10*0.0038 -> 29.26 | AI7: ='Wtr-Gas'!N10*0.0038 -> 16590.8 | AJ7: ='Wtr-Gas'!Q10*0.0038 -> 1.52 | AK7: ='Wtr-Gas'!U10*0.0038 -> 3281.908 | AL7: ='Wtr-Gas'!X10*0.0038 -> 3412.096 | AM7: ='Wtr-Gas'!AB10*0.0038 -> 2029.2 | AN7: ='Wtr-Gas'!AD10*0.0038 -> 102934.54 | AO7: ='Wtr-Gas'!AF10*0.0038 -> 684 | AP7: ='Wtr-Gas'!AH10*0.0038 -> 9754.6 | AQ7: ='Wtr-Gas'!AJ10*0.0038 -> 73.131 | AR7: ='Wtr-Gas'!AL10*0.0038 -> 946.2 | AS7: ='Wtr-Gas'!AN10*0.0038 -> 1.368 | AT7: ='Wtr-Gas'!AP10*0.0038 -> 8.36 | AU7: ='Wtr-Gas'!AT10*0.0038 -> 1.786 | AV7: ='Wtr-Gas'!AW10*0.0038 -> 862.6 | AW7: ='Wtr-Gas'!AY10*0.0038 -> 96.102 | AX7: ='Wtr-Gas'!AZ10*0.0038 -> 766.498 | AY7: ='Wtr-Gas'!BB10*0.0038 -> 215.84 | AZ7: ='Wtr-Gas'!BD10*0.0038 -> 11.4 | BA7: ='Wtr-Gas'!BF10*0.0038 -> 2873.5068
A8: Orlando | B8: 31 | C8: 7 | D8: 2018 | E8: =Elect!AW11 -> 2245 | F8: =Elect!I11 -> 182560 | G8: =Elect!H11 -> 2.112 | H8: =Elect!E11 -> 179200 | I8: =Elect!D11 -> 1.898 | J8: =Elect!Y11 -> 334800 | K8: =Elect!X11 -> 2.512 | L8: =Elect!AS11 -> 8280 | M8: =Elect!AR11 -> 0.409 | N8: =Elect!AC11 -> 315300 | O8: =Elect!AB11 -> 2.073 | P8: =Elect!Q11 -> 54000 | Q8: =Elect!P11 -> 2.5 | R8: =Elect!M11 -> 53200 | S8: =Elect!L11 -> 2.56 | T8: =Elect!U11 -> 56400 | U8: =Elect!T11 -> 2.55 | V8: =Elect!AG11 -> 28800 | W8: =Elect!AF11 -> 3.69 | X8: =Elect!AK11 -> 16800 | Y8: =Elect!AJ11 -> 2.91 | Z8: =Elect!AO11 -> 236800 | AA8: =Elect!AN11 -> 2.309 | AB8: =Elect!BJ11 -> 27500 | AC8: =Elect!BG11 -> 227900 | AD8: =Elect!BM11 -> 89184 | AE8: =Elect!BP11 -> 43650 | AF8: =('Wtr-Gas'!E11)*0.0038 -> 21069.746 | AG8: =('Wtr-Gas'!H11)*0.0038 -> 1902.736 | AH8: ='Wtr-Gas'!K11*0.0038 -> 33.44 | AI8: ='Wtr-Gas'!N11*0.0038 -> 17730.8 | AJ8: ='Wtr-Gas'!Q11*0.0038 -> 0 | AK8: ='Wtr-Gas'!U11*0.0038 -> 3281.908 | AL8: ='Wtr-Gas'!X11*0.0038 -> 3682.2 | AM8: ='Wtr-Gas'!AB11*0.0038 -> 2093.8 | AN8: ='Wtr-Gas'!AD11*0.0038 -> 105343.06 | AO8: ='Wtr-Gas'!AF11*0.0038 -> 573.8 | AP8: ='Wtr-Gas'!AH11*0.0038 -> 2036.8 | AQ8: ='Wtr-Gas'!AJ11*0.0038 -> 26.8318 | AR8: ='Wtr-Gas'!AL11*0.0038 -> 399 | AS8: ='Wtr-Gas'!AN11*0.0038 -> 1.406 | AT8: ='Wtr-Gas'!AP11*0.0038 -> 7.486 | AU8: ='Wtr-Gas'!AT11*0.0038 -> 1.7974 | AV8: ='Wtr-Gas'!AW11*0.0038 -> 919.6 | AW8: ='Wtr-Gas'!AY11*0.0038 -> 0 | AX8: ='Wtr-Gas'!AZ11*0.0038 -> 919.6 | AY8: ='Wtr-Gas'!BB11*0.0038 -> 37.62 | AZ8: ='Wtr-Gas'!BD11*0.0038 -> 7.6 | BA8: ='Wtr-Gas'!BF11*0.0038 -> 1968.4532
A9: Orlando | B9: 30 | C9: 8 | D9: 2018 | E9: =Elect!AW12 -> 5131 | F9: =Elect!I12 -> 392640 | G9: =Elect!H12 -> 2.106 | H9: =Elect!E12 -> 390400 | I9: =Elect!D12 -> 2.051 | J9: =Elect!Y12 -> 743100 | K9: =Elect!X12 -> 2.54 | L9: =Elect!AS12 -> 18360 | M9: =Elect!AR12 -> 0.412 | N9: =Elect!AC12 -> 713400 | O9: =Elect!AB12 -> 2.463 | P9: =Elect!Q12 -> 107200 | Q9: =Elect!P12 -> 2.21 | R9: =Elect!M12 -> 112400 | S9: =Elect!L12 -> 2.52 | T9: =Elect!U12 -> 114400 | U9: =Elect!T12 -> 2.64 | V9: =Elect!AG12 -> 62560 | W9: =Elect!AF12 -> 5.4 | X9: =Elect!AK12 -> 37280 | Y9: =Elect!AJ12 -> 3.61 | Z9: =Elect!AO12 -> 536200 | AA9: =Elect!AN12 -> 2.336 | AB9: =Elect!BJ12 -> 0 | AC9: =Elect!BG12 -> 0 | AD9: =Elect!BM12 -> 0 | AE9: =Elect!BP12 -> 0 | AF9: =('Wtr-Gas'!E12)*0.0038 -> 6522.738 | AG9: =('Wtr-Gas'!H12)*0.0038 -> 5394.556 | AH9: ='Wtr-Gas'!K12*0.0038 -> 136.04 | AI9: ='Wtr-Gas'!N12*0.0038 -> 35313.4 | AJ9: ='Wtr-Gas'!Q12*0.0038 -> 1463.76 | AK9: ='Wtr-Gas'!U12*0.0038 -> 679.82 | AL9: ='Wtr-Gas'!X12*0.0038 -> 7763.02 | AM9: ='Wtr-Gas'!AB12*0.0038 -> 4814.6 | AN9: ='Wtr-Gas'!AD12*0.0038 -> 255690.18 | AO9: ='Wtr-Gas'!AF12*0.0038 -> 1569.4 | AP9: ='Wtr-Gas'!AH12*0.0038 -> 16780.8 | AQ9: ='Wtr-Gas'!AJ12*0.0038 -> 240.5742 | AR9: ='Wtr-Gas'!AL12*0.0038 -> 1208.4 | AS9: ='Wtr-Gas'!AN12*0.0038 -> 3.42 | AT9: ='Wtr-Gas'!AP12*0.0038 -> 13.3 | AU9: ='Wtr-Gas'!AT12*0.0038 -> 2.3028 | AV9: ='Wtr-Gas'!AW12*0.0038 -> 1109.6 | AW9: ='Wtr-Gas'!AY12*0.0038 -> 0 | AX9: ='Wtr-Gas'!AZ12*0.0038 -> 1109.6 | AY9: ='Wtr-Gas'!BB12*0.0038 -> 57 | AZ9: ='Wtr-Gas'!BD12*0.0038 -> 3.8 | BA9: ='Wtr-Gas'!BF12*0.0038 -> 1621.84
A10: Orlando | B10: 23 | C10: 9 | D10: 2018 | E10: =Elect!AW13 -> 605 | F10: =Elect!I13 -> 44320 | G10: =Elect!H13 -> 2.18 | H10: =Elect!E13 -> 44960 | I10: =Elect!D13 -> 2.061 | J10: =Elect!Y13 -> 85500 | K10: =Elect!X13 -> 2.34 | L10: =Elect!AS13 -> 2080 | M10: =Elect!AR13 -> 0.412 | N10: =Elect!AC13 -> 55500 | O10: =Elect!AB13 -> 2.463 | P10: =Elect!Q13 -> 12000 | Q10: =Elect!P13 -> 2.22 | R10: =Elect!M13 -> 12000 | S10: =Elect!L13 -> 2.52 | T10: =Elect!U13 -> 13600 | U10: =Elect!T13 -> 2.78 | V10: =Elect!AG13 -> 12640 | W10: =Elect!AF13 -> 5.91 | X10: =Elect!AK13 -> 5120 | Y10: =Elect!AJ13 -> 3.63 | Z10: =Elect!AO13 -> 59000 | AA10: =Elect!AN13 -> 2.35 | AB10: =Elect!BJ13 -> 0 | AC10: =Elect!BG13 -> 0 | AD10: =Elect!BM13 -> 0 | AE10: =Elect!BP13 -> 0 | AF10: =('Wtr-Gas'!E13)*0.0038 -> 5202.884 | AG10: =('Wtr-Gas'!H13)*0.0038 -> 690.384 | AH10: ='Wtr-Gas'!K13*0.0038 -> 1.9 | AI10: ='Wtr-Gas'!N13*0.0038 -> 4028 | AJ10: ='Wtr-Gas'!Q13*0.0038 -> 0.38 | AK10: ='Wtr-Gas'!U13*0.0038 -> 81.662 | AL10: ='Wtr-Gas'!X13*0.0038 -> 1170.02 | AM10: ='Wtr-Gas'!AB13*0.0038 -> 577.6 | AN10: ='Wtr-Gas'!AD13*0.0038 -> 28579.192 | AO10: ='Wtr-Gas'!AF13*0.0038 -> 144.4 | AP10: ='Wtr-Gas'!AH13*0.0038 -> 3826.6 | AQ10: ='Wtr-Gas'!AJ13*0.0038 -> 26.7672 | AR10: ='Wtr-Gas'!AL13*0.0038 -> 323 | AS10: ='Wtr-Gas'!AN13*0.0038 -> 0.19 | AT10: ='Wtr-Gas'!AP13*0.0038 -> 1.368 | AU10: ='Wtr-Gas'!AT13*0.0038 -> 1.805 | AV10: ='Wtr-Gas'!AW13*0.0038 -> 1129.8844 | AW10: ='Wtr-Gas'!AY13*0.0038 -> 71.554 | AX10: ='Wtr-Gas'!AZ13*0.0038 -> 1058.3304 | AY10: ='Wtr-Gas'!BB13*0.0038 -> 57 | AZ10: ='Wtr-Gas'!BD13*0.0038 -> 3.8 | BA10: ='Wtr-Gas'!BF13*0.0038 -> 2303.94
A11: Orlando | B11: 31 | C11: 10 | D11: 2018 | E11: =Elect!AW14 -> 2181 | F11: =Elect!I14 -> 154080 | G11: =Elect!H14 -> 2.094 | H11: =Elect!E14 -> 153280 | I11: =Elect!D14 -> 2.033 | J11: =Elect!Y14 -> 231600 | K11: =Elect!X14 -> 2.138 | L11: =Elect!AS14 -> 6720 | M11: =Elect!AR14 -> 0.383 | N11: =Elect!AC14 -> 241800 | O11: =Elect!AB14 -> 1.872 | P11: =Elect!Q14 -> 41200 | Q11: =Elect!P14 -> 2.46 | R11: =Elect!M14 -> 40000 | S11: =Elect!L14 -> 2.48 | T11: =Elect!U14 -> 43200 | U11: =Elect!T14 -> 2.53 | V11: =Elect!AG14 -> 24160 | W11: =Elect!AF14 -> 4.42 | X11: =Elect!AK14 -> 14080 | Y11: =Elect!AJ14 -> 3.75 | Z11: =Elect!AO14 -> 193200 | AA11: =Elect!AN14 -> 2.122 | AB11: =Elect!BJ14 -> 0 | AC11: =Elect!BG14 -> 0 | AD11: =Elect!BM14 -> 0 | AE11: =Elect!BP14 -> 0 | AF11: =('Wtr-Gas'!E14)*0.0038 -> 16546.53 | AG11: =('Wtr-Gas'!H14)*0.0038 -> 2075.37 | AH11: ='Wtr-Gas'!K14*0.0038 -> 6.46 | AI11: ='Wtr-Gas'!N14*0.0038 -> 12790.8 | AJ11: ='Wtr-Gas'!Q14*0.0038 -> 0 | AK11: ='Wtr-Gas'!U14*0.0038 -> 267.558 | AL11: ='Wtr-Gas'!X14*0.0038 -> 9546.36 | AM11: ='Wtr-Gas'!AB14*0.0038 -> 1558 | AN11: ='Wtr-Gas'!AD14*0.0038 -> 83405.163 | AO11: ='Wtr-Gas'!AF14*0.0038 -> 429.4 | AP11: ='Wtr-Gas'!AH14*0.0038 -> 13771.2 | AQ11: ='Wtr-Gas'!AJ14*0.0038 -> 77.5884 | AR11: ='Wtr-Gas'!AL14*0.0038 -> 1037.4 | AS11: ='Wtr-Gas'!AN14*0.0038 -> 1.216 | AT11: ='Wtr-Gas'!AP14*0.0038 -> 5.206 | AU11: ='Wtr-Gas'!AT14*0.0038 -> 2.546 | AV11: ='Wtr-Gas'!AW14*0.0038 -> 914.5156 | AW11: ='Wtr-Gas'!AY14*0.0038 -> 0 | AX11: ='Wtr-Gas'!AZ14*0.0038 -> 914.5156 | AY11: ='Wtr-Gas'!BB14*0.0038 -> 64.6 | AZ11: ='Wtr-Gas'!BD14*0.0038 -> 3.8 | BA11: ='Wtr-Gas'!BF14*0.0038 -> 4288.3
A12: Orlando | B12: 4 | C12: 11 | D12: 2018 | E12: =Elect!AW15 -> 355 | F12: =Elect!I15 -> 24320 | G12: =Elect!H15 -> 2.219 | H12: =Elect!E15 -> 23040 | I12: =Elect!D15 -> 2.033 | J12: =Elect!Y15 -> 30300 | K12: =Elect!X15 -> 2.338 | L12: =Elect!AS15 -> 1000 | M12: =Elect!AR15 -> 0.383 | N12: =Elect!AC15 -> 24000 | O12: =Elect!AB15 -> 1.872 | P12: =Elect!Q15 -> 10400 | Q12: =Elect!P15 -> 2.46 | R12: =Elect!M15 -> 6400 | S12: =Elect!L15 -> 2.48 | T12: =Elect!U15 -> 6800 | U12: =Elect!T15 -> 2.53 | V12: =Elect!AG15 -> 3520 | W12: =Elect!AF15 -> 4.42 | X12: =Elect!AK15 -> 2080 | Y12: =Elect!AJ15 -> 3.25 | Z12: =Elect!AO15 -> 27200 | AA12: =Elect!AN15 -> 2.22 | AB12: =Elect!BJ15 -> 0 | AC12: =Elect!BG15 -> 0 | AD12: =Elect!BM15 -> 0 | AE12: =Elect!BP15 -> 0 | AF12: =('Wtr-Gas'!E15)*0.0038 -> 2433.482 | AG12: =('Wtr-Gas'!H15)*0.0038 -> 275.31 | AH12: ='Wtr-Gas'!K15*0.0038 -> 1.14 | AI12: ='Wtr-Gas'!N15*0.0038 -> 1744.2 | AJ12: ='Wtr-Gas'!Q15*0.0038 -> 0 | AK12: ='Wtr-Gas'!U15*0.0038 -> 39.748 | AL12: ='Wtr-Gas'!X15*0.0038 -> 2037.94 | AM12: ='Wtr-Gas'!AB15*0.0038 -> 182.4 | AN12: ='Wtr-Gas'!AD15*0.0038 -> 10175.473 | AO12: ='Wtr-Gas'!AF15*0.0038 -> 49.4 | AP12: ='Wtr-Gas'!AH15*0.0038 -> 1820.2 | AQ12: ='Wtr-Gas'!AJ15*0.0038 -> 7.5848 | AR12: ='Wtr-Gas'!AL15*0.0038 -> 201.4 | AS12: ='Wtr-Gas'!AN15*0.0038 -> 0.19 | AT12: ='Wtr-Gas'!AP15*0.0038 -> 0.608 | AU12: ='Wtr-Gas'!AT15*0.0038 -> 0 | AV12: ='Wtr-Gas'!AW15*0.0038 -> 0 | AW12: ='Wtr-Gas'!AY15*0.0038 -> 0 | AX12: ='Wtr-Gas'!AZ15*0.0038 -> 0 | AY12: ='Wtr-Gas'!BB15*0.0038 -> 0 | AZ12: ='Wtr-Gas'!BD15*0.0038 -> 0 | BA12: ='Wtr-Gas'!BF15*0.0038 -> 0
A13: Orlando | B13: 11 | C13: 11 | D13: 2018 | E13: =Elect!AW16 -> 646 | F13: =Elect!I16 -> 44800 | G13: =Elect!H16 -> 2.219 | H13: =Elect!E16 -> 44800 | I13: =Elect!D16 -> 2.033 | J13: =Elect!Y16 -> 88200 | K13: =Elect!X16 -> 2.476 | L13: =Elect!AS16 -> 1920 | M13: =Elect!AR16 -> 0.386 | N13: =Elect!AC16 -> 43500 | O13: =Elect!AB16 -> 1.872 | P13: =Elect!Q16 -> 8000 | Q13: =Elect!P16 -> 2.46 | R13: =Elect!M16 -> 12000 | S13: =Elect!L16 -> 2.48 | T13: =Elect!U16 -> 12800 | U13: =Elect!T16 -> 2.56 | V13: =Elect!AG16 -> 7360 | W13: =Elect!AF16 -> 4.42 | X13: =Elect!AK16 -> 4480 | Y13: =Elect!AJ16 -> 4 | Z13: =Elect!AO16 -> 55000 | AA13: =Elect!AN16 -> 2.22 | AB13: =Elect!BJ16 -> 0 | AC13: =Elect!BG16 -> 0 | AD13: =Elect!BM16 -> 0 | AE13: =Elect!BP16 -> 0 | AF13: =('Wtr-Gas'!E16)*0.0038 -> 5002.776 | AG13: =('Wtr-Gas'!H16)*0.0038 -> 556.434 | AH13: ='Wtr-Gas'!K16*0.0038 -> 1.9 | AI13: ='Wtr-Gas'!N16*0.0038 -> 3838 | AJ13: ='Wtr-Gas'!Q16*0.0038 -> 0 | AK13: ='Wtr-Gas'!U16*0.0038 -> 75.924 | AL13: ='Wtr-Gas'!X16*0.0038 -> 2591.98 | AM13: ='Wtr-Gas'!AB16*0.0038 -> 414.2 | AN13: ='Wtr-Gas'!AD16*0.0038 -> 23616.768 | AO13: ='Wtr-Gas'!AF16*0.0038 -> 57 | AP13: ='Wtr-Gas'!AH16*0.0038 -> 3602.4 | AQ13: ='Wtr-Gas'!AJ16*0.0038 -> 43.8368 | AR13: ='Wtr-Gas'!AL16*0.0038 -> 399 | AS13: ='Wtr-Gas'!AN16*0.0038 -> 0.304 | AT13: ='Wtr-Gas'!AP16*0.0038 -> 1.254 | AU13: ='Wtr-Gas'!AT16*0.0038 -> 0 | AV13: ='Wtr-Gas'!AW16*0.0038 -> 0 | AW13: ='Wtr-Gas'!AY16*0.0038 -> 0 | AX13: ='Wtr-Gas'!AZ16*0.0038 -> 0 | AY13: ='Wtr-Gas'!BB16*0.0038 -> 0 | AZ13: ='Wtr-Gas'!BD16*0.0038 -> 0 | BA13: ='Wtr-Gas'!BF16*0.0038 -> 0
... A19: Orlando | B19: 31 | C19: 12 | D19: 2018 | E19: =Elect!AW22 -> 1410 | F19: =Elect!I22 -> 101760 | G19: =Elect!H22 -> 2.433 | H19: =Elect!E22 -> 97440 | I19: =Elect!D22 -> 2.115 | J19: =Elect!Y22 -> 98700 | K19: =Elect!X22 -> 1.547 | L19: =Elect!AS22 -> 4200 | M19: =Elect!AR22 -> 0.401 | N19: =Elect!AC22 -> 80400 | O19: =Elect!AB22 -> 1.541 | P19: =Elect!Q22 -> 27200 | Q19: =Elect!P22 -> 2.72 | R19: =Elect!M22 -> 25600 | S19: =Elect!L22 -> 2.65 | T19: =Elect!U22 -> 28000 | U19: =Elect!T22 -> 2.73 | V19: =Elect!AG22 -> 14400 | W19: =Elect!AF22 -> 3.64 | X19: =Elect!AK22 -> 8640 | Y19: =Elect!AJ22 -> 2.5 | Z19: =Elect!AO22 -> 120600 | AA19: =Elect!AN22 -> 2.289 | AB19: =Elect!BJ22 -> 81800 | AC19: =Elect!BG22 -> 676200 | AD19: =Elect!BM22 -> -67332 | AE19: =Elect!BP22 -> 98240 | AF19: =('Wtr-Gas'!E22)*0.0038 -> 9988.186 | AG19: =('Wtr-Gas'!H22)*0.0038 -> 15.694 | AH19: ='Wtr-Gas'!K22*0.0038 -> 20.52 | AI19: ='Wtr-Gas'!N22*0.0038 -> 7413.8 | AJ19: ='Wtr-Gas'!Q22*0.0038 -> 0 | AK19: ='Wtr-Gas'!U22*0.0038 -> 191.71 | AL19: ='Wtr-Gas'!X22*0.0038 -> 13591.84 | AM19: ='Wtr-Gas'!AB22*0.0038 -> 3.8 | AN19: ='Wtr-Gas'!AD22*0.0038 -> 25537.634 | AO19: ='Wtr-Gas'!AF22*0.0038 -> 714.4 | AP19: ='Wtr-Gas'!AH22*0.0038 -> 6659602.6 | AQ19: ='Wtr-Gas'!AJ22*0.0038 -> 86.754 | AR19: ='Wtr-Gas'!AL22*0.0038 -> 779 | AS19: ='Wtr-Gas'!AN22*0.0038 -> 0 | AT19: ='Wtr-Gas'!AP22*0.0038 -> 2.698 | AU19: ='Wtr-Gas'!AT22*0.0038 -> 1.8962 | AV19: ='Wtr-Gas'!AW22*0.0038 -> 1212.4166 | AW19: ='Wtr-Gas'!AY22*0.0038 -> 45.486 | AX19: ='Wtr-Gas'!AZ22*0.0038 -> 1166.9306 | AY19: ='Wtr-Gas'!BB22*0.0038 -> 59.28 | AZ19: ='Wtr-Gas'!BD22*0.0038 -> 3.8 | BA19: ='Wtr-Gas'!BF22*0.0038 -> 553.5384

Sheet Info
B4: Electrical
B5: Location | C5: Transformer # | D5: Meter Serial # | E5: Reedy Creek # | F5: Service Area | G5: Multiplier | I5: Reedy Creek Description
B6: Service Yard #2 | C6: T7384 | D6: 68 425 008 | E6: CC0913A018 | G6: 160 | I6: HSB2 Section 1&2, Building A
B7: Service Yard #2 | C7: T2392 | D7: 68 425 010 | E7: CC0913A020 | G7: 160 | I7: HSB2 Section 4&5, Building A
B8: Service Yard #2 | C8: T2393 | D8: 68 425 078 | E8: CC0913A060 | G8: 400 | I8: LSB2 Building A - T2395
B9: Service Yard #2 | C9: T2395 | D9: 68 425 077 | E9: CC0913A059 | G9: 400 | I9: LSB2 Building A - T2393
B10: Service Yard #2 | C10: T7285 | D10: 68 425 071 | E10: CC0913A081 | G10: 400 | I10: LSB2 Building A - T7285
B11: Service Yard #1 | C11: T7380 | D11: 68 425 060 | E11: CC0913A054 | G11: 300 | I11: Main Electric Room #1
B12: Service Yard #1 | C12: T2390 | D12: 68 425 059 | E12: CC0913A053 | G12: 300 | I12: Service Yard #1
B13: Service Yard #1 | C13: T7382 | D13: 68 425 093 | E13: CC0913A075 | G13: 160 | I13: Main Electric Room #1 South
B14: Service Yard #1 | C14: T2391 | D14: 68 425 094 | E14: CC0913A076 | G14: 160 | I14: Main Electric Room #1 South
B15: Servcie Yard #3 | C15: T7283 | D15: 90 625 242 | E15: CC0912A18 | G15: 200 | I15: Out Buildings
B16: Servcie Yard #3 | C16: T7281 | D16: 68 425 097 | E16: CC0913A095 | G16: 40 | I16: Out Buildings
B17: Remote Parking Lot Lights | C17: T2009 | D17: 90 630 431 | E17: CS0212A003 | G17: 1 | I17: Employee Parking Lot Lights
B18: Golf Maintenance | D18: 67273163 | E18: CC0612A036 | I18: Golf Maintenace
B19: Golf Clubhouse | D19: 67662513 | E19: CG0612A084 | I19: Golf Clubhouse
B20: Golf Comfort Stations | D20: 61979920 | E20: CS0210A030 | I20: Comfort Stations
B21: Golf Irrigation Pump House | D21: 56253208 | E21: IC0608A03 | I21: Irrigation Pump House
B24: Water
B25: Service Entry | D25: 74860172 | E25: x10 | F25: Main Potable Water Feed | I25: Water
B26: Service Entry | D26: 74860173 | E26: x10 | F26: Re-use Water Feed | I26: Reclaimed Water
B27: Pump Room | D27: 44553004 | E27: x10 | F27: Fire System Make-up Feed
B28: Pump Room | D28: 70275191 | E28: x100 | F28: PW Feed for Bldg A | I28: Installed 1/31/14
B29: Boiler Room | D29: 2130521 | E29: x100 | F29: Steam Boiler M/U Water | I29: Installed 4/15/14
B31: Deduct Meters | C31: Added 7/15
B32: Chiller Room | D32: 79177804 | E32: x1 | F32: Make-up to Cooling Towers
B33: Chiller Room | D33: 79305675 | E33: x1 | F33: Cooling Tower Blowdown
B34: Building E | D34: 7919004D | E34: x1000 | F34: Irrigation Water
B35: Building E | D35: 79190041 | E35: x1000 | F35: Potable Water
B36: Building J | D36: 79190039 | E36: x1 | F36: Irrigation Water
B37: Lazy River | C37: Added 10/20/15 | D37: 79324776 | E37: x1000 | F37: Potable make-up water for Lazy River
B38: Building E - Inside | C38: Added 11/24/15 | D38: 112014001775 | E38: x100 | F38: Pool Hydranic Heater Make-up Water
B39: Service Yard #2 | C39: Added 11/24/15 | D39: 112014001771 | E39: x100 | F39: Mens and Womens Spa Pool Make-up Water
B43: Changes to Meters
B44: Exterior Pump Room | D44: 12C004186-C1 | E44: x100 | F44: Main Gas Feed | I44: Meter changed on 11/19/14
D45: 04B000408 | E45: 41962 | I45: New Meter Serial Number - Start Number 4668
B46: Golf Course Irrigation | D46: 80606729 | E46: 42522 | I46: New Meter Serial Number - Start Number 0
B48: Cooling Tower M/U Meter | D48: 85492530 | E48: 43698 | I48: Meter Changed by RCID
B51: Disputed Bill | D51: Customer # | E51: Account #
D52: 10816233 | E52: 2236896 | I52: ???

Sheet Logsheet
B1: Four Seasons Utility Readings
N2: updated 9/1/19
B3: Water Meters
B4: 74860172 | D4: 74860173 | F4: 44553004 | H4: 70275191 | J4: 2130521 | L4: 04B000408 | N4: 93477704
B6: Main PW Feed | D6: Main RW Feed | F6: Fire Prot Water Feed | H6: Potable Wtr Bldg A | J6: Steam Boiler M/U | L6: Main Gas Meter 2# | N6: Main Gas Meter 5#
B9: 85492530 | D9: 79305675 | F9: 79190041 | H9: 7919004D | J9: 79190039 | L9: 79324776
B10: Chiller Room | D10: Chiller Room | F10: Building E | H10: Building E | J10: Building J | L10: Lazy River | N10: Capa Terrace
B11: Cooling Tower M/U | D11: Cooling Tower Bleed | F11: Potable Water | H11: Irrigation | J11: Irrigation | L11: Potable Water | N11: Landscaping Mtr
B14: Electric Meters Service Yard #2
B15: CC0913A018 | D15: CC0913A020 | F15: CC0913A060 | H15: CC0913A059 | J15: CC0913A081
B16: 68 425 008 | C16: T7384 | D16: 68 425 010 | E16: T2392 | F16: 68 425 078 | G16: T2393 | H16: 68 425 077 | I16: T2395 | J16: 68 425 071 | K16: T7285
B17: KWH | C17: Demand | D17: KWH | E17: Demand | F17: KWH | G17: Demand | H17: KWH | I17: Demand | J17: KWH | K17: Demand
B20: Central Plant Service Yard | J20: Building E
B21: CC0913A054 | D21: CC0913A053 | F21: CC0913A075 | H21: CC0913A076 | J21: CC0912A18 | L21: CC0913A095
B22: 68 425 060 | C22: T7380 | D22: 68 425 059 | E22: T2390 | F22: 68 425 093 | G22: T7382 | H22: 68 425 094 | I22: T2391 | J22: 90 625 242 | K22: T7283 | L22: 68 425 097 | M22: T7281
B23: KWH | C23: Demand | D23: KWH | E23: Demand | F23: KWH | G23: Demand | H23: KWH | I23: Demand | J23: KWH | K23: Demand | L23: KWH | M23: Demand
B26: Employee Parking | D26: Emerg Generator | J26: 112014001775 | L26: 112014001771
B27: CS0212A003 | D27: GEN01 | J27: Building E - Inside | L27: Service Yard #2
B28: 90 630 431 | C28: T2009 | D28: Tank Level | J28: Pool Hydranic Heater | L28: Spa Jacuzzi's
B29: KWH | D29: 1/4-3/4 | J29: Make-up Water | L29: Make-up Water

Sheet Golf Logsheet
B2: Water Meters
B3: 73337589 | D3: 65956268 | F3: 1334021 | H3: 63265094 | J3: 80606729
B5: Club House | D5: Club House Deduct | F5: Golf Maintenance | H5: Comfort Stations | J5: Irrigation Reclaim Water
B8: Electric Meters
B9: CG0612A084 | D9: CC0612A036 | H9: CS0210A0300 | J9: IC0608A03
B10: 676 62 513 | D10: 672 73 163 | H10: 61 979 920 | J10: 56 253 208
B11: Club House | D11: Golf Maintenance | H11: Comfort Stations | J11: Irrigation Pump House
B14: Natural Gas / Petroleum
B15: 82SJ729151 | D15: Propane Tank #1 | F15: Propane Tank #2 | H15: Unleaded Tank | J15: Diesel Tank | L15: Lube Oil Tank
B16: 46801014
B17: Nat Gas-Clubhouse | D17: Golf Maintenance | F17: Golf Maintenance | H17: Golf Mainenance | J17: Golf Maintenance | L17: Golf Maintenance

Sheet Graphs
B2: Jan | C2: Feb | D2: Mar | E2: Apr | F2: May | G2: Jun | H2: Jul | I2: Aug | J2: Sep | K2: Oct | L2: Nov | M2: Dec | O2: KWH | P2: Fuel Surcharge | Q2: Demand
Z3: Electric | AA3: Gas
Y5: 2015 | Z5: =([1]Elect!#REF!) -> #REF!
Y6: 2016 | Z6: =([1]Elect!#REF!) -> #REF!
Y7: 2017 | Z7: =([1]Elect!#REF!) -> #REF!
Y8: 2018 | Z8: =([1]Elect!#REF!) -> #REF!
Y9: 2019 | Z9: =([1]Elect!#REF!) -> #REF!
X21: hi

Sheet Drawing
B3: Utility Distribution
B4: Four Seasons Resort Orlando at Walt Disney World Resort
B5: Electrical, Potable Water, Re-use Water, Natural Gas
AU14: Water Deduct Meters downstream | BX14: Golf Course Water
AU15: of the main water meter for the Resort | BX15: Distribution
AU16: Meter Numbers Listed | BX16: Meter Numbers Listed
AY18: Bldg A Fire | CL18: Golf Clubhouse
AY19: Sprinkler System | BY19: Golf Clubhouse | CL19: Flushing Valve
AY20: Make-up | BY20: 73337589 | CL20: Deduct
AY21: 44553004 | CL21: 65956268
G22: 12" Potable Water Line | AA22: Domestic Water
G23: Feed from | AA23: from RCES
G24: RCES | AA24: 74860172
AY25: Bdlg A Potable | BY25: Golf Maint
AY26: Water Feed | BY26: Facility
AY27: 70275191 | BY27: 1334021
CK28: Golf Course
M29: 8" Re-use Water Line | AA29: Re-use Water | CK29: Re-Use Irrigation
M30: Feed from | AA30: from RCES | CK30: 67327447
M31: RCES | AA31: 74860173
BY32: Golf Course
AY33: Steam Boilers | BY33: Comfort Stations
AY34: Make-up Water | BY34: 63265094
AY35: 2130521
AJ36: Landscaping
AJ37: Re-use System
AY40: Cooling Tower | BL40: Cooling Twr
AA41: Out Buildings | AY41: Make-up Water | BL41: Blowdown
AA42: Natural Gas Meter | AY42: 79177804 | BL42: Line Deduct
AA43: 93477704 | BL43: 79305675
M45: Natural Gas
M46: Feed at 50 PSI
M47: Reduced to 2 PSI | AY47: Bldg E Potable
M48: for building | AA48: Resort Natural | AY48: Water Meter
M49: Distribution | AA49: Gas Meter | AY49: 79190041
AA50: 12C004186-C1
AY54: Bldg J Irrigation
AY55: Water Meter
AA56: Golf Clubhouse | AY56: 79190039
AA57: Natural Gas
...

Sheet Occupancy
B3: CDD | C3: HDD | E3: % Occ | F3: 2018 | I3: CDD | J3: HDD
A4: Jan | B4: 159 | C4: 46 | E4: 75.9 | F4: 0.759 | G4: 13764 | H4: =SUM(F4*G4) -> 10446.876 | I4: 192 | J4: 31
A5: Feb | B5: 156 | C5: 76 | E5: 78.2 | F5: 0.782 | G5: 12432 | H5: =SUM(F5*G5) -> 9721.824 | I5: 125 | J5: 125
A6: Mar | B6: 264 | C6: 18 | E6: 85.6 | F6: 0.856 | G6: 13764 | H6: =SUM(F6*G6) -> 11781.984 | I6: 239 | J6: 21
A7: Apr | B7: 415 | C7: 0 | E7: 83.7 | F7: 0.837 | G7: 13320 | H7: =SUM(F7*G7) -> 11148.84 | I7: 328 | J7: 1
A8: May | B8: 487 | C8: 0 | E8: 75.9 | F8: 0.759 | G8: 13764 | H8: =SUM(F8*G8) -> 10446.876 | I8: 440 | J8: 0
A9: Jun | B9: 502 | C9: 0 | E9: 74.5 | F9: 0.745 | G9: 13320 | H9: =SUM(F9*G9) -> 9923.4 | I9: 477 | J9: 0
A10: Jul | B10: 492 | C10: 0 | E10: 70.8 | F10: 0.708 | G10: 13764 | H10: =SUM(F10*G10) -> 9744.912 | I10: 495 | J10: 0
A11: Aug | B11: 475 | C11: 0 | E11: 71.8 | F11: 0.718 | G11: 13764 | H11: =SUM(F11*G11) -> 9882.552 | I11: 500 | J11: 0
A12: Sep | B12: 500 | C12: 0 | E12: 59 | F12: 0.59 | G12: 13320 | H12: =SUM(F12*G12) -> 7858.8 | I12: 377 | J12: 8
A13: Oct | B13: 431 | C13: 66 | E13: 70.3 | F13: 0.703 | G13: 13764 | H13: =SUM(F13*G13) -> 9676.092 | I13: 187 | J13: 72
A14: Nov | B14: 167 | C14: 80 | E14: 74.5 | F14: 0.745 | G14: 13320 | H14: =SUM(F14*G14) -> 9923.4 | I14: 104 | J14: 146
A15: Dec | B15: 140 | C15: 133 | E15: 63.9 | F15: 0.639 | G15: 13764 | H15: =SUM(F15*G15) -> 8795.196 | I15: 68 | J15: 214
G16: =SUM(G4:G15) -> 162060 | H16: =SUM(H4:H15) -> 119350.75
L25: 2017 | M25: 2018 | N25: 2019
K26: Occupied Guest Rooms | L26: 120328 | M26: 119350 | N26: 91868
K27: Electric KWH | L27: 17910500 | M27: 17636409 | N27: 13838299
K28: Electrical Use per Occupied Room | L28: =SUM(L27/L26) -> 148.84732 | M28: =SUM(M27/M26) -> 147.7705 | N28: =SUM(N27/N26) -> 150.63242
K29: Gas CCF | L29: 600069 | M29: 584640 | N29: 432248
K30: Gas Use Per Occupied Room | L30: =SUM(L29/L26) -> 4.986944 | M30: =SUM(M29/M26) -> 4.8985337 | N30: =SUM(N29/N26) -> 4.7050986
K32: 2019 Totals are through Sept 30th

Sheet Elect
B1: 2018 | C1: CC0913A018 | G1: CC0913A020 | K1: CC0913A060 | O1: CC0913A059 | S1: CC0913A081 | W1: CC0913A054 | AA1: CC0913A053 | AE1: CC0913A075 | AI1: CC0913A076 | AM1: CC0912A18 | AQ1: CC0913A095 | AU1: CS0212A003 | BA1: Water Pk | BB1: % of KWH | BF1: CG0612A084 | BI1: CC0612A036 | BL1: CS0210A030 | BO1: IIC0608A03 | BU1: KWH | BY1: Account # - 02230191 | CC1: Meter # - CC0913A020 | CL1: Meter # - CC0913A018 | CU1: Meter # - CC0913A054 | DD1: Meter # - CC0913A095 | DM1: Meter # - CC0913A053 | DV1: Meter # - CC0913A059 | EE1: Meter # - CC0913A060 | EN1: Meter # - CC0913A081 | EW1: Meter # - CC0913A075 | FF1: Meter # - CC0913A076 | FO1: Meter # - CC90625425 | FZ1: Amount | GE1: Meter # - 672 73 163 | GN1: Meter # - 676 62 513 | GW1: Meter # - 61 979 920 | HC1: Meter # - 56 253 208
