Workbook

Sheet TOTAL
A1: Site Name | B1: Day | C1: Month | D1: Year | E1: Total Electricity Kwh | F1: Electricity Tariff ($/Kwh) | G1: Natual Gas (m3) | H1: Natural Gas $/m3 | I1: Water Utility Supply (m3) m3 | J1: Water Utility Supply (m3) $/m3 | K1: Room Nights
A2: Orlando | B2: 5 | C2: 1 | D2: 2020 | E2: =Submetering!F3+Submetering!H3+Submetering!J3+Submetering!L3+Submetering!N3+Submetering!P3+Submetering!R3+Submetering!T3+Submetering!V3+Submetering!X3+Submetering!Z3+Submetering!AB3+Submetering!AC3+Submetering!AD3+Submetering!AE3 -> 273801.6 | F2: =((((Submetering!E3+Submetering!AD3)*0.13773+(Submetering!E3+Submetering!AD3)*0.02095)*1.09+(2.85/30)*2)+(((Submetering!F3+Submetering!H3+Submetering!J3+Submetering!L3+Submetering!N3+Submetering!P3+Submetering!R3+Submetering!T3+Submetering!V3+Submetering!X3+Submetering!Z3+Submetering!AB3+Submetering!AC3+Submetering!AE3)*0.05155)+((Submetering!F3+Submetering!H3+Submetering!J3+Submetering!L3+Submetering!N3+Submetering!P3+Submetering!R3+Submetering!T3+Submetering!V3+Submetering!X3+Submetering!Z3+Submetering!AB3+Submetering!AC3+Submetering!AE3)*0.02095)+(20/30)*15)*1.1048)/E2 -> 0.080960258 | G2: =Submetering!AK3+Submetering!AL3+Submetering!AU3 -> 5732.3038 | H2: 0.8166 | I2: =Submetering!AF3+Submetering!AG3+Submetering!AV3+Submetering!AY3+Submetering!AZ3 -> 3362.373 | J2: =((Submetering!AG3+Submetering!BA3)*0.8868+(1712.96+1070.52)/30+(Submetering!AF3+Submetering!AY3+Submetering!AV3+Submetering!AZ3)*1.1251+(2076.11+129.67+207.57+207.57)/30+(11680.53+56.61)/30)/I2 -> 1.3007092 | K2: =Elect!C5 -> 1437
A3: Orlando | B3: 12 | C3: 1 | D3: 2020 | E3: =Submetering!F4+Submetering!H4+Submetering!J4+Submetering!L4+Submetering!N4+Submetering!P4+Submetering!R4+Submetering!T4+Submetering!V4+Submetering!X4+Submetering!Z4+Submetering!AB4+Submetering!AC4+Submetering!AD4+Submetering!AE4 -> 294900.65 | F3: =((((Submetering!E4+Submetering!AD4)*0.13773+(Submetering!E4+Submetering!AD4)*0.02095)*1.09+(2.85/30)*2)+(((Submetering!F4+Submetering!H4+Submetering!J4+Submetering!L4+Submetering!N4+Submetering!P4+Submetering!R4+Submetering!T4+Submetering!V4+Submetering!X4+Submetering!Z4+Submetering!AB4+Submetering!AC4+Submetering!AE4)*0.05155)+((Submetering!F4+Submetering!H4+Submetering!J4+Submetering!L4+Submetering!N4+Submetering!P4+Submetering!R4+Submetering!T4+Submetering!V4+Submetering!X4+Submetering!Z4+Submetering!AB4+Submetering!AC4+Submetering!AE4)*0.02095)+(20/30)*15)*1.1048)/E3 -> 0.08119182 | G3: =Submetering!AK4+Submetering!AL4+Submetering!AU4 -> 7093.1256 | H3: 0.8166 | I3: =Submetering!AF4+Submetering!AG4+Submetering!AV4+Submetering!AY4+Submetering!AZ4 -> 3823.161 | J3: =((Submetering!AG4+Submetering!BA4)*0.8868+(1712.96+1070.52)/30+(Submetering!AF4+Submetering!AY4+Submetering!AV4+Submetering!AZ4)*1.1251+(2076.11+129.67+207.57+207.57)/30+(11680.53+56.61)/30)/I3 -> 1.2700624 | K3: =Elect!C6 -> 1370
A4: Orlando | B4: 19 | C4: 1 | D4: 2020 | E4: =Submetering!F5+Submetering!H5+Submetering!J5+Submetering!L5+Submetering!N5+Submetering!P5+Submetering!R5+Submetering!T5+Submetering!V5+Submetering!X5+Submetering!Z5+Submetering!AB5+Submetering!AC5+Submetering!AD5+Submetering!AE5 -> 298844.67 | F4: =((((Submetering!E5+Submetering!AD5)*0.13773+(Submetering!E5+Submetering!AD5)*0.02095)*1.09+(2.85/30)*2)+(((Submetering!F5+Submetering!H5+Submetering!J5+Submetering!L5+Submetering!N5+Submetering!P5+Submetering!R5+Submetering!T5+Submetering!V5+Submetering!X5+Submetering!Z5+Submetering!AB5+Submetering!AC5+Submetering!AE5)*0.05155)+((Submetering!F5+Submetering!H5+Submetering!J5+Submetering!L5+Submetering!N5+Submetering!P5+Submetering!R5+Submetering!T5+Submetering!V5+Submetering!X5+Submetering!Z5+Submetering!AB5+Submetering!AC5+Submetering!AE5)*0.02095)+(20/30)*15)*1.1048)/E4 -> 0.081466767 | G4: =Submetering!AK5+Submetering!AL5+Submetering!AU5 -> 5253.025 | H4: 0.8166 | I4: =Submetering!AF5+Submetering!AG5+Submetering!AV5+Submetering!AY5+Submetering!AZ5 -> 4964.6202 | J4: =((Submetering!AG5+Submetering!BA5)*0.8868+(1712.96+1070.52)/30+(Submetering!AF5+Submetering!AY5+Submetering!AV5+Submetering!AZ5)*1.1251+(2076.11+129.67+207.57+207.57)/30+(11680.53+56.61)/30)/I4 -> 1.2282165 | K4: =Elect!C7 -> 2711
A5: Orlando | B5: 26 | C5: 1 | D5: 2020 | E5: =Submetering!F6+Submetering!H6+Submetering!J6+Submetering!L6+Submetering!N6+Submetering!P6+Submetering!R6+Submetering!T6+Submetering!V6+Submetering!X6+Submetering!Z6+Submetering!AB6+Submetering!AC6+Submetering!AD6+Submetering!AE6 -> 294986.72 | F5: =((((Submetering!E6+Submetering!AD6)*0.13773+(Submetering!E6+Submetering!AD6)*0.02095)*1.09+(2.85/30)*2)+(((Submetering!F6+Submetering!H6+Submetering!J6+Submetering!L6+Submetering!N6+Submetering!P6+Submetering!R6+Submetering!T6+Submetering!V6+Submetering!X6+Submetering!Z6+Submetering!AB6+Submetering!AC6+Submetering!AE6)*0.05155)+((Submetering!F6+Submetering!H6+Submetering!J6+Submetering!L6+Submetering!N6+Submetering!P6+Submetering!R6+Submetering!T6+Submetering!V6+Submetering!X6+Submetering!Z6+Submetering!AB6+Submetering!AC6+Submetering!AE6)*0.02095)+(20/30)*15)*1.1048)/E5 -> 0.081132867 | G5: =Submetering!AK6+Submetering!AL6+Submetering!AU6 -> 5892.812 | H5: 0.8166 | I5: =Submetering!AF6+Submetering!AG6+Submetering!AV6+Submetering!AY6+Submetering!AZ6 -> 3892.3628 | J5: =((Submetering!AG6+Submetering!BA6)*0.8868+(1712.96+1070.52)/30+(Submetering!AF6+Submetering!AY6+Submetering!AV6+Submetering!AZ6)*1.1251+(2076.11+129.67+207.57+207.57)/30+(11680.53+56.61)/30)/I5 -> 1.3551613 | K5: =Elect!C8 -> 2551
A6: Orlando | B6: 31 | C6: 1 | D6: 2020 | E6: =Submetering!F7+Submetering!H7+Submetering!J7+Submetering!L7+Submetering!N7+Submetering!P7+Submetering!R7+Submetering!T7+Submetering!V7+Submetering!X7+Submetering!Z7+Submetering!AB7+Submetering!AC7+Submetering!AD7+Submetering!AE7 -> 295079.86 | F6: =((((Submetering!E7+Submetering!AD7)*0.13773+(Submetering!E7+Submetering!AD7)*0.02095)*1.09+(2.85/30)*2)+(((Submetering!F7+Submetering!H7+Submetering!J7+Submetering!L7+Submetering!N7+Submetering!P7+Submetering!R7+Submetering!T7+Submetering!V7+Submetering!X7+Submetering!Z7+Submetering!AB7+Submetering!AC7+Submetering!AE7)*0.05155)+((Submetering!F7+Submetering!H7+Submetering!J7+Submetering!L7+Submetering!N7+Submetering!P7+Submetering!R7+Submetering!T7+Submetering!V7+Submetering!X7+Submetering!Z7+Submetering!AB7+Submetering!AC7+Submetering!AE7)*0.02095)+(20/30)*15)*1.1048)/E6 -> 0.081109289 | G6: =Submetering!AK7+Submetering!AL7+Submetering!AU7 -> 6048.2434 | H6: 0.8166 | I6: =Submetering!AF7+Submetering!AG7+Submetering!AV7+Submetering!AY7+Submetering!AZ7 -> 5210.9666 | J6: =((Submetering!AG7+Submetering!BA7)*0.8868+(1712.96+1070.52)/30+(Submetering!AF7+Submetering!AY7+Submetering!AV7+Submetering!AZ7)*1.1251+(2076.11+129.67+207.57+207.57)/30+(11680.53+56.61)/30)/I6 -> 1.2567467 | K6: =Elect!C9 -> 2016
A7: Orlando | B7: 9 | C7: 2 | D7: 2020 | E7: =Submetering!F8+Submetering!H8+Submetering!J8+Submetering!L8+Submetering!N8+Submetering!P8+Submetering!R8+Submetering!T8+Submetering!V8+Submetering!X8+Submetering!Z8+Submetering!AB8+Submetering!AC8+Submetering!AD8+Submetering!AE8 -> 301467.82 | F7: =((((Submetering!E8+Submetering!AD8)*0.13773+(Submetering!E8+Submetering!AD8)*0.02095)*1.09+(2.85/30)*2)+(((Submetering!F8+Submetering!H8+Submetering!J8+Submetering!L8+Submetering!N8+Submetering!P8+Submetering!R8+Submetering!T8+Submetering!V8+Submetering!X8+Submetering!Z8+Submetering!AB8+Submetering!AC8+Submetering!AE8)*0.05155)+((Submetering!F8+Submetering!H8+Submetering!J8+Submetering!L8+Submetering!N8+Submetering!P8+Submetering!R8+Submetering!T8+Submetering!V8+Submetering!X8+Submetering!Z8+Submetering!AB8+Submetering!AC8+Submetering!AE8)*0.02095)+(20/30)*15)*1.1048)/E7 -> 0.081053246 | G7: =Submetering!AK8+Submetering!AL8+Submetering!AU8 -> 7739.08 | H7: 0.8166 | I7: =Submetering!AF8+Submetering!AG8+Submetering!AV8+Submetering!AY8+Submetering!AZ8 -> 4719.961 | J7: =((Submetering!AG8+Submetering!BA8)*0.8868+(1712.96+1070.52)/30+(Submetering!AF8+Submetering!AY8+Submetering!AV8+Submetering!AZ8)*1.1251+(2076.11+129.67+207.57+207.57)/30+(11680.53+56.61)/30)/I7 -> 1.2544278 | K7: =Elect!C10 -> 2858
A8: Orlando | B8: 16 | C8: 2 | D8: 2020 | E8: =Submetering!F9+Submetering!H9+Submetering!J9+Submetering!L9+Submetering!N9+Submetering!P9+Submetering!R9+Submetering!T9+Submetering!V9+Submetering!X9+Submetering!Z9+Submetering!AB9+Submetering!AC9+Submetering!AD9+Submetering!AE9 -> 304149.82 | F8: =((((Submetering!E9+Submetering!AD9)*0.13773+(Submetering!E9+Submetering!AD9)*0.02095)*1.09+(2.85/30)*2)+(((Submetering!F9+Submetering!H9+Submetering!J9+Submetering!L9+Submetering!N9+Submetering!P9+Submetering!R9+Submetering!T9+Submetering!V9+Submetering!X9+Submetering!Z9+Submetering!AB9+Submetering!AC9+Submetering!AE9)*0.05155)+((Submetering!F9+Submetering!H9+Submetering!J9+Submetering!L9+Submetering!N9+Submetering!P9+Submetering!R9+Submetering!T9+Submetering!V9+Submetering!X9+Submetering!Z9+Submetering!AB9+Submetering!AC9+Submetering!AE9)*0.02095)+(20/30)*15)*1.1048)/E8 -> 0.081044823 | G8: =Submetering!AK9+Submetering!AL9+Submetering!AU9 -> 5602.9366 | H8: 0.8166 | I8: =Submetering!AF9+Submetering!AG9+Submetering!AV9+Submetering!AY9+Submetering!AZ9 -> 5358.646 | J8: =((Submetering!AG9+Submetering!BA9)*0.8868+(1712.96+1070.52)/30+(Submetering!AF9+Submetering!AY9+Submetering!AV9+Submetering!AZ9)*1.1251+(2076.11+129.67+207.57+207.57)/30+(11680.53+56.61)/30)/I8 -> 1.2857249 | K8: =Elect!C11 -> 2355
A9: Orlando | B9: 24 | C9: 2 | D9: 2020 | E9: =Submetering!F10+Submetering!H10+Submetering!J10+Submetering!L10+Submetering!N10+Submetering!P10+Submetering!R10+Submetering!T10+Submetering!V10+Submetering!X10+Submetering!Z10+Submetering!AB10+Submetering!AC10+Submetering!AD10+Submetering!AE10 -> 306313.62 | F9: =((((Submetering!E10+Submetering!AD10)*0.13773+(Submetering!E10+Submetering!AD10)*0.02095)*1.09+(2.85/30)*2)+(((Submetering!F10+Submetering!H10+Submetering!J10+Submetering!L10+Submetering!N10+Submetering!P10+Submetering!R10+Submetering!T10+Submetering!V10+Submetering!X10+Submetering!Z10+Submetering!AB10+Submetering!AC10+Submetering!AE10)*0.05155)+((Submetering!F10+Submetering!H10+Submetering!J10+Submetering!L10+Submetering!N10+Submetering!P10+Submetering!R10+Submetering!T10+Submetering!V10+Submetering!X10+Submetering!Z10+Submetering!AB10+Submetering!AC10+Submetering!AE10)*0.02095)+(20/30)*15)*1.1048)/E9 -> 0.081038134 | G9: =Submetering!AK10+Submetering!AL10+Submetering!AU10 -> 6087.22 | H9: 0.8166 | I9: =Submetering!AF10+Submetering!AG10+Submetering!AV10+Submetering!AY10+Submetering!AZ10 -> 5222.1652 | J9: =((Submetering!AG10+Submetering!BA10)*0.8868+(1712.96+1070.52)/30+(Submetering!AF10+Submetering!AY10+Submetering!AV10+Submetering!AZ10)*1.1251+(2076.11+129.67+207.57+207.57)/30+(11680.53+56.61)/30)/I9 -> 1.3733765 | K9: =Elect!C12 -> 3005
A10: Orlando | B10: 29 | C10: 2 | D10: 2020 | E10: =Submetering!F11+Submetering!H11+Submetering!J11+Submetering!L11+Submetering!N11+Submetering!P11+Submetering!R11+Submetering!T11+Submetering!V11+Submetering!X11+Submetering!Z11+Submetering!AB11+Submetering!AC11+Submetering!AD11+Submetering!AE11 -> 295146.41 | F10: =((((Submetering!E11+Submetering!AD11)*0.13773+(Submetering!E11+Submetering!AD11)*0.02095)*1.09+(2.85/30)*2)+(((Submetering!F11+Submetering!H11+Submetering!J11+Submetering!L11+Submetering!N11+Submetering!P11+Submetering!R11+Submetering!T11+Submetering!V11+Submetering!X11+Submetering!Z11+Submetering!AB11+Submetering!AC11+Submetering!AE11)*0.05155)+((Submetering!F11+Submetering!H11+Submetering!J11+Submetering!L11+Submetering!N11+Submetering!P11+Submetering!R11+Submetering!T11+Submetering!V11+Submetering!X11+Submetering!Z11+Submetering!AB11+Submetering!AC11+Submetering!AE11)*0.02095)+(20/30)*15)*1.1048)/E10 -> 0.081188591 | G10: =Submetering!AK11+Submetering!AL11+Submetering!AU11 -> 6370.7722 | H10: 0.8166 | I10: =Submetering!AF11+Submetering!AG11+Submetering!AV11+Submetering!AY11+Submetering!AZ11 -> 4390.0222 | J10: =((Submetering!AG11+Submetering!BA11)*0.8868+(1712.96+1070.52)/30+(Submetering!AF11+Submetering!AY11+Submetering!AV11+Submetering!AZ11)*1.1251+(2076.11+129.67+207.57+207.57)/30+(11680.53+56.61)/30)/I10 -> 1.417961 | K10: =Elect!C13 -> 1896
A11: Orlando | B11: 8 | C11: 3 | D11: 2020 | E11: =Submetering!F12+Submetering!H12+Submetering!J12+Submetering!L12+Submetering!N12+Submetering!P12+Submetering!R12+Submetering!T12+Submetering!V12+Submetering!X12+Submetering!Z12+Submetering!AB12+Submetering!AC12+Submetering!AD12+Submetering!AE12 -> 319308.89 | F11: =((((Submetering!E12+Submetering!AD12)*0.13773+(Submetering!E12+Submetering!AD12)*0.02095)*1.09+(2.85/30)*2)+(((Submetering!F12+Submetering!H12+Submetering!J12+Submetering!L12+Submetering!N12+Submetering!P12+Submetering!R12+Submetering!T12+Submetering!V12+Submetering!X12+Submetering!Z12+Submetering!AB12+Submetering!AC12+Submetering!AE12)*0.05155)+((Submetering!F12+Submetering!H12+Submetering!J12+Submetering!L12+Submetering!N12+Submetering!P12+Submetering!R12+Submetering!T12+Submetering!V12+Submetering!X12+Submetering!Z12+Submetering!AB12+Submetering!AC12+Submetering!AE12)*0.02095)+(20/30)*15)*1.1048)/E11 -> 0.08105404 | G11: =Submetering!AK12+Submetering!AL12+Submetering!AU12 -> 7051.736 | H11: 0.8166 | I11: =Submetering!AF12+Submetering!AG12+Submetering!AV12+Submetering!AY12+Submetering!AZ12 -> 5569.071 | J11: =((Submetering!AG12+Submetering!BA12)*0.8868+(1712.96+1070.52)/30+(Submetering!AF12+Submetering!AY12+Submetering!AV12+Submetering!AZ12)*1.1251+(2076.11+129.67+207.57+207.57)/30+(11680.53+56.61)/30)/I11 -> 1.3949611 | K11: =Elect!C14 -> 2040
A12: Orlando | B12: 15 | C12: 3 | D12: 2020 | E12: =Submetering!F13+Submetering!H13+Submetering!J13+Submetering!L13+Submetering!N13+Submetering!P13+Submetering!R13+Submetering!T13+Submetering!V13+Submetering!X13+Submetering!Z13+Submetering!AB13+Submetering!AC13+Submetering!AD13+Submetering!AE13 -> 303445.89 | F12: =((((Submetering!E13+Submetering!AD13)*0.13773+(Submetering!E13+Submetering!AD13)*0.02095)*1.09+(2.85/30)*2)+(((Submetering!F13+Submetering!H13+Submetering!J13+Submetering!L13+Submetering!N13+Submetering!P13+Submetering!R13+Submetering!T13+Submetering!V13+Submetering!X13+Submetering!Z13+Submetering!AB13+Submetering!AC13+Submetering!AE13)*0.05155)+((Submetering!F13+Submetering!H13+Submetering!J13+Submetering!L13+Submetering!N13+Submetering!P13+Submetering!R13+Submetering!T13+Submetering!V13+Submetering!X13+Submetering!Z13+Submetering!AB13+Submetering!AC13+Submetering!AE13)*0.02095)+(20/30)*15)*1.1048)/E12 -> 0.081104018 | G12: =Submetering!AK13+Submetering!AL13+Submetering!AU13 -> 4599.9266 | H12: 0.8166 | I12: =Submetering!AF13+Submetering!AG13+Submetering!AV13+Submetering!AY13+Submetering!AZ13 -> 5029.8776 | J12: =((Submetering!AG13+Submetering!BA13)*0.8868+(1712.96+1070.52)/30+(Submetering!AF13+Submetering!AY13+Submetering!AV13+Submetering!AZ13)*1.1251+(2076.11+129.67+207.57+207.57)/30+(11680.53+56.61)/30)/I12 -> 1.4323413 | K12: =Elect!C15 -> 1354
A13: Orlando | B13: 22 | C13: 3 | D13: 2020 | E13: =Submetering!F14+Submetering!H14+Submetering!J14+Submetering!L14+Submetering!N14+Submetering!P14+Submetering!R14+Submetering!T14+Submetering!V14+Submetering!X14+Submetering!Z14+Submetering!AB14+Submetering!AC14+Submetering!AD14+Submetering!AE14 -> 292921.33 | F13: =((((Submetering!E14+Submetering!AD14)*0.13773+(Submetering!E14+Submetering!AD14)*0.02095)*1.09+(2.85/30)*2)+(((Submetering!F14+Submetering!H14+Submetering!J14+Submetering!L14+Submetering!N14+Submetering!P14+Submetering!R14+Submetering!T14+Submetering!V14+Submetering!X14+Submetering!Z14+Submetering!AB14+Submetering!AC14+Submetering!AE14)*0.05155)+((Submetering!F14+Submetering!H14+Submetering!J14+Submetering!L14+Submetering!N14+Submetering!P14+Submetering!R14+Submetering!T14+Submetering!V14+Submetering!X14+Submetering!Z14+Submetering!AB14+Submetering!AC14+Submetering!AE14)*0.02095)+(20/30)*15)*1.1048)/E13 -> 0.081081117 | G13: =Submetering!AK14+Submetering!AL14+Submetering!AU14 -> 3333.36 | H13: 0.8166 | I13: =Submetering!AF14+Submetering!AG14+Submetering!AV14+Submetering!AY14+Submetering!AZ14 -> 4327.2234 | J13: =((Submetering!AG14+Submetering!BA14)*0.8868+(1712.96+1070.52)/30+(Submetering!AF14+Submetering!AY14+Submetering!AV14+Submetering!AZ14)*1.1251+(2076.11+129.67+207.57+207.57)/30+(11680.53+56.61)/30)/I13 -> 1.411974 | K13: =Elect!C16 -> 242
... A61: Orlando | B61: 31 | C61: 12 | D61: 2020 | E61: =Submetering!F62+Submetering!H62+Submetering!J62+Submetering!L62+Submetering!N62+Submetering!P62+Submetering!R62+Submetering!T62+Submetering!V62+Submetering!X62+Submetering!Z62+Submetering!AB62+Submetering!AC62+Submetering!AD62+Submetering!AE62 -> 0 | F61: =((((Submetering!E62+Submetering!AD62)*0.13773+(Submetering!E62+Submetering!AD62)*0.02095)*1.09+(2.85/30)*2)+(((Submetering!F62+Submetering!H62+Submetering!J62+Submetering!L62+Submetering!N62+Submetering!P62+Submetering!R62+Submetering!T62+Submetering!V62+Submetering!X62+Submetering!Z62+Submetering!AB62+Submetering!AC62+Submetering!AE62)*0.05155)+((Submetering!F62+Submetering!H62+Submetering!J62+Submetering!L62+Submetering!N62+Submetering!P62+Submetering!R62+Submetering!T62+Submetering!V62+Submetering!X62+Submetering!Z62+Submetering!AB62+Submetering!AC62+Submetering!AE62)*0.02095)+(20/30)*15)*1.1048)/E61 -> #DIV/0! | G61: =Submetering!AK62+Submetering!AL62+Submetering!AU62 -> 4024.067 | H61: 0.8166 | I61: =Submetering!AF62+Submetering!AG62+Submetering!AV62+Submetering!AY62+Submetering!AZ62 -> 2789.9334 | J61: =((Submetering!AG62+Submetering!BA62)*0.8868+(1712.96+1070.52)/30+(Submetering!AF62+Submetering!AY62+Submetering!AV62+Submetering!AZ62)*1.1251+(2076.11+129.67+207.57+207.57)/30+(11680.53+56.61)/30)/I61 -> 1.32208 | K61: =Elect!C64 -> 563

Sheet Submetering
A1: Site Name | B1: Day | C1: Month | D1: Year | E1: 90 630 431 (KWh) | F1: 68 425 010 (KWh) | G1: T2392 (KWh) | H1: 68 425 008 (KWh) | I1: T7384 (KWh) | J1: 68 425 060 (KWh) | K1: T7380 (KWh) | L1: 68 425 097 (KWh) | M1: T7281 (KWh) | N1: 68 425 059 (KWh) | O1: T2390 (KWh) | P1: 68 425 077 (KWh) | Q1: T2395 (KWh) | R1: 68 425 078 (KWh) | S1: T2393 (KWh) | T1: 68 425 071 (KWh) | U1: T7285 (KWh) | V1: 68 425 093 (KWh) | W1: T7382 (KWh) | X1: 68 425 094 (KWh) | Y1: T2391 (KWh) | Z1: 90 625 242 (KWh) | AA1: T7283 (KWh) | AB1: 672 73 163 (KWh) | AC1: 676 62 513 (KWh) | AD1: 61 979 920 (KWh) | AE1: 56 253 208 (KWh) | AF1: Domestic Water from RCES 74860172 (m3) | AG1: Re-use Water from RCES 74860173 (m3) | AH1: Building A Fire Sprinkler System Make-up 44553004 (m3) | AI1: Building A Potable Water Feed 70275191 (m3) | AJ1: Steam Boilers Make-up Water 2130521 (m3) | AK1: Resort Natural Gas Meter 12C004186-C1 (m3) | AL1: Out Buildings Natural Gas Meter 93477704 (m3) | AM1: Cooling Tower Make-up Water 79177804 (m3) | AN1: Cooling Tower Blowdown Line Deduct 79305675 (m3) | AO1: Building E Potable Water Meter 79190041 (m3) | AP1: 7919004D | AQ1: Building J Irrigation Water Meter 79190039 (m3) | AR1: Lazy Pool River Make-up Water 79324776 (m3) | AS1: Pool Hydraunic Boiler Water Make-up 112014001775 (m3) | AT1: SPA Jacuzzi Water Make-up 112014001771 (m3) | AU1: Golf Clubhouse Natural Gas Meter 82SJ729151 (m3) | AV1: 73337589 - 1387142 | AW1: Golf Clubhouse Flushing Valve Deduct 65956268 (m3) | AX1: Clubhouse | AY1: Golf Maintenance Facility 1334021 (m3) | AZ1: Golf Course Comfort Stations 63265094 (m3) | BA1: Golf Course Re-use Irrigation 67327447 (m3) | BB1: Room Nights
A2: Orlando | B2: 1 | C2: 1 | D2: 2020 | E2: =Elect!AX4 -> 0 | F2: =Elect!J4 -> 9749 | G2: =Elect!I4 -> 0 | H2: =Elect!F4 -> 0 | I2: =Elect!E4 -> 2.15 | J2: =Elect!Z4 -> 0.312 | K2: =Elect!Y4 -> 16096 | L2: =Elect!AT4 -> 43831 | M2: =Elect!AS4 -> 0 | N2: =Elect!AD4 -> 0 | O2: =Elect!AC4 -> 0.217 | P2: =Elect!R4 -> 0 | Q2: =Elect!Q4 -> 0.311 | R2: =Elect!N4 -> 0.271 | S2: =Elect!M4 -> 9644 | T2: =Elect!V4 -> 64573 | U2: =Elect!U4 -> 0 | V2: =Elect!AH4 -> 15574 | W2: =Elect!AG4 -> 0 | X2: =Elect!AL4 -> 0 | Y2: =Elect!AK4 -> 49414 | Z2: =Elect!AP4 -> 0 | AA2: =Elect!AO4 -> 0 | AB2: =Elect!BK4 -> 49414 | AC2: =Elect!BH4 -> 0 | AD2: =Elect!BN4 -> 0 | AE2: =Elect!BQ4 -> 2.483 | AF2: ='Wtr-Gas'!E4 -> 0 | AG2: ='Wtr-Gas'!H4 -> 0 | AH2: ='Wtr-Gas'!K4 -> 0 | AI2: ='Wtr-Gas'!N4 -> 0 | AJ2: ='Wtr-Gas'!Q4 -> 0 | AK2: ='Wtr-Gas'!U4 -> 0 | AL2: ='Wtr-Gas'!X4 -> 0 | AM2: ='Wtr-Gas'!AB4 -> 0 | AN2: ='Wtr-Gas'!AD4 -> 0 | AO2: ='Wtr-Gas'!AF4 -> 0 | AP2: ='Wtr-Gas'!AH4 -> 0 | AQ2: ='Wtr-Gas'!AJ4 -> 0 | AR2: ='Wtr-Gas'!AL4 -> 0 | AS2: ='Wtr-Gas'!AN4 -> 0 | AT2: ='Wtr-Gas'!AP4 -> 0 | AU2: ='Wtr-Gas'!AT4 -> 0 | AV2: ='Wtr-Gas'!AW4 -> 0 | AW2: ='Wtr-Gas'!AY4 -> 0 | AX2: ='Wtr-Gas'!AZ4 -> 0 | AY2: ='Wtr-Gas'!BB4 -> 0 | AZ2: ='Wtr-Gas'!BD4 -> 0 | BA2: ='Wtr-Gas'!BF4 -> 0 | BB2: =Elect!C4 -> 0
A3: Orlando | B3: 5 | C3: 1 | D3: 2020 | E3: =Elect!AX5 -> 1300 | F3: =Elect!J5 -> 9777 | G3: =Elect!I5 -> 41600 | H3: =Elect!F5 -> 39200 | I3: =Elect!E5 -> 2.291 | J3: =Elect!Z5 -> 0.312 | K3: =Elect!Y5 -> 16123 | L3: =Elect!AT5 -> 43835 | M3: =Elect!AS5 -> 0 | N3: =Elect!AD5 -> 2720 | O3: =Elect!AC5 -> 0.278 | P3: =Elect!R5 -> 11200 | Q3: =Elect!Q5 -> 0.315 | R3: =Elect!N5 -> 0.286 | S3: =Elect!M5 -> 9669 | T3: =Elect!V5 -> 64685 | U3: =Elect!U5 -> 37800 | V3: =Elect!AH5 -> 15606 | W3: =Elect!AG5 -> 35400 | X3: =Elect!AL5 -> 342 | Y3: =Elect!AK5 -> 49756 | Z3: =Elect!AP5 -> 36680 | AA3: =Elect!AO5 -> 228662 | AB3: =Elect!BK5 -> 49756 | AC3: =Elect!BH5 -> 0 | AD3: =Elect!BN5 -> 0 | AE3: =Elect!BQ5 -> 0 | AF3: =('Wtr-Gas'!E5)*0.0038 -> 3089.97 | AG3: =('Wtr-Gas'!H5)*0.0038 -> 8.702 | AH3: ='Wtr-Gas'!K5*0.0038 -> 0.342 | AI3: ='Wtr-Gas'!N5*0.0038 -> 1907.6 | AJ3: ='Wtr-Gas'!Q5*0.0038 -> 49.78 | AK3: ='Wtr-Gas'!U5*0.0038 -> 739.48 | AL3: ='Wtr-Gas'!X5*0.0038 -> 4992.44 | AM3: ='Wtr-Gas'!AB5*0.0038 -> 4028 | AN3: ='Wtr-Gas'!AD5*0.0038 -> 853.83986 | AO3: ='Wtr-Gas'!AF5*0.0038 -> 0.684 | AP3: ='Wtr-Gas'!AH5*0.0038 -> 149.074 | AQ3: ='Wtr-Gas'!AJ5*0.0038 -> 46.0788 | AR3: ='Wtr-Gas'!AL5*0.0038 -> 106.4 | AS3: ='Wtr-Gas'!AN5*0.0038 -> 0 | AT3: ='Wtr-Gas'!AP5*0.0038 -> 15.2 | AU3: ='Wtr-Gas'!AT5*0.0038 -> 0.3838 | AV3: ='Wtr-Gas'!AW5*0.0038 -> 257.241 | AW3: ='Wtr-Gas'!AY5*0.0038 -> 213.38474 | AX3: ='Wtr-Gas'!AZ5*0.0038 -> 43.856256 | AY3: ='Wtr-Gas'!BB5*0.0038 -> 5.7 | AZ3: ='Wtr-Gas'!BD5*0.0038 -> 0.76 | BA3: ='Wtr-Gas'!BF5*0.0038 -> 23.8526 | BB3: =Elect!C5 -> 1437
A4: Orlando | B4: 12 | C4: 1 | D4: 2020 | E4: =Elect!AX6 -> 1800 | F4: =Elect!J6 -> 9807 | G4: =Elect!I6 -> 49920 | H4: =Elect!F6 -> 47360 | I4: =Elect!E6 -> 2.291 | J4: =Elect!Z6 -> 0.365 | K4: =Elect!Y6 -> 16161 | L4: =Elect!AT6 -> 43842 | M4: =Elect!AS6 -> 0 | N4: =Elect!AD6 -> 4320 | O4: =Elect!AC6 -> 0.31 | P4: =Elect!R6 -> 12400 | Q4: =Elect!Q6 -> 0.315 | R4: =Elect!N6 -> 0.286 | S4: =Elect!M6 -> 9698 | T4: =Elect!V6 -> 64833 | U4: =Elect!U6 -> 44700 | V4: =Elect!AH6 -> 15646 | W4: =Elect!AG6 -> 44400 | X4: =Elect!AL6 -> 468 | Y4: =Elect!AK6 -> 50224 | Z4: =Elect!AP6 -> 46000 | AA4: =Elect!AO6 -> 279248 | AB4: =Elect!BK6 -> 50224 | AC4: =Elect!BH6 -> 0 | AD4: =Elect!BN6 -> 0 | AE4: =Elect!BQ6 -> 0 | AF4: =('Wtr-Gas'!E6)*0.0038 -> 3315.196 | AG4: =('Wtr-Gas'!H6)*0.0038 -> 178.182 | AH4: ='Wtr-Gas'!K6*0.0038 -> 0.912 | AI4: ='Wtr-Gas'!N6*0.0038 -> 2420.6 | AJ4: ='Wtr-Gas'!Q6*0.0038 -> 14.06 | AK4: ='Wtr-Gas'!U6*0.0038 -> 791.92 | AL4: ='Wtr-Gas'!X6*0.0038 -> 6300.78 | AM4: ='Wtr-Gas'!AB6*0.0038 -> 5282 | AN4: ='Wtr-Gas'!AD6*0.0038 -> 1022.4424 | AO4: ='Wtr-Gas'!AF6*0.0038 -> 10.374 | AP4: ='Wtr-Gas'!AH6*0.0038 -> 355.262 | AQ4: ='Wtr-Gas'!AJ6*0.0038 -> 61.56 | AR4: ='Wtr-Gas'!AL6*0.0038 -> 243.2 | AS4: ='Wtr-Gas'!AN6*0.0038 -> 0 | AT4: ='Wtr-Gas'!AP6*0.0038 -> 21.66 | AU4: ='Wtr-Gas'!AT6*0.0038 -> 0.4256 | AV4: ='Wtr-Gas'!AW6*0.0038 -> 305.463 | AW4: ='Wtr-Gas'!AY6*0.0038 -> 248.8452 | AX4: ='Wtr-Gas'!AZ6*0.0038 -> 56.617796 | AY4: ='Wtr-Gas'!BB6*0.0038 -> 22.8 | AZ4: ='Wtr-Gas'!BD6*0.0038 -> 1.52 | BA4: ='Wtr-Gas'!BF6*0.0038 -> 28.519 | BB4: =Elect!C6 -> 1370
A5: Orlando | B5: 19 | C5: 1 | D5: 2020 | E5: =Elect!AX7 -> 2300 | F5: =Elect!J7 -> 9838 | G5: =Elect!I7 -> 49280 | H5: =Elect!F7 -> 47200 | I5: =Elect!E7 -> 2.291 | J5: =Elect!Z7 -> 0.384 | K5: =Elect!Y7 -> 16205 | L5: =Elect!AT7 -> 43849 | M5: =Elect!AS7 -> 0 | N5: =Elect!AD7 -> 5440 | O5: =Elect!AC7 -> 0.391 | P5: =Elect!R7 -> 12000 | Q5: =Elect!Q7 -> 0.315 | R5: =Elect!N7 -> 0.286 | S5: =Elect!M7 -> 9727 | T5: =Elect!V7 -> 65036 | U5: =Elect!U7 -> 51300 | V5: =Elect!AH7 -> 15687 | W5: =Elect!AG7 -> 47000 | X5: =Elect!AL7 -> 465 | Y5: =Elect!AK7 -> 50689 | Z5: =Elect!AP7 -> 48640 | AA5: =Elect!AO7 -> 306265 | AB5: =Elect!BK7 -> 50689 | AC5: =Elect!BH7 -> 0 | AD5: =Elect!BN7 -> 0 | AE5: =Elect!BQ7 -> 0 | AF5: =('Wtr-Gas'!E7)*0.0038 -> 4243.08 | AG5: =('Wtr-Gas'!H7)*0.0038 -> 352.792 | AH5: ='Wtr-Gas'!K7*0.0038 -> 2.584 | AI5: ='Wtr-Gas'!N7*0.0038 -> 3169.2 | AJ5: ='Wtr-Gas'!Q7*0.0038 -> 0 | AK5: ='Wtr-Gas'!U7*0.0038 -> 798.38 | AL5: ='Wtr-Gas'!X7*0.0038 -> 4453.98 | AM5: ='Wtr-Gas'!AB7*0.0038 -> 7220 | AN5: ='Wtr-Gas'!AD7*0.0038 -> 1653.2155 | AO5: ='Wtr-Gas'!AF7*0.0038 -> 5.662 | AP5: ='Wtr-Gas'!AH7*0.0038 -> 482.752 | AQ5: ='Wtr-Gas'!AJ7*0.0038 -> 62.8634 | AR5: ='Wtr-Gas'!AL7*0.0038 -> 205.2 | AS5: ='Wtr-Gas'!AN7*0.0038 -> 0 | AT5: ='Wtr-Gas'!AP7*0.0038 -> 22.42 | AU5: ='Wtr-Gas'!AT7*0.0038 -> 0.665 | AV5: ='Wtr-Gas'!AW7*0.0038 -> 347.8482 | AW5: ='Wtr-Gas'!AY7*0.0038 -> 244.72 | AX5: ='Wtr-Gas'!AZ7*0.0038 -> 103.1282 | AY5: ='Wtr-Gas'!BB7*0.0038 -> 16.72 | AZ5: ='Wtr-Gas'!BD7*0.0038 -> 4.18 | BA5: ='Wtr-Gas'!BF7*0.0038 -> 27.7628 | BB5: =Elect!C7 -> 2711
A6: Orlando | B6: 26 | C6: 1 | D6: 2020 | E6: =Elect!AX8 -> 1700 | F6: =Elect!J8 -> 9878 | G6: =Elect!I8 -> 52000 | H6: =Elect!F8 -> 47840 | I6: =Elect!E8 -> 2.163 | J6: =Elect!Z8 -> 0.389 | K6: =Elect!Y8 -> 16250 | L6: =Elect!AT8 -> 43856 | M6: =Elect!AS8 -> 0 | N6: =Elect!AD8 -> 5920 | O6: =Elect!AC8 -> 0.451 | P6: =Elect!R8 -> 15200 | Q6: =Elect!Q8 -> 0.4 | R6: =Elect!N8 -> 0.333 | S6: =Elect!M8 -> 9762 | T6: =Elect!V8 -> 65146 | U6: =Elect!U8 -> 38100 | V6: =Elect!AH8 -> 15727 | W6: =Elect!AG8 -> 38200 | X6: =Elect!AL8 -> 465 | Y6: =Elect!AK8 -> 51154 | Z6: =Elect!AP8 -> 39800 | AA6: =Elect!AO8 -> 269525 | AB6: =Elect!BK8 -> 51154 | AC6: =Elect!BH8 -> 0 | AD6: =Elect!BN8 -> 0 | AE6: =Elect!BQ8 -> 0 | AF6: =('Wtr-Gas'!E8)*0.0038 -> 3487.83 | AG6: =('Wtr-Gas'!H8)*0.0038 -> 16.264 | AH6: ='Wtr-Gas'!K8*0.0038 -> 0.912 | AI6: ='Wtr-Gas'!N8*0.0038 -> 2796.8 | AJ6: ='Wtr-Gas'!Q8*0.0038 -> 0 | AK6: ='Wtr-Gas'!U8*0.0038 -> 971.28 | AL6: ='Wtr-Gas'!X8*0.0038 -> 4921 | AM6: ='Wtr-Gas'!AB8*0.0038 -> 2926 | AN6: ='Wtr-Gas'!AD8*0.0038 -> 680.7586 | AO6: ='Wtr-Gas'!AF8*0.0038 -> 4.408 | AP6: ='Wtr-Gas'!AH8*0.0038 -> 214.738 | AQ6: ='Wtr-Gas'!AJ8*0.0038 -> 65.3334 | AR6: ='Wtr-Gas'!AL8*0.0038 -> 11.4 | AS6: ='Wtr-Gas'!AN8*0.0038 -> 3.8 | AT6: ='Wtr-Gas'!AP8*0.0038 -> 19.76 | AU6: ='Wtr-Gas'!AT8*0.0038 -> 0.532 | AV6: ='Wtr-Gas'!AW8*0.0038 -> 298.2088 | AW6: ='Wtr-Gas'!AY8*0.0038 -> 246.51383 | AX6: ='Wtr-Gas'!AZ8*0.0038 -> 51.694972 | AY6: ='Wtr-Gas'!BB8*0.0038 -> 11.4 | AZ6: ='Wtr-Gas'!BD8*0.0038 -> 78.66 | BA6: ='Wtr-Gas'!BF8*0.0038 -> 369.8388 | BB6: =Elect!C8 -> 2551
A7: Orlando | B7: 1 | C7: 2 | D7: 2020 | E7: =Elect!AX9 -> 1500 | F7: =Elect!J9 -> 9914 | G7: =Elect!I9 -> 49600 | H7: =Elect!F9 -> 47680 | I7: =Elect!E9 -> 2.163 | J7: =Elect!Z9 -> 0.415 | K7: =Elect!Y9 -> 16293 | L7: =Elect!AT9 -> 43862 | M7: =Elect!AS9 -> 0 | N7: =Elect!AD9 -> 4960 | O7: =Elect!AC9 -> 0.451 | P7: =Elect!R9 -> 13200 | Q7: =Elect!Q9 -> 0.4 | R7: =Elect!N9 -> 0.333 | S7: =Elect!M9 -> 9793 | T7: =Elect!V9 -> 65273 | U7: =Elect!U9 -> 34200 | V7: =Elect!AH9 -> 15763 | W7: =Elect!AG9 -> 40600 | X7: =Elect!AL9 -> 466 | Y7: =Elect!AK9 -> 51620 | Z7: =Elect!AP9 -> 42040 | AA7: =Elect!AO9 -> 263926 | AB7: =Elect!BK9 -> 51620 | AC7: =Elect!BH9 -> 0 | AD7: =Elect!BN9 -> 298.62484 | AE7: =Elect!BQ9 -> 2.483 | AF7: =('Wtr-Gas'!E9)*0.0038 -> 4612.06 | AG7: =('Wtr-Gas'!H9)*0.0038 -> 280.022 | AH7: ='Wtr-Gas'!K9*0.0038 -> 1.026 | AI7: ='Wtr-Gas'!N9*0.0038 -> 2686.6 | AJ7: ='Wtr-Gas'!Q9*0.0038 -> 0 | AK7: ='Wtr-Gas'!U9*0.0038 -> 886.16 | AL7: ='Wtr-Gas'!X9*0.0038 -> 5161.54 | AM7: ='Wtr-Gas'!AB9*0.0038 -> 3344 | AN7: ='Wtr-Gas'!AD9*0.0038 -> 772.88428 | AO7: ='Wtr-Gas'!AF9*0.0038 -> 28.462 | AP7: ='Wtr-Gas'!AH9*0.0038 -> 468.996 | AQ7: ='Wtr-Gas'!AJ9*0.0038 -> 61.0318 | AR7: ='Wtr-Gas'!AL9*0.0038 -> 216.6 | AS7: ='Wtr-Gas'!AN9*0.0038 -> 0 | AT7: ='Wtr-Gas'!AP9*0.0038 -> 14.82 | AU7: ='Wtr-Gas'!AT9*0.0038 -> 0.5434 | AV7: ='Wtr-Gas'!AW9*0.0038 -> 307.4846 | AW7: ='Wtr-Gas'!AY9*0.0038 -> 246.53021 | AX7: ='Wtr-Gas'!AZ9*0.0038 -> 60.954394 | AY7: ='Wtr-Gas'!BB9*0.0038 -> 6.46 | AZ7: ='Wtr-Gas'!BD9*0.0038 -> 4.94 | BA7: ='Wtr-Gas'!BF9*0.0038 -> 204.5008 | BB7: =Elect!C9 -> 2016
A8: Orlando | B8: 9 | C8: 2 | D8: 2020 | E8: =Elect!AX10 -> 1600 | F8: =Elect!J10 -> 9949 | G8: =Elect!I10 -> 48960 | H8: =Elect!F10 -> 47360 | I8: =Elect!E10 -> 2.163 | J8: =Elect!Z10 -> 0.491 | K8: =Elect!Y10 -> 16339 | L8: =Elect!AT10 -> 43870 | M8: =Elect!AS10 -> 0 | N8: =Elect!AD10 -> 5280 | O8: =Elect!AC10 -> 0.451 | P8: =Elect!R10 -> 12800 | Q8: =Elect!Q10 -> 0.4 | R8: =Elect!N10 -> 0.333 | S8: =Elect!M10 -> 9825 | T8: =Elect!V10 -> 65431 | U8: =Elect!U10 -> 42300 | V8: =Elect!AH10 -> 15809 | W8: =Elect!AG10 -> 46600 | X8: =Elect!AL10 -> 454 | Y8: =Elect!AK10 -> 52074 | Z8: =Elect!AP10 -> 48440 | AA8: =Elect!AO10 -> 287154 | AB8: =Elect!BK10 -> 52074 | AC8: =Elect!BH10 -> 0 | AD8: =Elect!BN10 -> 0 | AE8: =Elect!BQ10 -> 0 | AF8: =('Wtr-Gas'!E10)*0.0038 -> 4104.038 | AG8: =('Wtr-Gas'!H10)*0.0038 -> 302.404 | AH8: ='Wtr-Gas'!K10*0.0038 -> 1.102 | AI8: ='Wtr-Gas'!N10*0.0038 -> 3078 | AJ8: ='Wtr-Gas'!Q10*0.0038 -> 0 | AK8: ='Wtr-Gas'!U10*0.0038 -> 887.68 | AL8: ='Wtr-Gas'!X10*0.0038 -> 6851.4 | AM8: ='Wtr-Gas'!AB10*0.0038 -> 4902 | AN8: ='Wtr-Gas'!AD10*0.0038 -> 1020.5979 | AO8: ='Wtr-Gas'!AF10*0.0038 -> 0.19 | AP8: ='Wtr-Gas'!AH10*0.0038 -> 494.722 | AQ8: ='Wtr-Gas'!AJ10*0.0038 -> 57.5016 | AR8: ='Wtr-Gas'!AL10*0.0038 -> 171 | AS8: ='Wtr-Gas'!AN10*0.0038 -> 0 | AT8: ='Wtr-Gas'!AP10*0.0038 -> 17.86 | AU8: ='Wtr-Gas'!AT10*0.0038 -> 0 | AV8: ='Wtr-Gas'!AW10*0.0038 -> 302.119 | AW8: ='Wtr-Gas'!AY10*0.0038 -> 247.51323 | AX8: ='Wtr-Gas'!AZ10*0.0038 -> 54.605772 | AY8: ='Wtr-Gas'!BB10*0.0038 -> 9.12 | AZ8: ='Wtr-Gas'!BD10*0.0038 -> 2.28 | BA8: ='Wtr-Gas'!BF10*0.0038 -> 125.2822 | BB8: =Elect!C10 -> 2858
A9: Orlando | B9: 16 | C9: 2 | D9: 2020 | E9: =Elect!AX11 -> 1600 | F9: =Elect!J11 -> 9979 | G9: =Elect!I11 -> 50240 | H9: =Elect!F11 -> 48320 | I9: =Elect!E11 -> 2.222 | J9: =Elect!Z11 -> 0.491 | K9: =Elect!Y11 -> 16381 | L9: =Elect!AT11 -> 43877 | M9: =Elect!AS11 -> 0 | N9: =Elect!AD11 -> 4800 | O9: =Elect!AC11 -> 0.451 | P9: =Elect!R11 -> 12000 | Q9: =Elect!Q11 -> 0.4 | R9: =Elect!N11 -> 0.333 | S9: =Elect!M11 -> 9854 | T9: =Elect!V11 -> 65604 | U9: =Elect!U11 -> 71700 | V9: =Elect!AH11 -> 15853 | W9: =Elect!AG11 -> 49000 | X9: =Elect!AL11 -> 441 | Y9: =Elect!AK11 -> 52515 | Z9: =Elect!AP11 -> 50760 | AA9: =Elect!AO11 -> 320481 | AB9: =Elect!BK11 -> 52515 | AC9: =Elect!BH11 -> 0 | AD9: =Elect!BN11 -> 0 | AE9: =Elect!BQ11 -> 0 | AF9: =('Wtr-Gas'!E11)*0.0038 -> 4611.756 | AG9: =('Wtr-Gas'!H11)*0.0038 -> 433.656 | AH9: ='Wtr-Gas'!K11*0.0038 -> 1.14 | AI9: ='Wtr-Gas'!N11*0.0038 -> 3515 | AJ9: ='Wtr-Gas'!Q11*0.0038 -> 0 | AK9: ='Wtr-Gas'!U11*0.0038 -> 879.32 | AL9: ='Wtr-Gas'!X11*0.0038 -> 4722.64 | AM9: ='Wtr-Gas'!AB11*0.0038 -> 8170 | AN9: ='Wtr-Gas'!AD11*0.0038 -> 2038.2011 | AO9: ='Wtr-Gas'!AF11*0.0038 -> 10.298 | AP9: ='Wtr-Gas'!AH11*0.0038 -> 526.224 | AQ9: ='Wtr-Gas'!AJ11*0.0038 -> 60.3478 | AR9: ='Wtr-Gas'!AL11*0.0038 -> 144.4 | AS9: ='Wtr-Gas'!AN11*0.0038 -> 3.8 | AT9: ='Wtr-Gas'!AP11*0.0038 -> 17.48 | AU9: ='Wtr-Gas'!AT11*0.0038 -> 0.9766 | AV9: ='Wtr-Gas'!AW11*0.0038 -> 301.454 | AW9: ='Wtr-Gas'!AY11*0.0038 -> 245.83614 | AX9: ='Wtr-Gas'!AZ11*0.0038 -> 55.617864 | AY9: ='Wtr-Gas'!BB11*0.0038 -> 10.26 | AZ9: ='Wtr-Gas'!BD11*0.0038 -> 1.52 | BA9: ='Wtr-Gas'!BF11*0.0038 -> 442.814 | BB9: =Elect!C11 -> 2355
A10: Orlando | B10: 24 | C10: 2 | D10: 2020 | E10: =Elect!AX12 -> 1600 | F10: =Elect!J12 -> 10014 | G10: =Elect!I12 -> 49760 | H10: =Elect!F12 -> 47520 | I10: =Elect!E12 -> 2.133 | J10: =Elect!Z12 -> 0.367 | K10: =Elect!Y12 -> 16435 | L10: =Elect!AT12 -> 43885 | M10: =Elect!AS12 -> 0 | N10: =Elect!AD12 -> 4960 | O10: =Elect!AC12 -> 0.289 | P10: =Elect!R12 -> 12800 | Q10: =Elect!Q12 -> 0.298 | R10: =Elect!N12 -> 0.254 | S10: =Elect!M12 -> 9885 | T10: =Elect!V12 -> 65797 | U10: =Elect!U12 -> 52500 | V10: =Elect!AH12 -> 15894 | W10: =Elect!AG12 -> 50400 | X10: =Elect!AL12 -> 444 | Y10: =Elect!AK12 -> 52959 | Z10: =Elect!AP12 -> 52040 | AA10: =Elect!AO12 -> 312964 | AB10: =Elect!BK12 -> 52959 | AC10: =Elect!BH12 -> 0 | AD10: =Elect!BN12 -> 0 | AE10: =Elect!BQ12 -> 0 | AF10: =('Wtr-Gas'!E12)*0.0038 -> 4560.304 | AG10: =('Wtr-Gas'!H12)*0.0038 -> 297.996 | AH10: ='Wtr-Gas'!K12*0.0038 -> 1.102 | AI10: ='Wtr-Gas'!N12*0.0038 -> 3484.6 | AJ10: ='Wtr-Gas'!Q12*0.0038 -> 0 | AK10: ='Wtr-Gas'!U12*0.0038 -> 959.88 | AL10: ='Wtr-Gas'!X12*0.0038 -> 5127.34 | AM10: ='Wtr-Gas'!AB12*0.0038 -> 6498 | AN10: ='Wtr-Gas'!AD12*0.0038 -> 1454.5568 | AO10: ='Wtr-Gas'!AF12*0.0038 -> 22.154 | AP10: ='Wtr-Gas'!AH12*0.0038 -> 514.178 | AQ10: ='Wtr-Gas'!AJ12*0.0038 -> 66.9712 | AR10: ='Wtr-Gas'!AL12*0.0038 -> 167.2 | AS10: ='Wtr-Gas'!AN12*0.0038 -> 0 | AT10: ='Wtr-Gas'!AP12*0.0038 -> 20.52 | AU10: ='Wtr-Gas'!AT12*0.0038 -> 0 | AV10: ='Wtr-Gas'!AW12*0.0038 -> 333.8452 | AW10: ='Wtr-Gas'!AY12*0.0038 -> 245.67125 | AX10: ='Wtr-Gas'!AZ12*0.0038 -> 88.173946 | AY10: ='Wtr-Gas'!BB12*0.0038 -> 4.56 | AZ10: ='Wtr-Gas'!BD12*0.0038 -> 25.46 | BA10: ='Wtr-Gas'!BF12*0.0038 -> 897.7994 | BB10: =Elect!C12 -> 3005
A11: Orlando | B11: 1 | C11: 3 | D11: 2020 | E11: =Elect!AX13 -> 1600 | F11: =Elect!J13 -> 10045 | G11: =Elect!I13 -> 44320 | H11: =Elect!F13 -> 43040 | I11: =Elect!E13 -> 2.33 | J11: =Elect!Z13 -> 0.511 | K11: =Elect!Y13 -> 16477 | L11: =Elect!AT13 -> 43891 | M11: =Elect!AS13 -> 0 | N11: =Elect!AD13 -> 4000 | O11: =Elect!AC13 -> 0.347 | P11: =Elect!R13 -> 11600 | Q11: =Elect!Q13 -> 0.298 | R11: =Elect!N13 -> 0.254 | S11: =Elect!M13 -> 9912 | T11: =Elect!V13 -> 65909 | U11: =Elect!U13 -> 42000 | V11: =Elect!AH13 -> 15930 | W11: =Elect!AG13 -> 45200 | X11: =Elect!AL13 -> 382 | Y11: =Elect!AK13 -> 53341 | Z11: =Elect!AP13 -> 46640 | AA11: =Elect!AO13 -> 255502 | AB11: =Elect!BK13 -> 53341 | AC11: =Elect!BH13 -> 0 | AD11: =Elect!BN13 -> 365.13879 | AE11: =Elect!BQ13 -> 2.506 | AF11: =('Wtr-Gas'!E13)*0.0038 -> 3675.094 | AG11: =('Wtr-Gas'!H13)*0.0038 -> 380.608 | AH11: ='Wtr-Gas'!K13*0.0038 -> 0.95 | AI11: ='Wtr-Gas'!N13*0.0038 -> 2796.8 | AJ11: ='Wtr-Gas'!Q13*0.0038 -> 0 | AK11: ='Wtr-Gas'!U13*0.0038 -> 826.88 | AL11: ='Wtr-Gas'!X13*0.0038 -> 5542.68 | AM11: ='Wtr-Gas'!AB13*0.0038 -> 3914 | AN11: ='Wtr-Gas'!AD13*0.0038 -> 937.31522 | AO11: ='Wtr-Gas'!AF13*0.0038 -> 0.266 | AP11: ='Wtr-Gas'!AH13*0.0038 -> 362.558 | AQ11: ='Wtr-Gas'!AJ13*0.0038 -> 58.558 | AR11: ='Wtr-Gas'!AL13*0.0038 -> 159.6 | AS11: ='Wtr-Gas'!AN13*0.0038 -> 3.8 | AT11: ='Wtr-Gas'!AP13*0.0038 -> 18.24 | AU11: ='Wtr-Gas'!AT13*0.0038 -> 1.2122 | AV11: ='Wtr-Gas'!AW13*0.0038 -> 306.9602 | AW11: ='Wtr-Gas'!AY13*0.0038 -> 245.38348 | AX11: ='Wtr-Gas'!AZ13*0.0038 -> 61.57672 | AY11: ='Wtr-Gas'!BB13*0.0038 -> 10.26 | AZ11: ='Wtr-Gas'!BD13*0.0038 -> 17.1 | BA11: ='Wtr-Gas'!BF13*0.0038 -> 907.7364 | BB11: =Elect!C13 -> 1896
A12: Orlando | B12: 8 | C12: 3 | D12: 2020 | E12: =Elect!AX14 -> 1700 | F12: =Elect!J14 -> 10079 | G12: =Elect!I14 -> 54880 | H12: =Elect!F14 -> 53440 | I12: =Elect!E14 -> 2.233 | J12: =Elect!Z14 -> 0.637 | K12: =Elect!Y14 -> 16538 | L12: =Elect!AT14 -> 43898 | M12: =Elect!AS14 -> 0 | N12: =Elect!AD14 -> 4960 | O12: =Elect!AC14 -> 0.347 | P12: =Elect!R14 -> 13600 | Q12: =Elect!Q14 -> 0.298 | R12: =Elect!N14 -> 0.254 | S12: =Elect!M14 -> 9945 | T12: =Elect!V14 -> 66075 | U12: =Elect!U14 -> 60000 | V12: =Elect!AH14 -> 15975 | W12: =Elect!AG14 -> 55200 | X12: =Elect!AL14 -> 470 | Y12: =Elect!AK14 -> 53811 | Z12: =Elect!AP14 -> 57000 | AA12: =Elect!AO14 -> 330710 | AB12: =Elect!BK14 -> 53811 | AC12: =Elect!BH14 -> 0 | AD12: =Elect!BN14 -> 0 | AE12: =Elect!BQ14 -> 0 | AF12: =('Wtr-Gas'!E14)*0.0038 -> 4845.608 | AG12: =('Wtr-Gas'!H14)*0.0038 -> 406.828 | AH12: ='Wtr-Gas'!K14*0.0038 -> 1.216 | AI12: ='Wtr-Gas'!N14*0.0038 -> 3632.8 | AJ12: ='Wtr-Gas'!Q14*0.0038 -> 0 | AK12: ='Wtr-Gas'!U14*0.0038 -> 1009.28 | AL12: ='Wtr-Gas'!X14*0.0038 -> 6042 | AM12: ='Wtr-Gas'!AB14*0.0038 -> 6422 | AN12: ='Wtr-Gas'!AD14*0.0038 -> 1258.4076 | AO12: ='Wtr-Gas'!AF14*0.0038 -> 7.524 | AP12: ='Wtr-Gas'!AH14*0.0038 -> 621.794 | AQ12: ='Wtr-Gas'!AJ14*0.0038 -> 81.795 | AR12: ='Wtr-Gas'!AL14*0.0038 -> 216.6 | AS12: ='Wtr-Gas'!AN14*0.0038 -> 0 | AT12: ='Wtr-Gas'!AP14*0.0038 -> 31.54 | AU12: ='Wtr-Gas'!AT14*0.0038 -> 0.456 | AV12: ='Wtr-Gas'!AW14*0.0038 -> 297.635 | AW12: ='Wtr-Gas'!AY14*0.0038 -> 243.73276 | AX12: ='Wtr-Gas'!AZ14*0.0038 -> 53.90224 | AY12: ='Wtr-Gas'!BB14*0.0038 -> 15.2 | AZ12: ='Wtr-Gas'!BD14*0.0038 -> 3.8 | BA12: ='Wtr-Gas'!BF14*0.0038 -> 1159.7182 | BB12: =Elect!C14 -> 2040
A13: Orlando | B13: 15 | C13: 3 | D13: 2020 | E13: =Elect!AX15 -> 1700 | F13: =Elect!J15 -> 10106 | G13: =Elect!I15 -> 47040 | H13: =Elect!F15 -> 46560 | I13: =Elect!E15 -> 2.233 | J13: =Elect!Z15 -> 0.637 | K13: =Elect!Y15 -> 16575 | L13: =Elect!AT15 -> 43905 | M13: =Elect!AS15 -> 0 | N13: =Elect!AD15 -> 4160 | O13: =Elect!AC15 -> 0.347 | P13: =Elect!R15 -> 11200 | Q13: =Elect!Q15 -> 0.298 | R13: =Elect!N15 -> 0.254 | S13: =Elect!M15 -> 9972 | T13: =Elect!V15 -> 66254 | U13: =Elect!U15 -> 50400 | V13: =Elect!AH15 -> 16015 | W13: =Elect!AG15 -> 49000 | X13: =Elect!AL15 -> 417 | Y13: =Elect!AK15 -> 54228 | Z13: =Elect!AP15 -> 50600 | AA13: =Elect!AO15 -> 291597 | AB13: =Elect!BK15 -> 54228 | AC13: =Elect!BH15 -> 0 | AD13: =Elect!BN15 -> 0 | AE13: =Elect!BQ15 -> 0 | AF13: =('Wtr-Gas'!E15)*0.0038 -> 4263.486 | AG13: =('Wtr-Gas'!H15)*0.0038 -> 438.9 | AH13: ='Wtr-Gas'!K15*0.0038 -> 1.064 | AI13: ='Wtr-Gas'!N15*0.0038 -> 3028.6 | AJ13: ='Wtr-Gas'!Q15*0.0038 -> 0 | AK13: ='Wtr-Gas'!U15*0.0038 -> 824.22 | AL13: ='Wtr-Gas'!X15*0.0038 -> 3775.3 | AM13: ='Wtr-Gas'!AB15*0.0038 -> 7182 | AN13: ='Wtr-Gas'!AD15*0.0038 -> 1528.9057 | AO13: ='Wtr-Gas'!AF15*0.0038 -> 8.816 | AP13: ='Wtr-Gas'!AH15*0.0038 -> 555.788 | AQ13: ='Wtr-Gas'!AJ15*0.0038 -> 80.693 | AR13: ='Wtr-Gas'!AL15*0.0038 -> 140.6 | AS13: ='Wtr-Gas'!AN15*0.0038 -> 0 | AT13: ='Wtr-Gas'!AP15*0.0038 -> 32.68 | AU13: ='Wtr-Gas'!AT15*0.0038 -> 0.4066 | AV13: ='Wtr-Gas'!AW15*0.0038 -> 296.3316 | AW13: ='Wtr-Gas'!AY15*0.0038 -> 244.17983 | AX13: ='Wtr-Gas'!AZ15*0.0038 -> 52.15177 | AY13: ='Wtr-Gas'!BB15*0.0038 -> 26.6 | AZ13: ='Wtr-Gas'!BD15*0.0038 -> 4.56 | BA13: ='Wtr-Gas'!BF15*0.0038 -> 1216.2736 | BB13: =Elect!C15 -> 1354
A14: Orlando | B14: 22 | C14: 3 | D14: 2020 | E14: =Elect!AX16 -> 1600 | F14: =Elect!J16 -> 10127 | G14: =Elect!I16 -> 41920 | H14: =Elect!F16 -> 41600 | I14: =Elect!E16 -> 1.536 | J14: =Elect!Z16 -> 0.212 | K14: =Elect!Y16 -> 16604 | L14: =Elect!AT16 -> 43912 | M14: =Elect!AS16 -> 0 | N14: =Elect!AD16 -> 2400 | O14: =Elect!AC16 -> 0.102 | P14: =Elect!R16 -> 8800 | Q14: =Elect!Q16 -> 0.111 | R14: =Elect!N16 -> 0.115 | S14: =Elect!M16 -> 9994 | T14: =Elect!V16 -> 66420 | U14: =Elect!U16 -> 54600 | V14: =Elect!AH16 -> 16054 | W14: =Elect!AG16 -> 47000 | X14: =Elect!AL16 -> 410 | Y14: =Elect!AK16 -> 54638 | Z14: =Elect!AP16 -> 48560 | AA14: =Elect!AO16 -> 269930 | AB14: =Elect!BK16 -> 54638 | AC14: =Elect!BH16 -> 0 | AD14: =Elect!BN16 -> 0 | AE14: =Elect!BQ16 -> 0 | AF14: =('Wtr-Gas'!E16)*0.0038 -> 3198.308 | AG14: =('Wtr-Gas'!H16)*0.0038 -> 824.296 | AH14: ='Wtr-Gas'!K16*0.0038 -> 1.026 | AI14: ='Wtr-Gas'!N16*0.0038 -> 1964.6 | AJ14: ='Wtr-Gas'!Q16*0.0038 -> 0 | AK14: ='Wtr-Gas'!U16*0.0038 -> 564.68 | AL14: ='Wtr-Gas'!X16*0.0038 -> 2768.68 | AM14: ='Wtr-Gas'!AB16*0.0038 -> 7638 | AN14: ='Wtr-Gas'!AD16*0.0038 -> 1680.8935 | AO14: ='Wtr-Gas'!AF16*0.0038 -> 29.222 | AP14: ='Wtr-Gas'!AH16*0.0038 -> 609.482 | AQ14: ='Wtr-Gas'!AJ16*0.0038 -> 70.1328 | AR14: ='Wtr-Gas'!AL16*0.0038 -> 136.8 | AS14: ='Wtr-Gas'!AN16*0.0038 -> 0 | AT14: ='Wtr-Gas'!AP16*0.0038 -> 25.84 | AU14: ='Wtr-Gas'!AT16*0.0038 -> 0 | AV14: ='Wtr-Gas'!AW16*0.0038 -> 287.5194 | AW14: ='Wtr-Gas'!AY16*0.0038 -> 240.82424 | AX14: ='Wtr-Gas'!AZ16*0.0038 -> 46.69516 | AY14: ='Wtr-Gas'!BB16*0.0038 -> 15.58 | AZ14: ='Wtr-Gas'!BD16*0.0038 -> 1.52 | BA14: ='Wtr-Gas'!BF16*0.0038 -> 977.0104 | BB14: =Elect!C16 -> 242
... A51: Orlando | B51: 1 | C51: 11 | D51: 2020 | E51: =Elect!AX53 -> 1500 | F51: =Elect!J53 -> 10661 | G51: =Elect!I53 -> 42880 | H51: =Elect!F53 -> 39040 | I51: =Elect!E53 -> 1.904 | J51: =Elect!Z53 -> 2.96 | K51: =Elect!Y53 -> 17536 | L51: =Elect!AT53 -> 44136 | M51: =Elect!AS53 -> 0 | N51: =Elect!AD53 -> 2400 | O51: =Elect!AC53 -> 1.69 | P51: =Elect!R53 -> 8000 | Q51: =Elect!Q53 -> 1.76 | R51: =Elect!N53 -> 1.51 | S51: =Elect!M53 -> 10581 | T51: =Elect!V53 -> 72352 | U51: =Elect!U53 -> 53700 | V51: =Elect!AH53 -> 17160 | W51: =Elect!AG53 -> 48000 | X51: =Elect!AL53 -> 504 | Y51: =Elect!AK53 -> 65767 | Z51: =Elect!AP53 -> 49600 | AA51: =Elect!AO53 -> 273864 | AB51: =Elect!BK53 -> 65767 | AC51: =Elect!BH53 -> 0 | AD51: =Elect!BN53 -> 0 | AE51: =Elect!BQ53 -> 0 | AF51: =('Wtr-Gas'!E53)*0.0038 -> 4066.418 | AG51: =('Wtr-Gas'!H53)*0.0038 -> 285.038 | AH51: ='Wtr-Gas'!K53*0.0038 -> 0.608 | AI51: ='Wtr-Gas'!N53*0.0038 -> 2576.4 | AJ51: ='Wtr-Gas'!Q53*0.0038 -> 83.6 | AK51: ='Wtr-Gas'!U53*0.0038 -> 644.86 | AL51: ='Wtr-Gas'!X53*0.0038 -> 2025.4 | AM51: ='Wtr-Gas'!AB53*0.0038 -> 9766 | AN51: ='Wtr-Gas'!AD53*0.0038 -> 3089.7709 | AO51: ='Wtr-Gas'!AF53*0.0038 -> 4.028 | AP51: ='Wtr-Gas'!AH53*0.0038 -> 706.762 | AQ51: ='Wtr-Gas'!AJ53*0.0038 -> 39.6872 | AR51: ='Wtr-Gas'!AL53*0.0038 -> 532 | AS51: ='Wtr-Gas'!AN53*0.0038 -> 3.8 | AT51: ='Wtr-Gas'!AP53*0.0038 -> 13.68 | AU51: ='Wtr-Gas'!AT53*0.0038 -> 0.437 | AV51: ='Wtr-Gas'!AW53*0.0038 -> 192.4434 | AW51: ='Wtr-Gas'!AY53*0.0038 -> 153.15759 | AX51: ='Wtr-Gas'!AZ53*0.0038 -> 39.285806 | AY51: ='Wtr-Gas'!BB53*0.0038 -> 20.9 | AZ51: ='Wtr-Gas'!BD53*0.0038 -> 2.66 | BA51: ='Wtr-Gas'!BF53*0.0038 -> 34.4318 | BB51: =Elect!C53 -> 502
A52: Orlando | B52: 2 | C52: 11 | D52: 2020 | E52: =Elect!AX55 -> 2000 | F52: =Elect!J55 -> 10681 | G52: =Elect!I55 -> 43200 | H52: =Elect!F55 -> 40000 | I52: =Elect!E55 -> 1.925 | J52: =Elect!Z55 -> 3.12 | K52: =Elect!Y55 -> 17570 | L52: =Elect!AT55 -> 44144 | M52: =Elect!AS55 -> 0 | N52: =Elect!AD55 -> 2560 | O52: =Elect!AC55 -> 1.69 | P52: =Elect!R55 -> 8000 | Q52: =Elect!Q55 -> 1.77 | R52: =Elect!N55 -> 1.63 | S52: =Elect!M55 -> 10603 | T52: =Elect!V55 -> 72468 | U52: =Elect!U55 -> 61500 | V52: =Elect!AH55 -> 17198 | W52: =Elect!AG55 -> 46000 | X52: =Elect!AL55 -> 504 | Y52: =Elect!AK55 -> 66271 | Z52: =Elect!AP55 -> 47520 | AA52: =Elect!AO55 -> 260324 | AB52: =Elect!BK55 -> 66271 | AC52: =Elect!BH55 -> 0 | AD52: =Elect!BN55 -> 0 | AE52: =Elect!BQ55 -> 0 | AF52: =('Wtr-Gas'!E54)*0.0038 -> 3543.234 | AG52: =('Wtr-Gas'!H54)*0.0038 -> 360.506 | AH52: ='Wtr-Gas'!K54*0.0038 -> 0.646 | AI52: ='Wtr-Gas'!N54*0.0038 -> 2302.8 | AJ52: ='Wtr-Gas'!Q54*0.0038 -> 68.02 | AK52: ='Wtr-Gas'!U54*0.0038 -> 590.14 | AL52: ='Wtr-Gas'!X54*0.0038 -> 2029.2 | AM52: ='Wtr-Gas'!AB54*0.0038 -> 8664 | AN52: ='Wtr-Gas'!AD54*0.0038 -> 2149.0866 | AO52: ='Wtr-Gas'!AF54*0.0038 -> 12.312 | AP52: ='Wtr-Gas'!AH54*0.0038 -> 391.894 | AQ52: ='Wtr-Gas'!AJ54*0.0038 -> 42.5752 | AR52: ='Wtr-Gas'!AL54*0.0038 -> 623.2 | AS52: ='Wtr-Gas'!AN54*0.0038 -> 0 | AT52: ='Wtr-Gas'!AP54*0.0038 -> 12.16 | AU52: ='Wtr-Gas'!AT54*0.0038 -> 0.2242 | AV52: ='Wtr-Gas'!AW54*0.0038 -> 164.8022 | AW52: ='Wtr-Gas'!AY54*0.0038 -> 137.69342 | AX52: ='Wtr-Gas'!AZ54*0.0038 -> 27.108782 | AY52: ='Wtr-Gas'!BB54*0.0038 -> 8.74 | AZ52: ='Wtr-Gas'!BD54*0.0038 -> 2.66 | BA52: ='Wtr-Gas'!BF54*0.0038 -> 370.1314 | BB52: =Elect!C55 -> 676
A53: Orlando | B53: 9 | C53: 11 | D53: 2020 | E53: =Elect!AX56 -> 1900 | F53: =Elect!J56 -> 10702 | G53: =Elect!I56 -> 43360 | H53: =Elect!F56 -> 39360 | I53: =Elect!E56 -> 1.925 | J53: =Elect!Z56 -> 3.12 | K53: =Elect!Y56 -> 17603 | L53: =Elect!AT56 -> 44151 | M53: =Elect!AS56 -> 0 | N53: =Elect!AD56 -> 2560 | O53: =Elect!AC56 -> 1.74 | P53: =Elect!R56 -> 8000 | Q53: =Elect!Q56 -> 1.77 | R53: =Elect!N56 -> 1.63 | S53: =Elect!M56 -> 10623 | T53: =Elect!V56 -> 72703 | U53: =Elect!U56 -> 53700 | V53: =Elect!AH56 -> 17236 | W53: =Elect!AG56 -> 49600 | X53: =Elect!AL56 -> 508 | Y53: =Elect!AK56 -> 66779 | Z53: =Elect!AP56 -> 51120 | AA53: =Elect!AO56 -> 290788 | AB53: =Elect!BK56 -> 0 | AC53: =Elect!BH56 -> 0 | AD53: =Elect!BN56 -> 0 | AE53: =Elect!BQ56 -> 0 | AF53: =('Wtr-Gas'!E55)*0.0038 -> 3290.306 | AG53: =('Wtr-Gas'!H55)*0.0038 -> 489.706 | AH53: ='Wtr-Gas'!K55*0.0038 -> 0.646 | AI53: ='Wtr-Gas'!N55*0.0038 -> 2048.2 | AJ53: ='Wtr-Gas'!Q55*0.0038 -> 68.78 | AK53: ='Wtr-Gas'!U55*0.0038 -> 659.3 | AL53: ='Wtr-Gas'!X55*0.0038 -> 4647.4 | AM53: ='Wtr-Gas'!AB55*0.0038 -> 5966 | AN53: ='Wtr-Gas'!AD55*0.0038 -> 680.51996 | AO53: ='Wtr-Gas'!AF55*0.0038 -> 4.902 | AP53: ='Wtr-Gas'!AH55*0.0038 -> 387.638 | AQ53: ='Wtr-Gas'!AJ55*0.0038 -> 37.2438 | AR53: ='Wtr-Gas'!AL55*0.0038 -> 668.8 | AS53: ='Wtr-Gas'!AN55*0.0038 -> 0 | AT53: ='Wtr-Gas'!AP55*0.0038 -> 3.42 | AU53: ='Wtr-Gas'!AT55*0.0038 -> 0.2774 | AV53: ='Wtr-Gas'!AW55*0.0038 -> 201.8142 | AW53: ='Wtr-Gas'!AY55*0.0038 -> 174.33982 | AX53: ='Wtr-Gas'!AZ55*0.0038 -> 27.47438 | AY53: ='Wtr-Gas'!BB55*0.0038 -> 6.46 | AZ53: ='Wtr-Gas'!BD55*0.0038 -> 3.42 | BA53: ='Wtr-Gas'!BF55*0.0038 -> 2219.352 | BB53: =Elect!C56 -> 684
A54: Orlando | B54: 16 | C54: 11 | D54: 2020 | E54: =Elect!AX57 -> 1500 | F54: =Elect!J57 -> 10724 | G54: =Elect!I57 -> 43840 | H54: =Elect!F57 -> 40320 | I54: =Elect!E57 -> 1.8 | J54: =Elect!Z57 -> 3.36 | K54: =Elect!Y57 -> 17639 | L54: =Elect!AT57 -> 44158 | M54: =Elect!AS57 -> 0 | N54: =Elect!AD57 -> 3040 | O54: =Elect!AC57 -> 1.45 | P54: =Elect!R57 -> 8400 | Q54: =Elect!Q57 -> 1.56 | R54: =Elect!N57 -> 1.65 | S54: =Elect!M57 -> 10645 | T54: =Elect!V57 -> 72856 | U54: =Elect!U57 -> 47400 | V54: =Elect!AH57 -> 17273 | W54: =Elect!AG57 -> 50400 | X54: =Elect!AL57 -> 525 | Y54: =Elect!AK57 -> 67304 | Z54: =Elect!AP57 -> 51880 | AA54: =Elect!AO57 -> 264665 | AB54: =Elect!BK57 -> 0 | AC54: =Elect!BH57 -> 0 | AD54: =Elect!BN57 -> 0 | AE54: =Elect!BQ57 -> 0 | AF54: =('Wtr-Gas'!E56)*0.0038 -> 3075.188 | AG54: =('Wtr-Gas'!H56)*0.0038 -> 237.994 | AH54: ='Wtr-Gas'!K56*0.0038 -> 0.646 | AI54: ='Wtr-Gas'!N56*0.0038 -> 2223 | AJ54: ='Wtr-Gas'!Q56*0.0038 -> 70.68 | AK54: ='Wtr-Gas'!U56*0.0038 -> 669.56 | AL54: ='Wtr-Gas'!X56*0.0038 -> 2663.8 | AM54: ='Wtr-Gas'!AB56*0.0038 -> 8550 | AN54: ='Wtr-Gas'!AD56*0.0038 -> 1967.8999 | AO54: ='Wtr-Gas'!AF56*0.0038 -> 1.216 | AP54: ='Wtr-Gas'!AH56*0.0038 -> 386.232 | AQ54: ='Wtr-Gas'!AJ56*0.0038 -> 14.7934 | AR54: ='Wtr-Gas'!AL56*0.0038 -> 345.8 | AS54: ='Wtr-Gas'!AN56*0.0038 -> -0.0152 | AT54: ='Wtr-Gas'!AP56*0.0038 -> 3.8 | AU54: ='Wtr-Gas'!AT56*0.0038 -> 0.3724 | AV54: ='Wtr-Gas'!AW56*0.0038 -> 211.0026 | AW54: ='Wtr-Gas'!AY56*0.0038 -> 175.5866 | AX54: ='Wtr-Gas'!AZ56*0.0038 -> 35.41714 | AY54: ='Wtr-Gas'!BB56*0.0038 -> 6.84 | AZ54: ='Wtr-Gas'!BD56*0.0038 -> 2.66 | BA54: ='Wtr-Gas'!BF56*0.0038 -> 35.2982 | BB54: =Elect!C57 -> 870
A55: Orlando | B55: 23 | C55: 11 | D55: 2020 | E55: =Elect!AX58 -> 1700 | F55: =Elect!J58 -> 10746 | G55: =Elect!I58 -> 45120 | H55: =Elect!F58 -> 41920 | I55: =Elect!E58 -> 2.074 | J55: =Elect!Z58 -> 3.36 | K55: =Elect!Y58 -> 17670 | L55: =Elect!AT58 -> 44165 | M55: =Elect!AS58 -> 0 | N55: =Elect!AD58 -> 2560 | O55: =Elect!AC58 -> 1.6 | P55: =Elect!R58 -> 8400 | Q55: =Elect!Q58 -> 1.68 | R55: =Elect!N58 -> 1.92 | S55: =Elect!M58 -> 10670 | T55: =Elect!V58 -> 73038 | U55: =Elect!U58 -> 42900 | V55: =Elect!AH58 -> 17311 | W55: =Elect!AG58 -> 51000 | X55: =Elect!AL58 -> 530 | Y55: =Elect!AK58 -> 67834 | Z55: =Elect!AP58 -> 52520 | AA55: =Elect!AO58 -> 272310 | AB55: =Elect!BK58 -> 0 | AC55: =Elect!BH58 -> 0 | AD55: =Elect!BN58 -> 0 | AE55: =Elect!BQ58 -> 0 | AF55: =('Wtr-Gas'!E57)*0.0038 -> 3237.562 | AG55: =('Wtr-Gas'!H57)*0.0038 -> 434.834 | AH55: ='Wtr-Gas'!K57*0.0038 -> 0.608 | AI55: ='Wtr-Gas'!N57*0.0038 -> 2124.2 | AJ55: ='Wtr-Gas'!Q57*0.0038 -> 75.62 | AK55: ='Wtr-Gas'!U57*0.0038 -> 745.18 | AL55: ='Wtr-Gas'!X57*0.0038 -> 4883 | AM55: ='Wtr-Gas'!AB57*0.0038 -> 6308 | AN55: ='Wtr-Gas'!AD57*0.0038 -> 1282.0866 | AO55: ='Wtr-Gas'!AF57*0.0038 -> 6.536 | AP55: ='Wtr-Gas'!AH57*0.0038 -> 367.65 | AQ55: ='Wtr-Gas'!AJ57*0.0038 -> 33.2234 | AR55: ='Wtr-Gas'!AL57*0.0038 -> 562.4 | AS55: ='Wtr-Gas'!AN57*0.0038 -> 0.1216 | AT55: ='Wtr-Gas'!AP57*0.0038 -> 14.44 | AU55: ='Wtr-Gas'!AT57*0.0038 -> 0.2926 | AV55: ='Wtr-Gas'!AW57*0.0038 -> 162.1802 | AW55: ='Wtr-Gas'!AY57*0.0038 -> 130.492 | AX55: ='Wtr-Gas'!AZ57*0.0038 -> 31.688998 | AY55: ='Wtr-Gas'!BB57*0.0038 -> 6.08 | AZ55: ='Wtr-Gas'!BD57*0.0038 -> 3.42 | BA55: ='Wtr-Gas'!BF57*0.0038 -> 27.0636 | BB55: =Elect!C58 -> 1156
A56: Orlando | B56: 30 | C56: 11 | D56: 2020 | E56: =Elect!AX59 -> 100 | F56: =Elect!J59 -> 10753 | G56: =Elect!I59 -> 13280 | H56: =Elect!F59 -> 12320 | I56: =Elect!E59 -> 2.074 | J56: =Elect!Z59 -> 3.36 | K56: =Elect!Y59 -> 17680 | L56: =Elect!AT59 -> 44166 | M56: =Elect!AS59 -> 0 | N56: =Elect!AD59 -> 800 | O56: =Elect!AC59 -> 2.3 | P56: =Elect!R59 -> 2400 | Q56: =Elect!Q59 -> 1.95 | R56: =Elect!N59 -> 1.95 | S56: =Elect!M59 -> 10677 | T56: =Elect!V59 -> 73081 | U56: =Elect!U59 -> 8100 | V56: =Elect!AH59 -> 17322 | W56: =Elect!AG59 -> 13400 | X56: =Elect!AL59 -> 193 | Y56: =Elect!AK59 -> 68027 | Z56: =Elect!AP59 -> 13840 | AA56: =Elect!AO59 -> 71033 | AB56: =Elect!BK59 -> 0 | AC56: =Elect!BH59 -> 0 | AD56: =Elect!BN59 -> 0 | AE56: =Elect!BQ59 -> 0 | AF56: =('Wtr-Gas'!E58)*0.0038 -> 3804.066 | AG56: =('Wtr-Gas'!H58)*0.0038 -> 414.732 | AH56: ='Wtr-Gas'!K58*0.0038 -> 0.646 | AI56: ='Wtr-Gas'!N58*0.0038 -> 2603 | AJ56: ='Wtr-Gas'!Q58*0.0038 -> 79.04 | AK56: ='Wtr-Gas'!U58*0.0038 -> 804.46 | AL56: ='Wtr-Gas'!X58*0.0038 -> 4078.54 | AM56: ='Wtr-Gas'!AB58*0.0038 -> 6726 | AN56: ='Wtr-Gas'!AD58*0.0038 -> 1393.2442 | AO56: ='Wtr-Gas'!AF58*0.0038 -> 12.008 | AP56: ='Wtr-Gas'!AH58*0.0038 -> 307.116 | AQ56: ='Wtr-Gas'!AJ58*0.0038 -> 38.855 | AR56: ='Wtr-Gas'!AL58*0.0038 -> 691.6 | AS56: ='Wtr-Gas'!AN58*0.0038 -> 2.1698 | AT56: ='Wtr-Gas'!AP58*0.0038 -> 6.46 | AU56: ='Wtr-Gas'!AT58*0.0038 -> 0.361 | AV56: ='Wtr-Gas'!AW58*0.0038 -> 190.5282 | AW56: ='Wtr-Gas'!AY58*0.0038 -> 151.4376 | AX56: ='Wtr-Gas'!AZ58*0.0038 -> 39.089118 | AY56: ='Wtr-Gas'!BB58*0.0038 -> 15.96 | AZ56: ='Wtr-Gas'!BD58*0.0038 -> 4.18 | BA56: ='Wtr-Gas'!BF58*0.0038 -> 588.164 | BB56: =Elect!C59 -> 46
A57: Orlando | B57: 1 | C57: 12 | D57: 2020 | E57: =Elect!AX60 -> 1300 | F57: =Elect!J60 -> 10771 | G57: =Elect!I60 -> 32160 | H57: =Elect!F60 -> 29920 | I57: =Elect!E60 -> 2.074 | J57: =Elect!Z60 -> 3.36 | K57: =Elect!Y60 -> 17705 | L57: =Elect!AT60 -> 44172 | M57: =Elect!AS60 -> 0 | N57: =Elect!AD60 -> 1920 | O57: =Elect!AC60 -> 2.3 | P57: =Elect!R60 -> 6800 | Q57: =Elect!Q60 -> 2.35 | R57: =Elect!N60 -> 2.23 | S57: =Elect!M60 -> 10696 | T57: =Elect!V60 -> 73171 | U57: =Elect!U60 -> 19200 | V57: =Elect!AH60 -> 17349 | W57: =Elect!AG60 -> 32200 | X57: =Elect!AL60 -> 474 | Y57: =Elect!AK60 -> 68501 | Z57: =Elect!AP60 -> 33280 | AA57: =Elect!AO60 -> 169554 | AB57: =Elect!BK60 -> 0 | AC57: =Elect!BH60 -> 0 | AD57: =Elect!BN60 -> 0 | AE57: =Elect!BQ60 -> 0 | AF57: =('Wtr-Gas'!E59)*0.0038 -> 916.142 | AG57: =('Wtr-Gas'!H59)*0.0038 -> 148.542 | AH57: ='Wtr-Gas'!K59*0.0038 -> 0.57 | AI57: ='Wtr-Gas'!N59*0.0038 -> 528.2 | AJ57: ='Wtr-Gas'!Q59*0.0038 -> 22.42 | AK57: ='Wtr-Gas'!U59*0.0038 -> 244.34 | AL57: ='Wtr-Gas'!X59*0.0038 -> 2404.26 | AM57: ='Wtr-Gas'!AB59*0.0038 -> 1178 | AN57: ='Wtr-Gas'!AD59*0.0038 -> 415.91076 | AO57: ='Wtr-Gas'!AF59*0.0038 -> 2.698 | AP57: ='Wtr-Gas'!AH59*0.0038 -> 95.076 | AQ57: ='Wtr-Gas'!AJ59*0.0038 -> 16.7542 | AR57: ='Wtr-Gas'!AL59*0.0038 -> 231.8 | AS57: ='Wtr-Gas'!AN59*0.0038 -> 0.494 | AT57: ='Wtr-Gas'!AP59*0.0038 -> 1.52 | AU57: ='Wtr-Gas'!AT59*0.0038 -> 0.038 | AV57: ='Wtr-Gas'!AW59*0.0038 -> 25.042 | AW57: ='Wtr-Gas'!AY59*0.0038 -> 22.382 | AX57: ='Wtr-Gas'!AZ59*0.0038 -> 2.659924 | AY57: ='Wtr-Gas'!BB59*0.0038 -> 0.38 | AZ57: ='Wtr-Gas'!BD59*0.0038 -> 0.76 | BA57: ='Wtr-Gas'!BF59*0.0038 -> 0 | BB57: =Elect!C60 -> 809
A58: Orlando | B58: 7 | C58: 12 | D58: 2020 | E58: =Elect!AX61 -> 1600 | F58: =Elect!J61 -> 10795 | G58: =Elect!I61 -> 43040 | H58: =Elect!F61 -> 40000 | I58: =Elect!E61 -> 2.074 | J58: =Elect!Z61 -> 3.36 | K58: =Elect!Y61 -> 17739 | L58: =Elect!AT61 -> 44179 | M58: =Elect!AS61 -> 0 | N58: =Elect!AD61 -> 2560 | O58: =Elect!AC61 -> 2.3 | P58: =Elect!R61 -> 8800 | Q58: =Elect!Q61 -> 3.45 | R58: =Elect!N61 -> 3.01 | S58: =Elect!M61 -> 10718 | T58: =Elect!V61 -> 73257 | U58: =Elect!U61 -> 35700 | V58: =Elect!AH61 -> 17389 | W58: =Elect!AG61 -> 43200 | X58: =Elect!AL61 -> 448 | Y58: =Elect!AK61 -> 68949 | Z58: =Elect!AP61 -> 44800 | AA58: =Elect!AO61 -> 224988 | AB58: =Elect!BK61 -> 0 | AC58: =Elect!BH61 -> 0 | AD58: =Elect!BN61 -> 0 | AE58: =Elect!BQ61 -> 0 | AF58: =('Wtr-Gas'!E60)*0.0038 -> 2299.304 | AG58: =('Wtr-Gas'!H60)*0.0038 -> 336.414 | AH58: ='Wtr-Gas'!K60*0.0038 -> 0.608 | AI58: ='Wtr-Gas'!N60*0.0038 -> 1402.2 | AJ58: ='Wtr-Gas'!Q60*0.0038 -> 54.34 | AK58: ='Wtr-Gas'!U60*0.0038 -> 572.28 | AL58: ='Wtr-Gas'!X60*0.0038 -> 4753.8 | AM58: ='Wtr-Gas'!AB60*0.0038 -> 2622 | AN58: ='Wtr-Gas'!AD60*0.0038 -> 669.96318 | AO58: ='Wtr-Gas'!AF60*0.0038 -> 4.522 | AP58: ='Wtr-Gas'!AH60*0.0038 -> 236.55 | AQ58: ='Wtr-Gas'!AJ60*0.0038 -> 27.5576 | AR58: ='Wtr-Gas'!AL60*0.0038 -> 497.8 | AS58: ='Wtr-Gas'!AN60*0.0038 -> 1.406 | AT58: ='Wtr-Gas'!AP60*0.0038 -> 3.04 | AU58: ='Wtr-Gas'!AT60*0.0038 -> 0.3724 | AV58: ='Wtr-Gas'!AW60*0.0038 -> 168.245 | AW58: ='Wtr-Gas'!AY60*0.0038 -> 130.4426 | AX58: ='Wtr-Gas'!AZ60*0.0038 -> 37.804034 | AY58: ='Wtr-Gas'!BB60*0.0038 -> 15.2 | AZ58: ='Wtr-Gas'!BD60*0.0038 -> 4.18 | BA58: ='Wtr-Gas'!BF60*0.0038 -> 599.203 | BB58: =Elect!C61 -> 1067
A59: Orlando | B59: 14 | C59: 12 | D59: 2020 | E59: =Elect!AX62 -> 1500 | F59: =Elect!J62 -> 10821 | G59: =Elect!I62 -> 44960 | H59: =Elect!F62 -> 39840 | I59: =Elect!E62 -> 2.074 | J59: =Elect!Z62 -> 3.36 | K59: =Elect!Y62 -> 17774 | L59: =Elect!AT62 -> 44186 | M59: =Elect!AS62 -> 0 | N59: =Elect!AD62 -> 2720 | O59: =Elect!AC62 -> 2.3 | P59: =Elect!R62 -> 9600 | Q59: =Elect!Q62 -> 3.45 | R59: =Elect!N62 -> 3.01 | S59: =Elect!M62 -> 10740 | T59: =Elect!V62 -> 73406 | U59: =Elect!U62 -> 31500 | V59: =Elect!AH62 -> 17420 | W59: =Elect!AG62 -> 45000 | X59: =Elect!AL62 -> 544 | Y59: =Elect!AK62 -> 69493 | Z59: =Elect!AP62 -> 46240 | AA59: =Elect!AO62 -> 244904 | AB59: =Elect!BK62 -> 0 | AC59: =Elect!BH62 -> 0 | AD59: =Elect!BN62 -> 0 | AE59: =Elect!BQ62 -> 0 | AF59: =('Wtr-Gas'!E61)*0.0038 -> 2861.856 | AG59: =('Wtr-Gas'!H61)*0.0038 -> 440.002 | AH59: ='Wtr-Gas'!K61*0.0038 -> 0.304 | AI59: ='Wtr-Gas'!N61*0.0038 -> 1729 | AJ59: ='Wtr-Gas'!Q61*0.0038 -> 75.62 | AK59: ='Wtr-Gas'!U61*0.0038 -> 758.1 | AL59: ='Wtr-Gas'!X61*0.0038 -> 6904.6 | AM59: ='Wtr-Gas'!AB61*0.0038 -> 3192 | AN59: ='Wtr-Gas'!AD61*0.0038 -> 1001.1921 | AO59: ='Wtr-Gas'!AF61*0.0038 -> 3.724 | AP59: ='Wtr-Gas'!AH61*0.0038 -> 231.648 | AQ59: ='Wtr-Gas'!AJ61*0.0038 -> 86.2334 | AR59: ='Wtr-Gas'!AL61*0.0038 -> 718.2 | AS59: ='Wtr-Gas'!AN61*0.0038 -> 0.2166 | AT59: ='Wtr-Gas'!AP61*0.0038 -> 4.18 | AU59: ='Wtr-Gas'!AT61*0.0038 -> 0.456 | AV59: ='Wtr-Gas'!AW61*0.0038 -> 190.2736 | AW59: ='Wtr-Gas'!AY61*0.0038 -> 152.6612 | AX59: ='Wtr-Gas'!AZ61*0.0038 -> 37.612362 | AY59: ='Wtr-Gas'!BB61*0.0038 -> 10.64 | AZ59: ='Wtr-Gas'!BD61*0.0038 -> 5.32 | BA59: ='Wtr-Gas'!BF61*0.0038 -> 0 | BB59: =Elect!C62 -> 757
A60: Orlando | B60: 21 | C60: 12 | D60: 2020 | E60: =Elect!AX63 -> 1600 | F60: =Elect!J63 -> 10852 | G60: =Elect!I63 -> 47360 | H60: =Elect!F63 -> 42560 | I60: =Elect!E63 -> 1.99 | J60: =Elect!Z63 -> 2.51 | K60: =Elect!Y63 -> 17806 | L60: =Elect!AT63 -> 44193 | M60: =Elect!AS63 -> 0 | N60: =Elect!AD63 -> 2400 | O60: =Elect!AC63 -> 1.54 | P60: =Elect!R63 -> 11200 | Q60: =Elect!Q63 -> 2.77 | R60: =Elect!N63 -> 2.48 | S60: =Elect!M63 -> 10769 | T60: =Elect!V63 -> 73488 | U60: =Elect!U63 -> 36900 | V60: =Elect!AH63 -> 17458 | W60: =Elect!AG63 -> 45400 | X60: =Elect!AL63 -> 562 | Y60: =Elect!AK63 -> 70055 | Z60: =Elect!AP63 -> 46920 | AA60: =Elect!AO63 -> 241622 | AB60: =Elect!BK63 -> 0 | AC60: =Elect!BH63 -> 0 | AD60: =Elect!BN63 -> 0 | AE60: =Elect!BQ63 -> 0 | AF60: =('Wtr-Gas'!E62)*0.0038 -> 3336.894 | AG60: =('Wtr-Gas'!H62)*0.0038 -> 548.34 | AH60: ='Wtr-Gas'!K62*0.0038 -> 0.836 | AI60: ='Wtr-Gas'!N62*0.0038 -> 1938 | AJ60: ='Wtr-Gas'!Q62*0.0038 -> 72.2 | AK60: ='Wtr-Gas'!U62*0.0038 -> 803.7 | AL60: ='Wtr-Gas'!X62*0.0038 -> 6140.8 | AM60: ='Wtr-Gas'!AB62*0.0038 -> 4256 | AN60: ='Wtr-Gas'!AD62*0.0038 -> 1000.0019 | AO60: ='Wtr-Gas'!AF62*0.0038 -> 8.322 | AP60: ='Wtr-Gas'!AH62*0.0038 -> 439.47 | AQ60: ='Wtr-Gas'!AJ62*0.0038 -> 49.4646 | AR60: ='Wtr-Gas'!AL62*0.0038 -> 729.6 | AS60: ='Wtr-Gas'!AN62*0.0038 -> 0.0798 | AT60: ='Wtr-Gas'!AP62*0.0038 -> 4.94 | AU60: ='Wtr-Gas'!AT62*0.0038 -> 0.4408 | AV60: ='Wtr-Gas'!AW62*0.0038 -> 188.8068 | AW60: ='Wtr-Gas'!AY62*0.0038 -> 153.4212 | AX60: ='Wtr-Gas'!AZ62*0.0038 -> 35.383776 | AY60: ='Wtr-Gas'!BB62*0.0038 -> 20.14 | AZ60: ='Wtr-Gas'!BD62*0.0038 -> 6.08 | BA60: ='Wtr-Gas'!BF62*0.0038 -> 267.9532 | BB60: =Elect!C63 -> 1353
A61: Orlando | B61: 28 | C61: 12 | D61: 2020 | E61: =Elect!AX64 -> 900 | F61: =Elect!J64 -> 10869 | G61: =Elect!I64 -> 26880 | H61: =Elect!F64 -> 23840 | I61: =Elect!E64 -> 1.99 | J61: =Elect!Z64 -> 2.56 | K61: =Elect!Y64 -> 17824 | L61: =Elect!AT64 -> 44197 | M61: =Elect!AS64 -> 0 | N61: =Elect!AD64 -> 1600 | O61: =Elect!AC64 -> 1.73 | P61: =Elect!R64 -> 5600 | Q61: =Elect!Q64 -> 2.77 | R61: =Elect!N64 -> 2.48 | S61: =Elect!M64 -> 10784 | T61: =Elect!V64 -> 73548 | U61: =Elect!U64 -> 28800 | V61: =Elect!AH64 -> 17476 | W61: =Elect!AG64 -> 30400 | X61: =Elect!AL64 -> 285 | Y61: =Elect!AK64 -> 70340 | Z61: =Elect!AP64 -> 31120 | AA61: =Elect!AO64 -> 151805 | AB61: =Elect!BK64 -> 0 | AC61: =Elect!BH64 -> 0 | AD61: =Elect!BN64 -> 0 | AE61: =Elect!BQ64 -> 0 | AF61: =('Wtr-Gas'!E63)*0.0038 -> 3607.302 | AG61: =('Wtr-Gas'!H63)*0.0038 -> 272.536 | AH61: ='Wtr-Gas'!K63*0.0038 -> 0.874 | AI61: ='Wtr-Gas'!N63*0.0038 -> 2348.4 | AJ61: ='Wtr-Gas'!Q63*0.0038 -> 71.06 | AK61: ='Wtr-Gas'!U63*0.0038 -> 889.58 | AL61: ='Wtr-Gas'!X63*0.0038 -> 7964.8 | AM61: ='Wtr-Gas'!AB63*0.0038 -> 3192 | AN61: ='Wtr-Gas'!AD63*0.0038 -> 1034.6021 | AO61: ='Wtr-Gas'!AF63*0.0038 -> 3.762 | AP61: ='Wtr-Gas'!AH63*0.0038 -> 311.296 | AQ61: ='Wtr-Gas'!AJ63*0.0038 -> 41.5454 | AR61: ='Wtr-Gas'!AL63*0.0038 -> 714.4 | AS61: ='Wtr-Gas'!AN63*0.0038 -> 0.0722 | AT61: ='Wtr-Gas'!AP63*0.0038 -> 4.18 | AU61: ='Wtr-Gas'!AT63*0.0038 -> 0.4978 | AV61: ='Wtr-Gas'!AW63*0.0038 -> 202.331 | AW61: ='Wtr-Gas'!AY63*0.0038 -> 153.8544 | AX61: ='Wtr-Gas'!AZ63*0.0038 -> 48.476106 | AY61: ='Wtr-Gas'!BB63*0.0038 -> 2.66 | AZ61: ='Wtr-Gas'!BD63*0.0038 -> 6.46 | BA61: ='Wtr-Gas'!BF63*0.0038 -> 0 | BB61: =Elect!C64 -> 563
