Workbook

Sheet TOTAL
A1: Site Name | B1: Day | C1: Month | D1: Year | E1: Total Electricity Kwh | F1: Electricity Tariff ($/Kwh) | G1: Natual Gas (m3) | H1: Natural Gas $/m3 | I1: Water Utility Supply (m3) m3 | J1: Water Utility Supply (m3) $/m3 | K1: Room Nights
A2: Orlando | B2: 4 | C2: 1 | D2: 2021 | E2: =Submetering!F3+Submetering!H3+Submetering!J3+Submetering!L3+Submetering!N3+Submetering!P3+Submetering!R3+Submetering!T3+Submetering!V3+Submetering!X3+Submetering!Z3+Submetering!AB3+Submetering!AC3+Submetering!AD3+Submetering!AE3 -> 139689 | F2: =((((Submetering!E3+Submetering!AD3)*0.13773+(Submetering!E3+Submetering!AD3)*0.02095)*1.09+(2.85/30)*2)+(((Submetering!F3+Submetering!H3+Submetering!J3+Submetering!L3+Submetering!N3+Submetering!P3+Submetering!R3+Submetering!T3+Submetering!V3+Submetering!X3+Submetering!Z3+Submetering!AB3+Submetering!AC3+Submetering!AE3)*0.05155)+((Submetering!F3+Submetering!H3+Submetering!J3+Submetering!L3+Submetering!N3+Submetering!P3+Submetering!R3+Submetering!T3+Submetering!V3+Submetering!X3+Submetering!Z3+Submetering!AB3+Submetering!AC3+Submetering!AE3)*0.02095)+(20/30)*15)*1.1048)/E2 -> 0.081080229 | G2: =Submetering!AK3+Submetering!AL3+Submetering!AU3 -> 2596.3234 | H2: 0.8166 | I2: =Submetering!AF3+Submetering!AG3+Submetering!AV3+Submetering!AY3+Submetering!AZ3 -> 3611.4706 | J2: =((Submetering!AG3+Submetering!BA3)*0.8868+(1712.96+1070.52)/30+(Submetering!AF3+Submetering!AY3+Submetering!AV3+Submetering!AZ3)*1.1251+(2076.11+129.67+207.57+207.57)/30+(11680.53+56.61)/30)/I2 -> 1.1862449 | K2: =Elect!C5 -> 756
A3: Orlando | B3: 11 | C3: 1 | D3: 2021 | E3: =Submetering!F4+Submetering!H4+Submetering!J4+Submetering!L4+Submetering!N4+Submetering!P4+Submetering!R4+Submetering!T4+Submetering!V4+Submetering!X4+Submetering!Z4+Submetering!AB4+Submetering!AC4+Submetering!AD4+Submetering!AE4 -> 240829 | F3: =((((Submetering!E4+Submetering!AD4)*0.13773+(Submetering!E4+Submetering!AD4)*0.02095)*1.09+(2.85/30)*2)+(((Submetering!F4+Submetering!H4+Submetering!J4+Submetering!L4+Submetering!N4+Submetering!P4+Submetering!R4+Submetering!T4+Submetering!V4+Submetering!X4+Submetering!Z4+Submetering!AB4+Submetering!AC4+Submetering!AE4)*0.05155)+((Submetering!F4+Submetering!H4+Submetering!J4+Submetering!L4+Submetering!N4+Submetering!P4+Submetering!R4+Submetering!T4+Submetering!V4+Submetering!X4+Submetering!Z4+Submetering!AB4+Submetering!AC4+Submetering!AE4)*0.02095)+(20/30)*15)*1.1048)/E3 -> 0.08089305 | G3: =Submetering!AK4+Submetering!AL4+Submetering!AU4 -> 8660.2798 | H3: 0.8166 | I3: =Submetering!AF4+Submetering!AG4+Submetering!AV4+Submetering!AY4+Submetering!AZ4 -> 4458.3348 | J3: =((Submetering!AG4+Submetering!BA4)*0.8868+(1712.96+1070.52)/30+(Submetering!AF4+Submetering!AY4+Submetering!AV4+Submetering!AZ4)*1.1251+(2076.11+129.67+207.57+207.57)/30+(11680.53+56.61)/30)/I3 -> 1.195494 | K3: =Elect!C6 -> 724
A4: Orlando | B4: 18 | C4: 1 | D4: 2021 | E4: =Submetering!F5+Submetering!H5+Submetering!J5+Submetering!L5+Submetering!N5+Submetering!P5+Submetering!R5+Submetering!T5+Submetering!V5+Submetering!X5+Submetering!Z5+Submetering!AB5+Submetering!AC5+Submetering!AD5+Submetering!AE5 -> 243403 | F4: =((((Submetering!E5+Submetering!AD5)*0.13773+(Submetering!E5+Submetering!AD5)*0.02095)*1.09+(2.85/30)*2)+(((Submetering!F5+Submetering!H5+Submetering!J5+Submetering!L5+Submetering!N5+Submetering!P5+Submetering!R5+Submetering!T5+Submetering!V5+Submetering!X5+Submetering!Z5+Submetering!AB5+Submetering!AC5+Submetering!AE5)*0.05155)+((Submetering!F5+Submetering!H5+Submetering!J5+Submetering!L5+Submetering!N5+Submetering!P5+Submetering!R5+Submetering!T5+Submetering!V5+Submetering!X5+Submetering!Z5+Submetering!AB5+Submetering!AC5+Submetering!AE5)*0.02095)+(20/30)*15)*1.1048)/E4 -> 0.080880684 | G4: =Submetering!AK5+Submetering!AL5+Submetering!AU5 -> 8077.7588 | H4: 0.8166 | I4: =Submetering!AF5+Submetering!AG5+Submetering!AV5+Submetering!AY5+Submetering!AZ5 -> 4406.3736 | J4: =((Submetering!AG5+Submetering!BA5)*0.8868+(1712.96+1070.52)/30+(Submetering!AF5+Submetering!AY5+Submetering!AV5+Submetering!AZ5)*1.1251+(2076.11+129.67+207.57+207.57)/30+(11680.53+56.61)/30)/I4 -> 1.2112628 | K4: =Elect!C7 -> 772
A5: Orlando | B5: 25 | C5: 1 | D5: 2021 | E5: =Submetering!F6+Submetering!H6+Submetering!J6+Submetering!L6+Submetering!N6+Submetering!P6+Submetering!R6+Submetering!T6+Submetering!V6+Submetering!X6+Submetering!Z6+Submetering!AB6+Submetering!AC6+Submetering!AD6+Submetering!AE6 -> 275379 | F5: =((((Submetering!E6+Submetering!AD6)*0.13773+(Submetering!E6+Submetering!AD6)*0.02095)*1.09+(2.85/30)*2)+(((Submetering!F6+Submetering!H6+Submetering!J6+Submetering!L6+Submetering!N6+Submetering!P6+Submetering!R6+Submetering!T6+Submetering!V6+Submetering!X6+Submetering!Z6+Submetering!AB6+Submetering!AC6+Submetering!AE6)*0.05155)+((Submetering!F6+Submetering!H6+Submetering!J6+Submetering!L6+Submetering!N6+Submetering!P6+Submetering!R6+Submetering!T6+Submetering!V6+Submetering!X6+Submetering!Z6+Submetering!AB6+Submetering!AC6+Submetering!AE6)*0.02095)+(20/30)*15)*1.1048)/E5 -> 0.080649402 | G5: =Submetering!AK6+Submetering!AL6+Submetering!AU6 -> 7589.8046 | H5: 0.8166 | I5: =Submetering!AF6+Submetering!AG6+Submetering!AV6+Submetering!AY6+Submetering!AZ6 -> 5141.9852 | J5: =((Submetering!AG6+Submetering!BA6)*0.8868+(1712.96+1070.52)/30+(Submetering!AF6+Submetering!AY6+Submetering!AV6+Submetering!AZ6)*1.1251+(2076.11+129.67+207.57+207.57)/30+(11680.53+56.61)/30)/I5 -> 1.1897873 | K5: =Elect!C8 -> 1454
A6: Orlando | B6: 31 | C6: 1 | D6: 2021 | E6: =Submetering!F7+Submetering!H7+Submetering!J7+Submetering!L7+Submetering!N7+Submetering!P7+Submetering!R7+Submetering!T7+Submetering!V7+Submetering!X7+Submetering!Z7+Submetering!AB7+Submetering!AC7+Submetering!AD7+Submetering!AE7 -> 262834 | F6: =((((Submetering!E7+Submetering!AD7)*0.13773+(Submetering!E7+Submetering!AD7)*0.02095)*1.09+(2.85/30)*2)+(((Submetering!F7+Submetering!H7+Submetering!J7+Submetering!L7+Submetering!N7+Submetering!P7+Submetering!R7+Submetering!T7+Submetering!V7+Submetering!X7+Submetering!Z7+Submetering!AB7+Submetering!AC7+Submetering!AE7)*0.05155)+((Submetering!F7+Submetering!H7+Submetering!J7+Submetering!L7+Submetering!N7+Submetering!P7+Submetering!R7+Submetering!T7+Submetering!V7+Submetering!X7+Submetering!Z7+Submetering!AB7+Submetering!AC7+Submetering!AE7)*0.02095)+(20/30)*15)*1.1048)/E6 -> 0.080859183 | G6: =Submetering!AK7+Submetering!AL7+Submetering!AU7 -> 6553.9132 | H6: 0.8166 | I6: =Submetering!AF7+Submetering!AG7+Submetering!AV7+Submetering!AY7+Submetering!AZ7 -> 4916.3944 | J6: =((Submetering!AG7+Submetering!BA7)*0.8868+(1712.96+1070.52)/30+(Submetering!AF7+Submetering!AY7+Submetering!AV7+Submetering!AZ7)*1.1251+(2076.11+129.67+207.57+207.57)/30+(11680.53+56.61)/30)/I6 -> 1.2039799 | K6: =Elect!C9 -> 591
A7: Orlando | B7: 8 | C7: 2 | D7: 2021 | E7: =Submetering!F8+Submetering!H8+Submetering!J8+Submetering!L8+Submetering!N8+Submetering!P8+Submetering!R8+Submetering!T8+Submetering!V8+Submetering!X8+Submetering!Z8+Submetering!AB8+Submetering!AC8+Submetering!AD8+Submetering!AE8 -> 244571 | F7: =((((Submetering!E8+Submetering!AD8)*0.13773+(Submetering!E8+Submetering!AD8)*0.02095)*1.09+(2.85/30)*2)+(((Submetering!F8+Submetering!H8+Submetering!J8+Submetering!L8+Submetering!N8+Submetering!P8+Submetering!R8+Submetering!T8+Submetering!V8+Submetering!X8+Submetering!Z8+Submetering!AB8+Submetering!AC8+Submetering!AE8)*0.05155)+((Submetering!F8+Submetering!H8+Submetering!J8+Submetering!L8+Submetering!N8+Submetering!P8+Submetering!R8+Submetering!T8+Submetering!V8+Submetering!X8+Submetering!Z8+Submetering!AB8+Submetering!AC8+Submetering!AE8)*0.02095)+(20/30)*15)*1.1048)/E7 -> 0.080975181 | G7: =Submetering!AK8+Submetering!AL8+Submetering!AU8 -> 7512.3606 | H7: 0.8166 | I7: =Submetering!AF8+Submetering!AG8+Submetering!AV8+Submetering!AY8+Submetering!AZ8 -> 4292.3356 | J7: =((Submetering!AG8+Submetering!BA8)*0.8868+(1712.96+1070.52)/30+(Submetering!AF8+Submetering!AY8+Submetering!AV8+Submetering!AZ8)*1.1251+(2076.11+129.67+207.57+207.57)/30+(11680.53+56.61)/30)/I7 -> 1.2192793 | K7: =Elect!C10 -> 748
A8: Orlando | B8: 15 | C8: 2 | D8: 2021 | E8: =Submetering!F9+Submetering!H9+Submetering!J9+Submetering!L9+Submetering!N9+Submetering!P9+Submetering!R9+Submetering!T9+Submetering!V9+Submetering!X9+Submetering!Z9+Submetering!AB9+Submetering!AC9+Submetering!AD9+Submetering!AE9 -> 294875 | F8: =((((Submetering!E9+Submetering!AD9)*0.13773+(Submetering!E9+Submetering!AD9)*0.02095)*1.09+(2.85/30)*2)+(((Submetering!F9+Submetering!H9+Submetering!J9+Submetering!L9+Submetering!N9+Submetering!P9+Submetering!R9+Submetering!T9+Submetering!V9+Submetering!X9+Submetering!Z9+Submetering!AB9+Submetering!AC9+Submetering!AE9)*0.05155)+((Submetering!F9+Submetering!H9+Submetering!J9+Submetering!L9+Submetering!N9+Submetering!P9+Submetering!R9+Submetering!T9+Submetering!V9+Submetering!X9+Submetering!Z9+Submetering!AB9+Submetering!AC9+Submetering!AE9)*0.02095)+(20/30)*15)*1.1048)/E8 -> 0.080722391 | G8: =Submetering!AK9+Submetering!AL9+Submetering!AU9 -> 4271.618 | H8: 0.8166 | I8: =Submetering!AF9+Submetering!AG9+Submetering!AV9+Submetering!AY9+Submetering!AZ9 -> 4845.1368 | J8: =((Submetering!AG9+Submetering!BA9)*0.8868+(1712.96+1070.52)/30+(Submetering!AF9+Submetering!AY9+Submetering!AV9+Submetering!AZ9)*1.1251+(2076.11+129.67+207.57+207.57)/30+(11680.53+56.61)/30)/I8 -> 1.1968249 | K8: =Elect!C11 -> 941
A9: Orlando | B9: 22 | C9: 2 | D9: 2021 | E9: =Submetering!F10+Submetering!H10+Submetering!J10+Submetering!L10+Submetering!N10+Submetering!P10+Submetering!R10+Submetering!T10+Submetering!V10+Submetering!X10+Submetering!Z10+Submetering!AB10+Submetering!AC10+Submetering!AD10+Submetering!AE10 -> 280664 | F9: =((((Submetering!E10+Submetering!AD10)*0.13773+(Submetering!E10+Submetering!AD10)*0.02095)*1.09+(2.85/30)*2)+(((Submetering!F10+Submetering!H10+Submetering!J10+Submetering!L10+Submetering!N10+Submetering!P10+Submetering!R10+Submetering!T10+Submetering!V10+Submetering!X10+Submetering!Z10+Submetering!AB10+Submetering!AC10+Submetering!AE10)*0.05155)+((Submetering!F10+Submetering!H10+Submetering!J10+Submetering!L10+Submetering!N10+Submetering!P10+Submetering!R10+Submetering!T10+Submetering!V10+Submetering!X10+Submetering!Z10+Submetering!AB10+Submetering!AC10+Submetering!AE10)*0.02095)+(20/30)*15)*1.1048)/E9 -> 0.080802235 | G9: =Submetering!AK10+Submetering!AL10+Submetering!AU10 -> 5643.4864 | H9: 0.8166 | I9: =Submetering!AF10+Submetering!AG10+Submetering!AV10+Submetering!AY10+Submetering!AZ10 -> 4707.82 | J9: =((Submetering!AG10+Submetering!BA10)*0.8868+(1712.96+1070.52)/30+(Submetering!AF10+Submetering!AY10+Submetering!AV10+Submetering!AZ10)*1.1251+(2076.11+129.67+207.57+207.57)/30+(11680.53+56.61)/30)/I9 -> 1.1971608 | K9: =Elect!C12 -> 1084
A10: Orlando | B10: 28 | C10: 2 | D10: 2021 | E10: =Submetering!F11+Submetering!H11+Submetering!J11+Submetering!L11+Submetering!N11+Submetering!P11+Submetering!R11+Submetering!T11+Submetering!V11+Submetering!X11+Submetering!Z11+Submetering!AB11+Submetering!AC11+Submetering!AD11+Submetering!AE11 -> 290324 | F10: =((((Submetering!E11+Submetering!AD11)*0.13773+(Submetering!E11+Submetering!AD11)*0.02095)*1.09+(2.85/30)*2)+(((Submetering!F11+Submetering!H11+Submetering!J11+Submetering!L11+Submetering!N11+Submetering!P11+Submetering!R11+Submetering!T11+Submetering!V11+Submetering!X11+Submetering!Z11+Submetering!AB11+Submetering!AC11+Submetering!AE11)*0.05155)+((Submetering!F11+Submetering!H11+Submetering!J11+Submetering!L11+Submetering!N11+Submetering!P11+Submetering!R11+Submetering!T11+Submetering!V11+Submetering!X11+Submetering!Z11+Submetering!AB11+Submetering!AC11+Submetering!AE11)*0.02095)+(20/30)*15)*1.1048)/E10 -> 0.08068893 | G10: =Submetering!AK11+Submetering!AL11+Submetering!AU11 -> 5096.8678 | H10: 0.8166 | I10: =Submetering!AF11+Submetering!AG11+Submetering!AV11+Submetering!AY11+Submetering!AZ11 -> 4680.5246 | J10: =((Submetering!AG11+Submetering!BA11)*0.8868+(1712.96+1070.52)/30+(Submetering!AF11+Submetering!AY11+Submetering!AV11+Submetering!AZ11)*1.1251+(2076.11+129.67+207.57+207.57)/30+(11680.53+56.61)/30)/I10 -> 1.2106391 | K10: =Elect!C13 -> 1427
A11: Orlando | B11: 8 | C11: 3 | D11: 2021 | E11: =Submetering!F12+Submetering!H12+Submetering!J12+Submetering!L12+Submetering!N12+Submetering!P12+Submetering!R12+Submetering!T12+Submetering!V12+Submetering!X12+Submetering!Z12+Submetering!AB12+Submetering!AC12+Submetering!AD12+Submetering!AE12 -> 282601 | F11: =((((Submetering!E12+Submetering!AD12)*0.13773+(Submetering!E12+Submetering!AD12)*0.02095)*1.09+(2.85/30)*2)+(((Submetering!F12+Submetering!H12+Submetering!J12+Submetering!L12+Submetering!N12+Submetering!P12+Submetering!R12+Submetering!T12+Submetering!V12+Submetering!X12+Submetering!Z12+Submetering!AB12+Submetering!AC12+Submetering!AE12)*0.05155)+((Submetering!F12+Submetering!H12+Submetering!J12+Submetering!L12+Submetering!N12+Submetering!P12+Submetering!R12+Submetering!T12+Submetering!V12+Submetering!X12+Submetering!Z12+Submetering!AB12+Submetering!AC12+Submetering!AE12)*0.02095)+(20/30)*15)*1.1048)/E11 -> 0.08074781 | G11: =Submetering!AK12+Submetering!AL12+Submetering!AU12 -> 6028.985 | H11: 0.8166 | I11: =Submetering!AF12+Submetering!AG12+Submetering!AV12+Submetering!AY12+Submetering!AZ12 -> 4693.6308 | J11: =((Submetering!AG12+Submetering!BA12)*0.8868+(1712.96+1070.52)/30+(Submetering!AF12+Submetering!AY12+Submetering!AV12+Submetering!AZ12)*1.1251+(2076.11+129.67+207.57+207.57)/30+(11680.53+56.61)/30)/I11 -> 1.2559947 | K11: =Elect!C14 -> 1082
A12: Orlando | B12: 15 | C12: 3 | D12: 2021 | E12: =Submetering!F13+Submetering!H13+Submetering!J13+Submetering!L13+Submetering!N13+Submetering!P13+Submetering!R13+Submetering!T13+Submetering!V13+Submetering!X13+Submetering!Z13+Submetering!AB13+Submetering!AC13+Submetering!AD13+Submetering!AE13 -> 266757 | F12: =((((Submetering!E13+Submetering!AD13)*0.13773+(Submetering!E13+Submetering!AD13)*0.02095)*1.09+(2.85/30)*2)+(((Submetering!F13+Submetering!H13+Submetering!J13+Submetering!L13+Submetering!N13+Submetering!P13+Submetering!R13+Submetering!T13+Submetering!V13+Submetering!X13+Submetering!Z13+Submetering!AB13+Submetering!AC13+Submetering!AE13)*0.05155)+((Submetering!F13+Submetering!H13+Submetering!J13+Submetering!L13+Submetering!N13+Submetering!P13+Submetering!R13+Submetering!T13+Submetering!V13+Submetering!X13+Submetering!Z13+Submetering!AB13+Submetering!AC13+Submetering!AE13)*0.02095)+(20/30)*15)*1.1048)/E12 -> 0.080785182 | G12: =Submetering!AK13+Submetering!AL13+Submetering!AU13 -> 6328.2008 | H12: 0.8166 | I12: =Submetering!AF13+Submetering!AG13+Submetering!AV13+Submetering!AY13+Submetering!AZ13 -> 5043.379 | J12: =((Submetering!AG13+Submetering!BA13)*0.8868+(1712.96+1070.52)/30+(Submetering!AF13+Submetering!AY13+Submetering!AV13+Submetering!AZ13)*1.1251+(2076.11+129.67+207.57+207.57)/30+(11680.53+56.61)/30)/I12 -> 1.3764006 | K12: =Elect!C15 -> 1285
A13: Orlando | B13: 22 | C13: 3 | D13: 2021 | E13: =Submetering!F14+Submetering!H14+Submetering!J14+Submetering!L14+Submetering!N14+Submetering!P14+Submetering!R14+Submetering!T14+Submetering!V14+Submetering!X14+Submetering!Z14+Submetering!AB14+Submetering!AC14+Submetering!AD14+Submetering!AE14 -> 303821 | F13: =((((Submetering!E14+Submetering!AD14)*0.13773+(Submetering!E14+Submetering!AD14)*0.02095)*1.09+(2.85/30)*2)+(((Submetering!F14+Submetering!H14+Submetering!J14+Submetering!L14+Submetering!N14+Submetering!P14+Submetering!R14+Submetering!T14+Submetering!V14+Submetering!X14+Submetering!Z14+Submetering!AB14+Submetering!AC14+Submetering!AE14)*0.05155)+((Submetering!F14+Submetering!H14+Submetering!J14+Submetering!L14+Submetering!N14+Submetering!P14+Submetering!R14+Submetering!T14+Submetering!V14+Submetering!X14+Submetering!Z14+Submetering!AB14+Submetering!AC14+Submetering!AE14)*0.02095)+(20/30)*15)*1.1048)/E13 -> 0.080633988 | G13: =Submetering!AK14+Submetering!AL14+Submetering!AU14 -> 5438.18 | H13: 0.8166 | I13: =Submetering!AF14+Submetering!AG14+Submetering!AV14+Submetering!AY14+Submetering!AZ14 -> 5470.157 | J13: =((Submetering!AG14+Submetering!BA14)*0.8868+(1712.96+1070.52)/30+(Submetering!AF14+Submetering!AY14+Submetering!AV14+Submetering!AZ14)*1.1251+(2076.11+129.67+207.57+207.57)/30+(11680.53+56.61)/30)/I13 -> 1.352804 | K13: =Elect!C16 -> 1842
... A60: Orlando | B60: 31 | C60: 12 | D60: 2021 | E60: =Submetering!F61+Submetering!H61+Submetering!J61+Submetering!L61+Submetering!N61+Submetering!P61+Submetering!R61+Submetering!T61+Submetering!V61+Submetering!X61+Submetering!Z61+Submetering!AB61+Submetering!AC61+Submetering!AD61+Submetering!AE61 -> 0 | F60: =((((Submetering!E61+Submetering!AD61)*0.13773+(Submetering!E61+Submetering!AD61)*0.02095)*1.09+(2.85/30)*2)+(((Submetering!F61+Submetering!H61+Submetering!J61+Submetering!L61+Submetering!N61+Submetering!P61+Submetering!R61+Submetering!T61+Submetering!V61+Submetering!X61+Submetering!Z61+Submetering!AB61+Submetering!AC61+Submetering!AE61)*0.05155)+((Submetering!F61+Submetering!H61+Submetering!J61+Submetering!L61+Submetering!N61+Submetering!P61+Submetering!R61+Submetering!T61+Submetering!V61+Submetering!X61+Submetering!Z61+Submetering!AB61+Submetering!AC61+Submetering!AE61)*0.02095)+(20/30)*15)*1.1048)/E60 -> #DIV/0! | G60: =Submetering!AK61+Submetering!AL61+Submetering!AU61 -> 0 | H60: 0.8166 | I60: =Submetering!AF61+Submetering!AG61+Submetering!AV61+Submetering!AY61+Submetering!AZ61 -> 0 | J60: =((Submetering!AG61+Submetering!BA61)*0.8868+(1712.96+1070.52)/30+(Submetering!AF61+Submetering!AY61+Submetering!AV61+Submetering!AZ61)*1.1251+(2076.11+129.67+207.57+207.57)/30+(11680.53+56.61)/30)/I60 -> #DIV/0! | K60: =Elect!C63 -> 1430

Sheet Submetering
A1: Site Name | B1: Day | C1: Month | D1: Year | E1: 90 630 431 (KWh) | F1: 68 425 010 (KWh) | G1: T2392 (KWh) | H1: 68 425 008 (KWh) | I1: T7384 (KWh) | J1: 68 425 060 (KWh) | K1: T7380 (KWh) | L1: 68 425 097 (KWh) | M1: T7281 (KWh) | N1: 68 425 059 (KWh) | O1: T2390 (KWh) | P1: 68 425 077 (KWh) | Q1: T2395 (KWh) | R1: 68 425 078 (KWh) | S1: T2393 (KWh) | T1: 68 425 071 (KWh) | U1: T7285 (KWh) | V1: 68 425 093 (KWh) | W1: T7382 (KWh) | X1: 68 425 094 (KWh) | Y1: T2391 (KWh) | Z1: 90 625 242 (KWh) | AA1: T7283 (KWh) | AB1: 672 73 163 (KWh) | AC1: 676 62 513 (KWh) | AD1: 61 979 920 (KWh) | AE1: 56 253 208 (KWh) | AF1: Domestic Water from RCES 74860172 (m3) | AG1: Re-use Water from RCES 74860173 (m3) | AH1: Building A Fire Sprinkler System Make-up 44553004 (m3) | AI1: Building A Potable Water Feed 70275191 (m3) | AJ1: Steam Boilers Make-up Water 2130521 (m3) | AK1: Resort Natural Gas Meter 12C004186-C1 (m3) | AL1: Out Buildings Natural Gas Meter 93477704 (m3) | AM1: Cooling Tower Make-up Water 79177804 (m3) | AN1: Cooling Tower Blowdown Line Deduct 79305675 (m3) | AO1: Building E Potable Water Meter 79190041 (m3) | AP1: 7919004D | AQ1: Building J Irrigation Water Meter 79190039 (m3) | AR1: Lazy Pool River Make-up Water 79324776 (m3) | AS1: Pool Hydraunic Boiler Water Make-up 112014001775 (m3) | AT1: SPA Jacuzzi Water Make-up 112014001771 (m3) | AU1: Golf Clubhouse Natural Gas Meter 82SJ729151 (m3) | AV1: 73337589 - 1387142 | AW1: Golf Clubhouse Flushing Valve Deduct 65956268 (m3) | AX1: Clubhouse | AY1: Golf Maintenance Facility 1334021 (m3) | AZ1: Golf Course Comfort Stations 63265094 (m3) | BA1: Golf Course Re-use Irrigation 67327447 (m3)
A2: Orlando | B2: 1 | C2: 1 | D2: 2020 | E2: =IF(Elect!AM4<0,"0",Elect!AM4) -> 0 | F2: =IF(Elect!I4<0,"0",Elect!I4) | G2: =Elect!H4 -> 2.299 | H2: =IF(Elect!F4<0,"0",Elect!F4) | I2: =Elect!E4 -> 1.99 | J2: =IF(Elect!U4<0,"0",Elect!U4) | K2: =Elect!T4 -> 1.964 | L2: =IF(Elect!AJ4<0,"0",Elect!AJ4) | M2: =Elect!AI4 -> 0.331 | N2: =IF(Elect!X4<0,"0",Elect!X4) | O2: =Elect!W4 -> 1.376 | P2: =IF(Elect!O4<0,"0",Elect!O4) | Q2: =Elect!N4 -> 2.48 | R2: =IF(Elect!L4<0,"0",Elect!L4) | S2: =Elect!K4 -> 3.07 | T2: =IF(Elect!R4<0,"0",Elect!R4) | U2: =Elect!Q4 -> 2.77 | V2: =IF(Elect!AA4<0,"0",Elect!AA4) | W2: =Elect!Z4 -> 2.56 | X2: =IF(Elect!AD4<0,"0",Elect!AD4) | Y2: =Elect!AC4 -> 1.73 | Z2: =IF(Elect!AG4<0,"0",Elect!AG4) | AA2: =Elect!AF4 -> 2.162 | AB2: =IF(Elect!AX4<0,"0",Elect!AX4) | AC2: =IF(Elect!AV4<0,"0",Elect!AV4) | AD2: =IF(Elect!AZ4<0,"0",Elect!AZ4) | AE2: =IF(Elect!BB4<0,"0",Elect!BB4) | AF2: =IF('Wtr-Gas'!E4<0,"0",('Wtr-Gas'!E4)*0.0038) -> 0 | AG2: =IF('Wtr-Gas'!H4<0,"0",('Wtr-Gas'!H4)*0.0038) -> 0 | AH2: =IF('Wtr-Gas'!K4<0,"0",('Wtr-Gas'!K4)*0.0038) -> 0 | AI2: =IF('Wtr-Gas'!N4<0,"0",('Wtr-Gas'!N4)*0.0038) -> 0 | AJ2: =IF('Wtr-Gas'!Q4<0,"0",('Wtr-Gas'!Q4)*0.0038) -> 0 | AK2: =IF('Wtr-Gas'!U4<0,"0",('Wtr-Gas'!U4)*0.0038) -> 0 | AL2: =IF('Wtr-Gas'!X4<0,"0",('Wtr-Gas'!X4)*0.0038) -> 0 | AM2: =IF('Wtr-Gas'!AB4<0,"0",('Wtr-Gas'!AB4)*0.0038) -> 0 | AN2: =IF('Wtr-Gas'!AD4<0,"0",('Wtr-Gas'!AD4)*0.0038) -> 0 | AO2: =IF('Wtr-Gas'!AF4<0,"0",('Wtr-Gas'!AF4)*0.0038) -> 0 | AP2: =IF('Wtr-Gas'!AH4<0,"0",('Wtr-Gas'!AH4)*0.0038) -> 0 | AQ2: =IF('Wtr-Gas'!AJ4<0,"0",('Wtr-Gas'!AJ4)*0.0038) -> 0 | AR2: =IF('Wtr-Gas'!AL4<0,"0",('Wtr-Gas'!AL4)*0.0038) -> 0 | AS2: =IF('Wtr-Gas'!AN4<0,"0",('Wtr-Gas'!AN4)*0.0038) -> 0 | AT2: =IF('Wtr-Gas'!AP4<0,"0",('Wtr-Gas'!AP4)*0.0038) -> 0 | AU2: =IF('Wtr-Gas'!AT4<0,"0",('Wtr-Gas'!AT4)*0.0038) -> 0 | AV2: =IF('Wtr-Gas'!AW4<0,"0",('Wtr-Gas'!AW4)*0.0038) -> 0 | AW2: =IF('Wtr-Gas'!AY4<0,"0",('Wtr-Gas'!AY4)*0.0038) -> 0 | AX2: =IF('Wtr-Gas'!AZ4<0,"0",('Wtr-Gas'!AZ4)*0.0038) -> 0 | AY2: =IF('Wtr-Gas'!BB4<0,"0",('Wtr-Gas'!BB4)*0.0038) -> 0 | AZ2: =IF('Wtr-Gas'!BD4<0,"0",('Wtr-Gas'!BD4)*0.0038) -> 0 | BA2: =IF('Wtr-Gas'!BF4<0,"0",('Wtr-Gas'!BF4)*0.0038) -> 0
A3: Orlando | B3: 4 | C3: 1 | D3: 2021 | E3: =IF(Elect!AM5<0,"0",Elect!AM5) -> 251 | F3: =IF(Elect!I5<0,"0",Elect!I5) -> 21440 | G3: =Elect!H5 -> 2.299 | H3: =IF(Elect!F5<0,"0",Elect!F5) -> 19200 | I3: =Elect!E5 -> 1.99 | J3: =IF(Elect!U5<0,"0",Elect!U5) -> 31800 | K3: =Elect!T5 -> 2.067 | L3: =IF(Elect!AJ5<0,"0",Elect!AJ5) -> 0 | M3: =Elect!AI5 -> 0.331 | N3: =IF(Elect!X5<0,"0",Elect!X5) -> 18300 | O3: =Elect!W5 -> 1.373 | P3: =IF(Elect!O5<0,"0",Elect!O5) -> 4400 | Q3: =Elect!N5 -> 2.48 | R3: =IF(Elect!L5<0,"0",Elect!L5) -> 5200 | S3: =Elect!K5 -> 3.07 | T3: =IF(Elect!R5<0,"0",Elect!R5) -> 4800 | U3: =Elect!Q5 -> 2.77 | V3: =IF(Elect!AA5<0,"0",Elect!AA5) -> 2240 | W3: =Elect!Z5 -> 2.56 | X3: =IF(Elect!AD5<0,"0",Elect!AD5) -> 1280 | Y3: =Elect!AC5 -> 1.74 | Z3: =IF(Elect!AG5<0,"0",Elect!AG5) -> 21800 | AA3: =Elect!AF5 -> 2.162 | AB3: =IF(Elect!AX5<0,"0",Elect!AX5) -> 500 | AC3: =IF(Elect!AV5<0,"0",Elect!AV5) -> 5200 | AD3: =IF(Elect!AZ5<0,"0",Elect!AZ5) -> 889 | AE3: =IF(Elect!BB5<0,"0",Elect!BB5) -> 2640 | AF3: =IF('Wtr-Gas'!E5<0,"0",('Wtr-Gas'!E5)*0.0038) -> 2003.588 | AG3: =IF('Wtr-Gas'!H5<0,"0",('Wtr-Gas'!H5)*0.0038) -> 1514.224 | AH3: =IF('Wtr-Gas'!K5<0,"0",('Wtr-Gas'!K5)*0.0038) -> 0.228 | AI3: =IF('Wtr-Gas'!N5<0,"0",('Wtr-Gas'!N5)*0.0038) -> 1413.6 | AJ3: =IF('Wtr-Gas'!Q5<0,"0",('Wtr-Gas'!Q5)*0.0038) -> 29.64 | AK3: =IF('Wtr-Gas'!U5<0,"0",('Wtr-Gas'!U5)*0.0038) -> 424.46 | AL3: =IF('Wtr-Gas'!X5<0,"0",('Wtr-Gas'!X5)*0.0038) -> 2171.7 | AM3: =IF('Wtr-Gas'!AB5<0,"0",('Wtr-Gas'!AB5)*0.0038) -> 3116 | AN3: =IF('Wtr-Gas'!AD5<0,"0",('Wtr-Gas'!AD5)*0.0038) -> 695.67664 | AO3: =IF('Wtr-Gas'!AF5<0,"0",('Wtr-Gas'!AF5)*0.0038) -> 1.9 | AP3: =IF('Wtr-Gas'!AH5<0,"0",('Wtr-Gas'!AH5)*0.0038) -> 156.332 | AQ3: =IF('Wtr-Gas'!AJ5<0,"0",('Wtr-Gas'!AJ5)*0.0038) -> 15.3596 | AR3: =IF('Wtr-Gas'!AL5<0,"0",('Wtr-Gas'!AL5)*0.0038) -> 338.2 | AS3: =IF('Wtr-Gas'!AN5<0,"0",('Wtr-Gas'!AN5)*0.0038) -> 0.0532 | AT3: =IF('Wtr-Gas'!AP5<0,"0",('Wtr-Gas'!AP5)*0.0038) -> 2.28 | AU3: =IF('Wtr-Gas'!AT5<0,"0",('Wtr-Gas'!AT5)*0.0038) -> 0.1634 | AV3: =IF('Wtr-Gas'!AW5<0,"0",('Wtr-Gas'!AW5)*0.0038) -> 83.7786 | AW3: =IF('Wtr-Gas'!AY5<0,"0",('Wtr-Gas'!AY5)*0.0038) -> 64.7292 | AX3: =IF('Wtr-Gas'!AZ5<0,"0",('Wtr-Gas'!AZ5)*0.0038) -> 19.047614 | AY3: =IF('Wtr-Gas'!BB5<0,"0",('Wtr-Gas'!BB5)*0.0038) -> 2.28 | AZ3: =IF('Wtr-Gas'!BD5<0,"0",('Wtr-Gas'!BD5)*0.0038) -> 7.6 | BA3: =IF('Wtr-Gas'!BF5<0,"0",('Wtr-Gas'!BF5)*0.0038) -> 11.59
A4: Orlando | B4: 11 | C4: 1 | D4: 2021 | E4: =IF(Elect!AM6<0,"0",Elect!AM6) -> 554 | F4: =IF(Elect!I6<0,"0",Elect!I6) -> 44320 | G4: =Elect!H6 -> 2.299 | H4: =IF(Elect!F6<0,"0",Elect!F6) -> 40320 | I4: =Elect!E6 -> 1.99 | J4: =IF(Elect!U6<0,"0",Elect!U6) -> 24300 | K4: =Elect!T6 -> 2.067 | L4: =IF(Elect!AJ6<0,"0",Elect!AJ6) -> 3480 | M4: =Elect!AI6 -> 0.331 | N4: =IF(Elect!X6<0,"0",Elect!X6) -> 24600 | O4: =Elect!W6 -> 1.373 | P4: =IF(Elect!O6<0,"0",Elect!O6) -> 9200 | Q4: =Elect!N6 -> 2.48 | R4: =IF(Elect!L6<0,"0",Elect!L6) -> 10400 | S4: =Elect!K6 -> 3.07 | T4: =IF(Elect!R6<0,"0",Elect!R6) -> 9600 | U4: =Elect!Q6 -> 2.77 | V4: =IF(Elect!AA6<0,"0",Elect!AA6) -> 5120 | W4: =Elect!Z6 -> 2.72 | X4: =IF(Elect!AD6<0,"0",Elect!AD6) -> 2400 | Y4: =Elect!AC6 -> 1.74 | Z4: =IF(Elect!AG6<0,"0",Elect!AG6) -> 50400 | AA4: =Elect!AF6 -> 2.162 | AB4: =IF(Elect!AX6<0,"0",Elect!AX6) -> 1500 | AC4: =IF(Elect!AV6<0,"0",Elect!AV6) -> 11000 | AD4: =IF(Elect!AZ6<0,"0",Elect!AZ6) -> 909 | AE4: =IF(Elect!BB6<0,"0",Elect!BB6) -> 3280 | AF4: =IF('Wtr-Gas'!E6<0,"0",('Wtr-Gas'!E6)*0.0038) -> 3158.712 | AG4: =IF('Wtr-Gas'!H6<0,"0",('Wtr-Gas'!H6)*0.0038) -> 1080.758 | AH4: =IF('Wtr-Gas'!K6<0,"0",('Wtr-Gas'!K6)*0.0038) -> 1.064 | AI4: =IF('Wtr-Gas'!N6<0,"0",('Wtr-Gas'!N6)*0.0038) -> 1725.2 | AJ4: =IF('Wtr-Gas'!Q6<0,"0",('Wtr-Gas'!Q6)*0.0038) -> 79.8 | AK4: =IF('Wtr-Gas'!U6<0,"0",('Wtr-Gas'!U6)*0.0038) -> 755.06 | AL4: =IF('Wtr-Gas'!X6<0,"0",('Wtr-Gas'!X6)*0.0038) -> 7904.76 | AM4: =IF('Wtr-Gas'!AB6<0,"0",('Wtr-Gas'!AB6)*0.0038) -> 2432 | AN4: =IF('Wtr-Gas'!AD6<0,"0",('Wtr-Gas'!AD6)*0.0038) -> 809.4874 | AO4: =IF('Wtr-Gas'!AF6<0,"0",('Wtr-Gas'!AF6)*0.0038) -> 7.258 | AP4: =IF('Wtr-Gas'!AH6<0,"0",('Wtr-Gas'!AH6)*0.0038) -> 343.52 | AQ4: =IF('Wtr-Gas'!AJ6<0,"0",('Wtr-Gas'!AJ6)*0.0038) -> 41.0514 | AR4: =IF('Wtr-Gas'!AL6<0,"0",('Wtr-Gas'!AL6)*0.0038) -> 839.8 | AS4: =IF('Wtr-Gas'!AN6<0,"0",('Wtr-Gas'!AN6)*0.0038) -> 0.1178 | AT4: =IF('Wtr-Gas'!AP6<0,"0",('Wtr-Gas'!AP6)*0.0038) -> 4.56 | AU4: =IF('Wtr-Gas'!AT6<0,"0",('Wtr-Gas'!AT6)*0.0038) -> 0.4598 | AV4: =IF('Wtr-Gas'!AW6<0,"0",('Wtr-Gas'!AW6)*0.0038) -> 188.4648 | AW4: =IF('Wtr-Gas'!AY6<0,"0",('Wtr-Gas'!AY6)*0.0038) -> 151.3426 | AX4: =IF('Wtr-Gas'!AZ6<0,"0",('Wtr-Gas'!AZ6)*0.0038) -> 37.121668 | AY4: =IF('Wtr-Gas'!BB6<0,"0",('Wtr-Gas'!BB6)*0.0038) -> 22.42 | AZ4: =IF('Wtr-Gas'!BD6<0,"0",('Wtr-Gas'!BD6)*0.0038) -> 7.98 | BA4: =IF('Wtr-Gas'!BF6<0,"0",('Wtr-Gas'!BF6)*0.0038) -> 0
A5: Orlando | B5: 18 | C5: 1 | D5: 2021 | E5: =IF(Elect!AM7<0,"0",Elect!AM7) -> 564 | F5: =IF(Elect!I7<0,"0",Elect!I7) -> 45120 | G5: =Elect!H7 -> 2.299 | H5: =IF(Elect!F7<0,"0",Elect!F7) -> 40800 | I5: =Elect!E7 -> 1.99 | J5: =IF(Elect!U7<0,"0",Elect!U7) -> 17400 | K5: =Elect!T7 -> 2.067 | L5: =IF(Elect!AJ7<0,"0",Elect!AJ7) -> 1440 | M5: =Elect!AI7 -> 0.346 | N5: =IF(Elect!X7<0,"0",Elect!X7) -> 34500 | O5: =Elect!W7 -> 1.373 | P5: =IF(Elect!O7<0,"0",Elect!O7) -> 8800 | Q5: =Elect!N7 -> 2.48 | R5: =IF(Elect!L7<0,"0",Elect!L7) -> 12800 | S5: =Elect!K7 -> 3.07 | T5: =IF(Elect!R7<0,"0",Elect!R7) -> 9600 | U5: =Elect!Q7 -> 2.77 | V5: =IF(Elect!AA7<0,"0",Elect!AA7) -> 6080 | W5: =Elect!Z7 -> 3.03 | X5: =IF(Elect!AD7<0,"0",Elect!AD7) -> 3040 | Y5: =Elect!AC7 -> 1.76 | Z5: =IF(Elect!AG7<0,"0",Elect!AG7) -> 50600 | AA5: =Elect!AF7 -> 2.162 | AB5: =IF(Elect!AX7<0,"0",Elect!AX7) -> 1400 | AC5: =IF(Elect!AV7<0,"0",Elect!AV7) -> 10900 | AD5: =IF(Elect!AZ7<0,"0",Elect!AZ7) -> 880 | AE5: =IF(Elect!BB7<0,"0",Elect!BB7) -> 43 | AF5: =IF('Wtr-Gas'!E7<0,"0",('Wtr-Gas'!E7)*0.0038) -> 3168.174 | AG5: =IF('Wtr-Gas'!H7<0,"0",('Wtr-Gas'!H7)*0.0038) -> 1035.652 | AH5: =IF('Wtr-Gas'!K7<0,"0",('Wtr-Gas'!K7)*0.0038) -> 1.14 | AI5: =IF('Wtr-Gas'!N7<0,"0",('Wtr-Gas'!N7)*0.0038) -> 1824 | AJ5: =IF('Wtr-Gas'!Q7<0,"0",('Wtr-Gas'!Q7)*0.0038) -> 82.46 | AK5: =IF('Wtr-Gas'!U7<0,"0",('Wtr-Gas'!U7)*0.0038) -> 770.64 | AL5: =IF('Wtr-Gas'!X7<0,"0",('Wtr-Gas'!X7)*0.0038) -> 7306.64 | AM5: =IF('Wtr-Gas'!AB7<0,"0",('Wtr-Gas'!AB7)*0.0038) -> 2432 | AN5: =IF('Wtr-Gas'!AD7<0,"0",('Wtr-Gas'!AD7)*0.0038) -> 742.45008 | AO5: =IF('Wtr-Gas'!AF7<0,"0",('Wtr-Gas'!AF7)*0.0038) -> 3.952 | AP5: =IF('Wtr-Gas'!AH7<0,"0",('Wtr-Gas'!AH7)*0.0038) -> 337.288 | AQ5: =IF('Wtr-Gas'!AJ7<0,"0",('Wtr-Gas'!AJ7)*0.0038) -> 34.4014 | AR5: =IF('Wtr-Gas'!AL7<0,"0",('Wtr-Gas'!AL7)*0.0038) -> 786.6 | AS5: =IF('Wtr-Gas'!AN7<0,"0",('Wtr-Gas'!AN7)*0.0038) -> 0.1786 | AT5: =IF('Wtr-Gas'!AP7<0,"0",('Wtr-Gas'!AP7)*0.0038) -> 8.36 | AU5: =IF('Wtr-Gas'!AT7<0,"0",('Wtr-Gas'!AT7)*0.0038) -> 0.4788 | AV5: =IF('Wtr-Gas'!AW7<0,"0",('Wtr-Gas'!AW7)*0.0038) -> 190.0076 | AW5: =IF('Wtr-Gas'!AY7<0,"0",('Wtr-Gas'!AY7)*0.0038) -> 153.9684 | AX5: =IF('Wtr-Gas'!AZ7<0,"0",('Wtr-Gas'!AZ7)*0.0038) -> 36.03787 | AY5: =IF('Wtr-Gas'!BB7<0,"0",('Wtr-Gas'!BB7)*0.0038) -> 7.98 | AZ5: =IF('Wtr-Gas'!BD7<0,"0",('Wtr-Gas'!BD7)*0.0038) -> 4.56 | BA5: =IF('Wtr-Gas'!BF7<0,"0",('Wtr-Gas'!BF7)*0.0038) -> 62.1072
A6: Orlando | B6: 25 | C6: 1 | D6: 2021 | E6: =IF(Elect!AM8<0,"0",Elect!AM8) -> 341 | F6: =IF(Elect!I8<0,"0",Elect!I8) -> 47680 | G6: =Elect!H8 -> 2.261 | H6: =IF(Elect!F8<0,"0",Elect!F8) -> 42880 | I6: =Elect!E8 -> 1.963 | J6: =IF(Elect!U8<0,"0",Elect!U8) -> 34500 | K6: =Elect!T8 -> 1.767 | L6: =IF(Elect!AJ8<0,"0",Elect!AJ8) -> 1560 | M6: =Elect!AI8 -> 0.267 | N6: =IF(Elect!X8<0,"0",Elect!X8) -> 38100 | O6: =Elect!W8 -> 1.7 | P6: =IF(Elect!O8<0,"0",Elect!O8) -> 9600 | Q6: =Elect!N8 -> 1.88 | R6: =IF(Elect!L8<0,"0",Elect!L8) -> 11200 | S6: =Elect!K8 -> 2.63 | T6: =IF(Elect!R8<0,"0",Elect!R8) -> 9600 | U6: =Elect!Q8 -> 2.18 | V6: =IF(Elect!AA8<0,"0",Elect!AA8) -> 6560 | W6: =Elect!Z8 -> 3.22 | X6: =IF(Elect!AD8<0,"0",Elect!AD8) -> 4160 | Y6: =Elect!AC8 -> 2.96 | Z6: =IF(Elect!AG8<0,"0",Elect!AG8) -> 52600 | AA6: =Elect!AF8 -> 2.013 | AB6: =IF(Elect!AX8<0,"0",Elect!AX8) -> 1900 | AC6: =IF(Elect!AV8<0,"0",Elect!AV8) -> 12800 | AD6: =IF(Elect!AZ8<0,"0",Elect!AZ8) -> 879 | AE6: =IF(Elect!BB8<0,"0",Elect!BB8) -> 1360 | AF6: =IF('Wtr-Gas'!E8<0,"0",('Wtr-Gas'!E8)*0.0038) -> 3898.952 | AG6: =IF('Wtr-Gas'!H8<0,"0",('Wtr-Gas'!H8)*0.0038) -> 1001.946 | AH6: =IF('Wtr-Gas'!K8<0,"0",('Wtr-Gas'!K8)*0.0038) -> 2.052 | AI6: =IF('Wtr-Gas'!N8<0,"0",('Wtr-Gas'!N8)*0.0038) -> 2470 | AJ6: =IF('Wtr-Gas'!Q8<0,"0",('Wtr-Gas'!Q8)*0.0038) -> 99.56 | AK6: =IF('Wtr-Gas'!U8<0,"0",('Wtr-Gas'!U8)*0.0038) -> 905.16 | AL6: =IF('Wtr-Gas'!X8<0,"0",('Wtr-Gas'!X8)*0.0038) -> 6684.2 | AM6: =IF('Wtr-Gas'!AB8<0,"0",('Wtr-Gas'!AB8)*0.0038) -> 3952 | AN6: =IF('Wtr-Gas'!AD8<0,"0",('Wtr-Gas'!AD8)*0.0038) -> 912.75392 | AO6: =IF('Wtr-Gas'!AF8<0,"0",('Wtr-Gas'!AF8)*0.0038) -> 6.27 | AP6: =IF('Wtr-Gas'!AH8<0,"0",('Wtr-Gas'!AH8)*0.0038) -> 376.01 | AQ6: =IF('Wtr-Gas'!AJ8<0,"0",('Wtr-Gas'!AJ8)*0.0038) -> 48.3208 | AR6: =IF('Wtr-Gas'!AL8<0,"0",('Wtr-Gas'!AL8)*0.0038) -> 805.6 | AS6: =IF('Wtr-Gas'!AN8<0,"0",('Wtr-Gas'!AN8)*0.0038) -> 0.1444 | AT6: =IF('Wtr-Gas'!AP8<0,"0",('Wtr-Gas'!AP8)*0.0038) -> 15.2 | AU6: =IF('Wtr-Gas'!AT8<0,"0",('Wtr-Gas'!AT8)*0.0038) -> 0.4446 | AV6: =IF('Wtr-Gas'!AW8<0,"0",('Wtr-Gas'!AW8)*0.0038) -> 217.9072 | AW6: =IF('Wtr-Gas'!AY8<0,"0",('Wtr-Gas'!AY8)*0.0038) -> 150.404 | AX6: =IF('Wtr-Gas'!AZ8<0,"0",('Wtr-Gas'!AZ8)*0.0038) -> 67.502022 | AY6: =IF('Wtr-Gas'!BB8<0,"0",('Wtr-Gas'!BB8)*0.0038) -> 19.76 | AZ6: =IF('Wtr-Gas'!BD8<0,"0",('Wtr-Gas'!BD8)*0.0038) -> 3.42 | BA6: =IF('Wtr-Gas'!BF8<0,"0",('Wtr-Gas'!BF8)*0.0038) -> 0
A7: Orlando | B7: 31 | C7: 1 | D7: 2021 | E7: =IF(Elect!AM9<0,"0",Elect!AM9) -> 601 | F7: =IF(Elect!I9<0,"0",Elect!I9) -> 44960 | G7: =Elect!H9 -> 2.261 | H7: =IF(Elect!F9<0,"0",Elect!F9) -> 38720 | I7: =Elect!E9 -> 1.963 | J7: =IF(Elect!U9<0,"0",Elect!U9) -> 36000 | K7: =Elect!T9 -> 1.978 | L7: =IF(Elect!AJ9<0,"0",Elect!AJ9) -> 3000 | M7: =Elect!AI9 -> 0.267 | N7: =IF(Elect!X9<0,"0",Elect!X9) -> 38400 | O7: =Elect!W9 -> 1.7 | P7: =IF(Elect!O9<0,"0",Elect!O9) -> 8800 | Q7: =Elect!N9 -> 1.88 | R7: =IF(Elect!L9<0,"0",Elect!L9) -> 9600 | S7: =Elect!K9 -> 2.63 | T7: =IF(Elect!R9<0,"0",Elect!R9) -> 9200 | U7: =Elect!Q9 -> 2.18 | V7: =IF(Elect!AA9<0,"0",Elect!AA9) -> 5280 | W7: =Elect!Z9 -> 3.22 | X7: =IF(Elect!AD9<0,"0",Elect!AD9) -> 2720 | Y7: =Elect!AC9 -> 2.96 | Z7: =IF(Elect!AG9<0,"0",Elect!AG9) -> 49600 | AA7: =Elect!AF9 -> 2.013 | AB7: =IF(Elect!AX9<0,"0",Elect!AX9) -> 1400 | AC7: =IF(Elect!AV9<0,"0",Elect!AV9) -> 12000 | AD7: =IF(Elect!AZ9<0,"0",Elect!AZ9) -> 914 | AE7: =IF(Elect!BB9<0,"0",Elect!BB9) -> 2240 | AF7: =IF('Wtr-Gas'!E9<0,"0",('Wtr-Gas'!E9)*0.0038) -> 3949.986 | AG7: =IF('Wtr-Gas'!H9<0,"0",('Wtr-Gas'!H9)*0.0038) -> 770.374 | AH7: =IF('Wtr-Gas'!K9<0,"0",('Wtr-Gas'!K9)*0.0038) -> 1.216 | AI7: =IF('Wtr-Gas'!N9<0,"0",('Wtr-Gas'!N9)*0.0038) -> 2572.6 | AJ7: =IF('Wtr-Gas'!Q9<0,"0",('Wtr-Gas'!Q9)*0.0038) -> 90.82 | AK7: =IF('Wtr-Gas'!U9<0,"0",('Wtr-Gas'!U9)*0.0038) -> 773.68 | AL7: =IF('Wtr-Gas'!X9<0,"0",('Wtr-Gas'!X9)*0.0038) -> 5779.8 | AM7: =IF('Wtr-Gas'!AB9<0,"0",('Wtr-Gas'!AB9)*0.0038) -> 4408 | AN7: =IF('Wtr-Gas'!AD9<0,"0",('Wtr-Gas'!AD9)*0.0038) -> 1011.066 | AO7: =IF('Wtr-Gas'!AF9<0,"0",('Wtr-Gas'!AF9)*0.0038) -> 7.828 | AP7: =IF('Wtr-Gas'!AH9<0,"0",('Wtr-Gas'!AH9)*0.0038) -> 372.856 | AQ7: =IF('Wtr-Gas'!AJ9<0,"0",('Wtr-Gas'!AJ9)*0.0038) -> 43.4074 | AR7: =IF('Wtr-Gas'!AL9<0,"0",('Wtr-Gas'!AL9)*0.0038) -> 782.8 | AS7: =IF('Wtr-Gas'!AN9<0,"0",('Wtr-Gas'!AN9)*0.0038) -> 0.0988 | AT7: =IF('Wtr-Gas'!AP9<0,"0",('Wtr-Gas'!AP9)*0.0038) -> 4.18 | AU7: =IF('Wtr-Gas'!AT9<0,"0",('Wtr-Gas'!AT9)*0.0038) -> 0.4332 | AV7: =IF('Wtr-Gas'!AW9<0,"0",('Wtr-Gas'!AW9)*0.0038) -> 184.6344 | AW7: =IF('Wtr-Gas'!AY9<0,"0",('Wtr-Gas'!AY9)*0.0038) -> 150.3698 | AX7: =IF('Wtr-Gas'!AZ9<0,"0",('Wtr-Gas'!AZ9)*0.0038) -> 34.264714 | AY7: =IF('Wtr-Gas'!BB9<0,"0",('Wtr-Gas'!BB9)*0.0038) -> 9.88 | AZ7: =IF('Wtr-Gas'!BD9<0,"0",('Wtr-Gas'!BD9)*0.0038) -> 1.52 | BA7: =IF('Wtr-Gas'!BF9<0,"0",('Wtr-Gas'!BF9)*0.0038) -> 0
A8: Orlando | B8: 8 | C8: 2 | D8: 2021 | E8: =IF(Elect!AM10<0,"0",Elect!AM10) -> 697 | F8: =IF(Elect!I10<0,"0",Elect!I10) -> 44480 | G8: =Elect!H10 -> 2.261 | H8: =IF(Elect!F10<0,"0",Elect!F10) -> 39360 | I8: =Elect!E10 -> 1.963 | J8: =IF(Elect!U10<0,"0",Elect!U10) -> 25800 | K8: =Elect!T10 -> 1.978 | L8: =IF(Elect!AJ10<0,"0",Elect!AJ10) -> 0 | M8: =Elect!AI10 -> 0.281 | N8: =IF(Elect!X10<0,"0",Elect!X10) -> 34500 | O8: =Elect!W10 -> 1.7 | P8: =IF(Elect!O10<0,"0",Elect!O10) -> 9200 | Q8: =Elect!N10 -> 2.38 | R8: =IF(Elect!L10<0,"0",Elect!L10) -> 10800 | S8: =Elect!K10 -> 3.05 | T8: =IF(Elect!R10<0,"0",Elect!R10) -> 9200 | U8: =Elect!Q10 -> 2.7 | V8: =IF(Elect!AA10<0,"0",Elect!AA10) -> 5120 | W8: =Elect!Z10 -> 3.38 | X8: =IF(Elect!AD10<0,"0",Elect!AD10) -> 2400 | Y8: =Elect!AC10 -> 2.96 | Z8: =IF(Elect!AG10<0,"0",Elect!AG10) -> 48400 | AA8: =Elect!AF10 -> 2.042 | AB8: =IF(Elect!AX10<0,"0",Elect!AX10) -> 1400 | AC8: =IF(Elect!AV10<0,"0",Elect!AV10) -> 11100 | AD8: =IF(Elect!AZ10<0,"0",Elect!AZ10) -> 891 | AE8: =IF(Elect!BB10<0,"0",Elect!BB10) -> 1920 | AF8: =IF('Wtr-Gas'!E10<0,"0",('Wtr-Gas'!E10)*0.0038) -> 3397.542 | AG8: =IF('Wtr-Gas'!H10<0,"0",('Wtr-Gas'!H10)*0.0038) -> 701.366 | AH8: =IF('Wtr-Gas'!K10<0,"0",('Wtr-Gas'!K10)*0.0038) -> 0.798 | AI8: =IF('Wtr-Gas'!N10<0,"0",('Wtr-Gas'!N10)*0.0038) -> 2150.8 | AJ8: =IF('Wtr-Gas'!Q10<0,"0",('Wtr-Gas'!Q10)*0.0038) -> 83.98 | AK8: =IF('Wtr-Gas'!U10<0,"0",('Wtr-Gas'!U10)*0.0038) -> 797.24 | AL8: =IF('Wtr-Gas'!X10<0,"0",('Wtr-Gas'!X10)*0.0038) -> 6714.6 | AM8: =IF('Wtr-Gas'!AB10<0,"0",('Wtr-Gas'!AB10)*0.0038) -> 3192 | AN8: =IF('Wtr-Gas'!AD10<0,"0",('Wtr-Gas'!AD10)*0.0038) -> 877.914 | AO8: =IF('Wtr-Gas'!AF10<0,"0",('Wtr-Gas'!AF10)*0.0038) -> 4.56 | AP8: =IF('Wtr-Gas'!AH10<0,"0",('Wtr-Gas'!AH10)*0.0038) -> 433.352 | AQ8: =IF('Wtr-Gas'!AJ10<0,"0",('Wtr-Gas'!AJ10)*0.0038) -> 25.783 | AR8: =IF('Wtr-Gas'!AL10<0,"0",('Wtr-Gas'!AL10)*0.0038) -> 562.4 | AS8: =IF('Wtr-Gas'!AN10<0,"0",('Wtr-Gas'!AN10)*0.0038) -> 0.3572 | AT8: =IF('Wtr-Gas'!AP10<0,"0",('Wtr-Gas'!AP10)*0.0038) -> 8.36 | AU8: =IF('Wtr-Gas'!AT10<0,"0",('Wtr-Gas'!AT10)*0.0038) -> 0.5206 | AV8: =IF('Wtr-Gas'!AW10<0,"0",('Wtr-Gas'!AW10)*0.0038) -> 186.2076 | AW8: =IF('Wtr-Gas'!AY10<0,"0",('Wtr-Gas'!AY10)*0.0038) -> 151.2286 | AX8: =IF('Wtr-Gas'!AZ10<0,"0",('Wtr-Gas'!AZ10)*0.0038) -> 34.977252 | AY8: =IF('Wtr-Gas'!BB10<0,"0",('Wtr-Gas'!BB10)*0.0038) -> 6.08 | AZ8: =IF('Wtr-Gas'!BD10<0,"0",('Wtr-Gas'!BD10)*0.0038) -> 1.14 | BA8: =IF('Wtr-Gas'!BF10<0,"0",('Wtr-Gas'!BF10)*0.0038) -> 0
A9: Orlando | B9: 15 | C9: 2 | D9: 2021 | E9: =IF(Elect!AM11<0,"0",Elect!AM11) -> 519 | F9: =IF(Elect!I11<0,"0",Elect!I11) -> 45600 | G9: =Elect!H11 -> 2.261 | H9: =IF(Elect!F11<0,"0",Elect!F11) -> 41440 | I9: =Elect!E11 -> 1.963 | J9: =IF(Elect!U11<0,"0",Elect!U11) -> 68700 | K9: =Elect!T11 -> 2.073 | L9: =IF(Elect!AJ11<0,"0",Elect!AJ11) -> 1440 | M9: =Elect!AI11 -> 0.297 | N9: =IF(Elect!X11<0,"0",Elect!X11) -> 38700 | O9: =Elect!W11 -> 1.7 | P9: =IF(Elect!O11<0,"0",Elect!O11) -> 9200 | Q9: =Elect!N11 -> 2.38 | R9: =IF(Elect!L11<0,"0",Elect!L11) -> 9200 | S9: =Elect!K11 -> 3.05 | T9: =IF(Elect!R11<0,"0",Elect!R11) -> 8400 | U9: =Elect!Q11 -> 2.7 | V9: =IF(Elect!AA11<0,"0",Elect!AA11) -> 5120 | W9: =Elect!Z11 -> 3.38 | X9: =IF(Elect!AD11<0,"0",Elect!AD11) -> 2560 | Y9: =Elect!AC11 -> 2.96 | Z9: =IF(Elect!AG11<0,"0",Elect!AG11) -> 46600 | AA9: =Elect!AF11 -> 2.042 | AB9: =IF(Elect!AX11<0,"0",Elect!AX11) -> 1700 | AC9: =IF(Elect!AV11<0,"0",Elect!AV11) -> 13200 | AD9: =IF(Elect!AZ11<0,"0",Elect!AZ11) -> 895 | AE9: =IF(Elect!BB11<0,"0",Elect!BB11) -> 2120 | AF9: =IF('Wtr-Gas'!E11<0,"0",('Wtr-Gas'!E11)*0.0038) -> 3703.822 | AG9: =IF('Wtr-Gas'!H11<0,"0",('Wtr-Gas'!H11)*0.0038) -> 939.436 | AH9: =IF('Wtr-Gas'!K11<0,"0",('Wtr-Gas'!K11)*0.0038) -> 2.698 | AI9: =IF('Wtr-Gas'!N11<0,"0",('Wtr-Gas'!N11)*0.0038) -> 2929.8 | AJ9: =IF('Wtr-Gas'!Q11<0,"0",('Wtr-Gas'!Q11)*0.0038) -> 88.92 | AK9: =IF('Wtr-Gas'!U11<0,"0",('Wtr-Gas'!U11)*0.0038) -> 824.6 | AL9: =IF('Wtr-Gas'!X11<0,"0",('Wtr-Gas'!X11)*0.0038) -> 3446.6 | AM9: =IF('Wtr-Gas'!AB11<0,"0",('Wtr-Gas'!AB11)*0.0038) -> 6840 | AN9: =IF('Wtr-Gas'!AD11<0,"0",('Wtr-Gas'!AD11)*0.0038) -> 1379.997 | AO9: =IF('Wtr-Gas'!AF11<0,"0",('Wtr-Gas'!AF11)*0.0038) -> 3.23 | AP9: =IF('Wtr-Gas'!AH11<0,"0",('Wtr-Gas'!AH11)*0.0038) -> 410.058 | AQ9: =IF('Wtr-Gas'!AJ11<0,"0",('Wtr-Gas'!AJ11)*0.0038) -> 28.0288 | AR9: =IF('Wtr-Gas'!AL11<0,"0",('Wtr-Gas'!AL11)*0.0038) -> 254.6 | AS9: =IF('Wtr-Gas'!AN11<0,"0",('Wtr-Gas'!AN11)*0.0038) -> 0.0874 | AT9: =IF('Wtr-Gas'!AP11<0,"0",('Wtr-Gas'!AP11)*0.0038) -> 46.74 | AU9: =IF('Wtr-Gas'!AT11<0,"0",('Wtr-Gas'!AT11)*0.0038) -> 0.418 | AV9: =IF('Wtr-Gas'!AW11<0,"0",('Wtr-Gas'!AW11)*0.0038) -> 187.4388 | AW9: =IF('Wtr-Gas'!AY11<0,"0",('Wtr-Gas'!AY11)*0.0038) -> 152.2698 | AX9: =IF('Wtr-Gas'!AZ11<0,"0",('Wtr-Gas'!AZ11)*0.0038) -> 35.16862 | AY9: =IF('Wtr-Gas'!BB11<0,"0",('Wtr-Gas'!BB11)*0.0038) -> 12.92 | AZ9: =IF('Wtr-Gas'!BD11<0,"0",('Wtr-Gas'!BD11)*0.0038) -> 1.52 | BA9: =IF('Wtr-Gas'!BF11<0,"0",('Wtr-Gas'!BF11)*0.0038) -> 0
A10: Orlando | B10: 22 | C10: 2 | D10: 2021 | E10: =IF(Elect!AM12<0,"0",Elect!AM12) -> 528 | F10: =IF(Elect!I12<0,"0",Elect!I12) -> 46880 | G10: =Elect!H12 -> 1.586 | H10: =IF(Elect!F12<0,"0",Elect!F12) -> 40800 | I10: =Elect!E12 -> 1.235 | J10: =IF(Elect!U12<0,"0",Elect!U12) -> 56400 | K10: =Elect!T12 -> 2.185 | L10: =IF(Elect!AJ12<0,"0",Elect!AJ12) -> 1440 | M10: =Elect!AI12 -> 1.71 | N10: =IF(Elect!X12<0,"0",Elect!X12) -> 31200 | O10: =Elect!W12 -> 1.7 | P10: =IF(Elect!O12<0,"0",Elect!O12) -> 9200 | Q10: =Elect!N12 -> 0.068 | R10: =IF(Elect!L12<0,"0",Elect!L12) -> 10800 | S10: =Elect!K12 -> 0.085 | T10: =IF(Elect!R12<0,"0",Elect!R12) -> 9600 | U10: =Elect!Q12 -> 0.071 | V10: =IF(Elect!AA12<0,"0",Elect!AA12) -> 4960 | W10: =Elect!Z12 -> 3.38 | X10: =IF(Elect!AD12<0,"0",Elect!AD12) -> 2720 | Y10: =Elect!AC12 -> 2.96 | Z10: =IF(Elect!AG12<0,"0",Elect!AG12) -> 48000 | AA10: =Elect!AF12 -> 2.7 | AB10: =IF(Elect!AX12<0,"0",Elect!AX12) -> 1800 | AC10: =IF(Elect!AV12<0,"0",Elect!AV12) -> 14200 | AD10: =IF(Elect!AZ12<0,"0",Elect!AZ12) -> 1024 | AE10: =IF(Elect!BB12<0,"0",Elect!BB12) -> 1640 | AF10: =IF('Wtr-Gas'!E12<0,"0",('Wtr-Gas'!E12)*0.0038) -> 3505.272 | AG10: =IF('Wtr-Gas'!H12<0,"0",('Wtr-Gas'!H12)*0.0038) -> 974.13 | AH10: =IF('Wtr-Gas'!K12<0,"0",('Wtr-Gas'!K12)*0.0038) -> 0.608 | AI10: =IF('Wtr-Gas'!N12<0,"0",('Wtr-Gas'!N12)*0.0038) -> 2413 | AJ10: =IF('Wtr-Gas'!Q12<0,"0",('Wtr-Gas'!Q12)*0.0038) -> 99.56 | AK10: =IF('Wtr-Gas'!U12<0,"0",('Wtr-Gas'!U12)*0.0038) -> 843.6 | AL10: =IF('Wtr-Gas'!X12<0,"0",('Wtr-Gas'!X12)*0.0038) -> 4799.4 | AM10: =IF('Wtr-Gas'!AB12<0,"0",('Wtr-Gas'!AB12)*0.0038) -> 5320 | AN10: =IF('Wtr-Gas'!AD12<0,"0",('Wtr-Gas'!AD12)*0.0038) -> 1185.915 | AO10: =IF('Wtr-Gas'!AF12<0,"0",('Wtr-Gas'!AF12)*0.0038) -> 6.042 | AP10: =IF('Wtr-Gas'!AH12<0,"0",('Wtr-Gas'!AH12)*0.0038) -> 411.312 | AQ10: =IF('Wtr-Gas'!AJ12<0,"0",('Wtr-Gas'!AJ12)*0.0038) -> 35.15 | AR10: =IF('Wtr-Gas'!AL12<0,"0",('Wtr-Gas'!AL12)*0.0038) -> 345.8 | AS10: =IF('Wtr-Gas'!AN12<0,"0",('Wtr-Gas'!AN12)*0.0038) -> 0.114 | AT10: =IF('Wtr-Gas'!AP12<0,"0",('Wtr-Gas'!AP12)*0.0038) -> 3.42 | AU10: =IF('Wtr-Gas'!AT12<0,"0",('Wtr-Gas'!AT12)*0.0038) -> 0.4864 | AV10: =IF('Wtr-Gas'!AW12<0,"0",('Wtr-Gas'!AW12)*0.0038) -> 211.698 | AW10: =IF('Wtr-Gas'!AY12<0,"0",('Wtr-Gas'!AY12)*0.0038) -> 172.5694 | AX10: =IF('Wtr-Gas'!AZ12<0,"0",('Wtr-Gas'!AZ12)*0.0038) -> 39.129436 | AY10: =IF('Wtr-Gas'!BB12<0,"0",('Wtr-Gas'!BB12)*0.0038) -> 14.82 | AZ10: =IF('Wtr-Gas'!BD12<0,"0",('Wtr-Gas'!BD12)*0.0038) -> 1.9 | BA10: =IF('Wtr-Gas'!BF12<0,"0",('Wtr-Gas'!BF12)*0.0038) -> 0
A11: Orlando | B11: 28 | C11: 2 | D11: 2021 | E11: =IF(Elect!AM13<0,"0",Elect!AM13) -> 506 | F11: =IF(Elect!I13<0,"0",Elect!I13) -> 47040 | G11: =Elect!H13 -> 2.188 | H11: =IF(Elect!F13<0,"0",Elect!F13) -> 40800 | I11: =Elect!E13 -> 1.934 | J11: =IF(Elect!U13<0,"0",Elect!U13) -> 49200 | K11: =Elect!T13 -> 2.583 | L11: =IF(Elect!AJ13<0,"0",Elect!AJ13) -> 1440 | M11: =Elect!AI13 -> 0.301 | N11: =IF(Elect!X13<0,"0",Elect!X13) -> 48000 | O11: =Elect!W13 -> 1.888 | P11: =IF(Elect!O13<0,"0",Elect!O13) -> 9200 | Q11: =Elect!N13 -> 1.79 | R11: =IF(Elect!L13<0,"0",Elect!L13) -> 10000 | S11: =Elect!K13 -> 2.17 | T11: =IF(Elect!R13<0,"0",Elect!R13) -> 9200 | U11: =Elect!Q13 -> 1.87 | V11: =IF(Elect!AA13<0,"0",Elect!AA13) -> 6240 | W11: =Elect!Z13 -> 3.74 | X11: =IF(Elect!AD13<0,"0",Elect!AD13) -> 3200 | Y11: =Elect!AC13 -> 2.06 | Z11: =IF(Elect!AG13<0,"0",Elect!AG13) -> 48200 | AA11: =Elect!AF13 -> 1.896 | AB11: =IF(Elect!AX13<0,"0",Elect!AX13) -> 1500 | AC11: =IF(Elect!AV13<0,"0",Elect!AV13) -> 11600 | AD11: =IF(Elect!AZ13<0,"0",Elect!AZ13) -> 784 | AE11: =IF(Elect!BB13<0,"0",Elect!BB13) -> 3920 | AF11: =IF('Wtr-Gas'!E13<0,"0",('Wtr-Gas'!E13)*0.0038) -> 3780.848 | AG11: =IF('Wtr-Gas'!H13<0,"0",('Wtr-Gas'!H13)*0.0038) -> 717.668 | AH11: =IF('Wtr-Gas'!K13<0,"0",('Wtr-Gas'!K13)*0.0038) -> 1.026 | AI11: =IF('Wtr-Gas'!N13<0,"0",('Wtr-Gas'!N13)*0.0038) -> 2717 | AJ11: =IF('Wtr-Gas'!Q13<0,"0",('Wtr-Gas'!Q13)*0.0038) -> 101.84 | AK11: =IF('Wtr-Gas'!U13<0,"0",('Wtr-Gas'!U13)*0.0038) -> 855.76 | AL11: =IF('Wtr-Gas'!X13<0,"0",('Wtr-Gas'!X13)*0.0038) -> 4240.8 | AM11: =IF('Wtr-Gas'!AB13<0,"0",('Wtr-Gas'!AB13)*0.0038) -> 6232 | AN11: =IF('Wtr-Gas'!AD13<0,"0",('Wtr-Gas'!AD13)*0.0038) -> 1208.59 | AO11: =IF('Wtr-Gas'!AF13<0,"0",('Wtr-Gas'!AF13)*0.0038) -> 7.22 | AP11: =IF('Wtr-Gas'!AH13<0,"0",('Wtr-Gas'!AH13)*0.0038) -> 412.718 | AQ11: =IF('Wtr-Gas'!AJ13<0,"0",('Wtr-Gas'!AJ13)*0.0038) -> 30.3164 | AR11: =IF('Wtr-Gas'!AL13<0,"0",('Wtr-Gas'!AL13)*0.0038) -> 345.8 | AS11: =IF('Wtr-Gas'!AN13<0,"0",('Wtr-Gas'!AN13)*0.0038) -> 0.0798 | AT11: =IF('Wtr-Gas'!AP13<0,"0",('Wtr-Gas'!AP13)*0.0038) -> 14.06 | AU11: =IF('Wtr-Gas'!AT13<0,"0",('Wtr-Gas'!AT13)*0.0038) -> 0.3078 | AV11: =IF('Wtr-Gas'!AW13<0,"0",('Wtr-Gas'!AW13)*0.0038) -> 162.6286 | AW11: =IF('Wtr-Gas'!AY13<0,"0",('Wtr-Gas'!AY13)*0.0038) -> 128.2044 | AX11: =IF('Wtr-Gas'!AZ13<0,"0",('Wtr-Gas'!AZ13)*0.0038) -> 34.42439 | AY11: =IF('Wtr-Gas'!BB13<0,"0",('Wtr-Gas'!BB13)*0.0038) -> 18.24 | AZ11: =IF('Wtr-Gas'!BD13<0,"0",('Wtr-Gas'!BD13)*0.0038) -> 1.14 | BA11: =IF('Wtr-Gas'!BF13<0,"0",('Wtr-Gas'!BF13)*0.0038) -> 0.0038
A12: Orlando | B12: 8 | C12: 3 | D12: 2021 | E12: =IF(Elect!AM14<0,"0",Elect!AM14) -> 513 | F12: =IF(Elect!I14<0,"0",Elect!I14) -> 47520 | G12: =Elect!H14 -> 2.378 | H12: =IF(Elect!F14<0,"0",Elect!F14) -> 41920 | I12: =Elect!E14 -> 1.934 | J12: =IF(Elect!U14<0,"0",Elect!U14) -> 29700 | K12: =Elect!T14 -> 2.583 | L12: =IF(Elect!AJ14<0,"0",Elect!AJ14) -> 1480 | M12: =Elect!AI14 -> 0.301 | N12: =IF(Elect!X14<0,"0",Elect!X14) -> 57000 | O12: =Elect!W14 -> 1.969 | P12: =IF(Elect!O14<0,"0",Elect!O14) -> 9600 | Q12: =Elect!N14 -> 1.95 | R12: =IF(Elect!L14<0,"0",Elect!L14) -> 9600 | S12: =Elect!K14 -> 2.24 | T12: =IF(Elect!R14<0,"0",Elect!R14) -> 8800 | U12: =Elect!Q14 -> 1.96 | V12: =IF(Elect!AA14<0,"0",Elect!AA14) -> 6400 | W12: =Elect!Z14 -> 3.79 | X12: =IF(Elect!AD14<0,"0",Elect!AD14) -> 3040 | Y12: =Elect!AC14 -> 2.06 | Z12: =IF(Elect!AG14<0,"0",Elect!AG14) -> 49600 | AA12: =Elect!AF14 -> 1.994 | AB12: =IF(Elect!AX14<0,"0",Elect!AX14) -> 1600 | AC12: =IF(Elect!AV14<0,"0",Elect!AV14) -> 12800 | AD12: =IF(Elect!AZ14<0,"0",Elect!AZ14) -> 901 | AE12: =IF(Elect!BB14<0,"0",Elect!BB14) -> 2640 | AF12: =IF('Wtr-Gas'!E14<0,"0",('Wtr-Gas'!E14)*0.0038) -> 3679.502 | AG12: =IF('Wtr-Gas'!H14<0,"0",('Wtr-Gas'!H14)*0.0038) -> 809.21 | AH12: =IF('Wtr-Gas'!K14<0,"0",('Wtr-Gas'!K14)*0.0038) -> 3.192 | AI12: =IF('Wtr-Gas'!N14<0,"0",('Wtr-Gas'!N14)*0.0038) -> 2527 | AJ12: =IF('Wtr-Gas'!Q14<0,"0",('Wtr-Gas'!Q14)*0.0038) -> 104.88 | AK12: =IF('Wtr-Gas'!U14<0,"0",('Wtr-Gas'!U14)*0.0038) -> 879.7 | AL12: =IF('Wtr-Gas'!X14<0,"0",('Wtr-Gas'!X14)*0.0038) -> 5149 | AM12: =IF('Wtr-Gas'!AB14<0,"0",('Wtr-Gas'!AB14)*0.0038) -> 5320 | AN12: =IF('Wtr-Gas'!AD14<0,"0",('Wtr-Gas'!AD14)*0.0038) -> 1201.2663 | AO12: =IF('Wtr-Gas'!AF14<0,"0",('Wtr-Gas'!AF14)*0.0038) -> 5.51 | AP12: =IF('Wtr-Gas'!AH14<0,"0",('Wtr-Gas'!AH14)*0.0038) -> 502.702 | AQ12: =IF('Wtr-Gas'!AJ14<0,"0",('Wtr-Gas'!AJ14)*0.0038) -> 36.6092 | AR12: =IF('Wtr-Gas'!AL14<0,"0",('Wtr-Gas'!AL14)*0.0038) -> 342 | AS12: =IF('Wtr-Gas'!AN14<0,"0",('Wtr-Gas'!AN14)*0.0038) -> 0.1254 | AT12: =IF('Wtr-Gas'!AP14<0,"0",('Wtr-Gas'!AP14)*0.0038) -> 3.04 | AU12: =IF('Wtr-Gas'!AT14<0,"0",('Wtr-Gas'!AT14)*0.0038) -> 0.285 | AV12: =IF('Wtr-Gas'!AW14<0,"0",('Wtr-Gas'!AW14)*0.0038) -> 191.2388 | AW12: =IF('Wtr-Gas'!AY14<0,"0",('Wtr-Gas'!AY14)*0.0038) -> 150.4838 | AX12: =IF('Wtr-Gas'!AZ14<0,"0",('Wtr-Gas'!AZ14)*0.0038) -> 40.755342 | AY12: =IF('Wtr-Gas'!BB14<0,"0",('Wtr-Gas'!BB14)*0.0038) -> 11.4 | AZ12: =IF('Wtr-Gas'!BD14<0,"0",('Wtr-Gas'!BD14)*0.0038) -> 2.28 | BA12: =IF('Wtr-Gas'!BF14<0,"0",('Wtr-Gas'!BF14)*0.0038) -> 265.924
A13: Orlando | B13: 15 | C13: 3 | D13: 2021 | E13: =IF(Elect!AM15<0,"0",Elect!AM15) -> 524 | F13: =IF(Elect!I15<0,"0",Elect!I15) -> 46560 | G13: =Elect!H15 -> 2.378 | H13: =IF(Elect!F15<0,"0",Elect!F15) -> 40960 | I13: =Elect!E15 -> 1.947 | J13: =IF(Elect!U15<0,"0",Elect!U15) -> 32100 | K13: =Elect!T15 -> 2.583 | L13: =IF(Elect!AJ15<0,"0",Elect!AJ15) -> 1400 | M13: =Elect!AI15 -> 0.301 | N13: =IF(Elect!X15<0,"0",Elect!X15) -> 41400 | O13: =Elect!W15 -> 1.969 | P13: =IF(Elect!O15<0,"0",Elect!O15) -> 9200 | Q13: =Elect!N15 -> 1.95 | R13: =IF(Elect!L15<0,"0",Elect!L15) -> 9600 | S13: =Elect!K15 -> 2.28 | T13: =IF(Elect!R15<0,"0",Elect!R15) -> 8800 | U13: =Elect!Q15 -> 1.98 | V13: =IF(Elect!AA15<0,"0",Elect!AA15) -> 5120 | W13: =Elect!Z15 -> 3.79 | X13: =IF(Elect!AD15<0,"0",Elect!AD15) -> 2560 | Y13: =Elect!AC15 -> 2.06 | Z13: =IF(Elect!AG15<0,"0",Elect!AG15) -> 50200 | AA13: =Elect!AF15 -> 2.045 | AB13: =IF(Elect!AX15<0,"0",Elect!AX15) -> 1600 | AC13: =IF(Elect!AV15<0,"0",Elect!AV15) -> 11700 | AD13: =IF(Elect!AZ15<0,"0",Elect!AZ15) -> 877 | AE13: =IF(Elect!BB15<0,"0",Elect!BB15) -> 4680 | AF13: =IF('Wtr-Gas'!E15<0,"0",('Wtr-Gas'!E15)*0.0038) -> 4172.932 | AG13: =IF('Wtr-Gas'!H15<0,"0",('Wtr-Gas'!H15)*0.0038) -> 805.752 | AH13: =IF('Wtr-Gas'!K15<0,"0",('Wtr-Gas'!K15)*0.0038) -> 2.85 | AI13: =IF('Wtr-Gas'!N15<0,"0",('Wtr-Gas'!N15)*0.0038) -> 2595.4 | AJ13: =IF('Wtr-Gas'!Q15<0,"0",('Wtr-Gas'!Q15)*0.0038) -> 92.34 | AK13: =IF('Wtr-Gas'!U15<0,"0",('Wtr-Gas'!U15)*0.0038) -> 825.36 | AL13: =IF('Wtr-Gas'!X15<0,"0",('Wtr-Gas'!X15)*0.0038) -> 5502.4 | AM13: =IF('Wtr-Gas'!AB15<0,"0",('Wtr-Gas'!AB15)*0.0038) -> 4826 | AN13: =IF('Wtr-Gas'!AD15<0,"0",('Wtr-Gas'!AD15)*0.0038) -> 996.76774 | AO13: =IF('Wtr-Gas'!AF15<0,"0",('Wtr-Gas'!AF15)*0.0038) -> 9.918 | AP13: =IF('Wtr-Gas'!AH15<0,"0",('Wtr-Gas'!AH15)*0.0038) -> 395.276 | AQ13: =IF('Wtr-Gas'!AJ15<0,"0",('Wtr-Gas'!AJ15)*0.0038) -> 53.6104 | AR13: =IF('Wtr-Gas'!AL15<0,"0",('Wtr-Gas'!AL15)*0.0038) -> 733.4 | AS13: =IF('Wtr-Gas'!AN15<0,"0",('Wtr-Gas'!AN15)*0.0038) -> 0.2166 | AT13: =IF('Wtr-Gas'!AP15<0,"0",('Wtr-Gas'!AP15)*0.0038) -> 3.42 | AU13: =IF('Wtr-Gas'!AT15<0,"0",('Wtr-Gas'!AT15)*0.0038) -> 0.4408 | AV13: =IF('Wtr-Gas'!AW15<0,"0",('Wtr-Gas'!AW15)*0.0038) -> 44.935 | AW13: =IF('Wtr-Gas'!AY15<0,"0",('Wtr-Gas'!AY15)*0.0038) -> 142.6634 | AX13: =IF('Wtr-Gas'!AZ15<0,"0",('Wtr-Gas'!AZ15)*0.0038) -> 0 | AY13: =IF('Wtr-Gas'!BB15<0,"0",('Wtr-Gas'!BB15)*0.0038) -> 18.62 | AZ13: =IF('Wtr-Gas'!BD15<0,"0",('Wtr-Gas'!BD15)*0.0038) -> 1.14 | BA13: =IF('Wtr-Gas'!BF15<0,"0",('Wtr-Gas'!BF15)*0.0038) -> 1001.3874
... A62: Orlando | B62: 31 | C62: 12 | D62: 2021 | E62: =IF(Elect!AM64<0,"0",Elect!AM64) -> 0 | F62: =IF(Elect!I64<0,"0",Elect!I64) -> 0 | G62: =Elect!H64 -> 0 | H62: =IF(Elect!F64<0,"0",Elect!F64) -> 0 | I62: =Elect!E64 -> 0 | J62: =IF(Elect!U64<0,"0",Elect!U64) -> 0 | K62: =Elect!T64 -> 0 | L62: =IF(Elect!AJ64<0,"0",Elect!AJ64) -> 0 | M62: =Elect!AI64 -> 0 | N62: =IF(Elect!X64<0,"0",Elect!X64) -> 0 | O62: =Elect!W64 -> 0 | P62: =IF(Elect!O64<0,"0",Elect!O64) -> 0 | Q62: =Elect!N64 -> 0 | R62: =IF(Elect!L64<0,"0",Elect!L64) -> 0 | S62: =Elect!K64 -> 0 | T62: =IF(Elect!R64<0,"0",Elect!R64) -> 0 | U62: =Elect!Q64 -> 0 | V62: =IF(Elect!AA64<0,"0",Elect!AA64) -> 0 | W62: =Elect!Z64 -> 0 | X62: =IF(Elect!AD64<0,"0",Elect!AD64) -> 0 | Y62: =Elect!AC64 -> 0 | Z62: =IF(Elect!AG64<0,"0",Elect!AG64) -> 0 | AA62: =Elect!AF64 -> 0 | AB62: =IF(Elect!AX64<0,"0",Elect!AX64) -> 0 | AC62: =IF(Elect!AV64<0,"0",Elect!AV64) -> 0 | AD62: =IF(Elect!AZ64<0,"0",Elect!AZ64) -> 0 | AE62: =IF(Elect!BB64<0,"0",Elect!BB64) -> 0 | AF62: =IF('Wtr-Gas'!E64<0,"0",('Wtr-Gas'!E64)*0.0038) -> 0 | AG62: =IF('Wtr-Gas'!H64<0,"0",('Wtr-Gas'!H64)*0.0038) -> 0 | AH62: =IF('Wtr-Gas'!K64<0,"0",('Wtr-Gas'!K64)*0.0038) -> 0 | AI62: =IF('Wtr-Gas'!N64<0,"0",('Wtr-Gas'!N64)*0.0038) -> 0 | AJ62: =IF('Wtr-Gas'!Q64<0,"0",('Wtr-Gas'!Q64)*0.0038) -> 0 | AK62: =IF('Wtr-Gas'!U64<0,"0",('Wtr-Gas'!U64)*0.0038) -> 0 | AL62: =IF('Wtr-Gas'!X64<0,"0",('Wtr-Gas'!X64)*0.0038) -> 0 | AM62: =IF('Wtr-Gas'!AB64<0,"0",('Wtr-Gas'!AB64)*0.0038) -> 0 | AN62: =IF('Wtr-Gas'!AD64<0,"0",('Wtr-Gas'!AD64)*0.0038) -> 0 | AO62: =IF('Wtr-Gas'!AF64<0,"0",('Wtr-Gas'!AF64)*0.0038) -> 0 | AP62: =IF('Wtr-Gas'!AH64<0,"0",('Wtr-Gas'!AH64)*0.0038) -> 0 | AQ62: =IF('Wtr-Gas'!AJ64<0,"0",('Wtr-Gas'!AJ64)*0.0038) -> 0 | AR62: =IF('Wtr-Gas'!AL64<0,"0",('Wtr-Gas'!AL64)*0.0038) -> 0 | AS62: =IF('Wtr-Gas'!AN64<0,"0",('Wtr-Gas'!AN64)*0.0038) -> 0 | AT62: =IF('Wtr-Gas'!AP64<0,"0",('Wtr-Gas'!AP64)*0.0038) -> 0 | AU62: =IF('Wtr-Gas'!AT64<0,"0",('Wtr-Gas'!AT64)*0.0038) -> 0 | AV62: =IF('Wtr-Gas'!AW64<0,"0",('Wtr-Gas'!AW64)*0.0038) -> 0 | AW62: =IF('Wtr-Gas'!AY64<0,"0",('Wtr-Gas'!AY64)*0.0038) -> 0 | AX62: =IF('Wtr-Gas'!AZ64<0,"0",('Wtr-Gas'!AZ64)*0.0038) -> 0 | AY62: =IF('Wtr-Gas'!BB64<0,"0",('Wtr-Gas'!BB64)*0.0038) -> 0 | AZ62: =IF('Wtr-Gas'!BD64<0,"0",('Wtr-Gas'!BD64)*0.0038) -> 0 | BA62: =IF('Wtr-Gas'!BF64<0,"0",('Wtr-Gas'!BF64)*0.0038) -> 0

Sheet Info
B4: Electrical
B5: Location | C5: Transformer # | D5: Meter Serial # | E5: Reedy Creek # | F5: Service Area | G5: Multiplier | I5: Reedy Creek Description
B6: Service Yard #2 | C6: T7384 | D6: 68 425 008 | E6: CC0913A018 | G6: 160 | I6: HSB2 Section 1&2, Building A
B7: Service Yard #2 | C7: T2392 | D7: 68 425 010 | E7: CC0913A020 | G7: 160 | I7: HSB2 Section 4&5, Building A
B8: Service Yard #2 | C8: T2393 | D8: 68 425 078 | E8: CC0913A060 | G8: 400 | I8: LSB2 Building A - T2395
B9: Service Yard #2 | C9: T2395 | D9: 68 425 077 | E9: CC0913A059 | G9: 400 | I9: LSB2 Building A - T2393
B10: Service Yard #2 | C10: T7285 | D10: 68 425 071 | E10: CC0913A081 | G10: 400 | I10: LSB2 Building A - T7285
B11: Service Yard #1 | C11: T7380 | D11: 68 425 060 | E11: CC0913A054 | G11: 300 | I11: Main Electric Room #1
B12: Service Yard #1 | C12: T2390 | D12: 68 425 059 | E12: CC0913A053 | G12: 300 | I12: Service Yard #1
B13: Service Yard #1 | C13: T7382 | D13: 68 425 093 | E13: CC0913A075 | G13: 160 | I13: Main Electric Room #1 South
B14: Service Yard #1 | C14: T2391 | D14: 68 425 094 | E14: CC0913A076 | G14: 160 | I14: Main Electric Room #1 South
B15: Servcie Yard #3 | C15: T7283 | D15: 90 625 242 | E15: CC0912A18 | G15: 200 | I15: Out Buildings
B16: Servcie Yard #3 | C16: T7281 | D16: 68 425 097 | E16: CC0913A095 | G16: 40 | I16: Out Buildings
B17: Remote Parking Lot Lights | C17: T2009 | D17: 90 630 431 | E17: CS0212A003 | G17: 1 | I17: Employee Parking Lot Lights
B18: Golf Maintenance | D18: 67273163 | E18: CC0612A036 | I18: Golf Maintenace
B19: Golf Clubhouse | D19: 67662513 | E19: CG0612A084 | I19: Golf Clubhouse
B20: Golf Comfort Stations | D20: 61979920 | E20: CS0210A030 | I20: Comfort Stations
B21: Golf Irrigation Pump House | D21: 56253208 | E21: IC0608A03 | I21: Irrigation Pump House
B24: Water
B25: Service Entry | D25: 74860172 | E25: x10 | F25: Main Potable Water Feed | I25: Water
B26: Service Entry | D26: 74860173 | E26: x10 | F26: Re-use Water Feed | I26: Reclaimed Water
B27: Pump Room | D27: 44553004 | E27: x10 | F27: Fire System Make-up Feed
B28: Pump Room | D28: 70275191 | E28: x100 | F28: PW Feed for Bldg A | I28: Installed 1/31/14
B29: Boiler Room | D29: 2130521 | E29: x100 | F29: Steam Boiler M/U Water | I29: Installed 4/15/14
B31: Deduct Meters | C31: Added 7/15
B32: Chiller Room | D32: 79177804 | E32: x1 | F32: Make-up to Cooling Towers
B33: Chiller Room | D33: 79305675 | E33: x1 | F33: Cooling Tower Blowdown
B34: Building E | D34: 7919004D | E34: x1000 | F34: Irrigation Water
B35: Building E | D35: 79190041 | E35: x1000 | F35: Potable Water
B36: Building J | D36: 79190039 | E36: x1 | F36: Irrigation Water
B37: Lazy River | C37: Added 10/20/15 | D37: 79324776 | E37: x1000 | F37: Potable make-up water for Lazy River
B38: Building E - Inside | C38: Added 11/24/15 | D38: 112014001775 | E38: x100 | F38: Pool Hydranic Heater Make-up Water
B39: Service Yard #2 | C39: Added 11/24/15 | D39: 112014001771 | E39: x100 | F39: Mens and Womens Spa Pool Make-up Water
B43: Changes to Meters
B44: Exterior Pump Room | D44: 12C004186-C1 | E44: x100 | F44: Main Gas Feed | I44: Meter changed on 11/19/14
D45: 04B000408 | E45: 41962 | I45: New Meter Serial Number - Start Number 4668
B46: Golf Course Irrigation | D46: 80606729 | E46: 42522 | I46: New Meter Serial Number - Start Number 0
B48: Cooling Tower M/U Meter | D48: 85492530 | E48: 43698 | I48: Meter Changed by RCID
B51: Disputed Bill | D51: Customer # | E51: Account #
D52: 10816233 | E52: 2236896 | I52: ???

Sheet Logsheet
B1: Four Seasons Utility Readings
N2: updated 9/1/19
B3: Water Meters
B4: 74860172 | D4: 74860173 | F4: 44553004 | H4: 70275191 | J4: 2130521 | L4: 04B000408 | N4: 93477704
B6: Main PW Feed | D6: Main RW Feed | F6: Fire Prot Water Feed | H6: Potable Wtr Bldg A | J6: Steam Boiler M/U | L6: Main Gas Meter 2# | N6: Main Gas Meter 5#
B9: 85492530 | D9: 79305675 | F9: 79190041 | H9: 7919004D | J9: 79190039 | L9: 79324776
B10: Chiller Room | D10: Chiller Room | F10: Building E | H10: Building E | J10: Building J | L10: Lazy River | N10: Capa Terrace
B11: Cooling Tower M/U | D11: Cooling Tower Bleed | F11: Potable Water | H11: Irrigation | J11: Irrigation | L11: Potable Water | N11: Landscaping Mtr
B14: Electric Meters Service Yard #2
B15: CC0913A018 | D15: CC0913A020 | F15: CC0913A060 | H15: CC0913A059 | J15: CC0913A081
B16: 68 425 008 | C16: T7384 | D16: 68 425 010 | E16: T2392 | F16: 68 425 078 | G16: T2393 | H16: 68 425 077 | I16: T2395 | J16: 68 425 071 | K16: T7285
B17: KWH | C17: Demand | D17: KWH | E17: Demand | F17: KWH | G17: Demand | H17: KWH | I17: Demand | J17: KWH | K17: Demand
B20: Central Plant Service Yard | J20: Building E
B21: CC0913A054 | D21: CC0913A053 | F21: CC0913A075 | H21: CC0913A076 | J21: CC0912A18 | L21: CC0913A095
B22: 68 425 060 | C22: T7380 | D22: 68 425 059 | E22: T2390 | F22: 68 425 093 | G22: T7382 | H22: 68 425 094 | I22: T2391 | J22: 90 625 242 | K22: T7283 | L22: 68 425 097 | M22: T7281
B23: KWH | C23: Demand | D23: KWH | E23: Demand | F23: KWH | G23: Demand | H23: KWH | I23: Demand | J23: KWH | K23: Demand | L23: KWH | M23: Demand
B26: Employee Parking | D26: Emerg Generator | J26: 112014001775 | L26: 112014001771
B27: CS0212A003 | D27: GEN01 | J27: Building E - Inside | L27: Service Yard #2
B28: 90 630 431 | C28: T2009 | D28: Tank Level | J28: Pool Hydranic Heater | L28: Spa Jacuzzi's
B29: KWH | D29: 1/4-3/4 | J29: Make-up Water | L29: Make-up Water

Sheet Golf Logsheet
B2: Water Meters
B3: 73337589 | D3: 65956268 | F3: 1334021 | H3: 63265094 | J3: 80606729
B5: Club House | D5: Club House Deduct | F5: Golf Maintenance | H5: Comfort Stations | J5: Irrigation Reclaim Water
B8: Electric Meters
B9: CG0612A084 | D9: CC0612A036 | H9: CS0210A0300 | J9: IC0608A03
B10: 676 62 513 | D10: 672 73 163 | H10: 61 979 920 | J10: 56 253 208
B11: Club House | D11: Golf Maintenance | H11: Comfort Stations | J11: Irrigation Pump House
B14: Natural Gas / Petroleum
B15: 82SJ729151 | D15: Propane Tank #1 | F15: Propane Tank #2 | H15: Unleaded Tank | J15: Diesel Tank | L15: Lube Oil Tank
B16: 46801014
B17: Nat Gas-Clubhouse | D17: Golf Maintenance | F17: Golf Maintenance | H17: Golf Mainenance | J17: Golf Maintenance | L17: Golf Maintenance

Sheet Graphs
B2: Jan | C2: Feb | D2: Mar | E2: Apr | F2: May | G2: Jun | H2: Jul | I2: Aug | J2: Sep | K2: Oct | L2: Nov | M2: Dec | O2: KWH | P2: Fuel Surcharge | Q2: Demand
Z3: Electric | AA3: Gas
Y5: 2015 | Z5: =([1]Elect!#REF!) -> #REF!
Y6: 2016 | Z6: =([1]Elect!#REF!) -> #REF!
Y7: 2017 | Z7: =([1]Elect!#REF!) -> #REF!
Y8: 2018 | Z8: =([1]Elect!#REF!) -> #REF!
Y9: 2019 | Z9: =([1]Elect!#REF!) -> #REF!
X21: hi

Sheet Drawing
B3: Utility Distribution
B4: Four Seasons Resort Orlando at Walt Disney World Resort
B5: Electrical, Potable Water, Re-use Water, Natural Gas
AU14: Water Deduct Meters downstream | BX14: Golf Course Water
AU15: of the main water meter for the Resort | BX15: Distribution
AU16: Meter Numbers Listed | BX16: Meter Numbers Listed
AY18: Bldg A Fire | CL18: Golf Clubhouse
AY19: Sprinkler System | BY19: Golf Clubhouse | CL19: Flushing Valve
AY20: Make-up | BY20: 73337589 | CL20: Deduct
AY21: 44553004 | CL21: 65956268
G22: 12" Potable Water Line | AA22: Domestic Water
G23: Feed from | AA23: from RCES
G24: RCES | AA24: 74860172
AY25: Bdlg A Potable | BY25: Golf Maint
AY26: Water Feed | BY26: Facility
AY27: 70275191 | BY27: 1334021
CK28: Golf Course
M29: 8" Re-use Water Line | AA29: Re-use Water | CK29: Re-Use Irrigation
M30: Feed from | AA30: from RCES | CK30: 67327447
M31: RCES | AA31: 74860173
BY32: Golf Course
AY33: Steam Boilers | BY33: Comfort Stations
AY34: Make-up Water | BY34: 63265094
AY35: 2130521
AJ36: Landscaping
AJ37: Re-use System
AY40: Cooling Tower | BL40: Cooling Twr
AA41: Out Buildings | AY41: Make-up Water | BL41: Blowdown
AA42: Natural Gas Meter | AY42: 79177804 | BL42: Line Deduct
AA43: 93477704 | BL43: 79305675
M45: Natural Gas
M46: Feed at 50 PSI
M47: Reduced to 2 PSI | AY47: Bldg E Potable
M48: for building | AA48: Resort Natural | AY48: Water Meter
M49: Distribution | AA49: Gas Meter | AY49: 79190041
AA50: 12C004186-C1
AY54: Bldg J Irrigation
AY55: Water Meter
AA56: Golf Clubhouse | AY56: 79190039
AA57: Natural Gas
...

Sheet Occupancy
P1: Rooms Dept. | Q1: Total Occupied
P2: Room Nights Input
B3: CDD | C3: HDD | E3: % Occ | F3: 2021 | N3: 01 | O3: Month: January | Q3: =+P3/444 -> 0
A4: Jan | G4: 13764 | H4: =SUM(F4*G4) -> 0 | N4: 02 | O4: Month: January | Q4: =+P4/444 -> 0
