Workbook

Sheet TOTAL
A1: Site Name | B1: Day | C1: Month | D1: Year | E1: Total Electricity Kwh | F1: Electricity Tariff ($/Kwh) | G1: Natual Gas (m3) | H1: Natural Gas $/m3 | I1: Water Utility Supply (m3) m3 | J1: Water Utility Supply (m3) $/m3 | K1: Room Nights
A2: Cairo at Nile Plaza | B2: 1 | C2: 2 | D2: 2022 | E2: =(((Submetering!O2+Submetering!P2)*0.842284+Submetering!Q2+(Submetering!M2+Submetering!N2+Submetering!Y2)*0.7362)+(Submetering!O2+Submetering!P2+Submetering!Q2)*0.1488+(Submetering!M2+Submetering!N2+Submetering!Y2)*0.1167+(Submetering!K2+Submetering!L2-Submetering!Z2-Submetering!AA2-Submetering!AB2-Submetering!AC2-Submetering!Q2)+(Submetering!M2+Submetering!N2+Submetering!Y2)*0.1139) -> 37785.874 | F2: 1.27 | G2: =Gas!C3*0.9147 -> 4556.1207 | H2: 3.65 | I2: =Submetering!H2+Submetering!AD2+Submetering!AE2 -> 646 | J2: 10.03 | K2: =ELECT.!B3 -> 235
A3: Cairo at Nile Plaza | B3: =B2+1 -> 2 | C3: 2 | D3: 2022 | E3: =(((Submetering!O3+Submetering!P3)*0.842284+Submetering!Q3+(Submetering!M3+Submetering!N3+Submetering!Y3)*0.7362)+(Submetering!O3+Submetering!P3+Submetering!Q3)*0.1488+(Submetering!M3+Submetering!N3+Submetering!Y3)*0.1167+(Submetering!K3+Submetering!L3-Submetering!Z3-Submetering!AA3-Submetering!AB3-Submetering!AC3-Submetering!Q3)+(Submetering!M3+Submetering!N3+Submetering!Y3)*0.1139) -> 51787.769 | F3: 1.27 | G3: =Gas!C4*0.9147 -> 3151.1415 | H3: 3.65 | I3: =Submetering!H3+Submetering!AD3+Submetering!AE3 -> 616 | J3: 10.03 | K3: =ELECT.!B4 -> 190
A4: Cairo at Nile Plaza | B4: =B3+1 -> 3 | C4: 2 | D4: 2022 | E4: =(((Submetering!O4+Submetering!P4)*0.842284+Submetering!Q4+(Submetering!M4+Submetering!N4+Submetering!Y4)*0.7362)+(Submetering!O4+Submetering!P4+Submetering!Q4)*0.1488+(Submetering!M4+Submetering!N4+Submetering!Y4)*0.1167+(Submetering!K4+Submetering!L4-Submetering!Z4-Submetering!AA4-Submetering!AB4-Submetering!AC4-Submetering!Q4)+(Submetering!M4+Submetering!N4+Submetering!Y4)*0.1139) -> 30046.785 | F4: 1.27 | G4: =Gas!C5*0.9147 -> 3087.1125 | H4: 3.65 | I4: =Submetering!H4+Submetering!AD4+Submetering!AE4 -> 616 | J4: 10.03 | K4: =ELECT.!B5 -> 182
A5: Cairo at Nile Plaza | B5: =B4+1 -> 4 | C5: 2 | D5: 2022 | E5: =(((Submetering!O5+Submetering!P5)*0.842284+Submetering!Q5+(Submetering!M5+Submetering!N5+Submetering!Y5)*0.7362)+(Submetering!O5+Submetering!P5+Submetering!Q5)*0.1488+(Submetering!M5+Submetering!N5+Submetering!Y5)*0.1167+(Submetering!K5+Submetering!L5-Submetering!Z5-Submetering!AA5-Submetering!AB5-Submetering!AC5-Submetering!Q5)+(Submetering!M5+Submetering!N5+Submetering!Y5)*0.1139) -> 48904.452 | F5: 1.27 | G5: =Gas!C6*0.9147 -> 2825.5083 | H5: 3.65 | I5: =Submetering!H5+Submetering!AD5+Submetering!AE5 -> 546 | J5: 10.03 | K5: =ELECT.!B6 -> 178
A6: Cairo at Nile Plaza | B6: =B5+1 -> 5 | C6: 2 | D6: 2022 | E6: =(((Submetering!O6+Submetering!P6)*0.842284+Submetering!Q6+(Submetering!M6+Submetering!N6+Submetering!Y6)*0.7362)+(Submetering!O6+Submetering!P6+Submetering!Q6)*0.1488+(Submetering!M6+Submetering!N6+Submetering!Y6)*0.1167+(Submetering!K6+Submetering!L6-Submetering!Z6-Submetering!AA6-Submetering!AB6-Submetering!AC6-Submetering!Q6)+(Submetering!M6+Submetering!N6+Submetering!Y6)*0.1139) -> 41927.922 | F6: 1.27 | G6: =Gas!C7*0.9147 -> 2716.659 | H6: 3.65 | I6: =Submetering!H6+Submetering!AD6+Submetering!AE6 -> 646 | J6: 10.03 | K6: =ELECT.!B7 -> 211
A7: Cairo at Nile Plaza | B7: =B6+1 -> 6 | C7: 2 | D7: 2022 | E7: =(((Submetering!O7+Submetering!P7)*0.842284+Submetering!Q7+(Submetering!M7+Submetering!N7+Submetering!Y7)*0.7362)+(Submetering!O7+Submetering!P7+Submetering!Q7)*0.1488+(Submetering!M7+Submetering!N7+Submetering!Y7)*0.1167+(Submetering!K7+Submetering!L7-Submetering!Z7-Submetering!AA7-Submetering!AB7-Submetering!AC7-Submetering!Q7)+(Submetering!M7+Submetering!N7+Submetering!Y7)*0.1139) -> 54278.329 | F7: 1.27 | G7: =Gas!C8*0.9147 -> 2430.3579 | H7: 3.65 | I7: =Submetering!H7+Submetering!AD7+Submetering!AE7 -> 646 | J7: 10.03 | K7: =ELECT.!B8 -> 216
A8: Cairo at Nile Plaza | B8: =B7+1 -> 7 | C8: 2 | D8: 2022 | E8: =(((Submetering!O8+Submetering!P8)*0.842284+Submetering!Q8+(Submetering!M8+Submetering!N8+Submetering!Y8)*0.7362)+(Submetering!O8+Submetering!P8+Submetering!Q8)*0.1488+(Submetering!M8+Submetering!N8+Submetering!Y8)*0.1167+(Submetering!K8+Submetering!L8-Submetering!Z8-Submetering!AA8-Submetering!AB8-Submetering!AC8-Submetering!Q8)+(Submetering!M8+Submetering!N8+Submetering!Y8)*0.1139) -> 33188.191 | F8: 1.27 | G8: =Gas!C9*0.9147 -> 2282.1765 | H8: 3.65 | I8: =Submetering!H8+Submetering!AD8+Submetering!AE8 -> 606 | J8: 10.03 | K8: =ELECT.!B9 -> 264
A9: Cairo at Nile Plaza | B9: =B8+1 -> 8 | C9: 2 | D9: 2022 | E9: =(((Submetering!O9+Submetering!P9)*0.842284+Submetering!Q9+(Submetering!M9+Submetering!N9+Submetering!Y9)*0.7362)+(Submetering!O9+Submetering!P9+Submetering!Q9)*0.1488+(Submetering!M9+Submetering!N9+Submetering!Y9)*0.1167+(Submetering!K9+Submetering!L9-Submetering!Z9-Submetering!AA9-Submetering!AB9-Submetering!AC9-Submetering!Q9)+(Submetering!M9+Submetering!N9+Submetering!Y9)*0.1139) -> 53966.054 | F9: 1.27 | G9: =Gas!C10*0.9147 -> 3176.7531 | H9: 3.65 | I9: =Submetering!H9+Submetering!AD9+Submetering!AE9 -> 696 | J9: 10.03 | K9: =ELECT.!B10 -> 242
A10: Cairo at Nile Plaza | B10: =B9+1 -> 9 | C10: 2 | D10: 2022 | E10: =(((Submetering!O10+Submetering!P10)*0.842284+Submetering!Q10+(Submetering!M10+Submetering!N10+Submetering!Y10)*0.7362)+(Submetering!O10+Submetering!P10+Submetering!Q10)*0.1488+(Submetering!M10+Submetering!N10+Submetering!Y10)*0.1167+(Submetering!K10+Submetering!L10-Submetering!Z10-Submetering!AA10-Submetering!AB10-Submetering!AC10-Submetering!Q10)+(Submetering!M10+Submetering!N10+Submetering!Y10)*0.1139) -> 0 | F10: 1.27 | G10: =Gas!C11*0.9147 -> 0 | H10: 3.65 | I10: =Submetering!H10+Submetering!AD10+Submetering!AE10 -> -194 | J10: 10.03 | K10: =ELECT.!B11 -> 0
A11: Cairo at Nile Plaza | B11: =B10+1 -> 10 | C11: 2 | D11: 2022 | E11: =(((Submetering!O11+Submetering!P11)*0.842284+Submetering!Q11+(Submetering!M11+Submetering!N11+Submetering!Y11)*0.7362)+(Submetering!O11+Submetering!P11+Submetering!Q11)*0.1488+(Submetering!M11+Submetering!N11+Submetering!Y11)*0.1167+(Submetering!K11+Submetering!L11-Submetering!Z11-Submetering!AA11-Submetering!AB11-Submetering!AC11-Submetering!Q11)+(Submetering!M11+Submetering!N11+Submetering!Y11)*0.1139) -> 0 | F11: 1.27 | G11: =Gas!C12*0.9147 -> 0 | H11: 3.65 | I11: =Submetering!H11+Submetering!AD11+Submetering!AE11 -> -194 | J11: 10.03 | K11: =ELECT.!B12 -> 0
A12: Cairo at Nile Plaza | B12: =B11+1 -> 11 | C12: 2 | D12: 2022 | E12: =(((Submetering!O12+Submetering!P12)*0.842284+Submetering!Q12+(Submetering!M12+Submetering!N12+Submetering!Y12)*0.7362)+(Submetering!O12+Submetering!P12+Submetering!Q12)*0.1488+(Submetering!M12+Submetering!N12+Submetering!Y12)*0.1167+(Submetering!K12+Submetering!L12-Submetering!Z12-Submetering!AA12-Submetering!AB12-Submetering!AC12-Submetering!Q12)+(Submetering!M12+Submetering!N12+Submetering!Y12)*0.1139) -> 0 | F12: 1.27 | G12: =Gas!C13*0.9147 -> 0 | H12: 3.65 | I12: =Submetering!H12+Submetering!AD12+Submetering!AE12 -> -194 | J12: 10.03 | K12: =ELECT.!B13 -> 0
A13: Cairo at Nile Plaza | B13: =B12+1 -> 12 | C13: 2 | D13: 2022 | E13: =(((Submetering!O13+Submetering!P13)*0.842284+Submetering!Q13+(Submetering!M13+Submetering!N13+Submetering!Y13)*0.7362)+(Submetering!O13+Submetering!P13+Submetering!Q13)*0.1488+(Submetering!M13+Submetering!N13+Submetering!Y13)*0.1167+(Submetering!K13+Submetering!L13-Submetering!Z13-Submetering!AA13-Submetering!AB13-Submetering!AC13-Submetering!Q13)+(Submetering!M13+Submetering!N13+Submetering!Y13)*0.1139) -> 0 | F13: 1.27 | G13: =Gas!C14*0.9147 -> 0 | H13: 3.65 | I13: =Submetering!H13+Submetering!AD13+Submetering!AE13 -> -194 | J13: 10.03 | K13: =ELECT.!B14 -> 0
A14: Cairo at Nile Plaza | B14: =B13+1 -> 13 | C14: 2 | D14: 2022 | E14: =(((Submetering!O14+Submetering!P14)*0.842284+Submetering!Q14+(Submetering!M14+Submetering!N14+Submetering!Y14)*0.7362)+(Submetering!O14+Submetering!P14+Submetering!Q14)*0.1488+(Submetering!M14+Submetering!N14+Submetering!Y14)*0.1167+(Submetering!K14+Submetering!L14-Submetering!Z14-Submetering!AA14-Submetering!AB14-Submetering!AC14-Submetering!Q14)+(Submetering!M14+Submetering!N14+Submetering!Y14)*0.1139) -> 0 | F14: 1.27 | G14: =Gas!C15*0.9147 -> 0 | H14: 3.65 | I14: =Submetering!H14+Submetering!AD14+Submetering!AE14 -> -194 | J14: 10.03 | K14: =ELECT.!B15 -> 0
... A29: Cairo at Nile Plaza | B29: =B28+1 -> 28 | C29: 2 | D29: 2022 | E29: =(((Submetering!O29+Submetering!P29)*0.842284+Submetering!Q29+(Submetering!M29+Submetering!N29+Submetering!Y29)*0.7362)+(Submetering!O29+Submetering!P29+Submetering!Q29)*0.1488+(Submetering!M29+Submetering!N29+Submetering!Y29)*0.1167+(Submetering!K29+Submetering!L29-Submetering!Z29-Submetering!AA29-Submetering!AB29-Submetering!AC29-Submetering!Q29)+(Submetering!M29+Submetering!N29+Submetering!Y29)*0.1139) -> 0 | F29: 1.27 | G29: =Gas!C30*0.9147 -> 0 | H29: 3.65 | I29: =Submetering!H29+Submetering!AD29+Submetering!AE29 -> -194 | J29: 10.03 | K29: =ELECT.!B30 -> 0

Sheet Submetering
A1: Site Name | B1: Day | C1: Month | D1: Year | E1: Main (m3) | F1: Podium (m3) | G1: Hotel (m3) | H1: Large (m3) | I1: Feeder 1 (KWh) | J1: Feeder 2 (KWh) | K1: T1 (KWh) | L1: T2 (KWh) | M1: T3 (KWh) | N1: T4 (KWh) | O1: T5 (KWh) | P1: T7 (KWh) | Q1: New Chiller (KWh) | R1: Hotel (BTU) | S1: B.S (BTU) | T1: LS (BTU) | U1: Mall (BTU) | V1: AHU#25 (BTU) | W1: AHU#9 (BTU) | X1: Room Nights | Y1: Loss (KWH) | Z1: Mall (KWH) | AA1: Citadel (KWH) | AB1: Rotana (KWH) | AC1: CIB (KWH) | AD1: Plaza suits water consumption (M3) | AE1: Hotel water consumption (M3)
A2: Cairo at Nile Plaza | B2: 1 | C2: 2 | D2: 2022 | E2: =Water!C3 -> 840 | F2: =Water!E3 -> 490 | G2: =Water!G3 -> 237.6 | H2: =Water!I3 -> 5.535 | I2: =ELECT.!F3 -> 8271 | J2: =ELECT.!H3 -> 32113 | K2: =ELECT.!K3 -> 8148 | L2: =ELECT.!M3 -> 3565 | M2: =ELECT.!O3 -> 4586 | N2: =ELECT.!Q3 -> 2093 | O2: =ELECT.!S3 -> 7900 | P2: =ELECT.!W3*2 -> 17168 | Q2: =ELECT.!D3 -> 0 | R2: =BTU!C3 -> 2.015 | S2: =BTU!F3 -> 0.463 | T2: =BTU!I3 -> 5 | U2: =BTU!O3 -> 1.108 | V2: =BTU!L3 -> 0 | W2: =BTU!R3 -> 0 | X2: =ELECT.!B3 -> 235 | Y2: =I2+J2-(K2+L2+M2+N2+O2+P2) -> -3076 | Z2: ='Mall, Citadel, Rotana'!C3+'Mall, Citadel, Rotana'!E3+'Mall, Citadel, Rotana'!G3+'Mall, Citadel, Rotana'!I3 -> 1375 | AA2: ='Mall, Citadel, Rotana'!K3+'Mall, Citadel, Rotana'!M3 -> 640 | AB2: ='Mall, Citadel, Rotana'!O3 -> 116 | AC2: ='Mall, Citadel, Rotana'!Q3+'Mall, Citadel, Rotana'!S3 -> 124 | AD2: =(E2-H2-194)*0.1318 -> 84.413287 | AE2: =E2-H2-AD2-194 -> 556.05171
A3: Cairo at Nile Plaza | B3: =B2+1 -> 2 | C3: 2 | D3: 2022 | E3: =Water!C4 -> 810 | F3: =Water!E4 -> 500 | G3: =Water!G4 -> 251.1 | H3: =Water!I4 -> 5.67 | I3: =ELECT.!F4 -> 10599 | J3: =ELECT.!H4 -> 43604 | K3: =ELECT.!K4 -> 10828 | L3: =ELECT.!M4 -> 4874 | M3: =ELECT.!O4 -> 5576 | N3: =ELECT.!Q4 -> 3201 | O3: =ELECT.!S4 -> 11280 | P3: =ELECT.!W4*2 -> 22446 | Q3: =ELECT.!D4 -> 0 | R3: =BTU!C4 -> 1.806 | S3: =BTU!F4 -> 0.452 | T3: =BTU!I4 -> 4 | U3: =BTU!O4 -> 0.965 | V3: =BTU!L4 -> 0 | W3: =BTU!R4 -> 0 | X3: =ELECT.!B4 -> 190 | Y3: =I3+J3-(K3+L3+M3+N3+O3+P3) -> -4002 | Z3: ='Mall, Citadel, Rotana'!C4+'Mall, Citadel, Rotana'!E4+'Mall, Citadel, Rotana'!G4+'Mall, Citadel, Rotana'!I4 -> 1355 | AA3: ='Mall, Citadel, Rotana'!K4+'Mall, Citadel, Rotana'!M4 -> 480 | AB3: ='Mall, Citadel, Rotana'!O4 -> 121 | AC3: ='Mall, Citadel, Rotana'!Q4+'Mall, Citadel, Rotana'!S4 -> 0 | AD3: =(E3-H3-194)*0.1318 -> 80.441494 | AE3: =E3-H3-AD3-194 -> 529.88851
A4: Cairo at Nile Plaza | B4: =B3+1 -> 3 | C4: 2 | D4: 2022 | E4: =Water!C5 -> 810 | F4: =Water!E5 -> 500 | G4: =Water!G5 -> 251.1 | H4: =Water!I5 -> 5.67 | I4: =ELECT.!F5 -> 4081 | J4: =ELECT.!H5 -> 28056 | K4: =ELECT.!K5 -> 6740 | L4: =ELECT.!M5 -> 3075 | M4: =ELECT.!O5 -> 916 | N4: =ELECT.!Q5 -> 4661 | O4: =ELECT.!S5 -> 6428 | P4: =ELECT.!W5*2 -> 12880 | Q4: =ELECT.!D5 -> 0 | R4: =BTU!C5 -> 2.143 | S4: =BTU!F5 -> 0.512 | T4: =BTU!I5 -> 4 | U4: =BTU!O5 -> 1.009 | V4: =BTU!L5 -> 0 | W4: =BTU!R5 -> 0 | X4: =ELECT.!B5 -> 182 | Y4: =I4+J4-(K4+L4+M4+N4+O4+P4) -> -2563 | Z4: ='Mall, Citadel, Rotana'!C5+'Mall, Citadel, Rotana'!E5+'Mall, Citadel, Rotana'!G5+'Mall, Citadel, Rotana'!I5 -> 1375 | AA4: ='Mall, Citadel, Rotana'!K5+'Mall, Citadel, Rotana'!M5 -> 320 | AB4: ='Mall, Citadel, Rotana'!O5 -> 123 | AC4: ='Mall, Citadel, Rotana'!Q5+'Mall, Citadel, Rotana'!S5 -> 0 | AD4: =(E4-H4-194)*0.1318 -> 80.441494 | AE4: =E4-H4-AD4-194 -> 529.88851
A5: Cairo at Nile Plaza | B5: =B4+1 -> 4 | C5: 2 | D5: 2022 | E5: =Water!C6 -> 740 | F5: =Water!E6 -> 460 | G5: =Water!G6 -> 210.6 | H5: =Water!I6 -> 4.941 | I5: =ELECT.!F6 -> 9426 | J5: =ELECT.!H6 -> 41809 | K5: =ELECT.!K6 -> 9766 | L5: =ELECT.!M6 -> 4577 | M5: =ELECT.!O6 -> 4678 | N5: =ELECT.!Q6 -> 3766 | O5: =ELECT.!S6 -> 10787 | P5: =ELECT.!W6*2 -> 22744 | Q5: =ELECT.!D6 -> 0 | R5: =BTU!C6 -> 1.732 | S5: =BTU!F6 -> 0.334 | T5: =BTU!I6 -> 5 | U5: =BTU!O6 -> 0.972 | V5: =BTU!L6 -> 0 | W5: =BTU!R6 -> 0 | X5: =ELECT.!B6 -> 178 | Y5: =I5+J5-(K5+L5+M5+N5+O5+P5) -> -5083 | Z5: ='Mall, Citadel, Rotana'!C6+'Mall, Citadel, Rotana'!E6+'Mall, Citadel, Rotana'!G6+'Mall, Citadel, Rotana'!I6 -> 1214 | AA5: ='Mall, Citadel, Rotana'!K6+'Mall, Citadel, Rotana'!M6 -> 640 | AB5: ='Mall, Citadel, Rotana'!O6 -> 66 | AC5: ='Mall, Citadel, Rotana'!Q6+'Mall, Citadel, Rotana'!S6 -> 0 | AD5: =(E5-H5-194)*0.1318 -> 71.311576 | AE5: =E5-H5-AD5-194 -> 469.74742
A6: Cairo at Nile Plaza | B6: =B5+1 -> 5 | C6: 2 | D6: 2022 | E6: =Water!C7 -> 840 | F6: =Water!E7 -> 470 | G6: =Water!G7 -> 202.5 | H6: =Water!I7 -> 5.589 | I6: =ELECT.!F7 -> 8692 | J6: =ELECT.!H7 -> 35635 | K6: =ELECT.!K7 -> 8378 | L6: =ELECT.!M7 -> 4004 | M6: =ELECT.!O7 -> 4592 | N6: =ELECT.!Q7 -> 2389 | O6: =ELECT.!S7 -> 9320 | P6: =ELECT.!W7*2 -> 14708 | Q6: =ELECT.!D7 -> 0 | R6: =BTU!C7 -> 1.912 | S6: =BTU!F7 -> 0.379 | T6: =BTU!I7 -> 4 | U6: =BTU!O7 -> 0.966 | V6: =BTU!L7 -> 0 | W6: =BTU!R7 -> 0 | X6: =ELECT.!B7 -> 211 | Y6: =I6+J6-(K6+L6+M6+N6+O6+P6) -> 936 | Z6: ='Mall, Citadel, Rotana'!C7+'Mall, Citadel, Rotana'!E7+'Mall, Citadel, Rotana'!G7+'Mall, Citadel, Rotana'!I7 -> 1213 | AA6: ='Mall, Citadel, Rotana'!K7+'Mall, Citadel, Rotana'!M7 -> 640 | AB6: ='Mall, Citadel, Rotana'!O7 -> 69 | AC6: ='Mall, Citadel, Rotana'!Q7+'Mall, Citadel, Rotana'!S7 -> 0 | AD6: =(E6-H6-194)*0.1318 -> 84.40617 | AE6: =E6-H6-AD6-194 -> 556.00483
A7: Cairo at Nile Plaza | B7: =B6+1 -> 6 | C7: 2 | D7: 2022 | E7: =Water!C8 -> 840 | F7: =Water!E8 -> 520 | G7: =Water!G8 -> 207.9 | H7: =Water!I8 -> 6.291 | I7: =ELECT.!F8 -> 10721 | J7: =ELECT.!H8 -> 45688 | K7: =ELECT.!K8 -> 11202 | L7: =ELECT.!M8 -> 5327 | M7: =ELECT.!O8 -> 5726 | N7: =ELECT.!Q8 -> 2944 | O7: =ELECT.!S8 -> 12254 | P7: =ELECT.!W8*2 -> 26510 | Q7: =ELECT.!D8 -> 0 | R7: =BTU!C8 -> 2.176 | S7: =BTU!F8 -> 0.49 | T7: =BTU!I8 -> 4 | U7: =BTU!O8 -> 1.034 | V7: =BTU!L8 -> 0 | W7: =BTU!R8 -> 0 | X7: =ELECT.!B8 -> 216 | Y7: =I7+J7-(K7+L7+M7+N7+O7+P7) -> -7554 | Z7: ='Mall, Citadel, Rotana'!C8+'Mall, Citadel, Rotana'!E8+'Mall, Citadel, Rotana'!G8+'Mall, Citadel, Rotana'!I8 -> 1054 | AA7: ='Mall, Citadel, Rotana'!K8+'Mall, Citadel, Rotana'!M8 -> 640 | AB7: ='Mall, Citadel, Rotana'!O8 -> 54 | AC7: ='Mall, Citadel, Rotana'!Q8+'Mall, Citadel, Rotana'!S8 -> 0 | AD7: =(E7-H7-194)*0.1318 -> 84.313646 | AE7: =E7-H7-AD7-194 -> 555.39535
A8: Cairo at Nile Plaza | B8: =B7+1 -> 7 | C8: 2 | D8: 2022 | E8: =Water!C9 -> 800 | F8: =Water!E9 -> 440 | G8: =Water!G9 -> 245.7 | H8: =Water!I9 -> 5.67 | I8: =ELECT.!F9 -> 7528 | J8: =ELECT.!H9 -> 27902 | K8: =ELECT.!K9 -> 7052 | L8: =ELECT.!M9 -> 2706 | M8: =ELECT.!O9 -> 4216 | N8: =ELECT.!Q9 -> 1895 | O8: =ELECT.!S9 -> 6567 | P8: =ELECT.!W9*2 -> 8690 | Q8: =ELECT.!D9 -> 0 | R8: =BTU!C9 -> 2.81 | S8: =BTU!F9 -> 0.695 | T8: =BTU!I9 -> 6 | U8: =BTU!O9 -> 1.1 | V8: =BTU!L9 -> 0 | W8: =BTU!R9 -> 0 | X8: =ELECT.!B9 -> 264 | Y8: =I8+J8-(K8+L8+M8+N8+O8+P8) -> 4304 | Z8: ='Mall, Citadel, Rotana'!C9+'Mall, Citadel, Rotana'!E9+'Mall, Citadel, Rotana'!G9+'Mall, Citadel, Rotana'!I9 -> 1054 | AA8: ='Mall, Citadel, Rotana'!K9+'Mall, Citadel, Rotana'!M9 -> 640 | AB8: ='Mall, Citadel, Rotana'!O9 -> 66 | AC8: ='Mall, Citadel, Rotana'!Q9+'Mall, Citadel, Rotana'!S9 -> 0 | AD8: =(E8-H8-194)*0.1318 -> 79.123494 | AE8: =E8-H8-AD8-194 -> 521.20651
A9: Cairo at Nile Plaza | B9: =B8+1 -> 8 | C9: 2 | D9: 2022 | E9: =Water!C10 -> 890 | F9: =Water!E10 -> 470 | G9: =Water!G10 -> 332.1 | H9: =Water!I10 -> 6.075 | I9: =ELECT.!F10 -> 12461 | J9: =ELECT.!H10 -> 44188 | K9: =ELECT.!K10 -> 11164 | L9: =ELECT.!M10 -> 5818 | M9: =ELECT.!O10 -> 6484 | N9: =ELECT.!Q10 -> 3080 | O9: =ELECT.!S10 -> 11182 | P9: =ELECT.!W10*2 -> 29066 | Q9: =ELECT.!D10 -> 320 | R9: =BTU!C10 -> 1.629 | S9: =BTU!F10 -> 0.35 | T9: =BTU!I10 -> 3 | U9: =BTU!O10 -> 0.597 | V9: =BTU!L10 -> 0 | W9: =BTU!R10 -> 0 | X9: =ELECT.!B10 -> 242 | Y9: =I9+J9-(K9+L9+M9+N9+O9+P9) -> -10145 | Z9: ='Mall, Citadel, Rotana'!C10+'Mall, Citadel, Rotana'!E10+'Mall, Citadel, Rotana'!G10+'Mall, Citadel, Rotana'!I10 -> 2294 | AA9: ='Mall, Citadel, Rotana'!K10+'Mall, Citadel, Rotana'!M10 -> -160 | AB9: ='Mall, Citadel, Rotana'!O10 -> 257 | AC9: ='Mall, Citadel, Rotana'!Q10+'Mall, Citadel, Rotana'!S10 -> 0 | AD9: =(E9-H9-194)*0.1318 -> 90.932115 | AE9: =E9-H9-AD9-194 -> 598.99289
A10: Cairo at Nile Plaza | B10: =B9+1 -> 9 | C10: 2 | D10: 2022 | E10: =Water!C11 -> 0 | F10: =Water!E11 -> 0 | G10: =Water!G11 -> 0 | H10: =Water!I11 -> 0 | I10: =ELECT.!F11 -> 0 | J10: =ELECT.!H11 -> 0 | K10: =ELECT.!K11 -> 0 | L10: =ELECT.!M11 -> 0 | M10: =ELECT.!O11 -> 0 | N10: =ELECT.!Q11 -> 0 | O10: =ELECT.!S11 -> 0 | P10: =ELECT.!W11*2 -> 0 | Q10: =ELECT.!D11 -> 0 | R10: =BTU!C11 -> 0 | S10: =BTU!F11 -> 0 | T10: =BTU!I11 -> 0 | U10: =BTU!O11 -> 0 | V10: =BTU!L11 -> 0 | W10: =BTU!R11 -> 0 | X10: =ELECT.!B11 -> 0 | Y10: =I10+J10-(K10+L10+M10+N10+O10+P10) -> 0 | Z10: ='Mall, Citadel, Rotana'!C11+'Mall, Citadel, Rotana'!E11+'Mall, Citadel, Rotana'!G11+'Mall, Citadel, Rotana'!I11 -> 0 | AA10: ='Mall, Citadel, Rotana'!K11+'Mall, Citadel, Rotana'!M11 -> 0 | AB10: ='Mall, Citadel, Rotana'!O11 -> 0 | AC10: ='Mall, Citadel, Rotana'!Q11+'Mall, Citadel, Rotana'!S11 -> 0 | AD10: =(E10-H10-194)*0.1318 -> -25.5692 | AE10: =E10-H10-AD10-194 -> -168.4308
A11: Cairo at Nile Plaza | B11: =B10+1 -> 10 | C11: 2 | D11: 2022 | E11: =Water!C12 -> 0 | F11: =Water!E12 -> 0 | G11: =Water!G12 -> 0 | H11: =Water!I12 -> 0 | I11: =ELECT.!F12 -> 0 | J11: =ELECT.!H12 -> 0 | K11: =ELECT.!K12 -> 0 | L11: =ELECT.!M12 -> 0 | M11: =ELECT.!O12 -> 0 | N11: =ELECT.!Q12 -> 0 | O11: =ELECT.!S12 -> 0 | P11: =ELECT.!W12*2 -> 0 | Q11: =ELECT.!D12 -> 0 | R11: =BTU!C12 -> 0 | S11: =BTU!F12 -> 0 | T11: =BTU!I12 -> 0 | U11: =BTU!O12 -> 0 | V11: =BTU!L12 -> 0 | W11: =BTU!R12 -> 0 | X11: =ELECT.!B12 -> 0 | Y11: =I11+J11-(K11+L11+M11+N11+O11+P11) -> 0 | Z11: ='Mall, Citadel, Rotana'!C12+'Mall, Citadel, Rotana'!E12+'Mall, Citadel, Rotana'!G12+'Mall, Citadel, Rotana'!I12 -> 0 | AA11: ='Mall, Citadel, Rotana'!K12+'Mall, Citadel, Rotana'!M12 -> 0 | AB11: ='Mall, Citadel, Rotana'!O12 -> 0 | AC11: ='Mall, Citadel, Rotana'!Q12+'Mall, Citadel, Rotana'!S12 -> 0 | AD11: =(E11-H11-194)*0.1318 -> -25.5692 | AE11: =E11-H11-AD11-194 -> -168.4308
A12: Cairo at Nile Plaza | B12: =B11+1 -> 11 | C12: 2 | D12: 2022 | E12: =Water!C13 -> 0 | F12: =Water!E13 -> 0 | G12: =Water!G13 -> 0 | H12: =Water!I13 -> 0 | I12: =ELECT.!F13 -> 0 | J12: =ELECT.!H13 -> 0 | K12: =ELECT.!K13 -> 0 | L12: =ELECT.!M13 -> 0 | M12: =ELECT.!O13 -> 0 | N12: =ELECT.!Q13 -> 0 | O12: =ELECT.!S13 -> 0 | P12: =ELECT.!W13*2 -> 0 | Q12: =ELECT.!D13 -> 0 | R12: =BTU!C13 -> 0 | S12: =BTU!F13 -> 0 | T12: =BTU!I13 -> 0 | U12: =BTU!O13 -> 0 | V12: =BTU!L13 -> 0 | W12: =BTU!R13 -> 0 | X12: =ELECT.!B13 -> 0 | Y12: =I12+J12-(K12+L12+M12+N12+O12+P12) -> 0 | Z12: ='Mall, Citadel, Rotana'!C13+'Mall, Citadel, Rotana'!E13+'Mall, Citadel, Rotana'!G13+'Mall, Citadel, Rotana'!I13 -> 0 | AA12: ='Mall, Citadel, Rotana'!K13+'Mall, Citadel, Rotana'!M13 -> 0 | AB12: ='Mall, Citadel, Rotana'!O13 -> 0 | AC12: ='Mall, Citadel, Rotana'!Q13+'Mall, Citadel, Rotana'!S13 -> 0 | AD12: =(E12-H12-194)*0.1318 -> -25.5692 | AE12: =E12-H12-AD12-194 -> -168.4308
A13: Cairo at Nile Plaza | B13: =B12+1 -> 12 | C13: 2 | D13: 2022 | E13: =Water!C14 -> 0 | F13: =Water!E14 -> 0 | G13: =Water!G14 -> 0 | H13: =Water!I14 -> 0 | I13: =ELECT.!F14 -> 0 | J13: =ELECT.!H14 -> 0 | K13: =ELECT.!K14 -> 0 | L13: =ELECT.!M14 -> 0 | M13: =ELECT.!O14 -> 0 | N13: =ELECT.!Q14 -> 0 | O13: =ELECT.!S14 -> 0 | P13: =ELECT.!W14*2 -> 0 | Q13: =ELECT.!D14 -> 0 | R13: =BTU!C14 -> 0 | S13: =BTU!F14 -> 0 | T13: =BTU!I14 -> 0 | U13: =BTU!O14 -> 0 | V13: =BTU!L14 -> 0 | W13: =BTU!R14 -> 0 | X13: =ELECT.!B14 -> 0 | Y13: =I13+J13-(K13+L13+M13+N13+O13+P13) -> 0 | Z13: ='Mall, Citadel, Rotana'!C14+'Mall, Citadel, Rotana'!E14+'Mall, Citadel, Rotana'!G14+'Mall, Citadel, Rotana'!I14 -> 0 | AA13: ='Mall, Citadel, Rotana'!K14+'Mall, Citadel, Rotana'!M14 -> 0 | AB13: ='Mall, Citadel, Rotana'!O14 -> 0 | AC13: ='Mall, Citadel, Rotana'!Q14+'Mall, Citadel, Rotana'!S14 -> 0 | AD13: =(E13-H13-194)*0.1318 -> -25.5692 | AE13: =E13-H13-AD13-194 -> -168.4308
A14: Cairo at Nile Plaza | B14: =B13+1 -> 13 | C14: 2 | D14: 2022 | E14: =Water!C15 -> 0 | F14: =Water!E15 -> 0 | G14: =Water!G15 -> 0 | H14: =Water!I15 -> 0 | I14: =ELECT.!F15 -> 0 | J14: =ELECT.!H15 -> 0 | K14: =ELECT.!K15 -> 0 | L14: =ELECT.!M15 -> 0 | M14: =ELECT.!O15 -> 0 | N14: =ELECT.!Q15 -> 0 | O14: =ELECT.!S15 -> 0 | P14: =ELECT.!W15*2 -> 0 | Q14: =ELECT.!D15 -> 0 | R14: =BTU!C15 -> 0 | S14: =BTU!F15 -> 0 | T14: =BTU!I15 -> 0 | U14: =BTU!O15 -> 0 | V14: =BTU!L15 -> 0 | W14: =BTU!R15 -> 0 | X14: =ELECT.!B15 -> 0 | Y14: =I14+J14-(K14+L14+M14+N14+O14+P14) -> 0 | Z14: ='Mall, Citadel, Rotana'!C15+'Mall, Citadel, Rotana'!E15+'Mall, Citadel, Rotana'!G15+'Mall, Citadel, Rotana'!I15 -> 0 | AA14: ='Mall, Citadel, Rotana'!K15+'Mall, Citadel, Rotana'!M15 -> 0 | AB14: ='Mall, Citadel, Rotana'!O15 -> 0 | AC14: ='Mall, Citadel, Rotana'!Q15+'Mall, Citadel, Rotana'!S15 -> 0 | AD14: =(E14-H14-194)*0.1318 -> -25.5692 | AE14: =E14-H14-AD14-194 -> -168.4308
... A29: Cairo at Nile Plaza | B29: =B28+1 -> 28 | C29: 2 | D29: 2022 | E29: =Water!C30 -> 0 | F29: =Water!E30 -> 0 | G29: =Water!G30 -> 0 | H29: =Water!I30 -> 0 | I29: =ELECT.!F30 -> 0 | J29: =ELECT.!H30 -> 0 | K29: =ELECT.!K30 -> 0 | L29: =ELECT.!M30 -> 0 | M29: =ELECT.!O30 -> 0 | N29: =ELECT.!Q30 -> 0 | O29: =ELECT.!S30 -> 0 | P29: =ELECT.!W30*2 -> 0 | Q29: =ELECT.!D30 -> 0 | R29: =BTU!C30 -> 0 | S29: =BTU!F30 -> 0 | T29: =BTU!I30 -> 0 | U29: =BTU!O30 -> 0 | V29: =BTU!L30 -> 0 | W29: =BTU!R30 -> 0 | X29: =ELECT.!B30 -> 0 | Y29: =I29+J29-(K29+L29+M29+N29+O29+P29) -> 0 | Z29: ='Mall, Citadel, Rotana'!C30+'Mall, Citadel, Rotana'!E30+'Mall, Citadel, Rotana'!G30+'Mall, Citadel, Rotana'!I30 -> 0 | AA29: ='Mall, Citadel, Rotana'!K30+'Mall, Citadel, Rotana'!M30 -> 0 | AB29: ='Mall, Citadel, Rotana'!O30 -> 0 | AC29: ='Mall, Citadel, Rotana'!Q30+'Mall, Citadel, Rotana'!S30 -> 0 | AD29: =(E29-H29-194)*0.1318 -> -25.5692 | AE29: =E29-H29-AD29-194 -> -168.4308

Sheet Mall, Citadel, Rotana
A1: Day | B1: R1 | C1: Cons | D1: R2 | E1: Cons | F1: R3 | G1: Cons | H1: R4 | I1: Cons | J1: RO1 | K1: Cons | L1: RO2 | M1: Cons | N1: ROE | O1: Cons | P1: CIB. 1 | Q1: Cons | R1: CIB. E | S1: Cons | T1: Co | U1: Cons
A2: 44592 | B2: 46565 | D2: 40256 | F2: 21274 | H2: 253571 | J2: 303517 | K2: 0 | L2: 25813 | N2: 222148 | P2: 139521 | R2: 55047 | S2: 0 | T2: 3918
A3: 44593 | B3: 46570 | C3: =(B3-B2)*800/5 -> 800 | D3: 40259 | E3: =(D3-D2)*800/5 -> 480 | F3: 21278 | G3: =(F3-F2)*100/5 -> 80 | H3: 253586 | I3: =(H3-H2) -> 15 | J3: 303517 | K3: 0 | L3: 25817 | M3: =(L3-L2)*800/5 -> 640 | N3: 222264 | O3: =N3-N2 -> 116 | P3: 139625 | Q3: 124 | R3: =R2 -> 55047 | S3: 0 | T3: 3919 | U3: =(T3-T2)*800/5 -> 160
A4: 44594 | B4: 46575 | C4: =(B4-B3)*800/5 -> 800 | D4: 40262 | E4: =(D4-D3)*800/5 -> 480 | F4: 21281 | G4: =(F4-F3)*100/5 -> 60 | H4: 253601 | I4: =(H4-H3) -> 15 | J4: 303517 | K4: 0 | L4: 25820 | M4: =(L4-L3)*800/5 -> 480 | N4: 222385 | O4: =N4-N3 -> 121 | P4: 139625 | Q4: =P4-P3 -> 0 | R4: =R3 -> 55047 | S4: =R4-R3 -> 0 | T4: 3920 | U4: =(T4-T3)*800/5 -> 160
A5: 44595 | B5: 46580 | C5: =(B5-B4)*800/5 -> 800 | D5: 40265 | E5: =(D5-D4)*800/5 -> 480 | F5: 21285 | G5: =(F5-F4)*100/5 -> 80 | H5: 253616 | I5: =(H5-H4) -> 15 | J5: 303517 | K5: 0 | L5: 25822 | M5: =(L5-L4)*800/5 -> 320 | N5: 222508 | O5: =N5-N4 -> 123 | P5: =P4 -> 139625 | Q5: =P5-P4 -> 0 | R5: =R4 -> 55047 | S5: =R5-R4 -> 0 | T5: 3921 | U5: =(T5-T4)*800/5 -> 160
A6: 44596 | B6: 46584 | C6: =(B6-B5)*800/5 -> 640 | D6: 40268 | E6: =(D6-D5)*800/5 -> 480 | F6: 21289 | G6: =(F6-F5)*100/5 -> 80 | H6: 253630 | I6: =(H6-H5) -> 14 | J6: 303517 | K6: 0 | L6: 25826 | M6: =(L6-L5)*800/5 -> 640 | N6: 222574 | O6: =N6-N5 -> 66 | P6: =P5 -> 139625 | Q6: =P6-P5 -> 0 | R6: =R5 -> 55047 | S6: 0 | T6: 3922 | U6: =(T6-T5)*800/5 -> 160
A7: 44597 | B7: 46588 | C7: =(B7-B6)*800/5 -> 640 | D7: 40271 | E7: =(D7-D6)*800/5 -> 480 | F7: 21293 | G7: =(F7-F6)*100/5 -> 80 | H7: 253643 | I7: =(H7-H6) -> 13 | J7: 303517 | K7: 0 | L7: 25830 | M7: =(L7-L6)*800/5 -> 640 | N7: 222643 | O7: =N7-N6 -> 69 | P7: =P6 -> 139625 | Q7: 0 | R7: =R6 -> 55047 | S7: 0 | T7: 3923 | U7: =(T7-T6)*800/5 -> 160
A8: 44598 | B8: 46591 | C8: =(B8-B7)*800/5 -> 480 | D8: 40274 | E8: =(D8-D7)*800/5 -> 480 | F8: 21297 | G8: =(F8-F7)*100/5 -> 80 | H8: 253657 | I8: =(H8-H7) -> 14 | J8: 303517 | K8: 0 | L8: 25834 | M8: =(L8-L7)*800/5 -> 640 | N8: 222697 | O8: =N8-N7 -> 54 | P8: =P7 -> 139625 | Q8: =P8-P7 -> 0 | R8: =R7 -> 55047 | S8: =R8-R7 -> 0 | T8: 3924 | U8: =(T8-T7)*800/5 -> 160
A9: 44599 | B9: 46594 | C9: =(B9-B8)*800/5 -> 480 | D9: 40277 | E9: =(D9-D8)*800/5 -> 480 | F9: 21301 | G9: =(F9-F8)*100/5 -> 80 | H9: 253671 | I9: =(H9-H8) -> 14 | J9: 303517 | K9: 0 | L9: 25838 | M9: =(L9-L8)*800/5 -> 640 | N9: 222763 | O9: =N9-N8 -> 66 | P9: =P8 -> 139625 | Q9: =P9-P8 -> 0 | R9: =R8 -> 55047 | S9: =R9-R8 -> 0 | T9: 3925 | U9: =(T9-T8)*800/5 -> 160
A10: 44600 | B10: 46603 | C10: =(B10-B9)*800/5 -> 1440 | D10: 40282 | E10: =(D10-D9)*800/5 -> 800 | F10: 21303 | G10: =(F10-F9)*100/5 -> 40 | H10: 253685 | I10: =(H10-H9) -> 14 | J10: 303517 | K10: 0 | L10: 25837 | M10: =(L10-L9)*800/5 -> -160 | N10: 223020 | O10: =N10-N9 -> 257 | P10: =P9 -> 139625 | Q10: =P10-P9 -> 0 | R10: =R9 -> 55047 | S10: =R10-R9 -> 0 | T10: 3926 | U10: =(T10-T9)*800/5 -> 160
A11: 44601 | B11: =B10 -> 46603 | C11: =(B11-B10)*800/5 -> 0 | D11: =D10 -> 40282 | E11: =(D11-D10)*800/5 -> 0 | F11: =F10 -> 21303 | G11: =(F11-F10)*100/5 -> 0 | H11: =H10 -> 253685 | I11: =(H11-H10) -> 0 | J11: =J10 -> 303517 | K11: 0 | L11: =L10 -> 25837 | M11: =(L11-L10)*800/5 -> 0 | N11: =N10 -> 223020 | O11: =N11-N10 -> 0 | P11: =P10 -> 139625 | Q11: =P11-P10 -> 0 | R11: =R10 -> 55047 | S11: =R11-R10 -> 0 | T11: =T10 -> 3926 | U11: =(T11-T10)*800/5 -> 0
A12: 44602 | B12: =B11 -> 46603 | C12: =(B12-B11)*800/5 -> 0 | D12: =D11 -> 40282 | E12: =(D12-D11)*800/5 -> 0 | F12: =F11 -> 21303 | G12: =(F12-F11)*100/5 -> 0 | H12: =H11 -> 253685 | I12: =(H12-H11) -> 0 | J12: =J11 -> 303517 | K12: 0 | L12: =L11 -> 25837 | M12: =(L12-L11)*800/5 -> 0 | N12: =N11 -> 223020 | O12: =N12-N11 -> 0 | P12: =P11 -> 139625 | Q12: =P12-P11 -> 0 | R12: =R11 -> 55047 | S12: =R12-R11 -> 0 | T12: =T11 -> 3926 | U12: =(T12-T11)*800/5 -> 0
A13: 44603 | B13: =B12 -> 46603 | C13: =(B13-B12)*800/5 -> 0 | D13: =D12 -> 40282 | E13: =(D13-D12)*800/5 -> 0 | F13: =F12 -> 21303 | G13: =(F13-F12)*100/5 -> 0 | H13: =H12 -> 253685 | I13: =(H13-H12) -> 0 | J13: 303517 | K13: 0 | L13: =L12 -> 25837 | M13: =(L13-L12)*800/5 -> 0 | N13: =N12 -> 223020 | O13: =N13-N12 -> 0 | P13: =P12 -> 139625 | Q13: =P13-P12 -> 0 | R13: 55047 | S13: =R13-R12 -> 0 | T13: =T12 -> 3926 | U13: =(T13-T12)*800/5 -> 0
A14: 44604 | B14: =B13 -> 46603 | C14: =(B14-B13)*800/5 -> 0 | D14: =D13 -> 40282 | E14: =(D14-D13)*800/5 -> 0 | F14: =F13 -> 21303 | G14: =(F14-F13)*100/5 -> 0 | H14: =H13 -> 253685 | I14: =(H14-H13) -> 0 | J14: 303517 | K14: 0 | L14: =L13 -> 25837 | M14: =(L14-L13)*800/5 -> 0 | N14: =N13 -> 223020 | O14: =N14-N13 -> 0 | P14: =P13 -> 139625 | Q14: =P14-P13 -> 0 | R14: =R13 -> 55047 | S14: 0 | T14: =T13 -> 3926 | U14: =(T14-T13)*800/5 -> 0
A15: 44605 | B15: =B14 -> 46603 | C15: =(B15-B14)*800/5 -> 0 | D15: =D14 -> 40282 | E15: =(D15-D14)*800/5 -> 0 | F15: =F14 -> 21303 | G15: =(F15-F14)*100/5 -> 0 | H15: =H14 -> 253685 | I15: =(H15-H14) -> 0 | J15: 303517 | K15: 0 | L15: =L14 -> 25837 | M15: =(L15-L14)*800/5 -> 0 | N15: =N14 -> 223020 | O15: =N15-N14 -> 0 | P15: =P14 -> 139625 | Q15: =P15-P14 -> 0 | R15: 55047 | S15: 0 | T15: =T14 -> 3926 | U15: =(T15-T14)*800/5 -> 0
A16: 44606 | B16: =B15 -> 46603 | C16: =(B16-B15)*800/5 -> 0 | D16: =D15 -> 40282 | E16: =(D16-D15)*800/5 -> 0 | F16: =F15 -> 21303 | G16: =(F16-F15)*100/5 -> 0 | H16: =H15 -> 253685 | I16: =(H16-H15) -> 0 | J16: 305317 | K16: 0 | L16: =L15 -> 25837 | M16: =(L16-L15)*800/5 -> 0 | N16: =N15 -> 223020 | O16: =N16-N15 -> 0 | P16: =P15 -> 139625 | Q16: =P16-P15 -> 0 | R16: =R15 -> 55047 | S16: =R16-R15 -> 0 | T16: =T15 -> 3926 | U16: =(T16-T15)*800/5 -> 0
A17: 44607 | B17: =B16 -> 46603 | C17: =(B17-B16)*800/5 -> 0 | D17: =D16 -> 40282 | E17: =(D17-D16)*800/5 -> 0 | F17: =F16 -> 21303 | G17: =(F17-F16)*100/5 -> 0 | H17: =H16 -> 253685 | I17: =(H17-H16) -> 0 | J17: 303517 | K17: 0 | L17: =L16 -> 25837 | M17: =(L17-L16)*800/5 -> 0 | N17: =N16 -> 223020 | O17: =N17-N16 -> 0 | P17: =P16 -> 139625 | Q17: =P17-P16 -> 0 | R17: =R16 -> 55047 | S17: =S16 -> 0 | T17: =T16 -> 3926 | U17: =(T17-T16)*800/5 -> 0
A18: 44608 | B18: =B17 -> 46603 | C18: =(B18-B17)*800/5 -> 0 | D18: =D17 -> 40282 | E18: =(D18-D17)*800/5 -> 0 | F18: =F17 -> 21303 | G18: =(F18-F17)*100/5 -> 0 | H18: =H17 -> 253685 | I18: =(H18-H17) -> 0 | J18: =J17 -> 303517 | K18: 0 | L18: =L17 -> 25837 | M18: =(L18-L17)*800/5 -> 0 | N18: =N17 -> 223020 | O18: =N18-N17 -> 0 | P18: =P17 -> 139625 | Q18: =P18-P17 -> 0 | R18: =R17 -> 55047 | S18: =R18-R17 -> 0 | T18: =T17 -> 3926 | U18: =(T18-T17)*800/5 -> 0
A19: 44609 | B19: =B18 -> 46603 | C19: =(B19-B18)*800/5 -> 0 | D19: =D18 -> 40282 | E19: =(D19-D18)*800/5 -> 0 | F19: =F18 -> 21303 | G19: =(F19-F18)*100/5 -> 0 | H19: =H18 -> 253685 | I19: =(H19-H18) -> 0 | J19: 303517 | K19: 0 | L19: =L18 -> 25837 | M19: =(L19-L18)*800/5 -> 0 | N19: =N18 -> 223020 | O19: =N19-N18 -> 0 | P19: =P18 -> 139625 | Q19: =P19-P18 -> 0 | R19: =R18 -> 55047 | S19: =R19-R18 -> 0 | T19: =T18 -> 3926 | U19: =(T19-T18)*800/5 -> 0
A20: 44610 | B20: =B19 -> 46603 | C20: =(B20-B19)*800/5 -> 0 | D20: =D19 -> 40282 | E20: =(D20-D19)*800/5 -> 0 | F20: =F19 -> 21303 | G20: =(F20-F19)*100/5 -> 0 | H20: =H19 -> 253685 | I20: =(H20-H19) -> 0 | J20: =J19 -> 303517 | K20: 0 | L20: =L19 -> 25837 | M20: =(L20-L19)*800/5 -> 0 | N20: =N19 -> 223020 | O20: =N20-N19 -> 0 | P20: =P19 -> 139625 | Q20: =P20-P19 -> 0 | R20: =R19 -> 55047 | S20: =R20-R19 -> 0 | T20: =T19 -> 3926 | U20: =(T20-T19)*800/5 -> 0
A21: 44611 | B21: =B20 -> 46603 | C21: =(B21-B20)*800/5 -> 0 | D21: =D20 -> 40282 | E21: =(D21-D20)*800/5 -> 0 | F21: =F20 -> 21303 | G21: =(F21-F20)*100/5 -> 0 | H21: =H20 -> 253685 | I21: =(H21-H20) -> 0 | J21: 303517 | K21: 0 | L21: =L20 -> 25837 | M21: =(L21-L20)*800/5 -> 0 | N21: =N20 -> 223020 | O21: =N21-N20 -> 0 | P21: =P20 -> 139625 | Q21: =P21-P20 -> 0 | R21: =R20 -> 55047 | S21: =R21-R20 -> 0 | T21: =T20 -> 3926 | U21: =(T21-T20)*800/5 -> 0
A22: 44612 | B22: =B21 -> 46603 | C22: =(B22-B21)*800/5 -> 0 | D22: =D21 -> 40282 | E22: =(D22-D21)*800/5 -> 0 | F22: =F21 -> 21303 | G22: =(F22-F21)*100/5 -> 0 | H22: =H21 -> 253685 | I22: =(H22-H21) -> 0 | J22: 303517 | K22: 0 | L22: =L21 -> 25837 | M22: =(L22-L21)*800/5 -> 0 | N22: =N21 -> 223020 | O22: =N22-N21 -> 0 | P22: =P21 -> 139625 | Q22: =P22-P21 -> 0 | R22: =R21 -> 55047 | S22: =R22-R21 -> 0 | T22: =T21 -> 3926 | U22: =(T22-T21)*800/5 -> 0
A23: 44613 | B23: =B22 -> 46603 | C23: =(B23-B22)*800/5 -> 0 | D23: =D22 -> 40282 | E23: =(D23-D22)*800/5 -> 0 | F23: =F22 -> 21303 | G23: =(F23-F22)*100/5 -> 0 | H23: =H22 -> 253685 | I23: =(H23-H22) -> 0 | J23: 303517 | K23: 0 | L23: =L22 -> 25837 | M23: =(L23-L22)*800/5 -> 0 | N23: =N22 -> 223020 | O23: =N23-N22 -> 0 | P23: =P22 -> 139625 | Q23: =P23-P22 -> 0 | R23: =R22 -> 55047 | S23: =R23-R22 -> 0 | T23: =T22 -> 3926 | U23: =(T23-T22)*800/5 -> 0
A24: 44614 | B24: =B23 -> 46603 | C24: =(B24-B23)*800/5 -> 0 | D24: =D23 -> 40282 | E24: =(D24-D23)*800/5 -> 0 | F24: =F23 -> 21303 | G24: =(F24-F23)*100/5 -> 0 | H24: =H23 -> 253685 | I24: =(H24-H23) -> 0 | J24: =J23 -> 303517 | K24: 0 | L24: =L23 -> 25837 | M24: =(L24-L23)*800/5 -> 0 | N24: =N23 -> 223020 | O24: =N24-N23 -> 0 | P24: =P23 -> 139625 | Q24: =P24-P23 -> 0 | R24: =R23 -> 55047 | S24: =R24-R23 -> 0 | T24: =T23 -> 3926 | U24: =(T24-T23)*800/5 -> 0
A25: 44615 | B25: =B24 -> 46603 | C25: =(B25-B24)*800/5 -> 0 | D25: =D24 -> 40282 | E25: =(D25-D24)*800/5 -> 0 | F25: =F24 -> 21303 | G25: =(F25-F24)*100/5 -> 0 | H25: =H24 -> 253685 | I25: =(H25-H24) -> 0 | J25: 303517 | K25: 0 | L25: =L24 -> 25837 | M25: =(L25-L24)*800/5 -> 0 | N25: =N24 -> 223020 | O25: =N25-N24 -> 0 | P25: =P24 -> 139625 | Q25: =P25-P24 -> 0 | R25: 55047 | S25: =R25-R24 -> 0 | T25: =T24 -> 3926 | U25: =(T25-T24)*800/5 -> 0
A26: 44616 | B26: =B25 -> 46603 | C26: =(B26-B25)*800/5 -> 0 | D26: =D25 -> 40282 | E26: =(D26-D25)*800/5 -> 0 | F26: =F25 -> 21303 | G26: =(F26-F25)*100/5 -> 0 | H26: =H25 -> 253685 | I26: =(H26-H25) -> 0 | J26: 303517 | K26: 0 | L26: =L25 -> 25837 | M26: =(L26-L25)*800/5 -> 0 | N26: =N25 -> 223020 | O26: =N26-N25 -> 0 | P26: =P25 -> 139625 | Q26: =P26-P25 -> 0 | R26: =R25 -> 55047 | S26: =R26-R25 -> 0 | T26: =T25 -> 3926 | U26: =(T26-T25)*800/5 -> 0
A27: 44617 | B27: =B26 -> 46603 | C27: =(B27-B26)*800/5 -> 0 | D27: =D26 -> 40282 | E27: =(D27-D26)*800/5 -> 0 | F27: =F26 -> 21303 | G27: =(F27-F26)*100/5 -> 0 | H27: =H26 -> 253685 | I27: =(H27-H26) -> 0 | J27: 303517 | K27: 0 | L27: =L26 -> 25837 | M27: =(L27-L26)*800/5 -> 0 | N27: =N26 -> 223020 | O27: =N27-N26 -> 0 | P27: =P26 -> 139625 | Q27: =P27-P26 -> 0 | R27: =R26 -> 55047 | S27: =R27-R26 -> 0 | T27: =T26 -> 3926 | U27: =(T27-T26)*800/5 -> 0
A28: 44618 | B28: =B27 -> 46603 | C28: =(B28-B27)*800/5 -> 0 | D28: =D27 -> 40282 | E28: =(D28-D27)*800/5 -> 0 | F28: =F27 -> 21303 | G28: =(F28-F27)*100/5 -> 0 | H28: =H27 -> 253685 | I28: =(H28-H27) -> 0 | J28: 303517 | K28: 0 | L28: =L27 -> 25837 | M28: =(L28-L27)*800/5 -> 0 | N28: =N27 -> 223020 | O28: =N28-N27 -> 0 | P28: =P27 -> 139625 | Q28: =P28-P27 -> 0 | R28: 55047 | S28: =R28-R27 -> 0 | T28: =T27 -> 3926 | U28: =(T28-T27)*800/5 -> 0
A29: 44619 | B29: =B28 -> 46603 | C29: =(B29-B28)*800/5 -> 0 | D29: =D28 -> 40282 | E29: =(D29-D28)*800/5 -> 0 | F29: =F28 -> 21303 | G29: =(F29-F28)*100/5 -> 0 | H29: =H28 -> 253685 | I29: =(H29-H28) -> 0 | J29: 303517 | K29: 0 | L29: =L28 -> 25837 | M29: =(L29-L28)*800/5 -> 0 | N29: =N28 -> 223020 | O29: =N29-N28 -> 0 | P29: =P28 -> 139625 | Q29: =P29-P28 -> 0 | R29: 55047 | S29: =R29-R28 -> 0 | T29: =T28 -> 3926 | U29: =(T29-T28)*800/5 -> 0
A30: 44620 | B30: =B29 -> 46603 | C30: =(B30-B29)*800/5 -> 0 | D30: =D29 -> 40282 | E30: =(D30-D29)*800/5 -> 0 | F30: =F29 -> 21303 | G30: =(F30-F29)*100/5 -> 0 | H30: =H29 -> 253685 | I30: =(H30-H29) -> 0 | J30: =J29 -> 303517 | K30: 0 | L30: =L29 -> 25837 | M30: =(L30-L29)*800/5 -> 0 | N30: =N29 -> 223020 | O30: =N30-N29 -> 0 | P30: =P29 -> 139625 | Q30: =P30-P29 -> 0 | R30: =R29 -> 55047 | S30: =R30-R29 -> 0 | T30: =T29 -> 3926 | U30: =(T30-T29)*800/5 -> 0
A31: Total | C31: =SUM(C4:C30) -> 5280 | E31: =SUM(E4:E30) -> 3680 | G31: =SUM(G4:G30) -> 500 | I31: =SUM(I4:I30) -> 99 | K31: =SUM(K4:K30) -> 0 | M31: =SUM(M4:M30) -> 3200 | O31: =SUM(O4:O30) -> 756 | Q31: =SUM(Q4:Q30) -> 0 | S31: =SUM(S4:S30) -> 0 | U31: =SUM(U4:U30) -> 1120

Sheet ELECT.
A1: Day | B1: Rooms Sold | C1: New Chillers | D1: Cons | E1: F-1 | F1: Cons. | G1: F-2 | H1: Cons. | I1: Total | J1: T-1 | K1: Cons. | L1: T-2 | M1: Cons. | N1: T-3 | O1: Cons. | P1: T-4 | Q1: Cons. | R1: T-5 | S1: Cons. | T1: T-6 | U1: Cons. | V1: T-7 | W1: Cons. | X1: Total | Y1: Diff | Z1: Daily Money Value | AA1: MTD Total Money
A2: 44592 | B2: 0 | C2: 19316 | E2: 29669331 | G2: 94599632 | I2: =F2+H2 -> 0 | J2: 9386002 | L2: 9394543 | N2: 6292205 | P2: 5860545 | R2: 20049932 | T2: 0 | V2: 7942252 | X2: =K2+M2+O2+Q2+S2+U2+W2 -> 0 | Y2: =I2-X2 -> 0 | Z2: =(0.93352*(W2+S2)+0.5568*(Q2+O2))*0.26 -> 0
A3: 44593 | B3: 235 | C3: 19316 | D3: =IF((C3-C2)<0,"0",(C3-C2))*160 -> 0 | E3: 29677602 | F3: =IF((E3-E2)<0,"0",(E3-E2)) -> 8271 | G3: 94631745 | H3: =IF((G3-G2)<0,"0",(G3-G2)) -> 32113 | I3: =F3+H3 -> 40384 | J3: 9390076 | K3: =(IF((J3-J2)<L88,"0",(J3-J2)))*2 -> 8148 | L3: 9398108 | M3: =IF((L3-L2)<0,"0",(L3-L2)) -> 3565 | N3: 6294498 | O3: =(IF((N3-N2)<P88,"0",(N3-N2)))*2 -> 4586 | P3: 5862638 | Q3: =IF((P3-P2)<0,"0",(P3-P2)) -> 2093 | R3: 20057832 | S3: =IF((R3-R2)<0,"0",(R3-R2)) -> 7900 | T3: 0 | V3: 7950836 | W3: =IF((V3-V2)<0,"0",(V3-V2)) -> 8584 | X3: =K3+M3+O3+Q3+S3+U3+W3 -> 34876 | Y3: =I3-X3 -> 5508 | Z3: =(0.93352*(W3+S3)+0.5568*(Q3+O3))*0.26 -> 4967.8228 | AA3: =SUM(Z1:Z3) -> 4967.8228
A4: 44594 | B4: 190 | C4: 19316 | D4: =IF((C4-C3)<0,"0",(C4-C3))*160 -> 0 | E4: 29688201 | F4: =IF((E4-E3)<0,"0",(E4-E3)) -> 10599 | G4: 94675349 | H4: =IF((G4-G3)<0,"0",(G4-G3)) -> 43604 | I4: =F4+H4 -> 54203 | J4: 9395490 | K4: =(IF((J4-J3)<L90,"0",(J4-J3)))*2 -> 10828 | L4: 9402982 | M4: =IF((L4-L3)<0,"0",(L4-L3)) -> 4874 | N4: 6297286 | O4: =(IF((N4-N3)<P90,"0",(N4-N3)))*2 -> 5576 | P4: 5865839 | Q4: =IF((P4-P3)<0,"0",(P4-P3)) -> 3201 | R4: 20069112 | S4: =IF((R4-R3)<0,"0",(R4-R3)) -> 11280 | T4: 0 | V4: 7962059 | W4: =IF((V4-V3)<0,"0",(V4-V3)) -> 11223 | X4: =K4+M4+O4+Q4+S4+U4+W4 -> 46982 | Y4: =I4-X4 -> 7221 | Z4: =(0.93352*(W4+S4)+0.5568*(Q4+O4))*0.26 -> 6732.4489 | AA4: =SUM(Z2:Z4) -> 11700.272
A5: 44595 | B5: 182 | C5: 19316 | D5: =IF((C5-C4)<0,"0",(C5-C4))*160 -> 0 | E5: 29692282 | F5: =IF((E5-E4)<0,"0",(E5-E4)) -> 4081 | G5: 94703405 | H5: =IF((G5-G4)<0,"0",(G5-G4)) -> 28056 | I5: =F5+H5 -> 32137 | J5: 9398860 | K5: =(IF((J5-J4)<0,"0",(J5-J4)))*2 -> 6740 | L5: 9406057 | M5: =IF((L5-L4)<0,"0",(L5-L4)) -> 3075 | N5: 6297744 | O5: =(IF((N5-N4)<0,"0",(N5-N4)))*2 -> 916 | P5: 5870500 | Q5: =IF((P5-P4)<0,"0",(P5-P4)) -> 4661 | R5: 20075540 | S5: =IF((R5-R4)<0,"0",(R5-R4)) -> 6428 | T5: 0 | V5: 7968499 | W5: =IF((V5-V4)<0,"0",(V5-V4)) -> 6440 | X5: =K5+M5+O5+Q5+S5+U5+W5 -> 28260 | Y5: =I5-X5 -> 3877 | Z5: =(0.93352*(W5+S5)+0.5568*(Q5+O5))*0.26 -> 3930.6303 | AA5: =SUM(Z3:Z5) -> 15630.902
A6: 44596 | B6: 178 | C6: =C5 -> 19316 | D6: =IF((C6-C5)<0,"0",(C6-C5))*160 -> 0 | E6: 29701708 | F6: =IF((E6-E5)<0,"0",(E6-E5)) -> 9426 | G6: 94745214 | H6: =IF((G6-G5)<0,"0",(G6-G5)) -> 41809 | I6: =F6+H6 -> 51235 | J6: 9403743 | K6: =(IF((J6-J5)<0,"0",(J6-J5)))*2 -> 9766 | L6: 9410634 | M6: =IF((L6-L5)<0,"0",(L6-L5)) -> 4577 | N6: 6300083 | O6: =(IF((N6-N5)<0,"0",(N6-N5)))*2 -> 4678 | P6: 5874266 | Q6: =IF((P6-P5)<0,"0",(P6-P5)) -> 3766 | R6: 20086327 | S6: =IF((R6-R5)<0,"0",(R6-R5)) -> 10787 | T6: 0 | V6: 7979871 | W6: =IF((V6-V5)<0,"0",(V6-V5)) -> 11372 | X6: =K6+M6+O6+Q6+S6+U6+W6 -> 44946 | Y6: =I6-X6 -> 6289 | Z6: =(0.93352*(W6+S6)+0.5568*(Q6+O6))*0.26 -> 6600.7471 | AA6: =SUM(Z4:Z6) -> 17263.826
A7: 44597 | B7: 211 | C7: =C6 -> 19316 | D7: =IF((C7-C6)<0,"0",(C7-C6))*160 -> 0 | E7: 29710400 | F7: =IF((E7-E6)<0,"0",(E7-E6)) -> 8692 | G7: 94780849 | H7: =IF((G7-G6)<0,"0",(G7-G6)) -> 35635 | I7: =F7+H7 -> 44327 | J7: 9407932 | K7: =(IF((J7-J6)<0,"0",(J7-J6)))*2 -> 8378 | L7: 9414638 | M7: =IF((L7-L6)<0,"0",(L7-L6)) -> 4004 | N7: 6302379 | O7: =(IF((N7-N6)<0,"0",(N7-N6)))*2 -> 4592 | P7: 5876655 | Q7: =IF((P7-P6)<0,"0",(P7-P6)) -> 2389 | R7: 20095647 | S7: =IF((R7-R6)<0,"0",(R7-R6)) -> 9320 | T7: 0 | V7: 7987225 | W7: =IF((V7-V6)<0,"0",(V7-V6)) -> 7354 | X7: =K7+M7+O7+Q7+S7+U7+W7 -> 36037 | Y7: =I7-X7 -> 8290 | Z7: =(0.93352*(W7+S7)+0.5568*(Q7+O7))*0.26 -> 5057.6587 | AA7: =SUM(Z4:Z7) -> 22321.485
A8: 44598 | B8: 216 | C8: 19316 | D8: =IF((C8-C7)<0,"0",(C8-C7))*160 -> 0 | E8: 29721121 | F8: =IF((E8-E7)<0,"0",(E8-E7)) -> 10721 | G8: 94826537 | H8: =IF((G8-G7)<0,"0",(G8-G7)) -> 45688 | I8: =F8+H8 -> 56409 | J8: 9413533 | K8: =(IF((J8-J7)<0,"0",(J8-J7)))*2 -> 11202 | L8: 9419965 | M8: =IF((L8-L7)<0,"0",(L8-L7)) -> 5327 | N8: 6305242 | O8: =(IF((N8-N7)<0,"0",(N8-N7)))*2 -> 5726 | P8: 5879599 | Q8: =IF((P8-P7)<0,"0",(P8-P7)) -> 2944 | R8: 20107901 | S8: =IF((R8-R7)<0,"0",(R8-R7)) -> 12254 | T8: 0 | V8: 8000480 | W8: =IF((V8-V7)<0,"0",(V8-V7)) -> 13255 | X8: =K8+M8+O8+Q8+S8+U8+W8 -> 50708 | Y8: =I8-X8 -> 5701 | Z8: =(0.93352*(W8+S8)+0.5568*(Q8+O8))*0.26 -> 7446.5606 | AA8: =SUM(Z5:Z8) -> 23035.597
A9: 44599 | B9: 264 | C9: =C8 -> 19316 | D9: =IF((C9-C8)<0,"0",(C9-C8))*160 -> 0 | E9: 29728649 | F9: =IF((E9-E8)<0,"0",(E9-E8)) -> 7528 | G9: 94854439 | H9: =IF((G9-G8)<0,"0",(G9-G8)) -> 27902 | I9: =F9+H9 -> 35430 | J9: 9417059 | K9: =(IF((J9-J8)<0,"0",(J9-J8)))*2 -> 7052 | L9: 9422671 | M9: =IF((L9-L8)<0,"0",(L9-L8)) -> 2706 | N9: 6307350 | O9: =(IF((N9-N8)<0,"0",(N9-N8)))*2 -> 4216 | P9: 5881494 | Q9: =IF((P9-P8)<0,"0",(P9-P8)) -> 1895 | R9: 20114468 | S9: =IF((R9-R8)<0,"0",(R9-R8)) -> 6567 | T9: 0 | V9: 8004825 | W9: =IF((V9-V8)<0,"0",(V9-V8)) -> 4345 | X9: =K9+M9+O9+Q9+S9+U9+W9 -> 26781 | Y9: =I9-X9 -> 8649 | Z9: =(0.93352*(W9+S9)+0.5568*(Q9+O9))*0.26 -> 3533.1855 | AA9: =SUM(Z6:Z9) -> 22638.152
A10: 44600 | B10: 242 | C10: 19318 | D10: =IF((C10-C9)<0,"0",(C10-C9))*160 -> 320 | E10: 29741110 | F10: =IF((E10-E9)<0,"0",(E10-E9)) -> 12461 | G10: 94898627 | H10: =IF((G10-G9)<0,"0",(G10-G9)) -> 44188 | I10: =F10+H10 -> 56649 | J10: 9422641 | K10: =(IF((J10-J9)<0,"0",(J10-J9)))*2 -> 11164 | L10: 9428489 | M10: =IF((L10-L9)<0,"0",(L10-L9)) -> 5818 | N10: 6310592 | O10: =(IF((N10-N9)<0,"0",(N10-N9)))*2 -> 6484 | P10: 5884574 | Q10: =IF((P10-P9)<0,"0",(P10-P9)) -> 3080 | R10: 20125650 | S10: =IF((R10-R9)<0,"0",(R10-R9)) -> 11182 | T10: 0 | V10: 8019358 | W10: =IF((V10-V9)<0,"0",(V10-V9)) -> 14533 | X10: =K10+M10+O10+Q10+S10+U10+W10 -> 52261 | Y10: =I10-X10 -> 4388 | Z10: =(0.93352*(W10+S10)+0.5568*(Q10+O10))*0.26 -> 7625.9825 | AA10: =SUM(Z7:Z10) -> 23663.387
A11: 44601 | B11: 0 | C11: =C10 -> 19318 | D11: =IF((C11-C10)<0,"0",(C11-C10))*160 -> 0 | E11: =E10 -> 29741110 | F11: =IF((E11-E10)<0,"0",(E11-E10)) -> 0 | G11: =G10 -> 94898627 | H11: =IF((G11-G10)<0,"0",(G11-G10)) -> 0 | I11: =F11+H11 -> 0 | J11: =J10 -> 9422641 | K11: =(IF((J11-J10)<0,"0",(J11-J10)))*2 -> 0 | L11: =L10 -> 9428489 | M11: =IF((L11-L10)<0,"0",(L11-L10)) -> 0 | N11: =N10 -> 6310592 | O11: =(IF((N11-N10)<0,"0",(N11-N10)))*2 -> 0 | P11: =P10 -> 5884574 | Q11: =IF((P11-P10)<0,"0",(P11-P10)) -> 0 | R11: =R10 -> 20125650 | S11: =IF((R11-R10)<0,"0",(R11-R10)) -> 0 | T11: 0 | V11: =V10 -> 8019358 | W11: =IF((V11-V10)<0,"0",(V11-V10)) -> 0 | X11: =K11+M11+O11+Q11+S11+U11+W11 -> 0 | Y11: =I11-X11 -> 0 | Z11: =(0.93352*(W11+S11)+0.5568*(Q11+O11))*0.26 -> 0 | AA11: =SUM(Z8:Z11) -> 18605.729
A12: 44602 | B12: 0 | C12: =C11 -> 19318 | D12: =IF((C12-C11)<0,"0",(C12-C11))*160 -> 0 | E12: =E11 -> 29741110 | F12: =IF((E12-E11)<0,"0",(E12-E11)) -> 0 | G12: =G11 -> 94898627 | H12: =IF((G12-G11)<0,"0",(G12-G11)) -> 0 | I12: =F12+H12 -> 0 | J12: =J11 -> 9422641 | K12: =(IF((J12-J11)<0,"0",(J12-J11)))*2 -> 0 | L12: =L11 -> 9428489 | M12: =IF((L12-L11)<0,"0",(L12-L11)) -> 0 | N12: =N11 -> 6310592 | O12: =(IF((N12-N11)<0,"0",(N12-N11)))*2 -> 0 | P12: =P11 -> 5884574 | Q12: =IF((P12-P11)<0,"0",(P12-P11)) -> 0 | R12: =R11 -> 20125650 | S12: =IF((R12-R11)<0,"0",(R12-R11)) -> 0 | T12: 0 | V12: =V11 -> 8019358 | W12: =IF((V12-V11)<0,"0",(V12-V11)) -> 0 | X12: =K12+M12+O12+Q12+S12+U12+W12 -> 0 | Y12: =I12-X12 -> 0 | Z12: =(0.93352*(W12+S12)+0.5568*(Q12+O12))*0.26 -> 0 | AA12: =SUM(Z9:Z12) -> 11159.168
A13: 44603 | B13: 0 | C13: =C12 -> 19318 | D13: =IF((C13-C12)<0,"0",(C13-C12))*160 -> 0 | E13: =E12 -> 29741110 | F13: =IF((E13-E12)<0,"0",(E13-E12)) -> 0 | G13: =G12 -> 94898627 | H13: =IF((G13-G12)<0,"0",(G13-G12)) -> 0 | I13: =F13+H13 -> 0 | J13: =J12 -> 9422641 | K13: =(IF((J13-J12)<0,"0",(J13-J12)))*2 -> 0 | L13: =L12 -> 9428489 | M13: =IF((L13-L12)<0,"0",(L13-L12)) -> 0 | N13: =N12 -> 6310592 | O13: =(IF((N13-N12)<0,"0",(N13-N12)))*2 -> 0 | P13: =P12 -> 5884574 | Q13: =IF((P13-P12)<0,"0",(P13-P12)) -> 0 | R13: =R12 -> 20125650 | S13: =IF((R13-R12)<0,"0",(R13-R12)) -> 0 | T13: 0 | V13: =V12 -> 8019358 | W13: =IF((V13-V12)<0,"0",(V13-V12)) -> 0 | X13: =K13+M13+O13+Q13+S13+U13+W13 -> 0 | Y13: =I13-X13 -> 0 | Z13: =(0.93352*(W13+S13)+0.5568*(Q13+O13))*0.26 -> 0 | AA13: =SUM(Z10:Z13) -> 7625.9825
A14: 44604 | B14: 0 | C14: =C13 -> 19318 | D14: =IF((C14-C13)<0,"0",(C14-C13))*160 -> 0 | E14: =E13 -> 29741110 | F14: =IF((E14-E13)<0,"0",(E14-E13)) -> 0 | G14: =G13 -> 94898627 | H14: =IF((G14-G13)<0,"0",(G14-G13)) -> 0 | I14: =F14+H14 -> 0 | J14: =J13 -> 9422641 | K14: =(IF((J14-J13)<0,"0",(J14-J13)))*2 -> 0 | L14: =L13 -> 9428489 | M14: =IF((L14-L13)<0,"0",(L14-L13)) -> 0 | N14: =N13 -> 6310592 | O14: =(IF((N14-N13)<0,"0",(N14-N13)))*2 -> 0 | P14: =P13 -> 5884574 | Q14: =IF((P14-P13)<0,"0",(P14-P13)) -> 0 | R14: =R13 -> 20125650 | S14: =IF((R14-R13)<0,"0",(R14-R13)) -> 0 | T14: 0 | V14: =V13 -> 8019358 | W14: =IF((V14-V13)<0,"0",(V14-V13)) -> 0 | X14: =K14+M14+O14+Q14+S14+U14+W14 -> 0 | Y14: =I14-X14 -> 0 | Z14: =(0.93352*(W14+S14)+0.5568*(Q14+O14))*0.26 -> 0 | AA14: =SUM(Z11:Z14) -> 0
A15: 44605 | B15: 0 | C15: =C14 -> 19318 | D15: =IF((C15-C14)<0,"0",(C15-C14))*160 -> 0 | E15: =E14 -> 29741110 | F15: =IF((E15-E14)<0,"0",(E15-E14)) -> 0 | G15: =G14 -> 94898627 | H15: =IF((G15-G14)<0,"0",(G15-G14)) -> 0 | I15: =F15+H15 -> 0 | J15: =J14 -> 9422641 | K15: =(IF((J15-J14)<0,"0",(J15-J14)))*2 -> 0 | L15: =L14 -> 9428489 | M15: =IF((L15-L14)<0,"0",(L15-L14)) -> 0 | N15: =N14 -> 6310592 | O15: =(IF((N15-N14)<0,"0",(N15-N14)))*2 -> 0 | P15: =P14 -> 5884574 | Q15: =IF((P15-P14)<0,"0",(P15-P14)) -> 0 | R15: =R14 -> 20125650 | S15: =IF((R15-R14)<0,"0",(R15-R14)) -> 0 | T15: 0 | V15: =V14 -> 8019358 | W15: =IF((V15-V14)<0,"0",(V15-V14)) -> 0 | X15: =K15+M15+O15+Q15+S15+U15+W15 -> 0 | Y15: =I15-X15 -> 0 | Z15: =(0.93352*(W15+S15)+0.5568*(Q15+O15))*0.26 -> 0 | AA15: =SUM(Z12:Z15) -> 0
A16: 44606 | B16: 0 | C16: =C15 -> 19318 | D16: =IF((C16-C15)<0,"0",(C16-C15))*160 -> 0 | E16: =E15 -> 29741110 | F16: =IF((E16-E15)<0,"0",(E16-E15)) -> 0 | G16: =G15 -> 94898627 | H16: =IF((G16-G15)<0,"0",(G16-G15)) -> 0 | I16: =F16+H16 -> 0 | J16: =J15 -> 9422641 | K16: =(IF((J16-J15)<0,"0",(J16-J15)))*2 -> 0 | L16: =L15 -> 9428489 | M16: =IF((L16-L15)<0,"0",(L16-L15)) -> 0 | N16: =N15 -> 6310592 | O16: =(IF((N16-N15)<0,"0",(N16-N15)))*2 -> 0 | P16: =P15 -> 5884574 | Q16: =IF((P16-P15)<0,"0",(P16-P15)) -> 0 | R16: =R15 -> 20125650 | S16: =IF((R16-R15)<0,"0",(R16-R15)) -> 0 | T16: 0 | V16: =V15 -> 8019358 | W16: =IF((V16-V15)<0,"0",(V16-V15)) -> 0 | X16: =K16+M16+O16+Q16+S16+U16+W16 -> 0 | Y16: =I16-X16 -> 0 | Z16: =(0.93352*(W16+S16)+0.5568*(Q16+O16))*0.26 -> 0 | AA16: =SUM(Z13:Z16) -> 0
A17: 44607 | B17: 0 | C17: =C16 -> 19318 | D17: =IF((C17-C16)<0,"0",(C17-C16))*160 -> 0 | E17: =E16 -> 29741110 | F17: =IF((E17-E16)<0,"0",(E17-E16)) -> 0 | G17: =G16 -> 94898627 | H17: =IF((G17-G16)<0,"0",(G17-G16)) -> 0 | I17: =F17+H17 -> 0 | J17: =J16 -> 9422641 | K17: =(IF((J17-J16)<0,"0",(J17-J16)))*2 -> 0 | L17: =L16 -> 9428489 | M17: =IF((L17-L16)<0,"0",(L17-L16)) -> 0 | N17: =N16 -> 6310592 | O17: =(IF((N17-N16)<0,"0",(N17-N16)))*2 -> 0 | P17: =P16 -> 5884574 | Q17: =IF((P17-P16)<0,"0",(P17-P16)) -> 0 | R17: =R16 -> 20125650 | S17: =IF((R17-R16)<0,"0",(R17-R16)) -> 0 | T17: 0 | V17: =V16 -> 8019358 | W17: =IF((V17-V16)<0,"0",(V17-V16)) -> 0 | X17: =K17+M17+O17+Q17+S17+U17+W17 -> 0 | Y17: =I17-X17 -> 0 | Z17: =(0.93352*(W17+S17)+0.5568*(Q17+O17))*0.26 -> 0 | AA17: =SUM(Z14:Z17) -> 0
A18: 44608 | B18: 0 | C18: =C17 -> 19318 | D18: =IF((C18-C17)<0,"0",(C18-C17))*160 -> 0 | E18: =E17 -> 29741110 | F18: =IF((E18-E17)<0,"0",(E18-E17)) -> 0 | G18: =G17 -> 94898627 | H18: =IF((G18-G17)<0,"0",(G18-G17)) -> 0 | I18: =F18+H18 -> 0 | J18: =J17 -> 9422641 | K18: =(IF((J18-J17)<0,"0",(J18-J17)))*2 -> 0 | L18: =L17 -> 9428489 | M18: =IF((L18-L17)<0,"0",(L18-L17)) -> 0 | N18: =N17 -> 6310592 | O18: =(IF((N18-N17)<0,"0",(N18-N17)))*2 -> 0 | P18: =P17 -> 5884574 | Q18: =IF((P18-P17)<0,"0",(P18-P17)) -> 0 | R18: =R17 -> 20125650 | S18: =IF((R18-R17)<0,"0",(R18-R17)) -> 0 | T18: 0 | V18: =V17 -> 8019358 | W18: =IF((V18-V17)<0,"0",(V18-V17)) -> 0 | X18: =K18+M18+O18+Q18+S18+U18+W18 -> 0 | Y18: =I18-X18 -> 0 | Z18: =(0.93352*(W18+S18)+0.5568*(Q18+O18))*0.26 -> 0 | AA18: =SUM(Z15:Z18) -> 0
A19: 44609 | B19: 0 | C19: =C18 -> 19318 | D19: =IF((C19-C18)<0,"0",(C19-C18))*160 -> 0 | E19: =E18 -> 29741110 | F19: =IF((E19-E18)<0,"0",(E19-E18)) -> 0 | G19: =G18 -> 94898627 | H19: =IF((G19-G18)<0,"0",(G19-G18)) -> 0 | I19: =F19+H19 -> 0 | J19: =J18 -> 9422641 | K19: =(IF((J19-J18)<0,"0",(J19-J18)))*2 -> 0 | L19: =L18 -> 9428489 | M19: =IF((L19-L18)<0,"0",(L19-L18)) -> 0 | N19: =N18 -> 6310592 | O19: =(IF((N19-N18)<0,"0",(N19-N18)))*2 -> 0 | P19: =P18 -> 5884574 | Q19: =IF((P19-P18)<0,"0",(P19-P18)) -> 0 | R19: =R18 -> 20125650 | S19: =IF((R19-R18)<0,"0",(R19-R18)) -> 0 | T19: 0 | V19: =V18 -> 8019358 | W19: =IF((V19-V18)<0,"0",(V19-V18)) -> 0 | X19: =K19+M19+O19+Q19+S19+U19+W19 -> 0 | Y19: =I19-X19 -> 0 | Z19: =(0.93352*(W19+S19)+0.5568*(Q19+O19))*0.26 -> 0 | AA19: =SUM(Z16:Z19) -> 0
A20: 44610 | B20: 0 | C20: =C19 -> 19318 | D20: =IF((C20-C19)<0,"0",(C20-C19))*160 -> 0 | E20: =E19 -> 29741110 | F20: =IF((E20-E19)<0,"0",(E20-E19)) -> 0 | G20: =G19 -> 94898627 | H20: =IF((G20-G19)<0,"0",(G20-G19)) -> 0 | I20: =F20+H20 -> 0 | J20: =J19 -> 9422641 | K20: =(IF((J20-J19)<0,"0",(J20-J19)))*2 -> 0 | L20: =L19 -> 9428489 | M20: =IF((L20-L19)<0,"0",(L20-L19)) -> 0 | N20: =N19 -> 6310592 | O20: =(IF((N20-N19)<0,"0",(N20-N19)))*2 -> 0 | P20: =P19 -> 5884574 | Q20: =IF((P20-P19)<0,"0",(P20-P19)) -> 0 | R20: =R19 -> 20125650 | S20: =IF((R20-R19)<0,"0",(R20-R19)) -> 0 | T20: 0 | V20: =V19 -> 8019358 | W20: =IF((V20-V19)<0,"0",(V20-V19)) -> 0 | X20: =K20+M20+O20+Q20+S20+U20+W20 -> 0 | Y20: =I20-X20 -> 0 | Z20: =(0.93352*(W20+S20)+0.5568*(Q20+O20))*0.26 -> 0 | AA20: =SUM(Z17:Z20) -> 0
A21: 44611 | B21: 0 | C21: =C20 -> 19318 | D21: =IF((C21-C20)<0,"0",(C21-C20))*160 -> 0 | E21: =E20 -> 29741110 | F21: =IF((E21-E20)<0,"0",(E21-E20)) -> 0 | G21: =G20 -> 94898627 | H21: =IF((G21-G20)<0,"0",(G21-G20)) -> 0 | I21: =F21+H21 -> 0 | J21: =J20 -> 9422641 | K21: =(IF((J21-J20)<0,"0",(J21-J20)))*2 -> 0 | L21: =L20 -> 9428489 | M21: =IF((L21-L20)<0,"0",(L21-L20)) -> 0 | N21: =N20 -> 6310592 | O21: =(IF((N21-N20)<0,"0",(N21-N20)))*2 -> 0 | P21: =P20 -> 5884574 | Q21: =IF((P21-P20)<0,"0",(P21-P20)) -> 0 | R21: =R20 -> 20125650 | S21: =IF((R21-R20)<0,"0",(R21-R20)) -> 0 | T21: 0 | V21: =V20 -> 8019358 | W21: =IF((V21-V20)<0,"0",(V21-V20)) -> 0 | X21: =K21+M21+O21+Q21+S21+U21+W21 -> 0 | Y21: =I21-X21 -> 0 | Z21: =(0.93352*(W21+S21)+0.5568*(Q21+O21))*0.26 -> 0 | AA21: =SUM(Z18:Z21) -> 0
A22: 44612 | B22: 0 | C22: =C21 -> 19318 | D22: =IF((C22-C21)<0,"0",(C22-C21))*160 -> 0 | E22: =E21 -> 29741110 | F22: =IF((E22-E21)<0,"0",(E22-E21)) -> 0 | G22: =G21 -> 94898627 | H22: =IF((G22-G21)<0,"0",(G22-G21)) -> 0 | I22: =F22+H22 -> 0 | J22: =J21 -> 9422641 | K22: =(IF((J22-J21)<0,"0",(J22-J21)))*2 -> 0 | L22: =L21 -> 9428489 | M22: =IF((L22-L21)<0,"0",(L22-L21)) -> 0 | N22: =N21 -> 6310592 | O22: =(IF((N22-N21)<0,"0",(N22-N21)))*2 -> 0 | P22: =P21 -> 5884574 | Q22: =IF((P22-P21)<0,"0",(P22-P21)) -> 0 | R22: =R21 -> 20125650 | S22: =IF((R22-R21)<0,"0",(R22-R21)) -> 0 | T22: 0 | V22: =V21 -> 8019358 | W22: =IF((V22-V21)<0,"0",(V22-V21)) -> 0 | X22: =K22+M22+O22+Q22+S22+U22+W22 -> 0 | Y22: =I22-X22 -> 0 | Z22: =(0.93352*(W22+S22)+0.5568*(Q22+O22))*0.26 -> 0 | AA22: =SUM(Z19:Z22) -> 0
... A30: 44620 | B30: 0 | C30: =C29 -> 19318 | D30: =IF((C30-C29)<0,"0",(C30-C29))*160 -> 0 | E30: =E29 -> 29741110 | F30: =IF((E30-E29)<0,"0",(E30-E29)) -> 0 | G30: =G29 -> 94898627 | H30: =IF((G30-G29)<0,"0",(G30-G29)) -> 0 | I30: =F30+H30 -> 0 | J30: =J29 -> 9422641 | K30: =(IF((J30-J29)<0,"0",(J30-J29)))*2 -> 0 | L30: =L29 -> 9428489 | M30: =IF((L30-L29)<0,"0",(L30-L29)) -> 0 | N30: =N29 -> 6310592 | O30: =(IF((N30-N29)<0,"0",(N30-N29)))*2 -> 0 | P30: =P29 -> 5884574 | Q30: =IF((P30-P29)<0,"0",(P30-P29)) -> 0 | R30: =R29 -> 20125650 | S30: =IF((R30-R29)<0,"0",(R30-R29)) -> 0 | T30: 0 | V30: =V29 -> 8019358 | W30: =IF((V30-V29)<0,"0",(V30-V29)) -> 0 | X30: =K30+M30+O30+Q30+S30+U30+W30 -> 0 | Y30: =I30-X30 -> 0 | Z30: =(0.93352*(W30+S30)+0.5568*(Q30+O30))*0.26 -> 0 | AA30: =SUM(Z27:Z30) -> 0
A31: Total | B31: =SUM(B3:B30) -> 1718 | D31: =SUM(D3:D30) -> 320 | E31: 0 | F31: =SUM(F3:F30) -> 71779 | G31: 0 | H31: =SUM(H3:H30) -> 298995 | I31: =SUM(I6:I30) -> 244050 | J31: 0 | K31: =SUM(K3:K30) -> 73278 | L31: 0 | M31: =SUM(M3:M30) -> 33946 | N31: 0 | O31: =SUM(O3:O30) -> 36774 | P31: 0 | Q31: =SUM(Q3:Q30) -> 24029 | R31: 0 | S31: =SUM(S3:S30) -> 75718 | T31: =SUM(T6:T30) -> 0 | U31: =SUM(U3:U30) -> 0 | V31: 0 | W31: =SUM(W3:W30) -> 77106 | X31: =SUM(X6:X30) -> 210733 | Y31: =SUM(Y3:Y30) -> 49923 | Z31: =SUM(Z3:Z30) -> 45895.036 | AA31: =SUM(AA3:AA30) -> 178612.32

Sheet Water
A1: Day | B1: Main Reading | C1: Cons. | D1: Podium | E1: Cons. | F1: Hotel | G1: Cons. | H1: Large | I1: Cons. | J1: Total | K1: cost.LE
A2: 44592 | B2: 438386 | D2: 2852 | F2: 7674600 | H2: 771836 | J2: =C2+E2+G2+I2 -> 0 | K2: =J2*5.86 -> 0
A3: 44593 | B3: 438470 | C3: =(IF((B3-B2)<0,"0",(B3-B2)))*10 -> 840 | D3: 2901 | E3: =(D3-D2)*10 -> 490 | F3: 7683400 | G3: =(IF((F3-F2)<0,"0",(F3-F2)))*0.027 -> 237.6 | H3: 772041 | I3: =(IF((H3-H2)<0,"0",(H3-H2)))*0.027 -> 5.535 | J3: =C3+E3+G3+I3 -> 1573.135 | K3: =J3*5.86 -> 9218.5711
A4: 44594 | B4: 438551 | C4: =(IF((B4-B3)<0,"0",(B4-B3)))*10 -> 810 | D4: 2951 | E4: =(D4-D3)*10 -> 500 | F4: 7692700 | G4: =(IF((F4-F3)<0,"0",(F4-F3)))*0.027 -> 251.1 | H4: 772251 | I4: =(IF((H4-H3)<0,"0",(H4-H3)))*0.027 -> 5.67 | J4: =C4+E4+G4+I4 -> 1566.77 | K4: =J4*5.86 -> 9181.2722
A5: 44595 | B5: 438632 | C5: =(IF((B5-B4)<0,"0",(B5-B4)))*10 -> 810 | D5: 3001 | E5: =(D5-D4)*10 -> 500 | F5: 7702000 | G5: =(IF((F5-F4)<0,"0",(F5-F4)))*0.027 -> 251.1 | H5: 772461 | I5: =(IF((H5-H4)<0,"0",(H5-H4)))*0.027 -> 5.67 | J5: =C5+E5+G5+I5 -> 1566.77 | K5: =J5*5.86 -> 9181.2722
A6: 44596 | B6: 438706 | C6: =(IF((B6-B5)<0,"0",(B6-B5)))*10 -> 740 | D6: 3047 | E6: =(D6-D5)*10 -> 460 | F6: 7709800 | G6: =(IF((F6-F5)<0,"0",(F6-F5)))*0.027 -> 210.6 | H6: 772644 | I6: =(IF((H6-H5)<0,"0",(H6-H5)))*0.027 -> 4.941 | J6: =C6+E6+G6+I6 -> 1415.541 | K6: =J6*5.86 -> 8295.0703
A7: 44597 | B7: 438790 | C7: =(IF((B7-B6)<0,"0",(B7-B6)))*10 -> 840 | D7: 3094 | E7: =(D7-D6)*10 -> 470 | F7: 7717300 | G7: =(IF((F7-F6)<0,"0",(F7-F6)))*0.027 -> 202.5 | H7: 772851 | I7: =(IF((H7-H6)<0,"0",(H7-H6)))*0.027 -> 5.589 | J7: =C7+E7+G7+I7 -> 1518.089 | K7: =J7*5.86 -> 8896.0015
A8: 44598 | B8: 438874 | C8: =(IF((B8-B7)<0,"0",(B8-B7)))*10 -> 840 | D8: 3146 | E8: =(D8-D7)*10 -> 520 | F8: 7725000 | G8: =(IF((F8-F7)<0,"0",(F8-F7)))*0.027 -> 207.9 | H8: 773084 | I8: =(IF((H8-H7)<0,"0",(H8-H7)))*0.027 -> 6.291 | J8: =C8+E8+G8+I8 -> 1574.191 | K8: =J8*5.86 -> 9224.7593
A9: 44599 | B9: 438954 | C9: =(IF((B9-B8)<0,"0",(B9-B8)))*10 -> 800 | D9: 3190 | E9: =(D9-D8)*10 -> 440 | F9: 7734100 | G9: =(IF((F9-F8)<0,"0",(F9-F8)))*0.027 -> 245.7 | H9: 773294 | I9: =(IF((H9-H8)<0,"0",(H9-H8)))*0.027 -> 5.67 | J9: =C9+E9+G9+I9 -> 1491.37 | K9: =J9*5.86 -> 8739.4282
A10: 44600 | B10: 439043 | C10: =(IF((B10-B9)<0,"0",(B10-B9)))*10 -> 890 | D10: 3237 | E10: =(D10-D9)*10 -> 470 | F10: 7746400 | G10: =(IF((F10-F9)<0,"0",(F10-F9)))*0.027 -> 332.1 | H10: 773519 | I10: =(IF((H10-H9)<0,"0",(H10-H9)))*0.027 -> 6.075 | J10: =C10+E10+G10+I10 -> 1698.175 | K10: =J10*5.86 -> 9951.3055
A11: 44601 | B11: =B10 -> 439043 | C11: =(IF((B11-B10)<0,"0",(B11-B10)))*10 -> 0 | D11: =D10 -> 3237 | E11: =(D11-D10)*10 -> 0 | F11: =F10 -> 7746400 | G11: =(IF((F11-F10)<0,"0",(F11-F10)))*0.027 -> 0 | H11: =H10 -> 773519 | I11: =(IF((H11-H10)<0,"0",(H11-H10)))*0.027 -> 0 | J11: =C11+E11+G11+I11 -> 0 | K11: =J11*5.86 -> 0
A12: 44602 | B12: =B11 -> 439043 | C12: =(IF((B12-B11)<0,"0",(B12-B11)))*10 -> 0 | D12: =D11 -> 3237 | E12: =(D12-D11)*10 -> 0 | F12: =F11 -> 7746400 | G12: =(IF((F12-F11)<0,"0",(F12-F11)))*0.027 -> 0 | H12: =H11 -> 773519 | I12: =(IF((H12-H11)<0,"0",(H12-H11)))*0.027 -> 0 | J12: =C12+E12+G12+I12 -> 0 | K12: =J12*5.86 -> 0
A13: 44603 | B13: =B12 -> 439043 | C13: =(IF((B13-B12)<0,"0",(B13-B12)))*10 -> 0 | D13: =D12 -> 3237 | E13: =(D13-D12)*10 -> 0 | F13: =F12 -> 7746400 | G13: =(IF((F13-F12)<0,"0",(F13-F12)))*0.027 -> 0 | H13: =H12 -> 773519 | I13: =(IF((H13-H12)<0,"0",(H13-H12)))*0.027 -> 0 | J13: =C13+E13+G13+I13 -> 0 | K13: =J13*5.86 -> 0
A14: 44604 | B14: =B13 -> 439043 | C14: =(IF((B14-B13)<0,"0",(B14-B13)))*10 -> 0 | D14: =D13 -> 3237 | E14: =(D14-D13)*10 -> 0 | F14: =F13 -> 7746400 | G14: =(IF((F14-F13)<0,"0",(F14-F13)))*0.027 -> 0 | H14: =H13 -> 773519 | I14: =(IF((H14-H13)<0,"0",(H14-H13)))*0.027 -> 0 | J14: =C14+E14+G14+I14 -> 0 | K14: =J14*5.86 -> 0
A15: 44605 | B15: =B14 -> 439043 | C15: =(IF((B15-B14)<0,"0",(B15-B14)))*10 -> 0 | D15: =D14 -> 3237 | E15: =(D15-D14)*10 -> 0 | F15: =F14 -> 7746400 | G15: =(IF((F15-F14)<0,"0",(F15-F14)))*0.027 -> 0 | H15: =H14 -> 773519 | I15: =(IF((H15-H14)<0,"0",(H15-H14)))*0.027 -> 0 | J15: =C15+E15+G15+I15 -> 0 | K15: =J15*5.86 -> 0
A16: 44606 | B16: =B15 -> 439043 | C16: =(IF((B16-B15)<0,"0",(B16-B15)))*10 -> 0 | D16: =D15 -> 3237 | E16: =(D16-D15)*10 -> 0 | F16: =F15 -> 7746400 | G16: =(IF((F16-F15)<0,"0",(F16-F15)))*0.027 -> 0 | H16: =H15 -> 773519 | I16: =(IF((H16-H15)<0,"0",(H16-H15)))*0.027 -> 0 | J16: =C16+E16+G16+I16 -> 0 | K16: =J16*5.86 -> 0
A17: 44607 | B17: =B16 -> 439043 | C17: =(IF((B17-B16)<0,"0",(B17-B16)))*10 -> 0 | D17: =D16 -> 3237 | E17: =(D17-D16)*10 -> 0 | F17: =F16 -> 7746400 | G17: =(IF((F17-F16)<0,"0",(F17-F16)))*0.027 -> 0 | H17: =H16 -> 773519 | I17: =(IF((H17-H16)<0,"0",(H17-H16)))*0.027 -> 0 | J17: =C17+E17+G17+I17 -> 0 | K17: =J17*5.86 -> 0
A18: 44608 | B18: =B17 -> 439043 | C18: =(IF((B18-B17)<0,"0",(B18-B17)))*10 -> 0 | D18: =D17 -> 3237 | E18: =(D18-D17)*10 -> 0 | F18: =F17 -> 7746400 | G18: =(IF((F18-F17)<0,"0",(F18-F17)))*0.027 -> 0 | H18: =H17 -> 773519 | I18: =(IF((H18-H17)<0,"0",(H18-H17)))*0.027 -> 0 | J18: =C18+E18+G18+I18 -> 0 | K18: =J18*5.86 -> 0 | Q18: `
A19: 44609 | B19: =B18 -> 439043 | C19: =(IF((B19-B18)<0,"0",(B19-B18)))*10 -> 0 | D19: =D18 -> 3237 | E19: =(D19-D18)*10 -> 0 | F19: =F18 -> 7746400 | G19: =(IF((F19-F18)<0,"0",(F19-F18)))*0.027 -> 0 | H19: =H18 -> 773519 | I19: =(IF((H19-H18)<0,"0",(H19-H18)))*0.027 -> 0 | J19: =C19+E19+G19+I19 -> 0 | K19: =J19*5.86 -> 0
A20: 44610 | B20: =B19 -> 439043 | C20: =(IF((B20-B19)<0,"0",(B20-B19)))*10 -> 0 | D20: =D19 -> 3237 | E20: =(D20-D19)*10 -> 0 | F20: =F19 -> 7746400 | G20: =(IF((F20-F19)<0,"0",(F20-F19)))*0.027 -> 0 | H20: =H19 -> 773519 | I20: =(IF((H20-H19)<0,"0",(H20-H19)))*0.027 -> 0 | J20: =C20+E20+G20+I20 -> 0 | K20: =J20*5.86 -> 0
A21: 44611 | B21: =B20 -> 439043 | C21: =(IF((B21-B20)<0,"0",(B21-B20)))*10 -> 0 | D21: =D20 -> 3237 | E21: =(D21-D20)*10 -> 0 | F21: =F20 -> 7746400 | G21: =(IF((F21-F20)<0,"0",(F21-F20)))*0.027 -> 0 | H21: =H20 -> 773519 | I21: =(IF((H21-H20)<0,"0",(H21-H20)))*0.027 -> 0 | J21: =C21+E21+G21+I21 -> 0 | K21: =J21*5.86 -> 0
A22: 44612 | B22: =B21 -> 439043 | C22: =(IF((B22-B21)<0,"0",(B22-B21)))*10 -> 0 | D22: =D21 -> 3237 | E22: =(D22-D21)*10 -> 0 | F22: =F21 -> 7746400 | G22: =(IF((F22-F21)<0,"0",(F22-F21)))*0.027 -> 0 | H22: =H21 -> 773519 | I22: =(IF((H22-H21)<0,"0",(H22-H21)))*0.027 -> 0 | J22: =C22+E22+G22+I22 -> 0 | K22: =J22*5.86 -> 0
A23: 44613 | B23: =B22 -> 439043 | C23: =(IF((B23-B22)<0,"0",(B23-B22)))*10 -> 0 | D23: =D22 -> 3237 | E23: =(D23-D22)*10 -> 0 | F23: =F22 -> 7746400 | G23: =(IF((F23-F22)<0,"0",(F23-F22)))*0.027 -> 0 | H23: =H22 -> 773519 | I23: =(IF((H23-H22)<0,"0",(H23-H22)))*0.027 -> 0 | J23: =C23+E23+G23+I23 -> 0 | K23: =J23*5.86 -> 0
