Workbook

Sheet TOTAL
A1: Site Name | B1: Day | C1: Month | D1: Year | E1: Total Electricity Kwh | F1: Electricity Tariff ($/Kwh) | G1: Natual Gas (m3) | H1: Natural Gas $/m3 | I1: Water Utility Supply (m3) m3 | J1: Water Utility Supply (m3) $/m3 | K1: Room Nights | L1: Total Guests | M1: Utilities day cost dh
A2: Mumbai | B2: 1 | C2: 2 | D2: 2022 | E2: =(IF('Daily HLP'!H4>0,'Daily HLP'!H4,0)) -> 17458.85 | F2: 9 | G2: =(IF('Daily HLP'!L4>0,'Daily HLP'!L4,0)) -> 918.558 | H2: 75 | I2: =(IF('Daily HLP'!O4>0,'Daily HLP'!O4,0)) -> 235 | J2: 99 | K2: =Occupancy!G2 -> 126 | L2: =Occupancy!F2 -> 290 | M2: =E2*F2+G2*H2+#REF!*#REF!+I2*J2 -> #REF!
A3: Mumbai | B3: =B2+1 -> 2 | C3: 2 | D3: 2022 | E3: =(IF('Daily HLP'!H5>0,'Daily HLP'!H5,0)) -> 18338 | F3: 9 | G3: =(IF('Daily HLP'!L5>0,'Daily HLP'!L5,0)) -> 983.145 | H3: 75 | I3: =(IF('Daily HLP'!O5>0,'Daily HLP'!O5,0)) -> 183 | J3: 99 | K3: =Occupancy!G3 -> 142 | L3: =Occupancy!F3 -> 352 | M3: =E3*F3+G3*H3+#REF!*#REF!+I3*J3 -> #REF!
A4: Mumbai | B4: =B3+1 -> 3 | C4: 2 | D4: 2022 | E4: =(IF('Daily HLP'!H6>0,'Daily HLP'!H6,0)) -> 19219 | F4: 9 | G4: =(IF('Daily HLP'!L6>0,'Daily HLP'!L6,0)) -> 1012.348 | H4: 75 | I4: =(IF('Daily HLP'!O6>0,'Daily HLP'!O6,0)) -> 233 | J4: 99 | K4: =Occupancy!G4 -> 145 | L4: =Occupancy!F4 -> 406 | M4: =E4*F4+G4*H4+#REF!*#REF!+I4*J4 -> #REF!
A5: Mumbai | B5: =B4+1 -> 4 | C5: 2 | D5: 2022 | E5: =(IF('Daily HLP'!H7>0,'Daily HLP'!H7,0)) -> 18612.71 | F5: 9 | G5: =(IF('Daily HLP'!L7>0,'Daily HLP'!L7,0)) -> 997.952 | H5: 75 | I5: =(IF('Daily HLP'!O7>0,'Daily HLP'!O7,0)) -> 261 | J5: 99 | K5: =Occupancy!G5 -> 166 | L5: =Occupancy!F5 -> 461 | M5: =E5*F5+G5*H5+#REF!*#REF!+I5*J5 -> #REF!
A6: Mumbai | B6: =B5+1 -> 5 | C6: 2 | D6: 2022 | E6: =(IF('Daily HLP'!H8>0,'Daily HLP'!H8,0)) -> 20830.96 | F6: 9 | G6: =(IF('Daily HLP'!L8>0,'Daily HLP'!L8,0)) -> 1047.87 | H6: 75 | I6: =(IF('Daily HLP'!O8>0,'Daily HLP'!O8,0)) -> 294 | J6: 99 | K6: =Occupancy!G6 -> 171 | L6: =Occupancy!F6 -> 1487 | M6: =E6*F6+G6*H6+#REF!*#REF!+I6*J6 -> #REF!
A7: Mumbai | B7: =B6+1 -> 6 | C7: 2 | D7: 2022 | E7: =(IF('Daily HLP'!H9>0,'Daily HLP'!H9,0)) -> 20612 | F7: 9 | G7: =(IF('Daily HLP'!L9>0,'Daily HLP'!L9,0)) -> 1049.5 | H7: 75 | I7: =(IF('Daily HLP'!O9>0,'Daily HLP'!O9,0)) -> 275 | J7: 99 | K7: =Occupancy!G7 -> 150 | L7: =Occupancy!F7 -> 494 | M7: =E7*F7+G7*H7+#REF!*#REF!+I7*J7 -> #REF!
A8: Mumbai | B8: =B7+1 -> 7 | C8: 2 | D8: 2022 | E8: =(IF('Daily HLP'!H10>0,'Daily HLP'!H10,0)) -> 21704.24 | F8: 9 | G8: =(IF('Daily HLP'!L10>0,'Daily HLP'!L10,0)) -> 1030.68 | H8: 75 | I8: =(IF('Daily HLP'!O10>0,'Daily HLP'!O10,0)) -> 242 | J8: 99 | K8: =Occupancy!G8 -> 159 | L8: =Occupancy!F8 -> 704 | M8: =E8*F8+G8*H8+#REF!*#REF!+I8*J8 -> #REF!
A9: Mumbai | B9: =B8+1 -> 8 | C9: 2 | D9: 2022 | E9: =(IF('Daily HLP'!H11>0,'Daily HLP'!H11,0)) -> 19730.09 | F9: 9 | G9: =(IF('Daily HLP'!L11>0,'Daily HLP'!L11,0)) -> 1052.18 | H9: 75 | I9: =(IF('Daily HLP'!O11>0,'Daily HLP'!O11,0)) -> 232 | J9: 99 | K9: =Occupancy!G9 -> 129 | L9: =Occupancy!F9 -> 418 | M9: =E9*F9+G9*H9+#REF!*#REF!+I9*J9 -> #REF!
A10: Mumbai | B10: =B9+1 -> 9 | C10: 2 | D10: 2022 | E10: =(IF('Daily HLP'!H12>0,'Daily HLP'!H12,0)) -> 19467 | F10: 9 | G10: =(IF('Daily HLP'!L12>0,'Daily HLP'!L12,0)) -> 1070 | H10: 75 | I10: =(IF('Daily HLP'!O12>0,'Daily HLP'!O12,0)) -> 256 | J10: 99 | K10: =Occupancy!G10 -> 144 | L10: =Occupancy!F10 -> 483 | M10: =E10*F10+G10*H10+#REF!*#REF!+I10*J10 -> #REF!
A11: Mumbai | B11: =B10+1 -> 10 | C11: 2 | D11: 2022 | E11: =(IF('Daily HLP'!H13>0,'Daily HLP'!H13,0)) -> 20373 | F11: 9 | G11: =(IF('Daily HLP'!L13>0,'Daily HLP'!L13,0)) -> 1152 | H11: 75 | I11: =(IF('Daily HLP'!O13>0,'Daily HLP'!O13,0)) -> 317 | J11: 99 | K11: =Occupancy!G11 -> 149 | L11: =Occupancy!F11 -> 723 | M11: =E11*F11+G11*H11+#REF!*#REF!+I11*J11 -> #REF!
A12: Mumbai | B12: =B11+1 -> 11 | C12: 2 | D12: 2022 | E12: =(IF('Daily HLP'!H14>0,'Daily HLP'!H14,0)) -> 21020 | F12: 9 | G12: =(IF('Daily HLP'!L14>0,'Daily HLP'!L14,0)) -> 1118 | H12: 75 | I12: =(IF('Daily HLP'!O14>0,'Daily HLP'!O14,0)) -> 316 | J12: 99 | K12: =Occupancy!G12 -> 148 | L12: =Occupancy!F12 -> 899 | M12: =E12*F12+G12*H12+#REF!*#REF!+I12*J12 -> #REF!
A13: Mumbai | B13: =B12+1 -> 12 | C13: 2 | D13: 2022 | E13: =(IF('Daily HLP'!H15>0,'Daily HLP'!H15,0)) -> 22339 | F13: 9 | G13: =(IF('Daily HLP'!L15>0,'Daily HLP'!L15,0)) -> 1293 | H13: 75 | I13: =(IF('Daily HLP'!O15>0,'Daily HLP'!O15,0)) -> 339 | J13: 99 | K13: =Occupancy!G13 -> 154 | L13: =Occupancy!F13 -> 683 | M13: =E13*F13+G13*H13+#REF!*#REF!+I13*J13 -> #REF!
A14: Mumbai | B14: =B13+1 -> 13 | C14: 2 | D14: 2022 | E14: =(IF('Daily HLP'!H16>0,'Daily HLP'!H16,0)) -> 22200 | F14: 9 | G14: =(IF('Daily HLP'!L16>0,'Daily HLP'!L16,0)) -> 1108 | H14: 75 | I14: =(IF('Daily HLP'!O16>0,'Daily HLP'!O16,0)) -> 296 | J14: 99 | K14: =Occupancy!G14 -> 142 | L14: =Occupancy!F14 -> 1001 | M14: =E14*F14+G14*H14+#REF!*#REF!+I14*J14 -> #REF!
... A31: Mumbai | B31: =B30+1 -> 30 | C31: 2 | D31: 2022 | E31: =(IF('Daily HLP'!H33>0,'Daily HLP'!H33,0)) -> 17529 | F31: 9 | G31: =(IF('Daily HLP'!L33>0,'Daily HLP'!L33,0)) -> 929 | H31: 75 | I31: =(IF('Daily HLP'!O33>0,'Daily HLP'!O33,0)) -> 226 | J31: 99 | K31: =Occupancy!G31 -> 0 | L31: =Occupancy!F31 -> 0 | M31: =E31*F31+G31*H31+#REF!*#REF!+I31*J31 -> #REF!
A32: Mumbai | B32: =B31+1 -> 31 | C32: 2 | D32: 2022 | E32: =(IF('Daily HLP'!H34>0,'Daily HLP'!H34,0)) -> 17830.15 | F32: 9 | G32: =(IF('Daily HLP'!L34>0,'Daily HLP'!L34,0)) -> 915.767 | H32: 75 | I32: =(IF('Daily HLP'!O34>0,'Daily HLP'!O34,0)) -> 146 | J32: 99 | K32: =Occupancy!G32 -> 0 | L32: =Occupancy!F32 -> 0

Sheet Submetering
A1: Site Name | B1: Day | C1: Month | D1: Year | E1: ='Section Load'!F4 -> HVAC | F1: ='Section Load'!G4 -> Fire & Emergency PP | G1: ='Section Load'!H4 -> Main PP | H1: ='Section Load'!I4 -> Lighting PP | I1: ='Section Load'!J4 -> CH-1+ CH2+CH3+CH4 | J1: ='Section Load'!K4 -> Chilled water Pump | K1: ='Section Load'!L4 -> Ball Room-1 | L1: ='Section Load'!M4 -> Ball Room-2 | ... AL1: ='Section Load'!AM4 -> Cooling Tower | AM1: R.o.plant | AN1: STP Water Prod | AO1: Domestic Zone-1 | AP1: Domestic Zone-2 | AQ1: Domestic Zone-3 | AR1: Flush Zone -1 | AS1: Flush Zone -2 | AT1: Flush Zone -3 | AU1: Swimming pool | AV1: B2 Laundry | AW1: Boiler Feed Water | AX1: cooling tower filling water | AY1: STP flush(new water meter) | AZ1: Garden Water Pump | BA1: Flush Zone 2 pump meter | BB1: Flush Zone 3 Pump Meter (wtp transfer ) | BC1: Flush Tanker-Zone-1 | BD1: Total Domestic Water (Tanker (R.O) +BMC) | BE1: Total Domestic Consumption | BF1: Total STP Consumption | BG1: ='Section Load'!AN4 -> MGL | BH1: ='Section Load'!AO4 -> HWG | BI1: ='Section Load'!AP4 -> Prato | BJ1: ='Section Load'!AQ4 -> BR-1 | BK1: ='Section Load'!AR4 -> SanQi IND | BL1: ='Section Load'!AS4 -> SanQi JPN | BM1: ='Section Load'!AT4 -> Boiler
A2: Mumbai | B2: 1 | C2: 2 | D2: 2022 | E2: =(IF('Section Load'!F5>0,'Section Load'!F5,0)) -> 2185.1 | F2: =(IF('Section Load'!G5>0,'Section Load'!G5,0)) -> 1554.11 | G2: =(IF('Section Load'!H5>0,'Section Load'!H5,0)) -> 1620.27 | H2: =(IF('Section Load'!I5>0,'Section Load'!I5,0)) -> 2609.59 | I2: =(IF('Section Load'!J5>0,'Section Load'!J5,0)) -> 3987.79 | J2: =(IF('Section Load'!K5>0,'Section Load'!K5,0)) -> 1901.93 | K2: =(IF('Section Load'!L5>0,'Section Load'!L5,0)) -> 938.92 | L2: =(IF('Section Load'!M5>0,'Section Load'!M5,0)) -> 710.76 | ... AL2: =(IF('Section Load'!AM5>0,'Section Load'!AM5,0)) -> 492.57 | AM2: =(IF('Water Report'!$D$7>0,'Water Report'!$D$7,0)) -> 63 | AN2: =(IF('Water Report'!$D$8>0,'Water Report'!$D$8,0)) -> 132 | AO2: =(IF('Water Report'!$D$9>0,'Water Report'!$D$9,0)) -> 71 | AP2: =(IF('Water Report'!$D$10>0,'Water Report'!$D$10,0)) -> 17 | AQ2: =(IF('Water Report'!$D$11>0,'Water Report'!$D$11,0)) -> 14 | AR2: =(IF('Water Report'!$D$13>0,'Water Report'!$D$13,0)) -> 39 | AS2: =(IF('Water Report'!$D$14>0,'Water Report'!$D$14,0)) -> 9 | AT2: =(IF('Water Report'!$D$15>0,'Water Report'!$D$15,0)) -> 8 | AU2: =(IF('Water Report'!$D$17>0,'Water Report'!$D$17,0)) -> 0 | AV2: =(IF('Water Report'!$D$18>0,'Water Report'!$D$18,0)) -> 11 | AW2: =(IF('Water Report'!$D$19>0,'Water Report'!$D$19,0)) -> 10 | AX2: =(IF('Water Report'!$D$21>0,'Water Report'!$D$21,0)) -> 43 | AY2: =(IF('Water Report'!$D$22>0,'Water Report'!$D$22,0)) -> 29 | AZ2: =(IF('Water Report'!$D$23>0,'Water Report'!$D$23,0)) -> 3 | BA2: =(IF('Water Report'!$D$14>0,'Water Report'!$D$14,0)) -> 9 | BB2: =(IF('Water Report'!$D$15>0,'Water Report'!$D$15,0)) -> 8 | BC2: =(IF('Water Report'!$D$13>0,'Water Report'!$D$13,0)) -> 39 | BD2: =(IF('Water Report'!$D$24>0,'Water Report'!$D$24,0)) -> 235 | BE2: =(IF('Water Report'!$D$25>0,'Water Report'!$D$25,0)) -> 119 | BF2: =(IF('Water Report'!$D$27>0,'Water Report'!$D$27,0)) -> 85 | BG2: =(IF('Section Load'!AN5>0,'Section Load'!AN5,0)) -> 918.558 | BH2: =(IF('Section Load'!AO5>0,'Section Load'!AO5,0)) -> 314.531 | BI2: =(IF('Section Load'!AP5>0,'Section Load'!AP5,0)) -> 0 | BJ2: =(IF('Section Load'!AQ5>0,'Section Load'!AQ5,0)) -> 91.06 | BK2: =(IF('Section Load'!AR5>0,'Section Load'!AR5,0)) -> 29.7 | BL2: =(IF('Section Load'!AS5>0,'Section Load'!AS5,0)) -> 0 | BM2: =(IF('Section Load'!AT5>0,'Section Load'!AT5,0)) -> 483.267
A3: Mumbai | B3: =B2+1 -> 2 | C3: 2 | D3: 2022 | E3: =(IF('Section Load'!F6>0,'Section Load'!F6,0)) -> 2435.04 | F3: =(IF('Section Load'!G6>0,'Section Load'!G6,0)) -> 1547.1 | G3: =(IF('Section Load'!H6>0,'Section Load'!H6,0)) -> 1758.79 | H3: =(IF('Section Load'!I6>0,'Section Load'!I6,0)) -> 2628.22 | I3: =(IF('Section Load'!J6>0,'Section Load'!J6,0)) -> 3469.61 | J3: =(IF('Section Load'!K6>0,'Section Load'!K6,0)) -> 1997.16 | K3: =(IF('Section Load'!L6>0,'Section Load'!L6,0)) -> 987.53 | L3: =(IF('Section Load'!M6>0,'Section Load'!M6,0)) -> 811.5 | ... AL3: =(IF('Section Load'!AM6>0,'Section Load'!AM6,0)) -> 568.04 | AM3: =(IF('Water Report'!$E$7>0,'Water Report'!$E$7,0)) -> 105 | AN3: =(IF('Water Report'!$E$8>0,'Water Report'!$E$8,0)) -> 159 | AO3: =(IF('Water Report'!$E$9>0,'Water Report'!$E$9,0)) -> 71 | AP3: =(IF('Water Report'!$E$10>0,'Water Report'!$E$10,0)) -> 20 | AQ3: =(IF('Water Report'!$E$11>0,'Water Report'!$E$11,0)) -> 20 | AR3: =(IF('Water Report'!$E$13>0,'Water Report'!$E$13,0)) -> 30 | AS3: =(IF('Water Report'!$E$14>0,'Water Report'!$E$14,0)) -> 19 | AT3: =(IF('Water Report'!$E$15>0,'Water Report'!$E$15,0)) -> 10 | AU3: =(IF('Water Report'!$E$17>0,'Water Report'!$E$17,0)) -> 0 | AV3: =(IF('Water Report'!$E$18>0,'Water Report'!$E$18,0)) -> 11 | AW3: =(IF('Water Report'!$E$19>0,'Water Report'!$E$19,0)) -> 9 | AX3: =(IF('Water Report'!$E$21>0,'Water Report'!$E$21,0)) -> 90 | AY3: =(IF('Water Report'!$E$22>0,'Water Report'!$E$22,0)) -> 37 | AZ3: =(IF('Water Report'!$E$23>0,'Water Report'!$E$23,0)) -> 5 | BA3: =(IF('Water Report'!$E$14>0,'Water Report'!$E$14,0)) -> 19 | BB3: =(IF('Water Report'!$E$15>0,'Water Report'!$E$15,0)) -> 10 | BC3: =(IF('Water Report'!$E$13>0,'Water Report'!$E$13,0)) -> 30 | BD3: =(IF('Water Report'!$E$24>0,'Water Report'!$E$24,0)) -> 183 | BE3: =(IF('Water Report'!$E$25>0,'Water Report'!$E$25,0)) -> 140 | BF3: =(IF('Water Report'!$E$27>0,'Water Report'!$E$27,0)) -> 125 | BG3: =(IF('Section Load'!AN6>0,'Section Load'!AN6,0)) -> 983.145 | BH3: =(IF('Section Load'!AO6>0,'Section Load'!AO6,0)) -> 311.036 | BI3: =(IF('Section Load'!AP6>0,'Section Load'!AP6,0)) -> 0 | BJ3: =(IF('Section Load'!AQ6>0,'Section Load'!AQ6,0)) -> 115.71 | BK3: =(IF('Section Load'!AR6>0,'Section Load'!AR6,0)) -> 49.2 | BL3: =(IF('Section Load'!AS6>0,'Section Load'!AS6,0)) -> 1.7 | BM3: =(IF('Section Load'!AT6>0,'Section Load'!AT6,0)) -> 505.499
A4: Mumbai | B4: =B3+1 -> 3 | C4: 2 | D4: 2022 | E4: =(IF('Section Load'!F7>0,'Section Load'!F7,0)) -> 2503.17 | F4: =(IF('Section Load'!G7>0,'Section Load'!G7,0)) -> 1552.11 | G4: =(IF('Section Load'!H7>0,'Section Load'!H7,0)) -> 1668.15 | H4: =(IF('Section Load'!I7>0,'Section Load'!I7,0)) -> 2641.83 | I4: =(IF('Section Load'!J7>0,'Section Load'!J7,0)) -> 3484.57 | J4: =(IF('Section Load'!K7>0,'Section Load'!K7,0)) -> 2229.67 | K4: =(IF('Section Load'!L7>0,'Section Load'!L7,0)) -> 1070.06 | L4: =(IF('Section Load'!M7>0,'Section Load'!M7,0)) -> 935.7 | ... AL4: =(IF('Section Load'!AM7>0,'Section Load'!AM7,0)) -> 565.15 | AM4: =(IF('Water Report'!$F$7>0,'Water Report'!$F$7,0)) -> 74 | AN4: =(IF('Water Report'!$F$8>0,'Water Report'!$F$8,0)) -> 132 | AO4: =(IF('Water Report'!$F$9>0,'Water Report'!$G$9,0)) -> 87 | AP4: =(IF('Water Report'!$F$10>0,'Water Report'!$F$10,0)) -> 22 | AQ4: =(IF('Water Report'!$F$11>0,'Water Report'!$F$11,0)) -> 20 | AR4: =(IF('Water Report'!$F$13>0,'Water Report'!$F$13,0)) -> 28 | AS4: =(IF('Water Report'!$F$14>0,'Water Report'!$F$14,0)) -> 9 | AT4: =(IF('Water Report'!$F$15>0,'Water Report'!$F$15,0)) -> 9 | AU4: =(IF('Water Report'!$F$17>0,'Water Report'!$F$17,0)) -> 0 | AV4: =(IF('Water Report'!$F$18>0,'Water Report'!$F$18,0)) -> 12 | AW4: =(IF('Water Report'!$F$19>0,'Water Report'!$F$19,0)) -> 9 | AX4: =(IF('Water Report'!$F$21>0,'Water Report'!$F$21,0)) -> 9 | AY4: =(IF('Water Report'!$F$22>0,'Water Report'!$F$22,0)) -> 34 | AZ4: =(IF('Water Report'!$F$23>0,'Water Report'!$F$23,0)) -> 11 | BA4: =(IF('Water Report'!$F$14>0,'Water Report'!$F$14,0)) -> 9 | BB4: =(IF('Water Report'!$F$15>0,'Water Report'!$F$15,0)) -> 9 | BC4: =(IF('Water Report'!$F$13>0,'Water Report'!$F$13,0)) -> 28 | BD4: =(IF('Water Report'!$F$24>0,'Water Report'!$F$24,0)) -> 233 | BE4: =(IF('Water Report'!$F$25>0,'Water Report'!$F$25,0)) -> 154 | BF4: =(IF('Water Report'!$F$27>0,'Water Report'!$F$27,0)) -> 48 | BG4: =(IF('Section Load'!AN7>0,'Section Load'!AN7,0)) -> 1012.348 | BH4: =(IF('Section Load'!AO7>0,'Section Load'!AO7,0)) -> 310.544 | BI4: =(IF('Section Load'!AP7>0,'Section Load'!AP7,0)) -> 0 | BJ4: =(IF('Section Load'!AQ7>0,'Section Load'!AQ7,0)) -> 122.32 | BK4: =(IF('Section Load'!AR7>0,'Section Load'!AR7,0)) -> 46.4 | BL4: =(IF('Section Load'!AS7>0,'Section Load'!AS7,0)) -> 1.6 | BM4: =(IF('Section Load'!AT7>0,'Section Load'!AT7,0)) -> 531.484
A5: Mumbai | B5: =B4+1 -> 4 | C5: 2 | D5: 2022 | E5: =(IF('Section Load'!F8>0,'Section Load'!F8,0)) -> 2682.87 | F5: =(IF('Section Load'!G8>0,'Section Load'!G8,0)) -> 1614.1 | G5: =(IF('Section Load'!H8>0,'Section Load'!H8,0)) -> 1858.47 | H5: =(IF('Section Load'!I8>0,'Section Load'!I8,0)) -> 2666.71 | I5: =(IF('Section Load'!J8>0,'Section Load'!J8,0)) -> 2816.83 | J5: =(IF('Section Load'!K8>0,'Section Load'!K8,0)) -> 2395.18 | K5: =(IF('Section Load'!L8>0,'Section Load'!L8,0)) -> 1149.75 | L5: =(IF('Section Load'!M8>0,'Section Load'!M8,0)) -> 861.87 | ... AL5: =(IF('Section Load'!AM8>0,'Section Load'!AM8,0)) -> 690.83 | AM5: =(IF('Water Report'!$G$7>0,'Water Report'!$F$7,0)) -> 74 | AN5: =(IF('Water Report'!$G$8>0,'Water Report'!$F$8,0)) -> 132 | AO5: =(IF('Water Report'!$G$9>0,'Water Report'!$H$9,0)) -> 100 | AP5: =(IF('Water Report'!$G$10>0,'Water Report'!$G$10,0)) -> 30 | AQ5: =(IF('Water Report'!$G$11>0,'Water Report'!$G$11,0)) -> 25 | AR5: =(IF('Water Report'!$G$13>0,'Water Report'!$G$13,0)) -> 28 | AS5: =(IF('Water Report'!$G$14>0,'Water Report'!$G$14,0)) -> 7 | AT5: =(IF('Water Report'!$G$15>0,'Water Report'!$G$15,0)) -> 9 | AU5: =(IF('Water Report'!$G$17>0,'Water Report'!$G$17,0)) -> 0 | AV5: =(IF('Water Report'!$G$18>0,'Water Report'!$G$18,0)) -> 12 | AW5: =(IF('Water Report'!$G$19>0,'Water Report'!$G$19,0)) -> 10 | AX5: =(IF('Water Report'!$G$21>0,'Water Report'!$G$21,0)) -> 87 | AY5: =(IF('Water Report'!$G$22>0,'Water Report'!$G$22,0)) -> 23 | AZ5: =(IF('Water Report'!$G$23>0,'Water Report'!$G$23,0)) -> 10 | BA5: =(IF('Water Report'!$G$14>0,'Water Report'!$G$14,0)) -> 7 | BB5: =(IF('Water Report'!$G$15>0,'Water Report'!$G$15,0)) -> 9 | BC5: =(IF('Water Report'!$G$13>0,'Water Report'!$G$13,0)) -> 28 | BD5: =(IF('Water Report'!$G$24>0,'Water Report'!$G$24,0)) -> 261 | BE5: =(IF('Water Report'!$G$25>0,'Water Report'!$G$25,0)) -> 158 | BF5: =(IF('Water Report'!$G$27>0,'Water Report'!$G$27,0)) -> 125 | BG5: =(IF('Section Load'!AN8>0,'Section Load'!AN8,0)) -> 997.952 | BH5: =(IF('Section Load'!AO8>0,'Section Load'!AO8,0)) -> 297.04 | BI5: =(IF('Section Load'!AP8>0,'Section Load'!AP8,0)) -> 0 | BJ5: =(IF('Section Load'!AQ8>0,'Section Load'!AQ8,0)) -> 150.01 | BK5: =(IF('Section Load'!AR8>0,'Section Load'!AR8,0)) -> 47.9 | BL5: =(IF('Section Load'!AS8>0,'Section Load'!AS8,0)) -> 2.3 | BM5: =(IF('Section Load'!AT8>0,'Section Load'!AT8,0)) -> 500.702
A6: Mumbai | B6: =B5+1 -> 5 | C6: 2 | D6: 2022 | E6: =(IF('Section Load'!F9>0,'Section Load'!F9,0)) -> 2889 | F6: =(IF('Section Load'!G9>0,'Section Load'!G9,0)) -> 1683.92 | G6: =(IF('Section Load'!H9>0,'Section Load'!H9,0)) -> 1939.44 | H6: =(IF('Section Load'!I9>0,'Section Load'!I9,0)) -> 2758.02 | I6: =(IF('Section Load'!J9>0,'Section Load'!J9,0)) -> 3196.39 | J6: =(IF('Section Load'!K9>0,'Section Load'!K9,0)) -> 2237.76 | K6: =(IF('Section Load'!L9>0,'Section Load'!L9,0)) -> 1526.75 | L6: =(IF('Section Load'!M9>0,'Section Load'!M9,0)) -> 1353.26 | ... AL6: =(IF('Section Load'!AM9>0,'Section Load'!AM9,0)) -> 692.97 | AM6: =(IF('Water Report'!$H$7>0,'Water Report'!$H$7,0)) -> 136 | AN6: =(IF('Water Report'!$H$8>0,'Water Report'!$H$8,0)) -> 128 | AO6: =(IF('Water Report'!$H$9>0,'Water Report'!$H$9,0)) -> 100 | AP6: =(IF('Water Report'!$H$10>0,'Water Report'!$H$10,0)) -> 48 | AQ6: =(IF('Water Report'!$H$11>0,'Water Report'!$H$11,0)) -> 26 | AR6: =(IF('Water Report'!$H$13>0,'Water Report'!$H$13,0)) -> 33 | AS6: =(IF('Water Report'!$H$14>0,'Water Report'!$H$14,0)) -> 8 | AT6: =(IF('Water Report'!$H$15>0,'Water Report'!$H$15,0)) -> 9 | AU6: =(IF('Water Report'!$H$17>0,'Water Report'!$H$17,0)) -> 0 | AV6: =(IF('Water Report'!$H$18>0,'Water Report'!$H$18,0)) -> 15 | AW6: =(IF('Water Report'!$H$19>0,'Water Report'!$H$19,0)) -> 11 | AX6: =(IF('Water Report'!$H$21>0,'Water Report'!$H$21,0)) -> 64 | AY6: =(IF('Water Report'!$H$22>0,'Water Report'!$H$22,0)) -> 32 | AZ6: =(IF('Water Report'!$H$23>0,'Water Report'!$H$23,0)) -> 17 | BA6: =(IF('Water Report'!$H$14>0,'Water Report'!$H$14,0)) -> 8 | BB6: =(IF('Water Report'!$H$15>0,'Water Report'!$H$15,0)) -> 9 | BC6: =(IF('Water Report'!$H$13>0,'Water Report'!$H$13,0)) -> 33 | BD6: =(IF('Water Report'!$H$24>0,'Water Report'!$H$24,0)) -> 294 | BE6: =(IF('Water Report'!$H$25>0,'Water Report'!$H$25,0)) -> 191 | BF6: =(IF('Water Report'!$H$27>0,'Water Report'!$H$27,0)) -> 114 | BG6: =(IF('Section Load'!AN9>0,'Section Load'!AN9,0)) -> 1047.87 | BH6: =(IF('Section Load'!AO9>0,'Section Load'!AO9,0)) -> 284.74 | BI6: =(IF('Section Load'!AP9>0,'Section Load'!AP9,0)) -> 0 | BJ6: =(IF('Section Load'!AQ9>0,'Section Load'!AQ9,0)) -> 134 | BK6: =(IF('Section Load'!AR9>0,'Section Load'!AR9,0)) -> 59.8 | BL6: =(IF('Section Load'!AS9>0,'Section Load'!AS9,0)) -> 2.2 | BM6: =(IF('Section Load'!AT9>0,'Section Load'!AT9,0)) -> 567.13
A7: Mumbai | B7: =B6+1 -> 6 | C7: 2 | D7: 2022 | E7: =(IF('Section Load'!F10>0,'Section Load'!F10,0)) -> 3019.29 | F7: =(IF('Section Load'!G10>0,'Section Load'!G10,0)) -> 1645.66 | G7: =(IF('Section Load'!H10>0,'Section Load'!H10,0)) -> 1915.03 | H7: =(IF('Section Load'!I10>0,'Section Load'!I10,0)) -> 2776.56 | I7: =(IF('Section Load'!J10>0,'Section Load'!J10,0)) -> 3426.92 | J7: =(IF('Section Load'!K10>0,'Section Load'!K10,0)) -> 2145.35 | K7: =(IF('Section Load'!L10>0,'Section Load'!L10,0)) -> 1272.6 | L7: =(IF('Section Load'!M10>0,'Section Load'!M10,0)) -> 902.16 | ... AL7: =(IF('Section Load'!AM10>0,'Section Load'!AM10,0)) -> 622.39 | AM7: =(IF('Water Report'!$I$7>0,'Water Report'!$I$7,0)) -> 143 | AN7: =(IF('Water Report'!$I$8>0,'Water Report'!$I$8,0)) -> 132 | AO7: =(IF('Water Report'!$I$9>0,'Water Report'!$I$9,0)) -> 110 | AP7: =(IF('Water Report'!$I$10>0,'Water Report'!$I$10,0)) -> 26 | AQ7: =(IF('Water Report'!$I$11>0,'Water Report'!$I$11,0)) -> 31 | AR7: =(IF('Water Report'!$I$13>0,'Water Report'!$I$13,0)) -> 56 | AS7: =(IF('Water Report'!$I$14>0,'Water Report'!$I$14,0)) -> 11 | AT7: =(IF('Water Report'!$I$15>0,'Water Report'!$I$15,0)) -> 9 | AU7: =(IF('Water Report'!$I$17>0,'Water Report'!$I$17,0)) -> 0 | AV7: =(IF('Water Report'!$I$18>0,'Water Report'!$I$18,0)) -> 16 | AW7: =(IF('Water Report'!$I$19>0,'Water Report'!$I$19,0)) -> 11 | AX7: =(IF('Water Report'!$I$21>0,'Water Report'!$I$21,0)) -> 41 | AY7: =(IF('Water Report'!$I$22>0,'Water Report'!$I$22,0)) -> 70 | AZ7: =(IF('Water Report'!$I$23>0,'Water Report'!$I$23,0)) -> 0 | BA7: =(IF('Water Report'!$I$14>0,'Water Report'!$I$14,0)) -> 11 | BB7: =(IF('Water Report'!$I$15>0,'Water Report'!$I$15,0)) -> 9 | BC7: =(IF('Water Report'!$I$13>0,'Water Report'!$I$13,0)) -> 56 | BD7: =(IF('Water Report'!$I$24>0,'Water Report'!$I$24,0)) -> 275 | BE7: =(IF('Water Report'!$I$25>0,'Water Report'!$I$25,0)) -> 187 | BF7: =(IF('Water Report'!$I$27>0,'Water Report'!$I$27,0)) -> 97 | BG7: =(IF('Section Load'!AN10>0,'Section Load'!AN10,0)) -> 1049.5 | BH7: =(IF('Section Load'!AO10>0,'Section Load'!AO10,0)) -> 303.78 | BI7: =(IF('Section Load'!AP10>0,'Section Load'!AP10,0)) -> 0 | BJ7: =(IF('Section Load'!AQ10>0,'Section Load'!AQ10,0)) -> 109.81 | BK7: =(IF('Section Load'!AR10>0,'Section Load'!AR10,0)) -> 45.5 | BL7: =(IF('Section Load'!AS10>0,'Section Load'!AS10,0)) -> 1.3 | BM7: =(IF('Section Load'!AT10>0,'Section Load'!AT10,0)) -> 589.11
A8: Mumbai | B8: =B7+1 -> 7 | C8: 2 | D8: 2022 | E8: =(IF('Section Load'!F11>0,'Section Load'!F11,0)) -> 3100.34 | F8: =(IF('Section Load'!G11>0,'Section Load'!G11,0)) -> 1658.84 | G8: =(IF('Section Load'!H11>0,'Section Load'!H11,0)) -> 2017.74 | H8: =(IF('Section Load'!I11>0,'Section Load'!I11,0)) -> 3066.49 | I8: =(IF('Section Load'!J11>0,'Section Load'!J11,0)) -> 4458.75 | J8: =(IF('Section Load'!K11>0,'Section Load'!K11,0)) -> 2208.68 | K8: =(IF('Section Load'!L11>0,'Section Load'!L11,0)) -> 1415.62 | L8: =(IF('Section Load'!M11>0,'Section Load'!M11,0)) -> 840.57 | ... AL8: =(IF('Section Load'!AM11>0,'Section Load'!AM11,0)) -> 677.03 | AM8: =(IF('Water Report'!$J$7>0,'Water Report'!$J$7,0)) -> 142 | AN8: =(IF('Water Report'!$J$8>0,'Water Report'!$J$8,0)) -> 124 | AO8: =(IF('Water Report'!$J$9>0,'Water Report'!$J$9,0)) -> 96 | AP8: =(IF('Water Report'!$J$10>0,'Water Report'!$J$10,0)) -> 21 | AQ8: =(IF('Water Report'!$J$11>0,'Water Report'!$J$11,0)) -> 30 | AR8: =(IF('Water Report'!$J$13>0,'Water Report'!$J$13,0)) -> 43 | AS8: =(IF('Water Report'!$J$14>0,'Water Report'!$J$14,0)) -> 15 | AT8: =(IF('Water Report'!$J$15>0,'Water Report'!$J$15,0)) -> 23 | AU8: =(IF('Water Report'!$J$17>0,'Water Report'!$J$17,0)) -> 0 | AV8: =(IF('Water Report'!$J$18>0,'Water Report'!$J$18,0)) -> 14 | AW8: =(IF('Water Report'!$J$19>0,'Water Report'!$J$19,0)) -> 10 | AX8: =(IF('Water Report'!$J$21>0,'Water Report'!$J$21,0)) -> 68 | AY8: =(IF('Water Report'!$J$22>0,'Water Report'!$J$22,0)) -> 45 | AZ8: =(IF('Water Report'!$J$23>0,'Water Report'!$J$23,0)) -> 0 | BA8: =(IF('Water Report'!$J$14>0,'Water Report'!$J$14,0)) -> 15 | BB8: =(IF('Water Report'!$J$15>0,'Water Report'!$J$15,0)) -> 23 | BC8: =(IF('Water Report'!$J$13>0,'Water Report'!$J$13,0)) -> 43 | BD8: =(IF('Water Report'!$J$24>0,'Water Report'!$J$24,0)) -> 242 | BE8: =(IF('Water Report'!$J$25>0,'Water Report'!$J$25,0)) -> 185 | BF8: =(IF('Water Report'!$J$27>0,'Water Report'!$J$27,0)) -> 111 | BG8: =(IF('Section Load'!AN11>0,'Section Load'!AN11,0)) -> 1030.68 | BH8: =(IF('Section Load'!AO11>0,'Section Load'!AO11,0)) -> 301.66 | BI8: =(IF('Section Load'!AP11>0,'Section Load'!AP11,0)) -> 0 | BJ8: =(IF('Section Load'!AQ11>0,'Section Load'!AQ11,0)) -> 98.49 | BK8: =(IF('Section Load'!AR11>0,'Section Load'!AR11,0)) -> 55.9 | BL8: =(IF('Section Load'!AS11>0,'Section Load'!AS11,0)) -> 0.9 | BM8: =(IF('Section Load'!AT11>0,'Section Load'!AT11,0)) -> 573.73
A9: Mumbai | B9: =B8+1 -> 8 | C9: 2 | D9: 2022 | E9: =(IF('Section Load'!F12>0,'Section Load'!F12,0)) -> 3021.02 | F9: =(IF('Section Load'!G12>0,'Section Load'!G12,0)) -> 1609.07 | G9: =(IF('Section Load'!H12>0,'Section Load'!H12,0)) -> 1914.68 | H9: =(IF('Section Load'!I12>0,'Section Load'!I12,0)) -> 2923.29 | I9: =(IF('Section Load'!J12>0,'Section Load'!J12,0)) -> 4082.49 | J9: =(IF('Section Load'!K12>0,'Section Load'!K12,0)) -> 2123.67 | K9: =(IF('Section Load'!L12>0,'Section Load'!L12,0)) -> 1131.14 | L9: =(IF('Section Load'!M12>0,'Section Load'!M12,0)) -> 799.44 | ... AL9: =(IF('Section Load'!AM12>0,'Section Load'!AM12,0)) -> 647.32 | AM9: =(IF('Water Report'!$K$7>0,'Water Report'!$K$7,0)) -> 128 | AN9: =(IF('Water Report'!$K$8>0,'Water Report'!$K$8,0)) -> 103 | AO9: =(IF('Water Report'!$K$9>0,'Water Report'!$K$9,0)) -> 106 | AP9: =(IF('Water Report'!$K$10>0,'Water Report'!$K$10,0)) -> 19 | AQ9: =(IF('Water Report'!$K$11>0,'Water Report'!$K$11,0)) -> 16 | AR9: =(IF('Water Report'!$K$13>0,'Water Report'!$K$13,0)) -> 30 | AS9: =(IF('Water Report'!$K$14>0,'Water Report'!$K$14,0)) -> 10 | AT9: =(IF('Water Report'!$K$15>0,'Water Report'!$K$15,0)) -> 33 | AU9: =(IF('Water Report'!$K$17>0,'Water Report'!$K$17,0)) -> 0 | AV9: =(IF('Water Report'!$K$18>0,'Water Report'!$K$18,0)) -> 17 | AW9: =(IF('Water Report'!$K$19>0,'Water Report'!$K$19,0)) -> 12 | AX9: =(IF('Water Report'!$K$21>0,'Water Report'!$K$21,0)) -> 46 | AY9: =(IF('Water Report'!$K$22>0,'Water Report'!$K$22,0)) -> 25 | AZ9: =(IF('Water Report'!$K$23>0,'Water Report'!$K$23,0)) -> 17 | BA9: =(IF('Water Report'!$K$14>0,'Water Report'!$K$14,0)) -> 10 | BB9: =(IF('Water Report'!$K$15>0,'Water Report'!$K$15,0)) -> 33 | BC9: =(IF('Water Report'!$K$13>0,'Water Report'!$K$13,0)) -> 30 | BD9: =(IF('Water Report'!$K$24>0,'Water Report'!$K$24,0)) -> 232 | BE9: =(IF('Water Report'!$K$25>0,'Water Report'!$K$25,0)) -> 184 | BF9: =(IF('Water Report'!$K$27>0,'Water Report'!$K$27,0)) -> 93 | BG9: =(IF('Section Load'!AN12>0,'Section Load'!AN12,0)) -> 1052.18 | BH9: =(IF('Section Load'!AO12>0,'Section Load'!AO12,0)) -> 302.52 | BI9: =(IF('Section Load'!AP12>0,'Section Load'!AP12,0)) -> 0 | BJ9: =(IF('Section Load'!AQ12>0,'Section Load'!AQ12,0)) -> 110.6 | BK9: =(IF('Section Load'!AR12>0,'Section Load'!AR12,0)) -> 50.4 | BL9: =(IF('Section Load'!AS12>0,'Section Load'!AS12,0)) -> 1 | BM9: =(IF('Section Load'!AT12>0,'Section Load'!AT12,0)) -> 587.66
A10: Mumbai | B10: =B9+1 -> 9 | C10: 2 | D10: 2022 | E10: =(IF('Section Load'!F13>0,'Section Load'!F13,0)) -> 2906 | F10: =(IF('Section Load'!G13>0,'Section Load'!G13,0)) -> 1638 | G10: =(IF('Section Load'!H13>0,'Section Load'!H13,0)) -> 1923 | H10: =(IF('Section Load'!I13>0,'Section Load'!I13,0)) -> 3001 | I10: =(IF('Section Load'!J13>0,'Section Load'!J13,0)) -> 3894.53 | J10: =(IF('Section Load'!K13>0,'Section Load'!K13,0)) -> 2087 | K10: =(IF('Section Load'!L13>0,'Section Load'!L13,0)) -> 1118 | L10: =(IF('Section Load'!M13>0,'Section Load'!M13,0)) -> 779 | ... AL10: =(IF('Section Load'!AM13>0,'Section Load'!AM13,0)) -> 658 | AM10: =(IF('Water Report'!$L$7>0,'Water Report'!$L$7,0)) -> 142 | AN10: =(IF('Water Report'!$L$8>0,'Water Report'!$L$8,0)) -> 90 | AO10: =(IF('Water Report'!$L$9>0,'Water Report'!$L$9,0)) -> 103 | AP10: =(IF('Water Report'!$L$10>0,'Water Report'!$L$10,0)) -> 20 | AQ10: =(IF('Water Report'!$L$11>0,'Water Report'!$L$11,0)) -> 55 | AR10: =(IF('Water Report'!$L$13>0,'Water Report'!$L$13,0)) -> 37 | AS10: =(IF('Water Report'!$L$14>0,'Water Report'!$L$14,0)) -> 9 | AT10: =(IF('Water Report'!$L$15>0,'Water Report'!$L$15,0)) -> 14 | AU10: =(IF('Water Report'!$L$17>0,'Water Report'!$L$17,0)) -> 5 | AV10: =(IF('Water Report'!$L$18>0,'Water Report'!$L$18,0)) -> 12 | AW10: =(IF('Water Report'!$L$19>0,'Water Report'!$L$19,0)) -> 12 | AX10: =(IF('Water Report'!$L$21>0,'Water Report'!$L$21,0)) -> 38 | AY10: =(IF('Water Report'!$L$22>0,'Water Report'!$L$22,0)) -> 35 | AZ10: =(IF('Water Report'!$L$23>0,'Water Report'!$L$23,0)) -> 5 | BA10: =(IF('Water Report'!$L$14>0,'Water Report'!$L$14,0)) -> 9 | BB10: =(IF('Water Report'!$L$15>0,'Water Report'!$L$15,0)) -> 14 | BC10: =(IF('Water Report'!$L$13>0,'Water Report'!$L$13,0)) -> 37 | BD10: =(IF('Water Report'!$L$24>0,'Water Report'!$L$24,0)) -> 256 | BE10: =(IF('Water Report'!$L$25>0,'Water Report'!$L$25,0)) -> 201 | BF10: =(IF('Water Report'!$L$27>0,'Water Report'!$L$27,0)) -> 80 | BG10: =(IF('Section Load'!AN13>0,'Section Load'!AN13,0)) -> 1070 | BH10: =(IF('Section Load'!AO13>0,'Section Load'!AO13,0)) -> 301 | BI10: =(IF('Section Load'!AP13>0,'Section Load'!AP13,0)) -> 0.2 | BJ10: =(IF('Section Load'!AQ13>0,'Section Load'!AQ13,0)) -> 107 | BK10: =(IF('Section Load'!AR13>0,'Section Load'!AR13,0)) -> 43 | BL10: =(IF('Section Load'!AS13>0,'Section Load'!AS13,0)) -> 1 | BM10: =(IF('Section Load'!AT13>0,'Section Load'!AT13,0)) -> 617.8
A11: Mumbai | B11: =B10+1 -> 10 | C11: 2 | D11: 2022 | E11: =(IF('Section Load'!F14>0,'Section Load'!F14,0)) -> 2839 | F11: =(IF('Section Load'!G14>0,'Section Load'!G14,0)) -> 1647 | G11: =(IF('Section Load'!H14>0,'Section Load'!H14,0)) -> 1955 | H11: =(IF('Section Load'!I14>0,'Section Load'!I14,0)) -> 3035 | I11: =(IF('Section Load'!J14>0,'Section Load'!J14,0)) -> 4557 | J11: =(IF('Section Load'!K14>0,'Section Load'!K14,0)) -> 2097 | K11: =(IF('Section Load'!L14>0,'Section Load'!L14,0)) -> 1144 | L11: =(IF('Section Load'!M14>0,'Section Load'!M14,0)) -> 1084 | ... AL11: =(IF('Section Load'!AM14>0,'Section Load'!AM14,0)) -> 522 | AM11: =(IF('Water Report'!$M$7>0,'Water Report'!$M$7,0)) -> 170 | AN11: =(IF('Water Report'!$M$8>0,'Water Report'!$M$8,0)) -> 129 | AO11: =(IF('Water Report'!$M$9>0,'Water Report'!$M$9,0)) -> 105 | AP11: =(IF('Water Report'!$M$10>0,'Water Report'!$M$10,0)) -> 20 | AQ11: =(IF('Water Report'!$M$11>0,'Water Report'!$M$11,0)) -> 65 | AR11: =(IF('Water Report'!$M$13>0,'Water Report'!$M$13,0)) -> 40 | AS11: =(IF('Water Report'!$M$14>0,'Water Report'!$M$14,0)) -> 18 | AT11: =(IF('Water Report'!$M$15>0,'Water Report'!$M$15,0)) -> 8 | AU11: =(IF('Water Report'!$M$17>0,'Water Report'!$M$17,0)) -> 1 | AV11: =(IF('Water Report'!$M$18>0,'Water Report'!$M$18,0)) -> 14 | AW11: =(IF('Water Report'!$M$19>0,'Water Report'!$M$19,0)) -> 12 | AX11: =(IF('Water Report'!$M$21>0,'Water Report'!$M$21,0)) -> 47 | AY11: =(IF('Water Report'!$M$22>0,'Water Report'!$M$22,0)) -> 0 | AZ11: =(IF('Water Report'!$M$23>0,'Water Report'!$M$23,0)) -> 0 | BA11: =(IF('Water Report'!$M$14>0,'Water Report'!$M$14,0)) -> 18 | BB11: =(IF('Water Report'!$M$15>0,'Water Report'!$M$15,0)) -> 8 | BC11: =(IF('Water Report'!$M$13>0,'Water Report'!$M$13,0)) -> 40 | BD11: =(IF('Water Report'!$M$24>0,'Water Report'!$M$24,0)) -> 317 | BE11: =(IF('Water Report'!$M$25>0,'Water Report'!$M$25,0)) -> 216 | BF11: =(IF('Water Report'!$M$27>0,'Water Report'!$M$27,0)) -> 87 | BG11: =(IF('Section Load'!AN14>0,'Section Load'!AN14,0)) -> 1152 | BH11: =(IF('Section Load'!AO14>0,'Section Load'!AO14,0)) -> 341 | BI11: =(IF('Section Load'!AP14>0,'Section Load'!AP14,0)) -> 0 | BJ11: =(IF('Section Load'!AQ14>0,'Section Load'!AQ14,0)) -> 114 | BK11: =(IF('Section Load'!AR14>0,'Section Load'!AR14,0)) -> 43 | BL11: =(IF('Section Load'!AS14>0,'Section Load'!AS14,0)) -> 3 | BM11: =(IF('Section Load'!AT14>0,'Section Load'!AT14,0)) -> 651
A12: Mumbai | B12: =B11+1 -> 11 | C12: 2 | D12: 2022 | E12: =(IF('Section Load'!F15>0,'Section Load'!F15,0)) -> 2776 | F12: =(IF('Section Load'!G15>0,'Section Load'!G15,0)) -> 1684 | G12: =(IF('Section Load'!H15>0,'Section Load'!H15,0)) -> 2076 | H12: =(IF('Section Load'!I15>0,'Section Load'!I15,0)) -> 3148 | I12: =(IF('Section Load'!J15>0,'Section Load'!J15,0)) -> 4736 | J12: =(IF('Section Load'!K15>0,'Section Load'!K15,0)) -> 2112 | K12: =(IF('Section Load'!L15>0,'Section Load'!L15,0)) -> 1282 | L12: =(IF('Section Load'!M15>0,'Section Load'!M15,0)) -> 1077 | ... AL12: =(IF('Section Load'!AM15>0,'Section Load'!AM15,0)) -> 494 | AM12: =(IF('Water Report'!$N$7>0,'Water Report'!$N$7,0)) -> 181 | AN12: =(IF('Water Report'!$N$8>0,'Water Report'!$N$8,0)) -> 136 | AO12: =(IF('Water Report'!$N$9>0,'Water Report'!$N$9,0)) -> 104 | AP12: =(IF('Water Report'!$N$10>0,'Water Report'!$N$10,0)) -> 31 | AQ12: =(IF('Water Report'!$N$11>0,'Water Report'!$N$11,0)) -> 65 | AR12: =(IF('Water Report'!$N$13>0,'Water Report'!$N$13,0)) -> 53 | AS12: =(IF('Water Report'!$N$14>0,'Water Report'!$N$14,0)) -> 32 | AT12: =(IF('Water Report'!$N$15>0,'Water Report'!$N$15,0)) -> 12 | AU12: =(IF('Water Report'!$N$17>0,'Water Report'!$N$17,0)) -> 0 | AV12: =(IF('Water Report'!$N$18>0,'Water Report'!$N$18,0)) -> 12 | AW12: =(IF('Water Report'!$N$19>0,'Water Report'!$N$19,0)) -> 12 | AX12: =(IF('Water Report'!$N$21>0,'Water Report'!$N$21,0)) -> 30 | AY12: =(IF('Water Report'!$N$22>0,'Water Report'!$N$22,0)) -> 24 | AZ12: =(IF('Water Report'!$N$23>0,'Water Report'!$N$23,0)) -> 2 | BA12: =(IF('Water Report'!$N$14>0,'Water Report'!$N$14,0)) -> 32 | BB12: =(IF('Water Report'!$N$15>0,'Water Report'!$N$15,0)) -> 12 | BC12: =(IF('Water Report'!$N$13>0,'Water Report'!$N$13,0)) -> 53 | BD12: =(IF('Water Report'!$N$24>0,'Water Report'!$N$24,0)) -> 316 | BE12: =(IF('Water Report'!$N$25>0,'Water Report'!$N$25,0)) -> 244 | BF12: =(IF('Water Report'!$N$27>0,'Water Report'!$N$27,0)) -> 85 | BG12: =(IF('Section Load'!AN15>0,'Section Load'!AN15,0)) -> 1118 | BH12: =(IF('Section Load'!AO15>0,'Section Load'!AO15,0)) -> 316 | BI12: =(IF('Section Load'!AP15>0,'Section Load'!AP15,0)) -> 0 | BJ12: =(IF('Section Load'!AQ15>0,'Section Load'!AQ15,0)) -> 124 | BK12: =(IF('Section Load'!AR15>0,'Section Load'!AR15,0)) -> 53 | BL12: =(IF('Section Load'!AS15>0,'Section Load'!AS15,0)) -> 3 | BM12: =(IF('Section Load'!AT15>0,'Section Load'!AT15,0)) -> 622
A13: Mumbai | B13: =B12+1 -> 12 | C13: 2 | D13: 2022 | E13: =(IF('Section Load'!F16>0,'Section Load'!F16,0)) -> 3199 | F13: =(IF('Section Load'!G16>0,'Section Load'!G16,0)) -> 1783 | G13: =(IF('Section Load'!H16>0,'Section Load'!H16,0)) -> 2162 | H13: =(IF('Section Load'!I16>0,'Section Load'!I16,0)) -> 3245 | I13: =(IF('Section Load'!J16>0,'Section Load'!J16,0)) -> 4928 | J13: =(IF('Section Load'!K16>0,'Section Load'!K16,0)) -> 2226 | K13: =(IF('Section Load'!L16>0,'Section Load'!L16,0)) -> 1310 | L13: =(IF('Section Load'!M16>0,'Section Load'!M16,0)) -> 1194 | ... AL13: =(IF('Section Load'!AM16>0,'Section Load'!AM16,0)) -> 698 | AM13: =(IF('Water Report'!$O$7>0,'Water Report'!$O$7,0)) -> 177 | AN13: =(IF('Water Report'!$O$8>0,'Water Report'!$O$8,0)) -> 182 | AO13: =(IF('Water Report'!$O$9>0,'Water Report'!$O$9,0)) -> 126 | AP13: =(IF('Water Report'!$O$10>0,'Water Report'!$O$10,0)) -> 28 | AQ13: =(IF('Water Report'!$O$11>0,'Water Report'!$O$11,0)) -> 66 | AR13: =(IF('Water Report'!$O$13>0,'Water Report'!$O$13,0)) -> 52 | AS13: =(IF('Water Report'!$O$14>0,'Water Report'!$O$14,0)) -> 14 | AT13: =(IF('Water Report'!$O$15>0,'Water Report'!$O$15,0)) -> 5 | AU13: =(IF('Water Report'!$O$17>0,'Water Report'!$O$17,0)) -> 0 | AV13: =(IF('Water Report'!$O$18>0,'Water Report'!$O$18,0)) -> 17 | AW13: =(IF('Water Report'!$O$19>0,'Water Report'!$O$19,0)) -> 14 | AX13: =(IF('Water Report'!$O$21>0,'Water Report'!$O$21,0)) -> 95 | AY13: =(IF('Water Report'!$O$22>0,'Water Report'!$O$22,0)) -> 20 | AZ13: =(IF('Water Report'!$O$23>0,'Water Report'!$O$23,0)) -> 10 | BA13: =(IF('Water Report'!$O$14>0,'Water Report'!$O$14,0)) -> 14 | BB13: =(IF('Water Report'!$O$15>0,'Water Report'!$O$15,0)) -> 5 | BC13: =(IF('Water Report'!$O$13>0,'Water Report'!$O$13,0)) -> 52 | BD13: =(IF('Water Report'!$O$24>0,'Water Report'!$O$24,0)) -> 339 | BE13: =(IF('Water Report'!$O$25>0,'Water Report'!$O$25,0)) -> 239 | BF13: =(IF('Water Report'!$O$27>0,'Water Report'!$O$27,0)) -> 157 | BG13: =(IF('Section Load'!AN16>0,'Section Load'!AN16,0)) -> 1293 | BH13: =(IF('Section Load'!AO16>0,'Section Load'!AO16,0)) -> 324 | BI13: =(IF('Section Load'!AP16>0,'Section Load'!AP16,0)) -> 0 | BJ13: =(IF('Section Load'!AQ16>0,'Section Load'!AQ16,0)) -> 152 | BK13: =(IF('Section Load'!AR16>0,'Section Load'!AR16,0)) -> 58 | BL13: =(IF('Section Load'!AS16>0,'Section Load'!AS16,0)) -> 4 | BM13: =(IF('Section Load'!AT16>0,'Section Load'!AT16,0)) -> 755
A14: Mumbai | B14: =B13+1 -> 13 | C14: 2 | D14: 2022 | E14: =(IF('Section Load'!F17>0,'Section Load'!F17,0)) -> 2981 | F14: =(IF('Section Load'!G17>0,'Section Load'!G17,0)) -> 1781 | G14: =(IF('Section Load'!H17>0,'Section Load'!H17,0)) -> 2029 | H14: =(IF('Section Load'!I17>0,'Section Load'!I17,0)) -> 3279 | I14: =(IF('Section Load'!J17>0,'Section Load'!J17,0)) -> 5019 | J14: =(IF('Section Load'!K17>0,'Section Load'!K17,0)) -> 2145 | K14: =(IF('Section Load'!L17>0,'Section Load'!L17,0)) -> 1558 | L14: =(IF('Section Load'!M17>0,'Section Load'!M17,0)) -> 1069 | ... AL14: =(IF('Section Load'!AM17>0,'Section Load'!AM17,0)) -> 676 | AM14: =(IF('Water Report'!$P$7>0,'Water Report'!$P$7,0)) -> 177 | AN14: =(IF('Water Report'!$P$8>0,'Water Report'!$P$8,0)) -> 140 | AO14: =(IF('Water Report'!$P$9>0,'Water Report'!$P$9,0)) -> 112 | AP14: =(IF('Water Report'!$P$10>0,'Water Report'!$P$10,0)) -> 27 | AQ14: =(IF('Water Report'!$P$11>0,'Water Report'!$P$11,0)) -> 71 | AR14: =(IF('Water Report'!$P$13>0,'Water Report'!$P$13,0)) -> 32 | AS14: =(IF('Water Report'!$P$14>0,'Water Report'!$P$14,0)) -> 11 | AT14: =(IF('Water Report'!$P$15>0,'Water Report'!$P$15,0)) -> 8 | AU14: =(IF('Water Report'!$P$17>0,'Water Report'!$P$17,0)) -> 0 | AV14: =(IF('Water Report'!$P$18>0,'Water Report'!$P$18,0)) -> 12 | AW14: =(IF('Water Report'!$P$19>0,'Water Report'!$P$19,0)) -> 13 | AX14: =(IF('Water Report'!$P$21>0,'Water Report'!$P$21,0)) -> 42 | AY14: =(IF('Water Report'!$P$22>0,'Water Report'!$P$22,0)) -> 31 | AZ14: =(IF('Water Report'!$P$23>0,'Water Report'!$P$23,0)) -> 0 | BA14: =(IF('Water Report'!$P$14>0,'Water Report'!$P$14,0)) -> 11 | BB14: =(IF('Water Report'!$P$15>0,'Water Report'!$P$15,0)) -> 8 | BC14: =(IF('Water Report'!$P$13>0,'Water Report'!$P$13,0)) -> 32 | BD14: =(IF('Water Report'!$P$24>0,'Water Report'!$P$24,0)) -> 296 | BE14: =(IF('Water Report'!$P$25>0,'Water Report'!$P$25,0)) -> 229 | BF14: =(IF('Water Report'!$P$27>0,'Water Report'!$P$27,0)) -> 74 | BG14: =(IF('Section Load'!AN17>0,'Section Load'!AN17,0)) -> 1108 | BH14: =(IF('Section Load'!AO17>0,'Section Load'!AO17,0)) -> 287 | BI14: =(IF('Section Load'!AP17>0,'Section Load'!AP17,0)) -> 0 | BJ14: =(IF('Section Load'!AQ17>0,'Section Load'!AQ17,0)) -> 119 | BK14: =(IF('Section Load'!AR17>0,'Section Load'!AR17,0)) -> 52 | BL14: =(IF('Section Load'!AS17>0,'Section Load'!AS17,0)) -> 3 | BM14: =(IF('Section Load'!AT17>0,'Section Load'!AT17,0)) -> 647
A15: Mumbai | B15: =B14+1 -> 14 | C15: 2 | D15: 2022 | E15: =(IF('Section Load'!F18>0,'Section Load'!F18,0)) -> 0 | F15: =(IF('Section Load'!G18>0,'Section Load'!G18,0)) -> 0 | G15: =(IF('Section Load'!H18>0,'Section Load'!H18,0)) -> 0 | H15: =(IF('Section Load'!I18>0,'Section Load'!I18,0)) -> 0 | I15: =(IF('Section Load'!J18>0,'Section Load'!J18,0)) -> 0 | J15: =(IF('Section Load'!K18>0,'Section Load'!K18,0)) -> 2011 | K15: =(IF('Section Load'!L18>0,'Section Load'!L18,0)) -> 0 | L15: =(IF('Section Load'!M18>0,'Section Load'!M18,0)) -> 0 | ... AL15: =(IF('Section Load'!AM18>0,'Section Load'!AM18,0)) -> 0 | AM15: =(IF('Water Report'!$Q$7>0,'Water Report'!$Q$7,0)) -> 0 | AN15: =(IF('Water Report'!$Q$8>0,'Water Report'!$Q$8,0)) -> 49 | AO15: =(IF('Water Report'!$Q$9>0,'Water Report'!$Q$9,0)) -> 0 | AP15: =(IF('Water Report'!$Q$10>0,'Water Report'!$Q$10,0)) -> 0 | AQ15: =(IF('Water Report'!$Q$11>0,'Water Report'!$Q$11,0)) -> 0 | AR15: =(IF('Water Report'!$Q$13>0,'Water Report'!$Q$13,0)) -> 0 | AS15: =(IF('Water Report'!$Q$14>0,'Water Report'!$Q$14,0)) -> 0 | AT15: =(IF('Water Report'!$Q$15>0,'Water Report'!$Q$15,0)) -> 0 | AU15: =(IF('Water Report'!$Q$17>0,'Water Report'!$Q$17,0)) -> 0 | AV15: =(IF('Water Report'!$Q$18>0,'Water Report'!$Q$18,0)) -> 5 | AW15: =(IF('Water Report'!$Q$19>0,'Water Report'!$Q$19,0)) -> 0 | AX15: =(IF('Water Report'!$Q$21>0,'Water Report'!$Q$21,0)) -> 0 | AY15: =(IF('Water Report'!$Q$22>0,'Water Report'!$Q$22,0)) -> 0 | AZ15: =(IF('Water Report'!$Q$23>0,'Water Report'!$Q$23,0)) -> 0 | BA15: =(IF('Water Report'!$Q$14>0,'Water Report'!$Q$14,0)) -> 0 | BB15: =(IF('Water Report'!$Q$15>0,'Water Report'!$Q$15,0)) -> 0 | BC15: =(IF('Water Report'!$Q$13>0,'Water Report'!$Q$13,0)) -> 0 | BD15: =(IF('Water Report'!$Q$24>0,'Water Report'!$Q$24,0)) -> 0 | BE15: =(IF('Water Report'!$Q$25>0,'Water Report'!$Q$25,0)) -> 0 | BF15: =(IF('Water Report'!$Q$27>0,'Water Report'!$Q$27,0)) -> 0 | BG15: =(IF('Section Load'!AN18>0,'Section Load'!AN18,0)) -> 745 | BH15: =(IF('Section Load'!AO18>0,'Section Load'!AO18,0)) -> 0 | BI15: =(IF('Section Load'!AP18>0,'Section Load'!AP18,0)) -> 0 | BJ15: =(IF('Section Load'!AQ18>0,'Section Load'!AQ18,0)) -> 0 | BK15: =(IF('Section Load'!AR18>0,'Section Load'!AR18,0)) -> 0 | BL15: =(IF('Section Load'!AS18>0,'Section Load'!AS18,0)) -> 0 | BM15: =(IF('Section Load'!AT18>0,'Section Load'!AT18,0)) -> 14256
A16: Mumbai | B16: =B15+1 -> 15 | C16: 2 | D16: 2022 | E16: =(IF('Section Load'!F19>0,'Section Load'!F19,0)) -> 2552.43 | F16: =(IF('Section Load'!G19>0,'Section Load'!G19,0)) -> 1497.74 | G16: =(IF('Section Load'!H19>0,'Section Load'!H19,0)) -> 1386.95 | H16: =(IF('Section Load'!I19>0,'Section Load'!I19,0)) -> 2494.9 | I16: =(IF('Section Load'!J19>0,'Section Load'!J19,0)) -> 3008.37 | J16: =(IF('Section Load'!K19>0,'Section Load'!K19,0)) -> 2012.71 | K16: =(IF('Section Load'!L19>0,'Section Load'!L19,0)) -> 902.73 | L16: =(IF('Section Load'!M19>0,'Section Load'!M19,0)) -> 573.69 | ... AL16: =(IF('Section Load'!AM19>0,'Section Load'!AM19,0)) -> 398.27 | AM16: =(IF('Water Report'!$R$7>0,'Water Report'!$R$7,0)) -> 79 | AN16: =(IF('Water Report'!$R$8>0,'Water Report'!$R$8,0)) -> 95 | AO16: =(IF('Water Report'!$R$9>0,'Water Report'!$R$9,0)) -> 70 | AP16: =(IF('Water Report'!$R$10>0,'Water Report'!$R$10,0)) -> 17 | AQ16: =(IF('Water Report'!$R$11>0,'Water Report'!$R$11,0)) -> 23 | AR16: =(IF('Water Report'!$R$13>0,'Water Report'!$R$13,0)) -> 23 | AS16: =(IF('Water Report'!$R$14>0,'Water Report'!$R$14,0)) -> 11 | AT16: =(IF('Water Report'!$R$15>0,'Water Report'!$R$15,0)) -> 7 | AU16: =(IF('Water Report'!$R$17>0,'Water Report'!$R$17,0)) -> 0 | AV16: =(IF('Water Report'!$R$18>0,'Water Report'!$R$18,0)) -> 10 | AW16: =(IF('Water Report'!$R$19>0,'Water Report'!$R$19,0)) -> 13 | AX16: =(IF('Water Report'!$R$21>0,'Water Report'!$R$21,0)) -> 72 | AY16: =(IF('Water Report'!$R$22>0,'Water Report'!$R$22,0)) -> 20 | AZ16: =(IF('Water Report'!$R$23>0,'Water Report'!$R$23,0)) -> 11 | BA16: =(IF('Water Report'!$R$14>0,'Water Report'!$R$14,0)) -> 11 | BB16: =(IF('Water Report'!$R$15>0,'Water Report'!$R$15,0)) -> 7 | BC16: =(IF('Water Report'!$R$13>0,'Water Report'!$R$13,0)) -> 23 | BD16: =(IF('Water Report'!$R$24>0,'Water Report'!$R$24,0)) -> 155 | BE16: =(IF('Water Report'!$R$25>0,'Water Report'!$R$25,0)) -> 128 | BF16: =(IF('Water Report'!$R$27>0,'Water Report'!$R$27,0)) -> 106 | BG16: =(IF('Section Load'!AN19>0,'Section Load'!AN19,0)) -> 965 | BH16: =(IF('Section Load'!AO19>0,'Section Load'!AO19,0)) -> 313 | BI16: =(IF('Section Load'!AP19>0,'Section Load'!AP19,0)) -> 0 | BJ16: =(IF('Section Load'!AQ19>0,'Section Load'!AQ19,0)) -> 75 | BK16: =(IF('Section Load'!AR19>0,'Section Load'!AR19,0)) -> 26.4 | BL16: =(IF('Section Load'!AS19>0,'Section Load'!AS19,0)) -> 1 | BM16: =(IF('Section Load'!AT19>0,'Section Load'!AT19,0)) -> 549.6
A17: Mumbai | B17: =B16+1 -> 16 | C17: 2 | D17: 2022 | E17: =(IF('Section Load'!F20>0,'Section Load'!F20,0)) -> 2589.57 | F17: =(IF('Section Load'!G20>0,'Section Load'!G20,0)) -> 1483.26 | G17: =(IF('Section Load'!H20>0,'Section Load'!H20,0)) -> 1625.05 | H17: =(IF('Section Load'!I20>0,'Section Load'!I20,0)) -> 2600.1 | I17: =(IF('Section Load'!J20>0,'Section Load'!J20,0)) -> 3032.77 | J17: =(IF('Section Load'!K20>0,'Section Load'!K20,0)) -> 2071.29 | K17: =(IF('Section Load'!L20>0,'Section Load'!L20,0)) -> 868.27 | L17: =(IF('Section Load'!M20>0,'Section Load'!M20,0)) -> 587.31 | ... AL17: =(IF('Section Load'!AM20>0,'Section Load'!AM20,0)) -> 468.73 | AM17: =(IF('Water Report'!$S$7>0,'Water Report'!$S$7,0)) -> 66 | AN17: =(IF('Water Report'!$S$8>0,'Water Report'!$S$8,0)) -> 91 | AO17: =(IF('Water Report'!$S$9>0,'Water Report'!$S$9,0)) -> 62 | AP17: =(IF('Water Report'!$S$10>0,'Water Report'!$D$10,0)) -> 17 | AQ17: =(IF('Water Report'!$S$11>0,'Water Report'!$D$11,0)) -> 14 | AR17: =(IF('Water Report'!$S$13>0,'Water Report'!$D$13,0)) -> 39 | AS17: =(IF('Water Report'!$S$14>0,'Water Report'!$D$14,0)) -> 9 | AT17: =(IF('Water Report'!$S$15>0,'Water Report'!$D$15,0)) -> 8 | AU17: =(IF('Water Report'!$S$17>0,'Water Report'!$D$17,0)) -> 0 | AV17: =(IF('Water Report'!$S$18>0,'Water Report'!$D$18,0)) -> 11 | AW17: =(IF('Water Report'!$S$19>0,'Water Report'!$D$19,0)) -> 10 | AX17: =(IF('Water Report'!$S$21>0,'Water Report'!$D$21,0)) -> 43 | AY17: =(IF('Water Report'!$S$22>0,'Water Report'!$D$22,0)) -> 29 | AZ17: =(IF('Water Report'!$S$23>0,'Water Report'!$D$23,0)) -> 3 | BA17: =(IF('Water Report'!$S$14>0,'Water Report'!$D$14,0)) -> 9 | BB17: =(IF('Water Report'!$S$15>0,'Water Report'!$D$15,0)) -> 8 | BC17: =(IF('Water Report'!$S$13>0,'Water Report'!$D$13,0)) -> 39 | BD17: =(IF('Water Report'!$S$24>0,'Water Report'!$D$24,0)) -> 235 | BE17: =(IF('Water Report'!$S$25>0,'Water Report'!$D$25,0)) -> 119 | BF17: =(IF('Water Report'!$S$27>0,'Water Report'!$D$27,0)) -> 85 | BG17: =(IF('Section Load'!AN20>0,'Section Load'!AN20,0)) -> 1006 | BH17: =(IF('Section Load'!AO20>0,'Section Load'!AO20,0)) -> 304 | BI17: =(IF('Section Load'!AP20>0,'Section Load'!AP20,0)) -> 0 | BJ17: =(IF('Section Load'!AQ20>0,'Section Load'!AQ20,0)) -> 90 | BK17: =(IF('Section Load'!AR20>0,'Section Load'!AR20,0)) -> 26.6 | BL17: =(IF('Section Load'!AS20>0,'Section Load'!AS20,0)) -> 1 | BM17: =(IF('Section Load'!AT20>0,'Section Load'!AT20,0)) -> 584.4
A18: Mumbai | B18: =B17+1 -> 17 | C18: 2 | D18: 2022 | E18: =(IF('Section Load'!F21>0,'Section Load'!F21,0)) -> 2686.21 | F18: =(IF('Section Load'!G21>0,'Section Load'!G21,0)) -> 1510.42 | G18: =(IF('Section Load'!H21>0,'Section Load'!H21,0)) -> 1604.16 | H18: =(IF('Section Load'!I21>0,'Section Load'!I21,0)) -> 2698 | I18: =(IF('Section Load'!J21>0,'Section Load'!J21,0)) -> 3005.17 | J18: =(IF('Section Load'!K21>0,'Section Load'!K21,0)) -> 2219.15 | K18: =(IF('Section Load'!L21>0,'Section Load'!L21,0)) -> 838.53 | L18: =(IF('Section Load'!M21>0,'Section Load'!M21,0)) -> 592.46 | ... AL18: =(IF('Section Load'!AM21>0,'Section Load'!AM21,0)) -> 488.6 | AM18: =(IF('Water Report'!$T$7>0,'Water Report'!$T$7,0)) -> 66 | AN18: =(IF('Water Report'!$T$8>0,'Water Report'!$T$8,0)) -> 84 | AO18: =(IF('Water Report'!$T$9>0,'Water Report'!$T$9,0)) -> 65 | AP18: =(IF('Water Report'!$T$10>0,'Water Report'!$T$10,0)) -> 15 | AQ18: =(IF('Water Report'!$T$11>0,'Water Report'!$T$11,0)) -> 19 | AR18: =(IF('Water Report'!$T$13>0,'Water Report'!$T$13,0)) -> 21 | AS18: =(IF('Water Report'!$T$14>0,'Water Report'!$T$14,0)) -> 8 | AT18: =(IF('Water Report'!$T$15>0,'Water Report'!$T$15,0)) -> 7 | AU18: =(IF('Water Report'!$T$17>0,'Water Report'!$T$17,0)) -> 0 | AV18: =(IF('Water Report'!$T$18>0,'Water Report'!$T$18,0)) -> 0 | AW18: =(IF('Water Report'!$T$19>0,'Water Report'!$T$19,0)) -> 7 | AX18: =(IF('Water Report'!$T$21>0,'Water Report'!$T$21,0)) -> 60 | AY18: =(IF('Water Report'!$T$22>0,'Water Report'!$T$22,0)) -> 27 | AZ18: =(IF('Water Report'!$T$23>0,'Water Report'!$T$23,0)) -> 1 | BA18: =(IF('Water Report'!$T$14>0,'Water Report'!$T$14,0)) -> 8 | BB18: =(IF('Water Report'!$T$15>0,'Water Report'!$T$15,0)) -> 7 | BC18: =(IF('Water Report'!$T$13>0,'Water Report'!$T$13,0)) -> 21 | BD18: =(IF('Water Report'!$T$24>0,'Water Report'!$T$24,0)) -> 133 | BE18: =(IF('Water Report'!$T$25>0,'Water Report'!$T$25,0)) -> 114 | BF18: =(IF('Water Report'!$T$27>0,'Water Report'!$T$27,0)) -> 82 | BG18: =(IF('Section Load'!AN21>0,'Section Load'!AN21,0)) -> 734.273 | BH18: =(IF('Section Load'!AO21>0,'Section Load'!AO21,0)) -> 307.9 | BI18: =(IF('Section Load'!AP21>0,'Section Load'!AP21,0)) -> 0 | BJ18: =(IF('Section Load'!AQ21>0,'Section Load'!AQ21,0)) -> 73.5 | BK18: =(IF('Section Load'!AR21>0,'Section Load'!AR21,0)) -> 23.3 | BL18: =(IF('Section Load'!AS21>0,'Section Load'!AS21,0)) -> 0 | BM18: =(IF('Section Load'!AT21>0,'Section Load'!AT21,0)) -> 329.773
A19: Mumbai | B19: =B18+1 -> 18 | C19: 2 | D19: 2022 | E19: =(IF('Section Load'!F22>0,'Section Load'!F22,0)) -> 2634.48 | F19: =(IF('Section Load'!G22>0,'Section Load'!G22,0)) -> 1562.55 | G19: =(IF('Section Load'!H22>0,'Section Load'!H22,0)) -> 1696.3 | H19: =(IF('Section Load'!I22>0,'Section Load'!I22,0)) -> 2546.49 | I19: =(IF('Section Load'!J22>0,'Section Load'!J22,0)) -> 3090.52 | J19: =(IF('Section Load'!K22>0,'Section Load'!K22,0)) -> 2338 | K19: =(IF('Section Load'!L22>0,'Section Load'!L22,0)) -> 921.4 | L19: =(IF('Section Load'!M22>0,'Section Load'!M22,0)) -> 600.9 | ... AL19: =(IF('Section Load'!AM22>0,'Section Load'!AM22,0)) -> 500.8 | AM19: =(IF('Water Report'!$U$7>0,'Water Report'!$U$7,0)) -> 69 | AN19: =(IF('Water Report'!$U$8>0,'Water Report'!$U$8,0)) -> 124 | AO19: =(IF('Water Report'!$U$9>0,'Water Report'!$U$9,0)) -> 64 | AP19: =(IF('Water Report'!$U$10>0,'Water Report'!$U$10,0)) -> 11 | AQ19: =(IF('Water Report'!$U$11>0,'Water Report'!$U$11,0)) -> 22 | AR19: =(IF('Water Report'!$U$13>0,'Water Report'!$U$13,0)) -> 55 | AS19: =(IF('Water Report'!$U$14>0,'Water Report'!$U$14,0)) -> 12 | AT19: =(IF('Water Report'!$U$15>0,'Water Report'!$U$15,0)) -> 4 | AU19: =(IF('Water Report'!$U$17>0,'Water Report'!$U$17,0)) -> 0 | AV19: =(IF('Water Report'!$U$18>0,'Water Report'!$U$18,0)) -> 13 | AW19: =(IF('Water Report'!$U$19>0,'Water Report'!$U$19,0)) -> 10 | AX19: =(IF('Water Report'!$U$21>0,'Water Report'!$U$21,0)) -> 64 | AY19: =(IF('Water Report'!$U$22>0,'Water Report'!$U$22,0)) -> 54 | AZ19: =(IF('Water Report'!$U$23>0,'Water Report'!$U$23,0)) -> 15 | BA19: =(IF('Water Report'!$U$14>0,'Water Report'!$U$14,0)) -> 12 | BB19: =(IF('Water Report'!$U$15>0,'Water Report'!$U$15,0)) -> 4 | BC19: =(IF('Water Report'!$U$13>0,'Water Report'!$U$13,0)) -> 55 | BD19: =(IF('Water Report'!$U$24>0,'Water Report'!$U$24,0)) -> 154 | BE19: =(IF('Water Report'!$U$25>0,'Water Report'!$U$25,0)) -> 113 | BF19: =(IF('Water Report'!$U$27>0,'Water Report'!$U$27,0)) -> 134 | BG19: =(IF('Section Load'!AN22>0,'Section Load'!AN22,0)) -> 881.727 | BH19: =(IF('Section Load'!AO22>0,'Section Load'!AO22,0)) -> 285.25 | BI19: =(IF('Section Load'!AP22>0,'Section Load'!AP22,0)) -> 0 | BJ19: =(IF('Section Load'!AQ22>0,'Section Load'!AQ22,0)) -> 80.5 | BK19: =(IF('Section Load'!AR22>0,'Section Load'!AR22,0)) -> 22.7 | BL19: =(IF('Section Load'!AS22>0,'Section Load'!AS22,0)) -> 1 | BM19: =(IF('Section Load'!AT22>0,'Section Load'!AT22,0)) -> 492.277
A20: Mumbai | B20: =B19+1 -> 19 | C20: 2 | D20: 2022 | E20: =(IF('Section Load'!F23>0,'Section Load'!F23,0)) -> 2941.65 | F20: =(IF('Section Load'!G23>0,'Section Load'!G23,0)) -> 1596.17 | G20: =(IF('Section Load'!H23>0,'Section Load'!H23,0)) -> 1623.54 | H20: =(IF('Section Load'!I23>0,'Section Load'!I23,0)) -> 2646.07 | I20: =(IF('Section Load'!J23>0,'Section Load'!J23,0)) -> 2846.14 | J20: =(IF('Section Load'!K23>0,'Section Load'!K23,0)) -> 2372.37 | K20: =(IF('Section Load'!L23>0,'Section Load'!L23,0)) -> 975.76 | L20: =(IF('Section Load'!M23>0,'Section Load'!M23,0)) -> 661.6 | ... AL20: =(IF('Section Load'!AM23>0,'Section Load'!AM23,0)) -> 668.03 | AM20: =(IF('Water Report'!$V$7>0,'Water Report'!$V$7,0)) -> 60 | AN20: =(IF('Water Report'!$V$8>0,'Water Report'!$V$8,0)) -> 93 | AO20: =(IF('Water Report'!$V$9>0,'Water Report'!$V$9,0)) -> 63 | AP20: =(IF('Water Report'!$V$10>0,'Water Report'!$V$10,0)) -> 15 | AQ20: =(IF('Water Report'!$V$11>0,'Water Report'!$V$11,0)) -> 23 | AR20: =(IF('Water Report'!$V$13>0,'Water Report'!$V$13,0)) -> 30 | AS20: =(IF('Water Report'!$V$14>0,'Water Report'!$V$14,0)) -> 8 | AT20: =(IF('Water Report'!$V$15>0,'Water Report'!$V$15,0)) -> 6.1 | AU20: =(IF('Water Report'!$V$17>0,'Water Report'!$V$17,0)) -> 0 | AV20: =(IF('Water Report'!$V$18>0,'Water Report'!$V$18,0)) -> 9 | AW20: =(IF('Water Report'!$V$19>0,'Water Report'!$V$19,0)) -> 9 | AX20: =(IF('Water Report'!$V$21>0,'Water Report'!$V$21,0)) -> 35 | AY20: =(IF('Water Report'!$V$22>0,'Water Report'!$V$22,0)) -> 4 | AZ20: =(IF('Water Report'!$V$23>0,'Water Report'!$V$23,0)) -> 0 | BA20: =(IF('Water Report'!$V$14>0,'Water Report'!$V$14,0)) -> 8 | BB20: =(IF('Water Report'!$V$15>0,'Water Report'!$V$15,0)) -> 6.1 | BC20: =(IF('Water Report'!$V$13>0,'Water Report'!$V$13,0)) -> 30 | BD20: =(IF('Water Report'!$V$24>0,'Water Report'!$V$24,0)) -> 157 | BE20: =(IF('Water Report'!$V$25>0,'Water Report'!$V$25,0)) -> 115.1 | BF20: =(IF('Water Report'!$V$27>0,'Water Report'!$V$27,0)) -> 65 | BG20: =(IF('Section Load'!AN23>0,'Section Load'!AN23,0)) -> 834.3 | BH20: =(IF('Section Load'!AO23>0,'Section Load'!AO23,0)) -> 306.35 | BI20: =(IF('Section Load'!AP23>0,'Section Load'!AP23,0)) -> 0 | BJ20: =(IF('Section Load'!AQ23>0,'Section Load'!AQ23,0)) -> 83.9 | BK20: =(IF('Section Load'!AR23>0,'Section Load'!AR23,0)) -> 27.1 | BL20: =(IF('Section Load'!AS23>0,'Section Load'!AS23,0)) -> 1.3 | BM20: =(IF('Section Load'!AT23>0,'Section Load'!AT23,0)) -> 415.65
A21: Mumbai | B21: =B20+1 -> 20 | C21: 2 | D21: 2022 | E21: =(IF('Section Load'!F24>0,'Section Load'!F24,0)) -> 2570.57 | F21: =(IF('Section Load'!G24>0,'Section Load'!G24,0)) -> 1537.78 | G21: =(IF('Section Load'!H24>0,'Section Load'!H24,0)) -> 1612.85 | H21: =(IF('Section Load'!I24>0,'Section Load'!I24,0)) -> 2507.05 | I21: =(IF('Section Load'!J24>0,'Section Load'!J24,0)) -> 2588.64 | J21: =(IF('Section Load'!K24>0,'Section Load'!K24,0)) -> 2313.47 | K21: =(IF('Section Load'!L24>0,'Section Load'!L24,0)) -> 914.66 | L21: =(IF('Section Load'!M24>0,'Section Load'!M24,0)) -> 594.86 | ... AL21: =(IF('Section Load'!AM24>0,'Section Load'!AM24,0)) -> 655.39 | AM21: =(IF('Water Report'!$W$7>0,'Water Report'!$W$7,0)) -> 69 | AN21: =(IF('Water Report'!$W$8>0,'Water Report'!$W$8,0)) -> 105 | AO21: =(IF('Water Report'!$W$9>0,'Water Report'!$W$9,0)) -> 72 | AP21: =(IF('Water Report'!$W$10>0,'Water Report'!$W$10,0)) -> 10 | AQ21: =(IF('Water Report'!$W$11>0,'Water Report'!$W$11,0)) -> 23 | AR21: =(IF('Water Report'!$W$13>0,'Water Report'!$W$13,0)) -> 50 | AS21: =(IF('Water Report'!$W$14>0,'Water Report'!$W$14,0)) -> 14 | AT21: =(IF('Water Report'!$W$15>0,'Water Report'!$W$15,0)) -> 4.9 | AU21: =(IF('Water Report'!$W$17>0,'Water Report'!$W$17,0)) -> 0 | AV21: =(IF('Water Report'!$W$18>0,'Water Report'!$W$18,0)) -> 12 | AW21: =(IF('Water Report'!$W$19>0,'Water Report'!$W$19,0)) -> 12 | AX21: =(IF('Water Report'!$W$21>0,'Water Report'!$W$21,0)) -> 41 | AY21: =(IF('Water Report'!$W$22>0,'Water Report'!$W$22,0)) -> 0 | AZ21: =(IF('Water Report'!$W$23>0,'Water Report'!$W$23,0)) -> 12 | BA21: =(IF('Water Report'!$W$14>0,'Water Report'!$W$14,0)) -> 14 | BB21: =(IF('Water Report'!$W$15>0,'Water Report'!$W$15,0)) -> 4.9 | BC21: =(IF('Water Report'!$W$13>0,'Water Report'!$W$13,0)) -> 50 | BD21: =(IF('Water Report'!$W$24>0,'Water Report'!$W$24,0)) -> 216 | BE21: =(IF('Water Report'!$W$25>0,'Water Report'!$W$25,0)) -> 123.9 | BF21: =(IF('Water Report'!$W$27>0,'Water Report'!$W$27,0)) -> 103 | BG21: =(IF('Section Load'!AN24>0,'Section Load'!AN24,0)) -> 986.95 | BH21: =(IF('Section Load'!AO24>0,'Section Load'!AO24,0)) -> 295.15 | BI21: =(IF('Section Load'!AP24>0,'Section Load'!AP24,0)) -> 0 | BJ21: =(IF('Section Load'!AQ24>0,'Section Load'!AQ24,0)) -> 83.64 | BK21: =(IF('Section Load'!AR24>0,'Section Load'!AR24,0)) -> 25.6 | BL21: =(IF('Section Load'!AS24>0,'Section Load'!AS24,0)) -> 0.6 | BM21: =(IF('Section Load'!AT24>0,'Section Load'!AT24,0)) -> 581.96
A22: Mumbai | B22: =B21+1 -> 21 | C22: 2 | D22: 2022 | E22: =(IF('Section Load'!F25>0,'Section Load'!F25,0)) -> 2555.77 | F22: =(IF('Section Load'!G25>0,'Section Load'!G25,0)) -> 1565.5 | G22: =(IF('Section Load'!H25>0,'Section Load'!H25,0)) -> 1671.45 | H22: =(IF('Section Load'!I25>0,'Section Load'!I25,0)) -> 2598.24 | I22: =(IF('Section Load'!J25>0,'Section Load'!J25,0)) -> 2838.4 | J22: =(IF('Section Load'!K25>0,'Section Load'!K25,0)) -> 2339.94 | K22: =(IF('Section Load'!L25>0,'Section Load'!L25,0)) -> 1160.05 | L22: =(IF('Section Load'!M25>0,'Section Load'!M25,0)) -> 661.91 | ... AL22: =(IF('Section Load'!AM25>0,'Section Load'!AM25,0)) -> 655.84 | AM22: =(IF('Water Report'!$X$7>0,'Water Report'!$X$7,0)) -> 60 | AN22: =(IF('Water Report'!$X$8>0,'Water Report'!$X$8,0)) -> 96 | AO22: =(IF('Water Report'!$X$9>0,'Water Report'!$X$9,0)) -> 72 | AP22: =(IF('Water Report'!$X$10>0,'Water Report'!$X$10,0)) -> 12 | AQ22: =(IF('Water Report'!$X$11>0,'Water Report'!$X$11,0)) -> 20 | AR22: =(IF('Water Report'!$X$13>0,'Water Report'!$X$13,0)) -> 34 | AS22: =(IF('Water Report'!$X$14>0,'Water Report'!$X$14,0)) -> 8 | AT22: =(IF('Water Report'!$X$15>0,'Water Report'!$X$15,0)) -> 4 | AU22: =(IF('Water Report'!$X$17>0,'Water Report'!$X$17,0)) -> 0 | AV22: =(IF('Water Report'!$X$18>0,'Water Report'!$X$18,0)) -> 11 | AW22: =(IF('Water Report'!$X$19>0,'Water Report'!$X$19,0)) -> 10 | AX22: =(IF('Water Report'!$X$21>0,'Water Report'!$X$21,0)) -> 61 | AY22: =(IF('Water Report'!$X$22>0,'Water Report'!$X$22,0)) -> 20 | AZ22: =(IF('Water Report'!$X$23>0,'Water Report'!$X$23,0)) -> 14 | BA22: =(IF('Water Report'!$X$14>0,'Water Report'!$X$14,0)) -> 8 | BB22: =(IF('Water Report'!$X$15>0,'Water Report'!$X$15,0)) -> 4 | BC22: =(IF('Water Report'!$X$13>0,'Water Report'!$X$13,0)) -> 34 | BD22: =(IF('Water Report'!$X$24>0,'Water Report'!$X$24,0)) -> 167 | BE22: =(IF('Water Report'!$X$25>0,'Water Report'!$X$25,0)) -> 116 | BF22: =(IF('Water Report'!$X$27>0,'Water Report'!$X$27,0)) -> 109 | BG22: =(IF('Section Load'!AN25>0,'Section Load'!AN25,0)) -> 1017.34 | BH22: =(IF('Section Load'!AO25>0,'Section Load'!AO25,0)) -> 294.76 | BI22: =(IF('Section Load'!AP25>0,'Section Load'!AP25,0)) -> 0 | BJ22: =(IF('Section Load'!AQ25>0,'Section Load'!AQ25,0)) -> 104.78 | BK22: =(IF('Section Load'!AR25>0,'Section Load'!AR25,0)) -> 50.3 | BL22: =(IF('Section Load'!AS25>0,'Section Load'!AS25,0)) -> 1.1 | BM22: =(IF('Section Load'!AT25>0,'Section Load'!AT25,0)) -> 566.4
