Workbook

Sheet Total
A1: Site Name | B1: Day | C1: Month | D1: Year | E1: Total Electricity Kwh | F1: Electricity Tariff ($/Kwh) | G1: Total Fuel Oil (Liter) | H1: Fuel Oil $/Liter | I1: LPG (Kg) | J1: LPG $/Kg | K1: Water Utility Supply (m3) m3 | L1: Water Utility Supply (m3) $/m3 | M1: Irrigation Water (m3) m3 | N1: Irrigation water $/m3 | O1: Room Nights
A2: Beirut | B2: 1 | C2: 2 | D2: 2022 | E2: =ELEC!N4 -> 7726.8 | F2: =SUM('EDl log'!T4) -> 0.2540072 | G2: =-tanks!AW6 -> 485 | H2: =SUM(tanks!AV6) -> 0.638 | I2: =('B5'!AU5)*0.51 -> 0 | J2: ='B5'!AX5/0.51 -> 1.5686275 | K2: =WATER!I6 -> 0 | L2: =SUM(WATER!J6) -> 0 | M2: =WATER!Q6 -> 0 | N2: 0.6 | O2: =ELEC!B4 -> 0
A3: Beirut | B3: =B2+1 -> 2 | C3: 2 | D3: =D2 -> 2022 | E3: =ELEC!N5 -> 4558 | F3: =SUM('EDl log'!T5) -> 0.36813061 | G3: =-tanks!AW7 -> 503 | H3: =SUM(tanks!AV7) -> 0.638 | I3: =('B5'!AU6)*0.51 -> 0 | J3: ='B5'!AX6/0.51 -> 1.5686275 | K3: =WATER!I7 -> 0 | L3: =SUM(WATER!J7) -> 0 | M3: =WATER!Q7 -> 0 | N3: 0.6 | O3: =ELEC!B5 -> 0
A4: Beirut | B4: =B3+1 -> 3 | C4: 2 | D4: =D3 -> 2022 | E4: =ELEC!N6 -> 5673 | F4: =SUM('EDl log'!T6) -> 0.30769425 | G4: =-tanks!AW8 -> 323 | H4: =SUM(tanks!AV8) -> 0.638 | I4: =('B5'!AU7)*0.51 -> 0 | J4: ='B5'!AX7/0.51 -> 1.5686275 | K4: =WATER!I8 -> 0 | L4: =SUM(WATER!J8) -> 0 | M4: =WATER!Q8 -> 0 | N4: 0.6 | O4: =ELEC!B6 -> 0
A5: Beirut | B5: =B4+1 -> 4 | C5: 2 | D5: =D4 -> 2022 | E5: =ELEC!N7 -> 0 | F5: =SUM('EDl log'!T7) -> 0 | G5: =-tanks!AW9 -> 0 | H5: =SUM(tanks!AV9) -> 0.638 | I5: =('B5'!AU8)*0.51 -> 0 | J5: ='B5'!AX8/0.51 -> 1.5686275 | K5: =WATER!I9 -> 0 | L5: =SUM(WATER!J9) -> 0 | M5: =WATER!Q9 -> 0 | N5: 0.6 | O5: =ELEC!B7 -> 0
A6: Beirut | B6: =B5+1 -> 5 | C6: 2 | D6: =D5 -> 2022 | E6: =ELEC!N8 -> 0 | F6: =SUM('EDl log'!T8) -> 0 | G6: =-tanks!AW10 -> 0 | H6: =SUM(tanks!AV10) -> 0.638 | I6: =('B5'!AU9)*0.51 -> 0 | J6: ='B5'!AX9/0.51 -> 1.5686275 | K6: =WATER!I10 -> 0 | L6: =SUM(WATER!J10) -> 0 | M6: =WATER!Q10 -> 0 | N6: 0.6 | O6: =ELEC!B8 -> 0
A7: Beirut | B7: =B6+1 -> 6 | C7: 2 | D7: =D6 -> 2022 | E7: =ELEC!N9 -> 7240.4 | F7: =SUM('EDl log'!T9) -> 0.13876284 | G7: =-tanks!AW11 -> 396 | H7: =SUM(tanks!AV11) -> 0.76 | I7: =('B5'!AU10)*0.51 -> 0 | J7: ='B5'!AX10/0.51 -> 1.5686275 | K7: =WATER!I11 -> 0 | L7: =SUM(WATER!J11) -> 0 | M7: =WATER!Q11 -> 0 | N7: 0.6 | O7: =ELEC!B9 -> 0
A8: Beirut | B8: =B7+1 -> 7 | C8: 2 | D8: =D7 -> 2022 | E8: =ELEC!N10 -> 5591.6 | F8: =SUM('EDl log'!T10) -> 0.27850438 | G8: =-tanks!AW12 -> 581 | H8: =SUM(tanks!AV12) -> 0.76 | I8: =('B5'!AU11)*0.51 -> 0 | J8: ='B5'!AX11/0.51 -> 1.5686275 | K8: =WATER!I12 -> 0 | L8: =SUM(WATER!J12) -> 0 | M8: =WATER!Q12 -> 0 | N8: 0.6 | O8: =ELEC!B10 -> 0
A9: Beirut | B9: =B8+1 -> 8 | C9: 2 | D9: =D8 -> 2022 | E9: =ELEC!N11 -> 0 | F9: =SUM('EDl log'!T11) -> 0 | G9: =-tanks!AW13 -> 0 | H9: =SUM(tanks!AV13) -> 0.76 | I9: =('B5'!AU12)*0.51 -> 0 | J9: ='B5'!AX12/0.51 -> 1.5686275 | K9: =WATER!I13 -> 0 | L9: =SUM(WATER!J13) -> 0 | M9: =WATER!Q13 -> 0 | N9: 0.6 | O9: =ELEC!B11 -> 0
A10: Beirut | B10: =B9+1 -> 9 | C10: 2 | D10: =D9 -> 2022 | E10: =ELEC!N12 -> 4598 | F10: =SUM('EDl log'!T12) -> 0.30563253 | G10: =-tanks!AW14 -> 295 | H10: =SUM(tanks!AV14) -> 0.76 | I10: =('B5'!AU13)*0.51 -> 0 | J10: ='B5'!AX13/0.51 -> 1.5686275 | K10: =WATER!I14 -> 0 | L10: =SUM(WATER!J14) -> 0 | M10: =WATER!Q14 -> 0 | N10: 0.6 | O10: =ELEC!B12 -> 0
A11: Beirut | B11: =B10+1 -> 10 | C11: 2 | D11: =D10 -> 2022 | E11: =ELEC!N13 -> 5970 | F11: =SUM('EDl log'!T13) -> 0.29418193 | G11: =-tanks!AW15 -> 435 | H11: =SUM(tanks!AV15) -> 0.76 | I11: =('B5'!AU14)*0.51 -> 0 | J11: ='B5'!AX14/0.51 -> 1.5686275 | K11: =WATER!I15 -> 0 | L11: =SUM(WATER!J15) -> 0 | M11: =WATER!Q15 -> 0 | N11: 0.6 | O11: =ELEC!B13 -> 0
A12: Beirut | B12: =B11+1 -> 11 | C12: 2 | D12: =D11 -> 2022 | E12: =ELEC!N14 -> 0 | F12: =SUM('EDl log'!T14) -> 0 | G12: =-tanks!AW16 -> 0 | H12: =SUM(tanks!AV16) -> 0.76 | I12: =('B5'!AU15)*0.51 -> 0 | J12: ='B5'!AX15/0.51 -> 1.5686275 | K12: =WATER!I16 -> 0 | L12: =SUM(WATER!J16) -> 0 | M12: =WATER!Q16 -> 0 | N12: 0.6 | O12: =ELEC!B14 -> 0
A13: Beirut | B13: =B12+1 -> 12 | C13: 2 | D13: =D12 -> 2022 | E13: =ELEC!N15 -> 0 | F13: =SUM('EDl log'!T15) -> 0 | G13: =-tanks!AW17 -> 0 | H13: =SUM(tanks!AV17) -> 0.76 | I13: =('B5'!AU16)*0.51 -> 0 | J13: ='B5'!AX16/0.51 -> 1.5686275 | K13: =WATER!I17 -> 0 | L13: =SUM(WATER!J17) -> 0 | M13: =WATER!Q17 -> 0 | N13: 0.6 | O13: =ELEC!B15 -> 0
A14: Beirut | B14: =B13+1 -> 13 | C14: 2 | D14: =D13 -> 2022 | E14: =ELEC!N16 -> 6925 | F14: =SUM('EDl log'!T16) -> 0.1399264 | G14: =-tanks!AW18 -> 591 | H14: =SUM(tanks!AV18) -> 0.741 | I14: =('B5'!AU17)*0.51 -> 0 | J14: ='B5'!AX17/0.51 -> 1.5686275 | K14: =WATER!I18 -> 0 | L14: =SUM(WATER!J18) -> 0 | M14: =WATER!Q18 -> 0 | N14: 0.6 | O14: =ELEC!B16 -> 0
... A29: Beirut | B29: =B28+1 -> 28 | C29: 2 | D29: =D28 -> 2022 | E29: =ELEC!N31 -> 0 | F29: =SUM('EDl log'!T31) -> 0 | G29: =-tanks!AW33 -> 0 | H29: =SUM(tanks!AV33) -> 0.795 | I29: =('B5'!AU32)*0.51 -> 0 | J29: ='B5'!AX32/0.51 -> 1.5686275 | K29: =WATER!I33 -> 0 | L29: =SUM(WATER!J33) -> 0 | M29: =WATER!Q33 -> 0 | N29: 0.6 | O29: =ELEC!B31 -> 0
A30: Beirut
A31: Beirut
A32: Beirut

Sheet Submetering
A1: Site Name | B1: Day | C1: Month | D1: Year | E1: ATS1 Kwh | F1: ATS2 Kwh | G1: ATS3 Kwh | H1: ATS4 Kwh | I1: ATS5 Kwh | J1: Guest (m3) | K1: Kitchen & Laundry (m3) | L1: Room Nights
A2: Beirut | B2: 1 | C2: 2 | D2: 2022 | E2: =ELEC!M4 -> 1329 | F2: =ELEC!K4 -> 1844 | G2: =ELEC!I4 -> 350 | H2: =ELEC!E4 -> 3930 | I2: =ELEC!G4 -> 273.8 | J2: =WATER!Y6 -> 0 | K2: =WATER!AJ6 -> 0 | L2: =ELEC!B4 -> 0
A3: Beirut | B3: =B2+1 -> 2 | C3: 2 | D3: 2022 | E3: =ELEC!M5 -> 1092 | F3: =ELEC!K5 -> 1612 | G3: =ELEC!I5 -> 332 | H3: =ELEC!E5 -> 1260 | I3: =ELEC!G5 -> 262 | J3: =WATER!Y7 -> 0 | K3: =WATER!AJ7 -> 0 | L3: =ELEC!B5 -> 0
A4: Beirut | B4: =B3+1 -> 3 | C4: 2 | D4: 2022 | E4: =ELEC!M6 -> 1060 | F4: =ELEC!K6 -> 1562 | G4: =ELEC!I6 -> 450 | H4: =ELEC!E6 -> 2350 | I4: =ELEC!G6 -> 251 | J4: =WATER!Y8 -> 0 | K4: =WATER!AJ8 -> 0 | L4: =ELEC!B6 -> 0
A5: Beirut | B5: =B4+1 -> 4 | C5: 2 | D5: 2022 | E5: =ELEC!M7 -> 0 | F5: =ELEC!K7 -> 0 | G5: =ELEC!I7 -> 0 | H5: =ELEC!E7 -> 0 | I5: =ELEC!G7 -> 0 | J5: =WATER!Y9 -> 0 | K5: =WATER!AJ9 -> 0 | L5: =ELEC!B7 -> 0
A6: Beirut | B6: =B5+1 -> 5 | C6: 2 | D6: 2022 | E6: =ELEC!M8 -> 0 | F6: =ELEC!K8 -> 0 | G6: =ELEC!I8 -> 0 | H6: =ELEC!E8 -> 0 | I6: =ELEC!G8 -> 0 | J6: =WATER!Y10 -> 0 | K6: =WATER!AJ10 -> 0 | L6: =ELEC!B8 -> 0
A7: Beirut | B7: =B6+1 -> 6 | C7: 2 | D7: 2022 | E7: =ELEC!M9 -> 1396 | F7: =ELEC!K9 -> 1976 | G7: =ELEC!I9 -> 504 | H7: =ELEC!E9 -> 3040 | I7: =ELEC!G9 -> 324.4 | J7: =WATER!Y11 -> 0 | K7: =WATER!AJ11 -> 0 | L7: =ELEC!B9 -> 0
A8: Beirut | B8: =B7+1 -> 7 | C8: 2 | D8: 2022 | E8: =ELEC!M10 -> 1124 | F8: =ELEC!K10 -> 1556 | G8: =ELEC!I10 -> 396 | H8: =ELEC!E10 -> 2230 | I8: =ELEC!G10 -> 285.6 | J8: =WATER!Y12 -> 0 | K8: =WATER!AJ12 -> 0 | L8: =ELEC!B10 -> 0
A9: Beirut | B9: =B8+1 -> 8 | C9: 2 | D9: 2022 | E9: =ELEC!M11 -> 0 | F9: =ELEC!K11 -> 0 | G9: =ELEC!I11 -> 0 | H9: =ELEC!E11 -> 0 | I9: =ELEC!G11 -> 0 | J9: =WATER!Y13 -> 0 | K9: =WATER!AJ13 -> 0 | L9: =ELEC!B11 -> 0
A10: Beirut | B10: =B9+1 -> 9 | C10: 2 | D10: 2022 | E10: =ELEC!M12 -> 830 | F10: =ELEC!K12 -> 1252 | G10: =ELEC!I12 -> 392 | H10: =ELEC!E12 -> 1900 | I10: =ELEC!G12 -> 224 | J10: =WATER!Y14 -> 0 | K10: =WATER!AJ14 -> 0 | L10: =ELEC!B12 -> 0
A11: Beirut | B11: =B10+1 -> 10 | C11: 2 | D11: 2022 | E11: =ELEC!M13 -> 1046 | F11: =ELEC!K13 -> 1660 | G11: =ELEC!I13 -> 484 | H11: =ELEC!E13 -> 2520 | I11: =ELEC!G13 -> 260 | J11: =WATER!Y15 -> 0 | K11: =WATER!AJ15 -> 0 | L11: =ELEC!B13 -> 0
A12: Beirut | B12: =B11+1 -> 11 | C12: 2 | D12: 2022 | E12: =ELEC!M14 -> 0 | F12: =ELEC!K14 -> 0 | G12: =ELEC!I14 -> 0 | H12: =ELEC!E14 -> 0 | I12: =ELEC!G14 -> 0 | J12: =WATER!Y16 -> 0 | K12: =WATER!AJ16 -> 0 | L12: =ELEC!B14 -> 0
A13: Beirut | B13: =B12+1 -> 12 | C13: 2 | D13: 2022 | E13: =ELEC!M15 -> 0 | F13: =ELEC!K15 -> 0 | G13: =ELEC!I15 -> 0 | H13: =ELEC!E15 -> 0 | I13: =ELEC!G15 -> 0 | J13: =WATER!Y17 -> 0 | K13: =WATER!AJ17 -> 0 | L13: =ELEC!B15 -> 0
A14: Beirut | B14: =B13+1 -> 13 | C14: 2 | D14: 2022 | E14: =ELEC!M16 -> 1242 | F14: =ELEC!K16 -> 1946 | G14: =ELEC!I16 -> 566 | H14: =ELEC!E16 -> 2860 | I14: =ELEC!G16 -> 311 | J14: =WATER!Y18 -> 91 | K14: =WATER!AJ18 -> 0 | L14: =ELEC!B16 -> 0
... A29: Beirut | B29: =B28+1 -> 28 | C29: 2 | D29: 2022 | E29: =ELEC!M31 -> 0 | F29: =ELEC!K31 -> 0 | G29: =ELEC!I31 -> 0 | H29: =ELEC!E31 -> 0 | I29: =ELEC!G31 -> 0 | J29: =WATER!Y33 -> 0 | K29: =WATER!AJ33 -> 0 | L29: =ELEC!B31 -> 0
A30: Beirut
A31: Beirut
A32: Beirut
D45: .

Sheet ELEC
A2: OOC | B2: Room OCC | D2: MDB3 | E2: MDB3/day | F2: EMDB2 | G2: EMDB2/day | H2: EMDB1 | I2: EMDB1/day | J2: MDB2 | K2: mdb2/day | L2: MDB1 | M2: MDB1/Day | N2: Total KWH | O2: KWH/Rooc | P2: Gen MHW | Q2: Gen/Day KWH | R2: EDL KWH | S2: CH1 RH | T2: RH | U2: C1h1 power | V2: CH1 Con KWH | W2: CH2 RH | X2: RH | Y2: Ch2 power | Z2: CH2 Con KWH | AA2: CH3 RH | AB2: RH | AC2: Ch3 power | AD2: CH3 Con KWH | AE2: RH total | AF2: KWH total | AG2: AVG chiller KW/Hr
A3: =[1]ELEC!$A$34 -> 0 | B3: =[1]ELEC!$B$34 -> 0 | C3: =[2]ELEC!C34 -> 44592 | D3: =[2]ELEC!D34 -> 161650 | E3: =[2]ELEC!E34 -> 2130 | F3: =[2]ELEC!F34 -> 4114577.2 | G3: =[2]ELEC!G34 -> 236.2 | H3: =[2]ELEC!H34 -> 18010582 | I3: =[2]ELEC!I34 -> 292 | J3: =[2]ELEC!J34 -> 29685832 | ... AG3: =[2]ELEC!AG34 -> 0
A4: ='General information '!F5 -> 0 | B4: =SUM(230*A4) -> 0 | C4: 44593 | D4: 165580 | E4: =D4-D3 -> 3930 | F4: 4114851 | G4: =F4-F3 -> 273.8 | H4: 18010932 | I4: =H4-H3 -> 350 | J4: 29687676 | K4: =J4-J3 -> 1844 | L4: 24520730 | M4: =L4-L3 -> 1329 | N4: =M4+K4+I4+G4+E4 -> 7726.8 | O4: =IF(B4>0,N4/B4,0) -> 0 | P4: 18892.472 | Q4: =(P4-P3)*1000 -> 6186 | R4: =+N4-Q4 -> 1540.8 | S4: =S3 -> 10175 | T4: =S4-S3 -> 0 | U4: =U3 -> 429166 | V4: =U4-U3 -> 0 | W4: =W3 -> 33484 | X4: =W4-W3 -> 0 | Y4: =Y3 -> 996900 | Z4: =Y4-Y3 -> 0 | AA4: =AA3 -> 36796 | AB4: =AA4-AA3 -> 0 | AC4: =AC3 -> 1170505 | AD4: =AC4-AC3 -> 0 | AE4: =AB4+X4+T4 -> 0 | AF4: =V4+Z4+AD4 -> 0 | AG4: =IF(AE4>0,AF4/AE4,0) -> 0
A5: ='General information '!F6 -> 0 | B5: =SUM(230*A5) -> 0 | C5: 44594 | D5: 166840 | E5: =D5-D4 -> 1260 | F5: 4115113 | G5: =F5-F4 -> 262 | H5: 18011264 | I5: =H5-H4 -> 332 | J5: 29689288 | K5: =J5-J4 -> 1612 | L5: 24521822 | M5: =L5-L4 -> 1092 | N5: =M5+K5+I5+G5+E5 -> 4558 | O5: =IF(B5>0,N5/B5,0) -> 0 | P5: 18898.043 | Q5: =(P5-P4)*1000 -> 5571 | R5: =N5-Q5 -> -1013 | S5: =S4 -> 10175 | T5: =S5-S4 -> 0 | U5: =U4 -> 429166 | V5: =U5-U4 -> 0 | W5: =W4 -> 33484 | X5: =W5-W4 -> 0 | Y5: =Y4 -> 996900 | Z5: =Y5-Y4 -> 0 | AA5: =AA4 -> 36796 | AB5: =AA5-AA4 -> 0 | AC5: =AC4 -> 1170505 | AD5: =AC5-AC4 -> 0 | AE5: =AB5+X5+T5 -> 0 | AF5: =V5+Z5+AD5 -> 0 | AG5: =IF(AE5>0,AF5/AE5,0) -> 0
A6: ='General information '!F7 -> 0 | B6: =SUM(230*A6) -> 0 | C6: 44595 | D6: 169190 | E6: =D6-D5 -> 2350 | F6: 4115364 | G6: =F6-F5 -> 251 | H6: 18011714 | I6: =H6-H5 -> 450 | J6: 29690850 | K6: =J6-J5 -> 1562 | L6: 24522882 | M6: =L6-L5 -> 1060 | N6: =M6+K6+I6+G6+E6 -> 5673 | O6: =IF(B6>0,N6/B6,0) -> 0 | P6: 18903.573 | Q6: =(P6-P5)*1000 -> 5530 | R6: =N6-Q6 -> 143 | S6: =S5 -> 10175 | T6: =S6-S5 -> 0 | U6: =U5 -> 429166 | V6: =U6-U5 -> 0 | W6: =W5 -> 33484 | X6: =W6-W5 -> 0 | Y6: =Y5 -> 996900 | Z6: =Y6-Y5 -> 0 | AA6: =AA5 -> 36796 | AB6: =AA6-AA5 -> 0 | AC6: =AC5 -> 1170505 | AD6: =AC6-AC5 -> 0 | AE6: =AB6+X6+T6 -> 0 | AF6: =V6+Z6+AD6 -> 0 | AG6: =IF(AE6>0,AF6/AE6,0) -> 0
A7: ='General information '!F8 -> 0 | B7: =SUM(230*A7) -> 0 | C7: 44596 | D7: =D6 -> 169190 | E7: =D7-D6 -> 0 | F7: =F6 -> 4115364 | G7: =F7-F6 -> 0 | H7: =H6 -> 18011714 | I7: =H7-H6 -> 0 | J7: =J6 -> 29690850 | K7: =J7-J6 -> 0 | L7: =L6 -> 24522882 | M7: =L7-L6 -> 0 | N7: =M7+K7+I7+G7+E7 -> 0 | O7: =IF(B7>0,N7/B7,0) -> 0 | P7: =P6 -> 18903.573 | Q7: =(P7-P6)*1000 -> 0 | R7: =N7-Q7 -> 0 | S7: =S6 -> 10175 | T7: =S7-S6 -> 0 | U7: =U6 -> 429166 | V7: =U7-U6 -> 0 | W7: =W6 -> 33484 | X7: =W7-W6 -> 0 | Y7: =Y6 -> 996900 | Z7: =Y7-Y6 -> 0 | AA7: =AA6 -> 36796 | AB7: =AA7-AA6 -> 0 | AC7: =AC6 -> 1170505 | AD7: =AC7-AC6 -> 0 | AE7: =AB7+X7+T7 -> 0 | AF7: =V7+Z7+AD7 -> 0 | AG7: =IF(AE7>0,AF7/AE7,0) -> 0
A8: ='General information '!F9 -> 0 | B8: =SUM(230*A8) -> 0 | C8: 44597 | D8: =D7 -> 169190 | E8: =D8-D7 -> 0 | F8: =F7 -> 4115364 | G8: =F8-F7 -> 0 | H8: =H7 -> 18011714 | I8: =H8-H7 -> 0 | J8: =J7 -> 29690850 | K8: =J8-J7 -> 0 | L8: =L7 -> 24522882 | M8: =L8-L7 -> 0 | N8: =M8+K8+I8+G8+E8 -> 0 | O8: =IF(B8>0,N8/B8,0) -> 0 | P8: =P7 -> 18903.573 | Q8: =(P8-P7)*1000 -> 0 | R8: =N8-Q8 -> 0 | S8: =S7 -> 10175 | T8: =S8-S7 -> 0 | U8: =U7 -> 429166 | V8: =U8-U7 -> 0 | W8: =W7 -> 33484 | X8: =W8-W7 -> 0 | Y8: =Y7 -> 996900 | Z8: =Y8-Y7 -> 0 | AA8: =AA7 -> 36796 | AB8: =AA8-AA7 -> 0 | AC8: =AC7 -> 1170505 | AD8: =AC8-AC7 -> 0 | AE8: =AB8+X8+T8 -> 0 | AF8: =V8+Z8+AD8 -> 0 | AG8: =IF(AE8>0,AF8/AE8,0) -> 0
A9: ='General information '!F10 -> 0 | B9: =SUM(230*A9) -> 0 | C9: 44598 | D9: 172230 | E9: =D9-D8 -> 3040 | F9: 4115688.4 | G9: =F9-F8 -> 324.4 | H9: 18012218 | I9: =H9-H8 -> 504 | J9: 29692826 | K9: =J9-J8 -> 1976 | L9: 24524278 | M9: =L9-L8 -> 1396 | N9: =M9+K9+I9+G9+E9 -> 7240.4 | O9: =IF(B9>0,N9/B9,0) -> 0 | P9: 18910.821 | Q9: =(P9-P8)*1000 -> 7248 | R9: =N9-Q9 -> -7.6 | S9: =S8 -> 10175 | T9: =S9-S8 -> 0 | U9: =U8 -> 429166 | V9: =U9-U8 -> 0 | W9: =W8 -> 33484 | X9: =W9-W8 -> 0 | Y9: =Y8 -> 996900 | Z9: =Y9-Y8 -> 0 | AA9: =AA8 -> 36796 | AB9: =AA9-AA8 -> 0 | AC9: =AC8 -> 1170505 | AD9: =AC9-AC8 -> 0 | AE9: =AB9+X9+T9 -> 0 | AF9: =V9+Z9+AD9 -> 0 | AG9: =IF(AE9>0,AF9/AE9,0) -> 0
A10: ='General information '!F11 -> 0 | B10: =SUM(230*A10) -> 0 | C10: 44599 | D10: 174460 | E10: =D10-D9 -> 2230 | F10: 4115974 | G10: =F10-F9 -> 285.6 | H10: 18012614 | I10: =H10-H9 -> 396 | J10: 29694382 | K10: =J10-J9 -> 1556 | L10: 24525402 | M10: =L10-L9 -> 1124 | N10: =M10+K10+I10+G10+E10 -> 5591.6 | O10: =IF(B10>0,N10/B10,0) -> 0 | P10: 18916.374 | Q10: =(P10-P9)*1000 -> 5553 | R10: =N10-Q10 -> 38.6 | S10: =S9 -> 10175 | T10: =S10-S9 -> 0 | U10: =U9 -> 429166 | V10: =U10-U9 -> 0 | W10: =W9 -> 33484 | X10: =W10-W9 -> 0 | Y10: =Y9 -> 996900 | Z10: =Y10-Y9 -> 0 | AA10: =AA9 -> 36796 | AB10: =AA10-AA9 -> 0 | AC10: =AC9 -> 1170505 | AD10: =AC10-AC9 -> 0 | AE10: =AB10+X10+T10 -> 0 | AF10: =V10+Z10+AD10 -> 0 | AG10: =IF(AE10>0,AF10/AE10,0) -> 0
A11: ='General information '!F12 -> 0 | B11: =SUM(230*A11) -> 0 | C11: 44600 | D11: =D10 -> 174460 | E11: =D11-D10 -> 0 | F11: =F10 -> 4115974 | G11: =F11-F10 -> 0 | H11: =H10 -> 18012614 | I11: =H11-H10 -> 0 | J11: =J10 -> 29694382 | K11: =J11-J10 -> 0 | L11: =L10 -> 24525402 | M11: =L11-L10 -> 0 | N11: =M11+K11+I11+G11+E11 -> 0 | O11: =IF(B11>0,N11/B11,0) -> 0 | P11: =P10 -> 18916.374 | Q11: =(P11-P10)*1000 -> 0 | R11: =N11-Q11 -> 0 | S11: =S10 -> 10175 | T11: =S11-S10 -> 0 | U11: =U10 -> 429166 | V11: =U11-U10 -> 0 | W11: =W10 -> 33484 | X11: =W11-W10 -> 0 | Y11: =Y10 -> 996900 | Z11: =Y11-Y10 -> 0 | AA11: =AA10 -> 36796 | AB11: =AA11-AA10 -> 0 | AC11: =AC10 -> 1170505 | AD11: =AC11-AC10 -> 0 | AE11: =AB11+X11+T11 -> 0 | AF11: =V11+Z11+AD11 -> 0 | AG11: =IF(AE11>0,AF11/AE11,0) -> 0
A12: ='General information '!F13 -> 0 | B12: =SUM(230*A12) -> 0 | C12: 44601 | D12: 176360 | E12: =D12-D11 -> 1900 | F12: 4116198 | G12: =F12-F11 -> 224 | H12: 18013006 | I12: =H12-H11 -> 392 | J12: 29695634 | K12: =J12-J11 -> 1252 | L12: 24526232 | M12: =L12-L11 -> 830 | N12: =M12+K12+I12+G12+E12 -> 4598 | O12: =IF(B12>0,N12/B12,0) -> 0 | P12: 18920.781 | Q12: =(P12-P11)*1000 -> 4407 | R12: =N12-Q12 -> 191 | S12: =S11 -> 10175 | T12: =S12-S11 -> 0 | U12: =U11 -> 429166 | V12: =U12-U11 -> 0 | W12: =W11 -> 33484 | X12: =W12-W11 -> 0 | Y12: =Y11 -> 996900 | Z12: =Y12-Y11 -> 0 | AA12: =AA11 -> 36796 | AB12: =AA12-AA11 -> 0 | AC12: =AC11 -> 1170505 | AD12: =AC12-AC11 -> 0 | AE12: =AB12+X12+T12 -> 0 | AF12: =V12+Z12+AD12 -> 0 | AG12: =IF(AE12>0,AF12/AE12,0) -> 0
A13: ='General information '!F14 -> 0 | B13: =SUM(230*A13) -> 0 | C13: 44602 | D13: 178880 | E13: =D13-D12 -> 2520 | F13: 4116458 | G13: =F13-F12 -> 260 | H13: 18013490 | I13: =H13-H12 -> 484 | J13: 29697294 | K13: =J13-J12 -> 1660 | L13: 24527278 | M13: =L13-L12 -> 1046 | N13: =M13+K13+I13+G13+E13 -> 5970 | O13: =IF(B13>0,N13/B13,0) -> 0 | P13: 18926.369 | Q13: =(P13-P12)*1000 -> 5588 | R13: =N13-Q13 -> 382 | S13: =S12 -> 10175 | T13: =S13-S12 -> 0 | U13: =U12 -> 429166 | V13: =U13-U12 -> 0 | W13: =W12 -> 33484 | X13: =W13-W12 -> 0 | Y13: =Y12 -> 996900 | Z13: =Y13-Y12 -> 0 | AA13: =AA12 -> 36796 | AB13: =AA13-AA12 -> 0 | AC13: =AC12 -> 1170505 | AD13: =AC13-AC12 -> 0 | AE13: =AB13+X13+T13 -> 0 | AF13: =V13+Z13+AD13 -> 0 | AG13: =IF(AE13>0,AF13/AE13,0) -> 0
A14: ='General information '!F15 -> 0 | B14: =SUM(230*A14) -> 0 | C14: 44603 | D14: =D13 -> 178880 | E14: =D14-D13 -> 0 | F14: =F13 -> 4116458 | G14: =F14-F13 -> 0 | H14: =H13 -> 18013490 | I14: =H14-H13 -> 0 | J14: =J13 -> 29697294 | K14: =J14-J13 -> 0 | L14: =L13 -> 24527278 | M14: =L14-L13 -> 0 | N14: =M14+K14+I14+G14+E14 -> 0 | O14: =IF(B14>0,N14/B14,0) -> 0 | P14: =P13 -> 18926.369 | Q14: =(P14-P13)*1000 -> 0 | R14: =N14-Q14 -> 0 | S14: =S13 -> 10175 | T14: =S14-S13 -> 0 | U14: =U13 -> 429166 | V14: =U14-U13 -> 0 | W14: =W13 -> 33484 | X14: =W14-W13 -> 0 | Y14: =Y13 -> 996900 | Z14: =Y14-Y13 -> 0 | AA14: =AA13 -> 36796 | AB14: =AA14-AA13 -> 0 | AC14: =AC13 -> 1170505 | AD14: =AC14-AC13 -> 0 | AE14: =AB14+X14+T14 -> 0 | AF14: =V14+Z14+AD14 -> 0 | AG14: =IF(AE14>0,AF14/AE14,0) -> 0
A15: ='General information '!F16 -> 0 | B15: =SUM(230*A15) -> 0 | C15: 44604 | D15: =D14 -> 178880 | E15: =D15-D14 -> 0 | F15: =F14 -> 4116458 | G15: =F15-F14 -> 0 | H15: =H14 -> 18013490 | I15: =H15-H14 -> 0 | J15: =J14 -> 29697294 | K15: =J15-J14 -> 0 | L15: =L14 -> 24527278 | M15: =L15-L14 -> 0 | N15: =M15+K15+I15+G15+E15 -> 0 | O15: =IF(B15>0,N15/B15,0) -> 0 | P15: =P14 -> 18926.369 | Q15: =(P15-P14)*1000 -> 0 | R15: =N15-Q15 -> 0 | S15: =S14 -> 10175 | T15: =S15-S14 -> 0 | U15: =U14 -> 429166 | V15: =U15-U14 -> 0 | W15: =W14 -> 33484 | X15: =W15-W14 -> 0 | Y15: =Y14 -> 996900 | Z15: =Y15-Y14 -> 0 | AA15: =AA14 -> 36796 | AB15: =AA15-AA14 -> 0 | AC15: =AC14 -> 1170505 | AD15: =AC15-AC14 -> 0 | AE15: =AB15+X15+T15 -> 0 | AF15: =V15+Z15+AD15 -> 0 | AG15: =IF(AE15>0,AF15/AE15,0) -> 0
A16: ='General information '!F17 -> 0 | B16: =SUM(230*A16) -> 0 | C16: 44605 | D16: 181740 | E16: =D16-D15 -> 2860 | F16: 4116769 | G16: =F16-F15 -> 311 | H16: 18014056 | I16: =H16-H15 -> 566 | J16: 29699240 | K16: =J16-J15 -> 1946 | L16: 24528520 | M16: =L16-L15 -> 1242 | N16: =M16+K16+I16+G16+E16 -> 6925 | O16: =IF(B16>0,N16/B16,0) -> 0 | P16: 18932.882 | Q16: =(P16-P15)*1000 -> 6513 | R16: =N16-Q16 -> 412 | S16: =S15 -> 10175 | T16: =S16-S15 -> 0 | U16: =U15 -> 429166 | V16: =U16-U15 -> 0 | W16: =W15 -> 33484 | X16: =W16-W15 -> 0 | Y16: =Y15 -> 996900 | Z16: =Y16-Y15 -> 0 | AA16: =AA15 -> 36796 | AB16: =AA16-AA15 -> 0 | AC16: =AC15 -> 1170505 | AD16: =AC16-AC15 -> 0 | AE16: =AB16+X16+T16 -> 0 | AF16: =V16+Z16+AD16 -> 0 | AG16: =IF(AE16>0,AF16/AE16,0) -> 0
A17: ='General information '!F18 -> 0 | B17: =SUM(230*A17) -> 0 | C17: 44606 | D17: 184350 | E17: =D17-D16 -> 2610 | F17: 4117023 | G17: =F17-F16 -> 254 | H17: 18014530 | I17: =H17-H16 -> 474 | J17: 29700898 | K17: =J17-J16 -> 1658 | L17: 24529544 | M17: =L17-L16 -> 1024 | N17: =M17+K17+I17+G17+E17 -> 6020 | O17: =IF(B17>0,N17/B17,0) -> 0 | P17: 18938.981 | Q17: =(P17-P16)*1000 -> 6099 | R17: =N17-Q17 -> -79 | S17: =S16 -> 10175 | T17: =S17-S16 -> 0 | U17: =U16 -> 429166 | V17: =U17-U16 -> 0 | W17: =W16 -> 33484 | X17: =W17-W16 -> 0 | Y17: =Y16 -> 996900 | Z17: =Y17-Y16 -> 0 | AA17: =AA16 -> 36796 | AB17: =AA17-AA16 -> 0 | AC17: =AC16 -> 1170505 | AD17: =AC17-AC16 -> 0 | AE17: =AB17+X17+T17 -> 0 | AF17: =V17+Z17+AD17 -> 0 | AG17: =IF(AE17>0,AF17/AE17,0) -> 0
A18: ='General information '!F19 -> 0 | B18: =SUM(230*A18) -> 0 | C18: 44607 | D18: 186580 | E18: =D18-D17 -> 2230 | F18: 4117249 | G18: =F18-F17 -> 226 | H18: 18014958 | I18: =H18-H17 -> 428 | J18: 29702370 | K18: =J18-J17 -> 1472 | L18: 24530464 | M18: =L18-L17 -> 920 | N18: =M18+K18+I18+G18+E18 -> 5276 | O18: =IF(B18>0,N18/B18,0) -> 0 | P18: 18944.027 | Q18: =(P18-P17)*1000 -> 5046 | R18: =N18-Q18 -> 230 | S18: =S17 -> 10175 | T18: =S18-S17 -> 0 | U18: =U17 -> 429166 | V18: =U18-U17 -> 0 | W18: =W17 -> 33484 | X18: =W18-W17 -> 0 | Y18: =Y17 -> 996900 | Z18: =Y18-Y17 -> 0 | AA18: =AA17 -> 36796 | AB18: =AA18-AA17 -> 0 | AC18: =AC17 -> 1170505 | AD18: =AC18-AC17 -> 0 | AE18: =AB18+X18+T18 -> 0 | AF18: =V18+Z18+AD18 -> 0 | AG18: =IF(AE18>0,AF18/AE18,0) -> 0
A19: ='General information '!F20 -> 0 | B19: =SUM(230*A19) -> 0 | C19: 44608 | D19: 188920 | E19: =D19-D18 -> 2340 | F19: 4117469 | G19: =F19-F18 -> 220 | H19: 18015406 | I19: =H19-H18 -> 448 | J19: 29703826 | K19: =J19-J18 -> 1456 | L19: 24531334 | M19: =L19-L18 -> 870 | N19: =M19+K19+I19+G19+E19 -> 5334 | O19: =IF(B19>0,N19/B19,0) -> 0 | P19: 18949.195 | Q19: =(P19-P18)*1000 -> 5168 | R19: =N19-Q19 -> 166 | S19: =S18 -> 10175 | T19: =S19-S18 -> 0 | U19: =U18 -> 429166 | V19: =U19-U18 -> 0 | W19: =W18 -> 33484 | X19: =W19-W18 -> 0 | Y19: =Y18 -> 996900 | Z19: =Y19-Y18 -> 0 | AA19: =AA18 -> 36796 | AB19: =AA19-AA18 -> 0 | AC19: =AC18 -> 1170505 | AD19: =AC19-AC18 -> 0 | AE19: =AB19+X19+T19 -> 0 | AF19: =V19+Z19+AD19 -> 0 | AG19: =IF(AE19>0,AF19/AE19,0) -> 0
A20: ='General information '!F21 -> 0 | B20: =SUM(230*A20) -> 0 | C20: 44609 | D20: 191090 | E20: =D20-D19 -> 2170 | F20: 4117705 | G20: =F20-F19 -> 236 | H20: 18015854 | I20: =H20-H19 -> 448 | J20: 29705082 | K20: =J20-J19 -> 1256 | L20: 24532082 | M20: =L20-L19 -> 748 | N20: =M20+K20+I20+G20+E20 -> 4858 | O20: =IF(B20>0,N20/B20,0) -> 0 | P20: 18953.818 | Q20: =(P20-P19)*1000 -> 4623 | R20: =N20-Q20 -> 235 | S20: =S19 -> 10175 | T20: =S20-S19 -> 0 | U20: =U19 -> 429166 | V20: =U20-U19 -> 0 | W20: =W19 -> 33484 | X20: =W20-W19 -> 0 | Y20: =Y19 -> 996900 | Z20: =Y20-Y19 -> 0 | AA20: =AA19 -> 36796 | AB20: =AA20-AA19 -> 0 | AC20: =AC19 -> 1170505 | AD20: =AC20-AC19 -> 0 | AE20: =AB20+X20+T20 -> 0 | AF20: =V20+Z20+AD20 -> 0 | AG20: =IF(AE20>0,AF20/AE20,0) -> 0
A21: ='General information '!F22 -> 0 | B21: =SUM(230*A21) -> 0 | C21: 44610 | D21: =D20 -> 191090 | E21: =D21-D20 -> 0 | F21: =F20 -> 4117705 | G21: =F21-F20 -> 0 | H21: =H20 -> 18015854 | I21: =H21-H20 -> 0 | J21: =J20 -> 29705082 | K21: =J21-J20 -> 0 | L21: =L20 -> 24532082 | M21: =L21-L20 -> 0 | N21: =M21+K21+I21+G21+E21 -> 0 | O21: =IF(B21>0,N21/B21,0) -> 0 | P21: =P20 -> 18953.818 | Q21: =(P21-P20)*1000 -> 0 | R21: =N21-Q21 -> 0 | S21: =S20 -> 10175 | T21: =S21-S20 -> 0 | U21: =U20 -> 429166 | V21: =U21-U20 -> 0 | W21: =W20 -> 33484 | X21: =W21-W20 -> 0 | Y21: =Y20 -> 996900 | Z21: =Y21-Y20 -> 0 | AA21: =AA20 -> 36796 | AB21: =AA21-AA20 -> 0 | AC21: =AC20 -> 1170505 | AD21: =AC21-AC20 -> 0 | AE21: =AB21+X21+T21 -> 0 | AF21: =V21+Z21+AD21 -> 0 | AG21: =IF(AE21>0,AF21/AE21,0) -> 0
A22: ='General information '!F23 -> 0 | B22: =SUM(230*A22) -> 0 | C22: 44611 | D22: =D21 -> 191090 | E22: =D22-D21 -> 0 | F22: =F21 -> 4117705 | G22: =F22-F21 -> 0 | H22: =H21 -> 18015854 | I22: =H22-H21 -> 0 | J22: =J21 -> 29705082 | K22: =J22-J21 -> 0 | L22: =L21 -> 24532082 | M22: =L22-L21 -> 0 | N22: =M22+K22+I22+G22+E22 -> 0 | O22: =IF(B22>0,N22/B22,0) -> 0 | P22: =P21 -> 18953.818 | Q22: =(P22-P21)*1000 -> 0 | R22: =N22-Q22 -> 0 | S22: =S21 -> 10175 | T22: =S22-S21 -> 0 | U22: =U21 -> 429166 | V22: =U22-U21 -> 0 | W22: =W21 -> 33484 | X22: =W22-W21 -> 0 | Y22: =Y21 -> 996900 | Z22: =Y22-Y21 -> 0 | AA22: =AA21 -> 36796 | AB22: =AA22-AA21 -> 0 | AC22: =AC21 -> 1170505 | AD22: =AC22-AC21 -> 0 | AE22: =AB22+X22+T22 -> 0 | AF22: =V22+Z22+AD22 -> 0 | AG22: =IF(AE22>0,AF22/AE22,0) -> 0
A23: ='General information '!F24 -> 0 | B23: =SUM(230*A23) -> 0 | C23: 44612 | D23: =D22 -> 191090 | E23: =D23-D22 -> 0 | F23: =F22 -> 4117705 | G23: =F23-F22 -> 0 | H23: =H22 -> 18015854 | I23: =H23-H22 -> 0 | J23: =J22 -> 29705082 | K23: =J23-J22 -> 0 | L23: =L22 -> 24532082 | M23: =L23-L22 -> 0 | N23: =M23+K23+I23+G23+E23 -> 0 | O23: =IF(B23>0,N23/B23,0) -> 0 | P23: =P22 -> 18953.818 | Q23: =(P23-P22)*1000 -> 0 | R23: =N23-Q23 -> 0 | S23: =S22 -> 10175 | T23: =S23-S22 -> 0 | U23: =U22 -> 429166 | V23: =U23-U22 -> 0 | W23: =W22 -> 33484 | X23: =W23-W22 -> 0 | Y23: =Y22 -> 996900 | Z23: =Y23-Y22 -> 0 | AA23: =AA22 -> 36796 | AB23: =AA23-AA22 -> 0 | AC23: =AC22 -> 1170505 | AD23: =AC23-AC22 -> 0 | AE23: =AB23+X23+T23 -> 0 | AF23: =V23+Z23+AD23 -> 0 | AG23: =IF(AE23>0,AF23/AE23,0) -> 0
A24: ='General information '!F25 -> 0 | B24: =SUM(230*A24) -> 0 | C24: 44613 | D24: =D23 -> 191090 | E24: =D24-D23 -> 0 | F24: =F23 -> 4117705 | G24: =F24-F23 -> 0 | H24: =H23 -> 18015854 | I24: =H24-H23 -> 0 | J24: =J23 -> 29705082 | K24: =J24-J23 -> 0 | L24: =L23 -> 24532082 | M24: =L24-L23 -> 0 | N24: =M24+K24+I24+G24+E24 -> 0 | O24: =IF(B24>0,N24/B24,0) -> 0 | P24: =P23 -> 18953.818 | Q24: =(P24-P23)*1000 -> 0 | R24: =N24-Q24 -> 0 | S24: =S23 -> 10175 | T24: =S24-S23 -> 0 | U24: =U23 -> 429166 | V24: =U24-U23 -> 0 | W24: =W23 -> 33484 | X24: =W24-W23 -> 0 | Y24: =Y23 -> 996900 | Z24: =Y24-Y23 -> 0 | AA24: =AA23 -> 36796 | AB24: =AA24-AA23 -> 0 | AC24: =AC23 -> 1170505 | AD24: =AC24-AC23 -> 0 | AE24: =AB24+X24+T24 -> 0 | AF24: =V24+Z24+AD24 -> 0 | AG24: =IF(AE24>0,AF24/AE24,0) -> 0
A25: ='General information '!F26 -> 0 | B25: =SUM(230*A25) -> 0 | C25: 44614 | D25: =D24 -> 191090 | E25: =D25-D24 -> 0 | F25: =F24 -> 4117705 | G25: =F25-F24 -> 0 | H25: =H24 -> 18015854 | I25: =H25-H24 -> 0 | J25: =J24 -> 29705082 | K25: =J25-J24 -> 0 | L25: =L24 -> 24532082 | M25: =L25-L24 -> 0 | N25: =M25+K25+I25+G25+E25 -> 0 | O25: =IF(B25>0,N25/B25,0) -> 0 | P25: =P24 -> 18953.818 | Q25: =(P25-P24)*1000 -> 0 | R25: =N25-Q25 -> 0 | S25: =S24 -> 10175 | T25: =S25-S24 -> 0 | U25: =U24 -> 429166 | V25: =U25-U24 -> 0 | W25: =W24 -> 33484 | X25: =W25-W24 -> 0 | Y25: =Y24 -> 996900 | Z25: =Y25-Y24 -> 0 | AA25: =AA24 -> 36796 | AB25: =AA25-AA24 -> 0 | AC25: =AC24 -> 1170505 | AD25: =AC25-AC24 -> 0 | AE25: =AB25+X25+T25 -> 0 | AF25: =V25+Z25+AD25 -> 0 | AG25: =IF(AE25>0,AF25/AE25,0) -> 0
A26: ='General information '!F27 -> 0 | B26: =SUM(230*A26) -> 0 | C26: 44615 | D26: =D25 -> 191090 | E26: =D26-D25 -> 0 | F26: =F25 -> 4117705 | G26: =F26-F25 -> 0 | H26: =H25 -> 18015854 | I26: =H26-H25 -> 0 | J26: =J25 -> 29705082 | K26: =J26-J25 -> 0 | L26: =L25 -> 24532082 | M26: =L26-L25 -> 0 | N26: =M26+K26+I26+G26+E26 -> 0 | O26: =IF(B26>0,N26/B26,0) -> 0 | P26: =P25 -> 18953.818 | Q26: =(P26-P25)*1000 -> 0 | R26: =N26-Q26 -> 0 | S26: =S25 -> 10175 | T26: =S26-S25 -> 0 | U26: =U25 -> 429166 | V26: =U26-U25 -> 0 | W26: =W25 -> 33484 | X26: =W26-W25 -> 0 | Y26: =Y25 -> 996900 | Z26: =Y26-Y25 -> 0 | AA26: =AA25 -> 36796 | AB26: =AA26-AA25 -> 0 | AC26: =AC25 -> 1170505 | AD26: =AC26-AC25 -> 0 | AE26: =AB26+X26+T26 -> 0 | AF26: =V26+Z26+AD26 -> 0 | AG26: =IF(AE26>0,AF26/AE26,0) -> 0
A27: ='General information '!F28 -> 0 | B27: =SUM(230*A27) -> 0 | C27: 44616 | D27: =D26 -> 191090 | E27: =D27-D26 -> 0 | F27: =F26 -> 4117705 | G27: =F27-F26 -> 0 | H27: =H26 -> 18015854 | I27: =H27-H26 -> 0 | J27: =J26 -> 29705082 | K27: =J27-J26 -> 0 | L27: =L26 -> 24532082 | M27: =L27-L26 -> 0 | N27: =M27+K27+I27+G27+E27 -> 0 | O27: =IF(B27>0,N27/B27,0) -> 0 | P27: =P26 -> 18953.818 | Q27: =(P27-P26)*1000 -> 0 | R27: =N27-Q27 -> 0 | S27: =S26 -> 10175 | T27: =S27-S26 -> 0 | U27: =U26 -> 429166 | V27: =U27-U26 -> 0 | W27: =W26 -> 33484 | X27: =W27-W26 -> 0 | Y27: =Y26 -> 996900 | Z27: =Y27-Y26 -> 0 | AA27: =AA26 -> 36796 | AB27: =AA27-AA26 -> 0 | AC27: =AC26 -> 1170505 | AD27: =AC27-AC26 -> 0 | AE27: =AB27+X27+T27 -> 0 | AF27: =V27+Z27+AD27 -> 0 | AG27: =IF(AE27>0,AF27/AE27,0) -> 0
A28: ='General information '!F29 -> 0 | B28: =SUM(230*A28) -> 0 | C28: 44617 | D28: =D27 -> 191090 | E28: =D28-D27 -> 0 | F28: =F27 -> 4117705 | G28: =F28-F27 -> 0 | H28: =H27 -> 18015854 | I28: =H28-H27 -> 0 | J28: =J27 -> 29705082 | K28: =J28-J27 -> 0 | L28: =L27 -> 24532082 | M28: =L28-L27 -> 0 | N28: =M28+K28+I28+G28+E28 -> 0 | O28: =IF(B28>0,N28/B28,0) -> 0 | P28: =P27 -> 18953.818 | Q28: =(P28-P27)*1000 -> 0 | R28: =N28-Q28 -> 0 | S28: =S27 -> 10175 | T28: =S28-S27 -> 0 | U28: =U27 -> 429166 | V28: =U28-U27 -> 0 | W28: =W27 -> 33484 | X28: =W28-W27 -> 0 | Y28: =Y27 -> 996900 | Z28: =Y28-Y27 -> 0 | AA28: =AA27 -> 36796 | AB28: =AA28-AA27 -> 0 | AC28: =AC27 -> 1170505 | AD28: =AC28-AC27 -> 0 | AE28: =AB28+X28+T28 -> 0 | AF28: =V28+Z28+AD28 -> 0 | AG28: =IF(AE28>0,AF28/AE28,0) -> 0
A29: ='General information '!F30 -> 0 | B29: =SUM(230*A29) -> 0 | C29: 44618 | D29: =D28 -> 191090 | E29: =D29-D28 -> 0 | F29: =F28 -> 4117705 | G29: =F29-F28 -> 0 | H29: =H28 -> 18015854 | I29: =H29-H28 -> 0 | J29: =J28 -> 29705082 | K29: =J29-J28 -> 0 | L29: =L28 -> 24532082 | M29: =L29-L28 -> 0 | N29: =M29+K29+I29+G29+E29 -> 0 | O29: =IF(B29>0,N29/B29,0) -> 0 | P29: =P28 -> 18953.818 | Q29: =(P29-P28)*1000 -> 0 | R29: =N29-Q29 -> 0 | S29: =S28 -> 10175 | T29: =S29-S28 -> 0 | U29: =U28 -> 429166 | V29: =U29-U28 -> 0 | W29: =W28 -> 33484 | X29: =W29-W28 -> 0 | Y29: =Y28 -> 996900 | Z29: =Y29-Y28 -> 0 | AA29: =AA28 -> 36796 | AB29: =AA29-AA28 -> 0 | AC29: =AC28 -> 1170505 | AD29: =AC29-AC28 -> 0 | AE29: =AB29+X29+T29 -> 0 | AF29: =V29+Z29+AD29 -> 0 | AG29: =IF(AE29>0,AF29/AE29,0) -> 0
A30: ='General information '!F31 -> 0 | B30: =SUM(230*A30) -> 0 | C30: 44619 | D30: =D29 -> 191090 | E30: =D30-D29 -> 0 | F30: =F29 -> 4117705 | G30: =F30-F29 -> 0 | H30: =H29 -> 18015854 | I30: =H30-H29 -> 0 | J30: =J29 -> 29705082 | K30: =J30-J29 -> 0 | L30: =L29 -> 24532082 | M30: =L30-L29 -> 0 | N30: =M30+K30+I30+G30+E30 -> 0 | O30: =IF(B30>0,N30/B30,0) -> 0 | P30: =P29 -> 18953.818 | Q30: =(P30-P29)*1000 -> 0 | R30: =N30-Q30 -> 0 | S30: =S29 -> 10175 | T30: =S30-S29 -> 0 | U30: =U29 -> 429166 | V30: =U30-U29 -> 0 | W30: =W29 -> 33484 | X30: =W30-W29 -> 0 | Y30: =Y29 -> 996900 | Z30: =Y30-Y29 -> 0 | AA30: =AA29 -> 36796 | AB30: =AA30-AA29 -> 0 | AC30: =AC29 -> 1170505 | AD30: =AC30-AC29 -> 0 | AE30: =AB30+X30+T30 -> 0 | AF30: =V30+Z30+AD30 -> 0 | AG30: =IF(AE30>0,AF30/AE30,0) -> 0
A31: ='General information '!F32 -> 0 | B31: =SUM(230*A31) -> 0 | C31: 44620 | D31: =D30 -> 191090 | E31: =D31-D30 -> 0 | F31: =F30 -> 4117705 | G31: =F31-F30 -> 0 | H31: =H30 -> 18015854 | I31: =H31-H30 -> 0 | J31: =J30 -> 29705082 | K31: =J31-J30 -> 0 | L31: =L30 -> 24532082 | M31: =L31-L30 -> 0 | N31: =M31+K31+I31+G31+E31 -> 0 | O31: =IF(B31>0,N31/B31,0) -> 0 | P31: =P30 -> 18953.818 | Q31: =(P31-P30)*1000 -> 0 | R31: =N31-Q31 -> 0 | S31: =S30 -> 10175 | T31: =S31-S30 -> 0 | U31: =U30 -> 429166 | V31: =U31-U30 -> 0 | W31: =W30 -> 33484 | X31: =W31-W30 -> 0 | Y31: =Y30 -> 996900 | Z31: =Y31-Y30 -> 0 | AA31: =AA30 -> 36796 | AB31: =AA31-AA30 -> 0 | AC31: =AC30 -> 1170505 | AD31: =AC31-AC30 -> 0 | AE31: =AB31+X31+T31 -> 0 | AF31: =V31+Z31+AD31 -> 0 | AG31: =IF(AE31>0,AF31/AE31,0) -> 0
AG33: =IF(AE33>0,AF33/AE33,0) -> 0
AG34: =IF(AE34>0,AF34/AE34,0) -> 0

Sheet B5
F1: Boiler A | J1: =J36 -> 63.267857 | K1: Boiler B | P1: Boiler C | V1: Boiler | X1: SteamA | AC1: SteamB | AH1: Steam | AI1: Boiler & steam | AL1: Total Boiler Runing H | AM1: Total Steam Runing H | AN1: GAS1 % | AO1: GAS1/L | AP1: GAS2% | AQ1: Gas2/L | AR1: GAS3% | AS1: GAS3/L | AU1: Gas Cons | AV1: Delivery | AW1: Cost/L
B2: Level Tank Gen | C2: Level tank Boiler | D2: Daily Cons Bo. | E2: Boiler litter | F2: Boiler A | G2: Run Hr a | H2: Boiler A fuel | I2: Daily consumption | J2: AVG | K2: index Run H | L2: Run Hrb | M2: Boiler B Fuel | O2: Daily consumption | P2: Boiler C | S2: Run C | U2: Total RH | V2: Total Fuel | X2: SteamA | Y2: Run SA | Z2: Steam A Conter | AA2: Liters | AC2: SteamB | AD2: Run SteamB | AE2: Steam B Conter | AF2: SB Litters | AG2: Avg | AH2: Total Fuel | AI2: Total Fuel
S3: 0
A4: =[2]B5!A35 -> 44592 | B4: =[2]B5!B35 -> 162 | C4: =[2]B5!C35 -> 169 | D4: =[2]B5!D35 -> 7 | E4: =[2]B5!E35 -> 58.66 | F4: =[2]B5!F35 -> 2053 | G4: =[2]B5!G35 -> 6 | H4: =[2]B5!H35 -> 29215 | ... AX4: =[2]B5!AX35 -> 0.8
A5: =ELEC!C4 -> 44593 | B5: 153 | C5: 160 | D5: =C4-C5 -> 9 | E5: =D5*8.38 -> 75.42 | F5: 2059 | G5: =F5-F4 -> 6 | H5: 29700 | I5: =SUM(H5-H4) -> 485 | J5: 1 | K5: =K4 -> 2384 | L5: =K5-K4 -> 0 | M5: =M4 -> 176242 | N5: =M5-M4 -> 0 | O5: =O4 -> 1869 | P5: =P4 -> 2142 | Q5: =Q4 -> 179665 | R5: =Q5-Q4 -> 0 | S5: =SUM(P5-P4) -> 0 | T5: =SUM(S5*$T$2) -> 0 | U5: =SUM(G5+L5+S5) -> 6 | V5: =R5+N5+I5:I5 -> 485 | W5: =SUM(V5/U5) -> 80.833333 | X5: =X4 -> 2471 | Y5: =X5-X4 -> 0 | Z5: =Z4 -> 1392127 | AA5: =Z5-Z4 -> 0 | AB5: =SUM(Y5*$AB$2) -> 0 | AC5: =AC4 -> 1943 | AD5: =AC5-AC4 -> 0 | AE5: =AE4 -> 366210 | AF5: =AE5-AE4 -> 0 | AG5: =IF(AD5>0,AF5/AD5,0) -> 0 | AH5: =AF5+AA5 -> 0 | AI5: =SUM(AH5+V5) -> 485 | AJ5: =-tanks!AW6 -> 485 | AK5: =SUM(AJ5-AI5) -> 0 | AL5: =S5+L5+G5 -> 6 | AM5: =Y5+AD5 -> 0 | AN5: =AN4 -> 65 | AO5: =(AN5/100)*3000 -> 1950 | AP5: =AP4 -> 55 | AQ5: =(AP5/100)*3000 -> 1650 | AR5: =AR4 -> 61 | AS5: =(AR5/100)*3000 -> 1830 | AT5: =SUM(AO5+AQ5+AS5) -> 5430 | AU5: =AT4-AT5+AV5 -> 0 | AX5: =IF(AV5>0,AW5,AX4) -> 0.8
A6: =ELEC!C5 -> 44594 | B6: 145 | C6: 152 | D6: =C5-C6 -> 8 | E6: =D6*8.38 -> 67.04 | F6: 2066 | G6: =F6-F5 -> 7 | H6: 30203 | I6: =SUM(H6-H5) -> 503 | J6: =IF(G6>0,I6/G6,0) -> 71.857143 | K6: =K5 -> 2384 | L6: =K6-K5 -> 0 | M6: =M5 -> 176242 | N6: =M6-M5 -> 0 | O6: =O5 -> 1869 | P6: =P5 -> 2142 | Q6: =Q5 -> 179665 | R6: =Q6-Q5 -> 0 | S6: =SUM(P6-P5) -> 0 | T6: =SUM(S6*$T$2) -> 0 | U6: =SUM(G6+L6+S6) -> 7 | V6: =R6+N6+I6:I6 -> 503 | W6: =SUM(V6/U6) -> 71.857143 | X6: =X5 -> 2471 | Y6: =X6-X5 -> 0 | Z6: =Z5 -> 1392127 | AA6: =Z6-Z5 -> 0 | AB6: =SUM(Y6*$AB$2) -> 0 | AC6: =AC5 -> 1943 | AD6: =AC6-AC5 -> 0 | AE6: =AE5 -> 366210 | AF6: =AE6-AE5 -> 0 | AG6: =IF(AD6>0,AF6/AD6,0) -> 0 | AH6: =AF6+AA6 -> 0 | AI6: =SUM(AH6+V6) -> 503 | AJ6: =-tanks!AW7 -> 503 | AK6: =SUM(AJ6-AI6) -> 0 | AL6: =S6+L6+G6 -> 7 | AM6: =Y6+AD6 -> 0 | AN6: =AN5 -> 65 | AO6: =(AN6/100)*3000 -> 1950 | AP6: =AP5 -> 55 | AQ6: =(AP6/100)*3000 -> 1650 | AR6: =AR5 -> 61 | AS6: =(AR6/100)*3000 -> 1830 | AT6: =SUM(AO6+AQ6+AS6) -> 5430 | AU6: =AT5-AT6+AV6 -> 0 | AX6: =IF(AV6>0,AW6,AX5) -> 0.8
A7: =ELEC!C6 -> 44595 | B7: 137 | C7: 145 | D7: =C6-C7 -> 7 | E7: =D7*8.38 -> 58.66 | F7: 2070 | G7: =F7-F6 -> 4 | H7: 30526 | I7: =SUM(H7-H6) -> 323 | J7: =IF(G7>0,I7/G7,0) -> 80.75 | K7: =K6 -> 2384 | L7: =K7-K6 -> 0 | M7: =M6 -> 176242 | N7: =M7-M6 -> 0 | O7: =O6 -> 1869 | P7: =P6 -> 2142 | Q7: =Q6 -> 179665 | R7: =Q7-Q6 -> 0 | S7: =SUM(P7-P6) -> 0 | T7: =SUM(S7*$T$2) -> 0 | U7: =SUM(G7+L7+S7) -> 4 | V7: =R7+N7+I7:I7 -> 323 | W7: =SUM(V7/U7) -> 80.75 | X7: =X6 -> 2471 | Y7: =X7-X6 -> 0 | Z7: =Z6 -> 1392127 | AA7: =Z7-Z6 -> 0 | AB7: =SUM(Y7*$AB$2) -> 0 | AC7: =AC6 -> 1943 | AD7: =AC7-AC6 -> 0 | AE7: =AE6 -> 366210 | AF7: =AE7-AE6 -> 0 | AG7: =IF(AD7>0,AF7/AD7,0) -> 0 | AH7: =AF7+AA7 -> 0 | AI7: =SUM(AH7+V7) -> 323 | AJ7: =-tanks!AW8 -> 323 | AK7: =SUM(AJ7-AI7) -> 0 | AL7: =S7+L7+G7 -> 4 | AM7: =Y7+AD7 -> 0 | AN7: =AN6 -> 65 | AO7: =(AN7/100)*3000 -> 1950 | AP7: =AP6 -> 55 | AQ7: =(AP7/100)*3000 -> 1650 | AR7: =AR6 -> 61 | AS7: =(AR7/100)*3000 -> 1830 | AT7: =SUM(AO7+AQ7+AS7) -> 5430 | AU7: =AT6-AT7+AV7 -> 0 | AX7: =IF(AV7>0,AW7,AX6) -> 0.8
A8: =ELEC!C7 -> 44596 | B8: =B7 -> 137 | C8: =C7 -> 145 | D8: =C7-C8 -> 0 | E8: =D8*8.38 -> 0 | F8: =F7 -> 2070 | G8: =F8-F7 -> 0 | H8: =H7 -> 30526 | I8: =SUM(H8-H7) -> 0 | J8: =IF(G8>0,I8/G8,0) -> 0 | K8: =K7 -> 2384 | L8: =K8-K7 -> 0 | M8: =M7 -> 176242 | N8: =M8-M7 -> 0 | O8: =O7 -> 1869 | P8: =P7 -> 2142 | Q8: =Q7 -> 179665 | R8: =Q8-Q7 -> 0 | S8: =SUM(P8-P7) -> 0 | T8: =SUM(S8*$T$2) -> 0 | U8: =SUM(G8+L8+S8) -> 0 | V8: 0 | W8: =SUM(V8/U8) -> #DIV/0! | X8: 2471 | Y8: =X8-X7 -> 0 | Z8: =Z7 -> 1392127 | AA8: =Z8-Z7 -> 0 | AB8: =SUM(Y8*$AB$2) -> 0 | AC8: =AC7 -> 1943 | AD8: =AC8-AC7 -> 0 | AE8: =AE7 -> 366210 | AF8: =AE8-AE7 -> 0 | AG8: =IF(AD8>0,AF8/AD8,0) -> 0 | AH8: =AF8+AA8 -> 0 | AI8: =SUM(AH8+V8) -> 0 | AJ8: =-tanks!AW9 -> 0 | AK8: =SUM(AJ8-AI8) -> 0 | AL8: =S8+L8+G8 -> 0 | AM8: =Y8+AD8 -> 0 | AN8: =AN7 -> 65 | AO8: =(AN8/100)*3000 -> 1950 | AP8: =AP7 -> 55 | AQ8: =(AP8/100)*3000 -> 1650 | AR8: =AR7 -> 61 | AS8: =(AR8/100)*3000 -> 1830 | AT8: =SUM(AO8+AQ8+AS8) -> 5430 | AU8: =AT7-AT8+AV8 -> 0 | AX8: =IF(AV8>0,AW8,AX7) -> 0.8
A9: =ELEC!C8 -> 44597 | B9: =B8 -> 137 | C9: =C8 -> 145 | D9: =C8-C9 -> 0 | E9: =D9*8.38 -> 0 | F9: =F8 -> 2070 | G9: =F9-F8 -> 0 | H9: =H8 -> 30526 | I9: =SUM(H9-H8) -> 0 | J9: =IF(G9>0,I9/G9,0) -> 0 | K9: =K8 -> 2384 | L9: =K9-K8 -> 0 | M9: =M8 -> 176242 | N9: =M9-M8 -> 0 | O9: =O8 -> 1869 | P9: =P8 -> 2142 | Q9: =Q8 -> 179665 | R9: =Q9-Q8 -> 0 | S9: =SUM(P9-P8) -> 0 | T9: =SUM(S9*$T$2) -> 0 | U9: =SUM(G9+L9+S9) -> 0 | V9: =R9+N9+I9:I9 -> 0 | W9: =SUM(V9/U9) -> #DIV/0! | X9: =X8 -> 2471 | Y9: =X9-X8 -> 0 | Z9: =Z8 -> 1392127 | AA9: =Z9-Z8 -> 0 | AB9: =SUM(Y9*$AB$2) -> 0 | AC9: =AC8 -> 1943 | AD9: =AC9-AC8 -> 0 | AE9: =AE8 -> 366210 | AF9: =AE9-AE8 -> 0 | AG9: =IF(AD9>0,AF9/AD9,0) -> 0 | AH9: =AF9+AA9 -> 0 | AI9: =SUM(AH9+V9) -> 0 | AJ9: =-tanks!AW10 -> 0 | AK9: =SUM(AJ9-AI9) -> 0 | AL9: =S9+L9+G9 -> 0 | AM9: =Y9+AD9 -> 0 | AN9: =AN8 -> 65 | AO9: =(AN9/100)*3000 -> 1950 | AP9: =AP8 -> 55 | AQ9: =(AP9/100)*3000 -> 1650 | AR9: =AR8 -> 61 | AS9: =(AR9/100)*3000 -> 1830 | AT9: =SUM(AO9+AQ9+AS9) -> 5430 | AU9: =AT8-AT9+AV9 -> 0 | AX9: =IF(AV9>0,AW9,AX8) -> 0.8
A10: =ELEC!C9 -> 44598 | B10: 157 | C10: 163.5 | D10: =C9-C10 -> -18.5 | E10: =D10*8.38 -> -155.03 | F10: 2076 | G10: =F10-F9 -> 6 | H10: 30922 | I10: =SUM(H10-H9) -> 396 | J10: =IF(G10>0,I10/G10,0) -> 66 | K10: =K9 -> 2384 | L10: =K10-K9 -> 0 | M10: =M9 -> 176242 | N10: =M10-M9 -> 0 | O10: =O9 -> 1869 | P10: =P9 -> 2142 | Q10: =Q9 -> 179665 | R10: =Q10-Q9 -> 0 | S10: =SUM(P10-P9) -> 0 | T10: =SUM(S10*$T$2) -> 0 | U10: =SUM(G10+L10+S10) -> 6 | V10: =R10+N10+I10:I10 -> 396 | W10: =SUM(V10/U10) -> 66 | X10: =X9 -> 2471 | Y10: =X10-X9 -> 0 | Z10: =Z9 -> 1392127 | AA10: =Z10-Z9 -> 0 | AB10: =SUM(Y10*$AB$2) -> 0 | AC10: =AC9 -> 1943 | AD10: =AC10-AC9 -> 0 | AE10: =AE9 -> 366210 | AF10: =AE10-AE9 -> 0 | AG10: =IF(AD10>0,AF10/AD10,0) -> 0 | AH10: =AF10+AA10 -> 0 | AI10: =SUM(AH10+V10) -> 396 | AJ10: =-tanks!AW11 -> 396 | AK10: =SUM(AJ10-AI10) -> 0 | AL10: =S10+L10+G10 -> 6 | AM10: =Y10+AD10 -> 0 | AN10: =AN9 -> 65 | AO10: =(AN10/100)*3000 -> 1950 | AP10: =AP9 -> 55 | AQ10: =(AP10/100)*3000 -> 1650 | AR10: =AR9 -> 61 | AS10: =(AR10/100)*3000 -> 1830 | AT10: =SUM(AO10+AQ10+AS10) -> 5430 | AU10: =AT9-AT10+AV10 -> 0 | AX10: =IF(AV10>0,AW10,AX9) -> 0.8
A11: =ELEC!C10 -> 44599 | B11: =B10 -> 157 | C11: 165 | D11: =C10-C11 -> -1.5 | E11: =D11*8.38 -> -12.57 | F11: 2083 | G11: =F11-F10 -> 7 | H11: 31503 | I11: =SUM(H11-H10) -> 581 | J11: =IF(G11>0,I11/G11,0) -> 83 | K11: =K10 -> 2384 | L11: =K11-K10 -> 0 | M11: =M10 -> 176242 | N11: =M11-M10 -> 0 | O11: =O10 -> 1869 | P11: =P10 -> 2142 | Q11: =Q10 -> 179665 | R11: =Q11-Q10 -> 0 | S11: =SUM(P11-P10) -> 0 | T11: =SUM(S11*$T$2) -> 0 | U11: =SUM(G11+L11+S11) -> 7 | V11: =R11+N11+I11:I11 -> 581 | W11: =SUM(V11/U11) -> 83 | X11: =X10 -> 2471 | Y11: =X11-X10 -> 0 | Z11: =Z10 -> 1392127 | AA11: =Z11-Z10 -> 0 | AB11: =SUM(Y11*$AB$2) -> 0 | AC11: =AC10 -> 1943 | AD11: =AC11-AC10 -> 0 | AE11: =AE10 -> 366210 | AF11: =AE11-AE10 -> 0 | AG11: =IF(AD11>0,AF11/AD11,0) -> 0 | AH11: =AF11+AA11 -> 0 | AI11: =SUM(AH11+V11) -> 581 | AJ11: =-tanks!AW12 -> 581 | AK11: =SUM(AJ11-AI11) -> 0 | AL11: =S11+L11+G11 -> 7 | AM11: =Y11+AD11 -> 0 | AN11: =AN10 -> 65 | AO11: =(AN11/100)*3000 -> 1950 | AP11: =AP10 -> 55 | AQ11: =(AP11/100)*3000 -> 1650 | AR11: =AR10 -> 61 | AS11: =(AR11/100)*3000 -> 1830 | AT11: =SUM(AO11+AQ11+AS11) -> 5430 | AU11: =AT10-AT11+AV11 -> 0 | AX11: =IF(AV11>0,AW11,AX10) -> 0.8
A12: =ELEC!C11 -> 44600 | B12: =B11 -> 157 | C12: =C11 -> 165 | D12: =C11-C12 -> 0 | E12: =D12*8.38 -> 0 | F12: =F11 -> 2083 | G12: =F12-F11 -> 0 | H12: =H11 -> 31503 | I12: =SUM(H12-H11) -> 0 | J12: =IF(G12>0,I12/G12,0) -> 0 | K12: =K11 -> 2384 | L12: =K12-K11 -> 0 | M12: =M11 -> 176242 | N12: =M12-M11 -> 0 | O12: =O11 -> 1869 | P12: =P11 -> 2142 | Q12: =Q11 -> 179665 | R12: =Q12-Q11 -> 0 | S12: =SUM(P12-P11) -> 0 | T12: =SUM(S12*$T$2) -> 0 | U12: =SUM(G12+L12+S12) -> 0 | V12: =R12+N12+I12:I12 -> 0 | W12: =SUM(V12/U12) -> #DIV/0! | X12: =X11 -> 2471 | Y12: =X12-X11 -> 0 | Z12: =Z11 -> 1392127 | AA12: =Z12-Z11 -> 0 | AB12: =SUM(Y12*$AB$2) -> 0 | AC12: =AC11 -> 1943 | AD12: =AC12-AC11 -> 0 | AE12: =AE11 -> 366210 | AF12: =AE12-AE11 -> 0 | AG12: =IF(AD12>0,AF12/AD12,0) -> 0 | AH12: =AF12+AA12 -> 0 | AI12: =SUM(AH12+V12) -> 0 | AJ12: =-tanks!AW13 -> 0 | AK12: =SUM(AJ12-AI12) -> 0 | AL12: =S12+L12+G12 -> 0 | AM12: =Y12+AD12 -> 0 | AN12: =AN11 -> 65 | AO12: =(AN12/100)*3000 -> 1950 | AP12: =AP11 -> 55 | AQ12: =(AP12/100)*3000 -> 1650 | AR12: =AR11 -> 61 | AS12: =(AR12/100)*3000 -> 1830 | AT12: =SUM(AO12+AQ12+AS12) -> 5430 | AU12: =AT11-AT12+AV12 -> 0 | AX12: =IF(AV12>0,AW12,AX11) -> 0.8
A13: =ELEC!C12 -> 44601 | B13: 151 | C13: 158 | D13: =C12-C13 -> 7 | E13: =D13*8.38 -> 58.66 | F13: 2086 | G13: =F13-F12 -> 3 | H13: 31734 | I13: =SUM(H13-H12) -> 231 | J13: =IF(G13>0,I13/G13,0) -> 77 | K13: 2385 | L13: =K13-K12 -> 1 | M13: 176306 | N13: =M13-M12 -> 64 | O13: =O12 -> 1869 | P13: =P12 -> 2142 | Q13: =Q12 -> 179665 | R13: =Q13-Q12 -> 0 | S13: =SUM(P13-P12) -> 0 | T13: =SUM(S13*$T$2) -> 0 | U13: =SUM(G13+L13+S13) -> 4 | V13: =R13+N13+I13:I13 -> 295 | W13: =SUM(V13/U13) -> 73.75 | X13: =X12 -> 2471 | Y13: =X13-X12 -> 0 | Z13: =Z12 -> 1392127 | AA13: =Z13-Z12 -> 0 | AB13: =SUM(Y13*$AB$2) -> 0 | AC13: =AC12 -> 1943 | AD13: =AC13-AC12 -> 0 | AE13: =AE12 -> 366210 | AF13: =AE13-AE12 -> 0 | AG13: =IF(AD13>0,AF13/AD13,0) -> 0 | AH13: =AF13+AA13 -> 0 | AI13: =SUM(AH13+V13) -> 295 | AJ13: =-tanks!AW14 -> 295 | AK13: =SUM(AJ13-AI13) -> 0 | AL13: =S13+L13+G13 -> 4 | AM13: =Y13+AD13 -> 0 | AN13: =AN12 -> 65 | AO13: =(AN13/100)*3000 -> 1950 | AP13: =AP12 -> 55 | AQ13: =(AP13/100)*3000 -> 1650 | AR13: =AR12 -> 61 | AS13: =(AR13/100)*3000 -> 1830 | AT13: =SUM(AO13+AQ13+AS13) -> 5430 | AU13: =AT12-AT13+AV13 -> 0 | AX13: =IF(AV13>0,AW13,AX12) -> 0.8
A14: =ELEC!C13 -> 44602 | B14: 143 | C14: 150 | D14: =C13-C14 -> 8 | E14: =D14*8.38 -> 67.04 | F14: =F13 -> 2086 | G14: =F14-F13 -> 0 | H14: =H13 -> 31734 | I14: =SUM(H14-H13) -> 0 | J14: =IF(G14>0,I14/G14,0) -> 0 | K14: 2388 | L14: =K14-K13 -> 3 | M14: 176534 | N14: =M14-M13 -> 228 | O14: =O13 -> 1869 | P14: 2144 | Q14: 179872 | R14: =Q14-Q13 -> 207 | S14: =SUM(P14-P13) -> 2 | T14: =SUM(S14*$T$2) -> 0 | U14: =SUM(G14+L14+S14) -> 5 | V14: =R14+N14+I14:I14 -> 435 | W14: =SUM(V14/U14) -> 87 | X14: =X13 -> 2471 | Y14: =X14-X13 -> 0 | Z14: =Z13 -> 1392127 | AA14: =Z14-Z13 -> 0 | AB14: =SUM(Y14*$AB$2) -> 0 | AC14: =AC13 -> 1943 | AD14: =AC14-AC13 -> 0 | AE14: =AE13 -> 366210 | AF14: =AE14-AE13 -> 0 | AG14: =IF(AD14>0,AF14/AD14,0) -> 0 | AH14: =AF14+AA14 -> 0 | AI14: =SUM(AH14+V14) -> 435 | AJ14: =-tanks!AW15 -> 435 | AK14: =SUM(AJ14-AI14) -> 0 | AL14: =S14+L14+G14 -> 5 | AM14: =Y14+AD14 -> 0 | AN14: =AN13 -> 65 | AO14: =(AN14/100)*3000 -> 1950 | AP14: =AP13 -> 55 | AQ14: =(AP14/100)*3000 -> 1650 | AR14: =AR13 -> 61 | AS14: =(AR14/100)*3000 -> 1830 | AT14: =SUM(AO14+AQ14+AS14) -> 5430 | AU14: =AT13-AT14+AV14 -> 0 | AX14: =IF(AV14>0,AW14,AX13) -> 0.8
A15: =ELEC!C14 -> 44603 | B15: =B14 -> 143 | C15: =C14 -> 150 | D15: =C14-C15 -> 0 | E15: =D15*8.38 -> 0 | F15: =F14 -> 2086 | G15: =F15-F14 -> 0 | H15: =H14 -> 31734 | I15: =SUM(H15-H14) -> 0 | J15: =IF(G15>0,I15/G15,0) -> 0 | K15: =K14 -> 2388 | L15: =K15-K14 -> 0 | M15: =M14 -> 176534 | N15: =M15-M14 -> 0 | O15: =O14 -> 1869 | P15: =P14 -> 2144 | Q15: =Q14 -> 179872 | R15: =Q15-Q14 -> 0 | S15: =SUM(P15-P14) -> 0 | T15: =SUM(S15*$T$2) -> 0 | U15: =SUM(G15+L15+S15) -> 0 | V15: =R15+N15+I15:I15 -> 0 | W15: =SUM(V15/U15) -> #DIV/0! | X15: =X14 -> 2471 | Y15: =X15-X14 -> 0 | Z15: =Z14 -> 1392127 | AA15: =Z15-Z14 -> 0 | AB15: =SUM(Y15*$AB$2) -> 0 | AC15: =AC14 -> 1943 | AD15: =AC15-AC14 -> 0 | AE15: =AE14 -> 366210 | AF15: =AE15-AE14 -> 0 | AG15: =IF(AD15>0,AF15/AD15,0) -> 0 | AH15: =AF15+AA15 -> 0 | AI15: =SUM(AH15+V15) -> 0 | AJ15: =-tanks!AW16 -> 0 | AK15: =SUM(AJ15-AI15) -> 0 | AL15: =S15+L15+G15 -> 0 | AM15: =Y15+AD15 -> 0 | AN15: =AN14 -> 65 | AO15: =(AN15/100)*3000 -> 1950 | AP15: =AP14 -> 55 | AQ15: =(AP15/100)*3000 -> 1650 | AR15: =AR14 -> 61 | AS15: =(AR15/100)*3000 -> 1830 | AT15: =SUM(AO15+AQ15+AS15) -> 5430 | AU15: =AT14-AT15+AV15 -> 0 | AX15: =IF(AV15>0,AW15,AX14) -> 0.8
A16: =ELEC!C15 -> 44604 | B16: =B15 -> 143 | C16: =C15 -> 150 | D16: =C15-C16 -> 0 | E16: =D16*8.38 -> 0 | F16: =F15 -> 2086 | G16: =F16-F15 -> 0 | H16: =H15 -> 31734 | I16: =SUM(H16-H15) -> 0 | J16: =IF(G16>0,I16/G16,0) -> 0 | K16: =K15 -> 2388 | L16: =K16-K15 -> 0 | M16: =M15 -> 176534 | N16: =M16-M15 -> 0 | O16: =O15 -> 1869 | P16: =P15 -> 2144 | Q16: =Q15 -> 179872 | R16: =Q16-Q15 -> 0 | S16: =SUM(P16-P15) -> 0 | T16: =SUM(S16*$T$2) -> 0 | U16: =SUM(G16+L16+S16) -> 0 | V16: =R16+N16+I16:I16 -> 0 | W16: =SUM(V16/U16) -> #DIV/0! | X16: =X15 -> 2471 | Y16: =X16-X15 -> 0 | Z16: =Z15 -> 1392127 | AA16: =Z16-Z15 -> 0 | AB16: =SUM(Y16*$AB$2) -> 0 | AC16: =AC15 -> 1943 | AD16: =AC16-AC15 -> 0 | AE16: =AE15 -> 366210 | AF16: =AE16-AE15 -> 0 | AG16: =IF(AD16>0,AF16/AD16,0) -> 0 | AH16: =AF16+AA16 -> 0 | AI16: =SUM(AH16+V16) -> 0 | AJ16: =-tanks!AW17 -> 0 | AK16: =SUM(AJ16-AI16) -> 0 | AL16: =S16+L16+G16 -> 0 | AM16: =Y16+AD16 -> 0 | AN16: =AN15 -> 65 | AO16: =(AN16/100)*3000 -> 1950 | AP16: =AP15 -> 55 | AQ16: =(AP16/100)*3000 -> 1650 | AR16: =AR15 -> 61 | AS16: =(AR16/100)*3000 -> 1830 | AT16: =SUM(AO16+AQ16+AS16) -> 5430 | AU16: =AT15-AT16+AV16 -> 0 | AX16: =IF(AV16>0,AW16,AX15) -> 0.8
A17: =ELEC!C16 -> 44605 | B17: 169 | C17: 176 | D17: =C16-C17 -> -26 | E17: =D17*8.38 -> -217.88 | F17: =F16 -> 2086 | G17: =F17-F16 -> 0 | H17: =H16 -> 31734 | I17: =SUM(H17-H16) -> 0 | J17: =IF(G17>0,I17/G17,0) -> 0 | K17: 2390 | L17: =K17-K16 -> 2 | M17: 176670 | N17: =M17-M16 -> 136 | O17: =O16 -> 1869 | P17: 2150 | Q17: 180327 | R17: =Q17-Q16 -> 455 | S17: =SUM(P17-P16) -> 6 | T17: =SUM(S17*$T$2) -> 0 | U17: =SUM(G17+L17+S17) -> 8 | V17: =R17+N17+I17:I17 -> 591 | X17: =X16 -> 2471 | Y17: =X17-X16 -> 0 | Z17: =Z16 -> 1392127 | AA17: =Z17-Z16 -> 0 | AB17: =SUM(Y17*$AB$2) -> 0 | AC17: =AC16 -> 1943 | AD17: =AC17-AC16 -> 0 | AE17: =AE16 -> 366210 | AF17: =AE17-AE16 -> 0 | AG17: =IF(AD17>0,AF17/AD17,0) -> 0 | AH17: =AF17+AA17 -> 0 | AI17: =SUM(AH17+V17) -> 591 | AJ17: =-tanks!AW18 -> 591 | AK17: =SUM(AJ17-AI17) -> 0 | AL17: =S17+L17+G17 -> 8 | AM17: =Y17+AD17 -> 0 | AN17: =AN16 -> 65 | AO17: =(AN17/100)*3000 -> 1950 | AP17: =AP16 -> 55 | AQ17: =(AP17/100)*3000 -> 1650 | AR17: =AR16 -> 61 | AS17: =(AR17/100)*3000 -> 1830 | AT17: =SUM(AO17+AQ17+AS17) -> 5430 | AU17: =AT16-AT17+AV17 -> 0 | AX17: =IF(AV17>0,AW17,AX16) -> 0.8
A18: =ELEC!C17 -> 44606 | B18: 162 | C18: 169 | D18: =C17-C18 -> 7 | E18: =D18*8.38 -> 58.66 | F18: =F17 -> 2086 | G18: =F18-F17 -> 0 | H18: =H17 -> 31734 | I18: =SUM(H18-H17) -> 0 | J18: =IF(G18>0,I18/G18,0) -> 0 | K18: 2390 | L18: =K18-K17 -> 0 | M18: 176670 | N18: =M18-M17 -> 0 | O18: 1869 | P18: 2155 | Q18: 180657 | R18: =Q18-Q17 -> 330 | S18: =SUM(P18-P17) -> 5 | T18: =SUM(S18*$T$2) -> 0 | U18: =SUM(G18+L18+S18) -> 5 | V18: =R18+N18+I18:I18 -> 330 | X18: =X17 -> 2471 | Y18: =X18-X17 -> 0 | Z18: =Z17 -> 1392127 | AA18: =Z18-Z17 -> 0 | AB18: =SUM(Y18*$AB$2) -> 0 | AC18: =AC17 -> 1943 | AD18: =AC18-AC17 -> 0 | AE18: =AE17 -> 366210 | AF18: =AE18-AE17 -> 0 | AG18: =IF(AD18>0,AF18/AD18,0) -> 0 | AH18: =AF18+AA18 -> 0 | AI18: =SUM(AH18+V18) -> 330 | AJ18: =-tanks!AW19 -> 330 | AK18: =SUM(AJ18-AI18) -> 0 | AL18: =S18+L18+G18 -> 5 | AM18: =Y18+AD18 -> 0 | AN18: =AN17 -> 65 | AO18: =(AN18/100)*3000 -> 1950 | AP18: =AP17 -> 55 | AQ18: =(AP18/100)*3000 -> 1650 | AR18: =AR17 -> 61 | AS18: =(AR18/100)*3000 -> 1830 | AT18: =SUM(AO18+AQ18+AS18) -> 5430 | AU18: =AT17-AT18+AV18 -> 0 | AX18: =IF(AV18>0,AW18,AX17) -> 0.8
A19: =ELEC!C18 -> 44607 | B19: 155 | C19: 162 | D19: =C18-C19 -> 7 | E19: =D19*8.38 -> 58.66 | F19: =F18 -> 2086 | G19: =F19-F18 -> 0 | H19: =H18 -> 31734 | I19: =SUM(H19-H18) -> 0 | J19: =IF(G19>0,I19/G19,0) -> 0 | K19: =K18 -> 2390 | L19: =K19-K18 -> 0 | M19: =M18 -> 176670 | N19: =M19-M18 -> 0 | O19: =O18 -> 1869 | P19: 2159 | Q19: 180963 | R19: =Q19-Q18 -> 306 | S19: =SUM(P19-P18) -> 4 | T19: =SUM(S19*$T$2) -> 0 | U19: =SUM(G19+L19+S19) -> 4 | V19: =R19+N19+I19:I19 -> 306 | X19: =X18 -> 2471 | Y19: =X19-X18 -> 0 | Z19: =Z18 -> 1392127 | AA19: =Z19-Z18 -> 0 | AB19: =SUM(Y19*$AB$2) -> 0 | AC19: =AC18 -> 1943 | AD19: =AC19-AC18 -> 0 | AE19: =AE18 -> 366210 | AF19: =AE19-AE18 -> 0 | AG19: =IF(AD19>0,AF19/AD19,0) -> 0 | AH19: =AF19+AA19 -> 0 | AI19: =SUM(AH19+V19) -> 306 | AJ19: =-tanks!AW20 -> 306 | AK19: =SUM(AJ19-AI19) -> 0 | AL19: =S19+L19+G19 -> 4 | AM19: =Y19+AD19 -> 0 | AN19: =AN18 -> 65 | AO19: =(AN19/100)*3000 -> 1950 | AP19: =AP18 -> 55 | AQ19: =(AP19/100)*3000 -> 1650 | AR19: =AR18 -> 61 | AS19: =(AR19/100)*3000 -> 1830 | AT19: =SUM(AO19+AQ19+AS19) -> 5430 | AU19: =AT18-AT19+AV19 -> 0 | AX19: =IF(AV19>0,AW19,AX18) -> 0.8
A20: =ELEC!C19 -> 44608 | B20: 147 | C20: 155 | D20: =C19-C20 -> 7 | E20: =D20*8.38 -> 58.66 | F20: =F19 -> 2086 | G20: =F20-F19 -> 0 | H20: =H19 -> 31734 | I20: =SUM(H20-H19) -> 0 | J20: =IF(G20>0,I20/G20,0) -> 0 | K20: =K19 -> 2390 | L20: =K20-K19 -> 0 | M20: =M19 -> 176670 | N20: =M20-M19 -> 0 | O20: =O19 -> 1869 | P20: 2164 | Q20: 181570 | R20: =Q20-Q19 -> 607 | S20: =SUM(P20-P19) -> 5 | T20: =SUM(S20*$T$2) -> 0 | U20: =SUM(G20+L20+S20) -> 5 | V20: =R20+N20+I20:I20 -> 607 | X20: =X19 -> 2471 | Y20: =X20-X19 -> 0 | Z20: =Z19 -> 1392127 | AA20: =Z20-Z19 -> 0 | AB20: =SUM(Y20*$AB$2) -> 0 | AC20: =AC19 -> 1943 | AD20: =AC20-AC19 -> 0 | AE20: =AE19 -> 366210 | AF20: =AE20-AE19 -> 0 | AG20: =IF(AD20>0,AF20/AD20,0) -> 0 | AH20: =AF20+AA20 -> 0 | AI20: =SUM(AH20+V20) -> 607 | AJ20: =-tanks!AW21 -> 607 | AK20: =SUM(AJ20-AI20) -> 0 | AL20: =S20+L20+G20 -> 5 | AM20: =Y20+AD20 -> 0 | AN20: =AN19 -> 65 | AO20: =(AN20/100)*3000 -> 1950 | AP20: =AP19 -> 55 | AQ20: =(AP20/100)*3000 -> 1650 | AR20: =AR19 -> 61 | AS20: =(AR20/100)*3000 -> 1830 | AT20: =SUM(AO20+AQ20+AS20) -> 5430 | AU20: =AT19-AT20+AV20 -> 0 | AX20: =IF(AV20>0,AW20,AX19) -> 0.8
A21: =ELEC!C20 -> 44609 | B21: 179 | C21: 186 | D21: =C20-C21 -> -31 | E21: =D21*8.38 -> -259.78 | F21: =F20 -> 2086 | G21: =F21-F20 -> 0 | H21: =H20 -> 31734 | I21: =SUM(H21-H20) -> 0 | J21: =IF(G21>0,I21/G21,0) -> 0 | K21: =K20 -> 2390 | L21: =K21-K20 -> 0 | M21: =M20 -> 176670 | N21: =M21-M20 -> 0 | O21: =O20 -> 1869 | P21: 2167 | Q21: 181602 | R21: =Q21-Q20 -> 32 | S21: =SUM(P21-P20) -> 3 | T21: =SUM(S21*$T$2) -> 0 | U21: =SUM(G21+L21+S21) -> 3 | V21: =R21+N21+I21:I21 -> 32 | X21: =X20 -> 2471 | Y21: =X21-X20 -> 0 | Z21: =Z20 -> 1392127 | AA21: =Z21-Z20 -> 0 | AB21: =SUM(Y21*$AB$2) -> 0 | AC21: =AC20 -> 1943 | AD21: =AC21-AC20 -> 0 | AE21: =AE20 -> 366210 | AF21: =AE21-AE20 -> 0 | AG21: =IF(AD21>0,AF21/AD21,0) -> 0 | AH21: =AF21+AA21 -> 0 | AI21: =SUM(AH21+V21) -> 32 | AJ21: =-tanks!AW22 -> 32 | AK21: =SUM(AJ21-AI21) -> 0 | AL21: =S21+L21+G21 -> 3 | AM21: =Y21+AD21 -> 0 | AN21: =AN20 -> 65 | AO21: =(AN21/100)*3000 -> 1950 | AP21: =AP20 -> 55 | AQ21: =(AP21/100)*3000 -> 1650 | AR21: =AR20 -> 61 | AS21: =(AR21/100)*3000 -> 1830 | AT21: =SUM(AO21+AQ21+AS21) -> 5430 | AU21: =AT20-AT21+AV21 -> 0 | AX21: =IF(AV21>0,AW21,AX20) -> 0.8
A22: =ELEC!C21 -> 44610 | B22: =B21 -> 179 | C22: =C21 -> 186 | D22: =C21-C22 -> 0 | E22: =D22*8.38 -> 0 | F22: =F21 -> 2086 | G22: =F22-F21 -> 0 | H22: =H21 -> 31734 | I22: =SUM(H22-H21) -> 0 | J22: =IF(G22>0,I22/G22,0) -> 0 | K22: =K21 -> 2390 | L22: =K22-K21 -> 0 | M22: =M21 -> 176670 | N22: =M22-M21 -> 0 | O22: =O21 -> 1869 | P22: =P21 -> 2167 | Q22: =Q21 -> 181602 | R22: =Q22-Q21 -> 0 | S22: =SUM(P22-P21) -> 0 | T22: =SUM(S22*$T$2) -> 0 | U22: =SUM(G22+L22+S22) -> 0 | V22: =R22+N22+I22:I22 -> 0 | X22: =X21 -> 2471 | Y22: =X22-X21 -> 0 | Z22: =Z21 -> 1392127 | AA22: =Z22-Z21 -> 0 | AB22: =SUM(Y22*$AB$2) -> 0 | AC22: =AC21 -> 1943 | AD22: =AC22-AC21 -> 0 | AE22: =AE21 -> 366210 | AF22: =AE22-AE21 -> 0 | AG22: =IF(AD22>0,AF22/AD22,0) -> 0 | AH22: =AF22+AA22 -> 0 | AI22: =SUM(AH22+V22) -> 0 | AJ22: =-tanks!AW23 -> 0 | AK22: =SUM(AJ22-AI22) -> 0 | AL22: =S22+L22+G22 -> 0 | AM22: =Y22+AD22 -> 0 | AN22: =AN21 -> 65 | AO22: =(AN22/100)*3000 -> 1950 | AP22: =AP21 -> 55 | AQ22: =(AP22/100)*3000 -> 1650 | AR22: =AR21 -> 61 | AS22: =(AR22/100)*3000 -> 1830 | AT22: =SUM(AO22+AQ22+AS22) -> 5430 | AU22: =AT21-AT22+AV22 -> 0 | AX22: =IF(AV22>0,AW22,AX21) -> 0.8
A23: =ELEC!C22 -> 44611 | B23: =B22 -> 179 | C23: =C22 -> 186 | D23: =C22-C23 -> 0 | E23: =D23*8.38 -> 0 | F23: =F22 -> 2086 | G23: =F23-F22 -> 0 | H23: =H22 -> 31734 | I23: =SUM(H23-H22) -> 0 | J23: =IF(G23>0,I23/G23,0) -> 0 | K23: =K22 -> 2390 | L23: =K23-K22 -> 0 | M23: =M22 -> 176670 | N23: =M23-M22 -> 0 | O23: =O22 -> 1869 | P23: =P22 -> 2167 | Q23: =Q22 -> 181602 | R23: =Q23-Q22 -> 0 | S23: =SUM(P23-P22) -> 0 | T23: =SUM(S23*$T$2) -> 0 | U23: =SUM(G23+L23+S23) -> 0 | V23: =R23+N23+I23:I23 -> 0 | X23: =X22 -> 2471 | Y23: =X23-X22 -> 0 | Z23: =Z22 -> 1392127 | AA23: =Z23-Z22 -> 0 | AB23: =SUM(Y23*$AB$2) -> 0 | AC23: =AC22 -> 1943 | AD23: =AC23-AC22 -> 0 | AE23: =AE22 -> 366210 | AF23: =AE23-AE22 -> 0 | AG23: =IF(AD23>0,AF23/AD23,0) -> 0 | AH23: =AF23+AA23 -> 0 | AI23: =SUM(AH23+V23) -> 0 | AJ23: =-tanks!AW24 -> 0 | AK23: =SUM(AJ23-AI23) -> 0 | AL23: =S23+L23+G23 -> 0 | AM23: =Y23+AD23 -> 0 | AN23: =AN22 -> 65 | AO23: =(AN23/100)*3000 -> 1950 | AP23: =AP22 -> 55 | AQ23: =(AP23/100)*3000 -> 1650 | AR23: =AR22 -> 61 | AS23: =(AR23/100)*3000 -> 1830 | AT23: =SUM(AO23+AQ23+AS23) -> 5430 | AU23: =AT22-AT23+AV23 -> 0 | AX23: =IF(AV23>0,AW23,AX22) -> 0.8
A24: =ELEC!C23 -> 44612 | B24: =B23 -> 179 | C24: =C23 -> 186 | D24: =C23-C24 -> 0 | E24: =D24*8.38 -> 0 | F24: =F23 -> 2086 | G24: =F24-F23 -> 0 | H24: =H23 -> 31734 | I24: =SUM(H24-H23) -> 0 | J24: =IF(G24>0,I24/G24,0) -> 0 | K24: =K23 -> 2390 | L24: =K24-K23 -> 0 | M24: =M23 -> 176670 | N24: =M24-M23 -> 0 | O24: =O23 -> 1869 | P24: =P23 -> 2167 | Q24: =Q23 -> 181602 | R24: =Q24-Q23 -> 0 | S24: =SUM(P24-P23) -> 0 | T24: =SUM(S24*$T$2) -> 0 | U24: =SUM(G24+L24+S24) -> 0 | V24: =R24+N24+I24:I24 -> 0 | X24: =X23 -> 2471 | Y24: =X24-X23 -> 0 | Z24: =Z23 -> 1392127 | AA24: =Z24-Z23 -> 0 | AB24: =SUM(Y24*$AB$2) -> 0 | AC24: =AC23 -> 1943 | AD24: =AC24-AC23 -> 0 | AE24: =AE23 -> 366210 | AF24: =AE24-AE23 -> 0 | AG24: =IF(AD24>0,AF24/AD24,0) -> 0 | AH24: =AF24+AA24 -> 0 | AI24: =SUM(AH24+V24) -> 0 | AJ24: =-tanks!AW25 -> 0 | AK24: =SUM(AJ24-AI24) -> 0 | AL24: =S24+L24+G24 -> 0 | AM24: =Y24+AD24 -> 0 | AN24: =AN23 -> 65 | AO24: =(AN24/100)*3000 -> 1950 | AP24: =AP23 -> 55 | AQ24: =(AP24/100)*3000 -> 1650 | AR24: =AR23 -> 61 | AS24: =(AR24/100)*3000 -> 1830 | AT24: =SUM(AO24+AQ24+AS24) -> 5430 | AU24: =AT23-AT24+AV24 -> 0 | AX24: =IF(AV24>0,AW24,AX23) -> 0.8
A25: =ELEC!C24 -> 44613 | B25: =B24 -> 179 | C25: =C24 -> 186 | D25: =C24-C25 -> 0 | E25: =D25*8.38 -> 0 | F25: =F24 -> 2086 | G25: =F25-F24 -> 0 | H25: =H24 -> 31734 | I25: =SUM(H25-H24) -> 0 | J25: =IF(G25>0,I25/G25,0) -> 0 | K25: =K24 -> 2390 | L25: =K25-K24 -> 0 | M25: =M24 -> 176670 | N25: =M25-M24 -> 0 | O25: =O24 -> 1869 | P25: =P24 -> 2167 | Q25: =Q24 -> 181602 | R25: =Q25-Q24 -> 0 | S25: =SUM(P25-P24) -> 0 | T25: =SUM(S25*$T$2) -> 0 | U25: =SUM(G25+L25+S25) -> 0 | V25: =R25+N25+I25:I25 -> 0 | X25: =X24 -> 2471 | Y25: =X25-X24 -> 0 | Z25: =Z24 -> 1392127 | AA25: =Z25-Z24 -> 0 | AB25: =SUM(Y25*$AB$2) -> 0 | AC25: =AC24 -> 1943 | AD25: =AC25-AC24 -> 0 | AE25: =AE24 -> 366210 | AF25: =AE25-AE24 -> 0 | AG25: =IF(AD25>0,AF25/AD25,0) -> 0 | AH25: =AF25+AA25 -> 0 | AI25: =SUM(AH25+V25) -> 0 | AJ25: =-tanks!AW26 -> 0 | AK25: =SUM(AJ25-AI25) -> 0 | AL25: =S25+L25+G25 -> 0 | AM25: =Y25+AD25 -> 0 | AN25: =AN24 -> 65 | AO25: =(AN25/100)*3000 -> 1950 | AP25: =AP24 -> 55 | AQ25: =(AP25/100)*3000 -> 1650 | AR25: =AR24 -> 61 | AS25: =(AR25/100)*3000 -> 1830 | AT25: =SUM(AO25+AQ25+AS25) -> 5430 | AU25: =AT24-AT25+AV25 -> 0 | AX25: =IF(AV25>0,AW25,AX24) -> 0.8
A26: =ELEC!C25 -> 44614 | B26: =B25 -> 179 | C26: =C25 -> 186 | D26: =C25-C26 -> 0 | E26: =D26*8.38 -> 0 | F26: =F25 -> 2086 | G26: =F26-F25 -> 0 | H26: =H25 -> 31734 | I26: =SUM(H26-H25) -> 0 | J26: =IF(G26>0,I26/G26,0) -> 0 | K26: =K25 -> 2390 | L26: =K26-K25 -> 0 | M26: =M25 -> 176670 | N26: =M26-M25 -> 0 | O26: =O25 -> 1869 | P26: =P25 -> 2167 | Q26: =Q25 -> 181602 | R26: =Q26-Q25 -> 0 | S26: =SUM(P26-P25) -> 0 | T26: =SUM(S26*$T$2) -> 0 | U26: =SUM(G26+L26+S26) -> 0 | V26: =R26+N26+I26:I26 -> 0 | X26: =X25 -> 2471 | Y26: =X26-X25 -> 0 | Z26: =Z25 -> 1392127 | AA26: =Z26-Z25 -> 0 | AB26: =SUM(Y26*$AB$2) -> 0 | AC26: =AC25 -> 1943 | AD26: =AC26-AC25 -> 0 | AE26: =AE25 -> 366210 | AF26: =AE26-AE25 -> 0 | AG26: =IF(AD26>0,AF26/AD26,0) -> 0 | AH26: =AF26+AA26 -> 0 | AI26: =SUM(AH26+V26) -> 0 | AJ26: =-tanks!AW27 -> 0 | AK26: =SUM(AJ26-AI26) -> 0 | AL26: =S26+L26+G26 -> 0 | AM26: =Y26+AD26 -> 0 | AN26: =AN25 -> 65 | AO26: =(AN26/100)*3000 -> 1950 | AP26: =AP25 -> 55 | AQ26: =(AP26/100)*3000 -> 1650 | AR26: =AR25 -> 61 | AS26: =(AR26/100)*3000 -> 1830 | AT26: =SUM(AO26+AQ26+AS26) -> 5430 | AU26: =AT25-AT26+AV26 -> 0 | AX26: =IF(AV26>0,AW26,AX25) -> 0.8
A27: =ELEC!C26 -> 44615 | B27: =B26 -> 179 | C27: =C26 -> 186 | D27: =C26-C27 -> 0 | E27: =D27*8.38 -> 0 | F27: =F26 -> 2086 | G27: =F27-F26 -> 0 | H27: =H26 -> 31734 | I27: =SUM(H27-H26) -> 0 | J27: =IF(G27>0,I27/G27,0) -> 0 | K27: =K26 -> 2390 | L27: =K27-K26 -> 0 | M27: =M26 -> 176670 | N27: =M27-M26 -> 0 | O27: =O26 -> 1869 | P27: =P26 -> 2167 | Q27: =Q26 -> 181602 | R27: =Q27-Q26 -> 0 | S27: =SUM(P27-P26) -> 0 | T27: =SUM(S27*$T$2) -> 0 | U27: =SUM(G27+L27+S27) -> 0 | V27: =R27+N27+I27:I27 -> 0 | X27: =X26 -> 2471 | Y27: =X27-X26 -> 0 | Z27: =Z26 -> 1392127 | AA27: =Z27-Z26 -> 0 | AB27: =SUM(Y27*$AB$2) -> 0 | AC27: =AC26 -> 1943 | AD27: =AC27-AC26 -> 0 | AE27: =AE26 -> 366210 | AF27: =AE27-AE26 -> 0 | AG27: =IF(AD27>0,AF27/AD27,0) -> 0 | AH27: =AF27+AA27 -> 0 | AI27: =SUM(AH27+V27) -> 0 | AJ27: =-tanks!AW28 -> 0 | AK27: =SUM(AJ27-AI27) -> 0 | AL27: =S27+L27+G27 -> 0 | AM27: =Y27+AD27 -> 0 | AN27: =AN26 -> 65 | AO27: =(AN27/100)*3000 -> 1950 | AP27: =AP26 -> 55 | AQ27: =(AP27/100)*3000 -> 1650 | AR27: =AR26 -> 61 | AS27: =(AR27/100)*3000 -> 1830 | AT27: =SUM(AO27+AQ27+AS27) -> 5430 | AU27: =AT26-AT27+AV27 -> 0 | AX27: =IF(AV27>0,AW27,AX26) -> 0.8
A28: =ELEC!C27 -> 44616 | B28: =B27 -> 179 | C28: =C27 -> 186 | D28: =C27-C28 -> 0 | E28: =D28*8.38 -> 0 | F28: =F27 -> 2086 | G28: =F28-F27 -> 0 | H28: =H27 -> 31734 | I28: =SUM(H28-H27) -> 0 | J28: =IF(G28>0,I28/G28,0) -> 0 | K28: =K27 -> 2390 | L28: =K28-K27 -> 0 | M28: =M27 -> 176670 | N28: =M28-M27 -> 0 | O28: =O27 -> 1869 | P28: =P27 -> 2167 | Q28: =Q27 -> 181602 | R28: =Q28-Q27 -> 0 | S28: =SUM(P28-P27) -> 0 | T28: =SUM(S28*$T$2) -> 0 | U28: =SUM(G28+L28+S28) -> 0 | V28: =R28+N28+I28:I28 -> 0 | X28: =X27 -> 2471 | Y28: =X28-X27 -> 0 | Z28: =Z27 -> 1392127 | AA28: =Z28-Z27 -> 0 | AB28: =SUM(Y28*$AB$2) -> 0 | AC28: =AC27 -> 1943 | AD28: =AC28-AC27 -> 0 | AE28: =AE27 -> 366210 | AF28: =AE28-AE27 -> 0 | AG28: =IF(AD28>0,AF28/AD28,0) -> 0 | AH28: =AF28+AA28 -> 0 | AI28: =SUM(AH28+V28) -> 0 | AJ28: =-tanks!AW29 -> 0 | AK28: =SUM(AJ28-AI28) -> 0 | AL28: =S28+L28+G28 -> 0 | AM28: =Y28+AD28 -> 0 | AN28: =AN27 -> 65 | AO28: =(AN28/100)*3000 -> 1950 | AP28: =AP27 -> 55 | AQ28: =(AP28/100)*3000 -> 1650 | AR28: =AR27 -> 61 | AS28: =(AR28/100)*3000 -> 1830 | AT28: =SUM(AO28+AQ28+AS28) -> 5430 | AU28: =AT27-AT28+AV28 -> 0 | AX28: =IF(AV28>0,AW28,AX27) -> 0.8
