Workbook

Sheet TOTAL
A1: Site Name | B1: Day | C1: Month | D1: Year | E1: Total Electricity Kwh | F1: Electricity Tariff ($/Kwh) | G1: LPG (Kg) | H1: LPG $/Kg | I1: Water Utility Supply (m3) m3 | J1: Water Utility Supply (m3) $/m3 | K1: Room Nights | L1: Food Covers
A2: Maldives at Landaa Giraavaru | B2: 1 | C2: 2 | D2: 2022 | E2: ='Maldives at LG Daily'!D5 -> 5659000 | F2: 0.93 | G2: ='Maldives at LG Daily'!F5 -> 315 | H2: 1.24 | I2: ='Maldives at LG Daily'!H5 -> 468 | J2: 2.16 | K2: ='Maldives at LG Daily'!I5 -> 60 | L2: ='Maldives at LG Daily'!J5 -> 487
A3: Maldives at Landaa Giraavaru | B3: =B2+1 -> 2 | C3: 2 | D3: 2022 | E3: ='Maldives at LG Daily'!D6 -> 29643 | F3: 0.93 | G3: ='Maldives at LG Daily'!F6 -> 0 | H3: 1.24 | I3: ='Maldives at LG Daily'!H6 -> 447 | J3: 2.16 | K3: ='Maldives at LG Daily'!I6 -> 0 | L3: ='Maldives at LG Daily'!J6 -> 0
A4: Maldives at Landaa Giraavaru | B4: =B3+1 -> 3 | C4: 2 | D4: 2022 | E4: ='Maldives at LG Daily'!D7 -> 0 | F4: 0.93 | G4: ='Maldives at LG Daily'!F7 -> 0 | H4: 1.24 | I4: ='Maldives at LG Daily'!H7 -> 416 | J4: 2.16 | K4: ='Maldives at LG Daily'!I7 -> 0 | L4: ='Maldives at LG Daily'!J7 -> 0
A5: Maldives at Landaa Giraavaru | B5: =B4+1 -> 4 | C5: 2 | D5: 2022 | E5: ='Maldives at LG Daily'!D8 -> 0 | F5: 0.93 | G5: ='Maldives at LG Daily'!F8 -> 0 | H5: 1.24 | I5: ='Maldives at LG Daily'!H8 -> 0 | J5: 2.16 | K5: ='Maldives at LG Daily'!I8 -> 0 | L5: ='Maldives at LG Daily'!J8 -> 0
A6: Maldives at Landaa Giraavaru | B6: =B5+1 -> 5 | C6: 2 | D6: 2022 | E6: ='Maldives at LG Daily'!D9 -> 0 | F6: 0.93 | G6: ='Maldives at LG Daily'!F9 -> 0 | H6: 1.24 | I6: ='Maldives at LG Daily'!H9 -> 0 | J6: 2.16 | K6: ='Maldives at LG Daily'!I9 -> 0 | L6: ='Maldives at LG Daily'!J9 -> 0
A7: Maldives at Landaa Giraavaru | B7: =B6+1 -> 6 | C7: 2 | D7: 2022 | E7: ='Maldives at LG Daily'!D10 -> 0 | F7: 0.93 | G7: ='Maldives at LG Daily'!F10 -> 0 | H7: 1.24 | I7: ='Maldives at LG Daily'!H10 -> 0 | J7: 2.16 | K7: ='Maldives at LG Daily'!I10 -> 0 | L7: ='Maldives at LG Daily'!J10 -> 0
A8: Maldives at Landaa Giraavaru | B8: =B7+1 -> 7 | C8: 2 | D8: 2022 | E8: ='Maldives at LG Daily'!D11 -> 0 | F8: 0.93 | G8: ='Maldives at LG Daily'!F11 -> 0 | H8: 1.24 | I8: ='Maldives at LG Daily'!H11 -> 0 | J8: 2.16 | K8: ='Maldives at LG Daily'!I11 -> 0 | L8: ='Maldives at LG Daily'!J11 -> 0
A9: Maldives at Landaa Giraavaru | B9: =B8+1 -> 8 | C9: 2 | D9: 2022 | E9: ='Maldives at LG Daily'!D12 -> 0 | F9: 0.93 | G9: ='Maldives at LG Daily'!F12 -> 0 | H9: 1.24 | I9: ='Maldives at LG Daily'!H12 -> 0 | J9: 2.16 | K9: ='Maldives at LG Daily'!I12 -> 0 | L9: ='Maldives at LG Daily'!J12 -> 0
A10: Maldives at Landaa Giraavaru | B10: =B9+1 -> 9 | C10: 2 | D10: 2022 | E10: ='Maldives at LG Daily'!D13 -> 0 | F10: 0.93 | G10: ='Maldives at LG Daily'!F13 -> 0 | H10: 1.24 | I10: ='Maldives at LG Daily'!H13 -> 0 | J10: 2.16 | K10: ='Maldives at LG Daily'!I13 -> 0 | L10: ='Maldives at LG Daily'!J13 -> 0
A11: Maldives at Landaa Giraavaru | B11: =B10+1 -> 10 | C11: 2 | D11: 2022 | E11: ='Maldives at LG Daily'!D14 -> 0 | F11: 0.93 | G11: ='Maldives at LG Daily'!F14 -> 0 | H11: 1.24 | I11: ='Maldives at LG Daily'!H14 -> 0 | J11: 2.16 | K11: ='Maldives at LG Daily'!I14 -> 0 | L11: ='Maldives at LG Daily'!J14 -> 0
A12: Maldives at Landaa Giraavaru | B12: =B11+1 -> 11 | C12: 2 | D12: 2022 | E12: ='Maldives at LG Daily'!D15 -> 0 | F12: 0.93 | G12: ='Maldives at LG Daily'!F15 -> 0 | H12: 1.24 | I12: ='Maldives at LG Daily'!H15 -> 0 | J12: 2.16 | K12: ='Maldives at LG Daily'!I15 -> 0 | L12: ='Maldives at LG Daily'!J15 -> 0
A13: Maldives at Landaa Giraavaru | B13: =B12+1 -> 12 | C13: 2 | D13: 2022 | E13: ='Maldives at LG Daily'!D16 -> 0 | F13: 0.93 | G13: ='Maldives at LG Daily'!F16 -> 0 | H13: 1.24 | I13: ='Maldives at LG Daily'!H16 -> 0 | J13: 2.16 | K13: ='Maldives at LG Daily'!I16 -> 0 | L13: ='Maldives at LG Daily'!J16 -> 0
A14: Maldives at Landaa Giraavaru | B14: =B13+1 -> 13 | C14: 2 | D14: 2022 | E14: ='Maldives at LG Daily'!D17 -> 0 | F14: 0.93 | G14: ='Maldives at LG Daily'!F17 -> 0 | H14: 1.24 | I14: ='Maldives at LG Daily'!H17 -> 0 | J14: 2.16 | K14: ='Maldives at LG Daily'!I17 -> 0 | L14: ='Maldives at LG Daily'!J17 -> 0
... A30: Maldives at Landaa Giraavaru | B30: =B29+1 -> 29 | C30: 2 | D30: 2022 | E30: ='Maldives at LG Daily'!D33 -> 0 | F30: 0.93 | G30: ='Maldives at LG Daily'!F33 -> 0 | H30: 1.24 | I30: ='Maldives at LG Daily'!H33 -> 0 | J30: 2.16 | K30: ='Maldives at LG Daily'!I33 -> 0 | L30: ='Maldives at LG Daily'!J33 -> 0
A31: Maldives at Landaa Giraavaru | B31: 30 | C31: 2 | D31: 2022 | E31: ='Maldives at LG Daily'!D34 -> 0 | F31: 0.93 | G31: ='Maldives at LG Daily'!F34 -> 0 | H31: 1.24 | I31: ='Maldives at LG Daily'!H34 -> 0 | J31: 2.16 | K31: ='Maldives at LG Daily'!I34 -> 0 | L31: ='Maldives at LG Daily'!J34 -> 0
A32: Maldives at Landaa Giraavaru | B32: 31 | C32: 2 | D32: 2022 | E32: ='Maldives at LG Daily'!D35 -> 0 | F32: 0.93 | G32: ='Maldives at LG Daily'!F35 -> 0 | H32: 1.24 | I32: ='Maldives at LG Daily'!H35 -> 0 | J32: 2.16 | K32: ='Maldives at LG Daily'!I35 -> 0 | L32: ='Maldives at LG Daily'!J35 -> 0

Sheet Maldives at LG Daily
A2: Days | C2: Electricity Meter (KWh) | E2: Gas Kg | G2: Water m3
A3: Date | C3: Reading KWH | D3: Difference KWH | E3: Reading Kg | F3: Difference Kg | G3: Reading m³ | H3: Daily Consumption m³ | I3: ROOM NIGHTS | J3: Total Food Covers
A4: 44592 | C4: ='[1]Maldives at LG Daily'!$C$35 -> 92090395 | D4: 26752 | E4: ='Gas-2'!G5 -> 0 | F4: 90 | G4: =SUM(WATER!G6,WATER!L6,WATER!Q6,WATER!B6) -> 1067002 | H4: 423 | I4: 58 | J4: 498
A5: =A4+1 -> 44593 | C5: =SUM('GENSET #1'!C10+'GENSET #2'!C10+'GENSET #3'!C10+'GENSET #4'!C10+'GENSET #5'!C10) -> 97749395 | D5: =IF((C5-C4<0), "0",C5-C4) -> 5659000 | E5: ='Gas-2'!G6 -> 315 | F5: =IF((E5-E4<0), "0",E5-E4) -> 315 | G5: =SUM(WATER!C6,WATER!H6,WATER!M6,WATER!R6) -> 1067470 | H5: =IF((G5-G4<0), "0",G5-G4) -> 468 | I5: 60 | J5: 487
A6: =A5+1 -> 44594 | C6: =SUM('GENSET #1'!C11+'GENSET #2'!C11+'GENSET #3'!C11+'GENSET #4'!C11+'GENSET #5'!C11) -> 97779038 | D6: =IF((C6-C5<0), "0",C6-C5) -> 29643 | E6: ='Gas-2'!G7 -> 0 | F6: =IF((E6-E5<0), "0",E6-E5) -> 0 | G6: =SUM(WATER!C7,WATER!H7,WATER!M7,WATER!R7) -> 1067917 | H6: =IF((G6-G5<0), "0",G6-G5) -> 447
A7: =A6+1 -> 44595 | C7: =SUM('GENSET #1'!C12+'GENSET #2'!C12+'GENSET #3'!C12+'GENSET #4'!C12+'GENSET #5'!C12) -> 0 | D7: =IF((C7-C6<0), "0",C7-C6) -> 0 | E7: ='Gas-2'!G8 -> 0 | F7: =IF((E7-E6<0), "0",E7-E6) -> 0 | G7: =SUM(WATER!C8,WATER!H8,WATER!M8,WATER!R8) -> 1068333 | H7: =IF((G7-G6<0), "0",G7-G6) -> 416
A8: =A7+1 -> 44596 | C8: =SUM('GENSET #1'!C13+'GENSET #2'!C13+'GENSET #3'!C13+'GENSET #4'!C13+'GENSET #5'!C13) -> 0 | D8: =IF((C8-C7<0), "0",C8-C7) -> 0 | E8: ='Gas-2'!G9 -> 0 | F8: =IF((E8-E7<0), "0",E8-E7) -> 0 | G8: =SUM(WATER!C9,WATER!H9,WATER!M9,WATER!R9) -> 0 | H8: =IF((G8-G7<0), "0",G8-G7) -> 0
A9: =A8+1 -> 44597 | C9: =SUM('GENSET #1'!C14+'GENSET #2'!C14+'GENSET #3'!C14+'GENSET #4'!C14+'GENSET #5'!C14) -> 0 | D9: =IF((C9-C8<0), "0",C9-C8) -> 0 | E9: ='Gas-2'!G10 -> 0 | F9: =IF((E9-E8<0), "0",E9-E8) -> 0 | G9: =SUM(WATER!C10,WATER!H10,WATER!M10,WATER!R10) -> 0 | H9: =IF((G9-G8<0), "0",G9-G8) -> 0
A10: =A9+1 -> 44598 | C10: =SUM('GENSET #1'!C15+'GENSET #2'!C15+'GENSET #3'!C15+'GENSET #4'!C15+'GENSET #5'!C15) -> 0 | D10: =IF((C10-C9<0), "0",C10-C9) -> 0 | E10: ='Gas-2'!G11 -> 0 | F10: =IF((E10-E9<0), "0",E10-E9) -> 0 | G10: =SUM(WATER!C11,WATER!H11,WATER!M11,WATER!R11) -> 0 | H10: =IF((G10-G9<0), "0",G10-G9) -> 0
A11: =A10+1 -> 44599 | C11: =SUM('GENSET #1'!C16+'GENSET #2'!C16+'GENSET #3'!C16+'GENSET #4'!C16+'GENSET #5'!C16) -> 0 | D11: =IF((C11-C10<0), "0",C11-C10) -> 0 | E11: ='Gas-2'!G12 -> 0 | F11: =IF((E11-E10<0), "0",E11-E10) -> 0 | G11: =SUM(WATER!C12,WATER!H12,WATER!M12,WATER!R12) -> 0 | H11: =IF((G11-G10<0), "0",G11-G10) -> 0
A12: =A11+1 -> 44600 | C12: =SUM('GENSET #1'!C17+'GENSET #2'!C17+'GENSET #3'!C17+'GENSET #4'!C17+'GENSET #5'!C17) -> 0 | D12: =IF((C12-C11<0), "0",C12-C11) -> 0 | E12: ='Gas-2'!G13 -> 0 | F12: =IF((E12-E11<0), "0",E12-E11) -> 0 | G12: =SUM(WATER!C13,WATER!H13,WATER!M13,WATER!R13) -> 0 | H12: =IF((G12-G11<0), "0",G12-G11) -> 0
A13: =A12+1 -> 44601 | C13: =SUM('GENSET #1'!C18+'GENSET #2'!C18+'GENSET #3'!C18+'GENSET #4'!C18+'GENSET #5'!C18) -> 0 | D13: =IF((C13-C12<0), "0",C13-C12) -> 0 | E13: ='Gas-2'!G14 -> 0 | F13: =IF((E13-E12<0), "0",E13-E12) -> 0 | G13: =SUM(WATER!C14,WATER!H14,WATER!M14,WATER!R14) -> 0 | H13: =IF((G13-G12<0), "0",G13-G12) -> 0
A14: =A13+1 -> 44602 | C14: =SUM('GENSET #1'!C19+'GENSET #2'!C19+'GENSET #3'!C19+'GENSET #4'!C19+'GENSET #5'!C19) -> 0 | D14: =IF((C14-C13<0), "0",C14-C13) -> 0 | E14: ='Gas-2'!G15 -> 0 | F14: =IF((E14-E13<0), "0",E14-E13) -> 0 | G14: =SUM(WATER!C15,WATER!H15,WATER!M15,WATER!R15) -> 0 | H14: =IF((G14-G13<0), "0",G14-G13) -> 0
A15: =A14+1 -> 44603 | C15: =SUM('GENSET #1'!C20+'GENSET #2'!C20+'GENSET #3'!C20+'GENSET #4'!C20+'GENSET #5'!C20) -> 0 | D15: =IF((C15-C14<0), "0",C15-C14) -> 0 | E15: ='Gas-2'!G16 -> 0 | F15: =IF((E15-E14<0), "0",E15-E14) -> 0 | G15: =SUM(WATER!C16,WATER!H16,WATER!M16,WATER!R16) -> 0 | H15: =IF((G15-G14<0), "0",G15-G14) -> 0
A16: =A15+1 -> 44604 | C16: =SUM('GENSET #1'!C21+'GENSET #2'!C21+'GENSET #3'!C21+'GENSET #4'!C21+'GENSET #5'!C21) -> 0 | D16: =IF((C16-C15<0), "0",C16-C15) -> 0 | E16: ='Gas-2'!G17 -> 0 | F16: =IF((E16-E15<0), "0",E16-E15) -> 0 | G16: =SUM(WATER!C17,WATER!H17,WATER!M17,WATER!R17) -> 0 | H16: =IF((G16-G15<0), "0",G16-G15) -> 0
A17: =A16+1 -> 44605 | C17: =SUM('GENSET #1'!C22+'GENSET #2'!C22+'GENSET #3'!C22+'GENSET #4'!C22+'GENSET #5'!C22) -> 0 | D17: =IF((C17-C16<0), "0",C17-C16) -> 0 | E17: ='Gas-2'!G18 -> 0 | F17: =IF((E17-E16<0), "0",E17-E16) -> 0 | G17: =SUM(WATER!C18,WATER!H18,WATER!M18,WATER!R18) -> 0 | H17: =IF((G17-G16<0), "0",G17-G16) -> 0
... A35: =A34+1 -> 44623 | C35: =SUM('GENSET #1'!C40+'GENSET #2'!C40+'GENSET #3'!C40+'GENSET #4'!C40+'GENSET #5'!C40) -> 0 | D35: =IF((C35-C34<0), "0",C35-C34) -> 0 | E35: ='Gas-2'!G36 -> 0 | F35: =IF((E35-E34<0), "0",E35-E34) -> 0 | G35: =SUM(WATER!C36,WATER!H36,WATER!M36,WATER!R36) -> 0 | H35: =IF((G35-G34<0), "0",G35-G34) -> 0

Sheet Finance Only
A1: Four Seasons Landaa Giraavaru
A3: Property | B3: MLG | G3: 44470 | H3: =NOW() -> 44623.374 | J3: =H3-G3 -> 153.37412
A4: Month | B4: MARCH
A5: Year | B5: 2022
A7: DAY | B7: Electricity Consumption ( kwh) | C7: Diesel Consumption (Liters) | D7: Solar Power Consumption(kwh) | E7: Gas Consumption (kg) | F7: Water Consumption ( m3) | G7: Occupancy | H7: Weather | I7: Ambian Temperature | J7: Electricity Variance (Today vs Yesterday)
A8: 1 | B8: =SUM('GENSET #1:GENSET #5'!D10) -> 29703 | C8: ='Diesel consumption'!D5 -> 8260 | D8: ='SOLAR METER READING'!D9 -> 3176 | E8: ='Gas-2'!G6 -> 315 | F8: =WATER!V6 -> 468 | G8: =WATER!W6 -> 60 | H8: ='SOLAR METER READING'!E9 -> Sunny | I8: ='SOLAR METER READING'!F9 -> 29
A9: 2 | B9: =SUM('GENSET #1:GENSET #5'!D11) -> 29643 | C9: ='Diesel consumption'!D6 -> 8340 | D9: ='SOLAR METER READING'!D10 -> 3043 | E9: ='Gas-2'!G7 -> 0 | F9: =WATER!V7 -> 447 | G9: =WATER!W7 -> 0 | H9: ='SOLAR METER READING'!E10 -> Sunny | I9: ='SOLAR METER READING'!F10 -> 29 | J9: =B9-B8 -> -60
A10: 3 | B10: =SUM('GENSET #1:GENSET #5'!D12) -> 0 | C10: ='Diesel consumption'!D7 -> 0 | D10: ='SOLAR METER READING'!D11 -> 0 | E10: ='Gas-2'!G8 -> 0 | F10: =WATER!V8 -> 416 | G10: =WATER!W8 -> 0 | H10: ='SOLAR METER READING'!E11 -> 0 | I10: ='SOLAR METER READING'!F11 -> 0 | J10: =B10-B9 -> -29643
A11: 4 | B11: =SUM('GENSET #1:GENSET #5'!D13) -> 0 | C11: ='Diesel consumption'!D8 -> 0 | D11: ='SOLAR METER READING'!D12 -> 0 | E11: ='Gas-2'!G9 -> 0 | F11: =WATER!V9 -> 0 | G11: =WATER!W9 -> 0 | H11: ='SOLAR METER READING'!E12 -> 0 | I11: ='SOLAR METER READING'!F12 -> 0 | J11: =B11-B10 -> 0
A12: 5 | B12: =SUM('GENSET #1:GENSET #5'!D14) -> 0 | C12: ='Diesel consumption'!D9 -> 0 | D12: ='SOLAR METER READING'!D13 -> 0 | E12: ='Gas-2'!G10 -> 0 | F12: =WATER!V10 -> 0 | G12: =WATER!W10 -> 0 | H12: ='SOLAR METER READING'!E13 -> 0 | I12: ='SOLAR METER READING'!F13 -> 0 | J12: =B12-B11 -> 0
A13: 6 | B13: =SUM('GENSET #1:GENSET #5'!D15) -> 0 | C13: ='Diesel consumption'!D10 -> 0 | D13: ='SOLAR METER READING'!D14 -> 0 | E13: ='Gas-2'!G11 -> 0 | F13: =WATER!V11 -> 0 | G13: =WATER!W11 -> 0 | H13: ='SOLAR METER READING'!E14 -> 0 | I13: ='SOLAR METER READING'!F14 -> 0 | J13: =B13-B12 -> 0
A14: 7 | B14: =SUM('GENSET #1:GENSET #5'!D16) -> 0 | C14: ='Diesel consumption'!D11 -> 0 | D14: ='SOLAR METER READING'!D15 -> 0 | E14: ='Gas-2'!G12 -> 0 | F14: =WATER!V12 -> 0 | G14: =WATER!W12 -> 0 | H14: ='SOLAR METER READING'!E15 -> 0 | I14: ='SOLAR METER READING'!F15 -> 0 | J14: =B14-B13 -> 0
A15: 8 | B15: =SUM('GENSET #1:GENSET #5'!D17) -> 0 | C15: ='Diesel consumption'!D12 -> 0 | D15: ='SOLAR METER READING'!D16 -> 0 | E15: ='Gas-2'!G13 -> 0 | F15: =WATER!V13 -> 0 | G15: =WATER!W13 -> 0 | H15: ='SOLAR METER READING'!E16 -> 0 | I15: ='SOLAR METER READING'!F16 -> 0 | J15: =B15-B14 -> 0
A16: 9 | B16: =SUM('GENSET #1:GENSET #5'!D18) -> 0 | C16: ='Diesel consumption'!D13 -> 0 | D16: ='SOLAR METER READING'!D17 -> 0 | E16: ='Gas-2'!G14 -> 0 | F16: =WATER!V14 -> 0 | G16: =WATER!W14 -> 0 | H16: ='SOLAR METER READING'!E17 -> 0 | I16: ='SOLAR METER READING'!F17 -> 0 | J16: =B16-B15 -> 0
A17: 10 | B17: =SUM('GENSET #1:GENSET #5'!D19) -> 0 | C17: ='Diesel consumption'!D14 -> 0 | D17: ='SOLAR METER READING'!D18 -> 0 | E17: ='Gas-2'!G15 -> 0 | F17: =WATER!V15 -> 0 | G17: =WATER!W15 -> 0 | H17: ='SOLAR METER READING'!E18 -> 0 | I17: ='SOLAR METER READING'!F18 -> 0 | J17: =B17-B16 -> 0
A18: 11 | B18: =SUM('GENSET #1:GENSET #5'!D20) -> 0 | C18: ='Diesel consumption'!D15 -> 0 | D18: ='SOLAR METER READING'!D19 -> 0 | E18: ='Gas-2'!G16 -> 0 | F18: =WATER!V16 -> 0 | G18: =WATER!W16 -> 0 | H18: ='SOLAR METER READING'!E19 -> 0 | I18: ='SOLAR METER READING'!F19 -> 0 | J18: =B18-B17 -> 0
A19: 12 | B19: =SUM('GENSET #1:GENSET #5'!D21) -> 0 | C19: ='Diesel consumption'!D16 -> 0 | D19: ='SOLAR METER READING'!D20 -> 0 | E19: ='Gas-2'!G17 -> 0 | F19: =WATER!V17 -> 0 | G19: =WATER!W17 -> 0 | H19: ='SOLAR METER READING'!E20 -> 0 | I19: ='SOLAR METER READING'!F20 -> 0 | J19: =B19-B18 -> 0
A20: 13 | B20: =SUM('GENSET #1:GENSET #5'!D22) -> 0 | C20: ='Diesel consumption'!D17 -> 0 | D20: ='SOLAR METER READING'!D21 -> 0 | E20: ='Gas-2'!G18 -> 0 | F20: =WATER!V18 -> 0 | G20: =WATER!W18 -> 0 | H20: ='SOLAR METER READING'!E21 -> 0 | I20: ='SOLAR METER READING'!F21 -> 0 | J20: =B20-B19 -> 0
... A37: 30 | B37: =SUM('GENSET #1:GENSET #5'!D39) -> 0 | C37: ='Diesel consumption'!D34 -> 0 | D37: ='SOLAR METER READING'!D38 -> 0 | E37: ='Gas-2'!G35 -> 0 | F37: =WATER!V35 -> 0 | G37: =WATER!W35 -> 0 | H37: ='SOLAR METER READING'!E38 -> 0 | I37: ='SOLAR METER READING'!F38 -> 0 | J37: =B37-B36 -> 0
A38: 31 | B38: =SUM('GENSET #1:GENSET #5'!D40) -> 0 | C38: ='Diesel consumption'!D35 -> 0 | D38: ='SOLAR METER READING'!D39 -> 0 | E38: ='Gas-2'!G36 -> 0 | F38: =WATER!V36 -> 0 | G38: =WATER!W36 -> 0 | H38: sunny | I38: 29
A39: Total | B39: =SUM(B8:B38) -> 59346 | C39: =SUM(C8:C38) -> 16600 | D39: =SUM(D8:D38) -> 6219 | E39: =SUM(E8:E38) -> 315 | F39: =SUM(F8:F38) -> 1331 | G39: =SUM(G8:G38)/31 -> 1.9354839 | H39: ='SOLAR METER READING'!E40 -> 0 | I39: ='SOLAR METER READING'!F40 -> 0
A40: Avg | B40: =B39/31 -> 1914.3871 | C40: =C39/31 -> 535.48387 | D40: =D39/31 -> 200.6129 | E40: =E39/31 -> 10.16129 | F40: =F39/31 -> 42.935484

Sheet GENSET #1
C1: 1000 KVA
C3: NO#1
A6: 44621
B8: GENSET NO 1
A9: DAY | B9: YESTARDAY | C9: TODAY | D9: Final Electricity Consumption( KWh)
A10: 1 | B10: 18787532 | C10: 18795489 | D10: =MAX(0,C10-B10) -> 7957
A11: 2 | B11: =C10 -> 18795489 | C11: 18806702 | D11: =MAX(0,C11-B11) -> 11213
A12: 3 | B12: =C11 -> 18806702 | D12: =MAX(0,C12-B12) -> 0
A13: 4 | B13: =C12 -> 0 | D13: =MAX(0,C13-B13) -> 0
A14: 5 | B14: =C13 -> 0 | D14: =MAX(0,C14-B14) -> 0
A15: 6 | B15: =C14 -> 0 | D15: =MAX(0,C15-B15) -> 0
A16: 7 | B16: =C15 -> 0 | D16: =MAX(0,C16-B16) -> 0
A17: 8 | B17: =C16 -> 0 | D17: =MAX(0,C17-B17) -> 0
A18: 9 | B18: =C17 -> 0 | D18: =MAX(0,C18-B18) -> 0
A19: 10 | B19: =C18 -> 0 | D19: =MAX(0,C19-B19) -> 0
A20: 11 | B20: =C19 -> 0 | D20: =MAX(0,C20-B20) -> 0
A21: 12 | B21: =C20 -> 0 | D21: =MAX(0,C21-B21) -> 0
A22: 13 | B22: =C21 -> 0 | D22: =MAX(0,C22-B22) -> 0
A23: 14 | B23: =C22 -> 0 | D23: =MAX(0,C23-B23) -> 0
... A38: 29 | B38: =C37 -> 0 | D38: =MAX(0,C38-B38) -> 0
A39: 30 | B39: =C38 -> 0 | D39: =MAX(0,C39-B39) -> 0 | G39: NEW ENGINE PURCHASED FROM UK
A40: 31 | B40: =C39 -> 0 | D40: =MAX(0,C40-B40) -> 0
A41: Total | D41: =SUM(D10:D40) -> 19170 | G41: INSTALLED: NOV 30 2013

Sheet GENSET #2
C1: 1600 KVA
C3: NO#2
A6: ='GENSET #1'!A6 -> 44621
B8: GENSET NO 2
A9: DAY | B9: YESTARDAY | C9: TODAY | D9: Final Electricity Consumption( KW h)
A10: 1 | B10: 32246370 | C10: 32258047 | D10: =MAX(0,C10-B10) -> 11677
A11: 2 | B11: =C10 -> 32258047 | C11: 32269962 | D11: =MAX(0,C11-B11) -> 11915
A12: 3 | B12: =C11 -> 32269962 | D12: =MAX(0,C12-B12) -> 0
A13: 4 | B13: =C12 -> 0 | D13: =MAX(0,C13-B13) -> 0
A14: 5 | B14: =C13 -> 0 | D14: =MAX(0,C14-B14) -> 0
A15: 6 | B15: =C14 -> 0 | D15: =MAX(0,C15-B15) -> 0
A16: 7 | B16: =C15 -> 0 | D16: =MAX(0,C16-B16) -> 0
A17: 8 | B17: =C16 -> 0 | D17: =MAX(0,C17-B17) -> 0
A18: 9 | B18: =C17 -> 0 | D18: =MAX(0,C18-B18) -> 0
A19: 10 | B19: =C18 -> 0 | D19: =MAX(0,C19-B19) -> 0
A20: 11 | B20: =C19 -> 0 | D20: =MAX(0,C20-B20) -> 0
A21: 12 | B21: =C20 -> 0 | D21: =MAX(0,C21-B21) -> 0
A22: 13 | B22: =C21 -> 0 | D22: =MAX(0,C22-B22) -> 0
A23: 14 | B23: =C22 -> 0 | D23: =MAX(0,C23-B23) -> 0
... A40: 31 | B40: =C39 -> 0 | D40: =MAX(0,C40-B40) -> 0
A41: Total | B41: =#REF! -> #REF! | D41: =SUM(D10:D40) -> 23592

Sheet GENSET #3
C1: 900 KVA
C3: NO#3
A6: ='GENSET #2'!A6 -> 44621
B8: GENSET NO 3
A9: DAY | B9: YESTARDAY | C9: TODAY | D9: Final Electricity Consumption( KW h)
A10: 1 | B10: 14572350 | C10: 14572350 | D10: =MAX(0,C10-B10) -> 0
A11: 2 | B11: =C10 -> 14572350 | C11: 14573839 | D11: =MAX(0,C11-B11) -> 1489
A12: 3 | B12: =C11 -> 14573839 | D12: =MAX(0,C12-B12) -> 0
A13: 4 | B13: =C12 -> 0 | D13: =MAX(0,C13-B13) -> 0
A14: 5 | B14: =C13 -> 0 | D14: =MAX(0,C14-B14) -> 0
A15: 6 | B15: =C14 -> 0 | D15: =MAX(0,C15-B15) -> 0
A16: 7 | B16: =C15 -> 0 | D16: =MAX(0,C16-B16) -> 0
A17: 8 | B17: =C16 -> 0 | D17: =MAX(0,C17-B17) -> 0
A18: 9 | B18: =C17 -> 0 | D18: =MAX(0,C18-B18) -> 0
A19: 10 | B19: =C18 -> 0 | D19: =MAX(0,C19-B19) -> 0
A20: 11 | B20: =C19 -> 0 | D20: =MAX(0,C20-B20) -> 0
A21: 12 | B21: =C20 -> 0 | D21: =MAX(0,C21-B21) -> 0
A22: 13 | B22: =C21 -> 0 | D22: =MAX(0,C22-B22) -> 0
A23: 14 | B23: =C22 -> 0 | D23: =MAX(0,C23-B23) -> 0
... A40: 31 | B40: =C39 -> 0 | D40: =MAX(0,C40-B40) -> 0
A41: Total | B41: =#REF! -> #REF! | D41: =SUM(D10:D40) -> 1489

Sheet GENSET #4
C1: 500 KVA
C3: NO#4
A6: ='GENSET #3'!A6 -> 44621
B8: GENSET NO 4
A9: DAY | B9: YESTARDAY | C9: TODAY | D9: Final Electricity Consumption( KW h)
A10: 1 | B10: 12273051 | C10: 12273051 | D10: =MAX(0,C10-B10) -> 0
A11: 2 | B11: =C10 -> 12273051 | C11: 12274181 | D11: =MAX(0,C11-B11) -> 1130
A12: 3 | B12: =C11 -> 12274181 | D12: =MAX(0,C12-B12) -> 0
A13: 4 | B13: =C12 -> 0 | D13: =MAX(0,C13-B13) -> 0
A14: 5 | B14: =C13 -> 0 | D14: =MAX(0,C14-B14) -> 0
A15: 6 | B15: =C14 -> 0 | D15: =MAX(0,C15-B15) -> 0
A16: 7 | B16: =C15 -> 0 | D16: =MAX(0,C16-B16) -> 0
A17: 8 | B17: =C16 -> 0 | D17: =MAX(0,C17-B17) -> 0
A18: 9 | B18: =C17 -> 0 | D18: =MAX(0,C18-B18) -> 0
A19: 10 | B19: =C18 -> 0 | D19: =MAX(0,C19-B19) -> 0
A20: 11 | B20: =C19 -> 0 | D20: =MAX(0,C20-B20) -> 0
A21: 12 | B21: =C20 -> 0 | D21: =MAX(0,C21-B21) -> 0
A22: 13 | B22: =C21 -> 0 | D22: =MAX(0,C22-B22) -> 0
A23: 14 | B23: =C22 -> 0 | D23: =MAX(0,C23-B23) -> 0
... A40: 31 | B40: =C39 -> 0 | D40: =MAX(0,C40-B40) -> 0
A41: Total | B41: =#REF! -> #REF! | D41: =SUM(D10:D40) -> 1130

Sheet GENSET #5
C1: 1000 KVA
C3: NO#5
A6: ='GENSET #4'!A6 -> 44621
B8: GENSET NO 5
A9: DAY | B9: YESTARDAY | C9: TODAY | D9: Final Electricity Consumption( KWh)
A10: 1 | B10: 19840389 | C10: 19850458 | D10: =MAX(0,C10-B10) -> 10069
A11: 2 | B11: =C10 -> 19850458 | C11: 19854354 | D11: =MAX(0,C11-B11) -> 3896
A12: 3 | B12: =C11 -> 19854354 | D12: =MAX(0,C12-B12) -> 0
A13: 4 | B13: =C12 -> 0 | D13: =MAX(0,C13-B13) -> 0
A14: 5 | B14: =C13 -> 0 | D14: =MAX(0,C14-B14) -> 0
A15: 6 | B15: =C14 -> 0 | D15: =MAX(0,C15-B15) -> 0
A16: 7 | B16: =C15 -> 0 | D16: =MAX(0,C16-B16) -> 0
A17: 8 | B17: =C16 -> 0 | D17: =MAX(0,C17-B17) -> 0
A18: 9 | B18: =C17 -> 0 | D18: =MAX(0,C18-B18) -> 0
A19: 10 | B19: =C18 -> 0 | D19: =MAX(0,C19-B19) -> 0
A20: 11 | B20: =C19 -> 0 | D20: =MAX(0,C20-B20) -> 0
A21: 12 | B21: =C20 -> 0 | D21: =MAX(0,C21-B21) -> 0
A22: 13 | B22: =C21 -> 0 | D22: =MAX(0,C22-B22) -> 0
A23: 14 | B23: =C22 -> 0 | D23: =MAX(0,C23-B23) -> 0
... A40: 31 | B40: =C39 -> 0 | D40: =MAX(0,C40-B40) -> 0
A41: Total | D41: =SUM(D10:D40) -> 13965

Sheet Diesel consumption
A1: Diesel Consumption - Powerhouse | F1: Diesel Tank Jetty Meter
A2: ='GENSET #5'!A6 -> 44621
D3: Liters | F3: Boat meter Reading
A4: Date | B4: Yesterday | C4: Today | D4: ConsumptionIn 24 hrs | F4: Yesterday | G4: Today | H4: Consumption (Liters) | J4: In Barrels | L4: Carbon Emmision
A5: 1 | B5: 46104830 | C5: 46113090 | D5: =MAX(0,C5-B5) -> 8260 | F5: 1042330 | G5: 1044890 | H5: =MAX(0,G5-F5) -> 2560 | J5: =D5/200 -> 41.3 | L5: =2.68*D5 -> 22136.8 | M5: =L5/1000 -> 22.1368
A6: 2 | B6: =C5 -> 46113090 | C6: 46121430 | D6: =MAX(0,C6-B6) -> 8340 | F6: =G5 -> 1044890 | G6: 1044890 | H6: =MAX(0,G6-F6) -> 0 | J6: =D6/200 -> 41.7 | L6: =2.68*D6 -> 22351.2 | M6: =L6/1000 -> 22.3512
A7: 3 | B7: =C6 -> 46121430 | D7: =MAX(0,C7-B7) -> 0 | F7: =G6 -> 1044890 | H7: =MAX(0,G7-F7) -> 0 | J7: =D7/200 -> 0 | L7: =2.68*D7 -> 0 | M7: =L7/1000 -> 0
A8: 4 | B8: =C7 -> 0 | D8: =MAX(0,C8-B8) -> 0 | F8: =G7 -> 0 | H8: =MAX(0,G8-F8) -> 0 | J8: =D8/200 -> 0 | L8: =2.68*D8 -> 0 | M8: =L8/1000 -> 0
A9: 5 | B9: =C8 -> 0 | D9: =MAX(0,C9-B9) -> 0 | F9: =G8 -> 0 | H9: =MAX(0,G9-F9) -> 0 | J9: =D9/200 -> 0 | L9: =2.68*D9 -> 0 | M9: =L9/1000 -> 0
A10: 6 | B10: =C9 -> 0 | D10: =MAX(0,C10-B10) -> 0 | F10: =G9 -> 0 | H10: =MAX(0,G10-F10) -> 0 | J10: =D10/200 -> 0 | L10: =2.68*D10 -> 0 | M10: =L10/1000 -> 0
A11: 7 | B11: =C10 -> 0 | D11: =MAX(0,C11-B11) -> 0 | F11: =G10 -> 0 | H11: =MAX(0,G11-F11) -> 0 | J11: =D11/200 -> 0 | L11: =2.68*D11 -> 0 | M11: =L11/1000 -> 0
A12: 8 | B12: =C11 -> 0 | D12: =MAX(0,C12-B12) -> 0 | F12: =G11 -> 0 | H12: =MAX(0,G12-F12) -> 0 | J12: =D12/200 -> 0 | L12: =2.68*D12 -> 0 | M12: =L12/1000 -> 0
A13: 9 | B13: =C12 -> 0 | D13: =MAX(0,C13-B13) -> 0 | F13: =G12 -> 0 | H13: =MAX(0,G13-F13) -> 0 | J13: =D13/200 -> 0 | L13: =2.68*D13 -> 0 | M13: =L13/1000 -> 0
A14: 10 | B14: =C13 -> 0 | D14: =MAX(0,C14-B14) -> 0 | F14: =G13 -> 0 | H14: =MAX(0,G14-F14) -> 0 | J14: =D14/200 -> 0 | L14: =2.68*D14 -> 0 | M14: =L14/1000 -> 0
A15: 11 | B15: =C14 -> 0 | D15: =MAX(0,C15-B15) -> 0 | F15: =G14 -> 0 | H15: =MAX(0,G15-F15) -> 0 | J15: =D15/200 -> 0 | L15: =2.68*D15 -> 0 | M15: =L15/1000 -> 0
A16: 12 | B16: =C15 -> 0 | D16: =MAX(0,C16-B16) -> 0 | F16: =G15 -> 0 | H16: =MAX(0,G16-F16) -> 0 | J16: =D16/200 -> 0 | L16: =2.68*D16 -> 0 | M16: =L16/1000 -> 0
A17: 13 | B17: =C16 -> 0 | D17: =MAX(0,C17-B17) -> 0 | F17: =G16 -> 0 | H17: =MAX(0,G17-F17) -> 0 | J17: =D17/200 -> 0 | L17: =2.68*D17 -> 0 | M17: =L17/1000 -> 0
A18: 14 | B18: =C17 -> 0 | D18: =MAX(0,C18-B18) -> 0 | F18: =G17 -> 0 | H18: =MAX(0,G18-F18) -> 0 | J18: =D18/200 -> 0 | L18: =2.68*D18 -> 0 | M18: =L18/1000 -> 0
... A34: 30 | B34: =C33 -> 0 | D34: =MAX(0,C34-B34) -> 0 | F34: =G33 -> 0 | H34: =MAX(0,G34-F34) -> 0 | J34: =D34/200 -> 0 | L34: =2.68*D34 -> 0 | M34: =L34/1000 -> 0
A35: 31 | B35: =C34 -> 0 | D35: =MAX(0,C35-B35) -> 0 | F35: =G34 -> 0 | H35: =MAX(0,G35-F35) -> 0 | J35: =D35/200 -> 0 | L35: =2.68*D35 -> 0
D36: =SUM(D5:D35) -> 16600 | J36: =SUM(J5:J34) -> 83 | L36: =2.68*D36 -> 44488 | M36: =L36/1000 -> 44.488

Sheet SOLAR METER READING
C3: solar reading
B5: ='Diesel consumption'!A2 -> 44621
B7: Solar meter reading
A8: DAY | B8: YESTARDAY | C8: TODAY | D8: Final Electricity Consumption( KW h) | E8: Weather Condition | F8: Temperature
A9: 1 | B9: 3439504 | C9: 3442680 | D9: =MAX(0,C9-B9) -> 3176 | E9: Sunny | F9: 29
A10: 2 | B10: =C9 -> 3442680 | C10: 3445723 | D10: =MAX(0,C10-B10) -> 3043 | E10: Sunny | F10: 29
A11: 3 | B11: =C10 -> 3445723 | D11: =MAX(0,C11-B11) -> 0
A12: 4 | B12: =C11 -> 0 | D12: =MAX(0,C12-B12) -> 0
A13: 5 | B13: =C12 -> 0 | D13: =MAX(0,C13-B13) -> 0 | J13: 1 liter diesel | K13: 11.1 kwh
A14: 6 | B14: =C13 -> 0 | D14: =MAX(0,C14-B14) -> 0 | J14: 212.88 diesel | K14: 2363 kwh
A15: 7 | B15: =C14 -> 0 | D15: =MAX(0,C15-B15) -> 0
A16: 8 | B16: =C15 -> 0 | D16: =MAX(0,C16-B16) -> 0
A17: 9 | B17: =C16 -> 0 | D17: =MAX(0,C17-B17) -> 0
A18: 10 | B18: =C17 -> 0 | D18: =MAX(0,C18-B18) -> 0
A19: 11 | B19: =C18 -> 0 | D19: =MAX(0,C19-B19) -> 0
A20: 12 | B20: =C19 -> 0 | D20: =MAX(0,C20-B20) -> 0
A21: 13 | B21: =C20 -> 0 | D21: =MAX(0,C21-B21) -> 0
A22: 14 | B22: =C21 -> 0 | D22: =MAX(0,C22-B22) -> 0
A23: 15 | B23: =C22 -> 0 | D23: =MAX(0,C23-B23) -> 0
A24: 16 | B24: =C23 -> 0 | D24: =MAX(0,C24-B24) -> 0
A25: 17 | B25: =C24 -> 0 | D25: =MAX(0,C25-B25) -> 0
A26: 18 | B26: =C25 -> 0 | D26: =MAX(0,C26-B26) -> 0
... A39: 31 | B39: =C38 -> 0 | D39: =MAX(0,C39-B39) -> 0
A40: Total | D40: =SUM(D9:D39) -> 6219

Sheet FEEDER Consumption 
A1: ='SOLAR METER READING'!B5 -> 44621 | FR1: Daily Electricity (Kwh) Consumption by Building Categories
A2: POWER HOUSE FEEDER READING
C3: Main BLU FEEDER PANEL 1 | H3: Main BLU FEEDER PANEL 2 | M3: Main POWER HOUSE FEEDER PANEL NO:3 | R3: Main Kitchen -7 | W3: Main Kitchen -10 | AB3: Water treatment Plant | AG3: Sewage treatment Plant | AL3: Laundry--8SSB (HR/Tuck Shop Building) | AQ3: Laundry-9 (Machineries) | AV3: New staff accomodation (E0) | BA3: Staff block-16(E2-E3) | BF3: Staff Block Feeder-3(E4-E5) | BK3: Management block-5 (M1 to M6) | BP3: SNR STAFF BLOCK (PC Block) | BU3: BOAT DOCK FEEDER - 22 | BZ3: RECEPTION Building Full (Finance/Reservation) | CE3: DIVE CENTER (Inc MDC and Recreation) | CJ3: 301-307 | CO3: 308-314 | CT3: 315-320 | CY3: 401-407 | DD3: 408-414 | DI3: 415-420 | DN3: SPA - 1 | DS3: SPA - 2 | DX3: BLU KITCHEN - 1 | EC3: BLU KITCHEN - 2 | EH3: AL BARAKATH | EM3: STAFF KITCHEN | ER3: MANAGR BLOCK GARDEN (White House) | EW3: 121-131 | FB3: 113-120 | FG3: Room 855 Hot Water Boiler Kw reading | FL3: Room 911 Hot Water Boiler kw reading | FR3: Blu Feeders | FT3: ALL Kitchens | FV3: Laundry + HR Buidling | FX3: Employee Block | FZ3: Managers Block + SNR Block | GB3: HPL Project Team Usage
A4: DAY | B4: Occupancy | C4: Yesterday | D4: Today | E4: Consumption | F4: Variance (Tdy vs Ystdy) | G4: % | H4: Yesterday | I4: Today | J4: Consumption | K4: Var(Tdy vs Ystdy) | L4: % | M4: Yesterday | N4: Today | O4: Consumption | P4: Var (Tdy vs Ystdy) | Q4: % | R4: Yesterday | S4: Today | T4: Consumption | U4: Var(Tdy vs Ystdy) | V4: % | W4: Yesterday | X4: Today | Y4: Consumption | Z4: Var(Tdy vs Ystdy) | AA4: % | AB4: Yesterday | AC4: Today | AD4: Consumption | AE4: Var(Tdy vs Ystdy) | AF4: % | AG4: Yesterday | AH4: Today | AI4: Consumption | AJ4: Var(Tdy vs Ystdy) | AK4: % | AL4: Yesterday | AM4: Today | AN4: Consumption | AO4: Var(Tdy vs Ystdy) | AP4: % | AQ4: Yesterday | AR4: Today | AS4: Consumption | AT4: Var(Tdy vs Ystdy) | AU4: % | AV4: Yesterday | AW4: Today | AX4: Consumption | AY4: Var(Tdy vs Ystdy) | AZ4: % | BA4: Yesterday | BB4: Today | BC4: Consumption | BD4: Var(Tdy vs Ystdy) | BE4: % | BF4: Yesterday | BG4: Today | BH4: Consumption | BI4: Var(Tdy vs Ystdy) | BJ4: % | BK4: Yesterday | BL4: Today | BM4: Consumption | BN4: Var(Tdy vs Ystdy) | BO4: % | BP4: Yesterday | BQ4: Today | BR4: Consumption | BS4: Var(Tdy vs Ystdy) | BT4: % | BU4: Yesterday | BV4: Today | BW4: Consumption | BX4: Var(Tdy vs Ystdy) | BY4: % | BZ4: Yesterday | CA4: Today | CB4: Consumption | CC4: Var(Tdy vs Ystdy) | CD4: % | CE4: Yesterday | CF4: Today | CG4: Consumption | CH4: Var(Tdy vs Ystdy) | CI4: % | CJ4: Yesterday | CK4: Today | CL4: Consumption | CM4: Var(Tdy vs Ystdy) | CN4: % | CO4: Yesterday | CP4: Today | CQ4: Consumption | CR4: Var(Tdy vs Ystdy) | CS4: % | CT4: Yesterday | CU4: Today | CV4: Consumption | CW4: Var(Tdy vs Ystdy) | CX4: % | CY4: Yesterday | CZ4: Today | DA4: Consumption | DB4: Var(Tdy vs Ystdy) | DC4: % | DD4: Yesterday | DE4: Today | DF4: Consumption | DG4: Var(Tdy vs Ystdy) | DH4: % | DI4: Yesterday | DJ4: Today | DK4: Consumption | DL4: Var(Tdy vs Ystdy) | DM4: % | DN4: Yesterday | DO4: Today | DP4: Consumption | DQ4: Var(Tdy vs Ystdy) | DR4: % | DS4: Yesterday | DT4: Today | DU4: Consumption | DV4: Var(Tdy vs Ystdy) | DW4: % | DX4: Yesterday | DY4: Today | DZ4: Consumption | EA4: Var(Tdy vs Ystdy) | EB4: % | EC4: Yesterday | ED4: Today | EE4: Consumption | EF4: Var(Tdy vs Ystdy) | EG4: % | EH4: Yesterday | EI4: Today | EJ4: Consumption | EK4: Var(Tdy vs Ystdy) | EL4: % | EM4: Yesterday | EN4: Today | EO4: Consumption | EP4: Var(Tdy vs Ystdy) | EQ4: % | ER4: Yesterday | ES4: Today | ET4: Consumption | EU4: Var(Tdy vs Ystdy) | EV4: % | EW4: Yesterday | EX4: Today | EY4: Consumption | EZ4: Var(Tdy vs Ystdy) | FA4: % | FB4: Yesterday | FC4: Today | FD4: Consumption | FE4: Var(Tdy vs Ystdy) | FF4: % | FL4: Yesterday | FM4: Today | FN4: Consumption | FO4: Var(Tdy vs Ystdy) | FP4: % | FR4: Total (Kwh) | FS4: Avg | FT4: Total (Kwh) | FU4: Avg | FV4: Total (Kwh) | FW4: Avg | FX4: Total (Kwh) | FY4: Avg | FZ4: Total (Kwh) | GA4: Avg | GB4: Total (Kwh) | GC4: Avg
A5: 1 | B5: ='Finance Only'!G8 -> 60 | C5: 26372128 | D5: 26376286 | E5: =MAX(0,D5-C5) -> 4158 | H5: 23981447 | I5: 23986959 | J5: =MAX(0,I5-H5) -> 5512 | M5: 89608817 | N5: 89622716 | O5: =MAX(0,N5-M5) -> 13899 | R5: 2530400 | S5: 2532800 | T5: =MAX(0,S5-R5) -> 2400 | W5: 3520051 | X5: 3523144 | Y5: =MAX(0,X5-W5) -> 3093 | AB5: 2231500 | AC5: 2233700 | AD5: =MAX(0,AC5-AB5) -> 2200 | AG5: 961029 | AH5: 961871 | AI5: =MAX(0,AH5-AG5) -> 842 | AL5: 955500 | AM5: 956230 | AQ5: 2173100 | AR5: 2175200 | AS5: 785 | AV5: 622052 | AW5: 622528 | AX5: 443 | BA5: 903380 | BB5: 904050 | BC5: 871 | BF5: 994600 | BG5: 995550 | BH5: 865 | BK5: 1470400 | BL5: 1471100 | BM5: 1205 | BP5: 105020 | BQ5: 105150 | BR5: 944 | BU5: 484380 | BV5: 484910 | BW5: 355 | BZ5: 826850 | CA5: 828180 | CB5: 1250 | CE5: 259080 | CF5: 259570 | CG5: 380 | CJ5: 601580 | CK5: 602850 | CL5: =MAX(0,CK5-CJ5) -> 1270 | CO5: 49190 | CP5: 49320 | CQ5: =MAX(0,CP5-CO5) -> 130 | CT5: 41530 | CU5: 41615 | CV5: =MAX(0,CU5-CT5) -> 85 | CY5: 69818 | CZ5: 69942 | DA5: =MAX(0,CZ5-CY5) -> 124 | DD5: 529290 | DE5: 530250 | DF5: =MAX(0,DE5-DD5) -> 960 | DI5: 472490 | DJ5: 473270 | DK5: =MAX(0,DJ5-DI5) -> 780 | DN5: 271610 | DO5: 271990 | DP5: =MAX(0,DO5-DN5) -> 380 | DS5: 844880 | DT5: 846130 | DU5: =MAX(0,DT5-DS5) -> 1250 | DX5: 535500 | DY5: 536300 | DZ5: =MAX(0,DY5-DX5) -> 800 | EC5: 173240 | ED5: 173530 | EE5: =MAX(0,ED5-EC5) -> 290 | EH5: 181150 | EI5: 181540 | EJ5: =MAX(0,EI5-EH5) -> 390 | EM5: 320120 | EN5: 320630 | EO5: =MAX(0,EN5-EM5) -> 510 | ER5: 69098 | ET5: =MAX(0,ES5-ER5) -> 0 | EW5: 49150 | EX5: 50025 | EY5: =MAX(0,EX5-EW5) -> 875 | FB5: 13846 | FC5: 14420 | FD5: =MAX(0,FC5-FB5) -> 574 | FL5: 91210 | FN5: =MAX(0,FM5-FL5) -> 0 | FR5: =SUM(E5+J5) -> 9670 | FT5: =SUM(T5+Y5+DZ5+EE5+EJ5+EO5) -> 7483 | FV5: =SUM(AN5+AS5) -> 785 | FX5: =SUM(AX5+BC5+BH5) -> 2179 | FZ5: =SUM(BM5+BR5+ET5) -> 2149 | GB5: =SUM(EY5+FD5) -> 1449
A6: 2 | B6: ='Finance Only'!G9 -> 0 | C6: =D5 -> 26376286 | D6: 26380419 | E6: =MAX(0,D6-C6) -> 4133 | F6: =E6-E5 -> -25 | G6: =(E6/'Finance Only'!B9)*100 -> 13.942583 | H6: =I5 -> 23986959 | I6: 23992466 | J6: =MAX(0,I6-H6) -> 5507 | K6: =J6-J5 -> -5 | L6: =(J6/'Finance Only'!B9)*100 -> 18.577742 | M6: =N5 -> 89622716 | N6: 89636680 | O6: =MAX(0,N6-M6) -> 13964 | P6: =O6-O5 -> 65 | Q6: =(O6/'Finance Only'!B9)*100 -> 47.107243 | R6: =S5 -> 2532800 | S6: 2535200 | T6: =MAX(0,S6-R6) -> 2400 | U6: =T6-T5 -> 0 | V6: =(T6/'Finance Only'!B9)*100 -> 8.0963465 | W6: =X5 -> 3523144 | X6: 3526229 | Y6: =MAX(0,X6-W6) -> 3085 | Z6: =Y6-Y5 -> -8 | AA6: =(Y6/'Finance Only'!B9)*100 -> 10.407179 | AB6: =AC5 -> 2233700 | AC6: 2236000 | AD6: =MAX(0,AC6-AB6) -> 2300 | AE6: =AD6-AD5 -> 100 | AF6: =(AD6/'Finance Only'!B9)*100 -> 7.7589988 | AG6: =AH5 -> 961871 | AH6: 962738 | AI6: =MAX(0,AH6-AG6) -> 867 | AJ6: =AI6-AI5 -> 25 | AK6: =(AI6/'Finance Only'!B9)*100 -> 2.9248052 | AL6: =AM5 -> 956230 | AM6: 956910 | AN6: =MAX(0,AM6-AL6) -> 680 | AO6: =AN6-AN5 -> 680 | AP6: =(AN6/'Finance Only'!B9)*100 -> 2.2939648 | AQ6: =AR5 -> 2175200 | AR6: 2176900 | AS6: =MAX(0,AR6-AQ6) -> 1700 | AT6: =AS6-AS5 -> 915 | AU6: =(AS6/'Finance Only'!B9)*100 -> 5.7349121 | AV6: =AW5 -> 622528 | AW6: 622960 | AX6: =MAX(0,AW6-AV6) -> 432 | AY6: =AX6-AX5 -> -11 | AZ6: =(AX6/'Finance Only'!B9)*100 -> 1.4573424 | BA6: =BB5 -> 904050 | BB6: 904730 | BC6: =MAX(0,BB6-BA6) -> 680 | BD6: =BC6-BC5 -> -191 | BE6: =(BC6/'Finance Only'!B9)*100 -> 2.2939648 | BF6: =BG5 -> 995550 | BG6: 996500 | BH6: =MAX(0,BG6-BF6) -> 950 | BI6: =BH6-BH5 -> 85 | BJ6: =(BH6/'Finance Only'!B9)*100 -> 3.2048038 | BK6: =BL5 -> 1471100 | BL6: 1471700 | BM6: =MAX(0,BL6-BK6) -> 600 | BN6: =BM6-BM5 -> -605 | BO6: =(BM6/'Finance Only'!B9)*100 -> 2.0240866 | BP6: =BQ5 -> 105150 | BQ6: 105290 | BR6: =MAX(0,BQ6-BP6) -> 140 | BS6: =BR6-BR5 -> -804 | BT6: =(BR6/'Finance Only'!B9)*100 -> 0.47228688 | BU6: =BV5 -> 484910 | BV6: 485390 | BW6: =MAX(0,BV6-BU6) -> 480 | BX6: =BW6-BW5 -> 125 | BY6: =(BW6/'Finance Only'!B9)*100 -> 1.6192693 | BZ6: =CA5 -> 828180 | CA6: 829510 | CB6: =MAX(0,CA6-BZ6) -> 1330 | CC6: =CB6-CB5 -> 80 | CD6: =(CB6/'Finance Only'!B9)*100 -> 4.4867254 | CE6: =CF5 -> 259570 | CF6: 259980 | CG6: =MAX(0,CF6-CE6) -> 410 | CH6: =CG6-CG5 -> 30 | CI6: =(CG6/'Finance Only'!B9)*100 -> 1.3831259 | CJ6: =CK5 -> 602850 | CK6: 603970 | CL6: =MAX(0,CK6-CJ6) -> 1120 | CM6: =CL6-CL5 -> -150 | CN6: =(CL6/'Finance Only'!B9)*100 -> 3.778295 | CO6: =CP5 -> 49320 | CP6: 49467 | CQ6: =MAX(0,CP6-CO6) -> 147 | CR6: =CQ6-CQ5 -> 17 | CS6: =(CQ6/'Finance Only'!B9)*100 -> 0.49590122 | CT6: =CU5 -> 41615 | CU6: 41704 | CV6: =MAX(0,CU6-CT6) -> 89 | CW6: =CV6-CV5 -> 4 | CX6: =(CV6/'Finance Only'!B9)*100 -> 0.30023952 | CY6: =CZ5 -> 69942 | CZ6: 70065 | DA6: =MAX(0,CZ6-CY6) -> 123 | DB6: =DA6-DA5 -> -1 | DC6: =(DA6/'Finance Only'!B9)*100 -> 0.41493776 | DD6: =DE5 -> 530250 | DE6: 531180 | DF6: =MAX(0,DE6-DD6) -> 930 | DG6: =DF6-DF5 -> -30 | DH6: =(DF6/'Finance Only'!B9)*100 -> 3.1373343 | DI6: =DJ5 -> 473270 | DJ6: 474000 | DK6: =MAX(0,DJ6-DI6) -> 730 | DL6: =DK6-DK5 -> -50 | DM6: =(DK6/'Finance Only'!B9)*100 -> 2.4626387 | DN6: =DO5 -> 271990 | DO6: 272390 | DP6: =MAX(0,DO6-DN6) -> 400 | DQ6: =DP6-DP5 -> 20 | DR6: =(DP6/'Finance Only'!B9)*100 -> 1.3493911 | DS6: =DT5 -> 846130 | DT6: 847590 | DU6: =MAX(0,DT6-DS6) -> 1460 | DV6: =DU6-DU5 -> 210 | DW6: =(DU6/'Finance Only'!B9)*100 -> 4.9252775 | DX6: =DY5 -> 536300 | DY6: 537100 | DZ6: =MAX(0,DY6-DX6) -> 800 | EA6: =DZ6-DZ5 -> 0 | EB6: =(DZ6/'Finance Only'!B9)*100 -> 2.6987822 | EC6: =ED5 -> 173530 | ED6: 173830 | EE6: =MAX(0,ED6-EC6) -> 300 | EF6: =EE6-EE5 -> 10 | EG6: =(EE6/'Finance Only'!B9)*100 -> 1.0120433 | EH6: =EI5 -> 181540 | EI6: 181900 | EJ6: =MAX(0,EI6-EH6) -> 360 | EK6: =EJ6-EJ5 -> -30 | EL6: =(EJ6/'Finance Only'!B9)*100 -> 1.214452 | EM6: =EN5 -> 320630 | EN6: 321130 | EO6: =MAX(0,EN6-EM6) -> 500 | EP6: =EO6-EO5 -> -10 | EQ6: =(EO6/'Finance Only'!B9)*100 -> 1.6867389 | ER6: =ES5 -> 0 | ET6: =MAX(0,ES6-ER6) -> 0 | EU6: =ET6-ET5 -> 0 | EV6: =(ET6/'Finance Only'!B9)*100 -> 0 | EW6: =EX5 -> 50025 | EX6: 50974 | EY6: =MAX(0,EX6-EW6) -> 949 | EZ6: =EY6-EY5 -> 74 | FA6: =(EY6/'Finance Only'!G9)*100 -> #DIV/0! | FB6: =FC5 -> 14420 | FC6: 15012 | FD6: =MAX(0,FC6-FB6) -> 592 | FE6: =FD6-FD5 -> 18 | FF6: =(FD6/'Finance Only'!M9)*100 -> #DIV/0! | FL6: =FM5 -> 0 | FN6: =MAX(0,FM6-FL6) -> 0 | FO6: =FN6-FN5 -> 0 | FP6: =(FN6/'Finance Only'!R9)*100 -> #DIV/0! | FR6: =SUM(E6+J6) -> 9640 | FT6: =SUM(T6+Y6+DZ6+EE6+EJ6+EO6) -> 7445 | FV6: =SUM(AN6+AS6) -> 2380 | FX6: =SUM(AX6+BC6+BH6) -> 2062 | FZ6: =SUM(BM6+BR6+ET6) -> 740 | GB6: =SUM(EY6+FD6) -> 1541
A7: 3 | B7: ='Finance Only'!G10 -> 0 | C7: =D6 -> 26380419 | E7: =MAX(0,D7-C7) -> 0 | F7: =E7-E6 -> -4133 | G7: =(E7/'Finance Only'!B10)*100 -> #DIV/0! | H7: =I6 -> 23992466 | J7: =MAX(0,I7-H7) -> 0 | K7: =J7-J6 -> -5507 | L7: =(J7/'Finance Only'!B10)*100 -> #DIV/0! | M7: =N6 -> 89636680 | O7: =MAX(0,N7-M7) -> 0 | P7: =O7-O6 -> -13964 | Q7: =(O7/'Finance Only'!B10)*100 -> #DIV/0! | R7: =S6 -> 2535200 | T7: =MAX(0,S7-R7) -> 0 | U7: =T7-T6 -> -2400 | V7: =(T7/'Finance Only'!B10)*100 -> #DIV/0! | W7: =X6 -> 3526229 | Y7: =MAX(0,X7-W7) -> 0 | Z7: =Y7-Y6 -> -3085 | AA7: =(Y7/'Finance Only'!B10)*100 -> #DIV/0! | AB7: =AC6 -> 2236000 | AD7: =MAX(0,AC7-AB7) -> 0 | AE7: =AD7-AD6 -> -2300 | AF7: =(AD7/'Finance Only'!B10)*100 -> #DIV/0! | AG7: =AH6 -> 962738 | AI7: =MAX(0,AH7-AG7) -> 0 | AJ7: =AI7-AI6 -> -867 | AK7: =(AI7/'Finance Only'!B10)*100 -> #DIV/0! | AL7: =AM6 -> 956910 | AN7: =MAX(0,AM7-AL7) -> 0 | AO7: =AN7-AN6 -> -680 | AP7: =(AN7/'Finance Only'!B10)*100 -> #DIV/0! | AQ7: =AR6 -> 2176900 | AS7: =MAX(0,AR7-AQ7) -> 0 | AT7: =AS7-AS6 -> -1700 | AU7: =(AS7/'Finance Only'!B10)*100 -> #DIV/0! | AV7: =AW6 -> 622960 | AX7: =MAX(0,AW7-AV7) -> 0 | AY7: =AX7-AX6 -> -432 | AZ7: =(AX7/'Finance Only'!B10)*100 -> #DIV/0! | BA7: =BB6 -> 904730 | BC7: =MAX(0,BB7-BA7) -> 0 | BD7: =BC7-BC6 -> -680 | BE7: =(BC7/'Finance Only'!B10)*100 -> #DIV/0! | BF7: =BG6 -> 996500 | BH7: =MAX(0,BG7-BF7) -> 0 | BI7: =BH7-BH6 -> -950 | BJ7: =(BH7/'Finance Only'!B10)*100 -> #DIV/0! | BK7: =BL6 -> 1471700 | BM7: =MAX(0,BL7-BK7) -> 0 | BN7: =BM7-BM6 -> -600 | BO7: =(BM7/'Finance Only'!B10)*100 -> #DIV/0! | BP7: =BQ6 -> 105290 | BR7: =MAX(0,BQ7-BP7) -> 0 | BS7: =BR7-BR6 -> -140 | BT7: =(BR7/'Finance Only'!B10)*100 -> #DIV/0! | BU7: =BV6 -> 485390 | BW7: =MAX(0,BV7-BU7) -> 0 | BX7: =BW7-BW6 -> -480 | BY7: =(BW7/'Finance Only'!B10)*100 -> #DIV/0! | BZ7: =CA6 -> 829510 | CB7: =MAX(0,CA7-BZ7) -> 0 | CC7: =CB7-CB6 -> -1330 | CD7: =(CB7/'Finance Only'!B10)*100 -> #DIV/0! | CE7: =CF6 -> 259980 | CG7: =MAX(0,CF7-CE7) -> 0 | CH7: =CG7-CG6 -> -410 | CI7: =(CG7/'Finance Only'!B10)*100 -> #DIV/0! | CJ7: =CK6 -> 603970 | CL7: =MAX(0,CK7-CJ7) -> 0 | CM7: =CL7-CL6 -> -1120 | CN7: =(CL7/'Finance Only'!B10)*100 -> #DIV/0! | CO7: =CP6 -> 49467 | CQ7: =MAX(0,CP7-CO7) -> 0 | CR7: =CQ7-CQ6 -> -147 | CS7: =(CQ7/'Finance Only'!B10)*100 -> #DIV/0! | CT7: =CU6 -> 41704 | CV7: =MAX(0,CU7-CT7) -> 0 | CW7: =CV7-CV6 -> -89 | CX7: =(CV7/'Finance Only'!B10)*100 -> #DIV/0! | CY7: =CZ6 -> 70065 | DA7: =MAX(0,CZ7-CY7) -> 0 | DB7: =DA7-DA6 -> -123 | DC7: =(DA7/'Finance Only'!B10)*100 -> #DIV/0! | DD7: =DE6 -> 531180 | DF7: =MAX(0,DE7-DD7) -> 0 | DG7: =DF7-DF6 -> -930 | DH7: =(DF7/'Finance Only'!B10)*100 -> #DIV/0! | DI7: =DJ6 -> 474000 | DK7: =MAX(0,DJ7-DI7) -> 0 | DL7: =DK7-DK6 -> -730 | DM7: =(DK7/'Finance Only'!B10)*100 -> #DIV/0! | DN7: =DO6 -> 272390 | DP7: =MAX(0,DO7-DN7) -> 0 | DQ7: =DP7-DP6 -> -400 | DR7: =(DP7/'Finance Only'!B10)*100 -> #DIV/0! | DS7: =DT6 -> 847590 | DU7: =MAX(0,DT7-DS7) -> 0 | DV7: =DU7-DU6 -> -1460 | DW7: =(DU7/'Finance Only'!B10)*100 -> #DIV/0! | DX7: =DY6 -> 537100 | DZ7: =MAX(0,DY7-DX7) -> 0 | EA7: =DZ7-DZ6 -> -800 | EB7: =(DZ7/'Finance Only'!B10)*100 -> #DIV/0! | EC7: =ED6 -> 173830 | EE7: =MAX(0,ED7-EC7) -> 0 | EF7: =EE7-EE6 -> -300 | EG7: =(EE7/'Finance Only'!B10)*100 -> #DIV/0! | EH7: =EI6 -> 181900 | EJ7: =MAX(0,EI7-EH7) -> 0 | EK7: =EJ7-EJ6 -> -360 | EL7: =(EJ7/'Finance Only'!B10)*100 -> #DIV/0! | EM7: =EN6 -> 321130 | EO7: =MAX(0,EN7-EM7) -> 0 | EP7: =EO7-EO6 -> -500 | EQ7: =(EO7/'Finance Only'!B10)*100 -> #DIV/0! | ER7: =ES6 -> 0 | ET7: =MAX(0,ES7-ER7) -> 0 | EU7: =ET7-ET6 -> 0 | EV7: =(ET7/'Finance Only'!B10)*100 -> #DIV/0! | EW7: =EX6 -> 50974 | EY7: =MAX(0,EX7-EW7) -> 0 | EZ7: =EY7-EY6 -> -949 | FA7: =(EY7/'Finance Only'!G10)*100 -> #DIV/0! | FB7: =FC6 -> 15012 | FD7: =MAX(0,FC7-FB7) -> 0 | FE7: =FD7-FD6 -> -592 | FF7: =(FD7/'Finance Only'!M10)*100 -> #DIV/0! | FL7: =FM6 -> 0 | FN7: =MAX(0,FM7-FL7) -> 0 | FO7: =FN7-FN6 -> 0 | FP7: =(FN7/'Finance Only'!R10)*100 -> #DIV/0! | FR7: =SUM(E7+J7) -> 0 | FT7: =SUM(T7+Y7+DZ7+EE7+EJ7+EO7) -> 0 | FV7: =SUM(AN7+AS7) -> 0 | FX7: =SUM(AX7+BC7+BH7) -> 0 | FZ7: =SUM(BM7+BR7+ET7) -> 0 | GB7: =SUM(EY7+FD7) -> 0
A8: 4 | B8: ='Finance Only'!G11 -> 0 | C8: =D7 -> 0 | E8: =MAX(0,D8-C8) -> 0 | F8: =E8-E7 -> 0 | G8: =(E8/'Finance Only'!B11)*100 -> #DIV/0! | H8: =I7 -> 0 | J8: =MAX(0,I8-H8) -> 0 | K8: =J8-J7 -> 0 | L8: =(J8/'Finance Only'!B11)*100 -> #DIV/0! | M8: =N7 -> 0 | O8: =MAX(0,N8-M8) -> 0 | P8: =O8-O7 -> 0 | Q8: =(O8/'Finance Only'!B11)*100 -> #DIV/0! | R8: =S7 -> 0 | T8: =MAX(0,S8-R8) -> 0 | U8: =T8-T7 -> 0 | V8: =(T8/'Finance Only'!B11)*100 -> #DIV/0! | W8: =X7 -> 0 | Y8: =MAX(0,X8-W8) -> 0 | Z8: =Y8-Y7 -> 0 | AA8: =(Y8/'Finance Only'!B11)*100 -> #DIV/0! | AB8: =AC7 -> 0 | AD8: =MAX(0,AC8-AB8) -> 0 | AE8: =AD8-AD7 -> 0 | AF8: =(AD8/'Finance Only'!B11)*100 -> #DIV/0! | AG8: =AH7 -> 0 | AI8: =MAX(0,AH8-AG8) -> 0 | AJ8: =AI8-AI7 -> 0 | AK8: =(AI8/'Finance Only'!B11)*100 -> #DIV/0! | AL8: =AM7 -> 0 | AN8: =MAX(0,AM8-AL8) -> 0 | AO8: =AN8-AN7 -> 0 | AP8: =(AN8/'Finance Only'!B11)*100 -> #DIV/0! | AQ8: =AR7 -> 0 | AS8: =MAX(0,AR8-AQ8) -> 0 | AT8: =AS8-AS7 -> 0 | AU8: =(AS8/'Finance Only'!B11)*100 -> #DIV/0! | AV8: =AW7 -> 0 | AX8: =MAX(0,AW8-AV8) -> 0 | AY8: =AX8-AX7 -> 0 | AZ8: =(AX8/'Finance Only'!B11)*100 -> #DIV/0! | BA8: =BB7 -> 0 | BC8: =MAX(0,BB8-BA8) -> 0 | BD8: =BC8-BC7 -> 0 | BE8: =(BC8/'Finance Only'!B11)*100 -> #DIV/0! | BF8: =BG7 -> 0 | BH8: =MAX(0,BG8-BF8) -> 0 | BI8: =BH8-BH7 -> 0 | BJ8: =(BH8/'Finance Only'!B11)*100 -> #DIV/0! | BK8: =BL7 -> 0 | BM8: =MAX(0,BL8-BK8) -> 0 | BN8: =BM8-BM7 -> 0 | BO8: =(BM8/'Finance Only'!B11)*100 -> #DIV/0! | BP8: =BQ7 -> 0 | BR8: =MAX(0,BQ8-BP8) -> 0 | BS8: =BR8-BR7 -> 0 | BT8: =(BR8/'Finance Only'!B11)*100 -> #DIV/0! | BU8: =BV7 -> 0 | BW8: =MAX(0,BV8-BU8) -> 0 | BX8: =BW8-BW7 -> 0 | BY8: =(BW8/'Finance Only'!B11)*100 -> #DIV/0! | BZ8: =CA7 -> 0 | CB8: =MAX(0,CA8-BZ8) -> 0 | CC8: =CB8-CB7 -> 0 | CD8: =(CB8/'Finance Only'!B11)*100 -> #DIV/0! | CE8: =CF7 -> 0 | CG8: =MAX(0,CF8-CE8) -> 0 | CH8: =CG8-CG7 -> 0 | CI8: =(CG8/'Finance Only'!B11)*100 -> #DIV/0! | CJ8: =CK7 -> 0 | CL8: =MAX(0,CK8-CJ8) -> 0 | CM8: =CL8-CL7 -> 0 | CN8: =(CL8/'Finance Only'!B11)*100 -> #DIV/0! | CO8: =CP7 -> 0 | CQ8: =MAX(0,CP8-CO8) -> 0 | CR8: =CQ8-CQ7 -> 0 | CS8: =(CQ8/'Finance Only'!B11)*100 -> #DIV/0! | CT8: =CU7 -> 0 | CV8: =MAX(0,CU8-CT8) -> 0 | CW8: =CV8-CV7 -> 0 | CX8: =(CV8/'Finance Only'!B11)*100 -> #DIV/0! | CY8: =CZ7 -> 0 | DA8: =MAX(0,CZ8-CY8) -> 0 | DB8: =DA8-DA7 -> 0 | DC8: =(DA8/'Finance Only'!B11)*100 -> #DIV/0! | DD8: =DE7 -> 0 | DF8: =MAX(0,DE8-DD8) -> 0 | DG8: =DF8-DF7 -> 0 | DH8: =(DF8/'Finance Only'!B11)*100 -> #DIV/0! | DI8: =DJ7 -> 0 | DK8: =MAX(0,DJ8-DI8) -> 0 | DL8: =DK8-DK7 -> 0 | DM8: =(DK8/'Finance Only'!B11)*100 -> #DIV/0! | DN8: =DO7 -> 0 | DP8: =MAX(0,DO8-DN8) -> 0 | DQ8: =DP8-DP7 -> 0 | DR8: =(DP8/'Finance Only'!B11)*100 -> #DIV/0! | DS8: =DT7 -> 0 | DU8: =MAX(0,DT8-DS8) -> 0 | DV8: =DU8-DU7 -> 0 | DW8: =(DU8/'Finance Only'!B11)*100 -> #DIV/0! | DX8: =DY7 -> 0 | DZ8: =MAX(0,DY8-DX8) -> 0 | EA8: =DZ8-DZ7 -> 0 | EB8: =(DZ8/'Finance Only'!B11)*100 -> #DIV/0! | EC8: =ED7 -> 0 | EE8: =MAX(0,ED8-EC8) -> 0 | EF8: =EE8-EE7 -> 0 | EG8: =(EE8/'Finance Only'!B11)*100 -> #DIV/0! | EH8: =EI7 -> 0 | EJ8: =MAX(0,EI8-EH8) -> 0 | EK8: =EJ8-EJ7 -> 0 | EL8: =(EJ8/'Finance Only'!B11)*100 -> #DIV/0! | EM8: =EN7 -> 0 | EO8: =MAX(0,EN8-EM8) -> 0 | EP8: =EO8-EO7 -> 0 | EQ8: =(EO8/'Finance Only'!B11)*100 -> #DIV/0! | ER8: =ES7 -> 0 | ET8: =MAX(0,ES8-ER8) -> 0 | EU8: =ET8-ET7 -> 0 | EV8: =(ET8/'Finance Only'!B11)*100 -> #DIV/0! | EW8: =EX7 -> 0 | EY8: =MAX(0,EX8-EW8) -> 0 | EZ8: =EY8-EY7 -> 0 | FA8: =(EY8/'Finance Only'!G11)*100 -> #DIV/0! | FB8: =FC7 -> 0 | FD8: =MAX(0,FC8-FB8) -> 0 | FE8: =FD8-FD7 -> 0 | FF8: =(FD8/'Finance Only'!M11)*100 -> #DIV/0! | FL8: =FM7 -> 0 | FN8: =MAX(0,FM8-FL8) -> 0 | FO8: =FN8-FN7 -> 0 | FP8: =(FN8/'Finance Only'!R11)*100 -> #DIV/0! | FR8: =SUM(E8+J8) -> 0 | FT8: =SUM(T8+Y8+DZ8+EE8+EJ8+EO8) -> 0 | FV8: =SUM(AN8+AS8) -> 0 | FX8: =SUM(AX8+BC8+BH8) -> 0 | FZ8: =SUM(BM8+BR8+ET8) -> 0 | GB8: =SUM(EY8+FD8) -> 0
A9: 5 | B9: ='Finance Only'!G12 -> 0 | C9: =D8 -> 0 | E9: =MAX(0,D9-C9) -> 0 | F9: =E9-E8 -> 0 | G9: =(E9/'Finance Only'!B12)*100 -> #DIV/0! | H9: =I8 -> 0 | J9: =MAX(0,I9-H9) -> 0 | K9: =J9-J8 -> 0 | L9: =(J9/'Finance Only'!B12)*100 -> #DIV/0! | M9: =N8 -> 0 | O9: =MAX(0,N9-M9) -> 0 | P9: =O9-O8 -> 0 | Q9: =(O9/'Finance Only'!B12)*100 -> #DIV/0! | R9: =S8 -> 0 | T9: =MAX(0,S9-R9) -> 0 | U9: =T9-T8 -> 0 | V9: =(T9/'Finance Only'!B12)*100 -> #DIV/0! | W9: =X8 -> 0 | Y9: =MAX(0,X9-W9) -> 0 | Z9: =Y9-Y8 -> 0 | AA9: =(Y9/'Finance Only'!B12)*100 -> #DIV/0! | AB9: =AC8 -> 0 | AD9: =MAX(0,AC9-AB9) -> 0 | AE9: =AD9-AD8 -> 0 | AF9: =(AD9/'Finance Only'!B12)*100 -> #DIV/0! | AG9: =AH8 -> 0 | AI9: =MAX(0,AH9-AG9) -> 0 | AJ9: =AI9-AI8 -> 0 | AK9: =(AI9/'Finance Only'!B12)*100 -> #DIV/0! | AL9: =AM8 -> 0 | AN9: =MAX(0,AM9-AL9) -> 0 | AO9: =AN9-AN8 -> 0 | AP9: =(AN9/'Finance Only'!B12)*100 -> #DIV/0! | AQ9: =AR8 -> 0 | AS9: =MAX(0,AR9-AQ9) -> 0 | AT9: =AS9-AS8 -> 0 | AU9: =(AS9/'Finance Only'!B12)*100 -> #DIV/0! | AV9: =AW8 -> 0 | AX9: =MAX(0,AW9-AV9) -> 0 | AY9: =AX9-AX8 -> 0 | AZ9: =(AX9/'Finance Only'!B12)*100 -> #DIV/0! | BA9: =BB8 -> 0 | BC9: =MAX(0,BB9-BA9) -> 0 | BD9: =BC9-BC8 -> 0 | BE9: =(BC9/'Finance Only'!B12)*100 -> #DIV/0! | BF9: =BG8 -> 0 | BH9: =MAX(0,BG9-BF9) -> 0 | BI9: =BH9-BH8 -> 0 | BJ9: =(BH9/'Finance Only'!B12)*100 -> #DIV/0! | BK9: =BL8 -> 0 | BM9: =MAX(0,BL9-BK9) -> 0 | BN9: =BM9-BM8 -> 0 | BO9: =(BM9/'Finance Only'!B12)*100 -> #DIV/0! | BP9: =BQ8 -> 0 | BR9: =MAX(0,BQ9-BP9) -> 0 | BS9: =BR9-BR8 -> 0 | BT9: =(BR9/'Finance Only'!B12)*100 -> #DIV/0! | BU9: =BV8 -> 0 | BW9: =MAX(0,BV9-BU9) -> 0 | BX9: =BW9-BW8 -> 0 | BY9: =(BW9/'Finance Only'!B12)*100 -> #DIV/0! | BZ9: =CA8 -> 0 | CB9: =MAX(0,CA9-BZ9) -> 0 | CC9: =CB9-CB8 -> 0 | CD9: =(CB9/'Finance Only'!B12)*100 -> #DIV/0! | CE9: =CF8 -> 0 | CG9: =MAX(0,CF9-CE9) -> 0 | CH9: =CG9-CG8 -> 0 | CI9: =(CG9/'Finance Only'!B12)*100 -> #DIV/0! | CJ9: =CK8 -> 0 | CL9: =MAX(0,CK9-CJ9) -> 0 | CM9: =CL9-CL8 -> 0 | CN9: =(CL9/'Finance Only'!B12)*100 -> #DIV/0! | CO9: =CP8 -> 0 | CQ9: =MAX(0,CP9-CO9) -> 0 | CR9: =CQ9-CQ8 -> 0 | CS9: =(CQ9/'Finance Only'!B12)*100 -> #DIV/0! | CT9: =CU8 -> 0 | CV9: =MAX(0,CU9-CT9) -> 0 | CW9: =CV9-CV8 -> 0 | CX9: =(CV9/'Finance Only'!B12)*100 -> #DIV/0! | CY9: =CZ8 -> 0 | DA9: =MAX(0,CZ9-CY9) -> 0 | DB9: =DA9-DA8 -> 0 | DC9: =(DA9/'Finance Only'!B12)*100 -> #DIV/0! | DD9: =DE8 -> 0 | DF9: =MAX(0,DE9-DD9) -> 0 | DG9: =DF9-DF8 -> 0 | DH9: =(DF9/'Finance Only'!B12)*100 -> #DIV/0! | DI9: =DJ8 -> 0 | DK9: =MAX(0,DJ9-DI9) -> 0 | DL9: =DK9-DK8 -> 0 | DM9: =(DK9/'Finance Only'!B12)*100 -> #DIV/0! | DN9: =DO8 -> 0 | DP9: =MAX(0,DO9-DN9) -> 0 | DQ9: =DP9-DP8 -> 0 | DR9: =(DP9/'Finance Only'!B12)*100 -> #DIV/0! | DS9: =DT8 -> 0 | DU9: =MAX(0,DT9-DS9) -> 0 | DV9: =DU9-DU8 -> 0 | DW9: =(DU9/'Finance Only'!B12)*100 -> #DIV/0! | DX9: =DY8 -> 0 | DZ9: =MAX(0,DY9-DX9) -> 0 | EA9: =DZ9-DZ8 -> 0 | EB9: =(DZ9/'Finance Only'!B12)*100 -> #DIV/0! | EC9: =ED8 -> 0 | EE9: =MAX(0,ED9-EC9) -> 0 | EF9: =EE9-EE8 -> 0 | EG9: =(EE9/'Finance Only'!B12)*100 -> #DIV/0! | EH9: =EI8 -> 0 | EJ9: =MAX(0,EI9-EH9) -> 0 | EK9: =EJ9-EJ8 -> 0 | EL9: =(EJ9/'Finance Only'!B12)*100 -> #DIV/0! | EM9: =EN8 -> 0 | EO9: =MAX(0,EN9-EM9) -> 0 | EP9: =EO9-EO8 -> 0 | EQ9: =(EO9/'Finance Only'!B12)*100 -> #DIV/0! | ER9: =ES8 -> 0 | ET9: =MAX(0,ES9-ER9) -> 0 | EU9: =ET9-ET8 -> 0 | EV9: =(ET9/'Finance Only'!B12)*100 -> #DIV/0! | EW9: =EX8 -> 0 | EY9: =MAX(0,EX9-EW9) -> 0 | EZ9: =EY9-EY8 -> 0 | FA9: =(EY9/'Finance Only'!G12)*100 -> #DIV/0! | FB9: =FC8 -> 0 | FD9: =MAX(0,FC9-FB9) -> 0 | FE9: =FD9-FD8 -> 0 | FF9: =(FD9/'Finance Only'!M12)*100 -> #DIV/0! | FL9: =FM8 -> 0 | FN9: =MAX(0,FM9-FL9) -> 0 | FO9: =FN9-FN8 -> 0 | FP9: =(FN9/'Finance Only'!R12)*100 -> #DIV/0! | FR9: =SUM(E9+J9) -> 0 | FT9: =SUM(T9+Y9+DZ9+EE9+EJ9+EO9) -> 0 | FV9: =SUM(AN9+AS9) -> 0 | FX9: =SUM(AX9+BC9+BH9) -> 0 | FZ9: =SUM(BM9+BR9+ET9) -> 0 | GB9: =SUM(EY9+FD9) -> 0
A10: 6 | B10: ='Finance Only'!G13 -> 0 | C10: =D9 -> 0 | E10: =MAX(0,D10-C10) -> 0 | F10: =E10-E9 -> 0 | G10: =(E10/'Finance Only'!B13)*100 -> #DIV/0! | H10: =I9 -> 0 | J10: =MAX(0,I10-H10) -> 0 | K10: =J10-J9 -> 0 | L10: =(J10/'Finance Only'!B13)*100 -> #DIV/0! | M10: =N9 -> 0 | O10: =MAX(0,N10-M10) -> 0 | P10: =O10-O9 -> 0 | Q10: =(O10/'Finance Only'!B13)*100 -> #DIV/0! | R10: =S9 -> 0 | T10: =MAX(0,S10-R10) -> 0 | U10: =T10-T9 -> 0 | V10: =(T10/'Finance Only'!B13)*100 -> #DIV/0! | W10: =X9 -> 0 | Y10: =MAX(0,X10-W10) -> 0 | Z10: =Y10-Y9 -> 0 | AA10: =(Y10/'Finance Only'!B13)*100 -> #DIV/0! | AB10: =AC9 -> 0 | AD10: =MAX(0,AC10-AB10) -> 0 | AE10: =AD10-AD9 -> 0 | AF10: =(AD10/'Finance Only'!B13)*100 -> #DIV/0! | AG10: =AH9 -> 0 | AI10: =MAX(0,AH10-AG10) -> 0 | AJ10: =AI10-AI9 -> 0 | AK10: =(AI10/'Finance Only'!B13)*100 -> #DIV/0! | AL10: =AM9 -> 0 | AN10: =MAX(0,AM10-AL10) -> 0 | AO10: =AN10-AN9 -> 0 | AP10: =(AN10/'Finance Only'!B13)*100 -> #DIV/0! | AQ10: =AR9 -> 0 | AS10: =MAX(0,AR10-AQ10) -> 0 | AT10: =AS10-AS9 -> 0 | AU10: =(AS10/'Finance Only'!B13)*100 -> #DIV/0! | AV10: =AW9 -> 0 | AX10: =MAX(0,AW10-AV10) -> 0 | AY10: =AX10-AX9 -> 0 | AZ10: =(AX10/'Finance Only'!B13)*100 -> #DIV/0! | BA10: =BB9 -> 0 | BC10: =MAX(0,BB10-BA10) -> 0 | BD10: =BC10-BC9 -> 0 | BE10: =(BC10/'Finance Only'!B13)*100 -> #DIV/0! | BF10: =BG9 -> 0 | BH10: =MAX(0,BG10-BF10) -> 0 | BI10: =BH10-BH9 -> 0 | BJ10: =(BH10/'Finance Only'!B13)*100 -> #DIV/0! | BK10: =BL9 -> 0 | BM10: =MAX(0,BL10-BK10) -> 0 | BN10: =BM10-BM9 -> 0 | BO10: =(BM10/'Finance Only'!B13)*100 -> #DIV/0! | BP10: =BQ9 -> 0 | BR10: =MAX(0,BQ10-BP10) -> 0 | BS10: =BR10-BR9 -> 0 | BT10: =(BR10/'Finance Only'!B13)*100 -> #DIV/0! | BU10: =BV9 -> 0 | BW10: =MAX(0,BV10-BU10) -> 0 | BX10: =BW10-BW9 -> 0 | BY10: =(BW10/'Finance Only'!B13)*100 -> #DIV/0! | BZ10: =CA9 -> 0 | CB10: =MAX(0,CA10-BZ10) -> 0 | CC10: =CB10-CB9 -> 0 | CD10: =(CB10/'Finance Only'!B13)*100 -> #DIV/0! | CE10: =CF9 -> 0 | CG10: =MAX(0,CF10-CE10) -> 0 | CH10: =CG10-CG9 -> 0 | CI10: =(CG10/'Finance Only'!B13)*100 -> #DIV/0! | CJ10: =CK9 -> 0 | CL10: =MAX(0,CK10-CJ10) -> 0 | CM10: =CL10-CL9 -> 0 | CN10: =(CL10/'Finance Only'!B13)*100 -> #DIV/0! | CO10: =CP9 -> 0 | CQ10: =MAX(0,CP10-CO10) -> 0 | CR10: =CQ10-CQ9 -> 0 | CS10: =(CQ10/'Finance Only'!B13)*100 -> #DIV/0! | CT10: =CU9 -> 0 | CV10: =MAX(0,CU10-CT10) -> 0 | CW10: =CV10-CV9 -> 0 | CX10: =(CV10/'Finance Only'!B13)*100 -> #DIV/0! | CY10: =CZ9 -> 0 | DA10: =MAX(0,CZ10-CY10) -> 0 | DB10: =DA10-DA9 -> 0 | DC10: =(DA10/'Finance Only'!B13)*100 -> #DIV/0! | DD10: =DE9 -> 0 | DF10: =MAX(0,DE10-DD10) -> 0 | DG10: =DF10-DF9 -> 0 | DH10: =(DF10/'Finance Only'!B13)*100 -> #DIV/0! | DI10: =DJ9 -> 0 | DK10: =MAX(0,DJ10-DI10) -> 0 | DL10: =DK10-DK9 -> 0 | DM10: =(DK10/'Finance Only'!B13)*100 -> #DIV/0! | DN10: =DO9 -> 0 | DP10: =MAX(0,DO10-DN10) -> 0 | DQ10: =DP10-DP9 -> 0 | DR10: =(DP10/'Finance Only'!B13)*100 -> #DIV/0! | DS10: =DT9 -> 0 | DU10: =MAX(0,DT10-DS10) -> 0 | DV10: =DU10-DU9 -> 0 | DW10: =(DU10/'Finance Only'!B13)*100 -> #DIV/0! | DX10: =DY9 -> 0 | DZ10: =MAX(0,DY10-DX10) -> 0 | EA10: =DZ10-DZ9 -> 0 | EB10: =(DZ10/'Finance Only'!B13)*100 -> #DIV/0! | EC10: =ED9 -> 0 | EE10: =MAX(0,ED10-EC10) -> 0 | EF10: =EE10-EE9 -> 0 | EG10: =(EE10/'Finance Only'!B13)*100 -> #DIV/0! | EH10: =EI9 -> 0 | EJ10: =MAX(0,EI10-EH10) -> 0 | EK10: =EJ10-EJ9 -> 0 | EL10: =(EJ10/'Finance Only'!B13)*100 -> #DIV/0! | EM10: =EN9 -> 0 | EO10: =MAX(0,EN10-EM10) -> 0 | EP10: =EO10-EO9 -> 0 | EQ10: =(EO10/'Finance Only'!B13)*100 -> #DIV/0! | ER10: =ES9 -> 0 | ET10: =MAX(0,ES10-ER10) -> 0 | EU10: =ET10-ET9 -> 0 | EV10: =(ET10/'Finance Only'!B13)*100 -> #DIV/0! | EW10: =EX9 -> 0 | EY10: =MAX(0,EX10-EW10) -> 0 | EZ10: =EY10-EY9 -> 0 | FA10: =(EY10/'Finance Only'!G13)*100 -> #DIV/0! | FB10: =FC9 -> 0 | FD10: =MAX(0,FC10-FB10) -> 0 | FE10: =FD10-FD9 -> 0 | FF10: =(FD10/'Finance Only'!M13)*100 -> #DIV/0! | FL10: =FM9 -> 0 | FN10: =MAX(0,FM10-FL10) -> 0 | FO10: =FN10-FN9 -> 0 | FP10: =(FN10/'Finance Only'!R13)*100 -> #DIV/0! | FR10: =SUM(E10+J10) -> 0 | FT10: =SUM(T10+Y10+DZ10+EE10+EJ10+EO10) -> 0 | FV10: =SUM(AN10+AS10) -> 0 | FX10: =SUM(AX10+BC10+BH10) -> 0 | FZ10: =SUM(BM10+BR10+ET10) -> 0 | GB10: =SUM(EY10+FD10) -> 0
A11: 7 | B11: ='Finance Only'!G14 -> 0 | C11: =D10 -> 0 | E11: =MAX(0,D11-C11) -> 0 | F11: =E11-E10 -> 0 | G11: =(E11/'Finance Only'!B14)*100 -> #DIV/0! | H11: =I10 -> 0 | J11: =MAX(0,I11-H11) -> 0 | K11: =J11-J10 -> 0 | L11: =(J11/'Finance Only'!B14)*100 -> #DIV/0! | M11: =N10 -> 0 | O11: =MAX(0,N11-M11) -> 0 | P11: =O11-O10 -> 0 | Q11: =(O11/'Finance Only'!B14)*100 -> #DIV/0! | R11: =S10 -> 0 | T11: =MAX(0,S11-R11) -> 0 | U11: =T11-T10 -> 0 | V11: =(T11/'Finance Only'!B14)*100 -> #DIV/0! | W11: =X10 -> 0 | Y11: =MAX(0,X11-W11) -> 0 | Z11: =Y11-Y10 -> 0 | AA11: =(Y11/'Finance Only'!B14)*100 -> #DIV/0! | AB11: =AC10 -> 0 | AD11: =MAX(0,AC11-AB11) -> 0 | AE11: =AD11-AD10 -> 0 | AF11: =(AD11/'Finance Only'!B14)*100 -> #DIV/0! | AG11: =AH10 -> 0 | AI11: =MAX(0,AH11-AG11) -> 0 | AJ11: =AI11-AI10 -> 0 | AK11: =(AI11/'Finance Only'!B14)*100 -> #DIV/0! | AL11: =AM10 -> 0 | AN11: =MAX(0,AM11-AL11) -> 0 | AO11: =AN11-AN10 -> 0 | AP11: =(AN11/'Finance Only'!B14)*100 -> #DIV/0! | AQ11: =AR10 -> 0 | AS11: =MAX(0,AR11-AQ11) -> 0 | AT11: =AS11-AS10 -> 0 | AU11: =(AS11/'Finance Only'!B14)*100 -> #DIV/0! | AV11: =AW10 -> 0 | AX11: =MAX(0,AW11-AV11) -> 0 | AY11: =AX11-AX10 -> 0 | AZ11: =(AX11/'Finance Only'!B14)*100 -> #DIV/0! | BA11: =BB10 -> 0 | BC11: =MAX(0,BB11-BA11) -> 0 | BD11: =BC11-BC10 -> 0 | BE11: =(BC11/'Finance Only'!B14)*100 -> #DIV/0! | BF11: =BG10 -> 0 | BH11: =MAX(0,BG11-BF11) -> 0 | BI11: =BH11-BH10 -> 0 | BJ11: =(BH11/'Finance Only'!B14)*100 -> #DIV/0! | BK11: =BL10 -> 0 | BM11: =MAX(0,BL11-BK11) -> 0 | BN11: =BM11-BM10 -> 0 | BO11: =(BM11/'Finance Only'!B14)*100 -> #DIV/0! | BP11: =BQ10 -> 0 | BR11: =MAX(0,BQ11-BP11) -> 0 | BS11: =BR11-BR10 -> 0 | BT11: =(BR11/'Finance Only'!B14)*100 -> #DIV/0! | BU11: =BV10 -> 0 | BW11: =MAX(0,BV11-BU11) -> 0 | BX11: =BW11-BW10 -> 0 | BY11: =(BW11/'Finance Only'!B14)*100 -> #DIV/0! | BZ11: =CA10 -> 0 | CB11: =MAX(0,CA11-BZ11) -> 0 | CC11: =CB11-CB10 -> 0 | CD11: =(CB11/'Finance Only'!B14)*100 -> #DIV/0! | CE11: =CF10 -> 0 | CG11: =MAX(0,CF11-CE11) -> 0 | CH11: =CG11-CG10 -> 0 | CI11: =(CG11/'Finance Only'!B14)*100 -> #DIV/0! | CJ11: =CK10 -> 0 | CL11: =MAX(0,CK11-CJ11) -> 0 | CM11: =CL11-CL10 -> 0 | CN11: =(CL11/'Finance Only'!B14)*100 -> #DIV/0! | CO11: =CP10 -> 0 | CQ11: =MAX(0,CP11-CO11) -> 0 | CR11: =CQ11-CQ10 -> 0 | CS11: =(CQ11/'Finance Only'!B14)*100 -> #DIV/0! | CT11: =CU10 -> 0 | CV11: =MAX(0,CU11-CT11) -> 0 | CW11: =CV11-CV10 -> 0 | CX11: =(CV11/'Finance Only'!B14)*100 -> #DIV/0! | CY11: =CZ10 -> 0 | DA11: =MAX(0,CZ11-CY11) -> 0 | DB11: =DA11-DA10 -> 0 | DC11: =(DA11/'Finance Only'!B14)*100 -> #DIV/0! | DD11: =DE10 -> 0 | DF11: =MAX(0,DE11-DD11) -> 0 | DG11: =DF11-DF10 -> 0 | DH11: =(DF11/'Finance Only'!B14)*100 -> #DIV/0! | DI11: =DJ10 -> 0 | DK11: =MAX(0,DJ11-DI11) -> 0 | DL11: =DK11-DK10 -> 0 | DM11: =(DK11/'Finance Only'!B14)*100 -> #DIV/0! | DN11: =DO10 -> 0 | DP11: =MAX(0,DO11-DN11) -> 0 | DQ11: =DP11-DP10 -> 0 | DR11: =(DP11/'Finance Only'!B14)*100 -> #DIV/0! | DS11: =DT10 -> 0 | DU11: =MAX(0,DT11-DS11) -> 0 | DV11: =DU11-DU10 -> 0 | DW11: =(DU11/'Finance Only'!B14)*100 -> #DIV/0! | DX11: =DY10 -> 0 | DZ11: =MAX(0,DY11-DX11) -> 0 | EA11: =DZ11-DZ10 -> 0 | EB11: =(DZ11/'Finance Only'!B14)*100 -> #DIV/0! | EC11: =ED10 -> 0 | EE11: =MAX(0,ED11-EC11) -> 0 | EF11: =EE11-EE10 -> 0 | EG11: =(EE11/'Finance Only'!B14)*100 -> #DIV/0! | EH11: =EI10 -> 0 | EJ11: =MAX(0,EI11-EH11) -> 0 | EK11: =EJ11-EJ10 -> 0 | EL11: =(EJ11/'Finance Only'!B14)*100 -> #DIV/0! | EM11: =EN10 -> 0 | EO11: =MAX(0,EN11-EM11) -> 0 | EP11: =EO11-EO10 -> 0 | EQ11: =(EO11/'Finance Only'!B14)*100 -> #DIV/0! | ER11: =ES10 -> 0 | ET11: =MAX(0,ES11-ER11) -> 0 | EU11: =ET11-ET10 -> 0 | EV11: =(ET11/'Finance Only'!B14)*100 -> #DIV/0! | EW11: =EX10 -> 0 | EY11: =MAX(0,EX11-EW11) -> 0 | EZ11: =EY11-EY10 -> 0 | FA11: =(EY11/'Finance Only'!G14)*100 -> #DIV/0! | FB11: =FC10 -> 0 | FD11: =MAX(0,FC11-FB11) -> 0 | FE11: =FD11-FD10 -> 0 | FF11: =(FD11/'Finance Only'!M14)*100 -> #DIV/0! | FL11: =FM10 -> 0 | FN11: =MAX(0,FM11-FL11) -> 0 | FO11: =FN11-FN10 -> 0 | FP11: =(FN11/'Finance Only'!R14)*100 -> #DIV/0! | FR11: =SUM(E11+J11) -> 0 | FT11: =SUM(T11+Y11+DZ11+EE11+EJ11+EO11) -> 0 | FV11: =SUM(AN11+AS11) -> 0 | FX11: =SUM(AX11+BC11+BH11) -> 0 | FZ11: =SUM(BM11+BR11+ET11) -> 0 | GB11: =SUM(EY11+FD11) -> 0
