Workbook

Sheet TOTAL
A1: Site Name | B1: Day | C1: Month | D1: Year | E1: Total Electricity Kwh | F1: Electricity Tariff ($/Kwh) | G1: Natual Gas (m3) | H1: Natural Gas $/m3 | I1: District Energy Cooling Kwh | J1: District Energy Cooling $/Kwh | K1: Water Utility Supply (m3) m3 | L1: Water Utility Supply (m3) $/m3 | M1: Room Nights | N1: Total Guests
A2: Abu Dhabi | B2: 1 | C2: 2 | D2: 2022 | E2: =Submetering!E2+Submetering!F2+Submetering!G2+Submetering!H2+Submetering!I2+Submetering!J2+Submetering!K2 -> 31272 | F2: 0.2 | G2: =Submetering!P2 -> 702 | H2: 6.47 | I2: =Submetering!T2-Submetering!T2*15%-Submetering!X2 -> 10689.194 | J2: 0.21 | K2: =Submetering!N2-Submetering!O2 -> 87.21 | L2: 7.84 | M2: 128 | N2: =Submetering!Z2 -> 169
A3: Abu Dhabi | B3: =B2+1 -> 2 | C3: 2 | D3: 2022 | E3: =Submetering!E3+Submetering!F3+Submetering!G3+Submetering!H3+Submetering!I3+Submetering!J3+Submetering!K3 -> 31410 | F3: 0.2 | G3: =Submetering!P3 -> 728 | H3: 6.47 | I3: =Submetering!T3-Submetering!T3*15%-Submetering!X3 -> 10174.405 | J3: 0.21 | K3: =Submetering!N3-Submetering!O3 -> 133.658 | L3: 7.84 | M3: 140 | N3: =Submetering!Z3 -> 186
A4: Abu Dhabi | B4: =B3+1 -> 3 | C4: 2 | D4: 2022 | E4: =Submetering!E4+Submetering!F4+Submetering!G4+Submetering!H4+Submetering!I4+Submetering!J4+Submetering!K4 -> 32872 | F4: 0.2 | G4: =Submetering!P4 -> 795 | H4: 6.47 | I4: =Submetering!T4-Submetering!T4*15%-Submetering!X4 -> 12725.252 | J4: 0.21 | K4: =Submetering!N4-Submetering!O4 -> 151.225 | L4: 7.84 | M4: 184 | N4: =Submetering!Z4 -> 231
A5: Abu Dhabi | B5: =B4+1 -> 4 | C5: 2 | D5: 2022 | E5: =Submetering!E5+Submetering!F5+Submetering!G5+Submetering!H5+Submetering!I5+Submetering!J5+Submetering!K5 -> 31283 | F5: 0.2 | G5: =Submetering!P5 -> 771 | H5: 6.47 | I5: =Submetering!T5-Submetering!T5*15%-Submetering!X5 -> 13118.412 | J5: 0.21 | K5: =Submetering!N5-Submetering!O5 -> 125.758 | L5: 7.84 | M5: 168 | N5: =Submetering!Z5 -> 211
A6: Abu Dhabi | B6: =B5+1 -> 5 | C6: 2 | D6: 2022 | E6: =Submetering!E6+Submetering!F6+Submetering!G6+Submetering!H6+Submetering!I6+Submetering!J6+Submetering!K6 -> 31453 | F6: 0.2 | G6: =Submetering!P6 -> 798 | H6: 6.47 | I6: =Submetering!T6-Submetering!T6*15%-Submetering!X6 -> 12312.866 | J6: 0.21 | K6: =Submetering!N6-Submetering!O6 -> 120.691 | L6: 7.84 | M6: 172 | N6: =Submetering!Z6 -> 223
A7: Abu Dhabi | B7: =B6+1 -> 6 | C7: 2 | D7: 2022 | E7: =Submetering!E7+Submetering!F7+Submetering!G7+Submetering!H7+Submetering!I7+Submetering!J7+Submetering!K7 -> 32367 | F7: 0.2 | G7: =Submetering!P7 -> 774 | H7: 6.47 | I7: =Submetering!T7-Submetering!T7*15%-Submetering!X7 -> 10394.38 | J7: 0.21 | K7: =Submetering!N7-Submetering!O7 -> 144.812 | L7: 7.84 | M7: 183 | N7: =Submetering!Z7 -> 239
A8: Abu Dhabi | B8: =B7+1 -> 7 | C8: 2 | D8: 2022 | E8: =Submetering!E8+Submetering!F8+Submetering!G8+Submetering!H8+Submetering!I8+Submetering!J8+Submetering!K8 -> 33214 | F8: 0.2 | G8: =Submetering!P8 -> 781 | H8: 6.47 | I8: =Submetering!T8-Submetering!T8*15%-Submetering!X8 -> 8704.5582 | J8: 0.21 | K8: =Submetering!N8-Submetering!O8 -> 159.661 | L8: 7.84 | M8: 182 | N8: =Submetering!Z8 -> 242
A9: Abu Dhabi | B9: =B8+1 -> 8 | C9: 2 | D9: 2022 | E9: =Submetering!E9+Submetering!F9+Submetering!G9+Submetering!H9+Submetering!I9+Submetering!J9+Submetering!K9 -> 32679 | F9: 0.2 | G9: =Submetering!P9 -> 838 | H9: 6.47 | I9: =Submetering!T9-Submetering!T9*15%-Submetering!X9 -> 5997.2048 | J9: 0.21 | K9: =Submetering!N9-Submetering!O9 -> 144.211 | L9: 7.84 | M9: 187 | N9: =Submetering!Z9 -> 252
A10: Abu Dhabi | B10: =B9+1 -> 9 | C10: 2 | D10: 2022 | E10: =Submetering!E10+Submetering!F10+Submetering!G10+Submetering!H10+Submetering!I10+Submetering!J10+Submetering!K10 -> 32150 | F10: 0.2 | G10: =Submetering!P10 -> 789 | H10: 6.47 | I10: =Submetering!T10-Submetering!T10*15%-Submetering!X10 -> 9423.948 | J10: 0.21 | K10: =Submetering!N10-Submetering!O10 -> 124.293 | L10: 7.84 | M10: 189 | N10: =Submetering!Z10 -> 244
A11: Abu Dhabi | B11: =B10+1 -> 10 | C11: 2 | D11: 2022 | E11: =Submetering!E11+Submetering!F11+Submetering!G11+Submetering!H11+Submetering!I11+Submetering!J11+Submetering!K11 -> 30778 | F11: 0.2 | G11: =Submetering!P11 -> 757 | H11: 6.47 | I11: =Submetering!T11-Submetering!T11*15%-Submetering!X11 -> 11287.54 | J11: 0.21 | K11: =Submetering!N11-Submetering!O11 -> 148.883 | L11: 7.84 | M11: 168 | N11: =Submetering!Z11 -> 218
A12: Abu Dhabi | B12: =B11+1 -> 11 | C12: 2 | D12: 2022 | E12: =Submetering!E12+Submetering!F12+Submetering!G12+Submetering!H12+Submetering!I12+Submetering!J12+Submetering!K12 -> 30790 | F12: 0.2 | G12: =Submetering!P12 -> 700 | H12: 6.47 | I12: =Submetering!T12-Submetering!T12*15%-Submetering!X12 -> 11089.153 | J12: 0.21 | K12: =Submetering!N12-Submetering!O12 -> 134.02 | L12: 7.84 | M12: 174 | N12: =Submetering!Z12 -> 237
A13: Abu Dhabi | B13: =B12+1 -> 12 | C13: 2 | D13: 2022 | E13: =Submetering!E13+Submetering!F13+Submetering!G13+Submetering!H13+Submetering!I13+Submetering!J13+Submetering!K13 -> 30684 | F13: 0.2 | G13: =Submetering!P13 -> 789 | H13: 6.47 | I13: =Submetering!T13-Submetering!T13*15%-Submetering!X13 -> 11612.825 | J13: 0.21 | K13: =Submetering!N13-Submetering!O13 -> 129.813 | L13: 7.84 | M13: 170 | N13: =Submetering!Z13 -> 248
A14: Abu Dhabi | B14: =B13+1 -> 13 | C14: 2 | D14: 2022 | E14: =Submetering!E14+Submetering!F14+Submetering!G14+Submetering!H14+Submetering!I14+Submetering!J14+Submetering!K14 -> 31861 | F14: 0.2 | G14: =Submetering!P14 -> 738 | H14: 6.47 | I14: =Submetering!T14-Submetering!T14*15%-Submetering!X14 -> 7578.4104 | J14: 0.21 | K14: =Submetering!N14-Submetering!O14 -> 116.17 | L14: 7.84 | M14: 134 | N14: =Submetering!Z14 -> 187
... A29: Abu Dhabi | B29: =B28+1 -> 28 | C29: 2 | D29: 2022 | E29: =Submetering!E29+Submetering!F29+Submetering!G29+Submetering!H29+Submetering!I29+Submetering!J29+Submetering!K29 -> 31820 | F29: 0.2 | G29: =Submetering!P29 -> 786 | H29: 6.47 | I29: =Submetering!T29-Submetering!T29*15%-Submetering!X29 -> 16420.938 | J29: 0.21 | K29: =Submetering!N29-Submetering!O29 -> 135.605 | L29: 7.84 | M29: 177 | N29: =Submetering!Z29 -> 251
A30: Abu Dhabi | B30: =B29+1 -> 29 | C30: 2 | D30: 2022 | E30: =Submetering!E30+Submetering!F30+Submetering!G30+Submetering!H30+Submetering!I30+Submetering!J30+Submetering!K30 -> 0 | F30: 0.2 | G30: =Submetering!P30 -> 0 | H30: 6.47 | I30: =Submetering!T30-Submetering!T30*15%-Submetering!X30 -> 0 | J30: 0.21 | K30: =Submetering!N30-Submetering!O30 -> 0 | L30: 7.84 | M30: =Submetering!Y30 -> 0 | N30: =Submetering!Z30 -> 0
A31: Abu Dhabi | B31: =B30+1 -> 30 | C31: 2 | D31: 2022 | E31: =Submetering!E31+Submetering!F31+Submetering!G31+Submetering!H31+Submetering!I31+Submetering!J31+Submetering!K31 -> 0 | F31: 0.2 | G31: =Submetering!P31 -> 0 | H31: 6.47 | I31: =Submetering!T31-Submetering!T31*15%-Submetering!X31 -> 0 | J31: 0.21 | K31: =Submetering!N31-Submetering!O31 -> 0 | L31: 7.84 | M31: =Submetering!Y31 -> 0 | N31: =Submetering!Z31 -> 0
A32: Abu Dhabi | B32: =B31+1 -> 31 | C32: 2 | D32: 2022 | E32: =Submetering!E32+Submetering!F32+Submetering!G32+Submetering!H32+Submetering!I32+Submetering!J32+Submetering!K32 -> 0 | F32: 0.2 | G32: =Submetering!P32 -> 0 | H32: 6.47 | I32: =Submetering!T32-Submetering!T32*15%-Submetering!X32 -> 0 | J32: 0.21 | K32: =Submetering!N32-Submetering!O32 -> 0 | L32: 7.84 | M32: =Submetering!Y32 -> 0 | N32: =Submetering!Z32 -> 0
E33: =SUM(E2:E32) -> 883138 | G33: =SUM(G2:G32) -> 21713 | I33: =SUM(I2:I32) -> 314273.31 | K33: =SUM(K2:K32) -> 3675.402 | M33: =SUM(M2:M32) -> 4545 | N33: =SUM(N2:N32) -> 6191

Sheet Submetering
A1: Site Name | B1: Day | C1: Month | D1: Year | E1: LVS-1 SECTION A - KWh | F1: LVS-1 SECTION B - KWh | G1: LVS-2 (CAFE MILANO)- KWh | H1: LVS-3 SECTION A- KWh | I1: LVS-3 SECTION B- KWh | J1: LVS-4 SECTION A- KWh | K1: LVS-4 SECTION B- KWh | L1: LVS-5 (FLOOR 15-32) KWh | M1: LVS-LRLV (RETAIL)KWh | N1: Total Water- m3 | O1: Galleria Water m3 | P1: Main Gas m3 | Q1: HW Boiler Gas - m3 | R1: Steam Boiler Gas- m3 | S1: Total Kitchen- m3 | T1: Main District Cooling- KWh | U1: Podium District Cooling- KWh | V1: Guest Rooms District Cooling- KWh | W1: Residence District Cooling- KWh | X1: Galleria District Cooling KWh | Y1: Room Nights | Z1: Total Guests
A2: Abu Dhabi | B2: 1 | C2: 2 | D2: 2022 | E2: ='FS-AD Daily '!B6 -> 5883 | F2: ='FS-AD Daily '!C6 -> 4743 | G2: ='FS-AD Daily '!D6 -> 885 | H2: ='FS-AD Daily '!E6 -> 6858 | I2: ='FS-AD Daily '!F6 -> 5841 | J2: ='FS-AD Daily '!G6 -> 3289 | K2: ='FS-AD Daily '!H6 -> 3773 | L2: ='FS-AD Daily '!I6 -> 2357 | M2: ='FS-AD Daily '!J6 -> 6650 | N2: ='FS-AD Daily '!T6 -> 167.031 | O2: ='FS-AD Daily '!R6 -> 79.821 | P2: ='FS-AD Daily '!Z6 -> 702 | Q2: ='FS-AD Daily '!V6 -> 164.8 | R2: ='FS-AD Daily '!W6 -> 177.4 | S2: =P2-Q2-R2 -> 359.8 | T2: ='FS-AD Daily '!AD6*3.516 -> 42810.816 | U2: =('FS-AD Daily '!AF6)*1000 -> 21900 | V2: =('FS-AD Daily '!AG6)*1000 -> 0 | W2: ='FS-AD Daily '!AH6*1000 -> 7100 | X2: =('FS-AD Daily '!AK6)*1000 -> 25700 | Y2: 128 | Z2: 169
A3: Abu Dhabi | B3: =B2+1 -> 2 | C3: 2 | D3: 2022 | E3: ='FS-AD Daily '!B7 -> 6176 | F3: ='FS-AD Daily '!C7 -> 4634 | G3: ='FS-AD Daily '!D7 -> 842 | H3: ='FS-AD Daily '!E7 -> 6808 | I3: ='FS-AD Daily '!F7 -> 5761 | J3: ='FS-AD Daily '!G7 -> 3431 | K3: ='FS-AD Daily '!H7 -> 3758 | L3: ='FS-AD Daily '!I7 -> 2282 | M3: ='FS-AD Daily '!J7 -> 6951 | N3: ='FS-AD Daily '!T7 -> 211.271 | O3: ='FS-AD Daily '!R7 -> 77.613 | P3: ='FS-AD Daily '!Z7 -> 728 | Q3: ='FS-AD Daily '!V7 -> 185 | R3: ='FS-AD Daily '!W7 -> 158.98 | S3: =P3-Q3-R3 -> 384.02 | T3: ='FS-AD Daily '!AD7*3.516 -> 39969.888 | U3: =('FS-AD Daily '!AF7)*1000 -> 19600 | V3: =('FS-AD Daily '!AG7)*1000 -> 0 | W3: ='FS-AD Daily '!AH7*1000 -> 7000 | X3: =('FS-AD Daily '!AK7)*1000 -> 23800 | Y3: 140 | Z3: 186
A4: Abu Dhabi | B4: =B3+1 -> 3 | C4: 2 | D4: 2022 | E4: ='FS-AD Daily '!B8 -> 6861 | F4: ='FS-AD Daily '!C8 -> 4996 | G4: ='FS-AD Daily '!D8 -> 882 | H4: ='FS-AD Daily '!E8 -> 6901 | I4: ='FS-AD Daily '!F8 -> 5955 | J4: ='FS-AD Daily '!G8 -> 3444 | K4: ='FS-AD Daily '!H8 -> 3833 | L4: ='FS-AD Daily '!I8 -> 2378 | M4: ='FS-AD Daily '!J8 -> 6874 | N4: ='FS-AD Daily '!T8 -> 223.415 | O4: ='FS-AD Daily '!R8 -> 72.19 | P4: ='FS-AD Daily '!Z8 -> 795 | Q4: ='FS-AD Daily '!V8 -> 219.4 | R4: ='FS-AD Daily '!W8 -> 173.44 | S4: =P4-Q4-R4 -> 402.16 | T4: ='FS-AD Daily '!AD8*3.516 -> 41559.12 | U4: =('FS-AD Daily '!AF8)*1000 -> 20800 | V4: =('FS-AD Daily '!AG8)*1000 -> 0 | W4: ='FS-AD Daily '!AH8*1000 -> 7000 | X4: =('FS-AD Daily '!AK8)*1000 -> 22600 | Y4: 184 | Z4: 231
A5: Abu Dhabi | B5: =B4+1 -> 4 | C5: 2 | D5: 2022 | E5: ='FS-AD Daily '!B9 -> 6041 | F5: ='FS-AD Daily '!C9 -> 4928 | G5: ='FS-AD Daily '!D9 -> 964 | H5: ='FS-AD Daily '!E9 -> 6840 | I5: ='FS-AD Daily '!F9 -> 5644 | J5: ='FS-AD Daily '!G9 -> 3175 | K5: ='FS-AD Daily '!H9 -> 3691 | L5: ='FS-AD Daily '!I9 -> 2239 | M5: ='FS-AD Daily '!J9 -> 7151 | N5: ='FS-AD Daily '!T9 -> 203.685 | O5: ='FS-AD Daily '!R9 -> 77.927 | P5: ='FS-AD Daily '!Z9 -> 771 | Q5: ='FS-AD Daily '!V9 -> 218.5 | R5: ='FS-AD Daily '!W9 -> 178.8 | S5: =P5-Q5-R5 -> 373.7 | T5: ='FS-AD Daily '!AD9*3.516 -> 43668.72 | U5: =('FS-AD Daily '!AF9)*1000 -> 22000 | V5: =('FS-AD Daily '!AG9)*1000 -> 0 | W5: ='FS-AD Daily '!AH9*1000 -> 7000 | X5: =('FS-AD Daily '!AK9)*1000 -> 24000 | Y5: 168 | Z5: 211
A6: Abu Dhabi | B6: =B5+1 -> 5 | C6: 2 | D6: 2022 | E6: ='FS-AD Daily '!B10 -> 6385 | F6: ='FS-AD Daily '!C10 -> 4530 | G6: ='FS-AD Daily '!D10 -> 1006 | H6: ='FS-AD Daily '!E10 -> 6870 | I6: ='FS-AD Daily '!F10 -> 5847 | J6: ='FS-AD Daily '!G10 -> 3075 | K6: ='FS-AD Daily '!H10 -> 3740 | L6: ='FS-AD Daily '!I10 -> 2178 | M6: ='FS-AD Daily '!J10 -> 7304 | N6: ='FS-AD Daily '!T10 -> 202.754 | O6: ='FS-AD Daily '!R10 -> 82.063 | P6: ='FS-AD Daily '!Z10 -> 798 | Q6: ='FS-AD Daily '!V10 -> 239.5 | R6: ='FS-AD Daily '!W10 -> 177.72 | S6: =P6-Q6-R6 -> 380.78 | T6: ='FS-AD Daily '!AD10*3.516 -> 42603.372 | U6: =('FS-AD Daily '!AF10)*1000 -> 21700 | V6: =('FS-AD Daily '!AG10)*1000 -> 0 | W6: ='FS-AD Daily '!AH10*1000 -> 7100 | X6: =('FS-AD Daily '!AK10)*1000 -> 23900 | Y6: 172 | Z6: 223
A7: Abu Dhabi | B7: =B6+1 -> 6 | C7: 2 | D7: 2022 | E7: ='FS-AD Daily '!B11 -> 8019 | F7: ='FS-AD Daily '!C11 -> 4493 | G7: ='FS-AD Daily '!D11 -> 970 | H7: ='FS-AD Daily '!E11 -> 6596 | I7: ='FS-AD Daily '!F11 -> 5665 | J7: ='FS-AD Daily '!G11 -> 2947 | K7: ='FS-AD Daily '!H11 -> 3677 | L7: ='FS-AD Daily '!I11 -> 2316 | M7: ='FS-AD Daily '!J11 -> 7202 | N7: ='FS-AD Daily '!T11 -> 215.29 | O7: ='FS-AD Daily '!R11 -> 70.478 | P7: ='FS-AD Daily '!Z11 -> 774 | Q7: ='FS-AD Daily '!V11 -> 221.5 | R7: ='FS-AD Daily '!W11 -> 165.59 | S7: =P7-Q7-R7 -> 386.91 | T7: ='FS-AD Daily '!AD11*3.516 -> 39052.212 | U7: =('FS-AD Daily '!AF11)*1000 -> 20000 | V7: =('FS-AD Daily '!AG11)*1000 -> 0 | W7: ='FS-AD Daily '!AH11*1000 -> 6000 | X7: =('FS-AD Daily '!AK11)*1000 -> 22800 | Y7: 183 | Z7: 239
A8: Abu Dhabi | B8: =B7+1 -> 7 | C8: 2 | D8: 2022 | E8: ='FS-AD Daily '!B12 -> 8334 | F8: ='FS-AD Daily '!C12 -> 4781 | G8: ='FS-AD Daily '!D12 -> 919 | H8: ='FS-AD Daily '!E12 -> 6718 | I8: ='FS-AD Daily '!F12 -> 5700 | J8: ='FS-AD Daily '!G12 -> 3024 | K8: ='FS-AD Daily '!H12 -> 3738 | L8: ='FS-AD Daily '!I12 -> 2210 | M8: ='FS-AD Daily '!J12 -> 6901 | N8: ='FS-AD Daily '!T12 -> 227.689 | O8: ='FS-AD Daily '!R12 -> 68.028 | P8: ='FS-AD Daily '!Z12 -> 781 | Q8: ='FS-AD Daily '!V12 -> 221 | R8: ='FS-AD Daily '!W12 -> 186.14 | S8: =P8-Q8-R8 -> 373.86 | T8: ='FS-AD Daily '!AD12*3.516 -> 32828.892 | U8: =('FS-AD Daily '!AF12)*1000 -> 17700 | V8: =('FS-AD Daily '!AG12)*1000 -> 0 | W8: ='FS-AD Daily '!AH12*1000 -> 6000 | X8: =('FS-AD Daily '!AK12)*1000 -> 19200 | Y8: 182 | Z8: 242
A9: Abu Dhabi | B9: =B8+1 -> 8 | C9: 2 | D9: 2022 | E9: ='FS-AD Daily '!B13 -> 8326 | F9: ='FS-AD Daily '!C13 -> 4462 | G9: ='FS-AD Daily '!D13 -> 946 | H9: ='FS-AD Daily '!E13 -> 6684 | I9: ='FS-AD Daily '!F13 -> 5668 | J9: ='FS-AD Daily '!G13 -> 2854 | K9: ='FS-AD Daily '!H13 -> 3739 | L9: ='FS-AD Daily '!I13 -> 2248 | M9: ='FS-AD Daily '!J13 -> 6933 | N9: ='FS-AD Daily '!T13 -> 220.705 | O9: ='FS-AD Daily '!R13 -> 76.494 | P9: ='FS-AD Daily '!Z13 -> 838 | Q9: ='FS-AD Daily '!V13 -> 218 | R9: ='FS-AD Daily '!W13 -> 187.86 | S9: =P9-Q9-R9 -> 432.14 | T9: ='FS-AD Daily '!AD13*3.516 -> 32937.888 | U9: =('FS-AD Daily '!AF13)*1000 -> 16300 | V9: =('FS-AD Daily '!AG13)*1000 -> 0 | W9: ='FS-AD Daily '!AH13*1000 -> 6600 | X9: =('FS-AD Daily '!AK13)*1000 -> 22000 | Y9: 187 | Z9: 252
A10: Abu Dhabi | B10: =B9+1 -> 9 | C10: 2 | D10: 2022 | E10: ='FS-AD Daily '!B14 -> 7519 | F10: ='FS-AD Daily '!C14 -> 4511 | G10: ='FS-AD Daily '!D14 -> 916 | H10: ='FS-AD Daily '!E14 -> 6899 | I10: ='FS-AD Daily '!F14 -> 5743 | J10: ='FS-AD Daily '!G14 -> 2763 | K10: ='FS-AD Daily '!H14 -> 3799 | L10: ='FS-AD Daily '!I14 -> 2290 | M10: ='FS-AD Daily '!J14 -> 7120 | N10: ='FS-AD Daily '!T14 -> 194.567 | O10: ='FS-AD Daily '!R14 -> 70.274 | P10: ='FS-AD Daily '!Z14 -> 789 | Q10: ='FS-AD Daily '!V14 -> 216 | R10: ='FS-AD Daily '!W14 -> 189.8 | S10: =P10-Q10-R10 -> 383.2 | T10: ='FS-AD Daily '!AD14*3.516 -> 35792.88 | U10: =('FS-AD Daily '!AF14)*1000 -> 18300 | V10: =('FS-AD Daily '!AG14)*1000 -> 0 | W10: ='FS-AD Daily '!AH14*1000 -> 5400 | X10: =('FS-AD Daily '!AK14)*1000 -> 21000 | Y10: 189 | Z10: 244
A11: Abu Dhabi | B11: =B10+1 -> 10 | C11: 2 | D11: 2022 | E11: ='FS-AD Daily '!B15 -> 6297 | F11: ='FS-AD Daily '!C15 -> 4726 | G11: ='FS-AD Daily '!D15 -> 919 | H11: ='FS-AD Daily '!E15 -> 6806 | I11: ='FS-AD Daily '!F15 -> 5501 | J11: ='FS-AD Daily '!G15 -> 2813 | K11: ='FS-AD Daily '!H15 -> 3716 | L11: ='FS-AD Daily '!I15 -> 2244 | M11: ='FS-AD Daily '!J15 -> 7100 | N11: ='FS-AD Daily '!T15 -> 224.862 | O11: ='FS-AD Daily '!R15 -> 75.979 | P11: ='FS-AD Daily '!Z15 -> 757 | Q11: ='FS-AD Daily '!V15 -> 224.9 | R11: ='FS-AD Daily '!W15 -> 149 | S11: =P11-Q11-R11 -> 383.1 | T11: ='FS-AD Daily '!AD15*3.516 -> 41161.812 | U11: =('FS-AD Daily '!AF15)*1000 -> 21400 | V11: =('FS-AD Daily '!AG15)*1000 -> 0 | W11: ='FS-AD Daily '!AH15*1000 -> 7600 | X11: =('FS-AD Daily '!AK15)*1000 -> 23700 | Y11: 168 | Z11: 218
A12: Abu Dhabi | B12: =B11+1 -> 11 | C12: 2 | D12: 2022 | E12: ='FS-AD Daily '!B16 -> 5998 | F12: ='FS-AD Daily '!C16 -> 4695 | G12: ='FS-AD Daily '!D16 -> 918 | H12: ='FS-AD Daily '!E16 -> 6915 | I12: ='FS-AD Daily '!F16 -> 5671 | J12: ='FS-AD Daily '!G16 -> 2828 | K12: ='FS-AD Daily '!H16 -> 3765 | L12: ='FS-AD Daily '!I16 -> 2279 | M12: ='FS-AD Daily '!J16 -> 7154 | N12: ='FS-AD Daily '!T16 -> 218.338 | O12: ='FS-AD Daily '!R16 -> 84.318 | P12: ='FS-AD Daily '!Z16 -> 700 | Q12: ='FS-AD Daily '!V16 -> 213 | R12: ='FS-AD Daily '!W16 -> 101 | S12: =P12-Q12-R12 -> 386 | T12: ='FS-AD Daily '!AD16*3.516 -> 41281.356 | U12: =('FS-AD Daily '!AF16)*1000 -> 20700 | V12: =('FS-AD Daily '!AG16)*1000 -> 0 | W12: ='FS-AD Daily '!AH16*1000 -> 7000 | X12: =('FS-AD Daily '!AK16)*1000 -> 24000 | Y12: 174 | Z12: 237
A13: Abu Dhabi | B13: =B12+1 -> 12 | C13: 2 | D13: 2022 | E13: ='FS-AD Daily '!B17 -> 6439 | F13: ='FS-AD Daily '!C17 -> 4125 | G13: ='FS-AD Daily '!D17 -> 1017 | H13: ='FS-AD Daily '!E17 -> 6874 | I13: ='FS-AD Daily '!F17 -> 5643 | J13: ='FS-AD Daily '!G17 -> 2842 | K13: ='FS-AD Daily '!H17 -> 3744 | L13: ='FS-AD Daily '!I17 -> 2158 | M13: ='FS-AD Daily '!J17 -> 7280 | N13: ='FS-AD Daily '!T17 -> 216.252 | O13: ='FS-AD Daily '!R17 -> 86.439 | P13: ='FS-AD Daily '!Z17 -> 789 | Q13: ='FS-AD Daily '!V17 -> 249.3 | R13: ='FS-AD Daily '!W17 -> 164.5 | S13: =P13-Q13-R13 -> 375.2 | T13: ='FS-AD Daily '!AD17*3.516 -> 41073.912 | U13: =('FS-AD Daily '!AF17)*1000 -> 20000 | V13: =('FS-AD Daily '!AG17)*1000 -> 0 | W13: ='FS-AD Daily '!AH17*1000 -> 6900 | X13: =('FS-AD Daily '!AK17)*1000 -> 23300 | Y13: 170 | Z13: 248
A14: Abu Dhabi | B14: =B13+1 -> 13 | C14: 2 | D14: 2022 | E14: ='FS-AD Daily '!B18 -> 7954 | F14: ='FS-AD Daily '!C18 -> 3823 | G14: ='FS-AD Daily '!D18 -> 958 | H14: ='FS-AD Daily '!E18 -> 6753 | I14: ='FS-AD Daily '!F18 -> 5744 | J14: ='FS-AD Daily '!G18 -> 2933 | K14: ='FS-AD Daily '!H18 -> 3696 | L14: ='FS-AD Daily '!I18 -> 2257 | M14: ='FS-AD Daily '!J18 -> 7094 | N14: ='FS-AD Daily '!T18 -> 194.805 | O14: ='FS-AD Daily '!R18 -> 78.635 | P14: ='FS-AD Daily '!Z18 -> 738 | Q14: ='FS-AD Daily '!V18 -> 201.1 | R14: ='FS-AD Daily '!W18 -> 169.27 | S14: =P14-Q14-R14 -> 367.63 | T14: ='FS-AD Daily '!AD18*3.516 -> 35033.424 | U14: =('FS-AD Daily '!AF18)*1000 -> 17500 | V14: =('FS-AD Daily '!AG18)*1000 -> 0 | W14: ='FS-AD Daily '!AH18*1000 -> 6000 | X14: =('FS-AD Daily '!AK18)*1000 -> 22200 | Y14: 134 | Z14: 187
... A29: Abu Dhabi | B29: =B28+1 -> 28 | C29: 2 | D29: 2022 | E29: ='FS-AD Daily '!B33 -> 6158 | F29: ='FS-AD Daily '!C33 -> 4800 | G29: ='FS-AD Daily '!D33 -> 919 | H29: ='FS-AD Daily '!E33 -> 6896 | I29: ='FS-AD Daily '!F33 -> 6139 | J29: ='FS-AD Daily '!G33 -> 3043 | K29: ='FS-AD Daily '!H33 -> 3865 | L29: ='FS-AD Daily '!I33 -> 2318 | M29: ='FS-AD Daily '!J33 -> 7097 | N29: ='FS-AD Daily '!T33 -> 206.171 | O29: ='FS-AD Daily '!R33 -> 70.566 | P29: ='FS-AD Daily '!Z33 -> 786 | Q29: ='FS-AD Daily '!V33 -> 232.4 | R29: ='FS-AD Daily '!W33 -> 176.74 | S29: =P29-Q29-R29 -> 376.86 | T29: ='FS-AD Daily '!AD33*3.516 -> 52142.28 | U29: =('FS-AD Daily '!AF33)*1000 -> 26200 | V29: =('FS-AD Daily '!AG33)*1000 -> 0 | W29: ='FS-AD Daily '!AH33*1000 -> 8100 | X29: =('FS-AD Daily '!AK33)*1000 -> 27900 | Y29: 177 | Z29: 251
A30: Abu Dhabi | B30: =B29+1 -> 29 | C30: 2 | D30: 2022 | E30: ='FS-AD Daily '!B34 -> 0 | F30: ='FS-AD Daily '!C34 -> 0 | G30: ='FS-AD Daily '!D34 -> 0 | H30: ='FS-AD Daily '!E34 -> 0 | I30: ='FS-AD Daily '!F34 -> 0 | J30: ='FS-AD Daily '!G34 -> 0 | K30: ='FS-AD Daily '!H34 -> 0 | L30: ='FS-AD Daily '!I34 -> 0 | M30: ='FS-AD Daily '!J34 -> 0 | N30: ='FS-AD Daily '!T34 -> 0 | O30: ='FS-AD Daily '!R34 -> 0 | P30: ='FS-AD Daily '!Z34 -> 0 | Q30: ='FS-AD Daily '!V34 -> 0 | R30: ='FS-AD Daily '!W34 -> 0 | S30: =P30-Q30-R30 -> 0 | T30: ='FS-AD Daily '!AD34*3.516 -> 0 | U30: =('FS-AD Daily '!AF34)*1000 -> 0 | V30: =('FS-AD Daily '!AG34)*1000 -> 0 | W30: ='FS-AD Daily '!AH34*1000 -> 0 | X30: =('FS-AD Daily '!AK34)*1000 -> 0 | Y30: ='FS-AD Daily '!AN34 -> 0
A31: Abu Dhabi | B31: =B30+1 -> 30 | C31: 2 | D31: 2022 | E31: ='FS-AD Daily '!B35 -> 0 | F31: ='FS-AD Daily '!C35 -> 0 | G31: ='FS-AD Daily '!D35 -> 0 | H31: ='FS-AD Daily '!E35 -> 0 | I31: ='FS-AD Daily '!F35 -> 0 | J31: ='FS-AD Daily '!G35 -> 0 | K31: ='FS-AD Daily '!H35 -> 0 | L31: ='FS-AD Daily '!I35 -> 0 | M31: ='FS-AD Daily '!J35 -> 0 | N31: ='FS-AD Daily '!T35 -> 0 | O31: ='FS-AD Daily '!R35 -> 0 | P31: ='FS-AD Daily '!Z35 -> 0 | Q31: ='FS-AD Daily '!V35 -> 0 | R31: ='FS-AD Daily '!W35 -> 0 | S31: =P31-Q31-R31 -> 0 | T31: ='FS-AD Daily '!AD35*3.516 -> 0 | U31: =('FS-AD Daily '!AF35)*1000 -> 0 | V31: =('FS-AD Daily '!AG35)*1000 -> 0 | W31: ='FS-AD Daily '!AH35*1000 -> 0 | X31: =('FS-AD Daily '!AK35)*1000 -> 0 | Y31: ='FS-AD Daily '!AN35 -> 0
A32: Abu Dhabi | B32: =B31+1 -> 31 | C32: 2 | D32: 2022 | E32: ='FS-AD Daily '!B36 -> 0 | F32: ='FS-AD Daily '!C36 -> 0 | G32: ='FS-AD Daily '!D36 -> 0 | H32: ='FS-AD Daily '!E36 -> 0 | I32: ='FS-AD Daily '!F36 -> 0 | J32: ='FS-AD Daily '!G36 -> 0 | K32: ='FS-AD Daily '!H36 -> 0 | L32: ='FS-AD Daily '!I36 -> 0 | M32: ='FS-AD Daily '!J36 -> 0 | N32: ='FS-AD Daily '!T36 -> 0 | O32: ='FS-AD Daily '!R36 -> 0 | P32: ='FS-AD Daily '!Z36 -> 0 | Q32: ='FS-AD Daily '!V36 -> 0 | R32: ='FS-AD Daily '!W36 -> 0 | S32: =P32-Q32-R32 -> 0 | T32: ='FS-AD Daily '!AD36*3.516 -> 0 | U32: =('FS-AD Daily '!AF36)*1000 -> 0 | V32: =('FS-AD Daily '!AG36)*1000 -> 0 | W32: ='FS-AD Daily '!AH36*1000 -> 0 | X32: =('FS-AD Daily '!AK36)*1000 -> 0 | Y32: ='FS-AD Daily '!AN36 -> 0
I33: =SUM(I2:I32) -> 163210 | J33: =SUM(J2:J32) -> 82192 | K33: =SUM(K2:K32) -> 104752 | L33: =SUM(L2:L32) -> 62501 | M33: =SUM(M2:M32) -> 197166 | N33: =SUM(N2:N32) -> 5827.116 | O33: =SUM(O2:O32) -> 2151.714 | P33: =SUM(P2:P32) -> 21713 | ... W33: =SUM(W2:W32) -> 186800 | X33: ='FS-AD Daily '!U38 -> 28815.152 | Y33: =SUM(Y2:Y32) -> 4545 | Z33: =SUM(Z2:Z32) -> 6191

Sheet FS-AD Daily 
A1: DATE | B1: ELECTRICAL METERS | K1: TOTAL CONSUMPTION (kWh) | L1: ELECTRICITY - TOTAL (AED) | M1: Concrete Tank Meter (Daily Consumption) | N1: Fiber tank Meter Cold Water Podium & Galleria Staff Toilet Section 2 | O1: Galleria Hot water Public Area | P1: Water Bulk 3 Meter Galleria (Daily Consumption) section 1 | Q1: Irrigation Tank Meter (Daily Consumption) | R1: Galleria Consumption m3 | S1: GALLERIA WATER TOTAL COST (AED) | T1: WATER METER (Daily Consumption) m3 | U1: FSH WATER (AED) | V1: Hot Water Boiler (Daily Gas Consumption m 3) | W1: Steam Boiler (Daily Gas Consumption m 3) | X1: GAS METERS (Daily Reading) | Z1: GAS (Daily Consumption m 3) | AA1: Natural GAS (AED) | AB1: CHILLED WATER (Daily Reading) Present HT | AC1: CHILLED WATER (Daily Reading) Previous HT | AD1: CHILLED WATER (Daily Consumption) HT | AE1: CHILLED WATER (AED) | AF1: Podium Chilled Water - MWh | AG1: Guest Room Chilled Water MWh | AH1: Residence Chilled Water MWh | AI1: Galleria chilled water MWH Previous | AJ1: Galleria chilled water MWH Present | AK1: Galleria Chilled Water Total MWH | AL1: Galleria Chilled Water Total HT | AM1: CHILLED WATER (AED) | AN1: OCCUPANCY (Room Night) | AO1: TOTAL (AED) | AQ1: THR AED (0.334529) | AR1: MWH = H.TON (1 = 284.34)
A2: 2021 | B2: 1 | C2: 2 | D2: 3 | E2: 4 | F2: 5 | G2: 6 | H2: 7 | I2: 8 | J2: 9 | K2: TOTAL CONSUMPTION (KWH) | L2: TOTAL AMOUNT (AED) | X2: 1 | Y2: 2 | AA2: (AED. 6.47/m3 + AED. 0.00 Service) | AC2: (K21B2419000) | AE2: AED. 0.327795/ Ton | AM2: AED. 0.327795/ Ton
B3: 4626096222-E | C3: 6572482789-E | D3: 3190048503-E | E3: 3732963488-E | F3: 4626096253-E | G3: 7651356710-E | H3: 5076351256-E | I3: 8990986529-E | J3: 6057081392-E
B4: LVS-1 SECTION A | C4: LVS-1 SECTION B | D4: LVS-2 (CAFÉ MILANO) | E4: LVS-3 SECTION A | F4: LVS-3 SECTION B | G4: LVS-4 SECTION A | H4: LVS-4 SECTION B | I4: LVS-5 (FLOOR 15-32) | J4: LVS-LRLV (RETAIL) | Y4: 990074 | AB4: 11000507 | AI4: 50926 | AP4: 0.333415
A5: TOTAL | E5: Hot water calorifiers L 14 feed 15 - 19 floor | G5: Residence Apartment chilled water pump share feeder | H5: Residence Public Area Electric DB share feeder | I5: Residence apartments Electric DB (individual apartment feeder) | X5: Galleria independent supply | AA5: =SUM(#REF!) -> #REF! | AE5: =SUM(#REF!) -> #REF! | AK5: =SUM(#REF!) -> #REF! | AO5: =SUM(#REF!) -> #REF!
A6: 44593 | B6: =13409334-13403451 -> 5883 | C6: =8571749-8567006 -> 4743 | D6: =1700432-1699547 -> 885 | E6: =12855201-12848343 -> 6858 | F6: =12733068-12727227 -> 5841 | G6: =8941432-8938143 -> 3289 | H6: =9764526-9760753 -> 3773 | I6: =5693846-5691489 -> 2357 | J6: =13005944-12999294 -> 6650 | K6: =SUM(B6:H6) -> 31272 | L6: =K6*0.2 -> 6254.4 | M6: =11658.849-11491.922 -> 166.927 | N6: =4719.731-4716.278 -> 3.453 | O6: =10475.314-10475.165 -> 0.149 | P6: =5556.219-5480 -> 76.219 | Q6: =27311.149-27311.045 -> 0.104 | R6: =N6+O6+P6 -> 79.821 | S6: =(N6+O6+P6)*7.84 -> 625.79664 | T6: =M6+Q6 -> 167.031 | U6: =T6*7.84 -> 1309.523 | V6: =397750.1-397585.3 -> 164.8 | W6: =148660.47-148483.07 -> 177.4 | X6: 0001523.20 | Y6: 990776 | Z6: =IF((Y6-Y5<0), "0",Y6-Y4) -> 702 | AA6: =Z6*6.47 -> 4541.94 | AB6: 11012683 | AC6: =AB4 -> 11000507 | AD6: =IF((AB6-AC6<0), "0",AB6-AC6) -> 12176 | AE6: =AD6*0.327795 -> 3991.2319 | AF6: =96379.9-96358 -> 21.9 | AG6: =50692.5-50692.5 -> 0 | AH6: =30447.9-30440.8 -> 7.1 | AI6: =AI4 -> 50926 | AJ6: 50951.7 | AK6: =IF((AJ6-AI6)<0, "0",AJ6-AI6) -> 25.7 | AL6: =AK6*(284.34513609) -> 7307.67 | AM6: =AL6*0.327795 -> 2395.4177 | AN6: 128 | AO6: =L6+U6+AA6+AE6 -> 16097.095
A7: 44594 | B7: =13415510-13409334 -> 6176 | C7: =8576383-8571749 -> 4634 | D7: =1701274-1700432 -> 842 | E7: =12862009-12855201 -> 6808 | F7: =12738829-12733068 -> 5761 | G7: =8944863-8941432 -> 3431 | H7: =9768284-9764526 -> 3758 | I7: =5696128-5693846 -> 2282 | J7: =13012895-13005944 -> 6951 | K7: =SUM(B7:H7) -> 31410 | L7: =K7*0.2 -> 6282 | M7: =11845.618-11658.849 -> 186.769 | N7: =4722.517-4719.731 -> 2.786 | O7: =10475.557-10475.314 -> 0.243 | P7: =5630.803-5556.219 -> 74.584 | Q7: =27335.651-27311.149 -> 24.502 | R7: =N7+O7+P7 -> 77.613 | S7: =(N7+O7+P7)*7.84 -> 608.48592 | T7: =M7+Q7 -> 211.271 | U7: =T7*7.84 -> 1656.3646 | V7: =397935.1-397750.1 -> 185 | W7: =148819.45-148660.47 -> 158.98 | X7: 0001523.20 | Y7: 991504 | Z7: =IF((Y7-Y6<0), "0",Y7-Y6) -> 728 | AA7: =Z7*6.47 -> 4710.16 | AB7: 11024051 | AC7: =AB6 -> 11012683 | AD7: =IF((AB7-AC7<0), "0",AB7-AC7) -> 11368 | AE7: =AD7*0.327795 -> 3726.3736 | AF7: =96399.5-96379.9 -> 19.6 | AG7: =50692.5-50692.5 -> 0 | AH7: =30454.9-30447.9 -> 7 | AI7: =AJ6 -> 50951.7 | AJ7: 50975.5 | AK7: =IF((AJ7-AI7)<0, "0",AJ7-AI7) -> 23.8 | AL7: =AK7*(284.34513609) -> 6767.4142 | AM7: =AL7*0.327795 -> 2218.3246 | AN7: 140 | AO7: =L7+U7+AA7+AE7 -> 16374.898
A8: 44595 | B8: =13422371-13415510 -> 6861 | C8: =8581379-8576383 -> 4996 | D8: =1702156-1701274 -> 882 | E8: =12868910-12862009 -> 6901 | F8: =12744784-12738829 -> 5955 | G8: =8948307-8944863 -> 3444 | H8: =9772117-9768284 -> 3833 | I8: =5698506-5696128 -> 2378 | J8: =13019769-13012895 -> 6874 | K8: =SUM(B8:H8) -> 32872 | L8: =K8*0.2 -> 6574.4 | M8: =12042.65-11845.618 -> 197.032 | N8: =4725.273-4722.517 -> 2.756 | O8: =10475.769-10475.557 -> 0.212 | P8: =5700.025-5630.803 -> 69.222 | Q8: =27362.034-27335.651 -> 26.383 | R8: =N8+O8+P8 -> 72.19 | S8: =(N8+O8+P8)*7.84 -> 565.9696 | T8: =M8+Q8 -> 223.415 | U8: =T8*7.84 -> 1751.5736 | V8: =398154.5-397935.1 -> 219.4 | W8: =148992.89-148819.45 -> 173.44 | X8: 0001523.20 | Y8: 992299 | Z8: =IF((Y8-Y7<0), "0",Y8-Y7) -> 795 | AA8: =Z8*6.47 -> 5143.65 | AB8: 11035871 | AC8: =AB7 -> 11024051 | AD8: =IF((AB8-AC8<0), "0",AB8-AC8) -> 11820 | AE8: =AD8*0.327795 -> 3874.5369 | AF8: =96420.3-96399.5 -> 20.8 | AG8: =50692.5-50692.5 -> 0 | AH8: =30461.9-30454.9 -> 7 | AI8: =AJ7 -> 50975.5 | AJ8: 50998.1 | AK8: =IF((AJ8-AI8)<0, "0",AJ8-AI8) -> 22.6 | AL8: =AK8*(284.34513609) -> 6426.2001 | AM8: =AL8*0.327795 -> 2106.4763 | AN8: 184 | AO8: =L8+U8+AA8+AE8 -> 17344.16
A9: 44596 | B9: =13428412-13422371 -> 6041 | C9: =8586307-8581379 -> 4928 | D9: =1703120-1702156 -> 964 | E9: =12875750-12868910 -> 6840 | F9: =12750428-12744784 -> 5644 | G9: =8951482-8948307 -> 3175 | H9: =9775808-9772117 -> 3691 | I9: =5700745-5698506 -> 2239 | J9: =13026920-13019769 -> 7151 | K9: =SUM(B9:H9) -> 31283 | L9: =K9*0.2 -> 6256.6 | M9: =12235.064-12042.65 -> 192.414 | N9: =4727.906-4725.273 -> 2.633 | O9: =10476.083-10475.769 -> 0.314 | P9: =5775.005-5700.025 -> 74.98 | Q9: =27373.305-27362.034 -> 11.271 | R9: =N9+O9+P9 -> 77.927 | S9: =(N9+O9+P9)*7.84 -> 610.94768 | T9: =M9+Q9 -> 203.685 | U9: =T9*7.84 -> 1596.8904 | V9: =398373-398154.5 -> 218.5 | W9: =149171.69-148992.89 -> 178.8 | X9: 0001523.20 | Y9: 993070 | Z9: =IF((Y9-Y8<0), "0",Y9-Y8) -> 771 | AA9: =Z9*6.47 -> 4988.37 | AB9: 11048291 | AC9: =AB8 -> 11035871 | AD9: =IF((AB9-AC9<0), "0",AB9-AC9) -> 12420 | AE9: =AD9*0.327795 -> 4071.2139 | AF9: =96442.3-96420.3 -> 22 | AG9: =50692.5-50692.5 -> 0 | AH9: =30468.9-30461.9 -> 7 | AI9: =AJ8 -> 50998.1 | AJ9: 51022.1 | AK9: =IF((AJ9-AI9)<0, "0",AJ9-AI9) -> 24 | AL9: =AK9*(284.34513609) -> 6824.2833 | AM9: =AL9*0.327795 -> 2236.9659 | AN9: 168 | AO9: =L9+U9+AA9+AE9 -> 16913.074
A10: 44597 | B10: =13434797-13428412 -> 6385 | C10: =8590837-8586307 -> 4530 | D10: =1704126-1703120 -> 1006 | E10: =12882620-12875750 -> 6870 | F10: =12756275-12750428 -> 5847 | G10: =8954557-8951482 -> 3075 | H10: =9779548-9775808 -> 3740 | I10: =5702923-5700745 -> 2178 | J10: =13034224-13026920 -> 7304 | K10: =SUM(B10:H10) -> 31453 | L10: =K10*0.2 -> 6290.6 | M10: =12425.345-12235.064 -> 190.281 | N10: =4730.4-4727.906 -> 2.494 | O10: =10476.324-10476.083 -> 0.241 | P10: =5854.333-5775.005 -> 79.328 | Q10: =27385.778-27373.305 -> 12.473 | R10: =N10+O10+P10 -> 82.063 | S10: =(N10+O10+P10)*7.84 -> 643.37392 | T10: =M10+Q10 -> 202.754 | U10: =T10*7.84 -> 1589.5914 | V10: =398612.5-398373 -> 239.5 | W10: =149349.41-149171.69 -> 177.72 | X10: 0001523.20 | Y10: 993868 | Z10: =IF((Y10-Y9<0), "0",Y10-Y9) -> 798 | AA10: =Z10*6.47 -> 5163.06 | AB10: 11060408 | AC10: =AB9 -> 11048291 | AD10: =IF((AB10-AC10<0), "0",AB10-AC10) -> 12117 | AE10: =AD10*0.327795 -> 3971.892 | AF10: =96464-96442.3 -> 21.7 | AG10: =50692.5-50692.5 -> 0 | AH10: =30476-30468.9 -> 7.1 | AI10: =AJ9 -> 51022.1 | AJ10: 51046 | AK10: =IF((AJ10-AI10)<0, "0",AJ10-AI10) -> 23.9 | AL10: =AK10*(284.34513609) -> 6795.8488 | AM10: =AL10*0.327795 -> 2227.6452 | AN10: 172 | AO10: =L10+U10+AA10+AE10 -> 17015.143
A11: 44598 | B11: =13442816-13434797 -> 8019 | C11: =8595330-8590837 -> 4493 | D11: =1705096-1704126 -> 970 | E11: =12889216-12882620 -> 6596 | F11: =12761940-12756275 -> 5665 | G11: =8957504-8954557 -> 2947 | H11: =9783225-9779548 -> 3677 | I11: =5705239-5702923 -> 2316 | J11: =13041426-13034224 -> 7202 | K11: =SUM(B11:H11) -> 32367 | L11: =K11*0.2 -> 6473.4 | M11: =12618.111-12425.345 -> 192.766 | N11: =4731.98-4730.4 -> 1.58 | O11: =10476.444-10476.324 -> 0.12 | P11: =5923.111-5854.333 -> 68.778 | Q11: =27408.302-27385.778 -> 22.524 | R11: =N11+O11+P11 -> 70.478 | S11: =(N11+O11+P11)*7.84 -> 552.54752 | T11: =M11+Q11 -> 215.29 | U11: =T11*7.84 -> 1687.8736 | V11: =398834-398612.5 -> 221.5 | W11: =149515-149349.41 -> 165.59 | X11: 0001523.20 | Y11: 994642 | Z11: =IF((Y11-Y10<0), "0",Y11-Y10) -> 774 | AA11: =Z11*6.47 -> 5007.78 | AB11: 11071515 | AC11: =AB10 -> 11060408 | AD11: =IF((AB11-AC11<0), "0",AB11-AC11) -> 11107 | AE11: =AD11*0.327795 -> 3640.8191 | AF11: =96484-96464 -> 20 | AG11: =50692.5-50692.5 -> 0 | AH11: =30482-30476 -> 6 | AI11: =AJ10 -> 51046 | AJ11: 51068.8 | AK11: =IF((AJ11-AI11)<0, "0",AJ11-AI11) -> 22.8 | AL11: =AK11*(284.34513609) -> 6483.0691 | AM11: =AL11*0.327795 -> 2125.1176 | AN11: 183 | AO11: =L11+U11+AA11+AE11 -> 16809.873
A12: 44599 | B12: =13451150-13442816 -> 8334 | C12: =8600111-8595330 -> 4781 | D12: =1706015-1705096 -> 919 | E12: =12895934-12889216 -> 6718 | F12: =12767640-12761940 -> 5700 | G12: =8960528-8957504 -> 3024 | H12: =9786963-9783225 -> 3738 | I12: =5707449-5705239 -> 2210 | J12: =13048327-13041426 -> 6901 | K12: =SUM(B12:H12) -> 33214 | L12: =K12*0.2 -> 6642.8 | M12: =12827.467-12618.111 -> 209.356 | N12: =4734.344-4731.98 -> 2.364 | O12: =10476.59-10476.444 -> 0.146 | P12: =5988.629-5923.111 -> 65.518 | Q12: =27426.635-27408.302 -> 18.333 | R12: =N12+O12+P12 -> 68.028 | S12: =(N12+O12+P12)*7.84 -> 533.33952 | T12: =M12+Q12 -> 227.689 | U12: =T12*7.84 -> 1785.0818 | V12: =399055-398834 -> 221 | W12: =149701.14-149515 -> 186.14 | X12: 0001523.20 | Y12: 995423 | Z12: =IF((Y12-Y11<0), "0",Y12-Y11) -> 781 | AA12: =Z12*6.47 -> 5053.07 | AB12: 11080852 | AC12: =AB11 -> 11071515 | AD12: =IF((AB12-AC12<0), "0",AB12-AC12) -> 9337 | AE12: =AD12*0.327795 -> 3060.6219 | AF12: =96501.7-96484 -> 17.7 | AG12: =50692.5-50692.5 -> 0 | AH12: =30488-30482 -> 6 | AI12: =AJ11 -> 51068.8 | AJ12: 51088 | AK12: =IF((AJ12-AI12)<0, "0",AJ12-AI12) -> 19.2 | AL12: =AK12*(284.34513609) -> 5459.4266 | AM12: =AL12*0.327795 -> 1789.5727 | AN12: 182 | AO12: =L12+U12+AA12+AE12 -> 16541.574
A13: 44600 | B13: =13459476-13451150 -> 8326 | C13: =8604573-8600111 -> 4462 | D13: =1706961-1706015 -> 946 | E13: =12902618-12895934 -> 6684 | F13: =12773308-12767640 -> 5668 | G13: =8963382-8960528 -> 2854 | H13: =9790702-9786963 -> 3739 | I13: =5709697-5707449 -> 2248 | J13: =13055260-13048327 -> 6933 | K13: =SUM(B13:H13) -> 32679 | L13: =K13*0.2 -> 6535.8 | M13: =13035.838-12827.467 -> 208.371 | N13: =4737.504-4734.344 -> 3.16 | O13: =10476.956-10476.59 -> 0.366 | P13: =6061.597-5988.629 -> 72.968 | Q13: =27438.969-27426.635 -> 12.334 | R13: =N13+O13+P13 -> 76.494 | S13: =(N13+O13+P13)*7.84 -> 599.71296 | T13: =M13+Q13 -> 220.705 | U13: =T13*7.84 -> 1730.3272 | V13: =399273-399055 -> 218 | W13: =149889-149701.14 -> 187.86 | X13: 0001523.20 | Y13: 996261 | Z13: =IF((Y13-Y12<0), "0",Y13-Y12) -> 838 | AA13: =Z13*6.47 -> 5421.86 | AB13: 11090220 | AC13: =AB12 -> 11080852 | AD13: =IF((AB13-AC13<0), "0",AB13-AC13) -> 9368 | AE13: =AD13*0.327795 -> 3070.7836 | AF13: =96518-96501.7 -> 16.3 | AG13: =50692.5-50692.5 -> 0 | AH13: =30494.6-30488 -> 6.6 | AI13: =AJ12 -> 51088 | AJ13: 51110 | AK13: =IF((AJ13-AI13)<0, "0",AJ13-AI13) -> 22 | AL13: =AK13*(284.34513609) -> 6255.593 | AM13: =AL13*0.327795 -> 2050.5521 | AN13: 187 | AO13: =L13+U13+AA13+AE13 -> 16758.771
A14: 44601 | B14: =13466995-13459476 -> 7519 | C14: =8609084-8604573 -> 4511 | D14: =1707877-1706961 -> 916 | E14: =12909517-12902618 -> 6899 | F14: =12779051-12773308 -> 5743 | G14: =8966145-8963382 -> 2763 | H14: =9794501-9790702 -> 3799 | I14: =5711987-5709697 -> 2290 | J14: =13062380-13055260 -> 7120 | K14: =SUM(B14:H14) -> 32150 | L14: =K14*0.2 -> 6430 | M14: =13227.521-13035.838 -> 191.683 | N14: =4739.85-4737.504 -> 2.346 | O14: =10477.381-10476.956 -> 0.425 | P14: =6129.1-6061.597 -> 67.503 | Q14: =27441.853-27438.969 -> 2.884 | R14: =N14+O14+P14 -> 70.274 | S14: =(N14+O14+P14)*7.84 -> 550.94816 | T14: =M14+Q14 -> 194.567 | U14: =T14*7.84 -> 1525.4053 | V14: =399489-399273 -> 216 | W14: =150078.8-149889 -> 189.8 | X14: 0001523.20 | Y14: 997050 | Z14: =IF((Y14-Y13<0), "0",Y14-Y13) -> 789 | AA14: =Z14*6.47 -> 5104.83 | AB14: 11100400 | AC14: =AB13 -> 11090220 | AD14: =IF((AB14-AC14<0), "0",AB14-AC14) -> 10180 | AE14: =AD14*0.327795 -> 3336.9531 | AF14: =96536.3-96518 -> 18.3 | AG14: =50692.5-50692.5 -> 0 | AH14: =30500-30494.6 -> 5.4 | AI14: =AJ13 -> 51110 | AJ14: 51131 | AK14: =IF((AJ14-AI14)<0, "0",AJ14-AI14) -> 21 | AL14: =AK14*(284.34513609) -> 5971.2479 | AM14: =AL14*0.327795 -> 1957.3452 | AN14: 189 | AO14: =L14+U14+AA14+AE14 -> 16397.188
A15: 44602 | B15: =13473292-13466995 -> 6297 | C15: =8613810-8609084 -> 4726 | D15: =1708796-1707877 -> 919 | E15: =12916323-12909517 -> 6806 | F15: =12784552-12779051 -> 5501 | G15: =8968958-8966145 -> 2813 | H15: =9798217-9794501 -> 3716 | I15: =5714231-5711987 -> 2244 | J15: =13069480-13062380 -> 7100 | K15: =SUM(B15:H15) -> 30778 | L15: =K15*0.2 -> 6155.6 | M15: =13431.899-13227.521 -> 204.378 | N15: =4742.131-4739.85 -> 2.281 | O15: =10477.611-10477.381 -> 0.23 | P15: =6202.568-6129.1 -> 73.468 | Q15: =27462.337-27441.853 -> 20.484 | R15: =N15+O15+P15 -> 75.979 | S15: =(N15+O15+P15)*7.84 -> 595.67536 | T15: =M15+Q15 -> 224.862 | U15: =T15*7.84 -> 1762.9181 | V15: =399713.9-399489 -> 224.9 | W15: =150227.8-150078.8 -> 149 | X15: 0001523.20 | Y15: 997807 | Z15: =IF((Y15-Y14<0), "0",Y15-Y14) -> 757 | AA15: =Z15*6.47 -> 4897.79 | AB15: 11112107 | AC15: =AB14 -> 11100400 | AD15: =IF((AB15-AC15<0), "0",AB15-AC15) -> 11707 | AE15: =AD15*0.327795 -> 3837.4961 | AF15: =96557.7-96536.3 -> 21.4 | AG15: =50692.5-50692.5 -> 0 | AH15: =30507.6-30500 -> 7.6 | AI15: =AJ14 -> 51131 | AJ15: 51154.7 | AK15: =IF((AJ15-AI15)<0, "0",AJ15-AI15) -> 23.7 | AL15: =AK15*(284.34513609) -> 6738.9797 | AM15: =AL15*0.327795 -> 2209.0039 | AN15: 168 | AO15: =L15+U15+AA15+AE15 -> 16653.804
A16: 44603 | B16: =13479290-13473292 -> 5998 | C16: =8618505-8613810 -> 4695 | D16: =1709714-1708796 -> 918 | E16: =12923238-12916323 -> 6915 | F16: =12790223-12784552 -> 5671 | G16: =8971786-8968958 -> 2828 | H16: =9801982-9798217 -> 3765 | I16: =5716510-5714231 -> 2279 | J16: =13076634-13069480 -> 7154 | K16: =SUM(B16:H16) -> 30790 | L16: =K16*0.2 -> 6158 | M16: =13633.799-13431.899 -> 201.9 | N16: =4744.48-4742.131 -> 2.349 | O16: =10477.762-10477.611 -> 0.151 | P16: =6284.386-6202.568 -> 81.818 | Q16: =27478.775-27462.337 -> 16.438 | R16: =N16+O16+P16 -> 84.318 | S16: =(N16+O16+P16)*7.84 -> 661.05312 | T16: =M16+Q16 -> 218.338 | U16: =T16*7.84 -> 1711.7699 | V16: =399926.9-399713.9 -> 213 | W16: =150328.8-150227.8 -> 101 | X16: 0001523.20 | Y16: 998507 | Z16: =IF((Y16-Y15<0), "0",Y16-Y15) -> 700 | AA16: =Z16*6.47 -> 4529 | AB16: 11123848 | AC16: =AB15 -> 11112107 | AD16: =IF((AB16-AC16<0), "0",AB16-AC16) -> 11741 | AE16: =AD16*0.327795 -> 3848.6411 | AF16: =96578.4-96557.7 -> 20.7 | AG16: =50692.5-50692.5 -> 0 | AH16: =30514.6-30507.6 -> 7 | AI16: =AJ15 -> 51154.7 | AJ16: 51178.7 | AK16: =IF((AJ16-AI16)<0, "0",AJ16-AI16) -> 24 | AL16: =AK16*(284.34513609) -> 6824.2833 | AM16: =AL16*0.327795 -> 2236.9659 | AN16: 174 | AO16: =L16+U16+AA16+AE16 -> 16247.411
A17: 44604 | B17: =13485729-13479290 -> 6439 | C17: =8622630-8618505 -> 4125 | D17: =1710731-1709714 -> 1017 | E17: =12930112-12923238 -> 6874 | F17: =12795866-12790223 -> 5643 | G17: =8974628-8971786 -> 2842 | H17: =9805726-9801982 -> 3744 | I17: =5718668-5716510 -> 2158 | J17: =13083914-13076634 -> 7280 | K17: =SUM(B17:H17) -> 30684 | L17: =K17*0.2 -> 6136.8 | M17: =13839.28-13633.799 -> 205.481 | N17: =4748.282-4744.48 -> 3.802 | O17: =10477.954-10477.762 -> 0.192 | P17: =6366.831-6284.386 -> 82.445 | Q17: =27489.546-27478.775 -> 10.771 | R17: =N17+O17+P17 -> 86.439 | S17: =(N17+O17+P17)*7.84 -> 677.68176 | T17: =M17+Q17 -> 216.252 | U17: =T17*7.84 -> 1695.4157 | V17: =400176.2-399926.9 -> 249.3 | W17: =150493.3-150328.8 -> 164.5 | X17: 0001523.20 | Y17: 999296 | Z17: =IF((Y17-Y16<0), "0",Y17-Y16) -> 789 | AA17: =Z17*6.47 -> 5104.83 | AB17: 11135530 | AC17: =AB16 -> 11123848 | AD17: =IF((AB17-AC17<0), "0",AB17-AC17) -> 11682 | AE17: =AD17*0.327795 -> 3829.3012 | AF17: =96598.4-96578.4 -> 20 | AG17: =50692.5-50692.5 -> 0 | AH17: =30521.5-30514.6 -> 6.9 | AI17: =AJ16 -> 51178.7 | AJ17: 51202 | AK17: =IF((AJ17-AI17)<0, "0",AJ17-AI17) -> 23.3 | AL17: =AK17*(284.34513609) -> 6625.2417 | AM17: =AL17*0.327795 -> 2171.7211 | AN17: 170 | AO17: =L17+U17+AA17+AE17 -> 16766.347
A18: 44605 | B18: =13493683-13485729 -> 7954 | C18: =8626453-8622630 -> 3823 | D18: =1711689-1710731 -> 958 | E18: =12936865-12930112 -> 6753 | F18: =12801610-12795866 -> 5744 | G18: =8977561-8974628 -> 2933 | H18: =9809422-9805726 -> 3696 | I18: =5720925-5718668 -> 2257 | J18: =13091008-13083914 -> 7094 | K18: =SUM(B18:H18) -> 31861 | L18: =K18*0.2 -> 6372.2 | M18: =14018.87-13839.28 -> 179.59 | N18: =4750.426-4748.282 -> 2.144 | O18: =10478.291-10477.954 -> 0.337 | P18: =6442.985-6366.831 -> 76.154 | Q18: =27504.761-27489.546 -> 15.215 | R18: =N18+O18+P18 -> 78.635 | S18: =(N18+O18+P18)*7.84 -> 616.4984 | T18: =M18+Q18 -> 194.805 | U18: =T18*7.84 -> 1527.2712 | V18: =400377.3-400176.2 -> 201.1 | W18: =150662.57-150493.3 -> 169.27 | X18: 0001523.20 | Y18: 1000034 | Z18: =IF((Y18-Y17<0), "0",Y18-Y17) -> 738 | AA18: =Z18*6.47 -> 4774.86 | AB18: 11145494 | AC18: =AB17 -> 11135530 | AD18: =IF((AB18-AC18<0), "0",AB18-AC18) -> 9964 | AE18: =AD18*0.327795 -> 3266.1494 | AF18: =96615.9-96598.4 -> 17.5 | AG18: =50692.5-50692.5 -> 0 | AH18: =30527.5-30521.5 -> 6 | AI18: =AJ17 -> 51202 | AJ18: 51224.2 | AK18: =IF((AJ18-AI18)<0, "0",AJ18-AI18) -> 22.2 | AL18: =AK18*(284.34513609) -> 6312.462 | AM18: =AL18*0.327795 -> 2069.1935 | AN18: 134 | AO18: =L18+U18+AA18+AE18 -> 15940.481
A19: 44606 | B19: =13500850-13493683 -> 7167 | C19: =8631114-8626453 -> 4661 | D19: =1712639-1711689 -> 950 | E19: =12944110-12936865 -> 7245 | F19: =12807500-12801610 -> 5890 | G19: =8980463-8977561 -> 2902 | H19: =9813323-9809422 -> 3901 | I19: =5723292-5720925 -> 2367 | J19: =13098261-13091008 -> 7253 | K19: =SUM(B19:H19) -> 32716 | L19: =K19*0.2 -> 6543.2 | M19: =14218.401-14018.87 -> 199.531 | N19: =4752.898-4750.426 -> 2.472 | O19: =10478.593-10478.291 -> 0.302 | P19: =6523.866-6442.985 -> 80.881 | Q19: =27534.214-27504.761 -> 29.453 | R19: =N19+O19+P19 -> 83.655 | S19: =(N19+O19+P19)*7.84 -> 655.8552 | T19: =M19+Q19 -> 228.984 | U19: =T19*7.84 -> 1795.2346 | V19: =400546.8-400377.3 -> 169.5 | W19: =150812.15-150662.57 -> 149.58 | X19: 0001523.20 | Y19: 1000737 | Z19: =IF((Y19-Y18<0), "0",Y19-Y18) -> 703 | AA19: =Z19*6.47 -> 4548.41 | AB19: 11156055 | AC19: =AB18 -> 11145494 | AD19: =IF((AB19-AC19<0), "0",AB19-AC19) -> 10561 | AE19: =AD19*0.327795 -> 3461.843 | AF19: =96635.7-96615.9 -> 19.8 | AG19: =50692.5-50692.5 -> 0 | AH19: =30533.6-30527.5 -> 6.1 | AI19: =AJ18 -> 51224.2 | AJ19: 51247 | AK19: =IF((AJ19-AI19)<0, "0",AJ19-AI19) -> 22.8 | AL19: =AK19*(284.34513609) -> 6483.0691 | AM19: =AL19*0.327795 -> 2125.1176 | AN19: 144 | AO19: =L19+U19+AA19+AE19 -> 16348.688
A20: 44607 | B20: =13507029-13500850 -> 6179 | C20: =8636115-8631114 -> 5001 | D20: =1713605-1712639 -> 966 | E20: =12950935-12944110 -> 6825 | F20: =12813277-12807500 -> 5777 | G20: =8983204-8980463 -> 2741 | H20: =9816963-9813323 -> 3640 | I20: =5725561-5723292 -> 2269 | J20: =13105302-13098261 -> 7041 | K20: =SUM(B20:H20) -> 31129 | L20: =K20*0.2 -> 6225.8 | M20: =14390.164-14218.401 -> 171.763 | N20: =4755.765-4752.898 -> 2.867 | O20: =10478.929-10478.593 -> 0.336 | P20: =6591.794-6523.866 -> 67.928 | Q20: =27534.214-27534.214 -> 0 | R20: =N20+O20+P20 -> 71.131 | S20: =(N20+O20+P20)*7.84 -> 557.66704 | T20: =M20+Q20 -> 171.763 | U20: =T20*7.84 -> 1346.6219 | V20: =400754.4-400546.8 -> 207.6 | W20: =150936.58-150812.15 -> 124.43 | X20: 0001523.20 | Y20: 1001417 | Z20: =IF((Y20-Y19<0), "0",Y20-Y19) -> 680 | AA20: =Z20*6.47 -> 4399.6 | AB20: 11168341 | AC20: =AB19 -> 11156055 | AD20: =IF((AB20-AC20<0), "0",AB20-AC20) -> 12286 | AE20: =AD20*0.327795 -> 4027.2894 | AF20: =96657.7-96635.7 -> 22 | AG20: =50692.5-50692.5 -> 0 | AH20: =30540-30533.6 -> 6.4 | AI20: =AJ19 -> 51247 | AJ20: 51270.4 | AK20: =IF((AJ20-AI20)<0, "0",AJ20-AI20) -> 23.4 | AL20: =AK20*(284.34513609) -> 6653.6762 | AM20: =AL20*0.327795 -> 2181.0418 | AN20: 134 | AO20: =L20+U20+AA20+AE20 -> 15999.311
A21: 44608 | B21: =13513323-13507029 -> 6294 | C21: =8641130-8636115 -> 5015 | D21: =1714533-1713605 -> 928 | E21: =12957852-12950935 -> 6917 | F21: =12819034-12813277 -> 5757 | G21: =8985917-8983204 -> 2713 | H21: =9820521-9816963 -> 3558 | I21: =5727797-5725561 -> 2236 | J21: =13112336-13105302 -> 7034 | K21: =SUM(B21:H21) -> 31182 | L21: =K21*0.2 -> 6236.4 | M21: =14570.111-14390.164 -> 179.947 | N21: =4758.25-4755.765 -> 2.485 | O21: =10479.027-10478.929 -> 0.098 | P21: =6669.333-6591.794 -> 77.539 | Q21: =27534.214-27534.214 -> 0 | R21: =N21+O21+P21 -> 80.122 | S21: =(N21+O21+P21)*7.84 -> 628.15648 | T21: =M21+Q21 -> 179.947 | U21: =T21*7.84 -> 1410.7845 | V21: =400959-400754.4 -> 204.6 | W21: =151110.65-150936.58 -> 174.07 | X21: 0001523.20 | Y21: 1002169 | Z21: =IF((Y21-Y20<0), "0",Y21-Y20) -> 752 | AA21: =Z21*6.47 -> 4865.44 | AB21: 11180429 | AC21: =AB20 -> 11168341 | AD21: =IF((AB21-AC21<0), "0",AB21-AC21) -> 12088 | AE21: =AD21*0.327795 -> 3962.386 | AF21: =96679.4-96657.7 -> 21.7 | AG21: =50692.5-50692.5 -> 0 | AH21: =30546.5-30540 -> 6.5 | AI21: =AJ20 -> 51270.4 | AJ21: 51295.1 | AK21: =IF((AJ21-AI21)<0, "0",AJ21-AI21) -> 24.7 | AL21: =AK21*(284.34513609) -> 7023.3249 | AM21: =AL21*0.327795 -> 2302.2108 | AN21: 145 | AO21: =L21+U21+AA21+AE21 -> 16475.01
A22: 44609 | B22: =13520174-13513323 -> 6851 | C22: =8645674-8641130 -> 4544 | D22: =1715423-1714533 -> 890 | E22: =12964727-12957852 -> 6875 | F22: =12824676-12819034 -> 5642 | G22: =8988643-8985917 -> 2726 | H22: =9824177-9820521 -> 3656 | I22: =5729920-5727797 -> 2123 | J22: =13119302-13112336 -> 6966 | K22: =SUM(B22:H22) -> 31184 | L22: =K22*0.2 -> 6236.8 | M22: =14762.155-14570.111 -> 192.044 | N22: =4760.429-4758.25 -> 2.179 | O22: =10479.039-10479.027 -> 0.012 | P22: =6745.918-6669.333 -> 76.585 | Q22: =27534.535-27534.214 -> 0.321 | R22: =N22+O22+P22 -> 78.776 | S22: =(N22+O22+P22)*7.84 -> 617.60384 | T22: =M22+Q22 -> 192.365 | U22: =T22*7.84 -> 1508.1416 | V22: =401172.2-400959 -> 213.2 | W22: =151282.6-151110.65 -> 171.95 | X22: 0001523.20 | Y22: 1002915 | Z22: =IF((Y22-Y21<0), "0",Y22-Y21) -> 746 | AA22: =Z22*6.47 -> 4826.62 | AB22: 11191024 | AC22: =AB21 -> 11180429 | AD22: =IF((AB22-AC22<0), "0",AB22-AC22) -> 10595 | AE22: =AD22*0.327795 -> 3472.988 | AF22: =96698.3-96679.4 -> 18.9 | AG22: =50692.5-50692.5 -> 0 | AH22: =30552-30546.5 -> 5.5 | AI22: =AJ21 -> 51295.1 | AJ22: 51317.4 | AK22: =IF((AJ22-AI22)<0, "0",AJ22-AI22) -> 22.3 | AL22: =AK22*(284.34513609) -> 6340.8965 | AM22: =AL22*0.327795 -> 2078.5142 | AN22: 126 | AO22: =L22+U22+AA22+AE22 -> 16044.55
A23: 44610 | B23: =13526564-13520174 -> 6390 | C23: =8650350-8645674 -> 4676 | D23: =1716283-1715423 -> 860 | E23: =12971674-12964727 -> 6947 | F23: =12830619-12824676 -> 5943 | G23: =8991415-8988643 -> 2772 | H23: =9827891-9824177 -> 3714 | I23: =5732118-5729920 -> 2198 | J23: =13126499-13119302 -> 7197 | K23: =SUM(B23:H23) -> 31302 | L23: =K23*0.2 -> 6260.4 | M23: =14960.555-14762.155 -> 198.4 | N23: =4763.47-4760.429 -> 3.041 | O23: =10479.038-10479.039 -> -0.001 | P23: =6821.519-6745.918 -> 75.601 | Q23: =27567.206-27534.534 -> 32.672 | R23: =N23+O23+P23 -> 78.641 | S23: =(N23+O23+P23)*7.84 -> 616.54544 | T23: =M23+Q23 -> 231.072 | U23: =T23*7.84 -> 1811.6045 | V23: =401388.1-401172.2 -> 215.9 | W23: =151455.3-151282.6 -> 172.7 | X23: 0001523.20 | Y23: 1003659 | Z23: =IF((Y23-Y22<0), "0",Y23-Y22) -> 744 | AA23: =Z23*6.47 -> 4813.68 | AB23: 11202468 | AC23: =AB22 -> 11191024 | AD23: =IF((AB23-AC23<0), "0",AB23-AC23) -> 11444 | AE23: =AD23*0.327795 -> 3751.286 | AF23: =96718-96698.3 -> 19.7 | AG23: =50692.5-50692.5 -> 0 | AH23: =30558-30552 -> 6 | AI23: =AJ22 -> 51317.4 | AJ23: 51341 | AK23: =IF((AJ23-AI23)<0, "0",AJ23-AI23) -> 23.6 | AL23: =AK23*(284.34513609) -> 6710.5452 | AM23: =AL23*0.327795 -> 2199.6832 | AN23: 136 | AO23: =L23+U23+AA23+AE23 -> 16636.97
A24: 44611 | B24: =13532731-13526564 -> 6167 | C24: =8655158-8650350 -> 4808 | D24: =1717208-1716283 -> 925 | E24: =12978753-12971674 -> 7079 | F24: =12836714-12830619 -> 6095 | G24: =8994339-8991415 -> 2924 | H24: =9831659-9827891 -> 3768 | I24: =5734271-5732118 -> 2153 | J24: =13133832-13126499 -> 7333 | K24: =SUM(B24:H24) -> 31766 | L24: =K24*0.2 -> 6353.2 | M24: =15120.777-14960.555 -> 160.222 | N24: =4765.542-4763.47 -> 2.072 | O24: =10479.129-10479.038 -> 0.091 | P24: =6900.805-6821.519 -> 79.286 | Q24: =27579.079-27567.206 -> 11.873 | R24: =N24+O24+P24 -> 81.449 | S24: =(N24+O24+P24)*7.84 -> 638.56016 | T24: =M24+Q24 -> 172.095 | U24: =T24*7.84 -> 1349.2248 | V24: =401618.8-401388.1 -> 230.7 | W24: =151631.55-151455.3 -> 176.25 | X24: 0001523.20 | Y24: 1004433 | Z24: =IF((Y24-Y23<0), "0",Y24-Y23) -> 774 | AA24: =Z24*6.47 -> 5007.78 | AB24: 11214654 | AC24: =AB23 -> 11202468 | AD24: =IF((AB24-AC24<0), "0",AB24-AC24) -> 12186 | AE24: =AD24*0.327795 -> 3994.5099 | AF24: =96739.7-96718 -> 21.7 | AG24: =50692.5-50692.5 -> 0 | AH24: =30564.9-30558 -> 6.9 | AI24: =AJ23 -> 51341 | AJ24: 51366.7 | AK24: =IF((AJ24-AI24)<0, "0",AJ24-AI24) -> 25.7 | AL24: =AK24*(284.34513609) -> 7307.67 | AM24: =AL24*0.327795 -> 2395.4177 | AN24: 161 | AO24: =L24+U24+AA24+AE24 -> 16704.715
A25: 44612 | B25: =13538400-13532731 -> 5669 | C25: =8659434-8655158 -> 4276 | D25: =1718080-1717208 -> 872 | E25: =12985721-12978753 -> 6968 | F25: =12842144-12836714 -> 5430 | G25: =8996960-8994339 -> 2621 | H25: =9835195-9831659 -> 3536 | I25: =5736451-5734271 -> 2180 | J25: =13140894-13133832 -> 7062 | K25: =SUM(B25:H25) -> 29372 | L25: =K25*0.2 -> 5874.4 | M25: =15334-15120.777 -> 213.223 | N25: =4767.474-4765.542 -> 1.932 | O25: =10479.132-10479.129 -> 0.003 | P25: =6976.396-6900.805 -> 75.591 | Q25: =27596.414-27579.079 -> 17.335 | R25: =N25+O25+P25 -> 77.526 | S25: =(N25+O25+P25)*7.84 -> 607.80384 | T25: =M25+Q25 -> 230.558 | U25: =T25*7.84 -> 1807.5747 | V25: =401833.7-401618.8 -> 214.9 | W25: =151800.05-151631.55 -> 168.5 | X25: 0001523.20 | Y25: 1005206 | Z25: =IF((Y25-Y24<0), "0",Y25-Y24) -> 773 | AA25: =Z25*6.47 -> 5001.31 | AB25: 11227825 | AC25: =AB24 -> 11214654 | AD25: =IF((AB25-AC25<0), "0",AB25-AC25) -> 13171 | AE25: =AD25*0.327795 -> 4317.3879 | AF25: =96763-96739.7 -> 23.3 | AG25: =50692.5-50692.5 -> 0 | AH25: =30572-30564.9 -> 7.1 | AI25: =AJ24 -> 51366.7 | AJ25: 51391 | AK25: =IF((AJ25-AI25)<0, "0",AJ25-AI25) -> 24.3 | AL25: =AK25*(284.34513609) -> 6909.5868 | AM25: =AL25*0.327795 -> 2264.928 | AN25: 161 | AO25: =L25+U25+AA25+AE25 -> 17000.673
A26: 44613 | B26: =13545027-13538400 -> 6627 | C26: =8664099-8659434 -> 4665 | D26: =1718884-1718080 -> 804 | E26: =12992229-12985721 -> 6508 | F26: =12847947-12842144 -> 5803 | G26: =8999829-8996960 -> 2869 | H26: =9838975-9835195 -> 3780 | I26: =5738723-5736451 -> 2272 | J26: =13147557-13140894 -> 6663 | K26: =SUM(B26:H26) -> 31056 | L26: =K26*0.2 -> 6211.2 | M26: =15542.8-15334 -> 208.8 | N26: =4769.347-4767.474 -> 1.873 | O26: =10479.192-10479.132 -> 0.06 | P26: =7047.488-6976.396 -> 71.092 | Q26: =27596.414-27596.414 -> 0 | R26: =N26+O26+P26 -> 73.025 | S26: =(N26+O26+P26)*7.84 -> 572.516 | T26: =M26+Q26 -> 208.8 | U26: =T26*7.84 -> 1636.992 | V26: =402060.2-401833.7 -> 226.5 | W26: =151995-151800.05 -> 194.95 | X26: 0001523.20 | Y26: 1006013 | Z26: =IF((Y26-Y25<0), "0",Y26-Y25) -> 807 | AA26: =Z26*6.47 -> 5221.29 | AB26: 11240260 | AC26: =AB25 -> 11227825 | AD26: =IF((AB26-AC26<0), "0",AB26-AC26) -> 12435 | AE26: =AD26*0.327795 -> 4076.1308 | AF26: =96784-96763 -> 21 | AG26: =50692.5-50692.5 -> 0 | AH26: =30578-30572 -> 6 | AI26: =AJ25 -> 51391 | AJ26: 51416 | AK26: =IF((AJ26-AI26)<0, "0",AJ26-AI26) -> 25 | AL26: =AK26*(284.34513609) -> 7108.6284 | AM26: =AL26*0.327795 -> 2330.1728 | AN26: 154 | AO26: =L26+U26+AA26+AE26 -> 17145.613
A27: 44614 | B27: =13553434-13545027 -> 8407 | C27: =8668887-8664099 -> 4788 | D27: =1719774-1718884 -> 890 | E27: =12998728-12992229 -> 6499 | F27: =12853871-12847947 -> 5924 | G27: =9002651-8999829 -> 2822 | H27: =9842682-9838975 -> 3707 | I27: =5740862-5738723 -> 2139 | J27: =13154357-13147557 -> 6800 | K27: =SUM(B27:H27) -> 33037 | L27: =K27*0.2 -> 6607.4 | M27: =15743.24-15542.8 -> 200.44 | N27: =4771.018-4769.347 -> 1.671 | O27: =10479.212-10479.192 -> 0.02 | P27: =7118.551-7047.488 -> 71.063 | Q27: =27596.414-27596.414 -> 0 | R27: =N27+O27+P27 -> 72.754 | S27: =(N27+O27+P27)*7.84 -> 570.39136 | T27: =M27+Q27 -> 200.44 | U27: =T27*7.84 -> 1571.4496 | V27: =402267.8-402060.2 -> 207.6 | W27: =152169.25-151995 -> 174.25 | X27: 0001523.20 | Y27: 1006786 | Z27: =IF((Y27-Y26<0), "0",Y27-Y26) -> 773 | AA27: =Z27*6.47 -> 5001.31 | AB27: 11250780 | AC27: =AB26 -> 11240260 | AD27: =IF((AB27-AC27<0), "0",AB27-AC27) -> 10520 | AE27: =AD27*0.327795 -> 3448.4034 | AF27: =96804.5-96784 -> 20.5 | AG27: =50692.5-50692.5 -> 0 | AH27: =30584.8-30578 -> 6.8 | AI27: =AJ26 -> 51416 | AJ27: 51439.5 | AK27: =IF((AJ27-AI27)<0, "0",AJ27-AI27) -> 23.5 | AL27: =AK27*(284.34513609) -> 6682.1107 | AM27: =AL27*0.327795 -> 2190.3625 | AN27: 185 | AO27: =L27+U27+AA27+AE27 -> 16628.563
A28: 44615 | B28: =13560152-13553434 -> 6718 | C28: =8673712-8668887 -> 4825 | D28: =1720725-1719774 -> 951 | E28: =13005321-12998728 -> 6593 | F28: =12859818-12853871 -> 5947 | G28: =9005451-9002651 -> 2800 | H28: =9846447-9842682 -> 3765 | I28: =5743089-5740862 -> 2227 | J28: =13161307-13154357 -> 6950 | K28: =SUM(B28:H28) -> 31599 | L28: =K28*0.2 -> 6319.8 | M28: =15932.723-15743.24 -> 189.483 | N28: =4772.776-4771.018 -> 1.758 | O28: =10479.223-10479.212 -> 0.011 | P28: =7186.336-7118.551 -> 67.785 | Q28: =27617.786-27596.414 -> 21.372 | R28: =N28+O28+P28 -> 69.554 | S28: =(N28+O28+P28)*7.84 -> 545.30336 | T28: =M28+Q28 -> 210.855 | U28: =T28*7.84 -> 1653.1032 | V28: =402506.8-402267.8 -> 239 | W28: =152353.25-152169.25 -> 184 | X28: 0001523.20 | Y28: 1007615 | Z28: =IF((Y28-Y27<0), "0",Y28-Y27) -> 829 | AA28: =Z28*6.47 -> 5363.63 | AB28: 11262280 | AC28: =AB27 -> 11250780 | AD28: =IF((AB28-AC28<0), "0",AB28-AC28) -> 11500 | AE28: =AD28*0.327795 -> 3769.6425 | AF28: =96826.5-96804.5 -> 22 | AG28: =50692.5-50692.5 -> 0 | AH28: =30590.8-30584.8 -> 6 | AI28: =AJ27 -> 51439.5 | AJ28: 51463.5 | AK28: =IF((AJ28-AI28)<0, "0",AJ28-AI28) -> 24 | AL28: =AK28*(284.34513609) -> 6824.2833 | AM28: =AL28*0.327795 -> 2236.9659 | AN28: 184 | AO28: =L28+U28+AA28+AE28 -> 17106.176
A29: 44616 | B29: =13566474-13560152 -> 6322 | C29: =8678937-8673712 -> 5225 | D29: =1721669-1720725 -> 944 | E29: =13011871-13005321 -> 6550 | F29: =12865888-12859818 -> 6070 | G29: =9008358-9005451 -> 2907 | H29: =9850225-9846447 -> 3778 | I29: =5745326-5743089 -> 2237 | J29: =13168365-13161307 -> 7058 | K29: =SUM(B29:H29) -> 31796 | L29: =K29*0.2 -> 6359.2 | M29: =16152.899-15932.723 -> 220.176 | N29: =4775.124-4772.776 -> 2.348 | O29: =10479.228-10479.223 -> 0.005 | P29: =7263.336-7186.336 -> 77 | Q29: =27617.786-27617.786 -> 0 | R29: =N29+O29+P29 -> 79.353 | S29: =(N29+O29+P29)*7.84 -> 622.12752 | T29: =M29+Q29 -> 220.176 | U29: =T29*7.84 -> 1726.1798 | V29: =402779.8-402506.8 -> 273 | W29: =152535.25-152353.25 -> 182 | X29: 0001523.20 | Y29: 1008477 | Z29: =IF((Y29-Y28<0), "0",Y29-Y28) -> 862 | AA29: =Z29*6.47 -> 5577.14 | AB29: 11274585 | AC29: =AB28 -> 11262280 | AD29: =IF((AB29-AC29<0), "0",AB29-AC29) -> 12305 | AE29: =AD29*0.327795 -> 4033.5175 | AF29: =96849.5-96826.5 -> 23 | AG29: =50692.5-50692.5 -> 0 | AH29: =30597.8-30590.8 -> 7 | AI29: =AJ28 -> 51463.5 | AJ29: 51489.2 | AK29: =IF((AJ29-AI29)<0, "0",AJ29-AI29) -> 25.7 | AL29: =AK29*(284.34513609) -> 7307.67 | AM29: =AL29*0.327795 -> 2395.4177 | AN29: 183 | AO29: =L29+U29+AA29+AE29 -> 17696.037
A30: 44617 | B30: =13572246-13566474 -> 5772 | C30: =8684039-8678937 -> 5102 | D30: =1722600-1721669 -> 931 | E30: =13018540-13011871 -> 6669 | F30: =12872062-12865888 -> 6174 | G30: =9011358-9008358 -> 3000 | H30: =9854067-9850225 -> 3842 | I30: =5747466-5745326 -> 2140 | J30: =13175209-13168365 -> 6844 | K30: =SUM(B30:H30) -> 31490 | L30: =K30*0.2 -> 6298 | M30: =16352.091-16152.899 -> 199.192 | N30: =4777.532-4775.124 -> 2.408 | O30: =10479.956-10479.228 -> 0.728 | P30: =7335.978-7263.336 -> 72.642 | Q30: =27643.264-27617.786 -> 25.478 | R30: =N30+O30+P30 -> 75.778 | S30: =(N30+O30+P30)*7.84 -> 594.09952 | T30: =M30+Q30 -> 224.67 | U30: =T30*7.84 -> 1761.4128 | V30: =403042.8-402779.8 -> 263 | W30: =152719.25-152535.25 -> 184 | X30: 0001523.20 | Y30: 1009330 | Z30: =IF((Y30-Y29<0), "0",Y30-Y29) -> 853 | AA30: =Z30*6.47 -> 5518.91 | AB30: 11287540 | AC30: =AB29 -> 11274585 | AD30: =IF((AB30-AC30<0), "0",AB30-AC30) -> 12955 | AE30: =AD30*0.327795 -> 4246.5842 | AF30: =96872.5-96849.5 -> 23 | AG30: =50692.5-50692.5 -> 0 | AH30: =30604.5-30597.8 -> 6.7 | AI30: =AJ29 -> 51489.2 | AJ30: 51514.9 | AK30: =IF((AJ30-AI30)<0, "0",AJ30-AI30) -> 25.7 | AL30: =AK30*(284.34513609) -> 7307.67 | AM30: =AL30*0.327795 -> 2395.4177 | AN30: 188 | AO30: =L30+U30+AA30+AE30 -> 17824.907
A31: 44618 | B31: =13577662-13572246 -> 5416 | C31: =8688502-8684039 -> 4463 | D31: =1723513-1722600 -> 913 | E31: =13025226-13018540 -> 6686 | F31: =12878322-12872062 -> 6260 | G31: =9014384-9011358 -> 3026 | H31: =9857910-9854067 -> 3843 | I31: =5749519-5747466 -> 2053 | J31: =13182302-13175209 -> 7093 | K31: =SUM(B31:H31) -> 30607 | L31: =K31*0.2 -> 6121.4 | M31: =16569.199-16352.091 -> 217.108 | N31: =4779.489-4777.532 -> 1.957 | O31: =10479.998-10479.959 -> 0.039 | P31: =7416.027-7335.978 -> 80.049 | Q31: =27654.96-27643.264 -> 11.696 | R31: =N31+O31+P31 -> 82.045 | S31: =(N31+O31+P31)*7.84 -> 643.2328 | T31: =M31+Q31 -> 228.804 | U31: =T31*7.84 -> 1793.8234 | V31: =403350.7-403042.8 -> 307.9 | W31: =152921.07-152719.25 -> 201.82 | X31: 0001523.20 | Y31: 1010243 | Z31: =IF((Y31-Y30<0), "0",Y31-Y30) -> 913 | AA31: =Z31*6.47 -> 5907.11 | AB31: 11301138 | AC31: =AB30 -> 11287540 | AD31: =IF((AB31-AC31<0), "0",AB31-AC31) -> 13598 | AE31: =AD31*0.327795 -> 4457.3564 | AF31: =96894.5-96872.5 -> 22 | AG31: =50692.5-50692.5 -> 0 | AH31: =30611.7-30604.5 -> 7.2 | AI31: =AJ30 -> 51514.9 | AJ31: 51541.4 | AK31: =IF((AJ31-AI31)<0, "0",AJ31-AI31) -> 26.5 | AL31: =AK31*(284.34513609) -> 7535.1461 | AM31: =AL31*0.327795 -> 2469.9832 | AN31: 148 | AO31: =L31+U31+AA31+AE31 -> 18279.69
A32: 44619 | B32: =13583312-13577662 -> 5650 | C32: =8692870-8688502 -> 4368 | D32: =1724453-1723513 -> 940 | E32: =13031923-13025226 -> 6697 | F32: =12884298-12878322 -> 5976 | G32: =9017292-9014384 -> 2908 | H32: =9861640-9857910 -> 3730 | I32: =5751672-5749519 -> 2153 | J32: =13189363-13182302 -> 7061 | K32: =SUM(B32:H32) -> 30269 | L32: =K32*0.2 -> 6053.8 | M32: =16750.999-16569.199 -> 181.8 | N32: =4781.197-4779.489 -> 1.708 | O32: =10480.054-10479.998 -> 0.056 | P32: =7491.343-7416.027 -> 75.316 | Q32: =27672.912-27654.96 -> 17.952 | R32: =N32+O32+P32 -> 77.08 | S32: =(N32+O32+P32)*7.84 -> 604.3072 | T32: =M32+Q32 -> 199.752 | U32: =T32*7.84 -> 1566.0557 | V32: =403569-403350.7 -> 218.3 | W32: =153093.14-152921.07 -> 172.07 | X32: 0001523.20 | Y32: 1011001 | Z32: =IF((Y32-Y31<0), "0",Y32-Y31) -> 758 | AA32: =Z32*6.47 -> 4904.26 | AB32: 11314685 | AC32: =AB31 -> 11301138 | AD32: =IF((AB32-AC32<0), "0",AB32-AC32) -> 13547 | AE32: =AD32*0.327795 -> 4440.6389 | AF32: =96916.4-96894.5 -> 21.9 | AG32: =50692.5-50692.5 -> 0 | AH32: =30619.5-30611.7 -> 7.8 | AI32: =AJ31 -> 51541.4 | AJ32: 51567.1 | AK32: =IF((AJ32-AI32)<0, "0",AJ32-AI32) -> 25.7 | AL32: =AK32*(284.34513609) -> 7307.67 | AM32: =AL32*0.327795 -> 2395.4177 | AN32: 140 | AO32: =L32+U32+AA32+AE32 -> 16964.755
