Workbook

Sheet TOTAL
A1: Site Name | B1: Day | C1: Month | D1: Year | E1: Total Electricity Kwh | F1: Electricity Tariff ($/Kwh) | G1: Water Utility Supply (m3) m3 | H1: Water Utility Supply (m3) $/m3 | I1: Room Nights | J1: Total Guests | K1: Food Covers
A2: Koh Samui | B2: 1 | C2: 3 | D2: 2022 | E2: =Electricity!E7 -> 9054.74 | F2: =Electricity!I7/Electricity!E7 -> 3.6414247 | G2: =Water!AW9 -> 37 | H2: 60 | I2: 17 | J2: 44 | K2: 103
A3: Koh Samui | B3: =B2+1 -> 2 | C3: 3 | D3: 2022 | E3: =Electricity!E8 -> 8598.99 | F3: =Electricity!I8/Electricity!E8 -> 3.6472782 | G3: =Water!AW10 -> 41 | H3: 60 | I3: 22 | J3: 54 | K3: 128
A4: Koh Samui | B4: =B3+1 -> 3 | C4: 3 | D4: 2022 | E4: =Electricity!E9 -> 9444.03 | F4: =Electricity!I9/Electricity!E9 -> 3.6355971 | G4: =Water!AW11 -> 51 | H4: 60 | I4: 24 | J4: 60 | K4: 138
A5: Koh Samui | B5: =B4+1 -> 4 | C5: 3 | D5: 2022 | E5: =Electricity!E10 -> 9486.97 | F5: =Electricity!I10/Electricity!E10 -> 3.6342212 | G5: =Water!AW12 -> 70 | H5: 60 | I5: 24 | J5: 51 | K5: 133
A6: Koh Samui | B6: =B5+1 -> 5 | C6: 3 | D6: 2022 | E6: =Electricity!E11 -> 9248.98 | F6: =Electricity!I11/Electricity!E11 -> 2.6037 | G6: =Water!AW13 -> 54 | H6: 60 | I6: 23 | J6: 57 | K6: 162
A7: Koh Samui | B7: =B6+1 -> 6 | C7: 3 | D7: 2022 | E7: =Electricity!E12 -> 9424 | F7: =Electricity!I12/Electricity!E12 -> 2.6037 | G7: =Water!AW14 -> 77 | H7: 60 | I7: 18 | J7: 45 | K7: 123
A8: Koh Samui | B8: =B7+1 -> 7 | C8: 3 | D8: 2022 | E8: =Electricity!E13 -> 9524.44 | F8: =Electricity!I13/Electricity!E13 -> 3.6312255 | G8: =Water!AW15 -> 68 | H8: 60 | I8: 19 | J8: 49 | K8: 133
A9: Koh Samui | B9: =B8+1 -> 8 | C9: 3 | D9: 2022 | E9: =Electricity!E14 -> 8616.74 | F9: =Electricity!I14/Electricity!E14 -> 3.5947502 | G9: =Water!AW16 -> 64 | H9: 60 | I9: 19 | J9: 47 | K9: 104
A10: Koh Samui | B10: =B9+1 -> 9 | C10: 3 | D10: 2022 | E10: =Electricity!E15 -> 8858.29 | F10: =Electricity!I15/Electricity!E15 -> 3.6352864 | G10: =Water!AW17 -> 56 | H10: 60 | I10: 20 | J10: 49 | K10: 123
A11: Koh Samui | B11: =B10+1 -> 10 | C11: 3 | D11: 2022 | E11: =Electricity!E16 -> 9150.22 | F11: =Electricity!I16/Electricity!E16 -> 3.6208943 | G11: =Water!AW18 -> 68 | H11: 60 | I11: 21 | J11: 56 | K11: 132
A12: Koh Samui | B12: =B11+1 -> 11 | C12: 3 | D12: 2022 | E12: =Electricity!E17 -> 9531.5 | F12: =Electricity!I17/Electricity!E17 -> 3.6129855 | G12: =Water!AW19 -> 46 | H12: 60 | I12: 18 | J12: 53 | K12: 121
A13: Koh Samui | B13: =B12+1 -> 12 | C13: 3 | D13: 2022 | E13: =Electricity!E18 -> 9991.87 | F13: =Electricity!I18/Electricity!E18 -> 2.6037 | G13: =Water!AW20 -> 46 | H13: 60 | I13: 22 | J13: 66 | K13: 139
A14: Koh Samui | B14: =B13+1 -> 13 | C14: 3 | D14: 2022 | E14: =Electricity!E19 -> 10877.85 | F14: =Electricity!I19/Electricity!E19 -> 2.6037 | G14: =Water!AW21 -> 100 | H14: 60 | I14: 42 | J14: 96 | K14: 194
... A32: Koh Samui | B32: =B31+1 -> 31 | C32: 3 | D32: 2022 | E32: =Electricity!E37 -> 11102.82 | F32: =Electricity!I37/Electricity!E37 -> 3.6414712 | G32: =Water!AW39 -> 63 | H32: 60 | I32: 23 | J32: 63 | K32: 187
I33: =SUM(I2:I32) -> 771 | J33: =SUM(J2:J32) -> 2078 | K33: =SUM(K2:K32) -> 5166

Sheet Electricity
A2: Power Distribution log Sheet
A3: 44621 | J3: Villa
A4: Date | B4: Kwh A | C4: Kwh B | D4: Kwh C | E4: Total | F4: Cost A | G4: Cost B | H4: Cost C | I4: Cost/Day | J4: FT.Cost | L4: Room Nights | M4: Total Guests | N4: Food Covers
F5: On Peak | G5: Off Peak | H5: Holiday
E6: Kwh | F6: 4.1839 | G6: 2.6037 | H6: 2.06037 | J6: 0.0139
A7: 1 | B7: 5946.29 | C7: 3108.45 | E7: =+B7+C7+D7 -> 9054.74 | F7: =+B7*4.1839 -> 24878.683 | G7: =+C7*2.6037 -> 8093.4713 | H7: =+D7*2.6037 -> 0 | I7: =F7+G7+H7 -> 32972.154 | J7: =+E7*-0.1243 -> -1125.5042 | L7: 17 | M7: 44 | N7: 103
A8: 2 | B8: 5678.85 | C8: 2920.14 | E8: =+B8+C8+D8 -> 8598.99 | F8: =+B8*4.1839 -> 23759.741 | G8: =+C8*2.6037 -> 7603.1685 | H8: =+D8*2.6037 -> 0 | I8: =F8+G8+H8 -> 31362.909 | J8: =+E8*-0.1243 -> -1068.8545 | L8: 22 | M8: 54 | N8: 128
A9: 3 | B9: 6167.11 | C9: 3276.92 | E9: =+B9+C9+D9 -> 9444.03 | F9: =+B9*4.1839 -> 25802.572 | G9: =+C9*2.6037 -> 8532.1166 | H9: =+D9*2.6037 -> 0 | I9: =F9+G9+H9 -> 34334.688 | J9: =+E9*-0.1243 -> -1173.8929 | L9: 24 | M9: 60 | N9: 138
A10: 4 | B10: 6186.89 | C10: 3300.08 | E10: =+B10+C10+D10 -> 9486.97 | F10: =+B10*4.1839 -> 25885.329 | G10: =+C10*2.6037 -> 8592.4183 | H10: =+D10*2.6037 -> 0 | I10: =F10+G10+H10 -> 34477.747 | J10: =+E10*-0.1243 -> -1179.2304 | L10: 24 | M10: 51 | N10: 133
A11: 5 | D11: 9248.98 | E11: =+B11+C11+D11 -> 9248.98 | F11: =+B11*4.1839 -> 0 | G11: =+C11*2.6037 -> 0 | H11: =+D11*2.6037 -> 24081.569 | I11: =F11+G11+H11 -> 24081.569 | J11: =+E11*-0.1243 -> -1149.6482 | L11: 23 | M11: 57 | N11: 162
A12: 6 | D12: 9424 | E12: =+B12+C12+D12 -> 9424 | F12: =+B12*4.1839 -> 0 | G12: =+C12*2.6037 -> 0 | H12: =+D12*2.6037 -> 24537.269 | I12: =F12+G12+H12 -> 24537.269 | J12: =+E12*-0.1243 -> -1171.4032 | L12: 18 | M12: 45 | N12: 123
A13: 7 | B13: 6193.27 | C13: 3331.17 | E13: =+B13+C13+D13 -> 9524.44 | F13: =+B13*4.1839 -> 25912.022 | G13: =+C13*2.6037 -> 8673.3673 | H13: =+D13*2.6037 -> 0 | I13: =F13+G13+H13 -> 34585.39 | J13: =+E13*-0.1243 -> -1183.8879 | L13: 19 | M13: 49 | N13: 133
A14: 8 | B14: 5404.14 | C14: 3212.6 | E14: =+B14+C14+D14 -> 8616.74 | F14: =+B14*4.1839 -> 22610.381 | G14: =+C14*2.6037 -> 8364.6466 | H14: =+D14*2.6037 -> 0 | I14: =F14+G14+H14 -> 30975.028 | J14: =+E14*-0.1243 -> -1071.0608 | L14: 19 | M14: 47 | N14: 104
A15: 9 | B15: 5782.87 | C15: 3075.42 | E15: =+B15+C15+D15 -> 8858.29 | F15: =+B15*4.1839 -> 24194.95 | G15: =+C15*2.6037 -> 8007.4711 | H15: =+D15*2.6037 -> 0 | I15: =F15+G15+H15 -> 32202.421 | J15: =+E15*-0.1243 -> -1101.0854 | L15: 20 | M15: 49 | N15: 123
A16: 10 | B16: 5890.11 | C16: 3260.11 | E16: =+B16+C16+D16 -> 9150.22 | F16: =+B16*4.1839 -> 24643.631 | G16: =+C16*2.6037 -> 8488.3484 | H16: =+D16*2.6037 -> 0 | I16: =F16+G16+H16 -> 33131.98 | J16: =+E16*-0.1243 -> -1137.3723 | L16: 21 | M16: 56 | N16: 132
A17: 11 | B17: 6087.84 | C17: 3443.66 | E17: =+B17+C17+D17 -> 9531.5 | F17: =+B17*4.1839 -> 25470.914 | G17: =+C17*2.6037 -> 8966.2575 | H17: =+D17*2.6037 -> 0 | I17: =F17+G17+H17 -> 34437.171 | J17: =+E17*-0.1243 -> -1184.7654 | L17: 18 | M17: 53 | N17: 121
A18: 12 | D18: 9991.87 | E18: =+B18+C18+D18 -> 9991.87 | F18: =+B18*4.1839 -> 0 | G18: =+C18*2.6037 -> 0 | H18: =+D18*2.6037 -> 26015.832 | I18: =F18+G18+H18 -> 26015.832 | J18: =+E18*-0.1243 -> -1241.9894 | L18: 22 | M18: 66 | N18: 139
A19: 13 | D19: 10877.85 | E19: =+B19+C19+D19 -> 10877.85 | F19: =+B19*4.1839 -> 0 | G19: =+C19*2.6037 -> 0 | H19: =+D19*2.6037 -> 28322.658 | I19: =F19+G19+H19 -> 28322.658 | J19: =+E19*-0.1243 -> -1352.1168 | L19: 42 | M19: 96 | N19: 194
A20: 14 | B20: 6894.35 | C20: 3960.93 | E20: =+B20+C20+D20 -> 10855.28 | F20: =+B20*4.1839 -> 28845.271 | G20: =+C20*2.6037 -> 10313.073 | H20: =+D20*2.6037 -> 0 | I20: =F20+G20+H20 -> 39158.344 | J20: =+E20*-0.1243 -> -1349.3113 | L20: 38 | M20: 92 | N20: 168
A21: 15 | B21: 6637.69 | C21: 3536.8 | E21: =+B21+C21+D21 -> 10174.49 | F21: =+B21*4.1839 -> 27771.431 | G21: =+C21*2.6037 -> 9208.7662 | H21: =+D21*2.6037 -> 0 | I21: =F21+G21+H21 -> 36980.197 | J21: =+E21*-0.1243 -> -1264.6891 | L21: 20 | M21: 53 | N21: 166
A22: 16 | B22: 6262.94 | C22: 3329.72 | E22: =+B22+C22+D22 -> 9592.66 | F22: =+B22*4.1839 -> 26203.515 | G22: =+C22*2.6037 -> 8669.592 | H22: =+D22*2.6037 -> 0 | I22: =F22+G22+H22 -> 34873.107 | J22: =+E22*-0.1243 -> -1192.3676 | L22: 21 | M22: 56 | N22: 141
A23: 17 | B23: 6520.03 | C23: 3485.44 | E23: =+B23+C23+D23 -> 10005.47 | F23: =+B23*4.1839 -> 27279.154 | G23: =+C23*2.6037 -> 9075.0401 | H23: =+D23*2.6037 -> 0 | I23: =F23+G23+H23 -> 36354.194 | J23: =+E23*-0.1243 -> -1243.6799 | L23: 12 | M23: 46 | N23: 146
A24: 18 | B24: 6634.38 | C24: 3102.68 | E24: =+B24+C24+D24 -> 9737.06 | F24: =+B24*4.1839 -> 27757.582 | G24: =+C24*2.6037 -> 8078.4479 | H24: =+D24*2.6037 -> 0 | I24: =F24+G24+H24 -> 35836.03 | J24: =+E24*-0.1243 -> -1210.3166 | L24: 37 | M24: 101 | N24: 142
A25: 19 | D25: 11789.67 | E25: =+B25+C25+D25 -> 11789.67 | F25: =+B25*4.1839 -> 0 | G25: =+C25*2.6037 -> 0 | H25: =+D25*2.6037 -> 30696.764 | I25: =F25+G25+H25 -> 30696.764 | J25: =+E25*-0.1243 -> -1465.456 | L25: 48 | M25: 129 | N25: 304
A26: 20 | D26: 11615.84 | E26: =+B26+C26+D26 -> 11615.84 | F26: =+B26*4.1839 -> 0 | G26: =+C26*2.6037 -> 0 | H26: =+D26*2.6037 -> 30244.163 | I26: =F26+G26+H26 -> 30244.163 | J26: =+E26*-0.1243 -> -1443.8489 | L26: 36 | M26: 88 | N26: 264
A27: 21 | B27: 6975.35 | C27: 3553.09 | E27: =+B27+C27+D27 -> 10528.44 | F27: =+B27*4.1839 -> 29184.167 | G27: =+C27*2.6037 -> 9251.1804 | H27: =+D27*2.6037 -> 0 | I27: =F27+G27+H27 -> 38435.347 | J27: =+E27*-0.1243 -> -1308.6851 | L27: 23 | M27: 82 | N27: 218
A28: 22 | B28: 6462.19 | C28: 3336.11 | E28: =+B28+C28+D28 -> 9798.3 | F28: =+B28*4.1839 -> 27037.157 | G28: =+C28*2.6037 -> 8686.2296 | H28: =+D28*2.6037 -> 0 | I28: =F28+G28+H28 -> 35723.386 | J28: =+E28*-0.1243 -> -1217.9287 | L28: 24 | M28: 75 | N28: 210
A29: 23 | B29: 6122.81 | C29: 3366.91 | E29: =+B29+C29+D29 -> 9489.72 | F29: =+B29*4.1839 -> 25617.225 | G29: =+C29*2.6037 -> 8766.4236 | H29: =+D29*2.6037 -> 0 | I29: =F29+G29+H29 -> 34383.648 | J29: =+E29*-0.1243 -> -1179.5722 | L29: 19 | M29: 55 | N29: 166
A30: 24 | B30: 6220.7 | C30: 3621.61 | E30: =+B30+C30+D30 -> 9842.31 | F30: =+B30*4.1839 -> 26026.787 | G30: =+C30*2.6037 -> 9429.586 | H30: =+D30*2.6037 -> 0 | I30: =F30+G30+H30 -> 35456.373 | J30: =+E30*-0.1243 -> -1223.3991 | L30: 20 | M30: 48 | N30: 150
A31: 25 | B31: 6740.84 | C31: 3742.36 | E31: =+B31+C31+D31 -> 10483.2 | F31: =+B31*4.1839 -> 28203 | G31: =+C31*2.6037 -> 9743.9827 | H31: =+D31*2.6037 -> 0 | I31: =F31+G31+H31 -> 37946.983 | J31: =+E31*-0.1243 -> -1303.0618 | L31: 25 | M31: 74 | N31: 130
A32: 26 | D32: 10770.22 | E32: =+B32+C32+D32 -> 10770.22 | F32: =+B32*4.1839 -> 0 | G32: =+C32*2.6037 -> 0 | H32: =+D32*2.6037 -> 28042.422 | I32: =F32+G32+H32 -> 28042.422 | J32: =+E32*-0.1243 -> -1338.7383 | L32: 26 | M32: 75 | N32: 222
A33: 27 | D33: 11291.12 | E33: =+B33+C33+D33 -> 11291.12 | F33: =+B33*4.1839 -> 0 | G33: =+C33*2.6037 -> 0 | H33: =+D33*2.6037 -> 29398.689 | I33: =F33+G33+H33 -> 29398.689 | J33: =+E33*-0.1243 -> -1403.4862 | L33: 33 | M33: 91 | N33: 233
A34: 28 | B34: 7279.02 | C34: 4213.85 | E34: =+B34+C34+D34 -> 11492.87 | F34: =+B34*4.1839 -> 30454.692 | G34: =+C34*2.6037 -> 10971.601 | H34: =+D34*2.6037 -> 0 | I34: =F34+G34+H34 -> 41426.293 | J34: =+E34*-0.1243 -> -1428.5637 | L34: 26 | M34: 75 | N34: 222
A35: 29 | B35: 7250.38 | C35: 3976.12 | E35: =+B35+C35+D35 -> 11226.5 | F35: =+B35*4.1839 -> 30334.865 | G35: =+C35*2.6037 -> 10352.624 | H35: =+D35*2.6037 -> 0 | I35: =F35+G35+H35 -> 40687.489 | J35: =+E35*-0.1243 -> -1395.4539 | L35: 24 | M35: 71 | N35: 170
A36: 30 | B36: 7037.61 | C36: 3811.6 | E36: =+B36+C36+D36 -> 10849.21 | F36: =+B36*4.1839 -> 29444.656 | G36: =+C36*2.6037 -> 9924.2629 | H36: =+D36*2.6037 -> 0 | I36: =F36+G36+H36 -> 39368.919 | J36: =+E36*-0.1243 -> -1348.5568 | L36: 27 | M36: 77 | N36: 194
A37: 31 | B37: 7291.6 | C37: 3811.22 | E37: =+B37+C37+D37 -> 11102.82 | F37: =+B37*4.1839 -> 30507.325 | G37: =+C37*2.6037 -> 9923.2735 | H37: =+D37*2.6037 -> 0 | I37: =F37+G37+H37 -> 40430.599 | J37: =+E37*-0.1243 -> -1380.0805 | L37: 23 | M37: 63 | N37: 187
A38: Total | B38: =SUM(B6:B36) -> 140375.66 | C38: =SUM(C6:C36) -> 75965.77 | D38: =SUM(D6:D36) -> 85009.55 | E38: =SUM(E6:E36) -> 301350.98 | F38: =SUM(F6:F36) -> 587321.91 | G38: =SUM(G6:G36) -> 197794.68 | H38: =SUM(H6:H36) -> 221341.43 | I38: =SUM(I7:I37) -> 1046879.8 | J38: =SUM(J6:J36) -> -37457.913
G39: Peak Demand | I39: =A41*132.93 -> 0
A40: Peak Demand | C40: Date | E40: Time | G40: Service | I40: 312.24
E41: 18.3 | G41: Electric Cost | I41: =SUM(I38:I40) -> 1047192
...

Sheet Water
D3: Engineering Department
D4: Water Meter Log Sheet Villas Zone | I4: Every Sunday HK Drain all Villas & PA
D6: 44621 | AG6: **new** | AU6: old name coco rum
A7: Date | B7: Main Kit | C7: Unit | D7: Arrival sala | E7: Unit | F7: Soi 100 | G7: Unit | H7: Soi 200 | I7: Unit | J7: Soi 300 | K7: Unit | L7: Soi 400 | M7: Unit | N7: Soi 500 | O7: Unit | P7: Soi 600 | Q7: Unit | R7: Soi 700 | S7: Unit | T7: Soi 800 3 room | U7: Unit | V7: soi 900-901 | W7: Unit | X7: soi 902-907 | Y7: Unit | Z7: soi 908-910 Water supply from Soi 500 | AA7: Unit | AB7: All Soi Consumption M3 | AC7: Pla Pla | AD7: Unit | AE7: Pla Pla2 | AF7: Unit | AG7: (Meter Tag Coco rum ) under CoCoRum for the Bar & MP | AH7: Unit | AI7: Spa | AJ7: Unit | AK7: Beach House & kid club | AL7: Unit | AM7: GM Executive Office | AN7: Unit | AO7: Library Toilets | AP7: Unit | AQ7: Fitness | AR7: Unit | AS7: Retail Shop Toielts | AT7: Unit | AU7: Main Pool | AV7: Unit | AW7: Total Villa Consumption | AX7: Occ%
A8: 28 | B8: 28808 | D8: 12891 | F8: 33594 | H8: 26958 | J8: 21892 | L8: 16548 | N8: 14683 | P8: 21446 | R8: 25774 | T8: 1812 | V8: 3392 | X8: 31306 | Z8: 12902 | AC8: 13442 | AE8: 5254 | AG8: 5254 | AI8: 39732 | AK8: 4735 | AM8: 1616 | AO8: 1713 | AQ8: 539 | AS8: 1445 | AU8: 10149 | AW8: 48
A9: 1 | B9: 28813 | C9: 5 | D9: 12892 | E9: 1 | F9: 33599 | G9: 5 | H9: 26961 | I9: 3 | J9: 21894 | K9: 2 | L9: 16551 | M9: 3 | N9: 14685 | O9: 2 | P9: 21446 | Q9: 0 | R9: 25777 | S9: 3 | T9: 1814 | U9: 2 | V9: 3393 | W9: 1 | X9: 31308 | Y9: 2 | Z9: 12902 | AA9: 0 | AB9: 18 | AC9: 13448 | AD9: 6 | AE9: 5254 | AF9: 0 | AG9: 5254 | AH9: 0 | AI9: 39733 | AJ9: 1 | AK9: 4735 | AL9: 0 | AM9: 1617 | AN9: 1 | AO9: 1713 | AP9: 0 | AQ9: 539 | AR9: 0 | AS9: 1445 | AT9: 0 | AU9: 10149 | AV9: 0 | AW9: 37
A10: 2 | B10: 28819 | C10: 6 | D10: 12893 | E10: 1 | F10: 33602 | G10: 3 | H10: 26968 | I10: 7 | J10: 21896 | K10: 2 | L10: 16552 | M10: 1 | N10: 14687 | O10: 2 | P10: 21448 | Q10: 2 | R10: 25781 | S10: 4 | T10: 1817 | U10: 3 | V10: 3393 | W10: 0 | X10: 31310 | Y10: 2 | Z10: 12902 | AA10: 0 | AB10: 23 | AC10: 13454 | AD10: 6 | AE10: 5254 | AF10: 0 | AG10: 5254 | AH10: 0 | AI10: 39733 | AJ10: 0 | AK10: 4735 | AL10: 0 | AM10: 1618 | AN10: 1 | AO10: 1713 | AP10: 0 | AQ10: 539 | AR10: 0 | AS10: 1445 | AT10: 0 | AU10: 10150 | AV10: 1 | AW10: 41
A11: 3 | B11: 28825 | C11: 6 | D11: 12895 | E11: 2 | F11: 33606 | G11: 4 | H11: 26970 | I11: 2 | J11: 21898 | K11: 2 | L11: 16555 | M11: 3 | N11: 14688 | O11: 1 | P11: 21450 | Q11: 2 | R11: 25787 | S11: 6 | T11: 1819 | U11: 2 | V11: 3394 | W11: 1 | X11: 31312 | Y11: 2 | Z11: 12903 | AA11: 1 | AB11: 22 | AC11: 13461 | AD11: 7 | AE11: 5254 | AF11: 0 | AG11: 5254 | AH11: 0 | AI11: 39736 | AJ11: 3 | AK11: 4739 | AL11: 4 | AM11: 1619 | AN11: 1 | AO11: 1713 | AP11: 0 | AQ11: 539 | AR11: 0 | AS11: 1446 | AT11: 1 | AU11: 10151 | AV11: 1 | AW11: 51
A12: 4 | B12: 28832 | C12: 7 | D12: 12895 | E12: 0 | F12: 33611 | G12: 5 | H12: 26974 | I12: 4 | J12: 21900 | K12: 2 | L12: 16558 | M12: 3 | N12: 14694 | O12: 6 | P12: 21452 | Q12: 2 | R12: 25790 | S12: 3 | T12: 1824 | U12: 5 | V12: 3394 | W12: 0 | X12: 31314 | Y12: 2 | Z12: 12903 | AA12: 0 | AB12: 27 | AC12: 13474 | AD12: 13 | AE12: 5259 | AF12: 5 | AG12: 5259 | AH12: 5 | AI12: 39740 | AJ12: 4 | AK12: 4740 | AL12: 1 | AM12: 1620 | AN12: 1 | AO12: 1714 | AP12: 1 | AQ12: 539 | AR12: 0 | AS12: 1446 | AT12: 0 | AU12: 10157 | AV12: 6 | AW12: 70
A13: 5 | B13: 28837 | C13: 5 | D13: 12897 | E13: 2 | F13: 33616 | G13: 5 | H13: 26977 | I13: 3 | J13: 21904 | K13: 4 | L13: 16561 | M13: 3 | N13: 14696 | O13: 2 | P13: 21454 | Q13: 2 | R13: 25792 | S13: 2 | T13: 1826 | U13: 2 | V13: 3394 | W13: 0 | X13: 31316 | Y13: 2 | Z13: 12903 | AA13: 0 | AB13: 20 | AC13: 13483 | AD13: 9 | AE13: 5261 | AF13: 2 | AG13: 5261 | AH13: 2 | AI13: 39746 | AJ13: 6 | AK13: 4740 | AL13: 0 | AM13: 1622 | AN13: 2 | AO13: 1714 | AP13: 0 | AQ13: 539 | AR13: 0 | AS13: 1446 | AT13: 0 | AU13: 10160 | AV13: 3 | AW13: 54
A14: 6 | B14: 28844 | C14: 7 | D14: 12899 | E14: 2 | F14: 33623 | G14: 7 | H14: 26986 | I14: 9 | J14: 21907 | K14: 3 | L14: 16565 | M14: 4 | N14: 14700 | O14: 4 | P14: 21457 | Q14: 3 | R14: 25795 | S14: 3 | T14: 1829 | U14: 3 | V14: 3395 | W14: 1 | X14: 31320 | Y14: 4 | Z14: 12903 | AA14: 0 | AB14: 34 | AC14: 13494 | AD14: 11 | AE14: 5263 | AF14: 2 | AG14: 5263 | AH14: 2 | AI14: 39753 | AJ14: 7 | AK14: 4741 | AL14: 1 | AM14: 1624 | AN14: 2 | AO14: 1714 | AP14: 0 | AQ14: 539 | AR14: 0 | AS14: 1447 | AT14: 1 | AU14: 10163 | AV14: 3 | AW14: 77
A15: 7 | B15: 28850 | C15: 6 | D15: 12899 | E15: 0 | F15: 33626 | G15: 3 | H15: 27018 | I15: 32 | J15: 21908 | K15: 1 | L15: 16567 | M15: 2 | N15: 14702 | O15: 2 | P15: 21458 | Q15: 1 | R15: 25798 | S15: 3 | T15: 1830 | U15: 1 | V15: 3396 | W15: 1 | X15: 31322 | Y15: 2 | Z15: 12903 | AA15: 0 | AB15: 45 | AC15: 13501 | AD15: 7 | AE15: 5263 | AF15: 0 | AG15: 5263 | AH15: 0 | AI15: 39755 | AJ15: 2 | AK15: 4741 | AL15: 0 | AM15: 1627 | AN15: 3 | AO15: 1714 | AP15: 0 | AQ15: 540 | AR15: 1 | AS15: 1447 | AT15: 0 | AU15: 10164 | AV15: 1 | AW15: 68
A16: 8 | B16: 28857 | C16: 7 | D16: 12901 | E16: 2 | F16: 33629 | G16: 3 | H16: 27043 | I16: 25 | J16: 21910 | K16: 2 | L16: 16568 | M16: 1 | N16: 14704 | O16: 2 | P16: 21460 | Q16: 2 | R16: 25804 | S16: 6 | T16: 1833 | U16: 3 | V16: 3396 | W16: 0 | X16: 31323 | Y16: 1 | Z16: 12903 | AA16: 0 | AB16: 42 | AC16: 13509 | AD16: 8 | AE16: 5263 | AF16: 0 | AG16: 5263 | AH16: 0 | AI16: 39755 | AJ16: 0 | AK16: 4741 | AL16: 0 | AM16: 1628 | AN16: 1 | AO16: 1715 | AP16: 1 | AQ16: 540 | AR16: 0 | AS16: 1447 | AT16: 0 | AU16: 10164 | AV16: 0 | AW16: 64
A17: 9 | B17: 28864 | C17: 7 | D17: 12902 | E17: 1 | F17: 33632 | G17: 3 | H17: 27045 | I17: 2 | J17: 21912 | K17: 2 | L17: 16571 | M17: 3 | N17: 14722 | O17: 18 | P17: 21461 | Q17: 1 | R17: 25806 | S17: 2 | T17: 1834 | U17: 1 | V17: 3396 | W17: 0 | X17: 31324 | Y17: 1 | Z17: 12903 | AA17: 0 | AB17: 30 | AC17: 13516 | AD17: 7 | AE17: 5263 | AF17: 0 | AG17: 5263 | AH17: 0 | AI17: 39756 | AJ17: 1 | AK17: 4741 | AL17: 0 | AM17: 1630 | AN17: 2 | AO17: 1719 | AP17: 4 | AQ17: 540 | AR17: 0 | AS17: 1447 | AT17: 0 | AU17: 10165 | AV17: 1 | AW17: 56
A18: 10 | B18: 28870 | C18: 6 | D18: 12903 | E18: 1 | F18: 33661 | G18: 29 | H18: 27048 | I18: 3 | J18: 21914 | K18: 2 | L18: 16575 | M18: 4 | N18: 14723 | O18: 1 | P18: 21464 | Q18: 3 | R18: 25810 | S18: 4 | T18: 1835 | U18: 1 | V18: 3397 | W18: 1 | X18: 31325 | Y18: 1 | Z18: 12903 | AA18: 0 | AB18: 20 | AC18: 13524 | AD18: 8 | AE18: 5263 | AF18: 0 | AG18: 5263 | AH18: 0 | AI18: 39757 | AJ18: 1 | AK18: 4742 | AL18: 1 | AM18: 1631 | AN18: 1 | AO18: 1719 | AP18: 0 | AQ18: 540 | AR18: 0 | AS18: 1447 | AT18: 0 | AU18: 10166 | AV18: 1 | AW18: 68
A19: 11 | B19: 28876 | C19: 6 | D19: 12904 | E19: 1 | F19: 33673 | G19: 12 | H19: 27049 | I19: 1 | J19: 21915 | K19: 1 | L19: 16578 | M19: 3 | N19: 14723 | O19: 0 | P19: 21467 | Q19: 3 | R19: 25816 | S19: 6 | T19: 1838 | U19: 3 | V19: 3398 | W19: 1 | X19: 31328 | Y19: 3 | Z19: 12903 | AA19: 0 | AB19: 21 | AC19: 13528 | AD19: 4 | AE19: 5263 | AF19: 0 | AG19: 5263 | AH19: 0 | AI19: 39758 | AJ19: 1 | AK19: 4742 | AL19: 0 | AM19: 1632 | AN19: 1 | AO19: 1719 | AP19: 0 | AQ19: 540 | AR19: 0 | AS19: 1447 | AT19: 0 | AU19: 10166 | AV19: 0 | AW19: 46
A20: 12 | B20: 28883 | C20: 7 | D20: 12906 | E20: 2 | F20: 33678 | G20: 5 | H20: 27051 | I20: 2 | J20: 21917 | K20: 2 | L20: 16581 | M20: 3 | N20: 14724 | O20: 1 | P20: 21469 | Q20: 2 | R20: 25818 | S20: 2 | T20: 1840 | U20: 2 | V20: 3398 | W20: 0 | X20: 31330 | Y20: 2 | Z20: 12903 | AA20: 0 | AB20: 16 | AC20: 13535 | AD20: 7 | AE20: 5264 | AF20: 1 | AG20: 5264 | AH20: 1 | AI20: 39762 | AJ20: 4 | AK20: 4742 | AL20: 0 | AM20: 1634 | AN20: 2 | AO20: 1719 | AP20: 0 | AQ20: 540 | AR20: 0 | AS20: 1448 | AT20: 1 | AU20: 10167 | AV20: 1 | AW20: 46
... A36: 28 | B36: 29022 | C36: 9 | D36: 12939 | E36: 2 | F36: 33780 | G36: 5 | H36: 27116 | I36: 5 | J36: 21963 | K36: 2 | L36: 16623 | M36: 4 | N36: 14782 | O36: 2 | P36: 21547 | Q36: 2 | R36: 25890 | S36: 8 | T36: 1905 | U36: 0 | V36: 3410 | W36: 0 | X36: 31373 | Y36: 2 | Z36: 13022 | AA36: 0 | AB36: 25 | AC36: 13653 | AD36: 9 | AE36: 5288 | AF36: 0 | AG36: 5288 | AH36: 0 | AI36: 39834 | AJ36: 4 | AK36: 4754 | AL36: 1 | AM36: 1663 | AN36: 0 | AO36: 1743 | AP36: 0 | AQ36: 540 | AR36: 0 | AS36: 1454 | AT36: 0 | AU36: 10207 | AV36: 4 | AW36: 59
A37: 29 | B37: 29031 | C37: 9 | D37: 12943 | E37: 4 | F37: 33787 | G37: 7 | H37: 27122 | I37: 6 | J37: 21967 | K37: 4 | L37: 16627 | M37: 4 | N37: 14786 | O37: 4 | P37: 21549 | Q37: 2 | R37: 25893 | S37: 3 | T37: 1906 | U37: 1 | V37: 3410 | W37: 0 | X37: 31374 | Y37: 1 | Z37: 13022 | AA37: 0 | AB37: 25 | AC37: 13661 | AD37: 8 | AE37: 5297 | AF37: 9 | AG37: 5297 | AH37: 9 | AI37: 39836 | AJ37: 2 | AK37: 4761 | AL37: 7 | AM37: 1668 | AN37: 5 | AO37: 1743 | AQ37: 540 | AR37: 0 | AS37: 1454 | AT37: 0 | AU37: 10214 | AV37: 7 | AW37: 83
A38: 30 | B38: 29036 | C38: 5 | D38: 12944 | E38: 1 | F38: 33789 | G38: 2 | H38: 27127 | I38: 5 | J38: 21968 | K38: 1 | L38: 16629 | M38: 2 | N38: 14789 | O38: 3 | P38: 21551 | Q38: 2 | R38: 25896 | S38: 3 | T38: 1906 | U38: 0 | V38: 3410 | W38: 0 | X38: 31374 | Y38: 0 | Z38: 13022 | AA38: 0 | AB38: 16 | AC38: 13666 | AD38: 5 | AE38: 5300 | AF38: 3 | AG38: 5300 | AH38: 3 | AI38: 39837 | AJ38: 1 | AK38: 4761 | AL38: 0 | AM38: 1668 | AN38: 0 | AO38: 1743 | AP38: 0 | AQ38: 540 | AR38: 0 | AS38: 1454 | AT38: 0 | AU38: 10217 | AV38: 3 | AW38: 36
A39: 31 | B39: 29047 | C39: 11 | D39: 12945 | E39: 1 | F39: 33794 | G39: 5 | H39: 27132 | I39: 5 | J39: 21971 | K39: 3 | L39: 16632 | M39: 3 | N39: 14791 | O39: 2 | P39: 21554 | Q39: 3 | R39: 25899 | S39: 3 | T39: 1908 | U39: 2 | V39: 3410 | W39: 0 | X39: 31377 | Y39: 3 | Z39: 13022 | AA39: 0 | AB39: 24 | AC39: 13672 | AD39: 6 | AE39: 5303 | AF39: 3 | AG39: 5303 | AH39: 3 | AI39: 39840 | AJ39: 3 | AK39: 4762 | AL39: 1 | AM39: 1670 | AN39: 2 | AO39: 1744 | AP39: 1 | AQ39: 541 | AR39: 1 | AS39: 1455 | AT39: 1 | AU39: 10221 | AV39: 4 | AW39: 63
A40: Total | C40: 239 | E40: 54 | G40: 200 | I40: 174 | K40: 79 | M40: 84 | O40: 108 | Q40: 108 | S40: 125 | U40: 96 | W40: 18 | Y40: 71 | AA40: 120 | AB40: 959 | AD40: 230 | AF40: 49 | AH40: 49 | AJ40: 108 | AL40: 27 | AN40: 54 | AP40: 31 | AR40: 2 | AT40: 10 | AV40: 72 | AW40: =SUM(AW9:AW39) -> 2059
A42: Remark
