Workbook

Sheet TOTAL
A1: Site Name | B1: Day | C1: Month | D1: Year | E1: Total Electricity Kwh | F1: Electricity Tariff ($/Kwh) | G1: LPG (Kg) | H1: LPG $/Kg | I1: Water Utility Supply (m3) m3 | J1: Water Utility Supply (m3) $/m3 | K1: Room Nights | N1: Water Tanks | O1: Cost of Water Tanks Rs | P1: Water Utility Supply (m3) Rs/m3 | Q1: Electricity Tariff (Rs/Kwh) | R1: LPG Rs/Kg | S1: Exchange Rate | T1: Total LPG Cost | U1: Total Water Cost
A2: Mauritius at Anahita | B2: 1 | C2: 3 | D2: 2022 | E2: =HOTEL!E4 -> 24675 | F2: 6.25 | G2: =HOTEL!CV4 -> 41073 | H2: 67.75 | I2: =HOTEL!Z4+HOTEL!AF4 -> 433 | J2: =P2 -> 21.200924 | K2: =HOTEL!EP4 -> 0.6374 | N2: =HOTEL!AD4 -> 0 | O2: =N2*4000 -> 0 | P2: =IFERROR(((((HOTEL!Z4*34))+(N2*2500))/(I2+N2*40)),0) -> 21.200924 | Q2: 6.21 | R2: 70.35 | S2: 33.88 | T2: =G2*H2 -> 2782695.8 | U2: =I2*P2 -> 9180
A3: Mauritius at Anahita | B3: =B2+1 -> 2 | C3: 3 | D3: 2022 | E3: =HOTEL!E5 -> 26805 | F3: 6.25 | G3: =HOTEL!CV5 -> 41110 | H3: 67.75 | I3: =HOTEL!Z5+HOTEL!AF5 -> 448 | J3: =P3 -> 34 | K3: =HOTEL!EP5 -> 0.5275 | N3: =HOTEL!AD5 -> 0 | O3: =N3*4000 -> 0 | P3: =IFERROR(((((HOTEL!Z5*34))+(N3*2500))/(I3+N3*40)),0) -> 34 | Q3: 6.21 | R3: 70.35 | S3: 33.88 | T3: =G3*H3 -> 2785202.5 | U3: =I3*P3 -> 15232
A4: Mauritius at Anahita | B4: =B3+1 -> 3 | C4: 3 | D4: 2022 | E4: =HOTEL!E6 -> 26096 | F4: 6.25 | G4: =HOTEL!CV6 -> 41151 | H4: 67.75 | I4: =HOTEL!Z6+HOTEL!AF6 -> 448 | J4: =P4 -> 34 | K4: =HOTEL!EP6 -> 0.5165 | N4: =HOTEL!AD6 -> 0 | O4: =N4*4000 -> 0 | P4: =IFERROR(((((HOTEL!Z6*34))+(N4*2500))/(I4+N4*40)),0) -> 34 | Q4: 6.21 | R4: 70.35 | S4: 33.88 | T4: =G4*H4 -> 2787980.2 | U4: =I4*P4 -> 15232
A5: Mauritius at Anahita | B5: =B4+1 -> 4 | C5: 3 | D5: 2022 | E5: =HOTEL!E7 -> 26123 | F5: 6.25 | G5: =HOTEL!CV7 -> 41190 | H5: 67.75 | I5: =HOTEL!Z7+HOTEL!AF7 -> 126 | J5: =P5 -> 14.031746 | K5: =HOTEL!EP7 -> 0.4725 | N5: =HOTEL!AD7 -> 0 | O5: =N5*4000 -> 0 | P5: =IFERROR(((((HOTEL!Z7*34))+(N5*2500))/(I5+N5*40)),0) -> 14.031746 | Q5: 6.21 | R5: 70.35 | S5: 33.88 | T5: =G5*H5 -> 2790622.5 | U5: =I5*P5 -> 1768
A6: Mauritius at Anahita | B6: =B5+1 -> 5 | C6: 3 | D6: 2022 | E6: =HOTEL!E8 -> 26469 | F6: 6.25 | G6: =HOTEL!CV8 -> 41232 | H6: 67.75 | I6: =HOTEL!Z8+HOTEL!AF8 -> 359 | J6: =P6 -> 26.044568 | K6: =HOTEL!EP8 -> 0.4835 | N6: =HOTEL!AD8 -> 0 | O6: =N6*4000 -> 0 | P6: =IFERROR(((((HOTEL!Z8*34))+(N6*2500))/(I6+N6*40)),0) -> 26.044568 | Q6: 6.21 | R6: 70.35 | S6: 33.88 | T6: =G6*H6 -> 2793468 | U6: =I6*P6 -> 9350
A7: Mauritius at Anahita | B7: =B6+1 -> 6 | C7: 3 | D7: 2022 | E7: =HOTEL!E9 -> 23858 | F7: 6.25 | G7: =HOTEL!CV9 -> 41258 | H7: 67.75 | I7: =HOTEL!Z9+HOTEL!AF9 -> 306 | J7: =P7 -> 34 | K7: =HOTEL!EP9 -> 0.4286 | N7: =HOTEL!AD9 -> 0 | O7: =N7*4000 -> 0 | P7: =IFERROR(((((HOTEL!Z9*34))+(N7*2500))/(I7+N7*40)),0) -> 34 | Q7: 6.21 | R7: 70.35 | S7: 33.88 | T7: =G7*H7 -> 2795229.5 | U7: =I7*P7 -> 10404
A8: Mauritius at Anahita | B8: =B7+1 -> 7 | C8: 3 | D8: 2022 | E8: =HOTEL!E10 -> 25036 | F8: 6.25 | G8: =HOTEL!CV10 -> 41297 | H8: 67.75 | I8: =HOTEL!Z10+HOTEL!AF10 -> 328 | J8: =P8 -> 34 | K8: =HOTEL!EP10 -> 0.4835 | N8: =HOTEL!AD10 -> 0 | O8: =N8*4000 -> 0 | P8: =IFERROR(((((HOTEL!Z10*34))+(N8*2500))/(I8+N8*40)),0) -> 34 | Q8: 6.21 | R8: 70.35 | S8: 33.88 | T8: =G8*H8 -> 2797871.8 | U8: =I8*P8 -> 11152
A9: Mauritius at Anahita | B9: =B8+1 -> 8 | C9: 3 | D9: 2022 | E9: =HOTEL!E11 -> 22122 | F9: 6.25 | G9: =HOTEL!CV11 -> 41334 | H9: 67.75 | I9: =HOTEL!Z11+HOTEL!AF11 -> 372 | J9: =P9 -> 20.016129 | K9: =HOTEL!EP11 -> 0.4615 | N9: =HOTEL!AD11 -> 0 | O9: =N9*4000 -> 0 | P9: =IFERROR(((((HOTEL!Z11*34))+(N9*2500))/(I9+N9*40)),0) -> 20.016129 | Q9: 6.21 | R9: 70.35 | S9: 33.88 | T9: =G9*H9 -> 2800378.5 | U9: =I9*P9 -> 7446
A10: Mauritius at Anahita | B10: =B9+1 -> 9 | C10: 3 | D10: 2022 | E10: =HOTEL!E12 -> 23254 | F10: 6.25 | G10: =HOTEL!CV12 -> 41375.7 | H10: 67.75 | I10: =HOTEL!Z12+HOTEL!AF12 -> 302 | J10: =P10 -> 25.89404 | K10: =HOTEL!EP12 -> 0.5495 | N10: =HOTEL!AD12 -> 0 | O10: =N10*4000 -> 0 | P10: =IFERROR(((((HOTEL!Z12*34))+(N10*2500))/(I10+N10*40)),0) -> 25.89404 | Q10: 6.21 | R10: 70.35 | S10: 33.93 | T10: =G10*H10 -> 2803203.7 | U10: =I10*P10 -> 7820
A11: Mauritius at Anahita | B11: =B10+1 -> 10 | C11: 3 | D11: 2022 | E11: =HOTEL!E13 -> 24237 | F11: 6.25 | G11: =HOTEL!CV13 -> 41403 | H11: 67.75 | I11: =HOTEL!Z13+HOTEL!AF13 -> 238 | J11: =P11 -> 11 | K11: =HOTEL!EP13 -> 0.5055 | N11: =HOTEL!AD13 -> 0 | O11: =N11*4000 -> 0 | P11: =IFERROR(((((HOTEL!Z13*34))+(N11*2500))/(I11+N11*40)),0) -> 11 | Q11: 6.21 | R11: 70.35 | S11: 33.93 | T11: =G11*H11 -> 2805053.2 | U11: =I11*P11 -> 2618
A12: Mauritius at Anahita | B12: =B11+1 -> 11 | C12: 3 | D12: 2022 | E12: =HOTEL!E14 -> 24488 | F12: 6.25 | G12: =HOTEL!CV14 -> 41441 | H12: 67.75 | I12: =HOTEL!Z14+HOTEL!AF14 -> 315 | J12: =P12 -> 11.44127 | K12: =HOTEL!EP14 -> 0.4286 | N12: =HOTEL!AD14 -> 0 | O12: =N12*4000 -> 0 | P12: =IFERROR(((((HOTEL!Z14*34))+(N12*2500))/(I12+N12*40)),0) -> 11.44127 | Q12: 6.21 | R12: 70.35 | S12: 33.93 | T12: =G12*H12 -> 2807627.8 | U12: =I12*P12 -> 3604
A13: Mauritius at Anahita | B13: =B12+1 -> 12 | C13: 3 | D13: 2022 | E13: =HOTEL!E15 -> 25144 | F13: 6.25 | G13: =HOTEL!CV15 -> 41481 | H13: 67.75 | I13: =HOTEL!Z15+HOTEL!AF15 -> 778 | J13: =P13 -> 16.213368 | K13: =HOTEL!EP15 -> 0.4725 | N13: =HOTEL!AD15 -> 0 | O13: =N13*4000 -> 0 | P13: =IFERROR(((((HOTEL!Z15*34))+(N13*2500))/(I13+N13*40)),0) -> 16.213368 | Q13: 6.21 | R13: 70.35 | S13: 33.93 | T13: =G13*H13 -> 2810337.8 | U13: =I13*P13 -> 12614
A14: Mauritius at Anahita | B14: =B13+1 -> 13 | C14: 3 | D14: 2022 | E14: =HOTEL!E16 -> 23469 | F14: 6.25 | G14: =HOTEL!CV16 -> 41510 | H14: 67.75 | I14: =HOTEL!Z16+HOTEL!AF16 -> 223 | J14: =P14 -> 24.242152 | K14: =HOTEL!EP16 -> 0.5055 | N14: =HOTEL!AD16 -> 0 | O14: =N14*4000 -> 0 | P14: =IFERROR(((((HOTEL!Z16*34))+(N14*2500))/(I14+N14*40)),0) -> 24.242152 | Q14: 6.21 | R14: 70.35 | S14: 33.93 | T14: =G14*H14 -> 2812302.5 | U14: =I14*P14 -> 5406
... A32: Mauritius at Anahita | B32: =B31+1 -> 31 | C32: 3 | D32: 2022 | E32: =HOTEL!E34 -> 22834 | F32: 9.25 | G32: =HOTEL!CV34 -> 42207 | H32: 70.75 | I32: =HOTEL!Z34+HOTEL!AF34 -> 654 | J32: =P32 -> 14.712538 | K32: =HOTEL!EP34 -> 0.3516 | N32: =HOTEL!AD34 -> 0 | O32: =N32*4000 -> 0 | P32: =IFERROR(((((HOTEL!Z34*34))+(N32*2500))/(I32+N32*40)),0) -> 14.712538 | Q32: 9.21 | R32: 70.35 | S32: 36.93 | T32: =G32*H32 -> 2986145.2 | U32: =I32*P32 -> 9622

Sheet Submetering
A1: Site Name | B1: Day | C1: Month | D1: Year | E1: Hotel (KWh) | F1: Vacoas (KWh) | G1: Laundry (KWh) | H1: Villa 145 (KWh) | I1: Villa 146 (KWh) | J1: Villa 111 (KWh) | K1: Villa 128 (KWh) | L1: Hotel (m3) | M1: Bamboo Pool (m3) | N1: Island (m3) | O1: Main Building (m3) | P1: Pantry A (m3) | Q1: Pantry B (m3) | R1: Pantry C (m3) | S1: Pantry D (m3) | T1: Pantry E (m3) | U1: Pantry F (m3) | V1: Pantry G (m3) | W1: North Parcel (m3) | X1: South Parcel (m3) | Y1: Beau champ (Kg) | Z1: Acquapazza (Kg) | AA1: Bamboo (Kg) | AB1: Steam Boiler (Kg) | AC1: Laundry (Kg) | AD1: Pantry A (Kg) | AE1: Pantry B (Kg) | AF1: Pantry C (Kg) | AG1: Pantry D (Kg) | AH1: Pantry E (Kg) | AI1: Pantry F (Kg) | AJ1: Pantry G (Kg) | AK1: Room Nights
A2: Mauritius at Anahita | B2: =TOTAL!B2 -> 1 | C2: =TOTAL!C2 -> 3 | D2: 2021 | E2: =TOTAL!E2 -> 24675 | F2: =HOTEL!V4 -> 873 | G2: =HOTEL!X4 -> 417 | H2: =HOTEL!EI4 -> 0 | I2: =HOTEL!EK4 -> 0 | J2: =HOTEL!EM4 -> 0 | K2: =HOTEL!EO4 -> 0 | L2: =N2+W2+X2 -> 77 | M2: =HOTEL!AL4 -> 0 | N2: =HOTEL!AT4 -> 1 | O2: =HOTEL!AX4 -> 3 | P2: =HOTEL!AZ4 -> 3 | Q2: =HOTEL!BB4 -> 12 | R2: =HOTEL!BD4 -> 5 | S2: =HOTEL!BF4 -> 7 | T2: =HOTEL!BH4 -> 2 | U2: =HOTEL!BJ4 -> 1 | V2: =HOTEL!BL4 -> 5 | W2: =HOTEL!BX4 -> 15 | X2: =HOTEL!CE4 -> 61 | Y2: =HOTEL!CZ4 -> 6 | Z2: =HOTEL!DC3 -> #VALUE! | AA2: =HOTEL!DF4 -> 181 | AB2: =HOTEL!DI4 -> 25 | AC2: =HOTEL!DL4 -> 9 | AD2: =HOTEL!DO4 -> 4 | AE2: =HOTEL!DR4 -> 1 | AF2: =HOTEL!DU4 -> 7 | AG2: =HOTEL!DX4 -> 7 | AH2: =HOTEL!EA4 -> 6 | AI2: =HOTEL!ED4 -> 9 | AJ2: =HOTEL!EG4 -> 0 | AK2: =TOTAL!K2 -> 0.6374
A3: Mauritius at Anahita | B3: =TOTAL!B3 -> 2 | C3: =TOTAL!C3 -> 3 | D3: 2021 | E3: =TOTAL!E3 -> 26805 | F3: =HOTEL!V5 -> 1546 | G3: =HOTEL!X5 -> 415 | H3: =HOTEL!EI5 -> 0 | I3: =HOTEL!EK5 -> 0 | J3: =HOTEL!EM5 -> 0 | K3: =HOTEL!EO5 -> 0 | L3: =N3+W3+X3 -> 74 | M3: =HOTEL!AL5 -> 4 | N3: =HOTEL!AT5 -> 0 | O3: =HOTEL!AX5 -> 2 | P3: =HOTEL!AZ5 -> 2 | Q3: =HOTEL!BB5 -> 12 | R3: =HOTEL!BD5 -> 6 | S3: =HOTEL!BF5 -> 2 | T3: =HOTEL!BH5 -> 3 | U3: =HOTEL!BJ5 -> 1 | V3: =HOTEL!BL5 -> 6 | W3: =HOTEL!BX5 -> 15 | X3: =HOTEL!CE5 -> 59 | Y3: =HOTEL!CZ5 -> 6 | Z3: =HOTEL!DC4 -> 17 | AA3: =HOTEL!DF5 -> 76 | AB3: =HOTEL!DI5 -> 23 | AC3: =HOTEL!DL5 -> 8 | AD3: =HOTEL!DO5 -> 3 | AE3: =HOTEL!DR5 -> 2 | AF3: =HOTEL!DU5 -> 9 | AG3: =HOTEL!DX5 -> 8 | AH3: =HOTEL!EA5 -> 8 | AI3: =HOTEL!ED5 -> 11 | AJ3: =HOTEL!EG5 -> 0 | AK3: =TOTAL!K3 -> 0.5275
A4: Mauritius at Anahita | B4: =TOTAL!B4 -> 3 | C4: =TOTAL!C4 -> 3 | D4: 2021 | E4: =TOTAL!E4 -> 26096 | F4: =HOTEL!V6 -> 1544 | G4: =HOTEL!X6 -> 435 | H4: =HOTEL!EI6 -> 0 | I4: =HOTEL!EK6 -> 0 | J4: =HOTEL!EM6 -> 0 | K4: =HOTEL!EO6 -> 0 | L4: =N4+W4+X4 -> 61 | M4: =HOTEL!AL6 -> 0 | N4: =HOTEL!AT6 -> 0 | O4: =HOTEL!AX6 -> 3 | P4: =HOTEL!AZ6 -> 2 | Q4: =HOTEL!BB6 -> 13 | R4: =HOTEL!BD6 -> 4 | S4: =HOTEL!BF6 -> 2 | T4: =HOTEL!BH6 -> 3 | U4: =HOTEL!BJ6 -> 1 | V4: =HOTEL!BL6 -> 6 | W4: =HOTEL!BX6 -> 7 | X4: =HOTEL!CE6 -> 54 | Y4: =HOTEL!CZ6 -> 0 | Z4: =HOTEL!DC5 -> 17 | AA4: =HOTEL!DF6 -> 66 | AB4: =HOTEL!DI6 -> 19 | AC4: =HOTEL!DL6 -> 9 | AD4: =HOTEL!DO6 -> 3 | AE4: =HOTEL!DR6 -> 2 | AF4: =HOTEL!DU6 -> 10 | AG4: =HOTEL!DX6 -> 10 | AH4: =HOTEL!EA6 -> 8 | AI4: =HOTEL!ED6 -> 11 | AJ4: =HOTEL!EG6 -> 0 | AK4: =TOTAL!K4 -> 0.5165
A5: Mauritius at Anahita | B5: =TOTAL!B5 -> 4 | C5: =TOTAL!C5 -> 3 | D5: 2021 | E5: =TOTAL!E5 -> 26123 | F5: =HOTEL!V7 -> 1372 | G5: =HOTEL!X7 -> 416 | H5: =HOTEL!EI7 -> 0 | I5: =HOTEL!EK7 -> 0 | J5: =HOTEL!EM7 -> 0 | K5: =HOTEL!EO7 -> 0 | L5: =N5+W5+X5 -> 49 | M5: =HOTEL!AL7 -> 3 | N5: =HOTEL!AT7 -> 0 | O5: =HOTEL!AX7 -> 1 | P5: =HOTEL!AZ7 -> 2 | Q5: =HOTEL!BB7 -> 10 | R5: =HOTEL!BD7 -> 5 | S5: =HOTEL!BF7 -> 2 | T5: =HOTEL!BH7 -> 3 | U5: =HOTEL!BJ7 -> 0 | V5: =HOTEL!BL7 -> 5 | W5: =HOTEL!BX7 -> 1 | X5: =HOTEL!CE7 -> 48 | Y5: =HOTEL!CZ7 -> 7 | Z5: =HOTEL!DC6 -> 17 | AA5: =HOTEL!DF7 -> 70 | AB5: =HOTEL!DI7 -> 24 | AC5: =HOTEL!DL7 -> 9 | AD5: =HOTEL!DO7 -> 4 | AE5: =HOTEL!DR7 -> 0 | AF5: =HOTEL!DU7 -> 7 | AG5: =HOTEL!DX7 -> 7 | AH5: =HOTEL!EA7 -> 9 | AI5: =HOTEL!ED7 -> 13 | AJ5: =HOTEL!EG7 -> 0 | AK5: =TOTAL!K5 -> 0.4725
A6: Mauritius at Anahita | B6: =TOTAL!B6 -> 5 | C6: =TOTAL!C6 -> 3 | D6: 2021 | E6: =TOTAL!E6 -> 26469 | F6: =HOTEL!V8 -> 1117 | G6: =HOTEL!X8 -> 453 | H6: =HOTEL!EI8 -> 0 | I6: =HOTEL!EK8 -> 0 | J6: =HOTEL!EM8 -> 0 | K6: =HOTEL!EO8 -> 0 | L6: =N6+W6+X6 -> 55 | M6: =HOTEL!AL8 -> 1 | N6: =HOTEL!AT8 -> 1 | O6: =HOTEL!AX8 -> 0 | P6: =HOTEL!AZ8 -> 3 | Q6: =HOTEL!BB8 -> 12 | R6: =HOTEL!BD8 -> 4 | S6: =HOTEL!BF8 -> 2 | T6: =HOTEL!BH8 -> 2 | U6: =HOTEL!BJ8 -> 1 | V6: =HOTEL!BL8 -> 3 | W6: =HOTEL!BX8 -> 3 | X6: =HOTEL!CE8 -> 51 | Y6: =HOTEL!CZ8 -> 4 | Z6: =HOTEL!DC7 -> 17 | AA6: =HOTEL!DF8 -> 68 | AB6: =HOTEL!DI8 -> 21 | AC6: =HOTEL!DL8 -> 8 | AD6: =HOTEL!DO8 -> 3 | AE6: =HOTEL!DR8 -> 2 | AF6: =HOTEL!DU8 -> 8 | AG6: =HOTEL!DX8 -> 7 | AH6: =HOTEL!EA8 -> 8 | AI6: =HOTEL!ED8 -> 10 | AJ6: =HOTEL!EG8 -> 0 | AK6: =TOTAL!K6 -> 0.4835
A7: Mauritius at Anahita | B7: =TOTAL!B7 -> 6 | C7: =TOTAL!C7 -> 3 | D7: 2021 | E7: =TOTAL!E7 -> 23858 | F7: =HOTEL!V9 -> 1028 | G7: =HOTEL!X9 -> 409 | H7: =HOTEL!EI9 -> 0 | I7: =HOTEL!EK9 -> 0 | J7: =HOTEL!EM9 -> 0 | K7: =HOTEL!EO9 -> 0 | L7: =N7+W7+X7 -> 57 | M7: =HOTEL!AL9 -> 1 | N7: =HOTEL!AT9 -> 0 | O7: =HOTEL!AX9 -> 1 | P7: =HOTEL!AZ9 -> 3 | Q7: =HOTEL!BB9 -> 13 | R7: =HOTEL!BD9 -> 5 | S7: =HOTEL!BF9 -> 2 | T7: =HOTEL!BH9 -> 3 | U7: =HOTEL!BJ9 -> 0 | V7: =HOTEL!BL9 -> 4 | W7: =HOTEL!BX9 -> 2 | X7: =HOTEL!CE9 -> 55 | Y7: =HOTEL!CZ9 -> 7 | Z7: =HOTEL!DC8 -> 17 | AA7: =HOTEL!DF9 -> 63 | AB7: =HOTEL!DI9 -> 24 | AC7: =HOTEL!DL9 -> 10 | AD7: =HOTEL!DO9 -> 4 | AE7: =HOTEL!DR9 -> 1 | AF7: =HOTEL!DU9 -> 10 | AG7: =HOTEL!DX9 -> 10 | AH7: =HOTEL!EA9 -> 10 | AI7: =HOTEL!ED9 -> 13 | AJ7: =HOTEL!EG9 -> 0 | AK7: =TOTAL!K7 -> 0.4286
A8: Mauritius at Anahita | B8: =TOTAL!B8 -> 7 | C8: =TOTAL!C8 -> 3 | D8: 2021 | E8: =TOTAL!E8 -> 25036 | F8: =HOTEL!V10 -> 688 | G8: =HOTEL!X10 -> 411 | H8: =HOTEL!EI10 -> 0 | I8: =HOTEL!EK10 -> 0 | J8: =HOTEL!EM10 -> 0 | K8: =HOTEL!EO10 -> 0 | L8: =N8+W8+X8 -> 54 | M8: =HOTEL!AL10 -> 9 | N8: =HOTEL!AT10 -> 1 | O8: =HOTEL!AX10 -> 1 | P8: =HOTEL!AZ10 -> 1 | Q8: =HOTEL!BB10 -> 14 | R8: =HOTEL!BD10 -> 4 | S8: =HOTEL!BF10 -> 1 | T8: =HOTEL!BH10 -> 2 | U8: =HOTEL!BJ10 -> 1 | V8: =HOTEL!BL10 -> 4 | W8: =HOTEL!BX10 -> 5 | X8: =HOTEL!CE10 -> 48 | Y8: =HOTEL!CZ10 -> 5 | Z8: =HOTEL!DC9 -> 19 | AA8: =HOTEL!DF10 -> 74 | AB8: =HOTEL!DI10 -> 21 | AC8: =HOTEL!DL10 -> 8 | AD8: =HOTEL!DO10 -> 3 | AE8: =HOTEL!DR10 -> 2 | AF8: =HOTEL!DU10 -> 8 | AG8: =HOTEL!DX10 -> 7 | AH8: =HOTEL!EA10 -> 8 | AI8: =HOTEL!ED10 -> 11 | AJ8: =HOTEL!EG10 -> 0 | AK8: =TOTAL!K8 -> 0.4835
A9: Mauritius at Anahita | B9: =TOTAL!B9 -> 8 | C9: =TOTAL!C9 -> 3 | D9: 2021 | E9: =TOTAL!E9 -> 22122 | F9: =HOTEL!V11 -> 680 | G9: =HOTEL!X11 -> 388 | H9: =HOTEL!EI11 -> 0 | I9: =HOTEL!EK11 -> 0 | J9: =HOTEL!EM11 -> 0 | K9: =HOTEL!EO11 -> 0 | L9: =N9+W9+X9 -> 47 | M9: =HOTEL!AL11 -> 0 | N9: =HOTEL!AT11 -> 1 | O9: =HOTEL!AX11 -> 1 | P9: =HOTEL!AZ11 -> 1 | Q9: =HOTEL!BB11 -> 12 | R9: =HOTEL!BD11 -> 5 | S9: =HOTEL!BF11 -> 2 | T9: =HOTEL!BH11 -> 2 | U9: =HOTEL!BJ11 -> 0 | V9: =HOTEL!BL11 -> 5 | W9: =HOTEL!BX11 -> 0 | X9: =HOTEL!CE11 -> 46 | Y9: =HOTEL!CZ11 -> 0 | Z9: =HOTEL!DC10 -> 18 | AA9: =HOTEL!DF11 -> 59 | AB9: =HOTEL!DI11 -> 22 | AC9: =HOTEL!DL11 -> 11 | AD9: =HOTEL!DO11 -> 7 | AE9: =HOTEL!DR11 -> 1 | AF9: =HOTEL!DU11 -> 9 | AG9: =HOTEL!DX11 -> 10 | AH9: =HOTEL!EA11 -> 9 | AI9: =HOTEL!ED11 -> 11 | AJ9: =HOTEL!EG11 -> 0 | AK9: =TOTAL!K9 -> 0.4615
A10: Mauritius at Anahita | B10: =TOTAL!B10 -> 9 | C10: =TOTAL!C10 -> 3 | D10: 2021 | E10: =TOTAL!E10 -> 23254 | F10: =HOTEL!V12 -> 2081 | G10: =HOTEL!X12 -> 427 | H10: =HOTEL!EI12 -> 0 | I10: =HOTEL!EK12 -> 0 | J10: =HOTEL!EM12 -> 0 | K10: =HOTEL!EO12 -> 0 | L10: =N10+W10+X10 -> 44 | M10: =HOTEL!AL12 -> 0 | N10: =HOTEL!AT12 -> 0 | O10: =HOTEL!AX12 -> 1 | P10: =HOTEL!AZ12 -> 0 | Q10: =HOTEL!BB12 -> 12 | R10: =HOTEL!BD12 -> 5 | S10: =HOTEL!BF12 -> 1 | T10: =HOTEL!BH12 -> 2 | U10: =HOTEL!BJ12 -> 1 | V10: =HOTEL!BL12 -> 5 | W10: =HOTEL!BX12 -> 0 | X10: =HOTEL!CE12 -> 44 | Y10: =HOTEL!CZ12 -> 6 | Z10: =HOTEL!DC11 -> 8 | AA10: =HOTEL!DF12 -> 16 | AB10: =HOTEL!DI12 -> 20 | AC10: =HOTEL!DL12 -> 12 | AD10: =HOTEL!DO12 -> 10 | AE10: =HOTEL!DR12 -> 1 | AF10: =HOTEL!DU12 -> 8 | AG10: =HOTEL!DX12 -> 7 | AH10: =HOTEL!EA12 -> 9 | AI10: =HOTEL!ED12 -> 12 | AJ10: =HOTEL!EG12 -> 0 | AK10: =TOTAL!K10 -> 0.5495
A11: Mauritius at Anahita | B11: =TOTAL!B11 -> 10 | C11: =TOTAL!C11 -> 3 | D11: 2021 | E11: =TOTAL!E11 -> 24237 | F11: =HOTEL!V13 -> 1440 | G11: =HOTEL!X13 -> 428 | H11: =HOTEL!EI13 -> 0 | I11: =HOTEL!EK13 -> 0 | J11: =HOTEL!EM13 -> 0 | K11: =HOTEL!EO13 -> 0 | L11: =N11+W11+X11 -> 81 | M11: =HOTEL!AL13 -> 4 | N11: =HOTEL!AT13 -> 1 | O11: =HOTEL!AX13 -> 0 | P11: =HOTEL!AZ13 -> 1 | Q11: =HOTEL!BB13 -> 14 | R11: =HOTEL!BD13 -> 5 | S11: =HOTEL!BF13 -> 2 | T11: =HOTEL!BH13 -> 1 | U11: =HOTEL!BJ13 -> 34 | V11: =HOTEL!BL13 -> 5 | W11: =HOTEL!BX13 -> 0 | X11: =HOTEL!CE13 -> 80 | Y11: =HOTEL!CZ13 -> 5 | Z11: =HOTEL!DC12 -> 12.56 | AA11: =HOTEL!DF13 -> 141 | AB11: =HOTEL!DI13 -> 21 | AC11: =HOTEL!DL13 -> 8 | AD11: =HOTEL!DO13 -> 7 | AE11: =HOTEL!DR13 -> 2 | AF11: =HOTEL!DU13 -> 10 | AG11: =HOTEL!DX13 -> 9 | AH11: =HOTEL!EA13 -> 8 | AI11: =HOTEL!ED13 -> 22 | AJ11: =HOTEL!EG13 -> 0 | AK11: =TOTAL!K11 -> 0.5055
A12: Mauritius at Anahita | B12: =TOTAL!B12 -> 11 | C12: =TOTAL!C12 -> 3 | D12: 2021 | E12: =TOTAL!E12 -> 24488 | F12: =HOTEL!V14 -> 2504 | G12: =HOTEL!X14 -> 374 | H12: =HOTEL!EI14 -> 0 | I12: =HOTEL!EK14 -> 0 | J12: =HOTEL!EM14 -> 0 | K12: =HOTEL!EO14 -> 0 | L12: =N12+W12+X12 -> 87 | M12: =HOTEL!AL14 -> 2 | N12: =HOTEL!AT14 -> 1 | O12: =HOTEL!AX14 -> 1 | P12: =HOTEL!AZ14 -> 0 | Q12: =HOTEL!BB14 -> 12 | R12: =HOTEL!BD14 -> 5 | S12: =HOTEL!BF14 -> 1 | T12: =HOTEL!BH14 -> 2 | U12: =HOTEL!BJ14 -> 37 | V12: =HOTEL!BL14 -> 6 | W12: =HOTEL!BX14 -> 2 | X12: =HOTEL!CE14 -> 84 | Y12: =HOTEL!CZ14 -> 0 | Z12: =HOTEL!DC13 -> 18.44 | AA12: =HOTEL!DF14 -> 50 | AB12: =HOTEL!DI14 -> 23 | AC12: =HOTEL!DL14 -> 10 | AD12: =HOTEL!DO14 -> 9 | AE12: =HOTEL!DR14 -> 2 | AF12: =HOTEL!DU14 -> 8 | AG12: =HOTEL!DX14 -> 6 | AH12: =HOTEL!EA14 -> 8 | AI12: =HOTEL!ED14 -> 25 | AJ12: =HOTEL!EG14 -> 0 | AK12: =TOTAL!K12 -> 0.4286
A13: Mauritius at Anahita | B13: =TOTAL!B13 -> 12 | C13: =TOTAL!C13 -> 3 | D13: 2021 | E13: =TOTAL!E13 -> 25144 | F13: =HOTEL!V15 -> 1978 | G13: =HOTEL!X15 -> 428 | H13: =HOTEL!EI15 -> 0 | I13: =HOTEL!EK15 -> 0 | J13: =HOTEL!EM15 -> 0 | K13: =HOTEL!EO15 -> 0 | L13: =N13+W13+X13 -> 44 | M13: =HOTEL!AL15 -> 0 | N13: =HOTEL!AT15 -> 1 | O13: =HOTEL!AX15 -> 1 | P13: =HOTEL!AZ15 -> 0 | Q13: =HOTEL!BB15 -> 12 | R13: =HOTEL!BD15 -> 4 | S13: =HOTEL!BF15 -> 3 | T13: =HOTEL!BH15 -> 2 | U13: =HOTEL!BJ15 -> 1 | V13: =HOTEL!BL15 -> 4 | W13: =HOTEL!BX15 -> 0 | X13: =HOTEL!CE15 -> 43 | Y13: =HOTEL!CZ15 -> 6 | Z13: =HOTEL!DC14 -> 19 | AA13: =HOTEL!DF15 -> 71 | AB13: =HOTEL!DI15 -> 21 | AC13: =HOTEL!DL15 -> 10 | AD13: =HOTEL!DO15 -> 8 | AE13: =HOTEL!DR15 -> 1 | AF13: =HOTEL!DU15 -> 9 | AG13: =HOTEL!DX15 -> 9 | AH13: =HOTEL!EA15 -> 9 | AI13: =HOTEL!ED15 -> 11 | AJ13: =HOTEL!EG15 -> 0 | AK13: =TOTAL!K13 -> 0.4725
... A32: Mauritius at Anahita | B32: =TOTAL!B32 -> 31 | C32: =TOTAL!C32 -> 3 | D32: 2021 | E32: =TOTAL!E32 -> 22834 | F32: =HOTEL!V34 -> 833 | G32: =HOTEL!X34 -> 439 | H32: =HOTEL!EI34 -> 0 | I32: =HOTEL!EK34 -> 0 | J32: =HOTEL!EM34 -> 0 | K32: =HOTEL!EO34 -> 0 | L32: =N32+W32+X32 -> 79 | M32: =HOTEL!AL34 -> 0 | N32: =HOTEL!AT34 -> 3 | O32: =HOTEL!AX34 -> 2 | P32: =HOTEL!AZ34 -> 1 | Q32: =HOTEL!BB34 -> 25 | R32: =HOTEL!BD34 -> 4 | S32: =HOTEL!BF34 -> 2 | T32: =HOTEL!BH34 -> 2 | U32: =HOTEL!BJ34 -> 0 | V32: =HOTEL!BL34 -> 5 | W32: =HOTEL!BX34 -> 33 | X32: =HOTEL!CE34 -> 43 | Y32: =HOTEL!CZ34 -> 6 | Z32: =HOTEL!DC33 -> 12 | AA32: =HOTEL!DF34 -> 80 | AB32: =HOTEL!DI34 -> 26 | AC32: =HOTEL!DL34 -> 10 | AD32: =HOTEL!DO34 -> 9 | AE32: =HOTEL!DR34 -> 2 | AF32: =HOTEL!DU34 -> 8 | AG32: =HOTEL!DX34 -> 14 | AH32: =HOTEL!EA34 -> 8 | AI32: =HOTEL!ED34 -> 12 | AJ32: =HOTEL!EG34 -> 0 | AK32: =TOTAL!K32 -> 0.3516

Sheet HOTEL
B1: Hotel Electricity | I1: Gen 01 | M1: Gen 02 | Q1: MB & Island | R1: CONS | S1: North & South | T1: CONS | U1: Vacoas KW | V1: CONS | W1: Laundry (KWh) | X1: CONS | Y1: Hotel | AB1: % Water Available | AC1: Water reservoir, 400 m3 | AD1: water truck | AI1: Water Softener | AK1: bamboo pool | AM1: CWA (FS) | AN1: CONS | AP1: CONS | AQ1: Island | AS1: Island Sub | AU1: Main Building | AW1: Pantry A | AY1: Pantry B | BA1: Pantry C | BC1: Pantry D | BE1: Pantry E | BG1: Pantry F | BI1: Pantry G | BU1: North | BW1: North Sub | BY1: South | CA1: South Sub | CF1: Diesel | CJ1: Gas | DE1: Steam Boiler( Laundry) | DH1: Main Building ( boiler) | DK1: Pantry A | DN1: Pantry B | DQ1: Pantry C | DT1: Pantry D | DW1: Pantry E | DZ1: Pantry F | EC1: Pantry G | EQ1: Pool Temperature | ET1: BEVERAGE STORE
A2: Date | B2: KVAH | C2: CONS | D2: KWH | E2: CONS | F2: PF | G2: KVA | H2: KVA max | I2: KWH | J2: CONS | K2: Hrs | L2: CONS | M2: KWH | N2: CONS | O2: Hrs | P2: CONS | Q2: KWH | R2: CONS | S2: KWH | T2: CONS | U2: KWH | V2: CONS | W2: KWH | X2: CONS | Y2: CWA23 | Z2: CONS | AE2: Truck Meter | AF2: Cons | AG2: UV reading | AI2: chiller | AJ2: CONS | AL2: CONS | AQ2: island | AR2: cons | AU2: M.Buil | AV2: Cons | AW2: Pantry A | AX2: Cons | AY2: Pantry B | AZ2: Cons | BA2: Pantry C | BB2: cons | BC2: Pantry D | BD2: cons | BE2: Pantry E | BF2: cons | BG2: Pantry F | BH2: cons | BI2: Pantry G | BJ2: Cons | BK2: Main Kitchen | BL2: Cons | BM2: Bamboo C | BN2: Cons | BO2: Bamboo H | BP2: Cons | BQ2: cyclon bridge | BR2: cons | BS2: Island - Hot | BT2: Island Cold | BU2: north | BV2: cons | BY2: south | BZ2: cons | CC2: south | CD2: Total water consump | CE2: Total HW consump | CF2: DIESEL( cm) | CG2: stock | CH2: Del | CI2: CONS | CJ2: Meter | CK2: cons | CL2: Kg | CM2: LPG 1 | CN2: stock | CO2: LPG 2 | CP2: stock | CQ2: LPG 3 | CR2: stock | CS2: total stock | CT2: cons | CU2: del | CV2: Beau champ | CW2: cons(Litres) | CX2: Cons(Kg) | CY2: Acquapazza | CZ2: cons(Litres) | DA2: Cons(Kg) | DB2: Bamboo | DC2: cons(Litres) | DD2: Cons(Kg) | DF2: cons(Litres) | DG2: Cons(Kg) | DI2: cons(Litres) | DJ2: Cons(Kg) | DL2: cons(Litres) | DM2: Cons(Kg) | DO2: cons(Litres) | DP2: Cons(Kg) | DR2: cons(Litres) | DS2: Cons(Kg) | DU2: cons(Litres) | DV2: Cons(Kg) | DX2: cons(Litres) | DY2: Cons(Kg) | EA2: cons(Litres) | EB2: Cons(Kg) | ED2: cons(Litres) | EE2: Cons(Kg) | EF2: 145 | EG2: CONS | EH2: 146 | EI2: CONS | EJ2: Villa 111 | EK2: CONS | EL2: Villa 128 | EM2: CONS | EN2: Room Nights | EO2: Bed Nights | EP2: % OCC | EQ2: California | ER2: Infiniti | ES2: Fitness | ET2: 0.75 | EU2: 0 | EV2: 0.25
A3: 44620 | B3: 1325697 | C3: #VALUE! | D3: 385494 | E3: #VALUE! | F3: #VALUE! | G3: 1290 | H3: 1364 | I3: 291720 | J3: #VALUE! | K3: 801 | L3: 0 | M3: 644665 | N3: 0 | O3: 1032 | P3: #VALUE! | Q3: 1796900 | R3: #VALUE! | S3: 1817800 | T3: #VALUE! | U3: 2778583 | V3: #VALUE! | W3: 2263002 | X3: #VALUE! | Y3: 278199 | Z3: #VALUE! | AB3: 0.83333333 | AC3: 333.33333 | AE3: 175586 | AF3: #VALUE! | AG3: 481040 | AH3: #VALUE! | AI3: 1179 | AJ3: #VALUE! | AK3: 5444 | AL3: 5444 | AN3: 0 | AP3: 0 | AQ3: 615570 | AR3: #VALUE! | AS3: 1560 | AT3: 1560 | AU3: 55781 | AV3: #VALUE! | AW3: 9217 | AX3: #VALUE! | AY3: 10917 | AZ3: #VALUE! | BA3: 17827 | BB3: #VALUE! | BC3: 20253 | BD3: #VALUE! | BE3: 20990 | BF3: #VALUE! | BG3: 14279 | BH3: #VALUE! | BI3: 6519 | BJ3: #VALUE! | BK3: 27423 | BL3: #VALUE! | BM3: 5125 | BN3: #VALUE! | BO3: 23176 | BP3: #VALUE! | BQ3: 3636 | BR3: #VALUE! | BS3: #VALUE! | BT3: #VALUE! | BU3: 632180 | BW3: 3774 | BY3: 829370 | BZ3: #VALUE! | CB3: 0 | CC3: #VALUE! | CD3: #VALUE! | CE3: #VALUE! | CF3: 155 | CG3: 20161.857 | CI3: #VALUE! | CJ3: 234986 | CK3: #VALUE! | CL3: #VALUE! | CM3: 76 | CN3: 8189 | CO3: 80 | CP3: 8620 | CQ3: 80 | CR3: 8620 | CS3: 25429 | CT3: #VALUE! | CV3: 41036 | CW3: #VALUE! | CX3: #VALUE! | CY3: 35211 | CZ3: #VALUE! | DA3: #VALUE! | DB3: 12943 | DC3: #VALUE! | DD3: #VALUE! | DE3: 842322 | DF3: 842322 | DG3: 4809658.6 | DH3: 8355 | DI3: 8355 | DJ3: 47707.05 | DK3: 8965 | DL3: 8965 | DM3: 51190.15 | DN3: 5354 | DO3: 5354 | DP3: 30571.34 | DQ3: 2088 | DR3: 2088 | DS3: 11922.48 | DT3: 6354 | DU3: 6354 | DV3: 36281.34 | DW3: 5851 | DX3: 5851 | DY3: 33409.21 | DZ3: 6596 | EA3: 6596 | EB3: 37663.16 | EC3: 6480 | ED3: 6480 | EE3: 37000.8 | EG3: -145 | EI3: -146 | EK3: #VALUE! | EM3: #VALUE! | EP3: 0.6154
A4: 44621 | B4: 1351582 | C4: 25885 | D4: 410169 | E4: 24675 | F4: 0.95325478 | G4: 1282 | H4: 1364 | I4: 291720 | J4: 0 | K4: 801 | L4: 0 | M4: 644665 | N4: 0 | O4: 1032 | P4: 0 | Q4: 1807500 | R4: 10600 | S4: 1829500 | T4: 11700 | U4: 2779456 | V4: 873 | W4: 2263419 | X4: 417 | Y4: 278469 | Z4: 270 | AB4: 0.88888889 | AC4: 355.55556 | AE4: 175749 | AF4: 163 | AG4: 481360 | AH4: 320 | AI4: 1179 | AJ4: 0 | AK4: 5444 | AL4: 0 | AN4: 0 | AP4: 0 | AQ4: 615740 | AR4: 170 | AS4: 1561 | AT4: 1 | AU4: 55804 | AV4: 23 | AW4: 9220 | AX4: 3 | AY4: 10920 | AZ4: 3 | BA4: 17839 | BB4: 12 | BC4: 20258 | BD4: 5 | BE4: 20997 | BF4: 7 | BG4: 14281 | BH4: 2 | BI4: 6520 | BJ4: 1 | BK4: 27428 | BL4: 5 | BM4: 5130 | BN4: 5 | BO4: 23226 | BP4: 50 | BQ4: 3636 | BR4: 0 | BS4: 21 | BT4: 149 | BU4: 632350 | BV4: 170 | BW4: 3789 | BX4: 15 | BY4: 829620 | BZ4: 250 | CA4: 18135 | CB4: 18135 | CC4: 80 | CD4: 420 | CE4: 61 | CF4: 155 | CG4: 20161.857 | CI4: 0 | CJ4: 235179 | CK4: 193 | CL4: 1102.03 | CM4: 72 | CN4: 7758 | CO4: 76 | CP4: 8189 | CQ4: 75 | CR4: 8081.25 | CS4: 24028.25 | CT4: 1400.75 | CV4: 41073 | CW4: 37 | CX4: 211.27 | CY4: 35217 | CZ4: 6 | DA4: 34.26 | DB4: 12960 | DC4: 17 | DD4: 97.07 | DE4: 842503 | DF4: 181 | DG4: 1033.51 | DH4: 8380 | DI4: 25 | DJ4: 142.75 | DK4: 8974 | DL4: 9 | DM4: 51.39 | DN4: 5358 | DO4: 4 | DP4: 22.84 | DQ4: 2089 | DR4: 1 | DS4: 5.71 | DT4: 6361 | DU4: 7 | DV4: 39.97 | DW4: 5858 | DX4: 7 | DY4: 39.97 | DZ4: 6602 | EA4: 6 | EB4: 34.26 | EC4: 6489 | ED4: 9 | EE4: 51.39 | EG4: 0 | EI4: 0 | EK4: 0 | EM4: 0 | EP4: 0.6374
A5: 44622 | B5: 1379747 | C5: 28165 | D5: 436974 | E5: 26805 | F5: 0.95171312 | G5: 1310 | H5: 1364 | I5: 291720 | J5: 0 | K5: 801 | L5: 0 | M5: 644665 | N5: 0 | O5: 1032 | P5: 0 | Q5: 1818800 | R5: 11300 | S5: 1842500 | T5: 13000 | U5: 2781002 | V5: 1546 | W5: 2263834 | X5: 415 | Y5: 278917 | Z5: 448 | AB5: 1 | AC5: 400 | AE5: 175749 | AF5: 0 | AG5: 481820 | AH5: 460 | AI5: 1179 | AJ5: 0 | AK5: 5448 | AL5: 4 | AN5: 0 | AP5: 0 | AQ5: 615910 | AR5: 170 | AS5: 1561 | AT5: 0 | AU5: 55830 | AV5: 26 | AW5: 9222 | AX5: 2 | AY5: 10922 | AZ5: 2 | BA5: 17851 | BB5: 12 | BC5: 20264 | BD5: 6 | BE5: 20999 | BF5: 2 | BG5: 14284 | BH5: 3 | BI5: 6521 | BJ5: 1 | BK5: 27434 | BL5: 6 | BM5: 5135 | BN5: 5 | BO5: 23294 | BP5: 68 | BQ5: 3641 | BR5: 5 | BS5: 17 | BT5: 153 | BU5: 632530 | BV5: 180 | BW5: 3804 | BX5: 15 | BY5: 829940 | BZ5: 320 | CA5: 18210 | CB5: 75 | CC5: 150 | CD5: 500 | CE5: 59 | CF5: 155 | CG5: 20161.857 | CI5: 0 | CJ5: 235363 | CK5: 184 | CL5: 1050.64 | CM5: 70 | CN5: 7542.5 | CO5: 73 | CP5: 7865.75 | CQ5: 71 | CR5: 7650.25 | CS5: 23058.5 | CT5: 969.75 | CU5: 6314 | CV5: 41110 | CW5: 37 | CX5: 211.27 | CY5: 35223 | CZ5: 6 | DA5: 34.26 | DB5: 12977 | DC5: 17 | DD5: 97.07 | DE5: 842579 | DF5: 76 | DG5: 433.96 | DH5: 8403 | DI5: 23 | DJ5: 131.33 | DK5: 8982 | DL5: 8 | DM5: 45.68 | DN5: 5361 | DO5: 3 | DP5: 17.13 | DQ5: 2091 | DR5: 2 | DS5: 11.42 | DT5: 6370 | DU5: 9 | DV5: 51.39 | DW5: 5866 | DX5: 8 | DY5: 45.68 | DZ5: 6610 | EA5: 8 | EB5: 45.68 | EC5: 6500 | ED5: 11 | EE5: 62.81 | EG5: 0 | EI5: 0 | EK5: 0 | EM5: 0 | EP5: 0.5275
A6: 44623 | B6: 1407027 | C6: 27280 | D6: 463070 | E6: 26096 | F6: 0.95659824 | G6: 1318 | H6: 1364 | I6: 291720 | J6: 0 | K6: 801 | L6: 0 | M6: 644665 | N6: 0 | O6: 1032 | P6: 0 | Q6: 1829700 | R6: 10900 | S6: 1855300 | T6: 12800 | U6: 2782546 | V6: 1544 | W6: 2264269 | X6: 435 | Y6: 279365 | Z6: 448 | AB6: 0.77777778 | AC6: 311.11111 | AE6: 175749 | AF6: 0 | AG6: 482180 | AH6: 360 | AI6: 1179 | AJ6: 0 | AK6: 5448 | AL6: 0 | AM6: 13055 | AN6: 13055 | AP6: 0 | AQ6: 616050 | AR6: 140 | AS6: 1561 | AT6: 0 | AU6: 55850 | AV6: 20 | AW6: 9225 | AX6: 3 | AY6: 10924 | AZ6: 2 | BA6: 17864 | BB6: 13 | BC6: 20268 | BD6: 4 | BE6: 21001 | BF6: 2 | BG6: 14287 | BH6: 3 | BI6: 6522 | BJ6: 1 | BK6: 27440 | BL6: 6 | BM6: 5141 | BN6: 6 | BO6: 23375 | BP6: 81 | BQ6: 3641 | BR6: 0 | BS6: 18 | BT6: 122 | BU6: 632670 | BV6: 140 | BW6: 3811 | BX6: 7 | BY6: 830100 | BZ6: 160 | CA6: 18270 | CB6: 60 | CC6: 20 | CD6: 300 | CE6: 54 | CF6: 155 | CG6: 20161.857 | CI6: 0 | CJ6: 235530 | CK6: 167 | CL6: 953.57 | CM6: 86 | CN6: 9266.5 | CO6: 86 | CP6: 9266.5 | CQ6: 86 | CR6: 9266.5 | CS6: 27799.5 | CT6: 1573 | CV6: 41151 | CW6: 41 | CX6: 234.11 | CY6: 35223 | CZ6: 0 | DA6: 0 | DB6: 12994 | DC6: 17 | DD6: 97.07 | DE6: 842645 | DF6: 66 | DG6: 376.86 | DH6: 8422 | DI6: 19 | DJ6: 108.49 | DK6: 8991 | DL6: 9 | DM6: 51.39 | DN6: 5364 | DO6: 3 | DP6: 17.13 | DQ6: 2093 | DR6: 2 | DS6: 11.42 | DT6: 6380 | DU6: 10 | DV6: 57.1 | DW6: 5876 | DX6: 10 | DY6: 57.1 | DZ6: 6618 | EA6: 8 | EB6: 45.68 | EC6: 6511 | ED6: 11 | EE6: 62.81 | EG6: 0 | EI6: 0 | EK6: 0 | EM6: 0 | EP6: 0.5165
A7: 44624 | B7: 1434262 | C7: 27235 | D7: 489193 | E7: 26123 | F7: 0.95917019 | G7: 1318 | H7: 1364 | I7: 291720 | J7: 0 | K7: 801 | L7: 0 | M7: 644665 | N7: 0 | O7: 1032 | P7: 0 | Q7: 1840700 | R7: 11000 | S7: 1868100 | T7: 12800 | U7: 2783918 | V7: 1372 | W7: 2264685 | X7: 416 | Y7: 279417 | Z7: 52 | AB7: 0.94444444 | AC7: 377.77778 | AE7: 175823 | AF7: 74 | AG7: 482530 | AH7: 350 | AI7: 1179 | AJ7: 0 | AK7: 5451 | AL7: 3 | AM7: 13377 | AN7: 322 | AP7: 0 | AQ7: 616190 | AR7: 140 | AS7: 1561 | AT7: 0 | AU7: 55870 | AV7: 20 | AW7: 9226 | AX7: 1 | AY7: 10926 | AZ7: 2 | BA7: 17874 | BB7: 10 | BC7: 20273 | BD7: 5 | BE7: 21003 | BF7: 2 | BG7: 14290 | BH7: 3 | BI7: 6522 | BJ7: 0 | BK7: 27445 | BL7: 5 | BM7: 5146 | BN7: 5 | BO7: 23427 | BP7: 52 | BQ7: 3641 | BR7: 0 | BS7: 15 | BT7: 125 | BU7: 632800 | BV7: 130 | BW7: 3812 | BX7: 1 | BY7: 830310 | BZ7: 210 | CA7: 18325 | CB7: 55 | CC7: 70 | CD7: 340 | CE7: 48 | CF7: 155 | CG7: 20161.857 | CI7: 0 | CJ7: 235711 | CK7: 181 | CL7: 1033.51 | CM7: 83 | CN7: 8943.25 | CO7: 84 | CP7: 9051 | CQ7: 84 | CR7: 9051 | CS7: 27045.25 | CT7: 754.25 | CV7: 41190 | CW7: 39 | CX7: 222.69 | CY7: 35230 | CZ7: 7 | DA7: 39.97 | DB7: 13011 | DC7: 17 | DD7: 97.07 | DE7: 842715 | DF7: 70 | DG7: 399.7 | DH7: 8446 | DI7: 24 | DJ7: 137.04 | DK7: 9000 | DL7: 9 | DM7: 51.39 | DN7: 5368 | DO7: 4 | DP7: 22.84 | DQ7: 2093 | DR7: 0 | DS7: 0 | DT7: 6387 | DU7: 7 | DV7: 39.97 | DW7: 5883 | DX7: 7 | DY7: 39.97 | DZ7: 6627 | EA7: 9 | EB7: 51.39 | EC7: 6524 | ED7: 13 | EE7: 74.23 | EG7: 0 | EI7: 0 | EK7: 0 | EM7: 0 | EP7: 0.4725
A8: 44625 | B8: 1462009 | C8: 27747 | D8: 515662 | E8: 26469 | F8: 0.95394097 | G8: 1318 | H8: 1364 | I8: 291720 | J8: 0 | K8: 801 | L8: 0 | M8: 644665 | N8: 0 | O8: 1032 | P8: 0 | Q8: 1852000 | R8: 11300 | S8: 1880800 | T8: 12700 | U8: 2785035 | V8: 1117 | W8: 2265138 | X8: 453 | Y8: 279692 | Z8: 275 | AB8: 0.83333333 | AC8: 333.33333 | AE8: 175907 | AF8: 84 | AG8: 482870 | AH8: 340 | AI8: 1179 | AJ8: 0 | AK8: 5452 | AL8: 1 | AM8: 13655 | AN8: 278 | AP8: 0 | AQ8: 616330 | AR8: 140 | AS8: 1562 | AT8: 1 | AU8: 55894 | AV8: 24 | AW8: 9226 | AX8: 0 | AY8: 10929 | AZ8: 3 | BA8: 17886 | BB8: 12 | BC8: 20277 | BD8: 4 | BE8: 21005 | BF8: 2 | BG8: 14292 | BH8: 2 | BI8: 6523 | BJ8: 1 | BK8: 27448 | BL8: 3 | BM8: 5149 | BN8: 3 | BO8: 23489 | BP8: 62 | BQ8: 3641 | BR8: 0 | BS8: 16 | BT8: 124 | BU8: 632940 | BV8: 140 | BW8: 3815 | BX8: 3 | BY8: 830510 | BZ8: 200 | CA8: 18378 | CB8: 53 | CC8: 60 | CD8: 340 | CE8: 51 | CF8: 155 | CG8: 20161.857 | CI8: 0 | CJ8: 235901 | CK8: 190 | CL8: 1084.9 | CM8: 79 | CN8: 8512.25 | CO8: 80 | CP8: 8620 | CQ8: 81 | CR8: 8727.75 | CS8: 25860 | CT8: 1185.25 | CV8: 41232 | CW8: 42 | CX8: 239.82 | CY8: 35234 | CZ8: 4 | DA8: 22.84 | DB8: 13028 | DC8: 17 | DD8: 97.07 | DE8: 842783 | DF8: 68 | DG8: 388.28 | DH8: 8467 | DI8: 21 | DJ8: 119.91 | DK8: 9008 | DL8: 8 | DM8: 45.68 | DN8: 5371 | DO8: 3 | DP8: 17.13 | DQ8: 2095 | DR8: 2 | DS8: 11.42 | DT8: 6395 | DU8: 8 | DV8: 45.68 | DW8: 5890 | DX8: 7 | DY8: 39.97 | DZ8: 6635 | EA8: 8 | EB8: 45.68 | EC8: 6534 | ED8: 10 | EE8: 57.1 | EG8: 0 | EI8: 0 | EK8: 0 | EM8: 0 | EP8: 0.4835
A9: 44626 | B9: 1486998 | C9: 24989 | D9: 539520 | E9: 23858 | F9: 0.95474009 | G9: 1318 | H9: 1364 | I9: 291720 | J9: 0 | K9: 801 | L9: 0 | M9: 644665 | N9: 0 | O9: 1032 | P9: 0 | Q9: 1862200 | R9: 10200 | S9: 1892500 | T9: 11700 | U9: 2786063 | V9: 1028 | W9: 2265547 | X9: 409 | Y9: 279998 | Z9: 306 | AB9: 0.80555556 | AC9: 322.22222 | AE9: 175907 | AF9: 0 | AG9: 483260 | AH9: 390 | AI9: 1179 | AJ9: 0 | AK9: 5453 | AL9: 1 | AM9: 13981 | AN9: 326 | AP9: 0 | AQ9: 616480 | AR9: 150 | AS9: 1562 | AT9: 0 | AU9: 55916 | AV9: 22 | AW9: 9227 | AX9: 1 | AY9: 10932 | AZ9: 3 | BA9: 17899 | BB9: 13 | BC9: 20282 | BD9: 5 | BE9: 21007 | BF9: 2 | BG9: 14295 | BH9: 3 | BI9: 6523 | BJ9: 0 | BK9: 27452 | BL9: 4 | BM9: 5155 | BN9: 6 | BO9: 23561 | BP9: 72 | BQ9: 3641 | BR9: 0 | BS9: 18 | BT9: 132 | BU9: 633070 | BV9: 130 | BW9: 3817 | BX9: 2 | BY9: 830750 | BZ9: 240 | CA9: 18445 | CB9: 67 | CC9: 90 | CD9: 370 | CE9: 55 | CF9: 155 | CG9: 20161.857 | CI9: 0 | CJ9: 236067 | CK9: 166 | CL9: 947.86 | CM9: 76 | CN9: 8189 | CO9: 78 | CP9: 8404.5 | CQ9: 79 | CR9: 8512.25 | CS9: 25105.75 | CT9: 754.25 | CV9: 41258 | CW9: 26 | CX9: 148.46 | CY9: 35241 | CZ9: 7 | DA9: 39.97 | DB9: 13047 | DC9: 19 | DD9: 108.49 | DE9: 842846 | DF9: 63 | DG9: 359.73 | DH9: 8491 | DI9: 24 | DJ9: 137.04 | DK9: 9018 | DL9: 10 | DM9: 57.1 | DN9: 5375 | DO9: 4 | DP9: 22.84 | DQ9: 2096 | DR9: 1 | DS9: 5.71 | DT9: 6405 | DU9: 10 | DV9: 57.1 | DW9: 5900 | DX9: 10 | DY9: 57.1 | DZ9: 6645 | EA9: 10 | EB9: 57.1 | EC9: 6547 | ED9: 13 | EE9: 74.23 | EG9: 0 | EI9: 0 | EK9: 0 | EM9: 0 | EP9: 0.4286
A10: 44627 | B10: 1513112 | C10: 26114 | D10: 564556 | E10: 25036 | F10: 0.95871946 | G10: 1318 | H10: 1364 | I10: 291720 | J10: 0 | K10: 801 | L10: 0 | M10: 644665 | N10: 0 | O10: 1032 | P10: 0 | Q10: 1872800 | R10: 10600 | S10: 1904400 | T10: 11900 | U10: 2786751 | V10: 688 | W10: 2265958 | X10: 411 | Y10: 280326 | Z10: 328 | AB10: 0.72222222 | AC10: 288.88889 | AE10: 175907 | AF10: 0 | AG10: 483660 | AH10: 400 | AI10: 1179 | AJ10: 0 | AK10: 5462 | AL10: 9 | AM10: 14352 | AN10: 371 | AP10: 0 | AQ10: 616640 | AR10: 160 | AS10: 1563 | AT10: 1 | AU10: 55936 | AV10: 20 | AW10: 9228 | AX10: 1 | AY10: 10933 | AZ10: 1 | BA10: 17913 | BB10: 14 | BC10: 20286 | BD10: 4 | BE10: 21008 | BF10: 1 | BG10: 14297 | BH10: 2 | BI10: 6524 | BJ10: 1 | BK10: 27456 | BL10: 4 | BM10: 5159 | BN10: 4 | BO10: 23631 | BP10: 70 | BQ10: 3641 | BR10: 0 | BS10: 17 | BT10: 143 | BU10: 633230 | BV10: 160 | BW10: 3822 | BX10: 5 | BY10: 830990 | BZ10: 240 | CA10: 18523 | CB10: 78 | CC10: 80 | CD10: 400 | CE10: 48 | CF10: 155 | CG10: 20161.857 | CI10: 0 | CJ10: 236272 | CK10: 205 | CL10: 1170.55 | CM10: 72 | CN10: 7758 | CO10: 74 | CP10: 7973.5 | CQ10: 72 | CR10: 7758 | CS10: 23489.5 | CT10: 1616.25 | CV10: 41297 | CW10: 39 | CX10: 222.69 | CY10: 35246 | CZ10: 5 | DA10: 28.55 | DB10: 13065 | DC10: 18 | DD10: 102.78 | DE10: 842920 | DF10: 74 | DG10: 422.54 | DH10: 8512 | DI10: 21 | DJ10: 119.91 | DK10: 9026 | DL10: 8 | DM10: 45.68 | DN10: 5378 | DO10: 3 | DP10: 17.13 | DQ10: 2098 | DR10: 2 | DS10: 11.42 | DT10: 6413 | DU10: 8 | DV10: 45.68 | DW10: 5907 | DX10: 7 | DY10: 39.97 | DZ10: 6653 | EA10: 8 | EB10: 45.68 | EC10: 6558 | ED10: 11 | EE10: 62.81 | EG10: 0 | EI10: 0 | EK10: 0 | EM10: 0 | EP10: 0.4835
A11: 44628 | B11: 1536416 | C11: 23304 | D11: 586678 | E11: 22122 | F11: 0.94927909 | G11: 1318 | H11: 1364 | I11: 291720 | J11: 0 | K11: 801 | L11: 0 | M11: 644665 | N11: 0 | O11: 1032 | P11: 0 | Q11: 1882600 | R11: 9800 | S11: 1914600 | T11: 10200 | U11: 2787431 | V11: 680 | W11: 2266346 | X11: 388 | Y11: 280545 | Z11: 219 | AB11: 0.88888889 | AC11: 355.55556 | AE11: 176060 | AF11: 153 | AG11: 484000 | AH11: 340 | AI11: 1179 | AJ11: 0 | AK11: 5462 | AL11: 0 | AM11: 14567 | AN11: 215 | AP11: 0 | AQ11: 616770 | AR11: 130 | AS11: 1564 | AT11: 1 | AU11: 55955 | AV11: 19 | AW11: 9229 | AX11: 1 | AY11: 10934 | AZ11: 1 | BA11: 17925 | BB11: 12 | BC11: 20291 | BD11: 5 | BE11: 21010 | BF11: 2 | BG11: 14299 | BH11: 2 | BI11: 6524 | BJ11: 0 | BK11: 27461 | BL11: 5 | BM11: 5163 | BN11: 4 | BO11: 23703 | BP11: 72 | BQ11: 3641 | BR11: 0 | BS11: 16 | BT11: 114 | BU11: 633350 | BV11: 120 | BW11: 3821 | BX11: 0 | BY11: 831200 | BZ11: 210 | CA11: 18584 | CB11: 61 | CC11: 80 | CD11: 330 | CE11: 46 | CF11: 155 | CG11: 20161.857 | CI11: 0 | CJ11: 236439 | CK11: 167 | CL11: 953.57 | CM11: 69 | CN11: 7434.75 | CO11: 71 | CP11: 7650.25 | CQ11: 69 | CR11: 7434.75 | CS11: 22519.75 | CT11: 969.75 | CV11: 41334 | CW11: 37 | CX11: 211.27 | CY11: 35246 | CZ11: 0 | DA11: 0 | DB11: 13073 | DC11: 8 | DD11: 45.68 | DE11: 842979 | DF11: 59 | DG11: 336.89 | DH11: 8534 | DI11: 22 | DJ11: 125.62 | DK11: 9037 | DL11: 11 | DM11: 62.81 | DN11: 5385 | DO11: 7 | DP11: 39.97 | DQ11: 2099 | DR11: 1 | DS11: 5.71 | DT11: 6422 | DU11: 9 | DV11: 51.39 | DW11: 5917 | DX11: 10 | DY11: 57.1 | DZ11: 6662 | EA11: 9 | EB11: 51.39 | EC11: 6569 | ED11: 11 | EE11: 62.81 | EG11: 0 | EI11: 0 | EK11: 0 | EM11: 0 | EP11: 0.4615
A12: 44629 | B12: 1560726.4 | C12: 24310.4 | D12: 609932 | E12: 23254 | F12: 0.95654535 | G12: 1318 | H12: 1364 | I12: 291720 | J12: 0 | K12: 801 | L12: 0 | M12: 644665 | N12: 0 | O12: 1032 | P12: 0 | Q12: 1892900 | R12: 10300 | S12: 1925500 | T12: 10900 | U12: 2789512 | V12: 2081 | W12: 2266773 | X12: 427 | Y12: 280775 | Z12: 230 | AB12: 0.66666667 | AC12: 266.66667 | AE12: 176132 | AF12: 72 | AG12: 484370 | AH12: 370 | AI12: 1179 | AJ12: 0 | AK12: 5462 | AL12: 0 | AM12: 14782 | AN12: 215 | AP12: 0 | AQ12: 616900 | AR12: 130 | AS12: 1564 | AT12: 0 | AU12: 55973 | AV12: 18 | AW12: 9230 | AX12: 1 | AY12: 10934 | AZ12: 0 | BA12: 17937 | BB12: 12 | BC12: 20296 | BD12: 5 | BE12: 21011 | BF12: 1 | BG12: 14301 | BH12: 2 | BI12: 6525 | BJ12: 1 | BK12: 27466 | BL12: 5 | BM12: 5167 | BN12: 4 | BO12: 23763 | BP12: 60 | BQ12: 3641 | BR12: 0 | BS12: 15 | BT12: 115 | BU12: 633490 | BV12: 140 | BW12: 3821 | BX12: 0 | BY12: 831430 | BZ12: 230 | CA12: 18684 | CB12: 100 | CC12: 100 | CD12: 370 | CE12: 44 | CF12: 155 | CG12: 20161.857 | CI12: 0 | CJ12: 236639.6 | CK12: 200.6 | CL12: 1145.426 | CM12: 65 | CN12: 7003.75 | CO12: 68 | CP12: 7327 | CQ12: 65 | CR12: 7003.75 | CS12: 21334.5 | CT12: 1185.25 | CV12: 41375.7 | CW12: 41.7 | CX12: 238.107 | CY12: 35252 | CZ12: 6 | DA12: 34.26 | DB12: 13085.56 | DC12: 12.56 | DD12: 71.7176 | DE12: 842995 | DF12: 16 | DG12: 91.36 | DH12: 8554 | DI12: 20 | DJ12: 114.2 | DK12: 9049 | DL12: 12 | DM12: 68.52 | DN12: 5395 | DO12: 10 | DP12: 57.1 | DQ12: 2100 | DR12: 1 | DS12: 5.71 | DT12: 6430 | DU12: 8 | DV12: 45.68 | DW12: 5924 | DX12: 7 | DY12: 39.97 | DZ12: 6671 | EA12: 9 | EB12: 51.39 | EC12: 6581 | ED12: 12 | EE12: 68.52 | EG12: 0 | EI12: 0 | EK12: 0 | EM12: 0 | EP12: 0.5495
A13: 44630 | B13: 1586152 | C13: 25425.6 | D13: 634169 | E13: 24237 | F13: 0.95325184 | G13: 1318 | H13: 1364 | I13: 291720 | J13: 0 | K13: 801 | L13: 0 | M13: 644665 | N13: 0 | O13: 1032 | P13: 0 | Q13: 1903400 | R13: 10500 | S13: 1936900 | T13: 11400 | U13: 2790952 | V13: 1440 | W13: 2267201 | X13: 428 | Y13: 280852 | Z13: 77 | AB13: 0.55555556 | AC13: 222.22222 | AE13: 176293 | AF13: 161 | AG13: 484780 | AH13: 410 | AI13: 1179 | AJ13: 0 | AK13: 5466 | AL13: 4 | AM13: 14937 | AN13: 155 | AP13: 0 | AQ13: 617050 | AR13: 150 | AS13: 1565 | AT13: 1 | AU13: 55990 | AV13: 17 | AW13: 9230 | AX13: 0 | AY13: 10935 | AZ13: 1 | BA13: 17951 | BB13: 14 | BC13: 20301 | BD13: 5 | BE13: 21013 | BF13: 2 | BG13: 14302 | BH13: 1 | BI13: 6559 | BJ13: 34 | BK13: 27471 | BL13: 5 | BM13: 5173 | BN13: 6 | BO13: 23834 | BP13: 71 | BQ13: 3641 | BR13: 0 | BS13: 17 | BT13: 133 | BU13: 633630 | BV13: 140 | BW13: 3821 | BX13: 0 | BY13: 831680 | BZ13: 250 | CA13: 18783 | CB13: 99 | CC13: 100 | CD13: 390 | CE13: 80 | CF13: 155 | CG13: 20161.857 | CI13: 0 | CJ13: 236821 | CK13: 181.4 | CL13: 1035.794 | CM13: 61 | CN13: 6572.75 | CO13: 65 | CP13: 7003.75 | CQ13: 61 | CR13: 6572.75 | CS13: 20149.25 | CT13: 1185.25 | CU13: 8457 | CV13: 41403 | CW13: 27.3 | CX13: 155.883 | CY13: 35257 | CZ13: 5 | DA13: 28.55 | DB13: 13104 | DC13: 18.44 | DD13: 105.2924 | DE13: 843136 | DF13: 141 | DG13: 805.11 | DH13: 8575 | DI13: 21 | DJ13: 119.91 | DK13: 9057 | DL13: 8 | DM13: 45.68 | DN13: 5402 | DO13: 7 | DP13: 39.97 | DQ13: 2102 | DR13: 2 | DS13: 11.42 | DT13: 6440 | DU13: 10 | DV13: 57.1 | DW13: 5933 | DX13: 9 | DY13: 51.39 | DZ13: 6679 | EA13: 8 | EB13: 45.68 | EC13: 6603 | ED13: 22 | EE13: 125.62 | EG13: 0 | EI13: 0 | EK13: 0 | EM13: 0 | EP13: 0.5055
A14: 44631 | B14: 1611737 | C14: 25585 | D14: 658657 | E14: 24488 | F14: 0.95712331 | G14: 1318 | H14: 1364 | I14: 291720 | J14: 0 | K14: 801 | L14: 0 | M14: 644665 | N14: 0 | O14: 1032 | P14: 0 | Q14: 1913800 | R14: 10400 | S14: 1948700 | T14: 11800 | U14: 2793456 | V14: 2504 | W14: 2267575 | X14: 374 | Y14: 280958 | Z14: 106 | AB14: 0.5 | AC14: 200 | AE14: 176502 | AF14: 209 | AG14: 485210 | AH14: 430 | AI14: 1179 | AJ14: 0 | AK14: 5468 | AL14: 2 | AM14: 15038 | AN14: 101 | AP14: 0 | AQ14: 617210 | AR14: 160 | AS14: 1566 | AT14: 1 | AU14: 56011 | AV14: 21 | AW14: 9231 | AX14: 1 | AY14: 10935 | AZ14: 0 | BA14: 17963 | BB14: 12 | BC14: 20306 | BD14: 5 | BE14: 21014 | BF14: 1 | BG14: 14304 | BH14: 2 | BI14: 6596 | BJ14: 37 | BK14: 27477 | BL14: 6 | BM14: 5178 | BN14: 5 | BO14: 23897 | BP14: 63 | BQ14: 3641 | BR14: 0 | BS14: 15 | BT14: 145 | BU14: 633790 | BV14: 160 | BW14: 3823 | BX14: 2 | BY14: 831950 | BZ14: 270 | CA14: 18882 | CB14: 99 | CC14: 110 | CD14: 430 | CE14: 84 | CF14: 155 | CG14: 20161.857 | CI14: 0 | CJ14: 236997 | CK14: 176 | CL14: 1004.96 | CM14: 84 | CN14: 9051 | CO14: 86 | CP14: 9266.5 | CQ14: 84 | CR14: 9051 | CS14: 27368.5 | CT14: 1237.75 | CV14: 41441 | CW14: 38 | CX14: 216.98 | CY14: 35257 | CZ14: 0 | DA14: 0 | DB14: 13123 | DC14: 19 | DD14: 108.49 | DE14: 843186 | DF14: 50 | DG14: 285.5 | DH14: 8598 | DI14: 23 | DJ14: 131.33 | DK14: 9067 | DL14: 10 | DM14: 57.1 | DN14: 5411 | DO14: 9 | DP14: 51.39 | DQ14: 2104 | DR14: 2 | DS14: 11.42 | DT14: 6448 | DU14: 8 | DV14: 45.68 | DW14: 5939 | DX14: 6 | DY14: 34.26 | DZ14: 6687 | EA14: 8 | EB14: 45.68 | EC14: 6628 | ED14: 25 | EE14: 142.75 | EG14: 0 | EI14: 0 | EK14: 0 | EM14: 0 | EP14: 0.4286
A15: 44632 | B15: 1637987 | C15: 26250 | D15: 683801 | E15: 25144 | F15: 0.95786667 | G15: 1318 | H15: 1364 | I15: 291720 | J15: 0 | K15: 801 | L15: 0 | M15: 644665 | N15: 0 | O15: 1032 | P15: 0 | Q15: 1924600 | R15: 10800 | S15: 1960700 | T15: 12000 | U15: 2795434 | V15: 1978 | W15: 2268003 | X15: 428 | Y15: 281329 | Z15: 371 | AB15: 0.97222222 | AC15: 388.88889 | AE15: 176909 | AF15: 407 | AG15: 485610 | AH15: 400 | AI15: 1179 | AJ15: 0 | AK15: 5468 | AL15: 0 | AM15: 15439 | AN15: 401 | AP15: 0 | AQ15: 617370 | AR15: 160 | AS15: 1567 | AT15: 1 | AU15: 56028 | AV15: 17 | AW15: 9232 | AX15: 1 | AY15: 10935 | AZ15: 0 | BA15: 17975 | BB15: 12 | BC15: 20310 | BD15: 4 | BE15: 21017 | BF15: 3 | BG15: 14306 | BH15: 2 | BI15: 6597 | BJ15: 1 | BK15: 27481 | BL15: 4 | BM15: 5181 | BN15: 3 | BO15: 23963 | BP15: 66 | BQ15: 3641 | BR15: 0 | BS15: 17 | BT15: 143 | BU15: 633940 | BV15: 150 | BW15: 3823 | BX15: 0 | BY15: 832200 | BZ15: 250 | CA15: 18960 | CB15: 78 | CC15: 90 | CD15: 400 | CE15: 43 | CF15: 155 | CG15: 20161.857 | CI15: 0 | CJ15: 237179 | CK15: 182 | CL15: 1039.22 | CM15: 81 | CN15: 8727.75 | CO15: 84 | CP15: 9051 | CQ15: 81 | CR15: 8727.75 | CS15: 26506.5 | CT15: 862 | CV15: 41481 | CW15: 40 | CX15: 228.4 | CY15: 35263 | CZ15: 6 | DA15: 34.26 | DB15: 13132 | DC15: 9 | DD15: 51.39 | DE15: 843257 | DF15: 71 | DG15: 405.41 | DH15: 8619 | DI15: 21 | DJ15: 119.91 | DK15: 9077 | DL15: 10 | DM15: 57.1 | DN15: 5419 | DO15: 8 | DP15: 45.68 | DQ15: 2105 | DR15: 1 | DS15: 5.71 | DT15: 6457 | DU15: 9 | DV15: 51.39 | DW15: 5948 | DX15: 9 | DY15: 51.39 | DZ15: 6696 | EA15: 9 | EB15: 51.39 | EC15: 6639 | ED15: 11 | EE15: 62.81 | EG15: 0 | EI15: 0 | EK15: 0 | EM15: 0 | EP15: 0.4725
A16: 44633 | B16: 1662736 | C16: 24749 | D16: 707270 | E16: 23469 | F16: 0.94828074 | G16: 1318 | H16: 1364 | I16: 291720 | J16: 0 | K16: 801 | L16: 0 | M16: 644665 | N16: 0 | O16: 1032 | P16: 0 | Q16: 1934800 | R16: 10200 | S16: 1971800 | T16: 11100 | U16: 2797162 | V16: 1728 | W16: 2268435 | X16: 432 | Y16: 281488 | Z16: 159 | AB16: 0.77777778 | AC16: 311.11111 | AE16: 176973 | AF16: 64 | AG16: 485980 | AH16: 370 | AI16: 1179 | AJ16: 0 | AK16: 5477 | AL16: 9 | AM16: 15621 | AN16: 182 | AP16: 0 | AQ16: 617520 | AR16: 150 | AS16: 1568 | AT16: 1 | AU16: 56045 | AV16: 17 | AW16: 9233 | AX16: 1 | AY16: 10936 | AZ16: 1 | BA16: 17988 | BB16: 13 | BC16: 20313 | BD16: 3 | BE16: 21018 | BF16: 1 | BG16: 14308 | BH16: 2 | BI16: 6597 | BJ16: 0 | BK16: 27486 | BL16: 5 | BM16: 5185 | BN16: 4 | BO16: 24028 | BP16: 65 | BQ16: 3641 | BR16: 0 | BS16: 16 | BT16: 134 | BU16: 634070 | BV16: 130 | BW16: 3823 | BX16: 0 | BY16: 832430 | BZ16: 230 | CA16: 19037 | CB16: 77 | CC16: 80 | CD16: 360 | CE16: 42 | CF16: 155 | CG16: 20161.857 | CI16: 0 | CJ16: 237365 | CK16: 186 | CL16: 1062.06 | CM16: 79 | CN16: 8512.25 | CO16: 80 | CP16: 8620 | CQ16: 80 | CR16: 8620 | CS16: 25752.25 | CT16: 754.25 | CV16: 41510 | CW16: 29 | CX16: 165.59 | CY16: 35268 | CZ16: 5 | DA16: 28.55 | DB16: 13148 | DC16: 16 | DD16: 91.36 | DE16: 843329 | DF16: 72 | DG16: 411.12 | DH16: 8640 | DI16: 21 | DJ16: 119.91 | DK16: 9086 | DL16: 9 | DM16: 51.39 | DN16: 5427 | DO16: 8 | DP16: 45.68 | DQ16: 2106 | DR16: 1 | DS16: 5.71 | DT16: 6465 | DU16: 8 | DV16: 45.68 | DW16: 5956 | DX16: 8 | DY16: 45.68 | DZ16: 6704 | EA16: 8 | EB16: 45.68 | EC16: 6650 | ED16: 11 | EE16: 62.81 | EG16: 0 | EI16: 0 | EK16: 0 | EM16: 0 | EP16: 0.5055
A17: 44634 | B17: 1688910 | C17: 26174 | D17: 732332 | E17: 25062 | F17: 0.95751509 | G17: 1318 | H17: 1364 | I17: 291720 | J17: 0 | K17: 801 | L17: 0 | M17: 644665 | N17: 0 | O17: 1032 | P17: 0 | Q17: 1945000 | R17: 10200 | S17: 1982900 | T17: 11100 | U17: 2798907 | V17: 1745 | W17: 2268856 | X17: 421 | Y17: 281688 | Z17: 200 | AB17: 0.61111111 | AC17: 244.44444 | AE17: 177186 | AF17: 213 | AG17: 486440 | AH17: 460 | AI17: 1179 | AJ17: 0 | AK17: 5486 | AL17: 9 | AM17: 15786 | AN17: 165 | AP17: 0 | AQ17: 617700 | AR17: 180 | AS17: 1569 | AT17: 1 | AU17: 56046 | AV17: 1 | AW17: 9234 | AX17: 1 | AY17: 10936 | AZ17: 0 | BA17: 18000 | BB17: 12 | BC17: 20318 | BD17: 5 | BE17: 21020 | BF17: 2 | BG17: 14309 | BH17: 1 | BI17: 6597 | BJ17: 0 | BK17: 27492 | BL17: 6 | BM17: 5189 | BN17: 4 | BO17: 24089 | BP17: 61 | BQ17: 3641 | BR17: 0 | BS17: 15 | BT17: 165 | BU17: 634250 | BV17: 180 | BW17: 3844 | BX17: 21 | BY17: 832710 | BZ17: 280 | CA17: 19103 | CB17: 66 | CC17: 100 | CD17: 460 | CE17: 26 | CF17: 155 | CG17: 20161.857 | CI17: 0 | CJ17: 237574 | CK17: 209 | CL17: 1193.39 | CM17: 75 | CN17: 8081.25 | CO17: 75 | CP17: 8081.25 | CQ17: 75 | CR17: 8081.25 | CS17: 24243.75 | CT17: 1508.5 | CV17: 41553 | CW17: 43 | CX17: 245.53 | CY17: 35273 | CZ17: 5 | DA17: 28.55 | DB17: 13158 | DC17: 10 | DD17: 57.1 | DE17: 843409 | DF17: 80 | DG17: 456.8 | DH17: 8661 | DI17: 21 | DJ17: 119.91 | DK17: 9096 | DL17: 10 | DM17: 57.1 | DN17: 5435 | DO17: 8 | DP17: 45.68 | DQ17: 2108 | DR17: 2 | DS17: 11.42 | DT17: 6474 | DU17: 9 | DV17: 51.39 | DW17: 5962 | DX17: 6 | DY17: 34.26 | DZ17: 6712 | EA17: 8 | EB17: 45.68 | EC17: 6660 | ED17: 10 | EE17: 57.1 | EG17: 0 | EI17: 0 | EK17: 0 | EM17: 0 | EP17: 0.5055
A18: 44635 | B18: 1714784 | C18: 25874 | D18: 756960 | E18: 24628 | F18: 0.95184355 | G18: 1318 | H18: 1364 | I18: 291720 | J18: 0 | K18: 801 | L18: 0 | M18: 644665 | N18: 0 | O18: 1032 | P18: 0 | Q18: 1955800 | R18: 10800 | S18: 1995800 | T18: 12900 | U18: 2801026 | V18: 2119 | W18: 2269283 | X18: 427 | Y18: 281797 | Z18: 109 | AB18: 0.72222222 | AC18: 288.88889 | AE18: 177454 | AF18: 268 | AG18: 486890 | AH18: 450 | AI18: 1179 | AJ18: 0 | AK18: 5486 | AL18: 0 | AM18: 15936 | AN18: 150 | AP18: 0 | AQ18: 617860 | AR18: 160 | AS18: 1569 | AT18: 0 | AU18: 56066 | AV18: 20 | AW18: 9235 | AX18: 1 | AY18: 10936 | AZ18: 0 | BA18: 18015 | BB18: 15 | BC18: 20322 | BD18: 4 | BE18: 21022 | BF18: 2 | BG18: 14310 | BH18: 1 | BI18: 6598 | BJ18: 1 | BK18: 27497 | BL18: 5 | BM18: 5194 | BN18: 5 | BO18: 24156 | BP18: 67 | BQ18: 3641 | BR18: 0 | BS18: 18 | BT18: 142 | BU18: 634460 | BV18: 210 | BW18: 3870 | BX18: 26 | BY18: 832920 | BZ18: 210 | CA18: 19168 | CB18: 65 | CC18: 50 | CD18: 420 | CE18: 49 | CF18: 155 | CG18: 20161.857 | CI18: 0 | CJ18: 237732 | CK18: 158 | CL18: 902.18 | CM18: 71 | CN18: 7650.25 | CO18: 73 | CP18: 7865.75 | CQ18: 74 | CR18: 7973.5 | CS18: 23489.5 | CT18: 754.25 | CV18: 41588 | CW18: 35 | CX18: 199.85 | CY18: 35279 | CZ18: 6 | DA18: 34.26 | DB18: 13178 | DC18: 20 | DD18: 114.2 | DE18: 843470 | DF18: 61 | DG18: 348.31 | DH18: 8683 | DI18: 22 | DJ18: 125.62 | DK18: 9106 | DL18: 10 | DM18: 57.1 | DN18: 5443 | DO18: 8 | DP18: 45.68 | DQ18: 2109 | DR18: 1 | DS18: 5.71 | DT18: 6483 | DU18: 9 | DV18: 51.39 | DW18: 5971 | DX18: 9 | DY18: 51.39 | DZ18: 6720 | EA18: 8 | EB18: 45.68 | EC18: 6671 | ED18: 11 | EE18: 62.81 | EG18: 0 | EI18: 0 | EK18: 0 | EM18: 0 | EP18: 0.5055
A19: 44636 | B19: 1746856 | C19: 32072 | D19: 787566 | E19: 30606 | F19: 0.95429035 | G19: 1318 | H19: 1364 | I19: 291720 | J19: 0 | K19: 801 | L19: 0 | M19: 644665 | N19: 0 | O19: 1032 | P19: 0 | Q19: 1968400 | R19: 12600 | S19: 2011200 | T19: 15400 | U19: 2804173 | V19: 3147 | W19: 2269715 | X19: 432 | Y19: 282016 | Z19: 219 | AB19: 0.66666667 | AC19: 266.66667 | AE19: 177717 | AF19: 263 | AG19: 487310 | AH19: 420 | AI19: 1179 | AJ19: 0 | AK19: 5486 | AL19: 0 | AM19: 16177 | AN19: 241 | AP19: 0 | AQ19: 617990 | AR19: 130 | AS19: 1569 | AT19: 0 | AU19: 56085 | AV19: 19 | AW19: 9236 | AX19: 1 | AY19: 10937 | AZ19: 1 | BA19: 18029 | BB19: 14 | BC19: 20325 | BD19: 3 | BE19: 21023 | BF19: 1 | BG19: 14312 | BH19: 2 | BI19: 6598 | BJ19: 0 | BK19: 27503 | BL19: 6 | BM19: 5199 | BN19: 5 | BO19: 24224 | BP19: 68 | BQ19: 3641 | BR19: 0 | BS19: 17 | BT19: 113 | BU19: 634720 | BV19: 260 | BW19: 3895 | BX19: 25 | BY19: 833150 | BZ19: 230 | CA19: 19225 | CB19: 57 | CC19: 100 | CD19: 490 | CE19: 46 | CF19: 155 | CG19: 20161.857 | CI19: 0 | CJ19: 237926 | CK19: 194 | CL19: 1107.74 | CM19: 66 | CN19: 7111.5 | CO19: 70 | CP19: 7542.5 | CQ19: 70 | CR19: 7542.5 | CS19: 22196.5 | CT19: 1293 | CV19: 41637 | CW19: 49 | CX19: 279.79 | CY19: 35279 | CZ19: 0 | DA19: 0 | DB19: 13196 | DC19: 18 | DD19: 102.78 | DE19: 843528 | DF19: 58 | DG19: 331.18 | DH19: 8706 | DI19: 23 | DJ19: 131.33 | DK19: 9116 | DL19: 10 | DM19: 57.1 | DN19: 5451 | DO19: 8 | DP19: 45.68 | DQ19: 2110 | DR19: 1 | DS19: 5.71 | DT19: 6492 | DU19: 9 | DV19: 51.39 | DW19: 5979 | DX19: 8 | DY19: 45.68 | DZ19: 6728 | EA19: 8 | EB19: 45.68 | EC19: 6682 | ED19: 11 | EE19: 62.81 | EG19: 0 | EI19: 0 | EK19: 0 | EM19: 0 | EP19: 0.4725
A20: 44637 | B20: 1767746 | C20: 20890 | D20: 807342 | E20: 19776 | F20: 0.94667305 | G20: 1318 | H20: 1364 | I20: 291720 | J20: 0 | K20: 801 | L20: 0 | M20: 644665 | N20: 0 | O20: 1032 | P20: 0 | Q20: 1976600 | R20: 8200 | S20: 2021000 | T20: 9800 | U20: 2805950 | V20: 1777 | W20: 2270153 | X20: 438 | Y20: 282474 | Z20: 458 | AB20: 0.83333333 | AC20: 333.33333 | AE20: 177746 | AF20: 29 | AG20: 487790 | AH20: 480 | AI20: 1179 | AJ20: 0 | AK20: 5486 | AL20: 0 | AM20: 16630 | AN20: 453 | AP20: 0 | AQ20: 618180 | AR20: 190 | AS20: 1570 | AT20: 1 | AU20: 56102 | AV20: 17 | AW20: 9237 | AX20: 1 | AY20: 10938 | AZ20: 1 | BA20: 18059 | BB20: 30 | BC20: 20327 | BD20: 2 | BE20: 21025 | BF20: 2 | BG20: 14314 | BH20: 2 | BI20: 6598 | BJ20: 0 | BK20: 27510 | BL20: 7 | BM20: 5203 | BN20: 4 | BO20: 24290 | BP20: 66 | BQ20: 3641 | BR20: 0 | BS20: 34 | BT20: 156 | BU20: 634943 | BV20: 223 | BW20: 3914 | BX20: 19 | BY20: 833320 | BZ20: 170 | CA20: 19273 | CB20: 48 | CC20: -20 | CD20: 393 | CE20: 59 | CF20: 155 | CG20: 20161.857 | CI20: 0 | CJ20: 238092 | CK20: 166 | CL20: 947.86 | CM20: 64 | CN20: 6896 | CO20: 63 | CP20: 6788.25 | CQ20: 66 | CR20: 7111.5 | CS20: 20795.75 | CT20: 1400.75 | CU20: 5355 | CV20: 41676 | CW20: 39 | CX20: 222.69 | CY20: 35286 | CZ20: 7 | DA20: 39.97 | DB20: 13208 | DC20: 12 | DD20: 68.52 | DE20: 843598 | DF20: 70 | DG20: 399.7 | DH20: 8725 | DI20: 19 | DJ20: 108.49 | DK20: 9127 | DL20: 11 | DM20: 62.81 | DN20: 5460 | DO20: 9 | DP20: 51.39 | DQ20: 2112 | DR20: 2 | DS20: 11.42 | DT20: 6501 | DU20: 9 | DV20: 51.39 | DW20: 5987 | DX20: 8 | DY20: 45.68 | DZ20: 6737 | EA20: 9 | EB20: 51.39 | EC20: 6693 | ED20: 11 | EE20: 62.81 | EG20: 0 | EI20: 0 | EK20: 0 | EM20: 0 | EP20: 0.4615
A21: 44638 | B21: 1794544 | C21: 26798 | D21: 832860 | E21: 25518 | F21: 0.95223524 | G21: 1318 | H21: 1364 | I21: 291720 | J21: 0 | K21: 801 | L21: 0 | M21: 644665 | N21: 0 | O21: 1032 | P21: 0 | Q21: 1987300 | R21: 10700 | S21: 2033500 | T21: 12500 | U21: 2807854 | V21: 1904 | W21: 2270555 | X21: 402 | Y21: 282733 | Z21: 259 | AB21: 0.72222222 | AC21: 288.88889 | AE21: 177871 | AF21: 125 | AG21: 488230 | AH21: 440 | AI21: 1179 | AJ21: 0 | AK21: 5489 | AL21: 3 | AM21: 16954 | AN21: 324 | AP21: 0 | AQ21: 618280 | AR21: 100 | AS21: 1570 | AT21: 0 | AU21: 56129 | AV21: 27 | AW21: 9238 | AX21: 1 | AY21: 10937 | AZ21: 0 | BA21: 18075 | BB21: 16 | BC21: 20330 | BD21: 3 | BE21: 21027 | BF21: 2 | BG21: 14317 | BH21: 3 | BI21: 6599 | BJ21: 1 | BK21: 27516 | BL21: 6 | BM21: 5207 | BN21: 4 | BO21: 24358 | BP21: 68 | BQ21: 3641 | BR21: 0 | BS21: 21 | BT21: 79 | BU21: 635170 | BV21: 227 | BW21: 3929 | BX21: 15 | BY21: 833530 | BZ21: 210 | CA21: 19321 | CB21: 48 | CC21: 110 | CD21: 437 | CE21: 57 | CF21: 155 | CG21: 20161.857 | CI21: 0 | CJ21: 238279 | CK21: 187 | CL21: 1067.77 | CM21: 79 | CN21: 8512.25 | CO21: 79 | CP21: 8512.25 | CQ21: 79 | CR21: 8512.25 | CS21: 25536.75 | CT21: 614 | CV21: 41709 | CW21: 33 | CX21: 188.43 | CY21: 35291 | CZ21: 5 | DA21: 28.55 | DB21: 13224 | DC21: 16 | DD21: 91.36 | DE21: 843670 | DF21: 72 | DG21: 411.12 | DH21: 8746 | DI21: 21 | DJ21: 119.91 | DK21: 9137 | DL21: 10 | DM21: 57.1 | DN21: 5469 | DO21: 9 | DP21: 51.39 | DQ21: 2114 | DR21: 2 | DS21: 11.42 | DT21: 6510 | DU21: 9 | DV21: 51.39 | DW21: 6000 | DX21: 13 | DY21: 74.23 | DZ21: 6746 | EA21: 9 | EB21: 51.39 | EC21: 6703 | ED21: 10 | EE21: 57.1 | EG21: 0 | EI21: 0 | EK21: 0 | EM21: 0 | EP21: 0.4725
A22: 44639 | B22: 1821318 | C22: 26774 | D22: 858174 | E22: 25314 | F22: 0.94546949 | G22: 1318 | H22: 1364 | I22: 291720 | J22: 0 | K22: 801 | L22: 0 | M22: 644665 | N22: 0 | O22: 1032 | P22: 0 | Q22: 1998000 | R22: 10700 | S22: 2045800 | T22: 12300 | U22: 2809281 | V22: 1427 | W22: 2270959 | X22: 404 | Y22: 282992 | Z22: 259 | AB22: 0.77777778 | AC22: 311.11111 | AD22: 12 | AE22: 177996 | AF22: 125 | AG22: 488710 | AH22: 480 | AI22: 1179 | AJ22: 0 | AK22: 5489 | AL22: 0 | AM22: 17133 | AN22: 179 | AP22: 0 | AQ22: 618420 | AR22: 140 | AS22: 1571 | AT22: 1 | AU22: 56176 | AV22: 47 | AW22: 9239 | AX22: 1 | AY22: 10938 | AZ22: 1 | BA22: 18080 | BB22: 5 | BC22: 20332 | BD22: 2 | BE22: 21029 | BF22: 2 | BG22: 14318 | BH22: 1 | BI22: 6599 | BJ22: 0 | BK22: 27527 | BL22: 11 | BM22: 5213 | BN22: 6 | BO22: 24429 | BP22: 71 | BQ22: 3641 | BR22: 0 | BS22: 8 | BT22: 132 | BU22: 635440 | BV22: 270 | BW22: 3952 | BX22: 23 | BY22: 833720 | BZ22: 190 | CA22: 19371 | CB22: 50 | CC22: 50 | CD22: 460 | CE22: 65 | CF22: 155 | CG22: 20161.857 | CI22: 0 | CJ22: 238521 | CK22: 242 | CL22: 1381.82 | CM22: 74 | CN22: 7973.5 | CO22: 76 | CP22: 8189 | CQ22: 74 | CR22: 7973.5 | CS22: 24136 | CT22: 1400.75 | CV22: 41748 | CW22: 39 | CX22: 222.69 | CY22: 35291 | CZ22: 0 | DA22: 0 | DB22: 13241 | DC22: 17 | DD22: 97.07 | DE22: 843767 | DF22: 97 | DG22: 553.87 | DH22: 8774 | DI22: 28 | DJ22: 159.88 | DK22: 9147 | DL22: 10 | DM22: 57.1 | DN22: 5478 | DO22: 9 | DP22: 51.39 | DQ22: 2115 | DR22: 1 | DS22: 5.71 | DT22: 6521 | DU22: 11 | DV22: 62.81 | DW22: 6014 | DX22: 14 | DY22: 79.94 | DZ22: 6755 | EA22: 9 | EB22: 51.39 | EC22: 6714 | ED22: 11 | EE22: 62.81 | EG22: 0 | EI22: 0 | EK22: 0 | EM22: 0 | EP22: 0.5055
A23: 44640 | B23: 1845824 | C23: 24506 | D23: 881408 | E23: 23234 | F23: 0.94809434 | G23: 1318 | H23: 1364 | I23: 291720 | J23: 0 | K23: 801 | L23: 0 | M23: 644665 | N23: 0 | O23: 1032 | P23: 0 | Q23: 2008100 | R23: 10100 | S23: 2048100 | T23: 2300 | U23: 2810215 | V23: 934 | W23: 2271374 | X23: 415 | Y23: 283292 | Z23: 300 | AB23: 0.94444444 | AC23: 377.77778 | AE23: 178239 | AF23: 243 | AG23: 489150 | AH23: 440 | AI23: 1180 | AJ23: 1 | AK23: 5491 | AL23: 2 | AM23: 17568 | AN23: 435 | AP23: 0 | AQ23: 618570 | AR23: 150 | AS23: 1572 | AT23: 1 | AU23: 56206 | AV23: 30 | AW23: 9239 | AX23: 0 | AY23: 10938 | AZ23: 0 | BA23: 18103 | BB23: 23 | BC23: 20338 | BD23: 6 | BE23: 21031 | BF23: 2 | BG23: 14320 | BH23: 2 | BI23: 6600 | BJ23: 1 | BK23: 27536 | BL23: 9 | BM23: 5217 | BN23: 4 | BO23: 24485 | BP23: 56 | BQ23: 3641 | BR23: 0 | BS23: 27 | BT23: 123 | BU23: 635650 | BV23: 210 | BW23: 3970 | BX23: 18 | BY23: 833930 | BZ23: 210 | CA23: 19420 | CB23: 49 | CC23: 60 | CD23: 420 | CE23: 68 | CF23: 155 | CG23: 20161.857 | CI23: 0 | CJ23: 238700 | CK23: 179 | CL23: 1022.09 | CM23: 70 | CN23: 7542.5 | CO23: 72 | CP23: 7758 | CQ23: 70 | CR23: 7542.5 | CS23: 22843 | CT23: 1293 | CV23: 41788 | CW23: 40 | CX23: 228.4 | CY23: 35297 | CZ23: 6 | DA23: 34.26 | DB23: 13254 | DC23: 13 | DD23: 74.23 | DE23: 843839 | DF23: 72 | DG23: 411.12 | DH23: 8801 | DI23: 27 | DJ23: 154.17 | DK23: 9157 | DL23: 10 | DM23: 57.1 | DN23: 5486 | DO23: 8 | DP23: 45.68 | DQ23: 2116 | DR23: 1 | DS23: 5.71 | DT23: 6529 | DU23: 8 | DV23: 45.68 | DW23: 6025 | DX23: 11 | DY23: 62.81 | DZ23: 6764 | EA23: 9 | EB23: 51.39 | EC23: 6725 | ED23: 11 | EE23: 62.81 | EG23: 0 | EI23: 0 | EK23: 0 | EM23: 0 | EP23: 0.5165
A24: 44641 | B24: 1871699 | C24: 25875 | D24: 906022 | E24: 24614 | F24: 0.9512657 | G24: 1318 | H24: 1364 | I24: 291720 | J24: 0 | K24: 801 | L24: 0 | M24: 644665 | N24: 0 | O24: 1032 | P24: 0 | Q24: 2018900 | R24: 10800 | S24: 2063000 | T24: 14900 | U24: 2811732 | V24: 1517 | W24: 2271796 | X24: 422 | Y24: 283493 | Z24: 201 | AB24: 0.69444444 | AC24: 277.77778 | AE24: 178239 | AF24: 0 | AG24: 489570 | AH24: 420 | AI24: 1182 | AJ24: 2 | AK24: 5491 | AL24: 0 | AM24: 17808 | AN24: 240 | AP24: 0 | AQ24: 618700 | AR24: 130 | AS24: 1572 | AT24: 0 | AU24: 56235 | AV24: 29 | AW24: 9239 | AX24: 0 | AY24: 10939 | AZ24: 1 | BA24: 18116 | BB24: 13 | BC24: 20341 | BD24: 3 | BE24: 21033 | BF24: 2 | BG24: 14321 | BH24: 1 | BI24: 6600 | BJ24: 0 | BK24: 27543 | BL24: 7 | BM24: 5223 | BN24: 6 | BO24: 24544 | BP24: 59 | BQ24: 3641 | BR24: 0 | BS24: 16 | BT24: 114 | BU24: 635870 | BV24: 220 | BW24: 3988 | BX24: 18 | BY24: 834120 | BZ24: 190 | CA24: 19471 | CB24: 51 | CC24: 60 | CD24: 410 | CE24: 55 | CF24: 155 | CG24: 20161.857 | CI24: 0 | CJ24: 238911 | CK24: 211 | CL24: 1204.81 | CM24: 69 | CN24: 7434.75 | CO24: 66 | CP24: 7111.5 | CQ24: 67 | CR24: 7219.25 | CS24: 21765.5 | CT24: 1077.5 | CV24: 41814 | CW24: 26 | CX24: 148.46 | CY24: 35303 | CZ24: 6 | DA24: 34.26 | DB24: 13272 | DC24: 18 | DD24: 102.78 | DE24: 843899 | DF24: 60 | DG24: 342.6 | DH24: 8824 | DI24: 23 | DJ24: 131.33 | DK24: 9167 | DL24: 10 | DM24: 57.1 | DN24: 5494 | DO24: 8 | DP24: 45.68 | DQ24: 2118 | DR24: 2 | DS24: 11.42 | DT24: 6538 | DU24: 9 | DV24: 51.39 | DW24: 6037 | DX24: 12 | DY24: 68.52 | DZ24: 6773 | EA24: 9 | EB24: 51.39 | EC24: 6736 | ED24: 11 | EE24: 62.81 | EG24: 0 | EI24: 0 | EK24: 0 | EM24: 0 | EP24: 0.5495
A25: 44642 | B25: 1896644 | C25: 24945 | D25: 929902 | E25: 23880 | F25: 0.95730607 | G25: 1318 | H25: 1364 | I25: 291720 | J25: 0 | K25: 801 | L25: 0 | M25: 644665 | N25: 0 | O25: 1032 | P25: 0 | Q25: 2028900 | R25: 10000 | S25: 2080000 | T25: 17000 | U25: 2813915 | V25: 2183 | W25: 2272213 | X25: 417 | Y25: 283592 | Z25: 99 | AB25: 0.66666667 | AC25: 266.66667 | AE25: 178430 | AF25: 191 | AG25: 489960 | AH25: 390 | AI25: 1182 | AJ25: 0 | AK25: 5491 | AL25: 0 | AM25: 17927 | AN25: 119 | AP25: 0 | AQ25: 618840 | AR25: 140 | AS25: 1573 | AT25: 1 | AU25: 56238 | AV25: 3 | AW25: 9240 | AX25: 1 | AY25: 10940 | AZ25: 1 | BA25: 18129 | BB25: 13 | BC25: 20346 | BD25: 5 | BE25: 21035 | BF25: 2 | BG25: 14322 | BH25: 1 | BI25: 6601 | BJ25: 1 | BK25: 27549 | BL25: 6 | BM25: 5229 | BN25: 6 | BO25: 24611 | BP25: 67 | BQ25: 3641 | BR25: 0 | BS25: 16 | BT25: 124 | BU25: 636050 | BV25: 180 | BW25: 4024 | BX25: 36 | BY25: 834310 | BZ25: 190 | CA25: 19520 | CB25: 49 | CC25: 50 | CD25: 370 | CE25: 33 | CF25: 155 | CG25: 20161.857 | CI25: 0 | CJ25: 239047 | CK25: 136 | CL25: 776.56 | CM25: 63 | CN25: 6788.25 | CO25: 65 | CP25: 7003.75 | CQ25: 63 | CR25: 6788.25 | CS25: 20580.25 | CT25: 1185.25 | CV25: 41855 | CW25: 41 | CX25: 234.11 | CY25: 35309 | CZ25: 6 | DA25: 34.26 | DB25: 13283 | DC25: 11 | DD25: 62.81 | DE25: 843848 | DF25: 0 | DG25: 0 | DH25: 8841 | DI25: 17 | DJ25: 97.07 | DK25: 9177 | DL25: 10 | DM25: 57.1 | DN25: 5502 | DO25: 8 | DP25: 45.68 | DQ25: 2119 | DR25: 1 | DS25: 5.71 | DT25: 6548 | DU25: 10 | DV25: 57.1 | DW25: 6051 | DX25: 14 | DY25: 79.94 | DZ25: 6782 | EA25: 9 | EB25: 51.39 | EC25: 6748 | ED25: 12 | EE25: 68.52 | EG25: 0 | EI25: 0 | EK25: 0 | EM25: 0 | EP25: 0.5385
