Workbook

Sheet TOTAL
A1: Site Name | B1: Day | C1: Month | D1: Year | E1: Total Electricity Kwh | F1: Electricity Tariff ($/Kwh) | G1: Natual Gas (m3) | H1: Natural Gas $/m3 | I1: Water Utility Supply (m3) m3 | J1: Water Utility Supply (m3) $/m3 | K1: Room Nights
A2: Orlando | B2: 1 | C2: 1 | D2: 2022 | E2: =Submetering!F3+Submetering!H3+Submetering!J3+Submetering!L3+Submetering!N3+Submetering!P3+Submetering!R3+Submetering!T3+Submetering!V3+Submetering!X3+Submetering!Z3+Submetering!AB3+Submetering!AC3+Submetering!AD3+Submetering!AE3 -> 105883 | F2: =((((Submetering!E3+Submetering!AD3)*0.13773+(Submetering!E3+Submetering!AD3)*0.02095)*1.09+(2.85/30)*2)+(((Submetering!F3+Submetering!H3+Submetering!J3+Submetering!L3+Submetering!N3+Submetering!P3+Submetering!R3+Submetering!T3+Submetering!V3+Submetering!X3+Submetering!Z3+Submetering!AB3+Submetering!AC3+Submetering!AE3)*0.05155)+((Submetering!F3+Submetering!H3+Submetering!J3+Submetering!L3+Submetering!N3+Submetering!P3+Submetering!R3+Submetering!T3+Submetering!V3+Submetering!X3+Submetering!Z3+Submetering!AB3+Submetering!AC3+Submetering!AE3)*0.02095)+(20/30)*15)*1.1048)/E2 -> 0.080524989 | G2: =Submetering!AK3+Submetering!AL3+Submetering!AU3 -> 1424.8252 | H2: 0.8166 | I2: =Submetering!AF3+Submetering!AG3+Submetering!AV3+Submetering!AY3+Submetering!AZ3 -> 1752.465 | J2: =((Submetering!AG3+Submetering!BA3)*0.8868+(1712.96+1070.52)/30+(Submetering!AF3+Submetering!AY3+Submetering!AV3+Submetering!AZ3)*1.1251+(2076.11+129.67+207.57+207.57)/30+(11680.53+56.61)/30)/I2 -> 1.417625 | K2: =Elect!C5 -> 242.25
A3: Orlando | B3: 3 | C3: 1 | D3: 2022 | E3: =Submetering!F4+Submetering!H4+Submetering!J4+Submetering!L4+Submetering!N4+Submetering!P4+Submetering!R4+Submetering!T4+Submetering!V4+Submetering!X4+Submetering!Z4+Submetering!AB4+Submetering!AC4+Submetering!AD4+Submetering!AE4 -> 280408 | F3: =((((Submetering!E4+Submetering!AD4)*0.13773+(Submetering!E4+Submetering!AD4)*0.02095)*1.09+(2.85/30)*2)+(((Submetering!F4+Submetering!H4+Submetering!J4+Submetering!L4+Submetering!N4+Submetering!P4+Submetering!R4+Submetering!T4+Submetering!V4+Submetering!X4+Submetering!Z4+Submetering!AB4+Submetering!AC4+Submetering!AE4)*0.05155)+((Submetering!F4+Submetering!H4+Submetering!J4+Submetering!L4+Submetering!N4+Submetering!P4+Submetering!R4+Submetering!T4+Submetering!V4+Submetering!X4+Submetering!Z4+Submetering!AB4+Submetering!AC4+Submetering!AE4)*0.02095)+(20/30)*15)*1.1048)/E3 -> 0.080862566 | G3: =Submetering!AK4+Submetering!AL4+Submetering!AU4 -> 6586.654 | H3: 0.8166 | I3: =Submetering!AF4+Submetering!AG4+Submetering!AV4+Submetering!AY4+Submetering!AZ4 -> 5054.4598 | J3: =((Submetering!AG4+Submetering!BA4)*0.8868+(1712.96+1070.52)/30+(Submetering!AF4+Submetering!AY4+Submetering!AV4+Submetering!AZ4)*1.1251+(2076.11+129.67+207.57+207.57)/30+(11680.53+56.61)/30)/I3 -> 1.2130453 | K3: =Elect!C6 -> 1355
A4: Orlando | B4: 10 | C4: 1 | D4: 2022 | E4: =Submetering!F5+Submetering!H5+Submetering!J5+Submetering!L5+Submetering!N5+Submetering!P5+Submetering!R5+Submetering!T5+Submetering!V5+Submetering!X5+Submetering!Z5+Submetering!AB5+Submetering!AC5+Submetering!AD5+Submetering!AE5 -> 286418 | F4: =((((Submetering!E5+Submetering!AD5)*0.13773+(Submetering!E5+Submetering!AD5)*0.02095)*1.09+(2.85/30)*2)+(((Submetering!F5+Submetering!H5+Submetering!J5+Submetering!L5+Submetering!N5+Submetering!P5+Submetering!R5+Submetering!T5+Submetering!V5+Submetering!X5+Submetering!Z5+Submetering!AB5+Submetering!AC5+Submetering!AE5)*0.05155)+((Submetering!F5+Submetering!H5+Submetering!J5+Submetering!L5+Submetering!N5+Submetering!P5+Submetering!R5+Submetering!T5+Submetering!V5+Submetering!X5+Submetering!Z5+Submetering!AB5+Submetering!AC5+Submetering!AE5)*0.02095)+(20/30)*15)*1.1048)/E4 -> 0.080762706 | G4: =Submetering!AK5+Submetering!AL5+Submetering!AU5 -> 8168.8638 | H4: 0.8166 | I4: =Submetering!AF5+Submetering!AG5+Submetering!AV5+Submetering!AY5+Submetering!AZ5 -> 4647.001 | J4: =((Submetering!AG5+Submetering!BA5)*0.8868+(1712.96+1070.52)/30+(Submetering!AF5+Submetering!AY5+Submetering!AV5+Submetering!AZ5)*1.1251+(2076.11+129.67+207.57+207.57)/30+(11680.53+56.61)/30)/I4 -> 1.2293122 | K4: =Elect!C7 -> 1610
A5: Orlando | B5: 17 | C5: 1 | D5: 2022 | E5: =Submetering!F6+Submetering!H6+Submetering!J6+Submetering!L6+Submetering!N6+Submetering!P6+Submetering!R6+Submetering!T6+Submetering!V6+Submetering!X6+Submetering!Z6+Submetering!AB6+Submetering!AC6+Submetering!AD6+Submetering!AE6 -> 279751 | F5: =((((Submetering!E6+Submetering!AD6)*0.13773+(Submetering!E6+Submetering!AD6)*0.02095)*1.09+(2.85/30)*2)+(((Submetering!F6+Submetering!H6+Submetering!J6+Submetering!L6+Submetering!N6+Submetering!P6+Submetering!R6+Submetering!T6+Submetering!V6+Submetering!X6+Submetering!Z6+Submetering!AB6+Submetering!AC6+Submetering!AE6)*0.05155)+((Submetering!F6+Submetering!H6+Submetering!J6+Submetering!L6+Submetering!N6+Submetering!P6+Submetering!R6+Submetering!T6+Submetering!V6+Submetering!X6+Submetering!Z6+Submetering!AB6+Submetering!AC6+Submetering!AE6)*0.02095)+(20/30)*15)*1.1048)/E5 -> 0.08072582 | G5: =Submetering!AK6+Submetering!AL6+Submetering!AU6 -> 8793.7472 | H5: 0.8166 | I5: =Submetering!AF6+Submetering!AG6+Submetering!AV6+Submetering!AY6+Submetering!AZ6 -> 4520.7118 | J5: =((Submetering!AG6+Submetering!BA6)*0.8868+(1712.96+1070.52)/30+(Submetering!AF6+Submetering!AY6+Submetering!AV6+Submetering!AZ6)*1.1251+(2076.11+129.67+207.57+207.57)/30+(11680.53+56.61)/30)/I5 -> 1.2385967 | K5: =Elect!C8 -> 1849
A6: Orlando | B6: 24 | C6: 1 | D6: 2022 | E6: =Submetering!F7+Submetering!H7+Submetering!J7+Submetering!L7+Submetering!N7+Submetering!P7+Submetering!R7+Submetering!T7+Submetering!V7+Submetering!X7+Submetering!Z7+Submetering!AB7+Submetering!AC7+Submetering!AD7+Submetering!AE7 -> 261801 | F6: =((((Submetering!E7+Submetering!AD7)*0.13773+(Submetering!E7+Submetering!AD7)*0.02095)*1.09+(2.85/30)*2)+(((Submetering!F7+Submetering!H7+Submetering!J7+Submetering!L7+Submetering!N7+Submetering!P7+Submetering!R7+Submetering!T7+Submetering!V7+Submetering!X7+Submetering!Z7+Submetering!AB7+Submetering!AC7+Submetering!AE7)*0.05155)+((Submetering!F7+Submetering!H7+Submetering!J7+Submetering!L7+Submetering!N7+Submetering!P7+Submetering!R7+Submetering!T7+Submetering!V7+Submetering!X7+Submetering!Z7+Submetering!AB7+Submetering!AC7+Submetering!AE7)*0.02095)+(20/30)*15)*1.1048)/E6 -> 0.080697066 | G6: =Submetering!AK7+Submetering!AL7+Submetering!AU7 -> 9082.3306 | H6: 0.8166 | I6: =Submetering!AF7+Submetering!AG7+Submetering!AV7+Submetering!AY7+Submetering!AZ7 -> 3812.8896 | J6: =((Submetering!AG7+Submetering!BA7)*0.8868+(1712.96+1070.52)/30+(Submetering!AF7+Submetering!AY7+Submetering!AV7+Submetering!AZ7)*1.1251+(2076.11+129.67+207.57+207.57)/30+(11680.53+56.61)/30)/I6 -> 1.2732171 | K6: =Elect!C9 -> 724
A7: Orlando | B7: 31 | C7: 1 | D7: 2022 | E7: =Submetering!F8+Submetering!H8+Submetering!J8+Submetering!L8+Submetering!N8+Submetering!P8+Submetering!R8+Submetering!T8+Submetering!V8+Submetering!X8+Submetering!Z8+Submetering!AB8+Submetering!AC8+Submetering!AD8+Submetering!AE8 -> 280505 | F7: =((((Submetering!E8+Submetering!AD8)*0.13773+(Submetering!E8+Submetering!AD8)*0.02095)*1.09+(2.85/30)*2)+(((Submetering!F8+Submetering!H8+Submetering!J8+Submetering!L8+Submetering!N8+Submetering!P8+Submetering!R8+Submetering!T8+Submetering!V8+Submetering!X8+Submetering!Z8+Submetering!AB8+Submetering!AC8+Submetering!AE8)*0.05155)+((Submetering!F8+Submetering!H8+Submetering!J8+Submetering!L8+Submetering!N8+Submetering!P8+Submetering!R8+Submetering!T8+Submetering!V8+Submetering!X8+Submetering!Z8+Submetering!AB8+Submetering!AC8+Submetering!AE8)*0.02095)+(20/30)*15)*1.1048)/E7 -> 0.080991603 | G7: =Submetering!AK8+Submetering!AL8+Submetering!AU8 -> 7215.915 | H7: 0.8166 | I7: =Submetering!AF8+Submetering!AG8+Submetering!AV8+Submetering!AY8+Submetering!AZ8 -> 4725.3304 | J7: =((Submetering!AG8+Submetering!BA8)*0.8868+(1712.96+1070.52)/30+(Submetering!AF8+Submetering!AY8+Submetering!AV8+Submetering!AZ8)*1.1251+(2076.11+129.67+207.57+207.57)/30+(11680.53+56.61)/30)/I7 -> 1.2277025 | K7: =Elect!C10 -> 1557
A8: Orlando | B8: 7 | C8: 2 | D8: 2022 | E8: =Submetering!F9+Submetering!H9+Submetering!J9+Submetering!L9+Submetering!N9+Submetering!P9+Submetering!R9+Submetering!T9+Submetering!V9+Submetering!X9+Submetering!Z9+Submetering!AB9+Submetering!AC9+Submetering!AD9+Submetering!AE9 -> 260532 | F8: =((((Submetering!E9+Submetering!AD9)*0.13773+(Submetering!E9+Submetering!AD9)*0.02095)*1.09+(2.85/30)*2)+(((Submetering!F9+Submetering!H9+Submetering!J9+Submetering!L9+Submetering!N9+Submetering!P9+Submetering!R9+Submetering!T9+Submetering!V9+Submetering!X9+Submetering!Z9+Submetering!AB9+Submetering!AC9+Submetering!AE9)*0.05155)+((Submetering!F9+Submetering!H9+Submetering!J9+Submetering!L9+Submetering!N9+Submetering!P9+Submetering!R9+Submetering!T9+Submetering!V9+Submetering!X9+Submetering!Z9+Submetering!AB9+Submetering!AC9+Submetering!AE9)*0.02095)+(20/30)*15)*1.1048)/E8 -> 0.080416304 | G8: =Submetering!AK9+Submetering!AL9+Submetering!AU9 -> 4121.6472 | H8: 0.8166 | I8: =Submetering!AF9+Submetering!AG9+Submetering!AV9+Submetering!AY9+Submetering!AZ9 -> 4498.5388 | J8: =((Submetering!AG9+Submetering!BA9)*0.8868+(1712.96+1070.52)/30+(Submetering!AF9+Submetering!AY9+Submetering!AV9+Submetering!AZ9)*1.1251+(2076.11+129.67+207.57+207.57)/30+(11680.53+56.61)/30)/I8 -> 1.237892 | K8: =Elect!C11 -> 1315
A9: Orlando | B9: 14 | C9: 2 | D9: 2022 | E9: =Submetering!F10+Submetering!H10+Submetering!J10+Submetering!L10+Submetering!N10+Submetering!P10+Submetering!R10+Submetering!T10+Submetering!V10+Submetering!X10+Submetering!Z10+Submetering!AB10+Submetering!AC10+Submetering!AD10+Submetering!AE10 -> 316895 | F9: =((((Submetering!E10+Submetering!AD10)*0.13773+(Submetering!E10+Submetering!AD10)*0.02095)*1.09+(2.85/30)*2)+(((Submetering!F10+Submetering!H10+Submetering!J10+Submetering!L10+Submetering!N10+Submetering!P10+Submetering!R10+Submetering!T10+Submetering!V10+Submetering!X10+Submetering!Z10+Submetering!AB10+Submetering!AC10+Submetering!AE10)*0.05155)+((Submetering!F10+Submetering!H10+Submetering!J10+Submetering!L10+Submetering!N10+Submetering!P10+Submetering!R10+Submetering!T10+Submetering!V10+Submetering!X10+Submetering!Z10+Submetering!AB10+Submetering!AC10+Submetering!AE10)*0.02095)+(20/30)*15)*1.1048)/E9 -> 0.080646166 | G9: =Submetering!AK10+Submetering!AL10+Submetering!AU10 -> 10809.195 | H9: 0.8166 | I9: =Submetering!AF10+Submetering!AG10+Submetering!AV10+Submetering!AY10+Submetering!AZ10 -> 5814.171 | J9: =((Submetering!AG10+Submetering!BA10)*0.8868+(1712.96+1070.52)/30+(Submetering!AF10+Submetering!AY10+Submetering!AV10+Submetering!AZ10)*1.1251+(2076.11+129.67+207.57+207.57)/30+(11680.53+56.61)/30)/I9 -> 1.2057537 | K9: =Elect!C12 -> 2448
A10: Orlando | B10: 21 | C10: 2 | D10: 2022 | E10: =Submetering!F11+Submetering!H11+Submetering!J11+Submetering!L11+Submetering!N11+Submetering!P11+Submetering!R11+Submetering!T11+Submetering!V11+Submetering!X11+Submetering!Z11+Submetering!AB11+Submetering!AC11+Submetering!AD11+Submetering!AE11 -> 344088 | F10: =((((Submetering!E11+Submetering!AD11)*0.13773+(Submetering!E11+Submetering!AD11)*0.02095)*1.09+(2.85/30)*2)+(((Submetering!F11+Submetering!H11+Submetering!J11+Submetering!L11+Submetering!N11+Submetering!P11+Submetering!R11+Submetering!T11+Submetering!V11+Submetering!X11+Submetering!Z11+Submetering!AB11+Submetering!AC11+Submetering!AE11)*0.05155)+((Submetering!F11+Submetering!H11+Submetering!J11+Submetering!L11+Submetering!N11+Submetering!P11+Submetering!R11+Submetering!T11+Submetering!V11+Submetering!X11+Submetering!Z11+Submetering!AB11+Submetering!AC11+Submetering!AE11)*0.02095)+(20/30)*15)*1.1048)/E10 -> 0.080661383 | G10: =Submetering!AK11+Submetering!AL11+Submetering!AU11 -> 4867.116 | H10: 0.8166 | I10: =Submetering!AF11+Submetering!AG11+Submetering!AV11+Submetering!AY11+Submetering!AZ11 -> 6283.1328 | J10: =((Submetering!AG11+Submetering!BA11)*0.8868+(1712.96+1070.52)/30+(Submetering!AF11+Submetering!AY11+Submetering!AV11+Submetering!AZ11)*1.1251+(2076.11+129.67+207.57+207.57)/30+(11680.53+56.61)/30)/I10 -> 1.1954698 | K10: =Elect!C13 -> 2437
A11: Orlando | B11: 28 | C11: 2 | D11: 2022 | E11: =Submetering!F12+Submetering!H12+Submetering!J12+Submetering!L12+Submetering!N12+Submetering!P12+Submetering!R12+Submetering!T12+Submetering!V12+Submetering!X12+Submetering!Z12+Submetering!AB12+Submetering!AC12+Submetering!AD12+Submetering!AE12 -> 296800 | F11: =((((Submetering!E12+Submetering!AD12)*0.13773+(Submetering!E12+Submetering!AD12)*0.02095)*1.09+(2.85/30)*2)+(((Submetering!F12+Submetering!H12+Submetering!J12+Submetering!L12+Submetering!N12+Submetering!P12+Submetering!R12+Submetering!T12+Submetering!V12+Submetering!X12+Submetering!Z12+Submetering!AB12+Submetering!AC12+Submetering!AE12)*0.05155)+((Submetering!F12+Submetering!H12+Submetering!J12+Submetering!L12+Submetering!N12+Submetering!P12+Submetering!R12+Submetering!T12+Submetering!V12+Submetering!X12+Submetering!Z12+Submetering!AB12+Submetering!AC12+Submetering!AE12)*0.02095)+(20/30)*15)*1.1048)/E11 -> 0.080660521 | G11: =Submetering!AK12+Submetering!AL12+Submetering!AU12 -> 5659.7466 | H11: 0.8166 | I11: =Submetering!AF12+Submetering!AG12+Submetering!AV12+Submetering!AY12+Submetering!AZ12 -> 5705.776 | J11: =((Submetering!AG12+Submetering!BA12)*0.8868+(1712.96+1070.52)/30+(Submetering!AF12+Submetering!AY12+Submetering!AV12+Submetering!AZ12)*1.1251+(2076.11+129.67+207.57+207.57)/30+(11680.53+56.61)/30)/I11 -> 1.2029924 | K11: =Elect!C14 -> 2097
A12: Orlando | B12: 7 | C12: 3 | D12: 2022 | E12: =Submetering!F13+Submetering!H13+Submetering!J13+Submetering!L13+Submetering!N13+Submetering!P13+Submetering!R13+Submetering!T13+Submetering!V13+Submetering!X13+Submetering!Z13+Submetering!AB13+Submetering!AC13+Submetering!AD13+Submetering!AE13 -> 348260 | F12: =((((Submetering!E13+Submetering!AD13)*0.13773+(Submetering!E13+Submetering!AD13)*0.02095)*1.09+(2.85/30)*2)+(((Submetering!F13+Submetering!H13+Submetering!J13+Submetering!L13+Submetering!N13+Submetering!P13+Submetering!R13+Submetering!T13+Submetering!V13+Submetering!X13+Submetering!Z13+Submetering!AB13+Submetering!AC13+Submetering!AE13)*0.05155)+((Submetering!F13+Submetering!H13+Submetering!J13+Submetering!L13+Submetering!N13+Submetering!P13+Submetering!R13+Submetering!T13+Submetering!V13+Submetering!X13+Submetering!Z13+Submetering!AB13+Submetering!AC13+Submetering!AE13)*0.02095)+(20/30)*15)*1.1048)/E12 -> 0.080669363 | G12: =Submetering!AK13+Submetering!AL13+Submetering!AU13 -> 4913.8864 | H12: 0.8166 | I12: =Submetering!AF13+Submetering!AG13+Submetering!AV13+Submetering!AY13+Submetering!AZ13 -> 5010.1328 | J12: =((Submetering!AG13+Submetering!BA13)*0.8868+(1712.96+1070.52)/30+(Submetering!AF13+Submetering!AY13+Submetering!AV13+Submetering!AZ13)*1.1251+(2076.11+129.67+207.57+207.57)/30+(11680.53+56.61)/30)/I12 -> 1.2312131 | K12: =Elect!C15 -> 2923
A13: Orlando | B13: 14 | C13: 3 | D13: 2022 | E13: =Submetering!F14+Submetering!H14+Submetering!J14+Submetering!L14+Submetering!N14+Submetering!P14+Submetering!R14+Submetering!T14+Submetering!V14+Submetering!X14+Submetering!Z14+Submetering!AB14+Submetering!AC14+Submetering!AD14+Submetering!AE14 -> 324382 | F13: =((((Submetering!E14+Submetering!AD14)*0.13773+(Submetering!E14+Submetering!AD14)*0.02095)*1.09+(2.85/30)*2)+(((Submetering!F14+Submetering!H14+Submetering!J14+Submetering!L14+Submetering!N14+Submetering!P14+Submetering!R14+Submetering!T14+Submetering!V14+Submetering!X14+Submetering!Z14+Submetering!AB14+Submetering!AC14+Submetering!AE14)*0.05155)+((Submetering!F14+Submetering!H14+Submetering!J14+Submetering!L14+Submetering!N14+Submetering!P14+Submetering!R14+Submetering!T14+Submetering!V14+Submetering!X14+Submetering!Z14+Submetering!AB14+Submetering!AC14+Submetering!AE14)*0.02095)+(20/30)*15)*1.1048)/E13 -> 0.080641548 | G13: =Submetering!AK14+Submetering!AL14+Submetering!AU14 -> 1344.8162 | H13: 0.8166 | I13: =Submetering!AF14+Submetering!AG14+Submetering!AV14+Submetering!AY14+Submetering!AZ14 -> 5668.0002 | J13: =((Submetering!AG14+Submetering!BA14)*0.8868+(1712.96+1070.52)/30+(Submetering!AF14+Submetering!AY14+Submetering!AV14+Submetering!AZ14)*1.1251+(2076.11+129.67+207.57+207.57)/30+(11680.53+56.61)/30)/I13 -> 1.2078636 | K13: =Elect!C16 -> 2919
... A62: Orlando | B62: 31 | C62: 12 | D62: 2022 | E62: =Submetering!F63+Submetering!H63+Submetering!J63+Submetering!L63+Submetering!N63+Submetering!P63+Submetering!R63+Submetering!T63+Submetering!V63+Submetering!X63+Submetering!Z63+Submetering!AB63+Submetering!AC63+Submetering!AD63+Submetering!AE63 -> 0 | F62: =((((Submetering!E63+Submetering!AD63)*0.13773+(Submetering!E63+Submetering!AD63)*0.02095)*1.09+(2.85/30)*2)+(((Submetering!F63+Submetering!H63+Submetering!J63+Submetering!L63+Submetering!N63+Submetering!P63+Submetering!R63+Submetering!T63+Submetering!V63+Submetering!X63+Submetering!Z63+Submetering!AB63+Submetering!AC63+Submetering!AE63)*0.05155)+((Submetering!F63+Submetering!H63+Submetering!J63+Submetering!L63+Submetering!N63+Submetering!P63+Submetering!R63+Submetering!T63+Submetering!V63+Submetering!X63+Submetering!Z63+Submetering!AB63+Submetering!AC63+Submetering!AE63)*0.02095)+(20/30)*15)*1.1048)/E62 -> #DIV/0! | G62: =Submetering!AK63+Submetering!AL63+Submetering!AU63 -> 0 | H62: 2.8166 | I62: =Submetering!AF63+Submetering!AG63+Submetering!AV63+Submetering!AY63+Submetering!AZ63 -> 0 | J62: =((Submetering!AG63+Submetering!BA63)*0.8868+(1712.96+1070.52)/30+(Submetering!AF63+Submetering!AY63+Submetering!AV63+Submetering!AZ63)*1.1251+(2076.11+129.67+207.57+207.57)/30+(11680.53+56.61)/30)/I62 -> #DIV/0! | K62: =Elect!C65 -> 0

Sheet Submetering
A1: Site Name | B1: Day | C1: Month | D1: Year | E1: 90 630 431 (KWh) | F1: 68 425 010 (KWh) | G1: T2392 (KWh) | H1: 68 425 008 (KWh) | I1: T7384 (KWh) | J1: 68 425 060 (KWh) | K1: T7380 (KWh) | L1: 68 425 097 (KWh) | M1: T7281 (KWh) | N1: 68 425 059 (KWh) | O1: T2390 (KWh) | P1: 68 425 077 (KWh) | Q1: T2395 (KWh) | R1: 68 425 078 (KWh) | S1: T2393 (KWh) | T1: 68 425 071 (KWh) | U1: T7285 (KWh) | V1: 68 425 093 (KWh) | W1: T7382 (KWh) | X1: 68 425 094 (KWh) | Y1: T2391 (KWh) | Z1: 90 625 242 (KWh) | AA1: T7283 (KWh) | AB1: 672 73 163 (KWh) | AC1: 676 62 513 (KWh) | AD1: 61 979 920 (KWh) | AE1: 56 253 208 (KWh) | AF1: Domestic Water from RCES 74860172 (m3) | AG1: Re-use Water from RCES 74860173 (m3) | AH1: Building A Fire Sprinkler System Make-up 44553004 (m3) | AI1: Building A Potable Water Feed 70275191 (m3) | AJ1: Steam Boilers Make-up Water 2130521 (m3) | AK1: Resort Natural Gas Meter 12C004186-C1 (m3) | AL1: Out Buildings Natural Gas Meter 93477704 (m3) | AM1: Cooling Tower Make-up Water 79177804 (m3) | AN1: Cooling Tower Blowdown Line Deduct 79305675 (m3) | AO1: Building E Potable Water Meter 79190041 (m3) | AP1: 7919004D | AQ1: Building J Irrigation Water Meter 79190039 (m3) | AR1: Lazy Pool River Make-up Water 79324776 (m3) | AS1: Pool Hydraunic Boiler Water Make-up 112014001775 (m3) | AT1: SPA Jacuzzi Water Make-up 112014001771 (m3) | AU1: Golf Clubhouse Natural Gas Meter 82SJ729151 (m3) | AV1: 73337589 - 1387142 | AW1: Golf Clubhouse Flushing Valve Deduct 65956268 (m3) | AX1: Clubhouse | AY1: Golf Maintenance Facility 1334021 (m3) | AZ1: Golf Course Comfort Stations 63265094 (m3) | BA1: Golf Course Re-use Irrigation 67327447 (m3)
A2: Orlando | B2: 1 | C2: 1 | D2: 2022 | E2: =IF(Elect!AL4<0,"0",Elect!AL4) -> 0 | F2: =IF(Elect!I4<0,"0",Elect!I4) -> 0 | G2: =Elect!H4 -> 2.565 | H2: =IF(Elect!F4<0,"0",Elect!F4) -> 0 | I2: =Elect!E4 -> 1.923 | J2: =IF(Elect!U4<0,"0",Elect!U4) -> 0 | K2: =Elect!T4 -> 2.249 | L2: =IF(Elect!AJ4<0,"0",Elect!AJ4) -> 0 | M2: =Elect!AI4 -> 0.294 | N2: =IF(Elect!X4<0,"0",Elect!X4) -> 0 | O2: =Elect!W4 -> 1.671 | P2: =IF(Elect!O4<0,"0",Elect!O4) -> 0 | Q2: =Elect!N4 -> 2.73 | R2: =IF(Elect!L4<0,"0",Elect!L4) -> 0 | S2: =Elect!K4 -> 3.65 | T2: =IF(Elect!R4<0,"0",Elect!R4) -> 0 | U2: =Elect!Q4 -> 3.73 | V2: =IF(Elect!AA4<0,"0",Elect!AA4) -> 0 | W2: =Elect!Z4 -> 2.75 | X2: =IF(Elect!AD4<0,"0",Elect!AD4) -> 0 | Y2: =Elect!AC4 -> 2.31 | Z2: =IF(Elect!AG4<0,"0",Elect!AG4) -> 0 | AA2: =Elect!AF4 -> 2.166 | AB2: =IF(Elect!AX4<0,"0",Elect!AX4) -> 0 | AC2: =IF(Elect!AV4<0,"0",Elect!AV4) -> 0 | AD2: =IF(Elect!AZ4<0,"0",Elect!AZ4) -> 0 | AE2: =IF(Elect!BB4<0,"0",Elect!BB4) -> 0 | AF2: =IF('Wtr-Gas'!E4<0,"0",('Wtr-Gas'!E4)*0.0038) -> 0 | AG2: =IF('Wtr-Gas'!H4<0,"0",('Wtr-Gas'!H4)*0.0038) -> 0 | AH2: =IF('Wtr-Gas'!K4<0,"0",('Wtr-Gas'!K4)*0.0038) -> 0 | AI2: =IF('Wtr-Gas'!N4<0,"0",('Wtr-Gas'!N4)*0.0038) -> 0 | AJ2: =IF('Wtr-Gas'!Q4<0,"0",('Wtr-Gas'!Q4)*0.0038) -> 0 | AK2: =IF('Wtr-Gas'!U4<0,"0",('Wtr-Gas'!U4)*0.0038) -> 0 | AL2: =IF('Wtr-Gas'!X4<0,"0",('Wtr-Gas'!X4)*0.0038) -> 0 | AM2: =IF('Wtr-Gas'!AB4<0,"0",('Wtr-Gas'!AB4)*0.0038) -> 0 | AN2: =IF('Wtr-Gas'!AD4<0,"0",('Wtr-Gas'!AD4)*0.0038) -> 0 | AO2: =IF('Wtr-Gas'!AF4<0,"0",('Wtr-Gas'!AF4)*0.0038) -> 0 | AP2: =IF('Wtr-Gas'!AH4<0,"0",('Wtr-Gas'!AH4)*0.0038) -> 0 | AQ2: =IF('Wtr-Gas'!AJ4<0,"0",('Wtr-Gas'!AJ4)*0.0038) -> 0 | AR2: =IF('Wtr-Gas'!AL4<0,"0",('Wtr-Gas'!AL4)*0.0038) -> 0 | AS2: =IF('Wtr-Gas'!AN4<0,"0",('Wtr-Gas'!AN4)*0.0038) -> 0 | AT2: =IF('Wtr-Gas'!AP4<0,"0",('Wtr-Gas'!AP4)*0.0038) -> 0 | AU2: =IF('Wtr-Gas'!AT4<0,"0",('Wtr-Gas'!AT4)*0.0038) -> 0 | AV2: =IF('Wtr-Gas'!AW4<0,"0",('Wtr-Gas'!AW4)*0.0038) -> 0 | AW2: =IF('Wtr-Gas'!AY4<0,"0",('Wtr-Gas'!AY4)*0.0038) -> 0 | AX2: =IF('Wtr-Gas'!AZ4<0,"0",('Wtr-Gas'!AZ4)*0.0038) -> 0 | AY2: =IF('Wtr-Gas'!BB4<0,"0",('Wtr-Gas'!BB4)*0.0038) -> 0 | AZ2: =IF('Wtr-Gas'!BD4<0,"0",('Wtr-Gas'!BD4)*0.0038) -> 0 | BA2: =IF('Wtr-Gas'!BF4<0,"0",('Wtr-Gas'!BF4)*0.0038) -> 0
A3: Orlando | B3: 3 | C3: 1 | D3: 2022 | E3: =IF(Elect!AL5<0,"0",Elect!AL5) -> 23 | F3: =IF(Elect!I5<0,"0",Elect!I5) -> 14560 | G3: =Elect!H5 -> 2.565 | H3: =IF(Elect!F5<0,"0",Elect!F5) -> 19680 | I3: =Elect!E5 -> 1.923 | J3: =IF(Elect!U5<0,"0",Elect!U5) -> 18300 | K3: =Elect!T5 -> 2.249 | L3: =IF(Elect!AJ5<0,"0",Elect!AJ5) -> 400 | M3: =Elect!AI5 -> 0.297 | N3: =IF(Elect!X5<0,"0",Elect!X5) -> 17700 | O3: =Elect!W5 -> 1.838 | P3: =IF(Elect!O5<0,"0",Elect!O5) -> 3200 | Q3: =Elect!N5 -> 3.73 | R3: =IF(Elect!L5<0,"0",Elect!L5) -> 3600 | S3: =Elect!K5 -> 3.65 | T3: =IF(Elect!R5<0,"0",Elect!R5) -> 3200 | U3: =Elect!Q5 -> 3.73 | V3: =IF(Elect!AA5<0,"0",Elect!AA5) -> 1440 | W3: =Elect!Z5 -> 2.75 | X3: =IF(Elect!AD5<0,"0",Elect!AD5) -> 960 | Y3: =Elect!AC5 -> 2.31 | Z3: =IF(Elect!AG5<0,"0",Elect!AG5) -> 15200 | AA3: =Elect!AF5 -> 2.166 | AB3: =IF(Elect!AX5<0,"0",Elect!AX5) -> 600 | AC3: =IF(Elect!AV5<0,"0",Elect!AV5) -> 6200 | AD3: =IF(Elect!AZ5<0,"0",Elect!AZ5) -> 323 | AE3: =IF(Elect!BB5<0,"0",Elect!BB5) -> 520 | AF3: =IF('Wtr-Gas'!E5<0,"0",('Wtr-Gas'!E5)*0.0038) -> 1415.196 | AG3: =IF('Wtr-Gas'!H5<0,"0",('Wtr-Gas'!H5)*0.0038) -> 246.658 | AH3: =IF('Wtr-Gas'!K5<0,"0",('Wtr-Gas'!K5)*0.0038) -> 0.114 | AI3: =IF('Wtr-Gas'!N5<0,"0",('Wtr-Gas'!N5)*0.0038) -> 1064 | AJ3: =IF('Wtr-Gas'!Q5<0,"0",('Wtr-Gas'!Q5)*0.0038) -> 44.84 | AK3: =IF('Wtr-Gas'!U5<0,"0",('Wtr-Gas'!U5)*0.0038) -> 291.46 | AL3: =IF('Wtr-Gas'!X5<0,"0",('Wtr-Gas'!X5)*0.0038) -> 1133.16 | AM3: =IF('Wtr-Gas'!AB5<0,"0",('Wtr-Gas'!AB5)*0.0038) -> 2470 | AN3: =IF('Wtr-Gas'!AD5<0,"0",('Wtr-Gas'!AD5)*0.0038) -> 657.45358 | AO3: =IF('Wtr-Gas'!AF5<0,"0",('Wtr-Gas'!AF5)*0.0038) -> 2.964 | AP3: =IF('Wtr-Gas'!AH5<0,"0",('Wtr-Gas'!AH5)*0.0038) -> 43.13 | AQ3: =IF('Wtr-Gas'!AJ5<0,"0",('Wtr-Gas'!AJ5)*0.0038) -> 10.4766 | AR3: =IF('Wtr-Gas'!AL5<0,"0",('Wtr-Gas'!AL5)*0.0038) -> 193.8 | AS3: =IF('Wtr-Gas'!AN5<0,"0",('Wtr-Gas'!AN5)*0.0038) -> 0.0114 | AT3: =IF('Wtr-Gas'!AP5<0,"0",('Wtr-Gas'!AP5)*0.0038) -> 3.42 | AU3: =IF('Wtr-Gas'!AT5<0,"0",('Wtr-Gas'!AT5)*0.0038) -> 0.2052 | AV3: =IF('Wtr-Gas'!AW5<0,"0",('Wtr-Gas'!AW5)*0.0038) -> 88.331 | AW3: =IF('Wtr-Gas'!AY5<0,"0",('Wtr-Gas'!AY5)*0.0038) -> 64.104936 | AX3: =IF('Wtr-Gas'!AZ5<0,"0",('Wtr-Gas'!AZ5)*0.0038) -> 24.226064 | AY3: =IF('Wtr-Gas'!BB5<0,"0",('Wtr-Gas'!BB5)*0.0038) -> 1.52 | AZ3: =IF('Wtr-Gas'!BD5<0,"0",('Wtr-Gas'!BD5)*0.0038) -> 0.76 | BA3: =IF('Wtr-Gas'!BF5<0,"0",('Wtr-Gas'!BF5)*0.0038) -> 0.038
A4: Orlando | B4: 10 | C4: 1 | D4: 2022 | E4: =IF(Elect!AL6<0,"0",Elect!AL6) -> 730 | F4: =IF(Elect!I6<0,"0",Elect!I6) -> 51200 | G4: =Elect!H6 -> 2.565 | H4: =IF(Elect!F6<0,"0",Elect!F6) -> 40320 | I4: =Elect!E6 -> 1.923 | J4: =IF(Elect!U6<0,"0",Elect!U6) -> 42000 | K4: =Elect!T6 -> 2.249 | L4: =IF(Elect!AJ6<0,"0",Elect!AJ6) -> 1440 | M4: =Elect!AI6 -> 0.297 | N4: =IF(Elect!X6<0,"0",Elect!X6) -> 33900 | O4: =Elect!W6 -> 1.838 | P4: =IF(Elect!O6<0,"0",Elect!O6) -> 9200 | Q4: =Elect!N6 -> 2.73 | R4: =IF(Elect!L6<0,"0",Elect!L6) -> 10800 | S4: =Elect!K6 -> 3.65 | T4: =IF(Elect!R6<0,"0",Elect!R6) -> 10000 | U4: =Elect!Q6 -> 3.73 | V4: =IF(Elect!AA6<0,"0",Elect!AA6) -> 5440 | W4: =Elect!Z6 -> 3.16 | X4: =IF(Elect!AD6<0,"0",Elect!AD6) -> 3680 | Y4: =Elect!AC6 -> 3.23 | Z4: =IF(Elect!AG6<0,"0",Elect!AG6) -> 54200 | AA4: =Elect!AF6 -> 2.166 | AB4: =IF(Elect!AX6<0,"0",Elect!AX6) -> 1800 | AC4: =IF(Elect!AV6<0,"0",Elect!AV6) -> 13200 | AD4: =IF(Elect!AZ6<0,"0",Elect!AZ6) -> 828 | AE4: =IF(Elect!BB6<0,"0",Elect!BB6) -> 2400 | AF4: =IF('Wtr-Gas'!E6<0,"0",('Wtr-Gas'!E6)*0.0038) -> 4305.134 | AG4: =IF('Wtr-Gas'!H6<0,"0",('Wtr-Gas'!H6)*0.0038) -> 533.026 | AH4: =IF('Wtr-Gas'!K6<0,"0",('Wtr-Gas'!K6)*0.0038) -> 0.798 | AI4: =IF('Wtr-Gas'!N6<0,"0",('Wtr-Gas'!N6)*0.0038) -> 2967.8 | AJ4: =IF('Wtr-Gas'!Q6<0,"0",('Wtr-Gas'!Q6)*0.0038) -> 147.44 | AK4: =IF('Wtr-Gas'!U6<0,"0",('Wtr-Gas'!U6)*0.0038) -> 954.56 | AL4: =IF('Wtr-Gas'!X6<0,"0",('Wtr-Gas'!X6)*0.0038) -> 5631.6 | AM4: =IF('Wtr-Gas'!AB6<0,"0",('Wtr-Gas'!AB6)*0.0038) -> 4864 | AN4: =IF('Wtr-Gas'!AD6<0,"0",('Wtr-Gas'!AD6)*0.0038) -> 1206.006 | AO4: =IF('Wtr-Gas'!AF6<0,"0",('Wtr-Gas'!AF6)*0.0038) -> 10.336 | AP4: =IF('Wtr-Gas'!AH6<0,"0",('Wtr-Gas'!AH6)*0.0038) -> 146.908 | AQ4: =IF('Wtr-Gas'!AJ6<0,"0",('Wtr-Gas'!AJ6)*0.0038) -> 46.607 | AR4: =IF('Wtr-Gas'!AL6<0,"0",('Wtr-Gas'!AL6)*0.0038) -> 752.4 | AS4: =IF('Wtr-Gas'!AN6<0,"0",('Wtr-Gas'!AN6)*0.0038) -> 0.0646 | AT4: =IF('Wtr-Gas'!AP6<0,"0",('Wtr-Gas'!AP6)*0.0038) -> 10.64 | AU4: =IF('Wtr-Gas'!AT6<0,"0",('Wtr-Gas'!AT6)*0.0038) -> 0.494 | AV4: =IF('Wtr-Gas'!AW6<0,"0",('Wtr-Gas'!AW6)*0.0038) -> 195.0198 | AW4: =IF('Wtr-Gas'!AY6<0,"0",('Wtr-Gas'!AY6)*0.0038) -> 150.3109 | AX4: =IF('Wtr-Gas'!AZ6<0,"0",('Wtr-Gas'!AZ6)*0.0038) -> 44.7089 | AY4: =IF('Wtr-Gas'!BB6<0,"0",('Wtr-Gas'!BB6)*0.0038) -> 20.14 | AZ4: =IF('Wtr-Gas'!BD6<0,"0",('Wtr-Gas'!BD6)*0.0038) -> 1.14 | BA4: =IF('Wtr-Gas'!BF6<0,"0",('Wtr-Gas'!BF6)*0.0038) -> 0.171
A5: Orlando | B5: 17 | C5: 1 | D5: 2022 | E5: =IF(Elect!AL7<0,"0",Elect!AL7) -> 661 | F5: =IF(Elect!I7<0,"0",Elect!I7) -> 53280 | G5: =Elect!H7 -> 2.565 | H5: =IF(Elect!F7<0,"0",Elect!F7) -> 42560 | I5: =Elect!E7 -> 1.961 | J5: =IF(Elect!U7<0,"0",Elect!U7) -> 44400 | K5: =Elect!T7 -> 2.249 | L5: =IF(Elect!AJ7<0,"0",Elect!AJ7) -> 1520 | M5: =Elect!AI7 -> 0.297 | N5: =IF(Elect!X7<0,"0",Elect!X7) -> 30900 | O5: =Elect!W7 -> 1.838 | P5: =IF(Elect!O7<0,"0",Elect!O7) -> 10400 | Q5: =Elect!N7 -> 2.73 | R5: =IF(Elect!L7<0,"0",Elect!L7) -> 11200 | S5: =Elect!K7 -> 3.65 | T5: =IF(Elect!R7<0,"0",Elect!R7) -> 11600 | U5: =Elect!Q7 -> 3.73 | V5: =IF(Elect!AA7<0,"0",Elect!AA7) -> 6080 | W5: =Elect!Z7 -> 3.18 | X5: =IF(Elect!AD7<0,"0",Elect!AD7) -> 3840 | Y5: =Elect!AC7 -> 3.23 | Z5: =IF(Elect!AG7<0,"0",Elect!AG7) -> 55600 | AA5: =Elect!AF7 -> 2.166 | AB5: =IF(Elect!AX7<0,"0",Elect!AX7) -> 1600 | AC5: =IF(Elect!AV7<0,"0",Elect!AV7) -> 10900 | AD5: =IF(Elect!AZ7<0,"0",Elect!AZ7) -> 698 | AE5: =IF(Elect!BB7<0,"0",Elect!BB7) -> 1840 | AF5: =IF('Wtr-Gas'!E7<0,"0",('Wtr-Gas'!E7)*0.0038) -> 4065.468 | AG5: =IF('Wtr-Gas'!H7<0,"0",('Wtr-Gas'!H7)*0.0038) -> 366.738 | AH5: =IF('Wtr-Gas'!K7<0,"0",('Wtr-Gas'!K7)*0.0038) -> 1.52 | AI5: =IF('Wtr-Gas'!N7<0,"0",('Wtr-Gas'!N7)*0.0038) -> 2694.2 | AJ5: =IF('Wtr-Gas'!Q7<0,"0",('Wtr-Gas'!Q7)*0.0038) -> 148.96 | AK5: =IF('Wtr-Gas'!U7<0,"0",('Wtr-Gas'!U7)*0.0038) -> 943.54 | AL5: =IF('Wtr-Gas'!X7<0,"0",('Wtr-Gas'!X7)*0.0038) -> 7224.94 | AM5: =IF('Wtr-Gas'!AB7<0,"0",('Wtr-Gas'!AB7)*0.0038) -> 3724 | AN5: =IF('Wtr-Gas'!AD7<0,"0",('Wtr-Gas'!AD7)*0.0038) -> 992.78724 | AO5: =IF('Wtr-Gas'!AF7<0,"0",('Wtr-Gas'!AF7)*0.0038) -> 9.5 | AP5: =IF('Wtr-Gas'!AH7<0,"0",('Wtr-Gas'!AH7)*0.0038) -> 72.504 | AQ5: =IF('Wtr-Gas'!AJ7<0,"0",('Wtr-Gas'!AJ7)*0.0038) -> 50.7186 | AR5: =IF('Wtr-Gas'!AL7<0,"0",('Wtr-Gas'!AL7)*0.0038) -> 820.8 | AS5: =IF('Wtr-Gas'!AN7<0,"0",('Wtr-Gas'!AN7)*0.0038) -> 0.0722 | AT5: =IF('Wtr-Gas'!AP7<0,"0",('Wtr-Gas'!AP7)*0.0038) -> 12.16 | AU5: =IF('Wtr-Gas'!AT7<0,"0",('Wtr-Gas'!AT7)*0.0038) -> 0.3838 | AV5: =IF('Wtr-Gas'!AW7<0,"0",('Wtr-Gas'!AW7)*0.0038) -> 196.555 | AW5: =IF('Wtr-Gas'!AY7<0,"0",('Wtr-Gas'!AY7)*0.0038) -> 150.14393 | AX5: =IF('Wtr-Gas'!AZ7<0,"0",('Wtr-Gas'!AZ7)*0.0038) -> 46.411072 | AY5: =IF('Wtr-Gas'!BB7<0,"0",('Wtr-Gas'!BB7)*0.0038) -> 17.1 | AZ5: =IF('Wtr-Gas'!BD7<0,"0",('Wtr-Gas'!BD7)*0.0038) -> 1.14 | BA5: =IF('Wtr-Gas'!BF7<0,"0",('Wtr-Gas'!BF7)*0.0038) -> 0.3192
A6: Orlando | B6: 24 | C6: 1 | D6: 2022 | E6: =IF(Elect!AL8<0,"0",Elect!AL8) -> 558 | F6: =IF(Elect!I8<0,"0",Elect!I8) -> 51680 | G6: =Elect!H8 -> 2.403 | H6: =IF(Elect!F8<0,"0",Elect!F8) -> 41600 | I6: =Elect!E8 -> 1.86 | J6: =IF(Elect!U8<0,"0",Elect!U8) -> 32700 | K6: =Elect!T8 -> 2.249 | L6: =IF(Elect!AJ8<0,"0",Elect!AJ8) -> 1480 | M6: =Elect!AI8 -> 0.292 | N6: =IF(Elect!X8<0,"0",Elect!X8) -> 35700 | O6: =Elect!W8 -> 1.838 | P6: =IF(Elect!O8<0,"0",Elect!O8) -> 12000 | Q6: =Elect!N8 -> 2.85 | R6: =IF(Elect!L8<0,"0",Elect!L8) -> 13600 | S6: =Elect!K8 -> 3.25 | T6: =IF(Elect!R8<0,"0",Elect!R8) -> 13200 | U6: =Elect!Q8 -> 3.1 | V6: =IF(Elect!AA8<0,"0",Elect!AA8) -> 6080 | W6: =Elect!Z8 -> 2.99 | X6: =IF(Elect!AD8<0,"0",Elect!AD8) -> 4480 | Y6: =Elect!AC8 -> 2.45 | Z6: =IF(Elect!AG8<0,"0",Elect!AG8) -> 54000 | AA6: =Elect!AF8 -> 2.111 | AB6: =IF(Elect!AX8<0,"0",Elect!AX8) -> 1800 | AC6: =IF(Elect!AV8<0,"0",Elect!AV8) -> 9500 | AD6: =IF(Elect!AZ8<0,"0",Elect!AZ8) -> 731 | AE6: =IF(Elect!BB8<0,"0",Elect!BB8) -> 1200 | AF6: =IF('Wtr-Gas'!E8<0,"0",('Wtr-Gas'!E8)*0.0038) -> 4070.294 | AG6: =IF('Wtr-Gas'!H8<0,"0",('Wtr-Gas'!H8)*0.0038) -> 244.644 | AH6: =IF('Wtr-Gas'!K8<0,"0",('Wtr-Gas'!K8)*0.0038) -> 1.824 | AI6: =IF('Wtr-Gas'!N8<0,"0",('Wtr-Gas'!N8)*0.0038) -> 2850 | AJ6: =IF('Wtr-Gas'!Q8<0,"0",('Wtr-Gas'!Q8)*0.0038) -> 132.62 | AK6: =IF('Wtr-Gas'!U8<0,"0",('Wtr-Gas'!U8)*0.0038) -> 1027.14 | AL6: =IF('Wtr-Gas'!X8<0,"0",('Wtr-Gas'!X8)*0.0038) -> 7766.06 | AM6: =IF('Wtr-Gas'!AB8<0,"0",('Wtr-Gas'!AB8)*0.0038) -> 2698 | AN6: =IF('Wtr-Gas'!AD8<0,"0",('Wtr-Gas'!AD8)*0.0038) -> 703.15276 | AO6: =IF('Wtr-Gas'!AF8<0,"0",('Wtr-Gas'!AF8)*0.0038) -> 12.654 | AP6: =IF('Wtr-Gas'!AH8<0,"0",('Wtr-Gas'!AH8)*0.0038) -> 249.318 | AQ6: =IF('Wtr-Gas'!AJ8<0,"0",('Wtr-Gas'!AJ8)*0.0038) -> 38.7676 | AR6: =IF('Wtr-Gas'!AL8<0,"0",('Wtr-Gas'!AL8)*0.0038) -> 509.2 | AS6: =IF('Wtr-Gas'!AN8<0,"0",('Wtr-Gas'!AN8)*0.0038) -> 0.076 | AT6: =IF('Wtr-Gas'!AP8<0,"0",('Wtr-Gas'!AP8)*0.0038) -> 10.26 | AU6: =IF('Wtr-Gas'!AT8<0,"0",('Wtr-Gas'!AT8)*0.0038) -> 0.5472 | AV6: =IF('Wtr-Gas'!AW8<0,"0",('Wtr-Gas'!AW8)*0.0038) -> 195.8938 | AW6: =IF('Wtr-Gas'!AY8<0,"0",('Wtr-Gas'!AY8)*0.0038) -> 153.02 | AX6: =IF('Wtr-Gas'!AZ8<0,"0",('Wtr-Gas'!AZ8)*0.0038) -> 42.873804 | AY6: =IF('Wtr-Gas'!BB8<0,"0",('Wtr-Gas'!BB8)*0.0038) -> 8.74 | AZ6: =IF('Wtr-Gas'!BD8<0,"0",('Wtr-Gas'!BD8)*0.0038) -> 1.14 | BA6: =IF('Wtr-Gas'!BF8<0,"0",('Wtr-Gas'!BF8)*0.0038) -> 0
A7: Orlando | B7: 31 | C7: 1 | D7: 2022 | E7: =IF(Elect!AL9<0,"0",Elect!AL9) -> 401 | F7: =IF(Elect!I9<0,"0",Elect!I9) -> 50720 | G7: =Elect!H9 -> 2.478 | H7: =IF(Elect!F9<0,"0",Elect!F9) -> 41280 | I7: =Elect!E9 -> 1.906 | J7: =IF(Elect!U9<0,"0",Elect!U9) -> 24600 | K7: =Elect!T9 -> 1.359 | L7: =IF(Elect!AJ9<0,"0",Elect!AJ9) -> 1400 | M7: =Elect!AI9 -> 0.292 | N7: =IF(Elect!X9<0,"0",Elect!X9) -> 30600 | O7: =Elect!W9 -> 0.98 | P7: =IF(Elect!O9<0,"0",Elect!O9) -> 11200 | Q7: =Elect!N9 -> 2.96 | R7: =IF(Elect!L9<0,"0",Elect!L9) -> 12400 | S7: =Elect!K9 -> 3.25 | T7: =IF(Elect!R9<0,"0",Elect!R9) -> 11200 | U7: =Elect!Q9 -> 3.1 | V7: =IF(Elect!AA9<0,"0",Elect!AA9) -> 5440 | W7: =Elect!Z9 -> 3.25 | X7: =IF(Elect!AD9<0,"0",Elect!AD9) -> 3200 | Y7: =Elect!AC9 -> 2.85 | Z7: =IF(Elect!AG9<0,"0",Elect!AG9) -> 53200 | AA7: =Elect!AF9 -> 2.186 | AB7: =IF(Elect!AX9<0,"0",Elect!AX9) -> 1600 | AC7: =IF(Elect!AV9<0,"0",Elect!AV9) -> 12700 | AD7: =IF(Elect!AZ9<0,"0",Elect!AZ9) -> 821 | AE7: =IF(Elect!BB9<0,"0",Elect!BB9) -> 1440 | AF7: =IF('Wtr-Gas'!E9<0,"0",('Wtr-Gas'!E9)*0.0038) -> 3572.19 | AG7: =IF('Wtr-Gas'!H9<0,"0",('Wtr-Gas'!H9)*0.0038) -> 30.058 | AH7: =IF('Wtr-Gas'!K9<0,"0",('Wtr-Gas'!K9)*0.0038) -> 0.532 | AI7: =IF('Wtr-Gas'!N9<0,"0",('Wtr-Gas'!N9)*0.0038) -> 2078.6 | AJ7: =IF('Wtr-Gas'!Q9<0,"0",('Wtr-Gas'!Q9)*0.0038) -> 139.08 | AK7: =IF('Wtr-Gas'!U9<0,"0",('Wtr-Gas'!U9)*0.0038) -> 953.42 | AL7: =IF('Wtr-Gas'!X9<0,"0",('Wtr-Gas'!X9)*0.0038) -> 8128.2 | AM7: =IF('Wtr-Gas'!AB9<0,"0",('Wtr-Gas'!AB9)*0.0038) -> 1862 | AN7: =IF('Wtr-Gas'!AD9<0,"0",('Wtr-Gas'!AD9)*0.0038) -> 542.53284 | AO7: =IF('Wtr-Gas'!AF9<0,"0",('Wtr-Gas'!AF9)*0.0038) -> 8.702 | AP7: =IF('Wtr-Gas'!AH9<0,"0",('Wtr-Gas'!AH9)*0.0038) -> 194.636 | AQ7: =IF('Wtr-Gas'!AJ9<0,"0",('Wtr-Gas'!AJ9)*0.0038) -> 45.1402 | AR7: =IF('Wtr-Gas'!AL9<0,"0",('Wtr-Gas'!AL9)*0.0038) -> 805.6 | AS7: =IF('Wtr-Gas'!AN9<0,"0",('Wtr-Gas'!AN9)*0.0038) -> 0.0988 | AT7: =IF('Wtr-Gas'!AP9<0,"0",('Wtr-Gas'!AP9)*0.0038) -> 11.78 | AU7: =IF('Wtr-Gas'!AT9<0,"0",('Wtr-Gas'!AT9)*0.0038) -> 0.7106 | AV7: =IF('Wtr-Gas'!AW9<0,"0",('Wtr-Gas'!AW9)*0.0038) -> 197.3416 | AW7: =IF('Wtr-Gas'!AY9<0,"0",('Wtr-Gas'!AY9)*0.0038) -> 151.64124 | AX7: =IF('Wtr-Gas'!AZ9<0,"0",('Wtr-Gas'!AZ9)*0.0038) -> 45.700358 | AY7: =IF('Wtr-Gas'!BB9<0,"0",('Wtr-Gas'!BB9)*0.0038) -> 12.16 | AZ7: =IF('Wtr-Gas'!BD9<0,"0",('Wtr-Gas'!BD9)*0.0038) -> 1.14 | BA7: =IF('Wtr-Gas'!BF9<0,"0",('Wtr-Gas'!BF9)*0.0038) -> 0.6004
A8: Orlando | B8: 7 | C8: 2 | D8: 2022 | E8: =IF(Elect!AL10<0,"0",Elect!AL10) -> 995 | F8: =IF(Elect!I10<0,"0",Elect!I10) -> 48800 | G8: =Elect!H10 -> 2.478 | H8: =IF(Elect!F10<0,"0",Elect!F10) -> 40640 | I8: =Elect!E10 -> 1.908 | J8: =IF(Elect!U10<0,"0",Elect!U10) -> 37800 | K8: =Elect!T10 -> 2.01 | L8: =IF(Elect!AJ10<0,"0",Elect!AJ10) -> 1400 | M8: =Elect!AI10 -> 0.301 | N8: =IF(Elect!X10<0,"0",Elect!X10) -> 41400 | O8: =Elect!W10 -> 1.737 | P8: =IF(Elect!O10<0,"0",Elect!O10) -> 10800 | Q8: =Elect!N10 -> 2.96 | R8: =IF(Elect!L10<0,"0",Elect!L10) -> 10800 | S8: =Elect!K10 -> 3.25 | T8: =IF(Elect!R10<0,"0",Elect!R10) -> 10800 | U8: =Elect!Q10 -> 3.1 | V8: =IF(Elect!AA10<0,"0",Elect!AA10) -> 5920 | W8: =Elect!Z10 -> 3.25 | X8: =IF(Elect!AD10<0,"0",Elect!AD10) -> 4160 | Y8: =Elect!AC10 -> 3.15 | Z8: =IF(Elect!AG10<0,"0",Elect!AG10) -> 52000 | AA8: =Elect!AF10 -> 2.186 | AB8: =IF(Elect!AX10<0,"0",Elect!AX10) -> 1400 | AC8: =IF(Elect!AV10<0,"0",Elect!AV10) -> 11500 | AD8: =IF(Elect!AZ10<0,"0",Elect!AZ10) -> 725 | AE8: =IF(Elect!BB10<0,"0",Elect!BB10) -> 2360 | AF8: =IF('Wtr-Gas'!E10<0,"0",('Wtr-Gas'!E10)*0.0038) -> 4160.392 | AG8: =IF('Wtr-Gas'!H10<0,"0",('Wtr-Gas'!H10)*0.0038) -> 363.964 | AH8: =IF('Wtr-Gas'!K10<0,"0",('Wtr-Gas'!K10)*0.0038) -> 1.672 | AI8: =IF('Wtr-Gas'!N10<0,"0",('Wtr-Gas'!N10)*0.0038) -> 2774 | AJ8: =IF('Wtr-Gas'!Q10<0,"0",('Wtr-Gas'!Q10)*0.0038) -> 145.54 | AK8: =IF('Wtr-Gas'!U10<0,"0",('Wtr-Gas'!U10)*0.0038) -> 953.04 | AL8: =IF('Wtr-Gas'!X10<0,"0",('Wtr-Gas'!X10)*0.0038) -> 6262.4 | AM8: =IF('Wtr-Gas'!AB10<0,"0",('Wtr-Gas'!AB10)*0.0038) -> 4636 | AN8: =IF('Wtr-Gas'!AD10<0,"0",('Wtr-Gas'!AD10)*0.0038) -> 1138.2452 | AO8: =IF('Wtr-Gas'!AF10<0,"0",('Wtr-Gas'!AF10)*0.0038) -> 13.3 | AP8: =IF('Wtr-Gas'!AH10<0,"0",('Wtr-Gas'!AH10)*0.0038) -> 244.53 | AQ8: =IF('Wtr-Gas'!AJ10<0,"0",('Wtr-Gas'!AJ10)*0.0038) -> 47.1352 | AR8: =IF('Wtr-Gas'!AL10<0,"0",('Wtr-Gas'!AL10)*0.0038) -> 646 | AS8: =IF('Wtr-Gas'!AN10<0,"0",('Wtr-Gas'!AN10)*0.0038) -> 0.0494 | AT8: =IF('Wtr-Gas'!AP10<0,"0",('Wtr-Gas'!AP10)*0.0038) -> 10.26 | AU8: =IF('Wtr-Gas'!AT10<0,"0",('Wtr-Gas'!AT10)*0.0038) -> 0.475 | AV8: =IF('Wtr-Gas'!AW10<0,"0",('Wtr-Gas'!AW10)*0.0038) -> 190.3344 | AW8: =IF('Wtr-Gas'!AY10<0,"0",('Wtr-Gas'!AY10)*0.0038) -> 148.11743 | AX8: =IF('Wtr-Gas'!AZ10<0,"0",('Wtr-Gas'!AZ10)*0.0038) -> 42.216974 | AY8: =IF('Wtr-Gas'!BB10<0,"0",('Wtr-Gas'!BB10)*0.0038) -> 9.12 | AZ8: =IF('Wtr-Gas'!BD10<0,"0",('Wtr-Gas'!BD10)*0.0038) -> 1.52 | BA8: =IF('Wtr-Gas'!BF10<0,"0",('Wtr-Gas'!BF10)*0.0038) -> 0.2014
A9: Orlando | B9: 14 | C9: 2 | D9: 2022 | E9: =IF(Elect!AL11<0,"0",Elect!AL11) -> 0 | F9: =IF(Elect!I11<0,"0",Elect!I11) -> 50880 | G9: =Elect!H11 -> 2.478 | H9: =IF(Elect!F11<0,"0",Elect!F11) -> 41280 | I9: =Elect!E11 -> 1.938 | J9: =IF(Elect!U11<0,"0",Elect!U11) -> 42000 | K9: =Elect!T11 -> 2.01 | L9: =IF(Elect!AJ11<0,"0",Elect!AJ11) -> 1440 | M9: =Elect!AI11 -> 0.301 | N9: =IF(Elect!X11<0,"0",Elect!X11) -> 26100 | O9: =Elect!W11 -> 1.737 | P9: =IF(Elect!O11<0,"0",Elect!O11) -> 10000 | Q9: =Elect!N11 -> 2.96 | R9: =IF(Elect!L11<0,"0",Elect!L11) -> 1600 | S9: =Elect!K11 -> 3.25 | T9: =IF(Elect!R11<0,"0",Elect!R11) -> 10000 | U9: =Elect!Q11 -> 3.1 | V9: =IF(Elect!AA11<0,"0",Elect!AA11) -> 5760 | W9: =Elect!Z11 -> 3.25 | X9: =IF(Elect!AD11<0,"0",Elect!AD11) -> 3360 | Y9: =Elect!AC11 -> 3.15 | Z9: =IF(Elect!AG11<0,"0",Elect!AG11) -> 52800 | AA9: =Elect!AF11 -> 2.186 | AB9: =IF(Elect!AX11<0,"0",Elect!AX11) -> 1700 | AC9: =IF(Elect!AV11<0,"0",Elect!AV11) -> 11200 | AD9: =IF(Elect!AZ11<0,"0",Elect!AZ11) -> 772 | AE9: =IF(Elect!BB11<0,"0",Elect!BB11) -> 1640 | AF9: =IF('Wtr-Gas'!E11<0,"0",('Wtr-Gas'!E11)*0.0038) -> 4025.264 | AG9: =IF('Wtr-Gas'!H11<0,"0",('Wtr-Gas'!H11)*0.0038) -> 268.622 | AH9: =IF('Wtr-Gas'!K11<0,"0",('Wtr-Gas'!K11)*0.0038) -> 1.216 | AI9: =IF('Wtr-Gas'!N11<0,"0",('Wtr-Gas'!N11)*0.0038) -> 2606.8 | AJ9: =IF('Wtr-Gas'!Q11<0,"0",('Wtr-Gas'!Q11)*0.0038) -> 144.02 | AK9: =IF('Wtr-Gas'!U11<0,"0",('Wtr-Gas'!U11)*0.0038) -> 929.1 | AL9: =IF('Wtr-Gas'!X11<0,"0",('Wtr-Gas'!X11)*0.0038) -> 3192 | AM9: =IF('Wtr-Gas'!AB11<0,"0",('Wtr-Gas'!AB11)*0.0038) -> 2926 | AN9: =IF('Wtr-Gas'!AD11<0,"0",('Wtr-Gas'!AD11)*0.0038) -> 894.444 | AO9: =IF('Wtr-Gas'!AF11<0,"0",('Wtr-Gas'!AF11)*0.0038) -> 23.522 | AP9: =IF('Wtr-Gas'!AH11<0,"0",('Wtr-Gas'!AH11)*0.0038) -> 293.892 | AQ9: =IF('Wtr-Gas'!AJ11<0,"0",('Wtr-Gas'!AJ11)*0.0038) -> 43.7076 | AR9: =IF('Wtr-Gas'!AL11<0,"0",('Wtr-Gas'!AL11)*0.0038) -> 687.8 | AS9: =IF('Wtr-Gas'!AN11<0,"0",('Wtr-Gas'!AN11)*0.0038) -> 0.076 | AT9: =IF('Wtr-Gas'!AP11<0,"0",('Wtr-Gas'!AP11)*0.0038) -> 7.22 | AU9: =IF('Wtr-Gas'!AT11<0,"0",('Wtr-Gas'!AT11)*0.0038) -> 0.5472 | AV9: =IF('Wtr-Gas'!AW11<0,"0",('Wtr-Gas'!AW11)*0.0038) -> 189.8328 | AW9: =IF('Wtr-Gas'!AY11<0,"0",('Wtr-Gas'!AY11)*0.0038) -> 150.72305 | AX9: =IF('Wtr-Gas'!AZ11<0,"0",('Wtr-Gas'!AZ11)*0.0038) -> 39.109752 | AY9: =IF('Wtr-Gas'!BB11<0,"0",('Wtr-Gas'!BB11)*0.0038) -> 13.68 | AZ9: =IF('Wtr-Gas'!BD11<0,"0",('Wtr-Gas'!BD11)*0.0038) -> 1.14 | BA9: =IF('Wtr-Gas'!BF11<0,"0",('Wtr-Gas'!BF11)*0.0038) -> 0.0304
A10: Orlando | B10: 21 | C10: 2 | D10: 2022 | E10: =IF(Elect!AL12<0,"0",Elect!AL12) -> 534 | F10: =IF(Elect!I12<0,"0",Elect!I12) -> 52960 | G10: =Elect!H12 -> 2.478 | H10: =IF(Elect!F12<0,"0",Elect!F12) -> 43520 | I10: =Elect!E12 -> 1.938 | J10: =IF(Elect!U12<0,"0",Elect!U12) -> 57000 | K10: =Elect!T12 -> 2.221 | L10: =IF(Elect!AJ12<0,"0",Elect!AJ12) -> 1480 | M10: =Elect!AI12 -> 0.301 | N10: =IF(Elect!X12<0,"0",Elect!X12) -> 34500 | O10: =Elect!W12 -> 1.737 | P10: =IF(Elect!O12<0,"0",Elect!O12) -> 11600 | Q10: =Elect!N12 -> 2.96 | R10: =IF(Elect!L12<0,"0",Elect!L12) -> 22000 | S10: =Elect!K12 -> 3.25 | T10: =IF(Elect!R12<0,"0",Elect!R12) -> 11600 | U10: =Elect!Q12 -> 3.1 | V10: =IF(Elect!AA12<0,"0",Elect!AA12) -> 6080 | W10: =Elect!Z12 -> 3.25 | X10: =IF(Elect!AD12<0,"0",Elect!AD12) -> 3840 | Y10: =Elect!AC12 -> 3.15 | Z10: =IF(Elect!AG12<0,"0",Elect!AG12) -> 55000 | AA10: =Elect!AF12 -> 2.186 | AB10: =IF(Elect!AX12<0,"0",Elect!AX12) -> 1500 | AC10: =IF(Elect!AV12<0,"0",Elect!AV12) -> 12300 | AD10: =IF(Elect!AZ12<0,"0",Elect!AZ12) -> 755 | AE10: =IF(Elect!BB12<0,"0",Elect!BB12) -> 2760 | AF10: =IF('Wtr-Gas'!E12<0,"0",('Wtr-Gas'!E12)*0.0038) -> 5169.9 | AG10: =IF('Wtr-Gas'!H12<0,"0",('Wtr-Gas'!H12)*0.0038) -> 430.388 | AH10: =IF('Wtr-Gas'!K12<0,"0",('Wtr-Gas'!K12)*0.0038) -> 1.178 | AI10: =IF('Wtr-Gas'!N12<0,"0",('Wtr-Gas'!N12)*0.0038) -> 3739.2 | AJ10: =IF('Wtr-Gas'!Q12<0,"0",('Wtr-Gas'!Q12)*0.0038) -> 108.68 | AK10: =IF('Wtr-Gas'!U12<0,"0",('Wtr-Gas'!U12)*0.0038) -> 1008.52 | AL10: =IF('Wtr-Gas'!X12<0,"0",('Wtr-Gas'!X12)*0.0038) -> 9800.2 | AM10: =IF('Wtr-Gas'!AB12<0,"0",('Wtr-Gas'!AB12)*0.0038) -> 5700 | AN10: =IF('Wtr-Gas'!AD12<0,"0",('Wtr-Gas'!AD12)*0.0038) -> 1468.2292 | AO10: =IF('Wtr-Gas'!AF12<0,"0",('Wtr-Gas'!AF12)*0.0038) -> 18.772 | AP10: =IF('Wtr-Gas'!AH12<0,"0",('Wtr-Gas'!AH12)*0.0038) -> 333.83 | AQ10: =IF('Wtr-Gas'!AJ12<0,"0",('Wtr-Gas'!AJ12)*0.0038) -> 42.9628 | AR10: =IF('Wtr-Gas'!AL12<0,"0",('Wtr-Gas'!AL12)*0.0038) -> 516.8 | AS10: =IF('Wtr-Gas'!AN12<0,"0",('Wtr-Gas'!AN12)*0.0038) -> 0.0494 | AT10: =IF('Wtr-Gas'!AP12<0,"0",('Wtr-Gas'!AP12)*0.0038) -> 10.64 | AU10: =IF('Wtr-Gas'!AT12<0,"0",('Wtr-Gas'!AT12)*0.0038) -> 0.475 | AV10: =IF('Wtr-Gas'!AW12<0,"0",('Wtr-Gas'!AW12)*0.0038) -> 200.963 | AW10: =IF('Wtr-Gas'!AY12<0,"0",('Wtr-Gas'!AY12)*0.0038) -> 148.43423 | AX10: =IF('Wtr-Gas'!AZ12<0,"0",('Wtr-Gas'!AZ12)*0.0038) -> 52.528768 | AY10: =IF('Wtr-Gas'!BB12<0,"0",('Wtr-Gas'!BB12)*0.0038) -> 11.78 | AZ10: =IF('Wtr-Gas'!BD12<0,"0",('Wtr-Gas'!BD12)*0.0038) -> 1.14 | BA10: =IF('Wtr-Gas'!BF12<0,"0",('Wtr-Gas'!BF12)*0.0038) -> 0.1254
A11: Orlando | B11: 28 | C11: 2 | D11: 2022 | E11: =IF(Elect!AL13<0,"0",Elect!AL13) -> 622 | F11: =IF(Elect!I13<0,"0",Elect!I13) -> 52160 | G11: =Elect!H13 -> 2.288 | H11: =IF(Elect!F13<0,"0",Elect!F13) -> 42400 | I11: =Elect!E13 -> 1.894 | J11: =IF(Elect!U13<0,"0",Elect!U13) -> 52200 | K11: =Elect!T13 -> 1.589 | L11: =IF(Elect!AJ13<0,"0",Elect!AJ13) -> 1440 | M11: =Elect!AI13 -> 2.81 | N11: =IF(Elect!X13<0,"0",Elect!X13) -> 72000 | O11: =Elect!W13 -> 1.884 | P11: =IF(Elect!O13<0,"0",Elect!O13) -> 11200 | Q11: =Elect!N13 -> 2.28 | R11: =IF(Elect!L13<0,"0",Elect!L13) -> 12800 | S11: =Elect!K13 -> 2.41 | T11: =IF(Elect!R13<0,"0",Elect!R13) -> 11200 | U11: =Elect!Q13 -> 2.08 | V11: =IF(Elect!AA13<0,"0",Elect!AA13) -> 6560 | W11: =Elect!Z13 -> 3.72 | X11: =IF(Elect!AD13<0,"0",Elect!AD13) -> 4000 | Y11: =Elect!AC13 -> 2.66 | Z11: =IF(Elect!AG13<0,"0",Elect!AG13) -> 57400 | AA11: =Elect!AF13 -> 2.141 | AB11: =IF(Elect!AX13<0,"0",Elect!AX13) -> 1600 | AC11: =IF(Elect!AV13<0,"0",Elect!AV13) -> 14600 | AD11: =IF(Elect!AZ13<0,"0",Elect!AZ13) -> 808 | AE11: =IF(Elect!BB13<0,"0",Elect!BB13) -> 3720 | AF11: =IF('Wtr-Gas'!E13<0,"0",('Wtr-Gas'!E13)*0.0038) -> 5539.602 | AG11: =IF('Wtr-Gas'!H13<0,"0",('Wtr-Gas'!H13)*0.0038) -> 542.716 | AH11: =IF('Wtr-Gas'!K13<0,"0",('Wtr-Gas'!K13)*0.0038) -> 4.37 | AI11: =IF('Wtr-Gas'!N13<0,"0",('Wtr-Gas'!N13)*0.0038) -> 4164.8 | AJ11: =IF('Wtr-Gas'!Q13<0,"0",('Wtr-Gas'!Q13)*0.0038) -> 99.94 | AK11: =IF('Wtr-Gas'!U13<0,"0",('Wtr-Gas'!U13)*0.0038) -> 964.82 | AL11: =IF('Wtr-Gas'!X13<0,"0",('Wtr-Gas'!X13)*0.0038) -> 3901.84 | AM11: =IF('Wtr-Gas'!AB13<0,"0",('Wtr-Gas'!AB13)*0.0038) -> 8816 | AN11: =IF('Wtr-Gas'!AD13<0,"0",('Wtr-Gas'!AD13)*0.0038) -> 2391.5011 | AO11: =IF('Wtr-Gas'!AF13<0,"0",('Wtr-Gas'!AF13)*0.0038) -> 15.01 | AP11: =IF('Wtr-Gas'!AH13<0,"0",('Wtr-Gas'!AH13)*0.0038) -> 372.438 | AQ11: =IF('Wtr-Gas'!AJ13<0,"0",('Wtr-Gas'!AJ13)*0.0038) -> 50.9086 | AR11: =IF('Wtr-Gas'!AL13<0,"0",('Wtr-Gas'!AL13)*0.0038) -> 425.6 | AS11: =IF('Wtr-Gas'!AN13<0,"0",('Wtr-Gas'!AN13)*0.0038) -> 0.0418 | AT11: =IF('Wtr-Gas'!AP13<0,"0",('Wtr-Gas'!AP13)*0.0038) -> 7.6 | AU11: =IF('Wtr-Gas'!AT13<0,"0",('Wtr-Gas'!AT13)*0.0038) -> 0.456 | AV11: =IF('Wtr-Gas'!AW13<0,"0",('Wtr-Gas'!AW13)*0.0038) -> 192.4548 | AW11: =IF('Wtr-Gas'!AY13<0,"0",('Wtr-Gas'!AY13)*0.0038) -> 148.08828 | AX11: =IF('Wtr-Gas'!AZ13<0,"0",('Wtr-Gas'!AZ13)*0.0038) -> 44.36652 | AY11: =IF('Wtr-Gas'!BB13<0,"0",('Wtr-Gas'!BB13)*0.0038) -> 6.46 | AZ11: =IF('Wtr-Gas'!BD13<0,"0",('Wtr-Gas'!BD13)*0.0038) -> 1.9 | BA11: =IF('Wtr-Gas'!BF13<0,"0",('Wtr-Gas'!BF13)*0.0038) -> 0.0988
A12: Orlando | B12: 7 | C12: 3 | D12: 2022 | E12: =IF(Elect!AL14<0,"0",Elect!AL14) -> 503 | F12: =IF(Elect!I14<0,"0",Elect!I14) -> 49600 | G12: =Elect!H14 -> 2.39 | H12: =IF(Elect!F14<0,"0",Elect!F14) -> 40000 | I12: =Elect!E14 -> 1.969 | J12: =IF(Elect!U14<0,"0",Elect!U14) -> 45900 | K12: =Elect!T14 -> 1.749 | L12: =IF(Elect!AJ14<0,"0",Elect!AJ14) -> 1320 | M12: =Elect!AI14 -> 2.81 | N12: =IF(Elect!X14<0,"0",Elect!X14) -> 45300 | O12: =Elect!W14 -> 1.884 | P12: =IF(Elect!O14<0,"0",Elect!O14) -> 10400 | Q12: =Elect!N14 -> 2.28 | R12: =IF(Elect!L14<0,"0",Elect!L14) -> 11200 | S12: =Elect!K14 -> 2.79 | T12: =IF(Elect!R14<0,"0",Elect!R14) -> 10400 | U12: =Elect!Q14 -> 2.34 | V12: =IF(Elect!AA14<0,"0",Elect!AA14) -> 5920 | W12: =Elect!Z14 -> 3.72 | X12: =IF(Elect!AD14<0,"0",Elect!AD14) -> 4160 | Y12: =Elect!AC14 -> 2.79 | Z12: =IF(Elect!AG14<0,"0",Elect!AG14) -> 54400 | AA12: =Elect!AF14 -> 2.272 | AB12: =IF(Elect!AX14<0,"0",Elect!AX14) -> 1400 | AC12: =IF(Elect!AV14<0,"0",Elect!AV14) -> 13500 | AD12: =IF(Elect!AZ14<0,"0",Elect!AZ14) -> 740 | AE12: =IF(Elect!BB14<0,"0",Elect!BB14) -> 2560 | AF12: =IF('Wtr-Gas'!E14<0,"0",('Wtr-Gas'!E14)*0.0038) -> 4951.02 | AG12: =IF('Wtr-Gas'!H14<0,"0",('Wtr-Gas'!H14)*0.0038) -> 532.836 | AH12: =IF('Wtr-Gas'!K14<0,"0",('Wtr-Gas'!K14)*0.0038) -> 0.988 | AI12: =IF('Wtr-Gas'!N14<0,"0",('Wtr-Gas'!N14)*0.0038) -> 3986.2 | AJ12: =IF('Wtr-Gas'!Q14<0,"0",('Wtr-Gas'!Q14)*0.0038) -> 22.8 | AK12: =IF('Wtr-Gas'!U14<0,"0",('Wtr-Gas'!U14)*0.0038) -> 954.18 | AL12: =IF('Wtr-Gas'!X14<0,"0",('Wtr-Gas'!X14)*0.0038) -> 4705.16 | AM12: =IF('Wtr-Gas'!AB14<0,"0",('Wtr-Gas'!AB14)*0.0038) -> 6042 | AN12: =IF('Wtr-Gas'!AD14<0,"0",('Wtr-Gas'!AD14)*0.0038) -> 1336.1283 | AO12: =IF('Wtr-Gas'!AF14<0,"0",('Wtr-Gas'!AF14)*0.0038) -> 12.502 | AP12: =IF('Wtr-Gas'!AH14<0,"0",('Wtr-Gas'!AH14)*0.0038) -> 319.01 | AQ12: =IF('Wtr-Gas'!AJ14<0,"0",('Wtr-Gas'!AJ14)*0.0038) -> 50.7338 | AR12: =IF('Wtr-Gas'!AL14<0,"0",('Wtr-Gas'!AL14)*0.0038) -> 326.8 | AS12: =IF('Wtr-Gas'!AN14<0,"0",('Wtr-Gas'!AN14)*0.0038) -> 0.0494 | AT12: =IF('Wtr-Gas'!AP14<0,"0",('Wtr-Gas'!AP14)*0.0038) -> 11.02 | AU12: =IF('Wtr-Gas'!AT14<0,"0",('Wtr-Gas'!AT14)*0.0038) -> 0.4066 | AV12: =IF('Wtr-Gas'!AW14<0,"0",('Wtr-Gas'!AW14)*0.0038) -> 206.53 | AW12: =IF('Wtr-Gas'!AY14<0,"0",('Wtr-Gas'!AY14)*0.0038) -> 147.25536 | AX12: =IF('Wtr-Gas'!AZ14<0,"0",('Wtr-Gas'!AZ14)*0.0038) -> 59.274642 | AY12: =IF('Wtr-Gas'!BB14<0,"0",('Wtr-Gas'!BB14)*0.0038) -> 12.16 | AZ12: =IF('Wtr-Gas'!BD14<0,"0",('Wtr-Gas'!BD14)*0.0038) -> 3.23 | BA12: =IF('Wtr-Gas'!BF14<0,"0",('Wtr-Gas'!BF14)*0.0038) -> 0.0304
A13: Orlando | B13: 14 | C13: 3 | D13: 2022 | E13: =IF(Elect!AL15<0,"0",Elect!AL15) -> 613 | F13: =IF(Elect!I15<0,"0",Elect!I15) -> 52320 | G13: =Elect!H15 -> 2.413 | H13: =IF(Elect!F15<0,"0",Elect!F15) -> 41920 | I13: =Elect!E15 -> 1.961 | J13: =IF(Elect!U15<0,"0",Elect!U15) -> 60900 | K13: =Elect!T15 -> 2.726 | L13: =IF(Elect!AJ15<0,"0",Elect!AJ15) -> 1440 | M13: =Elect!AI15 -> 0.292 | N13: =IF(Elect!X15<0,"0",Elect!X15) -> 67500 | O13: =Elect!W15 -> 1.963 | P13: =IF(Elect!O15<0,"0",Elect!O15) -> 12000 | Q13: =Elect!N15 -> 3.2 | R13: =IF(Elect!L15<0,"0",Elect!L15) -> 13600 | S13: =Elect!K15 -> 3.44 | T13: =IF(Elect!R15<0,"0",Elect!R15) -> 11600 | U13: =Elect!Q15 -> 3.54 | V13: =IF(Elect!AA15<0,"0",Elect!AA15) -> 9120 | W13: =Elect!Z15 -> 0.618 | X13: =IF(Elect!AD15<0,"0",Elect!AD15) -> 4160 | Y13: =Elect!AC15 -> 2.93 | Z13: =IF(Elect!AG15<0,"0",Elect!AG15) -> 54000 | AA13: =Elect!AF15 -> 2.222 | AB13: =IF(Elect!AX15<0,"0",Elect!AX15) -> 1900 | AC13: =IF(Elect!AV15<0,"0",Elect!AV15) -> 15800 | AD13: =IF(Elect!AZ15<0,"0",Elect!AZ15) -> 880 | AE13: =IF(Elect!BB15<0,"0",Elect!BB15) -> 1120 | AF13: =IF('Wtr-Gas'!E15<0,"0",('Wtr-Gas'!E15)*0.0038) -> 4622.358 | AG13: =IF('Wtr-Gas'!H15<0,"0",('Wtr-Gas'!H15)*0.0038) -> 166.782 | AH13: =IF('Wtr-Gas'!K15<0,"0",('Wtr-Gas'!K15)*0.0038) -> 0.912 | AI13: =IF('Wtr-Gas'!N15<0,"0",('Wtr-Gas'!N15)*0.0038) -> 3727.8 | AJ13: =IF('Wtr-Gas'!Q15<0,"0",('Wtr-Gas'!Q15)*0.0038) -> 215.84 | AK13: =IF('Wtr-Gas'!U15<0,"0",('Wtr-Gas'!U15)*0.0038) -> 991.8 | AL13: =IF('Wtr-Gas'!X15<0,"0",('Wtr-Gas'!X15)*0.0038) -> 3921.6 | AM13: =IF('Wtr-Gas'!AB15<0,"0",('Wtr-Gas'!AB15)*0.0038) -> 8056 | AN13: =IF('Wtr-Gas'!AD15<0,"0",('Wtr-Gas'!AD15)*0.0038) -> 2040.1394 | AO13: =IF('Wtr-Gas'!AF15<0,"0",('Wtr-Gas'!AF15)*0.0038) -> 5.738 | AP13: =IF('Wtr-Gas'!AH15<0,"0",('Wtr-Gas'!AH15)*0.0038) -> 232.218 | AQ13: =IF('Wtr-Gas'!AJ15<0,"0",('Wtr-Gas'!AJ15)*0.0038) -> 28.538 | AR13: =IF('Wtr-Gas'!AL15<0,"0",('Wtr-Gas'!AL15)*0.0038) -> 30.4 | AS13: =IF('Wtr-Gas'!AN15<0,"0",('Wtr-Gas'!AN15)*0.0038) -> 0.0456 | AT13: =IF('Wtr-Gas'!AP15<0,"0",('Wtr-Gas'!AP15)*0.0038) -> 10.26 | AU13: =IF('Wtr-Gas'!AT15<0,"0",('Wtr-Gas'!AT15)*0.0038) -> 0.4864 | AV13: =IF('Wtr-Gas'!AW15<0,"0",('Wtr-Gas'!AW15)*0.0038) -> 211.4928 | AW13: =IF('Wtr-Gas'!AY15<0,"0",('Wtr-Gas'!AY15)*0.0038) -> 165.60149 | AX13: =IF('Wtr-Gas'!AZ15<0,"0",('Wtr-Gas'!AZ15)*0.0038) -> 45.891308 | AY13: =IF('Wtr-Gas'!BB15<0,"0",('Wtr-Gas'!BB15)*0.0038) -> 9.5 | AZ13: =IF('Wtr-Gas'!BD15<0,"0",('Wtr-Gas'!BD15)*0.0038) -> 0 | BA13: =IF('Wtr-Gas'!BF15<0,"0",('Wtr-Gas'!BF15)*0.0038) -> 0
... A62: Orlando | B62: 31 | C62: 12 | D62: 2022 | E62: =IF(Elect!AL64<0,"0",Elect!AL64) -> 0 | F62: =IF(Elect!I64<0,"0",Elect!I64) -> 0 | G62: =Elect!H64 -> 0 | H62: =IF(Elect!F64<0,"0",Elect!F64) -> 0 | I62: =Elect!E64 -> 0 | J62: =IF(Elect!U64<0,"0",Elect!U64) -> 0 | K62: =Elect!T64 -> 0 | L62: =IF(Elect!AJ64<0,"0",Elect!AJ64) -> 0 | M62: =Elect!AI64 -> 0 | N62: =IF(Elect!X64<0,"0",Elect!X64) -> 0 | O62: =Elect!W64 -> 0 | P62: =IF(Elect!O64<0,"0",Elect!O64) -> 0 | Q62: =Elect!N64 -> 0 | R62: =IF(Elect!L64<0,"0",Elect!L64) -> 0 | S62: =Elect!K64 -> 0 | T62: =IF(Elect!R64<0,"0",Elect!R64) -> 0 | U62: =Elect!Q64 -> 0 | V62: =IF(Elect!AA64<0,"0",Elect!AA64) -> 0 | W62: =Elect!Z64 -> 0 | X62: =IF(Elect!AD64<0,"0",Elect!AD64) -> 0 | Y62: =Elect!AC64 -> 0 | Z62: =IF(Elect!AG64<0,"0",Elect!AG64) -> 0 | AA62: =Elect!AF64 -> 0 | AB62: =IF(Elect!AX64<0,"0",Elect!AX64) -> 0 | AC62: =IF(Elect!AV64<0,"0",Elect!AV64) -> 0 | AD62: =IF(Elect!AZ64<0,"0",Elect!AZ64) -> 0 | AE62: =IF(Elect!BB64<0,"0",Elect!BB64) -> 0 | AF62: =IF('Wtr-Gas'!E64<0,"0",('Wtr-Gas'!E64)*0.0038) -> 0 | AG62: =IF('Wtr-Gas'!H64<0,"0",('Wtr-Gas'!H64)*0.0038) -> 0 | AH62: =IF('Wtr-Gas'!K64<0,"0",('Wtr-Gas'!K64)*0.0038) -> 0 | AI62: =IF('Wtr-Gas'!N64<0,"0",('Wtr-Gas'!N64)*0.0038) -> 0 | AJ62: =IF('Wtr-Gas'!Q64<0,"0",('Wtr-Gas'!Q64)*0.0038) -> 0 | AK62: =IF('Wtr-Gas'!U64<0,"0",('Wtr-Gas'!U64)*0.0038) -> 0 | AL62: =IF('Wtr-Gas'!X64<0,"0",('Wtr-Gas'!X64)*0.0038) -> 0 | AM62: =IF('Wtr-Gas'!AB64<0,"0",('Wtr-Gas'!AB64)*0.0038) -> 0 | AN62: =IF('Wtr-Gas'!AD64<0,"0",('Wtr-Gas'!AD64)*0.0038) -> 0 | AO62: =IF('Wtr-Gas'!AF64<0,"0",('Wtr-Gas'!AF64)*0.0038) -> 0 | AP62: =IF('Wtr-Gas'!AH64<0,"0",('Wtr-Gas'!AH64)*0.0038) -> 0 | AQ62: =IF('Wtr-Gas'!AJ64<0,"0",('Wtr-Gas'!AJ64)*0.0038) -> 0 | AR62: =IF('Wtr-Gas'!AL64<0,"0",('Wtr-Gas'!AL64)*0.0038) -> 0 | AS62: =IF('Wtr-Gas'!AN64<0,"0",('Wtr-Gas'!AN64)*0.0038) -> 0 | AT62: =IF('Wtr-Gas'!AP64<0,"0",('Wtr-Gas'!AP64)*0.0038) -> 0 | AU62: =IF('Wtr-Gas'!AT64<0,"0",('Wtr-Gas'!AT64)*0.0038) -> 0 | AV62: =IF('Wtr-Gas'!AW64<0,"0",('Wtr-Gas'!AW64)*0.0038) -> 0 | AW62: =IF('Wtr-Gas'!AY64<0,"0",('Wtr-Gas'!AY64)*0.0038) -> 0 | AX62: =IF('Wtr-Gas'!AZ64<0,"0",('Wtr-Gas'!AZ64)*0.0038) -> 0 | AY62: =IF('Wtr-Gas'!BB64<0,"0",('Wtr-Gas'!BB64)*0.0038) -> 0 | AZ62: =IF('Wtr-Gas'!BD64<0,"0",('Wtr-Gas'!BD64)*0.0038) -> 0 | BA62: =IF('Wtr-Gas'!BF64<0,"0",('Wtr-Gas'!BF64)*0.0038) -> 0

Sheet Elect
B1: 2021 | D1: CC0913A018 | G1: CC0913A020 | J1: CC0913A060 | M1: CC0913A059 | P1: CC0913A081 | S1: CC0913A054 | V1: CC0913A053 | Y1: CC0913A075 | AB1: CC0913A076 | AE1: CC0912A18 | AH1: CC0913A095 | AK1: CS0212A003 | AP1: Water Pk | AQ1: % of KWH | AU1: CG0612A084 | AW1: CC0612A036 | AY1: CS0210A030 | BA1: IIC0608A03 | BF1: KWH
B2: Date | C2: Occupancy | D2: 68 425 008 | E2: T7384 | F2: KWH Total | G2: 68 425 010 | H2: T2392 | I2: KWH Total | J2: 68 425 078 | K2: T2393 | L2: KWH Total | M2: 68 425 077 | N2: T2395 | O2: KWH Total | P2: 68 425 071 | Q2: T7285 | R2: KWH Total | S2: 68 425 060 | T2: T7380 | U2: KWH Total | V2: 68 425 059 | W2: T2390 | X2: KWH Total | Y2: 68 425 093 | Z2: T7382 | AA2: KWH Total | AB2: 68 425 094 | AC2: T2391 | AD2: KWH Total | AE2: 90 625 242 | AF2: T7283 | AG2: KWH Total | AH2: 68 425 097 | AI2: T7281 | AJ2: KWH Total | AK2: 90 630 431 | AM2: KWH Total | AO2: Total KWH | AP2: KWH | AR2: Total Mnth | AU2: 676 62 513 | AV2: KWH Total | AW2: 672 73 163 | AX2: KWH Total | AY2: 61 979 920 | AZ2: KWH Total | BA2: 56 253 208 | BB2: KWH Total | BD2: Total KWH | BE2: Total Mnth | BF2: Total
C3: Room Nights | D3: KWH | E3: Demand | F3: (x160) | G3: KWH | H3: Demand | I3: (x160) | J3: KWH | K3: Demand | L3: (x400) | M3: KWH | N3: Demand | O3: (x400) | P3: KWH | Q3: Demand | R3: (x400) | S3: KWH | T3: Demand | U3: (x300) | V3: KWH | W3: Demand | X3: (x300) | Y3: KWH | Z3: Demand | AA3: (x160) | AB3: KWH | AC3: Demand | AD3: (x160) | AE3: KWH | AF3: Demand | AG3: (X200) | AH3: KWH | AI3: Demand | AJ3: (x40) | AK3: KWH | AM3: (x1) | AR3: KWH | AU3: KWH | AV3: (x100) | AW3: KWH | AX3: (x100) | AY3: KWH | AZ3: (x1) | BA3: KWH | BB3: (x40) | BD3: Golf | BE3: Golf | BF3: Resort
B4: 44562 | C4: =(Occupancy!K8) -> 298 | D4: 11321 | E4: 1.923 | F4: 0 | G4: 10100 | H4: 2.565 | I4: 0 | J4: 12287 | K4: 3.65 | L4: 0 | M4: 12096 | N4: 2.73 | O4: 0 | P4: 12723 | Q4: 3.73 | R4: 0 | S4: 87171 | T4: 2.249 | U4: 0 | V4: 83846 | W4: 1.671 | X4: 0 | Y4: 19760 | Z4: 2.75 | AA4: 0 | AB4: 12886 | AC4: 2.31 | AD4: 0 | AE4: 6617 | AF4: 2.166 | AG4: 0 | AH4: 19427 | AI4: 0.294 | AJ4: 0 | AK4: 96927 | AL4: 0 | AT4: =B4 -> 44562 | AU4: 70527 | AV4: 0 | AW4: 9004 | AX4: 0 | AY4: 72470 | AZ4: 0 | BA4: 3543 | BB4: 0
B5: 44564 | C5: =(Occupancy!K9+K10) -> 242.25 | D5: 11444 | E5: 1.923 | F5: =SUM(D5-D4)*160 -> 19680 | G5: 10191 | H5: 2.565 | I5: =SUM(G5-G4)*160 -> 14560 | J5: 12296 | K5: 3.65 | L5: =SUM(J5-J4)*400 -> 3600 | M5: 12104 | N5: 3.73 | O5: =SUM(M5-M4)*400 -> 3200 | P5: 12731 | Q5: 3.73 | R5: =SUM(P5-P4)*400 -> 3200 | S5: 87232 | T5: 2.249 | U5: =SUM(S5-S4)*300 -> 18300 | V5: 83905 | W5: 1.838 | X5: =SUM(V5-V4)*300 -> 17700 | Y5: 19769 | Z5: 2.75 | AA5: =SUM(Y5-Y4)*160 -> 1440 | AB5: 12892 | AC5: 2.31 | AD5: =SUM(AB5-AB4)*160 -> 960 | AE5: 6693 | AF5: 2.166 | AG5: =SUM(AE5-AE4)*200 -> 15200 | AH5: 19437 | AI5: 0.297 | AJ5: =SUM(AH5-AH4)*40 -> 400 | AK5: 96950 | AL5: =SUM(AK5-AK4) -> 23 | AO5: =SUM(AG5+AD5+AA5+X5+U5+R5+O5+L5+I5+F5+AJ5+AL5) -> 98263 | AP5: =SUM(AG5+AJ5) -> 15600 | AQ5: =SUM(AP5/AO5) -> 0.15875762 | AT5: =B5 -> 44564 | AU5: 70589 | AV5: =SUM(AU5-AU4)*100 -> 6200 | AW5: 9010 | AX5: =SUM(AW5-AW4)*100 -> 600 | AY5: 72793 | AZ5: =SUM(AY5-AY4) -> 323 | BA5: 3556 | BB5: =SUM(BA5-BA4)*40 -> 520 | BD5: =SUM(AU5+AW5,AY5,BA5) -> 155948
B6: 44571 | C6: =SUM(Occupancy!K11:K17) -> 1355 | D6: 11696 | E6: 1.923 | F6: =SUM(D6-D5)*160 -> 40320 | G6: 10511 | H6: 2.565 | I6: =SUM(G6-G5)*160 -> 51200 | J6: 12323 | K6: 3.65 | L6: =SUM(J6-J5)*400 -> 10800 | M6: 12127 | N6: 2.73 | O6: =SUM(M6-M5)*400 -> 9200 | P6: 12756 | Q6: 3.73 | R6: =SUM(P6-P5)*400 -> 10000 | S6: 87372 | T6: 2.249 | U6: =SUM(S6-S5)*300 -> 42000 | V6: 84018 | W6: 1.838 | X6: =SUM(V6-V5)*300 -> 33900 | Y6: 19803 | Z6: 3.16 | AA6: =SUM(Y6-Y5)*160 -> 5440 | AB6: 12915 | AC6: 3.23 | AD6: =SUM(AB6-AB5)*160 -> 3680 | AE6: 6964 | AF6: 2.166 | AG6: =SUM(AE6-AE5)*200 -> 54200 | AH6: 19473 | AI6: 0.297 | AJ6: =SUM(AH6-AH5)*40 -> 1440 | AK6: 97680 | AL6: =SUM(AK6-AK5) -> 730 | AO6: =SUM(AG6+AD6+AA6+X6+U6+R6+O6+L6+I6+F6+AJ6+AL6) -> 262910 | AP6: =SUM(AG6+AJ6) -> 55640 | AQ6: =SUM(AP6/AO6) -> 0.21163136 | AT6: =B6 -> 44571 | AU6: 70721 | AV6: =SUM(AU6-AU5)*100 -> 13200 | AW6: 9028 | AX6: =SUM(AW6-AW5)*100 -> 1800 | AY6: 73621 | AZ6: =SUM(AY6-AY5) -> 828 | BA6: 3616 | BB6: =SUM(BA6-BA5)*40 -> 2400 | BD6: =SUM(AU6+AW6,AY6,BA6) -> 156986
B7: 44578 | C7: =SUM(Occupancy!K18:K24) -> 1610 | D7: 11962 | E7: 1.961 | F7: =SUM(D7-D6)*160 -> 42560 | G7: 10844 | H7: 2.565 | I7: =SUM(G7-G6)*160 -> 53280 | J7: 12351 | K7: 3.65 | L7: =SUM(J7-J6)*400 -> 11200 | M7: 12153 | N7: 2.73 | O7: =SUM(M7-M6)*400 -> 10400 | P7: 12785 | Q7: 3.73 | R7: =SUM(P7-P6)*400 -> 11600 | S7: 87520 | T7: 2.249 | U7: =SUM(S7-S6)*300 -> 44400 | V7: 84121 | W7: 1.838 | X7: =SUM(V7-V6)*300 -> 30900 | Y7: 19841 | Z7: 3.18 | AA7: =SUM(Y7-Y6)*160 -> 6080 | AB7: 12939 | AC7: 3.23 | AD7: =SUM(AB7-AB6)*160 -> 3840 | AE7: 7242 | AF7: 2.166 | AG7: =SUM(AE7-AE6)*200 -> 55600 | AH7: 19511 | AI7: 0.297 | AJ7: =SUM(AH7-AH6)*40 -> 1520 | AK7: 98341 | AL7: =SUM(AK7-AK6) -> 661 | AO7: =SUM(AG7+AD7+AA7+X7+U7+R7+O7+L7+I7+F7+AJ7+AL7) -> 272041 | AP7: =SUM(AG7+AJ7) -> 57120 | AQ7: =SUM(AP7/AO7) -> 0.20996835 | AT7: =B7 -> 44578 | AU7: 70830 | AV7: =SUM(AU7-AU6)*100 -> 10900 | AW7: 9044 | AX7: =SUM(AW7-AW6)*100 -> 1600 | AY7: 74319 | AZ7: =SUM(AY7-AY6) -> 698 | BA7: 3662 | BB7: =SUM(BA7-BA6)*40 -> 1840 | BD7: =SUM(AU7+AW7,AY7,BA7) -> 157855
B8: 44585 | C8: =SUM(Occupancy!K25:K31) -> 1849 | D8: 12222 | E8: 1.86 | F8: =SUM(D8-D7)*160 -> 41600 | G8: 11167 | H8: 2.403 | I8: =SUM(G8-G7)*160 -> 51680 | J8: 12385 | K8: 3.25 | L8: =SUM(J8-J7)*400 -> 13600 | M8: 12183 | N8: 2.85 | O8: =SUM(M8-M7)*400 -> 12000 | P8: 12818 | Q8: 3.1 | R8: =SUM(P8-P7)*400 -> 13200 | S8: 87629 | T8: 2.249 | U8: =SUM(S8-S7)*300 -> 32700 | V8: 84240 | W8: 1.838 | X8: =SUM(V8-V7)*300 -> 35700 | Y8: 19879 | Z8: 2.99 | AA8: =SUM(Y8-Y7)*160 -> 6080 | AB8: 12967 | AC8: 2.45 | AD8: =SUM(AB8-AB7)*160 -> 4480 | AE8: 7512 | AF8: 2.111 | AG8: =SUM(AE8-AE7)*200 -> 54000 | AH8: 19548 | AI8: 0.292 | AJ8: =SUM(AH8-AH7)*40 -> 1480 | AK8: 98899 | AL8: =SUM(AK8-AK7) -> 558 | AO8: =SUM(AG8+AD8+AA8+X8+U8+R8+O8+L8+I8+F8+AJ8+AL8) -> 267078 | AP8: =SUM(AG8+AJ8) -> 55480 | AQ8: =SUM(AP8/AO8) -> 0.20772958 | AT8: =B8 -> 44585 | AU8: 70925 | AV8: =SUM(AU8-AU7)*100 -> 9500 | AW8: 9062 | AX8: =SUM(AW8-AW7)*100 -> 1800 | AY8: 75050 | AZ8: =SUM(AY8-AY7) -> 731 | BA8: 3692 | BB8: =SUM(BA8-BA7)*40 -> 1200 | BD8: =SUM(AU8+AW8,AY8,BA8) -> 158729
B9: 44592 | C9: =SUM(Occupancy!K32:K38) -> 724 | D9: 12480 | E9: 1.906 | F9: =SUM(D9-D8)*160 -> 41280 | G9: 11484 | H9: 2.478 | I9: =SUM(G9-G8)*160 -> 50720 | J9: 12416 | K9: 3.25 | L9: =SUM(J9-J8)*400 -> 12400 | M9: 12211 | N9: 2.96 | O9: =SUM(M9-M8)*400 -> 11200 | P9: 12846 | Q9: 3.1 | R9: =SUM(P9-P8)*400 -> 11200 | S9: 87711 | T9: 1.359 | U9: =SUM(S9-S8)*300 -> 24600 | V9: 84342 | W9: 0.98 | X9: =SUM(V9-V8)*300 -> 30600 | Y9: 19913 | Z9: 3.25 | AA9: =SUM(Y9-Y8)*160 -> 5440 | AB9: 12987 | AC9: 2.85 | AD9: =SUM(AB9-AB8)*160 -> 3200 | AE9: 7778 | AF9: 2.186 | AG9: =SUM(AE9-AE8)*200 -> 53200 | AH9: 19583 | AI9: 0.292 | AJ9: =SUM(AH9-AH8)*40 -> 1400 | AK9: 99300 | AL9: =SUM(AK9-AK8) -> 401 | AO9: =SUM(AG9+AD9+AA9+X9+U9+R9+O9+L9+I9+F9+AJ9+AL9) -> 245641 | AP9: =SUM(AG9+AJ9) -> 54600 | AQ9: =SUM(AP9/AO9) -> 0.2222756 | AT9: =B9 -> 44592 | AU9: 71052 | AV9: =SUM(AU9-AU8)*100 -> 12700 | AW9: 9078 | AX9: =SUM(AW9-AW8)*100 -> 1600 | AY9: 75871 | AZ9: =SUM(AY9-AY8) -> 821 | BA9: 3728 | BB9: =SUM(BA9-BA8)*40 -> 1440 | BD9: =SUM(AU9+AW9,AY9,BA9) -> 159729
