Workbook

Sheet TOTAL
A1: Site Name | B1: Day | C1: Month | D1: Year | E1: Total Electricity Kwh | F1: Electricity Tariff ($/Kwh) | G1: Natual Gas (m3) | H1: Natural Gas $/m3 | I1: Water Utility Supply (m3) m3 | J1: Water Utility Supply (m3) $/m3 | K1: Room Nights
A2: Orlando | B2: 1 | C2: 1 | D2: 2019 | E2: =Submetering!F2+Submetering!H2+Submetering!J2+Submetering!L2+Submetering!N2+Submetering!P2+Submetering!R2+Submetering!T2+Submetering!V2+Submetering!X2+Submetering!Z2+Submetering!AB2+Submetering!AC2+Submetering!AD2+Submetering!AE2 -> 363215 | F2: =((((Submetering!E2+Submetering!AD2)*0.13773+(Submetering!E2+Submetering!AD2)*0.02095)*1.09+(2.85/30)*2)+(((Submetering!F2+Submetering!H2+Submetering!J2+Submetering!L2+Submetering!N2+Submetering!P2+Submetering!R2+Submetering!T2+Submetering!V2+Submetering!X2+Submetering!Z2+Submetering!AB2+Submetering!AC2+Submetering!AE2)*0.05155)+((Submetering!F2+Submetering!H2+Submetering!J2+Submetering!L2+Submetering!N2+Submetering!P2+Submetering!R2+Submetering!T2+Submetering!V2+Submetering!X2+Submetering!Z2+Submetering!AB2+Submetering!AC2+Submetering!AE2)*0.02095)+(20/30)*15)*1.1048)/E2 -> 0.080357765 | G2: =Submetering!AK2+Submetering!AL2+Submetering!AU2 -> 0 | H2: 0.8166 | I2: =Submetering!AF2+Submetering!AG2+Submetering!AV2+Submetering!AY2+Submetering!AZ2 -> 0 | J2: 0
A3: Orlando | B3: 13 | C3: 1 | D3: 2019 | E3: =Submetering!F3+Submetering!H3+Submetering!J3+Submetering!L3+Submetering!N3+Submetering!P3+Submetering!R3+Submetering!T3+Submetering!V3+Submetering!X3+Submetering!Z3+Submetering!AB3+Submetering!AC3+Submetering!AD3+Submetering!AE3 -> 875030 | F3: =((((Submetering!E3+Submetering!AD3)*0.13773+(Submetering!E3+Submetering!AD3)*0.02095)*1.09+(2.85/30)*2)+(((Submetering!F3+Submetering!H3+Submetering!J3+Submetering!L3+Submetering!N3+Submetering!P3+Submetering!R3+Submetering!T3+Submetering!V3+Submetering!X3+Submetering!Z3+Submetering!AB3+Submetering!AC3+Submetering!AE3)*0.05155)+((Submetering!F3+Submetering!H3+Submetering!J3+Submetering!L3+Submetering!N3+Submetering!P3+Submetering!R3+Submetering!T3+Submetering!V3+Submetering!X3+Submetering!Z3+Submetering!AB3+Submetering!AC3+Submetering!AE3)*0.02095)+(20/30)*15)*1.1048)/E3 -> 0.08021803 | G3: =Submetering!AK3+Submetering!AL3+Submetering!AU3 -> 18961.852 | H3: 0.8166 | I3: =Submetering!AF3+Submetering!AG3+Submetering!AV3+Submetering!AY3+Submetering!AZ3 -> 15244.68 | J3: =((Submetering!AG3+Submetering!BA3)*0.8868+(1712.96+1070.52)/30+(Submetering!AF3+Submetering!AY3+Submetering!AV3+Submetering!AZ3)*1.1251+(2076.11+129.67+207.57+207.57)/30+(11680.53+56.61)/30)/I3 -> 1.171823
A4: Orlando | B4: 21 | C4: 1 | D4: 2019 | E4: =Submetering!F4+Submetering!H4+Submetering!J4+Submetering!L4+Submetering!N4+Submetering!P4+Submetering!R4+Submetering!T4+Submetering!V4+Submetering!X4+Submetering!Z4+Submetering!AB4+Submetering!AC4+Submetering!AD4+Submetering!AE4 -> 297492 | F4: =((((Submetering!E4+Submetering!AD4)*0.13773+(Submetering!E4+Submetering!AD4)*0.02095)*1.09+(2.85/30)*2)+(((Submetering!F4+Submetering!H4+Submetering!J4+Submetering!L4+Submetering!N4+Submetering!P4+Submetering!R4+Submetering!T4+Submetering!V4+Submetering!X4+Submetering!Z4+Submetering!AB4+Submetering!AC4+Submetering!AE4)*0.05155)+((Submetering!F4+Submetering!H4+Submetering!J4+Submetering!L4+Submetering!N4+Submetering!P4+Submetering!R4+Submetering!T4+Submetering!V4+Submetering!X4+Submetering!Z4+Submetering!AB4+Submetering!AC4+Submetering!AE4)*0.02095)+(20/30)*15)*1.1048)/E4 -> 0.080376758 | G4: =Submetering!AK4+Submetering!AL4+Submetering!AU4 -> 8224.416 | H4: 0.8166 | I4: =Submetering!AF4+Submetering!AG4+Submetering!AV4+Submetering!AY4+Submetering!AZ4 -> 5203.0512 | J4: =((Submetering!AG4+Submetering!BA4)*0.8868+(1712.96+1070.52)/30+(Submetering!AF4+Submetering!AY4+Submetering!AV4+Submetering!AZ4)*1.1251+(2076.11+129.67+207.57+207.57)/30+(11680.53+56.61)/30)/I4 -> 1.2598407
A5: Orlando | B5: 28 | C5: 1 | D5: 2019 | E5: =Submetering!F5+Submetering!H5+Submetering!J5+Submetering!L5+Submetering!N5+Submetering!P5+Submetering!R5+Submetering!T5+Submetering!V5+Submetering!X5+Submetering!Z5+Submetering!AB5+Submetering!AC5+Submetering!AD5+Submetering!AE5 -> 294803 | F5: =((((Submetering!E5+Submetering!AD5)*0.13773+(Submetering!E5+Submetering!AD5)*0.02095)*1.09+(2.85/30)*2)+(((Submetering!F5+Submetering!H5+Submetering!J5+Submetering!L5+Submetering!N5+Submetering!P5+Submetering!R5+Submetering!T5+Submetering!V5+Submetering!X5+Submetering!Z5+Submetering!AB5+Submetering!AC5+Submetering!AE5)*0.05155)+((Submetering!F5+Submetering!H5+Submetering!J5+Submetering!L5+Submetering!N5+Submetering!P5+Submetering!R5+Submetering!T5+Submetering!V5+Submetering!X5+Submetering!Z5+Submetering!AB5+Submetering!AC5+Submetering!AE5)*0.02095)+(20/30)*15)*1.1048)/E5 -> 0.081827629 | G5: =Submetering!AK5+Submetering!AL5+Submetering!AU5 -> 9427.9064 | H5: 0.8166 | I5: =Submetering!AF5+Submetering!AG5+Submetering!AV5+Submetering!AY5+Submetering!AZ5 -> 4880.3248 | J5: =((Submetering!AG5+Submetering!BA5)*0.8868+(1712.96+1070.52)/30+(Submetering!AF5+Submetering!AY5+Submetering!AV5+Submetering!AZ5)*1.1251+(2076.11+129.67+207.57+207.57)/30+(11680.53+56.61)/30)/I5 -> 1.2832906
A6: Orlando | B6: 31 | C6: 1 | D6: 2019 | E6: =Submetering!F6+Submetering!H6+Submetering!J6+Submetering!L6+Submetering!N6+Submetering!P6+Submetering!R6+Submetering!T6+Submetering!V6+Submetering!X6+Submetering!Z6+Submetering!AB6+Submetering!AC6+Submetering!AD6+Submetering!AE6 -> 171764 | F6: =((((Submetering!E6+Submetering!AD6)*0.13773+(Submetering!E6+Submetering!AD6)*0.02095)*1.09+(2.85/30)*2)+(((Submetering!F6+Submetering!H6+Submetering!J6+Submetering!L6+Submetering!N6+Submetering!P6+Submetering!R6+Submetering!T6+Submetering!V6+Submetering!X6+Submetering!Z6+Submetering!AB6+Submetering!AC6+Submetering!AE6)*0.05155)+((Submetering!F6+Submetering!H6+Submetering!J6+Submetering!L6+Submetering!N6+Submetering!P6+Submetering!R6+Submetering!T6+Submetering!V6+Submetering!X6+Submetering!Z6+Submetering!AB6+Submetering!AC6+Submetering!AE6)*0.02095)+(20/30)*15)*1.1048)/E6 -> 0.080800435 | G6: =Submetering!AK6+Submetering!AL6+Submetering!AU6 -> 6304.1658 | H6: 0.8166 | I6: =Submetering!AF6+Submetering!AG6+Submetering!AV6+Submetering!AY6+Submetering!AZ6 -> 2806.167 | J6: =((Submetering!AG6+Submetering!BA6)*0.8868+(1712.96+1070.52)/30+(Submetering!AF6+Submetering!AY6+Submetering!AV6+Submetering!AZ6)*1.1251+(2076.11+129.67+207.57+207.57)/30+(11680.53+56.61)/30)/I6 -> 1.2993618 | K6: =Occupancy!H4 -> 10556.988
A7: Orlando | B7: 3 | C7: 2 | D7: 2019 | E7: =Submetering!F7+Submetering!H7+Submetering!J7+Submetering!L7+Submetering!N7+Submetering!P7+Submetering!R7+Submetering!T7+Submetering!V7+Submetering!X7+Submetering!Z7+Submetering!AB7+Submetering!AC7+Submetering!AD7+Submetering!AE7 -> 163226 | F7: =((((Submetering!E7+Submetering!AD7)*0.13773+(Submetering!E7+Submetering!AD7)*0.02095)*1.09+(2.85/30)*2)+(((Submetering!F7+Submetering!H7+Submetering!J7+Submetering!L7+Submetering!N7+Submetering!P7+Submetering!R7+Submetering!T7+Submetering!V7+Submetering!X7+Submetering!Z7+Submetering!AB7+Submetering!AC7+Submetering!AE7)*0.05155)+((Submetering!F7+Submetering!H7+Submetering!J7+Submetering!L7+Submetering!N7+Submetering!P7+Submetering!R7+Submetering!T7+Submetering!V7+Submetering!X7+Submetering!Z7+Submetering!AB7+Submetering!AC7+Submetering!AE7)*0.02095)+(20/30)*15)*1.1048)/E7 -> 0.080640768 | G7: =Submetering!AK7+Submetering!AL7+Submetering!AU7 -> 2881.8022 | H7: 0.8166 | I7: =Submetering!AF7+Submetering!AG7+Submetering!AV7+Submetering!AY7+Submetering!AZ7 -> 2011.5794 | J7: =((Submetering!AG7+Submetering!BA7)*0.8868+(1712.96+1070.52)/30+(Submetering!AF7+Submetering!AY7+Submetering!AV7+Submetering!AZ7)*1.1251+(2076.11+129.67+207.57+207.57)/30+(11680.53+56.61)/30)/I7 -> 1.3934509
A8: Orlando | B8: 10 | C8: 2 | D8: 2019 | E8: =Submetering!F8+Submetering!H8+Submetering!J8+Submetering!L8+Submetering!N8+Submetering!P8+Submetering!R8+Submetering!T8+Submetering!V8+Submetering!X8+Submetering!Z8+Submetering!AB8+Submetering!AC8+Submetering!AD8+Submetering!AE8 -> 290488 | F8: =((((Submetering!E8+Submetering!AD8)*0.13773+(Submetering!E8+Submetering!AD8)*0.02095)*1.09+(2.85/30)*2)+(((Submetering!F8+Submetering!H8+Submetering!J8+Submetering!L8+Submetering!N8+Submetering!P8+Submetering!R8+Submetering!T8+Submetering!V8+Submetering!X8+Submetering!Z8+Submetering!AB8+Submetering!AC8+Submetering!AE8)*0.05155)+((Submetering!F8+Submetering!H8+Submetering!J8+Submetering!L8+Submetering!N8+Submetering!P8+Submetering!R8+Submetering!T8+Submetering!V8+Submetering!X8+Submetering!Z8+Submetering!AB8+Submetering!AC8+Submetering!AE8)*0.02095)+(20/30)*15)*1.1048)/E8 -> 0.080776026 | G8: =Submetering!AK8+Submetering!AL8+Submetering!AU8 -> 6473.4824 | H8: 0.8166 | I8: =Submetering!AF8+Submetering!AG8+Submetering!AV8+Submetering!AY8+Submetering!AZ8 -> 4878.06 | J8: =((Submetering!AG8+Submetering!BA8)*0.8868+(1712.96+1070.52)/30+(Submetering!AF8+Submetering!AY8+Submetering!AV8+Submetering!AZ8)*1.1251+(2076.11+129.67+207.57+207.57)/30+(11680.53+56.61)/30)/I8 -> 1.2912818
A9: Orlando | B9: 17 | C9: 2 | D9: 2019 | E9: =Submetering!F9+Submetering!H9+Submetering!J9+Submetering!L9+Submetering!N9+Submetering!P9+Submetering!R9+Submetering!T9+Submetering!V9+Submetering!X9+Submetering!Z9+Submetering!AB9+Submetering!AC9+Submetering!AD9+Submetering!AE9 -> 318729 | F9: =((((Submetering!E9+Submetering!AD9)*0.13773+(Submetering!E9+Submetering!AD9)*0.02095)*1.09+(2.85/30)*2)+(((Submetering!F9+Submetering!H9+Submetering!J9+Submetering!L9+Submetering!N9+Submetering!P9+Submetering!R9+Submetering!T9+Submetering!V9+Submetering!X9+Submetering!Z9+Submetering!AB9+Submetering!AC9+Submetering!AE9)*0.05155)+((Submetering!F9+Submetering!H9+Submetering!J9+Submetering!L9+Submetering!N9+Submetering!P9+Submetering!R9+Submetering!T9+Submetering!V9+Submetering!X9+Submetering!Z9+Submetering!AB9+Submetering!AC9+Submetering!AE9)*0.02095)+(20/30)*15)*1.1048)/E9 -> 0.080715155 | G9: =Submetering!AK9+Submetering!AL9+Submetering!AU9 -> 6099.1862 | H9: 0.8166 | I9: =Submetering!AF9+Submetering!AG9+Submetering!AV9+Submetering!AY9+Submetering!AZ9 -> 5107.9524 | J9: =((Submetering!AG9+Submetering!BA9)*0.8868+(1712.96+1070.52)/30+(Submetering!AF9+Submetering!AY9+Submetering!AV9+Submetering!AZ9)*1.1251+(2076.11+129.67+207.57+207.57)/30+(11680.53+56.61)/30)/I9 -> 1.2162189
A10: Orlando | B10: 24 | C10: 2 | D10: 2019 | E10: =Submetering!F10+Submetering!H10+Submetering!J10+Submetering!L10+Submetering!N10+Submetering!P10+Submetering!R10+Submetering!T10+Submetering!V10+Submetering!X10+Submetering!Z10+Submetering!AB10+Submetering!AC10+Submetering!AD10+Submetering!AE10 -> 352596 | F10: =((((Submetering!E10+Submetering!AD10)*0.13773+(Submetering!E10+Submetering!AD10)*0.02095)*1.09+(2.85/30)*2)+(((Submetering!F10+Submetering!H10+Submetering!J10+Submetering!L10+Submetering!N10+Submetering!P10+Submetering!R10+Submetering!T10+Submetering!V10+Submetering!X10+Submetering!Z10+Submetering!AB10+Submetering!AC10+Submetering!AE10)*0.05155)+((Submetering!F10+Submetering!H10+Submetering!J10+Submetering!L10+Submetering!N10+Submetering!P10+Submetering!R10+Submetering!T10+Submetering!V10+Submetering!X10+Submetering!Z10+Submetering!AB10+Submetering!AC10+Submetering!AE10)*0.02095)+(20/30)*15)*1.1048)/E10 -> 0.080667532 | G10: =Submetering!AK10+Submetering!AL10+Submetering!AU10 -> 4079.091 | H10: 0.8166 | I10: =Submetering!AF10+Submetering!AG10+Submetering!AV10+Submetering!AY10+Submetering!AZ10 -> 5794.316 | J10: =((Submetering!AG10+Submetering!BA10)*0.8868+(1712.96+1070.52)/30+(Submetering!AF10+Submetering!AY10+Submetering!AV10+Submetering!AZ10)*1.1251+(2076.11+129.67+207.57+207.57)/30+(11680.53+56.61)/30)/I10 -> 1.2963944 | K10: =Occupancy!H5 -> 9920.736
A11: Orlando | B11: 28 | C11: 2 | D11: 2019 | E11: =Submetering!F11+Submetering!H11+Submetering!J11+Submetering!L11+Submetering!N11+Submetering!P11+Submetering!R11+Submetering!T11+Submetering!V11+Submetering!X11+Submetering!Z11+Submetering!AB11+Submetering!AC11+Submetering!AD11+Submetering!AE11 -> 176314 | F11: =((((Submetering!E11+Submetering!AD11)*0.13773+(Submetering!E11+Submetering!AD11)*0.02095)*1.09+(2.85/30)*2)+(((Submetering!F11+Submetering!H11+Submetering!J11+Submetering!L11+Submetering!N11+Submetering!P11+Submetering!R11+Submetering!T11+Submetering!V11+Submetering!X11+Submetering!Z11+Submetering!AB11+Submetering!AC11+Submetering!AE11)*0.05155)+((Submetering!F11+Submetering!H11+Submetering!J11+Submetering!L11+Submetering!N11+Submetering!P11+Submetering!R11+Submetering!T11+Submetering!V11+Submetering!X11+Submetering!Z11+Submetering!AB11+Submetering!AC11+Submetering!AE11)*0.02095)+(20/30)*15)*1.1048)/E11 -> 0.080642226 | G11: =Submetering!AK11+Submetering!AL11+Submetering!AU11 -> 1938.1938 | H11: 0.8166 | I11: =Submetering!AF11+Submetering!AG11+Submetering!AV11+Submetering!AY11+Submetering!AZ11 -> 2364.417 | J11: =((Submetering!AG11+Submetering!BA11)*0.8868+(1712.96+1070.52)/30+(Submetering!AF11+Submetering!AY11+Submetering!AV11+Submetering!AZ11)*1.1251+(2076.11+129.67+207.57+207.57)/30+(11680.53+56.61)/30)/I11 -> 1.4369717
A12: Orlando | B12: 4 | C12: 3 | D12: 2019 | E12: =Submetering!F12+Submetering!H12+Submetering!J12+Submetering!L12+Submetering!N12+Submetering!P12+Submetering!R12+Submetering!T12+Submetering!V12+Submetering!X12+Submetering!Z12+Submetering!AB12+Submetering!AC12+Submetering!AD12+Submetering!AE12 -> 154348 | F12: =((((Submetering!E12+Submetering!AD12)*0.13773+(Submetering!E12+Submetering!AD12)*0.02095)*1.09+(2.85/30)*2)+(((Submetering!F12+Submetering!H12+Submetering!J12+Submetering!L12+Submetering!N12+Submetering!P12+Submetering!R12+Submetering!T12+Submetering!V12+Submetering!X12+Submetering!Z12+Submetering!AB12+Submetering!AC12+Submetering!AE12)*0.05155)+((Submetering!F12+Submetering!H12+Submetering!J12+Submetering!L12+Submetering!N12+Submetering!P12+Submetering!R12+Submetering!T12+Submetering!V12+Submetering!X12+Submetering!Z12+Submetering!AB12+Submetering!AC12+Submetering!AE12)*0.02095)+(20/30)*15)*1.1048)/E12 -> 0.080857448 | G12: =Submetering!AK12+Submetering!AL12+Submetering!AU12 -> 1598.5954 | H12: 0.8166 | I12: =Submetering!AF12+Submetering!AG12+Submetering!AV12+Submetering!AY12+Submetering!AZ12 -> 3786.3618 | J12: =((Submetering!AG12+Submetering!BA12)*0.8868+(1712.96+1070.52)/30+(Submetering!AF12+Submetering!AY12+Submetering!AV12+Submetering!AZ12)*1.1251+(2076.11+129.67+207.57+207.57)/30+(11680.53+56.61)/30)/I12 -> 1.353942
A13: Orlando | B13: 10 | C13: 3 | D13: 2019 | E13: =Submetering!F13+Submetering!H13+Submetering!J13+Submetering!L13+Submetering!N13+Submetering!P13+Submetering!R13+Submetering!T13+Submetering!V13+Submetering!X13+Submetering!Z13+Submetering!AB13+Submetering!AC13+Submetering!AD13+Submetering!AE13 -> 303385 | F13: =((((Submetering!E13+Submetering!AD13)*0.13773+(Submetering!E13+Submetering!AD13)*0.02095)*1.09+(2.85/30)*2)+(((Submetering!F13+Submetering!H13+Submetering!J13+Submetering!L13+Submetering!N13+Submetering!P13+Submetering!R13+Submetering!T13+Submetering!V13+Submetering!X13+Submetering!Z13+Submetering!AB13+Submetering!AC13+Submetering!AE13)*0.05155)+((Submetering!F13+Submetering!H13+Submetering!J13+Submetering!L13+Submetering!N13+Submetering!P13+Submetering!R13+Submetering!T13+Submetering!V13+Submetering!X13+Submetering!Z13+Submetering!AB13+Submetering!AC13+Submetering!AE13)*0.02095)+(20/30)*15)*1.1048)/E13 -> 0.080744004 | G13: =Submetering!AK13+Submetering!AL13+Submetering!AU13 -> 6574.1786 | H13: 0.8166 | I13: =Submetering!AF13+Submetering!AG13+Submetering!AV13+Submetering!AY13+Submetering!AZ13 -> 5321.8392 | J13: =((Submetering!AG13+Submetering!BA13)*0.8868+(1712.96+1070.52)/30+(Submetering!AF13+Submetering!AY13+Submetering!AV13+Submetering!AZ13)*1.1251+(2076.11+129.67+207.57+207.57)/30+(11680.53+56.61)/30)/I13 -> 1.354468
A14: Orlando | B14: 17 | C14: 3 | D14: 2019 | E14: =Submetering!F14+Submetering!H14+Submetering!J14+Submetering!L14+Submetering!N14+Submetering!P14+Submetering!R14+Submetering!T14+Submetering!V14+Submetering!X14+Submetering!Z14+Submetering!AB14+Submetering!AC14+Submetering!AD14+Submetering!AE14 -> 322001 | F14: =((((Submetering!E14+Submetering!AD14)*0.13773+(Submetering!E14+Submetering!AD14)*0.02095)*1.09+(2.85/30)*2)+(((Submetering!F14+Submetering!H14+Submetering!J14+Submetering!L14+Submetering!N14+Submetering!P14+Submetering!R14+Submetering!T14+Submetering!V14+Submetering!X14+Submetering!Z14+Submetering!AB14+Submetering!AC14+Submetering!AE14)*0.05155)+((Submetering!F14+Submetering!H14+Submetering!J14+Submetering!L14+Submetering!N14+Submetering!P14+Submetering!R14+Submetering!T14+Submetering!V14+Submetering!X14+Submetering!Z14+Submetering!AB14+Submetering!AC14+Submetering!AE14)*0.02095)+(20/30)*15)*1.1048)/E14 -> 0.080715171 | G14: =Submetering!AK14+Submetering!AL14+Submetering!AU14 -> 5166.3014 | H14: 0.8166 | I14: =Submetering!AF14+Submetering!AG14+Submetering!AV14+Submetering!AY14+Submetering!AZ14 -> 5397.7594 | J14: =((Submetering!AG14+Submetering!BA14)*0.8868+(1712.96+1070.52)/30+(Submetering!AF14+Submetering!AY14+Submetering!AV14+Submetering!AZ14)*1.1251+(2076.11+129.67+207.57+207.57)/30+(11680.53+56.61)/30)/I14 -> 1.3449955
A15: Orlando | B15: 24 | C15: 3 | D15: 2019 | E15: =Submetering!F15+Submetering!H15+Submetering!J15+Submetering!L15+Submetering!N15+Submetering!P15+Submetering!R15+Submetering!T15+Submetering!V15+Submetering!X15+Submetering!Z15+Submetering!AB15+Submetering!AC15+Submetering!AD15+Submetering!AE15 -> 286637 | F15: =((((Submetering!E15+Submetering!AD15)*0.13773+(Submetering!E15+Submetering!AD15)*0.02095)*1.09+(2.85/30)*2)+(((Submetering!F15+Submetering!H15+Submetering!J15+Submetering!L15+Submetering!N15+Submetering!P15+Submetering!R15+Submetering!T15+Submetering!V15+Submetering!X15+Submetering!Z15+Submetering!AB15+Submetering!AC15+Submetering!AE15)*0.05155)+((Submetering!F15+Submetering!H15+Submetering!J15+Submetering!L15+Submetering!N15+Submetering!P15+Submetering!R15+Submetering!T15+Submetering!V15+Submetering!X15+Submetering!Z15+Submetering!AB15+Submetering!AC15+Submetering!AE15)*0.02095)+(20/30)*15)*1.1048)/E15 -> 0.080778554 | G15: =Submetering!AK15+Submetering!AL15+Submetering!AU15 -> 7184.3408 | H15: 0.8166 | I15: =Submetering!AF15+Submetering!AG15+Submetering!AV15+Submetering!AY15+Submetering!AZ15 -> 5514.4612 | J15: =((Submetering!AG15+Submetering!BA15)*0.8868+(1712.96+1070.52)/30+(Submetering!AF15+Submetering!AY15+Submetering!AV15+Submetering!AZ15)*1.1251+(2076.11+129.67+207.57+207.57)/30+(11680.53+56.61)/30)/I15 -> 1.3339083 | K15: =Occupancy!H6 -> 11314.008
A16: Orlando | B16: 31 | C16: 3 | D16: 2019 | E16: =Submetering!F16+Submetering!H16+Submetering!J16+Submetering!L16+Submetering!N16+Submetering!P16+Submetering!R16+Submetering!T16+Submetering!V16+Submetering!X16+Submetering!Z16+Submetering!AB16+Submetering!AC16+Submetering!AD16+Submetering!AE16 -> 298201 | F16: =((((Submetering!E16+Submetering!AD16)*0.13773+(Submetering!E16+Submetering!AD16)*0.02095)*1.09+(2.85/30)*2)+(((Submetering!F16+Submetering!H16+Submetering!J16+Submetering!L16+Submetering!N16+Submetering!P16+Submetering!R16+Submetering!T16+Submetering!V16+Submetering!X16+Submetering!Z16+Submetering!AB16+Submetering!AC16+Submetering!AE16)*0.05155)+((Submetering!F16+Submetering!H16+Submetering!J16+Submetering!L16+Submetering!N16+Submetering!P16+Submetering!R16+Submetering!T16+Submetering!V16+Submetering!X16+Submetering!Z16+Submetering!AB16+Submetering!AC16+Submetering!AE16)*0.02095)+(20/30)*15)*1.1048)/E16 -> 0.080725568 | G16: =Submetering!AK16+Submetering!AL16+Submetering!AU16 -> 5616.5254 | H16: 0.8166 | I16: =Submetering!AF16+Submetering!AG16+Submetering!AV16+Submetering!AY16+Submetering!AZ16 -> 5604.2704 | J16: =((Submetering!AG16+Submetering!BA16)*0.8868+(1712.96+1070.52)/30+(Submetering!AF16+Submetering!AY16+Submetering!AV16+Submetering!AZ16)*1.1251+(2076.11+129.67+207.57+207.57)/30+(11680.53+56.61)/30)/I16 -> 1.3647052
A17: Orlando | B17: 8 | C17: 4 | D17: 2019 | E17: =Submetering!F17+Submetering!H17+Submetering!J17+Submetering!L17+Submetering!N17+Submetering!P17+Submetering!R17+Submetering!T17+Submetering!V17+Submetering!X17+Submetering!Z17+Submetering!AB17+Submetering!AC17+Submetering!AD17+Submetering!AE17 -> 317497 | F17: =((((Submetering!E17+Submetering!AD17)*0.13773+(Submetering!E17+Submetering!AD17)*0.02095)*1.09+(2.85/30)*2)+(((Submetering!F17+Submetering!H17+Submetering!J17+Submetering!L17+Submetering!N17+Submetering!P17+Submetering!R17+Submetering!T17+Submetering!V17+Submetering!X17+Submetering!Z17+Submetering!AB17+Submetering!AC17+Submetering!AE17)*0.05155)+((Submetering!F17+Submetering!H17+Submetering!J17+Submetering!L17+Submetering!N17+Submetering!P17+Submetering!R17+Submetering!T17+Submetering!V17+Submetering!X17+Submetering!Z17+Submetering!AB17+Submetering!AC17+Submetering!AE17)*0.02095)+(20/30)*15)*1.1048)/E17 -> 0.080729384 | G17: =Submetering!AK17+Submetering!AL17+Submetering!AU17 -> 4580.7822 | H17: 0.8166 | I17: =Submetering!AF17+Submetering!AG17+Submetering!AV17+Submetering!AY17+Submetering!AZ17 -> 5703.7392 | J17: =((Submetering!AG17+Submetering!BA17)*0.8868+(1712.96+1070.52)/30+(Submetering!AF17+Submetering!AY17+Submetering!AV17+Submetering!AZ17)*1.1251+(2076.11+129.67+207.57+207.57)/30+(11680.53+56.61)/30)/I17 -> 1.3908903
A18: Orlando | B18: 14 | C18: 4 | D18: 2019 | E18: =Submetering!F18+Submetering!H18+Submetering!J18+Submetering!L18+Submetering!N18+Submetering!P18+Submetering!R18+Submetering!T18+Submetering!V18+Submetering!X18+Submetering!Z18+Submetering!AB18+Submetering!AC18+Submetering!AD18+Submetering!AE18 -> 361118 | F18: =((((Submetering!E18+Submetering!AD18)*0.13773+(Submetering!E18+Submetering!AD18)*0.02095)*1.09+(2.85/30)*2)+(((Submetering!F18+Submetering!H18+Submetering!J18+Submetering!L18+Submetering!N18+Submetering!P18+Submetering!R18+Submetering!T18+Submetering!V18+Submetering!X18+Submetering!Z18+Submetering!AB18+Submetering!AC18+Submetering!AE18)*0.05155)+((Submetering!F18+Submetering!H18+Submetering!J18+Submetering!L18+Submetering!N18+Submetering!P18+Submetering!R18+Submetering!T18+Submetering!V18+Submetering!X18+Submetering!Z18+Submetering!AB18+Submetering!AC18+Submetering!AE18)*0.02095)+(20/30)*15)*1.1048)/E18 -> 0.080594177 | G18: =Submetering!AK18+Submetering!AL18+Submetering!AU18 -> 3276.0826 | H18: 0.8166 | I18: =Submetering!AF18+Submetering!AG18+Submetering!AV18+Submetering!AY18+Submetering!AZ18 -> 5416.5656 | J18: =((Submetering!AG18+Submetering!BA18)*0.8868+(1712.96+1070.52)/30+(Submetering!AF18+Submetering!AY18+Submetering!AV18+Submetering!AZ18)*1.1251+(2076.11+129.67+207.57+207.57)/30+(11680.53+56.61)/30)/I18 -> 1.2512445
A19: Orlando | B19: 21 | C19: 4 | D19: 2019 | E19: =Submetering!F19+Submetering!H19+Submetering!J19+Submetering!L19+Submetering!N19+Submetering!P19+Submetering!R19+Submetering!T19+Submetering!V19+Submetering!X19+Submetering!Z19+Submetering!AB19+Submetering!AC19+Submetering!AD19+Submetering!AE19 -> 293799 | F19: =((((Submetering!E19+Submetering!AD19)*0.13773+(Submetering!E19+Submetering!AD19)*0.02095)*1.09+(2.85/30)*2)+(((Submetering!F19+Submetering!H19+Submetering!J19+Submetering!L19+Submetering!N19+Submetering!P19+Submetering!R19+Submetering!T19+Submetering!V19+Submetering!X19+Submetering!Z19+Submetering!AB19+Submetering!AC19+Submetering!AE19)*0.05155)+((Submetering!F19+Submetering!H19+Submetering!J19+Submetering!L19+Submetering!N19+Submetering!P19+Submetering!R19+Submetering!T19+Submetering!V19+Submetering!X19+Submetering!Z19+Submetering!AB19+Submetering!AC19+Submetering!AE19)*0.02095)+(20/30)*15)*1.1048)/E19 -> 0.080743169 | G19: =Submetering!AK19+Submetering!AL19+Submetering!AU19 -> 5036.976 | H19: 0.8166 | I19: =Submetering!AF19+Submetering!AG19+Submetering!AV19+Submetering!AY19+Submetering!AZ19 -> 5784.1738 | J19: =((Submetering!AG19+Submetering!BA19)*0.8868+(1712.96+1070.52)/30+(Submetering!AF19+Submetering!AY19+Submetering!AV19+Submetering!AZ19)*1.1251+(2076.11+129.67+207.57+207.57)/30+(11680.53+56.61)/30)/I19 -> 1.2808135
A20: Orlando | B20: 28 | C20: 4 | D20: 2019 | E20: =Submetering!F20+Submetering!H20+Submetering!J20+Submetering!L20+Submetering!N20+Submetering!P20+Submetering!R20+Submetering!T20+Submetering!V20+Submetering!X20+Submetering!Z20+Submetering!AB20+Submetering!AC20+Submetering!AD20+Submetering!AE20 -> 315499 | F20: =((((Submetering!E20+Submetering!AD20)*0.13773+(Submetering!E20+Submetering!AD20)*0.02095)*1.09+(2.85/30)*2)+(((Submetering!F20+Submetering!H20+Submetering!J20+Submetering!L20+Submetering!N20+Submetering!P20+Submetering!R20+Submetering!T20+Submetering!V20+Submetering!X20+Submetering!Z20+Submetering!AB20+Submetering!AC20+Submetering!AE20)*0.05155)+((Submetering!F20+Submetering!H20+Submetering!J20+Submetering!L20+Submetering!N20+Submetering!P20+Submetering!R20+Submetering!T20+Submetering!V20+Submetering!X20+Submetering!Z20+Submetering!AB20+Submetering!AC20+Submetering!AE20)*0.02095)+(20/30)*15)*1.1048)/E20 -> 0.080664257 | G20: =Submetering!AK20+Submetering!AL20+Submetering!AU20 -> 3864.258 | H20: 0.8166 | I20: =Submetering!AF20+Submetering!AG20+Submetering!AV20+Submetering!AY20+Submetering!AZ20 -> 5118.1972 | J20: =((Submetering!AG20+Submetering!BA20)*0.8868+(1712.96+1070.52)/30+(Submetering!AF20+Submetering!AY20+Submetering!AV20+Submetering!AZ20)*1.1251+(2076.11+129.67+207.57+207.57)/30+(11680.53+56.61)/30)/I20 -> 1.5293404 | K20: =Occupancy!H7 -> 10389.6
A21: Orlando | B21: 30 | C21: 4 | D21: 2019 | E21: =Submetering!F21+Submetering!H21+Submetering!J21+Submetering!L21+Submetering!N21+Submetering!P21+Submetering!R21+Submetering!T21+Submetering!V21+Submetering!X21+Submetering!Z21+Submetering!AB21+Submetering!AC21+Submetering!AD21+Submetering!AE21 -> 125450 | F21: =((((Submetering!E21+Submetering!AD21)*0.13773+(Submetering!E21+Submetering!AD21)*0.02095)*1.09+(2.85/30)*2)+(((Submetering!F21+Submetering!H21+Submetering!J21+Submetering!L21+Submetering!N21+Submetering!P21+Submetering!R21+Submetering!T21+Submetering!V21+Submetering!X21+Submetering!Z21+Submetering!AB21+Submetering!AC21+Submetering!AE21)*0.05155)+((Submetering!F21+Submetering!H21+Submetering!J21+Submetering!L21+Submetering!N21+Submetering!P21+Submetering!R21+Submetering!T21+Submetering!V21+Submetering!X21+Submetering!Z21+Submetering!AB21+Submetering!AC21+Submetering!AE21)*0.02095)+(20/30)*15)*1.1048)/E21 -> 0.080638736 | G21: =Submetering!AK21+Submetering!AL21+Submetering!AU21 -> 1155.3216 | H21: 0.8166 | I21: =Submetering!AF21+Submetering!AG21+Submetering!AV21+Submetering!AY21+Submetering!AZ21 -> 1979.5264 | J21: =((Submetering!AG21+Submetering!BA21)*0.8868+(1712.96+1070.52)/30+(Submetering!AF21+Submetering!AY21+Submetering!AV21+Submetering!AZ21)*1.1251+(2076.11+129.67+207.57+207.57)/30+(11680.53+56.61)/30)/I21 -> 1.7396392
A22: Orlando | B22: 5 | C22: 5 | D22: 2019 | E22: =Submetering!F22+Submetering!H22+Submetering!J22+Submetering!L22+Submetering!N22+Submetering!P22+Submetering!R22+Submetering!T22+Submetering!V22+Submetering!X22+Submetering!Z22+Submetering!AB22+Submetering!AC22+Submetering!AD22+Submetering!AE22 -> 235333 | F22: =((((Submetering!E22+Submetering!AD22)*0.13773+(Submetering!E22+Submetering!AD22)*0.02095)*1.09+(2.85/30)*2)+(((Submetering!F22+Submetering!H22+Submetering!J22+Submetering!L22+Submetering!N22+Submetering!P22+Submetering!R22+Submetering!T22+Submetering!V22+Submetering!X22+Submetering!Z22+Submetering!AB22+Submetering!AC22+Submetering!AE22)*0.05155)+((Submetering!F22+Submetering!H22+Submetering!J22+Submetering!L22+Submetering!N22+Submetering!P22+Submetering!R22+Submetering!T22+Submetering!V22+Submetering!X22+Submetering!Z22+Submetering!AB22+Submetering!AC22+Submetering!AE22)*0.02095)+(20/30)*15)*1.1048)/E22 -> 0.080630726 | G22: =Submetering!AK22+Submetering!AL22+Submetering!AU22 -> 1732.0248 | H22: 0.8166 | I22: =Submetering!AF22+Submetering!AG22+Submetering!AV22+Submetering!AY22+Submetering!AZ22 -> 3485.9148 | J22: =((Submetering!AG22+Submetering!BA22)*0.8868+(1712.96+1070.52)/30+(Submetering!AF22+Submetering!AY22+Submetering!AV22+Submetering!AZ22)*1.1251+(2076.11+129.67+207.57+207.57)/30+(11680.53+56.61)/30)/I22 -> 1.452091
A23: Orlando | B23: 13 | C23: 5 | D23: 2019 | E23: =Submetering!F23+Submetering!H23+Submetering!J23+Submetering!L23+Submetering!N23+Submetering!P23+Submetering!R23+Submetering!T23+Submetering!V23+Submetering!X23+Submetering!Z23+Submetering!AB23+Submetering!AC23+Submetering!AD23+Submetering!AE23 -> 365641 | F23: =((((Submetering!E23+Submetering!AD23)*0.13773+(Submetering!E23+Submetering!AD23)*0.02095)*1.09+(2.85/30)*2)+(((Submetering!F23+Submetering!H23+Submetering!J23+Submetering!L23+Submetering!N23+Submetering!P23+Submetering!R23+Submetering!T23+Submetering!V23+Submetering!X23+Submetering!Z23+Submetering!AB23+Submetering!AC23+Submetering!AE23)*0.05155)+((Submetering!F23+Submetering!H23+Submetering!J23+Submetering!L23+Submetering!N23+Submetering!P23+Submetering!R23+Submetering!T23+Submetering!V23+Submetering!X23+Submetering!Z23+Submetering!AB23+Submetering!AC23+Submetering!AE23)*0.02095)+(20/30)*15)*1.1048)/E23 -> 0.080591369 | G23: =Submetering!AK23+Submetering!AL23+Submetering!AU23 -> 2431.24 | H23: 0.8166 | I23: =Submetering!AF23+Submetering!AG23+Submetering!AV23+Submetering!AY23+Submetering!AZ23 -> 5757.2964 | J23: =((Submetering!AG23+Submetering!BA23)*0.8868+(1712.96+1070.52)/30+(Submetering!AF23+Submetering!AY23+Submetering!AV23+Submetering!AZ23)*1.1251+(2076.11+129.67+207.57+207.57)/30+(11680.53+56.61)/30)/I23 -> 1.3190278
A24: Orlando | B24: 20 | C24: 5 | D24: 2019 | E24: =Submetering!F24+Submetering!H24+Submetering!J24+Submetering!L24+Submetering!N24+Submetering!P24+Submetering!R24+Submetering!T24+Submetering!V24+Submetering!X24+Submetering!Z24+Submetering!AB24+Submetering!AC24+Submetering!AD24+Submetering!AE24 -> 343568 | F24: =((((Submetering!E24+Submetering!AD24)*0.13773+(Submetering!E24+Submetering!AD24)*0.02095)*1.09+(2.85/30)*2)+(((Submetering!F24+Submetering!H24+Submetering!J24+Submetering!L24+Submetering!N24+Submetering!P24+Submetering!R24+Submetering!T24+Submetering!V24+Submetering!X24+Submetering!Z24+Submetering!AB24+Submetering!AC24+Submetering!AE24)*0.05155)+((Submetering!F24+Submetering!H24+Submetering!J24+Submetering!L24+Submetering!N24+Submetering!P24+Submetering!R24+Submetering!T24+Submetering!V24+Submetering!X24+Submetering!Z24+Submetering!AB24+Submetering!AC24+Submetering!AE24)*0.02095)+(20/30)*15)*1.1048)/E24 -> 0.080630124 | G24: =Submetering!AK24+Submetering!AL24+Submetering!AU24 -> 2881.8516 | H24: 0.8166 | I24: =Submetering!AF24+Submetering!AG24+Submetering!AV24+Submetering!AY24+Submetering!AZ24 -> 5232.1592 | J24: =((Submetering!AG24+Submetering!BA24)*0.8868+(1712.96+1070.52)/30+(Submetering!AF24+Submetering!AY24+Submetering!AV24+Submetering!AZ24)*1.1251+(2076.11+129.67+207.57+207.57)/30+(11680.53+56.61)/30)/I24 -> 1.2953904
A25: Orlando | B25: 26 | C25: 5 | D25: 2019 | E25: =Submetering!F25+Submetering!H25+Submetering!J25+Submetering!L25+Submetering!N25+Submetering!P25+Submetering!R25+Submetering!T25+Submetering!V25+Submetering!X25+Submetering!Z25+Submetering!AB25+Submetering!AC25+Submetering!AD25+Submetering!AE25 -> 364698 | F25: =((((Submetering!E25+Submetering!AD25)*0.13773+(Submetering!E25+Submetering!AD25)*0.02095)*1.09+(2.85/30)*2)+(((Submetering!F25+Submetering!H25+Submetering!J25+Submetering!L25+Submetering!N25+Submetering!P25+Submetering!R25+Submetering!T25+Submetering!V25+Submetering!X25+Submetering!Z25+Submetering!AB25+Submetering!AC25+Submetering!AE25)*0.05155)+((Submetering!F25+Submetering!H25+Submetering!J25+Submetering!L25+Submetering!N25+Submetering!P25+Submetering!R25+Submetering!T25+Submetering!V25+Submetering!X25+Submetering!Z25+Submetering!AB25+Submetering!AC25+Submetering!AE25)*0.02095)+(20/30)*15)*1.1048)/E25 -> 0.080575756 | G25: =Submetering!AK25+Submetering!AL25+Submetering!AU25 -> 2328.1688 | H25: 0.8166 | I25: =Submetering!AF25+Submetering!AG25+Submetering!AV25+Submetering!AY25+Submetering!AZ25 -> 5687.4942 | J25: =((Submetering!AG25+Submetering!BA25)*0.8868+(1712.96+1070.52)/30+(Submetering!AF25+Submetering!AY25+Submetering!AV25+Submetering!AZ25)*1.1251+(2076.11+129.67+207.57+207.57)/30+(11680.53+56.61)/30)/I25 -> 1.5156292 | K25: =Occupancy!H8 -> 10749.684
A26: Orlando | B26: 31 | C26: 5 | D26: 2019 | E26: =Submetering!F26+Submetering!H26+Submetering!J26+Submetering!L26+Submetering!N26+Submetering!P26+Submetering!R26+Submetering!T26+Submetering!V26+Submetering!X26+Submetering!Z26+Submetering!AB26+Submetering!AC26+Submetering!AD26+Submetering!AE26 -> 373932 | F26: =((((Submetering!E26+Submetering!AD26)*0.13773+(Submetering!E26+Submetering!AD26)*0.02095)*1.09+(2.85/30)*2)+(((Submetering!F26+Submetering!H26+Submetering!J26+Submetering!L26+Submetering!N26+Submetering!P26+Submetering!R26+Submetering!T26+Submetering!V26+Submetering!X26+Submetering!Z26+Submetering!AB26+Submetering!AC26+Submetering!AE26)*0.05155)+((Submetering!F26+Submetering!H26+Submetering!J26+Submetering!L26+Submetering!N26+Submetering!P26+Submetering!R26+Submetering!T26+Submetering!V26+Submetering!X26+Submetering!Z26+Submetering!AB26+Submetering!AC26+Submetering!AE26)*0.02095)+(20/30)*15)*1.1048)/E26 -> 0.080482316 | G26: =Submetering!AK26+Submetering!AL26+Submetering!AU26 -> 1431.3954 | H26: 0.8166 | I26: =Submetering!AF26+Submetering!AG26+Submetering!AV26+Submetering!AY26+Submetering!AZ26 -> 6628.7466 | J26: =((Submetering!AG26+Submetering!BA26)*0.8868+(1712.96+1070.52)/30+(Submetering!AF26+Submetering!AY26+Submetering!AV26+Submetering!AZ26)*1.1251+(2076.11+129.67+207.57+207.57)/30+(11680.53+56.61)/30)/I26 -> 1.3879708
A27: Orlando | B27: 9 | C27: 6 | D27: 2019 | E27: =Submetering!F27+Submetering!H27+Submetering!J27+Submetering!L27+Submetering!N27+Submetering!P27+Submetering!R27+Submetering!T27+Submetering!V27+Submetering!X27+Submetering!Z27+Submetering!AB27+Submetering!AC27+Submetering!AD27+Submetering!AE27 -> 417150 | F27: =((((Submetering!E27+Submetering!AD27)*0.13773+(Submetering!E27+Submetering!AD27)*0.02095)*1.09+(2.85/30)*2)+(((Submetering!F27+Submetering!H27+Submetering!J27+Submetering!L27+Submetering!N27+Submetering!P27+Submetering!R27+Submetering!T27+Submetering!V27+Submetering!X27+Submetering!Z27+Submetering!AB27+Submetering!AC27+Submetering!AE27)*0.05155)+((Submetering!F27+Submetering!H27+Submetering!J27+Submetering!L27+Submetering!N27+Submetering!P27+Submetering!R27+Submetering!T27+Submetering!V27+Submetering!X27+Submetering!Z27+Submetering!AB27+Submetering!AC27+Submetering!AE27)*0.02095)+(20/30)*15)*1.1048)/E27 -> 0.080605959 | G27: =Submetering!AK27+Submetering!AL27+Submetering!AU27 -> 1496.2424 | H27: 0.8166 | I27: =Submetering!AF27+Submetering!AG27+Submetering!AV27+Submetering!AY27+Submetering!AZ27 -> 7053.1876 | J27: =((Submetering!AG27+Submetering!BA27)*0.8868+(1712.96+1070.52)/30+(Submetering!AF27+Submetering!AY27+Submetering!AV27+Submetering!AZ27)*1.1251+(2076.11+129.67+207.57+207.57)/30+(11680.53+56.61)/30)/I27 -> 1.3023518
A28: Orlando | B28: 16 | C28: 6 | D28: 2019 | E28: =Submetering!F28+Submetering!H28+Submetering!J28+Submetering!L28+Submetering!N28+Submetering!P28+Submetering!R28+Submetering!T28+Submetering!V28+Submetering!X28+Submetering!Z28+Submetering!AB28+Submetering!AC28+Submetering!AD28+Submetering!AE28 -> 377786 | F28: =((((Submetering!E28+Submetering!AD28)*0.13773+(Submetering!E28+Submetering!AD28)*0.02095)*1.09+(2.85/30)*2)+(((Submetering!F28+Submetering!H28+Submetering!J28+Submetering!L28+Submetering!N28+Submetering!P28+Submetering!R28+Submetering!T28+Submetering!V28+Submetering!X28+Submetering!Z28+Submetering!AB28+Submetering!AC28+Submetering!AE28)*0.05155)+((Submetering!F28+Submetering!H28+Submetering!J28+Submetering!L28+Submetering!N28+Submetering!P28+Submetering!R28+Submetering!T28+Submetering!V28+Submetering!X28+Submetering!Z28+Submetering!AB28+Submetering!AC28+Submetering!AE28)*0.02095)+(20/30)*15)*1.1048)/E28 -> 0.080562544 | G28: =Submetering!AK28+Submetering!AL28+Submetering!AU28 -> 1938.703 | H28: 0.8166 | I28: =Submetering!AF28+Submetering!AG28+Submetering!AV28+Submetering!AY28+Submetering!AZ28 -> 6189.9378 | J28: =((Submetering!AG28+Submetering!BA28)*0.8868+(1712.96+1070.52)/30+(Submetering!AF28+Submetering!AY28+Submetering!AV28+Submetering!AZ28)*1.1251+(2076.11+129.67+207.57+207.57)/30+(11680.53+56.61)/30)/I28 -> 1.192097
A29: Orlando | B29: 21 | C29: 6 | D29: 2019 | E29: =Submetering!F29+Submetering!H29+Submetering!J29+Submetering!L29+Submetering!N29+Submetering!P29+Submetering!R29+Submetering!T29+Submetering!V29+Submetering!X29+Submetering!Z29+Submetering!AB29+Submetering!AC29+Submetering!AD29+Submetering!AE29 -> 398825 | F29: =((((Submetering!E29+Submetering!AD29)*0.13773+(Submetering!E29+Submetering!AD29)*0.02095)*1.09+(2.85/30)*2)+(((Submetering!F29+Submetering!H29+Submetering!J29+Submetering!L29+Submetering!N29+Submetering!P29+Submetering!R29+Submetering!T29+Submetering!V29+Submetering!X29+Submetering!Z29+Submetering!AB29+Submetering!AC29+Submetering!AE29)*0.05155)+((Submetering!F29+Submetering!H29+Submetering!J29+Submetering!L29+Submetering!N29+Submetering!P29+Submetering!R29+Submetering!T29+Submetering!V29+Submetering!X29+Submetering!Z29+Submetering!AB29+Submetering!AC29+Submetering!AE29)*0.02095)+(20/30)*15)*1.1048)/E29 -> 0.080535637 | G29: =Submetering!AK29+Submetering!AL29+Submetering!AU29 -> 1587.8566 | H29: 0.8166 | I29: =Submetering!AF29+Submetering!AG29+Submetering!AV29+Submetering!AY29+Submetering!AZ29 -> 5632.3524 | J29: =((Submetering!AG29+Submetering!BA29)*0.8868+(1712.96+1070.52)/30+(Submetering!AF29+Submetering!AY29+Submetering!AV29+Submetering!AZ29)*1.1251+(2076.11+129.67+207.57+207.57)/30+(11680.53+56.61)/30)/I29 -> 1.2091908
A30: Orlando | B30: 30 | C30: 6 | D30: 2019 | E30: =Submetering!F30+Submetering!H30+Submetering!J30+Submetering!L30+Submetering!N30+Submetering!P30+Submetering!R30+Submetering!T30+Submetering!V30+Submetering!X30+Submetering!Z30+Submetering!AB30+Submetering!AC30+Submetering!AD30+Submetering!AE30 -> 402693 | F30: =((((Submetering!E30+Submetering!AD30)*0.13773+(Submetering!E30+Submetering!AD30)*0.02095)*1.09+(2.85/30)*2)+(((Submetering!F30+Submetering!H30+Submetering!J30+Submetering!L30+Submetering!N30+Submetering!P30+Submetering!R30+Submetering!T30+Submetering!V30+Submetering!X30+Submetering!Z30+Submetering!AB30+Submetering!AC30+Submetering!AE30)*0.05155)+((Submetering!F30+Submetering!H30+Submetering!J30+Submetering!L30+Submetering!N30+Submetering!P30+Submetering!R30+Submetering!T30+Submetering!V30+Submetering!X30+Submetering!Z30+Submetering!AB30+Submetering!AC30+Submetering!AE30)*0.02095)+(20/30)*15)*1.1048)/E30 -> 0.080531561 | G30: =Submetering!AK30+Submetering!AL30+Submetering!AU30 -> 1390.3972 | H30: 0.8166 | I30: =Submetering!AF30+Submetering!AG30+Submetering!AV30+Submetering!AY30+Submetering!AZ30 -> 6934.6276 | J30: =((Submetering!AG30+Submetering!BA30)*0.8868+(1712.96+1070.52)/30+(Submetering!AF30+Submetering!AY30+Submetering!AV30+Submetering!AZ30)*1.1251+(2076.11+129.67+207.57+207.57)/30+(11680.53+56.61)/30)/I30 -> 1.2895976 | K30: =Occupancy!H9 -> 10762.56
A31: Orlando | B31: 8 | C31: 7 | D31: 2019 | E31: =Submetering!F31+Submetering!H31+Submetering!J31+Submetering!L31+Submetering!N31+Submetering!P31+Submetering!R31+Submetering!T31+Submetering!V31+Submetering!X31+Submetering!Z31+Submetering!AB31+Submetering!AC31+Submetering!AD31+Submetering!AE31 -> 410334 | F31: =((((Submetering!E31+Submetering!AD31)*0.13773+(Submetering!E31+Submetering!AD31)*0.02095)*1.09+(2.85/30)*2)+(((Submetering!F31+Submetering!H31+Submetering!J31+Submetering!L31+Submetering!N31+Submetering!P31+Submetering!R31+Submetering!T31+Submetering!V31+Submetering!X31+Submetering!Z31+Submetering!AB31+Submetering!AC31+Submetering!AE31)*0.05155)+((Submetering!F31+Submetering!H31+Submetering!J31+Submetering!L31+Submetering!N31+Submetering!P31+Submetering!R31+Submetering!T31+Submetering!V31+Submetering!X31+Submetering!Z31+Submetering!AB31+Submetering!AC31+Submetering!AE31)*0.02095)+(20/30)*15)*1.1048)/E31 -> 0.080546054 | G31: =Submetering!AK31+Submetering!AL31+Submetering!AU31 -> 1263.1162 | H31: 0.8166 | I31: =Submetering!AF31+Submetering!AG31+Submetering!AV31+Submetering!AY31+Submetering!AZ31 -> 6850.602 | J31: =((Submetering!AG31+Submetering!BA31)*0.8868+(1712.96+1070.52)/30+(Submetering!AF31+Submetering!AY31+Submetering!AV31+Submetering!AZ31)*1.1251+(2076.11+129.67+207.57+207.57)/30+(11680.53+56.61)/30)/I31 -> 1.3015635
A32: Orlando | B32: 15 | C32: 7 | D32: 2019 | E32: =Submetering!F32+Submetering!H32+Submetering!J32+Submetering!L32+Submetering!N32+Submetering!P32+Submetering!R32+Submetering!T32+Submetering!V32+Submetering!X32+Submetering!Z32+Submetering!AB32+Submetering!AC32+Submetering!AD32+Submetering!AE32 -> 408096 | F32: =((((Submetering!E32+Submetering!AD32)*0.13773+(Submetering!E32+Submetering!AD32)*0.02095)*1.09+(2.85/30)*2)+(((Submetering!F32+Submetering!H32+Submetering!J32+Submetering!L32+Submetering!N32+Submetering!P32+Submetering!R32+Submetering!T32+Submetering!V32+Submetering!X32+Submetering!Z32+Submetering!AB32+Submetering!AC32+Submetering!AE32)*0.05155)+((Submetering!F32+Submetering!H32+Submetering!J32+Submetering!L32+Submetering!N32+Submetering!P32+Submetering!R32+Submetering!T32+Submetering!V32+Submetering!X32+Submetering!Z32+Submetering!AB32+Submetering!AC32+Submetering!AE32)*0.02095)+(20/30)*15)*1.1048)/E32 -> 0.080593608 | G32: =Submetering!AK32+Submetering!AL32+Submetering!AU32 -> 1361.6958 | H32: 0.8166 | I32: =Submetering!AF32+Submetering!AG32+Submetering!AV32+Submetering!AY32+Submetering!AZ32 -> 6548.9846 | J32: =((Submetering!AG32+Submetering!BA32)*0.8868+(1712.96+1070.52)/30+(Submetering!AF32+Submetering!AY32+Submetering!AV32+Submetering!AZ32)*1.1251+(2076.11+129.67+207.57+207.57)/30+(11680.53+56.61)/30)/I32 -> 1.1866247
A33: Orlando | B33: 21 | C33: 7 | D33: 2019 | E33: =Submetering!F33+Submetering!H33+Submetering!J33+Submetering!L33+Submetering!N33+Submetering!P33+Submetering!R33+Submetering!T33+Submetering!V33+Submetering!X33+Submetering!Z33+Submetering!AB33+Submetering!AC33+Submetering!AD33+Submetering!AE33 -> 388058 | F33: =((((Submetering!E33+Submetering!AD33)*0.13773+(Submetering!E33+Submetering!AD33)*0.02095)*1.09+(2.85/30)*2)+(((Submetering!F33+Submetering!H33+Submetering!J33+Submetering!L33+Submetering!N33+Submetering!P33+Submetering!R33+Submetering!T33+Submetering!V33+Submetering!X33+Submetering!Z33+Submetering!AB33+Submetering!AC33+Submetering!AE33)*0.05155)+((Submetering!F33+Submetering!H33+Submetering!J33+Submetering!L33+Submetering!N33+Submetering!P33+Submetering!R33+Submetering!T33+Submetering!V33+Submetering!X33+Submetering!Z33+Submetering!AB33+Submetering!AC33+Submetering!AE33)*0.02095)+(20/30)*15)*1.1048)/E33 -> 0.080483886 | G33: =Submetering!AK33+Submetering!AL33+Submetering!AU33 -> 1376.9908 | H33: 0.8166 | I33: =Submetering!AF33+Submetering!AG33+Submetering!AV33+Submetering!AY33+Submetering!AZ33 -> 5987.014 | J33: =((Submetering!AG33+Submetering!BA33)*0.8868+(1712.96+1070.52)/30+(Submetering!AF33+Submetering!AY33+Submetering!AV33+Submetering!AZ33)*1.1251+(2076.11+129.67+207.57+207.57)/30+(11680.53+56.61)/30)/I33 -> 1.1979216
A34: Orlando | B34: 28 | C34: 7 | D34: 2019 | E34: =Submetering!F34+Submetering!H34+Submetering!J34+Submetering!L34+Submetering!N34+Submetering!P34+Submetering!R34+Submetering!T34+Submetering!V34+Submetering!X34+Submetering!Z34+Submetering!AB34+Submetering!AC34+Submetering!AD34+Submetering!AE34 -> 390122 | F34: =((((Submetering!E34+Submetering!AD34)*0.13773+(Submetering!E34+Submetering!AD34)*0.02095)*1.09+(2.85/30)*2)+(((Submetering!F34+Submetering!H34+Submetering!J34+Submetering!L34+Submetering!N34+Submetering!P34+Submetering!R34+Submetering!T34+Submetering!V34+Submetering!X34+Submetering!Z34+Submetering!AB34+Submetering!AC34+Submetering!AE34)*0.05155)+((Submetering!F34+Submetering!H34+Submetering!J34+Submetering!L34+Submetering!N34+Submetering!P34+Submetering!R34+Submetering!T34+Submetering!V34+Submetering!X34+Submetering!Z34+Submetering!AB34+Submetering!AC34+Submetering!AE34)*0.02095)+(20/30)*15)*1.1048)/E34 -> 0.080565038 | G34: =Submetering!AK34+Submetering!AL34+Submetering!AU34 -> 1685.3418 | H34: 0.8166 | I34: =Submetering!AF34+Submetering!AG34+Submetering!AV34+Submetering!AY34+Submetering!AZ34 -> 6130.8858 | J34: =((Submetering!AG34+Submetering!BA34)*0.8868+(1712.96+1070.52)/30+(Submetering!AF34+Submetering!AY34+Submetering!AV34+Submetering!AZ34)*1.1251+(2076.11+129.67+207.57+207.57)/30+(11680.53+56.61)/30)/I34 -> 1.1944553
A35: Orlando | B35: 31 | C35: 7 | D35: 2019 | E35: =Submetering!F35+Submetering!H35+Submetering!J35+Submetering!L35+Submetering!N35+Submetering!P35+Submetering!R35+Submetering!T35+Submetering!V35+Submetering!X35+Submetering!Z35+Submetering!AB35+Submetering!AC35+Submetering!AD35+Submetering!AE35 -> 168225 | F35: =((((Submetering!E35+Submetering!AD35)*0.13773+(Submetering!E35+Submetering!AD35)*0.02095)*1.09+(2.85/30)*2)+(((Submetering!F35+Submetering!H35+Submetering!J35+Submetering!L35+Submetering!N35+Submetering!P35+Submetering!R35+Submetering!T35+Submetering!V35+Submetering!X35+Submetering!Z35+Submetering!AB35+Submetering!AC35+Submetering!AE35)*0.05155)+((Submetering!F35+Submetering!H35+Submetering!J35+Submetering!L35+Submetering!N35+Submetering!P35+Submetering!R35+Submetering!T35+Submetering!V35+Submetering!X35+Submetering!Z35+Submetering!AB35+Submetering!AC35+Submetering!AE35)*0.02095)+(20/30)*15)*1.1048)/E35 -> 0.080400636 | G35: =Submetering!AK35+Submetering!AL35+Submetering!AU35 -> 511.8752 | H35: 0.8166 | I35: =Submetering!AF35+Submetering!AG35+Submetering!AV35+Submetering!AY35+Submetering!AZ35 -> 2824.5932 | J35: =((Submetering!AG35+Submetering!BA35)*0.8868+(1712.96+1070.52)/30+(Submetering!AF35+Submetering!AY35+Submetering!AV35+Submetering!AZ35)*1.1251+(2076.11+129.67+207.57+207.57)/30+(11680.53+56.61)/30)/I35 -> 1.3050508 | K35: =Occupancy!H10 -> 11121.312
A36: Orlando | B36: 5 | C36: 8 | D36: 2019 | E36: =Submetering!F36+Submetering!H36+Submetering!J36+Submetering!L36+Submetering!N36+Submetering!P36+Submetering!R36+Submetering!T36+Submetering!V36+Submetering!X36+Submetering!Z36+Submetering!AB36+Submetering!AC36+Submetering!AD36+Submetering!AE36 -> 239598 | F36: =((((Submetering!E36+Submetering!AD36)*0.13773+(Submetering!E36+Submetering!AD36)*0.02095)*1.09+(2.85/30)*2)+(((Submetering!F36+Submetering!H36+Submetering!J36+Submetering!L36+Submetering!N36+Submetering!P36+Submetering!R36+Submetering!T36+Submetering!V36+Submetering!X36+Submetering!Z36+Submetering!AB36+Submetering!AC36+Submetering!AE36)*0.05155)+((Submetering!F36+Submetering!H36+Submetering!J36+Submetering!L36+Submetering!N36+Submetering!P36+Submetering!R36+Submetering!T36+Submetering!V36+Submetering!X36+Submetering!Z36+Submetering!AB36+Submetering!AC36+Submetering!AE36)*0.02095)+(20/30)*15)*1.1048)/E36 -> 0.080546662 | G36: =Submetering!AK36+Submetering!AL36+Submetering!AU36 -> 867.4222 | H36: 0.8166 | I36: =Submetering!AF36+Submetering!AG36+Submetering!AV36+Submetering!AY36+Submetering!AZ36 -> 3704.867 | J36: =((Submetering!AG36+Submetering!BA36)*0.8868+(1712.96+1070.52)/30+(Submetering!AF36+Submetering!AY36+Submetering!AV36+Submetering!AZ36)*1.1251+(2076.11+129.67+207.57+207.57)/30+(11680.53+56.61)/30)/I36 -> 1.2641377
A37: Orlando | B37: 12 | C37: 8 | D37: 2019 | E37: =Submetering!F37+Submetering!H37+Submetering!J37+Submetering!L37+Submetering!N37+Submetering!P37+Submetering!R37+Submetering!T37+Submetering!V37+Submetering!X37+Submetering!Z37+Submetering!AB37+Submetering!AC37+Submetering!AD37+Submetering!AE37 -> 406078 | F37: =((((Submetering!E37+Submetering!AD37)*0.13773+(Submetering!E37+Submetering!AD37)*0.02095)*1.09+(2.85/30)*2)+(((Submetering!F37+Submetering!H37+Submetering!J37+Submetering!L37+Submetering!N37+Submetering!P37+Submetering!R37+Submetering!T37+Submetering!V37+Submetering!X37+Submetering!Z37+Submetering!AB37+Submetering!AC37+Submetering!AE37)*0.05155)+((Submetering!F37+Submetering!H37+Submetering!J37+Submetering!L37+Submetering!N37+Submetering!P37+Submetering!R37+Submetering!T37+Submetering!V37+Submetering!X37+Submetering!Z37+Submetering!AB37+Submetering!AC37+Submetering!AE37)*0.02095)+(20/30)*15)*1.1048)/E37 -> 0.080487034 | G37: =Submetering!AK37+Submetering!AL37+Submetering!AU37 -> 1402.9562 | H37: 0.8166 | I37: =Submetering!AF37+Submetering!AG37+Submetering!AV37+Submetering!AY37+Submetering!AZ37 -> 5715.6674 | J37: =((Submetering!AG37+Submetering!BA37)*0.8868+(1712.96+1070.52)/30+(Submetering!AF37+Submetering!AY37+Submetering!AV37+Submetering!AZ37)*1.1251+(2076.11+129.67+207.57+207.57)/30+(11680.53+56.61)/30)/I37 -> 1.2116975
A38: Orlando | B38: 19 | C38: 8 | D38: 2019 | E38: =Submetering!F38+Submetering!H38+Submetering!J38+Submetering!L38+Submetering!N38+Submetering!P38+Submetering!R38+Submetering!T38+Submetering!V38+Submetering!X38+Submetering!Z38+Submetering!AB38+Submetering!AC38+Submetering!AD38+Submetering!AE38 -> 405474 | F38: =((((Submetering!E38+Submetering!AD38)*0.13773+(Submetering!E38+Submetering!AD38)*0.02095)*1.09+(2.85/30)*2)+(((Submetering!F38+Submetering!H38+Submetering!J38+Submetering!L38+Submetering!N38+Submetering!P38+Submetering!R38+Submetering!T38+Submetering!V38+Submetering!X38+Submetering!Z38+Submetering!AB38+Submetering!AC38+Submetering!AE38)*0.05155)+((Submetering!F38+Submetering!H38+Submetering!J38+Submetering!L38+Submetering!N38+Submetering!P38+Submetering!R38+Submetering!T38+Submetering!V38+Submetering!X38+Submetering!Z38+Submetering!AB38+Submetering!AC38+Submetering!AE38)*0.02095)+(20/30)*15)*1.1048)/E38 -> 0.080503852 | G38: =Submetering!AK38+Submetering!AL38+Submetering!AU38 -> 1440.1924 | H38: 0.8166 | I38: =Submetering!AF38+Submetering!AG38+Submetering!AV38+Submetering!AY38+Submetering!AZ38 -> 5293.3392 | J38: =((Submetering!AG38+Submetering!BA38)*0.8868+(1712.96+1070.52)/30+(Submetering!AF38+Submetering!AY38+Submetering!AV38+Submetering!AZ38)*1.1251+(2076.11+129.67+207.57+207.57)/30+(11680.53+56.61)/30)/I38 -> 1.2390699
A39: Orlando | B39: 26 | C39: 8 | D39: 2019 | E39: =Submetering!F39+Submetering!H39+Submetering!J39+Submetering!L39+Submetering!N39+Submetering!P39+Submetering!R39+Submetering!T39+Submetering!V39+Submetering!X39+Submetering!Z39+Submetering!AB39+Submetering!AC39+Submetering!AD39+Submetering!AE39 -> 418854 | F39: =((((Submetering!E39+Submetering!AD39)*0.13773+(Submetering!E39+Submetering!AD39)*0.02095)*1.09+(2.85/30)*2)+(((Submetering!F39+Submetering!H39+Submetering!J39+Submetering!L39+Submetering!N39+Submetering!P39+Submetering!R39+Submetering!T39+Submetering!V39+Submetering!X39+Submetering!Z39+Submetering!AB39+Submetering!AC39+Submetering!AE39)*0.05155)+((Submetering!F39+Submetering!H39+Submetering!J39+Submetering!L39+Submetering!N39+Submetering!P39+Submetering!R39+Submetering!T39+Submetering!V39+Submetering!X39+Submetering!Z39+Submetering!AB39+Submetering!AC39+Submetering!AE39)*0.02095)+(20/30)*15)*1.1048)/E39 -> 0.080477585 | G39: =Submetering!AK39+Submetering!AL39+Submetering!AU39 -> 1437.8858 | H39: 0.8166 | I39: =Submetering!AF39+Submetering!AG39+Submetering!AV39+Submetering!AY39+Submetering!AZ39 -> 6683.25 | J39: =((Submetering!AG39+Submetering!BA39)*0.8868+(1712.96+1070.52)/30+(Submetering!AF39+Submetering!AY39+Submetering!AV39+Submetering!AZ39)*1.1251+(2076.11+129.67+207.57+207.57)/30+(11680.53+56.61)/30)/I39 -> 1.3410749
A40: Orlando | B40: 31 | C40: 8 | D40: 2019 | E40: =Submetering!F40+Submetering!H40+Submetering!J40+Submetering!L40+Submetering!N40+Submetering!P40+Submetering!R40+Submetering!T40+Submetering!V40+Submetering!X40+Submetering!Z40+Submetering!AB40+Submetering!AC40+Submetering!AD40+Submetering!AE40 -> 372433 | F40: =((((Submetering!E40+Submetering!AD40)*0.13773+(Submetering!E40+Submetering!AD40)*0.02095)*1.09+(2.85/30)*2)+(((Submetering!F40+Submetering!H40+Submetering!J40+Submetering!L40+Submetering!N40+Submetering!P40+Submetering!R40+Submetering!T40+Submetering!V40+Submetering!X40+Submetering!Z40+Submetering!AB40+Submetering!AC40+Submetering!AE40)*0.05155)+((Submetering!F40+Submetering!H40+Submetering!J40+Submetering!L40+Submetering!N40+Submetering!P40+Submetering!R40+Submetering!T40+Submetering!V40+Submetering!X40+Submetering!Z40+Submetering!AB40+Submetering!AC40+Submetering!AE40)*0.02095)+(20/30)*15)*1.1048)/E40 -> 0.080508172 | G40: =Submetering!AK40+Submetering!AL40+Submetering!AU40 -> 1184.2738 | H40: 0.8166 | I40: =Submetering!AF40+Submetering!AG40+Submetering!AV40+Submetering!AY40+Submetering!AZ40 -> 4336.123 | J40: =((Submetering!AG40+Submetering!BA40)*0.8868+(1712.96+1070.52)/30+(Submetering!AF40+Submetering!AY40+Submetering!AV40+Submetering!AZ40)*1.1251+(2076.11+129.67+207.57+207.57)/30+(11680.53+56.61)/30)/I40 -> 1.2566232
...

Sheet Submetering
A1: Site Name | B1: Day | C1: Month | D1: Year | E1: 90 630 431 (KWh) | F1: 68 425 010 (KWh) | G1: T2392 (KWh) | H1: 68 425 008 (KWh) | I1: T7384 (KWh) | J1: 68 425 060 (KWh) | K1: T7380 (KWh) | L1: 68 425 097 (KWh) | M1: T7281 (KWh) | N1: 68 425 059 (KWh) | O1: T2390 (KWh) | P1: 68 425 077 (KWh) | Q1: T2395 (KWh) | R1: 68 425 078 (KWh) | S1: T2393 (KWh) | T1: 68 425 071 (KWh) | U1: T7285 (KWh) | V1: 68 425 093 (KWh) | W1: T7382 (KWh) | X1: 68 425 094 (KWh) | Y1: T2391 (KWh) | Z1: 90 625 242 (KWh) | AA1: T7283 (KWh) | AB1: 672 73 163 (KWh) | AC1: 676 62 513 (KWh) | AD1: 61 979 920 (KWh) | AE1: 56 253 208 (KWh) | AF1: Domestic Water from RCES 74860172 (m3) | AG1: Re-use Water from RCES 74860173 (m3) | AH1: Building A Fire Sprinkler System Make-up 44553004 (m3) | AI1: Building A Potable Water Feed 70275191 (m3) | AJ1: Steam Boilers Make-up Water 2130521 (m3) | AK1: Resort Natural Gas Meter 12C004186-C1 (m3) | AL1: Out Buildings Natural Gas Meter 93477704 (m3) | AM1: Cooling Tower Make-up Water 79177804 (m3) | AN1: Cooling Tower Blowdown Line Deduct 79305675 (m3) | AO1: Building E Potable Water Meter 79190041 (m3) | AP1: 7919004D | AQ1: Building J Irrigation Water Meter 79190039 (m3) | AR1: Lazy Pool River Make-up Water 79324776 (m3) | AS1: Pool Hydraunic Boiler Water Make-up 112014001775 (m3) | AT1: SPA Jacuzzi Water Make-up 112014001771 (m3) | AU1: Golf Clubhouse Natural Gas Meter 82SJ729151 (m3) | AV1: 73337589 - 1387142 | AW1: Golf Clubhouse Flushing Valve Deduct 65956268 (m3) | AX1: Clubhouse | AY1: Golf Maintenance Facility 1334021 (m3) | AZ1: Golf Course Comfort Stations 63265094 (m3) | BA1: Golf Course Re-use Irrigation 67327447 (m3)
A2: Orlando | B2: 1 | C2: 1 | D2: 2019 | E2: =Elect!AW4 -> 0 | F2: =Elect!I4 -> 55360 | G2: =Elect!H4 -> 2.219 | H2: =Elect!E4 -> 54240 | I2: =Elect!D4 -> 2.115 | J2: =Elect!Y4 -> 57300 | K2: =Elect!X4 -> 1.053 | L2: =Elect!AS4 -> 2200 | M2: =Elect!AR4 -> 0.379 | N2: =Elect!AC4 -> 53400 | O2: =Elect!AB4 -> 0.54 | P2: =Elect!Q4 -> 14800 | Q2: =Elect!P4 -> 2.62 | R2: =Elect!M4 -> 14400 | S2: =Elect!L4 -> 2.21 | T2: =Elect!U4 -> 16000 | U2: =Elect!T4 -> 2.47 | V2: =Elect!AG4 -> 7680 | W2: =Elect!AF4 -> 3.08 | X2: =Elect!AK4 -> 4640 | Y2: =Elect!AJ4 -> 1.89 | Z2: =Elect!AO4 -> 64800 | AA2: =Elect!AN4 -> 2.115 | AB2: =Elect!BJ4 -> 1700 | AC2: =Elect!BG4 -> 15200 | AD2: =Elect!BM4 -> 895 | AE2: =Elect!BP4 -> 600 | AF2: ='Wtr-Gas'!E4 -> 0 | AG2: ='Wtr-Gas'!H4 -> 0 | AH2: ='Wtr-Gas'!K4 -> 0 | AI2: ='Wtr-Gas'!N4 -> 0 | AJ2: ='Wtr-Gas'!Q4 -> 0 | AK2: ='Wtr-Gas'!U4 -> 0 | AL2: ='Wtr-Gas'!X4 -> 0 | AM2: ='Wtr-Gas'!AB4 -> 0 | AN2: ='Wtr-Gas'!AD4 -> 0 | AO2: ='Wtr-Gas'!AF4 -> 0 | AP2: ='Wtr-Gas'!AH4 -> 0 | AQ2: ='Wtr-Gas'!AJ4 -> 0 | AR2: ='Wtr-Gas'!AL4 -> 0 | AS2: ='Wtr-Gas'!AN4 -> 0 | AT2: ='Wtr-Gas'!AP4 -> 0 | AU2: ='Wtr-Gas'!AT4 -> 0 | AV2: ='Wtr-Gas'!AW4 -> 0 | AW2: ='Wtr-Gas'!AY4 -> 0 | AX2: ='Wtr-Gas'!AZ4 -> 0 | AY2: ='Wtr-Gas'!BB4 -> 0 | AZ2: ='Wtr-Gas'!BD4 -> 0 | BA2: ='Wtr-Gas'!BF4 -> 0
A3: Orlando | B3: 13 | C3: 1 | D3: 2019 | E3: =Elect!AW5 -> 0 | F3: =Elect!I5 -> 141280 | G3: =Elect!H5 -> 2.433 | H3: =Elect!E5 -> 137600 | I3: =Elect!D5 -> 2.115 | J3: =Elect!Y5 -> 115200 | K3: =Elect!X5 -> 1.733 | L3: =Elect!AS5 -> 5760 | M3: =Elect!AR5 -> 0.401 | N3: =Elect!AC5 -> 145200 | O3: =Elect!AB5 -> 1.622 | P3: =Elect!Q5 -> 37200 | Q3: =Elect!P5 -> 2.72 | R3: =Elect!M5 -> 37600 | S3: =Elect!L5 -> 2.65 | T3: =Elect!U5 -> 39600 | U3: =Elect!T5 -> 2.73 | V3: =Elect!AG5 -> 22400 | W3: =Elect!AF5 -> 5.48 | X3: =Elect!AK5 -> 2080 | Y3: =Elect!AJ5 -> 3.22 | Z3: =Elect!AO5 -> 169400 | AA3: =Elect!AN5 -> 2.289 | AB3: =Elect!BJ5 -> 2100 | AC3: =Elect!BG5 -> 16600 | AD3: =Elect!BM5 -> 1010 | AE3: =Elect!BP5 -> 2000 | AF3: =('Wtr-Gas'!E5)*0.0038 -> 14504.144 | AG3: =('Wtr-Gas'!H5)*0.0038 -> 420.66 | AH3: ='Wtr-Gas'!K5*0.0038 -> 17.48 | AI3: ='Wtr-Gas'!N5*0.0038 -> 10624.8 | AJ3: ='Wtr-Gas'!Q5*0.0038 -> 0 | AK3: ='Wtr-Gas'!U5*0.0038 -> 1677.7 | AL3: ='Wtr-Gas'!X5*0.0038 -> 17283.54 | AM3: ='Wtr-Gas'!AB5*0.0038 -> 5285.8 | AN3: ='Wtr-Gas'!AD5*0.0038 -> 41022.178 | AO3: ='Wtr-Gas'!AF5*0.0038 -> 6140.8 | AP3: ='Wtr-Gas'!AH5*0.0038 -> 122010.4 | AQ3: ='Wtr-Gas'!AJ5*0.0038 -> 112.1076 | AR3: ='Wtr-Gas'!AL5*0.0038 -> 1326.2 | AS3: ='Wtr-Gas'!AN5*0.0038 -> 1.444 | AT3: ='Wtr-Gas'!AP5*0.0038 -> 3.99 | AU3: ='Wtr-Gas'!AT5*0.0038 -> 0.6118 | AV3: ='Wtr-Gas'!AW5*0.0038 -> 280.7364 | AW3: ='Wtr-Gas'!AY5*0.0038 -> 7.03 | AX3: ='Wtr-Gas'!AZ5*0.0038 -> 273.7064 | AY3: ='Wtr-Gas'!BB5*0.0038 -> 36.48 | AZ3: ='Wtr-Gas'!BD5*0.0038 -> 2.66 | BA3: ='Wtr-Gas'!BF5*0.0038 -> 271.9166
A4: Orlando | B4: 21 | C4: 1 | D4: 2019 | E4: =Elect!AW6 -> 0 | F4: =Elect!I6 -> 46880 | G4: =Elect!H6 -> 2.433 | H4: =Elect!E6 -> 46400 | I4: =Elect!D6 -> 2.18 | J4: =Elect!Y6 -> 23700 | K4: =Elect!X6 -> 1.737 | L4: =Elect!AS6 -> 1880 | M4: =Elect!AR6 -> 0.401 | N4: =Elect!AC6 -> 45600 | O4: =Elect!AB6 -> 1.622 | P4: =Elect!Q6 -> 12800 | Q4: =Elect!P6 -> 2.83 | R4: =Elect!M6 -> 12800 | S4: =Elect!L6 -> 2.97 | T4: =Elect!U6 -> 13600 | U4: =Elect!T6 -> 2.8 | V4: =Elect!AG6 -> 7200 | W4: =Elect!AF6 -> 5.48 | X4: =Elect!AK6 -> 15840 | Y4: =Elect!AJ6 -> 3.22 | Z4: =Elect!AO6 -> 54600 | AA4: =Elect!AN6 -> 2.287 | AB4: =Elect!BJ6 -> 1800 | AC4: =Elect!BG6 -> 12900 | AD4: =Elect!BM6 -> 772 | AE4: =Elect!BP6 -> 720 | AF4: =('Wtr-Gas'!E6)*0.0038 -> 4476.096 | AG4: =('Wtr-Gas'!H6)*0.0038 -> 459.192 | AH4: ='Wtr-Gas'!K6*0.0038 -> 6.46 | AI4: ='Wtr-Gas'!N6*0.0038 -> 3260.4 | AJ4: ='Wtr-Gas'!Q6*0.0038 -> 0 | AK4: ='Wtr-Gas'!U6*0.0038 -> 484.5 | AL4: ='Wtr-Gas'!X6*0.0038 -> 7739.46 | AM4: ='Wtr-Gas'!AB6*0.0038 -> 836 | AN4: ='Wtr-Gas'!AD6*0.0038 -> 9177.9386 | AO4: ='Wtr-Gas'!AF6*0.0038 -> 1554.2 | AP4: ='Wtr-Gas'!AH6*0.0038 -> 20349 | AQ4: ='Wtr-Gas'!AJ6*0.0038 -> 55.043 | AR4: ='Wtr-Gas'!AL6*0.0038 -> 623.2 | AS4: ='Wtr-Gas'!AN6*0.0038 -> 0.076 | AT4: ='Wtr-Gas'!AP6*0.0038 -> 1.672 | AU4: ='Wtr-Gas'!AT6*0.0038 -> 0.456 | AV4: ='Wtr-Gas'!AW6*0.0038 -> 239.6432 | AW4: ='Wtr-Gas'!AY6*0.0038 -> 4.484 | AX4: ='Wtr-Gas'!AZ6*0.0038 -> 235.1592 | AY4: ='Wtr-Gas'!BB6*0.0038 -> 24.32 | AZ4: ='Wtr-Gas'!BD6*0.0038 -> 3.8 | BA4: ='Wtr-Gas'!BF6*0.0038 -> 269.6252
