Workbook

Sheet TOTAL
A1: Site Name | B1: Day | C1: Month | D1: Year | E1: Total Electricity Kwh | F1: Electricity Tariff ($/Kwh) | G1: Total Fuel Oil (Liter) | H1: Fuel Oil $/Liter | I1: Water Utility Supply (m3) m3 | J1: Water Utility Supply (m3) $/m3 | K1: LPG (Kg) | L1: LPG $/Kg | M1: Room Nights | N1: Total Guests | O1: Food Covers
A2: Maldives at Kuda Huraa | B2: 1 | C2: 4 | D2: 2022 | E2: 24100 | F2: 0.194 | G2: 6763 | H2: 0.7031 | I2: 393 | J2: 0.562 | L2: 1 | M2: 59 | N2: 160 | O2: 424
A3: Maldives at Kuda Huraa | B3: =B2+1 -> 2 | C3: 4 | D3: 2022 | E3: 24710 | F3: 0.194 | G3: 6854 | H3: 0.7031 | I3: 372 | J3: 0.562 | L3: 1 | M3: 58 | N3: 162 | O3: 474
A4: Maldives at Kuda Huraa | B4: =B3+1 -> 3 | C4: 4 | D4: 2022 | E4: 24350 | F4: 0.194 | G4: 6786 | H4: 0.7031 | I4: 373 | J4: 0.562 | L4: 1 | M4: 56 | N4: 161 | O4: 481
A5: Maldives at Kuda Huraa | B5: =B4+1 -> 4 | C5: 4 | D5: 2022 | E5: 23750 | F5: 0.194 | G5: 6687 | H5: 0.7031 | I5: 394 | J5: 0.562 | L5: 1 | M5: 63 | N5: 167 | O5: 441
A6: Maldives at Kuda Huraa | B6: =B5+1 -> 5 | C6: 4 | D6: 2022 | E6: 22510 | F6: 0.194 | G6: 6259 | H6: 0.7031 | I6: 364 | J6: 0.562 | L6: 1 | M6: 63 | N6: 172 | O6: 477
A7: Maldives at Kuda Huraa | B7: =B6+1 -> 6 | C7: 4 | D7: 2022 | E7: 23740 | F7: 0.194 | G7: 6466 | H7: 0.7031 | I7: 395 | J7: 0.562 | L7: 1 | M7: 67 | N7: 181 | O7: 472
A8: Maldives at Kuda Huraa | B8: =B7+1 -> 7 | C8: 4 | D8: 2022 | E8: 23790 | F8: 0.194 | G8: 6702 | H8: 0.7031 | I8: 379 | J8: 0.562 | L8: 1 | M8: 65 | N8: 177 | O8: 448
A9: Maldives at Kuda Huraa | B9: =B8+1 -> 8 | C9: 4 | D9: 2022 | E9: 24850 | F9: 0.194 | G9: 7089 | H9: 0.7031 | I9: 360 | J9: 0.562 | L9: 1 | M9: 69 | N9: 194 | O9: 522
A10: Maldives at Kuda Huraa | B10: =B9+1 -> 9 | C10: 4 | D10: 2022 | E10: 26020 | F10: 0.194 | G10: 7133 | H10: 0.7031 | I10: 398 | J10: 0.562 | L10: 1 | M10: 72 | N10: 202 | O10: 492
A11: Maldives at Kuda Huraa | B11: =B10+1 -> 10 | C11: 4 | D11: 2022 | E11: 24440 | F11: 0.194 | G11: 7027 | H11: 0.7031 | I11: 481 | J11: 0.562 | L11: 1 | M11: 75 | N11: 200 | O11: 534
A12: Maldives at Kuda Huraa | B12: =B11+1 -> 11 | C12: 4 | D12: 2022 | E12: 26060 | F12: 0.194 | G12: 7224 | H12: 0.7031 | I12: 415 | J12: 0.562 | L12: 1 | M12: 75 | N12: 188 | O12: 525
A13: Maldives at Kuda Huraa | B13: =B12+1 -> 12 | C13: 4 | D13: 2022 | E13: 25190 | F13: 0.194 | G13: -880135 | H13: 0.7031 | I13: 228 | J13: 0.562 | L13: 1 | M13: 77 | N13: 197 | O13: 561
A14: Maldives at Kuda Huraa | B14: =B13+1 -> 13 | C14: 4 | D14: 2022 | E14: 22230 | F14: 0.194 | G14: 6369 | H14: 0.7031 | I14: 335 | J14: 0.562 | L14: 1 | M14: 74 | N14: 186 | O14: 541
... A21: Maldives at Kuda Huraa | B21: =B20+1 -> 20 | C21: 4 | D21: 2022 | E21: 24010 | F21: 0.194 | G21: 6815 | H21: 0.7031 | I21: 325 | J21: 0.562 | L21: 1 | M21: 26 | N21: 73 | O21: 229
A22: Maldives at Kuda Huraa | B22: =B21+1 -> 21 | C22: 4 | D22: 2022 | F22: 0.194 | H22: 0.7031 | J22: 0.562 | L22: 1 | M22: 27 | N22: 66 | O22: 209
A23: Maldives at Kuda Huraa | B23: =B22+1 -> 22 | C23: 4 | D23: 2022 | F23: 0.194 | H23: 0.7031 | J23: 0.562 | L23: 1 | M23: 30 | N23: 78 | O23: 211
A24: Maldives at Kuda Huraa | B24: =B23+1 -> 23 | C24: 4 | D24: 2022 | F24: 0.194 | H24: 0.7031 | J24: 0.562 | L24: 1 | M24: 40 | N24: 102 | O24: 274
A25: Maldives at Kuda Huraa | B25: =B24+1 -> 24 | C25: 4 | D25: 2022 | F25: 0.194 | H25: 0.7031 | J25: 0.562 | L25: 1 | M25: 37 | N25: 89 | O25: 296
A26: Maldives at Kuda Huraa | B26: =B25+1 -> 25 | C26: 4 | D26: 2022 | F26: 0.194 | H26: 0.7031 | J26: 0.562 | L26: 1 | M26: 53 | N26: 116 | O26: 291
A27: Maldives at Kuda Huraa | B27: =B26+1 -> 26 | C27: 4 | D27: 2022 | F27: 0.194 | H27: 0.7031 | J27: 0.562 | L27: 1 | M27: 50 | N27: 105 | O27: 257
A28: Maldives at Kuda Huraa | B28: =B27+1 -> 27 | C28: 4 | D28: 2022 | F28: 0.194 | H28: 0.7031 | J28: 0.562 | L28: 1
A29: Maldives at Kuda Huraa | B29: =B28+1 -> 28 | C29: 4 | D29: 2022 | F29: 0.194 | H29: 0.7031 | J29: 0.562 | L29: 1
A30: Maldives at Kuda Huraa | B30: =B29+1 -> 29 | C30: 4 | D30: 2022 | F30: 0.194 | H30: 0.7031 | J30: 0.562 | L30: 1
A31: Maldives at Kuda Huraa | B31: =B30+1 -> 30 | C31: 4 | D31: 2022 | F31: 0.194 | H31: 0.7031 | J31: 0.562 | L31: 1
A32: Maldives at Kuda Huraa | B32: =B31+1 -> 31 | C32: 4 | D32: 2022 | F32: 0.194 | H32: 0.7031 | J32: 0.562 | L32: 1
A33: Total | E33: =SUM(E2:E32) -> 489770 | F33: 0 | G33: =SUM(G2:G32) -> -749780 | H33: 0 | I33: =SUM(I2:I32) -> 7372 | J33: 0 | K33: =SUM(K2:K32) -> 0 | L33: 0 | M33: =SUM(M2:M32) -> 1448 | N33: =SUM(N2:N32) -> 3833 | O33: =SUM(O2:O32) -> 10589

Sheet Kwh Reading
A1: Electric Consumption Record (4pm)
A2: Month | B2: BOH-1/ B&C Block GWH | C2: Pastry MWH | D2: Feeder 401-419 KWH | E2: Feeder 301-319 KWH | F2: Kitchen GWH | G2: Feeder 201-208 MWH | H2: Feeder 113-123 | I2: M - Block /PC MWH | J2: Laundry MWH | M2: Feeder 101-112 MWH | N2: Feeder 217-224 | O2: Spa MWH | P2: Feeder 124-134 | Q2: Feeder 209-216 | R2: STP -1 &2 MWH | S2: STP -3 MWH | T2: Reef Club MWH | V2: Room Nights | W2: Total Guests | X2: Food Covers
J3: A | K3: B | L3: C
A4: 44652 | B4: 1.3107 | C4: 298.74 | D4: 8060007.4 | E4: 8953592.2 | F4: 3.0869 | G4: 987.87 | H4: 865.12 | I4: 317.7 | J4: 432.98 | K4: 436.44 | L4: 296.61 | M4: 723.85 | N4: 683.45 | O4: 210.21 | P4: 890.12 | Q4: 656.22 | R4: 190.15 | S4: 152.2 | T4: 554.32 | V4: 59 | W4: 160 | X4: 424
A5: 44653 | B5: 1.312 | C5: 299 | D5: 8062170 | E5: 8956190.8 | F5: 3.0897 | G5: 988.95 | H5: 866.48 | I5: 318.07 | J5: 433.56 | K5: 436.79 | L5: 296.86 | M5: 724.73 | N5: 684.38 | O5: 210.42 | P5: 891.09 | Q5: 657.05 | R5: 190.15 | S5: 152.34 | T5: 554.63 | V5: 58 | W5: 162 | X5: 474
A6: 44654 | B6: 1.3133 | C6: 299.21 | D6: 8064348.5 | E6: 8959297.2 | F6: 3.0925 | G6: 990.03 | H6: 867.89 | I6: 318.43 | J6: 434.13 | K6: 437.18 | L6: 297.09 | M6: 725.65 | N6: 685.3 | O6: 210.65 | P6: 892.01 | Q6: 657.87 | R6: 190.15 | S6: 152.48 | T6: 555.21 | V6: 56 | W6: 161 | X6: 481
A7: 44655 | B7: 1.3146 | C7: 299.45 | D7: 8066600.4 | E7: 8962148 | F7: 3.0952 | G7: 991.06 | H7: 869.27 | I7: 318.78 | J7: 434.77 | K7: 437.57 | L7: 297.33 | M7: 726.58 | N7: 686.2 | O7: 210.88 | P7: 892.88 | Q7: 658.71 | R7: 190.15 | S7: 152.63 | T7: 555.78 | V7: 63 | W7: 167 | X7: 441
A8: 44656 | B8: 1.3156 | C8: 299.7 | D8: 8068635.8 | E8: 8965013.7 | F8: 3.098 | G8: 992.07 | H8: 870.75 | I8: 319.11 | J8: 435.35 | K8: 437.98 | L8: 297.58 | M8: 727.42 | N8: 687.11 | O8: 211.12 | P8: 893.96 | Q8: 659.55 | R8: 190.15 | S8: 152.76 | T8: 556.34 | V8: 63 | W8: 172 | X8: 477
A9: 44657 | B9: 1.317 | C9: 299.95 | D9: 8070573.5 | E9: 8967524.2 | F9: 3.1006 | G9: 992.99 | H9: 872.01 | I9: 319.41 | J9: 435.85 | K9: 438.38 | L9: 297.82 | M9: 728.14 | N9: 687.95 | O9: 211.31 | P9: 894.97 | Q9: 660.32 | R9: 190.15 | S9: 152.91 | T9: 556.9 | V9: 67 | W9: 181 | X9: 472
A10: 44658 | B10: 1.3182 | C10: 300.18 | D10: 8072544 | E10: 8970246.7 | F10: 3.1033 | G10: 993.94 | H10: 873.36 | I10: 319.74 | J10: 436.28 | K10: 438.77 | L10: 298.06 | M10: 728.91 | N10: 688.84 | O10: 211.53 | P10: 895.98 | Q10: 661.13 | R10: 190.15 | S10: 153.06 | T10: 557.48 | V10: 65 | W10: 177 | X10: 448
A11: 44659 | B11: 1.3195 | C11: 300.44 | D11: 8074633.4 | E11: 8973227.9 | F11: 3.106 | G11: 994.94 | H11: 874.77 | I11: 320.1 | J11: 436.82 | K11: 439.18 | L11: 298.29 | M11: 729.65 | N11: 689.77 | O11: 211.74 | P11: 897.06 | Q11: 661.97 | R11: 190.15 | S11: 153.21 | T11: 558.06 | V11: 69 | W11: 194 | X11: 522
A12: 44660 | B12: 1.3207 | C12: 300.7 | D12: 8076898.3 | E12: 8976318.9 | F12: 3.1088 | G12: 995.98 | H12: 876.25 | I12: 320.45 | J12: 437.59 | K12: 439.59 | L12: 298.53 | M12: 730.49 | N12: 690.75 | O12: 211.96 | P12: 898.16 | Q12: 662.84 | R12: 190.15 | S12: 153.32 | T12: 558.61 | V12: 72 | W12: 202 | X12: 492
A13: 44661 | B13: 1.322 | C13: 300.95 | D13: 8079132.8 | E13: 8979669.6 | F13: 3.1116 | G13: 997 | H13: 877.78 | I13: 320.8 | J13: 438.11 | K13: 440 | L13: 298.77 | M13: 731.36 | N13: 691.76 | O13: 212.17 | P13: 899.26 | Q13: 663.71 | R13: 190.15 | S13: 153.48 | T13: 559.19 | V13: 75 | W13: 200 | X13: 534
A14: 44662 | B14: 1.3233 | C14: 301.2 | D14: 8081291.5 | E14: 8983147.1 | F14: 3.1145 | G14: 997.97 | H14: 879.2 | I14: 321.19 | J14: 438.77 | K14: 440.4 | L14: 299.02 | M14: 732.24 | N14: 692.7 | O14: 212.39 | P14: 900.42 | Q14: 664.62 | R14: 190.15 | S14: 153.62 | T14: 559.76 | V14: 75 | W14: 188 | X14: 525
A15: 44663 | B15: 1.3245 | C15: 301.46 | D15: 8083649.7 | E15: 8986741.5 | F15: 3.1172 | G15: 998.99 | H15: 880.6 | I15: 321.54 | J15: 439.26 | K15: 440.85 | L15: 299.31 | M15: 733.14 | N15: 693.69 | O15: 212.61 | P15: 901.43 | Q15: 665.47 | R15: 190.15 | S15: 153.77 | T15: 560.32 | V15: 77 | W15: 197 | X15: 561
... A27: 44675 | B27: 1.339 | C27: 304.36 | D27: 8108381.6 | E27: 9023472.8 | F27: 3.1508 | G27: 1.0108 | H27: 896.64 | I27: 325.8 | J27: 446.86 | K27: 445.54 | L27: 302.37 | M27: 743.97 | N27: 704.11 | O27: 215.39 | P27: 912.67 | Q27: 674.88 | R27: 190.15 | S27: 155.54 | T27: 566.54 | V27: 37 | W27: 89 | X27: 296
A28: 44676 | V28: 53 | W28: 116 | X28: 291
A29: 44677 | V29: 50 | W29: 105 | X29: 257
A30: 44678
A31: 44679
A32: 44680
A33: 44681
A34: 44682
V35: =SUM(V4:V34) -> 1448 | W35: =SUM(W4:W34) -> 3833 | X35: =SUM(X4:X34) -> 10589
T42: ……..

Sheet Kwh Consumption
A2: Date | B2: Total KWH | C2: Reef Club KWH | D2: Kitchen KWH | E2: Pastry KWH | F2: Laundry KWH | I2: STP -1 &2 KWH | J2: STP -3 KWH | K2: M - Block /PC KWH | L2: B&C Block KWH | M2: Guest Room Beach Pavilion & Beach Bungalow KWH | S2: Guest Room Water Bungalow KWH | U2: Spa KWH | V2: Others KWH
F3: A | G3: B | H3: C | M3: Feeder -101-112 | N3: Feeder -113-123 | O3: Feeder -124-134 | P3: Feeder -201-208 | Q3: Feeder -209-216 | R3: Feeder -217-224 | S3: Feeder -301-319 | T3: Feeder 401-419
A4: ='Kwh Reading'!A4 -> 44652 | B4: =TOTAL!E2 -> 24100 | C4: =('Kwh Reading'!T5-'Kwh Reading'!T4)*1000 -> 310 | D4: =('Kwh Reading'!F5-'Kwh Reading'!F4)*1000000 -> 2800 | E4: =('Kwh Reading'!C5-'Kwh Reading'!C4)*1000 -> 260 | F4: =('Kwh Reading'!J5-'Kwh Reading'!J4)*1000 -> 580 | G4: =('Kwh Reading'!K5-'Kwh Reading'!K4)*1000 -> 350 | H4: =('Kwh Reading'!L5-'Kwh Reading'!L4)*1000 -> 250 | I4: =('Kwh Reading'!R5-'Kwh Reading'!R4)*1000 -> 0 | J4: =('Kwh Reading'!S5-'Kwh Reading'!S4)*1000 -> 140 | K4: =('Kwh Reading'!I5-'Kwh Reading'!I4)*1000 -> 370 | L4: =('Kwh Reading'!B5-'Kwh Reading'!B4)*1000000 -> 1300 | M4: =('Kwh Reading'!M5-'Kwh Reading'!M4)*1000 -> 880 | N4: =('Kwh Reading'!H5-'Kwh Reading'!H4)*1000 -> 1360 | O4: =('Kwh Reading'!P5-'Kwh Reading'!P4)*1000 -> 970 | P4: =('Kwh Reading'!G5-'Kwh Reading'!G4)*1000 -> 1080 | Q4: =('Kwh Reading'!Q5-'Kwh Reading'!Q4)*1000 -> 830 | R4: =('Kwh Reading'!N5-'Kwh Reading'!N4)*1000 -> 930 | S4: ='Kwh Reading'!E5-'Kwh Reading'!E4 -> 2598.52 | T4: ='Kwh Reading'!D5-'Kwh Reading'!D4 -> 2162.6 | U4: =('Kwh Reading'!O5-'Kwh Reading'!O4)*1000 -> 210 | V4: =B4-(SUM(C4:U4)) -> 6718.88
A5: ='Kwh Reading'!A5 -> 44653 | B5: =TOTAL!E3 -> 24710 | C5: =('Kwh Reading'!T6-'Kwh Reading'!T5)*1000 -> 580 | D5: =('Kwh Reading'!F6-'Kwh Reading'!F5)*1000000 -> 2800 | E5: =('Kwh Reading'!C6-'Kwh Reading'!C5)*1000 -> 210 | F5: =('Kwh Reading'!J6-'Kwh Reading'!J5)*1000 -> 570 | G5: =('Kwh Reading'!K6-'Kwh Reading'!K5)*1000 -> 390 | H5: =('Kwh Reading'!L6-'Kwh Reading'!L5)*1000 -> 230 | I5: =('Kwh Reading'!R6-'Kwh Reading'!R5)*1000 -> 0 | J5: =('Kwh Reading'!S6-'Kwh Reading'!S5)*1000 -> 140 | K5: =('Kwh Reading'!I6-'Kwh Reading'!I5)*1000 -> 360 | L5: =('Kwh Reading'!B6-'Kwh Reading'!B5)*1000000 -> 1300 | M5: =('Kwh Reading'!M6-'Kwh Reading'!M5)*1000 -> 920 | N5: =('Kwh Reading'!H6-'Kwh Reading'!H5)*1000 -> 1410 | O5: =('Kwh Reading'!P6-'Kwh Reading'!P5)*1000 -> 920 | P5: =('Kwh Reading'!G6-'Kwh Reading'!G5)*1000 -> 1080 | Q5: =('Kwh Reading'!Q6-'Kwh Reading'!Q5)*1000 -> 820 | R5: =('Kwh Reading'!N6-'Kwh Reading'!N5)*1000 -> 920 | S5: ='Kwh Reading'!E6-'Kwh Reading'!E5 -> 3106.43 | T5: ='Kwh Reading'!D6-'Kwh Reading'!D5 -> 2178.56 | U5: =('Kwh Reading'!O6-'Kwh Reading'!O5)*1000 -> 230 | V5: =B5-(SUM(C5:U5)) -> 6545.01
A6: ='Kwh Reading'!A6 -> 44654 | B6: =TOTAL!E4 -> 24350 | C6: =('Kwh Reading'!T7-'Kwh Reading'!T6)*1000 -> 570 | D6: =('Kwh Reading'!F7-'Kwh Reading'!F6)*1000000 -> 2700 | E6: =('Kwh Reading'!C7-'Kwh Reading'!C6)*1000 -> 240 | F6: =('Kwh Reading'!J7-'Kwh Reading'!J6)*1000 -> 640 | G6: =('Kwh Reading'!K7-'Kwh Reading'!K6)*1000 -> 390 | H6: =('Kwh Reading'!L7-'Kwh Reading'!L6)*1000 -> 240 | I6: =('Kwh Reading'!R7-'Kwh Reading'!R6)*1000 -> 0 | J6: =('Kwh Reading'!S7-'Kwh Reading'!S6)*1000 -> 150 | K6: =('Kwh Reading'!I7-'Kwh Reading'!I6)*1000 -> 350 | L6: =('Kwh Reading'!B7-'Kwh Reading'!B6)*1000000 -> 1300 | M6: =('Kwh Reading'!M7-'Kwh Reading'!M6)*1000 -> 930 | N6: =('Kwh Reading'!H7-'Kwh Reading'!H6)*1000 -> 1380 | O6: =('Kwh Reading'!P7-'Kwh Reading'!P6)*1000 -> 870 | P6: =('Kwh Reading'!G7-'Kwh Reading'!G6)*1000 -> 1030 | Q6: =('Kwh Reading'!Q7-'Kwh Reading'!Q6)*1000 -> 840 | R6: =('Kwh Reading'!N7-'Kwh Reading'!N6)*1000 -> 900 | S6: ='Kwh Reading'!E7-'Kwh Reading'!E6 -> 2850.78 | T6: ='Kwh Reading'!D7-'Kwh Reading'!D6 -> 2251.85 | U6: =('Kwh Reading'!O7-'Kwh Reading'!O6)*1000 -> 230 | V6: =B6-(SUM(C6:U6)) -> 6487.37
A7: ='Kwh Reading'!A7 -> 44655 | B7: =TOTAL!E5 -> 23750 | C7: =('Kwh Reading'!T8-'Kwh Reading'!T7)*1000 -> 560 | D7: =('Kwh Reading'!F8-'Kwh Reading'!F7)*1000000 -> 2800 | E7: =('Kwh Reading'!C8-'Kwh Reading'!C7)*1000 -> 250 | F7: =('Kwh Reading'!J8-'Kwh Reading'!J7)*1000 -> 580 | G7: =('Kwh Reading'!K8-'Kwh Reading'!K7)*1000 -> 410 | H7: =('Kwh Reading'!L8-'Kwh Reading'!L7)*1000 -> 250 | I7: =('Kwh Reading'!R8-'Kwh Reading'!R7)*1000 -> 0 | J7: =('Kwh Reading'!S8-'Kwh Reading'!S7)*1000 -> 130 | K7: =('Kwh Reading'!I8-'Kwh Reading'!I7)*1000 -> 330 | L7: =('Kwh Reading'!B8-'Kwh Reading'!B7)*1000000 -> 1000 | M7: =('Kwh Reading'!M8-'Kwh Reading'!M7)*1000 -> 840 | N7: =('Kwh Reading'!H8-'Kwh Reading'!H7)*1000 -> 1480 | O7: =('Kwh Reading'!P8-'Kwh Reading'!P7)*1000 -> 1080 | P7: =('Kwh Reading'!G8-'Kwh Reading'!G7)*1000 -> 1010 | Q7: =('Kwh Reading'!Q8-'Kwh Reading'!Q7)*1000 -> 840 | R7: =('Kwh Reading'!N8-'Kwh Reading'!N7)*1000 -> 910 | S7: ='Kwh Reading'!E8-'Kwh Reading'!E7 -> 2865.72 | T7: ='Kwh Reading'!D8-'Kwh Reading'!D7 -> 2035.35 | U7: =('Kwh Reading'!O8-'Kwh Reading'!O7)*1000 -> 240 | V7: =B7-(SUM(C7:U7)) -> 6138.93
A8: ='Kwh Reading'!A8 -> 44656 | B8: =TOTAL!E6 -> 22510 | C8: =('Kwh Reading'!T9-'Kwh Reading'!T8)*1000 -> 560 | D8: =('Kwh Reading'!F9-'Kwh Reading'!F8)*1000000 -> 2600 | E8: =('Kwh Reading'!C9-'Kwh Reading'!C8)*1000 -> 250 | F8: =('Kwh Reading'!J9-'Kwh Reading'!J8)*1000 -> 500 | G8: =('Kwh Reading'!K9-'Kwh Reading'!K8)*1000 -> 400 | H8: =('Kwh Reading'!L9-'Kwh Reading'!L8)*1000 -> 240 | I8: =('Kwh Reading'!R9-'Kwh Reading'!R8)*1000 -> 0 | J8: =('Kwh Reading'!S9-'Kwh Reading'!S8)*1000 -> 150 | K8: =('Kwh Reading'!I9-'Kwh Reading'!I8)*1000 -> 300 | L8: =('Kwh Reading'!B9-'Kwh Reading'!B8)*1000000 -> 1400 | M8: =('Kwh Reading'!M9-'Kwh Reading'!M8)*1000 -> 720 | N8: =('Kwh Reading'!H9-'Kwh Reading'!H8)*1000 -> 1260 | O8: =('Kwh Reading'!P9-'Kwh Reading'!P8)*1000 -> 1010 | P8: =('Kwh Reading'!G9-'Kwh Reading'!G8)*1000 -> 920 | Q8: =('Kwh Reading'!Q9-'Kwh Reading'!Q8)*1000 -> 770 | R8: =('Kwh Reading'!N9-'Kwh Reading'!N8)*1000 -> 840 | S8: ='Kwh Reading'!E9-'Kwh Reading'!E8 -> 2510.5 | T8: ='Kwh Reading'!D9-'Kwh Reading'!D8 -> 1937.72 | U8: =('Kwh Reading'!O9-'Kwh Reading'!O8)*1000 -> 190 | V8: =B8-(SUM(C8:U8)) -> 5951.78
A9: ='Kwh Reading'!A9 -> 44657 | B9: =TOTAL!E7 -> 23740 | C9: =('Kwh Reading'!T10-'Kwh Reading'!T9)*1000 -> 580 | D9: =('Kwh Reading'!F10-'Kwh Reading'!F9)*1000000 -> 2700 | E9: =('Kwh Reading'!C10-'Kwh Reading'!C9)*1000 -> 230 | F9: =('Kwh Reading'!J10-'Kwh Reading'!J9)*1000 -> 430 | G9: =('Kwh Reading'!K10-'Kwh Reading'!K9)*1000 -> 390 | H9: =('Kwh Reading'!L10-'Kwh Reading'!L9)*1000 -> 240 | I9: =('Kwh Reading'!R10-'Kwh Reading'!R9)*1000 -> 0 | J9: =('Kwh Reading'!S10-'Kwh Reading'!S9)*1000 -> 150 | K9: =('Kwh Reading'!I10-'Kwh Reading'!I9)*1000 -> 330 | L9: =('Kwh Reading'!B10-'Kwh Reading'!B9)*1000000 -> 1200 | M9: =('Kwh Reading'!M10-'Kwh Reading'!M9)*1000 -> 770 | N9: =('Kwh Reading'!H10-'Kwh Reading'!H9)*1000 -> 1350 | O9: =('Kwh Reading'!P10-'Kwh Reading'!P9)*1000 -> 1010 | P9: =('Kwh Reading'!G10-'Kwh Reading'!G9)*1000 -> 950 | Q9: =('Kwh Reading'!Q10-'Kwh Reading'!Q9)*1000 -> 810 | R9: =('Kwh Reading'!N10-'Kwh Reading'!N9)*1000 -> 890 | S9: ='Kwh Reading'!E10-'Kwh Reading'!E9 -> 2722.5 | T9: ='Kwh Reading'!D10-'Kwh Reading'!D9 -> 1970.54 | U9: =('Kwh Reading'!O10-'Kwh Reading'!O9)*1000 -> 220 | V9: =B9-(SUM(C9:U9)) -> 6796.96
A10: ='Kwh Reading'!A10 -> 44658 | B10: =TOTAL!E8 -> 23790 | C10: =('Kwh Reading'!T11-'Kwh Reading'!T10)*1000 -> 580 | D10: =('Kwh Reading'!F11-'Kwh Reading'!F10)*1000000 -> 2700 | E10: =('Kwh Reading'!C11-'Kwh Reading'!C10)*1000 -> 260 | F10: =('Kwh Reading'!J11-'Kwh Reading'!J10)*1000 -> 540 | G10: =('Kwh Reading'!K11-'Kwh Reading'!K10)*1000 -> 410 | H10: =('Kwh Reading'!L11-'Kwh Reading'!L10)*1000 -> 230 | I10: =('Kwh Reading'!R11-'Kwh Reading'!R10)*1000 -> 0 | J10: =('Kwh Reading'!S11-'Kwh Reading'!S10)*1000 -> 150 | K10: =('Kwh Reading'!I11-'Kwh Reading'!I10)*1000 -> 360 | L10: =('Kwh Reading'!B11-'Kwh Reading'!B10)*1000000 -> 1300 | M10: =('Kwh Reading'!M11-'Kwh Reading'!M10)*1000 -> 740 | N10: =('Kwh Reading'!H11-'Kwh Reading'!H10)*1000 -> 1410 | O10: =('Kwh Reading'!P11-'Kwh Reading'!P10)*1000 -> 1080 | P10: =('Kwh Reading'!G11-'Kwh Reading'!G10)*1000 -> 1000 | Q10: =('Kwh Reading'!Q11-'Kwh Reading'!Q10)*1000 -> 840 | R10: =('Kwh Reading'!N11-'Kwh Reading'!N10)*1000 -> 930 | S10: ='Kwh Reading'!E11-'Kwh Reading'!E10 -> 2981.2 | T10: ='Kwh Reading'!D11-'Kwh Reading'!D10 -> 2089.42 | U10: =('Kwh Reading'!O11-'Kwh Reading'!O10)*1000 -> 210 | V10: =B10-(SUM(C10:U10)) -> 5979.38
A11: ='Kwh Reading'!A11 -> 44659 | B11: =TOTAL!E9 -> 24850 | C11: =('Kwh Reading'!T12-'Kwh Reading'!T11)*1000 -> 550 | D11: =('Kwh Reading'!F12-'Kwh Reading'!F11)*1000000 -> 2800 | E11: =('Kwh Reading'!C12-'Kwh Reading'!C11)*1000 -> 260 | F11: =('Kwh Reading'!J12-'Kwh Reading'!J11)*1000 -> 770 | G11: =('Kwh Reading'!K12-'Kwh Reading'!K11)*1000 -> 410 | H11: =('Kwh Reading'!L12-'Kwh Reading'!L11)*1000 -> 240 | I11: =('Kwh Reading'!R12-'Kwh Reading'!R11)*1000 -> 0 | J11: =('Kwh Reading'!S12-'Kwh Reading'!S11)*1000 -> 110 | K11: =('Kwh Reading'!I12-'Kwh Reading'!I11)*1000 -> 350 | L11: =('Kwh Reading'!B12-'Kwh Reading'!B11)*1000000 -> 1200 | M11: =('Kwh Reading'!M12-'Kwh Reading'!M11)*1000 -> 840 | N11: =('Kwh Reading'!H12-'Kwh Reading'!H11)*1000 -> 1480 | O11: =('Kwh Reading'!P12-'Kwh Reading'!P11)*1000 -> 1100 | P11: =('Kwh Reading'!G12-'Kwh Reading'!G11)*1000 -> 1040 | Q11: =('Kwh Reading'!Q12-'Kwh Reading'!Q11)*1000 -> 870 | R11: =('Kwh Reading'!N12-'Kwh Reading'!N11)*1000 -> 980 | S11: ='Kwh Reading'!E12-'Kwh Reading'!E11 -> 3091.04 | T11: ='Kwh Reading'!D12-'Kwh Reading'!D11 -> 2264.85 | U11: =('Kwh Reading'!O12-'Kwh Reading'!O11)*1000 -> 220 | V11: =B11-(SUM(C11:U11)) -> 6274.11
A12: ='Kwh Reading'!A12 -> 44660 | B12: =TOTAL!E10 -> 26020 | C12: =('Kwh Reading'!T13-'Kwh Reading'!T12)*1000 -> 580 | D12: =('Kwh Reading'!F13-'Kwh Reading'!F12)*1000000 -> 2800 | E12: =('Kwh Reading'!C13-'Kwh Reading'!C12)*1000 -> 250 | F12: =('Kwh Reading'!J13-'Kwh Reading'!J12)*1000 -> 520 | G12: =('Kwh Reading'!K13-'Kwh Reading'!K12)*1000 -> 410 | H12: =('Kwh Reading'!L13-'Kwh Reading'!L12)*1000 -> 240 | I12: =('Kwh Reading'!R13-'Kwh Reading'!R12)*1000 -> 0 | J12: =('Kwh Reading'!S13-'Kwh Reading'!S12)*1000 -> 160 | K12: =('Kwh Reading'!I13-'Kwh Reading'!I12)*1000 -> 350 | L12: =('Kwh Reading'!B13-'Kwh Reading'!B12)*1000000 -> 1300 | M12: =('Kwh Reading'!M13-'Kwh Reading'!M12)*1000 -> 870 | N12: =('Kwh Reading'!H13-'Kwh Reading'!H12)*1000 -> 1530 | O12: =('Kwh Reading'!P13-'Kwh Reading'!P12)*1000 -> 1100 | P12: =('Kwh Reading'!G13-'Kwh Reading'!G12)*1000 -> 1020 | Q12: =('Kwh Reading'!Q13-'Kwh Reading'!Q12)*1000 -> 870 | R12: =('Kwh Reading'!N13-'Kwh Reading'!N12)*1000 -> 1010 | S12: ='Kwh Reading'!E13-'Kwh Reading'!E12 -> 3350.7 | T12: ='Kwh Reading'!D13-'Kwh Reading'!D12 -> 2234.54 | U12: =('Kwh Reading'!O13-'Kwh Reading'!O12)*1000 -> 210 | V12: =B12-(SUM(C12:U12)) -> 7214.76
A13: ='Kwh Reading'!A13 -> 44661 | B13: =TOTAL!E11 -> 24440 | C13: =('Kwh Reading'!T14-'Kwh Reading'!T13)*1000 -> 570 | D13: =('Kwh Reading'!F14-'Kwh Reading'!F13)*1000000 -> 2900 | E13: =('Kwh Reading'!C14-'Kwh Reading'!C13)*1000 -> 250 | F13: =('Kwh Reading'!J14-'Kwh Reading'!J13)*1000 -> 660 | G13: =('Kwh Reading'!K14-'Kwh Reading'!K13)*1000 -> 400 | H13: =('Kwh Reading'!L14-'Kwh Reading'!L13)*1000 -> 250 | I13: =('Kwh Reading'!R14-'Kwh Reading'!R13)*1000 -> 0 | J13: =('Kwh Reading'!S14-'Kwh Reading'!S13)*1000 -> 140 | K13: =('Kwh Reading'!I14-'Kwh Reading'!I13)*1000 -> 390 | L13: =('Kwh Reading'!B14-'Kwh Reading'!B13)*1000000 -> 1300 | M13: =('Kwh Reading'!M14-'Kwh Reading'!M13)*1000 -> 880 | N13: =('Kwh Reading'!H14-'Kwh Reading'!H13)*1000 -> 1420 | O13: =('Kwh Reading'!P14-'Kwh Reading'!P13)*1000 -> 1160 | P13: =('Kwh Reading'!G14-'Kwh Reading'!G13)*1000 -> 970 | Q13: =('Kwh Reading'!Q14-'Kwh Reading'!Q13)*1000 -> 910 | R13: =('Kwh Reading'!N14-'Kwh Reading'!N13)*1000 -> 940 | S13: ='Kwh Reading'!E14-'Kwh Reading'!E13 -> 3477.43 | T13: ='Kwh Reading'!D14-'Kwh Reading'!D13 -> 2158.73 | U13: =('Kwh Reading'!O14-'Kwh Reading'!O13)*1000 -> 220 | V13: =B13-(SUM(C13:U13)) -> 5443.84
A14: ='Kwh Reading'!A14 -> 44662 | B14: =TOTAL!E12 -> 26060 | C14: =('Kwh Reading'!T15-'Kwh Reading'!T14)*1000 -> 560 | D14: =('Kwh Reading'!F15-'Kwh Reading'!F14)*1000000 -> 2700 | E14: =('Kwh Reading'!C15-'Kwh Reading'!C14)*1000 -> 260 | F14: =('Kwh Reading'!J15-'Kwh Reading'!J14)*1000 -> 490 | G14: =('Kwh Reading'!K15-'Kwh Reading'!K14)*1000 -> 450 | H14: =('Kwh Reading'!L15-'Kwh Reading'!L14)*1000 -> 290 | I14: =('Kwh Reading'!R15-'Kwh Reading'!R14)*1000 -> 0 | J14: =('Kwh Reading'!S15-'Kwh Reading'!S14)*1000 -> 150 | K14: =('Kwh Reading'!I15-'Kwh Reading'!I14)*1000 -> 350 | L14: =('Kwh Reading'!B15-'Kwh Reading'!B14)*1000000 -> 1200 | M14: =('Kwh Reading'!M15-'Kwh Reading'!M14)*1000 -> 900 | N14: =('Kwh Reading'!H15-'Kwh Reading'!H14)*1000 -> 1400 | O14: =('Kwh Reading'!P15-'Kwh Reading'!P14)*1000 -> 1010 | P14: =('Kwh Reading'!G15-'Kwh Reading'!G14)*1000 -> 1020 | Q14: =('Kwh Reading'!Q15-'Kwh Reading'!Q14)*1000 -> 850 | R14: =('Kwh Reading'!N15-'Kwh Reading'!N14)*1000 -> 990 | S14: ='Kwh Reading'!E15-'Kwh Reading'!E14 -> 3594.46 | T14: ='Kwh Reading'!D15-'Kwh Reading'!D14 -> 2358.13 | U14: =('Kwh Reading'!O15-'Kwh Reading'!O14)*1000 -> 220 | V14: =B14-(SUM(C14:U14)) -> 7267.41
A15: ='Kwh Reading'!A15 -> 44663 | B15: =TOTAL!E13 -> 25190 | C15: =('Kwh Reading'!T16-'Kwh Reading'!T15)*1000 -> 540 | D15: =('Kwh Reading'!F16-'Kwh Reading'!F15)*1000000 -> 2900 | E15: =('Kwh Reading'!C16-'Kwh Reading'!C15)*1000 -> 250 | F15: =('Kwh Reading'!J16-'Kwh Reading'!J15)*1000 -> 520 | G15: =('Kwh Reading'!K16-'Kwh Reading'!K15)*1000 -> 450 | H15: =('Kwh Reading'!L16-'Kwh Reading'!L15)*1000 -> 290 | I15: =('Kwh Reading'!R16-'Kwh Reading'!R15)*1000 -> 0 | J15: =('Kwh Reading'!S16-'Kwh Reading'!S15)*1000 -> 170 | K15: =('Kwh Reading'!I16-'Kwh Reading'!I15)*1000 -> 330 | L15: =('Kwh Reading'!B16-'Kwh Reading'!B15)*1000000 -> 1200 | M15: =('Kwh Reading'!M16-'Kwh Reading'!M15)*1000 -> 830 | N15: =('Kwh Reading'!H16-'Kwh Reading'!H15)*1000 -> 1360 | O15: =('Kwh Reading'!P16-'Kwh Reading'!P15)*1000 -> 1050 | P15: =('Kwh Reading'!G16-'Kwh Reading'!G15)*1000 -> -997990 | Q15: =('Kwh Reading'!Q16-'Kwh Reading'!Q15)*1000 -> 850 | R15: =('Kwh Reading'!N16-'Kwh Reading'!N15)*1000 -> 960 | S15: ='Kwh Reading'!E16-'Kwh Reading'!E15 -> 3412.78 | T15: ='Kwh Reading'!D16-'Kwh Reading'!D15 -> 2249.51 | U15: =('Kwh Reading'!O16-'Kwh Reading'!O15)*1000 -> 250 | V15: =B15-(SUM(C15:U15)) -> 1005567.7
... A34: ='Kwh Reading'!A34 -> 44682 | B34: =TOTAL!E32 -> 0 | C34: =('Kwh Reading'!T35-'Kwh Reading'!T34)*1000 -> 0 | D34: =('Kwh Reading'!F35-'Kwh Reading'!F34)*1000000 -> 0 | E34: =('Kwh Reading'!C35-'Kwh Reading'!C34)*1000 -> 0 | F34: =('Kwh Reading'!J35-'Kwh Reading'!J34)*1000 -> 0 | G34: =('Kwh Reading'!K35-'Kwh Reading'!K34)*1000 -> 0 | H34: =('Kwh Reading'!L35-'Kwh Reading'!L34)*1000 -> 0 | I34: =('Kwh Reading'!R35-'Kwh Reading'!R34)*1000 -> 0 | J34: =('Kwh Reading'!S35-'Kwh Reading'!S34)*1000 -> 0 | K34: =('Kwh Reading'!I35-'Kwh Reading'!I34)*1000 -> 0 | L34: =('Kwh Reading'!B35-'Kwh Reading'!B34)*1000000 -> 0 | M34: =('Kwh Reading'!M35-'Kwh Reading'!M34)*1000 -> 0 | N34: =('Kwh Reading'!H35-'Kwh Reading'!H34)*1000 -> 0 | O34: =('Kwh Reading'!P35-'Kwh Reading'!P34)*1000 -> 0 | P34: =('Kwh Reading'!G35-'Kwh Reading'!G34)*1000 -> 0 | Q34: =('Kwh Reading'!Q35-'Kwh Reading'!Q34)*1000 -> 0 | R34: =('Kwh Reading'!N35-'Kwh Reading'!N34)*1000 -> 0 | S34: ='Kwh Reading'!E35-'Kwh Reading'!E34 -> 0 | T34: ='Kwh Reading'!D35-'Kwh Reading'!D34 -> 0 | U34: =('Kwh Reading'!O35-'Kwh Reading'!O34)*1000 -> 0 | V34: =B34-(SUM(C34:U34)) -> 0
A35: Total | B35: =SUM(B4:B34) -> 489770 | C35: =SUM(C4:C34) -> -554320 | D35: =SUM(D4:D34) -> -3086900 | E35: =SUM(E4:E34) -> -298740 | F35: =SUM(F4:F34) -> -432980 | G35: =SUM(G4:G34) -> -436440 | H35: =SUM(H4:H34) -> -296610 | I35: =SUM(I4:I34) -> -190150 | ... V35: =SUM(V4:V34) -> 29596950

Sheet Kwh area wise 
A2: Month | B2: Total KWH | C2: Reef Club Kitchen KWH | D2: Main Kitchen KWH | E2: Pastry Kitchen KWH | F2: Laundry KWH | G2: STP KWH | H2: Kuda Huraa Accomodation KWH | I2: Guest Room Beach Pavilion & Beach Bungalow KWH | J2: Guest Room Water Bungalow KWH | K2: Spa KWH | L2: Others KWH
A3: ='Kwh Reading'!A4 -> 44652 | B3: =TOTAL!E2 -> 24100 | C3: ='Kwh Consumption'!C4 -> 310 | D3: ='Kwh Consumption'!D4 -> 2800 | E3: ='Kwh Consumption'!E4 -> 260 | F3: =('Kwh Consumption'!F4+'Kwh Consumption'!G4+'Kwh Consumption'!H4) -> 1180 | G3: =('Kwh Consumption'!I4+'Kwh Consumption'!J4) -> 140 | H3: =('Kwh Consumption'!K4+'Kwh Consumption'!L4) -> 1670 | I3: =('Kwh Consumption'!M4+'Kwh Consumption'!N4+'Kwh Consumption'!O4+'Kwh Consumption'!P4+'Kwh Consumption'!Q4+'Kwh Consumption'!R4) -> 6050 | J3: =('Kwh Consumption'!S4+'Kwh Consumption'!T4) -> 4761.12 | K3: ='Kwh Consumption'!U4 -> 210 | L3: =B3-C3-D3-E3-F3-G3-H3-I3-J3-K3 -> 6718.88
A4: ='Kwh Reading'!A5 -> 44653 | B4: =TOTAL!E3 -> 24710 | C4: ='Kwh Consumption'!C5 -> 580 | D4: ='Kwh Consumption'!D5 -> 2800 | E4: ='Kwh Consumption'!E5 -> 210 | F4: =('Kwh Consumption'!F5+'Kwh Consumption'!G5+'Kwh Consumption'!H5) -> 1190 | G4: =('Kwh Consumption'!I5+'Kwh Consumption'!J5) -> 140 | H4: =('Kwh Consumption'!K5+'Kwh Consumption'!L5) -> 1660 | I4: =('Kwh Consumption'!M5+'Kwh Consumption'!N5+'Kwh Consumption'!O5+'Kwh Consumption'!P5+'Kwh Consumption'!Q5+'Kwh Consumption'!R5) -> 6070 | J4: =('Kwh Consumption'!S5+'Kwh Consumption'!T5) -> 5284.99 | K4: ='Kwh Consumption'!U5 -> 230 | L4: =B4-C4-D4-E4-F4-G4-H4-I4-J4-K4 -> 6545.01
A5: ='Kwh Reading'!A6 -> 44654 | B5: =TOTAL!E4 -> 24350 | C5: ='Kwh Consumption'!C6 -> 570 | D5: ='Kwh Consumption'!D6 -> 2700 | E5: ='Kwh Consumption'!E6 -> 240 | F5: =('Kwh Consumption'!F6+'Kwh Consumption'!G6+'Kwh Consumption'!H6) -> 1270 | G5: =('Kwh Consumption'!I6+'Kwh Consumption'!J6) -> 150 | H5: =('Kwh Consumption'!K6+'Kwh Consumption'!L6) -> 1650 | I5: =('Kwh Consumption'!M6+'Kwh Consumption'!N6+'Kwh Consumption'!O6+'Kwh Consumption'!P6+'Kwh Consumption'!Q6+'Kwh Consumption'!R6) -> 5950 | J5: =('Kwh Consumption'!S6+'Kwh Consumption'!T6) -> 5102.63 | K5: ='Kwh Consumption'!U6 -> 230 | L5: =B5-C5-D5-E5-F5-G5-H5-I5-J5-K5 -> 6487.37
A6: ='Kwh Reading'!A7 -> 44655 | B6: =TOTAL!E5 -> 23750 | C6: ='Kwh Consumption'!C7 -> 560 | D6: ='Kwh Consumption'!D7 -> 2800 | E6: ='Kwh Consumption'!E7 -> 250 | F6: =('Kwh Consumption'!F7+'Kwh Consumption'!G7+'Kwh Consumption'!H7) -> 1240 | G6: =('Kwh Consumption'!I7+'Kwh Consumption'!J7) -> 130 | H6: =('Kwh Consumption'!K7+'Kwh Consumption'!L7) -> 1330 | I6: =('Kwh Consumption'!M7+'Kwh Consumption'!N7+'Kwh Consumption'!O7+'Kwh Consumption'!P7+'Kwh Consumption'!Q7+'Kwh Consumption'!R7) -> 6160 | J6: =('Kwh Consumption'!S7+'Kwh Consumption'!T7) -> 4901.07 | K6: ='Kwh Consumption'!U7 -> 240 | L6: =B6-C6-D6-E6-F6-G6-H6-I6-J6-K6 -> 6138.93
A7: ='Kwh Reading'!A8 -> 44656 | B7: =TOTAL!E6 -> 22510 | C7: ='Kwh Consumption'!C8 -> 560 | D7: ='Kwh Consumption'!D8 -> 2600 | E7: ='Kwh Consumption'!E8 -> 250 | F7: =('Kwh Consumption'!F8+'Kwh Consumption'!G8+'Kwh Consumption'!H8) -> 1140 | G7: =('Kwh Consumption'!I8+'Kwh Consumption'!J8) -> 150 | H7: =('Kwh Consumption'!K8+'Kwh Consumption'!L8) -> 1700 | I7: =('Kwh Consumption'!M8+'Kwh Consumption'!N8+'Kwh Consumption'!O8+'Kwh Consumption'!P8+'Kwh Consumption'!Q8+'Kwh Consumption'!R8) -> 5520 | J7: =('Kwh Consumption'!S8+'Kwh Consumption'!T8) -> 4448.22 | K7: ='Kwh Consumption'!U8 -> 190 | L7: =B7-C7-D7-E7-F7-G7-H7-I7-J7-K7 -> 5951.78
A8: ='Kwh Reading'!A9 -> 44657 | B8: =TOTAL!E7 -> 23740 | C8: ='Kwh Consumption'!C9 -> 580 | D8: ='Kwh Consumption'!D9 -> 2700 | E8: ='Kwh Consumption'!E9 -> 230 | F8: =('Kwh Consumption'!F9+'Kwh Consumption'!G9+'Kwh Consumption'!H9) -> 1060 | G8: =('Kwh Consumption'!I9+'Kwh Consumption'!J9) -> 150 | H8: =('Kwh Consumption'!K9+'Kwh Consumption'!L9) -> 1530 | I8: =('Kwh Consumption'!M9+'Kwh Consumption'!N9+'Kwh Consumption'!O9+'Kwh Consumption'!P9+'Kwh Consumption'!Q9+'Kwh Consumption'!R9) -> 5780 | J8: =('Kwh Consumption'!S9+'Kwh Consumption'!T9) -> 4693.04 | K8: ='Kwh Consumption'!U9 -> 220 | L8: =B8-C8-D8-E8-F8-G8-H8-I8-J8-K8 -> 6796.96
A9: ='Kwh Reading'!A10 -> 44658 | B9: =TOTAL!E8 -> 23790 | C9: ='Kwh Consumption'!C10 -> 580 | D9: ='Kwh Consumption'!D10 -> 2700 | E9: ='Kwh Consumption'!E10 -> 260 | F9: =('Kwh Consumption'!F10+'Kwh Consumption'!G10+'Kwh Consumption'!H10) -> 1180 | G9: =('Kwh Consumption'!I10+'Kwh Consumption'!J10) -> 150 | H9: =('Kwh Consumption'!K10+'Kwh Consumption'!L10) -> 1660 | I9: =('Kwh Consumption'!M10+'Kwh Consumption'!N10+'Kwh Consumption'!O10+'Kwh Consumption'!P10+'Kwh Consumption'!Q10+'Kwh Consumption'!R10) -> 6000 | J9: =('Kwh Consumption'!S10+'Kwh Consumption'!T10) -> 5070.62 | K9: ='Kwh Consumption'!U10 -> 210 | L9: =B9-C9-D9-E9-F9-G9-H9-I9-J9-K9 -> 5979.38
A10: ='Kwh Reading'!A11 -> 44659 | B10: =TOTAL!E9 -> 24850 | C10: ='Kwh Consumption'!C11 -> 550 | D10: ='Kwh Consumption'!D11 -> 2800 | E10: ='Kwh Consumption'!E11 -> 260 | F10: =('Kwh Consumption'!F11+'Kwh Consumption'!G11+'Kwh Consumption'!H11) -> 1420 | G10: =('Kwh Consumption'!I11+'Kwh Consumption'!J11) -> 110 | H10: =('Kwh Consumption'!K11+'Kwh Consumption'!L11) -> 1550 | I10: =('Kwh Consumption'!M11+'Kwh Consumption'!N11+'Kwh Consumption'!O11+'Kwh Consumption'!P11+'Kwh Consumption'!Q11+'Kwh Consumption'!R11) -> 6310 | J10: =('Kwh Consumption'!S11+'Kwh Consumption'!T11) -> 5355.89 | K10: ='Kwh Consumption'!U11 -> 220 | L10: =B10-C10-D10-E10-F10-G10-H10-I10-J10-K10 -> 6274.11
A11: ='Kwh Reading'!A12 -> 44660 | B11: =TOTAL!E10 -> 26020 | C11: ='Kwh Consumption'!C12 -> 580 | D11: ='Kwh Consumption'!D12 -> 2800 | E11: ='Kwh Consumption'!E12 -> 250 | F11: =('Kwh Consumption'!F12+'Kwh Consumption'!G12+'Kwh Consumption'!H12) -> 1170 | G11: =('Kwh Consumption'!I12+'Kwh Consumption'!J12) -> 160 | H11: =('Kwh Consumption'!K12+'Kwh Consumption'!L12) -> 1650 | I11: =('Kwh Consumption'!M12+'Kwh Consumption'!N12+'Kwh Consumption'!O12+'Kwh Consumption'!P12+'Kwh Consumption'!Q12+'Kwh Consumption'!R12) -> 6400 | J11: =('Kwh Consumption'!S12+'Kwh Consumption'!T12) -> 5585.24 | K11: ='Kwh Consumption'!U12 -> 210 | L11: =B11-C11-D11-E11-F11-G11-H11-I11-J11-K11 -> 7214.76
A12: ='Kwh Reading'!A13 -> 44661 | B12: =TOTAL!E11 -> 24440 | C12: ='Kwh Consumption'!C13 -> 570 | D12: ='Kwh Consumption'!D13 -> 2900 | E12: ='Kwh Consumption'!E13 -> 250 | F12: =('Kwh Consumption'!F13+'Kwh Consumption'!G13+'Kwh Consumption'!H13) -> 1310 | G12: =('Kwh Consumption'!I13+'Kwh Consumption'!J13) -> 140 | H12: =('Kwh Consumption'!K13+'Kwh Consumption'!L13) -> 1690 | I12: =('Kwh Consumption'!M13+'Kwh Consumption'!N13+'Kwh Consumption'!O13+'Kwh Consumption'!P13+'Kwh Consumption'!Q13+'Kwh Consumption'!R13) -> 6280 | J12: =('Kwh Consumption'!S13+'Kwh Consumption'!T13) -> 5636.16 | K12: ='Kwh Consumption'!U13 -> 220 | L12: =B12-C12-D12-E12-F12-G12-H12-I12-J12-K12 -> 5443.84
A13: ='Kwh Reading'!A14 -> 44662 | B13: =TOTAL!E12 -> 26060 | C13: ='Kwh Consumption'!C14 -> 560 | D13: ='Kwh Consumption'!D14 -> 2700 | E13: ='Kwh Consumption'!E14 -> 260 | F13: =('Kwh Consumption'!F14+'Kwh Consumption'!G14+'Kwh Consumption'!H14) -> 1230 | G13: =('Kwh Consumption'!I14+'Kwh Consumption'!J14) -> 150 | H13: =('Kwh Consumption'!K14+'Kwh Consumption'!L14) -> 1550 | I13: =('Kwh Consumption'!M14+'Kwh Consumption'!N14+'Kwh Consumption'!O14+'Kwh Consumption'!P14+'Kwh Consumption'!Q14+'Kwh Consumption'!R14) -> 6170 | J13: =('Kwh Consumption'!S14+'Kwh Consumption'!T14) -> 5952.59 | K13: ='Kwh Consumption'!U14 -> 220 | L13: =B13-C13-D13-E13-F13-G13-H13-I13-J13-K13 -> 7267.41
A14: ='Kwh Reading'!A15 -> 44663 | B14: =TOTAL!E13 -> 25190 | C14: ='Kwh Consumption'!C15 -> 540 | D14: ='Kwh Consumption'!D15 -> 2900 | E14: ='Kwh Consumption'!E15 -> 250 | F14: =('Kwh Consumption'!F15+'Kwh Consumption'!G15+'Kwh Consumption'!H15) -> 1260 | G14: =('Kwh Consumption'!I15+'Kwh Consumption'!J15) -> 170 | H14: =('Kwh Consumption'!K15+'Kwh Consumption'!L15) -> 1530 | I14: =('Kwh Consumption'!M15+'Kwh Consumption'!N15+'Kwh Consumption'!O15+'Kwh Consumption'!P15+'Kwh Consumption'!Q15+'Kwh Consumption'!R15) -> -992940 | J14: =('Kwh Consumption'!S15+'Kwh Consumption'!T15) -> 5662.29 | K14: ='Kwh Consumption'!U15 -> 250 | L14: =B14-C14-D14-E14-F14-G14-H14-I14-J14-K14 -> 1005567.7
A15: ='Kwh Reading'!A16 -> 44664 | B15: =TOTAL!E14 -> 22230 | C15: 0 | D15: 0 | E15: 0 | F15: 0 | G15: 0 | H15: 0 | I15: =('Kwh Consumption'!M16+'Kwh Consumption'!N16+'Kwh Consumption'!O16+'Kwh Consumption'!P16+'Kwh Consumption'!Q16+'Kwh Consumption'!R16) -> 4270.9 | J15: =('Kwh Consumption'!S16+'Kwh Consumption'!T16) -> 4534 | K15: ='Kwh Consumption'!U16 -> 210 | L15: =B15-C15-D15-E15-F15-G15-H15-I15-J15-K15 -> 13215.1
A16: ='Kwh Reading'!A17 -> 44665 | B16: =TOTAL!E15 -> 24860 | C16: ='Kwh Consumption'!C17 -> 530 | D16: ='Kwh Consumption'!D17 -> 2900 | E16: ='Kwh Consumption'!E17 -> 260 | F16: =('Kwh Consumption'!F17+'Kwh Consumption'!G17+'Kwh Consumption'!H17) -> 1540 | G16: =('Kwh Consumption'!I17+'Kwh Consumption'!J17) -> 150 | H16: =('Kwh Consumption'!K17+'Kwh Consumption'!L17) -> 1400 | I16: =('Kwh Consumption'!M17+'Kwh Consumption'!N17+'Kwh Consumption'!O17+'Kwh Consumption'!P17+'Kwh Consumption'!Q17+'Kwh Consumption'!R17) -> 4731 | J16: =('Kwh Consumption'!S17+'Kwh Consumption'!T17) -> 4950.68 | K16: ='Kwh Consumption'!U17 -> 240 | L16: =B16-C16-D16-E16-F16-G16-H16-I16-J16-K16 -> 8158.32
A17: ='Kwh Reading'!A18 -> 44666 | B17: =TOTAL!E16 -> 25050 | C17: ='Kwh Consumption'!C18 -> 520 | D17: ='Kwh Consumption'!D18 -> 2800 | E17: ='Kwh Consumption'!E18 -> 240 | F17: =('Kwh Consumption'!F18+'Kwh Consumption'!G18+'Kwh Consumption'!H18) -> 1520 | G17: =('Kwh Consumption'!I18+'Kwh Consumption'!J18) -> 160 | H17: =('Kwh Consumption'!K18+'Kwh Consumption'!L18) -> 1630 | I17: =('Kwh Consumption'!M18+'Kwh Consumption'!N18+'Kwh Consumption'!O18+'Kwh Consumption'!P18+'Kwh Consumption'!Q18+'Kwh Consumption'!R18) -> 4981 | J17: =('Kwh Consumption'!S18+'Kwh Consumption'!T18) -> 5202.48 | K17: ='Kwh Consumption'!U18 -> 240 | L17: =B17-C17-D17-E17-F17-G17-H17-I17-J17-K17 -> 7756.52
A18: ='Kwh Reading'!A19 -> 44667 | B18: =TOTAL!E17 -> 25930 | C18: ='Kwh Consumption'!C19 -> 600 | D18: ='Kwh Consumption'!D19 -> 2800 | E18: ='Kwh Consumption'!E19 -> 240 | F18: =('Kwh Consumption'!F19+'Kwh Consumption'!G19+'Kwh Consumption'!H19) -> 1680 | G18: =('Kwh Consumption'!I19+'Kwh Consumption'!J19) -> 150 | H18: =('Kwh Consumption'!K19+'Kwh Consumption'!L19) -> 1760 | I18: =('Kwh Consumption'!M19+'Kwh Consumption'!N19+'Kwh Consumption'!O19+'Kwh Consumption'!P19+'Kwh Consumption'!Q19+'Kwh Consumption'!R19) -> 5201.1 | J18: =('Kwh Consumption'!S19+'Kwh Consumption'!T19) -> 5337.89 | K18: ='Kwh Consumption'!U19 -> 290 | L18: =B18-C18-D18-E18-F18-G18-H18-I18-J18-K18 -> 7871.01
A19: ='Kwh Reading'!A20 -> 44668 | B19: =TOTAL!E18 -> 26000 | C19: ='Kwh Consumption'!C20 -> 640 | D19: ='Kwh Consumption'!D20 -> 2800 | E19: ='Kwh Consumption'!E20 -> 230 | F19: =('Kwh Consumption'!F20+'Kwh Consumption'!G20+'Kwh Consumption'!H20) -> 1060 | G19: =('Kwh Consumption'!I20+'Kwh Consumption'!J20) -> 150 | H19: =('Kwh Consumption'!K20+'Kwh Consumption'!L20) -> 1500 | I19: =('Kwh Consumption'!M20+'Kwh Consumption'!N20+'Kwh Consumption'!O20+'Kwh Consumption'!P20+'Kwh Consumption'!Q20+'Kwh Consumption'!R20) -> 5251 | J19: =('Kwh Consumption'!S20+'Kwh Consumption'!T20) -> 5575.39 | K19: ='Kwh Consumption'!U20 -> 240 | L19: =B19-C19-D19-E19-F19-G19-H19-I19-J19-K19 -> 8553.61
A20: ='Kwh Reading'!A21 -> 44669 | B20: =TOTAL!E19 -> 24520 | C20: ='Kwh Consumption'!C21 -> 520 | D20: ='Kwh Consumption'!D21 -> 2700 | E20: ='Kwh Consumption'!E21 -> 240 | F20: =('Kwh Consumption'!F21+'Kwh Consumption'!G21+'Kwh Consumption'!H21) -> 1400 | G20: =('Kwh Consumption'!I21+'Kwh Consumption'!J21) -> 140 | H20: =('Kwh Consumption'!K21+'Kwh Consumption'!L21) -> 1870 | I20: =('Kwh Consumption'!M21+'Kwh Consumption'!N21+'Kwh Consumption'!O21+'Kwh Consumption'!P21+'Kwh Consumption'!Q21+'Kwh Consumption'!R21) -> 5001.1 | J20: =('Kwh Consumption'!S21+'Kwh Consumption'!T21) -> 4976.42 | K20: ='Kwh Consumption'!U21 -> 250 | L20: =B20-C20-D20-E20-F20-G20-H20-I20-J20-K20 -> 7422.48
A21: ='Kwh Reading'!A22 -> 44670 | B21: =TOTAL!E20 -> 23660 | C21: ='Kwh Consumption'!C22 -> 490 | D21: ='Kwh Consumption'!D22 -> 2800 | E21: ='Kwh Consumption'!E22 -> 250 | F21: =('Kwh Consumption'!F22+'Kwh Consumption'!G22+'Kwh Consumption'!H22) -> 1030 | G21: =('Kwh Consumption'!I22+'Kwh Consumption'!J22) -> 150 | H21: =('Kwh Consumption'!K22+'Kwh Consumption'!L22) -> 1590 | I21: =('Kwh Consumption'!M22+'Kwh Consumption'!N22+'Kwh Consumption'!O22+'Kwh Consumption'!P22+'Kwh Consumption'!Q22+'Kwh Consumption'!R22) -> 4590.9 | J21: =('Kwh Consumption'!S22+'Kwh Consumption'!T22) -> 5117.42 | K21: ='Kwh Consumption'!U22 -> 210 | L21: =B21-C21-D21-E21-F21-G21-H21-I21-J21-K21 -> 7431.68
A22: ='Kwh Reading'!A23 -> 44671 | B22: =TOTAL!E21 -> 24010 | C22: ='Kwh Consumption'!C23 -> 540 | D22: ='Kwh Consumption'!D23 -> 2700 | E22: ='Kwh Consumption'!E23 -> 230 | F22: =('Kwh Consumption'!F23+'Kwh Consumption'!G23+'Kwh Consumption'!H23) -> 1130 | G22: =('Kwh Consumption'!I23+'Kwh Consumption'!J23) -> 140 | H22: =('Kwh Consumption'!K23+'Kwh Consumption'!L23) -> 1620 | I22: =('Kwh Consumption'!M23+'Kwh Consumption'!N23+'Kwh Consumption'!O23+'Kwh Consumption'!P23+'Kwh Consumption'!Q23+'Kwh Consumption'!R23) -> 4881 | J22: =('Kwh Consumption'!S23+'Kwh Consumption'!T23) -> 5476.39 | K22: ='Kwh Consumption'!U23 -> 220 | L22: =B22-C22-D22-E22-F22-G22-H22-I22-J22-K22 -> 7072.61
A23: ='Kwh Reading'!A24 -> 44672 | B23: =TOTAL!E22 -> 0 | C23: ='Kwh Consumption'!C24 -> 550 | D23: ='Kwh Consumption'!D24 -> 2800 | E23: ='Kwh Consumption'!E24 -> 240 | F23: =('Kwh Consumption'!F24+'Kwh Consumption'!G24+'Kwh Consumption'!H24) -> 1110 | G23: =('Kwh Consumption'!I24+'Kwh Consumption'!J24) -> 160 | H23: =('Kwh Consumption'!K24+'Kwh Consumption'!L24) -> 1680 | I23: =('Kwh Consumption'!M24+'Kwh Consumption'!N24+'Kwh Consumption'!O24+'Kwh Consumption'!P24+'Kwh Consumption'!Q24+'Kwh Consumption'!R24) -> 7930.9 | J23: =('Kwh Consumption'!S24+'Kwh Consumption'!T24) -> 5204.52 | K23: ='Kwh Consumption'!U24 -> 200 | L23: =B23-C23-D23-E23-F23-G23-H23-I23-J23-K23 -> -19875.42
A24: ='Kwh Reading'!A25 -> 44673 | B24: =TOTAL!E23 -> 0 | C24: ='Kwh Consumption'!C25 -> 290 | D24: ='Kwh Consumption'!D25 -> 2700 | E24: ='Kwh Consumption'!E25 -> 240 | F24: =('Kwh Consumption'!F25+'Kwh Consumption'!G25+'Kwh Consumption'!H25) -> 960 | G24: =('Kwh Consumption'!I25+'Kwh Consumption'!J25) -> 130 | H24: =('Kwh Consumption'!K25+'Kwh Consumption'!L25) -> 1560 | I24: =('Kwh Consumption'!M25+'Kwh Consumption'!N25+'Kwh Consumption'!O25+'Kwh Consumption'!P25+'Kwh Consumption'!Q25+'Kwh Consumption'!R25) -> 1570.9 | J24: =('Kwh Consumption'!S25+'Kwh Consumption'!T25) -> 4518.49 | K24: ='Kwh Consumption'!U25 -> 220 | L24: =B24-C24-D24-E24-F24-G24-H24-I24-J24-K24 -> -12189.39
A25: ='Kwh Reading'!A26 -> 44674 | B25: =TOTAL!E24 -> 0 | C25: ='Kwh Consumption'!C26 -> 490 | D25: ='Kwh Consumption'!D26 -> 2800 | E25: ='Kwh Consumption'!E26 -> 230 | F25: =('Kwh Consumption'!F26+'Kwh Consumption'!G26+'Kwh Consumption'!H26) -> 940 | G25: =('Kwh Consumption'!I26+'Kwh Consumption'!J26) -> 130 | H25: =('Kwh Consumption'!K26+'Kwh Consumption'!L26) -> 1360 | I25: =('Kwh Consumption'!M26+'Kwh Consumption'!N26+'Kwh Consumption'!O26+'Kwh Consumption'!P26+'Kwh Consumption'!Q26+'Kwh Consumption'!R26) -> 4491 | J25: =('Kwh Consumption'!S26+'Kwh Consumption'!T26) -> 4907.3 | K25: ='Kwh Consumption'!U26 -> 210 | L25: =B25-C25-D25-E25-F25-G25-H25-I25-J25-K25 -> -15558.3
A26: ='Kwh Reading'!A27 -> 44675 | B26: =TOTAL!E25 -> 0 | C26: ='Kwh Consumption'!C27 -> -566540 | D26: ='Kwh Consumption'!D27 -> -3150800 | E26: ='Kwh Consumption'!E27 -> -304360 | F26: =('Kwh Consumption'!F27+'Kwh Consumption'!G27+'Kwh Consumption'!H27) -> -1194770 | G26: =('Kwh Consumption'!I27+'Kwh Consumption'!J27) -> -345690 | H26: =('Kwh Consumption'!K27+'Kwh Consumption'!L27) -> -1664800 | I26: =('Kwh Consumption'!M27+'Kwh Consumption'!N27+'Kwh Consumption'!O27+'Kwh Consumption'!P27+'Kwh Consumption'!Q27+'Kwh Consumption'!R27) -> -3933280.8 | J26: =('Kwh Consumption'!S27+'Kwh Consumption'!T27) -> -17131854 | K26: ='Kwh Consumption'!U27 -> -215390 | L26: =B26-C26-D26-E26-F26-G26-H26-I26-J26-K26 -> 28507485
A27: ='Kwh Reading'!A28 -> 44676 | B27: =TOTAL!E26 -> 0 | C27: ='Kwh Consumption'!C28 -> 0 | D27: ='Kwh Consumption'!D28 -> 0 | E27: ='Kwh Consumption'!E28 -> 0 | F27: =('Kwh Consumption'!F28+'Kwh Consumption'!G28+'Kwh Consumption'!H28) -> 0 | G27: =('Kwh Consumption'!I28+'Kwh Consumption'!J28) -> 0 | H27: =('Kwh Consumption'!K28+'Kwh Consumption'!L28) -> 0 | I27: =('Kwh Consumption'!M28+'Kwh Consumption'!N28+'Kwh Consumption'!O28+'Kwh Consumption'!P28+'Kwh Consumption'!Q28+'Kwh Consumption'!R28) -> 0 | J27: =('Kwh Consumption'!S28+'Kwh Consumption'!T28) -> 0 | K27: ='Kwh Consumption'!U28 -> 0 | L27: =B27-C27-D27-E27-F27-G27-H27-I27-J27-K27 -> 0
... A33: ='Kwh Reading'!A34 -> 44682 | B33: =TOTAL!E32 -> 0 | C33: ='Kwh Consumption'!C34 -> 0 | D33: ='Kwh Consumption'!D34 -> 0 | E33: ='Kwh Consumption'!E34 -> 0 | F33: =('Kwh Consumption'!F34+'Kwh Consumption'!G34+'Kwh Consumption'!H34) -> 0 | G33: =('Kwh Consumption'!I34+'Kwh Consumption'!J34) -> 0 | H33: =('Kwh Consumption'!K34+'Kwh Consumption'!L34) -> 0 | I33: =('Kwh Consumption'!M34+'Kwh Consumption'!N34+'Kwh Consumption'!O34+'Kwh Consumption'!P34+'Kwh Consumption'!Q34+'Kwh Consumption'!R34) -> 0 | J33: =('Kwh Consumption'!S34+'Kwh Consumption'!T34) -> 0 | K33: ='Kwh Consumption'!U34 -> 0 | L33: =B33-C33-D33-E33-F33-G33-H33-I33-J33-K33 -> 0
A34: Total kwh | B34: =SUM(B3:B33) -> 489770 | C34: =SUM(C3:C33) -> -554830 | D34: =SUM(D3:D33) -> -3089800 | E34: =SUM(E3:E33) -> -298990 | F34: =SUM(F3:F33) -> -1167750 | G34: =SUM(G3:G33) -> -342490 | H34: =SUM(H3:H33) -> -1629660 | I34: =SUM(I3:I33) -> -4806630 | ... L34: =SUM(L3:L33) -> 29603730 | M34: =C34+D34+E34+F34+G34+H34+I34+J34+K34+L34 -> 489770
A36: Total $ | B36: =TOTAL!F2 -> 0.194 | C36: =C34*B36 -> -107637.02 | D36: =D34*B36 -> -599421.2 | E36: =E34*B36 -> -58004.06 | F36: =F34*B36 -> -226543.5 | G36: =G34*B36 -> -66443.06 | H36: =H34*B36 -> -316154.04 | I36: =I34*B36 -> -932486.22 | J36: =J34*B36 -> -3300638.3 | K36: =K34*B36 -> -40780.74 | L36: =L34*B36 -> 5743123.5 | M36: =C36+D36+E36+F36+G36+H36+I36+J36+K36+L36 -> 95015.38

Sheet  Kwh area wise $ 
A2: Month | B2: $ /Per KWH | C2: Total $ | D2: Reef Club $ | E2: Kitchen $ | F2: Pastry $ | G2: Laundry $ | H2: STP $ | I2: Kuda Huraa Accomodation $ | J2: Guest Room Beach Pavilion & Beach Bungalow $ | K2: Guest Room Water Bungalow $ | L2: Spa $ | M2: Others $
A3: ='Kwh Reading'!A4 -> 44652 | B3: =TOTAL!F2 -> 0.194 | C3: ='Kwh Consumption'!B4*' Kwh area wise $ '!B3 -> 4675.4 | D3: ='Kwh Consumption'!C4*' Kwh area wise $ '!B3 -> 60.14 | E3: ='Kwh Consumption'!D4*' Kwh area wise $ '!B3 -> 543.2 | F3: ='Kwh Consumption'!E4*' Kwh area wise $ '!B3 -> 50.44 | G3: =('Kwh Consumption'!F4+'Kwh Consumption'!G4+'Kwh Consumption'!H4)*' Kwh area wise $ '!B3 -> 228.92 | H3: =('Kwh Consumption'!I4+'Kwh Consumption'!J4)*' Kwh area wise $ '!B3 -> 27.16 | I3: =('Kwh Consumption'!K4+'Kwh Consumption'!L4)*' Kwh area wise $ '!B3 -> 323.98 | J3: =('Kwh Consumption'!M4+'Kwh Consumption'!N4+'Kwh Consumption'!O4+'Kwh Consumption'!P4+'Kwh Consumption'!Q4+'Kwh Consumption'!R4)*' Kwh area wise $ '!B3 -> 1173.7 | K3: =('Kwh Consumption'!S4+'Kwh Consumption'!T4)*' Kwh area wise $ '!B3 -> 923.65728 | L3: ='Kwh Consumption'!U4*' Kwh area wise $ '!B3 -> 40.74 | M3: ='Kwh Consumption'!V4*' Kwh area wise $ '!B3 -> 1303.4627
A4: ='Kwh Reading'!A5 -> 44653 | B4: =TOTAL!F3 -> 0.194 | C4: ='Kwh Consumption'!B5*' Kwh area wise $ '!B4 -> 4793.74 | D4: ='Kwh Consumption'!C5*' Kwh area wise $ '!B4 -> 112.52 | E4: ='Kwh Consumption'!D5*' Kwh area wise $ '!B4 -> 543.2 | F4: ='Kwh Consumption'!E5*' Kwh area wise $ '!B4 -> 40.74 | G4: =('Kwh Consumption'!F5+'Kwh Consumption'!G5+'Kwh Consumption'!H5)*' Kwh area wise $ '!B4 -> 230.86 | H4: =('Kwh Consumption'!I5+'Kwh Consumption'!J5)*' Kwh area wise $ '!B4 -> 27.16 | I4: =('Kwh Consumption'!K5+'Kwh Consumption'!L5)*' Kwh area wise $ '!B4 -> 322.04 | J4: =('Kwh Consumption'!M5+'Kwh Consumption'!N5+'Kwh Consumption'!O5+'Kwh Consumption'!P5+'Kwh Consumption'!Q5+'Kwh Consumption'!R5)*' Kwh area wise $ '!B4 -> 1177.58 | K4: =('Kwh Consumption'!S5+'Kwh Consumption'!T5)*' Kwh area wise $ '!B4 -> 1025.2881 | L4: ='Kwh Consumption'!U5*' Kwh area wise $ '!B4 -> 44.62 | M4: ='Kwh Consumption'!V5*' Kwh area wise $ '!B4 -> 1269.7319
A5: ='Kwh Reading'!A6 -> 44654 | B5: =TOTAL!F4 -> 0.194 | C5: ='Kwh Consumption'!B6*' Kwh area wise $ '!B5 -> 4723.9 | D5: ='Kwh Consumption'!C6*' Kwh area wise $ '!B5 -> 110.58 | E5: ='Kwh Consumption'!D6*' Kwh area wise $ '!B5 -> 523.8 | F5: ='Kwh Consumption'!E6*' Kwh area wise $ '!B5 -> 46.56 | G5: =('Kwh Consumption'!F6+'Kwh Consumption'!G6+'Kwh Consumption'!H6)*' Kwh area wise $ '!B5 -> 246.38 | H5: =('Kwh Consumption'!I6+'Kwh Consumption'!J6)*' Kwh area wise $ '!B5 -> 29.1 | I5: =('Kwh Consumption'!K6+'Kwh Consumption'!L6)*' Kwh area wise $ '!B5 -> 320.1 | J5: =('Kwh Consumption'!M6+'Kwh Consumption'!N6+'Kwh Consumption'!O6+'Kwh Consumption'!P6+'Kwh Consumption'!Q6+'Kwh Consumption'!R6)*' Kwh area wise $ '!B5 -> 1154.3 | K5: =('Kwh Consumption'!S6+'Kwh Consumption'!T6)*' Kwh area wise $ '!B5 -> 989.91022 | L5: ='Kwh Consumption'!U6*' Kwh area wise $ '!B5 -> 44.62 | M5: ='Kwh Consumption'!V6*' Kwh area wise $ '!B5 -> 1258.5498
A6: ='Kwh Reading'!A7 -> 44655 | B6: =TOTAL!F5 -> 0.194 | C6: ='Kwh Consumption'!B7*' Kwh area wise $ '!B6 -> 4607.5 | D6: ='Kwh Consumption'!C7*' Kwh area wise $ '!B6 -> 108.64 | E6: ='Kwh Consumption'!D7*' Kwh area wise $ '!B6 -> 543.2 | F6: ='Kwh Consumption'!E7*' Kwh area wise $ '!B6 -> 48.5 | G6: =('Kwh Consumption'!F7+'Kwh Consumption'!G7+'Kwh Consumption'!H7)*' Kwh area wise $ '!B6 -> 240.56 | H6: =('Kwh Consumption'!I7+'Kwh Consumption'!J7)*' Kwh area wise $ '!B6 -> 25.22 | I6: =('Kwh Consumption'!K7+'Kwh Consumption'!L7)*' Kwh area wise $ '!B6 -> 258.02 | J6: =('Kwh Consumption'!M7+'Kwh Consumption'!N7+'Kwh Consumption'!O7+'Kwh Consumption'!P7+'Kwh Consumption'!Q7+'Kwh Consumption'!R7)*' Kwh area wise $ '!B6 -> 1195.04 | K6: =('Kwh Consumption'!S7+'Kwh Consumption'!T7)*' Kwh area wise $ '!B6 -> 950.80758 | L6: ='Kwh Consumption'!U7*' Kwh area wise $ '!B6 -> 46.56 | M6: ='Kwh Consumption'!V7*' Kwh area wise $ '!B6 -> 1190.9524
A7: ='Kwh Reading'!A8 -> 44656 | B7: =TOTAL!F6 -> 0.194 | C7: ='Kwh Consumption'!B8*' Kwh area wise $ '!B7 -> 4366.94 | D7: ='Kwh Consumption'!C8*' Kwh area wise $ '!B7 -> 108.64 | E7: ='Kwh Consumption'!D8*' Kwh area wise $ '!B7 -> 504.4 | F7: ='Kwh Consumption'!E8*' Kwh area wise $ '!B7 -> 48.5 | G7: =('Kwh Consumption'!F8+'Kwh Consumption'!G8+'Kwh Consumption'!H8)*' Kwh area wise $ '!B7 -> 221.16 | H7: =('Kwh Consumption'!I8+'Kwh Consumption'!J8)*' Kwh area wise $ '!B7 -> 29.1 | I7: =('Kwh Consumption'!K8+'Kwh Consumption'!L8)*' Kwh area wise $ '!B7 -> 329.8 | J7: =('Kwh Consumption'!M8+'Kwh Consumption'!N8+'Kwh Consumption'!O8+'Kwh Consumption'!P8+'Kwh Consumption'!Q8+'Kwh Consumption'!R8)*' Kwh area wise $ '!B7 -> 1070.88 | K7: =('Kwh Consumption'!S8+'Kwh Consumption'!T8)*' Kwh area wise $ '!B7 -> 862.95468 | L7: ='Kwh Consumption'!U8*' Kwh area wise $ '!B7 -> 36.86 | M7: ='Kwh Consumption'!V8*' Kwh area wise $ '!B7 -> 1154.6453
A8: ='Kwh Reading'!A9 -> 44657 | B8: =TOTAL!F7 -> 0.194 | C8: ='Kwh Consumption'!B9*' Kwh area wise $ '!B8 -> 4605.56 | D8: ='Kwh Consumption'!C9*' Kwh area wise $ '!B8 -> 112.52 | E8: ='Kwh Consumption'!D9*' Kwh area wise $ '!B8 -> 523.8 | F8: ='Kwh Consumption'!E9*' Kwh area wise $ '!B8 -> 44.62 | G8: =('Kwh Consumption'!F9+'Kwh Consumption'!G9+'Kwh Consumption'!H9)*' Kwh area wise $ '!B8 -> 205.64 | H8: =('Kwh Consumption'!I9+'Kwh Consumption'!J9)*' Kwh area wise $ '!B8 -> 29.1 | I8: =('Kwh Consumption'!K9+'Kwh Consumption'!L9)*' Kwh area wise $ '!B8 -> 296.82 | J8: =('Kwh Consumption'!M9+'Kwh Consumption'!N9+'Kwh Consumption'!O9+'Kwh Consumption'!P9+'Kwh Consumption'!Q9+'Kwh Consumption'!R9)*' Kwh area wise $ '!B8 -> 1121.32 | K8: =('Kwh Consumption'!S9+'Kwh Consumption'!T9)*' Kwh area wise $ '!B8 -> 910.44976 | L8: ='Kwh Consumption'!U9*' Kwh area wise $ '!B8 -> 42.68 | M8: ='Kwh Consumption'!V9*' Kwh area wise $ '!B8 -> 1318.6102
A9: ='Kwh Reading'!A10 -> 44658 | B9: =TOTAL!F8 -> 0.194 | C9: ='Kwh Consumption'!B10*' Kwh area wise $ '!B9 -> 4615.26 | D9: ='Kwh Consumption'!C10*' Kwh area wise $ '!B9 -> 112.52 | E9: ='Kwh Consumption'!D10*' Kwh area wise $ '!B9 -> 523.8 | F9: ='Kwh Consumption'!E10*' Kwh area wise $ '!B9 -> 50.44 | G9: =('Kwh Consumption'!F10+'Kwh Consumption'!G10+'Kwh Consumption'!H10)*' Kwh area wise $ '!B9 -> 228.92 | H9: =('Kwh Consumption'!I10+'Kwh Consumption'!J10)*' Kwh area wise $ '!B9 -> 29.1 | I9: =('Kwh Consumption'!K10+'Kwh Consumption'!L10)*' Kwh area wise $ '!B9 -> 322.04 | J9: =('Kwh Consumption'!M10+'Kwh Consumption'!N10+'Kwh Consumption'!O10+'Kwh Consumption'!P10+'Kwh Consumption'!Q10+'Kwh Consumption'!R10)*' Kwh area wise $ '!B9 -> 1164 | K9: =('Kwh Consumption'!S10+'Kwh Consumption'!T10)*' Kwh area wise $ '!B9 -> 983.70028 | L9: ='Kwh Consumption'!U10*' Kwh area wise $ '!B9 -> 40.74 | M9: ='Kwh Consumption'!V10*' Kwh area wise $ '!B9 -> 1159.9997
A10: ='Kwh Reading'!A11 -> 44659 | B10: =TOTAL!F9 -> 0.194 | C10: ='Kwh Consumption'!B11*' Kwh area wise $ '!B10 -> 4820.9 | D10: ='Kwh Consumption'!C11*' Kwh area wise $ '!B10 -> 106.7 | E10: ='Kwh Consumption'!D11*' Kwh area wise $ '!B10 -> 543.2 | F10: ='Kwh Consumption'!E11*' Kwh area wise $ '!B10 -> 50.44 | G10: =('Kwh Consumption'!F11+'Kwh Consumption'!G11+'Kwh Consumption'!H11)*' Kwh area wise $ '!B10 -> 275.48 | H10: =('Kwh Consumption'!I11+'Kwh Consumption'!J11)*' Kwh area wise $ '!B10 -> 21.34 | I10: =('Kwh Consumption'!K11+'Kwh Consumption'!L11)*' Kwh area wise $ '!B10 -> 300.7 | J10: =('Kwh Consumption'!M11+'Kwh Consumption'!N11+'Kwh Consumption'!O11+'Kwh Consumption'!P11+'Kwh Consumption'!Q11+'Kwh Consumption'!R11)*' Kwh area wise $ '!B10 -> 1224.14 | K10: =('Kwh Consumption'!S11+'Kwh Consumption'!T11)*' Kwh area wise $ '!B10 -> 1039.0427 | L10: ='Kwh Consumption'!U11*' Kwh area wise $ '!B10 -> 42.68 | M10: ='Kwh Consumption'!V11*' Kwh area wise $ '!B10 -> 1217.1773
A11: ='Kwh Reading'!A12 -> 44660 | B11: =TOTAL!F10 -> 0.194 | C11: ='Kwh Consumption'!B12*' Kwh area wise $ '!B11 -> 5047.88 | D11: ='Kwh Consumption'!C12*' Kwh area wise $ '!B11 -> 112.52 | E11: ='Kwh Consumption'!D12*' Kwh area wise $ '!B11 -> 543.2 | F11: ='Kwh Consumption'!E12*' Kwh area wise $ '!B11 -> 48.5 | G11: =('Kwh Consumption'!F12+'Kwh Consumption'!G12+'Kwh Consumption'!H12)*' Kwh area wise $ '!B11 -> 226.98 | H11: =('Kwh Consumption'!I12+'Kwh Consumption'!J12)*' Kwh area wise $ '!B11 -> 31.04 | I11: =('Kwh Consumption'!K12+'Kwh Consumption'!L12)*' Kwh area wise $ '!B11 -> 320.1 | J11: =('Kwh Consumption'!M12+'Kwh Consumption'!N12+'Kwh Consumption'!O12+'Kwh Consumption'!P12+'Kwh Consumption'!Q12+'Kwh Consumption'!R12)*' Kwh area wise $ '!B11 -> 1241.6 | K11: =('Kwh Consumption'!S12+'Kwh Consumption'!T12)*' Kwh area wise $ '!B11 -> 1083.5366 | L11: ='Kwh Consumption'!U12*' Kwh area wise $ '!B11 -> 40.74 | M11: ='Kwh Consumption'!V12*' Kwh area wise $ '!B11 -> 1399.6634
A12: ='Kwh Reading'!A13 -> 44661 | B12: =TOTAL!F11 -> 0.194 | C12: ='Kwh Consumption'!B13*' Kwh area wise $ '!B12 -> 4741.36 | D12: ='Kwh Consumption'!C13*' Kwh area wise $ '!B12 -> 110.58 | E12: ='Kwh Consumption'!D13*' Kwh area wise $ '!B12 -> 562.6 | F12: ='Kwh Consumption'!E13*' Kwh area wise $ '!B12 -> 48.5 | G12: =('Kwh Consumption'!F13+'Kwh Consumption'!G13+'Kwh Consumption'!H13)*' Kwh area wise $ '!B12 -> 254.14 | H12: =('Kwh Consumption'!I13+'Kwh Consumption'!J13)*' Kwh area wise $ '!B12 -> 27.16 | I12: =('Kwh Consumption'!K13+'Kwh Consumption'!L13)*' Kwh area wise $ '!B12 -> 327.86 | J12: =('Kwh Consumption'!M13+'Kwh Consumption'!N13+'Kwh Consumption'!O13+'Kwh Consumption'!P13+'Kwh Consumption'!Q13+'Kwh Consumption'!R13)*' Kwh area wise $ '!B12 -> 1218.32 | K12: =('Kwh Consumption'!S13+'Kwh Consumption'!T13)*' Kwh area wise $ '!B12 -> 1093.415 | L12: ='Kwh Consumption'!U13*' Kwh area wise $ '!B12 -> 42.68 | M12: ='Kwh Consumption'!V13*' Kwh area wise $ '!B12 -> 1056.105
A13: ='Kwh Reading'!A14 -> 44662 | B13: =TOTAL!F12 -> 0.194 | C13: ='Kwh Consumption'!B14*' Kwh area wise $ '!B13 -> 5055.64 | D13: ='Kwh Consumption'!C14*' Kwh area wise $ '!B13 -> 108.64 | E13: ='Kwh Consumption'!D14*' Kwh area wise $ '!B13 -> 523.8 | F13: ='Kwh Consumption'!E14*' Kwh area wise $ '!B13 -> 50.44 | G13: =('Kwh Consumption'!F14+'Kwh Consumption'!G14+'Kwh Consumption'!H14)*' Kwh area wise $ '!B13 -> 238.62 | H13: =('Kwh Consumption'!I14+'Kwh Consumption'!J14)*' Kwh area wise $ '!B13 -> 29.1 | I13: =('Kwh Consumption'!K14+'Kwh Consumption'!L14)*' Kwh area wise $ '!B13 -> 300.7 | J13: =('Kwh Consumption'!M14+'Kwh Consumption'!N14+'Kwh Consumption'!O14+'Kwh Consumption'!P14+'Kwh Consumption'!Q14+'Kwh Consumption'!R14)*' Kwh area wise $ '!B13 -> 1196.98 | K13: =('Kwh Consumption'!S14+'Kwh Consumption'!T14)*' Kwh area wise $ '!B13 -> 1154.8025 | L13: ='Kwh Consumption'!U14*' Kwh area wise $ '!B13 -> 42.68 | M13: ='Kwh Consumption'!V14*' Kwh area wise $ '!B13 -> 1409.8775
A14: ='Kwh Reading'!A15 -> 44663 | B14: =TOTAL!F13 -> 0.194 | C14: ='Kwh Consumption'!B15*' Kwh area wise $ '!B14 -> 4886.86 | D14: ='Kwh Consumption'!C15*' Kwh area wise $ '!B14 -> 104.76 | E14: ='Kwh Consumption'!D15*' Kwh area wise $ '!B14 -> 562.6 | F14: ='Kwh Consumption'!E15*' Kwh area wise $ '!B14 -> 48.5 | G14: =('Kwh Consumption'!F15+'Kwh Consumption'!G15+'Kwh Consumption'!H15)*' Kwh area wise $ '!B14 -> 244.44 | H14: =('Kwh Consumption'!I15+'Kwh Consumption'!J15)*' Kwh area wise $ '!B14 -> 32.98 | I14: =('Kwh Consumption'!K15+'Kwh Consumption'!L15)*' Kwh area wise $ '!B14 -> 296.82 | J14: =('Kwh Consumption'!M15+'Kwh Consumption'!N15+'Kwh Consumption'!O15+'Kwh Consumption'!P15+'Kwh Consumption'!Q15+'Kwh Consumption'!R15)*' Kwh area wise $ '!B14 -> -192630.36 | K14: =('Kwh Consumption'!S15+'Kwh Consumption'!T15)*' Kwh area wise $ '!B14 -> 1098.4843 | L14: ='Kwh Consumption'!U15*' Kwh area wise $ '!B14 -> 48.5 | M14: ='Kwh Consumption'!V15*' Kwh area wise $ '!B14 -> 195080.14
A15: ='Kwh Reading'!A16 -> 44664 | B15: =TOTAL!F14 -> 0.194 | C15: ='Kwh Consumption'!B16*' Kwh area wise $ '!B15 -> 4312.62 | D15: 0 | E15: 0 | F15: 0 | G15: 0 | H15: 0 | I15: 0 | J15: =('Kwh Consumption'!M16+'Kwh Consumption'!N16+'Kwh Consumption'!O16+'Kwh Consumption'!P16+'Kwh Consumption'!Q16+'Kwh Consumption'!R16)*' Kwh area wise $ '!B15 -> 828.5546 | K15: =('Kwh Consumption'!S16+'Kwh Consumption'!T16)*' Kwh area wise $ '!B15 -> 879.596 | L15: ='Kwh Consumption'!U16*' Kwh area wise $ '!B15 -> 40.74 | M15: ='Kwh Consumption'!V16*' Kwh area wise $ '!B15 -> 1248.4094
A16: ='Kwh Reading'!A17 -> 44665 | B16: =TOTAL!F15 -> 0.194 | C16: ='Kwh Consumption'!B17*' Kwh area wise $ '!B16 -> 4822.84 | D16: ='Kwh Consumption'!C17*' Kwh area wise $ '!B16 -> 102.82 | E16: ='Kwh Consumption'!D17*' Kwh area wise $ '!B16 -> 562.6 | F16: ='Kwh Consumption'!E17*' Kwh area wise $ '!B16 -> 50.44 | G16: =('Kwh Consumption'!F17+'Kwh Consumption'!G17+'Kwh Consumption'!H17)*' Kwh area wise $ '!B16 -> 298.76 | H16: =('Kwh Consumption'!I17+'Kwh Consumption'!J17)*' Kwh area wise $ '!B16 -> 29.1 | I16: =('Kwh Consumption'!K17+'Kwh Consumption'!L17)*' Kwh area wise $ '!B16 -> 271.6 | J16: =('Kwh Consumption'!M17+'Kwh Consumption'!N17+'Kwh Consumption'!O17+'Kwh Consumption'!P17+'Kwh Consumption'!Q17+'Kwh Consumption'!R17)*' Kwh area wise $ '!B16 -> 917.814 | K16: =('Kwh Consumption'!S17+'Kwh Consumption'!T17)*' Kwh area wise $ '!B16 -> 960.43192 | L16: ='Kwh Consumption'!U17*' Kwh area wise $ '!B16 -> 46.56 | M16: ='Kwh Consumption'!V17*' Kwh area wise $ '!B16 -> 1582.7141
A17: ='Kwh Reading'!A18 -> 44666 | B17: =TOTAL!F16 -> 0.194 | C17: ='Kwh Consumption'!B18*' Kwh area wise $ '!B17 -> 4859.7 | D17: ='Kwh Consumption'!C18*' Kwh area wise $ '!B17 -> 100.88 | E17: ='Kwh Consumption'!D18*' Kwh area wise $ '!B17 -> 543.2 | F17: ='Kwh Consumption'!E18*' Kwh area wise $ '!B17 -> 46.56 | G17: =('Kwh Consumption'!F18+'Kwh Consumption'!G18+'Kwh Consumption'!H18)*' Kwh area wise $ '!B17 -> 294.88 | H17: =('Kwh Consumption'!I18+'Kwh Consumption'!J18)*' Kwh area wise $ '!B17 -> 31.04 | I17: =('Kwh Consumption'!K18+'Kwh Consumption'!L18)*' Kwh area wise $ '!B17 -> 316.22 | J17: =('Kwh Consumption'!M18+'Kwh Consumption'!N18+'Kwh Consumption'!O18+'Kwh Consumption'!P18+'Kwh Consumption'!Q18+'Kwh Consumption'!R18)*' Kwh area wise $ '!B17 -> 966.314 | K17: =('Kwh Consumption'!S18+'Kwh Consumption'!T18)*' Kwh area wise $ '!B17 -> 1009.2811 | L17: ='Kwh Consumption'!U18*' Kwh area wise $ '!B17 -> 46.56 | M17: ='Kwh Consumption'!V18*' Kwh area wise $ '!B17 -> 1504.7649
A18: ='Kwh Reading'!A19 -> 44667 | B18: =TOTAL!F17 -> 0.194 | C18: ='Kwh Consumption'!B19*' Kwh area wise $ '!B18 -> 5030.42 | D18: ='Kwh Consumption'!C19*' Kwh area wise $ '!B18 -> 116.4 | E18: ='Kwh Consumption'!D19*' Kwh area wise $ '!B18 -> 543.2 | F18: ='Kwh Consumption'!E19*' Kwh area wise $ '!B18 -> 46.56 | G18: =('Kwh Consumption'!F19+'Kwh Consumption'!G19+'Kwh Consumption'!H19)*' Kwh area wise $ '!B18 -> 325.92 | H18: =('Kwh Consumption'!I19+'Kwh Consumption'!J19)*' Kwh area wise $ '!B18 -> 29.1 | I18: =('Kwh Consumption'!K19+'Kwh Consumption'!L19)*' Kwh area wise $ '!B18 -> 341.44 | J18: =('Kwh Consumption'!M19+'Kwh Consumption'!N19+'Kwh Consumption'!O19+'Kwh Consumption'!P19+'Kwh Consumption'!Q19+'Kwh Consumption'!R19)*' Kwh area wise $ '!B18 -> 1009.0134 | K18: =('Kwh Consumption'!S19+'Kwh Consumption'!T19)*' Kwh area wise $ '!B18 -> 1035.5507 | L18: ='Kwh Consumption'!U19*' Kwh area wise $ '!B18 -> 56.26 | M18: ='Kwh Consumption'!V19*' Kwh area wise $ '!B18 -> 1526.9759
