Workbook
Name Electricity: DAILY!$A$1:$I$41
Name GASHP: DAILY!$K$1:$Q$42
Name GASLP: DAILY!$K$44:$Q$84
Name GASWW: DAILY!$K$94:$Q$134
Name WATER: DAILY!$A$43:$G$83

Sheet Apr
A1: Site Name | B1: Day | C1: Month | D1: Year | E1: Total Electricity Kwh | F1: Electricity Tariff ($/Kwh) | G1: Natual Gas (m3) | H1: Natural Gas $/m3 | I1: Water Utility Supply (m3) m3 | J1: Water Utility Supply (m3) $/m3 | K1: Room Nights
A2: Washington DC | B2: 1 | C2: 4 | D2: 2022 | E2: 22200 | F2: =DAILY!D7 -> 0.0781 | G2: 914 | H2: 1.08 | I2: 669 | J2: 4.65 | K2: 153
A3: Washington DC | B3: =B2+1 -> 2 | C3: 4 | D3: 2022 | E3: 20400 | F3: =F2 -> 0.0781 | G3: 791 | H3: =H2 -> 1.08 | I3: 592 | J3: =J2 -> 4.65 | K3: 177
A4: Washington DC | B4: =B3+1 -> 3 | C4: 4 | D4: 2022 | E4: 81600 | F4: =F3 -> 0.0781 | G4: 1364 | H4: =H3 -> 1.08 | I4: 604 | J4: =J3 -> 4.65 | K4: 85
A5: Washington DC | B5: =B4+1 -> 4 | C5: 4 | D5: 2022 | E5: 75600 | F5: =F4 -> 0.0781 | G5: 413 | H5: =H4 -> 1.08 | I5: 648 | J5: =J4 -> 4.65 | K5: 103
A6: Washington DC | B6: =B5+1 -> 5 | C6: 4 | D6: 2022 | E6: 102000 | F6: =F5 -> 0.0781 | G6: 3870 | H6: =H5 -> 1.08 | I6: 441 | J6: =J5 -> 4.65 | K6: 113
A7: Washington DC | B7: =B6+1 -> 6 | C7: 4 | D7: 2022 | E7: 77400 | F7: =F6 -> 0.0781 | G7: 930 | H7: =H6 -> 1.08 | I7: 451 | J7: =J6 -> 4.65 | K7: 134
A8: Washington DC | B8: =B7+1 -> 7 | C8: 4 | D8: 2022 | E8: 79200 | F8: =F7 -> 0.0781 | G8: 429 | H8: =H7 -> 1.08 | I8: 240 | J8: =J7 -> 4.65 | K8: 201
A9: Washington DC | B9: =B8+1 -> 8 | C9: 4 | D9: 2022 | E9: 89200 | F9: =F8 -> 0.0781 | G9: 1469 | H9: =H8 -> 1.08 | I9: 1325 | J9: =J8 -> 4.65 | K9: 200
A10: Washington DC | B10: =B9+1 -> 9 | C10: 4 | D10: 2022 | E10: 19800 | F10: =F9 -> 0.0781 | G10: 852 | H10: =H9 -> 1.08 | I10: 649 | J10: =J9 -> 4.65 | K10: 181
A11: Washington DC | B11: =B10+1 -> 10 | C11: 4 | D11: 2022 | E11: 69000 | F11: =F10 -> 0.0781 | G11: 1126 | H11: =H10 -> 1.08 | I11: 786 | J11: =J10 -> 4.65 | K11: 84
A12: Washington DC | B12: =B11+1 -> 11 | C12: 4 | D12: 2022 | E12: 70200 | F12: =F11 -> 0.0781 | G12: 1258 | H12: =H11 -> 1.08 | I12: 507 | J12: =J11 -> 4.65 | K12: 149
A13: Washington DC | B13: =B12+1 -> 12 | C13: 4 | D13: 2022 | E13: 62400 | F13: =F12 -> 0.0781 | G13: 339 | H13: =H12 -> 1.08 | I13: 750 | J13: =J12 -> 4.65 | K13: 77
A14: Washington DC | B14: =B13+1 -> 13 | C14: 4 | D14: 2022 | E14: 66000 | F14: =F13 -> 0.0781 | G14: 976 | H14: =H13 -> 1.08 | I14: 613 | J14: =J13 -> 4.65 | K14: 65
... A31: Washington DC | B31: =B30+1 -> 30 | C31: 4 | D31: 2022 | E31: 16200 | F31: =F30 -> 0.0781 | G31: 872 | H31: =H30 -> 1.08 | I31: 588 | J31: =J30 -> 4.65 | K31: 197

Sheet DAILY
A1: DAILY ENERGY CONSUMPTION | K1: DAILY ENERGY CONSUMPTION
B2: For the month July 2021 | L2: For the month of July 2021.
D4: Meter A | E4: Meter B | F4: Meter A # 1182080412-8 Meter B # 12089312810 | K4: end of last month reading | N4: Meter # 615942
A5: end of last month reading | D5: 52554 | E5: 20699 | L5: 1588100 | M5: unit cost
F6: Area- Serves whole building | M6: 1.08 | N6: Area: Plant for Hot water boilers, steam boiler.
A7: ELECTRICITY | D7: 0.0781
K8: GAS HP
A9: date | B9: Reading "A" | C9: Reading "B" | D9: Meter A kwh ( x 600) | E9: Meter B kwh ( x 600) | F9: rooms occ | G9: cost/day | H9: cost /occ room | I9: remarks | K9: date | L9: meter reading | M9: therms consumption | N9: rooms occ | O9: cost/day | P9: cost /occ room | S9: =7446.43/24513.7 -> 0.30376606
A10: 1 | B10: 52570 | C10: 20721 | D10: =SUM(B10-D5)*600 -> 9600 | E10: =SUM(C10-E5)*600 -> 13200 | F10: 66 | G10: =SUM(D10*D$7)+SUM(E10*D$7) -> 1780.68 | K10: 1 | L10: 1588250 | M10: =SUM(L10-L5) -> 150 | N10: 66 | O10: =SUM(M10*M$6) -> 162 | P10: =IF(N10=0,"",O10/N10) -> 2.4545455
A11: 2 | B11: 52586 | C11: 20741 | D11: =SUM(B11-B10)*600 -> 9600 | E11: =SUM(C11-C10)*600 -> 12000 | F11: 102 | G11: =SUM(D11*D$7)+SUM(E11*D$7) -> 1686.96 | K11: 2 | L11: 1588349 | M11: =SUM(L11-L10) -> 99 | N11: 102 | O11: =SUM(M11*M$6) -> 106.92 | P11: =IF(N11=0,"",O11/N11) -> 1.0482353
A12: 3 | B12: 52605 | C12: 20762 | D12: =SUM(B12-B11)*600 -> 11400 | E12: =SUM(C12-C11)*600 -> 12600 | F12: 130 | G12: =SUM(D12*D$7)+SUM(E12*D$7) -> 1874.4 | K12: 3 | L12: 1588472 | M12: =SUM(L12-L11) -> 123 | N12: 130 | O12: =SUM(M12*M$6) -> 132.84 | P12: =IF(N12=0,"",O12/N12) -> 1.0218462
A13: 4 | B13: 52628 | C13: 20787 | D13: =SUM(B13-B12)*600 -> 13800 | E13: =SUM(C13-C12)*600 -> 15000 | F13: 123 | G13: =SUM(D13*D$7)+SUM(E13*D$7) -> 2249.28 | K13: 4 | L13: 1588703 | M13: =SUM(L13-L12) -> 231 | N13: 123 | O13: =SUM(M13*M$6) -> 249.48 | P13: =IF(N13=0,"",O13/N13) -> 2.0282927
A14: 5 | B14: 52641 | C14: 20805 | D14: =SUM(B14-B13)*600 -> 7800 | E14: =SUM(C14-C13)*600 -> 10800 | F14: 130 | G14: =SUM(D14*D$7)+SUM(E14*D$7) -> 1452.66 | K14: 5 | L14: 1588817 | M14: =SUM(L14-L13) -> 114 | N14: 130 | O14: =SUM(M14*M$6) -> 123.12 | P14: =IF(N14=0,"",O14/N14) -> 0.94707692
A15: 6 | B15: 52665 | C15: 20837 | D15: =SUM(B15-B14)*600 -> 14400 | E15: =SUM(C15-C14)*600 -> 19200 | F15: 126 | G15: =SUM(D15*D$7)+SUM(E15*D$7) -> 2624.16 | K15: 6 | L15: 1588958 | M15: =SUM(L15-L14) -> 141 | N15: 126 | O15: =SUM(M15*M$6) -> 152.28 | P15: =IF(N15=0,"",O15/N15) -> 1.2085714
A16: 7 | B16: 52682 | C16: 20853 | D16: =SUM(B16-B15)*600 -> 10200 | E16: =SUM(C16-C15)*600 -> 9600 | F16: 116 | G16: =SUM(D16*D$7)+SUM(E16*D$7) -> 1546.38 | K16: 7 | L16: 1589121 | M16: =SUM(L16-L15) -> 163 | N16: 116 | O16: =SUM(M16*M$6) -> 176.04 | P16: =IF(N16=0,"",O16/N16) -> 1.5175862
A17: 8 | B17: 52699 | C17: 20873 | D17: =SUM(B17-B16)*600 -> 10200 | E17: =SUM(C17-C16)*600 -> 12000 | F17: 61 | G17: =SUM(D17*D$7)+SUM(E17*D$7) -> 1733.82 | K17: 8 | L17: 1589324 | M17: =SUM(L17-L16) -> 203 | N17: 61 | O17: =SUM(M17*M$6) -> 219.24 | P17: =IF(N17=0,"",O17/N17) -> 3.5940984
A18: 9 | B18: 52719 | C18: 20898 | D18: =SUM(B18-B17)*600 -> 12000 | E18: =SUM(C18-C17)*600 -> 15000 | F18: 72 | G18: =SUM(D18*D$7)+SUM(E18*D$7) -> 2108.7 | K18: 9 | L18: 1589452 | M18: =SUM(L18-L17) -> 128 | N18: 72 | O18: =SUM(M18*M$6) -> 138.24 | P18: =IF(N18=0,"",O18/N18) -> 1.92
A19: 10 | B19: 52738 | C19: 20919 | D19: =SUM(B19-B18)*600 -> 11400 | E19: =SUM(C19-C18)*600 -> 12600 | F19: 83 | G19: =SUM(D19*D$7)+SUM(E19*D$7) -> 1874.4 | K19: 10 | L19: 1589616 | M19: =SUM(L19-L18) -> 164 | N19: 83 | O19: =SUM(M19*M$6) -> 177.12 | P19: =IF(N19=0,"",O19/N19) -> 2.1339759
A20: 11 | B20: 52753 | C20: 20942 | D20: =SUM(B20-B19)*600 -> 9000 | E20: =SUM(C20-C19)*600 -> 13800 | F20: 96 | G20: =SUM(D20*D$7)+SUM(E20*D$7) -> 1780.68 | K20: 11 | L20: 1589838 | M20: =SUM(L20-L19) -> 222 | N20: 96 | O20: =SUM(M20*M$6) -> 239.76 | P20: =IF(N20=0,"",O20/N20) -> 2.4975
A21: 12 | B21: 52781 | C21: 20970 | D21: =SUM(B21-B20)*600 -> 16800 | E21: =SUM(C21-C20)*600 -> 16800 | F21: 121 | G21: =SUM(D21*D$7)+SUM(E21*D$7) -> 2624.16 | K21: 12 | L21: 1589978 | M21: =SUM(L21-L20) -> 140 | N21: 121 | O21: =SUM(M21*M$6) -> 151.2 | P21: =IF(N21=0,"",O21/N21) -> 1.2495868
A22: 13 | B22: 52800 | C22: 20991 | D22: =SUM(B22-B21)*600 -> 11400 | E22: =SUM(C22-C21)*600 -> 12600 | F22: 136 | G22: =SUM(D22*D$7)+SUM(E22*D$7) -> 1874.4 | K22: 13 | L22: 1590099 | M22: =SUM(L22-L21) -> 121 | N22: 136 | O22: =SUM(M22*M$6) -> 130.68 | P22: =IF(N22=0,"",O22/N22) -> 0.96088235
A23: 14 | B23: 52818 | C23: 21011 | D23: =SUM(B23-B22)*600 -> 10800 | E23: =SUM(C23-C22)*600 -> 12000 | F23: 171 | G23: =SUM(D23*D$7)+SUM(E23*D$7) -> 1780.68 | K23: 14 | L23: 1590287 | M23: =SUM(L23-L22) -> 188 | N23: 171 | O23: =SUM(M23*M$6) -> 203.04 | P23: =IF(N23=0,"",O23/N23) -> 1.1873684
A24: 15 | D24: =SUM(B24-B23)*600 -> -31690800 | E24: =SUM(C24-C23)*600 -> -12606600 | G24: =SUM(D24*D$7)+SUM(E24*D$7) -> -3459626.9 | K24: 15 | M24: =SUM(L24-L23) -> -1590287 | O24: =SUM(M24*M$6) -> -1717510 | P24: =IF(N24=0,"",O24/N24)
A25: 16 | D25: =SUM(B25-B24)*600 -> 0 | E25: =SUM(C25-C24)*600 -> 0 | G25: =SUM(D25*D$7)+SUM(E25*D$7) -> 0 | K25: 16 | M25: =SUM(L25-L24) -> 0 | O25: =SUM(M25*M$6) -> 0 | P25: =IF(N25=0,"",O25/N25)
A26: 17 | D26: =SUM(B26-B25)*600 -> 0 | E26: =SUM(C26-C25)*600 -> 0 | G26: =SUM(D26*D$7)+SUM(E26*D$7) -> 0 | K26: 17 | M26: =SUM(L26-L25) -> 0 | O26: =SUM(M26*M$6) -> 0 | P26: =IF(N26=0,"",O26/N26)
A27: 18 | D27: =SUM(B27-B26)*600 -> 0 | E27: =SUM(C27-C26)*600 -> 0 | G27: =SUM(D27*D$7)+SUM(E27*D$7) -> 0 | K27: 18 | M27: =SUM(L27-L26) -> 0 | O27: =SUM(M27*M$6) -> 0 | P27: =IF(N27=0,"",O27/N27)
A28: 19 | D28: =SUM(B28-B27)*600 -> 0 | E28: =SUM(C28-C27)*600 -> 0 | G28: =SUM(D28*D$7)+SUM(E28*D$7) -> 0 | K28: 19 | M28: =SUM(L28-L27) -> 0 | O28: =SUM(M28*M$6) -> 0 | P28: =IF(N28=0,"",O28/N28)
A29: 20 | D29: =SUM(B29-B28)*600 -> 0 | E29: =SUM(C29-C28)*600 -> 0 | G29: =SUM(D29*D$7)+SUM(E29*D$7) -> 0 | K29: 20 | M29: =SUM(L29-L28) -> 0 | O29: =SUM(M29*M$6) -> 0 | P29: =IF(N29=0,"",O29/N29)
A30: 21 | D30: =SUM(B30-B29)*600 -> 0 | E30: =SUM(C30-C29)*600 -> 0 | G30: =SUM(D30*D$7)+SUM(E30*D$7) -> 0 | K30: 21 | M30: =SUM(L30-L29) -> 0 | O30: =SUM(M30*M$6) -> 0 | P30: =IF(N30=0,"",O30/N30)
A31: 22 | D31: =SUM(B31-B30)*600 -> 0 | E31: =SUM(C31-C30)*600 -> 0 | G31: =SUM(D31*D$7)+SUM(E31*D$7) -> 0 | K31: 22 | M31: =SUM(L31-L30) -> 0 | O31: =SUM(M31*M$6) -> 0 | P31: =IF(N31=0,"",O31/N31)
A32: 23 | D32: =SUM(B32-B31)*600 -> 0 | E32: =SUM(C32-C31)*600 -> 0 | G32: =SUM(D32*D$7)+SUM(E32*D$7) -> 0 | K32: 23 | M32: =SUM(L32-L31) -> 0 | O32: =SUM(M32*M$6) -> 0 | P32: =IF(N32=0,"",O32/N32)
A33: 24 | D33: =SUM(B33-B32)*600 -> 0 | E33: =SUM(C33-C32)*600 -> 0 | G33: =SUM(D33*D$7)+SUM(E33*D$7) -> 0 | K33: 24 | M33: =SUM(L33-L32) -> 0 | O33: =SUM(M33*M$6) -> 0 | P33: =IF(N33=0,"",O33/N33)
A34: 25 | D34: =SUM(B34-B33)*600 -> 0 | E34: =SUM(C34-C33)*600 -> 0 | G34: =SUM(D34*D$7)+SUM(E34*D$7) -> 0 | K34: 25 | M34: =SUM(L34-L33) -> 0 | O34: =SUM(M34*M$6) -> 0 | P34: =IF(N34=0,"",O34/N34)
A35: 26 | D35: =SUM(B35-B34)*600 -> 0 | E35: =SUM(C35-C34)*600 -> 0 | G35: =SUM(D35*D$7)+SUM(E35*D$7) -> 0 | K35: 26 | M35: =SUM(L35-L34) -> 0 | O35: =SUM(M35*M$6) -> 0 | P35: =IF(N35=0,"",O35/N35)
... A40: 31 | D40: =SUM(B40-B39)*600 -> 0 | E40: =SUM(C40-C39)*600 -> 0 | G40: =SUM(D40*D$7)+SUM(E40*D$7) -> 0 | K40: 31 | M40: =SUM(L40-L39) -> 0 | O40: =SUM(M40*M$6) -> 0 | P40: =IF(N40=0,"",O40/N40)
A41: Total | D41: =SUM(D10:D40) -> -31532400 | E41: =SUM(E10:E40) -> -12419400 | F41: =SUM(F10:F40) -> 1533 | G41: =SUM(G10:G40) -> -3432635.6 | H41: =G41/F41 -> -2239.1622 | K41: Total | M41: =SUM(M10:M40) -> -1588100 | N41: =SUM(N10:N40) -> 1533 | O41: =SUM(M41*0.15) -> -238215 | P41: =IF(N41=0,"",O41/N41) -> -155.39139
A43: DAILY ENERGY CONSUMPTION | K43: DAILY ENERGY CONSUMPTION
A44: For the month of July 2021. | L44: For the month of July 2021.
A46: end of last month reading | F46: Meter # 16096382A | K46: end of last month reading | N46: Meter # 174863
B47: 13468 | C47: 13717 | E47: unit cost | F47: BYPASS METER# 16096382B | L47: 96588 | M47: unit cost
...

Sheet Jan
A1: Site Name | B1: Day | C1: Month | D1: Year | E1: Total Electricity Kwh | F1: Electricity Tariff ($/Kwh) | G1: Natual Gas (m3) | H1: Natural Gas $/m3 | I1: Water Utility Supply (m3) m3 | J1: Water Utility Supply (m3) $/m3 | K1: Room Nights
A2: Washington DC | B2: 1 | C2: 1 | D2: 2022 | E2: 23400 | F2: =DAILY!D7 -> 0.0781 | G2: 944 | H2: 1.08 | I2: 714 | J2: 4.65 | K2: 149
A3: Washington DC | B3: =B2+1 -> 2 | C3: 1 | D3: 2022 | E3: 21000 | F3: =F2 -> 0.0781 | G3: 611 | H3: =H2 -> 1.08 | I3: 630 | J3: =J2 -> 4.65 | K3: 77
A4: Washington DC | B4: =B3+1 -> 3 | C4: 1 | D4: 2022 | E4: 21000 | F4: =F3 -> 0.0781 | G4: 1016 | H4: =H3 -> 1.08 | I4: 589 | J4: =J3 -> 4.65 | K4: 120
A5: Washington DC | B5: =B4+1 -> 4 | C5: 1 | D5: 2022 | E5: 22200 | F5: =F4 -> 0.0781 | G5: 782 | H5: =H4 -> 1.08 | I5: 448 | J5: =J4 -> 4.65 | K5: 63
A6: Washington DC | B6: =B5+1 -> 5 | C6: 1 | D6: 2022 | E6: 62400 | F6: =F5 -> 0.0781 | G6: 1110 | H6: =H5 -> 1.08 | I6: 687 | J6: =J5 -> 4.65 | K6: 26
A7: Washington DC | B7: =B6+1 -> 6 | C7: 1 | D7: 2022 | E7: 19800 | F7: =F6 -> 0.0781 | G7: 802 | H7: =H6 -> 1.08 | I7: 376 | J7: =J6 -> 4.65 | K7: 30
A8: Washington DC | B8: =B7+1 -> 7 | C8: 1 | D8: 2022 | E8: 22800 | F8: =F7 -> 0.0781 | G8: 1065 | H8: =H7 -> 1.08 | I8: 526 | J8: =J7 -> 4.65 | K8: 36
A9: Washington DC | B9: =B8+1 -> 8 | C9: 1 | D9: 2022 | E9: 20400 | F9: =F8 -> 0.0781 | G9: 1009 | H9: =H8 -> 1.08 | I9: 491 | J9: =J8 -> 4.65 | K9: 46
A10: Washington DC | B10: =B9+1 -> 9 | C10: 1 | D10: 2022 | E10: 24600 | F10: =F9 -> 0.0781 | G10: 192 | H10: =H9 -> 1.08 | I10: 617 | J10: =J9 -> 4.65 | K10: 75
A11: Washington DC | B11: =B10+1 -> 10 | C11: 1 | D11: 2022 | E11: 18000 | F11: =F10 -> 0.0781 | G11: 873 | H11: =H10 -> 1.08 | I11: 459 | J11: =J10 -> 4.65 | K11: 84
A12: Washington DC | B12: =B11+1 -> 11 | C12: 1 | D12: 2022 | E12: 22800 | F12: =F11 -> 0.0781 | G12: 823 | H12: =H11 -> 1.08 | I12: 601 | J12: =J11 -> 4.65 | K12: 80
A13: Washington DC | B13: =B12+1 -> 12 | C13: 1 | D13: 2022 | E13: 22200 | F13: =F12 -> 0.0781 | G13: 1309 | H13: =H12 -> 1.08 | I13: 415 | J13: =J12 -> 4.65 | K13: 32
A14: Washington DC | B14: =B13+1 -> 13 | C14: 1 | D14: 2022 | E14: 21600 | F14: =F13 -> 0.0781 | G14: 1023 | H14: =H13 -> 1.08 | I14: 460 | J14: =J13 -> 4.65 | K14: 33
... A32: Washington DC | B32: =B31+1 -> 31 | C32: 1 | D32: 2022 | E32: 25800 | F32: =F31 -> 0.0781 | G32: 1280 | H32: =H31 -> 1.08 | I32: 374 | J32: =J31 -> 4.65 | K32: 157

Sheet Feb
A1: Site Name | B1: Day | C1: Month | D1: Year | E1: Total Electricity Kwh | F1: Electricity Tariff ($/Kwh) | G1: Natual Gas (m3) | H1: Natural Gas $/m3 | I1: Water Utility Supply (m3) m3 | J1: Water Utility Supply (m3) $/m3 | K1: Room Nights
A2: Washington DC | B2: 1 | C2: 2 | D2: 2022 | E2: 22800 | F2: =DAILY!D7 -> 0.0781 | G2: 1109 | H2: 1.08 | I2: 623 | J2: 4.65 | K2: 84
A3: Washington DC | B3: =B2+1 -> 2 | C3: 2 | D3: 2022 | E3: 22200 | F3: =F2 -> 0.0781 | G3: 341 | H3: =H2 -> 1.08 | I3: 124 | J3: =J2 -> 4.65 | K3: 54
A4: Washington DC | B4: =B3+1 -> 3 | C4: 2 | D4: 2022 | E4: 23400 | F4: =F3 -> 0.0781 | G4: 1753 | H4: =H3 -> 1.08 | I4: 825 | J4: =J3 -> 4.65 | K4: 81
A5: Washington DC | B5: =B4+1 -> 4 | C5: 2 | D5: 2022 | E5: 17400 | F5: =F4 -> 0.0781 | G5: 892 | H5: =H4 -> 1.08 | I5: 411 | J5: =J4 -> 4.65 | K5: 98
A6: Washington DC | B6: =B5+1 -> 5 | C6: 2 | D6: 2022 | E6: 21000 | F6: =F5 -> 0.0781 | G6: 904 | H6: =H5 -> 1.08 | I6: 432 | J6: =J5 -> 4.65 | K6: 55
A7: Washington DC | B7: =B6+1 -> 6 | C7: 2 | D7: 2022 | E7: 27600 | F7: =F6 -> 0.0781 | G7: 1427 | H7: =H6 -> 1.08 | I7: 571 | J7: =J6 -> 4.65 | K7: 122
A8: Washington DC | B8: =B7+1 -> 7 | C8: 2 | D8: 2022 | E8: 13200 | F8: =F7 -> 0.0781 | G8: 653 | H8: =H7 -> 1.08 | I8: 416 | J8: =J7 -> 4.65 | K8: 147
A9: Washington DC | B9: =B8+1 -> 8 | C9: 2 | D9: 2022 | E9: 25800 | F9: =F8 -> 0.0781 | G9: 1153 | H9: =H8 -> 1.08 | I9: 428 | J9: =J8 -> 4.65 | K9: 101
A10: Washington DC | B10: =B9+1 -> 9 | C10: 2 | D10: 2022 | E10: 26400 | F10: =F9 -> 0.0781 | G10: 1092 | H10: =H9 -> 1.08 | I10: 573 | J10: =J9 -> 4.65 | K10: 91
A11: Washington DC | B11: =B10+1 -> 10 | C11: 2 | D11: 2022 | E11: 23400 | F11: =F10 -> 0.0781 | G11: 942 | H11: =H10 -> 1.08 | I11: 528 | J11: =J10 -> 4.65 | K11: 145
A12: Washington DC | B12: =B11+1 -> 11 | C12: 2 | D12: 2022 | E12: 18600 | F12: =F11 -> 0.0781 | G12: 797 | H12: =H11 -> 1.08 | I12: 476 | J12: =J11 -> 4.65 | K12: 115
A13: Washington DC | B13: =B12+1 -> 12 | C13: 2 | D13: 2022 | E13: 21600 | F13: =F12 -> 0.0781 | G13: 849 | H13: =H12 -> 1.08 | I13: 525 | J13: =J12 -> 4.65 | K13: 140
A14: Washington DC | B14: =B13+1 -> 13 | C14: 2 | D14: 2022 | E14: 28600 | F14: =F13 -> 0.0781 | G14: 562 | H14: =H13 -> 1.08 | I14: 121 | J14: =J13 -> 4.65 | K14: 111
... A29: Washington DC | B29: =B28+1 -> 28 | C29: 2 | D29: 2022 | E29: 19800 | F29: =F28 -> 0.0781 | G29: 860 | H29: =H28 -> 1.08 | I29: 815 | J29: =J28 -> 4.65 | K29: 122

Sheet Mar
A1: Site Name | B1: Day | C1: Month | D1: Year | E1: Total Electricity Kwh | F1: Electricity Tariff ($/Kwh) | G1: Natual Gas (m3) | H1: Natural Gas $/m3 | I1: Water Utility Supply (m3) m3 | J1: Water Utility Supply (m3) $/m3 | K1: Room Nights
A2: Washington DC | B2: 1 | C2: 3 | D2: 2022 | E2: 23400 | F2: =DAILY!D7 -> 0.0781 | G2: 926 | H2: 1.08 | I2: 541 | J2: 4.65 | K2: 196
A3: Washington DC | B3: =B2+1 -> 2 | C3: 3 | D3: 2022 | E3: 24600 | F3: =F2 -> 0.0781 | G3: 819 | H3: =H2 -> 1.08 | I3: 384 | J3: =J2 -> 4.65 | K3: 146
A4: Washington DC | B4: =B3+1 -> 3 | C4: 3 | D4: 2022 | E4: 25800 | F4: =F3 -> 0.0781 | G4: 1254 | H4: =H3 -> 1.08 | I4: 643 | J4: =J3 -> 4.65 | K4: 199
A5: Washington DC | B5: =B4+1 -> 4 | C5: 3 | D5: 2022 | E5: 16800 | F5: =F4 -> 0.0781 | G5: 454 | H5: =H4 -> 1.08 | I5: 494 | J5: =J4 -> 4.65 | K5: 222
A6: Washington DC | B6: =B5+1 -> 5 | C6: 3 | D6: 2022 | E6: 22200 | F6: =F5 -> 0.0781 | G6: 935 | H6: =H5 -> 1.08 | I6: 602 | J6: =J5 -> 4.65 | K6: 156
A7: Washington DC | B7: =B6+1 -> 6 | C7: 3 | D7: 2022 | E7: 24000 | F7: =F6 -> 0.0781 | G7: 937 | H7: =H6 -> 1.08 | I7: 679 | J7: =J6 -> 4.65 | K7: 48
A8: Washington DC | B8: =B7+1 -> 7 | C8: 3 | D8: 2022 | E8: 22800 | F8: =F7 -> 0.0781 | G8: 352 | H8: =H7 -> 1.08 | I8: 549 | J8: =J7 -> 4.65 | K8: 85
A9: Washington DC | B9: =B8+1 -> 8 | C9: 3 | D9: 2022 | E9: 19800 | F9: =F8 -> 0.0781 | G9: 593 | H9: =H8 -> 1.08 | I9: 434 | J9: =J8 -> 4.65 | K9: 104
A10: Washington DC | B10: =B9+1 -> 9 | C10: 3 | D10: 2022 | E10: 16200 | F10: =F9 -> 0.0781 | G10: 848 | H10: =H9 -> 1.08 | I10: 530 | J10: =J9 -> 4.65 | K10: 183
A11: Washington DC | B11: =B10+1 -> 10 | C11: 3 | D11: 2022 | E11: 21000 | F11: =F10 -> 0.0781 | G11: 1058 | H11: =H10 -> 1.08 | I11: 615 | J11: =J10 -> 4.65 | K11: 189
A12: Washington DC | B12: =B11+1 -> 11 | C12: 3 | D12: 2022 | E12: 23400 | F12: =F11 -> 0.0781 | G12: 929 | H12: =H11 -> 1.08 | I12: 607 | J12: =J11 -> 4.65 | K12: 205
A13: Washington DC | B13: =B12+1 -> 12 | C13: 3 | D13: 2022 | E13: 22800 | F13: =F12 -> 0.0781 | G13: 873 | H13: =H12 -> 1.08 | I13: 570 | J13: =J12 -> 4.65 | K13: 105
A14: Washington DC | B14: =B13+1 -> 13 | C14: 3 | D14: 2022 | E14: 23400 | F14: =F13 -> 0.0781 | G14: 1248 | H14: =H13 -> 1.08 | I14: 543 | J14: =J13 -> 4.65 | K14: 158
... A32: Washington DC | B32: =B31+1 -> 31 | C32: 3 | D32: 2022 | E32: 13200 | F32: =F31 -> 0.0781 | G32: 486 | H32: =H31 -> 1.08 | I32: 497 | J32: =J31 -> 4.65 | K32: 144

Sheet May
A1: Site Name | B1: Day | C1: Month | D1: Year | E1: Total Electricity Kwh | F1: Electricity Tariff ($/Kwh) | G1: Natual Gas (m3) | H1: Natural Gas $/m3 | I1: Water Utility Supply (m3) m3 | J1: Water Utility Supply (m3) $/m3 | K1: Room Nights
A2: Washington DC | B2: 1 | C2: 5 | D2: 2022 | F2: =DAILY!D7 -> 0.0781 | H2: 1.08 | J2: 4.65
A3: Washington DC | B3: =B2+1 -> 2 | C3: 5 | D3: 2022 | F3: =F2 -> 0.0781 | H3: =H2 -> 1.08 | J3: =J2 -> 4.65
A4: Washington DC | B4: =B3+1 -> 3 | C4: 5 | D4: 2022 | F4: =F3 -> 0.0781 | H4: =H3 -> 1.08 | J4: =J3 -> 4.65
A5: Washington DC | B5: =B4+1 -> 4 | C5: 5 | D5: 2022 | F5: =F4 -> 0.0781 | H5: =H4 -> 1.08 | J5: =J4 -> 4.65
A6: Washington DC | B6: =B5+1 -> 5 | C6: 5 | D6: 2022 | F6: =F5 -> 0.0781 | H6: =H5 -> 1.08 | J6: =J5 -> 4.65
A7: Washington DC | B7: =B6+1 -> 6 | C7: 5 | D7: 2022 | F7: =F6 -> 0.0781 | H7: =H6 -> 1.08 | J7: =J6 -> 4.65
A8: Washington DC | B8: =B7+1 -> 7 | C8: 5 | D8: 2022 | F8: =F7 -> 0.0781 | H8: =H7 -> 1.08 | J8: =J7 -> 4.65
A9: Washington DC | B9: =B8+1 -> 8 | C9: 5 | D9: 2022 | F9: =F8 -> 0.0781 | H9: =H8 -> 1.08 | J9: =J8 -> 4.65
A10: Washington DC | B10: =B9+1 -> 9 | C10: 5 | D10: 2022 | F10: =F9 -> 0.0781 | H10: =H9 -> 1.08 | J10: =J9 -> 4.65
A11: Washington DC | B11: =B10+1 -> 10 | C11: 5 | D11: 2022 | F11: =F10 -> 0.0781 | H11: =H10 -> 1.08 | J11: =J10 -> 4.65
A12: Washington DC | B12: =B11+1 -> 11 | C12: 5 | D12: 2022 | F12: =F11 -> 0.0781 | H12: =H11 -> 1.08 | J12: =J11 -> 4.65
A13: Washington DC | B13: =B12+1 -> 12 | C13: 5 | D13: 2022 | F13: =F12 -> 0.0781 | H13: =H12 -> 1.08 | J13: =J12 -> 4.65
A14: Washington DC | B14: =B13+1 -> 13 | C14: 5 | D14: 2022 | F14: =F13 -> 0.0781 | H14: =H13 -> 1.08 | J14: =J13 -> 4.65
... A32: Washington DC | B32: =B31+1 -> 31 | C32: 5 | D32: 2022 | F32: =F31 -> 0.0781 | H32: =H31 -> 1.08 | J32: =J31 -> 4.65

Sheet Jun
A1: Site Name | B1: Day | C1: Month | D1: Year | E1: Total Electricity Kwh | F1: Electricity Tariff ($/Kwh) | G1: Natual Gas (m3) | H1: Natural Gas $/m3 | I1: Water Utility Supply (m3) m3 | J1: Water Utility Supply (m3) $/m3 | K1: Room Nights
A2: Washington DC | B2: 1 | C2: 6 | D2: 2022 | F2: =DAILY!D7 -> 0.0781 | H2: 1.08 | J2: 4.65
A3: Washington DC | B3: =B2+1 -> 2 | C3: 6 | D3: 2022 | F3: =F2 -> 0.0781 | H3: =H2 -> 1.08 | J3: =J2 -> 4.65
A4: Washington DC | B4: =B3+1 -> 3 | C4: 6 | D4: 2022 | F4: =F3 -> 0.0781 | H4: =H3 -> 1.08 | J4: =J3 -> 4.65
A5: Washington DC | B5: =B4+1 -> 4 | C5: 6 | D5: 2022 | F5: =F4 -> 0.0781 | H5: =H4 -> 1.08 | J5: =J4 -> 4.65
A6: Washington DC | B6: =B5+1 -> 5 | C6: 6 | D6: 2022 | F6: =F5 -> 0.0781 | H6: =H5 -> 1.08 | J6: =J5 -> 4.65
A7: Washington DC | B7: =B6+1 -> 6 | C7: 6 | D7: 2022 | F7: =F6 -> 0.0781 | H7: =H6 -> 1.08 | J7: =J6 -> 4.65
A8: Washington DC | B8: =B7+1 -> 7 | C8: 6 | D8: 2022 | F8: =F7 -> 0.0781 | H8: =H7 -> 1.08 | J8: =J7 -> 4.65
A9: Washington DC | B9: =B8+1 -> 8 | C9: 6 | D9: 2022 | F9: =F8 -> 0.0781 | H9: =H8 -> 1.08 | J9: =J8 -> 4.65
A10: Washington DC | B10: =B9+1 -> 9 | C10: 6 | D10: 2022 | F10: =F9 -> 0.0781 | H10: =H9 -> 1.08 | J10: =J9 -> 4.65
A11: Washington DC | B11: =B10+1 -> 10 | C11: 6 | D11: 2022 | F11: =F10 -> 0.0781 | H11: =H10 -> 1.08 | J11: =J10 -> 4.65
A12: Washington DC | B12: =B11+1 -> 11 | C12: 6 | D12: 2022 | F12: =F11 -> 0.0781 | H12: =H11 -> 1.08 | J12: =J11 -> 4.65
A13: Washington DC | B13: =B12+1 -> 12 | C13: 6 | D13: 2022 | F13: =F12 -> 0.0781 | H13: =H12 -> 1.08 | J13: =J12 -> 4.65
A14: Washington DC | B14: =B13+1 -> 13 | C14: 6 | D14: 2022 | F14: =F13 -> 0.0781 | H14: =H13 -> 1.08 | J14: =J13 -> 4.65
... A32: Washington DC | B32: =B31+1 -> 31 | C32: 6 | D32: 2022 | F32: =F31 -> 0.0781 | H32: =H31 -> 1.08 | J32: =J31 -> 4.65

Sheet July
A1: Site Name | B1: Day | C1: Month | D1: Year | E1: Total Electricity Kwh | F1: Electricity Tariff ($/Kwh) | G1: Natual Gas (m3) | H1: Natural Gas $/m3 | I1: Water Utility Supply (m3) m3 | J1: Water Utility Supply (m3) $/m3 | K1: Room Nights
A2: Washington DC | B2: 1 | C2: 7 | D2: 2022 | F2: =DAILY!D7 -> 0.0781 | H2: 1.08 | J2: 4.65
A3: Washington DC | B3: =B2+1 -> 2 | C3: 7 | D3: 2022 | F3: =F2 -> 0.0781 | H3: =H2 -> 1.08 | J3: =J2 -> 4.65
A4: Washington DC | B4: =B3+1 -> 3 | C4: 7 | D4: 2022 | F4: =F3 -> 0.0781 | H4: =H3 -> 1.08 | J4: =J3 -> 4.65
A5: Washington DC | B5: =B4+1 -> 4 | C5: 7 | D5: 2022 | F5: =F4 -> 0.0781 | H5: =H4 -> 1.08 | J5: =J4 -> 4.65
A6: Washington DC | B6: =B5+1 -> 5 | C6: 7 | D6: 2022 | F6: =F5 -> 0.0781 | H6: =H5 -> 1.08 | J6: =J5 -> 4.65
A7: Washington DC | B7: =B6+1 -> 6 | C7: 7 | D7: 2022 | F7: =F6 -> 0.0781 | H7: =H6 -> 1.08 | J7: =J6 -> 4.65
A8: Washington DC | B8: =B7+1 -> 7 | C8: 7 | D8: 2022 | F8: =F7 -> 0.0781 | H8: =H7 -> 1.08 | J8: =J7 -> 4.65
A9: Washington DC | B9: =B8+1 -> 8 | C9: 7 | D9: 2022 | F9: =F8 -> 0.0781 | H9: =H8 -> 1.08 | J9: =J8 -> 4.65
A10: Washington DC | B10: =B9+1 -> 9 | C10: 7 | D10: 2022 | F10: =F9 -> 0.0781 | H10: =H9 -> 1.08 | J10: =J9 -> 4.65
A11: Washington DC | B11: =B10+1 -> 10 | C11: 7 | D11: 2022 | F11: =F10 -> 0.0781 | H11: =H10 -> 1.08 | J11: =J10 -> 4.65
A12: Washington DC | B12: =B11+1 -> 11 | C12: 7 | D12: 2022 | F12: =F11 -> 0.0781 | H12: =H11 -> 1.08 | J12: =J11 -> 4.65
A13: Washington DC | B13: =B12+1 -> 12 | C13: 7 | D13: 2022 | F13: =F12 -> 0.0781 | H13: =H12 -> 1.08 | J13: =J12 -> 4.65
A14: Washington DC | B14: =B13+1 -> 13 | C14: 7 | D14: 2022 | F14: =F13 -> 0.0781 | H14: =H13 -> 1.08 | J14: =J13 -> 4.65
... A32: Washington DC | B32: =B31+1 -> 31 | C32: 7 | D32: 2022 | F32: =F31 -> 0.0781 | H32: =H31 -> 1.08 | J32: =J31 -> 4.65

Sheet August 
A1: Site Name | B1: Day | C1: Month | D1: Year | E1: Total Electricity Kwh | F1: Electricity Tariff ($/Kwh) | G1: Natual Gas (m3) | H1: Natural Gas $/m3 | I1: Water Utility Supply (m3) m3 | J1: Water Utility Supply (m3) $/m3 | K1: Room Nights
A2: Washington DC | B2: 1 | C2: 8 | D2: 2022 | F2: =DAILY!D7 -> 0.0781 | H2: 1.08 | J2: 4.65
A3: Washington DC | B3: =B2+1 -> 2 | C3: 8 | D3: 2022 | F3: =F2 -> 0.0781 | H3: =H2 -> 1.08 | J3: =J2 -> 4.65
A4: Washington DC | B4: =B3+1 -> 3 | C4: 8 | D4: 2022 | F4: =F3 -> 0.0781 | H4: =H3 -> 1.08 | J4: =J3 -> 4.65
A5: Washington DC | B5: =B4+1 -> 4 | C5: 8 | D5: 2022 | F5: =F4 -> 0.0781 | H5: =H4 -> 1.08 | J5: =J4 -> 4.65
A6: Washington DC | B6: =B5+1 -> 5 | C6: 8 | D6: 2022 | F6: =F5 -> 0.0781 | H6: =H5 -> 1.08 | J6: =J5 -> 4.65
A7: Washington DC | B7: =B6+1 -> 6 | C7: 8 | D7: 2022 | F7: =F6 -> 0.0781 | H7: =H6 -> 1.08 | J7: =J6 -> 4.65
A8: Washington DC | B8: =B7+1 -> 7 | C8: 8 | D8: 2022 | F8: =F7 -> 0.0781 | H8: =H7 -> 1.08 | J8: =J7 -> 4.65
A9: Washington DC | B9: =B8+1 -> 8 | C9: 8 | D9: 2022 | F9: =F8 -> 0.0781 | H9: =H8 -> 1.08 | J9: =J8 -> 4.65
A10: Washington DC | B10: =B9+1 -> 9 | C10: 8 | D10: 2022 | F10: =F9 -> 0.0781 | H10: =H9 -> 1.08 | J10: =J9 -> 4.65
A11: Washington DC | B11: =B10+1 -> 10 | C11: 8 | D11: 2022 | F11: =F10 -> 0.0781 | H11: =H10 -> 1.08 | J11: =J10 -> 4.65
A12: Washington DC | B12: =B11+1 -> 11 | C12: 8 | D12: 2022 | F12: =F11 -> 0.0781 | H12: =H11 -> 1.08 | J12: =J11 -> 4.65
A13: Washington DC | B13: =B12+1 -> 12 | C13: 8 | D13: 2022 | F13: =F12 -> 0.0781 | H13: =H12 -> 1.08 | J13: =J12 -> 4.65
A14: Washington DC | B14: =B13+1 -> 13 | C14: 8 | D14: 2022 | F14: =F13 -> 0.0781 | H14: =H13 -> 1.08 | J14: =J13 -> 4.65
... A32: Washington DC | B32: =B31+1 -> 31 | C32: 8 | D32: 2022 | F32: =F31 -> 0.0781 | H32: =H31 -> 1.08 | J32: =J31 -> 4.65

Sheet September
A1: Site Name | B1: Day | C1: Month | D1: Year | E1: Total Electricity Kwh | F1: Electricity Tariff ($/Kwh) | G1: Natual Gas (m3) | H1: Natural Gas $/m3 | I1: Water Utility Supply (m3) m3 | J1: Water Utility Supply (m3) $/m3 | K1: Room Nights
A2: Washington DC | B2: 1 | C2: 9 | D2: 2022 | F2: =DAILY!D7 -> 0.0781 | H2: 1.08 | J2: 4.65
A3: Washington DC | B3: =B2+1 -> 2 | C3: 9 | D3: 2022 | F3: =F2 -> 0.0781 | H3: =H2 -> 1.08 | J3: =J2 -> 4.65
A4: Washington DC | B4: =B3+1 -> 3 | C4: 9 | D4: 2022 | F4: =F3 -> 0.0781 | H4: =H3 -> 1.08 | J4: =J3 -> 4.65
A5: Washington DC | B5: =B4+1 -> 4 | C5: 9 | D5: 2022 | F5: =F4 -> 0.0781 | H5: =H4 -> 1.08 | J5: =J4 -> 4.65
A6: Washington DC | B6: =B5+1 -> 5 | C6: 9 | D6: 2022 | F6: =F5 -> 0.0781 | H6: =H5 -> 1.08 | J6: =J5 -> 4.65
A7: Washington DC | B7: =B6+1 -> 6 | C7: 9 | D7: 2022 | F7: =F6 -> 0.0781 | H7: =H6 -> 1.08 | J7: =J6 -> 4.65
A8: Washington DC | B8: =B7+1 -> 7 | C8: 9 | D8: 2022 | F8: =F7 -> 0.0781 | H8: =H7 -> 1.08 | J8: =J7 -> 4.65
A9: Washington DC | B9: =B8+1 -> 8 | C9: 9 | D9: 2022 | F9: =F8 -> 0.0781 | H9: =H8 -> 1.08 | J9: =J8 -> 4.65
A10: Washington DC | B10: =B9+1 -> 9 | C10: 9 | D10: 2022 | F10: =F9 -> 0.0781 | H10: =H9 -> 1.08 | J10: =J9 -> 4.65
A11: Washington DC | B11: =B10+1 -> 10 | C11: 9 | D11: 2022 | F11: =F10 -> 0.0781 | H11: =H10 -> 1.08 | J11: =J10 -> 4.65
A12: Washington DC | B12: =B11+1 -> 11 | C12: 9 | D12: 2022 | F12: =F11 -> 0.0781 | H12: =H11 -> 1.08 | J12: =J11 -> 4.65
A13: Washington DC | B13: =B12+1 -> 12 | C13: 9 | D13: 2022 | F13: =F12 -> 0.0781 | H13: =H12 -> 1.08 | J13: =J12 -> 4.65
A14: Washington DC | B14: =B13+1 -> 13 | C14: 9 | D14: 2022 | F14: =F13 -> 0.0781 | H14: =H13 -> 1.08 | J14: =J13 -> 4.65
... A31: Washington DC | B31: =B30+1 -> 30 | C31: 9 | D31: 2022 | F31: =F30 -> 0.0781 | H31: =H30 -> 1.08 | J31: =J30 -> 4.65

Sheet October
A1: Site Name | B1: Day | C1: Month | D1: Year | E1: Total Electricity Kwh | F1: Electricity Tariff ($/Kwh) | G1: Natual Gas (m3) | H1: Natural Gas $/m3 | I1: Water Utility Supply (m3) m3 | J1: Water Utility Supply (m3) $/m3 | K1: Room Nights
A2: Washington DC | B2: 1 | C2: 10 | D2: 2022 | F2: =DAILY!D7 -> 0.0781 | H2: 1.08 | J2: 4.65
A3: Washington DC | B3: =B2+1 -> 2 | C3: 10 | D3: 2022 | F3: =F2 -> 0.0781 | H3: =H2 -> 1.08 | J3: =J2 -> 4.65
A4: Washington DC | B4: =B3+1 -> 3 | C4: 10 | D4: 2022 | F4: =F3 -> 0.0781 | H4: =H3 -> 1.08 | J4: =J3 -> 4.65
A5: Washington DC | B5: =B4+1 -> 4 | C5: 10 | D5: 2022 | F5: =F4 -> 0.0781 | H5: =H4 -> 1.08 | J5: =J4 -> 4.65
A6: Washington DC | B6: =B5+1 -> 5 | C6: 10 | D6: 2022 | F6: =F5 -> 0.0781 | H6: =H5 -> 1.08 | J6: =J5 -> 4.65
A7: Washington DC | B7: =B6+1 -> 6 | C7: 10 | D7: 2022 | F7: =F6 -> 0.0781 | H7: =H6 -> 1.08 | J7: =J6 -> 4.65
A8: Washington DC | B8: =B7+1 -> 7 | C8: 10 | D8: 2022 | F8: =F7 -> 0.0781 | H8: =H7 -> 1.08 | J8: =J7 -> 4.65
A9: Washington DC | B9: =B8+1 -> 8 | C9: 10 | D9: 2022 | F9: =F8 -> 0.0781 | H9: =H8 -> 1.08 | J9: =J8 -> 4.65
A10: Washington DC | B10: =B9+1 -> 9 | C10: 10 | D10: 2022 | F10: =F9 -> 0.0781 | H10: =H9 -> 1.08 | J10: =J9 -> 4.65
A11: Washington DC | B11: =B10+1 -> 10 | C11: 10 | D11: 2022 | F11: =F10 -> 0.0781 | H11: =H10 -> 1.08 | J11: =J10 -> 4.65
A12: Washington DC | B12: =B11+1 -> 11 | C12: 10 | D12: 2022 | F12: =F11 -> 0.0781 | H12: =H11 -> 1.08 | J12: =J11 -> 4.65
A13: Washington DC | B13: =B12+1 -> 12 | C13: 10 | D13: 2022 | F13: =F12 -> 0.0781 | H13: =H12 -> 1.08 | J13: =J12 -> 4.65
A14: Washington DC | B14: =B13+1 -> 13 | C14: 10 | D14: 2022 | F14: =F13 -> 0.0781 | H14: =H13 -> 1.08 | J14: =J13 -> 4.65
... A30: Washington DC | B30: =B29+1 -> 29 | C30: 10 | D30: 2022 | F30: =F29 -> 0.0781 | H30: =H29 -> 1.08 | J30: =J29 -> 4.65
A31: Washington DC | B31: =B30+1 -> 30 | C31: 10 | D31: 2022 | F31: =F29 -> 0.0781 | H31: =H29 -> 1.08 | J31: =J29 -> 4.65
A32: Washington DC | B32: =B31+1 -> 31 | C32: 10 | D32: 2022 | F32: =F30 -> 0.0781 | H32: =H30 -> 1.08 | J32: =J30 -> 4.65

Sheet November
A1: Site Name | B1: Day | C1: Month | D1: Year | E1: Total Electricity Kwh | F1: Electricity Tariff ($/Kwh) | G1: Natual Gas (m3) | H1: Natural Gas $/m3 | I1: Water Utility Supply (m3) m3 | J1: Water Utility Supply (m3) $/m3 | K1: Room Nights
A2: Washington DC | B2: 1 | C2: 11 | D2: 2022 | F2: =DAILY!D7 -> 0.0781 | H2: 0.15 | J2: 4.65
A3: Washington DC | B3: =B2+1 -> 2 | C3: 11 | D3: 2022 | F3: =F2 -> 0.0781 | H3: =H2 -> 0.15 | J3: =J2 -> 4.65
A4: Washington DC | B4: =B3+1 -> 3 | C4: 11 | D4: 2022 | F4: =F3 -> 0.0781 | H4: =H3 -> 0.15 | J4: =J3 -> 4.65
A5: Washington DC | B5: =B4+1 -> 4 | C5: 11 | D5: 2022 | F5: =F4 -> 0.0781 | H5: =H4 -> 0.15 | J5: =J4 -> 4.65
A6: Washington DC | B6: =B5+1 -> 5 | C6: 11 | D6: 2022 | F6: =F5 -> 0.0781 | H6: =H5 -> 0.15 | J6: =J5 -> 4.65
A7: Washington DC | B7: =B6+1 -> 6 | C7: 11 | D7: 2022 | F7: =F6 -> 0.0781 | H7: =H6 -> 0.15 | J7: =J6 -> 4.65
A8: Washington DC | B8: =B7+1 -> 7 | C8: 11 | D8: 2022 | F8: =F7 -> 0.0781 | H8: =H7 -> 0.15 | J8: =J7 -> 4.65
A9: Washington DC | B9: =B8+1 -> 8 | C9: 11 | D9: 2022 | F9: =F8 -> 0.0781 | H9: =H8 -> 0.15 | J9: =J8 -> 4.65
A10: Washington DC | B10: =B9+1 -> 9 | C10: 11 | D10: 2022 | F10: =F9 -> 0.0781 | H10: =H9 -> 0.15 | J10: =J9 -> 4.65
A11: Washington DC | B11: =B10+1 -> 10 | C11: 11 | D11: 2022 | F11: =F10 -> 0.0781 | H11: =H10 -> 0.15 | J11: =J10 -> 4.65
A12: Washington DC | B12: =B11+1 -> 11 | C12: 11 | D12: 2022 | F12: =F11 -> 0.0781 | H12: =H11 -> 0.15 | J12: =J11 -> 4.65
A13: Washington DC | B13: =B12+1 -> 12 | C13: 11 | D13: 2022 | F13: =F12 -> 0.0781 | H13: =H12 -> 0.15 | J13: =J12 -> 4.65
A14: Washington DC | B14: =B13+1 -> 13 | C14: 11 | D14: 2022 | F14: =F13 -> 0.0781 | H14: =H13 -> 0.15 | J14: =J13 -> 4.65
... A30: Washington DC | B30: =B29+1 -> 29 | C30: 11 | D30: 2022 | F30: =F29 -> 0.0781 | H30: =H29 -> 0.15 | J30: =J29 -> 4.65
A31: Washington DC | B31: =B30+1 -> 30 | C31: 11 | D31: 2022 | F31: =F29 -> 0.0781 | H31: =H29 -> 0.15 | J31: =J29 -> 4.65

Sheet December
A1: Site Name | B1: Day | C1: Month | D1: Year | E1: Total Electricity Kwh | F1: Electricity Tariff ($/Kwh) | G1: Natual Gas (m3) | H1: Natural Gas $/m3 | I1: Water Utility Supply (m3) m3 | J1: Water Utility Supply (m3) $/m3 | K1: Room Nights
A2: Washington DC | B2: 1 | C2: 12 | D2: 2022 | F2: =DAILY!D7 -> 0.0781 | H2: 0.15 | J2: 4.65
A3: Washington DC | B3: =B2+1 -> 2 | C3: 12 | D3: 2022 | F3: =F2 -> 0.0781 | H3: =H2 -> 0.15 | J3: =J2 -> 4.65
A4: Washington DC | B4: =B3+1 -> 3 | C4: 12 | D4: 2022 | F4: =F3 -> 0.0781 | H4: =H3 -> 0.15 | J4: =J3 -> 4.65
A5: Washington DC | B5: =B4+1 -> 4 | C5: 12 | D5: 2022 | F5: =F4 -> 0.0781 | H5: =H4 -> 0.15 | J5: =J4 -> 4.65
A6: Washington DC | B6: =B5+1 -> 5 | C6: 12 | D6: 2022 | F6: =F5 -> 0.0781 | H6: =H5 -> 0.15 | J6: =J5 -> 4.65
A7: Washington DC | B7: =B6+1 -> 6 | C7: 12 | D7: 2022 | F7: =F6 -> 0.0781 | H7: =H6 -> 0.15 | J7: =J6 -> 4.65
A8: Washington DC | B8: =B7+1 -> 7 | C8: 12 | D8: 2022 | F8: =F7 -> 0.0781 | H8: =H7 -> 0.15 | J8: =J7 -> 4.65
A9: Washington DC | B9: =B8+1 -> 8 | C9: 12 | D9: 2022 | F9: =F8 -> 0.0781 | H9: =H8 -> 0.15 | J9: =J8 -> 4.65
A10: Washington DC | B10: =B9+1 -> 9 | C10: 12 | D10: 2022 | F10: =F9 -> 0.0781 | H10: =H9 -> 0.15 | J10: =J9 -> 4.65
A11: Washington DC | B11: =B10+1 -> 10 | C11: 12 | D11: 2022 | F11: =F10 -> 0.0781 | H11: =H10 -> 0.15 | J11: =J10 -> 4.65
A12: Washington DC | B12: =B11+1 -> 11 | C12: 12 | D12: 2022 | F12: =F11 -> 0.0781 | H12: =H11 -> 0.15 | J12: =J11 -> 4.65
A13: Washington DC | B13: =B12+1 -> 12 | C13: 12 | D13: 2022 | F13: =F12 -> 0.0781 | H13: =H12 -> 0.15 | J13: =J12 -> 4.65
A14: Washington DC | B14: =B13+1 -> 13 | C14: 12 | D14: 2022 | F14: =F13 -> 0.0781 | H14: =H13 -> 0.15 | J14: =J13 -> 4.65
... A30: Washington DC | B30: =B29+1 -> 29 | C30: 12 | D30: 2022 | F30: =F29 -> 0.0781 | H30: =H29 -> 0.15 | J30: =J29 -> 4.65
A31: Washington DC | B31: 30 | C31: 12 | D31: 2022 | F31: =F30 -> 0.0781 | H31: =H30 -> 0.15 | J31: =J30 -> 4.65
A32: Washington DC | B32: 31 | C32: 12 | D32: 2022 | F32: =F29 -> 0.0781 | H32: =H29 -> 0.15 | J32: =J29 -> 4.65
