Workbook

Sheet TOTAL
A1: Site Name | B1: Day | C1: Month | D1: Year | E1: Total Electricity Kwh | F1: Electricity Tariff ($/Kwh) | G1: LPG (Kg) | H1: LPG $/Kg | I1: Water Utility Supply (m3) m3 | J1: Water Utility Supply (m3) $/m3 | K1: Room Nights
A2: Seychelles at Desroches Island | B2: 1 | C2: 5 | D2: 2022 | E2: =Submetering!E2+Submetering!F2+Submetering!G2+Submetering!H2+Submetering!J2-Submetering!AV2 -> 14820 | F2: 0.5876503 | G2: =(Submetering!AX2+Submetering!AY2+Submetering!AZ2+Submetering!BA2+Submetering!BB2) -> 18.315 | H2: 0.99 | I2: ='FS Desroches Daily'!CM4 -> 109 | J2: 10.487298 | K2: ='FS Desroches Daily'!CN4 -> 0
A3: Seychelles at Desroches Island | B3: 2 | C3: 5 | D3: 2022 | E3: =Submetering!E3+Submetering!F3+Submetering!G3+Submetering!H3+Submetering!J3-Submetering!AV3 -> 14080 | F3: =F2 -> 0.5876503 | G3: =(Submetering!AX3+Submetering!AY3+Submetering!AZ3+Submetering!BA3+Submetering!BB3) -> 20.1465 | H3: =H2 -> 0.99 | I3: ='FS Desroches Daily'!CM5 -> 103.5 | J3: =J2 -> 10.487298 | K3: ='FS Desroches Daily'!CN5 -> 0
A4: Seychelles at Desroches Island | B4: 3 | C4: 5 | D4: 2022 | E4: =Submetering!E4+Submetering!F4+Submetering!G4+Submetering!H4+Submetering!J4-Submetering!AV4 -> 15320 | F4: =F3 -> 0.5876503 | G4: =(Submetering!AX4+Submetering!AY4+Submetering!AZ4+Submetering!BA4+Submetering!BB4) -> 29.304 | H4: =H3 -> 0.99 | I4: ='FS Desroches Daily'!CM6 -> 138.7 | J4: =J3 -> 10.487298 | K4: ='FS Desroches Daily'!CN6 -> 0
A5: Seychelles at Desroches Island | B5: 4 | C5: 5 | D5: 2022 | E5: =Submetering!E5+Submetering!F5+Submetering!G5+Submetering!H5+Submetering!J5-Submetering!AV5 -> 15440 | F5: =F4 -> 0.5876503 | G5: =(Submetering!AX5+Submetering!AY5+Submetering!AZ5+Submetering!BA5+Submetering!BB5) -> 14.652 | H5: =H4 -> 0.99 | I5: ='FS Desroches Daily'!CM7 -> 140.2 | J5: =J4 -> 10.487298 | K5: ='FS Desroches Daily'!CN7 -> 49
A6: Seychelles at Desroches Island | B6: 5 | C6: 5 | D6: 2022 | E6: =Submetering!E6+Submetering!F6+Submetering!G6+Submetering!H6+Submetering!J6-Submetering!AV6 -> 11660 | F6: =F5 -> 0.5876503 | G6: =(Submetering!AX6+Submetering!AY6+Submetering!AZ6+Submetering!BA6+Submetering!BB6) -> 12.8205 | H6: =H5 -> 0.99 | I6: ='FS Desroches Daily'!CM8 -> 152.8 | J6: =J5 -> 10.487298 | K6: ='FS Desroches Daily'!CN8 -> 48
A7: Seychelles at Desroches Island | B7: 6 | C7: 5 | D7: 2022 | E7: =Submetering!E7+Submetering!F7+Submetering!G7+Submetering!H7+Submetering!J7-Submetering!AV7 -> 16850 | F7: =F6 -> 0.5876503 | G7: =(Submetering!AX7+Submetering!AY7+Submetering!AZ7+Submetering!BA7+Submetering!BB7) -> 9.1575 | H7: =H6 -> 0.99 | I7: ='FS Desroches Daily'!CM9 -> 119.5 | J7: =J6 -> 10.487298 | K7: ='FS Desroches Daily'!CN9 -> 50
A8: Seychelles at Desroches Island | B8: 7 | C8: 5 | D8: 2022 | E8: =Submetering!E8+Submetering!F8+Submetering!G8+Submetering!H8+Submetering!J8-Submetering!AV8 -> 15080 | F8: =F7 -> 0.5876503 | G8: =(Submetering!AX8+Submetering!AY8+Submetering!AZ8+Submetering!BA8+Submetering!BB8) -> 29.304 | H8: =H7 -> 0.99 | I8: ='FS Desroches Daily'!CM10 -> 115.5 | J8: =J7 -> 10.487298 | K8: ='FS Desroches Daily'!CN10 -> 46
A9: Seychelles at Desroches Island | B9: 8 | C9: 5 | D9: 2022 | E9: =Submetering!E9+Submetering!F9+Submetering!G9+Submetering!H9+Submetering!J9-Submetering!AV9 -> 14260 | F9: =F8 -> 0.5876503 | G9: =(Submetering!AX9+Submetering!AY9+Submetering!AZ9+Submetering!BA9+Submetering!BB9) -> 25.641 | H9: =H8 -> 0.99 | I9: ='FS Desroches Daily'!CM11 -> 131 | J9: =J8 -> 10.487298 | K9: ='FS Desroches Daily'!CN11 -> 43
A10: Seychelles at Desroches Island | B10: 9 | C10: 5 | D10: 2022 | E10: =Submetering!E10+Submetering!F10+Submetering!G10+Submetering!H10+Submetering!J10-Submetering!AV10 -> 14640 | F10: =F9 -> 0.5876503 | G10: =(Submetering!AX10+Submetering!AY10+Submetering!AZ10+Submetering!BA10+Submetering!BB10) -> 21.978 | H10: =H9 -> 0.99 | I10: ='FS Desroches Daily'!CM12 -> 141.8 | J10: =J9 -> 10.487298 | K10: ='FS Desroches Daily'!CN12 -> 43
A11: Seychelles at Desroches Island | B11: 10 | C11: 5 | D11: 2022 | E11: =Submetering!E11+Submetering!F11+Submetering!G11+Submetering!H11+Submetering!J11-Submetering!AV11 -> 13560 | F11: =F10 -> 0.5876503 | G11: =(Submetering!AX11+Submetering!AY11+Submetering!AZ11+Submetering!BA11+Submetering!BB11) -> 21.978 | H11: =H10 -> 0.99 | I11: ='FS Desroches Daily'!CM13 -> 143.2 | J11: =J10 -> 10.487298 | K11: ='FS Desroches Daily'!CN13 -> 40
A12: Seychelles at Desroches Island | B12: 11 | C12: 5 | D12: 2022 | E12: =Submetering!E12+Submetering!F12+Submetering!G12+Submetering!H12+Submetering!J12-Submetering!AV12 -> 14390 | F12: =F11 -> 0.5876503 | G12: =(Submetering!AX12+Submetering!AY12+Submetering!AZ12+Submetering!BA12+Submetering!BB12) -> 25.641 | H12: =H11 -> 0.99 | I12: ='FS Desroches Daily'!CM14 -> 137.8 | J12: =J11 -> 10.487298 | K12: ='FS Desroches Daily'!CN14 -> 41
A13: Seychelles at Desroches Island | B13: 12 | C13: 5 | D13: 2022 | E13: =Submetering!E13+Submetering!F13+Submetering!G13+Submetering!H13+Submetering!J13-Submetering!AV13 -> 12160 | F13: =F12 -> 0.5876503 | G13: =(Submetering!AX13+Submetering!AY13+Submetering!AZ13+Submetering!BA13+Submetering!BB13) -> 150.183 | H13: =H12 -> 0.99 | I13: ='FS Desroches Daily'!CM15 -> 139 | J13: =J12 -> 10.487298 | K13: ='FS Desroches Daily'!CN15 -> 49
A14: Seychelles at Desroches Island | B14: 13 | C14: 5 | D14: 2022 | E14: =Submetering!E14+Submetering!F14+Submetering!G14+Submetering!H14+Submetering!J14-Submetering!AV14 -> 16200 | F14: =F13 -> 0.5876503 | G14: =(Submetering!AX14+Submetering!AY14+Submetering!AZ14+Submetering!BA14+Submetering!BB14) -> 5.4945 | H14: =H13 -> 0.99 | I14: ='FS Desroches Daily'!CM16 -> 118 | J14: =J13 -> 10.487298 | K14: ='FS Desroches Daily'!CN16 -> 45
... A32: Seychelles at Desroches Island | B32: 31 | C32: 5 | D32: 2022 | E32: =Submetering!E32+Submetering!F32+Submetering!G32+Submetering!H32+Submetering!J32-Submetering!AV32 -> 9800 | F32: =F31 -> 0.5876503 | G32: =(Submetering!AX32+Submetering!AY32+Submetering!AZ32+Submetering!BA32+Submetering!BB32) -> 0 | H32: =H31 -> 0.99 | I32: ='FS Desroches Daily'!CM34 -> 99 | J32: =J31 -> 10.487298 | K32: ='FS Desroches Daily'!CN34 -> 22

Sheet Submetering
A1: Site Name | B1: Day | C1: Month | D1: Year | E1: TRF CQ6 -KWh | F1: TRF FQ7 -KWh | G1: MSB BOH Q8 -KWh | H1: EX MAIN Q3 -KWh | I1: TRF DQ2 -KWh | J1: TRF B Q1 -KWh | K1: CANCAN shop -KWh | L1: CANCAN store -KWh | M1: Laundry EQU P D.B -KWh | N1: Laundry lighting -KWh | O1: PANTRY 1 -KWh | P1: PANTRY 2 -KWh | Q1: SPA LIGHT HOUSE -KWh | R1: PANTRY 3 -KWh | S1: PANTRY 4 -KWh | T1: VMC -KWh | U1: VILLA 100/157 -KWh | V1: VILLA 101/158 -KWh | W1: VILLA 102/159 -KWh | X1: VILLA 103/160 -KWh | Y1: VILLA 104/161 -KWh | Z1: VILLA 105/162 -KWh | AA1: VILLA 106/163 -KWh | AB1: VILLA 107/164 -KWh | AC1: VILLA 108/165 -KWh | AD1: VILLA 109/166 -KWh | AE1: VILLA 110 -KWh | AF1: KUMAR&KUMAR -KWh | AG1: BLOCK 15 -KWh | AH1: BLOCK 16 -KWh | AI1: BLOCK 17 -KWh | AJ1: BLOCK 18 -KWh | AK1: BLOCK 19 -KWh | AL1: BLOCK 20 -KWh | AM1: BLOCK 21 -KWh | AN1: BLOCK 22 -KWh | AO1: BLOCK 23 -KWh | AP1: BLOCK 24 -KWh | AQ1: Exhaust Kitchen (Main) -KWh | AR1: Exhaust Kitchen (Breakfast) -KWh | AS1: Exhaust Lighthouse -KWh | AT1: Exhaust Canteen -KWh | AU1: Cold Store -KWh | AV1: RO Plant -KWh | AW1: Water (m3) | AX1: Main kitchen M1 (9598630) - Kg | AY1: Main kitchen M2 (9598611) -Kg | AZ1: Main kitchen M3 (9249533) -Kg | BA1: Lighthouse -Kg | BB1: Canteen -Kg | BC1: Room Nights
A2: Seychelles at Desroches Island | B2: 1 | C2: 5 | D2: 2022 | E2: ='FS Desroches Daily'!D4 -> 3800 | F2: ='FS Desroches Daily'!F4 -> 3800 | G2: ='FS Desroches Daily'!H4 -> 3900 | H2: ='FS Desroches Daily'!J4 -> 1900 | I2: ='FS Desroches Daily'!L4 -> 3200 | J2: ='FS Desroches Daily'!N4 -> 2400 | K2: ='FS Desroches Daily'!P4 -> 35 | L2: ='FS Desroches Daily'!R4 -> 6 | M2: ='FS Desroches Daily'!T4 -> 1.5 | N2: ='FS Desroches Daily'!V4 -> 543.6 | O2: ='FS Desroches Daily'!X4 -> 380 | P2: ='FS Desroches Daily'!Z4 -> 3300 | Q2: ='FS Desroches Daily'!AB4 -> 510 | R2: ='FS Desroches Daily'!AD4 -> 610 | S2: ='FS Desroches Daily'!AF4 -> 1150 | T2: ='FS Desroches Daily'!AH4 -> 38 | U2: ='FS Desroches Daily'!AJ4 -> 1020 | V2: ='FS Desroches Daily'!AL4 -> 290 | W2: ='FS Desroches Daily'!AN4 -> 300 | X2: ='FS Desroches Daily'!AP4 -> 310 | Y2: ='FS Desroches Daily'!AR4 -> 190 | Z2: ='FS Desroches Daily'!AT4 -> 150 | AA2: ='FS Desroches Daily'!AT4 -> 150 | AB2: ='FS Desroches Daily'!AV4 -> 250 | AC2: ='FS Desroches Daily'!AZ4 -> 180 | AD2: ='FS Desroches Daily'!BB4 -> 240 | AE2: ='FS Desroches Daily'!BD4 -> 160 | AF2: ='FS Desroches Daily'!BF4 -> 22 | AG2: ='FS Desroches Daily'!BH4 -> 40 | AH2: ='FS Desroches Daily'!BJ4 -> 40 | AI2: ='FS Desroches Daily'!BL4 -> 60 | AJ2: ='FS Desroches Daily'!BN4 -> 50 | AK2: ='FS Desroches Daily'!BP4 -> 60 | AL2: ='FS Desroches Daily'!BR4 -> 51 | AM2: ='FS Desroches Daily'!BT4 -> 60 | AN2: ='FS Desroches Daily'!BV4 -> 50 | AO2: ='FS Desroches Daily'!BX4 -> 50 | AP2: ='FS Desroches Daily'!BZ4 -> 52 | AQ2: ='FS Desroches Daily'!CB4 -> 65.6 | AR2: ='FS Desroches Daily'!CD4 -> 13 | AS2: ='FS Desroches Daily'!CF4 -> 8.6 | AT2: ='FS Desroches Daily'!CH4 -> 60.3 | AU2: ='FS Desroches Daily'!CJ4 -> 301 | AV2: ='FS Desroches Daily'!CL4 -> 980 | AW2: ='FS Desroches Daily'!CM4 -> 109 | AX2: =IF(LPG!F9-LPG!F8<0,"0",(LPG!F9-LPG!F8)*1.8315) -> 0 | AY2: =IF(LPG!G9-LPG!G8<0,"0",(LPG!G9-LPG!G8)*1.8315) -> 0 | AZ2: =IF(LPG!H9-LPG!H8<0,"0",(LPG!H9-LPG!H8)*1.8315) -> 5.4945 | BA2: =IF(LPG!M9-LPG!M8<0,"0",(LPG!M9-LPG!M8)*1.8315) -> 5.4945 | BB2: =IF(LPG!Q9-LPG!Q8<0,"0",(LPG!Q9-LPG!Q8)*1.8315) -> 7.326 | BC2: ='FS Desroches Daily'!CN4 -> 0
A3: Seychelles at Desroches Island | B3: 2 | C3: 5 | D3: 2022 | E3: ='FS Desroches Daily'!D5 -> 3700 | F3: ='FS Desroches Daily'!F5 -> 3600 | G3: ='FS Desroches Daily'!H5 -> 3500 | H3: ='FS Desroches Daily'!J5 -> 1900 | I3: ='FS Desroches Daily'!L5 -> 3100 | J3: ='FS Desroches Daily'!N5 -> 2300 | K3: ='FS Desroches Daily'!P5 -> 37 | L3: ='FS Desroches Daily'!R5 -> 7 | M3: ='FS Desroches Daily'!T5 -> 1.5 | N3: ='FS Desroches Daily'!V5 -> 519.4 | O3: ='FS Desroches Daily'!X6 -> 450 | P3: ='FS Desroches Daily'!Z5 -> 3500 | Q3: ='FS Desroches Daily'!AB5 -> 490 | R3: ='FS Desroches Daily'!AD5 -> 630 | S3: ='FS Desroches Daily'!AF5 -> 1110 | T3: ='FS Desroches Daily'!AH5 -> 35 | U3: ='FS Desroches Daily'!AJ5 -> 1010 | V3: ='FS Desroches Daily'!AL5 -> 300 | W3: ='FS Desroches Daily'!AN5 -> 320 | X3: ='FS Desroches Daily'!AP5 -> 290 | Y3: ='FS Desroches Daily'!AR5 -> 210 | Z3: ='FS Desroches Daily'!AT5 -> 210 | AA3: ='FS Desroches Daily'!AT5 -> 210 | AB3: ='FS Desroches Daily'!AV5 -> 260 | AC3: ='FS Desroches Daily'!AZ5 -> 190 | AD3: ='FS Desroches Daily'!BB5 -> 280 | AE3: ='FS Desroches Daily'!BD5 -> 160 | AF3: ='FS Desroches Daily'!BF5 -> 31 | AG3: ='FS Desroches Daily'!BH5 -> 50 | AH3: ='FS Desroches Daily'!BJ5 -> 30 | AI3: ='FS Desroches Daily'!BL5 -> 50 | AJ3: ='FS Desroches Daily'!BN5 -> 50 | AK3: ='FS Desroches Daily'!BP5 -> 70 | AL3: ='FS Desroches Daily'!BR5 -> 50 | AM3: ='FS Desroches Daily'!BT5 -> 70 | AN3: ='FS Desroches Daily'!BV5 -> 52 | AO3: ='FS Desroches Daily'!BX5 -> 50 | AP3: ='FS Desroches Daily'!BZ5 -> 48 | AQ3: ='FS Desroches Daily'!CB5 -> 82.5 | AR3: ='FS Desroches Daily'!CD5 -> 11.4 | AS3: ='FS Desroches Daily'!CF5 -> 1.5 | AT3: ='FS Desroches Daily'!CH5 -> 60 | AU3: ='FS Desroches Daily'!CJ5 -> 323 | AV3: ='FS Desroches Daily'!CL5 -> 920 | AW3: ='FS Desroches Daily'!CM5 -> 103.5 | AX3: =IF(LPG!F10-LPG!F9<0,"0",(LPG!F10-LPG!F9)*1.8315) -> 0 | AY3: =IF(LPG!G10-LPG!G9<0,"0",(LPG!G10-LPG!G9)*1.8315) -> 0 | AZ3: =IF(LPG!H10-LPG!H9<0,"0",(LPG!H10-LPG!H9)*1.8315) -> 9.1575 | BA3: =IF(LPG!M10-LPG!M9<0,"0",(LPG!M10-LPG!M9)*1.8315) -> 3.663 | BB3: =IF(LPG!Q10-LPG!Q9<0,"0",(LPG!Q10-LPG!Q9)*1.8315) -> 7.326 | BC3: ='FS Desroches Daily'!CN5 -> 0
A4: Seychelles at Desroches Island | B4: 3 | C4: 5 | D4: 2022 | E4: ='FS Desroches Daily'!D6 -> 4000 | F4: ='FS Desroches Daily'!F6 -> 4100 | G4: ='FS Desroches Daily'!H6 -> 3800 | H4: ='FS Desroches Daily'!J6 -> 1900 | I4: ='FS Desroches Daily'!L6 -> 3100 | J4: ='FS Desroches Daily'!N6 -> 2500 | K4: ='FS Desroches Daily'!P6 -> 33 | L4: ='FS Desroches Daily'!R6 -> 6 | M4: ='FS Desroches Daily'!T6 -> 1.6 | N4: ='FS Desroches Daily'!V6 -> 554.4 | O4: ='FS Desroches Daily'!X7 -> 460 | P4: ='FS Desroches Daily'!Z6 -> 3600 | Q4: ='FS Desroches Daily'!AB6 -> 510 | R4: ='FS Desroches Daily'!AD6 -> 700 | S4: ='FS Desroches Daily'!AF6 -> 1200 | T4: ='FS Desroches Daily'!AH6 -> 42 | U4: ='FS Desroches Daily'!AJ6 -> 1000 | V4: ='FS Desroches Daily'!AL6 -> 300 | W4: ='FS Desroches Daily'!AN6 -> 320 | X4: ='FS Desroches Daily'!AP6 -> 350 | Y4: ='FS Desroches Daily'!AR6 -> 200 | Z4: ='FS Desroches Daily'!AT6 -> 290 | AA4: ='FS Desroches Daily'!AT6 -> 290 | AB4: ='FS Desroches Daily'!AV6 -> 280 | AC4: ='FS Desroches Daily'!AZ6 -> 180 | AD4: ='FS Desroches Daily'!BB6 -> 310 | AE4: ='FS Desroches Daily'!BD6 -> 160 | AF4: ='FS Desroches Daily'!BF6 -> 43 | AG4: ='FS Desroches Daily'!BH6 -> 50 | AH4: ='FS Desroches Daily'!BJ6 -> 40 | AI4: ='FS Desroches Daily'!BL6 -> 70 | AJ4: ='FS Desroches Daily'!BN6 -> 40 | AK4: ='FS Desroches Daily'!BP6 -> 70 | AL4: ='FS Desroches Daily'!BR6 -> 51 | AM4: ='FS Desroches Daily'!BT6 -> 60 | AN4: ='FS Desroches Daily'!BV6 -> 57 | AO4: ='FS Desroches Daily'!BX6 -> 50 | AP4: ='FS Desroches Daily'!BZ6 -> 53 | AQ4: ='FS Desroches Daily'!CB6 -> 69.1 | AR4: ='FS Desroches Daily'!CD6 -> 13.2 | AS4: ='FS Desroches Daily'!CF6 -> 2.4 | AT4: ='FS Desroches Daily'!CH6 -> 58.4 | AU4: ='FS Desroches Daily'!CJ6 -> 313 | AV4: ='FS Desroches Daily'!CL6 -> 980 | AW4: ='FS Desroches Daily'!CM6 -> 138.7 | AX4: =IF(LPG!F11-LPG!F10<0,"0",(LPG!F11-LPG!F10)*1.8315) -> 0 | AY4: =IF(LPG!G11-LPG!G10<0,"0",(LPG!G11-LPG!G10)*1.8315) -> 0 | AZ4: =IF(LPG!H13-LPG!H10<0,"0",(LPG!H13-LPG!H10)*1.8315) -> 18.315 | BA4: =IF(LPG!M11-LPG!M10<0,"0",(LPG!M11-LPG!M10)*1.8315) -> 5.4945 | BB4: =IF(LPG!Q11-LPG!Q10<0,"0",(LPG!Q11-LPG!Q10)*1.8315) -> 5.4945 | BC4: ='FS Desroches Daily'!CN6 -> 0
A5: Seychelles at Desroches Island | B5: 4 | C5: 5 | D5: 2022 | E5: ='FS Desroches Daily'!D7 -> 4300 | F5: ='FS Desroches Daily'!F7 -> 3900 | G5: ='FS Desroches Daily'!H7 -> 3800 | H5: ='FS Desroches Daily'!J7 -> 1900 | I5: ='FS Desroches Daily'!L7 -> 3200 | J5: ='FS Desroches Daily'!N7 -> 2500 | K5: ='FS Desroches Daily'!P7 -> 33 | L5: ='FS Desroches Daily'!R7 -> 7 | M5: ='FS Desroches Daily'!T7 -> 1.4 | N5: ='FS Desroches Daily'!V7 -> 473.3 | O5: ='FS Desroches Daily'!X8 -> 370 | P5: ='FS Desroches Daily'!Z7 -> 3100 | Q5: ='FS Desroches Daily'!AB7 -> 480 | R5: ='FS Desroches Daily'!AD7 -> 650 | S5: ='FS Desroches Daily'!AF7 -> 1190 | T5: ='FS Desroches Daily'!AH7 -> 36 | U5: ='FS Desroches Daily'!AJ7 -> 1180 | V5: ='FS Desroches Daily'!AL7 -> 310 | W5: ='FS Desroches Daily'!AN7 -> 330 | X5: ='FS Desroches Daily'!AP7 -> 390 | Y5: ='FS Desroches Daily'!AR7 -> 190 | Z5: ='FS Desroches Daily'!AT7 -> 280 | AA5: ='FS Desroches Daily'!AT7 -> 280 | AB5: ='FS Desroches Daily'!AV7 -> 290 | AC5: ='FS Desroches Daily'!AZ7 -> 220 | AD5: ='FS Desroches Daily'!BB7 -> 320 | AE5: ='FS Desroches Daily'!BD7 -> 180 | AF5: ='FS Desroches Daily'!BF7 -> 36 | AG5: ='FS Desroches Daily'!BH7 -> 40 | AH5: ='FS Desroches Daily'!BJ7 -> 40 | AI5: ='FS Desroches Daily'!BL7 -> 60 | AJ5: ='FS Desroches Daily'!BN7 -> 50 | AK5: ='FS Desroches Daily'!BP7 -> 60 | AL5: ='FS Desroches Daily'!BR7 -> 46 | AM5: ='FS Desroches Daily'!BT7 -> 60 | AN5: ='FS Desroches Daily'!BV7 -> 47 | AO5: ='FS Desroches Daily'!BX7 -> 50 | AP5: ='FS Desroches Daily'!BZ7 -> 47 | AQ5: ='FS Desroches Daily'!CB7 -> 68.3 | AR5: ='FS Desroches Daily'!CD7 -> 12.1 | AS5: ='FS Desroches Daily'!CF7 -> 2.6 | AT5: ='FS Desroches Daily'!CH7 -> 58.3 | AU5: ='FS Desroches Daily'!CJ7 -> 317 | AV5: ='FS Desroches Daily'!CL7 -> 960 | AW5: ='FS Desroches Daily'!CM7 -> 140.2 | AX5: =IF(LPG!F12-LPG!F11<0,"0",(LPG!F12-LPG!F11)*1.8315) -> 0 | AY5: =IF(LPG!G12-LPG!G11<0,"0",(LPG!G12-LPG!G11)*1.8315) -> 0 | AZ5: =IF(LPG!H12-LPG!H13<0,"0",(LPG!H12-LPG!H13)*1.8315) -> 0 | BA5: =IF(LPG!M12-LPG!M11<0,"0",(LPG!M12-LPG!M11)*1.8315) -> 5.4945 | BB5: =IF(LPG!Q12-LPG!Q11<0,"0",(LPG!Q12-LPG!Q11)*1.8315) -> 9.1575 | BC5: ='FS Desroches Daily'!CN7 -> 49
A6: Seychelles at Desroches Island | B6: 5 | C6: 5 | D6: 2022 | E6: ='FS Desroches Daily'!D8 -> 3000 | F6: ='FS Desroches Daily'!F8 -> 3000 | G6: ='FS Desroches Daily'!H8 -> 3500 | H6: ='FS Desroches Daily'!J8 -> 1200 | I6: ='FS Desroches Daily'!L8 -> 2800 | J6: ='FS Desroches Daily'!N8 -> 1900 | K6: ='FS Desroches Daily'!P8 -> 38 | L6: ='FS Desroches Daily'!R8 -> 6 | M6: ='FS Desroches Daily'!T8 -> 1.5 | N6: ='FS Desroches Daily'!V8 -> 539 | O6: ='FS Desroches Daily'!X8 -> 370 | P6: ='FS Desroches Daily'!Z8 -> 3100 | Q6: ='FS Desroches Daily'!AB8 -> 500 | R6: ='FS Desroches Daily'!AD8 -> 650 | S6: ='FS Desroches Daily'!AF8 -> 1240 | T6: ='FS Desroches Daily'!AH8 -> 39 | U6: ='FS Desroches Daily'!AJ8 -> 980 | V6: ='FS Desroches Daily'!AL8 -> 290 | W6: ='FS Desroches Daily'!AN8 -> 350 | X6: ='FS Desroches Daily'!AP8 -> 300 | Y6: ='FS Desroches Daily'!AR8 -> 200 | Z6: ='FS Desroches Daily'!AT8 -> 220 | AA6: ='FS Desroches Daily'!AT8 -> 220 | AB6: ='FS Desroches Daily'!AV8 -> 290 | AC6: ='FS Desroches Daily'!AZ8 -> 210 | AD6: ='FS Desroches Daily'!BB8 -> 330 | AE6: ='FS Desroches Daily'!BD8 -> 160 | AF6: ='FS Desroches Daily'!BF8 -> 49 | AG6: ='FS Desroches Daily'!BH8 -> 50 | AH6: ='FS Desroches Daily'!BJ8 -> 40 | AI6: ='FS Desroches Daily'!BL8 -> 50 | AJ6: ='FS Desroches Daily'!BN8 -> 40 | AK6: ='FS Desroches Daily'!BP8 -> 70 | AL6: ='FS Desroches Daily'!BR8 -> 45 | AM6: ='FS Desroches Daily'!BT8 -> 50 | AN6: ='FS Desroches Daily'!BV8 -> 47 | AO6: ='FS Desroches Daily'!BX8 -> 50 | AP6: ='FS Desroches Daily'!BZ8 -> 48 | AQ6: ='FS Desroches Daily'!CB8 -> 65.5 | AR6: ='FS Desroches Daily'!CD8 -> 19 | AS6: ='FS Desroches Daily'!CF8 -> 8.5 | AT6: ='FS Desroches Daily'!CH8 -> 54.2 | AU6: ='FS Desroches Daily'!CJ8 -> 286 | AV6: ='FS Desroches Daily'!CL8 -> 940 | AW6: ='FS Desroches Daily'!CM8 -> 152.8 | AX6: =IF(LPG!F13-LPG!F12<0,"0",(LPG!F13-LPG!F12)*1.8315) -> 0 | AY6: =IF(LPG!G13-LPG!G12<0,"0",(LPG!G13-LPG!G12)*1.8315) -> 0 | AZ6: 0 | BA6: =IF(LPG!M13-LPG!M12<0,"0",(LPG!M13-LPG!M12)*1.8315) -> 7.326 | BB6: =IF(LPG!Q13-LPG!Q12<0,"0",(LPG!Q13-LPG!Q12)*1.8315) -> 5.4945 | BC6: ='FS Desroches Daily'!CN8 -> 48
A7: Seychelles at Desroches Island | B7: 6 | C7: 5 | D7: 2022 | E7: ='FS Desroches Daily'!D9 -> 4800 | F7: ='FS Desroches Daily'!F9 -> 4000 | G7: ='FS Desroches Daily'!H9 -> 3600 | H7: ='FS Desroches Daily'!J9 -> 2500 | I7: ='FS Desroches Daily'!L9 -> 3200 | J7: ='FS Desroches Daily'!N9 -> 2900 | K7: ='FS Desroches Daily'!P9 -> 40 | L7: ='FS Desroches Daily'!R9 -> 6 | M7: ='FS Desroches Daily'!T9 -> 1.4 | N7: ='FS Desroches Daily'!V9 -> 461.3 | O7: ='FS Desroches Daily'!X9 -> 440 | P7: ='FS Desroches Daily'!Z9 -> 3500 | Q7: ='FS Desroches Daily'!AB9 -> 490 | R7: ='FS Desroches Daily'!AD9 -> 680 | S7: ='FS Desroches Daily'!AF9 -> 1230 | T7: ='FS Desroches Daily'!AH9 -> 34 | U7: ='FS Desroches Daily'!AJ9 -> 1060 | V7: ='FS Desroches Daily'!AL9 -> 320 | W7: ='FS Desroches Daily'!AN9 -> 380 | X7: ='FS Desroches Daily'!AP9 -> 240 | Y7: ='FS Desroches Daily'!AR9 -> 220 | Z7: ='FS Desroches Daily'!AT9 -> 300 | AA7: ='FS Desroches Daily'!AT9 -> 300 | AB7: ='FS Desroches Daily'!AV9 -> 270 | AC7: ='FS Desroches Daily'!AZ9 -> 220 | AD7: ='FS Desroches Daily'!BB9 -> 320 | AE7: ='FS Desroches Daily'!BD9 -> 150 | AF7: ='FS Desroches Daily'!BF9 -> 24 | AG7: ='FS Desroches Daily'!BH9 -> 50 | AH7: ='FS Desroches Daily'!BJ9 -> 30 | AI7: ='FS Desroches Daily'!BL9 -> 50 | AJ7: ='FS Desroches Daily'!BN9 -> 50 | AK7: ='FS Desroches Daily'!BP9 -> 60 | AL7: ='FS Desroches Daily'!BR9 -> 53 | AM7: ='FS Desroches Daily'!BT9 -> 50 | AN7: ='FS Desroches Daily'!BV9 -> 50 | AO7: ='FS Desroches Daily'!BX9 -> 50 | AP7: ='FS Desroches Daily'!BZ9 -> 49 | AQ7: ='FS Desroches Daily'!CB9 -> 74.9 | AR7: ='FS Desroches Daily'!CD9 -> 13.7 | AS7: ='FS Desroches Daily'!CF9 -> 2.4 | AT7: ='FS Desroches Daily'!CH9 -> 63.1 | AU7: ='FS Desroches Daily'!CJ9 -> 304 | AV7: ='FS Desroches Daily'!CL9 -> 950 | AW7: ='FS Desroches Daily'!CM9 -> 119.5 | AX7: =IF(LPG!F14-LPG!F13<0,"0",(LPG!F14-LPG!F13)*1.8315) -> 0 | AY7: =IF(LPG!G14-LPG!G13<0,"0",(LPG!G14-LPG!G13)*1.8315) -> 0 | AZ7: 0 | BA7: =IF(LPG!M14-LPG!M13<0,"0",(LPG!M14-LPG!M13)*1.8315) -> 5.4945 | BB7: =IF(LPG!Q14-LPG!Q13<0,"0",(LPG!Q14-LPG!Q13)*1.8315) -> 3.663 | BC7: ='FS Desroches Daily'!CN9 -> 50
A8: Seychelles at Desroches Island | B8: 7 | C8: 5 | D8: 2022 | E8: ='FS Desroches Daily'!D10 -> 3800 | F8: ='FS Desroches Daily'!F10 -> 4000 | G8: ='FS Desroches Daily'!H10 -> 3900 | H8: ='FS Desroches Daily'!J10 -> 1800 | I8: ='FS Desroches Daily'!L10 -> 2700 | J8: ='FS Desroches Daily'!N10 -> 2500 | K8: ='FS Desroches Daily'!P10 -> 41 | L8: ='FS Desroches Daily'!R10 -> 5 | M8: ='FS Desroches Daily'!T10 -> 1.4 | N8: ='FS Desroches Daily'!V10 -> 534.9 | O8: ='FS Desroches Daily'!X10 -> 370 | P8: ='FS Desroches Daily'!Z10 -> 3100 | Q8: ='FS Desroches Daily'!AB10 -> 470 | R8: ='FS Desroches Daily'!AD10 -> 590 | S8: ='FS Desroches Daily'!AF10 -> 1160 | T8: ='FS Desroches Daily'!AH10 -> 34 | U8: ='FS Desroches Daily'!AJ10 -> 950 | V8: ='FS Desroches Daily'!AL10 -> 280 | W8: ='FS Desroches Daily'!AN10 -> 300 | X8: ='FS Desroches Daily'!AP10 -> 270 | Y8: ='FS Desroches Daily'!AR10 -> 180 | Z8: ='FS Desroches Daily'!AT10 -> 390 | AA8: ='FS Desroches Daily'!AT10 -> 390 | AB8: ='FS Desroches Daily'!AV10 -> 270 | AC8: ='FS Desroches Daily'!AZ10 -> 180 | AD8: ='FS Desroches Daily'!BB10 -> 220 | AE8: ='FS Desroches Daily'!BD10 -> 160 | AF8: ='FS Desroches Daily'!BF10 -> 49 | AG8: ='FS Desroches Daily'!BH10 -> 50 | AH8: ='FS Desroches Daily'!BJ10 -> 40 | AI8: ='FS Desroches Daily'!BL10 -> 70 | AJ8: ='FS Desroches Daily'!BN10 -> 40 | AK8: ='FS Desroches Daily'!BP10 -> 70 | AL8: ='FS Desroches Daily'!BR10 -> 47 | AM8: ='FS Desroches Daily'!BT10 -> 60 | AN8: ='FS Desroches Daily'!BV10 -> 47 | AO8: ='FS Desroches Daily'!BX10 -> 50 | AP8: ='FS Desroches Daily'!BZ10 -> 46 | AQ8: ='FS Desroches Daily'!CB10 -> 68.8 | AR8: ='FS Desroches Daily'!CD10 -> 11.4 | AS8: ='FS Desroches Daily'!CF10 -> 3.2 | AT8: ='FS Desroches Daily'!CH10 -> 42.9 | AU8: ='FS Desroches Daily'!CJ10 -> 311 | AV8: ='FS Desroches Daily'!CL10 -> 920 | AW8: ='FS Desroches Daily'!CM10 -> 115.5 | AX8: =IF(LPG!F16-LPG!F14<0,"0",(LPG!F16-LPG!F14)*1.8315) -> 0 | AY8: =IF(LPG!G15-LPG!G14<0,"0",(LPG!G15-LPG!G14)*1.8315) -> 0 | AZ8: =IF(LPG!H16-LPG!H14<0,"0",(LPG!H16-LPG!H14)*1.8315) -> 12.8205 | BA8: =IF(LPG!M16-LPG!M14<0,"0",(LPG!M16-LPG!M14)*1.8315) -> 10.989 | BB8: =IF(LPG!Q15-LPG!Q14<0,"0",(LPG!Q15-LPG!Q14)*1.8315) -> 5.4945 | BC8: ='FS Desroches Daily'!CN10 -> 46
A9: Seychelles at Desroches Island | B9: 8 | C9: 5 | D9: 2022 | E9: ='FS Desroches Daily'!D11 -> 3900 | F9: ='FS Desroches Daily'!F11 -> 3200 | G9: ='FS Desroches Daily'!H11 -> 3800 | H9: ='FS Desroches Daily'!J11 -> 1900 | I9: ='FS Desroches Daily'!L11 -> 2600 | J9: ='FS Desroches Daily'!N11 -> 2500 | K9: ='FS Desroches Daily'!P11 -> 42 | L9: ='FS Desroches Daily'!R11 -> 7 | M9: ='FS Desroches Daily'!T11 -> 1.6 | N9: ='FS Desroches Daily'!V11 -> 457.4 | O9: ='FS Desroches Daily'!X11 -> 380 | P9: ='FS Desroches Daily'!Z11 -> 3100 | Q9: ='FS Desroches Daily'!AB11 -> 500 | R9: ='FS Desroches Daily'!AD11 -> 660 | S9: ='FS Desroches Daily'!AF11 -> 1210 | T9: ='FS Desroches Daily'!AH11 -> 38 | U9: ='FS Desroches Daily'!AJ11 -> 1070 | V9: ='FS Desroches Daily'!AL11 -> 310 | W9: ='FS Desroches Daily'!AN11 -> 320 | X9: ='FS Desroches Daily'!AP11 -> 280 | Y9: ='FS Desroches Daily'!AR11 -> 230 | Z9: ='FS Desroches Daily'!AT11 -> 370 | AA9: ='FS Desroches Daily'!AT11 -> 370 | AB9: ='FS Desroches Daily'!AV11 -> 390 | AC9: ='FS Desroches Daily'!AZ11 -> 220 | AD9: ='FS Desroches Daily'!BB11 -> 190 | AE9: ='FS Desroches Daily'!BD11 -> 170 | AF9: ='FS Desroches Daily'!BF11 -> 39 | AG9: ='FS Desroches Daily'!BH11 -> 40 | AH9: ='FS Desroches Daily'!BJ11 -> 40 | AI9: ='FS Desroches Daily'!BL11 -> 60 | AJ9: ='FS Desroches Daily'!BN11 -> 50 | AK9: ='FS Desroches Daily'!BP11 -> 70 | AL9: ='FS Desroches Daily'!BR11 -> 49 | AM9: ='FS Desroches Daily'!BT11 -> 60 | AN9: ='FS Desroches Daily'!BV11 -> 49 | AO9: ='FS Desroches Daily'!BX11 -> 50 | AP9: ='FS Desroches Daily'!BZ11 -> 53 | AQ9: ='FS Desroches Daily'!CB11 -> 70.5 | AR9: ='FS Desroches Daily'!CD11 -> 11.6 | AS9: ='FS Desroches Daily'!CF11 -> 26 | AT9: ='FS Desroches Daily'!CH11 -> 42.4 | AU9: ='FS Desroches Daily'!CJ11 -> 408 | AV9: ='FS Desroches Daily'!CL11 -> 1040 | AW9: ='FS Desroches Daily'!CM11 -> 131 | AX9: =IF(LPG!F17-LPG!F15<0,"0",(LPG!F17-LPG!F15)*1.8315) -> 0 | AY9: =IF(LPG!G16-LPG!G15<0,"0",(LPG!G16-LPG!G15)*1.8315) -> 0 | AZ9: =IF(LPG!H17-LPG!H15<0,"0",(LPG!H17-LPG!H15)*1.8315) -> 10.989 | BA9: =IF(LPG!M17-LPG!M15<0,"0",(LPG!M17-LPG!M15)*1.8315) -> 7.326 | BB9: =IF(LPG!Q16-LPG!Q15<0,"0",(LPG!Q16-LPG!Q15)*1.8315) -> 7.326 | BC9: ='FS Desroches Daily'!CN11 -> 43
A10: Seychelles at Desroches Island | B10: 9 | C10: 5 | D10: 2022 | E10: ='FS Desroches Daily'!D12 -> 4100 | F10: ='FS Desroches Daily'!F12 -> 3800 | G10: ='FS Desroches Daily'!H12 -> 3600 | H10: ='FS Desroches Daily'!J12 -> 1900 | I10: ='FS Desroches Daily'!L12 -> 2400 | J10: ='FS Desroches Daily'!N12 -> 2200 | K10: ='FS Desroches Daily'!P12 -> 40 | L10: ='FS Desroches Daily'!R12 -> 7 | M10: ='FS Desroches Daily'!T12 -> 1.6 | N10: ='FS Desroches Daily'!V12 -> 678.2 | O10: ='FS Desroches Daily'!X12 -> 410 | P10: ='FS Desroches Daily'!Z12 -> 3400 | Q10: ='FS Desroches Daily'!AB12 -> 470 | R10: ='FS Desroches Daily'!AD12 -> 610 | S10: ='FS Desroches Daily'!AF12 -> 1230 | T10: ='FS Desroches Daily'!AH12 -> 43 | U10: ='FS Desroches Daily'!AJ12 -> 1040 | V10: ='FS Desroches Daily'!AL12 -> 280 | W10: ='FS Desroches Daily'!AN12 -> 360 | X10: ='FS Desroches Daily'!AP12 -> 240 | Y10: ='FS Desroches Daily'!AR12 -> 380 | Z10: ='FS Desroches Daily'!AT12 -> 360 | AA10: ='FS Desroches Daily'!AT12 -> 360 | AB10: ='FS Desroches Daily'!AV12 -> 180 | AC10: ='FS Desroches Daily'!AZ12 -> 180 | AD10: ='FS Desroches Daily'!BB12 -> 210 | AE10: ='FS Desroches Daily'!BD12 -> 160 | AF10: ='FS Desroches Daily'!BF12 -> 36 | AG10: ='FS Desroches Daily'!BH12 -> 50 | AH10: ='FS Desroches Daily'!BJ12 -> 40 | AI10: ='FS Desroches Daily'!BL12 -> 70 | AJ10: ='FS Desroches Daily'!BN12 -> 50 | AK10: ='FS Desroches Daily'!BP12 -> 70 | AL10: ='FS Desroches Daily'!BR12 -> 55 | AM10: ='FS Desroches Daily'!BT12 -> 70 | AN10: ='FS Desroches Daily'!BV12 -> 51 | AO10: ='FS Desroches Daily'!BX12 -> 60 | AP10: ='FS Desroches Daily'!BZ12 -> 56 | AQ10: ='FS Desroches Daily'!CB12 -> 61 | AR10: ='FS Desroches Daily'!CD12 -> 12.9 | AS10: ='FS Desroches Daily'!CF12 -> 4.5 | AT10: ='FS Desroches Daily'!CH12 -> 54.8 | AU10: ='FS Desroches Daily'!CJ12 -> 263 | AV10: ='FS Desroches Daily'!CL12 -> 960 | AW10: ='FS Desroches Daily'!CM12 -> 141.8 | AX10: =IF(LPG!F18-LPG!F16<0,"0",(LPG!F18-LPG!F16)*1.8315) -> 0 | AY10: =IF(LPG!G17-LPG!G16<0,"0",(LPG!G17-LPG!G16)*1.8315) -> 0 | AZ10: =IF(LPG!H18-LPG!H16<0,"0",(LPG!H18-LPG!H16)*1.8315) -> 9.1575 | BA10: =IF(LPG!M18-LPG!M16<0,"0",(LPG!M18-LPG!M16)*1.8315) -> 5.4945 | BB10: =IF(LPG!Q17-LPG!Q16<0,"0",(LPG!Q17-LPG!Q16)*1.8315) -> 7.326 | BC10: ='FS Desroches Daily'!CN12 -> 43
A11: Seychelles at Desroches Island | B11: 10 | C11: 5 | D11: 2022 | E11: ='FS Desroches Daily'!D13 -> 3900 | F11: ='FS Desroches Daily'!F13 -> 3000 | G11: ='FS Desroches Daily'!H13 -> 3600 | H11: ='FS Desroches Daily'!J13 -> 1900 | I11: ='FS Desroches Daily'!L13 -> 2200 | J11: ='FS Desroches Daily'!N13 -> 2100 | K11: ='FS Desroches Daily'!P13 -> 35 | L11: ='FS Desroches Daily'!R13 -> 6 | M11: ='FS Desroches Daily'!T13 -> 1.5 | N11: ='FS Desroches Daily'!V13 -> 587.4 | O11: ='FS Desroches Daily'!X13 -> 340 | P11: ='FS Desroches Daily'!Z13 -> 2900 | Q11: ='FS Desroches Daily'!AB13 -> 280 | R11: ='FS Desroches Daily'!AD13 -> 510 | S11: ='FS Desroches Daily'!AF13 -> 1090 | T11: ='FS Desroches Daily'!AH13 -> 54 | U11: ='FS Desroches Daily'!AJ13 -> 980 | V11: ='FS Desroches Daily'!AL13 -> 280 | W11: ='FS Desroches Daily'!AN13 -> 320 | X11: ='FS Desroches Daily'!AP13 -> 210 | Y11: ='FS Desroches Daily'!AR13 -> 240 | Z11: ='FS Desroches Daily'!AT13 -> 340 | AA11: ='FS Desroches Daily'!AT13 -> 340 | AB11: ='FS Desroches Daily'!AV13 -> 260 | AC11: ='FS Desroches Daily'!AZ13 -> 170 | AD11: ='FS Desroches Daily'!BB13 -> 250 | AE11: ='FS Desroches Daily'!BD13 -> 170 | AF11: ='FS Desroches Daily'!BF13 -> 29 | AG11: ='FS Desroches Daily'!BH13 -> 40 | AH11: ='FS Desroches Daily'!BJ13 -> 40 | AI11: ='FS Desroches Daily'!BL13 -> 60 | AJ11: ='FS Desroches Daily'!BN13 -> 50 | AK11: ='FS Desroches Daily'!BP13 -> 70 | AL11: ='FS Desroches Daily'!BR13 -> 45 | AM11: ='FS Desroches Daily'!BT13 -> 60 | AN11: ='FS Desroches Daily'!BV13 -> 40 | AO11: ='FS Desroches Daily'!BX13 -> 50 | AP11: ='FS Desroches Daily'!BZ13 -> 48 | AQ11: ='FS Desroches Daily'!CB13 -> 62.8 | AR11: ='FS Desroches Daily'!CD13 -> 9 | AS11: ='FS Desroches Daily'!CF13 -> 0.1 | AT11: ='FS Desroches Daily'!CH13 -> 56.4 | AU11: ='FS Desroches Daily'!CJ13 -> 324 | AV11: ='FS Desroches Daily'!CL13 -> 940 | AW11: ='FS Desroches Daily'!CM13 -> 143.2 | AX11: =IF(LPG!F18-LPG!F17<0,"0",(LPG!F18-LPG!F17)*1.8315) -> 0 | AY11: =IF(LPG!G18-LPG!G17<0,"0",(LPG!G18-LPG!G17)*1.8315) -> 0 | AZ11: =IF(LPG!H18-LPG!H17<0,"0",(LPG!H18-LPG!H17)*1.8315) -> 5.4945 | BA11: =IF(LPG!M19-LPG!M17<0,"0",(LPG!M19-LPG!M17)*1.8315) -> 9.1575 | BB11: =IF(LPG!Q18-LPG!Q17<0,"0",(LPG!Q18-LPG!Q17)*1.8315) -> 7.326 | BC11: ='FS Desroches Daily'!CN13 -> 40
A12: Seychelles at Desroches Island | B12: 11 | C12: 5 | D12: 2022 | E12: ='FS Desroches Daily'!D14 -> 4000 | F12: ='FS Desroches Daily'!F14 -> 3600 | G12: ='FS Desroches Daily'!H14 -> 3600 | H12: ='FS Desroches Daily'!J14 -> 1800 | I12: ='FS Desroches Daily'!L14 -> 2100 | J12: ='FS Desroches Daily'!N14 -> 2300 | K12: ='FS Desroches Daily'!P14 -> 41 | L12: ='FS Desroches Daily'!R14 -> 6 | M12: ='FS Desroches Daily'!T14 -> 1.4 | N12: ='FS Desroches Daily'!V14 -> 592.1 | O12: ='FS Desroches Daily'!X14 -> 390 | P12: ='FS Desroches Daily'!Z14 -> 3000 | Q12: ='FS Desroches Daily'!AB14 -> 420 | R12: ='FS Desroches Daily'!AD14 -> 550 | S12: ='FS Desroches Daily'!AF14 -> 1120 | T12: ='FS Desroches Daily'!AH14 -> 62 | U12: ='FS Desroches Daily'!AJ14 -> 1080 | V12: ='FS Desroches Daily'!AL14 -> 350 | W12: ='FS Desroches Daily'!AN14 -> 350 | X12: ='FS Desroches Daily'!AP14 -> 230 | Y12: ='FS Desroches Daily'!AR14 -> 320 | Z12: ='FS Desroches Daily'!AT14 -> 390 | AA12: ='FS Desroches Daily'!AT14 -> 390 | AB12: ='FS Desroches Daily'!AV14 -> 280 | AC12: ='FS Desroches Daily'!AZ14 -> 240 | AD12: ='FS Desroches Daily'!BB14 -> 240 | AE12: ='FS Desroches Daily'!BD14 -> 170 | AF12: ='FS Desroches Daily'!BF14 -> 39 | AG12: ='FS Desroches Daily'!BH14 -> 40 | AH12: ='FS Desroches Daily'!BJ14 -> 30 | AI12: ='FS Desroches Daily'!BL14 -> 60 | AJ12: ='FS Desroches Daily'!BN14 -> 60 | AK12: ='FS Desroches Daily'!BP14 -> 70 | AL12: ='FS Desroches Daily'!BR14 -> 44 | AM12: ='FS Desroches Daily'!BT14 -> 50 | AN12: ='FS Desroches Daily'!BV14 -> 57 | AO12: ='FS Desroches Daily'!BX14 -> 50 | AP12: ='FS Desroches Daily'!BZ14 -> 50 | AQ12: ='FS Desroches Daily'!CB14 -> 60 | AR12: ='FS Desroches Daily'!CD14 -> 8.7 | AS12: ='FS Desroches Daily'!CF14 -> 5.5 | AT12: ='FS Desroches Daily'!CH14 -> 46.9 | AU12: ='FS Desroches Daily'!CJ14 -> 317 | AV12: ='FS Desroches Daily'!CL14 -> 910 | AW12: ='FS Desroches Daily'!CM14 -> 137.8 | AX12: =IF(LPG!F19-LPG!F18<0,"0",(LPG!F19-LPG!F18)*1.8315) -> 0 | AY12: =IF(LPG!G19-LPG!G18<0,"0",(LPG!G19-LPG!G18)*1.8315) -> 0 | AZ12: =IF(LPG!H19-LPG!H18<0,"0",(LPG!H19-LPG!H18)*1.8315) -> 7.326 | BA12: =IF(LPG!M19-LPG!M18<0,"0",(LPG!M19-LPG!M18)*1.8315) -> 3.663 | BB12: =IF(LPG!Q20-LPG!Q18<0,"0",(LPG!Q20-LPG!Q18)*1.8315) -> 14.652 | BC12: ='FS Desroches Daily'!CN14 -> 41
A13: Seychelles at Desroches Island | B13: 12 | C13: 5 | D13: 2022 | E13: ='FS Desroches Daily'!D15 -> 4400 | F13: ='FS Desroches Daily'!F15 -> 900 | G13: ='FS Desroches Daily'!H15 -> 3600 | H13: ='FS Desroches Daily'!J15 -> 1900 | I13: ='FS Desroches Daily'!L15 -> 2200 | J13: ='FS Desroches Daily'!N15 -> 2300 | K13: ='FS Desroches Daily'!P15 -> 42 | L13: ='FS Desroches Daily'!R15 -> 7 | M13: ='FS Desroches Daily'!T15 -> 1.3 | N13: ='FS Desroches Daily'!V15 -> 515.5 | O13: ='FS Desroches Daily'!X15 -> 400 | P13: ='FS Desroches Daily'!Z15 -> 3200 | Q13: ='FS Desroches Daily'!AB15 -> 440 | R13: ='FS Desroches Daily'!AD15 -> 570 | S13: ='FS Desroches Daily'!AF15 -> 1230 | T13: ='FS Desroches Daily'!AH15 -> 44 | U13: ='FS Desroches Daily'!AJ15 -> 1080 | V13: ='FS Desroches Daily'!AL15 -> 260 | W13: ='FS Desroches Daily'!AN15 -> 380 | X13: ='FS Desroches Daily'!AP15 -> 230 | Y13: ='FS Desroches Daily'!AR15 -> 280 | Z13: ='FS Desroches Daily'!AT15 -> 380 | AA13: ='FS Desroches Daily'!AT15 -> 380 | AB13: ='FS Desroches Daily'!AV15 -> 330 | AC13: ='FS Desroches Daily'!AZ15 -> 310 | AD13: ='FS Desroches Daily'!BB15 -> 240 | AE13: ='FS Desroches Daily'!BD15 -> 160 | AF13: ='FS Desroches Daily'!BF15 -> 37 | AG13: ='FS Desroches Daily'!BH15 -> 40 | AH13: ='FS Desroches Daily'!BJ15 -> 50 | AI13: ='FS Desroches Daily'!BL15 -> 80 | AJ13: ='FS Desroches Daily'!BN15 -> 60 | AK13: ='FS Desroches Daily'!BP15 -> 60 | AL13: ='FS Desroches Daily'!BR15 -> 50 | AM13: ='FS Desroches Daily'!BT15 -> 60 | AN13: ='FS Desroches Daily'!BV15 -> 57 | AO13: ='FS Desroches Daily'!BX15 -> 50 | AP13: ='FS Desroches Daily'!BZ15 -> 56 | AQ13: ='FS Desroches Daily'!CB15 -> 54.4 | AR13: ='FS Desroches Daily'!CD15 -> 13.7 | AS13: ='FS Desroches Daily'!CF15 -> 7.7 | AT13: ='FS Desroches Daily'!CH15 -> 49.8 | AU13: ='FS Desroches Daily'!CJ15 -> 325 | AV13: ='FS Desroches Daily'!CL15 -> 940 | AW13: ='FS Desroches Daily'!CM15 -> 139 | AX13: =IF(LPG!F20-LPG!F19<0,"0",(LPG!F20-LPG!F19)*1.8315) -> 0 | AY13: =IF(LPG!G20-LPG!G19<0,"0",(LPG!G20-LPG!G19)*1.8315) -> 137.3625 | AZ13: =IF(LPG!H20-LPG!H19<0,"0",(LPG!H20-LPG!H19)*1.8315) -> 5.4945 | BA13: =IF(LPG!M20-LPG!M19<0,"0",(LPG!M20-LPG!M19)*1.8315) -> 5.4945 | BB13: =IF(LPG!Q20-LPG!Q19<0,"0",(LPG!Q20-LPG!Q19)*1.8315) -> 1.8315 | BC13: ='FS Desroches Daily'!CN15 -> 49
A14: Seychelles at Desroches Island | B14: 13 | C14: 5 | D14: 2022 | E14: ='FS Desroches Daily'!D16 -> 4100 | F14: ='FS Desroches Daily'!F16 -> 5500 | G14: ='FS Desroches Daily'!H16 -> 3600 | H14: ='FS Desroches Daily'!J16 -> 1900 | I14: ='FS Desroches Daily'!L16 -> 2100 | J14: ='FS Desroches Daily'!N16 -> 2300 | K14: ='FS Desroches Daily'!P16 -> 43 | L14: ='FS Desroches Daily'!R16 -> 6 | M14: ='FS Desroches Daily'!T16 -> 1.4 | N14: ='FS Desroches Daily'!V16 -> 544.4 | O14: ='FS Desroches Daily'!X16 -> 370 | P14: ='FS Desroches Daily'!Z16 -> 3000 | Q14: ='FS Desroches Daily'!AB16 -> 440 | R14: ='FS Desroches Daily'!AD16 -> 560 | S14: ='FS Desroches Daily'!AF16 -> 1230 | T14: ='FS Desroches Daily'!AH16 -> 47 | U14: ='FS Desroches Daily'!AJ16 -> 1010 | V14: ='FS Desroches Daily'!AL16 -> 290 | W14: ='FS Desroches Daily'!AN16 -> 370 | X14: ='FS Desroches Daily'!AP16 -> 220 | Y14: ='FS Desroches Daily'!AR16 -> 310 | Z14: ='FS Desroches Daily'!AT16 -> 380 | AA14: ='FS Desroches Daily'!AT16 -> 380 | AB14: ='FS Desroches Daily'!AV16 -> 350 | AC14: ='FS Desroches Daily'!AZ16 -> 270 | AD14: ='FS Desroches Daily'!BB16 -> 630 | AE14: ='FS Desroches Daily'!BD16 -> 160 | AF14: ='FS Desroches Daily'!BF16 -> 40 | AG14: ='FS Desroches Daily'!BH16 -> 50 | AH14: ='FS Desroches Daily'!BJ16 -> 50 | AI14: ='FS Desroches Daily'!BL16 -> 70 | AJ14: ='FS Desroches Daily'!BN16 -> 50 | AK14: ='FS Desroches Daily'!BP16 -> 70 | AL14: ='FS Desroches Daily'!BR16 -> 45 | AM14: ='FS Desroches Daily'!BT16 -> 60 | AN14: ='FS Desroches Daily'!BV16 -> 38 | AO14: ='FS Desroches Daily'!BX16 -> 60 | AP14: ='FS Desroches Daily'!BZ16 -> 55 | AQ14: ='FS Desroches Daily'!CB16 -> 48.4 | AR14: ='FS Desroches Daily'!CD16 -> 12.4 | AS14: ='FS Desroches Daily'!CF16 -> 7.5 | AT14: ='FS Desroches Daily'!CH16 -> 80 | AU14: ='FS Desroches Daily'!CJ16 -> 334 | AV14: ='FS Desroches Daily'!CL16 -> 1200 | AW14: ='FS Desroches Daily'!CM16 -> 118 | AX14: =IF(LPG!F21-LPG!F20<0,"0",(LPG!F21-LPG!F20)*1.8315) -> 0 | AY14: =IF(LPG!G21-LPG!G20<0,"0",(LPG!G21-LPG!G20)*1.8315) -> 0 | AZ14: =IF(LPG!H21-LPG!H20<0,"0",(LPG!H21-LPG!H20)*1.8315) -> 0 | BA14: =IF(LPG!M21-LPG!M20<0,"0",(LPG!M21-LPG!M20)*1.8315) -> 3.663 | BB14: =IF(LPG!Q21-LPG!Q20<0,"0",(LPG!Q21-LPG!Q20)*1.8315) -> 1.8315 | BC14: ='FS Desroches Daily'!CN16 -> 45
A15: Seychelles at Desroches Island | B15: 14 | C15: 5 | D15: 2022 | E15: ='FS Desroches Daily'!D17 -> 4000 | F15: ='FS Desroches Daily'!F17 -> 3000 | G15: ='FS Desroches Daily'!H17 -> 3700 | H15: ='FS Desroches Daily'!J17 -> 2000 | I15: ='FS Desroches Daily'!L17 -> 2100 | J15: ='FS Desroches Daily'!N17 -> 2300 | K15: ='FS Desroches Daily'!P17 -> 41 | L15: ='FS Desroches Daily'!R17 -> 7 | M15: ='FS Desroches Daily'!T17 -> 1.5 | N15: ='FS Desroches Daily'!V17 -> 574.9 | O15: ='FS Desroches Daily'!X17 -> 370 | P15: ='FS Desroches Daily'!Z17 -> 3100 | Q15: ='FS Desroches Daily'!AB17 -> 430 | R15: ='FS Desroches Daily'!AD17 -> 620 | S15: ='FS Desroches Daily'!AF17 -> 1190 | T15: ='FS Desroches Daily'!AH17 -> 42 | U15: ='FS Desroches Daily'!AJ17 -> 970 | V15: ='FS Desroches Daily'!AL17 -> 320 | W15: ='FS Desroches Daily'!AN17 -> 340 | X15: ='FS Desroches Daily'!AP17 -> 220 | Y15: ='FS Desroches Daily'!AR17 -> 436.5 | Z15: ='FS Desroches Daily'!AT17 -> 400 | AA15: ='FS Desroches Daily'!AT17 -> 400 | AB15: ='FS Desroches Daily'!AV17 -> 390 | AC15: ='FS Desroches Daily'!AZ17 -> 290 | AD15: ='FS Desroches Daily'!BB17 -> 40 | AE15: ='FS Desroches Daily'!BD17 -> 170 | AF15: ='FS Desroches Daily'!BF17 -> 28 | AG15: ='FS Desroches Daily'!BH17 -> 60 | AH15: ='FS Desroches Daily'!BJ17 -> 50 | AI15: ='FS Desroches Daily'!BL17 -> 70 | AJ15: ='FS Desroches Daily'!BN17 -> 50 | AK15: ='FS Desroches Daily'!BP17 -> 80 | AL15: ='FS Desroches Daily'!BR17 -> 46 | AM15: ='FS Desroches Daily'!BT17 -> 70 | AN15: ='FS Desroches Daily'!BV17 -> 59 | AO15: ='FS Desroches Daily'!BX17 -> 50 | AP15: ='FS Desroches Daily'!BZ17 -> 60 | AQ15: ='FS Desroches Daily'!CB17 -> 48.3 | AR15: ='FS Desroches Daily'!CD17 -> 15 | AS15: ='FS Desroches Daily'!CF17 -> 4.5 | AT15: ='FS Desroches Daily'!CH17 -> 26.8 | AU15: ='FS Desroches Daily'!CJ17 -> 349 | AV15: ='FS Desroches Daily'!CL17 -> 600 | AW15: ='FS Desroches Daily'!CM17 -> 120 | AX15: =IF(LPG!F22-LPG!F21<0,"0",(LPG!F22-LPG!F21)*1.8315) -> 0 | AY15: =IF(LPG!G22-LPG!G21<0,"0",(LPG!G22-LPG!G21)*1.8315) -> 0 | AZ15: =IF(LPG!H22-LPG!H21<0,"0",(LPG!H22-LPG!H21)*1.8315) -> 14.652 | BA15: =IF(LPG!M22-LPG!M21<0,"0",(LPG!M22-LPG!M21)*1.8315) -> 5.4945 | BB15: =IF(LPG!Q22-LPG!Q21<0,"0",(LPG!Q22-LPG!Q21)*1.8315) -> 7.326 | BC15: ='FS Desroches Daily'!CN17 -> 45
A16: Seychelles at Desroches Island | B16: 15 | C16: 5 | D16: 2022 | E16: ='FS Desroches Daily'!D18 -> 4000 | F16: ='FS Desroches Daily'!F18 -> 4000 | G16: ='FS Desroches Daily'!H18 -> 3800 | H16: ='FS Desroches Daily'!J18 -> 1800 | I16: ='FS Desroches Daily'!L18 -> 2100 | J16: ='FS Desroches Daily'!N18 -> 2300 | K16: ='FS Desroches Daily'!P18 -> 40 | L16: ='FS Desroches Daily'!R18 -> 6 | M16: ='FS Desroches Daily'!T18 -> 1.8 | N16: ='FS Desroches Daily'!V18 -> 662.3 | O16: ='FS Desroches Daily'!X18 -> 420 | P16: ='FS Desroches Daily'!Z18 -> 3100 | Q16: ='FS Desroches Daily'!AB18 -> 450 | R16: ='FS Desroches Daily'!AD18 -> 630 | S16: ='FS Desroches Daily'!AF18 -> 1160 | T16: ='FS Desroches Daily'!AH18 -> 48 | U16: ='FS Desroches Daily'!AJ18 -> 850 | V16: ='FS Desroches Daily'!AL18 -> 260 | W16: ='FS Desroches Daily'!AN18 -> 230 | X16: ='FS Desroches Daily'!AP18 -> 240 | Y16: ='FS Desroches Daily'!AR18 -> 300 | Z16: ='FS Desroches Daily'!AT18 -> 360 | AA16: ='FS Desroches Daily'!AT18 -> 360 | AB16: ='FS Desroches Daily'!AV18 -> 380 | AC16: ='FS Desroches Daily'!AZ18 -> 300 | AD16: ='FS Desroches Daily'!BB18 -> 50 | AE16: ='FS Desroches Daily'!BD18 -> 180 | AF16: ='FS Desroches Daily'!BF18 -> 57 | AG16: ='FS Desroches Daily'!BH18 -> 50 | AH16: ='FS Desroches Daily'!BJ18 -> 30 | AI16: ='FS Desroches Daily'!BL18 -> 80 | AJ16: ='FS Desroches Daily'!BN18 -> 50 | AK16: ='FS Desroches Daily'!BP18 -> 70 | AL16: ='FS Desroches Daily'!BR18 -> 46 | AM16: ='FS Desroches Daily'!BT18 -> 50 | AN16: ='FS Desroches Daily'!BV18 -> 50 | AO16: ='FS Desroches Daily'!BX18 -> 60 | AP16: ='FS Desroches Daily'!BZ18 -> 56 | AQ16: ='FS Desroches Daily'!CB18 -> 43.1 | AR16: ='FS Desroches Daily'!CD18 -> 11.3 | AS16: ='FS Desroches Daily'!CF18 -> 1.8 | AT16: ='FS Desroches Daily'!CH18 -> 47.3 | AU16: ='FS Desroches Daily'!CJ18 -> 332 | AV16: ='FS Desroches Daily'!CL18 -> 1120 | AW16: ='FS Desroches Daily'!CM18 -> 124 | AX16: =IF(LPG!F23-LPG!F22<0,"0",(LPG!F23-LPG!F22)*1.8315) -> 0 | AY16: =IF(LPG!G23-LPG!G22<0,"0",(LPG!G23-LPG!G22)*1.8315) -> 0 | AZ16: =IF(LPG!H23-LPG!H22<0,"0",(LPG!H23-LPG!H22)*1.8315) -> 5.4945 | BA16: =IF(LPG!M23-LPG!M22<0,"0",(LPG!M23-LPG!M22)*1.8315) -> 3.663 | BB16: =IF(LPG!Q23-LPG!Q22<0,"0",(LPG!Q23-LPG!Q22)*1.8315) -> 7.326 | BC16: ='FS Desroches Daily'!CN18 -> 40
A17: Seychelles at Desroches Island | B17: 16 | C17: 5 | D17: 2022 | E17: ='FS Desroches Daily'!D19 -> 3600 | F17: ='FS Desroches Daily'!F19 -> 4000 | G17: ='FS Desroches Daily'!H19 -> 3500 | H17: ='FS Desroches Daily'!J19 -> 1900 | I17: ='FS Desroches Daily'!L19 -> 2000 | J17: ='FS Desroches Daily'!N19 -> 2100 | K17: ='FS Desroches Daily'!P19 -> 33 | L17: ='FS Desroches Daily'!R19 -> 5 | M17: ='FS Desroches Daily'!T19 -> 1.2 | N17: ='FS Desroches Daily'!V19 -> 440.1 | O17: ='FS Desroches Daily'!X19 -> 320 | P17: ='FS Desroches Daily'!Z19 -> 3000 | Q17: ='FS Desroches Daily'!AB19 -> 420 | R17: ='FS Desroches Daily'!AD19 -> 520 | S17: ='FS Desroches Daily'!AF19 -> 1010 | T17: ='FS Desroches Daily'!AH19 -> 37 | U17: ='FS Desroches Daily'!AJ19 -> 780 | V17: ='FS Desroches Daily'!AL19 -> 230 | W17: ='FS Desroches Daily'!AN19 -> 220 | X17: ='FS Desroches Daily'!AP19 -> 200 | Y17: ='FS Desroches Daily'!AR19 -> 250 | Z17: ='FS Desroches Daily'!AU20 -> 346.72 | AA17: ='FS Desroches Daily'!AU20 -> 346.72 | AB17: ='FS Desroches Daily'!AV19 -> 340 | AC17: ='FS Desroches Daily'!AZ19 -> 230 | AD17: ='FS Desroches Daily'!BB19 -> 230 | AE17: ='FS Desroches Daily'!BD19 -> 100 | AF17: ='FS Desroches Daily'!BF19 -> 21 | AG17: ='FS Desroches Daily'!BH19 -> 40 | AH17: ='FS Desroches Daily'!BJ19 -> 30 | AI17: ='FS Desroches Daily'!BL19 -> 60 | AJ17: ='FS Desroches Daily'!BN19 -> 50 | AK17: ='FS Desroches Daily'!BP19 -> 70 | AL17: ='FS Desroches Daily'!BR19 -> 46 | AM17: ='FS Desroches Daily'!BT19 -> 50 | AN17: ='FS Desroches Daily'!BV19 -> 51 | AO17: ='FS Desroches Daily'!BX19 -> 50 | AP17: ='FS Desroches Daily'!BZ19 -> 49 | AQ17: ='FS Desroches Daily'!CB19 -> 50.4 | AR17: ='FS Desroches Daily'!CD19 -> 10 | AS17: ='FS Desroches Daily'!CF19 -> 5.1 | AT17: ='FS Desroches Daily'!CH19 -> 39.4 | AU17: ='FS Desroches Daily'!CJ19 -> 332 | AV17: ='FS Desroches Daily'!CL19 -> 890 | AW17: ='FS Desroches Daily'!CM19 -> 122 | AX17: =IF(LPG!F24-LPG!F23<0,"0",(LPG!F24-LPG!F23)*1.8315) -> 0 | AY17: =IF(LPG!G24-LPG!G23<0,"0",(LPG!G24-LPG!G23)*1.8315) -> 0 | AZ17: =IF(LPG!H24-LPG!H23<0,"0",(LPG!H24-LPG!H23)*1.8315) -> 5.4945 | BA17: =IF(LPG!M24-LPG!M23<0,"0",(LPG!M24-LPG!M23)*1.8315) -> 0 | BB17: =IF(LPG!Q24-LPG!Q23<0,"0",(LPG!Q24-LPG!Q23)*1.8315) -> 5.4945 | BC17: ='FS Desroches Daily'!CN19 -> 37
A18: Seychelles at Desroches Island | B18: 17 | C18: 5 | D18: 2022 | E18: ='FS Desroches Daily'!D20 -> 2700 | F18: ='FS Desroches Daily'!F20 -> 2700 | G18: ='FS Desroches Daily'!H20 -> 3500 | H18: ='FS Desroches Daily'!J20 -> 1500 | I18: ='FS Desroches Daily'!L20 -> 2000 | J18: ='FS Desroches Daily'!N20 -> 1600 | K18: ='FS Desroches Daily'!P20 -> 18 | L18: ='FS Desroches Daily'!R20 -> 3 | M18: ='FS Desroches Daily'!T20 -> 1.2 | N18: ='FS Desroches Daily'!V20 -> 421.6 | O18: ='FS Desroches Daily'!X20 -> 300 | P18: ='FS Desroches Daily'!Z20 -> 2900 | Q18: ='FS Desroches Daily'!AB20 -> 220 | R18: ='FS Desroches Daily'!AD20 -> 440 | S18: ='FS Desroches Daily'!AF20 -> 860 | T18: ='FS Desroches Daily'!AH20 -> 30 | U18: ='FS Desroches Daily'!AJ20 -> 660 | V18: ='FS Desroches Daily'!AL20 -> 190 | W18: ='FS Desroches Daily'!AN20 -> 190 | X18: ='FS Desroches Daily'!AP20 -> 180 | Y18: ='FS Desroches Daily'!AR20 -> 240 | Z18: ='FS Desroches Daily'!AT20 -> 300 | AA18: ='FS Desroches Daily'!AT20 -> 300 | AB18: ='FS Desroches Daily'!AV20 -> 260 | AC18: ='FS Desroches Daily'!AZ20 -> 160 | AD18: ='FS Desroches Daily'!BB20 -> 150 | AE18: ='FS Desroches Daily'!BD20 -> 50 | AF18: ='FS Desroches Daily'!BF20 -> 36 | AG18: ='FS Desroches Daily'!BH20 -> 40 | AH18: ='FS Desroches Daily'!BJ20 -> 30 | AI18: ='FS Desroches Daily'!BL20 -> 60 | AJ18: ='FS Desroches Daily'!BN20 -> 50 | AK18: ='FS Desroches Daily'!BP20 -> 50 | AL18: ='FS Desroches Daily'!BR20 -> 38 | AM18: ='FS Desroches Daily'!BT20 -> 40 | AN18: ='FS Desroches Daily'!BV20 -> 43 | AO18: ='FS Desroches Daily'!BX20 -> 30 | AP18: ='FS Desroches Daily'!BZ20 -> 39 | AQ18: ='FS Desroches Daily'!CB20 -> 50.3 | AR18: ='FS Desroches Daily'!CD20 -> 10.6 | AS18: ='FS Desroches Daily'!CF20 -> 2.6 | AT18: ='FS Desroches Daily'!CH20 -> 49.1 | AU18: ='FS Desroches Daily'!CJ20 -> 280 | AV18: ='FS Desroches Daily'!CL20 -> 950 | AW18: ='FS Desroches Daily'!CM20 -> 96 | AX18: =IF(LPG!F25-LPG!F24<0,"0",(LPG!F25-LPG!F24)*1.8315) -> 0 | AY18: =IF(LPG!G25-LPG!G24<0,"0",(LPG!G25-LPG!G24)*1.8315) -> 0 | AZ18: =IF(LPG!H25-LPG!H24<0,"0",(LPG!H25-LPG!H24)*1.8315) -> 5.4945 | BA18: =IF(LPG!M25-LPG!M24<0,"0",(LPG!M25-LPG!M24)*1.8315) -> 1.8315 | BB18: =IF(LPG!Q25-LPG!Q24<0,"0",(LPG!Q25-LPG!Q24)*1.8315) -> 7.326 | BC18: ='FS Desroches Daily'!CN20 -> 38
A19: Seychelles at Desroches Island | B19: 18 | C19: 5 | D19: 2022 | E19: ='FS Desroches Daily'!D21 -> 3400 | F19: ='FS Desroches Daily'!F21 -> 3300 | G19: ='FS Desroches Daily'!H21 -> 3300 | H19: ='FS Desroches Daily'!J21 -> 1800 | I19: ='FS Desroches Daily'!L21 -> 2100 | J19: ='FS Desroches Daily'!N21 -> 2200 | K19: ='FS Desroches Daily'!P21 -> 29 | L19: ='FS Desroches Daily'!R21 -> 6 | M19: ='FS Desroches Daily'!T21 -> 1.2 | N19: ='FS Desroches Daily'!V21 -> 464.6 | O19: ='FS Desroches Daily'!X21 -> 340 | P19: ='FS Desroches Daily'!Z21 -> 2900 | Q19: ='FS Desroches Daily'!AB21 -> 400 | R19: ='FS Desroches Daily'!AD21 -> 540 | S19: ='FS Desroches Daily'!AF21 -> 1060 | T19: ='FS Desroches Daily'!AH21 -> 35 | U19: ='FS Desroches Daily'!AJ21 -> 770 | V19: ='FS Desroches Daily'!AL21 -> 250 | W19: ='FS Desroches Daily'!AN21 -> 340 | X19: ='FS Desroches Daily'!AP21 -> 240 | Y19: ='FS Desroches Daily'!AR21 -> 330 | Z19: ='FS Desroches Daily'!AT21 -> 350 | AA19: ='FS Desroches Daily'!AT21 -> 350 | AB19: ='FS Desroches Daily'!AV21 -> 350 | AC19: ='FS Desroches Daily'!AZ21 -> 180 | AD19: ='FS Desroches Daily'!BB21 -> 200 | AE19: ='FS Desroches Daily'!BD21 -> 70 | AF19: ='FS Desroches Daily'!BF21 -> 27 | AG19: ='FS Desroches Daily'!BH21 -> 50 | AH19: ='FS Desroches Daily'!BJ21 -> 40 | AI19: ='FS Desroches Daily'!BL21 -> 70 | AJ19: ='FS Desroches Daily'!BN21 -> 60 | AK19: ='FS Desroches Daily'!BP21 -> 70 | AL19: ='FS Desroches Daily'!BR21 -> 43 | AM19: ='FS Desroches Daily'!BT21 -> 50 | AN19: ='FS Desroches Daily'!BV21 -> 53 | AO19: ='FS Desroches Daily'!BX21 -> 50 | AP19: ='FS Desroches Daily'!BZ21 -> 48 | AQ19: ='FS Desroches Daily'!CB21 -> 47 | AR19: ='FS Desroches Daily'!CD21 -> 9.7 | AS19: ='FS Desroches Daily'!CF21 -> 5.7 | AT19: ='FS Desroches Daily'!CH21 -> 47.1 | AU19: ='FS Desroches Daily'!CJ21 -> 295 | AV19: ='FS Desroches Daily'!CL21 -> 910 | AW19: ='FS Desroches Daily'!CM21 -> 92 | AX19: =IF(LPG!F26-LPG!F25<0,"0",(LPG!F26-LPG!F25)*1.8315) -> 0 | AY19: =IF(LPG!G26-LPG!G25<0,"0",(LPG!G26-LPG!G25)*1.8315) -> 0 | AZ19: =IF(LPG!H26-LPG!H25<0,"0",(LPG!H26-LPG!H25)*1.8315) -> 3.663 | BA19: =IF(LPG!M26-LPG!M25<0,"0",(LPG!M26-LPG!M25)*1.8315) -> 3.663 | BB19: =IF(LPG!Q26-LPG!Q25<0,"0",(LPG!Q26-LPG!Q25)*1.8315) -> 3.663 | BC19: ='FS Desroches Daily'!CN21 -> 40
A20: Seychelles at Desroches Island | B20: 19 | C20: 5 | D20: 2022 | E20: ='FS Desroches Daily'!D22 -> 3300 | F20: ='FS Desroches Daily'!F22 -> 3000 | G20: ='FS Desroches Daily'!H22 -> 3700 | H20: ='FS Desroches Daily'!J22 -> 1700 | I20: ='FS Desroches Daily'!L22 -> 2100 | J20: ='FS Desroches Daily'!N22 -> 2000 | K20: ='FS Desroches Daily'!P22 -> 30 | L20: ='FS Desroches Daily'!R22 -> 5 | M20: ='FS Desroches Daily'!T22 -> 1.6 | N20: ='FS Desroches Daily'!V22 -> 636.4 | O20: ='FS Desroches Daily'!X22 -> 360 | P20: ='FS Desroches Daily'!Z22 -> 2800 | Q20: ='FS Desroches Daily'!AB22 -> 450 | R20: ='FS Desroches Daily'!AD22 -> 420 | S20: ='FS Desroches Daily'!AF22 -> 1050 | T20: ='FS Desroches Daily'!AH22 -> 32 | U20: ='FS Desroches Daily'!AJ22 -> 730 | V20: ='FS Desroches Daily'!AL22 -> 290 | W20: ='FS Desroches Daily'!AN22 -> 270 | X20: ='FS Desroches Daily'!AP22 -> 190 | Y20: ='FS Desroches Daily'!AR22 -> 180 | Z20: ='FS Desroches Daily'!AT22 -> 380 | AA20: ='FS Desroches Daily'!AT22 -> 380 | AB20: ='FS Desroches Daily'!AV22 -> 350 | AC20: ='FS Desroches Daily'!AZ22 -> 150 | AD20: ='FS Desroches Daily'!BB22 -> 160 | AE20: ='FS Desroches Daily'!BD22 -> 60 | AF20: ='FS Desroches Daily'!BF22 -> 34 | AG20: ='FS Desroches Daily'!BH22 -> 40 | AH20: ='FS Desroches Daily'!BJ22 -> 30 | AI20: ='FS Desroches Daily'!BL22 -> 60 | AJ20: ='FS Desroches Daily'!BN22 -> 50 | AK20: ='FS Desroches Daily'!BP22 -> 70 | AL20: ='FS Desroches Daily'!BR22 -> 40 | AM20: ='FS Desroches Daily'!BT22 -> 50 | AN20: ='FS Desroches Daily'!BV22 -> 43 | AO20: ='FS Desroches Daily'!BX22 -> 50 | AP20: ='FS Desroches Daily'!BZ22 -> 42 | AQ20: ='FS Desroches Daily'!CB22 -> 36.3 | AR20: ='FS Desroches Daily'!CD22 -> 8.6 | AS20: ='FS Desroches Daily'!CF22 -> 4.7 | AT20: ='FS Desroches Daily'!CH22 -> 35.5 | AU20: ='FS Desroches Daily'!CJ22 -> 269 | AV20: ='FS Desroches Daily'!CL22 -> 820 | AW20: ='FS Desroches Daily'!CM22 -> 98 | AX20: =IF(LPG!F27-LPG!F26<0,"0",(LPG!F27-LPG!F26)*1.8315) -> 0 | AY20: =IF(LPG!G27-LPG!G26<0,"0",(LPG!G27-LPG!G26)*1.8315) -> 0 | AZ20: =IF(LPG!H27-LPG!H26<0,"0",(LPG!H27-LPG!H26)*1.8315) -> 5.4945 | BA20: =IF(LPG!M27-LPG!M26<0,"0",(LPG!M27-LPG!M26)*1.8315) -> 3.663 | BB20: =IF(LPG!Q27-LPG!Q26<0,"0",(LPG!Q27-LPG!Q26)*1.8315) -> 16.4835 | BC20: ='FS Desroches Daily'!CN22 -> 27
A21: Seychelles at Desroches Island | B21: 20 | C21: 5 | D21: 2022 | E21: ='FS Desroches Daily'!D23 -> 3200 | F21: ='FS Desroches Daily'!F23 -> 3500 | G21: ='FS Desroches Daily'!H23 -> 3200 | H21: ='FS Desroches Daily'!J23 -> 1700 | I21: ='FS Desroches Daily'!L23 -> 2000 | J21: ='FS Desroches Daily'!N23 -> 1900 | K21: ='FS Desroches Daily'!P23 -> 27 | L21: ='FS Desroches Daily'!R23 -> 4 | M21: ='FS Desroches Daily'!T23 -> 1.3 | N21: ='FS Desroches Daily'!V23 -> 560.8 | O21: ='FS Desroches Daily'!X23 -> 330 | P21: ='FS Desroches Daily'!Z23 -> 2800 | Q21: ='FS Desroches Daily'!AB23 -> 420 | R21: ='FS Desroches Daily'!AD23 -> 370 | S21: ='FS Desroches Daily'!AF23 -> 950 | T21: ='FS Desroches Daily'!AH23 -> 36 | U21: ='FS Desroches Daily'!AJ23 -> 880 | V21: ='FS Desroches Daily'!AL23 -> 280 | W21: ='FS Desroches Daily'!AN23 -> 250 | X21: ='FS Desroches Daily'!AP23 -> 200 | Y21: ='FS Desroches Daily'!AR23 -> 170 | Z21: ='FS Desroches Daily'!AT23 -> 280 | AA21: ='FS Desroches Daily'!AT23 -> 280 | AB21: ='FS Desroches Daily'!AV23 -> 340 | AC21: ='FS Desroches Daily'!AZ23 -> 160 | AD21: ='FS Desroches Daily'!BB23 -> 150 | AE21: ='FS Desroches Daily'!BD23 -> 120 | AF21: ='FS Desroches Daily'!BF23 -> 32 | AG21: ='FS Desroches Daily'!BH23 -> 40 | AH21: ='FS Desroches Daily'!BJ23 -> 40 | AI21: ='FS Desroches Daily'!BL23 -> 70 | AJ21: ='FS Desroches Daily'!BN23 -> 40 | AK21: ='FS Desroches Daily'!BP23 -> 70 | AL21: ='FS Desroches Daily'!BR23 -> 44 | AM21: ='FS Desroches Daily'!BT23 -> 60 | AN21: ='FS Desroches Daily'!BV23 -> 47 | AO21: ='FS Desroches Daily'!BX23 -> 50 | AP21: ='FS Desroches Daily'!BZ23 -> 45 | AQ21: ='FS Desroches Daily'!CB23 -> 41.7 | AR21: ='FS Desroches Daily'!CD23 -> 11.4 | AS21: ='FS Desroches Daily'!CF23 -> 2 | AT21: ='FS Desroches Daily'!CH23 -> 55.7 | AU21: ='FS Desroches Daily'!CJ23 -> 318 | AV21: ='FS Desroches Daily'!CL23 -> 760 | AW21: ='FS Desroches Daily'!CM23 -> 99 | AX21: =IF(LPG!F28-LPG!F27<0,"0",(LPG!F28-LPG!F27)*1.8315) -> 0 | AY21: =IF(LPG!G28-LPG!G27<0,"0",(LPG!G28-LPG!G27)*1.8315) -> 0 | AZ21: =IF(LPG!H28-LPG!H27<0,"0",(LPG!H28-LPG!H27)*1.8315) -> 7.326 | BA21: =IF(LPG!M28-LPG!M27<0,"0",(LPG!M28-LPG!M27)*1.8315) -> 0 | BB21: =IF(LPG!Q28-LPG!Q27<0,"0",(LPG!Q28-LPG!Q27)*1.8315) -> 0 | BC21: ='FS Desroches Daily'!CN23 -> 27
A22: Seychelles at Desroches Island | B22: 21 | C22: 5 | D22: 2022 | E22: ='FS Desroches Daily'!D24 -> 2900 | F22: ='FS Desroches Daily'!F24 -> 3100 | G22: ='FS Desroches Daily'!H24 -> 3200 | H22: ='FS Desroches Daily'!J24 -> 1700 | I22: ='FS Desroches Daily'!L24 -> 2200 | J22: ='FS Desroches Daily'!N24 -> 1700 | K22: ='FS Desroches Daily'!P24 -> 25 | L22: ='FS Desroches Daily'!R24 -> 5 | M22: ='FS Desroches Daily'!T24 -> 1.1 | N22: ='FS Desroches Daily'!V24 -> 465.5 | O22: ='FS Desroches Daily'!X24 -> 350 | P22: ='FS Desroches Daily'!Z24 -> 3000 | Q22: ='FS Desroches Daily'!AB24 -> 270 | R22: ='FS Desroches Daily'!AD24 -> 440 | S22: ='FS Desroches Daily'!AF24 -> 990 | T22: ='FS Desroches Daily'!AH24 -> 30 | U22: ='FS Desroches Daily'!AJ24 -> 880 | V22: ='FS Desroches Daily'!AL24 -> 310 | W22: ='FS Desroches Daily'!AN24 -> 260 | X22: ='FS Desroches Daily'!AP24 -> 190 | Y22: ='FS Desroches Daily'!AR24 -> 180 | Z22: ='FS Desroches Daily'!AT24 -> 140 | AA22: ='FS Desroches Daily'!AT24 -> 140 | AB22: ='FS Desroches Daily'!AV24 -> 140 | AC22: ='FS Desroches Daily'!AZ24 -> 150 | AD22: ='FS Desroches Daily'!BB24 -> 140 | AE22: ='FS Desroches Daily'!BD24 -> 120 | AF22: ='FS Desroches Daily'!BF24 -> 42 | AG22: ='FS Desroches Daily'!BH24 -> 50 | AH22: ='FS Desroches Daily'!BJ24 -> 40 | AI22: ='FS Desroches Daily'!BL24 -> 60 | AJ22: ='FS Desroches Daily'!BN24 -> 50 | AK22: ='FS Desroches Daily'!BP24 -> 70 | AL22: ='FS Desroches Daily'!BR24 -> 39 | AM22: ='FS Desroches Daily'!BT24 -> 50 | AN22: ='FS Desroches Daily'!BV24 -> 43 | AO22: ='FS Desroches Daily'!BX24 -> 40 | AP22: ='FS Desroches Daily'!BZ24 -> 48 | AQ22: ='FS Desroches Daily'!CB24 -> 46.5 | AR22: ='FS Desroches Daily'!CD24 -> 11.6 | AS22: ='FS Desroches Daily'!CF24 -> 4 | AT22: ='FS Desroches Daily'!CH24 -> 45.5 | AU22: ='FS Desroches Daily'!CJ24 -> 289 | AV22: ='FS Desroches Daily'!CL24 -> 850 | AW22: ='FS Desroches Daily'!CM24 -> 96.3 | AX22: =IF(LPG!F29-LPG!F28<0,"0",(LPG!F29-LPG!F28)*1.8315) -> 0 | AY22: =IF(LPG!G29-LPG!G28<0,"0",(LPG!G29-LPG!G28)*1.8315) -> 0 | AZ22: =IF(LPG!H29-LPG!H28<0,"0",(LPG!H29-LPG!H28)*1.8315) -> 5.4945 | BA22: =IF(LPG!M29-LPG!M28<0,"0",(LPG!M29-LPG!M28)*1.8315) -> 5.4945 | BB22: =IF(LPG!Q29-LPG!Q28<0,"0",(LPG!Q29-LPG!Q28)*1.8315) -> 9.1575 | BC22: ='FS Desroches Daily'!CN24 -> 27
A23: Seychelles at Desroches Island | B23: 22 | C23: 5 | D23: 2022 | E23: ='FS Desroches Daily'!D25 -> 2300 | F23: ='FS Desroches Daily'!F25 -> 3000 | G23: ='FS Desroches Daily'!H25 -> 3000 | H23: ='FS Desroches Daily'!J25 -> 1600 | I23: ='FS Desroches Daily'!L25 -> 2000 | J23: ='FS Desroches Daily'!N25 -> 1900 | K23: ='FS Desroches Daily'!P25 -> 44 | L23: ='FS Desroches Daily'!R25 -> 4 | M23: ='FS Desroches Daily'!T25 -> 1.2 | N23: ='FS Desroches Daily'!V25 -> 418.9 | O23: ='FS Desroches Daily'!X25 -> 310 | P23: ='FS Desroches Daily'!Z25 -> 2800 | Q23: ='FS Desroches Daily'!AB25 -> 420 | R23: ='FS Desroches Daily'!AD25 -> 440 | S23: ='FS Desroches Daily'!AF25 -> 1060 | T23: ='FS Desroches Daily'!AH25 -> 27 | U23: ='FS Desroches Daily'!AJ25 -> 800 | V23: ='FS Desroches Daily'!AL25 -> 280 | W23: ='FS Desroches Daily'!AN25 -> 230 | X23: ='FS Desroches Daily'!AP25 -> 160 | Y23: ='FS Desroches Daily'!AR25 -> 140 | Z23: ='FS Desroches Daily'!AT25 -> 90 | AA23: ='FS Desroches Daily'!AT25 -> 90 | AB23: ='FS Desroches Daily'!AV25 -> 50 | AC23: ='FS Desroches Daily'!AZ25 -> 140 | AD23: ='FS Desroches Daily'!BB25 -> 120 | AE23: ='FS Desroches Daily'!BD25 -> 110 | AF23: ='FS Desroches Daily'!BF25 -> 17 | AG23: ='FS Desroches Daily'!BH25 -> 40 | AH23: ='FS Desroches Daily'!BJ25 -> 40 | AI23: ='FS Desroches Daily'!BL25 -> 50 | AJ23: ='FS Desroches Daily'!BN25 -> 40 | AK23: ='FS Desroches Daily'!BP25 -> 60 | AL23: ='FS Desroches Daily'!BR25 -> 37 | AM23: ='FS Desroches Daily'!BT25 -> 50 | AN23: ='FS Desroches Daily'!BV25 -> 42 | AO23: ='FS Desroches Daily'!BX25 -> 40 | AP23: ='FS Desroches Daily'!BZ25 -> 46 | AQ23: ='FS Desroches Daily'!CB25 -> 46.5 | AR23: ='FS Desroches Daily'!CD25 -> 8.5 | AS23: ='FS Desroches Daily'!CF25 -> 9.2 | AT23: ='FS Desroches Daily'!CH25 -> 47.4 | AU23: ='FS Desroches Daily'!CJ25 -> 280 | AV23: ='FS Desroches Daily'!CL25 -> 810 | AW23: ='FS Desroches Daily'!CM25 -> 94.7 | AX23: =IF(LPG!F30-LPG!F29<0,"0",(LPG!F30-LPG!F29)*1.8315) -> 0 | AY23: =IF(LPG!G30-LPG!G29<0,"0",(LPG!G30-LPG!G29)*1.8315) -> 0 | AZ23: =IF(LPG!H30-LPG!H29<0,"0",(LPG!H30-LPG!H29)*1.8315) -> 1.8315 | BA23: =IF(LPG!M30-LPG!M29<0,"0",(LPG!M30-LPG!M29)*1.8315) -> 3.663 | BB23: =IF(LPG!Q30-LPG!Q29<0,"0",(LPG!Q30-LPG!Q29)*1.8315) -> 3.663 | BC23: ='FS Desroches Daily'!CN25 -> 0
A24: Seychelles at Desroches Island | B24: 23 | C24: 5 | D24: 2022 | E24: ='FS Desroches Daily'!D26 -> 2600 | F24: ='FS Desroches Daily'!F26 -> 3300 | G24: ='FS Desroches Daily'!H26 -> 3200 | H24: ='FS Desroches Daily'!J26 -> 1600 | I24: ='FS Desroches Daily'!L26 -> 2200 | J24: ='FS Desroches Daily'!N26 -> 2100 | K24: ='FS Desroches Daily'!P26 -> 8 | L24: ='FS Desroches Daily'!R26 -> 5 | M24: ='FS Desroches Daily'!T26 -> 1.1 | N24: ='FS Desroches Daily'!V26 -> 411 | O24: ='FS Desroches Daily'!X26 -> 280 | P24: ='FS Desroches Daily'!Z26 -> 2700 | Q24: ='FS Desroches Daily'!AB26 -> 390 | R24: ='FS Desroches Daily'!AD26 -> 500 | S24: ='FS Desroches Daily'!AF26 -> 920 | T24: ='FS Desroches Daily'!AH26 -> 26 | U24: ='FS Desroches Daily'!AJ26 -> 710 | V24: ='FS Desroches Daily'!AL26 -> 250 | W24: ='FS Desroches Daily'!AN26 -> 190 | X24: ='FS Desroches Daily'!AP26 -> 130 | Y24: ='FS Desroches Daily'!AR26 -> 140 | Z24: ='FS Desroches Daily'!AT26 -> 130 | AA24: ='FS Desroches Daily'!AT26 -> 130 | AB24: ='FS Desroches Daily'!AV26 -> 100 | AC24: ='FS Desroches Daily'!AZ26 -> 100 | AD24: ='FS Desroches Daily'!BB26 -> 110 | AE24: ='FS Desroches Daily'!BD26 -> 70 | AF24: ='FS Desroches Daily'!BF26 -> 39 | AG24: ='FS Desroches Daily'!BH26 -> 40 | AH24: ='FS Desroches Daily'!BJ26 -> 30 | AI24: ='FS Desroches Daily'!BL26 -> 60 | AJ24: ='FS Desroches Daily'!BN26 -> 50 | AK24: ='FS Desroches Daily'!BP26 -> 60 | AL24: ='FS Desroches Daily'!BR26 -> 35 | AM24: ='FS Desroches Daily'!BT26 -> 60 | AN24: ='FS Desroches Daily'!BV26 -> 47 | AO24: ='FS Desroches Daily'!BX26 -> 50 | AP24: ='FS Desroches Daily'!BZ26 -> 44 | AQ24: ='FS Desroches Daily'!CB26 -> 46 | AR24: ='FS Desroches Daily'!CD26 -> 8.9 | AS24: ='FS Desroches Daily'!CF26 -> 4.9 | AT24: ='FS Desroches Daily'!CH26 -> 40.8 | AU24: ='FS Desroches Daily'!CJ26 -> 300 | AV24: ='FS Desroches Daily'!CL26 -> 820 | AW24: ='FS Desroches Daily'!CM26 -> 101 | AX24: =IF(LPG!F31-LPG!F30<0,"0",(LPG!F31-LPG!F30)*1.8315) -> 0 | AY24: =IF(LPG!G31-LPG!G30<0,"0",(LPG!G31-LPG!G30)*1.8315) -> 0 | AZ24: =IF(LPG!H31-LPG!H30<0,"0",(LPG!H31-LPG!H30)*1.8315) -> 7.326 | BA24: =IF(LPG!M31-LPG!M30<0,"0",(LPG!M31-LPG!M30)*1.8315) -> 0 | BB24: =IF(LPG!Q31-LPG!Q30<0,"0",(LPG!Q31-LPG!Q30)*1.8315) -> 5.4945 | BC24: ='FS Desroches Daily'!CN26 -> 35
