Workbook

Sheet TOTAL
A1: Site Name | B1: Day | C1: Month | D1: Year | E1: Total Electricity Kwh | F1: Electricity Tariff ($/Kwh) | G1: Water Utility Supply (m3) m3 | H1: Water Utility Supply (m3) $/m3 | I1: Room Nights | J1: Total Guests | K1: Cooling Degree Day
A2: Doha | B2: 1 | C2: 5 | D2: 2022 | E2: =0.75*INDEX('13 - Electrical Readings'!$H$8:$H$966,1+(2*(ROWS(A$1:A1)-1)))+INDEX('13 - Electrical Readings'!$Q$8:$Q$967,1+(2*(ROWS(A$1:A1)-1))) -> 59818.25 | F2: 0.041 | G2: =0.75*INDEX('9 - Water Readings'!$F$8:$F$970,1+(2*(ROWS(A$1:A1)-1)))+INDEX('9 - Water Readings'!$M$8:$M$970,1+(2*(ROWS(A$1:A1)-1))) -> 366 | H2: 1.5571913 | I2: ='Submetering '!AA2 -> 50 | J2: ='Submetering '!AB2 -> 212 | K2: ='Submetering '!AC2 -> 9.1
A3: Doha | B3: =B2+1 -> 2 | C3: 5 | D3: 2022 | E3: =0.75*INDEX('13 - Electrical Readings'!$H$8:$H$966,1+(2*(ROWS(A$1:A2)-1)))+INDEX('13 - Electrical Readings'!$Q$8:$Q$967,1+(2*(ROWS(A$1:A2)-1))) -> 56979.75 | F3: 0.041 | G3: =0.75*INDEX('9 - Water Readings'!$F$8:$F$970,1+(2*(ROWS(A$1:A2)-1)))+INDEX('9 - Water Readings'!$M$8:$M$970,1+(2*(ROWS(A$1:A2)-1))) -> 414 | H3: 1.5571913 | I3: ='Submetering '!AA3 -> 84 | J3: ='Submetering '!AB3 -> 358 | K3: ='Submetering '!AC3 -> 9.9
A4: Doha | B4: =B3+1 -> 3 | C4: 5 | D4: 2022 | E4: =0.75*INDEX('13 - Electrical Readings'!$H$8:$H$966,1+(2*(ROWS(A$1:A3)-1)))+INDEX('13 - Electrical Readings'!$Q$8:$Q$967,1+(2*(ROWS(A$1:A3)-1))) -> 60101.5 | F4: 0.041 | G4: =0.75*INDEX('9 - Water Readings'!$F$8:$F$970,1+(2*(ROWS(A$1:A3)-1)))+INDEX('9 - Water Readings'!$M$8:$M$970,1+(2*(ROWS(A$1:A3)-1))) -> 510 | H4: 1.5571913 | I4: ='Submetering '!AA4 -> 148 | J4: ='Submetering '!AB4 -> 644 | K4: ='Submetering '!AC4 -> 11
A5: Doha | B5: =B4+1 -> 4 | C5: 5 | D5: 2022 | E5: =0.75*INDEX('13 - Electrical Readings'!$H$8:$H$966,1+(2*(ROWS(A$1:A4)-1)))+INDEX('13 - Electrical Readings'!$Q$8:$Q$967,1+(2*(ROWS(A$1:A4)-1))) -> 59386.5 | F5: 0.041 | G5: =0.75*INDEX('9 - Water Readings'!$F$8:$F$970,1+(2*(ROWS(A$1:A4)-1)))+INDEX('9 - Water Readings'!$M$8:$M$970,1+(2*(ROWS(A$1:A4)-1))) -> 473.75 | H5: 1.5571913 | I5: ='Submetering '!AA5 -> 182 | J5: ='Submetering '!AB5 -> 808 | K5: ='Submetering '!AC5 -> 13.7
A6: Doha | B6: =B5+1 -> 5 | C6: 5 | D6: 2022 | E6: =0.75*INDEX('13 - Electrical Readings'!$H$8:$H$966,1+(2*(ROWS(A$1:A5)-1)))+INDEX('13 - Electrical Readings'!$Q$8:$Q$967,1+(2*(ROWS(A$1:A5)-1))) -> 64434.75 | F6: 0.041 | G6: =0.75*INDEX('9 - Water Readings'!$F$8:$F$970,1+(2*(ROWS(A$1:A5)-1)))+INDEX('9 - Water Readings'!$M$8:$M$970,1+(2*(ROWS(A$1:A5)-1))) -> 501 | H6: 1.5571913 | I6: ='Submetering '!AA6 -> 198 | J6: ='Submetering '!AB6 -> 880 | K6: ='Submetering '!AC6 -> 12.4
A7: Doha | B7: =B6+1 -> 6 | C7: 5 | D7: 2022 | E7: =0.75*INDEX('13 - Electrical Readings'!$H$8:$H$966,1+(2*(ROWS(A$1:A6)-1)))+INDEX('13 - Electrical Readings'!$Q$8:$Q$967,1+(2*(ROWS(A$1:A6)-1))) -> 64716.75 | F7: 0.041 | G7: =0.75*INDEX('9 - Water Readings'!$F$8:$F$970,1+(2*(ROWS(A$1:A6)-1)))+INDEX('9 - Water Readings'!$M$8:$M$970,1+(2*(ROWS(A$1:A6)-1))) -> 490 | H7: 1.5571913 | I7: ='Submetering '!AA7 -> 172 | J7: ='Submetering '!AB7 -> 732 | K7: ='Submetering '!AC7 -> 12.5
A8: Doha | B8: =B7+1 -> 7 | C8: 5 | D8: 2022 | E8: =0.75*INDEX('13 - Electrical Readings'!$H$8:$H$966,1+(2*(ROWS(A$1:A7)-1)))+INDEX('13 - Electrical Readings'!$Q$8:$Q$967,1+(2*(ROWS(A$1:A7)-1))) -> 65223.25 | F8: 0.041 | G8: =0.75*INDEX('9 - Water Readings'!$F$8:$F$970,1+(2*(ROWS(A$1:A7)-1)))+INDEX('9 - Water Readings'!$M$8:$M$970,1+(2*(ROWS(A$1:A7)-1))) -> 474 | H8: 1.5571913 | I8: ='Submetering '!AA8 -> 215 | J8: ='Submetering '!AB8 -> 922 | K8: ='Submetering '!AC8 -> 11
A9: Doha | B9: =B8+1 -> 8 | C9: 5 | D9: 2022 | E9: =0.75*INDEX('13 - Electrical Readings'!$H$8:$H$966,1+(2*(ROWS(A$1:A8)-1)))+INDEX('13 - Electrical Readings'!$Q$8:$Q$967,1+(2*(ROWS(A$1:A8)-1))) -> 63891 | F9: 0.041 | G9: =0.75*INDEX('9 - Water Readings'!$F$8:$F$970,1+(2*(ROWS(A$1:A8)-1)))+INDEX('9 - Water Readings'!$M$8:$M$970,1+(2*(ROWS(A$1:A8)-1))) -> 447 | H9: 1.5571913 | I9: ='Submetering '!AA9 -> 201 | J9: ='Submetering '!AB9 -> 840 | K9: ='Submetering '!AC9 -> 11
A10: Doha | B10: =B9+1 -> 9 | C10: 5 | D10: 2022 | E10: =0.75*INDEX('13 - Electrical Readings'!$H$8:$H$966,1+(2*(ROWS(A$1:A9)-1)))+INDEX('13 - Electrical Readings'!$Q$8:$Q$967,1+(2*(ROWS(A$1:A9)-1))) -> 62083.5 | F10: 0.041 | G10: =0.75*INDEX('9 - Water Readings'!$F$8:$F$970,1+(2*(ROWS(A$1:A9)-1)))+INDEX('9 - Water Readings'!$M$8:$M$970,1+(2*(ROWS(A$1:A9)-1))) -> 487 | H10: 1.5571913 | I10: ='Submetering '!AA10 -> 140 | J10: ='Submetering '!AB10 -> 442 | K10: ='Submetering '!AC10 -> 10
A11: Doha | B11: =B10+1 -> 10 | C11: 5 | D11: 2022 | E11: =0.75*INDEX('13 - Electrical Readings'!$H$8:$H$966,1+(2*(ROWS(A$1:A10)-1)))+INDEX('13 - Electrical Readings'!$Q$8:$Q$967,1+(2*(ROWS(A$1:A10)-1))) -> 58166.5 | F11: 0.041 | G11: =0.75*INDEX('9 - Water Readings'!$F$8:$F$970,1+(2*(ROWS(A$1:A10)-1)))+INDEX('9 - Water Readings'!$M$8:$M$970,1+(2*(ROWS(A$1:A10)-1))) -> 419 | H11: 1.5571913 | I11: ='Submetering '!AA11 -> 144 | J11: ='Submetering '!AB11 -> 206 | K11: ='Submetering '!AC11 -> 10.6
A12: Doha | B12: =B11+1 -> 11 | C12: 5 | D12: 2022 | E12: =0.75*INDEX('13 - Electrical Readings'!$H$8:$H$966,1+(2*(ROWS(A$1:A11)-1)))+INDEX('13 - Electrical Readings'!$Q$8:$Q$967,1+(2*(ROWS(A$1:A11)-1))) -> 62466 | F12: 0.041 | G12: =0.75*INDEX('9 - Water Readings'!$F$8:$F$970,1+(2*(ROWS(A$1:A11)-1)))+INDEX('9 - Water Readings'!$M$8:$M$970,1+(2*(ROWS(A$1:A11)-1))) -> 442 | H12: 1.5571913 | I12: ='Submetering '!AA12 -> 151 | J12: ='Submetering '!AB12 -> 440 | K12: ='Submetering '!AC12 -> 13.2
A13: Doha | B13: =B12+1 -> 12 | C13: 5 | D13: 2022 | E13: =0.75*INDEX('13 - Electrical Readings'!$H$8:$H$966,1+(2*(ROWS(A$1:A12)-1)))+INDEX('13 - Electrical Readings'!$Q$8:$Q$967,1+(2*(ROWS(A$1:A12)-1))) -> 63069.5 | F13: 0.041 | G13: =0.75*INDEX('9 - Water Readings'!$F$8:$F$970,1+(2*(ROWS(A$1:A12)-1)))+INDEX('9 - Water Readings'!$M$8:$M$970,1+(2*(ROWS(A$1:A12)-1))) -> 496 | H13: 1.5571913 | I13: ='Submetering '!AA13 -> 163 | J13: ='Submetering '!AB13 -> 574 | K13: ='Submetering '!AC13 -> 13.6
A14: Doha | B14: =B13+1 -> 13 | C14: 5 | D14: 2022 | E14: =0.75*INDEX('13 - Electrical Readings'!$H$8:$H$966,1+(2*(ROWS(A$1:A13)-1)))+INDEX('13 - Electrical Readings'!$Q$8:$Q$967,1+(2*(ROWS(A$1:A13)-1))) -> 65869.75 | F14: 0.041 | G14: =0.75*INDEX('9 - Water Readings'!$F$8:$F$970,1+(2*(ROWS(A$1:A13)-1)))+INDEX('9 - Water Readings'!$M$8:$M$970,1+(2*(ROWS(A$1:A13)-1))) -> 482 | H14: 1.5571913 | I14: ='Submetering '!AA14 -> 168 | J14: ='Submetering '!AB14 -> 628 | K14: ='Submetering '!AC14 -> 12.4
... A32: Doha | B32: =B31+1 -> 31 | C32: 5 | D32: 2022 | E32: =0.75*INDEX('13 - Electrical Readings'!$H$8:$H$966,1+(2*(ROWS(A$1:A31)-1)))+INDEX('13 - Electrical Readings'!$Q$8:$Q$967,1+(2*(ROWS(A$1:A31)-1))) -> 62866.25 | F32: 3.041 | G32: =0.75*INDEX('9 - Water Readings'!$F$8:$F$970,1+(2*(ROWS(A$1:A31)-1)))+INDEX('9 - Water Readings'!$M$8:$M$970,1+(2*(ROWS(A$1:A31)-1))) -> 426 | H32: 4.5571913 | I32: ='Submetering '!AA32 -> 137 | J32: ='Submetering '!AB32 -> 368 | K32: ='Submetering '!AC32 -> 14.5
E33: =SUM(E2:E32) -> 1905666.5 | G33: =SUM(G2:G32) -> 13844.75 | I33: =SUM(I2:I32) -> 4366 | J33: =SUM(J2:J32) -> 14858 | K33: =SUM(K2:K32) -> 405.7

Sheet Submetering 
A1: Site Name | B1: Day | C1: Month | D1: Year | E1: CP Chillers 157691 (KWh) | F1: CP Chillers 157692 (KWh) | G1: CP Chillers 157693 (KWh) | H1: CP Chillers 157694 (KWh) | I1: CP Chillers 167609 (KWh) | J1: Town House 166443 (KWh) | K1: Hotel 157687 (KWh) | L1: Hotel 157688 (KWh) | M1: Hotel 157689 (KWh) | N1: Hotel 157690 (KWh) | O1: SPA (KWh) | P1: Marina (KWh) | Q1: Nobu (KWh) | R1: CP F/F (m3) | S1: CP Chillers (m3) | T1: CP Parking (m3) | U1: Town House (m3) | V1: Spa B (m3) | W1: Spa A (m3) | X1: CW Hotel A (m3) | Y1: CCW Hotel B (m3) | Z1: Marina (m3) | AA1: Room Nights | AB1: Total Guests | AC1: Cooling Degree Day
A2: Doha | B2: 1 | C2: 5 | D2: 2022 | E2: =INDEX('13 - Electrical Readings'!$C$8:$C$966,1+(2*(ROWS(A$1:A1)-1))) -> 8693 | F2: =INDEX('13 - Electrical Readings'!$D$6:$D$966,1+(2*(ROWS(A$1:A2)-1))) -> 11682 | G2: =INDEX('13 - Electrical Readings'!$E$6:$E$966,1+(2*(ROWS(A$1:A2)-1))) -> 3284 | H2: =INDEX('13 - Electrical Readings'!$F$6:$F$966,1+(2*(ROWS(A$1:A2)-1))) -> 4056 | I2: =INDEX('13 - Electrical Readings'!$G$6:$G$966,1+(2*(ROWS(A$1:A2)-1))) -> 16 | J2: =INDEX('13 - Electrical Readings'!$I$6:$I$966,1+(2*(ROWS(A$1:A2)-1))) -> 1963 | K2: =INDEX('13 - Electrical Readings'!$J$6:$J$966,1+(2*(ROWS(B$1:B2)-1))) -> 9876 | L2: =INDEX('13 - Electrical Readings'!$K$6:$K$966,1+(2*(ROWS(C$1:C2)-1))) -> 3158 | M2: =INDEX('13 - Electrical Readings'!$L$6:$L$966,1+(2*(ROWS(D$1:D2)-1))) -> 4517 | N2: =INDEX('13 - Electrical Readings'!$M$6:$M$966,1+(2*(ROWS(E$1:E2)-1))) -> 7232 | O2: =INDEX('13 - Electrical Readings'!$N$6:$N$966,1+(2*(ROWS(E$1:E2)-1))) -> 7006 | P2: =INDEX('13 - Electrical Readings'!$O$6:$O$966,1+(2*(ROWS(E$1:E2)-1))) -> 2708 | Q2: =INDEX('13 - Electrical Readings'!$P$6:$P$966,1+(2*(ROWS(E$1:E2)-1))) -> 2560 | R2: =INDEX('9 - Water Readings'!$C$8:$C$970,1+(2*(ROWS(A$1:A1)-1))) -> 0 | S2: =INDEX('9 - Water Readings'!$D$8:$D$969,1+(2*(ROWS(A$1:A1)-1))) -> 0 | T2: =INDEX('9 - Water Readings'!$E$8:$E$970,1+(2*(ROWS(A$1:A1)-1))) -> 0 | U2: =INDEX('9 - Water Readings'!$G$8:$G$969,1+(2*(ROWS(A$1:A1)-1))) -> 98 | V2: =INDEX('9 - Water Readings'!$H$8:$H$970,1+(2*(ROWS(A$1:A1)-1))) -> 14 | W2: =INDEX('9 - Water Readings'!$I$8:$I$970,1+(2*(ROWS(A$1:A1)-1))) -> 25 | X2: =INDEX('9 - Water Readings'!$J$8:$J$970,1+(2*(ROWS(A$1:A1)-1))) -> 229 | Y2: =INDEX('9 - Water Readings'!$K$8:$K$970,1+(2*(ROWS(A$1:A1)-1))) -> 0 | Z2: =INDEX('9 - Water Readings'!$L$8:$L$970,1+(2*(ROWS(A$1:A1)-1))) -> 0 | AA2: ='9 - Water Readings'!Q7 -> 50 | AB2: ='9 - Water Readings'!R7 -> 212 | AC2: ='9 - Water Readings'!S7 -> 9.1
A3: Doha | B3: =B2+1 -> 2 | C3: 5 | D3: 2022 | E3: =INDEX('13 - Electrical Readings'!$C$8:$C$966,1+(2*(ROWS(A$1:A2)-1))) -> 18933 | F3: =INDEX('13 - Electrical Readings'!$D$6:$D$966,1+(2*(ROWS(A$1:A3)-1))) -> 5072 | G3: =INDEX('13 - Electrical Readings'!$E$6:$E$966,1+(2*(ROWS(A$1:A3)-1))) -> 3218 | H3: =INDEX('13 - Electrical Readings'!$F$6:$F$966,1+(2*(ROWS(A$1:A3)-1))) -> 4293 | I3: =INDEX('13 - Electrical Readings'!$G$6:$G$966,1+(2*(ROWS(A$1:A3)-1))) -> 13 | J3: =INDEX('13 - Electrical Readings'!$I$6:$I$966,1+(2*(ROWS(A$1:A3)-1))) -> 1804 | K3: =INDEX('13 - Electrical Readings'!$J$6:$J$966,1+(2*(ROWS(B$1:B3)-1))) -> 6090 | L3: =INDEX('13 - Electrical Readings'!$K$6:$K$966,1+(2*(ROWS(C$1:C3)-1))) -> 3474 | M3: =INDEX('13 - Electrical Readings'!$L$6:$L$966,1+(2*(ROWS(D$1:D3)-1))) -> 4661 | N3: =INDEX('13 - Electrical Readings'!$M$6:$M$966,1+(2*(ROWS(E$1:E3)-1))) -> 7387 | O3: =INDEX('13 - Electrical Readings'!$N$6:$N$966,1+(2*(ROWS(E$1:E3)-1))) -> 7468 | P3: =INDEX('13 - Electrical Readings'!$O$6:$O$966,1+(2*(ROWS(E$1:E3)-1))) -> 2449 | Q3: =INDEX('13 - Electrical Readings'!$P$6:$P$966,1+(2*(ROWS(E$1:E3)-1))) -> 0 | R3: =INDEX('9 - Water Readings'!$C$8:$C$970,1+(2*(ROWS(A$1:A2)-1))) -> 0 | S3: =INDEX('9 - Water Readings'!$D$8:$D$969,1+(2*(ROWS(A$1:A2)-1))) -> 0 | T3: =INDEX('9 - Water Readings'!$E$8:$E$970,1+(2*(ROWS(A$1:A2)-1))) -> 0 | U3: =INDEX('9 - Water Readings'!$G$8:$G$969,1+(2*(ROWS(A$1:A2)-1))) -> 106 | V3: =INDEX('9 - Water Readings'!$H$8:$H$970,1+(2*(ROWS(A$1:A2)-1))) -> 10 | W3: =INDEX('9 - Water Readings'!$I$8:$I$970,1+(2*(ROWS(A$1:A2)-1))) -> 42 | X3: =INDEX('9 - Water Readings'!$J$8:$J$970,1+(2*(ROWS(A$1:A2)-1))) -> 256 | Y3: =INDEX('9 - Water Readings'!$K$8:$K$970,1+(2*(ROWS(A$1:A2)-1))) -> 0 | Z3: =INDEX('9 - Water Readings'!$L$8:$L$970,1+(2*(ROWS(A$1:A2)-1))) -> 0 | AA3: ='9 - Water Readings'!Q8 -> 84 | AB3: ='9 - Water Readings'!R8 -> 358 | AC3: ='9 - Water Readings'!S8 -> 9.9
A4: Doha | B4: =B3+1 -> 3 | C4: 5 | D4: 2022 | E4: =INDEX('13 - Electrical Readings'!$C$8:$C$966,1+(2*(ROWS(A$1:A3)-1))) -> 19697 | F4: =INDEX('13 - Electrical Readings'!$D$6:$D$966,1+(2*(ROWS(A$1:A4)-1))) -> 2885 | G4: =INDEX('13 - Electrical Readings'!$E$6:$E$966,1+(2*(ROWS(A$1:A4)-1))) -> 2815 | H4: =INDEX('13 - Electrical Readings'!$F$6:$F$966,1+(2*(ROWS(A$1:A4)-1))) -> 3967 | I4: =INDEX('13 - Electrical Readings'!$G$6:$G$966,1+(2*(ROWS(A$1:A4)-1))) -> 14 | J4: =INDEX('13 - Electrical Readings'!$I$6:$I$966,1+(2*(ROWS(A$1:A4)-1))) -> 1929 | K4: =INDEX('13 - Electrical Readings'!$J$6:$J$966,1+(2*(ROWS(B$1:B4)-1))) -> 8013 | L4: =INDEX('13 - Electrical Readings'!$K$6:$K$966,1+(2*(ROWS(C$1:C4)-1))) -> 3338 | M4: =INDEX('13 - Electrical Readings'!$L$6:$L$966,1+(2*(ROWS(D$1:D4)-1))) -> 4762 | N4: =INDEX('13 - Electrical Readings'!$M$6:$M$966,1+(2*(ROWS(E$1:E4)-1))) -> 6978 | O4: =INDEX('13 - Electrical Readings'!$N$6:$N$966,1+(2*(ROWS(E$1:E4)-1))) -> 7658 | P4: =INDEX('13 - Electrical Readings'!$O$6:$O$966,1+(2*(ROWS(E$1:E4)-1))) -> 2750 | Q4: =INDEX('13 - Electrical Readings'!$P$6:$P$966,1+(2*(ROWS(E$1:E4)-1))) -> 2640 | R4: =INDEX('9 - Water Readings'!$C$8:$C$970,1+(2*(ROWS(A$1:A3)-1))) -> 0 | S4: =INDEX('9 - Water Readings'!$D$8:$D$969,1+(2*(ROWS(A$1:A3)-1))) -> 0 | T4: =INDEX('9 - Water Readings'!$E$8:$E$970,1+(2*(ROWS(A$1:A3)-1))) -> 0 | U4: =INDEX('9 - Water Readings'!$G$8:$G$969,1+(2*(ROWS(A$1:A3)-1))) -> 102 | V4: =INDEX('9 - Water Readings'!$H$8:$H$970,1+(2*(ROWS(A$1:A3)-1))) -> 72 | W4: =INDEX('9 - Water Readings'!$I$8:$I$970,1+(2*(ROWS(A$1:A3)-1))) -> 47 | X4: =INDEX('9 - Water Readings'!$J$8:$J$970,1+(2*(ROWS(A$1:A3)-1))) -> 289 | Y4: =INDEX('9 - Water Readings'!$K$8:$K$970,1+(2*(ROWS(A$1:A3)-1))) -> 0 | Z4: =INDEX('9 - Water Readings'!$L$8:$L$970,1+(2*(ROWS(A$1:A3)-1))) -> 0 | AA4: ='9 - Water Readings'!Q9 -> 148 | AB4: ='9 - Water Readings'!R9 -> 644 | AC4: ='9 - Water Readings'!S9 -> 11
A5: Doha | B5: =B4+1 -> 4 | C5: 5 | D5: 2022 | E5: =INDEX('13 - Electrical Readings'!$C$8:$C$966,1+(2*(ROWS(A$1:A4)-1))) -> 19109 | F5: =INDEX('13 - Electrical Readings'!$D$6:$D$966,1+(2*(ROWS(A$1:A5)-1))) -> 3057 | G5: =INDEX('13 - Electrical Readings'!$E$6:$E$966,1+(2*(ROWS(A$1:A5)-1))) -> 2810 | H5: =INDEX('13 - Electrical Readings'!$F$6:$F$966,1+(2*(ROWS(A$1:A5)-1))) -> 3930 | I5: =INDEX('13 - Electrical Readings'!$G$6:$G$966,1+(2*(ROWS(A$1:A5)-1))) -> 12 | J5: =INDEX('13 - Electrical Readings'!$I$6:$I$966,1+(2*(ROWS(A$1:A5)-1))) -> 1919 | K5: =INDEX('13 - Electrical Readings'!$J$6:$J$966,1+(2*(ROWS(B$1:B5)-1))) -> 7883 | L5: =INDEX('13 - Electrical Readings'!$K$6:$K$966,1+(2*(ROWS(C$1:C5)-1))) -> 3105 | M5: =INDEX('13 - Electrical Readings'!$L$6:$L$966,1+(2*(ROWS(D$1:D5)-1))) -> 4551 | N5: =INDEX('13 - Electrical Readings'!$M$6:$M$966,1+(2*(ROWS(E$1:E5)-1))) -> 6776 | O5: =INDEX('13 - Electrical Readings'!$N$6:$N$966,1+(2*(ROWS(E$1:E5)-1))) -> 8151 | P5: =INDEX('13 - Electrical Readings'!$O$6:$O$966,1+(2*(ROWS(E$1:E5)-1))) -> 2673 | Q5: =INDEX('13 - Electrical Readings'!$P$6:$P$966,1+(2*(ROWS(E$1:E5)-1))) -> 2640 | R5: =INDEX('9 - Water Readings'!$C$8:$C$970,1+(2*(ROWS(A$1:A4)-1))) -> 0 | S5: =INDEX('9 - Water Readings'!$D$8:$D$969,1+(2*(ROWS(A$1:A4)-1))) -> 1 | T5: =INDEX('9 - Water Readings'!$E$8:$E$970,1+(2*(ROWS(A$1:A4)-1))) -> 0 | U5: =INDEX('9 - Water Readings'!$G$8:$G$969,1+(2*(ROWS(A$1:A4)-1))) -> 102 | V5: =INDEX('9 - Water Readings'!$H$8:$H$970,1+(2*(ROWS(A$1:A4)-1))) -> 20 | W5: =INDEX('9 - Water Readings'!$I$8:$I$970,1+(2*(ROWS(A$1:A4)-1))) -> 52 | X5: =INDEX('9 - Water Readings'!$J$8:$J$970,1+(2*(ROWS(A$1:A4)-1))) -> 299 | Y5: =INDEX('9 - Water Readings'!$K$8:$K$970,1+(2*(ROWS(A$1:A4)-1))) -> 0 | Z5: =INDEX('9 - Water Readings'!$L$8:$L$970,1+(2*(ROWS(A$1:A4)-1))) -> 0 | AA5: ='9 - Water Readings'!Q10 -> 182 | AB5: ='9 - Water Readings'!R10 -> 808 | AC5: ='9 - Water Readings'!S10 -> 13.7
A6: Doha | B6: =B5+1 -> 5 | C6: 5 | D6: 2022 | E6: =INDEX('13 - Electrical Readings'!$C$8:$C$966,1+(2*(ROWS(A$1:A5)-1))) -> 17488 | F6: =INDEX('13 - Electrical Readings'!$D$6:$D$966,1+(2*(ROWS(A$1:A6)-1))) -> 8080 | G6: =INDEX('13 - Electrical Readings'!$E$6:$E$966,1+(2*(ROWS(A$1:A6)-1))) -> 3766 | H6: =INDEX('13 - Electrical Readings'!$F$6:$F$966,1+(2*(ROWS(A$1:A6)-1))) -> 4027 | I6: =INDEX('13 - Electrical Readings'!$G$6:$G$966,1+(2*(ROWS(A$1:A6)-1))) -> 12 | J6: =INDEX('13 - Electrical Readings'!$I$6:$I$966,1+(2*(ROWS(A$1:A6)-1))) -> 1830 | K6: =INDEX('13 - Electrical Readings'!$J$6:$J$966,1+(2*(ROWS(B$1:B6)-1))) -> 7460 | L6: =INDEX('13 - Electrical Readings'!$K$6:$K$966,1+(2*(ROWS(C$1:C6)-1))) -> 3332 | M6: =INDEX('13 - Electrical Readings'!$L$6:$L$966,1+(2*(ROWS(D$1:D6)-1))) -> 4764 | N6: =INDEX('13 - Electrical Readings'!$M$6:$M$966,1+(2*(ROWS(E$1:E6)-1))) -> 7354 | O6: =INDEX('13 - Electrical Readings'!$N$6:$N$966,1+(2*(ROWS(E$1:E6)-1))) -> 8451 | P6: =INDEX('13 - Electrical Readings'!$O$6:$O$966,1+(2*(ROWS(E$1:E6)-1))) -> 3584 | Q6: =INDEX('13 - Electrical Readings'!$P$6:$P$966,1+(2*(ROWS(E$1:E6)-1))) -> 2630 | R6: =INDEX('9 - Water Readings'!$C$8:$C$970,1+(2*(ROWS(A$1:A5)-1))) -> 0 | S6: =INDEX('9 - Water Readings'!$D$8:$D$969,1+(2*(ROWS(A$1:A5)-1))) -> 0 | T6: =INDEX('9 - Water Readings'!$E$8:$E$970,1+(2*(ROWS(A$1:A5)-1))) -> 0 | U6: =INDEX('9 - Water Readings'!$G$8:$G$969,1+(2*(ROWS(A$1:A5)-1))) -> 109 | V6: =INDEX('9 - Water Readings'!$H$8:$H$970,1+(2*(ROWS(A$1:A5)-1))) -> 17 | W6: =INDEX('9 - Water Readings'!$I$8:$I$970,1+(2*(ROWS(A$1:A5)-1))) -> 52 | X6: =INDEX('9 - Water Readings'!$J$8:$J$970,1+(2*(ROWS(A$1:A5)-1))) -> 323 | Y6: =INDEX('9 - Water Readings'!$K$8:$K$970,1+(2*(ROWS(A$1:A5)-1))) -> 0 | Z6: =INDEX('9 - Water Readings'!$L$8:$L$970,1+(2*(ROWS(A$1:A5)-1))) -> 0 | AA6: ='9 - Water Readings'!Q11 -> 198 | AB6: ='9 - Water Readings'!R11 -> 880 | AC6: ='9 - Water Readings'!S11 -> 12.4
A7: Doha | B7: =B6+1 -> 6 | C7: 5 | D7: 2022 | E7: =INDEX('13 - Electrical Readings'!$C$8:$C$966,1+(2*(ROWS(A$1:A6)-1))) -> 19726 | F7: =INDEX('13 - Electrical Readings'!$D$6:$D$966,1+(2*(ROWS(A$1:A7)-1))) -> 8174 | G7: =INDEX('13 - Electrical Readings'!$E$6:$E$966,1+(2*(ROWS(A$1:A7)-1))) -> 3676 | H7: =INDEX('13 - Electrical Readings'!$F$6:$F$966,1+(2*(ROWS(A$1:A7)-1))) -> 4315 | I7: =INDEX('13 - Electrical Readings'!$G$6:$G$966,1+(2*(ROWS(A$1:A7)-1))) -> 14 | J7: =INDEX('13 - Electrical Readings'!$I$6:$I$966,1+(2*(ROWS(A$1:A7)-1))) -> 1879 | K7: =INDEX('13 - Electrical Readings'!$J$6:$J$966,1+(2*(ROWS(B$1:B7)-1))) -> 6982 | L7: =INDEX('13 - Electrical Readings'!$K$6:$K$966,1+(2*(ROWS(C$1:C7)-1))) -> 3457 | M7: =INDEX('13 - Electrical Readings'!$L$6:$L$966,1+(2*(ROWS(D$1:D7)-1))) -> 4516 | N7: =INDEX('13 - Electrical Readings'!$M$6:$M$966,1+(2*(ROWS(E$1:E7)-1))) -> 7370 | O7: =INDEX('13 - Electrical Readings'!$N$6:$N$966,1+(2*(ROWS(E$1:E7)-1))) -> 8127 | P7: =INDEX('13 - Electrical Readings'!$O$6:$O$966,1+(2*(ROWS(E$1:E7)-1))) -> 2587 | Q7: =INDEX('13 - Electrical Readings'!$P$6:$P$966,1+(2*(ROWS(E$1:E7)-1))) -> 2870 | R7: =INDEX('9 - Water Readings'!$C$8:$C$970,1+(2*(ROWS(A$1:A6)-1))) -> 0 | S7: =INDEX('9 - Water Readings'!$D$8:$D$969,1+(2*(ROWS(A$1:A6)-1))) -> 0 | T7: =INDEX('9 - Water Readings'!$E$8:$E$970,1+(2*(ROWS(A$1:A6)-1))) -> 0 | U7: =INDEX('9 - Water Readings'!$G$8:$G$969,1+(2*(ROWS(A$1:A6)-1))) -> 100 | V7: =INDEX('9 - Water Readings'!$H$8:$H$970,1+(2*(ROWS(A$1:A6)-1))) -> 19 | W7: =INDEX('9 - Water Readings'!$I$8:$I$970,1+(2*(ROWS(A$1:A6)-1))) -> 59 | X7: =INDEX('9 - Water Readings'!$J$8:$J$970,1+(2*(ROWS(A$1:A6)-1))) -> 312 | Y7: =INDEX('9 - Water Readings'!$K$8:$K$970,1+(2*(ROWS(A$1:A6)-1))) -> 0 | Z7: =INDEX('9 - Water Readings'!$L$8:$L$970,1+(2*(ROWS(A$1:A6)-1))) -> 0 | AA7: ='9 - Water Readings'!Q12 -> 172 | AB7: ='9 - Water Readings'!R12 -> 732 | AC7: ='9 - Water Readings'!S12 -> 12.5
A8: Doha | B8: =B7+1 -> 7 | C8: 5 | D8: 2022 | E8: =INDEX('13 - Electrical Readings'!$C$8:$C$966,1+(2*(ROWS(A$1:A7)-1))) -> 17248 | F8: =INDEX('13 - Electrical Readings'!$D$6:$D$966,1+(2*(ROWS(A$1:A8)-1))) -> 9345 | G8: =INDEX('13 - Electrical Readings'!$E$6:$E$966,1+(2*(ROWS(A$1:A8)-1))) -> 4859 | H8: =INDEX('13 - Electrical Readings'!$F$6:$F$966,1+(2*(ROWS(A$1:A8)-1))) -> 4685 | I8: =INDEX('13 - Electrical Readings'!$G$6:$G$966,1+(2*(ROWS(A$1:A8)-1))) -> 14 | J8: =INDEX('13 - Electrical Readings'!$I$6:$I$966,1+(2*(ROWS(A$1:A8)-1))) -> 1871 | K8: =INDEX('13 - Electrical Readings'!$J$6:$J$966,1+(2*(ROWS(B$1:B8)-1))) -> 6970 | L8: =INDEX('13 - Electrical Readings'!$K$6:$K$966,1+(2*(ROWS(C$1:C8)-1))) -> 3334 | M8: =INDEX('13 - Electrical Readings'!$L$6:$L$966,1+(2*(ROWS(D$1:D8)-1))) -> 4532 | N8: =INDEX('13 - Electrical Readings'!$M$6:$M$966,1+(2*(ROWS(E$1:E8)-1))) -> 7609 | O8: =INDEX('13 - Electrical Readings'!$N$6:$N$966,1+(2*(ROWS(E$1:E8)-1))) -> 8272 | P8: =INDEX('13 - Electrical Readings'!$O$6:$O$966,1+(2*(ROWS(E$1:E8)-1))) -> 3042 | Q8: =INDEX('13 - Electrical Readings'!$P$6:$P$966,1+(2*(ROWS(E$1:E8)-1))) -> 2480 | R8: =INDEX('9 - Water Readings'!$C$8:$C$970,1+(2*(ROWS(A$1:A7)-1))) -> 0 | S8: =INDEX('9 - Water Readings'!$D$8:$D$969,1+(2*(ROWS(A$1:A7)-1))) -> 0 | T8: =INDEX('9 - Water Readings'!$E$8:$E$970,1+(2*(ROWS(A$1:A7)-1))) -> 0 | U8: =INDEX('9 - Water Readings'!$G$8:$G$969,1+(2*(ROWS(A$1:A7)-1))) -> 106 | V8: =INDEX('9 - Water Readings'!$H$8:$H$970,1+(2*(ROWS(A$1:A7)-1))) -> 15 | W8: =INDEX('9 - Water Readings'!$I$8:$I$970,1+(2*(ROWS(A$1:A7)-1))) -> 56 | X8: =INDEX('9 - Water Readings'!$J$8:$J$970,1+(2*(ROWS(A$1:A7)-1))) -> 297 | Y8: =INDEX('9 - Water Readings'!$K$8:$K$970,1+(2*(ROWS(A$1:A7)-1))) -> 0 | Z8: =INDEX('9 - Water Readings'!$L$8:$L$970,1+(2*(ROWS(A$1:A7)-1))) -> 0 | AA8: ='9 - Water Readings'!Q13 -> 215 | AB8: ='9 - Water Readings'!R13 -> 922 | AC8: ='9 - Water Readings'!S13 -> 11
A9: Doha | B9: =B8+1 -> 8 | C9: 5 | D9: 2022 | E9: =INDEX('13 - Electrical Readings'!$C$8:$C$966,1+(2*(ROWS(A$1:A8)-1))) -> 11421 | F9: =INDEX('13 - Electrical Readings'!$D$6:$D$966,1+(2*(ROWS(A$1:A9)-1))) -> 974 | G9: =INDEX('13 - Electrical Readings'!$E$6:$E$966,1+(2*(ROWS(A$1:A9)-1))) -> 8053 | H9: =INDEX('13 - Electrical Readings'!$F$6:$F$966,1+(2*(ROWS(A$1:A9)-1))) -> 4420 | I9: =INDEX('13 - Electrical Readings'!$G$6:$G$966,1+(2*(ROWS(A$1:A9)-1))) -> 9476 | J9: =INDEX('13 - Electrical Readings'!$I$6:$I$966,1+(2*(ROWS(A$1:A9)-1))) -> 1890 | K9: =INDEX('13 - Electrical Readings'!$J$6:$J$966,1+(2*(ROWS(B$1:B9)-1))) -> 6974 | L9: =INDEX('13 - Electrical Readings'!$K$6:$K$966,1+(2*(ROWS(C$1:C9)-1))) -> 3520 | M9: =INDEX('13 - Electrical Readings'!$L$6:$L$966,1+(2*(ROWS(D$1:D9)-1))) -> 4590 | N9: =INDEX('13 - Electrical Readings'!$M$6:$M$966,1+(2*(ROWS(E$1:E9)-1))) -> 7288 | O9: =INDEX('13 - Electrical Readings'!$N$6:$N$966,1+(2*(ROWS(E$1:E9)-1))) -> 8296 | P9: =INDEX('13 - Electrical Readings'!$O$6:$O$966,1+(2*(ROWS(E$1:E9)-1))) -> 3375 | Q9: =INDEX('13 - Electrical Readings'!$P$6:$P$966,1+(2*(ROWS(E$1:E9)-1))) -> 2200 | R9: =INDEX('9 - Water Readings'!$C$8:$C$970,1+(2*(ROWS(A$1:A8)-1))) -> 0 | S9: =INDEX('9 - Water Readings'!$D$8:$D$969,1+(2*(ROWS(A$1:A8)-1))) -> 0 | T9: =INDEX('9 - Water Readings'!$E$8:$E$970,1+(2*(ROWS(A$1:A8)-1))) -> 0 | U9: =INDEX('9 - Water Readings'!$G$8:$G$969,1+(2*(ROWS(A$1:A8)-1))) -> 100 | V9: =INDEX('9 - Water Readings'!$H$8:$H$970,1+(2*(ROWS(A$1:A8)-1))) -> 17 | W9: =INDEX('9 - Water Readings'!$I$8:$I$970,1+(2*(ROWS(A$1:A8)-1))) -> 30 | X9: =INDEX('9 - Water Readings'!$J$8:$J$970,1+(2*(ROWS(A$1:A8)-1))) -> 300 | Y9: =INDEX('9 - Water Readings'!$K$8:$K$970,1+(2*(ROWS(A$1:A8)-1))) -> 0 | Z9: =INDEX('9 - Water Readings'!$L$8:$L$970,1+(2*(ROWS(A$1:A8)-1))) -> 0 | AA9: ='9 - Water Readings'!Q14 -> 201 | AB9: ='9 - Water Readings'!R14 -> 840 | AC9: ='9 - Water Readings'!S14 -> 11
A10: Doha | B10: =B9+1 -> 9 | C10: 5 | D10: 2022 | E10: =INDEX('13 - Electrical Readings'!$C$8:$C$966,1+(2*(ROWS(A$1:A9)-1))) -> 3281 | F10: =INDEX('13 - Electrical Readings'!$D$6:$D$966,1+(2*(ROWS(A$1:A10)-1))) -> 816 | G10: =INDEX('13 - Electrical Readings'!$E$6:$E$966,1+(2*(ROWS(A$1:A10)-1))) -> 2915 | H10: =INDEX('13 - Electrical Readings'!$F$6:$F$966,1+(2*(ROWS(A$1:A10)-1))) -> 3593 | I10: =INDEX('13 - Electrical Readings'!$G$6:$G$966,1+(2*(ROWS(A$1:A10)-1))) -> 18797 | J10: =INDEX('13 - Electrical Readings'!$I$6:$I$966,1+(2*(ROWS(A$1:A10)-1))) -> 2047 | K10: =INDEX('13 - Electrical Readings'!$J$6:$J$966,1+(2*(ROWS(B$1:B10)-1))) -> 7717 | L10: =INDEX('13 - Electrical Readings'!$K$6:$K$966,1+(2*(ROWS(C$1:C10)-1))) -> 3775 | M10: =INDEX('13 - Electrical Readings'!$L$6:$L$966,1+(2*(ROWS(D$1:D10)-1))) -> 5129 | N10: =INDEX('13 - Electrical Readings'!$M$6:$M$966,1+(2*(ROWS(E$1:E10)-1))) -> 7202 | O10: =INDEX('13 - Electrical Readings'!$N$6:$N$966,1+(2*(ROWS(E$1:E10)-1))) -> 8364 | P10: =INDEX('13 - Electrical Readings'!$O$6:$O$966,1+(2*(ROWS(E$1:E10)-1))) -> 3288 | Q10: =INDEX('13 - Electrical Readings'!$P$6:$P$966,1+(2*(ROWS(E$1:E10)-1))) -> 2510 | R10: =INDEX('9 - Water Readings'!$C$8:$C$970,1+(2*(ROWS(A$1:A9)-1))) -> 0 | S10: =INDEX('9 - Water Readings'!$D$8:$D$969,1+(2*(ROWS(A$1:A9)-1))) -> 0 | T10: =INDEX('9 - Water Readings'!$E$8:$E$970,1+(2*(ROWS(A$1:A9)-1))) -> 0 | U10: =INDEX('9 - Water Readings'!$G$8:$G$969,1+(2*(ROWS(A$1:A9)-1))) -> 118 | V10: =INDEX('9 - Water Readings'!$H$8:$H$970,1+(2*(ROWS(A$1:A9)-1))) -> 15 | W10: =INDEX('9 - Water Readings'!$I$8:$I$970,1+(2*(ROWS(A$1:A9)-1))) -> 54 | X10: =INDEX('9 - Water Readings'!$J$8:$J$970,1+(2*(ROWS(A$1:A9)-1))) -> 300 | Y10: =INDEX('9 - Water Readings'!$K$8:$K$970,1+(2*(ROWS(A$1:A9)-1))) -> 0 | Z10: =INDEX('9 - Water Readings'!$L$8:$L$970,1+(2*(ROWS(A$1:A9)-1))) -> 0 | AA10: ='9 - Water Readings'!Q15 -> 140 | AB10: ='9 - Water Readings'!R15 -> 442 | AC10: ='9 - Water Readings'!S15 -> 10
A11: Doha | B11: =B10+1 -> 10 | C11: 5 | D11: 2022 | E11: =INDEX('13 - Electrical Readings'!$C$8:$C$966,1+(2*(ROWS(A$1:A10)-1))) -> 5800 | F11: =INDEX('13 - Electrical Readings'!$D$6:$D$966,1+(2*(ROWS(A$1:A11)-1))) -> 762 | G11: =INDEX('13 - Electrical Readings'!$E$6:$E$966,1+(2*(ROWS(A$1:A11)-1))) -> 3319 | H11: =INDEX('13 - Electrical Readings'!$F$6:$F$966,1+(2*(ROWS(A$1:A11)-1))) -> 3326 | I11: =INDEX('13 - Electrical Readings'!$G$6:$G$966,1+(2*(ROWS(A$1:A11)-1))) -> 16667 | J11: =INDEX('13 - Electrical Readings'!$I$6:$I$966,1+(2*(ROWS(A$1:A11)-1))) -> 1909 | K11: =INDEX('13 - Electrical Readings'!$J$6:$J$966,1+(2*(ROWS(B$1:B11)-1))) -> 7056 | L11: =INDEX('13 - Electrical Readings'!$K$6:$K$966,1+(2*(ROWS(C$1:C11)-1))) -> 3187 | M11: =INDEX('13 - Electrical Readings'!$L$6:$L$966,1+(2*(ROWS(D$1:D11)-1))) -> 4166 | N11: =INDEX('13 - Electrical Readings'!$M$6:$M$966,1+(2*(ROWS(E$1:E11)-1))) -> 6335 | O11: =INDEX('13 - Electrical Readings'!$N$6:$N$966,1+(2*(ROWS(E$1:E11)-1))) -> 7607 | P11: =INDEX('13 - Electrical Readings'!$O$6:$O$966,1+(2*(ROWS(E$1:E11)-1))) -> 3051 | Q11: =INDEX('13 - Electrical Readings'!$P$6:$P$966,1+(2*(ROWS(E$1:E11)-1))) -> 2450 | R11: =INDEX('9 - Water Readings'!$C$8:$C$970,1+(2*(ROWS(A$1:A10)-1))) -> 0 | S11: =INDEX('9 - Water Readings'!$D$8:$D$969,1+(2*(ROWS(A$1:A10)-1))) -> 0 | T11: =INDEX('9 - Water Readings'!$E$8:$E$970,1+(2*(ROWS(A$1:A10)-1))) -> 0 | U11: =INDEX('9 - Water Readings'!$G$8:$G$969,1+(2*(ROWS(A$1:A10)-1))) -> 108 | V11: =INDEX('9 - Water Readings'!$H$8:$H$970,1+(2*(ROWS(A$1:A10)-1))) -> 12 | W11: =INDEX('9 - Water Readings'!$I$8:$I$970,1+(2*(ROWS(A$1:A10)-1))) -> 49 | X11: =INDEX('9 - Water Readings'!$J$8:$J$970,1+(2*(ROWS(A$1:A10)-1))) -> 250 | Y11: =INDEX('9 - Water Readings'!$K$8:$K$970,1+(2*(ROWS(A$1:A10)-1))) -> 0 | Z11: =INDEX('9 - Water Readings'!$L$8:$L$970,1+(2*(ROWS(A$1:A10)-1))) -> 0 | AA11: ='9 - Water Readings'!Q16 -> 144 | AB11: ='9 - Water Readings'!R16 -> 206 | AC11: ='9 - Water Readings'!S16 -> 10.6
A12: Doha | B12: =B11+1 -> 11 | C12: 5 | D12: 2022 | E12: =INDEX('13 - Electrical Readings'!$C$8:$C$966,1+(2*(ROWS(A$1:A11)-1))) -> 5876 | F12: =INDEX('13 - Electrical Readings'!$D$6:$D$966,1+(2*(ROWS(A$1:A12)-1))) -> 774 | G12: =INDEX('13 - Electrical Readings'!$E$6:$E$966,1+(2*(ROWS(A$1:A12)-1))) -> 3324 | H12: =INDEX('13 - Electrical Readings'!$F$6:$F$966,1+(2*(ROWS(A$1:A12)-1))) -> 3485 | I12: =INDEX('13 - Electrical Readings'!$G$6:$G$966,1+(2*(ROWS(A$1:A12)-1))) -> 17797 | J12: =INDEX('13 - Electrical Readings'!$I$6:$I$966,1+(2*(ROWS(A$1:A12)-1))) -> 2072 | K12: =INDEX('13 - Electrical Readings'!$J$6:$J$966,1+(2*(ROWS(B$1:B12)-1))) -> 7681 | L12: =INDEX('13 - Electrical Readings'!$K$6:$K$966,1+(2*(ROWS(C$1:C12)-1))) -> 3638 | M12: =INDEX('13 - Electrical Readings'!$L$6:$L$966,1+(2*(ROWS(D$1:D12)-1))) -> 4605 | N12: =INDEX('13 - Electrical Readings'!$M$6:$M$966,1+(2*(ROWS(E$1:E12)-1))) -> 6897 | O12: =INDEX('13 - Electrical Readings'!$N$6:$N$966,1+(2*(ROWS(E$1:E12)-1))) -> 8317 | P12: =INDEX('13 - Electrical Readings'!$O$6:$O$966,1+(2*(ROWS(E$1:E12)-1))) -> 3314 | Q12: =INDEX('13 - Electrical Readings'!$P$6:$P$966,1+(2*(ROWS(E$1:E12)-1))) -> 2500 | R12: =INDEX('9 - Water Readings'!$C$8:$C$970,1+(2*(ROWS(A$1:A11)-1))) -> 0 | S12: =INDEX('9 - Water Readings'!$D$8:$D$969,1+(2*(ROWS(A$1:A11)-1))) -> 0 | T12: =INDEX('9 - Water Readings'!$E$8:$E$970,1+(2*(ROWS(A$1:A11)-1))) -> 0 | U12: =INDEX('9 - Water Readings'!$G$8:$G$969,1+(2*(ROWS(A$1:A11)-1))) -> 107 | V12: =INDEX('9 - Water Readings'!$H$8:$H$970,1+(2*(ROWS(A$1:A11)-1))) -> 12 | W12: =INDEX('9 - Water Readings'!$I$8:$I$970,1+(2*(ROWS(A$1:A11)-1))) -> 49 | X12: =INDEX('9 - Water Readings'!$J$8:$J$970,1+(2*(ROWS(A$1:A11)-1))) -> 274 | Y12: =INDEX('9 - Water Readings'!$K$8:$K$970,1+(2*(ROWS(A$1:A11)-1))) -> 0 | Z12: =INDEX('9 - Water Readings'!$L$8:$L$970,1+(2*(ROWS(A$1:A11)-1))) -> 0 | AA12: ='9 - Water Readings'!Q17 -> 151 | AB12: ='9 - Water Readings'!R17 -> 440 | AC12: ='9 - Water Readings'!S17 -> 13.2
A13: Doha | B13: =B12+1 -> 12 | C13: 5 | D13: 2022 | E13: =INDEX('13 - Electrical Readings'!$C$8:$C$966,1+(2*(ROWS(A$1:A12)-1))) -> 7188 | F13: =INDEX('13 - Electrical Readings'!$D$6:$D$966,1+(2*(ROWS(A$1:A13)-1))) -> 789 | G13: =INDEX('13 - Electrical Readings'!$E$6:$E$966,1+(2*(ROWS(A$1:A13)-1))) -> 3510 | H13: =INDEX('13 - Electrical Readings'!$F$6:$F$966,1+(2*(ROWS(A$1:A13)-1))) -> 3422 | I13: =INDEX('13 - Electrical Readings'!$G$6:$G$966,1+(2*(ROWS(A$1:A13)-1))) -> 17573 | J13: =INDEX('13 - Electrical Readings'!$I$6:$I$966,1+(2*(ROWS(A$1:A13)-1))) -> 2014 | K13: =INDEX('13 - Electrical Readings'!$J$6:$J$966,1+(2*(ROWS(B$1:B13)-1))) -> 7601 | L13: =INDEX('13 - Electrical Readings'!$K$6:$K$966,1+(2*(ROWS(C$1:C13)-1))) -> 3684 | M13: =INDEX('13 - Electrical Readings'!$L$6:$L$966,1+(2*(ROWS(D$1:D13)-1))) -> 4585 | N13: =INDEX('13 - Electrical Readings'!$M$6:$M$966,1+(2*(ROWS(E$1:E13)-1))) -> 6584 | O13: =INDEX('13 - Electrical Readings'!$N$6:$N$966,1+(2*(ROWS(E$1:E13)-1))) -> 8326 | P13: =INDEX('13 - Electrical Readings'!$O$6:$O$966,1+(2*(ROWS(E$1:E13)-1))) -> 3514 | Q13: =INDEX('13 - Electrical Readings'!$P$6:$P$966,1+(2*(ROWS(E$1:E13)-1))) -> 2400 | R13: =INDEX('9 - Water Readings'!$C$8:$C$970,1+(2*(ROWS(A$1:A12)-1))) -> 0 | S13: =INDEX('9 - Water Readings'!$D$8:$D$969,1+(2*(ROWS(A$1:A12)-1))) -> 0 | T13: =INDEX('9 - Water Readings'!$E$8:$E$970,1+(2*(ROWS(A$1:A12)-1))) -> 0 | U13: =INDEX('9 - Water Readings'!$G$8:$G$969,1+(2*(ROWS(A$1:A12)-1))) -> 108 | V13: =INDEX('9 - Water Readings'!$H$8:$H$970,1+(2*(ROWS(A$1:A12)-1))) -> 13 | W13: =INDEX('9 - Water Readings'!$I$8:$I$970,1+(2*(ROWS(A$1:A12)-1))) -> 51 | X13: =INDEX('9 - Water Readings'!$J$8:$J$970,1+(2*(ROWS(A$1:A12)-1))) -> 324 | Y13: =INDEX('9 - Water Readings'!$K$8:$K$970,1+(2*(ROWS(A$1:A12)-1))) -> 0 | Z13: =INDEX('9 - Water Readings'!$L$8:$L$970,1+(2*(ROWS(A$1:A12)-1))) -> 0 | AA13: ='9 - Water Readings'!Q18 -> 163 | AB13: ='9 - Water Readings'!R18 -> 574 | AC13: ='9 - Water Readings'!S18 -> 13.6
A14: Doha | B14: =B13+1 -> 13 | C14: 5 | D14: 2022 | E14: =INDEX('13 - Electrical Readings'!$C$8:$C$966,1+(2*(ROWS(A$1:A13)-1))) -> 11098 | F14: =INDEX('13 - Electrical Readings'!$D$6:$D$966,1+(2*(ROWS(A$1:A14)-1))) -> 801 | G14: =INDEX('13 - Electrical Readings'!$E$6:$E$966,1+(2*(ROWS(A$1:A14)-1))) -> 4207 | H14: =INDEX('13 - Electrical Readings'!$F$6:$F$966,1+(2*(ROWS(A$1:A14)-1))) -> 3675 | I14: =INDEX('13 - Electrical Readings'!$G$6:$G$966,1+(2*(ROWS(A$1:A14)-1))) -> 15884 | J14: =INDEX('13 - Electrical Readings'!$I$6:$I$966,1+(2*(ROWS(A$1:A14)-1))) -> 2078 | K14: =INDEX('13 - Electrical Readings'!$J$6:$J$966,1+(2*(ROWS(B$1:B14)-1))) -> 7688 | L14: =INDEX('13 - Electrical Readings'!$K$6:$K$966,1+(2*(ROWS(C$1:C14)-1))) -> 3477 | M14: =INDEX('13 - Electrical Readings'!$L$6:$L$966,1+(2*(ROWS(D$1:D14)-1))) -> 4682 | N14: =INDEX('13 - Electrical Readings'!$M$6:$M$966,1+(2*(ROWS(E$1:E14)-1))) -> 6833 | O14: =INDEX('13 - Electrical Readings'!$N$6:$N$966,1+(2*(ROWS(E$1:E14)-1))) -> 8398 | P14: =INDEX('13 - Electrical Readings'!$O$6:$O$966,1+(2*(ROWS(E$1:E14)-1))) -> 3255 | Q14: =INDEX('13 - Electrical Readings'!$P$6:$P$966,1+(2*(ROWS(E$1:E14)-1))) -> 2710 | R14: =INDEX('9 - Water Readings'!$C$8:$C$970,1+(2*(ROWS(A$1:A13)-1))) -> 0 | S14: =INDEX('9 - Water Readings'!$D$8:$D$969,1+(2*(ROWS(A$1:A13)-1))) -> 0 | T14: =INDEX('9 - Water Readings'!$E$8:$E$970,1+(2*(ROWS(A$1:A13)-1))) -> 0 | U14: =INDEX('9 - Water Readings'!$G$8:$G$969,1+(2*(ROWS(A$1:A13)-1))) -> 106 | V14: =INDEX('9 - Water Readings'!$H$8:$H$970,1+(2*(ROWS(A$1:A13)-1))) -> 14 | W14: =INDEX('9 - Water Readings'!$I$8:$I$970,1+(2*(ROWS(A$1:A13)-1))) -> 57 | X14: =INDEX('9 - Water Readings'!$J$8:$J$970,1+(2*(ROWS(A$1:A13)-1))) -> 305 | Y14: =INDEX('9 - Water Readings'!$K$8:$K$970,1+(2*(ROWS(A$1:A13)-1))) -> 0 | Z14: =INDEX('9 - Water Readings'!$L$8:$L$970,1+(2*(ROWS(A$1:A13)-1))) -> 0 | AA14: ='9 - Water Readings'!Q19 -> 168 | AB14: ='9 - Water Readings'!R19 -> 628 | AC14: ='9 - Water Readings'!S19 -> 12.4
... A31: Doha | B31: =B30+1 -> 30 | C31: 5 | D31: 2022 | E31: =INDEX('13 - Electrical Readings'!$C$8:$C$966,1+(2*(ROWS(A$1:A30)-1))) -> 8 | F31: =INDEX('13 - Electrical Readings'!$D$6:$D$966,1+(2*(ROWS(A$1:A31)-1))) -> 11400 | G31: =INDEX('13 - Electrical Readings'!$E$6:$E$966,1+(2*(ROWS(A$1:A31)-1))) -> 11017 | H31: =INDEX('13 - Electrical Readings'!$F$6:$F$966,1+(2*(ROWS(A$1:A31)-1))) -> 4190 | I31: =INDEX('13 - Electrical Readings'!$G$6:$G$966,1+(2*(ROWS(A$1:A31)-1))) -> 18 | J31: =INDEX('13 - Electrical Readings'!$I$6:$I$966,1+(2*(ROWS(A$1:A31)-1))) -> 2083 | K31: =INDEX('13 - Electrical Readings'!$J$6:$J$966,1+(2*(ROWS(B$1:B31)-1))) -> 8217 | L31: =INDEX('13 - Electrical Readings'!$K$6:$K$966,1+(2*(ROWS(C$1:C31)-1))) -> 3538 | M31: =INDEX('13 - Electrical Readings'!$L$6:$L$966,1+(2*(ROWS(D$1:D31)-1))) -> 4314 | N31: =INDEX('13 - Electrical Readings'!$M$6:$M$966,1+(2*(ROWS(E$1:E31)-1))) -> 6863 | O31: =INDEX('13 - Electrical Readings'!$N$6:$N$966,1+(2*(ROWS(E$1:E31)-1))) -> 8800 | P31: =INDEX('13 - Electrical Readings'!$O$6:$O$966,1+(2*(ROWS(E$1:E31)-1))) -> 3163 | Q31: =INDEX('13 - Electrical Readings'!$P$6:$P$966,1+(2*(ROWS(E$1:E31)-1))) -> 2460 | R31: =INDEX('9 - Water Readings'!$C$8:$C$970,1+(2*(ROWS(A$1:A30)-1))) -> 1 | S31: =INDEX('9 - Water Readings'!$D$8:$D$969,1+(2*(ROWS(A$1:A30)-1))) -> 1 | T31: =INDEX('9 - Water Readings'!$E$8:$E$970,1+(2*(ROWS(A$1:A30)-1))) -> 0 | U31: =INDEX('9 - Water Readings'!$G$8:$G$969,1+(2*(ROWS(A$1:A30)-1))) -> 101 | V31: =INDEX('9 - Water Readings'!$H$8:$H$970,1+(2*(ROWS(A$1:A30)-1))) -> 11 | W31: =INDEX('9 - Water Readings'!$I$8:$I$970,1+(2*(ROWS(A$1:A30)-1))) -> 44 | X31: =INDEX('9 - Water Readings'!$J$8:$J$970,1+(2*(ROWS(A$1:A30)-1))) -> 272 | Y31: =INDEX('9 - Water Readings'!$K$8:$K$970,1+(2*(ROWS(A$1:A30)-1))) -> 0 | Z31: =INDEX('9 - Water Readings'!$L$8:$L$970,1+(2*(ROWS(A$1:A30)-1))) -> 0 | AA31: ='9 - Water Readings'!Q36 -> 105 | AB31: ='9 - Water Readings'!R36 -> 298 | AC31: ='9 - Water Readings'!S36 -> 17.5
B32: =B31+1 -> 31 | C32: 5 | D32: 2022 | E32: =INDEX('13 - Electrical Readings'!$C$8:$C$966,1+(2*(ROWS(A$1:A31)-1))) -> 6 | F32: =INDEX('13 - Electrical Readings'!$D$6:$D$966,1+(2*(ROWS(A$1:A32)-1))) -> 12354 | G32: =INDEX('13 - Electrical Readings'!$E$6:$E$966,1+(2*(ROWS(A$1:A32)-1))) -> 12335 | H32: =INDEX('13 - Electrical Readings'!$F$6:$F$966,1+(2*(ROWS(A$1:A32)-1))) -> 4479 | I32: =INDEX('13 - Electrical Readings'!$G$6:$G$966,1+(2*(ROWS(A$1:A32)-1))) -> 17 | J32: =INDEX('13 - Electrical Readings'!$I$6:$I$966,1+(2*(ROWS(A$1:A32)-1))) -> 1966 | K32: =INDEX('13 - Electrical Readings'!$J$6:$J$966,1+(2*(ROWS(B$1:B32)-1))) -> 8463 | L32: =INDEX('13 - Electrical Readings'!$K$6:$K$966,1+(2*(ROWS(C$1:C32)-1))) -> 3635 | M32: =INDEX('13 - Electrical Readings'!$L$6:$L$966,1+(2*(ROWS(D$1:D32)-1))) -> 4289 | N32: =INDEX('13 - Electrical Readings'!$M$6:$M$966,1+(2*(ROWS(E$1:E32)-1))) -> 8301 | O32: =INDEX('13 - Electrical Readings'!$N$6:$N$966,1+(2*(ROWS(E$1:E32)-1))) -> 8676 | P32: =INDEX('13 - Electrical Readings'!$O$6:$O$966,1+(2*(ROWS(E$1:E32)-1))) -> 3083 | Q32: =INDEX('13 - Electrical Readings'!$P$6:$P$966,1+(2*(ROWS(E$1:E32)-1))) -> 2560 | R32: =INDEX('9 - Water Readings'!$C$8:$C$970,1+(2*(ROWS(A$1:A31)-1))) -> 0 | S32: =INDEX('9 - Water Readings'!$D$8:$D$969,1+(2*(ROWS(A$1:A31)-1))) -> 0 | T32: =INDEX('9 - Water Readings'!$E$8:$E$970,1+(2*(ROWS(A$1:A31)-1))) -> 0 | U32: =INDEX('9 - Water Readings'!$G$8:$G$969,1+(2*(ROWS(A$1:A31)-1))) -> 100 | V32: =INDEX('9 - Water Readings'!$H$8:$H$970,1+(2*(ROWS(A$1:A31)-1))) -> 11 | W32: =INDEX('9 - Water Readings'!$I$8:$I$970,1+(2*(ROWS(A$1:A31)-1))) -> 54 | X32: =INDEX('9 - Water Readings'!$J$8:$J$970,1+(2*(ROWS(A$1:A31)-1))) -> 261 | Y32: =INDEX('9 - Water Readings'!$K$8:$K$970,1+(2*(ROWS(A$1:A31)-1))) -> 0 | Z32: =INDEX('9 - Water Readings'!$L$8:$L$970,1+(2*(ROWS(A$1:A31)-1))) -> 0 | AA32: ='9 - Water Readings'!Q37 -> 137 | AB32: ='9 - Water Readings'!R37 -> 368 | AC32: ='9 - Water Readings'!S37 -> 14.5

Sheet 13 - Electrical Readings
F2: Central Plant Engineering
F3: Daily Electrical Meter Readings | N3: Month: MAY- 2022
B5: Date | C5: CP Chillers | D5: CP Chillers | E5: CP Chillers | F5: CP Chillers | G5: CP Chillers | H5: CP Total kWh | I5: Town House | J5: Hotel | K5: Hotel | L5: Hotel | M5: Hotel | N5: Spa | O5: Marina | P5: Nobu | Q5: Hotel Total kWh | R5: Grand Total kWh
C6: 157691 | D6: 157692 | E6: 157693 | F6: 157694 | G6: 167609 | I6: 166443 | J6: 157687 | K6: 157688 | L6: 157689 | M6: 157690 | N6: 174390 | O6: 173992 | P6: 1180004
B7: 1 | C7: 20248324 | D7: 14568398 | E7: 26559577 | F7: 26752906 | G7: 16683977 | I7: 5963519 | J7: 26305592 | K7: 8655237 | L7: 12990435 | M7: 19209654 | N7: 25015183 | O7: 8002554 | P7: 7279190
B8: Consumption | C8: 8693 | D8: 11682 | E8: 3284 | F8: 4056 | G8: 16 | H8: 27731 | I8: 1963 | J8: 9876 | K8: 3158 | L8: 4517 | M8: 7232 | N8: 7006 | O8: 2708 | P8: 2560 | Q8: =P8+O8+N8+M8+L8+K8+J8+I8 -> 39020 | R8: =Q8+H8 -> 66751
B9: 2 | C9: 20267257 | D9: 14573470 | E9: 26562795 | F9: 26757199 | G9: 16683990 | I9: 5965323 | J9: 26311682 | K9: 8658711 | L9: 12995096 | M9: 19217041 | N9: 25022651 | O9: 8005003 | P9: 7281470
B10: Consumption | C10: =+C9-C7 -> 18933 | D10: =+D9-D7 -> 5072 | E10: =+E9-E7 -> 3218 | F10: =+F9-F7 -> 4293 | G10: =+G9-G7 -> 13 | H10: =G10+F10+E10+D10+C10 -> 31529 | I10: =I9-I7 -> 1804 | J10: =J9-J7 -> 6090 | K10: =K9-K7 -> 3474 | L10: =L9-L7 -> 4661 | M10: =M9-M7 -> 7387 | N10: =N9-N7 -> 7468 | O10: =O9-O7 -> 2449 | Q10: =P10+O10+N10+M10+L10+K10+J10+I10 -> 33333 | R10: =Q10+H10 -> 64862
B11: 3 | C11: 20286954 | D11: 14576355 | E11: 26565610 | F11: 26761166 | G11: 16684004 | I11: 5967252 | J11: 26319695 | K11: 8662049 | L11: 12999858 | M11: 19224019 | N11: 25030309 | O11: 8007753 | P11: 7284110
B12: Consumption | C12: =+C11-C9 -> 19697 | D12: =+D11-D9 -> 2885 | E12: =+E11-E9 -> 2815 | F12: =+F11-F9 -> 3967 | G12: =+G11-G9 -> 14 | H12: =G12+F12+E12+D12+C12 -> 29378 | I12: =I11-I9 -> 1929 | J12: =J11-J9 -> 8013 | K12: =K11-K9 -> 3338 | L12: =L11-L9 -> 4762 | M12: =M11-M9 -> 6978 | N12: =N11-N9 -> 7658 | O12: =O11-O9 -> 2750 | P12: =P11-P9 -> 2640 | Q12: =P12+O12+N12+M12+L12+K12+J12+I12 -> 38068 | R12: =Q12+H12 -> 67446
B13: 4 | C13: 20306063 | D13: 14579412 | E13: 26568420 | F13: 26765096 | G13: 16684016 | I13: 5969171 | J13: 26327578 | K13: 8665154 | L13: 13004409 | M13: 19230795 | N13: 25038460 | O13: 8010426 | P13: 7286750
B14: Consumption | C14: =+C13-C11 -> 19109 | D14: =+D13-D11 -> 3057 | E14: =+E13-E11 -> 2810 | F14: =+F13-F11 -> 3930 | G14: =+G13-G11 -> 12 | H14: =G14+F14+E14+D14+C14 -> 28918 | I14: =I13-I11 -> 1919 | J14: =J13-J11 -> 7883 | K14: =K13-K11 -> 3105 | L14: =L13-L11 -> 4551 | M14: =M13-M11 -> 6776 | N14: =N13-N11 -> 8151 | O14: =O13-O11 -> 2673 | P14: =P13-P11 -> 2640 | Q14: =P14+O14+N14+M14+L14+K14+J14+I14 -> 37698 | R14: =Q14+H14 -> 66616
B15: 5 | C15: 20323551 | D15: 14587492 | E15: 26572186 | F15: 26769123 | G15: 16684028 | I15: 5971001 | J15: 26335038 | K15: 8668486 | L15: 13009173 | M15: 19238149 | N15: 25046911 | O15: 8014010 | P15: 7289380
B16: Consumption | C16: =+C15-C13 -> 17488 | D16: =+D15-D13 -> 8080 | E16: =+E15-E13 -> 3766 | F16: =+F15-F13 -> 4027 | G16: =+G15-G13 -> 12 | H16: =G16+F16+E16+D16+C16 -> 33373 | I16: =I15-I13 -> 1830 | J16: =J15-J13 -> 7460 | K16: =K15-K13 -> 3332 | L16: =L15-L13 -> 4764 | M16: =M15-M13 -> 7354 | N16: =N15-N13 -> 8451 | O16: =O15-O13 -> 3584 | P16: =P15-P13 -> 2630 | Q16: =P16+O16+N16+M16+L16+K16+J16+I16 -> 39405 | R16: =Q16+H16 -> 72778
B17: 6 | C17: 20343277 | D17: 14595666 | E17: 26575862 | F17: 26773438 | G17: 16684042 | I17: 5972880 | J17: 26342020 | K17: 8671943 | L17: 13013689 | M17: 19245519 | N17: 25055038 | O17: 8016597 | P17: 7292250
B18: Consumption | C18: =+C17-C15 -> 19726 | D18: =+D17-D15 -> 8174 | E18: =+E17-E15 -> 3676 | F18: =+F17-F15 -> 4315 | G18: =+G17-G15 -> 14 | H18: =G18+F18+E18+D18+C18 -> 35905 | I18: =I17-I15 -> 1879 | J18: =J17-J15 -> 6982 | K18: =K17-K15 -> 3457 | L18: =L17-L15 -> 4516 | M18: =M17-M15 -> 7370 | N18: =N17-N15 -> 8127 | O18: =O17-O15 -> 2587 | P18: =P17-P15 -> 2870 | Q18: =P18+O18+N18+M18+L18+K18+J18+I18 -> 37788 | R18: =Q18+H18 -> 73693
B19: 7 | C19: 20360525 | D19: 14605011 | E19: 26580721 | F19: 26778123 | G19: 16684056 | I19: 5974751 | J19: 26348990 | K19: 8675277 | L19: 13018221 | M19: 19253128 | N19: 25063310 | O19: 8019639 | P19: 7294730
B20: Consumption | C20: =+C19-C17 -> 17248 | D20: =+D19-D17 -> 9345 | E20: =+E19-E17 -> 4859 | F20: =+F19-F17 -> 4685 | G20: =+G19-G17 -> 14 | H20: =G20+F20+E20+D20+C20 -> 36151 | I20: =I19-I17 -> 1871 | J20: =J19-J17 -> 6970 | K20: =K19-K17 -> 3334 | L20: =L19-L17 -> 4532 | M20: =M19-M17 -> 7609 | N20: =N19-N17 -> 8272 | O20: =O19-O17 -> 3042 | P20: =P19-P17 -> 2480 | Q20: =P20+O20+N20+M20+L20+K20+J20+I20 -> 38110 | R20: =Q20+H20 -> 74261
B21: 8 | C21: 20371946 | D21: 14605985 | E21: 26588774 | F21: 26782543 | G21: 16693532 | I21: 5976641 | J21: 26355964 | K21: 8678797 | L21: 13022811 | M21: 19260416 | N21: 25071606 | O21: 8023014 | P21: 7296930
B22: Consumption | C22: =+C21-C19 -> 11421 | D22: =+D21-D19 -> 974 | E22: =+E21-E19 -> 8053 | F22: =+F21-F19 -> 4420 | G22: =+G21-G19 -> 9476 | H22: =G22+F22+E22+D22+C22 -> 34344 | I22: =I21-I19 -> 1890 | J22: =J21-J19 -> 6974 | K22: =K21-K19 -> 3520 | L22: =L21-L19 -> 4590 | M22: =M21-M19 -> 7288 | N22: =N21-N19 -> 8296 | O22: =O21-O19 -> 3375 | P22: =P21-P19 -> 2200 | Q22: =P22+O22+N22+M22+L22+K22+J22+I22 -> 38133 | R22: =Q22+H22 -> 72477
B23: 9 | C23: 20375227 | D23: 14606801 | E23: 26591689 | F23: 26786136 | G23: 16712329 | I23: 5978688 | J23: 26363681 | K23: 8682572 | L23: 13027940 | M23: 19267618 | N23: 25079970 | O23: 8026302 | P23: 7299440
B24: Consumption | C24: =+C23-C21 -> 3281 | D24: =+D23-D21 -> 816 | E24: =+E23-E21 -> 2915 | F24: =+F23-F21 -> 3593 | G24: =+G23-G21 -> 18797 | H24: =G24+F24+E24+D24+C24 -> 29402 | I24: =I23-I21 -> 2047 | J24: =J23-J21 -> 7717 | K24: =K23-K21 -> 3775 | L24: =L23-L21 -> 5129 | M24: =M23-M21 -> 7202 | N24: =N23-N21 -> 8364 | O24: =O23-O21 -> 3288 | P24: =P23-P21 -> 2510 | Q24: =P24+O24+N24+M24+L24+K24+J24+I24 -> 40032 | R24: =Q24+H24 -> 69434
B25: 10 | C25: 20381027 | D25: 14607563 | E25: 26595008 | F25: 26789462 | G25: 16728996 | I25: 5980597 | J25: 26370737 | K25: 8685759 | L25: 13032106 | M25: 19273953 | N25: 25087577 | O25: 8029353 | P25: 7301890
B26: Consumption | C26: =+C25-C23 -> 5800 | D26: =+D25-D23 -> 762 | E26: =+E25-E23 -> 3319 | F26: =+F25-F23 -> 3326 | G26: =+G25-G23 -> 16667 | H26: =G26+F26+E26+D26+C26 -> 29874 | I26: =I25-I23 -> 1909 | J26: =J25-J23 -> 7056 | K26: =K25-K23 -> 3187 | L26: =L25-L23 -> 4166 | M26: =M25-M23 -> 6335 | N26: =N25-N23 -> 7607 | O26: =O25-O23 -> 3051 | P26: =P25-P23 -> 2450 | Q26: =P26+O26+N26+M26+L26+K26+J26+I26 -> 35761 | R26: =Q26+H26 -> 65635
B27: 11 | C27: 20386903 | D27: 14608337 | E27: 26598332 | F27: 26792947 | G27: 16746793 | I27: 5982669 | J27: 26378418 | K27: 8689397 | L27: 13036711 | M27: 19280850 | N27: 25095894 | O27: 8032667 | P27: 7304390
B28: Consumption | C28: =+C27-C25 -> 5876 | D28: =+D27-D25 -> 774 | E28: =+E27-E25 -> 3324 | F28: =+F27-F25 -> 3485 | G28: =+G27-G25 -> 17797 | H28: =G28+F28+E28+D28+C28 -> 31256 | I28: =I27-I25 -> 2072 | J28: =J27-J25 -> 7681 | K28: =K27-K25 -> 3638 | L28: =L27-L25 -> 4605 | M28: =M27-M25 -> 6897 | N28: =N27-N25 -> 8317 | O28: =O27-O25 -> 3314 | P28: =P27-P25 -> 2500 | Q28: =P28+O28+N28+M28+L28+K28+J28+I28 -> 39024 | R28: =Q28+H28 -> 70280
B29: 12 | C29: 20394091 | D29: 14609126 | E29: 26601842 | F29: 26796369 | G29: 16764366 | I29: 5984683 | J29: 26386019 | K29: 8693081 | L29: 13041296 | M29: 19287434 | N29: 25104220 | O29: 8036181 | P29: 7306790
B30: Consumption | C30: =+C29-C27 -> 7188 | D30: =+D29-D27 -> 789 | E30: =+E29-E27 -> 3510 | F30: =+F29-F27 -> 3422 | G30: =+G29-G27 -> 17573 | H30: =G30+F30+E30+D30+C30 -> 32482 | I30: =I29-I27 -> 2014 | J30: =J29-J27 -> 7601 | K30: =K29-K27 -> 3684 | L30: =L29-L27 -> 4585 | M30: =M29-M27 -> 6584 | N30: =N29-N27 -> 8326 | O30: =O29-O27 -> 3514 | P30: =P29-P27 -> 2400 | Q30: =P30+O30+N30+M30+L30+K30+J30+I30 -> 38708 | R30: =Q30+H30 -> 71190
B31: 13 | C31: 20405189 | D31: 14609927 | E31: 26606049 | F31: 26800044 | G31: 16780250 | I31: 5986761 | J31: 26393707 | K31: 8696558 | L31: 13045978 | M31: 19294267 | N31: 25112618 | O31: 8039436 | P31: 7309500
B32: Consumption | C32: =+C31-C29 -> 11098 | D32: =+D31-D29 -> 801 | E32: =+E31-E29 -> 4207 | F32: =+F31-F29 -> 3675 | G32: =+G31-G29 -> 15884 | H32: =G32+F32+E32+D32+C32 -> 35665 | I32: =I31-I29 -> 2078 | J32: =J31-J29 -> 7688 | K32: =K31-K29 -> 3477 | L32: =L31-L29 -> 4682 | M32: =M31-M29 -> 6833 | N32: =N31-N29 -> 8398 | O32: =O31-O29 -> 3255 | P32: =P31-P29 -> 2710 | Q32: =P32+O32+N32+M32+L32+K32+J32+I32 -> 39121 | R32: =Q32+H32 -> 74786
B33: 14 | C33: 20410570 | D33: 14610754 | E33: 26609304 | F33: 26803423 | G33: 16798456 | I33: 5988726 | J33: 26401172 | K33: 8699815 | L33: 13050434 | M33: 19301313 | N33: 25120582 | O33: 8042707 | P33: 7311770
B34: Consumption | C34: =+C33-C31 -> 5381 | D34: =+D33-D31 -> 827 | E34: =+E33-E31 -> 3255 | F34: =+F33-F31 -> 3379 | G34: =+G33-G31 -> 18206 | H34: =G34+F34+E34+D34+C34 -> 31048 | I34: =I33-I31 -> 1965 | J34: =J33-J31 -> 7465 | K34: =K33-K31 -> 3257 | L34: =L33-L31 -> 4456 | M34: =M33-M31 -> 7046 | N34: =N33-N31 -> 7964 | O34: =O33-O31 -> 3271 | P34: =P33-P31 -> 2270 | Q34: =P34+O34+N34+M34+L34+K34+J34+I34 -> 37694 | R34: =Q34+H34 -> 68742
B35: 15 | C35: 20413515 | D35: 14611568 | E35: 26613420 | F35: 26812676 | G35: 16816070 | I35: 5990232 | J35: 26408726 | K35: 8703175 | L35: 13054608 | M35: 19310844 | N35: 25128630 | O35: 8045500 | P35: 7313820
B36: Consumption | C36: =+C35-C33 -> 2945 | D36: =+D35-D33 -> 814 | E36: =+E35-E33 -> 4116 | F36: =+F35-F33 -> 9253 | G36: =+G35-G33 -> 17614 | H36: =G36+F36+E36+D36+C36 -> 34742 | I36: =I35-I33 -> 1506 | J36: =J35-J33 -> 7554 | K36: =K35-K33 -> 3360 | L36: =L35-L33 -> 4174 | M36: =M35-M33 -> 9531 | N36: =N35-N33 -> 8048 | O36: =O35-O33 -> 2793 | P36: =P35-P33 -> 2050 | Q36: =P36+O36+N36+M36+L36+K36+J36+I36 -> 39016 | R36: =Q36+H36 -> 73758
B37: 16 | C37: 20422175 | D37: 14612523 | E37: 26617413 | F37: 26827869 | G37: 16817216 | I37: 5991711 | J37: 26416715 | K37: 8706611 | L37: 13059033 | M37: 19320009 | N37: 25136836 | O37: 8048964 | P37: 7316300
B38: Consumption | C38: =+C37-C35 -> 8660 | D38: =+D37-D35 -> 955 | E38: =+E37-E35 -> 3993 | F38: =+F37-F35 -> 15193 | G38: =+G37-G35 -> 1146 | H38: =G38+F38+E38+D38+C38 -> 29947 | I38: =I37-I35 -> 1479 | J38: =J37-J35 -> 7989 | K38: =K37-K35 -> 3436 | L38: =L37-L35 -> 4425 | M38: =M37-M35 -> 9165 | N38: =N37-N35 -> 8206 | O38: =O37-O35 -> 3464 | P38: =P37-P35 -> 2480 | Q38: =P38+O38+N38+M38+L38+K38+J38+I38 -> 40644 | R38: =Q38+H38 -> 70591
B39: 17 | C39: 20430745 | D39: 14613320 | E39: 26621207 | F39: 26842094 | G39: 16817229 | I39: 5993106 | J39: 26423504 | K39: 8709831 | L39: 13063326 | M39: 19326888 | N39: 25144672 | O39: 8052087 | P39: 7318940
B40: Consumption | C40: =+C39-C37 -> 8570 | D40: =+D39-D37 -> 797 | E40: =+E39-E37 -> 3794 | F40: =+F39-F37 -> 14225 | G40: =+G39-G37 -> 13 | H40: =G40+F40+E40+D40+C40 -> 27399 | I40: =I39-I37 -> 1395 | J40: =J39-J37 -> 6789 | K40: =K39-K37 -> 3220 | L40: =L39-L37 -> 4293 | M40: =M39-M37 -> 6879 | N40: =N39-N37 -> 7836 | O40: =O39-O37 -> 3123 | P40: =P39-P37 -> 2640 | Q40: =P40+O40+N40+M40+L40+K40+J40+I40 -> 36175 | R40: =Q40+H40 -> 63574
B41: 18 | C41: 20439700 | D41: 14614085 | E41: 26624921 | F41: 26857271 | G41: 16817242 | I41: 5994625 | J41: 26430887 | K41: 8713218 | L41: 13067871 | M41: 19334653 | N41: 25153109 | O41: 8055792 | P41: 7321220
B42: Consumption | C42: =+C41-C39 -> 8955 | D42: =+D41-D39 -> 765 | E42: =+E41-E39 -> 3714 | F42: =+F41-F39 -> 15177 | G42: =+G41-G39 -> 13 | H42: =G42+F42+E42+D42+C42 -> 28624 | I42: =I41-I39 -> 1519 | J42: =J41-J39 -> 7383 | K42: =K41-K39 -> 3387 | L42: =L41-L39 -> 4545 | M42: =M41-M39 -> 7765 | N42: =N41-N39 -> 8437 | O42: =O41-O39 -> 3705 | P42: =P41-P39 -> 2280 | Q42: =P42+O42+N42+M42+L42+K42+J42+I42 -> 39021 | R42: =Q42+H42 -> 67645
...

Sheet 9 - Water Readings
F2: Central Plant Engineering
F3: Daily Water Meter Readings | M3: Month: MAY- 2022
B5: Date | C5: CP F/F | D5: CP Chillers | E5: CP Parking | F5: CP Total M3 | G5: Town House | H5: Spa B | I5: Spa A | J5: CW Hotel A | K5: CCW Hotel B | L5: Marina | M5: Hotel Total M3 | N5: Grand Total M3 | P5: Day | Q5: Room Nights | R5: Total Guests | S5: Cooling Degree Day
C6: 130465 | D6: 130460 | E6: 130461 | G6: 130464 | H6: 130456 | I6: 130457 | J6: 130458 | K6: 130459 | L6: 130466 | T6: Following Meters are not working
B7: 1 | C7: 8203 | D7: 490 | E7: 46762 | G7: 269082 | H7: 164299 | I7: 174438 | J7: 839532 | K7: 639094 | L7: 445642 | P7: 1 | Q7: 50 | R7: 212 | S7: 9.1 | T7: 130461 | U7: CP Parking
B8: Consumption | C8: 0 | D8: 0 | E8: 0 | F8: =E8+D8+C8 -> 0 | G8: 98 | H8: 14 | I8: 25 | J8: 229 | K8: 0 | L8: 0 | M8: =L8+K8+J8+I8+H8+G8 -> 366 | N8: =M8+F8 -> 366 | P8: 2 | Q8: 84 | R8: 358 | S8: 9.9 | T8: 130459 | U8: CCW Hotel B
B9: 2 | C9: 8203 | D9: 490 | E9: 46762 | G9: 269188 | H9: 164309 | I9: 174480 | J9: 839788 | K9: 639094 | L9: 445642 | P9: 3 | Q9: 148 | R9: 644 | S9: 11 | T9: 130466 | U9: Marina
B10: Consumption | C10: =+C9-C7 -> 0 | D10: =+D9-D7 -> 0 | E10: =+E9-E7 -> 0 | F10: =E10+D10+C10 -> 0 | G10: =G9-G7 -> 106 | H10: =H9-H7 -> 10 | I10: =I9-I7 -> 42 | J10: =J9-J7 -> 256 | K10: =K9-K7 -> 0 | L10: =L9-L7 -> 0 | M10: =L10+K10+J10+I10+H10+G10 -> 414 | N10: =M10+F10 -> 414 | P10: 4 | Q10: 182 | R10: 808 | S10: 13.7
B11: 3 | C11: 8203 | D11: 490 | E11: 46762 | G11: 269290 | H11: 164381 | I11: 174527 | J11: 840077 | K11: 639094 | L11: 445642 | P11: 5 | Q11: 198 | R11: 880 | S11: 12.4
B12: Consumption | C12: =+C11-C9 -> 0 | D12: =+D11-D9 -> 0 | E12: =+E11-E9 -> 0 | F12: =E12+D12+C12 -> 0 | G12: =G11-G9 -> 102 | H12: =H11-H9 -> 72 | I12: =I11-I9 -> 47 | J12: =J11-J9 -> 289 | K12: =K11-K9 -> 0 | L12: =L11-L9 -> 0 | M12: =L12+K12+J12+I12+H12+G12 -> 510 | N12: =M12+F12 -> 510 | P12: 6 | Q12: 172 | R12: 732 | S12: 12.5
B13: 4 | C13: 8203 | D13: 491 | E13: 46762 | G13: 269392 | H13: 164401 | I13: 174579 | J13: 840376 | K13: 639094 | L13: 445642 | P13: 7 | Q13: 215 | R13: 922 | S13: 11
B14: Consumption | C14: =+C13-C11 -> 0 | D14: =+D13-D11 -> 1 | E14: =+E13-E11 -> 0 | F14: =E14+D14+C14 -> 1 | G14: =G13-G11 -> 102 | H14: =H13-H11 -> 20 | I14: =I13-I11 -> 52 | J14: =J13-J11 -> 299 | K14: =K13-K11 -> 0 | L14: =L13-L11 -> 0 | M14: =L14+K14+J14+I14+H14+G14 -> 473 | N14: =M14+F14 -> 474 | P14: 8 | Q14: 201 | R14: 840 | S14: 11
B15: 5 | C15: 8203 | D15: 491 | E15: 46762 | G15: 269501 | H15: 164418 | I15: 174631 | J15: 840699 | K15: 639094 | L15: 445642 | P15: 9 | Q15: 140 | R15: 442 | S15: 10
B16: Consumption | C16: =+C15-C13 -> 0 | D16: =+D15-D13 -> 0 | E16: =+E15-E13 -> 0 | F16: =E16+D16+C16 -> 0 | G16: =G15-G13 -> 109 | H16: =H15-H13 -> 17 | I16: =I15-I13 -> 52 | J16: =J15-J13 -> 323 | K16: =K15-K13 -> 0 | L16: =L15-L13 -> 0 | M16: =L16+K16+J16+I16+H16+G16 -> 501 | N16: =M16+F16 -> 501 | P16: 10 | Q16: 144 | R16: 206 | S16: 10.6
B17: 6 | C17: 8203 | D17: 491 | E17: 46762 | G17: 269601 | H17: 164437 | I17: 174690 | J17: 841011 | K17: 639094 | L17: 445642 | P17: 11 | Q17: 151 | R17: 440 | S17: 13.2
B18: Consumption | C18: =+C17-C15 -> 0 | D18: =+D17-D15 -> 0 | E18: =+E17-E15 -> 0 | F18: =E18+D18+C18 -> 0 | G18: =G17-G15 -> 100 | H18: =H17-H15 -> 19 | I18: =I17-I15 -> 59 | J18: =J17-J15 -> 312 | K18: =K17-K15 -> 0 | L18: =L17-L15 -> 0 | M18: =L18+K18+J18+I18+H18+G18 -> 490 | N18: =M18+F18 -> 490 | P18: 12 | Q18: 163 | R18: 574 | S18: 13.6
B19: 7 | C19: 8203 | D19: 491 | E19: 46762 | G19: 269707 | H19: 164452 | I19: 174746 | J19: 841308 | K19: 639094 | L19: 445642 | P19: 13 | Q19: 168 | R19: 628 | S19: 12.4
B20: Consumption | C20: =+C19-C17 -> 0 | D20: =+D19-D17 -> 0 | E20: =+E19-E17 -> 0 | F20: =E20+D20+C20 -> 0 | G20: =G19-G17 -> 106 | H20: =H19-H17 -> 15 | I20: =I19-I17 -> 56 | J20: =J19-J17 -> 297 | K20: =K19-K17 -> 0 | L20: =L19-L17 -> 0 | M20: =L20+K20+J20+I20+H20+G20 -> 474 | N20: =M20+F20 -> 474 | P20: 14 | Q20: 125 | R20: 382 | S20: 10.4
B21: 8 | C21: 8203 | D21: 491 | E21: 46762 | G21: 269807 | H21: 164469 | I21: 174776 | J21: 841608 | K21: 639094 | L21: 445642 | P21: 15 | Q21: 124 | R21: 346 | S21: 10.3
B22: Consumption | C22: =+C21-C19 -> 0 | D22: =+D21-D19 -> 0 | E22: =+E21-E19 -> 0 | F22: =E22+D22+C22 -> 0 | G22: =G21-G19 -> 100 | H22: =H21-H19 -> 17 | I22: =I21-I19 -> 30 | J22: =J21-J19 -> 300 | K22: =K21-K19 -> 0 | L22: =L21-L19 -> 0 | M22: =L22+K22+J22+I22+H22+G22 -> 447 | N22: =M22+F22 -> 447 | P22: 16 | Q22: 133 | R22: 384 | S22: 11.9
B23: 9 | C23: 8203 | D23: 491 | E23: 46762 | G23: 269925 | H23: 164484 | I23: 174830 | J23: 841908 | K23: 639094 | L23: 445642 | P23: 17 | Q23: 142 | R23: 396 | S23: 12.2
B24: Consumption | C24: =+C23-C21 -> 0 | D24: =+D23-D21 -> 0 | E24: =+E23-E21 -> 0 | F24: =E24+D24+C24 -> 0 | G24: =G23-G21 -> 118 | H24: =H23-H21 -> 15 | I24: =I23-I21 -> 54 | J24: =J23-J21 -> 300 | K24: =K23-K21 -> 0 | L24: =L23-L21 -> 0 | M24: =L24+K24+J24+I24+H24+G24 -> 487 | N24: =M24+F24 -> 487 | P24: 18 | Q24: 115 | R24: 332 | S24: 15.4
B25: 10 | C25: 8203 | D25: 491 | E25: 46762 | G25: 270033 | H25: 164496 | I25: 174879 | J25: 842158 | K25: 639094 | L25: 445642 | P25: 19 | Q25: 142 | R25: 480 | S25: 16.5
B26: Consumption | C26: =+C25-C23 -> 0 | D26: =+D25-D23 -> 0 | E26: =+E25-E23 -> 0 | F26: =E26+D26+C26 -> 0 | G26: =G25-G23 -> 108 | H26: =H25-H23 -> 12 | I26: =I25-I23 -> 49 | J26: =J25-J23 -> 250 | K26: =K25-K23 -> 0 | L26: =L25-L23 -> 0 | M26: =L26+K26+J26+I26+H26+G26 -> 419 | N26: =M26+F26 -> 419 | P26: 20 | Q26: 147 | R26: 544 | S26: 18
B27: 11 | C27: 8203 | D27: 491 | E27: 46762 | G27: 270140 | H27: 164508 | I27: 174928 | J27: 842432 | K27: 639094 | L27: 445642 | P27: 21 | Q27: 150 | R27: 468 | S27: 18.4
B28: Consumption | C28: =+C27-C25 -> 0 | D28: =+D27-D25 -> 0 | E28: =+E27-E25 -> 0 | F28: =E28+D28+C28 -> 0 | G28: =G27-G25 -> 107 | H28: =H27-H25 -> 12 | I28: =I27-I25 -> 49 | J28: =J27-J25 -> 274 | K28: =K27-K25 -> 0 | L28: =L27-L25 -> 0 | M28: =L28+K28+J28+I28+H28+G28 -> 442 | N28: =M28+F28 -> 442 | P28: 22 | Q28: 115 | R28: 288 | S28: 15.6
B29: 12 | C29: 8203 | D29: 491 | E29: 46762 | G29: 270248 | H29: 164521 | I29: 174979 | J29: 842756 | K29: 639094 | L29: 445642 | P29: 23 | Q29: 151 | R29: 394 | S29: 12.2
B30: Consumption | C30: =+C29-C27 -> 0 | D30: =+D29-D27 -> 0 | E30: =+E29-E27 -> 0 | F30: =E30+D30+C30 -> 0 | G30: =G29-G27 -> 108 | H30: =H29-H27 -> 13 | I30: =I29-I27 -> 51 | J30: =J29-J27 -> 324 | K30: =K29-K27 -> 0 | L30: =L29-L27 -> 0 | M30: =L30+K30+J30+I30+H30+G30 -> 496 | N30: =M30+F30 -> 496 | P30: 24 | Q30: 109 | R30: 276 | S30: 11.9
B31: 13 | C31: 8203 | D31: 491 | E31: 46762 | G31: 270354 | H31: 164535 | I31: 175036 | J31: 843061 | K31: 639094 | L31: 445642 | P31: 25 | Q31: 111 | R31: 328 | S31: 12.6
B32: Consumption | C32: =+C31-C29 -> 0 | D32: =+D31-D29 -> 0 | E32: =+E31-E29 -> 0 | F32: =E32+D32+C32 -> 0 | G32: =G31-G29 -> 106 | H32: =H31-H29 -> 14 | I32: =I31-I29 -> 57 | J32: =J31-J29 -> 305 | K32: =K31-K29 -> 0 | L32: =L31-L29 -> 0 | M32: =L32+K32+J32+I32+H32+G32 -> 482 | N32: =M32+F32 -> 482 | P32: 26 | Q32: 164 | R32: 580 | S32: 14.3
B33: 14 | C33: 8203 | D33: 491 | E33: 46762 | G33: 270458 | H33: 164547 | I33: 175086 | J33: 843338 | K33: 639094 | L33: 445642 | P33: 27 | Q33: 180 | R33: 680 | S33: 14.4
B34: Consumption | C34: =+C33-C31 -> 0 | D34: =+D33-D31 -> 0 | E34: =+E33-E31 -> 0 | F34: =E34+D34+C34 -> 0 | G34: =G33-G31 -> 104 | H34: =H33-H31 -> 12 | I34: =I33-I31 -> 50 | J34: =J33-J31 -> 277 | K34: =K33-K31 -> 0 | L34: =L33-L31 -> 0 | M34: =L34+K34+J34+I34+H34+G34 -> 443 | N34: =M34+F34 -> 443 | P34: 28 | Q34: 107 | R34: 360 | S34: 14.5
B35: 15 | C35: 8204 | D35: 491 | E35: 46762 | G35: 270539 | H35: 164557 | I35: 175118 | J35: 843597 | K35: 639094 | L35: 445642 | P35: 29 | Q35: 93 | R35: 268 | S35: 14.7
B36: Consumption | C36: =+C35-C33 -> 1 | D36: =+D35-D33 -> 0 | E36: =+E35-E33 -> 0 | F36: =E36+D36+C36 -> 1 | G36: =G35-G33 -> 81 | H36: =H35-H33 -> 10 | I36: =I35-I33 -> 32 | J36: =J35-J33 -> 259 | K36: =K35-K33 -> 0 | L36: =L35-L33 -> 0 | M36: =L36+K36+J36+I36+H36+G36 -> 382 | N36: =M36+F36 -> 383 | P36: 30 | Q36: 105 | R36: 298 | S36: 17.5
B37: 16 | C37: 8204 | D37: 491 | E37: 46762 | G37: 270620 | H37: 164569 | I37: 175165 | J37: 843847 | K37: 639094 | L37: 445642 | P37: 31 | Q37: 137 | R37: 368 | S37: 14.5
B38: Consumption | C38: =+C37-C35 -> 0 | D38: =+D37-D35 -> 0 | E38: =+E37-E35 -> 0 | F38: =E38+D38+C38 -> 0 | G38: =G37-G35 -> 81 | H38: =H37-H35 -> 12 | I38: =I37-I35 -> 47 | J38: =J37-J35 -> 250 | K38: =K37-K35 -> 0 | L38: =L37-L35 -> 0 | M38: =L38+K38+J38+I38+H38+G38 -> 390 | N38: =M38+F38 -> 390 | Q38: =SUM(Q7:Q37) -> 4366 | R38: =SUM(R7:R37) -> 14858 | S38: =SUM(S7:S37) -> 405.7
B39: 17 | C39: 8204 | D39: 491 | E39: 46762 | G39: 270694 | H39: 164580 | I39: 175214 | J39: 844096 | K39: 639094 | L39: 445642
B40: Consumption | C40: =+C39-C37 -> 0 | D40: =+D39-D37 -> 0 | E40: =+E39-E37 -> 0 | F40: =E40+D40+C40 -> 0 | G40: =G39-G37 -> 74 | H40: =H39-H37 -> 11 | I40: =I39-I37 -> 49 | J40: =J39-J37 -> 249 | K40: =K39-K37 -> 0 | L40: =L39-L37 -> 0 | M40: =L40+K40+J40+I40+H40+G40 -> 383 | N40: =M40+F40 -> 383
B41: 18 | C41: 8204 | D41: 492 | E41: 46762 | G41: 270777 | H41: 164593 | I41: 175263 | J41: 844373 | K41: 639094 | L41: 445642
B42: Consumption | C42: =+C41-C39 -> 0 | D42: =+D41-D39 -> 1 | E42: =+E41-E39 -> 0 | F42: =E42+D42+C42 -> 1 | G42: =G41-G39 -> 83 | H42: =H41-H39 -> 13 | I42: =I41-I39 -> 49 | J42: =J41-J39 -> 277 | K42: =K41-K39 -> 0 | L42: =L41-L39 -> 0 | M42: =L42+K42+J42+I42+H42+G42 -> 422 | N42: =M42+F42 -> 423
...

Sheet LPG
D2: Central Plant Engineering
D3: Daily LPG Meter Readings
D4: Month: MAY- 2022
B5: Date | C5: COMMON LPG READING/M3 | D5: NOBU/M3 | E5: LPG Total
C6: HOTEL+NOBU
B7: 1 | C7: 255106 | D7: 54220
B8: Consumption | C8: 240 | D8: 0 | E8: =C8 -> 240
B9: 2 | C9: 255365 | D9: 54220
B10: Consumption | C10: =C9-C7 -> 259 | D10: =D9-D7 -> 0 | E10: =C10 -> 259
B11: 3 | C11: 255689 | D11: 54220
B12: Consumption | C12: =C11-C9 -> 324 | D12: =D11-D9 -> 0 | E12: =C12 -> 324
B13: 4 | C13: 255996 | D13: 54220
B14: Consumption | C14: =C13-C11 -> 307 | D14: =D13-D11 -> 0 | E14: =C14 -> 307
B15: 5 | C15: 256295 | D15: 54220
B16: Consumption | C16: =C15-C13 -> 299 | D16: =D15-D13 -> 0 | E16: =C16 -> 299
B17: 6 | C17: 256596 | D17: 54220
B18: Consumption | C18: =C17-C15 -> 301 | D18: =D17-D15 -> 0 | E18: =C18 -> 301
B19: 7 | C19: 256881 | D19: 54220
B20: Consumption | C20: =C19-C17 -> 285 | D20: =D19-D17 -> 0 | E20: =C20 -> 285
B21: 8 | C21: 257184 | D21: 54220
B22: Consumption | C22: =C21-C19 -> 303 | D22: =D21-D19 -> 0 | E22: =C22 -> 303
B23: 9 | C23: 257552 | D23: 54220
