Workbook

Sheet TOTAL
A1: Site Name | B1: Day | C1: Month | D1: Year | E1: Total Electricity Kwh | F1: Electricity Tariff ($/Kwh) | G1: Natual Gas (m3) | H1: Natural Gas $/m3 | I1: Water Utility Supply (m3) m3 | J1: Water Utility Supply (m3) $/m3 | K1: Room Nights | L1: Total Guests
A2: Hong Kong | B2: 1 | C2: 5 | D2: 2021 | E2: =Combine!G3 -> 41420 | F2: 1.3024 | G2: =Combine!M3 -> 3305.1201 | H2: 8.5851 | I2: =Combine!J3 -> 634.4021 | J2: 8.13 | K2: =Combine!N3 -> 137 | L2: =Combine!O3 -> 349
A3: Hong Kong | B3: 2 | C3: 5 | D3: 2021 | E3: =Combine!G4 -> 41602 | F3: 1.3024 | G3: =Combine!M4 -> 3086.8364 | H3: 8.5851 | I3: =Combine!J4 -> 522 | J3: 8.13 | K3: =Combine!N4 -> 56 | L3: =Combine!O4 -> 121
A4: Hong Kong | B4: 3 | C4: 5 | D4: 2021 | E4: =Combine!G5 -> 39408 | F4: 1.3024 | G4: =Combine!M5 -> 2930.193 | H4: 8.5851 | I4: =Combine!J5 -> 414 | J4: 8.13 | K4: =Combine!N5 -> 43 | L4: =Combine!O5 -> 89
A5: Hong Kong | B5: 4 | C5: 5 | D5: 2021 | E5: =Combine!G6 -> 38440 | F5: 1.3024 | G5: =Combine!M6 -> 2811.5916 | H5: 8.5851 | I5: =Combine!J6 -> 405 | J5: 8.13 | K5: =Combine!N6 -> 41 | L5: =Combine!O6 -> 80
A6: Hong Kong | B6: 5 | C6: 5 | D6: 2021 | E6: =Combine!G7 -> 40826 | F6: 1.3024 | G6: =Combine!M7 -> 2716.9144 | H6: 8.5851 | I6: =Combine!J7 -> 359 | J6: 8.13 | K6: =Combine!N7 -> 35 | L6: =Combine!O7 -> 67
A7: Hong Kong | B7: 6 | C7: 5 | D7: 2021 | E7: =Combine!G8 -> 40084 | F7: 1.3024 | G7: =Combine!M8 -> 2750.5989 | H7: 8.5851 | I7: =Combine!J8 -> 387 | J7: 8.13 | K7: =Combine!N8 -> 38 | L7: =Combine!O8 -> 76
A8: Hong Kong | B8: 7 | C8: 5 | D8: 2021 | E8: =Combine!G9 -> 39537 | F8: 1.3024 | G8: =Combine!M9 -> 2689.1375 | H8: 8.5851 | I8: =Combine!J9 -> 353 | J8: 8.13 | K8: =Combine!N9 -> 56 | L8: =Combine!O9 -> 131
A9: Hong Kong | B9: 8 | C9: 5 | D9: 2021 | E9: =Combine!G10 -> 43175 | F9: 1.3024 | G9: =Combine!M10 -> 2710.8836 | H9: 8.5851 | I9: =Combine!J10 -> 399 | J9: 8.13 | K9: =Combine!N10 -> 141 | L9: =Combine!O10 -> 347
A10: Hong Kong | B10: 9 | C10: 5 | D10: 2021 | E10: =Combine!G11 -> 40956 | F10: 1.3024 | G10: =Combine!M11 -> 2867.9497 | H10: 8.5851 | I10: =Combine!J11 -> 499 | J10: 8.13 | K10: =Combine!N11 -> 50 | L10: =Combine!O11 -> 109
A11: Hong Kong | B11: 10 | C11: 5 | D11: 2021 | E11: =Combine!G12 -> 42589 | F11: 1.3024 | G11: =Combine!M12 -> 2777.4732 | H11: 8.5851 | I11: =Combine!J12 -> 389 | J11: 8.13 | K11: =Combine!N12 -> 61 | L11: =Combine!O12 -> 126
A12: Hong Kong | B12: 11 | C12: 5 | D12: 2021 | E12: =Combine!G13 -> 41586.5 | F12: 1.3024 | G12: =Combine!M13 -> 2604.759 | H12: 8.5851 | I12: =Combine!J13 -> 397 | J12: 8.13 | K12: =Combine!N13 -> 52 | L12: =Combine!O13 -> 103
A13: Hong Kong | B13: 12 | C13: 5 | D13: 2021 | E13: =Combine!G14 -> 46005.5 | F13: 1.3024 | G13: =Combine!M14 -> 2647.4219 | H13: 8.5851 | I13: =Combine!J14 -> 406 | J13: 8.13 | K13: =Combine!N14 -> 73 | L13: =Combine!O14 -> 149
... A32: Hong Kong | B32: 31 | C32: 5 | D32: 2021 | E32: =Combine!G33 -> 48040 | F32: 1.3024 | G32: =Combine!M33 -> 2783.0154 | H32: 8.5851 | I32: =Combine!J33 -> 454.95 | J32: 8.13 | K32: =Combine!N33 -> 95 | L32: =Combine!O33 -> 186

Sheet Combine
E1: FSH | F1: FSP | G1: FSH & FSP | H1: FSH | I1: FSP | J1: FSH & FSP | K1: FSH | L1: FSP | M1: FSH & FSP | N1: FSH & FSP
A2: Site Name | B2: Day | C2: Month | E2: Total Electricity Kwh | F2: Total Electricity Kwh | G2: Total Electricity Kwh | H2: Water Utility supply (m3) | I2: Water Utility supply (m3) | J2: Water Utility supply (m3) | K2: Town Gas (mJ) | L2: Town Gas (mJ) | M2: Town Gas (m3) | N2: Occ room | O2: Total Guest | P2: Total Rooms | Q2: Temp ( C )
A3: FSHK | B3: 1 | C3: 5 | D3: 2021 | E3: ='Athens Daily - EL'!AK8 -> 41420 | G3: =SUM(E3,F3) -> 41420 | H3: ='Athens Daily - Water'!R7 -> 634.4021 | J3: =SUM(H3,I3) -> 634.4021 | K3: ='Athens Daily - Gas'!BH9 -> 127610.69 | M3: =SUM(K3,L3)/38.61 -> 3305.1201 | N3: =Occ!G10 -> 137 | O3: =Occ!H10 -> 349 | P3: 918
A4: FSHK | B4: 2 | C4: 5 | D4: 2021 | E4: ='Athens Daily - EL'!AK9 -> 41602 | G4: =SUM(E4,F4) -> 41602 | H4: ='Athens Daily - Water'!R8 -> 522 | J4: =SUM(H4,I4) -> 522 | K4: ='Athens Daily - Gas'!BH10 -> 119182.75 | M4: =SUM(K4,L4)/38.61 -> 3086.8364 | N4: =Occ!G11 -> 56 | O4: =Occ!H11 -> 121 | P4: 918
A5: FSHK | B5: 3 | C5: 5 | D5: 2021 | E5: ='Athens Daily - EL'!AK10 -> 39408 | G5: =SUM(E5,F5) -> 39408 | H5: ='Athens Daily - Water'!R9 -> 414 | J5: =SUM(H5,I5) -> 414 | K5: ='Athens Daily - Gas'!BH11 -> 113134.75 | M5: =SUM(K5,L5)/38.61 -> 2930.193 | N5: =Occ!G12 -> 43 | O5: =Occ!H12 -> 89 | P5: 918
A6: FSHK | B6: 4 | C6: 5 | D6: 2021 | E6: ='Athens Daily - EL'!AK11 -> 38440 | G6: =SUM(E6,F6) -> 38440 | H6: ='Athens Daily - Water'!R10 -> 405 | J6: =SUM(H6,I6) -> 405 | K6: ='Athens Daily - Gas'!BH12 -> 108555.55 | M6: =SUM(K6,L6)/38.61 -> 2811.5916 | N6: =Occ!G13 -> 41 | O6: =Occ!H13 -> 80 | P6: 918
A7: FSHK | B7: 5 | C7: 5 | D7: 2021 | E7: ='Athens Daily - EL'!AK12 -> 40826 | G7: =SUM(E7,F7) -> 40826 | H7: ='Athens Daily - Water'!R11 -> 359 | J7: =SUM(H7,I7) -> 359 | K7: ='Athens Daily - Gas'!BH13 -> 104900.06 | M7: =SUM(K7,L7)/38.61 -> 2716.9144 | N7: =Occ!G14 -> 35 | O7: =Occ!H14 -> 67 | P7: 918
A8: FSHK | B8: 6 | C8: 5 | D8: 2021 | E8: ='Athens Daily - EL'!AK13 -> 40084 | G8: =SUM(E8,F8) -> 40084 | H8: ='Athens Daily - Water'!R12 -> 387 | J8: =SUM(H8,I8) -> 387 | K8: ='Athens Daily - Gas'!BH14 -> 106200.62 | M8: =SUM(K8,L8)/38.61 -> 2750.5989 | N8: =Occ!G15 -> 38 | O8: =Occ!H15 -> 76 | P8: 918
A9: FSHK | B9: 7 | C9: 5 | D9: 2021 | E9: ='Athens Daily - EL'!AK14 -> 39537 | G9: =SUM(E9,F9) -> 39537 | H9: ='Athens Daily - Water'!R13 -> 353 | J9: =SUM(H9,I9) -> 353 | K9: ='Athens Daily - Gas'!BH15 -> 103827.6 | M9: =SUM(K9,L9)/38.61 -> 2689.1375 | N9: =Occ!G16 -> 56 | O9: =Occ!H16 -> 131 | P9: 918
A10: FSHK | B10: 8 | C10: 5 | D10: 2021 | E10: ='Athens Daily - EL'!AK15 -> 43175 | G10: =SUM(E10,F10) -> 43175 | H10: ='Athens Daily - Water'!R14 -> 399 | J10: =SUM(H10,I10) -> 399 | K10: ='Athens Daily - Gas'!BH16 -> 104667.22 | M10: =SUM(K10,L10)/38.61 -> 2710.8836 | N10: =Occ!G17 -> 141 | O10: =Occ!H17 -> 347 | P10: 918
A11: FSHK | B11: 9 | C11: 5 | D11: 2021 | E11: ='Athens Daily - EL'!AK16 -> 40956 | G11: =SUM(E11,F11) -> 40956 | H11: ='Athens Daily - Water'!R15 -> 499 | J11: =SUM(H11,I11) -> 499 | K11: ='Athens Daily - Gas'!BH17 -> 110731.54 | M11: =SUM(K11,L11)/38.61 -> 2867.9497 | N11: =Occ!G18 -> 50 | O11: =Occ!H18 -> 109 | P11: 918
A12: FSHK | B12: 10 | C12: 5 | D12: 2021 | E12: ='Athens Daily - EL'!AK17 -> 42589 | G12: =SUM(E12,F12) -> 42589 | H12: ='Athens Daily - Water'!R16 -> 389 | J12: =SUM(H12,I12) -> 389 | K12: ='Athens Daily - Gas'!BH18 -> 107238.24 | M12: =SUM(K12,L12)/38.61 -> 2777.4732 | N12: =Occ!G19 -> 61 | O12: =Occ!H19 -> 126 | P12: 918
A13: FSHK | B13: 11 | C13: 5 | D13: 2021 | E13: ='Athens Daily - EL'!AK18 -> 41586.5 | G13: =SUM(E13,F13) -> 41586.5 | H13: ='Athens Daily - Water'!R17 -> 397 | J13: =SUM(H13,I13) -> 397 | K13: ='Athens Daily - Gas'!BH19 -> 100569.74 | M13: =SUM(K13,L13)/38.61 -> 2604.759 | N13: =Occ!G20 -> 52 | O13: =Occ!H20 -> 103 | P13: 918
A14: FSHK | B14: 12 | C14: 5 | D14: 2021 | E14: ='Athens Daily - EL'!AK19 -> 46005.5 | G14: =SUM(E14,F14) -> 46005.5 | H14: ='Athens Daily - Water'!R18 -> 406 | J14: =SUM(H14,I14) -> 406 | K14: ='Athens Daily - Gas'!BH20 -> 102216.96 | M14: =SUM(K14,L14)/38.61 -> 2647.4219 | N14: =Occ!G21 -> 73 | O14: =Occ!H21 -> 149 | P14: 918
... A33: FSHK | B33: 31 | C33: 5 | D33: 2021 | E33: ='Athens Daily - EL'!AK38 -> 48040 | G33: =SUM(E33,F33) -> 48040 | H33: ='Athens Daily - Water'!R37 -> 454.95 | J33: =SUM(H33,I33) -> 454.95 | K33: ='Athens Daily - Gas'!BH39 -> 107452.22 | M33: =SUM(K33,L33)/38.61 -> 2783.0154 | N33: =Occ!G40 -> 95 | O33: =Occ!H40 -> 186 | P33: 918
M35: =SUM(M3:M33) -> 86205.173

Sheet Occ
A1: Property: | B1: FS Hotel Hong Kong
C3: Year: 2021
C4: Actual
C5: Working
C6: Total Rooms
B7: Day of month | C7: Month: May 2021
B8: Net Amount | G8: Data to be input in HEP
B9: Daily Average | C9: FSH Occ Rooms | D9: no.of guest | E9: FSP Occ rooms | F9: no.of guest | G9: Total OCC | H9: Total Guest | I9: Total Rooms
B10: 01 | C10: 137 | D10: 349 | G10: =SUM(C10+E10) -> 137 | H10: =D10+F10 -> 349 | I10: 918
B11: 02 | C11: 56 | D11: 121 | G11: =SUM(C11+E11) -> 56 | H11: =D11+F11 -> 121 | I11: 918
B12: 03 | C12: 43 | D12: 89 | G12: =SUM(C12+E12) -> 43 | H12: =D12+F12 -> 89 | I12: 918
B13: 04 | C13: 41 | D13: 80 | G13: =SUM(C13+E13) -> 41 | H13: =D13+F13 -> 80 | I13: 918
B14: 05 | C14: 35 | D14: 67 | G14: =SUM(C14+E14) -> 35 | H14: =D14+F14 -> 67 | I14: 918
B15: 06 | C15: 38 | D15: 76 | G15: =SUM(C15+E15) -> 38 | H15: =D15+F15 -> 76 | I15: 918
B16: 07 | C16: 56 | D16: 131 | G16: =SUM(C16+E16) -> 56 | H16: =D16+F16 -> 131 | I16: 918
B17: 08 | C17: 141 | D17: 347 | G17: =SUM(C17+E17) -> 141 | H17: =D17+F17 -> 347 | I17: 918
B18: 09 | C18: 50 | D18: 109 | G18: =SUM(C18+E18) -> 50 | H18: =D18+F18 -> 109 | I18: 918
B19: 10 | C19: 61 | D19: 126 | G19: =SUM(C19+E19) -> 61 | H19: =D19+F19 -> 126 | I19: 918
B20: 11 | C20: 52 | D20: 103 | G20: =SUM(C20+E20) -> 52 | H20: =D20+F20 -> 103 | I20: 918
B21: 12 | C21: 73 | D21: 149 | G21: =SUM(C21+E21) -> 73 | H21: =D21+F21 -> 149 | I21: 918
... B40: 31 | C40: 95 | D40: 186 | G40: =SUM(C40+E40) -> 95 | H40: =D40+F40 -> 186 | I40: 918
C41: =SUM(C10:C40) -> 3000

Sheet Total - FSH
A1: Site Name | B1: Day | C1: Month | E1: Total Electricity Kwh | F1: Electricity Tariff ($/Kwh) | G1: Town Gas (mJ) | H1: Town Gas (m3) | I1: Town Gas $/mJ | J1: Water Utility supply (m3) | K1: Water Utility (m3) $/m3 | L1: Rooms Nights | M1: Total Guests | N1: Temp
A2: FSHK | B2: 1 | C2: 1 | D2: 2021 | E2: ='Athens Daily - EL'!AK8 -> 41420 | G2: ='Athens Daily - Gas'!BH9 -> 127610.69 | H2: =G2/38.3 -> 3331.8717 | J2: ='Athens Daily - Water'!R7 -> 634.4021 | L2: 142 | M2: =L2*2 -> 284 | N2: 10
A3: FSHK | B3: 2 | C3: 1 | D3: 2021 | E3: ='Athens Daily - EL'!AK9 -> 41602 | G3: ='Athens Daily - Gas'!BH10 -> 119182.75 | H3: =G3/38.3 -> 3111.8212 | J3: ='Athens Daily - Water'!R8 -> 522 | L3: 102 | M3: =L3*2 -> 204 | N3: 12
A4: FSHK | B4: 3 | C4: 1 | D4: 2021 | E4: ='Athens Daily - EL'!AK10 -> 39408 | G4: ='Athens Daily - Gas'!BH11 -> 113134.75 | H4: =G4/38.3 -> 2953.91 | J4: ='Athens Daily - Water'!R9 -> 414 | L4: 55 | M4: =L4*2 -> 110 | N4: 15
A5: FSHK | B5: 4 | C5: 1 | D5: 2021 | E5: ='Athens Daily - EL'!AK11 -> 38440 | G5: ='Athens Daily - Gas'!BH12 -> 108555.55 | H5: =G5/38.3 -> 2834.3486 | J5: ='Athens Daily - Water'!R10 -> 405 | L5: 45 | M5: =L5*2 -> 90 | N5: 17
A6: FSHK | B6: 5 | C6: 1 | D6: 2021 | E6: ='Athens Daily - EL'!AK12 -> 40826 | G6: ='Athens Daily - Gas'!BH13 -> 104900.06 | H6: =G6/38.3 -> 2738.9051 | J6: ='Athens Daily - Water'!R11 -> 359 | L6: 34 | M6: =L6*2 -> 68 | N6: 15
A7: FSHK | B7: 6 | C7: 1 | D7: 2021 | E7: ='Athens Daily - EL'!AK13 -> 40084 | G7: ='Athens Daily - Gas'!BH14 -> 106200.62 | H7: =G7/38.3 -> 2772.8622 | J7: ='Athens Daily - Water'!R12 -> 387 | L7: 36 | M7: =L7*2 -> 72
A8: FSHK | B8: 7 | C8: 1 | D8: 2021 | E8: ='Athens Daily - EL'!AK14 -> 39537 | G8: ='Athens Daily - Gas'!BH15 -> 103827.6 | H8: =G8/38.3 -> 2710.9034 | J8: ='Athens Daily - Water'!R13 -> 353 | L8: 60 | M8: =L8*2 -> 120
A9: FSHK | B9: 8 | C9: 1 | D9: 2021 | E9: ='Athens Daily - EL'!AK15 -> 43175 | G9: ='Athens Daily - Gas'!BH16 -> 104667.22 | H9: =G9/38.3 -> 2732.8255 | J9: ='Athens Daily - Water'!R14 -> 399 | L9: 64 | M9: =L9*2 -> 128
A10: FSHK | B10: 9 | C10: 1 | D10: 2021 | E10: ='Athens Daily - EL'!AK16 -> 40956 | G10: ='Athens Daily - Gas'!BH17 -> 110731.54 | H10: =G10/38.3 -> 2891.1628 | J10: ='Athens Daily - Water'!R15 -> 499 | L10: 100 | M10: =L10*2 -> 200 | N10: 9
A11: FSHK | B11: 10 | C11: 1 | D11: 2021 | E11: ='Athens Daily - EL'!AK17 -> 42589 | G11: ='Athens Daily - Gas'!BH18 -> 107238.24 | H11: =G11/38.3 -> 2799.954 | J11: ='Athens Daily - Water'!R16 -> 389 | L11: 63 | M11: =L11*2 -> 126 | N11: 12
A12: FSHK | B12: 11 | C12: 1 | D12: 2021 | E12: ='Athens Daily - EL'!AK18 -> 41586.5 | G12: ='Athens Daily - Gas'!BH19 -> 100569.74 | H12: =G12/38.3 -> 2625.8419 | J12: ='Athens Daily - Water'!R17 -> 397 | L12: 39 | M12: =L12*2 -> 78 | N12: 12
A13: FSHK | B13: 12 | C13: 1 | D13: 2021 | E13: ='Athens Daily - EL'!AK19 -> 46005.5 | G13: ='Athens Daily - Gas'!BH20 -> 102216.96 | H13: =G13/38.3 -> 2668.8501 | J13: ='Athens Daily - Water'!R18 -> 406 | L13: 43 | M13: =L13*2 -> 86 | N13: 10
A14: FSHK | B14: 13 | C14: 1 | D14: 2021 | E14: ='Athens Daily - EL'!AK20 -> 48126.5 | G14: ='Athens Daily - Gas'!BH21 -> 97289.28 | H14: =G14/38.3 -> 2540.1901 | J14: ='Athens Daily - Water'!R19 -> 392 | L14: 46 | M14: =L14*2 -> 92 | N14: 12
A15: FSHK | B15: 14 | C15: 1 | D15: 2021 | E15: ='Athens Daily - EL'!AK21 -> 43546.5 | G15: ='Athens Daily - Gas'!BH22 -> 105855.26 | H15: =G15/38.3 -> 2763.845 | J15: ='Athens Daily - Water'!R20 -> 441 | L15: 55 | M15: =L15*2 -> 110 | N15: 13
A16: FSHK | B16: 15 | C16: 1 | D16: 2021 | E16: ='Athens Daily - EL'!AK22 -> 46026.5 | G16: ='Athens Daily - Gas'!BH23 -> 107393.28 | H16: =G16/38.3 -> 2804.0021 | J16: ='Athens Daily - Water'!R21 -> 525.1582 | L16: 74 | M16: =L16*2 -> 148 | N16: 13
A17: FSHK | B17: 16 | C17: 1 | D17: 2021 | E17: ='Athens Daily - EL'!AK23 -> 46171.5 | G17: ='Athens Daily - Gas'!BH24 -> 114782.02 | H17: =G17/38.3 -> 2996.9195 | J17: ='Athens Daily - Water'!R22 -> 526.5 | L17: 149 | M17: =L17*2 -> 298
A18: FSHK | B18: 17 | C18: 1 | D18: 2021 | E18: ='Athens Daily - EL'!AK24 -> 47646.5 | G18: ='Athens Daily - Gas'!BH25 -> 93566.016 | H18: =G18/38.3 -> 2442.9769 | J18: ='Athens Daily - Water'!R23 -> 474.7085 | L18: 64 | M18: =L18*2 -> 128
A19: FSHK | B19: 18 | C19: 1 | D19: 2021 | E19: ='Athens Daily - EL'!AK25 -> 47138.5 | G19: ='Athens Daily - Gas'!BH26 -> 123796.27 | H19: =G19/38.3 -> 3232.2786 | J19: ='Athens Daily - Water'!R24 -> 453.36 | L19: 58 | M19: =L19*2 -> 116
A20: FSHK | B20: 19 | C20: 1 | D20: 2021 | E20: ='Athens Daily - EL'!AK26 -> 43661 | G20: ='Athens Daily - Gas'!BH27 -> 108149.57 | H20: =G20/38.3 -> 2823.7485 | J20: ='Athens Daily - Water'!R25 -> 436.2723 | L20: 69 | M20: =L20*2 -> 138
A21: FSHK | B21: 20 | C21: 1 | D21: 2021 | E21: ='Athens Daily - EL'!AK27 -> 43695.5 | G21: ='Athens Daily - Gas'!BH28 -> 109866.96 | H21: =G21/38.3 -> 2868.589 | J21: ='Athens Daily - Water'!R26 -> 537.264 | L21: 42 | M21: =L21*2 -> 84
A22: FSHK | B22: 21 | C22: 1 | D22: 2021 | E22: ='Athens Daily - EL'!AK28 -> 46210.5 | G22: ='Athens Daily - Gas'!BH29 -> 106293.26 | H22: =G22/38.3 -> 2775.281 | J22: ='Athens Daily - Water'!R27 -> 432.429 | L22: 45 | M22: =L22*2 -> 90
A23: FSHK | B23: 22 | C23: 1 | D23: 2021 | E23: ='Athens Daily - EL'!AK29 -> 44170 | G23: ='Athens Daily - Gas'!BH30 -> 106156.18 | H23: =G23/38.3 -> 2771.7017 | J23: ='Athens Daily - Water'!R28 -> 463.1988 | L23: 82 | M23: =L23*2 -> 164 | N23: 19
A24: FSHK | B24: 23 | C24: 1 | D24: 2021 | E24: ='Athens Daily - EL'!AK30 -> 44879.5 | G24: ='Athens Daily - Gas'!BH31 -> 106156.18 | H24: =G24/38.3 -> 2771.7017 | J24: ='Athens Daily - Water'!R29 -> 598.2343 | L24: 170 | M24: =L24*2 -> 340 | N24: 20
A25: FSHK | B25: 24 | C25: 1 | D25: 2021 | E25: ='Athens Daily - EL'!AK31 -> 44748.5 | G25: ='Athens Daily - Gas'!BH32 -> 106156.18 | H25: =G25/38.3 -> 2771.7017 | J25: ='Athens Daily - Water'!R30 -> 465.8749 | L25: 91 | M25: =L25*2 -> 182 | N25: 19
A26: FSHK | B26: 25 | C26: 1 | D26: 2021 | E26: ='Athens Daily - EL'!AK32 -> 42855.5 | G26: ='Athens Daily - Gas'!BH33 -> 105344.26 | H26: =G26/38.3 -> 2750.5028 | J26: ='Athens Daily - Water'!R31 -> 403 | L26: 56 | M26: =L26*2 -> 112
A27: FSHK | B27: 26 | C27: 1 | D27: 2021 | E27: ='Athens Daily - EL'!AK33 -> 41857 | G27: ='Athens Daily - Gas'!BH34 -> 102327.31 | H27: =G27/38.3 -> 2671.7314 | J27: ='Athens Daily - Water'!R32 -> 449.5 | M27: =L27*2 -> 0
A28: FSHK | B28: 27 | C28: 1 | D28: 2021 | E28: ='Athens Daily - EL'!AK34 -> 43254.5 | G28: ='Athens Daily - Gas'!BH35 -> 100569.12 | H28: =G28/38.3 -> 2625.8256 | J28: ='Athens Daily - Water'!R33 -> 423 | M28: =L28*2 -> 0
A29: FSHK | B29: 28 | C29: 1 | D29: 2021 | E29: ='Athens Daily - EL'!AK35 -> 43036.5 | G29: ='Athens Daily - Gas'!BH36 -> 105074.54 | H29: =G29/38.3 -> 2743.4607 | J29: ='Athens Daily - Water'!R34 -> 470.23 | M29: =L29*2 -> 0
A30: FSHK | B30: 29 | C30: 1 | D30: 2021 | E30: ='Athens Daily - EL'!AK36 -> 43916.5 | G30: ='Athens Daily - Gas'!BH37 -> 104610.38 | H30: =G30/38.3 -> 2731.3416 | J30: ='Athens Daily - Water'!R35 -> 467.27 | M30: =L30*2 -> 0
A31: FSHK | B31: 30 | C31: 1 | D31: 2021 | E31: ='Athens Daily - EL'!AK37 -> 44402 | G31: ='Athens Daily - Gas'!BH38 -> 108707.71 | H31: =G31/38.3 -> 2838.3215 | J31: ='Athens Daily - Water'!R37 -> 454.95 | M31: =L31*2 -> 0
A32: FSHK | B32: 31 | C32: 1 | D32: 2021 | E32: ='Athens Daily - EL'!AK38 -> 48040 | G32: ='Athens Daily - Gas'!BH39 -> 107452.22 | H32: =G32/38.3 -> 2805.5411 | J32: ='Athens Daily - Water'!R38 -> 0 | M32: =L32*2 -> 0

Sheet Total - FSP
A1: Site Name | B1: Day | C1: Month | D1: Year | E1: Total Electricity Kwh | F1: Electricity Tariff ($/Kwh) | G1: Town Gas (mJ) | H1: Town Gas $/mJ | I1: Water Utility supply (m3) | J1: Water Utility (m3) $/m3 | K1: Rooms Nights | L1: Total Guests
A2: FSHK | B2: 1 | C2: 1 | D2: 2021 | E2: ='Athens Daily - EL'!AL8 -> 8468 | G2: ='Athens Daily - Gas'!BI9 -> 79488 | I2: ='Athens Daily - Water'!S7 -> 192.5 | K2: 286 | L2: 2
A3: FSHK | B3: 2 | C3: 1 | D3: 2021 | E3: ='Athens Daily - EL'!AL9 -> 9200 | G3: ='Athens Daily - Gas'!BI10 -> 63139.2 | I3: ='Athens Daily - Water'!S8 -> 156 | K3: 285 | L3: 2
A4: FSHK | B4: 3 | C4: 1 | D4: 2021 | E4: ='Athens Daily - EL'!AL10 -> 7739 | G4: ='Athens Daily - Gas'!BI11 -> 59107.2 | I4: ='Athens Daily - Water'!S9 -> 150.05 | K4: 282 | L4: 2
A5: FSHK | B5: 4 | C5: 1 | D5: 2021 | E5: ='Athens Daily - EL'!AL11 -> 8023 | G5: ='Athens Daily - Gas'!BI12 -> 56054.4 | I5: ='Athens Daily - Water'!S10 -> 298.25 | K5: 284 | L5: 2
A6: FSHK | B6: 5 | C6: 1 | D6: 2021 | E6: ='Athens Daily - EL'!AL12 -> 9279 | G6: ='Athens Daily - Gas'!BI13 -> 61104 | I6: ='Athens Daily - Water'!S11 -> 157.2 | K6: 286 | L6: 2
A7: FSHK | B7: 6 | C7: 1 | D7: 2021 | E7: ='Athens Daily - EL'!AL13 -> 7873 | G7: ='Athens Daily - Gas'!BI14 -> 60777.6 | I7: ='Athens Daily - Water'!S12 -> 140.2 | K7: 288 | L7: 2
A8: FSHK | B8: 7 | C8: 1 | D8: 2021 | E8: ='Athens Daily - EL'!AL14 -> 9281 | G8: ='Athens Daily - Gas'!BI15 -> 61276.8 | I8: ='Athens Daily - Water'!S13 -> 149.4 | K8: 286 | L8: 2
A9: FSHK | B9: 8 | C9: 1 | D9: 2021 | E9: ='Athens Daily - EL'!AL15 -> 9085 | G9: ='Athens Daily - Gas'!BI16 -> 58723.2 | I9: ='Athens Daily - Water'!S14 -> 120.15 | K9: 287 | L9: 2
A10: FSHK | B10: 9 | C10: 1 | D10: 2021 | E10: ='Athens Daily - EL'!AL16 -> 9466 | G10: ='Athens Daily - Gas'!BI17 -> 60667.2 | I10: ='Athens Daily - Water'!S15 -> 157.4 | K10: 284 | L10: 2
A11: FSHK | B11: 10 | C11: 1 | D11: 2021 | E11: ='Athens Daily - EL'!AL17 -> 11750 | G11: ='Athens Daily - Gas'!BI18 -> 60667.2 | I11: ='Athens Daily - Water'!S16 -> 145.15 | K11: 284 | L11: 2
A12: FSHK | B12: 11 | C12: 1 | D12: 2021 | E12: ='Athens Daily - EL'!AL18 -> 11124.5 | G12: ='Athens Daily - Gas'!BI19 -> 58963.2 | I12: ='Athens Daily - Water'!S17 -> 143.4 | K12: 284 | L12: 2
A13: FSHK | B13: 12 | C13: 1 | D13: 2021 | E13: ='Athens Daily - EL'!AL19 -> 13529.5 | G13: ='Athens Daily - Gas'!BI20 -> 58540.8 | I13: ='Athens Daily - Water'!S18 -> 173.9 | K13: 286 | L13: 2
... A30: FSHK | B30: 29 | C30: 1 | D30: 2021 | E30: ='Athens Daily - EL'!AL36 -> 10766.5 | G30: ='Athens Daily - Gas'!BI37 -> 58003.2 | I30: ='Athens Daily - Water'!S35 -> 142.65 | K30: 291 | L30: 2
A31: FSHK | B31: 30 | C31: 1 | D31: 2021 | E31: ='Athens Daily - EL'!AL37 -> 10945 | G31: ='Athens Daily - Gas'!BI38 -> 59760 | I31: ='Athens Daily - Water'!S37 -> 156.05 | K31: 290 | L31: 2
A32: FSHK | B32: 31 | C32: 1 | D32: 2021 | E32: ='Athens Daily - EL'!AL38 -> 15435 | G32: ='Athens Daily - Gas'!BI39 -> 59683.2 | I32: ='Athens Daily - Water'!S38 -> 0

Sheet Athens Daily - EL
C1: FSH | E1: FSH | G1: FSH | J1: FSH | L1: FSH | N1: FSH & FSP | Q1: FSH & FSP | T1: FSH & FSP | W1: FSH & FSP | Z1: FSP | AB1: FSP | AD1: FSP | AF1: FSP | AH1: FSP
C2: HOT Normal and Essential power for linen chute(9/F-45/F), HOT water pump at 8/F, Podium dimmer supply(P1-P6), MVAC system(B1/F-B2/F), Bus station BPTT supply. | E2: HOT Normal Power for Guest rooms supply (9/F-45/F), MVAC system (2/F & 46/F), P&D system(46/F) Podium MVAC system (P1/F-P6/F) | G2: P5 Pool Plant, Laundry (hotel 70%,Place 30%), 9/F - 28/F public area, 29/F 46/F Public area Podium normal power supply for water feature(G/F), Chiller WCC-01(B2/F)(FSH 50%, FSP 50%) | J2: Podium normal power for Administration office(P5/F & P6/F), P&D system supply(B2/F), Planter lighting supply(Open Space), Kitchen public supply(B1/F, P1/F, P2/F, P3/F, P4/F & P6/F), BMS room supply(B1/F), Security room supply(G/F), Computer & PABX room | L2: Podium normal power supply for Public supply(P1/F - P6/F), Kitchen(B1/F, P1/F, P2/F, P3/F, P4/F & P6/F), P&D system supply(B1/F), Refuse room supply(G/F), Gas boiler supply(B2/F) and MVAC system supply(P1/F-P6/F). | N2: Podium normal power supply for main P&D system supply(B1/F), MVAC chilled water pump(B1/F) Chiller WCC-02(B2/F) (FSH 50%, FSP 50%) | Q2: Chiller # 3 (FSH 50%, FSP 50%) | T2: Chiller # 4 (FSH 50%, FSP 50%) | W2: Chiller # 5 (FSH 50%, FSP 50%) | Z2: SHT normal power for Guest rooms supply (11/F-23/F). | AB2: SHT normal power for Guest rooms supply (25/F-57/F). | AD2: SHT Essential Power for Public Power supply, F.S. Pump (9/F, 57/F & 39/F), Podium F.S. pump(P1M), Lift LT/S1-LT/S7(LM/F), Lift LT/S8-S9(59/F) and Lift LT/S10(8/F). | AF2: SHT normal power for Guest rooms supply (25/F-57/F). | AH2: SHT normal power for MVAC System(8/F & 40/F), Public supply (8-R/F), P&D system(40/F & 60/F), swimming pool(57/F), SWB 3&4(40/F)
C3: 5065546 | E3: 5065547 | G3: 5008272 | J3: 5065548 | L3: 5465545 | N3: 5008273 | Q3: 5018351 | T3: 5018354 | W3: 5018350 | Z3: 5065543 | AB3: 5065544 | AD3: 5065541 | AF3: 5065542 | AH3: 5065540 | AK3: Daily Total consumption
C4: TXW1 | E4: TXW4 | G4: TXW2 | J4: TXC2 | L4: TXC1 | N4: TXW3 | Q4: TXN1 | T4: TXN2 | W4: TXN3 | Z4: TXN4 | AB4: TXE1 | AD4: TXE2 | AF4: TXE3 | AH4: TXE4
A5: Tariff Type | C5: MD-LV | E5: MD-LV | G5: MD-LV | J5: MD-LV | L5: MD-LV | N5: MD-LV | Q5: Non-Residential | T5: Non-Residential | W5: Non-Residential | Z5: MD-LV | AB5: MD-LV | AD5: MD-LV | AF5: MD-LV | AH5: MD-LV
A6: Date | C6: Reading Kwh | D6: Differecne Kwh | E6: Reading Kwh | F6: Differecne Kwh | G6: Reading Kwh | H6: Differecne Kwh | I6: FSH 50% / FSP 50% | J6: Reading Kwh | K6: Differecne Kwh | L6: Reading Kwh | M6: Differecne Kwh | N6: Reading Kwh | O6: Differecne Kwh | P6: FSH 50% / FSP 50% | Q6: Reading Kwh | R6: Differecne Kwh | S6: FSH 50% / FSP 50% | T6: Reading Kwh | U6: Differecne Kwh | V6: FSH 50% / FSP 50% | W6: Reading Kwh | X6: Differecne Kwh | Y6: FSH 50% / FSP 50% | Z6: Reading Kwh | AA6: Differecne Kwh | AB6: Reading Kwh | AC6: Differecne Kwh | AD6: Reading Kwh | AE6: Differecne Kwh | AF6: Reading Kwh | AG6: Differecne Kwh | AH6: Reading Kwh | AI6: Differecne Kwh | AK6: FSH | AL6: FSP
A7: 44316 | C7: 104795 | E7: 162829 | G7: 949379 | J7: 145616 | L7: 226957 | N7: 859217 | Q7: 144492 | T7: 74790 | W7: 152233 | Z7: 28669 | AB7: 58181 | AD7: 104366 | AF7: 56537 | AH7: 281818
A8: 44317 | C8: 105195 | D8: =(C8-C7)*10 -> 4000 | E8: 163599 | F8: =(E8-E7)*10 -> 7700 | G8: 950768 | H8: =(G8-G7)*10 -> 13890 | I8: =H8*50% -> 6945 | J8: 146236 | K8: =(J8-J7)*10 -> 6200 | L8: 227944 | M8: =(L8-L7)*10 -> 9870 | N8: 859673 | O8: =(N8-N7)*10 -> 4560 | P8: =O8*50% -> 2280 | Q8: 144842 | R8: =(Q8-Q7)*10 -> 3500 | S8: =R8*50% -> 1750 | T8: 75289 | U8: =(T8-T7)*10 -> 4990 | V8: =U8*50% -> 2495 | W8: 152269 | X8: =(W8-W7)*10 -> 360 | Y8: =X8*50% -> 180 | Z8: 28767 | AA8: =Z8-Z7 -> 98 | AB8: 58379 | AC8: =AB8-AB7 -> 198 | AD8: 104721 | AE8: =AD8-AD7 -> 355 | AF8: 56721 | AG8: =AF8-AF7 -> 184 | AH8: 282746 | AI8: =AH8-AH7 -> 928 | AK8: =SUM(D8,F8,I8,K8,M8,P8,S8,V8,Y8) -> 41420 | AL8: =SUM(P8,S8,V8,Y8,AA8,AC8,AE8,AG8,AI8) -> 8468
A9: 44318 | C9: 105586 | D9: =(C9-C8)*10 -> 3910 | E9: 164322 | F9: =(E9-E8)*10 -> 7230 | G9: 952228 | H9: =(G9-G8)*10 -> 14600 | I9: =H9*50% -> 7300 | J9: 146835 | K9: =(J9-J8)*10 -> 5990 | L9: 228918 | M9: =(L9-L8)*10 -> 9740 | N9: 860135 | O9: =(N9-N8)*10 -> 4620 | P9: =O9*50% -> 2310 | Q9: 145399 | R9: =(Q9-Q8)*10 -> 5570 | S9: =R9*50% -> 2785 | T9: 75753 | U9: =(T9-T8)*10 -> 4640 | V9: =U9*50% -> 2320 | W9: 152303 | X9: =W9-W8 -> 34 | Y9: =X9*50% -> 17 | Z9: 28857 | AA9: =Z9-Z8 -> 90 | AB9: 58575 | AC9: =AB9-AB8 -> 196 | AD9: 105068 | AE9: =AD9-AD8 -> 347 | AF9: 56909 | AG9: =AF9-AF8 -> 188 | AH9: 283693 | AI9: =AH9-AH8 -> 947 | AK9: =SUM(D9,F9,I9,K9,M9,P9,S9,V9,Y9) -> 41602 | AL9: =SUM(P9,S9,V9,Y9,AA9,AC9,AE9,AG9,AI9) -> 9200
A10: 44319 | C10: 105953 | D10: =(C10-C9)*10 -> 3670 | E10: 165035 | F10: =(E10-E9)*10 -> 7130 | G10: 953694 | H10: =(G10-G9)*10 -> 14660 | I10: =H10*50% -> 7330 | J10: 147422 | K10: =(J10-J9)*10 -> 5870 | L10: 229861 | M10: =(L10-L9)*10 -> 9430 | N10: 860789 | O10: =(N10-N9)*10 -> 6540 | P10: =O10*50% -> 3270 | Q10: 145401 | R10: =(Q10-Q9)*10 -> 20 | S10: =R10*50% -> 10 | T10: 76289 | U10: =(T10-T9)*10 -> 5360 | V10: =U10*50% -> 2680 | W10: 152339 | X10: =W10-W9 -> 36 | Y10: =X10*50% -> 18 | Z10: 28944 | AA10: =Z10-Z9 -> 87 | AB10: 58786 | AC10: =AB10-AB9 -> 211 | AD10: 105427 | AE10: =AD10-AD9 -> 359 | AF10: 57097 | AG10: =AF10-AF9 -> 188 | AH10: 284609 | AI10: =AH10-AH9 -> 916 | AK10: =SUM(D10,F10,I10,K10,M10,P10,S10,V10,Y10) -> 39408 | AL10: =SUM(P10,S10,V10,Y10,AA10,AC10,AE10,AG10,AI10) -> 7739
A11: 44320 | C11: 106327 | D11: =(C11-C10)*10 -> 3740 | E11: 165716 | F11: =(E11-E10)*10 -> 6810 | G11: 955103 | H11: =(G11-G10)*10 -> 14090 | I11: =H11*50% -> 7045 | J11: 147979 | K11: =(J11-J10)*10 -> 5570 | L11: 230762 | M11: =(L11-L10)*10 -> 9010 | N11: 861268 | O11: =(N11-N10)*10 -> 4790 | P11: =O11*50% -> 2395 | Q11: 145403 | R11: =(Q11-Q10)*10 -> 20 | S11: =R11*50% -> 10 | T11: 77010 | U11: =(T11-T10)*10 -> 7210 | V11: =U11*50% -> 3605 | W11: 152849 | X11: =W11-W10 -> 510 | Y11: =X11*50% -> 255 | Z11: 29030 | AA11: =Z11-Z10 -> 86 | AB11: 58985 | AC11: =AB11-AB10 -> 199 | AD11: 105782 | AE11: =AD11-AD10 -> 355 | AF11: 57282 | AG11: =AF11-AF10 -> 185 | AH11: 285542 | AI11: =AH11-AH10 -> 933 | AK11: =SUM(D11,F11,I11,K11,M11,P11,S11,V11,Y11) -> 38440 | AL11: =SUM(P11,S11,V11,Y11,AA11,AC11,AE11,AG11,AI11) -> 8023
A12: 44321 | C12: 106709 | D12: =(C12-C11)*10 -> 3820 | E12: 166414 | F12: =(E12-E11)*10 -> 6980 | G12: 956629 | H12: =(G12-G11)*10 -> 15260 | I12: =H12*50% -> 7630 | J12: 148559 | K12: =(J12-J11)*10 -> 5800 | L12: 231674 | M12: =(L12-L11)*10 -> 9120 | N12: 861743 | O12: =(N12-N11)*10 -> 4750 | P12: =O12*50% -> 2375 | Q12: 146175 | R12: =(Q12-Q11)*10 -> 7720 | S12: =R12*50% -> 3860 | T12: 77256 | U12: =(T12-T11)*10 -> 2460 | V12: =U12*50% -> 1230 | W12: 152871 | X12: =W12-W11 -> 22 | Y12: =X12*50% -> 11 | Z12: 29123 | AA12: =Z12-Z11 -> 93 | AB12: 59191 | AC12: =AB12-AB11 -> 206 | AD12: 106147 | AE12: =AD12-AD11 -> 365 | AF12: 57469 | AG12: =AF12-AF11 -> 187 | AH12: 286494 | AI12: =AH12-AH11 -> 952 | AK12: =SUM(D12,F12,I12,K12,M12,P12,S12,V12,Y12) -> 40826 | AL12: =SUM(P12,S12,V12,Y12,AA12,AC12,AE12,AG12,AI12) -> 9279
A13: 44322 | C13: 107100 | D13: =(C13-C12)*10 -> 3910 | E13: 167146 | F13: =(E13-E12)*10 -> 7320 | G13: 958119 | H13: =(G13-G12)*10 -> 14900 | I13: =H13*50% -> 7450 | J13: 149155 | K13: =(J13-J12)*10 -> 5960 | L13: 232613 | M13: =(L13-L12)*10 -> 9390 | N13: 862256 | O13: =(N13-N12)*10 -> 5130 | P13: =O13*50% -> 2565 | Q13: 146870 | R13: =(Q13-Q12)*10 -> 6950 | S13: =R13*50% -> 3475 | T13: 77258 | U13: =(T13-T12)*10 -> 20 | V13: =U13*50% -> 10 | W13: 152879 | X13: =W13-W12 -> 8 | Y13: =X13*50% -> 4 | Z13: 29223 | AA13: =Z13-Z12 -> 100 | AB13: 59405 | AC13: =AB13-AB12 -> 214 | AD13: 106512 | AE13: =AD13-AD12 -> 365 | AF13: 57659 | AG13: =AF13-AF12 -> 190 | AH13: 287444 | AI13: =AH13-AH12 -> 950 | AK13: =SUM(D13,F13,I13,K13,M13,P13,S13,V13,Y13) -> 40084 | AL13: =SUM(P13,S13,V13,Y13,AA13,AC13,AE13,AG13,AI13) -> 7873
A14: 44323 | C14: 107474 | D14: =(C14-C13)*10 -> 3740 | E14: 167824 | F14: =(E14-E13)*10 -> 6780 | G14: 959526 | H14: =(G14-G13)*10 -> 14070 | I14: =H14*50% -> 7035 | J14: 149713 | K14: =(J14-J13)*10 -> 5580 | L14: 233498 | M14: =(L14-L13)*10 -> 8850 | N14: 863047 | O14: =(N14-N13)*10 -> 7910 | P14: =O14*50% -> 3955 | Q14: 146872 | R14: =(Q14-Q13)*10 -> 20 | S14: =R14*50% -> 10 | T14: 77971 | U14: =(T14-T13)*10 -> 7130 | V14: =U14*50% -> 3565 | W14: 152923 | X14: =W14-W13 -> 44 | Y14: =X14*50% -> 22 | Z14: 29307 | AA14: =Z14-Z13 -> 84 | AB14: 59606 | AC14: =AB14-AB13 -> 201 | AD14: 106860 | AE14: =AD14-AD13 -> 348 | AF14: 57836 | AG14: =AF14-AF13 -> 177 | AH14: 288363 | AI14: =AH14-AH13 -> 919 | AK14: =SUM(D14,F14,I14,K14,M14,P14,S14,V14,Y14) -> 39537 | AL14: =SUM(P14,S14,V14,Y14,AA14,AC14,AE14,AG14,AI14) -> 9281
A15: 44324 | C15: 107879 | D15: =(C15-C14)*10 -> 4050 | E15: 168603 | F15: =(E15-E14)*10 -> 7790 | G15: 961084 | H15: =(G15-G14)*10 -> 15580 | I15: =H15*50% -> 7790 | J15: 150352 | K15: =(J15-J14)*10 -> 6390 | L15: 234490 | M15: =(L15-L14)*10 -> 9920 | N15: 863621 | O15: =(N15-N14)*10 -> 5740 | P15: =O15*50% -> 2870 | Q15: 147683 | R15: =(Q15-Q14)*10 -> 8110 | S15: =R15*50% -> 4055 | T15: 77974 | U15: =(T15-T14)*10 -> 30 | V15: =U15*50% -> 15 | W15: 153513 | X15: =W15-W14 -> 590 | Y15: =X15*50% -> 295 | Z15: 29403 | AA15: =Z15-Z14 -> 96 | AB15: 59812 | AC15: =AB15-AB14 -> 206 | AD15: 107223 | AE15: =AD15-AD14 -> 363 | AF15: 58031 | AG15: =AF15-AF14 -> 195 | AH15: 289353 | AI15: =AH15-AH14 -> 990 | AK15: =SUM(D15,F15,I15,K15,M15,P15,S15,V15,Y15) -> 43175 | AL15: =SUM(P15,S15,V15,Y15,AA15,AC15,AE15,AG15,AI15) -> 9085
A16: 44325 | C16: 108259 | D16: =(C16-C15)*10 -> 3800 | E16: 169332 | F16: =(E16-E15)*10 -> 7290 | G16: 962485 | H16: =(G16-G15)*10 -> 14010 | I16: =H16*50% -> 7005 | J16: 150936 | K16: =(J16-J15)*10 -> 5840 | L16: 235411 | M16: =(L16-L15)*10 -> 9210 | N16: 864152 | O16: =(N16-N15)*10 -> 5310 | P16: =O16*50% -> 2655 | Q16: 148651 | R16: =(Q16-Q15)*10 -> 9680 | S16: =R16*50% -> 4840 | T16: 77976 | U16: =(T16-T15)*10 -> 20 | V16: =U16*50% -> 10 | W16: 154125 | X16: =W16-W15 -> 612 | Y16: =X16*50% -> 306 | Z16: 29492 | AA16: =Z16-Z15 -> 89 | AB16: 59993 | AC16: =AB16-AB15 -> 181 | AD16: 107548 | AE16: =AD16-AD15 -> 325 | AF16: 58204 | AG16: =AF16-AF15 -> 173 | AH16: 290240 | AI16: =AH16-AH15 -> 887 | AK16: =SUM(D16,F16,I16,K16,M16,P16,S16,V16,Y16) -> 40956 | AL16: =SUM(P16,S16,V16,Y16,AA16,AC16,AE16,AG16,AI16) -> 9466
A17: 44326 | C17: 108648 | D17: =(C17-C16)*10 -> 3890 | E17: 170008 | F17: =(E17-E16)*10 -> 6760 | G17: 963880 | H17: =(G17-G16)*10 -> 13950 | I17: =H17*50% -> 6975 | J17: 151517 | K17: =(J17-J16)*10 -> 5810 | L17: 236331 | M17: =(L17-L16)*10 -> 9200 | N17: 864823 | O17: =(N17-N16)*10 -> 6710 | P17: =O17*50% -> 3355 | Q17: 149605 | R17: =(Q17-Q16)*10 -> 9540 | S17: =R17*50% -> 4770 | T17: 78339 | U17: =(T17-T16)*10 -> 3630 | V17: =U17*50% -> 1815 | W17: 154153 | X17: =W17-W16 -> 28 | Y17: =X17*50% -> 14 | Z17: 29580 | AA17: =Z17-Z16 -> 88 | AB17: 60192 | AC17: =AB17-AB16 -> 199 | AD17: 107912 | AE17: =AD17-AD16 -> 364 | AF17: 58387 | AG17: =AF17-AF16 -> 183 | AH17: 291202 | AI17: =AH17-AH16 -> 962 | AK17: =SUM(D17,F17,I17,K17,M17,P17,S17,V17,Y17) -> 42589 | AL17: =SUM(P17,S17,V17,Y17,AA17,AC17,AE17,AG17,AI17) -> 11750
A18: 44327 | C18: 109029 | D18: =(C18-C17)*10 -> 3810 | E18: 170687 | F18: =(E18-E17)*10 -> 6790 | G18: 965320 | H18: =(G18-G17)*10 -> 14400 | I18: =H18*50% -> 7200 | J18: 152080 | K18: =(J18-J17)*10 -> 5630 | L18: 237212 | M18: =(L18-L17)*10 -> 8810 | N18: 865336 | O18: =(N18-N17)*10 -> 5130 | P18: =O18*50% -> 2565 | Q18: 150570 | R18: =(Q18-Q17)*10 -> 9650 | S18: =R18*50% -> 4825 | T18: 78683 | U18: =(T18-T17)*10 -> 3440 | V18: =U18*50% -> 1720 | W18: 154626 | X18: =W18-W17 -> 473 | Y18: =X18*50% -> 236.5 | Z18: 29666 | AA18: =Z18-Z17 -> 86 | AB18: 60384 | AC18: =AB18-AB17 -> 192 | AD18: 108274 | AE18: =AD18-AD17 -> 362 | AF18: 58567 | AG18: =AF18-AF17 -> 180 | AH18: 292160 | AI18: =AH18-AH17 -> 958 | AK18: =SUM(D18,F18,I18,K18,M18,P18,S18,V18,Y18) -> 41586.5 | AL18: =SUM(P18,S18,V18,Y18,AA18,AC18,AE18,AG18,AI18) -> 11124.5
A19: 44328 | C19: 109434 | D19: =(C19-C18)*10 -> 4050 | E19: 171409 | F19: =(E19-E18)*10 -> 7220 | G19: 966880 | H19: =(G19-G18)*10 -> 15600 | I19: =H19*50% -> 7800 | J19: 152680 | K19: =(J19-J18)*10 -> 6000 | L19: 238129 | M19: =(L19-L18)*10 -> 9170 | N19: 865879 | O19: =(N19-N18)*10 -> 5430 | P19: =O19*50% -> 2715 | Q19: 151662 | R19: =(Q19-Q18)*10 -> 10920 | S19: =R19*50% -> 5460 | T19: 79397 | U19: =(T19-T18)*10 -> 7140 | V19: =U19*50% -> 3570 | W19: 154667 | X19: =W19-W18 -> 41 | Y19: =X19*50% -> 20.5 | Z19: 29760 | AA19: =Z19-Z18 -> 94 | AB19: 60515 | AC19: =AB19-AB18 -> 131 | AD19: 108651 | AE19: =AD19-AD18 -> 377 | AF19: 58757 | AG19: =AF19-AF18 -> 190 | AH19: 293132 | AI19: =AH19-AH18 -> 972 | AK19: =SUM(D19,F19,I19,K19,M19,P19,S19,V19,Y19) -> 46005.5 | AL19: =SUM(P19,S19,V19,Y19,AA19,AC19,AE19,AG19,AI19) -> 13529.5
A20: 44329 | C20: 109823 | D20: =(C20-C19)*10 -> 3890 | E20: 172111 | F20: =(E20-E19)*10 -> 7020 | G20: 968388 | H20: =(G20-G19)*10 -> 15080 | I20: =H20*50% -> 7540 | J20: 153281 | K20: =(J20-J19)*10 -> 6010 | L20: 239039 | M20: =(L20-L19)*10 -> 9100 | N20: 866400 | O20: =(N20-N19)*10 -> 5210 | P20: =O20*50% -> 2605 | Q20: 153281 | R20: =(Q20-Q19)*10 -> 16190 | S20: =R20*50% -> 8095 | T20: 80166 | U20: =(T20-T19)*10 -> 7690 | V20: =U20*50% -> 3845 | W20: 154710 | X20: =W20-W19 -> 43 | Y20: =X20*50% -> 21.5 | Z20: 29856 | AA20: =Z20-Z19 -> 96 | AB20: 60798 | AC20: =AB20-AB19 -> 283 | AD20: 109016 | AE20: =AD20-AD19 -> 365 | AF20: 58938 | AG20: =AF20-AF19 -> 181 | AH20: 294073 | AI20: =AH20-AH19 -> 941 | AK20: =SUM(D20,F20,I20,K20,M20,P20,S20,V20,Y20) -> 48126.5 | AL20: =SUM(P20,S20,V20,Y20,AA20,AC20,AE20,AG20,AI20) -> 16432.5
... A37: 44346 | C37: 116899 | D37: =(C37-C36)*10 -> 4350 | E37: 184009 | F37: =(E37-E36)*10 -> 7050 | G37: 993652 | H37: =(G37-G36)*10 -> 15600 | I37: =H37*50% -> 7800 | J37: 163777 | K37: =(J37-J36)*10 -> 6330 | L37: 255236 | M37: =(L37-L36)*10 -> 9760 | N37: 875684 | O37: =(N37-N36)*10 -> 5660 | P37: =O37*50% -> 2830 | Q37: 168785 | R37: =(Q37-Q36)*10 -> 8740 | S37: =R37*50% -> 4370 | T37: 88999 | U37: =(T37-T36)*10 -> 2580 | V37: =U37*50% -> 1290 | W37: 166953 | X37: =W37-W36 -> 1244 | Y37: =X37*50% -> 622 | Z37: 31492 | AA37: =Z37-Z36 -> 96 | AB37: 64156 | AC37: =AB37-AB36 -> 197 | AD37: 115053 | AE37: =AD37-AD36 -> 340 | AF37: 61931 | AG37: =AF37-AF36 -> 179 | AH37: 310898 | AI37: =AH37-AH36 -> 1021 | AK37: =SUM(D37,F37,I37,K37,M37,P37,S37,V37,Y37) -> 44402 | AL37: =SUM(P37,S37,V37,Y37,AA37,AC37,AE37,AG37,AI37) -> 10945
A38: 44347 | C38: 117326 | D38: =(C38-C37)*10 -> 4270 | E38: 184712 | F38: =(E38-E37)*10 -> 7030 | G38: 995172 | H38: =(G38-G37)*10 -> 15200 | I38: =H38*50% -> 7600 | J38: 164404 | K38: =(J38-J37)*10 -> 6270 | L38: 256163 | M38: =(L38-L37)*10 -> 9270 | N38: 876249 | O38: =(N38-N37)*10 -> 5650 | P38: =O38*50% -> 2825 | Q38: 169485 | R38: =(Q38-Q37)*10 -> 7000 | S38: =R38*50% -> 3500 | T38: 89303 | U38: =(T38-T37)*10 -> 3040 | V38: =U38*50% -> 1520 | W38: 168104 | X38: =(W38-W37)*10 -> 11510 | Y38: =X38*50% -> 5755 | Z38: 31587 | AA38: =Z38-Z37 -> 95 | AB38: 64363 | AC38: =AB38-AB37 -> 207 | AD38: 115402 | AE38: =AD38-AD37 -> 349 | AF38: 62109 | AG38: =AF38-AF37 -> 178 | AH38: 311904 | AI38: =AH38-AH37 -> 1006 | AK38: =SUM(D38,F38,I38,K38,M38,P38,S38,V38,Y38) -> 48040 | AL38: =SUM(P38,S38,V38,Y38,AA38,AC38,AE38,AG38,AI38) -> 15435

Sheet Athens Daily - Water
C1: FSH | E1: FSH | G1: FSH | I1: FSH | K1: FSH & FSP | O1: FSP
C2: Hotel & podium Fresh Water | E2: Food & Beverage Outlets | G2: Fountains | I2: Swimming Pool | K2: Laundry (FSH 55% : FSP 45%) | O2: Place - Guest Floor Fresh Water
C3: M16601852 | E3: M118410300 | G3: M16449102 | I3: M9192527 | K3: M16601455 | O3: M16601818 | R3: Daily Total consumption
A4: Tariff Type
A5: Date | C5: Reading | D5: Differecne m3 | E5: Reading | F5: Differecne m3 | G5: Reading | H5: Differecne m3 | I5: Reading | J5: Differecne m3 | K5: Reading | L5: Differecne m3 | M5: FSH | N5: FSP | O5: Reading | P5: Differecne m3
A6: 44316 | C6: 208178 | E6: 208141 | G6: 6455.5979 | I6: 13342 | K6: 146995 | O6: 107027
A7: 44317 | C7: 208441 | D7: =(C7-C6) -> 263 | E7: 208510 | F7: =(E7-E6) -> 369 | G7: 6458 | H7: =(G7-G6) -> 2.4021 | I7: 13355 | J7: =(I7-I6) -> 13 | K7: 147205 | L7: =(K7-K6) -> 210 | M7: =L7*55% -> 115.5 | N7: =L7*45% -> 94.5 | O7: 107125 | P7: =(O7-O6) -> 98 | R7: =SUM(D7,F7,M71,H7) -> 634.4021 | S7: =SUM(N7,P7) -> 192.5
A8: 44318 | C8: 208653 | D8: =(C8-C7) -> 212 | E8: 208816 | F8: =(E8-E7) -> 306 | G8: 6462 | H8: =(G8-G7) -> 4 | I8: 13366 | J8: =(I8-I7) -> 11 | K8: 147365 | L8: =(K8-K7) -> 160 | M8: =L8*55% -> 88 | N8: =L8*45% -> 72 | O8: 107209 | P8: =(O8-O7) -> 84 | R8: =SUM(D8,F8,M72,H8) -> 522 | S8: =SUM(N8,P8) -> 156
A9: 44319 | C9: 208796 | D9: =(C9-C8) -> 143 | E9: 209081 | F9: =(E9-E8) -> 265 | G9: 6468 | H9: =(G9-G8) -> 6 | I9: 13382 | J9: =(I9-I8) -> 16 | K9: 147534 | L9: =(K9-K8) -> 169 | M9: =L9*55% -> 92.95 | N9: =L9*45% -> 76.05 | O9: 107283 | P9: =(O9-O8) -> 74 | R9: =SUM(D9,F9,M73,H9) -> 414 | S9: =SUM(N9,P9) -> 150.05
A10: 44320 | C10: 208935 | D10: =(C10-C9) -> 139 | E10: 209344 | F10: =(E10-E9) -> 263 | G10: 6471 | H10: =(G10-G9) -> 3 | I10: 13394 | J10: =(I10-I9) -> 12 | K10: 147719 | L10: =(K10-K9) -> 185 | M10: =L10*55% -> 101.75 | N10: =L10*45% -> 83.25 | O10: 107498 | P10: =(O10-O9) -> 215 | R10: =SUM(D10,F10,M74,H10) -> 405 | S10: =SUM(N10,P10) -> 298.25
A11: 44321 | C11: 209041 | D11: =(C11-C10) -> 106 | E11: 209595 | F11: =(E11-E10) -> 251 | G11: 6473 | H11: =(G11-G10) -> 2 | I11: 13400 | J11: =(I11-I10) -> 6 | K11: 147855 | L11: =(K11-K10) -> 136 | M11: =L11*55% -> 74.8 | N11: =L11*45% -> 61.2 | O11: 107594 | P11: =(O11-O10) -> 96 | R11: =SUM(D11,F11,M75,H11) -> 359 | S11: =SUM(N11,P11) -> 157.2
A12: 44322 | C12: 209143 | D12: =(C12-C11) -> 102 | E12: 209874 | F12: =(E12-E11) -> 279 | G12: 6479 | H12: =(G12-G11) -> 6 | I12: 13409 | J12: =(I12-I11) -> 9 | K12: 147991 | L12: =(K12-K11) -> 136 | M12: =L12*55% -> 74.8 | N12: =L12*45% -> 61.2 | O12: 107673 | P12: =(O12-O11) -> 79 | R12: =SUM(D12,F12,M76,H12) -> 387 | S12: =SUM(N12,P12) -> 140.2
A13: 44323 | C13: 209238 | D13: =(C13-C12) -> 95 | E13: 210126 | F13: =(E13-E12) -> 252 | G13: 6485 | H13: =(G13-G12) -> 6 | I13: 13421 | J13: =(I13-I12) -> 12 | K13: 148123 | L13: =(K13-K12) -> 132 | M13: =L13*55% -> 72.6 | N13: =L13*45% -> 59.4 | O13: 107763 | P13: =(O13-O12) -> 90 | R13: =SUM(D13,F13,M77,H13) -> 353 | S13: =SUM(N13,P13) -> 149.4
A14: 44324 | C14: 209349 | D14: =(C14-C13) -> 111 | E14: 210409 | F14: =(E14-E13) -> 283 | G14: 6490 | H14: =(G14-G13) -> 5 | I14: 13431 | J14: =(I14-I13) -> 10 | K14: 148250 | L14: =(K14-K13) -> 127 | M14: =L14*55% -> 69.85 | N14: =L14*45% -> 57.15 | O14: 107826 | P14: =(O14-O13) -> 63 | R14: =SUM(D14,F14,M78,H14) -> 399 | S14: =SUM(N14,P14) -> 120.15
A15: 44325 | C15: 209497 | D15: =(C15-C14) -> 148 | E15: 210757 | F15: =(E15-E14) -> 348 | G15: 6493 | H15: =(G15-G14) -> 3 | I15: 13443 | J15: =(I15-I14) -> 12 | K15: 148402 | L15: =(K15-K14) -> 152 | M15: =L15*55% -> 83.6 | N15: =L15*45% -> 68.4 | O15: 107915 | P15: =(O15-O14) -> 89 | R15: =SUM(D15,F15,M79,H15) -> 499 | S15: =SUM(N15,P15) -> 157.4
A16: 44326 | C16: 209634 | D16: =(C16-C15) -> 137 | E16: 211006 | F16: =(E16-E15) -> 249 | G16: 6496 | H16: =(G16-G15) -> 3 | I16: 13458 | J16: =(I16-I15) -> 15 | K16: 148529 | L16: =(K16-K15) -> 127 | M16: =L16*55% -> 69.85 | N16: =L16*45% -> 57.15 | O16: 108003 | P16: =(O16-O15) -> 88 | R16: =SUM(D16,F16,M80,H16) -> 389 | S16: =SUM(N16,P16) -> 145.15
A17: 44327 | C17: 209748 | D17: =(C17-C16) -> 114 | E17: 211281 | F17: =(E17-E16) -> 275 | G17: 6504 | H17: =(G17-G16) -> 8 | I17: 13467 | J17: =(I17-I16) -> 9 | K17: 148681 | L17: =(K17-K16) -> 152 | M17: =L17*55% -> 83.6 | N17: =L17*45% -> 68.4 | O17: 108078 | P17: =(O17-O16) -> 75 | R17: =SUM(D17,F17,M81,H17) -> 397 | S17: =SUM(N17,P17) -> 143.4
A18: 44328 | C18: 209901 | D18: =(C18-C17) -> 153 | E18: 211531 | F18: =(E18-E17) -> 250 | G18: 6507 | H18: =(G18-G17) -> 3 | I18: 13480 | J18: =(I18-I17) -> 13 | K18: 148843 | L18: =(K18-K17) -> 162 | M18: =L18*55% -> 89.1 | N18: =L18*45% -> 72.9 | O18: 108179 | P18: =(O18-O17) -> 101 | R18: =SUM(D18,F18,M82,H18) -> 406 | S18: =SUM(N18,P18) -> 173.9
... A20: 44330 | C20: 210227 | D20: =(C20-C19) -> 173 | E20: 212031 | F20: =(E20-E19) -> 264 | G20: 6514 | H20: =(G20-G19) -> 4 | I20: 13493 | J20: =(I20-I19) -> 4 | K20: 149132 | L20: =(K20-K19) -> 143 | M20: =L20*55% -> 78.65 | N20: =L20*45% -> 64.35 | O20: 108328 | P20: =(O20-O19) -> 74 | R20: =SUM(D20,F20,M84,H20) -> 441 | S20: =SUM(N20,P20) -> 138.35
A21: 44331 | C21: =(C22+C20)/2 -> 210418 | D21: =(C21-C20) -> 191 | E21: =(E22+E20)/2 -> 212356.5 | F21: =(E21-E20) -> 325.5 | G21: 6522.6582 | H21: =(G21-G20) -> 8.6582 | I21: 13504 | J21: =(I21-I20) -> 11 | K21: 149286 | L21: =(K21-K20) -> 154 | M21: =L21*55% -> 84.7 | N21: =L21*45% -> 69.3 | O21: =(O22+O20)/2 -> 108407 | P21: =(O21-O20) -> 79 | R21: =SUM(D21,F21,M85,H21) -> 525.1582 | S21: =SUM(N21,P21) -> 148.3
A22: 44332 | C22: 210609 | D22: =(C22-C21) -> 191 | E22: 212682 | F22: =(E22-E21) -> 325.5 | G22: 6532.6582 | H22: =(G22-G21) -> 10 | I22: 13513 | J22: =(I22-I21) -> 9 | K22: 149441 | L22: =(K22-K21) -> 155 | M22: =L22*55% -> 85.25 | N22: =L22*45% -> 69.75 | O22: 108486 | P22: =(O22-O21) -> 79 | R22: =SUM(D22,F22,M86,H22) -> 526.5 | S22: =SUM(N22,P22) -> 148.75
A23: 44333 | C23: 210771 | D23: =(C23-C22) -> 162 | E23: 212999 | F23: =(E23-E22) -> 317 | G23: 6528.3667 | H23: =(G23-G22) -> -4.2915 | I23: 13520 | J23: =(I23-I22) -> 7 | K23: 149607 | L23: =(K23-K22) -> 166 | M23: =L23*55% -> 91.3 | N23: =L23*45% -> 74.7 | O23: 108562 | P23: =(O23-O22) -> 76 | R23: =SUM(D23,F23,M87,H23) -> 474.7085 | S23: =SUM(N23,P23) -> 150.7
A24: 44334 | C24: 210937 | D24: =(C24-C23) -> 166 | E24: 213281 | F24: =(E24-E23) -> 282 | G24: 6533.7267 | H24: =(G24-G23) -> 5.36 | I24: 13529 | J24: =(I24-I23) -> 9 | K24: 149784 | L24: =(K24-K23) -> 177 | M24: =L24*55% -> 97.35 | N24: =L24*45% -> 79.65 | O24: 108641 | P24: =(O24-O23) -> 79 | R24: =SUM(D24,F24,M88,H24) -> 453.36 | S24: =SUM(N24,P24) -> 158.65
A25: 44335 | C25: 211146 | D25: =(C25-C24) -> 209 | E25: 213503 | F25: =(E25-E24) -> 222 | G25: 6538.999 | H25: =(G25-G24) -> 5.2723 | I25: 13557 | J25: =(I25-I24) -> 28 | K25: 149928 | L25: =(K25-K24) -> 144 | M25: =L25*55% -> 79.2 | N25: =L25*45% -> 64.8 | O25: 108716 | P25: =(O25-O24) -> 75 | R25: =SUM(D25,F25,M89,H25) -> 436.2723 | S25: =SUM(N25,P25) -> 139.8
A26: 44336 | C26: 211340 | D26: =(C26-C25) -> 194 | E26: 213842 | F26: =(E26-E25) -> 339 | G26: 6543.263 | H26: =(G26-G25) -> 4.264 | I26: 13558 | J26: =(I26-I25) -> 1 | K26: 150116 | L26: =(K26-K25) -> 188 | M26: =L26*55% -> 103.4 | N26: =L26*45% -> 84.6 | O26: 108799 | P26: =(O26-O25) -> 83 | R26: =SUM(D26,F26,M90,H26) -> 537.264 | S26: =SUM(N26,P26) -> 167.6
A27: 44337 | C27: 211511 | D27: =(C27-C26) -> 171 | E27: 214098 | F27: =(E27-E26) -> 256 | G27: 6548.692 | H27: =(G27-G26) -> 5.429 | I27: 13561 | J27: =(I27-I26) -> 3 | K27: 150283 | L27: =(K27-K26) -> 167 | M27: =L27*55% -> 91.85 | N27: =L27*45% -> 75.15 | O27: 108898 | P27: =(O27-O26) -> 99 | R27: =SUM(D27,F27,M91,H27) -> 432.429 | S27: =SUM(N27,P27) -> 174.15
A28: 44338 | C28: 211672 | D28: =(C28-C27) -> 161 | E28: 214395 | F28: =(E28-E27) -> 297 | G28: 6553.8908 | H28: =(G28-G27) -> 5.1988 | I28: 13576 | J28: =(I28-I27) -> 15 | K28: 150441 | L28: =(K28-K27) -> 158 | M28: =L28*55% -> 86.9 | N28: =L28*45% -> 71.1 | O28: 108939 | P28: =(O28-O27) -> 41 | R28: =SUM(D28,F28,M92,H28) -> 463.1988 | S28: =SUM(N28,P28) -> 112.1
A29: 44339 | C29: 211875 | D29: =(C29-C28) -> 203 | E29: 214782 | F29: =(E29-E28) -> 387 | G29: 6562.1251 | H29: =(G29-G28) -> 8.2343 | I29: 13579 | J29: =(I29-I28) -> 3 | K29: 150608 | L29: =(K29-K28) -> 167 | M29: =L29*55% -> 91.85 | N29: =L29*45% -> 75.15 | O29: 109015 | P29: =(O29-O28) -> 76 | R29: =SUM(D29,F29,M93,H29) -> 598.2343 | S29: =SUM(N29,P29) -> 151.15
A30: 44340 | C30: 212087 | D30: =(C30-C29) -> 212 | E30: 215032 | F30: =(E30-E29) -> 250 | G30: 6566 | H30: =(G30-G29) -> 3.8749 | I30: =(I29+I31)/2 -> 13599 | J30: =(I30-I29) -> 20 | K30: 150766 | L30: =(K30-K29) -> 158 | M30: =L30*55% -> 86.9 | N30: =L30*45% -> 71.1 | O30: =(O29+O31)/2 -> 109103 | P30: =(O30-O29) -> 88 | R30: =SUM(D30,F30,M94,H30) -> 465.8749 | S30: =SUM(N30,P30) -> 159.1
A31: 44341 | C31: 212209 | D31: =(C31-C30) -> 122 | E31: 215309 | F31: =(E31-E30) -> 277 | G31: 6570 | H31: =(G31-G30) -> 4 | I31: 13619 | J31: =(I31-I30) -> 20 | K31: 150933 | L31: =(K31-K30) -> 167 | M31: =L31*55% -> 91.85 | N31: =L31*45% -> 75.15 | O31: 109191 | P31: =(O31-O30) -> 88 | R31: =SUM(D31,F31,M95,H31) -> 403 | S31: =SUM(N31,P31) -> 163.15
A32: 44342 | C32: 212377 | D32: =(C32-C31) -> 168 | E32: 215587 | F32: =(E32-E31) -> 278 | G32: 6573.5 | H32: =(G32-G31) -> 3.5 | I32: 13626 | J32: =(I32-I31) -> 7 | K32: 151087 | L32: =(K32-K31) -> 154 | M32: =L32*55% -> 84.7 | N32: =L32*45% -> 69.3 | O32: 109257 | P32: =(O32-O31) -> 66 | R32: =SUM(D32,F32,M96,H32) -> 449.5 | S32: =SUM(N32,P32) -> 135.3
A33: 44343 | C33: 212528 | D33: =(C33-C32) -> 151 | E33: 215858 | F33: =(E33-E32) -> 271 | G33: 6574.5 | H33: =(G33-G32) -> 1 | I33: 13635 | J33: =(I33-I32) -> 9 | K33: 151243 | L33: =(K33-K32) -> 156 | M33: =L33*55% -> 85.8 | N33: =L33*45% -> 70.2 | O33: 109351 | P33: =(O33-O32) -> 94 | R33: =SUM(D33,F33,M97,H33) -> 423 | S33: =SUM(N33,P33) -> 164.2
A34: 44344 | C34: 212686 | D34: =(C34-C33) -> 158 | E34: 216161 | F34: =(E34-E33) -> 303 | G34: 6583.73 | H34: =(G34-G33) -> 9.23 | I34: 13647 | J34: =(I34-I33) -> 12 | K34: 151409 | L34: =(K34-K33) -> 166 | M34: =L34*55% -> 91.3 | N34: =L34*45% -> 74.7 | O34: 109414 | P34: =(O34-O33) -> 63 | R34: =SUM(D34,F34,M98,H34) -> 470.23 | S34: =SUM(N34,P34) -> 137.7
A35: 44345 | C35: 212856 | D35: =(C35-C34) -> 170 | E35: 216455 | F35: =(E35-E34) -> 294 | G35: 6587 | H35: =(G35-G34) -> 3.27 | I35: =(I37-I34)/3+I34 -> 13662.667 | J35: =(I35-I34) -> 15.666667 | K35: 151566 | L35: =(K35-K34) -> 157 | M35: =L35*55% -> 86.35 | N35: =L35*45% -> 70.65 | O35: 109486 | P35: =(O35-O34) -> 72 | R35: =SUM(D35,F35,M99,H35) -> 467.27 | S35: =SUM(N35,P35) -> 142.65
A36: 44346 | C36: 213068 | D36: =(C36-C35) -> 212 | E36: 216762 | F36: =(E36-E35) -> 307 | G36: 6590 | H36: =(G36-G35) -> 3 | I36: =(I37-I34)/3+I35 -> 13678.333 | J36: =(I36-I35) -> 15.666667 | K36: 151734 | L36: =(K36-K35) -> 168 | M36: =L36*55% -> 92.4 | N36: =L36*45% -> 75.6 | O36: 109553 | P36: =(O36-O35) -> 67 | R36: =SUM(D36,F36,M100,H36) -> 522 | S36: =SUM(N36,P36) -> 142.6
A37: 44347 | C37: 213232 | D37: =(C37-C36) -> 164 | E37: 217049 | F37: =(E37-E36) -> 287 | G37: 6593.95 | H37: =(G37-G36) -> 3.95 | I37: 13694 | J37: =(I37-I36) -> 15.666667 | K37: 151903 | L37: =(K37-K36) -> 169 | M37: =L37*55% -> 92.95 | N37: =L37*45% -> 76.05 | O37: 109633 | P37: =(O37-O36) -> 80 | R37: =SUM(D37,F37,M101,H37) -> 454.95 | S37: =SUM(N37,P37) -> 156.05
D38: =SUM(D7:D37) -> 5054 | F38: =SUM(F7:F37) -> 8908 | H38: =SUM(H7:H37) -> 138.3521 | J38: =SUM(J7:J37) -> 352 | L38: =SUM(L7:L37) -> 4908 | P38: =SUM(P7:P37) -> 2606

Sheet Athens Daily - Gas
C1: FSH & FSP | G1: FSH | I1: FSH | K1: FSH | M1: FSH | O1: FSH | Q1: FSH | S1: FSH | U1: FSH | W1: FSH | Y1: FSH | AA1: FSH | AC1: FSH | AE1: FSH | AG1: FSH | AI1: FSH | AK1: FSH | AM1: FSP | AO1: FSP | AQ1: FSP | AS1: FSP | AU1: FSP | AW1: FSP | AY1: FSP | BA1: FSP | BC1: FSP | BE1: FSP
C2: B2/F Steam Boiler Room | G2: B1/F Main Kitchen | I2: P1/F Lobby Lounge | K2: P2/F Grand Ball Room | M2: P3 Steward | O2: P4/F Chinese Restaurant | Q2: P4/F Junior Ball Room | S2: P5/F Staff Dining | U2: P6/F Pool side bar pantry | W2: P6/F French Restaurant | Y2: P5/F Condensing Boiler Room | AA2: P5/F Filtration Plan Room | AC2: L8/F Plant Room | AE2: L46/F Plant Room | AG2: L46/F Plant Room | AI2: L46/F Plant Room | AK2: L46/F Plant Room | AM2: SHT 8/F Plant Room | AO2: SHT 40/F Plant Room | AQ2: SHT 57/F Condensing Boiler Room | AS2: SHT 57/F Condensing Boiler Room | AU2: SHT 60/F - Room 6023 ( Penhouse 1 ) | AW2: SHT 60/F - Room 6038 ( Penhouse 2 ) | AY2: L40/F Plant Room | BA2: L40/F Plant Room | BC2: L57/F Plant Room | BE2: L57/F Plant Room
C3: Steam Boiler for Hot Water & Laundry ( FSH 60% : FSP 40%) | E3: FSH | F3: FSP | G3: Kitchen | I3: Kitchen | K3: Kitchen | M3: Dish Washing area | O3: Kitchen | Q3: Kitchen | S3: Kitchen | U3: Kitchen | W3: Kitchen | Y3: Condensing Boiler for P6 Swimming Pool & Jacuzzi | AA3: 6/F Patio Spaces heater | AC3: Dehumidifier for Guest Rooms RH Control | AE3: Dehumidifier for Guest Rooms RH Control | AG3: Presidential Room Room 4305 | AI3: New Gas Heat Pump | AK3: New Gas Heat Pump ( Heater ) | AM3: Dehumidifier For Guest Rooms RH Control | AO3: Dehumidifier For Guest Rooms RH Control | AQ3: Condensing Boiler for 59/F Swimming Pool & Jacuzzis | AS3: 59/F Patio Spaces heater | AU3: Gas appliances ( Include Patio Space Heater ) | AW3: Gas appliances ( Include Patio Space Heater ) | AY3: New Gas Heat Pump | BA3: New Gas Heat Pump ( Heater ) | BC3: New Gas Heat Pump | BE3: New Gas Heat Pump ( Heater )
C4: 0234229050 | E4: Ratio | G4: 0234229130 | I4: 0234230090 | K4: 0234229210 | M4: 7092801222 | O4: 0234229460 | Q4: 0234229380 | S4: 0234229540 | U4: 0234229620 | W4: 0234230740 | Y4: 0234229870 | AA4: 0234229790 | AC4: 0234228820 | AE4: 0234228990 | AG4: 0234230820 | AI4: 7105826734 | AK4: 7105825932 | AM4: 0234230170 | AO4: 0234230250 | AQ4: 0234230330 | AS4: 0234230410 | AU4: 0234230580 | AW4: 0234230660 | AY4: 7111912486 | BA4: 7111911842 | BC4: 7111913281 | BE4: 7111912723 | BH4: Daily Total consumption
A5: Gas Meter | C5: 9955475 | E5: 0.6 | F5: 0.4 | G5: 436641 | I5: 436656 | K5: 431271 | M5: 1038664 | O5: 522469 | Q5: 431269 | S5: 436624 | U5: 5399693 | W5: 522607 | Y5: 436606 | AA5: 432481 | AC5: 410677 | AE5: 431229 | AG5: 522557 | AI5: 0333732 | AK5: 0655375 | AM5: 431241 | AO5: 410724 | AQ5: 9313879 | AS5: 4500420S | AU5: 436758 | AW5: 431227 | AY5: 744483 | BA5: 119314 | BC5: 1053229 | BE5: 1053215
A6: Tariff Type
A7: Date | C7: Reading | D7: Differecne MJ | E7: Differecne MJ | F7: Differecne MJ | G7: Reading | H7: Differecne MJ | I7: Reading | J7: Differecne MJ | K7: Reading | L7: Differecne MJ | M7: Reading | N7: Differecne MJ | O7: Reading | P7: Differecne MJ | Q7: Reading | R7: Differecne MJ | S7: Reading | T7: Differecne MJ | U7: Reading | V7: Differecne MJ | W7: Reading | X7: Differecne MJ | Y7: Reading | Z7: Differecne MJ | AA7: Reading | AB7: Differecne MJ | AC7: Reading | AD7: Differecne MJ | AE7: Reading | AF7: Differecne MJ | AG7: Reading | AH7: Differecne MJ | AI7: Reading | AJ7: Differecne MJ | AK7: Reading | AL7: Differecne MJ | AM7: Reading | AN7: Differecne MJ | AO7: Reading | AP7: Differecne MJ | AQ7: Reading | AR7: Differecne MJ | AS7: Reading | AT7: Differecne MJ | AU7: Reading | AV7: Differecne MJ | AW7: Reading | AX7: Differecne MJ | AY7: Reading | AZ7: Differecne MJ | BA7: Reading | BB7: Differecne MJ | BC7: Reading | BD7: Differecne MJ | BE7: Reading | BF7: Differecne MJ | BH7: FSH | BI7: FSP
A8: 44316 | C8: 6004304 | G8: 281100 | I8: 121085 | K8: 258044 | M8: 24470 | O8: 258470 | Q8: 447388 | S8: 720709 | U8: 99107.247 | W8: 80540 | Y8: 1499005 | AA8: 13232 | AC8: 453460 | AE8: 526296 | AG8: 49712 | AI8: 414751 | AK8: 102770 | AM8: 571442 | AO8: 924404 | AQ8: 77468 | AS8: 2262 | AU8: 939 | AW8: 3109 | AY8: 315216 | BA8: 161101 | BC8: 215570 | BE8: 5347
A9: 44317 | C9: 6006509 | D9: =(+C9-+C8)*48 -> 105840 | E9: =D9*0.6 -> 63504 | F9: =D9*0.4 -> 42336 | G9: 281143 | H9: =(+G9-+G8)*48 -> 2064 | I9: 121260 | J9: =(+I9-+I8)*48 -> 8400 | K9: 258092 | L9: =(+K9-+K8)*48 -> 2304 | M9: 24695 | N9: =(+M9-+M8)*48 -> 10800 | O9: 258663 | P9: =(+O9-+O8)*48 -> 9264 | Q9: 447440 | R9: =(+Q9-+Q8)*48 -> 2496 | S9: 720848 | T9: =(+S9-+S8)*48 -> 6672 | U9: 99130.803 | V9: =(+U9-+U8)*48 -> 1130.688 | W9: 80555 | X9: =(+W9-+W8)*48 -> 720 | Y9: 1499059 | Z9: =(+Y9-+Y8)*48 -> 2592 | AA9: 13264 | AB9: =(+AA9-+AA8)*48 -> 1536 | AC9: 453571 | AD9: =(+AC9-+AC8)*48 -> 5328 | AE9: 526398 | AF9: =(+AE9-+AE8)*48 -> 4896 | AG9: 49716 | AH9: =(+AG9-+AG8)*48 -> 192 | AI9: 414870 | AJ9: =(+AI9-+AI8)*48 -> 5712 | AK9: 102770 | AL9: =(+AK9-+AK8)*48 -> 0 | AM9: 571848 | AN9: =(+AM9-+AM8)*48 -> 19488 | AO9: 924601 | AP9: =(+AO9-+AO8)*48 -> 9456 | AQ9: 77519 | AR9: =(+AQ9-+AQ8)*48 -> 2448 | AS9: 2262 | AT9: =(+AS9-+AS8)*48 -> 0 | AU9: 939 | AV9: =(+AU9-+AU8)*48 -> 0 | AW9: 3109 | AX9: =(+AW9-+AW8)*48 -> 0 | AY9: 315287 | AZ9: =(+AY9-+AY8)*48 -> 3408 | BA9: 161101 | BB9: =(+BA9-+BA8)*48 -> 0 | BC9: 215619 | BD9: =(+BC9-+BC8)*48 -> 2352 | BE9: 5347 | BF9: =(+BE9-+BE8)*48 -> 0 | BH9: =SUM(E9,J9,P9,H9,L9,R9,T9,V9,X9,N9,AB9,Z9,AD9,AF9,AH9,AL9,AJ9) -> 127610.69 | BI9: =SUM(F9,AN9,AP9,AT9,AV9,AX9,AR9,AZ9,BB9,BD9,BF9) -> 79488
A10: 44318 | C10: 6008845 | D10: =(+C10-+C9)*48 -> 112128 | E10: =D10*0.6 -> 67276.8 | F10: =D10*0.4 -> 44851.2 | G10: =(G12-G9)/3+G9 -> 281179.33 | H10: =(+G10-+G9)*48 -> 1744 | I10: =(I12-I9)/3+I9 -> 121426.67 | J10: =(+I10-+I9)*48 -> 8000 | K10: =(K12-K9)/3+K9 -> 258120.67 | L10: =(+K10-+K9)*48 -> 1376 | M10: =(M12-M9)/3+M9 -> 24717 | N10: =(+M10-+M9)*48 -> 1056 | O10: =(O12-O9)/3+O9 -> 258869.33 | P10: =(+O10-+O9)*48 -> 9904 | Q10: =(Q12-Q9)/3+Q9 -> 447511.33 | R10: =(+Q10-+Q9)*48 -> 3424 | S10: =(S12-S9)/3+S9 -> 720981.33 | T10: =(+S10-+S9)*48 -> 6400 | U10: =(U12-U9)/3+U9 -> 99155.51 | V10: =(+U10-+U9)*48 -> 1185.952 | W10: =(W12-W9)/3+W9 -> 80568.333 | X10: =(+W10-+W9)*48 -> 640 | Y10: =(Y12-Y9)/3+Y9 -> 1499121.7 | Z10: =(+Y10-+Y9)*48 -> 3008 | AA10: =(AA12-AA9)/3+AA9 -> 13264 | AB10: =(+AA10-+AA9)*48 -> 0 | AC10: =(AC12-AC9)/3+AC9 -> 453678.33 | AD10: =(+AC10-+AC9)*48 -> 5152 | AE10: =(AE12-AE9)/3+AE9 -> 526492.67 | AF10: =(+AE10-+AE9)*48 -> 4544 | AG10: =(AG12-AG9)/3+AG9 -> 49720 | AH10: =(+AG10-+AG9)*48 -> 192 | AI10: =(AI12-AI9)/3+AI9 -> 414980 | AJ10: =(+AI10-+AI9)*48 -> 5280 | AK10: =(AK12-AK9)/3+AK9 -> 102770 | AL10: =(+AK10-+AK9)*48 -> 0 | AM10: =(AM12-AM9)/3+AM9 -> 571856.67 | AN10: =(+AM10-+AM9)*48 -> 416 | AO10: =(AO12-AO9)/3+AO9 -> 924799 | AP10: =(+AO10-+AO9)*48 -> 9504 | AQ10: =(AQ12-AQ9)/3+AQ9 -> 77571.333 | AR10: =(+AQ10-+AQ9)*48 -> 2512 | AS10: 2262 | AT10: =(+AS10-+AS9)*48 -> 0 | AU10: 939 | AV10: =(+AU10-+AU9)*48 -> 0 | AW10: 3109 | AX10: =(+AW10-+AW9)*48 -> 0 | AY10: =(AY12-AY9)/3+AY9 -> 315360 | AZ10: =(+AY10-+AY9)*48 -> 3504 | BA10: 161101 | BB10: =(+BA10-+BA9)*48 -> 0 | BC10: =(BC12-BC9)/3+BC9 -> 215668 | BD10: =(+BC10-+BC9)*48 -> 2352 | BE10: 5347 | BF10: =(+BE10-+BE9)*48 -> 0 | BH10: =SUM(E10,J10,P10,H10,L10,R10,T10,V10,X10,N10,AB10,Z10,AD10,AF10,AH10,AL10,AJ10) -> 119182.75 | BI10: =SUM(F10,AN10,AP10,AT10,AV10,AX10,AR10,AZ10,BB10,BD10,BF10) -> 63139.2
A11: 44319 | C11: 6010971 | D11: =(+C11-+C10)*48 -> 102048 | E11: =D11*0.6 -> 61228.8 | F11: =D11*0.4 -> 40819.2 | G11: =(G12-G9)/3+G10 -> 281215.67 | H11: =(+G11-+G10)*48 -> 1744 | I11: =(I12-I9)/3+I10 -> 121593.33 | J11: =(+I11-+I10)*48 -> 8000 | K11: =(K12-K9)/3+K10 -> 258149.33 | L11: =(+K11-+K10)*48 -> 1376 | M11: =(M12-M9)/3+M10 -> 24739 | N11: =(+M11-+M10)*48 -> 1056 | O11: =(O12-O9)/3+O10 -> 259075.67 | P11: =(+O11-+O10)*48 -> 9904 | Q11: =(Q12-Q9)/3+Q10 -> 447582.67 | R11: =(+Q11-+Q10)*48 -> 3424 | S11: =(S12-S9)/3+S10 -> 721114.67 | T11: =(+S11-+S10)*48 -> 6400 | U11: =(U12-U9)/3+U10 -> 99180.218 | V11: =(+U11-+U10)*48 -> 1185.952 | W11: =(W12-W9)/3+W10 -> 80581.667 | X11: =(+W11-+W10)*48 -> 640 | Y11: =(Y12-Y9)/3+Y10 -> 1499184.3 | Z11: =(+Y11-+Y10)*48 -> 3008 | AA11: =(AA12-AA9)/3+AA10 -> 13264 | AB11: =(+AA11-+AA10)*48 -> 0 | AC11: =(AC12-AC9)/3+AC10 -> 453785.67 | AD11: =(+AC11-+AC10)*48 -> 5152 | AE11: =(AE12-AE9)/3+AE10 -> 526587.33 | AF11: =(+AE11-+AE10)*48 -> 4544 | AG11: =(AG12-AG9)/3+AG10 -> 49724 | AH11: =(+AG11-+AG10)*48 -> 192 | AI11: =(AI12-AI9)/3+AI10 -> 415090 | AJ11: =(+AI11-+AI10)*48 -> 5280 | AK11: =(AK12-AK9)/3+AK10 -> 102770 | AL11: =(+AK11-+AK10)*48 -> 0 | AM11: =(AM12-AM9)/3+AM10 -> 571865.33 | AN11: =(+AM11-+AM10)*48 -> 416 | AO11: =(AO12-AO9)/3+AO10 -> 924997 | AP11: =(+AO11-+AO10)*48 -> 9504 | AQ11: =(AQ12-AQ9)/3+AQ10 -> 77623.667 | AR11: =(+AQ11-+AQ10)*48 -> 2512 | AS11: 2262 | AT11: =(+AS11-+AS10)*48 -> 0 | AU11: 939 | AV11: =(+AU11-+AU10)*48 -> 0 | AW11: 3109 | AX11: =(+AW11-+AW10)*48 -> 0 | AY11: =(AY12-AY9)/3+AY10 -> 315433 | AZ11: =(+AY11-+AY10)*48 -> 3504 | BA11: 161101 | BB11: =(+BA11-+BA10)*48 -> 0 | BC11: =(BC12-BC9)/3+BC10 -> 215717 | BD11: =(+BC11-+BC10)*48 -> 2352 | BE11: 5347 | BF11: =(+BE11-+BE10)*48 -> 0 | BH11: =SUM(E11,J11,P11,H11,L11,R11,T11,V11,X11,N11,AB11,Z11,AD11,AF11,AH11,AL11,AJ11) -> 113134.75 | BI11: =SUM(F11,AN11,AP11,AT11,AV11,AX11,AR11,AZ11,BB11,BD11,BF11) -> 59107.2
A12: 44320 | C12: 6012938 | D12: =(+C12-+C11)*48 -> 94416 | E12: =D12*0.6 -> 56649.6 | F12: =D12*0.4 -> 37766.4 | G12: 281252 | H12: =(+G12-+G11)*48 -> 1744 | I12: 121760 | J12: =(+I12-+I11)*48 -> 8000 | K12: 258178 | L12: =(+K12-+K11)*48 -> 1376 | M12: 24761 | N12: =(+M12-+M11)*48 -> 1056 | O12: 259282 | P12: =(+O12-+O11)*48 -> 9904 | Q12: 447654 | R12: =(+Q12-+Q11)*48 -> 3424 | S12: 721248 | T12: =(+S12-+S11)*48 -> 6400 | U12: 99204.925 | V12: =(+U12-+U11)*48 -> 1185.952 | W12: 80595 | X12: =(+W12-+W11)*48 -> 640 | Y12: 1499247 | Z12: =(+Y12-+Y11)*48 -> 3008 | AA12: 13264 | AB12: =(+AA12-+AA11)*48 -> 0 | AC12: 453893 | AD12: =(+AC12-+AC11)*48 -> 5152 | AE12: 526682 | AF12: =(+AE12-+AE11)*48 -> 4544 | AG12: 49728 | AH12: =(+AG12-+AG11)*48 -> 192 | AI12: 415200 | AJ12: =(+AI12-+AI11)*48 -> 5280 | AK12: 102770 | AL12: =(+AK12-+AK11)*48 -> 0 | AM12: 571874 | AN12: =(+AM12-+AM11)*48 -> 416 | AO12: 925195 | AP12: =(+AO12-+AO11)*48 -> 9504 | AQ12: 77676 | AR12: =(+AQ12-+AQ11)*48 -> 2512 | AS12: 2262 | AT12: =(+AS12-+AS11)*48 -> 0 | AU12: 939 | AV12: =(+AU12-+AU11)*48 -> 0 | AW12: 3109 | AX12: =(+AW12-+AW11)*48 -> 0 | AY12: 315506 | AZ12: =(+AY12-+AY11)*48 -> 3504 | BA12: 161101 | BB12: =(+BA12-+BA11)*48 -> 0 | BC12: 215766 | BD12: =(+BC12-+BC11)*48 -> 2352 | BE12: 5347 | BF12: =(+BE12-+BE11)*48 -> 0 | BH12: =SUM(E12,J12,P12,H12,L12,R12,T12,V12,X12,N12,AB12,Z12,AD12,AF12,AH12,AL12,AJ12) -> 108555.55 | BI12: =SUM(F12,AN12,AP12,AT12,AV12,AX12,AR12,AZ12,BB12,BD12,BF12) -> 56054.4
A13: 44321 | C13: 6015008 | D13: =(+C13-+C12)*48 -> 99360 | E13: =D13*0.6 -> 59616 | F13: =D13*0.4 -> 39744 | G13: 281282 | H13: =(+G13-+G12)*48 -> 1440 | I13: 121933 | J13: =(+I13-+I12)*48 -> 8304 | K13: 258183 | L13: =(+K13-+K12)*48 -> 240 | M13: 24771 | N13: =(+M13-+M12)*48 -> 480 | O13: 259467 | P13: =(+O13-+O12)*48 -> 8880 | Q13: 447693 | R13: =(+Q13-+Q12)*48 -> 1872 | S13: 721369 | T13: =(+S13-+S12)*48 -> 5808 | U13: 99227.343 | V13: =(+U13-+U12)*48 -> 1076.064 | W13: 80609 | X13: =(+W13-+W12)*48 -> 672 | Y13: 1499296 | Z13: =(+Y13-+Y12)*48 -> 2352 | AA13: 13264 | AB13: =(+AA13-+AA12)*48 -> 0 | AC13: 454002 | AD13: =(+AC13-+AC12)*48 -> 5232 | AE13: 526774 | AF13: =(+AE13-+AE12)*48 -> 4416 | AG13: 49732 | AH13: =(+AG13-+AG12)*48 -> 192 | AI13: 415290 | AJ13: =(+AI13-+AI12)*48 -> 4320 | AK13: 102770 | AL13: =(+AK13-+AK12)*48 -> 0 | AM13: 571983 | AN13: =(+AM13-+AM12)*48 -> 5232 | AO13: 925392 | AP13: =(+AO13-+AO12)*48 -> 9456 | AQ13: 77689 | AR13: =(+AQ13-+AQ12)*48 -> 624 | AS13: 2262 | AT13: =(+AS13-+AS12)*48 -> 0 | AU13: 939 | AV13: =(+AU13-+AU12)*48 -> 0 | AW13: 3109 | AX13: =(+AW13-+AW12)*48 -> 0 | AY13: 315582 | AZ13: =(+AY13-+AY12)*48 -> 3648 | BA13: 161101 | BB13: =(+BA13-+BA12)*48 -> 0 | BC13: 215816 | BD13: =(+BC13-+BC12)*48 -> 2400 | BE13: 5347 | BF13: =(+BE13-+BE12)*48 -> 0 | BH13: =SUM(E13,J13,P13,H13,L13,R13,T13,V13,X13,N13,AB13,Z13,AD13,AF13,AH13,AL13,AJ13) -> 104900.06 | BI13: =SUM(F13,AN13,AP13,AT13,AV13,AX13,AR13,AZ13,BB13,BD13,BF13) -> 61104
