Workbook

Sheet TOTAL
A1: Site Name | B1: Day | C1: Month | D1: Year | E1: Total Electricity Kwh | F1: Electricity Tariff ($/Kwh) | G1: Total Fuel Oil (Liter) | H1: Fuel Oil $/Liter | I1: Water Utility Supply (m3) m3 | J1: Water Utility Supply (m3) $/m3 | K1: LPG (Kg) | L1: LPG $/Kg | M1: Room Nights | N1: Total Guests | O1: Food Covers
A2: Maldives at Kuda Huraa | B2: 1 | C2: 6 | D2: 2022 | M2: 20 | N2: 59 | O2: 143
A3: Maldives at Kuda Huraa | B3: =B2+1 -> 2 | C3: 6 | D3: 2022 | M3: 22 | N3: 66 | O3: 146
A4: Maldives at Kuda Huraa | B4: =B3+1 -> 3 | C4: 6 | D4: 2022 | M4: 22 | N4: 67 | O4: 171
A5: Maldives at Kuda Huraa | B5: =B4+1 -> 4 | C5: 6 | D5: 2022 | M5: 23 | N5: 63 | O5: 150
A6: Maldives at Kuda Huraa | B6: =B5+1 -> 5 | C6: 6 | D6: 2022 | M6: 27 | N6: 74 | O6: 172
A7: Maldives at Kuda Huraa | B7: =B6+1 -> 6 | C7: 6 | D7: 2022 | M7: 21 | N7: 62 | O7: 171
A8: Maldives at Kuda Huraa | B8: =B7+1 -> 7 | C8: 6 | D8: 2022 | M8: 17 | N8: 50 | O8: 117
A9: Maldives at Kuda Huraa | B9: =B8+1 -> 8 | C9: 6 | D9: 2022
A10: Maldives at Kuda Huraa | B10: =B9+1 -> 9 | C10: 6 | D10: 2022
A11: Maldives at Kuda Huraa | B11: =B10+1 -> 10 | C11: 6 | D11: 2022
A12: Maldives at Kuda Huraa | B12: =B11+1 -> 11 | C12: 6 | D12: 2022
A13: Maldives at Kuda Huraa | B13: =B12+1 -> 12 | C13: 6 | D13: 2022
A14: Maldives at Kuda Huraa | B14: =B13+1 -> 13 | C14: 6 | D14: 2022
A15: Maldives at Kuda Huraa | B15: =B14+1 -> 14 | C15: 6 | D15: 2022
A16: Maldives at Kuda Huraa | B16: =B15+1 -> 15 | C16: 6 | D16: 2022
A17: Maldives at Kuda Huraa | B17: =B16+1 -> 16 | C17: 6 | D17: 2022
A18: Maldives at Kuda Huraa | B18: =B17+1 -> 17 | C18: 6 | D18: 2022
A19: Maldives at Kuda Huraa | B19: =B18+1 -> 18 | C19: 6 | D19: 2022
A20: Maldives at Kuda Huraa | B20: =B19+1 -> 19 | C20: 6 | D20: 2022
... A32: Maldives at Kuda Huraa | B32: =B31+1 -> 31 | C32: 6 | D32: 2022
A33: Total | F33: 0 | H33: 0 | J33: 0 | K33: =SUM(K2:K32) -> 0 | L33: 0

Sheet Kwh Reading
A1: Electric Consumption Record (4pm)
A2: Month | B2: BOH-1/ B&C Block GWH | C2: Pastry MWH | D2: Feeder 401-419 KWH | E2: Feeder 301-319 KWH | F2: Kitchen GWH | G2: Feeder 201-208 GWH | H2: Feeder 113-123 | I2: M - Block /PC MWH | J2: Laundry MWH | M2: Feeder 101-112 MWH | N2: Feeder 217-224 | O2: Spa MWH | P2: Feeder 124-134 | Q2: Feeder 209-216 | R2: STP -1 &2 MWH | S2: STP -3 MWH | T2: Reef Club MWH | V2: Room Nights | W2: Total Guests | X2: Food Covers
J3: A | K3: B | L3: C
A4: 44713 | B4: 1.382 | C4: 313.43 | D4: 8189226.5 | E4: 9144633.5 | F4: 3.2548 | G4: 1.0458 | H4: 943.61 | I4: 338.16 | J4: 467.59 | K4: 458.27 | L4: 311.64 | M4: 776.06 | N4: 727.05 | O4: 223.53 | P4: 948.62 | Q4: 704.27 | R4: 190.15 | S4: 161.04 | T4: 585.44 | V4: 20 | W4: 59 | X4: 143
A5: 44714 | B5: 1.3831 | C5: 313.66 | D5: 8191103.9 | E5: 9147470.8 | F5: 3.2575 | G5: 1.0465 | H5: 944.73 | I5: 338.5 | J5: 468.12 | K5: 458.61 | L5: 311.88 | M5: 776.87 | N5: 727.31 | O5: 223.74 | P5: 949.28 | Q5: 704.84 | R5: 190.15 | S5: 161.18 | T5: 585.94 | V5: 22 | W5: 66 | X5: 146
A6: 44715 | B6: 1.3842 | C6: 313.9 | D6: 8192995.6 | E6: 9150608.2 | F6: 3.2602 | G6: 1.0474 | H6: 946.02 | I6: 338.86 | J6: 468.39 | K6: 458.86 | L6: 312.1 | M6: 777.73 | N6: 727.59 | O6: 223.94 | P6: 950 | Q6: 705.55 | R6: 190.15 | S6: 161.33 | T6: 586.44 | V6: 22 | W6: 67 | X6: 171
A7: 44716 | B7: 1.3852 | C7: 314.15 | D7: 8194961.8 | E7: 9153397.6 | F7: 3.2629 | G7: 1.0483 | H7: 947.37 | I7: 339.23 | J7: 468.8 | K7: 459.17 | L7: 312.32 | M7: 778.61 | N7: 727.85 | O7: 224.14 | P7: 950.72 | Q7: 706.32 | R7: 190.15 | S7: 161.46 | T7: 586.72 | V7: 23 | W7: 63 | X7: 150
A8: 44717 | B8: 1.3863 | C8: 318.37 | D8: 8196793.8 | E8: 9156412.2 | F8: 3.2656 | G8: 1.0492 | H8: 948.61 | I8: 339.59 | J8: 469.16 | K8: 959.44 | L8: 312.53 | M8: 779.5 | N8: 728.11 | O8: 224.34 | P8: 951.42 | Q8: 706.96 | R8: 190.15 | S8: 161.6 | T8: 587.2 | V8: 27 | W8: 74 | X8: 172
A9: 44718 | B9: 1.3873 | C9: 314.58 | D9: 8198744.6 | E9: 9159357.4 | F9: 3.2684 | G9: 1.0501 | H9: 949.71 | I9: 339.93 | J9: 469.47 | K9: 459.71 | L9: 312.74 | M9: 780.35 | N9: 728.37 | O9: 224.53 | P9: 952.09 | Q9: 707.59 | R9: 190.15 | S9: 161.74 | T9: 587.66 | V9: 21 | W9: 62 | X9: 171
A10: 44719 | B10: 1.3884 | C10: 314.8 | D10: 8200506.3 | E10: 9162267.7 | F10: 3.271 | G10: 1.0511 | H10: 950.86 | I10: 340.27 | J10: 469.91 | K10: 459.98 | L10: 312.96 | M10: 781.18 | N10: 728.63 | O10: 224.76 | P10: 952.72 | Q10: 708.3 | R10: 190.15 | S10: 161.88 | T10: 588.18 | V10: 17 | W10: 50 | X10: 117
A11: 44720 | B11: 1.3894 | C11: 315.02 | D11: 8202202 | E11: 9169140.7 | F11: 3.2736 | G11: 1.052 | H11: 951.87 | I11: 340.64 | J11: 470.41 | K11: 460.27 | L11: 313.16 | M11: 781.9 | N11: 728.88 | O11: 224.97 | P11: 953.35 | Q11: 708.94 | R11: 190.15 | S11: 162.01 | T11: 588.67
A12: 44721
A13: 44722
A14: 44723
A15: 44724
A16: 44725
A17: 44726
A18: 44727
A19: 44728
A20: 44729
A21: 44730
A22: 44731
A23: 44732
... A34: 44743
V35: =SUM(V4:V34) -> 152 | W35: =SUM(W4:W34) -> 441 | X35: =SUM(X4:X34) -> 1070
T42: ……..

Sheet Kwh Consumption
A2: Date | B2: Total KWH | C2: Reef Club KWH | D2: Kitchen KWH | E2: Pastry KWH | F2: Laundry KWH | I2: STP -1 &2 KWH | J2: STP -3 KWH | K2: M - Block /PC KWH | L2: B&C Block KWH | M2: Guest Room Beach Pavilion & Beach Bungalow KWH | S2: Guest Room Water Bungalow KWH | U2: Spa KWH | V2: Others KWH
F3: A | G3: B | H3: C | M3: Feeder -101-112 | N3: Feeder -113-123 | O3: Feeder -124-134 | P3: Feeder -201-208 | Q3: Feeder -209-216 | R3: Feeder -217-224 | S3: Feeder -301-319 | T3: Feeder 401-419
A4: ='Kwh Reading'!A4 -> 44713 | B4: =TOTAL!E2 -> 0 | C4: =('Kwh Reading'!T5-'Kwh Reading'!T4)*1000 -> 500 | D4: =('Kwh Reading'!F5-'Kwh Reading'!F4)*1000000 -> 2700 | E4: =('Kwh Reading'!C5-'Kwh Reading'!C4)*1000 -> 230 | F4: =('Kwh Reading'!J5-'Kwh Reading'!J4)*1000 -> 530 | G4: =('Kwh Reading'!K5-'Kwh Reading'!K4)*1000 -> 340 | H4: =('Kwh Reading'!L5-'Kwh Reading'!L4)*1000 -> 240 | I4: =('Kwh Reading'!R5-'Kwh Reading'!R4)*1000 -> 0 | J4: =('Kwh Reading'!S5-'Kwh Reading'!S4)*1000 -> 140 | K4: =('Kwh Reading'!I5-'Kwh Reading'!I4)*1000 -> 340 | L4: =('Kwh Reading'!B5-'Kwh Reading'!B4)*1000000 -> 1100 | M4: =('Kwh Reading'!M5-'Kwh Reading'!M4)*1000 -> 810 | N4: =('Kwh Reading'!H5-'Kwh Reading'!H4)*1000 -> 1120 | O4: =('Kwh Reading'!P5-'Kwh Reading'!P4)*1000 -> 660 | P4: =('Kwh Reading'!G5-'Kwh Reading'!G4)*1000000 -> 700 | Q4: =('Kwh Reading'!Q5-'Kwh Reading'!Q4)*1000 -> 570 | R4: =('Kwh Reading'!N5-'Kwh Reading'!N4)*1000 -> 260 | S4: ='Kwh Reading'!E5-'Kwh Reading'!E4 -> 2837.3 | T4: ='Kwh Reading'!D5-'Kwh Reading'!D4 -> 1877.38 | U4: =('Kwh Reading'!O5-'Kwh Reading'!O4)*1000 -> 210 | V4: =B4-(SUM(C4:U4)) -> -15164.68
A5: ='Kwh Reading'!A5 -> 44714 | B5: =TOTAL!E3 -> 0 | C5: =('Kwh Reading'!T6-'Kwh Reading'!T5)*1000 -> 500 | D5: =('Kwh Reading'!F6-'Kwh Reading'!F5)*1000000 -> 2700 | E5: =('Kwh Reading'!C6-'Kwh Reading'!C5)*1000 -> 240 | F5: =('Kwh Reading'!J6-'Kwh Reading'!J5)*1000 -> 270 | G5: =('Kwh Reading'!K6-'Kwh Reading'!K5)*1000 -> 250 | H5: =('Kwh Reading'!L6-'Kwh Reading'!L5)*1000 -> 220 | I5: =('Kwh Reading'!R6-'Kwh Reading'!R5)*1000 -> 0 | J5: =('Kwh Reading'!S6-'Kwh Reading'!S5)*1000 -> 150 | K5: =('Kwh Reading'!I6-'Kwh Reading'!I5)*1000 -> 360 | L5: =('Kwh Reading'!B6-'Kwh Reading'!B5)*1000000 -> 1100 | M5: =('Kwh Reading'!M6-'Kwh Reading'!M5)*1000 -> 860 | N5: =('Kwh Reading'!H6-'Kwh Reading'!H5)*1000 -> 1290 | O5: =('Kwh Reading'!P6-'Kwh Reading'!P5)*1000 -> 720 | P5: =('Kwh Reading'!G6-'Kwh Reading'!G5)*1000000 -> 900 | Q5: =('Kwh Reading'!Q6-'Kwh Reading'!Q5)*1000 -> 710 | R5: =('Kwh Reading'!N6-'Kwh Reading'!N5)*1000 -> 280 | S5: ='Kwh Reading'!E6-'Kwh Reading'!E5 -> 3137.35 | T5: ='Kwh Reading'!D6-'Kwh Reading'!D5 -> 1891.72 | U5: =('Kwh Reading'!O6-'Kwh Reading'!O5)*1000 -> 200 | V5: =B5-(SUM(C5:U5)) -> -15779.07
A6: ='Kwh Reading'!A6 -> 44715 | B6: =TOTAL!E4 -> 0 | C6: =('Kwh Reading'!T7-'Kwh Reading'!T6)*1000 -> 280 | D6: =('Kwh Reading'!F7-'Kwh Reading'!F6)*1000000 -> 2700 | E6: =('Kwh Reading'!C7-'Kwh Reading'!C6)*1000 -> 250 | F6: =('Kwh Reading'!J7-'Kwh Reading'!J6)*1000 -> 410 | G6: =('Kwh Reading'!K7-'Kwh Reading'!K6)*1000 -> 310 | H6: =('Kwh Reading'!L7-'Kwh Reading'!L6)*1000 -> 220 | I6: =('Kwh Reading'!R7-'Kwh Reading'!R6)*1000 -> 0 | J6: =('Kwh Reading'!S7-'Kwh Reading'!S6)*1000 -> 130 | K6: =('Kwh Reading'!I7-'Kwh Reading'!I6)*1000 -> 370 | L6: =('Kwh Reading'!B7-'Kwh Reading'!B6)*1000000 -> 1000 | M6: =('Kwh Reading'!M7-'Kwh Reading'!M6)*1000 -> 880 | N6: =('Kwh Reading'!H7-'Kwh Reading'!H6)*1000 -> 1350 | O6: =('Kwh Reading'!P7-'Kwh Reading'!P6)*1000 -> 720 | P6: =('Kwh Reading'!G7-'Kwh Reading'!G6)*1000000 -> 900 | Q6: =('Kwh Reading'!Q7-'Kwh Reading'!Q6)*1000 -> 770 | R6: =('Kwh Reading'!N7-'Kwh Reading'!N6)*1000 -> 260 | S6: ='Kwh Reading'!E7-'Kwh Reading'!E6 -> 2789.4 | T6: ='Kwh Reading'!D7-'Kwh Reading'!D6 -> 1966.2 | U6: =('Kwh Reading'!O7-'Kwh Reading'!O6)*1000 -> 200 | V6: =B6-(SUM(C6:U6)) -> -15505.6
A7: ='Kwh Reading'!A7 -> 44716 | B7: =TOTAL!E5 -> 0 | C7: =('Kwh Reading'!T8-'Kwh Reading'!T7)*1000 -> 480 | D7: =('Kwh Reading'!F8-'Kwh Reading'!F7)*1000000 -> 2700 | E7: =('Kwh Reading'!C8-'Kwh Reading'!C7)*1000 -> 4220 | F7: =('Kwh Reading'!J8-'Kwh Reading'!J7)*1000 -> 360 | G7: =('Kwh Reading'!K8-'Kwh Reading'!K7)*1000 -> 500270 | H7: =('Kwh Reading'!L8-'Kwh Reading'!L7)*1000 -> 210 | I7: =('Kwh Reading'!R8-'Kwh Reading'!R7)*1000 -> 0 | J7: =('Kwh Reading'!S8-'Kwh Reading'!S7)*1000 -> 140 | K7: =('Kwh Reading'!I8-'Kwh Reading'!I7)*1000 -> 360 | L7: =('Kwh Reading'!B8-'Kwh Reading'!B7)*1000000 -> 1100 | M7: =('Kwh Reading'!M8-'Kwh Reading'!M7)*1000 -> 890 | N7: =('Kwh Reading'!H8-'Kwh Reading'!H7)*1000 -> 1240 | O7: =('Kwh Reading'!P8-'Kwh Reading'!P7)*1000 -> 700 | P7: =('Kwh Reading'!G8-'Kwh Reading'!G7)*1000000 -> 900 | Q7: =('Kwh Reading'!Q8-'Kwh Reading'!Q7)*1000 -> 640 | R7: =('Kwh Reading'!N8-'Kwh Reading'!N7)*1000 -> 260 | S7: ='Kwh Reading'!E8-'Kwh Reading'!E7 -> 3014.62 | T7: ='Kwh Reading'!D8-'Kwh Reading'!D7 -> 1832.02 | U7: =('Kwh Reading'!O8-'Kwh Reading'!O7)*1000 -> 200 | V7: =B7-(SUM(C7:U7)) -> -519516.64
A8: ='Kwh Reading'!A8 -> 44717 | B8: =TOTAL!E6 -> 0 | C8: =('Kwh Reading'!T9-'Kwh Reading'!T8)*1000 -> 460 | D8: =('Kwh Reading'!F9-'Kwh Reading'!F8)*1000000 -> 2800 | E8: =('Kwh Reading'!C9-'Kwh Reading'!C8)*1000 -> -3790 | F8: =('Kwh Reading'!J9-'Kwh Reading'!J8)*1000 -> 310 | G8: =('Kwh Reading'!K9-'Kwh Reading'!K8)*1000 -> -499730 | H8: =('Kwh Reading'!L9-'Kwh Reading'!L8)*1000 -> 210 | I8: =('Kwh Reading'!R9-'Kwh Reading'!R8)*1000 -> 0 | J8: =('Kwh Reading'!S9-'Kwh Reading'!S8)*1000 -> 140 | K8: =('Kwh Reading'!I9-'Kwh Reading'!I8)*1000 -> 340 | L8: =('Kwh Reading'!B9-'Kwh Reading'!B8)*1000000 -> 1000 | M8: =('Kwh Reading'!M9-'Kwh Reading'!M8)*1000 -> 850 | N8: =('Kwh Reading'!H9-'Kwh Reading'!H8)*1000 -> 1100 | O8: =('Kwh Reading'!P9-'Kwh Reading'!P8)*1000 -> 670 | P8: =('Kwh Reading'!G9-'Kwh Reading'!G8)*1000000 -> 900 | Q8: =('Kwh Reading'!Q9-'Kwh Reading'!Q8)*1000 -> 630 | R8: =('Kwh Reading'!N9-'Kwh Reading'!N8)*1000 -> 260 | S8: ='Kwh Reading'!E9-'Kwh Reading'!E8 -> 2945.18 | T8: ='Kwh Reading'!D9-'Kwh Reading'!D8 -> 1950.74 | U8: =('Kwh Reading'!O9-'Kwh Reading'!O8)*1000 -> 190 | V8: =B8-(SUM(C8:U8)) -> 488764.08
A9: ='Kwh Reading'!A9 -> 44718 | B9: =TOTAL!E7 -> 0 | C9: =('Kwh Reading'!T10-'Kwh Reading'!T9)*1000 -> 520 | D9: =('Kwh Reading'!F10-'Kwh Reading'!F9)*1000000 -> 2600 | E9: =('Kwh Reading'!C10-'Kwh Reading'!C9)*1000 -> 220 | F9: =('Kwh Reading'!J10-'Kwh Reading'!J9)*1000 -> 440 | G9: =('Kwh Reading'!K10-'Kwh Reading'!K9)*1000 -> 270 | H9: =('Kwh Reading'!L10-'Kwh Reading'!L9)*1000 -> 220 | I9: =('Kwh Reading'!R10-'Kwh Reading'!R9)*1000 -> 0 | J9: =('Kwh Reading'!S10-'Kwh Reading'!S9)*1000 -> 140 | K9: =('Kwh Reading'!I10-'Kwh Reading'!I9)*1000 -> 340 | L9: =('Kwh Reading'!B10-'Kwh Reading'!B9)*1000000 -> 1100 | M9: =('Kwh Reading'!M10-'Kwh Reading'!M9)*1000 -> 830 | N9: =('Kwh Reading'!H10-'Kwh Reading'!H9)*1000 -> 1150 | O9: =('Kwh Reading'!P10-'Kwh Reading'!P9)*1000 -> 630 | P9: =('Kwh Reading'!G10-'Kwh Reading'!G9)*1000000 -> 1000 | Q9: =('Kwh Reading'!Q10-'Kwh Reading'!Q9)*1000 -> 710 | R9: =('Kwh Reading'!N10-'Kwh Reading'!N9)*1000 -> 260 | S9: ='Kwh Reading'!E10-'Kwh Reading'!E9 -> 2910.28 | T9: ='Kwh Reading'!D10-'Kwh Reading'!D9 -> 1761.68 | U9: =('Kwh Reading'!O10-'Kwh Reading'!O9)*1000 -> 230 | V9: =B9-(SUM(C9:U9)) -> -15331.96
A10: ='Kwh Reading'!A10 -> 44719 | B10: =TOTAL!E8 -> 0 | C10: =('Kwh Reading'!T11-'Kwh Reading'!T10)*1000 -> 490 | D10: =('Kwh Reading'!F11-'Kwh Reading'!F10)*1000000 -> 2600 | E10: =('Kwh Reading'!C11-'Kwh Reading'!C10)*1000 -> 220 | F10: =('Kwh Reading'!J11-'Kwh Reading'!J10)*1000 -> 500 | G10: =('Kwh Reading'!K11-'Kwh Reading'!K10)*1000 -> 290 | H10: =('Kwh Reading'!L11-'Kwh Reading'!L10)*1000 -> 200 | I10: =('Kwh Reading'!R11-'Kwh Reading'!R10)*1000 -> 0 | J10: =('Kwh Reading'!S11-'Kwh Reading'!S10)*1000 -> 130 | K10: =('Kwh Reading'!I11-'Kwh Reading'!I10)*1000 -> 370 | L10: =('Kwh Reading'!B11-'Kwh Reading'!B10)*1000000 -> 1000 | M10: =('Kwh Reading'!M11-'Kwh Reading'!M10)*1000 -> 720 | N10: =('Kwh Reading'!H11-'Kwh Reading'!H10)*1000 -> 1010 | O10: =('Kwh Reading'!P11-'Kwh Reading'!P10)*1000 -> 630 | P10: =('Kwh Reading'!G11-'Kwh Reading'!G10)*1000000 -> 900 | Q10: =('Kwh Reading'!Q11-'Kwh Reading'!Q10)*1000 -> 640 | R10: =('Kwh Reading'!N11-'Kwh Reading'!N10)*1000 -> 250 | S10: ='Kwh Reading'!E11-'Kwh Reading'!E10 -> 6873 | T10: ='Kwh Reading'!D11-'Kwh Reading'!D10 -> 1695.73 | U10: =('Kwh Reading'!O11-'Kwh Reading'!O10)*1000 -> 210 | V10: =B10-(SUM(C10:U10)) -> -18728.73
A11: ='Kwh Reading'!A11 -> 44720 | B11: =TOTAL!E9 -> 0 | C11: =('Kwh Reading'!T12-'Kwh Reading'!T11)*1000 -> -588670 | D11: =('Kwh Reading'!F12-'Kwh Reading'!F11)*1000000 -> -3273600 | E11: =('Kwh Reading'!C12-'Kwh Reading'!C11)*1000 -> -315020 | F11: =('Kwh Reading'!J12-'Kwh Reading'!J11)*1000 -> -470410 | G11: =('Kwh Reading'!K12-'Kwh Reading'!K11)*1000 -> -460270 | H11: =('Kwh Reading'!L12-'Kwh Reading'!L11)*1000 -> -313160 | I11: =('Kwh Reading'!R12-'Kwh Reading'!R11)*1000 -> -190150 | J11: =('Kwh Reading'!S12-'Kwh Reading'!S11)*1000 -> -162010 | K11: =('Kwh Reading'!I12-'Kwh Reading'!I11)*1000 -> -340640 | L11: =('Kwh Reading'!B12-'Kwh Reading'!B11)*1000000 -> -1389400 | M11: =('Kwh Reading'!M12-'Kwh Reading'!M11)*1000 -> -781900 | N11: =('Kwh Reading'!H12-'Kwh Reading'!H11)*1000 -> -951870 | O11: =('Kwh Reading'!P12-'Kwh Reading'!P11)*1000 -> -953350 | P11: =('Kwh Reading'!G12-'Kwh Reading'!G11)*1000000 -> -1052000 | Q11: =('Kwh Reading'!Q12-'Kwh Reading'!Q11)*1000 -> -708940 | R11: =('Kwh Reading'!N12-'Kwh Reading'!N11)*1000 -> -728880 | S11: ='Kwh Reading'!E12-'Kwh Reading'!E11 -> -9169140.7 | T11: ='Kwh Reading'!D12-'Kwh Reading'!D11 -> -8202202 | U11: =('Kwh Reading'!O12-'Kwh Reading'!O11)*1000 -> -224970 | V11: =B11-(SUM(C11:U11)) -> 30276583
A12: ='Kwh Reading'!A12 -> 44721 | B12: =TOTAL!E10 -> 0 | C12: =('Kwh Reading'!T13-'Kwh Reading'!T12)*1000 -> 0 | D12: =('Kwh Reading'!F13-'Kwh Reading'!F12)*1000000 -> 0 | E12: =('Kwh Reading'!C13-'Kwh Reading'!C12)*1000 -> 0 | F12: =('Kwh Reading'!J13-'Kwh Reading'!J12)*1000 -> 0 | G12: =('Kwh Reading'!K13-'Kwh Reading'!K12)*1000 -> 0 | H12: =('Kwh Reading'!L13-'Kwh Reading'!L12)*1000 -> 0 | I12: =('Kwh Reading'!R13-'Kwh Reading'!R12)*1000 -> 0 | J12: =('Kwh Reading'!S13-'Kwh Reading'!S12)*1000 -> 0 | K12: =('Kwh Reading'!I13-'Kwh Reading'!I12)*1000 -> 0 | L12: =('Kwh Reading'!B13-'Kwh Reading'!B12)*1000000 -> 0 | M12: =('Kwh Reading'!M13-'Kwh Reading'!M12)*1000 -> 0 | N12: =('Kwh Reading'!H13-'Kwh Reading'!H12)*1000 -> 0 | O12: =('Kwh Reading'!P13-'Kwh Reading'!P12)*1000 -> 0 | P12: =('Kwh Reading'!G13-'Kwh Reading'!G12)*1000000 -> 0 | Q12: =('Kwh Reading'!Q13-'Kwh Reading'!Q12)*1000 -> 0 | R12: =('Kwh Reading'!N13-'Kwh Reading'!N12)*1000 -> 0 | S12: ='Kwh Reading'!E13-'Kwh Reading'!E12 -> 0 | T12: ='Kwh Reading'!D13-'Kwh Reading'!D12 -> 0 | U12: =('Kwh Reading'!O13-'Kwh Reading'!O12)*1000 -> 0 | V12: =B12-(SUM(C12:U12)) -> 0
A13: ='Kwh Reading'!A13 -> 44722 | B13: =TOTAL!E11 -> 0 | C13: =('Kwh Reading'!T14-'Kwh Reading'!T13)*1000 -> 0 | D13: =('Kwh Reading'!F14-'Kwh Reading'!F13)*1000000 -> 0 | E13: =('Kwh Reading'!C14-'Kwh Reading'!C13)*1000 -> 0 | F13: =('Kwh Reading'!J14-'Kwh Reading'!J13)*1000 -> 0 | G13: =('Kwh Reading'!K14-'Kwh Reading'!K13)*1000 -> 0 | H13: =('Kwh Reading'!L14-'Kwh Reading'!L13)*1000 -> 0 | I13: =('Kwh Reading'!R14-'Kwh Reading'!R13)*1000 -> 0 | J13: =('Kwh Reading'!S14-'Kwh Reading'!S13)*1000 -> 0 | K13: =('Kwh Reading'!I14-'Kwh Reading'!I13)*1000 -> 0 | L13: =('Kwh Reading'!B14-'Kwh Reading'!B13)*1000000 -> 0 | M13: =('Kwh Reading'!M14-'Kwh Reading'!M13)*1000 -> 0 | N13: =('Kwh Reading'!H14-'Kwh Reading'!H13)*1000 -> 0 | O13: =('Kwh Reading'!P14-'Kwh Reading'!P13)*1000 -> 0 | P13: =('Kwh Reading'!G14-'Kwh Reading'!G13)*1000000 -> 0 | Q13: =('Kwh Reading'!Q14-'Kwh Reading'!Q13)*1000 -> 0 | R13: =('Kwh Reading'!N14-'Kwh Reading'!N13)*1000 -> 0 | S13: ='Kwh Reading'!E14-'Kwh Reading'!E13 -> 0 | T13: ='Kwh Reading'!D14-'Kwh Reading'!D13 -> 0 | U13: =('Kwh Reading'!O14-'Kwh Reading'!O13)*1000 -> 0 | V13: =B13-(SUM(C13:U13)) -> 0
A14: ='Kwh Reading'!A14 -> 44723 | B14: =TOTAL!E12 -> 0 | C14: =('Kwh Reading'!T15-'Kwh Reading'!T14)*1000 -> 0 | D14: =('Kwh Reading'!F15-'Kwh Reading'!F14)*1000000 -> 0 | E14: =('Kwh Reading'!C15-'Kwh Reading'!C14)*1000 -> 0 | F14: =('Kwh Reading'!J15-'Kwh Reading'!J14)*1000 -> 0 | G14: =('Kwh Reading'!K15-'Kwh Reading'!K14)*1000 -> 0 | H14: =('Kwh Reading'!L15-'Kwh Reading'!L14)*1000 -> 0 | I14: =('Kwh Reading'!R15-'Kwh Reading'!R14)*1000 -> 0 | J14: =('Kwh Reading'!S15-'Kwh Reading'!S14)*1000 -> 0 | K14: =('Kwh Reading'!I15-'Kwh Reading'!I14)*1000 -> 0 | L14: =('Kwh Reading'!B15-'Kwh Reading'!B14)*1000000 -> 0 | M14: =('Kwh Reading'!M15-'Kwh Reading'!M14)*1000 -> 0 | N14: =('Kwh Reading'!H15-'Kwh Reading'!H14)*1000 -> 0 | O14: =('Kwh Reading'!P15-'Kwh Reading'!P14)*1000 -> 0 | P14: =('Kwh Reading'!G15-'Kwh Reading'!G14)*1000000 -> 0 | Q14: =('Kwh Reading'!Q15-'Kwh Reading'!Q14)*1000 -> 0 | R14: =('Kwh Reading'!N15-'Kwh Reading'!N14)*1000 -> 0 | S14: ='Kwh Reading'!E15-'Kwh Reading'!E14 -> 0 | T14: ='Kwh Reading'!D15-'Kwh Reading'!D14 -> 0 | U14: =('Kwh Reading'!O15-'Kwh Reading'!O14)*1000 -> 0 | V14: =B14-(SUM(C14:U14)) -> 0
A15: ='Kwh Reading'!A15 -> 44724 | B15: =TOTAL!E13 -> 0 | C15: =('Kwh Reading'!T16-'Kwh Reading'!T15)*1000 -> 0 | D15: =('Kwh Reading'!F16-'Kwh Reading'!F15)*1000000 -> 0 | E15: =('Kwh Reading'!C16-'Kwh Reading'!C15)*1000 -> 0 | F15: =('Kwh Reading'!J16-'Kwh Reading'!J15)*1000 -> 0 | G15: =('Kwh Reading'!K16-'Kwh Reading'!K15)*1000 -> 0 | H15: =('Kwh Reading'!L16-'Kwh Reading'!L15)*1000 -> 0 | I15: =('Kwh Reading'!R16-'Kwh Reading'!R15)*1000 -> 0 | J15: =('Kwh Reading'!S16-'Kwh Reading'!S15)*1000 -> 0 | K15: =('Kwh Reading'!I16-'Kwh Reading'!I15)*1000 -> 0 | L15: =('Kwh Reading'!B16-'Kwh Reading'!B15)*1000000 -> 0 | M15: =('Kwh Reading'!M16-'Kwh Reading'!M15)*1000 -> 0 | N15: =('Kwh Reading'!H16-'Kwh Reading'!H15)*1000 -> 0 | O15: =('Kwh Reading'!P16-'Kwh Reading'!P15)*1000 -> 0 | P15: =('Kwh Reading'!G16-'Kwh Reading'!G15)*1000000 -> 0 | Q15: =('Kwh Reading'!Q16-'Kwh Reading'!Q15)*1000 -> 0 | R15: =('Kwh Reading'!N16-'Kwh Reading'!N15)*1000 -> 0 | S15: ='Kwh Reading'!E16-'Kwh Reading'!E15 -> 0 | T15: ='Kwh Reading'!D16-'Kwh Reading'!D15 -> 0 | U15: =('Kwh Reading'!O16-'Kwh Reading'!O15)*1000 -> 0 | V15: =B15-(SUM(C15:U15)) -> 0
... A34: ='Kwh Reading'!A34 -> 44743 | B34: =TOTAL!E32 -> 0 | C34: =('Kwh Reading'!T35-'Kwh Reading'!T34)*1000 -> 0 | D34: =('Kwh Reading'!F35-'Kwh Reading'!F34)*1000000 -> 0 | E34: =('Kwh Reading'!C35-'Kwh Reading'!C34)*1000 -> 0 | F34: =('Kwh Reading'!J35-'Kwh Reading'!J34)*1000 -> 0 | G34: =('Kwh Reading'!K35-'Kwh Reading'!K34)*1000 -> 0 | H34: =('Kwh Reading'!L35-'Kwh Reading'!L34)*1000 -> 0 | I34: =('Kwh Reading'!R35-'Kwh Reading'!R34)*1000 -> 0 | J34: =('Kwh Reading'!S35-'Kwh Reading'!S34)*1000 -> 0 | K34: =('Kwh Reading'!I35-'Kwh Reading'!I34)*1000 -> 0 | L34: =('Kwh Reading'!B35-'Kwh Reading'!B34)*1000000 -> 0 | M34: =('Kwh Reading'!M35-'Kwh Reading'!M34)*1000 -> 0 | N34: =('Kwh Reading'!H35-'Kwh Reading'!H34)*1000 -> 0 | O34: =('Kwh Reading'!P35-'Kwh Reading'!P34)*1000 -> 0 | P34: =('Kwh Reading'!G35-'Kwh Reading'!G34)*1000000 -> 0 | Q34: =('Kwh Reading'!Q35-'Kwh Reading'!Q34)*1000 -> 0 | R34: =('Kwh Reading'!N35-'Kwh Reading'!N34)*1000 -> 0 | S34: ='Kwh Reading'!E35-'Kwh Reading'!E34 -> 0 | T34: ='Kwh Reading'!D35-'Kwh Reading'!D34 -> 0 | U34: =('Kwh Reading'!O35-'Kwh Reading'!O34)*1000 -> 0 | V34: =B34-(SUM(C34:U34)) -> 0
A35: Total | B35: =SUM(B4:B34) -> 0 | C35: =SUM(C4:C34) -> -585440 | D35: =SUM(D4:D34) -> -3254800 | E35: =SUM(E4:E34) -> -313430 | F35: =SUM(F4:F34) -> -467590 | G35: =SUM(G4:G34) -> -458270 | H35: =SUM(H4:H34) -> -311640 | I35: =SUM(I4:I34) -> -190150 | ... V35: =SUM(V4:V34) -> 30165320

Sheet Kwh area wise 
A2: Month | B2: Total KWH | C2: Reef Club Kitchen KWH | D2: Main Kitchen KWH | E2: Pastry Kitchen KWH | F2: Laundry KWH | G2: STP KWH | H2: Kuda Huraa Accomodation KWH | I2: Guest Room Beach Pavilion & Beach Bungalow KWH | J2: Guest Room Water Bungalow KWH | K2: Spa KWH | L2: Others KWH
A3: ='Kwh Reading'!A4 -> 44713 | B3: =TOTAL!E2 -> 0 | C3: ='Kwh Consumption'!C4 -> 500 | D3: ='Kwh Consumption'!D4 -> 2700 | E3: ='Kwh Consumption'!E4 -> 230 | F3: =('Kwh Consumption'!F4+'Kwh Consumption'!G4+'Kwh Consumption'!H4) -> 1110 | G3: =('Kwh Consumption'!I4+'Kwh Consumption'!J4) -> 140 | H3: =('Kwh Consumption'!K4+'Kwh Consumption'!L4) -> 1440 | I3: =('Kwh Consumption'!M4+'Kwh Consumption'!N4+'Kwh Consumption'!O4+'Kwh Consumption'!P4+'Kwh Consumption'!Q4+'Kwh Consumption'!R4) -> 4120 | J3: =('Kwh Consumption'!S4+'Kwh Consumption'!T4) -> 4714.68 | K3: ='Kwh Consumption'!U4 -> 210 | L3: =B3-C3-D3-E3-F3-G3-H3-I3-J3-K3 -> -15164.68
A4: ='Kwh Reading'!A5 -> 44714 | B4: =TOTAL!E3 -> 0 | C4: ='Kwh Consumption'!C5 -> 500 | D4: ='Kwh Consumption'!D5 -> 2700 | E4: ='Kwh Consumption'!E5 -> 240 | F4: =('Kwh Consumption'!F5+'Kwh Consumption'!G5+'Kwh Consumption'!H5) -> 740 | G4: =('Kwh Consumption'!I5+'Kwh Consumption'!J5) -> 150 | H4: =('Kwh Consumption'!K5+'Kwh Consumption'!L5) -> 1460 | I4: =('Kwh Consumption'!M5+'Kwh Consumption'!N5+'Kwh Consumption'!O5+'Kwh Consumption'!P5+'Kwh Consumption'!Q5+'Kwh Consumption'!R5) -> 4760 | J4: =('Kwh Consumption'!S5+'Kwh Consumption'!T5) -> 5029.07 | K4: ='Kwh Consumption'!U5 -> 200 | L4: =B4-C4-D4-E4-F4-G4-H4-I4-J4-K4 -> -15779.07
A5: ='Kwh Reading'!A6 -> 44715 | B5: =TOTAL!E4 -> 0 | C5: ='Kwh Consumption'!C6 -> 280 | D5: ='Kwh Consumption'!D6 -> 2700 | E5: ='Kwh Consumption'!E6 -> 250 | F5: =('Kwh Consumption'!F6+'Kwh Consumption'!G6+'Kwh Consumption'!H6) -> 940 | G5: =('Kwh Consumption'!I6+'Kwh Consumption'!J6) -> 130 | H5: =('Kwh Consumption'!K6+'Kwh Consumption'!L6) -> 1370 | I5: =('Kwh Consumption'!M6+'Kwh Consumption'!N6+'Kwh Consumption'!O6+'Kwh Consumption'!P6+'Kwh Consumption'!Q6+'Kwh Consumption'!R6) -> 4880 | J5: =('Kwh Consumption'!S6+'Kwh Consumption'!T6) -> 4755.6 | K5: ='Kwh Consumption'!U6 -> 200 | L5: =B5-C5-D5-E5-F5-G5-H5-I5-J5-K5 -> -15505.6
A6: ='Kwh Reading'!A7 -> 44716 | B6: =TOTAL!E5 -> 0 | C6: ='Kwh Consumption'!C7 -> 480 | D6: ='Kwh Consumption'!D7 -> 2700 | E6: ='Kwh Consumption'!E7 -> 4220 | F6: =('Kwh Consumption'!F7+'Kwh Consumption'!G7+'Kwh Consumption'!H7) -> 500840 | G6: =('Kwh Consumption'!I7+'Kwh Consumption'!J7) -> 140 | H6: =('Kwh Consumption'!K7+'Kwh Consumption'!L7) -> 1460 | I6: =('Kwh Consumption'!M7+'Kwh Consumption'!N7+'Kwh Consumption'!O7+'Kwh Consumption'!P7+'Kwh Consumption'!Q7+'Kwh Consumption'!R7) -> 4630 | J6: =('Kwh Consumption'!S7+'Kwh Consumption'!T7) -> 4846.64 | K6: ='Kwh Consumption'!U7 -> 200 | L6: =B6-C6-D6-E6-F6-G6-H6-I6-J6-K6 -> -519516.64
A7: ='Kwh Reading'!A8 -> 44717 | B7: =TOTAL!E6 -> 0 | C7: ='Kwh Consumption'!C8 -> 460 | D7: ='Kwh Consumption'!D8 -> 2800 | E7: ='Kwh Consumption'!E8 -> -3790 | F7: =('Kwh Consumption'!F8+'Kwh Consumption'!G8+'Kwh Consumption'!H8) -> -499210 | G7: =('Kwh Consumption'!I8+'Kwh Consumption'!J8) -> 140 | H7: =('Kwh Consumption'!K8+'Kwh Consumption'!L8) -> 1340 | I7: =('Kwh Consumption'!M8+'Kwh Consumption'!N8+'Kwh Consumption'!O8+'Kwh Consumption'!P8+'Kwh Consumption'!Q8+'Kwh Consumption'!R8) -> 4410 | J7: =('Kwh Consumption'!S8+'Kwh Consumption'!T8) -> 4895.92 | K7: ='Kwh Consumption'!U8 -> 190 | L7: =B7-C7-D7-E7-F7-G7-H7-I7-J7-K7 -> 488764.08
A8: ='Kwh Reading'!A9 -> 44718 | B8: =TOTAL!E7 -> 0 | C8: ='Kwh Consumption'!C9 -> 520 | D8: ='Kwh Consumption'!D9 -> 2600 | E8: ='Kwh Consumption'!E9 -> 220 | F8: =('Kwh Consumption'!F9+'Kwh Consumption'!G9+'Kwh Consumption'!H9) -> 930 | G8: =('Kwh Consumption'!I9+'Kwh Consumption'!J9) -> 140 | H8: =('Kwh Consumption'!K9+'Kwh Consumption'!L9) -> 1440 | I8: =('Kwh Consumption'!M9+'Kwh Consumption'!N9+'Kwh Consumption'!O9+'Kwh Consumption'!P9+'Kwh Consumption'!Q9+'Kwh Consumption'!R9) -> 4580 | J8: =('Kwh Consumption'!S9+'Kwh Consumption'!T9) -> 4671.96 | K8: ='Kwh Consumption'!U9 -> 230 | L8: =B8-C8-D8-E8-F8-G8-H8-I8-J8-K8 -> -15331.96
A9: ='Kwh Reading'!A10 -> 44719 | B9: =TOTAL!E8 -> 0 | C9: ='Kwh Consumption'!C10 -> 490 | D9: ='Kwh Consumption'!D10 -> 2600 | E9: ='Kwh Consumption'!E10 -> 220 | F9: =('Kwh Consumption'!F10+'Kwh Consumption'!G10+'Kwh Consumption'!H10) -> 990 | G9: =('Kwh Consumption'!I10+'Kwh Consumption'!J10) -> 130 | H9: =('Kwh Consumption'!K10+'Kwh Consumption'!L10) -> 1370 | I9: =('Kwh Consumption'!M10+'Kwh Consumption'!N10+'Kwh Consumption'!O10+'Kwh Consumption'!P10+'Kwh Consumption'!Q10+'Kwh Consumption'!R10) -> 4150 | J9: =('Kwh Consumption'!S10+'Kwh Consumption'!T10) -> 8568.73 | K9: ='Kwh Consumption'!U10 -> 210 | L9: =B9-C9-D9-E9-F9-G9-H9-I9-J9-K9 -> -18728.73
A10: ='Kwh Reading'!A11 -> 44720 | B10: =TOTAL!E9 -> 0 | C10: ='Kwh Consumption'!C11 -> -588670 | D10: ='Kwh Consumption'!D11 -> -3273600 | E10: ='Kwh Consumption'!E11 -> -315020 | F10: =('Kwh Consumption'!F11+'Kwh Consumption'!G11+'Kwh Consumption'!H11) -> -1243840 | G10: =('Kwh Consumption'!I11+'Kwh Consumption'!J11) -> -352160 | H10: =('Kwh Consumption'!K11+'Kwh Consumption'!L11) -> -1730040 | I10: =('Kwh Consumption'!M11+'Kwh Consumption'!N11+'Kwh Consumption'!O11+'Kwh Consumption'!P11+'Kwh Consumption'!Q11+'Kwh Consumption'!R11) -> -5176940 | J10: =('Kwh Consumption'!S11+'Kwh Consumption'!T11) -> -17371343 | K10: ='Kwh Consumption'!U11 -> -224970 | L10: =B10-C10-D10-E10-F10-G10-H10-I10-J10-K10 -> 30276583
A11: ='Kwh Reading'!A12 -> 44721 | B11: =TOTAL!E10 -> 0 | C11: ='Kwh Consumption'!C12 -> 0 | D11: ='Kwh Consumption'!D12 -> 0 | E11: ='Kwh Consumption'!E12 -> 0 | F11: =('Kwh Consumption'!F12+'Kwh Consumption'!G12+'Kwh Consumption'!H12) -> 0 | G11: =('Kwh Consumption'!I12+'Kwh Consumption'!J12) -> 0 | H11: =('Kwh Consumption'!K12+'Kwh Consumption'!L12) -> 0 | I11: =('Kwh Consumption'!M12+'Kwh Consumption'!N12+'Kwh Consumption'!O12+'Kwh Consumption'!P12+'Kwh Consumption'!Q12+'Kwh Consumption'!R12) -> 0 | J11: =('Kwh Consumption'!S12+'Kwh Consumption'!T12) -> 0 | K11: ='Kwh Consumption'!U12 -> 0 | L11: =B11-C11-D11-E11-F11-G11-H11-I11-J11-K11 -> 0
A12: ='Kwh Reading'!A13 -> 44722 | B12: =TOTAL!E11 -> 0 | C12: ='Kwh Consumption'!C13 -> 0 | D12: ='Kwh Consumption'!D13 -> 0 | E12: ='Kwh Consumption'!E13 -> 0 | F12: =('Kwh Consumption'!F13+'Kwh Consumption'!G13+'Kwh Consumption'!H13) -> 0 | G12: =('Kwh Consumption'!I13+'Kwh Consumption'!J13) -> 0 | H12: =('Kwh Consumption'!K13+'Kwh Consumption'!L13) -> 0 | I12: =('Kwh Consumption'!M13+'Kwh Consumption'!N13+'Kwh Consumption'!O13+'Kwh Consumption'!P13+'Kwh Consumption'!Q13+'Kwh Consumption'!R13) -> 0 | J12: =('Kwh Consumption'!S13+'Kwh Consumption'!T13) -> 0 | K12: ='Kwh Consumption'!U13 -> 0 | L12: =B12-C12-D12-E12-F12-G12-H12-I12-J12-K12 -> 0
A13: ='Kwh Reading'!A14 -> 44723 | B13: =TOTAL!E12 -> 0 | C13: ='Kwh Consumption'!C14 -> 0 | D13: ='Kwh Consumption'!D14 -> 0 | E13: ='Kwh Consumption'!E14 -> 0 | F13: =('Kwh Consumption'!F14+'Kwh Consumption'!G14+'Kwh Consumption'!H14) -> 0 | G13: =('Kwh Consumption'!I14+'Kwh Consumption'!J14) -> 0 | H13: =('Kwh Consumption'!K14+'Kwh Consumption'!L14) -> 0 | I13: =('Kwh Consumption'!M14+'Kwh Consumption'!N14+'Kwh Consumption'!O14+'Kwh Consumption'!P14+'Kwh Consumption'!Q14+'Kwh Consumption'!R14) -> 0 | J13: =('Kwh Consumption'!S14+'Kwh Consumption'!T14) -> 0 | K13: ='Kwh Consumption'!U14 -> 0 | L13: =B13-C13-D13-E13-F13-G13-H13-I13-J13-K13 -> 0
A14: ='Kwh Reading'!A15 -> 44724 | B14: =TOTAL!E13 -> 0 | C14: ='Kwh Consumption'!C15 -> 0 | D14: ='Kwh Consumption'!D15 -> 0 | E14: ='Kwh Consumption'!E15 -> 0 | F14: =('Kwh Consumption'!F15+'Kwh Consumption'!G15+'Kwh Consumption'!H15) -> 0 | G14: =('Kwh Consumption'!I15+'Kwh Consumption'!J15) -> 0 | H14: =('Kwh Consumption'!K15+'Kwh Consumption'!L15) -> 0 | I14: =('Kwh Consumption'!M15+'Kwh Consumption'!N15+'Kwh Consumption'!O15+'Kwh Consumption'!P15+'Kwh Consumption'!Q15+'Kwh Consumption'!R15) -> 0 | J14: =('Kwh Consumption'!S15+'Kwh Consumption'!T15) -> 0 | K14: ='Kwh Consumption'!U15 -> 0 | L14: =B14-C14-D14-E14-F14-G14-H14-I14-J14-K14 -> 0
... A33: ='Kwh Reading'!A34 -> 44743 | B33: =TOTAL!E32 -> 0 | C33: ='Kwh Consumption'!C34 -> 0 | D33: ='Kwh Consumption'!D34 -> 0 | E33: ='Kwh Consumption'!E34 -> 0 | F33: =('Kwh Consumption'!F34+'Kwh Consumption'!G34+'Kwh Consumption'!H34) -> 0 | G33: =('Kwh Consumption'!I34+'Kwh Consumption'!J34) -> 0 | H33: =('Kwh Consumption'!K34+'Kwh Consumption'!L34) -> 0 | I33: =('Kwh Consumption'!M34+'Kwh Consumption'!N34+'Kwh Consumption'!O34+'Kwh Consumption'!P34+'Kwh Consumption'!Q34+'Kwh Consumption'!R34) -> 0 | J33: =('Kwh Consumption'!S34+'Kwh Consumption'!T34) -> 0 | K33: ='Kwh Consumption'!U34 -> 0 | L33: =B33-C33-D33-E33-F33-G33-H33-I33-J33-K33 -> 0
A34: Total kwh | B34: =SUM(B3:B33) -> 0 | C34: =SUM(C3:C33) -> -585440 | D34: =SUM(D3:D33) -> -3254800 | E34: =SUM(E3:E33) -> -313430 | F34: =SUM(F3:F33) -> -1237500 | G34: =SUM(G3:G33) -> -351190 | H34: =SUM(H3:H33) -> -1720160 | I34: =SUM(I3:I33) -> -5145410 | ... L34: =SUM(L3:L33) -> 30165320 | M34: =C34+D34+E34+F34+G34+H34+I34+J34+K34+L34 -> 0
A36: Total $ | B36: =TOTAL!F2 -> 0 | C36: =C34*B36 -> 0 | D36: =D34*B36 -> 0 | E36: =E34*B36 -> 0 | F36: =F34*B36 -> 0 | G36: =G34*B36 -> 0 | H36: =H34*B36 -> 0 | I36: =I34*B36 -> 0 | J36: =J34*B36 -> 0 | K36: =K34*B36 -> 0 | L36: =L34*B36 -> 0 | M36: =C36+D36+E36+F36+G36+H36+I36+J36+K36+L36 -> 0

Sheet  Kwh area wise $ 
A2: Month | B2: $ /Per KWH | C2: Total $ | D2: Reef Club $ | E2: Kitchen $ | F2: Pastry $ | G2: Laundry $ | H2: STP $ | I2: Kuda Huraa Accomodation $ | J2: Guest Room Beach Pavilion & Beach Bungalow $ | K2: Guest Room Water Bungalow $ | L2: Spa $ | M2: Others $
A3: ='Kwh Reading'!A4 -> 44713 | B3: =TOTAL!F2 -> 0 | C3: ='Kwh Consumption'!B4*' Kwh area wise $ '!B3 -> 0 | D3: ='Kwh Consumption'!C4*' Kwh area wise $ '!B3 -> 0 | E3: ='Kwh Consumption'!D4*' Kwh area wise $ '!B3 -> 0 | F3: ='Kwh Consumption'!E4*' Kwh area wise $ '!B3 -> 0 | G3: =('Kwh Consumption'!F4+'Kwh Consumption'!G4+'Kwh Consumption'!H4)*' Kwh area wise $ '!B3 -> 0 | H3: =('Kwh Consumption'!I4+'Kwh Consumption'!J4)*' Kwh area wise $ '!B3 -> 0 | I3: =('Kwh Consumption'!K4+'Kwh Consumption'!L4)*' Kwh area wise $ '!B3 -> 0 | J3: =('Kwh Consumption'!M4+'Kwh Consumption'!N4+'Kwh Consumption'!O4+'Kwh Consumption'!P4+'Kwh Consumption'!Q4+'Kwh Consumption'!R4)*' Kwh area wise $ '!B3 -> 0 | K3: =('Kwh Consumption'!S4+'Kwh Consumption'!T4)*' Kwh area wise $ '!B3 -> 0 | L3: ='Kwh Consumption'!U4*' Kwh area wise $ '!B3 -> 0 | M3: ='Kwh Consumption'!V4*' Kwh area wise $ '!B3 -> 0
A4: ='Kwh Reading'!A5 -> 44714 | B4: =TOTAL!F3 -> 0 | C4: ='Kwh Consumption'!B5*' Kwh area wise $ '!B4 -> 0 | D4: ='Kwh Consumption'!C5*' Kwh area wise $ '!B4 -> 0 | E4: ='Kwh Consumption'!D5*' Kwh area wise $ '!B4 -> 0 | F4: ='Kwh Consumption'!E5*' Kwh area wise $ '!B4 -> 0 | G4: =('Kwh Consumption'!F5+'Kwh Consumption'!G5+'Kwh Consumption'!H5)*' Kwh area wise $ '!B4 -> 0 | H4: =('Kwh Consumption'!I5+'Kwh Consumption'!J5)*' Kwh area wise $ '!B4 -> 0 | I4: =('Kwh Consumption'!K5+'Kwh Consumption'!L5)*' Kwh area wise $ '!B4 -> 0 | J4: =('Kwh Consumption'!M5+'Kwh Consumption'!N5+'Kwh Consumption'!O5+'Kwh Consumption'!P5+'Kwh Consumption'!Q5+'Kwh Consumption'!R5)*' Kwh area wise $ '!B4 -> 0 | K4: =('Kwh Consumption'!S5+'Kwh Consumption'!T5)*' Kwh area wise $ '!B4 -> 0 | L4: ='Kwh Consumption'!U5*' Kwh area wise $ '!B4 -> 0 | M4: ='Kwh Consumption'!V5*' Kwh area wise $ '!B4 -> 0
A5: ='Kwh Reading'!A6 -> 44715 | B5: =TOTAL!F4 -> 0 | C5: ='Kwh Consumption'!B6*' Kwh area wise $ '!B5 -> 0 | D5: ='Kwh Consumption'!C6*' Kwh area wise $ '!B5 -> 0 | E5: ='Kwh Consumption'!D6*' Kwh area wise $ '!B5 -> 0 | F5: ='Kwh Consumption'!E6*' Kwh area wise $ '!B5 -> 0 | G5: =('Kwh Consumption'!F6+'Kwh Consumption'!G6+'Kwh Consumption'!H6)*' Kwh area wise $ '!B5 -> 0 | H5: =('Kwh Consumption'!I6+'Kwh Consumption'!J6)*' Kwh area wise $ '!B5 -> 0 | I5: =('Kwh Consumption'!K6+'Kwh Consumption'!L6)*' Kwh area wise $ '!B5 -> 0 | J5: =('Kwh Consumption'!M6+'Kwh Consumption'!N6+'Kwh Consumption'!O6+'Kwh Consumption'!P6+'Kwh Consumption'!Q6+'Kwh Consumption'!R6)*' Kwh area wise $ '!B5 -> 0 | K5: =('Kwh Consumption'!S6+'Kwh Consumption'!T6)*' Kwh area wise $ '!B5 -> 0 | L5: ='Kwh Consumption'!U6*' Kwh area wise $ '!B5 -> 0 | M5: ='Kwh Consumption'!V6*' Kwh area wise $ '!B5 -> 0
A6: ='Kwh Reading'!A7 -> 44716 | B6: =TOTAL!F5 -> 0 | C6: ='Kwh Consumption'!B7*' Kwh area wise $ '!B6 -> 0 | D6: ='Kwh Consumption'!C7*' Kwh area wise $ '!B6 -> 0 | E6: ='Kwh Consumption'!D7*' Kwh area wise $ '!B6 -> 0 | F6: ='Kwh Consumption'!E7*' Kwh area wise $ '!B6 -> 0 | G6: =('Kwh Consumption'!F7+'Kwh Consumption'!G7+'Kwh Consumption'!H7)*' Kwh area wise $ '!B6 -> 0 | H6: =('Kwh Consumption'!I7+'Kwh Consumption'!J7)*' Kwh area wise $ '!B6 -> 0 | I6: =('Kwh Consumption'!K7+'Kwh Consumption'!L7)*' Kwh area wise $ '!B6 -> 0 | J6: =('Kwh Consumption'!M7+'Kwh Consumption'!N7+'Kwh Consumption'!O7+'Kwh Consumption'!P7+'Kwh Consumption'!Q7+'Kwh Consumption'!R7)*' Kwh area wise $ '!B6 -> 0 | K6: =('Kwh Consumption'!S7+'Kwh Consumption'!T7)*' Kwh area wise $ '!B6 -> 0 | L6: ='Kwh Consumption'!U7*' Kwh area wise $ '!B6 -> 0 | M6: ='Kwh Consumption'!V7*' Kwh area wise $ '!B6 -> 0
A7: ='Kwh Reading'!A8 -> 44717 | B7: =TOTAL!F6 -> 0 | C7: ='Kwh Consumption'!B8*' Kwh area wise $ '!B7 -> 0 | D7: ='Kwh Consumption'!C8*' Kwh area wise $ '!B7 -> 0 | E7: ='Kwh Consumption'!D8*' Kwh area wise $ '!B7 -> 0 | F7: ='Kwh Consumption'!E8*' Kwh area wise $ '!B7 -> 0 | G7: =('Kwh Consumption'!F8+'Kwh Consumption'!G8+'Kwh Consumption'!H8)*' Kwh area wise $ '!B7 -> 0 | H7: =('Kwh Consumption'!I8+'Kwh Consumption'!J8)*' Kwh area wise $ '!B7 -> 0 | I7: =('Kwh Consumption'!K8+'Kwh Consumption'!L8)*' Kwh area wise $ '!B7 -> 0 | J7: =('Kwh Consumption'!M8+'Kwh Consumption'!N8+'Kwh Consumption'!O8+'Kwh Consumption'!P8+'Kwh Consumption'!Q8+'Kwh Consumption'!R8)*' Kwh area wise $ '!B7 -> 0 | K7: =('Kwh Consumption'!S8+'Kwh Consumption'!T8)*' Kwh area wise $ '!B7 -> 0 | L7: ='Kwh Consumption'!U8*' Kwh area wise $ '!B7 -> 0 | M7: ='Kwh Consumption'!V8*' Kwh area wise $ '!B7 -> 0
A8: ='Kwh Reading'!A9 -> 44718 | B8: =TOTAL!F7 -> 0 | C8: ='Kwh Consumption'!B9*' Kwh area wise $ '!B8 -> 0 | D8: ='Kwh Consumption'!C9*' Kwh area wise $ '!B8 -> 0 | E8: ='Kwh Consumption'!D9*' Kwh area wise $ '!B8 -> 0 | F8: ='Kwh Consumption'!E9*' Kwh area wise $ '!B8 -> 0 | G8: =('Kwh Consumption'!F9+'Kwh Consumption'!G9+'Kwh Consumption'!H9)*' Kwh area wise $ '!B8 -> 0 | H8: =('Kwh Consumption'!I9+'Kwh Consumption'!J9)*' Kwh area wise $ '!B8 -> 0 | I8: =('Kwh Consumption'!K9+'Kwh Consumption'!L9)*' Kwh area wise $ '!B8 -> 0 | J8: =('Kwh Consumption'!M9+'Kwh Consumption'!N9+'Kwh Consumption'!O9+'Kwh Consumption'!P9+'Kwh Consumption'!Q9+'Kwh Consumption'!R9)*' Kwh area wise $ '!B8 -> 0 | K8: =('Kwh Consumption'!S9+'Kwh Consumption'!T9)*' Kwh area wise $ '!B8 -> 0 | L8: ='Kwh Consumption'!U9*' Kwh area wise $ '!B8 -> 0 | M8: ='Kwh Consumption'!V9*' Kwh area wise $ '!B8 -> 0
A9: ='Kwh Reading'!A10 -> 44719 | B9: =TOTAL!F8 -> 0 | C9: ='Kwh Consumption'!B10*' Kwh area wise $ '!B9 -> 0 | D9: ='Kwh Consumption'!C10*' Kwh area wise $ '!B9 -> 0 | E9: ='Kwh Consumption'!D10*' Kwh area wise $ '!B9 -> 0 | F9: ='Kwh Consumption'!E10*' Kwh area wise $ '!B9 -> 0 | G9: =('Kwh Consumption'!F10+'Kwh Consumption'!G10+'Kwh Consumption'!H10)*' Kwh area wise $ '!B9 -> 0 | H9: =('Kwh Consumption'!I10+'Kwh Consumption'!J10)*' Kwh area wise $ '!B9 -> 0 | I9: =('Kwh Consumption'!K10+'Kwh Consumption'!L10)*' Kwh area wise $ '!B9 -> 0 | J9: =('Kwh Consumption'!M10+'Kwh Consumption'!N10+'Kwh Consumption'!O10+'Kwh Consumption'!P10+'Kwh Consumption'!Q10+'Kwh Consumption'!R10)*' Kwh area wise $ '!B9 -> 0 | K9: =('Kwh Consumption'!S10+'Kwh Consumption'!T10)*' Kwh area wise $ '!B9 -> 0 | L9: ='Kwh Consumption'!U10*' Kwh area wise $ '!B9 -> 0 | M9: ='Kwh Consumption'!V10*' Kwh area wise $ '!B9 -> 0
A10: ='Kwh Reading'!A11 -> 44720 | B10: =TOTAL!F9 -> 0 | C10: ='Kwh Consumption'!B11*' Kwh area wise $ '!B10 -> 0 | D10: ='Kwh Consumption'!C11*' Kwh area wise $ '!B10 -> 0 | E10: ='Kwh Consumption'!D11*' Kwh area wise $ '!B10 -> 0 | F10: ='Kwh Consumption'!E11*' Kwh area wise $ '!B10 -> 0 | G10: =('Kwh Consumption'!F11+'Kwh Consumption'!G11+'Kwh Consumption'!H11)*' Kwh area wise $ '!B10 -> 0 | H10: =('Kwh Consumption'!I11+'Kwh Consumption'!J11)*' Kwh area wise $ '!B10 -> 0 | I10: =('Kwh Consumption'!K11+'Kwh Consumption'!L11)*' Kwh area wise $ '!B10 -> 0 | J10: =('Kwh Consumption'!M11+'Kwh Consumption'!N11+'Kwh Consumption'!O11+'Kwh Consumption'!P11+'Kwh Consumption'!Q11+'Kwh Consumption'!R11)*' Kwh area wise $ '!B10 -> 0 | K10: =('Kwh Consumption'!S11+'Kwh Consumption'!T11)*' Kwh area wise $ '!B10 -> 0 | L10: ='Kwh Consumption'!U11*' Kwh area wise $ '!B10 -> 0 | M10: ='Kwh Consumption'!V11*' Kwh area wise $ '!B10 -> 0
A11: ='Kwh Reading'!A12 -> 44721 | B11: =TOTAL!F10 -> 0 | C11: ='Kwh Consumption'!B12*' Kwh area wise $ '!B11 -> 0 | D11: ='Kwh Consumption'!C12*' Kwh area wise $ '!B11 -> 0 | E11: ='Kwh Consumption'!D12*' Kwh area wise $ '!B11 -> 0 | F11: ='Kwh Consumption'!E12*' Kwh area wise $ '!B11 -> 0 | G11: =('Kwh Consumption'!F12+'Kwh Consumption'!G12+'Kwh Consumption'!H12)*' Kwh area wise $ '!B11 -> 0 | H11: =('Kwh Consumption'!I12+'Kwh Consumption'!J12)*' Kwh area wise $ '!B11 -> 0 | I11: =('Kwh Consumption'!K12+'Kwh Consumption'!L12)*' Kwh area wise $ '!B11 -> 0 | J11: =('Kwh Consumption'!M12+'Kwh Consumption'!N12+'Kwh Consumption'!O12+'Kwh Consumption'!P12+'Kwh Consumption'!Q12+'Kwh Consumption'!R12)*' Kwh area wise $ '!B11 -> 0 | K11: =('Kwh Consumption'!S12+'Kwh Consumption'!T12)*' Kwh area wise $ '!B11 -> 0 | L11: ='Kwh Consumption'!U12*' Kwh area wise $ '!B11 -> 0 | M11: ='Kwh Consumption'!V12*' Kwh area wise $ '!B11 -> 0
A12: ='Kwh Reading'!A13 -> 44722 | B12: =TOTAL!F11 -> 0 | C12: ='Kwh Consumption'!B13*' Kwh area wise $ '!B12 -> 0 | D12: ='Kwh Consumption'!C13*' Kwh area wise $ '!B12 -> 0 | E12: ='Kwh Consumption'!D13*' Kwh area wise $ '!B12 -> 0 | F12: ='Kwh Consumption'!E13*' Kwh area wise $ '!B12 -> 0 | G12: =('Kwh Consumption'!F13+'Kwh Consumption'!G13+'Kwh Consumption'!H13)*' Kwh area wise $ '!B12 -> 0 | H12: =('Kwh Consumption'!I13+'Kwh Consumption'!J13)*' Kwh area wise $ '!B12 -> 0 | I12: =('Kwh Consumption'!K13+'Kwh Consumption'!L13)*' Kwh area wise $ '!B12 -> 0 | J12: =('Kwh Consumption'!M13+'Kwh Consumption'!N13+'Kwh Consumption'!O13+'Kwh Consumption'!P13+'Kwh Consumption'!Q13+'Kwh Consumption'!R13)*' Kwh area wise $ '!B12 -> 0 | K12: =('Kwh Consumption'!S13+'Kwh Consumption'!T13)*' Kwh area wise $ '!B12 -> 0 | L12: ='Kwh Consumption'!U13*' Kwh area wise $ '!B12 -> 0 | M12: ='Kwh Consumption'!V13*' Kwh area wise $ '!B12 -> 0
A13: ='Kwh Reading'!A14 -> 44723 | B13: =TOTAL!F12 -> 0 | C13: ='Kwh Consumption'!B14*' Kwh area wise $ '!B13 -> 0 | D13: ='Kwh Consumption'!C14*' Kwh area wise $ '!B13 -> 0 | E13: ='Kwh Consumption'!D14*' Kwh area wise $ '!B13 -> 0 | F13: ='Kwh Consumption'!E14*' Kwh area wise $ '!B13 -> 0 | G13: =('Kwh Consumption'!F14+'Kwh Consumption'!G14+'Kwh Consumption'!H14)*' Kwh area wise $ '!B13 -> 0 | H13: =('Kwh Consumption'!I14+'Kwh Consumption'!J14)*' Kwh area wise $ '!B13 -> 0 | I13: =('Kwh Consumption'!K14+'Kwh Consumption'!L14)*' Kwh area wise $ '!B13 -> 0 | J13: =('Kwh Consumption'!M14+'Kwh Consumption'!N14+'Kwh Consumption'!O14+'Kwh Consumption'!P14+'Kwh Consumption'!Q14+'Kwh Consumption'!R14)*' Kwh area wise $ '!B13 -> 0 | K13: =('Kwh Consumption'!S14+'Kwh Consumption'!T14)*' Kwh area wise $ '!B13 -> 0 | L13: ='Kwh Consumption'!U14*' Kwh area wise $ '!B13 -> 0 | M13: ='Kwh Consumption'!V14*' Kwh area wise $ '!B13 -> 0
A14: ='Kwh Reading'!A15 -> 44724 | B14: =TOTAL!F13 -> 0 | C14: ='Kwh Consumption'!B15*' Kwh area wise $ '!B14 -> 0 | D14: ='Kwh Consumption'!C15*' Kwh area wise $ '!B14 -> 0 | E14: ='Kwh Consumption'!D15*' Kwh area wise $ '!B14 -> 0 | F14: ='Kwh Consumption'!E15*' Kwh area wise $ '!B14 -> 0 | G14: =('Kwh Consumption'!F15+'Kwh Consumption'!G15+'Kwh Consumption'!H15)*' Kwh area wise $ '!B14 -> 0 | H14: =('Kwh Consumption'!I15+'Kwh Consumption'!J15)*' Kwh area wise $ '!B14 -> 0 | I14: =('Kwh Consumption'!K15+'Kwh Consumption'!L15)*' Kwh area wise $ '!B14 -> 0 | J14: =('Kwh Consumption'!M15+'Kwh Consumption'!N15+'Kwh Consumption'!O15+'Kwh Consumption'!P15+'Kwh Consumption'!Q15+'Kwh Consumption'!R15)*' Kwh area wise $ '!B14 -> 0 | K14: =('Kwh Consumption'!S15+'Kwh Consumption'!T15)*' Kwh area wise $ '!B14 -> 0 | L14: ='Kwh Consumption'!U15*' Kwh area wise $ '!B14 -> 0 | M14: ='Kwh Consumption'!V15*' Kwh area wise $ '!B14 -> 0
... A33: ='Kwh Reading'!A34 -> 44743 | B33: =TOTAL!F32 -> 0 | C33: ='Kwh Consumption'!B34*' Kwh area wise $ '!B33 -> 0 | D33: ='Kwh Consumption'!C34*' Kwh area wise $ '!B33 -> 0 | E33: ='Kwh Consumption'!D34*' Kwh area wise $ '!B33 -> 0 | F33: ='Kwh Consumption'!E34*' Kwh area wise $ '!B33 -> 0 | G33: =('Kwh Consumption'!F34+'Kwh Consumption'!G34+'Kwh Consumption'!H34)*' Kwh area wise $ '!B33 -> 0 | H33: =('Kwh Consumption'!I34+'Kwh Consumption'!J34)*' Kwh area wise $ '!B33 -> 0 | I33: =('Kwh Consumption'!K34+'Kwh Consumption'!L34)*' Kwh area wise $ '!B33 -> 0 | J33: =('Kwh Consumption'!M34+'Kwh Consumption'!N34+'Kwh Consumption'!O34+'Kwh Consumption'!P34+'Kwh Consumption'!Q34+'Kwh Consumption'!R34)*' Kwh area wise $ '!B33 -> 0 | K33: =('Kwh Consumption'!S34+'Kwh Consumption'!T34)*' Kwh area wise $ '!B33 -> 0 | L33: ='Kwh Consumption'!U34*' Kwh area wise $ '!B33 -> 0 | M33: ='Kwh Consumption'!V34*' Kwh area wise $ '!B33 -> 0
A34: Total | C34: =SUM(C3:C33) -> 0 | D34: =SUM(D3:D33) -> 0 | E34: =SUM(E3:E33) -> 0 | F34: =SUM(F3:F33) -> 0 | G34: =SUM(G3:G33) -> 0 | H34: =SUM(H3:H33) -> 0 | I34: =SUM(I3:I33) -> 0 | J34: =SUM(J3:J33) -> 0 | ... M34: =SUM(M3:M33) -> 0 | N34: =D34+E34+F34+G34+H34+I34+J34+K34+L34+M34 -> 0

Sheet Water Reading
B1: Meter 1 | C1: Meter 2 | D1: Meter 6 | E1: Meter 8 | F1: Meter 7 | G1: Meter 9 | H1: Meter 3 | I1: Meter 5 | J1: Meter 10 | K1: Meter 13 | L1: Meter 16 | M1: Meter 17 | N1: Meter 15 | O1: Meter 14 | P1: Meter 4 | Q1: Meter 11 | R1: Meter 12
A2: Date | B2: Main Meter 1 | C2: Main Meter 2 | D2: Beach Bunglow | E2: Kuda Huraa staff | F2: Bodu hura staff | G2: Laundry | H2: Water Bunglow | I2: Main Kitchen | J2: Second stage | K2: Supply jetty | L2: Staff housing A | M2: Staff housing B | N2: Spa | O2: Staff jetty | P2: Main pool | Q2: Reef club pool | R2: Reef club kitchen
A3: 44713 | B3: 229814 | D3: 268149 | E3: 270526 | F3: 67184 | G3: 119680 | H3: 62098 | I3: 75855 | J3: 22819 | K3: 1024 | L3: 18685 | M3: 27528 | N3: 8625 | O3: 2149 | P3: 31133 | Q3: 1702 | R3: 189
A4: 44714 | B4: 230000 | D4: 268305 | E4: 270612 | F4: 67184 | G4: 119701 | H4: 62098 | I4: 75371 | J4: 22824 | K4: 1024 | L4: 18869 | M4: 27535 | N4: 8626 | O4: 2150 | P4: 31134 | Q4: 1710 | R4: 194
A5: 44715 | B5: 230159 | D5: 268437 | E5: 270675 | F5: 67184 | G5: 119719 | H5: 62098 | I5: 75400 | J5: 22830 | K5: 1024 | L5: 18872 | M5: 27542 | N5: 8627 | O5: 2152 | P5: 31134 | Q5: 1712 | R5: 198
A6: 44716 | B6: 230320 | D6: 268581 | E6: 270738 | F6: 67185 | G6: 119740 | H6: 62098 | I6: 75416 | J6: 22835 | K6: 1024 | L6: 18877 | M6: 27547 | N6: 8630 | O6: 2154 | P6: 31143 | Q6: 1714 | R6: 199
A7: 44717 | B7: 230509 | D7: 268733 | E7: 270799 | F7: 67186 | G7: 119760 | H7: 62098 | I7: 75455 | J7: 22841 | K7: 1024 | L7: 18880 | M7: 27552 | N7: 8631 | O7: 2156 | P7: 31158 | Q7: 1718 | R7: 205
A8: 44718 | B8: 230660 | D8: 268895 | E8: 270877 | F8: 67188 | G8: 119779 | H8: 62099 | I8: 75478 | J8: 22846 | K8: 1024 | L8: 18884 | M8: 27559 | N8: 8639 | O8: 2159 | P8: 31163 | Q8: 1719 | R8: 207
A9: 44719 | B9: 230822 | D9: 269051 | E9: 270440 | F9: 67187 | G9: 119800 | H9: 62099 | I9: 75509 | J9: 22851 | K9: 1024 | L9: 18887 | M9: 27564 | N9: 8632 | O9: 2161 | P9: 31174 | Q9: 1720 | R9: 210
A10: 44720 | B10: 230962 | D10: 269187 | E10: 271002 | F10: 67188 | G10: 119821 | H10: 62099 | I10: 75548 | J10: 22856 | K10: 1024 | L10: 18891 | M10: 27569 | N10: 8635 | O10: 2163 | P10: 31190 | Q10: 1724 | R10: 215
A11: 44721
A12: 44722
A13: 44723
A14: 44724
A15: 44725
A16: 44726
A17: 44727
A18: 44728
A19: 44729
A20: 44730
A21: 44731
A22: 44732
A23: 44733 | S23: .
A24: 44734
A25: 44735
A26: 44736
A27: 44737
A28: 44738
A29: 44739
A30: 44740
A31: 44741
A32: 44742
A33: 44743

Sheet Water consumption
A2: Date | B2: RO production (Ro 1 : 4) | C2: Total Consumption M3 (Meter 1 : 2) | E2: Water Bunglow | G2: Beach bunglow | I2: Main Pool | K2: Main kitchen | M2: Reef club kitchen | O2: Reef club pool | Q2: Bodu Huraa staff | S2: Kuda Huraa staff | U2: Laundry | W2: Second stage | Y2: Total
C3: M3 | D3: % of Total production | E3: M3 | F3: % | G3: M3 | H3: % | I3: M3 | J3: % | K3: M3 | L3: % | M3: M3 | N3: % | O3: M3 | P3: % | Q3: M3 | R3: % | S3: M3 | T3: % | U3: M3 | V3: % | W3: M3 | X3: % | Y3: M3 | Z3: %
A4: ='Water Reading'!A3 -> 44713 | B4: =TOTAL!I2 -> 0 | C4: =('Water Reading'!B4-'Water Reading'!B3)+('Water Reading'!C4-'Water Reading'!C3) -> 186 | D4: =C4/B4 -> #DIV/0! | E4: ='Water Reading'!H4-'Water Reading'!H3 -> 0 | F4: =E4/C4 -> 0 | G4: =('Water Reading'!D4-'Water Reading'!D3)-('Water Reading'!R4-'Water Reading'!R3)-('Water Reading'!Q4-'Water Reading'!Q3) -> 143 | H4: =G4/C4 -> 0.7688172 | I4: ='Water Reading'!P4-'Water Reading'!P3 -> 1 | J4: =I4/C4 -> 0.0053763441 | K4: =('Water Reading'!I4-'Water Reading'!I3)-('Water Reading'!P4-'Water Reading'!P3) -> -485 | L4: =K4/C4 -> -2.6075269 | M4: ='Water Reading'!R4-'Water Reading'!R3 -> 5 | N4: =M4/C4 -> 0.02688172 | O4: ='Water Reading'!Q4-'Water Reading'!Q3 -> 8 | P4: =O4/C4 -> 0.043010753 | Q4: ='Water Reading'!F4-'Water Reading'!F3 -> 0 | R4: =Q4/C4 -> 0 | S4: ='Water Reading'!E4-'Water Reading'!E3 -> 86 | T4: =S4/C4 -> 0.46236559 | U4: ='Water Reading'!G4-'Water Reading'!G3 -> 21 | V4: =U4/C4 -> 0.11290323 | W4: ='Water Reading'!J4-'Water Reading'!J3 -> 5 | X4: =W4/C4 -> 0.02688172 | Y4: =E4+I4+K4+M4+O4+G4+Q4+S4+U4+W4 -> -216 | Z4: =Y4/B4 -> #DIV/0!
A5: ='Water Reading'!A4 -> 44714 | B5: =TOTAL!I3 -> 0 | C5: =('Water Reading'!B5-'Water Reading'!B4)+('Water Reading'!C5-'Water Reading'!C4) -> 159 | D5: =C5/B5 -> #DIV/0! | E5: ='Water Reading'!H5-'Water Reading'!H4 -> 0 | F5: =E5/C5 -> 0 | G5: =('Water Reading'!D5-'Water Reading'!D4)-('Water Reading'!R5-'Water Reading'!R4)-('Water Reading'!Q5-'Water Reading'!Q4) -> 126 | H5: =G5/C5 -> 0.79245283 | I5: ='Water Reading'!P5-'Water Reading'!P4 -> 0 | J5: =I5/C5 -> 0 | K5: =('Water Reading'!I5-'Water Reading'!I4)-('Water Reading'!P5-'Water Reading'!P4) -> 29 | L5: =K5/C5 -> 0.18238994 | M5: ='Water Reading'!R5-'Water Reading'!R4 -> 4 | N5: =M5/C5 -> 0.025157233 | O5: ='Water Reading'!Q5-'Water Reading'!Q4 -> 2 | P5: =O5/C5 -> 0.012578616 | Q5: ='Water Reading'!F5-'Water Reading'!F4 -> 0 | R5: =Q5/C5 -> 0 | S5: ='Water Reading'!E5-'Water Reading'!E4 -> 63 | T5: =S5/C5 -> 0.39622642 | U5: ='Water Reading'!G5-'Water Reading'!G4 -> 18 | V5: =U5/C5 -> 0.11320755 | W5: ='Water Reading'!J5-'Water Reading'!J4 -> 6 | X5: =W5/C5 -> 0.037735849 | Y5: =E5+I5+K5+M5+O5+G5+Q5+S5+U5+W5 -> 248 | Z5: =Y5/B5 -> #DIV/0!
A6: ='Water Reading'!A5 -> 44715 | B6: =TOTAL!I4 -> 0 | C6: =('Water Reading'!B6-'Water Reading'!B5)+('Water Reading'!C6-'Water Reading'!C5) -> 161 | D6: =C6/B6 -> #DIV/0! | E6: ='Water Reading'!H6-'Water Reading'!H5 -> 0 | F6: =E6/C6 -> 0 | G6: =('Water Reading'!D6-'Water Reading'!D5)-('Water Reading'!R6-'Water Reading'!R5)-('Water Reading'!Q6-'Water Reading'!Q5) -> 141 | H6: =G6/C6 -> 0.8757764 | I6: ='Water Reading'!P6-'Water Reading'!P5 -> 9 | J6: =I6/C6 -> 0.055900621 | K6: =('Water Reading'!I6-'Water Reading'!I5)-('Water Reading'!P6-'Water Reading'!P5) -> 7 | L6: =K6/C6 -> 0.043478261 | M6: ='Water Reading'!R6-'Water Reading'!R5 -> 1 | N6: =M6/C6 -> 0.0062111801 | O6: ='Water Reading'!Q6-'Water Reading'!Q5 -> 2 | P6: =O6/C6 -> 0.01242236 | Q6: ='Water Reading'!F6-'Water Reading'!F5 -> 1 | R6: =Q6/C6 -> 0.0062111801 | S6: ='Water Reading'!E6-'Water Reading'!E5 -> 63 | T6: =S6/C6 -> 0.39130435 | U6: ='Water Reading'!G6-'Water Reading'!G5 -> 21 | V6: =U6/C6 -> 0.13043478 | W6: ='Water Reading'!J6-'Water Reading'!J5 -> 5 | X6: =W6/C6 -> 0.031055901 | Y6: =E6+I6+K6+M6+O6+G6+Q6+S6+U6+W6 -> 250 | Z6: =Y6/B6 -> #DIV/0!
A7: ='Water Reading'!A6 -> 44716 | B7: =TOTAL!I5 -> 0 | C7: =('Water Reading'!B7-'Water Reading'!B6)+('Water Reading'!C7-'Water Reading'!C6) -> 189 | D7: =C7/B7 -> #DIV/0! | E7: ='Water Reading'!H7-'Water Reading'!H6 -> 0 | F7: =E7/C7 -> 0 | G7: =('Water Reading'!D7-'Water Reading'!D6)-('Water Reading'!R7-'Water Reading'!R6)-('Water Reading'!Q7-'Water Reading'!Q6) -> 142 | H7: =G7/C7 -> 0.75132275 | I7: ='Water Reading'!P7-'Water Reading'!P6 -> 15 | J7: =I7/C7 -> 0.079365079 | K7: =('Water Reading'!I7-'Water Reading'!I6)-('Water Reading'!P7-'Water Reading'!P6) -> 24 | L7: =K7/C7 -> 0.12698413 | M7: ='Water Reading'!R7-'Water Reading'!R6 -> 6 | N7: =M7/C7 -> 0.031746032 | O7: ='Water Reading'!Q7-'Water Reading'!Q6 -> 4 | P7: =O7/C7 -> 0.021164021 | Q7: ='Water Reading'!F7-'Water Reading'!F6 -> 1 | R7: =Q7/C7 -> 0.0052910053 | S7: ='Water Reading'!E7-'Water Reading'!E6 -> 61 | T7: =S7/C7 -> 0.32275132 | U7: ='Water Reading'!G7-'Water Reading'!G6 -> 20 | V7: =U7/C7 -> 0.10582011 | W7: ='Water Reading'!J7-'Water Reading'!J6 -> 6 | X7: =W7/C7 -> 0.031746032 | Y7: =E7+I7+K7+M7+O7+G7+Q7+S7+U7+W7 -> 279 | Z7: =Y7/B7 -> #DIV/0!
A8: ='Water Reading'!A7 -> 44717 | B8: =TOTAL!I6 -> 0 | C8: =('Water Reading'!B8-'Water Reading'!B7)+('Water Reading'!C8-'Water Reading'!C7) -> 151 | D8: =C8/B8 -> #DIV/0! | E8: ='Water Reading'!H8-'Water Reading'!H7 -> 1 | F8: =E8/C8 -> 0.0066225166 | G8: =('Water Reading'!D8-'Water Reading'!D7)-('Water Reading'!R8-'Water Reading'!R7)-('Water Reading'!Q8-'Water Reading'!Q7) -> 159 | H8: =G8/C8 -> 1.0529801 | I8: ='Water Reading'!P8-'Water Reading'!P7 -> 5 | J8: =I8/C8 -> 0.033112583 | K8: =('Water Reading'!I8-'Water Reading'!I7)-('Water Reading'!P8-'Water Reading'!P7) -> 18 | L8: =K8/C8 -> 0.1192053 | M8: ='Water Reading'!R8-'Water Reading'!R7 -> 2 | N8: =M8/C8 -> 0.013245033 | O8: ='Water Reading'!Q8-'Water Reading'!Q7 -> 1 | P8: =O8/C8 -> 0.0066225166 | Q8: ='Water Reading'!F8-'Water Reading'!F7 -> 2 | R8: =Q8/C8 -> 0.013245033 | S8: ='Water Reading'!E8-'Water Reading'!E7 -> 78 | T8: =S8/C8 -> 0.51655629 | U8: ='Water Reading'!G8-'Water Reading'!G7 -> 19 | V8: =U8/C8 -> 0.12582781 | W8: ='Water Reading'!J8-'Water Reading'!J7 -> 5 | X8: =W8/C8 -> 0.033112583 | Y8: =E8+I8+K8+M8+O8+G8+Q8+S8+U8+W8 -> 290 | Z8: =Y8/B8 -> #DIV/0!
A9: ='Water Reading'!A8 -> 44718 | B9: =TOTAL!I7 -> 0 | C9: =('Water Reading'!B9-'Water Reading'!B8)+('Water Reading'!C9-'Water Reading'!C8) -> 162 | D9: =C9/B9 -> #DIV/0! | E9: ='Water Reading'!H9-'Water Reading'!H8 -> 0 | F9: =E9/C9 -> 0 | G9: =('Water Reading'!D9-'Water Reading'!D8)-('Water Reading'!R9-'Water Reading'!R8)-('Water Reading'!Q9-'Water Reading'!Q8) -> 152 | H9: =G9/C9 -> 0.9382716 | I9: ='Water Reading'!P9-'Water Reading'!P8 -> 11 | J9: =I9/C9 -> 0.067901235 | K9: =('Water Reading'!I9-'Water Reading'!I8)-('Water Reading'!P9-'Water Reading'!P8) -> 20 | L9: =K9/C9 -> 0.12345679 | M9: ='Water Reading'!R9-'Water Reading'!R8 -> 3 | N9: =M9/C9 -> 0.018518519 | O9: ='Water Reading'!Q9-'Water Reading'!Q8 -> 1 | P9: =O9/C9 -> 0.0061728395 | Q9: ='Water Reading'!F9-'Water Reading'!F8 -> -1 | R9: =Q9/C9 -> -0.0061728395 | S9: ='Water Reading'!E9-'Water Reading'!E8 -> -437 | T9: =S9/C9 -> -2.6975309 | U9: ='Water Reading'!G9-'Water Reading'!G8 -> 21 | V9: =U9/C9 -> 0.12962963 | W9: ='Water Reading'!J9-'Water Reading'!J8 -> 5 | X9: =W9/C9 -> 0.030864198 | Y9: =E9+I9+K9+M9+O9+G9+Q9+S9+U9+W9 -> -225 | Z9: =Y9/B9 -> #DIV/0!
A10: ='Water Reading'!A9 -> 44719 | B10: =TOTAL!I8 -> 0 | C10: =('Water Reading'!B10-'Water Reading'!B9)+('Water Reading'!C10-'Water Reading'!C9) -> 140 | D10: =C10/B10 -> #DIV/0! | E10: ='Water Reading'!H10-'Water Reading'!H9 -> 0 | F10: =E10/C10 -> 0 | G10: =('Water Reading'!D10-'Water Reading'!D9)-('Water Reading'!R10-'Water Reading'!R9)-('Water Reading'!Q10-'Water Reading'!Q9) -> 127 | H10: =G10/C10 -> 0.90714286 | I10: ='Water Reading'!P10-'Water Reading'!P9 -> 16 | J10: =I10/C10 -> 0.11428571 | K10: =('Water Reading'!I10-'Water Reading'!I9)-('Water Reading'!P10-'Water Reading'!P9) -> 23 | L10: =K10/C10 -> 0.16428571 | M10: ='Water Reading'!R10-'Water Reading'!R9 -> 5 | N10: =M10/C10 -> 0.035714286 | O10: ='Water Reading'!Q10-'Water Reading'!Q9 -> 4 | P10: =O10/C10 -> 0.028571429 | Q10: ='Water Reading'!F10-'Water Reading'!F9 -> 1 | R10: =Q10/C10 -> 0.0071428571 | S10: ='Water Reading'!E10-'Water Reading'!E9 -> 562 | T10: =S10/C10 -> 4.0142857 | U10: ='Water Reading'!G10-'Water Reading'!G9 -> 21 | V10: =U10/C10 -> 0.15 | W10: ='Water Reading'!J10-'Water Reading'!J9 -> 5 | X10: =W10/C10 -> 0.035714286 | Y10: =E10+I10+K10+M10+O10+G10+Q10+S10+U10+W10 -> 764 | Z10: =Y10/B10 -> #DIV/0!
A11: ='Water Reading'!A10 -> 44720 | B11: =TOTAL!I9 -> 0 | C11: =('Water Reading'!B11-'Water Reading'!B10)+('Water Reading'!C11-'Water Reading'!C10) -> -230962 | D11: =C11/B11 -> #DIV/0! | E11: ='Water Reading'!H11-'Water Reading'!H10 -> -62099 | F11: =E11/C11 -> 0.26887107 | G11: =('Water Reading'!D11-'Water Reading'!D10)-('Water Reading'!R11-'Water Reading'!R10)-('Water Reading'!Q11-'Water Reading'!Q10) -> -267248 | H11: =G11/C11 -> 1.1571081 | I11: ='Water Reading'!P11-'Water Reading'!P10 -> -31190 | J11: =I11/C11 -> 0.13504386 | K11: =('Water Reading'!I11-'Water Reading'!I10)-('Water Reading'!P11-'Water Reading'!P10) -> -44358 | L11: =K11/C11 -> 0.19205757 | M11: ='Water Reading'!R11-'Water Reading'!R10 -> -215 | N11: =M11/C11 -> 0.00093088906 | O11: ='Water Reading'!Q11-'Water Reading'!Q10 -> -1724 | P11: =O11/C11 -> 0.0074644314 | Q11: ='Water Reading'!F11-'Water Reading'!F10 -> -67188 | R11: =Q11/C11 -> 0.290905 | S11: ='Water Reading'!E11-'Water Reading'!E10 -> -271002 | T11: =S11/C11 -> 1.1733619 | U11: ='Water Reading'!G11-'Water Reading'!G10 -> -119821 | V11: =U11/C11 -> 0.51879097 | W11: ='Water Reading'!J11-'Water Reading'!J10 -> -22856 | X11: =W11/C11 -> 0.098960002 | Y11: =E11+I11+K11+M11+O11+G11+Q11+S11+U11+W11 -> -887701 | Z11: =Y11/B11 -> #DIV/0!
A12: ='Water Reading'!A11 -> 44721 | B12: =TOTAL!I10 -> 0 | C12: =('Water Reading'!B12-'Water Reading'!B11)+('Water Reading'!C12-'Water Reading'!C11) -> 0 | D12: =C12/B12 -> #DIV/0! | E12: ='Water Reading'!H12-'Water Reading'!H11 -> 0 | F12: =E12/C12 -> #DIV/0! | G12: =('Water Reading'!D12-'Water Reading'!D11)-('Water Reading'!R12-'Water Reading'!R11)-('Water Reading'!Q12-'Water Reading'!Q11) -> 0 | H12: =G12/C12 -> #DIV/0! | I12: ='Water Reading'!P12-'Water Reading'!P11 -> 0 | J12: =I12/C12 -> #DIV/0! | K12: =('Water Reading'!I12-'Water Reading'!I11)-('Water Reading'!P12-'Water Reading'!P11) -> 0 | L12: =K12/C12 -> #DIV/0! | M12: ='Water Reading'!R12-'Water Reading'!R11 -> 0 | N12: =M12/C12 -> #DIV/0! | O12: ='Water Reading'!Q12-'Water Reading'!Q11 -> 0 | P12: =O12/C12 -> #DIV/0! | Q12: ='Water Reading'!F12-'Water Reading'!F11 -> 0 | R12: =Q12/C12 -> #DIV/0! | S12: ='Water Reading'!E12-'Water Reading'!E11 -> 0 | T12: =S12/C12 -> #DIV/0! | U12: ='Water Reading'!G12-'Water Reading'!G11 -> 0 | V12: =U12/C12 -> #DIV/0! | W12: ='Water Reading'!J12-'Water Reading'!J11 -> 0 | X12: =W12/C12 -> #DIV/0! | Y12: =E12+I12+K12+M12+O12+G12+Q12+S12+U12+W12 -> 0 | Z12: =Y12/B12 -> #DIV/0!
A13: ='Water Reading'!A12 -> 44722 | B13: =TOTAL!I11 -> 0 | C13: =('Water Reading'!B13-'Water Reading'!B12)+('Water Reading'!C13-'Water Reading'!C12) -> 0 | D13: =C13/B13 -> #DIV/0! | E13: ='Water Reading'!H13-'Water Reading'!H12 -> 0 | F13: =E13/C13 -> #DIV/0! | G13: =('Water Reading'!D13-'Water Reading'!D12)-('Water Reading'!R13-'Water Reading'!R12)-('Water Reading'!Q13-'Water Reading'!Q12) -> 0 | H13: =G13/C13 -> #DIV/0! | I13: ='Water Reading'!P13-'Water Reading'!P12 -> 0 | J13: =I13/C13 -> #DIV/0! | K13: =('Water Reading'!I13-'Water Reading'!I12)-('Water Reading'!P13-'Water Reading'!P12) -> 0 | L13: =K13/C13 -> #DIV/0! | M13: ='Water Reading'!R13-'Water Reading'!R12 -> 0 | N13: =M13/C13 -> #DIV/0! | O13: ='Water Reading'!Q13-'Water Reading'!Q12 -> 0 | P13: =O13/C13 -> #DIV/0! | Q13: ='Water Reading'!F13-'Water Reading'!F12 -> 0 | R13: =Q13/C13 -> #DIV/0! | S13: ='Water Reading'!E13-'Water Reading'!E12 -> 0 | T13: =S13/C13 -> #DIV/0! | U13: ='Water Reading'!G13-'Water Reading'!G12 -> 0 | V13: =U13/C13 -> #DIV/0! | W13: ='Water Reading'!J13-'Water Reading'!J12 -> 0 | X13: =W13/C13 -> #DIV/0! | Y13: =E13+I13+K13+M13+O13+G13+Q13+S13+U13+W13 -> 0 | Z13: =Y13/B13 -> #DIV/0!
A14: ='Water Reading'!A13 -> 44723 | B14: =TOTAL!I12 -> 0 | C14: =('Water Reading'!B14-'Water Reading'!B13)+('Water Reading'!C14-'Water Reading'!C13) -> 0 | D14: =C14/B14 -> #DIV/0! | E14: ='Water Reading'!H14-'Water Reading'!H13 -> 0 | F14: =E14/C14 -> #DIV/0! | G14: =('Water Reading'!D14-'Water Reading'!D13)-('Water Reading'!R14-'Water Reading'!R13)-('Water Reading'!Q14-'Water Reading'!Q13) -> 0 | H14: =G14/C14 -> #DIV/0! | I14: ='Water Reading'!P14-'Water Reading'!P13 -> 0 | J14: =I14/C14 -> #DIV/0! | K14: =('Water Reading'!I14-'Water Reading'!I13)-('Water Reading'!P14-'Water Reading'!P13) -> 0 | L14: =K14/C14 -> #DIV/0! | M14: ='Water Reading'!R14-'Water Reading'!R13 -> 0 | N14: =M14/C14 -> #DIV/0! | O14: ='Water Reading'!Q14-'Water Reading'!Q13 -> 0 | P14: =O14/C14 -> #DIV/0! | Q14: ='Water Reading'!F14-'Water Reading'!F13 -> 0 | R14: =Q14/C14 -> #DIV/0! | S14: ='Water Reading'!E14-'Water Reading'!E13 -> 0 | T14: =S14/C14 -> #DIV/0! | U14: ='Water Reading'!G14-'Water Reading'!G13 -> 0 | V14: =U14/C14 -> #DIV/0! | W14: ='Water Reading'!J14-'Water Reading'!J13 -> 0 | X14: =W14/C14 -> #DIV/0! | Y14: =E14+I14+K14+M14+O14+G14+Q14+S14+U14+W14 -> 0 | Z14: =Y14/B14 -> #DIV/0!
A15: ='Water Reading'!A14 -> 44724 | B15: =TOTAL!I13 -> 0 | C15: =('Water Reading'!B15-'Water Reading'!B14)+('Water Reading'!C15-'Water Reading'!C14) -> 0 | D15: =C15/B15 -> #DIV/0! | E15: ='Water Reading'!H15-'Water Reading'!H14 -> 0 | F15: =E15/C15 -> #DIV/0! | G15: =('Water Reading'!D15-'Water Reading'!D14)-('Water Reading'!R15-'Water Reading'!R14)-('Water Reading'!Q15-'Water Reading'!Q14) -> 0 | H15: =G15/C15 -> #DIV/0! | I15: ='Water Reading'!P15-'Water Reading'!P14 -> 0 | J15: =I15/C15 -> #DIV/0! | K15: =('Water Reading'!I15-'Water Reading'!I14)-('Water Reading'!P15-'Water Reading'!P14) -> 0 | L15: =K15/C15 -> #DIV/0! | M15: ='Water Reading'!R15-'Water Reading'!R14 -> 0 | N15: =M15/C15 -> #DIV/0! | O15: ='Water Reading'!Q15-'Water Reading'!Q14 -> 0 | P15: =O15/C15 -> #DIV/0! | Q15: ='Water Reading'!F15-'Water Reading'!F14 -> 0 | R15: =Q15/C15 -> #DIV/0! | S15: ='Water Reading'!E15-'Water Reading'!E14 -> 0 | T15: =S15/C15 -> #DIV/0! | U15: ='Water Reading'!G15-'Water Reading'!G14 -> 0 | V15: =U15/C15 -> #DIV/0! | W15: ='Water Reading'!J15-'Water Reading'!J14 -> 0 | X15: =W15/C15 -> #DIV/0! | Y15: =E15+I15+K15+M15+O15+G15+Q15+S15+U15+W15 -> 0 | Z15: =Y15/B15 -> #DIV/0!
