Workbook

Sheet TOTAL
A1: Site Name | B1: Day | C1: Month | D1: Year | E1: Total Electricity Kwh | F1: Electricity Tariff ($/Kwh) | G1: LPG (Kg) | H1: LPG $/Kg | I1: Water Utility Supply (m3) m3 | J1: Water Utility Supply (m3) $/m3 | K1: Irrigation Water (m3) m3 | L1: Irrigation water $/m3 | M1: Room Nights
A2: Seychelles | B2: 1 | C2: 6 | D2: 2022 | E2: ='Submetering '!O2+'Submetering '!P2+'Submetering '!Q2+'Submetering '!R2+'Submetering '!S2+'Submetering '!U2 -> 34905 | F2: =(('FS Seychelles'!R3*'FS Seychelles'!S3)+('FS Seychelles'!T3*'FS Seychelles'!U3))/TOTAL!E2 -> 0.33775677 | G2: =('FS Seychelles'!$AF$10+'FS Seychelles'!$AF$15)/30 -> 0 | H2: 1.05 | I2: ='FS Seychelles'!V3+'FS Seychelles'!X3+'FS Seychelles'!Y3+'FS Seychelles'!Z3 -> 359 | J2: 0 | K2: ='Submetering '!AA2 -> 40 | L2: 0 | M2: ='FS Seychelles'!B3 -> 56.6
A3: Seychelles | B3: =B2+1 -> 2 | C3: 6 | D3: 2022 | E3: ='Submetering '!O3+'Submetering '!P3+'Submetering '!Q3+'Submetering '!R3+'Submetering '!S3+'Submetering '!U3 -> 34551 | F3: =(('FS Seychelles'!R4*'FS Seychelles'!S4)+('FS Seychelles'!T4*'FS Seychelles'!U4))/TOTAL!E3 -> 0.3122 | G3: =('FS Seychelles'!$AF$10+'FS Seychelles'!$AF$15)/30 -> 0 | H3: =H2 -> 1.05 | I3: ='FS Seychelles'!V4+'FS Seychelles'!X4+'FS Seychelles'!Y4+'FS Seychelles'!Z4 -> 424 | J3: =J2 -> 0 | K3: ='Submetering '!AA3 -> 9 | L3: =L2 -> 0 | M3: ='FS Seychelles'!B4 -> 69.7
A4: Seychelles | B4: =B3+1 -> 3 | C4: 6 | D4: 2022 | E4: ='Submetering '!O4+'Submetering '!P4+'Submetering '!Q4+'Submetering '!R4+'Submetering '!S4+'Submetering '!U4 -> 32996 | F4: =(('FS Seychelles'!R5*'FS Seychelles'!S5)+('FS Seychelles'!T5*'FS Seychelles'!U5))/TOTAL!E4 -> 0.34441591 | G4: =('FS Seychelles'!$AF$10+'FS Seychelles'!$AF$15)/30 -> 0 | H4: =H3 -> 1.05 | I4: ='FS Seychelles'!V5+'FS Seychelles'!X5+'FS Seychelles'!Y5+'FS Seychelles'!Z5 -> 436 | J4: =J3 -> 0 | K4: ='Submetering '!AA4 -> 124 | L4: =L3 -> 0 | M4: ='FS Seychelles'!B5 -> 68.4
A5: Seychelles | B5: =B4+1 -> 4 | C5: 6 | D5: 2022 | E5: ='Submetering '!O5+'Submetering '!P5+'Submetering '!Q5+'Submetering '!R5+'Submetering '!S5+'Submetering '!U5 -> 32944 | F5: =(('FS Seychelles'!R6*'FS Seychelles'!S6)+('FS Seychelles'!T6*'FS Seychelles'!U6))/TOTAL!E5 -> 0.31372498 | G5: =('FS Seychelles'!$AF$10+'FS Seychelles'!$AF$15)/30 -> 0 | H5: =H4 -> 1.05 | I5: ='FS Seychelles'!V6+'FS Seychelles'!X6+'FS Seychelles'!Y6+'FS Seychelles'!Z6 -> 428 | J5: =J4 -> 0 | K5: ='Submetering '!AA5 -> 108.8 | L5: =L4 -> 0 | M5: ='FS Seychelles'!B6 -> 63.2
A6: Seychelles | B6: =B5+1 -> 5 | C6: 6 | D6: 2022 | E6: ='Submetering '!O6+'Submetering '!P6+'Submetering '!Q6+'Submetering '!R6+'Submetering '!S6+'Submetering '!U6 -> 35661 | F6: =(('FS Seychelles'!R7*'FS Seychelles'!S7)+('FS Seychelles'!T7*'FS Seychelles'!U7))/TOTAL!E6 -> 0.33117273 | G6: =('FS Seychelles'!$AF$10+'FS Seychelles'!$AF$15)/30 -> 0 | H6: =H5 -> 1.05 | I6: ='FS Seychelles'!V7+'FS Seychelles'!X7+'FS Seychelles'!Y7+'FS Seychelles'!Z7 -> 481 | J6: =J5 -> 0 | K6: ='Submetering '!AA6 -> 112 | L6: =L5 -> 0 | M6: ='FS Seychelles'!B7 -> 69.7
A7: Seychelles | B7: =B6+1 -> 6 | C7: 6 | D7: 2022 | E7: ='Submetering '!O7+'Submetering '!P7+'Submetering '!Q7+'Submetering '!R7+'Submetering '!S7+'Submetering '!U7 -> 32497 | F7: =(('FS Seychelles'!R8*'FS Seychelles'!S8)+('FS Seychelles'!T8*'FS Seychelles'!U8))/TOTAL!E7 -> 0.31894242 | G7: =('FS Seychelles'!$AF$10+'FS Seychelles'!$AF$15)/30 -> 0 | H7: =H6 -> 1.05 | I7: ='FS Seychelles'!V8+'FS Seychelles'!X8+'FS Seychelles'!Y8+'FS Seychelles'!Z8 -> 446 | J7: =J6 -> 0 | K7: ='Submetering '!AA7 -> 109 | L7: =L6 -> 0 | M7: ='FS Seychelles'!B8 -> 61.8
A8: Seychelles | B8: =B7+1 -> 7 | C8: 6 | D8: 2022 | E8: ='Submetering '!O8+'Submetering '!P8+'Submetering '!Q8+'Submetering '!R8+'Submetering '!S8+'Submetering '!U8 -> 37469 | F8: =(('FS Seychelles'!R9*'FS Seychelles'!S9)+('FS Seychelles'!T9*'FS Seychelles'!U9))/TOTAL!E8 -> 0.32462058 | G8: =('FS Seychelles'!$AF$10+'FS Seychelles'!$AF$15)/30 -> 0 | H8: =H7 -> 1.05 | I8: ='FS Seychelles'!V9+'FS Seychelles'!X9+'FS Seychelles'!Y9+'FS Seychelles'!Z9 -> 487 | J8: =J7 -> 0 | K8: ='Submetering '!AA8 -> 112 | L8: =L7 -> 0 | M8: ='FS Seychelles'!B9 -> 57.9
A9: Seychelles | B9: =B8+1 -> 8 | C9: 6 | D9: 2022 | E9: ='Submetering '!O9+'Submetering '!P9+'Submetering '!Q9+'Submetering '!R9+'Submetering '!S9+'Submetering '!U9 -> 42031 | F9: =(('FS Seychelles'!R10*'FS Seychelles'!S10)+('FS Seychelles'!T10*'FS Seychelles'!U10))/TOTAL!E9 -> 0.29712869 | G9: =('FS Seychelles'!$AF$10+'FS Seychelles'!$AF$15)/30 -> 0 | H9: =H8 -> 1.05 | I9: ='FS Seychelles'!V10+'FS Seychelles'!X10+'FS Seychelles'!Y10+'FS Seychelles'!Z10 -> 392 | J9: =J8 -> 0 | K9: ='Submetering '!AA9 -> 107 | L9: =L8 -> 0 | M9: ='FS Seychelles'!B10 -> 56.6
A10: Seychelles | B10: =B9+1 -> 9 | C10: 6 | D10: 2022 | E10: ='Submetering '!O10+'Submetering '!P10+'Submetering '!Q10+'Submetering '!R10+'Submetering '!S10+'Submetering '!U10 -> 36989 | F10: =(('FS Seychelles'!R11*'FS Seychelles'!S11)+('FS Seychelles'!T11*'FS Seychelles'!U11))/TOTAL!E10 -> 0.3351736 | G10: =('FS Seychelles'!$AF$10+'FS Seychelles'!$AF$15)/30 -> 0 | H10: =H9 -> 1.05 | I10: ='FS Seychelles'!V11+'FS Seychelles'!X11+'FS Seychelles'!Y11+'FS Seychelles'!Z11 -> 468 | J10: =J9 -> 0 | K10: ='Submetering '!AA10 -> 108 | L10: =L9 -> 0 | M10: ='FS Seychelles'!B11 -> 56.6
A11: Seychelles | B11: =B10+1 -> 10 | C11: 6 | D11: 2022 | E11: ='Submetering '!O11+'Submetering '!P11+'Submetering '!Q11+'Submetering '!R11+'Submetering '!S11+'Submetering '!U11 -> 26452 | F11: =(('FS Seychelles'!R12*'FS Seychelles'!S12)+('FS Seychelles'!T12*'FS Seychelles'!U12))/TOTAL!E11 -> 0.30499634 | G11: =('FS Seychelles'!$AF$10+'FS Seychelles'!$AF$15)/30 -> 0 | H11: =H10 -> 1.05 | I11: ='FS Seychelles'!V12+'FS Seychelles'!X12+'FS Seychelles'!Y12+'FS Seychelles'!Z12 -> 397 | J11: =J10 -> 0 | K11: ='Submetering '!AA11 -> 110 | L11: =L10 -> 0 | M11: ='FS Seychelles'!B12 -> 48.9
A12: Seychelles | B12: =B11+1 -> 11 | C12: 6 | D12: 2022 | E12: ='Submetering '!O12+'Submetering '!P12+'Submetering '!Q12+'Submetering '!R12+'Submetering '!S12+'Submetering '!U12 -> 31948 | F12: =(('FS Seychelles'!R13*'FS Seychelles'!S13)+('FS Seychelles'!T13*'FS Seychelles'!U13))/TOTAL!E12 -> 0.389161 | G12: =('FS Seychelles'!$AF$10+'FS Seychelles'!$AF$15)/30 -> 0 | H12: =H11 -> 1.05 | I12: ='FS Seychelles'!V13+'FS Seychelles'!X13+'FS Seychelles'!Y13+'FS Seychelles'!Z13 -> 350 | J12: =J11 -> 0 | K12: ='Submetering '!AA12 -> 108 | L12: =L11 -> 0 | M12: ='FS Seychelles'!B13 -> 51.3
A13: Seychelles | B13: =B12+1 -> 12 | C13: 6 | D13: 2022 | E13: ='Submetering '!O13+'Submetering '!P13+'Submetering '!Q13+'Submetering '!R13+'Submetering '!S13+'Submetering '!U13 -> 27725 | F13: =(('FS Seychelles'!R14*'FS Seychelles'!S14)+('FS Seychelles'!T14*'FS Seychelles'!U14))/TOTAL!E13 -> 0.32911109 | G13: =('FS Seychelles'!$AF$10+'FS Seychelles'!$AF$15)/30 -> 0 | H13: =H12 -> 1.05 | I13: ='FS Seychelles'!V14+'FS Seychelles'!X14+'FS Seychelles'!Y14+'FS Seychelles'!Z14 -> 428 | J13: =J12 -> 0 | K13: ='Submetering '!AA13 -> 106 | L13: =L12 -> 0 | M13: ='FS Seychelles'!B14 -> 57.9
A14: Seychelles | B14: =B13+1 -> 13 | C14: 6 | D14: 2022 | E14: ='Submetering '!O14+'Submetering '!P14+'Submetering '!Q14+'Submetering '!R14+'Submetering '!S14+'Submetering '!U14 -> 29046 | F14: =(('FS Seychelles'!R15*'FS Seychelles'!S15)+('FS Seychelles'!T15*'FS Seychelles'!U15))/TOTAL!E14 -> 0.3262548 | G14: =('FS Seychelles'!$AF$10+'FS Seychelles'!$AF$15)/30 -> 0 | H14: =H13 -> 1.05 | I14: ='FS Seychelles'!V15+'FS Seychelles'!X15+'FS Seychelles'!Y15+'FS Seychelles'!Z15 -> 368 | J14: =J13 -> 0 | K14: ='Submetering '!AA14 -> 107 | L14: =L13 -> 0 | M14: ='FS Seychelles'!B15 -> 61.8
... A31: Seychelles | B31: =B30+1 -> 30 | C31: 6 | D31: 2022 | E31: ='Submetering '!O31+'Submetering '!P31+'Submetering '!Q31+'Submetering '!R31+'Submetering '!S31+'Submetering '!U31 -> 0 | F31: =(('FS Seychelles'!R32*'FS Seychelles'!S32)+('FS Seychelles'!T32*'FS Seychelles'!U32))/TOTAL!E31 -> #DIV/0! | G31: =('FS Seychelles'!$AF$10+'FS Seychelles'!$AF$15)/30 -> 0 | H31: =H30 -> 1.05 | I31: ='FS Seychelles'!V32+'FS Seychelles'!X32+'FS Seychelles'!Y32+'FS Seychelles'!Z32 -> 0 | J31: =J30 -> 0 | K31: ='Submetering '!AA31 -> 0 | L31: =L30 -> 0 | M31: ='FS Seychelles'!B32 -> 0
A32: Seychelles | D32: 2022 | E32: ='Submetering '!O32+'Submetering '!P32+'Submetering '!Q32+'Submetering '!R32+'Submetering '!S32+'Submetering '!U32 -> 0 | F32: =(('FS Seychelles'!R33*'FS Seychelles'!S33)+('FS Seychelles'!T33*'FS Seychelles'!U33))/TOTAL!E32 -> #DIV/0! | G32: =('FS Seychelles'!$AF$10+'FS Seychelles'!$AF$15)/30 -> 0 | H32: =H31 -> 1.05 | I32: ='FS Seychelles'!V33+'FS Seychelles'!X33+'FS Seychelles'!Y33+'FS Seychelles'!Z33 -> 0 | J32: =J31 -> 0 | K32: ='Submetering '!AA32 -> 0 | L32: =L31 -> 0 | M32: ='FS Seychelles'!B33 -> 0

Sheet Submetering 
A1: Site Name | B1: Day | C1: Month | D1: Year | E1: Room Night | F1: SS-A - KWh | G1: SS-B- KWh | H1: SS-C- KWh | I1: SS-D1- KWh | J1: SS-D2- KWh | K1: SS-E- KWh | L1: FIRE PUMP- KWh | M1: CASINO- KWh | N1: BOH- KWh | O1: Generator#1 - KWh | P1: Generator#2- KWh | Q1: Generator#3- KWh | R1: Generator#4- KWh | S1: Generator#5- KWh | T1: DIESEL - Liter | U1: PUC - KWh | V1: BOH Water- m3 | W1: E-Resort- m3 | X1: North RVs- m3 | Y1: WT59- m3 | Z1: WT08- m3 | AA1: PUC (HOH)- m3 | AB1: PUC (Resort) - m3 | AC1: LPG (Kg)
A2: Seychelles | B2: 1 | C2: 6 | D2: 2022 | E2: ='FS Seychelles'!B3 -> 56.6 | F2: ='FS Seychelles'!D3*1000 -> 0 | G2: ='FS Seychelles'!E3*1000 -> 0 | H2: ='FS Seychelles'!F3*1000 -> 0 | I2: ='FS Seychelles'!G3*1000 -> 0 | J2: ='FS Seychelles'!H3*1000 -> 0 | K2: ='FS Seychelles'!I3*1000 -> 0 | L2: ='FS Seychelles'!J3*1000 -> 0 | M2: ='FS Seychelles'!K3*1000 -> 0 | N2: ='FS Seychelles'!L3*1000 -> 0 | O2: ='FS Seychelles'!M3 -> 9633 | P2: ='FS Seychelles'!N3 -> 9544 | Q2: ='FS Seychelles'!O3 -> 3482 | R2: ='FS Seychelles'!P3 -> 6719 | S2: ='FS Seychelles'!Q3 -> 5527 | T2: ='FS Seychelles'!R3 -> 8020 | U2: ='FS Seychelles'!T3 -> 0 | V2: ='FS Seychelles'!V3 -> 55 | W2: ='FS Seychelles'!W3 -> 29 | X2: ='FS Seychelles'!X3 -> 62 | Y2: ='FS Seychelles'!Y3 -> 164 | Z2: ='FS Seychelles'!Z3 -> 78 | AA2: ='FS Seychelles'!AA3 -> 40 | AB2: ='FS Seychelles'!AB3 -> 108 | AC2: =('FS Seychelles'!AF9+'FS Seychelles'!AF15)/30 -> 0
A3: Seychelles | B3: =B2+1 -> 2 | C3: =C2 -> 6 | D3: 2022 | E3: ='FS Seychelles'!B4 -> 69.7 | F3: ='FS Seychelles'!D4*1000 -> 0 | G3: ='FS Seychelles'!E4*1000 -> 0 | H3: ='FS Seychelles'!F4*1000 -> 0 | I3: ='FS Seychelles'!G4*1000 -> 0 | J3: ='FS Seychelles'!H4*1000 -> 0 | K3: ='FS Seychelles'!I4*1000 -> 0 | L3: ='FS Seychelles'!J4*1000 -> 0 | M3: ='FS Seychelles'!K4*1000 -> 0 | N3: ='FS Seychelles'!L4*1000 -> 0 | O3: ='FS Seychelles'!M4 -> 11405 | P3: ='FS Seychelles'!N4 -> 6563 | Q3: ='FS Seychelles'!O4 -> 6876 | R3: ='FS Seychelles'!P4 -> 1053 | S3: ='FS Seychelles'!Q4 -> 8654 | T3: ='FS Seychelles'!R4 -> 7359 | U3: ='FS Seychelles'!T4 -> 0 | V3: ='FS Seychelles'!V4 -> 67 | W3: ='FS Seychelles'!W4 -> 20 | X3: ='FS Seychelles'!X4 -> 68 | Y3: ='FS Seychelles'!Y4 -> 192 | Z3: ='FS Seychelles'!Z4 -> 97 | AA3: ='FS Seychelles'!AA4 -> 9 | AB3: ='FS Seychelles'!AB4 -> 0 | AC3: =('FS Seychelles'!AF10+'FS Seychelles'!AF16)/30 -> 0
A4: Seychelles | B4: =B3+1 -> 3 | C4: =C3 -> 6 | D4: 2022 | E4: ='FS Seychelles'!B5 -> 68.4 | F4: ='FS Seychelles'!D5*1000 -> 0 | G4: ='FS Seychelles'!E5*1000 -> 0 | H4: ='FS Seychelles'!F5*1000 -> 0 | I4: ='FS Seychelles'!G5*1000 -> 0 | J4: ='FS Seychelles'!H5*1000 -> 0 | K4: ='FS Seychelles'!I5*1000 -> 0 | L4: ='FS Seychelles'!J5*1000 -> 0 | M4: ='FS Seychelles'!K5*1000 -> 0 | N4: ='FS Seychelles'!L5*1000 -> 0 | O4: ='FS Seychelles'!M5 -> 10001 | P4: ='FS Seychelles'!N5 -> 8150 | Q4: ='FS Seychelles'!O5 -> 0 | R4: ='FS Seychelles'!P5 -> 7890 | S4: ='FS Seychelles'!Q5 -> 6955 | T4: ='FS Seychelles'!R5 -> 7753 | U4: ='FS Seychelles'!T5 -> 0 | V4: ='FS Seychelles'!V5 -> 69 | W4: ='FS Seychelles'!W5 -> 38 | X4: ='FS Seychelles'!X5 -> 88 | Y4: ='FS Seychelles'!Y5 -> 200 | Z4: ='FS Seychelles'!Z5 -> 79 | AA4: ='FS Seychelles'!AA5 -> 124 | AB4: ='FS Seychelles'!AB5 -> 0 | AC4: =('FS Seychelles'!AF11+'FS Seychelles'!AF17)/30 -> 0
A5: Seychelles | B5: =B4+1 -> 4 | C5: =C4 -> 6 | D5: 2022 | E5: ='FS Seychelles'!B6 -> 63.2 | F5: ='FS Seychelles'!D6*1000 -> 0 | G5: ='FS Seychelles'!E6*1000 -> 0 | H5: ='FS Seychelles'!F6*1000 -> 0 | I5: ='FS Seychelles'!G6*1000 -> 0 | J5: ='FS Seychelles'!H6*1000 -> 0 | K5: ='FS Seychelles'!I6*1000 -> 0 | L5: ='FS Seychelles'!J6*1000 -> 0 | M5: ='FS Seychelles'!K6*1000 -> 0 | N5: ='FS Seychelles'!L6*1000 -> 0 | O5: ='FS Seychelles'!M6 -> 6980 | P5: ='FS Seychelles'!N6 -> 8315 | Q5: ='FS Seychelles'!O6 -> 8325 | R5: ='FS Seychelles'!P6 -> 2311 | S5: ='FS Seychelles'!Q6 -> 7013 | T5: ='FS Seychelles'!R6 -> 7051 | U5: ='FS Seychelles'!T6 -> 0 | V5: ='FS Seychelles'!V6 -> 64.3 | W5: ='FS Seychelles'!W6 -> 26.8 | X5: ='FS Seychelles'!X6 -> 73 | Y5: ='FS Seychelles'!Y6 -> 194.7 | Z5: ='FS Seychelles'!Z6 -> 96 | AA5: ='FS Seychelles'!AA6 -> 108.8 | AB5: ='FS Seychelles'!AB6 -> 0 | AC5: =('FS Seychelles'!AF12+'FS Seychelles'!AF18)/30 -> 0
A6: Seychelles | B6: =B5+1 -> 5 | C6: =C5 -> 6 | D6: 2022 | E6: ='FS Seychelles'!B7 -> 69.7 | F6: ='FS Seychelles'!D7*1000 -> 0 | G6: ='FS Seychelles'!E7*1000 -> 0 | H6: ='FS Seychelles'!F7*1000 -> 0 | I6: ='FS Seychelles'!G7*1000 -> 0 | J6: ='FS Seychelles'!H7*1000 -> 0 | K6: ='FS Seychelles'!I7*1000 -> 0 | L6: ='FS Seychelles'!J7*1000 -> 0 | M6: ='FS Seychelles'!K7*1000 -> 0 | N6: ='FS Seychelles'!L7*1000 -> 0 | O6: ='FS Seychelles'!M7 -> 10452 | P6: ='FS Seychelles'!N7 -> 3279 | Q6: ='FS Seychelles'!O7 -> 9168 | R6: ='FS Seychelles'!P7 -> 5313 | S6: ='FS Seychelles'!Q7 -> 7449 | T6: ='FS Seychelles'!R7 -> 8057 | U6: ='FS Seychelles'!T7 -> 0 | V6: ='FS Seychelles'!V7 -> 69 | W6: ='FS Seychelles'!W7 -> 24 | X6: ='FS Seychelles'!X7 -> 96 | Y6: ='FS Seychelles'!Y7 -> 212 | Z6: ='FS Seychelles'!Z7 -> 104 | AA6: ='FS Seychelles'!AA7 -> 112 | AB6: ='FS Seychelles'!AB7 -> 0 | AC6: =('FS Seychelles'!AF13+'FS Seychelles'!AF19)/30 -> 0
A7: Seychelles | B7: =B6+1 -> 6 | C7: =C6 -> 6 | D7: 2022 | E7: ='FS Seychelles'!B8 -> 61.8 | F7: ='FS Seychelles'!D8*1000 -> 0 | G7: ='FS Seychelles'!E8*1000 -> 0 | H7: ='FS Seychelles'!F8*1000 -> 0 | I7: ='FS Seychelles'!G8*1000 -> 0 | J7: ='FS Seychelles'!H8*1000 -> 0 | K7: ='FS Seychelles'!I8*1000 -> 0 | L7: ='FS Seychelles'!J8*1000 -> 0 | M7: ='FS Seychelles'!K8*1000 -> 0 | N7: ='FS Seychelles'!L8*1000 -> 0 | O7: ='FS Seychelles'!M8 -> 7566 | P7: ='FS Seychelles'!N8 -> 8328 | Q7: ='FS Seychelles'!O8 -> 8100 | R7: ='FS Seychelles'!P8 -> 1014 | S7: ='FS Seychelles'!Q8 -> 7489 | T7: ='FS Seychelles'!R8 -> 7071 | U7: ='FS Seychelles'!T8 -> 0 | V7: ='FS Seychelles'!V8 -> 61 | W7: ='FS Seychelles'!W8 -> 30 | X7: ='FS Seychelles'!X8 -> 65 | Y7: ='FS Seychelles'!Y8 -> 234 | Z7: ='FS Seychelles'!Z8 -> 86 | AA7: ='FS Seychelles'!AA8 -> 109 | AB7: ='FS Seychelles'!AB8 -> 0 | AC7: =('FS Seychelles'!AF14+'FS Seychelles'!AF20)/30 -> 0
A8: Seychelles | B8: =B7+1 -> 7 | C8: =C7 -> 6 | D8: 2022 | E8: ='FS Seychelles'!B9 -> 57.9 | F8: ='FS Seychelles'!D9*1000 -> 0 | G8: ='FS Seychelles'!E9*1000 -> 0 | H8: ='FS Seychelles'!F9*1000 -> 0 | I8: ='FS Seychelles'!G9*1000 -> 0 | J8: ='FS Seychelles'!H9*1000 -> 0 | K8: ='FS Seychelles'!I9*1000 -> 0 | L8: ='FS Seychelles'!J9*1000 -> 0 | M8: ='FS Seychelles'!K9*1000 -> 0 | N8: ='FS Seychelles'!L9*1000 -> 0 | O8: ='FS Seychelles'!M9 -> 8753 | P8: ='FS Seychelles'!N9 -> 8407 | Q8: ='FS Seychelles'!O9 -> 8082 | R8: ='FS Seychelles'!P9 -> 3863 | S8: ='FS Seychelles'!Q9 -> 8364 | T8: ='FS Seychelles'!R9 -> 8298 | U8: ='FS Seychelles'!T9 -> 0 | V8: ='FS Seychelles'!V9 -> 71 | W8: ='FS Seychelles'!W9 -> 26 | X8: ='FS Seychelles'!X9 -> 73 | Y8: ='FS Seychelles'!Y9 -> 253 | Z8: ='FS Seychelles'!Z9 -> 90 | AA8: ='FS Seychelles'!AA9 -> 112 | AB8: ='FS Seychelles'!AB9 -> 0 | AC8: =('FS Seychelles'!AF15+'FS Seychelles'!AF21)/30 -> 0
A9: Seychelles | B9: =B8+1 -> 8 | C9: =C8 -> 6 | D9: 2022 | E9: ='FS Seychelles'!B10 -> 56.6 | F9: ='FS Seychelles'!D10*1000 -> 0 | G9: ='FS Seychelles'!E10*1000 -> 0 | H9: ='FS Seychelles'!F10*1000 -> 0 | I9: ='FS Seychelles'!G10*1000 -> 0 | J9: ='FS Seychelles'!H10*1000 -> 0 | K9: ='FS Seychelles'!I10*1000 -> 0 | L9: ='FS Seychelles'!J10*1000 -> 0 | M9: ='FS Seychelles'!K10*1000 -> 0 | N9: ='FS Seychelles'!L10*1000 -> 0 | O9: ='FS Seychelles'!M10 -> 6127 | P9: ='FS Seychelles'!N10 -> 12474 | Q9: ='FS Seychelles'!O10 -> 0 | R9: ='FS Seychelles'!P10 -> 13684 | S9: ='FS Seychelles'!Q10 -> 9746 | T9: ='FS Seychelles'!R10 -> 8520 | U9: ='FS Seychelles'!T10 -> 0 | V9: ='FS Seychelles'!V10 -> 66 | W9: ='FS Seychelles'!W10 -> 38 | X9: ='FS Seychelles'!X10 -> 78 | Y9: ='FS Seychelles'!Y10 -> 163 | Z9: ='FS Seychelles'!Z10 -> 85 | AA9: ='FS Seychelles'!AA10 -> 107 | AB9: ='FS Seychelles'!AB10 -> 0 | AC9: =('FS Seychelles'!AF16+'FS Seychelles'!AF22)/30 -> 0
A10: Seychelles | B10: =B9+1 -> 9 | C10: =C9 -> 6 | D10: 2022 | E10: ='FS Seychelles'!B11 -> 56.6 | F10: ='FS Seychelles'!D11*1000 -> 0 | G10: ='FS Seychelles'!E11*1000 -> 0 | H10: ='FS Seychelles'!F11*1000 -> 0 | I10: ='FS Seychelles'!G11*1000 -> 0 | J10: ='FS Seychelles'!H11*1000 -> 0 | K10: ='FS Seychelles'!I11*1000 -> 0 | L10: ='FS Seychelles'!J11*1000 -> 0 | M10: ='FS Seychelles'!K11*1000 -> 0 | N10: ='FS Seychelles'!L11*1000 -> 0 | O10: ='FS Seychelles'!M11 -> 13506 | P10: ='FS Seychelles'!N11 -> 9804 | Q10: ='FS Seychelles'!O11 -> 5455 | R10: ='FS Seychelles'!P11 -> 8224 | S10: ='FS Seychelles'!Q11 -> 0 | T10: ='FS Seychelles'!R11 -> 8458 | U10: ='FS Seychelles'!T11 -> 0 | V10: ='FS Seychelles'!V11 -> 59 | W10: ='FS Seychelles'!W11 -> 26 | X10: ='FS Seychelles'!X11 -> 98 | Y10: ='FS Seychelles'!Y11 -> 227 | Z10: ='FS Seychelles'!Z11 -> 84 | AA10: ='FS Seychelles'!AA11 -> 108 | AB10: ='FS Seychelles'!AB11 -> 0 | AC10: =('FS Seychelles'!AF17+'FS Seychelles'!AF23)/30 -> 0
A11: Seychelles | B11: =B10+1 -> 10 | C11: =C10 -> 6 | D11: 2022 | E11: ='FS Seychelles'!B12 -> 48.9 | F11: ='FS Seychelles'!D12*1000 -> 0 | G11: ='FS Seychelles'!E12*1000 -> 0 | H11: ='FS Seychelles'!F12*1000 -> 0 | I11: ='FS Seychelles'!G12*1000 -> 0 | J11: ='FS Seychelles'!H12*1000 -> 0 | K11: ='FS Seychelles'!I12*1000 -> 0 | L11: ='FS Seychelles'!J12*1000 -> 0 | M11: ='FS Seychelles'!K12*1000 -> 0 | N11: ='FS Seychelles'!L12*1000 -> 0 | O11: ='FS Seychelles'!M12 -> 10688 | P11: ='FS Seychelles'!N12 -> 4617 | Q11: ='FS Seychelles'!O12 -> 5338 | R11: ='FS Seychelles'!P12 -> 0 | S11: ='FS Seychelles'!Q12 -> 5809 | T11: ='FS Seychelles'!R12 -> 5504 | U11: ='FS Seychelles'!T12 -> 0 | V11: ='FS Seychelles'!V12 -> 64 | W11: ='FS Seychelles'!W12 -> 18 | X11: ='FS Seychelles'!X12 -> 62 | Y11: ='FS Seychelles'!Y12 -> 152 | Z11: ='FS Seychelles'!Z12 -> 119 | AA11: ='FS Seychelles'!AA12 -> 110 | AB11: ='FS Seychelles'!AB12 -> 0 | AC11: =('FS Seychelles'!AF18+'FS Seychelles'!AF24)/30 -> 0
A12: Seychelles | B12: =B11+1 -> 11 | C12: =C11 -> 6 | D12: 2022 | E12: ='FS Seychelles'!B13 -> 51.3 | F12: ='FS Seychelles'!D13*1000 -> 0 | G12: ='FS Seychelles'!E13*1000 -> 0 | H12: ='FS Seychelles'!F13*1000 -> 0 | I12: ='FS Seychelles'!G13*1000 -> 0 | J12: ='FS Seychelles'!H13*1000 -> 0 | K12: ='FS Seychelles'!I13*1000 -> 0 | L12: ='FS Seychelles'!J13*1000 -> 0 | M12: ='FS Seychelles'!K13*1000 -> 0 | N12: ='FS Seychelles'!L13*1000 -> 0 | O12: ='FS Seychelles'!M13 -> 8950 | P12: ='FS Seychelles'!N13 -> 6070 | Q12: ='FS Seychelles'!O13 -> 8033 | R12: ='FS Seychelles'!P13 -> 0 | S12: ='FS Seychelles'!Q13 -> 8895 | T12: ='FS Seychelles'!R13 -> 8482 | U12: ='FS Seychelles'!T13 -> 0 | V12: ='FS Seychelles'!V13 -> 60 | W12: ='FS Seychelles'!W13 -> 16 | X12: ='FS Seychelles'!X13 -> 55 | Y12: ='FS Seychelles'!Y13 -> 149 | Z12: ='FS Seychelles'!Z13 -> 86 | AA12: ='FS Seychelles'!AA13 -> 108 | AB12: ='FS Seychelles'!AB13 -> 0 | AC12: =('FS Seychelles'!AF19+'FS Seychelles'!AF25)/30 -> 0
A13: Seychelles | B13: =B12+1 -> 12 | C13: =C12 -> 6 | D13: 2022 | E13: ='FS Seychelles'!B14 -> 57.9 | F13: ='FS Seychelles'!D14*1000 -> 0 | G13: ='FS Seychelles'!E14*1000 -> 0 | H13: ='FS Seychelles'!F14*1000 -> 0 | I13: ='FS Seychelles'!G14*1000 -> 0 | J13: ='FS Seychelles'!H14*1000 -> 0 | K13: ='FS Seychelles'!I14*1000 -> 0 | L13: ='FS Seychelles'!J14*1000 -> 0 | M13: ='FS Seychelles'!K14*1000 -> 0 | N13: ='FS Seychelles'!L14*1000 -> 0 | O13: ='FS Seychelles'!M14 -> 8208 | P13: ='FS Seychelles'!N14 -> 9618 | Q13: ='FS Seychelles'!O14 -> 5450 | R13: ='FS Seychelles'!P14 -> 0 | S13: ='FS Seychelles'!Q14 -> 4449 | T13: ='FS Seychelles'!R14 -> 6225 | U13: ='FS Seychelles'!T14 -> 0 | V13: ='FS Seychelles'!V14 -> 58 | W13: ='FS Seychelles'!W14 -> 31 | X13: ='FS Seychelles'!X14 -> 56 | Y13: ='FS Seychelles'!Y14 -> 205 | Z13: ='FS Seychelles'!Z14 -> 109 | AA13: ='FS Seychelles'!AA14 -> 106 | AB13: ='FS Seychelles'!AB14 -> 0 | AC13: =('FS Seychelles'!AF20+'FS Seychelles'!AF26)/30 -> 0
A14: Seychelles | B14: =B13+1 -> 13 | C14: =C13 -> 6 | D14: 2022 | E14: ='FS Seychelles'!B15 -> 61.8 | F14: ='FS Seychelles'!D15*1000 -> 0 | G14: ='FS Seychelles'!E15*1000 -> 0 | H14: ='FS Seychelles'!F15*1000 -> 0 | I14: ='FS Seychelles'!G15*1000 -> 0 | J14: ='FS Seychelles'!H15*1000 -> 0 | K14: ='FS Seychelles'!I15*1000 -> 0 | L14: ='FS Seychelles'!J15*1000 -> 0 | M14: ='FS Seychelles'!K15*1000 -> 0 | N14: ='FS Seychelles'!L15*1000 -> 0 | O14: ='FS Seychelles'!M15 -> 10082 | P14: ='FS Seychelles'!N15 -> 0 | Q14: ='FS Seychelles'!O15 -> 5338 | R14: ='FS Seychelles'!P15 -> 0 | S14: ='FS Seychelles'!Q15 -> 13626 | T14: ='FS Seychelles'!R15 -> 6465 | U14: ='FS Seychelles'!T15 -> 0 | V14: ='FS Seychelles'!V15 -> 63 | W14: ='FS Seychelles'!W15 -> 26 | X14: ='FS Seychelles'!X15 -> 66 | Y14: ='FS Seychelles'!Y15 -> 147 | Z14: ='FS Seychelles'!Z15 -> 92 | AA14: ='FS Seychelles'!AA15 -> 107 | AB14: ='FS Seychelles'!AB15 -> 0 | AC14: =('FS Seychelles'!AF21+'FS Seychelles'!AF27)/30 -> 0
... A20: Seychelles | B20: =B19+1 -> 19 | C20: =C19 -> 6 | D20: 2022 | E20: ='FS Seychelles'!B21 -> 59.2 | F20: ='FS Seychelles'!D21*1000 -> 0 | G20: ='FS Seychelles'!E21*1000 -> 0 | H20: ='FS Seychelles'!F21*1000 -> 0 | I20: ='FS Seychelles'!G21*1000 -> 0 | J20: ='FS Seychelles'!H21*1000 -> 0 | K20: ='FS Seychelles'!I21*1000 -> 0 | L20: ='FS Seychelles'!J21*1000 -> 0 | M20: ='FS Seychelles'!K21*1000 -> 0 | N20: ='FS Seychelles'!L21*1000 -> 0 | O20: ='FS Seychelles'!M21 -> 0 | P20: ='FS Seychelles'!N21 -> 11636 | Q20: ='FS Seychelles'!O21 -> 5504 | R20: ='FS Seychelles'!P21 -> 3638 | S20: ='FS Seychelles'!Q21 -> 10834 | T20: ='FS Seychelles'!R21 -> 7048 | U20: ='FS Seychelles'!T21 -> 0 | V20: ='FS Seychelles'!V21 -> 53 | W20: ='FS Seychelles'!W21 -> 30 | X20: ='FS Seychelles'!X21 -> 70 | Y20: ='FS Seychelles'!Y21 -> 165 | Z20: ='FS Seychelles'!Z21 -> 98 | AA20: ='FS Seychelles'!AA21 -> 47 | AB20: ='FS Seychelles'!AB21 -> 0 | AC20: =('FS Seychelles'!AF27+'FS Seychelles'!AF33)/30 -> 0
A21: Seychelles | B21: =B20+1 -> 20 | C21: =C20 -> 6 | D21: 2022 | E21: ='FS Seychelles'!B22 -> 63.2 | F21: ='FS Seychelles'!D22*1000 -> 0 | G21: ='FS Seychelles'!E22*1000 -> 0 | H21: ='FS Seychelles'!F22*1000 -> 0 | I21: ='FS Seychelles'!G22*1000 -> 0 | J21: ='FS Seychelles'!H22*1000 -> 0 | K21: ='FS Seychelles'!I22*1000 -> 0 | L21: ='FS Seychelles'!J22*1000 -> 0 | M21: ='FS Seychelles'!K22*1000 -> 0 | N21: ='FS Seychelles'!L22*1000 -> 0 | O21: ='FS Seychelles'!M22 -> 14445 | P21: ='FS Seychelles'!N22 -> 0 | Q21: ='FS Seychelles'!O22 -> 2019 | R21: ='FS Seychelles'!P22 -> 0 | S21: ='FS Seychelles'!Q23 -> 5520 | T21: ='FS Seychelles'!R22 -> 6366 | U21: ='FS Seychelles'!T22 -> 0 | V21: ='FS Seychelles'!V22 -> 57 | W21: ='FS Seychelles'!W22 -> 32 | X21: ='FS Seychelles'!X22 -> 87 | Y21: ='FS Seychelles'!Y22 -> 136 | Z21: ='FS Seychelles'!Z22 -> 86 | AA21: ='FS Seychelles'!AA22 -> 8 | AB21: ='FS Seychelles'!AB22 -> 0 | AC21: =('FS Seychelles'!AF28+'FS Seychelles'!AF34)/30 -> 0
A22: Seychelles | B22: =B21+1 -> 21 | C22: =C21 -> 6 | D22: 2022 | E22: ='FS Seychelles'!B23 -> 61.8 | F22: ='FS Seychelles'!D23*1000 -> 0 | G22: ='FS Seychelles'!E23*1000 -> 0 | H22: ='FS Seychelles'!F23*1000 -> 0 | I22: ='FS Seychelles'!G23*1000 -> 0 | J22: ='FS Seychelles'!H23*1000 -> 0 | K22: ='FS Seychelles'!I23*1000 -> 0 | L22: ='FS Seychelles'!J23*1000 -> 0 | M22: ='FS Seychelles'!K23*1000 -> 0 | N22: ='FS Seychelles'!L23*1000 -> 0 | O22: ='FS Seychelles'!M23 -> 9422 | P22: ='FS Seychelles'!N23 -> 4788 | Q22: ='FS Seychelles'!O23 -> 10314 | R22: ='FS Seychelles'!P23 -> 1537 | S22: ='FS Seychelles'!Q24 -> 0 | T22: ='FS Seychelles'!R23 -> 6909 | U22: ='FS Seychelles'!T23 -> 0 | V22: ='FS Seychelles'!V23 -> 0 | W22: ='FS Seychelles'!W23 -> 0 | X22: ='FS Seychelles'!X23 -> 0 | Y22: ='FS Seychelles'!Y23 -> 0 | Z22: ='FS Seychelles'!Z23 -> 0 | AA22: ='FS Seychelles'!AA23 -> 0 | AB22: ='FS Seychelles'!AB23 -> 0 | AC22: =('FS Seychelles'!AF29+'FS Seychelles'!AF35)/30 -> 0
A23: Seychelles | B23: =B22+1 -> 22 | C23: =C22 -> 6 | D23: 2022 | E23: ='FS Seychelles'!B24 -> 0 | F23: ='FS Seychelles'!D24*1000 -> 0 | G23: ='FS Seychelles'!E24*1000 -> 0 | H23: ='FS Seychelles'!F24*1000 -> 0 | I23: ='FS Seychelles'!G24*1000 -> 0 | J23: ='FS Seychelles'!H24*1000 -> 0 | K23: ='FS Seychelles'!I24*1000 -> 0 | L23: ='FS Seychelles'!J24*1000 -> 0 | M23: ='FS Seychelles'!K24*1000 -> 0 | N23: ='FS Seychelles'!L24*1000 -> 0 | O23: ='FS Seychelles'!M24 -> 0 | P23: ='FS Seychelles'!N24 -> 0 | Q23: ='FS Seychelles'!O24 -> 0 | R23: ='FS Seychelles'!P24 -> 0 | S23: ='FS Seychelles'!Q25 -> 0 | T23: ='FS Seychelles'!R24 -> 0 | U23: ='FS Seychelles'!T24 -> 0 | V23: ='FS Seychelles'!V24 -> 0 | W23: ='FS Seychelles'!W24 -> 0 | X23: ='FS Seychelles'!X24 -> 0 | Y23: ='FS Seychelles'!Y24 -> 0 | Z23: ='FS Seychelles'!Z24 -> 0 | AA23: ='FS Seychelles'!AA24 -> 0 | AB23: ='FS Seychelles'!AB24 -> 0 | AC23: =('FS Seychelles'!AF30+'FS Seychelles'!AF36)/30 -> 0
A24: Seychelles | B24: =B23+1 -> 23 | C24: =C23 -> 6 | D24: 2022 | E24: ='FS Seychelles'!B25 -> 0 | F24: ='FS Seychelles'!D25*1000 -> 0 | G24: ='FS Seychelles'!E25*1000 -> 0 | H24: ='FS Seychelles'!F25*1000 -> 0 | I24: ='FS Seychelles'!G25*1000 -> 0 | J24: ='FS Seychelles'!H25*1000 -> 0 | K24: ='FS Seychelles'!I25*1000 -> 0 | L24: ='FS Seychelles'!J25*1000 -> 0 | M24: ='FS Seychelles'!K25*1000 -> 0 | N24: ='FS Seychelles'!L25*1000 -> 0 | O24: ='FS Seychelles'!M25 -> 0 | P24: ='FS Seychelles'!N25 -> 0 | Q24: ='FS Seychelles'!O25 -> 0 | R24: ='FS Seychelles'!P25 -> 0 | S24: ='FS Seychelles'!Q25 -> 0 | T24: ='FS Seychelles'!R25 -> 0 | U24: ='FS Seychelles'!T25 -> 0 | V24: ='FS Seychelles'!V25 -> 0 | W24: ='FS Seychelles'!W25 -> 0 | X24: ='FS Seychelles'!X25 -> 0 | Y24: ='FS Seychelles'!Y25 -> 0 | Z24: ='FS Seychelles'!Z25 -> 0 | AA24: ='FS Seychelles'!AA25 -> 0 | AB24: ='FS Seychelles'!AB25 -> 0 | AC24: =('FS Seychelles'!AF31+'FS Seychelles'!AF37)/30 -> 0
A25: Seychelles | B25: =B24+1 -> 24 | C25: =C24 -> 6 | D25: 2022 | E25: ='FS Seychelles'!B26 -> 0 | F25: ='FS Seychelles'!D26*1000 -> 0 | G25: ='FS Seychelles'!E26*1000 -> 0 | H25: ='FS Seychelles'!F26*1000 -> 0 | I25: ='FS Seychelles'!G26*1000 -> 0 | J25: ='FS Seychelles'!H26*1000 -> 0 | K25: ='FS Seychelles'!I26*1000 -> 0 | L25: ='FS Seychelles'!J26*1000 -> 0 | M25: ='FS Seychelles'!K26*1000 -> 0 | N25: ='FS Seychelles'!L26*1000 -> 0 | O25: ='FS Seychelles'!M26 -> 0 | P25: ='FS Seychelles'!N26 -> 0 | Q25: ='FS Seychelles'!O26 -> 0 | R25: ='FS Seychelles'!P26 -> 0 | S25: ='FS Seychelles'!Q26 -> 0 | T25: ='FS Seychelles'!R26 -> 0 | U25: ='FS Seychelles'!T26 -> 0 | V25: ='FS Seychelles'!V26 -> 0 | W25: ='FS Seychelles'!W26 -> 0 | X25: ='FS Seychelles'!X26 -> 0 | Y25: ='FS Seychelles'!Y26 -> 0 | Z25: ='FS Seychelles'!Z26 -> 0 | AA25: ='FS Seychelles'!AA26 -> 0 | AB25: ='FS Seychelles'!AB26 -> 0 | AC25: =('FS Seychelles'!AF32+'FS Seychelles'!AF38)/30 -> 0
A26: Seychelles | B26: =B25+1 -> 25 | C26: =C25 -> 6 | D26: 2022 | E26: ='FS Seychelles'!B27 -> 0 | F26: ='FS Seychelles'!D27*1000 -> 0 | G26: ='FS Seychelles'!E27*1000 -> 0 | H26: ='FS Seychelles'!F27*1000 -> 0 | I26: ='FS Seychelles'!G27*1000 -> 0 | J26: ='FS Seychelles'!H27*1000 -> 0 | K26: ='FS Seychelles'!I27*1000 -> 0 | L26: ='FS Seychelles'!J27*1000 -> 0 | M26: ='FS Seychelles'!K27*1000 -> 0 | N26: ='FS Seychelles'!L27*1000 -> 0 | O26: ='FS Seychelles'!M27 -> 0 | P26: ='FS Seychelles'!N27 -> 0 | Q26: ='FS Seychelles'!O27 -> 0 | R26: ='FS Seychelles'!P27 -> 0 | S26: ='FS Seychelles'!Q27 -> 0 | T26: ='FS Seychelles'!R27 -> 0 | U26: ='FS Seychelles'!T27 -> 0 | V26: ='FS Seychelles'!V27 -> 0 | W26: ='FS Seychelles'!W27 -> 0 | X26: ='FS Seychelles'!X27 -> 0 | Y26: ='FS Seychelles'!Y27 -> 0 | Z26: ='FS Seychelles'!Z27 -> 0 | AA26: ='FS Seychelles'!AA27 -> 0 | AB26: ='FS Seychelles'!AB27 -> 0 | AC26: =('FS Seychelles'!AF33+'FS Seychelles'!AF39)/30 -> 0
A27: Seychelles | B27: =B26+1 -> 26 | C27: =C26 -> 6 | D27: 2022 | E27: ='FS Seychelles'!B28 -> 0 | F27: ='FS Seychelles'!D28*1000 -> 0 | G27: ='FS Seychelles'!E28*1000 -> 0 | H27: ='FS Seychelles'!F28*1000 -> 0 | I27: ='FS Seychelles'!G28*1000 -> 0 | J27: ='FS Seychelles'!H28*1000 -> 0 | K27: ='FS Seychelles'!I28*1000 -> 0 | L27: ='FS Seychelles'!J28*1000 -> 0 | M27: ='FS Seychelles'!K28*1000 -> 0 | N27: ='FS Seychelles'!L28*1000 -> 0 | O27: ='FS Seychelles'!M28 -> 0 | P27: ='FS Seychelles'!N28 -> 0 | Q27: ='FS Seychelles'!O28 -> 0 | R27: ='FS Seychelles'!P28 -> 0 | S27: ='FS Seychelles'!Q28 -> 0 | T27: ='FS Seychelles'!R28 -> 0 | U27: ='FS Seychelles'!T28 -> 0 | V27: ='FS Seychelles'!V28 -> 0 | W27: ='FS Seychelles'!W28 -> 0 | X27: ='FS Seychelles'!X28 -> 0 | Y27: ='FS Seychelles'!Y28 -> 0 | Z27: ='FS Seychelles'!Z28 -> 0 | AA27: ='FS Seychelles'!AA28 -> 0 | AB27: ='FS Seychelles'!AB28 -> 0 | AC27: =('FS Seychelles'!AF34+'FS Seychelles'!AF40)/30 -> 0
A28: Seychelles | B28: =B27+1 -> 27 | C28: =C27 -> 6 | D28: 2022 | E28: ='FS Seychelles'!B29 -> 0 | F28: ='FS Seychelles'!D29*1000 -> 0 | G28: ='FS Seychelles'!E29*1000 -> 0 | H28: ='FS Seychelles'!F29*1000 -> 0 | I28: ='FS Seychelles'!G29*1000 -> 0 | J28: ='FS Seychelles'!H29*1000 -> 0 | K28: ='FS Seychelles'!I29*1000 -> 0 | L28: ='FS Seychelles'!J29*1000 -> 0 | M28: ='FS Seychelles'!K29*1000 -> 0 | N28: ='FS Seychelles'!L29*1000 -> 0 | O28: ='FS Seychelles'!M29 -> 0 | P28: ='FS Seychelles'!N29 -> 0 | Q28: ='FS Seychelles'!O29 -> 0 | R28: ='FS Seychelles'!P29 -> 0 | S28: ='FS Seychelles'!Q29 -> 0 | T28: ='FS Seychelles'!R29 -> 0 | U28: ='FS Seychelles'!T29 -> 0 | V28: ='FS Seychelles'!V29 -> 0 | W28: ='FS Seychelles'!W29 -> 0 | X28: ='FS Seychelles'!X29 -> 0 | Y28: ='FS Seychelles'!Y29 -> 0 | Z28: ='FS Seychelles'!Z29 -> 0 | AA28: ='FS Seychelles'!AA29 -> 0 | AB28: ='FS Seychelles'!AB29 -> 0 | AC28: =('FS Seychelles'!AF35+'FS Seychelles'!AF41)/30 -> 0
A29: Seychelles | B29: =B28+1 -> 28 | C29: =C28 -> 6 | D29: 2022 | E29: ='FS Seychelles'!B30 -> 0 | F29: ='FS Seychelles'!D30*1000 -> 0 | G29: ='FS Seychelles'!E30*1000 -> 0 | H29: ='FS Seychelles'!F30*1000 -> 0 | I29: ='FS Seychelles'!G30*1000 -> 0 | J29: ='FS Seychelles'!H30*1000 -> 0 | K29: ='FS Seychelles'!I30*1000 -> 0 | L29: ='FS Seychelles'!J30*1000 -> 0 | M29: ='FS Seychelles'!K30*1000 -> 0 | N29: ='FS Seychelles'!L30*1000 -> 0 | O29: ='FS Seychelles'!M30 -> 0 | P29: ='FS Seychelles'!N30 -> 0 | Q29: ='FS Seychelles'!O30 -> 0 | R29: ='FS Seychelles'!P30 -> 0 | S29: ='FS Seychelles'!Q30 -> 0 | T29: ='FS Seychelles'!R30 -> 0 | U29: ='FS Seychelles'!T30 -> 0 | V29: ='FS Seychelles'!V30 -> 0 | W29: ='FS Seychelles'!W30 -> 0 | X29: ='FS Seychelles'!X30 -> 0 | Y29: ='FS Seychelles'!Y30 -> 0 | Z29: ='FS Seychelles'!Z30 -> 0 | AA29: ='FS Seychelles'!AA30 -> 0 | AB29: ='FS Seychelles'!AB30 -> 0 | AC29: =('FS Seychelles'!AF36+'FS Seychelles'!AF42)/30 -> 0
A30: Seychelles | B30: =B29+1 -> 29 | C30: =C29 -> 6 | D30: 2022 | E30: ='FS Seychelles'!B31 -> 0 | F30: ='FS Seychelles'!D31*1000 -> 0 | G30: ='FS Seychelles'!E31*1000 -> 0 | H30: ='FS Seychelles'!F31*1000 -> 0 | I30: ='FS Seychelles'!G31*1000 -> 0 | J30: ='FS Seychelles'!H31*1000 -> 0 | K30: ='FS Seychelles'!I31*1000 -> 0 | L30: ='FS Seychelles'!J31*1000 -> 0 | M30: ='FS Seychelles'!K31*1000 -> 0 | N30: ='FS Seychelles'!L31*1000 -> 0 | O30: ='FS Seychelles'!M31 -> 0 | P30: ='FS Seychelles'!N31 -> 0 | Q30: ='FS Seychelles'!O31 -> 0 | R30: ='FS Seychelles'!P31 -> 0 | S30: ='FS Seychelles'!Q31 -> 0 | T30: ='FS Seychelles'!R31 -> 0 | U30: ='FS Seychelles'!T31 -> 0 | V30: ='FS Seychelles'!V31 -> 0 | W30: ='FS Seychelles'!W31 -> 0 | X30: ='FS Seychelles'!X31 -> 0 | Y30: ='FS Seychelles'!Y31 -> 0 | Z30: ='FS Seychelles'!Z31 -> 0 | AA30: ='FS Seychelles'!AA31 -> 0 | AB30: ='FS Seychelles'!AB31 -> 0 | AC30: =('FS Seychelles'!AF37+'FS Seychelles'!AF43)/30 -> 0
A31: Seychelles | B31: =B30+1 -> 30 | C31: =C30 -> 6 | D31: 2022 | E31: ='FS Seychelles'!B32 -> 0 | F31: ='FS Seychelles'!D32*1000 -> 0 | G31: ='FS Seychelles'!E32*1000 -> 0 | H31: ='FS Seychelles'!F32*1000 -> 0 | I31: ='FS Seychelles'!G32*1000 -> 0 | J31: ='FS Seychelles'!H32*1000 -> 0 | K31: ='FS Seychelles'!I32*1000 -> 0 | L31: ='FS Seychelles'!J32*1000 -> 0 | M31: ='FS Seychelles'!K32*1000 -> 0 | N31: ='FS Seychelles'!L32*1000 -> 0 | O31: ='FS Seychelles'!M32 -> 0 | P31: ='FS Seychelles'!N32 -> 0 | Q31: ='FS Seychelles'!O32 -> 0 | R31: ='FS Seychelles'!P32 -> 0 | S31: ='FS Seychelles'!Q32 -> 0 | T31: ='FS Seychelles'!R32 -> 0 | U31: ='FS Seychelles'!T32 -> 0 | V31: ='FS Seychelles'!V32 -> 0 | W31: ='FS Seychelles'!W32 -> 0 | X31: ='FS Seychelles'!X32 -> 0 | Y31: ='FS Seychelles'!Y32 -> 0 | Z31: ='FS Seychelles'!Z32 -> 0 | AA31: ='FS Seychelles'!AA32 -> 0 | AB31: ='FS Seychelles'!AB32 -> 0 | AC31: =('FS Seychelles'!AF38+'FS Seychelles'!AF44)/30 -> 0
A32: Seychelles | D32: 2022 | E32: ='FS Seychelles'!B33 -> 0 | F32: ='FS Seychelles'!D33*1000 -> 0 | G32: ='FS Seychelles'!E33*1000 -> 0 | H32: ='FS Seychelles'!F33*1000 -> 0 | I32: ='FS Seychelles'!G33*1000 -> 0 | J32: ='FS Seychelles'!H33*1000 -> 0 | K32: ='FS Seychelles'!I33*1000 -> 0 | L32: ='FS Seychelles'!J33*1000 -> 0 | M32: ='FS Seychelles'!K33*1000 -> 0 | N32: ='FS Seychelles'!L33*1000 -> 0 | O32: ='FS Seychelles'!M33 -> 0 | P32: ='FS Seychelles'!N33 -> 0 | Q32: ='FS Seychelles'!O33 -> 0 | R32: ='FS Seychelles'!P33 -> 0 | S32: ='FS Seychelles'!Q33 -> 0 | T32: ='FS Seychelles'!R33 -> 0 | U32: ='FS Seychelles'!T33 -> 0 | V32: ='FS Seychelles'!V33 -> 0 | W32: ='FS Seychelles'!W33 -> 0 | X32: ='FS Seychelles'!X33 -> 0 | Y32: ='FS Seychelles'!Y33 -> 0 | Z32: ='FS Seychelles'!Z33 -> 0 | AA32: ='FS Seychelles'!AA33 -> 0 | AB32: ='FS Seychelles'!AB33 -> 0 | AC32: =('FS Seychelles'!AF39+'FS Seychelles'!AF45)/30 -> 0
P33: =SUM(P2:P32) -> 137225 | Q33: =SUM(Q2:Q32) -> 103052 | R33: =SUM(R2:R32) -> 70275
R35: =SUM(O33:R33) -> 310552

Sheet FS Seychelles
A2: DATE | B2: Room Night % | C2: Food Covers (Customers) | D2: SS-A (KWH) | E2: SS-B (KWH) | F2: SS-C (KWH) | G2: SS-D1 (KWH) | H2: SS-D2 (KWH) | I2: SS-E (KWH) | J2: FIRE PUMP (KWH) | K2: CASINO (KWH) | L2: BOH (KWH) | M2: Generator#1 (KWH) | N2: Generator#2 (KWH) | O2: Generator#3 (KWH) | P2: Generator#4 (KWH) | Q2: Generator#5 (KWH) | R2: DIESEL (Liter) | S2: DIESEL TARIFF (Euro/Liter) | T2: PUC (KWh) | U2: PUC Tariff (Euro/KWh) | V2: BOH Water (m3) | W2: E-Resort (m3) | X2: North RVs (m3) | Y2: WT59 (m3) | Z2: WT08 (m3) | AA2: PUC HOH (m3) | AB2: PUC Eresort (m3) | AC2: Fire Tank (m3) | AD2: LPG (Kg)
A3: 44682 | B3: 56.6 | C3: 311 | M3: =Generator!E3 -> 9633 | N3: =Generator!L3 -> 9544 | O3: =Generator!S3 -> 3482 | P3: =Generator!Z3 -> 6719 | Q3: =Generator!AG3 -> 5527 | R3: =SUM(Generator!C3,Generator!J3,Generator!Q3,Generator!X3,Generator!AE3) -> 8020 | S3: 1.47 | U3: 0.32 | V3: 55 | W3: 29 | X3: 62 | Y3: 164 | Z3: 78 | AA3: 40 | AB3: 108 | AC3: 0 | AD3: CYLINDER DELIVERY (KG)
A4: 44683 | B4: 69.7 | C4: 332 | M4: =Generator!E4 -> 11405 | N4: =Generator!L4 -> 6563 | O4: =Generator!S4 -> 6876 | P4: =Generator!Z4 -> 1053 | Q4: =Generator!AG4 -> 8654 | R4: =SUM(Generator!C4,Generator!J4,Generator!Q4,Generator!X4,Generator!AE4) -> 7359 | S4: =24.43*0.06 -> 1.4658 | U4: =U3 -> 0.32 | V4: 67 | W4: 20 | X4: 68 | Y4: 192 | Z4: 97 | AA4: 9 | AB4: 0 | AC4: 9 | AD4: Unit (kg) | AE4: Quantity | AF4: Sub total
A5: 44684 | B5: 68.4 | C5: 315 | M5: =Generator!E5 -> 10001 | N5: =Generator!L5 -> 8150 | O5: =Generator!S5 -> 0 | P5: =Generator!Z5 -> 7890 | Q5: =Generator!AG5 -> 6955 | R5: =SUM(Generator!C5,Generator!J5,Generator!Q5,Generator!X5,Generator!AE5) -> 7753 | S5: =24.43*0.06 -> 1.4658 | U5: =U4 -> 0.32 | V5: 69 | W5: 38 | X5: 88 | Y5: 200 | Z5: 79 | AA5: 124 | AB5: 0 | AC5: 0
A6: 44685 | B6: 63.2 | C6: 323 | M6: =Generator!E6 -> 6980 | N6: =Generator!L6 -> 8315 | O6: =Generator!S6 -> 8325 | P6: =Generator!Z6 -> 2311 | Q6: =Generator!AG6 -> 7013 | R6: =SUM(Generator!C6,Generator!J6,Generator!Q6,Generator!X6,Generator!AE6) -> 7051 | S6: =24.43*0.06 -> 1.4658 | U6: =U5 -> 0.32 | V6: =AVERAGE(V7:V16) -> 64.3 | W6: =AVERAGE(W7:W16) -> 26.8 | X6: =AVERAGE(X7:X16) -> 73 | Y6: =AVERAGE(Y7:Y16) -> 194.7 | Z6: =AVERAGE(Z7:Z16) -> 96 | AA6: =AVERAGE(AA7:AA16) -> 108.8 | AB6: =AVERAGE(AB7:AB16) -> 0 | AC6: 0
A7: 44686 | B7: 69.7 | C7: 330 | M7: =Generator!E7 -> 10452 | N7: =Generator!L7 -> 3279 | O7: =Generator!S7 -> 9168 | P7: =Generator!Z7 -> 5313 | Q7: =Generator!AG7 -> 7449 | R7: =SUM(Generator!C7,Generator!J7,Generator!Q7,Generator!X7,Generator!AE7) -> 8057 | S7: =24.43*0.06 -> 1.4658 | U7: =U6 -> 0.32 | V7: 69 | W7: 24 | X7: 96 | Y7: 212 | Z7: 104 | AA7: 112 | AB7: 0 | AC7: 1 | AD7: 20
A8: 44687 | B8: 61.8 | C8: 326 | M8: =Generator!E8 -> 7566 | N8: =Generator!L8 -> 8328 | O8: =Generator!S8 -> 8100 | P8: =Generator!Z8 -> 1014 | Q8: =Generator!AG8 -> 7489 | R8: =SUM(Generator!C8,Generator!J8,Generator!Q8,Generator!X8,Generator!AE8) -> 7071 | S8: =24.43*0.06 -> 1.4658 | U8: =U7 -> 0.32 | V8: 61 | W8: 30 | X8: 65 | Y8: 234 | Z8: 86 | AA8: 109 | AB8: 0 | AC8: 0 | AD8: 24
A9: 44688 | B9: 57.9 | C9: 312 | M9: =Generator!E9 -> 8753 | N9: =Generator!L9 -> 8407 | O9: =Generator!S9 -> 8082 | P9: =Generator!Z9 -> 3863 | Q9: =Generator!AG9 -> 8364 | R9: =SUM(Generator!C9,Generator!J9,Generator!Q9,Generator!X9,Generator!AE9) -> 8298 | S9: =24.43*0.06 -> 1.4658 | U9: =U8 -> 0.32 | V9: 71 | W9: 26 | X9: 73 | Y9: 253 | Z9: 90 | AA9: 112 | AB9: 0 | AC9: 0
A10: 44689 | B10: 56.6 | C10: 298 | M10: =Generator!E10 -> 6127 | N10: =Generator!L10 -> 12474 | O10: =Generator!S10 -> 0 | P10: =Generator!Z10 -> 13684 | Q10: =Generator!AG10 -> 9746 | R10: =SUM(Generator!C10,Generator!J10,Generator!Q10,Generator!X10,Generator!AE10) -> 8520 | S10: =24.43*0.06 -> 1.4658 | U10: =U9 -> 0.32 | V10: 66 | W10: 38 | X10: 78 | Y10: 163 | Z10: 85 | AA10: 107 | AB10: 0 | AC10: 0 | AE10: Total | AF10: =SUM(AF6:AF9) -> 0
A11: 44690 | B11: 56.6 | C11: 284 | M11: =Generator!E11 -> 13506 | N11: =Generator!L11 -> 9804 | O11: =Generator!S11 -> 5455 | P11: =Generator!Z11 -> 8224 | Q11: =Generator!AG11 -> 0 | R11: =SUM(Generator!C11,Generator!J11,Generator!Q11,Generator!X11,Generator!AE11) -> 8458 | S11: =24.43*0.06 -> 1.4658 | U11: =U10 -> 0.32 | V11: 59 | W11: 26 | X11: 98 | Y11: 227 | Z11: 84 | AA11: 108 | AB11: 0 | AC11: 36 | AD11: TRUCK DELIVERY (KG)
A12: 44691 | B12: 48.9 | C12: 172 | M12: =Generator!E12 -> 10688 | N12: =Generator!L12 -> 4617 | O12: =Generator!S12 -> 5338 | P12: =Generator!Z12 -> 0 | Q12: =Generator!AG12 -> 5809 | R12: =SUM(Generator!C12,Generator!J12,Generator!Q12,Generator!X12,Generator!AE12) -> 5504 | S12: =24.43*0.06 -> 1.4658 | U12: =U11 -> 0.32 | V12: 64 | W12: 18 | X12: 62 | Y12: 152 | Z12: 119 | AA12: 110 | AB12: 0 | AC12: 63 | AE12: Sub Total
A13: 44692 | B13: 51.3 | C13: 255 | M13: =Generator!E13 -> 8950 | N13: =Generator!L13 -> 6070 | O13: =Generator!S13 -> 8033 | P13: =Generator!Z13 -> 0 | Q13: =Generator!AG13 -> 8895 | R13: =SUM(Generator!C13,Generator!J13,Generator!Q13,Generator!X13,Generator!AE13) -> 8482 | S13: =24.43*0.06 -> 1.4658 | U13: =U12 -> 0.32 | V13: 60 | W13: 16 | X13: 55 | Y13: 149 | Z13: 86 | AA13: 108 | AB13: 0 | AC13: 72 | AD13: Sitronel
A14: 44693 | B14: 57.9 | C14: 308 | M14: =Generator!E14 -> 8208 | N14: =Generator!L14 -> 9618 | O14: =Generator!S14 -> 5450 | P14: =Generator!Z14 -> 0 | Q14: =Generator!AG14 -> 4449 | R14: =SUM(Generator!C14,Generator!J14,Generator!Q14,Generator!X14,Generator!AE14) -> 6225 | S14: =24.43*0.06 -> 1.4658 | U14: =U13 -> 0.32 | V14: 58 | W14: 31 | X14: 56 | Y14: 205 | Z14: 109 | AA14: 106 | AB14: 0 | AC14: 107 | AD14: Zez
A15: 44694 | B15: 61.8 | C15: 300 | M15: =Generator!E15 -> 10082 | N15: =Generator!L15 -> 0 | O15: =Generator!S15 -> 5338 | P15: =Generator!Z15 -> 0 | Q15: =Generator!AG15 -> 13626 | R15: =SUM(Generator!C15,Generator!J15,Generator!Q15,Generator!X15,Generator!AE15) -> 6465 | S15: =24.43*0.06 -> 1.4658 | U15: =U14 -> 0.32 | V15: 63 | W15: 26 | X15: 66 | Y15: 147 | Z15: 92 | AA15: 107 | AB15: 0 | AC15: 0 | AE15: Total | AF15: =SUM(AE13:AF14) -> 0
A16: 44695 | B16: 67.1 | C16: 361 | M16: =Generator!E16 -> 11200 | N16: =Generator!L16 -> 3279 | O16: =Generator!S16 -> 0 | P16: =Generator!Z16 -> 6093 | Q16: =Generator!AG16 -> 10607 | R16: =SUM(Generator!C16,Generator!J16,Generator!Q16,Generator!X16,Generator!AE16) -> 7104 | S16: =24.43*0.06 -> 1.4658 | U16: =U15 -> 0.32 | V16: 72 | W16: 33 | X16: 81 | Y16: 205 | Z16: 105 | AA16: 109 | AB16: 0 | AC16: 0
A17: 44696 | B17: 57.9 | C17: 326 | M17: =Generator!E17 -> 10504 | N17: =Generator!L17 -> 8248 | O17: =Generator!S17 -> 0 | P17: =Generator!Z17 -> 4612 | Q17: =Generator!AG17 -> 3814 | R17: =SUM(Generator!C17,Generator!J17,Generator!Q17,Generator!X17,Generator!AE17) -> 6266 | S17: =24.43*0.06 -> 1.4658 | U17: =U16 -> 0.32 | V17: 61 | W17: 17 | X17: 89 | Y17: 195 | Z17: 103 | AA17: 116 | AB17: 0 | AC17: 0
A18: 44697 | B18: 48.7 | C18: 263 | M18: =Generator!E18 -> 7129 | N18: =Generator!L18 -> 3999 | O18: =Generator!S18 -> 9274 | P18: =Generator!Z18 -> 0 | Q18: =Generator!AG18 -> 1426 | R18: =SUM(Generator!C18,Generator!J18,Generator!Q18,Generator!X18,Generator!AE18) -> 4721 | S18: =24.43*0.06 -> 1.4658 | U18: =U17 -> 0.32 | V18: 65 | W18: 29 | X18: 77 | Y18: 238 | Z18: 95 | AA18: 106 | AB18: 0 | AC18: 0
A19: 44698 | B19: 63.2 | C19: 307 | M19: =Generator!E19 -> 10477 | N19: =Generator!L19 -> 4980 | O19: =Generator!S19 -> 0 | P19: =Generator!Z19 -> 4324 | Q19: =Generator!AG19 -> 6621 | R19: =SUM(Generator!C19,Generator!J19,Generator!Q19,Generator!X19,Generator!AE19) -> 6278 | S19: =24.43*0.06 -> 1.4658 | U19: =U18 -> 0.32 | V19: 64 | W19: 24 | X19: 61 | Y19: 171 | Z19: 71 | AA19: 100 | AB19: 0 | AC19: 0
A20: 44699 | B20: 61.8 | C20: 344 | M20: =Generator!E20 -> 9492 | N20: =Generator!L20 -> 5126 | O20: =Generator!S20 -> 2294 | P20: =Generator!Z20 -> 0 | Q20: =Generator!AG20 -> 11964 | R20: =SUM(Generator!C20,Generator!J20,Generator!Q20,Generator!X20,Generator!AE20) -> 6426 | S20: =24.43*0.06 -> 1.4658 | U20: =U19 -> 0.32 | V20: 56 | W20: 23 | X20: 83 | Y20: 145 | Z20: 93 | AA20: 99 | AB20: 9 | AC20: 0
A21: 44700 | B21: 59.2 | C21: 341 | M21: =Generator!E21 -> 0 | N21: =Generator!L21 -> 11636 | O21: =Generator!S21 -> 5504 | P21: =Generator!Z21 -> 3638 | Q21: =Generator!AG21 -> 10834 | R21: =SUM(Generator!C21,Generator!J21,Generator!Q21,Generator!X21,Generator!AE21) -> 7048 | S21: =24.43*0.06 -> 1.4658 | U21: =U20 -> 0.32 | V21: 53 | W21: 30 | X21: 70 | Y21: 165 | Z21: 98 | AA21: 47 | AB21: 0 | AC21: 0
A22: 44701 | B22: 63.2 | C22: 280 | M22: =Generator!E22 -> 14445 | N22: =Generator!L22 -> 0 | O22: =Generator!S22 -> 2019 | P22: =Generator!Z22 -> 0 | Q22: =Generator!AG22 -> 12516 | R22: =SUM(Generator!C22,Generator!J22,Generator!Q22,Generator!X22,Generator!AE22) -> 6366 | S22: =25.26*0.06 -> 1.5156 | U22: =U21 -> 0.32 | V22: 57 | W22: 32 | X22: 87 | Y22: 136 | Z22: 86 | AA22: 8 | AB22: 0 | AC22: 0
A23: 44702 | B23: 61.8 | C23: 317 | M23: =Generator!E23 -> 9422 | N23: =Generator!L23 -> 4788 | O23: =Generator!S23 -> 10314 | P23: =Generator!Z23 -> 1537 | Q23: =Generator!AG23 -> 5520 | R23: =SUM(Generator!C23,Generator!J23,Generator!Q23,Generator!X23,Generator!AE23) -> 6909 | S23: =25.26*0.06 -> 1.5156 | U23: =U22 -> 0.32 | AC23: 0
A24: 44703 | M24: =Generator!E24 -> 0 | N24: =Generator!L24 -> 0 | O24: =Generator!S24 -> 0 | P24: =Generator!Z24 -> 0 | Q24: =Generator!AG24 -> 0 | R24: =SUM(Generator!C24,Generator!J24,Generator!Q24,Generator!X24,Generator!AE24) -> 0 | S24: =25.26*0.06 -> 1.5156 | U24: =U23 -> 0.32 | AC24: 0
A25: 44704 | M25: =Generator!E25 -> 0 | N25: =Generator!L25 -> 0 | O25: =Generator!S25 -> 0 | P25: =Generator!Z25 -> 0 | Q25: =Generator!AG25 -> 0 | R25: =SUM(Generator!C25,Generator!J25,Generator!Q25,Generator!X25,Generator!AE25) -> 0 | S25: =25.26*0.06 -> 1.5156 | U25: =U24 -> 0.32 | AC25: 0
A26: 44705 | M26: =Generator!E26 -> 0 | N26: =Generator!L26 -> 0 | O26: =Generator!S26 -> 0 | P26: =Generator!Z26 -> 0 | Q26: =Generator!AG26 -> 0 | R26: =SUM(Generator!C26,Generator!J26,Generator!Q26,Generator!X26,Generator!AE26) -> 0 | S26: =25.26*0.06 -> 1.5156 | U26: =U25 -> 0.32 | AC26: 0
A27: 44706 | M27: =Generator!E27 -> 0 | N27: =Generator!L27 -> 0 | O27: =Generator!S27 -> 0 | P27: =Generator!Z27 -> 0 | Q27: =Generator!AG27 -> 0 | R27: =SUM(Generator!C27,Generator!J27,Generator!Q27,Generator!X27,Generator!AE27) -> 0 | S27: =25.26*0.06 -> 1.5156 | U27: =U26 -> 0.32 | AC27: 0
A28: 44707 | M28: =Generator!E28 -> 0 | N28: =Generator!L28 -> 0 | O28: =Generator!S28 -> 0 | P28: =Generator!Z28 -> 0 | Q28: =Generator!AG28 -> 0 | R28: =SUM(Generator!C28,Generator!J28,Generator!Q28,Generator!X28,Generator!AE28) -> 0 | S28: =25.26*0.06 -> 1.5156 | U28: =U27 -> 0.32 | AC28: 0
A29: 44708 | M29: =Generator!E29 -> 0 | N29: =Generator!L29 -> 0 | O29: =Generator!S29 -> 0 | P29: =Generator!Z29 -> 0 | Q29: =Generator!AG29 -> 0 | R29: =SUM(Generator!C29,Generator!J29,Generator!Q29,Generator!X29,Generator!AE29) -> 0 | S29: =25.26*0.06 -> 1.5156 | U29: =U28 -> 0.32 | AC29: 0
A30: 44709 | M30: =Generator!E30 -> 0 | N30: =Generator!L30 -> 0 | O30: =Generator!S30 -> 0 | P30: =Generator!Z30 -> 0 | Q30: =Generator!AG30 -> 0 | R30: =SUM(Generator!C30,Generator!J30,Generator!Q30,Generator!X30,Generator!AE30) -> 0 | S30: =25.26*0.06 -> 1.5156 | U30: =U29 -> 0.32 | AC30: 0
A31: 44710 | M31: =Generator!E31 -> 0 | N31: =Generator!L31 -> 0 | O31: =Generator!S31 -> 0 | P31: =Generator!Z31 -> 0 | Q31: =Generator!AG31 -> 0 | R31: =SUM(Generator!C31,Generator!J31,Generator!Q31,Generator!X31,Generator!AE31) -> 0 | S31: =25.26*0.06 -> 1.5156 | U31: =U30 -> 0.32 | AC31: 0
A32: 44711 | M32: =Generator!E32 -> 0 | N32: =Generator!L32 -> 0 | O32: =Generator!S32 -> 0 | P32: =Generator!Z32 -> 0 | Q32: =Generator!AG32 -> 0 | R32: =SUM(Generator!C32,Generator!J32,Generator!Q32,Generator!X32,Generator!AE32) -> 0 | S32: =25.26*0.06 -> 1.5156 | U32: =U31 -> 0.32 | AC32: 0
A33: 44712 | M33: =Generator!E33 -> 0 | N33: =Generator!L33 -> 0 | O33: =Generator!S33 -> 0 | P33: =Generator!Z33 -> 0 | Q33: =Generator!AG33 -> 0 | R33: =SUM(Generator!C33,Generator!J33,Generator!Q33,Generator!X33,Generator!AE33) -> 0 | S33: =25.26*0.06 -> 1.5156 | U33: =U32 -> 0.32 | AC33: 0
L34: =SUM(M34:Q34) -> 662850 | M34: =SUM(M3:M33) -> 195020 | N34: =SUM(N3:N33) -> 137225 | O34: =SUM(O3:O33) -> 103052 | P34: =SUM(P3:P33) -> 70275 | Q34: =SUM(Q3:Q33) -> 157278 | R34: =SUM(R3:R33) -> 148381 | V34: =SUM(V3:V33) -> 1254.3 | W34: =SUM(W3:W33) -> 536.8 | X34: =SUM(X3:X33) -> 1488 | Y34: =SUM(Y3:Y33) -> 3747.7 | Z34: =SUM(Z3:Z33) -> 1856 | AA34: =SUM(AA3:AA33) -> 1845.8 | AB34: =SUM(AB3:AB33) -> 117 | AC34: =SUM(AC3:AC33) -> 288 | AD34: =SUM(V34:AC34) -> 11133.6
C35: =SUM(C3:C33) -> 6405

Sheet Generator
B1: Generator#1 (KWH) | I1: Generator#2 (KWH) | P1: Generator#3 (KWH) | W1: Generator#4 (KWH) | AD1: Generator#5 (KWH)
A2: DATE | B2: Running Hours | C2: Daily Fuel Burned | D2: Fuel burned Per Hour | E2: Daily Energy Consumed | F2: Energy Consumed Per Hour | G2: Engine Efficiency | I2: Running Hours | J2: Daily Fuel Burned | K2: Fuel burned Per Hour | L2: Daily Energy Consumed | M2: Energy Consumed Per Hour | N2: Engine Efficiency | P2: Running Hours | Q2: Daily Fuel Burned | R2: Fuel burned Per Hour | S2: Daily Energy Consumed | T2: Energy Consumed Per Hour | U2: Engine Efficiency | W2: Running Hours | X2: Daily Fuel Burned | Y2: Fuel burned Per Hour | Z2: Daily Energy Consumed | AA2: Energy Consumed Per Hour | AB2: Engine Efficiency | AD2: Running Hours | AE2: Daily Fuel Burned | AF2: Fuel burned Per Hour | AG2: Daily Energy Consumed | AH2: Energy Consumed Per Hour | AI2: Engine Efficiency
A3: 44713 | B3: 17 | C3: 2171 | D3: =C3/B3 -> 127.70588 | E3: 9633 | F3: =E3/B3 -> 566.64706 | G3: =F3/D3 -> 4.4371257 | I3: 14 | J3: 2146 | K3: =J3/I3 -> 153.28571 | L3: 9544 | M3: =L3/I3 -> 681.71429 | N3: =M3/K3 -> 4.4473439 | P3: 6 | Q3: 788 | R3: =Q3/P3 -> 131.33333 | S3: 3482 | T3: =S3/P3 -> 580.33333 | U3: =T3/R3 -> 4.4187817 | W3: 11 | X3: 1695 | Y3: =X3/W3 -> 154.09091 | Z3: 6719 | AA3: =Z3/W3 -> 610.81818 | AB3: =AA3/Y3 -> 3.9640118 | AD3: 11 | AE3: 1220 | AF3: =AE3/AD3 -> 110.90909 | AG3: 5527 | AH3: =AG3/AD3 -> 502.45455 | AI3: =AH3/AF3 -> 4.5303279
A4: 44714 | B4: 18 | C4: 2490 | D4: =C4/B4 -> 138.33333 | E4: 11405 | F4: =E4/B4 -> 633.61111 | G4: =F4/D4 -> 4.5803213 | I4: 10 | J4: 1431 | K4: =J4/I4 -> 143.1 | L4: 6563 | M4: =L4/I4 -> 656.3 | N4: =M4/K4 -> 4.5863033 | P4: 10 | Q4: 1420 | R4: =Q4/P4 -> 142 | S4: 6876 | T4: =S4/P4 -> 687.6 | U4: =T4/R4 -> 4.8422535 | W4: 1 | X4: 185 | Y4: =X4/W4 -> 185 | Z4: 1053 | AA4: =Z4/W4 -> 1053 | AB4: =AA4/Y4 -> 5.6918919 | AD4: 14 | AE4: 1833 | AF4: =AE4/AD4 -> 130.92857 | AG4: 8654 | AH4: =AG4/AD4 -> 618.14286 | AI4: =AH4/AF4 -> 4.721222
A5: 44715 | B5: 16 | C5: 2288 | D5: =C5/B5 -> 143 | E5: 10001 | F5: =E5/B5 -> 625.0625 | G5: =F5/D5 -> 4.3710664 | I5: 13 | J5: 1829 | K5: =J5/I5 -> 140.69231 | L5: 8150 | M5: =L5/I5 -> 626.92308 | N5: =M5/K5 -> 4.4559869 | P5: 0 | Q5: 0 | R5: =Q5/P5 -> #DIV/0! | S5: 0 | T5: =S5/P5 -> #DIV/0! | U5: =T5/R5 -> #DIV/0! | W5: 13 | X5: 2105 | Y5: =X5/W5 -> 161.92308 | Z5: 7890 | AA5: =Z5/W5 -> 606.92308 | AB5: =AA5/Y5 -> 3.7482185 | AD5: 11 | AE5: 1531 | AF5: =AE5/AD5 -> 139.18182 | AG5: 6955 | AH5: =AG5/AD5 -> 632.27273 | AI5: =AH5/AF5 -> 4.5427825
A6: 44716 | B6: 10 | C6: 1502 | D6: =C6/B6 -> 150.2 | E6: 6980 | F6: =E6/B6 -> 698 | G6: =F6/D6 -> 4.6471372 | I6: 11 | J6: 1800 | K6: =J6/I6 -> 163.63636 | L6: 8315 | M6: =L6/I6 -> 755.90909 | N6: =M6/K6 -> 4.6194444 | P6: 12 | Q6: 1726 | R6: =Q6/P6 -> 143.83333 | S6: 8325 | T6: =S6/P6 -> 693.75 | U6: =T6/R6 -> 4.8232908 | W6: 4 | X6: 504 | Y6: =X6/W6 -> 126 | Z6: 2311 | AA6: =Z6/W6 -> 577.75 | AB6: =AA6/Y6 -> 4.5853175 | AD6: 12 | AE6: 1519 | AF6: =AE6/AD6 -> 126.58333 | AG6: 7013 | AH6: =AG6/AD6 -> 584.41667 | AI6: =AH6/AF6 -> 4.6168532
A7: 44717 | B7: 18 | C7: 2371 | D7: =C7/B7 -> 131.72222 | E7: 10452 | F7: =E7/B7 -> 580.66667 | G7: =F7/D7 -> 4.4082666 | I7: 5 | J7: 730 | K7: =J7/I7 -> 146 | L7: 3279 | M7: =L7/I7 -> 655.8 | N7: =M7/K7 -> 4.4917808 | P7: 13 | Q7: 1948 | R7: =Q7/P7 -> 149.84615 | S7: 9168 | T7: =S7/P7 -> 705.23077 | U7: =T7/R7 -> 4.7063655 | W7: 7 | X7: 1358 | Y7: =X7/W7 -> 194 | Z7: 5313 | AA7: =Z7/W7 -> 759 | AB7: =AA7/Y7 -> 3.9123711 | AD7: 12 | AE7: 1650 | AF7: =AE7/AD7 -> 137.5 | AG7: 7449 | AH7: =AG7/AD7 -> 620.75 | AI7: =AH7/AF7 -> 4.5145455
A8: 44718 | B8: 13 | C8: 1710 | D8: =C8/B8 -> 131.53846 | E8: 7566 | F8: =E8/B8 -> 582 | G8: =F8/D8 -> 4.4245614 | I8: 12 | J8: 1787 | K8: =J8/I8 -> 148.91667 | L8: 8328 | M8: =L8/I8 -> 694 | N8: =M8/K8 -> 4.6603246 | P8: 11 | Q8: 1731 | R8: =Q8/P8 -> 157.36364 | S8: 8100 | T8: =S8/P8 -> 736.36364 | U8: =T8/R8 -> 4.6793761 | W8: 2 | X8: 204 | Y8: =X8/W8 -> 102 | Z8: 1014 | AA8: =Z8/W8 -> 507 | AB8: =AA8/Y8 -> 4.9705882 | AD8: 13 | AE8: 1639 | AF8: =AE8/AD8 -> 126.07692 | AG8: 7489 | AH8: =AG8/AD8 -> 576.07692 | AI8: =AH8/AF8 -> 4.5692495
A9: 44719 | B9: 12 | C9: 1834 | D9: =C9/B9 -> 152.83333 | E9: 8753 | F9: =E9/B9 -> 729.41667 | G9: =F9/D9 -> 4.7726281 | I9: 13 | J9: 1876 | K9: =J9/I9 -> 144.30769 | L9: 8407 | M9: =L9/I9 -> 646.69231 | N9: =M9/K9 -> 4.4813433 | P9: 12 | Q9: 1770 | R9: =Q9/P9 -> 147.5 | S9: 8082 | T9: =S9/P9 -> 673.5 | U9: =T9/R9 -> 4.5661017 | W9: 7 | X9: 1065 | Y9: =X9/W9 -> 152.14286 | Z9: 3863 | AA9: =Z9/W9 -> 551.85714 | AB9: =AA9/Y9 -> 3.62723 | AD9: 12 | AE9: 1753 | AF9: =AE9/AD9 -> 146.08333 | AG9: 8364 | AH9: =AG9/AD9 -> 697 | AI9: =AH9/AF9 -> 4.7712493
A10: 44720 | B10: 10 | C10: 1530 | D10: =C10/B10 -> 153 | E10: 6127 | F10: =E10/B10 -> 612.7 | G10: =F10/D10 -> 4.0045752 | I10: 17 | J10: 2746 | K10: =J10/I10 -> 161.52941 | L10: 12474 | M10: =L10/I10 -> 733.76471 | N10: =M10/K10 -> 4.5426074 | P10: 0 | Q10: 0 | R10: =Q10/P10 -> #DIV/0! | S10: 0 | T10: =S10/P10 -> #DIV/0! | U10: =T10/R10 -> #DIV/0! | W10: 21 | X10: 3396 | Y10: =X10/W10 -> 161.71429 | Z10: 13684 | AA10: =Z10/W10 -> 651.61905 | AB10: =AA10/Y10 -> 4.0294464 | AD10: 6 | AE10: 848 | AF10: =AE10/AD10 -> 141.33333 | AG10: 9746 | AH10: =AG10/AD10 -> 1624.3333 | AI10: =AH10/AF10 -> 11.492925
A11: 44721 | B11: 21 | C11: 2975 | D11: =C11/B11 -> 141.66667 | E11: 13506 | F11: =E11/B11 -> 643.14286 | G11: =F11/D11 -> 4.5398319 | I11: 15 | J11: 2140 | K11: =J11/I11 -> 142.66667 | L11: 9804 | M11: =L11/I11 -> 653.6 | N11: =M11/K11 -> 4.5813084 | P11: 10 | Q11: 1322 | R11: =Q11/P11 -> 132.2 | S11: 5455 | T11: =S11/P11 -> 545.5 | U11: =T11/R11 -> 4.1263238 | W11: 12 | X11: 2021 | Y11: =X11/W11 -> 168.41667 | Z11: 8224 | AA11: =Z11/W11 -> 685.33333 | AB11: =AA11/Y11 -> 4.0692726 | AD11: 0 | AE11: 0 | AF11: =AE11/AD11 -> #DIV/0! | AG11: 0 | AH11: =AG11/AD11 -> #DIV/0! | AI11: =AH11/AF11 -> #DIV/0!
A12: 44722 | B12: 19 | C12: 2443 | D12: =C12/B12 -> 128.57895 | E12: 10688 | F12: =E12/B12 -> 562.52632 | G12: =F12/D12 -> 4.3749488 | I12: 8 | J12: 1051 | K12: =J12/I12 -> 131.375 | L12: 4617 | M12: =L12/I12 -> 577.125 | N12: =M12/K12 -> 4.3929591 | P12: 8 | Q12: 1206 | R12: =Q12/P12 -> 150.75 | S12: 5338 | T12: =S12/P12 -> 667.25 | U12: =T12/R12 -> 4.4262023 | W12: 0 | X12: 0 | Y12: =X12/W12 -> #DIV/0! | Z12: 0 | AA12: =Z12/W12 -> #DIV/0! | AB12: =AA12/Y12 -> #DIV/0! | AD12: 10 | AE12: 804 | AF12: =AE12/AD12 -> 80.4 | AG12: 5809 | AH12: =AG12/AD12 -> 580.9 | AI12: =AH12/AF12 -> 7.2251244
A13: 44723 | B13: 16 | C13: 2000 | D13: =C13/B13 -> 125 | E13: 8950 | F13: =E13/B13 -> 559.375 | G13: =F13/D13 -> 4.475 | I13: 9 | J13: 1336 | K13: =J13/I13 -> 148.44444 | L13: 6070 | M13: =L13/I13 -> 674.44444 | N13: =M13/K13 -> 4.5434132 | P13: 13 | Q13: 1772 | R13: =Q13/P13 -> 136.30769 | S13: 8033 | T13: =S13/P13 -> 617.92308 | U13: =T13/R13 -> 4.5332957 | W13: 0 | X13: 0 | Y13: =X13/W13 -> #DIV/0! | Z13: 0 | AA13: =Z13/W13 -> #DIV/0! | AB13: =AA13/Y13 -> #DIV/0! | AD13: 15 | AE13: 3374 | AF13: =AE13/AD13 -> 224.93333 | AG13: 8895 | AH13: =AG13/AD13 -> 593 | AI13: =AH13/AF13 -> 2.6363367
A14: 44724 | B14: 12 | C14: 1853 | D14: =C14/B14 -> 154.41667 | E14: 8208 | F14: =E14/B14 -> 684 | G14: =F14/D14 -> 4.4295737 | I14: 14 | J14: 2157 | K14: =J14/I14 -> 154.07143 | L14: 9618 | M14: =L14/I14 -> 687 | N14: =M14/K14 -> 4.4589708 | P14: 8 | Q14: 1206 | R14: =Q14/P14 -> 150.75 | S14: 5450 | T14: =S14/P14 -> 681.25 | U14: =T14/R14 -> 4.5190713 | Y14: =X14/W14 -> #DIV/0! | AA14: =Z14/W14 -> #DIV/0! | AB14: =AA14/Y14 -> #DIV/0! | AD14: 6 | AE14: 1009 | AF14: =AE14/AD14 -> 168.16667 | AG14: 4449 | AH14: =AG14/AD14 -> 741.5 | AI14: =AH14/AF14 -> 4.4093162
A15: 44725 | B15: 14 | C15: 2302 | D15: =C15/B15 -> 164.42857 | E15: 10082 | F15: =E15/B15 -> 720.14286 | G15: =F15/D15 -> 4.3796699 | I15: 0 | J15: 0 | K15: =J15/I15 -> #DIV/0! | L15: 0 | M15: =L15/I15 -> #DIV/0! | N15: =M15/K15 -> #DIV/0! | P15: 9 | Q15: 1191 | R15: =Q15/P15 -> 132.33333 | S15: 5338 | T15: =S15/P15 -> 593.11111 | U15: =T15/R15 -> 4.4819479 | W15: 0 | X15: 0 | Y15: =X15/W15 -> #DIV/0! | Z15: 0 | AA15: =Z15/W15 -> #DIV/0! | AB15: =AA15/Y15 -> #DIV/0! | AD15: 22 | AE15: 2972 | AF15: =AE15/AD15 -> 135.09091 | AG15: 13626 | AH15: =AG15/AD15 -> 619.36364 | AI15: =AH15/AF15 -> 4.5847914
A16: 44726 | B16: 19 | C16: 2534 | D16: =C16/B16 -> 133.36842 | E16: 11200 | F16: =E16/B16 -> 589.47368 | G16: =F16/D16 -> 4.4198895 | I16: 5 | J16: 730 | K16: =J16/I16 -> 146 | L16: 3279 | M16: =L16/I16 -> 655.8 | N16: =M16/K16 -> 4.4917808 | P16: 0 | Q16: 0 | R16: =Q16/P16 -> #DIV/0! | S16: 0 | T16: =S16/P16 -> #DIV/0! | U16: =T16/R16 -> #DIV/0! | W16: 9 | X16: 1583 | Y16: =X16/W16 -> 175.88889 | Z16: 6093 | AA16: =Z16/W16 -> 677 | AB16: =AA16/Y16 -> 3.8490208 | AD16: 15 | AE16: 2257 | AF16: =AE16/AD16 -> 150.46667 | AG16: 10607 | AH16: =AG16/AD16 -> 707.13333 | AI16: =AH16/AF16 -> 4.6996012
A17: 44727 | B17: 17 | C17: 2454 | D17: =C17/B17 -> 144.35294 | E17: 10504 | F17: =E17/B17 -> 617.88235 | G17: =F17/D17 -> 4.2803586 | I17: 12 | J17: 1824 | K17: =J17/I17 -> 152 | L17: 8248 | M17: =L17/I17 -> 687.33333 | N17: =M17/K17 -> 4.5219298 | P17: 0 | Q17: 0 | R17: =Q17/P17 -> #DIV/0! | S17: 0 | T17: =S17/P17 -> #DIV/0! | U17: =T17/R17 -> #DIV/0! | W17: 9 | X17: 1137 | Y17: =X17/W17 -> 126.33333 | Z17: 4612 | AA17: =Z17/W17 -> 512.44444 | AB17: =AA17/Y17 -> 4.0562885 | AD17: 6 | AE17: 851 | AF17: =AE17/AD17 -> 141.83333 | AG17: 3814 | AH17: =AG17/AD17 -> 635.66667 | AI17: =AH17/AF17 -> 4.4817861
A18: 44728 | B18: 14 | C18: 1587 | D18: =C18/B18 -> 113.35714 | E18: 7129 | F18: =E18/B18 -> 509.21429 | G18: =F18/D18 -> 4.4921235 | I18: 8 | J18: 890 | K18: =J18/I18 -> 111.25 | L18: 3999 | M18: =L18/I18 -> 499.875 | N18: =M18/K18 -> 4.4932584 | P18: 15 | Q18: 1894 | R18: =Q18/P18 -> 126.26667 | S18: 9274 | T18: =S18/P18 -> 618.26667 | U18: =T18/R18 -> 4.8965153 | W18: 0 | X18: 0 | Y18: =X18/W18 -> #DIV/0! | Z18: 0 | AA18: =Z18/W18 -> #DIV/0! | AB18: =AA18/Y18 -> #DIV/0! | AD18: 2 | AE18: 350 | AF18: =AE18/AD18 -> 175 | AG18: 1426 | AH18: =AG18/AD18 -> 713 | AI18: =AH18/AF18 -> 4.0742857
A19: 44729 | B19: 16 | C19: 2299 | D19: =C19/B19 -> 143.6875 | E19: 10477 | F19: =E19/B19 -> 654.8125 | G19: =F19/D19 -> 4.5571988 | I19: 9 | J19: 1185 | K19: =J19/I19 -> 131.66667 | L19: 4980 | M19: =L19/I19 -> 553.33333 | N19: =M19/K19 -> 4.2025316 | P19: 0 | Q19: 0 | R19: =Q19/P19 -> #DIV/0! | S19: 0 | T19: =S19/P19 -> #DIV/0! | U19: =T19/R19 -> #DIV/0! | W19: 8 | X19: 1304 | Y19: =X19/W19 -> 163 | Z19: 4324 | AA19: =Z19/W19 -> 540.5 | AB19: =AA19/Y19 -> 3.3159509 | AD19: 12 | AE19: 1490 | AF19: =AE19/AD19 -> 124.16667 | AG19: 6621 | AH19: =AG19/AD19 -> 551.75 | AI19: =AH19/AF19 -> 4.4436242
A20: 44730 | B20: 13 | C20: 2112 | D20: =C20/B20 -> 162.46154 | E20: 9492 | F20: =E20/B20 -> 730.15385 | G20: =F20/D20 -> 4.4943182 | I20: 11 | J20: 1173 | K20: =J20/I20 -> 106.63636 | L20: 5126 | M20: =L20/I20 -> 466 | N20: =M20/K20 -> 4.3699915 | P20: 4 | Q20: 539 | R20: =Q20/P20 -> 134.75 | S20: 2294 | T20: =S20/P20 -> 573.5 | U20: =T20/R20 -> 4.2560297 | W20: 0 | X20: 0 | Y20: =X20/W20 -> #DIV/0! | Z20: 0 | AA20: =Z20/W20 -> #DIV/0! | AB20: =AA20/Y20 -> #DIV/0! | AD20: 20 | AE20: 2602 | AF20: =AE20/AD20 -> 130.1 | AG20: 11964 | AH20: =AG20/AD20 -> 598.2 | AI20: =AH20/AF20 -> 4.5980015
A21: 44731 | B21: 0 | C21: 0 | D21: =C21/B21 -> #DIV/0! | E21: 0 | F21: =E21/B21 -> #DIV/0! | G21: =F21/D21 -> #DIV/0! | I21: 19 | J21: 2625 | K21: =J21/I21 -> 138.15789 | L21: 11636 | M21: =L21/I21 -> 612.42105 | N21: =M21/K21 -> 4.4327619 | P21: 9 | Q21: 1183 | R21: =Q21/P21 -> 131.44444 | S21: 5504 | T21: =S21/P21 -> 611.55556 | U21: =T21/R21 -> 4.6525782 | W21: 5 | X21: 871 | Y21: =X21/W21 -> 174.2 | Z21: 3638 | AA21: =Z21/W21 -> 727.6 | AB21: =AA21/Y21 -> 4.1768083 | AD21: 17 | AE21: 2369 | AF21: =AE21/AD21 -> 139.35294 | AG21: 10834 | AH21: =AG21/AD21 -> 637.29412 | AI21: =AH21/AF21 -> 4.5732377
A22: 44732 | B22: 24 | C22: 3208 | D22: =C22/B22 -> 133.66667 | E22: 14445 | F22: =E22/B22 -> 601.875 | G22: =F22/D22 -> 4.5028055 | I22: 0 | J22: 0 | K22: =J22/I22 -> #DIV/0! | L22: 0 | M22: =L22/I22 -> #DIV/0! | N22: =M22/K22 -> #DIV/0! | P22: 4 | Q22: 476 | R22: =Q22/P22 -> 119 | S22: 2019 | T22: =S22/P22 -> 504.75 | U22: =T22/R22 -> 4.2415966 | W22: 0 | X22: 0 | Y22: =X22/W22 -> #DIV/0! | Z22: 0 | AA22: =Z22/W22 -> #DIV/0! | AB22: =AA22/Y22 -> #DIV/0! | AD22: 21 | AE22: 2682 | AF22: =AE22/AD22 -> 127.71429 | AG22: 12516 | AH22: =AG22/AD22 -> 596 | AI22: =AH22/AF22 -> 4.6666667
