Workbook

Sheet TOTAL
A1: Site Name | B1: Day | C1: Month | D1: Year | E1: Total Electricity Kwh | F1: Electricity Tariff ($/Kwh) | G1: LPG (Kg) | H1: LPG $/Kg | I1: Water Utility Supply (m3) m3 | J1: Water Utility Supply (m3) $/m3 | K1: Room Nights | L1: Total Guests | M1: Utilities day cost dh
A2: Casablanca | B2: 1 | C2: 6 | D2: 2022 | E2: =submetering!E2+submetering!F2+submetering!G2 -> 16925 | F2: 1.05 | G2: ='Consommation mensuel énergie'!V10 -> 159.99605 | H2: 13.14 | I2: ='Consommation mensuel énergie'!F10 -> 267 | J2: 11.4 | K2: ='Consommation mensuel énergie'!D10 -> 179 | L2: ='Consommation mensuel énergie'!E10 -> 253 | M2: =E2*F2+G2*H2+#REF!*#REF!+I2*J2 -> #REF!
A3: Casablanca | B3: =B2+1 -> 2 | C3: 6 | D3: 2022 | E3: =submetering!E3+submetering!F3+submetering!G3 -> 18635 | F3: 1.05 | G3: ='Consommation mensuel énergie'!V11 -> 287.99289 | H3: 13.14 | I3: ='Consommation mensuel énergie'!F11 -> 165.3 | J3: 11.4 | K3: ='Consommation mensuel énergie'!D11 -> 177 | L3: ='Consommation mensuel énergie'!E11 -> 263 | M3: =E3*F3+G3*H3+#REF!*#REF!+I3*J3 -> #REF!
A4: Casablanca | B4: =B3+1 -> 3 | C4: 6 | D4: 2022 | E4: =submetering!E4+submetering!F4+submetering!G4 -> 18097 | F4: 1.05 | G4: ='Consommation mensuel énergie'!V12 -> 319.9921 | H4: 13.14 | I4: ='Consommation mensuel énergie'!F12 -> 158.9 | J4: 11.4 | K4: ='Consommation mensuel énergie'!D12 -> 173 | L4: ='Consommation mensuel énergie'!E12 -> 289 | M4: =E4*F4+G4*H4+#REF!*#REF!+I4*J4 -> #REF!
A5: Casablanca | B5: =B4+1 -> 4 | C5: 6 | D5: 2022 | E5: =submetering!E5+submetering!F5+submetering!G5 -> 18960 | F5: 1.05 | G5: ='Consommation mensuel énergie'!V13 -> 352.6567 | H5: 13.14 | I5: ='Consommation mensuel énergie'!F13 -> 157.8 | J5: 11.4 | K5: ='Consommation mensuel énergie'!D13 -> 171 | L5: ='Consommation mensuel énergie'!E13 -> 289 | M5: =E5*F5+G5*H5+#REF!*#REF!+I5*J5 -> #REF!
A6: Casablanca | B6: =B5+1 -> 5 | C6: 6 | D6: 2022 | E6: =submetering!E6+submetering!F6+submetering!G6 -> 18545 | F6: 1.05 | G6: ='Consommation mensuel énergie'!V14 -> 287.99289 | H6: 13.14 | I6: ='Consommation mensuel énergie'!F14 -> 160 | J6: 11.4 | K6: ='Consommation mensuel énergie'!D14 -> 146 | L6: ='Consommation mensuel énergie'!E14 -> 229 | M6: =E6*F6+G6*H6+#REF!*#REF!+I6*J6 -> #REF!
A7: Casablanca | B7: =B6+1 -> 6 | C7: 6 | D7: 2022 | E7: =submetering!E7+submetering!F7+submetering!G7 -> 18059 | F7: 1.05 | G7: ='Consommation mensuel énergie'!V15 -> 127.99684 | H7: 13.14 | I7: ='Consommation mensuel énergie'!F15 -> 145 | J7: 11.4 | K7: ='Consommation mensuel énergie'!D15 -> 134 | L7: ='Consommation mensuel énergie'!E15 -> 208 | M7: =E7*F7+G7*H7+#REF!*#REF!+I7*J7 -> #REF!
A8: Casablanca | B8: =B7+1 -> 7 | C8: 6 | D8: 2022 | E8: =submetering!E8+submetering!F8+submetering!G8 -> 19823 | F8: 1.05 | G8: ='Consommation mensuel énergie'!V16 -> 351.99131 | H8: 13.14 | I8: ='Consommation mensuel énergie'!F16 -> 155 | J8: 11.4 | K8: ='Consommation mensuel énergie'!D16 -> 134 | L8: ='Consommation mensuel énergie'!E16 -> 201 | M8: =E8*F8+G8*H8+#REF!*#REF!+I8*J8 -> #REF!
A9: Casablanca | B9: =B8+1 -> 8 | C9: 6 | D9: 2022 | E9: =submetering!E9+submetering!F9+submetering!G9 -> 20062 | F9: 1.05 | G9: ='Consommation mensuel énergie'!V17 -> 223.99447 | H9: 13.14 | I9: ='Consommation mensuel énergie'!F17 -> 139 | J9: 11.4 | K9: ='Consommation mensuel énergie'!D17 -> 147 | L9: ='Consommation mensuel énergie'!E17 -> 205 | M9: =E9*F9+G9*H9+#REF!*#REF!+I9*J9 -> #REF!
A10: Casablanca | B10: =B9+1 -> 9 | C10: 6 | D10: 2022 | E10: =submetering!E10+submetering!F10+submetering!G10 -> 19837 | F10: 1.05 | G10: ='Consommation mensuel énergie'!V18 -> 287.99289 | H10: 13.14 | I10: ='Consommation mensuel énergie'!F18 -> 135 | J10: 11.4 | K10: ='Consommation mensuel énergie'!D18 -> 138 | L10: ='Consommation mensuel énergie'!E18 -> 200 | M10: =E10*F10+G10*H10+#REF!*#REF!+I10*J10 -> #REF!
A11: Casablanca | B11: =B10+1 -> 10 | C11: 6 | D11: 2022 | E11: =submetering!E11+submetering!F11+submetering!G11 -> 19644 | F11: 1.05 | G11: ='Consommation mensuel énergie'!V19 -> 383.99052 | H11: 13.14 | I11: ='Consommation mensuel énergie'!F19 -> 175.3 | J11: 11.4 | K11: ='Consommation mensuel énergie'!D19 -> 120 | L11: ='Consommation mensuel énergie'!E19 -> 175 | M11: =E11*F11+G11*H11+#REF!*#REF!+I11*J11 -> #REF!
A12: Casablanca | B12: =B11+1 -> 11 | C12: 6 | D12: 2022 | E12: =submetering!E12+submetering!F12+submetering!G12 -> 19982 | F12: 1.05 | G12: ='Consommation mensuel énergie'!V20 -> 415.98973 | H12: 13.14 | I12: ='Consommation mensuel énergie'!F20 -> 170.6 | J12: 11.4 | K12: ='Consommation mensuel énergie'!D20 -> 173 | L12: ='Consommation mensuel énergie'!E20 -> 223 | M12: =E12*F12+G12*H12+#REF!*#REF!+I12*J12 -> #REF!
A13: Casablanca | B13: =B12+1 -> 12 | C13: 6 | D13: 2022 | E13: =submetering!E13+submetering!F13+submetering!G13 -> 21334 | F13: 1.05 | G13: ='Consommation mensuel énergie'!V21 -> 159.99605 | H13: 13.14 | I13: ='Consommation mensuel énergie'!F21 -> 163.1 | J13: 11.4 | K13: ='Consommation mensuel énergie'!D21 -> 183 | L13: ='Consommation mensuel énergie'!E21 -> 237 | M13: =E13*F13+G13*H13+#REF!*#REF!+I13*J13 -> #REF!
A14: Casablanca | B14: =B13+1 -> 13 | C14: 6 | D14: 2022 | E14: =submetering!E14+submetering!F14+submetering!G14 -> 21345 | F14: 1.05 | G14: ='Consommation mensuel énergie'!V22 -> 95.99763 | H14: 13.14 | I14: ='Consommation mensuel énergie'!F22 -> 151 | J14: 11.4 | K14: ='Consommation mensuel énergie'!D22 -> 181 | L14: ='Consommation mensuel énergie'!E22 -> 226 | M14: =E14*F14+G14*H14+#REF!*#REF!+I14*J14 -> #REF!
... A26: Casablanca | B26: =B25+1 -> 25 | C26: 6 | D26: 2022 | E26: =submetering!E26+submetering!F26+submetering!G26 -> 17022 | F26: 1.05 | G26: ='Consommation mensuel énergie'!V34 -> 127.99684 | H26: 13.14 | I26: ='Consommation mensuel énergie'!F34 -> 154 | J26: 11.4 | K26: ='Consommation mensuel énergie'!D34 -> 146 | L26: ='Consommation mensuel énergie'!E34 -> 257 | M26: =E26*F26+G26*H26+#REF!*#REF!+I26*J26 -> #REF!
A27: Casablanca | B27: =B26+1 -> 26 | C27: 6 | D27: 2022 | E27: =submetering!E27+submetering!F27+submetering!G27 -> 17364 | F27: 1.05 | G27: ='Consommation mensuel énergie'!V35 -> 127.99684 | H27: 13.14 | I27: ='Consommation mensuel énergie'!F35 -> 176 | J27: 11.4 | K27: ='Consommation mensuel énergie'!D35 -> 143 | L27: ='Consommation mensuel énergie'!E35 -> 224
A28: Casablanca | B28: =B27+1 -> 27 | C28: 6 | D28: 2022 | E28: =submetering!E28+submetering!F28+submetering!G28 -> 15893 | F28: 1.05 | G28: ='Consommation mensuel énergie'!V36 -> 0 | H28: 13.14 | I28: ='Consommation mensuel énergie'!F36 -> 180 | J28: 11.4 | K28: ='Consommation mensuel énergie'!D36 -> 0 | L28: ='Consommation mensuel énergie'!E36 -> 0
A29: Casablanca | B29: =B28+1 -> 28 | C29: 6 | D29: 2022 | E29: =submetering!E29+submetering!F29+submetering!G29 -> 0 | F29: 1.05 | G29: ='Consommation mensuel énergie'!V37 -> 0 | H29: 13.14 | I29: ='Consommation mensuel énergie'!F37 -> 0 | J29: 11.4 | K29: ='Consommation mensuel énergie'!D37 -> 0 | L29: ='Consommation mensuel énergie'!E37 -> 0
A30: Casablanca | B30: =B29+1 -> 29 | C30: 6 | D30: 2022 | E30: =submetering!E30+submetering!F30+submetering!G30 -> 0 | F30: 1.05 | G30: ='Consommation mensuel énergie'!V38 -> 0 | H30: 13.14 | I30: ='Consommation mensuel énergie'!F38 -> 0 | J30: 11.4 | K30: ='Consommation mensuel énergie'!D38 -> 0 | L30: ='Consommation mensuel énergie'!E38 -> 0
A31: Casablanca | B31: =B30+1 -> 30 | C31: 6 | D31: 2022 | E31: =submetering!E31+submetering!F31+submetering!G31 -> 0 | F31: 1.05 | G31: ='Consommation mensuel énergie'!V39 -> 0 | H31: 13.14 | I31: ='Consommation mensuel énergie'!F39 -> 0 | J31: 11.4 | K31: ='Consommation mensuel énergie'!D39 -> 0 | L31: ='Consommation mensuel énergie'!E39 -> 0

Sheet submetering
A1: Site Name | B1: Day | C1: Month | D1: Year | E1: Creuse 81 - KWh | F1: Pleine 82-KWh | G1: Pointe 83 - KWh | H1: Room Nights | I1: Total Guests | J1: Utilities day cost dh
A2: Casablanca | B2: 1 | C2: 6 | D2: 2022 | E2: ='Consommation mensuel énergie'!L10 -> 4384 | F2: ='Consommation mensuel énergie'!M10 -> 9147 | G2: ='Consommation mensuel énergie'!N10 -> 3394 | H2: ='Consommation mensuel énergie'!D10 -> 179 | I2: ='Consommation mensuel énergie'!E10 -> 253 | J2: =E2*F2+G2*#REF!+#REF!*#REF!+#REF!*#REF! -> #REF!
A3: Casablanca | B3: =B2+1 -> 2 | C3: 6 | D3: 2022 | E3: ='Consommation mensuel énergie'!L11 -> 4441 | F3: ='Consommation mensuel énergie'!M11 -> 10256 | G3: ='Consommation mensuel énergie'!N14 -> 3938 | H3: ='Consommation mensuel énergie'!D11 -> 177 | I3: ='Consommation mensuel énergie'!E11 -> 263 | J3: =E3*F3+G3*#REF!+#REF!*#REF!+#REF!*#REF! -> #REF!
A4: Casablanca | B4: =B3+1 -> 3 | C4: 6 | D4: 2022 | E4: ='Consommation mensuel énergie'!L12 -> 3749 | F4: ='Consommation mensuel énergie'!M12 -> 10529 | G4: ='Consommation mensuel énergie'!N12 -> 3819 | H4: ='Consommation mensuel énergie'!D12 -> 173 | I4: ='Consommation mensuel énergie'!E12 -> 289 | J4: =E4*F4+G4*#REF!+#REF!*#REF!+#REF!*#REF! -> #REF!
A5: Casablanca | B5: =B4+1 -> 4 | C5: 6 | D5: 2022 | E5: ='Consommation mensuel énergie'!L13 -> 4936 | F5: ='Consommation mensuel énergie'!M13 -> 10072 | G5: ='Consommation mensuel énergie'!N13 -> 3952 | H5: ='Consommation mensuel énergie'!D13 -> 171 | I5: ='Consommation mensuel énergie'!E13 -> 289 | J5: =E5*F5+G5*#REF!+#REF!*#REF!+#REF!*#REF! -> #REF!
A6: Casablanca | B6: =B5+1 -> 5 | C6: 6 | D6: 2022 | E6: ='Consommation mensuel énergie'!L14 -> 4461 | F6: ='Consommation mensuel énergie'!M14 -> 10146 | G6: ='Consommation mensuel énergie'!N14 -> 3938 | H6: ='Consommation mensuel énergie'!D14 -> 146 | I6: ='Consommation mensuel énergie'!E14 -> 229 | J6: =E6*F6+G6*#REF!+#REF!*#REF!+#REF!*#REF! -> #REF!
A7: Casablanca | B7: =B6+1 -> 6 | C7: 6 | D7: 2022 | E7: ='Consommation mensuel énergie'!L15 -> 4437 | F7: ='Consommation mensuel énergie'!M15 -> 9912 | G7: ='Consommation mensuel énergie'!N15 -> 3710 | H7: ='Consommation mensuel énergie'!D15 -> 134 | I7: ='Consommation mensuel énergie'!E15 -> 208 | J7: =E7*F7+G7*#REF!+#REF!*#REF!+#REF!*#REF! -> #REF!
A8: Casablanca | B8: =B7+1 -> 7 | C8: 6 | D8: 2022 | E8: ='Consommation mensuel énergie'!L16 -> 4900 | F8: ='Consommation mensuel énergie'!M16 -> 10384 | G8: ='Consommation mensuel énergie'!N16 -> 4539 | H8: ='Consommation mensuel énergie'!D16 -> 134 | I8: ='Consommation mensuel énergie'!E16 -> 201 | J8: =E8*F8+G8*#REF!+#REF!*#REF!+#REF!*#REF! -> #REF!
A9: Casablanca | B9: =B8+1 -> 8 | C9: 6 | D9: 2022 | E9: ='Consommation mensuel énergie'!L17 -> 5117 | F9: ='Consommation mensuel énergie'!M17 -> 10773 | G9: ='Consommation mensuel énergie'!N17 -> 4172 | H9: ='Consommation mensuel énergie'!D17 -> 147 | I9: ='Consommation mensuel énergie'!E17 -> 205 | J9: =E9*F9+G9*#REF!+#REF!*#REF!+#REF!*#REF! -> #REF!
A10: Casablanca | B10: =B9+1 -> 9 | C10: 6 | D10: 2022 | E10: ='Consommation mensuel énergie'!L18 -> 5025 | F10: ='Consommation mensuel énergie'!M18 -> 10593 | G10: ='Consommation mensuel énergie'!N18 -> 4219 | H10: ='Consommation mensuel énergie'!D18 -> 138 | I10: ='Consommation mensuel énergie'!E18 -> 200 | J10: =E10*F10+G10*#REF!+#REF!*#REF!+#REF!*#REF! -> #REF!
A11: Casablanca | B11: =B10+1 -> 10 | C11: 6 | D11: 2022 | E11: ='Consommation mensuel énergie'!L19 -> 4793 | F11: ='Consommation mensuel énergie'!M19 -> 10865 | G11: ='Consommation mensuel énergie'!N19 -> 3986 | H11: ='Consommation mensuel énergie'!D19 -> 120 | I11: ='Consommation mensuel énergie'!E19 -> 175 | J11: =E11*F11+G11*#REF!+#REF!*#REF!+#REF!*#REF! -> #REF!
A12: Casablanca | B12: =B11+1 -> 11 | C12: 6 | D12: 2022 | E12: ='Consommation mensuel énergie'!L20 -> 5146 | F12: ='Consommation mensuel énergie'!M20 -> 10605 | G12: ='Consommation mensuel énergie'!N20 -> 4231 | H12: ='Consommation mensuel énergie'!D20 -> 173 | I12: ='Consommation mensuel énergie'!E20 -> 223 | J12: =E12*F12+G12*#REF!+#REF!*#REF!+#REF!*#REF! -> #REF!
A13: Casablanca | B13: =B12+1 -> 12 | C13: 6 | D13: 2022 | E13: ='Consommation mensuel énergie'!L21 -> 5362 | F13: ='Consommation mensuel énergie'!M21 -> 11461 | G13: ='Consommation mensuel énergie'!N21 -> 4511 | H13: ='Consommation mensuel énergie'!D21 -> 183 | I13: ='Consommation mensuel énergie'!E21 -> 237 | J13: =E13*F13+G13*#REF!+#REF!*#REF!+#REF!*#REF! -> #REF!
A14: Casablanca | B14: =B13+1 -> 13 | C14: 6 | D14: 2022 | E14: ='Consommation mensuel énergie'!L22 -> 4871 | F14: ='Consommation mensuel énergie'!M22 -> 12046 | G14: ='Consommation mensuel énergie'!N22 -> 4428 | H14: ='Consommation mensuel énergie'!D22 -> 181 | I14: ='Consommation mensuel énergie'!E22 -> 226 | J14: =E14*F14+G14*#REF!+#REF!*#REF!+#REF!*#REF! -> #REF!
A15: Casablanca | B15: =B14+1 -> 14 | C15: 6 | D15: 2022 | E15: ='Consommation mensuel énergie'!L23 -> 4707 | F15: ='Consommation mensuel énergie'!M23 -> 11903 | G15: ='Consommation mensuel énergie'!N23 -> 4890 | H15: ='Consommation mensuel énergie'!D23 -> 141 | I15: ='Consommation mensuel énergie'!E23 -> 189 | J15: =E15*F15+G15*#REF!+#REF!*#REF!+#REF!*#REF! -> #REF!
... A26: Casablanca | B26: =B25+1 -> 25 | C26: 6 | D26: 2022 | E26: ='Consommation mensuel énergie'!L34 -> 4488 | F26: ='Consommation mensuel énergie'!M34 -> 9074 | G26: ='Consommation mensuel énergie'!N34 -> 3460 | H26: ='Consommation mensuel énergie'!D34 -> 146 | I26: ='Consommation mensuel énergie'!E34 -> 257 | J26: =E26*F26+G26*#REF!+#REF!*#REF!+#REF!*#REF! -> #REF!
A27: Casablanca | B27: =B26+1 -> 26 | C27: 6 | D27: 2022 | E27: ='Consommation mensuel énergie'!L35 -> 4644 | F27: ='Consommation mensuel énergie'!M35 -> 9126 | G27: ='Consommation mensuel énergie'!N35 -> 3594 | H27: ='Consommation mensuel énergie'!D35 -> 143 | I27: ='Consommation mensuel énergie'!E35 -> 224
A28: Casablanca | B28: =B27+1 -> 27 | C28: 6 | D28: 2022 | E28: ='Consommation mensuel énergie'!L36 -> 4085 | F28: ='Consommation mensuel énergie'!M36 -> 8349 | G28: ='Consommation mensuel énergie'!N36 -> 3459 | H28: ='Consommation mensuel énergie'!D36 -> 0 | I28: ='Consommation mensuel énergie'!E36 -> 0
A29: Casablanca | B29: =B28+1 -> 28 | C29: 6 | D29: 2022 | E29: ='Consommation mensuel énergie'!L37 -> 0 | F29: ='Consommation mensuel énergie'!M37 -> 0 | G29: ='Consommation mensuel énergie'!N37 -> 0 | H29: ='Consommation mensuel énergie'!D37 -> 0 | I29: ='Consommation mensuel énergie'!E37 -> 0
A30: Casablanca | B30: =B29+1 -> 29 | C30: 6 | D30: 2022 | E30: ='Consommation mensuel énergie'!L38 -> 0 | F30: ='Consommation mensuel énergie'!M38 -> 0 | G30: ='Consommation mensuel énergie'!N38 -> 0 | H30: ='Consommation mensuel énergie'!D38 -> 0 | I30: ='Consommation mensuel énergie'!E38 -> 0
A31: Casablanca | B31: =B30+1 -> 30 | C31: 6 | D31: 2022 | E31: ='Consommation mensuel énergie'!L39 -> 0 | F31: ='Consommation mensuel énergie'!M39 -> 0 | G31: ='Consommation mensuel énergie'!N39 -> 0 | H31: ='Consommation mensuel énergie'!D39 -> 0 | I31: ='Consommation mensuel énergie'!E39 -> 0

Sheet Consommation mensuel énergie
I2: Consommation mensuel Eau /électricité/Gaz
B8: Date | D8: ROOM Nights | E8: Guests | F8: Cons Eau/Hotel | H8: Consommation du jour en DH | K8: date / électr | L8: ELECTRICITE en KWH | O8: total | Q8: Consommation du jour en DH | S8: Cons Elec/Villa | U8: Cons Elec/RIAD | V8: GAZ en Kg | X8: Consommation du jour en DH
L9: creuse 81 | M9: pleine 82 | N9: pointe 83
B10: 44713 | D10: 179 | E10: 253 | F10: ='Suivi EAU-ELEC'!E9 -> 267 | H10: =F10*8.79 -> 2346.93 | K10: 42278 | L10: ='Suivi EAU-ELEC'!G9 -> 4384 | M10: ='Suivi EAU-ELEC'!I9 -> 9147 | N10: ='Suivi EAU-ELEC'!K9 -> 3394 | O10: =L10+M10+N10 -> 16925 | Q10: =L10*0.6985+M10*0.9514+N10*1.3304 -> 16280.057 | V10: ='Suvi Gaz'!O4 -> 159.99605 | X10: =V10*13.14 -> 2102.3481
B11: 44714 | D11: 177 | E11: 263 | F11: ='Suivi EAU-ELEC'!E10 -> 165.3 | H11: =F11*8.79 -> 1452.987 | K11: 42279 | L11: ='Suivi EAU-ELEC'!G10 -> 4441 | M11: ='Suivi EAU-ELEC'!I10 -> 10256 | N11: ='Suivi EAU-ELEC'!K10 -> 3721 | O11: =L11+M11+N11 -> 18418 | Q11: =L11*0.6985+M11*0.9514+N14*1.3304 -> 18098.712 | V11: ='Suvi Gaz'!O5 -> 287.99289 | X11: =V11*13.14 -> 3784.2266
B12: 44715 | D12: 173 | E12: 289 | F12: ='Suivi EAU-ELEC'!E11 -> 158.9 | H12: =F12*8.79 -> 1396.731 | K12: 42280 | L12: ='Suivi EAU-ELEC'!G11 -> 3749 | M12: ='Suivi EAU-ELEC'!I11 -> 10529 | N12: ='Suivi EAU-ELEC'!K11 -> 3819 | O12: =L12+M12+N12 -> 18097 | Q12: =L12*0.6985+M12*0.9514+N12*1.3304 -> 17716.765 | V12: ='Suvi Gaz'!O6 -> 319.9921 | X12: =V12*13.14 -> 4204.6962
B13: 44716 | D13: 171 | E13: 289 | F13: ='Suivi EAU-ELEC'!E12 -> 157.8 | H13: =F13*8.79 -> 1387.062 | K13: 42281 | L13: ='Suivi EAU-ELEC'!G12 -> 4936 | M13: ='Suivi EAU-ELEC'!I12 -> 10072 | N13: ='Suivi EAU-ELEC'!K12 -> 3952 | O13: =L13+M13+N13 -> 18960 | Q13: =L13*0.6985+M13*0.9514+N13*1.3304 -> 18288.038 | V13: ='Suvi Gaz'!O7 -> 352.6567 | X13: =V13*13.14 -> 4633.909
B14: 44717 | D14: 146 | E14: 229 | F14: ='Suivi EAU-ELEC'!E13 -> 160 | H14: =F14*8.79 -> 1406.4 | K14: 42282 | L14: ='Suivi EAU-ELEC'!G13 -> 4461 | M14: ='Suivi EAU-ELEC'!I13 -> 10146 | N14: ='Suivi EAU-ELEC'!K13 -> 3938 | O14: =L14+M14+N14 -> 18545 | Q14: =L14*0.6985+M14*0.9514+N14*1.3304 -> 18008.028 | V14: ='Suvi Gaz'!O8 -> 287.99289 | X14: =V14*13.14 -> 3784.2266
B15: 44718 | D15: 134 | E15: 208 | F15: ='Suivi EAU-ELEC'!E14 -> 145 | H15: =F15*8.79 -> 1274.55 | K15: 42283 | L15: ='Suivi EAU-ELEC'!G14 -> 4437 | M15: ='Suivi EAU-ELEC'!I14 -> 9912 | N15: ='Suivi EAU-ELEC'!K14 -> 3710 | O15: =L15+M15+N15 -> 18059 | Q15: =L15*0.6985+M15*0.9514+N15*1.3304 -> 17465.305 | V15: ='Suvi Gaz'!O9 -> 127.99684 | X15: =V15*13.14 -> 1681.8785
B16: 44719 | D16: 134 | E16: 201 | F16: ='Suivi EAU-ELEC'!E15 -> 155 | H16: =F16*8.79 -> 1362.45 | K16: 42284 | L16: ='Suivi EAU-ELEC'!G15 -> 4900 | M16: ='Suivi EAU-ELEC'!I15 -> 10384 | N16: ='Suivi EAU-ELEC'!K15 -> 4539 | O16: =L16+M16+N16 -> 19823 | Q16: =L16*0.6985+M16*0.9514+N16*1.3304 -> 19340.673 | V16: ='Suvi Gaz'!O10 -> 351.99131 | X16: =V16*13.14 -> 4625.1658
B17: 44720 | D17: 147 | E17: 205 | F17: ='Suivi EAU-ELEC'!E16 -> 139 | H17: =F17*8.79 -> 1221.81 | K17: 42285 | L17: ='Suivi EAU-ELEC'!G16 -> 5117 | M17: ='Suivi EAU-ELEC'!I16 -> 10773 | N17: ='Suivi EAU-ELEC'!K16 -> 4172 | O17: =L17+M17+N17 -> 20062 | Q17: =L17*0.6985+M17*0.9514+N17*1.3304 -> 19374.086 | V17: ='Suvi Gaz'!O11 -> 223.99447 | X17: =V17*13.14 -> 2943.2873
B18: 44721 | D18: 138 | E18: 200 | F18: ='Suivi EAU-ELEC'!E17 -> 135 | H18: =F18*8.79 -> 1186.65 | K18: 42286 | L18: ='Suivi EAU-ELEC'!G17 -> 5025 | M18: ='Suivi EAU-ELEC'!I17 -> 10593 | N18: ='Suivi EAU-ELEC'!K17 -> 4219 | O18: =L18+M18+N18 -> 19837 | Q18: =L18*0.6985+M18*0.9514+N18*1.3304 -> 19201.1 | V18: ='Suvi Gaz'!O12 -> 287.99289 | X18: =V18*13.14 -> 3784.2266
B19: 44722 | D19: 120 | E19: 175 | F19: ='Suivi EAU-ELEC'!E18 -> 175.3 | H19: =F19*8.79 -> 1540.887 | K19: 42287 | L19: ='Suivi EAU-ELEC'!G18 -> 4793 | M19: ='Suivi EAU-ELEC'!I18 -> 10865 | N19: ='Suivi EAU-ELEC'!K18 -> 3986 | O19: =L19+M19+N19 -> 19644 | Q19: =L19*0.6985+M19*0.9514+N19*1.3304 -> 18987.846 | V19: ='Suvi Gaz'!O13 -> 383.99052 | X19: =V19*13.14 -> 5045.6354
B20: 44723 | D20: 173 | E20: 223 | F20: ='Suivi EAU-ELEC'!E19 -> 170.6 | H20: =F20*8.79 -> 1499.574 | K20: 42288 | L20: ='Suivi EAU-ELEC'!G19 -> 5146 | M20: ='Suivi EAU-ELEC'!I19 -> 10605 | N20: ='Suivi EAU-ELEC'!K19 -> 4231 | O20: =L20+M20+N20 -> 19982 | Q20: =L20*0.6985+M20*0.9514+N20*1.3304 -> 19313 | V20: ='Suvi Gaz'!O14 -> 415.98973 | X20: =V20*13.14 -> 5466.1051
B21: 44724 | D21: 183 | E21: 237 | F21: ='Suivi EAU-ELEC'!E20 -> 163.1 | H21: =F21*8.79 -> 1433.649 | K21: 42289 | L21: ='Suivi EAU-ELEC'!G20 -> 5362 | M21: ='Suivi EAU-ELEC'!I20 -> 11461 | N21: ='Suivi EAU-ELEC'!K20 -> 4511 | O21: =L21+M21+N21 -> 21334 | Q21: =L21*0.6985+M21*0.9514+N21*1.3304 -> 20650.787 | V21: ='Suvi Gaz'!O15 -> 159.99605 | X21: =V21*13.14 -> 2102.3481
B22: 44725 | D22: 181 | E22: 226 | F22: ='Suivi EAU-ELEC'!E21 -> 151 | H22: =F22*8.79 -> 1327.29 | K22: 42290 | L22: ='Suivi EAU-ELEC'!G21 -> 4871 | M22: ='Suivi EAU-ELEC'!I21 -> 12046 | N22: ='Suivi EAU-ELEC'!K21 -> 4428 | O22: =L22+M22+N22 -> 21345 | Q22: =L22*0.6985+M22*0.9514+N22*1.3304 -> 20753.969 | V22: ='Suvi Gaz'!O16 -> 95.99763 | X22: =V22*13.14 -> 1261.4089
B23: 44726 | D23: 141 | E23: 189 | F23: ='Suivi EAU-ELEC'!E22 -> 149.1 | H23: =F23*8.79 -> 1310.589 | K23: 42291 | L23: ='Suivi EAU-ELEC'!G22 -> 4707 | M23: ='Suivi EAU-ELEC'!I22 -> 11903 | N23: ='Suivi EAU-ELEC'!K22 -> 4890 | O23: =L23+M23+N23 -> 21500 | Q23: =L23*0.6985+M23*0.9514+N23*1.3304 -> 21118.01 | V23: ='Suvi Gaz'!O17 -> 287.99289 | X23: =V23*13.14 -> 3784.2266
... B35: 44738 | D35: 143 | E35: 224 | F35: ='Suivi EAU-ELEC'!E34 -> 176 | H35: =F35*8.79 -> 1547.04 | K35: 42303 | L35: ='Suivi EAU-ELEC'!G34 -> 4644 | M35: ='Suivi EAU-ELEC'!I34 -> 9126 | N35: ='Suivi EAU-ELEC'!K34 -> 3594 | O35: =L35+M35+N35 -> 17364 | Q35: =L35*0.6985+M35*0.9514+N35*1.3304 -> 16707.768 | V35: ='Suvi Gaz'!O29 -> 127.99684 | X35: =V35*13.14 -> 1681.8785
B36: 44739 | F36: ='Suivi EAU-ELEC'!E35 -> 180 | H36: =F36*8.79 -> 1582.2 | L36: ='Suivi EAU-ELEC'!G35 -> 4085 | M36: ='Suivi EAU-ELEC'!I35 -> 8349 | N36: ='Suivi EAU-ELEC'!K35 -> 3459 | O36: =L36+M36+N36 -> 15893 | Q36: =L36*0.6985+M36*0.9514+N36*1.3304 -> 15398.465 | X36: =V36*13.14 -> 0
B37: 44740 | H37: =F37*8.79 -> 0 | O37: =L37+M37+N37 -> 0 | Q37: =L37*0.6985+M37*0.9514+N37*1.3304 -> 0 | X37: =V37*13.14 -> 0
B38: 44741 | H38: =F38*8.79 -> 0 | K38: 42304 | O38: =L38+M38+N38 -> 0 | Q38: =L38*0.6985+M38*0.9514+N38*1.3304 -> 0 | X38: =V38*13.14 -> 0
B39: 44742 | H39: =F39*8.79 -> 0 | O39: =L39+M39+N39 -> 0 | Q39: =L39*0.6985+M39*0.9514+N39*1.3304 -> 0 | X39: =V39*13.14 -> 0
D40: =SUM(D10:D39) -> 4077 | E40: =SUM(E10:E39) -> 6043 | F40: =SUM(F10:F39) -> 4569 | H40: =SUM(H10:H39) -> 40161.51 | L40: =SUM(L10:L39) -> 130417 | M40: =SUM(M10:M39) -> 274229 | N40: =SUM(N10:N39) -> 108708 | O40: =SUM(O10:O39) -> 513354 | Q40: =L40*0.6985+M40*0.9514+N40*1.3304 -> 496622.87 | S40: =SUM(S10:S39) -> 0 | U40: =SUM(U10:U39) -> 0 | V40: =SUM(V10:V39) -> 6944.494 | X40: =SUM(X10:X39) -> 91250.651
A42: Désignation | H42: COUTS | I42: Consommations | L42: Consommations /DHs | N42: TOTAL Consommations /DHs
A43: ELECTRICITE / Kw/h | D43: creuse 81 | E43: creuse 81 | F43: creuse 81 | H43: 0.6985 | I43: =L40 -> 130417 | L43: =I43*H43 -> 91096.274 | N43: =L43+L44+L45 -> 496622.87
D44: pleine 82 | E44: pleine 82 | F44: pleine 82 | H44: 0.9514 | I44: =M40 -> 274229 | L44: =I44*H44 -> 260901.47
D45: pointe 83 | E45: pointe 83 | F45: pointe 83 | H45: 1.3304 | I45: =N40 -> 108708 | L45: =I45*H45 -> 144625.12
N46: =N43*1.3 -> 645609.73
A47: EAU HOTEL M3 | H47: 8.79 | I47: =F40 -> 4569 | L47: =I47*H47 -> 40161.51 | N47: =L47 -> 40161.51
A48: GAZ Kg | H48: 13.14 | I48: =V40 -> 6944.494 | L48: =I48*H48 -> 91250.651 | N48: =L48 -> 91250.651

Sheet Suivi EAU-ELEC
E1: Suivi Compteur d'Eau- électricité Lydec- JUIN 2022 | J1: Département Engineering 2022
A7: Date/électriqie | B7: Incendie | D7: Eau m3 | F7: Electricité Kw/h
B8: Compteur | C8: Consommation | D8: Compteur | E8: Consommation | F8: Compteur H.Creuse | G8: Consommation H.Creuse | H8: Compteur H.Pleine | I8: Consommation H.Pleine | J8: Compteur H.Pointe | K8: Consommation H.Pointe
A9: 44713 | B9: 2560 | C9: 0 | D9: 148296 | E9: 267 | F9: 11843664 | G9: 4384 | H9: 20106843 | I9: 9147 | J9: 8829353 | K9: 3394
A10: 44714 | B10: 2560 | C10: =B10-B9 -> 0 | D10: 148461.3 | E10: =D10-D9 -> 165.3 | F10: 11848105 | G10: =F10-F9 -> 4441 | H10: 20117099 | I10: =H10-H9 -> 10256 | J10: 8833074 | K10: =J10-J9 -> 3721
A11: 44715 | B11: 2560 | C11: =B11-B10 -> 0 | D11: 148620.2 | E11: =D11-D10 -> 158.9 | F11: 11851854 | G11: =F11-F10 -> 3749 | H11: 20127628 | I11: =H11-H10 -> 10529 | J11: 8836893 | K11: =J11-J10 -> 3819
A12: 44716 | B12: 2560 | C12: =B12-B11 -> 0 | D12: 148778 | E12: =D12-D11 -> 157.8 | F12: 11856790 | G12: =F12-F11 -> 4936 | H12: 20137700 | I12: =H12-H11 -> 10072 | J12: 8840845 | K12: =J12-J11 -> 3952
A13: 44717 | B13: 2560 | C13: =B13-B12 -> 0 | D13: 148938 | E13: =D13-D12 -> 160 | F13: 11861251 | G13: =F13-F12 -> 4461 | H13: 20147846 | I13: =H13-H12 -> 10146 | J13: 8844783 | K13: =J13-J12 -> 3938
A14: 44718 | B14: 2560 | C14: =B14-B13 -> 0 | D14: 149083 | E14: =D14-D13 -> 145 | F14: 11865688 | G14: =F14-F13 -> 4437 | H14: 20157758 | I14: =H14-H13 -> 9912 | J14: 8848493 | K14: =J14-J13 -> 3710
A15: 44719 | B15: 2560 | C15: =B15-B14 -> 0 | D15: 149238 | E15: =D15-D14 -> 155 | F15: 11870588 | G15: =F15-F14 -> 4900 | H15: 20168142 | I15: =H15-H14 -> 10384 | J15: 8853032 | K15: =J15-J14 -> 4539
A16: 44720 | B16: 2560 | C16: =B16-B15 -> 0 | D16: 149377 | E16: =D16-D15 -> 139 | F16: 11875705 | G16: =F16-F15 -> 5117 | H16: 20178915 | I16: =H16-H15 -> 10773 | J16: 8857204 | K16: =J16-J15 -> 4172
A17: 44721 | B17: 2560 | C17: =B17-B16 -> 0 | D17: 149512 | E17: =D17-D16 -> 135 | F17: 11880730 | G17: =F17-F16 -> 5025 | H17: 20189508 | I17: =H17-H16 -> 10593 | J17: 8861423 | K17: =J17-J16 -> 4219
A18: 44722 | B18: 2560 | C18: =B18-B17 -> 0 | D18: 149687.3 | E18: =D18-D17 -> 175.3 | F18: 11885523 | G18: =F18-F17 -> 4793 | H18: 20200373 | I18: =H18-H17 -> 10865 | J18: 8865409 | K18: =J18-J17 -> 3986
A19: 44723 | B19: 2560 | C19: =B19-B18 -> 0 | D19: 149857.9 | E19: =D19-D18 -> 170.6 | F19: 11890669 | G19: =F19-F18 -> 5146 | H19: 20210978 | I19: =H19-H18 -> 10605 | J19: 8869640 | K19: =J19-J18 -> 4231
A20: 44724 | B20: 2560 | C20: =B20-B19 -> 0 | D20: 150021 | E20: =D20-D19 -> 163.1 | F20: 11896031 | G20: =F20-F19 -> 5362 | H20: 20222439 | I20: =H20-H19 -> 11461 | J20: 8874151 | K20: =J20-J19 -> 4511
A21: 44725 | B21: 2560 | C21: =B21-B20 -> 0 | D21: 150172 | E21: =D21-D20 -> 151 | F21: 11900902 | G21: =F21-F20 -> 4871 | H21: 20234485 | I21: =H21-H20 -> 12046 | J21: 8878579 | K21: =J21-J20 -> 4428
... A35: 44739 | B35: 2560 | C35: =B35-B34 -> 0 | D35: 152598 | E35: =D35-D34 -> 180 | F35: 11969697 | G35: =F35-F34 -> 4085 | H35: 20371925 | I35: =H35-H34 -> 8349 | J35: 8934667 | K35: =J35-J34 -> 3459
A36: 44740
A37: 44741
A38: 44742
A39: 44743
A40: 44744

Sheet Suvi Gaz
F1: suivi Gaz juin 2022
Q2: 803 | T2: 519 | W2: 800 | Z2: 802
B3: Relvé C1 | C3: cons C1 | D3: Relvé C2 | E3: cons C2 | F3: Relvé C3 | G3: cons C3 | H3: Relvé C4 | I3: cons C4 | J3: ∑ des relevés | K3: moyen general % | L3: con.j | M3: ∑ de volume en L | N3: cons./jen L | O3: cons./jen Kg | P3: cons./jen DH | Q3: livraison C1 | R3: %Avant | S3: % Après | T3: livraison C2 | U3: %Avant | V3: % Après | W3: livraison C3 | X3: %Avant | Y3: % Après | Z3: livraison C4 | AA3: %Avant | AB3: % Après | AC3: total livraison litre | AD3: moyen general % Avant L | AE3: moyen general % Aaprés L
A4: 44713 | B4: 84 | C4: =IF(AC4>0,((B4-R4)+(S4-B5)),IF(B5=0, ,(B4-B5))) -> 3 | D4: 85 | E4: =IF(AC4>0,((D4-U4)+(V4-D5)),IF(D5=0, ,(D4-D5))) -> 2 | F4: 85 | G4: =IF(AC4>0,((F4-X4)+(Y4-F5)),IF(F5=0, ,(F4-F5))) -> 0 | H4: 85 | I4: =IF(AC4>0,((H4-AA4)+(AB4-H5)),IF(H5=0, ,(H4-H5))) -> 0 | J4: =B4+D4+F4+H4 -> 339 | K4: =J4/4 -> 84.75 | L4: =IF(AC4>0,((K4-AD4)+(AE4-K5)),IF(K5=0, ,(K4-K5))) -> 1.25 | M4: =6049*4 -> 24196 | N4: =L4*M4/100 -> 302.45 | O4: =N4*0.529 -> 159.99605 | P4: =O4*13.14 -> 2102.3481 | AC4: =Q4+T4+W4+Z4 -> 0 | AD4: =(R4+U4+X4+AA4)/4 -> 0 | AE4: =(S4+V4+Y4+AB4)/4 -> 0
A5: 44714 | B5: 81 | C5: =IF(AC5>0,((B5-R5)+(S5-B6)),IF(B6=0, ,(B5-B6))) -> 2 | D5: 83 | E5: =IF(AC5>0,((D5-U5)+(V5-D6)),IF(D6=0, ,(D5-D6))) -> 3 | F5: 85 | G5: =IF(AC5>0,((F5-X5)+(Y5-F6)),IF(F6=0, ,(F5-F6))) -> 2 | H5: 85 | I5: =IF(AC5>0,((H5-AA5)+(AB5-H6)),IF(H6=0, ,(H5-H6))) -> 2 | J5: =B5+D5+F5+H5 -> 334 | K5: =J5/4 -> 83.5 | L5: =IF(AC5>0,((K5-AD5)+(AE5-K6)),IF(K6=0, ,(K5-K6))) -> 2.25 | M5: =6049*4 -> 24196 | N5: =L5*M5/100 -> 544.41 | O5: =N5*0.529 -> 287.99289 | P5: =O5*13.14 -> 3784.2266 | AC5: =Q5+T5+W5+Z5 -> 0 | AD5: =(R5+U5+X5+AA5)/4 -> 0 | AE5: =(S5+V5+Y5+AB5)/4 -> 0
A6: 44715 | B6: 79 | C6: =IF(AC6>0,((B6-R6)+(S6-B7)),IF(B7=0, ,(B6-B7))) -> 3 | D6: 80 | E6: =IF(AC6>0,((D6-U6)+(V6-D7)),IF(D7=0, ,(D6-D7))) -> 1 | F6: 83 | G6: =IF(AC6>0,((F6-X6)+(Y6-F7)),IF(F7=0, ,(F6-F7))) -> 3 | H6: 83 | I6: =IF(AC6>0,((H6-AA6)+(AB6-H7)),IF(H7=0, ,(H6-H7))) -> 3 | J6: =B6+D6+F6+H6 -> 325 | K6: =J6/4 -> 81.25 | L6: =IF(AC6>0,((K6-AD6)+(AE6-K7)),IF(K7=0, ,(K6-K7))) -> 2.5 | M6: =6049*4 -> 24196 | N6: =L6*M6/100 -> 604.9 | O6: =N6*0.529 -> 319.9921 | P6: =O6*13.14 -> 4204.6962 | AC6: =Q6+T6+W6+Z6 -> 0 | AD6: =(R6+U6+X6+AA6)/4 -> 0 | AE6: =(S6+V6+Y6+AB6)/4 -> 0
A7: 44716 | B7: 76 | C7: =IF(AC7>0,((B7-R7)+(S7-B8)),IF(B8=0, ,(B7-B8))) -> 4 | D7: 79 | E7: =IF(AC7>0,((D7-U7)+(V7-D8)),IF(D8=0, ,(D7-D8))) -> 1 | F7: 80 | G7: =IF(AC7>0,((F7-X7)+(Y7-F8)),IF(F8=0, ,(F7-F8))) -> 3 | H7: 80 | I7: =IF(AC7>0,((H7-AA7)+(AB7-H8)),IF(H8=0, ,(H7-H8))) -> 3 | J7: =B7+D7+F7+H7 -> 315 | K7: =J7/4 -> 78.75 | L7: =IF(AC7>0,((K7-AD7)+(AE7-K8)),IF(K8=0, ,(K7-K8))) -> 2.75 | M7: =6049*4 -> 24196 | N7: =L7*M7/100 -> 665.39 | O7: =N7*0.53 -> 352.6567 | P7: =O7*13.14 -> 4633.909 | AC7: =Q7+T7+W7+Z7 -> 0 | AD7: =(R7+U7+X7+AA7)/4 -> 0 | AE7: =(S7+V7+Y7+AB7)/4 -> 0
A8: 44717 | B8: 72 | C8: =IF(AC8>0,((B8-R8)+(S8-B9)),IF(B9=0, ,(B8-B9))) -> 1 | D8: 78 | E8: =IF(AC8>0,((D8-U8)+(V8-D9)),IF(D9=0, ,(D8-D9))) -> 4 | F8: 77 | G8: =IF(AC8>0,((F8-X8)+(Y8-F9)),IF(F9=0, ,(F8-F9))) -> 2 | H8: 77 | I8: =IF(AC8>0,((H8-AA8)+(AB8-H9)),IF(H9=0, ,(H8-H9))) -> 2 | J8: =B8+D8+F8+H8 -> 304 | K8: =J8/4 -> 76 | L8: =IF(AC8>0,((K8-AD8)+(AE8-K9)),IF(K9=0, ,(K8-K9))) -> 2.25 | M8: =6049*4 -> 24196 | N8: =L8*M8/100 -> 544.41 | O8: =N8*0.529 -> 287.99289 | P8: =O8*13.14 -> 3784.2266 | AC8: =Q8+T8+W8+Z8 -> 0 | AD8: =(R8+U8+X8+AA8)/4 -> 0 | AE8: =(S8+V8+Y8+AB8)/4 -> 0
A9: 44718 | B9: 71 | C9: =IF(AC9>0,((B9-R9)+(S9-B10)),IF(B10=0, ,(B9-B10))) -> 1 | D9: 74 | E9: =IF(AC9>0,((D9-U9)+(V9-D10)),IF(D10=0, ,(D9-D10))) -> 3 | F9: 75 | G9: =IF(AC9>0,((F9-X9)+(Y9-F10)),IF(F10=0, ,(F9-F10))) -> 0 | H9: 75 | I9: =IF(AC9>0,((H9-AA9)+(AB9-H10)),IF(H10=0, ,(H9-H10))) -> 0 | J9: =B9+D9+F9+H9 -> 295 | K9: =J9/4 -> 73.75 | L9: =IF(AC9>0,((K9-AD9)+(AE9-K10)),IF(K10=0, ,(K9-K10))) -> 1 | M9: =6049*4 -> 24196 | N9: =L9*M9/100 -> 241.96 | O9: =N9*0.529 -> 127.99684 | P9: =O9*13.14 -> 1681.8785 | AC9: =Q9+T9+W9+Z9 -> 0 | AD9: =(R9+U9+X9+AA9)/4 -> 0 | AE9: =(S9+V9+Y9+AB9)/4 -> 0
A10: 44719 | B10: 70 | C10: =IF(AC10>0,((B10-R10)+(S10-B11)),IF(B11=0, ,(B10-B11))) -> 4 | D10: 71 | E10: =IF(AC10>0,((D10-U10)+(V10-D11)),IF(D11=0, ,(D10-D11))) -> 1 | F10: 75 | G10: =IF(AC10>0,((F10-X10)+(Y10-F11)),IF(F11=0, ,(F10-F11))) -> 3 | H10: 75 | I10: =IF(AC10>0,((H10-AA10)+(AB10-H11)),IF(H11=0, ,(H10-H11))) -> 3 | J10: =B10+D10+F10+H10 -> 291 | K10: =J10/4 -> 72.75 | L10: =IF(AC10>0,((K10-AD10)+(AE10-K11)),IF(K11=0, ,(K10-K11))) -> 2.75 | M10: =6049*4 -> 24196 | N10: =L10*M10/100 -> 665.39 | O10: =N10*0.529 -> 351.99131 | P10: =O10*13.14 -> 4625.1658 | AC10: =Q10+T10+W10+Z10 -> 0 | AD10: =(R10+U10+X10+AA10)/4 -> 0 | AE10: =(S10+V10+Y10+AB10)/4 -> 0
A11: 44720 | B11: 66 | C11: =IF(AC11>0,((B11-R11)+(S11-B12)),IF(B12=0, ,(B11-B12))) -> 1 | D11: 70 | E11: =IF(AC11>0,((D11-U11)+(V11-D12)),IF(D12=0, ,(D11-D12))) -> 2 | F11: 72 | G11: =IF(AC11>0,((F11-X11)+(Y11-F12)),IF(F12=0, ,(F11-F12))) -> 2 | H11: 72 | I11: =IF(AC11>0,((H11-AA11)+(AB11-H12)),IF(H12=0, ,(H11-H12))) -> 2 | J11: =B11+D11+F11+H11 -> 280 | K11: =J11/4 -> 70 | L11: =IF(AC11>0,((K11-AD11)+(AE11-K12)),IF(K12=0, ,(K11-K12))) -> 1.75 | M11: =6049*4 -> 24196 | N11: =L11*M11/100 -> 423.43 | O11: =N11*0.529 -> 223.99447 | P11: =O11*13.14 -> 2943.2873 | AC11: =Q11+T11+W11+Z11 -> 0 | AD11: =(R11+U11+X11+AA11)/4 -> 0 | AE11: =(S11+V11+Y11+AB11)/4 -> 0
A12: 44721 | B12: 65 | C12: =IF(AC12>0,((B12-R12)+(S12-B13)),IF(B13=0, ,(B12-B13))) -> 2 | D12: 68 | E12: =IF(AC12>0,((D12-U12)+(V12-D13)),IF(D13=0, ,(D12-D13))) -> 3 | F12: 70 | G12: =IF(AC12>0,((F12-X12)+(Y12-F13)),IF(F13=0, ,(F12-F13))) -> 2 | H12: 70 | I12: =IF(AC12>0,((H12-AA12)+(AB12-H13)),IF(H13=0, ,(H12-H13))) -> 2 | J12: =B12+D12+F12+H12 -> 273 | K12: =J12/4 -> 68.25 | L12: =IF(AC12>0,((K12-AD12)+(AE12-K13)),IF(K13=0, ,(K12-K13))) -> 2.25 | M12: =6049*4 -> 24196 | N12: =L12*M12/100 -> 544.41 | O12: =N12*0.529 -> 287.99289 | P12: =O12*13.14 -> 3784.2266 | AC12: =Q12+T12+W12+Z12 -> 0 | AD12: =(R12+U12+X12+AA12)/4 -> 0 | AE12: =(S12+V12+Y12+AB12)/4 -> 0
A13: 44722 | B13: 63 | C13: =IF(AC13>0,((B13-R13)+(S13-B14)),IF(B14=0, ,(B13-B14))) -> 3 | D13: 65 | E13: =IF(AC13>0,((D13-U13)+(V13-D14)),IF(D14=0, ,(D13-D14))) -> 3 | F13: 68 | G13: =IF(AC13>0,((F13-X13)+(Y13-F14)),IF(F14=0, ,(F13-F14))) -> 3 | H13: 68 | I13: =IF(AC13>0,((H13-AA13)+(AB13-H14)),IF(H14=0, ,(H13-H14))) -> 3 | J13: =B13+D13+F13+H13 -> 264 | K13: =J13/4 -> 66 | L13: =IF(AC13>0,((K13-AD13)+(AE13-K14)),IF(K14=0, ,(K13-K14))) -> 3 | M13: =6049*4 -> 24196 | N13: =L13*M13/100 -> 725.88 | O13: =N13*0.529 -> 383.99052 | P13: =O13*13.14 -> 5045.6354 | AC13: =Q13+T13+W13+Z13 -> 0 | AD13: =(R13+U13+X13+AA13)/4 -> 0 | AE13: =(S13+V13+Y13+AB13)/4 -> 0
A14: 44723 | B14: 60 | C14: =IF(AC14>0,((B14-R14)+(S14-B15)),IF(B15=0, ,(B14-B15))) -> 4 | D14: 62 | E14: =IF(AC14>0,((D14-U14)+(V14-D15)),IF(D15=0, ,(D14-D15))) -> 5 | F14: 65 | G14: =IF(AC14>0,((F14-X14)+(Y14-F15)),IF(F15=0, ,(F14-F15))) -> 2 | H14: 65 | I14: =IF(AC14>0,((H14-AA14)+(AB14-H15)),IF(H15=0, ,(H14-H15))) -> 2 | J14: =B14+D14+F14+H14 -> 252 | K14: =J14/4 -> 63 | L14: =IF(AC14>0,((K14-AD14)+(AE14-K15)),IF(K15=0, ,(K14-K15))) -> 3.25 | M14: =6049*4 -> 24196 | N14: =L14*M14/100 -> 786.37 | O14: =N14*0.529 -> 415.98973 | P14: =O14*13.14 -> 5466.1051 | Q14: 2136 | R14: 56 | S14: 85 | T14: 2110 | U14: 57 | V14: 85 | W14: 1776 | X14: 63 | Y14: 85 | Z14: 1751 | AA14: 63 | AB14: 85 | AC14: =Q14+T14+W14+Z14 -> 7773 | AD14: =(R14+U14+X14+AA14)/4 -> 59.75 | AE14: =(S14+V14+Y14+AB14)/4 -> 85
A15: 44724 | B15: 85 | C15: =IF(AC15>0,((B15-R15)+(S15-B16)),IF(B16=0, ,(B15-B16))) -> 2 | D15: 85 | E15: =IF(AC15>0,((D15-U15)+(V15-D16)),IF(D16=0, ,(D15-D16))) -> 3 | F15: 85 | G15: =IF(AC15>0,((F15-X15)+(Y15-F16)),IF(F16=0, ,(F15-F16))) -> 0 | H15: 85 | I15: =IF(AC15>0,((H15-AA15)+(AB15-H16)),IF(H16=0, ,(H15-H16))) -> 0 | J15: =B15+D15+F15+H15 -> 340 | K15: =J15/4 -> 85 | L15: =IF(AC15>0,((K15-AD15)+(AE15-K16)),IF(K16=0, ,(K15-K16))) -> 1.25 | M15: =6049*4 -> 24196 | N15: =L15*M15/100 -> 302.45 | O15: =N15*0.529 -> 159.99605 | P15: =O15*13.14 -> 2102.3481 | AC15: =Q15+T15+W15+Z15 -> 0 | AD15: =(R15+U15+X15+AA15)/4 -> 0 | AE15: =(S15+V15+Y15+AB15)/4 -> 0
A16: 44725 | B16: 83 | C16: =IF(AC16>0,((B16-R16)+(S16-B17)),IF(B17=0, ,(B16-B17))) -> 0 | D16: 82 | E16: =IF(AC16>0,((D16-U16)+(V16-D17)),IF(D17=0, ,(D16-D17))) -> 2 | F16: 85 | G16: =IF(AC16>0,((F16-X16)+(Y16-F17)),IF(F17=0, ,(F16-F17))) -> 0 | H16: 85 | I16: =IF(AC16>0,((H16-AA16)+(AB16-H17)),IF(H17=0, ,(H16-H17))) -> 1 | J16: =B16+D16+F16+H16 -> 335 | K16: =J16/4 -> 83.75 | L16: =IF(AC16>0,((K16-AD16)+(AE16-K17)),IF(K17=0, ,(K16-K17))) -> 0.75 | M16: =6049*4 -> 24196 | N16: =L16*M16/100 -> 181.47 | O16: =N16*0.529 -> 95.99763 | P16: =O16*13.14 -> 1261.4089 | AC16: =Q16+T16+W16+Z16 -> 0 | AD16: =(R16+U16+X16+AA16)/4 -> 0 | AE16: =(S16+V16+Y16+AB16)/4 -> 0
A17: 44726 | B17: 83 | C17: =IF(AC17>0,((B17-R17)+(S17-B18)),IF(B18=0, ,(B17-B18))) -> 2 | D17: 80 | E17: =IF(AC17>0,((D17-U17)+(V17-D18)),IF(D18=0, ,(D17-D18))) -> 0 | F17: 85 | G17: =IF(AC17>0,((F17-X17)+(Y17-F18)),IF(F18=0, ,(F17-F18))) -> 4 | H17: 84 | I17: =IF(AC17>0,((H17-AA17)+(AB17-H18)),IF(H18=0, ,(H17-H18))) -> 3 | J17: =B17+D17+F17+H17 -> 332 | K17: =J17/4 -> 83 | L17: =IF(AC17>0,((K17-AD17)+(AE17-K18)),IF(K18=0, ,(K17-K18))) -> 2.25 | M17: =6049*4 -> 24196 | N17: =L17*M17/100 -> 544.41 | O17: =N17*0.529 -> 287.99289 | P17: =O17*13.14 -> 3784.2266 | AC17: =Q17+T17+W17+Z17 -> 0 | AD17: =(R17+U17+X17+AA17)/4 -> 0 | AE17: =(S17+V17+Y17+AB17)/4 -> 0
A18: 44727 | B18: 81 | C18: =IF(AC18>0,((B18-R18)+(S18-B19)),IF(B19=0, ,(B18-B19))) -> 1 | D18: 80 | E18: =IF(AC18>0,((D18-U18)+(V18-D19)),IF(D19=0, ,(D18-D19))) -> 2 | F18: 81 | G18: =IF(AC18>0,((F18-X18)+(Y18-F19)),IF(F19=0, ,(F18-F19))) -> 1 | H18: 81 | I18: =IF(AC18>0,((H18-AA18)+(AB18-H19)),IF(H19=0, ,(H18-H19))) -> 1 | J18: =B18+D18+F18+H18 -> 323 | K18: =J18/4 -> 80.75 | L18: =IF(AC18>0,((K18-AD18)+(AE18-K19)),IF(K19=0, ,(K18-K19))) -> 1.25 | M18: =6049*4 -> 24196 | N18: =L18*M18/100 -> 302.45 | O18: =N18*0.529 -> 159.99605 | P18: =O18*13.14 -> 2102.3481 | AC18: =Q18+T18+W18+Z18 -> 0 | AD18: =(R18+U18+X18+AA18)/4 -> 0 | AE18: =(S18+V18+Y18+AB18)/4 -> 0
A19: 44728 | B19: 80 | C19: =IF(AC19>0,((B19-R19)+(S19-B20)),IF(B20=0, ,(B19-B20))) -> 2 | D19: 78 | E19: =IF(AC19>0,((D19-U19)+(V19-D20)),IF(D20=0, ,(D19-D20))) -> 2 | F19: 80 | G19: =IF(AC19>0,((F19-X19)+(Y19-F20)),IF(F20=0, ,(F19-F20))) -> 2 | H19: 80 | I19: =IF(AC19>0,((H19-AA19)+(AB19-H20)),IF(H20=0, ,(H19-H20))) -> 2 | J19: =B19+D19+F19+H19 -> 318 | K19: =J19/4 -> 79.5 | L19: =IF(AC19>0,((K19-AD19)+(AE19-K20)),IF(K20=0, ,(K19-K20))) -> 2 | M19: =6049*4 -> 24196 | N19: =L19*M19/100 -> 483.92 | O19: =N19*0.529 -> 255.99368 | P19: =O19*13.14 -> 3363.757 | AC19: =Q19+T19+W19+Z19 -> 0 | AD19: =(R19+U19+X19+AA19)/4 -> 0 | AE19: =(S19+V19+Y19+AB19)/4 -> 0
A20: 44729 | B20: 78 | C20: =IF(AC20>0,((B20-R20)+(S20-B21)),IF(B21=0, ,(B20-B21))) -> 3 | D20: 76 | E20: =IF(AC20>0,((D20-U20)+(V20-D21)),IF(D21=0, ,(D20-D21))) -> 3 | F20: 78 | G20: =IF(AC20>0,((F20-X20)+(Y20-F21)),IF(F21=0, ,(F20-F21))) -> 3 | H20: 78 | I20: =IF(AC20>0,((H20-AA20)+(AB20-H21)),IF(H21=0, ,(H20-H21))) -> 2 | J20: =B20+D20+F20+H20 -> 310 | K20: =J20/4 -> 77.5 | L20: =IF(AC20>0,((K20-AD20)+(AE20-K21)),IF(K21=0, ,(K20-K21))) -> 2.75 | M20: =6049*4 -> 24196 | N20: =L20*M20/100 -> 665.39 | O20: =N20*0.529 -> 351.99131 | P20: =O20*13.14 -> 4625.1658 | AC20: =Q20+T20+W20+Z20 -> 0 | AD20: =(R20+U20+X20+AA20)/4 -> 0 | AE20: =(S20+V20+Y20+AB20)/4 -> 0
A21: 44730 | B21: 75 | C21: =IF(AC21>0,((B21-R21)+(S21-B22)),IF(B22=0, ,(B21-B22))) -> 3 | D21: 73 | E21: =IF(AC21>0,((D21-U21)+(V21-D22)),IF(D22=0, ,(D21-D22))) -> 3 | F21: 75 | G21: =IF(AC21>0,((F21-X21)+(Y21-F22)),IF(F22=0, ,(F21-F22))) -> 0 | H21: 76 | I21: =IF(AC21>0,((H21-AA21)+(AB21-H22)),IF(H22=0, ,(H21-H22))) -> 1 | J21: =B21+D21+F21+H21 -> 299 | K21: =J21/4 -> 74.75 | L21: =IF(AC21>0,((K21-AD21)+(AE21-K22)),IF(K22=0, ,(K21-K22))) -> 1.75 | M21: =6049*4 -> 24196 | N21: =L21*M21/100 -> 423.43 | O21: =N21*0.529 -> 223.99447 | P21: =O21*13.14 -> 2943.2873 | AC21: =Q21+T21+W21+Z21 -> 0 | AD21: =(R21+U21+X21+AA21)/4 -> 0 | AE21: =(S21+V21+Y21+AB21)/4 -> 0
A22: 44731 | B22: 72 | C22: =IF(AC22>0,((B22-R22)+(S22-B23)),IF(B23=0, ,(B22-B23))) -> 2 | D22: 70 | E22: =IF(AC22>0,((D22-U22)+(V22-D23)),IF(D23=0, ,(D22-D23))) -> 1 | F22: 75 | G22: =IF(AC22>0,((F22-X22)+(Y22-F23)),IF(F23=0, ,(F22-F23))) -> 5 | H22: 75 | I22: =IF(AC22>0,((H22-AA22)+(AB22-H23)),IF(H23=0, ,(H22-H23))) -> 5 | J22: =B22+D22+F22+H22 -> 292 | K22: =J22/4 -> 73 | L22: =IF(AC22>0,((K22-AD22)+(AE22-K23)),IF(K23=0, ,(K22-K23))) -> 3.25 | M22: =6049*4 -> 24196 | N22: =L22*M22/100 -> 786.37 | O22: =N22*0.529 -> 415.98973 | P22: =O22*13.14 -> 5466.1051 | AC22: =Q22+T22+W22+Z22 -> 0 | AD22: =(R22+U22+X22+AA22)/4 -> 0 | AE22: =(S22+V22+Y22+AB22)/4 -> 0
A23: 44732 | B23: 70 | C23: =IF(AC23>0,((B23-R23)+(S23-B24)),IF(B24=0, ,(B23-B24))) -> 4 | D23: 69 | E23: =IF(AC23>0,((D23-U23)+(V23-D24)),IF(D24=0, ,(D23-D24))) -> 4 | F23: 70 | G23: =IF(AC23>0,((F23-X23)+(Y23-F24)),IF(F24=0, ,(F23-F24))) -> 0 | H23: 70 | I23: =IF(AC23>0,((H23-AA23)+(AB23-H24)),IF(H24=0, ,(H23-H24))) -> 0 | J23: =B23+D23+F23+H23 -> 279 | K23: =J23/4 -> 69.75 | L23: =IF(AC23>0,((K23-AD23)+(AE23-K24)),IF(K24=0, ,(K23-K24))) -> 2 | M23: =6049*4 -> 24196 | N23: =L23*M23/100 -> 483.92 | O23: =N23*0.529 -> 255.99368 | P23: =O23*13.14 -> 3363.757 | AC23: =Q23+T23+W23+Z23 -> 0 | AD23: =(R23+U23+X23+AA23)/4 -> 0 | AE23: =(S23+V23+Y23+AB23)/4 -> 0
A24: 44733 | B24: 66 | C24: =IF(AC24>0,((B24-R24)+(S24-B25)),IF(B25=0, ,(B24-B25))) -> 2 | D24: 65 | E24: =IF(AC24>0,((D24-U24)+(V24-D25)),IF(D25=0, ,(D24-D25))) -> 1 | F24: 70 | G24: =IF(AC24>0,((F24-X24)+(Y24-F25)),IF(F25=0, ,(F24-F25))) -> 2 | H24: 70 | I24: =IF(AC24>0,((H24-AA24)+(AB24-H25)),IF(H25=0, ,(H24-H25))) -> 4 | J24: =B24+D24+F24+H24 -> 271 | K24: =J24/4 -> 67.75 | L24: =IF(AC24>0,((K24-AD24)+(AE24-K25)),IF(K25=0, ,(K24-K25))) -> 2.25 | M24: =6049*4 -> 24196 | N24: =L24*M24/100 -> 544.41 | O24: =N24*0.529 -> 287.99289 | P24: =O24*13.14 -> 3784.2266 | AC24: =Q24+T24+W24+Z24 -> 0 | AD24: =(R24+U24+X24+AA24)/4 -> 0 | AE24: =(S24+V24+Y24+AB24)/4 -> 0
A25: 44734 | B25: 64 | C25: =IF(AC25>0,((B25-R25)+(S25-B26)),IF(B26=0, ,(B25-B26))) -> 3 | D25: 64 | E25: =IF(AC25>0,((D25-U25)+(V25-D26)),IF(D26=0, ,(D25-D26))) -> 4 | F25: 68 | G25: =IF(AC25>0,((F25-X25)+(Y25-F26)),IF(F26=0, ,(F25-F26))) -> 3 | H25: 66 | I25: =IF(AC25>0,((H25-AA25)+(AB25-H26)),IF(H26=0, ,(H25-H26))) -> 1 | J25: =B25+D25+F25+H25 -> 262 | K25: =J25/4 -> 65.5 | L25: =IF(AC25>0,((K25-AD25)+(AE25-K26)),IF(K26=0, ,(K25-K26))) -> 2.75 | M25: =6049*4 -> 24196 | N25: =L25*M25/100 -> 665.39 | O25: =N25*0.529 -> 351.99131 | P25: =O25*13.14 -> 4625.1658 | AC25: =Q25+T25+W25+Z25 -> 0 | AD25: =(R25+U25+X25+AA25)/4 -> 0 | AE25: =(S25+V25+Y25+AB25)/4 -> 0
A26: 44735 | B26: 61 | C26: =IF(AC26>0,((B26-R26)+(S26-B27)),IF(B27=0, ,(B26-B27))) -> 1 | D26: 60 | E26: =IF(AC26>0,((D26-U26)+(V26-D27)),IF(D27=0, ,(D26-D27))) -> 1 | F26: 65 | G26: =IF(AC26>0,((F26-X26)+(Y26-F27)),IF(F27=0, ,(F26-F27))) -> 3 | H26: 65 | I26: =IF(AC26>0,((H26-AA26)+(AB26-H27)),IF(H27=0, ,(H26-H27))) -> 3 | J26: =B26+D26+F26+H26 -> 251 | K26: =J26/4 -> 62.75 | L26: =IF(AC26>0,((K26-AD26)+(AE26-K27)),IF(K27=0, ,(K26-K27))) -> 2 | M26: =6049*4 -> 24196 | N26: =L26*M26/100 -> 483.92 | O26: =N26*0.529 -> 255.99368 | P26: =O26*13.14 -> 3363.757 | AC26: =Q26+T26+W26+Z26 -> 0 | AD26: =(R26+U26+X26+AA26)/4 -> 0 | AE26: =(S26+V26+Y26+AB26)/4 -> 0
... A30: 44739 | B30: 54 | C30: =IF(AC30>0,((B30-R30)+(S30-B31)),IF(B31=0, ,(B30-B31))) -> 0 | D30: 52 | E30: =IF(AC30>0,((D30-U30)+(V30-D31)),IF(D31=0, ,(D30-D31))) -> 0 | F30: 59 | G30: =IF(AC30>0,((F30-X30)+(Y30-F31)),IF(F31=0, ,(F30-F31))) -> 0 | H30: 58 | I30: =IF(AC30>0,((H30-AA30)+(AB30-H31)),IF(H31=0, ,(H30-H31))) -> 0 | J30: =B30+D30+F30+H30 -> 223 | K30: =J30/4 -> 55.75 | L30: =IF(AC30>0,((K30-AD30)+(AE30-K31)),IF(K31=0, ,(K30-K31))) -> 0 | M30: =6049*4 -> 24196 | N30: =L30*M30/100 -> 0 | O30: =N30*0.529 -> 0 | P30: =O30*13.14 -> 0 | AC30: =Q30+T30+W30+Z30 -> 0 | AD30: =(R30+U30+X30+AA30)/4 -> 0 | AE30: =(S30+V30+Y30+AB30)/4 -> 0
A31: 44740 | C31: =IF(AC31>0,((B31-R31)+(S31-B32)),IF(B32=0, ,(B31-B32))) -> 0 | E31: =IF(AC31>0,((D31-U31)+(V31-D32)),IF(D32=0, ,(D31-D32))) -> 0 | G31: =IF(AC31>0,((F31-X31)+(Y31-F32)),IF(F32=0, ,(F31-F32))) -> 0 | I31: =IF(AC31>0,((H31-AA31)+(AB31-H32)),IF(H32=0, ,(H31-H32))) -> 0 | J31: =B31+D31+F31+H31 -> 0 | K31: =J31/4 -> 0 | L31: =IF(AC31>0,((K31-AD31)+(AE31-K32)),IF(K32=0, ,(K31-K32))) -> 0 | M31: =6049*4 -> 24196 | N31: =L31*M31/100 -> 0 | O31: =N31*0.529 -> 0 | P31: =O31*13.14 -> 0 | AC31: =Q31+T31+W31+Z31 -> 0 | AD31: =(R31+U31+X31+AA31)/4 -> 0 | AE31: =(S31+V31+Y31+AB31)/4 -> 0
A32: 44741 | C32: =IF(AC32>0,((B32-R32)+(S32-B33)),IF(B33=0, ,(B32-B33))) -> 0 | E32: =IF(AC32>0,((D32-U32)+(V32-D33)),IF(D33=0, ,(D32-D33))) -> 0 | G32: =IF(AC32>0,((F32-X32)+(Y32-F33)),IF(F33=0, ,(F32-F33))) -> 0 | I32: =IF(AC32>0,((H32-AA32)+(AB32-H33)),IF(H33=0, ,(H32-H33))) -> 0 | J32: =B32+D32+F32+H32 -> 0 | K32: =J32/4 -> 0 | L32: =IF(AC32>0,((K32-AD32)+(AE32-K33)),IF(K33=0, ,(K32-K33))) -> 0 | M32: =6049*4 -> 24196 | N32: =L32*M32/100 -> 0 | O32: =N32*0.529 -> 0 | P32: =O32*13.14 -> 0 | AC32: =Q32+T32+W32+Z32 -> 0 | AD32: =(R32+U32+X32+AA32)/4 -> 0 | AE32: =(S32+V32+Y32+AB32)/4 -> 0
A33: 44742 | C33: =IF(AC33>0,((B33-R33)+(S33-B34)),IF(B34=0, ,(B33-B34))) -> 0 | E33: =IF(AC33>0,((D33-U33)+(V33-D34)),IF(D34=0, ,(D33-D34))) -> 0 | G33: =IF(AC33>0,((F33-X33)+(Y33-F34)),IF(F34=0, ,(F33-F34))) -> 0 | I33: =IF(AC33>0,((H33-AA33)+(AB33-H34)),IF(H34=0, ,(H33-H34))) -> 0 | J33: =B33+D33+F33+H33 -> 0 | K33: =J33/4 -> 0 | L33: =IF(AC33>0,((K33-AD33)+(AE33-K34)),IF(K34=0, ,(K33-K34))) -> 0 | M33: =6049*4 -> 24196 | N33: =L33*M33/100 -> 0 | O33: =N33*0.529 -> 0 | P33: =O33*13.14 -> 0 | AC33: =Q33+T33+W33+Z33 -> 0 | AD33: =(R33+U33+X33+AA33)/4 -> 0 | AE33: =(S33+V33+Y33+AB33)/4 -> 0
A34: 44743 | C34: =IF(AC34>0,((B34-R34)+(S34-B35)),IF(B35=0, ,(B34-B35))) -> 0 | E34: =IF(AC34>0,((D34-U34)+(V34-D35)),IF(D35=0, ,(D34-D35))) -> 0 | G34: =IF(AC34>0,((F34-X34)+(Y34-F35)),IF(F35=0, ,(F34-F35))) -> 0 | I34: =IF(AC34>0,((H34-AA34)+(AB34-H35)),IF(H35=0, ,(H34-H35))) -> 0 | J34: =B34+D34+F34+H34 -> 0 | K34: =J34/4 -> 0 | L34: =IF(AC34>0,((K34-AD34)+(AE34-K35)),IF(K35=0, ,(K34-K35))) -> 0 | M34: =6049*4 -> 24196 | N34: =L34*M34/100 -> 0 | O34: =N34*0.529 -> 0 | P34: =O34*13.64 -> 0 | AC34: =Q34+T34+W34+Z34 -> 0 | AD34: =(R34+U34+X34+AA34)/4 -> 0 | AE34: =(S34+V34+Y34+AB34)/4 -> 0
A35: 44744 | C35: =IF(AC35>0,((B35-R35)+(S35-B36)),IF(B36=0, ,(B35-B36))) -> 0 | E35: =IF(AC35>0,((D35-U35)+(V35-D36)),IF(D36=0, ,(D35-D36))) -> 0 | G35: =IF(AC35>0,((F35-X35)+(Y35-F36)),IF(F36=0, ,(F35-F36))) -> 0 | I35: =IF(AC35>0,((H35-AA35)+(AB35-H36)),IF(H36=0, ,(H35-H36))) -> 0 | J35: =B35+D35+F35+H35 -> 0 | K35: =J35/4 -> 0 | L35: =IF(AC35>0,((K35-AD35)+(AE35-K36)),IF(K36=0, ,(K35-K36))) -> 0 | M35: =6049*4 -> 24196 | N35: =L35*M35/100 -> 0 | O35: =N35*0.529 -> 0 | P35: =O35*13.64 -> 0 | AC35: =Q35+T35+W35+Z35 -> 0 | AD35: =(R35+U35+X35+AA35)/4 -> 0 | AE35: =(S35+V35+Y35+AB35)/4 -> 0
C36: =IF(AC36>0,((B36-R36)+(S36-B37)),IF(B37=0, ,(B36-B37))) -> 0 | E36: =IF(AC36>0,((D36-U36)+(V36-D37)),IF(D37=0, ,(D36-D37))) -> 0 | G36: =IF(AC36>0,((F36-X36)+(Y36-F37)),IF(F37=0, ,(F36-F37))) -> 0 | I36: =IF(AC36>0,((H36-AA36)+(AB36-H37)),IF(H37=0, ,(H36-H37))) -> 0 | J36: =B36+D36+F36+H36 -> 0 | K36: =J36/4 -> 0 | L36: =IF(AC36>0,((K36-AD36)+(AE36-K37)),IF(K37=0, ,(K36-K37))) -> 0 | M36: =6049*4 -> 24196 | N36: =L36*M36/100 -> 0 | O36: =N36*0.529 -> 0 | P36: =O36*13.64 -> 0 | AC36: =Q36+T36+W36+Z36 -> 0 | AD36: =(R36+U36+X36+AA36)/4 -> 0 | AE36: =(S36+V36+Y36+AB36)/4 -> 0
C37: =IF(AC37>0,((B37-R37)+(S37-B38)),IF(B38=0, ,(B37-B38))) -> 0 | E37: =IF(AC37:AC60>0,((D37-U37)+(V37-D38)),IF(D38=0, ,(D37-D38))) -> 0 | G37: =IF(AC37>0,((F37-X37)+(Y37-F38)),IF(F38=0, ,(F37-F38))) -> 0 | I37: =IF(AC37>0,((H37-AA37)+(AB37-H38)),IF(H38=0, ,(H37-H38))) -> 0 | J37: =B37+D37+F37+H37 -> 0 | K37: =J37/4 -> 0 | L37: =IF(AC37>0,((K37-AD37)+(AE37-K38)),IF(K38=0, ,(K37-K38))) -> 0 | M37: =6049*4 -> 24196 | N37: =L37*M37/100 -> 0 | O37: =N37*0.529 -> 0 | P37: =O37*12.64 -> 0 | AC37: =Q37+T37+W37+Z37 -> 0 | AD37: =(R37+U37+X37+AA37)/4 -> 0 | AE37: =(S37+V37+Y37+AB37)/4 -> 0
C38: =IF(AC38>0,((B38-R38)+(S38-B39)),IF(B39=0, ,(B38-B39))) -> 0 | E38: =IF(AC38:AC61>0,((D38-U38)+(V38-D39)),IF(D39=0, ,(D38-D39))) -> 0 | G38: =IF(AC38>0,((F38-X38)+(Y38-F39)),IF(F39=0, ,(F38-F39))) -> 0 | I38: =IF(AC38>0,((H38-AA38)+(AB38-H39)),IF(H39=0, ,(H38-H39))) -> 0 | J38: =B38+D38+F38+H38 -> 0 | K38: =J38/4 -> 0 | L38: =IF(AC38>0,((K38-AD38)+(AE38-K39)),IF(K39=0, ,(K38-K39))) -> 0 | M38: =6049*4 -> 24196 | N38: =L38*M38/100 -> 0 | O38: =N38*0.53 -> 0 | P38: =O38*11.565 -> 0 | AC38: =Q38+T38+W38+Z38 -> 0 | AD38: =(R38+U38+X38+AA38)/4 -> 0 | AE38: =(S38+V38+Y38+AB38)/4 -> 0
C39: =IF(AC39>0,((B39-R39)+(S39-B40)),IF(B40=0, ,(B39-B40))) -> 0 | E39: =IF(AC39>0,((D39-U39)+(V39-D40)),IF(D40=0, ,(D39-D40))) -> 0 | G39: =IF(AC39>0,((F39-X39)+(Y39-F40)),IF(F40=0, ,(F39-F40))) -> 0 | I39: =IF(AC39>0,((H39-AA39)+(AB39-H40)),IF(H40=0, ,(H39-H40))) -> 0 | J39: =B39+D39+F39+H39 -> 0 | K39: =J39/4 -> 0 | L39: =IF(AC39>0,((K39-AD39)+(AE39-K40)),IF(K40=0, ,(K39-K40))) -> 0 | M39: =6049*4 -> 24196 | N39: =L39*M39/100 -> 0 | O39: =N39*0.53 -> 0 | P39: =O39*11.2513 -> 0 | AC39: =Q39+T39+W39+Z39 -> 0 | AD39: =(R39+U39+X39+AA39)/4 -> 0 | AE39: =(S39+V39+Y39+AB39)/4 -> 0
C40: =IF(AC40>0,((B40-R40)+(S40-B41)),IF(B41=0, ,(B40-B41))) -> 0 | E40: =IF(AC40>0,((D40-U40)+(V40-D41)),IF(D41=0, ,(D40-D41))) -> 0 | G40: =IF(AC40>0,((F40-X40)+(Y40-F41)),IF(F41=0, ,(F40-F41))) -> 0 | I40: =IF(AC40>0,((H40-AA40)+(AB40-H41)),IF(H41=0, ,(H40-H41))) -> 0 | J40: =B40+D40+F40+H40 -> 0 | K40: =J40/4 -> 0 | L40: =IF(AC40>0,((K40-AD40)+(AE40-K41)),IF(K41=0, ,(K40-K41))) -> 0 | M40: =6049*4 -> 24196 | N40: =L40*M40/100 -> 0 | O40: =N40*0.53 -> 0 | P40: =O40*9.965 -> 0 | AC40: =Q40+T40+W40+Z40 -> 0 | AD40: =(R40+U40+X40+AA40)/4 -> 0 | AE40: =(S40+V40+Y40+AB40)/4 -> 0
C41: =IF(AC41>0,((B41-R41)+(S41-B42)),IF(B42=0, ,(B41-B42))) -> 0 | E41: =IF(AC41>0,((D41-U41)+(V41-D42)),IF(D42=0, ,(D41-D42))) -> 0 | G41: =IF(AC41>0,((F41-X41)+(Y41-F42)),IF(F42=0, ,(F41-F42))) -> 0 | I41: =IF(AC41>0,((H41-AA41)+(AB41-H42)),IF(H42=0, ,(H41-H42))) -> 0 | J41: =B41+D41+F41+H41 -> 0 | K41: =J41/4 -> 0 | L41: =IF(AC41>0,((K41-AD41)+(AE41-K42)),IF(K42=0, ,(K41-K42))) -> 0 | M41: =6049*4 -> 24196 | N41: =L41*M41/100 -> 0 | O41: =N41*0.53 -> 0 | P41: =O41*9.965 -> 0 | AC41: =Q41+T41+W41+Z41 -> 0 | AD41: =(R41+U41+X41+AA41)/4 -> 0 | AE41: =(S41+V41+Y41+AB41)/4 -> 0
C42: =IF(AC42>0,((B42-R42)+(S42-B43)),IF(B43=0, ,(B42-B43))) -> 0 | E42: =IF(AC42>0,((D42-U42)+(V42-D43)),IF(D43=0, ,(D42-D43))) -> 0 | G42: =IF(AC42>0,((F42-X42)+(Y42-F43)),IF(F43=0, ,(F42-F43))) -> 0 | I42: =IF(AC42>0,((H42-AA42)+(AB42-H43)),IF(H43=0, ,(H42-H43))) -> 0 | J42: =B42+D42+F42+H42 -> 0 | K42: =J42/4 -> 0 | L42: =IF(AC42>0,((K42-AD42)+(AE42-K43)),IF(K43=0, ,(K42-K43))) -> 0 | M42: =6049*4 -> 24196 | N42: =L42*M42/100 -> 0 | O42: =N42*0.53 -> 0 | P42: =O42*9.965 -> 0 | AC42: =Q42+T42+W42+Z42 -> 0 | AD42: =(R42+U42+X42+AA42)/4 -> 0 | AE42: =(S42+V42+Y42+AB42)/4 -> 0
N43: =SUM(N4:N42) -> 13126.33 | O43: =N43*0.529 -> 6943.8286 | P43: =O43*13.64 -> 94713.822 | Q43: =SUM(Q4:Q42) -> 2136 | T43: =SUM(T4:T42) -> 2110 | W43: =SUM(W4:W42) -> 1776 | Z43: =SUM(Z4:Z42) -> 1751 | AC43: =Q43+T43+W43+Z43 -> 7773
...

Sheet Facture journalier D'élect
C1: Estimation de la consommation électrique juin 2022 | H1: Fiche technique
H3: DT fourseasons CBL
A7: N° de compteur | C7: Ancienne date de lecture | E7: Nouvelle date de lecture | F7: N de jours de consommation | G7: Heures pleines | H7: Heures creuses | I7: Heures de pointe
A8: 95670781 | C8: 44567 | E8: 44598 | F8: 01jours
A11: Type de comptage | C11: Puissance installée KVA | E11: Puissance souscrite KVA | G11: Puissance appelée KVA | I11: Dépassement de la puissance souscrite KVA
A12: 4T | C12: 3750 | E12: 1000 | G12: 793
A16: Eléments de relève | C16: Nouvel Index | D16: Ancien Index | E16: Consommation | F16: Energie révaluée | G16: Consommation Compteur démarquant | I16: Energie à facturer
A17: HEURES PLEINE | C17: 20117099 | D17: 20106843 | E17: =MIN(C17-D17) -> 10256 | F17: =+E17 -> 10256 | I17: =+E17 -> 10256
A18: HEURES CREUSES | C18: 11848105 | D18: 11843664 | E18: =MIN(C18-D18) -> 4441 | F18: =+E18 -> 4441 | I18: =+E18 -> 4441
A19: HEURES DE POINTE | C19: 8833074 | D19: 8829353 | E19: =AVERAGE(C19-D19) -> 3721 | F19: =+E19 -> 3721 | I19: =+E19 -> 3721
A20: TOTAL | E20: =SUM(E17:E19) -> 18418
A23: Détail de la facture | D23: Quantité | E23: Prix unitaire | F23: Montant HT | G23: TVA | I23: Montant TTC
G24: Taux % | H24: Montant
A25: ENERGIE ACTIVE H. PLEINES | D25: =+E17 -> 10256 | E25: 0.9514 | F25: =PRODUCT(D25*E25) -> 9757.5584 | G25: 14 | H25: =PRODUCT(0.14,F25) -> 1366.0582 | I25: =SUM(H25,F25) -> 11123.617
A26: ENERGIE ACTIVE H. CREUSES | D26: =+E18 -> 4441 | E26: 0.6985 | F26: =PRODUCT(D26*E26) -> 3102.0385 | G26: 14 | H26: =PRODUCT(0.14,F26) -> 434.28539 | I26: =SUM(H26,F26) -> 3536.3239
A27: ENETGIE ACTIVE H. DE POINTE | D27: =+E19 -> 3721 | E27: 1.3304 | F27: =PRODUCT(D27*E27) -> 4950.4184 | G27: 14 | H27: =PRODUCT(0.14,F27) -> 693.05858 | I27: =SUM(H27,F27) -> 5643.477
A28: REDEVANCE DE PUISSANCE | D28: 1000 | E28: 43.88167 | F28: =PRODUCT(D28,E28) -> 43881.67 | G28: 14 | H28: =PRODUCT(0.14,F28) -> 6143.4338 | I28: =SUM(H28,F28) -> 50025.104
A29: DEPASSEMENT DE PUISSANCE | D29: 0 | E29: 48.97249 | F29: =PRODUCT(D29,E29) -> 0 | G29: 14 | H29: =PRODUCT(0.14,F29) -> 0 | I29: =SUM(H29,F29) -> 0
A30: ENTRETIEN COMPTAGE | F30: 841 | G30: 20 | H30: =PRODUCT(F30,0.2) -> 168.2 | I30: =SUM(H30,F30) -> 1009.2
A31: LOCATION COMPTAGE | F31: 1492 | G31: 7 | H31: =PRODUCT(F31,0.07) -> 104.44 | I31: =SUM(H31,F31) -> 1596.44
A32: Total | F32: =SUM(F25:F31) -> 64024.685 | I32: =SUM(I25:J31) -> 72934.161

Sheet facture électricité
C1: Estimation de la consommation électrique juin 2022 | H1: Fiche technique
H3: DT fourseasons CBL
A7: N° de compteur | C7: Ancienne date de lecture | E7: Nouvelle date de lecture | F7: N de jours de consommation | G7: Heures pleines | H7: Heures creuses | I7: Heures de pointe
A8: 95670781 | C8: 44314 | E8: 44709 | F8: 30jours
A11: Type de comptage | C11: Puissance installée KVA | E11: Puissance souscrite KVA | G11: Puissance appelée KVA | I11: Dépassement de la puissance souscrite KVA
A12: 4T | C12: 3750 | E12: 1000 | G12: 1135
A16: Eléments de relève | C16: Nouvel Index | D16: Ancien Index | E16: Consommation | F16: Energie révaluée | G16: Consommation Compteur démarquant | I16: Energie à facturer
A17: HEURES PLEINE | C17: 20068636 | D17: 19830772 | E17: =MIN(C17-D17) -> 237864 | F17: =+E17 -> 237864 | I17: =+E17 -> 237864
A18: HEURES CREUSES | C18: 11824428 | D18: 11704653 | E18: =MIN(C18-D18) -> 119775 | F18: =+E18 -> 119775 | I18: =+E18 -> 119775
A19: HEURES DE POINTE | C19: 8814739 | D19: 8719952 | E19: =AVERAGE(C19-D19) -> 94787 | F19: =+E19 -> 94787 | I19: =+E19 -> 94787
A20: TOTAL | E20: =SUM(E17:E19) -> 452426
A23: Détail de la facture | D23: Quantité | E23: Prix unitaire | F23: Montant HT | G23: TVA | I23: Montant TTC
G24: Taux % | H24: Montant
A25: ENERGIE ACTIVE H. PLEINES | D25: =+E17 -> 237864 | E25: 0.9514 | F25: =PRODUCT(D25*E25) -> 226303.81 | G25: 14 | H25: =PRODUCT(0.14,F25) -> 31682.533 | I25: =SUM(H25,F25) -> 257986.34
A26: ENERGIE ACTIVE H. CREUSES | D26: =+E18 -> 119775 | E26: 0.6985 | F26: =PRODUCT(D26*E26) -> 83662.837 | G26: 14 | H26: =PRODUCT(0.14,F26) -> 11712.797 | I26: =SUM(H26,F26) -> 95375.635
A27: ENETGIE ACTIVE H. DE POINTE | D27: =+E19 -> 94787 | E27: 1.3304 | F27: =PRODUCT(D27*E27) -> 126104.62 | G27: 14 | H27: =PRODUCT(0.14,F27) -> 17654.647 | I27: =SUM(H27,F27) -> 143759.27
A28: REDEVANCE DE PUISSANCE | D28: 1000 | E28: 43.88167 | F28: =PRODUCT(D28,E28) -> 43881.67 | G28: 14 | H28: =PRODUCT(0.14,F28) -> 6143.4338 | I28: =SUM(H28,F28) -> 50025.104
A29: DEPASSEMENT DE PUISSANCE | D29: =G12-D28 -> 135 | E29: =E28*1.5 -> 65.822505 | F29: =PRODUCT(D29,E29) -> 8886.0382 | G29: 14 | H29: =PRODUCT(0.14,F29) -> 1244.0453 | I29: =SUM(H29,F29) -> 10130.084
A30: ENTRETIEN COMPTAGE | F30: 841 | G30: 20 | H30: =PRODUCT(F30,0.2) -> 168.2 | I30: =SUM(H30,F30) -> 1009.2
A31: LOCATION COMPTAGE | F31: 1492 | G31: 7 | H31: =PRODUCT(F31,0.07) -> 104.44 | I31: =SUM(H31,F31) -> 1596.44
A32: Total | F32: =SUM(F25:F31) -> 491171.98 | I32: =SUM(I25:J31) -> 559882.08

Sheet facture d'eau
B1: Estimation de la consommation d'Eau Sanitaire juin 2022 | F1: Fiche technique
F3: DT fourseasons CBL
A7: N° de compteur | B7: Type de relevé | C7: Ancien index | D7: Ancienne date de lecture | E7: Nouvel index | F7: Nouvelle date de lecture | G7: Consommation M3 | H7: N de jours de consommation
B8: RELEVEE | C8: 143745 | D8: 44682 | E8: 148296.1 | F8: 44713 | G8: =E8-C8 -> 4551.1
B10: Quantité | D10: Prix unitaire HT | F10: Montant HT
A11: Redevances Fixes | F11: 23
A12: Consommation eau
A13: Tranche unique | B13: =G8 -> 4551.1 | D13: 8.79 | F13: =PRODUCT(D13,B13) -> 40004.169
A14: Assainissement
A16: Tranche 1 | B16: 0 | D16: 0 | F16: =PRODUCT(D16,B16) -> 0
A17: Tranche 2 | B17: 0 | D17: 0 | F17: =PRODUCT(D17,B17) -> 0
A18: Tranche 3 | B18: 0 | D18: 0 | F18: =PRODUCT(D18,B18) -> 0
A19: Tranche 4 | B19: =G8 -> 4551.1 | D19: 2.61 | F19: =PRODUCT(D19,B19) -> 11878.371
A20: Total HT | F20: =SUM(F11+F13+F16+F17+F18+F19) -> 51905.54
A21: TVA 7% | F21: =PRODUCT(F20,0.07) -> 3633.3878
A22: Timbres Fiscaux | F22: 208.26
A23: Total Taxes | F23: =SUM(F21:H22) -> 3841.6478
A24: Net à payer | F24: =SUM(F20,F23) -> 55747.188

Sheet Facture journalier d'eau
B1: Estimation de la consommation d'Eau Sanitaire MAI 2022 | F1: Fiche technique
F3: DT fourseasons CBL
A7: N° de compteur | B7: Type de relevé | C7: Ancien index | D7: Ancienne date de lecture | E7: Nouvel index | F7: Nouvelle date de lecture | G7: Consommation M3 | H7: N de jours de consommation
B8: RELEVEE | C8: 148296.1 | D8: 44713 | E8: 148461.3 | F8: 44714 | G8: =E8-C8 -> 165.2
B10: Quantité | D10: Prix unitaire HT | F10: Montant HT
A11: Redevances Fixes | F11: 23
A12: Consommation eau
A13: Tranche unique | B13: =G8 -> 165.2 | D13: 8.5 | F13: =PRODUCT(D13,B13) -> 1404.2
A14: Assainissement
A16: Tranche 1 | B16: 0 | D16: 0 | F16: =PRODUCT(D16,B16) -> 0
A17: Tranche 2 | B17: 0 | D17: 0 | F17: =PRODUCT(D17,B17) -> 0
A18: Tranche 3 | B18: 0 | D18: 0 | F18: =PRODUCT(D18,B18) -> 0
A19: Tranche 4 | B19: 0 | D19: 0 | F19: 0
A20: Tranche 5 | B20: =G8 -> 165.2 | D20: 2.54 | F20: =PRODUCT(D20,B20) -> 419.608
A21: Total HT | F21: =SUM(F11+F13+F16+F17+F18+F20) -> 1846.808
A22: TVA 7% | F22: =PRODUCT(F21,0.07) -> 129.27656
A23: Timbres Fiscaux | F23: 208.26
A24: Total Taxes | F24: =SUM(F22:H23) -> 337.53656
A25: Net à payer | F25: =SUM(F21,F24) -> 2184.3446

Sheet facture incendie
B1: Estimation de la consommation d'Eau incendie MAI 2022 | F1: Fiche technique
F3: DT fourseasons CBL
A7: N° de compteur | B7: Type de relevé | C7: Ancien index | D7: Ancienne date de lecture | E7: Nouvel index | F7: Nouvelle date de lecture | G7: Consommation M3 | H7: N de jours de consommation
B8: RELEVEE | C8: 2560 | D8: 44317 | E8: 2560 | F8: 44713 | G8: =E8-C8 -> 0
B10: Quantité | D10: Prix unitaire HT | F10: Montant HT
A11: Redevances Fixes | F11: 15
A12: Consommation eau
A13: Tranche unique 1 | B13: =G8 -> 0 | D13: 16.48 | F13: =PRODUCT(D13,B13) -> 0
A14: Tranche unique 2
A15: Tranche unique 3
A16: Tranche unique 4
A17: Tranche unique 5
A18: Assainissement
A20: Tranche 1 | B20: 0 | D20: 0 | F20: =PRODUCT(D20,B20) -> 0
A21: Tranche 2 | B21: 0 | D21: 0 | F21: =PRODUCT(D21,B21) -> 0
A22: Tranche 3 | B22: 0 | D22: 0 | F22: =PRODUCT(D22,B22) -> 0
A23: Tranche 4 | B23: =G8 -> 0 | D23: 0 | F23: =PRODUCT(D23,B23) -> 0
A24: Tranche 5 | B24: 0 | D24: 2.54 | F24: =B24*D24 -> 0
A25: Total HT | F25: =SUM(F11+F13+F20+F21+F22+F23) -> 15
A26: TVA 7% | F26: 63.63
A27: Timbres Fiscaux | F27: 2.43
A28: Total Taxes | F28: =SUM(F26:H27) -> 66.06
A29: Net à payer | F29: =SUM(F25,F28) -> 81.06

Sheet cons annuel électr
C5: électricité en KW
C7: Janvier | D7: Février | E7: Mars | F7: avril | G7: Mai | H7: juin | I7: Juillet | J7: aout | K7: Septembre | L7: Octobre | M7: Novembre | N7: Décembre
B8: Année 2015 | L8: 544520 | M8: 561765 | N8: 546771
B9: Année 2016 | C9: 564170 | D9: 532072 | E9: 405239 | F9: 469130 | G9: 543877 | H9: 605744 | I9: 722083 | J9: 802210 | K9: 762933 | L9: 670848 | M9: 626451 | N9: 557392
B10: Année 2017 | C10: 520977 | D10: 541271 | E10: 508392 | F10: 659200 | G10: 705703 | H10: 784214 | I10: 823726 | J10: 913736 | K10: 831734 | L10: 794243 | M10: 688127 | N10: 577067
B11: Année 2018 | C11: 586355 | D11: 563735 | E11: 512313 | F11: 573440 | G11: 535115 | H11: 570139 | I11: 669302 | J11: 704714 | K11: 682717 | L11: 581239 | M11: 438561 | N11: 400672
B12: Année 2019 | C12: 388363 | D12: 407737 | E12: 392102 | F12: 454554 | G12: 448580 | H12: 535391 | I12: 549301 | J12: 576078 | K12: 612675 | L12: 542640 | M12: 507495 | N12: 444826
B13: Année 2020 | C13: 417018 | D13: 434912 | E13: 278008 | F13: 90895 | G13: 70143 | H13: 76577 | I13: 238549 | J13: 371235 | K13: 295161 | L13: 318184 | M13: 297355 | N13: 260661
B14: Année 2021 | C14: 239911 | D14: 247692 | E14: 242350 | F14: 282564 | G14: 272836 | H14: 362809 | I14: 454598 | J14: 470109 | K14: 458455 | L14: 444199 | M14: 374528 | N14: 256419
B15: Année 2022 | C15: 206479 | D15: 244783 | E15: 316387 | F15: 353545 | G15: 452426
C16: électricité en DH HT
C18: Janvier | D18: Février | E18: Mars | F18: avril | G18: Mai | H18: juin | I18: Juillet | J18: aout | K18: Septembre | L18: Octobre | M18: Novembre | N18: Décembre
B19: Année 2015 | L19: 527344.76 | M19: 542887.95 | N19: 530789.1
B20: Année 2016 | C20: 577599.26 | D20: 549500.3 | E20: 437038.73 | F20: 498381.29 | G20: 567710.59 | H20: 626665.41 | I20: 732996.54 | J20: 807380.12 | K20: 765103.7 | L20: 674808.61 | M20: 636029.23 | N20: 575999.91
