Workbook

Sheet TOTAL
A1: Site Name | B1: Day | C1: Month | D1: Year | E1: Total Electricity Kwh | F1: Electricity Tariff ($/Kwh) | G1: Natual Gas (m3) | H1: Natural Gas $/m3 | I1: Water Utility Supply (m3) m3 | J1: Water Utility Supply (m3) $/m3 | K1: Room Nights
A2: Cairo at Nile Plaza | B2: 1 | C2: 6 | D2: 2022 | E2: =(((Submetering!O2+Submetering!P2)*0.842284+Submetering!Q2+(Submetering!M2+Submetering!N2+Submetering!Y2)*0.7362)+(Submetering!O2+Submetering!P2+Submetering!Q2)*0.1488+(Submetering!M2+Submetering!N2+Submetering!Y2)*0.1167+(Submetering!K2+Submetering!L2-Submetering!Z2-Submetering!AA2-Submetering!AB2-Submetering!AC2-Submetering!Q2)+(Submetering!M2+Submetering!N2+Submetering!Y2)*0.1139) -> 69269.46 | F2: 1.27 | G2: =Gas!C3*0.9147 -> 2396.514 | H2: 3.65 | I2: =Submetering!H2+Submetering!AD2+Submetering!AE2 -> 826 | J2: 10.03 | K2: =ELECT.!B3 -> 155
A3: Cairo at Nile Plaza | B3: =B2+1 -> 2 | C3: 6 | D3: 2022 | E3: =(((Submetering!O3+Submetering!P3)*0.842284+Submetering!Q3+(Submetering!M3+Submetering!N3+Submetering!Y3)*0.7362)+(Submetering!O3+Submetering!P3+Submetering!Q3)*0.1488+(Submetering!M3+Submetering!N3+Submetering!Y3)*0.1167+(Submetering!K3+Submetering!L3-Submetering!Z3-Submetering!AA3-Submetering!AB3-Submetering!AC3-Submetering!Q3)+(Submetering!M3+Submetering!N3+Submetering!Y3)*0.1139) -> 79908.367 | F3: 1.27 | G3: =Gas!C4*0.9147 -> 2564.8188 | H3: 3.65 | I3: =Submetering!H3+Submetering!AD3+Submetering!AE3 -> 826 | J3: 10.03 | K3: =ELECT.!B4 -> 160
A4: Cairo at Nile Plaza | B4: =B3+1 -> 3 | C4: 6 | D4: 2022 | E4: =(((Submetering!O4+Submetering!P4)*0.842284+Submetering!Q4+(Submetering!M4+Submetering!N4+Submetering!Y4)*0.7362)+(Submetering!O4+Submetering!P4+Submetering!Q4)*0.1488+(Submetering!M4+Submetering!N4+Submetering!Y4)*0.1167+(Submetering!K4+Submetering!L4-Submetering!Z4-Submetering!AA4-Submetering!AB4-Submetering!AC4-Submetering!Q4)+(Submetering!M4+Submetering!N4+Submetering!Y4)*0.1139) -> 58575.036 | F4: 1.27 | G4: =Gas!C5*0.9147 -> 2503.5339 | H4: 3.65 | I4: =Submetering!H4+Submetering!AD4+Submetering!AE4 -> 856 | J4: 10.03 | K4: =ELECT.!B5 -> 276
A5: Cairo at Nile Plaza | B5: =B4+1 -> 4 | C5: 6 | D5: 2022 | E5: =(((Submetering!O5+Submetering!P5)*0.842284+Submetering!Q5+(Submetering!M5+Submetering!N5+Submetering!Y5)*0.7362)+(Submetering!O5+Submetering!P5+Submetering!Q5)*0.1488+(Submetering!M5+Submetering!N5+Submetering!Y5)*0.1167+(Submetering!K5+Submetering!L5-Submetering!Z5-Submetering!AA5-Submetering!AB5-Submetering!AC5-Submetering!Q5)+(Submetering!M5+Submetering!N5+Submetering!Y5)*0.1139) -> 73065.192 | F5: 1.27 | G5: =Gas!C6*0.9147 -> 1746.1623 | H5: 3.65 | I5: =Submetering!H5+Submetering!AD5+Submetering!AE5 -> 1016 | J5: 10.03 | K5: =ELECT.!B6 -> 235
A6: Cairo at Nile Plaza | B6: =B5+1 -> 5 | C6: 6 | D6: 2022 | E6: =(((Submetering!O6+Submetering!P6)*0.842284+Submetering!Q6+(Submetering!M6+Submetering!N6+Submetering!Y6)*0.7362)+(Submetering!O6+Submetering!P6+Submetering!Q6)*0.1488+(Submetering!M6+Submetering!N6+Submetering!Y6)*0.1167+(Submetering!K6+Submetering!L6-Submetering!Z6-Submetering!AA6-Submetering!AB6-Submetering!AC6-Submetering!Q6)+(Submetering!M6+Submetering!N6+Submetering!Y6)*0.1139) -> 64503.578 | F6: 1.27 | G6: =Gas!C7*0.9147 -> 2008.6812 | H6: 3.65 | I6: =Submetering!H6+Submetering!AD6+Submetering!AE6 -> 836 | J6: 10.03 | K6: =ELECT.!B7 -> 209
A7: Cairo at Nile Plaza | B7: =B6+1 -> 6 | C7: 6 | D7: 2022 | E7: =(((Submetering!O7+Submetering!P7)*0.842284+Submetering!Q7+(Submetering!M7+Submetering!N7+Submetering!Y7)*0.7362)+(Submetering!O7+Submetering!P7+Submetering!Q7)*0.1488+(Submetering!M7+Submetering!N7+Submetering!Y7)*0.1167+(Submetering!K7+Submetering!L7-Submetering!Z7-Submetering!AA7-Submetering!AB7-Submetering!AC7-Submetering!Q7)+(Submetering!M7+Submetering!N7+Submetering!Y7)*0.1139) -> 122124.04 | F7: 1.27 | G7: =Gas!C8*0.9147 -> 2317.8498 | H7: 3.65 | I7: =Submetering!H7+Submetering!AD7+Submetering!AE7 -> 896 | J7: 10.03 | K7: =ELECT.!B8 -> 224
A8: Cairo at Nile Plaza | B8: =B7+1 -> 7 | C8: 6 | D8: 2022 | E8: =(((Submetering!O8+Submetering!P8)*0.842284+Submetering!Q8+(Submetering!M8+Submetering!N8+Submetering!Y8)*0.7362)+(Submetering!O8+Submetering!P8+Submetering!Q8)*0.1488+(Submetering!M8+Submetering!N8+Submetering!Y8)*0.1167+(Submetering!K8+Submetering!L8-Submetering!Z8-Submetering!AA8-Submetering!AB8-Submetering!AC8-Submetering!Q8)+(Submetering!M8+Submetering!N8+Submetering!Y8)*0.1139) -> 16021.069 | F8: 1.27 | G8: =Gas!C9*0.9147 -> 2405.661 | H8: 3.65 | I8: =Submetering!H8+Submetering!AD8+Submetering!AE8 -> 976 | J8: 10.03 | K8: =ELECT.!B9 -> 228
A9: Cairo at Nile Plaza | B9: =B8+1 -> 8 | C9: 6 | D9: 2022 | E9: =(((Submetering!O9+Submetering!P9)*0.842284+Submetering!Q9+(Submetering!M9+Submetering!N9+Submetering!Y9)*0.7362)+(Submetering!O9+Submetering!P9+Submetering!Q9)*0.1488+(Submetering!M9+Submetering!N9+Submetering!Y9)*0.1167+(Submetering!K9+Submetering!L9-Submetering!Z9-Submetering!AA9-Submetering!AB9-Submetering!AC9-Submetering!Q9)+(Submetering!M9+Submetering!N9+Submetering!Y9)*0.1139) -> 81703.932 | F9: 1.27 | G9: =Gas!C10*0.9147 -> 1856.841 | H9: 3.65 | I9: =Submetering!H9+Submetering!AD9+Submetering!AE9 -> 976 | J9: 10.03 | K9: =ELECT.!B10 -> 230
A10: Cairo at Nile Plaza | B10: =B9+1 -> 9 | C10: 6 | D10: 2022 | E10: =(((Submetering!O10+Submetering!P10)*0.842284+Submetering!Q10+(Submetering!M10+Submetering!N10+Submetering!Y10)*0.7362)+(Submetering!O10+Submetering!P10+Submetering!Q10)*0.1488+(Submetering!M10+Submetering!N10+Submetering!Y10)*0.1167+(Submetering!K10+Submetering!L10-Submetering!Z10-Submetering!AA10-Submetering!AB10-Submetering!AC10-Submetering!Q10)+(Submetering!M10+Submetering!N10+Submetering!Y10)*0.1139) -> 82504.456 | F10: 1.27 | G10: =Gas!C11*0.9147 -> 1736.1006 | H10: 3.65 | I10: =Submetering!H10+Submetering!AD10+Submetering!AE10 -> 976 | J10: 10.03 | K10: =ELECT.!B11 -> 221
A11: Cairo at Nile Plaza | B11: =B10+1 -> 10 | C11: 6 | D11: 2022 | E11: =(((Submetering!O11+Submetering!P11)*0.842284+Submetering!Q11+(Submetering!M11+Submetering!N11+Submetering!Y11)*0.7362)+(Submetering!O11+Submetering!P11+Submetering!Q11)*0.1488+(Submetering!M11+Submetering!N11+Submetering!Y11)*0.1167+(Submetering!K11+Submetering!L11-Submetering!Z11-Submetering!AA11-Submetering!AB11-Submetering!AC11-Submetering!Q11)+(Submetering!M11+Submetering!N11+Submetering!Y11)*0.1139) -> 64404.339 | F11: 1.27 | G11: =Gas!C12*0.9147 -> 2093.7483 | H11: 3.65 | I11: =Submetering!H11+Submetering!AD11+Submetering!AE11 -> 866 | J11: 10.03 | K11: =ELECT.!B12 -> 223
A12: Cairo at Nile Plaza | B12: =B11+1 -> 11 | C12: 6 | D12: 2022 | E12: =(((Submetering!O12+Submetering!P12)*0.842284+Submetering!Q12+(Submetering!M12+Submetering!N12+Submetering!Y12)*0.7362)+(Submetering!O12+Submetering!P12+Submetering!Q12)*0.1488+(Submetering!M12+Submetering!N12+Submetering!Y12)*0.1167+(Submetering!K12+Submetering!L12-Submetering!Z12-Submetering!AA12-Submetering!AB12-Submetering!AC12-Submetering!Q12)+(Submetering!M12+Submetering!N12+Submetering!Y12)*0.1139) -> 64334.137 | F12: 1.27 | G12: =Gas!C13*0.9147 -> 2321.5086 | H12: 3.65 | I12: =Submetering!H12+Submetering!AD12+Submetering!AE12 -> 876 | J12: 10.03 | K12: =ELECT.!B13 -> 182
A13: Cairo at Nile Plaza | B13: =B12+1 -> 12 | C13: 6 | D13: 2022 | E13: =(((Submetering!O13+Submetering!P13)*0.842284+Submetering!Q13+(Submetering!M13+Submetering!N13+Submetering!Y13)*0.7362)+(Submetering!O13+Submetering!P13+Submetering!Q13)*0.1488+(Submetering!M13+Submetering!N13+Submetering!Y13)*0.1167+(Submetering!K13+Submetering!L13-Submetering!Z13-Submetering!AA13-Submetering!AB13-Submetering!AC13-Submetering!Q13)+(Submetering!M13+Submetering!N13+Submetering!Y13)*0.1139) -> 89651.863 | F13: 1.27 | G13: =Gas!C14*0.9147 -> 1489.1316 | H13: 3.65 | I13: =Submetering!H13+Submetering!AD13+Submetering!AE13 -> 856 | J13: 10.03 | K13: =ELECT.!B14 -> 205
A14: Cairo at Nile Plaza | B14: =B13+1 -> 13 | C14: 6 | D14: 2022 | E14: =(((Submetering!O14+Submetering!P14)*0.842284+Submetering!Q14+(Submetering!M14+Submetering!N14+Submetering!Y14)*0.7362)+(Submetering!O14+Submetering!P14+Submetering!Q14)*0.1488+(Submetering!M14+Submetering!N14+Submetering!Y14)*0.1167+(Submetering!K14+Submetering!L14-Submetering!Z14-Submetering!AA14-Submetering!AB14-Submetering!AC14-Submetering!Q14)+(Submetering!M14+Submetering!N14+Submetering!Y14)*0.1139) -> 63450.001 | F14: 1.27 | G14: =Gas!C15*0.9147 -> 2486.1546 | H14: 3.65 | I14: =Submetering!H14+Submetering!AD14+Submetering!AE14 -> 706 | J14: 10.03 | K14: =ELECT.!B15 -> 245
... A31: Cairo at Nile Plaza | B31: =B30+1 -> 30 | C31: 6 | D31: 2022 | E31: =(((Submetering!O31+Submetering!P31)*0.842284+Submetering!Q31+(Submetering!M31+Submetering!N31+Submetering!Y31)*0.7362)+(Submetering!O31+Submetering!P31+Submetering!Q31)*0.1488+(Submetering!M31+Submetering!N31+Submetering!Y31)*0.1167+(Submetering!K31+Submetering!L31-Submetering!Z31-Submetering!AA31-Submetering!AB31-Submetering!AC31-Submetering!Q31)+(Submetering!M31+Submetering!N31+Submetering!Y31)*0.1139) -> 61917.717 | F31: 1.27 | G31: =Gas!C32*0.9147 -> 1096.7253 | H31: 3.65 | I31: =Submetering!H31+Submetering!AD31+Submetering!AE31 -> 916 | J31: 10.03 | K31: =ELECT.!B32 -> 172

Sheet Submetering
A1: Site Name | B1: Day | C1: Month | D1: Year | E1: Main (m3) | F1: Podium (m3) | G1: Hotel (m3) | H1: Large (m3) | I1: Feeder 1 (KWh) | J1: Feeder 2 (KWh) | K1: T1 (KWh) | L1: T2 (KWh) | M1: T3 (KWh) | N1: T4 (KWh) | O1: T5 (KWh) | P1: T7 (KWh) | Q1: New Chiller (KWh) | R1: Hotel (BTU) | S1: B.S (BTU) | T1: LS (BTU) | U1: Mall (BTU) | V1: AHU#25 (BTU) | W1: AHU#9 (BTU) | X1: Room Nights | Y1: Loss (KWH) | Z1: Mall (KWH) | AA1: Citadel (KWH) | AB1: Rotana (KWH) | AC1: CIB (KWH) | AD1: Plaza suits water consumption (M3) | AE1: Hotel water consumption (M3)
A2: Cairo at Nile Plaza | B2: 1 | C2: 6 | D2: 2022 | E2: =Water!C3 -> 1020 | F2: =Water!E3 -> 480 | G2: =Water!G3 -> 507.6 | H2: =Water!I3 -> 6.021 | I2: =ELECT.!F3 -> 19825 | J2: =ELECT.!H3 -> 52401 | K2: =ELECT.!K3 -> 10750 | L2: =ELECT.!M3 -> 6661 | M2: =ELECT.!O3 -> 8574 | N2: =ELECT.!Q3 -> 14287 | O2: =ELECT.!S3 -> 10742 | P2: =ELECT.!W3*2 -> 22856 | Q2: =ELECT.!D3 -> 480 | R2: =BTU!C3 -> 12.534 | S2: =BTU!F3 -> 2.956 | T2: =BTU!I3 -> 8 | U2: =BTU!O3 -> 1.37 | V2: =BTU!L3 -> 2.02 | W2: =BTU!R3 -> 1.15 | X2: =ELECT.!B3 -> 155 | Y2: =I2+J2-(K2+L2+M2+N2+O2+P2) -> -1644 | Z2: ='Mall, Citadel, Rotana'!C3+'Mall, Citadel, Rotana'!E3+'Mall, Citadel, Rotana'!G3+'Mall, Citadel, Rotana'!I3 -> 1403 | AA2: ='Mall, Citadel, Rotana'!K3+'Mall, Citadel, Rotana'!M3 -> 362 | AB2: ='Mall, Citadel, Rotana'!O3 -> 3 | AC2: ='Mall, Citadel, Rotana'!Q3+'Mall, Citadel, Rotana'!S3 -> 256 | AD2: =(E2-H2-194)*0.1318 -> 108.07323 | AE2: =E2-H2-AD2-194 -> 711.90577
A3: Cairo at Nile Plaza | B3: =B2+1 -> 2 | C3: 6 | D3: 2022 | E3: =Water!C4 -> 1020 | F3: =Water!E4 -> 480 | G3: =Water!G4 -> 507.6 | H3: =Water!I4 -> 6.021 | I3: =ELECT.!F4 -> 24005 | J3: =ELECT.!H4 -> 59214 | K3: =ELECT.!K4 -> 12064 | L3: =ELECT.!M4 -> 7776 | M3: =ELECT.!O4 -> 20406 | N3: =ELECT.!Q4 -> 13822 | O3: =ELECT.!S4 -> 12216 | P3: =ELECT.!W4*2 -> 25888 | Q3: =ELECT.!D4 -> 640 | R3: =BTU!C4 -> 13.179 | S3: =BTU!F4 -> 3.606 | T3: =BTU!I4 -> 8 | U3: =BTU!O4 -> 1.416 | V3: =BTU!L4 -> 2.46 | W3: =BTU!R4 -> 1.29 | X3: =ELECT.!B4 -> 160 | Y3: =I3+J3-(K3+L3+M3+N3+O3+P3) -> -8953 | Z3: ='Mall, Citadel, Rotana'!C4+'Mall, Citadel, Rotana'!E4+'Mall, Citadel, Rotana'!G4+'Mall, Citadel, Rotana'!I4 -> 1532 | AA3: ='Mall, Citadel, Rotana'!K4+'Mall, Citadel, Rotana'!M4 -> 427 | AB3: ='Mall, Citadel, Rotana'!O4 -> 4 | AC3: ='Mall, Citadel, Rotana'!Q4+'Mall, Citadel, Rotana'!S4 -> 264 | AD3: =(E3-H3-194)*0.1318 -> 108.07323 | AE3: =E3-H3-AD3-194 -> 711.90577
A4: Cairo at Nile Plaza | B4: =B3+1 -> 3 | C4: 6 | D4: 2022 | E4: =Water!C5 -> 1050 | F4: =Water!E5 -> 500 | G4: =Water!G5 -> 550.8 | H4: =Water!I5 -> 3.996 | I4: =ELECT.!F5 -> 16297 | J4: =ELECT.!H5 -> 44641 | K4: =ELECT.!K5 -> 8726 | L4: =ELECT.!M5 -> 5467 | M4: =ELECT.!O5 -> 10650 | N4: =ELECT.!Q5 -> 11171 | O4: =ELECT.!S5 -> 9398 | P4: =ELECT.!W5*2 -> 18750 | Q4: =ELECT.!D5 -> 480 | R4: =BTU!C5 -> 12.17 | S4: =BTU!F5 -> 2.256 | T4: =BTU!I5 -> 7 | U4: =BTU!O5 -> 1.48 | V4: =BTU!L5 -> 2.27 | W4: =BTU!R5 -> 1.45 | X4: =ELECT.!B5 -> 276 | Y4: =I4+J4-(K4+L4+M4+N4+O4+P4) -> -3224 | Z4: ='Mall, Citadel, Rotana'!C5+'Mall, Citadel, Rotana'!E5+'Mall, Citadel, Rotana'!G5+'Mall, Citadel, Rotana'!I5 -> 1226 | AA4: ='Mall, Citadel, Rotana'!K5+'Mall, Citadel, Rotana'!M5 -> 228 | AB4: ='Mall, Citadel, Rotana'!O5 -> 3 | AC4: ='Mall, Citadel, Rotana'!Q5+'Mall, Citadel, Rotana'!S5 -> 109 | AD4: =(E4-H4-194)*0.1318 -> 112.29413 | AE4: =E4-H4-AD4-194 -> 739.70987
A5: Cairo at Nile Plaza | B5: =B4+1 -> 4 | C5: 6 | D5: 2022 | E5: =Water!C6 -> 1210 | F5: =Water!E6 -> 530 | G5: =Water!G6 -> 413.1 | H5: =Water!I6 -> 5.13 | I5: =ELECT.!F6 -> 21626 | J5: =ELECT.!H6 -> 54235 | K5: =ELECT.!K6 -> 10308 | L5: =ELECT.!M6 -> 6534 | M5: =ELECT.!O6 -> 14894 | N5: =ELECT.!Q6 -> 13956 | O5: =ELECT.!S6 -> 11278 | P5: =ELECT.!W6*2 -> 22662 | Q5: =ELECT.!D6 -> 480 | R5: =BTU!C6 -> 13.446 | S5: =BTU!F6 -> 2.023 | T5: =BTU!I6 -> 7 | U5: =BTU!O6 -> 1.531 | V5: =BTU!L6 -> 2.35 | W5: =BTU!R6 -> 1.56 | X5: =ELECT.!B6 -> 235 | Y5: =I5+J5-(K5+L5+M5+N5+O5+P5) -> -3771 | Z5: ='Mall, Citadel, Rotana'!C6+'Mall, Citadel, Rotana'!E6+'Mall, Citadel, Rotana'!G6+'Mall, Citadel, Rotana'!I6 -> 1362 | AA5: ='Mall, Citadel, Rotana'!K6+'Mall, Citadel, Rotana'!M6 -> 252 | AB5: ='Mall, Citadel, Rotana'!O6 -> 3 | AC5: ='Mall, Citadel, Rotana'!Q6+'Mall, Citadel, Rotana'!S6 -> 115 | AD5: =(E5-H5-194)*0.1318 -> 133.23267 | AE5: =E5-H5-AD5-194 -> 877.63733
A6: Cairo at Nile Plaza | B6: =B5+1 -> 5 | C6: 6 | D6: 2022 | E6: =Water!C7 -> 1030 | F6: =Water!E7 -> 550 | G6: =Water!G7 -> 729 | H6: =Water!I7 -> 5.427 | I6: =ELECT.!F7 -> 19401 | J6: =ELECT.!H7 -> 47850 | K6: =ELECT.!K7 -> 9798 | L6: =ELECT.!M7 -> 5879 | M6: =ELECT.!O7 -> 13342 | N6: =ELECT.!Q7 -> 12512 | O6: =ELECT.!S7 -> 9892 | P6: =ELECT.!W7*2 -> 19584 | Q6: =ELECT.!D7 -> 800 | R6: =BTU!C7 -> 13.582 | S6: =BTU!F7 -> 2.53 | T6: =BTU!I7 -> 8 | U6: =BTU!O7 -> 1.466 | V6: =BTU!L7 -> 2.22 | W6: =BTU!R7 -> 1.54 | X6: =ELECT.!B7 -> 209 | Y6: =I6+J6-(K6+L6+M6+N6+O6+P6) -> -3756 | Z6: ='Mall, Citadel, Rotana'!C7+'Mall, Citadel, Rotana'!E7+'Mall, Citadel, Rotana'!G7+'Mall, Citadel, Rotana'!I7 -> 1342 | AA6: ='Mall, Citadel, Rotana'!K7+'Mall, Citadel, Rotana'!M7 -> 406 | AB6: ='Mall, Citadel, Rotana'!O7 -> 3 | AC6: ='Mall, Citadel, Rotana'!Q7+'Mall, Citadel, Rotana'!S7 -> 119 | AD6: =(E6-H6-194)*0.1318 -> 109.46952 | AE6: =E6-H6-AD6-194 -> 721.10348
A7: Cairo at Nile Plaza | B7: =B6+1 -> 6 | C7: 6 | D7: 2022 | E7: =Water!C8 -> 1090 | F7: =Water!E8 -> 490 | G7: =Water!G8 -> 502.2 | H7: =Water!I8 -> 5.265 | I7: =ELECT.!F8 -> 25415 | J7: =ELECT.!H8 -> 100837 | K7: =ELECT.!K8 -> 11828 | L7: =ELECT.!M8 -> 7994 | M7: =ELECT.!O8 -> 17222 | N7: =ELECT.!Q8 -> 15376 | O7: =ELECT.!S8 -> 12323 | P7: =ELECT.!W8*2 -> 25162 | Q7: =ELECT.!D8 -> 640 | R7: =BTU!C8 -> 19.067 | S7: =BTU!F8 -> 4.29 | T7: =BTU!I8 -> 12 | U7: =BTU!O8 -> 2.277 | V7: =BTU!L8 -> 3.6 | W7: =BTU!R8 -> 0.59 | X7: =ELECT.!B8 -> 224 | Y7: =I7+J7-(K7+L7+M7+N7+O7+P7) -> 36347 | Z7: ='Mall, Citadel, Rotana'!C8+'Mall, Citadel, Rotana'!E8+'Mall, Citadel, Rotana'!G8+'Mall, Citadel, Rotana'!I8 -> 1250 | AA7: ='Mall, Citadel, Rotana'!K8+'Mall, Citadel, Rotana'!M8 -> 347 | AB7: ='Mall, Citadel, Rotana'!O8 -> 3 | AC7: ='Mall, Citadel, Rotana'!Q8+'Mall, Citadel, Rotana'!S8 -> 0 | AD7: =(E7-H7-194)*0.1318 -> 117.39887 | AE7: =E7-H7-AD7-194 -> 773.33613
A8: Cairo at Nile Plaza | B8: =B7+1 -> 7 | C8: 6 | D8: 2022 | E8: =Water!C9 -> 1170 | F8: =Water!E9 -> 580 | G8: =Water!G9 -> 548.1 | H8: =Water!I9 -> 5.562 | I8: =ELECT.!F9 -> 17177 | J8: =ELECT.!H9 -> 0 | K8: =ELECT.!K9 -> 8656 | L8: =ELECT.!M9 -> 5452 | M8: =ELECT.!O9 -> 11552 | N8: =ELECT.!Q9 -> 10142 | O8: =ELECT.!S9 -> 8298 | P8: =ELECT.!W9*2 -> 17222 | Q8: =ELECT.!D9 -> 640 | R8: =BTU!C9 -> 9.058 | S8: =BTU!F9 -> 2.253 | T8: =BTU!I9 -> 5 | U8: =BTU!O9 -> 0.899 | V8: =BTU!L9 -> 1.28 | W8: =BTU!R9 -> 3.45 | X8: =ELECT.!B9 -> 228 | Y8: =I8+J8-(K8+L8+M8+N8+O8+P8) -> -44145 | Z8: ='Mall, Citadel, Rotana'!C9+'Mall, Citadel, Rotana'!E9+'Mall, Citadel, Rotana'!G9+'Mall, Citadel, Rotana'!I9 -> 1536 | AA8: ='Mall, Citadel, Rotana'!K9+'Mall, Citadel, Rotana'!M9 -> 344 | AB8: ='Mall, Citadel, Rotana'!O9 -> 4 | AC8: ='Mall, Citadel, Rotana'!Q9+'Mall, Citadel, Rotana'!S9 -> -115 | AD8: =(E8-H8-194)*0.1318 -> 127.90373 | AE8: =E8-H8-AD8-194 -> 842.53427
A9: Cairo at Nile Plaza | B9: =B8+1 -> 8 | C9: 6 | D9: 2022 | E9: =Water!C10 -> 1170 | F9: =Water!E10 -> 630 | G9: =Water!G10 -> 583.2 | H9: =Water!I10 -> 6.156 | I9: =ELECT.!F10 -> 24528 | J9: =ELECT.!H10 -> 59527 | K9: =ELECT.!K10 -> 11474 | L9: =ELECT.!M10 -> 7608 | M9: =ELECT.!O10 -> 16712 | N9: =ELECT.!Q10 -> 21392 | O9: =ELECT.!S10 -> 11959 | P9: =ELECT.!W10*2 -> 56926 | Q9: =ELECT.!D10 -> 640 | R9: =BTU!C10 -> 11.936 | S9: =BTU!F10 -> 2.862 | T9: =BTU!I10 -> 7 | U9: =BTU!O10 -> 1.358 | V9: =BTU!L10 -> 2.11 | W9: =BTU!R10 -> 1.27 | X9: =ELECT.!B10 -> 230 | Y9: =I9+J9-(K9+L9+M9+N9+O9+P9) -> -42016 | Z9: ='Mall, Citadel, Rotana'!C10+'Mall, Citadel, Rotana'!E10+'Mall, Citadel, Rotana'!G10+'Mall, Citadel, Rotana'!I10 -> 1384 | AA9: ='Mall, Citadel, Rotana'!K10+'Mall, Citadel, Rotana'!M10 -> 470 | AB9: ='Mall, Citadel, Rotana'!O10 -> 3 | AC9: ='Mall, Citadel, Rotana'!Q10+'Mall, Citadel, Rotana'!S10 -> 105 | AD9: =(E9-H9-194)*0.1318 -> 127.82544 | AE9: =E9-H9-AD9-194 -> 842.01856
A10: Cairo at Nile Plaza | B10: =B9+1 -> 9 | C10: 6 | D10: 2022 | E10: =Water!C11 -> 1170 | F10: =Water!E11 -> 630 | G10: =Water!G11 -> 583.2 | H10: =Water!I11 -> 6.156 | I10: =ELECT.!F11 -> 24861 | J10: =ELECT.!H11 -> 61172 | K10: =ELECT.!K11 -> 11820 | L10: =ELECT.!M11 -> 7833 | M10: =ELECT.!O11 -> 16832 | N10: =ELECT.!Q11 -> 9363 | O10: =ELECT.!S11 -> 12044 | P10: =ELECT.!W11*2 -> 6604 | Q10: =ELECT.!D11 -> 480 | R10: =BTU!C11 -> 13.729 | S10: =BTU!F11 -> 3.49 | T10: =BTU!I11 -> 9 | U10: =BTU!O11 -> 1.602 | V10: =BTU!L11 -> 2.46 | W10: =BTU!R11 -> 2.1 | X10: =ELECT.!B11 -> 221 | Y10: =I10+J10-(K10+L10+M10+N10+O10+P10) -> 21537 | Z10: ='Mall, Citadel, Rotana'!C11+'Mall, Citadel, Rotana'!E11+'Mall, Citadel, Rotana'!G11+'Mall, Citadel, Rotana'!I11 -> 1262 | AA10: ='Mall, Citadel, Rotana'!K11+'Mall, Citadel, Rotana'!M11 -> 464 | AB10: ='Mall, Citadel, Rotana'!O11 -> 3 | AC10: ='Mall, Citadel, Rotana'!Q11+'Mall, Citadel, Rotana'!S11 -> 120 | AD10: =(E10-H10-194)*0.1318 -> 127.82544 | AE10: =E10-H10-AD10-194 -> 842.01856
A11: Cairo at Nile Plaza | B11: =B10+1 -> 10 | C11: 6 | D11: 2022 | E11: =Water!C12 -> 1060 | F11: =Water!E12 -> 260 | G11: =Water!G12 -> 480.6 | H11: =Water!I12 -> 3.834 | I11: =ELECT.!F12 -> 19544 | J11: =ELECT.!H12 -> 47685 | K11: =ELECT.!K12 -> 8970 | L11: =ELECT.!M12 -> 5998 | M11: =ELECT.!O12 -> 13344 | N11: =ELECT.!Q12 -> 11960 | O11: =ELECT.!S12 -> 9287 | P11: =ELECT.!W12*2 -> 8896 | Q11: =ELECT.!D12 -> 960 | R11: =BTU!C12 -> 12.348 | S11: =BTU!F12 -> 1.689 | T11: =BTU!I12 -> 7 | U11: =BTU!O12 -> 1.446 | V11: =BTU!L12 -> 1.97 | W11: =BTU!R12 -> 2.1 | X11: =ELECT.!B12 -> 223 | Y11: =I11+J11-(K11+L11+M11+N11+O11+P11) -> 8774 | Z11: ='Mall, Citadel, Rotana'!C12+'Mall, Citadel, Rotana'!E12+'Mall, Citadel, Rotana'!G12+'Mall, Citadel, Rotana'!I12 -> 1355 | AA11: ='Mall, Citadel, Rotana'!K12+'Mall, Citadel, Rotana'!M12 -> 195 | AB11: ='Mall, Citadel, Rotana'!O12 -> 3 | AC11: ='Mall, Citadel, Rotana'!Q12+'Mall, Citadel, Rotana'!S12 -> 121 | AD11: =(E11-H11-194)*0.1318 -> 113.63348 | AE11: =E11-H11-AD11-194 -> 748.53252
A12: Cairo at Nile Plaza | B12: =B11+1 -> 11 | C12: 6 | D12: 2022 | E12: =Water!C13 -> 1070 | F12: =Water!E13 -> 450 | G12: =Water!G13 -> 572.4 | H12: =Water!I13 -> 5.94 | I12: =ELECT.!F13 -> 19496 | J12: =ELECT.!H13 -> 47369 | K12: =ELECT.!K13 -> 9100 | L12: =ELECT.!M13 -> 6039 | M12: =ELECT.!O13 -> 13290 | N12: =ELECT.!Q13 -> 12060 | O12: =ELECT.!S13 -> 9541 | P12: =ELECT.!W13*2 -> 20150 | Q12: =ELECT.!D13 -> 480 | R12: =BTU!C13 -> 19.306 | S12: =BTU!F13 -> 2.8 | T12: =BTU!I13 -> 11 | U12: =BTU!O13 -> 1.966 | V12: =BTU!L13 -> 3.52 | W12: =BTU!R13 -> 1.58 | X12: =ELECT.!B13 -> 182 | Y12: =I12+J12-(K12+L12+M12+N12+O12+P12) -> -3315 | Z12: ='Mall, Citadel, Rotana'!C13+'Mall, Citadel, Rotana'!E13+'Mall, Citadel, Rotana'!G13+'Mall, Citadel, Rotana'!I13 -> 1223 | AA12: ='Mall, Citadel, Rotana'!K13+'Mall, Citadel, Rotana'!M13 -> 262 | AB12: ='Mall, Citadel, Rotana'!O13 -> 3 | AC12: ='Mall, Citadel, Rotana'!Q13+'Mall, Citadel, Rotana'!S13 -> 118 | AD12: =(E12-H12-194)*0.1318 -> 114.67391 | AE12: =E12-H12-AD12-194 -> 755.38609
A13: Cairo at Nile Plaza | B13: =B12+1 -> 12 | C13: 6 | D13: 2022 | E13: =Water!C14 -> 1050 | F13: =Water!E14 -> 450 | G13: =Water!G14 -> 488.7 | H13: =Water!I14 -> 6.453 | I13: =ELECT.!F14 -> 27513 | J13: =ELECT.!H14 -> 65371 | K13: =ELECT.!K14 -> 12712 | L13: =ELECT.!M14 -> 8723 | M13: =ELECT.!O14 -> 18542 | N13: =ELECT.!Q14 -> 16444 | O13: =ELECT.!S14 -> 11052 | P13: =ELECT.!W14*2 -> 27744 | Q13: =ELECT.!D14 -> 960 | R13: =BTU!C14 -> 11.757 | S13: =BTU!F14 -> 3.298 | T13: =BTU!I14 -> 7 | U13: =BTU!O14 -> 1.289 | V13: =BTU!L14 -> 1.95 | W13: =BTU!R14 -> 1.34 | X13: =ELECT.!B14 -> 205 | Y13: =I13+J13-(K13+L13+M13+N13+O13+P13) -> -2333 | Z13: ='Mall, Citadel, Rotana'!C14+'Mall, Citadel, Rotana'!E14+'Mall, Citadel, Rotana'!G14+'Mall, Citadel, Rotana'!I14 -> 1508 | AA13: ='Mall, Citadel, Rotana'!K14+'Mall, Citadel, Rotana'!M14 -> 321 | AB13: ='Mall, Citadel, Rotana'!O14 -> 4 | AC13: ='Mall, Citadel, Rotana'!Q14+'Mall, Citadel, Rotana'!S14 -> 112 | AD13: =(E13-H13-194)*0.1318 -> 111.97029 | AE13: =E13-H13-AD13-194 -> 737.57671
A14: Cairo at Nile Plaza | B14: =B13+1 -> 13 | C14: 6 | D14: 2022 | E14: =Water!C15 -> 900 | F14: =Water!E15 -> 450 | G14: =Water!G15 -> 510.3 | H14: =Water!I15 -> 5.697 | I14: =ELECT.!F15 -> 19518 | J14: =ELECT.!H15 -> 46549 | K14: =ELECT.!K15 -> 9846 | L14: =ELECT.!M15 -> 6489 | M14: =ELECT.!O15 -> 12870 | N14: =ELECT.!Q15 -> 11452 | O14: =ELECT.!S15 -> 11624 | P14: =ELECT.!W15*2 -> 19922 | Q14: =ELECT.!D15 -> 800 | R14: =BTU!C15 -> 9.976 | S14: =BTU!F15 -> 2.23 | T14: =BTU!I15 -> 6 | U14: =BTU!O15 -> 1.009 | V14: =BTU!L15 -> 1.41 | W14: =BTU!R15 -> 4.96 | X14: =ELECT.!B15 -> 245 | Y14: =I14+J14-(K14+L14+M14+N14+O14+P14) -> -6136 | Z14: ='Mall, Citadel, Rotana'!C15+'Mall, Citadel, Rotana'!E15+'Mall, Citadel, Rotana'!G15+'Mall, Citadel, Rotana'!I15 -> 1352 | AA14: ='Mall, Citadel, Rotana'!K15+'Mall, Citadel, Rotana'!M15 -> 450 | AB14: ='Mall, Citadel, Rotana'!O15 -> 3 | AC14: ='Mall, Citadel, Rotana'!Q15+'Mall, Citadel, Rotana'!S15 -> 46 | AD14: =(E14-H14-194)*0.1318 -> 92.299935 | AE14: =E14-H14-AD14-194 -> 608.00306
... A31: Cairo at Nile Plaza | B31: =B30+1 -> 30 | C31: 6 | D31: 2022 | E31: =Water!C32 -> 1110 | F31: =Water!E32 -> 470 | G31: =Water!G32 -> 267.3 | H31: =Water!I32 -> 4.941 | I31: =ELECT.!F32 -> 18559 | J31: =ELECT.!H32 -> 45794 | K31: =ELECT.!K32 -> 7466 | L31: =ELECT.!M32 -> 5397 | M31: =ELECT.!O32 -> 13008 | N31: =ELECT.!Q32 -> 11840 | O31: =ELECT.!S32 -> 8695 | P31: =ELECT.!W32*2 -> 19758 | Q31: =ELECT.!D32 -> 640 | R31: =BTU!C32 -> 13.214 | S31: =BTU!F32 -> 2.182 | T31: =BTU!I32 -> 7 | U31: =BTU!O32 -> 1.696 | V31: =BTU!L32 -> 1.99 | W31: =BTU!R32 -> 2.24 | X31: =ELECT.!B32 -> 172 | Y31: =I31+J31-(K31+L31+M31+N31+O31+P31) -> -1811 | Z31: ='Mall, Citadel, Rotana'!C32+'Mall, Citadel, Rotana'!E32+'Mall, Citadel, Rotana'!G32+'Mall, Citadel, Rotana'!I32 -> 1264 | AA31: ='Mall, Citadel, Rotana'!K32+'Mall, Citadel, Rotana'!M32 -> 148 | AB31: ='Mall, Citadel, Rotana'!O32 -> 3 | AC31: ='Mall, Citadel, Rotana'!Q32+'Mall, Citadel, Rotana'!S32 -> 97 | AD31: =(E31-H31-194)*0.1318 -> 120.07758 | AE31: =E31-H31-AD31-194 -> 790.98142

Sheet Mall, Citadel, Rotana
A1: Day | B1: R1 | C1: Cons | D1: R2 | E1: Cons | F1: R3 | G1: Cons | H1: R4 | I1: Cons | J1: RO1 | K1: Cons | L1: RO2 | M1: Cons | N1: ROE | O1: Cons | P1: CIB. 1 | Q1: Cons | R1: CIB. E | S1: Cons | T1: Co | U1: Cons
A2: 44712 | B2: 47087 | D2: 40638 | F2: 21687 | H2: 255299 | J2: 316404 | L2: 26171 | N2: 226036 | P2: 154366 | R2: 55047 | T2: 3997
A3: 44713 | B3: 47092 | C3: =(B3-B2)*800/5 -> 800 | D3: 40641 | E3: =(D3-D2)*800/5 -> 480 | F3: 21692 | G3: =(F3-F2)*100/5 -> 100 | H3: 255322 | I3: =(H3-H2) -> 23 | J3: 316586 | K3: =(J3-J2) -> 182 | L3: 26174 | M3: =(L3-L2)*300/5 -> 180 | N3: 226039 | O3: =N3-N2 -> 3 | P3: 154622 | Q3: =P3-P2 -> 256 | R3: 55047 | S3: 0 | T3: 3998 | U3: =(T3-T2)*800/5 -> 160
A4: 44714 | B4: 47097 | C4: =(B4-B3)*800/5 -> 800 | D4: 40645 | E4: =(D4-D3)*800/5 -> 640 | F4: 21695 | G4: =(F4-F3)*100/5 -> 60 | H4: 255354 | I4: =(H4-H3) -> 32 | J4: 316773 | K4: =(J4-J3) -> 187 | L4: 26178 | M4: =(L4-L3)*300/5 -> 240 | N4: 226043 | O4: =N4-N3 -> 4 | P4: 154886 | Q4: =P4-P3 -> 264 | R4: =R3 -> 55047 | S4: =R4-R3 -> 0 | T4: 3999 | U4: =(T4-T3)*800/5 -> 160
A5: 44715 | B5: 47101 | C5: =(B5-B4)*800/5 -> 640 | D5: 40648 | E5: =(D5-D4)*800/5 -> 480 | F5: 21699 | G5: =(F5-F4)*100/5 -> 80 | H5: 255380 | I5: =(H5-H4) -> 26 | J5: 316881 | K5: =(J5-J4) -> 108 | L5: 26180 | M5: =(L5-L4)*300/5 -> 120 | N5: 226046 | O5: =N5-N4 -> 3 | P5: 154995 | Q5: =P5-P4 -> 109 | R5: 55047 | S5: =R5-R4 -> 0 | T5: 3999 | U5: =(T5-T4)*800/5 -> 0
A6: 44716 | B6: 47106 | C6: =(B6-B5)*800/5 -> 800 | D6: 40651 | E6: =(D6-D5)*800/5 -> 480 | F6: 21702 | G6: =(F6-F5)*100/5 -> 60 | H6: 255402 | I6: =(H6-H5) -> 22 | J6: 317013 | K6: =(J6-J5) -> 132 | L6: 26182 | M6: =(L6-L5)*300/5 -> 120 | N6: 226049 | O6: =N6-N5 -> 3 | P6: 155110 | Q6: =P6-P5 -> 115 | R6: =R5 -> 55047 | S6: 0 | T6: 4000 | U6: =(T6-T5)*800/5 -> 160
A7: 44717 | B7: 47111 | C7: =(B7-B6)*800/5 -> 800 | D7: 40654 | E7: =(D7-D6)*800/5 -> 480 | F7: 21704 | G7: =(F7-F6)*100/5 -> 40 | H7: 255424 | I7: =(H7-H6) -> 22 | J7: 317179 | K7: =(J7-J6) -> 166 | L7: 26186 | M7: =(L7-L6)*300/5 -> 240 | N7: 226052 | O7: =N7-N6 -> 3 | P7: 155229 | Q7: =P7-P6 -> 119 | R7: =R6 -> 55047 | S7: 0 | T7: =T6 -> 4000 | U7: =(T7-T6)*800/5 -> 0
A8: 44718 | B8: 47115 | C8: =(B8-B7)*800/5 -> 640 | D8: 40657 | E8: =(D8-D7)*800/5 -> 480 | F8: 21709 | G8: =(F8-F7)*100/5 -> 100 | H8: 255454 | I8: =(H8-H7) -> 30 | J8: 317346 | K8: =(J8-J7) -> 167 | L8: 26189 | M8: =(L8-L7)*300/5 -> 180 | N8: 226055 | O8: =N8-N7 -> 3 | P8: =P7 -> 155229 | Q8: =P8-P7 -> 0 | R8: =R7 -> 55047 | S8: =R8-R7 -> 0 | T8: 4001 | U8: =(T8-T7)*800/5 -> 160
A9: 44719 | B9: 47120 | C9: =(B9-B8)*800/5 -> 800 | D9: 40661 | E9: =(D9-D8)*800/5 -> 640 | F9: 21712 | G9: =(F9-F8)*100/5 -> 60 | H9: 255490 | I9: =(H9-H8) -> 36 | J9: 317510 | K9: =(J9-J8) -> 164 | L9: 26192 | M9: =(L9-L8)*300/5 -> 180 | N9: 226059 | O9: =N9-N8 -> 4 | P9: 155114 | Q9: =P9-P8 -> -115 | R9: =R8 -> 55047 | S9: =R9-R8 -> 0 | T9: 4002 | U9: =(T9-T8)*800/5 -> 160
A10: 44720 | B10: 47125 | C10: =(B10-B9)*800/5 -> 800 | D10: 40664 | E10: =(D10-D9)*800/5 -> 480 | F10: 21716 | G10: =(F10-F9)*100/5 -> 80 | H10: 255514 | I10: =(H10-H9) -> 24 | J10: 317680 | K10: =(J10-J9) -> 170 | L10: 26197 | M10: =(L10-L9)*300/5 -> 300 | N10: 226062 | O10: =N10-N9 -> 3 | P10: 155219 | Q10: =P10-P9 -> 105 | R10: 55047 | S10: =R10-R9 -> 0 | T10: =T9 -> 4002 | U10: =(T10-T9)*800/5 -> 0
A11: 44721 | B11: 47129 | C11: =(B11-B10)*800/5 -> 640 | D11: 40667 | E11: =(D11-D10)*800/5 -> 480 | F11: 21723 | G11: =(F11-F10)*100/5 -> 140 | H11: 255516 | I11: =(H11-H10) -> 2 | J11: 317844 | K11: =(J11-J10) -> 164 | L11: 26202 | M11: =(L11-L10)*300/5 -> 300 | N11: 226065 | O11: =N11-N10 -> 3 | P11: 155339 | Q11: =P11-P10 -> 120 | R11: =R10 -> 55047 | S11: =R11-R10 -> 0 | T11: 4003 | U11: =(T11-T10)*800/5 -> 160
A12: 44722 | B12: 47134 | C12: =(B12-B11)*800/5 -> 800 | D12: 40670 | E12: =(D12-D11)*800/5 -> 480 | F12: 21724 | G12: =(F12-F11)*100/5 -> 20 | H12: 255571 | I12: =(H12-H11) -> 55 | J12: 317979 | K12: =(J12-J11) -> 135 | L12: 26203 | M12: =(L12-L11)*300/5 -> 60 | N12: 226068 | O12: =N12-N11 -> 3 | P12: 155460 | Q12: =P12-P11 -> 121 | R12: =R11 -> 55047 | S12: =R12-R11 -> 0 | T12: 4004 | U12: =(T12-T11)*800/5 -> 160
A13: 44723 | B13: 47138 | C13: =(B13-B12)*800/5 -> 640 | D13: 40673 | E13: =(D13-D12)*800/5 -> 480 | F13: 21727 | G13: =(F13-F12)*100/5 -> 60 | H13: 255614 | I13: =(H13-H12) -> 43 | J13: 318121 | K13: =(J13-J12) -> 142 | L13: 26205 | M13: =(L13-L12)*300/5 -> 120 | N13: 226071 | O13: =N13-N12 -> 3 | P13: 155578 | Q13: =P13-P12 -> 118 | R13: =R12 -> 55047 | S13: =R13-R12 -> 0 | T13: 4005 | U13: =(T13-T12)*800/5 -> 160
A14: 44724 | B14: 47143 | C14: =(B14-B13)*800/5 -> 800 | D14: 40677 | E14: =(D14-D13)*800/5 -> 640 | F14: 21730 | G14: =(F14-F13)*100/5 -> 60 | H14: 255622 | I14: =(H14-H13) -> 8 | J14: 318202 | K14: =(J14-J13) -> 81 | L14: 26209 | M14: =(L14-L13)*300/5 -> 240 | N14: 226075 | O14: =N14-N13 -> 4 | P14: 155690 | Q14: =P14-P13 -> 112 | R14: =R13 -> 55047 | S14: 0 | T14: 4006 | U14: =(T14-T13)*800/5 -> 160
A15: 44725 | B15: 47148 | C15: =(B15-B14)*800/5 -> 800 | D15: 40680 | E15: =(D15-D14)*800/5 -> 480 | F15: 21733 | G15: =(F15-F14)*100/5 -> 60 | H15: 255634 | I15: =(H15-H14) -> 12 | J15: 318472 | K15: =(J15-J14) -> 270 | L15: 26212 | M15: =(L15-L14)*300/5 -> 180 | N15: 226078 | O15: =N15-N14 -> 3 | P15: 155736 | Q15: =P15-P14 -> 46 | R15: =R14 -> 55047 | S15: 0 | T15: 4006 | U15: =(T15-T14)*800/5 -> 0
A16: 44726 | B16: 47153 | C16: =(B16-B15)*800/5 -> 800 | D16: 40683 | E16: =(D16-D15)*800/5 -> 480 | F16: 21736 | G16: =(F16-F15)*100/5 -> 60 | H16: 255653 | I16: =(H16-H15) -> 19 | J16: 318649 | K16: =(J16-J15) -> 177 | L16: 26216 | M16: =(L16-L15)*300/5 -> 240 | N16: 226081 | O16: =N16-N15 -> 3 | P16: 155890 | Q16: =P16-P15 -> 154 | R16: =R15 -> 55047 | S16: =R16-R15 -> 0 | T16: =T15 -> 4006 | U16: =(T16-T15)*800/5 -> 0
A17: 44727 | B17: 47158 | C17: =(B17-B16)*800/5 -> 800 | D17: 40686 | E17: =(D17-D16)*800/5 -> 480 | F17: 21740 | G17: =(F17-F16)*100/5 -> 80 | H17: 255678 | I17: =(H17-H16) -> 25 | J17: 318817 | K17: =(J17-J16) -> 168 | L17: 26219 | M17: =(L17-L16)*300/5 -> 180 | N17: 226084 | O17: =N17-N16 -> 3 | P17: =P16 -> 155890 | Q17: =P17-P16 -> 0 | R17: =R16 -> 55047 | S17: =S16 -> 0 | T17: 4007 | U17: =(T17-T16)*800/5 -> 160
A18: 44728 | B18: 47163 | C18: =(B18-B17)*800/5 -> 800 | D18: 40690 | E18: =(D18-D17)*800/5 -> 640 | F18: 21743 | G18: =(F18-F17)*100/5 -> 60 | H18: 255707 | I18: =(H18-H17) -> 29 | J18: 319010 | K18: =(J18-J17) -> 193 | L18: 26223 | M18: =(L18-L17)*300/5 -> 240 | N18: 226087 | O18: =N18-N17 -> 3 | P18: =P17 -> 155890 | Q18: =P18-P17 -> 0 | R18: =R17 -> 55047 | S18: =R18-R17 -> 0 | T18: =T17 -> 4007 | U18: =(T18-T17)*800/5 -> 0
A19: 44729 | B19: 47167 | C19: =(B19-B18)*800/5 -> 640 | D19: 40693 | E19: =(D19-D18)*800/5 -> 480 | F19: 21747 | G19: =(F19-F18)*100/5 -> 80 | H19: 255736 | I19: =(H19-H18) -> 29 | J19: 319124 | K19: =(J19-J18) -> 114 | L19: 26225 | M19: =(L19-L18)*300/5 -> 120 | N19: 226090 | O19: =N19-N18 -> 3 | P19: =P18 -> 155890 | Q19: =P19-P18 -> 0 | R19: =R18 -> 55047 | S19: =R19-R18 -> 0 | T19: 4008 | U19: =(T19-T18)*800/5 -> 160
A20: 44730 | B20: 47172 | C20: =(B20-B19)*800/5 -> 800 | D20: 40696 | E20: =(D20-D19)*800/5 -> 480 | F20: 21752 | G20: =(F20-F19)*100/5 -> 100 | H20: 255754 | I20: =(H20-H19) -> 18 | J20: 319276 | K20: =(J20-J19) -> 152 | L20: 26227 | M20: =(L20-L19)*300/5 -> 120 | N20: 226094 | O20: =N20-N19 -> 4 | P20: =P19 -> 155890 | Q20: =P20-P19 -> 0 | R20: =R19 -> 55047 | S20: =R20-R19 -> 0 | T20: =T19 -> 4008 | U20: =(T20-T19)*800/5 -> 0
A21: 44731 | B21: 47177 | C21: =(B21-B20)*800/5 -> 800 | D21: 40699 | E21: =(D21-D20)*800/5 -> 480 | F21: 21755 | G21: =(F21-F20)*100/5 -> 60 | H21: 255774 | I21: =(H21-H20) -> 20 | J21: 319434 | K21: =(J21-J20) -> 158 | L21: 26231 | M21: =(L21-L20)*300/5 -> 240 | N21: 226097 | O21: =N21-N20 -> 3 | P21: 156904 | Q21: =P21-P20 -> 1014 | R21: =R20 -> 55047 | S21: =R21-R20 -> 0 | T21: 4009 | U21: =(T21-T20)*800/5 -> 160
A22: 44732 | B22: 47182 | C22: =(B22-B21)*800/5 -> 800 | D22: 40702 | E22: =(D22-D21)*800/5 -> 480 | F22: 21758 | G22: =(F22-F21)*100/5 -> 60 | H22: 255795 | I22: =(H22-H21) -> 21 | J22: 319601 | K22: =(J22-J21) -> 167 | L22: 26234 | M22: =(L22-L21)*300/5 -> 180 | N22: 226100 | O22: =N22-N21 -> 3 | P22: 157048 | Q22: =P22-P21 -> 144 | R22: =R21 -> 55047 | S22: =R22-R21 -> 0 | T22: 4009 | U22: =(T22-T21)*800/5 -> 0
A23: 44733 | B23: 47186 | C23: =(B23-B22)*800/5 -> 640 | D23: 40705 | E23: =(D23-D22)*800/5 -> 480 | F23: 21761 | G23: =(F23-F22)*100/5 -> 60 | H23: 255819 | I23: =(H23-H22) -> 24 | J23: 319767 | K23: =(J23-J22) -> 166 | L23: 26237 | M23: =(L23-L22)*300/5 -> 180 | N23: 226103 | O23: =N23-N22 -> 3 | P23: 157204 | Q23: =P23-P22 -> 156 | R23: =R22 -> 55047 | S23: =R23-R22 -> 0 | T23: 4010 | U23: =(T23-T22)*800/5 -> 160
A24: 44734 | B24: 47191 | C24: =(B24-B23)*800/5 -> 800 | D24: 40709 | E24: =(D24-D23)*800/5 -> 640 | F24: 21764 | G24: =(F24-F23)*100/5 -> 60 | H24: 255868 | I24: =(H24-H23) -> 49 | J24: 319936 | K24: =(J24-J23) -> 169 | L24: 26241 | M24: =(L24-L23)*300/5 -> 240 | N24: 226106 | O24: =N24-N23 -> 3 | P24: 157350 | Q24: =P24-P23 -> 146 | R24: =R23 -> 55047 | S24: =R24-R23 -> 0 | T24: 4011 | U24: =(T24-T23)*800/5 -> 160
A25: 44735 | B25: 47196 | C25: =(B25-B24)*800/5 -> 800 | D25: 40712 | E25: =(D25-D24)*800/5 -> 480 | F25: 21768 | G25: =(F25-F24)*100/5 -> 80 | H25: 255889 | I25: =(H25-H24) -> 21 | J25: 320103 | K25: =(J25-J24) -> 167 | L25: 26244 | M25: =(L25-L24)*300/5 -> 180 | N25: 226110 | O25: =N25-N24 -> 4 | P25: 157501 | Q25: =P25-P24 -> 151 | R25: =R24 -> 55047 | S25: =R25-R24 -> 0 | T25: 4011 | U25: =(T25-T24)*800/5 -> 0
A26: 44736 | B26: 47201 | C26: =(B26-B25)*800/5 -> 800 | D26: 40715 | E26: =(D26-D25)*800/5 -> 480 | F26: 21772 | G26: =(F26-F25)*100/5 -> 80 | H26: 255917 | I26: =(H26-H25) -> 28 | J26: 320205 | K26: =(J26-J25) -> 102 | L26: 26246 | M26: =(L26-L25)*300/5 -> 120 | N26: 226113 | O26: =N26-N25 -> 3 | P26: 157715 | Q26: =P26-P25 -> 214 | R26: =R25 -> 55047 | S26: =R26-R25 -> 0 | T26: 4012 | U26: =(T26-T25)*800/5 -> 160
A27: 44737 | B27: 47205 | C27: =(B27-B26)*800/5 -> 640 | D27: 40718 | E27: =(D27-D26)*800/5 -> 480 | F27: 21776 | G27: =(F27-F26)*100/5 -> 80 | H27: 255962 | I27: =(H27-H26) -> 45 | J27: 320346 | K27: =(J27-J26) -> 141 | L27: 26249 | M27: =(L27-L26)*300/5 -> 180 | N27: 226116 | O27: =N27-N26 -> 3 | P27: 157924 | Q27: =P27-P26 -> 209 | R27: =R26 -> 55047 | S27: =R27-R26 -> 0 | T27: 4012 | U27: =(T27-T26)*800/5 -> 0
A28: 44738 | B28: 47210 | C28: =(B28-B27)*800/5 -> 800 | D28: 40723 | E28: =(D28-D27)*800/5 -> 800 | F28: 21779 | G28: =(F28-F27)*100/5 -> 60 | H28: 255987 | I28: =(H28-H27) -> 25 | J28: 320517 | K28: =(J28-J27) -> 171 | L28: 26252 | M28: =(L28-L27)*300/5 -> 180 | N28: 226119 | O28: =N28-N27 -> 3 | P28: 158046 | Q28: =P28-P27 -> 122 | R28: =R27 -> 55047 | S28: =R28-R27 -> 0 | T28: 4013 | U28: =(T28-T27)*800/5 -> 160
A29: 44739 | B29: 47215 | C29: =(B29-B28)*800/5 -> 800 | D29: 40725 | E29: =(D29-D28)*800/5 -> 320 | F29: 21783 | G29: =(F29-F28)*100/5 -> 80 | H29: 256016 | I29: =(H29-H28) -> 29 | J29: 320682 | K29: =(J29-J28) -> 165 | L29: 26256 | M29: =(L29-L28)*300/5 -> 240 | N29: 226122 | O29: =N29-N28 -> 3 | P29: 158154 | Q29: =P29-P28 -> 108 | R29: =R28 -> 55047 | S29: =R29-R28 -> 0 | T29: 4013 | U29: =(T29-T28)*800/5 -> 0
A30: 44740 | B30: 47220 | C30: =(B30-B29)*800/5 -> 800 | D30: 40728 | E30: =(D30-D29)*800/5 -> 480 | F30: 21786 | G30: =(F30-F29)*100/5 -> 60 | H30: 256036 | I30: =(H30-H29) -> 20 | J30: 320853 | K30: =(J30-J29) -> 171 | L30: 26259 | M30: =(L30-L29)*300/5 -> 180 | N30: 226126 | O30: =N30-N29 -> 4 | P30: 158299 | Q30: =P30-P29 -> 145 | R30: =R29 -> 55047 | S30: =R30-R29 -> 0 | T30: 4014 | U30: =(T30-T29)*800/5 -> 160
A31: 44741 | B31: 47225 | C31: =(B31-B30)*800/5 -> 800 | D31: 40732 | E31: =(D31-D30)*800/5 -> 640 | F31: 21791 | G31: =(F31-F30)*100/5 -> 100 | H31: 256069 | I31: =(H31-H30) -> 33 | J31: 321002 | K31: =(J31-J30) -> 149 | L31: 26263 | M31: =(L31-L30)*300/5 -> 240 | N31: 226129 | O31: =N31-N30 -> 3 | P31: 158487 | Q31: =P31-P30 -> 188 | R31: =R30 -> 55047 | S31: 0 | T31: 4015 | U31: =(T31-T30)*800/5 -> 160
A32: 44742 | B32: 47229 | C32: =(B32-B31)*800/5 -> 640 | D32: 40735 | E32: =(D32-D31)*800/5 -> 480 | F32: 21796 | G32: =(F32-F31)*100/5 -> 100 | H32: 256113 | I32: =(H32-H31) -> 44 | J32: 321030 | K32: =(J32-J31) -> 28 | L32: 26265 | M32: =(L32-L31)*300/5 -> 120 | N32: 226132 | O32: =N32-N31 -> 3 | P32: 158584 | Q32: =P32-P31 -> 97 | R32: =R31 -> 55047 | S32: =R32-R31 -> 0 | T32: 4015 | U32: =(T32-T31)*800/5 -> 0
A33: Total | C33: =SUM(C3:C32) -> 22720 | E33: =SUM(E3:E32) -> 15520 | G33: =SUM(G3:G32) -> 2180 | I33: =SUM(I3:I32) -> 814 | K33: =SUM(K3:K32) -> 4626 | M33: =SUM(M3:M32) -> 5640 | O33: =SUM(O3:O32) -> 96 | Q33: =SUM(Q3:Q32) -> 4218 | S33: =SUM(S3:S32) -> 0 | U33: =SUM(U3:U32) -> 2880

Sheet ELECT.
A1: Day | B1: Rooms Sold | C1: New Chillers | D1: Cons | E1: F-1 | F1: Cons. | G1: F-2 | H1: Cons. | I1: Total | J1: T-1 | K1: Cons. | L1: T-2 | M1: Cons. | N1: T-3 | O1: Cons. | P1: T-4 | Q1: Cons. | R1: T-5 | S1: Cons. | T1: T-6 | U1: Cons. | V1: T-7 | W1: Cons. | X1: Total | Y1: Diff | Z1: Daily Money Value | AA1: MTD Total Money
A2: 44712 | B2: 152 | C2: 19676 | E2: 31095578 | G2: 99640821 | I2: =F2+H2 -> 0 | J2: 9920947 | L2: 94732 | N2: 6646256 | P2: 6636256 | R2: 21222233 | T2: 0 | V2: 9158946
A3: 44713 | B3: 155 | C3: 19679 | D3: =IF((C3-C2)<0,"0",(C3-C2))*160 -> 480 | E3: 31115403 | F3: =IF((E3-E2)<0,"0",(E3-E2)) -> 19825 | G3: 99693222 | H3: =IF((G3-G2)<0,"0",(G3-G2)) -> 52401 | I3: =F3+H3 -> 72226 | J3: 9926322 | K3: =(IF((J3-J2)<L90,"0",(J3-J2)))*2 -> 10750 | L3: 101393 | M3: =IF((L3-L2)<0,"0",(L3-L2)) -> 6661 | N3: 6650543 | O3: =(IF((N3-N2)<P90,"0",(N3-N2)))*2 -> 8574 | P3: 6650543 | Q3: =IF((P3-P2)<0,"0",(P3-P2)) -> 14287 | R3: 21232975 | S3: =IF((R3-R2)<0,"0",(R3-R2)) -> 10742 | T3: 0 | V3: 9170374 | W3: =IF((V3-V2)<0,"0",(V3-V2)) -> 11428 | X3: =K3+M3+O3+Q3+S3+U3+W3 -> 62442 | Y3: =I3-X3 -> 9784 | Z3: =(0.93352*(W3+S3)+0.5568*(Q3+O3))*0.26 -> 8690.5372 | AA3: =SUM(Z1:Z3) -> 8690.5372
A4: 44714 | B4: 160 | C4: 19683 | D4: =IF((C4-C3)<0,"0",(C4-C3))*160 -> 640 | E4: 31139408 | F4: =IF((E4-E3)<0,"0",(E4-E3)) -> 24005 | G4: 99752436 | H4: =IF((G4-G3)<0,"0",(G4-G3)) -> 59214 | I4: =F4+H4 -> 83219 | J4: 9932354 | K4: =(IF((J4-J3)<L92,"0",(J4-J3)))*2 -> 12064 | L4: 109169 | M4: =IF((L4-L3)<0,"0",(L4-L3)) -> 7776 | N4: 6660746 | O4: =(IF((N4-N3)<P92,"0",(N4-N3)))*2 -> 20406 | P4: 6664365 | Q4: =IF((P4-P3)<0,"0",(P4-P3)) -> 13822 | R4: 21245191 | S4: =IF((R4-R3)<0,"0",(R4-R3)) -> 12216 | T4: 0 | V4: 9183318 | W4: =IF((V4-V3)<0,"0",(V4-V3)) -> 12944 | X4: =K4+M4+O4+Q4+S4+U4+W4 -> 79228 | Y4: =I4-X4 -> 3991 | Z4: =(0.93352*(W4+S4)+0.5568*(Q4+O4))*0.26 -> 11061.834 | AA4: =SUM(Z1:Z4) -> 19752.371
A5: 44715 | B5: 276 | C5: 19686 | D5: =IF((C5-C4)<0,"0",(C5-C4))*160 -> 480 | E5: 31155705 | F5: =IF((E5-E4)<0,"0",(E5-E4)) -> 16297 | G5: 99797077 | H5: =IF((G5-G4)<0,"0",(G5-G4)) -> 44641 | I5: =F5+H5 -> 60938 | J5: 9936717 | K5: =(IF((J5-J4)<0,"0",(J5-J4)))*2 -> 8726 | L5: 114636 | M5: =IF((L5-L4)<0,"0",(L5-L4)) -> 5467 | N5: 6666071 | O5: =(IF((N5-N4)<0,"0",(N5-N4)))*2 -> 10650 | P5: 6675536 | Q5: =IF((P5-P4)<0,"0",(P5-P4)) -> 11171 | R5: 21254589 | S5: =IF((R5-R4)<0,"0",(R5-R4)) -> 9398 | T5: 0 | V5: 9192693 | W5: =IF((V5-V4)<0,"0",(V5-V4)) -> 9375 | X5: =K5+M5+O5+Q5+S5+U5+W5 -> 54787 | Y5: =I5-X5 -> 6151 | Z5: =(0.93352*(W5+S5)+0.5568*(Q5+O5))*0.26 -> 7715.475 | AA5: =SUM(Z1:Z5) -> 27467.846
A6: 44716 | B6: 235 | C6: 19689 | D6: =IF((C6-C5)<0,"0",(C6-C5))*160 -> 480 | E6: 31177331 | F6: =IF((E6-E5)<0,"0",(E6-E5)) -> 21626 | G6: 99851312 | H6: =IF((G6-G5)<0,"0",(G6-G5)) -> 54235 | I6: =F6+H6 -> 75861 | J6: 9941871 | K6: =(IF((J6-J5)<0,"0",(J6-J5)))*2 -> 10308 | L6: 121170 | M6: =IF((L6-L5)<0,"0",(L6-L5)) -> 6534 | N6: 6673518 | O6: =(IF((N6-N5)<0,"0",(N6-N5)))*2 -> 14894 | P6: 6689492 | Q6: =IF((P6-P5)<0,"0",(P6-P5)) -> 13956 | R6: 21265867 | S6: =IF((R6-R5)<0,"0",(R6-R5)) -> 11278 | T6: 0 | V6: 9204024 | W6: =IF((V6-V5)<0,"0",(V6-V5)) -> 11331 | X6: =K6+M6+O6+Q6+S6+U6+W6 -> 68301 | Y6: =I6-X6 -> 7560 | Z6: =(0.93352*(W6+S6)+0.5568*(Q6+O6))*0.26 -> 9664.1048 | AA6: =SUM(Z1:Z6) -> 37131.951
A7: 44717 | B7: 209 | C7: 19694 | D7: =IF((C7-C6)<0,"0",(C7-C6))*160 -> 800 | E7: 31196732 | F7: =IF((E7-E6)<0,"0",(E7-E6)) -> 19401 | G7: 99899162 | H7: =IF((G7-G6)<0,"0",(G7-G6)) -> 47850 | I7: =F7+H7 -> 67251 | J7: 9946770 | K7: =(IF((J7-J6)<0,"0",(J7-J6)))*2 -> 9798 | L7: 127049 | M7: =IF((L7-L6)<0,"0",(L7-L6)) -> 5879 | N7: 6680189 | O7: =(IF((N7-N6)<0,"0",(N7-N6)))*2 -> 13342 | P7: 6702004 | Q7: =IF((P7-P6)<0,"0",(P7-P6)) -> 12512 | R7: 21275759 | S7: =IF((R7-R6)<0,"0",(R7-R6)) -> 9892 | T7: 0 | V7: 9213816 | W7: =IF((V7-V6)<0,"0",(V7-V6)) -> 9792 | X7: =K7+M7+O7+Q7+S7+U7+W7 -> 61215 | Y7: =I7-X7 -> 6036 | Z7: =(0.93352*(W7+S7)+0.5568*(Q7+O7))*0.26 -> 8520.4379 | AA7: =SUM(Z1:Z7) -> 45652.388
A8: 44718 | B8: 224 | C8: 19698 | D8: =IF((C8-C7)<0,"0",(C8-C7))*160 -> 640 | E8: 31222147 | F8: =IF((E8-E7)<0,"0",(E8-E7)) -> 25415 | G8: 99999999 | H8: =IF((G8-G7)<0,"0",(G8-G7)) -> 100837 | I8: =F8+H8 -> 126252 | J8: 9952684 | K8: =(IF((J8-J7)<0,"0",(J8-J7)))*2 -> 11828 | L8: 135043 | M8: =IF((L8-L7)<0,"0",(L8-L7)) -> 7994 | N8: 6688800 | O8: =(IF((N8-N7)<0,"0",(N8-N7)))*2 -> 17222 | P8: 6717380 | Q8: =IF((P8-P7)<0,"0",(P8-P7)) -> 15376 | R8: 21288082 | S8: =IF((R8-R7)<0,"0",(R8-R7)) -> 12323 | T8: 0 | V8: 9226397 | W8: =IF((V8-V7)<0,"0",(V8-V7)) -> 12581 | X8: =K8+M8+O8+Q8+S8+U8+W8 -> 77324 | Y8: =I8-X8 -> 48928 | Z8: =(0.93352*(W8+S8)+0.5568*(Q8+O8))*0.26 -> 10763.727 | AA8: =SUM(Z1:Z8) -> 56416.115
A9: 44719 | B9: 228 | C9: 19702 | D9: =IF((C9-C8)<0,"0",(C9-C8))*160 -> 640 | E9: 31239324 | F9: =IF((E9-E8)<0,"0",(E9-E8)) -> 17177 | G9: 0 | H9: =(G9-G8)+99999999 -> 0 | I9: =F9+H9 -> 17177 | J9: 9957012 | K9: =(IF((J9-J8)<0,"0",(J9-J8)))*2 -> 8656 | L9: 140495 | M9: =IF((L9-L8)<0,"0",(L9-L8)) -> 5452 | N9: 6694576 | O9: =(IF((N9-N8)<0,"0",(N9-N8)))*2 -> 11552 | P9: 6727522 | Q9: =IF((P9-P8)<0,"0",(P9-P8)) -> 10142 | R9: 21296380 | S9: =IF((R9-R8)<0,"0",(R9-R8)) -> 8298 | T9: 0 | V9: 9235008 | W9: =IF((V9-V8)<0,"0",(V9-V8)) -> 8611 | X9: =K9+M9+O9+Q9+S9+U9+W9 -> 52711 | Y9: =I9-X9 -> -35534 | Z9: =(0.93352*(W9+S9)+0.5568*(Q9+O9))*0.26 -> 7244.6683 | AA9: =SUM(Z1:Z9) -> 63660.783
A10: 44720 | B10: 230 | C10: 19706 | D10: =IF((C10-C9)<0,"0",(C10-C9))*160 -> 640 | E10: 31263852 | F10: =IF((E10-E9)<0,"0",(E10-E9)) -> 24528 | G10: 59527 | H10: =IF((G10-G9)<0,"0",(G10-G9)) -> 59527 | I10: =F10+H10 -> 84055 | J10: 9962749 | K10: =(IF((J10-J9)<0,"0",(J10-J9)))*2 -> 11474 | L10: 148103 | M10: =IF((L10-L9)<0,"0",(L10-L9)) -> 7608 | N10: 6702932 | O10: =(IF((N10-N9)<0,"0",(N10-N9)))*2 -> 16712 | P10: 6748914 | Q10: =IF((P10-P9)<0,"0",(P10-P9)) -> 21392 | R10: 21308339 | S10: =IF((R10-R9)<0,"0",(R10-R9)) -> 11959 | T10: 0 | V10: 9263471 | W10: =IF((V10-V9)<0,"0",(V10-V9)) -> 28463 | X10: =K10+M10+O10+Q10+S10+U10+W10 -> 97608 | Y10: =I10-X10 -> -13553 | Z10: =(0.93352*(W10+S10)+0.5568*(Q10+O10))*0.26 -> 15327.274 | AA10: =SUM(Z1:Z10) -> 78988.057
A11: 44721 | B11: 221 | C11: 19709 | D11: =IF((C11-C10)<0,"0",(C11-C10))*160 -> 480 | E11: 31288713 | F11: =IF((E11-E10)<0,"0",(E11-E10)) -> 24861 | G11: 120699 | H11: =IF((G11-G10)<0,"0",(G11-G10)) -> 61172 | I11: =F11+H11 -> 86033 | J11: 9968659 | K11: =(IF((J11-J10)<0,"0",(J11-J10)))*2 -> 11820 | L11: 155936 | M11: =IF((L11-L10)<0,"0",(L11-L10)) -> 7833 | N11: 6711348 | O11: =(IF((N11-N10)<0,"0",(N11-N10)))*2 -> 16832 | P11: 6758277 | Q11: =IF((P11-P10)<0,"0",(P11-P10)) -> 9363 | R11: 21320383 | S11: =IF((R11-R10)<0,"0",(R11-R10)) -> 12044 | T11: 0 | V11: 9266773 | W11: =IF((V11-V10)<0,"0",(V11-V10)) -> 3302 | X11: =K11+M11+O11+Q11+S11+U11+W11 -> 61194 | Y11: =I11-X11 -> 24839 | Z11: =(0.93352*(W11+S11)+0.5568*(Q11+O11))*0.26 -> 7516.9052 | AA11: =SUM(Z1:Z11) -> 86504.962
A12: 44722 | B12: 223 | C12: 19715 | D12: =IF((C12-C11)<0,"0",(C12-C11))*160 -> 960 | E12: 31308257 | F12: =IF((E12-E11)<0,"0",(E12-E11)) -> 19544 | G12: 168384 | H12: =IF((G12-G11)<0,"0",(G12-G11)) -> 47685 | I12: =F12+H12 -> 67229 | J12: 9973144 | K12: =(IF((J12-J11)<0,"0",(J12-J11)))*2 -> 8970 | L12: 161934 | M12: =IF((L12-L11)<0,"0",(L12-L11)) -> 5998 | N12: 6718020 | O12: =(IF((N12-N11)<0,"0",(N12-N11)))*2 -> 13344 | P12: 6770237 | Q12: =IF((P12-P11)<0,"0",(P12-P11)) -> 11960 | R12: 21329670 | S12: =IF((R12-R11)<0,"0",(R12-R11)) -> 9287 | T12: 0 | V12: 9271221 | W12: =IF((V12-V11)<0,"0",(V12-V11)) -> 4448 | X12: =K12+M12+O12+Q12+S12+U12+W12 -> 54007 | Y12: =I12-X12 -> 13222 | Z12: =(0.93352*(W12+S12)+0.5568*(Q12+O12))*0.26 -> 6996.9027 | AA12: =SUM(Z1:Z12) -> 93501.865
A13: 44723 | B13: 182 | C13: 19718 | D13: =IF((C13-C12)<0,"0",(C13-C12))*160 -> 480 | E13: 31327753 | F13: =IF((E13-E12)<0,"0",(E13-E12)) -> 19496 | G13: 215753 | H13: =IF((G13-G12)<0,"0",(G13-G12)) -> 47369 | I13: =F13+H13 -> 66865 | J13: 9977694 | K13: =(IF((J13-J12)<0,"0",(J13-J12)))*2 -> 9100 | L13: 167973 | M13: =IF((L13-L12)<0,"0",(L13-L12)) -> 6039 | N13: 6724665 | O13: =(IF((N13-N12)<0,"0",(N13-N12)))*2 -> 13290 | P13: 6782297 | Q13: =IF((P13-P12)<0,"0",(P13-P12)) -> 12060 | R13: 21339211 | S13: =IF((R13-R12)<0,"0",(R13-R12)) -> 9541 | T13: 0 | V13: 9281296 | W13: =IF((V13-V12)<0,"0",(V13-V12)) -> 10075 | X13: =K13+M13+O13+Q13+S13+U13+W13 -> 60105 | Y13: =I13-X13 -> 6760 | Z13: =(0.93352*(W13+S13)+0.5568*(Q13+O13))*0.26 -> 8430.9702 | AA13: =SUM(Z1:Z13) -> 101932.84
A14: 44724 | B14: 205 | C14: 19724 | D14: =IF((C14-C13)<0,"0",(C14-C13))*160 -> 960 | E14: 31355266 | F14: =IF((E14-E13)<0,"0",(E14-E13)) -> 27513 | G14: 281124 | H14: =IF((G14-G13)<0,"0",(G14-G13)) -> 65371 | I14: =F14+H14 -> 92884 | J14: 9984050 | K14: =(IF((J14-J13)<0,"0",(J14-J13)))*2 -> 12712 | L14: 176696 | M14: =IF((L14-L13)<0,"0",(L14-L13)) -> 8723 | N14: 6733936 | O14: =(IF((N14-N13)<0,"0",(N14-N13)))*2 -> 18542 | P14: 6798741 | Q14: =IF((P14-P13)<0,"0",(P14-P13)) -> 16444 | R14: 21350263 | S14: =IF((R14-R13)<0,"0",(R14-R13)) -> 11052 | T14: 0 | V14: 9295168 | W14: =IF((V14-V13)<0,"0",(V14-V13)) -> 13872 | X14: =K14+M14+O14+Q14+S14+U14+W14 -> 81345 | Y14: =I14-X14 -> 11539 | Z14: =(0.93352*(W14+S14)+0.5568*(Q14+O14))*0.26 -> 11114.287 | AA14: =SUM(Z1:Z14) -> 113047.12
A15: 44725 | B15: 245 | C15: 19729 | D15: =IF((C15-C14)<0,"0",(C15-C14))*160 -> 800 | E15: 31374784 | F15: =IF((E15-E14)<0,"0",(E15-E14)) -> 19518 | G15: 327673 | H15: =IF((G15-G14)<0,"0",(G15-G14)) -> 46549 | I15: =F15+H15 -> 66067 | J15: 9988973 | K15: =(IF((J15-J14)<0,"0",(J15-J14)))*2 -> 9846 | L15: 183185 | M15: =IF((L15-L14)<0,"0",(L15-L14)) -> 6489 | N15: 6740371 | O15: =(IF((N15-N14)<0,"0",(N15-N14)))*2 -> 12870 | P15: 6810193 | Q15: =IF((P15-P14)<0,"0",(P15-P14)) -> 11452 | R15: 21361887 | S15: =IF((R15-R14)<0,"0",(R15-R14)) -> 11624 | T15: 0 | V15: 9305129 | W15: =IF((V15-V14)<0,"0",(V15-V14)) -> 9961 | X15: =K15+M15+O15+Q15+S15+U15+W15 -> 62242 | Y15: =I15-X15 -> 3825 | Z15: =(0.93352*(W15+S15)+0.5568*(Q15+O15))*0.26 -> 8760.0549 | AA15: =SUM(Z1:Z15) -> 121807.18
A16: 44726 | B16: 172 | C16: 19734 | D16: =IF((C16-C15)<0,"0",(C16-C15))*160 -> 800 | E16: 31394842 | F16: =IF((E16-E15)<0,"0",(E16-E15)) -> 20058 | G16: 376593 | H16: =IF((G16-G15)<0,"0",(G16-G15)) -> 48920 | I16: =F16+H16 -> 68978 | J16: 9994022 | K16: =(IF((J16-J15)<0,"0",(J16-J15)))*2 -> 10098 | L16: 189636 | M16: =IF((L16-L15)<0,"0",(L16-L15)) -> 6451 | N16: 6747072 | O16: =(IF((N16-N15)<0,"0",(N16-N15)))*2 -> 13402 | P16: 6822158 | Q16: =IF((P16-P15)<0,"0",(P16-P15)) -> 11965 | R16: 21371520 | S16: =IF((R16-R15)<0,"0",(R16-R15)) -> 9633 | T16: 0 | V16: 9315744 | W16: =IF((V16-V15)<0,"0",(V16-V15)) -> 10615 | X16: =K16+M16+O16+Q16+S16+U16+W16 -> 62164 | Y16: =I16-X16 -> 6814 | Z16: =(0.93352*(W16+S16)+0.5568*(Q16+O16))*0.26 -> 8586.8272 | AA16: =SUM(Z1:Z16) -> 130394
A17: 44727 | B17: 180 | C17: 19738 | D17: =IF((C17-C16)<0,"0",(C17-C16))*160 -> 640 | E17: 31415840 | F17: =IF((E17-E16)<0,"0",(E17-E16)) -> 20998 | G17: 427390 | H17: =IF((G17-G16)<0,"0",(G17-G16)) -> 50797 | I17: =F17+H17 -> 71795 | J17: 9999113 | K17: =(IF((J17-J16)<0,"0",(J17-J16)))*2 -> 10182 | L17: 196362 | M17: =IF((L17-L16)<0,"0",(L17-L16)) -> 6726 | N17: 6754127 | O17: =(IF((N17-N16)<0,"0",(N17-N16)))*2 -> 14110 | P17: 6834660 | Q17: =IF((P17-P16)<0,"0",(P17-P16)) -> 12502 | R17: 21381722 | S17: =IF((R17-R16)<0,"0",(R17-R16)) -> 10202 | T17: 0 | V17: 9326736 | W17: =IF((V17-V16)<0,"0",(V17-V16)) -> 10992 | X17: =K17+M17+O17+Q17+S17+U17+W17 -> 64714 | Y17: =I17-X17 -> 7081 | Z17: =(0.93352*(W17+S17)+0.5568*(Q17+O17))*0.26 -> 8996.672 | AA17: =SUM(Z1:Z17) -> 139390.68
A18: 44728 | B18: 201 | C18: 19742 | D18: =IF((C18-C17)<0,"0",(C18-C17))*160 -> 640 | E18: 31441378 | F18: =IF((E18-E17)<0,"0",(E18-E17)) -> 25538 | G18: 489977 | H18: =IF((G18-G17)<0,"0",(G18-G17)) -> 62587 | I18: =F18+H18 -> 88125 | J18: 5105 | K18: =(J18-J17)+9999999 -> 5991 | L18: 204260 | M18: =IF((L18-L17)<0,"0",(L18-L17)) -> 7898 | N18: 6762830 | O18: =(IF((N18-N17)<0,"0",(N18-N17)))*2 -> 17406 | P18: 6850147 | Q18: =IF((P18-P17)<0,"0",(P18-P17)) -> 15487 | R18: 21394708 | S18: =IF((R18-R17)<0,"0",(R18-R17)) -> 12986 | T18: 0 | V18: 9340102 | W18: =IF((V18-V17)<0,"0",(V18-V17)) -> 13366 | X18: =K18+M18+O18+Q18+S18+U18+W18 -> 73134 | Y18: =I18-X18 -> 14991 | Z18: =(0.93352*(W18+S18)+0.5568*(Q18+O18))*0.26 -> 11157.885 | AA18: =SUM(Z1:Z18) -> 150548.56
A19: 44729 | B19: 200 | C19: 19745 | D19: =IF((C19-C18)<0,"0",(C19-C18))*160 -> 480 | E19: 31461153 | F19: =IF((E19-E18)<0,"0",(E19-E18)) -> 19775 | G19: 539099 | H19: =IF((G19-G18)<0,"0",(G19-G18)) -> 49122 | I19: =F19+H19 -> 68897 | J19: 9617 | K19: =(IF((J19-J18)<0,"0",(J19-J18)))*2 -> 9024 | L19: 210107 | M19: =IF((L19-L18)<0,"0",(L19-L18)) -> 5847 | N19: 6769703 | O19: =(IF((N19-N18)<0,"0",(N19-N18)))*2 -> 13746 | P19: 6862414 | Q19: =IF((P19-P18)<0,"0",(P19-P18)) -> 12267 | R19: 21404755 | S19: =IF((R19-R18)<0,"0",(R19-R18)) -> 10047 | T19: 0 | V19: 9350789 | W19: =IF((V19-V18)<0,"0",(V19-V18)) -> 10687 | X19: =K19+M19+O19+Q19+S19+U19+W19 -> 61618 | Y19: =I19-X19 -> 7279 | Z19: =(0.93352*(W19+S19)+0.5568*(Q19+O19))*0.26 -> 8798.3069 | AA19: =SUM(Z1:Z19) -> 159346.87
A20: 44730 | B20: 169 | C20: 19749 | D20: =IF((C20-C19)<0,"0",(C20-C19))*160 -> 640 | E20: 31482885 | F20: =IF((E20-E19)<0,"0",(E20-E19)) -> 21732 | G20: 593441 | H20: =IF((G20-G19)<0,"0",(G20-G19)) -> 54342 | I20: =F20+H20 -> 76074 | J20: 14250 | K20: =(IF((J20-J19)<0,"0",(J20-J19)))*2 -> 9266 | L20: 216603 | M20: =IF((L20-L19)<0,"0",(L20-L19)) -> 6496 | N20: 6777233 | O20: =(IF((N20-N19)<0,"0",(N20-N19)))*2 -> 15060 | P20: 6875260 | Q20: =IF((P20-P19)<0,"0",(P20-P19)) -> 12846 | R20: 21415523 | S20: =IF((R20-R19)<0,"0",(R20-R19)) -> 10768 | T20: 0 | V20: 9362902 | W20: =IF((V20-V19)<0,"0",(V20-V19)) -> 12113 | X20: =K20+M20+O20+Q20+S20+U20+W20 -> 66549 | Y20: =I20-X20 -> 9525 | Z20: =(0.93352*(W20+S20)+0.5568*(Q20+O20))*0.26 -> 9593.4623 | AA20: =SUM(Z1:Z20) -> 168940.33
A21: 44731 | B21: 300 | C21: 19753 | D21: =IF((C21-C20)<0,"0",(C21-C20))*160 -> 640 | E21: 31503872 | F21: =IF((E21-E20)<0,"0",(E21-E20)) -> 20987 | G21: 646189 | H21: =IF((G21-G20)<0,"0",(G21-G20)) -> 52748 | I21: =F21+H21 -> 73735 | J21: 19351 | K21: =(IF((J21-J20)<0,"0",(J21-J20)))*2 -> 10202 | L21: 223136 | M21: =IF((L21-L20)<0,"0",(L21-L20)) -> 6533 | N21: 6784362 | O21: =(IF((N21-N20)<0,"0",(N21-N20)))*2 -> 14258 | P21: 6885041 | Q21: =IF((P21-P20)<0,"0",(P21-P20)) -> 9781 | R21: 21426166 | S21: =IF((R21-R20)<0,"0",(R21-R20)) -> 10643 | T21: 0 | V21: 9374524 | W21: =IF((V21-V20)<0,"0",(V21-V20)) -> 11622 | X21: =K21+M21+O21+Q21+S21+U21+W21 -> 63039 | Y21: =I21-X21 -> 10696 | Z21: =(0.93352*(W21+S21)+0.5568*(Q21+O21))*0.26 -> 8884.1319 | AA21: =SUM(Z1:Z21) -> 177824.46
A22: 44732 | B22: 324 | C22: 19756 | D22: =IF((C22-C21)<0,"0",(C22-C21))*160 -> 480 | E22: 31529162 | F22: =IF((E22-E21)<0,"0",(E22-E21)) -> 25290 | G22: 708745 | H22: =IF((G22-G21)<0,"0",(G22-G21)) -> 62556 | I22: =F22+H22 -> 87846 | J22: 25272 | K22: =(IF((J22-J21)<0,"0",(J22-J21)))*2 -> 11842 | L22: 231055 | M22: =IF((L22-L21)<0,"0",(L22-L21)) -> 7919 | N22: 6792942 | O22: =(IF((N22-N21)<0,"0",(N22-N21)))*2 -> 17160 | P22: 6903575 | Q22: =IF((P22-P21)<0,"0",(P22-P21)) -> 18534 | R22: 21438494 | S22: =IF((R22-R21)<0,"0",(R22-R21)) -> 12328 | T22: 0 | V22: 9388410 | W22: =IF((V22-V21)<0,"0",(V22-V21)) -> 13886 | X22: =K22+M22+O22+Q22+S22+U22+W22 -> 81669 | Y22: =I22-X22 -> 6177 | Z22: =(0.93352*(W22+S22)+0.5568*(Q22+O22))*0.26 -> 11529.885 | AA22: =SUM(Z1:Z22) -> 189354.35
A23: 44733 | B23: 324 | C23: 19760 | D23: =IF((C23-C22)<0,"0",(C23-C22))*160 -> 640 | E23: 31546120 | F23: =IF((E23-E22)<0,"0",(E23-E22)) -> 16958 | G23: 751160 | H23: =IF((G23-G22)<0,"0",(G23-G22)) -> 42415 | I23: =F23+H23 -> 59373 | J23: 29620 | K23: =(IF((J23-J22)<0,"0",(J23-J22)))*2 -> 8696 | L23: 236408 | M23: =IF((L23-L22)<0,"0",(L23-L22)) -> 5353 | N23: 6798658 | O23: =(IF((N23-N22)<0,"0",(N23-N22)))*2 -> 11432 | P23: 6913672 | Q23: =IF((P23-P22)<0,"0",(P23-P22)) -> 10097 | R23: 21446792 | S23: =IF((R23-R22)<0,"0",(R23-R22)) -> 8298 | T23: 0 | V23: 9397774 | W23: =IF((V23-V22)<0,"0",(V23-V22)) -> 9364 | X23: =K23+M23+O23+Q23+S23+U23+W23 -> 53240 | Y23: =I23-X23 -> 6133 | Z23: =(0.93352*(W23+S23)+0.5568*(Q23+O23))*0.26 -> 7403.5461 | AA23: =SUM(Z1:Z23) -> 196757.89
A24: 44734 | B24: 137 | C24: 19764 | D24: =IF((C24-C23)<0,"0",(C24-C23))*160 -> 640 | E24: 31568036 | F24: =IF((E24-E23)<0,"0",(E24-E23)) -> 21916 | G24: 804513 | H24: =IF((G24-G23)<0,"0",(G24-G23)) -> 53353 | I24: =F24+H24 -> 75269 | J24: 34845 | K24: =(IF((J24-J23)<0,"0",(J24-J23)))*2 -> 10450 | L24: 243232 | M24: =IF((L24-L23)<0,"0",(L24-L23)) -> 6824 | N24: 6806116 | O24: =(IF((N24-N23)<0,"0",(N24-N23)))*2 -> 14916 | P24: 6926638 | Q24: =IF((P24-P23)<0,"0",(P24-P23)) -> 12966 | R24: 21457188 | S24: =IF((R24-R23)<0,"0",(R24-R23)) -> 10396 | T24: 0 | V24: 9409573 | W24: =IF((V24-V23)<0,"0",(V24-V23)) -> 11799 | X24: =K24+M24+O24+Q24+S24+U24+W24 -> 67351 | Y24: =I24-X24 -> 7918 | Z24: =(0.93352*(W24+S24)+0.5568*(Q24+O24))*0.26 -> 9423.4852 | AA24: =SUM(Z1:Z24) -> 206181.38
A25: 44735 | B25: 200 | C25: 19768 | D25: =IF((C25-C24)<0,"0",(C25-C24))*160 -> 640 | E25: 31587953 | F25: =IF((E25-E24)<0,"0",(E25-E24)) -> 19917 | G25: 852788 | H25: =IF((G25-G24)<0,"0",(G25-G24)) -> 48275 | I25: =F25+H25 -> 68192 | J25: 39434 | K25: =(IF((J25-J24)<0,"0",(J25-J24)))*2 -> 9178 | L25: 249394 | M25: =IF((L25-L24)<0,"0",(L25-L24)) -> 6162 | N25: 6812892 | O25: =(IF((N25-N24)<0,"0",(N25-N24)))*2 -> 13552 | P25: 6938549 | Q25: =IF((P25-P24)<0,"0",(P25-P24)) -> 11911 | R25: 21466598 | S25: =IF((R25-R24)<0,"0",(R25-R24)) -> 9410 | T25: 0 | V25: 9420227 | W25: =IF((V25-V24)<0,"0",(V25-V24)) -> 10654 | X25: =K25+M25+O25+Q25+S25+U25+W25 -> 60867 | Y25: =I25-X25 -> 7325 | Z25: =(0.93352*(W25+S25)+0.5568*(Q25+O25))*0.26 -> 8556.0654 | AA25: =SUM(Z1:Z25) -> 214737.44
A26: 44736 | B26: 240 | C26: 19773 | D26: =IF((C26-C25)<0,"0",(C26-C25))*160 -> 800 | E26: 31614072 | F26: =IF((E26-E25)<0,"0",(E26-E25)) -> 26119 | G26: 914973 | H26: =IF((G26-G25)<0,"0",(G26-G25)) -> 62185 | I26: =F26+H26 -> 88304 | J26: 44268 | K26: =(IF((J26-J25)<0,"0",(J26-J25)))*2 -> 9668 | L26: 257345 | M26: =IF((L26-L25)<0,"0",(L26-L25)) -> 7951 | N26: 6821863 | O26: =(IF((N26-N25)<0,"0",(N26-N25)))*2 -> 17942 | P26: 6954526 | Q26: =IF((P26-P25)<0,"0",(P26-P25)) -> 15977 | R26: 21478765 | S26: =IF((R26-R25)<0,"0",(R26-R25)) -> 12167 | T26: 0 | V26: 9434192 | W26: =IF((V26-V25)<0,"0",(V26-V25)) -> 13965 | X26: =K26+M26+O26+Q26+S26+U26+W26 -> 77670 | Y26: =I26-X26 -> 10634 | Z26: =(0.93352*(W26+S26)+0.5568*(Q26+O26))*0.26 -> 11253.019 | AA26: =SUM(Z1:Z26) -> 225990.46
A27: 44737 | B27: 169 | C27: 19778 | D27: =IF((C27-C26)<0,"0",(C27-C26))*160 -> 800 | E27: 31636668 | F27: =IF((E27-E26)<0,"0",(E27-E26)) -> 22596 | G27: 971819 | H27: =IF((G27-G26)<0,"0",(G27-G26)) -> 56846 | I27: =F27+H27 -> 79442 | J27: 48606 | K27: =(IF((J27-J26)<0,"0",(J27-J26)))*2 -> 8676 | L27: 264459 | M27: =IF((L27-L26)<0,"0",(L27-L26)) -> 7114 | N27: 6829490 | O27: =(IF((N27-N26)<0,"0",(N27-N26)))*2 -> 15254 | P27: 6968985 | Q27: =IF((P27-P26)<0,"0",(P27-P26)) -> 14459 | R27: 21490090 | S27: =IF((R27-R26)<0,"0",(R27-R26)) -> 11325 | T27: 0 | V27: 9446991 | W27: =IF((V27-V26)<0,"0",(V27-V26)) -> 12799 | X27: =K27+M27+O27+Q27+S27+U27+W27 -> 69627 | Y27: =I27-X27 -> 9815 | Z27: =(0.93352*(W27+S27)+0.5568*(Q27+O27))*0.26 -> 10156.753 | AA27: =SUM(Z1:Z27) -> 236147.22
A28: 44738 | B28: 213 | C28: 19783 | D28: =IF((C28-C27)<0,"0",(C28-C27))*160 -> 800 | E28: 31657739 | F28: =IF((E28-E27)<0,"0",(E28-E27)) -> 21071 | G28: 1025590 | H28: =IF((G28-G27)<0,"0",(G28-G27)) -> 53771 | I28: =F28+H28 -> 74842 | J28: 53405 | K28: =(IF((J28-J27)<0,"0",(J28-J27)))*2 -> 9598 | L28: 271247 | M28: =IF((L28-L27)<0,"0",(L28-L27)) -> 6788 | N28: 6836552 | O28: =(IF((N28-N27)<0,"0",(N28-N27)))*2 -> 14124 | P28: 6982232 | Q28: =IF((P28-P27)<0,"0",(P28-P27)) -> 13247 | R28: 21500567 | S28: =IF((R28-R27)<0,"0",(R28-R27)) -> 10477 | T28: 0 | V28: 9459044 | W28: =IF((V28-V27)<0,"0",(V28-V27)) -> 12053 | X28: =K28+M28+O28+Q28+S28+U28+W28 -> 66287 | Y28: =I28-X28 -> 8555 | Z28: =(0.93352*(W28+S28)+0.5568*(Q28+O28))*0.26 -> 9430.8184 | AA28: =SUM(Z1:Z28) -> 245578.03
A29: 44739 | B29: 286 | C29: 19787 | D29: =IF((C29-C28)<0,"0",(C29-C28))*160 -> 640 | E29: 31677428 | F29: =IF((E29-E28)<0,"0",(E29-E28)) -> 19689 | G29: 1076024 | H29: =IF((G29-G28)<0,"0",(G29-G28)) -> 50434 | I29: =F29+H29 -> 70123 | J29: 58474 | K29: =(IF((J29-J28)<0,"0",(J29-J28)))*2 -> 10138 | L29: 277452 | M29: =IF((L29-L28)<0,"0",(L29-L28)) -> 6205 | N29: 6843205 | O29: =(IF((N29-N28)<0,"0",(N29-N28)))*2 -> 13306 | P29: 6994782 | Q29: =IF((P29-P28)<0,"0",(P29-P28)) -> 12550 | R29: 21510200 | S29: =IF((R29-R28)<0,"0",(R29-R28)) -> 9633 | T29: 0 | V29: 9470108 | W29: =IF((V29-V28)<0,"0",(V29-V28)) -> 11064 | X29: =K29+M29+O29+Q29+S29+U29+W29 -> 62896 | Y29: =I29-X29 -> 7227 | Z29: =(0.93352*(W29+S29)+0.5568*(Q29+O29))*0.26 -> 8766.5979 | AA29: =SUM(Z1:Z29) -> 254344.63
A30: 44740 | B30: 219 | C30: 19791 | D30: =IF((C30-C29)<0,"0",(C30-C29))*160 -> 640 | E30: 31702633 | F30: =IF((E30-E29)<0,"0",(E30-E29)) -> 25205 | G30: 1140903 | H30: =IF((G30-G29)<0,"0",(G30-G29)) -> 64879 | I30: =F30+H30 -> 90084 | J30: 65286 | K30: =(IF((J30-J29)<0,"0",(J30-J29)))*2 -> 13624 | L30: 285160 | M30: =IF((L30-L29)<0,"0",(L30-L29)) -> 7708 | N30: 6851845 | O30: =(IF((N30-N29)<0,"0",(N30-N29)))*2 -> 17280 | P30: 7010845 | Q30: =IF((P30-P29)<0,"0",(P30-P29)) -> 16063 | R30: 21522672 | S30: =IF((R30-R29)<0,"0",(R30-R29)) -> 12472 | T30: 0 | V30: 9484177 | W30: =IF((V30-V29)<0,"0",(V30-V29)) -> 14069 | X30: =K30+M30+O30+Q30+S30+U30+W30 -> 81216 | Y30: =I30-X30 -> 8868 | Z30: =(0.93352*(W30+S30)+0.5568*(Q30+O30))*0.26 -> 11268.904 | AA30: =SUM(Z1:Z30) -> 265613.54
A31: 44741 | B31: 225 | C31: 19795 | D31: =IF((C31-C30)<0,"0",(C31-C30))*160 -> 640 | E31: 31721699 | F31: =IF((E31-E30)<0,"0",(E31-E30)) -> 19066 | G31: 1188856 | H31: =IF((G31-G30)<0,"0",(G31-G30)) -> 47953 | I31: =F31+H31 -> 67019 | J31: 70299 | K31: =(IF((J31-J30)<0,"0",(J31-J30)))*2 -> 10026 | L31: 291086 | M31: =IF((L31-L30)<0,"0",(L31-L30)) -> 5926 | N31: 6858327 | O31: =(IF((N31-N30)<0,"0",(N31-N30)))*2 -> 12964 | P31: 7022822 | Q31: =IF((P31-P30)<0,"0",(P31-P30)) -> 11977 | R31: 21531558 | S31: =IF((R31-R30)<0,"0",(R31-R30)) -> 8886 | T31: 0 | V31: 9494718 | W31: =IF((V31-V30)<0,"0",(V31-V30)) -> 10541 | X31: =K31+M31+O31+Q31+S31+U31+W31 -> 60320 | Y31: =I31-X31 -> 6699 | Z31: =(0.93352*(W31+S31)+0.5568*(Q31+O31))*0.26 -> 8325.8869 | AA31: =SUM(Z1:Z31) -> 273939.42
