Workbook

Sheet TOTAL
A1: Site Name | B1: Day | C1: Month | D1: Year | E1: Total Electricity Kwh | F1: Electricity Tariff ($/Kwh) | G1: Natual Gas (m3) | H1: Natural Gas $/m3 | I1: Water Utility Supply (m3) m3 | J1: Water Utility Supply (m3) $/m3 | K1: Room Nights | L1: Total Guests | M1: Utilities day cost dh
A2: Mumbai | B2: 1 | C2: 6 | D2: 2022 | E2: =(IF('Daily HLP'!H4>0,'Daily HLP'!H4,0)) -> 28059 | F2: 9 | G2: =(IF('Daily HLP'!L4>0,'Daily HLP'!L4,0)) -> 1098 | H2: 75 | I2: =(IF('Daily HLP'!O4>0,'Daily HLP'!O4,0)) -> 316 | J2: 100 | K2: =Occupancy!G2 -> 168 | L2: =Occupancy!F2 -> 401 | M2: =E2*F2+G2*H2+#REF!*#REF!+I2*J2 -> #REF!
A3: Mumbai | B3: =B2+1 -> 2 | C3: 6 | D3: 2022 | E3: =(IF('Daily HLP'!H5>0,'Daily HLP'!H5,0)) -> 28576 | F3: 9 | G3: =(IF('Daily HLP'!L5>0,'Daily HLP'!L5,0)) -> 1043 | H3: 75 | I3: =(IF('Daily HLP'!O5>0,'Daily HLP'!O5,0)) -> 316 | J3: 100 | K3: =Occupancy!G3 -> 164 | L3: =Occupancy!F3 -> 329 | M3: =E3*F3+G3*H3+#REF!*#REF!+I3*J3 -> #REF!
A4: Mumbai | B4: =B3+1 -> 3 | C4: 6 | D4: 2022 | E4: =(IF('Daily HLP'!H6>0,'Daily HLP'!H6,0)) -> 28813 | F4: 9 | G4: =(IF('Daily HLP'!L6>0,'Daily HLP'!L6,0)) -> 1104 | H4: 75 | I4: =(IF('Daily HLP'!O6>0,'Daily HLP'!O6,0)) -> 304 | J4: 100 | K4: =Occupancy!G4 -> 167 | L4: =Occupancy!F4 -> 329 | M4: =E4*F4+G4*H4+#REF!*#REF!+I4*J4 -> #REF!
A5: Mumbai | B5: =B4+1 -> 4 | C5: 6 | D5: 2022 | E5: =(IF('Daily HLP'!H7>0,'Daily HLP'!H7,0)) -> 28412 | F5: 9 | G5: =(IF('Daily HLP'!L7>0,'Daily HLP'!L7,0)) -> 1121 | H5: 75 | I5: =(IF('Daily HLP'!O7>0,'Daily HLP'!O7,0)) -> 314 | J5: 100 | K5: =Occupancy!G5 -> 146 | L5: =Occupancy!F5 -> 366 | M5: =E5*F5+G5*H5+#REF!*#REF!+I5*J5 -> #REF!
A6: Mumbai | B6: =B5+1 -> 5 | C6: 6 | D6: 2022 | E6: =(IF('Daily HLP'!H8>0,'Daily HLP'!H8,0)) -> 27996 | F6: 9 | G6: =(IF('Daily HLP'!L8>0,'Daily HLP'!L8,0)) -> 1118 | H6: 75 | I6: =(IF('Daily HLP'!O8>0,'Daily HLP'!O8,0)) -> 307 | J6: 100 | K6: =Occupancy!G6 -> 90 | L6: =Occupancy!F6 -> 338 | M6: =E6*F6+G6*H6+#REF!*#REF!+I6*J6 -> #REF!
A7: Mumbai | B7: =B6+1 -> 6 | C7: 6 | D7: 2022 | E7: =(IF('Daily HLP'!H9>0,'Daily HLP'!H9,0)) -> 30439 | F7: 9 | G7: =(IF('Daily HLP'!L9>0,'Daily HLP'!L9,0)) -> 1084.6 | H7: 75 | I7: =(IF('Daily HLP'!O9>0,'Daily HLP'!O9,0)) -> 355 | J7: 100 | K7: =Occupancy!G7 -> 154 | L7: =Occupancy!F7 -> 420 | M7: =E7*F7+G7*H7+#REF!*#REF!+I7*J7 -> #REF!
A8: Mumbai | B8: =B7+1 -> 7 | C8: 6 | D8: 2022 | E8: =(IF('Daily HLP'!H10>0,'Daily HLP'!H10,0)) -> 28520 | F8: 9 | G8: =(IF('Daily HLP'!L10>0,'Daily HLP'!L10,0)) -> 1078.6 | H8: 75 | I8: =(IF('Daily HLP'!O10>0,'Daily HLP'!O10,0)) -> 218 | J8: 100 | K8: =Occupancy!G8 -> 158 | L8: =Occupancy!F8 -> 584 | M8: =E8*F8+G8*H8+#REF!*#REF!+I8*J8 -> #REF!
A9: Mumbai | B9: =B8+1 -> 8 | C9: 6 | D9: 2022 | E9: =(IF('Daily HLP'!H11>0,'Daily HLP'!H11,0)) -> 25251.66 | F9: 9 | G9: =(IF('Daily HLP'!L11>0,'Daily HLP'!L11,0)) -> 1052.8 | H9: 75 | I9: =(IF('Daily HLP'!O11>0,'Daily HLP'!O11,0)) -> 195 | J9: 100 | K9: =Occupancy!G9 -> 161 | L9: =Occupancy!F9 -> 681 | M9: =E9*F9+G9*H9+#REF!*#REF!+I9*J9 -> #REF!
A10: Mumbai | B10: =B9+1 -> 9 | C10: 6 | D10: 2022 | E10: =(IF('Daily HLP'!H12>0,'Daily HLP'!H12,0)) -> 30800.44 | F10: 9 | G10: =(IF('Daily HLP'!L12>0,'Daily HLP'!L12,0)) -> 916 | H10: 75 | I10: =(IF('Daily HLP'!O12>0,'Daily HLP'!O12,0)) -> 280 | J10: 100 | K10: =Occupancy!G10 -> 162 | L10: =Occupancy!F10 -> 337 | M10: =E10*F10+G10*H10+#REF!*#REF!+I10*J10 -> #REF!
A11: Mumbai | B11: =B10+1 -> 10 | C11: 6 | D11: 2022 | E11: =(IF('Daily HLP'!H13>0,'Daily HLP'!H13,0)) -> 31010 | F11: 9 | G11: =(IF('Daily HLP'!L13>0,'Daily HLP'!L13,0)) -> 1061.5 | H11: 75 | I11: =(IF('Daily HLP'!O13>0,'Daily HLP'!O13,0)) -> 200 | J11: 100 | K11: =Occupancy!G11 -> 162 | L11: =Occupancy!F11 -> 481 | M11: =E11*F11+G11*H11+#REF!*#REF!+I11*J11 -> #REF!
A12: Mumbai | B12: =B11+1 -> 11 | C12: 6 | D12: 2022 | E12: =(IF('Daily HLP'!H14>0,'Daily HLP'!H14,0)) -> 28751 | F12: 9 | G12: =(IF('Daily HLP'!L14>0,'Daily HLP'!L14,0)) -> 1053.5 | H12: 75 | I12: =(IF('Daily HLP'!O14>0,'Daily HLP'!O14,0)) -> 360 | J12: 100 | K12: =Occupancy!G12 -> 157 | L12: =Occupancy!F12 -> 414 | M12: =E12*F12+G12*H12+#REF!*#REF!+I12*J12 -> #REF!
A13: Mumbai | B13: =B12+1 -> 12 | C13: 6 | D13: 2022 | E13: =(IF('Daily HLP'!H15>0,'Daily HLP'!H15,0)) -> 30076 | F13: 9 | G13: =(IF('Daily HLP'!L15>0,'Daily HLP'!L15,0)) -> 1039 | H13: 75 | I13: =(IF('Daily HLP'!O15>0,'Daily HLP'!O15,0)) -> 270 | J13: 100 | K13: =Occupancy!G13 -> 141 | L13: =Occupancy!F13 -> 346 | M13: =E13*F13+G13*H13+#REF!*#REF!+I13*J13 -> #REF!
A14: Mumbai | B14: =B13+1 -> 13 | C14: 6 | D14: 2022 | E14: =(IF('Daily HLP'!H16>0,'Daily HLP'!H16,0)) -> 28733 | F14: 9 | G14: =(IF('Daily HLP'!L16>0,'Daily HLP'!L16,0)) -> 1055 | H14: 75 | I14: =(IF('Daily HLP'!O16>0,'Daily HLP'!O16,0)) -> 280 | J14: 100 | K14: =Occupancy!G14 -> 158 | L14: =Occupancy!F14 -> 728 | M14: =E14*F14+G14*H14+#REF!*#REF!+I14*J14 -> #REF!
... A31: Mumbai | B31: =B30+1 -> 30 | C31: 6 | D31: 2022 | E31: =(IF('Daily HLP'!H33>0,'Daily HLP'!H33,0)) -> 28500 | F31: 9 | G31: =(IF('Daily HLP'!L33>0,'Daily HLP'!L33,0)) -> 1100 | H31: 75 | I31: =(IF('Daily HLP'!O33>0,'Daily HLP'!O33,0)) -> 285 | J31: 100 | K31: =Occupancy!G31 -> 0 | L31: =Occupancy!F31 -> 0 | M31: =E31*F31+G31*H31+#REF!*#REF!+I31*J31 -> #REF!
A32: Mumbai | B32: =B31+1 -> 31 | C32: 6 | D32: 2022 | E32: =(IF('Daily HLP'!H34>0,'Daily HLP'!H34,0)) -> 28500 | F32: 9 | G32: =(IF('Daily HLP'!L34>0,'Daily HLP'!L34,0)) -> 1100 | H32: 75 | I32: =(IF('Daily HLP'!O34>0,'Daily HLP'!O34,0)) -> 350 | J32: 100 | K32: =Occupancy!G32 -> 0 | L32: =Occupancy!F32 -> 0

Sheet Submetering
A1: Site Name | B1: Day | C1: Month | D1: Year | E1: ='Section Load'!F4 -> HVAC | F1: ='Section Load'!G4 -> Fire & Emergency PP | G1: ='Section Load'!H4 -> Main PP | H1: ='Section Load'!I4 -> Lighting PP | I1: ='Section Load'!J4 -> CH-1+ CH2+CH3+CH4 | J1: ='Section Load'!K4 -> Chilled water Pump | K1: ='Section Load'!L4 -> Ball Room-1 | L1: ='Section Load'!M4 -> Ball Room-2 | ... AL1: ='Section Load'!AM4 -> Cooling Tower | AM1: R.o.plant | AN1: STP Water Prod | AO1: Domestic Zone-1 | AP1: Domestic Zone-2 | AQ1: Domestic Zone-3 | AR1: Flush Zone -1 | AS1: Flush Zone -2 | AT1: Flush Zone -3 | AU1: Swimming pool | AV1: B2 Laundry | AW1: Boiler Feed Water | AX1: cooling tower filling water | AY1: STP flush(new water meter) | AZ1: Garden Water Pump | BA1: Flush Zone 2 pump meter | BB1: Flush Zone 3 Pump Meter (wtp transfer ) | BC1: Flush Tanker-Zone-1 | BD1: Total Domestic Water (Tanker (R.O) +BMC) | BE1: Total Domestic Consumption | BF1: Total STP Consumption | BG1: ='Section Load'!AN4 -> MGL | BH1: ='Section Load'!AO4 -> HWG | BI1: ='Section Load'!AP4 -> Prato | BJ1: ='Section Load'!AQ4 -> BR-1 | BK1: ='Section Load'!AR4 -> SanQi IND | BL1: ='Section Load'!AS4 -> SanQi JPN | BM1: ='Section Load'!AT4 -> Boiler
A2: Mumbai | B2: 1 | C2: 6 | D2: 2022 | E2: =(IF('Section Load'!F5>0,'Section Load'!F5,0)) -> 4475 | F2: =(IF('Section Load'!G5>0,'Section Load'!G5,0)) -> 1714.32 | G2: =(IF('Section Load'!H5>0,'Section Load'!H5,0)) -> 2661.76 | H2: =(IF('Section Load'!I5>0,'Section Load'!I5,0)) -> 3034 | I2: =(IF('Section Load'!J5>0,'Section Load'!J5,0)) -> 8007.66 | J2: =(IF('Section Load'!K5>0,'Section Load'!K5,0)) -> 2589 | K2: =(IF('Section Load'!L5>0,'Section Load'!L5,0)) -> 815 | L2: =(IF('Section Load'!M5>0,'Section Load'!M5,0)) -> 696 | ... AL2: =(IF('Section Load'!AM5>0,'Section Load'!AM5,0)) -> 850 | AM2: =(IF('Water Report'!$D$7>0,'Water Report'!$D$7,0)) -> 190 | AN2: =(IF('Water Report'!$D$8>0,'Water Report'!$D$8,0)) -> 119 | AO2: =(IF('Water Report'!$D$9>0,'Water Report'!$D$9,0)) -> 116 | AP2: =(IF('Water Report'!$D$10>0,'Water Report'!$D$10,0)) -> 18 | AQ2: =(IF('Water Report'!$D$11>0,'Water Report'!$D$11,0)) -> 67 | AR2: =(IF('Water Report'!$D$13>0,'Water Report'!$D$13,0)) -> 15 | AS2: =(IF('Water Report'!$D$14>0,'Water Report'!$D$14,0)) -> 5 | AT2: =(IF('Water Report'!$D$15>0,'Water Report'!$D$15,0)) -> 24 | AU2: =(IF('Water Report'!$D$17>0,'Water Report'!$D$17,0)) -> 1 | AV2: =(IF('Water Report'!$D$18>0,'Water Report'!$D$18,0)) -> 14 | AW2: =(IF('Water Report'!$D$19>0,'Water Report'!$D$19,0)) -> 17 | AX2: =(IF('Water Report'!$D$21>0,'Water Report'!$D$21,0)) -> 103 | AY2: =(IF('Water Report'!$D$22>0,'Water Report'!$D$22,0)) -> 15 | AZ2: =(IF('Water Report'!$D$23>0,'Water Report'!$D$23,0)) -> 20 | BA2: =(IF('Water Report'!$D$14>0,'Water Report'!$D$14,0)) -> 5 | BB2: =(IF('Water Report'!$D$15>0,'Water Report'!$D$15,0)) -> 24 | BC2: =(IF('Water Report'!$D$13>0,'Water Report'!$D$13,0)) -> 15 | BD2: =(IF('Water Report'!$D$24>0,'Water Report'!$D$24,0)) -> 316 | BE2: =(IF('Water Report'!$D$25>0,'Water Report'!$D$25,0)) -> 230 | BF2: =(IF('Water Report'!$D$27>0,'Water Report'!$D$27,0)) -> 138 | BG2: =(IF('Section Load'!AN5>0,'Section Load'!AN5,0)) -> 1098 | BH2: =(IF('Section Load'!AO5>0,'Section Load'!AO5,0)) -> 328 | BI2: =(IF('Section Load'!AP5>0,'Section Load'!AP5,0)) -> 0 | BJ2: =(IF('Section Load'!AQ5>0,'Section Load'!AQ5,0)) -> 105 | BK2: =(IF('Section Load'!AR5>0,'Section Load'!AR5,0)) -> 48 | BL2: =(IF('Section Load'!AS5>0,'Section Load'!AS5,0)) -> 0 | BM2: =(IF('Section Load'!AT5>0,'Section Load'!AT5,0)) -> 617
A3: Mumbai | B3: =B2+1 -> 2 | C3: 6 | D3: 2022 | E3: =(IF('Section Load'!F6>0,'Section Load'!F6,0)) -> 3977 | F3: =(IF('Section Load'!G6>0,'Section Load'!G6,0)) -> 1795 | G3: =(IF('Section Load'!H6>0,'Section Load'!H6,0)) -> 2380 | H3: =(IF('Section Load'!I6>0,'Section Load'!I6,0)) -> 2966 | I3: =(IF('Section Load'!J6>0,'Section Load'!J6,0)) -> 8374 | J3: =(IF('Section Load'!K6>0,'Section Load'!K6,0)) -> 3077 | K3: =(IF('Section Load'!L6>0,'Section Load'!L6,0)) -> 850 | L3: =(IF('Section Load'!M6>0,'Section Load'!M6,0)) -> 984 | ... AL3: =(IF('Section Load'!AM6>0,'Section Load'!AM6,0)) -> 814 | AM3: =(IF('Water Report'!$E$7>0,'Water Report'!$E$7,0)) -> 165 | AN3: =(IF('Water Report'!$E$8>0,'Water Report'!$E$8,0)) -> 136 | AO3: =(IF('Water Report'!$E$9>0,'Water Report'!$E$9,0)) -> 105 | AP3: =(IF('Water Report'!$E$10>0,'Water Report'!$E$10,0)) -> 24 | AQ3: =(IF('Water Report'!$E$11>0,'Water Report'!$E$11,0)) -> 69 | AR3: =(IF('Water Report'!$E$13>0,'Water Report'!$E$13,0)) -> 17 | AS3: =(IF('Water Report'!$E$14>0,'Water Report'!$E$14,0)) -> 10 | AT3: =(IF('Water Report'!$E$15>0,'Water Report'!$E$15,0)) -> 8 | AU3: =(IF('Water Report'!$E$17>0,'Water Report'!$E$17,0)) -> 2 | AV3: =(IF('Water Report'!$E$18>0,'Water Report'!$E$18,0)) -> 14 | AW3: =(IF('Water Report'!$E$19>0,'Water Report'!$E$19,0)) -> 19 | AX3: =(IF('Water Report'!$E$21>0,'Water Report'!$E$21,0)) -> 92 | AY3: =(IF('Water Report'!$E$22>0,'Water Report'!$E$22,0)) -> 0 | AZ3: =(IF('Water Report'!$E$23>0,'Water Report'!$E$23,0)) -> 7 | BA3: =(IF('Water Report'!$E$14>0,'Water Report'!$E$14,0)) -> 10 | BB3: =(IF('Water Report'!$E$15>0,'Water Report'!$E$15,0)) -> 8 | BC3: =(IF('Water Report'!$E$13>0,'Water Report'!$E$13,0)) -> 17 | BD3: =(IF('Water Report'!$E$24>0,'Water Report'!$E$24,0)) -> 316 | BE3: =(IF('Water Report'!$E$25>0,'Water Report'!$E$25,0)) -> 216 | BF3: =(IF('Water Report'!$E$27>0,'Water Report'!$E$27,0)) -> 116 | BG3: =(IF('Section Load'!AN6>0,'Section Load'!AN6,0)) -> 1043 | BH3: =(IF('Section Load'!AO6>0,'Section Load'!AO6,0)) -> 331 | BI3: =(IF('Section Load'!AP6>0,'Section Load'!AP6,0)) -> 0 | BJ3: =(IF('Section Load'!AQ6>0,'Section Load'!AQ6,0)) -> 98 | BK3: =(IF('Section Load'!AR6>0,'Section Load'!AR6,0)) -> 41 | BL3: =(IF('Section Load'!AS6>0,'Section Load'!AS6,0)) -> 0 | BM3: =(IF('Section Load'!AT6>0,'Section Load'!AT6,0)) -> 573
A4: Mumbai | B4: =B3+1 -> 3 | C4: 6 | D4: 2022 | E4: =(IF('Section Load'!F7>0,'Section Load'!F7,0)) -> 3797 | F4: =(IF('Section Load'!G7>0,'Section Load'!G7,0)) -> 1844 | G4: =(IF('Section Load'!H7>0,'Section Load'!H7,0)) -> 2426 | H4: =(IF('Section Load'!I7>0,'Section Load'!I7,0)) -> 2963 | I4: =(IF('Section Load'!J7>0,'Section Load'!J7,0)) -> 8347 | J4: =(IF('Section Load'!K7>0,'Section Load'!K7,0)) -> 3116 | K4: =(IF('Section Load'!L7>0,'Section Load'!L7,0)) -> 1131 | L4: =(IF('Section Load'!M7>0,'Section Load'!M7,0)) -> 836 | ... AL4: =(IF('Section Load'!AM7>0,'Section Load'!AM7,0)) -> 869 | AM4: =(IF('Water Report'!$F$7>0,'Water Report'!$F$7,0)) -> 170 | AN4: =(IF('Water Report'!$F$8>0,'Water Report'!$F$8,0)) -> 132 | AO4: =(IF('Water Report'!$F$9>0,'Water Report'!$G$9,0)) -> 132 | AP4: =(IF('Water Report'!$F$10>0,'Water Report'!$F$10,0)) -> 31 | AQ4: =(IF('Water Report'!$F$11>0,'Water Report'!$F$11,0)) -> 74 | AR4: =(IF('Water Report'!$F$13>0,'Water Report'!$F$13,0)) -> 15 | AS4: =(IF('Water Report'!$F$14>0,'Water Report'!$F$14,0)) -> 6 | AT4: =(IF('Water Report'!$F$15>0,'Water Report'!$F$15,0)) -> 8 | AU4: =(IF('Water Report'!$F$17>0,'Water Report'!$F$17,0)) -> 0 | AV4: =(IF('Water Report'!$F$18>0,'Water Report'!$F$18,0)) -> 14 | AW4: =(IF('Water Report'!$F$19>0,'Water Report'!$F$19,0)) -> 17 | AX4: =(IF('Water Report'!$F$21>0,'Water Report'!$F$21,0)) -> 128 | AY4: =(IF('Water Report'!$F$22>0,'Water Report'!$F$22,0)) -> 0 | AZ4: =(IF('Water Report'!$F$23>0,'Water Report'!$F$23,0)) -> 18 | BA4: =(IF('Water Report'!$F$14>0,'Water Report'!$F$14,0)) -> 6 | BB4: =(IF('Water Report'!$F$15>0,'Water Report'!$F$15,0)) -> 8 | BC4: =(IF('Water Report'!$F$13>0,'Water Report'!$F$13,0)) -> 15 | BD4: =(IF('Water Report'!$F$24>0,'Water Report'!$F$24,0)) -> 304 | BE4: =(IF('Water Report'!$F$25>0,'Water Report'!$F$25,0)) -> 234 | BF4: =(IF('Water Report'!$F$27>0,'Water Report'!$F$27,0)) -> 161 | BG4: =(IF('Section Load'!AN7>0,'Section Load'!AN7,0)) -> 1104 | BH4: =(IF('Section Load'!AO7>0,'Section Load'!AO7,0)) -> 321 | BI4: =(IF('Section Load'!AP7>0,'Section Load'!AP7,0)) -> 0 | BJ4: =(IF('Section Load'!AQ7>0,'Section Load'!AQ7,0)) -> 135 | BK4: =(IF('Section Load'!AR7>0,'Section Load'!AR7,0)) -> 41 | BL4: =(IF('Section Load'!AS7>0,'Section Load'!AS7,0)) -> 0 | BM4: =(IF('Section Load'!AT7>0,'Section Load'!AT7,0)) -> 607
A5: Mumbai | B5: =B4+1 -> 4 | C5: 6 | D5: 2022 | E5: =(IF('Section Load'!F8>0,'Section Load'!F8,0)) -> 3536 | F5: =(IF('Section Load'!G8>0,'Section Load'!G8,0)) -> 1755 | G5: =(IF('Section Load'!H8>0,'Section Load'!H8,0)) -> 2483.99 | H5: =(IF('Section Load'!I8>0,'Section Load'!I8,0)) -> 2991 | I5: =(IF('Section Load'!J8>0,'Section Load'!J8,0)) -> 7679 | J5: =(IF('Section Load'!K8>0,'Section Load'!K8,0)) -> 3137 | K5: =(IF('Section Load'!L8>0,'Section Load'!L8,0)) -> 941 | L5: =(IF('Section Load'!M8>0,'Section Load'!M8,0)) -> 768 | ... AL5: =(IF('Section Load'!AM8>0,'Section Load'!AM8,0)) -> 863 | AM5: =(IF('Water Report'!$G$7>0,'Water Report'!$F$7,0)) -> 170 | AN5: =(IF('Water Report'!$G$8>0,'Water Report'!$F$8,0)) -> 132 | AO5: =(IF('Water Report'!$G$9>0,'Water Report'!$H$9,0)) -> 124 | AP5: =(IF('Water Report'!$G$10>0,'Water Report'!$G$10,0)) -> 31 | AQ5: =(IF('Water Report'!$G$11>0,'Water Report'!$G$11,0)) -> 75 | AR5: =(IF('Water Report'!$G$13>0,'Water Report'!$G$13,0)) -> 29 | AS5: =(IF('Water Report'!$G$14>0,'Water Report'!$G$14,0)) -> 28 | AT5: =(IF('Water Report'!$G$15>0,'Water Report'!$G$15,0)) -> 7 | AU5: =(IF('Water Report'!$G$17>0,'Water Report'!$G$17,0)) -> 0 | AV5: =(IF('Water Report'!$G$18>0,'Water Report'!$G$18,0)) -> 28 | AW5: =(IF('Water Report'!$G$19>0,'Water Report'!$G$19,0)) -> 16 | AX5: =(IF('Water Report'!$G$21>0,'Water Report'!$G$21,0)) -> 71 | AY5: =(IF('Water Report'!$G$22>0,'Water Report'!$G$22,0)) -> 0 | AZ5: =(IF('Water Report'!$G$23>0,'Water Report'!$G$23,0)) -> 18 | BA5: =(IF('Water Report'!$G$14>0,'Water Report'!$G$14,0)) -> 28 | BB5: =(IF('Water Report'!$G$15>0,'Water Report'!$G$15,0)) -> 7 | BC5: =(IF('Water Report'!$G$13>0,'Water Report'!$G$13,0)) -> 29 | BD5: =(IF('Water Report'!$G$24>0,'Water Report'!$G$24,0)) -> 314 | BE5: =(IF('Water Report'!$G$25>0,'Water Report'!$G$25,0)) -> 273 | BF5: =(IF('Water Report'!$G$27>0,'Water Report'!$G$27,0)) -> 118 | BG5: =(IF('Section Load'!AN8>0,'Section Load'!AN8,0)) -> 1121 | BH5: =(IF('Section Load'!AO8>0,'Section Load'!AO8,0)) -> 299 | BI5: =(IF('Section Load'!AP8>0,'Section Load'!AP8,0)) -> 0 | BJ5: =(IF('Section Load'!AQ8>0,'Section Load'!AQ8,0)) -> 116 | BK5: =(IF('Section Load'!AR8>0,'Section Load'!AR8,0)) -> 66 | BL5: =(IF('Section Load'!AS8>0,'Section Load'!AS8,0)) -> 0 | BM5: =(IF('Section Load'!AT8>0,'Section Load'!AT8,0)) -> 640
A6: Mumbai | B6: =B5+1 -> 5 | C6: 6 | D6: 2022 | E6: =(IF('Section Load'!F9>0,'Section Load'!F9,0)) -> 3453 | F6: =(IF('Section Load'!G9>0,'Section Load'!G9,0)) -> 1723.68 | G6: =(IF('Section Load'!H9>0,'Section Load'!H9,0)) -> 2433.01 | H6: =(IF('Section Load'!I9>0,'Section Load'!I9,0)) -> 3013 | I6: =(IF('Section Load'!J9>0,'Section Load'!J9,0)) -> 7126 | J6: =(IF('Section Load'!K9>0,'Section Load'!K9,0)) -> 2981 | K6: =(IF('Section Load'!L9>0,'Section Load'!L9,0)) -> 1674 | L6: =(IF('Section Load'!M9>0,'Section Load'!M9,0)) -> 741 | ... AL6: =(IF('Section Load'!AM9>0,'Section Load'!AM9,0)) -> 867 | AM6: =(IF('Water Report'!$H$7>0,'Water Report'!$H$7,0)) -> 225 | AN6: =(IF('Water Report'!$H$8>0,'Water Report'!$H$8,0)) -> 156 | AO6: =(IF('Water Report'!$H$9>0,'Water Report'!$H$9,0)) -> 124 | AP6: =(IF('Water Report'!$H$10>0,'Water Report'!$H$10,0)) -> 28 | AQ6: =(IF('Water Report'!$H$11>0,'Water Report'!$H$11,0)) -> 60 | AR6: =(IF('Water Report'!$H$13>0,'Water Report'!$H$13,0)) -> 39 | AS6: =(IF('Water Report'!$H$14>0,'Water Report'!$H$14,0)) -> 9 | AT6: =(IF('Water Report'!$H$15>0,'Water Report'!$H$15,0)) -> 6 | AU6: =(IF('Water Report'!$H$17>0,'Water Report'!$H$17,0)) -> 0 | AV6: =(IF('Water Report'!$H$18>0,'Water Report'!$H$18,0)) -> 0 | AW6: =(IF('Water Report'!$H$19>0,'Water Report'!$H$19,0)) -> 15 | AX6: =(IF('Water Report'!$H$21>0,'Water Report'!$H$21,0)) -> 91 | AY6: =(IF('Water Report'!$H$22>0,'Water Report'!$H$22,0)) -> 0 | AZ6: =(IF('Water Report'!$H$23>0,'Water Report'!$H$23,0)) -> 0 | BA6: =(IF('Water Report'!$H$14>0,'Water Report'!$H$14,0)) -> 9 | BB6: =(IF('Water Report'!$H$15>0,'Water Report'!$H$15,0)) -> 6 | BC6: =(IF('Water Report'!$H$13>0,'Water Report'!$H$13,0)) -> 39 | BD6: =(IF('Water Report'!$H$24>0,'Water Report'!$H$24,0)) -> 307 | BE6: =(IF('Water Report'!$H$25>0,'Water Report'!$H$25,0)) -> 227 | BF6: =(IF('Water Report'!$H$27>0,'Water Report'!$H$27,0)) -> 130 | BG6: =(IF('Section Load'!AN9>0,'Section Load'!AN9,0)) -> 1118 | BH6: =(IF('Section Load'!AO9>0,'Section Load'!AO9,0)) -> 323 | BI6: =(IF('Section Load'!AP9>0,'Section Load'!AP9,0)) -> 0 | BJ6: =(IF('Section Load'!AQ9>0,'Section Load'!AQ9,0)) -> 130 | BK6: =(IF('Section Load'!AR9>0,'Section Load'!AR9,0)) -> 46 | BL6: =(IF('Section Load'!AS9>0,'Section Load'!AS9,0)) -> 0.4 | BM6: =(IF('Section Load'!AT9>0,'Section Load'!AT9,0)) -> 618.6
A7: Mumbai | B7: =B6+1 -> 6 | C7: 6 | D7: 2022 | E7: =(IF('Section Load'!F10>0,'Section Load'!F10,0)) -> 3689 | F7: =(IF('Section Load'!G10>0,'Section Load'!G10,0)) -> 1752 | G7: =(IF('Section Load'!H10>0,'Section Load'!H10,0)) -> 2232 | H7: =(IF('Section Load'!I10>0,'Section Load'!I10,0)) -> 2982 | I7: =(IF('Section Load'!J10>0,'Section Load'!J10,0)) -> 9008 | J7: =(IF('Section Load'!K10>0,'Section Load'!K10,0)) -> 3199.58 | K7: =(IF('Section Load'!L10>0,'Section Load'!L10,0)) -> 1586 | L7: =(IF('Section Load'!M10>0,'Section Load'!M10,0)) -> 1086 | ... AL7: =(IF('Section Load'!AM10>0,'Section Load'!AM10,0)) -> 867 | AM7: =(IF('Water Report'!$I$7>0,'Water Report'!$I$7,0)) -> 100 | AN7: =(IF('Water Report'!$I$8>0,'Water Report'!$I$8,0)) -> 153 | AO7: =(IF('Water Report'!$I$9>0,'Water Report'!$I$9,0)) -> 106 | AP7: =(IF('Water Report'!$I$10>0,'Water Report'!$I$10,0)) -> 25 | AQ7: =(IF('Water Report'!$I$11>0,'Water Report'!$I$11,0)) -> 12 | AR7: =(IF('Water Report'!$I$13>0,'Water Report'!$I$13,0)) -> 17 | AS7: =(IF('Water Report'!$I$14>0,'Water Report'!$I$14,0)) -> 12 | AT7: =(IF('Water Report'!$I$15>0,'Water Report'!$I$15,0)) -> 4 | AU7: =(IF('Water Report'!$I$17>0,'Water Report'!$I$17,0)) -> 2 | AV7: =(IF('Water Report'!$I$18>0,'Water Report'!$I$18,0)) -> 13 | AW7: =(IF('Water Report'!$I$19>0,'Water Report'!$I$19,0)) -> 13 | AX7: =(IF('Water Report'!$I$21>0,'Water Report'!$I$21,0)) -> 133.7 | AY7: =(IF('Water Report'!$I$22>0,'Water Report'!$I$22,0)) -> 0 | AZ7: =(IF('Water Report'!$I$23>0,'Water Report'!$I$23,0)) -> 5 | BA7: =(IF('Water Report'!$I$14>0,'Water Report'!$I$14,0)) -> 12 | BB7: =(IF('Water Report'!$I$15>0,'Water Report'!$I$15,0)) -> 4 | BC7: =(IF('Water Report'!$I$13>0,'Water Report'!$I$13,0)) -> 17 | BD7: =(IF('Water Report'!$I$24>0,'Water Report'!$I$24,0)) -> 355 | BE7: =(IF('Water Report'!$I$25>0,'Water Report'!$I$25,0)) -> 159 | BF7: =(IF('Water Report'!$I$27>0,'Water Report'!$I$27,0)) -> 155.7 | BG7: =(IF('Section Load'!AN10>0,'Section Load'!AN10,0)) -> 1084.6 | BH7: =(IF('Section Load'!AO10>0,'Section Load'!AO10,0)) -> 311.43 | BI7: =(IF('Section Load'!AP10>0,'Section Load'!AP10,0)) -> 0 | BJ7: =(IF('Section Load'!AQ10>0,'Section Load'!AQ10,0)) -> 129.1 | BK7: =(IF('Section Load'!AR10>0,'Section Load'!AR10,0)) -> 41.3 | BL7: =(IF('Section Load'!AS10>0,'Section Load'!AS10,0)) -> 0 | BM7: =(IF('Section Load'!AT10>0,'Section Load'!AT10,0)) -> 602.77
A8: Mumbai | B8: =B7+1 -> 7 | C8: 6 | D8: 2022 | E8: =(IF('Section Load'!F11>0,'Section Load'!F11,0)) -> 3639 | F8: =(IF('Section Load'!G11>0,'Section Load'!G11,0)) -> 1684 | G8: =(IF('Section Load'!H11>0,'Section Load'!H11,0)) -> 2322 | H8: =(IF('Section Load'!I11>0,'Section Load'!I11,0)) -> 3002 | I8: =(IF('Section Load'!J11>0,'Section Load'!J11,0)) -> 8056.2 | J8: =(IF('Section Load'!K11>0,'Section Load'!K11,0)) -> 3153.92 | K8: =(IF('Section Load'!L11>0,'Section Load'!L11,0)) -> 1080 | L8: =(IF('Section Load'!M11>0,'Section Load'!M11,0)) -> 1022 | ... AL8: =(IF('Section Load'!AM11>0,'Section Load'!AM11,0)) -> 819 | AM8: =(IF('Water Report'!$J$7>0,'Water Report'!$J$7,0)) -> 172.4 | AN8: =(IF('Water Report'!$J$8>0,'Water Report'!$J$8,0)) -> 145 | AO8: =(IF('Water Report'!$J$9>0,'Water Report'!$J$9,0)) -> 157 | AP8: =(IF('Water Report'!$J$10>0,'Water Report'!$J$10,0)) -> 32 | AQ8: =(IF('Water Report'!$J$11>0,'Water Report'!$J$11,0)) -> 15 | AR8: =(IF('Water Report'!$J$13>0,'Water Report'!$J$13,0)) -> 21 | AS8: =(IF('Water Report'!$J$14>0,'Water Report'!$J$14,0)) -> 25 | AT8: =(IF('Water Report'!$J$15>0,'Water Report'!$J$15,0)) -> 6 | AU8: =(IF('Water Report'!$J$17>0,'Water Report'!$J$17,0)) -> 1 | AV8: =(IF('Water Report'!$J$18>0,'Water Report'!$J$18,0)) -> 15 | AW8: =(IF('Water Report'!$J$19>0,'Water Report'!$J$19,0)) -> 14 | AX8: =(IF('Water Report'!$J$21>0,'Water Report'!$J$21,0)) -> 115.3 | AY8: =(IF('Water Report'!$J$22>0,'Water Report'!$J$22,0)) -> 93 | AZ8: =(IF('Water Report'!$J$23>0,'Water Report'!$J$23,0)) -> 20 | BA8: =(IF('Water Report'!$J$14>0,'Water Report'!$J$14,0)) -> 25 | BB8: =(IF('Water Report'!$J$15>0,'Water Report'!$J$15,0)) -> 6 | BC8: =(IF('Water Report'!$J$13>0,'Water Report'!$J$13,0)) -> 21 | BD8: =(IF('Water Report'!$J$24>0,'Water Report'!$J$24,0)) -> 218 | BE8: =(IF('Water Report'!$J$25>0,'Water Report'!$J$25,0)) -> 235 | BF8: =(IF('Water Report'!$J$27>0,'Water Report'!$J$27,0)) -> 156.3 | BG8: =(IF('Section Load'!AN11>0,'Section Load'!AN11,0)) -> 1078.6 | BH8: =(IF('Section Load'!AO11>0,'Section Load'!AO11,0)) -> 321.13 | BI8: =(IF('Section Load'!AP11>0,'Section Load'!AP11,0)) -> 0 | BJ8: =(IF('Section Load'!AQ11>0,'Section Load'!AQ11,0)) -> 117.9 | BK8: =(IF('Section Load'!AR11>0,'Section Load'!AR11,0)) -> 52.6 | BL8: =(IF('Section Load'!AS11>0,'Section Load'!AS11,0)) -> 0 | BM8: =(IF('Section Load'!AT11>0,'Section Load'!AT11,0)) -> 586.97
A9: Mumbai | B9: =B8+1 -> 8 | C9: 6 | D9: 2022 | E9: =(IF('Section Load'!F12>0,'Section Load'!F12,0)) -> 1259 | F9: =(IF('Section Load'!G12>0,'Section Load'!G12,0)) -> 572 | G9: =(IF('Section Load'!H12>0,'Section Load'!H12,0)) -> 735 | H9: =(IF('Section Load'!I12>0,'Section Load'!I12,0)) -> 939 | I9: =(IF('Section Load'!J12>0,'Section Load'!J12,0)) -> 2008 | J9: =(IF('Section Load'!K12>0,'Section Load'!K12,0)) -> 3336.73 | K9: =(IF('Section Load'!L12>0,'Section Load'!L12,0)) -> 419 | L9: =(IF('Section Load'!M12>0,'Section Load'!M12,0)) -> 301 | ... AL9: =(IF('Section Load'!AM12>0,'Section Load'!AM12,0)) -> 320 | AM9: =(IF('Water Report'!$K$7>0,'Water Report'!$K$7,0)) -> 87.6 | AN9: =(IF('Water Report'!$K$8>0,'Water Report'!$K$8,0)) -> 81 | AO9: =(IF('Water Report'!$K$9>0,'Water Report'!$K$9,0)) -> 92 | AP9: =(IF('Water Report'!$K$10>0,'Water Report'!$K$10,0)) -> 25 | AQ9: =(IF('Water Report'!$K$11>0,'Water Report'!$K$11,0)) -> 13 | AR9: =(IF('Water Report'!$K$13>0,'Water Report'!$K$13,0)) -> 31 | AS9: =(IF('Water Report'!$K$14>0,'Water Report'!$K$14,0)) -> 8 | AT9: =(IF('Water Report'!$K$15>0,'Water Report'!$K$15,0)) -> 6 | AU9: =(IF('Water Report'!$K$17>0,'Water Report'!$K$17,0)) -> 3 | AV9: =(IF('Water Report'!$K$18>0,'Water Report'!$K$18,0)) -> 15 | AW9: =(IF('Water Report'!$K$19>0,'Water Report'!$K$19,0)) -> 13 | AX9: =(IF('Water Report'!$K$21>0,'Water Report'!$K$21,0)) -> 106 | AY9: =(IF('Water Report'!$K$22>0,'Water Report'!$K$22,0)) -> 34 | AZ9: =(IF('Water Report'!$K$23>0,'Water Report'!$K$23,0)) -> 4 | BA9: =(IF('Water Report'!$K$14>0,'Water Report'!$K$14,0)) -> 8 | BB9: =(IF('Water Report'!$K$15>0,'Water Report'!$K$15,0)) -> 6 | BC9: =(IF('Water Report'!$K$13>0,'Water Report'!$K$13,0)) -> 31 | BD9: =(IF('Water Report'!$K$24>0,'Water Report'!$K$24,0)) -> 195 | BE9: =(IF('Water Report'!$K$25>0,'Water Report'!$K$25,0)) -> 144 | BF9: =(IF('Water Report'!$K$27>0,'Water Report'!$K$27,0)) -> 141 | BG9: =(IF('Section Load'!AN12>0,'Section Load'!AN12,0)) -> 1052.8 | BH9: =(IF('Section Load'!AO12>0,'Section Load'!AO12,0)) -> 293.18 | BI9: =(IF('Section Load'!AP12>0,'Section Load'!AP12,0)) -> 0 | BJ9: =(IF('Section Load'!AQ12>0,'Section Load'!AQ12,0)) -> 113 | BK9: =(IF('Section Load'!AR12>0,'Section Load'!AR12,0)) -> 49.1 | BL9: =(IF('Section Load'!AS12>0,'Section Load'!AS12,0)) -> 0 | BM9: =(IF('Section Load'!AT12>0,'Section Load'!AT12,0)) -> 597.92
A10: Mumbai | B10: =B9+1 -> 9 | C10: 6 | D10: 2022 | E10: =(IF('Section Load'!F13>0,'Section Load'!F13,0)) -> 3675.9 | F10: =(IF('Section Load'!G13>0,'Section Load'!G13,0)) -> 3107.32 | G10: =(IF('Section Load'!H13>0,'Section Load'!H13,0)) -> 2250.79 | H10: =(IF('Section Load'!I13>0,'Section Load'!I13,0)) -> 2000 | I10: =(IF('Section Load'!J13>0,'Section Load'!J13,0)) -> 13570.42 | J10: =(IF('Section Load'!K13>0,'Section Load'!K13,0)) -> 3248.63 | K10: =(IF('Section Load'!L13>0,'Section Load'!L13,0)) -> 1886.93 | L10: =(IF('Section Load'!M13>0,'Section Load'!M13,0)) -> 1629 | ... AL10: =(IF('Section Load'!AM13>0,'Section Load'!AM13,0)) -> 1437.25 | AM10: =(IF('Water Report'!$L$7>0,'Water Report'!$L$7,0)) -> 127 | AN10: =(IF('Water Report'!$L$8>0,'Water Report'!$L$8,0)) -> 129 | AO10: =(IF('Water Report'!$L$9>0,'Water Report'!$L$9,0)) -> 119 | AP10: =(IF('Water Report'!$L$10>0,'Water Report'!$L$10,0)) -> 31 | AQ10: =(IF('Water Report'!$L$11>0,'Water Report'!$L$11,0)) -> 15 | AR10: =(IF('Water Report'!$L$13>0,'Water Report'!$L$13,0)) -> 40 | AS10: =(IF('Water Report'!$L$14>0,'Water Report'!$L$14,0)) -> 8 | AT10: =(IF('Water Report'!$L$15>0,'Water Report'!$L$15,0)) -> 9 | AU10: =(IF('Water Report'!$L$17>0,'Water Report'!$L$17,0)) -> 0 | AV10: =(IF('Water Report'!$L$18>0,'Water Report'!$L$18,0)) -> 13 | AW10: =(IF('Water Report'!$L$19>0,'Water Report'!$L$19,0)) -> 13 | AX10: =(IF('Water Report'!$L$21>0,'Water Report'!$L$21,0)) -> 137 | AY10: =(IF('Water Report'!$L$22>0,'Water Report'!$L$22,0)) -> 30 | AZ10: =(IF('Water Report'!$L$23>0,'Water Report'!$L$23,0)) -> 30 | BA10: =(IF('Water Report'!$L$14>0,'Water Report'!$L$14,0)) -> 8 | BB10: =(IF('Water Report'!$L$15>0,'Water Report'!$L$15,0)) -> 9 | BC10: =(IF('Water Report'!$L$13>0,'Water Report'!$L$13,0)) -> 40 | BD10: =(IF('Water Report'!$L$24>0,'Water Report'!$L$24,0)) -> 280 | BE10: =(IF('Water Report'!$L$25>0,'Water Report'!$L$25,0)) -> 182 | BF10: =(IF('Water Report'!$L$27>0,'Water Report'!$L$27,0)) -> 207 | BG10: =(IF('Section Load'!AN13>0,'Section Load'!AN13,0)) -> 916 | BH10: =(IF('Section Load'!AO13>0,'Section Load'!AO13,0)) -> 300.152 | BI10: =(IF('Section Load'!AP13>0,'Section Load'!AP13,0)) -> 0 | BJ10: =(IF('Section Load'!AQ13>0,'Section Load'!AQ13,0)) -> 96 | BK10: =(IF('Section Load'!AR13>0,'Section Load'!AR13,0)) -> 43 | BL10: =(IF('Section Load'!AS13>0,'Section Load'!AS13,0)) -> 0 | BM10: =(IF('Section Load'!AT13>0,'Section Load'!AT13,0)) -> 477.648
A11: Mumbai | B11: =B10+1 -> 10 | C11: 6 | D11: 2022 | E11: =(IF('Section Load'!F14>0,'Section Load'!F14,0)) -> 3797.05 | F11: =(IF('Section Load'!G14>0,'Section Load'!G14,0)) -> 1758.13 | G11: =(IF('Section Load'!H14>0,'Section Load'!H14,0)) -> 2457.45 | H11: =(IF('Section Load'!I14>0,'Section Load'!I14,0)) -> 3079.09 | I11: =(IF('Section Load'!J14>0,'Section Load'!J14,0)) -> 10623.72 | J11: =(IF('Section Load'!K14>0,'Section Load'!K14,0)) -> 3197.04 | K11: =(IF('Section Load'!L14>0,'Section Load'!L14,0)) -> 1407.18 | L11: =(IF('Section Load'!M14>0,'Section Load'!M14,0)) -> 985.8 | ... AL11: =(IF('Section Load'!AM14>0,'Section Load'!AM14,0)) -> 848.5 | AM11: =(IF('Water Report'!$M$7>0,'Water Report'!$M$7,0)) -> 131 | AN11: =(IF('Water Report'!$M$8>0,'Water Report'!$M$8,0)) -> 105 | AO11: =(IF('Water Report'!$M$9>0,'Water Report'!$M$9,0)) -> 116 | AP11: =(IF('Water Report'!$M$10>0,'Water Report'!$M$10,0)) -> 23 | AQ11: =(IF('Water Report'!$M$11>0,'Water Report'!$M$11,0)) -> 2 | AR11: =(IF('Water Report'!$M$13>0,'Water Report'!$M$13,0)) -> 31 | AS11: =(IF('Water Report'!$M$14>0,'Water Report'!$M$14,0)) -> 10 | AT11: =(IF('Water Report'!$M$15>0,'Water Report'!$M$15,0)) -> 15 | AU11: =(IF('Water Report'!$M$17>0,'Water Report'!$M$17,0)) -> 2 | AV11: =(IF('Water Report'!$M$18>0,'Water Report'!$M$18,0)) -> 17 | AW11: =(IF('Water Report'!$M$19>0,'Water Report'!$M$19,0)) -> 13 | AX11: =(IF('Water Report'!$M$21>0,'Water Report'!$M$21,0)) -> 110 | AY11: =(IF('Water Report'!$M$22>0,'Water Report'!$M$22,0)) -> 29 | AZ11: =(IF('Water Report'!$M$23>0,'Water Report'!$M$23,0)) -> 3 | BA11: =(IF('Water Report'!$M$14>0,'Water Report'!$M$14,0)) -> 10 | BB11: =(IF('Water Report'!$M$15>0,'Water Report'!$M$15,0)) -> 15 | BC11: =(IF('Water Report'!$M$13>0,'Water Report'!$M$13,0)) -> 31 | BD11: =(IF('Water Report'!$M$24>0,'Water Report'!$M$24,0)) -> 200 | BE11: =(IF('Water Report'!$M$25>0,'Water Report'!$M$25,0)) -> 166 | BF11: =(IF('Water Report'!$M$27>0,'Water Report'!$M$27,0)) -> 144 | BG11: =(IF('Section Load'!AN14>0,'Section Load'!AN14,0)) -> 1061.5 | BH11: =(IF('Section Load'!AO14>0,'Section Load'!AO14,0)) -> 291.281 | BI11: =(IF('Section Load'!AP14>0,'Section Load'!AP14,0)) -> 0.8 | BJ11: =(IF('Section Load'!AQ14>0,'Section Load'!AQ14,0)) -> 108 | BK11: =(IF('Section Load'!AR14>0,'Section Load'!AR14,0)) -> 58 | BL11: =(IF('Section Load'!AS14>0,'Section Load'!AS14,0)) -> 0 | BM11: =(IF('Section Load'!AT14>0,'Section Load'!AT14,0)) -> 603.419
A12: Mumbai | B12: =B11+1 -> 11 | C12: 6 | D12: 2022 | E12: =(IF('Section Load'!F15>0,'Section Load'!F15,0)) -> 3749.11 | F12: =(IF('Section Load'!G15>0,'Section Load'!G15,0)) -> 1739.12 | G12: =(IF('Section Load'!H15>0,'Section Load'!H15,0)) -> 2491.7 | H12: =(IF('Section Load'!I15>0,'Section Load'!I15,0)) -> 3101.95 | I12: =(IF('Section Load'!J15>0,'Section Load'!J15,0)) -> 9978.85 | J12: =(IF('Section Load'!K15>0,'Section Load'!K15,0)) -> 3247.2 | K12: =(IF('Section Load'!L15>0,'Section Load'!L15,0)) -> 995.78 | L12: =(IF('Section Load'!M15>0,'Section Load'!M15,0)) -> 719.1 | ... AL12: =(IF('Section Load'!AM15>0,'Section Load'!AM15,0)) -> 866.25 | AM12: =(IF('Water Report'!$N$7>0,'Water Report'!$N$7,0)) -> 142 | AN12: =(IF('Water Report'!$N$8>0,'Water Report'!$N$8,0)) -> 121 | AO12: =(IF('Water Report'!$N$9>0,'Water Report'!$N$9,0)) -> 129 | AP12: =(IF('Water Report'!$N$10>0,'Water Report'!$N$10,0)) -> 33 | AQ12: =(IF('Water Report'!$N$11>0,'Water Report'!$N$11,0)) -> 0 | AR12: =(IF('Water Report'!$N$13>0,'Water Report'!$N$13,0)) -> 36 | AS12: =(IF('Water Report'!$N$14>0,'Water Report'!$N$14,0)) -> 8 | AT12: =(IF('Water Report'!$N$15>0,'Water Report'!$N$15,0)) -> 8 | AU12: =(IF('Water Report'!$N$17>0,'Water Report'!$N$17,0)) -> 1 | AV12: =(IF('Water Report'!$N$18>0,'Water Report'!$N$18,0)) -> 16 | AW12: =(IF('Water Report'!$N$19>0,'Water Report'!$N$19,0)) -> 13 | AX12: =(IF('Water Report'!$N$21>0,'Water Report'!$N$21,0)) -> 135 | AY12: =(IF('Water Report'!$N$22>0,'Water Report'!$N$22,0)) -> 1 | AZ12: =(IF('Water Report'!$N$23>0,'Water Report'!$N$23,0)) -> 4 | BA12: =(IF('Water Report'!$N$14>0,'Water Report'!$N$14,0)) -> 8 | BB12: =(IF('Water Report'!$N$15>0,'Water Report'!$N$15,0)) -> 8 | BC12: =(IF('Water Report'!$N$13>0,'Water Report'!$N$13,0)) -> 36 | BD12: =(IF('Water Report'!$N$24>0,'Water Report'!$N$24,0)) -> 360 | BE12: =(IF('Water Report'!$N$25>0,'Water Report'!$N$25,0)) -> 178 | BF12: =(IF('Water Report'!$N$27>0,'Water Report'!$N$27,0)) -> 175 | BG12: =(IF('Section Load'!AN15>0,'Section Load'!AN15,0)) -> 1053.5 | BH12: =(IF('Section Load'!AO15>0,'Section Load'!AO15,0)) -> 278.507 | BI12: =(IF('Section Load'!AP15>0,'Section Load'!AP15,0)) -> 0 | BJ12: =(IF('Section Load'!AQ15>0,'Section Load'!AQ15,0)) -> 105 | BK12: =(IF('Section Load'!AR15>0,'Section Load'!AR15,0)) -> 50 | BL12: =(IF('Section Load'!AS15>0,'Section Load'!AS15,0)) -> 0.4 | BM12: =(IF('Section Load'!AT15>0,'Section Load'!AT15,0)) -> 619.593
A13: Mumbai | B13: =B12+1 -> 12 | C13: 6 | D13: 2022 | E13: =(IF('Section Load'!F16>0,'Section Load'!F16,0)) -> 3949.94 | F13: =(IF('Section Load'!G16>0,'Section Load'!G16,0)) -> 1720.75 | G13: =(IF('Section Load'!H16>0,'Section Load'!H16,0)) -> 2523.3 | H13: =(IF('Section Load'!I16>0,'Section Load'!I16,0)) -> 3189.05 | I13: =(IF('Section Load'!J16>0,'Section Load'!J16,0)) -> 10292.75 | J13: =(IF('Section Load'!K16>0,'Section Load'!K16,0)) -> 3313.9 | K13: =(IF('Section Load'!L16>0,'Section Load'!L16,0)) -> 949.11 | L13: =(IF('Section Load'!M16>0,'Section Load'!M16,0)) -> 955.1 | ... AL13: =(IF('Section Load'!AM16>0,'Section Load'!AM16,0)) -> 908 | AM13: =(IF('Water Report'!$O$7>0,'Water Report'!$O$7,0)) -> 122 | AN13: =(IF('Water Report'!$O$8>0,'Water Report'!$O$8,0)) -> 154 | AO13: =(IF('Water Report'!$O$9>0,'Water Report'!$O$9,0)) -> 109 | AP13: =(IF('Water Report'!$O$10>0,'Water Report'!$O$10,0)) -> 29 | AQ13: =(IF('Water Report'!$O$11>0,'Water Report'!$O$11,0)) -> 0 | AR13: =(IF('Water Report'!$O$13>0,'Water Report'!$O$13,0)) -> 37 | AS13: =(IF('Water Report'!$O$14>0,'Water Report'!$O$14,0)) -> 8 | AT13: =(IF('Water Report'!$O$15>0,'Water Report'!$O$15,0)) -> 7 | AU13: =(IF('Water Report'!$O$17>0,'Water Report'!$O$17,0)) -> 0 | AV13: =(IF('Water Report'!$O$18>0,'Water Report'!$O$18,0)) -> 16 | AW13: =(IF('Water Report'!$O$19>0,'Water Report'!$O$19,0)) -> 14 | AX13: =(IF('Water Report'!$O$21>0,'Water Report'!$O$21,0)) -> 76 | AY13: =(IF('Water Report'!$O$22>0,'Water Report'!$O$22,0)) -> 16 | AZ13: =(IF('Water Report'!$O$23>0,'Water Report'!$O$23,0)) -> 6 | BA13: =(IF('Water Report'!$O$14>0,'Water Report'!$O$14,0)) -> 8 | BB13: =(IF('Water Report'!$O$15>0,'Water Report'!$O$15,0)) -> 7 | BC13: =(IF('Water Report'!$O$13>0,'Water Report'!$O$13,0)) -> 37 | BD13: =(IF('Water Report'!$O$24>0,'Water Report'!$O$24,0)) -> 270 | BE13: =(IF('Water Report'!$O$25>0,'Water Report'!$O$25,0)) -> 153 | BF13: =(IF('Water Report'!$O$27>0,'Water Report'!$O$27,0)) -> 119 | BG13: =(IF('Section Load'!AN16>0,'Section Load'!AN16,0)) -> 1039 | BH13: =(IF('Section Load'!AO16>0,'Section Load'!AO16,0)) -> 320.32 | BI13: =(IF('Section Load'!AP16>0,'Section Load'!AP16,0)) -> 0.2 | BJ13: =(IF('Section Load'!AQ16>0,'Section Load'!AQ16,0)) -> 106 | BK13: =(IF('Section Load'!AR16>0,'Section Load'!AR16,0)) -> 45 | BL13: =(IF('Section Load'!AS16>0,'Section Load'!AS16,0)) -> 0 | BM13: =(IF('Section Load'!AT16>0,'Section Load'!AT16,0)) -> 567.48
A14: Mumbai | B14: =B13+1 -> 13 | C14: 6 | D14: 2022 | E14: =(IF('Section Load'!F17>0,'Section Load'!F17,0)) -> 3857 | F14: =(IF('Section Load'!G17>0,'Section Load'!G17,0)) -> 1681 | G14: =(IF('Section Load'!H17>0,'Section Load'!H17,0)) -> 2350 | H14: =(IF('Section Load'!I17>0,'Section Load'!I17,0)) -> 3101 | I14: =(IF('Section Load'!J17>0,'Section Load'!J17,0)) -> 9751 | J14: =(IF('Section Load'!K17>0,'Section Load'!K17,0)) -> 3231 | K14: =(IF('Section Load'!L17>0,'Section Load'!L17,0)) -> 945 | L14: =(IF('Section Load'!M17>0,'Section Load'!M17,0)) -> 703 | ... AL14: =(IF('Section Load'!AM17>0,'Section Load'!AM17,0)) -> 864 | AM14: =(IF('Water Report'!$P$7>0,'Water Report'!$P$7,0)) -> 133 | AN14: =(IF('Water Report'!$P$8>0,'Water Report'!$P$8,0)) -> 92 | AO14: =(IF('Water Report'!$P$9>0,'Water Report'!$P$9,0)) -> 136 | AP14: =(IF('Water Report'!$P$10>0,'Water Report'!$P$10,0)) -> 23 | AQ14: =(IF('Water Report'!$P$11>0,'Water Report'!$P$11,0)) -> 0 | AR14: =(IF('Water Report'!$P$13>0,'Water Report'!$P$13,0)) -> 38 | AS14: =(IF('Water Report'!$P$14>0,'Water Report'!$P$14,0)) -> 7 | AT14: =(IF('Water Report'!$P$15>0,'Water Report'!$P$15,0)) -> 8 | AU14: =(IF('Water Report'!$P$17>0,'Water Report'!$P$17,0)) -> 0 | AV14: =(IF('Water Report'!$P$18>0,'Water Report'!$P$18,0)) -> 15 | AW14: =(IF('Water Report'!$P$19>0,'Water Report'!$P$19,0)) -> 10 | AX14: =(IF('Water Report'!$P$21>0,'Water Report'!$P$21,0)) -> 78 | AY14: =(IF('Water Report'!$P$22>0,'Water Report'!$P$22,0)) -> 0 | AZ14: =(IF('Water Report'!$P$23>0,'Water Report'!$P$23,0)) -> 0 | BA14: =(IF('Water Report'!$P$14>0,'Water Report'!$P$14,0)) -> 7 | BB14: =(IF('Water Report'!$P$15>0,'Water Report'!$P$15,0)) -> 8 | BC14: =(IF('Water Report'!$P$13>0,'Water Report'!$P$13,0)) -> 38 | BD14: =(IF('Water Report'!$P$24>0,'Water Report'!$P$24,0)) -> 280 | BE14: =(IF('Water Report'!$P$25>0,'Water Report'!$P$25,0)) -> 174 | BF14: =(IF('Water Report'!$P$27>0,'Water Report'!$P$27,0)) -> 116 | BG14: =(IF('Section Load'!AN17>0,'Section Load'!AN17,0)) -> 1055 | BH14: =(IF('Section Load'!AO17>0,'Section Load'!AO17,0)) -> 318 | BI14: =(IF('Section Load'!AP17>0,'Section Load'!AP17,0)) -> 0 | BJ14: =(IF('Section Load'!AQ17>0,'Section Load'!AQ17,0)) -> 113 | BK14: =(IF('Section Load'!AR17>0,'Section Load'!AR17,0)) -> 47 | BL14: =(IF('Section Load'!AS17>0,'Section Load'!AS17,0)) -> 0 | BM14: =(IF('Section Load'!AT17>0,'Section Load'!AT17,0)) -> 577.6
A15: Mumbai | B15: =B14+1 -> 14 | C15: 6 | D15: 2022 | E15: =(IF('Section Load'!F18>0,'Section Load'!F18,0)) -> 3734 | F15: =(IF('Section Load'!G18>0,'Section Load'!G18,0)) -> 1688 | G15: =(IF('Section Load'!H18>0,'Section Load'!H18,0)) -> 2405 | H15: =(IF('Section Load'!I18>0,'Section Load'!I18,0)) -> 2986 | I15: =(IF('Section Load'!J18>0,'Section Load'!J18,0)) -> 9169.4 | J15: =(IF('Section Load'!K18>0,'Section Load'!K18,0)) -> 3212 | K15: =(IF('Section Load'!L18>0,'Section Load'!L18,0)) -> 953 | L15: =(IF('Section Load'!M18>0,'Section Load'!M18,0)) -> 1123 | ... AL15: =(IF('Section Load'!AM18>0,'Section Load'!AM18,0)) -> 754 | AM15: =(IF('Water Report'!$Q$7>0,'Water Report'!$Q$7,0)) -> 135 | AN15: =(IF('Water Report'!$Q$8>0,'Water Report'!$Q$8,0)) -> 152 | AO15: =(IF('Water Report'!$Q$9>0,'Water Report'!$Q$9,0)) -> 128 | AP15: =(IF('Water Report'!$Q$10>0,'Water Report'!$Q$10,0)) -> 30 | AQ15: =(IF('Water Report'!$Q$11>0,'Water Report'!$Q$11,0)) -> 1 | AR15: =(IF('Water Report'!$Q$13>0,'Water Report'!$Q$13,0)) -> 40 | AS15: =(IF('Water Report'!$Q$14>0,'Water Report'!$Q$14,0)) -> 7 | AT15: =(IF('Water Report'!$Q$15>0,'Water Report'!$Q$15,0)) -> 8 | AU15: =(IF('Water Report'!$Q$17>0,'Water Report'!$Q$17,0)) -> 0 | AV15: =(IF('Water Report'!$Q$18>0,'Water Report'!$Q$18,0)) -> 16 | AW15: =(IF('Water Report'!$Q$19>0,'Water Report'!$Q$19,0)) -> 15 | AX15: =(IF('Water Report'!$Q$21>0,'Water Report'!$Q$21,0)) -> 155 | AY15: =(IF('Water Report'!$Q$22>0,'Water Report'!$Q$22,0)) -> 0 | AZ15: =(IF('Water Report'!$Q$23>0,'Water Report'!$Q$23,0)) -> 2 | BA15: =(IF('Water Report'!$Q$14>0,'Water Report'!$Q$14,0)) -> 7 | BB15: =(IF('Water Report'!$Q$15>0,'Water Report'!$Q$15,0)) -> 8 | BC15: =(IF('Water Report'!$Q$13>0,'Water Report'!$Q$13,0)) -> 40 | BD15: =(IF('Water Report'!$Q$24>0,'Water Report'!$Q$24,0)) -> 290 | BE15: =(IF('Water Report'!$Q$25>0,'Water Report'!$Q$25,0)) -> 174 | BF15: =(IF('Water Report'!$Q$27>0,'Water Report'!$Q$27,0)) -> 197 | BG15: =(IF('Section Load'!AN18>0,'Section Load'!AN18,0)) -> 1050 | BH15: =(IF('Section Load'!AO18>0,'Section Load'!AO18,0)) -> 314 | BI15: =(IF('Section Load'!AP18>0,'Section Load'!AP18,0)) -> 0 | BJ15: =(IF('Section Load'!AQ18>0,'Section Load'!AQ18,0)) -> 109 | BK15: =(IF('Section Load'!AR18>0,'Section Load'!AR18,0)) -> 45 | BL15: =(IF('Section Load'!AS18>0,'Section Load'!AS18,0)) -> 0 | BM15: =(IF('Section Load'!AT18>0,'Section Load'!AT18,0)) -> 582
A16: Mumbai | B16: =B15+1 -> 15 | C16: 6 | D16: 2022 | E16: =(IF('Section Load'!F19>0,'Section Load'!F19,0)) -> 3640 | F16: =(IF('Section Load'!G19>0,'Section Load'!G19,0)) -> 1655 | G16: =(IF('Section Load'!H19>0,'Section Load'!H19,0)) -> 2311 | H16: =(IF('Section Load'!I19>0,'Section Load'!I19,0)) -> 3010 | I16: =(IF('Section Load'!J19>0,'Section Load'!J19,0)) -> 9511 | J16: =(IF('Section Load'!K19>0,'Section Load'!K19,0)) -> 3224 | K16: =(IF('Section Load'!L19>0,'Section Load'!L19,0)) -> 977 | L16: =(IF('Section Load'!M19>0,'Section Load'!M19,0)) -> 699 | ... AL16: =(IF('Section Load'!AM19>0,'Section Load'!AM19,0)) -> 725 | AM16: =(IF('Water Report'!$R$7>0,'Water Report'!$R$7,0)) -> 132 | AN16: =(IF('Water Report'!$R$8>0,'Water Report'!$R$8,0)) -> 142 | AO16: =(IF('Water Report'!$R$9>0,'Water Report'!$R$9,0)) -> 107 | AP16: =(IF('Water Report'!$R$10>0,'Water Report'!$R$10,0)) -> 19 | AQ16: =(IF('Water Report'!$R$11>0,'Water Report'!$R$11,0)) -> 0 | AR16: =(IF('Water Report'!$R$13>0,'Water Report'!$R$13,0)) -> 33 | AS16: =(IF('Water Report'!$R$14>0,'Water Report'!$R$14,0)) -> 22 | AT16: =(IF('Water Report'!$R$15>0,'Water Report'!$R$15,0)) -> 5 | AU16: =(IF('Water Report'!$R$17>0,'Water Report'!$R$17,0)) -> 0 | AV16: =(IF('Water Report'!$R$18>0,'Water Report'!$R$18,0)) -> 14 | AW16: =(IF('Water Report'!$R$19>0,'Water Report'!$R$19,0)) -> 14 | AX16: =(IF('Water Report'!$R$21>0,'Water Report'!$R$21,0)) -> 110 | AY16: =(IF('Water Report'!$R$22>0,'Water Report'!$R$22,0)) -> 0 | AZ16: =(IF('Water Report'!$R$23>0,'Water Report'!$R$23,0)) -> 1 | BA16: =(IF('Water Report'!$R$14>0,'Water Report'!$R$14,0)) -> 22 | BB16: =(IF('Water Report'!$R$15>0,'Water Report'!$R$15,0)) -> 5 | BC16: =(IF('Water Report'!$R$13>0,'Water Report'!$R$13,0)) -> 33 | BD16: =(IF('Water Report'!$R$24>0,'Water Report'!$R$24,0)) -> 250 | BE16: =(IF('Water Report'!$R$25>0,'Water Report'!$R$25,0)) -> 153 | BF16: =(IF('Water Report'!$R$27>0,'Water Report'!$R$27,0)) -> 144 | BG16: =(IF('Section Load'!AN19>0,'Section Load'!AN19,0)) -> 1071 | BH16: =(IF('Section Load'!AO19>0,'Section Load'!AO19,0)) -> 312 | BI16: =(IF('Section Load'!AP19>0,'Section Load'!AP19,0)) -> 0 | BJ16: =(IF('Section Load'!AQ19>0,'Section Load'!AQ19,0)) -> 114 | BK16: =(IF('Section Load'!AR19>0,'Section Load'!AR19,0)) -> 52 | BL16: =(IF('Section Load'!AS19>0,'Section Load'!AS19,0)) -> 0 | BM16: =(IF('Section Load'!AT19>0,'Section Load'!AT19,0)) -> 593
A17: Mumbai | B17: =B16+1 -> 16 | C17: 6 | D17: 2022 | E17: =(IF('Section Load'!F20>0,'Section Load'!F20,0)) -> 3360 | F17: =(IF('Section Load'!G20>0,'Section Load'!G20,0)) -> 1666 | G17: =(IF('Section Load'!H20>0,'Section Load'!H20,0)) -> 2366 | H17: =(IF('Section Load'!I20>0,'Section Load'!I20,0)) -> 3099 | I17: =(IF('Section Load'!J20>0,'Section Load'!J20,0)) -> 10363 | J17: =(IF('Section Load'!K20>0,'Section Load'!K20,0)) -> 3266 | K17: =(IF('Section Load'!L20>0,'Section Load'!L20,0)) -> 861 | L17: =(IF('Section Load'!M20>0,'Section Load'!M20,0)) -> 634 | ... AL17: =(IF('Section Load'!AM20>0,'Section Load'!AM20,0)) -> 622 | AM17: =(IF('Water Report'!$S$7>0,'Water Report'!$S$7,0)) -> 123 | AN17: =(IF('Water Report'!$S$8>0,'Water Report'!$S$8,0)) -> 127 | AO17: =(IF('Water Report'!$S$9>0,'Water Report'!$S$9,0)) -> 123 | AP17: =(IF('Water Report'!$S$10>0,'Water Report'!$D$10,0)) -> 18 | AQ17: =(IF('Water Report'!$S$11>0,'Water Report'!$D$11,0)) -> 0 | AR17: =(IF('Water Report'!$S$13>0,'Water Report'!$D$13,0)) -> 15 | AS17: =(IF('Water Report'!$S$14>0,'Water Report'!$D$14,0)) -> 5 | AT17: =(IF('Water Report'!$S$15>0,'Water Report'!$D$15,0)) -> 24 | AU17: =(IF('Water Report'!$S$17>0,'Water Report'!$D$17,0)) -> 0 | AV17: =(IF('Water Report'!$S$18>0,'Water Report'!$D$18,0)) -> 14 | AW17: =(IF('Water Report'!$S$19>0,'Water Report'!$D$19,0)) -> 17 | AX17: =(IF('Water Report'!$S$21>0,'Water Report'!$D$21,0)) -> 103 | AY17: =(IF('Water Report'!$S$22>0,'Water Report'!$D$22,0)) -> 0 | AZ17: =(IF('Water Report'!$S$23>0,'Water Report'!$D$23,0)) -> 20 | BA17: =(IF('Water Report'!$S$14>0,'Water Report'!$D$14,0)) -> 5 | BB17: =(IF('Water Report'!$S$15>0,'Water Report'!$D$15,0)) -> 24 | BC17: =(IF('Water Report'!$S$13>0,'Water Report'!$D$13,0)) -> 15 | BD17: =(IF('Water Report'!$S$24>0,'Water Report'!$D$24,0)) -> 316 | BE17: =(IF('Water Report'!$S$25>0,'Water Report'!$D$25,0)) -> 230 | BF17: =(IF('Water Report'!$S$27>0,'Water Report'!$D$27,0)) -> 138 | BG17: =(IF('Section Load'!AN20>0,'Section Load'!AN20,0)) -> 1026 | BH17: =(IF('Section Load'!AO20>0,'Section Load'!AO20,0)) -> 311 | BI17: =(IF('Section Load'!AP20>0,'Section Load'!AP20,0)) -> 0 | BJ17: =(IF('Section Load'!AQ20>0,'Section Load'!AQ20,0)) -> 63 | BK17: =(IF('Section Load'!AR20>0,'Section Load'!AR20,0)) -> 43 | BL17: =(IF('Section Load'!AS20>0,'Section Load'!AS20,0)) -> 0 | BM17: =(IF('Section Load'!AT20>0,'Section Load'!AT20,0)) -> 609
A18: Mumbai | B18: =B17+1 -> 17 | C18: 6 | D18: 2022 | E18: =(IF('Section Load'!F21>0,'Section Load'!F21,0)) -> 3494 | F18: =(IF('Section Load'!G21>0,'Section Load'!G21,0)) -> 1704 | G18: =(IF('Section Load'!H21>0,'Section Load'!H21,0)) -> 2355 | H18: =(IF('Section Load'!I21>0,'Section Load'!I21,0)) -> 3142 | I18: =(IF('Section Load'!J21>0,'Section Load'!J21,0)) -> 10550 | J18: =(IF('Section Load'!K21>0,'Section Load'!K21,0)) -> 3226 | K18: =(IF('Section Load'!L21>0,'Section Load'!L21,0)) -> 1457 | L18: =(IF('Section Load'!M21>0,'Section Load'!M21,0)) -> 721 | ... AL18: =(IF('Section Load'!AM21>0,'Section Load'!AM21,0)) -> 609 | AM18: =(IF('Water Report'!$T$7>0,'Water Report'!$T$7,0)) -> 117 | AN18: =(IF('Water Report'!$T$8>0,'Water Report'!$T$8,0)) -> 109 | AO18: =(IF('Water Report'!$T$9>0,'Water Report'!$T$9,0)) -> 119 | AP18: =(IF('Water Report'!$T$10>0,'Water Report'!$T$10,0)) -> 20 | AQ18: =(IF('Water Report'!$T$11>0,'Water Report'!$T$11,0)) -> 0 | AR18: =(IF('Water Report'!$T$13>0,'Water Report'!$T$13,0)) -> 66 | AS18: =(IF('Water Report'!$T$14>0,'Water Report'!$T$14,0)) -> 7 | AT18: =(IF('Water Report'!$T$15>0,'Water Report'!$T$15,0)) -> 6 | AU18: =(IF('Water Report'!$T$17>0,'Water Report'!$T$17,0)) -> 0 | AV18: =(IF('Water Report'!$T$18>0,'Water Report'!$T$18,0)) -> 14 | AW18: =(IF('Water Report'!$T$19>0,'Water Report'!$T$19,0)) -> 12 | AX18: =(IF('Water Report'!$T$21>0,'Water Report'!$T$21,0)) -> 64 | AY18: =(IF('Water Report'!$T$22>0,'Water Report'!$T$22,0)) -> 0 | AZ18: =(IF('Water Report'!$T$23>0,'Water Report'!$T$23,0)) -> 2 | BA18: =(IF('Water Report'!$T$14>0,'Water Report'!$T$14,0)) -> 7 | BB18: =(IF('Water Report'!$T$15>0,'Water Report'!$T$15,0)) -> 6 | BC18: =(IF('Water Report'!$T$13>0,'Water Report'!$T$13,0)) -> 66 | BD18: =(IF('Water Report'!$T$24>0,'Water Report'!$T$24,0)) -> 283 | BE18: =(IF('Water Report'!$T$25>0,'Water Report'!$T$25,0)) -> 152 | BF18: =(IF('Water Report'!$T$27>0,'Water Report'!$T$27,0)) -> 132 | BG18: =(IF('Section Load'!AN21>0,'Section Load'!AN21,0)) -> 1015 | BH18: =(IF('Section Load'!AO21>0,'Section Load'!AO21,0)) -> 293.52 | BI18: =(IF('Section Load'!AP21>0,'Section Load'!AP21,0)) -> 0 | BJ18: =(IF('Section Load'!AQ21>0,'Section Load'!AQ21,0)) -> 132 | BK18: =(IF('Section Load'!AR21>0,'Section Load'!AR21,0)) -> 38 | BL18: =(IF('Section Load'!AS21>0,'Section Load'!AS21,0)) -> 0 | BM18: =(IF('Section Load'!AT21>0,'Section Load'!AT21,0)) -> 551.48
A19: Mumbai | B19: =B18+1 -> 18 | C19: 6 | D19: 2022 | E19: =(IF('Section Load'!F22>0,'Section Load'!F22,0)) -> 3488 | F19: =(IF('Section Load'!G22>0,'Section Load'!G22,0)) -> 1729 | G19: =(IF('Section Load'!H22>0,'Section Load'!H22,0)) -> 2397 | H19: =(IF('Section Load'!I22>0,'Section Load'!I22,0)) -> 3158 | I19: =(IF('Section Load'!J22>0,'Section Load'!J22,0)) -> 10831 | J19: =(IF('Section Load'!K22>0,'Section Load'!K22,0)) -> 3098 | K19: =(IF('Section Load'!L22>0,'Section Load'!L22,0)) -> 1503 | L19: =(IF('Section Load'!M22>0,'Section Load'!M22,0)) -> 1045 | ... AL19: =(IF('Section Load'!AM22>0,'Section Load'!AM22,0)) -> 628 | AM19: =(IF('Water Report'!$U$7>0,'Water Report'!$U$7,0)) -> 118 | AN19: =(IF('Water Report'!$U$8>0,'Water Report'!$U$8,0)) -> 168 | AO19: =(IF('Water Report'!$U$9>0,'Water Report'!$U$9,0)) -> 112 | AP19: =(IF('Water Report'!$U$10>0,'Water Report'!$U$10,0)) -> 24 | AQ19: =(IF('Water Report'!$U$11>0,'Water Report'!$U$11,0)) -> 0 | AR19: =(IF('Water Report'!$U$13>0,'Water Report'!$U$13,0)) -> 59 | AS19: =(IF('Water Report'!$U$14>0,'Water Report'!$U$14,0)) -> 9 | AT19: =(IF('Water Report'!$U$15>0,'Water Report'!$U$15,0)) -> 7 | AU19: =(IF('Water Report'!$U$17>0,'Water Report'!$U$17,0)) -> 0 | AV19: =(IF('Water Report'!$U$18>0,'Water Report'!$U$18,0)) -> 15 | AW19: =(IF('Water Report'!$U$19>0,'Water Report'!$U$19,0)) -> 14 | AX19: =(IF('Water Report'!$U$21>0,'Water Report'!$U$21,0)) -> 108 | AY19: =(IF('Water Report'!$U$22>0,'Water Report'!$U$22,0)) -> 0 | AZ19: =(IF('Water Report'!$U$23>0,'Water Report'!$U$23,0)) -> 3 | BA19: =(IF('Water Report'!$U$14>0,'Water Report'!$U$14,0)) -> 9 | BB19: =(IF('Water Report'!$U$15>0,'Water Report'!$U$15,0)) -> 7 | BC19: =(IF('Water Report'!$U$13>0,'Water Report'!$U$13,0)) -> 59 | BD19: =(IF('Water Report'!$U$24>0,'Water Report'!$U$24,0)) -> 232 | BE19: =(IF('Water Report'!$U$25>0,'Water Report'!$U$25,0)) -> 152 | BF19: =(IF('Water Report'!$U$27>0,'Water Report'!$U$27,0)) -> 170 | BG19: =(IF('Section Load'!AN22>0,'Section Load'!AN22,0)) -> 1052 | BH19: =(IF('Section Load'!AO22>0,'Section Load'!AO22,0)) -> 297.48 | BI19: =(IF('Section Load'!AP22>0,'Section Load'!AP22,0)) -> 0 | BJ19: =(IF('Section Load'!AQ22>0,'Section Load'!AQ22,0)) -> 111 | BK19: =(IF('Section Load'!AR22>0,'Section Load'!AR22,0)) -> 50 | BL19: =(IF('Section Load'!AS22>0,'Section Load'!AS22,0)) -> 0 | BM19: =(IF('Section Load'!AT22>0,'Section Load'!AT22,0)) -> 593.52
A20: Mumbai | B20: =B19+1 -> 19 | C20: 6 | D20: 2022 | E20: =(IF('Section Load'!F23>0,'Section Load'!F23,0)) -> 3557 | F20: =(IF('Section Load'!G23>0,'Section Load'!G23,0)) -> 1734 | G20: =(IF('Section Load'!H23>0,'Section Load'!H23,0)) -> 2342 | H20: =(IF('Section Load'!I23>0,'Section Load'!I23,0)) -> 3175 | I20: =(IF('Section Load'!J23>0,'Section Load'!J23,0)) -> 10354 | J20: =(IF('Section Load'!K23>0,'Section Load'!K23,0)) -> 3130 | K20: =(IF('Section Load'!L23>0,'Section Load'!L23,0)) -> 958 | L20: =(IF('Section Load'!M23>0,'Section Load'!M23,0)) -> 1321 | ... AL20: =(IF('Section Load'!AM23>0,'Section Load'!AM23,0)) -> 623 | AM20: =(IF('Water Report'!$V$7>0,'Water Report'!$V$7,0)) -> 116 | AN20: =(IF('Water Report'!$V$8>0,'Water Report'!$V$8,0)) -> 157 | AO20: =(IF('Water Report'!$V$9>0,'Water Report'!$V$9,0)) -> 110 | AP20: =(IF('Water Report'!$V$10>0,'Water Report'!$V$10,0)) -> 23 | AQ20: =(IF('Water Report'!$V$11>0,'Water Report'!$V$11,0)) -> 0 | AR20: =(IF('Water Report'!$V$13>0,'Water Report'!$V$13,0)) -> 45 | AS20: =(IF('Water Report'!$V$14>0,'Water Report'!$V$14,0)) -> 11 | AT20: =(IF('Water Report'!$V$15>0,'Water Report'!$V$15,0)) -> 8 | AU20: =(IF('Water Report'!$V$17>0,'Water Report'!$V$17,0)) -> 0 | AV20: =(IF('Water Report'!$V$18>0,'Water Report'!$V$18,0)) -> 16 | AW20: =(IF('Water Report'!$V$19>0,'Water Report'!$V$19,0)) -> 11 | AX20: =(IF('Water Report'!$V$21>0,'Water Report'!$V$21,0)) -> 111 | AY20: =(IF('Water Report'!$V$22>0,'Water Report'!$V$22,0)) -> 0 | AZ20: =(IF('Water Report'!$V$23>0,'Water Report'!$V$23,0)) -> 2 | BA20: =(IF('Water Report'!$V$14>0,'Water Report'!$V$14,0)) -> 11 | BB20: =(IF('Water Report'!$V$15>0,'Water Report'!$V$15,0)) -> 8 | BC20: =(IF('Water Report'!$V$13>0,'Water Report'!$V$13,0)) -> 45 | BD20: =(IF('Water Report'!$V$24>0,'Water Report'!$V$24,0)) -> 212 | BE20: =(IF('Water Report'!$V$25>0,'Water Report'!$V$25,0)) -> 152 | BF20: =(IF('Water Report'!$V$27>0,'Water Report'!$V$27,0)) -> 158 | BG20: =(IF('Section Load'!AN23>0,'Section Load'!AN23,0)) -> 1047 | BH20: =(IF('Section Load'!AO23>0,'Section Load'!AO23,0)) -> 300 | BI20: =(IF('Section Load'!AP23>0,'Section Load'!AP23,0)) -> 0 | BJ20: =(IF('Section Load'!AQ23>0,'Section Load'!AQ23,0)) -> 118 | BK20: =(IF('Section Load'!AR23>0,'Section Load'!AR23,0)) -> 63 | BL20: =(IF('Section Load'!AS23>0,'Section Load'!AS23,0)) -> 0 | BM20: =(IF('Section Load'!AT23>0,'Section Load'!AT23,0)) -> 566
A21: Mumbai | B21: =B20+1 -> 20 | C21: 6 | D21: 2022 | E21: =(IF('Section Load'!F24>0,'Section Load'!F24,0)) -> 3591 | F21: =(IF('Section Load'!G24>0,'Section Load'!G24,0)) -> 1669 | G21: =(IF('Section Load'!H24>0,'Section Load'!H24,0)) -> 2341 | H21: =(IF('Section Load'!I24>0,'Section Load'!I24,0)) -> 3213 | I21: =(IF('Section Load'!J24>0,'Section Load'!J24,0)) -> 9993 | J21: =(IF('Section Load'!K24>0,'Section Load'!K24,0)) -> 3092 | K21: =(IF('Section Load'!L24>0,'Section Load'!L24,0)) -> 1133 | L21: =(IF('Section Load'!M24>0,'Section Load'!M24,0)) -> 1199 | ... AL21: =(IF('Section Load'!AM24>0,'Section Load'!AM24,0)) -> 619 | AM21: =(IF('Water Report'!$W$7>0,'Water Report'!$W$7,0)) -> 125 | AN21: =(IF('Water Report'!$W$8>0,'Water Report'!$W$8,0)) -> 145 | AO21: =(IF('Water Report'!$W$9>0,'Water Report'!$W$9,0)) -> 117 | AP21: =(IF('Water Report'!$W$10>0,'Water Report'!$W$10,0)) -> 23 | AQ21: =(IF('Water Report'!$W$11>0,'Water Report'!$W$11,0)) -> 0 | AR21: =(IF('Water Report'!$W$13>0,'Water Report'!$W$13,0)) -> 36 | AS21: =(IF('Water Report'!$W$14>0,'Water Report'!$W$14,0)) -> 7 | AT21: =(IF('Water Report'!$W$15>0,'Water Report'!$W$15,0)) -> 20 | AU21: =(IF('Water Report'!$W$17>0,'Water Report'!$W$17,0)) -> 0 | AV21: =(IF('Water Report'!$W$18>0,'Water Report'!$W$18,0)) -> 14 | AW21: =(IF('Water Report'!$W$19>0,'Water Report'!$W$19,0)) -> 11 | AX21: =(IF('Water Report'!$W$21>0,'Water Report'!$W$21,0)) -> 110 | AY21: =(IF('Water Report'!$W$22>0,'Water Report'!$W$22,0)) -> 0 | AZ21: =(IF('Water Report'!$W$23>0,'Water Report'!$W$23,0)) -> 2 | BA21: =(IF('Water Report'!$W$14>0,'Water Report'!$W$14,0)) -> 7 | BB21: =(IF('Water Report'!$W$15>0,'Water Report'!$W$15,0)) -> 20 | BC21: =(IF('Water Report'!$W$13>0,'Water Report'!$W$13,0)) -> 36 | BD21: =(IF('Water Report'!$W$24>0,'Water Report'!$W$24,0)) -> 253 | BE21: =(IF('Water Report'!$W$25>0,'Water Report'!$W$25,0)) -> 167 | BF21: =(IF('Water Report'!$W$27>0,'Water Report'!$W$27,0)) -> 148 | BG21: =(IF('Section Load'!AN24>0,'Section Load'!AN24,0)) -> 1014 | BH21: =(IF('Section Load'!AO24>0,'Section Load'!AO24,0)) -> 296 | BI21: =(IF('Section Load'!AP24>0,'Section Load'!AP24,0)) -> 0 | BJ21: =(IF('Section Load'!AQ24>0,'Section Load'!AQ24,0)) -> 103 | BK21: =(IF('Section Load'!AR24>0,'Section Load'!AR24,0)) -> 42 | BL21: =(IF('Section Load'!AS24>0,'Section Load'!AS24,0)) -> 0 | BM21: =(IF('Section Load'!AT24>0,'Section Load'!AT24,0)) -> 573
A22: Mumbai | B22: =B21+1 -> 21 | C22: 6 | D22: 2022 | E22: =(IF('Section Load'!F25>0,'Section Load'!F25,0)) -> 3632.07 | F22: =(IF('Section Load'!G25>0,'Section Load'!G25,0)) -> 1661.05 | G22: =(IF('Section Load'!H25>0,'Section Load'!H25,0)) -> 2383.15 | H22: =(IF('Section Load'!I25>0,'Section Load'!I25,0)) -> 3123.91 | I22: =(IF('Section Load'!J25>0,'Section Load'!J25,0)) -> 7747.26 | J22: =(IF('Section Load'!K25>0,'Section Load'!K25,0)) -> 3040.23 | K22: =(IF('Section Load'!L25>0,'Section Load'!L25,0)) -> 1132.41 | L22: =(IF('Section Load'!M25>0,'Section Load'!M25,0)) -> 811.33 | ... AL22: =(IF('Section Load'!AM25>0,'Section Load'!AM25,0)) -> 623.91 | AM22: =(IF('Water Report'!$X$7>0,'Water Report'!$X$7,0)) -> 103 | AN22: =(IF('Water Report'!$X$8>0,'Water Report'!$X$8,0)) -> 115 | AO22: =(IF('Water Report'!$X$9>0,'Water Report'!$X$9,0)) -> 102 | AP22: =(IF('Water Report'!$X$10>0,'Water Report'!$X$10,0)) -> 15 | AQ22: =(IF('Water Report'!$X$11>0,'Water Report'!$X$11,0)) -> 0 | AR22: =(IF('Water Report'!$X$13>0,'Water Report'!$X$13,0)) -> 33 | AS22: =(IF('Water Report'!$X$14>0,'Water Report'!$X$14,0)) -> 3 | AT22: =(IF('Water Report'!$X$15>0,'Water Report'!$X$15,0)) -> 5 | AU22: =(IF('Water Report'!$X$17>0,'Water Report'!$X$17,0)) -> 0 | AV22: =(IF('Water Report'!$X$18>0,'Water Report'!$X$18,0)) -> 17 | AW22: =(IF('Water Report'!$X$19>0,'Water Report'!$X$19,0)) -> 13 | AX22: =(IF('Water Report'!$X$21>0,'Water Report'!$X$21,0)) -> 116 | AY22: =(IF('Water Report'!$X$22>0,'Water Report'!$X$22,0)) -> 0 | AZ22: =(IF('Water Report'!$X$23>0,'Water Report'!$X$23,0)) -> 0 | BA22: =(IF('Water Report'!$X$14>0,'Water Report'!$X$14,0)) -> 3 | BB22: =(IF('Water Report'!$X$15>0,'Water Report'!$X$15,0)) -> 5 | BC22: =(IF('Water Report'!$X$13>0,'Water Report'!$X$13,0)) -> 33 | BD22: =(IF('Water Report'!$X$24>0,'Water Report'!$X$24,0)) -> 263 | BE22: =(IF('Water Report'!$X$25>0,'Water Report'!$X$25,0)) -> 125 | BF22: =(IF('Water Report'!$X$27>0,'Water Report'!$X$27,0)) -> 149 | BG22: =(IF('Section Load'!AN25>0,'Section Load'!AN25,0)) -> 1049.42 | BH22: =(IF('Section Load'!AO25>0,'Section Load'!AO25,0)) -> 293.62 | BI22: =(IF('Section Load'!AP25>0,'Section Load'!AP25,0)) -> 0 | BJ22: =(IF('Section Load'!AQ25>0,'Section Load'!AQ25,0)) -> 113.63 | BK22: =(IF('Section Load'!AR25>0,'Section Load'!AR25,0)) -> 45.4 | BL22: =(IF('Section Load'!AS25>0,'Section Load'!AS25,0)) -> 0 | BM22: =(IF('Section Load'!AT25>0,'Section Load'!AT25,0)) -> 596.77
A23: Mumbai | B23: =B22+1 -> 22 | C23: 6 | D23: 2022 | E23: =(IF('Section Load'!F26>0,'Section Load'!F26,0)) -> 3530.44 | F23: =(IF('Section Load'!G26>0,'Section Load'!G26,0)) -> 1658.74 | G23: =(IF('Section Load'!H26>0,'Section Load'!H26,0)) -> 2286.4 | H23: =(IF('Section Load'!I26>0,'Section Load'!I26,0)) -> 3040.24 | I23: =(IF('Section Load'!J26>0,'Section Load'!J26,0)) -> 8692.71 | J23: =(IF('Section Load'!K26>0,'Section Load'!K26,0)) -> 3050.06 | K23: =(IF('Section Load'!L26>0,'Section Load'!L26,0)) -> 1142.5 | L23: =(IF('Section Load'!M26>0,'Section Load'!M26,0)) -> 719.92 | ... AL23: =(IF('Section Load'!AM26>0,'Section Load'!AM26,0)) -> 605.14 | AM23: =(IF('Water Report'!$Y$7>0,'Water Report'!$Y$7,0)) -> 95 | AN23: =(IF('Water Report'!$Y$8>0,'Water Report'!$Y$8,0)) -> 133 | AO23: =(IF('Water Report'!$Y$9>0,'Water Report'!$Y$9,0)) -> 100 | AP23: =(IF('Water Report'!$Y$10>0,'Water Report'!$Y$10,0)) -> 19 | AQ23: =(IF('Water Report'!$Y$11>0,'Water Report'!$Y$11,0)) -> 0 | AR23: =(IF('Water Report'!$Y$13>0,'Water Report'!$Y$13,0)) -> 51 | AS23: =(IF('Water Report'!$Y$14>0,'Water Report'!$Y$14,0)) -> 5 | AT23: =(IF('Water Report'!$Y$15>0,'Water Report'!$Y$15,0)) -> 6 | AU23: =(IF('Water Report'!$Y$17>0,'Water Report'!$Y$17,0)) -> 0 | AV23: =(IF('Water Report'!$Y$18>0,'Water Report'!$Y$18,0)) -> 16 | AW23: =(IF('Water Report'!$Y$19>0,'Water Report'!$Y$19,0)) -> 11 | AX23: =(IF('Water Report'!$Y$21>0,'Water Report'!$Y$21,0)) -> 115 | AY23: =(IF('Water Report'!$Y$22>0,'Water Report'!$Y$22,0)) -> 0 | AZ23: =(IF('Water Report'!$Y$23>0,'Water Report'!$Y$23,0)) -> 3 | BA23: =(IF('Water Report'!$Y$14>0,'Water Report'!$Y$14,0)) -> 5 | BB23: =(IF('Water Report'!$Y$15>0,'Water Report'!$Y$15,0)) -> 6 | BC23: =(IF('Water Report'!$Y$13>0,'Water Report'!$Y$13,0)) -> 51 | BD23: =(IF('Water Report'!$Y$24>0,'Water Report'!$Y$24,0)) -> 243 | BE23: =(IF('Water Report'!$Y$25>0,'Water Report'!$Y$25,0)) -> 130 | BF23: =(IF('Water Report'!$Y$27>0,'Water Report'!$Y$27,0)) -> 169 | BG23: =(IF('Section Load'!AN26>0,'Section Load'!AN26,0)) -> 974.61 | BH23: =(IF('Section Load'!AO26>0,'Section Load'!AO26,0)) -> 299.88 | BI23: =(IF('Section Load'!AP26>0,'Section Load'!AP26,0)) -> 0 | BJ23: =(IF('Section Load'!AQ26>0,'Section Load'!AQ26,0)) -> 97.87 | BK23: =(IF('Section Load'!AR26>0,'Section Load'!AR26,0)) -> 34.8 | BL23: =(IF('Section Load'!AS26>0,'Section Load'!AS26,0)) -> 0 | BM23: =(IF('Section Load'!AT26>0,'Section Load'!AT26,0)) -> 542.06
