Workbook

Sheet Total
A1: Site Name | B1: Day | C1: Month | D1: Year | E1: Total Electricity Kwh | F1: Electricity Tariff ($/Kwh) | G1: Natual Gas (m3) | H1: Natural Gas $/m3 | I1: Water Utility Supply (m3) m3 | J1: Water Utility Supply (m3) $/m3 | K1: Room Nights | L1: Total Guests
A2: Istanbul at the Bosphorus | B2: 1 | C2: 1 | D2: 2022 | E2: ='Electricity '!I4+'Electricity '!O4 -> 24202.44 | F2: 2.06 | G2: ='Gas Water'!M5 -> 2757 | H2: 6.17 | I2: ='Gas Water'!L5 -> 184 | J2: 14.95 | K2: 145 | L2: 294
A3: Istanbul at the Bosphorus | B3: 2 | C3: 1 | D3: 2022 | E3: ='Electricity '!I5+'Electricity '!O5 -> 24239.7 | F3: 2.06 | G3: ='Gas Water'!M6 -> 2787 | H3: 6.17 | I3: ='Gas Water'!L6 -> 202 | J3: 14.95 | K3: 127 | L3: 252
A4: Istanbul at the Bosphorus | B4: 3 | C4: 1 | D4: 2022 | E4: ='Electricity '!I6+'Electricity '!O6 -> 21979.26 | F4: 2.06 | G4: ='Gas Water'!M7 -> 2470 | H4: 6.17 | I4: ='Gas Water'!L7 -> 221 | J4: 14.95 | K4: 143 | L4: 256
A5: Istanbul at the Bosphorus | B5: 4 | C5: 1 | D5: 2022 | E5: ='Electricity '!I7+'Electricity '!O7 -> 21432.78 | F5: 2.06 | G5: ='Gas Water'!M8 -> 2283 | H5: 6.17 | I5: ='Gas Water'!L8 -> 206 | J5: 14.95 | K5: 148 | L5: 255
A6: Istanbul at the Bosphorus | B6: 5 | C6: 1 | D6: 2022 | E6: ='Electricity '!I8+'Electricity '!O8 -> 22736.88 | F6: 2.06 | G6: ='Gas Water'!M9 -> 2077 | H6: 6.17 | I6: ='Gas Water'!L9 -> 183 | J6: 14.95 | K6: 147 | L6: 265
A7: Istanbul at the Bosphorus | B7: 6 | C7: 1 | D7: 2022 | E7: ='Electricity '!I9+'Electricity '!O9 -> 23142.6 | F7: 2.06 | G7: ='Gas Water'!M10 -> 2098 | H7: 6.17 | I7: ='Gas Water'!L10 -> 174 | J7: 14.95 | K7: 152 | L7: 279
A8: Istanbul at the Bosphorus | B8: 7 | C8: 1 | D8: 2022 | E8: ='Electricity '!I10+'Electricity '!O10 -> 23693.22 | F8: 2.06 | G8: ='Gas Water'!M11 -> 2634 | H8: 6.17 | I8: ='Gas Water'!L11 -> 179 | J8: 14.95 | K8: 155 | L8: 296
A9: Istanbul at the Bosphorus | B9: 8 | C9: 1 | D9: 2022 | E9: ='Electricity '!I12+'Electricity '!O11 -> 23763.6 | F9: 2.06 | G9: ='Gas Water'!M12 -> 2711 | H9: 6.17 | I9: ='Gas Water'!L12 -> 190 | J9: 14.95 | K9: 136 | L9: 264
A10: Istanbul at the Bosphorus | B10: 9 | C10: 1 | D10: 2022 | E10: ='Electricity '!I13+'Electricity '!O12 -> 24012 | F10: 2.06 | G10: ='Gas Water'!M13 -> 2672 | H10: 6.17 | I10: ='Gas Water'!L13 -> 223 | J10: 14.95 | K10: 125 | L10: 224
A11: Istanbul at the Bosphorus | B11: 10 | C11: 1 | D11: 2022 | E11: ='Electricity '!I14+'Electricity '!O13 -> 24065.82 | F11: 2.06 | G11: ='Gas Water'!M14 -> 2670 | H11: 6.17 | I11: ='Gas Water'!L14 -> 182 | J11: 14.95 | K11: 98 | L11: 164
A12: Istanbul at the Bosphorus | B12: 11 | C12: 1 | D12: 2022 | E12: ='Electricity '!I14+'Electricity '!O14 -> 24065.82 | F12: 2.06 | G12: ='Gas Water'!M15 -> 3164 | H12: 6.17 | I12: ='Gas Water'!L15 -> 148 | J12: 14.95 | K12: 97 | L12: 159
A13: Istanbul at the Bosphorus | B13: 12 | C13: 1 | D13: 2022 | E13: ='Electricity '!I15+'Electricity '!O15 -> 23991.3 | F13: 2.06 | G13: ='Gas Water'!M16 -> 3991 | H13: 6.17 | I13: ='Gas Water'!L16 -> 175 | J13: 14.95 | K13: 96 | L13: 139
A14: Istanbul at the Bosphorus | B14: 13 | C14: 1 | D14: 2022 | E14: ='Electricity '!I16+'Electricity '!O16 -> 23179.86 | F14: 2.06 | G14: ='Gas Water'!M17 -> 4064 | H14: 6.17 | I14: ='Gas Water'!L17 -> 122 | J14: 14.95 | K14: 102 | L14: 167
A15: Istanbul at the Bosphorus | B15: 14 | C15: 1 | D15: 2022 | E15: ='Electricity '!I17+'Electricity '!O17 -> 23473.8 | F15: 2.06 | G15: ='Gas Water'!M18 -> 3946 | H15: 6.17 | I15: ='Gas Water'!L18 -> 144 | J15: 14.95 | K15: 111 | L15: 186
A16: Istanbul at the Bosphorus | B16: 15 | C16: 1 | D16: 2022 | E16: ='Electricity '!I18+'Electricity '!O18 -> 23560.74 | F16: 2.06 | G16: ='Gas Water'!M19 -> 3639 | H16: 6.17 | I16: ='Gas Water'!L19 -> 161 | J16: 14.95 | K16: 100 | L16: 178
A17: Istanbul at the Bosphorus | B17: 16 | C17: 1 | D17: 2022 | E17: ='Electricity '!I19+'Electricity '!O19 -> 23378.58 | F17: 2.06 | G17: ='Gas Water'!M20 -> 3669 | H17: 6.17 | I17: ='Gas Water'!L20 -> 139 | J17: 14.95 | K17: 67 | L17: 116
A18: Istanbul at the Bosphorus | B18: 17 | C18: 1 | D18: 2022 | E18: 24653 | F18: 2.06 | G18: 3409 | H18: 6.17 | I18: 168 | J18: 14.95 | K18: 46 | L18: 84
A19: Istanbul at the Bosphorus | B19: 18 | C19: 1 | D19: 2022 | E19: 23080 | F19: 2.06 | G19: 3817 | H19: 6.17 | I19: 121 | J19: 14.95 | K19: 57 | L19: 89
A20: Istanbul at the Bosphorus | B20: 19 | C20: 1 | D20: 2022 | E20: 23101 | F20: 2.06 | G20: 4098 | H20: 6.17 | I20: 128 | J20: 14.95 | K20: 67 | L20: 109
A21: Istanbul at the Bosphorus | B21: 20 | C21: 1 | D21: 2022 | E21: 23378 | F21: 2.06 | G21: 3568 | H21: 6.17 | I21: 147 | J21: 14.95 | K21: 91 | L21: 143
A22: Istanbul at the Bosphorus | B22: 21 | C22: 1 | D22: 2022 | E22: 22612 | F22: 2.06 | G22: 2117 | H22: 6.17 | I22: 117 | J22: 14.95 | K22: 87 | L22: 140
A23: Istanbul at the Bosphorus | B23: 22 | C23: 1 | D23: 2022 | E23: 24827 | F23: 2.06 | G23: 1731 | H23: 6.17 | I23: 140 | J23: 14.95 | K23: 104 | L23: 170
A24: Istanbul at the Bosphorus | B24: 23 | C24: 1 | D24: 2022 | E24: ='Electricity '!I26+'Electricity '!O26 -> 22132.44 | F24: 2.06 | G24: ='Gas Water'!M27 -> 4282 | H24: 6.17 | I24: ='Gas Water'!L27 -> 140 | J24: 14.95 | K24: 82 | L24: 118
A25: Istanbul at the Bosphorus | B25: 24 | C25: 1 | D25: 2022 | E25: ='Electricity '!I27+'Electricity '!O27 -> 21047.76 | F25: 2.06 | G25: ='Gas Water'!M28 -> 4328 | H25: 6.17 | I25: ='Gas Water'!L28 -> 110 | J25: 14.95 | K25: 94 | L25: 145
A26: Istanbul at the Bosphorus | B26: 25 | C26: 1 | D26: 2022 | E26: ='Electricity '!I28+'Electricity '!O28 -> 21457.62 | F26: 2.06 | G26: ='Gas Water'!M29 -> 4490 | H26: 6.17 | I26: ='Gas Water'!L29 -> 114 | J26: 14.95 | K26: 70 | L26: 104
A27: Istanbul at the Bosphorus | B27: 26 | C27: 1 | D27: 2022 | E27: ='Electricity '!I29+'Electricity '!O29 -> 22095.18 | F27: 2.06 | G27: ='Gas Water'!M30 -> 4233 | H27: 6.17 | I27: ='Gas Water'!L30 -> 140 | J27: 14.95 | K27: 67 | L27: 101
A28: Istanbul at the Bosphorus | B28: 27 | C28: 1 | D28: 2022 | E28: ='Electricity '!I30+'Electricity '!O30 -> 21913.02 | F28: 2.06 | G28: ='Gas Water'!M31 -> 3868 | H28: 6.17 | I28: ='Gas Water'!L31 -> 127 | J28: 14.95 | K28: 128 | L28: 145
A29: Istanbul at the Bosphorus | B29: 28 | C29: 1 | D29: 2022 | E29: ='Electricity '!I31+'Electricity '!O31 -> 21921.3 | F29: 2.06 | G29: ='Gas Water'!M32 -> 3653 | H29: 6.17 | I29: ='Gas Water'!L32 -> 173 | J29: 14.95 | K29: 88 | L29: 118
A30: Istanbul at the Bosphorus | B30: 29 | C30: 1 | D30: 2022 | E30: ='Electricity '!I32+'Electricity '!O32 -> 20521.98 | F30: 2.06 | G30: ='Gas Water'!M33 -> 3567 | H30: 6.17 | I30: ='Gas Water'!L33 -> 126 | J30: 14.95 | K30: 107 | L30: 111
A31: Istanbul at the Bosphorus | B31: 30 | C31: 1 | D31: 2022 | E31: ='Electricity '!I33+'Electricity '!O33 -> 22351.86 | F31: 2.06 | G31: ='Gas Water'!M34 -> 3523 | H31: 6.17 | I31: ='Gas Water'!L34 -> 127 | J31: 14.95 | K31: 110 | L31: 125
A32: Istanbul at the Bosphorus | B32: 31 | C32: 1 | D32: 2022 | E32: ='Electricity '!I34+'Electricity '!O34 -> 22070.34 | F32: 2.06 | G32: ='Gas Water'!M35 -> 3359 | H32: 6.17 | I32: ='Gas Water'!L35 -> 124 | J32: 14.95 | K32: 83 | L32: 105
A33: Istanbul at the Bosphorus | B33: 1 | C33: 2 | D33: 2022 | E33: ='Electricity '!I35+'Electricity '!O35 -> 22620.96 | F33: 1.7 | G33: ='Gas Water'!M36 -> 3285 | H33: 8.2 | I33: ='Gas Water'!L36 -> 148 | J33: 14.95 | K33: 60 | L33: 83
A34: Istanbul at the Bosphorus | B34: 2 | C34: 2 | D34: 2022 | E34: ='Electricity '!I36+'Electricity '!O36 -> 24016.14 | F34: 1.7 | G34: ='Gas Water'!M37 -> 3411 | H34: 8.2 | I34: ='Gas Water'!L37 -> 109 | J34: 14.95 | K34: 69 | L34: 93
A35: Istanbul at the Bosphorus | B35: 3 | C35: 2 | D35: 2022 | E35: ='Electricity '!I37+'Electricity '!O37 -> 22542.3 | F35: 1.7 | G35: ='Gas Water'!M38 -> 3911 | H35: 8.2 | I35: ='Gas Water'!L38 -> 151 | J35: 14.95 | K35: 71 | L35: 96
... A175: Istanbul at the Bosphorus | B175: 23 | C175: 6 | D175: 2022 | E175: ='Electricity '!I177+'Electricity '!O177 -> 34991.28 | F175: 2.7 | G175: ='Gas Water'!M178 -> 1890 | H175: 13.68 | I175: ='Gas Water'!L178 -> 324 | J175: 22.4 | K175: 144 | L175: 286
A176: Istanbul at the Bosphorus | B176: 24 | C176: 6 | D176: 2022 | E176: 31480 | F176: 2.7 | G176: ='Gas Water'!M179 -> 1760 | H176: 13.68 | I176: ='Gas Water'!L179 -> 286 | J176: 22.4 | K176: 154 | L176: 290
A177: Istanbul at the Bosphorus | B177: 25 | C177: 6 | D177: 2022 | E177: 33020 | F177: 2.7 | G177: ='Gas Water'!M180 -> 1951 | H177: 13.68 | I177: ='Gas Water'!L180 -> 281 | J177: 22.4 | K177: 142 | L177: 255
A178: Istanbul at the Bosphorus | B178: 26 | C178: 6 | D178: 2022 | E178: 30329 | F178: 2.7 | G178: ='Gas Water'!M181 -> 1802 | H178: 13.68 | I178: ='Gas Water'!L181 -> 311 | J178: 22.4 | K178: 133 | L178: 242
A179: Istanbul at the Bosphorus | B179: 27 | C179: 6 | D179: 2022 | E179: 33910 | F179: 2.7 | G179: ='Gas Water'!M182 -> 1826 | H179: 13.68 | I179: ='Gas Water'!L182 -> 324 | J179: 22.4 | K179: 141 | L179: 271
...

Sheet Electricity 
A1: Date | B1: TR1 (bilgisayarda) | C1: TR2 (bilgisayardan) | D1: Meter Reading(Active)KWh | E1: Reactive Reading KWh | F1: Capacitive Reading KWh | G1: Şebekeye | H1: Meter Multipier | I1: Şebekeden (kWh) | J1: Endüktif (kVAr) | K1: Reaktif Endüktif Oranı | L1: Kapasitif (kVAr) | M1: Reaktif Kapasitif Oranı | N1: Kojen Değeri | O1: Kojen (kWh)
A2: 43465 | D2: 4926.457 | E2: 220.02 | F2: 169.75 | N2: 66068309
A3: 44561 | D3: 0.142 | E3: 1877.924 | F3: 61.573 | H3: 4140 | I3: 24293 | J3: 260.82 | K3: =IF(J3="","",+(J3/I3)) -> 0.010736426 | L3: 260.82 | M3: =IF(L3="","",(L3/I3)) -> 0.010736426 | N3: 66068309 | O3: 0 | P3: =IF(N3="",0,1) -> 1 | Q3: =IF(N3="",1,0) -> 0
A4: 44562 | D4: 0.142 | E4: 1883.77 | F4: 61.636 | G4: 183.709 | H4: 4140 | I4: =IF(D4="","",+(E4-E3)*4140) -> 24202.44 | J4: =IF(E4="","",+(F4-F3)*4140) -> 260.82 | K4: =IF(J4="","",+(J4/I4)) -> 0.010776599 | L4: =IF(F4="","",+(F4-F3)*4140) -> 260.82 | M4: =IF(L4="","",(L4/I4)) -> 0.010776599 | N4: 66068309 | O4: 0 | P4: =IF(N4="",0,1) -> 1 | Q4: =IF(N4="",1,0) -> 0
A5: 44563 | D5: 0.142 | E5: 1889.625 | F5: 61.733 | G5: 183.741 | H5: 4140 | I5: =IF(D5="","",+(E5-E4)*4140) -> 24239.7 | J5: =IF(E5="","",+(F5-F4)*4140) -> 401.58 | K5: =IF(J5="","",+(J5/I5)) -> 0.016567037 | L5: =IF(F5="","",+(F5-F4)*4140) -> 401.58 | M5: =IF(L5="","",(L5/I5)) -> 0.016567037 | N5: 66068309 | O5: 0 | P5: =IF(N5="",0,1) -> 1 | Q5: =IF(N5="",1,0) -> 0
A6: 44564 | D6: 0.142 | E6: 1894.934 | F6: 61.826 | G6: 183.781 | H6: 4140 | I6: =IF(D6="","",+(E6-E5)*4140) -> 21979.26 | J6: =IF(E6="","",+(F6-F5)*4140) -> 385.02 | K6: =IF(J6="","",+(J6/I6)) -> 0.017517423 | L6: =IF(F6="","",+(F6-F5)*4140) -> 385.02 | M6: =IF(L6="","",(L6/I6)) -> 0.017517423 | N6: 66068309 | O6: 0 | P6: =IF(N6="",0,1) -> 1 | Q6: =IF(N6="",1,0) -> 0
A7: 44565 | D7: 0.142 | E7: 1900.111 | F7: 61.918 | G7: 183.809 | H7: 4140 | I7: =IF(D7="","",+(E7-E6)*4140) -> 21432.78 | J7: =IF(E7="","",+(F7-F6)*4140) -> 380.88 | K7: =IF(J7="","",+(J7/I7)) -> 0.01777091 | L7: =IF(F7="","",+(F7-F6)*4140) -> 380.88 | M7: =IF(L7="","",(L7/I7)) -> 0.01777091 | N7: 66068309 | O7: 0 | P7: =IF(N7="",0,1) -> 1 | Q7: =IF(N7="",1,0) -> 0
A8: 44566 | D8: 0.142 | E8: 1905.603 | F8: 61.968 | G8: 183.832 | H8: 4140 | I8: =IF(D8="","",+(E8-E7)*4140) -> 22736.88 | J8: =IF(E8="","",+(F8-F7)*4140) -> 207 | K8: =IF(J8="","",+(J8/I8)) -> 0.0091041515 | L8: =IF(F8="","",+(F8-F7)*4140) -> 207 | M8: =IF(L8="","",(L8/I8)) -> 0.0091041515 | N8: 66068309 | O8: 0 | R8: =IF(N8="",0,1) -> 1 | S8: =IF(N8="",1,0) -> 0
A9: 44567 | D9: 0.142 | E9: 1911.193 | F9: 62.044 | G9: 183.872 | H9: 4140 | I9: =IF(D9="","",+(E9-E8)*4140) -> 23142.6 | J9: =IF(E9="","",+(F9-F8)*4140) -> 314.64 | K9: =IF(J9="","",+(J9/I9)) -> 0.013595707 | L9: =IF(F9="","",+(F9-F8)*4140) -> 314.64 | M9: =IF(L9="","",(L9/I9)) -> 0.013595707 | N9: 66068309 | O9: 0 | R9: =IF(N9="",0,1) -> 1 | S9: =IF(N9="",1,0) -> 0
A10: 44568 | D10: 0.142 | E10: 1916.916 | F10: 62.166 | G10: 183.909 | H10: 4140 | I10: =IF(D10="","",+(E10-E9)*4140) -> 23693.22 | J10: =IF(E10="","",+(F10-F9)*4140) -> 505.08 | K10: =IF(J10="","",+(J10/I10)) -> 0.021317491 | L10: =IF(F10="","",+(F10-F9)*4140) -> 505.08 | M10: =IF(L10="","",(L10/I10)) -> 0.021317491 | N10: 66068309 | O10: 0 | R10: =IF(N10="",0,1) -> 1 | S10: =IF(N10="",1,0) -> 0
A11: 44569 | D11: 0.142 | E11: 1922.64 | F11: 62.226 | G11: 183.944 | H11: 4140 | I11: =IF(D11="","",+(E11-E10)*4140) -> 23697.36 | J11: =IF(E11="","",+(F11-F10)*4140) -> 248.4 | K11: =IF(J11="","",+(J11/I11)) -> 0.01048218 | L11: =IF(F11="","",+(F11-F10)*4140) -> 248.4 | M11: =IF(L11="","",(L11/I11)) -> 0.01048218 | N11: 66068309 | O11: 0 | R11: =IF(N11="",0,1) -> 1 | S11: =IF(N11="",1,0) -> 0
A12: 44570 | D12: 0.142 | E12: 1928.38 | F12: 62.285 | G12: 183.986 | H12: 4140 | I12: =IF(D12="","",+(E12-E11)*4140) -> 23763.6 | J12: =IF(E12="","",+(F12-F11)*4140) -> 244.26 | K12: =IF(J12="","",+(J12/I12)) -> 0.010278746 | L12: =IF(F12="","",+(F12-F11)*4140) -> 244.26 | M12: =IF(L12="","",(L12/I12)) -> 0.010278746 | N12: 66068309 | O12: 0 | R12: =IF(N12="",0,1) -> 1 | S12: =IF(N12="",1,0) -> 0
A13: 44571 | D13: 0.142 | E13: 1934.18 | F13: 62.383 | G13: 184.028 | H13: 4140 | I13: =IF(D13="","",+(E13-E12)*4140) -> 24012 | J13: =IF(E13="","",+(F13-F12)*4140) -> 405.72 | K13: =IF(J13="","",+(J13/I13)) -> 0.016896552 | L13: =IF(F13="","",+(F13-F12)*4140) -> 405.72 | M13: =IF(L13="","",(L13/I13)) -> 0.016896552 | N13: 66068309 | O13: 0 | R13: =IF(N13="",0,1) -> 1 | S13: =IF(N13="",1,0) -> 0
A14: 44572 | D14: 0.142 | E14: 1939.993 | F14: 62.448 | G14: 184.073 | H14: 4140 | I14: =IF(D14="","",+(E14-E13)*4140) -> 24065.82 | J14: =IF(E14="","",+(F14-F13)*4140) -> 269.1 | K14: =IF(J14="","",+(J14/I14)) -> 0.011181834 | L14: =IF(F14="","",+(F14-F13)*4140) -> 269.1 | M14: =IF(L14="","",(L14/I14)) -> 0.011181834 | N14: 66068309 | O14: 0 | R14: =IF(N14="",0,1) -> 1 | S14: =IF(N14="",1,0) -> 0
A15: 44573 | D15: 0.142 | E15: 1945.788 | F15: 62.552 | G15: 184.107 | H15: 4140 | I15: =IF(D15="","",+(E15-E14)*4140) -> 23991.3 | J15: =IF(E15="","",+(F15-F14)*4140) -> 430.56 | K15: =IF(J15="","",+(J15/I15)) -> 0.017946506 | L15: =IF(F15="","",+(F15-F14)*4140) -> 430.56 | M15: =IF(L15="","",(L15/I15)) -> 0.017946506 | N15: 66068309 | O15: 0 | R15: =IF(N15="",0,1) -> 1 | S15: =IF(N15="",1,0) -> 0
A16: 44574 | D16: 0.142 | E16: 1951.387 | F16: 62.622 | G16: 184.131 | H16: 4140 | I16: =IF(D16="","",+(E16-E15)*4140) -> 23179.86 | J16: =IF(E16="","",+(F16-F15)*4140) -> 289.8 | K16: =IF(J16="","",+(J16/I16)) -> 0.012502233 | L16: =IF(F16="","",+(F16-F15)*4140) -> 289.8 | M16: =IF(L16="","",(L16/I16)) -> 0.012502233 | N16: 66068309 | O16: 0 | R16: =IF(N16="",0,1) -> 1 | S16: =IF(N16="",1,0) -> 0
A17: 44575 | D17: 0.142 | E17: 1957.057 | F17: 62.703 | G17: 184.166 | H17: 4140 | I17: =IF(D17="","",+(E17-E16)*4140) -> 23473.8 | J17: =IF(E17="","",+(F17-F16)*4140) -> 335.34 | K17: =IF(J17="","",+(J17/I17)) -> 0.014285714 | L17: =IF(F17="","",+(F17-F16)*4140) -> 335.34 | M17: =IF(L17="","",(L17/I17)) -> 0.014285714 | N17: 66068309 | O17: 0 | R17: =IF(N17="",0,1) -> 1 | S17: =IF(N17="",1,0) -> 0
A18: 44576 | D18: 0.142 | E18: 1962.748 | F18: 62.829 | G18: 184.206 | H18: 4140 | I18: =IF(D18="","",+(E18-E17)*4140) -> 23560.74 | J18: =IF(E18="","",+(F18-F17)*4140) -> 521.64 | K18: =IF(J18="","",+(J18/I18)) -> 0.022140221 | L18: =IF(F18="","",+(F18-F17)*4140) -> 521.64 | M18: =IF(L18="","",(L18/I18)) -> 0.022140221 | N18: 66068309 | O18: 0 | R18: =IF(N18="",0,1) -> 1 | S18: =IF(N18="",1,0) -> 0
A19: 44577 | D19: 0.142 | E19: 1968.395 | F19: 62.919 | G19: 184.245 | H19: 4140 | I19: =IF(D19="","",+(E19-E18)*4140) -> 23378.58 | J19: =IF(E19="","",+(F19-F18)*4140) -> 372.6 | K19: =IF(J19="","",+(J19/I19)) -> 0.015937666 | L19: =IF(F19="","",+(F19-F18)*4140) -> 372.6 | M19: =IF(L19="","",(L19/I19)) -> 0.015937666 | N19: 66068309 | O19: 0 | R19: =IF(N19="",0,1) -> 1 | S19: =IF(N19="",1,0) -> 0
A20: 44578 | D20: 0.142 | E20: 1974.35 | F20: 63.036 | G20: 184.282 | H20: 4140 | I20: =IF(D20="","",+(E20-E19)*4140) -> 24653.7 | J20: =IF(E20="","",+(F20-F19)*4140) -> 484.38 | K20: =IF(J20="","",+(J20/I20)) -> 0.019647355 | L20: =IF(F20="","",+(F20-F19)*4140) -> 484.38 | M20: =IF(L20="","",(L20/I20)) -> 0.019647355 | N20: 66068309 | O20: 0 | R20: =IF(N20="",0,1) -> 1 | S20: =IF(N20="",1,0) -> 0
A21: 44579 | D21: 0.142 | E21: 1979.925 | F21: 63.126 | G21: 184.312 | H21: 4140 | I21: =IF(D21="","",+(E21-E20)*4140) -> 23080.5 | J21: =IF(E21="","",+(F21-F20)*4140) -> 372.6 | K21: =IF(J21="","",+(J21/I21)) -> 0.016143498 | L21: =IF(F21="","",+(F21-F20)*4140) -> 372.6 | M21: =IF(L21="","",(L21/I21)) -> 0.016143498 | N21: 66068309 | O21: 0 | P21: Ocak / Jan | R21: =IF(N21="",0,1) -> 1 | S21: =IF(N21="",1,0) -> 0
A22: 44580 | D22: 0.142 | E22: 1985.505 | F22: 63.203 | G22: 184.348 | H22: 4140 | I22: =IF(D22="","",+(E22-E21)*4140) -> 23101.2 | J22: =IF(E22="","",+(F22-F21)*4140) -> 318.78 | K22: =IF(J22="","",+(J22/I22)) -> 0.013799283 | L22: =IF(F22="","",+(F22-F21)*4140) -> 318.78 | M22: =IF(L22="","",(L22/I22)) -> 0.013799283 | N22: 66068309 | O22: 0 | R22: =IF(N22="",0,1) -> 1 | S22: =IF(N22="",1,0) -> 0
A23: 44581 | D23: 0.142 | E23: 1991.152 | F23: 63.287 | G23: 184.39 | H23: 4140 | I23: =IF(D23="","",+(E23-E22)*4140) -> 23378.58 | J23: =IF(E23="","",+(F23-F22)*4140) -> 347.76 | K23: =IF(J23="","",+(J23/I23)) -> 0.014875155 | L23: =IF(F23="","",+(F23-F22)*4140) -> 347.76 | M23: =IF(L23="","",(L23/I23)) -> 0.014875155 | N23: 66068309 | O23: 0 | P23: End. | Q23: Kap. | R23: =IF(N23="",0,1) -> 1 | S23: =IF(N23="",1,0) -> 0
A24: 44582 | D24: 0.142 | E24: 1996.614 | F24: 63.38 | G24: 184.438 | H24: 4140 | I24: =IF(D24="","",+(E24-E23)*4140) -> 22612.68 | J24: =IF(E24="","",+(F24-F23)*4140) -> 385.02 | K24: =IF(J24="","",+(J24/I24)) -> 0.01702673 | L24: =IF(F24="","",+(F24-F23)*4140) -> 385.02 | M24: =IF(L24="","",(L24/I24)) -> 0.01702673 | N24: 66068309 | O24: 0 | P24: =IF(J3="",0,+SUM(J3:J33)/SUM(I3:I33)) -> 0.01552924 | Q24: =IF(L3="",0,+SUM(L3:L33)/SUM(I3:I33)) -> 0.01552924 | R24: =IF(N24="",0,1) -> 1 | S24: =IF(N24="",1,0) -> 0
A25: 44583 | D25: 0.142 | E25: 2002.611 | F25: 63.488 | G25: 184.483 | H25: 4140 | I25: =IF(D25="","",+(E25-E24)*4140) -> 24827.58 | J25: =IF(E25="","",+(F25-F24)*4140) -> 447.12 | K25: =IF(J25="","",+(J25/I25)) -> 0.018009005 | L25: =IF(F25="","",+(F25-F24)*4140) -> 447.12 | M25: =IF(L25="","",(L25/I25)) -> 0.018009005 | N25: 66068309 | O25: 0 | P25: =IF(J3="",0,+(+(LOOKUP(9.99999999999999E+307,E3:E33)-E2))/(+(LOOKUP(9.99999999999999E+307,D3:D33)-D2))) -> -0.37035492 | Q25: =IF(L3="",0,+(+(LOOKUP(9.99999999999999E+307,F3:F33)-F2))/(+(LOOKUP(9.99999999999999E+307,D3:D33)-D2))) -> 0.021428187 | R25: =IF(N25="",0,1) -> 1 | S25: =IF(N25="",1,0) -> 0
A26: 44584 | D26: 0.142 | E26: 2007.957 | F26: 63.579 | G26: 184.538 | H26: 4140 | I26: =IF(D26="","",+(E26-E25)*4140) -> 22132.44 | J26: =IF(E26="","",+(F26-F25)*4140) -> 376.74 | K26: =IF(J26="","",+(J26/I26)) -> 0.017022073 | L26: =IF(F26="","",+(F26-F25)*4140) -> 376.74 | M26: =IF(L26="","",(L26/I26)) -> 0.017022073 | N26: 66068309 | O26: 0 | P26: Cat Aylık | Q26: Cat Günlük | R26: =IF(N26="",0,1) -> 1 | S26: =IF(N26="",1,0) -> 0
A27: 44585 | D27: 0.142 | E27: 2013.041 | F27: 63.663 | G27: 184.571 | H27: 4140 | I27: =IF(D27="","",+(E27-E26)*4140) -> 21047.76 | J27: =IF(E27="","",+(F27-F26)*4140) -> 347.76 | K27: =IF(J27="","",+(J27/I27)) -> 0.016522423 | L27: =IF(F27="","",+(F27-F26)*4140) -> 347.76 | M27: =IF(L27="","",(L27/I27)) -> 0.016522423 | N27: 66068309 | O27: 0 | P27: =IF(N2="",0,+(LOOKUP(9.99999999999999E+307,N2:N33)-N2)) -> 0 | Q27: =IF(P27="",0,+P27/SUM(R3:R33)) -> 0 | R27: =IF(N27="",0,1) -> 1 | S27: =IF(N27="",1,0) -> 0
A28: 44586 | D28: 0.142 | E28: 2018.224 | F28: 63.71 | G28: 184.61 | H28: 4140 | I28: =IF(D28="","",+(E28-E27)*4140) -> 21457.62 | J28: =IF(E28="","",+(F28-F27)*4140) -> 194.58 | K28: =IF(J28="","",+(J28/I28)) -> 0.0090681073 | L28: =IF(F28="","",+(F28-F27)*4140) -> 194.58 | M28: =IF(L28="","",(L28/I28)) -> 0.0090681073 | N28: 66068309 | O28: 0 | P28: Bedaş Aylık | Q28: Bedaş Günlük | R28: =IF(N28="",0,1) -> 1 | S28: =IF(N28="",1,0) -> 0
A29: 44587 | D29: 0.142 | E29: 2023.561 | F29: 63.9 | G29: 184.662 | H29: 4140 | I29: =IF(D29="","",+(E29-E28)*4140) -> 22095.18 | J29: =IF(E29="","",+(F29-F28)*4140) -> 786.6 | K29: =IF(J29="","",+(J29/I29)) -> 0.035600525 | L29: =IF(F29="","",+(F29-F28)*4140) -> 786.6 | M29: =IF(L29="","",(L29/I29)) -> 0.035600525 | N29: 66068309 | O29: 0 | P29: =IF(D3="",0,+(LOOKUP(9.99999999999999E+307,D2:D33)-D2))*4140 -> -20394944 | Q29: =IF(P29="",0,+P29/SUM(R3:R33)) -> -784420.93 | R29: =IF(N29="",0,1) -> 1 | S29: =IF(N29="",1,0) -> 0
A30: 44588 | D30: 0.142 | E30: 2028.854 | F30: 63.908 | G30: 184.722 | H30: 4140 | I30: =IF(D30="","",+(E30-E29)*4140) -> 21913.02 | J30: =IF(E30="","",+(F30-F29)*4140) -> 33.12 | K30: =IF(J30="","",+(J30/I30)) -> 0.0015114302 | L30: =IF(F30="","",+(F30-F29)*4140) -> 33.12 | M30: =IF(L30="","",(L30/I30)) -> 0.0015114302 | N30: 66068309 | O30: 0 | P30: Tüketim TL | Q30: Cat Birim TL | R30: =IF(N30="",0,1) -> 1 | S30: =IF(N30="",1,0) -> 0
A31: 44589 | D31: 0.142 | E31: 2034.149 | F31: 63.984 | G31: 184.769 | H31: 4140 | I31: =IF(D31="","",+(E31-E30)*4140) -> 21921.3 | J31: =IF(E31="","",+(F31-F30)*4140) -> 314.64 | K31: =IF(J31="","",+(J31/I31)) -> 0.014353163 | L31: =IF(F31="","",+(F31-F30)*4140) -> 314.64 | M31: =IF(L31="","",(L31/I31)) -> 0.014353163 | N31: 66068309 | O31: 0 | P31: =P29*Q34 -> -11625118 | Q31: =IF(Q34="",0,(SUM('[1]Günlük Tüketim'!H4:H34)*1.62)/SUM(O3:O33)) -> #DIV/0! | R31: =IF(N31="",0,1) -> 1 | S31: =IF(N31="",1,0) -> 0
A32: 44590 | D32: 0.142 | E32: 2039.106 | F32: 64.063 | G32: 184.81 | H32: 4140 | I32: =IF(D32="","",+(E32-E31)*4140) -> 20521.98 | J32: =IF(E32="","",+(F32-F31)*4140) -> 327.06 | K32: =IF(J32="","",+(J32/I32)) -> 0.015937059 | L32: =IF(F32="","",+(F32-F31)*4140) -> 327.06 | M32: =IF(L32="","",(L32/I32)) -> 0.015937059 | N32: 66068309 | O32: 0 | P32: Top. Tüketim TL | Q32: Top. Bedaş kWh | R32: =IF(N32="",0,1) -> 1 | S32: =IF(N32="",1,0) -> 0
A33: 44591 | D33: 0.142 | E33: 2044.505 | F33: 64.188 | G33: 184.857 | H33: 4140 | I33: =IF(D33="","",+(E33-E32)*4140) -> 22351.86 | J33: =IF(E33="","",+(F33-F32)*4140) -> 517.5 | K33: =IF(J33="","",+(J33/I33)) -> 0.023152436 | L33: =IF(F33="","",+(F33-F32)*4140) -> 517.5 | M33: =IF(L33="","",(L33/I33)) -> 0.023152436 | N33: 66068309 | O33: 0 | P33: =(P31+Q29*SUM(S3:S33)*Q34) -> -11625118 | Q33: =Q29*31 -> -24317049 | R33: =IF(N33="",0,1) -> 1 | S33: =IF(N33="",1,0) -> 0
A34: 44592 | D34: 0.142 | E34: 2049.836 | F34: 64.309 | G34: 184.89 | H34: 4140 | I34: =IF(D34="","",+(E34-E33)*4140) -> 22070.34 | J34: =IF(E34="","",+(F34-F33)*4140) -> 500.94 | K34: =IF(J34="","",+(J34/I34)) -> 0.02269743 | L34: =IF(F34="","",+(F34-F33)*4140) -> 500.94 | M34: =IF(L34="","",(L34/I34)) -> 0.02269743 | N34: 66068309 | O34: 0 | P34: Bedaş Birim | Q34: 0.57 | R34: =IF(N34="",0,1) -> 1 | S34: =IF(N34="",1,0) -> 0
A35: 44593 | D35: 0.142 | E35: 2055.3 | F35: 64.446 | G35: 184.919 | H35: 4140 | I35: =IF(D35="","",+(E35-E34)*4140) -> 22620.96 | J35: =IF(E35="","",+(F35-F34)*4140) -> 567.18 | K35: =IF(J35="","",+(J35/I35)) -> 0.025073206 | L35: =IF(F35="","",+(F35-F34)*4140) -> 567.18 | M35: =IF(L35="","",(L35/I35)) -> 0.025073206 | N35: 66068309 | O35: 0 | R35: =IF(N35="",0,1) -> 1 | S35: =IF(N35="",1,0) -> 0
A36: 44594 | D36: 0.142 | E36: 2061.101 | F36: 64.557 | G36: 184.967 | H36: 4140 | I36: =IF(D36="","",+(E36-E35)*4140) -> 24016.14 | J36: =IF(E36="","",+(F36-F35)*4140) -> 459.54 | K36: =IF(J36="","",+(J36/I36)) -> 0.019134632 | L36: =IF(F36="","",+(F36-F35)*4140) -> 459.54 | M36: =IF(L36="","",(L36/I36)) -> 0.019134632 | N36: 66068309 | O36: 0 | R36: =IF(N36="",0,1) -> 1 | S36: =IF(N36="",1,0) -> 0
A37: 44595 | D37: 0.142 | E37: 2066.546 | F37: 64.7 | G37: 185.077 | H37: 4140 | I37: =IF(D37="","",+(E37-E36)*4140) -> 22542.3 | J37: =IF(E37="","",+(F37-F36)*4140) -> 592.02 | K37: =IF(J37="","",+(J37/I37)) -> 0.026262626 | L37: =IF(F37="","",+(F37-F36)*4140) -> 592.02 | M37: =IF(L37="","",(L37/I37)) -> 0.026262626 | N37: 66068309 | O37: 0 | R37: =IF(N37="",0,1) -> 1 | S37: =IF(N37="",1,0) -> 0
A38: 44596 | D38: 0.142 | E38: 2071.964 | F38: 64.815 | G38: 185.119 | H38: 4140 | I38: =IF(D38="","",+(E38-E37)*4140) -> 22430.52 | J38: =IF(E38="","",+(F38-F37)*4140) -> 476.1 | K38: =IF(J38="","",+(J38/I38)) -> 0.021225544 | L38: =IF(F38="","",+(F38-F37)*4140) -> 476.1 | M38: =IF(L38="","",(L38/I38)) -> 0.021225544 | N38: 66068309 | O38: 0 | R38: =IF(N38="",0,1) -> 1 | S38: =IF(N38="",1,0) -> 0
A39: 44597 | D39: 0.142 | E39: 2077.457 | F39: 64.947 | G39: 185.148 | H39: 4140 | I39: =IF(D39="","",+(E39-E38)*4140) -> 22741.02 | J39: =IF(E39="","",+(F39-F38)*4140) -> 546.48 | K39: =IF(J39="","",+(J39/I39)) -> 0.024030584 | L39: =IF(F39="","",+(F39-F38)*4140) -> 546.48 | M39: =IF(L39="","",(L39/I39)) -> 0.024030584 | N39: 66068309 | O39: 0 | R39: =IF(N39="",0,1) -> 1 | S39: =IF(N39="",1,0) -> 0
A40: 44598 | D40: 0.142 | E40: 2082.827 | F40: 65.059 | G40: 185.192 | H40: 4140 | I40: =IF(D40="","",+(E40-E39)*4140) -> 22231.8 | J40: =IF(E40="","",+(F40-F39)*4140) -> 463.68 | K40: =IF(J40="","",+(J40/I40)) -> 0.020856611 | L40: =IF(F40="","",+(F40-F39)*4140) -> 463.68 | M40: =IF(L40="","",(L40/I40)) -> 0.020856611 | N40: 66068309 | O40: 0 | R40: =IF(N40="",0,1) -> 1 | S40: =IF(N40="",1,0) -> 0
...

Sheet Gas Water
B2: Date | C2: CHP Reading m3 | D2: Boiler Reading m3 | E2: Kitchen Reading m3 | F2: Laundry Reading m3 | G2: Water Supplier Credit m3 | H2: CHP Diffenece m3 | I2: Boiler Difference m3 | J2: Kitchen Difference m3 | K2: Laundry Difference m3 | L2: Water Difference m3 | M2: Total Gas Consumption m3
B3: 43830 | C3: 16228333 | D3: 3990997 | E3: 223696 | F3: 521490 | G3: 5647
B4: 44561 | C4: 16228335 | D4: 5099652 | E4: 243800 | F4: 638972 | G4: 293998 | H4: 0 | I4: 2760 | J4: 190 | K4: 222 | L4: 196 | M4: =IF(H4="","",+(H4+I4+J4+K4)) -> 3172 | O4: =IF(L4="",1,0) -> 0
B5: 44197 | C5: 16228335 | D5: 5101985 | E5: 244004 | F5: 639192 | G5: 294182 | H5: =IF(C5="","",+(C5-C4)) -> 0 | I5: =IF(D5="","",+(D5-D4)) -> 2333 | J5: =IF(E5="","",+(E5-E4)) -> 204 | K5: =IF(F5="","",+(F5-F4)) -> 220 | L5: =IF(G5="","",+(G5-G4)) -> 184 | M5: =IF(H5="","",+(H5+I5+J5+K5)) -> 2757 | Q5: =IF(L5="",1,0) -> 0
B6: 44198 | C6: 16228335 | D6: 5104352 | E6: 244192 | F6: 639424 | G6: 294384 | H6: =IF(C6="","",+(C6-C5)) -> 0 | I6: =IF(D6="","",+(D6-D5)) -> 2367 | J6: =IF(E6="","",+(E6-E5)) -> 188 | K6: =IF(F6="","",+(F6-F5)) -> 232 | L6: =IF(G6="","",+(G6-G5)) -> 202 | M6: =IF(H6="","",+(H6+I6+J6+K6)) -> 2787 | Q6: =IF(L6="",1,0) -> 0
B7: 44199 | C7: 16228335 | D7: 5106445 | E7: 244348 | F7: 639645 | G7: 294605 | H7: =IF(C7="","",+(C7-C6)) -> 0 | I7: =IF(D7="","",+(D7-D6)) -> 2093 | J7: =IF(E7="","",+(E7-E6)) -> 156 | K7: =IF(F7="","",+(F7-F6)) -> 221 | L7: =IF(G7="","",+(G7-G6)) -> 221 | M7: =IF(H7="","",+(H7+I7+J7+K7)) -> 2470 | Q7: =IF(L7="",1,0) -> 0
B8: 44200 | C8: 16228335 | D8: 5108382 | E8: 244496 | F8: 639843 | G8: 294811 | H8: =IF(C8="","",+(C8-C7)) -> 0 | I8: =IF(D8="","",+(D8-D7)) -> 1937 | J8: =IF(E8="","",+(E8-E7)) -> 148 | K8: =IF(F8="","",+(F8-F7)) -> 198 | L8: =IF(G8="","",+(G8-G7)) -> 206 | M8: =IF(H8="","",+(H8+I8+J8+K8)) -> 2283 | Q8: =IF(L8="",1,0) -> 0
B9: 44201 | C9: 16228335 | D9: 5110087 | E9: 244679 | F9: 640032 | G9: 294994 | H9: =IF(C9="","",+(C9-C8)) -> 0 | I9: =IF(D9="","",+(D9-D8)) -> 1705 | J9: =IF(E9="","",+(E9-E8)) -> 183 | K9: =IF(F9="","",+(F9-F8)) -> 189 | L9: =IF(G9="","",+(G9-G8)) -> 183 | M9: =IF(H9="","",+(H9+I9+J9+K9)) -> 2077 | Q9: =IF(L9="",1,0) -> 0
B10: 44202 | C10: 16228335 | D10: 5111788 | E10: 244873 | F10: 640235 | G10: 295168 | H10: =IF(C10="","",+(C10-C9)) -> 0 | I10: =IF(D10="","",+(D10-D9)) -> 1701 | J10: =IF(E10="","",+(E10-E9)) -> 194 | K10: =IF(F10="","",+(F10-F9)) -> 203 | L10: =IF(G10="","",+(G10-G9)) -> 174 | M10: =IF(H10="","",+(H10+I10+J10+K10)) -> 2098 | Q10: =IF(L10="",1,0) -> 0
B11: 44203 | C11: 16228335 | D11: 5114024 | E11: 245070 | F11: 640436 | G11: 295347 | H11: =IF(C11="","",+(C11-C10)) -> 0 | I11: =IF(D11="","",+(D11-D10)) -> 2236 | J11: =IF(E11="","",+(E11-E10)) -> 197 | K11: =IF(F11="","",+(F11-F10)) -> 201 | L11: =IF(G11="","",+(G11-G10)) -> 179 | M11: =IF(H11="","",+(H11+I11+J11+K11)) -> 2634 | Q11: =IF(L11="",1,0) -> 0
B12: 44204 | C12: 16228335 | D12: 5116326 | E12: 245248 | F12: 640667 | G12: 295537 | H12: =IF(C12="","",+(C12-C11)) -> 0 | I12: =IF(D12="","",+(D12-D11)) -> 2302 | J12: =IF(E12="","",+(E12-E11)) -> 178 | K12: =IF(F12="","",+(F12-F11)) -> 231 | L12: =IF(G12="","",+(G12-G11)) -> 190 | M12: =IF(H12="","",+(H12+I12+J12+K12)) -> 2711 | Q12: =IF(L12="",1,0) -> 0
B13: 44205 | C13: 16228335 | D13: 5118633 | E13: 245416 | F13: 640864 | G13: 295760 | H13: =IF(C13="","",+(C13-C12)) -> 0 | I13: =IF(D13="","",+(D13-D12)) -> 2307 | J13: =IF(E13="","",+(E13-E12)) -> 168 | K13: =IF(F13="","",+(F13-F12)) -> 197 | L13: =IF(G13="","",+(G13-G12)) -> 223 | M13: =IF(H13="","",+(H13+I13+J13+K13)) -> 2672 | Q13: =IF(L13="",1,0) -> 0
B14: 44206 | C14: 16228335 | D14: 5120934 | E14: 245586 | F14: 641063 | G14: 295942 | H14: =IF(C14="","",+(C14-C13)) -> 0 | I14: =IF(D14="","",+(D14-D13)) -> 2301 | J14: =IF(E14="","",+(E14-E13)) -> 170 | K14: =IF(F14="","",+(F14-F13)) -> 199 | L14: =IF(G14="","",+(G14-G13)) -> 182 | M14: =IF(H14="","",+(H14+I14+J14+K14)) -> 2670 | Q14: =IF(L14="",1,0) -> 0
B15: 44207 | C15: 16228335 | D15: 5123728 | E15: 245785 | F15: 641234 | G15: 296090 | H15: =IF(C15="","",+(C15-C14)) -> 0 | I15: =IF(D15="","",+(D15-D14)) -> 2794 | J15: =IF(E15="","",+(E15-E14)) -> 199 | K15: =IF(F15="","",+(F15-F14)) -> 171 | L15: =IF(G15="","",+(G15-G14)) -> 148 | M15: =IF(H15="","",+(H15+I15+J15+K15)) -> 3164 | Q15: =IF(L15="",1,0) -> 0
B16: 44208 | C16: 16228335 | D16: 5127388 | E16: 245930 | F16: 641420 | G16: 296265 | H16: =IF(C16="","",+(C16-C15)) -> 0 | I16: =IF(D16="","",+(D16-D15)) -> 3660 | J16: =IF(E16="","",+(E16-E15)) -> 145 | K16: =IF(F16="","",+(F16-F15)) -> 186 | L16: =IF(G16="","",+(G16-G15)) -> 175 | M16: =IF(H16="","",+(H16+I16+J16+K16)) -> 3991 | Q16: =IF(L16="",1,0) -> 0
... B24: 44216 | C24: 16228335 | D24: 5155253 | E24: 247040 | F24: 642655 | G24: 297395 | H24: =IF(C24="","",+(C24-C23)) -> 0 | I24: =IF(D24="","",+(D24-D23)) -> 3273 | J24: =IF(E24="","",+(E24-E23)) -> 154 | K24: =IF(F24="","",+(F24-F23)) -> 141 | L24: =IF(G24="","",+(G24-G23)) -> 147 | M24: =IF(H24="","",+(H24+I24+J24+K24)) -> 3568 | Q24: =IF(L24="",1,0) -> 0
B25: 44217 | C25: 16228335 | D25: 5157034 | E25: 247218 | F25: 642813 | G25: 297512 | H25: =IF(C25="","",+(C25-C24)) -> 0 | I25: =IF(D25="","",+(D25-D24)) -> 1781 | J25: =IF(E25="","",+(E25-E24)) -> 178 | K25: =IF(F25="","",+(F25-F24)) -> 158 | L25: =IF(G25="","",+(G25-G24)) -> 117 | M25: =IF(H25="","",+(H25+I25+J25+K25)) -> 2117 | N25: Total Water m3 | O25: Total Gas m3 | Q25: =IF(L25="",1,0) -> 0
B26: 44218 | C26: 16228335 | D26: 5158429 | E26: 247407 | F26: 642960 | G26: 297652 | H26: =IF(C26="","",+(C26-C25)) -> 0 | I26: =IF(D26="","",+(D26-D25)) -> 1395 | J26: =IF(E26="","",+(E26-E25)) -> 189 | K26: =IF(F26="","",+(F26-F25)) -> 147 | L26: =IF(G26="","",+(G26-G25)) -> 140 | M26: =IF(H26="","",+(H26+I26+J26+K26)) -> 1731 | Q26: =IF(L26="",1,0) -> 0
B27: 44219 | C27: 16228335 | D27: 5162376 | E27: 247548 | F27: 643154 | G27: 297792 | H27: =IF(C27="","",+(C27-C26)) -> 0 | I27: =IF(D27="","",+(D27-D26)) -> 3947 | J27: =IF(E27="","",+(E27-E26)) -> 141 | K27: =IF(F27="","",+(F27-F26)) -> 194 | L27: =IF(G27="","",+(G27-G26)) -> 140 | M27: =IF(H27="","",+(H27+I27+J27+K27)) -> 4282 | Q27: =IF(L27="",1,0) -> 0
B28: 44220 | C28: 16228335 | D28: 5166409 | E28: 247685 | F28: 643312 | G28: 297902 | H28: =IF(C28="","",+(C28-C27)) -> 0 | I28: =IF(D28="","",+(D28-D27)) -> 4033 | J28: =IF(E28="","",+(E28-E27)) -> 137 | K28: =IF(F28="","",+(F28-F27)) -> 158 | L28: =IF(G28="","",+(G28-G27)) -> 110 | M28: =IF(H28="","",+(H28+I28+J28+K28)) -> 4328 | N28: =SUM(L4:L34) -> 4907 | O28: =SUM(M4:M34) -> 101488 | Q28: =IF(L28="",1,0) -> 0
B29: 44221 | C29: 16228335 | D29: 5170609 | E29: 247833 | F29: 643454 | G29: 298016 | H29: =IF(C29="","",+(C29-C28)) -> 0 | I29: =IF(D29="","",+(D29-D28)) -> 4200 | J29: =IF(E29="","",+(E29-E28)) -> 148 | K29: =IF(F29="","",+(F29-F28)) -> 142 | L29: =IF(G29="","",+(G29-G28)) -> 114 | M29: =IF(H29="","",+(H29+I29+J29+K29)) -> 4490 | N29: Daily Average Water Consumption | O29: Daily Average Gas Consumption | Q29: =IF(L29="",1,0) -> 0
B30: 44222 | C30: 16228335 | D30: 5174551 | E30: 247969 | F30: 643609 | G30: 298156 | H30: =IF(C30="","",+(C30-C29)) -> 0 | I30: =IF(D30="","",+(D30-D29)) -> 3942 | J30: =IF(E30="","",+(E30-E29)) -> 136 | K30: =IF(F30="","",+(F30-F29)) -> 155 | L30: =IF(G30="","",+(G30-G29)) -> 140 | M30: =IF(H30="","",+(H30+I30+J30+K30)) -> 4233 | Q30: =IF(L30="",1,0) -> 0
B31: 44223 | C31: 16228335 | D31: 5178140 | E31: 248102 | F31: 643755 | G31: 298283 | H31: =IF(C31="","",+(C31-C30)) -> 0 | I31: =IF(D31="","",+(D31-D30)) -> 3589 | J31: =IF(E31="","",+(E31-E30)) -> 133 | K31: =IF(F31="","",+(F31-F30)) -> 146 | L31: =IF(G31="","",+(G31-G30)) -> 127 | M31: =IF(H31="","",+(H31+I31+J31+K31)) -> 3868 | N31: =AVERAGE(L4:L34) -> 158.29032 | O31: =AVERAGE(M4:M34) -> 3273.8065 | Q31: =IF(L31="",1,0) -> 0
B32: 44224 | C32: 16228335 | D32: 5181505 | E32: 248257 | F32: 643888 | G32: 298456 | H32: =IF(C32="","",+(C32-C31)) -> 0 | I32: =IF(D32="","",+(D32-D31)) -> 3365 | J32: =IF(E32="","",+(E32-E31)) -> 155 | K32: =IF(F32="","",+(F32-F31)) -> 133 | L32: =IF(G32="","",+(G32-G31)) -> 173 | M32: =IF(H32="","",+(H32+I32+J32+K32)) -> 3653 | O32: =IF(L32="",1,0) -> 0
B33: 44225 | C33: 16228335 | D33: 5184790 | E33: 248400 | F33: 644027 | G33: 298582 | H33: =IF(C33="","",+(C33-C32)) -> 0 | I33: =IF(D33="","",+(D33-D32)) -> 3285 | J33: =IF(E33="","",+(E33-E32)) -> 143 | K33: =IF(F33="","",+(F33-F32)) -> 139 | L33: =IF(G33="","",+(G33-G32)) -> 126 | M33: =IF(H33="","",+(H33+I33+J33+K33)) -> 3567 | O33: =IF(L33="",1,0) -> 0
B34: 44226 | C34: 16228335 | D34: 5188004 | E34: 248559 | F34: 644177 | G34: 298709 | H34: =IF(C34="","",+(C34-C33)) -> 0 | I34: =IF(D34="","",+(D34-D33)) -> 3214 | J34: =IF(E34="","",+(E34-E33)) -> 159 | K34: =IF(F34="","",+(F34-F33)) -> 150 | L34: =IF(G34="","",+(G34-G33)) -> 127 | M34: =IF(H34="","",+(H34+I34+J34+K34)) -> 3523 | Q34: =IF(L34="",1,0) -> 0
B35: 44227 | C35: 16228335 | D35: 5191070 | E35: 248709 | F35: 644320 | G35: 298833 | H35: =IF(C35="","",+(C35-C34)) -> 0 | I35: =IF(D35="","",+(D35-D34)) -> 3066 | J35: =IF(E35="","",+(E35-E34)) -> 150 | K35: =IF(F35="","",+(F35-F34)) -> 143 | L35: =IF(G35="","",+(G35-G34)) -> 124 | M35: =IF(H35="","",+(H35+I35+J35+K35)) -> 3359
B36: 44228 | C36: 16228335 | D36: 5194059 | E36: 248868 | F36: 644457 | G36: 298981 | H36: =IF(C36="","",+(C36-C35)) -> 0 | I36: =IF(D36="","",+(D36-D35)) -> 2989 | J36: =IF(E36="","",+(E36-E35)) -> 159 | K36: =IF(F36="","",+(F36-F35)) -> 137 | L36: =IF(G36="","",+(G36-G35)) -> 148 | M36: =IF(H36="","",+(H36+I36+J36+K36)) -> 3285 | Q36: =IF(L36="",1,0) -> 0
B37: 44229 | C37: 16228335 | D37: 5197173 | E37: 249031 | F37: 644591 | G37: 299090 | H37: =IF(C37="","",+(C37-C36)) -> 0 | I37: =IF(D37="","",+(D37-D36)) -> 3114 | J37: =IF(E37="","",+(E37-E36)) -> 163 | K37: =IF(F37="","",+(F37-F36)) -> 134 | L37: =IF(G37="","",+(G37-G36)) -> 109 | M37: =IF(H37="","",+(H37+I37+J37+K37)) -> 3411 | Q37: =IF(L37="",1,0) -> 0
B38: 44230 | C38: 16228335 | D38: 5200795 | E38: 249172 | F38: 644739 | G38: 299241 | H38: =IF(C38="","",+(C38-C37)) -> 0 | I38: =IF(D38="","",+(D38-D37)) -> 3622 | J38: =IF(E38="","",+(E38-E37)) -> 141 | K38: =IF(F38="","",+(F38-F37)) -> 148 | L38: =IF(G38="","",+(G38-G37)) -> 151 | M38: =IF(H38="","",+(H38+I38+J38+K38)) -> 3911 | Q38: =IF(L38="",1,0) -> 0
B39: 44231 | C39: 16228335 | D39: 5204301 | E39: 249325 | F39: 644892 | G39: 299402 | H39: =IF(C39="","",+(C39-C38)) -> 0 | I39: =IF(D39="","",+(D39-D38)) -> 3506 | J39: =IF(E39="","",+(E39-E38)) -> 153 | K39: =IF(F39="","",+(F39-F38)) -> 153 | L39: =IF(G39="","",+(G39-G38)) -> 161 | M39: =IF(H39="","",+(H39+I39+J39+K39)) -> 3812 | Q39: =IF(L39="",1,0) -> 0
B40: 44232 | C40: 16228335 | D40: 5207432 | E40: 249489 | F40: 645038 | G40: 299550 | H40: =IF(C40="","",+(C40-C39)) -> 0 | I40: =IF(D40="","",+(D40-D39)) -> 3131 | J40: =IF(E40="","",+(E40-E39)) -> 164 | K40: =IF(F40="","",+(F40-F39)) -> 146 | L40: =IF(G40="","",+(G40-G39)) -> 148 | M40: =IF(H40="","",+(H40+I40+J40+K40)) -> 3441 | Q40: =IF(L40="",1,0) -> 0
B41: 44233 | C41: 16228335 | D41: 5210303 | E41: 249650 | F41: 645209 | G41: 299690 | H41: =IF(C41="","",+(C41-C40)) -> 0 | I41: =IF(D41="","",+(D41-D40)) -> 2871 | J41: =IF(E41="","",+(E41-E40)) -> 161 | K41: =IF(F41="","",+(F41-F40)) -> 171 | L41: =IF(G41="","",+(G41-G40)) -> 140 | M41: =IF(H41="","",+(H41+I41+J41+K41)) -> 3203 | Q41: =IF(L41="",1,0) -> 0
B42: 44234 | C42: 16228335 | D42: 5212954 | E42: 249794 | F42: 645375 | G42: 299818 | H42: =IF(C42="","",+(C42-C41)) -> 0 | I42: =IF(D42="","",+(D42-D41)) -> 2651 | J42: =IF(E42="","",+(E42-E41)) -> 144 | K42: =IF(F42="","",+(F42-F41)) -> 166 | L42: =IF(G42="","",+(G42-G41)) -> 128 | M42: =IF(H42="","",+(H42+I42+J42+K42)) -> 2961 | Q42: =IF(L42="",1,0) -> 0
B43: 44235 | C43: 16228335 | D43: 5216476 | E43: 249954 | F43: 645507 | G43: 299946 | H43: =IF(C43="","",+(C43-C42)) -> 0 | I43: =IF(D43="","",+(D43-D42)) -> 3522 | J43: =IF(E43="","",+(E43-E42)) -> 160 | K43: =IF(F43="","",+(F43-F42)) -> 132 | L43: =IF(G43="","",+(G43-G42)) -> 128 | M43: =IF(H43="","",+(H43+I43+J43+K43)) -> 3814 | Q43: =IF(L43="",1,0) -> 0
B44: 44236 | C44: 16228335 | D44: 5219875 | E44: 250132 | F44: 645675 | G44: 300111 | H44: =IF(C44="","",+(C44-C43)) -> 0 | I44: =IF(D44="","",+(D44-D43)) -> 3399 | J44: =IF(E44="","",+(E44-E43)) -> 178 | K44: =IF(F44="","",+(F44-F43)) -> 168 | L44: =IF(G44="","",+(G44-G43)) -> 165 | M44: =IF(H44="","",+(H44+I44+J44+K44)) -> 3745 | Q44: =IF(L44="",1,0) -> 0
B45: 44237 | C45: 16228335 | D45: 5223086 | E45: 250333 | F45: 645842 | G45: 300272 | H45: =IF(C45="","",+(C45-C44)) -> 0 | I45: =IF(D45="","",+(D45-D44)) -> 3211 | J45: =IF(E45="","",+(E45-E44)) -> 201 | K45: =IF(F45="","",+(F45-F44)) -> 167 | L45: =IF(G45="","",+(G45-G44)) -> 161 | M45: =IF(H45="","",+(H45+I45+J45+K45)) -> 3579 | Q45: =IF(L45="",1,0) -> 0
B46: 44238 | C46: 16228335 | D46: 5226127 | E46: 250532 | F46: 646045 | G46: 300486 | H46: =IF(C46="","",+(C46-C45)) -> 0 | I46: =IF(D46="","",+(D46-D45)) -> 3041 | J46: =IF(E46="","",+(E46-E45)) -> 199 | K46: =IF(F46="","",+(F46-F45)) -> 203 | L46: =IF(G46="","",+(G46-G45)) -> 214 | M46: =IF(H46="","",+(H46+I46+J46+K46)) -> 3443 | Q46: =IF(L46="",1,0) -> 0
B47: 44239 | C47: 16228335 | D47: 5229020 | E47: 250734 | F47: 646259 | G47: 300676 | H47: =IF(C47="","",+(C47-C46)) -> 0 | I47: =IF(D47="","",+(D47-D46)) -> 2893 | J47: =IF(E47="","",+(E47-E46)) -> 202 | K47: =IF(F47="","",+(F47-F46)) -> 214 | L47: =IF(G47="","",+(G47-G46)) -> 190 | M47: =IF(H47="","",+(H47+I47+J47+K47)) -> 3309 | Q47: =IF(L47="",1,0) -> 0
... B52: 44244 | C52: 16228335 | D52: 5244248 | E52: 251661 | F52: 647234 | G52: 301286 | H52: =IF(C52="","",+(C52-C51)) -> 0 | I52: =IF(D52="","",+(D52-D51)) -> 2586 | J52: =IF(E52="","",+(E52-E51)) -> 169 | K52: =IF(F52="","",+(F52-F51)) -> 168 | L52: =IF(G52="","",+(G52-G51)) -> 125 | M52: =IF(H52="","",+(H52+I52+J52+K52)) -> 2923 | Q52: =IF(L52="",1,0) -> 0
...
