Workbook

Sheet Report current month
A1: Electricity Reading | U1: Year: 2020
A2: Meter: | B2: Main CEB | F2: Laundry | G2: Vacoas | H2: Main CEB - Golf | L2: Lifting | M2: Plantroom DB | N2: MAIN CEB | V2: Laundry | X2: Vacoas | Z2: GOLF CLUB HOUSE (07500232) | AG2: WATER FRONT VILLAGE | AN2: Lifting Station 4 (DC-6331745) | AP2: Plant Room DB (DC-8971990)
A3: Date | B3: KVAH | C3: KWH | D3: KVA | E3: KVA Max | F3: KWH | G3: KWH | H3: KVAH | I3: KWH | J3: KVA | K3: KVA Max | L3: KWH | M3: KWH | N3: KVAH | O3: KVAH Cons | P3: KWH | Q3: KWH Cons | S3: KVA | T3: Max. KVA | U3: Power Factor | V3: KWH | W3: KWH Cons | X3: KWH | Y3: KWH Cons | Z3: KVAH | AA3: KVAH Cons | AB3: KWH | AC3: KWH Cons | AD3: KVA | AE3: Max. KVA | AF3: Power Factor | AG3: KVAH | AH3: KVAH Cons | AI3: KWH | AJ3: KWH Cons | AK3: KVA | AL3: Max. KVA | AM3: Power Factor | AN3: KWH | AO3: KWH Cons | AP3: KWH | AQ3: KWH Cons
A4: ='Current month'!A3 -> 44773 | B4: ='Current month'!B3 -> 4947456 | C4: ='Current month'!D3 -> 3887248 | D4: ='Current month'!G3 -> 1070 | E4: ='Current month'!H3 -> 1110 | F4: ='Current month'!W3 -> 2327276 | G4: ='Current month'!U3 -> 2994789 | N4: =B4 -> 4947456 | P4: =C4 -> 3887248 | S4: =D4 -> 1070 | T4: =E4 -> 1110 | V4: =F4 -> 2327276 | X4: =G4 -> 2994789 | Z4: =H4 -> 0 | AB4: =I4 -> 0 | AD4: =J4 -> 0 | AE4: =K4 -> 0 | AF4: =AC4/AA4 -> #DIV/0! | AN4: =L4 -> 0 | AP4: =M4 -> 0
A5: ='Current month'!A4 -> 44774 | B5: ='Current month'!B4 -> 4969645 | C5: ='Current month'!D4 -> 3909086 | D5: ='Current month'!#REF! -> #REF! | E5: ='Current month'!G4 -> 1070 | F5: ='Current month'!W4 -> 2327780 | G5: ='Current month'!U4 -> 2995354 | N5: =B5 -> 4969645 | O5: =N5-N4 -> 22189 | P5: =C5 -> 3909086 | Q5: =P5-P4 -> 21838 | R5: =D5 -> #REF! | S5: =D5 -> #REF! | T5: =E5 -> 1070 | U5: =Q5/O5 -> 0.98418135 | V5: =F5 -> 2327780 | W5: =V5-V4 -> 504 | X5: =G5 -> 2995354 | Y5: =X5-X4 -> 565 | Z5: =H5 -> 0 | AA5: =Z5-Z4 -> 0 | AB5: =I5 -> 0 | AC5: =AB5-AB4 -> 0 | AD5: =J5 -> 0 | AE5: =K5 -> 0 | AF5: =AC5/AA5 -> #DIV/0! | AN5: =L5 -> 0 | AO5: =AN5-AN4 -> 0 | AP5: =M5 -> 0 | AQ5: =AP5-AP4 -> 0
A6: ='Current month'!A5 -> 44775 | B6: ='Current month'!B5 -> 4992194 | C6: ='Current month'!D5 -> 3930883 | D6: ='Current month'!G6 -> 1070 | E6: ='Current month'!H5 -> 1110 | F6: ='Current month'!W5 -> 2328316 | G6: ='Current month'!U5 -> 2996415 | H6: 2779830 | I6: 2384472 | J6: 96 | K6: 104 | L6: 41146 | M6: 32572 | N6: =B6 -> 4992194 | O6: =N6-N5 -> 22549 | P6: =C6 -> 3930883 | Q6: =P6-P5 -> 21797 | S6: =D6 -> 1070 | T6: =E6 -> 1110 | U6: =Q6/O6 -> 0.96665041 | V6: =F6 -> 2328316 | W6: =V6-V5 -> 536 | X6: =G6 -> 2996415 | Y6: =X6-X5 -> 1061 | Z6: =H6 -> 2779830 | AA6: =Z6-Z5 -> 2779830 | AB6: =I6 -> 2384472 | AC6: =AB6-AB5 -> 2384472 | AD6: =J6 -> 96 | AE6: =K6 -> 104 | AF6: =AC6/AA6 -> 0.85777619 | AN6: =L6 -> 41146 | AO6: =AN6-AN5 -> 41146 | AP6: =M6 -> 32572 | AQ6: =AP6-AP5 -> 32572
A7: ='Current month'!A6 -> 44776 | B7: ='Current month'!B6 -> 5016428 | C7: ='Current month'!D6 -> 3954367 | D7: ='Current month'!#REF! -> #REF! | E7: ='Current month'!H6 -> 1110 | F7: ='Current month'!W6 -> 2328838 | G7: ='Current month'!U6 -> 2998031 | H7: 2781496 | I7: 2385937 | J7: 96 | K7: 107 | L7: 41161 | M7: 32583 | N7: =B7 -> 5016428 | O7: =N7-N6 -> 24234 | P7: =C7 -> 3954367 | Q7: =P7-P6 -> 23484 | S7: =D7 -> #REF! | T7: =E7 -> 1110 | U7: =Q7/O7 -> 0.96905175 | V7: =F7 -> 2328838 | W7: =V7-V6 -> 522 | X7: =G7 -> 2998031 | Y7: =X7-X6 -> 1616 | Z7: =H7 -> 2781496 | AA7: =Z7-Z6 -> 1666 | AB7: =I7 -> 2385937 | AC7: =AB7-AB6 -> 1465 | AD7: =J7 -> 96 | AE7: =K7 -> 107 | AF7: =AC7/AA7 -> 0.87935174 | AN7: =L7 -> 41161 | AO7: =AN7-AN6 -> 15 | AP7: =M7 -> 32583 | AQ7: =AP7-AP6 -> 11
A8: ='Current month'!A7 -> 44777 | B8: ='Current month'!B7 -> 0 | C8: ='Current month'!D7 -> 0 | D8: ='Current month'!G7 -> 0 | E8: ='Current month'!H7 -> 0 | F8: ='Current month'!W7 -> 0 | G8: ='Current month'!U7 -> 0 | H8: 2783367 | I8: 2387576 | J8: 99 | K8: 111 | L8: 41177 | M8: 32595 | N8: =B8 -> 0 | O8: =N8-N7 -> -5016428 | P8: =C8 -> 0 | Q8: =P8-P7 -> -3954367 | S8: =D8 -> 0 | T8: =E8 -> 0 | U8: =Q8/O8 -> 0.78828342 | V8: =F8 -> 0 | W8: =V8-V7 -> -2328838 | X8: =G8 -> 0 | Y8: =X8-X7 -> -2998031 | Z8: =H8 -> 2783367 | AA8: =Z8-Z7 -> 1871 | AB8: =I8 -> 2387576 | AC8: =AB8-AB7 -> 1639 | AD8: =J8 -> 99 | AE8: =K8 -> 111 | AF8: =AC8/AA8 -> 0.87600214 | AN8: =L8 -> 41177 | AO8: =AN8-AN7 -> 16 | AP8: =M8 -> 32595 | AQ8: =AP8-AP7 -> 12
A9: ='Current month'!A8 -> 44778 | B9: ='Current month'!B8 -> 0 | C9: ='Current month'!D8 -> 0 | D9: ='Current month'!G8 -> 0 | E9: ='Current month'!H8 -> 0 | F9: ='Current month'!#REF! -> #REF! | G9: ='Current month'!W8 -> 0 | H9: 2785273 | I9: 2389230 | J9: 111 | K9: 114 | L9: 41193 | M9: 32607 | N9: =B9 -> 0 | O9: =N9-N8 -> 0 | P9: =C9 -> 0 | Q9: =P9-P8 -> 0 | S9: =D9 -> 0 | T9: =E9 -> 0 | U9: =Q9/O9 -> #DIV/0! | V9: =F9 -> #REF! | W9: =V9-V8 -> #REF! | X9: =G9 -> 0 | Y9: =X9-X8 -> 0 | Z9: =H9 -> 2785273 | AA9: =Z9-Z8 -> 1906 | AB9: =I9 -> 2389230 | AC9: =AB9-AB8 -> 1654 | AD9: =J9 -> 111 | AE9: =K9 -> 114 | AF9: =AC9/AA9 -> 0.86778594 | AN9: =L9 -> 41193 | AO9: =AN9-AN8 -> 16 | AP9: =M9 -> 32607 | AQ9: =AP9-AP8 -> 12
A10: ='Current month'!A9 -> 44779 | B10: ='Current month'!B9 -> 0 | C10: ='Current month'!D9 -> 0 | D10: ='Current month'!G9 -> 0 | E10: ='Current month'!H9 -> 0 | F10: ='Current month'!W9 -> 0 | G10: ='Current month'!U9 -> 0 | H10: 2786932 | I10: 2390670 | J10: 99 | K10: 111 | L10: 41208 | M10: 32617 | N10: =B10 -> 0 | O10: =N10-N9 -> 0 | P10: =C10 -> 0 | Q10: =P10-P9 -> 0 | S10: =D10 -> 0 | T10: =E10 -> 0 | U10: =Q10/O10 -> #DIV/0! | V10: =F10 -> 0 | W10: =V10-V9 -> #REF! | X10: =G10 -> 0 | Y10: =X10-X9 -> 0 | Z10: =H10 -> 2786932 | AA10: =Z10-Z9 -> 1659 | AB10: =I10 -> 2390670 | AC10: =AB10-AB9 -> 1440 | AD10: =J10 -> 99 | AE10: =K10 -> 111 | AF10: =AC10/AA10 -> 0.86799277 | AN10: =L10 -> 41208 | AO10: =AN10-AN9 -> 15 | AP10: =M10 -> 32617 | AQ10: =AP10-AP9 -> 10
A11: ='Current month'!A10 -> 44780 | B11: ='Current month'!B10 -> 0 | C11: ='Current month'!D10 -> 0 | D11: ='Current month'!G10 -> 0 | E11: ='Current month'!H10 -> 0 | F11: ='Current month'!W10 -> 0 | G11: ='Current month'!U10 -> 0 | H11: 2788735 | I11: 2392245 | J11: 99 | K11: 104 | L11: 41223 | M11: 32627 | N11: =B11 -> 0 | O11: =N11-N10 -> 0 | P11: =C11 -> 0 | Q11: =P11-P10 -> 0 | S11: =D11 -> 0 | T11: =E11 -> 0 | U11: =Q11/O11 -> #DIV/0! | V11: =F11 -> 0 | W11: =V11-V10 -> 0 | X11: =G11 -> 0 | Y11: =X11-X10 -> 0 | Z11: =H11 -> 2788735 | AA11: =Z11-Z10 -> 1803 | AB11: =I11 -> 2392245 | AC11: =AB11-AB10 -> 1575 | AD11: =J11 -> 99 | AE11: =K11 -> 104 | AF11: =AC11/AA11 -> 0.87354409 | AN11: =L11 -> 41223 | AO11: =AN11-AN10 -> 15 | AP11: =M11 -> 32627 | AQ11: =AP11-AP10 -> 10
A12: ='Current month'!A11 -> 44781 | B12: ='Current month'!B11 -> 0 | C12: ='Current month'!D11 -> 0 | D12: ='Current month'!G11 -> 0 | E12: ='Current month'!H11 -> 0 | F12: ='Current month'!W11 -> 0 | G12: ='Current month'!U11 -> 0 | H12: 2789392 | I12: 2392821 | J12: 99 | K12: 111 | L12: 41227 | M12: 32631 | N12: =B12 -> 0 | O12: =N12-N11 -> 0 | P12: =C12 -> 0 | Q12: =P12-P11 -> 0 | S12: =D12 -> 0 | T12: =E12 -> 0 | U12: =Q12/O12 -> #DIV/0! | V12: =F12 -> 0 | W12: =V12-V11 -> 0 | X12: =G12 -> 0 | Y12: =X12-X11 -> 0 | Z12: =H12 -> 2789392 | AA12: =Z12-Z11 -> 657 | AB12: =I12 -> 2392821 | AC12: =AB12-AB11 -> 576 | AD12: =J12 -> 99 | AE12: =K12 -> 111 | AF12: =AC12/AA12 -> 0.87671233 | AN12: =L12 -> 41227 | AO12: =AN12-AN11 -> 4 | AP12: =M12 -> 32631 | AQ12: =AP12-AP11 -> 4
A13: ='Current month'!A12 -> 44782 | B13: ='Current month'!B12 -> 0 | C13: ='Current month'!D12 -> 0 | D13: ='Current month'!G12 -> 0 | E13: ='Current month'!H12 -> 0 | F13: ='Current month'!W12 -> 0 | G13: ='Current month'!U12 -> 0 | N13: =B13 -> 0 | O13: =N13-N12 -> 0 | P13: =C13 -> 0 | Q13: =P13-P12 -> 0 | S13: =D13 -> 0 | T13: =E13 -> 0 | U13: =Q13/O13 -> #DIV/0! | V13: =F13 -> 0 | W13: =V13-V12 -> 0 | X13: =G13 -> 0 | Y13: =X13-X12 -> 0 | Z13: =H13 -> 0 | AB13: =I13 -> 0 | AD13: =J13 -> 0 | AE13: =K13 -> 0 | AF13: =AC13/AA13 -> #DIV/0! | AN13: =L13 -> 0 | AP13: =M13 -> 0
A14: ='Current month'!A13 -> 44783 | B14: ='Current month'!B13 -> 0 | C14: ='Current month'!D13 -> 0 | D14: ='Current month'!G13 -> 0 | E14: ='Current month'!H13 -> 0 | F14: ='Current month'!W13 -> 0 | G14: ='Current month'!U13 -> 0 | N14: =B14 -> 0 | O14: =N14-N13 -> 0 | P14: =C14 -> 0 | Q14: =P14-P13 -> 0 | S14: =D14 -> 0 | T14: =E14 -> 0 | U14: =Q14/O14 -> #DIV/0! | V14: =F14 -> 0 | W14: =V14-V13 -> 0 | X14: =G14 -> 0 | Y14: =X14-X13 -> 0 | Z14: =H14 -> 0 | AA14: =Z14-Z13 -> 0 | AB14: =I14 -> 0 | AC14: =AB14-AB13 -> 0 | AD14: =J14 -> 0 | AE14: =K14 -> 0 | AF14: =AC14/AA14 -> #DIV/0! | AN14: =L14 -> 0 | AO14: =AN14-AN13 -> 0 | AP14: =M14 -> 0 | AQ14: =AP14-AP13 -> 0
A15: ='Current month'!A14 -> 44784 | B15: ='Current month'!B14 -> 0 | C15: ='Current month'!D14 -> 0 | D15: ='Current month'!G14 -> 0 | E15: ='Current month'!H14 -> 0 | F15: ='Current month'!W14 -> 0 | G15: ='Current month'!U14 -> 0 | N15: =B15 -> 0 | O15: =N15-N14 -> 0 | P15: =C15 -> 0 | Q15: =P15-P14 -> 0 | S15: =D15 -> 0 | T15: =E15 -> 0 | U15: =Q15/O15 -> #DIV/0! | V15: =F15 -> 0 | W15: =V15-V14 -> 0 | X15: =G15 -> 0 | Y15: =X15-X14 -> 0 | Z15: =H15 -> 0 | AA15: =Z15-Z14 -> 0 | AB15: =I15 -> 0 | AC15: =AB15-AB14 -> 0 | AD15: =J15 -> 0 | AE15: =K15 -> 0 | AF15: =AC15/AA15 -> #DIV/0! | AN15: =L15 -> 0 | AO15: =AN15-AN14 -> 0 | AP15: =M15 -> 0 | AQ15: =AP15-AP14 -> 0
A16: ='Current month'!A15 -> 44785 | B16: ='Current month'!B15 -> 0 | C16: ='Current month'!D15 -> 0 | D16: ='Current month'!G15 -> 0 | E16: ='Current month'!H15 -> 0 | F16: ='Current month'!W15 -> 0 | G16: ='Current month'!U15 -> 0 | N16: =B16 -> 0 | O16: =N16-N15 -> 0 | P16: =C16 -> 0 | Q16: =P16-P15 -> 0 | S16: =D16 -> 0 | T16: =E16 -> 0 | U16: =Q16/O16 -> #DIV/0! | V16: =F16 -> 0 | W16: =V16-V15 -> 0 | X16: =G16 -> 0 | Y16: =X16-X15 -> 0 | Z16: =H16 -> 0 | AA16: =Z16-Z15 -> 0 | AB16: =I16 -> 0 | AC16: =AB16-AB15 -> 0 | AD16: =J16 -> 0 | AE16: =K16 -> 0 | AF16: =AC16/AA16 -> #DIV/0! | AN16: =L16 -> 0 | AO16: =AN16-AN15 -> 0 | AP16: =M16 -> 0 | AQ16: =AP16-AP15 -> 0
A17: ='Current month'!A16 -> 44786 | B17: ='Current month'!B16 -> 0 | C17: ='Current month'!D16 -> 0 | D17: ='Current month'!G16 -> 0 | E17: ='Current month'!H16 -> 0 | F17: ='Current month'!W16 -> 0 | G17: ='Current month'!U16 -> 0 | N17: =B17 -> 0 | O17: =N17-N16 -> 0 | P17: =C17 -> 0 | Q17: =P17-P16 -> 0 | S17: =D17 -> 0 | T17: =E17 -> 0 | U17: =Q17/O17 -> #DIV/0! | V17: =F17 -> 0 | W17: =V17-V16 -> 0 | X17: =G17 -> 0 | Y17: =X17-X16 -> 0 | Z17: =H17 -> 0 | AA17: =Z17-Z16 -> 0 | AB17: =I17 -> 0 | AC17: =AB17-AB16 -> 0 | AD17: =J17 -> 0 | AE17: =K17 -> 0 | AF17: =AC17/AA17 -> #DIV/0! | AN17: =L17 -> 0 | AO17: =AN17-AN16 -> 0 | AP17: =M17 -> 0 | AQ17: =AP17-AP16 -> 0
A18: ='Current month'!A17 -> 44787 | B18: ='Current month'!B17 -> 0 | C18: ='Current month'!D17 -> 0 | D18: ='Current month'!G17 -> 0 | E18: ='Current month'!H17 -> 0 | F18: ='Current month'!W17 -> 0 | G18: ='Current month'!U17 -> 0 | N18: =B18 -> 0 | O18: =N18-N17 -> 0 | P18: =C18 -> 0 | Q18: =P18-P17 -> 0 | S18: =D18 -> 0 | T18: =E18 -> 0 | U18: =Q18/O18 -> #DIV/0! | V18: =F18 -> 0 | W18: =V18-V17 -> 0 | X18: =G18 -> 0 | Y18: =X18-X17 -> 0 | Z18: =H18 -> 0 | AA18: =Z18-Z17 -> 0 | AB18: =I18 -> 0 | AC18: =AB18-AB17 -> 0 | AD18: =J18 -> 0 | AE18: =K18 -> 0 | AF18: =AC18/AA18 -> #DIV/0! | AN18: =L18 -> 0 | AO18: =AN18-AN17 -> 0 | AP18: =M18 -> 0 | AQ18: =AP18-AP17 -> 0
A19: ='Current month'!A18 -> 44788 | B19: ='Current month'!B18 -> 0 | C19: ='Current month'!D18 -> 0 | D19: ='Current month'!G18 -> 0 | E19: ='Current month'!H18 -> 0 | F19: ='Current month'!W18 -> 0 | G19: ='Current month'!U18 -> 0 | N19: =B19 -> 0 | O19: =N19-N18 -> 0 | P19: =C19 -> 0 | Q19: =P19-P18 -> 0 | S19: =D19 -> 0 | T19: =E19 -> 0 | U19: =Q19/O19 -> #DIV/0! | V19: =F19 -> 0 | W19: =V19-V18 -> 0 | X19: =G19 -> 0 | Y19: =X19-X18 -> 0 | Z19: =H19 -> 0 | AA19: =Z19-Z18 -> 0 | AB19: =I19 -> 0 | AC19: =AB19-AB18 -> 0 | AD19: =J19 -> 0 | AE19: =K19 -> 0 | AF19: =AC19/AA19 -> #DIV/0! | AN19: =L19 -> 0 | AO19: =AN19-AN18 -> 0 | AP19: =M19 -> 0 | AQ19: =AP19-AP18 -> 0
A20: ='Current month'!A19 -> 44789 | B20: ='Current month'!B19 -> 0 | C20: ='Current month'!D19 -> 0 | D20: ='Current month'!G19 -> 0 | E20: ='Current month'!H19 -> 0 | F20: ='Current month'!W19 -> 0 | G20: ='Current month'!U19 -> 0 | N20: =B20 -> 0 | O20: =N20-N19 -> 0 | P20: =C20 -> 0 | Q20: =P20-P19 -> 0 | S20: =D20 -> 0 | T20: =E20 -> 0 | U20: =Q20/O20 -> #DIV/0! | V20: =F20 -> 0 | W20: =V20-V19 -> 0 | X20: =G20 -> 0 | Y20: =X20-X19 -> 0 | Z20: =H20 -> 0 | AA20: =Z20-Z19 -> 0 | AB20: =I20 -> 0 | AC20: =AB20-AB19 -> 0 | AD20: =J20 -> 0 | AE20: =K20 -> 0 | AF20: =AC20/AA20 -> #DIV/0! | AN20: =L20 -> 0 | AO20: =AN20-AN19 -> 0 | AP20: =M20 -> 0 | AQ20: =AP20-AP19 -> 0
A21: ='Current month'!A20 -> 44790 | B21: ='Current month'!B20 -> 0 | C21: ='Current month'!D20 -> 0 | D21: ='Current month'!G20 -> 0 | E21: ='Current month'!H20 -> 0 | F21: ='Current month'!W20 -> 0 | G21: ='Current month'!U20 -> 0 | N21: =B21 -> 0 | O21: =N21-N20 -> 0 | P21: =C21 -> 0 | Q21: =P21-P20 -> 0 | S21: =D21 -> 0 | T21: =E21 -> 0 | U21: =Q21/O21 -> #DIV/0! | V21: =F21 -> 0 | W21: =V21-V20 -> 0 | X21: =G21 -> 0 | Y21: =X21-X20 -> 0 | Z21: =H21 -> 0 | AA21: =Z21-Z20 -> 0 | AB21: =I21 -> 0 | AC21: =AB21-AB20 -> 0 | AD21: =J21 -> 0 | AE21: =K21 -> 0 | AF21: =AC21/AA21 -> #DIV/0! | AN21: =L21 -> 0 | AO21: =AN21-AN20 -> 0 | AP21: =M21 -> 0 | AQ21: =AP21-AP20 -> 0
A22: ='Current month'!A21 -> 44791 | B22: ='Current month'!B21 -> 0 | C22: ='Current month'!D21 -> 0 | D22: ='Current month'!G21 -> 0 | E22: ='Current month'!H21 -> 0 | F22: ='Current month'!W21 -> 0 | G22: ='Current month'!U21 -> 0 | N22: =B22 -> 0 | O22: =N22-N21 -> 0 | P22: =C22 -> 0 | Q22: =P22-P21 -> 0 | S22: =D22 -> 0 | T22: =E22 -> 0 | U22: =Q22/O22 -> #DIV/0! | V22: =F22 -> 0 | W22: =V22-V21 -> 0 | X22: =G22 -> 0 | Y22: =X22-X21 -> 0 | Z22: =H22 -> 0 | AA22: =Z22-Z21 -> 0 | AB22: =I22 -> 0 | AC22: =AB22-AB21 -> 0 | AD22: =J22 -> 0 | AE22: =K22 -> 0 | AF22: =AC22/AA22 -> #DIV/0! | AN22: =L22 -> 0 | AO22: =AN22-AN21 -> 0 | AP22: =M22 -> 0 | AQ22: =AP22-AP21 -> 0
A23: ='Current month'!A22 -> 44792 | B23: ='Current month'!B22 -> 0 | C23: ='Current month'!D22 -> 0 | D23: ='Current month'!G22 -> 0 | E23: ='Current month'!H22 -> 0 | F23: ='Current month'!W22 -> 0 | G23: ='Current month'!U22 -> 0 | N23: =B23 -> 0 | O23: =N23-N22 -> 0 | P23: =C23 -> 0 | Q23: =P23-P22 -> 0 | S23: =D23 -> 0 | T23: =E23 -> 0 | U23: =Q23/O23 -> #DIV/0! | V23: =F23 -> 0 | W23: =V23-V22 -> 0 | X23: =G23 -> 0 | Y23: =X23-X22 -> 0 | Z23: =H23 -> 0 | AA23: =Z23-Z22 -> 0 | AB23: =I23 -> 0 | AC23: =AB23-AB22 -> 0 | AD23: =J23 -> 0 | AE23: =K23 -> 0 | AF23: =AC23/AA23 -> #DIV/0! | AN23: =L23 -> 0 | AO23: =AN23-AN22 -> 0 | AP23: =M23 -> 0 | AQ23: =AP23-AP22 -> 0
A24: ='Current month'!A23 -> 44793 | B24: ='Current month'!B23 -> 0 | C24: ='Current month'!D23 -> 0 | D24: ='Current month'!G23 -> 0 | E24: ='Current month'!H23 -> 0 | F24: ='Current month'!W23 -> 0 | G24: ='Current month'!U23 -> 0 | N24: =B24 -> 0 | O24: =N24-N23 -> 0 | P24: =C24 -> 0 | Q24: =P24-P23 -> 0 | S24: =D24 -> 0 | T24: =E24 -> 0 | U24: =Q24/O24 -> #DIV/0! | V24: =F24 -> 0 | W24: =V24-V23 -> 0 | X24: =G24 -> 0 | Y24: =X24-X23 -> 0 | Z24: =H24 -> 0 | AA24: =Z24-Z23 -> 0 | AB24: =I24 -> 0 | AC24: =AB24-AB23 -> 0 | AD24: =J24 -> 0 | AE24: =K24 -> 0 | AF24: =AC24/AA24 -> #DIV/0! | AN24: =L24 -> 0 | AO24: =AN24-AN23 -> 0 | AP24: =M24 -> 0 | AQ24: =AP24-AP23 -> 0
A25: ='Current month'!A24 -> 44794 | B25: ='Current month'!B24 -> 0 | C25: ='Current month'!D24 -> 0 | D25: ='Current month'!G24 -> 0 | E25: ='Current month'!H24 -> 0 | F25: ='Current month'!W24 -> 0 | G25: ='Current month'!U24 -> 0 | N25: =B25 -> 0 | O25: =N25-N24 -> 0 | P25: =C25 -> 0 | Q25: =P25-P24 -> 0 | S25: =D25 -> 0 | T25: =E25 -> 0 | U25: =Q25/O25 -> #DIV/0! | V25: =F25 -> 0 | W25: =V25-V24 -> 0 | X25: =G25 -> 0 | Y25: =X25-X24 -> 0 | Z25: =H25 -> 0 | AA25: =Z25-Z24 -> 0 | AB25: =I25 -> 0 | AC25: =AB25-AB24 -> 0 | AD25: =J25 -> 0 | AE25: =K25 -> 0 | AF25: =AC25/AA25 -> #DIV/0! | AN25: =L25 -> 0 | AO25: =AN25-AN24 -> 0 | AP25: =M25 -> 0 | AQ25: =AP25-AP24 -> 0
... A34: ='Current month'!A33 -> 44803 | B34: ='Current month'!B33 -> 0 | C34: ='Current month'!D33 -> 0 | D34: ='Current month'!G33 -> 0 | E34: ='Current month'!H33 -> 0 | F34: ='Current month'!W33 -> 0 | G34: ='Current month'!U33 -> 0 | N34: =B34 -> 0 | O34: =N34-N33 -> 0 | P34: =C34 -> 0 | Q34: =P34-P33 -> 0 | S34: =D34 -> 0 | T34: =E34 -> 0 | U34: =Q34/O34 -> #DIV/0! | V34: =F34 -> 0 | W34: =V34-V33 -> 0 | X34: =G34 -> 0 | Y34: =X34-X33 -> 0 | Z34: =H34 -> 0 | AA34: =Z34-Z33 -> 0 | AB34: =I34 -> 0 | AC34: =AB34-AB33 -> 0 | AD34: =J34 -> 0 | AE34: =K34 -> 0 | AF34: =AC34/AA34 -> #DIV/0! | AN34: =L34 -> 0 | AO34: =AN34-AN33 -> 0 | AP34: =M34 -> 0 | AQ34: =AP34-AP33 -> 0
A35: ='Current month'!#REF! -> #REF! | B35: ='Current month'!#REF! -> #REF! | C35: ='Current month'!#REF! -> #REF! | D35: ='Current month'!#REF! -> #REF! | E35: ='Current month'!#REF! -> #REF! | F35: ='Current month'!#REF! -> #REF! | G35: ='Current month'!#REF! -> #REF! | N35: =B35 -> #REF! | O35: =N35-N34 -> #REF! | P35: =C35 -> #REF! | Q35: =P35-P34 -> #REF! | S35: =D35 -> #REF! | T35: =E35 -> #REF! | U35: =Q35/O35 -> #REF! | V35: =F35 -> #REF! | W35: =V35-V34 -> #REF! | X35: =G35 -> #REF! | Y35: =X35-X34 -> #REF! | Z35: =H35 -> 0 | AA35: =Z35-Z34 -> 0 | AB35: =I35 -> 0 | AC35: =AB35-AB34 -> 0 | AD35: =J35 -> 0 | AE35: =K35 -> 0 | AF35: =AC35/AA35 -> #DIV/0! | AN35: =L35 -> 0 | AO35: =AN35-AN34 -> 0 | AP35: =M35 -> 0 | AQ35: =AP35-AP34 -> 0
R36: =D36 -> 0 | Z36: =H36 -> 0 | AB36: =I36 -> 0 | AD36: =J36 -> 0 | AE36: =K36 -> 0 | AM36: =L36 -> 0 | AN36: =L36 -> 0 | AP36: =M36 -> 0
O37: =SUM(O5:O36) -> #REF! | Q37: =SUM(Q5:Q36) -> #REF! | S37: =MAX(S4:S36) -> #REF! | T37: =MAX(T4:T36) -> #REF! | W37: =SUM(W5:W36) -> #REF! | Y37: =SUM(Y5:Y36) -> #REF! | AA37: =SUM(AA4:AA36) -> 2789392 | AC37: =SUM(AC4:AC36) -> 2392821 | AD37: =MAX(AD4:AD36) -> 111 | AE37: =MAX(AE4:AE36) -> 114 | AF37: =AC37/AA37 -> 0.85782887 | AO37: =SUM(AO4:AO36) -> 41227 | AQ37: =SUM(AQ4:AQ36) -> 32631
A39: CEB | B39: KVAH | C39: =O37 -> #REF!
B40: KWH | C40: =Q37 -> #REF!
B41: KVA | C41: 1222
B42: Max. KVA | C42: =MAX(E4:E35) -> #REF!
A43: Laundry | B43: KWH | C43: =W37 -> #REF!
A44: Vacoas | B44: KWH | C44: =Y37 -> #REF!
A45: Golf | B45: KVAH | C45: =AA37 -> 2789392
B46: KWH | C46: =AC37 -> 2392821
B47: KVA | C47: =MAX(J4:J35) -> 111
B48: Max. KVA | C48: =MAX(K4:K35) -> 114
A49: Lifting | B49: KWH | C49: =AO37 -> 41227
...

Sheet Daily report
L1: 0
C2: Date: | D2: =TODAY()-1 -> 44776 | O2: Signature: | P2: Michael
B4: ENERGY | L4: MAIN EQUIPMENT | V4: CHILLED WATER
B6: ELECTRICITY | D6: =D2 -> 44776 | F6: =D2-1 -> 44775 | H6: =F6-1 -> 44774 | J6: Average | L6: HOT WATER | W6: Chillers status(1,2): | X6: OK | Z6: OFF | AA6: set point 10
B8: Yester | C8: Consumption kWH: | D8: =VLOOKUP($D$2,'Current month'!$A$3:$EE$33,3,FALSE) -> 24234 | F8: =VLOOKUP($F$6,'Current month'!$A$3:$EE$33,3,FALSE) -> 22549 | H8: =VLOOKUP($H$6,'Current month'!$A$3:$EE$33,3,FALSE) -> 22189 | J8: 22k to 25K | M8: Yesterday's consumption: | N8: =VLOOKUP($D$2,'Current month'!$A$3:$EE$33,73,FALSE) -> 661100 | R8: Boiler tank Tem | W8: Temperature IN: | X8: 15.9 | Y8: 12.5
N9: 84 | X9: 7.5 | Z9: 0
C10: Back-up genset 1: | D10: OK | L10: Pantry A | M10: Boiler 1,2 | P10: OFF | R10: 0 | S10: 72 | W10: Temperature OUT: | X10: 13
L11: Pantry A | M11: Boiler 1,3 | N11: OK | P11: OK | Z11: 11
C12: Back-up genset 2: | D12: OK | L12: Pantry B | M12: Boiler 1,2 | N12: OFF | P12: OFF | R12: 0 | S12: 0 | V12: ∆T | X12: =+X8-X10 -> 2.9 | Z12: =+Z8-Z10 -> 0
L13: Pantry A | M13: Boiler 1,5 | N13: OK | P13: OK
C14: Diesel in stock: | D14: =VLOOKUP($D$2,'Current month'!A3:EE33,77,FALSE) -> 854250 | F14: Litres | L14: Pantry C | M14: Boiler 1,2 | N14: OFF | P14: OFF | R14: 0 | S14: 0 | V14: OTHER EQUIPMENT
H15: 22948 | L15: Pantry A | M15: Boiler 1,2 | N15: OK | P15: OK
L16: Pantry D | M16: Boiler 1,2 | N16: OFF | P16: OFF | R16: 0 | S16: 0 | V16: POSITIVE COLD ROOMS | Z16: Average +2 to +7
L17: Pantry D | M17: Boiler 1,2 | N17: OK | P17: OK | R17: 0
B18: WATER | F18: =D2-1 -> 44775 | H18: =F18-1 -> 44774 | L18: Pantry E | M18: Boiler 1,2 | N18: OFF | P18: OK | R18: 0 | S18: 70 | V18: Staff Kitchen | X18: OK
D19: 658 | L19: Pantry D | M19: Boiler 1,2 | N19: OK | P19: OK
C20: Yesterday's consumption m3: | D20: =VLOOKUP($D$2,'Current month'!A3:EE33,72,FALSE) -> 211 | F20: =VLOOKUP(F18,'Current month'!$A$3:$EE$33,72,FALSE) -> 156 | H20: =VLOOKUP(H18,'Current month'!$A$3:$EE$33,72,FALSE) -> 204 | L20: Pantry F | M20: Boiler 1,2 | N20: OFF | P20: OK | R20: 0 | S20: 70 | V20: Beau Champ | X20: OK
L21: Pantry D | M21: Boiler 1,2 | N21: OK | P21: OK
C22: CWA delivery | D22: =VLOOKUP($D$2,'Current month'!$A3:EE33,22,FALSE) -> 1616 | F22: =VLOOKUP($F$18,'Current month'!$A3:EG33,22,FALSE) -> 1061 | H22: =VLOOKUP($H$18,'Current month'!$A3:EI33,22,FALSE) -> 565 | L22: Pantry G | M22: Boiler 1,2 | N22: OFF | P22: OFF | R22: 0 | S22: 0 | V22: Pastry | X22: OK
M23: Boiler 1,2 | N23: OK | P23: OK | R23: 65
C24: North | D24: =VLOOKUP($D$2,'Current month'!$A$3:EE33,64,FALSE) -> 7 | F24: =VLOOKUP($F$18,'Current month'!$A$3:$EE$33,64,FALSE) -> 4 | H24: =VLOOKUP($H$18,'Current month'!$A$3:$EE$33,64,FALSE) -> 6 | L24: Main Building | M24: Boiler 1,2 | N24: OFF | P24: OK | R24: 0 | S24: 65 | V24: Breakfast | X24: OK
C26: South | D26: =VLOOKUP($D$2,'Current month'!$A$3:$EE$33,71,FALSE) -> 19 | F26: =VLOOKUP($F$18,'Current month'!$A$3:$EE$33,71,FALSE) -> 24 | H26: =VLOOKUP($H$18,'Current month'!$A$3:$EE$33,71,FALSE) -> 26 | L26: Set point | M26: 55 | V26: Larder | X26: OK
C27: Island | N27: 11.8
C28: Island | D28: =VLOOKUP($D$2,'Current month'!$A$3:$EE$33,34,FALSE) -> 470 | F28: =VLOOKUP($F$18,'Current month'!$A$3:$EE$33,34,FALSE) -> 470 | H28: =VLOOKUP($H$18,'Current month'!$A$3:$EE$33,34,FALSE) -> 470 | L28: FIRE FIGHTING SYSTEM | V28: Dairy | X28: OK
C30: Booster pump status(1,2,3): | D30: O.O.O | F30: OK | H30: OK | M30: Fire pump system: | N30: Operational | V30: Juice | X30: OK
C32: Water in stock: | D32: =VLOOKUP($D$2,'Current month'!$A$3:$EE$33,23,FALSE) -> 2328838 | F32: =D32%*400 -> 9315352 | H32: m3 | I32: 240 to 300 m3 | M32: Pressure: | N32: 3.8 | P32: Bars | R32: 5.5 to 6.5 | V32: Fish | X32: OK
B34: GAS | F34: =D2-1 -> 44775 | H34: =D2-2 -> 44774 | M34: Date of last test: | V34: Meat | X34: OK
N35: 40693
C36: Yesterday's consumption kg: | D36: =VLOOKUP($D$2,'Current month'!$A$3:$EE$33,81,FALSE) -> -230 | F36: =VLOOKUP($F$34,'Current month'!$A$3:$EE$33,81,FALSE) -> -180 | H36: =VLOOKUP($H$34,'Current month'!$A$3:$EE$33,81,FALSE) -> -230 | M36: Jockey pump running Hours: | N36: 1 | V36: Aquapazza | X36: OK
D37: 700
C38: Steam Boiler: | D38: =VLOOKUP($D$2,'Current month'!$A$3:$EE$33,103,FALSE) -> 36012 | F38: =VLOOKUP($F$34,'Current month'!$A$3:$EE$33,103,FALSE) -> 36003 | H38: =VLOOKUP($H$34,'Current month'!$A$3:$EE$33,103,FALSE) -> 35995 | L38: LIFTING PUMP | V38: Bamboo | X38: OK
C40: Gas tank status 1: | D40: OK | F40: =VLOOKUP($D$2,'Current month'!$A$3:$EE$33,83,FALSE) -> 69 | H40: % | L40: Main Building | M40: Pump 1 | N40: 2nd | P40: Pump 2 | R40: 2nd | V40: Wine Chill | X40: OK
C42: Gas tank status 2: | D42: OK | F42: =VLOOKUP($D$2,'Current month'!$A$3:$EE$33,85,FALSE) -> 19718.481 | H42: % | L42: Hobbit Village | M42: Pump 1 | N42: Low | P42: Pump 2 | R42: O.O.O | V42: NEGATIVE COLD ROOMS | Z42: Average -15 to -20
C44: Gas tank status 3: | D44: OK | F44: =VLOOKUP($D$2,'Current month'!$A$3:$EE$33,87,FALSE) -> 0 | H44: % | L44: Boundary | M44: Pump 1 | N44: Low | P44: Pump 2 | R44: Low
L45: Pantry B VR302 | M45: Pump 1 | N45: Low | P45: Pump 2 | R45: Low | V45: Pastry 1 | X45: OK
C46: Gas in hotel: | D46: =VLOOKUP($D$2,'Current month'!$A$3:$EE$33,89,FALSE) -> 3925 | F46: Kg | H46: 12500 kg | I46: to 27400 kg | L46: Pantry C Acqua | M46: Pump 1 | N46: Low | P46: Pump 2 | R46: Low | V46: Pastry 2 | X46: OK
L47: Spa | M47: Pump 1 | N47: Low | P47: Pump 2 | R47: O.O.O | V47: Bamboo Basement | X47: OK
C48: Pool temperature | D48: California | F48: Infiniti | H48: Fitness | L48: Pantry E GS183 | M48: Pump 1 | N48: Low | P48: Pump 2 | R48: O.O.O | V48: Vegetables: | X48: OK
D49: =VLOOKUP($D$2,'Current month'!$A$3:$ES$33,139,FALSE) -> 0 | F49: =VLOOKUP($D$2,'Current month'!$A$3:$ES$33,140,FALSE) -> 0 | H49: =VLOOKUP($D$2,'Current month'!$A$3:$ES$33,141,FALSE) -> 0 | L49: Pantry F GS110 | M49: Pump 1 | N49: Low | P49: Pump 2 | R49: Low | V49: Fish | X49: OK
L50: Pantry G VS215 | M50: Pump 1 | N50: Low | P50: Pump 2 | R50: Low | V50: Meat | X50: OK
...

Sheet Impact  
A1: PREVIOUS MONTH
A2: Date | B2: Units | K2: Cost - MUR | N2: CDD | O2: Total Daily Utilities Cost | Q2: Bed Nights | R2: % OCC | Y2: Date | Z2: Vacoas - Electricity | AC2: Laundry - Gas | AE2: Pantry F | AH2: Saving - MUR | AK2: Total Daily Saving
B3: Electricity | C3: Gas | D3: Water | K3: Electricity | L3: Gas | M3: Water | Z3: Units | AA3: % on Total | AB3: Cost | AC3: Units | AD3: Cost | AE3: Units | AF3: Cost | AH3: Electricity | AI3: Gas | AJ3: Water
A4: 43831 | B4: 21899 | C4: 943.75 | D4: 310 | K4: =B4*6.21 -> 135992.79 | L4: =C4*55.95 -> 52802.812 | M4: =D4*68.44 -> 21216.4 | N4: 27.6 | O4: =K4+L4+M4 -> 210012 | Q4: 248 | R4: 0.6 | Y4: 43831 | Z4: 1160 | AA4: =Z4/B4 -> 0.052970455 | AB4: =Z4*6.21 -> 7203.6 | AC4: 43.75 | AD4: =AC4*55.95 -> 2447.8125 | AE4: 25 | AF4: =AE4*55.95 -> 1398.75 | AH4: =$K$40-K4 -> 40422.292 | AI4: =$L$40-L4 -> 1996.6028 | AJ4: =$M$40-M4 -> 1611.6516 | AK4: =AH4+AI4+AJ4 -> 44030.547
A5: 43832 | B5: 25743 | C5: 975 | D5: 340 | K5: =B5*6.21 -> 159864.03 | L5: =C5*55.95 -> 54551.25 | M5: =D5*68.44 -> 23269.6 | N5: 26.9 | O5: =K5+L5+M5 -> 237684.88 | Q5: 228 | R5: 0.59 | Y5: 43832 | Z5: 665 | AA5: =Z5/B5 -> 0.025832265 | AB5: =Z5*6.21 -> 4129.65 | AC5: 37.5 | AD5: =AC5*55.95 -> 2098.125 | AE5: 31.25 | AF5: =AE5*55.95 -> 1748.4375 | AH5: =$K$40-K5 -> 16551.052 | AI5: =$L$40-L5 -> 248.16532 | AJ5: =$M$40-M5 -> -441.54839 | AK5: =AH5+AI5+AJ5 -> 16357.669
A6: 43833 | B6: 28432 | C6: 1093.75 | D6: 350 | K6: =B6*6.21 -> 176562.72 | L6: =C6*55.95 -> 61195.312 | M6: =D6*68.44 -> 23954 | N6: 26 | O6: =K6+L6+M6 -> 261712.03 | Q6: 238 | R6: 0.64 | Y6: 43833 | Z6: 771 | AA6: =Z6/B6 -> 0.027117333 | AB6: =Z6*6.21 -> 4787.91 | AC6: 31.25 | AD6: =AC6*55.95 -> 1748.4375 | AE6: 25 | AF6: =AE6*55.95 -> 1398.75 | AH6: =$K$40-K6 -> -147.63774 | AI6: =$L$40-L6 -> -6395.8972 | AJ6: =$M$40-M6 -> -1125.9484 | AK6: =AH6+AI6+AJ6 -> -7669.4833
A7: 43834 | B7: 28412 | C7: 906.25 | D7: 390 | K7: =B7*6.21 -> 176438.52 | L7: =C7*55.95 -> 50704.688 | M7: =D7*68.44 -> 26691.6 | N7: 25.4 | O7: =K7+L7+M7 -> 253834.81 | Q7: 236 | R7: 0.62 | Y7: 43834 | Z7: 1020 | AA7: =Z7/B7 -> 0.035900324 | AB7: =Z7*6.21 -> 6334.2 | AC7: 37.5 | AD7: =AC7*55.95 -> 2098.125 | AE7: 43.75 | AF7: =AE7*55.95 -> 2447.8125 | AH7: =$K$40-K7 -> -23.437742 | AI7: =$L$40-L7 -> 4094.7278 | AJ7: =$M$40-M7 -> -3863.5484 | AK7: =AH7+AI7+AJ7 -> 207.74169
A8: 43835 | B8: 25504 | C8: 1112.5 | D8: 300 | K8: =B8*6.21 -> 158379.84 | L8: =C8*55.95 -> 62244.375 | M8: =D8*68.44 -> 20532 | N8: 25 | O8: =K8+L8+M8 -> 241156.21 | Q8: 200 | R8: 0.55 | Y8: 43835 | Z8: 784 | AA8: =Z8/B8 -> 0.030740276 | AB8: =Z8*6.21 -> 4868.64 | AC8: 37.5 | AD8: =AC8*55.95 -> 2098.125 | AE8: 31.25 | AF8: =AE8*55.95 -> 1748.4375 | AH8: =$K$40-K8 -> 18035.242 | AI8: =$L$40-L8 -> -7444.9597 | AJ8: =$M$40-M8 -> 2296.0516 | AK8: =AH8+AI8+AJ8 -> 12886.334
A9: 43836 | B9: 28181 | C9: 681.25 | D9: 340 | K9: =B9*6.21 -> 175004.01 | L9: =C9*55.95 -> 38115.938 | M9: =D9*68.44 -> 23269.6 | N9: 26.3 | O9: =K9+L9+M9 -> 236389.55 | Q9: 177 | R9: 0.47 | Y9: 43836 | Z9: 898 | AA9: =Z9/B9 -> 0.031865441 | AB9: =Z9*6.21 -> 5576.58 | AC9: 31.25 | AD9: =AC9*55.95 -> 1748.4375 | AE9: 50 | AF9: =AE9*55.95 -> 2797.5 | AH9: =$K$40-K9 -> 1411.0723 | AI9: =$L$40-L9 -> 16683.478 | AJ9: =$M$40-M9 -> -441.54839 | AK9: =AH9+AI9+AJ9 -> 17653.002
A10: 43837 | B10: 28155 | C10: 1250 | D10: 340 | K10: =B10*6.21 -> 174842.55 | L10: =C10*55.95 -> 69937.5 | M10: =D10*68.44 -> 23269.6 | N10: 27.5 | O10: =K10+L10+M10 -> 268049.65 | Q10: 189 | R10: 0.51 | Y10: 43837 | Z10: 971 | AA10: =Z10/B10 -> 0.034487658 | AB10: =Z10*6.21 -> 6029.91 | AC10: 56.25 | AD10: =AC10*55.95 -> 3147.1875 | AE10: 37.5 | AF10: =AE10*55.95 -> 2098.125 | AH10: =$K$40-K10 -> 1572.5323 | AI10: =$L$40-L10 -> -15138.085 | AJ10: =$M$40-M10 -> -441.54839 | AK10: =AH10+AI10+AJ10 -> -14007.101
A11: 43838 | B11: 29552 | C11: 962.5 | D11: 330 | K11: =B11*6.21 -> 183517.92 | L11: =C11*55.95 -> 53851.875 | M11: =D11*68.44 -> 22585.2 | N11: 26.9 | O11: =K11+L11+M11 -> 259955 | Q11: 245 | R11: 0.67 | Y11: 43838 | Z11: 791 | AA11: =Z11/B11 -> 0.026766378 | AB11: =Z11*6.21 -> 4912.11 | AC11: 37.5 | AD11: =AC11*55.95 -> 2098.125 | AE11: 50 | AF11: =AE11*55.95 -> 2797.5 | AH11: =$K$40-K11 -> -7102.8377 | AI11: =$L$40-L11 -> 947.54032 | AJ11: =$M$40-M11 -> 242.85161 | AK11: =AH11+AI11+AJ11 -> -5912.4458
A12: 43839 | B12: 24412 | C12: 893.75 | D12: 330 | K12: =B12*6.21 -> 151598.52 | L12: =C12*55.95 -> 50005.312 | M12: =D12*68.44 -> 22585.2 | N12: 26.3 | O12: =K12+L12+M12 -> 224189.03 | Q12: 295 | R12: 0.79 | Y12: 43839 | Z12: 805 | AA12: =Z12/B12 -> 0.032975586 | AB12: =Z12*6.21 -> 4999.05 | AC12: 31.25 | AD12: =AC12*55.95 -> 1748.4375 | AE12: 43.75 | AF12: =AE12*55.95 -> 2447.8125 | AH12: =$K$40-K12 -> 24816.562 | AI12: =$L$40-L12 -> 4794.1028 | AJ12: =$M$40-M12 -> 242.85161 | AK12: =AH12+AI12+AJ12 -> 29853.517
A13: 43840 | B13: 28640 | C13: 1312.5 | D13: 370 | K13: =B13*6.21 -> 177854.4 | L13: =C13*55.95 -> 73434.375 | M13: =D13*68.44 -> 25322.8 | N13: 26 | O13: =K13+L13+M13 -> 276611.58 | Q13: 333 | R13: 0.89 | Y13: 43840 | Z13: 866 | AA13: =Z13/B13 -> 0.03023743 | AB13: =Z13*6.21 -> 5377.86 | AC13: 56.25 | AD13: =AC13*55.95 -> 3147.1875 | AE13: 56.25 | AF13: =AE13*55.95 -> 3147.1875 | AH13: =$K$40-K13 -> -1439.3177 | AI13: =$L$40-L13 -> -18634.96 | AJ13: =$M$40-M13 -> -2494.7484 | AK13: =AH13+AI13+AJ13 -> -22569.026
A14: 43841 | B14: 29594 | C14: 925 | D14: 330 | K14: =B14*6.21 -> 183778.74 | L14: =C14*55.95 -> 51753.75 | M14: =D14*68.44 -> 22585.2 | N14: 26 | O14: =K14+L14+M14 -> 258117.69 | Q14: 248 | R14: 0.87 | Y14: 43841 | Z14: 920 | AA14: =Z14/B14 -> 0.031087383 | AB14: =Z14*6.21 -> 5713.2 | AC14: 37.5 | AD14: =AC14*55.95 -> 2098.125 | AE14: 50 | AF14: =AE14*55.95 -> 2797.5 | AH14: =$K$40-K14 -> -7363.6577 | AI14: =$L$40-L14 -> 3045.6653 | AJ14: =$M$40-M14 -> 242.85161 | AK14: =AH14+AI14+AJ14 -> -4075.1408
A15: 43842 | B15: 30793 | C15: 1131.25 | D15: 410 | K15: =B15*6.21 -> 191224.53 | L15: =C15*55.95 -> 63293.438 | M15: =D15*68.44 -> 28060.4 | N15: 27.6 | O15: =K15+L15+M15 -> 282578.37 | Q15: 333 | R15: 0.84 | Y15: 43842 | Z15: 1147 | AA15: =Z15/B15 -> 0.037248725 | AB15: =Z15*6.21 -> 7122.87 | AC15: 31.25 | AD15: =AC15*55.95 -> 1748.4375 | AE15: 68.75 | AF15: =AE15*55.95 -> 3846.5625 | AH15: =$K$40-K15 -> -14809.448 | AI15: =$L$40-L15 -> -8494.0222 | AJ15: =$M$40-M15 -> -5232.3484 | AK15: =AH15+AI15+AJ15 -> -28535.818
... A28: 43855 | B28: 26788 | C28: 931.25 | D28: 350 | K28: =B28*6.21 -> 166353.48 | L28: =C28*55.95 -> 52103.438 | M28: =D28*68.44 -> 23954 | N28: 26.3 | O28: =K28+L28+M28 -> 242410.92 | Q28: 303 | R28: 0.79 | Y28: 43855 | Z28: 809 | AA28: =Z28/B28 -> 0.03020009 | AB28: =Z28*6.21 -> 5023.89 | AC28: 31.25 | AD28: =AC28*55.95 -> 1748.4375 | AE28: 62.5 | AF28: =AE28*55.95 -> 3496.875 | AH28: =$K$40-K28 -> 10061.602 | AI28: =$L$40-L28 -> 2695.9778 | AJ28: =$M$40-M28 -> -1125.9484 | AK28: =AH28+AI28+AJ28 -> 11631.632
A29: 43856 | B29: 24415 | C29: 950 | D29: 320 | K29: =B29*6.21 -> 151617.15 | L29: =C29*55.95 -> 53152.5 | M29: =D29*68.44 -> 21900.8 | N29: 26 | O29: =K29+L29+M29 -> 226670.45 | Q29: 283 | R29: 0.74 | Y29: 43856 | Z29: 550 | AA29: =Z29/B29 -> 0.022527135 | AB29: =Z29*6.21 -> 3415.5 | AC29: 31.25 | AD29: =AC29*55.95 -> 1748.4375 | AE29: 43.75 | AF29: =AE29*55.95 -> 2447.8125 | AH29: =$K$40-K29 -> 24797.932 | AI29: =$L$40-L29 -> 1646.9153 | AK29: =AH29+AI29+AJ29 -> 26444.848
A30: 43857 | B30: 25231 | C30: 943.75 | D30: 330 | K30: =B30*6.21 -> 156684.51 | L30: =C30*55.95 -> 52802.812 | M30: =D30*68.44 -> 22585.2 | N30: 25.2 | O30: =K30+L30+M30 -> 232072.52 | Q30: 276 | R30: 0.74 | Y30: 43857 | Z30: 2096 | AA30: =Z30/B30 -> 0.083072411 | AB30: =Z30*6.21 -> 13016.16 | AC30: 37.5 | AD30: =AC30*55.95 -> 2098.125 | AE30: 50 | AF30: =AE30*55.95 -> 2797.5 | AH30: =$K$40-K30 -> 19730.572 | AI30: =$L$40-L30 -> 1996.6028 | AK30: =AH30+AI30+AJ30 -> 21727.175
A31: 43858 | B31: 24760 | C31: 962.5 | D31: 310 | K31: =B31*6.21 -> 153759.6 | L31: =C31*55.95 -> 53851.875 | M31: =D31*68.44 -> 21216.4 | N31: 25 | O31: =K31+L31+M31 -> 228827.88 | Q31: 258 | R31: 0.72 | Y31: 43858 | Z31: 830 | AA31: =Z31/B31 -> 0.033521809 | AB31: =Z31*6.21 -> 5154.3 | AC31: 37.5 | AD31: =AC31*55.95 -> 2098.125 | AE31: 50 | AF31: =AE31*55.95 -> 2797.5 | AH31: =$K$40-K31 -> 22655.482 | AI31: =$L$40-L31 -> 947.54032 | AK31: =AH31+AI31+AJ31 -> 23603.023
A32: 43859 | B32: 25450 | C32: 912.5 | D32: 330 | K32: =B32*6.21 -> 158044.5 | L32: =C32*55.95 -> 51054.375 | M32: =D32*68.44 -> 22585.2 | N32: 24.7 | O32: =K32+L32+M32 -> 231684.08 | Q32: 255 | R32: 0.72 | Y32: 43859 | Z32: 648 | AA32: =Z32/B32 -> 0.02546169 | AB32: =Z32*6.21 -> 4024.08 | AC32: 31.25 | AD32: =AC32*55.95 -> 1748.4375 | AE32: 37.5 | AF32: =AE32*55.95 -> 2098.125 | AH32: =$K$40-K32 -> 18370.582 | AI32: =$L$40-L32 -> 3745.0403 | AK32: =AH32+AI32+AJ32 -> 22115.623
A33: 43860 | B33: 26859 | C33: 875 | D33: 320 | K33: =B33*6.21 -> 166794.39 | L33: =C33*55.95 -> 48956.25 | M33: =D33*68.44 -> 21900.8 | N33: 26 | O33: =K33+L33+M33 -> 237651.44 | Q33: 231 | R33: 0.63 | Y33: 43860 | Z33: 1349 | AA33: =Z33/B33 -> 0.05022525 | AB33: =Z33*6.21 -> 8377.29 | AC33: 87.5 | AD33: =AC33*55.95 -> 4895.625 | AE33: 43.75 | AF33: =AE33*55.95 -> 2447.8125 | AH33: =SUM(AH4:AH32) -> -10460.445 | AI33: =SUM(AI4:AI32) -> -12036.018 | AJ33: =SUM(AJ4:AJ32) -> -8301.1097 | AK33: =SUM(AK4:AK32) -> -30797.572
A34: 43861 | B34: 28273 | C34: 868.75 | D34: 270 | K34: =B34*6.21 -> 175575.33 | L34: =C34*55.95 -> 48606.562 | M34: =D34*68.44 -> 18478.8 | N34: 26 | O34: =K34+L34+M34 -> 242660.69 | Q34: 195 | R34: 0.65 | Y34: 43861 | Z34: 1136 | AA34: =Z34/B34 -> 0.040179677 | AB34: =Z34*6.21 -> 7054.56 | AC34: 31.25 | AD34: =AC34*55.95 -> 1748.4375 | AE34: 43.75 | AF34: =AE34*55.95 -> 2447.8125
A35: Total | B35: =SUM(B4:B34) -> 880655 | C35: =SUM(C4:C34) -> 30362.5 | D35: =SUM(D4:D34) -> 10340 | K35: =SUM(K4:K34) -> 5468867.5 | L35: =SUM(L4:L34) -> 1698781.9 | M35: =SUM(M4:M34) -> 707669.6 | O35: =SUM(O4:O34) -> 7875319 | Y35: Total | Z35: =SUM(Z4:Z34) -> 38462 | AB35: =SUM(AB4:AB34) -> 238849.02 | AC35: =SUM(AC4:AC34) -> 1200 | AD35: =SUM(AD4:AD34) -> 67140 | AE35: =SUM(AE4:AE34) -> 1406.25 | AF35: =SUM(AF4:AF34) -> 78679.688
B38: Units | K38: Cost - MUR | N38: CDD | O38: Daily Utilities Cost | Q38: Bed Nights | R38: % OCC | Z38: Vacoas - Electricity | AC38: Laundry - Gas | AE38: Pantry F
B39: Electricity | C39: Gas | D39: Water | K39: Electricity | L39: Gas | M39: Water | Z39: Units | AB39: Cost | AC39: Units | AD39: Cost | AE39: Units | AF39: Cost
A40: Ave/Day | B40: =B35/31 -> 28408.226 | C40: =C35/31 -> 979.43548 | D40: =D35/31 -> 333.54839 | K40: =K35/31 -> 176415.08 | L40: =L35/31 -> 54799.415 | M40: =M35/31 -> 22828.052 | N40: =AVERAGE(N4:N34) -> 26.706452 | O40: =O35/31 -> 254042.55 | Q40: =AVERAGE(Q4:Q34) -> 259.35484 | R40: =AVERAGE(R4:R34) -> 0.71645161 | Y40: Ave/Day | Z40: =Z35/31 -> 1240.7097 | AB40: =AB35/31 -> 7704.8071 | AC40: =AC35/31 -> 38.709677 | AD40: =AD35/31 -> 2165.8065 | AE40: =AE35/31 -> 45.362903 | AF40: =AF35/31 -> 2538.0544
A43: Date | B43: Units | K43: Cost - MUR | N43: CDD | O43: Total Daily Utilities Cost | Q43: Bed Nights | R43: % OCC | Y43: Date | Z43: Vacoas - Electricity | AC43: Laundry - Gas | AE43: Pantry F | AH43: Saving - MUR | AK43: Total Daily Saving
B44: Electricity | C44: Gas | D44: Water | K44: Electricity | L44: Gas | M44: Water | Z44: Units | AA44: % on Total | AB44: Cost | AC44: Units | AD44: Cost | AE44: Units | AF44: Cost | AH44: Electricity | AI44: Gas | AJ44: Water
A45: 43862 | B45: 27980 | C45: 975 | D45: 270 | K45: =B45*6.21 -> 173755.8 | L45: =C45*55.95 -> 54551.25 | M45: =D45*68.44 -> 18478.8 | N45: 27.3 | O45: =K45+L45+M45 -> 246785.85 | Q45: 209 | R45: 0.65 | Y45: 43862 | Z45: 704 | AA45: =Z45/B45 -> 0.025160829 | AB45: =Z45*6.21 -> 4371.84 | AC45: 31.25 | AD45: =AC45*55.95 -> 1748.4375 | AE45: 43.75 | AF45: =AE45*55.95 -> 2447.8125 | AH45: =$K$40-K45 -> 2659.2823 | AI45: =$L$40-L45 -> 248.16532 | AJ45: =$M$40-M45 -> 4349.2516 | AK45: =AH45+AI45+AJ45 -> 7256.6992
A46: 43863 | B46: 28575 | C46: 825 | D46: 290 | K46: =B46*6.21 -> 177450.75 | L46: =C46*55.95 -> 46158.75 | M46: =D46*68.44 -> 19847.6 | N46: 27 | O46: =K46+L46+M46 -> 243457.1 | Q46: 169 | R46: 0.56 | Y46: 43863 | Z46: 816 | AA46: =Z46/B46 -> 0.02855643 | AB46: =Z46*6.21 -> 5067.36 | AC46: 25 | AD46: =AC46*55.95 -> 1398.75 | AE46: 43.75 | AF46: =AE46*55.95 -> 2447.8125 | AH46: =$K$40-K46 -> -1035.6677 | AI46: =$L$40-L46 -> 8640.6653 | AJ46: =$M$40-M46 -> 2980.4516 | AK46: =AH46+AI46+AJ46 -> 10585.449
A47: 43864 | B47: 29882 | C47: 787.5 | D47: 270 | K47: =B47*6.21 -> 185567.22 | L47: =C47*55.95 -> 44060.625 | M47: =D47*68.44 -> 18478.8 | N47: 27.7 | O47: =K47+L47+M47 -> 248106.64 | Q47: 181 | R47: 0.59 | Y47: 43864 | Z47: 2059 | AA47: =Z47/B47 -> 0.068904357 | AB47: =Z47*6.21 -> 12786.39 | AC47: 25 | AD47: =AC47*55.95 -> 1398.75 | AE47: 50 | AF47: =AE47*55.95 -> 2797.5 | AH47: =$K$40-K47 -> -9152.1377 | AI47: =$L$40-L47 -> 10738.79 | AJ47: =$M$40-M47 -> 4349.2516 | AK47: =AH47+AI47+AJ47 -> 5935.9042
A48: 43865 | B48: 28520 | C48: 781.25 | D48: 300 | K48: =B48*6.21 -> 177109.2 | L48: =C48*55.95 -> 43710.938 | M48: =D48*68.44 -> 20532 | N48: 26.2 | O48: =K48+L48+M48 -> 241352.14 | Q48: 199 | R48: 0.64 | Y48: 43865 | Z48: 1922 | AA48: =Z48/B48 -> 0.067391304 | AB48: =Z48*6.21 -> 11935.62 | AC48: 25 | AD48: =AC48*55.95 -> 1398.75 | AE48: 43.75 | AF48: =AE48*55.95 -> 2447.8125 | AH48: =$K$40-K48 -> -694.11774 | AI48: =$L$40-L48 -> 11088.478 | AJ48: =$M$40-M48 -> 2296.0516 | AK48: =AH48+AI48+AJ48 -> 12690.412
A49: 43866 | B49: 27431 | C49: 818.75 | D49: 350 | K49: =B49*6.21 -> 170346.51 | L49: =C49*55.95 -> 45809.062 | M49: =D49*68.44 -> 23954 | N49: 27.4 | O49: =K49+L49+M49 -> 240109.57 | Q49: 182 | R49: 0.58 | Y49: 43866 | Z49: 2009 | AA49: =Z49/B49 -> 0.073238307 | AB49: =Z49*6.21 -> 12475.89 | AC49: 25 | AD49: =AC49*55.95 -> 1398.75 | AE49: 43.75 | AF49: =AE49*55.95 -> 2447.8125 | AH49: =$K$40-K49 -> 6068.5723 | AI49: =$L$40-L49 -> 8990.3528 | AJ49: =$M$40-M49 -> -1125.9484 | AK49: =AH49+AI49+AJ49 -> 13932.977
A50: 43867 | B50: 27753 | C50: 856.25 | D50: 310 | K50: =B50*6.21 -> 172346.13 | L50: =C50*55.95 -> 47907.188 | M50: =D50*68.44 -> 21216.4 | N50: 27.4 | O50: =K50+L50+M50 -> 241469.72 | Q50: 189 | R50: 0.59 | Y50: 43867 | Z50: 587 | AA50: =Z50/B50 -> 0.021150867 | AB50: =Z50*6.21 -> 3645.27 | AC50: 25 | AD50: =AC50*55.95 -> 1398.75 | AE50: 43.75 | AF50: =AE50*55.95 -> 2447.8125 | AH50: =$K$40-K50 -> 4068.9523 | AI50: =$L$40-L50 -> 6892.2278 | AJ50: =$M$40-M50 -> 1611.6516 | AK50: =AH50+AI50+AJ50 -> 12572.832
A51: 43868 | B51: 26949 | C51: 893.75 | D51: 290 | K51: =B51*6.21 -> 167353.29 | L51: =C51*55.95 -> 50005.312 | M51: =D51*68.44 -> 19847.6 | N51: 26.9 | O51: =K51+L51+M51 -> 237206.2 | Q51: 177 | R51: 0.56 | Y51: 43868 | Z51: 611 | AA51: =Z51/B51 -> 0.022672455 | AB51: =Z51*6.21 -> 3794.31 | AC51: 31.25 | AD51: =AC51*55.95 -> 1748.4375 | AE51: 37.5 | AF51: =AE51*55.95 -> 2098.125 | AH51: =$K$40-K51 -> 9061.7923 | AI51: =$L$40-L51 -> 4794.1028 | AJ51: =$M$40-M51 -> 2980.4516 | AK51: =AH51+AI51+AJ51 -> 16836.347
A52: 43869 | B52: 27034 | C52: 768.75 | D52: 320 | K52: =B52*6.21 -> 167881.14 | L52: =C52*55.95 -> 43011.562 | M52: =D52*68.44 -> 21900.8 | N52: 26.9 | O52: =K52+L52+M52 -> 232793.5 | Q52: 170 | R52: 0.52 | Y52: 43869 | Z52: 635 | AA52: =Z52/B52 -> 0.02348894 | AB52: =Z52*6.21 -> 3943.35 | AC52: 25 | AD52: =AC52*55.95 -> 1398.75 | AE52: 31.25 | AF52: =AE52*55.95 -> 1748.4375 | AH52: =$K$40-K52 -> 8533.9423 | AI52: =$L$40-L52 -> 11787.853 | AJ52: =$M$40-M52 -> 927.25161 | AK52: =AH52+AI52+AJ52 -> 21249.047
A53: 43870 | B53: 24570 | C53: 775 | D53: 300 | K53: =B53*6.21 -> 152579.7 | L53: =C53*55.95 -> 43361.25 | M53: =D53*68.44 -> 20532 | N53: 26.7 | O53: =K53+L53+M53 -> 216472.95 | Q53: 171 | R53: 0.51 | Y53: 43870 | Z53: 611 | AA53: =Z53/B53 -> 0.024867725 | AB53: =Z53*6.21 -> 3794.31 | AC53: 31.25 | AD53: =AC53*55.95 -> 1748.4375 | AE53: 31.25 | AF53: =AE53*55.95 -> 1748.4375 | AH53: =$K$40-K53 -> 23835.382 | AI53: =$L$40-L53 -> 11438.165 | AJ53: =$M$40-M53 -> 2296.0516 | AK53: =AH53+AI53+AJ53 -> 37569.599
A54: 43871 | B54: 25702 | C54: 743.75 | D54: 270 | K54: =B54*6.21 -> 159609.42 | L54: =C54*55.95 -> 41612.812 | M54: =D54*68.44 -> 18478.8 | N54: 26.1 | O54: =K54+L54+M54 -> 219701.03 | Q54: 150 | R54: 0.47 | Y54: 43871 | Z54: 508 | AA54: =Z54/B54 -> 0.019764999 | AB54: =Z54*6.21 -> 3154.68 | AC54: 25 | AD54: =AC54*55.95 -> 1398.75 | AE54: 25 | AF54: =AE54*55.95 -> 1398.75 | AH54: =$K$40-K54 -> 16805.662 | AI54: =$L$40-L54 -> 13186.603 | AJ54: =$M$40-M54 -> 4349.2516 | AK54: =AH54+AI54+AJ54 -> 34341.517
A55: 43872 | B55: 25512 | C55: 787.5 | D55: 300 | K55: =B55*6.21 -> 158429.52 | L55: =C55*55.95 -> 44060.625 | M55: =D55*68.44 -> 20532 | N55: 26.9 | O55: =K55+L55+M55 -> 223022.14 | Q55: 145 | R55: 0.47 | Y55: 43872 | Z55: 722 | AA55: =Z55/B55 -> 0.028300408 | AB55: =Z55*6.21 -> 4483.62 | AC55: 25 | AD55: =AC55*55.95 -> 1398.75 | AE55: 0 | AF55: =AE55*55.95 -> 0 | AH55: =$K$40-K55 -> 17985.562 | AI55: =$L$40-L55 -> 10738.79 | AJ55: =$M$40-M55 -> 2296.0516 | AK55: =AH55+AI55+AJ55 -> 31020.404
A56: 43873 | B56: 27320 | C56: 800 | D56: 260 | K56: =B56*6.21 -> 169657.2 | L56: =C56*55.95 -> 44760 | M56: =D56*68.44 -> 17794.4 | N56: 27.6 | O56: =K56+L56+M56 -> 232211.6 | Q56: 160 | R56: 0.5 | Y56: 43873 | Z56: 1305 | AA56: =Z56/B56 -> 0.047767204 | AB56: =Z56*6.21 -> 8104.05 | AC56: 31.25 | AD56: =AC56*55.95 -> 1748.4375 | AE56: 0 | AF56: =AE56*55.95 -> 0 | AH56: =$K$40-K56 -> 6757.8823 | AI56: =$L$40-L56 -> 10039.415 | AJ56: =$M$40-M56 -> 5033.6516 | AK56: =AH56+AI56+AJ56 -> 21830.949
...

Sheet Current month
B1: Hotel Electricity | I1: Gen 01 | M1: Gen 02 | Q1: MB & Island | R1: CONS | S1: North & South | T1: CONS | U1: Vacoas KW | V1: CONS | W1: Laundry (KWh) | X1: CONS | Y1: Hotel | AB1: % Water Available | AC1: Water reservoir, 400 m3 | AD1: water truck | AI1: Water Softener | AK1: bamboo pool | AM1: CWA (FS) | AN1: CONS | AP1: CONS | AQ1: Island | AS1: Island Sub | AU1: Main Building | AW1: Pantry A | AY1: Pantry B | BA1: Pantry C | BC1: Pantry D | BE1: Pantry E | BG1: Pantry F | BI1: Pantry G | BU1: North | BW1: North Sub | BY1: South | CA1: South Sub | CF1: Diesel | CJ1: Gas | DE1: Steam Boiler( Laundry) | DH1: Main Building ( boiler) | DK1: Pantry A | DN1: Pantry B | DQ1: Pantry C | DT1: Pantry D | DW1: Pantry E | DZ1: Pantry F | EC1: Pantry G | EQ1: Pool Temperature | ET1: BEVERAGE STORE
A2: Date | B2: KVAH | C2: CONS | D2: KWH | E2: CONS | F2: PF | G2: KVA | H2: KVA max | I2: KWH | J2: CONS | K2: Hrs | L2: CONS | M2: KWH | N2: CONS | O2: Hrs | P2: CONS | Q2: KWH | R2: CONS | S2: KWH | T2: CONS | U2: KWH | V2: CONS | W2: KWH | X2: CONS | Y2: CWA23 | Z2: CONS | AD2: 38 | AE2: Truck Meter | AF2: Cons | AG2: UV reading | AI2: chiller | AJ2: CONS | AL2: CONS | AQ2: island | AR2: cons | AU2: M.Buil | AV2: Cons | AW2: Pantry A | AX2: Cons | AY2: Pantry B | AZ2: Cons | BA2: Pantry C | BB2: cons | BC2: Pantry D | BD2: cons | BE2: Pantry E | BF2: cons | BG2: Pantry F | BH2: cons | BI2: Pantry G | BJ2: Cons | BK2: Main Kitchen | BL2: Cons | BM2: Bamboo C | BN2: Cons | BO2: Bamboo H | BP2: Cons | BQ2: cyclon bridge | BR2: cons | BS2: Island - Hot | BT2: Island Cold | BU2: north | BV2: cons | BY2: south | BZ2: cons | CC2: south | CD2: Total water consump | CE2: Total HW consump | CF2: DIESEL( cm) | CG2: stock | CH2: Del | CI2: CONS | CJ2: Meter | CK2: cons | CL2: Kg | CM2: LPG 1 | CN2: stock | CO2: LPG 2 | CP2: stock | CQ2: LPG 3 | CR2: stock | CS2: total stock | CT2: cons | CU2: del | CV2: Beau champ ( Main kit) | CW2: cons(Litres) | CX2: Cons(Kg) | CY2: Acquapazza | CZ2: cons(Litres) | DA2: Cons(Kg) | DB2: Bamboo | DC2: cons(Litres) | DD2: Cons(Kg) | DF2: cons(Litres) | DG2: Cons(Kg) | DI2: cons(Litres) | DJ2: Cons(Kg) | DL2: cons(Litres) | DM2: Cons(Kg) | DO2: cons(Litres) | DP2: Cons(Kg) | DR2: cons(Litres) | DS2: Cons(Kg) | DU2: cons(Litres) | DV2: Cons(Kg) | DX2: cons(Litres) | DY2: Cons(Kg) | EA2: cons(Litres) | EB2: Cons(Kg) | ED2: cons(Litres) | EE2: Cons(Kg) | EF2: 145 | EG2: CONS | EH2: 146 | EI2: CONS | EJ2: Villa 111 | EK2: CONS | EL2: Villa 128 | EM2: CONS | EN2: Room Nights | EO2: Bed Nights | EP2: % OCC | EQ2: California | ER2: Infiniti | ES2: Fitness | ET2: 0.75 | EU2: 0 | EV2: 0.25
A3: 44773 | B3: 4947456 | C3: 24271 | D3: 3887248 | E3: 23114 | F3: 0.95232994 | G3: 1070 | H3: 1110 | I3: 292000 | J3: 0 | K3: 803 | L3: 0 | M3: 644837 | N3: 0 | O3: 1033 | P3: 0 | Q3: 3453800 | R3: 3453800 | S3: 3315500 | T3: 3315500 | U3: 2994789 | V3: 534 | W3: 2327276 | X3: 513 | Y3: 319524 | Z3: 279 | AB3: 0.72222222 | AC3: 288.88889 | AE3: 1340 | AF3: 0 | AG3: 549830 | AH3: 490 | AI3: 1180 | AJ3: 0 | AK3: 6029 | AL3: 3 | AM3: 58271 | AN3: 351 | AP3: 0 | AQ3: 640810 | AR3: 220 | AS3: 5172 | AT3: 32 | AU3: 58009 | AV3: 20 | AW3: 9445 | AX3: 4 | AY3: 11189 | AZ3: 4 | BA3: 19913 | BB3: 10 | BC3: 21369 | BD3: 7 | BE3: 21334 | BF3: 0 | BG3: 14700 | BH3: 6 | BI3: 6836 | BJ3: 1 | BK3: 28292 | BL3: 4 | BM3: 5951 | BN3: 3 | BO3: 33371 | BP3: 66 | BQ3: 3641 | BR3: 0 | BS3: 16 | BT3: 204 | BU3: 660530 | BV3: 190 | BX3: 0 | BY3: 854250 | BZ3: 0 | CA3: 28696 | CB3: 33 | CC3: -220 | CD3: 190 | CE3: 55 | CF3: 152 | CG3: 19718.481 | CJ3: 2694183 | CK3: 2425073 | CL3: 13847167 | CM3: 64 | CN3: 6896 | CO3: 65 | CP3: 7003.75 | CQ3: 65 | CR3: 7003.75 | CS3: 20903.5 | CT3: 1508.5 | CV3: 46855 | CW3: 43 | CX3: 245.53 | CY3: 35987 | CZ3: 9 | DA3: 51.39 | DB3: 15312 | DC3: 17 | DD3: 97.07 | DE3: 855886 | DF3: 127 | DG3: 725.17 | DH3: 11369 | DI3: 16 | DJ3: 91.36 | DK3: 10879 | DL3: 12 | DM3: 68.52 | DN3: 6636 | DO3: 15 | DP3: 85.65 | DQ3: 2309 | DR3: 2 | DS3: 11.42 | DT3: 8084 | DU3: 14 | DV3: 79.94 | DW3: 7482 | DX3: 9 | DY3: 51.39 | DZ3: 8072 | EA3: 11 | EB3: 62.81 | EC3: 7995 | ED3: 12 | EE3: 68.52 | EG3: 0 | EI3: 0 | EK3: 0 | EM3: 0 | EN3: 97 | EO3: 300 | EP3: 0.7582
A4: 44774 | B4: 4969645 | C4: =IF((B4-B3)<0,"0",(B4-B3)) -> 22189 | D4: 3909086 | E4: =IF((D4-D3)<0,"0",(D4-D3)) -> 21838 | F4: =E4/C4 -> 0.98418135 | G4: 1070 | H4: 1110 | I4: 292000 | J4: 0 | K4: 803 | L4: 1 | M4: 644807 | N4: 1 | O4: 1033 | P4: 1 | Q4: 3466300 | R4: =IF((Q4-Q3)<0,"0",(Q4-Q3)) -> 12500 | S4: 3366300 | T4: =IF((S4-S3)<0,"0",(S4-S3)) -> 50800 | U4: 2995354 | V4: =IF((U4-U3)<0,"0",(U4-U3)) -> 565 | W4: 2327780 | X4: =IF((W4-W3)<0,"0",(W4-W3)) -> 504 | Y4: 319839 | Z4: =Y4-Y3 -> 315 | AB4: =8.5/9 -> 0.94444444 | AC4: =AB4*400 -> 377.77778 | AE4: 1340 | AF4: =IF((AE4-AE3)<0,"0",(AE4-AE3)) -> 0 | AG4: 550300 | AH4: =IF((AG4-AG3)<0,"0",(AG4-AG3)) -> 470 | AI4: 1180 | AJ4: =IF((AI4-AI3)<0,"0",(AI4-AI3)) -> 0 | AK4: 6030 | AL4: =IF((AK4-AK3)<0,"0",(AK4-AK3)) -> 1 | AM4: 58658 | AN4: =IF((AM4-AM3)<0,"0",(AM4-AM3)) -> 387 | AP4: =IF((AO4-AO3)<0,"0",(AO4-AO3)) -> 0 | AQ4: 641040 | AR4: =IF((AQ4-AQ3)<0,"0",(AQ4-AQ3)) -> 230 | AS4: 5205 | AT4: =IF((AS4-AS3)<0,"0",(AS4-AS3)) -> 33 | AU4: 58030 | AV4: =IF((AU4-AU3)<0,"0",(AU4-AU3)) -> 21 | AW4: 9448 | AX4: =IF((AW4-AW3)<0,"0",(AW4-AW3)) -> 3 | AY4: 11191 | AZ4: =IF((AY4-AY3)<0,"0",(AY4-AY3)) -> 2 | BA4: 19921 | BB4: =IF((BA4-BA3)<0,"0",(BA4-BA3)) -> 8 | BC4: 21370 | BD4: =IF((BC4-BC3)<0,"0",(BC4-BC3)) -> 1 | BE4: 21346 | BF4: =IF((BE4-BE3)<0,"0",(BE4-BE3)) -> 12 | BG4: 14706 | BH4: =IF((BG4-BG3)<0,"0",(BG4-BG3)) -> 6 | BI4: 6837 | BJ4: =IF((BI4-BI3)<0,"0",(BI4-BI3)) -> 1 | BK4: 28298 | BL4: =IF((BK4-BK3)<0,"0",(BK4-BK3)) -> 6 | BM4: 5960 | BN4: =IF((BM4-BM3)<0,"0",(BM4-BM3)) -> 9 | BO4: 33434 | BP4: =IF((BO4-BO3)<0,"0",(BO4-BO3)) -> 63 | BQ4: 3641 | BR4: =IF((BQ4-BQ3)<0,"0",(BQ4-BQ3)) -> 0 | BS4: =BH4+BF4+BB4 -> 26 | BT4: =AR4-BS4 -> 204 | BU4: 660720 | BV4: =IF((BU4-BU3)<0,"0",(BU4-BU3)) -> 190 | BX4: =IF((BW4-BW3)<0,"0",(BW4-BW3)) -> 0 | BY4: 854250 | BZ4: =IF((BY4-BY3)<0,"0",(BY4-BY3)) -> 0 | CA4: 28725 | CB4: =IF((CA4-CA3)<0,"0",(CA4-CA3)) -> 29 | CC4: =BZ4-AR4 -> -230 | CD4: =SUM(BV4, BZ4) -> 190 | CE4: =SUM(AV4,AX4,AZ4,BB4,BD4,BF4,BH4,BJ4,BN4) -> 63 | CF4: 152 | CG4: =(IF(CF4<=116.4,((116.4*116.4*ACOS((116.4-CF4)/116.4))-((116.4-CF4)*SQRT(2*116.4*CF4-CF4*CF4)))*669.8,((3.1416*116.4*116.4)-((116.4*116.4*ACOS((116.4-(2*116.4-CF4))/116.4))-((116.4-(2*116.4-CF4))*SQRT(2*116.4*(2*116.4-CF4)-((2*116.4-CF4)*(2*116.4-CF4))))))*669.8))/1000 -> 19718.481 | CI4: =CG3-CG4+CH4 -> 0 | CJ4: 2697143 | CK4: =IF((CJ4-CJ3)<0,"0",(CJ4-CJ3)) -> 2960 | CL4: =CK4*5.71 -> 16901.6 | CM4: 59 | CO4: 60 | CP4: =(CO4*10775)/100 -> 6465 | CQ4: 60 | CR4: =(CQ4*10775)/100 -> 6465 | CS4: =CN4+CP4+CR4 -> 12930 | CT4: =IF((CS3-CS4+CU3)=CS3,"0",(CS3-CS4+CU3)) -> 7973.5 | CV4: 46893 | CW4: =IF((CV4-CV3)<0,"0",(CV4-CV3)) -> 38 | CX4: =CW4*5.71 -> 216.98 | CY4: 35995 | CZ4: =IF((CY4-CY3)<0,"0",(CY4-CY3)) -> 8 | DA4: =CZ4*5.71 -> 45.68 | DB4: 15328 | DC4: =IF((DB4-DB3)<0,"0",(DB4-DB3)) -> 16 | DD4: =DC4*5.71 -> 91.36 | DE4: 856017 | DF4: =IF((DE4-DE3)<0,"0",(DE4-DE3)) -> 131 | DG4: =DF4*5.71 -> 748.01 | DH4: 11385 | DI4: =IF((DH4-DH3)<0,"0",(DH4-DH3)) -> 16 | DJ4: =DI4*5.71 -> 91.36 | DK4: 10890 | DL4: =IF((DK4-DK3)<0,"0",(DK4-DK3)) -> 11 | DM4: =DL4*5.71 -> 62.81 | DN4: 6645 | DO4: =IF((DN4-DN3)<0,"0",(DN4-DN3)) -> 9 | DP4: =DO4*5.71 -> 51.39 | DQ4: 2310 | DR4: =IF((DQ4-DQ3)<0,"0",(DQ4-DQ3)) -> 1 | DS4: =DR4*5.71 -> 5.71 | DT4: 8098 | DU4: =IF((DT4-DT3)<0,"0",(DT4-DT3)) -> 14 | DV4: =DU4*5.71 -> 79.94 | DW4: 7492 | DX4: =IF((DW4-DW3)<0,"0",(DW4-DW3)) -> 10 | DY4: =DX4*5.71 -> 57.1 | DZ4: 8082 | EA4: =IF((DZ4-DZ3)<0,"0",(DZ4-DZ3)) -> 10 | EB4: =EA4*5.71 -> 57.1 | EC4: 8000 | ED4: =IF((EC4-EC3)<0,"0",(EC4-EC3)) -> 5 | EE4: =ED4*5.71 -> 28.55 | EG4: =(EF4-EF3) -> 0 | EI4: =(EH4-EH3) -> 0 | EK4: =(EJ4-EJ3) -> 0 | EM4: =(EL4-EL3) -> 0 | EN4: 100 | EO4: 271 | EP4: 0.748
A5: 44775 | B5: 4992194 | C5: =IF((B5-B4)<0,"0",(B5-B4)) -> 22549 | D5: 3930883 | E5: =IF((D5-D4)<0,"0",(D5-D4)) -> 21797 | F5: =E5/C5 -> 0.96665041 | G5: 1070 | H5: 1110 | I5: 292000 | J5: =IF((I5-I4)<0,"0",(I5-I4)) -> 0 | K5: 803 | L5: =IF((K5-K4)<0,"0",(K5-K4)) -> 0 | M5: 644837 | N5: =IF((M5-M4)<0,"0",(M5-M4)) -> 30 | O5: 1033 | P5: =IF((O5-O4)<0,"0",(O5-O4)) -> 0 | Q5: 3478700 | R5: =IF((Q5-Q4)<0,"0",(Q5-Q4)) -> 12400 | S5: 3369300 | T5: =IF((S5-S4)<0,"0",(S5-S4)) -> 3000 | U5: 2996415 | V5: =IF((U5-U4)<0,"0",(U5-U4)) -> 1061 | W5: 2328316 | X5: =IF((W5-W4)<0,"0",(W5-W4)) -> 536 | Y5: 320108 | Z5: =Y5-Y4 -> 269 | AB5: =6.75/9 -> 0.75 | AC5: =AB5*400 -> 300 | AE5: 1340 | AF5: =IF((AE5-AE4)<0,"0",(AE5-AE4)) -> 0 | AG5: 550770 | AH5: =IF((AG5-AG4)<0,"0",(AG5-AG4)) -> 470 | AI5: 1180 | AJ5: =IF((AI5-AI4)<0,"0",(AI5-AI4)) -> 0 | AK5: 6030 | AL5: =IF((AK5-AK4)<0,"0",(AK5-AK4)) -> 0 | AM5: 58997 | AN5: =IF((AM5-AM4)<0,"0",(AM5-AM4)) -> 339 | AP5: =IF((AO5-AO4)<0,"0",(AO5-AO4)) -> 0 | AQ5: 641220 | AR5: =IF((AQ5-AQ4)<0,"0",(AQ5-AQ4)) -> 180 | AS5: 5240 | AT5: =IF((AS5-AS4)<0,"0",(AS5-AS4)) -> 35 | AU5: 58055 | AV5: =IF((AU5-AU4)<0,"0",(AU5-AU4)) -> 25 | AW5: 9449 | AX5: =IF((AW5-AW4)<0,"0",(AW5-AW4)) -> 1 | AY5: 11194 | AZ5: =IF((AY5-AY4)<0,"0",(AY5-AY4)) -> 3 | BA5: 19939 | BB5: =IF((BA5-BA4)<0,"0",(BA5-BA4)) -> 18 | BC5: 21385 | BD5: =IF((BC5-BC4)<0,"0",(BC5-BC4)) -> 15 | BE5: 21347 | BF5: =IF((BE5-BE4)<0,"0",(BE5-BE4)) -> 1 | BG5: 14711 | BH5: =IF((BG5-BG4)<0,"0",(BG5-BG4)) -> 5 | BI5: 6839 | BJ5: =IF((BI5-BI4)<0,"0",(BI5-BI4)) -> 2 | BK5: 28302 | BL5: =IF((BK5-BK4)<0,"0",(BK5-BK4)) -> 4 | BM5: 5967 | BN5: =IF((BM5-BM4)<0,"0",(BM5-BM4)) -> 7 | BO5: 33502 | BP5: =IF((BO5-BO4)<0,"0",(BO5-BO4)) -> 68 | BQ5: 3641 | BR5: =IF((BQ5-BQ4)<0,"0",(BQ5-BQ4)) -> 0 | BS5: =BH5+BF5+BB5 -> 24 | BT5: =AR5-BS5 -> 156 | BU5: 660920 | BV5: =IF((BU5-BU4)<0,"0",(BU5-BU4)) -> 200 | BX5: =IF((BW5-BW4)<0,"0",(BW5-BW4)) -> 0 | BY5: 854250 | BZ5: =IF((BY5-BY4)<0,"0",(BY5-BY4)) -> 0 | CA5: 28748 | CB5: =IF((CA5-CA4)<0,"0",(CA5-CA4)) -> 23 | CC5: =BZ5-AR5 -> -180 | CD5: =SUM(BV5, BZ5) -> 200 | CE5: =SUM(AV5,AX5,AZ5,BB5,BD5,BF5,BH5,BJ5,BN5) -> 77 | CF5: 152 | CG5: =(IF(CF5<=116.4,((116.4*116.4*ACOS((116.4-CF5)/116.4))-((116.4-CF5)*SQRT(2*116.4*CF5-CF5*CF5)))*669.8,((3.1416*116.4*116.4)-((116.4*116.4*ACOS((116.4-(2*116.4-CF5))/116.4))-((116.4-(2*116.4-CF5))*SQRT(2*116.4*(2*116.4-CF5)-((2*116.4-CF5)*(2*116.4-CF5))))))*669.8))/1000 -> 19718.481 | CI5: =CG4-CG5+CH5 -> 0 | CJ5: 2700335 | CK5: =IF((CJ5-CJ4)<0,"0",(CJ5-CJ4)) -> 3192 | CL5: =CK5*5.71 -> 18226.32 | CM5: 55 | CN5: =(CM5*10775)/100 -> 5926.25 | CO5: 55 | CP5: =(CO5*10775)/100 -> 5926.25 | CQ5: 55 | CR5: =(CQ5*10775)/100 -> 5926.25 | CS5: =CN5+CP5+CR5 -> 17778.75 | CT5: =IF((CS4-CS5+CU4)=CS4,"0",(CS4-CS5+CU4)) -> -4848.75 | CV5: 46936 | CW5: =IF((CV5-CV4)<0,"0",(CV5-CV4)) -> 43 | CX5: =CW5*5.71 -> 245.53 | CY5: 36003 | CZ5: =IF((CY5-CY4)<0,"0",(CY5-CY4)) -> 8 | DA5: =CZ5*5.71 -> 45.68 | DB5: 15346 | DC5: =IF((DB5-DB4)<0,"0",(DB5-DB4)) -> 18 | DD5: =DC5*5.71 -> 102.78 | DE5: 856145 | DF5: =IF((DE5-DE4)<0,"0",(DE5-DE4)) -> 128 | DG5: =DF5*5.71 -> 730.88 | DH5: 11403 | DI5: =IF((DH5-DH4)<0,"0",(DH5-DH4)) -> 18 | DJ5: =DI5*5.71 -> 102.78 | DK5: 10904 | DL5: =IF((DK5-DK4)<0,"0",(DK5-DK4)) -> 14 | DM5: =DL5*5.71 -> 79.94 | DN5: 6655 | DO5: =IF((DN5-DN4)<0,"0",(DN5-DN4)) -> 10 | DP5: =DO5*5.71 -> 57.1 | DQ5: 2312 | DR5: =IF((DQ5-DQ4)<0,"0",(DQ5-DQ4)) -> 2 | DS5: =DR5*5.71 -> 11.42 | DT5: 8115 | DU5: =IF((DT5-DT4)<0,"0",(DT5-DT4)) -> 17 | DV5: =DU5*5.71 -> 97.07 | DW5: 7503 | DX5: =IF((DW5-DW4)<0,"0",(DW5-DW4)) -> 11 | DY5: =DX5*5.71 -> 62.81 | DZ5: 8092 | EA5: =IF((DZ5-DZ4)<0,"0",(DZ5-DZ4)) -> 10 | EB5: =EA5*5.71 -> 57.1 | EC5: 8019 | ED5: =IF((EC5-EC4)<0,"0",(EC5-EC4)) -> 19 | EE5: =ED5*5.71 -> 108.49 | EG5: =(EF5-EF4) -> 0 | EI5: =(EH5-EH4) -> 0 | EK5: =(EJ5-EJ4) -> 0 | EM5: =(EL5-EL4) -> 0 | EN5: 105 | EO5: 332 | EP5: 0.791
A6: 44776 | B6: 5016428 | C6: =IF((B6-B5)<0,"0",(B6-B5)) -> 24234 | D6: 3954367 | E6: =IF((D6-D5)<0,"0",(D6-D5)) -> 23484 | F6: =E6/C6 -> 0.96905175 | G6: 1070 | H6: 1110 | I6: 292000 | J6: =IF((I6-I5)<0,"0",(I6-I5)) -> 0 | K6: 803 | L6: =IF((K6-K5)<0,"0",(K6-K5)) -> 0 | M6: 644837 | N6: =IF((M6-M5)<0,"0",(M6-M5)) -> 0 | O6: 1033 | P6: =IF((O6-O5)<0,"0",(O6-O5)) -> 0 | R6: =IF((Q6-Q5)<0,"0",(Q6-Q5)) -> 0 | T6: =IF((S6-S5)<0,"0",(S6-S5)) -> 0 | U6: 2998031 | V6: =IF((U6-U5)<0,"0",(U6-U5)) -> 1616 | W6: 2328838 | X6: =IF((W6-W5)<0,"0",(W6-W5)) -> 522 | Y6: 320384 | Z6: =Y6-Y5 -> 276 | AB6: =5.5/9 -> 0.61111111 | AC6: =AB6*400 -> 244.44444 | AE6: 1340 | AF6: =IF((AE6-AE5)<0,"0",(AE6-AE5)) -> 0 | AG6: 551240 | AH6: =IF((AG6-AG5)<0,"0",(AG6-AG5)) -> 470 | AJ6: =IF((AI6-AI5)<0,"0",(AI6-AI5)) -> 0 | AK6: 6033 | AL6: =IF((AK6-AK5)<0,"0",(AK6-AK5)) -> 3 | AM6: 59372 | AN6: =IF((AM6-AM5)<0,"0",(AM6-AM5)) -> 375 | AP6: =IF((AO6-AO5)<0,"0",(AO6-AO5)) -> 0 | AQ6: 641450 | AR6: =IF((AQ6-AQ5)<0,"0",(AQ6-AQ5)) -> 230 | AS6: 5272 | AT6: =IF((AS6-AS5)<0,"0",(AS6-AS5)) -> 32 | AU6: 58075 | AV6: =IF((AU6-AU5)<0,"0",(AU6-AU5)) -> 20 | AW6: 9451 | AX6: =IF((AW6-AW5)<0,"0",(AW6-AW5)) -> 2 | AY6: 11197 | AZ6: =IF((AY6-AY5)<0,"0",(AY6-AY5)) -> 3 | BA6: 19950 | BB6: =IF((BA6-BA5)<0,"0",(BA6-BA5)) -> 11 | BC6: 21393 | BD6: =IF((BC6-BC5)<0,"0",(BC6-BC5)) -> 8 | BE6: 21348 | BF6: =IF((BE6-BE5)<0,"0",(BE6-BE5)) -> 1 | BG6: 14718 | BH6: =IF((BG6-BG5)<0,"0",(BG6-BG5)) -> 7 | BI6: 6844 | BJ6: =IF((BI6-BI5)<0,"0",(BI6-BI5)) -> 5 | BK6: 28309 | BL6: =IF((BK6-BK5)<0,"0",(BK6-BK5)) -> 7 | BM6: 5979 | BN6: =IF((BM6-BM5)<0,"0",(BM6-BM5)) -> 12 | BO6: 33579 | BP6: =IF((BO6-BO5)<0,"0",(BO6-BO5)) -> 77 | BQ6: 3641 | BR6: =IF((BQ6-BQ5)<0,"0",(BQ6-BQ5)) -> 0 | BS6: =BH6+BF6+BB6 -> 19 | BT6: =AR6-BS6 -> 211 | BU6: 661100 | BV6: =IF((BU6-BU5)<0,"0",(BU6-BU5)) -> 180 | BX6: =IF((BW6-BW5)<0,"0",(BW6-BW5)) -> 0 | BY6: 854250 | BZ6: =IF((BY6-BY5)<0,"0",(BY6-BY5)) -> 0 | CA6: 28786 | CB6: =IF((CA6-CA5)<0,"0",(CA6-CA5)) -> 38 | CC6: =BZ6-AR6 -> -230 | CD6: =SUM(BV6, BZ6) -> 180 | CE6: =SUM(AV6,AX6,AZ6,BB6,BD6,BF6,BH6,BJ6,BN6) -> 69 | CF6: 152 | CG6: =(IF(CF6<=116.4,((116.4*116.4*ACOS((116.4-CF6)/116.4))-((116.4-CF6)*SQRT(2*116.4*CF6-CF6*CF6)))*669.8,((3.1416*116.4*116.4)-((116.4*116.4*ACOS((116.4-(2*116.4-CF6))/116.4))-((116.4-(2*116.4-CF6))*SQRT(2*116.4*(2*116.4-CF6)-((2*116.4-CF6)*(2*116.4-CF6))))))*669.8))/1000 -> 19718.481 | CI6: =CG5-CG6+CH6 -> 0 | CJ6: 2704260 | CK6: =IF((CJ6-CJ5)<0,"0",(CJ6-CJ5)) -> 3925 | CL6: =CK6*5.71 -> 22411.75 | CM6: 48 | CN6: =(CM6*10775)/100 -> 5172 | CO6: 50 | CP6: =(CO6*10775)/100 -> 5387.5 | CQ6: 48 | CR6: =(CQ6*10775)/100 -> 5172 | CS6: =CN6+CP6+CR6 -> 15731.5 | CT6: =IF((CS5-CS6+CU5)=CS5,"0",(CS5-CS6+CU5)) -> 2047.25 | CV6: 46983 | CW6: =IF((CV6-CV5)<0,"0",(CV6-CV5)) -> 47 | CX6: =CW6*5.71 -> 268.37 | CY6: 36012 | CZ6: =IF((CY6-CY5)<0,"0",(CY6-CY5)) -> 9 | DA6: =CZ6*5.71 -> 51.39 | DB6: 15363 | DC6: =IF((DB6-DB5)<0,"0",(DB6-DB5)) -> 17 | DD6: =DC6*5.71 -> 97.07 | DE6: 856335 | DF6: =IF((DE6-DE5)<0,"0",(DE6-DE5)) -> 190 | DG6: =DF6*5.71 -> 1084.9 | DH6: 11421 | DI6: =IF((DH6-DH5)<0,"0",(DH6-DH5)) -> 18 | DJ6: =DI6*5.71 -> 102.78 | DK6: 10919 | DL6: =IF((DK6-DK5)<0,"0",(DK6-DK5)) -> 15 | DM6: =DL6*5.71 -> 85.65 | DN6: 6668 | DO6: =IF((DN6-DN5)<0,"0",(DN6-DN5)) -> 13 | DP6: =DO6*5.71 -> 74.23 | DQ6: 2314 | DR6: =IF((DQ6-DQ5)<0,"0",(DQ6-DQ5)) -> 2 | DS6: =DR6*5.71 -> 11.42 | DT6: 8134 | DU6: =IF((DT6-DT5)<0,"0",(DT6-DT5)) -> 19 | DV6: =DU6*5.71 -> 108.49 | DW6: 7516 | DX6: =IF((DW6-DW5)<0,"0",(DW6-DW5)) -> 13 | DY6: =DX6*5.71 -> 74.23 | DZ6: 8105 | EA6: =IF((DZ6-DZ5)<0,"0",(DZ6-DZ5)) -> 13 | EB6: =EA6*5.71 -> 74.23 | EC6: 8036 | ED6: =IF((EC6-EC5)<0,"0",(EC6-EC5)) -> 17 | EE6: =ED6*5.71 -> 97.07 | EG6: =(EF6-EF5) -> 0 | EI6: =(EH6-EH5) -> 0 | EK6: =(EJ6-EJ5) -> 0 | EM6: =(EL6-EL5) -> 0 | EP6: 0.74
