Workbook

Sheet Total
A1: Site Name | B1: Day | C1: Month | D1: Year | E1: Total Electricity Kwh | F1: Electricity Tariff ($/Kwh) | G1: Natual Gas (m3) | H1: Natural Gas $/m3 | I1: Water Utility Supply (m3) m3 | J1: Water Utility Supply (m3) $/m3 | K1: Room Nights
A2: Cairo at The First Residence | B2: 1 | C2: 7 | D2: 2022 | E2: =Elect!BS6 -> 35119.362 | F2: ='Utility Consnsumption'!K13/'Utility Consnsumption'!J13 -> 1.3205473 | G2: =Gas!K7 -> 119.30291 | H2: 3.8 | I2: =Water!H7 -> 126.92961 | J2: 10 | K2: =Elect!BT6 -> 157
A3: Cairo at The First Residence | B3: =B2+1 -> 2 | C3: 7 | D3: 2022 | E3: =Elect!BS7 -> 33642.818 | F3: =F2 -> 1.3205473 | G3: =Gas!K8 -> 119.30291 | H3: 3.8 | I3: =Water!H8 -> 177.48 | J3: 10 | K3: =Elect!BT7 -> 135
A4: Cairo at The First Residence | B4: =B3+1 -> 3 | C4: 7 | D4: 2022 | E4: =Elect!BS8 -> 35136.58 | F4: =F3 -> 1.3205473 | G4: =Gas!K9 -> 94.897091 | H4: 3.8 | I4: =Water!H9 -> 344.52 | J4: 10 | K4: =Elect!BT8 -> 120
A5: Cairo at The First Residence | B5: =B4+1 -> 4 | C5: 7 | D5: 2022 | E5: =Elect!BS9 -> 32062.253 | F5: =F4 -> 1.3205473 | G5: =Gas!K10 -> 242.9 | H5: 3.8 | I5: =Water!H10 -> 416.44 | J5: 10 | K5: =Elect!BT9 -> 121
A6: Cairo at The First Residence | B6: =B5+1 -> 5 | C6: 7 | D6: 2022 | E6: =Elect!BS10 -> 37272.765 | F6: =F5 -> 1.3205473 | G6: =Gas!K11 -> 291.2 | H6: 3.8 | I6: =Water!H11 -> 383.96 | J6: 10 | K6: =Elect!BT10 -> 130
A7: Cairo at The First Residence | B7: =B6+1 -> 6 | C7: 7 | D7: 2022 | E7: =Elect!BS11 -> 33558.75 | F7: =F6 -> 1.3205473 | G7: =Gas!K12 -> 288.4 | H7: 3.8 | I7: =Water!H12 -> 377 | J7: 10 | K7: =Elect!BT11 -> 129
A8: Cairo at The First Residence | B8: =B7+1 -> 7 | C8: 7 | D8: 2022 | E8: =Elect!BS12 -> 33436.022 | F8: =F7 -> 1.3205473 | G8: =Gas!K13 -> 263.9 | H8: 3.8 | I8: =Water!H13 -> 388.6 | J8: 10 | K8: =Elect!BT12 -> 137
A9: Cairo at The First Residence | B9: =B8+1 -> 8 | C9: 7 | D9: 2022 | E9: =Elect!BS13 -> 33550.25 | F9: =F8 -> 1.3205473 | G9: =Gas!K14 -> 273.7 | H9: 3.8 | I9: =Water!H14 -> 359.6 | J9: 10 | K9: =Elect!BT13 -> 145
A10: Cairo at The First Residence | B10: =B9+1 -> 9 | C10: 7 | D10: 2022 | E10: =Elect!BS14 -> 33561.74 | F10: =F9 -> 1.3205473 | G10: =Gas!K15 -> 266.7 | H10: 3.8 | I10: =Water!H15 -> 365.98 | J10: 10 | K10: =Elect!BT14 -> 168
A11: Cairo at The First Residence | B11: =B10+1 -> 10 | C11: 7 | D11: 2022 | E11: =Elect!BS15 -> 35282.45 | F11: =F10 -> 1.3205473 | G11: =Gas!K16 -> 284.2 | H11: 3.8 | I11: =Water!H16 -> 342.2 | J11: 10 | K11: =Elect!BT15 -> 177
A12: Cairo at The First Residence | B12: =B11+1 -> 11 | C12: 7 | D12: 2022 | E12: =Elect!BS16 -> 30620.185 | F12: =F11 -> 1.3205473 | G12: =Gas!K17 -> 263.2 | H12: 3.8 | I12: =Water!H17 -> 382.8 | J12: 10 | K12: =Elect!BT16 -> 177
A13: Cairo at The First Residence | B13: =B12+1 -> 12 | C13: 7 | D13: 2022 | E13: =Elect!BS17 -> 34742.95 | F13: =F12 -> 1.3205473 | G13: =Gas!K18 -> 266.7 | H13: 3.8 | I13: =Water!H18 -> 394.4 | J13: 10 | K13: =Elect!BT17 -> 204
A14: Cairo at The First Residence | B14: =B13+1 -> 13 | C14: 7 | D14: 2022 | E14: =Elect!BS18 -> 35532.478 | F14: =F13 -> 1.3205473 | G14: =Gas!K19 -> 266 | H14: 3.8 | I14: =Water!H19 -> 353.8 | J14: 10 | K14: =Elect!BT18 -> 182
... A32: Cairo at The First Residence | B32: =B31+1 -> 31 | C32: 7 | D32: 2022 | E32: =Elect!BS36 -> 33084.919 | F32: =F31 -> 1.3205473 | G32: =Gas!K37 -> 288.54 | H32: 3.8 | I32: =Water!H37 -> 422.82 | J32: 10 | K32: =Elect!BT36 -> 198

Sheet Submetering
A1: Site Name | B1: Day | C1: Month | D1: Year | E1: Electricity | F1: Main Feeder -KWh | G1: T2+T8 -KWh | H1: La Gourmandize -KWh | I1: Casino 3rd floor EM -KWh | J1: Casino 3rd floor Normal -KWh | K1: Chiller 1 -KWh | L1: Chiller 2 -KWh | M1: Chiller 3 -KWh | N1: Chiller 4 -KWh | O1: Chiller 5 -KWh | P1: Chiller 6 -KWh | Q1: Cooling towers -KWh | R1: Chiller Pumps -KWh | S1: Cooling Tower Pumps -KWh | T1: Fiber Chiller -KWh | U1: Mall Ceiling light -KWh | V1: LG Bakery -KWh | W1: LG Bakery light ( Old lockers ) -KWh | X1: MCCR1 -KWh | Y1: Children Swimming Pool -KWh | Z1: DPH1 -KWh | AA1: Guest Rooms Emerg. -KWh | AB1: Hotel Hoods -KWh | AC1: Main G2 -KWh | AD1: Old Casino Emergency -KWh | AE1: L / A -KWh | AF1: L / B -KWh | AG1: L / C -KWh | AH1: Water | AI1: Main water meter 1 -m3 | AJ1: Main water meter 2 -m3 | AK1: Main water meter 3 -m3 | AL1: Gas | AM1: Main Gas Flow Meter -m3 | AN1: Laundry Gas Flow Meter -m3 | AO1: Gourmandize Gas Flow Meter -m3 | AP1: Room Nights
A2: Cairo at The First Residence | B2: 1 | C2: 7 | D2: 2022 | F2: =Elect!J6 -> 6310 | G2: =Elect!K6 -> 0 | H2: =Elect!Q6 -> 540 | I2: =Elect!S6 -> 147 | J2: =Elect!U6 -> 239 | K2: =Elect!W6 -> 4492.81 | L2: =Elect!Y6 -> 0 | M2: =Elect!AA6 -> 986.33 | N2: =Elect!AC6 -> 3075.06 | O2: =Elect!AE6 -> 11.13 | P2: =Elect!AG6 -> 1513.15 | Q2: =Elect!AI6 -> 1156.46 | R2: =Elect!AK6 -> 3623.61 | S2: =Elect!AM6 -> 108.65 | T2: =Elect!AP6 -> 338.5125 | U2: =Elect!AR6 -> 148 | V2: =Elect!AT6 -> 208 | W2: =Elect!AV6 -> 62 | X2: =Elect!AX6 -> 974 | Y2: =Elect!AZ6 -> 0 | Z2: =Elect!BB6 -> 4988 | AA2: =Elect!BD6 -> 103 | AB2: =Elect!BF6 -> 38 | AC2: =Elect!BH6 -> 6442.65 | AD2: =Elect!BL6 -> 299 | AE2: =Elect!BN6 -> 1507 | AF2: =Elect!BP6 -> 116 | AG2: =Elect!BR6 -> 147 | AI2: =Water!C7 -> 16.61361 | AJ2: =Water!E7 -> 0 | AK2: =Water!G7 -> 110.316 | AM2: =Gas!C7 -> 0 | AN2: =Gas!E7 -> 119.30291 | AO2: =Gas!G7 -> 121.50606 | AP2: =Elect!BT6 -> 157
A3: Cairo at The First Residence | B3: =B2+1 -> 2 | C3: 7 | D3: 2022 | F3: =Elect!J7 -> 5360 | G3: =Elect!K7 -> 2615.0214 | H3: =Elect!Q7 -> 480 | I3: =Elect!S7 -> 174 | J3: =Elect!U7 -> 273 | K3: =Elect!W7 -> 1750.06 | L3: =Elect!Y7 -> 1941.92 | M3: =Elect!AA7 -> 242.74 | N3: =Elect!AC7 -> 3785.26 | O3: =Elect!AE7 -> 11.13 | P3: =Elect!AG7 -> 1636.64 | Q3: =Elect!AI7 -> 1173.42 | R3: =Elect!AK7 -> 3756.11 | S3: =Elect!AM7 -> 113.95 | T3: =Elect!AP7 -> 276.6375 | U3: =Elect!AR7 -> 155 | V3: =Elect!AT7 -> 194 | W3: =Elect!AV7 -> 54 | X3: =Elect!AX7 -> 1113 | Y3: =Elect!AZ7 -> 0 | Z3: =Elect!BB7 -> 5052 | AA3: =Elect!BD7 -> 179 | AB3: =Elect!BF7 -> 70 | AC3: =Elect!BH7 -> 6297.95 | AD3: =Elect!BL7 -> 274 | AE3: =Elect!BN7 -> 1452 | AF3: =Elect!BP7 -> 117 | AG3: =Elect!BR7 -> 188 | AI3: =Water!C8 -> 46.4 | AJ3: =Water!E8 -> 46.4 | AK3: =Water!G8 -> 84.68 | AM3: =Gas!C8 -> 0 | AN3: =Gas!E8 -> 119.30291 | AO3: =Gas!G8 -> 121.50606 | AP3: =Elect!BT7 -> 135
A4: Cairo at The First Residence | B4: =B3+1 -> 3 | C4: 7 | D4: 2022 | F4: =Elect!J8 -> 5499 | G4: =Elect!K8 -> 2346.0214 | H4: =Elect!Q8 -> 570 | I4: =Elect!S8 -> 231 | J4: =Elect!U8 -> 256 | K4: =Elect!W8 -> 236.91 | L4: =Elect!Y8 -> 1199.92 | M4: =Elect!AA8 -> 4046.02 | N4: =Elect!AC8 -> 2585.87 | O4: =Elect!AE8 -> 216.77 | P4: =Elect!AG8 -> 1527.46 | Q4: =Elect!AI8 -> 1199.39 | R4: =Elect!AK8 -> 3839.32 | S4: =Elect!AM8 -> 113.42 | T4: =Elect!AP8 -> 254.25 | U4: =Elect!AR8 -> 181 | V4: =Elect!AT8 -> 196 | W4: =Elect!AV8 -> 67 | X4: =Elect!AX8 -> 1082 | Y4: =Elect!AZ8 -> 0 | Z4: =Elect!BB8 -> 5597 | AA4: =Elect!BD8 -> 202 | AB4: =Elect!BF8 -> 69 | AC4: =Elect!BH8 -> 6454.25 | AD4: =Elect!BL8 -> 283 | AE4: =Elect!BN8 -> 1519 | AF4: =Elect!BP8 -> 116 | AG4: =Elect!BR8 -> 177 | AI4: =Water!C9 -> 127.6 | AJ4: =Water!E9 -> 104.4 | AK4: =Water!G9 -> 112.52 | AM4: =Gas!C9 -> 0 | AN4: =Gas!E9 -> 94.897091 | AO4: =Gas!G9 -> 45.493939 | AP4: =Elect!BT8 -> 120
A5: Cairo at The First Residence | B5: =B4+1 -> 4 | C5: 7 | D5: 2022 | F5: =Elect!J9 -> 5457 | G5: =Elect!K9 -> 2466.0214 | H5: =Elect!Q9 -> 240 | I5: =Elect!S9 -> 227 | J5: =Elect!U9 -> 256 | K5: =Elect!W9 -> 1559.26 | L5: =Elect!Y9 -> 537.42 | M5: =Elect!AA9 -> 3944.26 | N5: =Elect!AC9 -> 251.75 | O5: =Elect!AE9 -> 1711.9 | P5: =Elect!AG9 -> 10.6 | Q5: =Elect!AI9 -> 1160.17 | R5: =Elect!AK9 -> 3727.49 | S5: =Elect!AM9 -> 107.59 | T5: =Elect!AP9 -> 264.7125 | U5: =Elect!AR9 -> 176 | V5: =Elect!AT9 -> 172 | W5: =Elect!AV9 -> 64 | X5: =Elect!AX9 -> 1003 | Y5: =Elect!AZ9 -> 0 | Z5: =Elect!BB9 -> 4952 | AA5: =Elect!BD9 -> 219 | AB5: =Elect!BF9 -> 45 | AC5: =Elect!BH9 -> 6459.1 | AD5: =Elect!BL9 -> 276 | AE5: =Elect!BN9 -> 1503 | AF5: =Elect!BP9 -> 119 | AG5: =Elect!BR9 -> 171 | AI5: =Water!C10 -> 116 | AJ5: =Water!E10 -> 179.8 | AK5: =Water!G10 -> 120.64 | AM5: =Gas!C10 -> 0 | AN5: =Gas!E10 -> 242.9 | AO5: =Gas!G10 -> 73 | AP5: =Elect!BT9 -> 121
A6: Cairo at The First Residence | B6: =B5+1 -> 5 | C6: 7 | D6: 2022 | F6: =Elect!J10 -> 5485 | G6: =Elect!K10 -> 2406.0214 | H6: =Elect!Q10 -> 750 | I6: =Elect!S10 -> 241 | J6: =Elect!U10 -> 278 | K6: =Elect!W10 -> 2982.31 | L6: =Elect!Y10 -> 2812.71 | M6: =Elect!AA10 -> 4071.46 | N6: =Elect!AC10 -> 0 | O6: =Elect!AE10 -> 1884.68 | P6: =Elect!AG10 -> 10.6 | Q6: =Elect!AI10 -> 1195.68 | R6: =Elect!AK10 -> 3810.17 | S6: =Elect!AM10 -> 111.83 | T6: =Elect!AP10 -> 278.325 | U6: =Elect!AR10 -> 179 | V6: =Elect!AT10 -> 194 | W6: =Elect!AV10 -> 66 | X6: =Elect!AX10 -> 1001 | Y6: =Elect!AZ10 -> 0 | Z6: =Elect!BB10 -> 5468 | AA6: =Elect!BD10 -> 228 | AB6: =Elect!BF10 -> 74 | AC6: =Elect!BH10 -> 6670 | AD6: =Elect!BL10 -> 291 | AE6: =Elect!BN10 -> 1512 | AF6: =Elect!BP10 -> 128 | AG6: =Elect!BR10 -> 155 | AI6: =Water!C11 -> 116 | AJ6: =Water!E11 -> 150.8 | AK6: =Water!G11 -> 117.16 | AM6: =Gas!C11 -> 0 | AN6: =Gas!E11 -> 291.2 | AO6: =Gas!G11 -> 73 | AP6: =Elect!BT10 -> 130
A7: Cairo at The First Residence | B7: =B6+1 -> 6 | C7: 7 | D7: 2022 | F7: =Elect!J11 -> 5478 | G7: =Elect!K11 -> 2385.0214 | H7: =Elect!Q11 -> 450 | I7: =Elect!S11 -> 224 | J7: =Elect!U11 -> 253 | K7: =Elect!W11 -> 3230.35 | L7: =Elect!Y11 -> 0 | M7: =Elect!AA11 -> 4011.57 | N7: =Elect!AC11 -> 0 | O7: =Elect!AE11 -> 1574.63 | P7: =Elect!AG11 -> 9.54 | Q7: =Elect!AI11 -> 1180.84 | R7: =Elect!AK11 -> 3745.51 | S7: =Elect!AM11 -> 112.36 | T7: =Elect!AP11 -> 279.9 | U7: =Elect!AR11 -> 168 | V7: =Elect!AT11 -> 193 | W7: =Elect!AV11 -> 65 | X7: =Elect!AX11 -> 999 | Y7: =Elect!AZ11 -> 0 | Z7: =Elect!BB11 -> 5227 | AA7: =Elect!BD11 -> 218 | AB7: =Elect!BF11 -> 50 | AC7: =Elect!BH11 -> 6566.05 | AD7: =Elect!BL11 -> 273 | AE7: =Elect!BN11 -> 1511 | AF7: =Elect!BP11 -> 120 | AG7: =Elect!BR11 -> 144 | AI7: =Water!C12 -> 116 | AJ7: =Water!E12 -> 150.8 | AK7: =Water!G12 -> 110.2 | AM7: =Gas!C12 -> 0 | AN7: =Gas!E12 -> 288.4 | AO7: =Gas!G12 -> 77 | AP7: =Elect!BT11 -> 129
A8: Cairo at The First Residence | B8: =B7+1 -> 7 | C8: 7 | D8: 2022 | F8: =Elect!J12 -> 5478 | G8: =Elect!K12 -> 2352.0214 | H8: =Elect!Q12 -> 540 | I8: =Elect!S12 -> 232 | J8: =Elect!U12 -> 246 | K8: =Elect!W12 -> 1336.13 | L8: =Elect!Y12 -> 933.33 | M8: =Elect!AA12 -> 3918.29 | N8: =Elect!AC12 -> 746.24 | O8: =Elect!AE12 -> 1165.47 | P8: =Elect!AG12 -> 339.2 | Q8: =Elect!AI12 -> 1160.7 | R8: =Elect!AK12 -> 3741.27 | S8: =Elect!AM12 -> 109.18 | T8: =Elect!AP12 -> 241.7625 | U8: =Elect!AR12 -> 218 | V8: =Elect!AT12 -> 201 | W8: =Elect!AV12 -> 58 | X8: =Elect!AX12 -> 987 | Y8: =Elect!AZ12 -> 0 | Z8: =Elect!BB12 -> 5441 | AA8: =Elect!BD12 -> 257 | AB8: =Elect!BF12 -> 65 | AC8: =Elect!BH12 -> 6499.45 | AD8: =Elect!BL12 -> 259 | AE8: =Elect!BN12 -> 1500 | AF8: =Elect!BP12 -> 119 | AG8: =Elect!BR12 -> 143 | AI8: =Water!C13 -> 116 | AJ8: =Water!E13 -> 150.8 | AK8: =Water!G13 -> 121.8 | AM8: =Gas!C13 -> 0 | AN8: =Gas!E13 -> 263.9 | AO8: =Gas!G13 -> 127 | AP8: =Elect!BT12 -> 137
A9: Cairo at The First Residence | B9: =B8+1 -> 8 | C9: 7 | D9: 2022 | F9: =Elect!J13 -> 5087 | G9: =Elect!K13 -> 2491.0214 | H9: =Elect!Q13 -> 360 | I9: =Elect!S13 -> 229 | J9: =Elect!U13 -> 239 | K9: =Elect!W13 -> 0 | L9: =Elect!Y13 -> 3746.57 | M9: =Elect!AA13 -> 4048.67 | N9: =Elect!AC13 -> 0 | O9: =Elect!AE13 -> 1729.39 | P9: =Elect!AG13 -> 11.66 | Q9: =Elect!AI13 -> 1173.95 | R9: =Elect!AK13 -> 3791.09 | S9: =Elect!AM13 -> 105.47 | T9: =Elect!AP13 -> 247.95 | U9: =Elect!AR13 -> 233 | V9: =Elect!AT13 -> 164 | W9: =Elect!AV13 -> 53 | X9: =Elect!AX13 -> 973 | Y9: =Elect!AZ13 -> 0 | Z9: =Elect!BB13 -> 5216 | AA9: =Elect!BD13 -> 269 | AB9: =Elect!BF13 -> 65 | AC9: =Elect!BH13 -> 6275.5 | AD9: =Elect!BL13 -> 275 | AE9: =Elect!BN13 -> 1402 | AF9: =Elect!BP13 -> 108 | AG9: =Elect!BR13 -> 156 | AI9: =Water!C14 -> 104.4 | AJ9: =Water!E14 -> 139.2 | AK9: =Water!G14 -> 116 | AM9: =Gas!C14 -> 0 | AN9: =Gas!E14 -> 273.7 | AO9: =Gas!G14 -> 49 | AP9: =Elect!BT13 -> 145
A10: Cairo at The First Residence | B10: =B9+1 -> 9 | C10: 7 | D10: 2022 | F10: =Elect!J14 -> 5222 | G10: =Elect!K14 -> 3660.0214 | H10: =Elect!Q14 -> 600 | I10: =Elect!S14 -> 227 | J10: =Elect!U14 -> 237 | K10: =Elect!W14 -> 0 | L10: =Elect!Y14 -> 3683.5 | M10: =Elect!AA14 -> 3998.85 | N10: =Elect!AC14 -> 0 | O10: =Elect!AE14 -> 1515.27 | P10: =Elect!AG14 -> 9.54 | Q10: =Elect!AI14 -> 1164.94 | R10: =Elect!AK14 -> 3769.36 | S10: =Elect!AM14 -> 103.88 | T10: =Elect!AP14 -> 247.95 | U10: =Elect!AR14 -> 139 | V10: =Elect!AT14 -> 208 | W10: =Elect!AV14 -> 50 | X10: =Elect!AX14 -> 976 | Y10: =Elect!AZ14 -> 0 | Z10: =Elect!BB14 -> 5216 | AA10: =Elect!BD14 -> 256 | AB10: =Elect!BF14 -> 65 | AC10: =Elect!BH14 -> 6336.45 | AD10: =Elect!BL14 -> 314 | AE10: =Elect!BN14 -> 1425 | AF10: =Elect!BP14 -> 134 | AG10: =Elect!BR14 -> 141 | AI10: =Water!C15 -> 116 | AJ10: =Water!E15 -> 150.8 | AK10: =Water!G15 -> 99.18 | AM10: =Gas!C15 -> 0 | AN10: =Gas!E15 -> 266.7 | AO10: =Gas!G15 -> 80 | AP10: =Elect!BT14 -> 168
A11: Cairo at The First Residence | B11: =B10+1 -> 10 | C11: 7 | D11: 2022 | F11: =Elect!J15 -> 5900 | G11: =Elect!K15 -> 2880.0214 | H11: =Elect!Q15 -> 300 | I11: =Elect!S15 -> 227 | J11: =Elect!U15 -> 253 | K11: =Elect!W15 -> 0 | L11: =Elect!Y15 -> 4012.63 | M11: =Elect!AA15 -> 4313.14 | N11: =Elect!AC15 -> 0 | O11: =Elect!AE15 -> 1796.7 | P11: =Elect!AG15 -> 11.66 | Q11: =Elect!AI15 -> 1270.94 | R11: =Elect!AK15 -> 4106.97 | S11: =Elect!AM15 -> 112.36 | T11: =Elect!AP15 -> 114.75 | U11: =Elect!AR15 -> 171 | V11: =Elect!AT15 -> 197 | W11: =Elect!AV15 -> 57 | X11: =Elect!AX15 -> 1046 | Y11: =Elect!AZ15 -> 0 | Z11: =Elect!BB15 -> 5670 | AA11: =Elect!BD15 -> 234 | AB11: =Elect!BF15 -> 65 | AC11: =Elect!BH15 -> 5903.3 | AD11: =Elect!BL15 -> 302 | AE11: =Elect!BN15 -> 1425 | AF11: =Elect!BP15 -> 121 | AG11: =Elect!BR15 -> 159 | AI11: =Water!C16 -> 150.8 | AJ11: =Water!E16 -> 191.4 | AK11: =Water!G16 -> 0 | AM11: =Gas!C16 -> 0 | AN11: =Gas!E16 -> 284.2 | AO11: =Gas!G16 -> 94 | AP11: =Elect!BT15 -> 177
A12: Cairo at The First Residence | B12: =B11+1 -> 11 | C12: 7 | D12: 2022 | F12: =Elect!J16 -> 4309 | G12: =Elect!K16 -> 3076.0214 | H12: =Elect!Q16 -> 600 | I12: =Elect!S16 -> 227 | J12: =Elect!U16 -> 260 | K12: =Elect!W16 -> 0 | L12: =Elect!Y16 -> 3243.07 | M12: =Elect!AA16 -> 3560.01 | N12: =Elect!AC16 -> 0 | O12: =Elect!AE16 -> 1339.31 | P12: =Elect!AG16 -> 8.48 | Q12: =Elect!AI16 -> 1053.64 | R12: =Elect!AK16 -> 3408.43 | S12: =Elect!AM16 -> 94.87 | T12: =Elect!AP16 -> 209.025 | U12: =Elect!AR16 -> 173 | V12: =Elect!AT16 -> 196 | W12: =Elect!AV16 -> 44 | X12: =Elect!AX16 -> 1046 | Y12: =Elect!AZ16 -> 0 | Z12: =Elect!BB16 -> 4940 | AA12: =Elect!BD16 -> 237 | AB12: =Elect!BF16 -> 112 | AC12: =Elect!BH16 -> 6046.35 | AD12: =Elect!BL16 -> 306 | AE12: =Elect!BN16 -> 1240 | AF12: =Elect!BP16 -> 117 | AG12: =Elect!BR16 -> 160 | AI12: =Water!C17 -> 168.2 | AJ12: =Water!E17 -> 214.6 | AK12: =Water!G17 -> 0 | AM12: =Gas!C17 -> 0 | AN12: =Gas!E17 -> 263.2 | AO12: =Gas!G17 -> 112 | AP12: =Elect!BT16 -> 177
A13: Cairo at The First Residence | B13: =B12+1 -> 12 | C13: 7 | D13: 2022 | F13: =Elect!J17 -> 5805 | G13: =Elect!K17 -> 3075.0214 | H13: =Elect!Q17 -> 600 | I13: =Elect!S17 -> 234 | J13: =Elect!U17 -> 276 | K13: =Elect!W17 -> 0 | L13: =Elect!Y17 -> 3874.3 | M13: =Elect!AA17 -> 4063.51 | N13: =Elect!AC17 -> 0 | O13: =Elect!AE17 -> 1583.64 | P13: =Elect!AG17 -> 10.6 | Q13: =Elect!AI17 -> 1211.05 | R13: =Elect!AK17 -> 3881.19 | S13: =Elect!AM17 -> 115.01 | T13: =Elect!AP17 -> 255.6 | U13: =Elect!AR17 -> 180 | V13: =Elect!AT17 -> 185 | W13: =Elect!AV17 -> 56 | X13: =Elect!AX17 -> 931 | Y13: =Elect!AZ17 -> 0 | Z13: =Elect!BB17 -> 5440 | AA13: =Elect!BD17 -> 217 | AB13: =Elect!BF17 -> 65 | AC13: =Elect!BH17 -> 6269.05 | AD13: =Elect!BL17 -> 310 | AE13: =Elect!BN17 -> 1387 | AF13: =Elect!BP17 -> 124 | AG13: =Elect!BR17 -> 144 | AI13: =Water!C18 -> 174 | AJ13: =Water!E18 -> 220.4 | AK13: =Water!G18 -> 0 | AM13: =Gas!C18 -> 0 | AN13: =Gas!E18 -> 266.7 | AO13: =Gas!G18 -> 63 | AP13: =Elect!BT17 -> 204
A14: Cairo at The First Residence | B14: =B13+1 -> 13 | C14: 7 | D14: 2022 | F14: =Elect!J18 -> 5655 | G14: =Elect!K18 -> 3076.0214 | H14: =Elect!Q18 -> 300 | I14: =Elect!S18 -> 229 | J14: =Elect!U18 -> 260 | K14: =Elect!W18 -> 2520.15 | L14: =Elect!Y18 -> 3696.22 | M14: =Elect!AA18 -> 858.6 | N14: =Elect!AC18 -> 36.57 | O14: =Elect!AE18 -> 416.05 | P14: =Elect!AG18 -> 3847.27 | Q14: =Elect!AI18 -> 1165.47 | R14: =Elect!AK18 -> 3767.24 | S14: =Elect!AM18 -> 105.47 | T14: =Elect!AP18 -> 219.9375 | U14: =Elect!AR18 -> 192 | V14: =Elect!AT18 -> 175 | W14: =Elect!AV18 -> 61 | X14: =Elect!AX18 -> 976 | Y14: =Elect!AZ18 -> 0 | Z14: =Elect!BB18 -> 5210 | AA14: =Elect!BD18 -> 199 | AB14: =Elect!BF18 -> 65 | AC14: =Elect!BH18 -> 6066.5 | AD14: =Elect!BL18 -> 306 | AE14: =Elect!BN18 -> 1469 | AF14: =Elect!BP18 -> 121 | AG14: =Elect!BR18 -> 158 | AI14: =Water!C19 -> 156.6 | AJ14: =Water!E19 -> 197.2 | AK14: =Water!G19 -> 0 | AM14: =Gas!C19 -> 0 | AN14: =Gas!E19 -> 266 | AO14: =Gas!G19 -> 73 | AP14: =Elect!BT18 -> 182
... A32: Cairo at The First Residence | B32: =B31+1 -> 31 | C32: 7 | D32: 2022 | F32: =Elect!J36 -> 5401.6667 | G32: =Elect!K36 -> 5172.6667 | H32: =Elect!Q36 -> 488 | I32: =Elect!S36 -> 138.5 | J32: =Elect!U36 -> 291.5 | K32: =Elect!W36 -> 3219.326 | L32: =Elect!Y36 -> 0 | M32: =Elect!AA36 -> 0 | N32: =Elect!AC36 -> 3745.775 | O32: =Elect!AE36 -> 1556.08 | P32: =Elect!AG36 -> 10.335 | Q32: =Elect!AI36 -> 1108.9013 | R32: =Elect!AK36 -> 3699.93 | S32: =Elect!AM36 -> 103.42067 | T32: =Elect!AP36 -> 275.175 | U32: =Elect!AR36 -> 171 | V32: =Elect!AT36 -> 167.8 | W32: =Elect!AV36 -> 63.7 | X32: =Elect!AX36 -> 989.5 | Y32: =Elect!AZ36 -> 0 | Z32: =Elect!BB36 -> 5305.3 | AA32: =Elect!BD36 -> 223.6 | AB32: =Elect!BF36 -> 84.388889 | AC32: =Elect!BH36 -> 6471.02 | AD32: =Elect!BL36 -> 226.9 | AE32: =Elect!BN36 -> 1434.6 | AF32: =Elect!BP36 -> 99.8 | AG32: =Elect!BR36 -> 140.5 | AI32: =Water!C37 -> 133.4 | AJ32: =Water!E37 -> 174 | AK32: =Water!G37 -> 115.42 | AM32: =Gas!C37 -> 0 | AN32: =Gas!E37 -> 288.54 | AO32: =Gas!G37 -> 81.955556 | AP32: =Elect!BT36 -> 198

Sheet Elect
A1: 44743 | M1: Electricity | BP1: Gourmandise UP | BR1: 1.6 | BS1: Power Taxes | BU1: Max Demand | BW1: 500 | BX1: Electricity UP | BZ1: 1.15
BS2: Light Taxes | BU2: PF Penalty | BX2: Max. Demand UP | BZ2: 30
A3: Date | B3: COUNTER (1) | D3: MD | F3: KVAR | H3: n | I3: Guest Rooms Consumption | R3: Casino Consumption | V3: Plant Room Shared Loads | AO3: To Be Charged By First Arabian | BK3: From Main Panel G2 | BS3: Total Consumption. | BT3: No. Of | BU3: KWH/ | BV3: No. Of | BW3: KWH/ | BX3: Total Cost | BY3: L.E\ | BZ3: L.E\
B4: Reading | C4: Consp. F: *800 | D4: Reading | E4: Consp F: 80 | F4: Reading | G4: Consp. F:*10 | I4: Main Feeder | J4: Consp | K4: T2+T8 | L4: Trans T2 | M4: Consp | N4: Trans T8 | O4: Consp | P4: La Gourmandize | Q4: Consp *30 | R4: Casino 3rd floor EM | S4: Consp | T4: Casino 3rd floor Normal | U4: Consp | V4: Chiller 1 | W4: Consp 53% | X4: Chiller 2 | Y4: Consp 53% | Z4: Chiller 3 | AA4: Consp 53% | AB4: Chiller 4 | AC4: Consp 53% | AD4: Chiller 5 | AE4: Consp 53% | AF4: Chiller 6 | AG4: Consp 53% | AH4: Cooling Towers | AI4: Consp 53% | AJ4: Chiller Pumps | AK4: Consp 53% | AL4: Cooling Tower Pumps | AM4: Consp 53% | AN4: Total Plant Room Consp | AO4: Fiber Chiller (N24) | AP4: Consp | AQ4: Mall Ceiling light (N4) | AR4: Consp | AS4: LG Bakery (N2) | AT4: Consp | AU4: LG Bakery light ( Old lockers ) | AV4: Consp | AW4: MCCR1 | AX4: Consp | AY4: Children Swimming pool | AZ4: Consp | BA4: DPH1 | BB4: Consp | BC4: Guest Rooms Emergency | BD4: Consp | BE4: Hotel Hoods | BF4: Consp | BG4: Main G2 | BH4: Consp | BI4: Total Consp From First Arabian | BJ4: First Arabian Charge Back | BK4: Old Casino Emergency | BL4: Consp | BM4: L / A | BN4: Consp | BO4: L / B | BP4: Consp | BQ4: L / C | BR4: Consp | BT4: Rooms | BU4: room | BV4: guest | BW4: guest | BY4: Room | BZ4: Guest
A5: Last Month Reading | I5: 24864175 | J5: =IF(I5>=I4,I5-I4,0) -> 0 | K5: =M5+O5 -> 0 | L5: 2168 | M5: =IF(L5>=L4,L5-L4,0) -> 0 | N5: 823897 | O5: =IF(N5>=N4,N5-N4,0) -> 0 | P5: 224329 | Q5: =IF(P5>=P4,P5-P4,0)*30 -> 0 | R5: 203308 | S5: =IF(R5>=R4,R5-R4,0) -> 0 | T5: 372364 | U5: =IF(T5>=T4,T5-T4,0) -> 0 | V5: 170459 | W5: =IF(V5>=V4,V5-V4,0)*0.53 -> 0 | X5: 368053 | Y5: =IF(X5>=X4,X5-X4,0)*0.53 -> 0 | Z5: 404391 | AA5: =IF(Z5>=Z4,Z5-Z4,0)*0.53 -> 0 | AB5: 709124 | AC5: =IF(AB5>=AB4,AB5-AB4,0)*0.53 -> 0 | AD5: 696639 | AE5: =IF(AD5>=AD4,AD5-AD4,0)*0.53 -> 0 | AF5: 872855 | AG5: =IF(AF5>=AF4,AF5-AF4,0)*0.53 -> 0 | AH5: 167871 | AI5: =IF(AH5>=AH4,AH5-AH4,0)*0.53 -> 0 | AJ5: 523393 | AK5: =IF(AJ5>=AJ4,AJ5-AJ4,0)*0.53 -> 0 | AL5: 535047 | AM5: =IF(AL5>=AL4,AL5-AL4,0)*0.53 -> 0 | AN5: =W5+Y5+AA5+AC5+AE5+AG5+AI5+AK5+AM5 -> 0 | AO5: 7818230 | AP5: =IF(AO5>=AO4,AO5-AO4,0)*0.1125 -> 0 | AQ5: 722438 | AR5: =IF(AQ5>=AQ4,AQ5-AQ4,0) -> 0 | AS5: 989332 | AT5: =IF(AS5>=AS4,AS5-AS4,0) -> 0 | AU5: 817531 | AV5: =IF(AU5>=AU4,AU5-AU4,0) -> 0 | AW5: 2735135 | AX5: =IF(AW5>=AW4,AW5-AW4,0) -> 0 | AY5: 229733 | AZ5: =IF(AY5>=AY4,AY5-AY4,0) -> 0 | BA5: 20012243 | BB5: =IF(BA5>=BA4,BA5-BA4,0) -> 0 | BC5: 602362 | BD5: =IF(BC5>=BC4,BC5-BC4,0) -> 0 | BE5: 35021 | BF5: =IF(BE5>=BE4,BE5-BE4,0) -> 0 | BG5: 25051475 | BH5: =IF(BG5>=BG4,BG5-BG4,0)-(0.45*BN5)-(0.45*BP5)-BR5 -> 0 | BI5: =AP5+AR5+AT5+AV5+AX5+AZ5+BB5+BD5+BF5+BH5 -> 0 | BJ5: =BI5+AN5 -> 0 | BK5: 1455942 | BL5: =IF(BK5>=BK4,BK5-BK4,0) -> 0 | BM5: 4094272 | BN5: =IF(BM5>=BM4,BM5-BM4,0) -> 0 | BO5: 432585 | BP5: =IF(BO5>=BO4,BO5-BO4,0) -> 0 | BQ5: 540013 | BR5: =IF(BQ5>=BQ4,BQ5-BQ4,0) -> 0
A6: 1 | C6: =IF(+B6-B5>0,B6-B5,(B6-B5)>0)*800 -> 0 | E6: =IF(+D6-D5>0,D6-D5,(D6-D5)>0)*80 -> 0 | G6: =IF(+F6-F5>0,F6-F5,(F6-F5)>0)*10 -> 0 | H6: 56 | I6: 24870485 | J6: =IF(I6>=I5,I6-I5,0) -> 6310 | K6: =M6+O6 -> 0 | L6: -24643.095 | M6: =IF(L6>=L5,L6-L5,0) -> 0 | N6: 822201 | O6: =IF(N6>=N5,N6-N5,0) -> 0 | P6: 224347 | Q6: =IF(P6>=P5,P6-P5,0)*30 -> 540 | R6: 203455 | S6: =IF(R6>=R5,R6-R5,0) -> 147 | T6: 372603 | U6: =IF(T6>=T5,T6-T5,0) -> 239 | V6: 178936 | W6: =IF(V6>=V5,V6-V5,0)*0.53 -> 4492.81 | X6: 368053 | Y6: =IF(X6>=X5,X6-X5,0)*0.53 -> 0 | Z6: 406252 | AA6: =IF(Z6>=Z5,Z6-Z5,0)*0.53 -> 986.33 | AB6: 714926 | AC6: =IF(AB6>=AB5,AB6-AB5,0)*0.53 -> 3075.06 | AD6: 696660 | AE6: =IF(AD6>=AD5,AD6-AD5,0)*0.53 -> 11.13 | AF6: 875710 | AG6: =IF(AF6>=AF5,AF6-AF5,0)*0.53 -> 1513.15 | AH6: 170053 | AI6: =IF(AH6>=AH5,AH6-AH5,0)*0.53 -> 1156.46 | AJ6: 530230 | AK6: =IF(AJ6>=AJ5,AJ6-AJ5,0)*0.53 -> 3623.61 | AL6: 535252 | AM6: =IF(AL6>=AL5,AL6-AL5,0)*0.53 -> 108.65 | AN6: =W6+Y6+AA6+AC6+AE6+AG6+AI6+AK6+AM6 -> 14967.2 | AO6: 7821239 | AP6: =IF(AO6>=AO5,AO6-AO5,0)*0.1125 -> 338.5125 | AQ6: 722586 | AR6: =IF(AQ6>=AQ5,AQ6-AQ5,0) -> 148 | AS6: 989540 | AT6: =IF(AS6>=AS5,AS6-AS5,0) -> 208 | AU6: 817593 | AV6: =IF(AU6>=AU5,AU6-AU5,0) -> 62 | AW6: 2736109 | AX6: =IF(AW6>=AW5,AW6-AW5,0) -> 974 | AY6: 229733 | AZ6: =IF(AY6>=AY5,AY6-AY5,0) -> 0 | BA6: 20017231 | BB6: =IF(BA6>=BA5,BA6-BA5,0) -> 4988 | BC6: 602465 | BD6: =IF(BC6>=BC5,BC6-BC5,0) -> 103 | BE6: 35059 | BF6: =IF(BE6>=BE5,BE6-BE5,0) -> 38 | BG6: 25058795 | BH6: =IF(BG6>=BG5,BG6-BG5,0)-(0.45*BN6)-(0.45*BP6)-BR6 -> 6442.65 | BI6: =AP6+AR6+AT6+AV6+AX6+AZ6+BB6+BD6+BF6+BH6 -> 13302.163 | BJ6: =BI6+AN6 -> 28269.362 | BK6: 1456241 | BL6: =IF(BK6>=BK5,BK6-BK5,0) -> 299 | BM6: 4095779 | BN6: =IF(BM6>=BM5,BM6-BM5,0) -> 1507 | BO6: 432701 | BP6: =IF(BO6>=BO5,BO6-BO5,0) -> 116 | BQ6: 540160 | BR6: =IF(BQ6>=BQ5,BQ6-BQ5,0) -> 147 | BS6: =J6+Q6+AN6+BI6 -> 35119.362 | BT6: 157 | BU6: =IF(BS6>0,BS6/BT5,0) -> #DIV/0! | BW6: =IF(BS6>0,BS6/BV6,0) -> #DIV/0! | BX6: =((BS6-Q6)*$BZ$1)+(Q6*$BR$1) -> 40630.267 | BY6: =IF(BX6>0,BX6/BT5,0) -> #DIV/0! | BZ6: =IF(BX6>0,BX6/BV6,0) -> #DIV/0!
A7: 2 | I7: 24875845 | J7: =IF(I7>=I6,I7-I6,0) -> 5360 | K7: =M7+O7 -> 2615.0214 | L7: -22659.074 | M7: =IF(L7>=L6,L7-L6,0) -> 1984.0214 | N7: 822832 | O7: =IF(N7>=N6,N7-N6,0) -> 631 | P7: 224363 | Q7: =IF(P7>=P6,P7-P6,0)*30 -> 480 | R7: 203629 | S7: =IF(R7>=R6,R7-R6,0) -> 174 | T7: 372876 | U7: =IF(T7>=T6,T7-T6,0) -> 273 | V7: 182238 | W7: =IF(V7>=V6,V7-V6,0)*0.53 -> 1750.06 | X7: 371717 | Y7: =IF(X7>=X6,X7-X6,0)*0.53 -> 1941.92 | Z7: 406710 | AA7: =IF(Z7>=Z6,Z7-Z6,0)*0.53 -> 242.74 | AB7: 722068 | AC7: =IF(AB7>=AB6,AB7-AB6,0)*0.53 -> 3785.26 | AD7: 696681 | AE7: =IF(AD7>=AD6,AD7-AD6,0)*0.53 -> 11.13 | AF7: 878798 | AG7: =IF(AF7>=AF6,AF7-AF6,0)*0.53 -> 1636.64 | AH7: 172267 | AI7: =IF(AH7>=AH6,AH7-AH6,0)*0.53 -> 1173.42 | AJ7: 537317 | AK7: =IF(AJ7>=AJ6,AJ7-AJ6,0)*0.53 -> 3756.11 | AL7: 535467 | AM7: =IF(AL7>=AL6,AL7-AL6,0)*0.53 -> 113.95 | AN7: =W7+Y7+AA7+AC7+AE7+AG7+AI7+AK7+AM7 -> 14411.23 | AO7: 7823698 | AP7: =IF(AO7>=AO6,AO7-AO6,0)*0.1125 -> 276.6375 | AQ7: 722741 | AR7: =IF(AQ7>=AQ6,AQ7-AQ6,0) -> 155 | AS7: 989734 | AT7: =IF(AS7>=AS6,AS7-AS6,0) -> 194 | AU7: 817647 | AV7: =IF(AU7>=AU6,AU7-AU6,0) -> 54 | AW7: 2737222 | AX7: =IF(AW7>=AW6,AW7-AW6,0) -> 1113 | AY7: 229733 | AZ7: =IF(AY7>=AY6,AY7-AY6,0) -> 0 | BA7: 20022283 | BB7: =IF(BA7>=BA6,BA7-BA6,0) -> 5052 | BC7: 602644 | BD7: =IF(BC7>=BC6,BC7-BC6,0) -> 179 | BE7: 35129 | BF7: =IF(BE7>=BE6,BE7-BE6,0) -> 70 | BG7: 25065987 | BH7: =IF(BG7>=BG6,BG7-BG6,0)-(0.45*BN7)-(0.45*BP7)-BR7 -> 6297.95 | BI7: =AP7+AR7+AT7+AV7+AX7+AZ7+BB7+BD7+BF7+BH7 -> 13391.588 | BJ7: =BI7+AN7 -> 27802.818 | BK7: 1456515 | BL7: =IF(BK7>=BK6,BK7-BK6,0) -> 274 | BM7: 4097231 | BN7: =IF(BM7>=BM6,BM7-BM6,0) -> 1452 | BO7: 432818 | BP7: =IF(BO7>=BO6,BO7-BO6,0) -> 117 | BQ7: 540348 | BR7: =IF(BQ7>=BQ6,BQ7-BQ6,0) -> 188 | BS7: =J7+Q7+AN7+BI7 -> 33642.818 | BT7: 135 | BU7: =IF(BS7>0,BS7/BT6,0) -> 214.28546 | BW7: =IF(BS7>0,BS7/BV7,0) -> #DIV/0! | BX7: =((BS7-Q7)*$BZ$1)+(Q7*$BR$1) -> 38905.24 | BY7: =IF(BX7>0,BX7/BT6,0) -> 247.80408 | BZ7: =IF(BX7>0,BX7/BV7,0) -> #DIV/0!
A8: 3 | C8: =IF(+B8-B7>0,B8-B7,(B8-B7)>0)*800 -> 0 | E8: =IF(+D8-D7>0,D8-D7,(D8-D7)>0)*80 -> 0 | G8: =IF(+F8-F7>0,F8-F7,(F8-F7)>0)*10 -> 0 | H8: 57 | I8: 24881344 | J8: =IF(I8>=I7,I8-I7,0) -> 5499 | K8: =M8+O8 -> 2346.0214 | L8: -20675.052 | M8: =IF(L8>=L7,L8-L7,0) -> 1984.0214 | N8: 823194 | O8: =IF(N8>=N7,N8-N7,0) -> 362 | P8: 224382 | Q8: =IF(P8>=P7,P8-P7,0)*30 -> 570 | R8: 203860 | S8: =IF(R8>=R7,R8-R7,0) -> 231 | T8: 373132 | U8: =IF(T8>=T7,T8-T7,0) -> 256 | V8: 182685 | W8: =IF(V8>=V7,V8-V7,0)*0.53 -> 236.91 | X8: 373981 | Y8: =IF(X8>=X7,X8-X7,0)*0.53 -> 1199.92 | Z8: 414344 | AA8: =IF(Z8>=Z7,Z8-Z7,0)*0.53 -> 4046.02 | AB8: 726947 | AC8: =IF(AB8>=AB7,AB8-AB7,0)*0.53 -> 2585.87 | AD8: 697090 | AE8: =IF(AD8>=AD7,AD8-AD7,0)*0.53 -> 216.77 | AF8: 881680 | AG8: =IF(AF8>=AF7,AF8-AF7,0)*0.53 -> 1527.46 | AH8: 174530 | AI8: =IF(AH8>=AH7,AH8-AH7,0)*0.53 -> 1199.39 | AJ8: 544561 | AK8: =IF(AJ8>=AJ7,AJ8-AJ7,0)*0.53 -> 3839.32 | AL8: 535681 | AM8: =IF(AL8>=AL7,AL8-AL7,0)*0.53 -> 113.42 | AN8: =W8+Y8+AA8+AC8+AE8+AG8+AI8+AK8+AM8 -> 14965.08 | AO8: 7825958 | AP8: =IF(AO8>=AO7,AO8-AO7,0)*0.1125 -> 254.25 | AQ8: 722922 | AR8: =IF(AQ8>=AQ7,AQ8-AQ7,0) -> 181 | AS8: 989930 | AT8: =IF(AS8>=AS7,AS8-AS7,0) -> 196 | AU8: 817714 | AV8: =IF(AU8>=AU7,AU8-AU7,0) -> 67 | AW8: 2738304 | AX8: =IF(AW8>=AW7,AW8-AW7,0) -> 1082 | AY8: 229733 | AZ8: =IF(AY8>=AY7,AY8-AY7,0) -> 0 | BA8: 20027880 | BB8: =IF(BA8>=BA7,BA8-BA7,0) -> 5597 | BC8: 602846 | BD8: =IF(BC8>=BC7,BC8-BC7,0) -> 202 | BE8: 35198 | BF8: =IF(BE8>=BE7,BE8-BE7,0) -> 69 | BG8: 25073354 | BH8: =IF(BG8>=BG7,BG8-BG7,0)-(0.45*BN8)-(0.45*BP8)-BR8 -> 6454.25 | BI8: =AP8+AR8+AT8+AV8+AX8+AZ8+BB8+BD8+BF8+BH8 -> 14102.5 | BJ8: =BI8+AN8 -> 29067.58 | BK8: 1456798 | BL8: =IF(BK8>=BK7,BK8-BK7,0) -> 283 | BM8: 4098750 | BN8: =IF(BM8>=BM7,BM8-BM7,0) -> 1519 | BO8: 432934 | BP8: =IF(BO8>=BO7,BO8-BO7,0) -> 116 | BQ8: 540525 | BR8: =IF(BQ8>=BQ7,BQ8-BQ7,0) -> 177 | BS8: =J8+Q8+AN8+BI8 -> 35136.58 | BT8: 120 | BU8: =IF(BS8>0,BS8/BT7,0) -> 260.27096 | BW8: =IF(BS8>0,BS8/BV8,0) -> #DIV/0! | BX8: =((BS8-Q8)*$BZ$1)+(Q8*$BR$1) -> 40663.567 | BY8: =IF(BX8>0,BX8/BT7,0) -> 301.21161 | BZ8: =IF(BX8>0,BX8/BV8,0) -> #DIV/0!
A9: 4 | C9: =IF(+B9-B8>0,B9-B8,(B9-B8)>0)*800 -> 0 | E9: =IF(+D9-D8>0,D9-D8,(D9-D8)>0)*80 -> 0 | G9: =IF(+F9-F8>0,F9-F8,(F9-F8)>0)*10 -> 0 | I9: 24886801 | J9: =IF(I9>=I8,I9-I8,0) -> 5457 | K9: =M9+O9 -> 2466.0214 | L9: -18691.031 | M9: =IF(L9>=L8,L9-L8,0) -> 1984.0214 | N9: 823676 | O9: =IF(N9>=N8,N9-N8,0) -> 482 | P9: 224390 | Q9: =IF(P9>=P8,P9-P8,0)*30 -> 240 | R9: 204087 | S9: =IF(R9>=R8,R9-R8,0) -> 227 | T9: 373388 | U9: =IF(T9>=T8,T9-T8,0) -> 256 | V9: 185627 | W9: =IF(V9>=V8,V9-V8,0)*0.53 -> 1559.26 | X9: 374995 | Y9: =IF(X9>=X8,X9-X8,0)*0.53 -> 537.42 | Z9: 421786 | AA9: =IF(Z9>=Z8,Z9-Z8,0)*0.53 -> 3944.26 | AB9: 727422 | AC9: =IF(AB9>=AB8,AB9-AB8,0)*0.53 -> 251.75 | AD9: 700320 | AE9: =IF(AD9>=AD8,AD9-AD8,0)*0.53 -> 1711.9 | AF9: 881700 | AG9: =IF(AF9>=AF8,AF9-AF8,0)*0.53 -> 10.6 | AH9: 176719 | AI9: =IF(AH9>=AH8,AH9-AH8,0)*0.53 -> 1160.17 | AJ9: 551594 | AK9: =IF(AJ9>=AJ8,AJ9-AJ8,0)*0.53 -> 3727.49 | AL9: 535884 | AM9: =IF(AL9>=AL8,AL9-AL8,0)*0.53 -> 107.59 | AN9: =W9+Y9+AA9+AC9+AE9+AG9+AI9+AK9+AM9 -> 13010.44 | AO9: 7828311 | AP9: =IF(AO9>=AO8,AO9-AO8,0)*0.1125 -> 264.7125 | AQ9: 723098 | AR9: =IF(AQ9>=AQ8,AQ9-AQ8,0) -> 176 | AS9: 990102 | AT9: =IF(AS9>=AS8,AS9-AS8,0) -> 172 | AU9: 817778 | AV9: =IF(AU9>=AU8,AU9-AU8,0) -> 64 | AW9: 2739307 | AX9: =IF(AW9>=AW8,AW9-AW8,0) -> 1003 | AY9: 229733 | AZ9: =IF(AY9>=AY8,AY9-AY8,0) -> 0 | BA9: 20032832 | BB9: =IF(BA9>=BA8,BA9-BA8,0) -> 4952 | BC9: 603065 | BD9: =IF(BC9>=BC8,BC9-BC8,0) -> 219 | BE9: 35243 | BF9: =IF(BE9>=BE8,BE9-BE8,0) -> 45 | BG9: 25080714 | BH9: =IF(BG9>=BG8,BG9-BG8,0)-(0.45*BN9)-(0.45*BP9)-BR9 -> 6459.1 | BI9: =AP9+AR9+AT9+AV9+AX9+AZ9+BB9+BD9+BF9+BH9 -> 13354.812 | BJ9: =BI9+AN9 -> 26365.253 | BK9: 1457074 | BL9: =IF(BK9>=BK8,BK9-BK8,0) -> 276 | BM9: 4100253 | BN9: =IF(BM9>=BM8,BM9-BM8,0) -> 1503 | BO9: 433053 | BP9: =IF(BO9>=BO8,BO9-BO8,0) -> 119 | BQ9: 540696 | BR9: =IF(BQ9>=BQ8,BQ9-BQ8,0) -> 171 | BS9: =J9+Q9+AN9+BI9 -> 32062.253 | BT9: 121 | BU9: =IF(BS9>0,BS9/BT8,0) -> 267.18544 | BW9: =IF(BS9>0,BS9/BV9,0) -> #DIV/0! | BX9: =((BS9-Q9)*$BZ$1)+(Q9*$BR$1) -> 36979.59 | BY9: =IF(BX9>0,BX9/BT8,0) -> 308.16325 | BZ9: =IF(BX9>0,BX9/BV9,0) -> #DIV/0!
A10: 5 | C10: =IF(+B10-B9>0,B10-B9,(B10-B9)>0)*800 -> 0 | E10: =IF(+D10-D9>0,D10-D9,(D10-D9)>0)*80 -> 0 | G10: =IF(+F10-F9>0,F10-F9,(F10-F9)>0)*10 -> 0 | H10: 58 | I10: 24892286 | J10: =IF(I10>=I9,I10-I9,0) -> 5485 | K10: =M10+O10 -> 2406.0214 | L10: -16707.01 | M10: =IF(L10>=L9,L10-L9,0) -> 1984.0214 | N10: 824098 | O10: =IF(N10>=N9,N10-N9,0) -> 422 | P10: 224415 | Q10: =IF(P10>=P9,P10-P9,0)*30 -> 750 | R10: 204328 | S10: =IF(R10>=R9,R10-R9,0) -> 241 | T10: 373666 | U10: =IF(T10>=T9,T10-T9,0) -> 278 | V10: 191254 | W10: =IF(V10>=V9,V10-V9,0)*0.53 -> 2982.31 | X10: 380302 | Y10: =IF(X10>=X9,X10-X9,0)*0.53 -> 2812.71 | Z10: 429468 | AA10: =IF(Z10>=Z9,Z10-Z9,0)*0.53 -> 4071.46 | AB10: 727422 | AC10: =IF(AB10>=AB9,AB10-AB9,0)*0.53 -> 0 | AD10: 703876 | AE10: =IF(AD10>=AD9,AD10-AD9,0)*0.53 -> 1884.68 | AF10: 881720 | AG10: =IF(AF10>=AF9,AF10-AF9,0)*0.53 -> 10.6 | AH10: 178975 | AI10: =IF(AH10>=AH9,AH10-AH9,0)*0.53 -> 1195.68 | AJ10: 558783 | AK10: =IF(AJ10>=AJ9,AJ10-AJ9,0)*0.53 -> 3810.17 | AL10: 536095 | AM10: =IF(AL10>=AL9,AL10-AL9,0)*0.53 -> 111.83 | AN10: =W10+Y10+AA10+AC10+AE10+AG10+AI10+AK10+AM10 -> 16879.44 | AO10: 7830785 | AP10: =IF(AO10>=AO9,AO10-AO9,0)*0.1125 -> 278.325 | AQ10: 723277 | AR10: =IF(AQ10>=AQ9,AQ10-AQ9,0) -> 179 | AS10: 990296 | AT10: =IF(AS10>=AS9,AS10-AS9,0) -> 194 | AU10: 817844 | AV10: =IF(AU10>=AU9,AU10-AU9,0) -> 66 | AW10: 2740308 | AX10: =IF(AW10>=AW9,AW10-AW9,0) -> 1001 | AY10: 229733 | AZ10: =IF(AY10>=AY9,AY10-AY9,0) -> 0 | BA10: 20038300 | BB10: =IF(BA10>=BA9,BA10-BA9,0) -> 5468 | BC10: 603293 | BD10: =IF(BC10>=BC9,BC10-BC9,0) -> 228 | BE10: 35317 | BF10: =IF(BE10>=BE9,BE10-BE9,0) -> 74 | BG10: 25088277 | BH10: =IF(BG10>=BG9,BG10-BG9,0)-(0.45*BN10)-(0.45*BP10)-BR10 -> 6670 | BI10: =AP10+AR10+AT10+AV10+AX10+AZ10+BB10+BD10+BF10+BH10 -> 14158.325 | BJ10: =BI10+AN10 -> 31037.765 | BK10: 1457365 | BL10: =IF(BK10>=BK9,BK10-BK9,0) -> 291 | BM10: 4101765 | BN10: =IF(BM10>=BM9,BM10-BM9,0) -> 1512 | BO10: 433181 | BP10: =IF(BO10>=BO9,BO10-BO9,0) -> 128 | BQ10: 540851 | BR10: =IF(BQ10>=BQ9,BQ10-BQ9,0) -> 155 | BS10: =J10+Q10+AN10+BI10 -> 37272.765 | BT10: 130 | BU10: =IF(BS10>0,BS10/BT9,0) -> 308.03938 | BW10: =IF(BS10>0,BS10/BV10,0) -> #DIV/0! | BX10: =((BS10-Q10)*$BZ$1)+(Q10*$BR$1) -> 43201.18 | BY10: =IF(BX10>0,BX10/BT9,0) -> 357.03454 | BZ10: =IF(BX10>0,BX10/BV10,0) -> #DIV/0!
A11: 6 | C11: =IF(+B11-B10>0,B11-B10,(B11-B10)>0)*800 -> 0 | E11: =IF(+D11-D10>0,D11-D10,(D11-D10)>0)*80 -> 0 | G11: =IF(+F11-F10>0,F11-F10,(F11-F10)>0)*10 -> 0 | I11: 24897764 | J11: =IF(I11>=I10,I11-I10,0) -> 5478 | K11: =M11+O11 -> 2385.0214 | L11: -14722.988 | M11: =IF(L11>=L10,L11-L10,0) -> 1984.0214 | N11: 824499 | O11: =IF(N11>=N10,N11-N10,0) -> 401 | P11: 224430 | Q11: =IF(P11>=P10,P11-P10,0)*30 -> 450 | R11: 204552 | S11: =IF(R11>=R10,R11-R10,0) -> 224 | T11: 373919 | U11: =IF(T11>=T10,T11-T10,0) -> 253 | V11: 197349 | W11: =IF(V11>=V10,V11-V10,0)*0.53 -> 3230.35 | X11: 380302 | Y11: =IF(X11>=X10,X11-X10,0)*0.53 -> 0 | Z11: 437037 | AA11: =IF(Z11>=Z10,Z11-Z10,0)*0.53 -> 4011.57 | AB11: 727422 | AC11: =IF(AB11>=AB10,AB11-AB10,0)*0.53 -> 0 | AD11: 706847 | AE11: =IF(AD11>=AD10,AD11-AD10,0)*0.53 -> 1574.63 | AF11: 881738 | AG11: =IF(AF11>=AF10,AF11-AF10,0)*0.53 -> 9.54 | AH11: 181203 | AI11: =IF(AH11>=AH10,AH11-AH10,0)*0.53 -> 1180.84 | AJ11: 565850 | AK11: =IF(AJ11>=AJ10,AJ11-AJ10,0)*0.53 -> 3745.51 | AL11: 536307 | AM11: =IF(AL11>=AL10,AL11-AL10,0)*0.53 -> 112.36 | AN11: =W11+Y11+AA11+AC11+AE11+AG11+AI11+AK11+AM11 -> 13864.8 | AO11: 7833273 | AP11: =IF(AO11>=AO10,AO11-AO10,0)*0.1125 -> 279.9 | AQ11: 723445 | AR11: =IF(AQ11>=AQ10,AQ11-AQ10,0) -> 168 | AS11: 990489 | AT11: =IF(AS11>=AS10,AS11-AS10,0) -> 193 | AU11: 817909 | AV11: =IF(AU11>=AU10,AU11-AU10,0) -> 65 | AW11: 2741307 | AX11: =IF(AW11>=AW10,AW11-AW10,0) -> 999 | AY11: 229733 | AZ11: =IF(AY11>=AY10,AY11-AY10,0) -> 0 | BA11: 20043527 | BB11: =IF(BA11>=BA10,BA11-BA10,0) -> 5227 | BC11: 603511 | BD11: =IF(BC11>=BC10,BC11-BC10,0) -> 218 | BE11: 35367 | BF11: =IF(BE11>=BE10,BE11-BE10,0) -> 50 | BG11: 25095721 | BH11: =IF(BG11>=BG10,BG11-BG10,0)-(0.45*BN11)-(0.45*BP11)-BR11 -> 6566.05 | BI11: =AP11+AR11+AT11+AV11+AX11+AZ11+BB11+BD11+BF11+BH11 -> 13765.95 | BJ11: =BI11+AN11 -> 27630.75 | BK11: 1457638 | BL11: =IF(BK11>=BK10,BK11-BK10,0) -> 273 | BM11: 4103276 | BN11: =IF(BM11>=BM10,BM11-BM10,0) -> 1511 | BO11: 433301 | BP11: =IF(BO11>=BO10,BO11-BO10,0) -> 120 | BQ11: 540995 | BR11: =IF(BQ11>=BQ10,BQ11-BQ10,0) -> 144 | BS11: =J11+Q11+AN11+BI11 -> 33558.75 | BT11: 129 | BU11: =IF(BS11>0,BS11/BT10,0) -> 258.14423 | BW11: =IF(BS11>0,BS11/BV11,0) -> #DIV/0! | BX11: =((BS11-Q11)*$BZ$1)+(Q11*$BR$1) -> 38795.062 | BY11: =IF(BX11>0,BX11/BT10,0) -> 298.42356 | BZ11: =IF(BX11>0,BX11/BV11,0) -> #DIV/0!
A12: 7 | C12: =IF(+B12-B11>0,B12-B11,(B12-B11)>0)*800 -> 0 | E12: =IF(+D12-D11>0,D12-D11,(D12-D11)>0)*80 -> 0 | G12: =IF(+F12-F11>0,F12-F11,(F12-F11)>0)*10 -> 0 | H12: 59 | I12: 24903242 | J12: =IF(I12>=I11,I12-I11,0) -> 5478 | K12: =M12+O12 -> 2352.0214 | L12: -12738.967 | M12: =IF(L12>=L11,L12-L11,0) -> 1984.0214 | N12: 824867 | O12: =IF(N12>=N11,N12-N11,0) -> 368 | P12: 224448 | Q12: =IF(P12>=P11,P12-P11,0)*30 -> 540 | R12: 204784 | S12: =IF(R12>=R11,R12-R11,0) -> 232 | T12: 374165 | U12: =IF(T12>=T11,T12-T11,0) -> 246 | V12: 199870 | W12: =IF(V12>=V11,V12-V11,0)*0.53 -> 1336.13 | X12: 382063 | Y12: =IF(X12>=X11,X12-X11,0)*0.53 -> 933.33 | Z12: 444430 | AA12: =IF(Z12>=Z11,Z12-Z11,0)*0.53 -> 3918.29 | AB12: 728830 | AC12: =IF(AB12>=AB11,AB12-AB11,0)*0.53 -> 746.24 | AD12: 709046 | AE12: =IF(AD12>=AD11,AD12-AD11,0)*0.53 -> 1165.47 | AF12: 882378 | AG12: =IF(AF12>=AF11,AF12-AF11,0)*0.53 -> 339.2 | AH12: 183393 | AI12: =IF(AH12>=AH11,AH12-AH11,0)*0.53 -> 1160.7 | AJ12: 572909 | AK12: =IF(AJ12>=AJ11,AJ12-AJ11,0)*0.53 -> 3741.27 | AL12: 536513 | AM12: =IF(AL12>=AL11,AL12-AL11,0)*0.53 -> 109.18 | AN12: =W12+Y12+AA12+AC12+AE12+AG12+AI12+AK12+AM12 -> 13449.81 | AO12: 7835422 | AP12: =IF(AO12>=AO11,AO12-AO11,0)*0.1125 -> 241.7625 | AQ12: 723663 | AR12: =IF(AQ12>=AQ11,AQ12-AQ11,0) -> 218 | AS12: 990690 | AT12: =IF(AS12>=AS11,AS12-AS11,0) -> 201 | AU12: 817967 | AV12: =IF(AU12>=AU11,AU12-AU11,0) -> 58 | AW12: 2742294 | AX12: =IF(AW12>=AW11,AW12-AW11,0) -> 987 | AY12: 229733 | AZ12: =IF(AY12>=AY11,AY12-AY11,0) -> 0 | BA12: 20048968 | BB12: =IF(BA12>=BA11,BA12-BA11,0) -> 5441 | BC12: 603768 | BD12: =IF(BC12>=BC11,BC12-BC11,0) -> 257 | BE12: 35432 | BF12: =IF(BE12>=BE11,BE12-BE11,0) -> 65 | BG12: 25103092 | BH12: =IF(BG12>=BG11,BG12-BG11,0)-(0.45*BN12)-(0.45*BP12)-BR12 -> 6499.45 | BI12: =AP12+AR12+AT12+AV12+AX12+AZ12+BB12+BD12+BF12+BH12 -> 13968.212 | BJ12: =BI12+AN12 -> 27418.022 | BK12: 1457897 | BL12: =IF(BK12>=BK11,BK12-BK11,0) -> 259 | BM12: 4104776 | BN12: =IF(BM12>=BM11,BM12-BM11,0) -> 1500 | BO12: 433420 | BP12: =IF(BO12>=BO11,BO12-BO11,0) -> 119 | BQ12: 541138 | BR12: =IF(BQ12>=BQ11,BQ12-BQ11,0) -> 143 | BS12: =J12+Q12+AN12+BI12 -> 33436.022 | BT12: 137 | BU12: =IF(BS12>0,BS12/BT11,0) -> 259.19397 | BW12: =IF(BS12>0,BS12/BV12,0) -> #DIV/0! | BX12: =((BS12-Q12)*$BZ$1)+(Q12*$BR$1) -> 38694.426 | BY12: =IF(BX12>0,BX12/BT11,0) -> 299.95679 | BZ12: =IF(BX12>0,BX12/BV12,0) -> #DIV/0!
A13: 8 | C13: =IF(+B13-B12>0,B13-B12,(B13-B12)>0)*800 -> 0 | E13: =IF(+D13-D12>0,D13-D12,(D13-D12)>0)*80 -> 0 | G13: =IF(+F13-F12>0,F13-F12,(F13-F12)>0)*10 -> 0 | I13: 24908329 | J13: =IF(I13>=I12,I13-I12,0) -> 5087 | K13: =M13+O13 -> 2491.0214 | L13: -10754.945 | M13: =IF(L13>=L12,L13-L12,0) -> 1984.0214 | N13: 825374 | O13: =IF(N13>=N12,N13-N12,0) -> 507 | P13: 224460 | Q13: =IF(P13>=P12,P13-P12,0)*30 -> 360 | R13: 205013 | S13: =IF(R13>=R12,R13-R12,0) -> 229 | T13: 374404 | U13: =IF(T13>=T12,T13-T12,0) -> 239 | V13: 199870 | W13: =IF(V13>=V12,V13-V12,0)*0.53 -> 0 | X13: 389132 | Y13: =IF(X13>=X12,X13-X12,0)*0.53 -> 3746.57 | Z13: 452069 | AA13: =IF(Z13>=Z12,Z13-Z12,0)*0.53 -> 4048.67 | AB13: 728830 | AC13: =IF(AB13>=AB12,AB13-AB12,0)*0.53 -> 0 | AD13: 712309 | AE13: =IF(AD13>=AD12,AD13-AD12,0)*0.53 -> 1729.39 | AF13: 882400 | AG13: =IF(AF13>=AF12,AF13-AF12,0)*0.53 -> 11.66 | AH13: 185608 | AI13: =IF(AH13>=AH12,AH13-AH12,0)*0.53 -> 1173.95 | AJ13: 580062 | AK13: =IF(AJ13>=AJ12,AJ13-AJ12,0)*0.53 -> 3791.09 | AL13: 536712 | AM13: =IF(AL13>=AL12,AL13-AL12,0)*0.53 -> 105.47 | AN13: =W13+Y13+AA13+AC13+AE13+AG13+AI13+AK13+AM13 -> 14606.8 | AO13: 7837626 | AP13: =IF(AO13>=AO12,AO13-AO12,0)*0.1125 -> 247.95 | AQ13: 723896 | AR13: =IF(AQ13>=AQ12,AQ13-AQ12,0) -> 233 | AS13: 990854 | AT13: =IF(AS13>=AS12,AS13-AS12,0) -> 164 | AU13: 818020 | AV13: =IF(AU13>=AU12,AU13-AU12,0) -> 53 | AW13: 2743267 | AX13: =IF(AW13>=AW12,AW13-AW12,0) -> 973 | AY13: 229733 | AZ13: =IF(AY13>=AY12,AY13-AY12,0) -> 0 | BA13: 20054184 | BB13: =IF(BA13>=BA12,BA13-BA12,0) -> 5216 | BC13: 604037 | BD13: =IF(BC13>=BC12,BC13-BC12,0) -> 269 | BE13: 35497 | BF13: =IF(BE13>=BE12,BE13-BE12,0) -> 65 | BG13: 25110203 | BH13: =IF(BG13>=BG12,BG13-BG12,0)-(0.45*BN13)-(0.45*BP13)-BR13 -> 6275.5 | BI13: =AP13+AR13+AT13+AV13+AX13+AZ13+BB13+BD13+BF13+BH13 -> 13496.45 | BJ13: =BI13+AN13 -> 28103.25 | BK13: 1458172 | BL13: =IF(BK13>=BK12,BK13-BK12,0) -> 275 | BM13: 4106178 | BN13: =IF(BM13>=BM12,BM13-BM12,0) -> 1402 | BO13: 433528 | BP13: =IF(BO13>=BO12,BO13-BO12,0) -> 108 | BQ13: 541294 | BR13: =IF(BQ13>=BQ12,BQ13-BQ12,0) -> 156 | BS13: =J13+Q13+AN13+BI13 -> 33550.25 | BT13: 145 | BU13: =IF(BS13>0,BS13/BT12,0) -> 244.89234 | BW13: =IF(BS13>0,BS13/BV13,0) -> #DIV/0! | BX13: =((BS13-Q13)*$BZ$1)+(Q13*$BR$1) -> 38744.787 | BY13: =IF(BX13>0,BX13/BT12,0) -> 282.80867 | BZ13: =IF(BX13>0,BX13/BV13,0) -> #DIV/0!
A14: 9 | C14: =IF(+B14-B13>0,B14-B13,(B14-B13)>0)*800 -> 0 | E14: =IF(+D14-D13>0,D14-D13,(D14-D13)>0)*80 -> 0 | G14: =IF(+F14-F13>0,F14-F13,(F14-F13)>0)*10 -> 0 | H14: 60 | I14: 24913551 | J14: =IF(I14>=I13,I14-I13,0) -> 5222 | K14: =M14+O14 -> 3660.0214 | L14: -8770.9238 | M14: =IF(L14>=L13,L14-L13,0) -> 1984.0214 | N14: 827050 | O14: =IF(N14>=N13,N14-N13,0) -> 1676 | P14: 224480 | Q14: =IF(P14>=P13,P14-P13,0)*30 -> 600 | R14: 205240 | S14: =IF(R14>=R13,R14-R13,0) -> 227 | T14: 374641 | U14: =IF(T14>=T13,T14-T13,0) -> 237 | V14: 199870 | W14: =IF(V14>=V13,V14-V13,0)*0.53 -> 0 | X14: 396082 | Y14: =IF(X14>=X13,X14-X13,0)*0.53 -> 3683.5 | Z14: 459614 | AA14: =IF(Z14>=Z13,Z14-Z13,0)*0.53 -> 3998.85 | AB14: 728830 | AC14: =IF(AB14>=AB13,AB14-AB13,0)*0.53 -> 0 | AD14: 715168 | AE14: =IF(AD14>=AD13,AD14-AD13,0)*0.53 -> 1515.27 | AF14: 882418 | AG14: =IF(AF14>=AF13,AF14-AF13,0)*0.53 -> 9.54 | AH14: 187806 | AI14: =IF(AH14>=AH13,AH14-AH13,0)*0.53 -> 1164.94 | AJ14: 587174 | AK14: =IF(AJ14>=AJ13,AJ14-AJ13,0)*0.53 -> 3769.36 | AL14: 536908 | AM14: =IF(AL14>=AL13,AL14-AL13,0)*0.53 -> 103.88 | AN14: =W14+Y14+AA14+AC14+AE14+AG14+AI14+AK14+AM14 -> 14245.34 | AO14: 7839830 | AP14: =IF(AO14>=AO13,AO14-AO13,0)*0.1125 -> 247.95 | AQ14: 724035 | AR14: =IF(AQ14>=AQ13,AQ14-AQ13,0) -> 139 | AS14: 991062 | AT14: =IF(AS14>=AS13,AS14-AS13,0) -> 208 | AU14: 818070 | AV14: =IF(AU14>=AU13,AU14-AU13,0) -> 50 | AW14: 2744243 | AX14: =IF(AW14>=AW13,AW14-AW13,0) -> 976 | AY14: 229733 | AZ14: =IF(AY14>=AY13,AY14-AY13,0) -> 0 | BA14: 20059400 | BB14: =IF(BA14>=BA13,BA14-BA13,0) -> 5216 | BC14: 604293 | BD14: =IF(BC14>=BC13,BC14-BC13,0) -> 256 | BE14: 35562 | BF14: =IF(BE14>=BE13,BE14-BE13,0) -> 65 | BG14: 25117382 | BH14: =IF(BG14>=BG13,BG14-BG13,0)-(0.45*BN14)-(0.45*BP14)-BR14 -> 6336.45 | BI14: =AP14+AR14+AT14+AV14+AX14+AZ14+BB14+BD14+BF14+BH14 -> 13494.4 | BJ14: =BI14+AN14 -> 27739.74 | BK14: 1458486 | BL14: =IF(BK14>=BK13,BK14-BK13,0) -> 314 | BM14: 4107603 | BN14: =IF(BM14>=BM13,BM14-BM13,0) -> 1425 | BO14: 433662 | BP14: =IF(BO14>=BO13,BO14-BO13,0) -> 134 | BQ14: 541435 | BR14: =IF(BQ14>=BQ13,BQ14-BQ13,0) -> 141 | BS14: =J14+Q14+AN14+BI14 -> 33561.74 | BT14: 168 | BU14: =IF(BS14>0,BS14/BT13,0) -> 231.46028 | BW14: =IF(BS14>0,BS14/BV14,0) -> #DIV/0! | BX14: =((BS14-Q14)*$BZ$1)+(Q14*$BR$1) -> 38866.001 | BY14: =IF(BX14>0,BX14/BT13,0) -> 268.04139 | BZ14: =IF(BX14>0,BX14/BV14,0) -> #DIV/0!
A15: 10 | C15: =IF(+B15-B14>0,B15-B14,(B15-B14)>0)*800 -> 0 | E15: =IF(+D15-D14>0,D15-D14,(D15-D14)>0)*80 -> 0 | G15: =IF(+F15-F14>0,F15-F14,(F15-F14)>0)*10 -> 0 | I15: 24919451 | J15: =IF(I15>=I14,I15-I14,0) -> 5900 | K15: =M15+O15 -> 2880.0214 | L15: -6786.9024 | M15: =IF(L15>=L14,L15-L14,0) -> 1984.0214 | N15: 827946 | O15: =IF(N15>=N14,N15-N14,0) -> 896 | P15: 224490 | Q15: =IF(P15>=P14,P15-P14,0)*30 -> 300 | R15: 205467 | S15: =IF(R15>=R14,R15-R14,0) -> 227 | T15: 374894 | U15: =IF(T15>=T14,T15-T14,0) -> 253 | V15: 199870 | W15: =IF(V15>=V14,V15-V14,0)*0.53 -> 0 | X15: 403653 | Y15: =IF(X15>=X14,X15-X14,0)*0.53 -> 4012.63 | Z15: 467752 | AA15: =IF(Z15>=Z14,Z15-Z14,0)*0.53 -> 4313.14 | AB15: 728830 | AC15: =IF(AB15>=AB14,AB15-AB14,0)*0.53 -> 0 | AD15: 718558 | AE15: =IF(AD15>=AD14,AD15-AD14,0)*0.53 -> 1796.7 | AF15: 882440 | AG15: =IF(AF15>=AF14,AF15-AF14,0)*0.53 -> 11.66 | AH15: 190204 | AI15: =IF(AH15>=AH14,AH15-AH14,0)*0.53 -> 1270.94 | AJ15: 594923 | AK15: =IF(AJ15>=AJ14,AJ15-AJ14,0)*0.53 -> 4106.97 | AL15: 537120 | AM15: =IF(AL15>=AL14,AL15-AL14,0)*0.53 -> 112.36 | AN15: =W15+Y15+AA15+AC15+AE15+AG15+AI15+AK15+AM15 -> 15624.4 | AO15: 7840850 | AP15: =IF(AO15>=AO14,AO15-AO14,0)*0.1125 -> 114.75 | AQ15: 724206 | AR15: =IF(AQ15>=AQ14,AQ15-AQ14,0) -> 171 | AS15: 991259 | AT15: =IF(AS15>=AS14,AS15-AS14,0) -> 197 | AU15: 818127 | AV15: =IF(AU15>=AU14,AU15-AU14,0) -> 57 | AW15: 2745289 | AX15: =IF(AW15>=AW14,AW15-AW14,0) -> 1046 | AY15: 229733 | AZ15: =IF(AY15>=AY14,AY15-AY14,0) -> 0 | BA15: 20065070 | BB15: =IF(BA15>=BA14,BA15-BA14,0) -> 5670 | BC15: 604527 | BD15: =IF(BC15>=BC14,BC15-BC14,0) -> 234 | BE15: 35627 | BF15: =IF(BE15>=BE14,BE15-BE14,0) -> 65 | BG15: 25124140 | BH15: =IF(BG15>=BG14,BG15-BG14,0)-(0.45*BN15)-(0.45*BP15)-BR15 -> 5903.3 | BI15: =AP15+AR15+AT15+AV15+AX15+AZ15+BB15+BD15+BF15+BH15 -> 13458.05 | BJ15: =BI15+AN15 -> 29082.45 | BK15: 1458788 | BL15: =IF(BK15>=BK14,BK15-BK14,0) -> 302 | BM15: 4109028 | BN15: =IF(BM15>=BM14,BM15-BM14,0) -> 1425 | BO15: 433783 | BP15: =IF(BO15>=BO14,BO15-BO14,0) -> 121 | BQ15: 541594 | BR15: =IF(BQ15>=BQ14,BQ15-BQ14,0) -> 159 | BS15: =J15+Q15+AN15+BI15 -> 35282.45 | BT15: 177 | BU15: =IF(BS15>0,BS15/BT14,0) -> 210.01458 | BW15: =IF(BS15>0,BS15/BV15,0) -> #DIV/0! | BX15: =((BS15-Q15)*$BZ$1)+(Q15*$BR$1) -> 40709.817 | BY15: =IF(BX15>0,BX15/BT14,0) -> 242.32034 | BZ15: =IF(BX15>0,BX15/BV15,0) -> #DIV/0!
A16: 11 | C16: =IF(+B16-B15>0,B16-B15,(B16-B15)>0)*800 -> 0 | E16: =IF(+D16-D15>0,D16-D15,(D16-D15)>0)*80 -> 0 | G16: =IF(+F16-F15>0,F16-F15,(F16-F15)>0)*10 -> 0 | H16: 61 | I16: 24923760 | J16: =IF(I16>=I15,I16-I15,0) -> 4309 | K16: =M16+O16 -> 3076.0214 | L16: -4802.881 | M16: =IF(L16>=L15,L16-L15,0) -> 1984.0214 | N16: 829038 | O16: =IF(N16>=N15,N16-N15,0) -> 1092 | P16: 224510 | Q16: =IF(P16>=P15,P16-P15,0)*30 -> 600 | R16: 205694 | S16: =IF(R16>=R15,R16-R15,0) -> 227 | T16: 375154 | U16: =IF(T16>=T15,T16-T15,0) -> 260 | V16: 199870 | W16: =IF(V16>=V15,V16-V15,0)*0.53 -> 0 | X16: 409772 | Y16: =IF(X16>=X15,X16-X15,0)*0.53 -> 3243.07 | Z16: 474469 | AA16: =IF(Z16>=Z15,Z16-Z15,0)*0.53 -> 3560.01 | AB16: 728830 | AC16: =IF(AB16>=AB15,AB16-AB15,0)*0.53 -> 0 | AD16: 721085 | AE16: =IF(AD16>=AD15,AD16-AD15,0)*0.53 -> 1339.31 | AF16: 882456 | AG16: =IF(AF16>=AF15,AF16-AF15,0)*0.53 -> 8.48 | AH16: 192192 | AI16: =IF(AH16>=AH15,AH16-AH15,0)*0.53 -> 1053.64 | AJ16: 601354 | AK16: =IF(AJ16>=AJ15,AJ16-AJ15,0)*0.53 -> 3408.43 | AL16: 537299 | AM16: =IF(AL16>=AL15,AL16-AL15,0)*0.53 -> 94.87 | AN16: =W16+Y16+AA16+AC16+AE16+AG16+AI16+AK16+AM16 -> 12707.81 | AO16: 7842708 | AP16: =IF(AO16>=AO15,AO16-AO15,0)*0.1125 -> 209.025 | AQ16: 724379 | AR16: =IF(AQ16>=AQ15,AQ16-AQ15,0) -> 173 | AS16: 991455 | AT16: =IF(AS16>=AS15,AS16-AS15,0) -> 196 | AU16: 818171 | AV16: =IF(AU16>=AU15,AU16-AU15,0) -> 44 | AW16: 2746335 | AX16: =IF(AW16>=AW15,AW16-AW15,0) -> 1046 | AY16: 229733 | AZ16: =IF(AY16>=AY15,AY16-AY15,0) -> 0 | BA16: 20070010 | BB16: =IF(BA16>=BA15,BA16-BA15,0) -> 4940 | BC16: 604764 | BD16: =IF(BC16>=BC15,BC16-BC15,0) -> 237 | BE16: 35739 | BF16: =IF(BE16>=BE15,BE16-BE15,0) -> 112 | BG16: 25130957 | BH16: =IF(BG16>=BG15,BG16-BG15,0)-(0.45*BN16)-(0.45*BP16)-BR16 -> 6046.35 | BI16: =AP16+AR16+AT16+AV16+AX16+AZ16+BB16+BD16+BF16+BH16 -> 13003.375 | BJ16: =BI16+AN16 -> 25711.185 | BK16: 1459094 | BL16: =IF(BK16>=BK15,BK16-BK15,0) -> 306 | BM16: 4110268 | BN16: =IF(BM16>=BM15,BM16-BM15,0) -> 1240 | BO16: 433900 | BP16: =IF(BO16>=BO15,BO16-BO15,0) -> 117 | BQ16: 541754 | BR16: =IF(BQ16>=BQ15,BQ16-BQ15,0) -> 160 | BS16: =J16+Q16+AN16+BI16 -> 30620.185 | BT16: 177 | BU16: =IF(BS16>0,BS16/BT15,0) -> 172.9954 | BW16: =IF(BS16>0,BS16/BV16,0) -> #DIV/0! | BX16: =((BS16-Q16)*$BZ$1)+(Q16*$BR$1) -> 35483.213 | BY16: =IF(BX16>0,BX16/BT15,0) -> 200.47013 | BZ16: =IF(BX16>0,BX16/BV16,0) -> #DIV/0!
A17: 12 | C17: =IF(+B17-B16>0,B17-B16,(B17-B16)>0)*800 -> 0 | E17: =IF(+D17-D16>0,D17-D16,(D17-D16)>0)*80 -> 0 | G17: =IF(+F17-F16>0,F17-F16,(F17-F16)>0)*10 -> 0 | I17: 24929565 | J17: =IF(I17>=I16,I17-I16,0) -> 5805 | K17: =M17+O17 -> 3075.0214 | L17: -2818.8595 | M17: =IF(L17>=L16,L17-L16,0) -> 1984.0214 | N17: 830129 | O17: =IF(N17>=N16,N17-N16,0) -> 1091 | P17: 224530 | Q17: =IF(P17>=P16,P17-P16,0)*30 -> 600 | R17: 205928 | S17: =IF(R17>=R16,R17-R16,0) -> 234 | T17: 375430 | U17: =IF(T17>=T16,T17-T16,0) -> 276 | V17: 199870 | W17: =IF(V17>=V16,V17-V16,0)*0.53 -> 0 | X17: 417082 | Y17: =IF(X17>=X16,X17-X16,0)*0.53 -> 3874.3 | Z17: 482136 | AA17: =IF(Z17>=Z16,Z17-Z16,0)*0.53 -> 4063.51 | AB17: 728830 | AC17: =IF(AB17>=AB16,AB17-AB16,0)*0.53 -> 0 | AD17: 724073 | AE17: =IF(AD17>=AD16,AD17-AD16,0)*0.53 -> 1583.64 | AF17: 882476 | AG17: =IF(AF17>=AF16,AF17-AF16,0)*0.53 -> 10.6 | AH17: 194477 | AI17: =IF(AH17>=AH16,AH17-AH16,0)*0.53 -> 1211.05 | AJ17: 608677 | AK17: =IF(AJ17>=AJ16,AJ17-AJ16,0)*0.53 -> 3881.19 | AL17: 537516 | AM17: =IF(AL17>=AL16,AL17-AL16,0)*0.53 -> 115.01 | AN17: =W17+Y17+AA17+AC17+AE17+AG17+AI17+AK17+AM17 -> 14739.3 | AO17: 7844980 | AP17: =IF(AO17>=AO16,AO17-AO16,0)*0.1125 -> 255.6 | AQ17: 724559 | AR17: =IF(AQ17>=AQ16,AQ17-AQ16,0) -> 180 | AS17: 991640 | AT17: =IF(AS17>=AS16,AS17-AS16,0) -> 185 | AU17: 818227 | AV17: =IF(AU17>=AU16,AU17-AU16,0) -> 56 | AW17: 2747266 | AX17: =IF(AW17>=AW16,AW17-AW16,0) -> 931 | AY17: 229733 | AZ17: =IF(AY17>=AY16,AY17-AY16,0) -> 0 | BA17: 20075450 | BB17: =IF(BA17>=BA16,BA17-BA16,0) -> 5440 | BC17: 604981 | BD17: =IF(BC17>=BC16,BC17-BC16,0) -> 217 | BE17: 35804 | BF17: =IF(BE17>=BE16,BE17-BE16,0) -> 65 | BG17: 25138050 | BH17: =IF(BG17>=BG16,BG17-BG16,0)-(0.45*BN17)-(0.45*BP17)-BR17 -> 6269.05 | BI17: =AP17+AR17+AT17+AV17+AX17+AZ17+BB17+BD17+BF17+BH17 -> 13598.65 | BJ17: =BI17+AN17 -> 28337.95 | BK17: 1459404 | BL17: =IF(BK17>=BK16,BK17-BK16,0) -> 310 | BM17: 4111655 | BN17: =IF(BM17>=BM16,BM17-BM16,0) -> 1387 | BO17: 434024 | BP17: =IF(BO17>=BO16,BO17-BO16,0) -> 124 | BQ17: 541898 | BR17: =IF(BQ17>=BQ16,BQ17-BQ16,0) -> 144 | BS17: =J17+Q17+AN17+BI17 -> 34742.95 | BT17: 204 | BU17: =IF(BS17>0,BS17/BT16,0) -> 196.28785 | BW17: =IF(BS17>0,BS17/BV17,0) -> #DIV/0! | BX17: =((BS17-Q17)*$BZ$1)+(Q17*$BR$1) -> 40224.393 | BY17: =IF(BX17>0,BX17/BT16,0) -> 227.25645 | BZ17: =IF(BX17>0,BX17/BV17,0) -> #DIV/0!
A18: 13 | C18: =IF(+B18-B17>0,B18-B17,(B18-B17)>0)*800 -> 0 | E18: =IF(+D18-D17>0,D18-D17,(D18-D17)>0)*80 -> 0 | G18: =IF(+F18-F17>0,F18-F17,(F18-F17)>0)*10 -> 0 | H18: 62 | I18: 24935220 | J18: =IF(I18>=I17,I18-I17,0) -> 5655 | K18: =M18+O18 -> 3076.0214 | L18: -834.8381 | M18: =IF(L18>=L17,L18-L17,0) -> 1984.0214 | N18: 831221 | O18: =IF(N18>=N17,N18-N17,0) -> 1092 | P18: 224540 | Q18: =IF(P18>=P17,P18-P17,0)*30 -> 300 | R18: 206157 | S18: =IF(R18>=R17,R18-R17,0) -> 229 | T18: 375690 | U18: =IF(T18>=T17,T18-T17,0) -> 260 | V18: 204625 | W18: =IF(V18>=V17,V18-V17,0)*0.53 -> 2520.15 | X18: 424056 | Y18: =IF(X18>=X17,X18-X17,0)*0.53 -> 3696.22 | Z18: 483756 | AA18: =IF(Z18>=Z17,Z18-Z17,0)*0.53 -> 858.6 | AB18: 728899 | AC18: =IF(AB18>=AB17,AB18-AB17,0)*0.53 -> 36.57 | AD18: 724858 | AE18: =IF(AD18>=AD17,AD18-AD17,0)*0.53 -> 416.05 | AF18: 889735 | AG18: =IF(AF18>=AF17,AF18-AF17,0)*0.53 -> 3847.27 | AH18: 196676 | AI18: =IF(AH18>=AH17,AH18-AH17,0)*0.53 -> 1165.47 | AJ18: 615785 | AK18: =IF(AJ18>=AJ17,AJ18-AJ17,0)*0.53 -> 3767.24 | AL18: 537715 | AM18: =IF(AL18>=AL17,AL18-AL17,0)*0.53 -> 105.47 | AN18: =W18+Y18+AA18+AC18+AE18+AG18+AI18+AK18+AM18 -> 16413.04 | AO18: 7846935 | AP18: =IF(AO18>=AO17,AO18-AO17,0)*0.1125 -> 219.9375 | AQ18: 724751 | AR18: =IF(AQ18>=AQ17,AQ18-AQ17,0) -> 192 | AS18: 991815 | AT18: =IF(AS18>=AS17,AS18-AS17,0) -> 175 | AU18: 818288 | AV18: =IF(AU18>=AU17,AU18-AU17,0) -> 61 | AW18: 2748242 | AX18: =IF(AW18>=AW17,AW18-AW17,0) -> 976 | AY18: 229733 | AZ18: =IF(AY18>=AY17,AY18-AY17,0) -> 0 | BA18: 20080660 | BB18: =IF(BA18>=BA17,BA18-BA17,0) -> 5210 | BC18: 605180 | BD18: =IF(BC18>=BC17,BC18-BC17,0) -> 199 | BE18: 35869 | BF18: =IF(BE18>=BE17,BE18-BE17,0) -> 65 | BG18: 25144990 | BH18: =IF(BG18>=BG17,BG18-BG17,0)-(0.45*BN18)-(0.45*BP18)-BR18 -> 6066.5 | BI18: =AP18+AR18+AT18+AV18+AX18+AZ18+BB18+BD18+BF18+BH18 -> 13164.438 | BJ18: =BI18+AN18 -> 29577.478 | BK18: 1459710 | BL18: =IF(BK18>=BK17,BK18-BK17,0) -> 306 | BM18: 4113124 | BN18: =IF(BM18>=BM17,BM18-BM17,0) -> 1469 | BO18: 434145 | BP18: =IF(BO18>=BO17,BO18-BO17,0) -> 121 | BQ18: 542056 | BR18: =IF(BQ18>=BQ17,BQ18-BQ17,0) -> 158 | BS18: =J18+Q18+AN18+BI18 -> 35532.478 | BT18: 182 | BU18: =IF(BS18>0,BS18/BT17,0) -> 174.17881 | BW18: =IF(BS18>0,BS18/BV18,0) -> #DIV/0! | BX18: =((BS18-Q18)*$BZ$1)+(Q18*$BR$1) -> 40997.349 | BY18: =IF(BX18>0,BX18/BT17,0) -> 200.9674 | BZ18: =IF(BX18>0,BX18/BV18,0) -> #DIV/0!
A19: 14 | C19: =IF(+B19-B18>0,B19-B18,(B19-B18)>0)*800 -> 0 | E19: =IF(+D19-D18>0,D19-D18,(D19-D18)>0)*80 -> 0 | G19: =IF(+F19-F18>0,F19-F18,(F19-F18)>0)*10 -> 0 | I19: 24941174 | J19: =IF(I19>=I18,I19-I18,0) -> 5954 | K19: =M19+O19 -> 1831.8381 | L19: 997 | M19: =IF(L19>=L18,L19-L18,0) -> 1831.8381 | N19: 1682 | O19: =IF(N19>=N18,N19-N18,0) -> 0 | P19: 224560 | Q19: =IF(P19>=P18,P19-P18,0)*30 -> 600 | R19: 206381 | S19: =IF(R19>=R18,R19-R18,0) -> 224 | T19: 375938 | U19: =IF(T19>=T18,T19-T18,0) -> 248 | V19: 210157 | W19: =IF(V19>=V18,V19-V18,0)*0.53 -> 2931.96 | X19: 425491 | Y19: =IF(X19>=X18,X19-X18,0)*0.53 -> 760.55 | Z19: 483756 | AA19: =IF(Z19>=Z18,Z19-Z18,0)*0.53 -> 0 | AB19: 734054 | AC19: =IF(AB19>=AB18,AB19-AB18,0)*0.53 -> 2732.15 | AD19: 724881 | AE19: =IF(AD19>=AD18,AD19-AD18,0)*0.53 -> 12.19 | AF19: 887421 | AG19: =IF(AF19>=AF18,AF19-AF18,0)*0.53 -> 0 | AH19: 198820 | AI19: =IF(AH19>=AH18,AH19-AH18,0)*0.53 -> 1136.32 | AJ19: 622696 | AK19: =IF(AJ19>=AJ18,AJ19-AJ18,0)*0.53 -> 3662.83 | AL19: 537910 | AM19: =IF(AL19>=AL18,AL19-AL18,0)*0.53 -> 103.35 | AN19: =W19+Y19+AA19+AC19+AE19+AG19+AI19+AK19+AM19 -> 11339.35 | AO19: 7848731 | AP19: =IF(AO19>=AO18,AO19-AO18,0)*0.1125 -> 202.05 | AQ19: 724899 | AR19: =IF(AQ19>=AQ18,AQ19-AQ18,0) -> 148 | AS19: 992012 | AT19: =IF(AS19>=AS18,AS19-AS18,0) -> 197 | AU19: 818337 | AV19: =IF(AU19>=AU18,AU19-AU18,0) -> 49 | AW19: 2749180 | AX19: =IF(AW19>=AW18,AW19-AW18,0) -> 938 | AY19: 229733 | AZ19: =IF(AY19>=AY18,AY19-AY18,0) -> 0 | BA19: 20085893 | BB19: =IF(BA19>=BA18,BA19-BA18,0) -> 5233 | BC19: 605377 | BD19: =IF(BC19>=BC18,BC19-BC18,0) -> 197 | BE19: 35934 | BF19: =IF(BE19>=BE18,BE19-BE18,0) -> 65 | BG19: 25151870 | BH19: =IF(BG19>=BG18,BG19-BG18,0)-(0.45*BN19)-(0.45*BP19)-BR19 -> 6173.5 | BI19: =AP19+AR19+AT19+AV19+AX19+AZ19+BB19+BD19+BF19+BH19 -> 13202.55 | BJ19: =BI19+AN19 -> 24541.9 | BK19: 1460012 | BL19: =IF(BK19>=BK18,BK19-BK18,0) -> 302 | BM19: 4114300 | BN19: =IF(BM19>=BM18,BM19-BM18,0) -> 1176 | BO19: 434259 | BP19: =IF(BO19>=BO18,BO19-BO18,0) -> 114 | BQ19: 542182 | BR19: =IF(BQ19>=BQ18,BQ19-BQ18,0) -> 126 | BS19: =J19+Q19+AN19+BI19 -> 31095.9 | BT19: 251 | BU19: =IF(BS19>0,BS19/BT18,0) -> 170.85659 | BW19: =IF(BS19>0,BS19/BV19,0) -> #DIV/0! | BX19: =((BS19-Q19)*$BZ$1)+(Q19*$BR$1) -> 36030.285 | BY19: =IF(BX19>0,BX19/BT18,0) -> 197.9686 | BZ19: =IF(BX19>0,BX19/BV19,0) -> #DIV/0!
A20: 15 | C20: =IF(+B20-B19>0,B20-B19,(B20-B19)>0)*800 -> 0 | E20: =IF(+D20-D19>0,D20-D19,(D20-D19)>0)*80 -> 0 | G20: =IF(+F20-F19>0,F20-F19,(F20-F19)>0)*10 -> 0 | H20: 63 | I20: 24947582 | J20: =IF(I20>=I19,I20-I19,0) -> 6408 | K20: =M20+O20 -> 5605 | L20: 3110 | M20: =IF(L20>=L19,L20-L19,0) -> 2113 | N20: 5174 | O20: =IF(N20>=N19,N20-N19,0) -> 3492 | P20: 224580 | Q20: =IF(P20>=P19,P20-P19,0)*30 -> 600 | R20: 206613 | S20: =IF(R20>=R19,R20-R19,0) -> 232 | T20: 376201 | U20: =IF(T20>=T19,T20-T19,0) -> 263 | V20: 215903 | W20: =IF(V20>=V19,V20-V19,0)*0.53 -> 3045.38 | X20: 425491 | Y20: =IF(X20>=X19,X20-X19,0)*0.53 -> 0 | Z20: 483756 | AA20: =IF(Z20>=Z19,Z20-Z19,0)*0.53 -> 0 | AB20: 740869 | AC20: =IF(AB20>=AB19,AB20-AB19,0)*0.53 -> 3611.95 | AD20: 724905 | AE20: =IF(AD20>=AD19,AD20-AD19,0)*0.53 -> 12.72 | AF20: 890114 | AG20: =IF(AF20>=AF19,AF20-AF19,0)*0.53 -> 1427.29 | AH20: 201059 | AI20: =IF(AH20>=AH19,AH20-AH19,0)*0.53 -> 1186.67 | AJ20: 629893 | AK20: =IF(AJ20>=AJ19,AJ20-AJ19,0)*0.53 -> 3814.41 | AL20: 538112 | AM20: =IF(AL20>=AL19,AL20-AL19,0)*0.53 -> 107.06 | AN20: =W20+Y20+AA20+AC20+AE20+AG20+AI20+AK20+AM20 -> 13205.48 | AO20: 7850758 | AP20: =IF(AO20>=AO19,AO20-AO19,0)*0.1125 -> 228.0375 | AQ20: 725060 | AR20: =IF(AQ20>=AQ19,AQ20-AQ19,0) -> 161 | AS20: 992212 | AT20: =IF(AS20>=AS19,AS20-AS19,0) -> 200 | AU20: 818387 | AV20: =IF(AU20>=AU19,AU20-AU19,0) -> 50 | AW20: 2750150 | AX20: =IF(AW20>=AW19,AW20-AW19,0) -> 970 | AY20: 229733 | AZ20: =IF(AY20>=AY19,AY20-AY19,0) -> 0 | BA20: 20091327 | BB20: =IF(BA20>=BA19,BA20-BA19,0) -> 5434 | BC20: 605587 | BD20: =IF(BC20>=BC19,BC20-BC19,0) -> 210 | BE20: 35997 | BF20: =IF(BE20>=BE19,BE20-BE19,0) -> 63 | BG20: 25159006 | BH20: =IF(BG20>=BG19,BG20-BG19,0)-(0.45*BN20)-(0.45*BP20)-BR20 -> 6109.45 | BI20: =AP20+AR20+AT20+AV20+AX20+AZ20+BB20+BD20+BF20+BH20 -> 13425.487 | BJ20: =BI20+AN20 -> 26630.967 | BK20: 1460327 | BL20: =IF(BK20>=BK19,BK20-BK19,0) -> 315 | BM20: 4116105 | BN20: =IF(BM20>=BM19,BM20-BM19,0) -> 1805 | BO20: 434373 | BP20: =IF(BO20>=BO19,BO20-BO19,0) -> 114 | BQ20: 542345 | BR20: =IF(BQ20>=BQ19,BQ20-BQ19,0) -> 163 | BS20: =J20+Q20+AN20+BI20 -> 33638.967 | BT20: 230 | BU20: =IF(BS20>0,BS20/BT20,0) -> 146.25638 | BW20: =IF(BS20>0,BS20/BV20,0) -> #DIV/0! | BX20: =((BS20-Q20)*$BZ$1)+(Q20*$BR$1) -> 38954.813 | BY20: =IF(BX20>0,BX20/BT20,0) -> 169.36875 | BZ20: =IF(BX20>0,BX20/BV20,0) -> #DIV/0!
A21: 16 | C21: =IF(+B21-B20>0,B21-B20,(B21-B20)>0)*800 -> 0 | E21: =IF(+D21-D20>0,D21-D20,(D21-D20)>0)*80 -> 0 | G21: =IF(+F21-F20>0,F21-F20,(F21-F20)>0)*10 -> 0 | I21: 24953115 | J21: =IF(I21>=I20,I21-I20,0) -> 5533 | K21: =M21+O21 -> 5066 | L21: 5139 | M21: =IF(L21>=L20,L21-L20,0) -> 2029 | N21: 8211 | O21: =IF(N21>=N20,N21-N20,0) -> 3037 | P21: 224590 | Q21: =IF(P21>=P20,P21-P20,0)*30 -> 300 | R21: 206810 | S21: =IF(R21>=R20,R21-R20,0) -> 197 | T21: 376464 | U21: =IF(T21>=T20,T21-T20,0) -> 263 | V21: 219482 | W21: =IF(V21>=V20,V21-V20,0)*0.53 -> 1896.87 | X21: 427650 | Y21: =IF(X21>=X20,X21-X20,0)*0.53 -> 1144.27 | Z21: 483904 | AA21: =IF(Z21>=Z20,Z21-Z20,0)*0.53 -> 78.44 | AB21: 747266 | AC21: =IF(AB21>=AB20,AB21-AB20,0)*0.53 -> 3390.41 | AD21: 724927 | AE21: =IF(AD21>=AD20,AD21-AD20,0)*0.53 -> 11.66 | AF21: 892497 | AG21: =IF(AF21>=AF20,AF21-AF20,0)*0.53 -> 1262.99 | AH21: 203221 | AI21: =IF(AH21>=AH20,AH21-AH20,0)*0.53 -> 1145.86 | AJ21: 636833 | AK21: =IF(AJ21>=AJ20,AJ21-AJ20,0)*0.53 -> 3678.2 | AL21: 538309 | AM21: =IF(AL21>=AL20,AL21-AL20,0)*0.53 -> 104.41 | AN21: =W21+Y21+AA21+AC21+AE21+AG21+AI21+AK21+AM21 -> 12713.11 | AO21: 7853082 | AP21: =IF(AO21>=AO20,AO21-AO20,0)*0.1125 -> 261.45 | AQ21: 725216 | AR21: =IF(AQ21>=AQ20,AQ21-AQ20,0) -> 156 | AS21: 992397 | AT21: =IF(AS21>=AS20,AS21-AS20,0) -> 185 | AU21: 818437 | AV21: =IF(AU21>=AU20,AU21-AU20,0) -> 50 | AW21: 2751117 | AX21: =IF(AW21>=AW20,AW21-AW20,0) -> 967 | AY21: 229733 | AZ21: =IF(AY21>=AY20,AY21-AY20,0) -> 0 | BA21: 20096576 | BB21: =IF(BA21>=BA20,BA21-BA20,0) -> 5249 | BC21: 605970 | BD21: =IF(BC21>=BC20,BC21-BC20,0) -> 383 | BE21: 36062 | BF21: =IF(BE21>=BE20,BE21-BE20,0) -> 65 | BG21: 25165724 | BH21: =IF(BG21>=BG20,BG21-BG20,0)-(0.45*BN21)-(0.45*BP21)-BR21 -> 5908.4 | BI21: =AP21+AR21+AT21+AV21+AX21+AZ21+BB21+BD21+BF21+BH21 -> 13224.85 | BJ21: =BI21+AN21 -> 25937.96 | BK21: 1460534 | BL21: =IF(BK21>=BK20,BK21-BK20,0) -> 207 | BM21: 4117561 | BN21: =IF(BM21>=BM20,BM21-BM20,0) -> 1456 | BO21: 434485 | BP21: =IF(BO21>=BO20,BO21-BO20,0) -> 112 | BQ21: 542449 | BR21: =IF(BQ21>=BQ20,BQ21-BQ20,0) -> 104 | BS21: =J21+Q21+AN21+BI21 -> 31770.96 | BT21: 192 | BU21: =IF(BS21>0,BS21/BT21,0) -> 165.47375 | BW21: =IF(BS21>0,BS21/BV21,0) -> #DIV/0! | BX21: =((BS21-Q21)*$BZ$1)+(Q21*$BR$1) -> 36671.604 | BY21: =IF(BX21>0,BX21/BT21,0) -> 190.99794 | BZ21: =IF(BX21>0,BX21/BV21,0) -> #DIV/0!
