Workbook

Sheet TOTAL
A1: Site Name | B1: Day | C1: Month | D1: Year | E1: Total Electricity Kwh | F1: Electricity Tariff ($/Kwh) | G1: LPG (Kg) | H1: LPG $/Kg | I1: Water Utility Supply (m3) m3 | J1: Water Utility Supply (m3) $/m3 | K1: Irrigation Water (m3) m3 | L1: Irrigation water $/m3 | M1: Room Nights
A2: Seychelles | B2: 1 | C2: 7 | D2: 2022 | E2: ='Submetering '!O2+'Submetering '!P2+'Submetering '!Q2+'Submetering '!R2+'Submetering '!S2+'Submetering '!U2 -> 26215 | F2: =(('FS Seychelles'!R3*'FS Seychelles'!S3)+('FS Seychelles'!T3*'FS Seychelles'!U3))/TOTAL!E2 -> 0.3295514 | G2: =('FS Seychelles'!$AC$10+'FS Seychelles'!$AC$15)/30 -> 426.66667 | H2: 1.05 | I2: ='FS Seychelles'!V3+'FS Seychelles'!#REF!+'FS Seychelles'!W3+'FS Seychelles'!X3 -> #REF! | J2: 0 | K2: ='Submetering '!Z2 -> 87 | L2: 0 | M2: ='FS Seychelles'!B3 -> 64.5
A3: Seychelles | B3: =B2+1 -> 2 | C3: 7 | D3: 2022 | E3: ='Submetering '!O3+'Submetering '!P3+'Submetering '!Q3+'Submetering '!R3+'Submetering '!S3+'Submetering '!U3 -> 27379 | F3: =(('FS Seychelles'!R4*'FS Seychelles'!S4)+('FS Seychelles'!T4*'FS Seychelles'!U4))/TOTAL!E3 -> 0.29434853 | G3: =('FS Seychelles'!$AC$10+'FS Seychelles'!$AC$15)/30 -> 426.66667 | H3: =H2 -> 1.05 | I3: ='FS Seychelles'!V4+'FS Seychelles'!#REF!+'FS Seychelles'!W4+'FS Seychelles'!X4 -> #REF! | J3: =J2 -> 0 | K3: ='Submetering '!Z3 -> 26 | L3: =L2 -> 0 | M3: ='FS Seychelles'!B4 -> 65.8
A4: Seychelles | B4: =B3+1 -> 3 | C4: 7 | D4: 2022 | E4: ='Submetering '!O4+'Submetering '!P4+'Submetering '!Q4+'Submetering '!R4+'Submetering '!S4+'Submetering '!U4 -> 35381 | F4: =(('FS Seychelles'!R5*'FS Seychelles'!S5)+('FS Seychelles'!T5*'FS Seychelles'!U5))/TOTAL!E4 -> 0.3242649 | G4: =('FS Seychelles'!$AC$10+'FS Seychelles'!$AC$15)/30 -> 426.66667 | H4: =H3 -> 1.05 | I4: ='FS Seychelles'!V5+'FS Seychelles'!#REF!+'FS Seychelles'!W5+'FS Seychelles'!X5 -> #REF! | J4: =J3 -> 0 | K4: ='Submetering '!Z4 -> 86 | L4: =L3 -> 0 | M4: ='FS Seychelles'!B5 -> 69.7
A5: Seychelles | B5: =B4+1 -> 4 | C5: 7 | D5: 2022 | E5: ='Submetering '!O5+'Submetering '!P5+'Submetering '!Q5+'Submetering '!R5+'Submetering '!S5+'Submetering '!U5 -> 29070 | F5: =(('FS Seychelles'!R6*'FS Seychelles'!S6)+('FS Seychelles'!T6*'FS Seychelles'!U6))/TOTAL!E5 -> 0.32280879 | G5: =('FS Seychelles'!$AC$10+'FS Seychelles'!$AC$15)/30 -> 426.66667 | H5: =H4 -> 1.05 | I5: ='FS Seychelles'!V6+'FS Seychelles'!#REF!+'FS Seychelles'!W6+'FS Seychelles'!X6 -> #REF! | J5: =J4 -> 0 | K5: ='Submetering '!Z5 -> 88 | L5: =L4 -> 0 | M5: ='FS Seychelles'!B6 -> 65.8
A6: Seychelles | B6: =B5+1 -> 5 | C6: 7 | D6: 2022 | E6: ='Submetering '!O6+'Submetering '!P6+'Submetering '!Q6+'Submetering '!R6+'Submetering '!S6+'Submetering '!U6 -> 30896 | F6: =(('FS Seychelles'!R7*'FS Seychelles'!S7)+('FS Seychelles'!T7*'FS Seychelles'!U7))/TOTAL!E6 -> 0.31293426 | G6: =('FS Seychelles'!$AC$10+'FS Seychelles'!$AC$15)/30 -> 426.66667 | H6: =H5 -> 1.05 | I6: ='FS Seychelles'!V7+'FS Seychelles'!#REF!+'FS Seychelles'!W7+'FS Seychelles'!X7 -> #REF! | J6: =J5 -> 0 | K6: ='Submetering '!Z6 -> 86 | L6: =L5 -> 0 | M6: ='FS Seychelles'!B7 -> 51.3
A7: Seychelles | B7: =B6+1 -> 6 | C7: 7 | D7: 2022 | E7: ='Submetering '!O7+'Submetering '!P7+'Submetering '!Q7+'Submetering '!R7+'Submetering '!S7+'Submetering '!U7 -> 28768 | F7: =(('FS Seychelles'!R8*'FS Seychelles'!S8)+('FS Seychelles'!T8*'FS Seychelles'!U8))/TOTAL!E7 -> 0.33012091 | G7: =('FS Seychelles'!$AC$10+'FS Seychelles'!$AC$15)/30 -> 426.66667 | H7: =H6 -> 1.05 | I7: ='FS Seychelles'!V8+'FS Seychelles'!#REF!+'FS Seychelles'!W8+'FS Seychelles'!X8 -> #REF! | J7: =J6 -> 0 | K7: ='Submetering '!Z7 -> 92 | L7: =L6 -> 0 | M7: ='FS Seychelles'!B8 -> 55.3
A8: Seychelles | B8: =B7+1 -> 7 | C8: 7 | D8: 2022 | E8: ='Submetering '!O8+'Submetering '!P8+'Submetering '!Q8+'Submetering '!R8+'Submetering '!S8+'Submetering '!U8 -> 32176 | F8: =(('FS Seychelles'!R9*'FS Seychelles'!S9)+('FS Seychelles'!T9*'FS Seychelles'!U9))/TOTAL!E8 -> 0.31638429 | G8: =('FS Seychelles'!$AC$10+'FS Seychelles'!$AC$15)/30 -> 426.66667 | H8: =H7 -> 1.05 | I8: ='FS Seychelles'!V9+'FS Seychelles'!#REF!+'FS Seychelles'!W9+'FS Seychelles'!X9 -> #REF! | J8: =J7 -> 0 | K8: ='Submetering '!Z8 -> 92 | L8: =L7 -> 0 | M8: ='FS Seychelles'!B9 -> 61.8
A9: Seychelles | B9: =B8+1 -> 8 | C9: 7 | D9: 2022 | E9: ='Submetering '!O9+'Submetering '!P9+'Submetering '!Q9+'Submetering '!R9+'Submetering '!S9+'Submetering '!U9 -> 31335 | F9: =(('FS Seychelles'!R10*'FS Seychelles'!S10)+('FS Seychelles'!T10*'FS Seychelles'!U10))/TOTAL!E9 -> 0.31958978 | G9: =('FS Seychelles'!$AC$10+'FS Seychelles'!$AC$15)/30 -> 426.66667 | H9: =H8 -> 1.05 | I9: ='FS Seychelles'!V10+'FS Seychelles'!#REF!+'FS Seychelles'!W10+'FS Seychelles'!X10 -> #REF! | J9: =J8 -> 0 | K9: ='Submetering '!Z9 -> 95 | L9: =L8 -> 0 | M9: ='FS Seychelles'!B10 -> 63.2
A10: Seychelles | B10: =B9+1 -> 9 | C10: 7 | D10: 2022 | E10: ='Submetering '!O10+'Submetering '!P10+'Submetering '!Q10+'Submetering '!R10+'Submetering '!S10+'Submetering '!U10 -> 31068 | F10: =(('FS Seychelles'!R11*'FS Seychelles'!S11)+('FS Seychelles'!T11*'FS Seychelles'!U11))/TOTAL!E10 -> 0.31398542 | G10: =('FS Seychelles'!$AC$10+'FS Seychelles'!$AC$15)/30 -> 426.66667 | H10: =H9 -> 1.05 | I10: ='FS Seychelles'!V11+'FS Seychelles'!#REF!+'FS Seychelles'!W11+'FS Seychelles'!X11 -> #REF! | J10: =J9 -> 0 | K10: ='Submetering '!Z10 -> 95 | L10: =L9 -> 0 | M10: ='FS Seychelles'!B11 -> 63.2
A11: Seychelles | B11: =B10+1 -> 10 | C11: 7 | D11: 2022 | E11: ='Submetering '!O11+'Submetering '!P11+'Submetering '!Q11+'Submetering '!R11+'Submetering '!S11+'Submetering '!U11 -> 31633 | F11: =(('FS Seychelles'!R12*'FS Seychelles'!S12)+('FS Seychelles'!T12*'FS Seychelles'!U12))/TOTAL!E11 -> 0.32186156 | G11: =('FS Seychelles'!$AC$10+'FS Seychelles'!$AC$15)/30 -> 426.66667 | H11: =H10 -> 1.05 | I11: ='FS Seychelles'!V12+'FS Seychelles'!#REF!+'FS Seychelles'!W12+'FS Seychelles'!X12 -> #REF! | J11: =J10 -> 0 | K11: ='Submetering '!Z11 -> 92 | L11: =L10 -> 0 | M11: ='FS Seychelles'!B12 -> 67.1
A12: Seychelles | B12: =B11+1 -> 11 | C12: 7 | D12: 2022 | E12: ='Submetering '!O12+'Submetering '!P12+'Submetering '!Q12+'Submetering '!R12+'Submetering '!S12+'Submetering '!U12 -> 30878 | F12: =(('FS Seychelles'!R13*'FS Seychelles'!S13)+('FS Seychelles'!T13*'FS Seychelles'!U13))/TOTAL!E12 -> 0.31776881 | G12: =('FS Seychelles'!$AC$10+'FS Seychelles'!$AC$15)/30 -> 426.66667 | H12: =H11 -> 1.05 | I12: ='FS Seychelles'!V13+'FS Seychelles'!#REF!+'FS Seychelles'!W13+'FS Seychelles'!X13 -> #REF! | J12: =J11 -> 0 | K12: ='Submetering '!Z12 -> 98 | L12: =L11 -> 0 | M12: ='FS Seychelles'!B13 -> 69.7
A13: Seychelles | B13: =B12+1 -> 12 | C13: 7 | D13: 2022 | E13: ='Submetering '!O13+'Submetering '!P13+'Submetering '!Q13+'Submetering '!R13+'Submetering '!S13+'Submetering '!U13 -> 30654 | F13: =(('FS Seychelles'!R14*'FS Seychelles'!S14)+('FS Seychelles'!T14*'FS Seychelles'!U14))/TOTAL!E13 -> 0.31827379 | G13: =('FS Seychelles'!$AC$10+'FS Seychelles'!$AC$15)/30 -> 426.66667 | H13: =H12 -> 1.05 | I13: ='FS Seychelles'!V14+'FS Seychelles'!#REF!+'FS Seychelles'!W14+'FS Seychelles'!X14 -> #REF! | J13: =J12 -> 0 | K13: ='Submetering '!Z13 -> 94 | L13: =L12 -> 0 | M13: ='FS Seychelles'!B14 -> 68.4
A14: Seychelles | B14: =B13+1 -> 13 | C14: 7 | D14: 2022 | E14: ='Submetering '!O14+'Submetering '!P14+'Submetering '!Q14+'Submetering '!R14+'Submetering '!S14+'Submetering '!U14 -> 30975 | F14: =(('FS Seychelles'!R15*'FS Seychelles'!S15)+('FS Seychelles'!T15*'FS Seychelles'!U15))/TOTAL!E14 -> 0.31947105 | G14: =('FS Seychelles'!$AC$10+'FS Seychelles'!$AC$15)/30 -> 426.66667 | H14: =H13 -> 1.05 | I14: ='FS Seychelles'!V15+'FS Seychelles'!#REF!+'FS Seychelles'!W15+'FS Seychelles'!X15 -> #REF! | J14: =J13 -> 0 | K14: ='Submetering '!Z14 -> 97 | L14: =L13 -> 0 | M14: ='FS Seychelles'!B15 -> 64.5
... A32: Seychelles | B32: =B31+1 -> 31 | C32: 7 | D32: 2022 | E32: ='Submetering '!O32+'Submetering '!P32+'Submetering '!Q32+'Submetering '!R32+'Submetering '!S32+'Submetering '!U32 -> 29961 | F32: =(('FS Seychelles'!R33*'FS Seychelles'!S33)+('FS Seychelles'!T33*'FS Seychelles'!U33))/TOTAL!E32 -> 0.32263599 | G32: =('FS Seychelles'!$AC$10+'FS Seychelles'!$AC$15)/30 -> 426.66667 | H32: =H31 -> 1.05 | I32: ='FS Seychelles'!V33+'FS Seychelles'!#REF!+'FS Seychelles'!W33+'FS Seychelles'!X33 -> #REF! | J32: =J31 -> 0 | K32: ='Submetering '!Z32 -> 101 | L32: =L31 -> 0 | M32: ='FS Seychelles'!B33 -> 0

Sheet Submetering 
A1: Site Name | B1: Day | C1: Month | D1: Year | E1: Room Night | F1: SS-A - KWh | G1: SS-B- KWh | H1: SS-C- KWh | I1: SS-D1- KWh | J1: SS-D2- KWh | K1: SS-E- KWh | L1: FIRE PUMP- KWh | M1: CASINO- KWh | N1: BOH- KWh | O1: Generator#1 - KWh | P1: Generator#2- KWh | Q1: Generator#3- KWh | R1: Generator#4- KWh | S1: Generator#5- KWh | T1: DIESEL - Liter | U1: PUC - KWh | V1: BOH Water- m3 | W1: E-Resort- m3 | X1: WT59- m3 | Y1: WT08- m3 | Z1: PUC (HOH)- m3 | AA1: PUC (Resort) - m3 | AB1: LPG (Kg)
A2: Seychelles | B2: 1 | C2: 7 | D2: 2022 | E2: ='FS Seychelles'!B3 -> 64.5 | F2: ='FS Seychelles'!D3*1000 -> #VALUE! | G2: ='FS Seychelles'!E3*1000 -> #VALUE! | H2: ='FS Seychelles'!F3*1000 -> #VALUE! | I2: ='FS Seychelles'!G3*1000 -> 0 | J2: ='FS Seychelles'!H3*1000 -> 0 | K2: ='FS Seychelles'!I3*1000 -> 0 | L2: ='FS Seychelles'!J3*1000 -> #VALUE! | M2: ='FS Seychelles'!K3*1000 -> #VALUE! | N2: ='FS Seychelles'!L3*1000 -> #VALUE! | O2: ='FS Seychelles'!M3 -> 5048 | P2: ='FS Seychelles'!N3 -> 9744 | Q2: ='FS Seychelles'!O3 -> 1658 | R2: ='FS Seychelles'!P3 -> 0 | S2: ='FS Seychelles'!Q3 -> 9765 | T2: ='FS Seychelles'!R3 -> 5877 | U2: ='FS Seychelles'!T3 -> 0 | V2: ='FS Seychelles'!V3 -> 23 | W2: ='FS Seychelles'!#REF! -> #REF! | X2: ='FS Seychelles'!W3 -> 118 | Y2: ='FS Seychelles'!X3 -> 72 | Z2: ='FS Seychelles'!Y3 -> 87 | AA2: ='FS Seychelles'!#REF! -> #REF! | AB2: =('FS Seychelles'!AC9+'FS Seychelles'!AC15)/30 -> 394.66667
A3: Seychelles | B3: =B2+1 -> 2 | C3: =C2 -> 7 | D3: 2022 | E3: ='FS Seychelles'!B4 -> 65.8 | F3: ='FS Seychelles'!D4*1000 -> #VALUE! | G3: ='FS Seychelles'!E4*1000 -> #VALUE! | H3: ='FS Seychelles'!F4*1000 -> #VALUE! | I3: ='FS Seychelles'!G4*1000 -> 0 | J3: ='FS Seychelles'!H4*1000 -> 0 | K3: ='FS Seychelles'!I4*1000 -> 0 | L3: ='FS Seychelles'!J4*1000 -> #VALUE! | M3: ='FS Seychelles'!K4*1000 -> #VALUE! | N3: ='FS Seychelles'!L4*1000 -> #VALUE! | O3: ='FS Seychelles'!M4 -> 6820 | P3: ='FS Seychelles'!N4 -> 5581 | Q3: ='FS Seychelles'!O4 -> 0 | R3: ='FS Seychelles'!P4 -> 7574 | S3: ='FS Seychelles'!Q4 -> 7404 | T3: ='FS Seychelles'!R4 -> 5498 | U3: ='FS Seychelles'!T4 -> 0 | V3: ='FS Seychelles'!V4 -> 44 | W3: ='FS Seychelles'!#REF! -> #REF! | X3: ='FS Seychelles'!W4 -> 109 | Y3: ='FS Seychelles'!X4 -> 51 | Z3: ='FS Seychelles'!Y4 -> 26 | AA3: ='FS Seychelles'!#REF! -> #REF! | AB3: =('FS Seychelles'!AC10+'FS Seychelles'!AC16)/30 -> 32
A4: Seychelles | B4: =B3+1 -> 3 | C4: =C3 -> 7 | D4: 2022 | E4: ='FS Seychelles'!B5 -> 69.7 | F4: ='FS Seychelles'!D5*1000 -> #VALUE! | G4: ='FS Seychelles'!E5*1000 -> #VALUE! | H4: ='FS Seychelles'!F5*1000 -> #VALUE! | I4: ='FS Seychelles'!G5*1000 -> 0 | J4: ='FS Seychelles'!H5*1000 -> 0 | K4: ='FS Seychelles'!I5*1000 -> 0 | L4: ='FS Seychelles'!J5*1000 -> #VALUE! | M4: ='FS Seychelles'!K5*1000 -> #VALUE! | N4: ='FS Seychelles'!L5*1000 -> #VALUE! | O4: ='FS Seychelles'!M5 -> 9824 | P4: ='FS Seychelles'!N5 -> 5251 | Q4: ='FS Seychelles'!O5 -> 9861 | R4: ='FS Seychelles'!P5 -> 5151 | S4: ='FS Seychelles'!Q5 -> 5294 | T4: ='FS Seychelles'!R5 -> 7827 | U4: ='FS Seychelles'!T5 -> 0 | V4: ='FS Seychelles'!V5 -> 59 | W4: ='FS Seychelles'!#REF! -> #REF! | X4: ='FS Seychelles'!W5 -> 158 | Y4: ='FS Seychelles'!X5 -> 67 | Z4: ='FS Seychelles'!Y5 -> 86 | AA4: ='FS Seychelles'!#REF! -> #REF! | AB4: =('FS Seychelles'!AC11+'FS Seychelles'!AC17)/30 -> 0
A5: Seychelles | B5: =B4+1 -> 4 | C5: =C4 -> 7 | D5: 2022 | E5: ='FS Seychelles'!B6 -> 65.8 | F5: ='FS Seychelles'!D6*1000 -> #VALUE! | G5: ='FS Seychelles'!E6*1000 -> #VALUE! | H5: ='FS Seychelles'!F6*1000 -> #VALUE! | I5: ='FS Seychelles'!G6*1000 -> 0 | J5: ='FS Seychelles'!H6*1000 -> 0 | K5: ='FS Seychelles'!I6*1000 -> 0 | L5: ='FS Seychelles'!J6*1000 -> #VALUE! | M5: ='FS Seychelles'!K6*1000 -> #VALUE! | N5: ='FS Seychelles'!L6*1000 -> #VALUE! | O5: ='FS Seychelles'!M6 -> 10140 | P5: ='FS Seychelles'!N6 -> 3751 | Q5: ='FS Seychelles'!O6 -> 10777 | R5: ='FS Seychelles'!P6 -> 0 | S5: ='FS Seychelles'!Q6 -> 4402 | T5: ='FS Seychelles'!R6 -> 6402 | U5: ='FS Seychelles'!T6 -> 0 | V5: ='FS Seychelles'!V6 -> 56 | W5: ='FS Seychelles'!#REF! -> #REF! | X5: ='FS Seychelles'!W6 -> 146 | Y5: ='FS Seychelles'!X6 -> 75 | Z5: ='FS Seychelles'!Y6 -> 88 | AA5: ='FS Seychelles'!#REF! -> #REF! | AB5: =('FS Seychelles'!AC12+'FS Seychelles'!AC18)/30 -> 0
A6: Seychelles | B6: =B5+1 -> 5 | C6: =C5 -> 7 | D6: 2022 | E6: ='FS Seychelles'!B7 -> 51.3 | F6: ='FS Seychelles'!D7*1000 -> #VALUE! | G6: ='FS Seychelles'!E7*1000 -> #VALUE! | H6: ='FS Seychelles'!F7*1000 -> #VALUE! | I6: ='FS Seychelles'!G7*1000 -> 0 | J6: ='FS Seychelles'!H7*1000 -> 0 | K6: ='FS Seychelles'!I7*1000 -> 0 | L6: ='FS Seychelles'!J7*1000 -> #VALUE! | M6: ='FS Seychelles'!K7*1000 -> #VALUE! | N6: ='FS Seychelles'!L7*1000 -> #VALUE! | O6: ='FS Seychelles'!M7 -> 11010 | P6: ='FS Seychelles'!N7 -> 4008 | Q6: ='FS Seychelles'!O7 -> 11026 | R6: ='FS Seychelles'!P7 -> 0 | S6: ='FS Seychelles'!Q7 -> 4852 | T6: ='FS Seychelles'!R7 -> 6596 | U6: ='FS Seychelles'!T7 -> 0 | V6: ='FS Seychelles'!V7 -> 57 | W6: ='FS Seychelles'!#REF! -> #REF! | X6: ='FS Seychelles'!W7 -> 112 | Y6: ='FS Seychelles'!X7 -> 64 | Z6: ='FS Seychelles'!Y7 -> 86 | AA6: ='FS Seychelles'!#REF! -> #REF! | AB6: =('FS Seychelles'!AC13+'FS Seychelles'!AC19)/30 -> 0
A7: Seychelles | B7: =B6+1 -> 6 | C7: =C6 -> 7 | D7: 2022 | E7: ='FS Seychelles'!B8 -> 55.3 | F7: ='FS Seychelles'!D8*1000 -> #VALUE! | G7: ='FS Seychelles'!E8*1000 -> #VALUE! | H7: ='FS Seychelles'!F8*1000 -> #VALUE! | I7: ='FS Seychelles'!G8*1000 -> 0 | J7: ='FS Seychelles'!H8*1000 -> 0 | K7: ='FS Seychelles'!I8*1000 -> 0 | L7: ='FS Seychelles'!J8*1000 -> #VALUE! | M7: ='FS Seychelles'!K8*1000 -> #VALUE! | N7: ='FS Seychelles'!L8*1000 -> #VALUE! | O7: ='FS Seychelles'!M8 -> 6750 | P7: ='FS Seychelles'!N8 -> 4907 | Q7: ='FS Seychelles'!O8 -> 9453 | R7: ='FS Seychelles'!P8 -> 0 | S7: ='FS Seychelles'!Q8 -> 7658 | T7: ='FS Seychelles'!R8 -> 6479 | U7: ='FS Seychelles'!T8 -> 0 | V7: ='FS Seychelles'!V8 -> 59 | W7: ='FS Seychelles'!#REF! -> #REF! | X7: ='FS Seychelles'!W8 -> 125 | Y7: ='FS Seychelles'!X8 -> 67 | Z7: ='FS Seychelles'!Y8 -> 92 | AA7: ='FS Seychelles'!#REF! -> #REF! | AB7: =('FS Seychelles'!AC14+'FS Seychelles'!AC20)/30 -> 0
A8: Seychelles | B8: =B7+1 -> 7 | C8: =C7 -> 7 | D8: 2022 | E8: ='FS Seychelles'!B9 -> 61.8 | F8: ='FS Seychelles'!D9*1000 -> #VALUE! | G8: ='FS Seychelles'!E9*1000 -> #VALUE! | H8: ='FS Seychelles'!F9*1000 -> #VALUE! | I8: ='FS Seychelles'!G9*1000 -> 0 | J8: ='FS Seychelles'!H9*1000 -> 0 | K8: ='FS Seychelles'!I9*1000 -> 0 | L8: ='FS Seychelles'!J9*1000 -> #VALUE! | M8: ='FS Seychelles'!K9*1000 -> #VALUE! | N8: ='FS Seychelles'!L9*1000 -> #VALUE! | O8: ='FS Seychelles'!M9 -> 5554 | P8: ='FS Seychelles'!N9 -> 5574 | Q8: ='FS Seychelles'!O9 -> 10535 | R8: ='FS Seychelles'!P9 -> 0 | S8: ='FS Seychelles'!Q9 -> 10513 | T8: ='FS Seychelles'!R9 -> 6945 | U8: ='FS Seychelles'!T9 -> 0 | V8: ='FS Seychelles'!V9 -> 59 | W8: ='FS Seychelles'!#REF! -> #REF! | X8: ='FS Seychelles'!W9 -> 129 | Y8: ='FS Seychelles'!X9 -> 50 | Z8: ='FS Seychelles'!Y9 -> 92 | AA8: ='FS Seychelles'!#REF! -> #REF! | AB8: =('FS Seychelles'!AC15+'FS Seychelles'!AC21)/30 -> 394.66667
A9: Seychelles | B9: =B8+1 -> 8 | C9: =C8 -> 7 | D9: 2022 | E9: ='FS Seychelles'!B10 -> 63.2 | F9: ='FS Seychelles'!D10*1000 -> #VALUE! | G9: ='FS Seychelles'!E10*1000 -> #VALUE! | H9: ='FS Seychelles'!F10*1000 -> #VALUE! | I9: ='FS Seychelles'!G10*1000 -> 0 | J9: ='FS Seychelles'!H10*1000 -> 0 | K9: ='FS Seychelles'!I10*1000 -> 0 | L9: ='FS Seychelles'!J10*1000 -> #VALUE! | M9: ='FS Seychelles'!K10*1000 -> #VALUE! | N9: ='FS Seychelles'!L10*1000 -> #VALUE! | O9: ='FS Seychelles'!M10 -> 5857 | P9: ='FS Seychelles'!N10 -> 5593 | Q9: ='FS Seychelles'!O10 -> 9935 | R9: ='FS Seychelles'!P10 -> 0 | S9: ='FS Seychelles'!Q10 -> 9950 | T9: ='FS Seychelles'!R10 -> 6832 | U9: ='FS Seychelles'!T10 -> 0 | V9: ='FS Seychelles'!V10 -> 62 | W9: ='FS Seychelles'!#REF! -> #REF! | X9: ='FS Seychelles'!W10 -> 139 | Y9: ='FS Seychelles'!X10 -> 45 | Z9: ='FS Seychelles'!Y10 -> 95 | AA9: ='FS Seychelles'!#REF! -> #REF! | AB9: =('FS Seychelles'!AC16+'FS Seychelles'!AC22)/30 -> 0
A10: Seychelles | B10: =B9+1 -> 9 | C10: =C9 -> 7 | D10: 2022 | E10: ='FS Seychelles'!B11 -> 63.2 | F10: ='FS Seychelles'!D11*1000 -> #VALUE! | G10: ='FS Seychelles'!E11*1000 -> #VALUE! | H10: ='FS Seychelles'!F11*1000 -> #VALUE! | I10: ='FS Seychelles'!G11*1000 -> 0 | J10: ='FS Seychelles'!H11*1000 -> 0 | K10: ='FS Seychelles'!I11*1000 -> 0 | L10: ='FS Seychelles'!J11*1000 -> #VALUE! | M10: ='FS Seychelles'!K11*1000 -> #VALUE! | N10: ='FS Seychelles'!L11*1000 -> #VALUE! | O10: ='FS Seychelles'!M11 -> 9812 | P10: ='FS Seychelles'!N11 -> 5432 | Q10: ='FS Seychelles'!O11 -> 5593 | R10: ='FS Seychelles'!P11 -> 0 | S10: ='FS Seychelles'!Q11 -> 10231 | T10: ='FS Seychelles'!R11 -> 6655 | U10: ='FS Seychelles'!T11 -> 0 | V10: ='FS Seychelles'!V11 -> 53 | W10: ='FS Seychelles'!#REF! -> #REF! | X10: ='FS Seychelles'!W11 -> 107 | Y10: ='FS Seychelles'!X11 -> 65 | Z10: ='FS Seychelles'!Y11 -> 95 | AA10: ='FS Seychelles'!#REF! -> #REF! | AB10: =('FS Seychelles'!AC17+'FS Seychelles'!AC23)/30 -> 0
A11: Seychelles | B11: =B10+1 -> 10 | C11: =C10 -> 7 | D11: 2022 | E11: ='FS Seychelles'!B12 -> 67.1 | F11: ='FS Seychelles'!D12*1000 -> #VALUE! | G11: ='FS Seychelles'!E12*1000 -> #VALUE! | H11: ='FS Seychelles'!F12*1000 -> #VALUE! | I11: ='FS Seychelles'!G12*1000 -> 0 | J11: ='FS Seychelles'!H12*1000 -> 0 | K11: ='FS Seychelles'!I12*1000 -> 0 | L11: ='FS Seychelles'!J12*1000 -> #VALUE! | M11: ='FS Seychelles'!K12*1000 -> #VALUE! | N11: ='FS Seychelles'!L12*1000 -> #VALUE! | O11: ='FS Seychelles'!M12 -> 5304 | P11: ='FS Seychelles'!N12 -> 10428 | Q11: ='FS Seychelles'!O12 -> 10665 | R11: ='FS Seychelles'!P12 -> 0 | S11: ='FS Seychelles'!Q12 -> 5236 | T11: ='FS Seychelles'!R12 -> 6946 | U11: ='FS Seychelles'!T12 -> 0 | V11: ='FS Seychelles'!V12 -> 49 | W11: ='FS Seychelles'!#REF! -> #REF! | X11: ='FS Seychelles'!W12 -> 134 | Y11: ='FS Seychelles'!X12 -> 51 | Z11: ='FS Seychelles'!Y12 -> 92 | AA11: ='FS Seychelles'!#REF! -> #REF! | AB11: =('FS Seychelles'!AC18+'FS Seychelles'!AC24)/30 -> 0
A12: Seychelles | B12: =B11+1 -> 11 | C12: =C11 -> 7 | D12: 2022 | E12: ='FS Seychelles'!B13 -> 69.7 | F12: ='FS Seychelles'!D13*1000 -> #VALUE! | G12: ='FS Seychelles'!E13*1000 -> #VALUE! | H12: ='FS Seychelles'!F13*1000 -> #VALUE! | I12: ='FS Seychelles'!G13*1000 -> 0 | J12: ='FS Seychelles'!H13*1000 -> 0 | K12: ='FS Seychelles'!I13*1000 -> 0 | L12: ='FS Seychelles'!J13*1000 -> #VALUE! | M12: ='FS Seychelles'!K13*1000 -> #VALUE! | N12: ='FS Seychelles'!L13*1000 -> #VALUE! | O12: ='FS Seychelles'!M13 -> 10840 | P12: ='FS Seychelles'!N13 -> 15499 | Q12: ='FS Seychelles'!O13 -> 0 | R12: ='FS Seychelles'!P13 -> 0 | S12: ='FS Seychelles'!Q13 -> 4539 | T12: ='FS Seychelles'!R13 -> 6694 | U12: ='FS Seychelles'!T13 -> 0 | V12: ='FS Seychelles'!V13 -> 63 | W12: ='FS Seychelles'!#REF! -> #REF! | X12: ='FS Seychelles'!W13 -> 121 | Y12: ='FS Seychelles'!X13 -> 51 | Z12: ='FS Seychelles'!Y13 -> 98 | AA12: ='FS Seychelles'!#REF! -> #REF! | AB12: =('FS Seychelles'!AC19+'FS Seychelles'!AC25)/30 -> 0
A13: Seychelles | B13: =B12+1 -> 12 | C13: =C12 -> 7 | D13: 2022 | E13: ='FS Seychelles'!B14 -> 68.4 | F13: ='FS Seychelles'!D14*1000 -> #VALUE! | G13: ='FS Seychelles'!E14*1000 -> #VALUE! | H13: ='FS Seychelles'!F14*1000 -> #VALUE! | I13: ='FS Seychelles'!G14*1000 -> 0 | J13: ='FS Seychelles'!H14*1000 -> 0 | K13: ='FS Seychelles'!I14*1000 -> 0 | L13: ='FS Seychelles'!J14*1000 -> #VALUE! | M13: ='FS Seychelles'!K14*1000 -> #VALUE! | N13: ='FS Seychelles'!L14*1000 -> #VALUE! | O13: ='FS Seychelles'!M14 -> 0 | P13: ='FS Seychelles'!N14 -> 4668 | Q13: ='FS Seychelles'!O14 -> 10699 | R13: ='FS Seychelles'!P14 -> 0 | S13: ='FS Seychelles'!Q14 -> 15287 | T13: ='FS Seychelles'!R14 -> 6656 | U13: ='FS Seychelles'!T14 -> 0 | V13: ='FS Seychelles'!V14 -> 59 | W13: ='FS Seychelles'!#REF! -> #REF! | X13: ='FS Seychelles'!W14 -> 106 | Y13: ='FS Seychelles'!X14 -> 45 | Z13: ='FS Seychelles'!Y14 -> 94 | AA13: ='FS Seychelles'!#REF! -> #REF! | AB13: =('FS Seychelles'!AC20+'FS Seychelles'!AC26)/30 -> 0
A14: Seychelles | B14: =B13+1 -> 13 | C14: =C13 -> 7 | D14: 2022 | E14: ='FS Seychelles'!B15 -> 64.5 | F14: ='FS Seychelles'!D15*1000 -> #VALUE! | G14: ='FS Seychelles'!E15*1000 -> #VALUE! | H14: ='FS Seychelles'!F15*1000 -> #VALUE! | I14: ='FS Seychelles'!G15*1000 -> 0 | J14: ='FS Seychelles'!H15*1000 -> 0 | K14: ='FS Seychelles'!I15*1000 -> 0 | L14: ='FS Seychelles'!J15*1000 -> #VALUE! | M14: ='FS Seychelles'!K15*1000 -> #VALUE! | N14: ='FS Seychelles'!L15*1000 -> #VALUE! | O14: ='FS Seychelles'!M15 -> 5991 | P14: ='FS Seychelles'!N15 -> 10265 | Q14: ='FS Seychelles'!O15 -> 10122 | R14: ='FS Seychelles'!P15 -> 0 | S14: ='FS Seychelles'!Q15 -> 4597 | T14: ='FS Seychelles'!R15 -> 6751 | U14: ='FS Seychelles'!T15 -> 0 | V14: ='FS Seychelles'!V15 -> 58 | W14: ='FS Seychelles'!#REF! -> #REF! | X14: ='FS Seychelles'!W15 -> 109 | Y14: ='FS Seychelles'!X15 -> 44 | Z14: ='FS Seychelles'!Y15 -> 97 | AA14: ='FS Seychelles'!#REF! -> #REF! | AB14: =('FS Seychelles'!AC21+'FS Seychelles'!AC27)/30 -> 0
... A20: Seychelles | B20: =B19+1 -> 19 | C20: =C19 -> 7 | D20: 2022 | E20: ='FS Seychelles'!B21 -> 69.7 | F20: ='FS Seychelles'!D21*1000 -> #VALUE! | G20: ='FS Seychelles'!E21*1000 -> #VALUE! | H20: ='FS Seychelles'!F21*1000 -> #VALUE! | I20: ='FS Seychelles'!G21*1000 -> 0 | J20: ='FS Seychelles'!H21*1000 -> 0 | K20: ='FS Seychelles'!I21*1000 -> 0 | L20: ='FS Seychelles'!J21*1000 -> #VALUE! | M20: ='FS Seychelles'!K21*1000 -> #VALUE! | N20: ='FS Seychelles'!L21*1000 -> #VALUE! | O20: ='FS Seychelles'!M21 -> 9503 | P20: ='FS Seychelles'!N21 -> 6728 | Q20: ='FS Seychelles'!O21 -> 6854 | R20: ='FS Seychelles'!P21 -> 9365 | S20: ='FS Seychelles'!Q21 -> 0 | T20: ='FS Seychelles'!R21 -> 7454 | U20: ='FS Seychelles'!T21 -> 0 | V20: ='FS Seychelles'!V21 -> 62 | W20: ='FS Seychelles'!#REF! -> #REF! | X20: ='FS Seychelles'!W21 -> 124 | Y20: ='FS Seychelles'!X21 -> 67 | Z20: ='FS Seychelles'!Y21 -> 97 | AA20: ='FS Seychelles'!#REF! -> #REF! | AB20: =('FS Seychelles'!AC27+'FS Seychelles'!AC33)/30 -> 0
A21: Seychelles | B21: =B20+1 -> 20 | C21: =C20 -> 7 | D21: 2022 | E21: ='FS Seychelles'!B22 -> 65.8 | F21: ='FS Seychelles'!D22*1000 -> #VALUE! | G21: ='FS Seychelles'!E22*1000 -> #VALUE! | H21: ='FS Seychelles'!F22*1000 -> #VALUE! | I21: ='FS Seychelles'!G22*1000 -> 0 | J21: ='FS Seychelles'!H22*1000 -> 0 | K21: ='FS Seychelles'!I22*1000 -> 0 | L21: ='FS Seychelles'!J22*1000 -> #VALUE! | M21: ='FS Seychelles'!K22*1000 -> #VALUE! | N21: ='FS Seychelles'!L22*1000 -> #VALUE! | O21: ='FS Seychelles'!M22 -> 10347 | P21: ='FS Seychelles'!N22 -> 7140 | Q21: ='FS Seychelles'!O22 -> 4363 | R21: ='FS Seychelles'!P22 -> 10285 | S21: ='FS Seychelles'!Q23 -> 0 | T21: ='FS Seychelles'!R22 -> 7683 | U21: ='FS Seychelles'!T22 -> 0 | V21: ='FS Seychelles'!V22 -> 60 | W21: ='FS Seychelles'!#REF! -> #REF! | X21: ='FS Seychelles'!W22 -> 116 | Y21: ='FS Seychelles'!X22 -> 57 | Z21: ='FS Seychelles'!Y22 -> 98 | AA21: ='FS Seychelles'!#REF! -> #REF! | AB21: =('FS Seychelles'!AC28+'FS Seychelles'!AC34)/30 -> 0
A22: Seychelles | B22: =B21+1 -> 21 | C22: =C21 -> 7 | D22: 2022 | E22: ='FS Seychelles'!B23 -> 67.1 | F22: ='FS Seychelles'!D23*1000 -> #VALUE! | G22: ='FS Seychelles'!E23*1000 -> #VALUE! | H22: ='FS Seychelles'!F23*1000 -> #VALUE! | I22: ='FS Seychelles'!G23*1000 -> 0 | J22: ='FS Seychelles'!H23*1000 -> 0 | K22: ='FS Seychelles'!I23*1000 -> 0 | L22: ='FS Seychelles'!J23*1000 -> #VALUE! | M22: ='FS Seychelles'!K23*1000 -> #VALUE! | N22: ='FS Seychelles'!L23*1000 -> #VALUE! | O22: ='FS Seychelles'!M23 -> 6778 | P22: ='FS Seychelles'!N23 -> 12609 | Q22: ='FS Seychelles'!O23 -> 6838 | R22: ='FS Seychelles'!P23 -> 10444 | S22: ='FS Seychelles'!Q24 -> 0 | T22: ='FS Seychelles'!R23 -> 7984 | U22: ='FS Seychelles'!T23 -> 0 | V22: ='FS Seychelles'!V23 -> 57 | W22: ='FS Seychelles'!#REF! -> #REF! | X22: ='FS Seychelles'!W23 -> 123 | Y22: ='FS Seychelles'!X23 -> 35 | Z22: ='FS Seychelles'!Y23 -> 99 | AA22: ='FS Seychelles'!#REF! -> #REF! | AB22: =('FS Seychelles'!AC29+'FS Seychelles'!AC35)/30 -> 0
A23: Seychelles | B23: =B22+1 -> 22 | C23: =C22 -> 7 | D23: 2022 | E23: ='FS Seychelles'!B24 -> 65.8 | F23: ='FS Seychelles'!D24*1000 -> #VALUE! | G23: ='FS Seychelles'!E24*1000 -> #VALUE! | H23: ='FS Seychelles'!F24*1000 -> #VALUE! | I23: ='FS Seychelles'!G24*1000 -> 0 | J23: ='FS Seychelles'!H24*1000 -> 0 | K23: ='FS Seychelles'!I24*1000 -> 0 | L23: ='FS Seychelles'!J24*1000 -> #VALUE! | M23: ='FS Seychelles'!K24*1000 -> #VALUE! | N23: ='FS Seychelles'!L24*1000 -> #VALUE! | O23: ='FS Seychelles'!M24 -> 10301 | P23: ='FS Seychelles'!N24 -> 9367 | Q23: ='FS Seychelles'!O24 -> 9123 | R23: ='FS Seychelles'!P24 -> 1050 | S23: ='FS Seychelles'!Q25 -> 10583 | T23: ='FS Seychelles'!R24 -> 6582 | U23: ='FS Seychelles'!T24 -> 0 | V23: ='FS Seychelles'!V24 -> 63 | W23: ='FS Seychelles'!#REF! -> #REF! | X23: ='FS Seychelles'!W24 -> 101 | Y23: ='FS Seychelles'!X24 -> 49 | Z23: ='FS Seychelles'!Y24 -> 93 | AA23: ='FS Seychelles'!#REF! -> #REF! | AB23: =('FS Seychelles'!AC30+'FS Seychelles'!AC36)/30 -> 0
A24: Seychelles | B24: =B23+1 -> 23 | C24: =C23 -> 7 | D24: 2022 | E24: ='FS Seychelles'!B25 -> 59.2 | F24: ='FS Seychelles'!D25*1000 -> #VALUE! | G24: ='FS Seychelles'!E25*1000 -> #VALUE! | H24: ='FS Seychelles'!F25*1000 -> #VALUE! | I24: ='FS Seychelles'!G25*1000 -> 0 | J24: ='FS Seychelles'!H25*1000 -> 0 | K24: ='FS Seychelles'!I25*1000 -> 0 | L24: ='FS Seychelles'!J25*1000 -> #VALUE! | M24: ='FS Seychelles'!K25*1000 -> #VALUE! | N24: ='FS Seychelles'!L25*1000 -> #VALUE! | O24: ='FS Seychelles'!M25 -> 9998 | P24: ='FS Seychelles'!N25 -> 6004 | Q24: ='FS Seychelles'!O25 -> 0 | R24: ='FS Seychelles'!P25 -> 9823 | S24: ='FS Seychelles'!Q25 -> 10583 | T24: ='FS Seychelles'!R25 -> 8519 | U24: ='FS Seychelles'!T25 -> 0 | V24: ='FS Seychelles'!V25 -> 64 | W24: ='FS Seychelles'!#REF! -> #REF! | X24: ='FS Seychelles'!W25 -> 88 | Y24: ='FS Seychelles'!X25 -> 51 | Z24: ='FS Seychelles'!Y25 -> 96 | AA24: ='FS Seychelles'!#REF! -> #REF! | AB24: =('FS Seychelles'!AC31+'FS Seychelles'!AC37)/30 -> 0
A25: Seychelles | B25: =B24+1 -> 24 | C25: =C24 -> 7 | D25: 2022 | E25: ='FS Seychelles'!B26 -> 51.3 | F25: ='FS Seychelles'!D26*1000 -> #VALUE! | G25: ='FS Seychelles'!E26*1000 -> #VALUE! | H25: ='FS Seychelles'!F26*1000 -> #VALUE! | I25: ='FS Seychelles'!G26*1000 -> 0 | J25: ='FS Seychelles'!H26*1000 -> 0 | K25: ='FS Seychelles'!I26*1000 -> 0 | L25: ='FS Seychelles'!J26*1000 -> #VALUE! | M25: ='FS Seychelles'!K26*1000 -> #VALUE! | N25: ='FS Seychelles'!L26*1000 -> #VALUE! | O25: ='FS Seychelles'!M26 -> 9606 | P25: ='FS Seychelles'!N26 -> 9488 | Q25: ='FS Seychelles'!O26 -> 0 | R25: ='FS Seychelles'!P26 -> 10025 | S25: ='FS Seychelles'!Q26 -> 6236 | T25: ='FS Seychelles'!R26 -> 7980 | U25: ='FS Seychelles'!T26 -> 0 | V25: ='FS Seychelles'!V26 -> 52 | W25: ='FS Seychelles'!#REF! -> #REF! | X25: ='FS Seychelles'!W26 -> 120 | Y25: ='FS Seychelles'!X26 -> 90 | Z25: ='FS Seychelles'!Y26 -> 79 | AA25: ='FS Seychelles'!#REF! -> #REF! | AB25: =('FS Seychelles'!AC32+'FS Seychelles'!AC38)/30 -> 0
A26: Seychelles | B26: =B25+1 -> 25 | C26: =C25 -> 7 | D26: 2022 | E26: ='FS Seychelles'!B27 -> 73.7 | F26: ='FS Seychelles'!D27*1000 -> #VALUE! | G26: ='FS Seychelles'!E27*1000 -> #VALUE! | H26: ='FS Seychelles'!F27*1000 -> #VALUE! | I26: ='FS Seychelles'!G27*1000 -> 0 | J26: ='FS Seychelles'!H27*1000 -> 0 | K26: ='FS Seychelles'!I27*1000 -> 0 | L26: ='FS Seychelles'!J27*1000 -> #VALUE! | M26: ='FS Seychelles'!K27*1000 -> #VALUE! | N26: ='FS Seychelles'!L27*1000 -> #VALUE! | O26: ='FS Seychelles'!M27 -> 6819 | P26: ='FS Seychelles'!N27 -> 4609 | Q26: ='FS Seychelles'!O27 -> 9162 | R26: ='FS Seychelles'!P27 -> 4433 | S26: ='FS Seychelles'!Q27 -> 8911 | T26: ='FS Seychelles'!R27 -> 7780 | U26: ='FS Seychelles'!T27 -> 0 | V26: ='FS Seychelles'!V27 -> 57 | W26: ='FS Seychelles'!#REF! -> #REF! | X26: ='FS Seychelles'!W27 -> 97 | Y26: ='FS Seychelles'!X27 -> 47 | Z26: ='FS Seychelles'!Y27 -> 61 | AA26: ='FS Seychelles'!#REF! -> #REF! | AB26: =('FS Seychelles'!AC33+'FS Seychelles'!AC39)/30 -> 0
A27: Seychelles | B27: =B26+1 -> 26 | C27: =C26 -> 7 | D27: 2022 | E27: ='FS Seychelles'!B28 -> 77.6 | F27: ='FS Seychelles'!D28*1000 -> #VALUE! | G27: ='FS Seychelles'!E28*1000 -> #VALUE! | H27: ='FS Seychelles'!F28*1000 -> #VALUE! | I27: ='FS Seychelles'!G28*1000 -> 0 | J27: ='FS Seychelles'!H28*1000 -> 0 | K27: ='FS Seychelles'!I28*1000 -> 0 | L27: ='FS Seychelles'!J28*1000 -> #VALUE! | M27: ='FS Seychelles'!K28*1000 -> #VALUE! | N27: ='FS Seychelles'!L28*1000 -> #VALUE! | O27: ='FS Seychelles'!M28 -> 9387 | P27: ='FS Seychelles'!N28 -> 5714 | Q27: ='FS Seychelles'!O28 -> 5694 | R27: ='FS Seychelles'!P28 -> 9314 | S27: ='FS Seychelles'!Q28 -> 8806 | T27: ='FS Seychelles'!R28 -> 8705 | U27: ='FS Seychelles'!T28 -> 0 | V27: ='FS Seychelles'!V28 -> 61 | W27: ='FS Seychelles'!#REF! -> #REF! | X27: ='FS Seychelles'!W28 -> 76 | Y27: ='FS Seychelles'!X28 -> 51 | Z27: ='FS Seychelles'!Y28 -> 11 | AA27: ='FS Seychelles'!#REF! -> #REF! | AB27: =('FS Seychelles'!AC34+'FS Seychelles'!AC40)/30 -> 0
A28: Seychelles | B28: =B27+1 -> 27 | C28: =C27 -> 7 | D28: 2022 | E28: ='FS Seychelles'!B29 -> 81.6 | F28: ='FS Seychelles'!D29*1000 -> #VALUE! | G28: ='FS Seychelles'!E29*1000 -> #VALUE! | H28: ='FS Seychelles'!F29*1000 -> #VALUE! | I28: ='FS Seychelles'!G29*1000 -> 0 | J28: ='FS Seychelles'!H29*1000 -> 0 | K28: ='FS Seychelles'!I29*1000 -> 0 | L28: ='FS Seychelles'!J29*1000 -> #VALUE! | M28: ='FS Seychelles'!K29*1000 -> #VALUE! | N28: ='FS Seychelles'!L29*1000 -> #VALUE! | O28: ='FS Seychelles'!M29 -> 10908 | P28: ='FS Seychelles'!N29 -> 0 | Q28: ='FS Seychelles'!O29 -> 5069 | R28: ='FS Seychelles'!P29 -> 10927 | S28: ='FS Seychelles'!Q29 -> 5999 | T28: ='FS Seychelles'!R29 -> 7823 | U28: ='FS Seychelles'!T29 -> 0 | V28: ='FS Seychelles'!V29 -> 52 | W28: ='FS Seychelles'!#REF! -> #REF! | X28: ='FS Seychelles'!W29 -> 107 | Y28: ='FS Seychelles'!X29 -> 42 | Z28: ='FS Seychelles'!Y29 -> 74 | AA28: ='FS Seychelles'!#REF! -> #REF! | AB28: =('FS Seychelles'!AC35+'FS Seychelles'!AC41)/30 -> 0
A29: Seychelles | B29: =B28+1 -> 28 | C29: =C28 -> 7 | D29: 2022 | E29: ='FS Seychelles'!B30 -> 78.9 | F29: ='FS Seychelles'!D30*1000 -> #VALUE! | G29: ='FS Seychelles'!E30*1000 -> #VALUE! | H29: ='FS Seychelles'!F30*1000 -> #VALUE! | I29: ='FS Seychelles'!G30*1000 -> 0 | J29: ='FS Seychelles'!H30*1000 -> 0 | K29: ='FS Seychelles'!I30*1000 -> 0 | L29: ='FS Seychelles'!J30*1000 -> #VALUE! | M29: ='FS Seychelles'!K30*1000 -> #VALUE! | N29: ='FS Seychelles'!L30*1000 -> #VALUE! | O29: ='FS Seychelles'!M30 -> 5255 | P29: ='FS Seychelles'!N30 -> 0 | Q29: ='FS Seychelles'!O30 -> 8751 | R29: ='FS Seychelles'!P30 -> 9233 | S29: ='FS Seychelles'!Q30 -> 9312 | T29: ='FS Seychelles'!R30 -> 7042 | U29: ='FS Seychelles'!T30 -> 0 | V29: ='FS Seychelles'!V30 -> 57 | W29: ='FS Seychelles'!#REF! -> #REF! | X29: ='FS Seychelles'!W30 -> 109 | Y29: ='FS Seychelles'!X30 -> 54 | Z29: ='FS Seychelles'!Y30 -> 104 | AA29: ='FS Seychelles'!#REF! -> #REF! | AB29: =('FS Seychelles'!AC36+'FS Seychelles'!AC42)/30 -> 0
A30: Seychelles | B30: =B29+1 -> 29 | C30: =C29 -> 7 | D30: 2022 | E30: ='FS Seychelles'!B31 -> 77.6 | F30: ='FS Seychelles'!D31*1000 -> #VALUE! | G30: ='FS Seychelles'!E31*1000 -> #VALUE! | H30: ='FS Seychelles'!F31*1000 -> #VALUE! | I30: ='FS Seychelles'!G31*1000 -> 0 | J30: ='FS Seychelles'!H31*1000 -> 0 | K30: ='FS Seychelles'!I31*1000 -> 0 | L30: ='FS Seychelles'!J31*1000 -> #VALUE! | M30: ='FS Seychelles'!K31*1000 -> #VALUE! | N30: ='FS Seychelles'!L31*1000 -> #VALUE! | O30: ='FS Seychelles'!M31 -> 11828 | P30: ='FS Seychelles'!N31 -> 6177 | Q30: ='FS Seychelles'!O31 -> 0 | R30: ='FS Seychelles'!P31 -> 10097 | S30: ='FS Seychelles'!Q31 -> 9307 | T30: ='FS Seychelles'!R31 -> 8208 | U30: ='FS Seychelles'!T31 -> 0 | V30: ='FS Seychelles'!V31 -> 54 | W30: ='FS Seychelles'!#REF! -> #REF! | X30: ='FS Seychelles'!W31 -> 108 | Y30: ='FS Seychelles'!X31 -> 37 | Z30: ='FS Seychelles'!Y31 -> 101 | AA30: ='FS Seychelles'!#REF! -> #REF! | AB30: =('FS Seychelles'!AC37+'FS Seychelles'!AC43)/30 -> 0
A31: Seychelles | B31: =B30+1 -> 30 | C31: =C30 -> 7 | D31: 2022 | E31: ='FS Seychelles'!B32 -> 80.3 | F31: ='FS Seychelles'!D32*1000 -> #VALUE! | G31: ='FS Seychelles'!E32*1000 -> #VALUE! | H31: ='FS Seychelles'!F32*1000 -> #VALUE! | I31: ='FS Seychelles'!G32*1000 -> 0 | J31: ='FS Seychelles'!H32*1000 -> 0 | K31: ='FS Seychelles'!I32*1000 -> 0 | L31: ='FS Seychelles'!J32*1000 -> #VALUE! | M31: ='FS Seychelles'!K32*1000 -> #VALUE! | N31: ='FS Seychelles'!L32*1000 -> #VALUE! | O31: ='FS Seychelles'!M32 -> 10662 | P31: ='FS Seychelles'!N32 -> 5147 | Q31: ='FS Seychelles'!O32 -> 0 | R31: ='FS Seychelles'!P32 -> 8670 | S31: ='FS Seychelles'!Q32 -> 10735 | T31: ='FS Seychelles'!R32 -> 7874 | U31: ='FS Seychelles'!T32 -> 0 | V31: ='FS Seychelles'!V32 -> 55 | W31: ='FS Seychelles'!#REF! -> #REF! | X31: ='FS Seychelles'!W32 -> 63 | Y31: ='FS Seychelles'!X32 -> 46 | Z31: ='FS Seychelles'!Y32 -> 94 | AA31: ='FS Seychelles'!#REF! -> #REF! | AB31: =('FS Seychelles'!AC38+'FS Seychelles'!AC44)/30 -> 0
A32: Seychelles | B32: =B31+1 -> 31 | C32: =C31 -> 7 | D32: 2022 | E32: ='FS Seychelles'!B33 -> 0 | F32: ='FS Seychelles'!D33*1000 -> #VALUE! | G32: ='FS Seychelles'!E33*1000 -> #VALUE! | H32: ='FS Seychelles'!F33*1000 -> #VALUE! | I32: ='FS Seychelles'!G33*1000 -> 0 | J32: ='FS Seychelles'!H33*1000 -> 0 | K32: ='FS Seychelles'!I33*1000 -> 0 | L32: ='FS Seychelles'!J33*1000 -> #VALUE! | M32: ='FS Seychelles'!K33*1000 -> #VALUE! | N32: ='FS Seychelles'!L33*1000 -> #VALUE! | O32: ='FS Seychelles'!M33 -> 10243 | P32: ='FS Seychelles'!N33 -> 5896 | Q32: ='FS Seychelles'!O33 -> 0 | R32: ='FS Seychelles'!P33 -> 3421 | S32: ='FS Seychelles'!Q33 -> 10401 | T32: ='FS Seychelles'!R33 -> 6378 | U32: ='FS Seychelles'!T33 -> 0 | V32: ='FS Seychelles'!V33 -> 53 | W32: ='FS Seychelles'!#REF! -> #REF! | X32: ='FS Seychelles'!W33 -> 105 | Y32: ='FS Seychelles'!X33 -> 36 | Z32: ='FS Seychelles'!Y33 -> 101 | AA32: ='FS Seychelles'!#REF! -> #REF! | AB32: =('FS Seychelles'!AC39+'FS Seychelles'!AC45)/30 -> 0
P33: =SUM(P2:P32) -> 225208 | Q33: =SUM(Q2:Q32) -> 203651 | R33: =SUM(R2:R32) -> 119812
R35: =SUM(O33:R33) -> 548671

Sheet FS Seychelles
A2: DATE | B2: Room Night % | C2: Food Covers (Customers) | D2: SS-A (MWH) | E2: SS-B (MWH) | F2: SS-C (MWH) | G2: SS-D1 (MWH) | H2: SS-D2 (MWH) | I2: SS-E (MWH) | J2: FIRE PUMP (MWH) | K2: CASINO (MWH) | L2: BOH (MWH) | M2: Generator#1 (KWH) | N2: Generator#2 (KWH) | O2: Generator#3 (KWH) | P2: Generator#4 (KWH) | Q2: Generator#5 (KWH) | R2: DIESEL (Liter) | S2: DIESEL TARIFF (Euro/Liter) | T2: PUC (KWh) | U2: PUC Tariff (Euro/KWh) | V2: BOH Water (m3) | W2: WT59= WT59-SRV1-(SRV2+3) | X2: WT08 (m3) | Y2: PUC HOH (m3) | Z2: Fire Tank (m3) | AA2: LPG (Kg) | AD2: STP (m3) | AE2: STP (m3) | AF2: Fire tank 250 m3
A3: 44743 | B3: 64.5 | C3: 342 | D3: 2,38 | E3: 3,69 | F3: 4,89 | J3: 1,19 | K3: 1,44 | L3: 3,60 | M3: =Generator!E3 -> 5048 | N3: =Generator!L3 -> 9744 | O3: =Generator!S3 -> 1658 | P3: =Generator!Z3 -> 0 | Q3: =Generator!AG3 -> 9765 | R3: =SUM(Generator!C3,Generator!J3,Generator!Q3,Generator!X3,Generator!AE3) -> 5877 | S3: 1.47 | U3: 0.32 | V3: 23 | W3: 118 | X3: 72 | Y3: 87 | Z3: 50 | AA3: CYLINDER DELIVERY (KG)
A4: 44744 | B4: 65.8 | C4: 305 | D4: 2,35 | E4: 3,76 | F4: 4,86 | J4: 1,38 | K4: 1,39 | L4: 3,52 | M4: =Generator!E4 -> 6820 | N4: =Generator!L4 -> 5581 | O4: =Generator!S4 -> 0 | P4: =Generator!Z4 -> 7574 | Q4: =Generator!AG4 -> 7404 | R4: =SUM(Generator!C4,Generator!J4,Generator!Q4,Generator!X4,Generator!AE4) -> 5498 | S4: =24.43*0.06 -> 1.4658 | U4: =U3 -> 0.32 | V4: 44 | W4: 109 | X4: 51 | Y4: 26 | Z4: 26 | AA4: Unit (kg) | AB4: Quantity | AC4: Sub total
A5: 44745 | B5: 69.7 | C5: 240 | D5: 2,51 | E5: 3,83 | F5: 5,09 | J5: 1,34 | K5: 1,37 | L5: 3,42 | M5: =Generator!E5 -> 9824 | N5: =Generator!L5 -> 5251 | O5: =Generator!S5 -> 9861 | P5: =Generator!Z5 -> 5151 | Q5: =Generator!AG5 -> 5294 | R5: =SUM(Generator!C5,Generator!J5,Generator!Q5,Generator!X5,Generator!AE5) -> 7827 | S5: =24.43*0.06 -> 1.4658 | U5: =U4 -> 0.32 | V5: 59 | W5: 158 | X5: 67 | Y5: 86 | Z5: 23 | AA5: 9
A6: 44746 | B6: 65.8 | C6: 200 | D6: 2,29 | E6: 3,65 | F6: 5,08 | J6: 1,32 | K6: 1,39 | L6: 3,61 | M6: =Generator!E6 -> 10140 | N6: =Generator!L6 -> 3751 | O6: =Generator!S6 -> 10777 | P6: =Generator!Z6 -> 0 | Q6: =Generator!AG6 -> 4402 | R6: =SUM(Generator!C6,Generator!J6,Generator!Q6,Generator!X6,Generator!AE6) -> 6402 | S6: =24.43*0.06 -> 1.4658 | U6: =U5 -> 0.32 | V6: 56 | W6: 146 | X6: 75 | Y6: 88 | Z6: 71 | AA6: 10
A7: 44747 | B7: 51.3 | C7: 329 | D7: 2,30 | E7: 3,72 | F7: 5,18 | J7: 1,39 | K7: 1,31 | L7: 3,62 | M7: =Generator!E7 -> 11010 | N7: =Generator!L7 -> 4008 | O7: =Generator!S7 -> 11026 | P7: =Generator!Z7 -> 0 | Q7: =Generator!AG7 -> 4852 | R7: =SUM(Generator!C7,Generator!J7,Generator!Q7,Generator!X7,Generator!AE7) -> 6596 | S7: =24.43*0.06 -> 1.4658 | U7: =U6 -> 0.32 | V7: 57 | W7: 112 | X7: 64 | Y7: 86 | Z7: 95 | AA7: 12
A8: 44748 | B8: 55.3 | C8: 313 | D8: 2,11 | E8: 3,56 | F8: 5,08 | J8: 1,17 | K8: 1,37 | L8: 3,24 | M8: =Generator!E8 -> 6750 | N8: =Generator!L8 -> 4907 | O8: =Generator!S8 -> 9453 | P8: =Generator!Z8 -> 0 | Q8: =Generator!AG8 -> 7658 | R8: =SUM(Generator!C8,Generator!J8,Generator!Q8,Generator!X8,Generator!AE8) -> 6479 | S8: =24.43*0.06 -> 1.4658 | U8: =U7 -> 0.32 | V8: 59 | W8: 125 | X8: 67 | Y8: 92 | Z8: 77 | AA8: 20 | AB8: 48 | AC8: =AB8*AA8 -> 960
A9: 44749 | B9: 61.8 | C9: 436 | D9: 2,17 | E9: 3,68 | F9: 5,10 | J9: 1,46 | K9: 1,46 | L9: 3,72 | M9: =Generator!E9 -> 5554 | N9: =Generator!L9 -> 5574 | O9: =Generator!S9 -> 10535 | P9: =Generator!Z9 -> 0 | Q9: =Generator!AG9 -> 10513 | R9: =SUM(Generator!C9,Generator!J9,Generator!Q9,Generator!X9,Generator!AE9) -> 6945 | S9: =24.43*0.06 -> 1.4658 | U9: =U8 -> 0.32 | V9: 59 | W9: 129 | X9: 50 | Y9: 92 | Z9: 37
A10: 44750 | B10: 63.2 | C10: 333 | D10: 2,14 | E10: 3,76 | F10: 5,01 | J10: 1,47 | K10: 1,40 | L10: 3,73 | M10: =Generator!E10 -> 5857 | N10: =Generator!L10 -> 5593 | O10: =Generator!S10 -> 9935 | P10: =Generator!Z10 -> 0 | Q10: =Generator!AG10 -> 9950 | R10: =SUM(Generator!C10,Generator!J10,Generator!Q10,Generator!X10,Generator!AE10) -> 6832 | S10: =24.43*0.06 -> 1.4658 | U10: =U9 -> 0.32 | V10: 62 | W10: 139 | X10: 45 | Y10: 95 | Z10: 57 | AB10: Total | AC10: =SUM(AC6:AC9) -> 960 | AD10: 34892
A11: 44751 | B11: 63.2 | C11: 342 | D11: 2,06 | E11: 3,55 | F11: 5,11 | J11: 1,44 | K11: 1,36 | L11: 3,70 | M11: =Generator!E11 -> 9812 | N11: =Generator!L11 -> 5432 | O11: =Generator!S11 -> 5593 | P11: =Generator!Z11 -> 0 | Q11: =Generator!AG11 -> 10231 | R11: =SUM(Generator!C11,Generator!J11,Generator!Q11,Generator!X11,Generator!AE11) -> 6655 | S11: =24.43*0.06 -> 1.4658 | U11: =U10 -> 0.32 | V11: 53 | W11: 107 | X11: 65 | Y11: 95 | Z11: 49 | AA11: TRUCK DELIVERY (KG)
A12: 44752 | B12: 67.1 | C12: 371 | D12: 2,12 | E12: 3,64 | F12: 5,13 | J12: 1,44 | K12: 1,39 | L12: 3,65 | M12: =Generator!E12 -> 5304 | N12: =Generator!L12 -> 10428 | O12: =Generator!S12 -> 10665 | P12: =Generator!Z12 -> 0 | Q12: =Generator!AG12 -> 5236 | R12: =SUM(Generator!C12,Generator!J12,Generator!Q12,Generator!X12,Generator!AE12) -> 6946 | S12: =24.43*0.06 -> 1.4658 | U12: =U11 -> 0.32 | V12: 49 | W12: 134 | X12: 51 | Y12: 92 | Z12: 65 | AB12: Sub Total
A13: 44753 | B13: 69.7 | C13: 395 | D13: 2,02 | E13: 3,76 | F13: 5,03 | J13: 1,33 | K13: 1,37 | L13: 3,65 | M13: =Generator!E13 -> 10840 | N13: =Generator!L13 -> 15499 | O13: =Generator!S13 -> 0 | P13: =Generator!Z13 -> 0 | Q13: =Generator!AG13 -> 4539 | R13: =SUM(Generator!C13,Generator!J13,Generator!Q13,Generator!X13,Generator!AE13) -> 6694 | S13: =24.43*0.06 -> 1.4658 | U13: =U12 -> 0.32 | V13: 63 | W13: 121 | X13: 51 | Y13: 98 | Z13: 62 | AA13: Sitronel | AB13: 8750
A14: 44754 | B14: 68.4 | C14: 384 | D14: 2,35 | E14: 3,55 | F14: 4,85 | J14: 1,45 | K14: 1,45 | L14: 3,69 | M14: =Generator!E14 -> 0 | N14: =Generator!L14 -> 4668 | O14: =Generator!S14 -> 10699 | P14: =Generator!Z14 -> 0 | Q14: =Generator!AG14 -> 15287 | R14: =SUM(Generator!C14,Generator!J14,Generator!Q14,Generator!X14,Generator!AE14) -> 6656 | S14: =24.43*0.06 -> 1.4658 | U14: =U13 -> 0.32 | V14: 59 | W14: 106 | X14: 45 | Y14: 94 | Z14: 51 | AA14: Zez | AB14: 3090 | AD14: 35408
A15: 44755 | B15: 64.5 | C15: 398 | D15: 2,29 | E15: 3,81 | F15: 4,77 | J15: 1,42 | K15: 1,37 | L15: 3,69 | M15: =Generator!E15 -> 5991 | N15: =Generator!L15 -> 10265 | O15: =Generator!S15 -> 10122 | P15: =Generator!Z15 -> 0 | Q15: =Generator!AG15 -> 4597 | R15: =SUM(Generator!C15,Generator!J15,Generator!Q15,Generator!X15,Generator!AE15) -> 6751 | S15: =24.43*0.06 -> 1.4658 | U15: =U14 -> 0.32 | V15: 58 | W15: 109 | X15: 44 | Y15: 97 | Z15: 49 | AB15: Total | AC15: =SUM(AB13:AC14) -> 11840 | AD15: 35578 | AG15: =AC10+AC15 -> 12800
A16: 44756 | B16: 72.4 | C16: 377 | D16: 2,26 | E16: 3,77 | F16: 4,92 | J16: 1,29 | K16: 1,38 | L16: 3,69 | M16: =Generator!E16 -> 3920 | N16: =Generator!L16 -> 10913 | O16: =Generator!S16 -> 10920 | P16: =Generator!Z16 -> 0 | Q16: =Generator!AG16 -> 3923 | R16: =SUM(Generator!C16,Generator!J16,Generator!Q16,Generator!X16,Generator!AE16) -> 6469 | S16: =24.43*0.06 -> 1.4658 | U16: =U15 -> 0.32 | V16: 58 | W16: 92 | X16: 44 | Y16: 97 | Z16: 50 | AD16: 35718
A17: 44757 | B17: 68.4 | C17: 389 | D17: 2,41 | E17: 3,93 | F17: 4,96 | J17: 1,43 | K17: 1,50 | L17: 3,74 | M17: =Generator!E17 -> 4013 | N17: =Generator!L17 -> 11244 | O17: =Generator!S17 -> 11229 | P17: =Generator!Z17 -> 0 | Q17: =Generator!AG17 -> 4000 | R17: =SUM(Generator!C17,Generator!J17,Generator!Q17,Generator!X17,Generator!AE17) -> 6616 | S17: =24.43*0.06 -> 1.4658 | U17: =U16 -> 0.32 | V17: 68 | W17: 108 | X17: 49 | Y17: 99 | Z17: 52 | AD17: 35882
A18: 44758 | B18: 71.1 | C18: 403 | D18: 2,71 | E18: 3,74 | F18: 5,00 | J18: 1,39 | K18: 1,45 | L18: 3,71 | M18: =Generator!E18 -> 5213 | N18: =Generator!L18 -> 10403 | O18: =Generator!S18 -> 10142 | P18: =Generator!Z18 -> 0 | Q18: =Generator!AG18 -> 6289 | R18: =SUM(Generator!C18,Generator!J18,Generator!Q18,Generator!X18,Generator!AE18) -> 7030 | S18: =24.43*0.06 -> 1.4658 | U18: =U17 -> 0.32 | V18: 62 | W18: 126 | X18: 37 | Y18: 90 | Z18: 50 | AD18: 36008
A19: 44759 | B19: 64.5 | C19: 359 | D19: 2,70 | E19: 3,60 | F19: 4,97 | J19: 1,43 | K19: 1,34 | L19: 3,69 | M19: =Generator!E19 -> 2452 | N19: =Generator!L19 -> 15072 | O19: =Generator!S19 -> 8264 | P19: =Generator!Z19 -> 0 | Q19: =Generator!AG19 -> 6915 | R19: =SUM(Generator!C19,Generator!J19,Generator!Q19,Generator!X19,Generator!AE19) -> 7099 | S19: =24.43*0.06 -> 1.4658 | U19: =U18 -> 0.32 | V19: 53 | W19: 139 | X19: 56 | Y19: 90 | Z19: 49
A20: Gd | B20: 59.2 | C20: 326 | D20: 2,30 | E20: 3,29 | F20: 4,70 | J20: 1,42 | K20: 1,34 | L20: 3,52 | M20: =Generator!E20 -> 8543 | N20: =Generator!L20 -> 7996 | O20: =Generator!S20 -> 6918 | P20: =Generator!Z20 -> 0 | Q20: =Generator!AG20 -> 6649 | R20: =SUM(Generator!C20,Generator!J20,Generator!Q20,Generator!X20,Generator!AE20) -> 6518 | S20: =24.43*0.06 -> 1.4658 | U20: =U19 -> 0.32 | V20: 55 | W20: 71 | X20: 37 | Y20: 93 | Z20: 33
A21: 44761 | B21: 69.7 | C21: 363 | D21: 2,41 | E21: 3,37 | F21: 4,75 | J21: 1,41 | K21: 1,29 | L21: 3,79 | M21: =Generator!E21 -> 9503 | N21: =Generator!L21 -> 6728 | O21: =Generator!S21 -> 6854 | P21: =Generator!Z21 -> 9365 | Q21: =Generator!AG21 -> 0 | R21: =SUM(Generator!C21,Generator!J21,Generator!Q21,Generator!X21,Generator!AE21) -> 7454 | S21: =24.43*0.06 -> 1.4658 | U21: =U20 -> 0.32 | V21: 62 | W21: 124 | X21: 67 | Y21: 97 | Z21: 27
A22: 44762 | B22: 65.8 | C22: 345 | D22: 2,75 | E22: 3,69 | F22: 4,74 | J22: 1,41 | K22: 1,25 | L22: 3,83 | M22: =Generator!E22 -> 10347 | N22: =Generator!L22 -> 7140 | O22: =Generator!S22 -> 4363 | P22: =Generator!Z22 -> 10285 | Q22: =Generator!AG22 -> 0 | R22: =SUM(Generator!C22,Generator!J22,Generator!Q22,Generator!X22,Generator!AE22) -> 7683 | S22: =25.26*0.06 -> 1.5156 | U22: =U21 -> 0.32 | V22: 60 | W22: 116 | X22: 57 | Y22: 98 | Z22: 27 | AD22: 36552
A23: 44763 | B23: 67.1 | C23: 379 | D23: 2,92 | E23: 3,40 | F23: 4,77 | J23: 1,21 | K23: 1,27 | L23: 3,50 | M23: =Generator!E23 -> 6778 | N23: =Generator!L23 -> 12609 | O23: =Generator!S23 -> 6838 | P23: =Generator!Z23 -> 10444 | Q23: =Generator!AG23 -> 0 | R23: =SUM(Generator!C23,Generator!J23,Generator!Q23,Generator!X23,Generator!AE23) -> 7984 | S23: =25.26*0.06 -> 1.5156 | U23: =U22 -> 0.32 | V23: 57 | W23: 123 | X23: 35 | Y23: 99 | Z23: 9 | AD23: 36709
A24: 44764 | B24: 65.8 | C24: 408 | D24: 3,23 | E24: 3,76 | F24: 4,93 | J24: 1,43 | K24: 1,39 | L24: 4,00 | M24: =Generator!E24 -> 10301 | N24: =Generator!L24 -> 9367 | O24: =Generator!S24 -> 9123 | P24: =Generator!Z24 -> 1050 | Q24: =Generator!AG24 -> 0 | R24: =SUM(Generator!C24,Generator!J24,Generator!Q24,Generator!X24,Generator!AE24) -> 6582 | S24: =25.26*0.06 -> 1.5156 | U24: =U23 -> 0.32 | V24: 63 | W24: 101 | X24: 49 | Y24: 93 | Z24: 31
A25: 44765 | B25: 59.2 | C25: 342 | D25: 3,11 | E25: 3,85 | F25: 5,01 | J25: 1,47 | K25: 1,49 | L25: 3,95 | M25: =Generator!E25 -> 9998 | N25: =Generator!L25 -> 6004 | O25: =Generator!S25 -> 0 | P25: =Generator!Z25 -> 9823 | Q25: =Generator!AG25 -> 10583 | R25: =SUM(Generator!C25,Generator!J25,Generator!Q25,Generator!X25,Generator!AE25) -> 8519 | S25: =25.26*0.06 -> 1.5156 | U25: =U24 -> 0.32 | V25: 64 | W25: 88 | X25: 51 | Y25: 96 | Z25: 41 | AD25: 36852
A26: 44766 | B26: 51.3 | C26: 401 | D26: 3,06 | E26: 3,79 | F26: 4,88 | J26: 1,37 | K26: 1,46 | L26: 3,72 | M26: =Generator!E26 -> 9606 | N26: =Generator!L26 -> 9488 | O26: =Generator!S26 -> 0 | P26: =Generator!Z26 -> 10025 | Q26: =Generator!AG26 -> 6236 | R26: =SUM(Generator!C26,Generator!J26,Generator!Q26,Generator!X26,Generator!AE26) -> 7980 | S26: =25.26*0.06 -> 1.5156 | U26: =U25 -> 0.32 | V26: 52 | W26: 120 | X26: 90 | Y26: 79 | Z26: 13 | AD26: 37140
A27: 44767 | B27: 73.7 | C27: 285 | D27: 2,87 | E27: 3,42 | F27: 4,89 | J27: 1,26 | K27: 1,29 | L27: 3,65 | M27: =Generator!E27 -> 6819 | N27: =Generator!L27 -> 4609 | O27: =Generator!S27 -> 9162 | P27: =Generator!Z27 -> 4433 | Q27: =Generator!AG27 -> 8911 | R27: =SUM(Generator!C27,Generator!J27,Generator!Q27,Generator!X27,Generator!AE27) -> 7780 | S27: =25.26*0.06 -> 1.5156 | U27: =U26 -> 0.32 | V27: 57 | W27: =156-38-18-3 -> 97 | X27: 47 | Y27: 61 | Z27: 0
A28: 44768 | B28: 77.6 | C28: 259 | D28: 2,97 | E28: 3,09 | F28: 4,92 | J28: 1,21 | K28: 1,44 | L28: 3,60 | M28: =Generator!E28 -> 9387 | N28: =Generator!L28 -> 5714 | O28: =Generator!S28 -> 5694 | P28: =Generator!Z28 -> 9314 | Q28: =Generator!AG28 -> 8806 | R28: =SUM(Generator!C28,Generator!J28,Generator!Q28,Generator!X28,Generator!AE28) -> 8705 | S28: =25.26*0.06 -> 1.5156 | U28: =U27 -> 0.32 | V28: 61 | W28: 76 | X28: 51 | Y28: 11 | Z28: 0 | AD28: 37380
A29: 44769 | B29: 81.6 | C29: 232 | D29: 2,99 | E29: 3,16 | F29: 4,81 | J29: 1,44 | K29: 1,46 | L29: 3,84 | M29: =Generator!E29 -> 10908 | N29: =Generator!L29 -> 0 | O29: =Generator!S29 -> 5069 | P29: =Generator!Z29 -> 10927 | Q29: =Generator!AG29 -> 5999 | R29: =SUM(Generator!C29,Generator!J29,Generator!Q29,Generator!X29,Generator!AE29) -> 7823 | S29: =25.26*0.06 -> 1.5156 | U29: =U28 -> 0.32 | V29: 52 | W29: 107 | X29: 42 | Y29: 74 | Z29: 0 | AD29: 37546
A30: 44770 | B30: 78.9 | C30: 283 | D30: 3,12 | E30: 3,62 | F30: 4,89 | J30: 1,39 | K30: 1,39 | L30: 3,74 | M30: =Generator!E30 -> 5255 | N30: =Generator!L30 -> 0 | O30: =Generator!S30 -> 8751 | P30: =Generator!Z30 -> 9233 | Q30: =Generator!AG30 -> 9312 | R30: =SUM(Generator!C30,Generator!J30,Generator!Q30,Generator!X30,Generator!AE30) -> 7042 | S30: =25.26*0.06 -> 1.5156 | U30: =U29 -> 0.32 | V30: 57 | W30: 109 | X30: 54 | Y30: 104 | Z30: 0 | AD30: 37697
A31: 44771 | B31: 77.6 | C31: 248 | D31: 3,05 | E31: 3,33 | F31: 4,82 | J31: 1,46 | K31: 1,32 | L31: 3,84 | M31: =Generator!E31 -> 11828 | N31: =Generator!L31 -> 6177 | O31: =Generator!S31 -> 0 | P31: =Generator!Z31 -> 10097 | Q31: =Generator!AG31 -> 9307 | R31: =SUM(Generator!C31,Generator!J31,Generator!Q31,Generator!X31,Generator!AE31) -> 8208 | S31: =25.26*0.06 -> 1.5156 | U31: =U30 -> 0.32 | V31: 54 | W31: 108 | X31: 37 | Y31: 101 | Z31: 0 | AD31: 37828
A32: 44772 | B32: 80.3 | C32: 309 | D32: 3,34 | E32: 3,42 | F32: 4,86 | J32: 1,42 | K32: 1,40 | L32: 3,77 | M32: =Generator!E32 -> 10662 | N32: =Generator!L32 -> 5147 | O32: =Generator!S32 -> 0 | P32: =Generator!Z32 -> 8670 | Q32: =Generator!AG32 -> 10735 | R32: =SUM(Generator!C32,Generator!J32,Generator!Q32,Generator!X32,Generator!AE32) -> 7874 | S32: =25.26*0.06 -> 1.5156 | U32: =U31 -> 0.32 | V32: 55 | W32: 63 | X32: 46 | Y32: 94 | Z32: 0 | AD32: 37938
A33: 44773 | D33: 3,25 | E33: 3,40 | F33: 4,89 | J33: 1,47 | K33: 1,39 | L33: 3,84 | M33: =Generator!E33 -> 10243 | N33: =Generator!L33 -> 5896 | O33: =Generator!S33 -> 0 | P33: =Generator!Z33 -> 3421 | Q33: =Generator!AG33 -> 10401 | R33: =SUM(Generator!C33,Generator!J33,Generator!Q33,Generator!X33,Generator!AE33) -> 6378 | S33: =25.26*0.06 -> 1.5156 | U33: =U32 -> 0.32 | V33: 53 | W33: 105 | X33: 36 | Y33: 101 | Z33: 52 | AD33: 30075
L34: =SUM(M34:Q34) -> 995191 | M34: =SUM(M3:M33) -> 238726 | N34: =SUM(N3:N33) -> 225208 | O34: =SUM(O3:O33) -> 203651 | P34: =SUM(P3:P33) -> 119812 | Q34: =SUM(Q3:Q33) -> 207794 | R34: =SUM(R3:R33) -> 219902 | V34: =SUM(V3:V33) -> 1744 | W34: =SUM(W3:W33) -> 3486 | X34: =SUM(X3:X33) -> 1632 | Y34: =SUM(Y3:Y33) -> 2705 | Z34: =SUM(Z3:Z33) -> 1146 | AA34: =SUM(V34:Z34) -> 10713
C35: =SUM(C3:C33) -> 10096
X36: =SUM(V34:Z34) -> 10713

Sheet Generator
B1: Generator#1 (KWH) | I1: Generator#2 (KWH) | P1: Generator#3 (KWH) | W1: Generator#4 (KWH) | AD1: Generator#5 (KWH)
A2: DATE | B2: Running Hours | C2: Daily Fuel Burned | D2: Fuel burned Per Hour | E2: Daily Energy Consumed | F2: Energy Consumed Per Hour | G2: Engine Efficiency | I2: Running Hours | J2: Daily Fuel Burned | K2: Fuel burned Per Hour | L2: Daily Energy Consumed | M2: Energy Consumed Per Hour | N2: Engine Efficiency | P2: Running Hours | Q2: Daily Fuel Burned | R2: Fuel burned Per Hour | S2: Daily Energy Consumed | T2: Energy Consumed Per Hour | U2: Engine Efficiency | W2: Running Hours | X2: Daily Fuel Burned | Y2: Fuel burned Per Hour | Z2: Daily Energy Consumed | AA2: Energy Consumed Per Hour | AB2: Engine Efficiency | AD2: Running Hours | AE2: Daily Fuel Burned | AF2: Fuel burned Per Hour | AG2: Daily Energy Consumed | AH2: Energy Consumed Per Hour | AI2: Engine Efficiency
A3: 44743 | B3: 10 | C3: 1197 | D3: =C3/B3 -> 119.7 | E3: 5048 | F3: =E3/B3 -> 504.8 | G3: =F3/D3 -> 4.2172097 | I3: 15 | J3: 2168 | K3: =J3/I3 -> 144.53333 | L3: 9744 | M3: =L3/I3 -> 649.6 | N3: =M3/K3 -> 4.4944649 | P3: 4 | Q3: 377 | R3: =Q3/P3 -> 94.25 | S3: 1658 | T3: =S3/P3 -> 414.5 | U3: =T3/R3 -> 4.397878 | W3: 0 | X3: 0 | Y3: =X3/W3 -> #DIV/0! | Z3: 0 | AA3: =Z3/W3 -> #DIV/0! | AB3: =AA3/Y3 -> #DIV/0! | AD3: 15 | AE3: 2135 | AF3: =AE3/AD3 -> 142.33333 | AG3: 9765 | AH3: =AG3/AD3 -> 651 | AI3: =AH3/AF3 -> 4.5737705
A4: 44744 | B4: 11 | C4: 1504 | D4: =C4/B4 -> 136.72727 | E4: 6820 | F4: =E4/B4 -> 620 | G4: =F4/D4 -> 4.5345745 | I4: 10 | J4: 1241 | K4: =J4/I4 -> 124.1 | L4: 5581 | M4: =L4/I4 -> 558.1 | N4: =M4/K4 -> 4.4971797 | P4: 0 | Q4: 0 | R4: =Q4/P4 -> #DIV/0! | S4: 0 | T4: =S4/P4 -> #DIV/0! | U4: =T4/R4 -> #DIV/0! | W4: 12 | X4: 1217 | Y4: =X4/W4 -> 101.41667 | Z4: 7574 | AA4: =Z4/W4 -> 631.16667 | AB4: =AA4/Y4 -> 6.2235004 | AD4: 14 | AE4: 1536 | AF4: =AE4/AD4 -> 109.71429 | AG4: 7404 | AH4: =AG4/AD4 -> 528.85714 | AI4: =AH4/AF4 -> 4.8203125
A5: 44745 | B5: 14 | C5: 2117 | D5: =C5/B5 -> 151.21429 | E5: 9824 | F5: =E5/B5 -> 701.71429 | G5: =F5/D5 -> 4.6405291 | I5: 10 | J5: 1217 | K5: =J5/I5 -> 121.7 | L5: 5251 | M5: =L5/I5 -> 525.1 | N5: =M5/K5 -> 4.3147083 | P5: 14 | Q5: 2090 | R5: =Q5/P5 -> 149.28571 | S5: 9861 | T5: =S5/P5 -> 704.35714 | U5: =T5/R5 -> 4.7181818 | W5: 10 | X5: 1217 | Y5: =X5/W5 -> 121.7 | Z5: 5151 | AA5: =Z5/W5 -> 515.1 | AB5: =AA5/Y5 -> 4.232539 | AD5: 9 | AE5: 1186 | AF5: =AE5/AD5 -> 131.77778 | AG5: 5294 | AH5: =AG5/AD5 -> 588.22222 | AI5: =AH5/AF5 -> 4.4637437
A6: 44746 | B6: 16 | C6: 2290 | D6: =C6/B6 -> 143.125 | E6: 10140 | F6: =E6/B6 -> 633.75 | G6: =F6/D6 -> 4.4279476 | I6: 8 | J6: 842 | K6: =J6/I6 -> 105.25 | L6: 3751 | M6: =L6/I6 -> 468.875 | N6: =M6/K6 -> 4.4548694 | P6: 17 | Q6: 2244 | R6: =Q6/P6 -> 132 | S6: 10777 | T6: =S6/P6 -> 633.94118 | U6: =T6/R6 -> 4.8025847 | W6: 0 | X6: 0 | Y6: =X6/W6 -> #DIV/0! | Z6: 0 | AA6: =Z6/W6 -> #DIV/0! | AB6: =AA6/Y6 -> #DIV/0! | AD6: 9 | AE6: 1026 | AF6: =AE6/AD6 -> 114 | AG6: 4402 | AH6: =AG6/AD6 -> 489.11111 | AI6: =AH6/AF6 -> 4.2904483
A7: 44747 | B7: 16 | C7: 2291 | D7: =C7/B7 -> 143.1875 | E7: 11010 | F7: =E7/B7 -> 688.125 | G7: =F7/D7 -> 4.8057617 | I7: 9 | J7: 941 | K7: =J7/I7 -> 104.55556 | L7: 4008 | M7: =L7/I7 -> 445.33333 | N7: =M7/K7 -> 4.2592986 | P7: 16 | Q7: 2266 | R7: =Q7/P7 -> 141.625 | S7: 11026 | T7: =S7/P7 -> 689.125 | U7: =T7/R7 -> 4.8658429 | W7: 0 | X7: 0 | Y7: =X7/W7 -> #DIV/0! | Z7: 0 | AA7: =Z7/W7 -> #DIV/0! | AB7: =AA7/Y7 -> #DIV/0! | AD7: 10 | AE7: 1098 | AF7: =AE7/AD7 -> 109.8 | AG7: 4852 | AH7: =AG7/AD7 -> 485.2 | AI7: =AH7/AF7 -> 4.4189435
A8: 44748 | B8: 13 | C8: 1643 | D8: =C8/B8 -> 126.38462 | E8: 6750 | F8: =E8/B8 -> 519.23077 | G8: =F8/D8 -> 4.1083384 | I8: 9 | J8: 1140 | K8: =J8/I8 -> 126.66667 | L8: 4907 | M8: =L8/I8 -> 545.22222 | N8: =M8/K8 -> 4.304386 | P8: 14 | Q8: 2013 | R8: =Q8/P8 -> 143.78571 | S8: 9453 | T8: =S8/P8 -> 675.21429 | U8: =T8/R8 -> 4.6959762 | W8: 0 | X8: 0 | Y8: =X8/W8 -> #DIV/0! | Z8: 0 | AA8: =Z8/W8 -> #DIV/0! | AB8: =AA8/Y8 -> #DIV/0! | AD8: 11 | AE8: 1683 | AF8: =AE8/AD8 -> 153 | AG8: 7658 | AH8: =AG8/AD8 -> 696.18182 | AI8: =AH8/AF8 -> 4.550208
A9: 44749 | B9: 10 | C9: 1263 | D9: =C9/B9 -> 126.3 | E9: 5554 | F9: =E9/B9 -> 555.4 | G9: =F9/D9 -> 4.3974663 | I9: 10 | J9: 1252 | K9: =J9/I9 -> 125.2 | L9: 5574 | M9: =L9/I9 -> 557.4 | N9: =M9/K9 -> 4.4520767 | P9: 15 | Q9: 2206 | R9: =Q9/P9 -> 147.06667 | S9: 10535 | T9: =S9/P9 -> 702.33333 | U9: =T9/R9 -> 4.775612 | W9: 0 | X9: 0 | Y9: =X9/W9 -> #DIV/0! | Z9: 0 | AA9: =Z9/W9 -> #DIV/0! | AB9: =AA9/Y9 -> #DIV/0! | AD9: 15 | AE9: 2224 | AF9: =AE9/AD9 -> 148.26667 | AG9: 10513 | AH9: =AG9/AD9 -> 700.86667 | AI9: =AH9/AF9 -> 4.7270683
A10: 44750 | B10: 10 | C10: 1366 | D10: =C10/B10 -> 136.6 | E10: 5857 | F10: =E10/B10 -> 585.7 | G10: =F10/D10 -> 4.2877013 | I10: 10 | J10: 1243 | K10: =J10/I10 -> 124.3 | L10: 5593 | M10: =L10/I10 -> 559.3 | N10: =M10/K10 -> 4.4995977 | P10: 14 | Q10: 2112 | R10: =Q10/P10 -> 150.85714 | S10: 9935 | T10: =S10/P10 -> 709.64286 | U10: =T10/R10 -> 4.704072 | W10: 0 | X10: 0 | Y10: =X10/W10 -> #DIV/0! | Z10: 0 | AA10: =Z10/W10 -> #DIV/0! | AB10: =AA10/Y10 -> #DIV/0! | AD10: 14 | AE10: 2111 | AF10: =AE10/AD10 -> 150.78571 | AG10: 9950 | AH10: =AG10/AD10 -> 710.71429 | AI10: =AH10/AF10 -> 4.713406
A11: 44751 | B11: 16 | C11: 2104 | D11: =C11/B11 -> 131.5 | E11: 9812 | F11: =E11/B11 -> 613.25 | G11: =F11/D11 -> 4.6634981 | I11: 10 | J11: 1207 | K11: =J11/I11 -> 120.7 | L11: 5432 | M11: =L11/I11 -> 543.2 | N11: =M11/K11 -> 4.5004143 | P11: 9 | Q11: 1122 | R11: =Q11/P11 -> 124.66667 | S11: 5593 | T11: =S11/P11 -> 621.44444 | U11: =T11/R11 -> 4.9848485 | W11: 0 | X11: 0 | Y11: =X11/W11 -> #DIV/0! | Z11: 0 | AA11: =Z11/W11 -> #DIV/0! | AB11: =AA11/Y11 -> #DIV/0! | AD11: 15 | AE11: 2222 | AF11: =AE11/AD11 -> 148.13333 | AG11: 10231 | AH11: =AG11/AD11 -> 682.06667 | AI11: =AH11/AF11 -> 4.6044104
A12: 44752 | B12: 10 | C12: 1212 | D12: =C12/B12 -> 121.2 | E12: 5304 | F12: =E12/B12 -> 530.4 | G12: =F12/D12 -> 4.3762376 | I12: 14 | J12: 2241 | K12: =J12/I12 -> 160.07143 | L12: 10428 | M12: =L12/I12 -> 744.85714 | N12: =M12/K12 -> 4.6532798 | P12: 14 | Q12: 2286 | R12: =Q12/P12 -> 163.28571 | S12: 10665 | T12: =S12/P12 -> 761.78571 | U12: =T12/R12 -> 4.6653543 | W12: 0 | X12: 0 | Y12: =X12/W12 -> #DIV/0! | Z12: 0 | AA12: =Z12/W12 -> #DIV/0! | AB12: =AA12/Y12 -> #DIV/0! | AD12: 10 | AE12: 1207 | AF12: =AE12/AD12 -> 120.7 | AG12: 5236 | AH12: =AG12/AD12 -> 523.6 | AI12: =AH12/AF12 -> 4.3380282
A13: 44753 | B13: 16 | C13: 2372 | D13: =C13/B13 -> 148.25 | E13: 10840 | F13: =E13/B13 -> 677.5 | G13: =F13/D13 -> 4.5699831 | I13: 25 | J13: 3392 | K13: =J13/I13 -> 135.68 | L13: 15499 | M13: =L13/I13 -> 619.96 | N13: =M13/K13 -> 4.5692807 | P13: 0 | Q13: 0 | R13: =Q13/P13 -> #DIV/0! | S13: 0 | T13: =S13/P13 -> #DIV/0! | U13: =T13/R13 -> #DIV/0! | W13: 0 | X13: 0 | Y13: =X13/W13 -> #DIV/0! | Z13: 0 | AA13: =Z13/W13 -> #DIV/0! | AB13: =AA13/Y13 -> #DIV/0! | AD13: 9 | AE13: 930 | AF13: =AE13/AD13 -> 103.33333 | AG13: 4539 | AH13: =AG13/AD13 -> 504.33333 | AI13: =AH13/AF13 -> 4.8806452
A14: 44754 | B14: 0 | C14: 0 | D14: =C14/B14 -> #DIV/0! | E14: 0 | F14: =E14/B14 -> #DIV/0! | G14: =F14/D14 -> #DIV/0! | I14: 9 | J14: 1052 | K14: =J14/I14 -> 116.88889 | L14: 4668 | M14: =L14/I14 -> 518.66667 | N14: =M14/K14 -> 4.4372624 | P14: 16 | Q14: 2284 | R14: =Q14/P14 -> 142.75 | S14: 10699 | T14: =S14/P14 -> 668.6875 | U14: =T14/R14 -> 4.6843257 | W14: 0 | X14: 0 | Y14: =X14/W14 -> #DIV/0! | Z14: 0 | AA14: =Z14/W14 -> #DIV/0! | AB14: =AA14/Y14 -> #DIV/0! | AD14: 24 | AE14: 3320 | AF14: =AE14/AD14 -> 138.33333 | AG14: 15287 | AH14: =AG14/AD14 -> 636.95833 | AI14: =AH14/AF14 -> 4.6045181
... A33: 44773 | B33: 14 | C33: 2192 | D33: =C33/B33 -> 156.57143 | E33: 10243 | F33: =E33/B33 -> 731.64286 | G33: =F33/D33 -> 4.6729015 | I33: 10 | J33: 1299 | K33: =J33/I33 -> 129.9 | L33: 5896 | M33: =L33/I33 -> 589.6 | N33: =M33/K33 -> 4.5388761 | P33: 0 | Q33: 0 | R33: =Q33/P33 -> #DIV/0! | S33: 0 | T33: =S33/P33 -> #DIV/0! | U33: =T33/R33 -> #DIV/0! | W33: 6 | X33: 749 | Y33: =X33/W33 -> 124.83333 | Z33: 3421 | AA33: =Z33/W33 -> 570.16667 | AB33: =AA33/Y33 -> 4.5674232 | AD33: 15 | AE33: 2138 | AF33: =AE33/AD33 -> 142.53333 | AG33: 10401 | AH33: =AG33/AD33 -> 693.4 | AI33: =AH33/AF33 -> 4.8648269
A34: TOTAL | B34: =SUM(B3:B33) -> 374 | C34: =SUM(C3:C33) -> 53420 | D34: =SUM(D3:D33) -> #DIV/0! | E34: =SUM(E3:E33) -> 238726 | F34: =SUM(F3:F33) -> #DIV/0! | G34: =SUM(G3:G33) -> #DIV/0! | I34: =SUM(I3:I33) -> 369 | J34: =SUM(J3:J33) -> 49565 | K34: =SUM(K3:K33) -> #DIV/0! | L34: =SUM(L3:L33) -> 225208 | M34: =SUM(M3:M33) -> #DIV/0! | N34: =SUM(N3:N33) -> #DIV/0! | R34: =SUM(R3:R33) -> #DIV/0! | S34: =SUM(S3:S33) -> 203651 | T34: =SUM(T3:T33) -> #DIV/0! | U34: =SUM(U3:U33) -> #DIV/0! | W34: =SUM(W3:W33) -> 184 | X34: =SUM(X3:X33) -> 28781 | Y34: =SUM(Y3:Y33) -> #DIV/0! | Z34: =SUM(Z3:Z33) -> 119812 | AA34: =SUM(AA3:AA33) -> #DIV/0! | AB34: =SUM(AB3:AB33) -> #DIV/0! | AD34: =SUM(AD3:AD33) -> 338 | AE34: =SUM(AE3:AE33) -> 45215 | AF34: =SUM(AF3:AF33) -> #DIV/0! | AG34: =SUM(AG3:AG33) -> 207794 | AH34: =SUM(AH3:AH33) -> #DIV/0! | AI34: =SUM(AI3:AI33) -> #DIV/0!
B36: DG1 | C36: DG2 | D36: DG3 | E36: DG4 | F36: DG5
A37: OLV | B37: =86-B22-B23-B24 -> 45 | C37: =169-I22-I23-I24-I25 -> 115 | D37: =112-P22-P23-P24 -> 78 | E37: =95-W22-W23-W24 -> 63 | F37: =237-AD23-AD24-AD25 -> 219 | G37: 3 DAYS
E66: 0

Sheet 2019-2022 Utility
A1: 44743 | B1: OCCUPANCY | D1: GENERATOR | F1: DIESEL | H1: WATER
A2: DAY | B2: 2019 | C2: 2022 | D2: 2019 | E2: 2022 | F2: 2019 | G2: 2022 | H2: 2019 | I2: 2022
A3: 1 | C3: ='FS Seychelles'!B3 -> 64.5 | D3: 0 | E3: =SUM('FS Seychelles'!M3:Q3) -> 26215 | F3: 0 | G3: ='FS Seychelles'!R3 -> 5877 | H3: 0 | I3: =SUM('FS Seychelles'!V3:Z3) -> 350
A4: 2 | C4: ='FS Seychelles'!B4 -> 65.8 | D4: 12131 | E4: =SUM('FS Seychelles'!M4:Q4) -> 27379 | F4: 3140 | G4: ='FS Seychelles'!R4 -> 5498 | H4: 0 | I4: =SUM('FS Seychelles'!V4:Z4) -> 256
