Workbook

Sheet TOTAL
A1: Site Name | B1: Day | C1: Month | D1: Year | E1: Total Electricity Kwh | F1: Electricity Tariff ($/Kwh) | G1: Natual Gas (m3) | H1: Natural Gas $/m3 | I1: Water Utility Supply (m3) m3 | J1: Water Utility Supply (m3) $/m3 | K1: Room Nights | L1: Total Guests | M1: Utilities day cost dh
A2: Mumbai | B2: 1 | C2: 8 | D2: 2022 | E2: =(IF('Daily HLP'!H4>0,'Daily HLP'!H4,0)) -> 25783 | F2: 9 | G2: =(IF('Daily HLP'!L4>0,'Daily HLP'!L4,0)) -> 1063.6 | H2: 75 | I2: =(IF('Daily HLP'!O4>0,'Daily HLP'!O4,0)) -> 182 | J2: 100 | K2: =Occupancy!G2 -> 119 | L2: =Occupancy!F2 -> 306 | M2: =E2*F2+G2*H2+#REF!*#REF!+I2*J2 -> #REF!
A3: Mumbai | B3: =B2+1 -> 2 | C3: 8 | D3: 2022 | E3: =(IF('Daily HLP'!H5>0,'Daily HLP'!H5,0)) -> 25845 | F3: 9 | G3: =(IF('Daily HLP'!L5>0,'Daily HLP'!L5,0)) -> 1000.7 | H3: 75 | I3: =(IF('Daily HLP'!O5>0,'Daily HLP'!O5,0)) -> 231 | J3: 100 | K3: =Occupancy!G3 -> 130 | L3: =Occupancy!F3 -> 406 | M3: =E3*F3+G3*H3+#REF!*#REF!+I3*J3 -> #REF!
A4: Mumbai | B4: =B3+1 -> 3 | C4: 8 | D4: 2022 | E4: =(IF('Daily HLP'!H6>0,'Daily HLP'!H6,0)) -> 28055 | F4: 9 | G4: =(IF('Daily HLP'!L6>0,'Daily HLP'!L6,0)) -> 979.2 | H4: 75 | I4: =(IF('Daily HLP'!O6>0,'Daily HLP'!O6,0)) -> 155 | J4: 100 | K4: =Occupancy!G4 -> 140 | L4: =Occupancy!F4 -> 744 | M4: =E4*F4+G4*H4+#REF!*#REF!+I4*J4 -> #REF!
A5: Mumbai | B5: =B4+1 -> 4 | C5: 8 | D5: 2022 | E5: =(IF('Daily HLP'!H7>0,'Daily HLP'!H7,0)) -> 25892 | F5: 9 | G5: =(IF('Daily HLP'!L7>0,'Daily HLP'!L7,0)) -> 1002.3 | H5: 75 | I5: =(IF('Daily HLP'!O7>0,'Daily HLP'!O7,0)) -> 183 | J5: 100 | K5: =Occupancy!G5 -> 147 | L5: =Occupancy!F5 -> 534 | M5: =E5*F5+G5*H5+#REF!*#REF!+I5*J5 -> #REF!
A6: Mumbai | B6: =B5+1 -> 5 | C6: 8 | D6: 2022 | E6: =(IF('Daily HLP'!H8>0,'Daily HLP'!H8,0)) -> 27118 | F6: 9 | G6: =(IF('Daily HLP'!L8>0,'Daily HLP'!L8,0)) -> 1047.2 | H6: 75 | I6: =(IF('Daily HLP'!O8>0,'Daily HLP'!O8,0)) -> 192 | J6: 100 | K6: =Occupancy!G6 -> 143 | L6: =Occupancy!F6 -> 428 | M6: =E6*F6+G6*H6+#REF!*#REF!+I6*J6 -> #REF!
A7: Mumbai | B7: =B6+1 -> 6 | C7: 8 | D7: 2022 | E7: =(IF('Daily HLP'!H9>0,'Daily HLP'!H9,0)) -> 26156 | F7: 9 | G7: =(IF('Daily HLP'!L9>0,'Daily HLP'!L9,0)) -> 981 | H7: 75 | I7: =(IF('Daily HLP'!O9>0,'Daily HLP'!O9,0)) -> 247 | J7: 100 | K7: =Occupancy!G7 -> 138 | L7: =Occupancy!F7 -> 596 | M7: =E7*F7+G7*H7+#REF!*#REF!+I7*J7 -> #REF!
A8: Mumbai | B8: =B7+1 -> 7 | C8: 8 | D8: 2022 | E8: =(IF('Daily HLP'!H10>0,'Daily HLP'!H10,0)) -> 25917 | F8: 9 | G8: =(IF('Daily HLP'!L10>0,'Daily HLP'!L10,0)) -> 1066 | H8: 75 | I8: =(IF('Daily HLP'!O10>0,'Daily HLP'!O10,0)) -> 287 | J8: 100 | K8: =Occupancy!G8 -> 125 | L8: =Occupancy!F8 -> 315 | M8: =E8*F8+G8*H8+#REF!*#REF!+I8*J8 -> #REF!
A9: Mumbai | B9: =B8+1 -> 8 | C9: 8 | D9: 2022 | E9: =(IF('Daily HLP'!H11>0,'Daily HLP'!H11,0)) -> 26500 | F9: 9 | G9: =(IF('Daily HLP'!L11>0,'Daily HLP'!L11,0)) -> 1000 | H9: 75 | I9: =(IF('Daily HLP'!O11>0,'Daily HLP'!O11,0)) -> 0 | J9: 100 | K9: =Occupancy!G9 -> 0 | L9: =Occupancy!F9 -> 0 | M9: =E9*F9+G9*H9+#REF!*#REF!+I9*J9 -> #REF!
A10: Mumbai | B10: =B9+1 -> 9 | C10: 8 | D10: 2022 | E10: =(IF('Daily HLP'!H12>0,'Daily HLP'!H12,0)) -> 26500 | F10: 9 | G10: =(IF('Daily HLP'!L12>0,'Daily HLP'!L12,0)) -> 1000 | H10: 75 | I10: =(IF('Daily HLP'!O12>0,'Daily HLP'!O12,0)) -> 270 | J10: 100 | K10: =Occupancy!G10 -> 0 | L10: =Occupancy!F10 -> 0 | M10: =E10*F10+G10*H10+#REF!*#REF!+I10*J10 -> #REF!
A11: Mumbai | B11: =B10+1 -> 10 | C11: 8 | D11: 2022 | E11: =(IF('Daily HLP'!H13>0,'Daily HLP'!H13,0)) -> 26500 | F11: 9 | G11: =(IF('Daily HLP'!L13>0,'Daily HLP'!L13,0)) -> 1000 | H11: 75 | I11: =(IF('Daily HLP'!O13>0,'Daily HLP'!O13,0)) -> 270 | J11: 100 | K11: =Occupancy!G11 -> 0 | L11: =Occupancy!F11 -> 0 | M11: =E11*F11+G11*H11+#REF!*#REF!+I11*J11 -> #REF!
A12: Mumbai | B12: =B11+1 -> 11 | C12: 8 | D12: 2022 | E12: =(IF('Daily HLP'!H14>0,'Daily HLP'!H14,0)) -> 26500 | F12: 9 | G12: =(IF('Daily HLP'!L14>0,'Daily HLP'!L14,0)) -> 1000 | H12: 75 | I12: =(IF('Daily HLP'!O14>0,'Daily HLP'!O14,0)) -> 221 | J12: 100 | K12: =Occupancy!G12 -> 0 | L12: =Occupancy!F12 -> 0 | M12: =E12*F12+G12*H12+#REF!*#REF!+I12*J12 -> #REF!
A13: Mumbai | B13: =B12+1 -> 12 | C13: 8 | D13: 2022 | E13: =(IF('Daily HLP'!H15>0,'Daily HLP'!H15,0)) -> 26500 | F13: 9 | G13: =(IF('Daily HLP'!L15>0,'Daily HLP'!L15,0)) -> 1000 | H13: 75 | I13: =(IF('Daily HLP'!O15>0,'Daily HLP'!O15,0)) -> 254 | J13: 100 | K13: =Occupancy!G13 -> 0 | L13: =Occupancy!F13 -> 0 | M13: =E13*F13+G13*H13+#REF!*#REF!+I13*J13 -> #REF!
A14: Mumbai | B14: =B13+1 -> 13 | C14: 8 | D14: 2022 | E14: =(IF('Daily HLP'!H16>0,'Daily HLP'!H16,0)) -> 26500 | F14: 9 | G14: =(IF('Daily HLP'!L16>0,'Daily HLP'!L16,0)) -> 1000 | H14: 75 | I14: =(IF('Daily HLP'!O16>0,'Daily HLP'!O16,0)) -> 170 | J14: 100 | K14: =Occupancy!G14 -> 0 | L14: =Occupancy!F14 -> 0 | M14: =E14*F14+G14*H14+#REF!*#REF!+I14*J14 -> #REF!
... A31: Mumbai | B31: =B30+1 -> 30 | C31: 8 | D31: 2022 | E31: =(IF('Daily HLP'!H33>0,'Daily HLP'!H33,0)) -> 26500 | F31: 9 | G31: =(IF('Daily HLP'!L33>0,'Daily HLP'!L33,0)) -> 1000 | H31: 75 | I31: =(IF('Daily HLP'!O33>0,'Daily HLP'!O33,0)) -> 181 | J31: 100 | K31: =Occupancy!G31 -> 0 | L31: =Occupancy!F31 -> 0 | M31: =E31*F31+G31*H31+#REF!*#REF!+I31*J31 -> #REF!
A32: Mumbai | B32: =B31+1 -> 31 | C32: 8 | D32: 2022 | E32: =(IF('Daily HLP'!H34>0,'Daily HLP'!H34,0)) -> 26500 | F32: 9 | G32: =(IF('Daily HLP'!L34>0,'Daily HLP'!L34,0)) -> 1000 | H32: 75 | I32: =(IF('Daily HLP'!O34>0,'Daily HLP'!O34,0)) -> 321 | J32: 100 | K32: =Occupancy!G32 -> 0 | L32: =Occupancy!F32 -> 0

Sheet Submetering
A1: Site Name | B1: Day | C1: Month | D1: Year | E1: ='Section Load'!F4 -> HVAC | F1: ='Section Load'!G4 -> Fire & Emergency PP | G1: ='Section Load'!H4 -> Main PP | H1: ='Section Load'!I4 -> Lighting PP | I1: ='Section Load'!J4 -> CH-1+ CH2+CH3+CH4 | J1: ='Section Load'!K4 -> Chilled water Pump | K1: ='Section Load'!L4 -> Ball Room-1 | L1: ='Section Load'!M4 -> Ball Room-2 | ... AL1: ='Section Load'!AM4 -> Cooling Tower | AM1: R.o.plant | AN1: STP Water Prod | AO1: Domestic Zone-1 | AP1: Domestic Zone-2 | AQ1: Domestic Zone-3 | AR1: Flush Zone -1 | AS1: Flush Zone -2 | AT1: Flush Zone -3 | AU1: Swimming pool | AV1: B2 Laundry | AW1: Boiler Feed Water | AX1: cooling tower filling water | AY1: STP flush(new water meter) | AZ1: Garden Water Pump | BA1: Flush Zone 2 pump meter | BB1: Flush Zone 3 Pump Meter (wtp transfer ) | BC1: Flush Tanker-Zone-1 | BD1: Total Domestic Water (Tanker (R.O) +BMC) | BE1: Total Domestic Consumption | BF1: Total STP Consumption | BG1: ='Section Load'!AN4 -> MGL | BH1: ='Section Load'!AO4 -> HWG | BI1: ='Section Load'!AP4 -> Prato | BJ1: ='Section Load'!AQ4 -> BR-1 | BK1: ='Section Load'!AR4 -> SanQi IND | BL1: ='Section Load'!AS4 -> SanQi JPN | BM1: ='Section Load'!AT4 -> Boiler
A2: Mumbai | B2: 1 | C2: 8 | D2: 2022 | E2: =(IF('Section Load'!F5>0,'Section Load'!F5,0)) -> 4229.35 | F2: =(IF('Section Load'!G5>0,'Section Load'!G5,0)) -> 1127.2 | G2: =(IF('Section Load'!H5>0,'Section Load'!H5,0)) -> 2260.06 | H2: =(IF('Section Load'!I5>0,'Section Load'!I5,0)) -> 4348.86 | I2: =(IF('Section Load'!J5>0,'Section Load'!J5,0)) -> 6923.3 | J2: =(IF('Section Load'!K5>0,'Section Load'!K5,0)) -> 3125.45 | K2: =(IF('Section Load'!L5>0,'Section Load'!L5,0)) -> 1020.39 | L2: =(IF('Section Load'!M5>0,'Section Load'!M5,0)) -> 620.19 | ... AL2: =(IF('Section Load'!AM5>0,'Section Load'!AM5,0)) -> 0 | AM2: =(IF('Water Report'!$D$7>0,'Water Report'!$D$7,0)) -> 97 | AN2: =(IF('Water Report'!$D$8>0,'Water Report'!$D$8,0)) -> 177 | AO2: =(IF('Water Report'!$D$9>0,'Water Report'!$D$9,0)) -> 92 | AP2: =(IF('Water Report'!$D$10>0,'Water Report'!$D$10,0)) -> 25 | AQ2: =(IF('Water Report'!$D$11>0,'Water Report'!$D$11,0)) -> 0 | AR2: =(IF('Water Report'!$D$13>0,'Water Report'!$D$13,0)) -> 18 | AS2: =(IF('Water Report'!$D$14>0,'Water Report'!$D$14,0)) -> 10 | AT2: =(IF('Water Report'!$D$15>0,'Water Report'!$D$15,0)) -> 6 | AU2: =(IF('Water Report'!$D$17>0,'Water Report'!$D$17,0)) -> 0 | AV2: =(IF('Water Report'!$D$18>0,'Water Report'!$D$18,0)) -> 13 | AW2: =(IF('Water Report'!$D$19>0,'Water Report'!$D$19,0)) -> 11 | AX2: =(IF('Water Report'!$D$21>0,'Water Report'!$D$21,0)) -> 109 | AY2: =(IF('Water Report'!$D$22>0,'Water Report'!$D$22,0)) -> 0 | AZ2: =(IF('Water Report'!$D$23>0,'Water Report'!$D$23,0)) -> 7 | BA2: =(IF('Water Report'!$D$14>0,'Water Report'!$D$14,0)) -> 10 | BB2: =(IF('Water Report'!$D$15>0,'Water Report'!$D$15,0)) -> 6 | BC2: =(IF('Water Report'!$D$13>0,'Water Report'!$D$13,0)) -> 18 | BD2: =(IF('Water Report'!$D$24>0,'Water Report'!$D$24,0)) -> 182 | BE2: =(IF('Water Report'!$D$25>0,'Water Report'!$D$25,0)) -> 133 | BF2: =(IF('Water Report'!$D$27>0,'Water Report'!$D$27,0)) -> 134 | BG2: =(IF('Section Load'!AN5>0,'Section Load'!AN5,0)) -> 1063.6 | BH2: =(IF('Section Load'!AO5>0,'Section Load'!AO5,0)) -> 308.04 | BI2: =(IF('Section Load'!AP5>0,'Section Load'!AP5,0)) -> 0 | BJ2: =(IF('Section Load'!AQ5>0,'Section Load'!AQ5,0)) -> 116.7 | BK2: =(IF('Section Load'!AR5>0,'Section Load'!AR5,0)) -> 43 | BL2: =(IF('Section Load'!AS5>0,'Section Load'!AS5,0)) -> 0 | BM2: =(IF('Section Load'!AT5>0,'Section Load'!AT5,0)) -> 596.66
A3: Mumbai | B3: =B2+1 -> 2 | C3: 8 | D3: 2022 | E3: =(IF('Section Load'!F6>0,'Section Load'!F6,0)) -> 4402.7 | F3: =(IF('Section Load'!G6>0,'Section Load'!G6,0)) -> 1083.31 | G3: =(IF('Section Load'!H6>0,'Section Load'!H6,0)) -> 2221.05 | H3: =(IF('Section Load'!I6>0,'Section Load'!I6,0)) -> 4423.63 | I3: =(IF('Section Load'!J6>0,'Section Load'!J6,0)) -> 6103.42 | J3: =(IF('Section Load'!K6>0,'Section Load'!K6,0)) -> 2942.62 | K3: =(IF('Section Load'!L6>0,'Section Load'!L6,0)) -> 1053.84 | L3: =(IF('Section Load'!M6>0,'Section Load'!M6,0)) -> 775.66 | ... AL3: =(IF('Section Load'!AM6>0,'Section Load'!AM6,0)) -> 0 | AM3: =(IF('Water Report'!$E$7>0,'Water Report'!$E$7,0)) -> 97 | AN3: =(IF('Water Report'!$E$8>0,'Water Report'!$E$8,0)) -> 147 | AO3: =(IF('Water Report'!$E$9>0,'Water Report'!$E$9,0)) -> 103 | AP3: =(IF('Water Report'!$E$10>0,'Water Report'!$E$10,0)) -> 17 | AQ3: =(IF('Water Report'!$E$11>0,'Water Report'!$E$11,0)) -> 0 | AR3: =(IF('Water Report'!$E$13>0,'Water Report'!$E$13,0)) -> 34 | AS3: =(IF('Water Report'!$E$14>0,'Water Report'!$E$14,0)) -> 3 | AT3: =(IF('Water Report'!$E$15>0,'Water Report'!$E$15,0)) -> 11 | AU3: =(IF('Water Report'!$E$17>0,'Water Report'!$E$17,0)) -> 5 | AV3: =(IF('Water Report'!$E$18>0,'Water Report'!$E$18,0)) -> 13 | AW3: =(IF('Water Report'!$E$19>0,'Water Report'!$E$19,0)) -> 12 | AX3: =(IF('Water Report'!$E$21>0,'Water Report'!$E$21,0)) -> 85 | AY3: =(IF('Water Report'!$E$22>0,'Water Report'!$E$22,0)) -> 0 | AZ3: =(IF('Water Report'!$E$23>0,'Water Report'!$E$23,0)) -> 0 | BA3: =(IF('Water Report'!$E$14>0,'Water Report'!$E$14,0)) -> 3 | BB3: =(IF('Water Report'!$E$15>0,'Water Report'!$E$15,0)) -> 11 | BC3: =(IF('Water Report'!$E$13>0,'Water Report'!$E$13,0)) -> 34 | BD3: =(IF('Water Report'!$E$24>0,'Water Report'!$E$24,0)) -> 231 | BE3: =(IF('Water Report'!$E$25>0,'Water Report'!$E$25,0)) -> 134 | BF3: =(IF('Water Report'!$E$27>0,'Water Report'!$E$27,0)) -> 119 | BG3: =(IF('Section Load'!AN6>0,'Section Load'!AN6,0)) -> 1000.7 | BH3: =(IF('Section Load'!AO6>0,'Section Load'!AO6,0)) -> 286.33 | BI3: =(IF('Section Load'!AP6>0,'Section Load'!AP6,0)) -> 0.8 | BJ3: =(IF('Section Load'!AQ6>0,'Section Load'!AQ6,0)) -> 112.3 | BK3: =(IF('Section Load'!AR6>0,'Section Load'!AR6,0)) -> 50.8 | BL3: =(IF('Section Load'!AS6>0,'Section Load'!AS6,0)) -> 0 | BM3: =(IF('Section Load'!AT6>0,'Section Load'!AT6,0)) -> 550.47
A4: Mumbai | B4: =B3+1 -> 3 | C4: 8 | D4: 2022 | E4: =(IF('Section Load'!F7>0,'Section Load'!F7,0)) -> 4074.19 | F4: =(IF('Section Load'!G7>0,'Section Load'!G7,0)) -> 1091.69 | G4: =(IF('Section Load'!H7>0,'Section Load'!H7,0)) -> 2247.12 | H4: =(IF('Section Load'!I7>0,'Section Load'!I7,0)) -> 4283.96 | I4: =(IF('Section Load'!J7>0,'Section Load'!J7,0)) -> 7359.41 | J4: =(IF('Section Load'!K7>0,'Section Load'!K7,0)) -> 3175.12 | K4: =(IF('Section Load'!L7>0,'Section Load'!L7,0)) -> 1586.54 | L4: =(IF('Section Load'!M7>0,'Section Load'!M7,0)) -> 1174.12 | ... AL4: =(IF('Section Load'!AM7>0,'Section Load'!AM7,0)) -> 0 | AM4: =(IF('Water Report'!$F$7>0,'Water Report'!$F$7,0)) -> 101 | AN4: =(IF('Water Report'!$F$8>0,'Water Report'!$F$8,0)) -> 116 | AO4: =(IF('Water Report'!$F$9>0,'Water Report'!$G$9,0)) -> 108 | AP4: =(IF('Water Report'!$F$10>0,'Water Report'!$F$10,0)) -> 20 | AQ4: =(IF('Water Report'!$F$11>0,'Water Report'!$F$11,0)) -> 0 | AR4: =(IF('Water Report'!$F$13>0,'Water Report'!$F$13,0)) -> 17 | AS4: =(IF('Water Report'!$F$14>0,'Water Report'!$F$14,0)) -> 3 | AT4: =(IF('Water Report'!$F$15>0,'Water Report'!$F$15,0)) -> 6 | AU4: =(IF('Water Report'!$F$17>0,'Water Report'!$F$17,0)) -> 0 | AV4: =(IF('Water Report'!$F$18>0,'Water Report'!$F$18,0)) -> 13 | AW4: =(IF('Water Report'!$F$19>0,'Water Report'!$F$19,0)) -> 12 | AX4: =(IF('Water Report'!$F$21>0,'Water Report'!$F$21,0)) -> 110 | AY4: =(IF('Water Report'!$F$22>0,'Water Report'!$F$22,0)) -> 0 | AZ4: =(IF('Water Report'!$F$23>0,'Water Report'!$F$23,0)) -> 0 | BA4: =(IF('Water Report'!$F$14>0,'Water Report'!$F$14,0)) -> 3 | BB4: =(IF('Water Report'!$F$15>0,'Water Report'!$F$15,0)) -> 6 | BC4: =(IF('Water Report'!$F$13>0,'Water Report'!$F$13,0)) -> 17 | BD4: =(IF('Water Report'!$F$24>0,'Water Report'!$F$24,0)) -> 155 | BE4: =(IF('Water Report'!$F$25>0,'Water Report'!$F$25,0)) -> 133 | BF4: =(IF('Water Report'!$F$27>0,'Water Report'!$F$27,0)) -> 127 | BG4: =(IF('Section Load'!AN7>0,'Section Load'!AN7,0)) -> 979.2 | BH4: =(IF('Section Load'!AO7>0,'Section Load'!AO7,0)) -> 281.28 | BI4: =(IF('Section Load'!AP7>0,'Section Load'!AP7,0)) -> 0 | BJ4: =(IF('Section Load'!AQ7>0,'Section Load'!AQ7,0)) -> 108 | BK4: =(IF('Section Load'!AR7>0,'Section Load'!AR7,0)) -> 48.2 | BL4: =(IF('Section Load'!AS7>0,'Section Load'!AS7,0)) -> 0 | BM4: =(IF('Section Load'!AT7>0,'Section Load'!AT7,0)) -> 542.52
A5: Mumbai | B5: =B4+1 -> 4 | C5: 8 | D5: 2022 | E5: =(IF('Section Load'!F8>0,'Section Load'!F8,0)) -> 4185.75 | F5: =(IF('Section Load'!G8>0,'Section Load'!G8,0)) -> 1113.08 | G5: =(IF('Section Load'!H8>0,'Section Load'!H8,0)) -> 2254.15 | H5: =(IF('Section Load'!I8>0,'Section Load'!I8,0)) -> 4351.13 | I5: =(IF('Section Load'!J8>0,'Section Load'!J8,0)) -> 6053.68 | J5: =(IF('Section Load'!K8>0,'Section Load'!K8,0)) -> 3159 | K5: =(IF('Section Load'!L8>0,'Section Load'!L8,0)) -> 1123.22 | L5: =(IF('Section Load'!M8>0,'Section Load'!M8,0)) -> 810.58 | ... AL5: =(IF('Section Load'!AM8>0,'Section Load'!AM8,0)) -> 0 | AM5: =(IF('Water Report'!$G$7>0,'Water Report'!$F$7,0)) -> 101 | AN5: =(IF('Water Report'!$G$8>0,'Water Report'!$F$8,0)) -> 116 | AO5: =(IF('Water Report'!$G$9>0,'Water Report'!$H$9,0)) -> 102 | AP5: =(IF('Water Report'!$G$10>0,'Water Report'!$G$10,0)) -> 22 | AQ5: =(IF('Water Report'!$G$11>0,'Water Report'!$G$11,0)) -> 0 | AR5: =(IF('Water Report'!$G$13>0,'Water Report'!$G$13,0)) -> 19 | AS5: =(IF('Water Report'!$G$14>0,'Water Report'!$G$14,0)) -> 2 | AT5: =(IF('Water Report'!$G$15>0,'Water Report'!$G$15,0)) -> 14 | AU5: =(IF('Water Report'!$G$17>0,'Water Report'!$G$17,0)) -> 5 | AV5: =(IF('Water Report'!$G$18>0,'Water Report'!$G$18,0)) -> 15 | AW5: =(IF('Water Report'!$G$19>0,'Water Report'!$G$19,0)) -> 12 | AX5: =(IF('Water Report'!$G$21>0,'Water Report'!$G$21,0)) -> 65 | AY5: =(IF('Water Report'!$G$22>0,'Water Report'!$G$22,0)) -> 0 | AZ5: =(IF('Water Report'!$G$23>0,'Water Report'!$G$23,0)) -> 0 | BA5: =(IF('Water Report'!$G$14>0,'Water Report'!$G$14,0)) -> 2 | BB5: =(IF('Water Report'!$G$15>0,'Water Report'!$G$15,0)) -> 14 | BC5: =(IF('Water Report'!$G$13>0,'Water Report'!$G$13,0)) -> 19 | BD5: =(IF('Water Report'!$G$24>0,'Water Report'!$G$24,0)) -> 183 | BE5: =(IF('Water Report'!$G$25>0,'Water Report'!$G$25,0)) -> 146 | BF5: =(IF('Water Report'!$G$27>0,'Water Report'!$G$27,0)) -> 84 | BG5: =(IF('Section Load'!AN8>0,'Section Load'!AN8,0)) -> 1002.3 | BH5: =(IF('Section Load'!AO8>0,'Section Load'!AO8,0)) -> 292.35 | BI5: =(IF('Section Load'!AP8>0,'Section Load'!AP8,0)) -> 0 | BJ5: =(IF('Section Load'!AQ8>0,'Section Load'!AQ8,0)) -> 106 | BK5: =(IF('Section Load'!AR8>0,'Section Load'!AR8,0)) -> 44 | BL5: =(IF('Section Load'!AS8>0,'Section Load'!AS8,0)) -> 0 | BM5: =(IF('Section Load'!AT8>0,'Section Load'!AT8,0)) -> 559.95
A6: Mumbai | B6: =B5+1 -> 5 | C6: 8 | D6: 2022 | E6: =(IF('Section Load'!F9>0,'Section Load'!F9,0)) -> 4350.01 | F6: =(IF('Section Load'!G9>0,'Section Load'!G9,0)) -> 1100.41 | G6: =(IF('Section Load'!H9>0,'Section Load'!H9,0)) -> 2239.38 | H6: =(IF('Section Load'!I9>0,'Section Load'!I9,0)) -> 4215.42 | I6: =(IF('Section Load'!J9>0,'Section Load'!J9,0)) -> 6662.02 | J6: =(IF('Section Load'!K9>0,'Section Load'!K9,0)) -> 3388.81 | K6: =(IF('Section Load'!L9>0,'Section Load'!L9,0)) -> 1030.01 | L6: =(IF('Section Load'!M9>0,'Section Load'!M9,0)) -> 1153.45 | ... AL6: =(IF('Section Load'!AM9>0,'Section Load'!AM9,0)) -> 0 | AM6: =(IF('Water Report'!$H$7>0,'Water Report'!$H$7,0)) -> 106 | AN6: =(IF('Water Report'!$H$8>0,'Water Report'!$H$8,0)) -> 137 | AO6: =(IF('Water Report'!$H$9>0,'Water Report'!$H$9,0)) -> 102 | AP6: =(IF('Water Report'!$H$10>0,'Water Report'!$H$10,0)) -> 25 | AQ6: =(IF('Water Report'!$H$11>0,'Water Report'!$H$11,0)) -> 0 | AR6: =(IF('Water Report'!$H$13>0,'Water Report'!$H$13,0)) -> 17 | AS6: =(IF('Water Report'!$H$14>0,'Water Report'!$H$14,0)) -> 12 | AT6: =(IF('Water Report'!$H$15>0,'Water Report'!$H$15,0)) -> 11 | AU6: =(IF('Water Report'!$H$17>0,'Water Report'!$H$17,0)) -> 0 | AV6: =(IF('Water Report'!$H$18>0,'Water Report'!$H$18,0)) -> 14 | AW6: =(IF('Water Report'!$H$19>0,'Water Report'!$H$19,0)) -> 11 | AX6: =(IF('Water Report'!$H$21>0,'Water Report'!$H$21,0)) -> 94 | AY6: =(IF('Water Report'!$H$22>0,'Water Report'!$H$22,0)) -> 0 | AZ6: =(IF('Water Report'!$H$23>0,'Water Report'!$H$23,0)) -> 0 | BA6: =(IF('Water Report'!$H$14>0,'Water Report'!$H$14,0)) -> 12 | BB6: =(IF('Water Report'!$H$15>0,'Water Report'!$H$15,0)) -> 11 | BC6: =(IF('Water Report'!$H$13>0,'Water Report'!$H$13,0)) -> 17 | BD6: =(IF('Water Report'!$H$24>0,'Water Report'!$H$24,0)) -> 192 | BE6: =(IF('Water Report'!$H$25>0,'Water Report'!$H$25,0)) -> 150 | BF6: =(IF('Water Report'!$H$27>0,'Water Report'!$H$27,0)) -> 111 | BG6: =(IF('Section Load'!AN9>0,'Section Load'!AN9,0)) -> 1047.2 | BH6: =(IF('Section Load'!AO9>0,'Section Load'!AO9,0)) -> 286.14 | BI6: =(IF('Section Load'!AP9>0,'Section Load'!AP9,0)) -> 0 | BJ6: =(IF('Section Load'!AQ9>0,'Section Load'!AQ9,0)) -> 116 | BK6: =(IF('Section Load'!AR9>0,'Section Load'!AR9,0)) -> 93 | BL6: =(IF('Section Load'!AS9>0,'Section Load'!AS9,0)) -> 0 | BM6: =(IF('Section Load'!AT9>0,'Section Load'!AT9,0)) -> 552.06
A7: Mumbai | B7: =B6+1 -> 6 | C7: 8 | D7: 2022 | E7: =(IF('Section Load'!F10>0,'Section Load'!F10,0)) -> 4273 | F7: =(IF('Section Load'!G10>0,'Section Load'!G10,0)) -> 1116 | G7: =(IF('Section Load'!H10>0,'Section Load'!H10,0)) -> 2225 | H7: =(IF('Section Load'!I10>0,'Section Load'!I10,0)) -> 4247 | I7: =(IF('Section Load'!J10>0,'Section Load'!J10,0)) -> 6391.17 | J7: =(IF('Section Load'!K10>0,'Section Load'!K10,0)) -> 3116 | K7: =(IF('Section Load'!L10>0,'Section Load'!L10,0)) -> 993 | L7: =(IF('Section Load'!M10>0,'Section Load'!M10,0)) -> 879 | ... AL7: =(IF('Section Load'!AM10>0,'Section Load'!AM10,0)) -> 0.41 | AM7: =(IF('Water Report'!$I$7>0,'Water Report'!$I$7,0)) -> 130 | AN7: =(IF('Water Report'!$I$8>0,'Water Report'!$I$8,0)) -> 98 | AO7: =(IF('Water Report'!$I$9>0,'Water Report'!$I$9,0)) -> 104 | AP7: =(IF('Water Report'!$I$10>0,'Water Report'!$I$10,0)) -> 23 | AQ7: =(IF('Water Report'!$I$11>0,'Water Report'!$I$11,0)) -> 0 | AR7: =(IF('Water Report'!$I$13>0,'Water Report'!$I$13,0)) -> 19 | AS7: =(IF('Water Report'!$I$14>0,'Water Report'!$I$14,0)) -> 6 | AT7: =(IF('Water Report'!$I$15>0,'Water Report'!$I$15,0)) -> 8 | AU7: =(IF('Water Report'!$I$17>0,'Water Report'!$I$17,0)) -> 2 | AV7: =(IF('Water Report'!$I$18>0,'Water Report'!$I$18,0)) -> 14 | AW7: =(IF('Water Report'!$I$19>0,'Water Report'!$I$19,0)) -> 14 | AX7: =(IF('Water Report'!$I$21>0,'Water Report'!$I$21,0)) -> 54 | AY7: =(IF('Water Report'!$I$22>0,'Water Report'!$I$22,0)) -> 0 | AZ7: =(IF('Water Report'!$I$23>0,'Water Report'!$I$23,0)) -> 2 | BA7: =(IF('Water Report'!$I$14>0,'Water Report'!$I$14,0)) -> 6 | BB7: =(IF('Water Report'!$I$15>0,'Water Report'!$I$15,0)) -> 8 | BC7: =(IF('Water Report'!$I$13>0,'Water Report'!$I$13,0)) -> 19 | BD7: =(IF('Water Report'!$I$24>0,'Water Report'!$I$24,0)) -> 247 | BE7: =(IF('Water Report'!$I$25>0,'Water Report'!$I$25,0)) -> 141 | BF7: =(IF('Water Report'!$I$27>0,'Water Report'!$I$27,0)) -> 75 | BG7: =(IF('Section Load'!AN10>0,'Section Load'!AN10,0)) -> 981 | BH7: =(IF('Section Load'!AO10>0,'Section Load'!AO10,0)) -> 312 | BI7: =(IF('Section Load'!AP10>0,'Section Load'!AP10,0)) -> 0 | BJ7: =(IF('Section Load'!AQ10>0,'Section Load'!AQ10,0)) -> 114 | BK7: =(IF('Section Load'!AR10>0,'Section Load'!AR10,0)) -> 3 | BL7: =(IF('Section Load'!AS10>0,'Section Load'!AS10,0)) -> 0.4 | BM7: =(IF('Section Load'!AT10>0,'Section Load'!AT10,0)) -> 551.6
A8: Mumbai | B8: =B7+1 -> 7 | C8: 8 | D8: 2022 | E8: =(IF('Section Load'!F11>0,'Section Load'!F11,0)) -> 4335 | F8: =(IF('Section Load'!G11>0,'Section Load'!G11,0)) -> 1065 | G8: =(IF('Section Load'!H11>0,'Section Load'!H11,0)) -> 2257 | H8: =(IF('Section Load'!I11>0,'Section Load'!I11,0)) -> 4343 | I8: =(IF('Section Load'!J11>0,'Section Load'!J11,0)) -> 6173 | J8: =(IF('Section Load'!K11>0,'Section Load'!K11,0)) -> 3091 | K8: =(IF('Section Load'!L11>0,'Section Load'!L11,0)) -> 1137 | L8: =(IF('Section Load'!M11>0,'Section Load'!M11,0)) -> 801 | ... AL8: =(IF('Section Load'!AM11>0,'Section Load'!AM11,0)) -> 0 | AM8: =(IF('Water Report'!$J$7>0,'Water Report'!$J$7,0)) -> 144 | AN8: =(IF('Water Report'!$J$8>0,'Water Report'!$J$8,0)) -> 106 | AO8: =(IF('Water Report'!$J$9>0,'Water Report'!$J$9,0)) -> 101 | AP8: =(IF('Water Report'!$J$10>0,'Water Report'!$J$10,0)) -> 31 | AQ8: =(IF('Water Report'!$J$11>0,'Water Report'!$J$11,0)) -> 0 | AR8: =(IF('Water Report'!$J$13>0,'Water Report'!$J$13,0)) -> 35 | AS8: =(IF('Water Report'!$J$14>0,'Water Report'!$J$14,0)) -> 6 | AT8: =(IF('Water Report'!$J$15>0,'Water Report'!$J$15,0)) -> 8 | AU8: =(IF('Water Report'!$J$17>0,'Water Report'!$J$17,0)) -> 0 | AV8: =(IF('Water Report'!$J$18>0,'Water Report'!$J$18,0)) -> 12 | AW8: =(IF('Water Report'!$J$19>0,'Water Report'!$J$19,0)) -> 12 | AX8: =(IF('Water Report'!$J$21>0,'Water Report'!$J$21,0)) -> 66 | AY8: =(IF('Water Report'!$J$22>0,'Water Report'!$J$22,0)) -> 0 | AZ8: =(IF('Water Report'!$J$23>0,'Water Report'!$J$23,0)) -> 5 | BA8: =(IF('Water Report'!$J$14>0,'Water Report'!$J$14,0)) -> 6 | BB8: =(IF('Water Report'!$J$15>0,'Water Report'!$J$15,0)) -> 8 | BC8: =(IF('Water Report'!$J$13>0,'Water Report'!$J$13,0)) -> 35 | BD8: =(IF('Water Report'!$J$24>0,'Water Report'!$J$24,0)) -> 287 | BE8: =(IF('Water Report'!$J$25>0,'Water Report'!$J$25,0)) -> 146 | BF8: =(IF('Water Report'!$J$27>0,'Water Report'!$J$27,0)) -> 106 | BG8: =(IF('Section Load'!AN11>0,'Section Load'!AN11,0)) -> 1066 | BH8: =(IF('Section Load'!AO11>0,'Section Load'!AO11,0)) -> 359 | BI8: =(IF('Section Load'!AP11>0,'Section Load'!AP11,0)) -> 0 | BJ8: =(IF('Section Load'!AQ11>0,'Section Load'!AQ11,0)) -> 111 | BK8: =(IF('Section Load'!AR11>0,'Section Load'!AR11,0)) -> 47 | BL8: =(IF('Section Load'!AS11>0,'Section Load'!AS11,0)) -> 0 | BM8: =(IF('Section Load'!AT11>0,'Section Load'!AT11,0)) -> 549
A9: Mumbai | B9: =B8+1 -> 8 | C9: 8 | D9: 2022 | E9: =(IF('Section Load'!F12>0,'Section Load'!F12,0)) -> 0 | F9: =(IF('Section Load'!G12>0,'Section Load'!G12,0)) -> 0 | G9: =(IF('Section Load'!H12>0,'Section Load'!H12,0)) -> 0 | H9: =(IF('Section Load'!I12>0,'Section Load'!I12,0)) -> 0 | I9: =(IF('Section Load'!J12>0,'Section Load'!J12,0)) -> 0 | J9: =(IF('Section Load'!K12>0,'Section Load'!K12,0)) -> 0 | K9: =(IF('Section Load'!L12>0,'Section Load'!L12,0)) -> 0 | L9: =(IF('Section Load'!M12>0,'Section Load'!M12,0)) -> 0 | ... AL9: =(IF('Section Load'!AM12>0,'Section Load'!AM12,0)) -> 567211 | AM9: =(IF('Water Report'!$K$7>0,'Water Report'!$K$7,0)) -> 0 | AN9: =(IF('Water Report'!$K$8>0,'Water Report'!$K$8,0)) -> 0 | AO9: =(IF('Water Report'!$K$9>0,'Water Report'!$K$9,0)) -> 0 | AP9: =(IF('Water Report'!$K$10>0,'Water Report'!$K$10,0)) -> 0 | AQ9: =(IF('Water Report'!$K$11>0,'Water Report'!$K$11,0)) -> 0 | AR9: =(IF('Water Report'!$K$13>0,'Water Report'!$K$13,0)) -> 0 | AS9: =(IF('Water Report'!$K$14>0,'Water Report'!$K$14,0)) -> 0 | AT9: =(IF('Water Report'!$K$15>0,'Water Report'!$K$15,0)) -> 0 | AU9: =(IF('Water Report'!$K$17>0,'Water Report'!$K$17,0)) -> 20 | AV9: =(IF('Water Report'!$K$18>0,'Water Report'!$K$18,0)) -> 0 | AW9: =(IF('Water Report'!$K$19>0,'Water Report'!$K$19,0)) -> 0 | AX9: =(IF('Water Report'!$K$21>0,'Water Report'!$K$21,0)) -> 0 | AY9: =(IF('Water Report'!$K$22>0,'Water Report'!$K$22,0)) -> 0 | AZ9: =(IF('Water Report'!$K$23>0,'Water Report'!$K$23,0)) -> 0 | BA9: =(IF('Water Report'!$K$14>0,'Water Report'!$K$14,0)) -> 0 | BB9: =(IF('Water Report'!$K$15>0,'Water Report'!$K$15,0)) -> 0 | BC9: =(IF('Water Report'!$K$13>0,'Water Report'!$K$13,0)) -> 0 | BD9: =(IF('Water Report'!$K$24>0,'Water Report'!$K$24,0)) -> 0 | BE9: =(IF('Water Report'!$K$25>0,'Water Report'!$K$25,0)) -> 0 | BF9: =(IF('Water Report'!$K$27>0,'Water Report'!$K$27,0)) -> 0 | BG9: =(IF('Section Load'!AN12>0,'Section Load'!AN12,0)) -> 1000 | BH9: =(IF('Section Load'!AO12>0,'Section Load'!AO12,0)) -> 0 | BI9: =(IF('Section Load'!AP12>0,'Section Load'!AP12,0)) -> 0.8 | BJ9: =(IF('Section Load'!AQ12>0,'Section Load'!AQ12,0)) -> 0 | BK9: =(IF('Section Load'!AR12>0,'Section Load'!AR12,0)) -> 0 | BL9: =(IF('Section Load'!AS12>0,'Section Load'!AS12,0)) -> 0 | BM9: =(IF('Section Load'!AT12>0,'Section Load'!AT12,0)) -> 15421.2
A10: Mumbai | B10: =B9+1 -> 9 | C10: 8 | D10: 2022 | E10: =(IF('Section Load'!F13>0,'Section Load'!F13,0)) -> 759.8 | F10: =(IF('Section Load'!G13>0,'Section Load'!G13,0)) -> 1573.75 | G10: =(IF('Section Load'!H13>0,'Section Load'!H13,0)) -> 2332.11 | H10: =(IF('Section Load'!I13>0,'Section Load'!I13,0)) -> 3026.15 | I10: =(IF('Section Load'!J13>0,'Section Load'!J13,0)) -> 8124.63 | J10: =(IF('Section Load'!K13>0,'Section Load'!K13,0)) -> 3152.45 | K10: =(IF('Section Load'!L13>0,'Section Load'!L13,0)) -> 1278.67 | L10: =(IF('Section Load'!M13>0,'Section Load'!M13,0)) -> 1130.17 | ... AL10: =(IF('Section Load'!AM13>0,'Section Load'!AM13,0)) -> 0 | AM10: =(IF('Water Report'!$L$7>0,'Water Report'!$L$7,0)) -> 121 | AN10: =(IF('Water Report'!$L$8>0,'Water Report'!$L$8,0)) -> 129 | AO10: =(IF('Water Report'!$L$9>0,'Water Report'!$L$9,0)) -> 101 | AP10: =(IF('Water Report'!$L$10>0,'Water Report'!$L$10,0)) -> 27 | AQ10: =(IF('Water Report'!$L$11>0,'Water Report'!$L$11,0)) -> 0 | AR10: =(IF('Water Report'!$L$13>0,'Water Report'!$L$13,0)) -> 40 | AS10: =(IF('Water Report'!$L$14>0,'Water Report'!$L$14,0)) -> 5 | AT10: =(IF('Water Report'!$L$15>0,'Water Report'!$L$15,0)) -> 6 | AU10: =(IF('Water Report'!$L$17>0,'Water Report'!$L$17,0)) -> 0 | AV10: =(IF('Water Report'!$L$18>0,'Water Report'!$L$18,0)) -> 14 | AW10: =(IF('Water Report'!$L$19>0,'Water Report'!$L$19,0)) -> 13 | AX10: =(IF('Water Report'!$L$21>0,'Water Report'!$L$21,0)) -> 110 | AY10: =(IF('Water Report'!$L$22>0,'Water Report'!$L$22,0)) -> 0 | AZ10: =(IF('Water Report'!$L$23>0,'Water Report'!$L$23,0)) -> 8 | BA10: =(IF('Water Report'!$L$14>0,'Water Report'!$L$14,0)) -> 5 | BB10: =(IF('Water Report'!$L$15>0,'Water Report'!$L$15,0)) -> 6 | BC10: =(IF('Water Report'!$L$13>0,'Water Report'!$L$13,0)) -> 40 | BD10: =(IF('Water Report'!$L$24>0,'Water Report'!$L$24,0)) -> 270 | BE10: =(IF('Water Report'!$L$25>0,'Water Report'!$L$25,0)) -> 139 | BF10: =(IF('Water Report'!$L$27>0,'Water Report'!$L$27,0)) -> 158 | BG10: =(IF('Section Load'!AN13>0,'Section Load'!AN13,0)) -> 1000 | BH10: =(IF('Section Load'!AO13>0,'Section Load'!AO13,0)) -> 328.45 | BI10: =(IF('Section Load'!AP13>0,'Section Load'!AP13,0)) -> 0 | BJ10: =(IF('Section Load'!AQ13>0,'Section Load'!AQ13,0)) -> 107.5 | BK10: =(IF('Section Load'!AR13>0,'Section Load'!AR13,0)) -> 122 | BL10: =(IF('Section Load'!AS13>0,'Section Load'!AS13,0)) -> 0 | BM10: =(IF('Section Load'!AT13>0,'Section Load'!AT13,0)) -> 442.45
A11: Mumbai | B11: =B10+1 -> 10 | C11: 8 | D11: 2022 | E11: =(IF('Section Load'!F14>0,'Section Load'!F14,0)) -> 3679.12 | F11: =(IF('Section Load'!G14>0,'Section Load'!G14,0)) -> 1524.5 | G11: =(IF('Section Load'!H14>0,'Section Load'!H14,0)) -> 2285.28 | H11: =(IF('Section Load'!I14>0,'Section Load'!I14,0)) -> 2907.96 | I11: =(IF('Section Load'!J14>0,'Section Load'!J14,0)) -> 5749.19 | J11: =(IF('Section Load'!K14>0,'Section Load'!K14,0)) -> 3210.36 | K11: =(IF('Section Load'!L14>0,'Section Load'!L14,0)) -> 1219.34 | L11: =(IF('Section Load'!M14>0,'Section Load'!M14,0)) -> 928.54 | ... AL11: =(IF('Section Load'!AM14>0,'Section Load'!AM14,0)) -> 782 | AM11: =(IF('Water Report'!$M$7>0,'Water Report'!$M$7,0)) -> 113 | AN11: =(IF('Water Report'!$M$8>0,'Water Report'!$M$8,0)) -> 105 | AO11: =(IF('Water Report'!$M$9>0,'Water Report'!$M$9,0)) -> 102 | AP11: =(IF('Water Report'!$M$10>0,'Water Report'!$M$10,0)) -> 25 | AQ11: =(IF('Water Report'!$M$11>0,'Water Report'!$M$11,0)) -> 0 | AR11: =(IF('Water Report'!$M$13>0,'Water Report'!$M$13,0)) -> 42 | AS11: =(IF('Water Report'!$M$14>0,'Water Report'!$M$14,0)) -> 6 | AT11: =(IF('Water Report'!$M$15>0,'Water Report'!$M$15,0)) -> 9 | AU11: =(IF('Water Report'!$M$17>0,'Water Report'!$M$17,0)) -> 0 | AV11: =(IF('Water Report'!$M$18>0,'Water Report'!$M$18,0)) -> 14 | AW11: =(IF('Water Report'!$M$19>0,'Water Report'!$M$19,0)) -> 12 | AX11: =(IF('Water Report'!$M$21>0,'Water Report'!$M$21,0)) -> 86 | AY11: =(IF('Water Report'!$M$22>0,'Water Report'!$M$22,0)) -> 0 | AZ11: =(IF('Water Report'!$M$23>0,'Water Report'!$M$23,0)) -> 11 | BA11: =(IF('Water Report'!$M$14>0,'Water Report'!$M$14,0)) -> 6 | BB11: =(IF('Water Report'!$M$15>0,'Water Report'!$M$15,0)) -> 9 | BC11: =(IF('Water Report'!$M$13>0,'Water Report'!$M$13,0)) -> 42 | BD11: =(IF('Water Report'!$M$24>0,'Water Report'!$M$24,0)) -> 270 | BE11: =(IF('Water Report'!$M$25>0,'Water Report'!$M$25,0)) -> 142 | BF11: =(IF('Water Report'!$M$27>0,'Water Report'!$M$27,0)) -> 139 | BG11: =(IF('Section Load'!AN14>0,'Section Load'!AN14,0)) -> 1000 | BH11: =(IF('Section Load'!AO14>0,'Section Load'!AO14,0)) -> 265.84 | BI11: =(IF('Section Load'!AP14>0,'Section Load'!AP14,0)) -> 0 | BJ11: =(IF('Section Load'!AQ14>0,'Section Load'!AQ14,0)) -> 98.5 | BK11: =(IF('Section Load'!AR14>0,'Section Load'!AR14,0)) -> 42 | BL11: =(IF('Section Load'!AS14>0,'Section Load'!AS14,0)) -> 0 | BM11: =(IF('Section Load'!AT14>0,'Section Load'!AT14,0)) -> 593.66
A12: Mumbai | B12: =B11+1 -> 11 | C12: 8 | D12: 2022 | E12: =(IF('Section Load'!F15>0,'Section Load'!F15,0)) -> 3790.72 | F12: =(IF('Section Load'!G15>0,'Section Load'!G15,0)) -> 1487.46 | G12: =(IF('Section Load'!H15>0,'Section Load'!H15,0)) -> 2304.16 | H12: =(IF('Section Load'!I15>0,'Section Load'!I15,0)) -> 2848.8 | I12: =(IF('Section Load'!J15>0,'Section Load'!J15,0)) -> 6949.27 | J12: =(IF('Section Load'!K15>0,'Section Load'!K15,0)) -> 2943.32 | K12: =(IF('Section Load'!L15>0,'Section Load'!L15,0)) -> 1058 | L12: =(IF('Section Load'!M15>0,'Section Load'!M15,0)) -> 696.84 | ... AL12: =(IF('Section Load'!AM15>0,'Section Load'!AM15,0)) -> 824 | AM12: =(IF('Water Report'!$N$7>0,'Water Report'!$N$7,0)) -> 122 | AN12: =(IF('Water Report'!$N$8>0,'Water Report'!$N$8,0)) -> 94 | AO12: =(IF('Water Report'!$N$9>0,'Water Report'!$N$9,0)) -> 102 | AP12: =(IF('Water Report'!$N$10>0,'Water Report'!$N$10,0)) -> 19 | AQ12: =(IF('Water Report'!$N$11>0,'Water Report'!$N$11,0)) -> 0 | AR12: =(IF('Water Report'!$N$13>0,'Water Report'!$N$13,0)) -> 25 | AS12: =(IF('Water Report'!$N$14>0,'Water Report'!$N$14,0)) -> 3 | AT12: =(IF('Water Report'!$N$15>0,'Water Report'!$N$15,0)) -> 14 | AU12: =(IF('Water Report'!$N$17>0,'Water Report'!$N$17,0)) -> 9 | AV12: =(IF('Water Report'!$N$18>0,'Water Report'!$N$18,0)) -> 16 | AW12: =(IF('Water Report'!$N$19>0,'Water Report'!$N$19,0)) -> 11 | AX12: =(IF('Water Report'!$N$21>0,'Water Report'!$N$21,0)) -> 108 | AY12: =(IF('Water Report'!$N$22>0,'Water Report'!$N$22,0)) -> 0 | AZ12: =(IF('Water Report'!$N$23>0,'Water Report'!$N$23,0)) -> 7 | BA12: =(IF('Water Report'!$N$14>0,'Water Report'!$N$14,0)) -> 3 | BB12: =(IF('Water Report'!$N$15>0,'Water Report'!$N$15,0)) -> 14 | BC12: =(IF('Water Report'!$N$13>0,'Water Report'!$N$13,0)) -> 25 | BD12: =(IF('Water Report'!$N$24>0,'Water Report'!$N$24,0)) -> 221 | BE12: =(IF('Water Report'!$N$25>0,'Water Report'!$N$25,0)) -> 138 | BF12: =(IF('Water Report'!$N$27>0,'Water Report'!$N$27,0)) -> 140 | BG12: =(IF('Section Load'!AN15>0,'Section Load'!AN15,0)) -> 1000 | BH12: =(IF('Section Load'!AO15>0,'Section Load'!AO15,0)) -> 270.44 | BI12: =(IF('Section Load'!AP15>0,'Section Load'!AP15,0)) -> 0 | BJ12: =(IF('Section Load'!AQ15>0,'Section Load'!AQ15,0)) -> 98 | BK12: =(IF('Section Load'!AR15>0,'Section Load'!AR15,0)) -> 35 | BL12: =(IF('Section Load'!AS15>0,'Section Load'!AS15,0)) -> 0 | BM12: =(IF('Section Load'!AT15>0,'Section Load'!AT15,0)) -> 596.56
A13: Mumbai | B13: =B12+1 -> 12 | C13: 8 | D13: 2022 | E13: =(IF('Section Load'!F16>0,'Section Load'!F16,0)) -> 3619.63 | F13: =(IF('Section Load'!G16>0,'Section Load'!G16,0)) -> 1552.32 | G13: =(IF('Section Load'!H16>0,'Section Load'!H16,0)) -> 2246.32 | H13: =(IF('Section Load'!I16>0,'Section Load'!I16,0)) -> 2839.8 | I13: =(IF('Section Load'!J16>0,'Section Load'!J16,0)) -> 6974.6 | J13: =(IF('Section Load'!K16>0,'Section Load'!K16,0)) -> 3131.1 | K13: =(IF('Section Load'!L16>0,'Section Load'!L16,0)) -> 1060.52 | L13: =(IF('Section Load'!M16>0,'Section Load'!M16,0)) -> 704.22 | ... AL13: =(IF('Section Load'!AM16>0,'Section Load'!AM16,0)) -> 785 | AM13: =(IF('Water Report'!$O$7>0,'Water Report'!$O$7,0)) -> 97 | AN13: =(IF('Water Report'!$O$8>0,'Water Report'!$O$8,0)) -> 87 | AO13: =(IF('Water Report'!$O$9>0,'Water Report'!$O$9,0)) -> 104 | AP13: =(IF('Water Report'!$O$10>0,'Water Report'!$O$10,0)) -> 24 | AQ13: =(IF('Water Report'!$O$11>0,'Water Report'!$O$11,0)) -> 0 | AR13: =(IF('Water Report'!$O$13>0,'Water Report'!$O$13,0)) -> 41 | AS13: =(IF('Water Report'!$O$14>0,'Water Report'!$O$14,0)) -> 4 | AT13: =(IF('Water Report'!$O$15>0,'Water Report'!$O$15,0)) -> 8 | AU13: =(IF('Water Report'!$O$17>0,'Water Report'!$O$17,0)) -> 0 | AV13: =(IF('Water Report'!$O$18>0,'Water Report'!$O$18,0)) -> 11 | AW13: =(IF('Water Report'!$O$19>0,'Water Report'!$O$19,0)) -> 12 | AX13: =(IF('Water Report'!$O$21>0,'Water Report'!$O$21,0)) -> 107 | AY13: =(IF('Water Report'!$O$22>0,'Water Report'!$O$22,0)) -> 0 | AZ13: =(IF('Water Report'!$O$23>0,'Water Report'!$O$23,0)) -> 5 | BA13: =(IF('Water Report'!$O$14>0,'Water Report'!$O$14,0)) -> 4 | BB13: =(IF('Water Report'!$O$15>0,'Water Report'!$O$15,0)) -> 8 | BC13: =(IF('Water Report'!$O$13>0,'Water Report'!$O$13,0)) -> 41 | BD13: =(IF('Water Report'!$O$24>0,'Water Report'!$O$24,0)) -> 254 | BE13: =(IF('Water Report'!$O$25>0,'Water Report'!$O$25,0)) -> 140 | BF13: =(IF('Water Report'!$O$27>0,'Water Report'!$O$27,0)) -> 153 | BG13: =(IF('Section Load'!AN16>0,'Section Load'!AN16,0)) -> 1000 | BH13: =(IF('Section Load'!AO16>0,'Section Load'!AO16,0)) -> 339.29 | BI13: =(IF('Section Load'!AP16>0,'Section Load'!AP16,0)) -> 0 | BJ13: =(IF('Section Load'!AQ16>0,'Section Load'!AQ16,0)) -> 88 | BK13: =(IF('Section Load'!AR16>0,'Section Load'!AR16,0)) -> 41 | BL13: =(IF('Section Load'!AS16>0,'Section Load'!AS16,0)) -> 0.4 | BM13: =(IF('Section Load'!AT16>0,'Section Load'!AT16,0)) -> 531.31
A14: Mumbai | B14: =B13+1 -> 13 | C14: 8 | D14: 2022 | E14: =(IF('Section Load'!F17>0,'Section Load'!F17,0)) -> 3392.04 | F14: =(IF('Section Load'!G17>0,'Section Load'!G17,0)) -> 1540.14 | G14: =(IF('Section Load'!H17>0,'Section Load'!H17,0)) -> 2289.24 | H14: =(IF('Section Load'!I17>0,'Section Load'!I17,0)) -> 2983.36 | I14: =(IF('Section Load'!J17>0,'Section Load'!J17,0)) -> 7606.62 | J14: =(IF('Section Load'!K17>0,'Section Load'!K17,0)) -> 2999.54 | K14: =(IF('Section Load'!L17>0,'Section Load'!L17,0)) -> 1455.08 | L14: =(IF('Section Load'!M17>0,'Section Load'!M17,0)) -> 743.06 | ... AL14: =(IF('Section Load'!AM17>0,'Section Load'!AM17,0)) -> 686.68 | AM14: =(IF('Water Report'!$P$7>0,'Water Report'!$P$7,0)) -> 97 | AN14: =(IF('Water Report'!$P$8>0,'Water Report'!$P$8,0)) -> 155 | AO14: =(IF('Water Report'!$P$9>0,'Water Report'!$P$9,0)) -> 99 | AP14: =(IF('Water Report'!$P$10>0,'Water Report'!$P$10,0)) -> 23 | AQ14: =(IF('Water Report'!$P$11>0,'Water Report'!$P$11,0)) -> 0 | AR14: =(IF('Water Report'!$P$13>0,'Water Report'!$P$13,0)) -> 24 | AS14: =(IF('Water Report'!$P$14>0,'Water Report'!$P$14,0)) -> 3 | AT14: =(IF('Water Report'!$P$15>0,'Water Report'!$P$15,0)) -> 9 | AU14: =(IF('Water Report'!$P$17>0,'Water Report'!$P$17,0)) -> 0 | AV14: =(IF('Water Report'!$P$18>0,'Water Report'!$P$18,0)) -> 10 | AW14: =(IF('Water Report'!$P$19>0,'Water Report'!$P$19,0)) -> 10 | AX14: =(IF('Water Report'!$P$21>0,'Water Report'!$P$21,0)) -> 109 | AY14: =(IF('Water Report'!$P$22>0,'Water Report'!$P$22,0)) -> 0 | AZ14: =(IF('Water Report'!$P$23>0,'Water Report'!$P$23,0)) -> 17 | BA14: =(IF('Water Report'!$P$14>0,'Water Report'!$P$14,0)) -> 3 | BB14: =(IF('Water Report'!$P$15>0,'Water Report'!$P$15,0)) -> 9 | BC14: =(IF('Water Report'!$P$13>0,'Water Report'!$P$13,0)) -> 24 | BD14: =(IF('Water Report'!$P$24>0,'Water Report'!$P$24,0)) -> 170 | BE14: =(IF('Water Report'!$P$25>0,'Water Report'!$P$25,0)) -> 134 | BF14: =(IF('Water Report'!$P$27>0,'Water Report'!$P$27,0)) -> 150 | BG14: =(IF('Section Load'!AN17>0,'Section Load'!AN17,0)) -> 1000 | BH14: =(IF('Section Load'!AO17>0,'Section Load'!AO17,0)) -> 375.91 | BI14: =(IF('Section Load'!AP17>0,'Section Load'!AP17,0)) -> 0 | BJ14: =(IF('Section Load'!AQ17>0,'Section Load'!AQ17,0)) -> 116.94 | BK14: =(IF('Section Load'!AR17>0,'Section Load'!AR17,0)) -> 57.5 | BL14: =(IF('Section Load'!AS17>0,'Section Load'!AS17,0)) -> 0 | BM14: =(IF('Section Load'!AT17>0,'Section Load'!AT17,0)) -> 450.05
A15: Mumbai | B15: =B14+1 -> 14 | C15: 8 | D15: 2022 | E15: =(IF('Section Load'!F18>0,'Section Load'!F18,0)) -> 3084.52 | F15: =(IF('Section Load'!G18>0,'Section Load'!G18,0)) -> 1526.88 | G15: =(IF('Section Load'!H18>0,'Section Load'!H18,0)) -> 2266.6 | H15: =(IF('Section Load'!I18>0,'Section Load'!I18,0)) -> 2924.2 | I15: =(IF('Section Load'!J18>0,'Section Load'!J18,0)) -> 7562.225 | J15: =(IF('Section Load'!K18>0,'Section Load'!K18,0)) -> 3165 | K15: =(IF('Section Load'!L18>0,'Section Load'!L18,0)) -> 1325.98 | L15: =(IF('Section Load'!M18>0,'Section Load'!M18,0)) -> 881.9 | ... AL15: =(IF('Section Load'!AM18>0,'Section Load'!AM18,0)) -> 607.56 | AM15: =(IF('Water Report'!$Q$7>0,'Water Report'!$Q$7,0)) -> 103 | AN15: =(IF('Water Report'!$Q$8>0,'Water Report'!$Q$8,0)) -> 133 | AO15: =(IF('Water Report'!$Q$9>0,'Water Report'!$Q$9,0)) -> 106 | AP15: =(IF('Water Report'!$Q$10>0,'Water Report'!$Q$10,0)) -> 27 | AQ15: =(IF('Water Report'!$Q$11>0,'Water Report'!$Q$11,0)) -> 0 | AR15: =(IF('Water Report'!$Q$13>0,'Water Report'!$Q$13,0)) -> 40 | AS15: =(IF('Water Report'!$Q$14>0,'Water Report'!$Q$14,0)) -> 5 | AT15: =(IF('Water Report'!$Q$15>0,'Water Report'!$Q$15,0)) -> 7 | AU15: =(IF('Water Report'!$Q$17>0,'Water Report'!$Q$17,0)) -> 0 | AV15: =(IF('Water Report'!$Q$18>0,'Water Report'!$Q$18,0)) -> 15 | AW15: =(IF('Water Report'!$Q$19>0,'Water Report'!$Q$19,0)) -> 11 | AX15: =(IF('Water Report'!$Q$21>0,'Water Report'!$Q$21,0)) -> 132 | AY15: =(IF('Water Report'!$Q$22>0,'Water Report'!$Q$22,0)) -> 0 | AZ15: =(IF('Water Report'!$Q$23>0,'Water Report'!$Q$23,0)) -> 28 | BA15: =(IF('Water Report'!$Q$14>0,'Water Report'!$Q$14,0)) -> 5 | BB15: =(IF('Water Report'!$Q$15>0,'Water Report'!$Q$15,0)) -> 7 | BC15: =(IF('Water Report'!$Q$13>0,'Water Report'!$Q$13,0)) -> 40 | BD15: =(IF('Water Report'!$Q$24>0,'Water Report'!$Q$24,0)) -> 192 | BE15: =(IF('Water Report'!$Q$25>0,'Water Report'!$Q$25,0)) -> 145 | BF15: =(IF('Water Report'!$Q$27>0,'Water Report'!$Q$27,0)) -> 200 | BG15: =(IF('Section Load'!AN18>0,'Section Load'!AN18,0)) -> 1000 | BH15: =(IF('Section Load'!AO18>0,'Section Load'!AO18,0)) -> 364.15 | BI15: =(IF('Section Load'!AP18>0,'Section Load'!AP18,0)) -> 0 | BJ15: =(IF('Section Load'!AQ18>0,'Section Load'!AQ18,0)) -> 116.06 | BK15: =(IF('Section Load'!AR18>0,'Section Load'!AR18,0)) -> 50.5 | BL15: =(IF('Section Load'!AS18>0,'Section Load'!AS18,0)) -> 0 | BM15: =(IF('Section Load'!AT18>0,'Section Load'!AT18,0)) -> 470.29
A16: Mumbai | B16: =B15+1 -> 15 | C16: 8 | D16: 2022 | E16: =(IF('Section Load'!F19>0,'Section Load'!F19,0)) -> 3477.09 | F16: =(IF('Section Load'!G19>0,'Section Load'!G19,0)) -> 1566.4 | G16: =(IF('Section Load'!H19>0,'Section Load'!H19,0)) -> 2416.64 | H16: =(IF('Section Load'!I19>0,'Section Load'!I19,0)) -> 2885.72 | I16: =(IF('Section Load'!J19>0,'Section Load'!J19,0)) -> 7325.475 | J16: =(IF('Section Load'!K19>0,'Section Load'!K19,0)) -> 3004.88 | K16: =(IF('Section Load'!L19>0,'Section Load'!L19,0)) -> 1019.7 | L16: =(IF('Section Load'!M19>0,'Section Load'!M19,0)) -> 1122.92 | ... AL16: =(IF('Section Load'!AM19>0,'Section Load'!AM19,0)) -> 337.78 | AM16: =(IF('Water Report'!$R$7>0,'Water Report'!$R$7,0)) -> 157 | AN16: =(IF('Water Report'!$R$8>0,'Water Report'!$R$8,0)) -> 145 | AO16: =(IF('Water Report'!$R$9>0,'Water Report'!$R$9,0)) -> 139 | AP16: =(IF('Water Report'!$R$10>0,'Water Report'!$R$10,0)) -> 34 | AQ16: =(IF('Water Report'!$R$11>0,'Water Report'!$R$11,0)) -> 0 | AR16: =(IF('Water Report'!$R$13>0,'Water Report'!$R$13,0)) -> 38 | AS16: =(IF('Water Report'!$R$14>0,'Water Report'!$R$14,0)) -> 5 | AT16: =(IF('Water Report'!$R$15>0,'Water Report'!$R$15,0)) -> 14 | AU16: =(IF('Water Report'!$R$17>0,'Water Report'!$R$17,0)) -> 0 | AV16: =(IF('Water Report'!$R$18>0,'Water Report'!$R$18,0)) -> 13 | AW16: =(IF('Water Report'!$R$19>0,'Water Report'!$R$19,0)) -> 12 | AX16: =(IF('Water Report'!$R$21>0,'Water Report'!$R$21,0)) -> 108 | AY16: =(IF('Water Report'!$R$22>0,'Water Report'!$R$22,0)) -> 0 | AZ16: =(IF('Water Report'!$R$23>0,'Water Report'!$R$23,0)) -> 5 | BA16: =(IF('Water Report'!$R$14>0,'Water Report'!$R$14,0)) -> 5 | BB16: =(IF('Water Report'!$R$15>0,'Water Report'!$R$15,0)) -> 14 | BC16: =(IF('Water Report'!$R$13>0,'Water Report'!$R$13,0)) -> 38 | BD16: =(IF('Water Report'!$R$24>0,'Water Report'!$R$24,0)) -> 243 | BE16: =(IF('Water Report'!$R$25>0,'Water Report'!$R$25,0)) -> 192 | BF16: =(IF('Water Report'!$R$27>0,'Water Report'!$R$27,0)) -> 151 | BG16: =(IF('Section Load'!AN19>0,'Section Load'!AN19,0)) -> 1000 | BH16: =(IF('Section Load'!AO19>0,'Section Load'!AO19,0)) -> 328.42 | BI16: =(IF('Section Load'!AP19>0,'Section Load'!AP19,0)) -> 0 | BJ16: =(IF('Section Load'!AQ19>0,'Section Load'!AQ19,0)) -> 114 | BK16: =(IF('Section Load'!AR19>0,'Section Load'!AR19,0)) -> 51 | BL16: =(IF('Section Load'!AS19>0,'Section Load'!AS19,0)) -> 1 | BM16: =(IF('Section Load'!AT19>0,'Section Load'!AT19,0)) -> 505.58
A17: Mumbai | B17: =B16+1 -> 16 | C17: 8 | D17: 2022 | E17: =(IF('Section Load'!F20>0,'Section Load'!F20,0)) -> 3597 | F17: =(IF('Section Load'!G20>0,'Section Load'!G20,0)) -> 1601.58 | G17: =(IF('Section Load'!H20>0,'Section Load'!H20,0)) -> 2437.48 | H17: =(IF('Section Load'!I20>0,'Section Load'!I20,0)) -> 2960.68 | I17: =(IF('Section Load'!J20>0,'Section Load'!J20,0)) -> 7993.48 | J17: =(IF('Section Load'!K20>0,'Section Load'!K20,0)) -> 3083.66 | K17: =(IF('Section Load'!L20>0,'Section Load'!L20,0)) -> 1357.71 | L17: =(IF('Section Load'!M20>0,'Section Load'!M20,0)) -> 901.56 | ... AL17: =(IF('Section Load'!AM20>0,'Section Load'!AM20,0)) -> 0 | AM17: =(IF('Water Report'!$S$7>0,'Water Report'!$S$7,0)) -> 137 | AN17: =(IF('Water Report'!$S$8>0,'Water Report'!$S$8,0)) -> 120 | AO17: =(IF('Water Report'!$S$9>0,'Water Report'!$S$9,0)) -> 109 | AP17: =(IF('Water Report'!$S$10>0,'Water Report'!$D$10,0)) -> 25 | AQ17: =(IF('Water Report'!$S$11>0,'Water Report'!$D$11,0)) -> 0 | AR17: =(IF('Water Report'!$S$13>0,'Water Report'!$D$13,0)) -> 18 | AS17: =(IF('Water Report'!$S$14>0,'Water Report'!$D$14,0)) -> 10 | AT17: =(IF('Water Report'!$S$15>0,'Water Report'!$D$15,0)) -> 6 | AU17: =(IF('Water Report'!$S$17>0,'Water Report'!$D$17,0)) -> 0 | AV17: =(IF('Water Report'!$S$18>0,'Water Report'!$D$18,0)) -> 13 | AW17: =(IF('Water Report'!$S$19>0,'Water Report'!$D$19,0)) -> 11 | AX17: =(IF('Water Report'!$S$21>0,'Water Report'!$D$21,0)) -> 109 | AY17: =(IF('Water Report'!$S$22>0,'Water Report'!$D$22,0)) -> 0 | AZ17: =(IF('Water Report'!$S$23>0,'Water Report'!$D$23,0)) -> 7 | BA17: =(IF('Water Report'!$S$14>0,'Water Report'!$D$14,0)) -> 10 | BB17: =(IF('Water Report'!$S$15>0,'Water Report'!$D$15,0)) -> 6 | BC17: =(IF('Water Report'!$S$13>0,'Water Report'!$D$13,0)) -> 18 | BD17: =(IF('Water Report'!$S$24>0,'Water Report'!$D$24,0)) -> 182 | BE17: =(IF('Water Report'!$S$25>0,'Water Report'!$D$25,0)) -> 133 | BF17: =(IF('Water Report'!$S$27>0,'Water Report'!$D$27,0)) -> 134 | BG17: =(IF('Section Load'!AN20>0,'Section Load'!AN20,0)) -> 1000 | BH17: =(IF('Section Load'!AO20>0,'Section Load'!AO20,0)) -> 309.15 | BI17: =(IF('Section Load'!AP20>0,'Section Load'!AP20,0)) -> 0 | BJ17: =(IF('Section Load'!AQ20>0,'Section Load'!AQ20,0)) -> 104 | BK17: =(IF('Section Load'!AR20>0,'Section Load'!AR20,0)) -> 57 | BL17: =(IF('Section Load'!AS20>0,'Section Load'!AS20,0)) -> 0 | BM17: =(IF('Section Load'!AT20>0,'Section Load'!AT20,0)) -> 529.85
A18: Mumbai | B18: =B17+1 -> 17 | C18: 8 | D18: 2022 | E18: =(IF('Section Load'!F21>0,'Section Load'!F21,0)) -> 3485.33 | F18: =(IF('Section Load'!G21>0,'Section Load'!G21,0)) -> 1544.6 | G18: =(IF('Section Load'!H21>0,'Section Load'!H21,0)) -> 2458.88 | H18: =(IF('Section Load'!I21>0,'Section Load'!I21,0)) -> 2887.64 | I18: =(IF('Section Load'!J21>0,'Section Load'!J21,0)) -> 7072.22 | J18: =(IF('Section Load'!K21>0,'Section Load'!K21,0)) -> 2989.2 | K18: =(IF('Section Load'!L21>0,'Section Load'!L21,0)) -> 1077.65 | L18: =(IF('Section Load'!M21>0,'Section Load'!M21,0)) -> 765.32 | ... AL18: =(IF('Section Load'!AM21>0,'Section Load'!AM21,0)) -> 0 | AM18: =(IF('Water Report'!$T$7>0,'Water Report'!$T$7,0)) -> 166 | AN18: =(IF('Water Report'!$T$8>0,'Water Report'!$T$8,0)) -> 137 | AO18: =(IF('Water Report'!$T$9>0,'Water Report'!$T$9,0)) -> 136 | AP18: =(IF('Water Report'!$T$10>0,'Water Report'!$T$10,0)) -> 28 | AQ18: =(IF('Water Report'!$T$11>0,'Water Report'!$T$11,0)) -> 1 | AR18: =(IF('Water Report'!$T$13>0,'Water Report'!$T$13,0)) -> 47 | AS18: =(IF('Water Report'!$T$14>0,'Water Report'!$T$14,0)) -> 5 | AT18: =(IF('Water Report'!$T$15>0,'Water Report'!$T$15,0)) -> 19 | AU18: =(IF('Water Report'!$T$17>0,'Water Report'!$T$17,0)) -> 0 | AV18: =(IF('Water Report'!$T$18>0,'Water Report'!$T$18,0)) -> 15 | AW18: =(IF('Water Report'!$T$19>0,'Water Report'!$T$19,0)) -> 12 | AX18: =(IF('Water Report'!$T$21>0,'Water Report'!$T$21,0)) -> 84 | AY18: =(IF('Water Report'!$T$22>0,'Water Report'!$T$22,0)) -> 0 | AZ18: =(IF('Water Report'!$T$23>0,'Water Report'!$T$23,0)) -> 15 | BA18: =(IF('Water Report'!$T$14>0,'Water Report'!$T$14,0)) -> 5 | BB18: =(IF('Water Report'!$T$15>0,'Water Report'!$T$15,0)) -> 19 | BC18: =(IF('Water Report'!$T$13>0,'Water Report'!$T$13,0)) -> 47 | BD18: =(IF('Water Report'!$T$24>0,'Water Report'!$T$24,0)) -> 320 | BE18: =(IF('Water Report'!$T$25>0,'Water Report'!$T$25,0)) -> 189 | BF18: =(IF('Water Report'!$T$27>0,'Water Report'!$T$27,0)) -> 146 | BG18: =(IF('Section Load'!AN21>0,'Section Load'!AN21,0)) -> 1000 | BH18: =(IF('Section Load'!AO21>0,'Section Load'!AO21,0)) -> 335.58 | BI18: =(IF('Section Load'!AP21>0,'Section Load'!AP21,0)) -> 0 | BJ18: =(IF('Section Load'!AQ21>0,'Section Load'!AQ21,0)) -> 114 | BK18: =(IF('Section Load'!AR21>0,'Section Load'!AR21,0)) -> 59.3 | BL18: =(IF('Section Load'!AS21>0,'Section Load'!AS21,0)) -> 0 | BM18: =(IF('Section Load'!AT21>0,'Section Load'!AT21,0)) -> 491.12
A19: Mumbai | B19: =B18+1 -> 18 | C19: 8 | D19: 2022 | E19: =(IF('Section Load'!F22>0,'Section Load'!F22,0)) -> 3521.96 | F19: =(IF('Section Load'!G22>0,'Section Load'!G22,0)) -> 1599.06 | G19: =(IF('Section Load'!H22>0,'Section Load'!H22,0)) -> 2493.71 | H19: =(IF('Section Load'!I22>0,'Section Load'!I22,0)) -> 2965.04 | I19: =(IF('Section Load'!J22>0,'Section Load'!J22,0)) -> 6799.23 | J19: =(IF('Section Load'!K22>0,'Section Load'!K22,0)) -> 2881.88 | K19: =(IF('Section Load'!L22>0,'Section Load'!L22,0)) -> 1162.14 | L19: =(IF('Section Load'!M22>0,'Section Load'!M22,0)) -> 1106.68 | ... AL19: =(IF('Section Load'!AM22>0,'Section Load'!AM22,0)) -> 0 | AM19: =(IF('Water Report'!$U$7>0,'Water Report'!$U$7,0)) -> 150 | AN19: =(IF('Water Report'!$U$8>0,'Water Report'!$U$8,0)) -> 134 | AO19: =(IF('Water Report'!$U$9>0,'Water Report'!$U$9,0)) -> 131 | AP19: =(IF('Water Report'!$U$10>0,'Water Report'!$U$10,0)) -> 24 | AQ19: =(IF('Water Report'!$U$11>0,'Water Report'!$U$11,0)) -> 0 | AR19: =(IF('Water Report'!$U$13>0,'Water Report'!$U$13,0)) -> 59 | AS19: =(IF('Water Report'!$U$14>0,'Water Report'!$U$14,0)) -> 6 | AT19: =(IF('Water Report'!$U$15>0,'Water Report'!$U$15,0)) -> 9 | AU19: =(IF('Water Report'!$U$17>0,'Water Report'!$U$17,0)) -> 0 | AV19: =(IF('Water Report'!$U$18>0,'Water Report'!$U$18,0)) -> 0 | AW19: =(IF('Water Report'!$U$19>0,'Water Report'!$U$19,0)) -> 12 | AX19: =(IF('Water Report'!$U$21>0,'Water Report'!$U$21,0)) -> 130 | AY19: =(IF('Water Report'!$U$22>0,'Water Report'!$U$22,0)) -> 0 | AZ19: =(IF('Water Report'!$U$23>0,'Water Report'!$U$23,0)) -> 8 | BA19: =(IF('Water Report'!$U$14>0,'Water Report'!$U$14,0)) -> 6 | BB19: =(IF('Water Report'!$U$15>0,'Water Report'!$U$15,0)) -> 9 | BC19: =(IF('Water Report'!$U$13>0,'Water Report'!$U$13,0)) -> 59 | BD19: =(IF('Water Report'!$U$24>0,'Water Report'!$U$24,0)) -> 274 | BE19: =(IF('Water Report'!$U$25>0,'Water Report'!$U$25,0)) -> 170 | BF19: =(IF('Water Report'!$U$27>0,'Water Report'!$U$27,0)) -> 197 | BG19: =(IF('Section Load'!AN22>0,'Section Load'!AN22,0)) -> 1000 | BH19: =(IF('Section Load'!AO22>0,'Section Load'!AO22,0)) -> 352.71 | BI19: =(IF('Section Load'!AP22>0,'Section Load'!AP22,0)) -> 0 | BJ19: =(IF('Section Load'!AQ22>0,'Section Load'!AQ22,0)) -> 85.41 | BK19: =(IF('Section Load'!AR22>0,'Section Load'!AR22,0)) -> 54.3 | BL19: =(IF('Section Load'!AS22>0,'Section Load'!AS22,0)) -> 0 | BM19: =(IF('Section Load'!AT22>0,'Section Load'!AT22,0)) -> 507.58
A20: Mumbai | B20: =B19+1 -> 19 | C20: 8 | D20: 2022 | E20: =(IF('Section Load'!F23>0,'Section Load'!F23,0)) -> 3706.03 | F20: =(IF('Section Load'!G23>0,'Section Load'!G23,0)) -> 1536.12 | G20: =(IF('Section Load'!H23>0,'Section Load'!H23,0)) -> 2304.21 | H20: =(IF('Section Load'!I23>0,'Section Load'!I23,0)) -> 2902.76 | I20: =(IF('Section Load'!J23>0,'Section Load'!J23,0)) -> 8734.11 | J20: =(IF('Section Load'!K23>0,'Section Load'!K23,0)) -> 3069.38 | K20: =(IF('Section Load'!L23>0,'Section Load'!L23,0)) -> 1786.38 | L20: =(IF('Section Load'!M23>0,'Section Load'!M23,0)) -> 1238.16 | ... AL20: =(IF('Section Load'!AM23>0,'Section Load'!AM23,0)) -> 0 | AM20: =(IF('Water Report'!$V$7>0,'Water Report'!$V$7,0)) -> 125 | AN20: =(IF('Water Report'!$V$8>0,'Water Report'!$V$8,0)) -> 111 | AO20: =(IF('Water Report'!$V$9>0,'Water Report'!$V$9,0)) -> 136 | AP20: =(IF('Water Report'!$V$10>0,'Water Report'!$V$10,0)) -> 19 | AQ20: =(IF('Water Report'!$V$11>0,'Water Report'!$V$11,0)) -> 0 | AR20: =(IF('Water Report'!$V$13>0,'Water Report'!$V$13,0)) -> 52 | AS20: =(IF('Water Report'!$V$14>0,'Water Report'!$V$14,0)) -> 4 | AT20: =(IF('Water Report'!$V$15>0,'Water Report'!$V$15,0)) -> 6 | AU20: =(IF('Water Report'!$V$17>0,'Water Report'!$V$17,0)) -> 0 | AV20: =(IF('Water Report'!$V$18>0,'Water Report'!$V$18,0)) -> 27 | AW20: =(IF('Water Report'!$V$19>0,'Water Report'!$V$19,0)) -> 12 | AX20: =(IF('Water Report'!$V$21>0,'Water Report'!$V$21,0)) -> 85 | AY20: =(IF('Water Report'!$V$22>0,'Water Report'!$V$22,0)) -> 0 | AZ20: =(IF('Water Report'!$V$23>0,'Water Report'!$V$23,0)) -> 10 | BA20: =(IF('Water Report'!$V$14>0,'Water Report'!$V$14,0)) -> 4 | BB20: =(IF('Water Report'!$V$15>0,'Water Report'!$V$15,0)) -> 6 | BC20: =(IF('Water Report'!$V$13>0,'Water Report'!$V$13,0)) -> 52 | BD20: =(IF('Water Report'!$V$24>0,'Water Report'!$V$24,0)) -> 226 | BE20: =(IF('Water Report'!$V$25>0,'Water Report'!$V$25,0)) -> 165 | BF20: =(IF('Water Report'!$V$27>0,'Water Report'!$V$27,0)) -> 147 | BG20: =(IF('Section Load'!AN23>0,'Section Load'!AN23,0)) -> 1000 | BH20: =(IF('Section Load'!AO23>0,'Section Load'!AO23,0)) -> 343.56 | BI20: =(IF('Section Load'!AP23>0,'Section Load'!AP23,0)) -> 0 | BJ20: =(IF('Section Load'!AQ23>0,'Section Load'!AQ23,0)) -> 96.99 | BK20: =(IF('Section Load'!AR23>0,'Section Load'!AR23,0)) -> 42.3 | BL20: =(IF('Section Load'!AS23>0,'Section Load'!AS23,0)) -> 0 | BM20: =(IF('Section Load'!AT23>0,'Section Load'!AT23,0)) -> 517.15
A21: Mumbai | B21: =B20+1 -> 20 | C21: 8 | D21: 2022 | E21: =(IF('Section Load'!F24>0,'Section Load'!F24,0)) -> 3725.81 | F21: =(IF('Section Load'!G24>0,'Section Load'!G24,0)) -> 1550.51 | G21: =(IF('Section Load'!H24>0,'Section Load'!H24,0)) -> 2246.61 | H21: =(IF('Section Load'!I24>0,'Section Load'!I24,0)) -> 2951.89 | I21: =(IF('Section Load'!J24>0,'Section Load'!J24,0)) -> 7199.17 | J21: =(IF('Section Load'!K24>0,'Section Load'!K24,0)) -> 2990.23 | K21: =(IF('Section Load'!L24>0,'Section Load'!L24,0)) -> 1834.83 | L21: =(IF('Section Load'!M24>0,'Section Load'!M24,0)) -> 1180.63 | ... AL21: =(IF('Section Load'!AM24>0,'Section Load'!AM24,0)) -> 0 | AM21: =(IF('Water Report'!$W$7>0,'Water Report'!$W$7,0)) -> 124 | AN21: =(IF('Water Report'!$W$8>0,'Water Report'!$W$8,0)) -> 128 | AO21: =(IF('Water Report'!$W$9>0,'Water Report'!$W$9,0)) -> 112 | AP21: =(IF('Water Report'!$W$10>0,'Water Report'!$W$10,0)) -> 22 | AQ21: =(IF('Water Report'!$W$11>0,'Water Report'!$W$11,0)) -> 0 | AR21: =(IF('Water Report'!$W$13>0,'Water Report'!$W$13,0)) -> 54 | AS21: =(IF('Water Report'!$W$14>0,'Water Report'!$W$14,0)) -> 3 | AT21: =(IF('Water Report'!$W$15>0,'Water Report'!$W$15,0)) -> 7 | AU21: =(IF('Water Report'!$W$17>0,'Water Report'!$W$17,0)) -> 0 | AV21: =(IF('Water Report'!$W$18>0,'Water Report'!$W$18,0)) -> 14 | AW21: =(IF('Water Report'!$W$19>0,'Water Report'!$W$19,0)) -> 12 | AX21: =(IF('Water Report'!$W$21>0,'Water Report'!$W$21,0)) -> 62 | AY21: =(IF('Water Report'!$W$22>0,'Water Report'!$W$22,0)) -> 0 | AZ21: =(IF('Water Report'!$W$23>0,'Water Report'!$W$23,0)) -> 0 | BA21: =(IF('Water Report'!$W$14>0,'Water Report'!$W$14,0)) -> 3 | BB21: =(IF('Water Report'!$W$15>0,'Water Report'!$W$15,0)) -> 7 | BC21: =(IF('Water Report'!$W$13>0,'Water Report'!$W$13,0)) -> 54 | BD21: =(IF('Water Report'!$W$24>0,'Water Report'!$W$24,0)) -> 273 | BE21: =(IF('Water Report'!$W$25>0,'Water Report'!$W$25,0)) -> 144 | BF21: =(IF('Water Report'!$W$27>0,'Water Report'!$W$27,0)) -> 116 | BG21: =(IF('Section Load'!AN24>0,'Section Load'!AN24,0)) -> 1000 | BH21: =(IF('Section Load'!AO24>0,'Section Load'!AO24,0)) -> 346.5 | BI21: =(IF('Section Load'!AP24>0,'Section Load'!AP24,0)) -> 0 | BJ21: =(IF('Section Load'!AQ24>0,'Section Load'!AQ24,0)) -> 114.6 | BK21: =(IF('Section Load'!AR24>0,'Section Load'!AR24,0)) -> 48.1 | BL21: =(IF('Section Load'!AS24>0,'Section Load'!AS24,0)) -> 0 | BM21: =(IF('Section Load'!AT24>0,'Section Load'!AT24,0)) -> 490.8
A22: Mumbai | B22: =B21+1 -> 21 | C22: 8 | D22: 2022 | E22: =(IF('Section Load'!F25>0,'Section Load'!F25,0)) -> 3627.95 | F22: =(IF('Section Load'!G25>0,'Section Load'!G25,0)) -> 1563 | G22: =(IF('Section Load'!H25>0,'Section Load'!H25,0)) -> 2209 | H22: =(IF('Section Load'!I25>0,'Section Load'!I25,0)) -> 2860 | I22: =(IF('Section Load'!J25>0,'Section Load'!J25,0)) -> 6568.78 | J22: =(IF('Section Load'!K25>0,'Section Load'!K25,0)) -> 3140 | K22: =(IF('Section Load'!L25>0,'Section Load'!L25,0)) -> 1434 | L22: =(IF('Section Load'!M25>0,'Section Load'!M25,0)) -> 726 | ... AL22: =(IF('Section Load'!AM25>0,'Section Load'!AM25,0)) -> 0.41 | AM22: =(IF('Water Report'!$X$7>0,'Water Report'!$X$7,0)) -> 105 | AN22: =(IF('Water Report'!$X$8>0,'Water Report'!$X$8,0)) -> 143 | AO22: =(IF('Water Report'!$X$9>0,'Water Report'!$X$9,0)) -> 99 | AP22: =(IF('Water Report'!$X$10>0,'Water Report'!$X$10,0)) -> 21 | AQ22: =(IF('Water Report'!$X$11>0,'Water Report'!$X$11,0)) -> 0 | AR22: =(IF('Water Report'!$X$13>0,'Water Report'!$X$13,0)) -> 56 | AS22: =(IF('Water Report'!$X$14>0,'Water Report'!$X$14,0)) -> 5 | AT22: =(IF('Water Report'!$X$15>0,'Water Report'!$X$15,0)) -> 21 | AU22: =(IF('Water Report'!$X$17>0,'Water Report'!$X$17,0)) -> 0 | AV22: =(IF('Water Report'!$X$18>0,'Water Report'!$X$18,0)) -> 14 | AW22: =(IF('Water Report'!$X$19>0,'Water Report'!$X$19,0)) -> 10 | AX22: =(IF('Water Report'!$X$21>0,'Water Report'!$X$21,0)) -> 61 | AY22: =(IF('Water Report'!$X$22>0,'Water Report'!$X$22,0)) -> 0 | AZ22: =(IF('Water Report'!$X$23>0,'Water Report'!$X$23,0)) -> 9 | BA22: =(IF('Water Report'!$X$14>0,'Water Report'!$X$14,0)) -> 5 | BB22: =(IF('Water Report'!$X$15>0,'Water Report'!$X$15,0)) -> 21 | BC22: =(IF('Water Report'!$X$13>0,'Water Report'!$X$13,0)) -> 56 | BD22: =(IF('Water Report'!$X$24>0,'Water Report'!$X$24,0)) -> 220 | BE22: =(IF('Water Report'!$X$25>0,'Water Report'!$X$25,0)) -> 146 | BF22: =(IF('Water Report'!$X$27>0,'Water Report'!$X$27,0)) -> 126 | BG22: =(IF('Section Load'!AN25>0,'Section Load'!AN25,0)) -> 1000 | BH22: =(IF('Section Load'!AO25>0,'Section Load'!AO25,0)) -> 337 | BI22: =(IF('Section Load'!AP25>0,'Section Load'!AP25,0)) -> 0 | BJ22: =(IF('Section Load'!AQ25>0,'Section Load'!AQ25,0)) -> 107 | BK22: =(IF('Section Load'!AR25>0,'Section Load'!AR25,0)) -> 49 | BL22: =(IF('Section Load'!AS25>0,'Section Load'!AS25,0)) -> 0 | BM22: =(IF('Section Load'!AT25>0,'Section Load'!AT25,0)) -> 507
