Workbook

Sheet Total
A1: Site Name | B1: Day | C1: Month | D1: Year | E1: Total Electricity Kwh | F1: Electricity Tariff ($/Kwh) | G1: Natual Gas (m3) | H1: Natural Gas $/m3 | I1: Water Utility Supply (m3) m3 | J1: Water Utility Supply (m3) $/m3 | K1: Room Nights
A2: Cairo at The First Residence | B2: 1 | C2: 2 | D2: 2021 | E2: 20187.71 | F2: 1.53 | G2: =1099.84+269.4 -> 1369.24 | H2: 3.89 | I2: 212.28 | J2: 10 | K2: 55
A3: Cairo at The First Residence | B3: =B2+1 -> 2 | C3: 2 | D3: 2021 | E3: 20187.71 | F3: =F2 -> 1.53 | G3: =1099.84+269.4 -> 1369.24 | H3: 3.89 | I3: 212.28 | J3: 10 | K3: 55
A4: Cairo at The First Residence | B4: =B3+1 -> 3 | C4: 2 | D4: 2021 | E4: 20187.71 | F4: =F3 -> 1.53 | G4: =1099.84+269.4 -> 1369.24 | H4: 3.89 | I4: 212.28 | J4: 10 | K4: 55
A5: Cairo at The First Residence | B5: =B4+1 -> 4 | C5: 2 | D5: 2021 | E5: 20187.71 | F5: =F4 -> 1.53 | G5: =1099.84+269.4 -> 1369.24 | H5: 3.89 | I5: 212.28 | J5: 10 | K5: 55
A6: Cairo at The First Residence | B6: =B5+1 -> 5 | C6: 2 | D6: 2021 | E6: 20187.71 | F6: =F5 -> 1.53 | G6: =1099.84+269.4 -> 1369.24 | H6: 3.89 | I6: 212.28 | J6: 10 | K6: 55
A7: Cairo at The First Residence | B7: =B6+1 -> 6 | C7: 2 | D7: 2021 | E7: 20187.71 | F7: =F6 -> 1.53 | G7: =1099.84+269.4 -> 1369.24 | H7: 3.89 | I7: 212.28 | J7: 10 | K7: 55
A8: Cairo at The First Residence | B8: =B7+1 -> 7 | C8: 2 | D8: 2021 | E8: 20187.71 | F8: =F7 -> 1.53 | G8: =1099.84+269.4 -> 1369.24 | H8: 3.89 | I8: 212.28 | J8: 10 | K8: 55
A9: Cairo at The First Residence | B9: =B8+1 -> 8 | C9: 2 | D9: 2021 | E9: 20187.71 | F9: =F8 -> 1.53 | G9: =1099.84+269.4 -> 1369.24 | H9: 3.89 | I9: 212.28 | J9: 10 | K9: 55
A10: Cairo at The First Residence | B10: =B9+1 -> 9 | C10: 2 | D10: 2021 | E10: 20187.71 | F10: =F9 -> 1.53 | G10: =1099.84+269.4 -> 1369.24 | H10: 3.89 | I10: 212.28 | J10: 10 | K10: 55
A11: Cairo at The First Residence | B11: =B10+1 -> 10 | C11: 2 | D11: 2021 | E11: 20187.71 | F11: =F10 -> 1.53 | G11: =1099.84+269.4 -> 1369.24 | H11: 3.89 | I11: 212.28 | J11: 10 | K11: 55
A12: Cairo at The First Residence | B12: =B11+1 -> 11 | C12: 2 | D12: 2021 | E12: 20187.71 | F12: =F11 -> 1.53 | G12: =1099.84+269.4 -> 1369.24 | H12: 3.89 | I12: 212.28 | J12: 10 | K12: 55
A13: Cairo at The First Residence | B13: =B12+1 -> 12 | C13: 2 | D13: 2021 | E13: 20187.71 | F13: =F12 -> 1.53 | G13: =1099.84+269.4 -> 1369.24 | H13: 3.89 | I13: 212.28 | J13: 10 | K13: 55
A14: Cairo at The First Residence | B14: =B13+1 -> 13 | C14: 2 | D14: 2021 | E14: 20187.71 | F14: =F13 -> 1.53 | G14: =1099.84+269.4 -> 1369.24 | H14: 3.89 | I14: 212.28 | J14: 10 | K14: 55
... A29: Cairo at The First Residence | B29: =B28+1 -> 28 | C29: 2 | D29: 2021 | E29: 20187.71 | F29: =F28 -> 1.53 | G29: =1099.84+269.4 -> 1369.24 | H29: 3.89 | I29: 212.28 | J29: 10 | K29: 56
A30: Cairo at The First Residence | B30: =B29+1 -> 29 | C30: 2 | D30: 2021 | E30: =Elect!BW34 -> 0 | F30: =F29 -> 1.53 | G30: =Gas!K35 -> 0 | H30: 3.89 | I30: =Water!H35 -> 0 | J30: 10 | K30: =Elect!BX34 -> 0
A31: Cairo at The First Residence | B31: =B30+1 -> 30 | C31: 2 | D31: 2021 | E31: =Elect!BW35 -> 0 | F31: =F30 -> 1.53 | G31: =Gas!K36 -> 0 | H31: 3.89 | I31: =Water!H36 -> 0 | J31: 10 | K31: =Elect!BX35 -> 0
A32: Cairo at The First Residence | B32: =B31+1 -> 31 | C32: 2 | D32: 2021 | E32: =Elect!BW36 -> 0 | F32: =F31 -> 1.53 | G32: =Gas!K37 -> 0 | H32: 3.89 | I32: =Water!H37 -> 0 | J32: 10 | K32: =Elect!BX36 -> 0

Sheet Submetering
A1: Site Name | B1: Day | C1: Month | D1: Year | E1: Electricity | F1: Main Feeder -KWh | G1: T2+T8 -KWh | H1: La Gourmandize -KWh | I1: Casino 3rd floor EM -KWh | J1: Casino 3rd floor Normal -KWh | K1: Chiller 1 -KWh | L1: Chiller 2 -KWh | M1: Chiller 3 -KWh | N1: Chiller 4 -KWh | O1: Chiller 5 -KWh | P1: Chiller 6 -KWh | Q1: Cooling towers -KWh | R1: Chiller Pumps -KWh | S1: Cooling Tower Pumps -KWh | T1: Fiber Chiller -KWh | U1: Mall Ceiling light -KWh | V1: LG Bakery -KWh | W1: LG Bakery light ( Old lockers ) -KWh | X1: MCCR1 -KWh | Y1: Children Swimming Pool -KWh | Z1: DPH1 -KWh | AA1: Guest Rooms Emerg. -KWh | AB1: Hotel Hoods -KWh | AC1: Main G2 -KWh | AD1: Old Casino Emergency -KWh | AE1: L / A -KWh | AF1: L / B -KWh | AG1: L / C -KWh | AH1: Water | AI1: Main water meter 1 -m3 | AJ1: Main water meter 2 -m3 | AK1: Main water meter 3 -m3 | AL1: Gas | AM1: Main Gas Flow Meter -m3 | AN1: Laundry Gas Flow Meter -m3 | AO1: Gourmandize Gas Flow Meter -m3 | AP1: Room Nights
A2: Cairo at The First Residence | B2: 1 | C2: 2 | D2: 2021 | F2: =Elect!J6 -> 2651 | G2: =Elect!K6 -> 2851 | H2: =Elect!Q6 -> 600 | I2: =Elect!W6 -> 154 | J2: =Elect!Y6 -> 240 | K2: =Elect!AA6 -> 0 | L2: =Elect!AC6 -> 1045.69 | M2: =Elect!AE6 -> 0 | N2: =Elect!AG6 -> 0 | O2: =Elect!AI6 -> 12.215238 | P2: =Elect!AK6 -> 12.164762 | Q2: =Elect!AM6 -> 108.65 | R2: =Elect!AO6 -> 1529.58 | S2: =Elect!AQ6 -> 172.81786 | T2: =Elect!AT6 -> 85.8375 | U2: =Elect!AV6 -> 220 | V2: =Elect!AX6 -> 127 | W2: =Elect!AZ6 -> 28 | X2: =Elect!BB6 -> 192 | Y2: =Elect!BD6 -> 68 | Z2: =Elect!BF6 -> 2693 | AA2: =Elect!BH6 -> 107.67857 | AB2: =Elect!BJ6 -> 0 | AC2: =Elect!BL6 -> 5078.2 | AD2: =Elect!BP6 -> 273 | AE2: =Elect!BR6 -> 946 | AF2: =Elect!BT6 -> 110 | AG2: =Elect!BV6 -> 197 | AI2: =Water!C7 -> 75.4 | AJ2: =Water!E7 -> 203 | AK2: =Water!G7 -> 0 | AM2: =Gas!C7 -> 608.44 | AN2: =Gas!E7 -> 331.8 | AO2: =Gas!G7 -> 30 | AP2: 55
A3: Cairo at The First Residence | B3: =B2+1 -> 2 | C3: 2 | D3: 2021 | F3: =Elect!J7 -> 4448 | G3: =Elect!K7 -> 2845 | H3: =Elect!Q7 -> 420 | I3: =Elect!W7 -> 148 | J3: =Elect!Y7 -> 258 | K3: =Elect!AA7 -> 297.33 | L3: =Elect!AC7 -> 1240.73 | M3: =Elect!AE7 -> 0 | N3: =Elect!AG7 -> 255.46 | O3: =Elect!AI7 -> 12.215238 | P3: =Elect!AK7 -> 12.164762 | Q3: =Elect!AM7 -> 238.5 | R3: =Elect!AO7 -> 404.39 | S3: =Elect!AQ7 -> 172.81786 | T3: =Elect!AT7 -> 80.2125 | U3: =Elect!AV7 -> 266 | V3: =Elect!AX7 -> 121 | W3: =Elect!AZ7 -> 38 | X3: =Elect!BB7 -> 200 | Y3: =Elect!BD7 -> 65 | Z3: =Elect!BF7 -> 3241 | AA3: =Elect!BH7 -> 107.67857 | AB3: =Elect!BJ7 -> 0 | AC3: =Elect!BL7 -> 4604.05 | AD3: =Elect!BP7 -> 273 | AE3: =Elect!BR7 -> 773 | AF3: =Elect!BT7 -> 118 | AG3: =Elect!BV7 -> 206 | AI3: =Water!C8 -> 98.6 | AJ3: =Water!E8 -> 110.2 | AK3: =Water!G8 -> 0 | AM3: =Gas!C8 -> 931.74 | AN3: =Gas!E8 -> 248.5 | AO3: =Gas!G8 -> 56 | AP3: 55
A4: Cairo at The First Residence | B4: =B3+1 -> 3 | C4: 2 | D4: 2021 | F4: =Elect!J8 -> 4078 | G4: =Elect!K8 -> 2734 | H4: =Elect!Q8 -> 390 | I4: =Elect!W8 -> 142 | J4: =Elect!Y8 -> 248 | K4: =Elect!AA8 -> 82.68 | L4: =Elect!AC8 -> 629.11 | M4: =Elect!AE8 -> 36.57 | N4: =Elect!AG8 -> 498.73 | O4: =Elect!AI8 -> 12.215238 | P4: =Elect!AK8 -> 12.164762 | Q4: =Elect!AM8 -> 242.21 | R4: =Elect!AO8 -> 3525.56 | S4: =Elect!AQ8 -> 172.81786 | T4: =Elect!AT8 -> 85.275 | U4: =Elect!AV8 -> 266 | V4: =Elect!AX8 -> 109 | W4: =Elect!AZ8 -> 39 | X4: =Elect!BB8 -> 398 | Y4: =Elect!BD8 -> 62 | Z4: =Elect!BF8 -> 3433 | AA4: =Elect!BH8 -> 107.67857 | AB4: =Elect!BJ8 -> 0 | AC4: =Elect!BL8 -> 4510.75 | AD4: =Elect!BP8 -> 273 | AE4: =Elect!BR8 -> 809 | AF4: =Elect!BT8 -> 116 | AG4: =Elect!BV8 -> 197 | AI4: =Water!C9 -> 110.2 | AJ4: =Water!E9 -> 75.4 | AK4: =Water!G9 -> 0 | AM4: =Gas!C9 -> 851.18 | AN4: =Gas!E9 -> 267.4 | AO4: =Gas!G9 -> 65 | AP4: 55
A5: Cairo at The First Residence | B5: =B4+1 -> 4 | C5: 2 | D5: 2021 | F5: =Elect!J9 -> 4608 | G5: =Elect!K9 -> 2854 | H5: =Elect!Q9 -> 540 | I5: =Elect!W9 -> 144 | J5: =Elect!Y9 -> 246 | K5: =Elect!AA9 -> 277.72 | L5: =Elect!AC9 -> 0 | M5: =Elect!AE9 -> 2401.43 | N5: =Elect!AG9 -> 0 | O5: =Elect!AI9 -> 12.215238 | P5: =Elect!AK9 -> 12.164762 | Q5: =Elect!AM9 -> 244.33 | R5: =Elect!AO9 -> 2289.6 | S5: =Elect!AQ9 -> 172.81786 | T5: =Elect!AT9 -> 87.8625 | U5: =Elect!AV9 -> 287 | V5: =Elect!AX9 -> 114 | W5: =Elect!AZ9 -> 41 | X5: =Elect!BB9 -> 383 | Y5: =Elect!BD9 -> 64 | Z5: =Elect!BF9 -> 3474 | AA5: =Elect!BH9 -> 107.67857 | AB5: =Elect!BJ9 -> 0 | AC5: =Elect!BL9 -> 4548 | AD5: =Elect!BP9 -> 273 | AE5: =Elect!BR9 -> 935 | AF5: =Elect!BT9 -> 125 | AG5: =Elect!BV9 -> 198 | AI5: =Water!C10 -> 174 | AJ5: =Water!E10 -> 179.8 | AK5: =Water!G10 -> 0 | AM5: =Gas!C10 -> 891.46 | AN5: =Gas!E10 -> 289.8 | AO5: =Gas!G10 -> 53 | AP5: 55
A6: Cairo at The First Residence | B6: =B5+1 -> 5 | C6: 2 | D6: 2021 | F6: =Elect!J10 -> 4629 | G6: =Elect!K10 -> 2786 | H6: =Elect!Q10 -> 510 | I6: =Elect!W10 -> 145 | J6: =Elect!Y10 -> 253 | K6: =Elect!AA10 -> 0 | L6: =Elect!AC10 -> 0 | M6: =Elect!AE10 -> 1743.17 | N6: =Elect!AG10 -> 0 | O6: =Elect!AI10 -> 12.215238 | P6: =Elect!AK10 -> 12.164762 | Q6: =Elect!AM10 -> 149.46 | R6: =Elect!AO10 -> 1706.6 | S6: =Elect!AQ10 -> 172.81786 | T6: =Elect!AT10 -> 68.7375 | U6: =Elect!AV10 -> 300 | V6: =Elect!AX10 -> 115 | W6: =Elect!AZ10 -> 35 | X6: =Elect!BB10 -> 359 | Y6: =Elect!BD10 -> 55 | Z6: =Elect!BF10 -> 3623 | AA6: =Elect!BH10 -> 107.67857 | AB6: =Elect!BJ10 -> 0 | AC6: =Elect!BL10 -> 5068 | AD6: =Elect!BP10 -> 273 | AE6: =Elect!BR10 -> 300 | AF6: =Elect!BT10 -> 80 | AG6: =Elect!BV10 -> 90 | AI6: =Water!C11 -> 174 | AJ6: =Water!E11 -> 150.8 | AK6: =Water!G11 -> 0 | AM6: =Gas!C11 -> 998.52 | AN6: =Gas!E11 -> 312.9 | AO6: =Gas!G11 -> 81 | AP6: 55
A7: Cairo at The First Residence | B7: =B6+1 -> 6 | C7: 2 | D7: 2021 | F7: =Elect!J11 -> 4466 | G7: =Elect!K11 -> 2826 | H7: =Elect!Q11 -> 600 | I7: =Elect!W11 -> 146 | J7: =Elect!Y11 -> 246 | K7: =Elect!AA11 -> 0 | L7: =Elect!AC11 -> 0 | M7: =Elect!AE11 -> 1742.11 | N7: =Elect!AG11 -> 0 | O7: =Elect!AI11 -> 12.215238 | P7: =Elect!AK11 -> 12.164762 | Q7: =Elect!AM11 -> 291.5 | R7: =Elect!AO11 -> 1824.79 | S7: =Elect!AQ11 -> 172.81786 | T7: =Elect!AT11 -> 86.9625 | U7: =Elect!AV11 -> 285 | V7: =Elect!AX11 -> 125 | W7: =Elect!AZ11 -> 29 | X7: =Elect!BB11 -> 378 | Y7: =Elect!BD11 -> 62 | Z7: =Elect!BF11 -> 3448 | AA7: =Elect!BH11 -> 107.67857 | AB7: =Elect!BJ11 -> 0 | AC7: =Elect!BL11 -> 4899.65 | AD7: =Elect!BP11 -> 273 | AE7: =Elect!BR11 -> 728 | AF7: =Elect!BT11 -> 35 | AG7: =Elect!BV11 -> 112 | AI7: =Water!C12 -> 116 | AJ7: =Water!E12 -> 58 | AK7: =Water!G12 -> 0 | AM7: =Gas!C12 -> 945.52 | AN7: =Gas!E12 -> 262.5 | AO7: =Gas!G12 -> 86 | AP7: 55
A8: Cairo at The First Residence | B8: =B7+1 -> 7 | C8: 2 | D8: 2021 | F8: =Elect!J12 -> 4626 | G8: =Elect!K12 -> 2998 | H8: =Elect!Q12 -> 600 | I8: =Elect!W12 -> 146 | J8: =Elect!Y12 -> 254 | K8: =Elect!AA12 -> 0 | L8: =Elect!AC12 -> 0 | M8: =Elect!AE12 -> 2625.62 | N8: =Elect!AG12 -> 0 | O8: =Elect!AI12 -> 12.215238 | P8: =Elect!AK12 -> 12.164762 | Q8: =Elect!AM12 -> 248.57 | R8: =Elect!AO12 -> 2170.88 | S8: =Elect!AQ12 -> 172.81786 | T8: =Elect!AT12 -> 80.2125 | U8: =Elect!AV12 -> 301 | V8: =Elect!AX12 -> 125 | W8: =Elect!AZ12 -> 44 | X8: =Elect!BB12 -> 396 | Y8: =Elect!BD12 -> 63 | Z8: =Elect!BF12 -> 3649 | AA8: =Elect!BH12 -> 107.67857 | AB8: =Elect!BJ12 -> 0 | AC8: =Elect!BL12 -> 4808.25 | AD8: =Elect!BP12 -> 273 | AE8: =Elect!BR12 -> 964 | AF8: =Elect!BT12 -> 111 | AG8: =Elect!BV12 -> 203 | AI8: =Water!C13 -> 111.02857 | AJ8: =Water!E13 -> 75.4 | AK8: =Water!G13 -> 0 | AM8: =Gas!C13 -> 786.52 | AN8: =Gas!E13 -> 254.1 | AO8: =Gas!G13 -> 79 | AP8: 55
A9: Cairo at The First Residence | B9: =B8+1 -> 8 | C9: 2 | D9: 2021 | F9: =Elect!J13 -> 4853 | G9: =Elect!K13 -> 3115 | H9: =Elect!Q13 -> 690 | I9: =Elect!W13 -> 147 | J9: =Elect!Y13 -> 251 | K9: =Elect!AA13 -> 1101.87 | L9: =Elect!AC13 -> 0 | M9: =Elect!AE13 -> 1019.19 | N9: =Elect!AG13 -> 0 | O9: =Elect!AI13 -> 12.215238 | P9: =Elect!AK13 -> 12.164762 | Q9: =Elect!AM13 -> 365.7 | R9: =Elect!AO13 -> 2178.83 | S9: =Elect!AQ13 -> 172.81786 | T9: =Elect!AT13 -> 72.45 | U9: =Elect!AV13 -> 257 | V9: =Elect!AX13 -> 126 | W9: =Elect!AZ13 -> 37 | X9: =Elect!BB13 -> 392 | Y9: =Elect!BD13 -> 62 | Z9: =Elect!BF13 -> 3504 | AA9: =Elect!BH13 -> 107.67857 | AB9: =Elect!BJ13 -> 0 | AC9: =Elect!BL13 -> 4719 | AD9: =Elect!BP13 -> 273 | AE9: =Elect!BR13 -> 1055 | AF9: =Elect!BT13 -> 125 | AG9: =Elect!BV13 -> 203 | AI9: =Water!C14 -> 120.97143 | AJ9: =Water!E14 -> 63.8 | AK9: =Water!G14 -> 0 | AM9: =Gas!C14 -> 906.3 | AN9: =Gas!E14 -> 251.3 | AO9: =Gas!G14 -> 88 | AP9: 55
A10: Cairo at The First Residence | B10: =B9+1 -> 9 | C10: 2 | D10: 2021 | F10: =Elect!J14 -> 4910 | G10: =Elect!K14 -> 3099 | H10: =Elect!Q14 -> 630 | I10: =Elect!W14 -> 143 | J10: =Elect!Y14 -> 244 | K10: =Elect!AA14 -> 2077.07 | L10: =Elect!AC14 -> 0 | M10: =Elect!AE14 -> 0 | N10: =Elect!AG14 -> 0 | O10: =Elect!AI14 -> 12.215238 | P10: =Elect!AK14 -> 12.164762 | Q10: =Elect!AM14 -> 488.66 | R10: =Elect!AO14 -> 2249.85 | S10: =Elect!AQ14 -> 172.81786 | T10: =Elect!AT14 -> 71.6625 | U10: =Elect!AV14 -> 284 | V10: =Elect!AX14 -> 126 | W10: =Elect!AZ14 -> 39 | X10: =Elect!BB14 -> 405 | Y10: =Elect!BD14 -> 64 | Z10: =Elect!BF14 -> 3376 | AA10: =Elect!BH14 -> 107.67857 | AB10: =Elect!BJ14 -> 0 | AC10: =Elect!BL14 -> 4720.55 | AD10: =Elect!BP14 -> 273 | AE10: =Elect!BR14 -> 1102 | AF10: =Elect!BT14 -> 119 | AG10: =Elect!BV14 -> 199 | AI10: =Water!C15 -> 139.2 | AJ10: =Water!E15 -> 52.2 | AK10: =Water!G15 -> 0 | AM10: =Gas!C15 -> 862.84 | AN10: =Gas!E15 -> 263.9 | AO10: =Gas!G15 -> 79 | AP10: 55
A11: Cairo at The First Residence | B11: =B10+1 -> 10 | C11: 2 | D11: 2021 | F11: =Elect!J15 -> 4535 | G11: =Elect!K15 -> 3305 | H11: =Elect!Q15 -> 570 | I11: =Elect!W15 -> 151 | J11: =Elect!Y15 -> 219 | K11: =Elect!AA15 -> 2177.24 | L11: =Elect!AC15 -> 0 | M11: =Elect!AE15 -> 0 | N11: =Elect!AG15 -> 0 | O11: =Elect!AI15 -> 12.215238 | P11: =Elect!AK15 -> 12.164762 | Q11: =Elect!AM15 -> 515.16 | R11: =Elect!AO15 -> 2374.4 | S11: =Elect!AQ15 -> 172.81786 | T11: =Elect!AT15 -> 76.05 | U11: =Elect!AV15 -> 272 | V11: =Elect!AX15 -> 130 | W11: =Elect!AZ15 -> 43 | X11: =Elect!BB15 -> 412 | Y11: =Elect!BD15 -> 68 | Z11: =Elect!BF15 -> 3545 | AA11: =Elect!BH15 -> 107.67857 | AB11: =Elect!BJ15 -> 0 | AC11: =Elect!BL15 -> 4813.25 | AD11: =Elect!BP15 -> 353 | AE11: =Elect!BR15 -> 1155 | AF11: =Elect!BT15 -> 120 | AG11: =Elect!BV15 -> 208 | AI11: =Water!C16 -> 127.6 | AJ11: =Water!E16 -> 69.6 | AK11: =Water!G16 -> 0 | AM11: =Gas!C16 -> 897.82 | AN11: =Gas!E16 -> 256.9 | AO11: =Gas!G16 -> 75 | AP11: 55
A12: Cairo at The First Residence | B12: =B11+1 -> 11 | C12: 2 | D12: 2021 | F12: =Elect!J16 -> 5806 | G12: =Elect!K16 -> 3134 | H12: =Elect!Q16 -> 690 | I12: =Elect!W16 -> 138 | J12: =Elect!Y16 -> 275 | K12: =Elect!AA16 -> 1860.83 | L12: =Elect!AC16 -> 0 | M12: =Elect!AE16 -> 0 | N12: =Elect!AG16 -> 0 | O12: =Elect!AI16 -> 12.215238 | P12: =Elect!AK16 -> 12.164762 | Q12: =Elect!AM16 -> 467.46 | R12: =Elect!AO16 -> 2121.06 | S12: =Elect!AQ16 -> 172.81786 | T12: =Elect!AT16 -> 82.2375 | U12: =Elect!AV16 -> 282 | V12: =Elect!AX16 -> 122 | W12: =Elect!AZ16 -> 36 | X12: =Elect!BB16 -> 340 | Y12: =Elect!BD16 -> 62 | Z12: =Elect!BF16 -> 3239 | AA12: =Elect!BH16 -> 107.67857 | AB12: =Elect!BJ16 -> 0 | AC12: =Elect!BL16 -> 4321.3 | AD12: =Elect!BP16 -> 222 | AE12: =Elect!BR16 -> 899 | AF12: =Elect!BT16 -> 107 | AG12: =Elect!BV16 -> 189 | AI12: =Water!C17 -> 127.6 | AJ12: =Water!E17 -> 52.2 | AK12: =Water!G17 -> 0 | AM12: =Gas!C17 -> 874.5 | AN12: =Gas!E17 -> 255.5 | AO12: =Gas!G17 -> 76 | AP12: 55
A13: Cairo at The First Residence | B13: =B12+1 -> 12 | C13: 2 | D13: 2021 | F13: =Elect!J17 -> 4685 | G13: =Elect!K17 -> 3241 | H13: =Elect!Q17 -> 570 | I13: =Elect!W17 -> 143 | J13: =Elect!Y17 -> 243 | K13: =Elect!AA17 -> 2070.18 | L13: =Elect!AC17 -> 0 | M13: =Elect!AE17 -> 0 | N13: =Elect!AG17 -> 0 | O13: =Elect!AI17 -> 12.215238 | P13: =Elect!AK17 -> 12.164762 | Q13: =Elect!AM17 -> 491.31 | R13: =Elect!AO17 -> 2177.24 | S13: =Elect!AQ17 -> 172.81786 | T13: =Elect!AT17 -> 63.675 | U13: =Elect!AV17 -> 289 | V13: =Elect!AX17 -> 127 | W13: =Elect!AZ17 -> 21 | X13: =Elect!BB17 -> 379 | Y13: =Elect!BD17 -> 65 | Z13: =Elect!BF17 -> 3327 | AA13: =Elect!BH17 -> 107.67857 | AB13: =Elect!BJ17 -> 0 | AC13: =Elect!BL17 -> 4467.8 | AD13: =Elect!BP17 -> 276 | AE13: =Elect!BR17 -> 936 | AF13: =Elect!BT17 -> 100 | AG13: =Elect!BV17 -> 200 | AI13: =Water!C18 -> 133.4 | AJ13: =Water!E18 -> 63.8 | AK13: =Water!G18 -> 0 | AM13: =Gas!C18 -> 896.76 | AN13: =Gas!E18 -> 261.1 | AO13: =Gas!G18 -> 72 | AP13: 55
A14: Cairo at The First Residence | B14: =B13+1 -> 13 | C14: 2 | D14: 2021 | F14: =Elect!J18 -> 5904 | G14: =Elect!K18 -> 3255 | H14: =Elect!Q18 -> 600 | I14: =Elect!W18 -> 148 | J14: =Elect!Y18 -> 249 | K14: =Elect!AA18 -> 2098.27 | L14: =Elect!AC18 -> 0 | M14: =Elect!AE18 -> 0 | N14: =Elect!AG18 -> 0 | O14: =Elect!AI18 -> 12.215238 | P14: =Elect!AK18 -> 12.164762 | Q14: =Elect!AM18 -> 506.68 | R14: =Elect!AO18 -> 2244.55 | S14: =Elect!AQ18 -> 172.81786 | T14: =Elect!AT18 -> 78.8625 | U14: =Elect!AV18 -> 250 | V14: =Elect!AX18 -> 104 | W14: =Elect!AZ18 -> 21 | X14: =Elect!BB18 -> 388 | Y14: =Elect!BD18 -> 66 | Z14: =Elect!BF18 -> 3465 | AA14: =Elect!BH18 -> 107.67857 | AB14: =Elect!BJ18 -> 0 | AC14: =Elect!BL18 -> 4660 | AD14: =Elect!BP18 -> 277 | AE14: =Elect!BR18 -> 938 | AF14: =Elect!BT18 -> 122 | AG14: =Elect!BV18 -> 204 | AI14: =Water!C19 -> 133.4 | AJ14: =Water!E19 -> 58 | AK14: =Water!G19 -> 0 | AM14: =Gas!C19 -> 870.26 | AN14: =Gas!E19 -> 256.9 | AO14: =Gas!G19 -> 78 | AP14: 55
... A29: Cairo at The First Residence | B29: =B28+1 -> 28 | C29: 2 | D29: 2021 | F29: =Elect!J33 -> 4950 | G29: =Elect!K33 -> 3334 | H29: =Elect!Q33 -> 540 | I29: =Elect!W33 -> 145 | J29: =Elect!Y33 -> 247 | K29: =Elect!AA33 -> 1445.84 | L29: =Elect!AC33 -> 203.52 | M29: =Elect!AE33 -> 0 | N29: =Elect!AG33 -> 0 | O29: =Elect!AI33 -> 12.19 | P29: =Elect!AK33 -> 12.19 | Q29: =Elect!AM33 -> 169.6 | R29: =Elect!AO33 -> 2031.49 | S29: =Elect!AQ33 -> 173.84 | T29: =Elect!AT33 -> 15.8625 | U29: =Elect!AV33 -> 305 | V29: =Elect!AX33 -> 104 | W29: =Elect!AZ33 -> 32 | X29: =Elect!BB33 -> 368 | Y29: =Elect!BD33 -> 63 | Z29: =Elect!BF33 -> 3342 | AA29: =Elect!BH33 -> 116 | AB29: =Elect!BJ33 -> 0 | AC29: =Elect!BL33 -> 4724.1 | AD29: =Elect!BP33 -> 399 | AE29: =Elect!BR33 -> 950 | AF29: =Elect!BT33 -> 112 | AG29: =Elect!BV33 -> 194 | AI29: =Water!C34 -> 116 | AJ29: =Water!E34 -> 5.8 | AK29: =Water!G34 -> 5.22 | AM29: =Gas!C34 -> 1092.86 | AN29: =Gas!E34 -> 264.6 | AO29: =Gas!G34 -> 69 | AP29: 56
A30: Cairo at The First Residence | B30: =B29+1 -> 29 | C30: 2 | D30: 2021 | F30: =Elect!J34 -> 0 | G30: =Elect!K34 -> 0 | H30: =Elect!Q34 -> 0 | I30: =Elect!W34 -> 0 | J30: =Elect!Y34 -> 0 | K30: =Elect!AA34 -> 0 | L30: =Elect!AC34 -> 0 | M30: =Elect!AE34 -> 0 | N30: =Elect!AG34 -> 0 | O30: =Elect!AI34 -> 0 | P30: =Elect!AK34 -> 0 | Q30: =Elect!AM34 -> 0 | R30: =Elect!AO34 -> 0 | S30: =Elect!AQ34 -> 0 | T30: =Elect!AT34 -> 0 | U30: =Elect!AV34 -> 0 | V30: =Elect!AX34 -> 0 | W30: =Elect!AZ34 -> 0 | X30: =Elect!BB34 -> 0 | Y30: =Elect!BD34 -> 0 | Z30: =Elect!BF34 -> 0 | AA30: =Elect!BH34 -> 0 | AB30: =Elect!BJ34 -> 0 | AC30: =Elect!BL34 -> 0 | AD30: =Elect!BP34 -> 0 | AE30: =Elect!BR34 -> 0 | AF30: =Elect!BT34 -> 0 | AG30: =Elect!BV34 -> 0 | AI30: =Water!C35 -> 0 | AJ30: =Water!E35 -> 0 | AK30: =Water!G35 -> 0 | AM30: =Gas!C35 -> 0 | AN30: =Gas!E35 -> 0 | AO30: =Gas!G35 -> 0 | AP30: =Elect!DC34 -> 0
A31: Cairo at The First Residence | B31: =B30+1 -> 30 | C31: 2 | D31: 2021 | F31: =Elect!J35 -> 0 | G31: =Elect!K35 -> 0 | H31: =Elect!Q35 -> 0 | I31: =Elect!W35 -> 0 | J31: =Elect!Y35 -> 0 | K31: =Elect!AA35 -> 0 | L31: =Elect!AC35 -> 0 | M31: =Elect!AE35 -> 0 | N31: =Elect!AG35 -> 0 | O31: =Elect!AI35 -> 0 | P31: =Elect!AK35 -> 0 | Q31: =Elect!AM35 -> 0 | R31: =Elect!AO35 -> 0 | S31: =Elect!AQ35 -> 0 | T31: =Elect!AT35 -> 0 | U31: =Elect!AV35 -> 0 | V31: =Elect!AX35 -> 0 | W31: =Elect!AZ35 -> 0 | X31: =Elect!BB35 -> 0 | Y31: =Elect!BD35 -> 0 | Z31: =Elect!BF35 -> 0 | AA31: =Elect!BH35 -> 0 | AB31: =Elect!BJ35 -> 0 | AC31: =Elect!BL35 -> 0 | AD31: =Elect!BP35 -> 0 | AE31: =Elect!BR35 -> 0 | AF31: =Elect!BT35 -> 0 | AG31: =Elect!BV35 -> 0 | AI31: =Water!C36 -> 0 | AJ31: =Water!E36 -> 0 | AK31: =Water!G36 -> 0 | AM31: =Gas!C36 -> 0 | AN31: =Gas!E36 -> 0 | AO31: =Gas!G36 -> 0 | AP31: =Elect!DC35 -> 0
A32: Cairo at The First Residence | B32: =B31+1 -> 31 | C32: 2 | D32: 2021 | F32: =Elect!J36 -> 0 | G32: =Elect!K36 -> 0 | H32: =Elect!Q36 -> 0 | I32: =Elect!W36 -> 0 | J32: =Elect!Y36 -> 0 | K32: =Elect!AA36 -> 0 | L32: =Elect!AC36 -> 0 | M32: =Elect!AE36 -> 0 | N32: =Elect!AG36 -> 0 | O32: =Elect!AI36 -> 0 | P32: =Elect!AK36 -> 0 | Q32: =Elect!AM36 -> 0 | R32: =Elect!AO36 -> 0 | S32: =Elect!AQ36 -> 0 | T32: =Elect!AT36 -> 0 | U32: =Elect!AV36 -> 0 | V32: =Elect!AX36 -> 0 | W32: =Elect!AZ36 -> 0 | X32: =Elect!BB36 -> 0 | Y32: =Elect!BD36 -> 0 | Z32: =Elect!BF36 -> 0 | AA32: =Elect!BH36 -> 0 | AB32: =Elect!BJ36 -> 0 | AC32: =Elect!BL36 -> 0 | AD32: =Elect!BP36 -> 0 | AE32: =Elect!BR36 -> 0 | AF32: =Elect!BT36 -> 0 | AG32: =Elect!BV36 -> 0 | AI32: =Water!C37 -> 0 | AJ32: =Water!E37 -> 0 | AK32: =Water!G37 -> 0 | AM32: =Gas!C37 -> 0 | AN32: =Gas!E37 -> 0 | AO32: =Gas!G37 -> 0 | AP32: =Elect!DC36 -> 0

Sheet Elect
A1: February | M1: Electricity | BW1: Power Taxes | BX1: 0.0006 | BY1: Max Demand | CA1: 500 | CB1: Electricity UP | CD1: 1.15
BW2: Light Taxes | BX2: 0.03 | BY2: PF Penalty | CB2: Max. Demand UP | CD2: 30
A3: Date | B3: COUNTER (1) | D3: MD | F3: KVAR | H3: n | I3: Guest Rooms Consumption | R3: Casino Consumption | Z3: Plant Room Shared Loads | AS3: To Be Charged By First Arabian | BO3: From Main Panel G2 | BW3: Total Consumption. | BX3: No. Of | BY3: KWH/ | BZ3: No. Of | CA3: KWH/ | CB3: Total Cost | CC3: L.E\ | CD3: L.E\
B4: Reading | C4: Consp. F: *800 | D4: Reading | E4: Consp F: 80 | F4: Reading | G4: Consp. F:*10 | I4: Main Feeder | J4: Consp | K4: T2+T8 | L4: Trans T2 | M4: Consp | N4: Trans T8 | O4: Consp | P4: La Gourmandize | Q4: Consp *30 | R4: Casino 1 | S4: Consp | T4: Casino 2 | U4: Consp | V4: Casino 3rd floor EM | W4: Consp | X4: Casino 3rd floor Normal | Y4: Consp | Z4: Chiller 1 | AA4: Consp 53% | AB4: Chiller 2 | AC4: Consp 53% | AD4: Chiller 3 | AE4: Consp 53% | AF4: Chiller 4 | AG4: Consp 53% | AH4: Chiller 5 | AI4: Consp 53% | AJ4: Chiller 6 | AK4: Consp 53% | AL4: Cooling Towers | AM4: Consp 53% | AN4: Chiller Pumps | AO4: Consp 53% | AP4: Cooling Tower Pumps | AQ4: Consp 53% | AR4: Total Plant Room Consp | AS4: Fiber Chiller (N24) | AT4: Consp | AU4: Mall Ceiling light (N4) | AV4: Consp | AW4: LG Bakery (N2) | AX4: Consp | AY4: LG Bakery light ( Old lockers ) | AZ4: Consp | BA4: MCCR1 | BB4: Consp | BC4: Children Swimming pool | BD4: Consp | BE4: DPH1 | BF4: Consp | BG4: Guest Rooms Emergency | BH4: Consp | BI4: Hotel Hoods | BJ4: Consp | BK4: Main G2 | BL4: Consp | BM4: Total Consp From First Arabian | BN4: First Arabian Charge Back | BO4: Old Casino Emergency | BP4: Consp | BQ4: L / A | BR4: Consp | BS4: L / B | BT4: Consp | BU4: L / C | BV4: Consp | BX4: Rooms | BY4: room | BZ4: guest | CA4: guest | CC4: Room | CD4: Guest
A5: Last Month Reading | I5: 22053832 | J5: =IF(I5>=I4,I5-I4,0) -> 0 | K5: =M5+O5 -> 0 | L5: 2554 | M5: =IF(L5>=L4,L5-L4,0) -> 0 | N5: 2947 | O5: =IF(N5>=N4,N5-N4,0) -> 0 | P5: 214736 | Q5: =IF(P5>=P4,P5-P4,0)*30 -> 0 | R5: 702925 | S5: =IF(R5>=R4,R5-R4,0) -> 0 | T5: 344001 | U5: =IF(T5>=T4,T5-T4,0) -> 0 | V5: 130984 | W5: =IF(V5>=V4,V5-V4,0) -> 0 | X5: 238297 | Y5: =IF(X5>=X4,X5-X4,0) -> 0 | Z5: 315335 | AA5: =IF(Z5>=Z4,Z5-Z4,0)*0.53 -> 0 | AB5: 382273 | AC5: =IF(AB5>=AB4,AB5-AB4,0)*0.53 -> 0 | AD5: 562354 | AE5: =IF(AD5>=AD4,AD5-AD4,0)*0.53 -> 0 | AF5: 307674 | AG5: =IF(AF5>=AF4,AF5-AF4,0)*0.53 -> 0 | AH5: 329500.27 | AI5: =IF(AH5>=AH4,AH5-AH4,0)*0.53 -> 0 | AJ5: 707620.73 | AK5: =IF(AJ5>=AJ4,AJ5-AJ4,0)*0.53 -> 0 | AL5: 533781 | AM5: =IF(AL5>=AL4,AL5-AL4,0)*0.53 -> 0 | AN5: 713719 | AO5: =IF(AN5>=AN4,AN5-AN4,0)*0.53 -> 0 | AP5: 380115.79 | AQ5: =IF(AP5>=AP4,AP5-AP4,0)*0.53 -> 0 | AR5: =AA5+AC5+AE5+AG5+AI5+AK5+AM5+AO5+AQ5 -> 0 | AS5: 7214129 | AT5: =IF(AS5>=AS4,AS5-AS4,0)*0.1125 -> 0 | AU5: 574281 | AV5: =IF(AU5>=AU4,AU5-AU4,0) -> 0 | AW5: 913468 | AX5: =IF(AW5>=AW4,AW5-AW4,0) -> 0 | AY5: 794724 | AZ5: =IF(AY5>=AY4,AY5-AY4,0) -> 0 | BA5: 2337484 | BB5: =IF(BA5>=BA4,BA5-BA4,0) -> 0 | BC5: 209470 | BD5: =IF(BC5>=BC4,BC5-BC4,0) -> 0 | BE5: 17670739 | BF5: =IF(BE5>=BE4,BE5-BE4,0) -> 0 | BG5: 498031.71 | BH5: =IF(BG5>=BG4,BG5-BG4,0) -> 0 | BI5: 8805 | BJ5: =IF(BI5>=BI4,BI5-BI4,0) -> 0 | BK5: 21892385 | BL5: =IF(BK5>=BK4,BK5-BK4,0)-(0.45*BR5)-(0.45*BT5)-BV5 -> 0 | BM5: =AT5+AV5+AX5+AZ5+BB5+BD5+BF5+BH5+BJ5+BL5 -> 0 | BN5: =BM5+AR5 -> 0 | BO5: 1369414 | BP5: =IF(BO5>=BO4,BO5-BO4,0) -> 0 | BQ5: 3491211 | BR5: =IF(BQ5>=BQ4,BQ5-BQ4,0) -> 0 | BS5: 372745 | BT5: =IF(BS5>=BS4,BS5-BS4,0) -> 0 | BU5: 452214 | BV5: =IF(BU5>=BU4,BU5-BU4,0) -> 0
A6: 1 | C6: =IF(+B6-B5>0,B6-B5,(B6-B5)>0)*800 -> 0 | E6: =IF(+D6-D5>0,D6-D5,(D6-D5)>0)*80 -> 0 | G6: =IF(+F6-F5>0,F6-F5,(F6-F5)>0)*10 -> 0 | H6: 56 | I6: 22056483 | J6: =IF(I6>=I5,I6-I5,0) -> 2651 | K6: =M6+O6 -> 2851 | L6: 3246 | M6: =IF(L6>=L5,L6-L5,0) -> 692 | N6: 5106 | O6: =IF(N6>=N5,N6-N5,0) -> 2159 | P6: 214756 | Q6: =IF(P6>=P5,P6-P5,0)*30 -> 600 | R6: 702925 | S6: =IF(R6>=R5,R6-R5,0) -> 0 | T6: 344001 | U6: =IF(T6>=T5,T6-T5,0) -> 0 | V6: 131138 | W6: =IF(V6>=V5,V6-V5,0) -> 154 | X6: 238537 | Y6: =IF(X6>=X5,X6-X5,0) -> 240 | Z6: 315335 | AA6: =IF(Z6>=Z5,Z6-Z5,0)*0.53 -> 0 | AB6: 384246 | AC6: =IF(AB6>=AB5,AB6-AB5,0)*0.53 -> 1045.69 | AD6: 562354 | AE6: =IF(AD6>=AD5,AD6-AD5,0)*0.53 -> 0 | AF6: 307674 | AG6: =IF(AF6>=AF5,AF6-AF5,0)*0.53 -> 0 | AH6: 329523.32 | AI6: =IF(AH6>=AH5,AH6-AH5,0)*0.53 -> 12.215238 | AJ6: 707643.68 | AK6: =IF(AJ6>=AJ5,AJ6-AJ5,0)*0.53 -> 12.164762 | AL6: 533986 | AM6: =IF(AL6>=AL5,AL6-AL5,0)*0.53 -> 108.65 | AN6: 716605 | AO6: =IF(AN6>=AN5,AN6-AN5,0)*0.53 -> 1529.58 | AP6: 380441.86 | AQ6: =IF(AP6>=AP5,AP6-AP5,0)*0.53 -> 172.81786 | AR6: =AA6+AC6+AE6+AG6+AI6+AK6+AM6+AO6+AQ6 -> 2881.1179 | AS6: 7214892 | AT6: =IF(AS6>=AS5,AS6-AS5,0)*0.1125 -> 85.8375 | AU6: 574501 | AV6: =IF(AU6>=AU5,AU6-AU5,0) -> 220 | AW6: 913595 | AX6: =IF(AW6>=AW5,AW6-AW5,0) -> 127 | AY6: 794752 | AZ6: =IF(AY6>=AY5,AY6-AY5,0) -> 28 | BA6: 2337676 | BB6: =IF(BA6>=BA5,BA6-BA5,0) -> 192 | BC6: 209538 | BD6: =IF(BC6>=BC5,BC6-BC5,0) -> 68 | BE6: 17673432 | BF6: =IF(BE6>=BE5,BE6-BE5,0) -> 2693 | BG6: 498139.39 | BH6: =IF(BG6>=BG5,BG6-BG5,0) -> 107.67857 | BI6: 8805 | BJ6: =IF(BI6>=BI5,BI6-BI5,0) -> 0 | BK6: 21898135 | BL6: =IF(BK6>=BK5,BK6-BK5,0)-(0.45*BR6)-(0.45*BT6)-BV6 -> 5078.2 | BM6: =AT6+AV6+AX6+AZ6+BB6+BD6+BF6+BH6+BJ6+BL6 -> 8599.7161 | BN6: =BM6+AR6 -> 11480.834 | BO6: 1369687 | BP6: =IF(BO6>=BO5,BO6-BO5,0) -> 273 | BQ6: 3492157 | BR6: =IF(BQ6>=BQ5,BQ6-BQ5,0) -> 946 | BS6: 372855 | BT6: =IF(BS6>=BS5,BS6-BS5,0) -> 110 | BU6: 452411 | BV6: =IF(BU6>=BU5,BU6-BU5,0) -> 197 | BW6: =J6+Q6+AR6+BM6 -> 14731.834 | BX6: 32 | BY6: =IF(BW6>0,BW6/BX5,0) -> #DIV/0! | CA6: =IF(BW6>0,BW6/BZ6,0) -> #DIV/0! | CB6: =BW6*CD1 -> 16941.609 | CC6: =IF(CB6>0,CB6/BX5,0) -> #DIV/0! | CD6: =IF(CB6>0,CB6/BZ6,0) -> #DIV/0!
A7: 2 | I7: 22060931 | J7: =IF(I7>=I6,I7-I6,0) -> 4448 | K7: =M7+O7 -> 2845 | L7: 4406 | M7: =IF(L7>=L6,L7-L6,0) -> 1160 | N7: 6791 | O7: =IF(N7>=N6,N7-N6,0) -> 1685 | P7: 214770 | Q7: =IF(P7>=P6,P7-P6,0)*30 -> 420 | R7: 702925 | S7: =IF(R7>=R6,R7-R6,0) -> 0 | T7: 344001 | U7: =IF(T7>=T6,T7-T6,0) -> 0 | V7: 131286 | W7: =IF(V7>=V6,V7-V6,0) -> 148 | X7: 238795 | Y7: =IF(X7>=X6,X7-X6,0) -> 258 | Z7: 315896 | AA7: =IF(Z7>=Z6,Z7-Z6,0)*0.53 -> 297.33 | AB7: 386587 | AC7: =IF(AB7>=AB6,AB7-AB6,0)*0.53 -> 1240.73 | AD7: 562354 | AE7: =IF(AD7>=AD6,AD7-AD6,0)*0.53 -> 0 | AF7: 308156 | AG7: =IF(AF7>=AF6,AF7-AF6,0)*0.53 -> 255.46 | AH7: 329546.37 | AI7: =IF(AH7>=AH6,AH7-AH6,0)*0.53 -> 12.215238 | AJ7: 707666.63 | AK7: =IF(AJ7>=AJ6,AJ7-AJ6,0)*0.53 -> 12.164762 | AL7: 534436 | AM7: =IF(AL7>=AL6,AL7-AL6,0)*0.53 -> 238.5 | AN7: 717368 | AO7: =IF(AN7>=AN6,AN7-AN6,0)*0.53 -> 404.39 | AP7: 380767.93 | AQ7: =IF(AP7>=AP6,AP7-AP6,0)*0.53 -> 172.81786 | AR7: =AA7+AC7+AE7+AG7+AI7+AK7+AM7+AO7+AQ7 -> 2633.6079 | AS7: 7215605 | AT7: =IF(AS7>=AS6,AS7-AS6,0)*0.1125 -> 80.2125 | AU7: 574767 | AV7: =IF(AU7>=AU6,AU7-AU6,0) -> 266 | AW7: 913716 | AX7: =IF(AW7>=AW6,AW7-AW6,0) -> 121 | AY7: 794790 | AZ7: =IF(AY7>=AY6,AY7-AY6,0) -> 38 | BA7: 2337876 | BB7: =IF(BA7>=BA6,BA7-BA6,0) -> 200 | BC7: 209603 | BD7: =IF(BC7>=BC6,BC7-BC6,0) -> 65 | BE7: 17676673 | BF7: =IF(BE7>=BE6,BE7-BE6,0) -> 3241 | BG7: 498247.07 | BH7: =IF(BG7>=BG6,BG7-BG6,0) -> 107.67857 | BI7: 8805 | BJ7: =IF(BI7>=BI6,BI7-BI6,0) -> 0 | BK7: 21903346 | BL7: =IF(BK7>=BK6,BK7-BK6,0)-(0.45*BR7)-(0.45*BT7)-BV7 -> 4604.05 | BM7: =AT7+AV7+AX7+AZ7+BB7+BD7+BF7+BH7+BJ7+BL7 -> 8722.9411 | BN7: =BM7+AR7 -> 11356.549 | BO7: 1369960 | BP7: =IF(BO7>=BO6,BO7-BO6,0) -> 273 | BQ7: 3492930 | BR7: =IF(BQ7>=BQ6,BQ7-BQ6,0) -> 773 | BS7: 372973 | BT7: =IF(BS7>=BS6,BS7-BS6,0) -> 118 | BU7: 452617 | BV7: =IF(BU7>=BU6,BU7-BU6,0) -> 206 | BW7: =J7+Q7+AR7+BM7 -> 16224.549 | BX7: 36 | BY7: =IF(BW7>0,BW7/BX6,0) -> 507.01715 | CA7: =IF(BW7>0,BW7/BZ7,0) -> #DIV/0! | CB7: =BW7*CD1 -> 18658.231 | CC7: =IF(CB7>0,CB7/BX6,0) -> 583.06973 | CD7: =IF(CB7>0,CB7/BZ7,0) -> #DIV/0!
A8: 3 | C8: =IF(+B8-B7>0,B8-B7,(B8-B7)>0)*800 -> 0 | E8: =IF(+D8-D7>0,D8-D7,(D8-D7)>0)*80 -> 0 | G8: =IF(+F8-F7>0,F8-F7,(F8-F7)>0)*10 -> 0 | H8: 57 | I8: 22065009 | J8: =IF(I8>=I7,I8-I7,0) -> 4078 | K8: =M8+O8 -> 2734 | L8: 5616 | M8: =IF(L8>=L7,L8-L7,0) -> 1210 | N8: 8315 | O8: =IF(N8>=N7,N8-N7,0) -> 1524 | P8: 214783 | Q8: =IF(P8>=P7,P8-P7,0)*30 -> 390 | R8: 702925 | S8: =IF(R8>=R7,R8-R7,0) -> 0 | T8: 344001 | U8: =IF(T8>=T7,T8-T7,0) -> 0 | V8: 131428 | W8: =IF(V8>=V7,V8-V7,0) -> 142 | X8: 239043 | Y8: =IF(X8>=X7,X8-X7,0) -> 248 | Z8: 316052 | AA8: =IF(Z8>=Z7,Z8-Z7,0)*0.53 -> 82.68 | AB8: 387774 | AC8: =IF(AB8>=AB7,AB8-AB7,0)*0.53 -> 629.11 | AD8: 562423 | AE8: =IF(AD8>=AD7,AD8-AD7,0)*0.53 -> 36.57 | AF8: 309097 | AG8: =IF(AF8>=AF7,AF8-AF7,0)*0.53 -> 498.73 | AH8: 329569.42 | AI8: =IF(AH8>=AH7,AH8-AH7,0)*0.53 -> 12.215238 | AJ8: 707689.58 | AK8: =IF(AJ8>=AJ7,AJ8-AJ7,0)*0.53 -> 12.164762 | AL8: 534893 | AM8: =IF(AL8>=AL7,AL8-AL7,0)*0.53 -> 242.21 | AN8: 724020 | AO8: =IF(AN8>=AN7,AN8-AN7,0)*0.53 -> 3525.56 | AP8: 381094 | AQ8: =IF(AP8>=AP7,AP8-AP7,0)*0.53 -> 172.81786 | AR8: =AA8+AC8+AE8+AG8+AI8+AK8+AM8+AO8+AQ8 -> 5212.0579 | AS8: 7216363 | AT8: =IF(AS8>=AS7,AS8-AS7,0)*0.1125 -> 85.275 | AU8: 575033 | AV8: =IF(AU8>=AU7,AU8-AU7,0) -> 266 | AW8: 913825 | AX8: =IF(AW8>=AW7,AW8-AW7,0) -> 109 | AY8: 794829 | AZ8: =IF(AY8>=AY7,AY8-AY7,0) -> 39 | BA8: 2338274 | BB8: =IF(BA8>=BA7,BA8-BA7,0) -> 398 | BC8: 209665 | BD8: =IF(BC8>=BC7,BC8-BC7,0) -> 62 | BE8: 17680106 | BF8: =IF(BE8>=BE7,BE8-BE7,0) -> 3433 | BG8: 498354.75 | BH8: =IF(BG8>=BG7,BG8-BG7,0) -> 107.67857 | BI8: 8805 | BJ8: =IF(BI8>=BI7,BI8-BI7,0) -> 0 | BK8: 21908470 | BL8: =IF(BK8>=BK7,BK8-BK7,0)-(0.45*BR8)-(0.45*BT8)-BV8 -> 4510.75 | BM8: =AT8+AV8+AX8+AZ8+BB8+BD8+BF8+BH8+BJ8+BL8 -> 9010.7036 | BN8: =BM8+AR8 -> 14222.761 | BO8: 1370233 | BP8: =IF(BO8>=BO7,BO8-BO7,0) -> 273 | BQ8: 3493739 | BR8: =IF(BQ8>=BQ7,BQ8-BQ7,0) -> 809 | BS8: 373089 | BT8: =IF(BS8>=BS7,BS8-BS7,0) -> 116 | BU8: 452814 | BV8: =IF(BU8>=BU7,BU8-BU7,0) -> 197 | BW8: =J8+Q8+AR8+BM8 -> 18690.761 | BX8: 43 | BY8: =IF(BW8>0,BW8/BX7,0) -> 519.18782 | CA8: =IF(BW8>0,BW8/BZ8,0) -> #DIV/0! | CB8: =BW8*CD1 -> 21494.376 | CC8: =IF(CB8>0,CB8/BX7,0) -> 597.06599 | CD8: =IF(CB8>0,CB8/BZ8,0) -> #DIV/0!
A9: 4 | C9: =IF(+B9-B8>0,B9-B8,(B9-B8)>0)*800 -> 0 | E9: =IF(+D9-D8>0,D9-D8,(D9-D8)>0)*80 -> 0 | G9: =IF(+F9-F8>0,F9-F8,(F9-F8)>0)*10 -> 0 | I9: 22069617 | J9: =IF(I9>=I8,I9-I8,0) -> 4608 | K9: =M9+O9 -> 2854 | L9: 6960 | M9: =IF(L9>=L8,L9-L8,0) -> 1344 | N9: 9825 | O9: =IF(N9>=N8,N9-N8,0) -> 1510 | P9: 214801 | Q9: =IF(P9>=P8,P9-P8,0)*30 -> 540 | R9: 702925 | S9: =IF(R9>=R8,R9-R8,0) -> 0 | T9: 344001 | U9: =IF(T9>=T8,T9-T8,0) -> 0 | V9: 131572 | W9: =IF(V9>=V8,V9-V8,0) -> 144 | X9: 239289 | Y9: =IF(X9>=X8,X9-X8,0) -> 246 | Z9: 316576 | AA9: =IF(Z9>=Z8,Z9-Z8,0)*0.53 -> 277.72 | AB9: 387774 | AC9: =IF(AB9>=AB8,AB9-AB8,0)*0.53 -> 0 | AD9: 566954 | AE9: =IF(AD9>=AD8,AD9-AD8,0)*0.53 -> 2401.43 | AF9: 309097 | AG9: =IF(AF9>=AF8,AF9-AF8,0)*0.53 -> 0 | AH9: 329592.46 | AI9: =IF(AH9>=AH8,AH9-AH8,0)*0.53 -> 12.215238 | AJ9: 707712.54 | AK9: =IF(AJ9>=AJ8,AJ9-AJ8,0)*0.53 -> 12.164762 | AL9: 535354 | AM9: =IF(AL9>=AL8,AL9-AL8,0)*0.53 -> 244.33 | AN9: 728340 | AO9: =IF(AN9>=AN8,AN9-AN8,0)*0.53 -> 2289.6 | AP9: 381420.07 | AQ9: =IF(AP9>=AP8,AP9-AP8,0)*0.53 -> 172.81786 | AR9: =AA9+AC9+AE9+AG9+AI9+AK9+AM9+AO9+AQ9 -> 5410.2779 | AS9: 7217144 | AT9: =IF(AS9>=AS8,AS9-AS8,0)*0.1125 -> 87.8625 | AU9: 575320 | AV9: =IF(AU9>=AU8,AU9-AU8,0) -> 287 | AW9: 913939 | AX9: =IF(AW9>=AW8,AW9-AW8,0) -> 114 | AY9: 794870 | AZ9: =IF(AY9>=AY8,AY9-AY8,0) -> 41 | BA9: 2338657 | BB9: =IF(BA9>=BA8,BA9-BA8,0) -> 383 | BC9: 209729 | BD9: =IF(BC9>=BC8,BC9-BC8,0) -> 64 | BE9: 17683580 | BF9: =IF(BE9>=BE8,BE9-BE8,0) -> 3474 | BG9: 498462.43 | BH9: =IF(BG9>=BG8,BG9-BG8,0) -> 107.67857 | BI9: 8805 | BJ9: =IF(BI9>=BI8,BI9-BI8,0) -> 0 | BK9: 21913693 | BL9: =IF(BK9>=BK8,BK9-BK8,0)-(0.45*BR9)-(0.45*BT9)-BV9 -> 4548 | BM9: =AT9+AV9+AX9+AZ9+BB9+BD9+BF9+BH9+BJ9+BL9 -> 9106.5411 | BN9: =BM9+AR9 -> 14516.819 | BO9: 1370506 | BP9: =IF(BO9>=BO8,BO9-BO8,0) -> 273 | BQ9: 3494674 | BR9: =IF(BQ9>=BQ8,BQ9-BQ8,0) -> 935 | BS9: 373214 | BT9: =IF(BS9>=BS8,BS9-BS8,0) -> 125 | BU9: 453012 | BV9: =IF(BU9>=BU8,BU9-BU8,0) -> 198 | BW9: =J9+Q9+AR9+BM9 -> 19664.819 | BX9: 66 | BY9: =IF(BW9>0,BW9/BX8,0) -> 457.32137 | CA9: =IF(BW9>0,BW9/BZ9,0) -> #DIV/0! | CB9: =BW9*CD1 -> 22614.542 | CC9: =IF(CB9>0,CB9/BX8,0) -> 525.91958 | CD9: =IF(CB9>0,CB9/BZ9,0) -> #DIV/0!
A10: 5 | C10: =IF(+B10-B9>0,B10-B9,(B10-B9)>0)*800 -> 0 | E10: =IF(+D10-D9>0,D10-D9,(D10-D9)>0)*80 -> 0 | G10: =IF(+F10-F9>0,F10-F9,(F10-F9)>0)*10 -> 0 | H10: 58 | I10: 22074246 | J10: =IF(I10>=I9,I10-I9,0) -> 4629 | K10: =M10+O10 -> 2786 | L10: 8261 | M10: =IF(L10>=L9,L10-L9,0) -> 1301 | N10: 11310 | O10: =IF(N10>=N9,N10-N9,0) -> 1485 | P10: 214818 | Q10: =IF(P10>=P9,P10-P9,0)*30 -> 510 | R10: 702925 | S10: =IF(R10>=R9,R10-R9,0) -> 0 | T10: 344001 | U10: =IF(T10>=T9,T10-T9,0) -> 0 | V10: 131717 | W10: =IF(V10>=V9,V10-V9,0) -> 145 | X10: 239542 | Y10: =IF(X10>=X9,X10-X9,0) -> 253 | Z10: 316576 | AA10: =IF(Z10>=Z9,Z10-Z9,0)*0.53 -> 0 | AB10: 387774 | AC10: =IF(AB10>=AB9,AB10-AB9,0)*0.53 -> 0 | AD10: 570243 | AE10: =IF(AD10>=AD9,AD10-AD9,0)*0.53 -> 1743.17 | AF10: 309097 | AG10: =IF(AF10>=AF9,AF10-AF9,0)*0.53 -> 0 | AH10: 329615.51 | AI10: =IF(AH10>=AH9,AH10-AH9,0)*0.53 -> 12.215238 | AJ10: 707735.49 | AK10: =IF(AJ10>=AJ9,AJ10-AJ9,0)*0.53 -> 12.164762 | AL10: 535636 | AM10: =IF(AL10>=AL9,AL10-AL9,0)*0.53 -> 149.46 | AN10: 731560 | AO10: =IF(AN10>=AN9,AN10-AN9,0)*0.53 -> 1706.6 | AP10: 381746.14 | AQ10: =IF(AP10>=AP9,AP10-AP9,0)*0.53 -> 172.81786 | AR10: =AA10+AC10+AE10+AG10+AI10+AK10+AM10+AO10+AQ10 -> 3796.4279 | AS10: 7217755 | AT10: =IF(AS10>=AS9,AS10-AS9,0)*0.1125 -> 68.7375 | AU10: 575620 | AV10: =IF(AU10>=AU9,AU10-AU9,0) -> 300 | AW10: 914054 | AX10: =IF(AW10>=AW9,AW10-AW9,0) -> 115 | AY10: 794905 | AZ10: =IF(AY10>=AY9,AY10-AY9,0) -> 35 | BA10: 2339016 | BB10: =IF(BA10>=BA9,BA10-BA9,0) -> 359 | BC10: 209784 | BD10: =IF(BC10>=BC9,BC10-BC9,0) -> 55 | BE10: 17687203 | BF10: =IF(BE10>=BE9,BE10-BE9,0) -> 3623 | BG10: 498570.11 | BH10: =IF(BG10>=BG9,BG10-BG9,0) -> 107.67857 | BI10: 8805 | BJ10: =IF(BI10>=BI9,BI10-BI9,0) -> 0 | BK10: 21919022 | BL10: =IF(BK10>=BK9,BK10-BK9,0)-(0.45*BR10)-(0.45*BT10)-BV10 -> 5068 | BM10: =AT10+AV10+AX10+AZ10+BB10+BD10+BF10+BH10+BJ10+BL10 -> 9731.4161 | BN10: =BM10+AR10 -> 13527.844 | BO10: 1370779 | BP10: =IF(BO10>=BO9,BO10-BO9,0) -> 273 | BQ10: 3494974 | BR10: =IF(BQ10>=BQ9,BQ10-BQ9,0) -> 300 | BS10: 373294 | BT10: =IF(BS10>=BS9,BS10-BS9,0) -> 80 | BU10: 453102 | BV10: =IF(BU10>=BU9,BU10-BU9,0) -> 90 | BW10: =J10+Q10+AR10+BM10 -> 18666.844 | BX10: 68 | BY10: =IF(BW10>0,BW10/BX9,0) -> 282.83097 | CA10: =IF(BW10>0,BW10/BZ10,0) -> #DIV/0! | CB10: =BW10*CD1 -> 21466.871 | CC10: =IF(CB10>0,CB10/BX9,0) -> 325.25561 | CD10: =IF(CB10>0,CB10/BZ10,0) -> #DIV/0!
A11: 6 | C11: =IF(+B11-B10>0,B11-B10,(B11-B10)>0)*800 -> 0 | E11: =IF(+D11-D10>0,D11-D10,(D11-D10)>0)*80 -> 0 | G11: =IF(+F11-F10>0,F11-F10,(F11-F10)>0)*10 -> 0 | I11: 22078712 | J11: =IF(I11>=I10,I11-I10,0) -> 4466 | K11: =M11+O11 -> 2826 | L11: 9539 | M11: =IF(L11>=L10,L11-L10,0) -> 1278 | N11: 12858 | O11: =IF(N11>=N10,N11-N10,0) -> 1548 | P11: 214838 | Q11: =IF(P11>=P10,P11-P10,0)*30 -> 600 | R11: 702925 | S11: =IF(R11>=R10,R11-R10,0) -> 0 | T11: 344001 | U11: =IF(T11>=T10,T11-T10,0) -> 0 | V11: 131863 | W11: =IF(V11>=V10,V11-V10,0) -> 146 | X11: 239788 | Y11: =IF(X11>=X10,X11-X10,0) -> 246 | Z11: 316576 | AA11: =IF(Z11>=Z10,Z11-Z10,0)*0.53 -> 0 | AB11: 387774 | AC11: =IF(AB11>=AB10,AB11-AB10,0)*0.53 -> 0 | AD11: 573530 | AE11: =IF(AD11>=AD10,AD11-AD10,0)*0.53 -> 1742.11 | AF11: 309097 | AG11: =IF(AF11>=AF10,AF11-AF10,0)*0.53 -> 0 | AH11: 329638.56 | AI11: =IF(AH11>=AH10,AH11-AH10,0)*0.53 -> 12.215238 | AJ11: 707758.44 | AK11: =IF(AJ11>=AJ10,AJ11-AJ10,0)*0.53 -> 12.164762 | AL11: 536186 | AM11: =IF(AL11>=AL10,AL11-AL10,0)*0.53 -> 291.5 | AN11: 735003 | AO11: =IF(AN11>=AN10,AN11-AN10,0)*0.53 -> 1824.79 | AP11: 382072.21 | AQ11: =IF(AP11>=AP10,AP11-AP10,0)*0.53 -> 172.81786 | AR11: =AA11+AC11+AE11+AG11+AI11+AK11+AM11+AO11+AQ11 -> 4055.5979 | AS11: 7218528 | AT11: =IF(AS11>=AS10,AS11-AS10,0)*0.1125 -> 86.9625 | AU11: 575905 | AV11: =IF(AU11>=AU10,AU11-AU10,0) -> 285 | AW11: 914179 | AX11: =IF(AW11>=AW10,AW11-AW10,0) -> 125 | AY11: 794934 | AZ11: =IF(AY11>=AY10,AY11-AY10,0) -> 29 | BA11: 2339394 | BB11: =IF(BA11>=BA10,BA11-BA10,0) -> 378 | BC11: 209846 | BD11: =IF(BC11>=BC10,BC11-BC10,0) -> 62 | BE11: 17690651 | BF11: =IF(BE11>=BE10,BE11-BE10,0) -> 3448 | BG11: 498677.79 | BH11: =IF(BG11>=BG10,BG11-BG10,0) -> 107.67857 | BI11: 8805 | BJ11: =IF(BI11>=BI10,BI11-BI10,0) -> 0 | BK11: 21924377 | BL11: =IF(BK11>=BK10,BK11-BK10,0)-(0.45*BR11)-(0.45*BT11)-BV11 -> 4899.65 | BM11: =AT11+AV11+AX11+AZ11+BB11+BD11+BF11+BH11+BJ11+BL11 -> 9421.2911 | BN11: =BM11+AR11 -> 13476.889 | BO11: 1371052 | BP11: =IF(BO11>=BO10,BO11-BO10,0) -> 273 | BQ11: 3495702 | BR11: =IF(BQ11>=BQ10,BQ11-BQ10,0) -> 728 | BS11: 373329 | BT11: =IF(BS11>=BS10,BS11-BS10,0) -> 35 | BU11: 453214 | BV11: =IF(BU11>=BU10,BU11-BU10,0) -> 112 | BW11: =J11+Q11+AR11+BM11 -> 18542.889 | BX11: 75 | BY11: =IF(BW11>0,BW11/BX10,0) -> 272.68954 | CA11: =IF(BW11>0,BW11/BZ11,0) -> #DIV/0! | CB11: =BW11*CD1 -> 21324.322 | CC11: =IF(CB11>0,CB11/BX10,0) -> 313.59297 | CD11: =IF(CB11>0,CB11/BZ11,0) -> #DIV/0!
A12: 7 | C12: =IF(+B12-B11>0,B12-B11,(B12-B11)>0)*800 -> 0 | E12: =IF(+D12-D11>0,D12-D11,(D12-D11)>0)*80 -> 0 | G12: =IF(+F12-F11>0,F12-F11,(F12-F11)>0)*10 -> 0 | H12: 59 | I12: 22083338 | J12: =IF(I12>=I11,I12-I11,0) -> 4626 | K12: =M12+O12 -> 2998 | L12: 10912 | M12: =IF(L12>=L11,L12-L11,0) -> 1373 | N12: 14483 | O12: =IF(N12>=N11,N12-N11,0) -> 1625 | P12: 214858 | Q12: =IF(P12>=P11,P12-P11,0)*30 -> 600 | R12: 702925 | S12: =IF(R12>=R11,R12-R11,0) -> 0 | T12: 344001 | U12: =IF(T12>=T11,T12-T11,0) -> 0 | V12: 132009 | W12: =IF(V12>=V11,V12-V11,0) -> 146 | X12: 240042 | Y12: =IF(X12>=X11,X12-X11,0) -> 254 | Z12: 316576 | AA12: =IF(Z12>=Z11,Z12-Z11,0)*0.53 -> 0 | AB12: 387774 | AC12: =IF(AB12>=AB11,AB12-AB11,0)*0.53 -> 0 | AD12: 578484 | AE12: =IF(AD12>=AD11,AD12-AD11,0)*0.53 -> 2625.62 | AF12: 309097 | AG12: =IF(AF12>=AF11,AF12-AF11,0)*0.53 -> 0 | AH12: 329661.61 | AI12: =IF(AH12>=AH11,AH12-AH11,0)*0.53 -> 12.215238 | AJ12: 707781.39 | AK12: =IF(AJ12>=AJ11,AJ12-AJ11,0)*0.53 -> 12.164762 | AL12: 536655 | AM12: =IF(AL12>=AL11,AL12-AL11,0)*0.53 -> 248.57 | AN12: 739099 | AO12: =IF(AN12>=AN11,AN12-AN11,0)*0.53 -> 2170.88 | AP12: 382398.29 | AQ12: =IF(AP12>=AP11,AP12-AP11,0)*0.53 -> 172.81786 | AR12: =AA12+AC12+AE12+AG12+AI12+AK12+AM12+AO12+AQ12 -> 5242.2679 | AS12: 7219241 | AT12: =IF(AS12>=AS11,AS12-AS11,0)*0.1125 -> 80.2125 | AU12: 576206 | AV12: =IF(AU12>=AU11,AU12-AU11,0) -> 301 | AW12: 914304 | AX12: =IF(AW12>=AW11,AW12-AW11,0) -> 125 | AY12: 794978 | AZ12: =IF(AY12>=AY11,AY12-AY11,0) -> 44 | BA12: 2339790 | BB12: =IF(BA12>=BA11,BA12-BA11,0) -> 396 | BC12: 209909 | BD12: =IF(BC12>=BC11,BC12-BC11,0) -> 63 | BE12: 17694300 | BF12: =IF(BE12>=BE11,BE12-BE11,0) -> 3649 | BG12: 498785.46 | BH12: =IF(BG12>=BG11,BG12-BG11,0) -> 107.67857 | BI12: 8805 | BJ12: =IF(BI12>=BI11,BI12-BI11,0) -> 0 | BK12: 21929872 | BL12: =IF(BK12>=BK11,BK12-BK11,0)-(0.45*BR12)-(0.45*BT12)-BV12 -> 4808.25 | BM12: =AT12+AV12+AX12+AZ12+BB12+BD12+BF12+BH12+BJ12+BL12 -> 9574.1411 | BN12: =BM12+AR12 -> 14816.409 | BO12: 1371325 | BP12: =IF(BO12>=BO11,BO12-BO11,0) -> 273 | BQ12: 3496666 | BR12: =IF(BQ12>=BQ11,BQ12-BQ11,0) -> 964 | BS12: 373440 | BT12: =IF(BS12>=BS11,BS12-BS11,0) -> 111 | BU12: 453417 | BV12: =IF(BU12>=BU11,BU12-BU11,0) -> 203 | BW12: =J12+Q12+AR12+BM12 -> 20042.409 | BX12: 59 | BY12: =IF(BW12>0,BW12/BX11,0) -> 267.23212 | CA12: =IF(BW12>0,BW12/BZ12,0) -> #DIV/0! | CB12: =BW12*CD1 -> 23048.77 | CC12: =IF(CB12>0,CB12/BX11,0) -> 307.31694 | CD12: =IF(CB12>0,CB12/BZ12,0) -> #DIV/0!
A13: 8 | C13: =IF(+B13-B12>0,B13-B12,(B13-B12)>0)*800 -> 0 | E13: =IF(+D13-D12>0,D13-D12,(D13-D12)>0)*80 -> 0 | G13: =IF(+F13-F12>0,F13-F12,(F13-F12)>0)*10 -> 0 | I13: 22088191 | J13: =IF(I13>=I12,I13-I12,0) -> 4853 | K13: =M13+O13 -> 3115 | L13: 12354 | M13: =IF(L13>=L12,L13-L12,0) -> 1442 | N13: 16156 | O13: =IF(N13>=N12,N13-N12,0) -> 1673 | P13: 214881 | Q13: =IF(P13>=P12,P13-P12,0)*30 -> 690 | R13: 702925 | S13: =IF(R13>=R12,R13-R12,0) -> 0 | T13: 344001 | U13: =IF(T13>=T12,T13-T12,0) -> 0 | V13: 132156 | W13: =IF(V13>=V12,V13-V12,0) -> 147 | X13: 240293 | Y13: =IF(X13>=X12,X13-X12,0) -> 251 | Z13: 318655 | AA13: =IF(Z13>=Z12,Z13-Z12,0)*0.53 -> 1101.87 | AB13: 387774 | AC13: =IF(AB13>=AB12,AB13-AB12,0)*0.53 -> 0 | AD13: 580407 | AE13: =IF(AD13>=AD12,AD13-AD12,0)*0.53 -> 1019.19 | AF13: 309097 | AG13: =IF(AF13>=AF12,AF13-AF12,0)*0.53 -> 0 | AH13: 329684.65 | AI13: =IF(AH13>=AH12,AH13-AH12,0)*0.53 -> 12.215238 | AJ13: 707804.35 | AK13: =IF(AJ13>=AJ12,AJ13-AJ12,0)*0.53 -> 12.164762 | AL13: 537345 | AM13: =IF(AL13>=AL12,AL13-AL12,0)*0.53 -> 365.7 | AN13: 743210 | AO13: =IF(AN13>=AN12,AN13-AN12,0)*0.53 -> 2178.83 | AP13: 382724.36 | AQ13: =IF(AP13>=AP12,AP13-AP12,0)*0.53 -> 172.81786 | AR13: =AA13+AC13+AE13+AG13+AI13+AK13+AM13+AO13+AQ13 -> 4862.7879 | AS13: 7219885 | AT13: =IF(AS13>=AS12,AS13-AS12,0)*0.1125 -> 72.45 | AU13: 576463 | AV13: =IF(AU13>=AU12,AU13-AU12,0) -> 257 | AW13: 914430 | AX13: =IF(AW13>=AW12,AW13-AW12,0) -> 126 | AY13: 795015 | AZ13: =IF(AY13>=AY12,AY13-AY12,0) -> 37 | BA13: 2340182 | BB13: =IF(BA13>=BA12,BA13-BA12,0) -> 392 | BC13: 209971 | BD13: =IF(BC13>=BC12,BC13-BC12,0) -> 62 | BE13: 17697804 | BF13: =IF(BE13>=BE12,BE13-BE12,0) -> 3504 | BG13: 498893.14 | BH13: =IF(BG13>=BG12,BG13-BG12,0) -> 107.67857 | BI13: 8805 | BJ13: =IF(BI13>=BI12,BI13-BI12,0) -> 0 | BK13: 21935325 | BL13: =IF(BK13>=BK12,BK13-BK12,0)-(0.45*BR13)-(0.45*BT13)-BV13 -> 4719 | BM13: =AT13+AV13+AX13+AZ13+BB13+BD13+BF13+BH13+BJ13+BL13 -> 9277.1286 | BN13: =BM13+AR13 -> 14139.916 | BO13: 1371598 | BP13: =IF(BO13>=BO12,BO13-BO12,0) -> 273 | BQ13: 3497721 | BR13: =IF(BQ13>=BQ12,BQ13-BQ12,0) -> 1055 | BS13: 373565 | BT13: =IF(BS13>=BS12,BS13-BS12,0) -> 125 | BU13: 453620 | BV13: =IF(BU13>=BU12,BU13-BU12,0) -> 203 | BW13: =J13+Q13+AR13+BM13 -> 19682.916 | BX13: 49 | BY13: =IF(BW13>0,BW13/BX12,0) -> 333.60875 | CA13: =IF(BW13>0,BW13/BZ13,0) -> #DIV/0! | CB13: =BW13*CD1 -> 22635.354 | CC13: =IF(CB13>0,CB13/BX12,0) -> 383.65007 | CD13: =IF(CB13>0,CB13/BZ13,0) -> #DIV/0!
A14: 9 | C14: =IF(+B14-B13>0,B14-B13,(B14-B13)>0)*800 -> 0 | E14: =IF(+D14-D13>0,D14-D13,(D14-D13)>0)*80 -> 0 | G14: =IF(+F14-F13>0,F14-F13,(F14-F13)>0)*10 -> 0 | H14: 60 | I14: 22093101 | J14: =IF(I14>=I13,I14-I13,0) -> 4910 | K14: =M14+O14 -> 3099 | L14: 13763 | M14: =IF(L14>=L13,L14-L13,0) -> 1409 | N14: 17846 | O14: =IF(N14>=N13,N14-N13,0) -> 1690 | P14: 214902 | Q14: =IF(P14>=P13,P14-P13,0)*30 -> 630 | R14: 702925 | S14: =IF(R14>=R13,R14-R13,0) -> 0 | T14: 344001 | U14: =IF(T14>=T13,T14-T13,0) -> 0 | V14: 132299 | W14: =IF(V14>=V13,V14-V13,0) -> 143 | X14: 240537 | Y14: =IF(X14>=X13,X14-X13,0) -> 244 | Z14: 322574 | AA14: =IF(Z14>=Z13,Z14-Z13,0)*0.53 -> 2077.07 | AB14: 387774 | AC14: =IF(AB14>=AB13,AB14-AB13,0)*0.53 -> 0 | AD14: 580407 | AE14: =IF(AD14>=AD13,AD14-AD13,0)*0.53 -> 0 | AF14: 309097 | AG14: =IF(AF14>=AF13,AF14-AF13,0)*0.53 -> 0 | AH14: 329707.7 | AI14: =IF(AH14>=AH13,AH14-AH13,0)*0.53 -> 12.215238 | AJ14: 707827.3 | AK14: =IF(AJ14>=AJ13,AJ14-AJ13,0)*0.53 -> 12.164762 | AL14: 538267 | AM14: =IF(AL14>=AL13,AL14-AL13,0)*0.53 -> 488.66 | AN14: 747455 | AO14: =IF(AN14>=AN13,AN14-AN13,0)*0.53 -> 2249.85 | AP14: 383050.43 | AQ14: =IF(AP14>=AP13,AP14-AP13,0)*0.53 -> 172.81786 | AR14: =AA14+AC14+AE14+AG14+AI14+AK14+AM14+AO14+AQ14 -> 5012.7779 | AS14: 7220522 | AT14: =IF(AS14>=AS13,AS14-AS13,0)*0.1125 -> 71.6625 | AU14: 576747 | AV14: =IF(AU14>=AU13,AU14-AU13,0) -> 284 | AW14: 914556 | AX14: =IF(AW14>=AW13,AW14-AW13,0) -> 126 | AY14: 795054 | AZ14: =IF(AY14>=AY13,AY14-AY13,0) -> 39 | BA14: 2340587 | BB14: =IF(BA14>=BA13,BA14-BA13,0) -> 405 | BC14: 210035 | BD14: =IF(BC14>=BC13,BC14-BC13,0) -> 64 | BE14: 17701180 | BF14: =IF(BE14>=BE13,BE14-BE13,0) -> 3376 | BG14: 499000.82 | BH14: =IF(BG14>=BG13,BG14-BG13,0) -> 107.67857 | BI14: 8805 | BJ14: =IF(BI14>=BI13,BI14-BI13,0) -> 0 | BK14: 21940794 | BL14: =IF(BK14>=BK13,BK14-BK13,0)-(0.45*BR14)-(0.45*BT14)-BV14 -> 4720.55 | BM14: =AT14+AV14+AX14+AZ14+BB14+BD14+BF14+BH14+BJ14+BL14 -> 9193.8911 | BN14: =BM14+AR14 -> 14206.669 | BO14: 1371871 | BP14: =IF(BO14>=BO13,BO14-BO13,0) -> 273 | BQ14: 3498823 | BR14: =IF(BQ14>=BQ13,BQ14-BQ13,0) -> 1102 | BS14: 373684 | BT14: =IF(BS14>=BS13,BS14-BS13,0) -> 119 | BU14: 453819 | BV14: =IF(BU14>=BU13,BU14-BU13,0) -> 199 | BW14: =J14+Q14+AR14+BM14 -> 19746.669 | BX14: 53 | BY14: =IF(BW14>0,BW14/BX13,0) -> 402.99324 | CA14: =IF(BW14>0,BW14/BZ14,0) -> #DIV/0! | CB14: =BW14*CD1 -> 22708.669 | CC14: =IF(CB14>0,CB14/BX13,0) -> 463.44223 | CD14: =IF(CB14>0,CB14/BZ14,0) -> #DIV/0!
A15: 10 | C15: =IF(+B15-B14>0,B15-B14,(B15-B14)>0)*800 -> 0 | E15: =IF(+D15-D14>0,D15-D14,(D15-D14)>0)*80 -> 0 | G15: =IF(+F15-F14>0,F15-F14,(F15-F14)>0)*10 -> 0 | I15: 22097636 | J15: =IF(I15>=I14,I15-I14,0) -> 4535 | K15: =M15+O15 -> 3305 | L15: 15269 | M15: =IF(L15>=L14,L15-L14,0) -> 1506 | N15: 19645 | O15: =IF(N15>=N14,N15-N14,0) -> 1799 | P15: 214921 | Q15: =IF(P15>=P14,P15-P14,0)*30 -> 570 | R15: 702925 | S15: =IF(R15>=R14,R15-R14,0) -> 0 | T15: 344001 | U15: =IF(T15>=T14,T15-T14,0) -> 0 | V15: 132450 | W15: =IF(V15>=V14,V15-V14,0) -> 151 | X15: 240756 | Y15: =IF(X15>=X14,X15-X14,0) -> 219 | Z15: 326682 | AA15: =IF(Z15>=Z14,Z15-Z14,0)*0.53 -> 2177.24 | AB15: 387774 | AC15: =IF(AB15>=AB14,AB15-AB14,0)*0.53 -> 0 | AD15: 580407 | AE15: =IF(AD15>=AD14,AD15-AD14,0)*0.53 -> 0 | AF15: 309097 | AG15: =IF(AF15>=AF14,AF15-AF14,0)*0.53 -> 0 | AH15: 329730.75 | AI15: =IF(AH15>=AH14,AH15-AH14,0)*0.53 -> 12.215238 | AJ15: 707850.25 | AK15: =IF(AJ15>=AJ14,AJ15-AJ14,0)*0.53 -> 12.164762 | AL15: 539239 | AM15: =IF(AL15>=AL14,AL15-AL14,0)*0.53 -> 515.16 | AN15: 751935 | AO15: =IF(AN15>=AN14,AN15-AN14,0)*0.53 -> 2374.4 | AP15: 383376.5 | AQ15: =IF(AP15>=AP14,AP15-AP14,0)*0.53 -> 172.81786 | AR15: =AA15+AC15+AE15+AG15+AI15+AK15+AM15+AO15+AQ15 -> 5263.9979 | AS15: 7221198 | AT15: =IF(AS15>=AS14,AS15-AS14,0)*0.1125 -> 76.05 | AU15: 577019 | AV15: =IF(AU15>=AU14,AU15-AU14,0) -> 272 | AW15: 914686 | AX15: =IF(AW15>=AW14,AW15-AW14,0) -> 130 | AY15: 795097 | AZ15: =IF(AY15>=AY14,AY15-AY14,0) -> 43 | BA15: 2340999 | BB15: =IF(BA15>=BA14,BA15-BA14,0) -> 412 | BC15: 210103 | BD15: =IF(BC15>=BC14,BC15-BC14,0) -> 68 | BE15: 17704725 | BF15: =IF(BE15>=BE14,BE15-BE14,0) -> 3545 | BG15: 499108.5 | BH15: =IF(BG15>=BG14,BG15-BG14,0) -> 107.67857 | BI15: 8805 | BJ15: =IF(BI15>=BI14,BI15-BI14,0) -> 0 | BK15: 21946389 | BL15: =IF(BK15>=BK14,BK15-BK14,0)-(0.45*BR15)-(0.45*BT15)-BV15 -> 4813.25 | BM15: =AT15+AV15+AX15+AZ15+BB15+BD15+BF15+BH15+BJ15+BL15 -> 9466.9786 | BN15: =BM15+AR15 -> 14730.976 | BO15: 1372224 | BP15: =IF(BO15>=BO14,BO15-BO14,0) -> 353 | BQ15: 3499978 | BR15: =IF(BQ15>=BQ14,BQ15-BQ14,0) -> 1155 | BS15: 373804 | BT15: =IF(BS15>=BS14,BS15-BS14,0) -> 120 | BU15: 454027 | BV15: =IF(BU15>=BU14,BU15-BU14,0) -> 208 | BW15: =J15+Q15+AR15+BM15 -> 19835.976 | BX15: 52 | BY15: =IF(BW15>0,BW15/BX14,0) -> 374.26371 | CA15: =IF(BW15>0,BW15/BZ15,0) -> #DIV/0! | CB15: =BW15*CD1 -> 22811.373 | CC15: =IF(CB15>0,CB15/BX14,0) -> 430.40326 | CD15: =IF(CB15>0,CB15/BZ15,0) -> #DIV/0!
A16: 11 | C16: =IF(+B16-B15>0,B16-B15,(B16-B15)>0)*800 -> 0 | E16: =IF(+D16-D15>0,D16-D15,(D16-D15)>0)*80 -> 0 | G16: =IF(+F16-F15>0,F16-F15,(F16-F15)>0)*10 -> 0 | H16: 61 | I16: 22103442 | J16: =IF(I16>=I15,I16-I15,0) -> 5806 | K16: =M16+O16 -> 3134 | L16: 16806 | M16: =IF(L16>=L15,L16-L15,0) -> 1537 | N16: 21242 | O16: =IF(N16>=N15,N16-N15,0) -> 1597 | P16: 214944 | Q16: =IF(P16>=P15,P16-P15,0)*30 -> 690 | R16: 702925 | S16: =IF(R16>=R15,R16-R15,0) -> 0 | T16: 344001 | U16: =IF(T16>=T15,T16-T15,0) -> 0 | V16: 132588 | W16: =IF(V16>=V15,V16-V15,0) -> 138 | X16: 241031 | Y16: =IF(X16>=X15,X16-X15,0) -> 275 | Z16: 330193 | AA16: =IF(Z16>=Z15,Z16-Z15,0)*0.53 -> 1860.83 | AB16: 387774 | AC16: =IF(AB16>=AB15,AB16-AB15,0)*0.53 -> 0 | AD16: 580407 | AE16: =IF(AD16>=AD15,AD16-AD15,0)*0.53 -> 0 | AF16: 309097 | AG16: =IF(AF16>=AF15,AF16-AF15,0)*0.53 -> 0 | AH16: 329753.8 | AI16: =IF(AH16>=AH15,AH16-AH15,0)*0.53 -> 12.215238 | AJ16: 707873.2 | AK16: =IF(AJ16>=AJ15,AJ16-AJ15,0)*0.53 -> 12.164762 | AL16: 540121 | AM16: =IF(AL16>=AL15,AL16-AL15,0)*0.53 -> 467.46 | AN16: 755937 | AO16: =IF(AN16>=AN15,AN16-AN15,0)*0.53 -> 2121.06 | AP16: 383702.57 | AQ16: =IF(AP16>=AP15,AP16-AP15,0)*0.53 -> 172.81786 | AR16: =AA16+AC16+AE16+AG16+AI16+AK16+AM16+AO16+AQ16 -> 4646.5479 | AS16: 7221929 | AT16: =IF(AS16>=AS15,AS16-AS15,0)*0.1125 -> 82.2375 | AU16: 577301 | AV16: =IF(AU16>=AU15,AU16-AU15,0) -> 282 | AW16: 914808 | AX16: =IF(AW16>=AW15,AW16-AW15,0) -> 122 | AY16: 795133 | AZ16: =IF(AY16>=AY15,AY16-AY15,0) -> 36 | BA16: 2341339 | BB16: =IF(BA16>=BA15,BA16-BA15,0) -> 340 | BC16: 210165 | BD16: =IF(BC16>=BC15,BC16-BC15,0) -> 62 | BE16: 17707964 | BF16: =IF(BE16>=BE15,BE16-BE15,0) -> 3239 | BG16: 499216.18 | BH16: =IF(BG16>=BG15,BG16-BG15,0) -> 107.67857 | BI16: 8805 | BJ16: =IF(BI16>=BI15,BI16-BI15,0) -> 0 | BK16: 21951352 | BL16: =IF(BK16>=BK15,BK16-BK15,0)-(0.45*BR16)-(0.45*BT16)-BV16 -> 4321.3 | BM16: =AT16+AV16+AX16+AZ16+BB16+BD16+BF16+BH16+BJ16+BL16 -> 8592.2161 | BN16: =BM16+AR16 -> 13238.764 | BO16: 1372446 | BP16: =IF(BO16>=BO15,BO16-BO15,0) -> 222 | BQ16: 3500877 | BR16: =IF(BQ16>=BQ15,BQ16-BQ15,0) -> 899 | BS16: 373911 | BT16: =IF(BS16>=BS15,BS16-BS15,0) -> 107 | BU16: 454216 | BV16: =IF(BU16>=BU15,BU16-BU15,0) -> 189 | BW16: =J16+Q16+AR16+BM16 -> 19734.764 | BX16: 54 | BY16: =IF(BW16>0,BW16/BX15,0) -> 379.51469 | CA16: =IF(BW16>0,BW16/BZ16,0) -> #DIV/0! | CB16: =BW16*CD1 -> 22694.979 | CC16: =IF(CB16>0,CB16/BX15,0) -> 436.44189 | CD16: =IF(CB16>0,CB16/BZ16,0) -> #DIV/0!
A17: 12 | C17: =IF(+B17-B16>0,B17-B16,(B17-B16)>0)*800 -> 0 | E17: =IF(+D17-D16>0,D17-D16,(D17-D16)>0)*80 -> 0 | G17: =IF(+F17-F16>0,F17-F16,(F17-F16)>0)*10 -> 0 | I17: 22108127 | J17: =IF(I17>=I16,I17-I16,0) -> 4685 | K17: =M17+O17 -> 3241 | L17: 18393 | M17: =IF(L17>=L16,L17-L16,0) -> 1587 | N17: 22896 | O17: =IF(N17>=N16,N17-N16,0) -> 1654 | P17: 214963 | Q17: =IF(P17>=P16,P17-P16,0)*30 -> 570 | R17: 702925 | S17: =IF(R17>=R16,R17-R16,0) -> 0 | T17: 344001 | U17: =IF(T17>=T16,T17-T16,0) -> 0 | V17: 132731 | W17: =IF(V17>=V16,V17-V16,0) -> 143 | X17: 241274 | Y17: =IF(X17>=X16,X17-X16,0) -> 243 | Z17: 334099 | AA17: =IF(Z17>=Z16,Z17-Z16,0)*0.53 -> 2070.18 | AB17: 387774 | AC17: =IF(AB17>=AB16,AB17-AB16,0)*0.53 -> 0 | AD17: 580407 | AE17: =IF(AD17>=AD16,AD17-AD16,0)*0.53 -> 0 | AF17: 309097 | AG17: =IF(AF17>=AF16,AF17-AF16,0)*0.53 -> 0 | AH17: 329776.85 | AI17: =IF(AH17>=AH16,AH17-AH16,0)*0.53 -> 12.215238 | AJ17: 707896.15 | AK17: =IF(AJ17>=AJ16,AJ17-AJ16,0)*0.53 -> 12.164762 | AL17: 541048 | AM17: =IF(AL17>=AL16,AL17-AL16,0)*0.53 -> 491.31 | AN17: 760045 | AO17: =IF(AN17>=AN16,AN17-AN16,0)*0.53 -> 2177.24 | AP17: 384028.64 | AQ17: =IF(AP17>=AP16,AP17-AP16,0)*0.53 -> 172.81786 | AR17: =AA17+AC17+AE17+AG17+AI17+AK17+AM17+AO17+AQ17 -> 4935.9279 | AS17: 7222495 | AT17: =IF(AS17>=AS16,AS17-AS16,0)*0.1125 -> 63.675 | AU17: 577590 | AV17: =IF(AU17>=AU16,AU17-AU16,0) -> 289 | AW17: 914935 | AX17: =IF(AW17>=AW16,AW17-AW16,0) -> 127 | AY17: 795154 | AZ17: =IF(AY17>=AY16,AY17-AY16,0) -> 21 | BA17: 2341718 | BB17: =IF(BA17>=BA16,BA17-BA16,0) -> 379 | BC17: 210230 | BD17: =IF(BC17>=BC16,BC17-BC16,0) -> 65 | BE17: 17711291 | BF17: =IF(BE17>=BE16,BE17-BE16,0) -> 3327 | BG17: 499323.86 | BH17: =IF(BG17>=BG16,BG17-BG16,0) -> 107.67857 | BI17: 8805 | BJ17: =IF(BI17>=BI16,BI17-BI16,0) -> 0 | BK17: 21956486 | BL17: =IF(BK17>=BK16,BK17-BK16,0)-(0.45*BR17)-(0.45*BT17)-BV17 -> 4467.8 | BM17: =AT17+AV17+AX17+AZ17+BB17+BD17+BF17+BH17+BJ17+BL17 -> 8847.1536 | BN17: =BM17+AR17 -> 13783.081 | BO17: 1372722 | BP17: =IF(BO17>=BO16,BO17-BO16,0) -> 276 | BQ17: 3501813 | BR17: =IF(BQ17>=BQ16,BQ17-BQ16,0) -> 936 | BS17: 374011 | BT17: =IF(BS17>=BS16,BS17-BS16,0) -> 100 | BU17: 454416 | BV17: =IF(BU17>=BU16,BU17-BU16,0) -> 200 | BW17: =J17+Q17+AR17+BM17 -> 19038.081 | BX17: 69 | BY17: =IF(BW17>0,BW17/BX16,0) -> 352.55706 | CA17: =IF(BW17>0,BW17/BZ17,0) -> #DIV/0! | CB17: =BW17*CD1 -> 21893.794 | CC17: =IF(CB17>0,CB17/BX16,0) -> 405.44062 | CD17: =IF(CB17>0,CB17/BZ17,0) -> #DIV/0!
A18: 13 | C18: =IF(+B18-B17>0,B18-B17,(B18-B17)>0)*800 -> 0 | E18: =IF(+D18-D17>0,D18-D17,(D18-D17)>0)*80 -> 0 | G18: =IF(+F18-F17>0,F18-F17,(F18-F17)>0)*10 -> 0 | H18: 62 | I18: 22114031 | J18: =IF(I18>=I17,I18-I17,0) -> 5904 | K18: =M18+O18 -> 3255 | L18: 20020 | M18: =IF(L18>=L17,L18-L17,0) -> 1627 | N18: 24524 | O18: =IF(N18>=N17,N18-N17,0) -> 1628 | P18: 214983 | Q18: =IF(P18>=P17,P18-P17,0)*30 -> 600 | R18: 702925 | S18: =IF(R18>=R17,R18-R17,0) -> 0 | T18: 344001 | U18: =IF(T18>=T17,T18-T17,0) -> 0 | V18: 132879 | W18: =IF(V18>=V17,V18-V17,0) -> 148 | X18: 241523 | Y18: =IF(X18>=X17,X18-X17,0) -> 249 | Z18: 338058 | AA18: =IF(Z18>=Z17,Z18-Z17,0)*0.53 -> 2098.27 | AB18: 387774 | AC18: =IF(AB18>=AB17,AB18-AB17,0)*0.53 -> 0 | AD18: 580407 | AE18: =IF(AD18>=AD17,AD18-AD17,0)*0.53 -> 0 | AF18: 309097 | AG18: =IF(AF18>=AF17,AF18-AF17,0)*0.53 -> 0 | AH18: 329799.89 | AI18: =IF(AH18>=AH17,AH18-AH17,0)*0.53 -> 12.215238 | AJ18: 707919.11 | AK18: =IF(AJ18>=AJ17,AJ18-AJ17,0)*0.53 -> 12.164762 | AL18: 542004 | AM18: =IF(AL18>=AL17,AL18-AL17,0)*0.53 -> 506.68 | AN18: 764280 | AO18: =IF(AN18>=AN17,AN18-AN17,0)*0.53 -> 2244.55 | AP18: 384354.71 | AQ18: =IF(AP18>=AP17,AP18-AP17,0)*0.53 -> 172.81786 | AR18: =AA18+AC18+AE18+AG18+AI18+AK18+AM18+AO18+AQ18 -> 5046.6979 | AS18: 7223196 | AT18: =IF(AS18>=AS17,AS18-AS17,0)*0.1125 -> 78.8625 | AU18: 577840 | AV18: =IF(AU18>=AU17,AU18-AU17,0) -> 250 | AW18: 915039 | AX18: =IF(AW18>=AW17,AW18-AW17,0) -> 104 | AY18: 795175 | AZ18: =IF(AY18>=AY17,AY18-AY17,0) -> 21 | BA18: 2342106 | BB18: =IF(BA18>=BA17,BA18-BA17,0) -> 388 | BC18: 210296 | BD18: =IF(BC18>=BC17,BC18-BC17,0) -> 66 | BE18: 17714756 | BF18: =IF(BE18>=BE17,BE18-BE17,0) -> 3465 | BG18: 499431.54 | BH18: =IF(BG18>=BG17,BG18-BG17,0) -> 107.67857 | BI18: 8805 | BJ18: =IF(BI18>=BI17,BI18-BI17,0) -> 0 | BK18: 21961827 | BL18: =IF(BK18>=BK17,BK18-BK17,0)-(0.45*BR18)-(0.45*BT18)-BV18 -> 4660 | BM18: =AT18+AV18+AX18+AZ18+BB18+BD18+BF18+BH18+BJ18+BL18 -> 9140.5411 | BN18: =BM18+AR18 -> 14187.239 | BO18: 1372999 | BP18: =IF(BO18>=BO17,BO18-BO17,0) -> 277 | BQ18: 3502751 | BR18: =IF(BQ18>=BQ17,BQ18-BQ17,0) -> 938 | BS18: 374133 | BT18: =IF(BS18>=BS17,BS18-BS17,0) -> 122 | BU18: 454620 | BV18: =IF(BU18>=BU17,BU18-BU17,0) -> 204 | BW18: =J18+Q18+AR18+BM18 -> 20691.239 | BX18: 54 | BY18: =IF(BW18>0,BW18/BX17,0) -> 299.87303 | CA18: =IF(BW18>0,BW18/BZ18,0) -> #DIV/0! | CB18: =BW18*CD1 -> 23794.925 | CC18: =IF(CB18>0,CB18/BX17,0) -> 344.85398 | CD18: =IF(CB18>0,CB18/BZ18,0) -> #DIV/0!
A19: 14 | C19: =IF(+B19-B18>0,B19-B18,(B19-B18)>0)*800 -> 0 | E19: =IF(+D19-D18>0,D19-D18,(D19-D18)>0)*80 -> 0 | G19: =IF(+F19-F18>0,F19-F18,(F19-F18)>0)*10 -> 0 | I19: 22119160 | J19: =IF(I19>=I18,I19-I18,0) -> 5129 | K19: =M19+O19 -> 3144 | L19: 21586 | M19: =IF(L19>=L18,L19-L18,0) -> 1566 | N19: 26102 | O19: =IF(N19>=N18,N19-N18,0) -> 1578 | P19: 215001 | Q19: =IF(P19>=P18,P19-P18,0)*30 -> 540 | R19: 702925 | S19: =IF(R19>=R18,R19-R18,0) -> 0 | T19: 344001 | U19: =IF(T19>=T18,T19-T18,0) -> 0 | V19: 133023 | W19: =IF(V19>=V18,V19-V18,0) -> 144 | X19: 241763 | Y19: =IF(X19>=X18,X19-X18,0) -> 240 | Z19: 341930 | AA19: =IF(Z19>=Z18,Z19-Z18,0)*0.53 -> 2052.16 | AB19: 387774 | AC19: =IF(AB19>=AB18,AB19-AB18,0)*0.53 -> 0 | AD19: 580407 | AE19: =IF(AD19>=AD18,AD19-AD18,0)*0.53 -> 0 | AF19: 309097 | AG19: =IF(AF19>=AF18,AF19-AF18,0)*0.53 -> 0 | AH19: 329822.94 | AI19: =IF(AH19>=AH18,AH19-AH18,0)*0.53 -> 12.215238 | AJ19: 707942.06 | AK19: =IF(AJ19>=AJ18,AJ19-AJ18,0)*0.53 -> 12.164762 | AL19: 542928 | AM19: =IF(AL19>=AL18,AL19-AL18,0)*0.53 -> 489.72 | AN19: 768409 | AO19: =IF(AN19>=AN18,AN19-AN18,0)*0.53 -> 2188.37 | AP19: 384680.79 | AQ19: =IF(AP19>=AP18,AP19-AP18,0)*0.53 -> 172.81786 | AR19: =AA19+AC19+AE19+AG19+AI19+AK19+AM19+AO19+AQ19 -> 4927.4479 | AS19: 7223872 | AT19: =IF(AS19>=AS18,AS19-AS18,0)*0.1125 -> 76.05 | AU19: 578099 | AV19: =IF(AU19>=AU18,AU19-AU18,0) -> 259 | AW19: 915111 | AX19: =IF(AW19>=AW18,AW19-AW18,0) -> 72 | AY19: 795210 | AZ19: =IF(AY19>=AY18,AY19-AY18,0) -> 35 | BA19: 2342479 | BB19: =IF(BA19>=BA18,BA19-BA18,0) -> 373 | BC19: 210360 | BD19: =IF(BC19>=BC18,BC19-BC18,0) -> 64 | BE19: 17718257 | BF19: =IF(BE19>=BE18,BE19-BE18,0) -> 3501 | BG19: 499539.21 | BH19: =IF(BG19>=BG18,BG19-BG18,0) -> 107.67857 | BI19: 8805 | BJ19: =IF(BI19>=BI18,BI19-BI18,0) -> 0 | BK19: 21967195 | BL19: =IF(BK19>=BK18,BK19-BK18,0)-(0.45*BR19)-(0.45*BT19)-BV19 -> 4674.65 | BM19: =AT19+AV19+AX19+AZ19+BB19+BD19+BF19+BH19+BJ19+BL19 -> 9162.3786 | BN19: =BM19+AR19 -> 14089.826 | BO19: 1373276 | BP19: =IF(BO19>=BO18,BO19-BO18,0) -> 277 | BQ19: 3503738 | BR19: =IF(BQ19>=BQ18,BQ19-BQ18,0) -> 987 | BS19: 374249 | BT19: =IF(BS19>=BS18,BS19-BS18,0) -> 116 | BU19: 454817 | BV19: =IF(BU19>=BU18,BU19-BU18,0) -> 197 | BW19: =J19+Q19+AR19+BM19 -> 19758.826 | BX19: 68 | BY19: =IF(BW19>0,BW19/BX18,0) -> 365.90419 | CA19: =IF(BW19>0,BW19/BZ19,0) -> #DIV/0! | CB19: =BW19*CD1 -> 22722.65 | CC19: =IF(CB19>0,CB19/BX18,0) -> 420.78982 | CD19: =IF(CB19>0,CB19/BZ19,0) -> #DIV/0!
