Workbook

Sheet Total
A1: Site Name | B1: Day | C1: Month | D1: Year | E1: Total Electricity Kwh | F1: Electricity Tariff ($/Kwh) | G1: Natual Gas (m3) | H1: Natural Gas $/m3 | I1: Water Utility Supply (m3) m3 | J1: Water Utility Supply (m3) $/m3 | K1: Room Nights
A2: Cairo at The First Residence | B2: 1 | C2: 8 | D2: 2021 | E2: 37967.61 | F2: 1.32 | G2: =879.8+233.93 -> 1113.73 | H2: 3.89 | I2: 492.1 | J2: 10 | K2: 164
A3: Cairo at The First Residence | B3: =B2+1 -> 2 | C3: 8 | D3: 2021 | E3: 37967.61 | F3: =F2 -> 1.32 | G3: =879.8+233.93 -> 1113.73 | H3: 3.89 | I3: 492.1 | J3: 10 | K3: 164
A4: Cairo at The First Residence | B4: =B3+1 -> 3 | C4: 8 | D4: 2021 | E4: 37967.61 | F4: =F3 -> 1.32 | G4: =879.8+233.93 -> 1113.73 | H4: 3.89 | I4: 492.1 | J4: 10 | K4: 164
A5: Cairo at The First Residence | B5: =B4+1 -> 4 | C5: 8 | D5: 2021 | E5: 37967.61 | F5: =F4 -> 1.32 | G5: =879.8+233.93 -> 1113.73 | H5: 3.89 | I5: 492.1 | J5: 10 | K5: 164
A6: Cairo at The First Residence | B6: =B5+1 -> 5 | C6: 8 | D6: 2021 | E6: 37967.61 | F6: =F5 -> 1.32 | G6: =879.8+233.93 -> 1113.73 | H6: 3.89 | I6: 492.1 | J6: 10 | K6: 164
A7: Cairo at The First Residence | B7: =B6+1 -> 6 | C7: 8 | D7: 2021 | E7: 37967.61 | F7: =F6 -> 1.32 | G7: =879.8+233.93 -> 1113.73 | H7: 3.89 | I7: 492.1 | J7: 10 | K7: 164
A8: Cairo at The First Residence | B8: =B7+1 -> 7 | C8: 8 | D8: 2021 | E8: 37967.61 | F8: =F7 -> 1.32 | G8: =879.8+233.93 -> 1113.73 | H8: 3.89 | I8: 492.1 | J8: 10 | K8: 164
A9: Cairo at The First Residence | B9: =B8+1 -> 8 | C9: 8 | D9: 2021 | E9: 37967.61 | F9: =F8 -> 1.32 | G9: =879.8+233.93 -> 1113.73 | H9: 3.89 | I9: 492.1 | J9: 10 | K9: 164
A10: Cairo at The First Residence | B10: =B9+1 -> 9 | C10: 8 | D10: 2021 | E10: 37967.61 | F10: =F9 -> 1.32 | G10: =879.8+233.93 -> 1113.73 | H10: 3.89 | I10: 492.1 | J10: 10 | K10: 164
A11: Cairo at The First Residence | B11: =B10+1 -> 10 | C11: 8 | D11: 2021 | E11: 37967.61 | F11: =F10 -> 1.32 | G11: =879.8+233.93 -> 1113.73 | H11: 3.89 | I11: 492.1 | J11: 10 | K11: 164
A12: Cairo at The First Residence | B12: =B11+1 -> 11 | C12: 8 | D12: 2021 | E12: 37967.61 | F12: =F11 -> 1.32 | G12: =879.8+233.93 -> 1113.73 | H12: 3.89 | I12: 492.1 | J12: 10 | K12: 164
A13: Cairo at The First Residence | B13: =B12+1 -> 12 | C13: 8 | D13: 2021 | E13: 37967.61 | F13: =F12 -> 1.32 | G13: =879.8+233.93 -> 1113.73 | H13: 3.89 | I13: 492.1 | J13: 10 | K13: 164
A14: Cairo at The First Residence | B14: =B13+1 -> 13 | C14: 8 | D14: 2021 | E14: 37967.61 | F14: =F13 -> 1.32 | G14: =879.8+233.93 -> 1113.73 | H14: 3.89 | I14: 492.1 | J14: 10 | K14: 164
... A32: Cairo at The First Residence | B32: =B31+1 -> 31 | C32: 8 | D32: 2021 | E32: 37967.61 | F32: =F31 -> 1.32 | G32: =879.8+233.93 -> 1113.73 | H32: 3.89 | I32: 492.1 | J32: 10 | K32: 164

Sheet Submetering
A1: Site Name | B1: Day | C1: Month | D1: Year | E1: Electricity | F1: Main Feeder -KWh | G1: T2+T8 -KWh | H1: La Gourmandize -KWh | I1: Casino 3rd floor EM -KWh | J1: Casino 3rd floor Normal -KWh | K1: Chiller 1 -KWh | L1: Chiller 2 -KWh | M1: Chiller 3 -KWh | N1: Chiller 4 -KWh | O1: Chiller 5 -KWh | P1: Chiller 6 -KWh | Q1: Cooling towers -KWh | R1: Chiller Pumps -KWh | S1: Cooling Tower Pumps -KWh | T1: Fiber Chiller -KWh | U1: Mall Ceiling light -KWh | V1: LG Bakery -KWh | W1: LG Bakery light ( Old lockers ) -KWh | X1: MCCR1 -KWh | Y1: Children Swimming Pool -KWh | Z1: DPH1 -KWh | AA1: Guest Rooms Emerg. -KWh | AB1: Hotel Hoods -KWh | AC1: Main G2 -KWh | AD1: Old Casino Emergency -KWh | AE1: L / A -KWh | AF1: L / B -KWh | AG1: L / C -KWh | AH1: Water | AI1: Main water meter 1 -m3 | AJ1: Main water meter 2 -m3 | AK1: Main water meter 3 -m3 | AL1: Gas | AM1: Main Gas Flow Meter -m3 | AN1: Laundry Gas Flow Meter -m3 | AO1: Gourmandize Gas Flow Meter -m3 | AP1: Room Nights
A2: Cairo at The First Residence | B2: 1 | C2: 8 | D2: 2021 | F2: =Elect!J6 -> 9836 | G2: =Elect!K6 -> 3372 | H2: =Elect!Q6 -> 630 | I2: =Elect!S6 -> 412 | J2: =Elect!U6 -> 836 | K2: =Elect!W6 -> 6157.328 | L2: =Elect!Y6 -> 5469.07 | M2: =Elect!AA6 -> 0 | N2: =Elect!AC6 -> 42.4 | O2: =Elect!AE6 -> 2889.03 | P2: =Elect!AG6 -> 0 | Q2: =Elect!AI6 -> 1463.86 | R2: =Elect!AK6 -> 5512.53 | S2: =Elect!AM6 -> 212 | T2: =Elect!AP6 -> 221.9625 | U2: =Elect!AR6 -> 256 | V2: =Elect!AT6 -> 246 | W2: =Elect!AV6 -> 21 | X2: =Elect!AX6 -> 1341 | Y2: =Elect!AZ6 -> 0 | Z2: =Elect!BB6 -> 5908 | AA2: =Elect!BD6 -> 232 | AB2: =Elect!BF6 -> 137 | AC2: =Elect!BH6 -> 5937.25 | AD2: =Elect!BL6 -> 0 | AE2: =Elect!BN6 -> 1264 | AF2: =Elect!BP6 -> 131 | AG2: =Elect!BR6 -> 226 | AI2: =Water!C7 -> 0 | AJ2: =Water!E7 -> 423.4 | AK2: =Water!G7 -> 143.26 | AM2: =Gas!C7 -> 921.14 | AN2: =Gas!E7 -> 209.3 | AO2: =Gas!G7 -> 100 | AP2: 164
A3: Cairo at The First Residence | B3: =B2+1 -> 2 | C3: 8 | D3: 2021 | F3: =Elect!J7 -> 5216 | G3: =Elect!K7 -> 3379 | H3: =Elect!Q7 -> 450 | I3: =Elect!S7 -> 137 | J3: =Elect!U7 -> 271 | K3: =Elect!W7 -> 3504.36 | L3: =Elect!Y7 -> 4021.11 | M3: =Elect!AA7 -> 0 | N3: =Elect!AC7 -> 0 | O3: =Elect!AE7 -> 1864.54 | P3: =Elect!AG7 -> 9.54 | Q3: =Elect!AI7 -> 1115.12 | R3: =Elect!AK7 -> 3659.65 | S3: =Elect!AM7 -> 171.72 | T3: =Elect!AP7 -> 209.025 | U3: =Elect!AR7 -> 296 | V3: =Elect!AT7 -> 186 | W3: =Elect!AV7 -> 68 | X3: =Elect!AX7 -> 1059 | Y3: =Elect!AZ7 -> 12 | Z3: =Elect!BB7 -> 5007 | AA3: =Elect!BD7 -> 202 | AB3: =Elect!BF7 -> 151 | AC3: =Elect!BH7 -> 5832.1 | AD3: =Elect!BL7 -> 4 | AE3: =Elect!BN7 -> 1623 | AF3: =Elect!BP7 -> 119 | AG3: =Elect!BR7 -> 208 | AI3: =Water!C8 -> 0 | AJ3: =Water!E8 -> 516.2 | AK3: =Water!G8 -> 131.08 | AM3: =Gas!C8 -> 820.44 | AN3: =Gas!E8 -> 228.2 | AO3: =Gas!G8 -> 96 | AP3: 164
A4: Cairo at The First Residence | B4: =B3+1 -> 3 | C4: 8 | D4: 2021 | F4: =Elect!J8 -> 5430 | G4: =Elect!K8 -> 3481 | H4: =Elect!Q8 -> 600 | I4: =Elect!S8 -> 140 | J4: =Elect!U8 -> 265 | K4: =Elect!W8 -> 3673.43 | L4: =Elect!Y8 -> 4134.53 | M4: =Elect!AA8 -> 0 | N4: =Elect!AC8 -> 0 | O4: =Elect!AE8 -> 1849.7 | P4: =Elect!AG8 -> 81.09 | Q4: =Elect!AI8 -> 1142.15 | R4: =Elect!AK8 -> 3816.53 | S4: =Elect!AM8 -> 173.84 | T4: =Elect!AP8 -> 223.425 | U4: =Elect!AR8 -> 198 | V4: =Elect!AT8 -> 197 | W4: =Elect!AV8 -> 75 | X4: =Elect!AX8 -> 1106 | Y4: =Elect!AZ8 -> 17 | Z4: =Elect!BB8 -> 4909 | AA4: =Elect!BD8 -> 206 | AB4: =Elect!BF8 -> 129 | AC4: =Elect!BH8 -> 6001.6 | AD4: =Elect!BL8 -> 59 | AE4: =Elect!BN8 -> 1698 | AF4: =Elect!BP8 -> 114 | AG4: =Elect!BR8 -> 212 | AI4: =Water!C9 -> 0 | AJ4: =Water!E9 -> 516.2 | AK4: =Water!G9 -> 130.5 | AM4: =Gas!C9 -> 737.76 | AN4: =Gas!E9 -> 228.9 | AO4: =Gas!G9 -> 96 | AP4: 164
A5: Cairo at The First Residence | B5: =B4+1 -> 4 | C5: 8 | D5: 2021 | F5: =Elect!J9 -> 5586 | G5: =Elect!K9 -> 3484 | H5: =Elect!Q9 -> 720 | I5: =Elect!S9 -> 137 | J5: =Elect!U9 -> 270 | K5: =Elect!W9 -> 3703.11 | L5: =Elect!Y9 -> 4043.37 | M5: =Elect!AA9 -> 0 | N5: =Elect!AC9 -> 0 | O5: =Elect!AE9 -> 1629.22 | P5: =Elect!AG9 -> 427.71 | Q5: =Elect!AI9 -> 1114.06 | R5: =Elect!AK9 -> 3735.44 | S5: =Elect!AM9 -> 173.31 | T5: =Elect!AP9 -> 203.85 | U5: =Elect!AR9 -> 215 | V5: =Elect!AT9 -> 183 | W5: =Elect!AV9 -> 75 | X5: =Elect!AX9 -> 1073 | Y5: =Elect!AZ9 -> 17 | Z5: =Elect!BB9 -> 5446 | AA5: =Elect!BD9 -> 239 | AB5: =Elect!BF9 -> 57 | AC5: =Elect!BH9 -> 5962.1 | AD5: =Elect!BL9 -> 57 | AE5: =Elect!BN9 -> 1792 | AF5: =Elect!BP9 -> 110 | AG5: =Elect!BR9 -> 205 | AI5: =Water!C10 -> 0 | AJ5: =Water!E10 -> 806.2 | AK5: =Water!G10 -> 131.08 | AM5: =Gas!C10 -> 815.14 | AN5: =Gas!E10 -> 228.9 | AO5: =Gas!G10 -> 95 | AP5: 164
A6: Cairo at The First Residence | B6: =B5+1 -> 5 | C6: 8 | D6: 2021 | F6: =Elect!J10 -> 5913 | G6: =Elect!K10 -> 3689 | H6: =Elect!Q10 -> 510 | I6: =Elect!S10 -> 141 | J6: =Elect!U10 -> 290 | K6: =Elect!W10 -> 3518.67 | L6: =Elect!Y10 -> 4100.08 | M6: =Elect!AA10 -> 0 | N6: =Elect!AC10 -> 0 | O6: =Elect!AE10 -> 1831.68 | P6: =Elect!AG10 -> 11.13 | Q6: =Elect!AI10 -> 1147.98 | R6: =Elect!AK10 -> 3773.6 | S6: =Elect!AM10 -> 177.55 | T6: =Elect!AP10 -> 200.7 | U6: =Elect!AR10 -> 213 | V6: =Elect!AT10 -> 200 | W6: =Elect!AV10 -> 76 | X6: =Elect!AX10 -> 1106 | Y6: =Elect!AZ10 -> 47 | Z6: =Elect!BB10 -> 4758 | AA6: =Elect!BD10 -> 246 | AB6: =Elect!BF10 -> 206 | AC6: =Elect!BH10 -> 6135.75 | AD6: =Elect!BL10 -> 60 | AE6: =Elect!BN10 -> 1718 | AF6: =Elect!BP10 -> 127 | AG6: =Elect!BR10 -> 211 | AI6: =Water!C11 -> 0 | AJ6: =Water!E11 -> 922.2 | AK6: =Water!G11 -> 91.64 | AM6: =Gas!C11 -> 754.72 | AN6: =Gas!E11 -> 230.3 | AO6: =Gas!G11 -> 96 | AP6: 164
A7: Cairo at The First Residence | B7: =B6+1 -> 6 | C7: 8 | D7: 2021 | F7: =Elect!J11 -> 5933 | G7: =Elect!K11 -> 3687 | H7: =Elect!Q11 -> 600 | I7: =Elect!S11 -> 137 | J7: =Elect!U11 -> 283 | K7: =Elect!W11 -> 3864.76 | L7: =Elect!Y11 -> 4085.24 | M7: =Elect!AA11 -> 0 | N7: =Elect!AC11 -> 0 | O7: =Elect!AE11 -> 1857.65 | P7: =Elect!AG11 -> 10.07 | Q7: =Elect!AI11 -> 1123.6 | R7: =Elect!AK11 -> 3394.65 | S7: =Elect!AM11 -> 177.02 | T7: =Elect!AP11 -> 202.8375 | U7: =Elect!AR11 -> 181 | V7: =Elect!AT11 -> 195 | W7: =Elect!AV11 -> 35 | X7: =Elect!AX11 -> 1136 | Y7: =Elect!AZ11 -> 52 | Z7: =Elect!BB11 -> 5302 | AA7: =Elect!BD11 -> 215 | AB7: =Elect!BF11 -> 120 | AC7: =Elect!BH11 -> 5915.9 | AD7: =Elect!BL11 -> 57 | AE7: =Elect!BN11 -> 1628 | AF7: =Elect!BP11 -> 110 | AG7: =Elect!BR11 -> 200 | AI7: =Water!C12 -> 0 | AJ7: =Water!E12 -> 440.8 | AK7: =Water!G12 -> 102.66 | AM7: =Gas!C12 -> 189.74 | AN7: =Gas!E12 -> 227.5 | AO7: =Gas!G12 -> 93 | AP7: 164
A8: Cairo at The First Residence | B8: =B7+1 -> 7 | C8: 8 | D8: 2021 | F8: =Elect!J12 -> 5895 | G8: =Elect!K12 -> 3550 | H8: =Elect!Q12 -> 600 | I8: =Elect!S12 -> 141 | J8: =Elect!U12 -> 286 | K8: =Elect!W12 -> 3815.47 | L8: =Elect!Y12 -> 1369.52 | M8: =Elect!AA12 -> 2816.95 | N8: =Elect!AC12 -> 15.37 | O8: =Elect!AE12 -> 1905.88 | P8: =Elect!AG12 -> 10.6 | Q8: =Elect!AI12 -> 1167.59 | R8: =Elect!AK12 -> 4259.61 | S8: =Elect!AM12 -> 181.26 | T8: =Elect!AP12 -> 202.05 | U8: =Elect!AR12 -> 172 | V8: =Elect!AT12 -> 209 | W8: =Elect!AV12 -> 43 | X8: =Elect!AX12 -> 1137 | Y8: =Elect!AZ12 -> 78 | Z8: =Elect!BB12 -> 4719 | AA8: =Elect!BD12 -> 247 | AB8: =Elect!BF12 -> 22 | AC8: =Elect!BH12 -> 6032.4 | AD8: =Elect!BL12 -> 60 | AE8: =Elect!BN12 -> 1808 | AF8: =Elect!BP12 -> 120 | AG8: =Elect!BR12 -> 194 | AI8: =Water!C13 -> 0 | AJ8: =Water!E13 -> 440.8 | AK8: =Water!G13 -> 93.96 | AM8: =Gas!C13 -> 912.66 | AN8: =Gas!E13 -> 226.1 | AO8: =Gas!G13 -> 99.666667 | AP8: 164
A9: Cairo at The First Residence | B9: =B8+1 -> 8 | C9: 8 | D9: 2021 | F9: =Elect!J13 -> 5447 | G9: =Elect!K13 -> 3338 | H9: =Elect!Q13 -> 750 | I9: =Elect!S13 -> 138 | J9: =Elect!U13 -> 269 | K9: =Elect!W13 -> 4253.78 | L9: =Elect!Y13 -> 0 | M9: =Elect!AA13 -> 3816.53 | N9: =Elect!AC13 -> 0 | O9: =Elect!AE13 -> 1836.98 | P9: =Elect!AG13 -> 9.54 | Q9: =Elect!AI13 -> 1091.27 | R9: =Elect!AK13 -> 3774.13 | S9: =Elect!AM13 -> 171.19 | T9: =Elect!AP13 -> 190.4625 | U9: =Elect!AR13 -> 165 | V9: =Elect!AT13 -> 183 | W9: =Elect!AV13 -> 78 | X9: =Elect!AX13 -> 1042 | Y9: =Elect!AZ13 -> 75 | Z9: =Elect!BB13 -> 4795 | AA9: =Elect!BD13 -> 218 | AB9: =Elect!BF13 -> 299 | AC9: =Elect!BH13 -> 5786.65 | AD9: =Elect!BL13 -> 59 | AE9: =Elect!BN13 -> 1745 | AF9: =Elect!BP13 -> 118 | AG9: =Elect!BR13 -> 210 | AI9: =Water!C14 -> 0 | AJ9: =Water!E14 -> 562.6 | AK9: =Water!G14 -> 132.24 | AM9: =Gas!C14 -> 877.68 | AN9: =Gas!E14 -> 231 | AO9: =Gas!G14 -> 104.33333 | AP9: 164
A10: Cairo at The First Residence | B10: =B9+1 -> 9 | C10: 8 | D10: 2021 | F10: =Elect!J14 -> 5774 | G10: =Elect!K14 -> 3512 | H10: =Elect!Q14 -> 600 | I10: =Elect!S14 -> 138 | J10: =Elect!U14 -> 266 | K10: =Elect!W14 -> 3834.55 | L10: =Elect!Y14 -> 1965.24 | M10: =Elect!AA14 -> 2265.22 | N10: =Elect!AC14 -> 0 | O10: =Elect!AE14 -> 1893.16 | P10: =Elect!AG14 -> 10.6 | Q10: =Elect!AI14 -> 1117.77 | R10: =Elect!AK14 -> 4255.9 | S10: =Elect!AM14 -> 174.37 | T10: =Elect!AP14 -> 200.7 | U10: =Elect!AR14 -> 169 | V10: =Elect!AT14 -> 179 | W10: =Elect!AV14 -> 55 | X10: =Elect!AX14 -> 1072 | Y10: =Elect!AZ14 -> 76 | Z10: =Elect!BB14 -> 4651 | AA10: =Elect!BD14 -> 209 | AB10: =Elect!BF14 -> 73 | AC10: =Elect!BH14 -> 5906.8 | AD10: =Elect!BL14 -> 58 | AE10: =Elect!BN14 -> 1769 | AF10: =Elect!BP14 -> 107 | AG10: =Elect!BR14 -> 208 | AI10: =Water!C15 -> 0 | AJ10: =Water!E15 -> 522 | AK10: =Water!G15 -> 155.44 | AM10: =Gas!C15 -> 610.56 | AN10: =Gas!E15 -> 230.3 | AO10: =Gas!G15 -> 91 | AP10: 164
A11: Cairo at The First Residence | B11: =B10+1 -> 10 | C11: 8 | D11: 2021 | F11: =Elect!J15 -> 5674 | G11: =Elect!K15 -> 3674 | H11: =Elect!Q15 -> 600 | I11: =Elect!S15 -> 140 | J11: =Elect!U15 -> 274 | K11: =Elect!W15 -> 4223.04 | L11: =Elect!Y15 -> 3093.08 | M11: =Elect!AA15 -> 1383.83 | N11: =Elect!AC15 -> 39.75 | O11: =Elect!AE15 -> 1968.42 | P11: =Elect!AG15 -> 10.07 | Q11: =Elect!AI15 -> 1164.94 | R11: =Elect!AK15 -> 4393.7 | S11: =Elect!AM15 -> 181.26 | T11: =Elect!AP15 -> 209.8125 | U11: =Elect!AR15 -> 165 | V11: =Elect!AT15 -> 179 | W11: =Elect!AV15 -> 69 | X11: =Elect!AX15 -> 1165 | Y11: =Elect!AZ15 -> 74 | Z11: =Elect!BB15 -> 4700 | AA11: =Elect!BD15 -> 226 | AB11: =Elect!BF15 -> 124 | AC11: =Elect!BH15 -> 6314.6 | AD11: =Elect!BL15 -> 52 | AE11: =Elect!BN15 -> 1822 | AF11: =Elect!BP15 -> 110 | AG11: =Elect!BR15 -> 218 | AI11: =Water!C16 -> 0 | AJ11: =Water!E16 -> 458.2 | AK11: =Water!G16 -> 43.5 | AM11: =Gas!C16 -> 700.66 | AN11: =Gas!E16 -> 221.2 | AO11: =Gas!G16 -> 91 | AP11: 164
A12: Cairo at The First Residence | B12: =B11+1 -> 11 | C12: 8 | D12: 2021 | F12: =Elect!J16 -> 5894 | G12: =Elect!K16 -> 3856 | H12: =Elect!Q16 -> 630 | I12: =Elect!S16 -> 141 | J12: =Elect!U16 -> 281 | K12: =Elect!W16 -> 4364.55 | L12: =Elect!Y16 -> 4208.2 | M12: =Elect!AA16 -> 115.01 | N12: =Elect!AC16 -> 0 | O12: =Elect!AE16 -> 1839.63 | P12: =Elect!AG16 -> 10.07 | Q12: =Elect!AI16 -> 1166.53 | R12: =Elect!AK16 -> 4200.25 | S12: =Elect!AM16 -> 179.14 | T12: =Elect!AP16 -> 160.3125 | U12: =Elect!AR16 -> 170 | V12: =Elect!AT16 -> 172 | W12: =Elect!AV16 -> 86 | X12: =Elect!AX16 -> 1188 | Y12: =Elect!AZ16 -> 75 | Z12: =Elect!BB16 -> 4883 | AA12: =Elect!BD16 -> 211 | AB12: =Elect!BF16 -> 95 | AC12: =Elect!BH16 -> 5906.4 | AD12: =Elect!BL16 -> 74 | AE12: =Elect!BN16 -> 1677 | AF12: =Elect!BP16 -> 111 | AG12: =Elect!BR16 -> 205 | AI12: =Water!C17 -> 0 | AJ12: =Water!E17 -> 493 | AK12: =Water!G17 -> 19.14 | AM12: =Gas!C17 -> 700.66 | AN12: =Gas!E17 -> 233.1 | AO12: =Gas!G17 -> 91 | AP12: 164
A13: Cairo at The First Residence | B13: =B12+1 -> 12 | C13: 8 | D13: 2021 | F13: =Elect!J17 -> 5756 | G13: =Elect!K17 -> 3440 | H13: =Elect!Q17 -> 630 | I13: =Elect!S17 -> 143 | J13: =Elect!U17 -> 280 | K13: =Elect!W17 -> 4094.25 | L13: =Elect!Y17 -> 1163.88 | M13: =Elect!AA17 -> 2725.79 | N13: =Elect!AC17 -> 0 | O13: =Elect!AE17 -> 1895.81 | P13: =Elect!AG17 -> 10.07 | Q13: =Elect!AI17 -> 1067.42 | R13: =Elect!AK17 -> 3846.21 | S13: =Elect!AM17 -> 165.89 | T13: =Elect!AP17 -> 193.95 | U13: =Elect!AR17 -> 169 | V13: =Elect!AT17 -> 159 | W13: =Elect!AV17 -> 46 | X13: =Elect!AX17 -> 1102 | Y13: =Elect!AZ17 -> 64 | Z13: =Elect!BB17 -> 5084 | AA13: =Elect!BD17 -> 217 | AB13: =Elect!BF17 -> 108 | AC13: =Elect!BH17 -> 6123.6 | AD13: =Elect!BL17 -> 88 | AE13: =Elect!BN17 -> 1756 | AF13: =Elect!BP17 -> 116 | AG13: =Elect!BR17 -> 211 | AI13: =Water!C18 -> 0 | AJ13: =Water!E18 -> 493 | AK13: =Water!G18 -> 44.08 | AM13: =Gas!C18 -> 700.66 | AN13: =Gas!E18 -> 228.2 | AO13: =Gas!G18 -> 91 | AP13: 164
A14: Cairo at The First Residence | B14: =B13+1 -> 13 | C14: 8 | D14: 2021 | F14: =Elect!J18 -> 5391 | G14: =Elect!K18 -> 3373 | H14: =Elect!Q18 -> 630 | I14: =Elect!S18 -> 134 | J14: =Elect!U18 -> 259 | K14: =Elect!W18 -> 4095.31 | L14: =Elect!Y18 -> 2153.92 | M14: =Elect!AA18 -> 1769.14 | N14: =Elect!AC18 -> 0 | O14: =Elect!AE18 -> 1820.55 | P14: =Elect!AG18 -> 10.07 | Q14: =Elect!AI18 -> 1069.01 | R14: =Elect!AK18 -> 3898.15 | S14: =Elect!AM18 -> 166.95 | T14: =Elect!AP18 -> 214.2 | U14: =Elect!AR18 -> 173 | V14: =Elect!AT18 -> 162 | W14: =Elect!AV18 -> 38 | X14: =Elect!AX18 -> 1107 | Y14: =Elect!AZ18 -> 55 | Z14: =Elect!BB18 -> 4412 | AA14: =Elect!BD18 -> 195 | AB14: =Elect!BF18 -> 53 | AC14: =Elect!BH18 -> 5937.5 | AD14: =Elect!BL18 -> 73 | AE14: =Elect!BN18 -> 1668 | AF14: =Elect!BP18 -> 102 | AG14: =Elect!BR18 -> 201 | AI14: =Water!C19 -> 0 | AJ14: =Water!E19 -> 493 | AK14: =Water!G19 -> 5.8 | AM14: =Gas!C19 -> 699.6 | AN14: =Gas!E19 -> 224 | AO14: =Gas!G19 -> 91 | AP14: 164
... A32: Cairo at The First Residence | B32: =B31+1 -> 31 | C32: 8 | D32: 2021 | F32: =Elect!J36 -> 5520 | G32: =Elect!K36 -> 3012 | H32: =Elect!Q36 -> 630 | I32: =Elect!S36 -> 148 | J32: =Elect!U36 -> 232 | K32: =Elect!W36 -> 2931.96 | L32: =Elect!Y36 -> 3971.29 | M32: =Elect!AA36 -> 0 | N32: =Elect!AC36 -> 0 | O32: =Elect!AE36 -> 1836.45 | P32: =Elect!AG36 -> 11.66 | Q32: =Elect!AI36 -> 1025.02 | R32: =Elect!AK36 -> 3897.09 | S32: =Elect!AM36 -> 152.64 | T32: =Elect!AP36 -> 161.8875 | U32: =Elect!AR36 -> 239 | V32: =Elect!AT36 -> 192 | W32: =Elect!AV36 -> 52 | X32: =Elect!AX36 -> 1005 | Y32: =Elect!AZ36 -> 34 | Z32: =Elect!BB36 -> 4533 | AA32: =Elect!BD36 -> 197 | AB32: =Elect!BF36 -> 54 | AC32: =Elect!BH36 -> 7114.35 | AD32: =Elect!BL36 -> 291 | AE32: =Elect!BN36 -> 1313 | AF32: =Elect!BP36 -> 84 | AG32: =Elect!BR36 -> 137 | AI32: =Water!C37 -> 0 | AJ32: =Water!E37 -> 5.8 | AK32: =Water!G37 -> 0 | AM32: =Gas!C37 -> 785.46 | AN32: =Gas!E37 -> 225.4 | AO32: =Gas!G37 -> 94 | AP32: 164

Sheet Elect
A1: August | M1: Electricity | BP1: Gourmandise UP | BR1: 1.6 | BS1: Power Taxes | BU1: Max Demand | BW1: 500 | BX1: Electricity UP | BZ1: 1.15
AD2: Chiller 5 Meter was miswired and was corrected on 21st | BJ2: =SUM(BJ27:BJ36) -> 277001.82 | BS2: Light Taxes | BU2: PF Penalty | BX2: Max. Demand UP | BZ2: 30
A3: Date | B3: COUNTER (1) | D3: MD | F3: KVAR | H3: n | I3: Guest Rooms Consumption | R3: Casino Consumption | V3: Plant Room Shared Loads | AO3: To Be Charged By First Arabian | BK3: From Main Panel G2 | BS3: Total Consumption. | BT3: No. Of | BU3: KWH/ | BV3: No. Of | BW3: KWH/ | BX3: Total Cost | BY3: L.E\ | BZ3: L.E\
B4: Reading | C4: Consp. F: *800 | D4: Reading | E4: Consp F: 80 | F4: Reading | G4: Consp. F:*10 | I4: Main Feeder | J4: Consp | K4: T2+T8 | L4: Trans T2 | M4: Consp | N4: Trans T8 | O4: Consp | P4: La Gourmandize | Q4: Consp *30 | R4: Casino 3rd floor EM | S4: Consp | T4: Casino 3rd floor Normal | U4: Consp | V4: Chiller 1 | W4: Consp 53% | X4: Chiller 2 | Y4: Consp 53% | Z4: Chiller 3 | AA4: Consp 53% | AB4: Chiller 4 | AC4: Consp 53% | AD4: Chiller 5 | AE4: Consp 53% | AF4: Chiller 6 | AG4: Consp 53% | AH4: Cooling Towers | AI4: Consp 53% | AJ4: Chiller Pumps | AK4: Consp 53% | AL4: Cooling Tower Pumps | AM4: Consp 53% | AN4: Total Plant Room Consp | AO4: Fiber Chiller (N24) | AP4: Consp | AQ4: Mall Ceiling light (N4) | AR4: Consp | AS4: LG Bakery (N2) | AT4: Consp | AU4: LG Bakery light ( Old lockers ) | AV4: Consp | AW4: MCCR1 | AX4: Consp | AY4: Children Swimming pool | AZ4: Consp | BA4: DPH1 | BB4: Consp | BC4: Guest Rooms Emergency | BD4: Consp | BE4: Hotel Hoods | BF4: Consp | BG4: Main G2 | BH4: Consp | BI4: Total Consp From First Arabian | BJ4: First Arabian Charge Back | BK4: Old Casino Emergency | BL4: Consp | BM4: L / A | BN4: Consp | BO4: L / B | BP4: Consp | BQ4: L / C | BR4: Consp | BT4: Rooms | BU4: room | BV4: guest | BW4: guest | BY4: Room | BZ4: Guest
A5: Last Month Reading | I5: 22912342 | J5: =IF(I5>=I4,I5-I4,0) -> 0 | K5: =M5+O5 -> 0 | L5: 276660 | M5: =IF(L5>=L4,L5-L4,0) -> 0 | N5: 275186 | O5: =IF(N5>=N4,N5-N4,0) -> 0 | P5: 218214 | Q5: =IF(P5>=P4,P5-P4,0)*30 -> 0 | R5: 156363 | S5: =IF(R5>=R4,R5-R4,0) -> 0 | T5: 284891 | U5: =IF(T5>=T4,T5-T4,0) -> 0 | V5: 74714.4 | W5: =IF(V5>=V4,V5-V4,0)*0.53 -> 0 | X5: 656436 | Y5: =IF(X5>=X4,X5-X4,0)*0.53 -> 0 | Z5: 812070 | AA5: =IF(Z5>=Z4,Z5-Z4,0)*0.53 -> 0 | AB5: 384369 | AC5: =IF(AB5>=AB4,AB5-AB4,0)*0.53 -> 0 | AD5: 444403 | AE5: =IF(AD5>=AD4,AD5-AD4,0)*0.53 -> 0 | AF5: 828640 | AG5: =IF(AF5>=AF4,AF5-AF4,0)*0.53 -> 0 | AH5: 773964 | AI5: =IF(AH5>=AH4,AH5-AH4,0)*0.53 -> 0 | AJ5: 714100 | AK5: =IF(AJ5>=AJ4,AJ5-AJ4,0)*0.53 -> 0 | AL5: 437279 | AM5: =IF(AL5>=AL4,AL5-AL4,0)*0.53 -> 0 | AN5: =W5+Y5+AA5+AC5+AE5+AG5+AI5+AK5+AM5 -> 0 | AO5: 7423402 | AP5: =IF(AO5>=AO4,AO5-AO4,0)*0.1125 -> 0 | AQ5: 625376 | AR5: =IF(AQ5>=AQ4,AQ5-AQ4,0) -> 0 | AS5: 937331 | AT5: =IF(AS5>=AS4,AS5-AS4,0) -> 0 | AU5: 801963 | AV5: =IF(AU5>=AU4,AU5-AU4,0) -> 0 | AW5: 2465053 | AX5: =IF(AW5>=AW4,AW5-AW4,0) -> 0 | AY5: 219380 | AZ5: =IF(AY5>=AY4,AY5-AY4,0) -> 0 | BA5: 18406250 | BB5: =IF(BA5>=BA4,BA5-BA4,0) -> 0 | BC5: 523872 | BD5: =IF(BC5>=BC4,BC5-BC4,0) -> 0 | BE5: 16072 | BF5: =IF(BE5>=BE4,BE5-BE4,0) -> 0 | BG5: 22977793 | BH5: =IF(BG5>=BG4,BG5-BG4,0)-(0.45*BN5)-(0.45*BP5)-BR5 -> 0 | BI5: =AP5+AR5+AT5+AV5+AX5+AZ5+BB5+BD5+BF5+BH5 -> 0 | BJ5: =BI5+AN5 -> 0 | BK5: 1394789 | BL5: =IF(BK5>=BK4,BK5-BK4,0) -> 0 | BM5: 3706215 | BN5: =IF(BM5>=BM4,BM5-BM4,0) -> 0 | BO5: 392214 | BP5: =IF(BO5>=BO4,BO5-BO4,0) -> 0 | BQ5: 488874 | BR5: =IF(BQ5>=BQ4,BQ5-BQ4,0) -> 0
A6: 1 | C6: =IF(+B6-B5>0,B6-B5,(B6-B5)>0)*800 -> 0 | E6: =IF(+D6-D5>0,D6-D5,(D6-D5)>0)*80 -> 0 | G6: =IF(+F6-F5>0,F6-F5,(F6-F5)>0)*10 -> 0 | H6: 56 | I6: 22922178 | J6: =IF(I6>=I5,I6-I5,0) -> 9836 | K6: =M6+O6 -> 3372 | L6: 279129 | M6: =IF(L6>=L5,L6-L5,0) -> 2469 | N6: 276089 | O6: =IF(N6>=N5,N6-N5,0) -> 903 | P6: 218235 | Q6: =IF(P6>=P5,P6-P5,0)*30 -> 630 | R6: 156775 | S6: =IF(R6>=R5,R6-R5,0) -> 412 | T6: 285727 | U6: =IF(T6>=T5,T6-T5,0) -> 836 | V6: 86332 | W6: =IF(V6>=V5,V6-V5,0)*0.53 -> 6157.328 | X6: 666755 | Y6: =IF(X6>=X5,X6-X5,0)*0.53 -> 5469.07 | Z6: 812070 | AA6: =IF(Z6>=Z5,Z6-Z5,0)*0.53 -> 0 | AB6: 384449 | AC6: =IF(AB6>=AB5,AB6-AB5,0)*0.53 -> 42.4 | AD6: 449854 | AE6: =IF(AD6>=AD5,AD6-AD5,0)*0.53 -> 2889.03 | AF6: 828148 | AG6: =IF(AF6>=AF5,AF6-AF5,0)*0.53 -> 0 | AH6: 776726 | AI6: =IF(AH6>=AH5,AH6-AH5,0)*0.53 -> 1463.86 | AJ6: 724501 | AK6: =IF(AJ6>=AJ5,AJ6-AJ5,0)*0.53 -> 5512.53 | AL6: 437679 | AM6: =IF(AL6>=AL5,AL6-AL5,0)*0.53 -> 212 | AN6: =W6+Y6+AA6+AC6+AE6+AG6+AI6+AK6+AM6 -> 21746.218 | AO6: 7425375 | AP6: =IF(AO6>=AO5,AO6-AO5,0)*0.1125 -> 221.9625 | AQ6: 625632 | AR6: =IF(AQ6>=AQ5,AQ6-AQ5,0) -> 256 | AS6: 937577 | AT6: =IF(AS6>=AS5,AS6-AS5,0) -> 246 | AU6: 801984 | AV6: =IF(AU6>=AU5,AU6-AU5,0) -> 21 | AW6: 2466394 | AX6: =IF(AW6>=AW5,AW6-AW5,0) -> 1341 | AY6: 219380 | AZ6: =IF(AY6>=AY5,AY6-AY5,0) -> 0 | BA6: 18412158 | BB6: =IF(BA6>=BA5,BA6-BA5,0) -> 5908 | BC6: 524104 | BD6: =IF(BC6>=BC5,BC6-BC5,0) -> 232 | BE6: 16209 | BF6: =IF(BE6>=BE5,BE6-BE5,0) -> 137 | BG6: 22984584 | BH6: =IF(BG6>=BG5,BG6-BG5,0)-(0.45*BN6)-(0.45*BP6)-BR6 -> 5937.25 | BI6: =AP6+AR6+AT6+AV6+AX6+AZ6+BB6+BD6+BF6+BH6 -> 14300.212 | BJ6: =BI6+AN6 -> 36046.431 | BK6: 1394789 | BL6: =IF(BK6>=BK5,BK6-BK5,0) -> 0 | BM6: 3707479 | BN6: =IF(BM6>=BM5,BM6-BM5,0) -> 1264 | BO6: 392345 | BP6: =IF(BO6>=BO5,BO6-BO5,0) -> 131 | BQ6: 489100 | BR6: =IF(BQ6>=BQ5,BQ6-BQ5,0) -> 226 | BS6: =J6+Q6+AN6+BI6 -> 46512.431 | BT6: 177 | BU6: =IF(BS6>0,BS6/BT5,0) -> #DIV/0! | BW6: =IF(BS6>0,BS6/BV6,0) -> #DIV/0! | BX6: =((BS6-Q6)*$BZ$1)+(Q6*$BR$1) -> 53772.795 | BY6: =IF(BX6>0,BX6/BT5,0) -> #DIV/0! | BZ6: =IF(BX6>0,BX6/BV6,0) -> #DIV/0!
A7: 2 | I7: 22927394 | J7: =IF(I7>=I6,I7-I6,0) -> 5216 | K7: =M7+O7 -> 3379 | L7: 281166 | M7: =IF(L7>=L6,L7-L6,0) -> 2037 | N7: 277431 | O7: =IF(N7>=N6,N7-N6,0) -> 1342 | P7: 218250 | Q7: =IF(P7>=P6,P7-P6,0)*30 -> 450 | R7: 156912 | S7: =IF(R7>=R6,R7-R6,0) -> 137 | T7: 285998 | U7: =IF(T7>=T6,T7-T6,0) -> 271 | V7: 92944 | W7: =IF(V7>=V6,V7-V6,0)*0.53 -> 3504.36 | X7: 674342 | Y7: =IF(X7>=X6,X7-X6,0)*0.53 -> 4021.11 | Z7: 812070 | AA7: =IF(Z7>=Z6,Z7-Z6,0)*0.53 -> 0 | AB7: 384449 | AC7: =IF(AB7>=AB6,AB7-AB6,0)*0.53 -> 0 | AD7: 453372 | AE7: =IF(AD7>=AD6,AD7-AD6,0)*0.53 -> 1864.54 | AF7: 828166 | AG7: =IF(AF7>=AF6,AF7-AF6,0)*0.53 -> 9.54 | AH7: 778830 | AI7: =IF(AH7>=AH6,AH7-AH6,0)*0.53 -> 1115.12 | AJ7: 731406 | AK7: =IF(AJ7>=AJ6,AJ7-AJ6,0)*0.53 -> 3659.65 | AL7: 438003 | AM7: =IF(AL7>=AL6,AL7-AL6,0)*0.53 -> 171.72 | AN7: =W7+Y7+AA7+AC7+AE7+AG7+AI7+AK7+AM7 -> 14346.04 | AO7: 7427233 | AP7: =IF(AO7>=AO6,AO7-AO6,0)*0.1125 -> 209.025 | AQ7: 625928 | AR7: =IF(AQ7>=AQ6,AQ7-AQ6,0) -> 296 | AS7: 937763 | AT7: =IF(AS7>=AS6,AS7-AS6,0) -> 186 | AU7: 802052 | AV7: =IF(AU7>=AU6,AU7-AU6,0) -> 68 | AW7: 2467453 | AX7: =IF(AW7>=AW6,AW7-AW6,0) -> 1059 | AY7: 219392 | AZ7: =IF(AY7>=AY6,AY7-AY6,0) -> 12 | BA7: 18417165 | BB7: =IF(BA7>=BA6,BA7-BA6,0) -> 5007 | BC7: 524306 | BD7: =IF(BC7>=BC6,BC7-BC6,0) -> 202 | BE7: 16360 | BF7: =IF(BE7>=BE6,BE7-BE6,0) -> 151 | BG7: 22991408 | BH7: =IF(BG7>=BG6,BG7-BG6,0)-(0.45*BN7)-(0.45*BP7)-BR7 -> 5832.1 | BI7: =AP7+AR7+AT7+AV7+AX7+AZ7+BB7+BD7+BF7+BH7 -> 13022.125 | BJ7: =BI7+AN7 -> 27368.165 | BK7: 1394793 | BL7: =IF(BK7>=BK6,BK7-BK6,0) -> 4 | BM7: 3709102 | BN7: =IF(BM7>=BM6,BM7-BM6,0) -> 1623 | BO7: 392464 | BP7: =IF(BO7>=BO6,BO7-BO6,0) -> 119 | BQ7: 489308 | BR7: =IF(BQ7>=BQ6,BQ7-BQ6,0) -> 208 | BS7: =J7+Q7+AN7+BI7 -> 33034.165 | BT7: 212 | BU7: =IF(BS7>0,BS7/BT6,0) -> 186.6337 | BW7: =IF(BS7>0,BS7/BV7,0) -> #DIV/0! | BX7: =((BS7-Q7)*$BZ$1)+(Q7*$BR$1) -> 38191.79 | BY7: =IF(BX7>0,BX7/BT6,0) -> 215.77282 | BZ7: =IF(BX7>0,BX7/BV7,0) -> #DIV/0!
A8: 3 | C8: =IF(+B8-B7>0,B8-B7,(B8-B7)>0)*800 -> 0 | E8: =IF(+D8-D7>0,D8-D7,(D8-D7)>0)*80 -> 0 | G8: =IF(+F8-F7>0,F8-F7,(F8-F7)>0)*10 -> 0 | H8: 57 | I8: 22932824 | J8: =IF(I8>=I7,I8-I7,0) -> 5430 | K8: =M8+O8 -> 3481 | L8: 283234 | M8: =IF(L8>=L7,L8-L7,0) -> 2068 | N8: 278844 | O8: =IF(N8>=N7,N8-N7,0) -> 1413 | P8: 218270 | Q8: =IF(P8>=P7,P8-P7,0)*30 -> 600 | R8: 157052 | S8: =IF(R8>=R7,R8-R7,0) -> 140 | T8: 286263 | U8: =IF(T8>=T7,T8-T7,0) -> 265 | V8: 99875 | W8: =IF(V8>=V7,V8-V7,0)*0.53 -> 3673.43 | X8: 682143 | Y8: =IF(X8>=X7,X8-X7,0)*0.53 -> 4134.53 | Z8: 812070 | AA8: =IF(Z8>=Z7,Z8-Z7,0)*0.53 -> 0 | AB8: 384449 | AC8: =IF(AB8>=AB7,AB8-AB7,0)*0.53 -> 0 | AD8: 456862 | AE8: =IF(AD8>=AD7,AD8-AD7,0)*0.53 -> 1849.7 | AF8: 828319 | AG8: =IF(AF8>=AF7,AF8-AF7,0)*0.53 -> 81.09 | AH8: 780985 | AI8: =IF(AH8>=AH7,AH8-AH7,0)*0.53 -> 1142.15 | AJ8: 738607 | AK8: =IF(AJ8>=AJ7,AJ8-AJ7,0)*0.53 -> 3816.53 | AL8: 438331 | AM8: =IF(AL8>=AL7,AL8-AL7,0)*0.53 -> 173.84 | AN8: =W8+Y8+AA8+AC8+AE8+AG8+AI8+AK8+AM8 -> 14871.27 | AO8: 7429219 | AP8: =IF(AO8>=AO7,AO8-AO7,0)*0.1125 -> 223.425 | AQ8: 626126 | AR8: =IF(AQ8>=AQ7,AQ8-AQ7,0) -> 198 | AS8: 937960 | AT8: =IF(AS8>=AS7,AS8-AS7,0) -> 197 | AU8: 802127 | AV8: =IF(AU8>=AU7,AU8-AU7,0) -> 75 | AW8: 2468559 | AX8: =IF(AW8>=AW7,AW8-AW7,0) -> 1106 | AY8: 219409 | AZ8: =IF(AY8>=AY7,AY8-AY7,0) -> 17 | BA8: 18422074 | BB8: =IF(BA8>=BA7,BA8-BA7,0) -> 4909 | BC8: 524512 | BD8: =IF(BC8>=BC7,BC8-BC7,0) -> 206 | BE8: 16489 | BF8: =IF(BE8>=BE7,BE8-BE7,0) -> 129 | BG8: 22998437 | BH8: =IF(BG8>=BG7,BG8-BG7,0)-(0.45*BN8)-(0.45*BP8)-BR8 -> 6001.6 | BI8: =AP8+AR8+AT8+AV8+AX8+AZ8+BB8+BD8+BF8+BH8 -> 13062.025 | BJ8: =BI8+AN8 -> 27933.295 | BK8: 1394852 | BL8: =IF(BK8>=BK7,BK8-BK7,0) -> 59 | BM8: 3710800 | BN8: =IF(BM8>=BM7,BM8-BM7,0) -> 1698 | BO8: 392578 | BP8: =IF(BO8>=BO7,BO8-BO7,0) -> 114 | BQ8: 489520 | BR8: =IF(BQ8>=BQ7,BQ8-BQ7,0) -> 212 | BS8: =J8+Q8+AN8+BI8 -> 33963.295 | BT8: 214 | BU8: =IF(BS8>0,BS8/BT7,0) -> 160.20422 | BW8: =IF(BS8>0,BS8/BV8,0) -> #DIV/0! | BX8: =((BS8-Q8)*$BZ$1)+(Q8*$BR$1) -> 39327.789 | BY8: =IF(BX8>0,BX8/BT7,0) -> 185.50844 | BZ8: =IF(BX8>0,BX8/BV8,0) -> #DIV/0!
A9: 4 | C9: =IF(+B9-B8>0,B9-B8,(B9-B8)>0)*800 -> 0 | E9: =IF(+D9-D8>0,D9-D8,(D9-D8)>0)*80 -> 0 | G9: =IF(+F9-F8>0,F9-F8,(F9-F8)>0)*10 -> 0 | I9: 22938410 | J9: =IF(I9>=I8,I9-I8,0) -> 5586 | K9: =M9+O9 -> 3484 | L9: 285293 | M9: =IF(L9>=L8,L9-L8,0) -> 2059 | N9: 280269 | O9: =IF(N9>=N8,N9-N8,0) -> 1425 | P9: 218294 | Q9: =IF(P9>=P8,P9-P8,0)*30 -> 720 | R9: 157189 | S9: =IF(R9>=R8,R9-R8,0) -> 137 | T9: 286533 | U9: =IF(T9>=T8,T9-T8,0) -> 270 | V9: 106862 | W9: =IF(V9>=V8,V9-V8,0)*0.53 -> 3703.11 | X9: 689772 | Y9: =IF(X9>=X8,X9-X8,0)*0.53 -> 4043.37 | Z9: 812070 | AA9: =IF(Z9>=Z8,Z9-Z8,0)*0.53 -> 0 | AB9: 384449 | AC9: =IF(AB9>=AB8,AB9-AB8,0)*0.53 -> 0 | AD9: 459936 | AE9: =IF(AD9>=AD8,AD9-AD8,0)*0.53 -> 1629.22 | AF9: 829126 | AG9: =IF(AF9>=AF8,AF9-AF8,0)*0.53 -> 427.71 | AH9: 783087 | AI9: =IF(AH9>=AH8,AH9-AH8,0)*0.53 -> 1114.06 | AJ9: 745655 | AK9: =IF(AJ9>=AJ8,AJ9-AJ8,0)*0.53 -> 3735.44 | AL9: 438658 | AM9: =IF(AL9>=AL8,AL9-AL8,0)*0.53 -> 173.31 | AN9: =W9+Y9+AA9+AC9+AE9+AG9+AI9+AK9+AM9 -> 14826.22 | AO9: 7431031 | AP9: =IF(AO9>=AO8,AO9-AO8,0)*0.1125 -> 203.85 | AQ9: 626341 | AR9: =IF(AQ9>=AQ8,AQ9-AQ8,0) -> 215 | AS9: 938143 | AT9: =IF(AS9>=AS8,AS9-AS8,0) -> 183 | AU9: 802202 | AV9: =IF(AU9>=AU8,AU9-AU8,0) -> 75 | AW9: 2469632 | AX9: =IF(AW9>=AW8,AW9-AW8,0) -> 1073 | AY9: 219426 | AZ9: =IF(AY9>=AY8,AY9-AY8,0) -> 17 | BA9: 18427520 | BB9: =IF(BA9>=BA8,BA9-BA8,0) -> 5446 | BC9: 524751 | BD9: =IF(BC9>=BC8,BC9-BC8,0) -> 239 | BE9: 16546 | BF9: =IF(BE9>=BE8,BE9-BE8,0) -> 57 | BG9: 23005460 | BH9: =IF(BG9>=BG8,BG9-BG8,0)-(0.45*BN9)-(0.45*BP9)-BR9 -> 5962.1 | BI9: =AP9+AR9+AT9+AV9+AX9+AZ9+BB9+BD9+BF9+BH9 -> 13470.95 | BJ9: =BI9+AN9 -> 28297.17 | BK9: 1394909 | BL9: =IF(BK9>=BK8,BK9-BK8,0) -> 57 | BM9: 3712592 | BN9: =IF(BM9>=BM8,BM9-BM8,0) -> 1792 | BO9: 392688 | BP9: =IF(BO9>=BO8,BO9-BO8,0) -> 110 | BQ9: 489725 | BR9: =IF(BQ9>=BQ8,BQ9-BQ8,0) -> 205 | BS9: =J9+Q9+AN9+BI9 -> 34603.17 | BT9: 222 | BU9: =IF(BS9>0,BS9/BT8,0) -> 161.69706 | BW9: =IF(BS9>0,BS9/BV9,0) -> #DIV/0! | BX9: =((BS9-Q9)*$BZ$1)+(Q9*$BR$1) -> 40117.645 | BY9: =IF(BX9>0,BX9/BT8,0) -> 187.46563 | BZ9: =IF(BX9>0,BX9/BV9,0) -> #DIV/0!
A10: 5 | C10: =IF(+B10-B9>0,B10-B9,(B10-B9)>0)*800 -> 0 | E10: =IF(+D10-D9>0,D10-D9,(D10-D9)>0)*80 -> 0 | G10: =IF(+F10-F9>0,F10-F9,(F10-F9)>0)*10 -> 0 | H10: 58 | I10: 22944323 | J10: =IF(I10>=I9,I10-I9,0) -> 5913 | K10: =M10+O10 -> 3689 | L10: 287435 | M10: =IF(L10>=L9,L10-L9,0) -> 2142 | N10: 281816 | O10: =IF(N10>=N9,N10-N9,0) -> 1547 | P10: 218311 | Q10: =IF(P10>=P9,P10-P9,0)*30 -> 510 | R10: 157330 | S10: =IF(R10>=R9,R10-R9,0) -> 141 | T10: 286823 | U10: =IF(T10>=T9,T10-T9,0) -> 290 | V10: 113501 | W10: =IF(V10>=V9,V10-V9,0)*0.53 -> 3518.67 | X10: 697508 | Y10: =IF(X10>=X9,X10-X9,0)*0.53 -> 4100.08 | Z10: 812070 | AA10: =IF(Z10>=Z9,Z10-Z9,0)*0.53 -> 0 | AB10: 384449 | AC10: =IF(AB10>=AB9,AB10-AB9,0)*0.53 -> 0 | AD10: 463392 | AE10: =IF(AD10>=AD9,AD10-AD9,0)*0.53 -> 1831.68 | AF10: 829147 | AG10: =IF(AF10>=AF9,AF10-AF9,0)*0.53 -> 11.13 | AH10: 785253 | AI10: =IF(AH10>=AH9,AH10-AH9,0)*0.53 -> 1147.98 | AJ10: 752775 | AK10: =IF(AJ10>=AJ9,AJ10-AJ9,0)*0.53 -> 3773.6 | AL10: 438993 | AM10: =IF(AL10>=AL9,AL10-AL9,0)*0.53 -> 177.55 | AN10: =W10+Y10+AA10+AC10+AE10+AG10+AI10+AK10+AM10 -> 14560.69 | AO10: 7432815 | AP10: =IF(AO10>=AO9,AO10-AO9,0)*0.1125 -> 200.7 | AQ10: 626554 | AR10: =IF(AQ10>=AQ9,AQ10-AQ9,0) -> 213 | AS10: 938343 | AT10: =IF(AS10>=AS9,AS10-AS9,0) -> 200 | AU10: 802278 | AV10: =IF(AU10>=AU9,AU10-AU9,0) -> 76 | AW10: 2470738 | AX10: =IF(AW10>=AW9,AW10-AW9,0) -> 1106 | AY10: 219473 | AZ10: =IF(AY10>=AY9,AY10-AY9,0) -> 47 | BA10: 18432278 | BB10: =IF(BA10>=BA9,BA10-BA9,0) -> 4758 | BC10: 524997 | BD10: =IF(BC10>=BC9,BC10-BC9,0) -> 246 | BE10: 16752 | BF10: =IF(BE10>=BE9,BE10-BE9,0) -> 206 | BG10: 23012637 | BH10: =IF(BG10>=BG9,BG10-BG9,0)-(0.45*BN10)-(0.45*BP10)-BR10 -> 6135.75 | BI10: =AP10+AR10+AT10+AV10+AX10+AZ10+BB10+BD10+BF10+BH10 -> 13188.45 | BJ10: =BI10+AN10 -> 27749.14 | BK10: 1394969 | BL10: =IF(BK10>=BK9,BK10-BK9,0) -> 60 | BM10: 3714310 | BN10: =IF(BM10>=BM9,BM10-BM9,0) -> 1718 | BO10: 392815 | BP10: =IF(BO10>=BO9,BO10-BO9,0) -> 127 | BQ10: 489936 | BR10: =IF(BQ10>=BQ9,BQ10-BQ9,0) -> 211 | BS10: =J10+Q10+AN10+BI10 -> 34172.14 | BT10: 231 | BU10: =IF(BS10>0,BS10/BT9,0) -> 153.92856 | BW10: =IF(BS10>0,BS10/BV10,0) -> #DIV/0! | BX10: =((BS10-Q10)*$BZ$1)+(Q10*$BR$1) -> 39527.461 | BY10: =IF(BX10>0,BX10/BT9,0) -> 178.05163 | BZ10: =IF(BX10>0,BX10/BV10,0) -> #DIV/0!
A11: 6 | C11: =IF(+B11-B10>0,B11-B10,(B11-B10)>0)*800 -> 0 | E11: =IF(+D11-D10>0,D11-D10,(D11-D10)>0)*80 -> 0 | G11: =IF(+F11-F10>0,F11-F10,(F11-F10)>0)*10 -> 0 | I11: 22950256 | J11: =IF(I11>=I10,I11-I10,0) -> 5933 | K11: =M11+O11 -> 3687 | L11: 289564 | M11: =IF(L11>=L10,L11-L10,0) -> 2129 | N11: 283374 | O11: =IF(N11>=N10,N11-N10,0) -> 1558 | P11: 218331 | Q11: =IF(P11>=P10,P11-P10,0)*30 -> 600 | R11: 157467 | S11: =IF(R11>=R10,R11-R10,0) -> 137 | T11: 287106 | U11: =IF(T11>=T10,T11-T10,0) -> 283 | V11: 120793 | W11: =IF(V11>=V10,V11-V10,0)*0.53 -> 3864.76 | X11: 705216 | Y11: =IF(X11>=X10,X11-X10,0)*0.53 -> 4085.24 | Z11: 812070 | AA11: =IF(Z11>=Z10,Z11-Z10,0)*0.53 -> 0 | AB11: 384449 | AC11: =IF(AB11>=AB10,AB11-AB10,0)*0.53 -> 0 | AD11: 466897 | AE11: =IF(AD11>=AD10,AD11-AD10,0)*0.53 -> 1857.65 | AF11: 829166 | AG11: =IF(AF11>=AF10,AF11-AF10,0)*0.53 -> 10.07 | AH11: 787373 | AI11: =IF(AH11>=AH10,AH11-AH10,0)*0.53 -> 1123.6 | AJ11: 759180 | AK11: =IF(AJ11>=AJ10,AJ11-AJ10,0)*0.53 -> 3394.65 | AL11: 439327 | AM11: =IF(AL11>=AL10,AL11-AL10,0)*0.53 -> 177.02 | AN11: =W11+Y11+AA11+AC11+AE11+AG11+AI11+AK11+AM11 -> 14512.99 | AO11: 7434618 | AP11: =IF(AO11>=AO10,AO11-AO10,0)*0.1125 -> 202.8375 | AQ11: 626735 | AR11: =IF(AQ11>=AQ10,AQ11-AQ10,0) -> 181 | AS11: 938538 | AT11: =IF(AS11>=AS10,AS11-AS10,0) -> 195 | AU11: 802313 | AV11: =IF(AU11>=AU10,AU11-AU10,0) -> 35 | AW11: 2471874 | AX11: =IF(AW11>=AW10,AW11-AW10,0) -> 1136 | AY11: 219525 | AZ11: =IF(AY11>=AY10,AY11-AY10,0) -> 52 | BA11: 18437580 | BB11: =IF(BA11>=BA10,BA11-BA10,0) -> 5302 | BC11: 525212 | BD11: =IF(BC11>=BC10,BC11-BC10,0) -> 215 | BE11: 16872 | BF11: =IF(BE11>=BE10,BE11-BE10,0) -> 120 | BG11: 23019535 | BH11: =IF(BG11>=BG10,BG11-BG10,0)-(0.45*BN11)-(0.45*BP11)-BR11 -> 5915.9 | BI11: =AP11+AR11+AT11+AV11+AX11+AZ11+BB11+BD11+BF11+BH11 -> 13354.737 | BJ11: =BI11+AN11 -> 27867.728 | BK11: 1395026 | BL11: =IF(BK11>=BK10,BK11-BK10,0) -> 57 | BM11: 3715938 | BN11: =IF(BM11>=BM10,BM11-BM10,0) -> 1628 | BO11: 392925 | BP11: =IF(BO11>=BO10,BO11-BO10,0) -> 110 | BQ11: 490136 | BR11: =IF(BQ11>=BQ10,BQ11-BQ10,0) -> 200 | BS11: =J11+Q11+AN11+BI11 -> 34400.727 | BT11: 226 | BU11: =IF(BS11>0,BS11/BT10,0) -> 148.9209 | BW11: =IF(BS11>0,BS11/BV11,0) -> #DIV/0! | BX11: =((BS11-Q11)*$BZ$1)+(Q11*$BR$1) -> 39830.837 | BY11: =IF(BX11>0,BX11/BT10,0) -> 172.42786 | BZ11: =IF(BX11>0,BX11/BV11,0) -> #DIV/0!
A12: 7 | C12: =IF(+B12-B11>0,B12-B11,(B12-B11)>0)*800 -> 0 | E12: =IF(+D12-D11>0,D12-D11,(D12-D11)>0)*80 -> 0 | G12: =IF(+F12-F11>0,F12-F11,(F12-F11)>0)*10 -> 0 | H12: 59 | I12: 22956151 | J12: =IF(I12>=I11,I12-I11,0) -> 5895 | K12: =M12+O12 -> 3550 | L12: 291656 | M12: =IF(L12>=L11,L12-L11,0) -> 2092 | N12: 284832 | O12: =IF(N12>=N11,N12-N11,0) -> 1458 | P12: 218351 | Q12: =IF(P12>=P11,P12-P11,0)*30 -> 600 | R12: 157608 | S12: =IF(R12>=R11,R12-R11,0) -> 141 | T12: 287392 | U12: =IF(T12>=T11,T12-T11,0) -> 286 | V12: 127992 | W12: =IF(V12>=V11,V12-V11,0)*0.53 -> 3815.47 | X12: 707800 | Y12: =IF(X12>=X11,X12-X11,0)*0.53 -> 1369.52 | Z12: 817385 | AA12: =IF(Z12>=Z11,Z12-Z11,0)*0.53 -> 2816.95 | AB12: 384478 | AC12: =IF(AB12>=AB11,AB12-AB11,0)*0.53 -> 15.37 | AD12: 470493 | AE12: =IF(AD12>=AD11,AD12-AD11,0)*0.53 -> 1905.88 | AF12: 829186 | AG12: =IF(AF12>=AF11,AF12-AF11,0)*0.53 -> 10.6 | AH12: 789576 | AI12: =IF(AH12>=AH11,AH12-AH11,0)*0.53 -> 1167.59 | AJ12: 767217 | AK12: =IF(AJ12>=AJ11,AJ12-AJ11,0)*0.53 -> 4259.61 | AL12: 439669 | AM12: =IF(AL12>=AL11,AL12-AL11,0)*0.53 -> 181.26 | AN12: =W12+Y12+AA12+AC12+AE12+AG12+AI12+AK12+AM12 -> 15542.25 | AO12: 7436414 | AP12: =IF(AO12>=AO11,AO12-AO11,0)*0.1125 -> 202.05 | AQ12: 626907 | AR12: =IF(AQ12>=AQ11,AQ12-AQ11,0) -> 172 | AS12: 938747 | AT12: =IF(AS12>=AS11,AS12-AS11,0) -> 209 | AU12: 802356 | AV12: =IF(AU12>=AU11,AU12-AU11,0) -> 43 | AW12: 2473011 | AX12: =IF(AW12>=AW11,AW12-AW11,0) -> 1137 | AY12: 219603 | AZ12: =IF(AY12>=AY11,AY12-AY11,0) -> 78 | BA12: 18442299 | BB12: =IF(BA12>=BA11,BA12-BA11,0) -> 4719 | BC12: 525459 | BD12: =IF(BC12>=BC11,BC12-BC11,0) -> 247 | BE12: 16894 | BF12: =IF(BE12>=BE11,BE12-BE11,0) -> 22 | BG12: 23026629 | BH12: =IF(BG12>=BG11,BG12-BG11,0)-(0.45*BN12)-(0.45*BP12)-BR12 -> 6032.4 | BI12: =AP12+AR12+AT12+AV12+AX12+AZ12+BB12+BD12+BF12+BH12 -> 12861.45 | BJ12: =BI12+AN12 -> 28403.7 | BK12: 1395086 | BL12: =IF(BK12>=BK11,BK12-BK11,0) -> 60 | BM12: 3717746 | BN12: =IF(BM12>=BM11,BM12-BM11,0) -> 1808 | BO12: 393045 | BP12: =IF(BO12>=BO11,BO12-BO11,0) -> 120 | BQ12: 490330 | BR12: =IF(BQ12>=BQ11,BQ12-BQ11,0) -> 194 | BS12: =J12+Q12+AN12+BI12 -> 34898.7 | BT12: 187 | BU12: =IF(BS12>0,BS12/BT11,0) -> 154.41903 | BW12: =IF(BS12>0,BS12/BV12,0) -> #DIV/0! | BX12: =((BS12-Q12)*$BZ$1)+(Q12*$BR$1) -> 40403.505 | BY12: =IF(BX12>0,BX12/BT11,0) -> 178.77657 | BZ12: =IF(BX12>0,BX12/BV12,0) -> #DIV/0!
A13: 8 | C13: =IF(+B13-B12>0,B13-B12,(B13-B12)>0)*800 -> 0 | E13: =IF(+D13-D12>0,D13-D12,(D13-D12)>0)*80 -> 0 | G13: =IF(+F13-F12>0,F13-F12,(F13-F12)>0)*10 -> 0 | I13: 22961598 | J13: =IF(I13>=I12,I13-I12,0) -> 5447 | K13: =M13+O13 -> 3338 | L13: 293610 | M13: =IF(L13>=L12,L13-L12,0) -> 1954 | N13: 286216 | O13: =IF(N13>=N12,N13-N12,0) -> 1384 | P13: 218376 | Q13: =IF(P13>=P12,P13-P12,0)*30 -> 750 | R13: 157746 | S13: =IF(R13>=R12,R13-R12,0) -> 138 | T13: 287661 | U13: =IF(T13>=T12,T13-T12,0) -> 269 | V13: 136018 | W13: =IF(V13>=V12,V13-V12,0)*0.53 -> 4253.78 | X13: 707800 | Y13: =IF(X13>=X12,X13-X12,0)*0.53 -> 0 | Z13: 824586 | AA13: =IF(Z13>=Z12,Z13-Z12,0)*0.53 -> 3816.53 | AB13: 384478 | AC13: =IF(AB13>=AB12,AB13-AB12,0)*0.53 -> 0 | AD13: 473959 | AE13: =IF(AD13>=AD12,AD13-AD12,0)*0.53 -> 1836.98 | AF13: 829204 | AG13: =IF(AF13>=AF12,AF13-AF12,0)*0.53 -> 9.54 | AH13: 791635 | AI13: =IF(AH13>=AH12,AH13-AH12,0)*0.53 -> 1091.27 | AJ13: 774338 | AK13: =IF(AJ13>=AJ12,AJ13-AJ12,0)*0.53 -> 3774.13 | AL13: 439992 | AM13: =IF(AL13>=AL12,AL13-AL12,0)*0.53 -> 171.19 | AN13: =W13+Y13+AA13+AC13+AE13+AG13+AI13+AK13+AM13 -> 14953.42 | AO13: 7438107 | AP13: =IF(AO13>=AO12,AO13-AO12,0)*0.1125 -> 190.4625 | AQ13: 627072 | AR13: =IF(AQ13>=AQ12,AQ13-AQ12,0) -> 165 | AS13: 938930 | AT13: =IF(AS13>=AS12,AS13-AS12,0) -> 183 | AU13: 802434 | AV13: =IF(AU13>=AU12,AU13-AU12,0) -> 78 | AW13: 2474053 | AX13: =IF(AW13>=AW12,AW13-AW12,0) -> 1042 | AY13: 219678 | AZ13: =IF(AY13>=AY12,AY13-AY12,0) -> 75 | BA13: 18447094 | BB13: =IF(BA13>=BA12,BA13-BA12,0) -> 4795 | BC13: 525677 | BD13: =IF(BC13>=BC12,BC13-BC12,0) -> 218 | BE13: 17193 | BF13: =IF(BE13>=BE12,BE13-BE12,0) -> 299 | BG13: 23033464 | BH13: =IF(BG13>=BG12,BG13-BG12,0)-(0.45*BN13)-(0.45*BP13)-BR13 -> 5786.65 | BI13: =AP13+AR13+AT13+AV13+AX13+AZ13+BB13+BD13+BF13+BH13 -> 12832.112 | BJ13: =BI13+AN13 -> 27785.533 | BK13: 1395145 | BL13: =IF(BK13>=BK12,BK13-BK12,0) -> 59 | BM13: 3719491 | BN13: =IF(BM13>=BM12,BM13-BM12,0) -> 1745 | BO13: 393163 | BP13: =IF(BO13>=BO12,BO13-BO12,0) -> 118 | BQ13: 490540 | BR13: =IF(BQ13>=BQ12,BQ13-BQ12,0) -> 210 | BS13: =J13+Q13+AN13+BI13 -> 33982.533 | BT13: 173 | BU13: =IF(BS13>0,BS13/BT12,0) -> 181.72477 | BW13: =IF(BS13>0,BS13/BV13,0) -> #DIV/0! | BX13: =((BS13-Q13)*$BZ$1)+(Q13*$BR$1) -> 39417.412 | BY13: =IF(BX13>0,BX13/BT12,0) -> 210.7883 | BZ13: =IF(BX13>0,BX13/BV13,0) -> #DIV/0!
A14: 9 | C14: =IF(+B14-B13>0,B14-B13,(B14-B13)>0)*800 -> 0 | E14: =IF(+D14-D13>0,D14-D13,(D14-D13)>0)*80 -> 0 | G14: =IF(+F14-F13>0,F14-F13,(F14-F13)>0)*10 -> 0 | H14: 60 | I14: 22967372 | J14: =IF(I14>=I13,I14-I13,0) -> 5774 | K14: =M14+O14 -> 3512 | L14: 295670 | M14: =IF(L14>=L13,L14-L13,0) -> 2060 | N14: 287668 | O14: =IF(N14>=N13,N14-N13,0) -> 1452 | P14: 218396 | Q14: =IF(P14>=P13,P14-P13,0)*30 -> 600 | R14: 157884 | S14: =IF(R14>=R13,R14-R13,0) -> 138 | T14: 287927 | U14: =IF(T14>=T13,T14-T13,0) -> 266 | V14: 143253 | W14: =IF(V14>=V13,V14-V13,0)*0.53 -> 3834.55 | X14: 711508 | Y14: =IF(X14>=X13,X14-X13,0)*0.53 -> 1965.24 | Z14: 828860 | AA14: =IF(Z14>=Z13,Z14-Z13,0)*0.53 -> 2265.22 | AB14: 384478 | AC14: =IF(AB14>=AB13,AB14-AB13,0)*0.53 -> 0 | AD14: 477531 | AE14: =IF(AD14>=AD13,AD14-AD13,0)*0.53 -> 1893.16 | AF14: 829224 | AG14: =IF(AF14>=AF13,AF14-AF13,0)*0.53 -> 10.6 | AH14: 793744 | AI14: =IF(AH14>=AH13,AH14-AH13,0)*0.53 -> 1117.77 | AJ14: 782368 | AK14: =IF(AJ14>=AJ13,AJ14-AJ13,0)*0.53 -> 4255.9 | AL14: 440321 | AM14: =IF(AL14>=AL13,AL14-AL13,0)*0.53 -> 174.37 | AN14: =W14+Y14+AA14+AC14+AE14+AG14+AI14+AK14+AM14 -> 15516.81 | AO14: 7439891 | AP14: =IF(AO14>=AO13,AO14-AO13,0)*0.1125 -> 200.7 | AQ14: 627241 | AR14: =IF(AQ14>=AQ13,AQ14-AQ13,0) -> 169 | AS14: 939109 | AT14: =IF(AS14>=AS13,AS14-AS13,0) -> 179 | AU14: 802489 | AV14: =IF(AU14>=AU13,AU14-AU13,0) -> 55 | AW14: 2475125 | AX14: =IF(AW14>=AW13,AW14-AW13,0) -> 1072 | AY14: 219754 | AZ14: =IF(AY14>=AY13,AY14-AY13,0) -> 76 | BA14: 18451745 | BB14: =IF(BA14>=BA13,BA14-BA13,0) -> 4651 | BC14: 525886 | BD14: =IF(BC14>=BC13,BC14-BC13,0) -> 209 | BE14: 17266 | BF14: =IF(BE14>=BE13,BE14-BE13,0) -> 73 | BG14: 23040423 | BH14: =IF(BG14>=BG13,BG14-BG13,0)-(0.45*BN14)-(0.45*BP14)-BR14 -> 5906.8 | BI14: =AP14+AR14+AT14+AV14+AX14+AZ14+BB14+BD14+BF14+BH14 -> 12591.5 | BJ14: =BI14+AN14 -> 28108.31 | BK14: 1395203 | BL14: =IF(BK14>=BK13,BK14-BK13,0) -> 58 | BM14: 3721260 | BN14: =IF(BM14>=BM13,BM14-BM13,0) -> 1769 | BO14: 393270 | BP14: =IF(BO14>=BO13,BO14-BO13,0) -> 107 | BQ14: 490748 | BR14: =IF(BQ14>=BQ13,BQ14-BQ13,0) -> 208 | BS14: =J14+Q14+AN14+BI14 -> 34482.31 | BT14: 170 | BU14: =IF(BS14>0,BS14/BT13,0) -> 199.31971 | BW14: =IF(BS14>0,BS14/BV14,0) -> #DIV/0! | BX14: =((BS14-Q14)*$BZ$1)+(Q14*$BR$1) -> 39924.657 | BY14: =IF(BX14>0,BX14/BT13,0) -> 230.77836 | BZ14: =IF(BX14>0,BX14/BV14,0) -> #DIV/0!
A15: 10 | C15: =IF(+B15-B14>0,B15-B14,(B15-B14)>0)*800 -> 0 | E15: =IF(+D15-D14>0,D15-D14,(D15-D14)>0)*80 -> 0 | G15: =IF(+F15-F14>0,F15-F14,(F15-F14)>0)*10 -> 0 | I15: 22973046 | J15: =IF(I15>=I14,I15-I14,0) -> 5674 | K15: =M15+O15 -> 3674 | L15: 297867 | M15: =IF(L15>=L14,L15-L14,0) -> 2197 | N15: 289145 | O15: =IF(N15>=N14,N15-N14,0) -> 1477 | P15: 218416 | Q15: =IF(P15>=P14,P15-P14,0)*30 -> 600 | R15: 158024 | S15: =IF(R15>=R14,R15-R14,0) -> 140 | T15: 288201 | U15: =IF(T15>=T14,T15-T14,0) -> 274 | V15: 151221 | W15: =IF(V15>=V14,V15-V14,0)*0.53 -> 4223.04 | X15: 717344 | Y15: =IF(X15>=X14,X15-X14,0)*0.53 -> 3093.08 | Z15: 831471 | AA15: =IF(Z15>=Z14,Z15-Z14,0)*0.53 -> 1383.83 | AB15: 384553 | AC15: =IF(AB15>=AB14,AB15-AB14,0)*0.53 -> 39.75 | AD15: 481245 | AE15: =IF(AD15>=AD14,AD15-AD14,0)*0.53 -> 1968.42 | AF15: 829243 | AG15: =IF(AF15>=AF14,AF15-AF14,0)*0.53 -> 10.07 | AH15: 795942 | AI15: =IF(AH15>=AH14,AH15-AH14,0)*0.53 -> 1164.94 | AJ15: 790658 | AK15: =IF(AJ15>=AJ14,AJ15-AJ14,0)*0.53 -> 4393.7 | AL15: 440663 | AM15: =IF(AL15>=AL14,AL15-AL14,0)*0.53 -> 181.26 | AN15: =W15+Y15+AA15+AC15+AE15+AG15+AI15+AK15+AM15 -> 16458.09 | AO15: 7441756 | AP15: =IF(AO15>=AO14,AO15-AO14,0)*0.1125 -> 209.8125 | AQ15: 627406 | AR15: =IF(AQ15>=AQ14,AQ15-AQ14,0) -> 165 | AS15: 939288 | AT15: =IF(AS15>=AS14,AS15-AS14,0) -> 179 | AU15: 802558 | AV15: =IF(AU15>=AU14,AU15-AU14,0) -> 69 | AW15: 2476290 | AX15: =IF(AW15>=AW14,AW15-AW14,0) -> 1165 | AY15: 219828 | AZ15: =IF(AY15>=AY14,AY15-AY14,0) -> 74 | BA15: 18456445 | BB15: =IF(BA15>=BA14,BA15-BA14,0) -> 4700 | BC15: 526112 | BD15: =IF(BC15>=BC14,BC15-BC14,0) -> 226 | BE15: 17390 | BF15: =IF(BE15>=BE14,BE15-BE14,0) -> 124 | BG15: 23047825 | BH15: =IF(BG15>=BG14,BG15-BG14,0)-(0.45*BN15)-(0.45*BP15)-BR15 -> 6314.6 | BI15: =AP15+AR15+AT15+AV15+AX15+AZ15+BB15+BD15+BF15+BH15 -> 13226.413 | BJ15: =BI15+AN15 -> 29684.503 | BK15: 1395255 | BL15: =IF(BK15>=BK14,BK15-BK14,0) -> 52 | BM15: 3723082 | BN15: =IF(BM15>=BM14,BM15-BM14,0) -> 1822 | BO15: 393380 | BP15: =IF(BO15>=BO14,BO15-BO14,0) -> 110 | BQ15: 490966 | BR15: =IF(BQ15>=BQ14,BQ15-BQ14,0) -> 218 | BS15: =J15+Q15+AN15+BI15 -> 35958.503 | BT15: 171 | BU15: =IF(BS15>0,BS15/BT14,0) -> 211.5206 | BW15: =IF(BS15>0,BS15/BV15,0) -> #DIV/0! | BX15: =((BS15-Q15)*$BZ$1)+(Q15*$BR$1) -> 41622.278 | BY15: =IF(BX15>0,BX15/BT14,0) -> 244.83693 | BZ15: =IF(BX15>0,BX15/BV15,0) -> #DIV/0!
A16: 11 | C16: =IF(+B16-B15>0,B16-B15,(B16-B15)>0)*800 -> 0 | E16: =IF(+D16-D15>0,D16-D15,(D16-D15)>0)*80 -> 0 | G16: =IF(+F16-F15>0,F16-F15,(F16-F15)>0)*10 -> 0 | H16: 61 | I16: 22978940 | J16: =IF(I16>=I15,I16-I15,0) -> 5894 | K16: =M16+O16 -> 3856 | L16: 300160 | M16: =IF(L16>=L15,L16-L15,0) -> 2293 | N16: 290708 | O16: =IF(N16>=N15,N16-N15,0) -> 1563 | P16: 218437 | Q16: =IF(P16>=P15,P16-P15,0)*30 -> 630 | R16: 158165 | S16: =IF(R16>=R15,R16-R15,0) -> 141 | T16: 288482 | U16: =IF(T16>=T15,T16-T15,0) -> 281 | V16: 159456 | W16: =IF(V16>=V15,V16-V15,0)*0.53 -> 4364.55 | X16: 725284 | Y16: =IF(X16>=X15,X16-X15,0)*0.53 -> 4208.2 | Z16: 831688 | AA16: =IF(Z16>=Z15,Z16-Z15,0)*0.53 -> 115.01 | AB16: 384553 | AC16: =IF(AB16>=AB15,AB16-AB15,0)*0.53 -> 0 | AD16: 484716 | AE16: =IF(AD16>=AD15,AD16-AD15,0)*0.53 -> 1839.63 | AF16: 829262 | AG16: =IF(AF16>=AF15,AF16-AF15,0)*0.53 -> 10.07 | AH16: 798143 | AI16: =IF(AH16>=AH15,AH16-AH15,0)*0.53 -> 1166.53 | AJ16: 798583 | AK16: =IF(AJ16>=AJ15,AJ16-AJ15,0)*0.53 -> 4200.25 | AL16: 441001 | AM16: =IF(AL16>=AL15,AL16-AL15,0)*0.53 -> 179.14 | AN16: =W16+Y16+AA16+AC16+AE16+AG16+AI16+AK16+AM16 -> 16083.38 | AO16: 7443181 | AP16: =IF(AO16>=AO15,AO16-AO15,0)*0.1125 -> 160.3125 | AQ16: 627576 | AR16: =IF(AQ16>=AQ15,AQ16-AQ15,0) -> 170 | AS16: 939460 | AT16: =IF(AS16>=AS15,AS16-AS15,0) -> 172 | AU16: 802644 | AV16: =IF(AU16>=AU15,AU16-AU15,0) -> 86 | AW16: 2477478 | AX16: =IF(AW16>=AW15,AW16-AW15,0) -> 1188 | AY16: 219903 | AZ16: =IF(AY16>=AY15,AY16-AY15,0) -> 75 | BA16: 18461328 | BB16: =IF(BA16>=BA15,BA16-BA15,0) -> 4883 | BC16: 526323 | BD16: =IF(BC16>=BC15,BC16-BC15,0) -> 211 | BE16: 17485 | BF16: =IF(BE16>=BE15,BE16-BE15,0) -> 95 | BG16: 23054741 | BH16: =IF(BG16>=BG15,BG16-BG15,0)-(0.45*BN16)-(0.45*BP16)-BR16 -> 5906.4 | BI16: =AP16+AR16+AT16+AV16+AX16+AZ16+BB16+BD16+BF16+BH16 -> 12946.713 | BJ16: =BI16+AN16 -> 29030.092 | BK16: 1395329 | BL16: =IF(BK16>=BK15,BK16-BK15,0) -> 74 | BM16: 3724759 | BN16: =IF(BM16>=BM15,BM16-BM15,0) -> 1677 | BO16: 393491 | BP16: =IF(BO16>=BO15,BO16-BO15,0) -> 111 | BQ16: 491171 | BR16: =IF(BQ16>=BQ15,BQ16-BQ15,0) -> 205 | BS16: =J16+Q16+AN16+BI16 -> 35554.092 | BT16: 176 | BU16: =IF(BS16>0,BS16/BT15,0) -> 207.91867 | BW16: =IF(BS16>0,BS16/BV16,0) -> #DIV/0! | BX16: =((BS16-Q16)*$BZ$1)+(Q16*$BR$1) -> 41170.706 | BY16: =IF(BX16>0,BX16/BT15,0) -> 240.76436 | BZ16: =IF(BX16>0,BX16/BV16,0) -> #DIV/0!
A17: 12 | C17: =IF(+B17-B16>0,B17-B16,(B17-B16)>0)*800 -> 0 | E17: =IF(+D17-D16>0,D17-D16,(D17-D16)>0)*80 -> 0 | G17: =IF(+F17-F16>0,F17-F16,(F17-F16)>0)*10 -> 0 | I17: 22984696 | J17: =IF(I17>=I16,I17-I16,0) -> 5756 | K17: =M17+O17 -> 3440 | L17: 302267 | M17: =IF(L17>=L16,L17-L16,0) -> 2107 | N17: 292041 | O17: =IF(N17>=N16,N17-N16,0) -> 1333 | P17: 218458 | Q17: =IF(P17>=P16,P17-P16,0)*30 -> 630 | R17: 158308 | S17: =IF(R17>=R16,R17-R16,0) -> 143 | T17: 288762 | U17: =IF(T17>=T16,T17-T16,0) -> 280 | V17: 167181 | W17: =IF(V17>=V16,V17-V16,0)*0.53 -> 4094.25 | X17: 727480 | Y17: =IF(X17>=X16,X17-X16,0)*0.53 -> 1163.88 | Z17: 836831 | AA17: =IF(Z17>=Z16,Z17-Z16,0)*0.53 -> 2725.79 | AB17: 384553 | AC17: =IF(AB17>=AB16,AB17-AB16,0)*0.53 -> 0 | AD17: 488293 | AE17: =IF(AD17>=AD16,AD17-AD16,0)*0.53 -> 1895.81 | AF17: 829281 | AG17: =IF(AF17>=AF16,AF17-AF16,0)*0.53 -> 10.07 | AH17: 800157 | AI17: =IF(AH17>=AH16,AH17-AH16,0)*0.53 -> 1067.42 | AJ17: 805840 | AK17: =IF(AJ17>=AJ16,AJ17-AJ16,0)*0.53 -> 3846.21 | AL17: 441314 | AM17: =IF(AL17>=AL16,AL17-AL16,0)*0.53 -> 165.89 | AN17: =W17+Y17+AA17+AC17+AE17+AG17+AI17+AK17+AM17 -> 14969.32 | AO17: 7444905 | AP17: =IF(AO17>=AO16,AO17-AO16,0)*0.1125 -> 193.95 | AQ17: 627745 | AR17: =IF(AQ17>=AQ16,AQ17-AQ16,0) -> 169 | AS17: 939619 | AT17: =IF(AS17>=AS16,AS17-AS16,0) -> 159 | AU17: 802690 | AV17: =IF(AU17>=AU16,AU17-AU16,0) -> 46 | AW17: 2478580 | AX17: =IF(AW17>=AW16,AW17-AW16,0) -> 1102 | AY17: 219967 | AZ17: =IF(AY17>=AY16,AY17-AY16,0) -> 64 | BA17: 18466412 | BB17: =IF(BA17>=BA16,BA17-BA16,0) -> 5084 | BC17: 526540 | BD17: =IF(BC17>=BC16,BC17-BC16,0) -> 217 | BE17: 17593 | BF17: =IF(BE17>=BE16,BE17-BE16,0) -> 108 | BG17: 23061918 | BH17: =IF(BG17>=BG16,BG17-BG16,0)-(0.45*BN17)-(0.45*BP17)-BR17 -> 6123.6 | BI17: =AP17+AR17+AT17+AV17+AX17+AZ17+BB17+BD17+BF17+BH17 -> 13266.55 | BJ17: =BI17+AN17 -> 28235.87 | BK17: 1395417 | BL17: =IF(BK17>=BK16,BK17-BK16,0) -> 88 | BM17: 3726515 | BN17: =IF(BM17>=BM16,BM17-BM16,0) -> 1756 | BO17: 393607 | BP17: =IF(BO17>=BO16,BO17-BO16,0) -> 116 | BQ17: 491382 | BR17: =IF(BQ17>=BQ16,BQ17-BQ16,0) -> 211 | BS17: =J17+Q17+AN17+BI17 -> 34621.87 | BT17: 200 | BU17: =IF(BS17>0,BS17/BT16,0) -> 196.71517 | BW17: =IF(BS17>0,BS17/BV17,0) -> #DIV/0! | BX17: =((BS17-Q17)*$BZ$1)+(Q17*$BR$1) -> 40098.65 | BY17: =IF(BX17>0,BX17/BT16,0) -> 227.83324 | BZ17: =IF(BX17>0,BX17/BV17,0) -> #DIV/0!
A18: 13 | C18: =IF(+B18-B17>0,B18-B17,(B18-B17)>0)*800 -> 0 | E18: =IF(+D18-D17>0,D18-D17,(D18-D17)>0)*80 -> 0 | G18: =IF(+F18-F17>0,F18-F17,(F18-F17)>0)*10 -> 0 | H18: 62 | I18: 22990087 | J18: =IF(I18>=I17,I18-I17,0) -> 5391 | K18: =M18+O18 -> 3373 | L18: 304313 | M18: =IF(L18>=L17,L18-L17,0) -> 2046 | N18: 293368 | O18: =IF(N18>=N17,N18-N17,0) -> 1327 | P18: 218479 | Q18: =IF(P18>=P17,P18-P17,0)*30 -> 630 | R18: 158442 | S18: =IF(R18>=R17,R18-R17,0) -> 134 | T18: 289021 | U18: =IF(T18>=T17,T18-T17,0) -> 259 | V18: 174908 | W18: =IF(V18>=V17,V18-V17,0)*0.53 -> 4095.31 | X18: 731544 | Y18: =IF(X18>=X17,X18-X17,0)*0.53 -> 2153.92 | Z18: 840169 | AA18: =IF(Z18>=Z17,Z18-Z17,0)*0.53 -> 1769.14 | AB18: 384553 | AC18: =IF(AB18>=AB17,AB18-AB17,0)*0.53 -> 0 | AD18: 491728 | AE18: =IF(AD18>=AD17,AD18-AD17,0)*0.53 -> 1820.55 | AF18: 829300 | AG18: =IF(AF18>=AF17,AF18-AF17,0)*0.53 -> 10.07 | AH18: 802174 | AI18: =IF(AH18>=AH17,AH18-AH17,0)*0.53 -> 1069.01 | AJ18: 813195 | AK18: =IF(AJ18>=AJ17,AJ18-AJ17,0)*0.53 -> 3898.15 | AL18: 441629 | AM18: =IF(AL18>=AL17,AL18-AL17,0)*0.53 -> 166.95 | AN18: =W18+Y18+AA18+AC18+AE18+AG18+AI18+AK18+AM18 -> 14983.1 | AO18: 7446809 | AP18: =IF(AO18>=AO17,AO18-AO17,0)*0.1125 -> 214.2 | AQ18: 627918 | AR18: =IF(AQ18>=AQ17,AQ18-AQ17,0) -> 173 | AS18: 939781 | AT18: =IF(AS18>=AS17,AS18-AS17,0) -> 162 | AU18: 802728 | AV18: =IF(AU18>=AU17,AU18-AU17,0) -> 38 | AW18: 2479687 | AX18: =IF(AW18>=AW17,AW18-AW17,0) -> 1107 | AY18: 220022 | AZ18: =IF(AY18>=AY17,AY18-AY17,0) -> 55 | BA18: 18470824 | BB18: =IF(BA18>=BA17,BA18-BA17,0) -> 4412 | BC18: 526735 | BD18: =IF(BC18>=BC17,BC18-BC17,0) -> 195 | BE18: 17646 | BF18: =IF(BE18>=BE17,BE18-BE17,0) -> 53 | BG18: 23068853 | BH18: =IF(BG18>=BG17,BG18-BG17,0)-(0.45*BN18)-(0.45*BP18)-BR18 -> 5937.5 | BI18: =AP18+AR18+AT18+AV18+AX18+AZ18+BB18+BD18+BF18+BH18 -> 12346.7 | BJ18: =BI18+AN18 -> 27329.8 | BK18: 1395490 | BL18: =IF(BK18>=BK17,BK18-BK17,0) -> 73 | BM18: 3728183 | BN18: =IF(BM18>=BM17,BM18-BM17,0) -> 1668 | BO18: 393709 | BP18: =IF(BO18>=BO17,BO18-BO17,0) -> 102 | BQ18: 491583 | BR18: =IF(BQ18>=BQ17,BQ18-BQ17,0) -> 201 | BS18: =J18+Q18+AN18+BI18 -> 33350.8 | BT18: 186 | BU18: =IF(BS18>0,BS18/BT17,0) -> 166.754 | BW18: =IF(BS18>0,BS18/BV18,0) -> #DIV/0! | BX18: =((BS18-Q18)*$BZ$1)+(Q18*$BR$1) -> 38636.92 | BY18: =IF(BX18>0,BX18/BT17,0) -> 193.1846 | BZ18: =IF(BX18>0,BX18/BV18,0) -> #DIV/0!
A19: 14 | C19: =IF(+B19-B18>0,B19-B18,(B19-B18)>0)*800 -> 0 | E19: =IF(+D19-D18>0,D19-D18,(D19-D18)>0)*80 -> 0 | G19: =IF(+F19-F18>0,F19-F18,(F19-F18)>0)*10 -> 0 | I19: 22995323 | J19: =IF(I19>=I18,I19-I18,0) -> 5236 | K19: =M19+O19 -> 3535 | L19: 306440 | M19: =IF(L19>=L18,L19-L18,0) -> 2127 | N19: 294776 | O19: =IF(N19>=N18,N19-N18,0) -> 1408 | P19: 218499 | Q19: =IF(P19>=P18,P19-P18,0)*30 -> 600 | R19: 158575 | S19: =IF(R19>=R18,R19-R18,0) -> 133 | T19: 289283 | U19: =IF(T19>=T18,T19-T18,0) -> 262 | V19: 181652 | W19: =IF(V19>=V18,V19-V18,0)*0.53 -> 3574.32 | X19: 739015 | Y19: =IF(X19>=X18,X19-X18,0)*0.53 -> 3959.63 | Z19: 840169 | AA19: =IF(Z19>=Z18,Z19-Z18,0)*0.53 -> 0 | AB19: 384553 | AC19: =IF(AB19>=AB18,AB19-AB18,0)*0.53 -> 0 | AD19: 494861 | AE19: =IF(AD19>=AD18,AD19-AD18,0)*0.53 -> 1660.49 | AF19: 829319 | AG19: =IF(AF19>=AF18,AF19-AF18,0)*0.53 -> 10.07 | AH19: 804285 | AI19: =IF(AH19>=AH18,AH19-AH18,0)*0.53 -> 1118.83 | AJ19: 820862 | AK19: =IF(AJ19>=AJ18,AJ19-AJ18,0)*0.53 -> 4063.51 | AL19: 441957 | AM19: =IF(AL19>=AL18,AL19-AL18,0)*0.53 -> 173.84 | AN19: =W19+Y19+AA19+AC19+AE19+AG19+AI19+AK19+AM19 -> 14560.69 | AO19: 7448776 | AP19: =IF(AO19>=AO18,AO19-AO18,0)*0.1125 -> 221.2875 | AQ19: 628078 | AR19: =IF(AQ19>=AQ18,AQ19-AQ18,0) -> 160 | AS19: 939958 | AT19: =IF(AS19>=AS18,AS19-AS18,0) -> 177 | AU19: 802776 | AV19: =IF(AU19>=AU18,AU19-AU18,0) -> 48 | AW19: 2480801 | AX19: =IF(AW19>=AW18,AW19-AW18,0) -> 1114 | AY19: 220083 | AZ19: =IF(AY19>=AY18,AY19-AY18,0) -> 61 | BA19: 18475688 | BB19: =IF(BA19>=BA18,BA19-BA18,0) -> 4864 | BC19: 526935 | BD19: =IF(BC19>=BC18,BC19-BC18,0) -> 200 | BE19: 17697 | BF19: =IF(BE19>=BE18,BE19-BE18,0) -> 51 | BG19: 23075792 | BH19: =IF(BG19>=BG18,BG19-BG18,0)-(0.45*BN19)-(0.45*BP19)-BR19 -> 5891.5 | BI19: =AP19+AR19+AT19+AV19+AX19+AZ19+BB19+BD19+BF19+BH19 -> 12787.788 | BJ19: =BI19+AN19 -> 27348.478 | BK19: 1395548 | BL19: =IF(BK19>=BK18,BK19-BK18,0) -> 58 | BM19: 3729948 | BN19: =IF(BM19>=BM18,BM19-BM18,0) -> 1765 | BO19: 393814 | BP19: =IF(BO19>=BO18,BO19-BO18,0) -> 105 | BQ19: 491789 | BR19: =IF(BQ19>=BQ18,BQ19-BQ18,0) -> 206 | BS19: =J19+Q19+AN19+BI19 -> 33184.478 | BT19: 161 | BU19: =IF(BS19>0,BS19/BT18,0) -> 178.41117 | BW19: =IF(BS19>0,BS19/BV19,0) -> #DIV/0! | BX19: =((BS19-Q19)*$BZ$1)+(Q19*$BR$1) -> 38432.149 | BY19: =IF(BX19>0,BX19/BT18,0) -> 206.62446 | BZ19: =IF(BX19>0,BX19/BV19,0) -> #DIV/0!
A20: 15 | C20: =IF(+B20-B19>0,B20-B19,(B20-B19)>0)*800 -> 0 | E20: =IF(+D20-D19>0,D20-D19,(D20-D19)>0)*80 -> 0 | G20: =IF(+F20-F19>0,F20-F19,(F20-F19)>0)*10 -> 0 | H20: 63 | I20: 23000505 | J20: =IF(I20>=I19,I20-I19,0) -> 5182 | K20: =M20+O20 -> 3317 | L20: 308418 | M20: =IF(L20>=L19,L20-L19,0) -> 1978 | N20: 296115 | O20: =IF(N20>=N19,N20-N19,0) -> 1339 | P20: 218519 | Q20: =IF(P20>=P19,P20-P19,0)*30 -> 600 | R20: 158713 | S20: =IF(R20>=R19,R20-R19,0) -> 138 | T20: 289540 | U20: =IF(T20>=T19,T20-T19,0) -> 257 | V20: 183363 | W20: =IF(V20>=V19,V20-V19,0)*0.53 -> 906.83 | X20: 746542 | Y20: =IF(X20>=X19,X20-X19,0)*0.53 -> 3989.31 | Z20: 840169 | AA20: =IF(Z20>=Z19,Z20-Z19,0)*0.53 -> 0 | AB20: 389824 | AC20: =IF(AB20>=AB19,AB20-AB19,0)*0.53 -> 2793.63 | AD20: 498290 | AE20: =IF(AD20>=AD19,AD20-AD19,0)*0.53 -> 1817.37 | AF20: 829339 | AG20: =IF(AF20>=AF19,AF20-AF19,0)*0.53 -> 10.6 | AH20: 806357 | AI20: =IF(AH20>=AH19,AH20-AH19,0)*0.53 -> 1098.16 | AJ20: 828428 | AK20: =IF(AJ20>=AJ19,AJ20-AJ19,0)*0.53 -> 4009.98 | AL20: 442278 | AM20: =IF(AL20>=AL19,AL20-AL19,0)*0.53 -> 170.13 | AN20: =W20+Y20+AA20+AC20+AE20+AG20+AI20+AK20+AM20 -> 14796.01 | AO20: 7450700 | AP20: =IF(AO20>=AO19,AO20-AO19,0)*0.1125 -> 216.45 | AQ20: 628263 | AR20: =IF(AQ20>=AQ19,AQ20-AQ19,0) -> 185 | AS20: 940107 | AT20: =IF(AS20>=AS19,AS20-AS19,0) -> 149 | AU20: 802843 | AV20: =IF(AU20>=AU19,AU20-AU19,0) -> 67 | AW20: 2481918 | AX20: =IF(AW20>=AW19,AW20-AW19,0) -> 1117 | AY20: 220140 | AZ20: =IF(AY20>=AY19,AY20-AY19,0) -> 57 | BA20: 18480583 | BB20: =IF(BA20>=BA19,BA20-BA19,0) -> 4895 | BC20: 527136 | BD20: =IF(BC20>=BC19,BC20-BC19,0) -> 201 | BE20: 17742 | BF20: =IF(BE20>=BE19,BE20-BE19,0) -> 45 | BG20: 23082760 | BH20: =IF(BG20>=BG19,BG20-BG19,0)-(0.45*BN20)-(0.45*BP20)-BR20 -> 5930.05 | BI20: =AP20+AR20+AT20+AV20+AX20+AZ20+BB20+BD20+BF20+BH20 -> 12862.5 | BJ20: =BI20+AN20 -> 27658.51 | BK20: 1395606 | BL20: =IF(BK20>=BK19,BK20-BK19,0) -> 58 | BM20: 3731688 | BN20: =IF(BM20>=BM19,BM20-BM19,0) -> 1740 | BO20: 393925 | BP20: =IF(BO20>=BO19,BO20-BO19,0) -> 111 | BQ20: 491994 | BR20: =IF(BQ20>=BQ19,BQ20-BQ19,0) -> 205 | BS20: =J20+Q20+AN20+BI20 -> 33440.51 | BT20: 137 | BU20: =IF(BS20>0,BS20/BT20,0) -> 244.09131 | BW20: =IF(BS20>0,BS20/BV20,0) -> #DIV/0! | BX20: =((BS20-Q20)*$BZ$1)+(Q20*$BR$1) -> 38726.586 | BY20: =IF(BX20>0,BX20/BT20,0) -> 282.67581 | BZ20: =IF(BX20>0,BX20/BV20,0) -> #DIV/0!
A21: 16 | C21: =IF(+B21-B20>0,B21-B20,(B21-B20)>0)*800 -> 0 | E21: =IF(+D21-D20>0,D21-D20,(D21-D20)>0)*80 -> 0 | G21: =IF(+F21-F20>0,F21-F20,(F21-F20)>0)*10 -> 0 | I21: 23005540 | J21: =IF(I21>=I20,I21-I20,0) -> 5035 | K21: =M21+O21 -> 3407 | L21: 310433 | M21: =IF(L21>=L20,L21-L20,0) -> 2015 | N21: 297507 | O21: =IF(N21>=N20,N21-N20,0) -> 1392 | P21: 218538 | Q21: =IF(P21>=P20,P21-P20,0)*30 -> 570 | R21: 158852 | S21: =IF(R21>=R20,R21-R20,0) -> 139 | T21: 289807 | U21: =IF(T21>=T20,T21-T20,0) -> 267 | V21: 183363 | W21: =IF(V21>=V20,V21-V20,0)*0.53 -> 0 | X21: 753590 | Y21: =IF(X21>=X20,X21-X20,0)*0.53 -> 3735.44 | Z21: 840169 | AA21: =IF(Z21>=Z20,Z21-Z20,0)*0.53 -> 0 | AB21: 396331 | AC21: =IF(AB21>=AB20,AB21-AB20,0)*0.53 -> 3448.71 | AD21: 501666 | AE21: =IF(AD21>=AD20,AD21-AD20,0)*0.53 -> 1789.28 | AF21: 829359 | AG21: =IF(AF21>=AF20,AF21-AF20,0)*0.53 -> 10.6 | AH21: 808510 | AI21: =IF(AH21>=AH20,AH21-AH20,0)*0.53 -> 1141.09 | AJ21: 835665 | AK21: =IF(AJ21>=AJ20,AJ21-AJ20,0)*0.53 -> 3835.61 | AL21: 442614 | AM21: =IF(AL21>=AL20,AL21-AL20,0)*0.53 -> 178.08 | AN21: =W21+Y21+AA21+AC21+AE21+AG21+AI21+AK21+AM21 -> 14138.81 | AO21: 7452608 | AP21: =IF(AO21>=AO20,AO21-AO20,0)*0.1125 -> 214.65 | AQ21: 628511 | AR21: =IF(AQ21>=AQ20,AQ21-AQ20,0) -> 248 | AS21: 940302 | AT21: =IF(AS21>=AS20,AS21-AS20,0) -> 195 | AU21: 802912 | AV21: =IF(AU21>=AU20,AU21-AU20,0) -> 69 | AW21: 2483041 | AX21: =IF(AW21>=AW20,AW21-AW20,0) -> 1123 | AY21: 220195 | AZ21: =IF(AY21>=AY20,AY21-AY20,0) -> 55 | BA21: 18485698 | BB21: =IF(BA21>=BA20,BA21-BA20,0) -> 5115 | BC21: 527336 | BD21: =IF(BC21>=BC20,BC21-BC20,0) -> 200 | BE21: 17792 | BF21: =IF(BE21>=BE20,BE21-BE20,0) -> 50 | BG21: 23089804 | BH21: =IF(BG21>=BG20,BG21-BG20,0)-(0.45*BN21)-(0.45*BP21)-BR21 -> 6638.55 | BI21: =AP21+AR21+AT21+AV21+AX21+AZ21+BB21+BD21+BF21+BH21 -> 13908.2 | BJ21: =BI21+AN21 -> 28047.01 | BK21: 1395665 | BL21: =IF(BK21>=BK20,BK21-BK20,0) -> 59 | BM21: 3732589 | BN21: =IF(BM21>=BM20,BM21-BM20,0) -> 901 | BO21: 393925 | BP21: =IF(BO21>=BO20,BO21-BO20,0) -> 0 | BQ21: 491994 | BR21: =IF(BQ21>=BQ20,BQ21-BQ20,0) -> 0 | BS21: =J21+Q21+AN21+BI21 -> 33652.01 | BT21: 133 | BU21: =IF(BS21>0,BS21/BT21,0) -> 253.02263 | BW21: =IF(BS21>0,BS21/BV21,0) -> #DIV/0! | BX21: =((BS21-Q21)*$BZ$1)+(Q21*$BR$1) -> 38956.311 | BY21: =IF(BX21>0,BX21/BT21,0) -> 292.9046 | BZ21: =IF(BX21>0,BX21/BV21,0) -> #DIV/0!
