Workbook

Sheet Total
A1: Site Name | B1: Day | C1: Month | D1: Year | E1: Total Electricity Kwh | F1: Electricity Tariff ($/Kwh) | G1: Natual Gas (m3) | H1: Natural Gas $/m3 | I1: Water Utility Supply (m3) m3 | J1: Water Utility Supply (m3) $/m3 | K1: Room Nights
A2: Cairo at The First Residence | B2: 1 | C2: 6 | D2: 2021 | E2: 32736.34 | F2: 1.35 | G2: =1025.57+228.17 -> 1253.74 | H2: 3.89 | I2: 279.02 | J2: 10 | K2: 158
A3: Cairo at The First Residence | B3: =B2+1 -> 2 | C3: 6 | D3: 2021 | E3: 32736.34 | F3: =F2 -> 1.35 | G3: =1025.57+228.17 -> 1253.74 | H3: 3.89 | I3: 279.02 | J3: 10 | K3: 158
A4: Cairo at The First Residence | B4: =B3+1 -> 3 | C4: 6 | D4: 2021 | E4: 32736.34 | F4: =F3 -> 1.35 | G4: =1025.57+228.17 -> 1253.74 | H4: 3.89 | I4: 279.02 | J4: 10 | K4: 158
A5: Cairo at The First Residence | B5: =B4+1 -> 4 | C5: 6 | D5: 2021 | E5: 32736.34 | F5: =F4 -> 1.35 | G5: =1025.57+228.17 -> 1253.74 | H5: 3.89 | I5: 279.02 | J5: 10 | K5: 158
A6: Cairo at The First Residence | B6: =B5+1 -> 5 | C6: 6 | D6: 2021 | E6: 32736.34 | F6: =F5 -> 1.35 | G6: =1025.57+228.17 -> 1253.74 | H6: 3.89 | I6: 279.02 | J6: 10 | K6: 158
A7: Cairo at The First Residence | B7: =B6+1 -> 6 | C7: 6 | D7: 2021 | E7: 32736.34 | F7: =F6 -> 1.35 | G7: =1025.57+228.17 -> 1253.74 | H7: 3.89 | I7: 279.02 | J7: 10 | K7: 158
A8: Cairo at The First Residence | B8: =B7+1 -> 7 | C8: 6 | D8: 2021 | E8: 32736.34 | F8: =F7 -> 1.35 | G8: =1025.57+228.17 -> 1253.74 | H8: 3.89 | I8: 279.02 | J8: 10 | K8: 158
A9: Cairo at The First Residence | B9: =B8+1 -> 8 | C9: 6 | D9: 2021 | E9: 32736.34 | F9: =F8 -> 1.35 | G9: =1025.57+228.17 -> 1253.74 | H9: 3.89 | I9: 279.02 | J9: 10 | K9: 158
A10: Cairo at The First Residence | B10: =B9+1 -> 9 | C10: 6 | D10: 2021 | E10: 32736.34 | F10: =F9 -> 1.35 | G10: =1025.57+228.17 -> 1253.74 | H10: 3.89 | I10: 279.02 | J10: 10 | K10: 158
A11: Cairo at The First Residence | B11: =B10+1 -> 10 | C11: 6 | D11: 2021 | E11: 32736.34 | F11: =F10 -> 1.35 | G11: =1025.57+228.17 -> 1253.74 | H11: 3.89 | I11: 279.02 | J11: 10 | K11: 158
A12: Cairo at The First Residence | B12: =B11+1 -> 11 | C12: 6 | D12: 2021 | E12: 32736.34 | F12: =F11 -> 1.35 | G12: =1025.57+228.17 -> 1253.74 | H12: 3.89 | I12: 279.02 | J12: 10 | K12: 158
A13: Cairo at The First Residence | B13: =B12+1 -> 12 | C13: 6 | D13: 2021 | E13: 32736.34 | F13: =F12 -> 1.35 | G13: =1025.57+228.17 -> 1253.74 | H13: 3.89 | I13: 279.02 | J13: 10 | K13: 158
A14: Cairo at The First Residence | B14: =B13+1 -> 13 | C14: 6 | D14: 2021 | E14: 32736.34 | F14: =F13 -> 1.35 | G14: =1025.57+228.17 -> 1253.74 | H14: 3.89 | I14: 279.02 | J14: 10 | K14: 158
... A31: Cairo at The First Residence | B31: =B30+1 -> 30 | C31: 6 | D31: 2021 | E31: 32736.34 | F31: =F30 -> 1.35 | G31: =1025.57+228.17 -> 1253.74 | H31: 3.89 | I31: 279.02 | J31: 10 | K31: 158
A32: Cairo at The First Residence | B32: =B31+1 -> 31 | C32: 6 | D32: 2021 | E32: =Elect!BS36 -> 0 | F32: =F31 -> 1.35 | G32: =Gas!K37 -> 0 | H32: 3.89 | I32: =Water!H37 -> 0 | J32: 10 | K32: =Elect!BT36 -> 0

Sheet Submetering
A1: Site Name | B1: Day | C1: Month | D1: Year | E1: Electricity | F1: Main Feeder -KWh | G1: T2+T8 -KWh | H1: La Gourmandize -KWh | I1: Casino 3rd floor EM -KWh | J1: Casino 3rd floor Normal -KWh | K1: Chiller 1 -KWh | L1: Chiller 2 -KWh | M1: Chiller 3 -KWh | N1: Chiller 4 -KWh | O1: Chiller 5 -KWh | P1: Chiller 6 -KWh | Q1: Cooling towers -KWh | R1: Chiller Pumps -KWh | S1: Cooling Tower Pumps -KWh | T1: Fiber Chiller -KWh | U1: Mall Ceiling light -KWh | V1: LG Bakery -KWh | W1: LG Bakery light ( Old lockers ) -KWh | X1: MCCR1 -KWh | Y1: Children Swimming Pool -KWh | Z1: DPH1 -KWh | AA1: Guest Rooms Emerg. -KWh | AB1: Hotel Hoods -KWh | AC1: Main G2 -KWh | AD1: Old Casino Emergency -KWh | AE1: L / A -KWh | AF1: L / B -KWh | AG1: L / C -KWh | AH1: Water | AI1: Main water meter 1 -m3 | AJ1: Main water meter 2 -m3 | AK1: Main water meter 3 -m3 | AL1: Gas | AM1: Main Gas Flow Meter -m3 | AN1: Laundry Gas Flow Meter -m3 | AO1: Gourmandize Gas Flow Meter -m3 | AP1: Room Nights
A2: Cairo at The First Residence | B2: 1 | C2: 6 | D2: 2021 | F2: =Elect!J6 -> 4739 | G2: =Elect!K6 -> 3106 | H2: =Elect!Q6 -> 510 | I2: =Elect!S6 -> 168 | J2: =Elect!U6 -> 300 | K2: =Elect!W6 -> 2728.44 | L2: =Elect!Y6 -> 0 | M2: =Elect!AA6 -> 2163.99 | N2: =Elect!AC6 -> 2095.62 | O2: =Elect!AE6 -> 0 | P2: =Elect!AG6 -> 1886.27 | Q2: =Elect!AI6 -> 1136.85 | R2: =Elect!AK6 -> 3993.02 | S2: =Elect!AM6 -> 179.67 | T2: =Elect!AP6 -> 206.6625 | U2: =Elect!AR6 -> 247 | V2: =Elect!AT6 -> 151 | W2: =Elect!AV6 -> 72 | X2: =Elect!AX6 -> 1175 | Y2: =Elect!AZ6 -> 79 | Z2: =Elect!BB6 -> 5068 | AA2: =Elect!BD6 -> 153 | AB2: =Elect!BF6 -> 89 | AC2: =Elect!BH6 -> 7923.95 | AD2: =Elect!BL6 -> 386 | AE2: =Elect!BN6 -> 1441 | AF2: =Elect!BP6 -> 128 | AG2: =Elect!BR6 -> 226 | AI2: =Water!C7 -> 203 | AJ2: =Water!E7 -> 0 | AK2: =Water!G7 -> 10.44 | AM2: =Gas!C7 -> 941.28 | AN2: =Gas!E7 -> 186.9 | AO2: =Gas!G7 -> 76 | AP2: 158
A3: Cairo at The First Residence | B3: =B2+1 -> 2 | C3: 6 | D3: 2021 | F3: =Elect!J7 -> 4842 | G3: =Elect!K7 -> 2936 | H3: =Elect!Q7 -> 480 | I3: =Elect!S7 -> 139 | J3: =Elect!U7 -> 263 | K3: =Elect!W7 -> 2643.64 | L3: =Elect!Y7 -> 2155.51 | M3: =Elect!AA7 -> 0 | N3: =Elect!AC7 -> 168.54 | O3: =Elect!AE7 -> 0 | P3: =Elect!AG7 -> 1419.34 | Q3: =Elect!AI7 -> 1122.01 | R3: =Elect!AK7 -> 3796.39 | S3: =Elect!AM7 -> 171.19 | T3: =Elect!AP7 -> 270.225 | U3: =Elect!AR7 -> 311 | V3: =Elect!AT7 -> 162 | W3: =Elect!AV7 -> 47 | X3: =Elect!AX7 -> 1109 | Y3: =Elect!AZ7 -> 70 | Z3: =Elect!BB7 -> 4673 | AA3: =Elect!BD7 -> 135 | AB3: =Elect!BF7 -> 50 | AC3: =Elect!BH7 -> 5696.4 | AD3: =Elect!BL7 -> 265 | AE3: =Elect!BN7 -> 1456 | AF3: =Elect!BP7 -> 112 | AG3: =Elect!BR7 -> 212 | AI3: =Water!C8 -> 226.2 | AJ3: =Water!E8 -> 0 | AK3: =Water!G8 -> 32.48 | AM3: =Gas!C8 -> 1069.54 | AN3: =Gas!E8 -> 148.4 | AO3: =Gas!G8 -> 80 | AP3: 158
A4: Cairo at The First Residence | B4: =B3+1 -> 3 | C4: 6 | D4: 2021 | F4: =Elect!J8 -> 4825 | G4: =Elect!K8 -> 3117 | H4: =Elect!Q8 -> 570 | I4: =Elect!S8 -> 148 | J4: =Elect!U8 -> 268 | K4: =Elect!W8 -> 2406.2 | L4: =Elect!Y8 -> 2371.22 | M4: =Elect!AA8 -> 0 | N4: =Elect!AC8 -> 0 | O4: =Elect!AE8 -> 0 | P4: =Elect!AG8 -> 1513.68 | Q4: =Elect!AI8 -> 1094.98 | R4: =Elect!AK8 -> 3894.44 | S4: =Elect!AM8 -> 183.91 | T4: =Elect!AP8 -> 239.625 | U4: =Elect!AR8 -> 386 | V4: =Elect!AT8 -> 165 | W4: =Elect!AV8 -> 50 | X4: =Elect!AX8 -> 1047 | Y4: =Elect!AZ8 -> 74 | Z4: =Elect!BB8 -> 4762 | AA4: =Elect!BD8 -> 155 | AB4: =Elect!BF8 -> 157 | AC4: =Elect!BH8 -> 5829.05 | AD4: =Elect!BL8 -> 280 | AE4: =Elect!BN8 -> 1514 | AF4: =Elect!BP8 -> 117 | AG4: =Elect!BR8 -> 223 | AI4: =Water!C9 -> 237.8 | AJ4: =Water!E9 -> 0 | AK4: =Water!G9 -> 20.3 | AM4: =Gas!C9 -> 1028.2 | AN4: =Gas!E9 -> 141.4 | AO4: =Gas!G9 -> 88 | AP4: 158
A5: Cairo at The First Residence | B5: =B4+1 -> 4 | C5: 6 | D5: 2021 | F5: =Elect!J9 -> 4408 | G5: =Elect!K9 -> 2704 | H5: =Elect!Q9 -> 450 | I5: =Elect!S9 -> 128 | J5: =Elect!U9 -> 241 | K5: =Elect!W9 -> 2819.07 | L5: =Elect!Y9 -> 1028.73 | M5: =Elect!AA9 -> 0 | N5: =Elect!AC9 -> 0 | O5: =Elect!AE9 -> 0 | P5: =Elect!AG9 -> 1275.18 | Q5: =Elect!AI9 -> 780.16 | R5: =Elect!AK9 -> 2910.76 | S5: =Elect!AM9 -> 157.94 | T5: =Elect!AP9 -> 230.85 | U5: =Elect!AR9 -> 322 | V5: =Elect!AT9 -> 144 | W5: =Elect!AV9 -> 23 | X5: =Elect!AX9 -> 726 | Y5: =Elect!AZ9 -> 64 | Z5: =Elect!BB9 -> 3881 | AA5: =Elect!BD9 -> 147 | AB5: =Elect!BF9 -> 61 | AC5: =Elect!BH9 -> 5196.6 | AD5: =Elect!BL9 -> 248 | AE5: =Elect!BN9 -> 1307 | AF5: =Elect!BP9 -> 105 | AG5: =Elect!BR9 -> 198 | AI5: =Water!C10 -> 313.2 | AJ5: =Water!E10 -> 0 | AK5: =Water!G10 -> 23.78 | AM5: =Gas!C10 -> 850.12 | AN5: =Gas!E10 -> 284.2 | AO5: =Gas!G10 -> 96 | AP5: 158
A6: Cairo at The First Residence | B6: =B5+1 -> 5 | C6: 6 | D6: 2021 | F6: =Elect!J10 -> 4951 | G6: =Elect!K10 -> 3044 | H6: =Elect!Q10 -> 510 | I6: =Elect!S10 -> 140 | J6: =Elect!U10 -> 265 | K6: =Elect!W10 -> 2545.06 | L6: =Elect!Y10 -> 1586.29 | M6: =Elect!AA10 -> 0 | N6: =Elect!AC10 -> 0 | O6: =Elect!AE10 -> 0 | P6: =Elect!AG10 -> 1370.05 | Q6: =Elect!AI10 -> 917.96 | R6: =Elect!AK10 -> 3371.33 | S6: =Elect!AM10 -> 166.95 | T6: =Elect!AP10 -> 210.9375 | U6: =Elect!AR10 -> 304 | V6: =Elect!AT10 -> 142 | W6: =Elect!AV10 -> 32 | X6: =Elect!AX10 -> 740 | Y6: =Elect!AZ10 -> 73 | Z6: =Elect!BB10 -> 4564 | AA6: =Elect!BD10 -> 162 | AB6: =Elect!BF10 -> 108 | AC6: =Elect!BH10 -> 5511.6 | AD6: =Elect!BL10 -> 213 | AE6: =Elect!BN10 -> 1368 | AF6: =Elect!BP10 -> 104 | AG6: =Elect!BR10 -> 210 | AI6: =Water!C11 -> 249.4 | AJ6: =Water!E11 -> 0 | AK6: =Water!G11 -> 27.26 | AM6: =Gas!C11 -> 1089.68 | AN6: =Gas!E11 -> 298.9 | AO6: =Gas!G11 -> 101 | AP6: 158
A7: Cairo at The First Residence | B7: =B6+1 -> 6 | C7: 6 | D7: 2021 | F7: =Elect!J11 -> 5148 | G7: =Elect!K11 -> 3203 | H7: =Elect!Q11 -> 600 | I7: =Elect!S11 -> 140 | J7: =Elect!U11 -> 263 | K7: =Elect!W11 -> 2509.55 | L7: =Elect!Y11 -> 0 | M7: =Elect!AA11 -> 2450.72 | N7: =Elect!AC11 -> 0 | O7: =Elect!AE11 -> 0 | P7: =Elect!AG11 -> 1335.6 | Q7: =Elect!AI11 -> 1023.96 | R7: =Elect!AK11 -> 3574.85 | S7: =Elect!AM11 -> 166.42 | T7: =Elect!AP11 -> 205.9875 | U7: =Elect!AR11 -> 293 | V7: =Elect!AT11 -> 137 | W7: =Elect!AV11 -> 46 | X7: =Elect!AX11 -> 750 | Y7: =Elect!AZ11 -> 72 | Z7: =Elect!BB11 -> 4275 | AA7: =Elect!BD11 -> 165 | AB7: =Elect!BF11 -> 123 | AC7: =Elect!BH11 -> 5192.6 | AD7: =Elect!BL11 -> 0 | AE7: =Elect!BN11 -> 1300 | AF7: =Elect!BP11 -> 112 | AG7: =Elect!BR11 -> 209 | AI7: =Water!C12 -> 208.8 | AJ7: =Water!E12 -> 0 | AK7: =Water!G12 -> 23.78 | AM7: =Gas!C12 -> 1062.12 | AN7: =Gas!E12 -> 308 | AO7: =Gas!G12 -> 106 | AP7: 158
A8: Cairo at The First Residence | B8: =B7+1 -> 7 | C8: 6 | D8: 2021 | F8: =Elect!J12 -> 5028 | G8: =Elect!K12 -> 3083 | H8: =Elect!Q12 -> 360 | I8: =Elect!S12 -> 138 | J8: =Elect!U12 -> 261 | K8: =Elect!W12 -> 2559.9 | L8: =Elect!Y12 -> 0 | M8: =Elect!AA12 -> 151.05 | N8: =Elect!AC12 -> 2162.93 | O8: =Elect!AE12 -> 0 | P8: =Elect!AG12 -> 1499.37 | Q8: =Elect!AI12 -> 849.06 | R8: =Elect!AK12 -> 3567.43 | S8: =Elect!AM12 -> 166.95 | T8: =Elect!AP12 -> 236.1375 | U8: =Elect!AR12 -> 295 | V8: =Elect!AT12 -> 147 | W8: =Elect!AV12 -> 52 | X8: =Elect!AX12 -> 768 | Y8: =Elect!AZ12 -> 72 | Z8: =Elect!BB12 -> 4332 | AA8: =Elect!BD12 -> 165 | AB8: =Elect!BF12 -> 139 | AC8: =Elect!BH12 -> 5686.1 | AD8: =Elect!BL12 -> 209 | AE8: =Elect!BN12 -> 1408 | AF8: =Elect!BP12 -> 114 | AG8: =Elect!BR12 -> 211 | AI8: =Water!C13 -> 197.2 | AJ8: =Water!E13 -> 0 | AK8: =Water!G13 -> 45.24 | AM8: =Gas!C13 -> 930.68 | AN8: =Gas!E13 -> 235.9 | AO8: =Gas!G13 -> 93 | AP8: 158
A9: Cairo at The First Residence | B9: =B8+1 -> 8 | C9: 6 | D9: 2021 | F9: =Elect!J13 -> 5556 | G9: =Elect!K13 -> 3452 | H9: =Elect!Q13 -> 510 | I9: =Elect!S13 -> 148 | J9: =Elect!U13 -> 282 | K9: =Elect!W13 -> 2915.53 | L9: =Elect!Y13 -> 2408.85 | M9: =Elect!AA13 -> 0 | N9: =Elect!AC13 -> 0 | O9: =Elect!AE13 -> 0 | P9: =Elect!AG13 -> 681.05 | Q9: =Elect!AI13 -> 921.14 | R9: =Elect!AK13 -> 3879.07 | S9: =Elect!AM13 -> 175.96 | T9: =Elect!AP13 -> 271.4625 | U9: =Elect!AR13 -> 283 | V9: =Elect!AT13 -> 149 | W9: =Elect!AV13 -> 52 | X9: =Elect!AX13 -> 846 | Y9: =Elect!AZ13 -> 77 | Z9: =Elect!BB13 -> 4532 | AA9: =Elect!BD13 -> 179 | AB9: =Elect!BF13 -> 34 | AC9: =Elect!BH13 -> 5772.4 | AD9: =Elect!BL13 -> 117 | AE9: =Elect!BN13 -> 1394 | AF9: =Elect!BP13 -> 114 | AG9: =Elect!BR13 -> 222 | AI9: =Water!C14 -> 208.8 | AJ9: =Water!E14 -> 0 | AK9: =Water!G14 -> 37.12 | AM9: =Gas!C14 -> 382.66 | AN9: =Gas!E14 -> 261.1 | AO9: =Gas!G14 -> 91 | AP9: 158
A10: Cairo at The First Residence | B10: =B9+1 -> 9 | C10: 6 | D10: 2021 | F10: =Elect!J14 -> 4703 | G10: =Elect!K14 -> 3078 | H10: =Elect!Q14 -> 630 | I10: =Elect!S14 -> 131 | J10: =Elect!U14 -> 253 | K10: =Elect!W14 -> 3164.63 | L10: =Elect!Y14 -> 0 | M10: =Elect!AA14 -> 1683.81 | N10: =Elect!AC14 -> 0 | O10: =Elect!AE14 -> 0 | P10: =Elect!AG14 -> 10.6 | Q10: =Elect!AI14 -> 958.77 | R10: =Elect!AK14 -> 3440.76 | S10: =Elect!AM14 -> 166.42 | T10: =Elect!AP14 -> 213.6375 | U10: =Elect!AR14 -> 275 | V10: =Elect!AT14 -> 127 | W10: =Elect!AV14 -> 56 | X10: =Elect!AX14 -> 836 | Y10: =Elect!AZ14 -> 69 | Z10: =Elect!BB14 -> 4203 | AA10: =Elect!BD14 -> 161 | AB10: =Elect!BF14 -> 121 | AC10: =Elect!BH14 -> 5080.85 | AD10: =Elect!BL14 -> 2 | AE10: =Elect!BN14 -> 1291 | AF10: =Elect!BP14 -> 96 | AG10: =Elect!BR14 -> 202 | AI10: =Water!C15 -> 201.06667 | AJ10: =Water!E15 -> 0 | AK10: =Water!G15 -> 42.533333 | AM10: =Gas!C15 -> 1322.88 | AN10: =Gas!E15 -> 182 | AO10: =Gas!G15 -> 18 | AP10: 158
A11: Cairo at The First Residence | B11: =B10+1 -> 10 | C11: 6 | D11: 2021 | F11: =Elect!J15 -> 4927 | G11: =Elect!K15 -> 3158 | H11: =Elect!Q15 -> 570 | I11: =Elect!S15 -> 140 | J11: =Elect!U15 -> 268 | K11: =Elect!W15 -> 3035.31 | L11: =Elect!Y15 -> 0 | M11: =Elect!AA15 -> 3027.36 | N11: =Elect!AC15 -> 0 | O11: =Elect!AE15 -> 9.54 | P11: =Elect!AG15 -> 11.13 | Q11: =Elect!AI15 -> 1131.02 | R11: =Elect!AK15 -> 3911.93 | S11: =Elect!AM15 -> 171.72 | T11: =Elect!AP15 -> 192.6 | U11: =Elect!AR15 -> 276 | V11: =Elect!AT15 -> 173 | W11: =Elect!AV15 -> 66 | X11: =Elect!AX15 -> 862 | Y11: =Elect!AZ15 -> 74 | Z11: =Elect!BB15 -> 4135 | AA11: =Elect!BD15 -> 170 | AB11: =Elect!BF15 -> 100 | AC11: =Elect!BH15 -> 6305.9 | AD11: =Elect!BL15 -> 251 | AE11: =Elect!BN15 -> 1446 | AF11: =Elect!BP15 -> 112 | AG11: =Elect!BR15 -> 220 | AI11: =Water!C16 -> 291.93333 | AJ11: =Water!E16 -> 0 | AK11: =Water!G16 -> 0 | AM11: =Gas!C16 -> 519.4 | AN11: =Gas!E16 -> 304.5 | AO11: =Gas!G16 -> 61 | AP11: 158
A12: Cairo at The First Residence | B12: =B11+1 -> 11 | C12: 6 | D12: 2021 | F12: =Elect!J16 -> 5329 | G12: =Elect!K16 -> 3142 | H12: =Elect!Q16 -> 540 | I12: =Elect!S16 -> 141 | J12: =Elect!U16 -> 269 | K12: =Elect!W16 -> 2849.81 | L12: =Elect!Y16 -> 0 | M12: =Elect!AA16 -> 2613.96 | N12: =Elect!AC16 -> 0 | O12: =Elect!AE16 -> 4.24 | P12: =Elect!AG16 -> 11.13 | Q12: =Elect!AI16 -> 965.13 | R12: =Elect!AK16 -> 3505.95 | S12: =Elect!AM16 -> 158.47 | T12: =Elect!AP16 -> 212.0625 | U12: =Elect!AR16 -> 304 | V12: =Elect!AT16 -> 178 | W12: =Elect!AV16 -> 53 | X12: =Elect!AX16 -> 801 | Y12: =Elect!AZ16 -> 74 | Z12: =Elect!BB16 -> 4562 | AA12: =Elect!BD16 -> 171 | AB12: =Elect!BF16 -> 125 | AC12: =Elect!BH16 -> 5843.65 | AD12: =Elect!BL16 -> 256 | AE12: =Elect!BN16 -> 1325 | AF12: =Elect!BP16 -> 98 | AG12: =Elect!BR16 -> 203 | AI12: =Water!C17 -> 179.8 | AJ12: =Water!E17 -> 0 | AK12: =Water!G17 -> 0 | AM12: =Gas!C17 -> 1094.98 | AN12: =Gas!E17 -> 279.3 | AO12: =Gas!G17 -> 75 | AP12: 158
A13: Cairo at The First Residence | B13: =B12+1 -> 12 | C13: 6 | D13: 2021 | F13: =Elect!J17 -> 5210 | G13: =Elect!K17 -> 3334 | H13: =Elect!Q17 -> 540 | I13: =Elect!S17 -> 141 | J13: =Elect!U17 -> 275 | K13: =Elect!W17 -> 3205.44 | L13: =Elect!Y17 -> 2405.14 | M13: =Elect!AA17 -> 35.51 | N13: =Elect!AC17 -> 0 | O13: =Elect!AE17 -> 8.48 | P13: =Elect!AG17 -> 11.13 | Q13: =Elect!AI17 -> 1041.98 | R13: =Elect!AK17 -> 3879.07 | S13: =Elect!AM17 -> 172.78 | T13: =Elect!AP17 -> 201.6 | U13: =Elect!AR17 -> 244 | V13: =Elect!AT17 -> 153 | W13: =Elect!AV17 -> 59 | X13: =Elect!AX17 -> 856 | Y13: =Elect!AZ17 -> 75 | Z13: =Elect!BB17 -> 4891 | AA13: =Elect!BD17 -> 179 | AB13: =Elect!BF17 -> 114 | AC13: =Elect!BH17 -> 6214.2 | AD13: =Elect!BL17 -> 270 | AE13: =Elect!BN17 -> 1401 | AF13: =Elect!BP17 -> 103 | AG13: =Elect!BR17 -> 212 | AI13: =Water!C18 -> 336.4 | AJ13: =Water!E18 -> 0 | AK13: =Water!G18 -> 0 | AM13: =Gas!C18 -> 1193.56 | AN13: =Gas!E18 -> 212.8 | AO13: =Gas!G18 -> 64 | AP13: 158
A14: Cairo at The First Residence | B14: =B13+1 -> 13 | C14: 6 | D14: 2021 | F14: =Elect!J18 -> 5191 | G14: =Elect!K18 -> 3314 | H14: =Elect!Q18 -> 630 | I14: =Elect!S18 -> 137 | J14: =Elect!U18 -> 267 | K14: =Elect!W18 -> 3123.29 | L14: =Elect!Y18 -> 2871.54 | M14: =Elect!AA18 -> 0 | N14: =Elect!AC18 -> 0 | O14: =Elect!AE18 -> 5.83 | P14: =Elect!AG18 -> 19.61 | Q14: =Elect!AI18 -> 1076.96 | R14: =Elect!AK18 -> 3978.18 | S14: =Elect!AM18 -> 169.6 | T14: =Elect!AP18 -> 203.4 | U14: =Elect!AR18 -> 281 | V14: =Elect!AT18 -> 151 | W14: =Elect!AV18 -> 60 | X14: =Elect!AX18 -> 849 | Y14: =Elect!AZ18 -> 74 | Z14: =Elect!BB18 -> 4662 | AA14: =Elect!BD18 -> 171 | AB14: =Elect!BF18 -> 119 | AC14: =Elect!BH18 -> 5828.3 | AD14: =Elect!BL18 -> 253 | AE14: =Elect!BN18 -> 1340 | AF14: =Elect!BP18 -> 106 | AG14: =Elect!BR18 -> 204 | AI14: =Water!C19 -> 168.2 | AJ14: =Water!E19 -> 0 | AK14: =Water!G19 -> 0 | AM14: =Gas!C19 -> 776.98 | AN14: =Gas!E19 -> 179.2 | AO14: =Gas!G19 -> 63 | AP14: 158
... A31: Cairo at The First Residence | B31: =B30+1 -> 30 | C31: 6 | D31: 2021 | F31: =Elect!J35 -> 5721 | G31: =Elect!K35 -> 3425 | H31: =Elect!Q35 -> 540 | I31: =Elect!S35 -> 147 | J31: =Elect!U35 -> 293 | K31: =Elect!W35 -> 3454.01 | L31: =Elect!Y35 -> 1867.19 | M31: =Elect!AA35 -> 3451.89 | N31: =Elect!AC35 -> 33.92 | O31: =Elect!AE35 -> 1196.21 | P31: =Elect!AG35 -> 1436.83 | Q31: =Elect!AI35 -> 1291.08 | R31: =Elect!AK35 -> 4313.14 | S31: =Elect!AM35 -> 184.97 | T31: =Elect!AP35 -> 197.4375 | U31: =Elect!AR35 -> 243 | V31: =Elect!AT35 -> 160 | W31: =Elect!AV35 -> 53 | X31: =Elect!AX35 -> 937 | Y31: =Elect!AZ35 -> 66 | Z31: =Elect!BB35 -> 4746 | AA31: =Elect!BD35 -> 192 | AB31: =Elect!BF35 -> 83 | AC31: =Elect!BH35 -> 5949.95 | AD31: =Elect!BL35 -> 59 | AE31: =Elect!BN35 -> 1522 | AF31: =Elect!BP35 -> 107 | AG31: =Elect!BR35 -> 230 | AI31: =Water!C36 -> 284.2 | AJ31: =Water!E36 -> 0 | AK31: =Water!G36 -> 0 | AM31: =Gas!C36 -> 831.04 | AN31: =Gas!E36 -> 162.4 | AO31: =Gas!G36 -> 65 | AP31: 158
A32: Cairo at The First Residence | B32: =B31+1 -> 31 | C32: 6 | D32: 2021 | F32: =Elect!J36 -> 0 | G32: =Elect!K36 -> 0 | H32: =Elect!Q36 -> 0 | I32: =Elect!S36 -> 0 | J32: =Elect!U36 -> 0 | K32: =Elect!W36 -> 0 | L32: =Elect!Y36 -> 0 | M32: =Elect!AA36 -> 0 | N32: =Elect!AC36 -> 0 | O32: =Elect!AE36 -> 0 | P32: =Elect!AG36 -> 0 | Q32: =Elect!AI36 -> 0 | R32: =Elect!AK36 -> 0 | S32: =Elect!AM36 -> 0 | T32: =Elect!AP36 -> 0 | U32: =Elect!AR36 -> 0 | V32: =Elect!AT36 -> 0 | W32: =Elect!AV36 -> 0 | X32: =Elect!AX36 -> 0 | Y32: =Elect!AZ36 -> 0 | Z32: =Elect!BB36 -> 0 | AA32: =Elect!BD36 -> 0 | AB32: =Elect!BF36 -> 0 | AC32: =Elect!BH36 -> 0 | AD32: =Elect!BL36 -> 0 | AE32: =Elect!BN36 -> 0 | AF32: =Elect!BP36 -> 0 | AG32: =Elect!BR36 -> 0 | AI32: =Water!C37 -> 0 | AJ32: =Water!E37 -> 0 | AK32: =Water!G37 -> 0 | AM32: =Gas!C37 -> 0 | AN32: =Gas!E37 -> 0 | AO32: =Gas!G37 -> 0 | AP32: =Elect!CY36 -> 0

Sheet Elect
A1: June | M1: Electricity | BP1: Gourmandise UP | BR1: 1.6 | BS1: Power Taxes | BU1: Max Demand | BW1: 500 | BX1: Electricity UP | BZ1: 1.15
AD2: Chiller 5 Meter was miswired and was corrected on 21st | BS2: Light Taxes | BU2: PF Penalty | BX2: Max. Demand UP | BZ2: 30
A3: Date | B3: COUNTER (1) | D3: MD | F3: KVAR | H3: n | I3: Guest Rooms Consumption | R3: Casino Consumption | V3: Plant Room Shared Loads | AO3: To Be Charged By First Arabian | BK3: From Main Panel G2 | BS3: Total Consumption. | BT3: No. Of | BU3: KWH/ | BV3: No. Of | BW3: KWH/ | BX3: Total Cost | BY3: L.E\ | BZ3: L.E\
B4: Reading | C4: Consp. F: *800 | D4: Reading | E4: Consp F: 80 | F4: Reading | G4: Consp. F:*10 | I4: Main Feeder | J4: Consp | K4: T2+T8 | L4: Trans T2 | M4: Consp | N4: Trans T8 | O4: Consp | P4: La Gourmandize | Q4: Consp *30 | R4: Casino 3rd floor EM | S4: Consp | T4: Casino 3rd floor Normal | U4: Consp | V4: Chiller 1 | W4: Consp 53% | X4: Chiller 2 | Y4: Consp 53% | Z4: Chiller 3 | AA4: Consp 53% | AB4: Chiller 4 | AC4: Consp 53% | AD4: Chiller 5 | AE4: Consp 53% | AF4: Chiller 6 | AG4: Consp 53% | AH4: Cooling Towers | AI4: Consp 53% | AJ4: Chiller Pumps | AK4: Consp 53% | AL4: Cooling Tower Pumps | AM4: Consp 53% | AN4: Total Plant Room Consp | AO4: Fiber Chiller (N24) | AP4: Consp | AQ4: Mall Ceiling light (N4) | AR4: Consp | AS4: LG Bakery (N2) | AT4: Consp | AU4: LG Bakery light ( Old lockers ) | AV4: Consp | AW4: MCCR1 | AX4: Consp | AY4: Children Swimming pool | AZ4: Consp | BA4: DPH1 | BB4: Consp | BC4: Guest Rooms Emergency | BD4: Consp | BE4: Hotel Hoods | BF4: Consp | BG4: Main G2 | BH4: Consp | BI4: Total Consp From First Arabian | BJ4: First Arabian Charge Back | BK4: Old Casino Emergency | BL4: Consp | BM4: L / A | BN4: Consp | BO4: L / B | BP4: Consp | BQ4: L / C | BR4: Consp | BT4: Rooms | BU4: room | BV4: guest | BW4: guest | BY4: Room | BZ4: Guest
A5: Last Month Reading | I5: 22590286 | J5: =IF(I5>=I4,I5-I4,0) -> 0 | K5: =M5+O5 -> 0 | L5: 164375 | M5: =IF(L5>=L4,L5-L4,0) -> 0 | N5: 181359 | O5: =IF(N5>=N4,N5-N4,0) -> 0 | P5: 217068 | Q5: =IF(P5>=P4,P5-P4,0)*30 -> 0 | R5: 148148 | S5: =IF(R5>=R4,R5-R4,0) -> 0 | T5: 268811 | U5: =IF(T5>=T4,T5-T4,0) -> 0 | V5: 740296 | W5: =IF(V5>=V4,V5-V4,0)*0.53 -> 0 | X5: 434694 | Y5: =IF(X5>=X4,X5-X4,0)*0.53 -> 0 | Z5: 690715 | AA5: =IF(Z5>=Z4,Z5-Z4,0)*0.53 -> 0 | AB5: 324857 | AC5: =IF(AB5>=AB4,AB5-AB4,0)*0.53 -> 0 | AD5: 421367.4 | AE5: =IF(AD5>=AD4,AD5-AD4,0)*0.53 -> 0 | AF5: 745569 | AG5: =IF(AF5>=AF4,AF5-AF4,0)*0.53 -> 0 | AH5: 648195 | AI5: =IF(AH5>=AH4,AH5-AH4,0)*0.53 -> 0 | AJ5: 277404 | AK5: =IF(AJ5>=AJ4,AJ5-AJ4,0)*0.53 -> 0 | AL5: 417958 | AM5: =IF(AL5>=AL4,AL5-AL4,0)*0.53 -> 0 | AN5: =W5+Y5+AA5+AC5+AE5+AG5+AI5+AK5+AM5 -> 0 | AO5: 7315006 | AP5: =IF(AO5>=AO4,AO5-AO4,0)*0.1125 -> 0 | AQ5: 611191 | AR5: =IF(AQ5>=AQ4,AQ5-AQ4,0) -> 0 | AS5: 927541 | AT5: =IF(AS5>=AS4,AS5-AS4,0) -> 0 | AU5: 798914 | AV5: =IF(AU5>=AU4,AU5-AU4,0) -> 0 | AW5: 2406790 | AX5: =IF(AW5>=AW4,AW5-AW4,0) -> 0 | AY5: 215052 | AZ5: =IF(AY5>=AY4,AY5-AY4,0) -> 0 | BA5: 18119598 | BB5: =IF(BA5>=BA4,BA5-BA4,0) -> 0 | BC5: 512642 | BD5: =IF(BC5>=BC4,BC5-BC4,0) -> 0 | BE5: 9263 | BF5: =IF(BE5>=BE4,BE5-BE4,0) -> 0 | BG5: 22567804 | BH5: =IF(BG5>=BG4,BG5-BG4,0)-(0.45*BN5)-(0.45*BP5)-BR5 -> 0 | BI5: =AP5+AR5+AT5+AV5+AX5+AZ5+BB5+BD5+BF5+BH5 -> 0 | BJ5: =BI5+AN5 -> 0 | BK5: 1389277 | BL5: =IF(BK5>=BK4,BK5-BK4,0) -> 0 | BM5: 3618486 | BN5: =IF(BM5>=BM4,BM5-BM4,0) -> 0 | BO5: 385840 | BP5: =IF(BO5>=BO4,BO5-BO4,0) -> 0 | BQ5: 476466 | BR5: =IF(BQ5>=BQ4,BQ5-BQ4,0) -> 0
A6: 1 | C6: =IF(+B6-B5>0,B6-B5,(B6-B5)>0)*800 -> 0 | E6: =IF(+D6-D5>0,D6-D5,(D6-D5)>0)*80 -> 0 | G6: =IF(+F6-F5>0,F6-F5,(F6-F5)>0)*10 -> 0 | H6: 56 | I6: 22595025 | J6: =IF(I6>=I5,I6-I5,0) -> 4739 | K6: =M6+O6 -> 3106 | L6: 165884 | M6: =IF(L6>=L5,L6-L5,0) -> 1509 | N6: 182956 | O6: =IF(N6>=N5,N6-N5,0) -> 1597 | P6: 217085 | Q6: =IF(P6>=P5,P6-P5,0)*30 -> 510 | R6: 148316 | S6: =IF(R6>=R5,R6-R5,0) -> 168 | T6: 269111 | U6: =IF(T6>=T5,T6-T5,0) -> 300 | V6: 745444 | W6: =IF(V6>=V5,V6-V5,0)*0.53 -> 2728.44 | X6: 434694 | Y6: =IF(X6>=X5,X6-X5,0)*0.53 -> 0 | Z6: 694798 | AA6: =IF(Z6>=Z5,Z6-Z5,0)*0.53 -> 2163.99 | AB6: 328811 | AC6: =IF(AB6>=AB5,AB6-AB5,0)*0.53 -> 2095.62 | AD6: 421367.4 | AE6: =IF(AD6>=AD5,AD6-AD5,0)*0.53 -> 0 | AF6: 749128 | AG6: =IF(AF6>=AF5,AF6-AF5,0)*0.53 -> 1886.27 | AH6: 650340 | AI6: =IF(AH6>=AH5,AH6-AH5,0)*0.53 -> 1136.85 | AJ6: 284938 | AK6: =IF(AJ6>=AJ5,AJ6-AJ5,0)*0.53 -> 3993.02 | AL6: 418297 | AM6: =IF(AL6>=AL5,AL6-AL5,0)*0.53 -> 179.67 | AN6: =W6+Y6+AA6+AC6+AE6+AG6+AI6+AK6+AM6 -> 14183.86 | AO6: 7316843 | AP6: =IF(AO6>=AO5,AO6-AO5,0)*0.1125 -> 206.6625 | AQ6: 611438 | AR6: =IF(AQ6>=AQ5,AQ6-AQ5,0) -> 247 | AS6: 927692 | AT6: =IF(AS6>=AS5,AS6-AS5,0) -> 151 | AU6: 798986 | AV6: =IF(AU6>=AU5,AU6-AU5,0) -> 72 | AW6: 2407965 | AX6: =IF(AW6>=AW5,AW6-AW5,0) -> 1175 | AY6: 215131 | AZ6: =IF(AY6>=AY5,AY6-AY5,0) -> 79 | BA6: 18124666 | BB6: =IF(BA6>=BA5,BA6-BA5,0) -> 5068 | BC6: 512795 | BD6: =IF(BC6>=BC5,BC6-BC5,0) -> 153 | BE6: 9352 | BF6: =IF(BE6>=BE5,BE6-BE5,0) -> 89 | BG6: 22576660 | BH6: =IF(BG6>=BG5,BG6-BG5,0)-(0.45*BN6)-(0.45*BP6)-BR6 -> 7923.95 | BI6: =AP6+AR6+AT6+AV6+AX6+AZ6+BB6+BD6+BF6+BH6 -> 15164.612 | BJ6: =BI6+AN6 -> 29348.472 | BK6: 1389663 | BL6: =IF(BK6>=BK5,BK6-BK5,0) -> 386 | BM6: 3619927 | BN6: =IF(BM6>=BM5,BM6-BM5,0) -> 1441 | BO6: 385968 | BP6: =IF(BO6>=BO5,BO6-BO5,0) -> 128 | BQ6: 476692 | BR6: =IF(BQ6>=BQ5,BQ6-BQ5,0) -> 226 | BS6: =J6+Q6+AN6+BI6 -> 34597.473 | BT6: 94 | BU6: =IF(BS6>0,BS6/BT5,0) -> #DIV/0! | BW6: =IF(BS6>0,BS6/BV6,0) -> #DIV/0! | BX6: =((BS6-Q6)*$BZ$1)+(Q6*$BR$1) -> 40016.593 | BY6: =IF(BX6>0,BX6/BT5,0) -> #DIV/0! | BZ6: =IF(BX6>0,BX6/BV6,0) -> #DIV/0!
A7: 2 | I7: 22599867 | J7: =IF(I7>=I6,I7-I6,0) -> 4842 | K7: =M7+O7 -> 2936 | L7: 167264 | M7: =IF(L7>=L6,L7-L6,0) -> 1380 | N7: 184512 | O7: =IF(N7>=N6,N7-N6,0) -> 1556 | P7: 217101 | Q7: =IF(P7>=P6,P7-P6,0)*30 -> 480 | R7: 148455 | S7: =IF(R7>=R6,R7-R6,0) -> 139 | T7: 269374 | U7: =IF(T7>=T6,T7-T6,0) -> 263 | V7: 750432 | W7: =IF(V7>=V6,V7-V6,0)*0.53 -> 2643.64 | X7: 438761 | Y7: =IF(X7>=X6,X7-X6,0)*0.53 -> 2155.51 | Z7: 694798 | AA7: =IF(Z7>=Z6,Z7-Z6,0)*0.53 -> 0 | AB7: 329129 | AC7: =IF(AB7>=AB6,AB7-AB6,0)*0.53 -> 168.54 | AD7: 421367.4 | AE7: =IF(AD7>=AD6,AD7-AD6,0)*0.53 -> 0 | AF7: 751806 | AG7: =IF(AF7>=AF6,AF7-AF6,0)*0.53 -> 1419.34 | AH7: 652457 | AI7: =IF(AH7>=AH6,AH7-AH6,0)*0.53 -> 1122.01 | AJ7: 292101 | AK7: =IF(AJ7>=AJ6,AJ7-AJ6,0)*0.53 -> 3796.39 | AL7: 418620 | AM7: =IF(AL7>=AL6,AL7-AL6,0)*0.53 -> 171.19 | AN7: =W7+Y7+AA7+AC7+AE7+AG7+AI7+AK7+AM7 -> 11476.62 | AO7: 7319245 | AP7: =IF(AO7>=AO6,AO7-AO6,0)*0.1125 -> 270.225 | AQ7: 611749 | AR7: =IF(AQ7>=AQ6,AQ7-AQ6,0) -> 311 | AS7: 927854 | AT7: =IF(AS7>=AS6,AS7-AS6,0) -> 162 | AU7: 799033 | AV7: =IF(AU7>=AU6,AU7-AU6,0) -> 47 | AW7: 2409074 | AX7: =IF(AW7>=AW6,AW7-AW6,0) -> 1109 | AY7: 215201 | AZ7: =IF(AY7>=AY6,AY7-AY6,0) -> 70 | BA7: 18129339 | BB7: =IF(BA7>=BA6,BA7-BA6,0) -> 4673 | BC7: 512930 | BD7: =IF(BC7>=BC6,BC7-BC6,0) -> 135 | BE7: 9402 | BF7: =IF(BE7>=BE6,BE7-BE6,0) -> 50 | BG7: 22583274 | BH7: =IF(BG7>=BG6,BG7-BG6,0)-(0.45*BN7)-(0.45*BP7)-BR7 -> 5696.4 | BI7: =AP7+AR7+AT7+AV7+AX7+AZ7+BB7+BD7+BF7+BH7 -> 12523.625 | BJ7: =BI7+AN7 -> 24000.245 | BK7: 1389928 | BL7: =IF(BK7>=BK6,BK7-BK6,0) -> 265 | BM7: 3621383 | BN7: =IF(BM7>=BM6,BM7-BM6,0) -> 1456 | BO7: 386080 | BP7: =IF(BO7>=BO6,BO7-BO6,0) -> 112 | BQ7: 476904 | BR7: =IF(BQ7>=BQ6,BQ7-BQ6,0) -> 212 | BS7: =J7+Q7+AN7+BI7 -> 29322.245 | BT7: 125 | BU7: =IF(BS7>0,BS7/BT6,0) -> 311.93878 | BW7: =IF(BS7>0,BS7/BV7,0) -> #DIV/0! | BX7: =((BS7-Q7)*$BZ$1)+(Q7*$BR$1) -> 33936.582 | BY7: =IF(BX7>0,BX7/BT6,0) -> 361.02747 | BZ7: =IF(BX7>0,BX7/BV7,0) -> #DIV/0!
A8: 3 | C8: =IF(+B8-B7>0,B8-B7,(B8-B7)>0)*800 -> 0 | E8: =IF(+D8-D7>0,D8-D7,(D8-D7)>0)*80 -> 0 | G8: =IF(+F8-F7>0,F8-F7,(F8-F7)>0)*10 -> 0 | H8: 57 | I8: 22604692 | J8: =IF(I8>=I7,I8-I7,0) -> 4825 | K8: =M8+O8 -> 3117 | L8: 168812 | M8: =IF(L8>=L7,L8-L7,0) -> 1548 | N8: 186081 | O8: =IF(N8>=N7,N8-N7,0) -> 1569 | P8: 217120 | Q8: =IF(P8>=P7,P8-P7,0)*30 -> 570 | R8: 148603 | S8: =IF(R8>=R7,R8-R7,0) -> 148 | T8: 269642 | U8: =IF(T8>=T7,T8-T7,0) -> 268 | V8: 754972 | W8: =IF(V8>=V7,V8-V7,0)*0.53 -> 2406.2 | X8: 443235 | Y8: =IF(X8>=X7,X8-X7,0)*0.53 -> 2371.22 | Z8: 694798 | AA8: =IF(Z8>=Z7,Z8-Z7,0)*0.53 -> 0 | AB8: 329129 | AC8: =IF(AB8>=AB7,AB8-AB7,0)*0.53 -> 0 | AD8: 421367.4 | AE8: =IF(AD8>=AD7,AD8-AD7,0)*0.53 -> 0 | AF8: 754662 | AG8: =IF(AF8>=AF7,AF8-AF7,0)*0.53 -> 1513.68 | AH8: 654523 | AI8: =IF(AH8>=AH7,AH8-AH7,0)*0.53 -> 1094.98 | AJ8: 299449 | AK8: =IF(AJ8>=AJ7,AJ8-AJ7,0)*0.53 -> 3894.44 | AL8: 418967 | AM8: =IF(AL8>=AL7,AL8-AL7,0)*0.53 -> 183.91 | AN8: =W8+Y8+AA8+AC8+AE8+AG8+AI8+AK8+AM8 -> 11464.43 | AO8: 7321375 | AP8: =IF(AO8>=AO7,AO8-AO7,0)*0.1125 -> 239.625 | AQ8: 612135 | AR8: =IF(AQ8>=AQ7,AQ8-AQ7,0) -> 386 | AS8: 928019 | AT8: =IF(AS8>=AS7,AS8-AS7,0) -> 165 | AU8: 799083 | AV8: =IF(AU8>=AU7,AU8-AU7,0) -> 50 | AW8: 2410121 | AX8: =IF(AW8>=AW7,AW8-AW7,0) -> 1047 | AY8: 215275 | AZ8: =IF(AY8>=AY7,AY8-AY7,0) -> 74 | BA8: 18134101 | BB8: =IF(BA8>=BA7,BA8-BA7,0) -> 4762 | BC8: 513085 | BD8: =IF(BC8>=BC7,BC8-BC7,0) -> 155 | BE8: 9559 | BF8: =IF(BE8>=BE7,BE8-BE7,0) -> 157 | BG8: 22590060 | BH8: =IF(BG8>=BG7,BG8-BG7,0)-(0.45*BN8)-(0.45*BP8)-BR8 -> 5829.05 | BI8: =AP8+AR8+AT8+AV8+AX8+AZ8+BB8+BD8+BF8+BH8 -> 12864.675 | BJ8: =BI8+AN8 -> 24329.105 | BK8: 1390208 | BL8: =IF(BK8>=BK7,BK8-BK7,0) -> 280 | BM8: 3622897 | BN8: =IF(BM8>=BM7,BM8-BM7,0) -> 1514 | BO8: 386197 | BP8: =IF(BO8>=BO7,BO8-BO7,0) -> 117 | BQ8: 477127 | BR8: =IF(BQ8>=BQ7,BQ8-BQ7,0) -> 223 | BS8: =J8+Q8+AN8+BI8 -> 29724.105 | BT8: 135 | BU8: =IF(BS8>0,BS8/BT7,0) -> 237.79284 | BW8: =IF(BS8>0,BS8/BV8,0) -> #DIV/0! | BX8: =((BS8-Q8)*$BZ$1)+(Q8*$BR$1) -> 34439.221 | BY8: =IF(BX8>0,BX8/BT7,0) -> 275.51377 | BZ8: =IF(BX8>0,BX8/BV8,0) -> #DIV/0!
A9: 4 | C9: =IF(+B9-B8>0,B9-B8,(B9-B8)>0)*800 -> 0 | E9: =IF(+D9-D8>0,D9-D8,(D9-D8)>0)*80 -> 0 | G9: =IF(+F9-F8>0,F9-F8,(F9-F8)>0)*10 -> 0 | I9: 22609100 | J9: =IF(I9>=I8,I9-I8,0) -> 4408 | K9: =M9+O9 -> 2704 | L9: 170292 | M9: =IF(L9>=L8,L9-L8,0) -> 1480 | N9: 187305 | O9: =IF(N9>=N8,N9-N8,0) -> 1224 | P9: 217135 | Q9: =IF(P9>=P8,P9-P8,0)*30 -> 450 | R9: 148731 | S9: =IF(R9>=R8,R9-R8,0) -> 128 | T9: 269883 | U9: =IF(T9>=T8,T9-T8,0) -> 241 | V9: 760291 | W9: =IF(V9>=V8,V9-V8,0)*0.53 -> 2819.07 | X9: 445176 | Y9: =IF(X9>=X8,X9-X8,0)*0.53 -> 1028.73 | Z9: 694798 | AA9: =IF(Z9>=Z8,Z9-Z8,0)*0.53 -> 0 | AB9: 329129 | AC9: =IF(AB9>=AB8,AB9-AB8,0)*0.53 -> 0 | AD9: 421367.4 | AE9: =IF(AD9>=AD8,AD9-AD8,0)*0.53 -> 0 | AF9: 757068 | AG9: =IF(AF9>=AF8,AF9-AF8,0)*0.53 -> 1275.18 | AH9: 655995 | AI9: =IF(AH9>=AH8,AH9-AH8,0)*0.53 -> 780.16 | AJ9: 304941 | AK9: =IF(AJ9>=AJ8,AJ9-AJ8,0)*0.53 -> 2910.76 | AL9: 419265 | AM9: =IF(AL9>=AL8,AL9-AL8,0)*0.53 -> 157.94 | AN9: =W9+Y9+AA9+AC9+AE9+AG9+AI9+AK9+AM9 -> 8971.84 | AO9: 7323427 | AP9: =IF(AO9>=AO8,AO9-AO8,0)*0.1125 -> 230.85 | AQ9: 612457 | AR9: =IF(AQ9>=AQ8,AQ9-AQ8,0) -> 322 | AS9: 928163 | AT9: =IF(AS9>=AS8,AS9-AS8,0) -> 144 | AU9: 799106 | AV9: =IF(AU9>=AU8,AU9-AU8,0) -> 23 | AW9: 2410847 | AX9: =IF(AW9>=AW8,AW9-AW8,0) -> 726 | AY9: 215339 | AZ9: =IF(AY9>=AY8,AY9-AY8,0) -> 64 | BA9: 18137982 | BB9: =IF(BA9>=BA8,BA9-BA8,0) -> 3881 | BC9: 513232 | BD9: =IF(BC9>=BC8,BC9-BC8,0) -> 147 | BE9: 9620 | BF9: =IF(BE9>=BE8,BE9-BE8,0) -> 61 | BG9: 22596090 | BH9: =IF(BG9>=BG8,BG9-BG8,0)-(0.45*BN9)-(0.45*BP9)-BR9 -> 5196.6 | BI9: =AP9+AR9+AT9+AV9+AX9+AZ9+BB9+BD9+BF9+BH9 -> 10795.45 | BJ9: =BI9+AN9 -> 19767.29 | BK9: 1390456 | BL9: =IF(BK9>=BK8,BK9-BK8,0) -> 248 | BM9: 3624204 | BN9: =IF(BM9>=BM8,BM9-BM8,0) -> 1307 | BO9: 386302 | BP9: =IF(BO9>=BO8,BO9-BO8,0) -> 105 | BQ9: 477325 | BR9: =IF(BQ9>=BQ8,BQ9-BQ8,0) -> 198 | BS9: =J9+Q9+AN9+BI9 -> 24625.29 | BT9: 171 | BU9: =IF(BS9>0,BS9/BT8,0) -> 182.40956 | BW9: =IF(BS9>0,BS9/BV9,0) -> #DIV/0! | BX9: =((BS9-Q9)*$BZ$1)+(Q9*$BR$1) -> 28521.584 | BY9: =IF(BX9>0,BX9/BT8,0) -> 211.27099 | BZ9: =IF(BX9>0,BX9/BV9,0) -> #DIV/0!
A10: 5 | C10: =IF(+B10-B9>0,B10-B9,(B10-B9)>0)*800 -> 0 | E10: =IF(+D10-D9>0,D10-D9,(D10-D9)>0)*80 -> 0 | G10: =IF(+F10-F9>0,F10-F9,(F10-F9)>0)*10 -> 0 | H10: 58 | I10: 22614051 | J10: =IF(I10>=I9,I10-I9,0) -> 4951 | K10: =M10+O10 -> 3044 | L10: 171920 | M10: =IF(L10>=L9,L10-L9,0) -> 1628 | N10: 188721 | O10: =IF(N10>=N9,N10-N9,0) -> 1416 | P10: 217152 | Q10: =IF(P10>=P9,P10-P9,0)*30 -> 510 | R10: 148871 | S10: =IF(R10>=R9,R10-R9,0) -> 140 | T10: 270148 | U10: =IF(T10>=T9,T10-T9,0) -> 265 | V10: 765093 | W10: =IF(V10>=V9,V10-V9,0)*0.53 -> 2545.06 | X10: 448169 | Y10: =IF(X10>=X9,X10-X9,0)*0.53 -> 1586.29 | Z10: 694798 | AA10: =IF(Z10>=Z9,Z10-Z9,0)*0.53 -> 0 | AB10: 329129 | AC10: =IF(AB10>=AB9,AB10-AB9,0)*0.53 -> 0 | AD10: 421367.4 | AE10: =IF(AD10>=AD9,AD10-AD9,0)*0.53 -> 0 | AF10: 759653 | AG10: =IF(AF10>=AF9,AF10-AF9,0)*0.53 -> 1370.05 | AH10: 657727 | AI10: =IF(AH10>=AH9,AH10-AH9,0)*0.53 -> 917.96 | AJ10: 311302 | AK10: =IF(AJ10>=AJ9,AJ10-AJ9,0)*0.53 -> 3371.33 | AL10: 419580 | AM10: =IF(AL10>=AL9,AL10-AL9,0)*0.53 -> 166.95 | AN10: =W10+Y10+AA10+AC10+AE10+AG10+AI10+AK10+AM10 -> 9957.64 | AO10: 7325302 | AP10: =IF(AO10>=AO9,AO10-AO9,0)*0.1125 -> 210.9375 | AQ10: 612761 | AR10: =IF(AQ10>=AQ9,AQ10-AQ9,0) -> 304 | AS10: 928305 | AT10: =IF(AS10>=AS9,AS10-AS9,0) -> 142 | AU10: 799138 | AV10: =IF(AU10>=AU9,AU10-AU9,0) -> 32 | AW10: 2411587 | AX10: =IF(AW10>=AW9,AW10-AW9,0) -> 740 | AY10: 215412 | AZ10: =IF(AY10>=AY9,AY10-AY9,0) -> 73 | BA10: 18142546 | BB10: =IF(BA10>=BA9,BA10-BA9,0) -> 4564 | BC10: 513394 | BD10: =IF(BC10>=BC9,BC10-BC9,0) -> 162 | BE10: 9728 | BF10: =IF(BE10>=BE9,BE10-BE9,0) -> 108 | BG10: 22602474 | BH10: =IF(BG10>=BG9,BG10-BG9,0)-(0.45*BN10)-(0.45*BP10)-BR10 -> 5511.6 | BI10: =AP10+AR10+AT10+AV10+AX10+AZ10+BB10+BD10+BF10+BH10 -> 11847.537 | BJ10: =BI10+AN10 -> 21805.177 | BK10: 1390669 | BL10: =IF(BK10>=BK9,BK10-BK9,0) -> 213 | BM10: 3625572 | BN10: =IF(BM10>=BM9,BM10-BM9,0) -> 1368 | BO10: 386406 | BP10: =IF(BO10>=BO9,BO10-BO9,0) -> 104 | BQ10: 477535 | BR10: =IF(BQ10>=BQ9,BQ10-BQ9,0) -> 210 | BS10: =J10+Q10+AN10+BI10 -> 27266.177 | BT10: 160 | BU10: =IF(BS10>0,BS10/BT9,0) -> 159.45133 | BW10: =IF(BS10>0,BS10/BV10,0) -> #DIV/0! | BX10: =((BS10-Q10)*$BZ$1)+(Q10*$BR$1) -> 31585.604 | BY10: =IF(BX10>0,BX10/BT9,0) -> 184.71114 | BZ10: =IF(BX10>0,BX10/BV10,0) -> #DIV/0!
A11: 6 | C11: =IF(+B11-B10>0,B11-B10,(B11-B10)>0)*800 -> 0 | E11: =IF(+D11-D10>0,D11-D10,(D11-D10)>0)*80 -> 0 | G11: =IF(+F11-F10>0,F11-F10,(F11-F10)>0)*10 -> 0 | I11: 22619199 | J11: =IF(I11>=I10,I11-I10,0) -> 5148 | K11: =M11+O11 -> 3203 | L11: 173548 | M11: =IF(L11>=L10,L11-L10,0) -> 1628 | N11: 190296 | O11: =IF(N11>=N10,N11-N10,0) -> 1575 | P11: 217172 | Q11: =IF(P11>=P10,P11-P10,0)*30 -> 600 | R11: 149011 | S11: =IF(R11>=R10,R11-R10,0) -> 140 | T11: 270411 | U11: =IF(T11>=T10,T11-T10,0) -> 263 | V11: 769828 | W11: =IF(V11>=V10,V11-V10,0)*0.53 -> 2509.55 | X11: 448169 | Y11: =IF(X11>=X10,X11-X10,0)*0.53 -> 0 | Z11: 699422 | AA11: =IF(Z11>=Z10,Z11-Z10,0)*0.53 -> 2450.72 | AB11: 329129 | AC11: =IF(AB11>=AB10,AB11-AB10,0)*0.53 -> 0 | AD11: 421367.4 | AE11: =IF(AD11>=AD10,AD11-AD10,0)*0.53 -> 0 | AF11: 762173 | AG11: =IF(AF11>=AF10,AF11-AF10,0)*0.53 -> 1335.6 | AH11: 659659 | AI11: =IF(AH11>=AH10,AH11-AH10,0)*0.53 -> 1023.96 | AJ11: 318047 | AK11: =IF(AJ11>=AJ10,AJ11-AJ10,0)*0.53 -> 3574.85 | AL11: 419894 | AM11: =IF(AL11>=AL10,AL11-AL10,0)*0.53 -> 166.42 | AN11: =W11+Y11+AA11+AC11+AE11+AG11+AI11+AK11+AM11 -> 11061.1 | AO11: 7327133 | AP11: =IF(AO11>=AO10,AO11-AO10,0)*0.1125 -> 205.9875 | AQ11: 613054 | AR11: =IF(AQ11>=AQ10,AQ11-AQ10,0) -> 293 | AS11: 928442 | AT11: =IF(AS11>=AS10,AS11-AS10,0) -> 137 | AU11: 799184 | AV11: =IF(AU11>=AU10,AU11-AU10,0) -> 46 | AW11: 2412337 | AX11: =IF(AW11>=AW10,AW11-AW10,0) -> 750 | AY11: 215484 | AZ11: =IF(AY11>=AY10,AY11-AY10,0) -> 72 | BA11: 18146821 | BB11: =IF(BA11>=BA10,BA11-BA10,0) -> 4275 | BC11: 513559 | BD11: =IF(BC11>=BC10,BC11-BC10,0) -> 165 | BE11: 9851 | BF11: =IF(BE11>=BE10,BE11-BE10,0) -> 123 | BG11: 22608511 | BH11: =IF(BG11>=BG10,BG11-BG10,0)-(0.45*BN11)-(0.45*BP11)-BR11 -> 5192.6 | BI11: =AP11+AR11+AT11+AV11+AX11+AZ11+BB11+BD11+BF11+BH11 -> 11259.588 | BJ11: =BI11+AN11 -> 22320.688 | BK11: 1390669 | BL11: =IF(BK11>=BK10,BK11-BK10,0) -> 0 | BM11: 3626872 | BN11: =IF(BM11>=BM10,BM11-BM10,0) -> 1300 | BO11: 386518 | BP11: =IF(BO11>=BO10,BO11-BO10,0) -> 112 | BQ11: 477744 | BR11: =IF(BQ11>=BQ10,BQ11-BQ10,0) -> 209 | BS11: =J11+Q11+AN11+BI11 -> 28068.688 | BT11: 152 | BU11: =IF(BS11>0,BS11/BT10,0) -> 175.4293 | BW11: =IF(BS11>0,BS11/BV11,0) -> #DIV/0! | BX11: =((BS11-Q11)*$BZ$1)+(Q11*$BR$1) -> 32548.991 | BY11: =IF(BX11>0,BX11/BT10,0) -> 203.43119 | BZ11: =IF(BX11>0,BX11/BV11,0) -> #DIV/0!
A12: 7 | C12: =IF(+B12-B11>0,B12-B11,(B12-B11)>0)*800 -> 0 | E12: =IF(+D12-D11>0,D12-D11,(D12-D11)>0)*80 -> 0 | G12: =IF(+F12-F11>0,F12-F11,(F12-F11)>0)*10 -> 0 | H12: 59 | I12: 22624227 | J12: =IF(I12>=I11,I12-I11,0) -> 5028 | K12: =M12+O12 -> 3083 | L12: 175216 | M12: =IF(L12>=L11,L12-L11,0) -> 1668 | N12: 191711 | O12: =IF(N12>=N11,N12-N11,0) -> 1415 | P12: 217184 | Q12: =IF(P12>=P11,P12-P11,0)*30 -> 360 | R12: 149149 | S12: =IF(R12>=R11,R12-R11,0) -> 138 | T12: 270672 | U12: =IF(T12>=T11,T12-T11,0) -> 261 | V12: 774658 | W12: =IF(V12>=V11,V12-V11,0)*0.53 -> 2559.9 | X12: 448169 | Y12: =IF(X12>=X11,X12-X11,0)*0.53 -> 0 | Z12: 699707 | AA12: =IF(Z12>=Z11,Z12-Z11,0)*0.53 -> 151.05 | AB12: 333210 | AC12: =IF(AB12>=AB11,AB12-AB11,0)*0.53 -> 2162.93 | AD12: 421367.4 | AE12: =IF(AD12>=AD11,AD12-AD11,0)*0.53 -> 0 | AF12: 765002 | AG12: =IF(AF12>=AF11,AF12-AF11,0)*0.53 -> 1499.37 | AH12: 661261 | AI12: =IF(AH12>=AH11,AH12-AH11,0)*0.53 -> 849.06 | AJ12: 324778 | AK12: =IF(AJ12>=AJ11,AJ12-AJ11,0)*0.53 -> 3567.43 | AL12: 420209 | AM12: =IF(AL12>=AL11,AL12-AL11,0)*0.53 -> 166.95 | AN12: =W12+Y12+AA12+AC12+AE12+AG12+AI12+AK12+AM12 -> 10956.69 | AO12: 7329232 | AP12: =IF(AO12>=AO11,AO12-AO11,0)*0.1125 -> 236.1375 | AQ12: 613349 | AR12: =IF(AQ12>=AQ11,AQ12-AQ11,0) -> 295 | AS12: 928589 | AT12: =IF(AS12>=AS11,AS12-AS11,0) -> 147 | AU12: 799236 | AV12: =IF(AU12>=AU11,AU12-AU11,0) -> 52 | AW12: 2413105 | AX12: =IF(AW12>=AW11,AW12-AW11,0) -> 768 | AY12: 215556 | AZ12: =IF(AY12>=AY11,AY12-AY11,0) -> 72 | BA12: 18151153 | BB12: =IF(BA12>=BA11,BA12-BA11,0) -> 4332 | BC12: 513724 | BD12: =IF(BC12>=BC11,BC12-BC11,0) -> 165 | BE12: 9990 | BF12: =IF(BE12>=BE11,BE12-BE11,0) -> 139 | BG12: 22615093 | BH12: =IF(BG12>=BG11,BG12-BG11,0)-(0.45*BN12)-(0.45*BP12)-BR12 -> 5686.1 | BI12: =AP12+AR12+AT12+AV12+AX12+AZ12+BB12+BD12+BF12+BH12 -> 11892.237 | BJ12: =BI12+AN12 -> 22848.928 | BK12: 1390878 | BL12: =IF(BK12>=BK11,BK12-BK11,0) -> 209 | BM12: 3628280 | BN12: =IF(BM12>=BM11,BM12-BM11,0) -> 1408 | BO12: 386632 | BP12: =IF(BO12>=BO11,BO12-BO11,0) -> 114 | BQ12: 477955 | BR12: =IF(BQ12>=BQ11,BQ12-BQ11,0) -> 211 | BS12: =J12+Q12+AN12+BI12 -> 28236.928 | BT12: 161 | BU12: =IF(BS12>0,BS12/BT11,0) -> 185.76926 | BW12: =IF(BS12>0,BS12/BV12,0) -> #DIV/0! | BX12: =((BS12-Q12)*$BZ$1)+(Q12*$BR$1) -> 32634.467 | BY12: =IF(BX12>0,BX12/BT11,0) -> 214.70044 | BZ12: =IF(BX12>0,BX12/BV12,0) -> #DIV/0!
A13: 8 | C13: =IF(+B13-B12>0,B13-B12,(B13-B12)>0)*800 -> 0 | E13: =IF(+D13-D12>0,D13-D12,(D13-D12)>0)*80 -> 0 | G13: =IF(+F13-F12>0,F13-F12,(F13-F12)>0)*10 -> 0 | I13: 22629783 | J13: =IF(I13>=I12,I13-I12,0) -> 5556 | K13: =M13+O13 -> 3452 | L13: 177062 | M13: =IF(L13>=L12,L13-L12,0) -> 1846 | N13: 193317 | O13: =IF(N13>=N12,N13-N12,0) -> 1606 | P13: 217201 | Q13: =IF(P13>=P12,P13-P12,0)*30 -> 510 | R13: 149297 | S13: =IF(R13>=R12,R13-R12,0) -> 148 | T13: 270954 | U13: =IF(T13>=T12,T13-T12,0) -> 282 | V13: 780159 | W13: =IF(V13>=V12,V13-V12,0)*0.53 -> 2915.53 | X13: 452714 | Y13: =IF(X13>=X12,X13-X12,0)*0.53 -> 2408.85 | Z13: 699707 | AA13: =IF(Z13>=Z12,Z13-Z12,0)*0.53 -> 0 | AB13: 333210 | AC13: =IF(AB13>=AB12,AB13-AB12,0)*0.53 -> 0 | AD13: 421367.4 | AE13: =IF(AD13>=AD12,AD13-AD12,0)*0.53 -> 0 | AF13: 766287 | AG13: =IF(AF13>=AF12,AF13-AF12,0)*0.53 -> 681.05 | AH13: 662999 | AI13: =IF(AH13>=AH12,AH13-AH12,0)*0.53 -> 921.14 | AJ13: 332097 | AK13: =IF(AJ13>=AJ12,AJ13-AJ12,0)*0.53 -> 3879.07 | AL13: 420541 | AM13: =IF(AL13>=AL12,AL13-AL12,0)*0.53 -> 175.96 | AN13: =W13+Y13+AA13+AC13+AE13+AG13+AI13+AK13+AM13 -> 10981.6 | AO13: 7331645 | AP13: =IF(AO13>=AO12,AO13-AO12,0)*0.1125 -> 271.4625 | AQ13: 613632 | AR13: =IF(AQ13>=AQ12,AQ13-AQ12,0) -> 283 | AS13: 928738 | AT13: =IF(AS13>=AS12,AS13-AS12,0) -> 149 | AU13: 799288 | AV13: =IF(AU13>=AU12,AU13-AU12,0) -> 52 | AW13: 2413951 | AX13: =IF(AW13>=AW12,AW13-AW12,0) -> 846 | AY13: 215633 | AZ13: =IF(AY13>=AY12,AY13-AY12,0) -> 77 | BA13: 18155685 | BB13: =IF(BA13>=BA12,BA13-BA12,0) -> 4532 | BC13: 513903 | BD13: =IF(BC13>=BC12,BC13-BC12,0) -> 179 | BE13: 10024 | BF13: =IF(BE13>=BE12,BE13-BE12,0) -> 34 | BG13: 22621766 | BH13: =IF(BG13>=BG12,BG13-BG12,0)-(0.45*BN13)-(0.45*BP13)-BR13 -> 5772.4 | BI13: =AP13+AR13+AT13+AV13+AX13+AZ13+BB13+BD13+BF13+BH13 -> 12195.862 | BJ13: =BI13+AN13 -> 23177.463 | BK13: 1390995 | BL13: =IF(BK13>=BK12,BK13-BK12,0) -> 117 | BM13: 3629674 | BN13: =IF(BM13>=BM12,BM13-BM12,0) -> 1394 | BO13: 386746 | BP13: =IF(BO13>=BO12,BO13-BO12,0) -> 114 | BQ13: 478177 | BR13: =IF(BQ13>=BQ12,BQ13-BQ12,0) -> 222 | BS13: =J13+Q13+AN13+BI13 -> 29243.462 | BT13: 91 | BU13: =IF(BS13>0,BS13/BT12,0) -> 181.63641 | BW13: =IF(BS13>0,BS13/BV13,0) -> #DIV/0! | BX13: =((BS13-Q13)*$BZ$1)+(Q13*$BR$1) -> 33859.482 | BY13: =IF(BX13>0,BX13/BT12,0) -> 210.30734 | BZ13: =IF(BX13>0,BX13/BV13,0) -> #DIV/0!
A14: 9 | C14: =IF(+B14-B13>0,B14-B13,(B14-B13)>0)*800 -> 0 | E14: =IF(+D14-D13>0,D14-D13,(D14-D13)>0)*80 -> 0 | G14: =IF(+F14-F13>0,F14-F13,(F14-F13)>0)*10 -> 0 | H14: 60 | I14: 22634486 | J14: =IF(I14>=I13,I14-I13,0) -> 4703 | K14: =M14+O14 -> 3078 | L14: 178713 | M14: =IF(L14>=L13,L14-L13,0) -> 1651 | N14: 194744 | O14: =IF(N14>=N13,N14-N13,0) -> 1427 | P14: 217222 | Q14: =IF(P14>=P13,P14-P13,0)*30 -> 630 | R14: 149428 | S14: =IF(R14>=R13,R14-R13,0) -> 131 | T14: 271207 | U14: =IF(T14>=T13,T14-T13,0) -> 253 | V14: 786130 | W14: =IF(V14>=V13,V14-V13,0)*0.53 -> 3164.63 | X14: 452714 | Y14: =IF(X14>=X13,X14-X13,0)*0.53 -> 0 | Z14: 702884 | AA14: =IF(Z14>=Z13,Z14-Z13,0)*0.53 -> 1683.81 | AB14: 333210 | AC14: =IF(AB14>=AB13,AB14-AB13,0)*0.53 -> 0 | AD14: 366331 | AE14: =IF(AD14>=AD13,AD14-AD13,0)*0.53 -> 0 | AF14: 766307 | AG14: =IF(AF14>=AF13,AF14-AF13,0)*0.53 -> 10.6 | AH14: 664808 | AI14: =IF(AH14>=AH13,AH14-AH13,0)*0.53 -> 958.77 | AJ14: 338589 | AK14: =IF(AJ14>=AJ13,AJ14-AJ13,0)*0.53 -> 3440.76 | AL14: 420855 | AM14: =IF(AL14>=AL13,AL14-AL13,0)*0.53 -> 166.42 | AN14: =W14+Y14+AA14+AC14+AE14+AG14+AI14+AK14+AM14 -> 9424.99 | AO14: 7333544 | AP14: =IF(AO14>=AO13,AO14-AO13,0)*0.1125 -> 213.6375 | AQ14: 613907 | AR14: =IF(AQ14>=AQ13,AQ14-AQ13,0) -> 275 | AS14: 928865 | AT14: =IF(AS14>=AS13,AS14-AS13,0) -> 127 | AU14: 799344 | AV14: =IF(AU14>=AU13,AU14-AU13,0) -> 56 | AW14: 2414787 | AX14: =IF(AW14>=AW13,AW14-AW13,0) -> 836 | AY14: 215702 | AZ14: =IF(AY14>=AY13,AY14-AY13,0) -> 69 | BA14: 18159888 | BB14: =IF(BA14>=BA13,BA14-BA13,0) -> 4203 | BC14: 514064 | BD14: =IF(BC14>=BC13,BC14-BC13,0) -> 161 | BE14: 10145 | BF14: =IF(BE14>=BE13,BE14-BE13,0) -> 121 | BG14: 22627673 | BH14: =IF(BG14>=BG13,BG14-BG13,0)-(0.45*BN14)-(0.45*BP14)-BR14 -> 5080.85 | BI14: =AP14+AR14+AT14+AV14+AX14+AZ14+BB14+BD14+BF14+BH14 -> 11142.487 | BJ14: =BI14+AN14 -> 20567.478 | BK14: 1390997 | BL14: =IF(BK14>=BK13,BK14-BK13,0) -> 2 | BM14: 3630965 | BN14: =IF(BM14>=BM13,BM14-BM13,0) -> 1291 | BO14: 386842 | BP14: =IF(BO14>=BO13,BO14-BO13,0) -> 96 | BQ14: 478379 | BR14: =IF(BQ14>=BQ13,BQ14-BQ13,0) -> 202 | BS14: =J14+Q14+AN14+BI14 -> 25900.478 | BT14: 156 | BU14: =IF(BS14>0,BS14/BT13,0) -> 284.62063 | BW14: =IF(BS14>0,BS14/BV14,0) -> #DIV/0! | BX14: =((BS14-Q14)*$BZ$1)+(Q14*$BR$1) -> 30069.049 | BY14: =IF(BX14>0,BX14/BT13,0) -> 330.42911 | BZ14: =IF(BX14>0,BX14/BV14,0) -> #DIV/0!
A15: 10 | C15: =IF(+B15-B14>0,B15-B14,(B15-B14)>0)*800 -> 0 | E15: =IF(+D15-D14>0,D15-D14,(D15-D14)>0)*80 -> 0 | G15: =IF(+F15-F14>0,F15-F14,(F15-F14)>0)*10 -> 0 | I15: 22639413 | J15: =IF(I15>=I14,I15-I14,0) -> 4927 | K15: =M15+O15 -> 3158 | L15: 180405 | M15: =IF(L15>=L14,L15-L14,0) -> 1692 | N15: 196210 | O15: =IF(N15>=N14,N15-N14,0) -> 1466 | P15: 217241 | Q15: =IF(P15>=P14,P15-P14,0)*30 -> 570 | R15: 149568 | S15: =IF(R15>=R14,R15-R14,0) -> 140 | T15: 271475 | U15: =IF(T15>=T14,T15-T14,0) -> 268 | V15: 791857 | W15: =IF(V15>=V14,V15-V14,0)*0.53 -> 3035.31 | X15: 452714 | Y15: =IF(X15>=X14,X15-X14,0)*0.53 -> 0 | Z15: 708596 | AA15: =IF(Z15>=Z14,Z15-Z14,0)*0.53 -> 3027.36 | AB15: 333210 | AC15: =IF(AB15>=AB14,AB15-AB14,0)*0.53 -> 0 | AD15: 366349 | AE15: =IF(AD15>=AD14,AD15-AD14,0)*0.53 -> 9.54 | AF15: 766328 | AG15: =IF(AF15>=AF14,AF15-AF14,0)*0.53 -> 11.13 | AH15: 666942 | AI15: =IF(AH15>=AH14,AH15-AH14,0)*0.53 -> 1131.02 | AJ15: 345970 | AK15: =IF(AJ15>=AJ14,AJ15-AJ14,0)*0.53 -> 3911.93 | AL15: 421179 | AM15: =IF(AL15>=AL14,AL15-AL14,0)*0.53 -> 171.72 | AN15: =W15+Y15+AA15+AC15+AE15+AG15+AI15+AK15+AM15 -> 11298.01 | AO15: 7335256 | AP15: =IF(AO15>=AO14,AO15-AO14,0)*0.1125 -> 192.6 | AQ15: 614183 | AR15: =IF(AQ15>=AQ14,AQ15-AQ14,0) -> 276 | AS15: 929038 | AT15: =IF(AS15>=AS14,AS15-AS14,0) -> 173 | AU15: 799410 | AV15: =IF(AU15>=AU14,AU15-AU14,0) -> 66 | AW15: 2415649 | AX15: =IF(AW15>=AW14,AW15-AW14,0) -> 862 | AY15: 215776 | AZ15: =IF(AY15>=AY14,AY15-AY14,0) -> 74 | BA15: 18164023 | BB15: =IF(BA15>=BA14,BA15-BA14,0) -> 4135 | BC15: 514234 | BD15: =IF(BC15>=BC14,BC15-BC14,0) -> 170 | BE15: 10245 | BF15: =IF(BE15>=BE14,BE15-BE14,0) -> 100 | BG15: 22634900 | BH15: =IF(BG15>=BG14,BG15-BG14,0)-(0.45*BN15)-(0.45*BP15)-BR15 -> 6305.9 | BI15: =AP15+AR15+AT15+AV15+AX15+AZ15+BB15+BD15+BF15+BH15 -> 12354.5 | BJ15: =BI15+AN15 -> 23652.51 | BK15: 1391248 | BL15: =IF(BK15>=BK14,BK15-BK14,0) -> 251 | BM15: 3632411 | BN15: =IF(BM15>=BM14,BM15-BM14,0) -> 1446 | BO15: 386954 | BP15: =IF(BO15>=BO14,BO15-BO14,0) -> 112 | BQ15: 478599 | BR15: =IF(BQ15>=BQ14,BQ15-BQ14,0) -> 220 | BS15: =J15+Q15+AN15+BI15 -> 29149.51 | BT15: 154 | BU15: =IF(BS15>0,BS15/BT14,0) -> 186.85583 | BW15: =IF(BS15>0,BS15/BV15,0) -> #DIV/0! | BX15: =((BS15-Q15)*$BZ$1)+(Q15*$BR$1) -> 33778.437 | BY15: =IF(BX15>0,BX15/BT14,0) -> 216.52844 | BZ15: =IF(BX15>0,BX15/BV15,0) -> #DIV/0!
A16: 11 | C16: =IF(+B16-B15>0,B16-B15,(B16-B15)>0)*800 -> 0 | E16: =IF(+D16-D15>0,D16-D15,(D16-D15)>0)*80 -> 0 | G16: =IF(+F16-F15>0,F16-F15,(F16-F15)>0)*10 -> 0 | H16: 61 | I16: 22644742 | J16: =IF(I16>=I15,I16-I15,0) -> 5329 | K16: =M16+O16 -> 3142 | L16: 182097 | M16: =IF(L16>=L15,L16-L15,0) -> 1692 | N16: 197660 | O16: =IF(N16>=N15,N16-N15,0) -> 1450 | P16: 217259 | Q16: =IF(P16>=P15,P16-P15,0)*30 -> 540 | R16: 149709 | S16: =IF(R16>=R15,R16-R15,0) -> 141 | T16: 271744 | U16: =IF(T16>=T15,T16-T15,0) -> 269 | V16: 797234 | W16: =IF(V16>=V15,V16-V15,0)*0.53 -> 2849.81 | X16: 452714 | Y16: =IF(X16>=X15,X16-X15,0)*0.53 -> 0 | Z16: 713528 | AA16: =IF(Z16>=Z15,Z16-Z15,0)*0.53 -> 2613.96 | AB16: 333210 | AC16: =IF(AB16>=AB15,AB16-AB15,0)*0.53 -> 0 | AD16: 366357 | AE16: =IF(AD16>=AD15,AD16-AD15,0)*0.53 -> 4.24 | AF16: 766349 | AG16: =IF(AF16>=AF15,AF16-AF15,0)*0.53 -> 11.13 | AH16: 668763 | AI16: =IF(AH16>=AH15,AH16-AH15,0)*0.53 -> 965.13 | AJ16: 352585 | AK16: =IF(AJ16>=AJ15,AJ16-AJ15,0)*0.53 -> 3505.95 | AL16: 421478 | AM16: =IF(AL16>=AL15,AL16-AL15,0)*0.53 -> 158.47 | AN16: =W16+Y16+AA16+AC16+AE16+AG16+AI16+AK16+AM16 -> 10108.69 | AO16: 7337141 | AP16: =IF(AO16>=AO15,AO16-AO15,0)*0.1125 -> 212.0625 | AQ16: 614487 | AR16: =IF(AQ16>=AQ15,AQ16-AQ15,0) -> 304 | AS16: 929216 | AT16: =IF(AS16>=AS15,AS16-AS15,0) -> 178 | AU16: 799463 | AV16: =IF(AU16>=AU15,AU16-AU15,0) -> 53 | AW16: 2416450 | AX16: =IF(AW16>=AW15,AW16-AW15,0) -> 801 | AY16: 215850 | AZ16: =IF(AY16>=AY15,AY16-AY15,0) -> 74 | BA16: 18168585 | BB16: =IF(BA16>=BA15,BA16-BA15,0) -> 4562 | BC16: 514405 | BD16: =IF(BC16>=BC15,BC16-BC15,0) -> 171 | BE16: 10370 | BF16: =IF(BE16>=BE15,BE16-BE15,0) -> 125 | BG16: 22641587 | BH16: =IF(BG16>=BG15,BG16-BG15,0)-(0.45*BN16)-(0.45*BP16)-BR16 -> 5843.65 | BI16: =AP16+AR16+AT16+AV16+AX16+AZ16+BB16+BD16+BF16+BH16 -> 12323.712 | BJ16: =BI16+AN16 -> 22432.403 | BK16: 1391504 | BL16: =IF(BK16>=BK15,BK16-BK15,0) -> 256 | BM16: 3633736 | BN16: =IF(BM16>=BM15,BM16-BM15,0) -> 1325 | BO16: 387052 | BP16: =IF(BO16>=BO15,BO16-BO15,0) -> 98 | BQ16: 478802 | BR16: =IF(BQ16>=BQ15,BQ16-BQ15,0) -> 203 | BS16: =J16+Q16+AN16+BI16 -> 28301.403 | BT16: 164 | BU16: =IF(BS16>0,BS16/BT15,0) -> 183.77534 | BW16: =IF(BS16>0,BS16/BV16,0) -> #DIV/0! | BX16: =((BS16-Q16)*$BZ$1)+(Q16*$BR$1) -> 32789.613 | BY16: =IF(BX16>0,BX16/BT15,0) -> 212.91956 | BZ16: =IF(BX16>0,BX16/BV16,0) -> #DIV/0!
A17: 12 | C17: =IF(+B17-B16>0,B17-B16,(B17-B16)>0)*800 -> 0 | E17: =IF(+D17-D16>0,D17-D16,(D17-D16)>0)*80 -> 0 | G17: =IF(+F17-F16>0,F17-F16,(F17-F16)>0)*10 -> 0 | I17: 22649952 | J17: =IF(I17>=I16,I17-I16,0) -> 5210 | K17: =M17+O17 -> 3334 | L17: 183888 | M17: =IF(L17>=L16,L17-L16,0) -> 1791 | N17: 199203 | O17: =IF(N17>=N16,N17-N16,0) -> 1543 | P17: 217277 | Q17: =IF(P17>=P16,P17-P16,0)*30 -> 540 | R17: 149850 | S17: =IF(R17>=R16,R17-R16,0) -> 141 | T17: 272019 | U17: =IF(T17>=T16,T17-T16,0) -> 275 | V17: 803282 | W17: =IF(V17>=V16,V17-V16,0)*0.53 -> 3205.44 | X17: 457252 | Y17: =IF(X17>=X16,X17-X16,0)*0.53 -> 2405.14 | Z17: 713595 | AA17: =IF(Z17>=Z16,Z17-Z16,0)*0.53 -> 35.51 | AB17: 333210 | AC17: =IF(AB17>=AB16,AB17-AB16,0)*0.53 -> 0 | AD17: 366373 | AE17: =IF(AD17>=AD16,AD17-AD16,0)*0.53 -> 8.48 | AF17: 766370 | AG17: =IF(AF17>=AF16,AF17-AF16,0)*0.53 -> 11.13 | AH17: 670729 | AI17: =IF(AH17>=AH16,AH17-AH16,0)*0.53 -> 1041.98 | AJ17: 359904 | AK17: =IF(AJ17>=AJ16,AJ17-AJ16,0)*0.53 -> 3879.07 | AL17: 421804 | AM17: =IF(AL17>=AL16,AL17-AL16,0)*0.53 -> 172.78 | AN17: =W17+Y17+AA17+AC17+AE17+AG17+AI17+AK17+AM17 -> 10759.53 | AO17: 7338933 | AP17: =IF(AO17>=AO16,AO17-AO16,0)*0.1125 -> 201.6 | AQ17: 614731 | AR17: =IF(AQ17>=AQ16,AQ17-AQ16,0) -> 244 | AS17: 929369 | AT17: =IF(AS17>=AS16,AS17-AS16,0) -> 153 | AU17: 799522 | AV17: =IF(AU17>=AU16,AU17-AU16,0) -> 59 | AW17: 2417306 | AX17: =IF(AW17>=AW16,AW17-AW16,0) -> 856 | AY17: 215925 | AZ17: =IF(AY17>=AY16,AY17-AY16,0) -> 75 | BA17: 18173476 | BB17: =IF(BA17>=BA16,BA17-BA16,0) -> 4891 | BC17: 514584 | BD17: =IF(BC17>=BC16,BC17-BC16,0) -> 179 | BE17: 10484 | BF17: =IF(BE17>=BE16,BE17-BE16,0) -> 114 | BG17: 22648690 | BH17: =IF(BG17>=BG16,BG17-BG16,0)-(0.45*BN17)-(0.45*BP17)-BR17 -> 6214.2 | BI17: =AP17+AR17+AT17+AV17+AX17+AZ17+BB17+BD17+BF17+BH17 -> 12986.8 | BJ17: =BI17+AN17 -> 23746.33 | BK17: 1391774 | BL17: =IF(BK17>=BK16,BK17-BK16,0) -> 270 | BM17: 3635137 | BN17: =IF(BM17>=BM16,BM17-BM16,0) -> 1401 | BO17: 387155 | BP17: =IF(BO17>=BO16,BO17-BO16,0) -> 103 | BQ17: 479014 | BR17: =IF(BQ17>=BQ16,BQ17-BQ16,0) -> 212 | BS17: =J17+Q17+AN17+BI17 -> 29496.33 | BT17: 147 | BU17: =IF(BS17>0,BS17/BT16,0) -> 179.85567 | BW17: =IF(BS17>0,BS17/BV17,0) -> #DIV/0! | BX17: =((BS17-Q17)*$BZ$1)+(Q17*$BR$1) -> 34163.779 | BY17: =IF(BX17>0,BX17/BT16,0) -> 208.31573 | BZ17: =IF(BX17>0,BX17/BV17,0) -> #DIV/0!
A18: 13 | C18: =IF(+B18-B17>0,B18-B17,(B18-B17)>0)*800 -> 0 | E18: =IF(+D18-D17>0,D18-D17,(D18-D17)>0)*80 -> 0 | G18: =IF(+F18-F17>0,F18-F17,(F18-F17)>0)*10 -> 0 | H18: 62 | I18: 22655143 | J18: =IF(I18>=I17,I18-I17,0) -> 5191 | K18: =M18+O18 -> 3314 | L18: 185662 | M18: =IF(L18>=L17,L18-L17,0) -> 1774 | N18: 200743 | O18: =IF(N18>=N17,N18-N17,0) -> 1540 | P18: 217298 | Q18: =IF(P18>=P17,P18-P17,0)*30 -> 630 | R18: 149987 | S18: =IF(R18>=R17,R18-R17,0) -> 137 | T18: 272286 | U18: =IF(T18>=T17,T18-T17,0) -> 267 | V18: 809175 | W18: =IF(V18>=V17,V18-V17,0)*0.53 -> 3123.29 | X18: 462670 | Y18: =IF(X18>=X17,X18-X17,0)*0.53 -> 2871.54 | Z18: 713595 | AA18: =IF(Z18>=Z17,Z18-Z17,0)*0.53 -> 0 | AB18: 333210 | AC18: =IF(AB18>=AB17,AB18-AB17,0)*0.53 -> 0 | AD18: 366384 | AE18: =IF(AD18>=AD17,AD18-AD17,0)*0.53 -> 5.83 | AF18: 766407 | AG18: =IF(AF18>=AF17,AF18-AF17,0)*0.53 -> 19.61 | AH18: 672761 | AI18: =IF(AH18>=AH17,AH18-AH17,0)*0.53 -> 1076.96 | AJ18: 367410 | AK18: =IF(AJ18>=AJ17,AJ18-AJ17,0)*0.53 -> 3978.18 | AL18: 422124 | AM18: =IF(AL18>=AL17,AL18-AL17,0)*0.53 -> 169.6 | AN18: =W18+Y18+AA18+AC18+AE18+AG18+AI18+AK18+AM18 -> 11245.01 | AO18: 7340741 | AP18: =IF(AO18>=AO17,AO18-AO17,0)*0.1125 -> 203.4 | AQ18: 615012 | AR18: =IF(AQ18>=AQ17,AQ18-AQ17,0) -> 281 | AS18: 929520 | AT18: =IF(AS18>=AS17,AS18-AS17,0) -> 151 | AU18: 799582 | AV18: =IF(AU18>=AU17,AU18-AU17,0) -> 60 | AW18: 2418155 | AX18: =IF(AW18>=AW17,AW18-AW17,0) -> 849 | AY18: 215999 | AZ18: =IF(AY18>=AY17,AY18-AY17,0) -> 74 | BA18: 18178138 | BB18: =IF(BA18>=BA17,BA18-BA17,0) -> 4662 | BC18: 514755 | BD18: =IF(BC18>=BC17,BC18-BC17,0) -> 171 | BE18: 10603 | BF18: =IF(BE18>=BE17,BE18-BE17,0) -> 119 | BG18: 22655373 | BH18: =IF(BG18>=BG17,BG18-BG17,0)-(0.45*BN18)-(0.45*BP18)-BR18 -> 5828.3 | BI18: =AP18+AR18+AT18+AV18+AX18+AZ18+BB18+BD18+BF18+BH18 -> 12398.7 | BJ18: =BI18+AN18 -> 23643.71 | BK18: 1392027 | BL18: =IF(BK18>=BK17,BK18-BK17,0) -> 253 | BM18: 3636477 | BN18: =IF(BM18>=BM17,BM18-BM17,0) -> 1340 | BO18: 387261 | BP18: =IF(BO18>=BO17,BO18-BO17,0) -> 106 | BQ18: 479218 | BR18: =IF(BQ18>=BQ17,BQ18-BQ17,0) -> 204 | BS18: =J18+Q18+AN18+BI18 -> 29464.71 | BT18: 131 | BU18: =IF(BS18>0,BS18/BT17,0) -> 200.4402 | BW18: =IF(BS18>0,BS18/BV18,0) -> #DIV/0! | BX18: =((BS18-Q18)*$BZ$1)+(Q18*$BR$1) -> 34167.916 | BY18: =IF(BX18>0,BX18/BT17,0) -> 232.43481 | BZ18: =IF(BX18>0,BX18/BV18,0) -> #DIV/0!
A19: 14 | C19: =IF(+B19-B18>0,B19-B18,(B19-B18)>0)*800 -> 0 | E19: =IF(+D19-D18>0,D19-D18,(D19-D18)>0)*80 -> 0 | G19: =IF(+F19-F18>0,F19-F18,(F19-F18)>0)*10 -> 0 | I19: 22660136 | J19: =IF(I19>=I18,I19-I18,0) -> 4993 | K19: =M19+O19 -> 3278 | L19: 187336 | M19: =IF(L19>=L18,L19-L18,0) -> 1674 | N19: 202347 | O19: =IF(N19>=N18,N19-N18,0) -> 1604 | P19: 217316 | Q19: =IF(P19>=P18,P19-P18,0)*30 -> 540 | R19: 150123 | S19: =IF(R19>=R18,R19-R18,0) -> 136 | T19: 272544 | U19: =IF(T19>=T18,T19-T18,0) -> 258 | V19: 813696 | W19: =IF(V19>=V18,V19-V18,0)*0.53 -> 2396.13 | X19: 469390 | Y19: =IF(X19>=X18,X19-X18,0)*0.53 -> 3561.6 | Z19: 713595 | AA19: =IF(Z19>=Z18,Z19-Z18,0)*0.53 -> 0 | AB19: 333210 | AC19: =IF(AB19>=AB18,AB19-AB18,0)*0.53 -> 0 | AD19: 366403 | AE19: =IF(AD19>=AD18,AD19-AD18,0)*0.53 -> 10.07 | AF19: 766427 | AG19: =IF(AF19>=AF18,AF19-AF18,0)*0.53 -> 10.6 | AH19: 674778 | AI19: =IF(AH19>=AH18,AH19-AH18,0)*0.53 -> 1069.01 | AJ19: 375004 | AK19: =IF(AJ19>=AJ18,AJ19-AJ18,0)*0.53 -> 4024.82 | AL19: 422435 | AM19: =IF(AL19>=AL18,AL19-AL18,0)*0.53 -> 164.83 | AN19: =W19+Y19+AA19+AC19+AE19+AG19+AI19+AK19+AM19 -> 11237.06 | AO19: 7342612 | AP19: =IF(AO19>=AO18,AO19-AO18,0)*0.1125 -> 210.4875 | AQ19: 615297 | AR19: =IF(AQ19>=AQ18,AQ19-AQ18,0) -> 285 | AS19: 929686 | AT19: =IF(AS19>=AS18,AS19-AS18,0) -> 166 | AU19: 799630 | AV19: =IF(AU19>=AU18,AU19-AU18,0) -> 48 | AW19: 2418983 | AX19: =IF(AW19>=AW18,AW19-AW18,0) -> 828 | AY19: 216072 | AZ19: =IF(AY19>=AY18,AY19-AY18,0) -> 73 | BA19: 18182463 | BB19: =IF(BA19>=BA18,BA19-BA18,0) -> 4325 | BC19: 514911 | BD19: =IF(BC19>=BC18,BC19-BC18,0) -> 156 | BE19: 10709 | BF19: =IF(BE19>=BE18,BE19-BE18,0) -> 106 | BG19: 22662077 | BH19: =IF(BG19>=BG18,BG19-BG18,0)-(0.45*BN19)-(0.45*BP19)-BR19 -> 5826.05 | BI19: =AP19+AR19+AT19+AV19+AX19+AZ19+BB19+BD19+BF19+BH19 -> 12023.538 | BJ19: =BI19+AN19 -> 23260.598 | BK19: 1392288 | BL19: =IF(BK19>=BK18,BK19-BK18,0) -> 261 | BM19: 3637858 | BN19: =IF(BM19>=BM18,BM19-BM18,0) -> 1381 | BO19: 387371 | BP19: =IF(BO19>=BO18,BO19-BO18,0) -> 110 | BQ19: 479425 | BR19: =IF(BQ19>=BQ18,BQ19-BQ18,0) -> 207 | BS19: =J19+Q19+AN19+BI19 -> 28793.598 | BT19: 146 | BU19: =IF(BS19>0,BS19/BT18,0) -> 219.79845 | BW19: =IF(BS19>0,BS19/BV19,0) -> #DIV/0! | BX19: =((BS19-Q19)*$BZ$1)+(Q19*$BR$1) -> 33355.637 | BY19: =IF(BX19>0,BX19/BT18,0) -> 254.62318 | BZ19: =IF(BX19>0,BX19/BV19,0) -> #DIV/0!
A20: 15 | C20: =IF(+B20-B19>0,B20-B19,(B20-B19)>0)*800 -> 0 | E20: =IF(+D20-D19>0,D20-D19,(D20-D19)>0)*80 -> 0 | G20: =IF(+F20-F19>0,F20-F19,(F20-F19)>0)*10 -> 0 | H20: 63 | I20: 22665686 | J20: =IF(I20>=I19,I20-I19,0) -> 5550 | K20: =M20+O20 -> 3319 | L20: 189007 | M20: =IF(L20>=L19,L20-L19,0) -> 1671 | N20: 203995 | O20: =IF(N20>=N19,N20-N19,0) -> 1648 | P20: 217334 | Q20: =IF(P20>=P19,P20-P19,0)*30 -> 540 | R20: 150263 | S20: =IF(R20>=R19,R20-R19,0) -> 140 | T20: 272809 | U20: =IF(T20>=T19,T20-T19,0) -> 265 | V20: 819233 | W20: =IF(V20>=V19,V20-V19,0)*0.53 -> 2934.61 | X20: 474105 | Y20: =IF(X20>=X19,X20-X19,0)*0.53 -> 2498.95 | Z20: 713595 | AA20: =IF(Z20>=Z19,Z20-Z19,0)*0.53 -> 0 | AB20: 333210 | AC20: =IF(AB20>=AB19,AB20-AB19,0)*0.53 -> 0 | AD20: 366419 | AE20: =IF(AD20>=AD19,AD20-AD19,0)*0.53 -> 8.48 | AF20: 766447 | AG20: =IF(AF20>=AF19,AF20-AF19,0)*0.53 -> 10.6 | AH20: 676660 | AI20: =IF(AH20>=AH19,AH20-AH19,0)*0.53 -> 997.46 | AJ20: 381673 | AK20: =IF(AJ20>=AJ19,AJ20-AJ19,0)*0.53 -> 3534.57 | AL20: 422737 | AM20: =IF(AL20>=AL19,AL20-AL19,0)*0.53 -> 160.06 | AN20: =W20+Y20+AA20+AC20+AE20+AG20+AI20+AK20+AM20 -> 10144.73 | AO20: 7344495 | AP20: =IF(AO20>=AO19,AO20-AO19,0)*0.1125 -> 211.8375 | AQ20: 615577 | AR20: =IF(AQ20>=AQ19,AQ20-AQ19,0) -> 280 | AS20: 929831 | AT20: =IF(AS20>=AS19,AS20-AS19,0) -> 145 | AU20: 799679 | AV20: =IF(AU20>=AU19,AU20-AU19,0) -> 49 | AW20: 2419790 | AX20: =IF(AW20>=AW19,AW20-AW19,0) -> 807 | AY20: 216147 | AZ20: =IF(AY20>=AY19,AY20-AY19,0) -> 75 | BA20: 18186808 | BB20: =IF(BA20>=BA19,BA20-BA19,0) -> 4345 | BC20: 515082 | BD20: =IF(BC20>=BC19,BC20-BC19,0) -> 171 | BE20: 10796 | BF20: =IF(BE20>=BE19,BE20-BE19,0) -> 87 | BG20: 22669060 | BH20: =IF(BG20>=BG19,BG20-BG19,0)-(0.45*BN20)-(0.45*BP20)-BR20 -> 6114.85 | BI20: =AP20+AR20+AT20+AV20+AX20+AZ20+BB20+BD20+BF20+BH20 -> 12285.688 | BJ20: =BI20+AN20 -> 22430.417 | BK20: 1392552 | BL20: =IF(BK20>=BK19,BK20-BK19,0) -> 264 | BM20: 3639216 | BN20: =IF(BM20>=BM19,BM20-BM19,0) -> 1358 | BO20: 387480 | BP20: =IF(BO20>=BO19,BO20-BO19,0) -> 109 | BQ20: 479633 | BR20: =IF(BQ20>=BQ19,BQ20-BQ19,0) -> 208 | BS20: =J20+Q20+AN20+BI20 -> 28520.417 | BT20: 147 | BU20: =IF(BS20>0,BS20/BT20,0) -> 194.01645 | BW20: =IF(BS20>0,BS20/BV20,0) -> #DIV/0! | BX20: =((BS20-Q20)*$BZ$1)+(Q20*$BR$1) -> 33041.48 | BY20: =IF(BX20>0,BX20/BT20,0) -> 224.77197 | BZ20: =IF(BX20>0,BX20/BV20,0) -> #DIV/0!
A21: 16 | C21: =IF(+B21-B20>0,B21-B20,(B21-B20)>0)*800 -> 0 | E21: =IF(+D21-D20>0,D21-D20,(D21-D20)>0)*80 -> 0 | G21: =IF(+F21-F20>0,F21-F20,(F21-F20)>0)*10 -> 0 | I21: 22671296 | J21: =IF(I21>=I20,I21-I20,0) -> 5610 | K21: =M21+O21 -> 3495 | L21: 190818 | M21: =IF(L21>=L20,L21-L20,0) -> 1811 | N21: 205679 | O21: =IF(N21>=N20,N21-N20,0) -> 1684 | P21: 217354 | Q21: =IF(P21>=P20,P21-P20,0)*30 -> 600 | R21: 150401 | S21: =IF(R21>=R20,R21-R20,0) -> 138 | T21: 273068 | U21: =IF(T21>=T20,T21-T20,0) -> 259 | V21: 824638 | W21: =IF(V21>=V20,V21-V20,0)*0.53 -> 2864.65 | X21: 479163 | Y21: =IF(X21>=X20,X21-X20,0)*0.53 -> 2680.74 | Z21: 713595 | AA21: =IF(Z21>=Z20,Z21-Z20,0)*0.53 -> 0 | AB21: 333210 | AC21: =IF(AB21>=AB20,AB21-AB20,0)*0.53 -> 0 | AD21: 364960 | AE21: =IF(AD21>=AD20,AD21-AD20,0)*0.53 -> 0 | AF21: 768432 | AG21: =IF(AF21>=AF20,AF21-AF20,0)*0.53 -> 1052.05 | AH21: 678569 | AI21: =IF(AH21>=AH20,AH21-AH20,0)*0.53 -> 1011.77 | AJ21: 388739 | AK21: =IF(AJ21>=AJ20,AJ21-AJ20,0)*0.53 -> 3744.98 | AL21: 423042 | AM21: =IF(AL21>=AL20,AL21-AL20,0)*0.53 -> 161.65 | AN21: =W21+Y21+AA21+AC21+AE21+AG21+AI21+AK21+AM21 -> 11515.84 | AO21: 7346240 | AP21: =IF(AO21>=AO20,AO21-AO20,0)*0.1125 -> 196.3125 | AQ21: 615812 | AR21: =IF(AQ21>=AQ20,AQ21-AQ20,0) -> 235 | AS21: 929970 | AT21: =IF(AS21>=AS20,AS21-AS20,0) -> 139 | AU21: 799730 | AV21: =IF(AU21>=AU20,AU21-AU20,0) -> 51 | AW21: 2420634 | AX21: =IF(AW21>=AW20,AW21-AW20,0) -> 844 | AY21: 216220 | AZ21: =IF(AY21>=AY20,AY21-AY20,0) -> 73 | BA21: 18191288 | BB21: =IF(BA21>=BA20,BA21-BA20,0) -> 4480 | BC21: 515236 | BD21: =IF(BC21>=BC20,BC21-BC20,0) -> 154 | BE21: 10908 | BF21: =IF(BE21>=BE20,BE21-BE20,0) -> 112 | BG21: 22675797 | BH21: =IF(BG21>=BG20,BG21-BG20,0)-(0.45*BN21)-(0.45*BP21)-BR21 -> 5880.5 | BI21: =AP21+AR21+AT21+AV21+AX21+AZ21+BB21+BD21+BF21+BH21 -> 12164.812 | BJ21: =BI21+AN21 -> 23680.653 | BK21: 1392811 | BL21: =IF(BK21>=BK20,BK21-BK20,0) -> 259 | BM21: 3640559 | BN21: =IF(BM21>=BM20,BM21-BM20,0) -> 1343 | BO21: 387587 | BP21: =IF(BO21>=BO20,BO21-BO20,0) -> 107 | BQ21: 479837 | BR21: =IF(BQ21>=BQ20,BQ21-BQ20,0) -> 204 | BS21: =J21+Q21+AN21+BI21 -> 29890.653 | BT21: 160 | BU21: =IF(BS21>0,BS21/BT21,0) -> 186.81658 | BW21: =IF(BS21>0,BS21/BV21,0) -> #DIV/0! | BX21: =((BS21-Q21)*$BZ$1)+(Q21*$BR$1) -> 34644.25 | BY21: =IF(BX21>0,BX21/BT21,0) -> 216.52656 | BZ21: =IF(BX21>0,BX21/BV21,0) -> #DIV/0!
