Workbook

Sheet Total
A1: Site Name | B1: Day | C1: Month | D1: Year | E1: Total Electricity Kwh | F1: Electricity Tariff ($/Kwh) | G1: Natual Gas (m3) | H1: Natural Gas $/m3 | I1: Water Utility Supply (m3) m3 | J1: Water Utility Supply (m3) $/m3 | K1: Room Nights
A2: Cairo at The First Residence | B2: 1 | C2: 1 | D2: 2021 | E2: 19809.19 | F2: 1.5 | G2: =1102.82+263.03 -> 1365.85 | H2: 3.89 | I2: 256.65 | J2: 10 | K2: 41
A3: Cairo at The First Residence | B3: =B2+1 -> 2 | C3: 1 | D3: 2021 | E3: 19809.19 | F3: =F2 -> 1.5 | G3: =1102.82+263.03 -> 1365.85 | H3: 3.89 | I3: 256.65 | J3: 10 | K3: 41
A4: Cairo at The First Residence | B4: =B3+1 -> 3 | C4: 1 | D4: 2021 | E4: 19809.19 | F4: =F3 -> 1.5 | G4: =1102.82+263.03 -> 1365.85 | H4: 3.89 | I4: 256.65 | J4: 10 | K4: 41
A5: Cairo at The First Residence | B5: =B4+1 -> 4 | C5: 1 | D5: 2021 | E5: 19809.19 | F5: =F4 -> 1.5 | G5: =1102.82+263.03 -> 1365.85 | H5: 3.89 | I5: 256.65 | J5: 10 | K5: 41
A6: Cairo at The First Residence | B6: =B5+1 -> 5 | C6: 1 | D6: 2021 | E6: 19809.19 | F6: =F5 -> 1.5 | G6: =1102.82+263.03 -> 1365.85 | H6: 3.89 | I6: 256.65 | J6: 10 | K6: 41
A7: Cairo at The First Residence | B7: =B6+1 -> 6 | C7: 1 | D7: 2021 | E7: 19809.19 | F7: =F6 -> 1.5 | G7: =1102.82+263.03 -> 1365.85 | H7: 3.89 | I7: 256.65 | J7: 10 | K7: 41
A8: Cairo at The First Residence | B8: =B7+1 -> 7 | C8: 1 | D8: 2021 | E8: 19809.19 | F8: =F7 -> 1.5 | G8: =1102.82+263.03 -> 1365.85 | H8: 3.89 | I8: 256.65 | J8: 10 | K8: 41
A9: Cairo at The First Residence | B9: =B8+1 -> 8 | C9: 1 | D9: 2021 | E9: 19809.19 | F9: =F8 -> 1.5 | G9: =1102.82+263.03 -> 1365.85 | H9: 3.89 | I9: 256.65 | J9: 10 | K9: 41
A10: Cairo at The First Residence | B10: =B9+1 -> 9 | C10: 1 | D10: 2021 | E10: 19809.19 | F10: =F9 -> 1.5 | G10: =1102.82+263.03 -> 1365.85 | H10: 3.89 | I10: 256.65 | J10: 10 | K10: 41
A11: Cairo at The First Residence | B11: =B10+1 -> 10 | C11: 1 | D11: 2021 | E11: 19809.19 | F11: =F10 -> 1.5 | G11: =1102.82+263.03 -> 1365.85 | H11: 3.89 | I11: 256.65 | J11: 10 | K11: 41
A12: Cairo at The First Residence | B12: =B11+1 -> 11 | C12: 1 | D12: 2021 | E12: 19809.19 | F12: =F11 -> 1.5 | G12: =1102.82+263.03 -> 1365.85 | H12: 3.89 | I12: 256.65 | J12: 10 | K12: 41
A13: Cairo at The First Residence | B13: =B12+1 -> 12 | C13: 1 | D13: 2021 | E13: 19809.19 | F13: =F12 -> 1.5 | G13: =1102.82+263.03 -> 1365.85 | H13: 3.89 | I13: 256.65 | J13: 10 | K13: 41
A14: Cairo at The First Residence | B14: =B13+1 -> 13 | C14: 1 | D14: 2021 | E14: 19809.19 | F14: =F13 -> 1.5 | G14: =1102.82+263.03 -> 1365.85 | H14: 3.89 | I14: 256.65 | J14: 10 | K14: 41
... A32: Cairo at The First Residence | B32: =B31+1 -> 31 | C32: 1 | D32: 2021 | E32: 19809.19 | F32: =F31 -> 1.5 | G32: =1102.82+263.03 -> 1365.85 | H32: 3.89 | I32: 256.65 | J32: 10 | K32: 42

Sheet Submetering
A1: Site Name | B1: Day | C1: Month | D1: Year | E1: Electricity | F1: Main Feeder -KWh | G1: T2+T8 -KWh | H1: La Gourmandize -KWh | I1: Casino 3rd floor EM -KWh | J1: Casino 3rd floor Normal -KWh | K1: Chiller 1 -KWh | L1: Chiller 2 -KWh | M1: Chiller 3 -KWh | N1: Chiller 4 -KWh | O1: Cooling towers -KWh | P1: Chiller Pumps -KWh | Q1: LG Bakery -KWh | R1: Mall Ceiling light -KWh | S1: New chiller for Second floor -KWh | T1: LG Bakery light ( Old lockers ) -KWh | U1: MCCR1 -KWh | V1: Children Swimming pool -KWh | W1: DPH1 -KWh | X1: Main G2 -KWh | Y1: Casino Emergency -KWh | Z1: L / A -KWh | AA1: L / B -KWh | AB1: L / C -KWh | AC1: Water | AD1: Main water meter 1 -m3 | AE1: Main water meter 2 -m3 | AF1: Main water meter 3 -m3 | AG1: Gas | AH1: Main Gas Flow Meter -m3 | AI1: Laundry Gas Flow Meter -m3 | AJ1: Gourmandize Gas Flow Meter -m3 | AK1: Room Nights
A2: Cairo at The First Residence | B2: 1 | C2: 1 | D2: 2021 | F2: =Elect!J6 -> 4287 | G2: =Elect!K6 -> 2822 | H2: =Elect!Q6 -> 540 | I2: =Elect!W6 -> 142 | J2: =Elect!Y6 -> 231 | K2: =Elect!AA6 -> 0 | L2: =Elect!AC6 -> 1736.28 | M2: =Elect!AE6 -> 706.49 | N2: =Elect!AG6 -> 0 | O2: =Elect!AI6 -> 305.81 | P2: =Elect!AK6 -> 1786.63 | Q2: =Elect!AN6 -> 378 | R2: =Elect!AP6 -> 262 | S2: =Elect!AR6 -> 9.57 | T2: =Elect!AT6 -> 59 | U2: =Elect!AV6 -> 613 | V2: =Elect!AX6 -> 66 | W2: =Elect!AZ6 -> 3967 | X2: =Elect!BB6 -> 3506.5 | Y2: =Elect!BE6 -> 358 | Z2: =Elect!BG6 -> 560 | AA2: =Elect!BI6 -> 111 | AB2: =Elect!BK6 -> 186 | AD2: =Water!C7 -> 0 | AE2: =Water!E7 -> 237.8 | AF2: =Water!G7 -> 7.54 | AH2: =Gas!C7 -> 894.64 | AI2: =Gas!E7 -> 375.2 | AJ2: =Gas!G7 -> 69 | AK2: 41
A3: Cairo at The First Residence | B3: =B2+1 -> 2 | C3: 1 | D3: 2021 | F3: =Elect!J7 -> 4841 | G3: =Elect!K7 -> 3098 | H3: =Elect!Q7 -> 510 | I3: =Elect!W7 -> 148 | J3: =Elect!Y7 -> 250 | K3: =Elect!AA7 -> 0 | L3: =Elect!AC7 -> 1426.76 | M3: =Elect!AE7 -> 4.77 | N3: =Elect!AG7 -> 0 | O3: =Elect!AI7 -> 264.47 | P3: =Elect!AK7 -> 1919.13 | Q3: =Elect!AN7 -> 935 | R3: =Elect!AP7 -> 217 | S3: =Elect!AR7 -> 13.31 | T3: =Elect!AT7 -> 42 | U3: =Elect!AV7 -> 606 | V3: =Elect!AX7 -> 67 | W3: =Elect!AZ7 -> 3652 | X3: =Elect!BB7 -> 4968 | Y3: =Elect!BE7 -> 358 | Z3: =Elect!BG7 -> 200 | AA3: =Elect!BI7 -> 50 | AB3: =Elect!BK7 -> 100 | AD3: =Water!C8 -> 0 | AE3: =Water!E8 -> 150.8 | AF3: =Water!G8 -> 12.18 | AH3: =Gas!C8 -> 1228.54 | AI3: =Gas!E8 -> 234.5 | AJ3: =Gas!G8 -> 64 | AK3: 41
A4: Cairo at The First Residence | B4: =B3+1 -> 3 | C4: 1 | D4: 2021 | F4: =Elect!J8 -> 4443 | G4: =Elect!K8 -> 2802 | H4: =Elect!Q8 -> 540 | I4: =Elect!W8 -> 139 | J4: =Elect!Y8 -> 233 | K4: =Elect!AA8 -> 0 | L4: =Elect!AC8 -> 2759.18 | M4: =Elect!AE8 -> 0 | N4: =Elect!AG8 -> 0 | O4: =Elect!AI8 -> 235.85 | P4: =Elect!AK8 -> 2025.66 | Q4: =Elect!AN8 -> 838 | R4: =Elect!AP8 -> 278 | S4: =Elect!AR8 -> 13.86 | T4: =Elect!AT8 -> 42 | U4: =Elect!AV8 -> 485 | V4: =Elect!AX8 -> 64 | W4: =Elect!AZ8 -> 3547 | X4: =Elect!BB8 -> 4254.1 | Y4: =Elect!BE8 -> 358 | Z4: =Elect!BG8 -> 679 | AA4: =Elect!BI8 -> 61 | AB4: =Elect!BK8 -> 91 | AD4: =Water!C9 -> 5.8 | AE4: =Water!E9 -> 185.6 | AF4: =Water!G9 -> 10.44 | AH4: =Gas!C9 -> 1025.02 | AI4: =Gas!E9 -> 297.5 | AJ4: =Gas!G9 -> 67 | AK4: 41
A5: Cairo at The First Residence | B5: =B4+1 -> 4 | C5: 1 | D5: 2021 | F5: =Elect!J9 -> 4708 | G5: =Elect!K9 -> 3174 | H5: =Elect!Q9 -> 570 | I5: =Elect!W9 -> 155 | J5: =Elect!Y9 -> 262 | K5: =Elect!AA9 -> 0 | L5: =Elect!AC9 -> 1894.22 | M5: =Elect!AE9 -> 0 | N5: =Elect!AG9 -> 0 | O5: =Elect!AI9 -> 212.53 | P5: =Elect!AK9 -> 1886.27 | Q5: =Elect!AN9 -> 1131 | R5: =Elect!AP9 -> 275 | S5: =Elect!AR9 -> 15.4 | T5: =Elect!AT9 -> 50 | U5: =Elect!AV9 -> 582 | V5: =Elect!AX9 -> 68 | W5: =Elect!AZ9 -> 4103 | X5: =Elect!BB9 -> 4703.4 | Y5: =Elect!BE9 -> 358 | Z5: =Elect!BG9 -> 946 | AA5: =Elect!BI9 -> 120 | AB5: =Elect!BK9 -> 225 | AD5: =Water!C10 -> 0 | AE5: =Water!E10 -> 174 | AF5: =Water!G10 -> 4.64 | AH5: =Gas!C10 -> 700.66 | AI5: =Gas!E10 -> 228.2 | AJ5: =Gas!G10 -> 71 | AK5: 41
A6: Cairo at The First Residence | B6: =B5+1 -> 5 | C6: 1 | D6: 2021 | F6: =Elect!J10 -> 4642 | G6: =Elect!K10 -> 2700 | H6: =Elect!Q10 -> 540 | I6: =Elect!W10 -> 144 | J6: =Elect!Y10 -> 247 | K6: =Elect!AA10 -> 0 | L6: =Elect!AC10 -> 1632.93 | M6: =Elect!AE10 -> 229.49 | N6: =Elect!AG10 -> 0 | O6: =Elect!AI10 -> 297.86 | P6: =Elect!AK10 -> 1744.23 | Q6: =Elect!AN10 -> 1209 | R6: =Elect!AP10 -> 279 | S6: =Elect!AR10 -> 14.41 | T6: =Elect!AT10 -> 37 | U6: =Elect!AV10 -> 498 | V6: =Elect!AX10 -> 67 | W6: =Elect!AZ10 -> 3339 | X6: =Elect!BB10 -> 4735.6 | Y6: =Elect!BE10 -> 358 | Z6: =Elect!BG10 -> 949 | AA6: =Elect!BI10 -> 114 | AB6: =Elect!BK10 -> 229 | AD6: =Water!C11 -> 0 | AE6: =Water!E11 -> 232 | AF6: =Water!G11 -> 8.7 | AH6: =Gas!C11 -> 1176.6 | AI6: =Gas!E11 -> 284.2 | AJ6: =Gas!G11 -> 82 | AK6: 41
A7: Cairo at The First Residence | B7: =B6+1 -> 6 | C7: 1 | D7: 2021 | F7: =Elect!J11 -> 5488 | G7: =Elect!K11 -> 2856 | H7: =Elect!Q11 -> 660 | I7: =Elect!W11 -> 176 | J7: =Elect!Y11 -> 247 | K7: =Elect!AA11 -> 0 | L7: =Elect!AC11 -> 0 | M7: =Elect!AE11 -> 1870.37 | N7: =Elect!AG11 -> 0 | O7: =Elect!AI11 -> 307.4 | P7: =Elect!AK11 -> 1781.86 | Q7: =Elect!AN11 -> 1333 | R7: =Elect!AP11 -> 295 | S7: =Elect!AR11 -> 14.74 | T7: =Elect!AT11 -> 39 | U7: =Elect!AV11 -> 510 | V7: =Elect!AX11 -> 84 | W7: =Elect!AZ11 -> 3744 | X7: =Elect!BB11 -> 4311.3 | Y7: =Elect!BE11 -> 358 | Z7: =Elect!BG11 -> 857 | AA7: =Elect!BI11 -> 97 | AB7: =Elect!BK11 -> 210 | AD7: =Water!C12 -> 5.8 | AE7: =Water!E12 -> 156.6 | AF7: =Water!G12 -> 6.96 | AH7: =Gas!C12 -> 982.62 | AI7: =Gas!E12 -> 289.1 | AJ7: =Gas!G12 -> 61 | AK7: 41
A8: Cairo at The First Residence | B8: =B7+1 -> 7 | C8: 1 | D8: 2021 | F8: =Elect!J12 -> 4353 | G8: =Elect!K12 -> 3602 | H8: =Elect!Q12 -> 570 | I8: =Elect!W12 -> 146 | J8: =Elect!Y12 -> 274 | K8: =Elect!AA12 -> 0 | L8: =Elect!AC12 -> 0 | M8: =Elect!AE12 -> 3138.13 | N8: =Elect!AG12 -> 0 | O8: =Elect!AI12 -> 328.07 | P8: =Elect!AK12 -> 2531.81 | Q8: =Elect!AN12 -> 1170 | R8: =Elect!AP12 -> 235 | S8: =Elect!AR12 -> 14.63 | T8: =Elect!AT12 -> 39 | U8: =Elect!AV12 -> 598 | V8: =Elect!AX12 -> 65 | W8: =Elect!AZ12 -> 4097 | X8: =Elect!BB12 -> 4360.1 | Y8: =Elect!BE12 -> 358 | Z8: =Elect!BG12 -> 874 | AA8: =Elect!BI12 -> 89 | AB8: =Elect!BK12 -> 199 | AD8: =Water!C13 -> 0 | AE8: =Water!E13 -> 232 | AF8: =Water!G13 -> 6.96 | AH8: =Gas!C13 -> 915.84 | AI8: =Gas!E13 -> 235.2 | AJ8: =Gas!G13 -> 54 | AK8: 41
A9: Cairo at The First Residence | B9: =B8+1 -> 8 | C9: 1 | D9: 2021 | F9: =Elect!J13 -> 4426 | G9: =Elect!K13 -> 2785 | H9: =Elect!Q13 -> 450 | I9: =Elect!W13 -> 116 | J9: =Elect!Y13 -> 225 | K9: =Elect!AA13 -> 0 | L9: =Elect!AC13 -> 0 | M9: =Elect!AE13 -> 2217.52 | N9: =Elect!AG13 -> 0 | O9: =Elect!AI13 -> 295.74 | P9: =Elect!AK13 -> 1919.66 | Q9: =Elect!AN13 -> 886 | R9: =Elect!AP13 -> 344 | S9: =Elect!AR13 -> 14.63 | T9: =Elect!AT13 -> 21 | U9: =Elect!AV13 -> 452 | V9: =Elect!AX13 -> 53 | W9: =Elect!AZ13 -> 3383 | X9: =Elect!BB13 -> 4241.5 | Y9: =Elect!BE13 -> 358 | Z9: =Elect!BG13 -> 870 | AA9: =Elect!BI13 -> 93 | AB9: =Elect!BK13 -> 193 | AD9: =Water!C14 -> 0 | AE9: =Water!E14 -> 185.6 | AF9: =Water!G14 -> 6.38 | AH9: =Gas!C14 -> 743.06 | AI9: =Gas!E14 -> 249.9 | AJ9: =Gas!G14 -> 76 | AK9: 41
A10: Cairo at The First Residence | B10: =B9+1 -> 9 | C10: 1 | D10: 2021 | F10: =Elect!J14 -> 4074 | G10: =Elect!K14 -> 2602 | H10: =Elect!Q14 -> 510 | I10: =Elect!W14 -> 152 | J10: =Elect!Y14 -> 263 | K10: =Elect!AA14 -> 0 | L10: =Elect!AC14 -> 0 | M10: =Elect!AE14 -> 0 | N10: =Elect!AG14 -> 1514.74 | O10: =Elect!AI14 -> 156.88 | P10: =Elect!AK14 -> 1643 | Q10: =Elect!AN14 -> 1139 | R10: =Elect!AP14 -> 289 | S10: =Elect!AR14 -> 13.53 | T10: =Elect!AT14 -> 21 | U10: =Elect!AV14 -> 424 | V10: =Elect!AX14 -> 70 | W10: =Elect!AZ14 -> 3798 | X10: =Elect!BB14 -> 3776.6 | Y10: =Elect!BE14 -> 358 | Z10: =Elect!BG14 -> 809 | AA10: =Elect!BI14 -> 110 | AB10: =Elect!BK14 -> 176 | AD10: =Water!C15 -> 0 | AE10: =Water!E15 -> 307.4 | AF10: =Water!G15 -> 10.44 | AH10: =Gas!C15 -> 854.36 | AI10: =Gas!E15 -> 290.5 | AJ10: =Gas!G15 -> 67 | AK10: 41
A11: Cairo at The First Residence | B11: =B10+1 -> 10 | C11: 1 | D11: 2021 | F11: =Elect!J15 -> 5552 | G11: =Elect!K15 -> 2812 | H11: =Elect!Q15 -> 540 | I11: =Elect!W15 -> 135 | J11: =Elect!Y15 -> 236 | K11: =Elect!AA15 -> 0 | L11: =Elect!AC15 -> 0 | M11: =Elect!AE15 -> 0 | N11: =Elect!AG15 -> 2221.23 | O11: =Elect!AI15 -> 209.88 | P11: =Elect!AK15 -> 1989.09 | Q11: =Elect!AN15 -> 1067 | R11: =Elect!AP15 -> 275 | S11: =Elect!AR15 -> 15.18 | T11: =Elect!AT15 -> 38 | U11: =Elect!AV15 -> 447 | V11: =Elect!AX15 -> 62 | W11: =Elect!AZ15 -> 2855 | X11: =Elect!BB15 -> 4956 | Y11: =Elect!BE15 -> 358 | Z11: =Elect!BG15 -> 1065 | AA11: =Elect!BI15 -> 138 | AB11: =Elect!BK15 -> 226 | AD11: =Water!C16 -> 5.8 | AE11: =Water!E16 -> 307.4 | AF11: =Water!G16 -> 8.12 | AH11: =Gas!C16 -> 1020.78 | AI11: =Gas!E16 -> 314.3 | AJ11: =Gas!G16 -> 102 | AK11: 41
A12: Cairo at The First Residence | B12: =B11+1 -> 11 | C12: 1 | D12: 2021 | F12: =Elect!J16 -> 2990 | G12: =Elect!K16 -> 2698 | H12: =Elect!Q16 -> 540 | I12: =Elect!W16 -> 135 | J12: =Elect!Y16 -> 234 | K12: =Elect!AA16 -> 0 | L12: =Elect!AC16 -> 0 | M12: =Elect!AE16 -> 0 | N12: =Elect!AG16 -> 2017.18 | O12: =Elect!AI16 -> 172.78 | P12: =Elect!AK16 -> 1856.59 | Q12: =Elect!AN16 -> 1063 | R12: =Elect!AP16 -> 275 | S12: =Elect!AR16 -> 10.89 | T12: =Elect!AT16 -> 38 | U12: =Elect!AV16 -> 472 | V12: =Elect!AX16 -> 35 | W12: =Elect!AZ16 -> 3367 | X12: =Elect!BB16 -> 3231.7 | Y12: =Elect!BE16 -> 358 | Z12: =Elect!BG16 -> 678 | AA12: =Elect!BI16 -> 87 | AB12: =Elect!BK16 -> 148 | AD12: =Water!C17 -> 0 | AE12: =Water!E17 -> 284.2 | AF12: =Water!G17 -> 6.38 | AH12: =Gas!C17 -> 915.84 | AI12: =Gas!E17 -> 232.4 | AJ12: =Gas!G17 -> 50 | AK12: 41
A13: Cairo at The First Residence | B13: =B12+1 -> 12 | C13: 1 | D13: 2021 | F13: =Elect!J17 -> 4437 | G13: =Elect!K17 -> 2787 | H13: =Elect!Q17 -> 600 | I13: =Elect!W17 -> 152 | J13: =Elect!Y17 -> 263 | K13: =Elect!AA17 -> 0 | L13: =Elect!AC17 -> 0 | M13: =Elect!AE17 -> 0 | N13: =Elect!AG17 -> 2237.13 | O13: =Elect!AI17 -> 208.82 | P13: =Elect!AK17 -> 2083.96 | Q13: =Elect!AN17 -> 1032 | R13: =Elect!AP17 -> 297 | S13: =Elect!AR17 -> 14.85 | T13: =Elect!AT17 -> 44 | U13: =Elect!AV17 -> 505 | V13: =Elect!AX17 -> 17 | W13: =Elect!AZ17 -> 3794 | X13: =Elect!BB17 -> 4736.4 | Y13: =Elect!BE17 -> 358 | Z13: =Elect!BG17 -> 956 | AA13: =Elect!BI17 -> 112 | AB13: =Elect!BK17 -> 211 | AD13: =Water!C18 -> 0 | AE13: =Water!E18 -> 237.8 | AF13: =Water!G18 -> 6.96 | AH13: =Gas!C18 -> 963.54 | AI13: =Gas!E18 -> 209.3 | AJ13: =Gas!G18 -> 80 | AK13: 41
A14: Cairo at The First Residence | B14: =B13+1 -> 13 | C14: 1 | D14: 2021 | F14: =Elect!J18 -> 3726 | G14: =Elect!K18 -> 2485 | H14: =Elect!Q18 -> 480 | I14: =Elect!W18 -> 118 | J14: =Elect!Y18 -> 211 | K14: =Elect!AA18 -> 0 | L14: =Elect!AC18 -> 1437.36 | M14: =Elect!AE18 -> 0 | N14: =Elect!AG18 -> 353.51 | O14: =Elect!AI18 -> 151.58 | P14: =Elect!AK18 -> 1656.25 | Q14: =Elect!AN18 -> 1150 | R14: =Elect!AP18 -> 268 | S14: =Elect!AR18 -> 12.76 | T14: =Elect!AT18 -> 35 | U14: =Elect!AV18 -> 428 | V14: =Elect!AX18 -> 35 | W14: =Elect!AZ18 -> 3082 | X14: =Elect!BB18 -> 3811.4 | Y14: =Elect!BE18 -> 358 | Z14: =Elect!BG18 -> 776 | AA14: =Elect!BI18 -> 84 | AB14: =Elect!BK18 -> 173 | AD14: =Water!C19 -> 5.8 | AE14: =Water!E19 -> 214.6 | AF14: =Water!G19 -> 6.96 | AH14: =Gas!C19 -> 962.48 | AI14: =Gas!E19 -> 179.2 | AJ14: =Gas!G19 -> 71 | AK14: 41
... A32: Cairo at The First Residence | B32: =B31+1 -> 31 | C32: 1 | D32: 2021 | F32: =Elect!J36 -> 4562 | G32: =Elect!K36 -> 2818 | H32: =Elect!Q36 -> 570 | I32: =Elect!W36 -> 144 | J32: =Elect!Y36 -> 243 | K32: =Elect!AA36 -> 0 | L32: =Elect!AC36 -> 1307.51 | M32: =Elect!AE36 -> 0 | N32: =Elect!AG36 -> 0 | O32: =Elect!AI36 -> 160.06 | P32: =Elect!AK36 -> 1604.31 | Q32: =Elect!AN36 -> 679 | R32: =Elect!AP36 -> 284 | S32: =Elect!AR36 -> 12.65 | T32: =Elect!AT36 -> 29 | U32: =Elect!AV36 -> 424 | V32: =Elect!AX36 -> 61 | W32: =Elect!AZ36 -> 3432 | X32: =Elect!BB36 -> 3383 | Y32: =Elect!BE36 -> 351 | Z32: =Elect!BG36 -> 871 | AA32: =Elect!BI36 -> 114 | AB32: =Elect!BK36 -> 201 | AD32: =Water!C37 -> 0 | AE32: =Water!E37 -> 208.8 | AF32: =Water!G37 -> 0 | AH32: =Gas!C37 -> 1490.36 | AI32: =Gas!E37 -> 202.3 | AJ32: =Gas!G37 -> 41 | AK32: 42

Sheet Elect
A1: January | M1: Electricity | BL1: Power Taxes | BM1: 0.0006 | BN1: Max Demand | BP1: 500 | BQ1: Electricity UP | BS1: 0.46
AL2: =SUM(AL22:AL36) -> 46363.34 | BC2: =SUM(BC22:BC36) -> 135013.66 | BL2: Light Taxes | BM2: 0.03 | BN2: PF Penalty | BQ2: Max. Demand UP | BS2: 30
A3: Date | B3: COUNTER (1) | D3: MD | F3: KVAR | H3: n | I3: Guest Rooms Consumption | R3: Casino Consumption | AD3: Plant Room Shared Loads | AW3: To Be Charged By First Arabian | BG3: From Main Panel G2 | BL3: Total Consumption. | BM3: No. Of | BN3: KWH/ | BO3: No. Of | BP3: KWH/ | BQ3: Total Cost | BR3: L.E\ | BS3: L.E\
B4: Reading | C4: Consp. F: *800 | D4: Reading | E4: Consp F: 80 | F4: Reading | G4: Consp. F:*10 | I4: Main Feeder | J4: Consp | K4: T2+T8 | L4: Trans T2 | M4: Consp | N4: Trans T8 | O4: Consp | P4: La Gourmandize | Q4: Consp *30 | R4: Casino 1 | S4: Consp | T4: Casino 2 | U4: Consp | V4: Casino 3rd floor EM | W4: Consp | X4: Casino 3rd floor Normal | Y4: Consp | Z4: Chiller 1 | AA4: Consp 53% | AB4: Chiller 2 | AC4: Consp 53% | AD4: Chiller 3 | AE4: Consp 53% | AF4: Chiller 4 | AG4: Consp 53% | AH4: Cooling towers | AI4: Consp 53% | AJ4: Chiller Pumps | AK4: Consp 53% | AL4: Total Plant Room Consp | AM4: LG Emergency (N24) | AN4: Consp | AO4: Mall Ceiling light | AP4: Consp | AQ4: New chiller for Second floor | AR4: Consp | AS4: LG Bakery light ( Old lockers ) | AT4: Consp | AU4: MCCR1 | AV4: Consp | AW4: Children Swimming pool | AX4: Consp | AY4: DPH1 | AZ4: Consp | BA4: Main G2 | BB4: Consp | BC4: Total Consp From First Arabian | BD4: Casino Emergency | BE4: Consp | BF4: L / A | BG4: Consp | BH4: L / B | BI4: Consp | BJ4: L / C | BK4: Consp | BM4: Rooms | BN4: room | BO4: guest | BP4: guest | BR4: Room | BS4: Guest
A5: Last Month Reading | I5: 21912456 | J5: =IF(I5>=I4,I5-I4,0) -> 0 | K5: =M5+O5 -> 0 | L5: 963064 | M5: =IF(L5>=L4,L5-L4,0) -> 0 | N5: 960763 | O5: =IF(N5>=N4,N5-N4,0) -> 0 | P5: 214160 | Q5: =IF(P5>=P4,P5-P4,0)*30 -> 0 | R5: 702925 | S5: =IF(R5>=R4,R5-R4,0) -> 0 | T5: 344001 | U5: =IF(T5>=T4,T5-T4,0) -> 0 | V5: 126502 | W5: =IF(V5>=V4,V5-V4,0) -> 0 | X5: 230746 | Y5: =IF(X5>=X4,X5-X4,0) -> 0 | Z5: 315108 | AA5: =IF(Z5>=Z4,Z5-Z4,0)*0.53 -> 0 | AB5: 329557 | AC5: =IF(AB5>=AB4,AB5-AB4,0)*0.53 -> 0 | AD5: 536016 | AE5: =IF(AD5>=AD4,AD5-AD4,0)*0.53 -> 0 | AF5: 289399 | AG5: =IF(AF5>=AF4,AF5-AF4,0)*0.53 -> 0 | AH5: 522364 | AI5: =IF(AH5>=AH4,AH5-AH4,0)*0.53 -> 0 | AJ5: 610356 | AK5: =IF(AJ5>=AJ4,AJ5-AJ4,0)*0.53 -> 0 | AL5: =AA5+AC5+AE5+AG5+AI5+AK5 -> 0 | AM5: 7188062 | AN5: =IF(AM5>=AM4,AM5-AM4,0) -> 0 | AO5: 565575 | AP5: =IF(AO5>=AO4,AO5-AO4,0) -> 0 | AQ5: 909729 | AR5: =IF(AQ5>=AQ4,AQ5-AQ4,0)*0.11 -> 0 | AS5: 793687 | AT5: =IF(AS5>=AS4,AS5-AS4,0) -> 0 | AU5: 2322338 | AV5: =IF(AU5>=AU4,AU5-AU4,0) -> 0 | AW5: 207611 | AX5: 0 | AY5: 17561805 | AZ5: =IF(AY5>=AY4,AY5-AY4,0) -> 0 | BA5: 21729015 | BB5: =IF(BA5>=BA4,BA5-BA4,0)-(0.6*BG5)-(0.5*BI5)-BK5-BE5 -> 0 | BC5: =AN5+AP5+AR5+AT5+AV5+AX5+AZ5+BB5 -> 0 | BD5: 1358289 | BE5: =IF(BD5>=BD4,BD5-BD4,0) -> 0 | BF5: 3465261 | BG5: =IF(BF5>=BF4,BF5-BF4,0) -> 0 | BH5: 369481 | BI5: =IF(BH5>=BH4,BH5-BH4,0) -> 0 | BJ5: 446214 | BK5: =IF(BJ5>=BJ4,BJ5-BJ4,0) -> 0
A6: 1 | C6: =IF(+B6-B5>0,B6-B5,(B6-B5)>0)*800 -> 0 | E6: =IF(+D6-D5>0,D6-D5,(D6-D5)>0)*80 -> 0 | G6: =IF(+F6-F5>0,F6-F5,(F6-F5)>0)*10 -> 0 | H6: 56 | I6: 21916743 | J6: =IF(I6>=I5,I6-I5,0) -> 4287 | K6: =M6+O6 -> 2822 | L6: 964445 | M6: =IF(L6>=L5,L6-L5,0) -> 1381 | N6: 962204 | O6: =IF(N6>=N5,N6-N5,0) -> 1441 | P6: 214178 | Q6: =IF(P6>=P5,P6-P5,0)*30 -> 540 | R6: 702925 | S6: =IF(R6>=R5,R6-R5,0) -> 0 | T6: 344001 | U6: =IF(T6>=T5,T6-T5,0) -> 0 | V6: 126644 | W6: =IF(V6>=V5,V6-V5,0) -> 142 | X6: 230977 | Y6: =IF(X6>=X5,X6-X5,0) -> 231 | Z6: 315108 | AA6: =IF(Z6>=Z5,Z6-Z5,0)*0.53 -> 0 | AB6: 332833 | AC6: =IF(AB6>=AB5,AB6-AB5,0)*0.53 -> 1736.28 | AD6: 537349 | AE6: =IF(AD6>=AD5,AD6-AD5,0)*0.53 -> 706.49 | AF6: 289399 | AG6: =IF(AF6>=AF5,AF6-AF5,0)*0.53 -> 0 | AH6: 522941 | AI6: =IF(AH6>=AH5,AH6-AH5,0)*0.53 -> 305.81 | AJ6: 613727 | AK6: =IF(AJ6>=AJ5,AJ6-AJ5,0)*0.53 -> 1786.63 | AL6: =AA6+AC6+AE6+AG6+AI6+AK6 -> 4535.21 | AM6: 7188440 | AN6: =IF(AM6>=AM5,AM6-AM5,0) -> 378 | AO6: 565837 | AP6: =IF(AO6>=AO5,AO6-AO5,0) -> 262 | AQ6: 909816 | AR6: =IF(AQ6>=AQ5,AQ6-AQ5,0)*0.11 -> 9.57 | AS6: 793746 | AT6: =IF(AS6>=AS5,AS6-AS5,0) -> 59 | AU6: 2322951 | AV6: =IF(AU6>=AU5,AU6-AU5,0) -> 613 | AW6: 207677 | AX6: =IF(AW6>=AW5,AW6-AW5,0) -> 66 | AY6: 17565772 | AZ6: =IF(AY6>=AY5,AY6-AY5,0) -> 3967 | BA6: 21733457 | BB6: =IF(BA6>=BA5,BA6-BA5,0)-(0.6*BG6)-(0.5*BI6)-BK6-BE6 -> 3506.5 | BC6: =AN6+AP6+AR6+AT6+AV6+AX6+AZ6+BB6 -> 8861.07 | BD6: 1358647 | BE6: =IF(BD6>=BD5,BD6-BD5,0) -> 358 | BF6: 3465821 | BG6: =IF(BF6>=BF5,BF6-BF5,0) -> 560 | BH6: 369592 | BI6: =IF(BH6>=BH5,BH6-BH5,0) -> 111 | BJ6: 446400 | BK6: =IF(BJ6>=BJ5,BJ6-BJ5,0) -> 186 | BL6: =J6+Q6+AL6+BC6 -> 18223.28 | BM6: 73 | BN6: =IF(BL6>0,BL6/#REF!,0) -> #REF! | BP6: =IF(BL6>0,BL6/BO6,0) -> #DIV/0! | BQ6: =BL6*BS1 -> 8382.7088 | BR6: =IF(BQ6>0,BQ6/#REF!,0) -> #REF! | BS6: =IF(BQ6>0,BQ6/BO6,0) -> #DIV/0!
A7: 2 | I7: 21921584 | J7: =IF(I7>=I6,I7-I6,0) -> 4841 | K7: =M7+O7 -> 3098 | L7: 965956 | M7: =IF(L7>=L6,L7-L6,0) -> 1511 | N7: 963791 | O7: =IF(N7>=N6,N7-N6,0) -> 1587 | P7: 214195 | Q7: =IF(P7>=P6,P7-P6,0)*30 -> 510 | R7: 702925 | S7: =IF(R7>=R6,R7-R6,0) -> 0 | T7: 344001 | U7: =IF(T7>=T6,T7-T6,0) -> 0 | V7: 126792 | W7: =IF(V7>=V6,V7-V6,0) -> 148 | X7: 231227 | Y7: =IF(X7>=X6,X7-X6,0) -> 250 | Z7: 315108 | AA7: =IF(Z7>=Z6,Z7-Z6,0)*0.53 -> 0 | AB7: 335525 | AC7: =IF(AB7>=AB6,AB7-AB6,0)*0.53 -> 1426.76 | AD7: 537358 | AE7: =IF(AD7>=AD6,AD7-AD6,0)*0.53 -> 4.77 | AF7: 289399 | AG7: =IF(AF7>=AF6,AF7-AF6,0)*0.53 -> 0 | AH7: 523440 | AI7: =IF(AH7>=AH6,AH7-AH6,0)*0.53 -> 264.47 | AJ7: 617348 | AK7: =IF(AJ7>=AJ6,AJ7-AJ6,0)*0.53 -> 1919.13 | AL7: =AA7+AC7+AE7+AG7+AI7+AK7 -> 3615.13 | AM7: 7189375 | AN7: =IF(AM7>=AM6,AM7-AM6,0) -> 935 | AO7: 566054 | AP7: =IF(AO7>=AO6,AO7-AO6,0) -> 217 | AQ7: 909937 | AR7: =IF(AQ7>=AQ6,AQ7-AQ6,0)*0.11 -> 13.31 | AS7: 793788 | AT7: =IF(AS7>=AS6,AS7-AS6,0) -> 42 | AU7: 2323557 | AV7: =IF(AU7>=AU6,AU7-AU6,0) -> 606 | AW7: 207744 | AX7: =IF(AW7>=AW6,AW7-AW6,0) -> 67 | AY7: 17569424 | AZ7: =IF(AY7>=AY6,AY7-AY6,0) -> 3652 | BA7: 21739028 | BB7: =IF(BA7>=BA6,BA7-BA6,0)-(0.6*BG7)-(0.5*BI7)-BK7-BE7 -> 4968 | BC7: =AN7+AP7+AR7+AT7+AV7+AX7+AZ7+BB7 -> 10500.31 | BD7: 1359005 | BE7: =IF(BD7>=BD6,BD7-BD6,0) -> 358 | BF7: 3466021 | BG7: =IF(BF7>=BF6,BF7-BF6,0) -> 200 | BH7: 369642 | BI7: =IF(BH7>=BH6,BH7-BH6,0) -> 50 | BJ7: 446500 | BK7: =IF(BJ7>=BJ6,BJ7-BJ6,0) -> 100 | BL7: =J7+Q7+AL7+BC7 -> 19466.44 | BM7: 54 | BN7: =IF(BL7>0,BL7/BM6,0) -> 266.66356 | BP7: =IF(BL7>0,BL7/BO7,0) -> #DIV/0! | BQ7: =BL7*BS1 -> 8954.5624 | BR7: =IF(BQ7>0,BQ7/BM6,0) -> 122.66524 | BS7: =IF(BQ7>0,BQ7/BO7,0) -> #DIV/0!
A8: 3 | C8: =IF(+B8-B7>0,B8-B7,(B8-B7)>0)*800 -> 0 | E8: =IF(+D8-D7>0,D8-D7,(D8-D7)>0)*80 -> 0 | G8: =IF(+F8-F7>0,F8-F7,(F8-F7)>0)*10 -> 0 | H8: 57 | I8: 21926027 | J8: =IF(I8>=I7,I8-I7,0) -> 4443 | K8: =M8+O8 -> 2802 | L8: 967261 | M8: =IF(L8>=L7,L8-L7,0) -> 1305 | N8: 965288 | O8: =IF(N8>=N7,N8-N7,0) -> 1497 | P8: 214213 | Q8: =IF(P8>=P7,P8-P7,0)*30 -> 540 | R8: 702925 | S8: =IF(R8>=R7,R8-R7,0) -> 0 | T8: 344001 | U8: =IF(T8>=T7,T8-T7,0) -> 0 | V8: 126931 | W8: =IF(V8>=V7,V8-V7,0) -> 139 | X8: 231460 | Y8: =IF(X8>=X7,X8-X7,0) -> 233 | Z8: 315108 | AA8: =IF(Z8>=Z7,Z8-Z7,0)*0.53 -> 0 | AB8: 340731 | AC8: =IF(AB8>=AB7,AB8-AB7,0)*0.53 -> 2759.18 | AD8: 537358 | AE8: =IF(AD8>=AD7,AD8-AD7,0)*0.53 -> 0 | AF8: 289399 | AG8: =IF(AF8>=AF7,AF8-AF7,0)*0.53 -> 0 | AH8: 523885 | AI8: =IF(AH8>=AH7,AH8-AH7,0)*0.53 -> 235.85 | AJ8: 621170 | AK8: =IF(AJ8>=AJ7,AJ8-AJ7,0)*0.53 -> 2025.66 | AL8: =AA8+AC8+AE8+AG8+AI8+AK8 -> 5020.69 | AM8: 7190213 | AN8: =IF(AM8>=AM7,AM8-AM7,0) -> 838 | AO8: 566332 | AP8: =IF(AO8>=AO7,AO8-AO7,0) -> 278 | AQ8: 910063 | AR8: =IF(AQ8>=AQ7,AQ8-AQ7,0)*0.11 -> 13.86 | AS8: 793830 | AT8: =IF(AS8>=AS7,AS8-AS7,0) -> 42 | AU8: 2324042 | AV8: =IF(AU8>=AU7,AU8-AU7,0) -> 485 | AW8: 207808 | AX8: =IF(AW8>=AW7,AW8-AW7,0) -> 64 | AY8: 17572971 | AZ8: =IF(AY8>=AY7,AY8-AY7,0) -> 3547 | BA8: 21744169 | BB8: =IF(BA8>=BA7,BA8-BA7,0)-(0.6*BG8)-(0.5*BI8)-BK8-BE8 -> 4254.1 | BC8: =AN8+AP8+AR8+AT8+AV8+AX8+AZ8+BB8 -> 9521.96 | BD8: 1359363 | BE8: =IF(BD8>=BD7,BD8-BD7,0) -> 358 | BF8: 3466700 | BG8: =IF(BF8>=BF7,BF8-BF7,0) -> 679 | BH8: 369703 | BI8: =IF(BH8>=BH7,BH8-BH7,0) -> 61 | BJ8: 446591 | BK8: =IF(BJ8>=BJ7,BJ8-BJ7,0) -> 91 | BL8: =J8+Q8+AL8+BC8 -> 19525.65 | BM8: 43 | BN8: =IF(BL8>0,BL8/BM7,0) -> 361.58611 | BP8: =IF(BL8>0,BL8/BO8,0) -> #DIV/0! | BQ8: =BL8*BS1 -> 8981.799 | BR8: =IF(BQ8>0,BQ8/BM7,0) -> 166.32961 | BS8: =IF(BQ8>0,BQ8/BO8,0) -> #DIV/0!
A9: 4 | C9: =IF(+B9-B8>0,B9-B8,(B9-B8)>0)*800 -> 0 | E9: =IF(+D9-D8>0,D9-D8,(D9-D8)>0)*80 -> 0 | G9: =IF(+F9-F8>0,F9-F8,(F9-F8)>0)*10 -> 0 | I9: 21930735 | J9: =IF(I9>=I8,I9-I8,0) -> 4708 | K9: =M9+O9 -> 3174 | L9: 968671 | M9: =IF(L9>=L8,L9-L8,0) -> 1410 | N9: 967052 | O9: =IF(N9>=N8,N9-N8,0) -> 1764 | P9: 214232 | Q9: =IF(P9>=P8,P9-P8,0)*30 -> 570 | R9: 702925 | S9: =IF(R9>=R8,R9-R8,0) -> 0 | T9: 344001 | U9: =IF(T9>=T8,T9-T8,0) -> 0 | V9: 127086 | W9: =IF(V9>=V8,V9-V8,0) -> 155 | X9: 231722 | Y9: =IF(X9>=X8,X9-X8,0) -> 262 | Z9: 315108 | AA9: =IF(Z9>=Z8,Z9-Z8,0)*0.53 -> 0 | AB9: 344305 | AC9: =IF(AB9>=AB8,AB9-AB8,0)*0.53 -> 1894.22 | AD9: 537358 | AE9: =IF(AD9>=AD8,AD9-AD8,0)*0.53 -> 0 | AF9: 289399 | AG9: =IF(AF9>=AF8,AF9-AF8,0)*0.53 -> 0 | AH9: 524286 | AI9: =IF(AH9>=AH8,AH9-AH8,0)*0.53 -> 212.53 | AJ9: 624729 | AK9: =IF(AJ9>=AJ8,AJ9-AJ8,0)*0.53 -> 1886.27 | AL9: =AA9+AC9+AE9+AG9+AI9+AK9 -> 3993.02 | AM9: 7191344 | AN9: =IF(AM9>=AM8,AM9-AM8,0) -> 1131 | AO9: 566607 | AP9: =IF(AO9>=AO8,AO9-AO8,0) -> 275 | AQ9: 910203 | AR9: =IF(AQ9>=AQ8,AQ9-AQ8,0)*0.11 -> 15.4 | AS9: 793880 | AT9: =IF(AS9>=AS8,AS9-AS8,0) -> 50 | AU9: 2324624 | AV9: =IF(AU9>=AU8,AU9-AU8,0) -> 582 | AW9: 207876 | AX9: =IF(AW9>=AW8,AW9-AW8,0) -> 68 | AY9: 17577074 | AZ9: =IF(AY9>=AY8,AY9-AY8,0) -> 4103 | BA9: 21750083 | BB9: =IF(BA9>=BA8,BA9-BA8,0)-(0.6*BG9)-(0.5*BI9)-BK9-BE9 -> 4703.4 | BC9: =AN9+AP9+AR9+AT9+AV9+AX9+AZ9+BB9 -> 10927.8 | BD9: 1359721 | BE9: =IF(BD9>=BD8,BD9-BD8,0) -> 358 | BF9: 3467646 | BG9: =IF(BF9>=BF8,BF9-BF8,0) -> 946 | BH9: 369823 | BI9: =IF(BH9>=BH8,BH9-BH8,0) -> 120 | BJ9: 446816 | BK9: =IF(BJ9>=BJ8,BJ9-BJ8,0) -> 225 | BL9: =J9+Q9+AL9+BC9 -> 20198.82 | BM9: 50 | BN9: =IF(BL9>0,BL9/BM8,0) -> 469.74 | BP9: =IF(BL9>0,BL9/BO9,0) -> #DIV/0! | BQ9: =BL9*BS1 -> 9291.4572 | BR9: =IF(BQ9>0,BQ9/BM8,0) -> 216.0804 | BS9: =IF(BQ9>0,BQ9/BO9,0) -> #DIV/0!
A10: 5 | C10: =IF(+B10-B9>0,B10-B9,(B10-B9)>0)*800 -> 0 | E10: =IF(+D10-D9>0,D10-D9,(D10-D9)>0)*80 -> 0 | G10: =IF(+F10-F9>0,F10-F9,(F10-F9)>0)*10 -> 0 | H10: 58 | I10: 21935377 | J10: =IF(I10>=I9,I10-I9,0) -> 4642 | K10: =M10+O10 -> 2700 | L10: 969846 | M10: =IF(L10>=L9,L10-L9,0) -> 1175 | N10: 968577 | O10: =IF(N10>=N9,N10-N9,0) -> 1525 | P10: 214250 | Q10: =IF(P10>=P9,P10-P9,0)*30 -> 540 | R10: 702925 | S10: =IF(R10>=R9,R10-R9,0) -> 0 | T10: 344001 | U10: =IF(T10>=T9,T10-T9,0) -> 0 | V10: 127230 | W10: =IF(V10>=V9,V10-V9,0) -> 144 | X10: 231969 | Y10: =IF(X10>=X9,X10-X9,0) -> 247 | Z10: 315108 | AA10: =IF(Z10>=Z9,Z10-Z9,0)*0.53 -> 0 | AB10: 347386 | AC10: =IF(AB10>=AB9,AB10-AB9,0)*0.53 -> 1632.93 | AD10: 537791 | AE10: =IF(AD10>=AD9,AD10-AD9,0)*0.53 -> 229.49 | AF10: 289399 | AG10: =IF(AF10>=AF9,AF10-AF9,0)*0.53 -> 0 | AH10: 524848 | AI10: =IF(AH10>=AH9,AH10-AH9,0)*0.53 -> 297.86 | AJ10: 628020 | AK10: =IF(AJ10>=AJ9,AJ10-AJ9,0)*0.53 -> 1744.23 | AL10: =AA10+AC10+AE10+AG10+AI10+AK10 -> 3904.51 | AM10: 7192553 | AN10: =IF(AM10>=AM9,AM10-AM9,0) -> 1209 | AO10: 566886 | AP10: =IF(AO10>=AO9,AO10-AO9,0) -> 279 | AQ10: 910334 | AR10: =IF(AQ10>=AQ9,AQ10-AQ9,0)*0.11 -> 14.41 | AS10: 793917 | AT10: =IF(AS10>=AS9,AS10-AS9,0) -> 37 | AU10: 2325122 | AV10: =IF(AU10>=AU9,AU10-AU9,0) -> 498 | AW10: 207943 | AX10: =IF(AW10>=AW9,AW10-AW9,0) -> 67 | AY10: 17580413 | AZ10: =IF(AY10>=AY9,AY10-AY9,0) -> 3339 | BA10: 21756032 | BB10: =IF(BA10>=BA9,BA10-BA9,0)-(0.6*BG10)-(0.5*BI10)-BK10-BE10 -> 4735.6 | BC10: =AN10+AP10+AR10+AT10+AV10+AX10+AZ10+BB10 -> 10179.01 | BD10: 1360079 | BE10: =IF(BD10>=BD9,BD10-BD9,0) -> 358 | BF10: 3468595 | BG10: =IF(BF10>=BF9,BF10-BF9,0) -> 949 | BH10: 369937 | BI10: =IF(BH10>=BH9,BH10-BH9,0) -> 114 | BJ10: 447045 | BK10: =IF(BJ10>=BJ9,BJ10-BJ9,0) -> 229 | BL10: =J10+Q10+AL10+BC10 -> 19265.52 | BM10: 53 | BN10: =IF(BL10>0,BL10/BM9,0) -> 385.3104 | BP10: =IF(BL10>0,BL10/BO10,0) -> #DIV/0! | BQ10: =BL10*BS1 -> 8862.1392 | BR10: =IF(BQ10>0,BQ10/BM9,0) -> 177.24278 | BS10: =IF(BQ10>0,BQ10/BO10,0) -> #DIV/0!
A11: 6 | C11: =IF(+B11-B10>0,B11-B10,(B11-B10)>0)*800 -> 0 | E11: =IF(+D11-D10>0,D11-D10,(D11-D10)>0)*80 -> 0 | G11: =IF(+F11-F10>0,F11-F10,(F11-F10)>0)*10 -> 0 | I11: 21940865 | J11: =IF(I11>=I10,I11-I10,0) -> 5488 | K11: =M11+O11 -> 2856 | L11: 971081 | M11: =IF(L11>=L10,L11-L10,0) -> 1235 | N11: 970198 | O11: =IF(N11>=N10,N11-N10,0) -> 1621 | P11: 214272 | Q11: =IF(P11>=P10,P11-P10,0)*30 -> 660 | R11: 702925 | S11: =IF(R11>=R10,R11-R10,0) -> 0 | T11: 344001 | U11: =IF(T11>=T10,T11-T10,0) -> 0 | V11: 127406 | W11: =IF(V11>=V10,V11-V10,0) -> 176 | X11: 232216 | Y11: =IF(X11>=X10,X11-X10,0) -> 247 | Z11: 315108 | AA11: =IF(Z11>=Z10,Z11-Z10,0)*0.53 -> 0 | AB11: 347386 | AC11: =IF(AB11>=AB10,AB11-AB10,0)*0.53 -> 0 | AD11: 541320 | AE11: =IF(AD11>=AD10,AD11-AD10,0)*0.53 -> 1870.37 | AF11: 289399 | AG11: =IF(AF11>=AF10,AF11-AF10,0)*0.53 -> 0 | AH11: 525428 | AI11: =IF(AH11>=AH10,AH11-AH10,0)*0.53 -> 307.4 | AJ11: 631382 | AK11: =IF(AJ11>=AJ10,AJ11-AJ10,0)*0.53 -> 1781.86 | AL11: =AA11+AC11+AE11+AG11+AI11+AK11 -> 3959.63 | AM11: 7193886 | AN11: =IF(AM11>=AM10,AM11-AM10,0) -> 1333 | AO11: 567181 | AP11: =IF(AO11>=AO10,AO11-AO10,0) -> 295 | AQ11: 910468 | AR11: =IF(AQ11>=AQ10,AQ11-AQ10,0)*0.11 -> 14.74 | AS11: 793956 | AT11: =IF(AS11>=AS10,AS11-AS10,0) -> 39 | AU11: 2325632 | AV11: =IF(AU11>=AU10,AU11-AU10,0) -> 510 | AW11: 208027 | AX11: =IF(AW11>=AW10,AW11-AW10,0) -> 84 | AY11: 17584157 | AZ11: =IF(AY11>=AY10,AY11-AY10,0) -> 3744 | BA11: 21761474 | BB11: =IF(BA11>=BA10,BA11-BA10,0)-(0.6*BG11)-(0.5*BI11)-BK11-BE11 -> 4311.3 | BC11: =AN11+AP11+AR11+AT11+AV11+AX11+AZ11+BB11 -> 10331.04 | BD11: 1360437 | BE11: =IF(BD11>=BD10,BD11-BD10,0) -> 358 | BF11: 3469452 | BG11: =IF(BF11>=BF10,BF11-BF10,0) -> 857 | BH11: 370034 | BI11: =IF(BH11>=BH10,BH11-BH10,0) -> 97 | BJ11: 447255 | BK11: =IF(BJ11>=BJ10,BJ11-BJ10,0) -> 210 | BL11: =J11+Q11+AL11+BC11 -> 20438.67 | BM11: 50 | BN11: =IF(BL11>0,BL11/BM10,0) -> 385.63528 | BP11: =IF(BL11>0,BL11/BO11,0) -> #DIV/0! | BQ11: =BL11*BS1 -> 9401.7882 | BR11: =IF(BQ11>0,BQ11/BM10,0) -> 177.39223 | BS11: =IF(BQ11>0,BQ11/BO11,0) -> #DIV/0!
A12: 7 | C12: =IF(+B12-B11>0,B12-B11,(B12-B11)>0)*800 -> 0 | E12: =IF(+D12-D11>0,D12-D11,(D12-D11)>0)*80 -> 0 | G12: =IF(+F12-F11>0,F12-F11,(F12-F11)>0)*10 -> 0 | H12: 59 | I12: 21945218 | J12: =IF(I12>=I11,I12-I11,0) -> 4353 | K12: =M12+O12 -> 3602 | L12: 972687 | M12: =IF(L12>=L11,L12-L11,0) -> 1606 | N12: 972194 | O12: =IF(N12>=N11,N12-N11,0) -> 1996 | P12: 214291 | Q12: =IF(P12>=P11,P12-P11,0)*30 -> 570 | R12: 702925 | S12: =IF(R12>=R11,R12-R11,0) -> 0 | T12: 344001 | U12: =IF(T12>=T11,T12-T11,0) -> 0 | V12: 127552 | W12: =IF(V12>=V11,V12-V11,0) -> 146 | X12: 232490 | Y12: =IF(X12>=X11,X12-X11,0) -> 274 | Z12: 315108 | AA12: =IF(Z12>=Z11,Z12-Z11,0)*0.53 -> 0 | AB12: 347386 | AC12: =IF(AB12>=AB11,AB12-AB11,0)*0.53 -> 0 | AD12: 547241 | AE12: =IF(AD12>=AD11,AD12-AD11,0)*0.53 -> 3138.13 | AF12: 289399 | AG12: =IF(AF12>=AF11,AF12-AF11,0)*0.53 -> 0 | AH12: 526047 | AI12: =IF(AH12>=AH11,AH12-AH11,0)*0.53 -> 328.07 | AJ12: 636159 | AK12: =IF(AJ12>=AJ11,AJ12-AJ11,0)*0.53 -> 2531.81 | AL12: =AA12+AC12+AE12+AG12+AI12+AK12 -> 5998.01 | AM12: 7195056 | AN12: =IF(AM12>=AM11,AM12-AM11,0) -> 1170 | AO12: 567416 | AP12: =IF(AO12>=AO11,AO12-AO11,0) -> 235 | AQ12: 910601 | AR12: =IF(AQ12>=AQ11,AQ12-AQ11,0)*0.11 -> 14.63 | AS12: 793995 | AT12: =IF(AS12>=AS11,AS12-AS11,0) -> 39 | AU12: 2326230 | AV12: =IF(AU12>=AU11,AU12-AU11,0) -> 598 | AW12: 208092 | AX12: =IF(AW12>=AW11,AW12-AW11,0) -> 65 | AY12: 17588254 | AZ12: =IF(AY12>=AY11,AY12-AY11,0) -> 4097 | BA12: 21766960 | BB12: =IF(BA12>=BA11,BA12-BA11,0)-(0.6*BG12)-(0.5*BI12)-BK12-BE12 -> 4360.1 | BC12: =AN12+AP12+AR12+AT12+AV12+AX12+AZ12+BB12 -> 10578.73 | BD12: 1360795 | BE12: =IF(BD12>=BD11,BD12-BD11,0) -> 358 | BF12: 3470326 | BG12: =IF(BF12>=BF11,BF12-BF11,0) -> 874 | BH12: 370123 | BI12: =IF(BH12>=BH11,BH12-BH11,0) -> 89 | BJ12: 447454 | BK12: =IF(BJ12>=BJ11,BJ12-BJ11,0) -> 199 | BL12: =J12+Q12+AL12+BC12 -> 21499.74 | BM12: 62 | BN12: =IF(BL12>0,BL12/BM11,0) -> 429.9948 | BP12: =IF(BL12>0,BL12/BO12,0) -> #DIV/0! | BQ12: =BL12*BS1 -> 9889.8804 | BR12: =IF(BQ12>0,BQ12/BM11,0) -> 197.79761 | BS12: =IF(BQ12>0,BQ12/BO12,0) -> #DIV/0!
A13: 8 | C13: =IF(+B13-B12>0,B13-B12,(B13-B12)>0)*800 -> 0 | E13: =IF(+D13-D12>0,D13-D12,(D13-D12)>0)*80 -> 0 | G13: =IF(+F13-F12>0,F13-F12,(F13-F12)>0)*10 -> 0 | I13: 21949644 | J13: =IF(I13>=I12,I13-I12,0) -> 4426 | K13: =M13+O13 -> 2785 | L13: 973956 | M13: =IF(L13>=L12,L13-L12,0) -> 1269 | N13: 973710 | O13: =IF(N13>=N12,N13-N12,0) -> 1516 | P13: 214306 | Q13: =IF(P13>=P12,P13-P12,0)*30 -> 450 | R13: 702925 | S13: =IF(R13>=R12,R13-R12,0) -> 0 | T13: 344001 | U13: =IF(T13>=T12,T13-T12,0) -> 0 | V13: 127668 | W13: =IF(V13>=V12,V13-V12,0) -> 116 | X13: 232715 | Y13: =IF(X13>=X12,X13-X12,0) -> 225 | Z13: 315108 | AA13: =IF(Z13>=Z12,Z13-Z12,0)*0.53 -> 0 | AB13: 347386 | AC13: =IF(AB13>=AB12,AB13-AB12,0)*0.53 -> 0 | AD13: 551425 | AE13: =IF(AD13>=AD12,AD13-AD12,0)*0.53 -> 2217.52 | AF13: 289399 | AG13: =IF(AF13>=AF12,AF13-AF12,0)*0.53 -> 0 | AH13: 526605 | AI13: =IF(AH13>=AH12,AH13-AH12,0)*0.53 -> 295.74 | AJ13: 639781 | AK13: =IF(AJ13>=AJ12,AJ13-AJ12,0)*0.53 -> 1919.66 | AL13: =AA13+AC13+AE13+AG13+AI13+AK13 -> 4432.92 | AM13: 7195942 | AN13: =IF(AM13>=AM12,AM13-AM12,0) -> 886 | AO13: 567760 | AP13: =IF(AO13>=AO12,AO13-AO12,0) -> 344 | AQ13: 910734 | AR13: =IF(AQ13>=AQ12,AQ13-AQ12,0)*0.11 -> 14.63 | AS13: 794016 | AT13: =IF(AS13>=AS12,AS13-AS12,0) -> 21 | AU13: 2326682 | AV13: =IF(AU13>=AU12,AU13-AU12,0) -> 452 | AW13: 208145 | AX13: =IF(AW13>=AW12,AW13-AW12,0) -> 53 | AY13: 17591637 | AZ13: =IF(AY13>=AY12,AY13-AY12,0) -> 3383 | BA13: 21772321 | BB13: =IF(BA13>=BA12,BA13-BA12,0)-(0.6*BG13)-(0.5*BI13)-BK13-BE13 -> 4241.5 | BC13: =AN13+AP13+AR13+AT13+AV13+AX13+AZ13+BB13 -> 9395.13 | BD13: 1361153 | BE13: =IF(BD13>=BD12,BD13-BD12,0) -> 358 | BF13: 3471196 | BG13: =IF(BF13>=BF12,BF13-BF12,0) -> 870 | BH13: 370216 | BI13: =IF(BH13>=BH12,BH13-BH12,0) -> 93 | BJ13: 447647 | BK13: =IF(BJ13>=BJ12,BJ13-BJ12,0) -> 193 | BL13: =J13+Q13+AL13+BC13 -> 18704.05 | BM13: 61 | BN13: =IF(BL13>0,BL13/BM12,0) -> 301.67823 | BP13: =IF(BL13>0,BL13/BO13,0) -> #DIV/0! | BQ13: =BL13*BS1 -> 8603.863 | BR13: =IF(BQ13>0,BQ13/BM12,0) -> 138.77198 | BS13: =IF(BQ13>0,BQ13/BO13,0) -> #DIV/0!
A14: 9 | C14: =IF(+B14-B13>0,B14-B13,(B14-B13)>0)*800 -> 0 | E14: =IF(+D14-D13>0,D14-D13,(D14-D13)>0)*80 -> 0 | G14: =IF(+F14-F13>0,F14-F13,(F14-F13)>0)*10 -> 0 | H14: 60 | I14: 21953718 | J14: =IF(I14>=I13,I14-I13,0) -> 4074 | K14: =M14+O14 -> 2602 | L14: 975164 | M14: =IF(L14>=L13,L14-L13,0) -> 1208 | N14: 975104 | O14: =IF(N14>=N13,N14-N13,0) -> 1394 | P14: 214323 | Q14: =IF(P14>=P13,P14-P13,0)*30 -> 510 | R14: 702925 | S14: =IF(R14>=R13,R14-R13,0) -> 0 | T14: 344001 | U14: =IF(T14>=T13,T14-T13,0) -> 0 | V14: 127820 | W14: =IF(V14>=V13,V14-V13,0) -> 152 | X14: 232978 | Y14: =IF(X14>=X13,X14-X13,0) -> 263 | Z14: 315108 | AA14: =IF(Z14>=Z13,Z14-Z13,0)*0.53 -> 0 | AB14: 347386 | AC14: =IF(AB14>=AB13,AB14-AB13,0)*0.53 -> 0 | AD14: 551425 | AE14: =IF(AD14>=AD13,AD14-AD13,0)*0.53 -> 0 | AF14: 292257 | AG14: =IF(AF14>=AF13,AF14-AF13,0)*0.53 -> 1514.74 | AH14: 526901 | AI14: =IF(AH14>=AH13,AH14-AH13,0)*0.53 -> 156.88 | AJ14: 642881 | AK14: =IF(AJ14>=AJ13,AJ14-AJ13,0)*0.53 -> 1643 | AL14: =AA14+AC14+AE14+AG14+AI14+AK14 -> 3314.62 | AM14: 7197081 | AN14: =IF(AM14>=AM13,AM14-AM13,0) -> 1139 | AO14: 568049 | AP14: =IF(AO14>=AO13,AO14-AO13,0) -> 289 | AQ14: 910857 | AR14: =IF(AQ14>=AQ13,AQ14-AQ13,0)*0.11 -> 13.53 | AS14: 794037 | AT14: =IF(AS14>=AS13,AS14-AS13,0) -> 21 | AU14: 2327106 | AV14: =IF(AU14>=AU13,AU14-AU13,0) -> 424 | AW14: 208215 | AX14: =IF(AW14>=AW13,AW14-AW13,0) -> 70 | AY14: 17595435 | AZ14: =IF(AY14>=AY13,AY14-AY13,0) -> 3798 | BA14: 21777172 | BB14: =IF(BA14>=BA13,BA14-BA13,0)-(0.6*BG14)-(0.5*BI14)-BK14-BE14 -> 3776.6 | BC14: =AN14+AP14+AR14+AT14+AV14+AX14+AZ14+BB14 -> 9531.13 | BD14: 1361511 | BE14: =IF(BD14>=BD13,BD14-BD13,0) -> 358 | BF14: 3472005 | BG14: =IF(BF14>=BF13,BF14-BF13,0) -> 809 | BH14: 370326 | BI14: =IF(BH14>=BH13,BH14-BH13,0) -> 110 | BJ14: 447823 | BK14: =IF(BJ14>=BJ13,BJ14-BJ13,0) -> 176 | BL14: =J14+Q14+AL14+BC14 -> 17429.75 | BM14: 59 | BN14: =IF(BL14>0,BL14/BM13,0) -> 285.73361 | BP14: =IF(BL14>0,BL14/BO14,0) -> #DIV/0! | BQ14: =BL14*BS1 -> 8017.685 | BR14: =IF(BQ14>0,BQ14/BM13,0) -> 131.43746 | BS14: =IF(BQ14>0,BQ14/BO14,0) -> #DIV/0!
A15: 10 | C15: =IF(+B15-B14>0,B15-B14,(B15-B14)>0)*800 -> 0 | E15: =IF(+D15-D14>0,D15-D14,(D15-D14)>0)*80 -> 0 | G15: =IF(+F15-F14>0,F15-F14,(F15-F14)>0)*10 -> 0 | I15: 21959270 | J15: =IF(I15>=I14,I15-I14,0) -> 5552 | K15: =M15+O15 -> 2812 | L15: 976482 | M15: =IF(L15>=L14,L15-L14,0) -> 1318 | N15: 976598 | O15: =IF(N15>=N14,N15-N14,0) -> 1494 | P15: 214341 | Q15: =IF(P15>=P14,P15-P14,0)*30 -> 540 | R15: 702925 | S15: =IF(R15>=R14,R15-R14,0) -> 0 | T15: 344001 | U15: =IF(T15>=T14,T15-T14,0) -> 0 | V15: 127955 | W15: =IF(V15>=V14,V15-V14,0) -> 135 | X15: 233214 | Y15: =IF(X15>=X14,X15-X14,0) -> 236 | Z15: 315108 | AA15: =IF(Z15>=Z14,Z15-Z14,0)*0.53 -> 0 | AB15: 347386 | AC15: =IF(AB15>=AB14,AB15-AB14,0)*0.53 -> 0 | AD15: 551425 | AE15: =IF(AD15>=AD14,AD15-AD14,0)*0.53 -> 0 | AF15: 296448 | AG15: =IF(AF15>=AF14,AF15-AF14,0)*0.53 -> 2221.23 | AH15: 527297 | AI15: =IF(AH15>=AH14,AH15-AH14,0)*0.53 -> 209.88 | AJ15: 646634 | AK15: =IF(AJ15>=AJ14,AJ15-AJ14,0)*0.53 -> 1989.09 | AL15: =AA15+AC15+AE15+AG15+AI15+AK15 -> 4420.2 | AM15: 7198148 | AN15: =IF(AM15>=AM14,AM15-AM14,0) -> 1067 | AO15: 568324 | AP15: =IF(AO15>=AO14,AO15-AO14,0) -> 275 | AQ15: 910995 | AR15: =IF(AQ15>=AQ14,AQ15-AQ14,0)*0.11 -> 15.18 | AS15: 794075 | AT15: =IF(AS15>=AS14,AS15-AS14,0) -> 38 | AU15: 2327553 | AV15: =IF(AU15>=AU14,AU15-AU14,0) -> 447 | AW15: 208277 | AX15: =IF(AW15>=AW14,AW15-AW14,0) -> 62 | AY15: 17598290 | AZ15: =IF(AY15>=AY14,AY15-AY14,0) -> 2855 | BA15: 21783420 | BB15: =IF(BA15>=BA14,BA15-BA14,0)-(0.6*BG15)-(0.5*BI15)-BK15-BE15 -> 4956 | BC15: =AN15+AP15+AR15+AT15+AV15+AX15+AZ15+BB15 -> 9715.18 | BD15: 1361869 | BE15: =IF(BD15>=BD14,BD15-BD14,0) -> 358 | BF15: 3473070 | BG15: =IF(BF15>=BF14,BF15-BF14,0) -> 1065 | BH15: 370464 | BI15: =IF(BH15>=BH14,BH15-BH14,0) -> 138 | BJ15: 448049 | BK15: =IF(BJ15>=BJ14,BJ15-BJ14,0) -> 226 | BL15: =J15+Q15+AL15+BC15 -> 20227.38 | BM15: 82 | BN15: =IF(BL15>0,BL15/BM14,0) -> 342.83695 | BP15: =IF(BL15>0,BL15/BO15,0) -> #DIV/0! | BQ15: =BL15*BS1 -> 9304.5948 | BR15: =IF(BQ15>0,BQ15/BM14,0) -> 157.705 | BS15: =IF(BQ15>0,BQ15/BO15,0) -> #DIV/0!
A16: 11 | C16: =IF(+B16-B15>0,B16-B15,(B16-B15)>0)*800 -> 0 | E16: =IF(+D16-D15>0,D16-D15,(D16-D15)>0)*80 -> 0 | G16: =IF(+F16-F15>0,F16-F15,(F16-F15)>0)*10 -> 0 | H16: 61 | I16: 21962260 | J16: =IF(I16>=I15,I16-I15,0) -> 2990 | K16: =M16+O16 -> 2698 | L16: 977727 | M16: =IF(L16>=L15,L16-L15,0) -> 1245 | N16: 978051 | O16: =IF(N16>=N15,N16-N15,0) -> 1453 | P16: 214359 | Q16: =IF(P16>=P15,P16-P15,0)*30 -> 540 | R16: 702925 | S16: =IF(R16>=R15,R16-R15,0) -> 0 | T16: 344001 | U16: =IF(T16>=T15,T16-T15,0) -> 0 | V16: 128090 | W16: =IF(V16>=V15,V16-V15,0) -> 135 | X16: 233448 | Y16: =IF(X16>=X15,X16-X15,0) -> 234 | Z16: 315108 | AA16: =IF(Z16>=Z15,Z16-Z15,0)*0.53 -> 0 | AB16: 347386 | AC16: =IF(AB16>=AB15,AB16-AB15,0)*0.53 -> 0 | AD16: 551425 | AE16: =IF(AD16>=AD15,AD16-AD15,0)*0.53 -> 0 | AF16: 300254 | AG16: =IF(AF16>=AF15,AF16-AF15,0)*0.53 -> 2017.18 | AH16: 527623 | AI16: =IF(AH16>=AH15,AH16-AH15,0)*0.53 -> 172.78 | AJ16: 650137 | AK16: =IF(AJ16>=AJ15,AJ16-AJ15,0)*0.53 -> 1856.59 | AL16: =AA16+AC16+AE16+AG16+AI16+AK16 -> 4046.55 | AM16: 7199211 | AN16: =IF(AM16>=AM15,AM16-AM15,0) -> 1063 | AO16: 568599 | AP16: =IF(AO16>=AO15,AO16-AO15,0) -> 275 | AQ16: 911094 | AR16: =IF(AQ16>=AQ15,AQ16-AQ15,0)*0.11 -> 10.89 | AS16: 794113 | AT16: =IF(AS16>=AS15,AS16-AS15,0) -> 38 | AU16: 2328025 | AV16: =IF(AU16>=AU15,AU16-AU15,0) -> 472 | AW16: 208312 | AX16: =IF(AW16>=AW15,AW16-AW15,0) -> 35 | AY16: 17601657 | AZ16: =IF(AY16>=AY15,AY16-AY15,0) -> 3367 | BA16: 21787608 | BB16: =IF(BA16>=BA15,BA16-BA15,0)-(0.6*BG16)-(0.5*BI16)-BK16-BE16 -> 3231.7 | BC16: =AN16+AP16+AR16+AT16+AV16+AX16+AZ16+BB16 -> 8492.59 | BD16: 1362227 | BE16: =IF(BD16>=BD15,BD16-BD15,0) -> 358 | BF16: 3473748 | BG16: =IF(BF16>=BF15,BF16-BF15,0) -> 678 | BH16: 370551 | BI16: =IF(BH16>=BH15,BH16-BH15,0) -> 87 | BJ16: 448197 | BK16: =IF(BJ16>=BJ15,BJ16-BJ15,0) -> 148 | BL16: =J16+Q16+AL16+BC16 -> 16069.14 | BM16: 35 | BN16: =IF(BL16>0,BL16/BM15,0) -> 195.96512 | BP16: =IF(BL16>0,BL16/BO16,0) -> #DIV/0! | BQ16: =BL16*BS1 -> 7391.8044 | BR16: =IF(BQ16>0,BQ16/BM15,0) -> 90.143956 | BS16: =IF(BQ16>0,BQ16/BO16,0) -> #DIV/0!
A17: 12 | C17: =IF(+B17-B16>0,B17-B16,(B17-B16)>0)*800 -> 0 | E17: =IF(+D17-D16>0,D17-D16,(D17-D16)>0)*80 -> 0 | G17: =IF(+F17-F16>0,F17-F16,(F17-F16)>0)*10 -> 0 | I17: 21966697 | J17: =IF(I17>=I16,I17-I16,0) -> 4437 | K17: =M17+O17 -> 2787 | L17: 978936 | M17: =IF(L17>=L16,L17-L16,0) -> 1209 | N17: 979629 | O17: =IF(N17>=N16,N17-N16,0) -> 1578 | P17: 214379 | Q17: =IF(P17>=P16,P17-P16,0)*30 -> 600 | R17: 702925 | S17: =IF(R17>=R16,R17-R16,0) -> 0 | T17: 344001 | U17: =IF(T17>=T16,T17-T16,0) -> 0 | V17: 128242 | W17: =IF(V17>=V16,V17-V16,0) -> 152 | X17: 233711 | Y17: =IF(X17>=X16,X17-X16,0) -> 263 | Z17: 315108 | AA17: =IF(Z17>=Z16,Z17-Z16,0)*0.53 -> 0 | AB17: 347386 | AC17: =IF(AB17>=AB16,AB17-AB16,0)*0.53 -> 0 | AD17: 551425 | AE17: =IF(AD17>=AD16,AD17-AD16,0)*0.53 -> 0 | AF17: 304475 | AG17: =IF(AF17>=AF16,AF17-AF16,0)*0.53 -> 2237.13 | AH17: 528017 | AI17: =IF(AH17>=AH16,AH17-AH16,0)*0.53 -> 208.82 | AJ17: 654069 | AK17: =IF(AJ17>=AJ16,AJ17-AJ16,0)*0.53 -> 2083.96 | AL17: =AA17+AC17+AE17+AG17+AI17+AK17 -> 4529.91 | AM17: 7200243 | AN17: =IF(AM17>=AM16,AM17-AM16,0) -> 1032 | AO17: 568896 | AP17: =IF(AO17>=AO16,AO17-AO16,0) -> 297 | AQ17: 911229 | AR17: =IF(AQ17>=AQ16,AQ17-AQ16,0)*0.11 -> 14.85 | AS17: 794157 | AT17: =IF(AS17>=AS16,AS17-AS16,0) -> 44 | AU17: 2328530 | AV17: =IF(AU17>=AU16,AU17-AU16,0) -> 505 | AW17: 208329 | AX17: =IF(AW17>=AW16,AW17-AW16,0) -> 17 | AY17: 17605451 | AZ17: =IF(AY17>=AY16,AY17-AY16,0) -> 3794 | BA17: 21793543 | BB17: =IF(BA17>=BA16,BA17-BA16,0)-(0.6*BG17)-(0.5*BI17)-BK17-BE17 -> 4736.4 | BC17: =AN17+AP17+AR17+AT17+AV17+AX17+AZ17+BB17 -> 10440.25 | BD17: 1362585 | BE17: =IF(BD17>=BD16,BD17-BD16,0) -> 358 | BF17: 3474704 | BG17: =IF(BF17>=BF16,BF17-BF16,0) -> 956 | BH17: 370663 | BI17: =IF(BH17>=BH16,BH17-BH16,0) -> 112 | BJ17: 448408 | BK17: =IF(BJ17>=BJ16,BJ17-BJ16,0) -> 211 | BL17: =J17+Q17+AL17+BC17 -> 20007.16 | BM17: 36 | BN17: =IF(BL17>0,BL17/BM16,0) -> 571.63314 | BP17: =IF(BL17>0,BL17/BO17,0) -> #DIV/0! | BQ17: =BL17*BS1 -> 9203.2936 | BR17: =IF(BQ17>0,BQ17/BM16,0) -> 262.95125 | BS17: =IF(BQ17>0,BQ17/BO17,0) -> #DIV/0!
A18: 13 | C18: =IF(+B18-B17>0,B18-B17,(B18-B17)>0)*800 -> 0 | E18: =IF(+D18-D17>0,D18-D17,(D18-D17)>0)*80 -> 0 | G18: =IF(+F18-F17>0,F18-F17,(F18-F17)>0)*10 -> 0 | H18: 62 | I18: 21970423 | J18: =IF(I18>=I17,I18-I17,0) -> 3726 | K18: =M18+O18 -> 2485 | L18: 979952 | M18: =IF(L18>=L17,L18-L17,0) -> 1016 | N18: 981098 | O18: =IF(N18>=N17,N18-N17,0) -> 1469 | P18: 214395 | Q18: =IF(P18>=P17,P18-P17,0)*30 -> 480 | R18: 702925 | S18: =IF(R18>=R17,R18-R17,0) -> 0 | T18: 344001 | U18: =IF(T18>=T17,T18-T17,0) -> 0 | V18: 128360 | W18: =IF(V18>=V17,V18-V17,0) -> 118 | X18: 233922 | Y18: =IF(X18>=X17,X18-X17,0) -> 211 | Z18: 315108 | AA18: =IF(Z18>=Z17,Z18-Z17,0)*0.53 -> 0 | AB18: 350098 | AC18: =IF(AB18>=AB17,AB18-AB17,0)*0.53 -> 1437.36 | AD18: 551425 | AE18: =IF(AD18>=AD17,AD18-AD17,0)*0.53 -> 0 | AF18: 305142 | AG18: =IF(AF18>=AF17,AF18-AF17,0)*0.53 -> 353.51 | AH18: 528303 | AI18: =IF(AH18>=AH17,AH18-AH17,0)*0.53 -> 151.58 | AJ18: 657194 | AK18: =IF(AJ18>=AJ17,AJ18-AJ17,0)*0.53 -> 1656.25 | AL18: =AA18+AC18+AE18+AG18+AI18+AK18 -> 3598.7 | AM18: 7201393 | AN18: =IF(AM18>=AM17,AM18-AM17,0) -> 1150 | AO18: 569164 | AP18: =IF(AO18>=AO17,AO18-AO17,0) -> 268 | AQ18: 911345 | AR18: =IF(AQ18>=AQ17,AQ18-AQ17,0)*0.11 -> 12.76 | AS18: 794192 | AT18: =IF(AS18>=AS17,AS18-AS17,0) -> 35 | AU18: 2328958 | AV18: =IF(AU18>=AU17,AU18-AU17,0) -> 428 | AW18: 208364 | AX18: =IF(AW18>=AW17,AW18-AW17,0) -> 35 | AY18: 17608533 | AZ18: =IF(AY18>=AY17,AY18-AY17,0) -> 3082 | BA18: 21798393 | BB18: =IF(BA18>=BA17,BA18-BA17,0)-(0.6*BG18)-(0.5*BI18)-BK18-BE18 -> 3811.4 | BC18: =AN18+AP18+AR18+AT18+AV18+AX18+AZ18+BB18 -> 8822.16 | BD18: 1362943 | BE18: =IF(BD18>=BD17,BD18-BD17,0) -> 358 | BF18: 3475480 | BG18: =IF(BF18>=BF17,BF18-BF17,0) -> 776 | BH18: 370747 | BI18: =IF(BH18>=BH17,BH18-BH17,0) -> 84 | BJ18: 448581 | BK18: =IF(BJ18>=BJ17,BJ18-BJ17,0) -> 173 | BL18: =J18+Q18+AL18+BC18 -> 16626.86 | BM18: 30 | BN18: =IF(BL18>0,BL18/BM17,0) -> 461.85722 | BP18: =IF(BL18>0,BL18/BO18,0) -> #DIV/0! | BQ18: =BL18*BS1 -> 7648.3556 | BR18: =IF(BQ18>0,BQ18/BM17,0) -> 212.45432 | BS18: =IF(BQ18>0,BQ18/BO18,0) -> #DIV/0!
A19: 14 | C19: =IF(+B19-B18>0,B19-B18,(B19-B18)>0)*800 -> 0 | E19: =IF(+D19-D18>0,D19-D18,(D19-D18)>0)*80 -> 0 | G19: =IF(+F19-F18>0,F19-F18,(F19-F18)>0)*10 -> 0 | I19: 21975104 | J19: =IF(I19>=I18,I19-I18,0) -> 4681 | K19: =M19+O19 -> 3188 | L19: 981379 | M19: =IF(L19>=L18,L19-L18,0) -> 1427 | N19: 982859 | O19: =IF(N19>=N18,N19-N18,0) -> 1761 | P19: 214418 | Q19: =IF(P19>=P18,P19-P18,0)*30 -> 690 | R19: 702925 | S19: =IF(R19>=R18,R19-R18,0) -> 0 | T19: 344001 | U19: =IF(T19>=T18,T19-T18,0) -> 0 | V19: 128526 | W19: =IF(V19>=V18,V19-V18,0) -> 166 | X19: 234186 | Y19: =IF(X19>=X18,X19-X18,0) -> 264 | Z19: 315108 | AA19: =IF(Z19>=Z18,Z19-Z18,0)*0.53 -> 0 | AB19: 354509 | AC19: =IF(AB19>=AB18,AB19-AB18,0)*0.53 -> 2337.83 | AD19: 551425 | AE19: =IF(AD19>=AD18,AD19-AD18,0)*0.53 -> 0 | AF19: 305142 | AG19: =IF(AF19>=AF18,AF19-AF18,0)*0.53 -> 0 | AH19: 528712 | AI19: =IF(AH19>=AH18,AH19-AH18,0)*0.53 -> 216.77 | AJ19: 661265 | AK19: =IF(AJ19>=AJ18,AJ19-AJ18,0)*0.53 -> 2157.63 | AL19: =AA19+AC19+AE19+AG19+AI19+AK19 -> 4712.23 | AM19: 7202497 | AN19: =IF(AM19>=AM18,AM19-AM18,0) -> 1104 | AO19: 569474 | AP19: =IF(AO19>=AO18,AO19-AO18,0) -> 310 | AQ19: 911484 | AR19: =IF(AQ19>=AQ18,AQ19-AQ18,0)*0.11 -> 15.29 | AS19: 794231 | AT19: =IF(AS19>=AS18,AS19-AS18,0) -> 39 | AU19: 2329504 | AV19: =IF(AU19>=AU18,AU19-AU18,0) -> 546 | AW19: 208436 | AX19: =IF(AW19>=AW18,AW19-AW18,0) -> 72 | AY19: 17612253 | AZ19: =IF(AY19>=AY18,AY19-AY18,0) -> 3720 | BA19: 21804470 | BB19: =IF(BA19>=BA18,BA19-BA18,0)-(0.6*BG19)-(0.5*BI19)-BK19-BE19 -> 4856.9 | BC19: =AN19+AP19+AR19+AT19+AV19+AX19+AZ19+BB19 -> 10663.19 | BD19: 1363301 | BE19: =IF(BD19>=BD18,BD19-BD18,0) -> 358 | BF19: 3476466 | BG19: =IF(BF19>=BF18,BF19-BF18,0) -> 986 | BH19: 370854 | BI19: =IF(BH19>=BH18,BH19-BH18,0) -> 107 | BJ19: 448798 | BK19: =IF(BJ19>=BJ18,BJ19-BJ18,0) -> 217 | BL19: =J19+Q19+AL19+BC19 -> 20746.42 | BM19: 43 | BN19: =IF(BL19>0,BL19/BM18,0) -> 691.54733 | BP19: =IF(BL19>0,BL19/BO19,0) -> #DIV/0! | BQ19: =BL19*BS1 -> 9543.3532 | BR19: =IF(BQ19>0,BQ19/BM18,0) -> 318.11177 | BS19: =IF(BQ19>0,BQ19/BO19,0) -> #DIV/0!
A20: 15 | C20: =IF(+B20-B19>0,B20-B19,(B20-B19)>0)*800 -> 0 | E20: =IF(+D20-D19>0,D20-D19,(D20-D19)>0)*80 -> 0 | G20: =IF(+F20-F19>0,F20-F19,(F20-F19)>0)*10 -> 0 | H20: 63 | I20: 21979629 | J20: =IF(I20>=I19,I20-I19,0) -> 4525 | K20: =M20+O20 -> 3046 | L20: 982844 | M20: =IF(L20>=L19,L20-L19,0) -> 1465 | N20: 984440 | O20: =IF(N20>=N19,N20-N19,0) -> 1581 | P20: 214437 | Q20: =IF(P20>=P19,P20-P19,0)*30 -> 570 | R20: 702925 | S20: =IF(R20>=R19,R20-R19,0) -> 0 | T20: 344001 | U20: =IF(T20>=T19,T20-T19,0) -> 0 | V20: 128674 | W20: =IF(V20>=V19,V20-V19,0) -> 148 | X20: 234434 | Y20: =IF(X20>=X19,X20-X19,0) -> 248 | Z20: 315108 | AA20: =IF(Z20>=Z19,Z20-Z19,0)*0.53 -> 0 | AB20: 356869 | AC20: =IF(AB20>=AB19,AB20-AB19,0)*0.53 -> 1250.8 | AD20: 551425 | AE20: =IF(AD20>=AD19,AD20-AD19,0)*0.53 -> 0 | AF20: 305142 | AG20: =IF(AF20>=AF19,AF20-AF19,0)*0.53 -> 0 | AH20: 528982 | AI20: =IF(AH20>=AH19,AH20-AH19,0)*0.53 -> 143.1 | AJ20: 664411 | AK20: =IF(AJ20>=AJ19,AJ20-AJ19,0)*0.53 -> 1667.38 | AL20: =AA20+AC20+AE20+AG20+AI20+AK20 -> 3061.28 | AM20: 7202833 | AN20: =IF(AM20>=AM19,AM20-AM19,0) -> 336 | AO20: 569752 | AP20: =IF(AO20>=AO19,AO20-AO19,0) -> 278 | AQ20: 911614 | AR20: =IF(AQ20>=AQ19,AQ20-AQ19,0)*0.11 -> 14.3 | AS20: 794256 | AT20: =IF(AS20>=AS19,AS20-AS19,0) -> 25 | AU20: 2330024 | AV20: =IF(AU20>=AU19,AU20-AU19,0) -> 520 | AW20: 208501 | AX20: =IF(AW20>=AW19,AW20-AW19,0) -> 65 | AY20: 17615799 | AZ20: =IF(AY20>=AY19,AY20-AY19,0) -> 3546 | BA20: 21810061 | BB20: =IF(BA20>=BA19,BA20-BA19,0)-(0.6*BG20)-(0.5*BI20)-BK20-BE20 -> 4455.4 | BC20: =AN20+AP20+AR20+AT20+AV20+AX20+AZ20+BB20 -> 9239.7 | BD20: 1363659 | BE20: =IF(BD20>=BD19,BD20-BD19,0) -> 358 | BF20: 3477342 | BG20: =IF(BF20>=BF19,BF20-BF19,0) -> 876 | BH20: 370954 | BI20: =IF(BH20>=BH19,BH20-BH19,0) -> 100 | BJ20: 449000 | BK20: =IF(BJ20>=BJ19,BJ20-BJ19,0) -> 202 | BL20: =J20+Q20+AL20+BC20 -> 17395.98 | BM20: 65 | BN20: =IF(BL20>0,BL20/BM20,0) -> 267.63046 | BP20: =IF(BL20>0,BL20/BO20,0) -> #DIV/0! | BQ20: =BL20*BS1 -> 8002.1508 | BR20: =IF(BQ20>0,BQ20/BM20,0) -> 123.11001 | BS20: =IF(BQ20>0,BQ20/BO20,0) -> #DIV/0!
A21: 16 | C21: =IF(+B21-B20>0,B21-B20,(B21-B20)>0)*800 -> 0 | E21: =IF(+D21-D20>0,D21-D20,(D21-D20)>0)*80 -> 0 | G21: =IF(+F21-F20>0,F21-F20,(F21-F20)>0)*10 -> 0 | I21: 21983843 | J21: =IF(I21>=I20,I21-I20,0) -> 4214 | K21: =M21+O21 -> 2757 | L21: 984104 | M21: =IF(L21>=L20,L21-L20,0) -> 1260 | N21: 985937 | O21: =IF(N21>=N20,N21-N20,0) -> 1497 | P21: 214454 | Q21: =IF(P21>=P20,P21-P20,0)*30 -> 510 | R21: 702925 | S21: =IF(R21>=R20,R21-R20,0) -> 0 | T21: 344001 | U21: =IF(T21>=T20,T21-T20,0) -> 0 | V21: 128808 | W21: =IF(V21>=V20,V21-V20,0) -> 134 | X21: 234655 | Y21: =IF(X21>=X20,X21-X20,0) -> 221 | Z21: 315108 | AA21: =IF(Z21>=Z20,Z21-Z20,0)*0.53 -> 0 | AB21: 359277 | AC21: =IF(AB21>=AB20,AB21-AB20,0)*0.53 -> 1276.24 | AD21: 551425 | AE21: =IF(AD21>=AD20,AD21-AD20,0)*0.53 -> 0 | AF21: 305142 | AG21: =IF(AF21>=AF20,AF21-AF20,0)*0.53 -> 0 | AH21: 529245 | AI21: =IF(AH21>=AH20,AH21-AH20,0)*0.53 -> 139.39 | AJ21: 667461 | AK21: =IF(AJ21>=AJ20,AJ21-AJ20,0)*0.53 -> 1616.5 | AL21: =AA21+AC21+AE21+AG21+AI21+AK21 -> 3032.13 | AM21: 7203772 | AN21: =IF(AM21>=AM20,AM21-AM20,0) -> 939 | AO21: 570017 | AP21: =IF(AO21>=AO20,AO21-AO20,0) -> 265 | AQ21: 911732 | AR21: =IF(AQ21>=AQ20,AQ21-AQ20,0)*0.11 -> 12.98 | AS21: 794279 | AT21: =IF(AS21>=AS20,AS21-AS20,0) -> 23 | AU21: 2330469 | AV21: =IF(AU21>=AU20,AU21-AU20,0) -> 445 | AW21: 208560 | AX21: =IF(AW21>=AW20,AW21-AW20,0) -> 59 | AY21: 17619002 | AZ21: =IF(AY21>=AY20,AY21-AY20,0) -> 3203 | BA21: 21815170 | BB21: =IF(BA21>=BA20,BA21-BA20,0)-(0.6*BG21)-(0.5*BI21)-BK21-BE21 -> 4043 | BC21: =AN21+AP21+AR21+AT21+AV21+AX21+AZ21+BB21 -> 8989.98 | BD21: 1364017 | BE21: =IF(BD21>=BD20,BD21-BD20,0) -> 358 | BF21: 3478132 | BG21: =IF(BF21>=BF20,BF21-BF20,0) -> 790 | BH21: 371050 | BI21: =IF(BH21>=BH20,BH21-BH20,0) -> 96 | BJ21: 449186 | BK21: =IF(BJ21>=BJ20,BJ21-BJ20,0) -> 186 | BL21: =J21+Q21+AL21+BC21 -> 16746.11 | BM21: 55 | BN21: =IF(BL21>0,BL21/BM21,0) -> 304.47473 | BP21: =IF(BL21>0,BL21/BO21,0) -> #DIV/0! | BQ21: =BL21*BS1 -> 7703.2106 | BR21: =IF(BQ21>0,BQ21/BM21,0) -> 140.05837 | BS21: =IF(BQ21>0,BQ21/BO21,0) -> #DIV/0!
A22: 17 | C22: =IF(+B22-B21>0,B22-B21,(B22-B21)>0)*800 -> 0 | E22: =IF(+D22-D21>0,D22-D21,(D22-D21)>0)*80 -> 0 | G22: =IF(+F22-F21>0,F22-F21,(F22-F21)>0)*10 -> 0 | H22: 64 | I22: 21988928 | J22: =IF(I22>=I21,I22-I21,0) -> 5085 | K22: =M22+O22 -> 3396 | L22: 985714 | M22: =IF(L22>=L21,L22-L21,0) -> 1610 | N22: 987723 | O22: =IF(N22>=N21,N22-N21,0) -> 1786 | P22: 214475 | Q22: =IF(P22>=P21,P22-P21,0)*30 -> 630 | R22: 702925 | S22: =IF(R22>=R21,R22-R21,0) -> 0 | T22: 344001 | U22: =IF(T22>=T21,T22-T21,0) -> 0 | V22: 128964 | W22: =IF(V22>=V21,V22-V21,0) -> 156 | X22: 234914 | Y22: =IF(X22>=X21,X22-X21,0) -> 259 | Z22: 315108 | AA22: =IF(Z22>=Z21,Z22-Z21,0)*0.53 -> 0 | AB22: 363229 | AC22: =IF(AB22>=AB21,AB22-AB21,0)*0.53 -> 2094.56 | AD22: 551425 | AE22: =IF(AD22>=AD21,AD22-AD21,0)*0.53 -> 0 | AF22: 305142 | AG22: =IF(AF22>=AF21,AF22-AF21,0)*0.53 -> 0 | AH22: 529582 | AI22: =IF(AH22>=AH21,AH22-AH21,0)*0.53 -> 178.61 | AJ22: 671689 | AK22: =IF(AJ22>=AJ21,AJ22-AJ21,0)*0.53 -> 2240.84 | AL22: =AA22+AC22+AE22+AG22+AI22+AK22 -> 4514.01 | AM22: 7204464 | AN22: =IF(AM22>=AM21,AM22-AM21,0) -> 692 | AO22: 570312 | AP22: =IF(AO22>=AO21,AO22-AO21,0) -> 295 | AQ22: 911855 | AR22: =IF(AQ22>=AQ21,AQ22-AQ21,0)*0.11 -> 13.53 | AS22: 794314 | AT22: =IF(AS22>=AS21,AS22-AS21,0) -> 35 | AU22: 2330996 | AV22: =IF(AU22>=AU21,AU22-AU21,0) -> 527 | AW22: 208621 | AX22: =IF(AW22>=AW21,AW22-AW21,0) -> 61 | AY22: 17622714 | AZ22: =IF(AY22>=AY21,AY22-AY21,0) -> 3712 | BA22: 21821007 | BB22: =IF(BA22>=BA21,BA22-BA21,0)-(0.6*BG22)-(0.5*BI22)-BK22-BE22 -> 4627.1 | BC22: =AN22+AP22+AR22+AT22+AV22+AX22+AZ22+BB22 -> 9962.63 | BD22: 1364375 | BE22: =IF(BD22>=BD21,BD22-BD21,0) -> 358 | BF22: 3479091 | BG22: =IF(BF22>=BF21,BF22-BF21,0) -> 959 | BH22: 371179 | BI22: =IF(BH22>=BH21,BH22-BH21,0) -> 129 | BJ22: 449398 | BK22: =IF(BJ22>=BJ21,BJ22-BJ21,0) -> 212 | BL22: =J22+Q22+AL22+BC22 -> 20191.64 | BM22: 60 | BN22: =IF(BL22>0,BL22/BM22,0) -> 336.52733 | BP22: =IF(BL22>0,BL22/BO22,0) -> #DIV/0! | BQ22: =BL22*BS1 -> 9288.1544 | BR22: =IF(BQ22>0,BQ22/BM22,0) -> 154.80257 | BS22: =IF(BQ22>0,BQ22/BO22,0) -> #DIV/0!
A23: 18 | C23: =IF(+B23-B22>0,B23-B22,(B23-B22)>0)*800 -> 0 | E23: =IF(+D23-D22>0,D23-D22,(D23-D22)>0)*80 -> 0 | G23: =IF(+F23-F22>0,F23-F22,(F23-F22)>0)*10 -> 0 | I23: 21993782 | J23: =IF(I23>=I22,I23-I22,0) -> 4854 | K23: =M23+O23 -> 3066 | L23: 987190 | M23: =IF(L23>=L22,L23-L22,0) -> 1476 | N23: 989313 | O23: =IF(N23>=N22,N23-N22,0) -> 1590 | P23: 214498 | Q23: =IF(P23>=P22,P23-P22,0)*30 -> 690 | R23: 702925 | S23: =IF(R23>=R22,R23-R22,0) -> 0 | T23: 344001 | U23: =IF(T23>=T22,T23-T22,0) -> 0 | V23: 129105 | W23: =IF(V23>=V22,V23-V22,0) -> 141 | X23: 235146 | Y23: =IF(X23>=X22,X23-X22,0) -> 232 | Z23: 315108 | AA23: =IF(Z23>=Z22,Z23-Z22,0)*0.53 -> 0 | AB23: 363773 | AC23: =IF(AB23>=AB22,AB23-AB22,0)*0.53 -> 288.32 | AD23: 551425 | AE23: =IF(AD23>=AD22,AD23-AD22,0)*0.53 -> 0 | AF23: 306455 | AG23: =IF(AF23>=AF22,AF23-AF22,0)*0.53 -> 695.89 | AH23: 529856 | AI23: =IF(AH23>=AH22,AH23-AH22,0)*0.53 -> 145.22 | AJ23: 674580 | AK23: =IF(AJ23>=AJ22,AJ23-AJ22,0)*0.53 -> 1532.23 | AL23: =AA23+AC23+AE23+AG23+AI23+AK23 -> 2661.66 | AM23: 7205134 | AN23: =IF(AM23>=AM22,AM23-AM22,0) -> 670 | AO23: 570600 | AP23: =IF(AO23>=AO22,AO23-AO22,0) -> 288 | AQ23: 911975 | AR23: =IF(AQ23>=AQ22,AQ23-AQ22,0)*0.11 -> 13.2 | AS23: 794349 | AT23: =IF(AS23>=AS22,AS23-AS22,0) -> 35 | AU23: 2331488 | AV23: =IF(AU23>=AU22,AU23-AU22,0) -> 492 | AW23: 208683 | AX23: =IF(AW23>=AW22,AW23-AW22,0) -> 62 | AY23: 17626217 | AZ23: =IF(AY23>=AY22,AY23-AY22,0) -> 3503 | BA23: 21826285 | BB23: =IF(BA23>=BA22,BA23-BA22,0)-(0.6*BG23)-(0.5*BI23)-BK23-BE23 -> 4143.2 | BC23: =AN23+AP23+AR23+AT23+AV23+AX23+AZ23+BB23 -> 9206.4 | BD23: 1364733 | BE23: =IF(BD23>=BD22,BD23-BD22,0) -> 358 | BF23: 3479969 | BG23: =IF(BF23>=BF22,BF23-BF22,0) -> 878 | BH23: 371285 | BI23: =IF(BH23>=BH22,BH23-BH22,0) -> 106 | BJ23: 449595 | BK23: =IF(BJ23>=BJ22,BJ23-BJ22,0) -> 197 | BL23: =J23+Q23+AL23+BC23 -> 17412.06 | BM23: 44 | BN23: =IF(BL23>0,BL23/BM23,0) -> 395.72864 | BP23: =IF(BL23>0,BL23/BO23,0) -> #DIV/0! | BQ23: =BL23*BS1 -> 8009.5476 | BR23: =IF(BQ23>0,BQ23/BM23,0) -> 182.03517 | BS23: =IF(BQ23>0,BQ23/BO23,0) -> #DIV/0!
A24: 19 | C24: =IF(+B24-B23>0,B24-B23,(B24-B23)>0)*800 -> 0 | E24: =IF(+D24-D23>0,D24-D23,(D24-D23)>0)*80 -> 0 | G24: =IF(+F24-F23>0,F24-F23,(F24-F23)>0)*10 -> 0 | H24: 65 | I24: 21998715 | J24: =IF(I24>=I23,I24-I23,0) -> 4933 | K24: =M24+O24 -> 3070 | L24: 988735 | M24: =IF(L24>=L23,L24-L23,0) -> 1545 | N24: 990838 | O24: =IF(N24>=N23,N24-N23,0) -> 1525 | P24: 214511 | Q24: =IF(P24>=P23,P24-P23,0)*30 -> 390 | R24: 702925 | S24: =IF(R24>=R23,R24-R23,0) -> 0 | T24: 344001 | U24: =IF(T24>=T23,T24-T23,0) -> 0 | V24: 129253 | W24: =IF(V24>=V23,V24-V23,0) -> 148 | X24: 235394 | Y24: =IF(X24>=X23,X24-X23,0) -> 248 | Z24: 315108 | AA24: =IF(Z24>=Z23,Z24-Z23,0)*0.53 -> 0 | AB24: 363773 | AC24: =IF(AB24>=AB23,AB24-AB23,0)*0.53 -> 0 | AD24: 552132 | AE24: =IF(AD24>=AD23,AD24-AD23,0)*0.53 -> 374.71 | AF24: 307674 | AG24: =IF(AF24>=AF23,AF24-AF23,0)*0.53 -> 646.07 | AH24: 530148 | AI24: =IF(AH24>=AH23,AH24-AH23,0)*0.53 -> 154.76 | AJ24: 677439 | AK24: =IF(AJ24>=AJ23,AJ24-AJ23,0)*0.53 -> 1515.27 | AL24: =AA24+AC24+AE24+AG24+AI24+AK24 -> 2690.81 | AM24: 7206055 | AN24: =IF(AM24>=AM23,AM24-AM23,0) -> 921 | AO24: 570875 | AP24: =IF(AO24>=AO23,AO24-AO23,0) -> 275 | AQ24: 912099 | AR24: =IF(AQ24>=AQ23,AQ24-AQ23,0)*0.11 -> 13.64 | AS24: 794383 | AT24: =IF(AS24>=AS23,AS24-AS23,0) -> 34 | AU24: 2332181 | AV24: =IF(AU24>=AU23,AU24-AU23,0) -> 693 | AW24: 208733 | AX24: =IF(AW24>=AW23,AW24-AW23,0) -> 50 | AY24: 17629691 | AZ24: =IF(AY24>=AY23,AY24-AY23,0) -> 3474 | BA24: 21831637 | BB24: =IF(BA24>=BA23,BA24-BA23,0)-(0.6*BG24)-(0.5*BI24)-BK24-BE24 -> 4202 | BC24: =AN24+AP24+AR24+AT24+AV24+AX24+AZ24+BB24 -> 9662.64 | BD24: 1365091 | BE24: =IF(BD24>=BD23,BD24-BD23,0) -> 358 | BF24: 3480859 | BG24: =IF(BF24>=BF23,BF24-BF23,0) -> 890 | BH24: 371395 | BI24: =IF(BH24>=BH23,BH24-BH23,0) -> 110 | BJ24: 449798 | BK24: =IF(BJ24>=BJ23,BJ24-BJ23,0) -> 203 | BL24: =J24+Q24+AL24+BC24 -> 17676.45 | BM24: 51 | BN24: =IF(BL24>0,BL24/BM24,0) -> 346.59706 | BP24: =IF(BL24>0,BL24/BO24,0) -> #DIV/0! | BQ24: =BL24*BS1 -> 8131.167 | BR24: =IF(BQ24>0,BQ24/BM24,0) -> 159.43465 | BS24: =IF(BQ24>0,BQ24/BO24,0) -> #DIV/0!
A25: 20 | C25: =IF(+B25-B24>0,B25-B24,(B25-B24)>0)*800 -> 0 | E25: =IF(+D25-D24>0,D25-D24,(D25-D24)>0)*80 -> 0 | G25: =IF(+F25-F24>0,F25-F24,(F25-F24)>0)*10 -> 0 | I25: 22003726 | J25: =IF(I25>=I24,I25-I24,0) -> 5011 | K25: =M25+O25 -> 3095 | L25: 990323 | M25: =IF(L25>=L24,L25-L24,0) -> 1588 | N25: 992345 | O25: =IF(N25>=N24,N25-N24,0) -> 1507 | P25: 214522 | Q25: =IF(P25>=P24,P25-P24,0)*30 -> 330 | R25: 702925 | S25: =IF(R25>=R24,R25-R24,0) -> 0 | T25: 344001 | U25: =IF(T25>=T24,T25-T24,0) -> 0 | V25: 129399 | W25: =IF(V25>=V24,V25-V24,0) -> 146 | X25: 235634 | Y25: =IF(X25>=X24,X25-X24,0) -> 240 | Z25: 315108 | AA25: =IF(Z25>=Z24,Z25-Z24,0)*0.53 -> 0 | AB25: 363773 | AC25: =IF(AB25>=AB24,AB25-AB24,0)*0.53 -> 0 | AD25: 554474 | AE25: =IF(AD25>=AD24,AD25-AD24,0)*0.53 -> 1241.26 | AF25: 307674 | AG25: =IF(AF25>=AF24,AF25-AF24,0)*0.53 -> 0 | AH25: 530514 | AI25: =IF(AH25>=AH24,AH25-AH24,0)*0.53 -> 193.98 | AJ25: 680516 | AK25: =IF(AJ25>=AJ24,AJ25-AJ24,0)*0.53 -> 1630.81 | AL25: =AA25+AC25+AE25+AG25+AI25+AK25 -> 3066.05 | AM25: 7206792 | AN25: =IF(AM25>=AM24,AM25-AM24,0) -> 737 | AO25: 571161 | AP25: =IF(AO25>=AO24,AO25-AO24,0) -> 286 | AQ25: 912224 | AR25: =IF(AQ25>=AQ24,AQ25-AQ24,0)*0.11 -> 13.75 | AS25: 794416 | AT25: =IF(AS25>=AS24,AS25-AS24,0) -> 33 | AU25: 2332940 | AV25: =IF(AU25>=AU24,AU25-AU24,0) -> 759 | AW25: 208796 | AX25: =IF(AW25>=AW24,AW25-AW24,0) -> 63 | AY25: 17632974 | AZ25: =IF(AY25>=AY24,AY25-AY24,0) -> 3283 | BA25: 21836872 | BB25: =IF(BA25>=BA24,BA25-BA24,0)-(0.6*BG25)-(0.5*BI25)-BK25-BE25 -> 4115.2 | BC25: =AN25+AP25+AR25+AT25+AV25+AX25+AZ25+BB25 -> 9289.95 | BD25: 1365449 | BE25: =IF(BD25>=BD24,BD25-BD24,0) -> 358 | BF25: 3481707 | BG25: =IF(BF25>=BF24,BF25-BF24,0) -> 848 | BH25: 371497 | BI25: =IF(BH25>=BH24,BH25-BH24,0) -> 102 | BJ25: 450000 | BK25: =IF(BJ25>=BJ24,BJ25-BJ24,0) -> 202 | BL25: =J25+Q25+AL25+BC25 -> 17697 | BM25: 48 | BN25: =IF(BL25>0,BL25/BM25,0) -> 368.6875 | BP25: =IF(BL25>0,BL25/BO25,0) -> #DIV/0! | BQ25: =BL25*BS1 -> 8140.62 | BR25: =IF(BQ25>0,BQ25/BM25,0) -> 169.59625 | BS25: =IF(BQ25>0,BQ25/BO25,0) -> #DIV/0!
