Workbook

Sheet Total
A1: Site Name | B1: Day | C1: Month | D1: Year | E1: Total Electricity Kwh | F1: Electricity Tariff ($/Kwh) | G1: Natual Gas (m3) | H1: Natural Gas $/m3 | I1: Water Utility Supply (m3) m3 | J1: Water Utility Supply (m3) $/m3 | K1: Room Nights
A2: Cairo at The First Residence | B2: 1 | C2: 7 | D2: 2021 | E2: 37683.18 | F2: 1.32 | G2: =963.56+217.5 -> 1181.06 | H2: 3.89 | I2: 352.77 | J2: 10 | K2: 178
A3: Cairo at The First Residence | B3: =B2+1 -> 2 | C3: 7 | D3: 2021 | E3: 37683.18 | F3: =F2 -> 1.32 | G3: =963.56+217.5 -> 1181.06 | H3: 3.89 | I3: 352.77 | J3: 10 | K3: 178
A4: Cairo at The First Residence | B4: =B3+1 -> 3 | C4: 7 | D4: 2021 | E4: 37683.18 | F4: =F3 -> 1.32 | G4: =963.56+217.5 -> 1181.06 | H4: 3.89 | I4: 352.77 | J4: 10 | K4: 178
A5: Cairo at The First Residence | B5: =B4+1 -> 4 | C5: 7 | D5: 2021 | E5: 37683.18 | F5: =F4 -> 1.32 | G5: =963.56+217.5 -> 1181.06 | H5: 3.89 | I5: 352.77 | J5: 10 | K5: 178
A6: Cairo at The First Residence | B6: =B5+1 -> 5 | C6: 7 | D6: 2021 | E6: 37683.18 | F6: =F5 -> 1.32 | G6: =963.56+217.5 -> 1181.06 | H6: 3.89 | I6: 352.77 | J6: 10 | K6: 178
A7: Cairo at The First Residence | B7: =B6+1 -> 6 | C7: 7 | D7: 2021 | E7: 37683.18 | F7: =F6 -> 1.32 | G7: =963.56+217.5 -> 1181.06 | H7: 3.89 | I7: 352.77 | J7: 10 | K7: 178
A8: Cairo at The First Residence | B8: =B7+1 -> 7 | C8: 7 | D8: 2021 | E8: 37683.18 | F8: =F7 -> 1.32 | G8: =963.56+217.5 -> 1181.06 | H8: 3.89 | I8: 352.77 | J8: 10 | K8: 178
A9: Cairo at The First Residence | B9: =B8+1 -> 8 | C9: 7 | D9: 2021 | E9: 37683.18 | F9: =F8 -> 1.32 | G9: =963.56+217.5 -> 1181.06 | H9: 3.89 | I9: 352.77 | J9: 10 | K9: 178
A10: Cairo at The First Residence | B10: =B9+1 -> 9 | C10: 7 | D10: 2021 | E10: 37683.18 | F10: =F9 -> 1.32 | G10: =963.56+217.5 -> 1181.06 | H10: 3.89 | I10: 352.77 | J10: 10 | K10: 178
A11: Cairo at The First Residence | B11: =B10+1 -> 10 | C11: 7 | D11: 2021 | E11: 37683.18 | F11: =F10 -> 1.32 | G11: =963.56+217.5 -> 1181.06 | H11: 3.89 | I11: 352.77 | J11: 10 | K11: 178
A12: Cairo at The First Residence | B12: =B11+1 -> 11 | C12: 7 | D12: 2021 | E12: 37683.18 | F12: =F11 -> 1.32 | G12: =963.56+217.5 -> 1181.06 | H12: 3.89 | I12: 352.77 | J12: 10 | K12: 178
A13: Cairo at The First Residence | B13: =B12+1 -> 12 | C13: 7 | D13: 2021 | E13: 37683.18 | F13: =F12 -> 1.32 | G13: =963.56+217.5 -> 1181.06 | H13: 3.89 | I13: 352.77 | J13: 10 | K13: 178
A14: Cairo at The First Residence | B14: =B13+1 -> 13 | C14: 7 | D14: 2021 | E14: 37683.18 | F14: =F13 -> 1.32 | G14: =963.56+217.5 -> 1181.06 | H14: 3.89 | I14: 352.77 | J14: 10 | K14: 178
... A32: Cairo at The First Residence | B32: =B31+1 -> 31 | C32: 7 | D32: 2021 | E32: 37683.18 | F32: =F31 -> 1.32 | G32: =963.56+217.5 -> 1181.06 | H32: 3.89 | I32: 352.77 | J32: 10 | K32: 178

Sheet Submetering
A1: Site Name | B1: Day | C1: Month | D1: Year | E1: Electricity | F1: Main Feeder -KWh | G1: T2+T8 -KWh | H1: La Gourmandize -KWh | I1: Casino 3rd floor EM -KWh | J1: Casino 3rd floor Normal -KWh | K1: Chiller 1 -KWh | L1: Chiller 2 -KWh | M1: Chiller 3 -KWh | N1: Chiller 4 -KWh | O1: Chiller 5 -KWh | P1: Chiller 6 -KWh | Q1: Cooling towers -KWh | R1: Chiller Pumps -KWh | S1: Cooling Tower Pumps -KWh | T1: Fiber Chiller -KWh | U1: Mall Ceiling light -KWh | V1: LG Bakery -KWh | W1: LG Bakery light ( Old lockers ) -KWh | X1: MCCR1 -KWh | Y1: Children Swimming Pool -KWh | Z1: DPH1 -KWh | AA1: Guest Rooms Emerg. -KWh | AB1: Hotel Hoods -KWh | AC1: Main G2 -KWh | AD1: Old Casino Emergency -KWh | AE1: L / A -KWh | AF1: L / B -KWh | AG1: L / C -KWh | AH1: Water | AI1: Main water meter 1 -m3 | AJ1: Main water meter 2 -m3 | AK1: Main water meter 3 -m3 | AL1: Gas | AM1: Main Gas Flow Meter -m3 | AN1: Laundry Gas Flow Meter -m3 | AO1: Gourmandize Gas Flow Meter -m3 | AP1: Room Nights
A2: Cairo at The First Residence | B2: 1 | C2: 7 | D2: 2021 | F2: =Elect!J6 -> 5335 | G2: =Elect!K6 -> 3380 | H2: =Elect!Q6 -> 600 | I2: =Elect!S6 -> 116 | J2: =Elect!U6 -> 228 | K2: =Elect!W6 -> 3795.33 | L2: =Elect!Y6 -> 0 | M2: =Elect!AA6 -> 3597.64 | N2: =Elect!AC6 -> 0 | O2: =Elect!AE6 -> 1768.08 | P2: =Elect!AG6 -> 0 | Q2: =Elect!AI6 -> 1109.29 | R2: =Elect!AK6 -> 3604.53 | S2: =Elect!AM6 -> 154.76 | T2: =Elect!AP6 -> 199.575 | U2: =Elect!AR6 -> 135 | V2: =Elect!AT6 -> 162 | W2: =Elect!AV6 -> 28 | X2: =Elect!AX6 -> 1171 | Y2: =Elect!AZ6 -> 65 | Z2: =Elect!BB6 -> 4065 | AA2: =Elect!BD6 -> 178 | AB2: =Elect!BF6 -> 132 | AC2: =Elect!BH6 -> 5599.65 | AD2: =Elect!BL6 -> 0 | AE2: =Elect!BN6 -> 1087 | AF2: =Elect!BP6 -> 76 | AG2: =Elect!BR6 -> 174 | AI2: =Water!C7 -> 197.2 | AJ2: =Water!E7 -> 0 | AK2: =Water!G7 -> 0 | AM2: =Gas!C7 -> 914.25 | AN2: =Gas!E7 -> 145.6 | AO2: =Gas!G7 -> 90 | AP2: 178
A3: Cairo at The First Residence | B3: =B2+1 -> 2 | C3: 7 | D3: 2021 | F3: =Elect!J7 -> 5320 | G3: =Elect!K7 -> 3529 | H3: =Elect!Q7 -> 600 | I3: =Elect!S7 -> 147 | J3: =Elect!U7 -> 295 | K3: =Elect!W7 -> 2934.08 | L3: =Elect!Y7 -> 1896.34 | M3: =Elect!AA7 -> 625.4 | N3: =Elect!AC7 -> 0 | O3: =Elect!AE7 -> 104.94 | P3: =Elect!AG7 -> 312.7 | Q3: =Elect!AI7 -> 1212.11 | R3: =Elect!AK7 -> 3848.86 | S3: =Elect!AM7 -> 171.19 | T3: =Elect!AP7 -> 205.0875 | U3: =Elect!AR7 -> 198 | V3: =Elect!AT7 -> 173 | W3: =Elect!AV7 -> 27 | X3: =Elect!AX7 -> 1100 | Y3: =Elect!AZ7 -> 79 | Z3: =Elect!BB7 -> 4780 | AA3: =Elect!BD7 -> 195 | AB3: =Elect!BF7 -> 150 | AC3: =Elect!BH7 -> 6085.85 | AD3: =Elect!BL7 -> 17 | AE3: =Elect!BN7 -> 1389 | AF3: =Elect!BP7 -> 98 | AG3: =Elect!BR7 -> 218 | AI3: =Water!C8 -> 295.8 | AJ3: =Water!E8 -> 0 | AK3: =Water!G8 -> 0 | AM3: =Gas!C8 -> 755.25 | AN3: =Gas!E8 -> 254.8 | AO3: =Gas!G8 -> 50 | AP3: 178
A4: Cairo at The First Residence | B4: =B3+1 -> 3 | C4: 7 | D4: 2021 | F4: =Elect!J8 -> 6025 | G4: =Elect!K8 -> 2722 | H4: =Elect!Q8 -> 510 | I4: =Elect!S8 -> 121 | J4: =Elect!U8 -> 241 | K4: =Elect!W8 -> 2322.46 | L4: =Elect!Y8 -> 3174.17 | M4: =Elect!AA8 -> 0 | N4: =Elect!AC8 -> 0 | O4: =Elect!AE8 -> 10.6 | P4: =Elect!AG8 -> 1565.62 | Q4: =Elect!AI8 -> 944.46 | R4: =Elect!AK8 -> 2957.4 | S4: =Elect!AM8 -> 136.21 | T4: =Elect!AP8 -> 189.1125 | U4: =Elect!AR8 -> 288 | V4: =Elect!AT8 -> 162 | W4: =Elect!AV8 -> 28 | X4: =Elect!AX8 -> 874 | Y4: =Elect!AZ8 -> 66 | Z4: =Elect!BB8 -> 4981 | AA4: =Elect!BD8 -> 183 | AB4: =Elect!BF8 -> 153 | AC4: =Elect!BH8 -> 5043.8 | AD4: =Elect!BL8 -> 48 | AE4: =Elect!BN8 -> 1174 | AF4: =Elect!BP8 -> 82 | AG4: =Elect!BR8 -> 168 | AI4: =Water!C9 -> 278.4 | AJ4: =Water!E9 -> 0 | AK4: =Water!G9 -> 84.68 | AM4: =Gas!C9 -> 1261.4 | AN4: =Gas!E9 -> 121.8 | AO4: =Gas!G9 -> 95 | AP4: 178
A5: Cairo at The First Residence | B5: =B4+1 -> 4 | C5: 7 | D5: 2021 | F5: =Elect!J9 -> 5129 | G5: =Elect!K9 -> 3304 | H5: =Elect!Q9 -> 510 | I5: =Elect!S9 -> 130 | J5: =Elect!U9 -> 251 | K5: =Elect!W9 -> 2560.96 | L5: =Elect!Y9 -> 3780.49 | M5: =Elect!AA9 -> 422.94 | N5: =Elect!AC9 -> 0 | O5: =Elect!AE9 -> 11.13 | P5: =Elect!AG9 -> 1634.52 | Q5: =Elect!AI9 -> 1145.86 | R5: =Elect!AK9 -> 3775.19 | S5: =Elect!AM9 -> 164.3 | T5: =Elect!AP9 -> 202.275 | U5: =Elect!AR9 -> 283 | V5: =Elect!AT9 -> 165 | W5: =Elect!AV9 -> 42 | X5: =Elect!AX9 -> 1041 | Y5: =Elect!AZ9 -> 71 | Z5: =Elect!BB9 -> 4725 | AA5: =Elect!BD9 -> 190 | AB5: =Elect!BF9 -> 107 | AC5: =Elect!BH9 -> 5812.4 | AD5: =Elect!BL9 -> 58 | AE5: =Elect!BN9 -> 1434 | AF5: =Elect!BP9 -> 94 | AG5: =Elect!BR9 -> 195 | AI5: =Water!C10 -> 179.8 | AJ5: =Water!E10 -> 0 | AK5: =Water!G10 -> 56.84 | AM5: =Gas!C10 -> 755.78 | AN5: =Gas!E10 -> 290.5 | AO5: =Gas!G10 -> 92 | AP5: 178
A6: Cairo at The First Residence | B6: =B5+1 -> 5 | C6: 7 | D6: 2021 | F6: =Elect!J10 -> 5357 | G6: =Elect!K10 -> 3233 | H6: =Elect!Q10 -> 540 | I6: =Elect!S10 -> 136 | J6: =Elect!U10 -> 271 | K6: =Elect!W10 -> 2312.39 | L6: =Elect!Y10 -> 3746.57 | M6: =Elect!AA10 -> 0 | N6: =Elect!AC10 -> 0 | O6: =Elect!AE10 -> 11.66 | P6: =Elect!AG10 -> 1597.95 | Q6: =Elect!AI10 -> 1063.71 | R6: =Elect!AK10 -> 3620.43 | S6: =Elect!AM10 -> 160.59 | T6: =Elect!AP10 -> 199.125 | U6: =Elect!AR10 -> 240 | V6: =Elect!AT10 -> 163 | W6: =Elect!AV10 -> 45 | X6: =Elect!AX10 -> 1055 | Y6: =Elect!AZ10 -> 65 | Z6: =Elect!BB10 -> 4864 | AA6: =Elect!BD10 -> 198 | AB6: =Elect!BF10 -> 112 | AC6: =Elect!BH10 -> 6638.55 | AD6: =Elect!BL10 -> 61 | AE6: =Elect!BN10 -> 1 | AF6: =Elect!BP10 -> 0 | AG6: =Elect!BR10 -> 0 | AI6: =Water!C11 -> 249.4 | AJ6: =Water!E11 -> 0 | AK6: =Water!G11 -> 65.54 | AM6: =Gas!C11 -> 754.72 | AN6: =Gas!E11 -> 163.8 | AO6: =Gas!G11 -> 38 | AP6: 178
A7: Cairo at The First Residence | B7: =B6+1 -> 6 | C7: 7 | D7: 2021 | F7: =Elect!J11 -> 5538 | G7: =Elect!K11 -> 3491 | H7: =Elect!Q11 -> 540 | I7: =Elect!S11 -> 136 | J7: =Elect!U11 -> 267 | K7: =Elect!W11 -> 2644.17 | L7: =Elect!Y11 -> 3925.18 | M7: =Elect!AA11 -> 0 | N7: =Elect!AC11 -> 0 | O7: =Elect!AE11 -> 11.13 | P7: =Elect!AG11 -> 1662.08 | Q7: =Elect!AI11 -> 1041.45 | R7: =Elect!AK11 -> 3857.34 | S7: =Elect!AM11 -> 161.65 | T7: =Elect!AP11 -> 204.6375 | U7: =Elect!AR11 -> 165 | V7: =Elect!AT11 -> 152 | W7: =Elect!AV11 -> 60 | X7: =Elect!AX11 -> 1096 | Y7: =Elect!AZ11 -> 55 | Z7: =Elect!BB11 -> 4983 | AA7: =Elect!BD11 -> 199 | AB7: =Elect!BF11 -> 111 | AC7: =Elect!BH11 -> 5929.5 | AD7: =Elect!BL11 -> 58 | AE7: =Elect!BN11 -> 1525 | AF7: =Elect!BP11 -> 105 | AG7: =Elect!BR11 -> 202 | AI7: =Water!C12 -> 243.6 | AJ7: =Water!E12 -> 0 | AK7: =Water!G12 -> 69.6 | AM7: =Gas!C12 -> 755.78 | AN7: =Gas!E12 -> 200.2 | AO7: =Gas!G12 -> 92 | AP7: 178
A8: Cairo at The First Residence | B8: =B7+1 -> 7 | C8: 7 | D8: 2021 | F8: =Elect!J12 -> 5916 | G8: =Elect!K12 -> 3810 | H8: =Elect!Q12 -> 540 | I8: =Elect!S12 -> 142 | J8: =Elect!U12 -> 283 | K8: =Elect!W12 -> 2751.23 | L8: =Elect!Y12 -> 3486.34 | M8: =Elect!AA12 -> 106.53 | N8: =Elect!AC12 -> 0 | O8: =Elect!AE12 -> 840.05 | P8: =Elect!AG12 -> 1772.85 | Q8: =Elect!AI12 -> 1188.26 | R8: =Elect!AK12 -> 3997.26 | S8: =Elect!AM12 -> 152.11 | T8: =Elect!AP12 -> 190.0125 | U8: =Elect!AR12 -> 227 | V8: =Elect!AT12 -> 156 | W8: =Elect!AV12 -> 63 | X8: =Elect!AX12 -> 1124 | Y8: =Elect!AZ12 -> 56 | Z8: =Elect!BB12 -> 4997 | AA8: =Elect!BD12 -> 199 | AB8: =Elect!BF12 -> 109 | AC8: =Elect!BH12 -> 6321.75 | AD8: =Elect!BL12 -> 59 | AE8: =Elect!BN12 -> 1535 | AF8: =Elect!BP12 -> 110 | AG8: =Elect!BR12 -> 211 | AI8: =Water!C13 -> 191.4 | AJ8: =Water!E13 -> 0 | AK8: =Water!G13 -> 98.02 | AM8: =Gas!C13 -> 754.72 | AN8: =Gas!E13 -> 200.2 | AO8: =Gas!G13 -> 96 | AP8: 178
A9: Cairo at The First Residence | B9: =B8+1 -> 8 | C9: 7 | D9: 2021 | F9: =Elect!J13 -> 5534 | G9: =Elect!K13 -> 3399 | H9: =Elect!Q13 -> 540 | I9: =Elect!S13 -> 140 | J9: =Elect!U13 -> 281 | K9: =Elect!W13 -> 2934.08 | L9: =Elect!Y13 -> 2004.46 | M9: =Elect!AA13 -> 2719.43 | N9: =Elect!AC13 -> 0 | O9: =Elect!AE13 -> 11.66 | P9: =Elect!AG13 -> 1816.84 | Q9: =Elect!AI13 -> 1143.74 | R9: =Elect!AK13 -> 4161.03 | S9: =Elect!AM13 -> 188.68 | T9: =Elect!AP13 -> 199.35 | U9: =Elect!AR13 -> 203 | V9: =Elect!AT13 -> 149 | W9: =Elect!AV13 -> 53 | X9: =Elect!AX13 -> 985 | Y9: =Elect!AZ13 -> 74 | Z9: =Elect!BB13 -> 4476 | AA9: =Elect!BD13 -> 182 | AB9: =Elect!BF13 -> 131 | AC9: =Elect!BH13 -> 5672.8 | AD9: =Elect!BL13 -> 60 | AE9: =Elect!BN13 -> 1461 | AF9: =Elect!BP13 -> 115 | AG9: =Elect!BR13 -> 209 | AI9: =Water!C14 -> 185.6 | AJ9: =Water!E14 -> 0 | AK9: =Water!G14 -> 172.26 | AM9: =Gas!C14 -> 755.78 | AN9: =Gas!E14 -> 200.2 | AO9: =Gas!G14 -> 85 | AP9: 178
A10: Cairo at The First Residence | B10: =B9+1 -> 9 | C10: 7 | D10: 2021 | F10: =Elect!J14 -> 6464 | G10: =Elect!K14 -> 3403 | H10: =Elect!Q14 -> 540 | I10: =Elect!S14 -> 136 | J10: =Elect!U14 -> 272 | K10: =Elect!W14 -> 2679.68 | L10: =Elect!Y14 -> 0 | M10: =Elect!AA14 -> 3938.96 | N10: =Elect!AC14 -> 0 | O10: =Elect!AE14 -> 11.13 | P10: =Elect!AG14 -> 1765.96 | Q10: =Elect!AI14 -> 1142.15 | R10: =Elect!AK14 -> 4385.22 | S10: =Elect!AM14 -> 166.42 | T10: =Elect!AP14 -> 195.075 | U10: =Elect!AR14 -> 307 | V10: =Elect!AT14 -> 150 | W10: =Elect!AV14 -> 31 | X10: =Elect!AX14 -> 965 | Y10: =Elect!AZ14 -> 72 | Z10: =Elect!BB14 -> 4470 | AA10: =Elect!BD14 -> 184 | AB10: =Elect!BF14 -> 131 | AC10: =Elect!BH14 -> 5414.1 | AD10: =Elect!BL14 -> 58 | AE10: =Elect!BN14 -> 1392 | AF10: =Elect!BP14 -> 110 | AG10: =Elect!BR14 -> 205 | AI10: =Water!C15 -> 191.4 | AJ10: =Water!E15 -> 0 | AK10: =Water!G15 -> 122.96 | AM10: =Gas!C15 -> 754.72 | AN10: =Gas!E15 -> 228.2 | AO10: =Gas!G15 -> 60 | AP10: 178
A11: Cairo at The First Residence | B11: =B10+1 -> 10 | C11: 7 | D11: 2021 | F11: =Elect!J15 -> 4481 | G11: =Elect!K15 -> 4377 | H11: =Elect!Q15 -> 510 | I11: =Elect!S15 -> 144 | J11: =Elect!U15 -> 291 | K11: =Elect!W15 -> 3034.25 | L11: =Elect!Y15 -> 0 | M11: =Elect!AA15 -> 4044.96 | N11: =Elect!AC15 -> 0 | O11: =Elect!AE15 -> 961.42 | P11: =Elect!AG15 -> 873.97 | Q11: =Elect!AI15 -> 1146.92 | R11: =Elect!AK15 -> 4417.02 | S11: =Elect!AM15 -> 167.48 | T11: =Elect!AP15 -> 187.9875 | U11: =Elect!AR15 -> 228 | V11: =Elect!AT15 -> 152 | W11: =Elect!AV15 -> 37 | X11: =Elect!AX15 -> 966 | Y11: =Elect!AZ15 -> 77 | Z11: =Elect!BB15 -> 4608 | AA11: =Elect!BD15 -> 191 | AB11: =Elect!BF15 -> 131 | AC11: =Elect!BH15 -> 5897.45 | AD11: =Elect!BL15 -> 61 | AE11: =Elect!BN15 -> 1508 | AF11: =Elect!BP15 -> 111 | AG11: =Elect!BR15 -> 216 | AI11: =Water!C16 -> 185.6 | AJ11: =Water!E16 -> 0 | AK11: =Water!G16 -> 73.66 | AM11: =Gas!C16 -> 755.78 | AN11: =Gas!E16 -> 186.2 | AO11: =Gas!G16 -> 71 | AP11: 178
A12: Cairo at The First Residence | B12: =B11+1 -> 11 | C12: 7 | D12: 2021 | F12: =Elect!J16 -> 5145 | G12: =Elect!K16 -> 3405 | H12: =Elect!Q16 -> 510 | I12: =Elect!S16 -> 132 | J12: =Elect!U16 -> 267 | K12: =Elect!W16 -> 2618.2 | L12: =Elect!Y16 -> 1272.53 | M12: =Elect!AA16 -> 3853.63 | N12: =Elect!AC16 -> 0 | O12: =Elect!AE16 -> 1755.36 | P12: =Elect!AG16 -> 10.6 | Q12: =Elect!AI16 -> 1158.05 | R12: =Elect!AK16 -> 4269.15 | S12: =Elect!AM16 -> 169.07 | T12: =Elect!AP16 -> 196.0875 | U12: =Elect!AR16 -> 263 | V12: =Elect!AT16 -> 161 | W12: =Elect!AV16 -> 59 | X12: =Elect!AX16 -> 976 | Y12: =Elect!AZ16 -> 71 | Z12: =Elect!BB16 -> 4594 | AA12: =Elect!BD16 -> 181 | AB12: =Elect!BF16 -> 109 | AC12: =Elect!BH16 -> 5717.75 | AD12: =Elect!BL16 -> 59 | AE12: =Elect!BN16 -> 1524 | AF12: =Elect!BP16 -> 101 | AG12: =Elect!BR16 -> 204 | AI12: =Water!C17 -> 220.4 | AJ12: =Water!E17 -> 0 | AK12: =Water!G17 -> 72.5 | AM12: =Gas!C17 -> 771.68 | AN12: =Gas!E17 -> 367.5 | AO12: =Gas!G17 -> 147 | AP12: 178
A13: Cairo at The First Residence | B13: =B12+1 -> 12 | C13: 7 | D13: 2021 | F13: =Elect!J17 -> 5172 | G13: =Elect!K17 -> 3251 | H13: =Elect!Q17 -> 480 | I13: =Elect!S17 -> 137 | J13: =Elect!U17 -> 275 | K13: =Elect!W17 -> 2325.64 | L13: =Elect!Y17 -> 2282.71 | M13: =Elect!AA17 -> 3308.26 | N13: =Elect!AC17 -> 0 | O13: =Elect!AE17 -> 1812.6 | P13: =Elect!AG17 -> 10.6 | Q13: =Elect!AI17 -> 1129.96 | R13: =Elect!AK17 -> 4438.22 | S13: =Elect!AM17 -> 164.83 | T13: =Elect!AP17 -> 196.7625 | U13: =Elect!AR17 -> 172 | V13: =Elect!AT17 -> 154 | W13: =Elect!AV17 -> 63 | X13: =Elect!AX17 -> 971 | Y13: =Elect!AZ17 -> 74 | Z13: =Elect!BB17 -> 4609 | AA13: =Elect!BD17 -> 176 | AB13: =Elect!BF17 -> 111 | AC13: =Elect!BH17 -> 5871.65 | AD13: =Elect!BL17 -> 57 | AE13: =Elect!BN17 -> 1636 | AF13: =Elect!BP17 -> 107 | AG13: =Elect!BR17 -> 205 | AI13: =Water!C18 -> 104.4 | AJ13: =Water!E18 -> 0 | AK13: =Water!G18 -> 56.26 | AM13: =Gas!C18 -> 705.96 | AN13: =Gas!E18 -> 229.6 | AO13: =Gas!G18 -> 71 | AP13: 178
A14: Cairo at The First Residence | B14: =B13+1 -> 13 | C14: 7 | D14: 2021 | F14: =Elect!J18 -> 5485 | G14: =Elect!K18 -> 3433 | H14: =Elect!Q18 -> 450 | I14: =Elect!S18 -> 140 | J14: =Elect!U18 -> 281 | K14: =Elect!W18 -> 2241.9 | L14: =Elect!Y18 -> 3116.93 | M14: =Elect!AA18 -> 2307.62 | N14: =Elect!AC18 -> 0 | O14: =Elect!AE18 -> 1797.23 | P14: =Elect!AG18 -> 10.6 | Q14: =Elect!AI18 -> 1179.25 | R14: =Elect!AK18 -> 4369.85 | S14: =Elect!AM18 -> 170.13 | T14: =Elect!AP18 -> 191.5875 | U14: =Elect!AR18 -> 194 | V14: =Elect!AT18 -> 166 | W14: =Elect!AV18 -> 60 | X14: =Elect!AX18 -> 941 | Y14: =Elect!AZ18 -> 77 | Z14: =Elect!BB18 -> 5049 | AA14: =Elect!BD18 -> 177 | AB14: =Elect!BF18 -> 122 | AC14: =Elect!BH18 -> 5952.75 | AD14: =Elect!BL18 -> 59 | AE14: =Elect!BN18 -> 1698 | AF14: =Elect!BP18 -> 107 | AG14: =Elect!BR18 -> 212 | AI14: =Water!C19 -> 272.6 | AJ14: =Water!E19 -> 0 | AK14: =Water!G19 -> 125.86 | AM14: =Gas!C19 -> 804.54 | AN14: =Gas!E19 -> 177.1 | AO14: =Gas!G19 -> 110 | AP14: 178
... A32: Cairo at The First Residence | B32: =B31+1 -> 31 | C32: 7 | D32: 2021 | F32: =Elect!J36 -> 4629 | G32: =Elect!K36 -> 3504 | H32: =Elect!Q36 -> 690 | I32: =Elect!S36 -> 0 | J32: =Elect!U36 -> 0 | K32: =Elect!W36 -> 2791.828 | L32: =Elect!Y36 -> 3470.44 | M32: =Elect!AA36 -> 0 | N32: =Elect!AC36 -> 0 | O32: =Elect!AE36 -> 1313.87 | P32: =Elect!AG36 -> 147.34 | Q32: =Elect!AI36 -> 1007 | R32: =Elect!AK36 -> 3252.61 | S32: =Elect!AM36 -> 156.88 | T32: =Elect!AP36 -> 193.6125 | U32: =Elect!AR36 -> 166 | V32: =Elect!AT36 -> 160 | W32: =Elect!AV36 -> 64 | X32: =Elect!AX36 -> 1113.8 | Y32: =Elect!AZ36 -> 75 | Z32: =Elect!BB36 -> 4482 | AA32: =Elect!BD36 -> 203 | AB32: =Elect!BF36 -> 130 | AC32: =Elect!BH36 -> 5703.6 | AD32: =Elect!BL36 -> 43 | AE32: =Elect!BN36 -> 1598 | AF32: =Elect!BP36 -> 114 | AG32: =Elect!BR36 -> 201 | AI32: =Water!C37 -> 359.6 | AJ32: =Water!E37 -> 0 | AK32: =Water!G37 -> 0 | AM32: =Gas!C37 -> 942.34 | AN32: =Gas!E37 -> 216.3 | AO32: =Gas!G37 -> 104 | AP32: 178

Sheet Elect
A1: July | M1: Electricity | BP1: Gourmandise UP | BR1: 1.6 | BS1: Power Taxes | BU1: Max Demand | BW1: 500 | BX1: Electricity UP | BZ1: 1.15
AD2: Chiller 5 Meter was miswired and was corrected on 21st | BS2: Light Taxes | BU2: PF Penalty | BX2: Max. Demand UP | BZ2: 30
A3: Date | B3: COUNTER (1) | D3: MD | F3: KVAR | H3: n | I3: Guest Rooms Consumption | R3: Casino Consumption | V3: Plant Room Shared Loads | AO3: To Be Charged By First Arabian | BK3: From Main Panel G2 | BS3: Total Consumption. | BT3: No. Of | BU3: KWH/ | BV3: No. Of | BW3: KWH/ | BX3: Total Cost | BY3: L.E\ | BZ3: L.E\
B4: Reading | C4: Consp. F: *800 | D4: Reading | E4: Consp F: 80 | F4: Reading | G4: Consp. F:*10 | I4: Main Feeder | J4: Consp | K4: T2+T8 | L4: Trans T2 | M4: Consp | N4: Trans T8 | O4: Consp | P4: La Gourmandize | Q4: Consp *30 | R4: Casino 3rd floor EM | S4: Consp | T4: Casino 3rd floor Normal | U4: Consp | V4: Chiller 1 | W4: Consp 53% | X4: Chiller 2 | Y4: Consp 53% | Z4: Chiller 3 | AA4: Consp 53% | AB4: Chiller 4 | AC4: Consp 53% | AD4: Chiller 5 | AE4: Consp 53% | AF4: Chiller 6 | AG4: Consp 53% | AH4: Cooling Towers | AI4: Consp 53% | AJ4: Chiller Pumps | AK4: Consp 53% | AL4: Cooling Tower Pumps | AM4: Consp 53% | AN4: Total Plant Room Consp | AO4: Fiber Chiller (N24) | AP4: Consp | AQ4: Mall Ceiling light (N4) | AR4: Consp | AS4: LG Bakery (N2) | AT4: Consp | AU4: LG Bakery light ( Old lockers ) | AV4: Consp | AW4: MCCR1 | AX4: Consp | AY4: Children Swimming pool | AZ4: Consp | BA4: DPH1 | BB4: Consp | BC4: Guest Rooms Emergency | BD4: Consp | BE4: Hotel Hoods | BF4: Consp | BG4: Main G2 | BH4: Consp | BI4: Total Consp From First Arabian | BJ4: First Arabian Charge Back | BK4: Old Casino Emergency | BL4: Consp | BM4: L / A | BN4: Consp | BO4: L / B | BP4: Consp | BQ4: L / C | BR4: Consp | BT4: Rooms | BU4: room | BV4: guest | BW4: guest | BY4: Room | BZ4: Guest
A5: Last Month Reading | I5: 22746674 | J5: =IF(I5>=I4,I5-I4,0) -> 0 | K5: =M5+O5 -> 0 | L5: 216116 | M5: =IF(L5>=L4,L5-L4,0) -> 0 | N5: 227602 | O5: =IF(N5>=N4,N5-N4,0) -> 0 | P5: 217618 | Q5: =IF(P5>=P4,P5-P4,0)*30 -> 0 | R5: 152378 | S5: =IF(R5>=R4,R5-R4,0) -> 0 | T5: 276952 | U5: =IF(T5>=T4,T5-T4,0) -> 0 | V5: 904062 | W5: =IF(V5>=V4,V5-V4,0)*0.53 -> 0 | X5: 547768 | Y5: =IF(X5>=X4,X5-X4,0)*0.53 -> 0 | Z5: 740382 | AA5: =IF(Z5>=Z4,Z5-Z4,0)*0.53 -> 0 | AB5: 333452 | AC5: =IF(AB5>=AB4,AB5-AB4,0)*0.53 -> 0 | AD5: 374989 | AE5: =IF(AD5>=AD4,AD5-AD4,0)*0.53 -> 0 | AF5: 802312 | AG5: =IF(AF5>=AF4,AF5-AF4,0)*0.53 -> 0 | AH5: 708025 | AI5: =IF(AH5>=AH4,AH5-AH4,0)*0.53 -> 0 | AJ5: 493081 | AK5: =IF(AJ5>=AJ4,AJ5-AJ4,0)*0.53 -> 0 | AL5: 427617 | AM5: =IF(AL5>=AL4,AL5-AL4,0)*0.53 -> 0 | AN5: =W5+Y5+AA5+AC5+AE5+AG5+AI5+AK5+AM5 -> 0 | AO5: 7370675 | AP5: =IF(AO5>=AO4,AO5-AO4,0)*0.1125 -> 0 | AQ5: 619381 | AR5: =IF(AQ5>=AQ4,AQ5-AQ4,0) -> 0 | AS5: 932202 | AT5: =IF(AS5>=AS4,AS5-AS4,0) -> 0 | AU5: 800419 | AV5: =IF(AU5>=AU4,AU5-AU4,0) -> 0 | AW5: 2433073 | AX5: =IF(AW5>=AW4,AW5-AW4,0) -> 0 | AY5: 217166 | AZ5: =IF(AY5>=AY4,AY5-AY4,0) -> 0 | BA5: 18257880 | BB5: =IF(BA5>=BA4,BA5-BA4,0) -> 0 | BC5: 517828 | BD5: =IF(BC5>=BC4,BC5-BC4,0) -> 0 | BE5: 12219 | BF5: =IF(BE5>=BE4,BE5-BE4,0) -> 0 | BG5: 22769782 | BH5: =IF(BG5>=BG4,BG5-BG4,0)-(0.45*BN5)-(0.45*BP5)-BR5 -> 0 | BI5: =AP5+AR5+AT5+AV5+AX5+AZ5+BB5+BD5+BF5+BH5 -> 0 | BJ5: =BI5+AN5 -> 0 | BK5: 1393419 | BL5: =IF(BK5>=BK4,BK5-BK4,0) -> 0 | BM5: 3659868 | BN5: =IF(BM5>=BM4,BM5-BM4,0) -> 0 | BO5: 388992 | BP5: =IF(BO5>=BO4,BO5-BO4,0) -> 0 | BQ5: 482745 | BR5: =IF(BQ5>=BQ4,BQ5-BQ4,0) -> 0
A6: 1 | C6: =IF(+B6-B5>0,B6-B5,(B6-B5)>0)*800 -> 0 | E6: =IF(+D6-D5>0,D6-D5,(D6-D5)>0)*80 -> 0 | G6: =IF(+F6-F5>0,F6-F5,(F6-F5)>0)*10 -> 0 | H6: 56 | I6: 22752009 | J6: =IF(I6>=I5,I6-I5,0) -> 5335 | K6: =M6+O6 -> 3380 | L6: 218121 | M6: =IF(L6>=L5,L6-L5,0) -> 2005 | N6: 228977 | O6: =IF(N6>=N5,N6-N5,0) -> 1375 | P6: 217638 | Q6: =IF(P6>=P5,P6-P5,0)*30 -> 600 | R6: 152494 | S6: =IF(R6>=R5,R6-R5,0) -> 116 | T6: 277180 | U6: =IF(T6>=T5,T6-T5,0) -> 228 | V6: 911223 | W6: =IF(V6>=V5,V6-V5,0)*0.53 -> 3795.33 | X6: 547768 | Y6: =IF(X6>=X5,X6-X5,0)*0.53 -> 0 | Z6: 747170 | AA6: =IF(Z6>=Z5,Z6-Z5,0)*0.53 -> 3597.64 | AB6: 333452 | AC6: =IF(AB6>=AB5,AB6-AB5,0)*0.53 -> 0 | AD6: 378325 | AE6: =IF(AD6>=AD5,AD6-AD5,0)*0.53 -> 1768.08 | AF6: 802312 | AG6: =IF(AF6>=AF5,AF6-AF5,0)*0.53 -> 0 | AH6: 710118 | AI6: =IF(AH6>=AH5,AH6-AH5,0)*0.53 -> 1109.29 | AJ6: 499882 | AK6: =IF(AJ6>=AJ5,AJ6-AJ5,0)*0.53 -> 3604.53 | AL6: 427909 | AM6: =IF(AL6>=AL5,AL6-AL5,0)*0.53 -> 154.76 | AN6: =W6+Y6+AA6+AC6+AE6+AG6+AI6+AK6+AM6 -> 14029.63 | AO6: 7372449 | AP6: =IF(AO6>=AO5,AO6-AO5,0)*0.1125 -> 199.575 | AQ6: 619516 | AR6: =IF(AQ6>=AQ5,AQ6-AQ5,0) -> 135 | AS6: 932364 | AT6: =IF(AS6>=AS5,AS6-AS5,0) -> 162 | AU6: 800447 | AV6: =IF(AU6>=AU5,AU6-AU5,0) -> 28 | AW6: 2434244 | AX6: =IF(AW6>=AW5,AW6-AW5,0) -> 1171 | AY6: 217231 | AZ6: =IF(AY6>=AY5,AY6-AY5,0) -> 65 | BA6: 18261945 | BB6: =IF(BA6>=BA5,BA6-BA5,0) -> 4065 | BC6: 518006 | BD6: =IF(BC6>=BC5,BC6-BC5,0) -> 178 | BE6: 12351 | BF6: =IF(BE6>=BE5,BE6-BE5,0) -> 132 | BG6: 22776079 | BH6: =IF(BG6>=BG5,BG6-BG5,0)-(0.45*BN6)-(0.45*BP6)-BR6 -> 5599.65 | BI6: =AP6+AR6+AT6+AV6+AX6+AZ6+BB6+BD6+BF6+BH6 -> 11735.225 | BJ6: =BI6+AN6 -> 25764.855 | BK6: 1393373 | BL6: =IF(BK6>=BK5,BK6-BK5,0) -> 0 | BM6: 3660955 | BN6: =IF(BM6>=BM5,BM6-BM5,0) -> 1087 | BO6: 389068 | BP6: =IF(BO6>=BO5,BO6-BO5,0) -> 76 | BQ6: 482919 | BR6: =IF(BQ6>=BQ5,BQ6-BQ5,0) -> 174 | BS6: =J6+Q6+AN6+BI6 -> 31699.855 | BT6: 215 | BU6: =IF(BS6>0,BS6/BT5,0) -> #DIV/0! | BW6: =IF(BS6>0,BS6/BV6,0) -> #DIV/0! | BX6: =((BS6-Q6)*$BZ$1)+(Q6*$BR$1) -> 36724.833 | BY6: =IF(BX6>0,BX6/BT5,0) -> #DIV/0! | BZ6: =IF(BX6>0,BX6/BV6,0) -> #DIV/0!
A7: 2 | I7: 22757329 | J7: =IF(I7>=I6,I7-I6,0) -> 5320 | K7: =M7+O7 -> 3529 | L7: 220130 | M7: =IF(L7>=L6,L7-L6,0) -> 2009 | N7: 230497 | O7: =IF(N7>=N6,N7-N6,0) -> 1520 | P7: 217658 | Q7: =IF(P7>=P6,P7-P6,0)*30 -> 600 | R7: 152641 | S7: =IF(R7>=R6,R7-R6,0) -> 147 | T7: 277475 | U7: =IF(T7>=T6,T7-T6,0) -> 295 | V7: 916759 | W7: =IF(V7>=V6,V7-V6,0)*0.53 -> 2934.08 | X7: 551346 | Y7: =IF(X7>=X6,X7-X6,0)*0.53 -> 1896.34 | Z7: 748350 | AA7: =IF(Z7>=Z6,Z7-Z6,0)*0.53 -> 625.4 | AB7: 333452 | AC7: =IF(AB7>=AB6,AB7-AB6,0)*0.53 -> 0 | AD7: 378523 | AE7: =IF(AD7>=AD6,AD7-AD6,0)*0.53 -> 104.94 | AF7: 802902 | AG7: =IF(AF7>=AF6,AF7-AF6,0)*0.53 -> 312.7 | AH7: 712405 | AI7: =IF(AH7>=AH6,AH7-AH6,0)*0.53 -> 1212.11 | AJ7: 507144 | AK7: =IF(AJ7>=AJ6,AJ7-AJ6,0)*0.53 -> 3848.86 | AL7: 428232 | AM7: =IF(AL7>=AL6,AL7-AL6,0)*0.53 -> 171.19 | AN7: =W7+Y7+AA7+AC7+AE7+AG7+AI7+AK7+AM7 -> 11105.62 | AO7: 7374272 | AP7: =IF(AO7>=AO6,AO7-AO6,0)*0.1125 -> 205.0875 | AQ7: 619714 | AR7: =IF(AQ7>=AQ6,AQ7-AQ6,0) -> 198 | AS7: 932537 | AT7: =IF(AS7>=AS6,AS7-AS6,0) -> 173 | AU7: 800474 | AV7: =IF(AU7>=AU6,AU7-AU6,0) -> 27 | AW7: 2435344 | AX7: =IF(AW7>=AW6,AW7-AW6,0) -> 1100 | AY7: 217310 | AZ7: =IF(AY7>=AY6,AY7-AY6,0) -> 79 | BA7: 18266725 | BB7: =IF(BA7>=BA6,BA7-BA6,0) -> 4780 | BC7: 518201 | BD7: =IF(BC7>=BC6,BC7-BC6,0) -> 195 | BE7: 12501 | BF7: =IF(BE7>=BE6,BE7-BE6,0) -> 150 | BG7: 22783052 | BH7: =IF(BG7>=BG6,BG7-BG6,0)-(0.45*BN7)-(0.45*BP7)-BR7 -> 6085.85 | BI7: =AP7+AR7+AT7+AV7+AX7+AZ7+BB7+BD7+BF7+BH7 -> 12992.938 | BJ7: =BI7+AN7 -> 24098.558 | BK7: 1393390 | BL7: =IF(BK7>=BK6,BK7-BK6,0) -> 17 | BM7: 3662344 | BN7: =IF(BM7>=BM6,BM7-BM6,0) -> 1389 | BO7: 389166 | BP7: =IF(BO7>=BO6,BO7-BO6,0) -> 98 | BQ7: 483137 | BR7: =IF(BQ7>=BQ6,BQ7-BQ6,0) -> 218 | BS7: =J7+Q7+AN7+BI7 -> 30018.558 | BT7: 207 | BU7: =IF(BS7>0,BS7/BT6,0) -> 139.6212 | BW7: =IF(BS7>0,BS7/BV7,0) -> #DIV/0! | BX7: =((BS7-Q7)*$BZ$1)+(Q7*$BR$1) -> 34791.341 | BY7: =IF(BX7>0,BX7/BT6,0) -> 161.82019 | BZ7: =IF(BX7>0,BX7/BV7,0) -> #DIV/0!
A8: 3 | C8: =IF(+B8-B7>0,B8-B7,(B8-B7)>0)*800 -> 0 | E8: =IF(+D8-D7>0,D8-D7,(D8-D7)>0)*80 -> 0 | G8: =IF(+F8-F7>0,F8-F7,(F8-F7)>0)*10 -> 0 | H8: 57 | I8: 22763354 | J8: =IF(I8>=I7,I8-I7,0) -> 6025 | K8: =M8+O8 -> 2722 | L8: 221667 | M8: =IF(L8>=L7,L8-L7,0) -> 1537 | N8: 231682 | O8: =IF(N8>=N7,N8-N7,0) -> 1185 | P8: 217675 | Q8: =IF(P8>=P7,P8-P7,0)*30 -> 510 | R8: 152762 | S8: =IF(R8>=R7,R8-R7,0) -> 121 | T8: 277716 | U8: =IF(T8>=T7,T8-T7,0) -> 241 | V8: 921141 | W8: =IF(V8>=V7,V8-V7,0)*0.53 -> 2322.46 | X8: 557335 | Y8: =IF(X8>=X7,X8-X7,0)*0.53 -> 3174.17 | Z8: 748350 | AA8: =IF(Z8>=Z7,Z8-Z7,0)*0.53 -> 0 | AB8: 333452 | AC8: =IF(AB8>=AB7,AB8-AB7,0)*0.53 -> 0 | AD8: 378543 | AE8: =IF(AD8>=AD7,AD8-AD7,0)*0.53 -> 10.6 | AF8: 805856 | AG8: =IF(AF8>=AF7,AF8-AF7,0)*0.53 -> 1565.62 | AH8: 714187 | AI8: =IF(AH8>=AH7,AH8-AH7,0)*0.53 -> 944.46 | AJ8: 512724 | AK8: =IF(AJ8>=AJ7,AJ8-AJ7,0)*0.53 -> 2957.4 | AL8: 428489 | AM8: =IF(AL8>=AL7,AL8-AL7,0)*0.53 -> 136.21 | AN8: =W8+Y8+AA8+AC8+AE8+AG8+AI8+AK8+AM8 -> 11110.92 | AO8: 7375953 | AP8: =IF(AO8>=AO7,AO8-AO7,0)*0.1125 -> 189.1125 | AQ8: 620002 | AR8: =IF(AQ8>=AQ7,AQ8-AQ7,0) -> 288 | AS8: 932699 | AT8: =IF(AS8>=AS7,AS8-AS7,0) -> 162 | AU8: 800502 | AV8: =IF(AU8>=AU7,AU8-AU7,0) -> 28 | AW8: 2436218 | AX8: =IF(AW8>=AW7,AW8-AW7,0) -> 874 | AY8: 217376 | AZ8: =IF(AY8>=AY7,AY8-AY7,0) -> 66 | BA8: 18271706 | BB8: =IF(BA8>=BA7,BA8-BA7,0) -> 4981 | BC8: 518384 | BD8: =IF(BC8>=BC7,BC8-BC7,0) -> 183 | BE8: 12654 | BF8: =IF(BE8>=BE7,BE8-BE7,0) -> 153 | BG8: 22788829 | BH8: =IF(BG8>=BG7,BG8-BG7,0)-(0.45*BN8)-(0.45*BP8)-BR8 -> 5043.8 | BI8: =AP8+AR8+AT8+AV8+AX8+AZ8+BB8+BD8+BF8+BH8 -> 11967.913 | BJ8: =BI8+AN8 -> 23078.833 | BK8: 1393438 | BL8: =IF(BK8>=BK7,BK8-BK7,0) -> 48 | BM8: 3663518 | BN8: =IF(BM8>=BM7,BM8-BM7,0) -> 1174 | BO8: 389248 | BP8: =IF(BO8>=BO7,BO8-BO7,0) -> 82 | BQ8: 483305 | BR8: =IF(BQ8>=BQ7,BQ8-BQ7,0) -> 168 | BS8: =J8+Q8+AN8+BI8 -> 29613.832 | BT8: 177 | BU8: =IF(BS8>0,BS8/BT7,0) -> 143.06199 | BW8: =IF(BS8>0,BS8/BV8,0) -> #DIV/0! | BX8: =((BS8-Q8)*$BZ$1)+(Q8*$BR$1) -> 34285.407 | BY8: =IF(BX8>0,BX8/BT7,0) -> 165.62999 | BZ8: =IF(BX8>0,BX8/BV8,0) -> #DIV/0!
A9: 4 | C9: =IF(+B9-B8>0,B9-B8,(B9-B8)>0)*800 -> 0 | E9: =IF(+D9-D8>0,D9-D8,(D9-D8)>0)*80 -> 0 | G9: =IF(+F9-F8>0,F9-F8,(F9-F8)>0)*10 -> 0 | I9: 22768483 | J9: =IF(I9>=I8,I9-I8,0) -> 5129 | K9: =M9+O9 -> 3304 | L9: 223571 | M9: =IF(L9>=L8,L9-L8,0) -> 1904 | N9: 233082 | O9: =IF(N9>=N8,N9-N8,0) -> 1400 | P9: 217692 | Q9: =IF(P9>=P8,P9-P8,0)*30 -> 510 | R9: 152892 | S9: =IF(R9>=R8,R9-R8,0) -> 130 | T9: 277967 | U9: =IF(T9>=T8,T9-T8,0) -> 251 | V9: 925973 | W9: =IF(V9>=V8,V9-V8,0)*0.53 -> 2560.96 | X9: 564468 | Y9: =IF(X9>=X8,X9-X8,0)*0.53 -> 3780.49 | Z9: 749148 | AA9: =IF(Z9>=Z8,Z9-Z8,0)*0.53 -> 422.94 | AB9: 333452 | AC9: =IF(AB9>=AB8,AB9-AB8,0)*0.53 -> 0 | AD9: 378564 | AE9: =IF(AD9>=AD8,AD9-AD8,0)*0.53 -> 11.13 | AF9: 808940 | AG9: =IF(AF9>=AF8,AF9-AF8,0)*0.53 -> 1634.52 | AH9: 716349 | AI9: =IF(AH9>=AH8,AH9-AH8,0)*0.53 -> 1145.86 | AJ9: 519847 | AK9: =IF(AJ9>=AJ8,AJ9-AJ8,0)*0.53 -> 3775.19 | AL9: 428799 | AM9: =IF(AL9>=AL8,AL9-AL8,0)*0.53 -> 164.3 | AN9: =W9+Y9+AA9+AC9+AE9+AG9+AI9+AK9+AM9 -> 13495.39 | AO9: 7377751 | AP9: =IF(AO9>=AO8,AO9-AO8,0)*0.1125 -> 202.275 | AQ9: 620285 | AR9: =IF(AQ9>=AQ8,AQ9-AQ8,0) -> 283 | AS9: 932864 | AT9: =IF(AS9>=AS8,AS9-AS8,0) -> 165 | AU9: 800544 | AV9: =IF(AU9>=AU8,AU9-AU8,0) -> 42 | AW9: 2437259 | AX9: =IF(AW9>=AW8,AW9-AW8,0) -> 1041 | AY9: 217447 | AZ9: =IF(AY9>=AY8,AY9-AY8,0) -> 71 | BA9: 18276431 | BB9: =IF(BA9>=BA8,BA9-BA8,0) -> 4725 | BC9: 518574 | BD9: =IF(BC9>=BC8,BC9-BC8,0) -> 190 | BE9: 12761 | BF9: =IF(BE9>=BE8,BE9-BE8,0) -> 107 | BG9: 22795524 | BH9: =IF(BG9>=BG8,BG9-BG8,0)-(0.45*BN9)-(0.45*BP9)-BR9 -> 5812.4 | BI9: =AP9+AR9+AT9+AV9+AX9+AZ9+BB9+BD9+BF9+BH9 -> 12638.675 | BJ9: =BI9+AN9 -> 26134.065 | BK9: 1393496 | BL9: =IF(BK9>=BK8,BK9-BK8,0) -> 58 | BM9: 3664952 | BN9: =IF(BM9>=BM8,BM9-BM8,0) -> 1434 | BO9: 389342 | BP9: =IF(BO9>=BO8,BO9-BO8,0) -> 94 | BQ9: 483500 | BR9: =IF(BQ9>=BQ8,BQ9-BQ8,0) -> 195 | BS9: =J9+Q9+AN9+BI9 -> 31773.065 | BT9: 177 | BU9: =IF(BS9>0,BS9/BT8,0) -> 179.50884 | BW9: =IF(BS9>0,BS9/BV9,0) -> #DIV/0! | BX9: =((BS9-Q9)*$BZ$1)+(Q9*$BR$1) -> 36768.525 | BY9: =IF(BX9>0,BX9/BT8,0) -> 207.73178 | BZ9: =IF(BX9>0,BX9/BV9,0) -> #DIV/0!
A10: 5 | C10: =IF(+B10-B9>0,B10-B9,(B10-B9)>0)*800 -> 0 | E10: =IF(+D10-D9>0,D10-D9,(D10-D9)>0)*80 -> 0 | G10: =IF(+F10-F9>0,F10-F9,(F10-F9)>0)*10 -> 0 | H10: 58 | I10: 22773840 | J10: =IF(I10>=I9,I10-I9,0) -> 5357 | K10: =M10+O10 -> 3233 | L10: 225436 | M10: =IF(L10>=L9,L10-L9,0) -> 1865 | N10: 234450 | O10: =IF(N10>=N9,N10-N9,0) -> 1368 | P10: 217710 | Q10: =IF(P10>=P9,P10-P9,0)*30 -> 540 | R10: 153028 | S10: =IF(R10>=R9,R10-R9,0) -> 136 | T10: 278238 | U10: =IF(T10>=T9,T10-T9,0) -> 271 | V10: 930336 | W10: =IF(V10>=V9,V10-V9,0)*0.53 -> 2312.39 | X10: 571537 | Y10: =IF(X10>=X9,X10-X9,0)*0.53 -> 3746.57 | Z10: 749148 | AA10: =IF(Z10>=Z9,Z10-Z9,0)*0.53 -> 0 | AB10: 333452 | AC10: =IF(AB10>=AB9,AB10-AB9,0)*0.53 -> 0 | AD10: 378586 | AE10: =IF(AD10>=AD9,AD10-AD9,0)*0.53 -> 11.66 | AF10: 811955 | AG10: =IF(AF10>=AF9,AF10-AF9,0)*0.53 -> 1597.95 | AH10: 718356 | AI10: =IF(AH10>=AH9,AH10-AH9,0)*0.53 -> 1063.71 | AJ10: 526678 | AK10: =IF(AJ10>=AJ9,AJ10-AJ9,0)*0.53 -> 3620.43 | AL10: 429102 | AM10: =IF(AL10>=AL9,AL10-AL9,0)*0.53 -> 160.59 | AN10: =W10+Y10+AA10+AC10+AE10+AG10+AI10+AK10+AM10 -> 12513.3 | AO10: 7379521 | AP10: =IF(AO10>=AO9,AO10-AO9,0)*0.1125 -> 199.125 | AQ10: 620525 | AR10: =IF(AQ10>=AQ9,AQ10-AQ9,0) -> 240 | AS10: 933027 | AT10: =IF(AS10>=AS9,AS10-AS9,0) -> 163 | AU10: 800589 | AV10: =IF(AU10>=AU9,AU10-AU9,0) -> 45 | AW10: 2438314 | AX10: =IF(AW10>=AW9,AW10-AW9,0) -> 1055 | AY10: 217512 | AZ10: =IF(AY10>=AY9,AY10-AY9,0) -> 65 | BA10: 18281295 | BB10: =IF(BA10>=BA9,BA10-BA9,0) -> 4864 | BC10: 518772 | BD10: =IF(BC10>=BC9,BC10-BC9,0) -> 198 | BE10: 12873 | BF10: =IF(BE10>=BE9,BE10-BE9,0) -> 112 | BG10: 22802163 | BH10: =IF(BG10>=BG9,BG10-BG9,0)-(0.45*BN10)-(0.45*BP10)-BR10 -> 6638.55 | BI10: =AP10+AR10+AT10+AV10+AX10+AZ10+BB10+BD10+BF10+BH10 -> 13579.675 | BJ10: =BI10+AN10 -> 26092.975 | BK10: 1393557 | BL10: =IF(BK10>=BK9,BK10-BK9,0) -> 61 | BM10: 3664953 | BN10: =IF(BM10>=BM9,BM10-BM9,0) -> 1 | BO10: 389342 | BP10: =IF(BO10>=BO9,BO10-BO9,0) -> 0 | BQ10: 483500 | BR10: =IF(BQ10>=BQ9,BQ10-BQ9,0) -> 0 | BS10: =J10+Q10+AN10+BI10 -> 31989.975 | BT10: 173 | BU10: =IF(BS10>0,BS10/BT9,0) -> 180.73432 | BW10: =IF(BS10>0,BS10/BV10,0) -> #DIV/0! | BX10: =((BS10-Q10)*$BZ$1)+(Q10*$BR$1) -> 37031.471 | BY10: =IF(BX10>0,BX10/BT9,0) -> 209.21735 | BZ10: =IF(BX10>0,BX10/BV10,0) -> #DIV/0!
A11: 6 | C11: =IF(+B11-B10>0,B11-B10,(B11-B10)>0)*800 -> 0 | E11: =IF(+D11-D10>0,D11-D10,(D11-D10)>0)*80 -> 0 | G11: =IF(+F11-F10>0,F11-F10,(F11-F10)>0)*10 -> 0 | I11: 22779378 | J11: =IF(I11>=I10,I11-I10,0) -> 5538 | K11: =M11+O11 -> 3491 | L11: 227429 | M11: =IF(L11>=L10,L11-L10,0) -> 1993 | N11: 235948 | O11: =IF(N11>=N10,N11-N10,0) -> 1498 | P11: 217728 | Q11: =IF(P11>=P10,P11-P10,0)*30 -> 540 | R11: 153164 | S11: =IF(R11>=R10,R11-R10,0) -> 136 | T11: 278505 | U11: =IF(T11>=T10,T11-T10,0) -> 267 | V11: 935325 | W11: =IF(V11>=V10,V11-V10,0)*0.53 -> 2644.17 | X11: 578943 | Y11: =IF(X11>=X10,X11-X10,0)*0.53 -> 3925.18 | Z11: 749148 | AA11: =IF(Z11>=Z10,Z11-Z10,0)*0.53 -> 0 | AB11: 333452 | AC11: =IF(AB11>=AB10,AB11-AB10,0)*0.53 -> 0 | AD11: 378607 | AE11: =IF(AD11>=AD10,AD11-AD10,0)*0.53 -> 11.13 | AF11: 815091 | AG11: =IF(AF11>=AF10,AF11-AF10,0)*0.53 -> 1662.08 | AH11: 720321 | AI11: =IF(AH11>=AH10,AH11-AH10,0)*0.53 -> 1041.45 | AJ11: 533956 | AK11: =IF(AJ11>=AJ10,AJ11-AJ10,0)*0.53 -> 3857.34 | AL11: 429407 | AM11: =IF(AL11>=AL10,AL11-AL10,0)*0.53 -> 161.65 | AN11: =W11+Y11+AA11+AC11+AE11+AG11+AI11+AK11+AM11 -> 13303 | AO11: 7381340 | AP11: =IF(AO11>=AO10,AO11-AO10,0)*0.1125 -> 204.6375 | AQ11: 620690 | AR11: =IF(AQ11>=AQ10,AQ11-AQ10,0) -> 165 | AS11: 933179 | AT11: =IF(AS11>=AS10,AS11-AS10,0) -> 152 | AU11: 800649 | AV11: =IF(AU11>=AU10,AU11-AU10,0) -> 60 | AW11: 2439410 | AX11: =IF(AW11>=AW10,AW11-AW10,0) -> 1096 | AY11: 217567 | AZ11: =IF(AY11>=AY10,AY11-AY10,0) -> 55 | BA11: 18286278 | BB11: =IF(BA11>=BA10,BA11-BA10,0) -> 4983 | BC11: 518971 | BD11: =IF(BC11>=BC10,BC11-BC10,0) -> 199 | BE11: 12984 | BF11: =IF(BE11>=BE10,BE11-BE10,0) -> 111 | BG11: 22809028 | BH11: =IF(BG11>=BG10,BG11-BG10,0)-(0.45*BN11)-(0.45*BP11)-BR11 -> 5929.5 | BI11: =AP11+AR11+AT11+AV11+AX11+AZ11+BB11+BD11+BF11+BH11 -> 12955.138 | BJ11: =BI11+AN11 -> 26258.138 | BK11: 1393615 | BL11: =IF(BK11>=BK10,BK11-BK10,0) -> 58 | BM11: 3666478 | BN11: =IF(BM11>=BM10,BM11-BM10,0) -> 1525 | BO11: 389447 | BP11: =IF(BO11>=BO10,BO11-BO10,0) -> 105 | BQ11: 483702 | BR11: =IF(BQ11>=BQ10,BQ11-BQ10,0) -> 202 | BS11: =J11+Q11+AN11+BI11 -> 32336.138 | BT11: 158 | BU11: =IF(BS11>0,BS11/BT10,0) -> 186.91409 | BW11: =IF(BS11>0,BS11/BV11,0) -> #DIV/0! | BX11: =((BS11-Q11)*$BZ$1)+(Q11*$BR$1) -> 37429.558 | BY11: =IF(BX11>0,BX11/BT10,0) -> 216.35583 | BZ11: =IF(BX11>0,BX11/BV11,0) -> #DIV/0!
A12: 7 | C12: =IF(+B12-B11>0,B12-B11,(B12-B11)>0)*800 -> 0 | E12: =IF(+D12-D11>0,D12-D11,(D12-D11)>0)*80 -> 0 | G12: =IF(+F12-F11>0,F12-F11,(F12-F11)>0)*10 -> 0 | H12: 59 | I12: 22785294 | J12: =IF(I12>=I11,I12-I11,0) -> 5916 | K12: =M12+O12 -> 3810 | L12: 229511 | M12: =IF(L12>=L11,L12-L11,0) -> 2082 | N12: 237676 | O12: =IF(N12>=N11,N12-N11,0) -> 1728 | P12: 217746 | Q12: =IF(P12>=P11,P12-P11,0)*30 -> 540 | R12: 153306 | S12: =IF(R12>=R11,R12-R11,0) -> 142 | T12: 278788 | U12: =IF(T12>=T11,T12-T11,0) -> 283 | V12: 940516 | W12: =IF(V12>=V11,V12-V11,0)*0.53 -> 2751.23 | X12: 585521 | Y12: =IF(X12>=X11,X12-X11,0)*0.53 -> 3486.34 | Z12: 749349 | AA12: =IF(Z12>=Z11,Z12-Z11,0)*0.53 -> 106.53 | AB12: 333452 | AC12: =IF(AB12>=AB11,AB12-AB11,0)*0.53 -> 0 | AD12: 380192 | AE12: =IF(AD12>=AD11,AD12-AD11,0)*0.53 -> 840.05 | AF12: 818436 | AG12: =IF(AF12>=AF11,AF12-AF11,0)*0.53 -> 1772.85 | AH12: 722563 | AI12: =IF(AH12>=AH11,AH12-AH11,0)*0.53 -> 1188.26 | AJ12: 541498 | AK12: =IF(AJ12>=AJ11,AJ12-AJ11,0)*0.53 -> 3997.26 | AL12: 429694 | AM12: =IF(AL12>=AL11,AL12-AL11,0)*0.53 -> 152.11 | AN12: =W12+Y12+AA12+AC12+AE12+AG12+AI12+AK12+AM12 -> 14294.63 | AO12: 7383029 | AP12: =IF(AO12>=AO11,AO12-AO11,0)*0.1125 -> 190.0125 | AQ12: 620917 | AR12: =IF(AQ12>=AQ11,AQ12-AQ11,0) -> 227 | AS12: 933335 | AT12: =IF(AS12>=AS11,AS12-AS11,0) -> 156 | AU12: 800712 | AV12: =IF(AU12>=AU11,AU12-AU11,0) -> 63 | AW12: 2440534 | AX12: =IF(AW12>=AW11,AW12-AW11,0) -> 1124 | AY12: 217623 | AZ12: =IF(AY12>=AY11,AY12-AY11,0) -> 56 | BA12: 18291275 | BB12: =IF(BA12>=BA11,BA12-BA11,0) -> 4997 | BC12: 519170 | BD12: =IF(BC12>=BC11,BC12-BC11,0) -> 199 | BE12: 13093 | BF12: =IF(BE12>=BE11,BE12-BE11,0) -> 109 | BG12: 22816301 | BH12: =IF(BG12>=BG11,BG12-BG11,0)-(0.45*BN12)-(0.45*BP12)-BR12 -> 6321.75 | BI12: =AP12+AR12+AT12+AV12+AX12+AZ12+BB12+BD12+BF12+BH12 -> 13442.763 | BJ12: =BI12+AN12 -> 27737.393 | BK12: 1393674 | BL12: =IF(BK12>=BK11,BK12-BK11,0) -> 59 | BM12: 3668013 | BN12: =IF(BM12>=BM11,BM12-BM11,0) -> 1535 | BO12: 389557 | BP12: =IF(BO12>=BO11,BO12-BO11,0) -> 110 | BQ12: 483913 | BR12: =IF(BQ12>=BQ11,BQ12-BQ11,0) -> 211 | BS12: =J12+Q12+AN12+BI12 -> 34193.393 | BT12: 171 | BU12: =IF(BS12>0,BS12/BT11,0) -> 216.41388 | BW12: =IF(BS12>0,BS12/BV12,0) -> #DIV/0! | BX12: =((BS12-Q12)*$BZ$1)+(Q12*$BR$1) -> 39565.401 | BY12: =IF(BX12>0,BX12/BT11,0) -> 250.41393 | BZ12: =IF(BX12>0,BX12/BV12,0) -> #DIV/0!
A13: 8 | C13: =IF(+B13-B12>0,B13-B12,(B13-B12)>0)*800 -> 0 | E13: =IF(+D13-D12>0,D13-D12,(D13-D12)>0)*80 -> 0 | G13: =IF(+F13-F12>0,F13-F12,(F13-F12)>0)*10 -> 0 | I13: 22790828 | J13: =IF(I13>=I12,I13-I12,0) -> 5534 | K13: =M13+O13 -> 3399 | L13: 231416 | M13: =IF(L13>=L12,L13-L12,0) -> 1905 | N13: 239170 | O13: =IF(N13>=N12,N13-N12,0) -> 1494 | P13: 217764 | Q13: =IF(P13>=P12,P13-P12,0)*30 -> 540 | R13: 153446 | S13: =IF(R13>=R12,R13-R12,0) -> 140 | T13: 279069 | U13: =IF(T13>=T12,T13-T12,0) -> 281 | V13: 946052 | W13: =IF(V13>=V12,V13-V12,0)*0.53 -> 2934.08 | X13: 589303 | Y13: =IF(X13>=X12,X13-X12,0)*0.53 -> 2004.46 | Z13: 754480 | AA13: =IF(Z13>=Z12,Z13-Z12,0)*0.53 -> 2719.43 | AB13: 333452 | AC13: =IF(AB13>=AB12,AB13-AB12,0)*0.53 -> 0 | AD13: 380214 | AE13: =IF(AD13>=AD12,AD13-AD12,0)*0.53 -> 11.66 | AF13: 821864 | AG13: =IF(AF13>=AF12,AF13-AF12,0)*0.53 -> 1816.84 | AH13: 724721 | AI13: =IF(AH13>=AH12,AH13-AH12,0)*0.53 -> 1143.74 | AJ13: 549349 | AK13: =IF(AJ13>=AJ12,AJ13-AJ12,0)*0.53 -> 4161.03 | AL13: 430050 | AM13: =IF(AL13>=AL12,AL13-AL12,0)*0.53 -> 188.68 | AN13: =W13+Y13+AA13+AC13+AE13+AG13+AI13+AK13+AM13 -> 14979.92 | AO13: 7384801 | AP13: =IF(AO13>=AO12,AO13-AO12,0)*0.1125 -> 199.35 | AQ13: 621120 | AR13: =IF(AQ13>=AQ12,AQ13-AQ12,0) -> 203 | AS13: 933484 | AT13: =IF(AS13>=AS12,AS13-AS12,0) -> 149 | AU13: 800765 | AV13: =IF(AU13>=AU12,AU13-AU12,0) -> 53 | AW13: 2441519 | AX13: =IF(AW13>=AW12,AW13-AW12,0) -> 985 | AY13: 217697 | AZ13: =IF(AY13>=AY12,AY13-AY12,0) -> 74 | BA13: 18295751 | BB13: =IF(BA13>=BA12,BA13-BA12,0) -> 4476 | BC13: 519352 | BD13: =IF(BC13>=BC12,BC13-BC12,0) -> 182 | BE13: 13224 | BF13: =IF(BE13>=BE12,BE13-BE12,0) -> 131 | BG13: 22822892 | BH13: =IF(BG13>=BG12,BG13-BG12,0)-(0.45*BN13)-(0.45*BP13)-BR13 -> 5672.8 | BI13: =AP13+AR13+AT13+AV13+AX13+AZ13+BB13+BD13+BF13+BH13 -> 12125.15 | BJ13: =BI13+AN13 -> 27105.07 | BK13: 1393734 | BL13: =IF(BK13>=BK12,BK13-BK12,0) -> 60 | BM13: 3669474 | BN13: =IF(BM13>=BM12,BM13-BM12,0) -> 1461 | BO13: 389672 | BP13: =IF(BO13>=BO12,BO13-BO12,0) -> 115 | BQ13: 484122 | BR13: =IF(BQ13>=BQ12,BQ13-BQ12,0) -> 209 | BS13: =J13+Q13+AN13+BI13 -> 33179.07 | BT13: 195 | BU13: =IF(BS13>0,BS13/BT12,0) -> 194.02965 | BW13: =IF(BS13>0,BS13/BV13,0) -> #DIV/0! | BX13: =((BS13-Q13)*$BZ$1)+(Q13*$BR$1) -> 38398.931 | BY13: =IF(BX13>0,BX13/BT12,0) -> 224.55515 | BZ13: =IF(BX13>0,BX13/BV13,0) -> #DIV/0!
A14: 9 | C14: =IF(+B14-B13>0,B14-B13,(B14-B13)>0)*800 -> 0 | E14: =IF(+D14-D13>0,D14-D13,(D14-D13)>0)*80 -> 0 | G14: =IF(+F14-F13>0,F14-F13,(F14-F13)>0)*10 -> 0 | H14: 60 | I14: 22797292 | J14: =IF(I14>=I13,I14-I13,0) -> 6464 | K14: =M14+O14 -> 3403 | L14: 233394 | M14: =IF(L14>=L13,L14-L13,0) -> 1978 | N14: 240595 | O14: =IF(N14>=N13,N14-N13,0) -> 1425 | P14: 217782 | Q14: =IF(P14>=P13,P14-P13,0)*30 -> 540 | R14: 153582 | S14: =IF(R14>=R13,R14-R13,0) -> 136 | T14: 279341 | U14: =IF(T14>=T13,T14-T13,0) -> 272 | V14: 951108 | W14: =IF(V14>=V13,V14-V13,0)*0.53 -> 2679.68 | X14: 589303 | Y14: =IF(X14>=X13,X14-X13,0)*0.53 -> 0 | Z14: 761912 | AA14: =IF(Z14>=Z13,Z14-Z13,0)*0.53 -> 3938.96 | AB14: 333452 | AC14: =IF(AB14>=AB13,AB14-AB13,0)*0.53 -> 0 | AD14: 380235 | AE14: =IF(AD14>=AD13,AD14-AD13,0)*0.53 -> 11.13 | AF14: 825196 | AG14: =IF(AF14>=AF13,AF14-AF13,0)*0.53 -> 1765.96 | AH14: 726876 | AI14: =IF(AH14>=AH13,AH14-AH13,0)*0.53 -> 1142.15 | AJ14: 557623 | AK14: =IF(AJ14>=AJ13,AJ14-AJ13,0)*0.53 -> 4385.22 | AL14: 430364 | AM14: =IF(AL14>=AL13,AL14-AL13,0)*0.53 -> 166.42 | AN14: =W14+Y14+AA14+AC14+AE14+AG14+AI14+AK14+AM14 -> 14089.52 | AO14: 7386535 | AP14: =IF(AO14>=AO13,AO14-AO13,0)*0.1125 -> 195.075 | AQ14: 621427 | AR14: =IF(AQ14>=AQ13,AQ14-AQ13,0) -> 307 | AS14: 933634 | AT14: =IF(AS14>=AS13,AS14-AS13,0) -> 150 | AU14: 800796 | AV14: =IF(AU14>=AU13,AU14-AU13,0) -> 31 | AW14: 2442484 | AX14: =IF(AW14>=AW13,AW14-AW13,0) -> 965 | AY14: 217769 | AZ14: =IF(AY14>=AY13,AY14-AY13,0) -> 72 | BA14: 18300221 | BB14: =IF(BA14>=BA13,BA14-BA13,0) -> 4470 | BC14: 519536 | BD14: =IF(BC14>=BC13,BC14-BC13,0) -> 184 | BE14: 13355 | BF14: =IF(BE14>=BE13,BE14-BE13,0) -> 131 | BG14: 22829187 | BH14: =IF(BG14>=BG13,BG14-BG13,0)-(0.45*BN14)-(0.45*BP14)-BR14 -> 5414.1 | BI14: =AP14+AR14+AT14+AV14+AX14+AZ14+BB14+BD14+BF14+BH14 -> 11919.175 | BJ14: =BI14+AN14 -> 26008.695 | BK14: 1393792 | BL14: =IF(BK14>=BK13,BK14-BK13,0) -> 58 | BM14: 3670866 | BN14: =IF(BM14>=BM13,BM14-BM13,0) -> 1392 | BO14: 389782 | BP14: =IF(BO14>=BO13,BO14-BO13,0) -> 110 | BQ14: 484327 | BR14: =IF(BQ14>=BQ13,BQ14-BQ13,0) -> 205 | BS14: =J14+Q14+AN14+BI14 -> 33012.695 | BT14: 178 | BU14: =IF(BS14>0,BS14/BT13,0) -> 169.29587 | BW14: =IF(BS14>0,BS14/BV14,0) -> #DIV/0! | BX14: =((BS14-Q14)*$BZ$1)+(Q14*$BR$1) -> 38207.599 | BY14: =IF(BX14>0,BX14/BT13,0) -> 195.93641 | BZ14: =IF(BX14>0,BX14/BV14,0) -> #DIV/0!
A15: 10 | C15: =IF(+B15-B14>0,B15-B14,(B15-B14)>0)*800 -> 0 | E15: =IF(+D15-D14>0,D15-D14,(D15-D14)>0)*80 -> 0 | G15: =IF(+F15-F14>0,F15-F14,(F15-F14)>0)*10 -> 0 | I15: 22801773 | J15: =IF(I15>=I14,I15-I14,0) -> 4481 | K15: =M15+O15 -> 4377 | L15: 235273 | M15: =IF(L15>=L14,L15-L14,0) -> 1879 | N15: 243093 | O15: =IF(N15>=N14,N15-N14,0) -> 2498 | P15: 217799 | Q15: =IF(P15>=P14,P15-P14,0)*30 -> 510 | R15: 153726 | S15: =IF(R15>=R14,R15-R14,0) -> 144 | T15: 279632 | U15: =IF(T15>=T14,T15-T14,0) -> 291 | V15: 956833 | W15: =IF(V15>=V14,V15-V14,0)*0.53 -> 3034.25 | X15: 589303 | Y15: =IF(X15>=X14,X15-X14,0)*0.53 -> 0 | Z15: 769544 | AA15: =IF(Z15>=Z14,Z15-Z14,0)*0.53 -> 4044.96 | AB15: 333452 | AC15: =IF(AB15>=AB14,AB15-AB14,0)*0.53 -> 0 | AD15: 382049 | AE15: =IF(AD15>=AD14,AD15-AD14,0)*0.53 -> 961.42 | AF15: 826845 | AG15: =IF(AF15>=AF14,AF15-AF14,0)*0.53 -> 873.97 | AH15: 729040 | AI15: =IF(AH15>=AH14,AH15-AH14,0)*0.53 -> 1146.92 | AJ15: 565957 | AK15: =IF(AJ15>=AJ14,AJ15-AJ14,0)*0.53 -> 4417.02 | AL15: 430680 | AM15: =IF(AL15>=AL14,AL15-AL14,0)*0.53 -> 167.48 | AN15: =W15+Y15+AA15+AC15+AE15+AG15+AI15+AK15+AM15 -> 14646.02 | AO15: 7388206 | AP15: =IF(AO15>=AO14,AO15-AO14,0)*0.1125 -> 187.9875 | AQ15: 621655 | AR15: =IF(AQ15>=AQ14,AQ15-AQ14,0) -> 228 | AS15: 933786 | AT15: =IF(AS15>=AS14,AS15-AS14,0) -> 152 | AU15: 800833 | AV15: =IF(AU15>=AU14,AU15-AU14,0) -> 37 | AW15: 2443450 | AX15: =IF(AW15>=AW14,AW15-AW14,0) -> 966 | AY15: 217846 | AZ15: =IF(AY15>=AY14,AY15-AY14,0) -> 77 | BA15: 18304829 | BB15: =IF(BA15>=BA14,BA15-BA14,0) -> 4608 | BC15: 519727 | BD15: =IF(BC15>=BC14,BC15-BC14,0) -> 191 | BE15: 13486 | BF15: =IF(BE15>=BE14,BE15-BE14,0) -> 131 | BG15: 22836029 | BH15: =IF(BG15>=BG14,BG15-BG14,0)-(0.45*BN15)-(0.45*BP15)-BR15 -> 5897.45 | BI15: =AP15+AR15+AT15+AV15+AX15+AZ15+BB15+BD15+BF15+BH15 -> 12475.438 | BJ15: =BI15+AN15 -> 27121.458 | BK15: 1393853 | BL15: =IF(BK15>=BK14,BK15-BK14,0) -> 61 | BM15: 3672374 | BN15: =IF(BM15>=BM14,BM15-BM14,0) -> 1508 | BO15: 389893 | BP15: =IF(BO15>=BO14,BO15-BO14,0) -> 111 | BQ15: 484543 | BR15: =IF(BQ15>=BQ14,BQ15-BQ14,0) -> 216 | BS15: =J15+Q15+AN15+BI15 -> 32112.458 | BT15: 135 | BU15: =IF(BS15>0,BS15/BT14,0) -> 180.40706 | BW15: =IF(BS15>0,BS15/BV15,0) -> #DIV/0! | BX15: =((BS15-Q15)*$BZ$1)+(Q15*$BR$1) -> 37158.826 | BY15: =IF(BX15>0,BX15/BT14,0) -> 208.75745 | BZ15: =IF(BX15>0,BX15/BV15,0) -> #DIV/0!
A16: 11 | C16: =IF(+B16-B15>0,B16-B15,(B16-B15)>0)*800 -> 0 | E16: =IF(+D16-D15>0,D16-D15,(D16-D15)>0)*80 -> 0 | G16: =IF(+F16-F15>0,F16-F15,(F16-F15)>0)*10 -> 0 | H16: 61 | I16: 22806918 | J16: =IF(I16>=I15,I16-I15,0) -> 5145 | K16: =M16+O16 -> 3405 | L16: 237137 | M16: =IF(L16>=L15,L16-L15,0) -> 1864 | N16: 244634 | O16: =IF(N16>=N15,N16-N15,0) -> 1541 | P16: 217816 | Q16: =IF(P16>=P15,P16-P15,0)*30 -> 510 | R16: 153858 | S16: =IF(R16>=R15,R16-R15,0) -> 132 | T16: 279899 | U16: =IF(T16>=T15,T16-T15,0) -> 267 | V16: 961773 | W16: =IF(V16>=V15,V16-V15,0)*0.53 -> 2618.2 | X16: 591704 | Y16: =IF(X16>=X15,X16-X15,0)*0.53 -> 1272.53 | Z16: 776815 | AA16: =IF(Z16>=Z15,Z16-Z15,0)*0.53 -> 3853.63 | AB16: 333452 | AC16: =IF(AB16>=AB15,AB16-AB15,0)*0.53 -> 0 | AD16: 385361 | AE16: =IF(AD16>=AD15,AD16-AD15,0)*0.53 -> 1755.36 | AF16: 826865 | AG16: =IF(AF16>=AF15,AF16-AF15,0)*0.53 -> 10.6 | AH16: 731225 | AI16: =IF(AH16>=AH15,AH16-AH15,0)*0.53 -> 1158.05 | AJ16: 574012 | AK16: =IF(AJ16>=AJ15,AJ16-AJ15,0)*0.53 -> 4269.15 | AL16: 430999 | AM16: =IF(AL16>=AL15,AL16-AL15,0)*0.53 -> 169.07 | AN16: =W16+Y16+AA16+AC16+AE16+AG16+AI16+AK16+AM16 -> 15106.59 | AO16: 7389949 | AP16: =IF(AO16>=AO15,AO16-AO15,0)*0.1125 -> 196.0875 | AQ16: 621918 | AR16: =IF(AQ16>=AQ15,AQ16-AQ15,0) -> 263 | AS16: 933947 | AT16: =IF(AS16>=AS15,AS16-AS15,0) -> 161 | AU16: 800892 | AV16: =IF(AU16>=AU15,AU16-AU15,0) -> 59 | AW16: 2444426 | AX16: =IF(AW16>=AW15,AW16-AW15,0) -> 976 | AY16: 217917 | AZ16: =IF(AY16>=AY15,AY16-AY15,0) -> 71 | BA16: 18309423 | BB16: =IF(BA16>=BA15,BA16-BA15,0) -> 4594 | BC16: 519908 | BD16: =IF(BC16>=BC15,BC16-BC15,0) -> 181 | BE16: 13595 | BF16: =IF(BE16>=BE15,BE16-BE15,0) -> 109 | BG16: 22842682 | BH16: =IF(BG16>=BG15,BG16-BG15,0)-(0.45*BN16)-(0.45*BP16)-BR16 -> 5717.75 | BI16: =AP16+AR16+AT16+AV16+AX16+AZ16+BB16+BD16+BF16+BH16 -> 12327.837 | BJ16: =BI16+AN16 -> 27434.427 | BK16: 1393912 | BL16: =IF(BK16>=BK15,BK16-BK15,0) -> 59 | BM16: 3673898 | BN16: =IF(BM16>=BM15,BM16-BM15,0) -> 1524 | BO16: 389994 | BP16: =IF(BO16>=BO15,BO16-BO15,0) -> 101 | BQ16: 484747 | BR16: =IF(BQ16>=BQ15,BQ16-BQ15,0) -> 204 | BS16: =J16+Q16+AN16+BI16 -> 33089.427 | BT16: 123 | BU16: =IF(BS16>0,BS16/BT15,0) -> 245.10687 | BW16: =IF(BS16>0,BS16/BV16,0) -> #DIV/0! | BX16: =((BS16-Q16)*$BZ$1)+(Q16*$BR$1) -> 38282.342 | BY16: =IF(BX16>0,BX16/BT15,0) -> 283.5729 | BZ16: =IF(BX16>0,BX16/BV16,0) -> #DIV/0!
A17: 12 | C17: =IF(+B17-B16>0,B17-B16,(B17-B16)>0)*800 -> 0 | E17: =IF(+D17-D16>0,D17-D16,(D17-D16)>0)*80 -> 0 | G17: =IF(+F17-F16>0,F17-F16,(F17-F16)>0)*10 -> 0 | I17: 22812090 | J17: =IF(I17>=I16,I17-I16,0) -> 5172 | K17: =M17+O17 -> 3251 | L17: 238933 | M17: =IF(L17>=L16,L17-L16,0) -> 1796 | N17: 246089 | O17: =IF(N17>=N16,N17-N16,0) -> 1455 | P17: 217832 | Q17: =IF(P17>=P16,P17-P16,0)*30 -> 480 | R17: 153995 | S17: =IF(R17>=R16,R17-R16,0) -> 137 | T17: 280174 | U17: =IF(T17>=T16,T17-T16,0) -> 275 | V17: 966161 | W17: =IF(V17>=V16,V17-V16,0)*0.53 -> 2325.64 | X17: 596011 | Y17: =IF(X17>=X16,X17-X16,0)*0.53 -> 2282.71 | Z17: 783057 | AA17: =IF(Z17>=Z16,Z17-Z16,0)*0.53 -> 3308.26 | AB17: 333452 | AC17: =IF(AB17>=AB16,AB17-AB16,0)*0.53 -> 0 | AD17: 388781 | AE17: =IF(AD17>=AD16,AD17-AD16,0)*0.53 -> 1812.6 | AF17: 826885 | AG17: =IF(AF17>=AF16,AF17-AF16,0)*0.53 -> 10.6 | AH17: 733357 | AI17: =IF(AH17>=AH16,AH17-AH16,0)*0.53 -> 1129.96 | AJ17: 582386 | AK17: =IF(AJ17>=AJ16,AJ17-AJ16,0)*0.53 -> 4438.22 | AL17: 431310 | AM17: =IF(AL17>=AL16,AL17-AL16,0)*0.53 -> 164.83 | AN17: =W17+Y17+AA17+AC17+AE17+AG17+AI17+AK17+AM17 -> 15472.82 | AO17: 7391698 | AP17: =IF(AO17>=AO16,AO17-AO16,0)*0.1125 -> 196.7625 | AQ17: 622090 | AR17: =IF(AQ17>=AQ16,AQ17-AQ16,0) -> 172 | AS17: 934101 | AT17: =IF(AS17>=AS16,AS17-AS16,0) -> 154 | AU17: 800955 | AV17: =IF(AU17>=AU16,AU17-AU16,0) -> 63 | AW17: 2445397 | AX17: =IF(AW17>=AW16,AW17-AW16,0) -> 971 | AY17: 217991 | AZ17: =IF(AY17>=AY16,AY17-AY16,0) -> 74 | BA17: 18314032 | BB17: =IF(BA17>=BA16,BA17-BA16,0) -> 4609 | BC17: 520084 | BD17: =IF(BC17>=BC16,BC17-BC16,0) -> 176 | BE17: 13706 | BF17: =IF(BE17>=BE16,BE17-BE16,0) -> 111 | BG17: 22849543 | BH17: =IF(BG17>=BG16,BG17-BG16,0)-(0.45*BN17)-(0.45*BP17)-BR17 -> 5871.65 | BI17: =AP17+AR17+AT17+AV17+AX17+AZ17+BB17+BD17+BF17+BH17 -> 12398.413 | BJ17: =BI17+AN17 -> 27871.233 | BK17: 1393969 | BL17: =IF(BK17>=BK16,BK17-BK16,0) -> 57 | BM17: 3675534 | BN17: =IF(BM17>=BM16,BM17-BM16,0) -> 1636 | BO17: 390101 | BP17: =IF(BO17>=BO16,BO17-BO16,0) -> 107 | BQ17: 484952 | BR17: =IF(BQ17>=BQ16,BQ17-BQ16,0) -> 205 | BS17: =J17+Q17+AN17+BI17 -> 33523.232 | BT17: 118 | BU17: =IF(BS17>0,BS17/BT16,0) -> 272.54661 | BW17: =IF(BS17>0,BS17/BV17,0) -> #DIV/0! | BX17: =((BS17-Q17)*$BZ$1)+(Q17*$BR$1) -> 38767.717 | BY17: =IF(BX17>0,BX17/BT16,0) -> 315.18469 | BZ17: =IF(BX17>0,BX17/BV17,0) -> #DIV/0!
A18: 13 | C18: =IF(+B18-B17>0,B18-B17,(B18-B17)>0)*800 -> 0 | E18: =IF(+D18-D17>0,D18-D17,(D18-D17)>0)*80 -> 0 | G18: =IF(+F18-F17>0,F18-F17,(F18-F17)>0)*10 -> 0 | H18: 62 | I18: 22817575 | J18: =IF(I18>=I17,I18-I17,0) -> 5485 | K18: =M18+O18 -> 3433 | L18: 240824 | M18: =IF(L18>=L17,L18-L17,0) -> 1891 | N18: 247631 | O18: =IF(N18>=N17,N18-N17,0) -> 1542 | P18: 217847 | Q18: =IF(P18>=P17,P18-P17,0)*30 -> 450 | R18: 154135 | S18: =IF(R18>=R17,R18-R17,0) -> 140 | T18: 280455 | U18: =IF(T18>=T17,T18-T17,0) -> 281 | V18: 970391 | W18: =IF(V18>=V17,V18-V17,0)*0.53 -> 2241.9 | X18: 601892 | Y18: =IF(X18>=X17,X18-X17,0)*0.53 -> 3116.93 | Z18: 787411 | AA18: =IF(Z18>=Z17,Z18-Z17,0)*0.53 -> 2307.62 | AB18: 333452 | AC18: =IF(AB18>=AB17,AB18-AB17,0)*0.53 -> 0 | AD18: 392172 | AE18: =IF(AD18>=AD17,AD18-AD17,0)*0.53 -> 1797.23 | AF18: 826905 | AG18: =IF(AF18>=AF17,AF18-AF17,0)*0.53 -> 10.6 | AH18: 735582 | AI18: =IF(AH18>=AH17,AH18-AH17,0)*0.53 -> 1179.25 | AJ18: 590631 | AK18: =IF(AJ18>=AJ17,AJ18-AJ17,0)*0.53 -> 4369.85 | AL18: 431631 | AM18: =IF(AL18>=AL17,AL18-AL17,0)*0.53 -> 170.13 | AN18: =W18+Y18+AA18+AC18+AE18+AG18+AI18+AK18+AM18 -> 15193.51 | AO18: 7393401 | AP18: =IF(AO18>=AO17,AO18-AO17,0)*0.1125 -> 191.5875 | AQ18: 622284 | AR18: =IF(AQ18>=AQ17,AQ18-AQ17,0) -> 194 | AS18: 934267 | AT18: =IF(AS18>=AS17,AS18-AS17,0) -> 166 | AU18: 801015 | AV18: =IF(AU18>=AU17,AU18-AU17,0) -> 60 | AW18: 2446338 | AX18: =IF(AW18>=AW17,AW18-AW17,0) -> 941 | AY18: 218068 | AZ18: =IF(AY18>=AY17,AY18-AY17,0) -> 77 | BA18: 18319081 | BB18: =IF(BA18>=BA17,BA18-BA17,0) -> 5049 | BC18: 520261 | BD18: =IF(BC18>=BC17,BC18-BC17,0) -> 177 | BE18: 13828 | BF18: =IF(BE18>=BE17,BE18-BE17,0) -> 122 | BG18: 22856520 | BH18: =IF(BG18>=BG17,BG18-BG17,0)-(0.45*BN18)-(0.45*BP18)-BR18 -> 5952.75 | BI18: =AP18+AR18+AT18+AV18+AX18+AZ18+BB18+BD18+BF18+BH18 -> 12930.337 | BJ18: =BI18+AN18 -> 28123.847 | BK18: 1394028 | BL18: =IF(BK18>=BK17,BK18-BK17,0) -> 59 | BM18: 3677232 | BN18: =IF(BM18>=BM17,BM18-BM17,0) -> 1698 | BO18: 390208 | BP18: =IF(BO18>=BO17,BO18-BO17,0) -> 107 | BQ18: 485164 | BR18: =IF(BQ18>=BQ17,BQ18-BQ17,0) -> 212 | BS18: =J18+Q18+AN18+BI18 -> 34058.848 | BT18: 120 | BU18: =IF(BS18>0,BS18/BT17,0) -> 288.6343 | BW18: =IF(BS18>0,BS18/BV18,0) -> #DIV/0! | BX18: =((BS18-Q18)*$BZ$1)+(Q18*$BR$1) -> 39370.175 | BY18: =IF(BX18>0,BX18/BT17,0) -> 333.64555 | BZ18: =IF(BX18>0,BX18/BV18,0) -> #DIV/0!
A19: 14 | C19: =IF(+B19-B18>0,B19-B18,(B19-B18)>0)*800 -> 0 | E19: =IF(+D19-D18>0,D19-D18,(D19-D18)>0)*80 -> 0 | G19: =IF(+F19-F18>0,F19-F18,(F19-F18)>0)*10 -> 0 | I19: 22823159 | J19: =IF(I19>=I18,I19-I18,0) -> 5584 | K19: =M19+O19 -> 3559 | L19: 242734 | M19: =IF(L19>=L18,L19-L18,0) -> 1910 | N19: 249280 | O19: =IF(N19>=N18,N19-N18,0) -> 1649 | P19: 217864 | Q19: =IF(P19>=P18,P19-P18,0)*30 -> 510 | R19: 154279 | S19: =IF(R19>=R18,R19-R18,0) -> 144 | T19: 280742 | U19: =IF(T19>=T18,T19-T18,0) -> 287 | V19: 975924 | W19: =IF(V19>=V18,V19-V18,0)*0.53 -> 2932.49 | X19: 601892 | Y19: =IF(X19>=X18,X19-X18,0)*0.53 -> 0 | Z19: 795052 | AA19: =IF(Z19>=Z18,Z19-Z18,0)*0.53 -> 4049.73 | AB19: 333452 | AC19: =IF(AB19>=AB18,AB19-AB18,0)*0.53 -> 0 | AD19: 393985 | AE19: =IF(AD19>=AD18,AD19-AD18,0)*0.53 -> 960.89 | AF19: 826926 | AG19: =IF(AF19>=AF18,AF19-AF18,0)*0.53 -> 11.13 | AH19: 737917 | AI19: =IF(AH19>=AH18,AH19-AH18,0)*0.53 -> 1237.55 | AJ19: 598014 | AK19: =IF(AJ19>=AJ18,AJ19-AJ18,0)*0.53 -> 3912.99 | AL19: 432113 | AM19: =IF(AL19>=AL18,AL19-AL18,0)*0.53 -> 255.46 | AN19: =W19+Y19+AA19+AC19+AE19+AG19+AI19+AK19+AM19 -> 13360.24 | AO19: 7395068 | AP19: =IF(AO19>=AO18,AO19-AO18,0)*0.1125 -> 187.5375 | AQ19: 622497 | AR19: =IF(AQ19>=AQ18,AQ19-AQ18,0) -> 213 | AS19: 934465 | AT19: =IF(AS19>=AS18,AS19-AS18,0) -> 198 | AU19: 801077 | AV19: =IF(AU19>=AU18,AU19-AU18,0) -> 62 | AW19: 2447206 | AX19: =IF(AW19>=AW18,AW19-AW18,0) -> 868 | AY19: 218145 | AZ19: =IF(AY19>=AY18,AY19-AY18,0) -> 77 | BA19: 18324090 | BB19: =IF(BA19>=BA18,BA19-BA18,0) -> 5009 | BC19: 520436 | BD19: =IF(BC19>=BC18,BC19-BC18,0) -> 175 | BE19: 13957 | BF19: =IF(BE19>=BE18,BE19-BE18,0) -> 129 | BG19: 22863453 | BH19: =IF(BG19>=BG18,BG19-BG18,0)-(0.45*BN19)-(0.45*BP19)-BR19 -> 5945.85 | BI19: =AP19+AR19+AT19+AV19+AX19+AZ19+BB19+BD19+BF19+BH19 -> 12864.388 | BJ19: =BI19+AN19 -> 26224.628 | BK19: 1394054 | BL19: =IF(BK19>=BK18,BK19-BK18,0) -> 26 | BM19: 3678830 | BN19: =IF(BM19>=BM18,BM19-BM18,0) -> 1598 | BO19: 390317 | BP19: =IF(BO19>=BO18,BO19-BO18,0) -> 109 | BQ19: 485383 | BR19: =IF(BQ19>=BQ18,BQ19-BQ18,0) -> 219 | BS19: =J19+Q19+AN19+BI19 -> 32318.627 | BT19: 124 | BU19: =IF(BS19>0,BS19/BT18,0) -> 269.3219 | BW19: =IF(BS19>0,BS19/BV19,0) -> #DIV/0! | BX19: =((BS19-Q19)*$BZ$1)+(Q19*$BR$1) -> 37395.922 | BY19: =IF(BX19>0,BX19/BT18,0) -> 311.63268 | BZ19: =IF(BX19>0,BX19/BV19,0) -> #DIV/0!
A20: 15 | C20: =IF(+B20-B19>0,B20-B19,(B20-B19)>0)*800 -> 0 | E20: =IF(+D20-D19>0,D20-D19,(D20-D19)>0)*80 -> 0 | G20: =IF(+F20-F19>0,F20-F19,(F20-F19)>0)*10 -> 0 | H20: 63 | I20: 22828763 | J20: =IF(I20>=I19,I20-I19,0) -> 5604 | K20: =M20+O20 -> 3175 | L20: 244490 | M20: =IF(L20>=L19,L20-L19,0) -> 1756 | N20: 250699 | O20: =IF(N20>=N19,N20-N19,0) -> 1419 | P20: 217884 | Q20: =IF(P20>=P19,P20-P19,0)*30 -> 600 | R20: 154428 | S20: =IF(R20>=R19,R20-R19,0) -> 149 | T20: 281034 | U20: =IF(T20>=T19,T20-T19,0) -> 292 | V20: 981904 | W20: =IF(V20>=V19,V20-V19,0)*0.53 -> 3169.4 | X20: 601892 | Y20: =IF(X20>=X19,X20-X19,0)*0.53 -> 0 | Z20: 802301 | AA20: =IF(Z20>=Z19,Z20-Z19,0)*0.53 -> 3841.97 | AB20: 333452 | AC20: =IF(AB20>=AB19,AB20-AB19,0)*0.53 -> 0 | AD20: 398218 | AE20: =IF(AD20>=AD19,AD20-AD19,0)*0.53 -> 2243.49 | AF20: 826951 | AG20: =IF(AF20>=AF19,AF20-AF19,0)*0.53 -> 13.25 | AH20: 740041 | AI20: =IF(AH20>=AH19,AH20-AH19,0)*0.53 -> 1125.72 | AJ20: 604964 | AK20: =IF(AJ20>=AJ19,AJ20-AJ19,0)*0.53 -> 3683.5 | AL20: 432422 | AM20: =IF(AL20>=AL19,AL20-AL19,0)*0.53 -> 163.77 | AN20: =W20+Y20+AA20+AC20+AE20+AG20+AI20+AK20+AM20 -> 14241.1 | AO20: 7396767 | AP20: =IF(AO20>=AO19,AO20-AO19,0)*0.1125 -> 191.1375 | AQ20: 622703 | AR20: =IF(AQ20>=AQ19,AQ20-AQ19,0) -> 206 | AS20: 934671 | AT20: =IF(AS20>=AS19,AS20-AS19,0) -> 206 | AU20: 801140 | AV20: =IF(AU20>=AU19,AU20-AU19,0) -> 63 | AW20: 2448044 | AX20: =IF(AW20>=AW19,AW20-AW19,0) -> 838 | AY20: 218213 | AZ20: =IF(AY20>=AY19,AY20-AY19,0) -> 68 | BA20: 18330005 | BB20: =IF(BA20>=BA19,BA20-BA19,0) -> 5915 | BC20: 520619 | BD20: =IF(BC20>=BC19,BC20-BC19,0) -> 183 | BE20: 14003 | BF20: =IF(BE20>=BE19,BE20-BE19,0) -> 46 | BG20: 22870490 | BH20: =IF(BG20>=BG19,BG20-BG19,0)-(0.45*BN20)-(0.45*BP20)-BR20 -> 6030.25 | BI20: =AP20+AR20+AT20+AV20+AX20+AZ20+BB20+BD20+BF20+BH20 -> 13746.388 | BJ20: =BI20+AN20 -> 27987.488 | BK20: 1394056 | BL20: =IF(BK20>=BK19,BK20-BK19,0) -> 2 | BM20: 3680453 | BN20: =IF(BM20>=BM19,BM20-BM19,0) -> 1623 | BO20: 390429 | BP20: =IF(BO20>=BO19,BO20-BO19,0) -> 112 | BQ20: 485609 | BR20: =IF(BQ20>=BQ19,BQ20-BQ19,0) -> 226 | BS20: =J20+Q20+AN20+BI20 -> 34191.488 | BT20: 116 | BU20: =IF(BS20>0,BS20/BT20,0) -> 294.7542 | BW20: =IF(BS20>0,BS20/BV20,0) -> #DIV/0! | BX20: =((BS20-Q20)*$BZ$1)+(Q20*$BR$1) -> 39590.211 | BY20: =IF(BX20>0,BX20/BT20,0) -> 341.29492 | BZ20: =IF(BX20>0,BX20/BV20,0) -> #DIV/0!
A21: 16 | C21: =IF(+B21-B20>0,B21-B20,(B21-B20)>0)*800 -> 0 | E21: =IF(+D21-D20>0,D21-D20,(D21-D20)>0)*80 -> 0 | G21: =IF(+F21-F20>0,F21-F20,(F21-F20)>0)*10 -> 0 | I21: 22834362 | J21: =IF(I21>=I20,I21-I20,0) -> 5599.2286 | K21: =M21+O21 -> 1723 | L21: 246212 | M21: =IF(L21>=L20,L21-L20,0) -> 1722 | N21: 250700 | O21: =IF(N21>=N20,N21-N20,0) -> 1 | P21: 217902 | Q21: =IF(P21>=P20,P21-P20,0)*30 -> 540 | R21: 154624 | S21: =IF(R21>=R20,R21-R20,0) -> 196 | T21: 281300 | U21: =IF(T21>=T20,T21-T20,0) -> 266 | V21: 988648 | W21: =IF(V21>=V20,V21-V20,0)*0.53 -> 3574.32 | X21: 602300 | Y21: =IF(X21>=X20,X21-X20,0)*0.53 -> 216.24 | Z21: 809368 | AA21: =IF(Z21>=Z20,Z21-Z20,0)*0.53 -> 3745.51 | AB21: 333452 | AC21: =IF(AB21>=AB20,AB21-AB20,0)*0.53 -> 0 | AD21: 401157 | AE21: =IF(AD21>=AD20,AD21-AD20,0)*0.53 -> 1557.67 | AF21: 826968 | AG21: =IF(AF21>=AF20,AF21-AF20,0)*0.53 -> 9.01 | AH21: 742085 | AI21: =IF(AH21>=AH20,AH21-AH20,0)*0.53 -> 1083.32 | AJ21: 612538 | AK21: =IF(AJ21>=AJ20,AJ21-AJ20,0)*0.53 -> 4014.22 | AL21: 432730 | AM21: =IF(AL21>=AL20,AL21-AL20,0)*0.53 -> 163.24 | AN21: =W21+Y21+AA21+AC21+AE21+AG21+AI21+AK21+AM21 -> 14363.53 | AO21: 7397062 | AP21: =IF(AO21>=AO20,AO21-AO20,0)*0.1125 -> 33.1875 | AQ21: 622892 | AR21: =IF(AQ21>=AQ20,AQ21-AQ20,0) -> 189 | AS21: 934821 | AT21: =IF(AS21>=AS20,AS21-AS20,0) -> 150 | AU21: 801177 | AV21: =IF(AU21>=AU20,AU21-AU20,0) -> 37 | AW21: 2448878 | AX21: =IF(AW21>=AW20,AW21-AW20,0) -> 834 | AY21: 218285 | AZ21: =IF(AY21>=AY20,AY21-AY20,0) -> 72 | BA21: 18335195 | BB21: =IF(BA21>=BA20,BA21-BA20,0) -> 5190 | BC21: 520763 | BD21: =IF(BC21>=BC20,BC21-BC20,0) -> 144 | BE21: 14185 | BF21: =IF(BE21>=BE20,BE21-BE20,0) -> 182 | BG21: 22876274 | BH21: =IF(BG21>=BG20,BG21-BG20,0)-(0.45*BN21)-(0.45*BP21)-BR21 -> 4940.05 | BI21: =AP21+AR21+AT21+AV21+AX21+AZ21+BB21+BD21+BF21+BH21 -> 11771.237 | BJ21: =BI21+AN21 -> 26134.768 | BK21: 1394057 | BL21: =IF(BK21>=BK20,BK21-BK20,0) -> 1 | BM21: 3681832 | BN21: =IF(BM21>=BM20,BM21-BM20,0) -> 1379 | BO21: 390521 | BP21: =IF(BO21>=BO20,BO21-BO20,0) -> 92 | BQ21: 485791 | BR21: =IF(BQ21>=BQ20,BQ21-BQ20,0) -> 182 | BS21: =J21+Q21+AN21+BI21 -> 32273.996 | BT21: 161 | BU21: =IF(BS21>0,BS21/BT21,0) -> 200.4596 | BW21: =IF(BS21>0,BS21/BV21,0) -> #DIV/0! | BX21: =((BS21-Q21)*$BZ$1)+(Q21*$BR$1) -> 37358.095 | BY21: =IF(BX21>0,BX21/BT21,0) -> 232.03786 | BZ21: =IF(BX21>0,BX21/BV21,0) -> #DIV/0!
