Workbook

Sheet TOTAL
A1: Site Name | B1: Day | C1: Month | D1: Year | E1: Total Electricity Kwh | F1: Electricity Tariff ($/Kwh) | G1: LPG (Kg) | H1: LPG $/Kg | I1: Water Utility Supply (m3) m3 | J1: Water Utility Supply (m3) $/m3 | K1: Room Nights
A2: Seychelles at Desroches Island | B2: 1 | C2: 8 | D2: 2022 | E2: =Submetering!E2+Submetering!F2+Submetering!G2+Submetering!H2+Submetering!J2-Submetering!AV2 -> 10900 | F2: 0.5876503 | G2: =(Submetering!AX2+Submetering!AY2+Submetering!AZ2+Submetering!BA2+Submetering!BB2) -> 10.989 | H2: 0.99 | I2: ='FS Desroches Daily'!CM4 -> 120.4 | J2: 10.487298 | K2: ='FS Desroches Daily'!CN4 -> 42
A3: Seychelles at Desroches Island | B3: 2 | C3: 8 | D3: 2022 | E3: =Submetering!E3+Submetering!F3+Submetering!G3+Submetering!H3+Submetering!J3-Submetering!AV3 -> 10500 | F3: =F2 -> 0.5876503 | G3: =(Submetering!AX3+Submetering!AY3+Submetering!AZ3+Submetering!BA3+Submetering!BB3) -> 18.315 | H3: =H2 -> 0.99 | I3: ='FS Desroches Daily'!CM5 -> 128 | J3: =J2 -> 10.487298 | K3: ='FS Desroches Daily'!CN5 -> 42
A4: Seychelles at Desroches Island | B4: 3 | C4: 8 | D4: 2022 | E4: =Submetering!E4+Submetering!F4+Submetering!G4+Submetering!H4+Submetering!J4-Submetering!AV4 -> 10900 | F4: =F3 -> 0.5876503 | G4: =(Submetering!AX4+Submetering!AY4+Submetering!AZ4+Submetering!BA4+Submetering!BB4) -> 27.4725 | H4: =H3 -> 0.99 | I4: ='FS Desroches Daily'!CM6 -> 121.9 | J4: =J3 -> 10.487298 | K4: ='FS Desroches Daily'!CN6 -> 42
A5: Seychelles at Desroches Island | B5: 4 | C5: 8 | D5: 2022 | E5: =Submetering!E5+Submetering!F5+Submetering!G5+Submetering!H5+Submetering!J5-Submetering!AV5 -> 10700 | F5: =F4 -> 0.5876503 | G5: =(Submetering!AX5+Submetering!AY5+Submetering!AZ5+Submetering!BA5+Submetering!BB5) -> 10.989 | H5: =H4 -> 0.99 | I5: ='FS Desroches Daily'!CM7 -> 122.3 | J5: =J4 -> 10.487298 | K5: ='FS Desroches Daily'!CN7 -> 42
A6: Seychelles at Desroches Island | B6: 5 | C6: 8 | D6: 2022 | E6: =Submetering!E6+Submetering!F6+Submetering!G6+Submetering!H6+Submetering!J6-Submetering!AV6 -> 10700 | F6: =F5 -> 0.5876503 | G6: =(Submetering!AX6+Submetering!AY6+Submetering!AZ6+Submetering!BA6+Submetering!BB6) -> 10.989 | H6: =H5 -> 0.99 | I6: ='FS Desroches Daily'!CM8 -> 126.9 | J6: =J5 -> 10.487298 | K6: ='FS Desroches Daily'!CN8 -> 46
A7: Seychelles at Desroches Island | B7: 6 | C7: 8 | D7: 2022 | E7: =Submetering!E7+Submetering!F7+Submetering!G7+Submetering!H7+Submetering!J7-Submetering!AV7 -> 11500 | F7: =F6 -> 0.5876503 | G7: =(Submetering!AX7+Submetering!AY7+Submetering!AZ7+Submetering!BA7+Submetering!BB7) -> 7.326 | H7: =H6 -> 0.99 | I7: ='FS Desroches Daily'!CM9 -> 131.5 | J7: =J6 -> 10.487298 | K7: ='FS Desroches Daily'!CN9 -> 54
A8: Seychelles at Desroches Island | B8: 7 | C8: 8 | D8: 2022 | E8: =Submetering!E8+Submetering!F8+Submetering!G8+Submetering!H8+Submetering!J8-Submetering!AV8 -> 11800 | F8: =F7 -> 0.5876503 | G8: =(Submetering!AX8+Submetering!AY8+Submetering!AZ8+Submetering!BA8+Submetering!BB8) -> 25.641 | H8: =H7 -> 0.99 | I8: ='FS Desroches Daily'!CM10 -> 127.2 | J8: =J7 -> 10.487298 | K8: ='FS Desroches Daily'!CN10 -> 54
A9: Seychelles at Desroches Island | B9: 8 | C9: 8 | D9: 2022 | E9: =Submetering!E9+Submetering!F9+Submetering!G9+Submetering!H9+Submetering!J9-Submetering!AV9 -> 11200 | F9: =F8 -> 0.5876503 | G9: =(Submetering!AX9+Submetering!AY9+Submetering!AZ9+Submetering!BA9+Submetering!BB9) -> 20.1465 | H9: =H8 -> 0.99 | I9: ='FS Desroches Daily'!CM11 -> 126.8 | J9: =J8 -> 10.487298 | K9: ='FS Desroches Daily'!CN11 -> 54
A10: Seychelles at Desroches Island | B10: 9 | C10: 8 | D10: 2022 | E10: =Submetering!E10+Submetering!F10+Submetering!G10+Submetering!H10+Submetering!J10-Submetering!AV10 -> 11300 | F10: =F9 -> 0.5876503 | G10: =(Submetering!AX10+Submetering!AY10+Submetering!AZ10+Submetering!BA10+Submetering!BB10) -> 21.978 | H10: =H9 -> 0.99 | I10: ='FS Desroches Daily'!CM12 -> 123 | J10: =J9 -> 10.487298 | K10: ='FS Desroches Daily'!CN12 -> 52
A11: Seychelles at Desroches Island | B11: 10 | C11: 8 | D11: 2022 | E11: =Submetering!E11+Submetering!F11+Submetering!G11+Submetering!H11+Submetering!J11-Submetering!AV11 -> 10100 | F11: =F10 -> 0.5876503 | G11: =(Submetering!AX11+Submetering!AY11+Submetering!AZ11+Submetering!BA11+Submetering!BB11) -> 18.315 | H11: =H10 -> 0.99 | I11: ='FS Desroches Daily'!CM13 -> 127 | J11: =J10 -> 10.487298 | K11: ='FS Desroches Daily'!CN13 -> 51
A12: Seychelles at Desroches Island | B12: 11 | C12: 8 | D12: 2022 | E12: =Submetering!E12+Submetering!F12+Submetering!G12+Submetering!H12+Submetering!J12-Submetering!AV12 -> 11100 | F12: =F11 -> 0.5876503 | G12: =(Submetering!AX12+Submetering!AY12+Submetering!AZ12+Submetering!BA12+Submetering!BB12) -> 14.652 | H12: =H11 -> 0.99 | I12: ='FS Desroches Daily'!CM14 -> 114 | J12: =J11 -> 10.487298 | K12: ='FS Desroches Daily'!CN14 -> 41
A13: Seychelles at Desroches Island | B13: 12 | C13: 8 | D13: 2022 | E13: =Submetering!E13+Submetering!F13+Submetering!G13+Submetering!H13+Submetering!J13-Submetering!AV13 -> 10800 | F13: =F12 -> 0.5876503 | G13: =(Submetering!AX13+Submetering!AY13+Submetering!AZ13+Submetering!BA13+Submetering!BB13) -> 16.4835 | H13: =H12 -> 0.99 | I13: ='FS Desroches Daily'!CM15 -> 126 | J13: =J12 -> 10.487298 | K13: ='FS Desroches Daily'!CN15 -> 42
A14: Seychelles at Desroches Island | B14: 13 | C14: 8 | D14: 2022 | E14: =Submetering!E14+Submetering!F14+Submetering!G14+Submetering!H14+Submetering!J14-Submetering!AV14 -> 11600 | F14: =F13 -> 0.5876503 | G14: =(Submetering!AX14+Submetering!AY14+Submetering!AZ14+Submetering!BA14+Submetering!BB14) -> 16.4835 | H14: =H13 -> 0.99 | I14: ='FS Desroches Daily'!CM16 -> 100 | J14: =J13 -> 10.487298 | K14: ='FS Desroches Daily'!CN16 -> 41
... A32: Seychelles at Desroches Island | B32: 31 | C32: 8 | D32: 2022 | E32: =Submetering!E32+Submetering!F32+Submetering!G32+Submetering!H32+Submetering!J32-Submetering!AV32 -> 0 | F32: =F31 -> 0.5876503 | G32: =(Submetering!AX32+Submetering!AY32+Submetering!AZ32+Submetering!BA32+Submetering!BB32) -> 0 | H32: =H31 -> 0.99 | I32: ='FS Desroches Daily'!CM34 -> 0 | J32: =J31 -> 10.487298 | K32: ='FS Desroches Daily'!CN34 -> 0
E33: =SUM(E2:E32) -> #VALUE! | G33: =SUM(G2:G32) -> 336.996 | I33: =SUM(I2:I32) -> #VALUE! | K33: =SUM(K2:K32) -> 940

Sheet Submetering
A1: Site Name | B1: Day | C1: Month | D1: Year | E1: TRF CQ6 -KWh | F1: TRF FQ7 -KWh | G1: MSB BOH Q8 -KWh | H1: EX MAIN Q3 -KWh | I1: TRF DQ2 -KWh | J1: TRF B Q1 -KWh | K1: CANCAN shop -KWh | L1: CANCAN store -KWh | M1: Laundry EQU P D.B -KWh | N1: Laundry lighting -KWh | O1: PANTRY 1 -KWh | P1: PANTRY 2 -KWh | Q1: SPA LIGHT HOUSE -KWh | R1: PANTRY 3 -KWh | S1: PANTRY 4 -KWh | T1: VMC -KWh | U1: VILLA 100/157 -KWh | V1: VILLA 101/158 -KWh | W1: VILLA 102/159 -KWh | X1: VILLA 103/160 -KWh | Y1: VILLA 104/161 -KWh | Z1: VILLA 105/162 -KWh | AA1: VILLA 106/163 -KWh | AB1: VILLA 107/164 -KWh | AC1: VILLA 108/165 -KWh | AD1: VILLA 109/166 -KWh | AE1: VILLA 110 -KWh | AF1: KUMAR&KUMAR -KWh | AG1: BLOCK 15 -KWh | AH1: BLOCK 16 -KWh | AI1: BLOCK 17 -KWh | AJ1: BLOCK 18 -KWh | AK1: BLOCK 19 -KWh | AL1: BLOCK 20 -KWh | AM1: BLOCK 21 -KWh | AN1: BLOCK 22 -KWh | AO1: BLOCK 23 -KWh | AP1: BLOCK 24 -KWh | AQ1: Exhaust Kitchen (Main) -KWh | AR1: Exhaust Kitchen (Breakfast) -KWh | AS1: Exhaust Lighthouse -KWh | AT1: Exhaust Canteen -KWh | AU1: Cold Store -KWh | AV1: RO Plant -KWh | AW1: Water (m3) | AX1: Main kitchen M1 (9598630) - Kg | AY1: Main kitchen M2 (9598611) -Kg | AZ1: Main kitchen M3 (9249533) -Kg | BA1: Lighthouse -Kg | BB1: Canteen -Kg | BC1: Room Nights
A2: Seychelles at Desroches Island | B2: 1 | C2: 8 | D2: 2022 | E2: ='FS Desroches Daily'!D4 -> 2200 | F2: ='FS Desroches Daily'!F4 -> 3100 | G2: ='FS Desroches Daily'!H4 -> 3600 | H2: ='FS Desroches Daily'!J4 -> 1400 | I2: ='FS Desroches Daily'!L4 -> 1900 | J2: ='FS Desroches Daily'!N4 -> 1500 | K2: ='FS Desroches Daily'!P4 -> 18 | L2: ='FS Desroches Daily'!R4 -> 0 | M2: ='FS Desroches Daily'!T4 -> 1.6 | N2: ='FS Desroches Daily'!V4 -> 519.4 | O2: ='FS Desroches Daily'!X4 -> 290 | P2: ='FS Desroches Daily'!Z4 -> 2700 | Q2: ='FS Desroches Daily'!AB4 -> 390 | R2: ='FS Desroches Daily'!AD4 -> 340 | S2: ='FS Desroches Daily'!AF4 -> 700 | T2: ='FS Desroches Daily'!AH4 -> 34 | U2: ='FS Desroches Daily'!AJ4 -> 560 | V2: ='FS Desroches Daily'!AL4 -> 240 | W2: ='FS Desroches Daily'!AN4 -> 120 | X2: ='FS Desroches Daily'!AP4 -> 180 | Y2: ='FS Desroches Daily'!AR4 -> 160 | Z2: ='FS Desroches Daily'!AT4 -> 130 | AA2: ='FS Desroches Daily'!AT4 -> 130 | AB2: ='FS Desroches Daily'!AV4 -> 90 | AC2: ='FS Desroches Daily'!AZ4 -> 160 | AD2: ='FS Desroches Daily'!BB4 -> 130 | AE2: ='FS Desroches Daily'!BD4 -> 20 | AF2: ='FS Desroches Daily'!BF4 -> 26 | AG2: ='FS Desroches Daily'!BH4 -> 30 | AH2: ='FS Desroches Daily'!BJ4 -> 40 | AI2: ='FS Desroches Daily'!BL4 -> 40 | AJ2: ='FS Desroches Daily'!BN4 -> 30 | AK2: ='FS Desroches Daily'!BP4 -> 30 | AL2: ='FS Desroches Daily'!BR4 -> 32 | AM2: ='FS Desroches Daily'!BT4 -> 40 | AN2: ='FS Desroches Daily'!BV4 -> 17 | AO2: ='FS Desroches Daily'!BX4 -> 40 | AP2: ='FS Desroches Daily'!BZ4 -> 34 | AQ2: ='FS Desroches Daily'!CB4 -> 57.4 | AR2: ='FS Desroches Daily'!CD4 -> 8.7 | AS2: ='FS Desroches Daily'!CF4 -> 1.4 | AT2: ='FS Desroches Daily'!CH4 -> 56.5 | AU2: ='FS Desroches Daily'!CJ4 -> 294 | AV2: ='FS Desroches Daily'!CL4 -> 900 | AW2: ='FS Desroches Daily'!CM4 -> 120.4 | AX2: =IF(LPG!F9-LPG!F8<0,"0",(LPG!F9-LPG!F8)*1.8315) -> 0 | AY2: =IF(LPG!H9-LPG!H8<0,"0",(LPG!H9-LPG!H8)*1.8315) -> 0 | AZ2: =IF(LPG!J9-LPG!J8<0,"0",(LPG!J9-LPG!J8)*1.8315) -> 5.4945 | BA2: =IF(LPG!M9-LPG!M8<0,"0",(LPG!M9-LPG!M8)*1.8315) -> 0 | BB2: =IF(LPG!Q9-LPG!Q8<0,"0",(LPG!Q9-LPG!Q8)*1.8315) -> 5.4945 | BC2: ='FS Desroches Daily'!CN4 -> 42
A3: Seychelles at Desroches Island | B3: 2 | C3: 8 | D3: 2022 | E3: ='FS Desroches Daily'!D5 -> 2100 | F3: ='FS Desroches Daily'!F5 -> 2900 | G3: ='FS Desroches Daily'!H5 -> 3300 | H3: ='FS Desroches Daily'!J5 -> 1500 | I3: ='FS Desroches Daily'!L5 -> 2000 | J3: ='FS Desroches Daily'!N5 -> 1500 | K3: ='FS Desroches Daily'!P5 -> 22 | L3: ='FS Desroches Daily'!R5 -> 4 | M3: ='FS Desroches Daily'!T5 -> 1.5 | N3: ='FS Desroches Daily'!V5 -> 433 | O3: ='FS Desroches Daily'!X6 -> 310 | P3: ='FS Desroches Daily'!Z5 -> 2800 | Q3: ='FS Desroches Daily'!AB5 -> 280 | R3: ='FS Desroches Daily'!AD5 -> 360 | S3: ='FS Desroches Daily'!AF5 -> 770 | T3: ='FS Desroches Daily'!AH5 -> 34 | U3: ='FS Desroches Daily'!AJ5 -> 570 | V3: ='FS Desroches Daily'!AL5 -> 210 | W3: ='FS Desroches Daily'!AN5 -> 140 | X3: ='FS Desroches Daily'!AP5 -> 190 | Y3: ='FS Desroches Daily'!AR5 -> 170 | Z3: ='FS Desroches Daily'!AT5 -> 160 | AA3: ='FS Desroches Daily'!AT5 -> 160 | AB3: ='FS Desroches Daily'!AV5 -> 110 | AC3: ='FS Desroches Daily'!AZ5 -> 190 | AD3: ='FS Desroches Daily'!BB5 -> 130 | AE3: ='FS Desroches Daily'!BD5 -> 40 | AF3: ='FS Desroches Daily'!BF5 -> 30 | AG3: ='FS Desroches Daily'!BH5 -> 30 | AH3: ='FS Desroches Daily'!BJ5 -> 20 | AI3: ='FS Desroches Daily'!BL5 -> 50 | AJ3: ='FS Desroches Daily'!BN5 -> 30 | AK3: ='FS Desroches Daily'!BP5 -> 40 | AL3: ='FS Desroches Daily'!BR5 -> 34 | AM3: ='FS Desroches Daily'!BT5 -> 30 | AN3: ='FS Desroches Daily'!BV5 -> 51 | AO3: ='FS Desroches Daily'!BX5 -> 30 | AP3: ='FS Desroches Daily'!BZ5 -> 39 | AQ3: ='FS Desroches Daily'!CB5 -> 52 | AR3: ='FS Desroches Daily'!CD5 -> 10.3 | AS3: ='FS Desroches Daily'!CF5 -> 7.3 | AT3: ='FS Desroches Daily'!CH5 -> 54.2 | AU3: ='FS Desroches Daily'!CJ5 -> 289 | AV3: ='FS Desroches Daily'!CL5 -> 800 | AW3: ='FS Desroches Daily'!CM5 -> 128 | AX3: =IF(LPG!F10-LPG!F9<0,"0",(LPG!F10-LPG!F9)*1.8315) -> 0 | AY3: =IF(LPG!H10-LPG!H9<0,"0",(LPG!H10-LPG!H9)*1.8315) -> 0 | AZ3: =IF(LPG!J10-LPG!J9<0,"0",(LPG!J10-LPG!J9)*1.8315) -> 5.4945 | BA3: =IF(LPG!M10-LPG!M9<0,"0",(LPG!M10-LPG!M9)*1.8315) -> 5.4945 | BB3: =IF(LPG!Q10-LPG!Q9<0,"0",(LPG!Q10-LPG!Q9)*1.8315) -> 7.326 | BC3: ='FS Desroches Daily'!CN5 -> 42
A4: Seychelles at Desroches Island | B4: 3 | C4: 8 | D4: 2022 | E4: ='FS Desroches Daily'!D6 -> 2200 | F4: ='FS Desroches Daily'!F6 -> 3000 | G4: ='FS Desroches Daily'!H6 -> 3500 | H4: ='FS Desroches Daily'!J6 -> 1400 | I4: ='FS Desroches Daily'!L6 -> 2000 | J4: ='FS Desroches Daily'!N6 -> 1700 | K4: ='FS Desroches Daily'!P6 -> 18 | L4: ='FS Desroches Daily'!R6 -> 2 | M4: ='FS Desroches Daily'!T6 -> 1.5 | N4: ='FS Desroches Daily'!V6 -> 354.2 | O4: ='FS Desroches Daily'!X7 -> 300 | P4: ='FS Desroches Daily'!Z6 -> 2600 | Q4: ='FS Desroches Daily'!AB6 -> 390 | R4: ='FS Desroches Daily'!AD6 -> 380 | S4: ='FS Desroches Daily'!AF6 -> 800 | T4: ='FS Desroches Daily'!AH6 -> 30 | U4: ='FS Desroches Daily'!AJ6 -> 550 | V4: ='FS Desroches Daily'!AL6 -> 190 | W4: ='FS Desroches Daily'!AN6 -> 170 | X4: ='FS Desroches Daily'!AP6 -> 170 | Y4: ='FS Desroches Daily'!AR6 -> 140 | Z4: ='FS Desroches Daily'!AT6 -> 160 | AA4: ='FS Desroches Daily'!AT6 -> 160 | AB4: ='FS Desroches Daily'!AV6 -> 110 | AC4: ='FS Desroches Daily'!AZ6 -> 160 | AD4: ='FS Desroches Daily'!BB6 -> 130 | AE4: ='FS Desroches Daily'!BD6 -> 40 | AF4: ='FS Desroches Daily'!BF6 -> 52 | AG4: ='FS Desroches Daily'!BH6 -> 30 | AH4: ='FS Desroches Daily'!BJ6 -> 30 | AI4: ='FS Desroches Daily'!BL6 -> 30 | AJ4: ='FS Desroches Daily'!BN6 -> 30 | AK4: ='FS Desroches Daily'!BP6 -> 30 | AL4: ='FS Desroches Daily'!BR6 -> 26 | AM4: ='FS Desroches Daily'!BT6 -> 40 | AN4: ='FS Desroches Daily'!BV6 -> 28 | AO4: ='FS Desroches Daily'!BX6 -> 30 | AP4: ='FS Desroches Daily'!BZ6 -> 31 | AQ4: ='FS Desroches Daily'!CB6 -> 63 | AR4: ='FS Desroches Daily'!CD6 -> 10.2 | AS4: ='FS Desroches Daily'!CF6 -> 1 | AT4: ='FS Desroches Daily'!CH6 -> 65 | AU4: ='FS Desroches Daily'!CJ6 -> 293 | AV4: ='FS Desroches Daily'!CL6 -> 900 | AW4: ='FS Desroches Daily'!CM6 -> 121.9 | AX4: =IF(LPG!F11-LPG!F10<0,"0",(LPG!F11-LPG!F10)*1.8315) -> 0 | AY4: =IF(LPG!H11-LPG!H10<0,"0",(LPG!H11-LPG!H10)*1.8315) -> 0 | AZ4: =IF(LPG!J13-LPG!J10<0,"0",(LPG!J13-LPG!J10)*1.8315) -> 21.978 | BA4: =IF(LPG!M11-LPG!M10<0,"0",(LPG!M11-LPG!M10)*1.8315) -> 0 | BB4: =IF(LPG!Q11-LPG!Q10<0,"0",(LPG!Q11-LPG!Q10)*1.8315) -> 5.4945 | BC4: ='FS Desroches Daily'!CN6 -> 42
A5: Seychelles at Desroches Island | B5: 4 | C5: 8 | D5: 2022 | E5: ='FS Desroches Daily'!D7 -> 2100 | F5: ='FS Desroches Daily'!F7 -> 3100 | G5: ='FS Desroches Daily'!H7 -> 3700 | H5: ='FS Desroches Daily'!J7 -> 1400 | I5: ='FS Desroches Daily'!L7 -> 2000 | J5: ='FS Desroches Daily'!N7 -> 1400 | K5: ='FS Desroches Daily'!P7 -> 24 | L5: ='FS Desroches Daily'!R7 -> 3 | M5: ='FS Desroches Daily'!T7 -> 1.6 | N5: ='FS Desroches Daily'!V7 -> 421.7 | O5: ='FS Desroches Daily'!X8 -> 310 | P5: ='FS Desroches Daily'!Z7 -> 2900 | Q5: ='FS Desroches Daily'!AB7 -> 230 | R5: ='FS Desroches Daily'!AD7 -> 280 | S5: ='FS Desroches Daily'!AF7 -> 820 | T5: ='FS Desroches Daily'!AH7 -> 29 | U5: ='FS Desroches Daily'!AJ7 -> 540 | V5: ='FS Desroches Daily'!AL7 -> 180 | W5: ='FS Desroches Daily'!AN7 -> 210 | X5: ='FS Desroches Daily'!AP7 -> 180 | Y5: ='FS Desroches Daily'!AR7 -> 140 | Z5: ='FS Desroches Daily'!AT7 -> 130 | AA5: ='FS Desroches Daily'!AT7 -> 130 | AB5: ='FS Desroches Daily'!AV7 -> 130 | AC5: ='FS Desroches Daily'!AZ7 -> 170 | AD5: ='FS Desroches Daily'!BB7 -> 140 | AE5: ='FS Desroches Daily'!BD7 -> 30 | AF5: ='FS Desroches Daily'!BF7 -> 28 | AG5: ='FS Desroches Daily'!BH7 -> 30 | AH5: ='FS Desroches Daily'!BJ7 -> 20 | AI5: ='FS Desroches Daily'!BL7 -> 50 | AJ5: ='FS Desroches Daily'!BN7 -> 30 | AK5: ='FS Desroches Daily'!BP7 -> 40 | AL5: ='FS Desroches Daily'!BR7 -> 27 | AM5: ='FS Desroches Daily'!BT7 -> 40 | AN5: ='FS Desroches Daily'!BV7 -> 30 | AO5: ='FS Desroches Daily'!BX7 -> 30 | AP5: ='FS Desroches Daily'!BZ7 -> 35 | AQ5: ='FS Desroches Daily'!CB7 -> 63.4 | AR5: ='FS Desroches Daily'!CD7 -> 10.4 | AS5: ='FS Desroches Daily'!CF7 -> 1 | AT5: ='FS Desroches Daily'!CH7 -> 58.3 | AU5: ='FS Desroches Daily'!CJ7 -> 280 | AV5: ='FS Desroches Daily'!CL7 -> 1000 | AW5: ='FS Desroches Daily'!CM7 -> 122.3 | AX5: =IF(LPG!F12-LPG!F11<0,"0",(LPG!F12-LPG!F11)*1.8315) -> 0 | AY5: =IF(LPG!H12-LPG!H11<0,"0",(LPG!H12-LPG!H11)*1.8315) -> 0 | AZ5: =IF(LPG!J12-LPG!J13<0,"0",(LPG!J12-LPG!J13)*1.8315) -> 0 | BA5: =IF(LPG!M12-LPG!M11<0,"0",(LPG!M12-LPG!M11)*1.8315) -> 5.4945 | BB5: =IF(LPG!Q12-LPG!Q11<0,"0",(LPG!Q12-LPG!Q11)*1.8315) -> 5.4945 | BC5: ='FS Desroches Daily'!CN7 -> 42
A6: Seychelles at Desroches Island | B6: 5 | C6: 8 | D6: 2022 | E6: ='FS Desroches Daily'!D8 -> 2100 | F6: ='FS Desroches Daily'!F8 -> 3000 | G6: ='FS Desroches Daily'!H8 -> 3500 | H6: ='FS Desroches Daily'!J8 -> 1400 | I6: ='FS Desroches Daily'!L8 -> 2000 | J6: ='FS Desroches Daily'!N8 -> 1700 | K6: ='FS Desroches Daily'!P8 -> 20 | L6: ='FS Desroches Daily'!R8 -> 2 | M6: ='FS Desroches Daily'!T8 -> 1.4 | N6: ='FS Desroches Daily'!V8 -> 386.3 | O6: ='FS Desroches Daily'!X8 -> 310 | P6: ='FS Desroches Daily'!Z8 -> 2600 | Q6: ='FS Desroches Daily'!AB8 -> 410 | R6: ='FS Desroches Daily'!AD8 -> 300 | S6: ='FS Desroches Daily'!AF8 -> 880 | T6: ='FS Desroches Daily'!AH8 -> 32 | U6: ='FS Desroches Daily'!AJ8 -> 520 | V6: ='FS Desroches Daily'!AL8 -> 180 | W6: ='FS Desroches Daily'!AN8 -> 150 | X6: ='FS Desroches Daily'!AP8 -> 190 | Y6: ='FS Desroches Daily'!AR8 -> 130 | Z6: ='FS Desroches Daily'!AT8 -> 130 | AA6: ='FS Desroches Daily'!AT8 -> 130 | AB6: ='FS Desroches Daily'!AV8 -> 120 | AC6: ='FS Desroches Daily'!AZ8 -> 150 | AD6: ='FS Desroches Daily'!BB8 -> 140 | AE6: ='FS Desroches Daily'!BD8 -> 30 | AF6: ='FS Desroches Daily'!BF8 -> 45 | AG6: ='FS Desroches Daily'!BH8 -> 30 | AH6: ='FS Desroches Daily'!BJ8 -> 30 | AI6: ='FS Desroches Daily'!BL8 -> 50 | AJ6: ='FS Desroches Daily'!BN8 -> 20 | AK6: ='FS Desroches Daily'!BP8 -> 30 | AL6: ='FS Desroches Daily'!BR8 -> 26 | AM6: ='FS Desroches Daily'!BT8 -> 30 | AN6: ='FS Desroches Daily'!BV8 -> 31 | AO6: ='FS Desroches Daily'!BX8 -> 30 | AP6: ='FS Desroches Daily'!BZ8 -> 34 | AQ6: ='FS Desroches Daily'!CB8 -> 56.5 | AR6: ='FS Desroches Daily'!CD8 -> 9.2 | AS6: ='FS Desroches Daily'!CF8 -> 7 | AT6: ='FS Desroches Daily'!CH8 -> 62.1 | AU6: ='FS Desroches Daily'!CJ8 -> 286 | AV6: ='FS Desroches Daily'!CL8 -> 1000 | AW6: ='FS Desroches Daily'!CM8 -> 126.9 | AX6: =IF(LPG!F13-LPG!F12<0,"0",(LPG!F13-LPG!F12)*1.8315) -> 0 | AY6: =IF(LPG!H13-LPG!H12<0,"0",(LPG!H13-LPG!H12)*1.8315) -> 0 | AZ6: 0 | BA6: =IF(LPG!M13-LPG!M12<0,"0",(LPG!M13-LPG!M12)*1.8315) -> 1.8315 | BB6: =IF(LPG!Q13-LPG!Q12<0,"0",(LPG!Q13-LPG!Q12)*1.8315) -> 9.1575 | BC6: ='FS Desroches Daily'!CN8 -> 46
A7: Seychelles at Desroches Island | B7: 6 | C7: 8 | D7: 2022 | E7: ='FS Desroches Daily'!D9 -> 2400 | F7: ='FS Desroches Daily'!F9 -> 3100 | G7: ='FS Desroches Daily'!H9 -> 3600 | H7: ='FS Desroches Daily'!J9 -> 1500 | I7: ='FS Desroches Daily'!L9 -> 2100 | J7: ='FS Desroches Daily'!N9 -> 1800 | K7: ='FS Desroches Daily'!P9 -> 21 | L7: ='FS Desroches Daily'!R9 -> 3 | M7: ='FS Desroches Daily'!T9 -> 1.6 | N7: ='FS Desroches Daily'!V9 -> 429.6 | O7: ='FS Desroches Daily'!X9 -> 330 | P7: ='FS Desroches Daily'!Z9 -> 3100 | Q7: ='FS Desroches Daily'!AB9 -> 390 | R7: ='FS Desroches Daily'!AD9 -> 360 | S7: ='FS Desroches Daily'!AF9 -> 970 | T7: ='FS Desroches Daily'!AH9 -> 38 | U7: ='FS Desroches Daily'!AJ9 -> 180 | V7: ='FS Desroches Daily'!AL9 -> 240 | W7: ='FS Desroches Daily'!AN9 -> 180 | X7: ='FS Desroches Daily'!AP9 -> 210 | Y7: ='FS Desroches Daily'!AR9 -> 190 | Z7: ='FS Desroches Daily'!AT9 -> 170 | AA7: ='FS Desroches Daily'!AT9 -> 170 | AB7: ='FS Desroches Daily'!AV9 -> 120 | AC7: ='FS Desroches Daily'!AZ9 -> 170 | AD7: ='FS Desroches Daily'!BB9 -> 170 | AE7: ='FS Desroches Daily'!BD9 -> 30 | AF7: ='FS Desroches Daily'!BF9 -> 24 | AG7: ='FS Desroches Daily'!BH9 -> 30 | AH7: ='FS Desroches Daily'!BJ9 -> 20 | AI7: ='FS Desroches Daily'!BL9 -> 50 | AJ7: ='FS Desroches Daily'!BN9 -> 30 | AK7: ='FS Desroches Daily'!BP9 -> 40 | AL7: ='FS Desroches Daily'!BR9 -> 29 | AM7: ='FS Desroches Daily'!BT9 -> 30 | AN7: ='FS Desroches Daily'!BV9 -> 29 | AO7: ='FS Desroches Daily'!BX9 -> 40 | AP7: ='FS Desroches Daily'!BZ9 -> 36 | AQ7: ='FS Desroches Daily'!CB9 -> 58.8 | AR7: ='FS Desroches Daily'!CD9 -> 14.2 | AS7: ='FS Desroches Daily'!CF9 -> 9.2 | AT7: ='FS Desroches Daily'!CH9 -> 56.4 | AU7: ='FS Desroches Daily'!CJ9 -> 276 | AV7: ='FS Desroches Daily'!CL9 -> 900 | AW7: ='FS Desroches Daily'!CM9 -> 131.5 | AX7: =IF(LPG!F14-LPG!F13<0,"0",(LPG!F14-LPG!F13)*1.8315) -> 0 | AY7: =IF(LPG!H14-LPG!H13<0,"0",(LPG!H14-LPG!H13)*1.8315) -> 0 | AZ7: 0 | BA7: =IF(LPG!M14-LPG!M13<0,"0",(LPG!M14-LPG!M13)*1.8315) -> 3.663 | BB7: =IF(LPG!Q14-LPG!Q13<0,"0",(LPG!Q14-LPG!Q13)*1.8315) -> 3.663 | BC7: ='FS Desroches Daily'!CN9 -> 54
A8: Seychelles at Desroches Island | B8: 7 | C8: 8 | D8: 2022 | E8: ='FS Desroches Daily'!D10 -> 2400 | F8: ='FS Desroches Daily'!F10 -> 3300 | G8: ='FS Desroches Daily'!H10 -> 3800 | H8: ='FS Desroches Daily'!J10 -> 1500 | I8: ='FS Desroches Daily'!L10 -> 1900 | J8: ='FS Desroches Daily'!N10 -> 1700 | K8: ='FS Desroches Daily'!P10 -> 18 | L8: ='FS Desroches Daily'!R10 -> 2 | M8: ='FS Desroches Daily'!T10 -> 2.1 | N8: ='FS Desroches Daily'!V10 -> 491.2 | O8: ='FS Desroches Daily'!X10 -> 240 | P8: ='FS Desroches Daily'!Z10 -> 2800 | Q8: ='FS Desroches Daily'!AB10 -> 350 | R8: ='FS Desroches Daily'!AD10 -> 370 | S8: ='FS Desroches Daily'!AF10 -> 830 | T8: ='FS Desroches Daily'!AH10 -> 33 | U8: ='FS Desroches Daily'!AJ10 -> 1230 | V8: ='FS Desroches Daily'!AL10 -> 160 | W8: ='FS Desroches Daily'!AN10 -> 140 | X8: ='FS Desroches Daily'!AP10 -> 120 | Y8: ='FS Desroches Daily'!AR10 -> 170 | Z8: ='FS Desroches Daily'!AT10 -> 180 | AA8: ='FS Desroches Daily'!AT10 -> 180 | AB8: ='FS Desroches Daily'!AV10 -> 120 | AC8: ='FS Desroches Daily'!AZ10 -> 180 | AD8: ='FS Desroches Daily'!BB10 -> 130 | AE8: ='FS Desroches Daily'!BD10 -> 30 | AF8: ='FS Desroches Daily'!BF10 -> 35 | AG8: ='FS Desroches Daily'!BH10 -> 40 | AH8: ='FS Desroches Daily'!BJ10 -> 30 | AI8: ='FS Desroches Daily'!BL10 -> 50 | AJ8: ='FS Desroches Daily'!BN10 -> 40 | AK8: ='FS Desroches Daily'!BP10 -> 30 | AL8: ='FS Desroches Daily'!BR10 -> 38 | AM8: ='FS Desroches Daily'!BT10 -> 40 | AN8: ='FS Desroches Daily'!BV10 -> 33 | AO8: ='FS Desroches Daily'!BX10 -> 40 | AP8: ='FS Desroches Daily'!BZ10 -> 44 | AQ8: ='FS Desroches Daily'!CB10 -> 53.8 | AR8: ='FS Desroches Daily'!CD10 -> 9.3 | AS8: ='FS Desroches Daily'!CF10 -> 3.8 | AT8: ='FS Desroches Daily'!CH10 -> 66.2 | AU8: ='FS Desroches Daily'!CJ10 -> 291 | AV8: ='FS Desroches Daily'!CL10 -> 900 | AW8: ='FS Desroches Daily'!CM10 -> 127.2 | AX8: =IF(LPG!F16-LPG!F14<0,"0",(LPG!F16-LPG!F14)*1.8315) -> 0 | AY8: =IF(LPG!H16-LPG!H14<0,"0",(LPG!H16-LPG!H14)*1.8315) -> 0 | AZ8: =IF(LPG!J16-LPG!J14<0,"0",(LPG!J16-LPG!J14)*1.8315) -> 12.8205 | BA8: =IF(LPG!M16-LPG!M14<0,"0",(LPG!M16-LPG!M14)*1.8315) -> 5.4945 | BB8: =IF(LPG!Q15-LPG!Q14<0,"0",(LPG!Q15-LPG!Q14)*1.8315) -> 7.326 | BC8: ='FS Desroches Daily'!CN10 -> 54
A9: Seychelles at Desroches Island | B9: 8 | C9: 8 | D9: 2022 | E9: ='FS Desroches Daily'!D11 -> 2200 | F9: ='FS Desroches Daily'!F11 -> 3100 | G9: ='FS Desroches Daily'!H11 -> 3600 | H9: ='FS Desroches Daily'!J11 -> 1500 | I9: ='FS Desroches Daily'!L11 -> 2000 | J9: ='FS Desroches Daily'!N11 -> 1600 | K9: ='FS Desroches Daily'!P11 -> 18 | L9: ='FS Desroches Daily'!R11 -> 1 | M9: ='FS Desroches Daily'!T11 -> 1.4 | N9: ='FS Desroches Daily'!V11 -> 543.9 | O9: ='FS Desroches Daily'!X11 -> 260 | P9: ='FS Desroches Daily'!Z11 -> 3200 | Q9: ='FS Desroches Daily'!AB11 -> 410 | R9: ='FS Desroches Daily'!AD11 -> 310 | S9: ='FS Desroches Daily'!AF11 -> 770 | T9: ='FS Desroches Daily'!AH11 -> 38 | U9: ='FS Desroches Daily'!AJ11 -> 710 | V9: ='FS Desroches Daily'!AL11 -> 190 | W9: ='FS Desroches Daily'!AN11 -> 150 | X9: ='FS Desroches Daily'!AP11 -> 130 | Y9: ='FS Desroches Daily'!AR11 -> 190 | Z9: ='FS Desroches Daily'!AT11 -> 180 | AA9: ='FS Desroches Daily'!AT11 -> 180 | AB9: ='FS Desroches Daily'!AV11 -> 130 | AC9: ='FS Desroches Daily'!AZ11 -> 170 | AD9: ='FS Desroches Daily'!BB11 -> 100 | AE9: ='FS Desroches Daily'!BD11 -> 20 | AF9: ='FS Desroches Daily'!BF11 -> 65 | AG9: ='FS Desroches Daily'!BH11 -> 20 | AH9: ='FS Desroches Daily'!BJ11 -> 30 | AI9: ='FS Desroches Daily'!BL11 -> 40 | AJ9: ='FS Desroches Daily'!BN11 -> 30 | AK9: ='FS Desroches Daily'!BP11 -> 20 | AL9: ='FS Desroches Daily'!BR11 -> 25 | AM9: ='FS Desroches Daily'!BT11 -> 30 | AN9: ='FS Desroches Daily'!BV11 -> 27 | AO9: ='FS Desroches Daily'!BX11 -> 30 | AP9: ='FS Desroches Daily'!BZ11 -> 36 | AQ9: ='FS Desroches Daily'!CB11 -> 65.6 | AR9: ='FS Desroches Daily'!CD11 -> 11.9 | AS9: ='FS Desroches Daily'!CF11 -> 8.3 | AT9: ='FS Desroches Daily'!CH11 -> 54.6 | AU9: ='FS Desroches Daily'!CJ11 -> 308 | AV9: ='FS Desroches Daily'!CL11 -> 800 | AW9: ='FS Desroches Daily'!CM11 -> 126.8 | AX9: =IF(LPG!F17-LPG!F15<0,"0",(LPG!F17-LPG!F15)*1.8315) -> 0 | AY9: =IF(LPG!H17-LPG!H15<0,"0",(LPG!H17-LPG!H15)*1.8315) -> 0 | AZ9: =IF(LPG!J17-LPG!J15<0,"0",(LPG!J17-LPG!J15)*1.8315) -> 9.1575 | BA9: =IF(LPG!M17-LPG!M15<0,"0",(LPG!M17-LPG!M15)*1.8315) -> 5.4945 | BB9: =IF(LPG!Q16-LPG!Q15<0,"0",(LPG!Q16-LPG!Q15)*1.8315) -> 5.4945 | BC9: ='FS Desroches Daily'!CN11 -> 54
A10: Seychelles at Desroches Island | B10: 9 | C10: 8 | D10: 2022 | E10: ='FS Desroches Daily'!D12 -> 2200 | F10: ='FS Desroches Daily'!F12 -> 3200 | G10: ='FS Desroches Daily'!H12 -> 3700 | H10: ='FS Desroches Daily'!J12 -> 1500 | I10: ='FS Desroches Daily'!L12 -> 2000 | J10: ='FS Desroches Daily'!N12 -> 1600 | K10: ='FS Desroches Daily'!P12 -> 26 | L10: ='FS Desroches Daily'!R12 -> 4 | M10: ='FS Desroches Daily'!T12 -> 1.6 | N10: ='FS Desroches Daily'!V12 -> 408.3 | O10: ='FS Desroches Daily'!X12 -> 230 | P10: ='FS Desroches Daily'!Z12 -> 2900 | Q10: ='FS Desroches Daily'!AB12 -> 400 | R10: ='FS Desroches Daily'!AD12 -> 320 | S10: ='FS Desroches Daily'!AF12 -> 740 | T10: ='FS Desroches Daily'!AH12 -> 32 | U10: ='FS Desroches Daily'!AJ12 -> 610 | V10: ='FS Desroches Daily'!AL12 -> 210 | W10: ='FS Desroches Daily'!AN12 -> 150 | X10: ='FS Desroches Daily'!AP12 -> 100 | Y10: ='FS Desroches Daily'!AR12 -> 140 | Z10: ='FS Desroches Daily'!AT12 -> 180 | AA10: ='FS Desroches Daily'!AT12 -> 180 | AB10: ='FS Desroches Daily'!AV12 -> 120 | AC10: ='FS Desroches Daily'!AZ12 -> 140 | AD10: ='FS Desroches Daily'!BB12 -> 110 | AE10: ='FS Desroches Daily'!BD12 -> 30 | AF10: ='FS Desroches Daily'!BF12 -> 38 | AG10: ='FS Desroches Daily'!BH12 -> 30 | AH10: ='FS Desroches Daily'!BJ12 -> 30 | AI10: ='FS Desroches Daily'!BL12 -> 50 | AJ10: ='FS Desroches Daily'!BN12 -> 30 | AK10: ='FS Desroches Daily'!BP12 -> 40 | AL10: ='FS Desroches Daily'!BR12 -> 34 | AM10: ='FS Desroches Daily'!BT12 -> 30 | AN10: ='FS Desroches Daily'!BV12 -> 34 | AO10: ='FS Desroches Daily'!BX12 -> 30 | AP10: ='FS Desroches Daily'!BZ12 -> 37 | AQ10: ='FS Desroches Daily'!CB12 -> 56.4 | AR10: ='FS Desroches Daily'!CD12 -> 9.1 | AS10: ='FS Desroches Daily'!CF12 -> 5.2 | AT10: ='FS Desroches Daily'!CH12 -> 58.9 | AU10: ='FS Desroches Daily'!CJ12 -> 278 | AV10: ='FS Desroches Daily'!CL12 -> 900 | AW10: ='FS Desroches Daily'!CM12 -> 123 | AX10: =IF(LPG!F18-LPG!F16<0,"0",(LPG!F18-LPG!F16)*1.8315) -> 0 | AY10: =IF(LPG!H18-LPG!H16<0,"0",(LPG!H18-LPG!H16)*1.8315) -> 0 | AZ10: =IF(LPG!J18-LPG!J16<0,"0",(LPG!J18-LPG!J16)*1.8315) -> 10.989 | BA10: =IF(LPG!M18-LPG!M16<0,"0",(LPG!M18-LPG!M16)*1.8315) -> 3.663 | BB10: =IF(LPG!Q17-LPG!Q16<0,"0",(LPG!Q17-LPG!Q16)*1.8315) -> 7.326 | BC10: ='FS Desroches Daily'!CN12 -> 52
A11: Seychelles at Desroches Island | B11: 10 | C11: 8 | D11: 2022 | E11: ='FS Desroches Daily'!D13 -> 2000 | F11: ='FS Desroches Daily'!F13 -> 2800 | G11: ='FS Desroches Daily'!H13 -> 3500 | H11: ='FS Desroches Daily'!J13 -> 1400 | I11: ='FS Desroches Daily'!L13 -> 2000 | J11: ='FS Desroches Daily'!N13 -> 1400 | K11: ='FS Desroches Daily'!P13 -> 19 | L11: ='FS Desroches Daily'!R13 -> 1 | M11: ='FS Desroches Daily'!T13 -> 1.5 | N11: ='FS Desroches Daily'!V13 -> 333 | O11: ='FS Desroches Daily'!X13 -> 250 | P11: ='FS Desroches Daily'!Z13 -> 2500 | Q11: ='FS Desroches Daily'!AB13 -> 380 | R11: ='FS Desroches Daily'!AD13 -> 280 | S11: ='FS Desroches Daily'!AF13 -> 730 | T11: ='FS Desroches Daily'!AH13 -> 28 | U11: ='FS Desroches Daily'!AJ13 -> 540 | V11: ='FS Desroches Daily'!AL13 -> 180 | W11: ='FS Desroches Daily'!AN13 -> 150 | X11: ='FS Desroches Daily'!AP13 -> 100 | Y11: ='FS Desroches Daily'!AR13 -> 130 | Z11: ='FS Desroches Daily'!AT13 -> 170 | AA11: ='FS Desroches Daily'!AT13 -> 170 | AB11: ='FS Desroches Daily'!AV13 -> 90 | AC11: ='FS Desroches Daily'!AZ13 -> 130 | AD11: ='FS Desroches Daily'!BB13 -> 90 | AE11: ='FS Desroches Daily'!BD13 -> 40 | AF11: ='FS Desroches Daily'!BF13 -> 43 | AG11: ='FS Desroches Daily'!BH13 -> 20 | AH11: ='FS Desroches Daily'!BJ13 -> 20 | AI11: ='FS Desroches Daily'!BL13 -> 40 | AJ11: ='FS Desroches Daily'!BN13 -> 30 | AK11: ='FS Desroches Daily'!BP13 -> 20 | AL11: ='FS Desroches Daily'!BR13 -> 27 | AM11: ='FS Desroches Daily'!BT13 -> 20 | AN11: ='FS Desroches Daily'!BV13 -> 32 | AO11: ='FS Desroches Daily'!BX13 -> 30 | AP11: ='FS Desroches Daily'!BZ13 -> 34 | AQ11: ='FS Desroches Daily'!CB13 -> 44.1 | AR11: ='FS Desroches Daily'!CD13 -> 8.2 | AS11: ='FS Desroches Daily'!CF13 -> 3.7 | AT11: ='FS Desroches Daily'!CH13 -> 45.4 | AU11: ='FS Desroches Daily'!CJ13 -> 288 | AV11: ='FS Desroches Daily'!CL13 -> 1000 | AW11: ='FS Desroches Daily'!CM13 -> 127 | AX11: =IF(LPG!F18-LPG!F17<0,"0",(LPG!F18-LPG!F17)*1.8315) -> 0 | AY11: =IF(LPG!H18-LPG!H17<0,"0",(LPG!H18-LPG!H17)*1.8315) -> 0 | AZ11: =IF(LPG!J18-LPG!J17<0,"0",(LPG!J18-LPG!J17)*1.8315) -> 7.326 | BA11: =IF(LPG!M19-LPG!M17<0,"0",(LPG!M19-LPG!M17)*1.8315) -> 0 | BB11: =IF(LPG!Q18-LPG!Q17<0,"0",(LPG!Q18-LPG!Q17)*1.8315) -> 10.989 | BC11: ='FS Desroches Daily'!CN13 -> 51
A12: Seychelles at Desroches Island | B12: 11 | C12: 8 | D12: 2022 | E12: ='FS Desroches Daily'!D14 -> 2100 | F12: ='FS Desroches Daily'!F14 -> 3300 | G12: ='FS Desroches Daily'!H14 -> 3800 | H12: ='FS Desroches Daily'!J14 -> 1400 | I12: ='FS Desroches Daily'!L14 -> 2000 | J12: ='FS Desroches Daily'!N14 -> 1400 | K12: ='FS Desroches Daily'!P14 -> 19 | L12: ='FS Desroches Daily'!R14 -> 2 | M12: ='FS Desroches Daily'!T14 -> 1.8 | N12: ='FS Desroches Daily'!V14 -> 439.6 | O12: ='FS Desroches Daily'!X14 -> 350 | P12: ='FS Desroches Daily'!Z14 -> 3100 | Q12: ='FS Desroches Daily'!AB14 -> 260 | R12: ='FS Desroches Daily'!AD14 -> 300 | S12: ='FS Desroches Daily'!AF14 -> 730 | T12: ='FS Desroches Daily'!AH14 -> 31 | U12: ='FS Desroches Daily'!AJ14 -> 630 | V12: ='FS Desroches Daily'!AL14 -> 210 | W12: ='FS Desroches Daily'!AN14 -> 180 | X12: ='FS Desroches Daily'!AP14 -> 130 | Y12: ='FS Desroches Daily'!AR14 -> 180 | Z12: ='FS Desroches Daily'!AT14 -> 190 | AA12: ='FS Desroches Daily'!AT14 -> 190 | AB12: ='FS Desroches Daily'!AV14 -> 90 | AC12: ='FS Desroches Daily'!AZ14 -> 110 | AD12: ='FS Desroches Daily'!BB14 -> 80 | AE12: ='FS Desroches Daily'!BD14 -> 40 | AF12: ='FS Desroches Daily'!BF14 -> 37 | AG12: ='FS Desroches Daily'!BH14 -> 30 | AH12: ='FS Desroches Daily'!BJ14 -> 30 | AI12: ='FS Desroches Daily'!BL14 -> 40 | AJ12: ='FS Desroches Daily'!BN14 -> 30 | AK12: ='FS Desroches Daily'!BP14 -> 40 | AL12: ='FS Desroches Daily'!BR14 -> 34 | AM12: ='FS Desroches Daily'!BT14 -> 30 | AN12: ='FS Desroches Daily'!BV14 -> 32 | AO12: ='FS Desroches Daily'!BX14 -> 30 | AP12: ='FS Desroches Daily'!BZ14 -> 38 | AQ12: ='FS Desroches Daily'!CB14 -> 60.3 | AR12: ='FS Desroches Daily'!CD14 -> 20.6 | AS12: ='FS Desroches Daily'!CF14 -> 3.4 | AT12: ='FS Desroches Daily'!CH14 -> 45.7 | AU12: ='FS Desroches Daily'!CJ14 -> 294 | AV12: ='FS Desroches Daily'!CL14 -> 900 | AW12: ='FS Desroches Daily'!CM14 -> 114 | AX12: =IF(LPG!F19-LPG!F18<0,"0",(LPG!F19-LPG!F18)*1.8315) -> 0 | AY12: =IF(LPG!H19-LPG!H18<0,"0",(LPG!H19-LPG!H18)*1.8315) -> 0 | AZ12: =IF(LPG!J19-LPG!J18<0,"0",(LPG!J19-LPG!J18)*1.8315) -> 5.4945 | BA12: =IF(LPG!M19-LPG!M18<0,"0",(LPG!M19-LPG!M18)*1.8315) -> 0 | BB12: =IF(LPG!Q20-LPG!Q18<0,"0",(LPG!Q20-LPG!Q18)*1.8315) -> 9.1575 | BC12: ='FS Desroches Daily'!CN14 -> 41
A13: Seychelles at Desroches Island | B13: 12 | C13: 8 | D13: 2022 | E13: ='FS Desroches Daily'!D15 -> 2100 | F13: ='FS Desroches Daily'!F15 -> 3200 | G13: ='FS Desroches Daily'!H15 -> 3500 | H13: ='FS Desroches Daily'!J15 -> 1500 | I13: ='FS Desroches Daily'!L15 -> 2000 | J13: ='FS Desroches Daily'!N15 -> 1500 | K13: ='FS Desroches Daily'!P15 -> 30 | L13: ='FS Desroches Daily'!R15 -> 3 | M13: ='FS Desroches Daily'!T15 -> 1.3 | N13: ='FS Desroches Daily'!V15 -> 383.8 | O13: ='FS Desroches Daily'!X15 -> 290 | P13: ='FS Desroches Daily'!Z15 -> 1100 | Q13: ='FS Desroches Daily'!AB15 -> 400 | R13: ='FS Desroches Daily'!AD15 -> 320 | S13: ='FS Desroches Daily'!AF15 -> 710 | T13: ='FS Desroches Daily'!AH15 -> 34 | U13: ='FS Desroches Daily'!AJ15 -> 650 | V13: ='FS Desroches Daily'!AL15 -> 190 | W13: ='FS Desroches Daily'!AN15 -> 180 | X13: ='FS Desroches Daily'!AP15 -> 110 | Y13: ='FS Desroches Daily'!AR15 -> 100 | Z13: ='FS Desroches Daily'!AT15 -> 180 | AA13: ='FS Desroches Daily'!AT15 -> 180 | AB13: ='FS Desroches Daily'!AV15 -> 110 | AC13: ='FS Desroches Daily'!AZ15 -> 90 | AD13: ='FS Desroches Daily'!BB15 -> 130 | AE13: ='FS Desroches Daily'!BD15 -> 20 | AF13: ='FS Desroches Daily'!BF15 -> 42 | AG13: ='FS Desroches Daily'!BH15 -> 20 | AH13: ='FS Desroches Daily'!BJ15 -> 30 | AI13: ='FS Desroches Daily'!BL15 -> 40 | AJ13: ='FS Desroches Daily'!BN15 -> 40 | AK13: ='FS Desroches Daily'!BP15 -> 30 | AL13: ='FS Desroches Daily'!BR15 -> 30 | AM13: ='FS Desroches Daily'!BT15 -> 30 | AN13: ='FS Desroches Daily'!BV15 -> 39 | AO13: ='FS Desroches Daily'!BX15 -> 40 | AP13: ='FS Desroches Daily'!BZ15 -> 39 | AQ13: ='FS Desroches Daily'!CB15 -> 46.8 | AR13: ='FS Desroches Daily'!CD15 -> 10 | AS13: ='FS Desroches Daily'!CF15 -> 4.3 | AT13: ='FS Desroches Daily'!CH15 -> 46.9 | AU13: ='FS Desroches Daily'!CJ15 -> 294 | AV13: ='FS Desroches Daily'!CL15 -> 1000 | AW13: ='FS Desroches Daily'!CM15 -> 126 | AX13: =IF(LPG!F20-LPG!F19<0,"0",(LPG!F20-LPG!F19)*1.8315) -> 0 | AY13: =IF(LPG!H20-LPG!H19<0,"0",(LPG!H20-LPG!H19)*1.8315) -> 0 | AZ13: =IF(LPG!J20-LPG!J19<0,"0",(LPG!J20-LPG!J19)*1.8315) -> 5.4945 | BA13: =IF(LPG!M20-LPG!M19<0,"0",(LPG!M20-LPG!M19)*1.8315) -> 5.4945 | BB13: =IF(LPG!Q20-LPG!Q19<0,"0",(LPG!Q20-LPG!Q19)*1.8315) -> 5.4945 | BC13: ='FS Desroches Daily'!CN15 -> 42
A14: Seychelles at Desroches Island | B14: 13 | C14: 8 | D14: 2022 | E14: ='FS Desroches Daily'!D16 -> 2600 | F14: ='FS Desroches Daily'!F16 -> 3300 | G14: ='FS Desroches Daily'!H16 -> 3500 | H14: ='FS Desroches Daily'!J16 -> 1500 | I14: ='FS Desroches Daily'!L16 -> 2300 | J14: ='FS Desroches Daily'!N16 -> 1600 | K14: ='FS Desroches Daily'!P16 -> 22 | L14: ='FS Desroches Daily'!R16 -> 6 | M14: ='FS Desroches Daily'!T16 -> 1.5 | N14: ='FS Desroches Daily'!V16 -> 392.8 | O14: ='FS Desroches Daily'!X16 -> 390 | P14: ='FS Desroches Daily'!Z16 -> 5000 | Q14: ='FS Desroches Daily'!AB16 -> 380 | R14: ='FS Desroches Daily'!AD16 -> 300 | S14: ='FS Desroches Daily'!AF16 -> 730 | T14: ='FS Desroches Daily'!AH16 -> 33 | U14: ='FS Desroches Daily'!AJ16 -> 780 | V14: ='FS Desroches Daily'!AL16 -> 210 | W14: ='FS Desroches Daily'!AN16 -> 180 | X14: ='FS Desroches Daily'!AP16 -> 140 | Y14: ='FS Desroches Daily'!AR16 -> 220 | Z14: ='FS Desroches Daily'!AT16 -> 240 | AA14: ='FS Desroches Daily'!AT16 -> 240 | AB14: ='FS Desroches Daily'!AV16 -> 170 | AC14: ='FS Desroches Daily'!AZ16 -> 150 | AD14: ='FS Desroches Daily'!BB16 -> 130 | AE14: ='FS Desroches Daily'!BD16 -> 20 | AF14: ='FS Desroches Daily'!BF16 -> 34 | AG14: ='FS Desroches Daily'!BH16 -> 30 | AH14: ='FS Desroches Daily'!BJ16 -> 20 | AI14: ='FS Desroches Daily'!BL16 -> 40 | AJ14: ='FS Desroches Daily'!BN16 -> 30 | AK14: ='FS Desroches Daily'!BP16 -> 40 | AL14: ='FS Desroches Daily'!BR16 -> 31 | AM14: ='FS Desroches Daily'!BT16 -> 30 | AN14: ='FS Desroches Daily'!BV16 -> 30 | AO14: ='FS Desroches Daily'!BX16 -> 30 | AP14: ='FS Desroches Daily'!BZ16 -> 39 | AQ14: ='FS Desroches Daily'!CB16 -> 56.8 | AR14: ='FS Desroches Daily'!CD16 -> 12.4 | AS14: ='FS Desroches Daily'!CF16 -> 2.2 | AT14: ='FS Desroches Daily'!CH16 -> 46.7 | AU14: ='FS Desroches Daily'!CJ16 -> 291 | AV14: ='FS Desroches Daily'!CL16 -> 900 | AW14: ='FS Desroches Daily'!CM16 -> 100 | AX14: =IF(LPG!F21-LPG!F20<0,"0",(LPG!F21-LPG!F20)*1.8315) -> 0 | AY14: =IF(LPG!H21-LPG!H20<0,"0",(LPG!H21-LPG!H20)*1.8315) -> 0 | AZ14: =IF(LPG!J21-LPG!J20<0,"0",(LPG!J21-LPG!J20)*1.8315) -> 5.4945 | BA14: =IF(LPG!M21-LPG!M20<0,"0",(LPG!M21-LPG!M20)*1.8315) -> 3.663 | BB14: =IF(LPG!Q21-LPG!Q20<0,"0",(LPG!Q21-LPG!Q20)*1.8315) -> 7.326 | BC14: ='FS Desroches Daily'!CN16 -> 41
A15: Seychelles at Desroches Island | B15: 14 | C15: 8 | D15: 2022 | E15: ='FS Desroches Daily'!D17 -> 2400 | F15: ='FS Desroches Daily'!F17 -> 3200 | G15: ='FS Desroches Daily'!H17 -> 3600 | H15: ='FS Desroches Daily'!J17 -> 1400 | I15: ='FS Desroches Daily'!L17 -> 2100 | J15: ='FS Desroches Daily'!N17 -> 1500 | K15: ='FS Desroches Daily'!P17 -> 23 | L15: ='FS Desroches Daily'!R17 -> 0 | M15: ='FS Desroches Daily'!T17 -> 1.4 | N15: ='FS Desroches Daily'!V17 -> 382.5 | O15: ='FS Desroches Daily'!X17 -> 260 | P15: ='FS Desroches Daily'!Z17 -> 2400 | Q15: ='FS Desroches Daily'!AB17 -> 360 | R15: ='FS Desroches Daily'!AD17 -> 280 | S15: ='FS Desroches Daily'!AF17 -> 750 | T15: ='FS Desroches Daily'!AH17 -> 30 | U15: ='FS Desroches Daily'!AJ17 -> 630 | V15: ='FS Desroches Daily'!AL17 -> 180 | W15: ='FS Desroches Daily'!AN17 -> 140 | X15: ='FS Desroches Daily'!AP17 -> 150 | Y15: ='FS Desroches Daily'!AR17 -> 200 | Z15: ='FS Desroches Daily'!AT17 -> 190 | AA15: ='FS Desroches Daily'!AT17 -> 190 | AB15: ='FS Desroches Daily'!AV17 -> 170 | AC15: ='FS Desroches Daily'!AZ17 -> 90 | AD15: ='FS Desroches Daily'!BB17 -> 120 | AE15: ='FS Desroches Daily'!BD17 -> 20 | AF15: ='FS Desroches Daily'!BF17 -> 29 | AG15: ='FS Desroches Daily'!BH17 -> 30 | AH15: ='FS Desroches Daily'!BJ17 -> 30 | AI15: ='FS Desroches Daily'!BL17 -> 30 | AJ15: ='FS Desroches Daily'!BN17 -> 40 | AK15: ='FS Desroches Daily'!BP17 -> 30 | AL15: ='FS Desroches Daily'!BR17 -> 28 | AM15: ='FS Desroches Daily'!BT17 -> 30 | AN15: ='FS Desroches Daily'!BV17 -> 35 | AO15: ='FS Desroches Daily'!BX17 -> 30 | AP15: ='FS Desroches Daily'!BZ17 -> 44 | AQ15: ='FS Desroches Daily'!CB17 -> 54.4 | AR15: ='FS Desroches Daily'!CD17 -> 7.4 | AS15: ='FS Desroches Daily'!CF17 -> 1.9 | AT15: ='FS Desroches Daily'!CH17 -> 42.8 | AU15: ='FS Desroches Daily'!CJ17 -> 296 | AV15: ='FS Desroches Daily'!CL17 -> 1100 | AW15: ='FS Desroches Daily'!CM17 -> 121.5 | AX15: =IF(LPG!F22-LPG!F21<0,"0",(LPG!F22-LPG!F21)*1.8315) -> 0 | AY15: =IF(LPG!H22-LPG!H21<0,"0",(LPG!H22-LPG!H21)*1.8315) -> 0 | AZ15: =IF(LPG!J22-LPG!J21<0,"0",(LPG!J22-LPG!J21)*1.8315) -> 9.1575 | BA15: =IF(LPG!M22-LPG!M21<0,"0",(LPG!M22-LPG!M21)*1.8315) -> 1.8315 | BB15: =IF(LPG!Q22-LPG!Q21<0,"0",(LPG!Q22-LPG!Q21)*1.8315) -> 7.326 | BC15: ='FS Desroches Daily'!CN17 -> 54
A16: Seychelles at Desroches Island | B16: 15 | C16: 8 | D16: 2022 | E16: ='FS Desroches Daily'!D18 -> 2300 | F16: ='FS Desroches Daily'!F18 -> 3000 | G16: ='FS Desroches Daily'!H18 -> 3000 | H16: ='FS Desroches Daily'!J18 -> 1500 | I16: ='FS Desroches Daily'!L18 -> 2100 | J16: ='FS Desroches Daily'!N18 -> 1500 | K16: ='FS Desroches Daily'!P18 -> 25 | L16: ='FS Desroches Daily'!R18 -> 3 | M16: ='FS Desroches Daily'!T18 -> 1.3 | N16: ='FS Desroches Daily'!V18 -> 360.2 | O16: ='FS Desroches Daily'!X18 -> 280 | P16: ='FS Desroches Daily'!Z18 -> 2800 | Q16: ='FS Desroches Daily'!AB18 -> 390 | R16: ='FS Desroches Daily'!AD18 -> 370 | S16: ='FS Desroches Daily'!AF18 -> 690 | T16: ='FS Desroches Daily'!AH18 -> 31 | U16: ='FS Desroches Daily'!AJ18 -> 670 | V16: ='FS Desroches Daily'!AL18 -> 180 | W16: ='FS Desroches Daily'!AN18 -> 150 | X16: ='FS Desroches Daily'!AP18 -> 160 | Y16: ='FS Desroches Daily'!AR18 -> 180 | Z16: ='FS Desroches Daily'!AT18 -> 210 | AA16: ='FS Desroches Daily'!AT18 -> 210 | AB16: ='FS Desroches Daily'!AV18 -> 170 | AC16: ='FS Desroches Daily'!AZ18 -> 170 | AD16: ='FS Desroches Daily'!BB18 -> 120 | AE16: ='FS Desroches Daily'!BD18 -> 40 | AF16: ='FS Desroches Daily'!BF18 -> 38 | AG16: ='FS Desroches Daily'!BH18 -> 30 | AH16: ='FS Desroches Daily'!BJ18 -> 30 | AI16: ='FS Desroches Daily'!BL18 -> 40 | AJ16: ='FS Desroches Daily'!BN18 -> 30 | AK16: ='FS Desroches Daily'!BP18 -> 40 | AL16: ='FS Desroches Daily'!BR18 -> 30 | AM16: ='FS Desroches Daily'!BT18 -> 40 | AN16: ='FS Desroches Daily'!BV18 -> 35 | AO16: ='FS Desroches Daily'!BX18 -> 40 | AP16: ='FS Desroches Daily'!BZ18 -> 42 | AQ16: ='FS Desroches Daily'!CB18 -> 56.9 | AR16: ='FS Desroches Daily'!CD18 -> 18.7 | AS16: ='FS Desroches Daily'!CF18 -> 3.6 | AT16: ='FS Desroches Daily'!CH18 -> 49.3 | AU16: ='FS Desroches Daily'!CJ18 -> 307 | AV16: ='FS Desroches Daily'!CL18 -> 700 | AW16: ='FS Desroches Daily'!CM18 -> 120.2 | AX16: =IF(LPG!F23-LPG!F22<0,"0",(LPG!F23-LPG!F22)*1.8315) -> 0 | AY16: =IF(LPG!H23-LPG!H22<0,"0",(LPG!H23-LPG!H22)*1.8315) -> 0 | AZ16: =IF(LPG!J23-LPG!J22<0,"0",(LPG!J23-LPG!J22)*1.8315) -> 5.4945 | BA16: =IF(LPG!M23-LPG!M22<0,"0",(LPG!M23-LPG!M22)*1.8315) -> 0 | BB16: =IF(LPG!Q23-LPG!Q22<0,"0",(LPG!Q23-LPG!Q22)*1.8315) -> 3.663 | BC16: ='FS Desroches Daily'!CN18 -> 32
A17: Seychelles at Desroches Island | B17: 16 | C17: 8 | D17: 2022 | E17: ='FS Desroches Daily'!D19 -> 2400 | F17: ='FS Desroches Daily'!F19 -> 3400 | G17: ='FS Desroches Daily'!H19 -> 3200 | H17: ='FS Desroches Daily'!J19 -> 1500 | I17: ='FS Desroches Daily'!L19 -> 2100 | J17: ='FS Desroches Daily'!N19 -> 1400 | K17: ='FS Desroches Daily'!P19 -> 24 | L17: ='FS Desroches Daily'!R19 -> 4 | M17: ='FS Desroches Daily'!T19 -> 1.4 | N17: ='FS Desroches Daily'!V19 -> 374.5 | O17: ='FS Desroches Daily'!X19 -> 290 | P17: ='FS Desroches Daily'!Z19 -> 3200 | Q17: ='FS Desroches Daily'!AB19 -> 250 | R17: ='FS Desroches Daily'!AD19 -> 310 | S17: ='FS Desroches Daily'!AF19 -> 740 | T17: ='FS Desroches Daily'!AH19 -> 34 | U17: ='FS Desroches Daily'!AJ19 -> 670 | V17: ='FS Desroches Daily'!AL19 -> 180 | W17: ='FS Desroches Daily'!AN19 -> 180 | X17: ='FS Desroches Daily'!AP19 -> 160 | Y17: ='FS Desroches Daily'!AR19 -> 150 | Z17: ='FS Desroches Daily'!AU20 -> 359.52 | AA17: ='FS Desroches Daily'!AU20 -> 359.52 | AB17: ='FS Desroches Daily'!AV19 -> 230 | AC17: ='FS Desroches Daily'!AZ19 -> 210 | AD17: ='FS Desroches Daily'!BB19 -> 110 | AE17: ='FS Desroches Daily'!BD19 -> 40 | AF17: ='FS Desroches Daily'!BF19 -> 44 | AG17: ='FS Desroches Daily'!BH19 -> 30 | AH17: ='FS Desroches Daily'!BJ19 -> 30 | AI17: ='FS Desroches Daily'!BL19 -> 40 | AJ17: ='FS Desroches Daily'!BN19 -> 30 | AK17: ='FS Desroches Daily'!BP19 -> 40 | AL17: ='FS Desroches Daily'!BR19 -> 34 | AM17: ='FS Desroches Daily'!BT19 -> 30 | AN17: ='FS Desroches Daily'!BV19 -> 37 | AO17: ='FS Desroches Daily'!BX19 -> 30 | AP17: ='FS Desroches Daily'!BZ19 -> 39 | AQ17: ='FS Desroches Daily'!CB19 -> 66 | AR17: ='FS Desroches Daily'!CD19 -> 10.6 | AS17: ='FS Desroches Daily'!CF19 -> 5.9 | AT17: ='FS Desroches Daily'!CH19 -> 47.3 | AU17: ='FS Desroches Daily'!CJ19 -> 294 | AV17: ='FS Desroches Daily'!CL19 -> 700 | AW17: ='FS Desroches Daily'!CM19 -> 125.6 | AX17: =IF(LPG!F24-LPG!F23<0,"0",(LPG!F24-LPG!F23)*1.8315) -> 0 | AY17: =IF(LPG!H24-LPG!H23<0,"0",(LPG!H24-LPG!H23)*1.8315) -> 0 | AZ17: =IF(LPG!J24-LPG!J23<0,"0",(LPG!J24-LPG!J23)*1.8315) -> 5.4945 | BA17: =IF(LPG!M24-LPG!M23<0,"0",(LPG!M24-LPG!M23)*1.8315) -> 3.663 | BB17: =IF(LPG!Q24-LPG!Q23<0,"0",(LPG!Q24-LPG!Q23)*1.8315) -> 7.326 | BC17: ='FS Desroches Daily'!CN19 -> 32
A18: Seychelles at Desroches Island | B18: 17 | C18: 8 | D18: 2022 | E18: ='FS Desroches Daily'!D20 -> 2500 | F18: ='FS Desroches Daily'!F20 -> 3000 | G18: ='FS Desroches Daily'!H20 -> 3600 | H18: ='FS Desroches Daily'!J20 -> 1600 | I18: ='FS Desroches Daily'!L20 -> 2100 | J18: ='FS Desroches Daily'!N20 -> 1500 | K18: ='FS Desroches Daily'!P20 -> 22 | L18: ='FS Desroches Daily'!R20 -> 2 | M18: ='FS Desroches Daily'!T20 -> 1.5 | N18: ='FS Desroches Daily'!V20 -> 423.9 | O18: ='FS Desroches Daily'!X20 -> 280 | P18: ='FS Desroches Daily'!Z20 -> 2700 | Q18: ='FS Desroches Daily'!AB20 -> 380 | R18: ='FS Desroches Daily'!AD20 -> 300 | S18: ='FS Desroches Daily'!AF20 -> 680 | T18: ='FS Desroches Daily'!AH20 -> 36 | U18: ='FS Desroches Daily'!AJ20 -> 720 | V18: ='FS Desroches Daily'!AL20 -> 200 | W18: ='FS Desroches Daily'!AN20 -> 170 | X18: ='FS Desroches Daily'!AP20 -> 160 | Y18: ='FS Desroches Daily'!AR20 -> 140 | Z18: ='FS Desroches Daily'!AT20 -> 250 | AA18: ='FS Desroches Daily'!AT20 -> 250 | AB18: ='FS Desroches Daily'!AV20 -> 240 | AC18: ='FS Desroches Daily'!AZ20 -> 160 | AD18: ='FS Desroches Daily'!BB20 -> 120 | AE18: ='FS Desroches Daily'!BD20 -> 20 | AF18: ='FS Desroches Daily'!BF20 -> 48 | AG18: ='FS Desroches Daily'!BH20 -> 30 | AH18: ='FS Desroches Daily'!BJ20 -> 30 | AI18: ='FS Desroches Daily'!BL20 -> 50 | AJ18: ='FS Desroches Daily'!BN20 -> 50 | AK18: ='FS Desroches Daily'!BP20 -> 40 | AL18: ='FS Desroches Daily'!BR20 -> 36 | AM18: ='FS Desroches Daily'!BT20 -> 40 | AN18: ='FS Desroches Daily'!BV20 -> 33 | AO18: ='FS Desroches Daily'!BX20 -> 30 | AP18: ='FS Desroches Daily'!BZ20 -> 41 | AQ18: ='FS Desroches Daily'!CB20 -> 58.5 | AR18: ='FS Desroches Daily'!CD20 -> 9.9 | AS18: ='FS Desroches Daily'!CF20 -> 0.9 | AT18: ='FS Desroches Daily'!CH20 -> 47.6 | AU18: ='FS Desroches Daily'!CJ20 -> 300 | AV18: ='FS Desroches Daily'!CL20 -> 800 | AW18: ='FS Desroches Daily'!CM20 -> 121 | AX18: =IF(LPG!F25-LPG!F24<0,"0",(LPG!F25-LPG!F24)*1.8315) -> 0 | AY18: =IF(LPG!H25-LPG!H24<0,"0",(LPG!H25-LPG!H24)*1.8315) -> 0 | AZ18: =IF(LPG!J25-LPG!J24<0,"0",(LPG!J25-LPG!J24)*1.8315) -> 7.326 | BA18: =IF(LPG!M25-LPG!M24<0,"0",(LPG!M25-LPG!M24)*1.8315) -> 0 | BB18: =IF(LPG!Q25-LPG!Q24<0,"0",(LPG!Q25-LPG!Q24)*1.8315) -> 5.4945 | BC18: ='FS Desroches Daily'!CN20 -> 32
A19: Seychelles at Desroches Island | B19: 18 | C19: 8 | D19: 2022 | E19: ='FS Desroches Daily'!D21 -> 2500 | F19: ='FS Desroches Daily'!F21 -> 3100 | G19: ='FS Desroches Daily'!H21 -> 3400 | H19: ='FS Desroches Daily'!J21 -> 1400 | I19: ='FS Desroches Daily'!L21 -> 1900 | J19: ='FS Desroches Daily'!N21 -> 1400 | K19: ='FS Desroches Daily'!P21 -> 25 | L19: ='FS Desroches Daily'!R21 -> 2 | M19: ='FS Desroches Daily'!T21 -> 1.3 | N19: ='FS Desroches Daily'!V21 -> 375.9 | O19: ='FS Desroches Daily'!X21 -> 280 | P19: ='FS Desroches Daily'!Z21 -> 2800 | Q19: ='FS Desroches Daily'!AB21 -> 240 | R19: ='FS Desroches Daily'!AD21 -> 310 | S19: ='FS Desroches Daily'!AF21 -> 780 | T19: ='FS Desroches Daily'!AH21 -> 37 | U19: ='FS Desroches Daily'!AJ21 -> 760 | V19: ='FS Desroches Daily'!AL21 -> 180 | W19: ='FS Desroches Daily'!AN21 -> 220 | X19: ='FS Desroches Daily'!AP21 -> 130 | Y19: ='FS Desroches Daily'!AR21 -> 130 | Z19: ='FS Desroches Daily'!AT21 -> 200 | AA19: ='FS Desroches Daily'!AT21 -> 200 | AB19: ='FS Desroches Daily'!AV21 -> 180 | AC19: ='FS Desroches Daily'!AZ21 -> 170 | AD19: ='FS Desroches Daily'!BB21 -> 100 | AE19: ='FS Desroches Daily'!BD21 -> 40 | AF19: ='FS Desroches Daily'!BF21 -> 37 | AG19: ='FS Desroches Daily'!BH21 -> 30 | AH19: ='FS Desroches Daily'!BJ21 -> 30 | AI19: ='FS Desroches Daily'!BL21 -> 50 | AJ19: ='FS Desroches Daily'!BN21 -> 30 | AK19: ='FS Desroches Daily'!BP21 -> 40 | AL19: ='FS Desroches Daily'!BR21 -> 32 | AM19: ='FS Desroches Daily'!BT21 -> 30 | AN19: ='FS Desroches Daily'!BV21 -> 31 | AO19: ='FS Desroches Daily'!BX21 -> 30 | AP19: ='FS Desroches Daily'!BZ21 -> 39 | AQ19: ='FS Desroches Daily'!CB21 -> 50.9 | AR19: ='FS Desroches Daily'!CD21 -> 8.6 | AS19: ='FS Desroches Daily'!CF21 -> 6.1 | AT19: ='FS Desroches Daily'!CH21 -> 49 | AU19: ='FS Desroches Daily'!CJ21 -> 276 | AV19: ='FS Desroches Daily'!CL21 -> 1000 | AW19: ='FS Desroches Daily'!CM21 -> 120.7 | AX19: =IF(LPG!F26-LPG!F25<0,"0",(LPG!F26-LPG!F25)*1.8315) -> 0 | AY19: =IF(LPG!H26-LPG!H25<0,"0",(LPG!H26-LPG!H25)*1.8315) -> 0 | AZ19: =IF(LPG!J26-LPG!J25<0,"0",(LPG!J26-LPG!J25)*1.8315) -> 5.4945 | BA19: =IF(LPG!M26-LPG!M25<0,"0",(LPG!M26-LPG!M25)*1.8315) -> 3.663 | BB19: =IF(LPG!Q26-LPG!Q25<0,"0",(LPG!Q26-LPG!Q25)*1.8315) -> 7.326 | BC19: ='FS Desroches Daily'!CN21 -> 32
A20: Seychelles at Desroches Island | B20: 19 | C20: 8 | D20: 2022 | E20: ='FS Desroches Daily'!D22 -> 2500 | F20: ='FS Desroches Daily'!F22 -> 2900 | G20: ='FS Desroches Daily'!H22 -> 3200 | H20: ='FS Desroches Daily'!J22 -> 1500 | I20: ='FS Desroches Daily'!L22 -> 2000 | J20: ='FS Desroches Daily'!N22 -> 1600 | K20: ='FS Desroches Daily'!P22 -> 20 | L20: ='FS Desroches Daily'!R22 -> 3 | M20: ='FS Desroches Daily'!T22 -> 1.1 | N20: ='FS Desroches Daily'!V22 -> 321.5 | O20: ='FS Desroches Daily'!X22 -> 290 | P20: ='FS Desroches Daily'!Z22 -> 2700 | Q20: ='FS Desroches Daily'!AB22 -> 390 | R20: ='FS Desroches Daily'!AD22 -> 320 | S20: ='FS Desroches Daily'!AF22 -> 760 | T20: ='FS Desroches Daily'!AH22 -> 33 | U20: ='FS Desroches Daily'!AJ22 -> 650 | V20: ='FS Desroches Daily'!AL22 -> 200 | W20: ='FS Desroches Daily'!AN22 -> 220 | X20: ='FS Desroches Daily'!AP22 -> 170 | Y20: ='FS Desroches Daily'!AR22 -> 130 | Z20: ='FS Desroches Daily'!AT22 -> 120 | AA20: ='FS Desroches Daily'!AT22 -> 120 | AB20: ='FS Desroches Daily'!AV22 -> 190 | AC20: ='FS Desroches Daily'!AZ22 -> 160 | AD20: ='FS Desroches Daily'!BB22 -> 120 | AE20: ='FS Desroches Daily'!BD22 -> 90 | AF20: ='FS Desroches Daily'!BF22 -> 58 | AG20: ='FS Desroches Daily'!BH22 -> 30 | AH20: ='FS Desroches Daily'!BJ22 -> 30 | AI20: ='FS Desroches Daily'!BL22 -> 30 | AJ20: ='FS Desroches Daily'!BN22 -> 30 | AK20: ='FS Desroches Daily'!BP22 -> 40 | AL20: ='FS Desroches Daily'!BR22 -> 29 | AM20: ='FS Desroches Daily'!BT22 -> 40 | AN20: ='FS Desroches Daily'!BV22 -> 36 | AO20: ='FS Desroches Daily'!BX22 -> 40 | AP20: ='FS Desroches Daily'!BZ22 -> 40 | AQ20: ='FS Desroches Daily'!CB22 -> 48.9 | AR20: ='FS Desroches Daily'!CD22 -> 8.5 | AS20: ='FS Desroches Daily'!CF22 -> 4.3 | AT20: ='FS Desroches Daily'!CH22 -> 51 | AU20: ='FS Desroches Daily'!CJ22 -> 281 | AV20: ='FS Desroches Daily'!CL22 -> 1000 | AW20: ='FS Desroches Daily'!CM22 -> 130.5 | AX20: =IF(LPG!F27-LPG!F26<0,"0",(LPG!F27-LPG!F26)*1.8315) -> 0 | AY20: =IF(LPG!H27-LPG!H26<0,"0",(LPG!H27-LPG!H26)*1.8315) -> 0 | AZ20: =IF(LPG!J27-LPG!J26<0,"0",(LPG!J27-LPG!J26)*1.8315) -> 5.4945 | BA20: =IF(LPG!M27-LPG!M26<0,"0",(LPG!M27-LPG!M26)*1.8315) -> 3.663 | BB20: =IF(LPG!Q27-LPG!Q26<0,"0",(LPG!Q27-LPG!Q26)*1.8315) -> 7.326 | BC20: ='FS Desroches Daily'!CN22 -> 33
A21: Seychelles at Desroches Island | B21: 20 | C21: 8 | D21: 2022 | E21: ='FS Desroches Daily'!D23 -> 2200 | F21: ='FS Desroches Daily'!F23 -> 3200 | G21: ='FS Desroches Daily'!H23 -> 3400 | H21: ='FS Desroches Daily'!J23 -> 1400 | I21: ='FS Desroches Daily'!L23 -> 2400 | J21: ='FS Desroches Daily'!N23 -> 1700 | K21: ='FS Desroches Daily'!P23 -> 12 | L21: ='FS Desroches Daily'!R23 -> 4 | M21: ='FS Desroches Daily'!T23 -> 1.5 | N21: ='FS Desroches Daily'!V23 -> 463.9 | O21: ='FS Desroches Daily'!X23 -> 330 | P21: ='FS Desroches Daily'!Z23 -> 3000 | Q21: ='FS Desroches Daily'!AB23 -> 380 | R21: ='FS Desroches Daily'!AD23 -> 320 | S21: ='FS Desroches Daily'!AF23 -> 890 | T21: ='FS Desroches Daily'!AH23 -> 42 | U21: ='FS Desroches Daily'!AJ23 -> 640 | V21: ='FS Desroches Daily'!AL23 -> 230 | W21: ='FS Desroches Daily'!AN23 -> 250 | X21: ='FS Desroches Daily'!AP23 -> 210 | Y21: ='FS Desroches Daily'!AR23 -> 150 | Z21: ='FS Desroches Daily'!AT23 -> 140 | AA21: ='FS Desroches Daily'!AT23 -> 140 | AB21: ='FS Desroches Daily'!AV23 -> 150 | AC21: ='FS Desroches Daily'!AZ23 -> 180 | AD21: ='FS Desroches Daily'!BB23 -> 210 | AE21: ='FS Desroches Daily'!BD23 -> 100 | AF21: ='FS Desroches Daily'!BF23 -> 30 | AG21: ='FS Desroches Daily'!BH23 -> 20 | AH21: ='FS Desroches Daily'!BJ23 -> 30 | AI21: ='FS Desroches Daily'!BL23 -> 40 | AJ21: ='FS Desroches Daily'!BN23 -> 30 | AK21: ='FS Desroches Daily'!BP23 -> 40 | AL21: ='FS Desroches Daily'!BR23 -> 28 | AM21: ='FS Desroches Daily'!BT23 -> 30 | AN21: ='FS Desroches Daily'!BV23 -> 33 | AO21: ='FS Desroches Daily'!BX23 -> 40 | AP21: ='FS Desroches Daily'!BZ23 -> 39 | AQ21: ='FS Desroches Daily'!CB23 -> 56.4 | AR21: ='FS Desroches Daily'!CD23 -> 11.5 | AS21: ='FS Desroches Daily'!CF23 -> 5.9 | AT21: ='FS Desroches Daily'!CH23 -> 49.2 | AU21: ='FS Desroches Daily'!CJ23 -> 281 | AV21: ='FS Desroches Daily'!CL23 -> 1000 | AW21: ='FS Desroches Daily'!CM23 -> 101.5 | AX21: =IF(LPG!F28-LPG!F27<0,"0",(LPG!F28-LPG!F27)*1.8315) -> 0 | AY21: =IF(LPG!H28-LPG!H27<0,"0",(LPG!H28-LPG!H27)*1.8315) -> 0 | AZ21: =IF(LPG!J28-LPG!J27<0,"0",(LPG!J28-LPG!J27)*1.8315) -> 5.4945 | BA21: =IF(LPG!M28-LPG!M27<0,"0",(LPG!M28-LPG!M27)*1.8315) -> 3.663 | BB21: =IF(LPG!Q28-LPG!Q27<0,"0",(LPG!Q28-LPG!Q27)*1.8315) -> 5.4945 | BC21: ='FS Desroches Daily'!CN23 -> 30
A22: Seychelles at Desroches Island | B22: 21 | C22: 8 | D22: 2022 | E22: ='FS Desroches Daily'!D24 -> 3000 | F22: ='FS Desroches Daily'!F24 -> 3200 | G22: ='FS Desroches Daily'!H24 -> 3300 | H22: ='FS Desroches Daily'!J24 -> 1400 | I22: ='FS Desroches Daily'!L24 -> 2000 | J22: ='FS Desroches Daily'!N24 -> 1600 | K22: ='FS Desroches Daily'!P24 -> 31 | L22: ='FS Desroches Daily'!R24 -> 2 | M22: ='FS Desroches Daily'!T24 -> 1.3 | N22: ='FS Desroches Daily'!V24 -> 337.2 | O22: ='FS Desroches Daily'!X24 -> 270 | P22: ='FS Desroches Daily'!Z24 -> 2700 | Q22: ='FS Desroches Daily'!AB24 -> 330 | R22: ='FS Desroches Daily'!AD24 -> 290 | S22: ='FS Desroches Daily'!AF24 -> 870 | T22: ='FS Desroches Daily'!AH24 -> 36 | U22: ='FS Desroches Daily'!AJ24 -> 510 | V22: ='FS Desroches Daily'!AL24 -> 180 | W22: ='FS Desroches Daily'!AN24 -> 180 | X22: ='FS Desroches Daily'!AP24 -> 180 | Y22: ='FS Desroches Daily'!AR24 -> 130 | Z22: ='FS Desroches Daily'!AT24 -> 120 | AA22: ='FS Desroches Daily'!AT24 -> 120 | AB22: ='FS Desroches Daily'!AV24 -> 120 | AC22: ='FS Desroches Daily'!AZ24 -> 140 | AD22: ='FS Desroches Daily'!BB24 -> 150 | AE22: ='FS Desroches Daily'!BD24 -> 90 | AF22: ='FS Desroches Daily'!BF24 -> 17 | AG22: ='FS Desroches Daily'!BH24 -> 40 | AH22: ='FS Desroches Daily'!BJ24 -> 30 | AI22: ='FS Desroches Daily'!BL24 -> 30 | AJ22: ='FS Desroches Daily'!BN24 -> 40 | AK22: ='FS Desroches Daily'!BP24 -> 50 | AL22: ='FS Desroches Daily'!BR24 -> 36 | AM22: ='FS Desroches Daily'!BT24 -> 50 | AN22: ='FS Desroches Daily'!BV24 -> 35 | AO22: ='FS Desroches Daily'!BX24 -> 40 | AP22: ='FS Desroches Daily'!BZ24 -> 43 | AQ22: ='FS Desroches Daily'!CB24 -> 53.5 | AR22: ='FS Desroches Daily'!CD24 -> 6.9 | AS22: ='FS Desroches Daily'!CF24 -> 2.9 | AT22: ='FS Desroches Daily'!CH24 -> 52.8 | AU22: ='FS Desroches Daily'!CJ24 -> 281 | AV22: ='FS Desroches Daily'!CL24 -> 1000 | AW22: ='FS Desroches Daily'!CM24 -> 108.2 | AX22: =IF(LPG!F29-LPG!F28<0,"0",(LPG!F29-LPG!F28)*1.8315) -> 0 | AY22: =IF(LPG!H29-LPG!H28<0,"0",(LPG!H29-LPG!H28)*1.8315) -> 0 | AZ22: =IF(LPG!J29-LPG!J28<0,"0",(LPG!J29-LPG!J28)*1.8315) -> 5.4945 | BA22: =IF(LPG!M29-LPG!M28<0,"0",(LPG!M29-LPG!M28)*1.8315) -> 1.8315 | BB22: =IF(LPG!Q29-LPG!Q28<0,"0",(LPG!Q29-LPG!Q28)*1.8315) -> 5.4945 | BC22: ='FS Desroches Daily'!CN24 -> 30
A23: Seychelles at Desroches Island | B23: 22 | C23: 8 | D23: 2022 | E23: ='FS Desroches Daily'!D25 -> 2000 | F23: ='FS Desroches Daily'!F25 -> 3000 | G23: ='FS Desroches Daily'!H25 -> 2900 | H23: ='FS Desroches Daily'!J25 -> 1500 | I23: ='FS Desroches Daily'!L25 -> 2000 | J23: ='FS Desroches Daily'!N25 -> 1600 | K23: ='FS Desroches Daily'!P25 -> 36 | L23: ='FS Desroches Daily'!R25 -> 4 | M23: ='FS Desroches Daily'!T25 -> 1.2 | N23: ='FS Desroches Daily'!V25 -> 434.6 | O23: ='FS Desroches Daily'!X25 -> 350 | P23: ='FS Desroches Daily'!Z25 -> 2900 | Q23: ='FS Desroches Daily'!AB25 -> 370 | R23: ='FS Desroches Daily'!AD25 -> 330 | S23: ='FS Desroches Daily'!AF25 -> 880 | T23: ='FS Desroches Daily'!AH25 -> 42 | U23: ='FS Desroches Daily'!AJ25 -> 640 | V23: ='FS Desroches Daily'!AL25 -> 200 | W23: ='FS Desroches Daily'!AN25 -> 170 | X23: ='FS Desroches Daily'!AP25 -> 210 | Y23: ='FS Desroches Daily'!AR25 -> 160 | Z23: ='FS Desroches Daily'!AT25 -> 140 | AA23: ='FS Desroches Daily'!AT25 -> 140 | AB23: ='FS Desroches Daily'!AV25 -> 120 | AC23: ='FS Desroches Daily'!AZ25 -> 230 | AD23: ='FS Desroches Daily'!BB25 -> 160 | AE23: ='FS Desroches Daily'!BD25 -> 90 | AF23: ='FS Desroches Daily'!BF25 -> 76 | AG23: ='FS Desroches Daily'!BH25 -> 30 | AH23: ='FS Desroches Daily'!BJ25 -> 30 | AI23: ='FS Desroches Daily'!BL25 -> 40 | AJ23: ='FS Desroches Daily'!BN25 -> 30 | AK23: ='FS Desroches Daily'!BP25 -> 40 | AL23: ='FS Desroches Daily'!BR25 -> 32 | AM23: ='FS Desroches Daily'!BT25 -> 40 | AN23: ='FS Desroches Daily'!BV25 -> 32 | AO23: ='FS Desroches Daily'!BX25 -> 40 | AP23: ='FS Desroches Daily'!BZ25 -> 37 | AQ23: ='FS Desroches Daily'!CB25 -> 69.5 | AR23: ='FS Desroches Daily'!CD25 -> 11.1 | AS23: ='FS Desroches Daily'!CF25 -> 2 | AT23: ='FS Desroches Daily'!CH25 -> 47.3 | AU23: ='FS Desroches Daily'!CJ25 -> 295 | AV23: ='FS Desroches Daily'!CL25 -> 1000 | AW23: ='FS Desroches Daily'!CM25 -> 128.8 | AX23: =IF(LPG!F30-LPG!F29<0,"0",(LPG!F30-LPG!F29)*1.8315) -> 0 | AY23: =IF(LPG!H30-LPG!H29<0,"0",(LPG!H30-LPG!H29)*1.8315) -> 0 | AZ23: =IF(LPG!J30-LPG!J29<0,"0",(LPG!J30-LPG!J29)*1.8315) -> 0 | BA23: =IF(LPG!M30-LPG!M29<0,"0",(LPG!M30-LPG!M29)*1.8315) -> 0 | BB23: =IF(LPG!Q30-LPG!Q29<0,"0",(LPG!Q30-LPG!Q29)*1.8315) -> 0 | BC23: ='FS Desroches Daily'!CN25 -> 30
A24: Seychelles at Desroches Island | B24: 23 | C24: 8 | D24: 2022 | E24: ='FS Desroches Daily'!D26 -> 0 | F24: ='FS Desroches Daily'!F26 -> 0 | G24: ='FS Desroches Daily'!H26 -> 0 | H24: ='FS Desroches Daily'!J26 -> 0 | I24: ='FS Desroches Daily'!L26 -> 0 | J24: ='FS Desroches Daily'!N26 | K24: ='FS Desroches Daily'!P26 | L24: ='FS Desroches Daily'!R26 | M24: ='FS Desroches Daily'!T26 | N24: ='FS Desroches Daily'!V26 | O24: ='FS Desroches Daily'!X26 | P24: ='FS Desroches Daily'!Z26 | Q24: ='FS Desroches Daily'!AB26 | R24: ='FS Desroches Daily'!AD26 | S24: ='FS Desroches Daily'!AF26 | T24: ='FS Desroches Daily'!AH26 | U24: ='FS Desroches Daily'!AJ26 | V24: ='FS Desroches Daily'!AL26 | W24: ='FS Desroches Daily'!AN26 | X24: ='FS Desroches Daily'!AP26 | Y24: ='FS Desroches Daily'!AR26 | Z24: ='FS Desroches Daily'!AT26 | AA24: ='FS Desroches Daily'!AT26 | AB24: ='FS Desroches Daily'!AV26 | AC24: ='FS Desroches Daily'!AZ26 | AD24: ='FS Desroches Daily'!BB26 | AE24: ='FS Desroches Daily'!BD26 | AF24: ='FS Desroches Daily'!BF26 | AG24: ='FS Desroches Daily'!BH26 | AH24: ='FS Desroches Daily'!BJ26 | AI24: ='FS Desroches Daily'!BL26 | AJ24: ='FS Desroches Daily'!BN26 | AK24: ='FS Desroches Daily'!BP26 | AL24: ='FS Desroches Daily'!BR26 | AM24: ='FS Desroches Daily'!BT26 | AN24: ='FS Desroches Daily'!BV26 | AO24: ='FS Desroches Daily'!BX26 | AP24: ='FS Desroches Daily'!BZ26 | AQ24: ='FS Desroches Daily'!CB26 | AR24: ='FS Desroches Daily'!CD26 | AS24: ='FS Desroches Daily'!CF26 | AT24: ='FS Desroches Daily'!CH26 | AU24: ='FS Desroches Daily'!CJ26 | AV24: ='FS Desroches Daily'!CL26 | AW24: ='FS Desroches Daily'!CM26 -> #VALUE! | AX24: =IF(LPG!F31-LPG!F30<0,"0",(LPG!F31-LPG!F30)*1.8315) -> 0 | AY24: =IF(LPG!H31-LPG!H30<0,"0",(LPG!H31-LPG!H30)*1.8315) -> 0 | AZ24: =IF(LPG!J31-LPG!J30<0,"0",(LPG!J31-LPG!J30)*1.8315) -> 0 | BA24: =IF(LPG!M31-LPG!M30<0,"0",(LPG!M31-LPG!M30)*1.8315) -> 0 | BB24: =IF(LPG!Q31-LPG!Q30<0,"0",(LPG!Q31-LPG!Q30)*1.8315) -> 0 | BC24: ='FS Desroches Daily'!CN26 -> 32
