Workbook

Sheet TOTAL
A1: Site Name | B1: Day | C1: Month | D1: Year | E1: Total Electricity Kwh | F1: Electricity Tariff ($/Kwh) | G1: Total Fuel Oil (Liter) | H1: Fuel Oil $/Liter | I1: Water Utility Supply (m3) m3 | J1: Water Utility Supply (m3) $/m3 | K1: LPG (Kg) | L1: LPG $/Kg | M1: Room Nights | N1: Total Guests | O1: Food Covers
A2: Maldives at Kuda Huraa | B2: 1 | C2: 8 | D2: 2022 | E2: 19350 | G2: 5192 | I2: 326 | M2: 12 | N2: 49 | O2: 106
A3: Maldives at Kuda Huraa | B3: =B2+1 -> 2 | C3: 8 | D3: 2022 | E3: 19530 | G3: 5564 | I3: 336 | M3: 18 | N3: 58 | O3: 126
A4: Maldives at Kuda Huraa | B4: =B3+1 -> 3 | C4: 8 | D4: 2022 | E4: 21162 | G4: 5711 | I4: 301 | M4: 17 | N4: 50 | O4: 119
A5: Maldives at Kuda Huraa | B5: =B4+1 -> 4 | C5: 8 | D5: 2022 | E5: 19068 | G5: 5452 | I5: 259 | M5: 21 | N5: 57 | O5: 123
A6: Maldives at Kuda Huraa | B6: =B5+1 -> 5 | C6: 8 | D6: 2022 | E6: 18570 | G6: 5119 | I6: 282 | M6: 22 | N6: 58 | O6: 149
A7: Maldives at Kuda Huraa | B7: =B6+1 -> 6 | C7: 8 | D7: 2022 | E7: 19560 | G7: 5378 | I7: 341 | M7: 22 | N7: 60 | O7: 180
A8: Maldives at Kuda Huraa | B8: =B7+1 -> 7 | C8: 8 | D8: 2022 | E8: 20700 | G8: 5780 | I8: 333 | M8: 22 | N8: 66 | O8: 174
A9: Maldives at Kuda Huraa | B9: =B8+1 -> 8 | C9: 8 | D9: 2022 | E9: 20510 | G9: 5655 | I9: 349 | M9: 29 | N9: 82 | O9: 182
A10: Maldives at Kuda Huraa | B10: =B9+1 -> 9 | C10: 8 | D10: 2022 | E10: 19900 | G10: 5496 | I10: 296 | M10: 32 | N10: 91 | O10: 198
A11: Maldives at Kuda Huraa | B11: =B10+1 -> 10 | C11: 8 | D11: 2022 | E11: 19910 | G11: 5336 | I11: 315 | M11: 30 | N11: 87 | O11: 333
A12: Maldives at Kuda Huraa | B12: =B11+1 -> 11 | C12: 8 | D12: 2022 | E12: 18760 | G12: 5176 | I12: 312 | M12: 35 | N12: 99 | O12: 210
A13: Maldives at Kuda Huraa | B13: =B12+1 -> 12 | C13: 8 | D13: 2022 | E13: 19000 | G13: 5433 | I13: 297 | M13: 39 | N13: 115 | O13: 241
A14: Maldives at Kuda Huraa | B14: =B13+1 -> 13 | C14: 8 | D14: 2022 | M14: 36 | N14: 100 | O14: 245
A15: Maldives at Kuda Huraa | B15: =B14+1 -> 14 | C15: 8 | D15: 2022 | M15: 28 | N15: 79 | O15: 191
A16: Maldives at Kuda Huraa | B16: =B15+1 -> 15 | C16: 8 | D16: 2022 | M16: 23 | N16: 66 | O16: 187
A17: Maldives at Kuda Huraa | B17: =B16+1 -> 16 | C17: 8 | D17: 2022 | M17: 28 | N17: 73 | O17: 196
A18: Maldives at Kuda Huraa | B18: =B17+1 -> 17 | C18: 8 | D18: 2022 | M18: 28 | N18: 71 | O18: 202
A19: Maldives at Kuda Huraa | B19: =B18+1 -> 18 | C19: 8 | D19: 2022 | M19: 33 | N19: 93 | O19: 195
A20: Maldives at Kuda Huraa | B20: =B19+1 -> 19 | C20: 8 | D20: 2022 | M20: 27 | N20: 76 | O20: 245
A21: Maldives at Kuda Huraa | B21: =B20+1 -> 20 | C21: 8 | D21: 2022 | M21: 30 | N21: 86 | O21: 233
A22: Maldives at Kuda Huraa | B22: =B21+1 -> 21 | C22: 8 | D22: 2022 | M22: 26 | N22: 83 | O22: 208
A23: Maldives at Kuda Huraa | B23: =B22+1 -> 22 | C23: 8 | D23: 2022 | M23: 33 | N23: 130 | O23: 268
A24: Maldives at Kuda Huraa | B24: =B23+1 -> 23 | C24: 8 | D24: 2022 | M24: 25 | N24: 114 | O24: 230
A25: Maldives at Kuda Huraa | B25: =B24+1 -> 24 | C25: 8 | D25: 2022 | M25: 21 | N25: 119 | O25: 204
... A31: Maldives at Kuda Huraa | B31: =B30+1 -> 30 | C31: 8 | D31: 2022 | M31: 15 | N31: 54 | O31: 133
A32: Maldives at Kuda Huraa | B32: =B31+1 -> 31 | C32: 8 | D32: 2022
A33: Total | E33: =SUM(E2:E32) -> 236020 | F33: 0 | G33: =SUM(G2:G32) -> 65292 | H33: 0 | I33: =SUM(I2:I32) -> 3747 | J33: 0 | K33: =SUM(K2:K32) -> 0 | L33: 0 | M33: =SUM(M2:M32) -> 746 | N33: =SUM(N2:N32) -> 2497 | O33: =SUM(O2:O32) -> 5803

Sheet Kwh Reading
A1: Electric Consumption Record (4pm)
A2: Month | B2: BOH-1/ B&C Block GWH | C2: Pastry MWH | D2: Feeder 401-419 KWH | E2: Feeder 301-319 KWH | F2: Kitchen GWH | G2: Feeder 201-208 GWH | H2: Feeder 113-123 | I2: M - Block /PC MWH | J2: Laundry MWH | M2: Feeder 101-112 MWH | N2: Feeder 217-224 | O2: Spa MWH | P2: Feeder 124-134 | Q2: Feeder 209-216 | R2: STP -1 &2 MWH | S2: STP -3 MWH | T2: Reef Club MWH | V2: Room Nights | W2: Total Guests | X2: Food Covers
J3: A | K3: B | L3: C
A4: 44774 | B4: 1.4441 | C4: 328.18 | D4: 8299585.3 | E4: 9301762.3 | F4: 3.4184 | G4: 1.0938 | H4: 1.008 | I4: 356.43 | J4: 496.57 | K4: 476.71 | L4: 325.77 | M4: 819.48 | N4: 746.05 | O4: 236.09 | P4: 995.81 | Q4: 743.73 | R4: 190.15 | S4: 169.45 | T4: 613.67 | V4: 12 | W4: 49 | X4: 106
A5: 44775 | B5: 1.445 | C5: 328.41 | D5: 8301462.5 | E5: 9303951 | F5: 3.421 | G5: 1.0945 | H5: 1.0089 | I5: 356.7 | J5: 497.01 | K5: 477.03 | L5: 326.02 | M5: 820.09 | N5: 746.26 | O5: 236.29 | P5: 996.51 | Q5: 743.96 | R5: 190.15 | S5: 169.59 | T5: 614.15 | V5: 18 | W5: 58 | X5: 126
A6: 44776 | B6: 1.4459 | C6: 328.67 | D6: 8303584.5 | E6: 9306579.5 | F6: 3.4236 | G6: 1.0952 | H6: 1.01 | I6: 357 | J6: 497.27 | K6: 477.25 | L6: 326.21 | M6: 820.7 | N6: 746.57 | O6: 236.5 | P6: 997.23 | Q6: 744.33 | R6: 190.15 | S6: 169.73 | T6: 614.65 | V6: 17 | W6: 50 | X6: 119
A7: 44777 | B7: 1.4469 | C7: 328.92 | D7: 8305756.4 | E7: 9309303.2 | F7: 3.4263 | G7: 1.096 | H7: 1.0111 | I7: 357.33 | J7: 497.75 | K7: 477.53 | L7: 326.45 | M7: 821.39 | N7: 747 | O7: 236.68 | P7: 997.93 | Q7: 744.72 | R7: 190.15 | S7: 169.88 | T7: 615.16 | V7: 21 | W7: 57 | X7: 123
A8: 44778 | B8: 1.4479 | C8: 329.16 | D8: 8307493.3 | E8: 9311725.6 | F8: 3.4289 | G8: 1.0967 | H8: 1.0121 | I8: 357.63 | J8: 498.16 | K8: 477.97 | L8: 326.66 | M8: 822.04 | N8: 747.37 | O8: 236.89 | P8: 998.53 | Q8: 745.06 | R8: 190.15 | S8: 170.02 | T8: 615.64 | V8: 22 | W8: 58 | X8: 149
A9: 44779 | B9: 1.4488 | C9: 329.4 | D9: 8309192.6 | E9: 9313795.6 | F9: 3.4315 | G9: 1.0974 | H9: 1.013 | I9: 357.91 | J9: 498.55 | K9: 478 | L9: 326.88 | M9: 822.65 | N9: 747.66 | O9: 237.1 | P9: 999.15 | Q9: 745.37 | R9: 190.15 | S9: 170.16 | T9: 615.89 | V9: 22 | W9: 60 | X9: 180
A10: 44780 | B10: 1.4498 | C10: 329.65 | D10: 8311079.8 | E10: 9316293.1 | F10: 3.434 | G10: 1.0981 | H10: 1.014 | I10: 358.22 | J10: 499.1 | K10: 478.26 | L10: 327.1 | M10: 823.33 | N10: 747.89 | O10: 237.29 | P10: 999.72 | Q10: 745.68 | R10: 190.15 | S10: 170.3 | T10: 616.35 | V10: 22 | W10: 66 | X10: 174
A11: 44781 | B11: 1.4508 | C11: 329.88 | D11: 8313030.4 | E11: 9318899.1 | F11: 3.4366 | G11: 1.0989 | H11: 1.0151 | I11: 358.55 | J11: 499.52 | K11: 478.57 | L11: 327.35 | M11: 824.04 | N11: 748.18 | O11: 237.49 | P11: 1.0004 | Q11: 746 | R11: 190.15 | S11: 170.44 | T11: 616.84 | V11: 29 | W11: 82 | X11: 182
A12: 44782 | B12: 1.4519 | C12: 330.12 | D12: 8315101.3 | E12: 9321407.5 | F12: 3.4392 | G12: 1.0998 | H12: 1.0161 | I12: 358.88 | J12: 499.91 | K12: 478.83 | L12: 327.58 | M12: 824.72 | N12: 748.5 | O12: 237.68 | P12: 1.0011 | Q12: 746.37 | R12: 190.15 | S12: 170.58 | T12: 617.3 | V12: 32 | W12: 91 | X12: 198
A13: 44783 | B13: 1.4529 | C13: 330.37 | D13: 8317104.6 | E13: 9323837.3 | F13: 3.4417 | G13: 1.1006 | H13: 1.0172 | I13: 359.18 | J13: 500.32 | K13: 479.07 | L13: 327.83 | M13: 825.42 | N13: 748.8 | O13: 237.87 | P13: 1.0018 | Q13: 746.7 | R13: 190.15 | S13: 170.71 | T13: 617.78 | V13: 30 | W13: 87 | X13: 333
A14: 44784 | B14: 1.454 | C14: 330.64 | D14: 8318835.5 | E14: 9326174.7 | F14: 3.4443 | G14: 1.1014 | H14: 1.0182 | I14: 359.48 | J14: 500.72 | K14: 479.36 | L14: 328.06 | M14: 826.11 | N14: 749.1 | O14: 238.04 | P14: 1.0026 | Q14: 747.04 | R14: 190.15 | S14: 170.86 | T14: 618.29 | V14: 35 | W14: 99 | X14: 210
A15: 44785 | B15: 1.4551 | C15: 330.94 | D15: 8320799.5 | E15: 9328678.7 | F15: 3.4471 | G15: 1.1022 | H15: 1.0194 | I15: 359.8 | J15: 501.83 | K15: 479.82 | L15: 328.42 | M15: 826.84 | N15: 749.61 | O15: 238.27 | P15: 1.0033 | Q15: 747.41 | R15: 190.15 | S15: 171.04 | T15: 618.72 | V15: 39 | W15: 115 | X15: 241
... A33: 44803 | B33: 1.474 | C33: 335.59 | D33: 8351916 | E33: 93690412 | F33: 3.4946 | G33: 1.1151 | H33: 1.0346 | I33: 364.83 | J33: 511.09 | K33: 485.58 | L33: 332.72 | M33: 837.2 | N33: 756.86 | O33: 242.04 | P33: 1.0164 | Q33: 751.4 | R33: 190.15 | S33: 173.66 | T33: 626.73 | V33: 15 | W33: 54 | X33: 133
A34: 44804
A35: 44805 | V35: =SUM(V4:V34) -> 746 | W35: =SUM(W4:W34) -> 2497 | X35: =SUM(X4:X34) -> 5803
T42: ……..

Sheet Kwh Consumption
A2: Date | B2: Total KWH | C2: Reef Club KWH | D2: Kitchen KWH | E2: Pastry KWH | F2: Laundry KWH | I2: STP -1 &2 KWH | J2: STP -3 KWH | K2: M - Block /PC KWH | L2: B&C Block KWH | M2: Guest Room Beach Pavilion & Beach Bungalow KWH | S2: Guest Room Water Bungalow KWH | U2: Spa KWH | V2: Others KWH
F3: A | G3: B | H3: C | M3: Feeder -101-112 | N3: Feeder -113-123 | O3: Feeder -124-134 | P3: Feeder -201-208 | Q3: Feeder -209-216 | R3: Feeder -217-224 | S3: Feeder -301-319 | T3: Feeder 401-419
A4: ='Kwh Reading'!A4 -> 44774 | B4: =TOTAL!E2 -> 19350 | C4: =('Kwh Reading'!T5-'Kwh Reading'!T4)*1000 -> 480 | D4: =('Kwh Reading'!F5-'Kwh Reading'!F4)*1000000 -> 2600 | E4: =('Kwh Reading'!C5-'Kwh Reading'!C4)*1000 -> 230 | F4: =('Kwh Reading'!J5-'Kwh Reading'!J4)*1000 -> 440 | G4: =('Kwh Reading'!K5-'Kwh Reading'!K4)*1000 -> 320 | H4: =('Kwh Reading'!L5-'Kwh Reading'!L4)*1000 -> 250 | I4: =('Kwh Reading'!R5-'Kwh Reading'!R4)*1000 -> 0 | J4: =('Kwh Reading'!S5-'Kwh Reading'!S4)*1000 -> 140 | K4: =('Kwh Reading'!I5-'Kwh Reading'!I4)*1000 -> 270 | L4: =('Kwh Reading'!B5-'Kwh Reading'!B4)*1000000 -> 900 | M4: =('Kwh Reading'!M5-'Kwh Reading'!M4)*1000 -> 610 | N4: =('Kwh Reading'!H5-'Kwh Reading'!H4)*1000 -> 0.9 | O4: =('Kwh Reading'!P5-'Kwh Reading'!P4)*1000 -> 700 | P4: =('Kwh Reading'!G5-'Kwh Reading'!G4)*1000000 -> 700 | Q4: =('Kwh Reading'!Q5-'Kwh Reading'!Q4)*1000 -> 230 | R4: =('Kwh Reading'!N5-'Kwh Reading'!N4)*1000 -> 210 | S4: ='Kwh Reading'!E5-'Kwh Reading'!E4 -> 2188.65 | T4: ='Kwh Reading'!D5-'Kwh Reading'!D4 -> 1877.15 | U4: =('Kwh Reading'!O5-'Kwh Reading'!O4)*1000 -> 200 | V4: =B4-(SUM(C4:U4)) -> 7003.3
A5: ='Kwh Reading'!A5 -> 44775 | B5: =TOTAL!E3 -> 19530 | C5: =('Kwh Reading'!T6-'Kwh Reading'!T5)*1000 -> 500 | D5: =('Kwh Reading'!F6-'Kwh Reading'!F5)*1000000 -> 2600 | E5: =('Kwh Reading'!C6-'Kwh Reading'!C5)*1000 -> 260 | F5: =('Kwh Reading'!J6-'Kwh Reading'!J5)*1000 -> 260 | G5: =('Kwh Reading'!K6-'Kwh Reading'!K5)*1000 -> 220 | H5: =('Kwh Reading'!L6-'Kwh Reading'!L5)*1000 -> 190 | I5: =('Kwh Reading'!R6-'Kwh Reading'!R5)*1000 -> 0 | J5: =('Kwh Reading'!S6-'Kwh Reading'!S5)*1000 -> 140 | K5: =('Kwh Reading'!I6-'Kwh Reading'!I5)*1000 -> 300 | L5: =('Kwh Reading'!B6-'Kwh Reading'!B5)*1000000 -> 900 | M5: =('Kwh Reading'!M6-'Kwh Reading'!M5)*1000 -> 610 | N5: =('Kwh Reading'!H6-'Kwh Reading'!H5)*1000 -> 1.1 | O5: =('Kwh Reading'!P6-'Kwh Reading'!P5)*1000 -> 720 | P5: =('Kwh Reading'!G6-'Kwh Reading'!G5)*1000000 -> 700 | Q5: =('Kwh Reading'!Q6-'Kwh Reading'!Q5)*1000 -> 370 | R5: =('Kwh Reading'!N6-'Kwh Reading'!N5)*1000 -> 310 | S5: ='Kwh Reading'!E6-'Kwh Reading'!E5 -> 2628.52 | T5: ='Kwh Reading'!D6-'Kwh Reading'!D5 -> 2121.96 | U5: =('Kwh Reading'!O6-'Kwh Reading'!O5)*1000 -> 210 | V5: =B5-(SUM(C5:U5)) -> 6488.42
A6: ='Kwh Reading'!A6 -> 44776 | B6: =TOTAL!E4 -> 21162 | C6: =('Kwh Reading'!T7-'Kwh Reading'!T6)*1000 -> 510 | D6: =('Kwh Reading'!F7-'Kwh Reading'!F6)*1000000 -> 2700 | E6: =('Kwh Reading'!C7-'Kwh Reading'!C6)*1000 -> 250 | F6: =('Kwh Reading'!J7-'Kwh Reading'!J6)*1000 -> 480 | G6: =('Kwh Reading'!K7-'Kwh Reading'!K6)*1000 -> 280 | H6: =('Kwh Reading'!L7-'Kwh Reading'!L6)*1000 -> 240 | I6: =('Kwh Reading'!R7-'Kwh Reading'!R6)*1000 -> 0 | J6: =('Kwh Reading'!S7-'Kwh Reading'!S6)*1000 -> 150 | K6: =('Kwh Reading'!I7-'Kwh Reading'!I6)*1000 -> 330 | L6: =('Kwh Reading'!B7-'Kwh Reading'!B6)*1000000 -> 1000 | M6: =('Kwh Reading'!M7-'Kwh Reading'!M6)*1000 -> 690 | N6: =('Kwh Reading'!H7-'Kwh Reading'!H6)*1000 -> 1.1 | O6: =('Kwh Reading'!P7-'Kwh Reading'!P6)*1000 -> 700 | P6: =('Kwh Reading'!G7-'Kwh Reading'!G6)*1000000 -> 800 | Q6: =('Kwh Reading'!Q7-'Kwh Reading'!Q6)*1000 -> 390 | R6: =('Kwh Reading'!N7-'Kwh Reading'!N6)*1000 -> 430 | S6: ='Kwh Reading'!E7-'Kwh Reading'!E6 -> 2723.71 | T6: ='Kwh Reading'!D7-'Kwh Reading'!D6 -> 2171.93 | U6: =('Kwh Reading'!O7-'Kwh Reading'!O6)*1000 -> 180 | V6: =B6-(SUM(C6:U6)) -> 7135.26
A7: ='Kwh Reading'!A7 -> 44777 | B7: =TOTAL!E5 -> 19068 | C7: =('Kwh Reading'!T8-'Kwh Reading'!T7)*1000 -> 480 | D7: =('Kwh Reading'!F8-'Kwh Reading'!F7)*1000000 -> 2600 | E7: =('Kwh Reading'!C8-'Kwh Reading'!C7)*1000 -> 240 | F7: =('Kwh Reading'!J8-'Kwh Reading'!J7)*1000 -> 410 | G7: =('Kwh Reading'!K8-'Kwh Reading'!K7)*1000 -> 440 | H7: =('Kwh Reading'!L8-'Kwh Reading'!L7)*1000 -> 210 | I7: =('Kwh Reading'!R8-'Kwh Reading'!R7)*1000 -> 0 | J7: =('Kwh Reading'!S8-'Kwh Reading'!S7)*1000 -> 140 | K7: =('Kwh Reading'!I8-'Kwh Reading'!I7)*1000 -> 300 | L7: =('Kwh Reading'!B8-'Kwh Reading'!B7)*1000000 -> 1000 | M7: =('Kwh Reading'!M8-'Kwh Reading'!M7)*1000 -> 650 | N7: =('Kwh Reading'!H8-'Kwh Reading'!H7)*1000 -> 1 | O7: =('Kwh Reading'!P8-'Kwh Reading'!P7)*1000 -> 600 | P7: =('Kwh Reading'!G8-'Kwh Reading'!G7)*1000000 -> 700 | Q7: =('Kwh Reading'!Q8-'Kwh Reading'!Q7)*1000 -> 340 | R7: =('Kwh Reading'!N8-'Kwh Reading'!N7)*1000 -> 370 | S7: ='Kwh Reading'!E8-'Kwh Reading'!E7 -> 2422.36 | T7: ='Kwh Reading'!D8-'Kwh Reading'!D7 -> 1736.92 | U7: =('Kwh Reading'!O8-'Kwh Reading'!O7)*1000 -> 210 | V7: =B7-(SUM(C7:U7)) -> 6217.72
A8: ='Kwh Reading'!A8 -> 44778 | B8: =TOTAL!E6 -> 18570 | C8: =('Kwh Reading'!T9-'Kwh Reading'!T8)*1000 -> 250 | D8: =('Kwh Reading'!F9-'Kwh Reading'!F8)*1000000 -> 2600 | E8: =('Kwh Reading'!C9-'Kwh Reading'!C8)*1000 -> 240 | F8: =('Kwh Reading'!J9-'Kwh Reading'!J8)*1000 -> 390 | G8: =('Kwh Reading'!K9-'Kwh Reading'!K8)*1000 -> 30 | H8: =('Kwh Reading'!L9-'Kwh Reading'!L8)*1000 -> 220 | I8: =('Kwh Reading'!R9-'Kwh Reading'!R8)*1000 -> 0 | J8: =('Kwh Reading'!S9-'Kwh Reading'!S8)*1000 -> 140 | K8: =('Kwh Reading'!I9-'Kwh Reading'!I8)*1000 -> 280 | L8: =('Kwh Reading'!B9-'Kwh Reading'!B8)*1000000 -> 900 | M8: =('Kwh Reading'!M9-'Kwh Reading'!M8)*1000 -> 610 | N8: =('Kwh Reading'!H9-'Kwh Reading'!H8)*1000 -> 0.9 | O8: =('Kwh Reading'!P9-'Kwh Reading'!P8)*1000 -> 620 | P8: =('Kwh Reading'!G9-'Kwh Reading'!G8)*1000000 -> 700 | Q8: =('Kwh Reading'!Q9-'Kwh Reading'!Q8)*1000 -> 310 | R8: =('Kwh Reading'!N9-'Kwh Reading'!N8)*1000 -> 290 | S8: ='Kwh Reading'!E9-'Kwh Reading'!E8 -> 2070 | T8: ='Kwh Reading'!D9-'Kwh Reading'!D8 -> 1699.32 | U8: =('Kwh Reading'!O9-'Kwh Reading'!O8)*1000 -> 210 | V8: =B8-(SUM(C8:U8)) -> 7009.78
A9: ='Kwh Reading'!A9 -> 44779 | B9: =TOTAL!E7 -> 19560 | C9: =('Kwh Reading'!T10-'Kwh Reading'!T9)*1000 -> 460 | D9: =('Kwh Reading'!F10-'Kwh Reading'!F9)*1000000 -> 2500 | E9: =('Kwh Reading'!C10-'Kwh Reading'!C9)*1000 -> 250 | F9: =('Kwh Reading'!J10-'Kwh Reading'!J9)*1000 -> 550 | G9: =('Kwh Reading'!K10-'Kwh Reading'!K9)*1000 -> 260 | H9: =('Kwh Reading'!L10-'Kwh Reading'!L9)*1000 -> 220 | I9: =('Kwh Reading'!R10-'Kwh Reading'!R9)*1000 -> 0 | J9: =('Kwh Reading'!S10-'Kwh Reading'!S9)*1000 -> 140 | K9: =('Kwh Reading'!I10-'Kwh Reading'!I9)*1000 -> 310 | L9: =('Kwh Reading'!B10-'Kwh Reading'!B9)*1000000 -> 1000 | M9: =('Kwh Reading'!M10-'Kwh Reading'!M9)*1000 -> 680 | N9: =('Kwh Reading'!H10-'Kwh Reading'!H9)*1000 -> 1 | O9: =('Kwh Reading'!P10-'Kwh Reading'!P9)*1000 -> 570 | P9: =('Kwh Reading'!G10-'Kwh Reading'!G9)*1000000 -> 700 | Q9: =('Kwh Reading'!Q10-'Kwh Reading'!Q9)*1000 -> 310 | R9: =('Kwh Reading'!N10-'Kwh Reading'!N9)*1000 -> 230 | S9: ='Kwh Reading'!E10-'Kwh Reading'!E9 -> 2497.51 | T9: ='Kwh Reading'!D10-'Kwh Reading'!D9 -> 1887.19 | U9: =('Kwh Reading'!O10-'Kwh Reading'!O9)*1000 -> 190 | V9: =B9-(SUM(C9:U9)) -> 6804.3
A10: ='Kwh Reading'!A10 -> 44780 | B10: =TOTAL!E8 -> 20700 | C10: =('Kwh Reading'!T11-'Kwh Reading'!T10)*1000 -> 490 | D10: =('Kwh Reading'!F11-'Kwh Reading'!F10)*1000000 -> 2600 | E10: =('Kwh Reading'!C11-'Kwh Reading'!C10)*1000 -> 230 | F10: =('Kwh Reading'!J11-'Kwh Reading'!J10)*1000 -> 420 | G10: =('Kwh Reading'!K11-'Kwh Reading'!K10)*1000 -> 310 | H10: =('Kwh Reading'!L11-'Kwh Reading'!L10)*1000 -> 250 | I10: =('Kwh Reading'!R11-'Kwh Reading'!R10)*1000 -> 0 | J10: =('Kwh Reading'!S11-'Kwh Reading'!S10)*1000 -> 140 | K10: =('Kwh Reading'!I11-'Kwh Reading'!I10)*1000 -> 330 | L10: =('Kwh Reading'!B11-'Kwh Reading'!B10)*1000000 -> 1000 | M10: =('Kwh Reading'!M11-'Kwh Reading'!M10)*1000 -> 710 | N10: =('Kwh Reading'!H11-'Kwh Reading'!H10)*1000 -> 1.1 | O10: =('Kwh Reading'!P11-'Kwh Reading'!P10)*1000 -> -998719.6 | P10: =('Kwh Reading'!G11-'Kwh Reading'!G10)*1000000 -> 800 | Q10: =('Kwh Reading'!Q11-'Kwh Reading'!Q10)*1000 -> 320 | R10: =('Kwh Reading'!N11-'Kwh Reading'!N10)*1000 -> 290 | S10: ='Kwh Reading'!E11-'Kwh Reading'!E10 -> 2605.99 | T10: ='Kwh Reading'!D11-'Kwh Reading'!D10 -> 1950.6 | U10: =('Kwh Reading'!O11-'Kwh Reading'!O10)*1000 -> 200 | V10: =B10-(SUM(C10:U10)) -> 1006771.9
A11: ='Kwh Reading'!A11 -> 44781 | B11: =TOTAL!E9 -> 20510 | C11: =('Kwh Reading'!T12-'Kwh Reading'!T11)*1000 -> 460 | D11: =('Kwh Reading'!F12-'Kwh Reading'!F11)*1000000 -> 2600 | E11: =('Kwh Reading'!C12-'Kwh Reading'!C11)*1000 -> 240 | F11: =('Kwh Reading'!J12-'Kwh Reading'!J11)*1000 -> 390 | G11: =('Kwh Reading'!K12-'Kwh Reading'!K11)*1000 -> 260 | H11: =('Kwh Reading'!L12-'Kwh Reading'!L11)*1000 -> 230 | I11: =('Kwh Reading'!R12-'Kwh Reading'!R11)*1000 -> 0 | J11: =('Kwh Reading'!S12-'Kwh Reading'!S11)*1000 -> 140 | K11: =('Kwh Reading'!I12-'Kwh Reading'!I11)*1000 -> 330 | L11: =('Kwh Reading'!B12-'Kwh Reading'!B11)*1000000 -> 1100 | M11: =('Kwh Reading'!M12-'Kwh Reading'!M11)*1000 -> 680 | N11: =('Kwh Reading'!H12-'Kwh Reading'!H11)*1000 -> 1 | O11: =('Kwh Reading'!P12-'Kwh Reading'!P11)*1000 -> 0.7 | P11: =('Kwh Reading'!G12-'Kwh Reading'!G11)*1000000 -> 900 | Q11: =('Kwh Reading'!Q12-'Kwh Reading'!Q11)*1000 -> 370 | R11: =('Kwh Reading'!N12-'Kwh Reading'!N11)*1000 -> 320 | S11: ='Kwh Reading'!E12-'Kwh Reading'!E11 -> 2508.43 | T11: ='Kwh Reading'!D12-'Kwh Reading'!D11 -> 2070.86 | U11: =('Kwh Reading'!O12-'Kwh Reading'!O11)*1000 -> 190 | V11: =B11-(SUM(C11:U11)) -> 7719.01
A12: ='Kwh Reading'!A12 -> 44782 | B12: =TOTAL!E10 -> 19900 | C12: =('Kwh Reading'!T13-'Kwh Reading'!T12)*1000 -> 480 | D12: =('Kwh Reading'!F13-'Kwh Reading'!F12)*1000000 -> 2500 | E12: =('Kwh Reading'!C13-'Kwh Reading'!C12)*1000 -> 250 | F12: =('Kwh Reading'!J13-'Kwh Reading'!J12)*1000 -> 410 | G12: =('Kwh Reading'!K13-'Kwh Reading'!K12)*1000 -> 240 | H12: =('Kwh Reading'!L13-'Kwh Reading'!L12)*1000 -> 250 | I12: =('Kwh Reading'!R13-'Kwh Reading'!R12)*1000 -> 0 | J12: =('Kwh Reading'!S13-'Kwh Reading'!S12)*1000 -> 130 | K12: =('Kwh Reading'!I13-'Kwh Reading'!I12)*1000 -> 300 | L12: =('Kwh Reading'!B13-'Kwh Reading'!B12)*1000000 -> 1000 | M12: =('Kwh Reading'!M13-'Kwh Reading'!M12)*1000 -> 700 | N12: =('Kwh Reading'!H13-'Kwh Reading'!H12)*1000 -> 1.1 | O12: =('Kwh Reading'!P13-'Kwh Reading'!P12)*1000 -> 0.7 | P12: =('Kwh Reading'!G13-'Kwh Reading'!G12)*1000000 -> 800 | Q12: =('Kwh Reading'!Q13-'Kwh Reading'!Q12)*1000 -> 330 | R12: =('Kwh Reading'!N13-'Kwh Reading'!N12)*1000 -> 300 | S12: ='Kwh Reading'!E13-'Kwh Reading'!E12 -> 2429.79 | T12: ='Kwh Reading'!D13-'Kwh Reading'!D12 -> 2003.33 | U12: =('Kwh Reading'!O13-'Kwh Reading'!O12)*1000 -> 190 | V12: =B12-(SUM(C12:U12)) -> 7585.08
A13: ='Kwh Reading'!A13 -> 44783 | B13: =TOTAL!E11 -> 19910 | C13: =('Kwh Reading'!T14-'Kwh Reading'!T13)*1000 -> 510 | D13: =('Kwh Reading'!F14-'Kwh Reading'!F13)*1000000 -> 2600 | E13: =('Kwh Reading'!C14-'Kwh Reading'!C13)*1000 -> 270 | F13: =('Kwh Reading'!J14-'Kwh Reading'!J13)*1000 -> 400 | G13: =('Kwh Reading'!K14-'Kwh Reading'!K13)*1000 -> 290 | H13: =('Kwh Reading'!L14-'Kwh Reading'!L13)*1000 -> 230 | I13: =('Kwh Reading'!R14-'Kwh Reading'!R13)*1000 -> 0 | J13: =('Kwh Reading'!S14-'Kwh Reading'!S13)*1000 -> 150 | K13: =('Kwh Reading'!I14-'Kwh Reading'!I13)*1000 -> 300 | L13: =('Kwh Reading'!B14-'Kwh Reading'!B13)*1000000 -> 1100 | M13: =('Kwh Reading'!M14-'Kwh Reading'!M13)*1000 -> 690 | N13: =('Kwh Reading'!H14-'Kwh Reading'!H13)*1000 -> 1 | O13: =('Kwh Reading'!P14-'Kwh Reading'!P13)*1000 -> 0.8 | P13: =('Kwh Reading'!G14-'Kwh Reading'!G13)*1000000 -> 800 | Q13: =('Kwh Reading'!Q14-'Kwh Reading'!Q13)*1000 -> 340 | R13: =('Kwh Reading'!N14-'Kwh Reading'!N13)*1000 -> 300 | S13: ='Kwh Reading'!E14-'Kwh Reading'!E13 -> 2337.42 | T13: ='Kwh Reading'!D14-'Kwh Reading'!D13 -> 1730.94 | U13: =('Kwh Reading'!O14-'Kwh Reading'!O13)*1000 -> 170 | V13: =B13-(SUM(C13:U13)) -> 7689.84
A14: ='Kwh Reading'!A14 -> 44784 | B14: =TOTAL!E12 -> 18760 | C14: =('Kwh Reading'!T15-'Kwh Reading'!T14)*1000 -> 430 | D14: =('Kwh Reading'!F15-'Kwh Reading'!F14)*1000000 -> 2800 | E14: =('Kwh Reading'!C15-'Kwh Reading'!C14)*1000 -> 300 | F14: =('Kwh Reading'!J15-'Kwh Reading'!J14)*1000 -> 1110 | G14: =('Kwh Reading'!K15-'Kwh Reading'!K14)*1000 -> 460 | H14: =('Kwh Reading'!L15-'Kwh Reading'!L14)*1000 -> 360 | I14: =('Kwh Reading'!R15-'Kwh Reading'!R14)*1000 -> 0 | J14: =('Kwh Reading'!S15-'Kwh Reading'!S14)*1000 -> 180 | K14: =('Kwh Reading'!I15-'Kwh Reading'!I14)*1000 -> 320 | L14: =('Kwh Reading'!B15-'Kwh Reading'!B14)*1000000 -> 1100 | M14: =('Kwh Reading'!M15-'Kwh Reading'!M14)*1000 -> 730 | N14: =('Kwh Reading'!H15-'Kwh Reading'!H14)*1000 -> 1.2 | O14: =('Kwh Reading'!P15-'Kwh Reading'!P14)*1000 -> 0.7 | P14: =('Kwh Reading'!G15-'Kwh Reading'!G14)*1000000 -> 800 | Q14: =('Kwh Reading'!Q15-'Kwh Reading'!Q14)*1000 -> 370 | R14: =('Kwh Reading'!N15-'Kwh Reading'!N14)*1000 -> 510 | S14: ='Kwh Reading'!E15-'Kwh Reading'!E14 -> 2504.05 | T14: ='Kwh Reading'!D15-'Kwh Reading'!D14 -> 1964.01 | U14: =('Kwh Reading'!O15-'Kwh Reading'!O14)*1000 -> 230 | V14: =B14-(SUM(C14:U14)) -> 4590.04
A15: ='Kwh Reading'!A15 -> 44785 | B15: =TOTAL!E13 -> 19000 | C15: =('Kwh Reading'!T16-'Kwh Reading'!T15)*1000 -> 280 | D15: =('Kwh Reading'!F16-'Kwh Reading'!F15)*1000000 -> 2400 | E15: =('Kwh Reading'!C16-'Kwh Reading'!C15)*1000 -> 190 | F15: =('Kwh Reading'!J16-'Kwh Reading'!J15)*1000 -> 380 | G15: =('Kwh Reading'!K16-'Kwh Reading'!K15)*1000 -> 130 | H15: =('Kwh Reading'!L16-'Kwh Reading'!L15)*1000 -> 110 | I15: =('Kwh Reading'!R16-'Kwh Reading'!R15)*1000 -> 0 | J15: =('Kwh Reading'!S16-'Kwh Reading'!S15)*1000 -> 100 | K15: =('Kwh Reading'!I16-'Kwh Reading'!I15)*1000 -> 210 | L15: =('Kwh Reading'!B16-'Kwh Reading'!B15)*1000000 -> 800 | M15: =('Kwh Reading'!M16-'Kwh Reading'!M15)*1000 -> 450 | N15: =('Kwh Reading'!H16-'Kwh Reading'!H15)*1000 -> 0.7 | O15: =('Kwh Reading'!P16-'Kwh Reading'!P15)*1000 -> 0.5 | P15: =('Kwh Reading'!G16-'Kwh Reading'!G15)*1000000 -> 600 | Q15: =('Kwh Reading'!Q16-'Kwh Reading'!Q15)*1000 -> 230 | R15: =('Kwh Reading'!N16-'Kwh Reading'!N15)*1000 -> 240 | S15: ='Kwh Reading'!E16-'Kwh Reading'!E15 -> 1367.15 | T15: ='Kwh Reading'!D16-'Kwh Reading'!D15 -> 1231.66 | U15: =('Kwh Reading'!O16-'Kwh Reading'!O15)*1000 -> 140 | V15: =B15-(SUM(C15:U15)) -> 10139.99
... A34: ='Kwh Reading'!A34 -> 44804 | B34: =TOTAL!E32 -> 0 | C34: =('Kwh Reading'!T35-'Kwh Reading'!T34)*1000 -> 0 | D34: =('Kwh Reading'!F35-'Kwh Reading'!F34)*1000000 -> 0 | E34: =('Kwh Reading'!C35-'Kwh Reading'!C34)*1000 -> 0 | F34: =('Kwh Reading'!J35-'Kwh Reading'!J34)*1000 -> 0 | G34: =('Kwh Reading'!K35-'Kwh Reading'!K34)*1000 -> 0 | H34: =('Kwh Reading'!L35-'Kwh Reading'!L34)*1000 -> 0 | I34: =('Kwh Reading'!R35-'Kwh Reading'!R34)*1000 -> 0 | J34: =('Kwh Reading'!S35-'Kwh Reading'!S34)*1000 -> 0 | K34: =('Kwh Reading'!I35-'Kwh Reading'!I34)*1000 -> 0 | L34: =('Kwh Reading'!B35-'Kwh Reading'!B34)*1000000 -> 0 | M34: =('Kwh Reading'!M35-'Kwh Reading'!M34)*1000 -> 0 | N34: =('Kwh Reading'!H35-'Kwh Reading'!H34)*1000 -> 0 | O34: =('Kwh Reading'!P35-'Kwh Reading'!P34)*1000 -> 0 | P34: =('Kwh Reading'!G35-'Kwh Reading'!G34)*1000000 -> 0 | Q34: =('Kwh Reading'!Q35-'Kwh Reading'!Q34)*1000 -> 0 | R34: =('Kwh Reading'!N35-'Kwh Reading'!N34)*1000 -> 0 | S34: ='Kwh Reading'!E35-'Kwh Reading'!E34 -> 0 | T34: ='Kwh Reading'!D35-'Kwh Reading'!D34 -> 0 | U34: =('Kwh Reading'!O35-'Kwh Reading'!O34)*1000 -> 0 | V34: =B34-(SUM(C34:U34)) -> 0
A35: Total | B35: =SUM(B4:B34) -> 236020 | C35: =SUM(C4:C34) -> -613670 | D35: =SUM(D4:D34) -> -3418400 | E35: =SUM(E4:E34) -> -328180 | F35: =SUM(F4:F34) -> -496570 | G35: =SUM(G4:G34) -> -476710 | H35: =SUM(H4:H34) -> -325770 | I35: =SUM(I4:I34) -> -190150 | ... V35: =SUM(V4:V34) -> 30292766

Sheet Kwh area wise 
A2: Month | B2: Total KWH | C2: Reef Club Kitchen KWH | D2: Main Kitchen KWH | E2: Pastry Kitchen KWH | F2: Laundry KWH | G2: STP KWH | H2: Kuda Huraa Accomodation KWH | I2: Guest Room Beach Pavilion & Beach Bungalow KWH | J2: Guest Room Water Bungalow KWH | K2: Spa KWH | L2: Others KWH
A3: ='Kwh Reading'!A4 -> 44774 | B3: =TOTAL!E2 -> 19350 | C3: ='Kwh Consumption'!C4 -> 480 | D3: ='Kwh Consumption'!D4 -> 2600 | E3: ='Kwh Consumption'!E4 -> 230 | F3: =('Kwh Consumption'!F4+'Kwh Consumption'!G4+'Kwh Consumption'!H4) -> 1010 | G3: =('Kwh Consumption'!I4+'Kwh Consumption'!J4) -> 140 | H3: =('Kwh Consumption'!K4+'Kwh Consumption'!L4) -> 1170 | I3: =('Kwh Consumption'!M4+'Kwh Consumption'!N4+'Kwh Consumption'!O4+'Kwh Consumption'!P4+'Kwh Consumption'!Q4+'Kwh Consumption'!R4) -> 2450.9 | J3: =('Kwh Consumption'!S4+'Kwh Consumption'!T4) -> 4065.8 | K3: ='Kwh Consumption'!U4 -> 200 | L3: =B3-C3-D3-E3-F3-G3-H3-I3-J3-K3 -> 7003.3
A4: ='Kwh Reading'!A5 -> 44775 | B4: =TOTAL!E3 -> 19530 | C4: ='Kwh Consumption'!C5 -> 500 | D4: ='Kwh Consumption'!D5 -> 2600 | E4: ='Kwh Consumption'!E5 -> 260 | F4: =('Kwh Consumption'!F5+'Kwh Consumption'!G5+'Kwh Consumption'!H5) -> 670 | G4: =('Kwh Consumption'!I5+'Kwh Consumption'!J5) -> 140 | H4: =('Kwh Consumption'!K5+'Kwh Consumption'!L5) -> 1200 | I4: =('Kwh Consumption'!M5+'Kwh Consumption'!N5+'Kwh Consumption'!O5+'Kwh Consumption'!P5+'Kwh Consumption'!Q5+'Kwh Consumption'!R5) -> 2711.1 | J4: =('Kwh Consumption'!S5+'Kwh Consumption'!T5) -> 4750.48 | K4: ='Kwh Consumption'!U5 -> 210 | L4: =B4-C4-D4-E4-F4-G4-H4-I4-J4-K4 -> 6488.42
A5: ='Kwh Reading'!A6 -> 44776 | B5: =TOTAL!E4 -> 21162 | C5: ='Kwh Consumption'!C6 -> 510 | D5: ='Kwh Consumption'!D6 -> 2700 | E5: ='Kwh Consumption'!E6 -> 250 | F5: =('Kwh Consumption'!F6+'Kwh Consumption'!G6+'Kwh Consumption'!H6) -> 1000 | G5: =('Kwh Consumption'!I6+'Kwh Consumption'!J6) -> 150 | H5: =('Kwh Consumption'!K6+'Kwh Consumption'!L6) -> 1330 | I5: =('Kwh Consumption'!M6+'Kwh Consumption'!N6+'Kwh Consumption'!O6+'Kwh Consumption'!P6+'Kwh Consumption'!Q6+'Kwh Consumption'!R6) -> 3011.1 | J5: =('Kwh Consumption'!S6+'Kwh Consumption'!T6) -> 4895.64 | K5: ='Kwh Consumption'!U6 -> 180 | L5: =B5-C5-D5-E5-F5-G5-H5-I5-J5-K5 -> 7135.26
A6: ='Kwh Reading'!A7 -> 44777 | B6: =TOTAL!E5 -> 19068 | C6: ='Kwh Consumption'!C7 -> 480 | D6: ='Kwh Consumption'!D7 -> 2600 | E6: ='Kwh Consumption'!E7 -> 240 | F6: =('Kwh Consumption'!F7+'Kwh Consumption'!G7+'Kwh Consumption'!H7) -> 1060 | G6: =('Kwh Consumption'!I7+'Kwh Consumption'!J7) -> 140 | H6: =('Kwh Consumption'!K7+'Kwh Consumption'!L7) -> 1300 | I6: =('Kwh Consumption'!M7+'Kwh Consumption'!N7+'Kwh Consumption'!O7+'Kwh Consumption'!P7+'Kwh Consumption'!Q7+'Kwh Consumption'!R7) -> 2661 | J6: =('Kwh Consumption'!S7+'Kwh Consumption'!T7) -> 4159.28 | K6: ='Kwh Consumption'!U7 -> 210 | L6: =B6-C6-D6-E6-F6-G6-H6-I6-J6-K6 -> 6217.72
A7: ='Kwh Reading'!A8 -> 44778 | B7: =TOTAL!E6 -> 18570 | C7: ='Kwh Consumption'!C8 -> 250 | D7: ='Kwh Consumption'!D8 -> 2600 | E7: ='Kwh Consumption'!E8 -> 240 | F7: =('Kwh Consumption'!F8+'Kwh Consumption'!G8+'Kwh Consumption'!H8) -> 640 | G7: =('Kwh Consumption'!I8+'Kwh Consumption'!J8) -> 140 | H7: =('Kwh Consumption'!K8+'Kwh Consumption'!L8) -> 1180 | I7: =('Kwh Consumption'!M8+'Kwh Consumption'!N8+'Kwh Consumption'!O8+'Kwh Consumption'!P8+'Kwh Consumption'!Q8+'Kwh Consumption'!R8) -> 2530.9 | J7: =('Kwh Consumption'!S8+'Kwh Consumption'!T8) -> 3769.32 | K7: ='Kwh Consumption'!U8 -> 210 | L7: =B7-C7-D7-E7-F7-G7-H7-I7-J7-K7 -> 7009.78
A8: ='Kwh Reading'!A9 -> 44779 | B8: =TOTAL!E7 -> 19560 | C8: ='Kwh Consumption'!C9 -> 460 | D8: ='Kwh Consumption'!D9 -> 2500 | E8: ='Kwh Consumption'!E9 -> 250 | F8: =('Kwh Consumption'!F9+'Kwh Consumption'!G9+'Kwh Consumption'!H9) -> 1030 | G8: =('Kwh Consumption'!I9+'Kwh Consumption'!J9) -> 140 | H8: =('Kwh Consumption'!K9+'Kwh Consumption'!L9) -> 1310 | I8: =('Kwh Consumption'!M9+'Kwh Consumption'!N9+'Kwh Consumption'!O9+'Kwh Consumption'!P9+'Kwh Consumption'!Q9+'Kwh Consumption'!R9) -> 2491 | J8: =('Kwh Consumption'!S9+'Kwh Consumption'!T9) -> 4384.7 | K8: ='Kwh Consumption'!U9 -> 190 | L8: =B8-C8-D8-E8-F8-G8-H8-I8-J8-K8 -> 6804.3
A9: ='Kwh Reading'!A10 -> 44780 | B9: =TOTAL!E8 -> 20700 | C9: ='Kwh Consumption'!C10 -> 490 | D9: ='Kwh Consumption'!D10 -> 2600 | E9: ='Kwh Consumption'!E10 -> 230 | F9: =('Kwh Consumption'!F10+'Kwh Consumption'!G10+'Kwh Consumption'!H10) -> 980 | G9: =('Kwh Consumption'!I10+'Kwh Consumption'!J10) -> 140 | H9: =('Kwh Consumption'!K10+'Kwh Consumption'!L10) -> 1330 | I9: =('Kwh Consumption'!M10+'Kwh Consumption'!N10+'Kwh Consumption'!O10+'Kwh Consumption'!P10+'Kwh Consumption'!Q10+'Kwh Consumption'!R10) -> -996598.5 | J9: =('Kwh Consumption'!S10+'Kwh Consumption'!T10) -> 4556.59 | K9: ='Kwh Consumption'!U10 -> 200 | L9: =B9-C9-D9-E9-F9-G9-H9-I9-J9-K9 -> 1006771.9
A10: ='Kwh Reading'!A11 -> 44781 | B10: =TOTAL!E9 -> 20510 | C10: ='Kwh Consumption'!C11 -> 460 | D10: ='Kwh Consumption'!D11 -> 2600 | E10: ='Kwh Consumption'!E11 -> 240 | F10: =('Kwh Consumption'!F11+'Kwh Consumption'!G11+'Kwh Consumption'!H11) -> 880 | G10: =('Kwh Consumption'!I11+'Kwh Consumption'!J11) -> 140 | H10: =('Kwh Consumption'!K11+'Kwh Consumption'!L11) -> 1430 | I10: =('Kwh Consumption'!M11+'Kwh Consumption'!N11+'Kwh Consumption'!O11+'Kwh Consumption'!P11+'Kwh Consumption'!Q11+'Kwh Consumption'!R11) -> 2271.7 | J10: =('Kwh Consumption'!S11+'Kwh Consumption'!T11) -> 4579.29 | K10: ='Kwh Consumption'!U11 -> 190 | L10: =B10-C10-D10-E10-F10-G10-H10-I10-J10-K10 -> 7719.01
A11: ='Kwh Reading'!A12 -> 44782 | B11: =TOTAL!E10 -> 19900 | C11: ='Kwh Consumption'!C12 -> 480 | D11: ='Kwh Consumption'!D12 -> 2500 | E11: ='Kwh Consumption'!E12 -> 250 | F11: =('Kwh Consumption'!F12+'Kwh Consumption'!G12+'Kwh Consumption'!H12) -> 900 | G11: =('Kwh Consumption'!I12+'Kwh Consumption'!J12) -> 130 | H11: =('Kwh Consumption'!K12+'Kwh Consumption'!L12) -> 1300 | I11: =('Kwh Consumption'!M12+'Kwh Consumption'!N12+'Kwh Consumption'!O12+'Kwh Consumption'!P12+'Kwh Consumption'!Q12+'Kwh Consumption'!R12) -> 2131.8 | J11: =('Kwh Consumption'!S12+'Kwh Consumption'!T12) -> 4433.12 | K11: ='Kwh Consumption'!U12 -> 190 | L11: =B11-C11-D11-E11-F11-G11-H11-I11-J11-K11 -> 7585.08
A12: ='Kwh Reading'!A13 -> 44783 | B12: =TOTAL!E11 -> 19910 | C12: ='Kwh Consumption'!C13 -> 510 | D12: ='Kwh Consumption'!D13 -> 2600 | E12: ='Kwh Consumption'!E13 -> 270 | F12: =('Kwh Consumption'!F13+'Kwh Consumption'!G13+'Kwh Consumption'!H13) -> 920 | G12: =('Kwh Consumption'!I13+'Kwh Consumption'!J13) -> 150 | H12: =('Kwh Consumption'!K13+'Kwh Consumption'!L13) -> 1400 | I12: =('Kwh Consumption'!M13+'Kwh Consumption'!N13+'Kwh Consumption'!O13+'Kwh Consumption'!P13+'Kwh Consumption'!Q13+'Kwh Consumption'!R13) -> 2131.8 | J12: =('Kwh Consumption'!S13+'Kwh Consumption'!T13) -> 4068.36 | K12: ='Kwh Consumption'!U13 -> 170 | L12: =B12-C12-D12-E12-F12-G12-H12-I12-J12-K12 -> 7689.84
A13: ='Kwh Reading'!A14 -> 44784 | B13: =TOTAL!E12 -> 18760 | C13: ='Kwh Consumption'!C14 -> 430 | D13: ='Kwh Consumption'!D14 -> 2800 | E13: ='Kwh Consumption'!E14 -> 300 | F13: =('Kwh Consumption'!F14+'Kwh Consumption'!G14+'Kwh Consumption'!H14) -> 1930 | G13: =('Kwh Consumption'!I14+'Kwh Consumption'!J14) -> 180 | H13: =('Kwh Consumption'!K14+'Kwh Consumption'!L14) -> 1420 | I13: =('Kwh Consumption'!M14+'Kwh Consumption'!N14+'Kwh Consumption'!O14+'Kwh Consumption'!P14+'Kwh Consumption'!Q14+'Kwh Consumption'!R14) -> 2411.9 | J13: =('Kwh Consumption'!S14+'Kwh Consumption'!T14) -> 4468.06 | K13: ='Kwh Consumption'!U14 -> 230 | L13: =B13-C13-D13-E13-F13-G13-H13-I13-J13-K13 -> 4590.04
A14: ='Kwh Reading'!A15 -> 44785 | B14: =TOTAL!E13 -> 19000 | C14: ='Kwh Consumption'!C15 -> 280 | D14: ='Kwh Consumption'!D15 -> 2400 | E14: ='Kwh Consumption'!E15 -> 190 | F14: =('Kwh Consumption'!F15+'Kwh Consumption'!G15+'Kwh Consumption'!H15) -> 620 | G14: =('Kwh Consumption'!I15+'Kwh Consumption'!J15) -> 100 | H14: =('Kwh Consumption'!K15+'Kwh Consumption'!L15) -> 1010 | I14: =('Kwh Consumption'!M15+'Kwh Consumption'!N15+'Kwh Consumption'!O15+'Kwh Consumption'!P15+'Kwh Consumption'!Q15+'Kwh Consumption'!R15) -> 1521.2 | J14: =('Kwh Consumption'!S15+'Kwh Consumption'!T15) -> 2598.81 | K14: ='Kwh Consumption'!U15 -> 140 | L14: =B14-C14-D14-E14-F14-G14-H14-I14-J14-K14 -> 10139.99
... A33: ='Kwh Reading'!A34 -> 44804 | B33: =TOTAL!E32 -> 0 | C33: ='Kwh Consumption'!C34 -> 0 | D33: ='Kwh Consumption'!D34 -> 0 | E33: ='Kwh Consumption'!E34 -> 0 | F33: =('Kwh Consumption'!F34+'Kwh Consumption'!G34+'Kwh Consumption'!H34) -> 0 | G33: =('Kwh Consumption'!I34+'Kwh Consumption'!J34) -> 0 | H33: =('Kwh Consumption'!K34+'Kwh Consumption'!L34) -> 0 | I33: =('Kwh Consumption'!M34+'Kwh Consumption'!N34+'Kwh Consumption'!O34+'Kwh Consumption'!P34+'Kwh Consumption'!Q34+'Kwh Consumption'!R34) -> 0 | J33: =('Kwh Consumption'!S34+'Kwh Consumption'!T34) -> 0 | K33: ='Kwh Consumption'!U34 -> 0 | L33: =B33-C33-D33-E33-F33-G33-H33-I33-J33-K33 -> 0
A34: Total kwh | B34: =SUM(B3:B33) -> 236020 | C34: =SUM(C3:C33) -> -613670 | D34: =SUM(D3:D33) -> -3418400 | E34: =SUM(E3:E33) -> -328180 | F34: =SUM(F3:F33) -> -1299050 | G34: =SUM(G3:G33) -> -359600 | H34: =SUM(H3:H33) -> -1800530 | I34: =SUM(I3:I33) -> -4399878 | ... L34: =SUM(L3:L33) -> 30292766 | M34: =C34+D34+E34+F34+G34+H34+I34+J34+K34+L34 -> 236020
A36: Total $ | B36: =TOTAL!F2 -> 0 | C36: =C34*B36 -> 0 | D36: =D34*B36 -> 0 | E36: =E34*B36 -> 0 | F36: =F34*B36 -> 0 | G36: =G34*B36 -> 0 | H36: =H34*B36 -> 0 | I36: =I34*B36 -> 0 | J36: =J34*B36 -> 0 | K36: =K34*B36 -> 0 | L36: =L34*B36 -> 0 | M36: =C36+D36+E36+F36+G36+H36+I36+J36+K36+L36 -> 0

Sheet  Kwh area wise $ 
A2: Month | B2: $ /Per KWH | C2: Total $ | D2: Reef Club $ | E2: Kitchen $ | F2: Pastry $ | G2: Laundry $ | H2: STP $ | I2: Kuda Huraa Accomodation $ | J2: Guest Room Beach Pavilion & Beach Bungalow $ | K2: Guest Room Water Bungalow $ | L2: Spa $ | M2: Others $
A3: ='Kwh Reading'!A4 -> 44774 | B3: =TOTAL!F2 -> 0 | C3: ='Kwh Consumption'!B4*' Kwh area wise $ '!B3 -> 0 | D3: ='Kwh Consumption'!C4*' Kwh area wise $ '!B3 -> 0 | E3: ='Kwh Consumption'!D4*' Kwh area wise $ '!B3 -> 0 | F3: ='Kwh Consumption'!E4*' Kwh area wise $ '!B3 -> 0 | G3: =('Kwh Consumption'!F4+'Kwh Consumption'!G4+'Kwh Consumption'!H4)*' Kwh area wise $ '!B3 -> 0 | H3: =('Kwh Consumption'!I4+'Kwh Consumption'!J4)*' Kwh area wise $ '!B3 -> 0 | I3: =('Kwh Consumption'!K4+'Kwh Consumption'!L4)*' Kwh area wise $ '!B3 -> 0 | J3: =('Kwh Consumption'!M4+'Kwh Consumption'!N4+'Kwh Consumption'!O4+'Kwh Consumption'!P4+'Kwh Consumption'!Q4+'Kwh Consumption'!R4)*' Kwh area wise $ '!B3 -> 0 | K3: =('Kwh Consumption'!S4+'Kwh Consumption'!T4)*' Kwh area wise $ '!B3 -> 0 | L3: ='Kwh Consumption'!U4*' Kwh area wise $ '!B3 -> 0 | M3: ='Kwh Consumption'!V4*' Kwh area wise $ '!B3 -> 0
A4: ='Kwh Reading'!A5 -> 44775 | B4: =TOTAL!F3 -> 0 | C4: ='Kwh Consumption'!B5*' Kwh area wise $ '!B4 -> 0 | D4: ='Kwh Consumption'!C5*' Kwh area wise $ '!B4 -> 0 | E4: ='Kwh Consumption'!D5*' Kwh area wise $ '!B4 -> 0 | F4: ='Kwh Consumption'!E5*' Kwh area wise $ '!B4 -> 0 | G4: =('Kwh Consumption'!F5+'Kwh Consumption'!G5+'Kwh Consumption'!H5)*' Kwh area wise $ '!B4 -> 0 | H4: =('Kwh Consumption'!I5+'Kwh Consumption'!J5)*' Kwh area wise $ '!B4 -> 0 | I4: =('Kwh Consumption'!K5+'Kwh Consumption'!L5)*' Kwh area wise $ '!B4 -> 0 | J4: =('Kwh Consumption'!M5+'Kwh Consumption'!N5+'Kwh Consumption'!O5+'Kwh Consumption'!P5+'Kwh Consumption'!Q5+'Kwh Consumption'!R5)*' Kwh area wise $ '!B4 -> 0 | K4: =('Kwh Consumption'!S5+'Kwh Consumption'!T5)*' Kwh area wise $ '!B4 -> 0 | L4: ='Kwh Consumption'!U5*' Kwh area wise $ '!B4 -> 0 | M4: ='Kwh Consumption'!V5*' Kwh area wise $ '!B4 -> 0
A5: ='Kwh Reading'!A6 -> 44776 | B5: =TOTAL!F4 -> 0 | C5: ='Kwh Consumption'!B6*' Kwh area wise $ '!B5 -> 0 | D5: ='Kwh Consumption'!C6*' Kwh area wise $ '!B5 -> 0 | E5: ='Kwh Consumption'!D6*' Kwh area wise $ '!B5 -> 0 | F5: ='Kwh Consumption'!E6*' Kwh area wise $ '!B5 -> 0 | G5: =('Kwh Consumption'!F6+'Kwh Consumption'!G6+'Kwh Consumption'!H6)*' Kwh area wise $ '!B5 -> 0 | H5: =('Kwh Consumption'!I6+'Kwh Consumption'!J6)*' Kwh area wise $ '!B5 -> 0 | I5: =('Kwh Consumption'!K6+'Kwh Consumption'!L6)*' Kwh area wise $ '!B5 -> 0 | J5: =('Kwh Consumption'!M6+'Kwh Consumption'!N6+'Kwh Consumption'!O6+'Kwh Consumption'!P6+'Kwh Consumption'!Q6+'Kwh Consumption'!R6)*' Kwh area wise $ '!B5 -> 0 | K5: =('Kwh Consumption'!S6+'Kwh Consumption'!T6)*' Kwh area wise $ '!B5 -> 0 | L5: ='Kwh Consumption'!U6*' Kwh area wise $ '!B5 -> 0 | M5: ='Kwh Consumption'!V6*' Kwh area wise $ '!B5 -> 0
A6: ='Kwh Reading'!A7 -> 44777 | B6: =TOTAL!F5 -> 0 | C6: ='Kwh Consumption'!B7*' Kwh area wise $ '!B6 -> 0 | D6: ='Kwh Consumption'!C7*' Kwh area wise $ '!B6 -> 0 | E6: ='Kwh Consumption'!D7*' Kwh area wise $ '!B6 -> 0 | F6: ='Kwh Consumption'!E7*' Kwh area wise $ '!B6 -> 0 | G6: =('Kwh Consumption'!F7+'Kwh Consumption'!G7+'Kwh Consumption'!H7)*' Kwh area wise $ '!B6 -> 0 | H6: =('Kwh Consumption'!I7+'Kwh Consumption'!J7)*' Kwh area wise $ '!B6 -> 0 | I6: =('Kwh Consumption'!K7+'Kwh Consumption'!L7)*' Kwh area wise $ '!B6 -> 0 | J6: =('Kwh Consumption'!M7+'Kwh Consumption'!N7+'Kwh Consumption'!O7+'Kwh Consumption'!P7+'Kwh Consumption'!Q7+'Kwh Consumption'!R7)*' Kwh area wise $ '!B6 -> 0 | K6: =('Kwh Consumption'!S7+'Kwh Consumption'!T7)*' Kwh area wise $ '!B6 -> 0 | L6: ='Kwh Consumption'!U7*' Kwh area wise $ '!B6 -> 0 | M6: ='Kwh Consumption'!V7*' Kwh area wise $ '!B6 -> 0
A7: ='Kwh Reading'!A8 -> 44778 | B7: =TOTAL!F6 -> 0 | C7: ='Kwh Consumption'!B8*' Kwh area wise $ '!B7 -> 0 | D7: ='Kwh Consumption'!C8*' Kwh area wise $ '!B7 -> 0 | E7: ='Kwh Consumption'!D8*' Kwh area wise $ '!B7 -> 0 | F7: ='Kwh Consumption'!E8*' Kwh area wise $ '!B7 -> 0 | G7: =('Kwh Consumption'!F8+'Kwh Consumption'!G8+'Kwh Consumption'!H8)*' Kwh area wise $ '!B7 -> 0 | H7: =('Kwh Consumption'!I8+'Kwh Consumption'!J8)*' Kwh area wise $ '!B7 -> 0 | I7: =('Kwh Consumption'!K8+'Kwh Consumption'!L8)*' Kwh area wise $ '!B7 -> 0 | J7: =('Kwh Consumption'!M8+'Kwh Consumption'!N8+'Kwh Consumption'!O8+'Kwh Consumption'!P8+'Kwh Consumption'!Q8+'Kwh Consumption'!R8)*' Kwh area wise $ '!B7 -> 0 | K7: =('Kwh Consumption'!S8+'Kwh Consumption'!T8)*' Kwh area wise $ '!B7 -> 0 | L7: ='Kwh Consumption'!U8*' Kwh area wise $ '!B7 -> 0 | M7: ='Kwh Consumption'!V8*' Kwh area wise $ '!B7 -> 0
A8: ='Kwh Reading'!A9 -> 44779 | B8: =TOTAL!F7 -> 0 | C8: ='Kwh Consumption'!B9*' Kwh area wise $ '!B8 -> 0 | D8: ='Kwh Consumption'!C9*' Kwh area wise $ '!B8 -> 0 | E8: ='Kwh Consumption'!D9*' Kwh area wise $ '!B8 -> 0 | F8: ='Kwh Consumption'!E9*' Kwh area wise $ '!B8 -> 0 | G8: =('Kwh Consumption'!F9+'Kwh Consumption'!G9+'Kwh Consumption'!H9)*' Kwh area wise $ '!B8 -> 0 | H8: =('Kwh Consumption'!I9+'Kwh Consumption'!J9)*' Kwh area wise $ '!B8 -> 0 | I8: =('Kwh Consumption'!K9+'Kwh Consumption'!L9)*' Kwh area wise $ '!B8 -> 0 | J8: =('Kwh Consumption'!M9+'Kwh Consumption'!N9+'Kwh Consumption'!O9+'Kwh Consumption'!P9+'Kwh Consumption'!Q9+'Kwh Consumption'!R9)*' Kwh area wise $ '!B8 -> 0 | K8: =('Kwh Consumption'!S9+'Kwh Consumption'!T9)*' Kwh area wise $ '!B8 -> 0 | L8: ='Kwh Consumption'!U9*' Kwh area wise $ '!B8 -> 0 | M8: ='Kwh Consumption'!V9*' Kwh area wise $ '!B8 -> 0
A9: ='Kwh Reading'!A10 -> 44780 | B9: =TOTAL!F8 -> 0 | C9: ='Kwh Consumption'!B10*' Kwh area wise $ '!B9 -> 0 | D9: ='Kwh Consumption'!C10*' Kwh area wise $ '!B9 -> 0 | E9: ='Kwh Consumption'!D10*' Kwh area wise $ '!B9 -> 0 | F9: ='Kwh Consumption'!E10*' Kwh area wise $ '!B9 -> 0 | G9: =('Kwh Consumption'!F10+'Kwh Consumption'!G10+'Kwh Consumption'!H10)*' Kwh area wise $ '!B9 -> 0 | H9: =('Kwh Consumption'!I10+'Kwh Consumption'!J10)*' Kwh area wise $ '!B9 -> 0 | I9: =('Kwh Consumption'!K10+'Kwh Consumption'!L10)*' Kwh area wise $ '!B9 -> 0 | J9: =('Kwh Consumption'!M10+'Kwh Consumption'!N10+'Kwh Consumption'!O10+'Kwh Consumption'!P10+'Kwh Consumption'!Q10+'Kwh Consumption'!R10)*' Kwh area wise $ '!B9 -> 0 | K9: =('Kwh Consumption'!S10+'Kwh Consumption'!T10)*' Kwh area wise $ '!B9 -> 0 | L9: ='Kwh Consumption'!U10*' Kwh area wise $ '!B9 -> 0 | M9: ='Kwh Consumption'!V10*' Kwh area wise $ '!B9 -> 0
A10: ='Kwh Reading'!A11 -> 44781 | B10: =TOTAL!F9 -> 0 | C10: ='Kwh Consumption'!B11*' Kwh area wise $ '!B10 -> 0 | D10: ='Kwh Consumption'!C11*' Kwh area wise $ '!B10 -> 0 | E10: ='Kwh Consumption'!D11*' Kwh area wise $ '!B10 -> 0 | F10: ='Kwh Consumption'!E11*' Kwh area wise $ '!B10 -> 0 | G10: =('Kwh Consumption'!F11+'Kwh Consumption'!G11+'Kwh Consumption'!H11)*' Kwh area wise $ '!B10 -> 0 | H10: =('Kwh Consumption'!I11+'Kwh Consumption'!J11)*' Kwh area wise $ '!B10 -> 0 | I10: =('Kwh Consumption'!K11+'Kwh Consumption'!L11)*' Kwh area wise $ '!B10 -> 0 | J10: =('Kwh Consumption'!M11+'Kwh Consumption'!N11+'Kwh Consumption'!O11+'Kwh Consumption'!P11+'Kwh Consumption'!Q11+'Kwh Consumption'!R11)*' Kwh area wise $ '!B10 -> 0 | K10: =('Kwh Consumption'!S11+'Kwh Consumption'!T11)*' Kwh area wise $ '!B10 -> 0 | L10: ='Kwh Consumption'!U11*' Kwh area wise $ '!B10 -> 0 | M10: ='Kwh Consumption'!V11*' Kwh area wise $ '!B10 -> 0
A11: ='Kwh Reading'!A12 -> 44782 | B11: =TOTAL!F10 -> 0 | C11: ='Kwh Consumption'!B12*' Kwh area wise $ '!B11 -> 0 | D11: ='Kwh Consumption'!C12*' Kwh area wise $ '!B11 -> 0 | E11: ='Kwh Consumption'!D12*' Kwh area wise $ '!B11 -> 0 | F11: ='Kwh Consumption'!E12*' Kwh area wise $ '!B11 -> 0 | G11: =('Kwh Consumption'!F12+'Kwh Consumption'!G12+'Kwh Consumption'!H12)*' Kwh area wise $ '!B11 -> 0 | H11: =('Kwh Consumption'!I12+'Kwh Consumption'!J12)*' Kwh area wise $ '!B11 -> 0 | I11: =('Kwh Consumption'!K12+'Kwh Consumption'!L12)*' Kwh area wise $ '!B11 -> 0 | J11: =('Kwh Consumption'!M12+'Kwh Consumption'!N12+'Kwh Consumption'!O12+'Kwh Consumption'!P12+'Kwh Consumption'!Q12+'Kwh Consumption'!R12)*' Kwh area wise $ '!B11 -> 0 | K11: =('Kwh Consumption'!S12+'Kwh Consumption'!T12)*' Kwh area wise $ '!B11 -> 0 | L11: ='Kwh Consumption'!U12*' Kwh area wise $ '!B11 -> 0 | M11: ='Kwh Consumption'!V12*' Kwh area wise $ '!B11 -> 0
A12: ='Kwh Reading'!A13 -> 44783 | B12: =TOTAL!F11 -> 0 | C12: ='Kwh Consumption'!B13*' Kwh area wise $ '!B12 -> 0 | D12: ='Kwh Consumption'!C13*' Kwh area wise $ '!B12 -> 0 | E12: ='Kwh Consumption'!D13*' Kwh area wise $ '!B12 -> 0 | F12: ='Kwh Consumption'!E13*' Kwh area wise $ '!B12 -> 0 | G12: =('Kwh Consumption'!F13+'Kwh Consumption'!G13+'Kwh Consumption'!H13)*' Kwh area wise $ '!B12 -> 0 | H12: =('Kwh Consumption'!I13+'Kwh Consumption'!J13)*' Kwh area wise $ '!B12 -> 0 | I12: =('Kwh Consumption'!K13+'Kwh Consumption'!L13)*' Kwh area wise $ '!B12 -> 0 | J12: =('Kwh Consumption'!M13+'Kwh Consumption'!N13+'Kwh Consumption'!O13+'Kwh Consumption'!P13+'Kwh Consumption'!Q13+'Kwh Consumption'!R13)*' Kwh area wise $ '!B12 -> 0 | K12: =('Kwh Consumption'!S13+'Kwh Consumption'!T13)*' Kwh area wise $ '!B12 -> 0 | L12: ='Kwh Consumption'!U13*' Kwh area wise $ '!B12 -> 0 | M12: ='Kwh Consumption'!V13*' Kwh area wise $ '!B12 -> 0
A13: ='Kwh Reading'!A14 -> 44784 | B13: =TOTAL!F12 -> 0 | C13: ='Kwh Consumption'!B14*' Kwh area wise $ '!B13 -> 0 | D13: ='Kwh Consumption'!C14*' Kwh area wise $ '!B13 -> 0 | E13: ='Kwh Consumption'!D14*' Kwh area wise $ '!B13 -> 0 | F13: ='Kwh Consumption'!E14*' Kwh area wise $ '!B13 -> 0 | G13: =('Kwh Consumption'!F14+'Kwh Consumption'!G14+'Kwh Consumption'!H14)*' Kwh area wise $ '!B13 -> 0 | H13: =('Kwh Consumption'!I14+'Kwh Consumption'!J14)*' Kwh area wise $ '!B13 -> 0 | I13: =('Kwh Consumption'!K14+'Kwh Consumption'!L14)*' Kwh area wise $ '!B13 -> 0 | J13: =('Kwh Consumption'!M14+'Kwh Consumption'!N14+'Kwh Consumption'!O14+'Kwh Consumption'!P14+'Kwh Consumption'!Q14+'Kwh Consumption'!R14)*' Kwh area wise $ '!B13 -> 0 | K13: =('Kwh Consumption'!S14+'Kwh Consumption'!T14)*' Kwh area wise $ '!B13 -> 0 | L13: ='Kwh Consumption'!U14*' Kwh area wise $ '!B13 -> 0 | M13: ='Kwh Consumption'!V14*' Kwh area wise $ '!B13 -> 0
A14: ='Kwh Reading'!A15 -> 44785 | B14: =TOTAL!F13 -> 0 | C14: ='Kwh Consumption'!B15*' Kwh area wise $ '!B14 -> 0 | D14: ='Kwh Consumption'!C15*' Kwh area wise $ '!B14 -> 0 | E14: ='Kwh Consumption'!D15*' Kwh area wise $ '!B14 -> 0 | F14: ='Kwh Consumption'!E15*' Kwh area wise $ '!B14 -> 0 | G14: =('Kwh Consumption'!F15+'Kwh Consumption'!G15+'Kwh Consumption'!H15)*' Kwh area wise $ '!B14 -> 0 | H14: =('Kwh Consumption'!I15+'Kwh Consumption'!J15)*' Kwh area wise $ '!B14 -> 0 | I14: =('Kwh Consumption'!K15+'Kwh Consumption'!L15)*' Kwh area wise $ '!B14 -> 0 | J14: =('Kwh Consumption'!M15+'Kwh Consumption'!N15+'Kwh Consumption'!O15+'Kwh Consumption'!P15+'Kwh Consumption'!Q15+'Kwh Consumption'!R15)*' Kwh area wise $ '!B14 -> 0 | K14: =('Kwh Consumption'!S15+'Kwh Consumption'!T15)*' Kwh area wise $ '!B14 -> 0 | L14: ='Kwh Consumption'!U15*' Kwh area wise $ '!B14 -> 0 | M14: ='Kwh Consumption'!V15*' Kwh area wise $ '!B14 -> 0
... A33: ='Kwh Reading'!A34 -> 44804 | B33: =TOTAL!F32 -> 0 | C33: ='Kwh Consumption'!B34*' Kwh area wise $ '!B33 -> 0 | D33: ='Kwh Consumption'!C34*' Kwh area wise $ '!B33 -> 0 | E33: ='Kwh Consumption'!D34*' Kwh area wise $ '!B33 -> 0 | F33: ='Kwh Consumption'!E34*' Kwh area wise $ '!B33 -> 0 | G33: =('Kwh Consumption'!F34+'Kwh Consumption'!G34+'Kwh Consumption'!H34)*' Kwh area wise $ '!B33 -> 0 | H33: =('Kwh Consumption'!I34+'Kwh Consumption'!J34)*' Kwh area wise $ '!B33 -> 0 | I33: =('Kwh Consumption'!K34+'Kwh Consumption'!L34)*' Kwh area wise $ '!B33 -> 0 | J33: =('Kwh Consumption'!M34+'Kwh Consumption'!N34+'Kwh Consumption'!O34+'Kwh Consumption'!P34+'Kwh Consumption'!Q34+'Kwh Consumption'!R34)*' Kwh area wise $ '!B33 -> 0 | K33: =('Kwh Consumption'!S34+'Kwh Consumption'!T34)*' Kwh area wise $ '!B33 -> 0 | L33: ='Kwh Consumption'!U34*' Kwh area wise $ '!B33 -> 0 | M33: ='Kwh Consumption'!V34*' Kwh area wise $ '!B33 -> 0
A34: Total | C34: =SUM(C3:C33) -> 0 | D34: =SUM(D3:D33) -> 0 | E34: =SUM(E3:E33) -> 0 | F34: =SUM(F3:F33) -> 0 | G34: =SUM(G3:G33) -> 0 | H34: =SUM(H3:H33) -> 0 | I34: =SUM(I3:I33) -> 0 | J34: =SUM(J3:J33) -> 0 | ... M34: =SUM(M3:M33) -> 0 | N34: =D34+E34+F34+G34+H34+I34+J34+K34+L34+M34 -> 0

Sheet Water Reading
B1: Meter 1 | C1: Meter 2 | D1: Meter 6 | E1: Meter 8 | F1: Meter 7 | G1: Meter 9 | H1: Meter 3 | I1: Meter 5 | J1: Meter 10 | K1: Meter 13 | L1: Meter 16 | M1: Meter 17 | N1: Meter 15 | O1: Meter 14 | P1: Meter 4 | Q1: Meter 11 | R1: Meter 12
A2: Date | B2: Main Meter 1 | C2: Main Meter 2 | D2: Beach Bunglow | E2: Kuda Huraa staff | F2: Bodu hura staff | G2: Laundry | H2: Water Bunglow | I2: Main Kitchen | J2: Second stage | K2: Supply jetty | L2: Staff housing A | M2: Staff housing B | N2: Spa | O2: Staff jetty | P2: Main pool | Q2: Reef club pool | R2: Reef club kitchen
A3: 44774 | B3: 7190 | C3: 9613 | D3: 276842 | E3: 274770 | F3: 67225 | G3: 121037 | H3: 62098 | I3: 77074 | J3: 23163 | K3: 1024 | L3: 19072 | M3: 27877 | N3: 8752 | O3: 2247 | P3: 31606 | Q3: 1908 | R3: 433
A4: 44775 | B4: 7308 | C4: 9784 | D4: 276922 | E4: 274853 | F4: 67225 | G4: 121065 | H4: 62098 | I4: 77104 | J4: 23169 | K4: 1024 | L4: 19084 | M4: 27882 | N4: 8758 | O4: 2249 | P4: 31615 | Q4: 1908 | R4: 437
A5: 44776 | B5: 7450 | C5: 9988 | D5: 277072 | E5: 274926 | F5: 67226 | G5: 121079 | H5: 62098 | I5: 77119 | J5: 23174 | K5: 1024 | L5: 19078 | M5: 27888 | N5: 8759 | O5: 2251 | P5: 31615 | Q5: 1908 | R5: 440
A6: 44777 | B6: 7572 | C6: 10163 | D6: 277190 | E6: 275001 | F6: 67227 | G6: 121099 | H6: 62098 | I6: 77147 | J6: 23180 | K6: 1024 | L6: 19081 | M6: 27893 | N6: 8764 | O6: 2252 | P6: 31623 | Q6: 1908 | R6: 445
A7: 44778 | B7: 7692 | C7: 10335 | D7: 277289 | E7: 275075 | F7: 67227 | G7: 121120 | H7: 62098 | I7: 77183 | J7: 23186 | K7: 1024 | L7: 19083 | M7: 27887 | N7: 8770 | O7: 2254 | P7: 31636 | Q7: 1908 | R7: 449
A8: 44779 | B8: 7813 | C8: 10508 | D8: 277425 | E8: 275148 | F8: 67228 | G8: 121136 | H8: 62098 | I8: 77204 | J8: 23191 | K8: 1024 | L8: 19086 | M8: 27901 | N8: 8773 | O8: 2256 | P8: 31642 | Q8: 1908 | R8: 450
A9: 44780 | B9: 7955 | C9: 10713 | D9: 277614 | E9: 275213 | F9: 67228 | G9: 121157 | H9: 62098 | I9: 77218 | J9: 23197 | K9: 1024 | L9: 19089 | M9: 27907 | N9: 8774 | O9: 2258 | P9: 31642 | Q9: 1908 | R9: 455
A10: 44781 | B10: 8100 | C10: 10922 | D10: 277795 | E10: 275292 | F10: 67229 | G10: 121180 | H10: 62098 | I10: 77244 | J10: 23203 | K10: 1024 | L10: 19092 | M10: 27912 | N10: 8776 | O10: 2260 | P10: 31648 | Q10: 1918 | R10: 459
A11: 44782 | B11: 8249 | C11: 11138 | D11: 277957 | E11: 275368 | F11: 67229 | G11: 121202 | H11: 62098 | I11: 77290 | J11: 23208 | K11: 1024 | L11: 19094 | M11: 27916 | N11: 8780 | O11: 2262 | P11: 31671 | Q11: 1923 | R11: 464
A12: 44783 | B12: 8380 | C12: 11324 | D12: 278093 | E12: 275440 | F12: 67231 | G12: 121223 | H12: 62098 | I12: 77323 | J12: 23214 | K12: 1024 | L12: 19097 | M12: 27921 | N12: 8781 | O12: 2263 | P12: 31687 | Q12: 1925 | R12: 468
A13: 44784 | B13: 8500 | C13: 11488 | D13: 278221 | E13: 275512 | F13: 67231 | G13: 121245 | H13: 62098 | I13: 77343 | J13: 23220 | K13: 1024 | L13: 19099 | M13: 27928 | N13: 8783 | O13: 2264 | P13: 31687 | Q13: 1925 | R13: 471
A14: 44785 | B14: 8670 | C14: 11720 | D14: 278418 | E14: 275596 | F14: 67232 | G14: 121275 | H14: 62098 | I14: 77382 | J14: 23226 | K14: 1024 | L14: 19102 | M14: 27932 | N14: 8785 | O14: 2266 | P14: 31703 | Q14: 1925 | R14: 476
... A22: 44793 | B22: 98100 | C22: 13275 | D22: 279686 | E22: 276198 | F22: 67238 | G22: 121484 | H22: 62098 | I22: 77616 | J22: 23272 | K22: 1024 | L22: 19123 | M22: 27972 | N22: 8808 | O22: 2276 | P22: 31768 | Q22: 1943 | R22: 501
A23: 44794 | B23: 9931 | C23: 13439 | D23: 279820 | E23: 276259 | F23: 67238 | G23: 121513 | H23: 62098 | I23: 77636 | J23: 23277 | K23: 1024 | L23: 19127 | M23: 27978 | N23: 8810 | O23: 2278 | P23: 31768 | Q23: 1950 | R23: 507 | S23: .
A24: 44795 | B24: 10079 | C24: 13642 | D24: 279974 | E24: 276331 | F24: 67239 | G24: 121543 | H24: 62098 | I24: 77683 | J24: 23283 | K24: 1024 | L24: 19129 | M24: 27983 | N24: 8813 | O24: 2279 | P24: 31791 | Q24: 1951 | R24: 510
A25: 44796 | B25: 10270 | C25: 13906 | D25: 280224 | E25: 276402 | F25: 67239 | G25: 121573 | H25: 62098 | I25: 77706 | J25: 23289 | K25: 1024 | L25: 19131 | M25: 27987 | N25: 8814 | O25: 2280 | P25: 31794 | Q25: 1952 | R25: 514
A26: 44797 | B26: 10456 | C26: 14062 | D26: 28049 | E26: 276481 | F26: 67242 | G26: 121605 | H26: 62098 | I26: 77733 | J26: 23295 | K26: 1024 | L26: 19134 | M26: 27992 | N26: 8818 | O26: 2282 | P26: 31794 | Q26: 1960 | R26: 517
A27: 44798 | B27: 10633 | C27: 14370 | D27: 280684 | E27: 276555 | F27: 67242 | G27: 121638 | H27: 62098 | I27: 77763 | J27: 23301 | K27: 1024 | L27: 19137 | M27: 27997 | N27: 8820 | O27: 2283 | P27: 31308 | Q27: 1969 | R27: 519
A28: 44799 | B28: 10805 | C28: 14628 | D28: 280880 | E28: 276645 | F28: 67243 | G28: 121679 | H28: 62098 | I28: 77811 | J28: 23308 | K28: 1024 | L28: 19140 | M28: 28004 | N28: 8823 | O28: 2285 | P28: 31924 | Q28: 1970 | R28: 525
A29: 44800 | B29: 10918 | C29: 14795 | D29: 281011 | E29: 276714 | F29: 67244 | G29: 121697 | H29: 62098 | I29: 77834 | J29: 23313 | K29: 1024 | L29: 19143 | M29: 28009 | N29: 8823 | O29: 2287 | P29: 31226 | Q29: 1973 | R29: 525
A30: 44801 | B30: 11047 | C30: 14992 | D30: 281158 | E30: 276795 | F30: 67244 | G30: 121728 | H30: 62098 | I30: 77857 | J30: 23320 | K30: 1024 | L30: 19147 | M30: 28015 | N30: 8831 | O30: 2289 | P30: 31826 | Q30: 1973 | R30: 529
A31: 44802 | B31: 11164 | C31: 15160 | D31: 281287 | E31: 276863 | F31: 67245 | G31: 121750 | H31: 62098 | I31: 77880 | J31: 23326 | K31: 1024 | L31: 19150 | M31: 28021 | N31: 8843 | O31: 2291 | P31: 31826 | Q31: 1973 | R31: 532
A32: 44803 | B32: 11307 | C32: 15373 | D32: 281497 | E32: 276929 | F32: 67246 | G32: 121772 | H32: 62048 | I32: 77898 | J32: 23332 | K32: 1024 | L32: 19153 | M32: 28027 | N32: 8845 | O32: 2292 | P32: 31826 | Q32: 1973 | R32: 536
A33: 44804
A34: 44805

Sheet Water consumption
A2: Date | B2: RO production (Ro 1 : 4) | C2: Total Consumption M3 (Meter 1 : 2) | E2: Water Bunglow | G2: Beach bunglow | I2: Main Pool | K2: Main kitchen | M2: Reef club kitchen | O2: Reef club pool | Q2: Bodu Huraa staff | S2: Kuda Huraa staff | U2: Laundry | W2: Second stage | Y2: Total
C3: M3 | D3: % of Total production | E3: M3 | F3: % | G3: M3 | H3: % | I3: M3 | J3: % | K3: M3 | L3: % | M3: M3 | N3: % | O3: M3 | P3: % | Q3: M3 | R3: % | S3: M3 | T3: % | U3: M3 | V3: % | W3: M3 | X3: % | Y3: M3 | Z3: %
A4: ='Water Reading'!A3 -> 44774 | B4: =TOTAL!I2 -> 326 | C4: =('Water Reading'!B4-'Water Reading'!B3)+('Water Reading'!C4-'Water Reading'!C3) -> 289 | D4: =C4/B4 -> 0.88650307 | E4: ='Water Reading'!H4-'Water Reading'!H3 -> 0 | F4: =E4/C4 -> 0 | G4: =('Water Reading'!D4-'Water Reading'!D3)-('Water Reading'!R4-'Water Reading'!R3)-('Water Reading'!Q4-'Water Reading'!Q3) -> 76 | H4: =G4/C4 -> 0.26297578 | I4: ='Water Reading'!P4-'Water Reading'!P3 -> 9 | J4: =I4/C4 -> 0.031141869 | K4: =('Water Reading'!I4-'Water Reading'!I3)-('Water Reading'!P4-'Water Reading'!P3) -> 21 | L4: =K4/C4 -> 0.07266436 | M4: ='Water Reading'!R4-'Water Reading'!R3 -> 4 | N4: =M4/C4 -> 0.01384083 | O4: ='Water Reading'!Q4-'Water Reading'!Q3 -> 0 | P4: =O4/C4 -> 0 | Q4: ='Water Reading'!F4-'Water Reading'!F3 -> 0 | R4: =Q4/C4 -> 0 | S4: ='Water Reading'!E4-'Water Reading'!E3 -> 83 | T4: =S4/C4 -> 0.28719723 | U4: ='Water Reading'!G4-'Water Reading'!G3 -> 28 | V4: =U4/C4 -> 0.096885813 | W4: ='Water Reading'!J4-'Water Reading'!J3 -> 6 | X4: =W4/C4 -> 0.020761246 | Y4: =E4+I4+K4+M4+O4+G4+Q4+S4+U4+W4 -> 227 | Z4: =Y4/B4 -> 0.69631902
A5: ='Water Reading'!A4 -> 44775 | B5: =TOTAL!I3 -> 336 | C5: =('Water Reading'!B5-'Water Reading'!B4)+('Water Reading'!C5-'Water Reading'!C4) -> 346 | D5: =C5/B5 -> 1.0297619 | E5: ='Water Reading'!H5-'Water Reading'!H4 -> 0 | F5: =E5/C5 -> 0 | G5: =('Water Reading'!D5-'Water Reading'!D4)-('Water Reading'!R5-'Water Reading'!R4)-('Water Reading'!Q5-'Water Reading'!Q4) -> 147 | H5: =G5/C5 -> 0.42485549 | I5: ='Water Reading'!P5-'Water Reading'!P4 -> 0 | J5: =I5/C5 -> 0 | K5: =('Water Reading'!I5-'Water Reading'!I4)-('Water Reading'!P5-'Water Reading'!P4) -> 15 | L5: =K5/C5 -> 0.043352601 | M5: ='Water Reading'!R5-'Water Reading'!R4 -> 3 | N5: =M5/C5 -> 0.0086705202 | O5: ='Water Reading'!Q5-'Water Reading'!Q4 -> 0 | P5: =O5/C5 -> 0 | Q5: ='Water Reading'!F5-'Water Reading'!F4 -> 1 | R5: =Q5/C5 -> 0.0028901734 | S5: ='Water Reading'!E5-'Water Reading'!E4 -> 73 | T5: =S5/C5 -> 0.21098266 | U5: ='Water Reading'!G5-'Water Reading'!G4 -> 14 | V5: =U5/C5 -> 0.040462428 | W5: ='Water Reading'!J5-'Water Reading'!J4 -> 5 | X5: =W5/C5 -> 0.014450867 | Y5: =E5+I5+K5+M5+O5+G5+Q5+S5+U5+W5 -> 258 | Z5: =Y5/B5 -> 0.76785714
A6: ='Water Reading'!A5 -> 44776 | B6: =TOTAL!I4 -> 301 | C6: =('Water Reading'!B6-'Water Reading'!B5)+('Water Reading'!C6-'Water Reading'!C5) -> 297 | D6: =C6/B6 -> 0.98671096 | E6: ='Water Reading'!H6-'Water Reading'!H5 -> 0 | F6: =E6/C6 -> 0 | G6: =('Water Reading'!D6-'Water Reading'!D5)-('Water Reading'!R6-'Water Reading'!R5)-('Water Reading'!Q6-'Water Reading'!Q5) -> 113 | H6: =G6/C6 -> 0.38047138 | I6: ='Water Reading'!P6-'Water Reading'!P5 -> 8 | J6: =I6/C6 -> 0.026936027 | K6: =('Water Reading'!I6-'Water Reading'!I5)-('Water Reading'!P6-'Water Reading'!P5) -> 20 | L6: =K6/C6 -> 0.067340067 | M6: ='Water Reading'!R6-'Water Reading'!R5 -> 5 | N6: =M6/C6 -> 0.016835017 | O6: ='Water Reading'!Q6-'Water Reading'!Q5 -> 0 | P6: =O6/C6 -> 0 | Q6: ='Water Reading'!F6-'Water Reading'!F5 -> 1 | R6: =Q6/C6 -> 0.0033670034 | S6: ='Water Reading'!E6-'Water Reading'!E5 -> 75 | T6: =S6/C6 -> 0.25252525 | U6: ='Water Reading'!G6-'Water Reading'!G5 -> 20 | V6: =U6/C6 -> 0.067340067 | W6: ='Water Reading'!J6-'Water Reading'!J5 -> 6 | X6: =W6/C6 -> 0.02020202 | Y6: =E6+I6+K6+M6+O6+G6+Q6+S6+U6+W6 -> 248 | Z6: =Y6/B6 -> 0.82392027
A7: ='Water Reading'!A6 -> 44777 | B7: =TOTAL!I5 -> 259 | C7: =('Water Reading'!B7-'Water Reading'!B6)+('Water Reading'!C7-'Water Reading'!C6) -> 292 | D7: =C7/B7 -> 1.1274131 | E7: ='Water Reading'!H7-'Water Reading'!H6 -> 0 | F7: =E7/C7 -> 0 | G7: =('Water Reading'!D7-'Water Reading'!D6)-('Water Reading'!R7-'Water Reading'!R6)-('Water Reading'!Q7-'Water Reading'!Q6) -> 95 | H7: =G7/C7 -> 0.32534247 | I7: ='Water Reading'!P7-'Water Reading'!P6 -> 13 | J7: =I7/C7 -> 0.044520548 | K7: =('Water Reading'!I7-'Water Reading'!I6)-('Water Reading'!P7-'Water Reading'!P6) -> 23 | L7: =K7/C7 -> 0.078767123 | M7: ='Water Reading'!R7-'Water Reading'!R6 -> 4 | N7: =M7/C7 -> 0.01369863 | O7: ='Water Reading'!Q7-'Water Reading'!Q6 -> 0 | P7: =O7/C7 -> 0 | Q7: ='Water Reading'!F7-'Water Reading'!F6 -> 0 | R7: =Q7/C7 -> 0 | S7: ='Water Reading'!E7-'Water Reading'!E6 -> 74 | T7: =S7/C7 -> 0.25342466 | U7: ='Water Reading'!G7-'Water Reading'!G6 -> 21 | V7: =U7/C7 -> 0.071917808 | W7: ='Water Reading'!J7-'Water Reading'!J6 -> 6 | X7: =W7/C7 -> 0.020547945 | Y7: =E7+I7+K7+M7+O7+G7+Q7+S7+U7+W7 -> 236 | Z7: =Y7/B7 -> 0.91119691
A8: ='Water Reading'!A7 -> 44778 | B8: =TOTAL!I6 -> 282 | C8: =('Water Reading'!B8-'Water Reading'!B7)+('Water Reading'!C8-'Water Reading'!C7) -> 294 | D8: =C8/B8 -> 1.0425532 | E8: ='Water Reading'!H8-'Water Reading'!H7 -> 0 | F8: =E8/C8 -> 0 | G8: =('Water Reading'!D8-'Water Reading'!D7)-('Water Reading'!R8-'Water Reading'!R7)-('Water Reading'!Q8-'Water Reading'!Q7) -> 135 | H8: =G8/C8 -> 0.45918367 | I8: ='Water Reading'!P8-'Water Reading'!P7 -> 6 | J8: =I8/C8 -> 0.020408163 | K8: =('Water Reading'!I8-'Water Reading'!I7)-('Water Reading'!P8-'Water Reading'!P7) -> 15 | L8: =K8/C8 -> 0.051020408 | M8: ='Water Reading'!R8-'Water Reading'!R7 -> 1 | N8: =M8/C8 -> 0.0034013605 | O8: ='Water Reading'!Q8-'Water Reading'!Q7 -> 0 | P8: =O8/C8 -> 0 | Q8: ='Water Reading'!F8-'Water Reading'!F7 -> 1 | R8: =Q8/C8 -> 0.0034013605 | S8: ='Water Reading'!E8-'Water Reading'!E7 -> 73 | T8: =S8/C8 -> 0.24829932 | U8: ='Water Reading'!G8-'Water Reading'!G7 -> 16 | V8: =U8/C8 -> 0.054421769 | W8: ='Water Reading'!J8-'Water Reading'!J7 -> 5 | X8: =W8/C8 -> 0.017006803 | Y8: =E8+I8+K8+M8+O8+G8+Q8+S8+U8+W8 -> 252 | Z8: =Y8/B8 -> 0.89361702
A9: ='Water Reading'!A8 -> 44779 | B9: =TOTAL!I7 -> 341 | C9: =('Water Reading'!B9-'Water Reading'!B8)+('Water Reading'!C9-'Water Reading'!C8) -> 347 | D9: =C9/B9 -> 1.0175953 | E9: ='Water Reading'!H9-'Water Reading'!H8 -> 0 | F9: =E9/C9 -> 0 | G9: =('Water Reading'!D9-'Water Reading'!D8)-('Water Reading'!R9-'Water Reading'!R8)-('Water Reading'!Q9-'Water Reading'!Q8) -> 184 | H9: =G9/C9 -> 0.53025937 | I9: ='Water Reading'!P9-'Water Reading'!P8 -> 0 | J9: =I9/C9 -> 0 | K9: =('Water Reading'!I9-'Water Reading'!I8)-('Water Reading'!P9-'Water Reading'!P8) -> 14 | L9: =K9/C9 -> 0.040345821 | M9: ='Water Reading'!R9-'Water Reading'!R8 -> 5 | N9: =M9/C9 -> 0.014409222 | O9: ='Water Reading'!Q9-'Water Reading'!Q8 -> 0 | P9: =O9/C9 -> 0 | Q9: ='Water Reading'!F9-'Water Reading'!F8 -> 0 | R9: =Q9/C9 -> 0 | S9: ='Water Reading'!E9-'Water Reading'!E8 -> 65 | T9: =S9/C9 -> 0.18731988 | U9: ='Water Reading'!G9-'Water Reading'!G8 -> 21 | V9: =U9/C9 -> 0.060518732 | W9: ='Water Reading'!J9-'Water Reading'!J8 -> 6 | X9: =W9/C9 -> 0.017291066 | Y9: =E9+I9+K9+M9+O9+G9+Q9+S9+U9+W9 -> 295 | Z9: =Y9/B9 -> 0.86510264
