Workbook

Sheet TOTAL
A1: Site Name | B1: Day | C1: Month | D1: Year | E1: Total Electricity Kwh | F1: Electricity Tariff ($/Kwh) | G1: Natual Gas (m3) | H1: Natural Gas $/m3 | I1: District Energy Cooling Kwh | J1: District Energy Cooling $/Kwh | K1: Water Utility Supply (m3) m3 | L1: Water Utility Supply (m3) $/m3 | M1: Room Nights | N1: Total Guests
A2: Abu Dhabi | B2: 1 | C2: 8 | D2: 2022 | E2: =Submetering!E2+Submetering!F2+Submetering!G2+Submetering!H2+Submetering!I2+Submetering!J2+Submetering!K2 -> 32105 | F2: 0.2 | G2: =Submetering!P2 -> 594 | H2: 6.47 | I2: =Submetering!T2-Submetering!T2*15%-Submetering!X2 -> 58542.03 | J2: 0.21 | K2: =Submetering!N2-Submetering!O2 -> 112.265 | L2: 7.84 | M2: 66 | N2: =Submetering!Z2 -> 104
A3: Abu Dhabi | B3: =B2+1 -> 2 | C3: 8 | D3: 2022 | E3: =Submetering!E3+Submetering!F3+Submetering!G3+Submetering!H3+Submetering!I3+Submetering!J3+Submetering!K3 -> 32533 | F3: 0.2 | G3: =Submetering!P3 -> 624 | H3: 6.47 | I3: =Submetering!T3-Submetering!T3*15%-Submetering!X3 -> 61902.593 | J3: 0.21 | K3: =Submetering!N3-Submetering!O3 -> 122.746 | L3: 7.84 | M3: 67 | N3: =Submetering!Z3 -> 104
A4: Abu Dhabi | B4: =B3+1 -> 3 | C4: 8 | D4: 2022 | E4: =Submetering!E4+Submetering!F4+Submetering!G4+Submetering!H4+Submetering!I4+Submetering!J4+Submetering!K4 -> 31830 | F4: 0.2 | G4: =Submetering!P4 -> 615 | H4: 6.47 | I4: =Submetering!T4-Submetering!T4*15%-Submetering!X4 -> 63341.054 | J4: 0.21 | K4: =Submetering!N4-Submetering!O4 -> 104.731 | L4: 7.84 | M4: 58 | N4: =Submetering!Z4 -> 95
A5: Abu Dhabi | B5: =B4+1 -> 4 | C5: 8 | D5: 2022 | E5: =Submetering!E5+Submetering!F5+Submetering!G5+Submetering!H5+Submetering!I5+Submetering!J5+Submetering!K5 -> 32703 | F5: 0.2 | G5: =Submetering!P5 -> 659 | H5: 6.47 | I5: =Submetering!T5-Submetering!T5*15%-Submetering!X5 -> 72093.565 | J5: 0.21 | K5: =Submetering!N5-Submetering!O5 -> 133.545 | L5: 7.84 | M5: 67 | N5: =Submetering!Z5 -> 121
A6: Abu Dhabi | B6: =B5+1 -> 5 | C6: 8 | D6: 2022 | E6: =Submetering!E6+Submetering!F6+Submetering!G6+Submetering!H6+Submetering!I6+Submetering!J6+Submetering!K6 -> 33163 | F6: 0.2 | G6: =Submetering!P6 -> 672 | H6: 6.47 | I6: =Submetering!T6-Submetering!T6*15%-Submetering!X6 -> 70924.313 | J6: 0.21 | K6: =Submetering!N6-Submetering!O6 -> 144.708 | L6: 7.84 | M6: 76 | N6: =Submetering!Z6 -> 145
A7: Abu Dhabi | B7: =B6+1 -> 6 | C7: 8 | D7: 2022 | E7: =Submetering!E7+Submetering!F7+Submetering!G7+Submetering!H7+Submetering!I7+Submetering!J7+Submetering!K7 -> 33282 | F7: 0.2 | G7: =Submetering!P7 -> 681 | H7: 6.47 | I7: =Submetering!T7-Submetering!T7*15%-Submetering!X7 -> 66884.866 | J7: 0.21 | K7: =Submetering!N7-Submetering!O7 -> 133.897 | L7: 7.84 | M7: 86 | N7: =Submetering!Z7 -> 168
A8: Abu Dhabi | B8: =B7+1 -> 7 | C8: 8 | D8: 2022 | E8: =Submetering!E8+Submetering!F8+Submetering!G8+Submetering!H8+Submetering!I8+Submetering!J8+Submetering!K8 -> 32519 | F8: 0.2 | G8: =Submetering!P8 -> 539 | H8: 6.47 | I8: =Submetering!T8-Submetering!T8*15%-Submetering!X8 -> 61589.93 | J8: 0.21 | K8: =Submetering!N8-Submetering!O8 -> 101.285 | L8: 7.84 | M8: 63 | N8: =Submetering!Z8 -> 112
A9: Abu Dhabi | B9: =B8+1 -> 8 | C9: 8 | D9: 2022 | E9: =Submetering!E9+Submetering!F9+Submetering!G9+Submetering!H9+Submetering!I9+Submetering!J9+Submetering!K9 -> 32464 | F9: 0.2 | G9: =Submetering!P9 -> 611 | H9: 6.47 | I9: =Submetering!T9-Submetering!T9*15%-Submetering!X9 -> 71565.25 | J9: 0.21 | K9: =Submetering!N9-Submetering!O9 -> 117.849 | L9: 7.84 | M9: 79 | N9: =Submetering!Z9 -> 141
A10: Abu Dhabi | B10: =B9+1 -> 9 | C10: 8 | D10: 2022 | E10: =Submetering!E10+Submetering!F10+Submetering!G10+Submetering!H10+Submetering!I10+Submetering!J10+Submetering!K10 -> 33272 | F10: 0.2 | G10: =Submetering!P10 -> 618 | H10: 6.47 | I10: =Submetering!T10-Submetering!T10*15%-Submetering!X10 -> 66267.089 | J10: 0.21 | K10: =Submetering!N10-Submetering!O10 -> 131.635 | L10: 7.84 | M10: 93 | N10: =Submetering!Z10 -> 169
A11: Abu Dhabi | B11: =B10+1 -> 10 | C11: 8 | D11: 2022 | E11: =Submetering!E11+Submetering!F11+Submetering!G11+Submetering!H11+Submetering!I11+Submetering!J11+Submetering!K11 -> 34233 | F11: 0.2 | G11: =Submetering!P11 -> 613 | H11: 6.47 | I11: =Submetering!T11-Submetering!T11*15%-Submetering!X11 -> 77603.167 | J11: 0.21 | K11: =Submetering!N11-Submetering!O11 -> 113.976 | L11: 7.84 | M11: 87 | N11: =Submetering!Z11 -> 152
A12: Abu Dhabi | B12: =B11+1 -> 11 | C12: 8 | D12: 2022 | E12: =Submetering!E12+Submetering!F12+Submetering!G12+Submetering!H12+Submetering!I12+Submetering!J12+Submetering!K12 -> 35189 | F12: 0.2 | G12: =Submetering!P12 -> 627 | H12: 6.47 | I12: =Submetering!T12-Submetering!T12*15%-Submetering!X12 -> 80193.379 | J12: 0.21 | K12: =Submetering!N12-Submetering!O12 -> 114.416 | L12: 7.84 | M12: 73 | N12: =Submetering!Z12 -> 125
A13: Abu Dhabi | B13: =B12+1 -> 12 | C13: 8 | D13: 2022 | E13: =Submetering!E13+Submetering!F13+Submetering!G13+Submetering!H13+Submetering!I13+Submetering!J13+Submetering!K13 -> 34414 | F13: 0.2 | G13: =Submetering!P13 -> 638 | H13: 6.47 | I13: =Submetering!T13-Submetering!T13*15%-Submetering!X13 -> 84139.471 | J13: 0.21 | K13: =Submetering!N13-Submetering!O13 -> 108.946 | L13: 7.84 | M13: 82 | N13: =Submetering!Z13 -> 147
A14: Abu Dhabi | B14: =B13+1 -> 13 | C14: 8 | D14: 2022 | E14: =Submetering!E14+Submetering!F14+Submetering!G14+Submetering!H14+Submetering!I14+Submetering!J14+Submetering!K14 -> 34092 | F14: 0.2 | G14: =Submetering!P14 -> 660 | H14: 6.47 | I14: =Submetering!T14-Submetering!T14*15%-Submetering!X14 -> 58219.734 | J14: 0.21 | K14: =Submetering!N14-Submetering!O14 -> 109.026 | L14: 7.84 | M14: 64 | N14: =Submetering!Z14 -> 116
... A32: Abu Dhabi | B32: =B31+1 -> 31 | C32: 8 | D32: 2022 | E32: =Submetering!E32+Submetering!F32+Submetering!G32+Submetering!H32+Submetering!I32+Submetering!J32+Submetering!K32 -> 32179 | F32: 0.2 | G32: =Submetering!P32 -> 720 | H32: 6.47 | I32: =Submetering!T32-Submetering!T32*15%-Submetering!X32 -> 58301.761 | J32: 0.21 | K32: =Submetering!N32-Submetering!O32 -> 119.747 | L32: 7.84 | M32: 64 | N32: =Submetering!Z32 -> 102
E33: =SUM(E2:E32) -> 1022642 | G33: =SUM(G2:G32) -> 19680 | I33: =SUM(I2:I32) -> 2010064 | K33: =SUM(K2:K32) -> 3572.803 | M33: =SUM(M2:M32) -> 2082 | N33: =SUM(N2:N32) -> 3690

Sheet Submetering
A1: Site Name | B1: Day | C1: Month | D1: Year | E1: LVS-1 SECTION A - KWh | F1: LVS-1 SECTION B - KWh | G1: LVS-2 (CAFE MILANO)- KWh | H1: LVS-3 SECTION A- KWh | I1: LVS-3 SECTION B- KWh | J1: LVS-4 SECTION A- KWh | K1: LVS-4 SECTION B- KWh | L1: LVS-5 (FLOOR 15-32) KWh | M1: LVS-LRLV (RETAIL)KWh | N1: Total Water- m3 | O1: Galleria Water m3 | P1: Main Gas m3 | Q1: HW Boiler Gas - m3 | R1: Steam Boiler Gas- m3 | S1: Total Kitchen- m3 | T1: Main District Cooling- KWh | U1: Podium District Cooling- KWh | V1: Guest Rooms District Cooling- KWh | W1: Residence District Cooling- KWh | X1: Galleria District Cooling KWh | Y1: Room Nights | Z1: Total Guests
A2: Abu Dhabi | B2: 1 | C2: 8 | D2: 2022 | E2: ='FS-AD Daily '!B6 -> 5328 | F2: ='FS-AD Daily '!C6 -> 3217 | G2: ='FS-AD Daily '!D6 -> 861 | H2: ='FS-AD Daily '!E6 -> 7091 | I2: ='FS-AD Daily '!F6 -> 5995 | J2: ='FS-AD Daily '!G6 -> 2760 | K2: ='FS-AD Daily '!H6 -> 6853 | L2: ='FS-AD Daily '!I6 -> 2256 | M2: ='FS-AD Daily '!J6 -> 6806 | N2: ='FS-AD Daily '!T6 -> 178.283 | O2: ='FS-AD Daily '!R6 -> 66.018 | P2: ='FS-AD Daily '!Z6 -> 594 | Q2: ='FS-AD Daily '!V6 -> 158.1 | R2: ='FS-AD Daily '!W6 -> 173.18 | S2: =P2-Q2-R2 -> 262.72 | T2: ='FS-AD Daily '!AD6*3.516 -> 101461.21 | U2: =('FS-AD Daily '!AF6)*1000 -> 46300 | V2: =('FS-AD Daily '!AG6)*1000 -> 0 | W2: ='FS-AD Daily '!AH6*1000 -> 17000 | X2: =('FS-AD Daily '!AK6)*1000 -> 27700 | Y2: 66 | Z2: 104
A3: Abu Dhabi | B3: =B2+1 -> 2 | C3: 8 | D3: 2022 | E3: ='FS-AD Daily '!B7 -> 5435 | F3: ='FS-AD Daily '!C7 -> 3304 | G3: ='FS-AD Daily '!D7 -> 881 | H3: ='FS-AD Daily '!E7 -> 7223 | I3: ='FS-AD Daily '!F7 -> 6163 | J3: ='FS-AD Daily '!G7 -> 2704 | K3: ='FS-AD Daily '!H7 -> 6823 | L3: ='FS-AD Daily '!I7 -> 2253 | M3: ='FS-AD Daily '!J7 -> 6826 | N3: ='FS-AD Daily '!T7 -> 195.459 | O3: ='FS-AD Daily '!R7 -> 72.713 | P3: ='FS-AD Daily '!Z7 -> 624 | Q3: ='FS-AD Daily '!V7 -> 175.5 | R3: ='FS-AD Daily '!W7 -> 180.89 | S3: =P3-Q3-R3 -> 267.61 | T3: ='FS-AD Daily '!AD7*3.516 -> 105297.17 | U3: =('FS-AD Daily '!AF7)*1000 -> 48600 | V3: =('FS-AD Daily '!AG7)*1000 -> 0 | W3: ='FS-AD Daily '!AH7*1000 -> 17500 | X3: =('FS-AD Daily '!AK7)*1000 -> 27600 | Y3: 67 | Z3: 104
A4: Abu Dhabi | B4: =B3+1 -> 3 | C4: 8 | D4: 2022 | E4: ='FS-AD Daily '!B8 -> 5316 | F4: ='FS-AD Daily '!C8 -> 3164 | G4: ='FS-AD Daily '!D8 -> 795 | H4: ='FS-AD Daily '!E8 -> 7010 | I4: ='FS-AD Daily '!F8 -> 6085 | J4: ='FS-AD Daily '!G8 -> 2748 | K4: ='FS-AD Daily '!H8 -> 6712 | L4: ='FS-AD Daily '!I8 -> 2261 | M4: ='FS-AD Daily '!J8 -> 6784 | N4: ='FS-AD Daily '!T8 -> 175.74 | O4: ='FS-AD Daily '!R8 -> 71.009 | P4: ='FS-AD Daily '!Z8 -> 615 | Q4: ='FS-AD Daily '!V8 -> 168 | R4: ='FS-AD Daily '!W8 -> 174.4 | S4: =P4-Q4-R4 -> 272.6 | T4: ='FS-AD Daily '!AD8*3.516 -> 107930.65 | U4: =('FS-AD Daily '!AF8)*1000 -> 49700 | V4: =('FS-AD Daily '!AG8)*1000 -> 0 | W4: ='FS-AD Daily '!AH8*1000 -> 17500 | X4: =('FS-AD Daily '!AK8)*1000 -> 28400 | Y4: 58 | Z4: 95
A5: Abu Dhabi | B5: =B4+1 -> 4 | C5: 8 | D5: 2022 | E5: ='FS-AD Daily '!B9 -> 5399 | F5: ='FS-AD Daily '!C9 -> 3541 | G5: ='FS-AD Daily '!D9 -> 883 | H5: ='FS-AD Daily '!E9 -> 6923 | I5: ='FS-AD Daily '!F9 -> 6243 | J5: ='FS-AD Daily '!G9 -> 2968 | K5: ='FS-AD Daily '!H9 -> 6746 | L5: ='FS-AD Daily '!I9 -> 2330 | M5: ='FS-AD Daily '!J9 -> 6903 | N5: ='FS-AD Daily '!T9 -> 208.345 | O5: ='FS-AD Daily '!R9 -> 74.8 | P5: ='FS-AD Daily '!Z9 -> 659 | Q5: ='FS-AD Daily '!V9 -> 202.6 | R5: ='FS-AD Daily '!W9 -> 180.1 | S5: =P5-Q5-R5 -> 276.3 | T5: ='FS-AD Daily '!AD9*3.516 -> 120110.08 | U5: =('FS-AD Daily '!AF9)*1000 -> 56200 | V5: =('FS-AD Daily '!AG9)*1000 -> 0 | W5: ='FS-AD Daily '!AH9*1000 -> 17800 | X5: =('FS-AD Daily '!AK9)*1000 -> 30000 | Y5: 67 | Z5: 121
A6: Abu Dhabi | B6: =B5+1 -> 5 | C6: 8 | D6: 2022 | E6: ='FS-AD Daily '!B10 -> 5394 | F6: ='FS-AD Daily '!C10 -> 3992 | G6: ='FS-AD Daily '!D10 -> 892 | H6: ='FS-AD Daily '!E10 -> 6869 | I6: ='FS-AD Daily '!F10 -> 6170 | J6: ='FS-AD Daily '!G10 -> 3097 | K6: ='FS-AD Daily '!H10 -> 6749 | L6: ='FS-AD Daily '!I10 -> 2259 | M6: ='FS-AD Daily '!J10 -> 6923 | N6: ='FS-AD Daily '!T10 -> 216.253 | O6: ='FS-AD Daily '!R10 -> 71.545 | P6: ='FS-AD Daily '!Z10 -> 672 | Q6: ='FS-AD Daily '!V10 -> 205.8 | R6: ='FS-AD Daily '!W10 -> 170.53 | S6: =P6-Q6-R6 -> 295.67 | T6: ='FS-AD Daily '!AD10*3.516 -> 118028.6 | U6: =('FS-AD Daily '!AF10)*1000 -> 55800 | V6: =('FS-AD Daily '!AG10)*1000 -> 0 | W6: ='FS-AD Daily '!AH10*1000 -> 17100 | X6: =('FS-AD Daily '!AK10)*1000 -> 29400 | Y6: 76 | Z6: 145
A7: Abu Dhabi | B7: =B6+1 -> 6 | C7: 8 | D7: 2022 | E7: ='FS-AD Daily '!B11 -> 5445 | F7: ='FS-AD Daily '!C11 -> 4134 | G7: ='FS-AD Daily '!D11 -> 856 | H7: ='FS-AD Daily '!E11 -> 6946 | I7: ='FS-AD Daily '!F11 -> 6290 | J7: ='FS-AD Daily '!G11 -> 2976 | K7: ='FS-AD Daily '!H11 -> 6635 | L7: ='FS-AD Daily '!I11 -> 2181 | M7: ='FS-AD Daily '!J11 -> 6924 | N7: ='FS-AD Daily '!T11 -> 211.717 | O7: ='FS-AD Daily '!R11 -> 77.82 | P7: ='FS-AD Daily '!Z11 -> 681 | Q7: ='FS-AD Daily '!V11 -> 192.6 | R7: ='FS-AD Daily '!W11 -> 170.7 | S7: =P7-Q7-R7 -> 317.7 | T7: ='FS-AD Daily '!AD11*3.516 -> 112923.37 | U7: =('FS-AD Daily '!AF11)*1000 -> 52900 | V7: =('FS-AD Daily '!AG11)*1000 -> 0 | W7: ='FS-AD Daily '!AH11*1000 -> 17100 | X7: =('FS-AD Daily '!AK11)*1000 -> 29100 | Y7: 86 | Z7: 168
A8: Abu Dhabi | B8: =B7+1 -> 7 | C8: 8 | D8: 2022 | E8: ='FS-AD Daily '!B12 -> 5383 | F8: ='FS-AD Daily '!C12 -> 3800 | G8: ='FS-AD Daily '!D12 -> 830 | H8: ='FS-AD Daily '!E12 -> 7093 | I8: ='FS-AD Daily '!F12 -> 5955 | J8: ='FS-AD Daily '!G12 -> 2869 | K8: ='FS-AD Daily '!H12 -> 6589 | L8: ='FS-AD Daily '!I12 -> 2224 | M8: ='FS-AD Daily '!J12 -> 6770 | N8: ='FS-AD Daily '!T12 -> 170.678 | O8: ='FS-AD Daily '!R12 -> 69.393 | P8: ='FS-AD Daily '!Z12 -> 539 | Q8: ='FS-AD Daily '!V12 -> 166.1 | R8: ='FS-AD Daily '!W12 -> 146.31 | S8: =P8-Q8-R8 -> 226.59 | T8: ='FS-AD Daily '!AD12*3.516 -> 104576.39 | U8: =('FS-AD Daily '!AF12)*1000 -> 49100 | V8: =('FS-AD Daily '!AG12)*1000 -> 0 | W8: ='FS-AD Daily '!AH12*1000 -> 16700 | X8: =('FS-AD Daily '!AK12)*1000 -> 27300 | Y8: 63 | Z8: 112
A9: Abu Dhabi | B9: =B8+1 -> 8 | C9: 8 | D9: 2022 | E9: ='FS-AD Daily '!B13 -> 5190 | F9: ='FS-AD Daily '!C13 -> 4030 | G9: ='FS-AD Daily '!D13 -> 860 | H9: ='FS-AD Daily '!E13 -> 6925 | I9: ='FS-AD Daily '!F13 -> 5849 | J9: ='FS-AD Daily '!G13 -> 3070 | K9: ='FS-AD Daily '!H13 -> 6540 | L9: ='FS-AD Daily '!I13 -> 2233 | M9: ='FS-AD Daily '!J13 -> 6571 | N9: ='FS-AD Daily '!T13 -> 182.954 | O9: ='FS-AD Daily '!R13 -> 65.105 | P9: ='FS-AD Daily '!Z13 -> 611 | Q9: ='FS-AD Daily '!V13 -> 163.5 | R9: ='FS-AD Daily '!W13 -> 176.7 | S9: =P9-Q9-R9 -> 270.8 | T9: ='FS-AD Daily '!AD13*3.516 -> 118665 | U9: =('FS-AD Daily '!AF13)*1000 -> 56200 | V9: =('FS-AD Daily '!AG13)*1000 -> 0 | W9: ='FS-AD Daily '!AH13*1000 -> 18200 | X9: =('FS-AD Daily '!AK13)*1000 -> 29300 | Y9: 79 | Z9: 141
A10: Abu Dhabi | B10: =B9+1 -> 9 | C10: 8 | D10: 2022 | E10: ='FS-AD Daily '!B14 -> 5312 | F10: ='FS-AD Daily '!C14 -> 4487 | G10: ='FS-AD Daily '!D14 -> 875 | H10: ='FS-AD Daily '!E14 -> 6947 | I10: ='FS-AD Daily '!F14 -> 5892 | J10: ='FS-AD Daily '!G14 -> 3054 | K10: ='FS-AD Daily '!H14 -> 6705 | L10: ='FS-AD Daily '!I14 -> 2215 | M10: ='FS-AD Daily '!J14 -> 6643 | N10: ='FS-AD Daily '!T14 -> 188.818 | O10: ='FS-AD Daily '!R14 -> 57.183 | P10: ='FS-AD Daily '!Z14 -> 618 | Q10: ='FS-AD Daily '!V14 -> 182.7 | R10: ='FS-AD Daily '!W14 -> 177.2 | S10: =P10-Q10-R10 -> 258.1 | T10: ='FS-AD Daily '!AD14*3.516 -> 110078.93 | U10: =('FS-AD Daily '!AF14)*1000 -> 52600 | V10: =('FS-AD Daily '!AG14)*1000 -> 0 | W10: ='FS-AD Daily '!AH14*1000 -> 16700 | X10: =('FS-AD Daily '!AK14)*1000 -> 27300 | Y10: 93 | Z10: 169
A11: Abu Dhabi | B11: =B10+1 -> 10 | C11: 8 | D11: 2022 | E11: ='FS-AD Daily '!B15 -> 5365 | F11: ='FS-AD Daily '!C15 -> 4789 | G11: ='FS-AD Daily '!D15 -> 835 | H11: ='FS-AD Daily '!E15 -> 6940 | I11: ='FS-AD Daily '!F15 -> 6120 | J11: ='FS-AD Daily '!G15 -> 3074 | K11: ='FS-AD Daily '!H15 -> 7110 | L11: ='FS-AD Daily '!I15 -> 2216 | M11: ='FS-AD Daily '!J15 -> 6667 | N11: ='FS-AD Daily '!T15 -> 184.872 | O11: ='FS-AD Daily '!R15 -> 70.896 | P11: ='FS-AD Daily '!Z15 -> 613 | Q11: ='FS-AD Daily '!V15 -> 172.4 | R11: ='FS-AD Daily '!W15 -> 182.36 | S11: =P11-Q11-R11 -> 258.24 | T11: ='FS-AD Daily '!AD15*3.516 -> 126709.61 | U11: =('FS-AD Daily '!AF15)*1000 -> 60600 | V11: =('FS-AD Daily '!AG15)*1000 -> 0 | W11: ='FS-AD Daily '!AH15*1000 -> 17200 | X11: =('FS-AD Daily '!AK15)*1000 -> 30100 | Y11: 87 | Z11: 152
A12: Abu Dhabi | B12: =B11+1 -> 11 | C12: 8 | D12: 2022 | E12: ='FS-AD Daily '!B16 -> 5361 | F12: ='FS-AD Daily '!C16 -> 5414 | G12: ='FS-AD Daily '!D16 -> 848 | H12: ='FS-AD Daily '!E16 -> 7223 | I12: ='FS-AD Daily '!F16 -> 6146 | J12: ='FS-AD Daily '!G16 -> 3042 | K12: ='FS-AD Daily '!H16 -> 7155 | L12: ='FS-AD Daily '!I16 -> 2266 | M12: ='FS-AD Daily '!J16 -> 6799 | N12: ='FS-AD Daily '!T16 -> 191.844 | O12: ='FS-AD Daily '!R16 -> 77.428 | P12: ='FS-AD Daily '!Z16 -> 627 | Q12: ='FS-AD Daily '!V16 -> 170.3 | R12: ='FS-AD Daily '!W16 -> 180.23 | S12: =P12-Q12-R12 -> 276.47 | T12: ='FS-AD Daily '!AD16*3.516 -> 130345.15 | U12: =('FS-AD Daily '!AF16)*1000 -> 63100 | V12: =('FS-AD Daily '!AG16)*1000 -> 0 | W12: ='FS-AD Daily '!AH16*1000 -> 17700 | X12: =('FS-AD Daily '!AK16)*1000 -> 30600 | Y12: 73 | Z12: 125
A13: Abu Dhabi | B13: =B12+1 -> 12 | C13: 8 | D13: 2022 | E13: ='FS-AD Daily '!B17 -> 5410 | F13: ='FS-AD Daily '!C17 -> 4982 | G13: ='FS-AD Daily '!D17 -> 852 | H13: ='FS-AD Daily '!E17 -> 6940 | I13: ='FS-AD Daily '!F17 -> 6085 | J13: ='FS-AD Daily '!G17 -> 3005 | K13: ='FS-AD Daily '!H17 -> 7140 | L13: ='FS-AD Daily '!I17 -> 2187 | M13: ='FS-AD Daily '!J17 -> 6784 | N13: ='FS-AD Daily '!T17 -> 181.006 | O13: ='FS-AD Daily '!R17 -> 72.06 | P13: ='FS-AD Daily '!Z17 -> 638 | Q13: ='FS-AD Daily '!V17 -> 181.5 | R13: ='FS-AD Daily '!W17 -> 183.02 | S13: =P13-Q13-R13 -> 273.48 | T13: ='FS-AD Daily '!AD17*3.516 -> 134634.67 | U13: =('FS-AD Daily '!AF17)*1000 -> 66700 | V13: =('FS-AD Daily '!AG17)*1000 -> 0 | W13: ='FS-AD Daily '!AH17*1000 -> 16900 | X13: =('FS-AD Daily '!AK17)*1000 -> 30300 | Y13: 82 | Z13: 147
A14: Abu Dhabi | B14: =B13+1 -> 13 | C14: 8 | D14: 2022 | E14: ='FS-AD Daily '!B18 -> 5531 | F14: ='FS-AD Daily '!C18 -> 4490 | G14: ='FS-AD Daily '!D18 -> 857 | H14: ='FS-AD Daily '!E18 -> 7020 | I14: ='FS-AD Daily '!F18 -> 6085 | J14: ='FS-AD Daily '!G18 -> 2949 | K14: ='FS-AD Daily '!H18 -> 7160 | L14: ='FS-AD Daily '!I18 -> 2238 | M14: ='FS-AD Daily '!J18 -> 6925 | N14: ='FS-AD Daily '!T18 -> 188.062 | O14: ='FS-AD Daily '!R18 -> 79.036 | P14: ='FS-AD Daily '!Z18 -> 660 | Q14: ='FS-AD Daily '!V18 -> 177.6 | R14: ='FS-AD Daily '!W18 -> 181.18 | S14: =P14-Q14-R14 -> 301.22 | T14: ='FS-AD Daily '!AD18*3.516 -> 101552.63 | U14: =('FS-AD Daily '!AF18)*1000 -> 56000 | V14: =('FS-AD Daily '!AG18)*1000 -> 0 | W14: ='FS-AD Daily '!AH18*1000 -> 18000 | X14: =('FS-AD Daily '!AK18)*1000 -> 28100 | Y14: 64 | Z14: 116
... A32: Abu Dhabi | B32: =B31+1 -> 31 | C32: 8 | D32: 2022 | E32: ='FS-AD Daily '!B36 -> 5572 | F32: ='FS-AD Daily '!C36 -> 4022 | G32: ='FS-AD Daily '!D36 -> 898 | H32: ='FS-AD Daily '!E36 -> 6532 | I32: ='FS-AD Daily '!F36 -> 6118 | J32: ='FS-AD Daily '!G36 -> 2665 | K32: ='FS-AD Daily '!H36 -> 6372 | L32: ='FS-AD Daily '!I36 -> 2461 | M32: ='FS-AD Daily '!J36 -> 6626 | N32: ='FS-AD Daily '!T36 -> 184.68 | O32: ='FS-AD Daily '!R36 -> 64.933 | P32: ='FS-AD Daily '!Z36 -> 720 | Q32: ='FS-AD Daily '!V36 -> 232.8 | R32: ='FS-AD Daily '!W36 -> 181.41 | S32: =P32-Q32-R32 -> 305.79 | T32: ='FS-AD Daily '!AD36*3.516 -> 100002.07 | U32: =('FS-AD Daily '!AF36)*1000 -> 52100 | V32: =('FS-AD Daily '!AG36)*1000 -> 0 | W32: ='FS-AD Daily '!AH36*1000 -> 16200 | X32: =('FS-AD Daily '!AK36)*1000 -> 26700 | Y32: 64 | Z32: 102
I33: =SUM(I2:I32) -> 188820 | J33: =SUM(J2:J32) -> 88938 | K33: =SUM(K2:K32) -> 205407 | L33: =SUM(L2:L32) -> 70941 | M33: =SUM(M2:M32) -> 209629 | N33: =SUM(N2:N32) -> 5767.506 | O33: =SUM(O2:O32) -> 2194.703 | P33: =SUM(P2:P32) -> 19680 | ... W33: =SUM(W2:W32) -> 526000 | X33: ='FS-AD Daily '!U38 -> 28010.776 | Y33: =SUM(Y2:Y32) -> 2082 | Z33: =SUM(Z2:Z32) -> 3690

Sheet FS-AD Daily 
A1: DATE | B1: ELECTRICAL METERS | K1: TOTAL CONSUMPTION (kWh) | L1: ELECTRICITY - TOTAL (AED) | M1: Concrete Tank Meter (Daily Consumption) | N1: Fiber tank Meter Cold Water Podium & Galleria Staff Toilet Section 2 | O1: Galleria Hot water Public Area | P1: Water Bulk 3 Meter Galleria (Daily Consumption) section 1 | Q1: Irrigation Tank Meter (Daily Consumption) | R1: Galleria Consumption m3 | S1: GALLERIA WATER TOTAL COST (AED) | T1: WATER METER (Daily Consumption) m3 | U1: FSH WATER (AED) | V1: Hot Water Boiler (Daily Gas Consumption m 3) | W1: Steam Boiler (Daily Gas Consumption m 3) | X1: GAS METERS (Daily Reading) | Z1: GAS (Daily Consumption m 3) | AA1: Natural GAS (AED) | AB1: CHILLED WATER (Daily Reading) Present HT | AC1: CHILLED WATER (Daily Reading) Previous HT | AD1: CHILLED WATER (Daily Consumption) HT | AE1: CHILLED WATER (AED) | AF1: Podium Chilled Water - MWh | AG1: Guest Room Chilled Water MWh | AH1: Residence Chilled Water MWh | AI1: Galleria chilled water MWH Previous | AJ1: Galleria chilled water MWH Present | AK1: Galleria Chilled Water Total MWH | AL1: Galleria Chilled Water Total HT | AM1: CHILLED WATER (AED) | AN1: OCCUPANCY (Room Night) | AO1: TOTAL (AED) | AQ1: THR AED (0.334529) | AR1: MWH = H.TON (1 = 284.34)
A2: 2022 | B2: 1 | C2: 2 | D2: 3 | E2: 4 | F2: 5 | G2: 6 | H2: 7 | I2: 8 | J2: 9 | K2: TOTAL CONSUMPTION (KWH) | L2: TOTAL AMOUNT (AED) | X2: 1 | Y2: 2 | AA2: (AED. 6.47/m3 + AED. 0.00 Service) | AC2: (K21B2419000) | AE2: AED. 0.327899/ Ton | AM2: AED. 0.327899/ Ton
B3: 4626096222-E | C3: 6572482789-E | D3: 3190048503-E | E3: 3732963488-E | F3: 4626096253-E | G3: 7651356710-E | H3: 5076351256-E | I3: 8990986529-E | J3: 6057081392-E
B4: LVS-1 SECTION A | C4: LVS-1 SECTION B | D4: LVS-2 (CAFÉ MILANO) | E4: LVS-3 SECTION A | F4: LVS-3 SECTION B | G4: LVS-4 SECTION A | H4: LVS-4 SECTION B | I4: LVS-5 (FLOOR 15-32) | J4: LVS-LRLV (RETAIL) | Y4: 1115587 | AB4: 15191348 | AI4: 56284.8 | AP4: 0.333415
A5: TOTAL | E5: Hot water calorifiers L 14 feed 15 - 19 floor | G5: Residence Apartment chilled water pump share feeder | H5: Residence Public Area Electric DB share feeder | I5: Residence apartments Electric DB (individual apartment feeder) | X5: Galleria independent supply | AA5: =SUM(#REF!) -> #REF! | AE5: =SUM(#REF!) -> #REF! | AK5: =SUM(#REF!) -> #REF! | AO5: =SUM(#REF!) -> #REF!
A6: 44774 | B6: =14583308-14577980 -> 5328 | C6: =9352265-9349048 -> 3217 | D6: =1864703-1863842 -> 861 | E6: =14143681-14136590 -> 7091 | F6: =13812909-13806914 -> 5995 | G6: =9453998-9451238 -> 2760 | H6: =10914839-10907986 -> 6853 | I6: =6116092-6113836 -> 2256 | J6: =14280639-14273833 -> 6806 | K6: =SUM(B6:H6) -> 32105 | L6: =K6*0.2 -> 6421 | M6: =44975.616-44813.964 -> 161.652 | N6: =5209.939-5206.6 -> 3.339 | O6: =10506.855-10506.709 -> 0.146 | P6: =18845.64-18783.107 -> 62.533 | Q6: =30649.092-30632.461 -> 16.631 | R6: =N6+O6+P6 -> 66.018 | S6: =(N6+O6+P6)*7.84 -> 517.58112 | T6: =M6+Q6 -> 178.283 | U6: =T6*7.84 -> 1397.7387 | V6: =432404.4-432246.3 -> 158.1 | W6: =175196.88-175023.7 -> 173.18 | X6: 0001523.20 | Y6: 1116181 | Z6: =IF((Y6-Y5<0), "0",Y6-Y4) -> 594 | AA6: =Z6*6.47 -> 3843.18 | AB6: 15220205 | AC6: =AB4 -> 15191348 | AD6: =IF((AB6-AC6<0), "0",AB6-AC6) -> 28857 | AE6: =AD6*0.327899 -> 9462.1814 | AF6: =103674.5-103628.2 -> 46.3 | AG6: =50692.5-50692.5 -> 0 | AH6: =32716.6-32699.6 -> 17 | AI6: =AI4 -> 56284.8 | AJ6: 56312.5 | AK6: =IF((AJ6-AI6)<0, "0",AJ6-AI6) -> 27.7 | AL6: =AK6*(284.34513609) -> 7876.3603 | AM6: =AL6*0.327899 -> 2582.6507 | AO6: =L6+U6+AA6+AE6 -> 21124.1
A7: 44775 | B7: =14588743-14583308 -> 5435 | C7: =9355569-9352265 -> 3304 | D7: =1865584-1864703 -> 881 | E7: =14150904-14143681 -> 7223 | F7: =13819072-13812909 -> 6163 | G7: =9456702-9453998 -> 2704 | H7: =10921662-10914839 -> 6823 | I7: =6118345-6116092 -> 2253 | J7: =14287465-14280639 -> 6826 | K7: =SUM(B7:H7) -> 32533 | L7: =K7*0.2 -> 6506.6 | M7: =45143.832-44975.616 -> 168.216 | N7: =5213.49-5209.939 -> 3.551 | O7: =10507.096-10506.855 -> 0.241 | P7: =18914.561-18845.64 -> 68.921 | Q7: =30676.335-30649.092 -> 27.243 | R7: =N7+O7+P7 -> 72.713 | S7: =(N7+O7+P7)*7.84 -> 570.06992 | T7: =M7+Q7 -> 195.459 | U7: =T7*7.84 -> 1532.3986 | V7: =432579.9-432404.4 -> 175.5 | W7: =175377.77-175196.88 -> 180.89 | X7: 0001523.20 | Y7: 1116805 | Z7: =IF((Y7-Y6<0), "0",Y7-Y6) -> 624 | AA7: =Z7*6.47 -> 4037.28 | AB7: 15250153 | AC7: =AB6 -> 15220205 | AD7: =IF((AB7-AC7<0), "0",AB7-AC7) -> 29948 | AE7: =AD7*0.327899 -> 9819.9193 | AF7: =103723.1-103674.5 -> 48.6 | AG7: =50692.5-50692.5 -> 0 | AH7: =32734.1-32716.6 -> 17.5 | AI7: =AJ6 -> 56312.5 | AJ7: 56340.1 | AK7: =IF((AJ7-AI7)<0, "0",AJ7-AI7) -> 27.6 | AL7: =AK7*(284.34513609) -> 7847.9258 | AM7: =AL7*0.327899 -> 2573.327 | AO7: =L7+U7+AA7+AE7 -> 21896.198
A8: 44776 | B8: =14594059-14588743 -> 5316 | C8: =9358733-9355569 -> 3164 | D8: =1866379-1865584 -> 795 | E8: =14157914-14150904 -> 7010 | F8: =13825157-13819072 -> 6085 | G8: =9459450-9456702 -> 2748 | H8: =10928374-10921662 -> 6712 | I8: =6120606-6118345 -> 2261 | J8: =14294249-14287465 -> 6784 | K8: =SUM(B8:H8) -> 31830 | L8: =K8*0.2 -> 6366 | M8: =45302.173-45143.832 -> 158.341 | N8: =5216.87-5213.49 -> 3.38 | O8: =10507.296-10507.096 -> 0.2 | P8: =18981.99-18914.561 -> 67.429 | Q8: =30693.734-30676.335 -> 17.399 | R8: =N8+O8+P8 -> 71.009 | S8: =(N8+O8+P8)*7.84 -> 556.71056 | T8: =M8+Q8 -> 175.74 | U8: =T8*7.84 -> 1377.8016 | V8: =432747.9-432579.9 -> 168 | W8: =175552.17-175377.77 -> 174.4 | X8: 0001523.20 | Y8: 1117420 | Z8: =IF((Y8-Y7<0), "0",Y8-Y7) -> 615 | AA8: =Z8*6.47 -> 3979.05 | AB8: 15280850 | AC8: =AB7 -> 15250153 | AD8: =IF((AB8-AC8<0), "0",AB8-AC8) -> 30697 | AE8: =AD8*0.327899 -> 10065.516 | AF8: =103772.8-103723.1 -> 49.7 | AG8: =50692.5-50692.5 -> 0 | AH8: =32751.6-32734.1 -> 17.5 | AI8: =AJ7 -> 56340.1 | AJ8: 56368.5 | AK8: =IF((AJ8-AI8)<0, "0",AJ8-AI8) -> 28.4 | AL8: =AK8*(284.34513609) -> 8075.4019 | AM8: =AL8*0.327899 -> 2647.9162 | AO8: =L8+U8+AA8+AE8 -> 21788.367
A9: 44777 | B9: =14599458-14594059 -> 5399 | C9: =9362274-9358733 -> 3541 | D9: =1867262-1866379 -> 883 | E9: =14164837-14157914 -> 6923 | F9: =13831400-13825157 -> 6243 | G9: =9462418-9459450 -> 2968 | H9: =10935120-10928374 -> 6746 | I9: =6122936-6120606 -> 2330 | J9: =14301152-14294249 -> 6903 | K9: =SUM(B9:H9) -> 32703 | L9: =K9*0.2 -> 6540.6 | M9: =45492.435-45302.173 -> 190.262 | N9: =5220.504-5216.87 -> 3.634 | O9: =10507.467-10507.296 -> 0.171 | P9: =19052.985-18981.99 -> 70.995 | Q9: =30711.817-30693.734 -> 18.083 | R9: =N9+O9+P9 -> 74.8 | S9: =(N9+O9+P9)*7.84 -> 586.432 | T9: =M9+Q9 -> 208.345 | U9: =T9*7.84 -> 1633.4248 | V9: =432950.5-432747.9 -> 202.6 | W9: =175732.27-175552.17 -> 180.1 | X9: 0001523.20 | Y9: 1118079 | Z9: =IF((Y9-Y8<0), "0",Y9-Y8) -> 659 | AA9: =Z9*6.47 -> 4263.73 | AB9: 15315011 | AC9: =AB8 -> 15280850 | AD9: =IF((AB9-AC9<0), "0",AB9-AC9) -> 34161 | AE9: =AD9*0.327899 -> 11201.358 | AF9: =103829-103772.8 -> 56.2 | AG9: =50692.5-50692.5 -> 0 | AH9: =32769.4-32751.6 -> 17.8 | AI9: =AJ8 -> 56368.5 | AJ9: 56398.5 | AK9: =IF((AJ9-AI9)<0, "0",AJ9-AI9) -> 30 | AL9: =AK9*(284.34513609) -> 8530.3541 | AM9: =AL9*0.327899 -> 2797.0946 | AO9: =L9+U9+AA9+AE9 -> 23639.113
A10: 44778 | B10: =14604852-14599458 -> 5394 | C10: =9366266-9362274 -> 3992 | D10: =1868154-1867262 -> 892 | E10: =14171706-14164837 -> 6869 | F10: =13837570-13831400 -> 6170 | G10: =9465515-9462418 -> 3097 | H10: =10941869-10935120 -> 6749 | I10: =6125195-6122936 -> 2259 | J10: =14308075-14301152 -> 6923 | K10: =SUM(B10:H10) -> 33163 | L10: =K10*0.2 -> 6632.6 | M10: =45678.287-45492.435 -> 185.852 | N10: =5222.869-5220.504 -> 2.365 | O10: =10507.512-10507.467 -> 0.045 | P10: =19122.12-19052.985 -> 69.135 | Q10: =30742.218-30711.817 -> 30.401 | R10: =N10+O10+P10 -> 71.545 | S10: =(N10+O10+P10)*7.84 -> 560.9128 | T10: =M10+Q10 -> 216.253 | U10: =T10*7.84 -> 1695.4235 | V10: =433156.3-432950.5 -> 205.8 | W10: =175902.8-175732.27 -> 170.53 | X10: 0001523.20 | Y10: 1118751 | Z10: =IF((Y10-Y9<0), "0",Y10-Y9) -> 672 | AA10: =Z10*6.47 -> 4347.84 | AB10: 15348580 | AC10: =AB9 -> 15315011 | AD10: =IF((AB10-AC10<0), "0",AB10-AC10) -> 33569 | AE10: =AD10*0.327899 -> 11007.242 | AF10: =103884.8-103829 -> 55.8 | AG10: =50692.5-50692.5 -> 0 | AH10: =32786.5-32769.4 -> 17.1 | AI10: =AJ9 -> 56398.5 | AJ10: 56427.9 | AK10: =IF((AJ10-AI10)<0, "0",AJ10-AI10) -> 29.4 | AL10: =AK10*(284.34513609) -> 8359.747 | AM10: =AL10*0.327899 -> 2741.1527 | AO10: =L10+U10+AA10+AE10 -> 23683.105
A11: 44779 | B11: =14610297-14604852 -> 5445 | C11: =9370400-9366266 -> 4134 | D11: =1869010-1868154 -> 856 | E11: =14178652-14171706 -> 6946 | F11: =13843860-13837570 -> 6290 | G11: =9468491-9465515 -> 2976 | H11: =10948504-10941869 -> 6635 | I11: =6127376-6125195 -> 2181 | J11: =14314999-14308075 -> 6924 | K11: =SUM(B11:H11) -> 33282 | L11: =K11*0.2 -> 6656.4 | M11: =45881.772-45678.287 -> 203.485 | N11: =5225.542-5222.869 -> 2.673 | O11: =10507.791-10507.512 -> 0.279 | P11: =19196.988-19122.12 -> 74.868 | Q11: =30750.45-30742.218 -> 8.232 | R11: =N11+O11+P11 -> 77.82 | S11: =(N11+O11+P11)*7.84 -> 610.1088 | T11: =M11+Q11 -> 211.717 | U11: =T11*7.84 -> 1659.8613 | V11: =433348.9-433156.3 -> 192.6 | W11: =176073.5-175902.8 -> 170.7 | X11: 0001523.20 | Y11: 1119432 | Z11: =IF((Y11-Y10<0), "0",Y11-Y10) -> 681 | AA11: =Z11*6.47 -> 4406.07 | AB11: 15380697 | AC11: =AB10 -> 15348580 | AD11: =IF((AB11-AC11<0), "0",AB11-AC11) -> 32117 | AE11: =AD11*0.327899 -> 10531.132 | AF11: =103937.7-103884.8 -> 52.9 | AG11: =50692.5-50692.5 -> 0 | AH11: =32803.6-32786.5 -> 17.1 | AI11: =AJ10 -> 56427.9 | AJ11: 56457 | AK11: =IF((AJ11-AI11)<0, "0",AJ11-AI11) -> 29.1 | AL11: =AK11*(284.34513609) -> 8274.4435 | AM11: =AL11*0.327899 -> 2713.1817 | AO11: =L11+U11+AA11+AE11 -> 23253.463
A12: 44780 | B12: =14615680-14610297 -> 5383 | C12: =9374200-9370400 -> 3800 | D12: =1869840-1869010 -> 830 | E12: =14185745-14178652 -> 7093 | F12: =13849815-13843860 -> 5955 | G12: =9471360-9468491 -> 2869 | H12: =10955093-10948504 -> 6589 | I12: =6129600-6127376 -> 2224 | J12: =14321769-14314999 -> 6770 | K12: =SUM(B12:H12) -> 32519 | L12: =K12*0.2 -> 6503.8 | M12: =46024.109-45881.772 -> 142.337 | N12: =5228.084-5225.542 -> 2.542 | O12: =10507.955-10507.791 -> 0.164 | P12: =19263.675-19196.988 -> 66.687 | Q12: =30778.791-30750.45 -> 28.341 | R12: =N12+O12+P12 -> 69.393 | S12: =(N12+O12+P12)*7.84 -> 544.04112 | T12: =M12+Q12 -> 170.678 | U12: =T12*7.84 -> 1338.1155 | V12: =433515-433348.9 -> 166.1 | W12: =176219.81-176073.5 -> 146.31 | X12: 0001523.20 | Y12: 1119971 | Z12: =IF((Y12-Y11<0), "0",Y12-Y11) -> 539 | AA12: =Z12*6.47 -> 3487.33 | AB12: 15410440 | AC12: =AB11 -> 15380697 | AD12: =IF((AB12-AC12<0), "0",AB12-AC12) -> 29743 | AE12: =AD12*0.327899 -> 9752.7 | AF12: =103986.8-103937.7 -> 49.1 | AG12: =50692.5-50692.5 -> 0 | AH12: =32820.3-32803.6 -> 16.7 | AI12: =AJ11 -> 56457 | AJ12: 56484.3 | AK12: =IF((AJ12-AI12)<0, "0",AJ12-AI12) -> 27.3 | AL12: =AK12*(284.34513609) -> 7762.6222 | AM12: =AL12*0.327899 -> 2545.3561 | AO12: =L12+U12+AA12+AE12 -> 21081.945
A13: 44781 | B13: =14620870-14615680 -> 5190 | C13: =9378230-9374200 -> 4030 | D13: =1870700-1869840 -> 860 | E13: =14192670-14185745 -> 6925 | F13: =13855664-13849815 -> 5849 | G13: =9474430-9471360 -> 3070 | H13: =10961633-10955093 -> 6540 | I13: =6131833-6129600 -> 2233 | J13: =14328340-14321769 -> 6571 | K13: =SUM(B13:H13) -> 32464 | L13: =K13*0.2 -> 6492.8 | M13: =46186.412-46024.109 -> 162.303 | N13: =5230.714-5228.084 -> 2.63 | O13: =10508.115-10507.955 -> 0.16 | P13: =19325.99-19263.675 -> 62.315 | Q13: =30799.442-30778.791 -> 20.651 | R13: =N13+O13+P13 -> 65.105 | S13: =(N13+O13+P13)*7.84 -> 510.4232 | T13: =M13+Q13 -> 182.954 | U13: =T13*7.84 -> 1434.3594 | V13: =433678.5-433515 -> 163.5 | W13: =176396.51-176219.81 -> 176.7 | X13: 0001523.20 | Y13: 1120582 | Z13: =IF((Y13-Y12<0), "0",Y13-Y12) -> 611 | AA13: =Z13*6.47 -> 3953.17 | AB13: 15444190 | AC13: =AB12 -> 15410440 | AD13: =IF((AB13-AC13<0), "0",AB13-AC13) -> 33750 | AE13: =AD13*0.327899 -> 11066.591 | AF13: =104043-103986.8 -> 56.2 | AG13: =50692.5-50692.5 -> 0 | AH13: =32838.5-32820.3 -> 18.2 | AI13: =AJ12 -> 56484.3 | AJ13: 56513.6 | AK13: =IF((AJ13-AI13)<0, "0",AJ13-AI13) -> 29.3 | AL13: =AK13*(284.34513609) -> 8331.3125 | AM13: =AL13*0.327899 -> 2731.829 | AO13: =L13+U13+AA13+AE13 -> 22946.921
A14: 44782 | B14: =14626182-14620870 -> 5312 | C14: =9382717-9378230 -> 4487 | D14: =1871575-1870700 -> 875 | E14: =14199617-14192670 -> 6947 | F14: =13861556-13855664 -> 5892 | G14: =9477484-9474430 -> 3054 | H14: =10968338-10961633 -> 6705 | I14: =6134048-6131833 -> 2215 | J14: =14334983-14328340 -> 6643 | K14: =SUM(B14:H14) -> 33272 | L14: =K14*0.2 -> 6654.4 | M14: =46356.535-46186.412 -> 170.123 | N14: =5233.32-5230.714 -> 2.606 | O14: =10508.323-10508.115 -> 0.208 | P14: =19380.359-19325.99 -> 54.369 | Q14: =30818.137-30799.442 -> 18.695 | R14: =N14+O14+P14 -> 57.183 | S14: =(N14+O14+P14)*7.84 -> 448.31472 | T14: =M14+Q14 -> 188.818 | U14: =T14*7.84 -> 1480.3331 | V14: =433861.2-433678.5 -> 182.7 | W14: =176573.71-176396.51 -> 177.2 | X14: 0001523.20 | Y14: 1121200 | Z14: =IF((Y14-Y13<0), "0",Y14-Y13) -> 618 | AA14: =Z14*6.47 -> 3998.46 | AB14: 15475498 | AC14: =AB13 -> 15444190 | AD14: =IF((AB14-AC14<0), "0",AB14-AC14) -> 31308 | AE14: =AD14*0.327899 -> 10265.862 | AF14: =104095.6-104043 -> 52.6 | AG14: =50692.5-50692.5 -> 0 | AH14: =32855.2-32838.5 -> 16.7 | AI14: =AJ13 -> 56513.6 | AJ14: 56540.9 | AK14: =IF((AJ14-AI14)<0, "0",AJ14-AI14) -> 27.3 | AL14: =AK14*(284.34513609) -> 7762.6222 | AM14: =AL14*0.327899 -> 2545.3561 | AO14: =L14+U14+AA14+AE14 -> 22399.055
A15: 44783 | B15: =14631547-14626182 -> 5365 | C15: =9387506-9382717 -> 4789 | D15: =1872410-1871575 -> 835 | E15: =14206557-14199617 -> 6940 | F15: =13867676-13861556 -> 6120 | G15: =9480558-9477484 -> 3074 | H15: =10975448-10968338 -> 7110 | I15: =6136264-6134048 -> 2216 | J15: =14341650-14334983 -> 6667 | K15: =SUM(B15:H15) -> 34233 | L15: =K15*0.2 -> 6846.6 | M15: =46516.155-46356.535 -> 159.62 | N15: =5235.389-5233.32 -> 2.069 | O15: =10508.427-10508.323 -> 0.104 | P15: =19449.082-19380.359 -> 68.723 | Q15: =30843.389-30818.137 -> 25.252 | R15: =N15+O15+P15 -> 70.896 | S15: =(N15+O15+P15)*7.84 -> 555.82464 | T15: =M15+Q15 -> 184.872 | U15: =T15*7.84 -> 1449.3965 | V15: =434033.6-433861.2 -> 172.4 | W15: =176756.07-176573.71 -> 182.36 | X15: 0001523.20 | Y15: 1121813 | Z15: =IF((Y15-Y14<0), "0",Y15-Y14) -> 613 | AA15: =Z15*6.47 -> 3966.11 | AB15: 15511536 | AC15: =AB14 -> 15475498 | AD15: =IF((AB15-AC15<0), "0",AB15-AC15) -> 36038 | AE15: =AD15*0.327899 -> 11816.824 | AF15: =104156.2-104095.6 -> 60.6 | AG15: =50692.5-50692.5 -> 0 | AH15: =32872.4-32855.2 -> 17.2 | AI15: =AJ14 -> 56540.9 | AJ15: 56571 | AK15: =IF((AJ15-AI15)<0, "0",AJ15-AI15) -> 30.1 | AL15: =AK15*(284.34513609) -> 8558.7886 | AM15: =AL15*0.327899 -> 2806.4182 | AO15: =L15+U15+AA15+AE15 -> 24078.931
A16: 44784 | B16: =14636908-14631547 -> 5361 | C16: =9392920-9387506 -> 5414 | D16: =1873258-1872410 -> 848 | E16: =14213780-14206557 -> 7223 | F16: =13873822-13867676 -> 6146 | G16: =9483600-9480558 -> 3042 | H16: =10982603-10975448 -> 7155 | I16: =6138530-6136264 -> 2266 | J16: =14348449-14341650 -> 6799 | K16: =SUM(B16:H16) -> 35189 | L16: =K16*0.2 -> 7037.8 | M16: =46688.519-46516.155 -> 172.364 | N16: =5238.383-5235.389 -> 2.994 | O16: =10508.459-10508.427 -> 0.032 | P16: =19523.484-19449.082 -> 74.402 | Q16: =30862.869-30843.389 -> 19.48 | R16: =N16+O16+P16 -> 77.428 | S16: =(N16+O16+P16)*7.84 -> 607.03552 | T16: =M16+Q16 -> 191.844 | U16: =T16*7.84 -> 1504.057 | V16: =434203.9-434033.6 -> 170.3 | W16: =176936.3-176756.07 -> 180.23 | X16: 0001523.20 | Y16: 1122440 | Z16: =IF((Y16-Y15<0), "0",Y16-Y15) -> 627 | AA16: =Z16*6.47 -> 4056.69 | AB16: 15548608 | AC16: =AB15 -> 15511536 | AD16: =IF((AB16-AC16<0), "0",AB16-AC16) -> 37072 | AE16: =AD16*0.327899 -> 12155.872 | AF16: =104219.3-104156.2 -> 63.1 | AG16: =50692.5-50692.5 -> 0 | AH16: =32890.1-32872.4 -> 17.7 | AI16: =AJ15 -> 56571 | AJ16: 56601.6 | AK16: =IF((AJ16-AI16)<0, "0",AJ16-AI16) -> 30.6 | AL16: =AK16*(284.34513609) -> 8700.9612 | AM16: =AL16*0.327899 -> 2853.0365 | AO16: =L16+U16+AA16+AE16 -> 24754.419
A17: 44785 | B17: =14642318-14636908 -> 5410 | C17: =9397902-9392920 -> 4982 | D17: =1874110-1873258 -> 852 | E17: =14220720-14213780 -> 6940 | F17: =13879907-13873822 -> 6085 | G17: =9486605-9483600 -> 3005 | H17: =10989743-10982603 -> 7140 | I17: =6140717-6138530 -> 2187 | J17: =14355233-14348449 -> 6784 | K17: =SUM(B17:H17) -> 34414 | L17: =K17*0.2 -> 6882.8 | M17: =46848.2-46688.519 -> 159.681 | N17: =5240.402-5238.383 -> 2.019 | O17: =10508.502-10508.459 -> 0.043 | P17: =19593.482-19523.484 -> 69.998 | Q17: =30884.194-30862.869 -> 21.325 | R17: =N17+O17+P17 -> 72.06 | S17: =(N17+O17+P17)*7.84 -> 564.9504 | T17: =M17+Q17 -> 181.006 | U17: =T17*7.84 -> 1419.087 | V17: =434385.4-434203.9 -> 181.5 | W17: =177119.32-176936.3 -> 183.02 | X17: 0001523.20 | Y17: 1123078 | Z17: =IF((Y17-Y16<0), "0",Y17-Y16) -> 638 | AA17: =Z17*6.47 -> 4127.86 | AB17: 15586900 | AC17: =AB16 -> 15548608 | AD17: =IF((AB17-AC17<0), "0",AB17-AC17) -> 38292 | AE17: =AD17*0.327899 -> 12555.909 | AF17: =104286-104219.3 -> 66.7 | AG17: =50692.5-50692.5 -> 0 | AH17: =32907-32890.1 -> 16.9 | AI17: =AJ16 -> 56601.6 | AJ17: 56631.9 | AK17: =IF((AJ17-AI17)<0, "0",AJ17-AI17) -> 30.3 | AL17: =AK17*(284.34513609) -> 8615.6576 | AM17: =AL17*0.327899 -> 2825.0655 | AO17: =L17+U17+AA17+AE17 -> 24985.656
A18: 44786 | B18: =14647849-14642318 -> 5531 | C18: =9402392-9397902 -> 4490 | D18: =1874967-1874110 -> 857 | E18: =14227740-14220720 -> 7020 | F18: =13885992-13879907 -> 6085 | G18: =9489554-9486605 -> 2949 | H18: =10996903-10989743 -> 7160 | I18: =6142955-6140717 -> 2238 | J18: =14362158-14355233 -> 6925 | K18: =SUM(B18:H18) -> 34092 | L18: =K18*0.2 -> 6818.4 | M18: =47027.525-46848.2 -> 179.325 | N18: =5246.456-5240.402 -> 6.054 | O18: =10508.9-10508.502 -> 0.398 | P18: =19666.066-19593.482 -> 72.584 | Q18: =30892.931-30884.194 -> 8.737 | R18: =N18+O18+P18 -> 79.036 | S18: =(N18+O18+P18)*7.84 -> 619.64224 | T18: =M18+Q18 -> 188.062 | U18: =T18*7.84 -> 1474.4061 | V18: =434563-434385.4 -> 177.6 | W18: =177300.5-177119.32 -> 181.18 | X18: 0001523.20 | Y18: 1123738 | Z18: =IF((Y18-Y17<0), "0",Y18-Y17) -> 660 | AA18: =Z18*6.47 -> 4270.2 | AB18: 15615783 | AC18: =AB17 -> 15586900 | AD18: =IF((AB18-AC18<0), "0",AB18-AC18) -> 28883 | AE18: =AD18*0.327899 -> 9470.7068 | AF18: =104342-104286 -> 56 | AG18: =50692.5-50692.5 -> 0 | AH18: =32925-32907 -> 18 | AI18: =AJ17 -> 56631.9 | AJ18: 56660 | AK18: =IF((AJ18-AI18)<0, "0",AJ18-AI18) -> 28.1 | AL18: =AK18*(284.34513609) -> 7990.0983 | AM18: =AL18*0.327899 -> 2619.9453 | AO18: =L18+U18+AA18+AE18 -> 22033.713
A19: 44787 | B19: =14653325-14647849 -> 5476 | C19: =9406539-9402392 -> 4147 | D19: =1875890-1874967 -> 923 | E19: =14234725-14227740 -> 6985 | F19: =13891986-13885992 -> 5994 | G19: =9492358-9489554 -> 2804 | H19: =11003829-10996903 -> 6926 | I19: =6145282-6142955 -> 2327 | J19: =14369001-14362158 -> 6843 | K19: =SUM(B19:H19) -> 33255 | L19: =K19*0.2 -> 6651 | M19: =47177.555-47027.525 -> 150.03 | N19: =5248.358-5246.456 -> 1.902 | O19: =10508.954-10508.9 -> 0.054 | P19: =19737.6-19666.066 -> 71.534 | Q19: =30924.531-30892.931 -> 31.6 | R19: =N19+O19+P19 -> 73.49 | S19: =(N19+O19+P19)*7.84 -> 576.1616 | T19: =M19+Q19 -> 181.63 | U19: =T19*7.84 -> 1423.9792 | V19: =434727.3-434563 -> 164.3 | W19: =177481.68-177300.5 -> 181.18 | X19: 0001523.20 | Y19: 1124362 | Z19: =IF((Y19-Y18<0), "0",Y19-Y18) -> 624 | AA19: =Z19*6.47 -> 4037.28 | AB19: 15651390 | AC19: =AB18 -> 15615783 | AD19: =IF((AB19-AC19<0), "0",AB19-AC19) -> 35607 | AE19: =AD19*0.327899 -> 11675.5 | AF19: =104396-104342 -> 54 | AG19: =50692.5-50692.5 -> 0 | AH19: =32942-32925 -> 17 | AI19: =AJ18 -> 56660 | AJ19: 56688 | AK19: =IF((AJ19-AI19)<0, "0",AJ19-AI19) -> 28 | AL19: =AK19*(284.34513609) -> 7961.6638 | AM19: =AL19*0.327899 -> 2610.6216 | AO19: =L19+U19+AA19+AE19 -> 23787.759
A20: 44788 | B20: =14658904-14653325 -> 5579 | C20: =9410860-9406539 -> 4321 | D20: =1876638-1875890 -> 748 | E20: =14241778-14234725 -> 7053 | F20: =13898032-13891986 -> 6046 | G20: =9495166-9492358 -> 2808 | H20: =11010446-11003829 -> 6617 | I20: =6147653-6145282 -> 2371 | J20: =14375665-14369001 -> 6664 | K20: =SUM(B20:H20) -> 33172 | L20: =K20*0.2 -> 6634.4 | M20: =47332.786-47177.555 -> 155.231 | N20: =5250.924-5248.358 -> 2.566 | O20: =10509.104-10508.954 -> 0.15 | P20: =19798.369-19737.6 -> 60.769 | Q20: =30925.761-30924.531 -> 1.23 | R20: =N20+O20+P20 -> 63.485 | S20: =(N20+O20+P20)*7.84 -> 497.7224 | T20: =M20+Q20 -> 156.461 | U20: =T20*7.84 -> 1226.6542 | V20: =434882.2-434727.3 -> 154.9 | W20: =177656.19-177481.68 -> 174.51 | X20: 0001523.20 | Y20: 1124960 | Z20: =IF((Y20-Y19<0), "0",Y20-Y19) -> 598 | AA20: =Z20*6.47 -> 3869.06 | AB20: 15681933 | AC20: =AB19 -> 15651390 | AD20: =IF((AB20-AC20<0), "0",AB20-AC20) -> 30543 | AE20: =AD20*0.327899 -> 10015.019 | AF20: =104451.1-104396 -> 55.1 | AG20: =50692.5-50692.5 -> 0 | AH20: =32969.4-32942 -> 27.4 | AI20: =AJ19 -> 56688 | AJ20: 56716.1 | AK20: =IF((AJ20-AI20)<0, "0",AJ20-AI20) -> 28.1 | AL20: =AK20*(284.34513609) -> 7990.0983 | AM20: =AL20*0.327899 -> 2619.9453 | AO20: =L20+U20+AA20+AE20 -> 21745.133
A21: 44789 | B21: =14664467-14658904 -> 5563 | C21: =9415006-9410860 -> 4146 | D21: =1877524-1876638 -> 886 | E21: =14248927-14241778 -> 7149 | F21: =13904085-13898032 -> 6053 | G21: =9497978-9495166 -> 2812 | H21: =11017011-11010446 -> 6565 | I21: =6149992-6147653 -> 2339 | J21: =14382392-14375665 -> 6727 | K21: =SUM(B21:H21) -> 33174 | L21: =K21*0.2 -> 6634.8 | M21: =47507.961-47332.786 -> 175.175 | N21: =5265.111-5250.924 -> 14.187 | O21: =10509.35-10509.104 -> 0.246 | P21: =19861.311-19798.369 -> 62.942 | Q21: =30958.355-30925.761 -> 32.594 | R21: =N21+O21+P21 -> 77.375 | S21: =(N21+O21+P21)*7.84 -> 606.62 | T21: =M21+Q21 -> 207.769 | U21: =T21*7.84 -> 1628.909 | V21: =435055.1-434882.2 -> 172.9 | W21: =177837.12-177656.19 -> 180.93 | X21: 0001523.20 | Y21: 1125605 | Z21: =IF((Y21-Y20<0), "0",Y21-Y20) -> 645 | AA21: =Z21*6.47 -> 4173.15 | AB21: 15713680 | AC21: =AB20 -> 15681933 | AD21: =IF((AB21-AC21<0), "0",AB21-AC21) -> 31747 | AE21: =AD21*0.327899 -> 10409.81 | AF21: =104511.4-104451.1 -> 60.3 | AG21: =50692.5-50692.5 -> 0 | AH21: =32976.4-32969.4 -> 7 | AI21: =AJ20 -> 56716.1 | AJ21: 56742.7 | AK21: =IF((AJ21-AI21)<0, "0",AJ21-AI21) -> 26.6 | AL21: =AK21*(284.34513609) -> 7563.5806 | AM21: =AL21*0.327899 -> 2480.0905 | AO21: =L21+U21+AA21+AE21 -> 22846.669
A22: 44790 | B22: =14669992-14664467 -> 5525 | C22: =9419314-9415006 -> 4308 | D22: =1878425-1877524 -> 901 | E22: =14256007-14248927 -> 7080 | F22: =13910186-13904085 -> 6101 | G22: =9500840-9497978 -> 2862 | H22: =11023560-11017011 -> 6549 | I22: =6152298-6149992 -> 2306 | J22: =14389171-14382392 -> 6779 | K22: =SUM(B22:H22) -> 33326 | L22: =K22*0.2 -> 6665.2 | M22: =47696.699-47507.961 -> 188.738 | N22: =5268.325-5265.111 -> 3.214 | O22: =10509.405-10509.35 -> 0.055 | P22: =19928.483-19861.311 -> 67.172 | Q22: =30976.85-30958.355 -> 18.495 | R22: =N22+O22+P22 -> 70.441 | S22: =(N22+O22+P22)*7.84 -> 552.25744 | T22: =M22+Q22 -> 207.233 | U22: =T22*7.84 -> 1624.7067 | V22: =435236.6-435055.1 -> 181.5 | W22: =178017.79-177837.12 -> 180.67 | X22: 0001523.20 | Y22: 1126268 | Z22: =IF((Y22-Y21<0), "0",Y22-Y21) -> 663 | AA22: =Z22*6.47 -> 4289.61 | AB22: 15746585 | AC22: =AB21 -> 15713680 | AD22: =IF((AB22-AC22<0), "0",AB22-AC22) -> 32905 | AE22: =AD22*0.327899 -> 10789.517 | AF22: =104573.6-104511.4 -> 62.2 | AG22: =50692.5-50692.5 -> 0 | AH22: =32993.3-32976.4 -> 16.9 | AI22: =AJ21 -> 56742.7 | AJ22: 56770.6 | AK22: =IF((AJ22-AI22)<0, "0",AJ22-AI22) -> 27.9 | AL22: =AK22*(284.34513609) -> 7933.2293 | AM22: =AL22*0.327899 -> 2601.298 | AO22: =L22+U22+AA22+AE22 -> 23369.033
A23: 44791 | B23: =14675512-14669992 -> 5520 | C23: =9423944-9419314 -> 4630 | D23: =1879344-1878425 -> 919 | E23: =14263136-14256007 -> 7129 | F23: =13916226-13910186 -> 6040 | G23: =9503730-9500840 -> 2890 | H23: =11030131-11023560 -> 6571 | I23: =6154638-6152298 -> 2340 | J23: =14396115-14389171 -> 6944 | K23: =SUM(B23:H23) -> 33699 | L23: =K23*0.2 -> 6739.8 | M23: =47872.396-47696.699 -> 175.697 | N23: =5271.591-5268.325 -> 3.266 | O23: =10509.473-10509.405 -> 0.068 | P23: =19991.336-19928.483 -> 62.853 | Q23: =30990.461-30976.85 -> 13.611 | R23: =N23+O23+P23 -> 66.187 | S23: =(N23+O23+P23)*7.84 -> 518.90608 | T23: =M23+Q23 -> 189.308 | U23: =T23*7.84 -> 1484.1747 | V23: =435421.7-435236.6 -> 185.1 | W23: =178132.16-178017.79 -> 114.37 | X23: 0001523.20 | Y23: 1126876 | Z23: =IF((Y23-Y22<0), "0",Y23-Y22) -> 608 | AA23: =Z23*6.47 -> 3933.76 | AB23: 15778276 | AC23: =AB22 -> 15746585 | AD23: =IF((AB23-AC23<0), "0",AB23-AC23) -> 31691 | AE23: =AD23*0.327899 -> 10391.447 | AF23: =104633.5-104573.6 -> 59.9 | AG23: =50692.5-50692.5 -> 0 | AH23: =33010-32993.3 -> 16.7 | AI23: =AJ22 -> 56770.6 | AJ23: 56797.6 | AK23: =IF((AJ23-AI23)<0, "0",AJ23-AI23) -> 27 | AL23: =AK23*(284.34513609) -> 7677.3187 | AM23: =AL23*0.327899 -> 2517.3851 | AO23: =L23+U23+AA23+AE23 -> 22549.182
A24: 44792 | B24: =14681035-14675512 -> 5523 | C24: =9427948-9423944 -> 4004 | D24: =1880223-1879344 -> 879 | E24: =14270305-14263136 -> 7169 | F24: =13922372-13916226 -> 6146 | G24: =9506678-9503730 -> 2948 | H24: =11036735-11030131 -> 6604 | I24: =6156915-6154638 -> 2277 | J24: =14402977-14396115 -> 6862 | K24: =SUM(B24:H24) -> 33273 | L24: =K24*0.2 -> 6654.6 | M24: =48039.816-47872.396 -> 167.42 | N24: =5274.681-5271.591 -> 3.09 | O24: =10509.522-10509.473 -> 0.049 | P24: =20066.58-19991.336 -> 75.244 | Q24: =31022.604-30990.461 -> 32.143 | R24: =N24+O24+P24 -> 78.383 | S24: =(N24+O24+P24)*7.84 -> 614.52272 | T24: =M24+Q24 -> 199.563 | U24: =T24*7.84 -> 1564.5739 | V24: =435597-435421.7 -> 175.3 | W24: =178306.31-178132.16 -> 174.15 | X24: 0001523.20 | Y24: 1127542 | Z24: =IF((Y24-Y23<0), "0",Y24-Y23) -> 666 | AA24: =Z24*6.47 -> 4309.02 | AB24: 15803446 | AC24: =AB23 -> 15778276 | AD24: =IF((AB24-AC24<0), "0",AB24-AC24) -> 25170 | AE24: =AD24*0.327899 -> 8253.2178 | AF24: =104691.3-104633.5 -> 57.8 | AG24: =50692.5-50692.5 -> 0 | AH24: =33026.7-33010 -> 16.7 | AI24: =AJ23 -> 56797.6 | AJ24: 56824.9 | AK24: =IF((AJ24-AI24)<0, "0",AJ24-AI24) -> 27.3 | AL24: =AK24*(284.34513609) -> 7762.6222 | AM24: =AL24*0.327899 -> 2545.3561 | AO24: =L24+U24+AA24+AE24 -> 20781.412
A25: 44793 | B25: =14686651-14681035 -> 5616 | C25: =9431871-9427948 -> 3923 | D25: =1881081-1880223 -> 858 | E25: =14277448-14270305 -> 7143 | F25: =13928647-13922372 -> 6275 | G25: =9509719-9506678 -> 3041 | H25: =11043255-11036735 -> 6520 | I25: =6159177-6156915 -> 2262 | J25: =14409840-14402977 -> 6863 | K25: =SUM(B25:H25) -> 33376 | L25: =K25*0.2 -> 6675.2 | M25: =48230.378-48039.816 -> 190.562 | N25: =5277.713-5274.681 -> 3.032 | O25: =10509.824-10509.522 -> 0.302 | P25: =20145.034-20066.58 -> 78.454 | Q25: =31031.367-31022.604 -> 8.763 | R25: =N25+O25+P25 -> 81.788 | S25: =(N25+O25+P25)*7.84 -> 641.21792 | T25: =M25+Q25 -> 199.325 | U25: =T25*7.84 -> 1562.708 | V25: =435790.1-435597 -> 193.1 | W25: =178491.44-178306.31 -> 185.13 | X25: 0001523.20 | Y25: 1128242 | Z25: =IF((Y25-Y24<0), "0",Y25-Y24) -> 700 | AA25: =Z25*6.47 -> 4529 | AB25: 15836240 | AC25: =AB24 -> 15803446 | AD25: =IF((AB25-AC25<0), "0",AB25-AC25) -> 32794 | AE25: =AD25*0.327899 -> 10753.12 | AF25: =104753.8-104691.3 -> 62.5 | AG25: =50692.5-50692.5 -> 0 | AH25: =33044.2-33026.7 -> 17.5 | AI25: =AJ24 -> 56824.9 | AJ25: 56852.5 | AK25: =IF((AJ25-AI25)<0, "0",AJ25-AI25) -> 27.6 | AL25: =AK25*(284.34513609) -> 7847.9258 | AM25: =AL25*0.327899 -> 2573.327 | AO25: =L25+U25+AA25+AE25 -> 23520.028
A26: 44794 | B26: =14692030-14686651 -> 5379 | C26: =9435545-9431871 -> 3674 | D26: =1881960-1881081 -> 879 | E26: =14284362-14277448 -> 6914 | F26: =13934566-13928647 -> 5919 | G26: =9512478-9509719 -> 2759 | H26: =11049660-11043255 -> 6405 | I26: =6161379-6159177 -> 2202 | J26: =14416549-14409840 -> 6709 | K26: =SUM(B26:H26) -> 31929 | L26: =K26*0.2 -> 6385.8 | M26: =48383.937-48230.378 -> 153.559 | N26: =5280.149-5277.713 -> 2.436 | O26: =10510.097-10509.824 -> 0.273 | P26: =20213.409-20145.034 -> 68.375 | Q26: =31062.034-31031.367 -> 30.667 | R26: =N26+O26+P26 -> 71.084 | S26: =(N26+O26+P26)*7.84 -> 557.29856 | T26: =M26+Q26 -> 184.226 | U26: =T26*7.84 -> 1444.3318 | V26: =435957.2-435790.1 -> 167.1 | W26: =178648.22-178491.44 -> 156.78 | X26: 0001523.20 | Y26: 1128857 | Z26: =IF((Y26-Y25<0), "0",Y26-Y25) -> 615 | AA26: =Z26*6.47 -> 3979.05 | AB26: 15864852 | AC26: =AB25 -> 15836240 | AD26: =IF((AB26-AC26<0), "0",AB26-AC26) -> 28612 | AE26: =AD26*0.327899 -> 9381.8462 | AF26: =104807.6-104753.8 -> 53.8 | AG26: =50692.5-50692.5 -> 0 | AH26: =33060.4-33044.2 -> 16.2 | AI26: =AJ25 -> 56852.5 | AJ26: 56878.5 | AK26: =IF((AJ26-AI26)<0, "0",AJ26-AI26) -> 26 | AL26: =AK26*(284.34513609) -> 7392.9735 | AM26: =AL26*0.327899 -> 2424.1486 | AO26: =L26+U26+AA26+AE26 -> 21191.028
A27: 44795 | B27: =14697608-14692030 -> 5578 | C27: =9439484-9435545 -> 3939 | D27: =1882810-1881960 -> 850 | E27: =14291016-14284362 -> 6654 | F27: =13940716-13934566 -> 6150 | G27: =9515280-9512478 -> 2802 | H27: =11056088-11049660 -> 6428 | I27: =6163669-6161379 -> 2290 | J27: =14423259-14416549 -> 6710 | K27: =SUM(B27:H27) -> 32401 | L27: =K27*0.2 -> 6480.2 | M27: =48541.793-48383.937 -> 157.856 | N27: =5282.84-5280.149 -> 2.691 | O27: =10510.302-10510.097 -> 0.205 | P27: =20276.767-20213.409 -> 63.358 | Q27: =31081.665-31062.034 -> 19.631 | R27: =N27+O27+P27 -> 66.254 | S27: =(N27+O27+P27)*7.84 -> 519.43136 | T27: =M27+Q27 -> 177.487 | U27: =T27*7.84 -> 1391.4981 | V27: =436152.6-435957.2 -> 195.4 | W27: =178715.57-178648.22 -> 67.35 | X27: 0001523.20 | Y27: 1129404 | Z27: =IF((Y27-Y26<0), "0",Y27-Y26) -> 547 | AA27: =Z27*6.47 -> 3539.09 | AB27: 15893184 | AC27: =AB26 -> 15864852 | AD27: =IF((AB27-AC27<0), "0",AB27-AC27) -> 28332 | AE27: =AD27*0.327899 -> 9290.0345 | AF27: =104860.3-104807.6 -> 52.7 | AG27: =50692.5-50692.5 -> 0 | AH27: =33077-33060.4 -> 16.6 | AI27: =AJ26 -> 56878.5 | AJ27: 56904.7 | AK27: =IF((AJ27-AI27)<0, "0",AJ27-AI27) -> 26.2 | AL27: =AK27*(284.34513609) -> 7449.8426 | AM27: =AL27*0.327899 -> 2442.7959 | AO27: =L27+U27+AA27+AE27 -> 20700.823
A28: 44796 | B28: =14703022-14697608 -> 5414 | C28: =9443504-9439484 -> 4020 | D28: =1883688-1882810 -> 878 | E28: =14297830-14291016 -> 6814 | F28: =13946803-13940716 -> 6087 | G28: =9518220-9515280 -> 2940 | H28: =11062447-11056088 -> 6359 | I28: =6165961-6163669 -> 2292 | J28: =14429951-14423259 -> 6692 | K28: =SUM(B28:H28) -> 32512 | L28: =K28*0.2 -> 6502.4 | M28: =48676.193-48541.793 -> 134.4 | N28: =5285.597-5282.84 -> 2.757 | O28: =10510.459-10510.302 -> 0.157 | P28: =20347.1-20276.767 -> 70.333 | Q28: =31107.304-31081.665 -> 25.639 | R28: =N28+O28+P28 -> 73.247 | S28: =(N28+O28+P28)*7.84 -> 574.25648 | T28: =M28+Q28 -> 160.039 | U28: =T28*7.84 -> 1254.7058 | V28: =436344.3-436152.6 -> 191.7 | W28: =178887.84-178715.57 -> 172.27 | X28: 0001523.20 | Y28: 1130069 | Z28: =IF((Y28-Y27<0), "0",Y28-Y27) -> 665 | AA28: =Z28*6.47 -> 4302.55 | AB28: 15925802 | AC28: =AB27 -> 15893184 | AD28: =IF((AB28-AC28<0), "0",AB28-AC28) -> 32618 | AE28: =AD28*0.327899 -> 10695.41 | AF28: =104923.8-104860.3 -> 63.5 | AG28: =50692.5-50692.5 -> 0 | AH28: =33093.9-33077 -> 16.9 | AI28: =AJ27 -> 56904.7 | AJ28: 56931.8 | AK28: =IF((AJ28-AI28)<0, "0",AJ28-AI28) -> 27.1 | AL28: =AK28*(284.34513609) -> 7705.7532 | AM28: =AL28*0.327899 -> 2526.7088 | AO28: =L28+U28+AA28+AE28 -> 22755.065
A29: 44797 | B29: =14708482-14703022 -> 5460 | C29: =9447671-9443504 -> 4167 | D29: =1884565-1883688 -> 877 | E29: =14304838-14297830 -> 7008 | F29: =13952940-13946803 -> 6137 | G29: =9521124-9518220 -> 2904 | H29: =11068902-11062447 -> 6455 | I29: =6168237-6165961 -> 2276 | J29: =14436721-14429951 -> 6770 | K29: =SUM(B29:H29) -> 33008 | L29: =K29*0.2 -> 6601.6 | M29: =48849.94-48676.193 -> 173.747 | N29: =5288.851-5285.599 -> 3.252 | O29: =10510.575-10510.459 -> 0.116 | P29: =20414.725-20347.1 -> 67.625 | Q29: =31120.293-31107.304 -> 12.989 | R29: =N29+O29+P29 -> 70.993 | S29: =(N29+O29+P29)*7.84 -> 556.58512 | T29: =M29+Q29 -> 186.736 | U29: =T29*7.84 -> 1464.0102 | V29: =436540.7-436344.3 -> 196.4 | W29: =179023.21-178887.84 -> 135.37 | X29: 0001523.20 | Y29: 1130675 | Z29: =IF((Y29-Y28<0), "0",Y29-Y28) -> 606 | AA29: =Z29*6.47 -> 3920.82 | AB29: 15957186 | AC29: =AB28 -> 15925802 | AD29: =IF((AB29-AC29<0), "0",AB29-AC29) -> 31384 | AE29: =AD29*0.327899 -> 10290.782 | AF29: =104983.6-104923.8 -> 59.8 | AG29: =50692.5-50692.5 -> 0 | AH29: =33110.9-33093.9 -> 17 | AI29: =AJ28 -> 56931.8 | AJ29: 56958.7 | AK29: =IF((AJ29-AI29)<0, "0",AJ29-AI29) -> 26.9 | AL29: =AK29*(284.34513609) -> 7648.8842 | AM29: =AL29*0.327899 -> 2508.0615 | AO29: =L29+U29+AA29+AE29 -> 22277.212
A30: 44798 | B30: =14714054-14708482 -> 5572 | C30: =9451736-9447671 -> 4065 | D30: =1885410-1884565 -> 845 | E30: =14311910-14304838 -> 7072 | F30: =13959115-13952940 -> 6175 | G30: =9524072-9521124 -> 2948 | H30: =11075348-11068902 -> 6446 | I30: =6170512-6168237 -> 2275 | J30: =14443463-14436721 -> 6742 | K30: =SUM(B30:H30) -> 33123 | L30: =K30*0.2 -> 6624.6 | M30: =48998.58-48849.94 -> 148.64 | N30: =5291.372-5288.851 -> 2.521 | O30: =10510.816-10510.575 -> 0.241 | P30: =20484.167-20414.725 -> 69.442 | Q30: =31141.812-31120.293 -> 21.519 | R30: =N30+O30+P30 -> 72.204 | S30: =(N30+O30+P30)*7.84 -> 566.07936 | T30: =M30+Q30 -> 170.159 | U30: =T30*7.84 -> 1334.0466 | V30: =436737.5-436540.7 -> 196.8 | W30: =179124.76-179023.21 -> 101.55 | X30: 0001523.20 | Y30: 1131294 | Z30: =IF((Y30-Y29<0), "0",Y30-Y29) -> 619 | AA30: =Z30*6.47 -> 4004.93 | AB30: 15987550 | AC30: =AB29 -> 15957186 | AD30: =IF((AB30-AC30<0), "0",AB30-AC30) -> 30364 | AE30: =AD30*0.327899 -> 9956.3252 | AF30: =105040-104983.6 -> 56.4 | AG30: =50692.5-50692.5 -> 0 | AH30: =33128-33110.9 -> 17.1 | AI30: =AJ29 -> 56958.7 | AJ30: 56985 | AK30: =IF((AJ30-AI30)<0, "0",AJ30-AI30) -> 26.3 | AL30: =AK30*(284.34513609) -> 7478.2771 | AM30: =AL30*0.327899 -> 2452.1196 | AO30: =L30+U30+AA30+AE30 -> 21919.902
A31: 44799 | B31: =14719567-14714054 -> 5513 | C31: =9455916-9451736 -> 4180 | D31: =1886292-1885410 -> 882 | E31: =14318892-14311910 -> 6982 | F31: =13965314-13959115 -> 6199 | G31: =9526878-9524072 -> 2806 | H31: =11081788-11075348 -> 6440 | I31: =6172775-6170512 -> 2263 | J31: =14450312-14443463 -> 6849 | K31: =SUM(B31:H31) -> 33002 | L31: =K31*0.2 -> 6600.4 | M31: =49156.668-48998.58 -> 158.088 | N31: =5294.135-5291.372 -> 2.763 | O31: =10510.866-10510.816 -> 0.05 | P31: =20546.996-20484.167 -> 62.829 | Q31: =31169.61-31141.812 -> 27.798 | R31: =N31+O31+P31 -> 65.642 | S31: =(N31+O31+P31)*7.84 -> 514.63328 | T31: =M31+Q31 -> 185.886 | U31: =T31*7.84 -> 1457.3462 | V31: =436925-436737.5 -> 187.5 | W31: =179263.31-179124.76 -> 138.55 | X31: 0001523.20 | Y31: 1131937 | Z31: =IF((Y31-Y30<0), "0",Y31-Y30) -> 643 | AA31: =Z31*6.47 -> 4160.21 | AB31: 16013732 | AC31: =AB30 -> 15987550 | AD31: =IF((AB31-AC31<0), "0",AB31-AC31) -> 26182 | AE31: =AD31*0.327899 -> 8585.0516 | AF31: =105088-105040 -> 48 | AG31: =50692.5-50692.5 -> 0 | AH31: =33144-33128 -> 16 | AI31: =AJ30 -> 56985 | AJ31: 57010 | AK31: =IF((AJ31-AI31)<0, "0",AJ31-AI31) -> 25 | AL31: =AK31*(284.34513609) -> 7108.6284 | AM31: =AL31*0.327899 -> 2330.9121 | AO31: =L31+U31+AA31+AE31 -> 20803.008
A32: 44800 | B32: =14725168-14719567 -> 5601 | C32: =9460019-9455916 -> 4103 | D32: =1887186-1886292 -> 894 | E32: =14325826-14318892 -> 6934 | F32: =13971586-13965314 -> 6272 | G32: =9529593-9526878 -> 2715 | H32: =11088067-11081788 -> 6279 | I32: =6175027-6172775 -> 2252 | J32: =14457161-14450312 -> 6849 | K32: =SUM(B32:H32) -> 32798 | L32: =K32*0.2 -> 6559.6 | M32: =49323.885-49156.668 -> 167.217 | N32: =5297.44-5294.135 -> 3.305 | O32: =10511.107-10510.866 -> 0.241 | P32: =20626.81-20546.996 -> 79.814 | Q32: =31179.67-31169.61 -> 10.06 | R32: =N32+O32+P32 -> 83.36 | S32: =(N32+O32+P32)*7.84 -> 653.5424 | T32: =M32+Q32 -> 177.277 | U32: =T32*7.84 -> 1389.8517 | V32: =437120-436925 -> 195 | W32: =179410.42-179263.31 -> 147.11 | X32: 0001523.20 | Y32: 1132601 | Z32: =IF((Y32-Y31<0), "0",Y32-Y31) -> 664 | AA32: =Z32*6.47 -> 4296.08 | AB32: 16040136 | AC32: =AB31 -> 16013732 | AD32: =IF((AB32-AC32<0), "0",AB32-AC32) -> 26404 | AE32: =AD32*0.327899 -> 8657.8452 | AF32: =105135-105088 -> 47 | AG32: =50692.5-50692.5 -> 0 | AH32: =33160-33144 -> 16 | AI32: =AJ31 -> 57010 | AJ32: 57036 | AK32: =IF((AJ32-AI32)<0, "0",AJ32-AI32) -> 26 | AL32: =AK32*(284.34513609) -> 7392.9735 | AM32: =AL32*0.327899 -> 2424.1486 | AO32: =L32+U32+AA32+AE32 -> 20903.377
A33: 44801 | B33: =14730770-14725168 -> 5602 | C33: =9463766-9460019 -> 3747 | D33: =1888062-1887186 -> 876 | E33: =14332722-14325826 -> 6896 | F33: =13977550-13971586 -> 5964 | G33: =9532235-9529593 -> 2642 | H33: =11094334-11088067 -> 6267 | I33: =6177375-6175027 -> 2348 | J33: =14463861-14457161 -> 6700 | K33: =SUM(B33:H33) -> 31994 | L33: =K33*0.2 -> 6398.8 | M33: =49470.834-49323.885 -> 146.949 | N33: =5299.194-5297.44 -> 1.754 | O33: =10511.237-10511.107 -> 0.13 | P33: =20699.937-20626.81 -> 73.127 | Q33: =31206.391-31179.67 -> 26.721 | R33: =N33+O33+P33 -> 75.011 | S33: =(N33+O33+P33)*7.84 -> 588.08624 | T33: =M33+Q33 -> 173.67 | U33: =T33*7.84 -> 1361.5728 | V33: =437301.4-437120 -> 181.4 | W33: =179582.42-179410.42 -> 172 | X33: 0001523.20 | Y33: 1133250 | Z33: =IF((Y33-Y32<0), "0",Y33-Y32) -> 649 | AA33: =Z33*6.47 -> 4199.03 | AB33: 16066833 | AC33: =AB32 -> 16040136 | AD33: =IF((AB33-AC33<0), "0",AB33-AC33) -> 26697 | AE33: =AD33*0.327899 -> 8753.9196 | AF33: =105183-105135 -> 48 | AG33: =50692.5-50692.5 -> 0 | AH33: =33176-33160 -> 16 | AI33: =AJ32 -> 57036 | AJ33: 57062 | AK33: =IF((AJ33-AI33)<0, "0",AJ33-AI33) -> 26 | AL33: =AK33*(284.34513609) -> 7392.9735 | AM33: =AL33*0.327899 -> 2424.1486 | AO33: =L33+U33+AA33+AE33 -> 20713.322
A34: 44802 | B34: =14736392-14730770 -> 5622 | C34: =9468033-9463766 -> 4267 | D34: =1888935-1888062 -> 873 | E34: =14339390-14332722 -> 6668 | F34: =13983524-13977550 -> 5974 | G34: =9534901-9532235 -> 2666 | H34: =11100689-11094334 -> 6355 | I34: =6179794-6177375 -> 2419 | J34: =14470379-14463861 -> 6518 | K34: =SUM(B34:H34) -> 32425 | L34: =K34*0.2 -> 6485 | M34: =49617.171-49470.834 -> 146.337 | N34: =5301.973-5299.194 -> 2.779 | O34: =10511.435-10511.237 -> 0.198 | P34: =20763.97-20699.937 -> 64.033 | Q34: =31216.303-31206.391 -> 9.912 | R34: =N34+O34+P34 -> 67.01 | S34: =(N34+O34+P34)*7.84 -> 525.3584 | T34: =M34+Q34 -> 156.249 | U34: =T34*7.84 -> 1224.9922 | V34: =437497.5-437301.4 -> 196.1 | W34: =179745.12-179582.42 -> 162.7 | X34: 0001523.20 | Y34: 1133890 | Z34: =IF((Y34-Y33<0), "0",Y34-Y33) -> 640 | AA34: =Z34*6.47 -> 4140.8 | AB34: 16095498 | AC34: =AB33 -> 16066833 | AD34: =IF((AB34-AC34<0), "0",AB34-AC34) -> 28665 | AE34: =AD34*0.327899 -> 9399.2248 | AF34: =105235.3-105183 -> 52.3 | AG34: =50692.5-50692.5 -> 0 | AH34: =33193.2-33176 -> 17.2 | AI34: =AJ33 -> 57062 | AJ34: 57089.9 | AK34: =IF((AJ34-AI34)<0, "0",AJ34-AI34) -> 27.9 | AL34: =AK34*(284.34513609) -> 7933.2293 | AM34: =AL34*0.327899 -> 2601.298 | AO34: =L34+U34+AA34+AE34 -> 21250.017
A35: 44803 | B35: =14741997-14736392 -> 5605 | C35: =9471772-9468033 -> 3739 | D35: =1889880-1888935 -> 945 | E35: =14346264-14339390 -> 6874 | F35: =13989616-13983524 -> 6092 | G35: =9537511-9534901 -> 2610 | H35: =11107021-11100689 -> 6332 | I35: =6182316-6179794 -> 2522 | J35: =14476836-14470379 -> 6457 | K35: =SUM(B35:H35) -> 32197 | L35: =K35*0.2 -> 6439.4 | M35: =49787.067-49617.171 -> 169.896 | N35: =5304.496-5301.973 -> 2.523 | O35: =10511.577-10511.435 -> 0.142 | P35: =20810.115-20763.97 -> 46.145 | Q35: =31242.184-31216.303 -> 25.881 | R35: =N35+O35+P35 -> 48.81 | S35: =(N35+O35+P35)*7.84 -> 382.6704 | T35: =M35+Q35 -> 195.777 | U35: =T35*7.84 -> 1534.8917 | V35: =437696.3-437497.5 -> 198.8 | W35: =179922.64-179745.12 -> 177.52 | X35: 0001523.20 | Y35: 1134547 | Z35: =IF((Y35-Y34<0), "0",Y35-Y34) -> 657 | AA35: =Z35*6.47 -> 4250.79 | AB35: 16122641 | AC35: =AB34 -> 16095498 | AD35: =IF((AB35-AC35<0), "0",AB35-AC35) -> 27143 | AE35: =AD35*0.327899 -> 8900.1626 | AF35: =105284.4-105235.3 -> 49.1 | AG35: =50692.5-50692.5 -> 0 | AH35: =33209.4-33193.2 -> 16.2 | AI35: =AJ34 -> 57089.9 | AJ35: 57116.3 | AK35: =IF((AJ35-AI35)<0, "0",AJ35-AI35) -> 26.4 | AL35: =AK35*(284.34513609) -> 7506.7116 | AM35: =AL35*0.327899 -> 2461.4432 | AO35: =L35+U35+AA35+AE35 -> 21125.244
