Workbook

Sheet TOTAL
A1: Site Name | B1: Day | C1: Month | D1: Year | E1: Total Electricity Kwh | F1: Electricity Tariff ($/Kwh) | G1: Natual Gas (m3) | H1: Natural Gas $/m3 | I1: Water Utility Supply (m3) m3 | J1: Water Utility Supply (m3) $/m3 | K1: Room Nights
A2: Cairo at Nile Plaza | B2: 1 | C2: 8 | D2: 2022 | E2: =(((Submetering!O2+Submetering!P2)*0.842284+Submetering!Q2+(Submetering!M2+Submetering!N2+Submetering!Y2)*0.7362)+(Submetering!O2+Submetering!P2+Submetering!Q2)*0.1488+(Submetering!M2+Submetering!N2+Submetering!Y2)*0.1167+(Submetering!K2+Submetering!L2-Submetering!Z2-Submetering!AA2-Submetering!AB2-Submetering!AC2-Submetering!Q2)+(Submetering!M2+Submetering!N2+Submetering!Y2)*0.1139) -> 84560.416 | F2: 1.27 | G2: =Gas!C3*0.9147 -> 1906.2348 | H2: 3.65 | I2: =Submetering!H2+Submetering!AD2+Submetering!AE2 -> 1036 | J2: 10.03 | K2: =ELECT.!B3 -> 0
A3: Cairo at Nile Plaza | B3: =B2+1 -> 2 | C3: 8 | D3: 2022 | E3: =(((Submetering!O3+Submetering!P3)*0.842284+Submetering!Q3+(Submetering!M3+Submetering!N3+Submetering!Y3)*0.7362)+(Submetering!O3+Submetering!P3+Submetering!Q3)*0.1488+(Submetering!M3+Submetering!N3+Submetering!Y3)*0.1167+(Submetering!K3+Submetering!L3-Submetering!Z3-Submetering!AA3-Submetering!AB3-Submetering!AC3-Submetering!Q3)+(Submetering!M3+Submetering!N3+Submetering!Y3)*0.1139) -> 64846.019 | F3: 1.27 | G3: =Gas!C4*0.9147 -> 1973.0079 | H3: 3.65 | I3: =Submetering!H3+Submetering!AD3+Submetering!AE3 -> 796 | J3: 10.03 | K3: =ELECT.!B4 -> 195
A4: Cairo at Nile Plaza | B4: =B3+1 -> 3 | C4: 8 | D4: 2022 | E4: =(((Submetering!O4+Submetering!P4)*0.842284+Submetering!Q4+(Submetering!M4+Submetering!N4+Submetering!Y4)*0.7362)+(Submetering!O4+Submetering!P4+Submetering!Q4)*0.1488+(Submetering!M4+Submetering!N4+Submetering!Y4)*0.1167+(Submetering!K4+Submetering!L4-Submetering!Z4-Submetering!AA4-Submetering!AB4-Submetering!AC4-Submetering!Q4)+(Submetering!M4+Submetering!N4+Submetering!Y4)*0.1139) -> 78015.971 | F4: 1.27 | G4: =Gas!C5*0.9147 -> 1877.8791 | H4: 3.65 | I4: =Submetering!H4+Submetering!AD4+Submetering!AE4 -> 1016 | J4: 10.03 | K4: =ELECT.!B5 -> 180
A5: Cairo at Nile Plaza | B5: =B4+1 -> 4 | C5: 8 | D5: 2022 | E5: =(((Submetering!O5+Submetering!P5)*0.842284+Submetering!Q5+(Submetering!M5+Submetering!N5+Submetering!Y5)*0.7362)+(Submetering!O5+Submetering!P5+Submetering!Q5)*0.1488+(Submetering!M5+Submetering!N5+Submetering!Y5)*0.1167+(Submetering!K5+Submetering!L5-Submetering!Z5-Submetering!AA5-Submetering!AB5-Submetering!AC5-Submetering!Q5)+(Submetering!M5+Submetering!N5+Submetering!Y5)*0.1139) -> 91948.48 | F5: 1.27 | G5: =Gas!C6*0.9147 -> 2274.8589 | H5: 3.65 | I5: =Submetering!H5+Submetering!AD5+Submetering!AE5 -> 1686 | J5: 10.03 | K5: =ELECT.!B6 -> 201
A6: Cairo at Nile Plaza | B6: =B5+1 -> 5 | C6: 8 | D6: 2022 | E6: =(((Submetering!O6+Submetering!P6)*0.842284+Submetering!Q6+(Submetering!M6+Submetering!N6+Submetering!Y6)*0.7362)+(Submetering!O6+Submetering!P6+Submetering!Q6)*0.1488+(Submetering!M6+Submetering!N6+Submetering!Y6)*0.1167+(Submetering!K6+Submetering!L6-Submetering!Z6-Submetering!AA6-Submetering!AB6-Submetering!AC6-Submetering!Q6)+(Submetering!M6+Submetering!N6+Submetering!Y6)*0.1139) -> 81554.591 | F6: 1.27 | G6: =Gas!C7*0.9147 -> 1224.7833 | H6: 3.65 | I6: =Submetering!H6+Submetering!AD6+Submetering!AE6 -> 626 | J6: 10.03 | K6: =ELECT.!B7 -> 198
A7: Cairo at Nile Plaza | B7: =B6+1 -> 6 | C7: 8 | D7: 2022 | E7: =(((Submetering!O7+Submetering!P7)*0.842284+Submetering!Q7+(Submetering!M7+Submetering!N7+Submetering!Y7)*0.7362)+(Submetering!O7+Submetering!P7+Submetering!Q7)*0.1488+(Submetering!M7+Submetering!N7+Submetering!Y7)*0.1167+(Submetering!K7+Submetering!L7-Submetering!Z7-Submetering!AA7-Submetering!AB7-Submetering!AC7-Submetering!Q7)+(Submetering!M7+Submetering!N7+Submetering!Y7)*0.1139) -> 57165.184 | F7: 1.27 | G7: =Gas!C8*0.9147 -> 1317.168 | H7: 3.65 | I7: =Submetering!H7+Submetering!AD7+Submetering!AE7 -> -104 | J7: 10.03 | K7: =ELECT.!B8 -> 195
A8: Cairo at Nile Plaza | B8: =B7+1 -> 7 | C8: 8 | D8: 2022 | E8: =(((Submetering!O8+Submetering!P8)*0.842284+Submetering!Q8+(Submetering!M8+Submetering!N8+Submetering!Y8)*0.7362)+(Submetering!O8+Submetering!P8+Submetering!Q8)*0.1488+(Submetering!M8+Submetering!N8+Submetering!Y8)*0.1167+(Submetering!K8+Submetering!L8-Submetering!Z8-Submetering!AA8-Submetering!AB8-Submetering!AC8-Submetering!Q8)+(Submetering!M8+Submetering!N8+Submetering!Y8)*0.1139) -> 83503.326 | F8: 1.27 | G8: =Gas!C9*0.9147 -> 1249.4802 | H8: 3.65 | I8: =Submetering!H8+Submetering!AD8+Submetering!AE8 -> 636 | J8: 10.03 | K8: =ELECT.!B9 -> 185
A9: Cairo at Nile Plaza | B9: =B8+1 -> 8 | C9: 8 | D9: 2022 | E9: =(((Submetering!O9+Submetering!P9)*0.842284+Submetering!Q9+(Submetering!M9+Submetering!N9+Submetering!Y9)*0.7362)+(Submetering!O9+Submetering!P9+Submetering!Q9)*0.1488+(Submetering!M9+Submetering!N9+Submetering!Y9)*0.1167+(Submetering!K9+Submetering!L9-Submetering!Z9-Submetering!AA9-Submetering!AB9-Submetering!AC9-Submetering!Q9)+(Submetering!M9+Submetering!N9+Submetering!Y9)*0.1139) -> 86978.515 | F9: 1.27 | G9: =Gas!C10*0.9147 -> 1887.0261 | H9: 3.65 | I9: =Submetering!H9+Submetering!AD9+Submetering!AE9 -> 836 | J9: 10.03 | K9: =ELECT.!B10 -> 245
A10: Cairo at Nile Plaza | B10: =B9+1 -> 9 | C10: 8 | D10: 2022 | E10: =(((Submetering!O10+Submetering!P10)*0.842284+Submetering!Q10+(Submetering!M10+Submetering!N10+Submetering!Y10)*0.7362)+(Submetering!O10+Submetering!P10+Submetering!Q10)*0.1488+(Submetering!M10+Submetering!N10+Submetering!Y10)*0.1167+(Submetering!K10+Submetering!L10-Submetering!Z10-Submetering!AA10-Submetering!AB10-Submetering!AC10-Submetering!Q10)+(Submetering!M10+Submetering!N10+Submetering!Y10)*0.1139) -> 68027.62 | F10: 1.27 | G10: =Gas!C11*0.9147 -> 1801.0443 | H10: 3.65 | I10: =Submetering!H10+Submetering!AD10+Submetering!AE10 -> 806 | J10: 10.03 | K10: =ELECT.!B11 -> 203
A11: Cairo at Nile Plaza | B11: =B10+1 -> 10 | C11: 8 | D11: 2022 | E11: =(((Submetering!O11+Submetering!P11)*0.842284+Submetering!Q11+(Submetering!M11+Submetering!N11+Submetering!Y11)*0.7362)+(Submetering!O11+Submetering!P11+Submetering!Q11)*0.1488+(Submetering!M11+Submetering!N11+Submetering!Y11)*0.1167+(Submetering!K11+Submetering!L11-Submetering!Z11-Submetering!AA11-Submetering!AB11-Submetering!AC11-Submetering!Q11)+(Submetering!M11+Submetering!N11+Submetering!Y11)*0.1139) -> 66002.122 | F11: 1.27 | G11: =Gas!C12*0.9147 -> 1670.2422 | H11: 3.65 | I11: =Submetering!H11+Submetering!AD11+Submetering!AE11 -> 786 | J11: 10.03 | K11: =ELECT.!B12 -> 234
A12: Cairo at Nile Plaza | B12: =B11+1 -> 11 | C12: 8 | D12: 2022 | E12: =(((Submetering!O12+Submetering!P12)*0.842284+Submetering!Q12+(Submetering!M12+Submetering!N12+Submetering!Y12)*0.7362)+(Submetering!O12+Submetering!P12+Submetering!Q12)*0.1488+(Submetering!M12+Submetering!N12+Submetering!Y12)*0.1167+(Submetering!K12+Submetering!L12-Submetering!Z12-Submetering!AA12-Submetering!AB12-Submetering!AC12-Submetering!Q12)+(Submetering!M12+Submetering!N12+Submetering!Y12)*0.1139) -> 104692.76 | F12: 1.27 | G12: =Gas!C13*0.9147 -> 1706.8302 | H12: 3.65 | I12: =Submetering!H12+Submetering!AD12+Submetering!AE12 -> 1006 | J12: 10.03 | K12: =ELECT.!B13 -> 222
A13: Cairo at Nile Plaza | B13: =B12+1 -> 12 | C13: 8 | D13: 2022 | E13: =(((Submetering!O13+Submetering!P13)*0.842284+Submetering!Q13+(Submetering!M13+Submetering!N13+Submetering!Y13)*0.7362)+(Submetering!O13+Submetering!P13+Submetering!Q13)*0.1488+(Submetering!M13+Submetering!N13+Submetering!Y13)*0.1167+(Submetering!K13+Submetering!L13-Submetering!Z13-Submetering!AA13-Submetering!AB13-Submetering!AC13-Submetering!Q13)+(Submetering!M13+Submetering!N13+Submetering!Y13)*0.1139) -> 66811.583 | F13: 1.27 | G13: =Gas!C14*0.9147 -> 1511.0844 | H13: 3.65 | I13: =Submetering!H13+Submetering!AD13+Submetering!AE13 -> 906 | J13: 10.03 | K13: =ELECT.!B14 -> 245
A14: Cairo at Nile Plaza | B14: =B13+1 -> 13 | C14: 8 | D14: 2022 | E14: =(((Submetering!O14+Submetering!P14)*0.842284+Submetering!Q14+(Submetering!M14+Submetering!N14+Submetering!Y14)*0.7362)+(Submetering!O14+Submetering!P14+Submetering!Q14)*0.1488+(Submetering!M14+Submetering!N14+Submetering!Y14)*0.1167+(Submetering!K14+Submetering!L14-Submetering!Z14-Submetering!AA14-Submetering!AB14-Submetering!AC14-Submetering!Q14)+(Submetering!M14+Submetering!N14+Submetering!Y14)*0.1139) -> 75219.952 | F14: 1.27 | G14: =Gas!C15*0.9147 -> 2232.7827 | H14: 3.65 | I14: =Submetering!H14+Submetering!AD14+Submetering!AE14 -> 866 | J14: 10.03 | K14: =ELECT.!B15 -> 218
... A17: Cairo at Nile Plaza | B17: =B16+1 -> 16 | C17: 8 | D17: 2022 | E17: =(((Submetering!O17+Submetering!P17)*0.842284+Submetering!Q17+(Submetering!M17+Submetering!N17+Submetering!Y17)*0.7362)+(Submetering!O17+Submetering!P17+Submetering!Q17)*0.1488+(Submetering!M17+Submetering!N17+Submetering!Y17)*0.1167+(Submetering!K17+Submetering!L17-Submetering!Z17-Submetering!AA17-Submetering!AB17-Submetering!AC17-Submetering!Q17)+(Submetering!M17+Submetering!N17+Submetering!Y17)*0.1139) -> 62741.829 | F17: 1.27 | G17: =Gas!C18*0.9147 -> 1648.2894 | H17: 3.65 | I17: =Submetering!H17+Submetering!AD17+Submetering!AE17 -> 906 | J17: 10.03 | K17: =ELECT.!B18 -> 107
A18: Cairo at Nile Plaza | B18: =B17+1 -> 17 | C18: 8 | D18: 2022 | E18: =(((Submetering!O18+Submetering!P18)*0.842284+Submetering!Q18+(Submetering!M18+Submetering!N18+Submetering!Y18)*0.7362)+(Submetering!O18+Submetering!P18+Submetering!Q18)*0.1488+(Submetering!M18+Submetering!N18+Submetering!Y18)*0.1167+(Submetering!K18+Submetering!L18-Submetering!Z18-Submetering!AA18-Submetering!AB18-Submetering!AC18-Submetering!Q18)+(Submetering!M18+Submetering!N18+Submetering!Y18)*0.1139) -> 88313.335 | F18: 1.27 | G18: =Gas!C19*0.9147 -> 1632.7395 | H18: 3.65 | I18: =Submetering!H18+Submetering!AD18+Submetering!AE18 -> 996 | J18: 10.03 | K18: 231
A19: Cairo at Nile Plaza | B19: =B18+1 -> 18 | C19: 8 | D19: 2022 | E19: =(((Submetering!O19+Submetering!P19)*0.842284+Submetering!Q19+(Submetering!M19+Submetering!N19+Submetering!Y19)*0.7362)+(Submetering!O19+Submetering!P19+Submetering!Q19)*0.1488+(Submetering!M19+Submetering!N19+Submetering!Y19)*0.1167+(Submetering!K19+Submetering!L19-Submetering!Z19-Submetering!AA19-Submetering!AB19-Submetering!AC19-Submetering!Q19)+(Submetering!M19+Submetering!N19+Submetering!Y19)*0.1139) -> 63465.578 | F19: 1.27 | G19: =Gas!C20*0.9147 -> 1684.8774 | H19: 3.65 | I19: =Submetering!H19+Submetering!AD19+Submetering!AE19 -> 896 | J19: 10.03 | K19: =ELECT.!B20 -> 155
A20: Cairo at Nile Plaza | B20: =B19+1 -> 19 | C20: 8 | D20: 2022 | E20: =(((Submetering!O20+Submetering!P20)*0.842284+Submetering!Q20+(Submetering!M20+Submetering!N20+Submetering!Y20)*0.7362)+(Submetering!O20+Submetering!P20+Submetering!Q20)*0.1488+(Submetering!M20+Submetering!N20+Submetering!Y20)*0.1167+(Submetering!K20+Submetering!L20-Submetering!Z20-Submetering!AA20-Submetering!AB20-Submetering!AC20-Submetering!Q20)+(Submetering!M20+Submetering!N20+Submetering!Y20)*0.1139) -> 82897.442 | F20: 1.27 | G20: =Gas!C21*0.9147 -> 1448.8848 | H20: 3.65 | I20: =Submetering!H20+Submetering!AD20+Submetering!AE20 -> 976 | J20: 10.03 | K20: =ELECT.!B21 -> 160
A21: Cairo at Nile Plaza | B21: =B20+1 -> 20 | C21: 8 | D21: 2022 | E21: =(((Submetering!O21+Submetering!P21)*0.842284+Submetering!Q21+(Submetering!M21+Submetering!N21+Submetering!Y21)*0.7362)+(Submetering!O21+Submetering!P21+Submetering!Q21)*0.1488+(Submetering!M21+Submetering!N21+Submetering!Y21)*0.1167+(Submetering!K21+Submetering!L21-Submetering!Z21-Submetering!AA21-Submetering!AB21-Submetering!AC21-Submetering!Q21)+(Submetering!M21+Submetering!N21+Submetering!Y21)*0.1139) -> 73111.027 | F21: 1.27 | G21: =Gas!C22*0.9147 -> 2018.7429 | H21: 3.65 | I21: =Submetering!H21+Submetering!AD21+Submetering!AE21 -> 1086 | J21: 10.03 | K21: =ELECT.!B22 -> 152
A22: Cairo at Nile Plaza | B22: =B21+1 -> 21 | C22: 8 | D22: 2022 | E22: =(((Submetering!O22+Submetering!P22)*0.842284+Submetering!Q22+(Submetering!M22+Submetering!N22+Submetering!Y22)*0.7362)+(Submetering!O22+Submetering!P22+Submetering!Q22)*0.1488+(Submetering!M22+Submetering!N22+Submetering!Y22)*0.1167+(Submetering!K22+Submetering!L22-Submetering!Z22-Submetering!AA22-Submetering!AB22-Submetering!AC22-Submetering!Q22)+(Submetering!M22+Submetering!N22+Submetering!Y22)*0.1139) -> 88830.94 | F22: 1.27 | G22: =Gas!C23*0.9147 -> 1798.3002 | H22: 3.65 | I22: =Submetering!H22+Submetering!AD22+Submetering!AE22 -> 1016 | J22: 10.03 | K22: =ELECT.!B23 -> 226
A23: Cairo at Nile Plaza | B23: =B22+1 -> 22 | C23: 8 | D23: 2022 | E23: =(((Submetering!O23+Submetering!P23)*0.842284+Submetering!Q23+(Submetering!M23+Submetering!N23+Submetering!Y23)*0.7362)+(Submetering!O23+Submetering!P23+Submetering!Q23)*0.1488+(Submetering!M23+Submetering!N23+Submetering!Y23)*0.1167+(Submetering!K23+Submetering!L23-Submetering!Z23-Submetering!AA23-Submetering!AB23-Submetering!AC23-Submetering!Q23)+(Submetering!M23+Submetering!N23+Submetering!Y23)*0.1139) -> 73378.36 | F23: 1.27 | G23: =Gas!C24*0.9147 -> 2784.3468 | H23: 3.65 | I23: =Submetering!H23+Submetering!AD23+Submetering!AE23 -> 826 | J23: 10.03 | K23: =ELECT.!B24 -> 225
A24: Cairo at Nile Plaza | B24: =B23+1 -> 23 | C24: 8 | D24: 2022 | E24: =(((Submetering!O24+Submetering!P24)*0.842284+Submetering!Q24+(Submetering!M24+Submetering!N24+Submetering!Y24)*0.7362)+(Submetering!O24+Submetering!P24+Submetering!Q24)*0.1488+(Submetering!M24+Submetering!N24+Submetering!Y24)*0.1167+(Submetering!K24+Submetering!L24-Submetering!Z24-Submetering!AA24-Submetering!AB24-Submetering!AC24-Submetering!Q24)+(Submetering!M24+Submetering!N24+Submetering!Y24)*0.1139) -> 62335.986 | F24: 1.27 | G24: =Gas!C25*0.9147 -> 1434.2496 | H24: 3.65 | I24: =Submetering!H24+Submetering!AD24+Submetering!AE24 -> 1106 | J24: 10.03 | K24: =ELECT.!B25 -> 175
A25: Cairo at Nile Plaza | B25: =B24+1 -> 24 | C25: 8 | D25: 2022 | E25: =(((Submetering!O25+Submetering!P25)*0.842284+Submetering!Q25+(Submetering!M25+Submetering!N25+Submetering!Y25)*0.7362)+(Submetering!O25+Submetering!P25+Submetering!Q25)*0.1488+(Submetering!M25+Submetering!N25+Submetering!Y25)*0.1167+(Submetering!K25+Submetering!L25-Submetering!Z25-Submetering!AA25-Submetering!AB25-Submetering!AC25-Submetering!Q25)+(Submetering!M25+Submetering!N25+Submetering!Y25)*0.1139) -> 82134.847 | F25: 1.27 | G25: =Gas!C26*0.9147 -> 1477.2405 | H25: 3.65 | I25: =Submetering!H25+Submetering!AD25+Submetering!AE25 -> 816 | J25: 10.03 | K25: =ELECT.!B26 -> 177
A26: Cairo at Nile Plaza | B26: =B25+1 -> 25 | C26: 8 | D26: 2022 | E26: =(((Submetering!O26+Submetering!P26)*0.842284+Submetering!Q26+(Submetering!M26+Submetering!N26+Submetering!Y26)*0.7362)+(Submetering!O26+Submetering!P26+Submetering!Q26)*0.1488+(Submetering!M26+Submetering!N26+Submetering!Y26)*0.1167+(Submetering!K26+Submetering!L26-Submetering!Z26-Submetering!AA26-Submetering!AB26-Submetering!AC26-Submetering!Q26)+(Submetering!M26+Submetering!N26+Submetering!Y26)*0.1139) -> 75821.706 | F26: 1.27 | G26: =Gas!C27*0.9147 -> 2541.0366 | H26: 3.65 | I26: =Submetering!H26+Submetering!AD26+Submetering!AE26 -> 866 | J26: 10.03 | K26: =ELECT.!B27 -> 180
A27: Cairo at Nile Plaza | B27: =B26+1 -> 26 | C27: 8 | D27: 2022 | E27: =(((Submetering!O27+Submetering!P27)*0.842284+Submetering!Q27+(Submetering!M27+Submetering!N27+Submetering!Y27)*0.7362)+(Submetering!O27+Submetering!P27+Submetering!Q27)*0.1488+(Submetering!M27+Submetering!N27+Submetering!Y27)*0.1167+(Submetering!K27+Submetering!L27-Submetering!Z27-Submetering!AA27-Submetering!AB27-Submetering!AC27-Submetering!Q27)+(Submetering!M27+Submetering!N27+Submetering!Y27)*0.1139) -> 88873.032 | F27: 1.27 | G27: =Gas!C28*0.9147 -> 1826.6559 | H27: 3.65 | I27: =Submetering!H27+Submetering!AD27+Submetering!AE27 -> 746 | J27: 10.03 | K27: =ELECT.!B28 -> 188
A28: Cairo at Nile Plaza | B28: =B27+1 -> 27 | C28: 8 | D28: 2022 | E28: =(((Submetering!O28+Submetering!P28)*0.842284+Submetering!Q28+(Submetering!M28+Submetering!N28+Submetering!Y28)*0.7362)+(Submetering!O28+Submetering!P28+Submetering!Q28)*0.1488+(Submetering!M28+Submetering!N28+Submetering!Y28)*0.1167+(Submetering!K28+Submetering!L28-Submetering!Z28-Submetering!AA28-Submetering!AB28-Submetering!AC28-Submetering!Q28)+(Submetering!M28+Submetering!N28+Submetering!Y28)*0.1139) -> 66711.951 | F28: 1.27 | G28: =Gas!C29*0.9147 -> 1727.8683 | H28: 3.65 | I28: =Submetering!H28+Submetering!AD28+Submetering!AE28 -> 866 | J28: 10.03 | K28: =ELECT.!B29 -> 154
A29: Cairo at Nile Plaza | B29: =B28+1 -> 28 | C29: 8 | D29: 2022 | E29: =(((Submetering!O29+Submetering!P29)*0.842284+Submetering!Q29+(Submetering!M29+Submetering!N29+Submetering!Y29)*0.7362)+(Submetering!O29+Submetering!P29+Submetering!Q29)*0.1488+(Submetering!M29+Submetering!N29+Submetering!Y29)*0.1167+(Submetering!K29+Submetering!L29-Submetering!Z29-Submetering!AA29-Submetering!AB29-Submetering!AC29-Submetering!Q29)+(Submetering!M29+Submetering!N29+Submetering!Y29)*0.1139) -> 81168.071 | F29: 1.27 | G29: =Gas!C30*0.9147 -> 648.5223 | H29: 3.65 | I29: =Submetering!H29+Submetering!AD29+Submetering!AE29 -> 806 | J29: 10.03 | K29: =ELECT.!B30 -> 212
A30: Cairo at Nile Plaza | B30: =B29+1 -> 29 | C30: 8 | D30: 2022 | E30: =(((Submetering!O30+Submetering!P30)*0.842284+Submetering!Q30+(Submetering!M30+Submetering!N30+Submetering!Y30)*0.7362)+(Submetering!O30+Submetering!P30+Submetering!Q30)*0.1488+(Submetering!M30+Submetering!N30+Submetering!Y30)*0.1167+(Submetering!K30+Submetering!L30-Submetering!Z30-Submetering!AA30-Submetering!AB30-Submetering!AC30-Submetering!Q30)+(Submetering!M30+Submetering!N30+Submetering!Y30)*0.1139) -> 87558.192 | F30: 1.27 | G30: =Gas!C31*0.9147 -> 1765.371 | H30: 3.65 | I30: =Submetering!H30+Submetering!AD30+Submetering!AE30 -> 786 | J30: 10.03 | K30: =ELECT.!B31 -> 197
... A32: Cairo at Nile Plaza | B32: =B31+1 -> 31 | C32: 8 | D32: 2022 | E32: =(((Submetering!O32+Submetering!P32)*0.842284+Submetering!Q32+(Submetering!M32+Submetering!N32+Submetering!Y32)*0.7362)+(Submetering!O32+Submetering!P32+Submetering!Q32)*0.1488+(Submetering!M32+Submetering!N32+Submetering!Y32)*0.1167+(Submetering!K32+Submetering!L32-Submetering!Z32-Submetering!AA32-Submetering!AB32-Submetering!AC32-Submetering!Q32)+(Submetering!M32+Submetering!N32+Submetering!Y32)*0.1139) -> 92503.112 | F32: 1.27 | G32: =Gas!C33*0.9147 -> 1603.4691 | H32: 3.65 | I32: =Submetering!H32+Submetering!AD32+Submetering!AE32 -> 906 | J32: 10.03 | K32: =ELECT.!B33 -> 230

Sheet Submetering
A1: Site Name | B1: Day | C1: Month | D1: Year | E1: Main (m3) | F1: Podium (m3) | G1: Hotel (m3) | H1: Large (m3) | I1: Feeder 1 (KWh) | J1: Feeder 2 (KWh) | K1: T1 (KWh) | L1: T2 (KWh) | M1: T3 (KWh) | N1: T4 (KWh) | O1: T5 (KWh) | P1: T7 (KWh) | Q1: New Chiller (KWh) | R1: Hotel (BTU) | S1: B.S (BTU) | T1: LS (BTU) | U1: Mall (BTU) | V1: AHU#25 (BTU) | W1: AHU#9 (BTU) | X1: Room Nights | Y1: Loss (KWH) | Z1: Mall (KWH) | AA1: Citadel (KWH) | AB1: Rotana (KWH) | AC1: CIB (KWH) | AD1: Plaza suits water consumption (M3) | AE1: Hotel water consumption (M3)
A2: Cairo at Nile Plaza | B2: 1 | C2: 8 | D2: 2022 | E2: =Water!C3 -> 1230 | F2: =Water!E3 -> 480 | G2: =Water!G3 -> 639.9 | H2: =Water!I3 -> 3.456 | I2: =ELECT.!F3 -> 27470 | J2: =ELECT.!H3 -> 59901 | K2: =ELECT.!K3 -> 13974 | L2: =ELECT.!M3 -> 7313 | M2: =ELECT.!O3 -> 20004 | N2: =ELECT.!Q3 -> 15489 | O2: =ELECT.!S3 -> 11486 | P2: =ELECT.!W3*2 -> 25516 | Q2: =ELECT.!D3 -> 960 | R2: =BTU!C3 -> 15.762 | S2: =BTU!F3 -> 3.746 | T2: =BTU!I3 -> 8 | U2: =BTU!O3 -> 1.944 | V2: =BTU!L3 -> 2.78 | W2: =BTU!R3 -> 0 | X2: =ELECT.!B3 -> 0 | Y2: =I2+J2-(K2+L2+M2+N2+O2+P2) -> -6411 | Z2: ='Mall, Citadel, Rotana'!C3+'Mall, Citadel, Rotana'!E3+'Mall, Citadel, Rotana'!G3+'Mall, Citadel, Rotana'!I3 -> 1017 | AA2: ='Mall, Citadel, Rotana'!K3+'Mall, Citadel, Rotana'!M3 -> 414 | AB2: ='Mall, Citadel, Rotana'!O3 -> 3 | AC2: ='Mall, Citadel, Rotana'!Q3+'Mall, Citadel, Rotana'!S3 -> 224 | AD2: =(E2-H2-194)*0.1318 -> 136.0893 | AE2: =E2-H2-AD2-194 -> 896.4547
A3: Cairo at Nile Plaza | B3: =B2+1 -> 2 | C3: 8 | D3: 2022 | E3: =Water!C4 -> 990 | F3: =Water!E4 -> 320 | G3: =Water!G4 -> 588.6 | H3: =Water!I4 -> 3.132 | I3: =ELECT.!F4 -> 20689 | J3: =ELECT.!H4 -> 47057 | K3: =ELECT.!K4 -> 9950 | L3: =ELECT.!M4 -> 5657 | M3: =ELECT.!O4 -> 14832 | N3: =ELECT.!Q4 -> 11860 | O3: =ELECT.!S4 -> 8818 | P3: =ELECT.!W4*2 -> 20370 | Q3: =ELECT.!D4 -> 640 | R3: =BTU!C4 -> 13.223 | S3: =BTU!F4 -> 2.708 | T3: =BTU!I4 -> 7 | U3: =BTU!O4 -> 1.966 | V3: =BTU!L4 -> 2.2 | W3: =BTU!R4 -> 1.83 | X3: =ELECT.!B4 -> 195 | Y3: =I3+J3-(K3+L3+M3+N3+O3+P3) -> -3741 | Z3: ='Mall, Citadel, Rotana'!C4+'Mall, Citadel, Rotana'!E4+'Mall, Citadel, Rotana'!G4+'Mall, Citadel, Rotana'!I4 -> 1412 | AA3: ='Mall, Citadel, Rotana'!K4+'Mall, Citadel, Rotana'!M4 -> 422 | AB3: ='Mall, Citadel, Rotana'!O4 -> 4 | AC3: ='Mall, Citadel, Rotana'!Q4+'Mall, Citadel, Rotana'!S4 -> 135 | AD3: =(E3-H3-194)*0.1318 -> 104.5 | AE3: =E3-H3-AD3-194 -> 688.368
A4: Cairo at Nile Plaza | B4: =B3+1 -> 3 | C4: 8 | D4: 2022 | E4: =Water!C5 -> 1210 | F4: =Water!E5 -> 440 | G4: =Water!G5 -> 669.6 | H4: =Water!I5 -> 3.861 | I4: =ELECT.!F5 -> 24437 | J4: =ELECT.!H5 -> 56297 | K4: =ELECT.!K5 -> 11578 | L4: =ELECT.!M5 -> 6850 | M4: =ELECT.!O5 -> 17382 | N4: =ELECT.!Q5 -> 13976 | O4: =ELECT.!S5 -> 10651 | P4: =ELECT.!W5*2 -> 24652 | Q4: =ELECT.!D5 -> 640 | R4: =BTU!C5 -> 14.973 | S4: =BTU!F5 -> 3.925 | T4: =BTU!I5 -> 9 | U4: =BTU!O5 -> 2.042 | V4: =BTU!L5 -> 2.67 | W4: =BTU!R5 -> 1.2 | X4: =ELECT.!B5 -> 180 | Y4: =I4+J4-(K4+L4+M4+N4+O4+P4) -> -4355 | Z4: ='Mall, Citadel, Rotana'!C5+'Mall, Citadel, Rotana'!E5+'Mall, Citadel, Rotana'!G5+'Mall, Citadel, Rotana'!I5 -> 1250 | AA4: ='Mall, Citadel, Rotana'!K5+'Mall, Citadel, Rotana'!M5 -> 349 | AB4: ='Mall, Citadel, Rotana'!O5 -> 3 | AC4: ='Mall, Citadel, Rotana'!Q5+'Mall, Citadel, Rotana'!S5 -> 0 | AD4: =(E4-H4-194)*0.1318 -> 133.39992 | AE4: =E4-H4-AD4-194 -> 878.73908
A5: Cairo at Nile Plaza | B5: =B4+1 -> 4 | C5: 8 | D5: 2022 | E5: =Water!C6 -> 1880 | F5: =Water!E6 -> 450 | G5: =Water!G6 -> 580.5 | H5: =Water!I6 -> 3.618 | I5: =ELECT.!F6 -> 29027 | J5: =ELECT.!H6 -> 66155 | K5: =ELECT.!K6 -> 13402 | L5: =ELECT.!M6 -> 8076 | M5: =ELECT.!O6 -> 20722 | N5: =ELECT.!Q6 -> 16273 | O5: =ELECT.!S6 -> 12875 | P5: =ELECT.!W6*2 -> 28890 | Q5: =ELECT.!D6 -> 640 | R5: =BTU!C6 -> 15.926 | S5: =BTU!F6 -> 4.111 | T5: =BTU!I6 -> 10 | U5: =BTU!O6 -> 1.991 | V5: =BTU!L6 -> 2.63 | W5: =BTU!R6 -> 3.74 | X5: =ELECT.!B6 -> 201 | Y5: =I5+J5-(K5+L5+M5+N5+O5+P5) -> -5056 | Z5: ='Mall, Citadel, Rotana'!C6+'Mall, Citadel, Rotana'!E6+'Mall, Citadel, Rotana'!G6+'Mall, Citadel, Rotana'!I6 -> 1549 | AA5: ='Mall, Citadel, Rotana'!K6+'Mall, Citadel, Rotana'!M6 -> 344 | AB5: ='Mall, Citadel, Rotana'!O6 -> 3 | AC5: ='Mall, Citadel, Rotana'!Q6+'Mall, Citadel, Rotana'!S6 -> 0 | AD5: =(E5-H5-194)*0.1318 -> 221.73795 | AE5: =E5-H5-AD5-194 -> 1460.6441
A6: Cairo at Nile Plaza | B6: =B5+1 -> 5 | C6: 8 | D6: 2022 | E6: =Water!C7 -> 820 | F6: =Water!E7 -> 360 | G6: =Water!G7 -> 469.8 | H6: =Water!I7 -> 2.754 | I6: =ELECT.!F7 -> 25690 | J6: =ELECT.!H7 -> 59175 | K6: =ELECT.!K7 -> 10828 | L6: =ELECT.!M7 -> 6766 | M6: =ELECT.!O7 -> 12478 | N6: =ELECT.!Q7 -> 14631 | O6: =ELECT.!S7 -> 11797 | P6: =ELECT.!W7*2 -> 26078 | Q6: =ELECT.!D7 -> 640 | R6: =BTU!C7 -> 15.108 | S6: =BTU!F7 -> 1.921 | T6: =BTU!I7 -> 7 | U6: =BTU!O7 -> 2.015 | V6: =BTU!L7 -> 3.19 | W6: =BTU!R7 -> 2.21 | X6: =ELECT.!B7 -> 198 | Y6: =I6+J6-(K6+L6+M6+N6+O6+P6) -> 2287 | Z6: ='Mall, Citadel, Rotana'!C7+'Mall, Citadel, Rotana'!E7+'Mall, Citadel, Rotana'!G7+'Mall, Citadel, Rotana'!I7 -> 1091 | AA6: ='Mall, Citadel, Rotana'!K7+'Mall, Citadel, Rotana'!M7 -> 226 | AB6: ='Mall, Citadel, Rotana'!O7 -> 3 | AC6: ='Mall, Citadel, Rotana'!Q7+'Mall, Citadel, Rotana'!S7 -> 772 | AD6: =(E6-H6-194)*0.1318 -> 82.143823 | AE6: =E6-H6-AD6-194 -> 541.10218
A7: Cairo at Nile Plaza | B7: =B6+1 -> 6 | C7: 8 | D7: 2022 | E7: =Water!C8 -> 90 | F7: =Water!E8 -> 410 | G7: =Water!G8 -> 567 | H7: =Water!I8 -> 3.078 | I7: =ELECT.!F8 -> 18172 | J7: =ELECT.!H8 -> 41433 | K7: =ELECT.!K8 -> 7782 | L7: =ELECT.!M8 -> 4903 | M7: =ELECT.!O8 -> 19312 | N7: =ELECT.!Q8 -> 10346 | O7: =ELECT.!S8 -> 7981 | P7: =ELECT.!W8*2 -> 18328 | Q7: =ELECT.!D8 -> 800 | R7: =BTU!C8 -> 12.821 | S7: =BTU!F8 -> 2.228 | T7: =BTU!I8 -> 8 | U7: =BTU!O8 -> 1.951 | V7: =BTU!L8 -> 2.78 | W7: =BTU!R8 -> 2.37 | X7: =ELECT.!B8 -> 195 | Y7: =I7+J7-(K7+L7+M7+N7+O7+P7) -> -9047 | Z7: ='Mall, Citadel, Rotana'!C8+'Mall, Citadel, Rotana'!E8+'Mall, Citadel, Rotana'!G8+'Mall, Citadel, Rotana'!I8 -> 1234 | AA7: ='Mall, Citadel, Rotana'!K8+'Mall, Citadel, Rotana'!M8 -> 267 | AB7: ='Mall, Citadel, Rotana'!O8 -> 3 | AC7: ='Mall, Citadel, Rotana'!Q8+'Mall, Citadel, Rotana'!S8 -> 136 | AD7: =(E7-H7-194)*0.1318 -> -14.11288 | AE7: =E7-H7-AD7-194 -> -92.96512
A8: Cairo at Nile Plaza | B8: =B7+1 -> 7 | C8: 8 | D8: 2022 | E8: =Water!C9 -> 830 | F8: =Water!E9 -> 440 | G8: =Water!G9 -> 604.8 | H8: =Water!I9 -> 3.78 | I8: =ELECT.!F9 -> 26520 | J8: =ELECT.!H9 -> 60112 | K8: =ELECT.!K9 -> 11822 | L8: =ELECT.!M9 -> 7208 | M8: =ELECT.!O9 -> 19084 | N8: =ELECT.!Q9 -> 15008 | O8: =ELECT.!S9 -> 11496 | P8: =ELECT.!W9*2 -> 26450 | Q8: =ELECT.!D9 -> 640 | R8: =BTU!C9 -> 18.333 | S8: =BTU!F9 -> 3.715 | T8: =BTU!I9 -> 10 | U8: =BTU!O9 -> 2.701 | V8: =BTU!L9 -> 3.73 | W8: =BTU!R9 -> 2.28 | X8: =ELECT.!B9 -> 185 | Y8: =I8+J8-(K8+L8+M8+N8+O8+P8) -> -4436 | Z8: ='Mall, Citadel, Rotana'!C9+'Mall, Citadel, Rotana'!E9+'Mall, Citadel, Rotana'!G9+'Mall, Citadel, Rotana'!I9 -> 1379 | AA8: ='Mall, Citadel, Rotana'!K9+'Mall, Citadel, Rotana'!M9 -> 402 | AB8: ='Mall, Citadel, Rotana'!O9 -> 4 | AC8: ='Mall, Citadel, Rotana'!Q9+'Mall, Citadel, Rotana'!S9 -> 116 | AD8: =(E8-H8-194)*0.1318 -> 83.326596 | AE8: =E8-H8-AD8-194 -> 548.8934
A9: Cairo at Nile Plaza | B9: =B8+1 -> 8 | C9: 8 | D9: 2022 | E9: =Water!C10 -> 1030 | F9: =Water!E10 -> 410 | G9: =Water!G10 -> 531.9 | H9: =Water!I10 -> 3.186 | I9: =ELECT.!F10 -> 27207 | J9: =ELECT.!H10 -> 62879 | K9: =ELECT.!K10 -> 12734 | L9: =ELECT.!M10 -> 7330 | M9: =ELECT.!O10 -> 19670 | N9: =ELECT.!Q10 -> 15531 | O9: =ELECT.!S10 -> 12065 | P9: =ELECT.!W10*2 -> 27558 | Q9: =ELECT.!D10 -> 800 | R9: =BTU!C10 -> 12.494 | S9: =BTU!F10 -> 2.116 | T9: =BTU!I10 -> 7 | U9: =BTU!O10 -> 1.589 | V9: =BTU!L10 -> 1.48 | W9: =BTU!R10 -> 0.54 | X9: =ELECT.!B10 -> 245 | Y9: =I9+J9-(K9+L9+M9+N9+O9+P9) -> -4802 | Z9: ='Mall, Citadel, Rotana'!C10+'Mall, Citadel, Rotana'!E10+'Mall, Citadel, Rotana'!G10+'Mall, Citadel, Rotana'!I10 -> 1387 | AA9: ='Mall, Citadel, Rotana'!K10+'Mall, Citadel, Rotana'!M10 -> 353 | AB9: ='Mall, Citadel, Rotana'!O10 -> 3 | AC9: ='Mall, Citadel, Rotana'!Q10+'Mall, Citadel, Rotana'!S10 -> 121 | AD9: =(E9-H9-194)*0.1318 -> 109.76489 | AE9: =E9-H9-AD9-194 -> 723.04911
A10: Cairo at Nile Plaza | B10: =B9+1 -> 9 | C10: 8 | D10: 2022 | E10: =Water!C11 -> 1000 | F10: =Water!E11 -> 450 | G10: =Water!G11 -> 591.3 | H10: =Water!I11 -> 3.483 | I10: =ELECT.!F11 -> 21948 | J10: =ELECT.!H11 -> 48774 | K10: =ELECT.!K11 -> 10282 | L10: =ELECT.!M11 -> 5872 | M10: =ELECT.!O11 -> 15870 | N10: =ELECT.!Q11 -> 12499 | O10: =ELECT.!S11 -> 9506 | P10: =ELECT.!W11*2 -> 20598 | Q10: =ELECT.!D11 -> 640 | R10: =BTU!C11 -> 10.02 | S10: =BTU!F11 -> 3.3 | T10: =BTU!I11 -> 7 | U10: =BTU!O11 -> 1.3 | V10: =BTU!L11 -> 1.9 | W10: =BTU!R11 -> 1 | X10: =ELECT.!B11 -> 203 | Y10: =I10+J10-(K10+L10+M10+N10+O10+P10) -> -3905 | Z10: ='Mall, Citadel, Rotana'!C11+'Mall, Citadel, Rotana'!E11+'Mall, Citadel, Rotana'!G11+'Mall, Citadel, Rotana'!I11 -> 1241 | AA10: ='Mall, Citadel, Rotana'!K11+'Mall, Citadel, Rotana'!M11 -> 350 | AB10: ='Mall, Citadel, Rotana'!O11 -> 3 | AC10: ='Mall, Citadel, Rotana'!Q11+'Mall, Citadel, Rotana'!S11 -> 115 | AD10: =(E10-H10-194)*0.1318 -> 105.77174 | AE10: =E10-H10-AD10-194 -> 696.74526
A11: Cairo at Nile Plaza | B11: =B10+1 -> 10 | C11: 8 | D11: 2022 | E11: =Water!C12 -> 980 | F11: =Water!E12 -> 410 | G11: =Water!G12 -> 569.7 | H11: =Water!I12 -> 3.672 | I11: =ELECT.!F12 -> 21596 | J11: =ELECT.!H12 -> 48029 | K11: =ELECT.!K12 -> 10088 | L11: =ELECT.!M12 -> 5571 | M11: =ELECT.!O12 -> 15848 | N11: =ELECT.!Q12 -> 12350 | O11: =ELECT.!S12 -> 9269 | P11: =ELECT.!W12*2 -> 20370 | Q11: =ELECT.!D12 -> 800 | R11: =BTU!C12 -> 14.849 | S11: =BTU!F12 -> 3.767 | T11: =BTU!I12 -> 9 | U11: =BTU!O12 -> 1.66 | V11: =BTU!L12 -> 2.74 | W11: =BTU!R12 -> 1.05 | X11: =ELECT.!B12 -> 234 | Y11: =I11+J11-(K11+L11+M11+N11+O11+P11) -> -3871 | Z11: ='Mall, Citadel, Rotana'!C12+'Mall, Citadel, Rotana'!E12+'Mall, Citadel, Rotana'!G12+'Mall, Citadel, Rotana'!I12 -> 1837 | AA11: ='Mall, Citadel, Rotana'!K12+'Mall, Citadel, Rotana'!M12 -> 706 | AB11: ='Mall, Citadel, Rotana'!O12 -> 6 | AC11: ='Mall, Citadel, Rotana'!Q12+'Mall, Citadel, Rotana'!S12 -> 121 | AD11: =(E11-H11-194)*0.1318 -> 103.11083 | AE11: =E11-H11-AD11-194 -> 679.21717
A12: Cairo at Nile Plaza | B12: =B11+1 -> 11 | C12: 8 | D12: 2022 | E12: =Water!C13 -> 1200 | F12: =Water!E13 -> 480 | G12: =Water!G13 -> 602.1 | H12: =Water!I13 -> 3.456 | I12: =ELECT.!F13 -> 32407 | J12: =ELECT.!H13 -> 73860 | K12: =ELECT.!K13 -> 14956 | L12: =ELECT.!M13 -> 8187 | M12: =ELECT.!O13 -> 23962 | N12: =ELECT.!Q13 -> 18974 | O12: =ELECT.!S13 -> 14756 | P12: =ELECT.!W13*2 -> 31120 | Q12: =ELECT.!D13 -> 480 | R12: =BTU!C13 -> 15.455 | S12: =BTU!F13 -> 3.46 | T12: =BTU!I13 -> 8 | U12: =BTU!O13 -> 2.062 | V12: =BTU!L13 -> 2.55 | W12: =BTU!R13 -> 1.12 | X12: =ELECT.!B13 -> 222 | Y12: =I12+J12-(K12+L12+M12+N12+O12+P12) -> -5688 | Z12: ='Mall, Citadel, Rotana'!C13+'Mall, Citadel, Rotana'!E13+'Mall, Citadel, Rotana'!G13+'Mall, Citadel, Rotana'!I13 -> 0 | AA12: ='Mall, Citadel, Rotana'!K13+'Mall, Citadel, Rotana'!M13 -> 0 | AB12: ='Mall, Citadel, Rotana'!O13 -> 0 | AC12: ='Mall, Citadel, Rotana'!Q13+'Mall, Citadel, Rotana'!S13 -> 0 | AD12: =(E12-H12-194)*0.1318 -> 132.1353 | AE12: =E12-H12-AD12-194 -> 870.4087
A13: Cairo at Nile Plaza | B13: =B12+1 -> 12 | C13: 8 | D13: 2022 | E13: =Water!C14 -> 1100 | F13: =Water!E14 -> 430 | G13: =Water!G14 -> 569.7 | H13: =Water!I14 -> 3.456 | I13: =ELECT.!F14 -> 21145 | J13: =ELECT.!H14 -> 48912 | K13: =ELECT.!K14 -> 9378 | L13: =ELECT.!M14 -> 5450 | M13: =ELECT.!O14 -> 15486 | N13: =ELECT.!Q14 -> 12299 | O13: =ELECT.!S14 -> 9947 | P13: =ELECT.!W14*2 -> 21018 | Q13: =ELECT.!D14 -> 640 | R13: =BTU!C14 -> 14.021 | S13: =BTU!F14 -> 1.731 | T13: =BTU!I14 -> 7 | U13: =BTU!O14 -> 1.799 | V13: =BTU!L14 -> 2.58 | W13: =BTU!R14 -> 0.93 | X13: =ELECT.!B14 -> 245 | Y13: =I13+J13-(K13+L13+M13+N13+O13+P13) -> -3521 | Z13: ='Mall, Citadel, Rotana'!C14+'Mall, Citadel, Rotana'!E14+'Mall, Citadel, Rotana'!G14+'Mall, Citadel, Rotana'!I14 -> 2016 | AA13: ='Mall, Citadel, Rotana'!K14+'Mall, Citadel, Rotana'!M14 -> 239 | AB13: ='Mall, Citadel, Rotana'!O14 -> 4 | AC13: ='Mall, Citadel, Rotana'!Q14+'Mall, Citadel, Rotana'!S14 -> 0 | AD13: =(E13-H13-194)*0.1318 -> 118.9553 | AE13: =E13-H13-AD13-194 -> 783.5887
A14: Cairo at Nile Plaza | B14: =B13+1 -> 13 | C14: 8 | D14: 2022 | E14: =Water!C15 -> 1060 | F14: =Water!E15 -> 440 | G14: =Water!G15 -> 588.6 | H14: =Water!I15 -> 2.835 | I14: =ELECT.!F15 -> 23240 | J14: =ELECT.!H15 -> 54688 | K14: =ELECT.!K15 -> 10760 | L14: =ELECT.!M15 -> 5944 | M14: =ELECT.!O15 -> 17104 | N14: =ELECT.!Q15 -> 13562 | O14: =ELECT.!S15 -> 13214 | P14: =ELECT.!W15*2 -> 23368 | Q14: =ELECT.!D15 -> 640 | R14: =BTU!C15 -> 18.18 | S14: =BTU!F15 -> 2.426 | T14: =BTU!I15 -> 9 | U14: =BTU!O15 -> 3.08 | V14: =BTU!L15 -> 3.33 | W14: =BTU!R15 -> 1.18 | X14: =ELECT.!B15 -> 218 | Y14: =I14+J14-(K14+L14+M14+N14+O14+P14) -> -6024 | Z14: ='Mall, Citadel, Rotana'!C15+'Mall, Citadel, Rotana'!E15+'Mall, Citadel, Rotana'!G15+'Mall, Citadel, Rotana'!I15 -> 1398 | AA14: ='Mall, Citadel, Rotana'!K15+'Mall, Citadel, Rotana'!M15 -> 258 | AB14: ='Mall, Citadel, Rotana'!O15 -> 3 | AC14: ='Mall, Citadel, Rotana'!Q15+'Mall, Citadel, Rotana'!S15 -> 0 | AD14: =(E14-H14-194)*0.1318 -> 113.76515 | AE14: =E14-H14-AD14-194 -> 749.39985
... A32: Cairo at Nile Plaza | B32: =B31+1 -> 31 | C32: 8 | D32: 2022 | E32: =Water!C33 -> 1100 | F32: =Water!E33 -> 560 | G32: =Water!G33 -> 577.8 | H32: =Water!I33 -> 4.509 | I32: =ELECT.!F33 -> 28430 | J32: =ELECT.!H33 -> 67452 | K32: =ELECT.!K33 -> 13306 | L32: =ELECT.!M33 -> 7785 | M32: =ELECT.!O33 -> 20406 | N32: =ELECT.!Q33 -> 17051 | O32: =ELECT.!S33 -> 13271 | P32: =ELECT.!W33*2 -> 28606 | Q32: =ELECT.!D33 -> 640 | R32: =BTU!C33 -> 13.594 | S32: =BTU!F33 -> 2.926 | T32: =BTU!I33 -> 8 | U32: =BTU!O33 -> 1.9 | V32: =BTU!L33 -> 2.185 | W32: =BTU!R33 -> 1.7 | X32: =ELECT.!B33 -> 230 | Y32: =I32+J32-(K32+L32+M32+N32+O32+P32) -> -4543 | Z32: ='Mall, Citadel, Rotana'!C33+'Mall, Citadel, Rotana'!E33+'Mall, Citadel, Rotana'!G33+'Mall, Citadel, Rotana'!I33 -> 1423 | AA32: ='Mall, Citadel, Rotana'!K33+'Mall, Citadel, Rotana'!M33 -> 355 | AB32: ='Mall, Citadel, Rotana'!O33 -> 4 | AC32: ='Mall, Citadel, Rotana'!Q33+'Mall, Citadel, Rotana'!S33 -> 226 | AD32: =(E32-H32-194)*0.1318 -> 118.81651 | AE32: =E32-H32-AD32-194 -> 782.67449

Sheet Mall, Citadel, Rotana
A1: Day | B1: R1 | C1: Cons | D1: R2 | E1: Cons | F1: R3 | G1: Cons | H1: R4 | I1: Cons | J1: RO1 | K1: Cons | L1: RO2 | M1: Cons | N1: ROE | O1: Cons | P1: CIB. 1 | Q1: Cons | R1: CIB. E | S1: Cons | T1: Co | U1: Cons
A2: 44773 | B2: 47370 | D2: 40832 | F2: 21902 | H2: 257036 | J2: 325715 | L2: 26354 | N2: 226230 | P2: 162611 | R2: 55047 | T2: 4029
A3: 44774 | B3: 47374 | C3: =(B3-B2)*800/5 -> 640 | D3: 40834 | E3: =(D3-D2)*800/5 -> 320 | F3: 21903 | G3: =(F3-F2)*100/5 -> 20 | H3: 257073 | I3: =(H3-H2) -> 37 | J3: 325889 | K3: =(J3-J2) -> 174 | L3: 26358 | M3: =(L3-L2)*300/5 -> 240 | N3: 226233 | O3: =N3-N2 -> 3 | P3: 162835 | Q3: =P3-P2 -> 224 | R3: 55047 | S3: 0 | T3: 4030 | U3: =(T3-T2)*800/5 -> 160
A4: 44775 | B4: 47379 | C4: =(B4-B3)*800/5 -> 800 | D4: 40837 | E4: =(D4-D3)*800/5 -> 480 | F4: 21908 | G4: =(F4-F3)*100/5 -> 100 | H4: 257105 | I4: =(H4-H3) -> 32 | J4: 326071 | K4: =(J4-J3) -> 182 | L4: 26362 | M4: =(L4-L3)*300/5 -> 240 | N4: 226237 | O4: =N4-N3 -> 4 | P4: 162970 | Q4: =P4-P3 -> 135 | R4: 55047 | S4: 0 | T4: 4030 | U4: =(T4-T3)*800/5 -> 0
A5: 44776 | B5: 47383 | C5: =(B5-B4)*800/5 -> 640 | D5: 40840 | E5: =(D5-D4)*800/5 -> 480 | F5: 21913 | G5: =(F5-F4)*100/5 -> 100 | H5: 257135 | I5: =(H5-H4) -> 30 | J5: 326240 | K5: =(J5-J4) -> 169 | L5: 26365 | M5: =(L5-L4)*300/5 -> 180 | N5: 226240 | O5: =N5-N4 -> 3 | P5: =P4 -> 162970 | Q5: =P5-P4 -> 0 | R5: =R4 -> 55047 | S5: =R5-R4 -> 0 | T5: =T4 -> 4030 | U5: =(T5-T4)*800/5 -> 0
A6: 44777 | B6: 47388 | C6: =(B6-B5)*800/5 -> 800 | D6: 40844 | E6: =(D6-D5)*800/5 -> 640 | F6: 21917 | G6: =(F6-F5)*100/5 -> 80 | H6: 257164 | I6: =(H6-H5) -> 29 | J6: 326404 | K6: =(J6-J5) -> 164 | L6: 26368 | M6: =(L6-L5)*300/5 -> 180 | N6: 226243 | O6: =N6-N5 -> 3 | P6: =P5 -> 162970 | Q6: =P6-P5 -> 0 | R6: =R5 -> 55047 | S6: 0 | T6: 4031 | U6: =(T6-T5)*800/5 -> 160
A7: 44778 | B7: 47392 | C7: =(B7-B6)*800/5 -> 640 | D7: 40846 | E7: =(D7-D6)*800/5 -> 320 | F7: 21921 | G7: =(F7-F6)*100/5 -> 80 | H7: 257215 | I7: =(H7-H6) -> 51 | J7: 326510 | K7: =(J7-J6) -> 106 | L7: 26370 | M7: =(L7-L6)*300/5 -> 120 | N7: 226246 | O7: =N7-N6 -> 3 | P7: 163742 | Q7: =P7-P6 -> 772 | R7: =R6 -> 55047 | S7: 0 | T7: =T6 -> 4031 | U7: =(T7-T6)*800/5 -> 0
A8: 44779 | B8: 47396 | C8: =(B8-B7)*800/5 -> 640 | D8: 40849 | E8: =(D8-D7)*800/5 -> 480 | F8: 21925 | G8: =(F8-F7)*100/5 -> 80 | H8: 257249 | I8: =(H8-H7) -> 34 | J8: 326657 | K8: =(J8-J7) -> 147 | L8: 26372 | M8: =(L8-L7)*300/5 -> 120 | N8: 226249 | O8: =N8-N7 -> 3 | P8: 163878 | Q8: =P8-P7 -> 136 | R8: =R7 -> 55047 | S8: =R8-R7 -> 0 | T8: =T7 -> 4031 | U8: =(T8-T7)*800/5 -> 0
A9: 44780 | B9: 47401 | C9: =(B9-B8)*800/5 -> 800 | D9: 40852 | E9: =(D9-D8)*800/5 -> 480 | F9: 21928 | G9: =(F9-F8)*100/5 -> 60 | H9: 257288 | I9: =(H9-H8) -> 39 | J9: 326879 | K9: =(J9-J8) -> 222 | L9: 26375 | M9: =(L9-L8)*300/5 -> 180 | N9: 226253 | O9: =N9-N8 -> 4 | P9: 163994 | Q9: =P9-P8 -> 116 | R9: =R8 -> 55047 | S9: =R9-R8 -> 0 | T9: 4031 | U9: =(T9-T8)*800/5 -> 0
A10: 44781 | B10: 47406 | C10: =(B10-B9)*800/5 -> 800 | D10: 40855 | E10: =(D10-D9)*800/5 -> 480 | F10: 21931 | G10: =(F10-F9)*100/5 -> 60 | H10: 257335 | I10: =(H10-H9) -> 47 | J10: 326992 | K10: =(J10-J9) -> 113 | L10: 26379 | M10: =(L10-L9)*300/5 -> 240 | N10: 226256 | O10: =N10-N9 -> 3 | P10: 164115 | Q10: =P10-P9 -> 121 | R10: =R9 -> 55047 | S10: =R10-R9 -> 0 | T10: 4032 | U10: =(T10-T9)*800/5 -> 160
A11: 44782 | B11: 47410 | C11: =(B11-B10)*800/5 -> 640 | D11: 40858 | E11: =(D11-D10)*800/5 -> 480 | F11: 21935 | G11: =(F11-F10)*100/5 -> 80 | H11: 257376 | I11: =(H11-H10) -> 41 | J11: 327162 | K11: =(J11-J10) -> 170 | L11: 26382 | M11: =(L11-L10)*300/5 -> 180 | N11: 226259 | O11: =N11-N10 -> 3 | P11: 164230 | Q11: =P11-P10 -> 115 | R11: =R10 -> 55047 | S11: =R11-R10 -> 0 | T11: 4032 | U11: =(T11-T10)*800/5 -> 0
A12: 44783 | B12: 47414 | C12: =(B12-B11)*800/5 -> 640 | D12: 40864 | E12: =(D12-D11)*800/5 -> 960 | F12: 21943 | G12: =(F12-F11)*100/5 -> 160 | H12: 257453 | I12: =(H12-H11) -> 77 | J12: 327508 | K12: =(J12-J11) -> 346 | L12: 26388 | M12: =(L12-L11)*300/5 -> 360 | N12: 226265 | O12: =N12-N11 -> 6 | P12: 164351 | Q12: =P12-P11 -> 121 | R12: =R11 -> 55047 | S12: =R12-R11 -> 0 | T12: 4033 | U12: =(T12-T11)*800/5 -> 160
A13: 44784 | B13: =B12 -> 47414 | C13: =(B13-B12)*800/5 -> 0 | D13: =D12 -> 40864 | E13: =(D13-D12)*800/5 -> 0 | F13: =F12 -> 21943 | G13: =(F13-F12)*100/5 -> 0 | H13: =H12 -> 257453 | I13: =(H13-H12) -> 0 | J13: =J12 -> 327508 | K13: =(J13-J12) -> 0 | L13: =L12 -> 26388 | M13: =(L13-L12)*300/5 -> 0 | N13: =N12 -> 226265 | O13: =N13-N12 -> 0 | P13: =P12 -> 164351 | Q13: =P13-P12 -> 0 | R13: =R12 -> 55047 | S13: =R13-R12 -> 0 | T13: =T12 -> 4033 | U13: =(T13-T12)*800/5 -> 0
A14: 44785 | B14: 47423 | C14: =(B14-B13)*800/5 -> 1440 | D14: 40867 | E14: =(D14-D13)*800/5 -> 480 | F14: 21947 | G14: =(F14-F13)*100/5 -> 80 | H14: 257469 | I14: =(H14-H13) -> 16 | J14: 327627 | K14: =(J14-J13) -> 119 | L14: 26390 | M14: =(L14-L13)*300/5 -> 120 | N14: 226269 | O14: =N14-N13 -> 4 | P14: =P13 -> 164351 | Q14: =P14-P13 -> 0 | R14: =R13 -> 55047 | S14: 0 | T14: 4034 | U14: =(T14-T13)*800/5 -> 160
A15: 44786 | B15: 47428 | C15: =(B15-B14)*800/5 -> 800 | D15: 40870 | E15: =(D15-D14)*800/5 -> 480 | F15: 21951 | G15: =(F15-F14)*100/5 -> 80 | H15: 257507 | I15: =(H15-H14) -> 38 | J15: 327765 | K15: =(J15-J14) -> 138 | L15: 26392 | M15: =(L15-L14)*300/5 -> 120 | N15: 226272 | O15: =N15-N14 -> 3 | P15: =P14 -> 164351 | Q15: =P15-P14 -> 0 | R15: =R14 -> 55047 | S15: 0 | T15: 4034 | U15: =(T15-T14)*800/5 -> 0
A16: 44787 | B16: =B15 -> 47428 | C16: =(B16-B15)*800/5 -> 0 | D16: =D15 -> 40870 | E16: =(D16-D15)*800/5 -> 0 | F16: =F15 -> 21951 | G16: =(F16-F15)*100/5 -> 0 | H16: =H15 -> 257507 | I16: =(H16-H15) -> 0 | J16: =J15 -> 327765 | K16: =(J16-J15) -> 0 | L16: =L15 -> 26392 | M16: =(L16-L15)*300/5 -> 0 | N16: =N15 -> 226272 | O16: =N16-N15 -> 0 | P16: =P15 -> 164351 | Q16: =P16-P15 -> 0 | R16: =R15 -> 55047 | S16: =R16-R15 -> 0 | T16: =T15 -> 4034 | U16: =(T16-T15)*800/5 -> 0
A17: 44788 | B17: 47437 | C17: =(B17-B16)*800/5 -> 1440 | D17: 40876 | E17: =(D17-D16)*800/5 -> 960 | F17: 21958 | G17: =(F17-F16)*100/5 -> 140 | H17: 257568 | I17: =(H17-H16) -> 61 | J17: 328098 | K17: =(J17-J16) -> 333 | L17: 26399 | M17: =(L17-L16)*300/5 -> 420 | N17: 226278 | O17: =N17-N16 -> 6 | P17: =P16 -> 164351 | Q17: =P17-P16 -> 0 | R17: =R16 -> 55047 | S17: =S16 -> 0 | T17: 4035 | U17: =(T17-T16)*800/5 -> 160
A18: 44789 | B18: 47442 | C18: =(B18-B17)*800/5 -> 800 | D18: 40879 | E18: =(D18-D17)*800/5 -> 480 | F18: 21961 | G18: =(F18-F17)*100/5 -> 60 | H18: 257610 | I18: =(H18-H17) -> 42 | J18: 328266 | K18: =(J18-J17) -> 168 | L18: 26403 | M18: =(L18-L17)*300/5 -> 240 | N18: 226282 | O18: =N18-N17 -> 4 | P18: =P17 -> 164351 | Q18: =P18-P17 -> 0 | R18: =R17 -> 55047 | S18: =R18-R17 -> 0 | T18: 4036 | U18: =(T18-T17)*800/5 -> 160
A19: 44790 | B19: 47447 | C19: =(B19-B18)*800/5 -> 800 | D19: 40882 | E19: =(D19-D18)*800/5 -> 480 | F19: 21964 | G19: =(F19-F18)*100/5 -> 60 | H19: 257645 | I19: =(H19-H18) -> 35 | J19: 328434 | K19: =(J19-J18) -> 168 | L19: 26406 | M19: =(L19-L18)*300/5 -> 180 | N19: 226285 | O19: =N19-N18 -> 3 | P19: =P18 -> 164351 | Q19: 0 | R19: =R18 -> 55047 | S19: =R19-R18 -> 0 | T19: 4037 | U19: =(T19-T18)*800/5 -> 160
A20: 44791 | B20: 47451 | C20: =(B20-B19)*800/5 -> 640 | D20: 40885 | E20: =(D20-D19)*800/5 -> 480 | F20: 21968 | G20: =(F20-F19)*100/5 -> 80 | H20: 257668 | I20: =(H20-H19) -> 23 | J20: 328593 | K20: =(J20-J19) -> 159 | L20: 26409 | M20: =(L20-L19)*300/5 -> 180 | N20: 226288 | O20: =N20-N19 -> 3 | P20: 165777 | Q20: =P20-P19 -> 1426 | R20: 55047 | S20: =R20-R19 -> 0 | T20: 4037 | U20: =(T20-T19)*800/5 -> 0
A21: 44792 | B21: 47456 | C21: =(B21-B20)*800/5 -> 800 | D21: 40888 | E21: =(D21-D20)*800/5 -> 480 | F21: 21973 | G21: =(F21-F20)*100/5 -> 100 | H21: 257708 | I21: =(H21-H20) -> 40 | J21: 328700 | K21: =(J21-J20) -> 107 | L21: 26411 | M21: =(L21-L20)*300/5 -> 120 | N21: 226291 | O21: =N21-N20 -> 3 | P21: 165891 | Q21: =P21-P20 -> 114 | R21: =R20 -> 55047 | S21: =R21-R20 -> 0 | T21: 4038 | U21: =(T21-T20)*800/5 -> 160
A22: 44793 | B22: 47461 | C22: =(B22-B21)*800/5 -> 800 | D22: 40891 | E22: =(D22-D21)*800/5 -> 480 | F22: 21977 | G22: =(F22-F21)*100/5 -> 80 | H22: 257758 | I22: =(H22-H21) -> 50 | J22: 328801 | K22: =(J22-J21) -> 101 | L22: 26414 | M22: =(L22-L21)*300/5 -> 180 | N22: 226294 | O22: =N22-N21 -> 3 | P22: 165998 | Q22: =P22-P21 -> 107 | R22: =R21 -> 55047 | S22: =R22-R21 -> 0 | T22: =T21 -> 4038 | U22: =(T22-T21)*800/5 -> 0
A23: 44794 | B23: 47465 | C23: =(B23-B22)*800/5 -> 640 | D23: 40893 | E23: =(D23-D22)*800/5 -> 320 | F23: 21981 | G23: =(F23-F22)*100/5 -> 80 | H23: 257810 | I23: =(H23-H22) -> 52 | J23: 328898 | K23: =(J23-J22) -> 97 | L23: 26416 | M23: =(L23-L22)*300/5 -> 120 | N23: 226296 | O23: =N23-N22 -> 2 | P23: =P22 -> 165998 | Q23: =P23-P22 -> 0 | R23: =R22 -> 55047 | S23: =R23-R22 -> 0 | T23: 4039 | U23: =(T23-T22)*800/5 -> 160
A24: 44795 | B24: 47467 | C24: =(B24-B23)*800/5 -> 320 | D24: 40897 | E24: =(D24-D23)*800/5 -> 640 | F24: 21984 | G24: =(F24-F23)*100/5 -> 60 | H24: 257820 | I24: =(H24-H23) -> 10 | J24: 329172 | K24: =(J24-J23) -> 274 | L24: 26420 | M24: =(L24-L23)*300/5 -> 240 | N24: 226301 | O24: =N24-N23 -> 5 | P24: 166363 | Q24: =P24-P23 -> 365 | R24: =R23 -> 55047 | S24: =R24-R23 -> 0 | T24: 4039 | U24: =(T24-T23)*800/5 -> 0
A25: 44796 | B25: 47469 | C25: =(B25-B24)*800/5 -> 320 | D25: 40900 | E25: =(D25-D24)*800/5 -> 480 | F25: 21989 | G25: =(F25-F24)*100/5 -> 100 | H25: 257830 | I25: =(H25-H24) -> 10 | J25: 329347 | K25: =(J25-J24) -> 175 | L25: 26424 | M25: =(L25-L24)*300/5 -> 240 | N25: 226301 | O25: =N25-N24 -> 0 | P25: =P24 -> 166363 | Q25: =P25-P24 -> 0 | R25: =R24 -> 55047 | S25: =R25-R24 -> 0 | T25: 4040 | U25: =(T25-T24)*800/5 -> 160
A26: 44797 | B26: 47472 | C26: =(B26-B25)*800/5 -> 480 | D26: 40903 | E26: =(D26-D25)*800/5 -> 480 | F26: 21992 | G26: =(F26-F25)*100/5 -> 60 | H26: 257840 | I26: =(H26-H25) -> 10 | J26: 329521 | K26: =(J26-J25) -> 174 | L26: 26427 | M26: =(L26-L25)*300/5 -> 180 | N26: 226307 | O26: =N26-N25 -> 6 | P26: 166701 | Q26: =P26-P25 -> 338 | R26: =R25 -> 55047 | S26: =R26-R25 -> 0 | T26: 4041 | U26: =(T26-T25)*800/5 -> 160
A27: 44798 | B27: 47475 | C27: =(B27-B26)*800/5 -> 480 | D27: 40906 | E27: =(D27-D26)*800/5 -> 480 | F27: 21995 | G27: =(F27-F26)*100/5 -> 60 | H27: 257851 | I27: =(H27-H26) -> 11 | J27: 329692 | K27: =(J27-J26) -> 171 | L27: 26431 | M27: =(L27-L26)*300/5 -> 240 | N27: 226310 | O27: =N27-N26 -> 3 | P27: 166821 | Q27: =P27-P26 -> 120 | R27: =R26 -> 55047 | S27: =R27-R26 -> 0 | T27: 4042 | U27: =(T27-T26)*800/5 -> 160
A28: 44799 | B28: 47487 | C28: =(B28-B27)*800/5 -> 1920 | D28: 40909 | E28: =(D28-D27)*800/5 -> 480 | F28: 22000 | G28: =(F28-F27)*100/5 -> 100 | H28: 257857 | I28: =(H28-H27) -> 6 | J28: 329806 | K28: =(J28-J27) -> 114 | L28: 26433 | M28: =(L28-L27)*300/5 -> 120 | N28: 226314 | O28: =N28-N27 -> 4 | P28: =P27 -> 166821 | Q28: =P28-P27 -> 0 | R28: =R27 -> 55047 | S28: =R28-R27 -> 0 | T28: 4042 | U28: =(T28-T27)*800/5 -> 0
A29: 44800 | B29: 47491 | C29: =(B29-B28)*800/5 -> 640 | D29: 40912 | E29: =(D29-D28)*800/5 -> 480 | F29: 22003 | G29: =(F29-F28)*100/5 -> 60 | H29: 257878 | I29: =(H29-H28) -> 21 | J29: 329941 | K29: =(J29-J28) -> 135 | L29: 26435 | M29: =(L29-L28)*300/5 -> 120 | N29: 226317 | O29: =N29-N28 -> 3 | P29: =P28 -> 166821 | Q29: =P29-P28 -> 0 | R29: =R28 -> 55047 | S29: =R29-R28 -> 0 | T29: 4043 | U29: =(T29-T28)*800/5 -> 160
A30: 44801 | B30: 47495 | C30: =(B30-B29)*800/5 -> 640 | D30: 40914 | E30: =(D30-D29)*800/5 -> 320 | F30: 22006 | G30: =(F30-F29)*100/5 -> 60 | H30: 257897 | I30: =(H30-H29) -> 19 | J30: 330094 | K30: =(J30-J29) -> 153 | L30: 26438 | M30: =(L30-L29)*300/5 -> 180 | N30: 226320 | O30: =N30-N29 -> 3 | P30: =P29 -> 166821 | Q30: =P30-P29 -> 0 | R30: =R29 -> 55047 | S30: =R30-R29 -> 0 | T30: 4043 | U30: =(T30-T29)*800/5 -> 0
A31: 44802 | B31: 47500 | C31: =(B31-B30)*800/5 -> 800 | D31: 40918 | E31: =(D31-D30)*800/5 -> 640 | F31: 22011 | G31: =(F31-F30)*100/5 -> 100 | H31: 257912 | I31: =(H31-H30) -> 15 | J31: 330262 | K31: =(J31-J30) -> 168 | L31: 26442 | M31: =(L31-L30)*300/5 -> 240 | N31: 226323 | O31: =N31-N30 -> 3 | P31: 167475 | Q31: =P31-P30 -> 654 | R31: 55047 | S31: 0 | T31: 4044 | U31: =(T31-T30)*800/5 -> 160
A32: 44803 | B32: 47504 | C32: =(B32-B31)*800/5 -> 640 | D32: 40921 | E32: =(D32-D31)*800/5 -> 480 | F32: 22014 | G32: =(F32-F31)*100/5 -> 60 | H32: 257927 | I32: =(H32-H31) -> 15 | J32: 330432 | K32: =(J32-J31) -> 170 | L32: 26446 | M32: =(L32-L31)*300/5 -> 240 | N32: 226326 | O32: =N32-N31 -> 3 | P32: 167475 | Q32: =P32-P31 -> 0 | R32: =R31 -> 55047 | S32: =R32-R31 -> 0 | T32: 4045 | U32: =(T32-T31)*800/5 -> 160
A33: 44804 | B33: 47509 | C33: =(B33-B32)*800/5 -> 800 | D33: 40924 | E33: =(D33-D32)*800/5 -> 480 | F33: 22019 | G33: =(F33-F32)*100/5 -> 100 | H33: 257970 | I33: =(H33-H32) -> 43 | J33: 330607 | K33: =(J33-J32) -> 175 | L33: 26449 | M33: =(L33-L32)*300/5 -> 180 | N33: 226330 | O33: =N33-N32 -> 4 | P33: 167701 | Q33: =P33-P32 -> 226 | R33: =R32 -> 55047 | S33: =SUM(S3:S32) -> 0 | T33: 4046 | U33: =(T33-T32)*800/5 -> 160
A34: Total | C34: =SUM(C3:C33) -> 22240 | E34: =SUM(E3:E33) -> 14720 | G34: =SUM(G3:G33) -> 2340 | I34: =SUM(I3:I33) -> 934 | K34: =SUM(K3:K33) -> 4892 | M34: =SUM(M3:M33) -> 5700 | O34: =SUM(O3:O33) -> 100 | Q34: =SUM(Q3:Q33) -> 5090 | S34: =SUM(S3:S33) -> 0 | U34: =SUM(U3:U33) -> 2720

Sheet ELECT.
A1: Day | B1: Rooms Sold | C1: New Chillers | D1: Cons | E1: F-1 | F1: Cons. | G1: F-2 | H1: Cons. | I1: Total | J1: T-1 | K1: Cons. | L1: T-2 | M1: Cons. | N1: T-3 | O1: Cons. | P1: T-4 | Q1: Cons. | R1: T-5 | S1: Cons. | T1: T-6 | U1: Cons. | V1: T-7 | W1: Cons. | X1: Total | Y1: Diff | Z1: Daily Money Value | AA1: MTD Total Money
A2: 44773 | B2: 170 | C2: 19927 | E2: 32445770 | G2: 2929341 | I2: =F2+H2 -> 0 | J2: 245034 | L2: 497687 | N2: 7113857 | P2: 7467951 | R2: 21870756 | T2: 0 | V2: 9866667 | X2: =K2+M2+O2+Q2+S2+U2+W2 -> 0 | Y2: =I2-X2 -> 0 | Z2: =(0.93352*(W2+S2)+0.5568*(Q2+O2))*0.26 -> 0
A3: 44774 | C3: 19933 | D3: =IF((C3-C2)<0,"0",(C3-C2))*160 -> 960 | E3: 32473240 | F3: =IF((E3-E2)<0,"0",(E3-E2)) -> 27470 | G3: 2989242 | H3: =IF((G3-G2)<0,"0",(G3-G2)) -> 59901 | I3: =F3+H3 -> 87371 | J3: 252021 | K3: =(IF((J3-J2)<L90,"0",(J3-J2)))*2 -> 13974 | L3: 505000 | M3: =IF((L3-L2)<0,"0",(L3-L2)) -> 7313 | N3: 7123859 | O3: =(IF((N3-N2)<P90,"0",(N3-N2)))*2 -> 20004 | P3: 7483440 | Q3: =IF((P3-P2)<0,"0",(P3-P2)) -> 15489 | R3: 21882242 | S3: =IF((R3-R2)<0,"0",(R3-R2)) -> 11486 | T3: 0 | V3: 9879425 | W3: =IF((V3-V2)<0,"0",(V3-V2)) -> 12758 | X3: =K3+M3+O3+Q3+S3+U3+W3 -> 81024 | Y3: =I3-X3 -> 6347 | Z3: =(0.93352*(W3+S3)+0.5568*(Q3+O3))*0.26 -> 11022.638 | AA3: =SUM(Z1:Z3) -> 11022.638
A4: 44775 | B4: 195 | C4: 19937 | D4: =IF((C4-C3)<0,"0",(C4-C3))*160 -> 640 | E4: 32493929 | F4: =IF((E4-E3)<0,"0",(E4-E3)) -> 20689 | G4: 3036299 | H4: =IF((G4-G3)<0,"0",(G4-G3)) -> 47057 | I4: =F4+H4 -> 67746 | J4: 256996 | K4: =(IF((J4-J3)<L92,"0",(J4-J3)))*2 -> 9950 | L4: 510657 | M4: =IF((L4-L3)<0,"0",(L4-L3)) -> 5657 | N4: 7131275 | O4: =(IF((N4-N3)<P92,"0",(N4-N3)))*2 -> 14832 | P4: 7495300 | Q4: =IF((P4-P3)<0,"0",(P4-P3)) -> 11860 | R4: 21891060 | S4: =IF((R4-R3)<0,"0",(R4-R3)) -> 8818 | T4: 0 | V4: 9889610 | W4: =IF((V4-V3)<0,"0",(V4-V3)) -> 10185 | X4: =K4+M4+O4+Q4+S4+U4+W4 -> 61302 | Y4: =I4-X4 -> 6444 | Z4: =(0.93352*(W4+S4)+0.5568*(Q4+O4))*0.26 -> 8476.4644 | AA4: =SUM(Z1:Z4) -> 19499.102
A5: 44776 | B5: 180 | C5: 19941 | D5: =IF((C5-C4)<0,"0",(C5-C4))*160 -> 640 | E5: 32518366 | F5: =IF((E5-E4)<0,"0",(E5-E4)) -> 24437 | G5: 3092596 | H5: =IF((G5-G4)<0,"0",(G5-G4)) -> 56297 | I5: =F5+H5 -> 80734 | J5: 262785 | K5: =(IF((J5-J4)<0,"0",(J5-J4)))*2 -> 11578 | L5: 517507 | M5: =IF((L5-L4)<0,"0",(L5-L4)) -> 6850 | N5: 7139966 | O5: =(IF((N5-N4)<0,"0",(N5-N4)))*2 -> 17382 | P5: 7509276 | Q5: =IF((P5-P4)<0,"0",(P5-P4)) -> 13976 | R5: 21901711 | S5: =IF((R5-R4)<0,"0",(R5-R4)) -> 10651 | T5: 0 | V5: 9901936 | W5: =IF((V5-V4)<0,"0",(V5-V4)) -> 12326 | X5: =K5+M5+O5+Q5+S5+U5+W5 -> 72763 | Y5: =I5-X5 -> 7971 | Z5: =(0.93352*(W5+S5)+0.5568*(Q5+O5))*0.26 -> 10116.502 | AA5: =SUM(Z1:Z5) -> 29615.604
A6: 44777 | B6: 201 | C6: 19945 | D6: =IF((C6-C5)<0,"0",(C6-C5))*160 -> 640 | E6: 32547393 | F6: =IF((E6-E5)<0,"0",(E6-E5)) -> 29027 | G6: 3158751 | H6: =IF((G6-G5)<0,"0",(G6-G5)) -> 66155 | I6: =F6+H6 -> 95182 | J6: 269486 | K6: =(IF((J6-J5)<0,"0",(J6-J5)))*2 -> 13402 | L6: 525583 | M6: =IF((L6-L5)<0,"0",(L6-L5)) -> 8076 | N6: 7150327 | O6: =(IF((N6-N5)<0,"0",(N6-N5)))*2 -> 20722 | P6: 7525549 | Q6: =IF((P6-P5)<0,"0",(P6-P5)) -> 16273 | R6: 21914586 | S6: =IF((R6-R5)<0,"0",(R6-R5)) -> 12875 | T6: 0 | V6: 9916381 | W6: =IF((V6-V5)<0,"0",(V6-V5)) -> 14445 | X6: =K6+M6+O6+Q6+S6+U6+W6 -> 85793 | Y6: =I6-X6 -> 9389 | Z6: =(0.93352*(W6+S6)+0.5568*(Q6+O6))*0.26 -> 11986.671 | AA6: =SUM(Z1:Z6) -> 41602.276
A7: 44778 | B7: 198 | C7: 19949 | D7: =IF((C7-C6)<0,"0",(C7-C6))*160 -> 640 | E7: 32573083 | F7: =IF((E7-E6)<0,"0",(E7-E6)) -> 25690 | G7: 3217926 | H7: =IF((G7-G6)<0,"0",(G7-G6)) -> 59175 | I7: =F7+H7 -> 84865 | J7: 274900 | K7: =(IF((J7-J6)<0,"0",(J7-J6)))*2 -> 10828 | L7: 532349 | M7: =IF((L7-L6)<0,"0",(L7-L6)) -> 6766 | N7: 7156566 | O7: =(IF((N7-N6)<0,"0",(N7-N6)))*2 -> 12478 | P7: 7540180 | Q7: =IF((P7-P6)<0,"0",(P7-P6)) -> 14631 | R7: 21926383 | S7: =IF((R7-R6)<0,"0",(R7-R6)) -> 11797 | T7: 0 | V7: 9929420 | W7: =IF((V7-V6)<0,"0",(V7-V6)) -> 13039 | X7: =K7+M7+O7+Q7+S7+U7+W7 -> 69539 | Y7: =I7-X7 -> 15326 | Z7: =(0.93352*(W7+S7)+0.5568*(Q7+O7))*0.26 -> 9952.5904 | AA7: =SUM(Z1:Z7) -> 51554.866
A8: 44779 | B8: 195 | C8: 19954 | D8: =IF((C8-C7)<0,"0",(C8-C7))*160 -> 800 | E8: 32591255 | F8: =IF((E8-E7)<0,"0",(E8-E7)) -> 18172 | G8: 3259359 | H8: =IF((G8-G7)<0,"0",(G8-G7)) -> 41433 | I8: =F8+H8 -> 59605 | J8: 278791 | K8: =(IF((J8-J7)<0,"0",(J8-J7)))*2 -> 7782 | L8: 537252 | M8: =IF((L8-L7)<0,"0",(L8-L7)) -> 4903 | N8: 7166222 | O8: =(IF((N8-N7)<0,"0",(N8-N7)))*2 -> 19312 | P8: 7550526 | Q8: =IF((P8-P7)<0,"0",(P8-P7)) -> 10346 | R8: 21934364 | S8: =IF((R8-R7)<0,"0",(R8-R7)) -> 7981 | T8: 0 | V8: 9938584 | W8: =IF((V8-V7)<0,"0",(V8-V7)) -> 9164 | X8: =K8+M8+O8+Q8+S8+U8+W8 -> 59488 | Y8: =I8-X8 -> 117 | Z8: =(0.93352*(W8+S8)+0.5568*(Q8+O8))*0.26 -> 8454.8814 | AA8: =SUM(Z1:Z8) -> 60009.748
A9: 44780 | B9: 185 | C9: 19958 | D9: =IF((C9-C8)<0,"0",(C9-C8))*160 -> 640 | E9: 32617775 | F9: =IF((E9-E8)<0,"0",(E9-E8)) -> 26520 | G9: 3319471 | H9: =IF((G9-G8)<0,"0",(G9-G8)) -> 60112 | I9: =F9+H9 -> 86632 | J9: 284702 | K9: =(IF((J9-J8)<0,"0",(J9-J8)))*2 -> 11822 | L9: 544460 | M9: =IF((L9-L8)<0,"0",(L9-L8)) -> 7208 | N9: 7175764 | O9: =(IF((N9-N8)<0,"0",(N9-N8)))*2 -> 19084 | P9: 7565534 | Q9: =IF((P9-P8)<0,"0",(P9-P8)) -> 15008 | R9: 21945860 | S9: =IF((R9-R8)<0,"0",(R9-R8)) -> 11496 | T9: 0 | V9: 9951809 | W9: =IF((V9-V8)<0,"0",(V9-V8)) -> 13225 | X9: =K9+M9+O9+Q9+S9+U9+W9 -> 77843 | Y9: =I9-X9 -> 8789 | Z9: =(0.93352*(W9+S9)+0.5568*(Q9+O9))*0.26 -> 10935.593 | AA9: =SUM(Z1:Z9) -> 70945.341
A10: 44781 | B10: 245 | C10: 19963 | D10: =IF((C10-C9)<0,"0",(C10-C9))*160 -> 800 | E10: 32644982 | F10: =IF((E10-E9)<0,"0",(E10-E9)) -> 27207 | G10: 3382350 | H10: =IF((G10-G9)<0,"0",(G10-G9)) -> 62879 | I10: =F10+H10 -> 90086 | J10: 291069 | K10: =(IF((J10-J9)<0,"0",(J10-J9)))*2 -> 12734 | L10: 551790 | M10: =IF((L10-L9)<0,"0",(L10-L9)) -> 7330 | N10: 7185599 | O10: =(IF((N10-N9)<0,"0",(N10-N9)))*2 -> 19670 | P10: 7581065 | Q10: =IF((P10-P9)<0,"0",(P10-P9)) -> 15531 | R10: 21957925 | S10: =IF((R10-R9)<0,"0",(R10-R9)) -> 12065 | T10: 0 | V10: 9965588 | W10: =IF((V10-V9)<0,"0",(V10-V9)) -> 13779 | X10: =K10+M10+O10+Q10+S10+U10+W10 -> 81109 | Y10: =I10-X10 -> 8977 | Z10: =(0.93352*(W10+S10)+0.5568*(Q10+O10))*0.26 -> 11368.71 | AA10: =SUM(Z1:Z10) -> 82314.051
A11: 44782 | B11: 203 | C11: 19967 | D11: =IF((C11-C10)<0,"0",(C11-C10))*160 -> 640 | E11: 32666930 | F11: =IF((E11-E10)<0,"0",(E11-E10)) -> 21948 | G11: 3431124 | H11: =IF((G11-G10)<0,"0",(G11-G10)) -> 48774 | I11: =F11+H11 -> 70722 | J11: 296210 | K11: =(IF((J11-J10)<0,"0",(J11-J10)))*2 -> 10282 | L11: 557662 | M11: =IF((L11-L10)<0,"0",(L11-L10)) -> 5872 | N11: 7193534 | O11: =(IF((N11-N10)<0,"0",(N11-N10)))*2 -> 15870 | P11: 7593564 | Q11: =IF((P11-P10)<0,"0",(P11-P10)) -> 12499 | R11: 21967431 | S11: =IF((R11-R10)<0,"0",(R11-R10)) -> 9506 | T11: 0 | V11: 9975887 | W11: =IF((V11-V10)<0,"0",(V11-V10)) -> 10299 | X11: =K11+M11+O11+Q11+S11+U11+W11 -> 64328 | Y11: =I11-X11 -> 6394 | Z11: =(0.93352*(W11+S11)+0.5568*(Q11+O11))*0.26 -> 8913.8979 | AA11: =SUM(Z1:Z11) -> 91227.949
A12: 44783 | B12: 234 | C12: 19972 | D12: =IF((C12-C11)<0,"0",(C12-C11))*160 -> 800 | E12: 32688526 | F12: =IF((E12-E11)<0,"0",(E12-E11)) -> 21596 | G12: 3479153 | H12: =IF((G12-G11)<0,"0",(G12-G11)) -> 48029 | I12: =F12+H12 -> 69625 | J12: 301254 | K12: =(IF((J12-J11)<0,"0",(J12-J11)))*2 -> 10088 | L12: 563233 | M12: =IF((L12-L11)<0,"0",(L12-L11)) -> 5571 | N12: 7201458 | O12: =(IF((N12-N11)<0,"0",(N12-N11)))*2 -> 15848 | P12: 7605914 | Q12: =IF((P12-P11)<0,"0",(P12-P11)) -> 12350 | R12: 21976700 | S12: =IF((R12-R11)<0,"0",(R12-R11)) -> 9269 | T12: 0 | V12: 9986072 | W12: =IF((V12-V11)<0,"0",(V12-V11)) -> 10185 | X12: =K12+M12+O12+Q12+S12+U12+W12 -> 63311 | Y12: =I12-X12 -> 6314 | Z12: =(0.93352*(W12+S12)+0.5568*(Q12+O12))*0.26 -> 8803.9496 | AA12: =SUM(Z1:Z12) -> 100031.9
A13: 44784 | B13: 222 | C13: 19975 | D13: =IF((C13-C12)<0,"0",(C13-C12))*160 -> 480 | E13: 32720933 | F13: =IF((E13-E12)<0,"0",(E13-E12)) -> 32407 | G13: 3553013 | H13: =IF((G13-G12)<0,"0",(G13-G12)) -> 73860 | I13: =F13+H13 -> 106267 | J13: 308732 | K13: =(IF((J13-J12)<0,"0",(J13-J12)))*2 -> 14956 | L13: 571420 | M13: =IF((L13-L12)<0,"0",(L13-L12)) -> 8187 | N13: 7213439 | O13: =(IF((N13-N12)<0,"0",(N13-N12)))*2 -> 23962 | P13: 7624888 | Q13: =IF((P13-P12)<0,"0",(P13-P12)) -> 18974 | R13: 21991456 | S13: =IF((R13-R12)<0,"0",(R13-R12)) -> 14756 | T13: 0 | V13: 1633 | W13: =(V13-V12)+9999999 -> 15560 | X13: =K13+M13+O13+Q13+S13+U13+W13 -> 96395 | Y13: =I13-X13 -> 9872 | Z13: =(0.93352*(W13+S13)+0.5568*(Q13+O13))*0.26 -> 13573.913 | AA13: =SUM(Z1:Z13) -> 113605.81
A14: 44785 | B14: 245 | C14: 19979 | D14: =IF((C14-C13)<0,"0",(C14-C13))*160 -> 640 | E14: 32742078 | F14: =IF((E14-E13)<0,"0",(E14-E13)) -> 21145 | G14: 3601925 | H14: =IF((G14-G13)<0,"0",(G14-G13)) -> 48912 | I14: =F14+H14 -> 70057 | J14: 313421 | K14: =(IF((J14-J13)<0,"0",(J14-J13)))*2 -> 9378 | L14: 576870 | M14: =IF((L14-L13)<0,"0",(L14-L13)) -> 5450 | N14: 7221182 | O14: =(IF((N14-N13)<0,"0",(N14-N13)))*2 -> 15486 | P14: 7637187 | Q14: =IF((P14-P13)<0,"0",(P14-P13)) -> 12299 | R14: 22001403 | S14: =IF((R14-R13)<0,"0",(R14-R13)) -> 9947 | T14: 0 | V14: 12142 | W14: =IF((V14-V13)<0,"0",(V14-V13)) -> 10509 | X14: =K14+M14+O14+Q14+S14+U14+W14 -> 63069 | Y14: =I14-X14 -> 6988 | Z14: =(0.93352*(W14+S14)+0.5568*(Q14+O14))*0.26 -> 8987.361 | AA14: =SUM(Z1:Z14) -> 122593.17
A15: 44786 | B15: 218 | C15: 19983 | D15: =IF((C15-C14)<0,"0",(C15-C14))*160 -> 640 | E15: 32765318 | F15: =IF((E15-E14)<0,"0",(E15-E14)) -> 23240 | G15: 3656613 | H15: =IF((G15-G14)<0,"0",(G15-G14)) -> 54688 | I15: =F15+H15 -> 77928 | J15: 318801 | K15: =(IF((J15-J14)<0,"0",(J15-J14)))*2 -> 10760 | L15: 582814 | M15: =IF((L15-L14)<0,"0",(L15-L14)) -> 5944 | N15: 7229734 | O15: =(IF((N15-N14)<0,"0",(N15-N14)))*2 -> 17104 | P15: 7650749 | Q15: =IF((P15-P14)<0,"0",(P15-P14)) -> 13562 | R15: 22014617 | S15: =IF((R15-R14)<0,"0",(R15-R14)) -> 13214 | T15: 0 | V15: 23826 | W15: =IF((V15-V14)<0,"0",(V15-V14)) -> 11684 | X15: =K15+M15+O15+Q15+S15+U15+W15 -> 72268 | Y15: =I15-X15 -> 5660 | Z15: =(0.93352*(W15+S15)+0.5568*(Q15+O15))*0.26 -> 10482.579 | AA15: =SUM(Z1:Z15) -> 133075.75
A16: 44787 | B16: 224 | C16: 19987 | D16: =IF((C16-C15)<0,"0",(C16-C15))*160 -> 640 | E16: 32788519 | F16: =IF((E16-E15)<0,"0",(E16-E15)) -> 23201 | G16: 3709452 | H16: =IF((G16-G15)<0,"0",(G16-G15)) -> 52839 | I16: =F16+H16 -> 76040 | J16: 324286 | K16: =(IF((J16-J15)<0,"0",(J16-J15)))*2 -> 10970 | L16: 588852 | M16: =IF((L16-L15)<0,"0",(L16-L15)) -> 6038 | N16: 7238217 | O16: =(IF((N16-N15)<0,"0",(N16-N15)))*2 -> 16966 | P16: 7664316 | Q16: =IF((P16-P15)<0,"0",(P16-P15)) -> 13567 | R16: 22022034 | S16: =IF((R16-R15)<0,"0",(R16-R15)) -> 7417 | T16: 0 | V16: 34920 | W16: =IF((V16-V15)<0,"0",(V16-V15)) -> 11094 | X16: =K16+M16+O16+Q16+S16+U16+W16 -> 66052 | Y16: =I16-X16 -> 9988 | Z16: =(0.93352*(W16+S16)+0.5568*(Q16+O16))*0.26 -> 8913.1024 | AA16: =SUM(Z1:Z16) -> 141988.85
A17: 44788 | B17: 223 | C17: 19992 | D17: =IF((C17-C16)<0,"0",(C17-C16))*160 -> 800 | E17: 32818535 | F17: =IF((E17-E16)<0,"0",(E17-E16)) -> 30016 | G17: 3775700 | H17: =IF((G17-G16)<0,"0",(G17-G16)) -> 66248 | I17: =F17+H17 -> 96264 | J17: 331269 | K17: =(IF((J17-J16)<0,"0",(J17-J16)))*2 -> 13966 | L17: 597119 | M17: =IF((L17-L16)<0,"0",(L17-L16)) -> 8267 | N17: 7248972 | O17: =(IF((N17-N16)<0,"0",(N17-N16)))*2 -> 21510 | P17: 7681491 | Q17: =IF((P17-P16)<0,"0",(P17-P16)) -> 17175 | R17: 22035856 | S17: =IF((R17-R16)<0,"0",(R17-R16)) -> 13822 | T17: 0 | V17: 48859 | W17: =IF((V17-V16)<0,"0",(V17-V16)) -> 13939 | X17: =K17+M17+O17+Q17+S17+U17+W17 -> 88679 | Y17: =I17-X17 -> 7585 | Z17: =(0.93352*(W17+S17)+0.5568*(Q17+O17))*0.26 -> 12338.367 | AA17: =SUM(Z1:Z17) -> 154327.22
A18: 44789 | B18: 107 | C18: 19997 | D18: =IF((C18-C17)<0,"0",(C18-C17))*160 -> 800 | E18: 32838116 | F18: =IF((E18-E17)<0,"0",(E18-E17)) -> 19581 | G18: 3821509 | H18: =IF((G18-G17)<0,"0",(G18-G17)) -> 45809 | I18: =F18+H18 -> 65390 | J18: 336244 | K18: =(IF((J18-J17)<0,"0",(J18-J17)))*2 -> 9950 | L18: 602920 | M18: =IF((L18-L17)<0,"0",(L18-L17)) -> 5801 | N18: 7255764 | O18: =(IF((N18-N17)<0,"0",(N18-N17)))*2 -> 13584 | P18: 7693545 | Q18: =IF((P18-P17)<0,"0",(P18-P17)) -> 12054 | R18: 22044846 | S18: =IF((R18-R17)<0,"0",(R18-R17)) -> 8990 | T18: 0 | V18: 58258 | W18: =IF((V18-V17)<0,"0",(V18-V17)) -> 9399 | X18: =K18+M18+O18+Q18+S18+U18+W18 -> 59778 | Y18: =I18-X18 -> 5612 | Z18: =(0.93352*(W18+S18)+0.5568*(Q18+O18))*0.26 -> 8174.8518 | AA18: =SUM(Z1:Z18) -> 162502.07
A19: 44790 | B19: 150 | C19: 20001 | D19: =IF((C19-C18)<0,"0",(C19-C18))*160 -> 640 | E19: 32866411 | F19: =IF((E19-E18)<0,"0",(E19-E18)) -> 28295 | G19: 3884530 | H19: =IF((G19-G18)<0,"0",(G19-G18)) -> 63021 | I19: =F19+H19 -> 91316 | J19: 342982 | K19: =(IF((J19-J18)<0,"0",(J19-J18)))*2 -> 13476 | L19: 610869 | M19: =IF((L19-L18)<0,"0",(L19-L18)) -> 7949 | N19: 7265827 | O19: =(IF((N19-N18)<0,"0",(N19-N18)))*2 -> 20126 | P19: 7709448 | Q19: =IF((P19-P18)<0,"0",(P19-P18)) -> 15903 | R19: 22057106 | S19: =IF((R19-R18)<0,"0",(R19-R18)) -> 12260 | T19: 0 | V19: 71657 | W19: =IF((V19-V18)<0,"0",(V19-V18)) -> 13399 | X19: =K19+M19+O19+Q19+S19+U19+W19 -> 83113 | Y19: =I19-X19 -> 8203 | Z19: =(0.93352*(W19+S19)+0.5568*(Q19+O19))*0.26 -> 11443.676 | AA19: =SUM(Z1:Z19) -> 173945.75
