Workbook

Sheet TOTAL
A1: Site Name | B1: Day | C1: Month | D1: Year | E1: Total Electricity Kwh | F1: Electricity Tariff ($/Kwh) | G1: Water Utility Supply (m3) m3 | H1: Water Utility Supply (m3) $/m3 | I1: Room Nights | J1: Total Guests | K1: Cooling Degree Day
A2: Doha | B2: 1 | C2: 9 | D2: 2022 | E2: {=0.75*INDEX('13 - Electrical Readings'!$H$8:$H$998,1+(2*(ROWS(A$1:A1)-1)))+INDEX('13 - Electrical Readings'!$Q$8:$Q$998,1+(2*(ROWS(A$1:A1)-1)))} -> 86915.25 | F2: 0.041 | G2: {=0.75*INDEX('9 - Water Readings'!$F$8:$F$998,1+(2*(ROWS(A$1:A1)-1)))+INDEX('9 - Water Readings'!$M$8:$M$998,1+(2*(ROWS(A$1:A1)-1)))} -> 390 | H2: 1.5571913 | I2: ='Submetering '!AA2 -> 99 | J2: ='Submetering '!AB2 -> 394 | K2: ='Submetering '!AC2 -> 15.1
A3: Doha | B3: =B2+1 -> 2 | C3: 9 | D3: 2022 | E3: {=0.75*INDEX('13 - Electrical Readings'!$H$8:$H$998,1+(2*(ROWS(A$1:A2)-1)))+INDEX('13 - Electrical Readings'!$Q$8:$Q$998,1+(2*(ROWS(A$1:A2)-1)))} -> 83951.75 | F3: 0.041 | G3: {=0.75*INDEX('9 - Water Readings'!$F$8:$F$998,1+(2*(ROWS(A$1:A2)-1)))+INDEX('9 - Water Readings'!$M$8:$M$998,1+(2*(ROWS(A$1:A2)-1)))} -> 381 | H3: 1.5571913 | I3: ='Submetering '!AA3 -> 114 | J3: ='Submetering '!AB3 -> 454 | K3: ='Submetering '!AC3 -> 15
A4: Doha | B4: =B3+1 -> 3 | C4: 9 | D4: 2022 | E4: {=0.75*INDEX('13 - Electrical Readings'!$H$8:$H$998,1+(2*(ROWS(A$1:A3)-1)))+INDEX('13 - Electrical Readings'!$Q$8:$Q$998,1+(2*(ROWS(A$1:A3)-1)))} -> 83720.75 | F4: 0.041 | G4: {=0.75*INDEX('9 - Water Readings'!$F$8:$F$998,1+(2*(ROWS(A$1:A3)-1)))+INDEX('9 - Water Readings'!$M$8:$M$998,1+(2*(ROWS(A$1:A3)-1)))} -> 376 | H4: 1.5571913 | I4: ='Submetering '!AA4 -> 59 | J4: ='Submetering '!AB4 -> 192 | K4: ='Submetering '!AC4 -> 14.3
A5: Doha | B5: =B4+1 -> 4 | C5: 9 | D5: 2022 | E5: {=0.75*INDEX('13 - Electrical Readings'!$H$8:$H$998,1+(2*(ROWS(A$1:A4)-1)))+INDEX('13 - Electrical Readings'!$Q$8:$Q$998,1+(2*(ROWS(A$1:A4)-1)))} -> 84745.5 | F5: 0.041 | G5: {=0.75*INDEX('9 - Water Readings'!$F$8:$F$998,1+(2*(ROWS(A$1:A4)-1)))+INDEX('9 - Water Readings'!$M$8:$M$998,1+(2*(ROWS(A$1:A4)-1)))} -> 347 | H5: 1.5571913 | I5: ='Submetering '!AA5 -> 83 | J5: ='Submetering '!AB5 -> 228 | K5: ='Submetering '!AC5 -> 14.7
A6: Doha | B6: =B5+1 -> 5 | C6: 9 | D6: 2022 | E6: {=0.75*INDEX('13 - Electrical Readings'!$H$8:$H$998,1+(2*(ROWS(A$1:A5)-1)))+INDEX('13 - Electrical Readings'!$Q$8:$Q$998,1+(2*(ROWS(A$1:A5)-1)))} -> 80595.5 | F6: 0.041 | G6: {=0.75*INDEX('9 - Water Readings'!$F$8:$F$998,1+(2*(ROWS(A$1:A5)-1)))+INDEX('9 - Water Readings'!$M$8:$M$998,1+(2*(ROWS(A$1:A5)-1)))} -> 371 | H6: 1.5571913 | I6: ='Submetering '!AA6 -> 118 | J6: ='Submetering '!AB6 -> 292 | K6: ='Submetering '!AC6 -> 15.5
A7: Doha | B7: =B6+1 -> 6 | C7: 9 | D7: 2022 | E7: {=0.75*INDEX('13 - Electrical Readings'!$H$8:$H$998,1+(2*(ROWS(A$1:A6)-1)))+INDEX('13 - Electrical Readings'!$Q$8:$Q$998,1+(2*(ROWS(A$1:A6)-1)))} -> 83657.75 | F7: 0.041 | G7: {=0.75*INDEX('9 - Water Readings'!$F$8:$F$998,1+(2*(ROWS(A$1:A6)-1)))+INDEX('9 - Water Readings'!$M$8:$M$998,1+(2*(ROWS(A$1:A6)-1)))} -> 364 | H7: 1.5571913 | I7: ='Submetering '!AA7 -> 142 | J7: ='Submetering '!AB7 -> 346 | K7: ='Submetering '!AC7 -> 15.2
A8: Doha | B8: =B7+1 -> 7 | C8: 9 | D8: 2022 | E8: {=0.75*INDEX('13 - Electrical Readings'!$H$8:$H$998,1+(2*(ROWS(A$1:A7)-1)))+INDEX('13 - Electrical Readings'!$Q$8:$Q$998,1+(2*(ROWS(A$1:A7)-1)))} -> 84518.5 | F8: 0.041 | G8: {=0.75*INDEX('9 - Water Readings'!$F$8:$F$998,1+(2*(ROWS(A$1:A7)-1)))+INDEX('9 - Water Readings'!$M$8:$M$998,1+(2*(ROWS(A$1:A7)-1)))} -> 385 | H8: 1.5571913 | I8: ='Submetering '!AA8 -> 148 | J8: ='Submetering '!AB8 -> 368 | K8: ='Submetering '!AC8 -> 14.9
A9: Doha | B9: =B8+1 -> 8 | C9: 9 | D9: 2022 | E9: {=0.75*INDEX('13 - Electrical Readings'!$H$8:$H$998,1+(2*(ROWS(A$1:A8)-1)))+INDEX('13 - Electrical Readings'!$Q$8:$Q$998,1+(2*(ROWS(A$1:A8)-1)))} -> 85850.75 | F9: 0.041 | G9: {=0.75*INDEX('9 - Water Readings'!$F$8:$F$998,1+(2*(ROWS(A$1:A8)-1)))+INDEX('9 - Water Readings'!$M$8:$M$998,1+(2*(ROWS(A$1:A8)-1)))} -> 381.25 | H9: 1.5571913 | I9: ='Submetering '!AA9 -> 214 | J9: ='Submetering '!AB9 -> 648 | K9: ='Submetering '!AC9 -> 14.4
A10: Doha | B10: =B9+1 -> 9 | C10: 9 | D10: 2022 | E10: {=0.75*INDEX('13 - Electrical Readings'!$H$8:$H$998,1+(2*(ROWS(A$1:A9)-1)))+INDEX('13 - Electrical Readings'!$Q$8:$Q$998,1+(2*(ROWS(A$1:A9)-1)))} -> 85837.5 | F10: 0.041 | G10: {=0.75*INDEX('9 - Water Readings'!$F$8:$F$998,1+(2*(ROWS(A$1:A9)-1)))+INDEX('9 - Water Readings'!$M$8:$M$998,1+(2*(ROWS(A$1:A9)-1)))} -> 416 | H10: 1.5571913 | I10: ='Submetering '!AA10 -> 206 | J10: ='Submetering '!AB10 -> 668 | K10: ='Submetering '!AC10 -> 14.1
A11: Doha | B11: =B10+1 -> 10 | C11: 9 | D11: 2022 | E11: {=0.75*INDEX('13 - Electrical Readings'!$H$8:$H$998,1+(2*(ROWS(A$1:A10)-1)))+INDEX('13 - Electrical Readings'!$Q$8:$Q$998,1+(2*(ROWS(A$1:A10)-1)))} -> 83477.5 | F11: 0.041 | G11: {=0.75*INDEX('9 - Water Readings'!$F$8:$F$998,1+(2*(ROWS(A$1:A10)-1)))+INDEX('9 - Water Readings'!$M$8:$M$998,1+(2*(ROWS(A$1:A10)-1)))} -> 402 | H11: 1.5571913 | I11: ='Submetering '!AA11 -> 132 | J11: ='Submetering '!AB11 -> 362 | K11: ='Submetering '!AC11 -> 13.9
A12: Doha | B12: =B11+1 -> 11 | C12: 9 | D12: 2022 | E12: {=0.75*INDEX('13 - Electrical Readings'!$H$8:$H$998,1+(2*(ROWS(A$1:A11)-1)))+INDEX('13 - Electrical Readings'!$Q$8:$Q$998,1+(2*(ROWS(A$1:A11)-1)))} -> 0 | F12: 0.041 | G12: {=0.75*INDEX('9 - Water Readings'!$F$8:$F$998,1+(2*(ROWS(A$1:A11)-1)))+INDEX('9 - Water Readings'!$M$8:$M$998,1+(2*(ROWS(A$1:A11)-1)))} -> 0 | H12: 1.5571913 | I12: ='Submetering '!AA12 -> 122 | J12: ='Submetering '!AB12 -> 308 | K12: ='Submetering '!AC12 -> 14.4
A13: Doha | B13: =B12+1 -> 12 | C13: 9 | D13: 2022 | E13: {=0.75*INDEX('13 - Electrical Readings'!$H$8:$H$998,1+(2*(ROWS(A$1:A12)-1)))+INDEX('13 - Electrical Readings'!$Q$8:$Q$998,1+(2*(ROWS(A$1:A12)-1)))} -> 0 | F13: 0.041 | G13: {=0.75*INDEX('9 - Water Readings'!$F$8:$F$998,1+(2*(ROWS(A$1:A12)-1)))+INDEX('9 - Water Readings'!$M$8:$M$998,1+(2*(ROWS(A$1:A12)-1)))} -> 0 | H13: 1.5571913 | I13: ='Submetering '!AA13 -> 0 | J13: ='Submetering '!AB13 -> 0 | K13: ='Submetering '!AC13 -> 0
A14: Doha | B14: =B13+1 -> 13 | C14: 9 | D14: 2022 | E14: {=0.75*INDEX('13 - Electrical Readings'!$H$8:$H$998,1+(2*(ROWS(A$1:A13)-1)))+INDEX('13 - Electrical Readings'!$Q$8:$Q$998,1+(2*(ROWS(A$1:A13)-1)))} -> 0 | F14: 0.041 | G14: {=0.75*INDEX('9 - Water Readings'!$F$8:$F$998,1+(2*(ROWS(A$1:A13)-1)))+INDEX('9 - Water Readings'!$M$8:$M$998,1+(2*(ROWS(A$1:A13)-1)))} -> 0 | H14: 1.5571913 | I14: ='Submetering '!AA14 -> 0 | J14: ='Submetering '!AB14 -> 0 | K14: ='Submetering '!AC14 -> 0
... A31: Doha | B31: =B30+1 -> 30 | C31: 9 | D31: 2022 | E31: {=0.75*INDEX('13 - Electrical Readings'!$H$8:$H$998,1+(2*(ROWS(A$1:A30)-1)))+INDEX('13 - Electrical Readings'!$Q$8:$Q$998,1+(2*(ROWS(A$1:A30)-1)))} -> 0 | F31: 0.041 | G31: {=0.75*INDEX('9 - Water Readings'!$F$8:$F$998,1+(2*(ROWS(A$1:A30)-1)))+INDEX('9 - Water Readings'!$M$8:$M$998,1+(2*(ROWS(A$1:A30)-1)))} -> 0 | H31: 1.5571913 | I31: ='Submetering '!AA31 -> 0 | J31: ='Submetering '!AB31 -> 0 | K31: ='Submetering '!AC31 -> 0

Sheet Submetering 
A1: Site Name | B1: Day | C1: Month | D1: Year | E1: CP Chillers 157691 (KWh) | F1: CP Chillers 157692 (KWh) | G1: CP Chillers 157693 (KWh) | H1: CP Chillers 157694 (KWh) | I1: CP Chillers 167609 (KWh) | J1: Town House 166443 (KWh) | K1: Hotel 157687 (KWh) | L1: Hotel 157688 (KWh) | M1: Hotel 157689 (KWh) | N1: Hotel 157690 (KWh) | O1: SPA (KWh) | P1: Marina (KWh) | Q1: Nobu (KWh) | R1: CP F/F (m3) | S1: CP Chillers (m3) | T1: CP Parking (m3) | U1: Town House (m3) | V1: Spa B (m3) | W1: Spa A (m3) | X1: CW Hotel A (m3) | Y1: CCW Hotel B (m3) | Z1: Marina (m3) | AA1: Room Nights | AB1: Total Guests | AC1: Cooling Degree Day
A2: Doha | B2: 1 | C2: 9 | D2: 2022 | E2: =INDEX('13 - Electrical Readings'!$C$8:$C$962,1+(2*(ROWS(A$1:A1)-1))) -> 18380 | F2: =INDEX('13 - Electrical Readings'!$D$6:$D$962,1+(2*(ROWS(A$1:A2)-1))) -> 8600 | G2: =INDEX('13 - Electrical Readings'!$E$6:$E$962,1+(2*(ROWS(A$1:A2)-1))) -> 18322 | H2: =INDEX('13 - Electrical Readings'!$F$6:$F$962,1+(2*(ROWS(A$1:A2)-1))) -> 9468 | I2: =INDEX('13 - Electrical Readings'!$G$6:$G$962,1+(2*(ROWS(A$1:A2)-1))) -> 17 | J2: =INDEX('13 - Electrical Readings'!$I$6:$I$962,1+(2*(ROWS(A$1:A2)-1))) -> 2506 | K2: =INDEX('13 - Electrical Readings'!$J$6:$J$962,1+(2*(ROWS(B$1:B2)-1))) -> 9153 | L2: =INDEX('13 - Electrical Readings'!$K$6:$K$962,1+(2*(ROWS(C$1:C2)-1))) -> 3321 | M2: =INDEX('13 - Electrical Readings'!$L$6:$L$962,1+(2*(ROWS(D$1:D2)-1))) -> 4438 | N2: =INDEX('13 - Electrical Readings'!$M$6:$M$962,1+(2*(ROWS(E$1:E2)-1))) -> 10695 | O2: =INDEX('13 - Electrical Readings'!$N$6:$N$962,1+(2*(ROWS(E$1:E2)-1))) -> 8792 | P2: =INDEX('13 - Electrical Readings'!$O$6:$O$962,1+(2*(ROWS(E$1:E2)-1))) -> 4020 | Q2: =INDEX('13 - Electrical Readings'!$P$6:$P$962,1+(2*(ROWS(E$1:E2)-1))) -> 2900 | R2: =INDEX('9 - Water Readings'!$C$8:$C$966,1+(2*(ROWS(A$1:A1)-1))) -> 0 | S2: =INDEX('9 - Water Readings'!$D$8:$D$965,1+(2*(ROWS(A$1:A1)-1))) -> 0 | T2: =INDEX('9 - Water Readings'!$E$8:$E$966,1+(2*(ROWS(A$1:A1)-1))) -> 0 | U2: =INDEX('9 - Water Readings'!$G$8:$G$965,1+(2*(ROWS(A$1:A1)-1))) -> 113 | V2: =INDEX('9 - Water Readings'!$H$8:$H$966,1+(2*(ROWS(A$1:A1)-1))) -> 44 | W2: =INDEX('9 - Water Readings'!$I$8:$I$966,1+(2*(ROWS(A$1:A1)-1))) -> 0 | X2: =INDEX('9 - Water Readings'!$J$8:$J$966,1+(2*(ROWS(A$1:A1)-1))) -> 186 | Y2: =INDEX('9 - Water Readings'!$K$8:$K$966,1+(2*(ROWS(A$1:A1)-1))) -> 0 | Z2: =INDEX('9 - Water Readings'!$L$8:$L$966,1+(2*(ROWS(A$1:A1)-1))) -> 47 | AA2: ='9 - Water Readings'!Q7 -> 99 | AB2: ='9 - Water Readings'!R7 -> 394 | AC2: ='9 - Water Readings'!S7 -> 15.1
A3: Doha | B3: =B2+1 -> 2 | C3: 9 | D3: 2022 | E3: =INDEX('13 - Electrical Readings'!$C$8:$C$962,1+(2*(ROWS(A$1:A2)-1))) -> 18785 | F3: =INDEX('13 - Electrical Readings'!$D$6:$D$962,1+(2*(ROWS(A$1:A3)-1))) -> 13114 | G3: =INDEX('13 - Electrical Readings'!$E$6:$E$962,1+(2*(ROWS(A$1:A3)-1))) -> 13803 | H3: =INDEX('13 - Electrical Readings'!$F$6:$F$962,1+(2*(ROWS(A$1:A3)-1))) -> 5083 | I3: =INDEX('13 - Electrical Readings'!$G$6:$G$962,1+(2*(ROWS(A$1:A3)-1))) -> 16 | J3: =INDEX('13 - Electrical Readings'!$I$6:$I$962,1+(2*(ROWS(A$1:A3)-1))) -> 2482 | K3: =INDEX('13 - Electrical Readings'!$J$6:$J$962,1+(2*(ROWS(B$1:B3)-1))) -> 9277 | L3: =INDEX('13 - Electrical Readings'!$K$6:$K$962,1+(2*(ROWS(C$1:C3)-1))) -> 3445 | M3: =INDEX('13 - Electrical Readings'!$L$6:$L$962,1+(2*(ROWS(D$1:D3)-1))) -> 4522 | N3: =INDEX('13 - Electrical Readings'!$M$6:$M$962,1+(2*(ROWS(E$1:E3)-1))) -> 10442 | O3: =INDEX('13 - Electrical Readings'!$N$6:$N$962,1+(2*(ROWS(E$1:E3)-1))) -> 8557 | P3: =INDEX('13 - Electrical Readings'!$O$6:$O$962,1+(2*(ROWS(E$1:E3)-1))) -> 3916 | Q3: =INDEX('13 - Electrical Readings'!$P$6:$P$962,1+(2*(ROWS(E$1:E3)-1))) -> 3210 | R3: =INDEX('9 - Water Readings'!$C$8:$C$966,1+(2*(ROWS(A$1:A2)-1))) -> 0 | S3: =INDEX('9 - Water Readings'!$D$8:$D$965,1+(2*(ROWS(A$1:A2)-1))) -> 0 | T3: =INDEX('9 - Water Readings'!$E$8:$E$966,1+(2*(ROWS(A$1:A2)-1))) -> 0 | U3: =INDEX('9 - Water Readings'!$G$8:$G$965,1+(2*(ROWS(A$1:A2)-1))) -> 109 | V3: =INDEX('9 - Water Readings'!$H$8:$H$966,1+(2*(ROWS(A$1:A2)-1))) -> 13 | W3: =INDEX('9 - Water Readings'!$I$8:$I$966,1+(2*(ROWS(A$1:A2)-1))) -> 0 | X3: =INDEX('9 - Water Readings'!$J$8:$J$966,1+(2*(ROWS(A$1:A2)-1))) -> 221 | Y3: =INDEX('9 - Water Readings'!$K$8:$K$966,1+(2*(ROWS(A$1:A2)-1))) -> 0 | Z3: =INDEX('9 - Water Readings'!$L$8:$L$966,1+(2*(ROWS(A$1:A2)-1))) -> 38 | AA3: ='9 - Water Readings'!Q8 -> 114 | AB3: ='9 - Water Readings'!R8 -> 454 | AC3: ='9 - Water Readings'!S8 -> 15
A4: Doha | B4: =B3+1 -> 3 | C4: 9 | D4: 2022 | E4: =INDEX('13 - Electrical Readings'!$C$8:$C$962,1+(2*(ROWS(A$1:A3)-1))) -> 11212 | F4: =INDEX('13 - Electrical Readings'!$D$6:$D$962,1+(2*(ROWS(A$1:A4)-1))) -> 13846 | G4: =INDEX('13 - Electrical Readings'!$E$6:$E$962,1+(2*(ROWS(A$1:A4)-1))) -> 11473 | H4: =INDEX('13 - Electrical Readings'!$F$6:$F$962,1+(2*(ROWS(A$1:A4)-1))) -> 14230 | I4: =INDEX('13 - Electrical Readings'!$G$6:$G$962,1+(2*(ROWS(A$1:A4)-1))) -> 16 | J4: =INDEX('13 - Electrical Readings'!$I$6:$I$962,1+(2*(ROWS(A$1:A4)-1))) -> 2586 | K4: =INDEX('13 - Electrical Readings'!$J$6:$J$962,1+(2*(ROWS(B$1:B4)-1))) -> 9248 | L4: =INDEX('13 - Electrical Readings'!$K$6:$K$962,1+(2*(ROWS(C$1:C4)-1))) -> 3117 | M4: =INDEX('13 - Electrical Readings'!$L$6:$L$962,1+(2*(ROWS(D$1:D4)-1))) -> 4494 | N4: =INDEX('13 - Electrical Readings'!$M$6:$M$962,1+(2*(ROWS(E$1:E4)-1))) -> 10485 | O4: =INDEX('13 - Electrical Readings'!$N$6:$N$962,1+(2*(ROWS(E$1:E4)-1))) -> 8793 | P4: =INDEX('13 - Electrical Readings'!$O$6:$O$962,1+(2*(ROWS(E$1:E4)-1))) -> 3995 | Q4: =INDEX('13 - Electrical Readings'!$P$6:$P$962,1+(2*(ROWS(E$1:E4)-1))) -> 2920 | R4: =INDEX('9 - Water Readings'!$C$8:$C$966,1+(2*(ROWS(A$1:A3)-1))) -> 0 | S4: =INDEX('9 - Water Readings'!$D$8:$D$965,1+(2*(ROWS(A$1:A3)-1))) -> 0 | T4: =INDEX('9 - Water Readings'!$E$8:$E$966,1+(2*(ROWS(A$1:A3)-1))) -> 0 | U4: =INDEX('9 - Water Readings'!$G$8:$G$965,1+(2*(ROWS(A$1:A3)-1))) -> 117 | V4: =INDEX('9 - Water Readings'!$H$8:$H$966,1+(2*(ROWS(A$1:A3)-1))) -> 14 | W4: =INDEX('9 - Water Readings'!$I$8:$I$966,1+(2*(ROWS(A$1:A3)-1))) -> 0 | X4: =INDEX('9 - Water Readings'!$J$8:$J$966,1+(2*(ROWS(A$1:A3)-1))) -> 200 | Y4: =INDEX('9 - Water Readings'!$K$8:$K$966,1+(2*(ROWS(A$1:A3)-1))) -> 0 | Z4: =INDEX('9 - Water Readings'!$L$8:$L$966,1+(2*(ROWS(A$1:A3)-1))) -> 45 | AA4: ='9 - Water Readings'!Q9 -> 59 | AB4: ='9 - Water Readings'!R9 -> 192 | AC4: ='9 - Water Readings'!S9 -> 14.3
A5: Doha | B5: =B4+1 -> 4 | C5: 9 | D5: 2022 | E5: =INDEX('13 - Electrical Readings'!$C$8:$C$962,1+(2*(ROWS(A$1:A4)-1))) -> 7478 | F5: =INDEX('13 - Electrical Readings'!$D$6:$D$962,1+(2*(ROWS(A$1:A5)-1))) -> 13446 | G5: =INDEX('13 - Electrical Readings'!$E$6:$E$962,1+(2*(ROWS(A$1:A5)-1))) -> 14634 | H5: =INDEX('13 - Electrical Readings'!$F$6:$F$962,1+(2*(ROWS(A$1:A5)-1))) -> 17288 | I5: =INDEX('13 - Electrical Readings'!$G$6:$G$962,1+(2*(ROWS(A$1:A5)-1))) -> 16 | J5: =INDEX('13 - Electrical Readings'!$I$6:$I$962,1+(2*(ROWS(A$1:A5)-1))) -> 2635 | K5: =INDEX('13 - Electrical Readings'!$J$6:$J$962,1+(2*(ROWS(B$1:B5)-1))) -> 9143 | L5: =INDEX('13 - Electrical Readings'!$K$6:$K$962,1+(2*(ROWS(C$1:C5)-1))) -> 3090 | M5: =INDEX('13 - Electrical Readings'!$L$6:$L$962,1+(2*(ROWS(D$1:D5)-1))) -> 4384 | N5: =INDEX('13 - Electrical Readings'!$M$6:$M$962,1+(2*(ROWS(E$1:E5)-1))) -> 10662 | O5: =INDEX('13 - Electrical Readings'!$N$6:$N$962,1+(2*(ROWS(E$1:E5)-1))) -> 8580 | P5: =INDEX('13 - Electrical Readings'!$O$6:$O$962,1+(2*(ROWS(E$1:E5)-1))) -> 4195 | Q5: =INDEX('13 - Electrical Readings'!$P$6:$P$962,1+(2*(ROWS(E$1:E5)-1))) -> 2410 | R5: =INDEX('9 - Water Readings'!$C$8:$C$966,1+(2*(ROWS(A$1:A4)-1))) -> 0 | S5: =INDEX('9 - Water Readings'!$D$8:$D$965,1+(2*(ROWS(A$1:A4)-1))) -> 0 | T5: =INDEX('9 - Water Readings'!$E$8:$E$966,1+(2*(ROWS(A$1:A4)-1))) -> 0 | U5: =INDEX('9 - Water Readings'!$G$8:$G$965,1+(2*(ROWS(A$1:A4)-1))) -> 116 | V5: =INDEX('9 - Water Readings'!$H$8:$H$966,1+(2*(ROWS(A$1:A4)-1))) -> 13 | W5: =INDEX('9 - Water Readings'!$I$8:$I$966,1+(2*(ROWS(A$1:A4)-1))) -> 0 | X5: =INDEX('9 - Water Readings'!$J$8:$J$966,1+(2*(ROWS(A$1:A4)-1))) -> 180 | Y5: =INDEX('9 - Water Readings'!$K$8:$K$966,1+(2*(ROWS(A$1:A4)-1))) -> 0 | Z5: =INDEX('9 - Water Readings'!$L$8:$L$966,1+(2*(ROWS(A$1:A4)-1))) -> 38 | AA5: ='9 - Water Readings'!Q10 -> 83 | AB5: ='9 - Water Readings'!R10 -> 228 | AC5: ='9 - Water Readings'!S10 -> 14.7
A6: Doha | B6: =B5+1 -> 5 | C6: 9 | D6: 2022 | E6: =INDEX('13 - Electrical Readings'!$C$8:$C$962,1+(2*(ROWS(A$1:A5)-1))) -> 3 | F6: =INDEX('13 - Electrical Readings'!$D$6:$D$962,1+(2*(ROWS(A$1:A6)-1))) -> 13611 | G6: =INDEX('13 - Electrical Readings'!$E$6:$E$962,1+(2*(ROWS(A$1:A6)-1))) -> 18931 | H6: =INDEX('13 - Electrical Readings'!$F$6:$F$962,1+(2*(ROWS(A$1:A6)-1))) -> 14853 | I6: =INDEX('13 - Electrical Readings'!$G$6:$G$962,1+(2*(ROWS(A$1:A6)-1))) -> 12 | J6: =INDEX('13 - Electrical Readings'!$I$6:$I$962,1+(2*(ROWS(A$1:A6)-1))) -> 2684 | K6: =INDEX('13 - Electrical Readings'!$J$6:$J$962,1+(2*(ROWS(B$1:B6)-1))) -> 8924 | L6: =INDEX('13 - Electrical Readings'!$K$6:$K$962,1+(2*(ROWS(C$1:C6)-1))) -> 3183 | M6: =INDEX('13 - Electrical Readings'!$L$6:$L$962,1+(2*(ROWS(D$1:D6)-1))) -> 4380 | N6: =INDEX('13 - Electrical Readings'!$M$6:$M$962,1+(2*(ROWS(E$1:E6)-1))) -> 10327 | O6: =INDEX('13 - Electrical Readings'!$N$6:$N$962,1+(2*(ROWS(E$1:E6)-1))) -> 8743 | P6: =INDEX('13 - Electrical Readings'!$O$6:$O$962,1+(2*(ROWS(E$1:E6)-1))) -> 4127 | Q6: =INDEX('13 - Electrical Readings'!$P$6:$P$962,1+(2*(ROWS(E$1:E6)-1))) -> 2670 | R6: =INDEX('9 - Water Readings'!$C$8:$C$966,1+(2*(ROWS(A$1:A5)-1))) -> 0 | S6: =INDEX('9 - Water Readings'!$D$8:$D$965,1+(2*(ROWS(A$1:A5)-1))) -> 0 | T6: =INDEX('9 - Water Readings'!$E$8:$E$966,1+(2*(ROWS(A$1:A5)-1))) -> 0 | U6: =INDEX('9 - Water Readings'!$G$8:$G$965,1+(2*(ROWS(A$1:A5)-1))) -> 117 | V6: =INDEX('9 - Water Readings'!$H$8:$H$966,1+(2*(ROWS(A$1:A5)-1))) -> 28 | W6: =INDEX('9 - Water Readings'!$I$8:$I$966,1+(2*(ROWS(A$1:A5)-1))) -> 0 | X6: =INDEX('9 - Water Readings'!$J$8:$J$966,1+(2*(ROWS(A$1:A5)-1))) -> 192 | Y6: =INDEX('9 - Water Readings'!$K$8:$K$966,1+(2*(ROWS(A$1:A5)-1))) -> 0 | Z6: =INDEX('9 - Water Readings'!$L$8:$L$966,1+(2*(ROWS(A$1:A5)-1))) -> 34 | AA6: ='9 - Water Readings'!Q11 -> 118 | AB6: ='9 - Water Readings'!R11 -> 292 | AC6: ='9 - Water Readings'!S11 -> 15.5
A7: Doha | B7: =B6+1 -> 6 | C7: 9 | D7: 2022 | E7: =INDEX('13 - Electrical Readings'!$C$8:$C$962,1+(2*(ROWS(A$1:A6)-1))) -> 4 | F7: =INDEX('13 - Electrical Readings'!$D$6:$D$962,1+(2*(ROWS(A$1:A7)-1))) -> 14494 | G7: =INDEX('13 - Electrical Readings'!$E$6:$E$962,1+(2*(ROWS(A$1:A7)-1))) -> 19793 | H7: =INDEX('13 - Electrical Readings'!$F$6:$F$962,1+(2*(ROWS(A$1:A7)-1))) -> 15814 | I7: =INDEX('13 - Electrical Readings'!$G$6:$G$962,1+(2*(ROWS(A$1:A7)-1))) -> 16 | J7: =INDEX('13 - Electrical Readings'!$I$6:$I$962,1+(2*(ROWS(A$1:A7)-1))) -> 2759 | K7: =INDEX('13 - Electrical Readings'!$J$6:$J$962,1+(2*(ROWS(B$1:B7)-1))) -> 9409 | L7: =INDEX('13 - Electrical Readings'!$K$6:$K$962,1+(2*(ROWS(C$1:C7)-1))) -> 3403 | M7: =INDEX('13 - Electrical Readings'!$L$6:$L$962,1+(2*(ROWS(D$1:D7)-1))) -> 4548 | N7: =INDEX('13 - Electrical Readings'!$M$6:$M$962,1+(2*(ROWS(E$1:E7)-1))) -> 10240 | O7: =INDEX('13 - Electrical Readings'!$N$6:$N$962,1+(2*(ROWS(E$1:E7)-1))) -> 9047 | P7: =INDEX('13 - Electrical Readings'!$O$6:$O$962,1+(2*(ROWS(E$1:E7)-1))) -> 3671 | Q7: =INDEX('13 - Electrical Readings'!$P$6:$P$962,1+(2*(ROWS(E$1:E7)-1))) -> 2990 | R7: =INDEX('9 - Water Readings'!$C$8:$C$966,1+(2*(ROWS(A$1:A6)-1))) -> 0 | S7: =INDEX('9 - Water Readings'!$D$8:$D$965,1+(2*(ROWS(A$1:A6)-1))) -> 0 | T7: =INDEX('9 - Water Readings'!$E$8:$E$966,1+(2*(ROWS(A$1:A6)-1))) -> 0 | U7: =INDEX('9 - Water Readings'!$G$8:$G$965,1+(2*(ROWS(A$1:A6)-1))) -> 116 | V7: =INDEX('9 - Water Readings'!$H$8:$H$966,1+(2*(ROWS(A$1:A6)-1))) -> 15 | W7: =INDEX('9 - Water Readings'!$I$8:$I$966,1+(2*(ROWS(A$1:A6)-1))) -> 0 | X7: =INDEX('9 - Water Readings'!$J$8:$J$966,1+(2*(ROWS(A$1:A6)-1))) -> 195 | Y7: =INDEX('9 - Water Readings'!$K$8:$K$966,1+(2*(ROWS(A$1:A6)-1))) -> 0 | Z7: =INDEX('9 - Water Readings'!$L$8:$L$966,1+(2*(ROWS(A$1:A6)-1))) -> 38 | AA7: ='9 - Water Readings'!Q12 -> 142 | AB7: ='9 - Water Readings'!R12 -> 346 | AC7: ='9 - Water Readings'!S12 -> 15.2
A8: Doha | B8: =B7+1 -> 7 | C8: 9 | D8: 2022 | E8: =INDEX('13 - Electrical Readings'!$C$8:$C$962,1+(2*(ROWS(A$1:A7)-1))) -> 10 | F8: =INDEX('13 - Electrical Readings'!$D$6:$D$962,1+(2*(ROWS(A$1:A8)-1))) -> 13891 | G8: =INDEX('13 - Electrical Readings'!$E$6:$E$962,1+(2*(ROWS(A$1:A8)-1))) -> 19596 | H8: =INDEX('13 - Electrical Readings'!$F$6:$F$962,1+(2*(ROWS(A$1:A8)-1))) -> 18107 | I8: =INDEX('13 - Electrical Readings'!$G$6:$G$962,1+(2*(ROWS(A$1:A8)-1))) -> 14 | J8: =INDEX('13 - Electrical Readings'!$I$6:$I$962,1+(2*(ROWS(A$1:A8)-1))) -> 2635 | K8: =INDEX('13 - Electrical Readings'!$J$6:$J$962,1+(2*(ROWS(B$1:B8)-1))) -> 9220 | L8: =INDEX('13 - Electrical Readings'!$K$6:$K$962,1+(2*(ROWS(C$1:C8)-1))) -> 3358 | M8: =INDEX('13 - Electrical Readings'!$L$6:$L$962,1+(2*(ROWS(D$1:D8)-1))) -> 4411 | N8: =INDEX('13 - Electrical Readings'!$M$6:$M$962,1+(2*(ROWS(E$1:E8)-1))) -> 10454 | O8: =INDEX('13 - Electrical Readings'!$N$6:$N$962,1+(2*(ROWS(E$1:E8)-1))) -> 8898 | P8: =INDEX('13 - Electrical Readings'!$O$6:$O$962,1+(2*(ROWS(E$1:E8)-1))) -> 3959 | Q8: =INDEX('13 - Electrical Readings'!$P$6:$P$962,1+(2*(ROWS(E$1:E8)-1))) -> 2870 | R8: =INDEX('9 - Water Readings'!$C$8:$C$966,1+(2*(ROWS(A$1:A7)-1))) -> 0 | S8: =INDEX('9 - Water Readings'!$D$8:$D$965,1+(2*(ROWS(A$1:A7)-1))) -> 0 | T8: =INDEX('9 - Water Readings'!$E$8:$E$966,1+(2*(ROWS(A$1:A7)-1))) -> 0 | U8: =INDEX('9 - Water Readings'!$G$8:$G$965,1+(2*(ROWS(A$1:A7)-1))) -> 113 | V8: =INDEX('9 - Water Readings'!$H$8:$H$966,1+(2*(ROWS(A$1:A7)-1))) -> 21 | W8: =INDEX('9 - Water Readings'!$I$8:$I$966,1+(2*(ROWS(A$1:A7)-1))) -> 0 | X8: =INDEX('9 - Water Readings'!$J$8:$J$966,1+(2*(ROWS(A$1:A7)-1))) -> 207 | Y8: =INDEX('9 - Water Readings'!$K$8:$K$966,1+(2*(ROWS(A$1:A7)-1))) -> 0 | Z8: =INDEX('9 - Water Readings'!$L$8:$L$966,1+(2*(ROWS(A$1:A7)-1))) -> 44 | AA8: ='9 - Water Readings'!Q13 -> 148 | AB8: ='9 - Water Readings'!R13 -> 368 | AC8: ='9 - Water Readings'!S13 -> 14.9
A9: Doha | B9: =B8+1 -> 8 | C9: 9 | D9: 2022 | E9: =INDEX('13 - Electrical Readings'!$C$8:$C$962,1+(2*(ROWS(A$1:A8)-1))) -> 5 | F9: =INDEX('13 - Electrical Readings'!$D$6:$D$962,1+(2*(ROWS(A$1:A9)-1))) -> 13956 | G9: =INDEX('13 - Electrical Readings'!$E$6:$E$962,1+(2*(ROWS(A$1:A9)-1))) -> 19713 | H9: =INDEX('13 - Electrical Readings'!$F$6:$F$962,1+(2*(ROWS(A$1:A9)-1))) -> 18154 | I9: =INDEX('13 - Electrical Readings'!$G$6:$G$962,1+(2*(ROWS(A$1:A9)-1))) -> 13 | J9: =INDEX('13 - Electrical Readings'!$I$6:$I$962,1+(2*(ROWS(A$1:A9)-1))) -> 2568 | K9: =INDEX('13 - Electrical Readings'!$J$6:$J$962,1+(2*(ROWS(B$1:B9)-1))) -> 9349 | L9: =INDEX('13 - Electrical Readings'!$K$6:$K$962,1+(2*(ROWS(C$1:C9)-1))) -> 3456 | M9: =INDEX('13 - Electrical Readings'!$L$6:$L$962,1+(2*(ROWS(D$1:D9)-1))) -> 4501 | N9: =INDEX('13 - Electrical Readings'!$M$6:$M$962,1+(2*(ROWS(E$1:E9)-1))) -> 10645 | O9: =INDEX('13 - Electrical Readings'!$N$6:$N$962,1+(2*(ROWS(E$1:E9)-1))) -> 8867 | P9: =INDEX('13 - Electrical Readings'!$O$6:$O$962,1+(2*(ROWS(E$1:E9)-1))) -> 4624 | Q9: =INDEX('13 - Electrical Readings'!$P$6:$P$962,1+(2*(ROWS(E$1:E9)-1))) -> 2960 | R9: =INDEX('9 - Water Readings'!$C$8:$C$966,1+(2*(ROWS(A$1:A8)-1))) -> 3 | S9: =INDEX('9 - Water Readings'!$D$8:$D$965,1+(2*(ROWS(A$1:A8)-1))) -> 0 | T9: =INDEX('9 - Water Readings'!$E$8:$E$966,1+(2*(ROWS(A$1:A8)-1))) -> 0 | U9: =INDEX('9 - Water Readings'!$G$8:$G$965,1+(2*(ROWS(A$1:A8)-1))) -> 118 | V9: =INDEX('9 - Water Readings'!$H$8:$H$966,1+(2*(ROWS(A$1:A8)-1))) -> 10 | W9: =INDEX('9 - Water Readings'!$I$8:$I$966,1+(2*(ROWS(A$1:A8)-1))) -> 0 | X9: =INDEX('9 - Water Readings'!$J$8:$J$966,1+(2*(ROWS(A$1:A8)-1))) -> 206 | Y9: =INDEX('9 - Water Readings'!$K$8:$K$966,1+(2*(ROWS(A$1:A8)-1))) -> 0 | Z9: =INDEX('9 - Water Readings'!$L$8:$L$966,1+(2*(ROWS(A$1:A8)-1))) -> 45 | AA9: ='9 - Water Readings'!Q14 -> 214 | AB9: ='9 - Water Readings'!R14 -> 648 | AC9: ='9 - Water Readings'!S14 -> 14.4
A10: Doha | B10: =B9+1 -> 9 | C10: 9 | D10: 2022 | E10: =INDEX('13 - Electrical Readings'!$C$8:$C$962,1+(2*(ROWS(A$1:A9)-1))) -> 5 | F10: =INDEX('13 - Electrical Readings'!$D$6:$D$962,1+(2*(ROWS(A$1:A10)-1))) -> 13717 | G10: =INDEX('13 - Electrical Readings'!$E$6:$E$962,1+(2*(ROWS(A$1:A10)-1))) -> 19521 | H10: =INDEX('13 - Electrical Readings'!$F$6:$F$962,1+(2*(ROWS(A$1:A10)-1))) -> 18003 | I10: =INDEX('13 - Electrical Readings'!$G$6:$G$962,1+(2*(ROWS(A$1:A10)-1))) -> 16 | J10: =INDEX('13 - Electrical Readings'!$I$6:$I$962,1+(2*(ROWS(A$1:A10)-1))) -> 2578 | K10: =INDEX('13 - Electrical Readings'!$J$6:$J$962,1+(2*(ROWS(B$1:B10)-1))) -> 9501 | L10: =INDEX('13 - Electrical Readings'!$K$6:$K$962,1+(2*(ROWS(C$1:C10)-1))) -> 3750 | M10: =INDEX('13 - Electrical Readings'!$L$6:$L$962,1+(2*(ROWS(D$1:D10)-1))) -> 4532 | N10: =INDEX('13 - Electrical Readings'!$M$6:$M$962,1+(2*(ROWS(E$1:E10)-1))) -> 10604 | O10: =INDEX('13 - Electrical Readings'!$N$6:$N$962,1+(2*(ROWS(E$1:E10)-1))) -> 8933 | P10: =INDEX('13 - Electrical Readings'!$O$6:$O$962,1+(2*(ROWS(E$1:E10)-1))) -> 4383 | Q10: =INDEX('13 - Electrical Readings'!$P$6:$P$962,1+(2*(ROWS(E$1:E10)-1))) -> 3110 | R10: =INDEX('9 - Water Readings'!$C$8:$C$966,1+(2*(ROWS(A$1:A9)-1))) -> 0 | S10: =INDEX('9 - Water Readings'!$D$8:$D$965,1+(2*(ROWS(A$1:A9)-1))) -> 0 | T10: =INDEX('9 - Water Readings'!$E$8:$E$966,1+(2*(ROWS(A$1:A9)-1))) -> 0 | U10: =INDEX('9 - Water Readings'!$G$8:$G$965,1+(2*(ROWS(A$1:A9)-1))) -> 112 | V10: =INDEX('9 - Water Readings'!$H$8:$H$966,1+(2*(ROWS(A$1:A9)-1))) -> 20 | W10: =INDEX('9 - Water Readings'!$I$8:$I$966,1+(2*(ROWS(A$1:A9)-1))) -> 0 | X10: =INDEX('9 - Water Readings'!$J$8:$J$966,1+(2*(ROWS(A$1:A9)-1))) -> 236 | Y10: =INDEX('9 - Water Readings'!$K$8:$K$966,1+(2*(ROWS(A$1:A9)-1))) -> 0 | Z10: =INDEX('9 - Water Readings'!$L$8:$L$966,1+(2*(ROWS(A$1:A9)-1))) -> 48 | AA10: ='9 - Water Readings'!Q15 -> 206 | AB10: ='9 - Water Readings'!R15 -> 668 | AC10: ='9 - Water Readings'!S15 -> 14.1
A11: Doha | B11: =B10+1 -> 10 | C11: 9 | D11: 2022 | E11: =INDEX('13 - Electrical Readings'!$C$8:$C$962,1+(2*(ROWS(A$1:A10)-1))) -> 6 | F11: =INDEX('13 - Electrical Readings'!$D$6:$D$962,1+(2*(ROWS(A$1:A11)-1))) -> 13511 | G11: =INDEX('13 - Electrical Readings'!$E$6:$E$962,1+(2*(ROWS(A$1:A11)-1))) -> 19220 | H11: =INDEX('13 - Electrical Readings'!$F$6:$F$962,1+(2*(ROWS(A$1:A11)-1))) -> 17684 | I11: =INDEX('13 - Electrical Readings'!$G$6:$G$962,1+(2*(ROWS(A$1:A11)-1))) -> 13 | J11: =INDEX('13 - Electrical Readings'!$I$6:$I$962,1+(2*(ROWS(A$1:A11)-1))) -> 2494 | K11: =INDEX('13 - Electrical Readings'!$J$6:$J$962,1+(2*(ROWS(B$1:B11)-1))) -> 9281 | L11: =INDEX('13 - Electrical Readings'!$K$6:$K$962,1+(2*(ROWS(C$1:C11)-1))) -> 3375 | M11: =INDEX('13 - Electrical Readings'!$L$6:$L$962,1+(2*(ROWS(D$1:D11)-1))) -> 4409 | N11: =INDEX('13 - Electrical Readings'!$M$6:$M$962,1+(2*(ROWS(E$1:E11)-1))) -> 10470 | O11: =INDEX('13 - Electrical Readings'!$N$6:$N$962,1+(2*(ROWS(E$1:E11)-1))) -> 8769 | P11: =INDEX('13 - Electrical Readings'!$O$6:$O$962,1+(2*(ROWS(E$1:E11)-1))) -> 4204 | Q11: =INDEX('13 - Electrical Readings'!$P$6:$P$962,1+(2*(ROWS(E$1:E11)-1))) -> 2650 | R11: =INDEX('9 - Water Readings'!$C$8:$C$966,1+(2*(ROWS(A$1:A10)-1))) -> 0 | S11: =INDEX('9 - Water Readings'!$D$8:$D$965,1+(2*(ROWS(A$1:A10)-1))) -> 0 | T11: =INDEX('9 - Water Readings'!$E$8:$E$966,1+(2*(ROWS(A$1:A10)-1))) -> 0 | U11: =INDEX('9 - Water Readings'!$G$8:$G$965,1+(2*(ROWS(A$1:A10)-1))) -> 112 | V11: =INDEX('9 - Water Readings'!$H$8:$H$966,1+(2*(ROWS(A$1:A10)-1))) -> 21 | W11: =INDEX('9 - Water Readings'!$I$8:$I$966,1+(2*(ROWS(A$1:A10)-1))) -> 0 | X11: =INDEX('9 - Water Readings'!$J$8:$J$966,1+(2*(ROWS(A$1:A10)-1))) -> 229 | Y11: =INDEX('9 - Water Readings'!$K$8:$K$966,1+(2*(ROWS(A$1:A10)-1))) -> 0 | Z11: =INDEX('9 - Water Readings'!$L$8:$L$966,1+(2*(ROWS(A$1:A10)-1))) -> 40 | AA11: ='9 - Water Readings'!Q16 -> 132 | AB11: ='9 - Water Readings'!R16 -> 362 | AC11: ='9 - Water Readings'!S16 -> 13.9
A12: Doha | B12: =B11+1 -> 11 | C12: 9 | D12: 2022 | E12: =INDEX('13 - Electrical Readings'!$C$8:$C$962,1+(2*(ROWS(A$1:A11)-1))) -> 0 | F12: =INDEX('13 - Electrical Readings'!$D$6:$D$962,1+(2*(ROWS(A$1:A12)-1))) -> 0 | G12: =INDEX('13 - Electrical Readings'!$E$6:$E$962,1+(2*(ROWS(A$1:A12)-1))) -> 0 | H12: =INDEX('13 - Electrical Readings'!$F$6:$F$962,1+(2*(ROWS(A$1:A12)-1))) -> 0 | I12: =INDEX('13 - Electrical Readings'!$G$6:$G$962,1+(2*(ROWS(A$1:A12)-1))) -> 0 | J12: =INDEX('13 - Electrical Readings'!$I$6:$I$962,1+(2*(ROWS(A$1:A12)-1))) -> 0 | K12: =INDEX('13 - Electrical Readings'!$J$6:$J$962,1+(2*(ROWS(B$1:B12)-1))) -> 0 | L12: =INDEX('13 - Electrical Readings'!$K$6:$K$962,1+(2*(ROWS(C$1:C12)-1))) -> 0 | M12: =INDEX('13 - Electrical Readings'!$L$6:$L$962,1+(2*(ROWS(D$1:D12)-1))) -> 0 | N12: =INDEX('13 - Electrical Readings'!$M$6:$M$962,1+(2*(ROWS(E$1:E12)-1))) -> 0 | O12: =INDEX('13 - Electrical Readings'!$N$6:$N$962,1+(2*(ROWS(E$1:E12)-1))) -> 0 | P12: =INDEX('13 - Electrical Readings'!$O$6:$O$962,1+(2*(ROWS(E$1:E12)-1))) -> 0 | Q12: =INDEX('13 - Electrical Readings'!$P$6:$P$962,1+(2*(ROWS(E$1:E12)-1))) -> 0 | R12: =INDEX('9 - Water Readings'!$C$8:$C$966,1+(2*(ROWS(A$1:A11)-1))) -> 0 | S12: =INDEX('9 - Water Readings'!$D$8:$D$965,1+(2*(ROWS(A$1:A11)-1))) -> 0 | T12: =INDEX('9 - Water Readings'!$E$8:$E$966,1+(2*(ROWS(A$1:A11)-1))) -> 0 | U12: =INDEX('9 - Water Readings'!$G$8:$G$965,1+(2*(ROWS(A$1:A11)-1))) -> 0 | V12: =INDEX('9 - Water Readings'!$H$8:$H$966,1+(2*(ROWS(A$1:A11)-1))) -> 0 | W12: =INDEX('9 - Water Readings'!$I$8:$I$966,1+(2*(ROWS(A$1:A11)-1))) -> 0 | X12: =INDEX('9 - Water Readings'!$J$8:$J$966,1+(2*(ROWS(A$1:A11)-1))) -> 0 | Y12: =INDEX('9 - Water Readings'!$K$8:$K$966,1+(2*(ROWS(A$1:A11)-1))) -> 0 | Z12: =INDEX('9 - Water Readings'!$L$8:$L$966,1+(2*(ROWS(A$1:A11)-1))) -> 0 | AA12: ='9 - Water Readings'!Q17 -> 122 | AB12: ='9 - Water Readings'!R17 -> 308 | AC12: ='9 - Water Readings'!S17 -> 14.4
A13: Doha | B13: =B12+1 -> 12 | C13: 9 | D13: 2022 | E13: =INDEX('13 - Electrical Readings'!$C$8:$C$962,1+(2*(ROWS(A$1:A12)-1))) -> 0 | F13: =INDEX('13 - Electrical Readings'!$D$6:$D$962,1+(2*(ROWS(A$1:A13)-1))) -> 0 | G13: =INDEX('13 - Electrical Readings'!$E$6:$E$962,1+(2*(ROWS(A$1:A13)-1))) -> 0 | H13: =INDEX('13 - Electrical Readings'!$F$6:$F$962,1+(2*(ROWS(A$1:A13)-1))) -> 0 | I13: =INDEX('13 - Electrical Readings'!$G$6:$G$962,1+(2*(ROWS(A$1:A13)-1))) -> 0 | J13: =INDEX('13 - Electrical Readings'!$I$6:$I$962,1+(2*(ROWS(A$1:A13)-1))) -> 0 | K13: =INDEX('13 - Electrical Readings'!$J$6:$J$962,1+(2*(ROWS(B$1:B13)-1))) -> 0 | L13: =INDEX('13 - Electrical Readings'!$K$6:$K$962,1+(2*(ROWS(C$1:C13)-1))) -> 0 | M13: =INDEX('13 - Electrical Readings'!$L$6:$L$962,1+(2*(ROWS(D$1:D13)-1))) -> 0 | N13: =INDEX('13 - Electrical Readings'!$M$6:$M$962,1+(2*(ROWS(E$1:E13)-1))) -> 0 | O13: =INDEX('13 - Electrical Readings'!$N$6:$N$962,1+(2*(ROWS(E$1:E13)-1))) -> 0 | P13: =INDEX('13 - Electrical Readings'!$O$6:$O$962,1+(2*(ROWS(E$1:E13)-1))) -> 0 | Q13: =INDEX('13 - Electrical Readings'!$P$6:$P$962,1+(2*(ROWS(E$1:E13)-1))) -> 0 | R13: =INDEX('9 - Water Readings'!$C$8:$C$966,1+(2*(ROWS(A$1:A12)-1))) -> 0 | S13: =INDEX('9 - Water Readings'!$D$8:$D$965,1+(2*(ROWS(A$1:A12)-1))) -> 0 | T13: =INDEX('9 - Water Readings'!$E$8:$E$966,1+(2*(ROWS(A$1:A12)-1))) -> 0 | U13: =INDEX('9 - Water Readings'!$G$8:$G$965,1+(2*(ROWS(A$1:A12)-1))) -> 0 | V13: =INDEX('9 - Water Readings'!$H$8:$H$966,1+(2*(ROWS(A$1:A12)-1))) -> 0 | W13: =INDEX('9 - Water Readings'!$I$8:$I$966,1+(2*(ROWS(A$1:A12)-1))) -> 0 | X13: =INDEX('9 - Water Readings'!$J$8:$J$966,1+(2*(ROWS(A$1:A12)-1))) -> 0 | Y13: =INDEX('9 - Water Readings'!$K$8:$K$966,1+(2*(ROWS(A$1:A12)-1))) -> 0 | Z13: =INDEX('9 - Water Readings'!$L$8:$L$966,1+(2*(ROWS(A$1:A12)-1))) -> 0 | AA13: ='9 - Water Readings'!Q18 -> 0 | AB13: ='9 - Water Readings'!R18 -> 0 | AC13: ='9 - Water Readings'!S18 -> 0
A14: Doha | B14: =B13+1 -> 13 | C14: 9 | D14: 2022 | E14: =INDEX('13 - Electrical Readings'!$C$8:$C$962,1+(2*(ROWS(A$1:A13)-1))) -> 0 | F14: =INDEX('13 - Electrical Readings'!$D$6:$D$962,1+(2*(ROWS(A$1:A14)-1))) -> 0 | G14: =INDEX('13 - Electrical Readings'!$E$6:$E$962,1+(2*(ROWS(A$1:A14)-1))) -> 0 | H14: =INDEX('13 - Electrical Readings'!$F$6:$F$962,1+(2*(ROWS(A$1:A14)-1))) -> 0 | I14: =INDEX('13 - Electrical Readings'!$G$6:$G$962,1+(2*(ROWS(A$1:A14)-1))) -> 0 | J14: =INDEX('13 - Electrical Readings'!$I$6:$I$962,1+(2*(ROWS(A$1:A14)-1))) -> 0 | K14: =INDEX('13 - Electrical Readings'!$J$6:$J$962,1+(2*(ROWS(B$1:B14)-1))) -> 0 | L14: =INDEX('13 - Electrical Readings'!$K$6:$K$962,1+(2*(ROWS(C$1:C14)-1))) -> 0 | M14: =INDEX('13 - Electrical Readings'!$L$6:$L$962,1+(2*(ROWS(D$1:D14)-1))) -> 0 | N14: =INDEX('13 - Electrical Readings'!$M$6:$M$962,1+(2*(ROWS(E$1:E14)-1))) -> 0 | O14: =INDEX('13 - Electrical Readings'!$N$6:$N$962,1+(2*(ROWS(E$1:E14)-1))) -> 0 | P14: =INDEX('13 - Electrical Readings'!$O$6:$O$962,1+(2*(ROWS(E$1:E14)-1))) -> 0 | Q14: =INDEX('13 - Electrical Readings'!$P$6:$P$962,1+(2*(ROWS(E$1:E14)-1))) -> 0 | R14: =INDEX('9 - Water Readings'!$C$8:$C$966,1+(2*(ROWS(A$1:A13)-1))) -> 0 | S14: =INDEX('9 - Water Readings'!$D$8:$D$965,1+(2*(ROWS(A$1:A13)-1))) -> 0 | T14: =INDEX('9 - Water Readings'!$E$8:$E$966,1+(2*(ROWS(A$1:A13)-1))) -> 0 | U14: =INDEX('9 - Water Readings'!$G$8:$G$965,1+(2*(ROWS(A$1:A13)-1))) -> 0 | V14: =INDEX('9 - Water Readings'!$H$8:$H$966,1+(2*(ROWS(A$1:A13)-1))) -> 0 | W14: =INDEX('9 - Water Readings'!$I$8:$I$966,1+(2*(ROWS(A$1:A13)-1))) -> 0 | X14: =INDEX('9 - Water Readings'!$J$8:$J$966,1+(2*(ROWS(A$1:A13)-1))) -> 0 | Y14: =INDEX('9 - Water Readings'!$K$8:$K$966,1+(2*(ROWS(A$1:A13)-1))) -> 0 | Z14: =INDEX('9 - Water Readings'!$L$8:$L$966,1+(2*(ROWS(A$1:A13)-1))) -> 0 | AA14: ='9 - Water Readings'!Q19 -> 0 | AB14: ='9 - Water Readings'!R19 -> 0 | AC14: ='9 - Water Readings'!S19 -> 0
... A31: Doha | B31: =B30+1 -> 30 | C31: 9 | D31: 2022 | E31: =INDEX('13 - Electrical Readings'!$C$8:$C$962,1+(2*(ROWS(A$1:A30)-1))) -> 0 | F31: =INDEX('13 - Electrical Readings'!$D$6:$D$962,1+(2*(ROWS(A$1:A31)-1))) -> 0 | G31: =INDEX('13 - Electrical Readings'!$E$6:$E$962,1+(2*(ROWS(A$1:A31)-1))) -> 0 | H31: =INDEX('13 - Electrical Readings'!$F$6:$F$962,1+(2*(ROWS(A$1:A31)-1))) -> 0 | I31: =INDEX('13 - Electrical Readings'!$G$6:$G$962,1+(2*(ROWS(A$1:A31)-1))) -> 0 | J31: =INDEX('13 - Electrical Readings'!$I$6:$I$962,1+(2*(ROWS(A$1:A31)-1))) -> 0 | K31: =INDEX('13 - Electrical Readings'!$J$6:$J$962,1+(2*(ROWS(B$1:B31)-1))) -> 0 | L31: =INDEX('13 - Electrical Readings'!$K$6:$K$962,1+(2*(ROWS(C$1:C31)-1))) -> 0 | M31: =INDEX('13 - Electrical Readings'!$L$6:$L$962,1+(2*(ROWS(D$1:D31)-1))) -> 0 | N31: =INDEX('13 - Electrical Readings'!$M$6:$M$962,1+(2*(ROWS(E$1:E31)-1))) -> 0 | O31: =INDEX('13 - Electrical Readings'!$N$6:$N$962,1+(2*(ROWS(E$1:E31)-1))) -> 0 | P31: =INDEX('13 - Electrical Readings'!$O$6:$O$962,1+(2*(ROWS(E$1:E31)-1))) -> 0 | Q31: =INDEX('13 - Electrical Readings'!$P$6:$P$962,1+(2*(ROWS(E$1:E31)-1))) -> 0 | R31: =INDEX('9 - Water Readings'!$C$8:$C$966,1+(2*(ROWS(A$1:A30)-1))) -> 0 | S31: =INDEX('9 - Water Readings'!$D$8:$D$965,1+(2*(ROWS(A$1:A30)-1))) -> 0 | T31: =INDEX('9 - Water Readings'!$E$8:$E$966,1+(2*(ROWS(A$1:A30)-1))) -> 0 | U31: =INDEX('9 - Water Readings'!$G$8:$G$965,1+(2*(ROWS(A$1:A30)-1))) -> 0 | V31: =INDEX('9 - Water Readings'!$H$8:$H$966,1+(2*(ROWS(A$1:A30)-1))) -> 0 | W31: =INDEX('9 - Water Readings'!$I$8:$I$966,1+(2*(ROWS(A$1:A30)-1))) -> 0 | X31: =INDEX('9 - Water Readings'!$J$8:$J$966,1+(2*(ROWS(A$1:A30)-1))) -> 0 | Y31: =INDEX('9 - Water Readings'!$K$8:$K$966,1+(2*(ROWS(A$1:A30)-1))) -> 0 | Z31: =INDEX('9 - Water Readings'!$L$8:$L$966,1+(2*(ROWS(A$1:A30)-1))) -> 0 | AA31: ='9 - Water Readings'!Q36 -> 0 | AB31: ='9 - Water Readings'!R36 -> 0 | AC31: ='9 - Water Readings'!S36 -> 0

Sheet 13 - Electrical Readings
F2: Central Plant Engineering
F3: Daily Electrical Meter Readings | N3: Month: SEPTEMBER- 2022
B5: Date | C5: CP Chillers | D5: CP Chillers | E5: CP Chillers | F5: CP Chillers | G5: CP Chillers | H5: CP Total kWh | I5: Town House | J5: Hotel | K5: Hotel | L5: Hotel | M5: Hotel | N5: Spa | O5: Marina | P5: Nobu | Q5: Hotel Total kWh | R5: Grand Total kWh
C6: 157691 | D6: 157692 | E6: 157693 | F6: 157694 | G6: 167609 | I6: 166443 | J6: 157687 | K6: 157688 | L6: 157689 | M6: 157690 | N6: 174390 | O6: 173992 | P6: 1180004
B7: 1 | C7: 21829683 | D7: 15456889 | E7: 28068400 | F7: 28021670 | G7: 17224562 | I7: 6241703 | J7: 27342341 | K7: 9078001 | L7: 13526898 | M7: 20396236 | N7: 26060775 | O7: 8449276 | P7: 7609670
B8: Consumption | C8: =C7-21811303 -> 18380 | D8: =D7-15448289 -> 8600 | E8: =E7-28050078 -> 18322 | F8: =F7-28012202 -> 9468 | G8: =G7-17224545 -> 17 | H8: =G8+F8+E8+D8+C8 -> 54787 | I8: =I7-6239197 -> 2506 | J8: =J7-27333188 -> 9153 | K8: =K7-9074680 -> 3321 | L8: =L7-13522460 -> 4438 | M8: =M7-20385541 -> 10695 | N8: =N7-26051983 -> 8792 | O8: =O7-8445256 -> 4020 | P8: =P7-7606770 -> 2900 | Q8: =P8+O8+N8+M8+L8+K8+J8+I8 -> 45825 | R8: =Q8+H8 -> 100612
B9: 2 | C9: 21848468 | D9: 15470003 | E9: 28082203 | F9: 28026753 | G9: 17224578 | I9: 6244185 | J9: 27351618 | K9: 9081446 | L9: 13531420 | M9: 20406678 | N9: 26069332 | O9: 8453192 | P9: 7612880
B10: Consumption | C10: =C9-C7 -> 18785 | D10: =D9-D7 -> 13114 | E10: =E9-E7 -> 13803 | F10: =F9-F7 -> 5083 | G10: =G9-G7 -> 16 | H10: =G10+F10+E10+D10+C10 -> 50801 | I10: =I9-I7 -> 2482 | J10: =J9-J7 -> 9277 | K10: =K9-K7 -> 3445 | L10: =L9-L7 -> 4522 | M10: =M9-M7 -> 10442 | N10: =N9-N7 -> 8557 | O10: =O9-O7 -> 3916 | P10: =P9-P7 -> 3210 | Q10: =P10+O10+N10+M10+L10+K10+J10+I10 -> 45851 | R10: =Q10+H10 -> 96652
B11: 3 | C11: 21859680 | D11: 15483849 | E11: 28093676 | F11: 28040983 | G11: 17224594 | I11: 6246771 | J11: 27360866 | K11: 9084563 | L11: 13535914 | M11: 20417163 | N11: 26078125 | O11: 8457187 | P11: 7615800
B12: Consumption | C12: =C11-C9 -> 11212 | D12: =D11-D9 -> 13846 | E12: =E11-E9 -> 11473 | F12: =F11-F9 -> 14230 | G12: =G11-G9 -> 16 | H12: =G12+F12+E12+D12+C12 -> 50777 | I12: =I11-I9 -> 2586 | J12: =J11-J9 -> 9248 | K12: =K11-K9 -> 3117 | L12: =L11-L9 -> 4494 | M12: =M11-M9 -> 10485 | N12: =N11-N9 -> 8793 | O12: =O11-O9 -> 3995 | P12: =P11-P9 -> 2920 | Q12: =P12+O12+N12+M12+L12+K12+J12+I12 -> 45638 | R12: =Q12+H12 -> 96415
B13: 4 | C13: 21867158 | D13: 15497295 | E13: 28108310 | F13: 28058271 | G13: 17224610 | I13: 6249406 | J13: 27370009 | K13: 9087653 | L13: 13540298 | M13: 20427825 | N13: 26086705 | O13: 8461382 | P13: 7618210
B14: Consumption | C14: =C13-C11 -> 7478 | D14: =D13-D11 -> 13446 | E14: =E13-E11 -> 14634 | F14: =F13-F11 -> 17288 | G14: =G13-G11 -> 16 | H14: =G14+F14+E14+D14+C14 -> 52862 | I14: =I13-I11 -> 2635 | J14: =J13-J11 -> 9143 | K14: =K13-K11 -> 3090 | L14: =L13-L11 -> 4384 | M14: =M13-M11 -> 10662 | N14: =N13-N11 -> 8580 | O14: =O13-O11 -> 4195 | P14: =P13-P11 -> 2410 | Q14: =P14+O14+N14+M14+L14+K14+J14+I14 -> 45099 | R14: =Q14+H14 -> 97961
B15: 5 | C15: 21867161 | D15: 15510906 | E15: 28127241 | F15: 28073124 | G15: 17224622 | I15: 6252090 | J15: 27378933 | K15: 9090836 | L15: 13544678 | M15: 20438152 | N15: 26095448 | O15: 8465509 | P15: 7620880
B16: Consumption | C16: =C15-C13 -> 3 | D16: =D15-D13 -> 13611 | E16: =E15-E13 -> 18931 | F16: =F15-F13 -> 14853 | G16: =G15-G13 -> 12 | H16: =G16+F16+E16+D16+C16 -> 47410 | I16: =I15-I13 -> 2684 | J16: =J15-J13 -> 8924 | K16: =K15-K13 -> 3183 | L16: =L15-L13 -> 4380 | M16: =M15-M13 -> 10327 | N16: =N15-N13 -> 8743 | O16: =O15-O13 -> 4127 | P16: =P15-P13 -> 2670 | Q16: =P16+O16+N16+M16+L16+K16+J16+I16 -> 45038 | R16: =Q16+H16 -> 92448
B17: 6 | C17: 21867165 | D17: 15525400 | E17: 28147034 | F17: 28088938 | G17: 17224638 | I17: 6254849 | J17: 27388342 | K17: 9094239 | L17: 13549226 | M17: 20448392 | N17: 26104495 | O17: 8469180 | P17: 7623870
B18: Consumption | C18: =C17-C15 -> 4 | D18: =D17-D15 -> 14494 | E18: =E17-E15 -> 19793 | F18: =F17-F15 -> 15814 | G18: =G17-G15 -> 16 | H18: =G18+F18+E18+D18+C18 -> 50121 | I18: =I17-I15 -> 2759 | J18: =J17-J15 -> 9409 | K18: =K17-K15 -> 3403 | L18: =L17-L15 -> 4548 | M18: =M17-M15 -> 10240 | N18: =N17-N15 -> 9047 | O18: =O17-O15 -> 3671 | P18: =P17-P15 -> 2990 | Q18: =P18+O18+N18+M18+L18+K18+J18+I18 -> 46067 | R18: =Q18+H18 -> 96188
B19: 7 | C19: 21867175 | D19: 15539291 | E19: 28166630 | F19: 28107045 | G19: 17224652 | I19: 6257484 | J19: 27397562 | K19: 9097597 | L19: 13553637 | M19: 20458846 | N19: 26113393 | O19: 8473139 | P19: 7626740
B20: Consumption | C20: =C19-C17 -> 10 | D20: =D19-D17 -> 13891 | E20: =E19-E17 -> 19596 | F20: =F19-F17 -> 18107 | G20: =G19-G17 -> 14 | H20: =G20+F20+E20+D20+C20 -> 51618 | I20: =I19-I17 -> 2635 | J20: =J19-J17 -> 9220 | K20: =K19-K17 -> 3358 | L20: =L19-L17 -> 4411 | M20: =M19-M17 -> 10454 | N20: =N19-N17 -> 8898 | O20: =O19-O17 -> 3959 | P20: =P19-P17 -> 2870 | Q20: =P20+O20+N20+M20+L20+K20+J20+I20 -> 45805 | R20: =Q20+H20 -> 97423
B21: 8 | C21: 21867180 | D21: 15553247 | E21: 28186343 | F21: 28125199 | G21: 17224665 | I21: 6260052 | J21: 27406911 | K21: 9101053 | L21: 13558138 | M21: 20469491 | N21: 26122260 | O21: 8477763 | P21: 7629700
B22: Consumption | C22: =C21-C19 -> 5 | D22: =D21-D19 -> 13956 | E22: =E21-E19 -> 19713 | F22: =F21-F19 -> 18154 | G22: =G21-G19 -> 13 | H22: =G22+F22+E22+D22+C22 -> 51841 | I22: =I21-I19 -> 2568 | J22: =J21-J19 -> 9349 | K22: =K21-K19 -> 3456 | L22: =L21-L19 -> 4501 | M22: =M21-M19 -> 10645 | N22: =N21-N19 -> 8867 | O22: =O21-O19 -> 4624 | P22: =P21-P19 -> 2960 | Q22: =P22+O22+N22+M22+L22+K22+J22+I22 -> 46970 | R22: =Q22+H22 -> 98811
B23: 9 | C23: 21867185 | D23: 15566964 | E23: 28205864 | F23: 28143202 | G23: 17224681 | I23: 6262630 | J23: 27416412 | K23: 9104803 | L23: 13562670 | M23: 20480095 | N23: 26131193 | O23: 8482146 | P23: 7632810
B24: Consumption | C24: =C23-C21 -> 5 | D24: =D23-D21 -> 13717 | E24: =E23-E21 -> 19521 | F24: =F23-F21 -> 18003 | G24: =G23-G21 -> 16 | H24: =G24+F24+E24+D24+C24 -> 51262 | I24: =I23-I21 -> 2578 | J24: =J23-J21 -> 9501 | K24: =K23-K21 -> 3750 | L24: =L23-L21 -> 4532 | M24: =M23-M21 -> 10604 | N24: =N23-N21 -> 8933 | O24: =O23-O21 -> 4383 | P24: =P23-P21 -> 3110 | Q24: =P24+O24+N24+M24+L24+K24+J24+I24 -> 47391 | R24: =Q24+H24 -> 98653
B25: 10 | C25: 21867191 | D25: 15580475 | E25: 28225084 | F25: 28160886 | G25: 17224694 | I25: 6265124 | J25: 27425693 | K25: 9108178 | L25: 13567079 | M25: 20490565 | N25: 26139962 | O25: 8486350 | P25: 7635460
B26: Consumption | C26: =C25-C23 -> 6 | D26: =D25-D23 -> 13511 | E26: =E25-E23 -> 19220 | F26: =F25-F23 -> 17684 | G26: =G25-G23 -> 13 | H26: =G26+F26+E26+D26+C26 -> 50434 | I26: =I25-I23 -> 2494 | J26: =J25-J23 -> 9281 | K26: =K25-K23 -> 3375 | L26: =L25-L23 -> 4409 | M26: =M25-M23 -> 10470 | N26: =N25-N23 -> 8769 | O26: =O25-O23 -> 4204 | P26: =P25-P23 -> 2650 | Q26: =P26+O26+N26+M26+L26+K26+J26+I26 -> 45652 | R26: =Q26+H26 -> 96086
B27: 11
B28: Consumption
B29: 12
B30: Consumption
B31: 13
B32: Consumption
B33: 14
B34: Consumption
B35: 15
B36: Consumption
B37: 16
B38: Consumption
B39: 17
B40: Consumption
B41: 18
B42: Consumption
...

Sheet 9 - Water Readings
F2: Central Plant Engineering
F3: Daily Water Meter Readings | M3: Month:SEPTEMBER- 2022
B5: Date | C5: CP F/F | D5: CP Chillers | E5: CP Parking | F5: CP Total M3 | G5: Town House | H5: Spa B | I5: Spa A | J5: CW Hotel A | K5: CCW Hotel B | L5: Marina | M5: Hotel Total M3 | N5: Grand Total M3 | P5: Day | Q5: Room Nights | R5: Total Guests | S5: Cooling Degree Day | T5: Following Meters are not working
C6: 130465 | D6: 130460 | E6: 130461 | G6: 130464 | H6: 130456 | I6: 130457 | J6: 130458 | K6: 130459 | L6: 130466
B7: 1 | C7: 8284 | D7: 503 | E7: 46762 | G7: 282163 | H7: 166212 | I7: 178900 | J7: 869059 | K7: 639998 | L7: 1712 | P7: 1 | Q7: 99 | R7: 394 | S7: 15.1 | T7: 130461 | U7: CP Parking
B8: Consumption | C8: =C7-8284 -> 0 | D8: =D7-503 -> 0 | E8: =E7-46762 -> 0 | F8: =E8+D8+C8 -> 0 | G8: =G7-282050 -> 113 | H8: =H7-166168 -> 44 | I8: =I7-178900 -> 0 | J8: =J7-868873 -> 186 | K8: =K7-639998 -> 0 | L8: =L7-1665 -> 47 | M8: =L8+K8+J8+I8+H8+G8 -> 390 | N8: =M8+F8 -> 390 | P8: 2 | Q8: 114 | R8: 454 | S8: 15 | T8: 130457 | U8: SPA- A
B9: 2 | C9: 8284 | D9: 503 | E9: 46762 | G9: 282272 | H9: 166225 | I9: 178900 | J9: 869280 | K9: 639998 | L9: 1750 | P9: 3 | Q9: 59 | R9: 192 | S9: 14.3 | T9: 130459 | U9: CCW Hotel B
B10: Consumption | C10: =C9-C7 -> 0 | D10: =D9-D7 -> 0 | E10: =E9-E7 -> 0 | F10: =E10+D10+C10 -> 0 | G10: =G9-G7 -> 109 | H10: =H9-H7 -> 13 | I10: =I9-I7 -> 0 | J10: =J9-J7 -> 221 | K10: =K9-K7 -> 0 | L10: =L9-L7 -> 38 | M10: =L10+K10+J10+I10+H10+G10 -> 381 | N10: =M10+F10 -> 381 | P10: 4 | Q10: 83 | R10: 228 | S10: 14.7
B11: 3 | C11: 8284 | D11: 503 | E11: 46762 | G11: 282389 | H11: 166239 | I11: 178900 | J11: 869480 | K11: 639998 | L11: 1795 | P11: 5 | Q11: 118 | R11: 292 | S11: 15.5
B12: Consumption | C12: =C11-C9 -> 0 | D12: =D11-D9 -> 0 | E12: =E11-E9 -> 0 | F12: =E12+D12+C12 -> 0 | G12: =G11-G9 -> 117 | H12: =H11-H9 -> 14 | I12: =I11-I9 -> 0 | J12: =J11-J9 -> 200 | K12: =K11-K9 -> 0 | L12: =L11-L9 -> 45 | M12: =L12+K12+J12+I12+H12+G12 -> 376 | N12: =M12+F12 -> 376 | P12: 6 | Q12: 142 | R12: 346 | S12: 15.2
B13: 4 | C13: 8284 | D13: 503 | E13: 46762 | G13: 282505 | H13: 166252 | I13: 178900 | J13: 869660 | K13: 639998 | L13: 1833 | P13: 7 | Q13: 148 | R13: 368 | S13: 14.9
B14: Consumption | C14: =C13-C11 -> 0 | D14: =D13-D11 -> 0 | E14: =E13-E11 -> 0 | F14: =E14+D14+C14 -> 0 | G14: =G13-G11 -> 116 | H14: =H13-H11 -> 13 | I14: =I13-I11 -> 0 | J14: =J13-J11 -> 180 | K14: =K13-K11 -> 0 | L14: =L13-L11 -> 38 | M14: =L14+K14+J14+I14+H14+G14 -> 347 | N14: =M14+F14 -> 347 | P14: 8 | Q14: 214 | R14: 648 | S14: 14.4
B15: 5 | C15: 8284 | D15: 503 | E15: 46762 | G15: 282622 | H15: 166280 | I15: 178900 | J15: 869852 | K15: 639998 | L15: 1867 | P15: 9 | Q15: 206 | R15: 668 | S15: 14.1
B16: Consumption | C16: =C15-C13 -> 0 | D16: =D15-D13 -> 0 | E16: =E15-E13 -> 0 | F16: =E16+D16+C16 -> 0 | G16: =G15-G13 -> 117 | H16: =H15-H13 -> 28 | I16: =I15-I13 -> 0 | J16: =J15-J13 -> 192 | K16: =K15-K13 -> 0 | L16: =L15-L13 -> 34 | M16: =L16+K16+J16+I16+H16+G16 -> 371 | N16: =M16+F16 -> 371 | P16: 10 | Q16: 132 | R16: 362 | S16: 13.9
B17: 6 | C17: 8284 | D17: 503 | E17: 46762 | G17: 282738 | H17: 166295 | I17: 178900 | J17: 870047 | K17: 639998 | L17: 1905 | P17: 11 | Q17: 122 | R17: 308 | S17: 14.4
B18: Consumption | C18: =C17-C15 -> 0 | D18: =D17-D15 -> 0 | E18: =E17-E15 -> 0 | F18: =E18+D18+C18 -> 0 | G18: =G17-G15 -> 116 | H18: =H17-H15 -> 15 | I18: =I17-I15 -> 0 | J18: =J17-J15 -> 195 | K18: =K17-K15 -> 0 | L18: =L17-L15 -> 38 | M18: =L18+K18+J18+I18+H18+G18 -> 364 | N18: =M18+F18 -> 364 | P18: 12
B19: 7 | C19: 8284 | D19: 503 | E19: 46762 | G19: 282851 | H19: 166316 | I19: 178900 | J19: 870254 | K19: 639998 | L19: 1949 | P19: 13
B20: Consumption | C20: =C19-C17 -> 0 | D20: =D19-D17 -> 0 | E20: =E19-E17 -> 0 | F20: =E20+D20+C20 -> 0 | G20: =G19-G17 -> 113 | H20: =H19-H17 -> 21 | I20: =I19-I17 -> 0 | J20: =J19-J17 -> 207 | K20: =K19-K17 -> 0 | L20: =L19-L17 -> 44 | M20: =L20+K20+J20+I20+H20+G20 -> 385 | N20: =M20+F20 -> 385 | P20: 14
B21: 8 | C21: 8287 | D21: 503 | E21: 46762 | G21: 282969 | H21: 166326 | I21: 178900 | J21: 870460 | K21: 639998 | L21: 1994 | P21: 15
B22: Consumption | C22: =C21-C19 -> 3 | D22: =D21-D19 -> 0 | E22: =E21-E19 -> 0 | F22: =E22+D22+C22 -> 3 | G22: =G21-G19 -> 118 | H22: =H21-H19 -> 10 | I22: =I21-I19 -> 0 | J22: =J21-J19 -> 206 | K22: =K21-K19 -> 0 | L22: =L21-L19 -> 45 | M22: =L22+K22+J22+I22+H22+G22 -> 379 | N22: =M22+F22 -> 382 | P22: 16
B23: 9 | C23: 8287 | D23: 503 | E23: 46762 | G23: 283081 | H23: 166346 | I23: 178900 | J23: 870696 | K23: 639998 | L23: 2042 | P23: 17
B24: Consumption | C24: =C23-C21 -> 0 | D24: =D23-D21 -> 0 | E24: =E23-E21 -> 0 | F24: =E24+D24+C24 -> 0 | G24: =G23-G21 -> 112 | H24: =H23-H21 -> 20 | I24: =I23-I21 -> 0 | J24: =J23-J21 -> 236 | K24: =K23-K21 -> 0 | L24: =L23-L21 -> 48 | M24: =L24+K24+J24+I24+H24+G24 -> 416 | N24: =M24+F24 -> 416 | P24: 18
B25: 10 | C25: 8287 | D25: 503 | E25: 46762 | G25: 283193 | H25: 166367 | I25: 178900 | J25: 870925 | K25: 639998 | L25: 2082 | P25: 19
B26: Consumption | C26: =C25-C23 -> 0 | D26: =D25-D23 -> 0 | E26: =E25-E23 -> 0 | F26: =E26+D26+C26 -> 0 | G26: =G25-G23 -> 112 | H26: =H25-H23 -> 21 | I26: =I25-I23 -> 0 | J26: =J25-J23 -> 229 | K26: =K25-K23 -> 0 | L26: =L25-L23 -> 40 | M26: =L26+K26+J26+I26+H26+G26 -> 402 | N26: =M26+F26 -> 402 | P26: 20
B27: 11 | P27: 21
B28: Consumption | P28: 22
B29: 12 | P29: 23
B30: Consumption | P30: 24
B31: 13 | P31: 25
B32: Consumption | P32: 26
B33: 14 | P33: 27
B34: Consumption | P34: 28
B35: 15 | P35: 29
B36: Consumption | P36: 30
B37: 16 | P37: 31
B38: Consumption | Q38: =SUM(Q7:Q37) -> 1437 | R38: =SUM(R7:R37) -> 4260 | S38: =SUM(S7:S37) -> 161.5
B39: 17
B40: Consumption
B41: 18
B42: Consumption
...

Sheet LPG
D2: Central Plant Engineering
D3: Daily LPG Meter Readings
D4: Month: SEPTEMBER- 2022
B5: Date | C5: COMMON LPG READING/M3 | D5: NOBU/M3 | E5: LPG Total
C6: HOTEL+NOBU
B7: 1 | C7: 283884 | D7: 54220
B8: Consumption | C8: =C7-283689 -> 195 | D8: =D754220 -> 0 | E8: =C8 -> 195
B9: 2 | C9: 284105 | D9: 54220
B10: Consumption | C10: =C9-C7 -> 221 | D10: =D9-D7 -> 0 | E10: =C10 -> 221
B11: 3 | C11: 284320 | D11: 54220
B12: Consumption | C12: =C11-C9 -> 215 | D12: =D11-D9 -> 0 | E12: =C12 -> 215
B13: 4 | C13: 284506 | D13: 54220
B14: Consumption | C14: =C13-C11 -> 186 | D14: =D13-D11 -> 0 | E14: =C14 -> 186
B15: 5 | C15: 284703 | D15: 54220
B16: Consumption | C16: =C15-C13 -> 197 | D16: =D15-D13 -> 0 | E16: =C16 -> 197
B17: 6 | C17: 284903 | D17: 54220
B18: Consumption | C18: =C17-C15 -> 200 | D18: =D17-D15 -> 0 | E18: =C18 -> 200
B19: 7 | C19: 285107 | D19: 54220
B20: Consumption | C20: =C19-C17 -> 204 | D20: =D19-D17 -> 0 | E20: =C20 -> 204
B21: 8 | C21: 285317 | D21: 54220
B22: Consumption | C22: =C21-C19 -> 210 | D22: =D21-D19 -> 0 | E22: =C22 -> 210
B23: 9 | C23: 285548 | D23: 54220
B24: Consumption | C24: =C23-C21 -> 231 | D24: =D23-D21 -> 0 | E24: =C24 -> 231
B25: 10 | C25: 285785 | D25: 54220
B26: Consumption | C26: =C25-C23 -> 237 | D26: =D25-D23 -> 0 | E26: =C26 -> 237
B27: 11
B28: Consumption
B29: 12
B30: Consumption
B31: 13
B32: Consumption
B33: 14
B34: Consumption
B35: 15
B36: Consumption
B37: 16
B38: Consumption
B39: 17
B40: Consumption
B41: 18
...

Sheet Sheet1
