Workbook

Sheet TOTAL
A1: Site Name | B1: Day | C1: Month | D1: Year | E1: Total Electricity Kwh | F1: Electricity Tariff ($/Kwh) | G1: Natual Gas (m3) | H1: Natural Gas $/m3 | I1: Water Utility Supply (m3) m3 | J1: Water Utility Supply (m3) $/m3 | K1: Room Nights
A2: Cairo at Nile Plaza | B2: 1 | C2: 9 | D2: 2022 | E2: =(((Submetering!O2+Submetering!P2)*0.842284+Submetering!Q2+(Submetering!M2+Submetering!N2+Submetering!Y2)*0.7362)+(Submetering!O2+Submetering!P2+Submetering!Q2)*0.1488+(Submetering!M2+Submetering!N2+Submetering!Y2)*0.1167+(Submetering!K2+Submetering!L2-Submetering!Z2-Submetering!AA2-Submetering!AB2-Submetering!AC2-Submetering!Q2)+(Submetering!M2+Submetering!N2+Submetering!Y2)*0.1139) -> 87851.237 | F2: 1.27 | G2: =Gas!C3*0.9147 -> 1906.2348 | H2: 3.65 | I2: =Submetering!H2+Submetering!AD2+Submetering!AE2 -> 906 | J2: 10.03 | K2: =ELECT.!B3 -> 238
A3: Cairo at Nile Plaza | B3: =B2+1 -> 2 | C3: 9 | D3: 2022 | E3: =(((Submetering!O3+Submetering!P3)*0.842284+Submetering!Q3+(Submetering!M3+Submetering!N3+Submetering!Y3)*0.7362)+(Submetering!O3+Submetering!P3+Submetering!Q3)*0.1488+(Submetering!M3+Submetering!N3+Submetering!Y3)*0.1167+(Submetering!K3+Submetering!L3-Submetering!Z3-Submetering!AA3-Submetering!AB3-Submetering!AC3-Submetering!Q3)+(Submetering!M3+Submetering!N3+Submetering!Y3)*0.1139) -> 77284.358 | F3: 1.27 | G3: =Gas!C4*0.9147 -> 1607.1279 | H3: 3.65 | I3: =Submetering!H3+Submetering!AD3+Submetering!AE3 -> 946 | J3: 10.03 | K3: =ELECT.!B4 -> 207
A4: Cairo at Nile Plaza | B4: =B3+1 -> 3 | C4: 9 | D4: 2022 | E4: =(((Submetering!O4+Submetering!P4)*0.842284+Submetering!Q4+(Submetering!M4+Submetering!N4+Submetering!Y4)*0.7362)+(Submetering!O4+Submetering!P4+Submetering!Q4)*0.1488+(Submetering!M4+Submetering!N4+Submetering!Y4)*0.1167+(Submetering!K4+Submetering!L4-Submetering!Z4-Submetering!AA4-Submetering!AB4-Submetering!AC4-Submetering!Q4)+(Submetering!M4+Submetering!N4+Submetering!Y4)*0.1139) -> 58531.036 | F4: 1.27 | G4: =Gas!C5*0.9147 -> 1646.46 | H4: 3.65 | I4: =Submetering!H4+Submetering!AD4+Submetering!AE4 -> 666 | J4: 10.03 | K4: =ELECT.!B5 -> 207
A5: Cairo at Nile Plaza | B5: =B4+1 -> 4 | C5: 9 | D5: 2022 | E5: =(((Submetering!O5+Submetering!P5)*0.842284+Submetering!Q5+(Submetering!M5+Submetering!N5+Submetering!Y5)*0.7362)+(Submetering!O5+Submetering!P5+Submetering!Q5)*0.1488+(Submetering!M5+Submetering!N5+Submetering!Y5)*0.1167+(Submetering!K5+Submetering!L5-Submetering!Z5-Submetering!AA5-Submetering!AB5-Submetering!AC5-Submetering!Q5)+(Submetering!M5+Submetering!N5+Submetering!Y5)*0.1139) -> 89766.051 | F5: 1.27 | G5: =Gas!C6*0.9147 -> 1697.6832 | H5: 3.65 | I5: =Submetering!H5+Submetering!AD5+Submetering!AE5 -> 886 | J5: 10.03 | K5: =ELECT.!B6 -> 216
A6: Cairo at Nile Plaza | B6: =B5+1 -> 5 | C6: 9 | D6: 2022 | E6: =(((Submetering!O6+Submetering!P6)*0.842284+Submetering!Q6+(Submetering!M6+Submetering!N6+Submetering!Y6)*0.7362)+(Submetering!O6+Submetering!P6+Submetering!Q6)*0.1488+(Submetering!M6+Submetering!N6+Submetering!Y6)*0.1167+(Submetering!K6+Submetering!L6-Submetering!Z6-Submetering!AA6-Submetering!AB6-Submetering!AC6-Submetering!Q6)+(Submetering!M6+Submetering!N6+Submetering!Y6)*0.1139) -> 79447.497 | F6: 1.27 | G6: =Gas!C7*0.9147 -> 1986.7284 | H6: 3.65 | I6: =Submetering!H6+Submetering!AD6+Submetering!AE6 -> 796 | J6: 10.03 | K6: =ELECT.!B7 -> 260
A7: Cairo at Nile Plaza | B7: =B6+1 -> 6 | C7: 9 | D7: 2022 | E7: =(((Submetering!O7+Submetering!P7)*0.842284+Submetering!Q7+(Submetering!M7+Submetering!N7+Submetering!Y7)*0.7362)+(Submetering!O7+Submetering!P7+Submetering!Q7)*0.1488+(Submetering!M7+Submetering!N7+Submetering!Y7)*0.1167+(Submetering!K7+Submetering!L7-Submetering!Z7-Submetering!AA7-Submetering!AB7-Submetering!AC7-Submetering!Q7)+(Submetering!M7+Submetering!N7+Submetering!Y7)*0.1139) -> 68681.935 | F7: 1.27 | G7: =Gas!C8*0.9147 -> 1620.8484 | H7: 3.65 | I7: =Submetering!H7+Submetering!AD7+Submetering!AE7 -> 956 | J7: 10.03 | K7: =ELECT.!B8 -> 269
A8: Cairo at Nile Plaza | B8: =B7+1 -> 7 | C8: 9 | D8: 2022 | E8: =(((Submetering!O8+Submetering!P8)*0.842284+Submetering!Q8+(Submetering!M8+Submetering!N8+Submetering!Y8)*0.7362)+(Submetering!O8+Submetering!P8+Submetering!Q8)*0.1488+(Submetering!M8+Submetering!N8+Submetering!Y8)*0.1167+(Submetering!K8+Submetering!L8-Submetering!Z8-Submetering!AA8-Submetering!AB8-Submetering!AC8-Submetering!Q8)+(Submetering!M8+Submetering!N8+Submetering!Y8)*0.1139) -> 71827.977 | F8: 1.27 | G8: =Gas!C9*0.9147 -> 1781.8356 | H8: 3.65 | I8: =Submetering!H8+Submetering!AD8+Submetering!AE8 -> 726 | J8: 10.03 | K8: =ELECT.!B9 -> 257
A9: Cairo at Nile Plaza | B9: =B8+1 -> 8 | C9: 9 | D9: 2022 | E9: =(((Submetering!O9+Submetering!P9)*0.842284+Submetering!Q9+(Submetering!M9+Submetering!N9+Submetering!Y9)*0.7362)+(Submetering!O9+Submetering!P9+Submetering!Q9)*0.1488+(Submetering!M9+Submetering!N9+Submetering!Y9)*0.1167+(Submetering!K9+Submetering!L9-Submetering!Z9-Submetering!AA9-Submetering!AB9-Submetering!AC9-Submetering!Q9)+(Submetering!M9+Submetering!N9+Submetering!Y9)*0.1139) -> 92650.517 | F9: 1.27 | G9: =Gas!C10*0.9147 -> 2193.4506 | H9: 3.65 | I9: =Submetering!H9+Submetering!AD9+Submetering!AE9 -> 766 | J9: 10.03 | K9: =ELECT.!B10 -> 240
A10: Cairo at Nile Plaza | B10: =B9+1 -> 9 | C10: 9 | D10: 2022 | E10: =(((Submetering!O10+Submetering!P10)*0.842284+Submetering!Q10+(Submetering!M10+Submetering!N10+Submetering!Y10)*0.7362)+(Submetering!O10+Submetering!P10+Submetering!Q10)*0.1488+(Submetering!M10+Submetering!N10+Submetering!Y10)*0.1167+(Submetering!K10+Submetering!L10-Submetering!Z10-Submetering!AA10-Submetering!AB10-Submetering!AC10-Submetering!Q10)+(Submetering!M10+Submetering!N10+Submetering!Y10)*0.1139) -> 83255.654 | F10: 1.27 | G10: =Gas!C11*0.9147 -> 2067.222 | H10: 3.65 | I10: =Submetering!H10+Submetering!AD10+Submetering!AE10 -> 766 | J10: 10.03 | K10: =ELECT.!B11 -> 255
A11: Cairo at Nile Plaza | B11: =B10+1 -> 10 | C11: 9 | D11: 2022 | E11: =(((Submetering!O11+Submetering!P11)*0.842284+Submetering!Q11+(Submetering!M11+Submetering!N11+Submetering!Y11)*0.7362)+(Submetering!O11+Submetering!P11+Submetering!Q11)*0.1488+(Submetering!M11+Submetering!N11+Submetering!Y11)*0.1167+(Submetering!K11+Submetering!L11-Submetering!Z11-Submetering!AA11-Submetering!AB11-Submetering!AC11-Submetering!Q11)+(Submetering!M11+Submetering!N11+Submetering!Y11)*0.1139) -> 62394.958 | F11: 1.27 | G11: =Gas!C12*0.9147 -> 1867.8174 | H11: 3.65 | I11: =Submetering!H11+Submetering!AD11+Submetering!AE11 -> 736 | J11: 10.03 | K11: =ELECT.!B12 -> 222
A12: Cairo at Nile Plaza | B12: =B11+1 -> 11 | C12: 9 | D12: 2022 | E12: =(((Submetering!O12+Submetering!P12)*0.842284+Submetering!Q12+(Submetering!M12+Submetering!N12+Submetering!Y12)*0.7362)+(Submetering!O12+Submetering!P12+Submetering!Q12)*0.1488+(Submetering!M12+Submetering!N12+Submetering!Y12)*0.1167+(Submetering!K12+Submetering!L12-Submetering!Z12-Submetering!AA12-Submetering!AB12-Submetering!AC12-Submetering!Q12)+(Submetering!M12+Submetering!N12+Submetering!Y12)*0.1139) -> 68786.493 | F12: 1.27 | G12: =Gas!C13*0.9147 -> 2075.4543 | H12: 3.65 | I12: =Submetering!H12+Submetering!AD12+Submetering!AE12 -> 776 | J12: 10.03 | K12: =ELECT.!B13 -> 225
A13: Cairo at Nile Plaza | B13: =B12+1 -> 12 | C13: 9 | D13: 2022 | E13: =(((Submetering!O13+Submetering!P13)*0.842284+Submetering!Q13+(Submetering!M13+Submetering!N13+Submetering!Y13)*0.7362)+(Submetering!O13+Submetering!P13+Submetering!Q13)*0.1488+(Submetering!M13+Submetering!N13+Submetering!Y13)*0.1167+(Submetering!K13+Submetering!L13-Submetering!Z13-Submetering!AA13-Submetering!AB13-Submetering!AC13-Submetering!Q13)+(Submetering!M13+Submetering!N13+Submetering!Y13)*0.1139) -> 95444.772 | F13: 1.27 | G13: =Gas!C14*0.9147 -> 1645.5453 | H13: 3.65 | I13: =Submetering!H13+Submetering!AD13+Submetering!AE13 -> 786 | J13: 10.03 | K13: =ELECT.!B14 -> 210
A14: Cairo at Nile Plaza | B14: =B13+1 -> 13 | C14: 9 | D14: 2022 | E14: =(((Submetering!O14+Submetering!P14)*0.842284+Submetering!Q14+(Submetering!M14+Submetering!N14+Submetering!Y14)*0.7362)+(Submetering!O14+Submetering!P14+Submetering!Q14)*0.1488+(Submetering!M14+Submetering!N14+Submetering!Y14)*0.1167+(Submetering!K14+Submetering!L14-Submetering!Z14-Submetering!AA14-Submetering!AB14-Submetering!AC14-Submetering!Q14)+(Submetering!M14+Submetering!N14+Submetering!Y14)*0.1139) -> 64653.762 | F14: 1.27 | G14: =Gas!C15*0.9147 -> 594.555 | H14: 3.65 | I14: =Submetering!H14+Submetering!AD14+Submetering!AE14 -> 586 | J14: 10.03 | K14: =ELECT.!B15 -> 174
... A31: Cairo at Nile Plaza | B31: =B30+1 -> 30 | C31: 9 | D31: 2022 | E31: =(((Submetering!O31+Submetering!P31)*0.842284+Submetering!Q31+(Submetering!M31+Submetering!N31+Submetering!Y31)*0.7362)+(Submetering!O31+Submetering!P31+Submetering!Q31)*0.1488+(Submetering!M31+Submetering!N31+Submetering!Y31)*0.1167+(Submetering!K31+Submetering!L31-Submetering!Z31-Submetering!AA31-Submetering!AB31-Submetering!AC31-Submetering!Q31)+(Submetering!M31+Submetering!N31+Submetering!Y31)*0.1139) -> 0 | F31: 1.27 | G31: =Gas!C32*0.9147 -> 0 | H31: 3.65 | I31: =Submetering!H31+Submetering!AD31+Submetering!AE31 -> -194 | J31: 10.03 | K31: =ELECT.!B32 -> 0

Sheet Submetering
A1: Site Name | B1: Day | C1: Month | D1: Year | E1: Main (m3) | F1: Podium (m3) | G1: Hotel (m3) | H1: Large (m3) | I1: Feeder 1 (KWh) | J1: Feeder 2 (KWh) | K1: T1 (KWh) | L1: T2 (KWh) | M1: T3 (KWh) | N1: T4 (KWh) | O1: T5 (KWh) | P1: T7 (KWh) | Q1: New Chiller (KWh) | R1: Hotel (BTU) | S1: B.S (BTU) | T1: LS (BTU) | U1: Mall (BTU) | V1: AHU#25 (BTU) | W1: AHU#9 (BTU) | X1: Room Nights | Y1: Loss (KWH) | Z1: Mall (KWH) | AA1: Citadel (KWH) | AB1: Rotana (KWH) | AC1: CIB (KWH) | AD1: Plaza suits water consumption (M3) | AE1: Hotel water consumption (M3)
A2: Cairo at Nile Plaza | B2: 1 | C2: 9 | D2: 2022 | E2: =Water!C3 -> 1100 | F2: =Water!E3 -> 560 | G2: =Water!G3 -> 577.8 | H2: =Water!I3 -> 4.509 | I2: =ELECT.!F3 -> 26629 | J2: =ELECT.!H3 -> 64344 | K2: =ELECT.!K3 -> 13026 | L2: =ELECT.!M3 -> 7141 | M2: =ELECT.!O3 -> 19284 | N2: =ELECT.!Q3 -> 15896 | O2: =ELECT.!S3 -> 12637 | P2: =ELECT.!W3*2 -> 27462 | Q2: =ELECT.!D3 -> 640 | R2: =BTU!C3 -> 12.468 | S2: =BTU!F3 -> 2.852 | T2: =BTU!I3 -> 9 | U2: =BTU!O3 -> 2.174 | V2: =BTU!L3 -> 2.08 | W2: =BTU!R3 -> 1.03 | X2: =ELECT.!B3 -> 238 | Y2: =I2+J2-(K2+L2+M2+N2+O2+P2) -> -4473 | Z2: ='Mall, Citadel, Rotana'!C3+'Mall, Citadel, Rotana'!E3+'Mall, Citadel, Rotana'!G3+'Mall, Citadel, Rotana'!I3 -> 1364 | AA2: ='Mall, Citadel, Rotana'!K3+'Mall, Citadel, Rotana'!M3 -> 354 | AB2: ='Mall, Citadel, Rotana'!O3 -> 3 | AC2: ='Mall, Citadel, Rotana'!Q3+'Mall, Citadel, Rotana'!S3 -> 119 | AD2: =(E2-H2-194)*0.1318 -> 118.81651 | AE2: =E2-H2-AD2-194 -> 782.67449
A3: Cairo at Nile Plaza | B3: =B2+1 -> 2 | C3: 9 | D3: 2022 | E3: =Water!C4 -> 1140 | F3: =Water!E4 -> 430 | G3: =Water!G4 -> 564.3 | H3: =Water!I4 -> 3.483 | I3: =ELECT.!F4 -> 23697 | J3: =ELECT.!H4 -> 56399 | K3: =ELECT.!K4 -> 10938 | L3: =ELECT.!M4 -> 6380 | M3: =ELECT.!O4 -> 17202 | N3: =ELECT.!Q4 -> 13896 | O3: =ELECT.!S4 -> 11625 | P3: =ELECT.!W4*2 -> 23796 | Q3: =ELECT.!D4 -> 480 | R3: =BTU!C4 -> 12.775 | S3: =BTU!F4 -> 2.118 | T3: =BTU!I4 -> 7 | U3: =BTU!O4 -> 2.322 | V3: =BTU!L4 -> 2.49 | W3: =BTU!R4 -> 0.9 | X3: =ELECT.!B4 -> 207 | Y3: =I3+J3-(K3+L3+M3+N3+O3+P3) -> -3741 | Z3: ='Mall, Citadel, Rotana'!C4+'Mall, Citadel, Rotana'!E4+'Mall, Citadel, Rotana'!G4+'Mall, Citadel, Rotana'!I4 -> 1228 | AA3: ='Mall, Citadel, Rotana'!K4+'Mall, Citadel, Rotana'!M4 -> 306 | AB3: ='Mall, Citadel, Rotana'!O4 -> 3 | AC3: ='Mall, Citadel, Rotana'!Q4+'Mall, Citadel, Rotana'!S4 -> 122 | AD3: =(E3-H3-194)*0.1318 -> 124.22374 | AE3: =E3-H3-AD3-194 -> 818.29326
A4: Cairo at Nile Plaza | B4: =B3+1 -> 3 | C4: 9 | D4: 2022 | E4: =Water!C5 -> 860 | F4: =Water!E5 -> 390 | G4: =Water!G5 -> 529.2 | H4: =Water!I5 -> 4.023 | I4: =ELECT.!F5 -> 18082 | J4: =ELECT.!H5 -> 42862 | K4: =ELECT.!K5 -> 8754 | L4: =ELECT.!M5 -> 4937 | M4: =ELECT.!O5 -> 12870 | N4: =ELECT.!Q5 -> 10558 | O4: =ELECT.!S5 -> 8647 | P4: =ELECT.!W5*2 -> 18070 | Q4: =ELECT.!D5 -> 800 | R4: =BTU!C5 -> 13.725 | S4: =BTU!F5 -> 1.936 | T4: =BTU!I5 -> 9 | U4: =BTU!O5 -> 2.404 | V4: =BTU!L5 -> 2.96 | W4: =BTU!R5 -> 0.89 | X4: =ELECT.!B5 -> 207 | Y4: =I4+J4-(K4+L4+M4+N4+O4+P4) -> -2892 | Z4: ='Mall, Citadel, Rotana'!C5+'Mall, Citadel, Rotana'!E5+'Mall, Citadel, Rotana'!G5+'Mall, Citadel, Rotana'!I5 -> 1236 | AA4: ='Mall, Citadel, Rotana'!K5+'Mall, Citadel, Rotana'!M5 -> 255 | AB4: ='Mall, Citadel, Rotana'!O5 -> 3 | AC4: ='Mall, Citadel, Rotana'!Q5+'Mall, Citadel, Rotana'!S5 -> 118 | AD4: =(E4-H4-194)*0.1318 -> 87.248569 | AE4: =E4-H4-AD4-194 -> 574.72843
A5: Cairo at Nile Plaza | B5: =B4+1 -> 4 | C5: 9 | D5: 2022 | E5: =Water!C6 -> 1080 | F5: =Water!E6 -> 440 | G5: =Water!G6 -> 653.4 | H5: =Water!I6 -> 4.482 | I5: =ELECT.!F6 -> 27314 | J5: =ELECT.!H6 -> 65686 | K5: =ELECT.!K6 -> 13498 | L5: =ELECT.!M6 -> 7788 | M5: =ELECT.!O6 -> 19296 | N5: =ELECT.!Q6 -> 15931 | O5: =ELECT.!S6 -> 13530 | P5: =ELECT.!W6*2 -> 27638 | Q5: =ELECT.!D6 -> 640 | R5: =BTU!C6 -> 13.647 | S5: =BTU!F6 -> 3.29 | T5: =BTU!I6 -> 9 | U5: =BTU!O6 -> 2.313 | V5: =BTU!L6 -> 2.98 | W5: =BTU!R6 -> 1.4 | X5: =ELECT.!B6 -> 216 | Y5: =I5+J5-(K5+L5+M5+N5+O5+P5) -> -4681 | Z5: ='Mall, Citadel, Rotana'!C6+'Mall, Citadel, Rotana'!E6+'Mall, Citadel, Rotana'!G6+'Mall, Citadel, Rotana'!I6 -> 1397 | AA5: ='Mall, Citadel, Rotana'!K6+'Mall, Citadel, Rotana'!M6 -> 427 | AB5: ='Mall, Citadel, Rotana'!O6 -> 3 | AC5: ='Mall, Citadel, Rotana'!Q6+'Mall, Citadel, Rotana'!S6 -> 121 | AD5: =(E5-H5-194)*0.1318 -> 116.18407 | AE5: =E5-H5-AD5-194 -> 765.33393
A6: Cairo at Nile Plaza | B6: =B5+1 -> 5 | C6: 9 | D6: 2022 | E6: =Water!C7 -> 990 | F6: =Water!E7 -> 400 | G6: =Water!G7 -> 567 | H6: =Water!I7 -> 4.239 | I6: =ELECT.!F7 -> 24276 | J6: =ELECT.!H7 -> 58106 | K6: =ELECT.!K7 -> 12120 | L6: =ELECT.!M7 -> 6863 | M6: =ELECT.!O7 -> 17224 | N6: =ELECT.!Q7 -> 14292 | O6: =ELECT.!S7 -> 11622 | P6: =ELECT.!W7*2 -> 24546 | Q6: =ELECT.!D7 -> 800 | R6: =BTU!C7 -> 10.982 | S6: =BTU!F7 -> 2.655 | T6: =BTU!I7 -> 7 | U6: =BTU!O7 -> 1.827 | V6: =BTU!L7 -> 1.86 | W6: =BTU!R7 -> 2.72 | X6: =ELECT.!B7 -> 260 | Y6: =I6+J6-(K6+L6+M6+N6+O6+P6) -> -4285 | Z6: ='Mall, Citadel, Rotana'!C7+'Mall, Citadel, Rotana'!E7+'Mall, Citadel, Rotana'!G7+'Mall, Citadel, Rotana'!I7 -> 1355 | AA6: ='Mall, Citadel, Rotana'!K7+'Mall, Citadel, Rotana'!M7 -> 352 | AB6: ='Mall, Citadel, Rotana'!O7 -> 4 | AC6: ='Mall, Citadel, Rotana'!Q7+'Mall, Citadel, Rotana'!S7 -> 116 | AD6: =(E6-H6-194)*0.1318 -> 104.3541 | AE6: =E6-H6-AD6-194 -> 687.4069
A7: Cairo at Nile Plaza | B7: =B6+1 -> 6 | C7: 9 | D7: 2022 | E7: =Water!C8 -> 1150 | F7: =Water!E8 -> 450 | G7: =Water!G8 -> 675 | H7: =Water!I8 -> 4.239 | I7: =ELECT.!F8 -> 20996 | J7: =ELECT.!H8 -> 50629 | K7: =ELECT.!K8 -> 10352 | L7: =ELECT.!M8 -> 5783 | M7: =ELECT.!O8 -> 15010 | N7: =ELECT.!Q8 -> 12253 | O7: =ELECT.!S8 -> 10393 | P7: =ELECT.!W8*2 -> 21504 | Q7: =ELECT.!D8 -> 320 | R7: =BTU!C8 -> 12.289 | S7: =BTU!F8 -> 3.639 | T7: =BTU!I8 -> 9 | U7: =BTU!O8 -> 2.226 | V7: =BTU!L8 -> 2.23 | W7: =BTU!R8 -> 2.35 | X7: =ELECT.!B8 -> 269 | Y7: =I7+J7-(K7+L7+M7+N7+O7+P7) -> -3670 | Z7: ='Mall, Citadel, Rotana'!C8+'Mall, Citadel, Rotana'!E8+'Mall, Citadel, Rotana'!G8+'Mall, Citadel, Rotana'!I8 -> 1374 | AA7: ='Mall, Citadel, Rotana'!K8+'Mall, Citadel, Rotana'!M8 -> 422 | AB7: ='Mall, Citadel, Rotana'!O8 -> 3 | AC7: ='Mall, Citadel, Rotana'!Q8+'Mall, Citadel, Rotana'!S8 -> 124 | AD7: =(E7-H7-194)*0.1318 -> 125.4421 | AE7: =E7-H7-AD7-194 -> 826.3189
A8: Cairo at Nile Plaza | B8: =B7+1 -> 7 | C8: 9 | D8: 2022 | E8: =Water!C9 -> 920 | F8: =Water!E9 -> 380 | G8: =Water!G9 -> 648 | H8: =Water!I9 -> 4.293 | I8: =ELECT.!F9 -> 22331 | J8: =ELECT.!H9 -> 52415 | K8: =ELECT.!K9 -> 10732 | L8: =ELECT.!M9 -> 6357 | M8: =ELECT.!O9 -> 15790 | N8: =ELECT.!Q9 -> 12492 | O8: =ELECT.!S9 -> 10490 | P8: =ELECT.!W9*2 -> 22542 | Q8: =ELECT.!D9 -> 800 | R8: =BTU!C9 -> 13.351 | S8: =BTU!F9 -> 4.016 | T8: =BTU!I9 -> 9 | U8: =BTU!O9 -> 2.1 | V8: =BTU!L9 -> 2.53 | W8: =BTU!R9 -> 2.91 | X8: =ELECT.!B9 -> 257 | Y8: =I8+J8-(K8+L8+M8+N8+O8+P8) -> -3657 | Z8: ='Mall, Citadel, Rotana'!C9+'Mall, Citadel, Rotana'!E9+'Mall, Citadel, Rotana'!G9+'Mall, Citadel, Rotana'!I9 -> 1386 | AA8: ='Mall, Citadel, Rotana'!K9+'Mall, Citadel, Rotana'!M9 -> 417 | AB8: ='Mall, Citadel, Rotana'!O9 -> 3 | AC8: ='Mall, Citadel, Rotana'!Q9+'Mall, Citadel, Rotana'!S9 -> 119 | AD8: =(E8-H8-194)*0.1318 -> 95.120983 | AE8: =E8-H8-AD8-194 -> 626.58602
A9: Cairo at Nile Plaza | B9: =B8+1 -> 8 | C9: 9 | D9: 2022 | E9: =Water!C10 -> 960 | F9: =Water!E10 -> 430 | G9: =Water!G10 -> 556.2 | H9: =Water!I10 -> 4.509 | I9: =ELECT.!F10 -> 28554 | J9: =ELECT.!H10 -> 67688 | K9: =ELECT.!K10 -> 13554 | L9: =ELECT.!M10 -> 8178 | M9: =ELECT.!O10 -> 20162 | N9: =ELECT.!Q10 -> 16539 | O9: =ELECT.!S10 -> 13827 | P9: =ELECT.!W10*2 -> 28712 | Q9: =ELECT.!D10 -> 640 | R9: =BTU!C10 -> 12.535 | S9: =BTU!F10 -> 3.245 | T9: =BTU!I10 -> 9 | U9: =BTU!O10 -> 1.744 | V9: =BTU!L10 -> 2.25 | W9: =BTU!R10 -> 2.71 | X9: =ELECT.!B10 -> 240 | Y9: =I9+J9-(K9+L9+M9+N9+O9+P9) -> -4730 | Z9: ='Mall, Citadel, Rotana'!C10+'Mall, Citadel, Rotana'!E10+'Mall, Citadel, Rotana'!G10+'Mall, Citadel, Rotana'!I10 -> 1362 | AA9: ='Mall, Citadel, Rotana'!K10+'Mall, Citadel, Rotana'!M10 -> 349 | AB9: ='Mall, Citadel, Rotana'!O10 -> 4 | AC9: ='Mall, Citadel, Rotana'!Q10+'Mall, Citadel, Rotana'!S10 -> 531 | AD9: =(E9-H9-194)*0.1318 -> 100.36451 | AE9: =E9-H9-AD9-194 -> 661.12649
A10: Cairo at Nile Plaza | B10: =B9+1 -> 9 | C10: 9 | D10: 2022 | E10: =Water!C11 -> 960 | F10: =Water!E11 -> 400 | G10: =Water!G11 -> 572.4 | H10: =Water!I11 -> 5.184 | I10: =ELECT.!F11 -> 25242 | J10: =ELECT.!H11 -> 60675 | K10: =ELECT.!K11 -> 11308 | L10: =ELECT.!M11 -> 6781 | M10: =ELECT.!O11 -> 18218 | N10: =ELECT.!Q11 -> 14621 | O10: =ELECT.!S11 -> 12903 | P10: =ELECT.!W11*2 -> 25942 | Q10: =ELECT.!D11 -> 640 | R10: =BTU!C11 -> 16.252 | S10: =BTU!F11 -> 2.075 | T10: =BTU!I11 -> 10 | U10: =BTU!O11 -> 3.015 | V10: =BTU!L11 -> 3.22 | W10: =BTU!R11 -> 1.11 | X10: =ELECT.!B11 -> 255 | Y10: =I10+J10-(K10+L10+M10+N10+O10+P10) -> -3856 | Z10: ='Mall, Citadel, Rotana'!C11+'Mall, Citadel, Rotana'!E11+'Mall, Citadel, Rotana'!G11+'Mall, Citadel, Rotana'!I11 -> 1217 | AA10: ='Mall, Citadel, Rotana'!K11+'Mall, Citadel, Rotana'!M11 -> 229 | AB10: ='Mall, Citadel, Rotana'!O11 -> 2 | AC10: ='Mall, Citadel, Rotana'!Q11+'Mall, Citadel, Rotana'!S11 -> 0 | AD10: =(E10-H10-194)*0.1318 -> 100.27555 | AE10: =E10-H10-AD10-194 -> 660.54045
A11: Cairo at Nile Plaza | B11: =B10+1 -> 10 | C11: 9 | D11: 2022 | E11: =Water!C12 -> 930 | F11: =Water!E12 -> 420 | G11: =Water!G12 -> 567 | H11: =Water!I12 -> 5.13 | I11: =ELECT.!F12 -> 18966 | J11: =ELECT.!H12 -> 45936 | K11: =ELECT.!K12 -> 8534 | L11: =ELECT.!M12 -> 5309 | M11: =ELECT.!O12 -> 13490 | N11: =ELECT.!Q12 -> 10762 | O11: =ELECT.!S12 -> 9239 | P11: =ELECT.!W12*2 -> 19878 | Q11: =ELECT.!D12 -> 800 | R11: =BTU!C12 -> 11.464 | S11: =BTU!F12 -> 1.919 | T11: =BTU!I12 -> 8 | U11: =BTU!O12 -> 1.608 | V11: =BTU!L12 -> 1.91 | W11: =BTU!R12 -> 3.1 | X11: =ELECT.!B12 -> 222 | Y11: =I11+J11-(K11+L11+M11+N11+O11+P11) -> -2310 | Z11: ='Mall, Citadel, Rotana'!C12+'Mall, Citadel, Rotana'!E12+'Mall, Citadel, Rotana'!G12+'Mall, Citadel, Rotana'!I12 -> 1374 | AA11: ='Mall, Citadel, Rotana'!K12+'Mall, Citadel, Rotana'!M12 -> 260 | AB11: ='Mall, Citadel, Rotana'!O12 -> 4 | AC11: ='Mall, Citadel, Rotana'!Q12+'Mall, Citadel, Rotana'!S12 -> 0 | AD11: =(E11-H11-194)*0.1318 -> 96.328666 | AE11: =E11-H11-AD11-194 -> 634.54133
A12: Cairo at Nile Plaza | B12: =B11+1 -> 11 | C12: 9 | D12: 2022 | E12: =Water!C13 -> 970 | F12: =Water!E13 -> 380 | G12: =Water!G13 -> 583.2 | H12: =Water!I13 -> 4.671 | I12: =ELECT.!F13 -> 21260 | J12: =ELECT.!H13 -> 50156 | K12: =ELECT.!K13 -> 9460 | L12: =ELECT.!M13 -> 6063 | M12: =ELECT.!O13 -> 15012 | N12: =ELECT.!Q13 -> 11760 | O12: =ELECT.!S13 -> 10904 | P12: =ELECT.!W13*2 -> 22324 | Q12: =ELECT.!D13 -> 640 | R12: =BTU!C13 -> 8.872 | S12: =BTU!F13 -> 2.21 | T12: =BTU!I13 -> 7 | U12: =BTU!O13 -> 1.296 | V12: =BTU!L13 -> 1.22 | W12: =BTU!R13 -> 3.23 | X12: =ELECT.!B13 -> 225 | Y12: =I12+J12-(K12+L12+M12+N12+O12+P12) -> -4107 | Z12: ='Mall, Citadel, Rotana'!C13+'Mall, Citadel, Rotana'!E13+'Mall, Citadel, Rotana'!G13+'Mall, Citadel, Rotana'!I13 -> 1362 | AA12: ='Mall, Citadel, Rotana'!K13+'Mall, Citadel, Rotana'!M13 -> 310 | AB12: ='Mall, Citadel, Rotana'!O13 -> 4 | AC12: ='Mall, Citadel, Rotana'!Q13+'Mall, Citadel, Rotana'!S13 -> 0 | AD12: =(E12-H12-194)*0.1318 -> 101.66116 | AE12: =E12-H12-AD12-194 -> 669.66784
A13: Cairo at Nile Plaza | B13: =B12+1 -> 12 | C13: 9 | D13: 2022 | E13: =Water!C14 -> 980 | F13: =Water!E14 -> 330 | G13: =Water!G14 -> 572.4 | H13: =Water!I14 -> 4.671 | I13: =ELECT.!F14 -> 29667 | J13: =ELECT.!H14 -> 69578 | K13: =ELECT.!K14 -> 11560 | L13: =ELECT.!M14 -> 8787 | M13: =ELECT.!O14 -> 20654 | N13: =ELECT.!Q14 -> 16451 | O13: =ELECT.!S14 -> 14374 | P13: =ELECT.!W14*2 -> 31292 | Q13: =ELECT.!D14 -> 640 | R13: =BTU!C14 -> 12.64 | S13: =BTU!F14 -> 3.529 | T13: =BTU!I14 -> 10 | U13: =BTU!O14 -> 1.966 | V13: =BTU!L14 -> 0.475 | W13: =BTU!R14 -> 1.5 | X13: =ELECT.!B14 -> 210 | Y13: =I13+J13-(K13+L13+M13+N13+O13+P13) -> -3873 | Z13: ='Mall, Citadel, Rotana'!C14+'Mall, Citadel, Rotana'!E14+'Mall, Citadel, Rotana'!G14+'Mall, Citadel, Rotana'!I14 -> 1364 | AA13: ='Mall, Citadel, Rotana'!K14+'Mall, Citadel, Rotana'!M14 -> 444 | AB13: ='Mall, Citadel, Rotana'!O14 -> 2 | AC13: ='Mall, Citadel, Rotana'!Q14+'Mall, Citadel, Rotana'!S14 -> 575 | AD13: =(E13-H13-194)*0.1318 -> 102.97916 | AE13: =E13-H13-AD13-194 -> 678.34984
A14: Cairo at Nile Plaza | B14: =B13+1 -> 13 | C14: 9 | D14: 2022 | E14: =Water!C15 -> 780 | F14: =Water!E15 -> 340 | G14: =Water!G15 -> 588.6 | H14: =Water!I15 -> 4.293 | I14: =ELECT.!F15 -> 20256 | J14: =ELECT.!H15 -> 47234 | K14: =ELECT.!K15 -> 8980 | L14: =ELECT.!M15 -> 6042 | M14: =ELECT.!O15 -> 14014 | N14: =ELECT.!Q15 -> 11448 | O14: =ELECT.!S15 -> 9736 | P14: =ELECT.!W15*2 -> 20558 | Q14: =ELECT.!D15 -> 800 | R14: =BTU!C15 -> 12.307 | S14: =BTU!F15 -> 3.162 | T14: =BTU!I15 -> 10 | U14: =BTU!O15 -> 1.8101 | V14: =BTU!L15 -> 3.635 | W14: =BTU!R15 -> 3.99 | X14: =ELECT.!B15 -> 174 | Y14: =I14+J14-(K14+L14+M14+N14+O14+P14) -> -3288 | Z14: ='Mall, Citadel, Rotana'!C15+'Mall, Citadel, Rotana'!E15+'Mall, Citadel, Rotana'!G15+'Mall, Citadel, Rotana'!I15 -> 1367 | AA14: ='Mall, Citadel, Rotana'!K15+'Mall, Citadel, Rotana'!M15 -> 413 | AB14: ='Mall, Citadel, Rotana'!O15 -> 3 | AC14: ='Mall, Citadel, Rotana'!Q15+'Mall, Citadel, Rotana'!S15 -> 166 | AD14: =(E14-H14-194)*0.1318 -> 76.668983 | AE14: =E14-H14-AD14-194 -> 505.03802
... A31: Cairo at Nile Plaza | B31: =B30+1 -> 30 | C31: 9 | D31: 2022 | E31: =Water!C32 -> 0 | F31: =Water!E32 -> 0 | G31: =Water!G32 -> 0 | H31: =Water!I32 -> 0 | I31: =ELECT.!F32 -> 0 | J31: =ELECT.!H32 -> 0 | K31: =ELECT.!K32 -> 0 | L31: =ELECT.!M32 -> 0 | M31: =ELECT.!O32 -> 0 | N31: =ELECT.!Q32 -> 0 | O31: =ELECT.!S32 -> 0 | P31: =ELECT.!W32*2 -> 0 | Q31: =ELECT.!D32 -> 0 | R31: =BTU!C32 -> 0 | S31: =BTU!F32 -> 0 | T31: =BTU!I32 -> 0 | U31: =BTU!O32 -> 0 | V31: =BTU!L32 -> 0 | W31: =BTU!R32 -> 0 | X31: =ELECT.!B32 -> 0 | Y31: =I31+J31-(K31+L31+M31+N31+O31+P31) -> 0 | Z31: ='Mall, Citadel, Rotana'!C32+'Mall, Citadel, Rotana'!E32+'Mall, Citadel, Rotana'!G32+'Mall, Citadel, Rotana'!I32 -> 0 | AA31: ='Mall, Citadel, Rotana'!K32+'Mall, Citadel, Rotana'!M32 -> 0 | AB31: ='Mall, Citadel, Rotana'!O32 -> 0 | AC31: ='Mall, Citadel, Rotana'!Q32+'Mall, Citadel, Rotana'!S32 -> 0 | AD31: =(E31-H31-194)*0.1318 -> -25.5692 | AE31: =E31-H31-AD31-194 -> -168.4308

Sheet Mall, Citadel, Rotana
A1: Day | B1: R1 | C1: Cons | D1: R2 | E1: Cons | F1: R3 | G1: Cons | H1: R4 | I1: Cons | J1: RO1 | K1: Cons | L1: RO2 | M1: Cons | N1: ROE | O1: Cons | P1: CIB. 1 | Q1: Cons | R1: CIB. E | S1: Cons | T1: Co | U1: Cons
A2: 44804 | B2: 47509 | C2: 0 | D2: 40924 | E2: 0 | F2: 22019 | G2: 0 | H2: 257970 | I2: 0 | J2: 330607 | K2: 0 | L2: 26449 | M2: 0 | N2: 226330 | O2: 0 | P2: 167701 | Q2: 0 | R2: 55047 | S2: 0 | T2: 4046 | U2: 0
A3: 44805 | B3: 47514 | C3: =(B3-B2)*800/5 -> 800 | D3: 40927 | E3: =(D3-D2)*800/5 -> 480 | F3: 22022 | G3: =(F3-F2)*100/5 -> 60 | H3: 257994 | I3: =(H3-H2) -> 24 | J3: 330781 | K3: =(J3-J2) -> 174 | L3: 26452 | M3: =(L3-L2)*300/5 -> 180 | N3: 226333 | O3: =N3-N2 -> 3 | P3: 167820 | Q3: =P3-P2 -> 119 | R3: 55047 | S3: 0 | T3: 4046 | U3: =(T3-T2)*800/5 -> 0
A4: 44806 | B4: 47518 | C4: =(B4-B3)*800/5 -> 640 | D4: 40930 | E4: =(D4-D3)*800/5 -> 480 | F4: 22026 | G4: =(F4-F3)*100/5 -> 80 | H4: 258022 | I4: =(H4-H3) -> 28 | J4: 330907 | K4: =(J4-J3) -> 126 | L4: 26455 | M4: =(L4-L3)*300/5 -> 180 | N4: 226336 | O4: =N4-N3 -> 3 | P4: 167942 | Q4: =P4-P3 -> 122 | R4: 55047 | S4: 0 | T4: 4046 | U4: =(T4-T3)*800/5 -> 0
A5: 44807 | B5: 47522 | C5: =(B5-B4)*800/5 -> 640 | D5: 40933 | E5: =(D5-D4)*800/5 -> 480 | F5: 22030 | G5: =(F5-F4)*100/5 -> 80 | H5: 258058 | I5: =(H5-H4) -> 36 | J5: 331042 | K5: =(J5-J4) -> 135 | L5: 26457 | M5: =(L5-L4)*300/5 -> 120 | N5: 226339 | O5: =N5-N4 -> 3 | P5: 168060 | Q5: =P5-P4 -> 118 | R5: =R4 -> 55047 | S5: =R5-R4 -> 0 | T5: 4047 | U5: =(T5-T4)*800/5 -> 160
A6: 44808 | B6: 47527 | C6: =(B6-B5)*800/5 -> 800 | D6: 40936 | E6: =(D6-D5)*800/5 -> 480 | F6: 22034 | G6: =(F6-F5)*100/5 -> 80 | H6: 258095 | I6: =(H6-H5) -> 37 | J6: 331229 | K6: =(J6-J5) -> 187 | L6: 26461 | M6: =(L6-L5)*300/5 -> 240 | N6: 226342 | O6: =N6-N5 -> 3 | P6: 168181 | Q6: =P6-P5 -> 121 | R6: =R5 -> 55047 | S6: 0 | T6: 4048 | U6: =(T6-T5)*800/5 -> 160
A7: 44809 | B7: 47532 | C7: =(B7-B6)*800/5 -> 800 | D7: 40939 | E7: =(D7-D6)*800/5 -> 480 | F7: 22037 | G7: =(F7-F6)*100/5 -> 60 | H7: 258110 | I7: =(H7-H6) -> 15 | J7: 331401 | K7: =(J7-J6) -> 172 | L7: 26464 | M7: =(L7-L6)*300/5 -> 180 | N7: 226346 | O7: =N7-N6 -> 4 | P7: 168297 | Q7: =P7-P6 -> 116 | R7: =R6 -> 55047 | S7: 0 | T7: 4048 | U7: =(T7-T6)*800/5 -> 0
A8: 44810 | B8: 47537 | C8: =(B8-B7)*800/5 -> 800 | D8: 40942 | E8: =(D8-D7)*800/5 -> 480 | F8: 22041 | G8: =(F8-F7)*100/5 -> 80 | H8: 258124 | I8: =(H8-H7) -> 14 | J8: 331583 | K8: =(J8-J7) -> 182 | L8: 26468 | M8: =(L8-L7)*300/5 -> 240 | N8: 226349 | O8: =N8-N7 -> 3 | P8: 168421 | Q8: =P8-P7 -> 124 | R8: =R7 -> 55047 | S8: =R8-R7 -> 0 | T8: 4049 | U8: =(T8-T7)*800/5 -> 160
A9: 44811 | B9: 47542 | C9: =(B9-B8)*800/5 -> 800 | D9: 40945 | E9: =(D9-D8)*800/5 -> 480 | F9: 22045 | G9: =(F9-F8)*100/5 -> 80 | H9: 258150 | I9: =(H9-H8) -> 26 | J9: 331760 | K9: =(J9-J8) -> 177 | L9: 26472 | M9: =(L9-L8)*300/5 -> 240 | N9: 226352 | O9: =N9-N8 -> 3 | P9: 168540 | Q9: =P9-P8 -> 119 | R9: =R8 -> 55047 | S9: =R9-R8 -> 0 | T9: 4050 | U9: =(T9-T8)*800/5 -> 160
A10: 44812 | B10: 47547 | C10: =(B10-B9)*800/5 -> 800 | D10: 40948 | E10: =(D10-D9)*800/5 -> 480 | F10: 22048 | G10: =(F10-F9)*100/5 -> 60 | H10: 258172 | I10: =(H10-H9) -> 22 | J10: 331929 | K10: =(J10-J9) -> 169 | L10: 26475 | M10: =(L10-L9)*300/5 -> 180 | N10: 226356 | O10: =N10-N9 -> 4 | P10: 169071 | Q10: =P10-P9 -> 531 | R10: =R9 -> 55047 | S10: =R10-R9 -> 0 | T10: 4050 | U10: =(T10-T9)*800/5 -> 0
A11: 44813 | B11: 47551 | C11: =(B11-B10)*800/5 -> 640 | D11: 40951 | E11: =(D11-D10)*800/5 -> 480 | F11: 22052 | G11: =(F11-F10)*100/5 -> 80 | H11: 258189 | I11: =(H11-H10) -> 17 | J11: 332038 | K11: =(J11-J10) -> 109 | L11: 26477 | M11: =(L11-L10)*300/5 -> 120 | N11: 226358 | O11: =N11-N10 -> 2 | P11: =P10 -> 169071 | Q11: =P11-P10 -> 0 | R11: =R10 -> 55047 | S11: =R11-R10 -> 0 | T11: 4051 | U11: =(T11-T10)*800/5 -> 160
A12: 44814 | B12: 47556 | C12: =(B12-B11)*800/5 -> 800 | D12: 40954 | E12: =(D12-D11)*800/5 -> 480 | F12: 22056 | G12: =(F12-F11)*100/5 -> 80 | H12: 258203 | I12: =(H12-H11) -> 14 | J12: 332178 | K12: =(J12-J11) -> 140 | L12: 26479 | M12: =(L12-L11)*300/5 -> 120 | N12: 226362 | O12: =N12-N11 -> 4 | P12: =P11 -> 169071 | Q12: =P12-P11 -> 0 | R12: =R11 -> 55047 | S12: =R12-R11 -> 0 | T12: =T11 -> 4051 | U12: =(T12-T11)*800/5 -> 0
A13: 44815 | B13: 47561 | C13: =(B13-B12)*800/5 -> 800 | D13: 40957 | E13: =(D13-D12)*800/5 -> 480 | F13: 22059 | G13: =(F13-F12)*100/5 -> 60 | H13: 258225 | I13: =(H13-H12) -> 22 | J13: 332308 | K13: =(J13-J12) -> 130 | L13: 26482 | M13: =(L13-L12)*300/5 -> 180 | N13: 226366 | O13: =N13-N12 -> 4 | P13: =P12 -> 169071 | Q13: =P13-P12 -> 0 | R13: =R12 -> 55047 | S13: =R13-R12 -> 0 | T13: 4052 | U13: =(T13-T12)*800/5 -> 160
A14: 44816 | B14: 47566 | C14: =(B14-B13)*800/5 -> 800 | D14: 40960 | E14: =(D14-D13)*800/5 -> 480 | F14: 22063 | G14: =(F14-F13)*100/5 -> 80 | H14: 258229 | I14: =(H14-H13) -> 4 | J14: 332512 | K14: =(J14-J13) -> 204 | L14: 26486 | M14: =(L14-L13)*300/5 -> 240 | N14: 226368 | O14: =N14-N13 -> 2 | P14: 169646 | Q14: =P14-P13 -> 575 | R14: =R13 -> 55047 | S14: 0 | T14: =T13 -> 4052 | U14: =(T14-T13)*800/5 -> 0
A15: 44817 | B15: 47571 | C15: =(B15-B14)*800/5 -> 800 | D15: 40963 | E15: =(D15-D14)*800/5 -> 480 | F15: 22066 | G15: =(F15-F14)*100/5 -> 60 | H15: 258256 | I15: =(H15-H14) -> 27 | J15: 332685 | K15: =(J15-J14) -> 173 | L15: 26490 | M15: =(L15-L14)*300/5 -> 240 | N15: 226371 | O15: =N15-N14 -> 3 | P15: 169812 | Q15: =P15-P14 -> 166 | R15: 55047 | S15: 0 | T15: 4053 | U15: =(T15-T14)*800/5 -> 160
A16: 44818 | B16: 47575 | C16: =(B16-B15)*800/5 -> 640 | D16: 40967 | E16: =(D16-D15)*800/5 -> 640 | F16: 22069 | G16: =(F16-F15)*100/5 -> 60 | H16: 258281 | I16: =(H16-H15) -> 25 | J16: 332861 | K16: =(J16-J15) -> 176 | L16: 26494 | M16: =(L16-L15)*300/5 -> 240 | N16: 226374 | O16: =N16-N15 -> 3 | P16: 169933 | Q16: =P16-P15 -> 121 | R16: =R15 -> 55047 | S16: =R16-R15 -> 0 | T16: 4054 | U16: =(T16-T15)*800/5 -> 160
A17: 44819 | B17: 47581 | C17: =(B17-B16)*800/5 -> 960 | D17: 40969 | E17: =(D17-D16)*800/5 -> 320 | F17: 22074 | G17: =(F17-F16)*100/5 -> 100 | H17: 258293 | I17: =(H17-H16) -> 12 | J17: 333024 | K17: =(J17-J16) -> 163 | L17: 26497 | M17: =(L17-L16)*300/5 -> 180 | N17: 226377 | O17: =N17-N16 -> 3 | P17: 170056 | Q17: =P17-P16 -> 123 | R17: =R16 -> 55047 | S17: =S16 -> 0 | T17: 4054 | U17: =(T17-T16)*800/5 -> 0
A18: 44820 | B18: 47586 | C18: =(B18-B17)*800/5 -> 800 | D18: 40972 | E18: =(D18-D17)*800/5 -> 480 | F18: 22078 | G18: =(F18-F17)*100/5 -> 80 | H18: 258322 | I18: =(H18-H17) -> 29 | J18: 333135 | K18: =(J18-J17) -> 111 | L18: 26500 | M18: =(L18-L17)*300/5 -> 180 | N18: 226381 | O18: =N18-N17 -> 4 | P18: 170171 | Q18: =P18-P17 -> 115 | R18: =R17 -> 55047 | S18: =R18-R17 -> 0 | T18: 4055 | U18: =(T18-T17)*800/5 -> 160
A19: 44821 | B19: 47591 | C19: =(B19-B18)*800/5 -> 800 | D19: 40975 | E19: =(D19-D18)*800/5 -> 480 | F19: 22083 | G19: =(F19-F18)*100/5 -> 100 | H19: 258353 | I19: =(H19-H18) -> 31 | J19: 333280 | K19: =(J19-J18) -> 145 | L19: 26502 | M19: =(L19-L18)*300/5 -> 120 | N19: 226384 | O19: =N19-N18 -> 3 | P19: =P18 -> 170171 | Q19: 0 | R19: =R18 -> 55047 | S19: =R19-R18 -> 0 | T19: 4055 | U19: =(T19-T18)*800/5 -> 0
A20: 44822 | B20: 47595 | C20: =(B20-B19)*800/5 -> 640 | D20: 40978 | E20: =(D20-D19)*800/5 -> 480 | F20: 22086 | G20: =(F20-F19)*100/5 -> 60 | H20: 258368 | I20: =(H20-H19) -> 15 | J20: 333450 | K20: =(J20-J19) -> 170 | L20: 26506 | M20: =(L20-L19)*300/5 -> 240 | N20: 226387 | O20: =N20-N19 -> 3 | P20: 170547 | Q20: =P20-P19 -> 376 | R20: 55047 | S20: =R20-R19 -> 0 | T20: 4056 | U20: =(T20-T19)*800/5 -> 160
A21: 44823 | B21: 47600 | C21: =(B21-B20)*800/5 -> 800 | D21: 40981 | E21: =(D21-D20)*800/5 -> 480 | F21: 22089 | G21: =(F21-F20)*100/5 -> 60 | H21: 258393 | I21: =(H21-H20) -> 25 | J21: 333621 | K21: =(J21-J20) -> 171 | L21: 26509 | M21: =(L21-L20)*300/5 -> 180 | N21: 226390 | O21: =N21-N20 -> 3 | P21: =P20 -> 170547 | Q21: =P21-P20 -> 0 | R21: =R20 -> 55047 | S21: =R21-R20 -> 0 | T21: 4056 | U21: =(T21-T20)*800/5 -> 0
A22: 44824 | B22: 47605 | C22: =(B22-B21)*800/5 -> 800 | D22: 40984 | E22: =(D22-D21)*800/5 -> 480 | F22: 22093 | G22: =(F22-F21)*100/5 -> 80 | H22: 258412 | I22: =(H22-H21) -> 19 | J22: 333790 | K22: =(J22-J21) -> 169 | L22: 26513 | M22: =(L22-L21)*300/5 -> 240 | N22: 226393 | O22: =N22-N21 -> 3 | P22: =P21 -> 170547 | Q22: =P22-P21 -> 0 | R22: =R21 -> 55047 | S22: =R22-R21 -> 0 | T22: =T21 -> 4056 | U22: =(T22-T21)*800/5 -> 0
A23: 44825 | B23: 47610 | C23: =(B23-B22)*800/5 -> 800 | D23: 40987 | E23: =(D23-D22)*800/5 -> 480 | F23: 22096 | G23: =(F23-F22)*100/5 -> 60 | H23: 258438 | I23: =(H23-H22) -> 26 | J23: 333965 | K23: =(J23-J22) -> 175 | L23: 26516 | M23: =(L23-L22)*300/5 -> 180 | N23: 226397 | O23: =N23-N22 -> 4 | P23: 170907 | Q23: =P23-P22 -> 360 | R23: =R22 -> 55047 | S23: =R23-R22 -> 0 | T23: 4057 | U23: =(T23-T22)*800/5 -> 160
A24: 44826 | B24: 47614 | C24: =(B24-B23)*800/5 -> 640 | D24: 40990 | E24: =(D24-D23)*800/5 -> 480 | F24: 22099 | G24: =(F24-F23)*100/5 -> 60 | H24: 258471 | I24: =(H24-H23) -> 33 | J24: 334142 | K24: =(J24-J23) -> 177 | L24: 26519 | M24: =(L24-L23)*300/5 -> 180 | N24: 226400 | O24: =N24-N23 -> 3 | P24: =P23 -> 170907 | Q24: =P24-P23 -> 0 | R24: =R23 -> 55047 | S24: =R24-R23 -> 0 | T24: 4058 | U24: =(T24-T23)*800/5 -> 160
A25: 44827 | B25: =B24 -> 47614 | C25: =(B25-B24)*800/5 -> 0 | D25: =D24 -> 40990 | E25: =(D25-D24)*800/5 -> 0 | F25: =F24 -> 22099 | G25: =(F25-F24)*100/5 -> 0 | H25: =H24 -> 258471 | I25: =(H25-H24) -> 0 | J25: =J24 -> 334142 | K25: =(J25-J24) -> 0 | L25: =L24 -> 26519 | M25: =(L25-L24)*300/5 -> 0 | N25: =N24 -> 226400 | O25: =N25-N24 -> 0 | P25: =P24 -> 170907 | Q25: =P25-P24 -> 0 | R25: =R24 -> 55047 | S25: =R25-R24 -> 0 | T25: =T24 -> 4058 | U25: =(T25-T24)*800/5 -> 0
A26: 44828 | B26: =B25 -> 47614 | C26: =(B26-B25)*800/5 -> 0 | D26: =D25 -> 40990 | E26: =(D26-D25)*800/5 -> 0 | F26: =F25 -> 22099 | G26: =(F26-F25)*100/5 -> 0 | H26: =H25 -> 258471 | I26: =(H26-H25) -> 0 | J26: =J25 -> 334142 | K26: =(J26-J25) -> 0 | L26: =L25 -> 26519 | M26: =(L26-L25)*300/5 -> 0 | N26: =N25 -> 226400 | O26: =N26-N25 -> 0 | P26: =P25 -> 170907 | Q26: =P26-P25 -> 0 | R26: =R25 -> 55047 | S26: =R26-R25 -> 0 | T26: =T25 -> 4058 | U26: =(T26-T25)*800/5 -> 0
A27: 44829 | B27: =B26 -> 47614 | C27: =(B27-B26)*800/5 -> 0 | D27: =D26 -> 40990 | E27: =(D27-D26)*800/5 -> 0 | F27: =F26 -> 22099 | G27: =(F27-F26)*100/5 -> 0 | H27: =H26 -> 258471 | I27: =(H27-H26) -> 0 | J27: =J26 -> 334142 | K27: =(J27-J26) -> 0 | L27: =L26 -> 26519 | M27: =(L27-L26)*300/5 -> 0 | N27: =N26 -> 226400 | O27: =N27-N26 -> 0 | P27: =P26 -> 170907 | Q27: =P27-P26 -> 0 | R27: =R26 -> 55047 | S27: =R27-R26 -> 0 | T27: =T26 -> 4058 | U27: =(T27-T26)*800/5 -> 0
A28: 44830 | B28: =B27 -> 47614 | C28: =(B28-B27)*800/5 -> 0 | D28: =D27 -> 40990 | E28: =(D28-D27)*800/5 -> 0 | F28: =F27 -> 22099 | G28: =(F28-F27)*100/5 -> 0 | H28: =H27 -> 258471 | I28: =(H28-H27) -> 0 | J28: =J27 -> 334142 | K28: =(J28-J27) -> 0 | L28: =L27 -> 26519 | M28: =(L28-L27)*300/5 -> 0 | N28: =N27 -> 226400 | O28: =N28-N27 -> 0 | P28: =P27 -> 170907 | Q28: =P28-P27 -> 0 | R28: =R27 -> 55047 | S28: =R28-R27 -> 0 | T28: =T27 -> 4058 | U28: =(T28-T27)*800/5 -> 0
A29: 44831 | B29: =B28 -> 47614 | C29: =(B29-B28)*800/5 -> 0 | D29: =D28 -> 40990 | E29: =(D29-D28)*800/5 -> 0 | F29: =F28 -> 22099 | G29: =(F29-F28)*100/5 -> 0 | H29: =H28 -> 258471 | I29: =(H29-H28) -> 0 | J29: =J28 -> 334142 | K29: =(J29-J28) -> 0 | L29: =L28 -> 26519 | M29: =(L29-L28)*300/5 -> 0 | N29: =N28 -> 226400 | O29: =N29-N28 -> 0 | P29: =P28 -> 170907 | Q29: =P29-P28 -> 0 | R29: =R28 -> 55047 | S29: =R29-R28 -> 0 | T29: =T28 -> 4058 | U29: =(T29-T28)*800/5 -> 0
A30: 44832 | B30: =B29 -> 47614 | C30: =(B30-B29)*800/5 -> 0 | D30: =D29 -> 40990 | E30: =(D30-D29)*800/5 -> 0 | F30: =F29 -> 22099 | G30: =(F30-F29)*100/5 -> 0 | H30: =H29 -> 258471 | I30: =(H30-H29) -> 0 | J30: =J29 -> 334142 | K30: =(J30-J29) -> 0 | L30: =L29 -> 26519 | M30: =(L30-L29)*300/5 -> 0 | N30: =N29 -> 226400 | O30: =N30-N29 -> 0 | P30: =P29 -> 170907 | Q30: =P30-P29 -> 0 | R30: =R29 -> 55047 | S30: =R30-R29 -> 0 | T30: =T29 -> 4058 | U30: =(T30-T29)*800/5 -> 0
A31: 44833 | B31: =B30 -> 47614 | C31: =(B31-B30)*800/5 -> 0 | D31: =D30 -> 40990 | E31: =(D31-D30)*800/5 -> 0 | F31: =F30 -> 22099 | G31: =(F31-F30)*100/5 -> 0 | H31: =H30 -> 258471 | I31: =(H31-H30) -> 0 | J31: =J30 -> 334142 | K31: =(J31-J30) -> 0 | L31: =L30 -> 26519 | M31: =(L31-L30)*300/5 -> 0 | N31: =N30 -> 226400 | O31: =N31-N30 -> 0 | P31: =P30 -> 170907 | Q31: =P31-P30 -> 0 | R31: 55047 | S31: 0 | T31: =T30 -> 4058 | U31: =(T31-T30)*800/5 -> 0
A32: 44834 | B32: =B31 -> 47614 | C32: =(B32-B31)*800/5 -> 0 | D32: =D31 -> 40990 | E32: =(D32-D31)*800/5 -> 0 | F32: =F31 -> 22099 | G32: =(F32-F31)*100/5 -> 0 | H32: =H31 -> 258471 | I32: =(H32-H31) -> 0 | J32: =J31 -> 334142 | K32: =(J32-J31) -> 0 | L32: =L31 -> 26519 | M32: =(L32-L31)*300/5 -> 0 | N32: =N31 -> 226400 | O32: =N32-N31 -> 0 | P32: =P31 -> 170907 | Q32: =P32-P31 -> 0 | R32: =R31 -> 55047 | S32: =R32-R31 -> 0 | T32: =T31 -> 4058 | U32: =(T32-T31)*800/5 -> 0
A33: Total | C33: =SUM(C2:C32) -> 16800 | E33: =SUM(E2:E32) -> 10560 | G33: =SUM(G2:G32) -> 1600 | I33: =SUM(I2:I32) -> 501 | K33: =SUM(K2:K32) -> 3535 | M33: =SUM(M2:M32) -> 4200 | O33: =SUM(O2:O32) -> 70 | Q33: =SUM(Q2:Q32) -> 3206 | S33: =SUM(S2:S32) -> 0 | U33: =SUM(U2:U32) -> 1920

Sheet ELECT.
A1: Day | B1: Rooms Sold | C1: New Chillers | D1: Cons | E1: F-1 | F1: Cons. | G1: F-2 | H1: Cons. | I1: Total | J1: T-1 | K1: Cons. | L1: T-2 | M1: Cons. | N1: T-3 | O1: Cons. | P1: T-4 | Q1: Cons. | R1: T-5 | S1: Cons. | T1: T-6 | U1: Cons. | V1: T-7 | W1: Cons. | X1: Total | Y1: Diff | Z1: Daily Money Value | AA1: MTD Total Money
A2: 44804 | B2: 230 | C2: 20060 | E2: 33201142 | G2: 4671912 | I2: =F2+H2 -> 0 | J2: 422838 | L2: 701909 | N2: 7386230 | P2: 7910768 | R2: 22213458 | T2: 0 | V2: 236531 | X2: =K2+M2+O2+Q2+S2+U2+W2 -> 0 | Y2: =I2-X2 -> 0 | Z2: =(0.93352*(W2+S2)+0.5568*(Q2+O2))*0.26 -> 0 | AA2: 0
A3: 44805 | B3: 238 | C3: 20064 | D3: =IF((C3-C2)<0,"0",(C3-C2))*160 -> 640 | E3: 33227771 | F3: =IF((E3-E2)<0,"0",(E3-E2)) -> 26629 | G3: 4736256 | H3: =IF((G3-G2)<0,"0",(G3-G2)) -> 64344 | I3: =F3+H3 -> 90973 | J3: 429351 | K3: =(IF((J3-J2)<L90,"0",(J3-J2)))*2 -> 13026 | L3: 709050 | M3: =IF((L3-L2)<0,"0",(L3-L2)) -> 7141 | N3: 7395872 | O3: =(IF((N3-N2)<P90,"0",(N3-N2)))*2 -> 19284 | P3: 7926664 | Q3: =IF((P3-P2)<0,"0",(P3-P2)) -> 15896 | R3: 22226095 | S3: =IF((R3-R2)<0,"0",(R3-R2)) -> 12637 | T3: 0 | V3: 250262 | W3: =IF((V3-V2)<0,"0",(V3-V2)) -> 13731 | X3: =K3+M3+O3+Q3+S3+U3+W3 -> 81715 | Y3: =I3-X3 -> 9258 | Z3: =(0.93352*(W3+S3)+0.5568*(Q3+O3))*0.26 -> 11492.853 | AA3: =SUM(Z1:Z3) -> 11492.853
A4: 44806 | B4: 207 | C4: 20067 | D4: =IF((C4-C3)<0,"0",(C4-C3))*160 -> 480 | E4: 33251468 | F4: =IF((E4-E3)<0,"0",(E4-E3)) -> 23697 | G4: 4792655 | H4: =IF((G4-G3)<0,"0",(G4-G3)) -> 56399 | I4: =F4+H4 -> 80096 | J4: 434820 | K4: =(IF((J4-J3)<L92,"0",(J4-J3)))*2 -> 10938 | L4: 715430 | M4: =IF((L4-L3)<0,"0",(L4-L3)) -> 6380 | N4: 7404473 | O4: =(IF((N4-N3)<P92,"0",(N4-N3)))*2 -> 17202 | P4: 7940560 | Q4: =IF((P4-P3)<0,"0",(P4-P3)) -> 13896 | R4: 22237720 | S4: =IF((R4-R3)<0,"0",(R4-R3)) -> 11625 | T4: 0 | V4: 262160 | W4: =IF((V4-V3)<0,"0",(V4-V3)) -> 11898 | X4: =K4+M4+O4+Q4+S4+U4+W4 -> 71939 | Y4: =I4-X4 -> 8157 | Z4: =(0.93352*(W4+S4)+0.5568*(Q4+O4))*0.26 -> 10211.385 | AA4: =SUM(Z1:Z4) -> 21704.238
A5: 44807 | B5: 207 | C5: 20072 | D5: =IF((C5-C4)<0,"0",(C5-C4))*160 -> 800 | E5: 33269550 | F5: =IF((E5-E4)<0,"0",(E5-E4)) -> 18082 | G5: 4835517 | H5: =IF((G5-G4)<0,"0",(G5-G4)) -> 42862 | I5: =F5+H5 -> 60944 | J5: 439197 | K5: =(IF((J5-J4)<0,"0",(J5-J4)))*2 -> 8754 | L5: 720367 | M5: =IF((L5-L4)<0,"0",(L5-L4)) -> 4937 | N5: 7410908 | O5: =(IF((N5-N4)<0,"0",(N5-N4)))*2 -> 12870 | P5: 7951118 | Q5: =IF((P5-P4)<0,"0",(P5-P4)) -> 10558 | R5: 22246367 | S5: =IF((R5-R4)<0,"0",(R5-R4)) -> 8647 | T5: 0 | V5: 271195 | W5: =IF((V5-V4)<0,"0",(V5-V4)) -> 9035 | X5: =K5+M5+O5+Q5+S5+U5+W5 -> 54801 | Y5: =I5-X5 -> 6143 | Z5: =(0.93352*(W5+S5)+0.5568*(Q5+O5))*0.26 -> 7683.3149 | AA5: =SUM(Z1:Z5) -> 29387.552
A6: 44808 | B6: 216 | C6: 20076 | D6: =IF((C6-C5)<0,"0",(C6-C5))*160 -> 640 | E6: 33296864 | F6: =IF((E6-E5)<0,"0",(E6-E5)) -> 27314 | G6: 4901203 | H6: =IF((G6-G5)<0,"0",(G6-G5)) -> 65686 | I6: =F6+H6 -> 93000 | J6: 445946 | K6: =(IF((J6-J5)<0,"0",(J6-J5)))*2 -> 13498 | L6: 728155 | M6: =IF((L6-L5)<0,"0",(L6-L5)) -> 7788 | N6: 7420556 | O6: =(IF((N6-N5)<0,"0",(N6-N5)))*2 -> 19296 | P6: 7967049 | Q6: =IF((P6-P5)<0,"0",(P6-P5)) -> 15931 | R6: 22259897 | S6: =IF((R6-R5)<0,"0",(R6-R5)) -> 13530 | T6: 0 | V6: 285014 | W6: =IF((V6-V5)<0,"0",(V6-V5)) -> 13819 | X6: =K6+M6+O6+Q6+S6+U6+W6 -> 83862 | Y6: =I6-X6 -> 9138 | Z6: =(0.93352*(W6+S6)+0.5568*(Q6+O6))*0.26 -> 11737.76 | AA6: =SUM(Z1:Z6) -> 41125.313
A7: 44809 | B7: 260 | C7: 20081 | D7: =IF((C7-C6)<0,"0",(C7-C6))*160 -> 800 | E7: 33321140 | F7: =IF((E7-E6)<0,"0",(E7-E6)) -> 24276 | G7: 4959309 | H7: =IF((G7-G6)<0,"0",(G7-G6)) -> 58106 | I7: =F7+H7 -> 82382 | J7: 452006 | K7: =(IF((J7-J6)<0,"0",(J7-J6)))*2 -> 12120 | L7: 735018 | M7: =IF((L7-L6)<0,"0",(L7-L6)) -> 6863 | N7: 7429168 | O7: =(IF((N7-N6)<0,"0",(N7-N6)))*2 -> 17224 | P7: 7981341 | Q7: =IF((P7-P6)<0,"0",(P7-P6)) -> 14292 | R7: 22271519 | S7: =IF((R7-R6)<0,"0",(R7-R6)) -> 11622 | T7: 0 | V7: 297287 | W7: =IF((V7-V6)<0,"0",(V7-V6)) -> 12273 | X7: =K7+M7+O7+Q7+S7+U7+W7 -> 74394 | Y7: =I7-X7 -> 7988 | Z7: =(0.93352*(W7+S7)+0.5568*(Q7+O7))*0.26 -> 10362.188 | AA7: =SUM(Z1:Z7) -> 51487.501
A8: 44810 | B8: 269 | C8: 20083 | D8: =IF((C8-C7)<0,"0",(C8-C7))*160 -> 320 | E8: 33342136 | F8: =IF((E8-E7)<0,"0",(E8-E7)) -> 20996 | G8: 5009938 | H8: =IF((G8-G7)<0,"0",(G8-G7)) -> 50629 | I8: =F8+H8 -> 71625 | J8: 457182 | K8: =(IF((J8-J7)<0,"0",(J8-J7)))*2 -> 10352 | L8: 740801 | M8: =IF((L8-L7)<0,"0",(L8-L7)) -> 5783 | N8: 7436673 | O8: =(IF((N8-N7)<0,"0",(N8-N7)))*2 -> 15010 | P8: 7993594 | Q8: =IF((P8-P7)<0,"0",(P8-P7)) -> 12253 | R8: 22281912 | S8: =IF((R8-R7)<0,"0",(R8-R7)) -> 10393 | T8: 0 | V8: 308039 | W8: =IF((V8-V7)<0,"0",(V8-V7)) -> 10752 | X8: =K8+M8+O8+Q8+S8+U8+W8 -> 64543 | Y8: =I8-X8 -> 7082 | Z8: =(0.93352*(W8+S8)+0.5568*(Q8+O8))*0.26 -> 9079.0229 | AA8: =SUM(Z1:Z8) -> 60566.524
A9: 44811 | B9: 257 | C9: 20088 | D9: =IF((C9-C8)<0,"0",(C9-C8))*160 -> 800 | E9: 33364467 | F9: =IF((E9-E8)<0,"0",(E9-E8)) -> 22331 | G9: 5062353 | H9: =IF((G9-G8)<0,"0",(G9-G8)) -> 52415 | I9: =F9+H9 -> 74746 | J9: 462548 | K9: =(IF((J9-J8)<0,"0",(J9-J8)))*2 -> 10732 | L9: 747158 | M9: =IF((L9-L8)<0,"0",(L9-L8)) -> 6357 | N9: 7444568 | O9: =(IF((N9-N8)<0,"0",(N9-N8)))*2 -> 15790 | P9: 8006086 | Q9: =IF((P9-P8)<0,"0",(P9-P8)) -> 12492 | R9: 22292402 | S9: =IF((R9-R8)<0,"0",(R9-R8)) -> 10490 | T9: 0 | V9: 319310 | W9: =IF((V9-V8)<0,"0",(V9-V8)) -> 11271 | X9: =K9+M9+O9+Q9+S9+U9+W9 -> 67132 | Y9: =I9-X9 -> 7614 | Z9: =(0.93352*(W9+S9)+0.5568*(Q9+O9))*0.26 -> 9376.054 | AA9: =SUM(Z1:Z9) -> 69942.578
A10: 44812 | B10: 240 | C10: 20092 | D10: =IF((C10-C9)<0,"0",(C10-C9))*160 -> 640 | E10: 33393021 | F10: =IF((E10-E9)<0,"0",(E10-E9)) -> 28554 | G10: 5130041 | H10: =IF((G10-G9)<0,"0",(G10-G9)) -> 67688 | I10: =F10+H10 -> 96242 | J10: 469325 | K10: =(IF((J10-J9)<0,"0",(J10-J9)))*2 -> 13554 | L10: 755336 | M10: =IF((L10-L9)<0,"0",(L10-L9)) -> 8178 | N10: 7454649 | O10: =(IF((N10-N9)<0,"0",(N10-N9)))*2 -> 20162 | P10: 8022625 | Q10: =IF((P10-P9)<0,"0",(P10-P9)) -> 16539 | R10: 22306229 | S10: =IF((R10-R9)<0,"0",(R10-R9)) -> 13827 | T10: 0 | V10: 333666 | W10: =IF((V10-V9)<0,"0",(V10-V9)) -> 14356 | X10: =K10+M10+O10+Q10+S10+U10+W10 -> 86616 | Y10: =I10-X10 -> 9626 | Z10: =(0.93352*(W10+S10)+0.5568*(Q10+O10))*0.26 -> 12153.573 | AA10: =SUM(Z1:Z10) -> 82096.151
A11: 44813 | B11: 255 | C11: 20096 | D11: =IF((C11-C10)<0,"0",(C11-C10))*160 -> 640 | E11: 33418263 | F11: =IF((E11-E10)<0,"0",(E11-E10)) -> 25242 | G11: 5190716 | H11: =IF((G11-G10)<0,"0",(G11-G10)) -> 60675 | I11: =F11+H11 -> 85917 | J11: 474979 | K11: =(IF((J11-J10)<0,"0",(J11-J10)))*2 -> 11308 | L11: 762117 | M11: =IF((L11-L10)<0,"0",(L11-L10)) -> 6781 | N11: 7463758 | O11: =(IF((N11-N10)<0,"0",(N11-N10)))*2 -> 18218 | P11: 8037246 | Q11: =IF((P11-P10)<0,"0",(P11-P10)) -> 14621 | R11: 22319132 | S11: =IF((R11-R10)<0,"0",(R11-R10)) -> 12903 | T11: 0 | V11: 346637 | W11: =IF((V11-V10)<0,"0",(V11-V10)) -> 12971 | X11: =K11+M11+O11+Q11+S11+U11+W11 -> 76802 | Y11: =I11-X11 -> 9115 | Z11: =(0.93352*(W11+S11)+0.5568*(Q11+O11))*0.26 -> 11034.049 | AA11: =SUM(Z1:Z11) -> 93130.2
A12: 44814 | B12: 222 | C12: 20101 | D12: =IF((C12-C11)<0,"0",(C12-C11))*160 -> 800 | E12: 33437229 | F12: =IF((E12-E11)<0,"0",(E12-E11)) -> 18966 | G12: 5236652 | H12: =IF((G12-G11)<0,"0",(G12-G11)) -> 45936 | I12: =F12+H12 -> 64902 | J12: 479246 | K12: =(IF((J12-J11)<0,"0",(J12-J11)))*2 -> 8534 | L12: 767426 | M12: =IF((L12-L11)<0,"0",(L12-L11)) -> 5309 | N12: 7470503 | O12: =(IF((N12-N11)<0,"0",(N12-N11)))*2 -> 13490 | P12: 8048008 | Q12: =IF((P12-P11)<0,"0",(P12-P11)) -> 10762 | R12: 22328371 | S12: =IF((R12-R11)<0,"0",(R12-R11)) -> 9239 | T12: 0 | V12: 356576 | W12: =IF((V12-V11)<0,"0",(V12-V11)) -> 9939 | X12: =K12+M12+O12+Q12+S12+U12+W12 -> 57273 | Y12: =I12-X12 -> 7629 | Z12: =(0.93352*(W12+S12)+0.5568*(Q12+O12))*0.26 -> 8165.7056 | AA12: =SUM(Z1:Z12) -> 101295.91
A13: 44815 | B13: 225 | C13: 20105 | D13: =IF((C13-C12)<0,"0",(C13-C12))*160 -> 640 | E13: 33458489 | F13: =IF((E13-E12)<0,"0",(E13-E12)) -> 21260 | G13: 5286808 | H13: =IF((G13-G12)<0,"0",(G13-G12)) -> 50156 | I13: =F13+H13 -> 71416 | J13: 483976 | K13: =(IF((J13-J12)<0,"0",(J13-J12)))*2 -> 9460 | L13: 773489 | M13: =IF((L13-L12)<0,"0",(L13-L12)) -> 6063 | N13: 7478009 | O13: =(IF((N13-N12)<0,"0",(N13-N12)))*2 -> 15012 | P13: 8059768 | Q13: =IF((P13-P12)<0,"0",(P13-P12)) -> 11760 | R13: 22339275 | S13: =IF((R13-R12)<0,"0",(R13-R12)) -> 10904 | T13: 0 | V13: 367738 | W13: =IF((V13-V12)<0,"0",(V13-V12)) -> 11162 | X13: =K13+M13+O13+Q13+S13+U13+W13 -> 64361 | Y13: =I13-X13 -> 7055 | Z13: =(0.93352*(W13+S13)+0.5568*(Q13+O13))*0.26 -> 9231.4825 | AA13: =SUM(Z1:Z13) -> 110527.39
A14: 44816 | B14: 210 | C14: 20109 | D14: =IF((C14-C13)<0,"0",(C14-C13))*160 -> 640 | E14: 33488156 | F14: =IF((E14-E13)<0,"0",(E14-E13)) -> 29667 | G14: 5356386 | H14: =IF((G14-G13)<0,"0",(G14-G13)) -> 69578 | I14: =F14+H14 -> 99245 | J14: 489756 | K14: =(IF((J14-J13)<0,"0",(J14-J13)))*2 -> 11560 | L14: 782276 | M14: =IF((L14-L13)<0,"0",(L14-L13)) -> 8787 | N14: 7488336 | O14: =(IF((N14-N13)<0,"0",(N14-N13)))*2 -> 20654 | P14: 8076219 | Q14: =IF((P14-P13)<0,"0",(P14-P13)) -> 16451 | R14: 22353649 | S14: =IF((R14-R13)<0,"0",(R14-R13)) -> 14374 | T14: 0 | V14: 383384 | W14: =IF((V14-V13)<0,"0",(V14-V13)) -> 15646 | X14: =K14+M14+O14+Q14+S14+U14+W14 -> 87472 | Y14: =I14-X14 -> 11773 | Z14: =(0.93352*(W14+S14)+0.5568*(Q14+O14))*0.26 -> 12657.927 | AA14: =SUM(Z1:Z14) -> 123185.32
A15: 44817 | B15: 174 | C15: 20114 | D15: =IF((C15-C14)<0,"0",(C15-C14))*160 -> 800 | E15: 33508412 | F15: =IF((E15-E14)<0,"0",(E15-E14)) -> 20256 | G15: 5403620 | H15: =IF((G15-G14)<0,"0",(G15-G14)) -> 47234 | I15: =F15+H15 -> 67490 | J15: 494246 | K15: =(IF((J15-J14)<0,"0",(J15-J14)))*2 -> 8980 | L15: 788318 | M15: =IF((L15-L14)<0,"0",(L15-L14)) -> 6042 | N15: 7495343 | O15: =(IF((N15-N14)<0,"0",(N15-N14)))*2 -> 14014 | P15: 8087667 | Q15: =IF((P15-P14)<0,"0",(P15-P14)) -> 11448 | R15: 22363385 | S15: =IF((R15-R14)<0,"0",(R15-R14)) -> 9736 | T15: 0 | V15: 393663 | W15: =IF((V15-V14)<0,"0",(V15-V14)) -> 10279 | X15: =K15+M15+O15+Q15+S15+U15+W15 -> 60499 | Y15: =I15-X15 -> 6991 | Z15: =(0.93352*(W15+S15)+0.5568*(Q15+O15))*0.26 -> 8544.0275 | AA15: =SUM(Z1:Z15) -> 131729.34
A16: 44818 | B16: 156 | C16: 20119 | D16: =IF((C16-C15)<0,"0",(C16-C15))*160 -> 800 | E16: 33533509 | F16: =IF((E16-E15)<0,"0",(E16-E15)) -> 25097 | G16: 5464183 | H16: =IF((G16-G15)<0,"0",(G16-G15)) -> 60563 | I16: =F16+H16 -> 85660 | J16: 500716 | K16: =(IF((J16-J15)<0,"0",(J16-J15)))*2 -> 12940 | L16: 795944 | M16: =IF((L16-L15)<0,"0",(L16-L15)) -> 7626 | N16: 7503966 | O16: =(IF((N16-N15)<0,"0",(N16-N15)))*2 -> 17246 | P16: 8101210 | Q16: =IF((P16-P15)<0,"0",(P16-P15)) -> 13543 | R16: 22375348 | S16: =IF((R16-R15)<0,"0",(R16-R15)) -> 11963 | T16: 0 | V16: 407325 | W16: =IF((V16-V15)<0,"0",(V16-V15)) -> 13662 | X16: =K16+M16+O16+Q16+S16+U16+W16 -> 76980 | Y16: =I16-X16 -> 8680 | Z16: =(0.93352*(W16+S16)+0.5568*(Q16+O16))*0.26 -> 10676.839 | AA16: =SUM(Z1:Z16) -> 142406.18
A17: 44819 | B17: 169 | C17: 20122 | D17: =IF((C17-C16)<0,"0",(C17-C16))*160 -> 480 | E17: 33557643 | F17: =IF((E17-E16)<0,"0",(E17-E16)) -> 24134 | G17: 5523554 | H17: =IF((G17-G16)<0,"0",(G17-G16)) -> 59371 | I17: =F17+H17 -> 83505 | J17: 507213 | K17: =(IF((J17-J16)<0,"0",(J17-J16)))*2 -> 12994 | L17: 803533 | M17: =IF((L17-L16)<0,"0",(L17-L16)) -> 7589 | N17: 7512130 | O17: =(IF((N17-N16)<0,"0",(N17-N16)))*2 -> 16328 | P17: 8113689 | Q17: =IF((P17-P16)<0,"0",(P17-P16)) -> 12479 | R17: 22387708 | S17: =IF((R17-R16)<0,"0",(R17-R16)) -> 12360 | T17: 0 | V17: 420658 | W17: =IF((V17-V16)<0,"0",(V17-V16)) -> 13333 | X17: =K17+M17+O17+Q17+S17+U17+W17 -> 75083 | Y17: =I17-X17 -> 8422 | Z17: =(0.93352*(W17+S17)+0.5568*(Q17+O17))*0.26 -> 10406.413 | AA17: =SUM(Z1:Z17) -> 152812.59
A18: 44820 | B18: 307 | C18: 20128 | D18: =IF((C18-C17)<0,"0",(C18-C17))*160 -> 960 | E18: 33576731 | F18: =IF((E18-E17)<0,"0",(E18-E17)) -> 19088 | G18: 5569862 | H18: =IF((G18-G17)<0,"0",(G18-G17)) -> 46308 | I18: =F18+H18 -> 65396 | J18: 512009 | K18: =(IF((J18-J17)<0,"0",(J18-J17)))*2 -> 9592 | L18: 809321 | M18: =IF((L18-L17)<0,"0",(L18-L17)) -> 5788 | N18: 7518672 | O18: =(IF((N18-N17)<0,"0",(N18-N17)))*2 -> 13084 | P18: 8123615 | Q18: =IF((P18-P17)<0,"0",(P18-P17)) -> 9926 | R18: 22397268 | S18: =IF((R18-R17)<0,"0",(R18-R17)) -> 9560 | T18: 0 | V18: 431176 | W18: =IF((V18-V17)<0,"0",(V18-V17)) -> 10518 | X18: =K18+M18+O18+Q18+S18+U18+W18 -> 58468 | Y18: =I18-X18 -> 6928 | Z18: =(0.93352*(W18+S18)+0.5568*(Q18+O18))*0.26 -> 8204.3475 | AA18: =SUM(Z1:Z18) -> 161016.94
A19: 44821 | B19: 165 | C19: 20132 | D19: =IF((C19-C18)<0,"0",(C19-C18))*160 -> 640 | E19: 33599096 | F19: =IF((E19-E18)<0,"0",(E19-E18)) -> 22365 | G19: 5622351 | H19: =IF((G19-G18)<0,"0",(G19-G18)) -> 52489 | I19: =F19+H19 -> 74854 | J19: 517426 | K19: =(IF((J19-J18)<0,"0",(J19-J18)))*2 -> 10834 | L19: 815923 | M19: =IF((L19-L18)<0,"0",(L19-L18)) -> 6602 | N19: 7526445 | O19: =(IF((N19-N18)<0,"0",(N19-N18)))*2 -> 15546 | P19: 8135763 | Q19: =IF((P19-P18)<0,"0",(P19-P18)) -> 12148 | R19: 22408083 | S19: =IF((R19-R18)<0,"0",(R19-R18)) -> 10815 | T19: 0 | V19: 442634 | W19: =IF((V19-V18)<0,"0",(V19-V18)) -> 11458 | X19: =K19+M19+O19+Q19+S19+U19+W19 -> 67403 | Y19: =I19-X19 -> 7451 | Z19: =(0.93352*(W19+S19)+0.5568*(Q19+O19))*0.26 -> 9415.2006 | AA19: =SUM(Z1:Z19) -> 170432.14
A20: 44822 | B20: 127 | C20: 20136 | D20: =IF((C20-C19)<0,"0",(C20-C19))*160 -> 640 | E20: 33619818 | F20: =IF((E20-E19)<0,"0",(E20-E19)) -> 20722 | G20: 5672404 | H20: =IF((G20-G19)<0,"0",(G20-G19)) -> 50053 | I20: =F20+H20 -> 70775 | J20: 522914 | K20: =(IF((J20-J19)<0,"0",(J20-J19)))*2 -> 10976 | L20: 822020 | M20: =IF((L20-L19)<0,"0",(L20-L19)) -> 6097 | N20: 7533659 | O20: =(IF((N20-N19)<0,"0",(N20-N19)))*2 -> 14428 | P20: 8147022 | Q20: =IF((P20-P19)<0,"0",(P20-P19)) -> 11259 | R20: 22418427 | S20: =IF((R20-R19)<0,"0",(R20-R19)) -> 10344 | T20: 0 | V20: 453540 | W20: =IF((V20-V19)<0,"0",(V20-V19)) -> 10906 | X20: =K20+M20+O20+Q20+S20+U20+W20 -> 64010 | Y20: =I20-X20 -> 6765 | Z20: =(0.93352*(W20+S20)+0.5568*(Q20+O20))*0.26 -> 8876.3536 | AA20: =SUM(Z1:Z20) -> 179308.5
A21: 44823 | B21: 185 | C21: 20140 | D21: =IF((C21-C20)<0,"0",(C21-C20))*160 -> 640 | E21: 33641620 | F21: =IF((E21-E20)<0,"0",(E21-E20)) -> 21802 | G21: 5724339 | H21: =IF((G21-G20)<0,"0",(G21-G20)) -> 51935 | I21: =F21+H21 -> 73737 | J21: 528512 | K21: =(IF((J21-J20)<0,"0",(J21-J20)))*2 -> 11196 | L21: 828335 | M21: =IF((L21-L20)<0,"0",(L21-L20)) -> 6315 | N21: 7541297 | O21: =(IF((N21-N20)<0,"0",(N21-N20)))*2 -> 15276 | P21: 8158962 | Q21: =IF((P21-P20)<0,"0",(P21-P20)) -> 11940 | R21: 22429103 | S21: =IF((R21-R20)<0,"0",(R21-R20)) -> 10676 | T21: 0 | V21: 464810 | W21: =IF((V21-V20)<0,"0",(V21-V20)) -> 11270 | X21: =K21+M21+O21+Q21+S21+U21+W21 -> 66673 | Y21: =I21-X21 -> 7064 | Z21: =(0.93352*(W21+S21)+0.5568*(Q21+O21))*0.26 -> 9266.6337 | AA21: =SUM(Z1:Z21) -> 188575.13
A22: 44824 | B22: 171 | C22: 20144 | D22: =IF((C22-C21)<0,"0",(C22-C21))*160 -> 640 | E22: 33670709 | F22: =IF((E22-E21)<0,"0",(E22-E21)) -> 29089 | G22: 5793517 | H22: =IF((G22-G21)<0,"0",(G22-G21)) -> 69178 | I22: =F22+H22 -> 98267 | J22: 535414 | K22: =(IF((J22-J21)<0,"0",(J22-J21)))*2 -> 13804 | L22: 836888 | M22: =IF((L22-L21)<0,"0",(L22-L21)) -> 8553 | N22: 7551437 | O22: =(IF((N22-N21)<0,"0",(N22-N21)))*2 -> 20280 | P22: 8175000 | Q22: =IF((P22-P21)<0,"0",(P22-P21)) -> 16038 | R22: 22443459 | S22: =IF((R22-R21)<0,"0",(R22-R21)) -> 14356 | T22: 0 | V22: 479964 | W22: =IF((V22-V21)<0,"0",(V22-V21)) -> 15154 | X22: =K22+M22+O22+Q22+S22+U22+W22 -> 88185 | Y22: =I22-X22 -> 10082 | Z22: =(0.93352*(W22+S22)+0.5568*(Q22+O22))*0.26 -> 12420.21 | AA22: =SUM(Z1:Z22) -> 200995.34
A23: 44825 | B23: 186 | C23: 20148 | D23: =IF((C23-C22)<0,"0",(C23-C22))*160 -> 640 | E23: 33689653 | F23: =IF((E23-E22)<0,"0",(E23-E22)) -> 18944 | G23: 5839876 | H23: =IF((G23-G22)<0,"0",(G23-G22)) -> 46359 | I23: =F23+H23 -> 65303 | J23: 540636 | K23: =(IF((J23-J22)<0,"0",(J23-J22)))*2 -> 10444 | L23: 842484 | M23: =IF((L23-L22)<0,"0",(L23-L22)) -> 5596 | N23: 7558009 | O23: =(IF((N23-N22)<0,"0",(N23-N22)))*2 -> 13144 | P23: 8185876 | Q23: =IF((P23-P22)<0,"0",(P23-P22)) -> 10876 | R23: 22453124 | S23: =IF((R23-R22)<0,"0",(R23-R22)) -> 9665 | T23: 0 | V23: 490096 | W23: =IF((V23-V22)<0,"0",(V23-V22)) -> 10132 | X23: =K23+M23+O23+Q23+S23+U23+W23 -> 59857 | Y23: =I23-X23 -> 5446 | Z23: =(0.93352*(W23+S23)+0.5568*(Q23+O23))*0.26 -> 8282.3602 | AA23: =SUM(Z1:Z23) -> 209277.7
A24: 44826 | B24: 181 | C24: 20152 | D24: =IF((C24-C23)<0,"0",(C24-C23))*160 -> 640 | E24: 33713849 | F24: =IF((E24-E23)<0,"0",(E24-E23)) -> 24196 | G24: 5899451 | H24: =IF((G24-G23)<0,"0",(G24-G23)) -> 59575 | I24: =F24+H24 -> 83771 | J24: 546464 | K24: =(IF((J24-J23)<0,"0",(J24-J23)))*2 -> 11656 | L24: 849629 | M24: =IF((L24-L23)<0,"0",(L24-L23)) -> 7145 | N24: 7566413 | O24: =(IF((N24-N23)<0,"0",(N24-N23)))*2 -> 16808 | P24: 8198558 | Q24: =IF((P24-P23)<0,"0",(P24-P23)) -> 12682 | R24: 22465439 | S24: =IF((R24-R23)<0,"0",(R24-R23)) -> 12315 | T24: 0 | V24: 503216 | W24: =IF((V24-V23)<0,"0",(V24-V23)) -> 13120 | X24: =K24+M24+O24+Q24+S24+U24+W24 -> 73726 | Y24: =I24-X24 -> 10045 | Z24: =(0.93352*(W24+S24)+0.5568*(Q24+O24))*0.26 -> 10442.669 | AA24: =SUM(Z1:Z24) -> 219720.37
A25: 44827 | D25: =IF((C25-C24)<0,"0",(C25-C24))*160 -> 0 | F25: =IF((E25-E24)<0,"0",(E25-E24)) -> 0 | H25: =IF((G25-G24)<0,"0",(G25-G24)) -> 0 | I25: =F25+H25 -> 0 | K25: =(IF((J25-J24)<0,"0",(J25-J24)))*2 -> 0 | M25: =IF((L25-L24)<0,"0",(L25-L24)) -> 0 | O25: =(IF((N25-N24)<0,"0",(N25-N24)))*2 -> 0 | Q25: =IF((P25-P24)<0,"0",(P25-P24)) -> 0 | S25: =IF((R25-R24)<0,"0",(R25-R24)) -> 0 | T25: 0 | W25: =IF((V25-V24)<0,"0",(V25-V24)) -> 0 | X25: =K25+M25+O25+Q25+S25+U25+W25 -> 0 | Y25: =I25-X25 -> 0 | Z25: =(0.93352*(W25+S25)+0.5568*(Q25+O25))*0.26 -> 0 | AA25: =SUM(Z1:Z25) -> 219720.37
A26: 44828 | D26: =IF((C26-C25)<0,"0",(C26-C25))*160 -> 0 | F26: =IF((E26-E25)<0,"0",(E26-E25)) -> 0 | H26: =IF((G26-G25)<0,"0",(G26-G25)) -> 0 | I26: =F26+H26 -> 0 | K26: =(IF((J26-J25)<0,"0",(J26-J25)))*2 -> 0 | M26: =IF((L26-L25)<0,"0",(L26-L25)) -> 0 | O26: =(IF((N26-N25)<0,"0",(N26-N25)))*2 -> 0 | Q26: =IF((P26-P25)<0,"0",(P26-P25)) -> 0 | S26: =IF((R26-R25)<0,"0",(R26-R25)) -> 0 | T26: 0 | W26: =IF((V26-V25)<0,"0",(V26-V25)) -> 0 | X26: =K26+M26+O26+Q26+S26+U26+W26 -> 0 | Y26: =I26-X26 -> 0 | Z26: =(0.93352*(W26+S26)+0.5568*(Q26+O26))*0.26 -> 0 | AA26: =SUM(Z1:Z26) -> 219720.37
A27: 44829 | D27: =IF((C27-C26)<0,"0",(C27-C26))*160 -> 0 | F27: =IF((E27-E26)<0,"0",(E27-E26)) -> 0 | H27: =IF((G27-G26)<0,"0",(G27-G26)) -> 0 | I27: =F27+H27 -> 0 | K27: =(IF((J27-J26)<0,"0",(J27-J26)))*2 -> 0 | M27: =IF((L27-L26)<0,"0",(L27-L26)) -> 0 | O27: =(IF((N27-N26)<0,"0",(N27-N26)))*2 -> 0 | Q27: =IF((P27-P26)<0,"0",(P27-P26)) -> 0 | S27: =IF((R27-R26)<0,"0",(R27-R26)) -> 0 | T27: 0 | W27: =IF((V27-V26)<0,"0",(V27-V26)) -> 0 | X27: =K27+M27+O27+Q27+S27+U27+W27 -> 0 | Y27: =I27-X27 -> 0 | Z27: =(0.93352*(W27+S27)+0.5568*(Q27+O27))*0.26 -> 0 | AA27: =SUM(Z1:Z27) -> 219720.37
A28: 44830 | D28: =IF((C28-C27)<0,"0",(C28-C27))*160 -> 0 | F28: =IF((E28-E27)<0,"0",(E28-E27)) -> 0 | H28: =IF((G28-G27)<0,"0",(G28-G27)) -> 0 | I28: =F28+H28 -> 0 | K28: =(IF((J28-J27)<0,"0",(J28-J27)))*2 -> 0 | M28: =IF((L28-L27)<0,"0",(L28-L27)) -> 0 | O28: =(IF((N28-N27)<0,"0",(N28-N27)))*2 -> 0 | Q28: =IF((P28-P27)<0,"0",(P28-P27)) -> 0 | S28: =IF((R28-R27)<0,"0",(R28-R27)) -> 0 | T28: 0 | W28: =IF((V28-V27)<0,"0",(V28-V27)) -> 0 | X28: =K28+M28+O28+Q28+S28+U28+W28 -> 0 | Y28: =I28-X28 -> 0 | Z28: =(0.93352*(W28+S28)+0.5568*(Q28+O28))*0.26 -> 0 | AA28: =SUM(Z1:Z28) -> 219720.37
A29: 44831 | D29: =IF((C29-C28)<0,"0",(C29-C28))*160 -> 0 | F29: =IF((E29-E28)<0,"0",(E29-E28)) -> 0 | H29: =IF((G29-G28)<0,"0",(G29-G28)) -> 0 | I29: =F29+H29 -> 0 | K29: =(IF((J29-J28)<0,"0",(J29-J28)))*2 -> 0 | M29: =IF((L29-L28)<0,"0",(L29-L28)) -> 0 | O29: =(IF((N29-N28)<0,"0",(N29-N28)))*2 -> 0 | Q29: =IF((P29-P28)<0,"0",(P29-P28)) -> 0 | S29: =IF((R29-R28)<0,"0",(R29-R28)) -> 0 | T29: 0 | W29: =IF((V29-V28)<0,"0",(V29-V28)) -> 0 | X29: =K29+M29+O29+Q29+S29+U29+W29 -> 0 | Y29: =I29-X29 -> 0 | Z29: =(0.93352*(W29+S29)+0.5568*(Q29+O29))*0.26 -> 0 | AA29: =SUM(Z1:Z29) -> 219720.37
A30: 44832 | D30: =IF((C30-C29)<0,"0",(C30-C29))*160 -> 0 | F30: =IF((E30-E29)<0,"0",(E30-E29)) -> 0 | H30: =IF((G30-G29)<0,"0",(G30-G29)) -> 0 | I30: =F30+H30 -> 0 | K30: =(IF((J30-J29)<0,"0",(J30-J29)))*2 -> 0 | M30: =IF((L30-L29)<0,"0",(L30-L29)) -> 0 | O30: =(IF((N30-N29)<0,"0",(N30-N29)))*2 -> 0 | Q30: =IF((P30-P29)<0,"0",(P30-P29)) -> 0 | S30: =IF((R30-R29)<0,"0",(R30-R29)) -> 0 | T30: 0 | W30: =IF((V30-V29)<0,"0",(V30-V29)) -> 0 | X30: =K30+M30+O30+Q30+S30+U30+W30 -> 0 | Y30: =I30-X30 -> 0 | Z30: =(0.93352*(W30+S30)+0.5568*(Q30+O30))*0.26 -> 0 | AA30: =SUM(Z1:Z30) -> 219720.37
A31: 44833 | D31: =IF((C31-C30)<0,"0",(C31-C30))*160 -> 0 | F31: =IF((E31-E30)<0,"0",(E31-E30)) -> 0 | H31: =IF((G31-G30)<0,"0",(G31-G30)) -> 0 | I31: =F31+H31 -> 0 | K31: =(IF((J31-J30)<0,"0",(J31-J30)))*2 -> 0 | M31: =IF((L31-L30)<0,"0",(L31-L30)) -> 0 | O31: =(IF((N31-N30)<0,"0",(N31-N30)))*2 -> 0 | Q31: =IF((P31-P30)<0,"0",(P31-P30)) -> 0 | S31: =IF((R31-R30)<0,"0",(R31-R30)) -> 0 | T31: 0 | W31: =IF((V31-V30)<0,"0",(V31-V30)) -> 0 | X31: =K31+M31+O31+Q31+S31+U31+W31 -> 0 | Y31: =I31-X31 -> 0 | Z31: =(0.93352*(W31+S31)+0.5568*(Q31+O31))*0.26 -> 0 | AA31: =SUM(Z1:Z31) -> 219720.37
A32: 44834 | D32: =IF((C32-C31)<0,"0",(C32-C31))*160 -> 0 | F32: =IF((E32-E31)<0,"0",(E32-E31)) -> 0 | H32: =IF((G32-G31)<0,"0",(G32-G31)) -> 0 | I32: =F32+H32 -> 0 | K32: =(IF((J32-J31)<0,"0",(J32-J31)))*2 -> 0 | M32: =IF((L32-L31)<0,"0",(L32-L31)) -> 0 | O32: =(IF((N32-N31)<0,"0",(N32-N31)))*2 -> 0 | Q32: =IF((P32-P31)<0,"0",(P32-P31)) -> 0 | S32: =IF((R32-R31)<0,"0",(R32-R31)) -> 0 | T32: 0 | W32: =IF((V32-V31)<0,"0",(V32-V31)) -> 0 | X32: =K32+M32+O32+Q32+S32+U32+W32 -> 0 | Y32: =I32-X32 -> 0 | Z32: =(0.93352*(W32+S32)+0.5568*(Q32+O32))*0.26 -> 0 | AA32: =SUM(Z1:Z32) -> 219720.37
A33: Total | B33: =SUM(B2:B32) -> 4857 | C33: 0 | D33: =SUM(D2:D32) -> 14720 | E33: 0 | F33: =SUM(F2:F32) -> 512707 | G33: 0 | H33: =SUM(H2:H32) -> 1227539 | I33: =F33+H33 -> 1740246 | J33: 0 | K33: =SUM(K2:K32) -> 247252 | L33: 0 | M33: =SUM(M2:M32) -> 147720 | N33: 0 | O33: =SUM(O2:O32) -> 360366 | P33: 0 | Q33: =SUM(Q2:Q32) -> 287790 | R33: 0 | S33: =SUM(S2:S32) -> 251981 | T33: =SUM(T3:T32) -> 0 | U33: =SUM(U3:U32) -> 0 | V33: 0 | W33: =SUM(W2:W32) -> 266685 | X33: =SUM(X2:X32) -> 1561794 | Y33: =SUM(Y1:Y32) -> 178452 | Z33: =SUM(Z1:Z32) -> 219720.37 | AA33: =SUM(AA2:AA32) -> 4309978.7

Sheet Water
A1: Day | B1: Main Reading | C1: Cons. | D1: Podium | E1: Cons. | F1: Hotel | G1: Cons. | H1: Large | I1: Cons. | J1: Total | K1: cost.LE
A2: 44804 | B2: 459795 | D2: 12991 | F2: 11222500 | H2: 808267 | J2: =C2+E2+G2+I2 -> 0 | K2: =J2*5.86 -> 0
