Workbook

Sheet TOTAL
A1: Site Name | B1: Day | C1: Month | D1: Year | E1: Total Electricity Kwh | F1: Electricity Tariff ($/Kwh) | G1: LPG (Kg) | H1: LPG $/Kg | I1: Water Utility Supply (m3) m3 | J1: Water Utility Supply (m3) $/m3 | K1: Irrigation Water (m3) m3 | L1: Irrigation water $/m3 | M1: Room Nights
A2: Seychelles | B2: 1 | C2: 9 | D2: 2022 | E2: =SUM('FS Seychelles'!D3:I3)*1000 -> 17730 | F2: =(('FS Seychelles'!O3*'FS Seychelles'!P3)+('FS Seychelles'!Q3*'FS Seychelles'!R3))/TOTAL!E2 -> 0.58628539 | G2: =('FS Seychelles'!$Z$10+'FS Seychelles'!$Z$15)/30 -> 319.06667 | H2: 1.05 | I2: =SUM('FS Seychelles'!S3:W3) -> 282 | J2: 0 | K2: ='FS Seychelles'!AA3 -> 122 | L2: 0 | M2: ='FS Seychelles'!B3 -> 60.5
A3: Seychelles | B3: =B2+1 -> 2 | C3: =C2 -> 9 | D3: 2022 | E3: =SUM('FS Seychelles'!D4:I4)*1000 -> 18180 | F3: =(('FS Seychelles'!O4*'FS Seychelles'!P4)+('FS Seychelles'!Q4*'FS Seychelles'!R4))/TOTAL!E3 -> 0.40258361 | G3: =('FS Seychelles'!$Z$10+'FS Seychelles'!$Z$15)/30 -> 319.06667 | H3: =H2 -> 1.05 | I3: =SUM('FS Seychelles'!S4:W4) -> 347 | J3: =J2 -> 0 | K3: ='FS Seychelles'!AA4 -> 153 | L3: =L2 -> 0 | M3: ='FS Seychelles'!B4 -> 67.1
A4: Seychelles | B4: =B3+1 -> 3 | C4: =C3 -> 9 | D4: 2022 | E4: =SUM('FS Seychelles'!D5:I5)*1000 -> 18020 | F4: =(('FS Seychelles'!O5*'FS Seychelles'!P5)+('FS Seychelles'!Q5*'FS Seychelles'!R5))/TOTAL!E4 -> 0.5961232 | G4: =('FS Seychelles'!$Z$10+'FS Seychelles'!$Z$15)/30 -> 319.06667 | H4: =H3 -> 1.05 | I4: =SUM('FS Seychelles'!S5:W5) -> 318 | J4: =J3 -> 0 | K4: ='FS Seychelles'!AA5 -> 108 | L4: =L3 -> 0 | M4: ='FS Seychelles'!B5 -> 65.8
A5: Seychelles | B5: =B4+1 -> 4 | C5: =C4 -> 9 | D5: 2022 | E5: =SUM('FS Seychelles'!D6:I6)*1000 -> 17770 | F5: =(('FS Seychelles'!O6*'FS Seychelles'!P6)+('FS Seychelles'!Q6*'FS Seychelles'!R6))/TOTAL!E5 -> 0.57944232 | G5: =('FS Seychelles'!$Z$10+'FS Seychelles'!$Z$15)/30 -> 319.06667 | H5: =H4 -> 1.05 | I5: =SUM('FS Seychelles'!S6:W6) -> 357 | J5: =J4 -> 0 | K5: ='FS Seychelles'!AA6 -> 118 | L5: =L4 -> 0 | M5: ='FS Seychelles'!B6 -> 63.2
A6: Seychelles | B6: =B5+1 -> 5 | C6: =C5 -> 9 | D6: 2022 | E6: =SUM('FS Seychelles'!D7:I7)*1000 -> 18220 | F6: =(('FS Seychelles'!O7*'FS Seychelles'!P7)+('FS Seychelles'!Q7*'FS Seychelles'!R7))/TOTAL!E6 -> 0.60093359 | G6: =('FS Seychelles'!$Z$10+'FS Seychelles'!$Z$15)/30 -> 319.06667 | H6: =H5 -> 1.05 | I6: =SUM('FS Seychelles'!S7:W7) -> 334 | J6: =J5 -> 0 | K6: ='FS Seychelles'!AA7 -> 89 | L6: =L5 -> 0 | M6: ='FS Seychelles'!B7 -> 64.5
A7: Seychelles | B7: =B6+1 -> 6 | C7: =C6 -> 9 | D7: 2022 | E7: =SUM('FS Seychelles'!D8:I8)*1000 -> 18990 | F7: =(('FS Seychelles'!O8*'FS Seychelles'!P8)+('FS Seychelles'!Q8*'FS Seychelles'!R8))/TOTAL!E7 -> 0.58777883 | G7: =('FS Seychelles'!$Z$10+'FS Seychelles'!$Z$15)/30 -> 319.06667 | H7: =H6 -> 1.05 | I7: =SUM('FS Seychelles'!S8:W8) -> 309 | J7: =J6 -> 0 | K7: ='FS Seychelles'!AA8 -> 157 | L7: =L6 -> 0 | M7: ='FS Seychelles'!B8 -> 63.2
A8: Seychelles | B8: =B7+1 -> 7 | C8: =C7 -> 9 | D8: 2022 | E8: =SUM('FS Seychelles'!D9:I9)*1000 -> 18910 | F8: =(('FS Seychelles'!O9*'FS Seychelles'!P9)+('FS Seychelles'!Q9*'FS Seychelles'!R9))/TOTAL!E8 -> 0.48310418 | G8: =('FS Seychelles'!$Z$10+'FS Seychelles'!$Z$15)/30 -> 319.06667 | H8: =H7 -> 1.05 | I8: =SUM('FS Seychelles'!S9:W9) -> 339 | J8: =J7 -> 0 | K8: ='FS Seychelles'!AA9 -> 174 | L8: =L7 -> 0 | M8: ='FS Seychelles'!B9 -> 66.2
A9: Seychelles | B9: =B8+1 -> 8 | C9: =C8 -> 9 | D9: 2022 | E9: =SUM('FS Seychelles'!D10:I10)*1000 -> 18300 | F9: =(('FS Seychelles'!O10*'FS Seychelles'!P10)+('FS Seychelles'!Q10*'FS Seychelles'!R10))/TOTAL!E9 -> 0.60358743 | G9: =('FS Seychelles'!$Z$10+'FS Seychelles'!$Z$15)/30 -> 319.06667 | H9: =H8 -> 1.05 | I9: =SUM('FS Seychelles'!S10:W10) -> 354 | J9: =J8 -> 0 | K9: ='FS Seychelles'!AA10 -> 143 | L9: =L8 -> 0 | M9: ='FS Seychelles'!B10 -> 66.2
A10: Seychelles | B10: =B9+1 -> 9 | C10: =C9 -> 9 | D10: 2022 | E10: =SUM('FS Seychelles'!D11:I11)*1000 -> 18120 | F10: =(('FS Seychelles'!O11*'FS Seychelles'!P11)+('FS Seychelles'!Q11*'FS Seychelles'!R11))/TOTAL!E10 -> 0.55266667 | G10: =('FS Seychelles'!$Z$10+'FS Seychelles'!$Z$15)/30 -> 319.06667 | H10: =H9 -> 1.05 | I10: =SUM('FS Seychelles'!S11:W11) -> 326 | J10: =J9 -> 0 | K10: ='FS Seychelles'!AA11 -> 208 | L10: =L9 -> 0 | M10: ='FS Seychelles'!B11 -> 70.1
A11: Seychelles | B11: =B10+1 -> 10 | C11: =C10 -> 9 | D11: 2022 | E11: =SUM('FS Seychelles'!D12:I12)*1000 -> 19070 | F11: =(('FS Seychelles'!O12*'FS Seychelles'!P12)+('FS Seychelles'!Q12*'FS Seychelles'!R12))/TOTAL!E11 -> 0.57193131 | G11: =('FS Seychelles'!$Z$10+'FS Seychelles'!$Z$15)/30 -> 319.06667 | H11: =H10 -> 1.05 | I11: =SUM('FS Seychelles'!S12:W12) -> 307 | J11: =J10 -> 0 | K11: ='FS Seychelles'!AA12 -> 167 | L11: =L10 -> 0 | M11: ='FS Seychelles'!B12 -> 57.1
A12: Seychelles | B12: =B11+1 -> 11 | C12: =C11 -> 9 | D12: 2022 | E12: =SUM('FS Seychelles'!D13:I13)*1000 -> 17020 | F12: =(('FS Seychelles'!O13*'FS Seychelles'!P13)+('FS Seychelles'!Q13*'FS Seychelles'!R13))/TOTAL!E12 -> 0.45370975 | G12: =('FS Seychelles'!$Z$10+'FS Seychelles'!$Z$15)/30 -> 319.06667 | H12: =H11 -> 1.05 | I12: =SUM('FS Seychelles'!S13:W13) -> 233 | J12: =J11 -> 0 | K12: ='FS Seychelles'!AA13 -> 128 | L12: =L11 -> 0 | M12: ='FS Seychelles'!B13 -> 40.3
A13: Seychelles | B13: =B12+1 -> 12 | C13: =C12 -> 9 | D13: 2022 | E13: =SUM('FS Seychelles'!D14:I14)*1000 -> 17320 | F13: =(('FS Seychelles'!O14*'FS Seychelles'!P14)+('FS Seychelles'!Q14*'FS Seychelles'!R14))/TOTAL!E13 -> 0.76755427 | G13: =('FS Seychelles'!$Z$10+'FS Seychelles'!$Z$15)/30 -> 319.06667 | H13: =H12 -> 1.05 | I13: =SUM('FS Seychelles'!S14:W14) -> 238 | J13: =J12 -> 0 | K13: ='FS Seychelles'!AA14 -> 167 | L13: =L12 -> 0 | M13: ='FS Seychelles'!B14 -> 26
A14: Seychelles | B14: =B13+1 -> 13 | C14: =C13 -> 9 | D14: 2022 | E14: =SUM('FS Seychelles'!D15:I15)*1000 -> 17750 | F14: =(('FS Seychelles'!O15*'FS Seychelles'!P15)+('FS Seychelles'!Q15*'FS Seychelles'!R15))/TOTAL!E14 -> 0.5390062 | G14: =('FS Seychelles'!$Z$10+'FS Seychelles'!$Z$15)/30 -> 319.06667 | H14: =H13 -> 1.05 | I14: =SUM('FS Seychelles'!S15:W15) -> 331 | J14: =J13 -> 0 | K14: ='FS Seychelles'!AA15 -> 122 | L14: =L13 -> 0 | M14: ='FS Seychelles'!B15 -> 61
... A31: Seychelles | B31: =B30+1 -> 30 | C31: =C30 -> 9 | D31: 2022 | E31: =SUM('FS Seychelles'!D32:I32)*1000 -> 18720 | F31: =(('FS Seychelles'!O32*'FS Seychelles'!P32)+('FS Seychelles'!Q32*'FS Seychelles'!R32))/TOTAL!E31 -> 0.54293857 | G31: =('FS Seychelles'!$Z$10+'FS Seychelles'!$Z$15)/30 -> 319.06667 | H31: =H30 -> 1.05 | I31: =SUM('FS Seychelles'!S32:W32) -> 241 | J31: =J30 -> 0 | K31: ='FS Seychelles'!AA32 -> 51 | L31: =L30 -> 0 | M31: ='FS Seychelles'!B32 -> 0

Sheet Submetering 
A1: Site Name | B1: Day | C1: Month | D1: Year | E1: Room Night | F1: SS-A - KWh | G1: SS-B- KWh | H1: SS-C- KWh | I1: FIRE PUMP- KWh | J1: CASINO- KWh | K1: BOH- KWh | L1: Generator#1 - KWh | M1: Generator#2- KWh | N1: Generator#3- KWh | O1: Generator#4- KWh | P1: Generator#5- KWh | Q1: DIESEL - Liter | R1: PUC - KWh | S1: BOH Water- m3 | T1: WT59- m3 | U1: WT08- m3 | V1: PUC (HOH)- m3 | W1: Fire Pump- m3 | X1: LPG (Kg)
A2: Seychelles | B2: 1 | C2: 9 | D2: 2022 | E2: ='FS Seychelles'!B3 -> 60.5 | F2: ='FS Seychelles'!D3*1000 -> 2600 | G2: ='FS Seychelles'!E3*1000 -> 3840 | H2: ='FS Seychelles'!F3*1000 -> 4710 | I2: ='FS Seychelles'!G3*1000 -> 1320 | J2: ='FS Seychelles'!H3*1000 -> 1400 | K2: ='FS Seychelles'!I3*1000 -> 3860 | L2: ='FS Seychelles'!J3 -> 0 | M2: ='FS Seychelles'!K3 -> 11145 | N2: ='FS Seychelles'!L3 -> 9387 | O2: ='FS Seychelles'!M3 -> 5034 | P2: ='FS Seychelles'!N3 -> 5851 | Q2: ='FS Seychelles'!O3 -> 6884 | R2: ='FS Seychelles'!Q3 -> 0 | S2: ='FS Seychelles'!S3 -> 59 | T2: ='FS Seychelles'!T3 -> 97 | U2: ='FS Seychelles'!U3 -> 50 | V2: ='FS Seychelles'!V3 -> 76 | W2: ='FS Seychelles'!W3 -> 0 | X2: =('FS Seychelles'!Z9+'FS Seychelles'!Z15)/30 -> 319.06667
A3: Seychelles | B3: =B2+1 -> 2 | C3: =C2 -> 9 | D3: 2022 | E3: ='FS Seychelles'!B4 -> 67.1 | F3: ='FS Seychelles'!D4*1000 -> 2790 | G3: ='FS Seychelles'!E4*1000 -> 4040 | H3: ='FS Seychelles'!F4*1000 -> 4980 | I3: ='FS Seychelles'!G4*1000 -> 1190 | J3: ='FS Seychelles'!H4*1000 -> 1510 | K3: ='FS Seychelles'!I4*1000 -> 3670 | L3: ='FS Seychelles'!J4 -> 0 | M3: ='FS Seychelles'!K4 -> 5427 | N3: ='FS Seychelles'!L4 -> 9988 | O3: ='FS Seychelles'!M4 -> 227 | P3: ='FS Seychelles'!N4 -> 7017 | Q3: ='FS Seychelles'!O4 -> 4847 | R3: ='FS Seychelles'!Q4 -> 0 | S3: ='FS Seychelles'!S4 -> 52 | T3: ='FS Seychelles'!T4 -> 126 | U3: ='FS Seychelles'!U4 -> 77 | V3: ='FS Seychelles'!V4 -> 92 | W3: ='FS Seychelles'!W4 -> 0 | X3: =('FS Seychelles'!Z10+'FS Seychelles'!Z16)/30 -> 38.4
A4: Seychelles | B4: =B3+1 -> 3 | C4: =C3 -> 9 | D4: 2022 | E4: ='FS Seychelles'!B5 -> 65.8 | F4: ='FS Seychelles'!D5*1000 -> 2800 | G4: ='FS Seychelles'!E5*1000 -> 3900 | H4: ='FS Seychelles'!F5*1000 -> 5080 | I4: ='FS Seychelles'!G5*1000 -> 1220 | J4: ='FS Seychelles'!H5*1000 -> 1460 | K4: ='FS Seychelles'!I5*1000 -> 3560 | L4: ='FS Seychelles'!J5 -> 5243 | M4: ='FS Seychelles'!K5 -> 10249 | N4: ='FS Seychelles'!L5 -> 9186 | O4: ='FS Seychelles'!M5 -> 6498 | P4: ='FS Seychelles'!N5 -> 0 | Q4: ='FS Seychelles'!O5 -> 7114 | R4: ='FS Seychelles'!Q5 -> 0 | S4: ='FS Seychelles'!S5 -> 36 | T4: ='FS Seychelles'!T5 -> 119 | U4: ='FS Seychelles'!U5 -> 67 | V4: ='FS Seychelles'!V5 -> 96 | W4: ='FS Seychelles'!W5 -> 0 | X4: =('FS Seychelles'!Z11+'FS Seychelles'!Z17)/30 -> 0
A5: Seychelles | B5: =B4+1 -> 4 | C5: =C4 -> 9 | D5: 2022 | E5: ='FS Seychelles'!B6 -> 63.2 | F5: ='FS Seychelles'!D6*1000 -> 2680 | G5: ='FS Seychelles'!E6*1000 -> 3970 | H5: ='FS Seychelles'!F6*1000 -> 4920 | I5: ='FS Seychelles'!G6*1000 -> 1250 | J5: ='FS Seychelles'!H6*1000 -> 1400 | K5: ='FS Seychelles'!I6*1000 -> 3550 | L5: ='FS Seychelles'!J6 -> 0 | M5: ='FS Seychelles'!K6 -> 8561 | N5: ='FS Seychelles'!L6 -> 9841 | O5: ='FS Seychelles'!M6 -> 5563 | P5: ='FS Seychelles'!N6 -> 6333 | Q5: ='FS Seychelles'!O6 -> 6819 | R5: ='FS Seychelles'!Q6 -> 0 | S5: ='FS Seychelles'!S6 -> 75 | T5: ='FS Seychelles'!T6 -> 136 | U5: ='FS Seychelles'!U6 -> 54 | V5: ='FS Seychelles'!V6 -> 92 | W5: ='FS Seychelles'!W6 -> 0 | X5: =('FS Seychelles'!Z12+'FS Seychelles'!Z18)/30 -> 0
A6: Seychelles | B6: =B5+1 -> 5 | C6: =C5 -> 9 | D6: 2022 | E6: ='FS Seychelles'!B7 -> 64.5 | F6: ='FS Seychelles'!D7*1000 -> 2620 | G6: ='FS Seychelles'!E7*1000 -> 4030 | H6: ='FS Seychelles'!F7*1000 -> 4940 | I6: ='FS Seychelles'!G7*1000 -> 1350 | J6: ='FS Seychelles'!H7*1000 -> 1370 | K6: ='FS Seychelles'!I7*1000 -> 3910 | L6: ='FS Seychelles'!J7 -> 9983 | M6: ='FS Seychelles'!K7 -> 5254 | N6: ='FS Seychelles'!L7 -> 10539 | O6: ='FS Seychelles'!M7 -> 6832 | P6: ='FS Seychelles'!N7 -> 0 | Q6: ='FS Seychelles'!O7 -> 7251 | R6: ='FS Seychelles'!Q7 -> 0 | S6: ='FS Seychelles'!S7 -> 45 | T6: ='FS Seychelles'!T7 -> 124 | U6: ='FS Seychelles'!U7 -> 75 | V6: ='FS Seychelles'!V7 -> 90 | W6: ='FS Seychelles'!W7 -> 0 | X6: =('FS Seychelles'!Z13+'FS Seychelles'!Z19)/30 -> 0
A7: Seychelles | B7: =B6+1 -> 6 | C7: =C6 -> 9 | D7: 2022 | E7: ='FS Seychelles'!B8 -> 63.2 | F7: ='FS Seychelles'!D8*1000 -> 2840 | G7: ='FS Seychelles'!E8*1000 -> 4020 | H7: ='FS Seychelles'!F8*1000 -> 5140 | I7: ='FS Seychelles'!G8*1000 -> 1350 | J7: ='FS Seychelles'!H8*1000 -> 1590 | K7: ='FS Seychelles'!I8*1000 -> 4050 | L7: ='FS Seychelles'!J8 -> 11001 | M7: ='FS Seychelles'!K8 -> 4936 | N7: ='FS Seychelles'!L8 -> 6155 | O7: ='FS Seychelles'!M8 -> 0 | P7: ='FS Seychelles'!N8 -> 11089 | Q7: ='FS Seychelles'!O8 -> 7392 | R7: ='FS Seychelles'!Q8 -> 0 | S7: ='FS Seychelles'!S8 -> 58 | T7: ='FS Seychelles'!T8 -> 127 | U7: ='FS Seychelles'!U8 -> 59 | V7: ='FS Seychelles'!V8 -> 65 | W7: ='FS Seychelles'!W8 -> 0 | X7: =('FS Seychelles'!Z14+'FS Seychelles'!Z20)/30 -> 0
A8: Seychelles | B8: =B7+1 -> 7 | C8: =C7 -> 9 | D8: 2022 | E8: ='FS Seychelles'!B9 -> 66.2 | F8: ='FS Seychelles'!D9*1000 -> 2770 | G8: ='FS Seychelles'!E9*1000 -> 3940 | H8: ='FS Seychelles'!F9*1000 -> 5300 | I8: ='FS Seychelles'!G9*1000 -> 1340 | J8: ='FS Seychelles'!H9*1000 -> 1530 | K8: ='FS Seychelles'!I9*1000 -> 4030 | L8: ='FS Seychelles'!J9 -> 8993 | M8: ='FS Seychelles'!K9 -> 5031 | N8: ='FS Seychelles'!L9 -> 5523 | O8: ='FS Seychelles'!M9 -> 0 | P8: ='FS Seychelles'!N9 -> 9113 | Q8: ='FS Seychelles'!O9 -> 6050 | R8: ='FS Seychelles'!Q9 -> 0 | S8: ='FS Seychelles'!S9 -> 57 | T8: ='FS Seychelles'!T9 -> 138 | U8: ='FS Seychelles'!U9 -> 46 | V8: ='FS Seychelles'!V9 -> 98 | W8: ='FS Seychelles'!W9 -> 0 | X8: =('FS Seychelles'!Z15+'FS Seychelles'!Z21)/30 -> 280.66667
A9: Seychelles | B9: =B8+1 -> 8 | C9: =C8 -> 9 | D9: 2022 | E9: ='FS Seychelles'!B10 -> 66.2 | F9: ='FS Seychelles'!D10*1000 -> 2610 | G9: ='FS Seychelles'!E10*1000 -> 3660 | H9: ='FS Seychelles'!F10*1000 -> 5190 | I9: ='FS Seychelles'!G10*1000 -> 1320 | J9: ='FS Seychelles'!H10*1000 -> 1540 | K9: ='FS Seychelles'!I10*1000 -> 3980 | L9: ='FS Seychelles'!J10 -> 13400 | M9: ='FS Seychelles'!K10 -> 4187 | N9: ='FS Seychelles'!L10 -> 4236 | O9: ='FS Seychelles'!M10 -> 0 | P9: ='FS Seychelles'!N10 -> 11270 | Q9: ='FS Seychelles'!O10 -> 7315 | R9: ='FS Seychelles'!Q10 -> 0 | S9: ='FS Seychelles'!S10 -> 61 | T9: ='FS Seychelles'!T10 -> 143 | U9: ='FS Seychelles'!U10 -> 0 | V9: ='FS Seychelles'!V10 -> 112 | W9: ='FS Seychelles'!W10 -> 38 | X9: =('FS Seychelles'!Z16+'FS Seychelles'!Z22)/30 -> 0
A10: Seychelles | B10: =B9+1 -> 9 | C10: =C9 -> 9 | D10: 2022 | E10: ='FS Seychelles'!B11 -> 70.1 | F10: ='FS Seychelles'!D11*1000 -> 2600 | G10: ='FS Seychelles'!E11*1000 -> 3880 | H10: ='FS Seychelles'!F11*1000 -> 4980 | I10: ='FS Seychelles'!G11*1000 -> 1310 | J10: ='FS Seychelles'!H11*1000 -> 1500 | K10: ='FS Seychelles'!I11*1000 -> 3850 | L10: ='FS Seychelles'!J11 -> 10915 | M10: ='FS Seychelles'!K11 -> 9533 | N10: ='FS Seychelles'!L11 -> 8669 | O10: ='FS Seychelles'!M11 -> 0 | P10: ='FS Seychelles'!N11 -> 2255 | Q10: ='FS Seychelles'!O11 -> 6632 | R10: ='FS Seychelles'!Q11 -> 0 | S10: ='FS Seychelles'!S11 -> 59 | T10: ='FS Seychelles'!T11 -> 99 | U10: ='FS Seychelles'!U11 -> 67 | V10: ='FS Seychelles'!V11 -> 101 | W10: ='FS Seychelles'!W11 -> 0 | X10: =('FS Seychelles'!Z17+'FS Seychelles'!Z23)/30 -> 0
A11: Seychelles | B11: =B10+1 -> 10 | C11: =C10 -> 9 | D11: 2022 | E11: ='FS Seychelles'!B12 -> 57.1 | F11: ='FS Seychelles'!D12*1000 -> 2660 | G11: ='FS Seychelles'!E12*1000 -> 4330 | H11: ='FS Seychelles'!F12*1000 -> 5380 | I11: ='FS Seychelles'!G12*1000 -> 1270 | J11: ='FS Seychelles'!H12*1000 -> 1600 | K11: ='FS Seychelles'!I12*1000 -> 3830 | L11: ='FS Seychelles'!J12 -> 7215 | M11: ='FS Seychelles'!K12 -> 11630 | N11: ='FS Seychelles'!L12 -> 3527 | O11: ='FS Seychelles'!M12 -> 0 | P11: ='FS Seychelles'!N12 -> 10138 | Q11: ='FS Seychelles'!O12 -> 7223 | R11: ='FS Seychelles'!Q12 -> 0 | S11: ='FS Seychelles'!S12 -> 56 | T11: ='FS Seychelles'!T12 -> 106 | U11: ='FS Seychelles'!U12 -> 71 | V11: ='FS Seychelles'!V12 -> 74 | W11: ='FS Seychelles'!W12 -> 0 | X11: =('FS Seychelles'!Z18+'FS Seychelles'!Z24)/30 -> 0
A12: Seychelles | B12: =B11+1 -> 11 | C12: =C11 -> 9 | D12: 2022 | E12: ='FS Seychelles'!B13 -> 40.3 | F12: ='FS Seychelles'!D13*1000 -> 2080 | G12: ='FS Seychelles'!E13*1000 -> 3780 | H12: ='FS Seychelles'!F13*1000 -> 4840 | I12: ='FS Seychelles'!G13*1000 -> 1220 | J12: ='FS Seychelles'!H13*1000 -> 1520 | K12: ='FS Seychelles'!I13*1000 -> 3580 | L12: ='FS Seychelles'!J13 -> 8676 | M12: ='FS Seychelles'!K13 -> 6091 | N12: ='FS Seychelles'!L13 -> 8629 | O12: ='FS Seychelles'!M13 -> 0 | P12: ='FS Seychelles'!N13 -> 0 | Q12: ='FS Seychelles'!O13 -> 5114 | R12: ='FS Seychelles'!Q13 -> 0 | S12: ='FS Seychelles'!S13 -> 49 | T12: ='FS Seychelles'!T13 -> 119 | U12: ='FS Seychelles'!U13 -> 54 | V12: ='FS Seychelles'!V13 -> 11 | W12: ='FS Seychelles'!W13 -> 0 | X12: =('FS Seychelles'!Z19+'FS Seychelles'!Z25)/30 -> 0
A13: Seychelles | B13: =B12+1 -> 12 | C13: =C12 -> 9 | D13: 2022 | E13: ='FS Seychelles'!B14 -> 26 | F13: ='FS Seychelles'!D14*1000 -> 2200 | G13: ='FS Seychelles'!E14*1000 -> 3650 | H13: ='FS Seychelles'!F14*1000 -> 4750 | I13: ='FS Seychelles'!G14*1000 -> 1310 | J13: ='FS Seychelles'!H14*1000 -> 1600 | K13: ='FS Seychelles'!I14*1000 -> 3810 | L13: ='FS Seychelles'!J14 -> 9849 | M13: ='FS Seychelles'!K14 -> 10610 | N13: ='FS Seychelles'!L14 -> 10278 | O13: ='FS Seychelles'!M14 -> 0 | P13: ='FS Seychelles'!N14 -> 9645 | Q13: ='FS Seychelles'!O14 -> 8804 | R13: ='FS Seychelles'!Q14 -> 0 | S13: ='FS Seychelles'!S14 -> 55 | T13: ='FS Seychelles'!T14 -> 107 | U13: ='FS Seychelles'!U14 -> 73 | V13: ='FS Seychelles'!V14 -> 3 | W13: ='FS Seychelles'!W14 -> 0 | X13: =('FS Seychelles'!Z20+'FS Seychelles'!Z26)/30 -> 0
A14: Seychelles | B14: =B13+1 -> 13 | C14: =C13 -> 9 | D14: 2022 | E14: ='FS Seychelles'!B15 -> 61 | F14: ='FS Seychelles'!D15*1000 -> 2220 | G14: ='FS Seychelles'!E15*1000 -> 3780 | H14: ='FS Seychelles'!F15*1000 -> 4940 | I14: ='FS Seychelles'!G15*1000 -> 1300 | J14: ='FS Seychelles'!H15*1000 -> 1570 | K14: ='FS Seychelles'!I15*1000 -> 3940 | L14: ='FS Seychelles'!J15 -> 9921 | M14: ='FS Seychelles'!K15 -> 5495 | N14: ='FS Seychelles'!L15 -> 8239 | O14: ='FS Seychelles'!M15 -> 0 | P14: ='FS Seychelles'!N15 -> 5472 | Q14: ='FS Seychelles'!O15 -> 6336 | R14: ='FS Seychelles'!Q15 -> 0 | S14: ='FS Seychelles'!S15 -> 54 | T14: ='FS Seychelles'!T15 -> 154 | U14: ='FS Seychelles'!U15 -> 52 | V14: ='FS Seychelles'!V15 -> 71 | W14: ='FS Seychelles'!W15 -> 0 | X14: =('FS Seychelles'!Z21+'FS Seychelles'!Z27)/30 -> 0
... A19: Seychelles | B19: =B18+1 -> 18 | C19: =C18 -> 9 | D19: 2022 | E19: ='FS Seychelles'!B20 -> 76.6 | F19: ='FS Seychelles'!D20*1000 -> 2680 | G19: ='FS Seychelles'!E20*1000 -> 4100 | H19: ='FS Seychelles'!F20*1000 -> 5240 | I19: ='FS Seychelles'!G20*1000 -> 1240 | J19: ='FS Seychelles'!H20*1000 -> 1740 | K19: ='FS Seychelles'!I20*1000 -> 3490 | L19: ='FS Seychelles'!J20 -> 8001 | M19: ='FS Seychelles'!K20 -> 7994 | N19: ='FS Seychelles'!L20 -> 7955 | O19: ='FS Seychelles'!M20 -> 0 | P19: ='FS Seychelles'!N20 -> 7690 | Q19: ='FS Seychelles'!O20 -> 6931 | R19: ='FS Seychelles'!Q20 -> 0 | S19: ='FS Seychelles'!S20 -> 43 | T19: ='FS Seychelles'!T20 -> 89 | U19: ='FS Seychelles'!U20 -> 34 | V19: ='FS Seychelles'!V20 -> 89 | W19: ='FS Seychelles'!W20 -> 0 | X19: =('FS Seychelles'!Z26+'FS Seychelles'!Z32)/30 -> 0
A20: Seychelles | B20: =B19+1 -> 19 | C20: =C19 -> 9 | D20: 2022 | E20: ='FS Seychelles'!B21 -> 76.6 | F20: ='FS Seychelles'!D21*1000 -> 2380 | G20: ='FS Seychelles'!E21*1000 -> 3800 | H20: ='FS Seychelles'!F21*1000 -> 4940 | I20: ='FS Seychelles'!G21*1000 -> 1260 | J20: ='FS Seychelles'!H21*1000 -> 1780 | K20: ='FS Seychelles'!I21*1000 -> 3560 | L20: ='FS Seychelles'!J21 -> 10758 | M20: ='FS Seychelles'!K21 -> 4942 | N20: ='FS Seychelles'!L21 -> 10374 | O20: ='FS Seychelles'!M21 -> 0 | P20: ='FS Seychelles'!N21 -> 4892 | Q20: ='FS Seychelles'!O21 -> 6673 | R20: ='FS Seychelles'!Q21 -> 0 | S20: ='FS Seychelles'!S21 -> 53 | T20: ='FS Seychelles'!T21 -> 65 | U20: ='FS Seychelles'!U21 -> 38 | V20: ='FS Seychelles'!V21 -> 17 | W20: ='FS Seychelles'!W21 -> 0 | X20: =('FS Seychelles'!Z27+'FS Seychelles'!#REF!)/30 -> #REF!
A21: Seychelles | B21: =B20+1 -> 20 | C21: =C20 -> 9 | D21: 2022 | E21: ='FS Seychelles'!B22 -> 76.6 | F21: ='FS Seychelles'!D22*1000 -> 2490 | G21: ='FS Seychelles'!E22*1000 -> 4130 | H21: ='FS Seychelles'!F22*1000 -> 5250 | I21: ='FS Seychelles'!G22*1000 -> 1330 | J21: ='FS Seychelles'!H22*1000 -> 1850 | K21: ='FS Seychelles'!I22*1000 -> 3900 | L21: ='FS Seychelles'!J22 -> 7020 | M21: ='FS Seychelles'!K22 -> 11583 | N21: ='FS Seychelles'!L22 -> 4713 | O21: ='FS Seychelles'!M22 -> 0 | P21: ='FS Seychelles'!N23 -> 0 | Q21: ='FS Seychelles'!O22 -> 7341 | R21: ='FS Seychelles'!Q22 -> 0 | S21: ='FS Seychelles'!S22 -> 53.857143 | T21: ='FS Seychelles'!T22 -> 111.71429 | U21: ='FS Seychelles'!U22 -> 52.5 | V21: ='FS Seychelles'!V22 -> 55.642857 | W21: ='FS Seychelles'!W22 -> 2.7142857 | X21: 0
A22: Seychelles | B22: =B21+1 -> 21 | C22: =C21 -> 9 | D22: 2022 | E22: ='FS Seychelles'!B23 -> 76.6 | F22: ='FS Seychelles'!D23*1000 -> 2010 | G22: ='FS Seychelles'!E23*1000 -> 3750 | H22: ='FS Seychelles'!F23*1000 -> 5130 | I22: ='FS Seychelles'!G23*1000 -> 1320 | J22: ='FS Seychelles'!H23*1000 -> 1730 | K22: ='FS Seychelles'!I23*1000 -> 3890 | L22: ='FS Seychelles'!J23 -> 10890 | M22: ='FS Seychelles'!K23 -> 10920 | N22: ='FS Seychelles'!L23 -> 4163 | O22: ='FS Seychelles'!M23 -> 4011 | P22: ='FS Seychelles'!N24 -> 0 | Q22: ='FS Seychelles'!O23 -> 6722 | R22: ='FS Seychelles'!Q23 -> 0 | S22: ='FS Seychelles'!S23 -> 57 | T22: ='FS Seychelles'!T23 -> 112 | U22: ='FS Seychelles'!U23 -> 44 | V22: ='FS Seychelles'!V23 -> 43 | W22: ='FS Seychelles'!W23 -> 0 | X22: 0
A23: Seychelles | B23: =B22+1 -> 22 | C23: =C22 -> 9 | D23: 2022 | E23: ='FS Seychelles'!B24 -> 77.9 | F23: ='FS Seychelles'!D24*1000 -> 600 | G23: ='FS Seychelles'!E24*1000 -> 1160 | H23: ='FS Seychelles'!F24*1000 -> 1830 | I23: ='FS Seychelles'!G24*1000 -> 530 | J23: ='FS Seychelles'!H24*1000 -> 520 | K23: ='FS Seychelles'!I24*1000 -> 1460 | L23: ='FS Seychelles'!J24 -> 10004 | M23: ='FS Seychelles'!K24 -> 10694 | N23: ='FS Seychelles'!L24 -> 4310 | O23: ='FS Seychelles'!M24 -> 4057 | P23: ='FS Seychelles'!N25 -> 11020 | Q23: ='FS Seychelles'!O24 -> 6441 | R23: ='FS Seychelles'!Q24 -> 0 | S23: ='FS Seychelles'!S24 -> 58 | T23: ='FS Seychelles'!T24 -> 113 | U23: ='FS Seychelles'!U24 -> 48 | V23: ='FS Seychelles'!V24 -> 86 | W23: ='FS Seychelles'!W24 -> 0 | X23: =('FS Seychelles'!Z30+'FS Seychelles'!#REF!)/30 -> #REF!
A24: Seychelles | B24: =B23+1 -> 23 | C24: =C23 -> 9 | D24: 2022 | E24: ='FS Seychelles'!B25 -> 74 | F24: ='FS Seychelles'!D25*1000 -> 2800 | G24: ='FS Seychelles'!E25*1000 -> 4610 | H24: ='FS Seychelles'!F25*1000 -> 5370 | I24: ='FS Seychelles'!G25*1000 -> 1150 | J24: ='FS Seychelles'!H25*1000 -> 1640 | K24: ='FS Seychelles'!I25*1000 -> 3600 | L24: ='FS Seychelles'!J25 -> 4523 | M24: ='FS Seychelles'!K25 -> 10983 | N24: ='FS Seychelles'!L25 -> 7765 | O24: ='FS Seychelles'!M25 -> 0 | P24: ='FS Seychelles'!N25 -> 11020 | Q24: ='FS Seychelles'!O25 -> 7438 | R24: ='FS Seychelles'!Q25 -> 0 | S24: ='FS Seychelles'!S25 -> 56 | T24: ='FS Seychelles'!T25 -> 104 | U24: ='FS Seychelles'!U25 -> 57 | V24: ='FS Seychelles'!V25 -> 41 | W24: ='FS Seychelles'!W25 -> 0 | X24: =('FS Seychelles'!Z31+'FS Seychelles'!#REF!)/30 -> #REF!
A25: Seychelles | B25: =B24+1 -> 24 | C25: =C24 -> 9 | D25: 2022 | E25: ='FS Seychelles'!B26 -> 75.3 | F25: ='FS Seychelles'!D26*1000 -> 3090 | G25: ='FS Seychelles'!E26*1000 -> 4400 | H25: ='FS Seychelles'!F26*1000 -> 5440 | I25: ='FS Seychelles'!G26*1000 -> 1350 | J25: ='FS Seychelles'!H26*1000 -> 1640 | K25: ='FS Seychelles'!I26*1000 -> 3800 | L25: ='FS Seychelles'!J26 -> 9679 | M25: ='FS Seychelles'!K26 -> 9437 | N25: ='FS Seychelles'!L26 -> 5959 | O25: ='FS Seychelles'!M26 -> 5764 | P25: ='FS Seychelles'!N26 -> 9431 | Q25: ='FS Seychelles'!O26 -> 8942 | R25: ='FS Seychelles'!Q26 -> 0 | S25: ='FS Seychelles'!S26 -> 45 | T25: ='FS Seychelles'!T26 -> 95 | U25: ='FS Seychelles'!U26 -> 57 | V25: ='FS Seychelles'!V26 -> 95 | W25: ='FS Seychelles'!W26 -> 0 | X25: =('FS Seychelles'!Z32+'FS Seychelles'!Z33)/30 -> 0
A26: Seychelles | B26: =B25+1 -> 25 | C26: =C25 -> 9 | D26: 2022 | E26: ='FS Seychelles'!B27 -> 55.8 | F26: ='FS Seychelles'!D27*1000 -> 2880 | G26: ='FS Seychelles'!E27*1000 -> 4210 | H26: ='FS Seychelles'!F27*1000 -> 5100 | I26: ='FS Seychelles'!G27*1000 -> 1380 | J26: ='FS Seychelles'!H27*1000 -> 1590 | K26: ='FS Seychelles'!I27*1000 -> 3660 | L26: ='FS Seychelles'!J27 -> 2127 | M26: ='FS Seychelles'!K27 -> 9582 | N26: ='FS Seychelles'!L27 -> 0 | O26: ='FS Seychelles'!M27 -> 5393 | P26: ='FS Seychelles'!N27 -> 10027 | Q26: ='FS Seychelles'!O27 -> 6040 | R26: ='FS Seychelles'!Q27 -> 0 | S26: ='FS Seychelles'!S27 -> 51 | T26: ='FS Seychelles'!T27 -> 102 | U26: ='FS Seychelles'!U27 -> 36 | V26: ='FS Seychelles'!V27 -> 115 | W26: ='FS Seychelles'!W27 -> 0 | X26: =('FS Seychelles'!#REF!+'FS Seychelles'!Z34)/30 -> #REF!
A27: Seychelles | B27: =B26+1 -> 26 | C27: =C26 -> 9 | D27: 2022 | E27: ='FS Seychelles'!B28 -> 51.9 | F27: ='FS Seychelles'!D28*1000 -> 2870 | G27: ='FS Seychelles'!E28*1000 -> 4330 | H27: ='FS Seychelles'!F28*1000 -> 5160 | I27: ='FS Seychelles'!G28*1000 -> 1320 | J27: ='FS Seychelles'!H28*1000 -> 1710 | K27: ='FS Seychelles'!I28*1000 -> 3840 | L27: ='FS Seychelles'!J28 -> 6749 | M27: ='FS Seychelles'!K28 -> 5242 | N27: ='FS Seychelles'!L28 -> 8756 | O27: ='FS Seychelles'!M28 -> 6946 | P27: ='FS Seychelles'!N28 -> 6039 | Q27: ='FS Seychelles'!O28 -> 7591 | R27: ='FS Seychelles'!Q28 -> 0 | S27: ='FS Seychelles'!S28 -> 57 | T27: ='FS Seychelles'!T28 -> 112 | U27: ='FS Seychelles'!U28 -> 53 | V27: ='FS Seychelles'!V28 -> 103 | W27: ='FS Seychelles'!W28 -> 0 | X27: 0
A28: Seychelles | B28: =B27+1 -> 27 | C28: =C27 -> 9 | D28: 2022 | E28: ='FS Seychelles'!B29 -> 49.4 | F28: ='FS Seychelles'!D29*1000 -> 2480 | G28: ='FS Seychelles'!E29*1000 -> 3530 | H28: ='FS Seychelles'!F29*1000 -> 5070 | I28: ='FS Seychelles'!G29*1000 -> 1390 | J28: ='FS Seychelles'!H29*1000 -> 1640 | K28: ='FS Seychelles'!I29*1000 -> 3750 | L28: ='FS Seychelles'!J29 -> 0 | M28: ='FS Seychelles'!K29 -> 1342 | N28: ='FS Seychelles'!L29 -> 4655 | O28: ='FS Seychelles'!M29 -> 4554 | P28: ='FS Seychelles'!N29 -> 11234 | Q28: ='FS Seychelles'!O29 -> 5813 | R28: ='FS Seychelles'!Q29 -> 0 | S28: ='FS Seychelles'!S29 -> 57 | T28: ='FS Seychelles'!T29 -> 131 | U28: ='FS Seychelles'!U29 -> 59 | V28: ='FS Seychelles'!V29 -> 111 | W28: ='FS Seychelles'!W29 -> 0 | X28: 0
A29: Seychelles | B29: =B28+1 -> 28 | C29: =C28 -> 9 | D29: 2022 | E29: ='FS Seychelles'!B30 -> 57.1 | F29: ='FS Seychelles'!D30*1000 -> 2550 | G29: ='FS Seychelles'!E30*1000 -> 3730 | H29: ='FS Seychelles'!F30*1000 -> 4950 | I29: ='FS Seychelles'!G30*1000 -> 1330 | J29: ='FS Seychelles'!H30*1000 -> 1560 | K29: ='FS Seychelles'!I30*1000 -> 3650 | L29: ='FS Seychelles'!J30 -> 6309 | M29: ='FS Seychelles'!K30 -> 10880 | N29: ='FS Seychelles'!L30 -> 0 | O29: ='FS Seychelles'!M30 -> 2245 | P29: ='FS Seychelles'!N30 -> 9031 | Q29: ='FS Seychelles'!O30 -> 6547 | R29: ='FS Seychelles'!Q30 -> 0 | S29: ='FS Seychelles'!S30 -> 46 | T29: ='FS Seychelles'!T30 -> 84 | U29: ='FS Seychelles'!U30 -> 96 | V29: ='FS Seychelles'!V30 -> 96 | W29: ='FS Seychelles'!W30 -> 0 | X29: =('FS Seychelles'!#REF!+'FS Seychelles'!Z37)/30 -> #REF!
A30: Seychelles | B30: =B29+1 -> 29 | C30: =C29 -> 9 | D30: 2022 | E30: ='FS Seychelles'!B31 -> 53.4 | F30: ='FS Seychelles'!D31*1000 -> 2680 | G30: ='FS Seychelles'!E31*1000 -> 4140 | H30: ='FS Seychelles'!F31*1000 -> 5110 | I30: ='FS Seychelles'!G31*1000 -> 1220 | J30: ='FS Seychelles'!H31*1000 -> 1660 | K30: ='FS Seychelles'!I31*1000 -> 3680 | L30: ='FS Seychelles'!J31 -> 9198 | M30: ='FS Seychelles'!K31 -> 6300 | N30: ='FS Seychelles'!L31 -> 9157 | O30: ='FS Seychelles'!M31 -> 0 | P30: ='FS Seychelles'!N31 -> 8721 | Q30: ='FS Seychelles'!O31 -> 6958 | R30: ='FS Seychelles'!Q31 -> 0 | S30: ='FS Seychelles'!S31 -> 55 | T30: ='FS Seychelles'!T31 -> 88 | U30: ='FS Seychelles'!U31 -> 99 | V30: ='FS Seychelles'!V31 -> 107 | W30: ='FS Seychelles'!W31 -> 0 | X30: =('FS Seychelles'!#REF!+'FS Seychelles'!Z38)/30 -> #REF!
A31: Seychelles | B31: =B30+1 -> 30 | C31: =C30 -> 9 | D31: 2022 | E31: ='FS Seychelles'!B32 -> 0 | F31: ='FS Seychelles'!D32*1000 -> 2870 | G31: ='FS Seychelles'!E32*1000 -> 4110 | H31: ='FS Seychelles'!F32*1000 -> 5100 | I31: ='FS Seychelles'!G32*1000 -> 1270 | J31: ='FS Seychelles'!H32*1000 -> 1680 | K31: ='FS Seychelles'!I32*1000 -> 3690 | L31: ='FS Seychelles'!J32 -> 8567 | M31: ='FS Seychelles'!K32 -> 6549 | N31: ='FS Seychelles'!L32 -> 7072 | O31: ='FS Seychelles'!M32 -> 0 | P31: ='FS Seychelles'!N32 -> 9399 | Q31: ='FS Seychelles'!O32 -> 6731 | R31: ='FS Seychelles'!Q32 -> 0 | S31: ='FS Seychelles'!S32 -> 59 | T31: ='FS Seychelles'!T32 -> 31 | U31: ='FS Seychelles'!U32 -> 48 | V31: ='FS Seychelles'!V32 -> 103 | W31: ='FS Seychelles'!W32 -> 0 | X31: =('FS Seychelles'!Z33+'FS Seychelles'!Z39)/30 -> 0
M32: =SUM(M2:M31) -> 239862 | N32: =SUM(N2:N31) -> 198137 | O32: =SUM(O2:O31) -> 57124
O34: =SUM(L32:O32) -> 495123

Sheet FS Seychelles
A2: DATE | B2: Room Night % | C2: Food Covers (Customers) | D2: SS-A (MWH) | E2: SS-B (MWH) | F2: SS-C (MWH) | G2: FIRE PUMP (MWH) | H2: CASINO (MWH) | I2: BOH (MWH) | J2: Generator#1 (KWH) | K2: Generator#2 (KWH) | L2: Generator#3 (KWH) | M2: Generator#4 (KWH) | N2: Generator#5 (KWH) | O2: DIESEL (Liter) | P2: DIESEL TARIFF (Euro/Liter) | Q2: PUC (KWh) | R2: PUC Tariff (Euro/KWh) | S2: BOH Water (m3) | T2: WT59 (m3) | U2: WT08 (m3) | V2: PUC HOH (m3) | W2: Fire Tank (m3) | X2: LPG (Kg) | AA2: STP Irrigation Water (m3) | AB2: Fire tank 250 (m3) | AC2: Comment
A3: 44805 | B3: 60.5 | C3: 285 | D3: ='EMS Gridvis'!B2 -> 2.6 | E3: ='EMS Gridvis'!C2 -> 3.84 | F3: ='EMS Gridvis'!D2 -> 4.71 | G3: ='EMS Gridvis'!H2 -> 1.32 | H3: ='EMS Gridvis'!I2 -> 1.4 | I3: ='EMS Gridvis'!J2 -> 3.86 | J3: =Generator!D4 -> 0 | K3: =Generator!H4 -> 11145 | L3: =Generator!L4 -> 9387 | M3: =Generator!P4 -> 5034 | N3: =Generator!T4 -> 5851 | O3: =SUM(Generator!C4,Generator!G4,Generator!K4,Generator!O4,Generator!S4) -> 6884 | P3: 1.51 | R3: 1.84 | S3: ='RO Plant'!B3 -> 59 | T3: ='RO Plant'!M3 -> 97 | U3: ='RO Plant'!F3 -> 50 | V3: ='RO Plant'!I3 -> 76 | W3: ='RO Plant'!G3 -> 0 | X3: CYLINDER DELIVERY (KG) | AA3: =AB3-AC3 -> 122 | AB3: 43037 | AC3: 42915 | AD3: 44804
A4: 44806 | B4: 67.1 | C4: 345 | D4: ='EMS Gridvis'!B3 -> 2.79 | E4: ='EMS Gridvis'!C3 -> 4.04 | F4: ='EMS Gridvis'!D3 -> 4.98 | G4: ='EMS Gridvis'!H3 -> 1.19 | H4: ='EMS Gridvis'!I3 -> 1.51 | I4: ='EMS Gridvis'!J3 -> 3.67 | J4: =Generator!D5 -> 0 | K4: =Generator!H5 -> 5427 | L4: =Generator!L5 -> 9988 | M4: =Generator!P5 -> 227 | N4: =Generator!T5 -> 7017 | O4: =SUM(Generator!C5,Generator!G5,Generator!K5,Generator!O5,Generator!S5) -> 4847 | P4: 1.51 | R4: =R3 -> 1.84 | S4: ='RO Plant'!B4 -> 52 | T4: ='RO Plant'!M4 -> 126 | U4: ='RO Plant'!F4 -> 77 | V4: ='RO Plant'!I4 -> 92 | W4: ='RO Plant'!G4 -> 0 | X4: Unit (kg) | Y4: Quantity | Z4: Sub total | AA4: =AB4-AB3 -> 153 | AB4: 43190
A5: 44807 | B5: 65.8 | C5: 389 | D5: ='EMS Gridvis'!B4 -> 2.8 | E5: ='EMS Gridvis'!C4 -> 3.9 | F5: ='EMS Gridvis'!D4 -> 5.08 | G5: ='EMS Gridvis'!H4 -> 1.22 | H5: ='EMS Gridvis'!I4 -> 1.46 | I5: ='EMS Gridvis'!J4 -> 3.56 | J5: =Generator!D6 -> 5243 | K5: =Generator!H6 -> 10249 | L5: =Generator!L6 -> 9186 | M5: =Generator!P6 -> 6498 | N5: =Generator!T6 -> 0 | O5: =SUM(Generator!C6,Generator!G6,Generator!K6,Generator!O6,Generator!S6) -> 7114 | P5: 1.51 | R5: =R4 -> 1.84 | S5: ='RO Plant'!B5 -> 36 | T5: ='RO Plant'!M5 -> 119 | U5: ='RO Plant'!F5 -> 67 | V5: ='RO Plant'!I5 -> 96 | W5: ='RO Plant'!G5 -> 0 | X5: 9 | Y5: 0 | Z5: =X5*Y5 -> 0 | AA5: =AB5-AB4 -> 108 | AB5: 43298
A6: 44808 | B6: 63.2 | C6: 389 | D6: ='EMS Gridvis'!B5 -> 2.68 | E6: ='EMS Gridvis'!C5 -> 3.97 | F6: ='EMS Gridvis'!D5 -> 4.92 | G6: ='EMS Gridvis'!H5 -> 1.25 | H6: ='EMS Gridvis'!I5 -> 1.4 | I6: ='EMS Gridvis'!J5 -> 3.55 | J6: =Generator!D7 -> 0 | K6: =Generator!H7 -> 8561 | L6: =Generator!L7 -> 9841 | M6: =Generator!P7 -> 5563 | N6: =Generator!T7 -> 6333 | O6: =SUM(Generator!C7,Generator!G7,Generator!K7,Generator!O7,Generator!S7) -> 6819 | P6: 1.51 | R6: =R5 -> 1.84 | S6: ='RO Plant'!B6 -> 75 | T6: ='RO Plant'!M6 -> 136 | U6: ='RO Plant'!F6 -> 54 | V6: ='RO Plant'!I6 -> 92 | W6: ='RO Plant'!G6 -> 0 | X6: 10 | Y6: 0 | Z6: =X6*Y6 -> 0 | AA6: =AB6-AB5 -> 118 | AB6: 43416
A7: 44809 | B7: 64.5 | C7: 331 | D7: ='EMS Gridvis'!B6 -> 2.62 | E7: ='EMS Gridvis'!C6 -> 4.03 | F7: ='EMS Gridvis'!D6 -> 4.94 | G7: ='EMS Gridvis'!H6 -> 1.35 | H7: ='EMS Gridvis'!I6 -> 1.37 | I7: ='EMS Gridvis'!J6 -> 3.91 | J7: =Generator!D8 -> 9983 | K7: =Generator!H8 -> 5254 | L7: =Generator!L8 -> 10539 | M7: =Generator!P8 -> 6832 | N7: =Generator!T8 -> 0 | O7: =SUM(Generator!C8,Generator!G8,Generator!K8,Generator!O8,Generator!S8) -> 7251 | P7: 1.51 | R7: =R6 -> 1.84 | S7: ='RO Plant'!B7 -> 45 | T7: ='RO Plant'!M7 -> 124 | U7: ='RO Plant'!F7 -> 75 | V7: ='RO Plant'!I7 -> 90 | W7: ='RO Plant'!G7 -> 0 | X7: 12 | Y7: 0 | Z7: =X7*Y7 -> 0 | AA7: =AB7-AB6 -> 89 | AB7: 43505
A8: 44810 | B8: 63.2 | C8: 334 | D8: ='EMS Gridvis'!B7 -> 2.84 | E8: ='EMS Gridvis'!C7 -> 4.02 | F8: ='EMS Gridvis'!D7 -> 5.14 | G8: ='EMS Gridvis'!H7 -> 1.35 | H8: ='EMS Gridvis'!I7 -> 1.59 | I8: ='EMS Gridvis'!J7 -> 4.05 | J8: =Generator!D9 -> 11001 | K8: =Generator!H9 -> 4936 | L8: =Generator!L9 -> 6155 | M8: =Generator!P9 -> 0 | N8: =Generator!T9 -> 11089 | O8: =SUM(Generator!C9,Generator!G9,Generator!K9,Generator!O9,Generator!S9) -> 7392 | P8: 1.51 | R8: =R7 -> 1.84 | S8: ='RO Plant'!B8 -> 58 | T8: ='RO Plant'!M8 -> 127 | U8: ='RO Plant'!F8 -> 59 | V8: ='RO Plant'!I8 -> 65 | W8: ='RO Plant'!G8 -> 0 | X8: 20 | Y8: 0 | Z8: =X8*Y8 -> 0 | AA8: =AB8-AB7 -> 157 | AB8: 43662
A9: 44811 | B9: 66.2 | C9: 368 | D9: ='EMS Gridvis'!B8 -> 2.77 | E9: ='EMS Gridvis'!C8 -> 3.94 | F9: ='EMS Gridvis'!D8 -> 5.3 | G9: ='EMS Gridvis'!H8 -> 1.34 | H9: ='EMS Gridvis'!I8 -> 1.53 | I9: ='EMS Gridvis'!J8 -> 4.03 | J9: =Generator!D10 -> 8993 | K9: =Generator!H10 -> 5031 | L9: =Generator!L10 -> 5523 | M9: =Generator!P10 -> 0 | N9: =Generator!T10 -> 9113 | O9: =SUM(Generator!C10,Generator!G10,Generator!K10,Generator!O10,Generator!S10) -> 6050 | P9: 1.51 | R9: =R8 -> 1.84 | S9: ='RO Plant'!B9 -> 57 | T9: ='RO Plant'!M9 -> 138 | U9: ='RO Plant'!F9 -> 46 | V9: ='RO Plant'!I9 -> 98 | W9: ='RO Plant'!G9 -> 0 | X9: 24 | Y9: 48 | Z9: =X9*Y9 -> 1152 | AA9: =AB9-AB8 -> 174 | AB9: 43836
A10: 44812 | B10: 66.2 | C10: 333 | D10: ='EMS Gridvis'!B9 -> 2.61 | E10: ='EMS Gridvis'!C9 -> 3.66 | F10: ='EMS Gridvis'!D9 -> 5.19 | G10: ='EMS Gridvis'!H9 -> 1.32 | H10: ='EMS Gridvis'!I9 -> 1.54 | I10: ='EMS Gridvis'!J9 -> 3.98 | J10: =Generator!D11 -> 13400 | K10: =Generator!H11 -> 4187 | L10: =Generator!L11 -> 4236 | M10: =Generator!P11 -> 0 | N10: =Generator!T11 -> 11270 | O10: =SUM(Generator!C11,Generator!G11,Generator!K11,Generator!O11,Generator!S11) -> 7315 | P10: 1.51 | R10: =25.21/13.6813 -> 1.8426612 | S10: ='RO Plant'!B10 -> 61 | T10: ='RO Plant'!M10 -> 143 | U10: ='RO Plant'!F10 -> 0 | V10: ='RO Plant'!I10 -> 112 | W10: ='RO Plant'!G10 -> 38 | Y10: Total | Z10: =SUM(Z5:Z9) -> 1152 | AA10: =AB10-AB9 -> 143 | AB10: 43979
A11: 44813 | B11: 70.1 | C11: 349 | D11: ='EMS Gridvis'!B10 -> 2.6 | E11: ='EMS Gridvis'!C10 -> 3.88 | F11: ='EMS Gridvis'!D10 -> 4.98 | G11: ='EMS Gridvis'!H10 -> 1.31 | H11: ='EMS Gridvis'!I10 -> 1.5 | I11: ='EMS Gridvis'!J10 -> 3.85 | J11: =Generator!D12 -> 10915 | K11: =Generator!H12 -> 9533 | L11: =Generator!L12 -> 8669 | M11: =Generator!P12 -> 0 | N11: =Generator!T12 -> 2255 | O11: =SUM(Generator!C12,Generator!G12,Generator!K12,Generator!O12,Generator!S12) -> 6632 | P11: 1.51 | R11: =R10 -> 1.8426612 | S11: ='RO Plant'!B11 -> 59 | T11: ='RO Plant'!M11 -> 99 | U11: ='RO Plant'!F11 -> 67 | V11: ='RO Plant'!I11 -> 101 | W11: ='RO Plant'!G11 -> 0 | X11: TRUCK DELIVERY (KG) | AA11: =AB11-AB10 -> 208 | AB11: 44187
A12: 44814 | B12: 57.1 | C12: 320 | D12: ='EMS Gridvis'!B11 -> 2.66 | E12: ='EMS Gridvis'!C11 -> 4.33 | F12: ='EMS Gridvis'!D11 -> 5.38 | G12: ='EMS Gridvis'!H11 -> 1.27 | H12: ='EMS Gridvis'!I11 -> 1.6 | I12: ='EMS Gridvis'!J11 -> 3.83 | J12: =Generator!D13 -> 7215 | K12: =Generator!H13 -> 11630 | L12: =Generator!L13 -> 3527 | M12: =Generator!P13 -> 0 | N12: =Generator!T13 -> 10138 | O12: =SUM(Generator!C13,Generator!G13,Generator!K13,Generator!O13,Generator!S13) -> 7223 | P12: 1.51 | R12: =R11 -> 1.8426612 | S12: ='RO Plant'!B12 -> 56 | T12: ='RO Plant'!M12 -> 106 | U12: ='RO Plant'!F12 -> 71 | V12: ='RO Plant'!I12 -> 74 | W12: ='RO Plant'!G12 -> 0 | Y12: Sub Total | AA12: =AB12-AB11 -> 167 | AB12: 44354
A13: 44815 | B13: 40.3 | C13: 264 | D13: ='EMS Gridvis'!B12 -> 2.08 | E13: ='EMS Gridvis'!C12 -> 3.78 | F13: ='EMS Gridvis'!D12 -> 4.84 | G13: ='EMS Gridvis'!H12 -> 1.22 | H13: ='EMS Gridvis'!I12 -> 1.52 | I13: ='EMS Gridvis'!J12 -> 3.58 | J13: =Generator!D14 -> 8676 | K13: =Generator!H14 -> 6091 | L13: =Generator!L14 -> 8629 | M13: =Generator!P14 -> 0 | N13: =Generator!T14 -> 0 | O13: =SUM(Generator!C14,Generator!G14,Generator!K14,Generator!O14,Generator!S14) -> 5114 | P13: 1.51 | R13: =R12 -> 1.8426612 | S13: ='RO Plant'!B13 -> 49 | T13: ='RO Plant'!M13 -> 119 | U13: ='RO Plant'!F13 -> 54 | V13: ='RO Plant'!I13 -> 11 | W13: ='RO Plant'!G13 -> 0 | X13: Sitronel | Y13: 5900 | AA13: =AB13-AB12 -> 128 | AB13: 44482
A14: 44816 | B14: 26 | C14: 190 | D14: ='EMS Gridvis'!B13 -> 2.2 | E14: ='EMS Gridvis'!C13 -> 3.65 | F14: ='EMS Gridvis'!D13 -> 4.75 | G14: ='EMS Gridvis'!H13 -> 1.31 | H14: ='EMS Gridvis'!I13 -> 1.6 | I14: ='EMS Gridvis'!J13 -> 3.81 | J14: =Generator!D15 -> 9849 | K14: =Generator!H15 -> 10610 | L14: =Generator!L15 -> 10278 | M14: =Generator!P15 -> 0 | N14: =Generator!T15 -> 9645 | O14: =SUM(Generator!C15,Generator!G15,Generator!K15,Generator!O15,Generator!S15) -> 8804 | P14: 1.51 | R14: =R13 -> 1.8426612 | S14: ='RO Plant'!B14 -> 55 | T14: ='RO Plant'!M14 -> 107 | U14: ='RO Plant'!F14 -> 73 | V14: ='RO Plant'!I14 -> 3 | W14: ='RO Plant'!G14 -> 0 | X14: Zez | Y14: 2520 | AA14: =AB14-AB13 -> 167 | AB14: 44649
A15: 44817 | B15: 61 | C15: 156 | D15: ='EMS Gridvis'!B14 -> 2.22 | E15: ='EMS Gridvis'!C14 -> 3.78 | F15: ='EMS Gridvis'!D14 -> 4.94 | G15: ='EMS Gridvis'!H14 -> 1.3 | H15: ='EMS Gridvis'!I14 -> 1.57 | I15: ='EMS Gridvis'!J14 -> 3.94 | J15: =Generator!D16 -> 9921 | K15: =Generator!H16 -> 5495 | L15: =Generator!L16 -> 8239 | M15: =Generator!P16 -> 0 | N15: =Generator!T16 -> 5472 | O15: =SUM(Generator!C16,Generator!G16,Generator!K16,Generator!O16,Generator!S16) -> 6336 | P15: 1.51 | R15: =R14 -> 1.8426612 | S15: ='RO Plant'!B15 -> 54 | T15: ='RO Plant'!M15 -> 154 | U15: ='RO Plant'!F15 -> 52 | V15: ='RO Plant'!I15 -> 71 | W15: ='RO Plant'!G15 -> 0 | Y15: Total | Z15: =SUM(Y13:Z14) -> 8420 | AA15: =AB15-AB14 -> 122 | AB15: 44771
A16: 44818 | B16: 62.3 | C16: 244 | D16: ='EMS Gridvis'!B15 -> 2.24 | E16: ='EMS Gridvis'!C15 -> 3.92 | F16: ='EMS Gridvis'!D15 -> 5.01 | G16: ='EMS Gridvis'!H15 -> 1.37 | H16: ='EMS Gridvis'!I15 -> 1.58 | I16: ='EMS Gridvis'!J15 -> 3.9 | J16: =Generator!D17 -> 8288 | K16: =Generator!H17 -> 7928 | L16: =Generator!L17 -> 0 | M16: =Generator!P17 -> 0 | N16: =Generator!T17 -> 7921 | O16: =SUM(Generator!C17,Generator!G17,Generator!K17,Generator!O17,Generator!S17) -> 5099 | P16: 1.51 | R16: =R15 -> 1.8426612 | S16: ='RO Plant'!B16 -> 55 | T16: ='RO Plant'!M16 -> 92 | U16: ='RO Plant'!F16 -> 66 | V16: ='RO Plant'!I16 -> 107 | W16: ='RO Plant'!G16 -> 0 | AA16: =AB16-AB15 -> 173 | AB16: 44944
A17: 44819 | B17: 28.6 | C17: 214 | D17: ='EMS Gridvis'!B16 -> 2.28 | E17: ='EMS Gridvis'!C16 -> 4.02 | F17: ='EMS Gridvis'!D16 -> 5.11 | G17: ='EMS Gridvis'!H16 -> 1.19 | H17: ='EMS Gridvis'!I16 -> 1.67 | I17: ='EMS Gridvis'!J16 -> 3.75 | J17: =Generator!D18 -> 10000 | K17: =Generator!H18 -> 8286 | L17: =Generator!L18 -> 7074 | M17: =Generator!P18 -> 0 | N17: =Generator!T18 -> 6490 | O17: =SUM(Generator!C18,Generator!G18,Generator!K18,Generator!O18,Generator!S18) -> 6924 | P17: 1.51 | R17: =R16 -> 1.8426612 | S17: ='RO Plant'!B17 -> 56 | T17: ='RO Plant'!M17 -> 116 | U17: ='RO Plant'!F17 -> 55 | V17: ='RO Plant'!I17 -> 1 | W17: ='RO Plant'!G17 -> 0 | AA17: =AB17-AB16 -> 114 | AB17: 45058
A18: 44820 | B18: 39 | C18: 170 | D18: ='EMS Gridvis'!B17 -> 2.12 | E18: ='EMS Gridvis'!C17 -> 3.73 | F18: ='EMS Gridvis'!D17 -> 4.87 | G18: ='EMS Gridvis'!H17 -> 1.34 | H18: ='EMS Gridvis'!I17 -> 1.68 | I18: ='EMS Gridvis'!J17 -> 3.89 | J18: =Generator!D19 -> 5288 | K18: =Generator!H19 -> 10096 | L18: =Generator!L19 -> 5307 | M18: =Generator!P19 -> 0 | N18: =Generator!T19 -> 10026 | O18: =SUM(Generator!C19,Generator!G19,Generator!K19,Generator!O19,Generator!S19) -> 6735 | P18: 1.51 | R18: =R17 -> 1.8426612 | S18: ='RO Plant'!B18 -> 49 | T18: ='RO Plant'!M18 -> 85 | U18: ='RO Plant'!F18 -> 76 | V18: ='RO Plant'!I18 -> 0 | W18: ='RO Plant'!G18 -> 0 | AA18: =AB18-AB17 -> 89 | AB18: 45147
A19: 44821 | B19: 53.2 | C19: 196 | D19: ='EMS Gridvis'!B18 -> 2.14 | E19: ='EMS Gridvis'!C18 -> 3.74 | F19: ='EMS Gridvis'!D18 -> 5.06 | G19: ='EMS Gridvis'!H18 -> 1.33 | H19: ='EMS Gridvis'!I18 -> 1.65 | I19: ='EMS Gridvis'!J18 -> 3.71 | J19: =Generator!D20 -> 6713 | K19: =Generator!H20 -> 8955 | L19: =Generator!L20 -> 6680 | M19: =Generator!P20 -> 0 | N19: =Generator!T20 -> 9036 | O19: =SUM(Generator!C20,Generator!G20,Generator!K20,Generator!O20,Generator!S20) -> 6968 | P19: 1.51 | R19: =R18 -> 1.8426612 | S19: ='RO Plant'!B19 -> 49 | T19: ='RO Plant'!M19 -> 124 | U19: ='RO Plant'!F19 -> 44 | V19: ='RO Plant'!I19 -> 30 | W19: ='RO Plant'!G19 -> 0 | AA19: =AB19-AB18 -> 120 | AB19: 45267
A20: 44822 | B20: 76.6 | C20: 429 | D20: ='EMS Gridvis'!B19 -> 2.68 | E20: ='EMS Gridvis'!C19 -> 4.1 | F20: ='EMS Gridvis'!D19 -> 5.24 | G20: ='EMS Gridvis'!H19 -> 1.24 | H20: ='EMS Gridvis'!I19 -> 1.74 | I20: ='EMS Gridvis'!J19 -> 3.49 | J20: =Generator!D21 -> 8001 | K20: =Generator!H21 -> 7994 | L20: =Generator!L21 -> 7955 | M20: =Generator!P21 -> 0 | N20: =Generator!T21 -> 7690 | O20: =SUM(Generator!C21,Generator!G21,Generator!K21,Generator!O21,Generator!S21) -> 6931 | P20: 1.51 | R20: =R19 -> 1.8426612 | S20: ='RO Plant'!B20 -> 43 | T20: ='RO Plant'!M20 -> 89 | U20: ='RO Plant'!F20 -> 34 | V20: ='RO Plant'!I20 -> 89 | W20: ='RO Plant'!G20 -> 0 | AA20: =AB20-AB19 -> -45267
A21: 44823 | B21: 76.6 | C21: 223 | D21: ='EMS Gridvis'!B20 -> 2.38 | E21: ='EMS Gridvis'!C20 -> 3.8 | F21: ='EMS Gridvis'!D20 -> 4.94 | G21: ='EMS Gridvis'!H20 -> 1.26 | H21: ='EMS Gridvis'!I20 -> 1.78 | I21: ='EMS Gridvis'!J20 -> 3.56 | J21: =Generator!D22 -> 10758 | K21: =Generator!H22 -> 4942 | L21: =Generator!L22 -> 10374 | M21: =Generator!P22 -> 0 | N21: =Generator!T22 -> 4892 | O21: =SUM(Generator!C22,Generator!G22,Generator!K22,Generator!O22,Generator!S22) -> 6673 | P21: 1.51 | R21: =R20 -> 1.8426612 | S21: ='RO Plant'!B21 -> 53 | T21: ='RO Plant'!M21 -> 65 | U21: ='RO Plant'!F21 -> 38 | V21: ='RO Plant'!I21 -> 17 | W21: ='RO Plant'!G21 -> 0 | AA21: =AB21-AB20 -> 45519 | AB21: 45519
A22: 44824 | B22: 76.6 | C22: 205 | D22: ='EMS Gridvis'!B21 -> 2.49 | E22: ='EMS Gridvis'!C21 -> 4.13 | F22: ='EMS Gridvis'!D21 -> 5.25 | G22: ='EMS Gridvis'!H21 -> 1.33 | H22: ='EMS Gridvis'!I21 -> 1.85 | I22: ='EMS Gridvis'!J21 -> 3.9 | J22: =Generator!D23 -> 7020 | K22: =Generator!H23 -> 11583 | L22: =Generator!L23 -> 4713 | M22: =Generator!P23 -> 0 | N22: =Generator!T23 -> 9817 | O22: =SUM(Generator!C23,Generator!G23,Generator!K23,Generator!O23,Generator!S23) -> 7341 | P22: 1.51 | R22: =R21 -> 1.8426612 | S22: ='RO Plant'!B22 -> 53.857143 | T22: ='RO Plant'!M22 -> 111.71429 | U22: ='RO Plant'!F22 -> 52.5 | V22: ='RO Plant'!I22 -> 55.642857 | W22: ='RO Plant'!G22 -> 2.7142857 | AA22: =AB22-AB21 -> -45519
A23: 44825 | B23: 76.6 | C23: 387 | D23: ='EMS Gridvis'!B22 -> 2.01 | E23: ='EMS Gridvis'!C22 -> 3.75 | F23: ='EMS Gridvis'!D22 -> 5.13 | G23: ='EMS Gridvis'!H22 -> 1.32 | H23: ='EMS Gridvis'!I22 -> 1.73 | I23: ='EMS Gridvis'!J22 -> 3.89 | J23: =Generator!D24 -> 10890 | K23: =Generator!H24 -> 10920 | L23: =Generator!L24 -> 4163 | M23: =Generator!P24 -> 4011 | N23: =Generator!T24 -> 0 | O23: =SUM(Generator!C24,Generator!G24,Generator!K24,Generator!O24,Generator!S24) -> 6722 | P23: 1.51 | R23: =R22 -> 1.8426612 | S23: ='RO Plant'!B23 -> 57 | T23: ='RO Plant'!M23 -> 112 | U23: ='RO Plant'!F23 -> 44 | V23: ='RO Plant'!I23 -> 43 | W23: ='RO Plant'!G23 -> 0 | AA23: =AB23-AB22 -> 0
A24: 44826 | B24: 77.9 | C24: 358 | D24: ='EMS Gridvis'!B23 -> 0.6 | E24: ='EMS Gridvis'!C23 -> 1.16 | F24: ='EMS Gridvis'!D23 -> 1.83 | G24: ='EMS Gridvis'!H23 -> 0.53 | H24: ='EMS Gridvis'!I23 -> 0.52 | I24: ='EMS Gridvis'!J23 -> 1.46 | J24: =Generator!D25 -> 10004 | K24: =Generator!H25 -> 10694 | L24: =Generator!L25 -> 4310 | M24: =Generator!P25 -> 4057 | N24: =Generator!T25 -> 0 | O24: =SUM(Generator!C25,Generator!G25,Generator!K25,Generator!O25,Generator!S25) -> 6441 | P24: 1.51 | R24: =R23 -> 1.8426612 | S24: ='RO Plant'!B24 -> 58 | T24: ='RO Plant'!M24 -> 113 | U24: ='RO Plant'!F24 -> 48 | V24: ='RO Plant'!I24 -> 86 | W24: ='RO Plant'!G24 -> 0 | AA24: =AB24-AB23 -> 0
A25: 44827 | B25: 74 | C25: 529 | D25: ='EMS Gridvis'!B24 -> 2.8 | E25: ='EMS Gridvis'!C24 -> 4.61 | F25: ='EMS Gridvis'!D24 -> 5.37 | G25: ='EMS Gridvis'!H24 -> 1.15 | H25: ='EMS Gridvis'!I24 -> 1.64 | I25: ='EMS Gridvis'!J24 -> 3.6 | J25: =Generator!D26 -> 4523 | K25: =Generator!H26 -> 10983 | L25: =Generator!L26 -> 7765 | M25: =Generator!P26 -> 0 | N25: =Generator!T26 -> 11020 | O25: =SUM(Generator!C26,Generator!G26,Generator!K26,Generator!O26,Generator!S26) -> 7438 | P25: 1.51 | R25: =R24 -> 1.8426612 | S25: ='RO Plant'!B25 -> 56 | T25: ='RO Plant'!M25 -> 104 | U25: ='RO Plant'!F25 -> 57 | V25: ='RO Plant'!I25 -> 41 | W25: ='RO Plant'!G25 -> 0 | AA25: =AB25-AB24 -> 0
A26: 44828 | B26: 75.3 | C26: 400 | D26: ='EMS Gridvis'!B25 -> 3.09 | E26: ='EMS Gridvis'!C25 -> 4.4 | F26: ='EMS Gridvis'!D25 -> 5.44 | G26: ='EMS Gridvis'!H25 -> 1.35 | H26: ='EMS Gridvis'!I25 -> 1.64 | I26: ='EMS Gridvis'!J25 -> 3.8 | J26: =Generator!D27 -> 9679 | K26: =Generator!H27 -> 9437 | L26: =Generator!L27 -> 5959 | M26: =Generator!P27 -> 5764 | N26: =Generator!T27 -> 9431 | O26: =SUM(Generator!C27,Generator!G27,Generator!K27,Generator!O27,Generator!S27) -> 8942 | P26: 1.51 | R26: =R25 -> 1.8426612 | S26: ='RO Plant'!B26 -> 45 | T26: ='RO Plant'!M26 -> 95 | U26: ='RO Plant'!F26 -> 57 | V26: ='RO Plant'!I26 -> 95 | W26: ='RO Plant'!G26 -> 0 | AA26: =AB26-AB25 -> 0
A27: 44829 | B27: 55.8 | C27: 189 | D27: ='EMS Gridvis'!B26 -> 2.88 | E27: ='EMS Gridvis'!C26 -> 4.21 | F27: ='EMS Gridvis'!D26 -> 5.1 | G27: ='EMS Gridvis'!H26 -> 1.38 | H27: ='EMS Gridvis'!I26 -> 1.59 | I27: ='EMS Gridvis'!J26 -> 3.66 | J27: =Generator!D28 -> 2127 | K27: =Generator!H28 -> 9582 | L27: =Generator!L28 -> 0 | M27: =Generator!P28 -> 5393 | N27: =Generator!T28 -> 10027 | O27: =SUM(Generator!C28,Generator!G28,Generator!K28,Generator!O28,Generator!S28) -> 6040 | P27: 1.51 | R27: =R26 -> 1.8426612 | S27: ='RO Plant'!B27 -> 51 | T27: ='RO Plant'!M27 -> 102 | U27: ='RO Plant'!F27 -> 36 | V27: ='RO Plant'!I27 -> 115 | W27: ='RO Plant'!G27 -> 0 | AA27: =AB27-AB26 -> 0
A28: 44830 | B28: 51.9 | C28: 278 | D28: ='EMS Gridvis'!B27 -> 2.87 | E28: ='EMS Gridvis'!C27 -> 4.33 | F28: ='EMS Gridvis'!D27 -> 5.16 | G28: ='EMS Gridvis'!H27 -> 1.32 | H28: ='EMS Gridvis'!I27 -> 1.71 | I28: ='EMS Gridvis'!J27 -> 3.84 | J28: =Generator!D29 -> 6749 | K28: =Generator!H29 -> 5242 | L28: =Generator!L29 -> 8756 | M28: =Generator!P29 -> 6946 | N28: =Generator!T29 -> 6039 | O28: =SUM(Generator!C29,Generator!G29,Generator!K29,Generator!O29,Generator!S29) -> 7591 | P28: 1.51 | R28: =R27 -> 1.8426612 | S28: ='RO Plant'!B28 -> 57 | T28: ='RO Plant'!M28 -> 112 | U28: ='RO Plant'!F28 -> 53 | V28: ='RO Plant'!I28 -> 103 | W28: ='RO Plant'!G28 -> 0 | AA28: =AB28-AB27 -> 0
A29: 44831 | B29: 49.4 | C29: 306 | D29: ='EMS Gridvis'!B28 -> 2.48 | E29: ='EMS Gridvis'!C28 -> 3.53 | F29: ='EMS Gridvis'!D28 -> 5.07 | G29: ='EMS Gridvis'!H28 -> 1.39 | H29: ='EMS Gridvis'!I28 -> 1.64 | I29: ='EMS Gridvis'!J28 -> 3.75 | J29: =Generator!D30 -> 0 | K29: =Generator!H30 -> 1342 | L29: =Generator!L30 -> 4655 | M29: =Generator!P30 -> 4554 | N29: =Generator!T30 -> 11234 | O29: =SUM(Generator!C30,Generator!G30,Generator!K30,Generator!O30,Generator!S30) -> 5813 | P29: 1.51 | R29: =R28 -> 1.8426612 | S29: ='RO Plant'!B29 -> 57 | T29: ='RO Plant'!M29 -> 131 | U29: ='RO Plant'!F29 -> 59 | V29: ='RO Plant'!I29 -> 111 | W29: ='RO Plant'!G29 -> 0 | AA29: =AB29-AB28 -> 0
A30: 44832 | B30: 57.1 | C30: 304 | D30: ='EMS Gridvis'!B29 -> 2.55 | E30: ='EMS Gridvis'!C29 -> 3.73 | F30: ='EMS Gridvis'!D29 -> 4.95 | G30: ='EMS Gridvis'!H29 -> 1.33 | H30: ='EMS Gridvis'!I29 -> 1.56 | I30: ='EMS Gridvis'!J29 -> 3.65 | J30: =Generator!D31 -> 6309 | K30: =Generator!H31 -> 10880 | L30: =Generator!L31 -> 0 | M30: =Generator!P31 -> 2245 | N30: =Generator!T31 -> 9031 | O30: =SUM(Generator!C31,Generator!G31,Generator!K31,Generator!O31,Generator!S31) -> 6547 | P30: 1.51 | R30: =R29 -> 1.8426612 | S30: ='RO Plant'!B30 -> 46 | T30: ='RO Plant'!M30 -> 84 | U30: ='RO Plant'!F30 -> 96 | V30: ='RO Plant'!I30 -> 96 | W30: ='RO Plant'!G30 -> 0 | AA30: =AB30-AB29 -> 0
A31: 44833 | B31: 53.4 | C31: 310 | D31: ='EMS Gridvis'!B30 -> 2.68 | E31: ='EMS Gridvis'!C30 -> 4.14 | F31: ='EMS Gridvis'!D30 -> 5.11 | G31: ='EMS Gridvis'!H30 -> 1.22 | H31: ='EMS Gridvis'!I30 -> 1.66 | I31: ='EMS Gridvis'!J30 -> 3.68 | J31: =Generator!D32 -> 9198 | K31: =Generator!H32 -> 6300 | L31: =Generator!L32 -> 9157 | M31: =Generator!P32 -> 0 | N31: =Generator!T32 -> 8721 | O31: =SUM(Generator!C32,Generator!G32,Generator!K32,Generator!O32,Generator!S32) -> 6958 | P31: 1.51 | R31: =R30 -> 1.8426612 | S31: ='RO Plant'!B31 -> 55 | T31: ='RO Plant'!M31 -> 88 | U31: ='RO Plant'!F31 -> 99 | V31: ='RO Plant'!I31 -> 107 | W31: ='RO Plant'!G31 -> 0 | AA31: =AB31-AB30 -> 46769 | AB31: 46769
A32: 44834 | D32: ='EMS Gridvis'!B31 -> 2.87 | E32: ='EMS Gridvis'!C31 -> 4.11 | F32: ='EMS Gridvis'!D31 -> 5.1 | G32: ='EMS Gridvis'!H31 -> 1.27 | H32: ='EMS Gridvis'!I31 -> 1.68 | I32: ='EMS Gridvis'!J31 -> 3.69 | J32: =Generator!D33 -> 8567 | K32: =Generator!H33 -> 6549 | L32: =Generator!L33 -> 7072 | M32: =Generator!P33 -> 0 | N32: =Generator!T33 -> 9399 | O32: =SUM(Generator!C33,Generator!G33,Generator!K33,Generator!O33,Generator!S33) -> 6731 | P32: 1.51 | R32: =R31 -> 1.8426612 | S32: ='RO Plant'!B32 -> 59 | T32: ='RO Plant'!M32 -> 31 | U32: ='RO Plant'!F32 -> 48 | V32: ='RO Plant'!I32 -> 103 | W32: ='RO Plant'!G32 -> 0 | AA32: =AB32-AB31 -> 51 | AB32: 46820

Sheet Generator
B2: Generator#1 | F2: Generator#2 | J2: Generator#3 | N2: Generator#4 | R2: Generator#5
A3: DATE | B3: Running Hours | C3: Daily Fuel Burned | D3: Daily Energy Consumed | F3: Running Hours | G3: Daily Fuel Burned | H3: Daily Energy Consumed | J3: Running Hours | K3: Daily Fuel Burned | L3: Daily Energy Consumed | N3: Running Hours | O3: Daily Fuel Burned | P3: Daily Energy Consumed | R3: Running Hours | S3: Daily Fuel Burned | T3: Daily Energy Consumed
A4: 44805 | B4: 0 | C4: 0 | D4: 0 | F4: 19 | G4: 2540 | H4: 11145 | J4: 13 | K4: 1888 | L4: 9387 | N4: 7 | O4: 1237 | P4: 5034 | R4: 12 | S4: 1219 | T4: 5851
A5: 44806 | B5: 0 | C5: 0 | D5: 0 | F5: 11 | G5: 1239 | H5: 5427 | J5: 14 | K5: 2076 | L5: 9988 | N5: 1 | O5: 36 | P5: 227 | R5: 10 | S5: 1496 | T5: 7017
A6: 44807 | B6: 10 | C6: 1222 | D6: 5243 | F6: 14 | G6: 2305 | H6: 10249 | J6: 16 | K6: 2036 | L6: 9186 | N6: 9 | O6: 1551 | P6: 6498 | R6: 0 | S6: 0 | T6: 0
A7: 44808 | B7: 0 | C7: 0 | D7: 0 | F7: 12 | G7: 1862 | H7: 8561 | J7: 17 | K7: 2092 | L7: 9841 | N7: 8 | O7: 1439 | P7: 5563 | R7: 12 | S7: 1426 | T7: 6333
A8: 44809 | B8: 14 | C8: 2134 | D8: 9983 | F8: 10 | G8: 1197 | H8: 5254 | J8: 18 | K8: 2234 | L8: 10539 | N8: 9 | O8: 1686 | P8: 6832 | R8: 0 | S8: 0 | T8: 0
A9: 44810 | B9: 14 | C9: 2467 | D9: 11001 | F9: 9 | G9: 1135 | H9: 4936 | J9: 11 | K9: 1363 | L9: 6155 | N9: 0 | O9: 0 | P9: 0 | R9: 14 | S9: 2427 | T9: 11089
A10: 44811 | B10: 13 | C10: 1815 | D10: 8993 | F10: 9 | G10: 1141 | H10: 5031 | J10: 11 | K10: 1202 | L10: 5523 | N10: 0 | O10: 0 | P10: 0 | R10: 13 | S10: 1892 | T10: 9113
A11: 44812 | B11: 20 | C11: 3008 | D11: 13400 | F11: 8 | G11: 960 | H11: 4187 | J11: 8 | K11: 914 | L11: 4236 | N11: 0 | O11: 0 | P11: 0 | R11: 16 | S11: 2433 | T11: 11270
A12: 44813 | B12: 15 | C12: 2335 | D12: 10915 | F12: 16 | G12: 2089 | H12: 9533 | J12: 13 | K12: 1780 | L12: 8669 | N12: 0 | O12: 0 | P12: 0 | R12: 5 | S12: 428 | T12: 2255
A13: 44814 | B13: 13 | C13: 1659 | D13: 7215 | F13: 17 | G13: 2581 | H13: 11630 | J13: 7 | K13: 792 | L13: 3527 | N13: 0 | O13: 0 | P13: 0 | R13: 15 | S13: 2191 | T13: 10138
A14: 44815 | B14: 13 | C14: 1893 | D14: 8676 | F14: 12 | G14: 1385 | H14: 6091 | J14: 13 | K14: 1836 | L14: 8629 | N14: 0 | O14: 0 | P14: 0 | R14: 0 | S14: 0 | T14: 0
A15: 44816 | B15: 14 | C15: 2132 | D15: 9849 | F15: 17 | G15: 2382 | H15: 10610 | J15: 15 | K15: 2176 | L15: 10278 | N15: 0 | O15: 0 | P15: 0 | R15: 16 | S15: 2114 | T15: 9645
... A33: 44834 | B33: 12 | C33: 1772 | D33: 8567 | F33: 11 | G33: 1487 | H33: 6549 | J33: 10 | K33: 1438 | L33: 7072 | N33: 0 | O33: 0 | P33: 0 | R33: 17 | S33: 2034 | T33: 9399
A35: DATE | B35: Running Hours | C35: Daily Fuel Burned | D35: Daily Energy Consumed | F35: Running Hours | G35: Daily Fuel Burned | H35: Daily Energy Consumed | J35: Running Hours | K35: Daily Fuel Burned | L35: Daily Energy Consumed | N35: Running Hours | O35: Daily Fuel Burned | P35: Daily Energy Consumed | R35: Running Hours | S35: Daily Fuel Burned | T35: Daily Energy Consumed
A36: TOTAL | B36: =SUM(B4:B34) -> 338 | C36: =SUM(C4:C34) -> 48266 | D36: =SUM(D4:D34) -> 219310 | F36: =SUM(F4:F34) -> 383 | G36: =SUM(G4:G34) -> 53397 | H36: =SUM(H4:H34) -> 239862 | J36: =SUM(J4:J34) -> 325 | K36: =SUM(K4:K34) -> 42105 | L36: =SUM(L4:L34) -> 198137 | N36: =SUM(N4:N34) -> 93 | O36: =SUM(O4:O34) -> 14316 | P36: =SUM(P4:P34) -> 57124 | R36: =SUM(R4:R34) -> 326 | S36: =SUM(S4:S34) -> 45591 | T36: =SUM(T4:T34) -> 208957
B37: Generator#1 | F37: Generator#2 | J37: Generator#3 | N37: Generator#4 | R37: Generator#5
A38: DATE | B38: Fuel burned Per Hour | C38: Energy Consumed Per Hour | D38: Engine Efficiency | E38: Load % | F38: Fuel burned Per Hour | G38: Energy Consumed Per Hour | H38: Engine Efficiency | I38: Load % | J38: Fuel burned Per Hour | K38: Energy Consumed Per Hour | L38: Engine Efficiency | M38: Load % | N38: Fuel burned Per Hour | O38: Energy Consumed Per Hour | P38: Engine Efficiency | Q38: Load % | R38: Fuel burned Per Hour | S38: Energy Consumed Per Hour | T38: Engine Efficiency | U38: Load %
A39: =A4 -> 44805 | B39: =C4/B4 -> #DIV/0! | C39: =D4/B4 -> #DIV/0! | D39: =C39/B39 -> #DIV/0! | E39: =(C39/1120)*100 -> #DIV/0! | F39: =G4/F4 -> 133.68421 | G39: =H4/F4 -> 586.57895 | H39: =G39/F39 -> 4.3877953 | I39: =(G39/1120)*100 -> 52.37312 | J39: =K4/J4 -> 145.23077 | K39: =L4/J4 -> 722.07692 | L39: =K39/J39 -> 4.971928 | M39: =(K39/1120)*100 -> 64.471154 | N39: =O4/N4 -> 176.71429 | O39: =P4/N4 -> 719.14286 | P39: =O39/N39 -> 4.069523 | Q39: =(O39/1120)*100 -> 64.209184 | R39: =S4/R4 -> 101.58333 | S39: =T4/R4 -> 487.58333 | T39: =S39/R39 -> 4.7998359 | U39: =(S39/1120)*100 -> 43.534226
A40: =A5 -> 44806 | B40: =C5/B5 -> #DIV/0! | C40: =D5/B5 -> #DIV/0! | D40: =C40/B40 -> #DIV/0! | E40: =(C40/1120)*100 -> #DIV/0! | F40: =G5/F5 -> 112.63636 | G40: =H5/F5 -> 493.36364 | H40: =G40/F40 -> 4.3801453 | I40: =(G40/1120)*100 -> 44.050325 | J40: =K5/J5 -> 148.28571 | K40: =L5/J5 -> 713.42857 | L40: =K40/J40 -> 4.8111753 | M40: =(K40/1120)*100 -> 63.69898 | N40: =O5/N5 -> 36 | O40: =P5/N5 -> 227 | P40: =O40/N40 -> 6.3055556 | Q40: =(O40/1120)*100 -> 20.267857 | R40: =S5/R5 -> 149.6 | S40: =T5/R5 -> 701.7 | T40: =S40/R40 -> 4.690508 | U40: =(S40/1120)*100 -> 62.651786
A41: =A6 -> 44807 | B41: =C6/B6 -> 122.2 | C41: =D6/B6 -> 524.3 | D41: =C41/B41 -> 4.2905074 | E41: =(C41/1120)*100 -> 46.8125 | F41: =G6/F6 -> 164.64286 | G41: =H6/F6 -> 732.07143 | H41: =G41/F41 -> 4.4464208 | I41: =(G41/1120)*100 -> 65.36352 | J41: =K6/J6 -> 127.25 | K41: =L6/J6 -> 574.125 | L41: =K41/J41 -> 4.5117878 | M41: =(K41/1120)*100 -> 51.261161 | N41: =O6/N6 -> 172.33333 | O41: =P6/N6 -> 722 | P41: =O41/N41 -> 4.1895551 | Q41: =(O41/1120)*100 -> 64.464286 | R41: =S6/R6 -> #DIV/0! | S41: =T6/R6 -> #DIV/0! | T41: =S41/R41 -> #DIV/0! | U41: =(S41/1120)*100 -> #DIV/0!
A42: =A7 -> 44808 | B42: =C7/B7 -> #DIV/0! | C42: =D7/B7 -> #DIV/0! | D42: =C42/B42 -> #DIV/0! | E42: =(C42/1120)*100 -> #DIV/0! | F42: =G7/F7 -> 155.16667 | G42: =H7/F7 -> 713.41667 | H42: =G42/F42 -> 4.5977444 | I42: =(G42/1120)*100 -> 63.697917 | J42: =K7/J7 -> 123.05882 | K42: =L7/J7 -> 578.88235 | L42: =K42/J42 -> 4.7041109 | M42: =(K42/1120)*100 -> 51.685924 | N42: =O7/N7 -> 179.875 | O42: =P7/N7 -> 695.375 | P42: =O42/N42 -> 3.8658791 | Q42: =(O42/1120)*100 -> 62.087054 | R42: =S7/R7 -> 118.83333 | S42: =T7/R7 -> 527.75 | T42: =S42/R42 -> 4.441094 | U42: =(S42/1120)*100 -> 47.120536
A43: =A8 -> 44809 | B43: =C8/B8 -> 152.42857 | C43: =D8/B8 -> 713.07143 | D43: =C43/B43 -> 4.6780694 | E43: =(C43/1120)*100 -> 63.667092 | F43: =G8/F8 -> 119.7 | G43: =H8/F8 -> 525.4 | H43: =G43/F43 -> 4.3893066 | I43: =(G43/1120)*100 -> 46.910714 | J43: =K8/J8 -> 124.11111 | K43: =L8/J8 -> 585.5 | L43: =K43/J43 -> 4.717547 | M43: =(K43/1120)*100 -> 52.276786 | N43: =O8/N8 -> 187.33333 | O43: =P8/N8 -> 759.11111 | P43: =O43/N43 -> 4.0521945 | Q43: =(O43/1120)*100 -> 67.777778 | R43: =S8/R8 -> #DIV/0! | S43: =T8/R8 -> #DIV/0! | T43: =S43/R43 -> #DIV/0! | U43: =(S43/1120)*100 -> #DIV/0!
A44: =A9 -> 44810 | B44: =C9/B9 -> 176.21429 | C44: =D9/B9 -> 785.78571 | D44: =C44/B44 -> 4.4592623 | E44: =(C44/1120)*100 -> 70.159439 | F44: =G9/F9 -> 126.11111 | G44: =H9/F9 -> 548.44444 | H44: =G44/F44 -> 4.3488987 | I44: =(G44/1120)*100 -> 48.968254 | J44: =K9/J9 -> 123.90909 | K44: =L9/J9 -> 559.54545 | L44: =K44/J44 -> 4.515774 | M44: =(K44/1120)*100 -> 49.959416 | N44: =O9/N9 -> #DIV/0! | O44: =P9/N9 -> #DIV/0! | P44: =O44/N44 -> #DIV/0! | Q44: =(O44/1120)*100 -> #DIV/0! | R44: =S9/R9 -> 173.35714 | S44: =T9/R9 -> 792.07143 | T44: =S44/R44 -> 4.5690152 | U44: =(S44/1120)*100 -> 70.720663
A45: =A10 -> 44811 | B45: =C10/B10 -> 139.61538 | C45: =D10/B10 -> 691.76923 | D45: =C45/B45 -> 4.9548209 | E45: =(C45/1120)*100 -> 61.76511 | F45: =G10/F10 -> 126.77778 | G45: =H10/F10 -> 559 | H45: =G45/F45 -> 4.4092901 | I45: =(G45/1120)*100 -> 49.910714 | J45: =K10/J10 -> 109.27273 | K45: =L10/J10 -> 502.09091 | L45: =K45/J45 -> 4.5948419 | M45: =(K45/1120)*100 -> 44.829545 | N45: =O10/N10 -> #DIV/0! | O45: =P10/N10 -> #DIV/0! | P45: =O45/N45 -> #DIV/0! | Q45: =(O45/1120)*100 -> #DIV/0! | R45: =S10/R10 -> 145.53846 | S45: =T10/R10 -> 701 | T45: =S45/R45 -> 4.8165962 | U45: =(S45/1120)*100 -> 62.589286
A46: =A11 -> 44812 | B46: =C11/B11 -> 150.4 | C46: =D11/B11 -> 670 | D46: =C46/B46 -> 4.4547872 | E46: =(C46/1120)*100 -> 59.821429 | F46: =G11/F11 -> 120 | G46: =H11/F11 -> 523.375 | H46: =G46/F46 -> 4.3614583 | I46: =(G46/1120)*100 -> 46.729911 | J46: =K11/J11 -> 114.25 | K46: =L11/J11 -> 529.5 | L46: =K46/J46 -> 4.6345733 | M46: =(K46/1120)*100 -> 47.276786 | N46: =O11/N11 -> #DIV/0! | O46: =P11/N11 -> #DIV/0! | P46: =O46/N46 -> #DIV/0! | Q46: =(O46/1120)*100 -> #DIV/0! | R46: =S11/R11 -> 152.0625 | S46: =T11/R11 -> 704.375 | T46: =S46/R46 -> 4.6321414 | U46: =(S46/1120)*100 -> 62.890625
A47: =A12 -> 44813 | B47: =C12/B12 -> 155.66667 | C47: =D12/B12 -> 727.66667 | D47: =C47/B47 -> 4.6745182 | E47: =(C47/1120)*100 -> 64.970238 | F47: =G12/F12 -> 130.5625 | G47: =H12/F12 -> 595.8125 | H47: =G47/F47 -> 4.5634275 | I47: =(G47/1120)*100 -> 53.197545 | J47: =K12/J12 -> 136.92308 | K47: =L12/J12 -> 666.84615 | L47: =K47/J47 -> 4.8702247 | M47: =(K47/1120)*100 -> 59.539835 | N47: =O12/N12 -> #DIV/0! | O47: =P12/N12 -> #DIV/0! | P47: =O47/N47 -> #DIV/0! | Q47: =(O47/1120)*100 -> #DIV/0! | R47: =S12/R12 -> 85.6 | S47: =T12/R12 -> 451 | T47: =S47/R47 -> 5.2686916 | U47: =(S47/1120)*100 -> 40.267857
A48: =A13 -> 44814 | B48: =C13/B13 -> 127.61538 | C48: =D13/B13 -> 555 | D48: =C48/B48 -> 4.3490054 | E48: =(C48/1120)*100 -> 49.553571 | F48: =G13/F13 -> 151.82353 | G48: =H13/F13 -> 684.11765 | H48: =G48/F48 -> 4.5060054 | I48: =(G48/1120)*100 -> 61.081933 | J48: =K13/J13 -> 113.14286 | K48: =L13/J13 -> 503.85714 | L48: =K48/J48 -> 4.4532828 | M48: =(K48/1120)*100 -> 44.987245 | N48: =O13/N13 -> #DIV/0! | O48: =P13/N13 -> #DIV/0! | P48: =O48/N48 -> #DIV/0! | Q48: =(O48/1120)*100 -> #DIV/0! | R48: =S13/R13 -> 146.06667 | S48: =T13/R13 -> 675.86667 | T48: =S48/R48 -> 4.6271109 | U48: =(S48/1120)*100 -> 60.345238
