Workbook

Sheet TOTAL
A1: Site Name | B1: Day | C1: Month | D1: Year | E1: Total Electricity Kwh | F1: Electricity Tariff ($/Kwh) | G1: Total Fuel Oil (Liter) | H1: Fuel Oil $/Liter | I1: Water Utility Supply (m3) m3 | J1: Water Utility Supply (m3) $/m3 | K1: LPG (Kg) | L1: LPG $/Kg | M1: Room Nights | N1: Total Guests | O1: Food Covers
A2: Maldives at Kuda Huraa | B2: 1 | C2: 10 | D2: 2022 | E2: 17270 | G2: 5102 | I2: 326 | K2: 0 | M2: 17 | N2: 50 | O2: 130
A3: Maldives at Kuda Huraa | B3: =B2+1 -> 2 | C3: 10 | D3: 2022 | E3: 16960 | G3: 4710 | I3: 288 | M3: 17 | N3: 68 | O3: 138
A4: Maldives at Kuda Huraa | B4: =B3+1 -> 3 | C4: 10 | D4: 2022 | E4: 18580 | G4: 5015 | I4: 357 | M4: 15 | N4: 60 | O4: 146
A5: Maldives at Kuda Huraa | B5: =B4+1 -> 4 | C5: 10 | D5: 2022 | E5: 17550 | G5: 5004 | I5: 341 | M5: 13 | N5: 53 | O5: 120
A6: Maldives at Kuda Huraa | B6: =B5+1 -> 5 | C6: 10 | D6: 2022 | E6: 18520 | G6: 5085 | I6: 283 | M6: 15 | N6: 52 | O6: 134
A7: Maldives at Kuda Huraa | B7: =B6+1 -> 6 | C7: 10 | D7: 2022 | E7: 19040 | G7: 5274 | I7: 300 | M7: 19 | N7: 72 | O7: 154
A8: Maldives at Kuda Huraa | B8: =B7+1 -> 7 | C8: 10 | D8: 2022 | E8: 18260 | G8: 5152 | I8: 380 | M8: 17 | N8: 72 | O8: 172
A9: Maldives at Kuda Huraa | B9: =B8+1 -> 8 | C9: 10 | D9: 2022 | E9: 18200 | G9: 5114 | I9: 237 | M9: 27 | N9: 86 | O9: 199
A10: Maldives at Kuda Huraa | B10: =B9+1 -> 9 | C10: 10 | D10: 2022 | E10: 18530 | G10: 5387 | I10: 383 | M10: 39 | N10: 106 | O10: 261
A11: Maldives at Kuda Huraa | B11: =B10+1 -> 10 | C11: 10 | D11: 2022 | E11: 17510 | G11: 4927 | I11: 405 | M11: 38 | N11: 100 | O11: 249
A12: Maldives at Kuda Huraa | B12: =B11+1 -> 11 | C12: 10 | D12: 2022 | E12: 16480 | G12: 4603 | I12: 306 | M12: 37 | N12: 111 | O12: 239
A13: Maldives at Kuda Huraa | B13: =B12+1 -> 12 | C13: 10 | D13: 2022 | E13: 17610 | G13: 4746 | I13: 310 | M13: 34 | N13: 97 | O13: 265
A14: Maldives at Kuda Huraa | B14: =B13+1 -> 13 | C14: 10 | D14: 2022 | E14: 15050 | G14: 4253 | I14: 235 | M14: 34 | N14: 96 | O14: 247
A15: Maldives at Kuda Huraa | B15: =B14+1 -> 14 | C15: 10 | D15: 2022 | E15: 16260 | I15: 270 | M15: 24 | N15: 79 | O15: 213
A16: Maldives at Kuda Huraa | B16: =B15+1 -> 15 | C16: 10 | D16: 2022
A17: Maldives at Kuda Huraa | B17: =B16+1 -> 16 | C17: 10 | D17: 2022
A18: Maldives at Kuda Huraa | B18: =B17+1 -> 17 | C18: 10 | D18: 2022
A19: Maldives at Kuda Huraa | B19: =B18+1 -> 18 | C19: 10 | D19: 2022
A20: Maldives at Kuda Huraa | B20: =B19+1 -> 19 | C20: 10 | D20: 2022
A21: Maldives at Kuda Huraa | B21: =B20+1 -> 20 | C21: 10 | D21: 2022
A22: Maldives at Kuda Huraa | B22: =B21+1 -> 21 | C22: 10 | D22: 2022
A23: Maldives at Kuda Huraa | B23: =B22+1 -> 22 | C23: 10 | D23: 2022
A24: Maldives at Kuda Huraa | B24: =B23+1 -> 23 | C24: 10 | D24: 2022
A25: Maldives at Kuda Huraa | B25: =B24+1 -> 24 | C25: 10 | D25: 2022
A26: Maldives at Kuda Huraa | B26: =B25+1 -> 25 | C26: 10 | D26: 2022
A27: Maldives at Kuda Huraa | B27: =B26+1 -> 26 | C27: 10 | D27: 2022
... A32: Maldives at Kuda Huraa | B32: =B31+1 -> 31 | C32: 10 | D32: 2022
A33: Total | E33: =SUM(E2:E31) -> 245820 | F33: 0 | G33: =SUM(G2:G31) -> 64372 | H33: 0 | I33: =SUM(I2:I31) -> 4421 | J33: 0 | K33: =SUM(K2:K31) -> 0 | L33: 0 | M33: =SUM(M2:M31) -> 346 | N33: =SUM(N2:N31) -> 1102 | O33: =SUM(O2:O31) -> 2667

Sheet Monthly Budget 
A2: Site Name | B2: Month | C2: Year | D2: Purchased Electricity Kwh | E2: Purchased Electricity Tariff ($/Kwh) | F2: Electricity Total Budgeted | G2: Electricity Total Budgeted Cost ($) | H2: Fuel Oil Hot-Water Boilers (Liter) Liter | I2: Fuel Oil Hot-Water Boilers (Liter) $/Liter | J2: LPG Kitchen (Kg) | K2: LPG Kitchen $/Kg | L2: LPG Total Budgeted | M2: LPG Total Budgeted Cost ($) | N2: Water Utility Supply (m3) m3 | O2: Water Utility Supply (m3) $/m3 | P2: Water Total Budgeted | Q2: Water Total Budgeted Cost ($) | R2: Room Nights | S2: Food Covers
A3: Maldives at Kuda Huraa | B3: 1 | C3: 2022 | D3: 714310 | E3: 0.194 | F3: 714310 | G3: 171800 | H3: 189315 | I3: 0.7031 | J3: 9840 | K3: 1 | L3: 8640 | M3: 17900 | N3: 11040 | O3: 0.6 | P3: 9827 | Q3: 10800 | R3: 1738 | S3: 12281
A4: Maldives at Kuda Huraa | B4: 2 | C4: 2022 | D4: 654040 | E4: 0.18 | F4: 613620 | G4: 151800 | H4: 166967 | I4: 0.64 | J4: 6415 | K4: 0.9 | L4: 7255 | M4: 14100 | N4: 10412 | O4: 1.8 | P4: 9250 | Q4: 8500 | R4: 1497 | S4: 12274
A5: Maldives at Kuda Huraa | B5: 3 | C5: 2022 | D5: 729060 | E5: 0.194 | F5: 681590 | G5: 184500 | H5: 184995 | I5: 0.7031 | J5: 8780 | K5: 1 | L5: 7245 | M5: 16300 | N5: 10115 | O5: 0.562 | P5: 9500 | Q5: 16800 | R5: 1634 | S5: 13116.5
A6: Maldives at Kuda Huraa | B6: 4 | C6: 2022 | D6: 730070 | E6: 0.334 | F6: 708230 | G6: 184700 | H6: 205088 | I6: 1.1513 | J6: 7810 | K6: 1 | L6: 7515 | M6: 13900 | N6: 10731 | O6: 0.393 | P6: 9451 | Q6: 9300 | R6: 1664 | S6: 11957
A7: Maldives at Kuda Huraa | B7: 5 | C7: 2022 | D7: 710031.21 | E7: 0.3626 | F7: 685570 | G7: 186600 | H7: 196733 | I7: 1.1513 | J7: 8695 | K7: 1.165 | L7: 8055 | M7: 11100 | N7: 9917.61 | O7: 0.835 | P7: 8134 | Q7: 9000 | R7: 1248 | S7: 8217
A8: Maldives at Kuda Huraa | B8: 6 | C8: 2022 | D8: 625150 | E8: 0.333 | F8: 683690 | G8: 128400 | H8: 172603 | I8: 1.3504 | J8: 7835 | K8: 1.36 | L8: 5555 | M8: 8400 | N8: 8848 | O8: 1.46 | P8: 8982 | Q8: 13800 | R8: 658 | S8: 4555
A9: Maldives at Kuda Huraa | B9: 7 | C9: 2022 | D9: 636450 | E9: 0.393 | F9: 704110 | G9: 117000 | H9: 177084 | I9: 1.3345 | J9: 9015 | K9: 1.047 | L9: 5980 | M9: 8700 | N9: 9861 | O9: 0.867 | P9: 8746 | Q9: 12000 | R9: 980 | S9: 7559
A10: Maldives at Kuda Huraa | B10: 8 | C10: 2022 | D10: 599420 | E10: 0.394 | F10: 697360 | G10: 150600 | H10: 166385 | I10: 1.3053 | J10: 11141.27 | K10: 1 | L10: 7110 | M10: 11100 | N10: 10074 | O10: 0.9 | P10: 8500 | Q10: 12300 | R10: 759 | S10: 5884
A11: Maldives at Kuda Huraa | B11: 9 | C11: 2022 | D11: 531680 | E11: 0.412 | F11: 643900 | G11: 151400 | H11: 147447 | I11: 1.3052 | J11: 7469 | K11: 1 | L11: 6030 | M11: 8100 | N11: 9637 | O11: 0.753 | P11: 8300 | Q11: 12100 | R11: 494 | S11: 3484
A12: Maldives at Kuda Huraa | B12: 10 | C12: 2022 | F12: 689440 | G12: 211500 | L12: 7515 | M12: 12000 | P12: 8750 | Q12: 6500
A13: Maldives at Kuda Huraa | B13: 11 | C13: 2022 | F13: 654730 | G13: 211100 | L13: 8425 | M13: 11700 | P13: 9493 | Q13: 8000
A14: Maldives at Kuda Huraa | B14: 12 | C14: 2022 | F14: 710650 | G14: 179400 | L14: 9521 | M14: 14300 | P14: 12710 | Q14: 9600

Sheet Kwh Reading
A1: Electric Consumption Record (4pm)
A2: Month | B2: BOH-1/ B&C Block GWH | C2: Pastry MWH | D2: Feeder 401-419 KWH | E2: Feeder 301-319 KWH | F2: Kitchen GWH | G2: Feeder 201-208 GWH | H2: Feeder 113-123 | I2: M - Block /PC MWH | J2: Laundry MWH | M2: Feeder 101-112 MWH | N2: Feeder 217-224 | O2: Spa MWH | P2: Feeder 124-134 | Q2: Feeder 209-216 | R2: STP -1 &2 MWH | S2: STP -3 MWH | T2: Reef Club MWH | V2: Room Nights | W2: Total Guests | X2: Food Covers
J3: A | K3: B | L3: C
A4: 44835 | B4: 1.5078 | C4: 343.8 | D4: 8401516.8 | E4: 9436844.7 | F4: 3.5707 | G4: 1.1352 | H4: 1.0547 | I4: 373.99 | J4: 522.32 | K4: 494.14 | L4: 339.34 | M4: 851.09 | N4: 769.49 | O4: 248.26 | P4: 1.0336 | Q4: 758.48 | R4: 190.15 | S4: 177.79 | T4: 640.71
A5: 44836 | B5: 1.5087 | C5: 344.07 | D5: 8403273.9 | E5: 9438729.5 | F5: 3.5732 | G5: 1.1357 | H5: 1.0552 | I5: 374.27 | J5: 522.64 | K5: 494.39 | L5: 339.54 | M5: 851.4 | N5: 769.92 | O5: 248.47 | P5: 1.034 | Q5: 758.65 | R5: 190.15 | S5: 177.93 | T5: 641.1
A6: 44837 | B6: 1.5098 | C6: 344.33 | D6: 8404863.3 | E6: 9440838.6 | F6: 3.5759 | G6: 1.1362 | H6: 1.0558 | I6: 374.59 | J6: 523.03 | K6: 494.73 | L6: 339.81 | M6: 851.78 | N6: 770.35 | O6: 248.7 | P6: 1.0344 | Q6: 758.78 | R6: 190.15 | S6: 178.05 | T6: 641.59
A7: 44838 | B7: 1.5107 | C7: 344.59 | D7: 8406391.5 | E7: 9442967.5 | F7: 3.5785 | G7: 1.1363 | H7: 1.0564 | I7: 374.9 | J7: 523.6 | K7: 495.02 | L7: 340.01 | M7: 852.08 | N7: 770.8 | O7: 248.91 | P7: 1.0348 | Q7: 758.92 | R7: 190.15 | S7: 178.17 | T7: 642.06
A8: 44839 | B8: 1.5117 | C8: 344.85 | D8: 8407834.9 | E8: 9445179.3 | F8: 3.5809 | G8: 1.1373 | H8: 1.057 | I8: 375.19 | J8: 524.12 | K8: 495.26 | L8: 340.18 | M8: 852.43 | N8: 771.12 | O8: 249.1 | P8: 1.0352 | Q8: 759.05 | R8: 190.15 | S8: 178.36 | T8: 642.54
A9: 44840 | B9: 1.5128 | C9: 345.13 | D9: 8409438.2 | E9: 9447459 | F9: 3.5836 | G9: 1.1379 | H9: 1.0577 | I9: 375.53 | J9: 524.56 | K9: 495.57 | L9: 340.37 | M9: 852.77 | N9: 771.47 | O9: 249.29 | P9: 1.0357 | Q9: 759.27 | R9: 190.15 | S9: 178.41 | T9: 643.05
A10: 44841 | B10: 1.514 | C10: 345.41 | D10: 8410974.6 | E10: 9450054.2 | F10: 3.5863 | G10: 1.1384 | H10: 1.0583 | I10: 375.88 | J10: 524.88 | K10: 495.86 | L10: 340.56 | M10: 853.18 | N10: 771.86 | O10: 249.51 | P10: 1.0363 | Q10: 759.45 | R10: 190.15 | S10: 178.53 | T10: 643.55
A11: 44842 | B11: 1.515 | C11: 345.67 | D11: 1369.25 | E11: 9452022.8 | F11: 3.589 | G11: 1.1389 | H11: 1.059 | I11: 376.19 | J11: 525.27 | K11: 496.17 | L11: 340.79 | M11: 853.6 | N11: 772.24 | O11: 249.71 | P11: 1.0369 | Q11: 759.62 | R11: 190.15 | S11: 178.64 | T11: 643.82
A12: 44843 | B12: 1.516 | C12: 345.94 | D12: 2947.02 | E12: 9454187.1 | F12: 3.5917 | G12: 1.1394 | H12: 1.0597 | I12: 376.52 | J12: 525.68 | K12: 496.49 | L12: 341 | M12: 854 | N12: 772.64 | O12: 249.91 | P12: 1.0374 | Q12: 759.82 | R12: 190.15 | S12: 178.76 | T12: 644.31
A13: 44844 | B13: 1.5171 | C13: 346.21 | D13: 4569.55 | E13: 9456321.3 | F13: 3.5944 | G13: 1.14 | H13: 1.0603 | I13: 376.83 | J13: 526.11 | K13: 496.78 | L13: 341.19 | M13: 854.41 | N13: 773.01 | O13: 250.11 | P13: 1.038 | Q13: 760.03 | R13: 190.15 | S13: 178.87 | T13: 644.83
A14: 44845 | B14: 1.5181 | C14: 346.49 | D14: 5958.06 | E14: 9458195.4 | F14: 3.5971 | G14: 1.1405 | H14: 1.0609 | I14: 377.08 | J14: 526.57 | K14: 497.1 | L14: 341.4 | M14: 854.71 | N14: 773.33 | O14: 250.33 | P14: 1.0385 | Q14: 760.19 | R14: 190.15 | S14: 178.98 | T14: 645.29
A15: 44846 | B15: 1.519 | C15: 346.79 | D15: 7365.95 | E15: 9460035.6 | F15: 3.5996 | G15: 1.141 | H15: 1.0615 | I15: 377.32 | J15: 526.96 | K15: 497.4 | L15: 341.62 | M15: 855.07 | N15: 773.63 | O15: 250.53 | P15: 1.0389 | Q15: 760.33 | R15: 190.15 | S15: 179.05 | T15: 645.72
... A18: 44849 | B18: 1.5216 | C18: 347.58 | D18: 11021.01 | E18: 9465161.2 | F18: 3.6074 | G18: 1.1423 | H18: 1.0632 | I18: 378.06 | J18: 528.56 | K18: 498.38 | L18: 342.29 | M18: 856.15 | N18: 774.53 | O18: 251.17 | P18: 1.0402 | Q18: 760.7 | R18: 190.15 | S18: 179.05 | T18: 646.99
A19: 44850 | R19: 190.15
A20: 44851 | R20: 190.15
A21: 44852 | R21: 190.15
A22: 44853 | R22: 190.15
A23: 44854 | R23: 190.15
A24: 44855 | R24: 190.15
A25: 44856 | R25: 190.15
A26: 44857 | R26: 190.15
A27: 44858 | R27: 190.15
A28: 44859 | R28: 190.15
A29: 44860 | R29: 190.15
A30: 44861 | R30: 190.15
... A33: 44864 | R33: 190.15
A34: 44865
A35: 44866 | V35: =SUM(V4:V34) -> 0 | W35: =SUM(W4:W34) -> 0 | X35: =SUM(X4:X34) -> 0
T42: ……..

Sheet Kwh Consumption
A2: Date | B2: Total KWH | C2: Reef Club KWH | D2: Kitchen KWH | E2: Pastry KWH | F2: Laundry KWH | I2: STP -1 &2 KWH | J2: STP -3 KWH | K2: M - Block /PC KWH | L2: B&C Block KWH | M2: Guest Room Beach Pavilion & Beach Bungalow KWH | S2: Guest Room Water Bungalow KWH | U2: Spa KWH | V2: Others KWH
F3: A | G3: B | H3: C | M3: Feeder -101-112 | N3: Feeder -113-123 | O3: Feeder -124-134 | P3: Feeder -201-208 | Q3: Feeder -209-216 | R3: Feeder -217-224 | S3: Feeder -301-319 | T3: Feeder 401-419
A4: ='Kwh Reading'!A4 -> 44835 | B4: =TOTAL!E2 -> 17270 | C4: =('Kwh Reading'!T5-'Kwh Reading'!T4)*1000 -> 390 | D4: =('Kwh Reading'!F5-'Kwh Reading'!F4)*1000000 -> 2500 | E4: =('Kwh Reading'!C5-'Kwh Reading'!C4)*1000 -> 270 | F4: =('Kwh Reading'!J5-'Kwh Reading'!J4)*1000 -> 320 | G4: =('Kwh Reading'!K5-'Kwh Reading'!K4)*1000 -> 250 | H4: =('Kwh Reading'!L5-'Kwh Reading'!L4)*1000 -> 200 | I4: =('Kwh Reading'!R5-'Kwh Reading'!R4)*1000 -> 0 | J4: =('Kwh Reading'!S5-'Kwh Reading'!S4)*1000 -> 140 | K4: =('Kwh Reading'!I5-'Kwh Reading'!I4)*1000 -> 280 | L4: =('Kwh Reading'!B5-'Kwh Reading'!B4)*1000000 -> 900 | M4: =('Kwh Reading'!M5-'Kwh Reading'!M4)*1000 -> 310 | N4: =('Kwh Reading'!H5-'Kwh Reading'!H4)*1000000 -> 500 | O4: =('Kwh Reading'!P5-'Kwh Reading'!P4)*1000000 -> 400 | P4: =('Kwh Reading'!G5-'Kwh Reading'!G4)*1000000 -> 500 | Q4: =('Kwh Reading'!Q5-'Kwh Reading'!Q4)*1000 -> 170 | R4: =('Kwh Reading'!N5-'Kwh Reading'!N4)*1000 -> 430 | S4: ='Kwh Reading'!E5-'Kwh Reading'!E4 -> 1884.8 | T4: ='Kwh Reading'!D5-'Kwh Reading'!D4 -> 1757.13 | U4: =('Kwh Reading'!O5-'Kwh Reading'!O4)*1000 -> 210 | V4: =B4-(SUM(C4:U4)) -> 5858.07
A5: ='Kwh Reading'!A5 -> 44836 | B5: =TOTAL!E3 -> 16960 | C5: =('Kwh Reading'!T6-'Kwh Reading'!T5)*1000 -> 490 | D5: =('Kwh Reading'!F6-'Kwh Reading'!F5)*1000000 -> 2700 | E5: =('Kwh Reading'!C6-'Kwh Reading'!C5)*1000 -> 260 | F5: =('Kwh Reading'!J6-'Kwh Reading'!J5)*1000 -> 390 | G5: =('Kwh Reading'!K6-'Kwh Reading'!K5)*1000 -> 340 | H5: =('Kwh Reading'!L6-'Kwh Reading'!L5)*1000 -> 270 | I5: =('Kwh Reading'!R6-'Kwh Reading'!R5)*1000 -> 0 | J5: =('Kwh Reading'!S6-'Kwh Reading'!S5)*1000 -> 120 | K5: =('Kwh Reading'!I6-'Kwh Reading'!I5)*1000 -> 320 | L5: =('Kwh Reading'!B6-'Kwh Reading'!B5)*1000000 -> 1100 | M5: =('Kwh Reading'!M6-'Kwh Reading'!M5)*1000 -> 380 | N5: =('Kwh Reading'!H6-'Kwh Reading'!H5)*1000000 -> 600 | O5: =('Kwh Reading'!P6-'Kwh Reading'!P5)*1000000 -> 400 | P5: =('Kwh Reading'!G6-'Kwh Reading'!G5)*1000000 -> 500 | Q5: =('Kwh Reading'!Q6-'Kwh Reading'!Q5)*1000 -> 130 | R5: =('Kwh Reading'!N6-'Kwh Reading'!N5)*1000 -> 430 | S5: ='Kwh Reading'!E6-'Kwh Reading'!E5 -> 2109.07 | T5: ='Kwh Reading'!D6-'Kwh Reading'!D5 -> 1589.38 | U5: =('Kwh Reading'!O6-'Kwh Reading'!O5)*1000 -> 230 | V5: =B5-(SUM(C5:U5)) -> 4601.55
A6: ='Kwh Reading'!A6 -> 44837 | B6: =TOTAL!E4 -> 18580 | C6: =('Kwh Reading'!T7-'Kwh Reading'!T6)*1000 -> 470 | D6: =('Kwh Reading'!F7-'Kwh Reading'!F6)*1000000 -> 2600 | E6: =('Kwh Reading'!C7-'Kwh Reading'!C6)*1000 -> 260 | F6: =('Kwh Reading'!J7-'Kwh Reading'!J6)*1000 -> 570 | G6: =('Kwh Reading'!K7-'Kwh Reading'!K6)*1000 -> 290 | H6: =('Kwh Reading'!L7-'Kwh Reading'!L6)*1000 -> 200 | I6: =('Kwh Reading'!R7-'Kwh Reading'!R6)*1000 -> 0 | J6: =('Kwh Reading'!S7-'Kwh Reading'!S6)*1000 -> 120 | K6: =('Kwh Reading'!I7-'Kwh Reading'!I6)*1000 -> 310 | L6: =('Kwh Reading'!B7-'Kwh Reading'!B6)*1000000 -> 900 | M6: =('Kwh Reading'!M7-'Kwh Reading'!M6)*1000 -> 300 | N6: =('Kwh Reading'!H7-'Kwh Reading'!H6)*1000000 -> 600 | O6: =('Kwh Reading'!P7-'Kwh Reading'!P6)*1000000 -> 400 | P6: =('Kwh Reading'!G7-'Kwh Reading'!G6)*1000000 -> 100 | Q6: =('Kwh Reading'!Q7-'Kwh Reading'!Q6)*1000 -> 140 | R6: =('Kwh Reading'!N7-'Kwh Reading'!N6)*1000 -> 450 | S6: ='Kwh Reading'!E7-'Kwh Reading'!E6 -> 2128.95 | T6: ='Kwh Reading'!D7-'Kwh Reading'!D6 -> 1528.19 | U6: =('Kwh Reading'!O7-'Kwh Reading'!O6)*1000 -> 210 | V6: =B6-(SUM(C6:U6)) -> 7002.86
A7: ='Kwh Reading'!A7 -> 44838 | B7: =TOTAL!E5 -> 17550 | C7: =('Kwh Reading'!T8-'Kwh Reading'!T7)*1000 -> 480 | D7: =('Kwh Reading'!F8-'Kwh Reading'!F7)*1000000 -> 2400 | E7: =('Kwh Reading'!C8-'Kwh Reading'!C7)*1000 -> 260 | F7: =('Kwh Reading'!J8-'Kwh Reading'!J7)*1000 -> 520 | G7: =('Kwh Reading'!K8-'Kwh Reading'!K7)*1000 -> 240 | H7: =('Kwh Reading'!L8-'Kwh Reading'!L7)*1000 -> 170 | I7: =('Kwh Reading'!R8-'Kwh Reading'!R7)*1000 -> 0 | J7: =('Kwh Reading'!S8-'Kwh Reading'!S7)*1000 -> 190 | K7: =('Kwh Reading'!I8-'Kwh Reading'!I7)*1000 -> 290 | L7: =('Kwh Reading'!B8-'Kwh Reading'!B7)*1000000 -> 1000 | M7: =('Kwh Reading'!M8-'Kwh Reading'!M7)*1000 -> 350 | N7: =('Kwh Reading'!H8-'Kwh Reading'!H7)*1000000 -> 600 | O7: =('Kwh Reading'!P8-'Kwh Reading'!P7)*1000000 -> 400 | P7: =('Kwh Reading'!G8-'Kwh Reading'!G7)*1000000 -> 1000 | Q7: =('Kwh Reading'!Q8-'Kwh Reading'!Q7)*1000 -> 130 | R7: =('Kwh Reading'!N8-'Kwh Reading'!N7)*1000 -> 320 | S7: ='Kwh Reading'!E8-'Kwh Reading'!E7 -> 2211.84 | T7: ='Kwh Reading'!D8-'Kwh Reading'!D7 -> 1443.42 | U7: =('Kwh Reading'!O8-'Kwh Reading'!O7)*1000 -> 190 | V7: =B7-(SUM(C7:U7)) -> 5354.74
A8: ='Kwh Reading'!A8 -> 44839 | B8: =TOTAL!E6 -> 18520 | C8: =('Kwh Reading'!T9-'Kwh Reading'!T8)*1000 -> 510 | D8: =('Kwh Reading'!F9-'Kwh Reading'!F8)*1000000 -> 2700 | E8: =('Kwh Reading'!C9-'Kwh Reading'!C8)*1000 -> 280 | F8: =('Kwh Reading'!J9-'Kwh Reading'!J8)*1000 -> 440 | G8: =('Kwh Reading'!K9-'Kwh Reading'!K8)*1000 -> 310 | H8: =('Kwh Reading'!L9-'Kwh Reading'!L8)*1000 -> 190 | I8: =('Kwh Reading'!R9-'Kwh Reading'!R8)*1000 -> 0 | J8: =('Kwh Reading'!S9-'Kwh Reading'!S8)*1000 -> 50 | K8: =('Kwh Reading'!I9-'Kwh Reading'!I8)*1000 -> 340 | L8: =('Kwh Reading'!B9-'Kwh Reading'!B8)*1000000 -> 1100 | M8: =('Kwh Reading'!M9-'Kwh Reading'!M8)*1000 -> 340 | N8: =('Kwh Reading'!H9-'Kwh Reading'!H8)*1000000 -> 700 | O8: =('Kwh Reading'!P9-'Kwh Reading'!P8)*1000000 -> 500 | P8: =('Kwh Reading'!G9-'Kwh Reading'!G8)*1000000 -> 600 | Q8: =('Kwh Reading'!Q9-'Kwh Reading'!Q8)*1000 -> 220 | R8: =('Kwh Reading'!N9-'Kwh Reading'!N8)*1000 -> 350 | S8: ='Kwh Reading'!E9-'Kwh Reading'!E8 -> 2279.67 | T8: ='Kwh Reading'!D9-'Kwh Reading'!D8 -> 1603.3 | U8: =('Kwh Reading'!O9-'Kwh Reading'!O8)*1000 -> 190 | V8: =B8-(SUM(C8:U8)) -> 5817.03
A9: ='Kwh Reading'!A9 -> 44840 | B9: =TOTAL!E7 -> 19040 | C9: =('Kwh Reading'!T10-'Kwh Reading'!T9)*1000 -> 500 | D9: =('Kwh Reading'!F10-'Kwh Reading'!F9)*1000000 -> 2700 | E9: =('Kwh Reading'!C10-'Kwh Reading'!C9)*1000 -> 280 | F9: =('Kwh Reading'!J10-'Kwh Reading'!J9)*1000 -> 320 | G9: =('Kwh Reading'!K10-'Kwh Reading'!K9)*1000 -> 290 | H9: =('Kwh Reading'!L10-'Kwh Reading'!L9)*1000 -> 190 | I9: =('Kwh Reading'!R10-'Kwh Reading'!R9)*1000 -> 0 | J9: =('Kwh Reading'!S10-'Kwh Reading'!S9)*1000 -> 120 | K9: =('Kwh Reading'!I10-'Kwh Reading'!I9)*1000 -> 350 | L9: =('Kwh Reading'!B10-'Kwh Reading'!B9)*1000000 -> 1200 | M9: =('Kwh Reading'!M10-'Kwh Reading'!M9)*1000 -> 410 | N9: =('Kwh Reading'!H10-'Kwh Reading'!H9)*1000000 -> 600 | O9: =('Kwh Reading'!P10-'Kwh Reading'!P9)*1000000 -> 600 | P9: =('Kwh Reading'!G10-'Kwh Reading'!G9)*1000000 -> 500 | Q9: =('Kwh Reading'!Q10-'Kwh Reading'!Q9)*1000 -> 180 | R9: =('Kwh Reading'!N10-'Kwh Reading'!N9)*1000 -> 390 | S9: ='Kwh Reading'!E10-'Kwh Reading'!E9 -> 2595.14 | T9: ='Kwh Reading'!D10-'Kwh Reading'!D9 -> 1536.33 | U9: =('Kwh Reading'!O10-'Kwh Reading'!O9)*1000 -> 220 | V9: =B9-(SUM(C9:U9)) -> 6058.53
A10: ='Kwh Reading'!A10 -> 44841 | B10: =TOTAL!E8 -> 18260 | C10: =('Kwh Reading'!T11-'Kwh Reading'!T10)*1000 -> 270 | D10: =('Kwh Reading'!F11-'Kwh Reading'!F10)*1000000 -> 2700 | E10: =('Kwh Reading'!C11-'Kwh Reading'!C10)*1000 -> 260 | F10: =('Kwh Reading'!J11-'Kwh Reading'!J10)*1000 -> 390 | G10: =('Kwh Reading'!K11-'Kwh Reading'!K10)*1000 -> 310 | H10: =('Kwh Reading'!L11-'Kwh Reading'!L10)*1000 -> 230 | I10: =('Kwh Reading'!R11-'Kwh Reading'!R10)*1000 -> 0 | J10: =('Kwh Reading'!S11-'Kwh Reading'!S10)*1000 -> 110 | K10: =('Kwh Reading'!I11-'Kwh Reading'!I10)*1000 -> 310 | L10: =('Kwh Reading'!B11-'Kwh Reading'!B10)*1000000 -> 1000 | M10: =('Kwh Reading'!M11-'Kwh Reading'!M10)*1000 -> 420 | N10: =('Kwh Reading'!H11-'Kwh Reading'!H10)*1000000 -> 700 | O10: =('Kwh Reading'!P11-'Kwh Reading'!P10)*1000000 -> 600 | P10: =('Kwh Reading'!G11-'Kwh Reading'!G10)*1000000 -> 500 | Q10: =('Kwh Reading'!Q11-'Kwh Reading'!Q10)*1000 -> 170 | R10: =('Kwh Reading'!N11-'Kwh Reading'!N10)*1000 -> 380 | S10: ='Kwh Reading'!E11-'Kwh Reading'!E10 -> 1968.65 | T10: ='Kwh Reading'!D11-'Kwh Reading'!D10 -> -8409605.3 | U10: =('Kwh Reading'!O11-'Kwh Reading'!O10)*1000 -> 200 | V10: =B10-(SUM(C10:U10)) -> 8417346.6
A11: ='Kwh Reading'!A11 -> 44842 | B11: =TOTAL!E9 -> 18200 | C11: =('Kwh Reading'!T12-'Kwh Reading'!T11)*1000 -> 490 | D11: =('Kwh Reading'!F12-'Kwh Reading'!F11)*1000000 -> 2700 | E11: =('Kwh Reading'!C12-'Kwh Reading'!C11)*1000 -> 270 | F11: =('Kwh Reading'!J12-'Kwh Reading'!J11)*1000 -> 410 | G11: =('Kwh Reading'!K12-'Kwh Reading'!K11)*1000 -> 320 | H11: =('Kwh Reading'!L12-'Kwh Reading'!L11)*1000 -> 210 | I11: =('Kwh Reading'!R12-'Kwh Reading'!R11)*1000 -> 0 | J11: =('Kwh Reading'!S12-'Kwh Reading'!S11)*1000 -> 120 | K11: =('Kwh Reading'!I12-'Kwh Reading'!I11)*1000 -> 330 | L11: =('Kwh Reading'!B12-'Kwh Reading'!B11)*1000000 -> 1000 | M11: =('Kwh Reading'!M12-'Kwh Reading'!M11)*1000 -> 400 | N11: =('Kwh Reading'!H12-'Kwh Reading'!H11)*1000000 -> 700 | O11: =('Kwh Reading'!P12-'Kwh Reading'!P11)*1000000 -> 500 | P11: =('Kwh Reading'!G12-'Kwh Reading'!G11)*1000000 -> 500 | Q11: =('Kwh Reading'!Q12-'Kwh Reading'!Q11)*1000 -> 200 | R11: =('Kwh Reading'!N12-'Kwh Reading'!N11)*1000 -> 400 | S11: ='Kwh Reading'!E12-'Kwh Reading'!E11 -> 2164.34 | T11: ='Kwh Reading'!D12-'Kwh Reading'!D11 -> 1577.77 | U11: =('Kwh Reading'!O12-'Kwh Reading'!O11)*1000 -> 200 | V11: =B11-(SUM(C11:U11)) -> 5707.89
A12: ='Kwh Reading'!A12 -> 44843 | B12: =TOTAL!E10 -> 18530 | C12: =('Kwh Reading'!T13-'Kwh Reading'!T12)*1000 -> 520 | D12: =('Kwh Reading'!F13-'Kwh Reading'!F12)*1000000 -> 2700 | E12: =('Kwh Reading'!C13-'Kwh Reading'!C12)*1000 -> 270 | F12: =('Kwh Reading'!J13-'Kwh Reading'!J12)*1000 -> 430 | G12: =('Kwh Reading'!K13-'Kwh Reading'!K12)*1000 -> 290 | H12: =('Kwh Reading'!L13-'Kwh Reading'!L12)*1000 -> 190 | I12: =('Kwh Reading'!R13-'Kwh Reading'!R12)*1000 -> 0 | J12: =('Kwh Reading'!S13-'Kwh Reading'!S12)*1000 -> 110 | K12: =('Kwh Reading'!I13-'Kwh Reading'!I12)*1000 -> 310 | L12: =('Kwh Reading'!B13-'Kwh Reading'!B12)*1000000 -> 1100 | M12: =('Kwh Reading'!M13-'Kwh Reading'!M12)*1000 -> 410 | N12: =('Kwh Reading'!H13-'Kwh Reading'!H12)*1000000 -> 600 | O12: =('Kwh Reading'!P13-'Kwh Reading'!P12)*1000000 -> 600 | P12: =('Kwh Reading'!G13-'Kwh Reading'!G12)*1000000 -> 600 | Q12: =('Kwh Reading'!Q13-'Kwh Reading'!Q12)*1000 -> 210 | R12: =('Kwh Reading'!N13-'Kwh Reading'!N12)*1000 -> 370 | S12: ='Kwh Reading'!E13-'Kwh Reading'!E12 -> 2134.17 | T12: ='Kwh Reading'!D13-'Kwh Reading'!D12 -> 1622.53 | U12: =('Kwh Reading'!O13-'Kwh Reading'!O12)*1000 -> 200 | V12: =B12-(SUM(C12:U12)) -> 5863.3
A13: ='Kwh Reading'!A13 -> 44844 | B13: =TOTAL!E11 -> 17510 | C13: =('Kwh Reading'!T14-'Kwh Reading'!T13)*1000 -> 460 | D13: =('Kwh Reading'!F14-'Kwh Reading'!F13)*1000000 -> 2700 | E13: =('Kwh Reading'!C14-'Kwh Reading'!C13)*1000 -> 280 | F13: =('Kwh Reading'!J14-'Kwh Reading'!J13)*1000 -> 460 | G13: =('Kwh Reading'!K14-'Kwh Reading'!K13)*1000 -> 320 | H13: =('Kwh Reading'!L14-'Kwh Reading'!L13)*1000 -> 210 | I13: =('Kwh Reading'!R14-'Kwh Reading'!R13)*1000 -> 0 | J13: =('Kwh Reading'!S14-'Kwh Reading'!S13)*1000 -> 110 | K13: =('Kwh Reading'!I14-'Kwh Reading'!I13)*1000 -> 250 | L13: =('Kwh Reading'!B14-'Kwh Reading'!B13)*1000000 -> 1000 | M13: =('Kwh Reading'!M14-'Kwh Reading'!M13)*1000 -> 300 | N13: =('Kwh Reading'!H14-'Kwh Reading'!H13)*1000000 -> 600 | O13: =('Kwh Reading'!P14-'Kwh Reading'!P13)*1000000 -> 500 | P13: =('Kwh Reading'!G14-'Kwh Reading'!G13)*1000000 -> 500 | Q13: =('Kwh Reading'!Q14-'Kwh Reading'!Q13)*1000 -> 160 | R13: =('Kwh Reading'!N14-'Kwh Reading'!N13)*1000 -> 320 | S13: ='Kwh Reading'!E14-'Kwh Reading'!E13 -> 1874.08 | T13: ='Kwh Reading'!D14-'Kwh Reading'!D13 -> 1388.51 | U13: =('Kwh Reading'!O14-'Kwh Reading'!O13)*1000 -> 220 | V13: =B13-(SUM(C13:U13)) -> 5857.41
A14: ='Kwh Reading'!A14 -> 44845 | B14: =TOTAL!E12 -> 16480 | C14: =('Kwh Reading'!T15-'Kwh Reading'!T14)*1000 -> 430 | D14: =('Kwh Reading'!F15-'Kwh Reading'!F14)*1000000 -> 2500 | E14: =('Kwh Reading'!C15-'Kwh Reading'!C14)*1000 -> 300 | F14: =('Kwh Reading'!J15-'Kwh Reading'!J14)*1000 -> 390 | G14: =('Kwh Reading'!K15-'Kwh Reading'!K14)*1000 -> 300 | H14: =('Kwh Reading'!L15-'Kwh Reading'!L14)*1000 -> 220 | I14: =('Kwh Reading'!R15-'Kwh Reading'!R14)*1000 -> 0 | J14: =('Kwh Reading'!S15-'Kwh Reading'!S14)*1000 -> 70 | K14: =('Kwh Reading'!I15-'Kwh Reading'!I14)*1000 -> 240 | L14: =('Kwh Reading'!B15-'Kwh Reading'!B14)*1000000 -> 900 | M14: =('Kwh Reading'!M15-'Kwh Reading'!M14)*1000 -> 360 | N14: =('Kwh Reading'!H15-'Kwh Reading'!H14)*1000000 -> 600 | O14: =('Kwh Reading'!P15-'Kwh Reading'!P14)*1000000 -> 400 | P14: =('Kwh Reading'!G15-'Kwh Reading'!G14)*1000000 -> 500 | Q14: =('Kwh Reading'!Q15-'Kwh Reading'!Q14)*1000 -> 140 | R14: =('Kwh Reading'!N15-'Kwh Reading'!N14)*1000 -> 300 | S14: ='Kwh Reading'!E15-'Kwh Reading'!E14 -> 1840.22 | T14: ='Kwh Reading'!D15-'Kwh Reading'!D14 -> 1407.89 | U14: =('Kwh Reading'!O15-'Kwh Reading'!O14)*1000 -> 200 | V14: =B14-(SUM(C14:U14)) -> 5381.89
A15: ='Kwh Reading'!A15 -> 44846 | B15: =TOTAL!E13 -> 17610 | C15: =('Kwh Reading'!T16-'Kwh Reading'!T15)*1000 -> 470 | D15: =('Kwh Reading'!F16-'Kwh Reading'!F15)*1000000 -> 2600 | E15: =('Kwh Reading'!C16-'Kwh Reading'!C15)*1000 -> 260 | F15: =('Kwh Reading'!J16-'Kwh Reading'!J15)*1000 -> 650 | G15: =('Kwh Reading'!K16-'Kwh Reading'!K15)*1000 -> 340 | H15: =('Kwh Reading'!L16-'Kwh Reading'!L15)*1000 -> 240 | I15: =('Kwh Reading'!R16-'Kwh Reading'!R15)*1000 -> 0 | J15: =('Kwh Reading'!S16-'Kwh Reading'!S15)*1000 -> 0 | K15: =('Kwh Reading'!I16-'Kwh Reading'!I15)*1000 -> 260 | L15: =('Kwh Reading'!B16-'Kwh Reading'!B15)*1000000 -> 900 | M15: =('Kwh Reading'!M16-'Kwh Reading'!M15)*1000 -> 400 | N15: =('Kwh Reading'!H16-'Kwh Reading'!H15)*1000000 -> 600 | O15: =('Kwh Reading'!P16-'Kwh Reading'!P15)*1000000 -> 500 | P15: =('Kwh Reading'!G16-'Kwh Reading'!G15)*1000000 -> 400 | Q15: =('Kwh Reading'!Q16-'Kwh Reading'!Q15)*1000 -> 140 | R15: =('Kwh Reading'!N16-'Kwh Reading'!N15)*1000 -> 330 | S15: ='Kwh Reading'!E16-'Kwh Reading'!E15 -> 1992.87 | T15: ='Kwh Reading'!D16-'Kwh Reading'!D15 -> 1361.36 | U15: =('Kwh Reading'!O16-'Kwh Reading'!O15)*1000 -> 220 | V15: =B15-(SUM(C15:U15)) -> 5945.77
... A34: ='Kwh Reading'!A34 -> 44865 | B34: =TOTAL!E32 -> 0 | C34: =('Kwh Reading'!T35-'Kwh Reading'!T34)*1000 -> 0 | D34: =('Kwh Reading'!F35-'Kwh Reading'!F34)*1000000 -> 0 | E34: =('Kwh Reading'!C35-'Kwh Reading'!C34)*1000 -> 0 | F34: =('Kwh Reading'!J35-'Kwh Reading'!J34)*1000 -> 0 | G34: =('Kwh Reading'!K35-'Kwh Reading'!K34)*1000 -> 0 | H34: =('Kwh Reading'!L35-'Kwh Reading'!L34)*1000 -> 0 | I34: =('Kwh Reading'!R35-'Kwh Reading'!R34)*1000 -> 0 | J34: =('Kwh Reading'!S35-'Kwh Reading'!S34)*1000 -> 0 | K34: =('Kwh Reading'!I35-'Kwh Reading'!I34)*1000 -> 0 | L34: =('Kwh Reading'!B35-'Kwh Reading'!B34)*1000000 -> 0 | M34: =('Kwh Reading'!M35-'Kwh Reading'!M34)*1000 -> 0 | N34: =('Kwh Reading'!H35-'Kwh Reading'!H34)*1000000 -> 0 | O34: =('Kwh Reading'!P35-'Kwh Reading'!P34)*1000000 -> 0 | P34: =('Kwh Reading'!G35-'Kwh Reading'!G34)*1000000 -> 0 | Q34: =('Kwh Reading'!Q35-'Kwh Reading'!Q34)*1000 -> 0 | R34: =('Kwh Reading'!N35-'Kwh Reading'!N34)*1000 -> 0 | S34: ='Kwh Reading'!E35-'Kwh Reading'!E34 -> 0 | T34: ='Kwh Reading'!D35-'Kwh Reading'!D34 -> 0 | U34: =('Kwh Reading'!O35-'Kwh Reading'!O34)*1000 -> 0 | V34: =B34-(SUM(C34:U34)) -> 0
A35: Total | B35: =SUM(B4:B34) -> 245820 | C35: =SUM(C4:C34) -> -640710 | D35: =SUM(D4:D34) -> -3570700 | E35: =SUM(E4:E34) -> -343800 | F35: =SUM(F4:F34) -> -522320 | G35: =SUM(G4:G34) -> #VALUE! | H35: =SUM(H4:H34) -> -339340 | I35: =SUM(I4:I34) -> -190150 | ... V35: =SUM(V4:V34) -> #VALUE!

Sheet Kwh area wise 
A2: Month | B2: Total KWH | C2: Reef Club Kitchen KWH | D2: Main Kitchen KWH | E2: Pastry Kitchen KWH | F2: Laundry KWH | G2: STP KWH | H2: Kuda Huraa Accomodation KWH | I2: Guest Room Beach Pavilion & Beach Bungalow KWH | J2: Guest Room Water Bungalow KWH | K2: Spa KWH | L2: Others KWH
A3: ='Kwh Reading'!A4 -> 44835 | B3: =TOTAL!E2 -> 17270 | C3: ='Kwh Consumption'!C4 -> 390 | D3: ='Kwh Consumption'!D4 -> 2500 | E3: ='Kwh Consumption'!E4 -> 270 | F3: =('Kwh Consumption'!F4+'Kwh Consumption'!G4+'Kwh Consumption'!H4) -> 770 | G3: =('Kwh Consumption'!I4+'Kwh Consumption'!J4) -> 140 | H3: =('Kwh Consumption'!K4+'Kwh Consumption'!L4) -> 1180 | I3: =('Kwh Consumption'!M4+'Kwh Consumption'!N4+'Kwh Consumption'!O4+'Kwh Consumption'!P4+'Kwh Consumption'!Q4+'Kwh Consumption'!R4) -> 2310 | J3: =('Kwh Consumption'!S4+'Kwh Consumption'!T4) -> 3641.93 | K3: ='Kwh Consumption'!U4 -> 210 | L3: =B3-C3-D3-E3-F3-G3-H3-I3-J3-K3 -> 5858.07
A4: ='Kwh Reading'!A5 -> 44836 | B4: =TOTAL!E3 -> 16960 | C4: ='Kwh Consumption'!C5 -> 490 | D4: ='Kwh Consumption'!D5 -> 2700 | E4: ='Kwh Consumption'!E5 -> 260 | F4: =('Kwh Consumption'!F5+'Kwh Consumption'!G5+'Kwh Consumption'!H5) -> 1000 | G4: =('Kwh Consumption'!I5+'Kwh Consumption'!J5) -> 120 | H4: =('Kwh Consumption'!K5+'Kwh Consumption'!L5) -> 1420 | I4: =('Kwh Consumption'!M5+'Kwh Consumption'!N5+'Kwh Consumption'!O5+'Kwh Consumption'!P5+'Kwh Consumption'!Q5+'Kwh Consumption'!R5) -> 2440 | J4: =('Kwh Consumption'!S5+'Kwh Consumption'!T5) -> 3698.45 | K4: ='Kwh Consumption'!U5 -> 230 | L4: =B4-C4-D4-E4-F4-G4-H4-I4-J4-K4 -> 4601.55
A5: ='Kwh Reading'!A6 -> 44837 | B5: =TOTAL!E4 -> 18580 | C5: ='Kwh Consumption'!C6 -> 470 | D5: ='Kwh Consumption'!D6 -> 2600 | E5: ='Kwh Consumption'!E6 -> 260 | F5: =('Kwh Consumption'!F6+'Kwh Consumption'!G6+'Kwh Consumption'!H6) -> 1060 | G5: =('Kwh Consumption'!I6+'Kwh Consumption'!J6) -> 120 | H5: =('Kwh Consumption'!K6+'Kwh Consumption'!L6) -> 1210 | I5: =('Kwh Consumption'!M6+'Kwh Consumption'!N6+'Kwh Consumption'!O6+'Kwh Consumption'!P6+'Kwh Consumption'!Q6+'Kwh Consumption'!R6) -> 1990 | J5: =('Kwh Consumption'!S6+'Kwh Consumption'!T6) -> 3657.14 | K5: ='Kwh Consumption'!U6 -> 210 | L5: =B5-C5-D5-E5-F5-G5-H5-I5-J5-K5 -> 7002.86
A6: ='Kwh Reading'!A7 -> 44838 | B6: =TOTAL!E5 -> 17550 | C6: ='Kwh Consumption'!C7 -> 480 | D6: ='Kwh Consumption'!D7 -> 2400 | E6: ='Kwh Consumption'!E7 -> 260 | F6: =('Kwh Consumption'!F7+'Kwh Consumption'!G7+'Kwh Consumption'!H7) -> 930 | G6: =('Kwh Consumption'!I7+'Kwh Consumption'!J7) -> 190 | H6: =('Kwh Consumption'!K7+'Kwh Consumption'!L7) -> 1290 | I6: =('Kwh Consumption'!M7+'Kwh Consumption'!N7+'Kwh Consumption'!O7+'Kwh Consumption'!P7+'Kwh Consumption'!Q7+'Kwh Consumption'!R7) -> 2800 | J6: =('Kwh Consumption'!S7+'Kwh Consumption'!T7) -> 3655.26 | K6: ='Kwh Consumption'!U7 -> 190 | L6: =B6-C6-D6-E6-F6-G6-H6-I6-J6-K6 -> 5354.74
A7: ='Kwh Reading'!A8 -> 44839 | B7: =TOTAL!E6 -> 18520 | C7: ='Kwh Consumption'!C8 -> 510 | D7: ='Kwh Consumption'!D8 -> 2700 | E7: ='Kwh Consumption'!E8 -> 280 | F7: =('Kwh Consumption'!F8+'Kwh Consumption'!G8+'Kwh Consumption'!H8) -> 940 | G7: =('Kwh Consumption'!I8+'Kwh Consumption'!J8) -> 50 | H7: =('Kwh Consumption'!K8+'Kwh Consumption'!L8) -> 1440 | I7: =('Kwh Consumption'!M8+'Kwh Consumption'!N8+'Kwh Consumption'!O8+'Kwh Consumption'!P8+'Kwh Consumption'!Q8+'Kwh Consumption'!R8) -> 2710 | J7: =('Kwh Consumption'!S8+'Kwh Consumption'!T8) -> 3882.97 | K7: ='Kwh Consumption'!U8 -> 190 | L7: =B7-C7-D7-E7-F7-G7-H7-I7-J7-K7 -> 5817.03
A8: ='Kwh Reading'!A9 -> 44840 | B8: =TOTAL!E7 -> 19040 | C8: ='Kwh Consumption'!C9 -> 500 | D8: ='Kwh Consumption'!D9 -> 2700 | E8: ='Kwh Consumption'!E9 -> 280 | F8: =('Kwh Consumption'!F9+'Kwh Consumption'!G9+'Kwh Consumption'!H9) -> 800 | G8: =('Kwh Consumption'!I9+'Kwh Consumption'!J9) -> 120 | H8: =('Kwh Consumption'!K9+'Kwh Consumption'!L9) -> 1550 | I8: =('Kwh Consumption'!M9+'Kwh Consumption'!N9+'Kwh Consumption'!O9+'Kwh Consumption'!P9+'Kwh Consumption'!Q9+'Kwh Consumption'!R9) -> 2680 | J8: =('Kwh Consumption'!S9+'Kwh Consumption'!T9) -> 4131.47 | K8: ='Kwh Consumption'!U9 -> 220 | L8: =B8-C8-D8-E8-F8-G8-H8-I8-J8-K8 -> 6058.53
A9: ='Kwh Reading'!A10 -> 44841 | B9: =TOTAL!E8 -> 18260 | C9: ='Kwh Consumption'!C10 -> 270 | D9: ='Kwh Consumption'!D10 -> 2700 | E9: ='Kwh Consumption'!E10 -> 260 | F9: =('Kwh Consumption'!F10+'Kwh Consumption'!G10+'Kwh Consumption'!H10) -> 930 | G9: =('Kwh Consumption'!I10+'Kwh Consumption'!J10) -> 110 | H9: =('Kwh Consumption'!K10+'Kwh Consumption'!L10) -> 1310 | I9: =('Kwh Consumption'!M10+'Kwh Consumption'!N10+'Kwh Consumption'!O10+'Kwh Consumption'!P10+'Kwh Consumption'!Q10+'Kwh Consumption'!R10) -> 2770 | J9: =('Kwh Consumption'!S10+'Kwh Consumption'!T10) -> -8407636.7 | K9: ='Kwh Consumption'!U10 -> 200 | L9: =B9-C9-D9-E9-F9-G9-H9-I9-J9-K9 -> 8417346.6
A10: ='Kwh Reading'!A11 -> 44842 | B10: =TOTAL!E9 -> 18200 | C10: ='Kwh Consumption'!C11 -> 490 | D10: ='Kwh Consumption'!D11 -> 2700 | E10: ='Kwh Consumption'!E11 -> 270 | F10: =('Kwh Consumption'!F11+'Kwh Consumption'!G11+'Kwh Consumption'!H11) -> 940 | G10: =('Kwh Consumption'!I11+'Kwh Consumption'!J11) -> 120 | H10: =('Kwh Consumption'!K11+'Kwh Consumption'!L11) -> 1330 | I10: =('Kwh Consumption'!M11+'Kwh Consumption'!N11+'Kwh Consumption'!O11+'Kwh Consumption'!P11+'Kwh Consumption'!Q11+'Kwh Consumption'!R11) -> 2700 | J10: =('Kwh Consumption'!S11+'Kwh Consumption'!T11) -> 3742.11 | K10: ='Kwh Consumption'!U11 -> 200 | L10: =B10-C10-D10-E10-F10-G10-H10-I10-J10-K10 -> 5707.89
A11: ='Kwh Reading'!A12 -> 44843 | B11: =TOTAL!E10 -> 18530 | C11: ='Kwh Consumption'!C12 -> 520 | D11: ='Kwh Consumption'!D12 -> 2700 | E11: ='Kwh Consumption'!E12 -> 270 | F11: =('Kwh Consumption'!F12+'Kwh Consumption'!G12+'Kwh Consumption'!H12) -> 910 | G11: =('Kwh Consumption'!I12+'Kwh Consumption'!J12) -> 110 | H11: =('Kwh Consumption'!K12+'Kwh Consumption'!L12) -> 1410 | I11: =('Kwh Consumption'!M12+'Kwh Consumption'!N12+'Kwh Consumption'!O12+'Kwh Consumption'!P12+'Kwh Consumption'!Q12+'Kwh Consumption'!R12) -> 2790 | J11: =('Kwh Consumption'!S12+'Kwh Consumption'!T12) -> 3756.7 | K11: ='Kwh Consumption'!U12 -> 200 | L11: =B11-C11-D11-E11-F11-G11-H11-I11-J11-K11 -> 5863.3
A12: ='Kwh Reading'!A13 -> 44844 | B12: =TOTAL!E11 -> 17510 | C12: ='Kwh Consumption'!C13 -> 460 | D12: ='Kwh Consumption'!D13 -> 2700 | E12: ='Kwh Consumption'!E13 -> 280 | F12: =('Kwh Consumption'!F13+'Kwh Consumption'!G13+'Kwh Consumption'!H13) -> 990 | G12: =('Kwh Consumption'!I13+'Kwh Consumption'!J13) -> 110 | H12: =('Kwh Consumption'!K13+'Kwh Consumption'!L13) -> 1250 | I12: =('Kwh Consumption'!M13+'Kwh Consumption'!N13+'Kwh Consumption'!O13+'Kwh Consumption'!P13+'Kwh Consumption'!Q13+'Kwh Consumption'!R13) -> 2380 | J12: =('Kwh Consumption'!S13+'Kwh Consumption'!T13) -> 3262.59 | K12: ='Kwh Consumption'!U13 -> 220 | L12: =B12-C12-D12-E12-F12-G12-H12-I12-J12-K12 -> 5857.41
A13: ='Kwh Reading'!A14 -> 44845 | B13: =TOTAL!E12 -> 16480 | C13: ='Kwh Consumption'!C14 -> 430 | D13: ='Kwh Consumption'!D14 -> 2500 | E13: ='Kwh Consumption'!E14 -> 300 | F13: =('Kwh Consumption'!F14+'Kwh Consumption'!G14+'Kwh Consumption'!H14) -> 910 | G13: =('Kwh Consumption'!I14+'Kwh Consumption'!J14) -> 70 | H13: =('Kwh Consumption'!K14+'Kwh Consumption'!L14) -> 1140 | I13: =('Kwh Consumption'!M14+'Kwh Consumption'!N14+'Kwh Consumption'!O14+'Kwh Consumption'!P14+'Kwh Consumption'!Q14+'Kwh Consumption'!R14) -> 2300 | J13: =('Kwh Consumption'!S14+'Kwh Consumption'!T14) -> 3248.11 | K13: ='Kwh Consumption'!U14 -> 200 | L13: =B13-C13-D13-E13-F13-G13-H13-I13-J13-K13 -> 5381.89
A14: ='Kwh Reading'!A15 -> 44846 | B14: =TOTAL!E13 -> 17610 | C14: ='Kwh Consumption'!C15 -> 470 | D14: ='Kwh Consumption'!D15 -> 2600 | E14: ='Kwh Consumption'!E15 -> 260 | F14: =('Kwh Consumption'!F15+'Kwh Consumption'!G15+'Kwh Consumption'!H15) -> 1230 | G14: =('Kwh Consumption'!I15+'Kwh Consumption'!J15) -> 0 | H14: =('Kwh Consumption'!K15+'Kwh Consumption'!L15) -> 1160 | I14: =('Kwh Consumption'!M15+'Kwh Consumption'!N15+'Kwh Consumption'!O15+'Kwh Consumption'!P15+'Kwh Consumption'!Q15+'Kwh Consumption'!R15) -> 2370 | J14: =('Kwh Consumption'!S15+'Kwh Consumption'!T15) -> 3354.23 | K14: ='Kwh Consumption'!U15 -> 220 | L14: =B14-C14-D14-E14-F14-G14-H14-I14-J14-K14 -> 5945.77
... A33: ='Kwh Reading'!A34 -> 44865 | B33: =TOTAL!E32 -> 0 | C33: ='Kwh Consumption'!C34 -> 0 | D33: ='Kwh Consumption'!D34 -> 0 | E33: ='Kwh Consumption'!E34 -> 0 | F33: =('Kwh Consumption'!F34+'Kwh Consumption'!G34+'Kwh Consumption'!H34) -> 0 | G33: =('Kwh Consumption'!I34+'Kwh Consumption'!J34) -> 0 | H33: =('Kwh Consumption'!K34+'Kwh Consumption'!L34) -> 0 | I33: =('Kwh Consumption'!M34+'Kwh Consumption'!N34+'Kwh Consumption'!O34+'Kwh Consumption'!P34+'Kwh Consumption'!Q34+'Kwh Consumption'!R34) -> 0 | J33: =('Kwh Consumption'!S34+'Kwh Consumption'!T34) -> 0 | K33: ='Kwh Consumption'!U34 -> 0 | L33: =B33-C33-D33-E33-F33-G33-H33-I33-J33-K33 -> 0
A34: Total kwh | B34: =SUM(B3:B33) -> 245820 | C34: =SUM(C3:C33) -> -640710 | D34: =SUM(D3:D33) -> -3570700 | E34: =SUM(E3:E33) -> -343800 | F34: =SUM(F3:F33) -> #VALUE! | G34: =SUM(G3:G33) -> -367940 | H34: =SUM(H3:H33) -> -1881790 | I34: =SUM(I3:I33) -> -5602560 | ... L34: =SUM(L3:L33) -> #VALUE! | M34: =C34+D34+E34+F34+G34+H34+I34+J34+K34+L34 -> #VALUE!
A36: Total $ | B36: =TOTAL!F2 -> 0 | C36: =C34*B36 -> 0 | D36: =D34*B36 -> 0 | E36: =E34*B36 -> 0 | F36: =F34*B36 -> #VALUE! | G36: =G34*B36 -> 0 | H36: =H34*B36 -> 0 | I36: =I34*B36 -> 0 | J36: =J34*B36 -> 0 | K36: =K34*B36 -> 0 | L36: =L34*B36 -> #VALUE! | M36: =C36+D36+E36+F36+G36+H36+I36+J36+K36+L36 -> #VALUE!

Sheet  Kwh area wise $ 
A2: Month | B2: $ /Per KWH | C2: Total $ | D2: Reef Club $ | E2: Kitchen $ | F2: Pastry $ | G2: Laundry $ | H2: STP $ | I2: Kuda Huraa Accomodation $ | J2: Guest Room Beach Pavilion & Beach Bungalow $ | K2: Guest Room Water Bungalow $ | L2: Spa $ | M2: Others $
A3: ='Kwh Reading'!A4 -> 44835 | B3: =TOTAL!F2 -> 0 | C3: ='Kwh Consumption'!B4*' Kwh area wise $ '!B3 -> 0 | D3: ='Kwh Consumption'!C4*' Kwh area wise $ '!B3 -> 0 | E3: ='Kwh Consumption'!D4*' Kwh area wise $ '!B3 -> 0 | F3: ='Kwh Consumption'!E4*' Kwh area wise $ '!B3 -> 0 | G3: =('Kwh Consumption'!F4+'Kwh Consumption'!G4+'Kwh Consumption'!H4)*' Kwh area wise $ '!B3 -> 0 | H3: =('Kwh Consumption'!I4+'Kwh Consumption'!J4)*' Kwh area wise $ '!B3 -> 0 | I3: =('Kwh Consumption'!K4+'Kwh Consumption'!L4)*' Kwh area wise $ '!B3 -> 0 | J3: =('Kwh Consumption'!M4+'Kwh Consumption'!N4+'Kwh Consumption'!O4+'Kwh Consumption'!P4+'Kwh Consumption'!Q4+'Kwh Consumption'!R4)*' Kwh area wise $ '!B3 -> 0 | K3: =('Kwh Consumption'!S4+'Kwh Consumption'!T4)*' Kwh area wise $ '!B3 -> 0 | L3: ='Kwh Consumption'!U4*' Kwh area wise $ '!B3 -> 0 | M3: ='Kwh Consumption'!V4*' Kwh area wise $ '!B3 -> 0
A4: ='Kwh Reading'!A5 -> 44836 | B4: =TOTAL!F3 -> 0 | C4: ='Kwh Consumption'!B5*' Kwh area wise $ '!B4 -> 0 | D4: ='Kwh Consumption'!C5*' Kwh area wise $ '!B4 -> 0 | E4: ='Kwh Consumption'!D5*' Kwh area wise $ '!B4 -> 0 | F4: ='Kwh Consumption'!E5*' Kwh area wise $ '!B4 -> 0 | G4: =('Kwh Consumption'!F5+'Kwh Consumption'!G5+'Kwh Consumption'!H5)*' Kwh area wise $ '!B4 -> 0 | H4: =('Kwh Consumption'!I5+'Kwh Consumption'!J5)*' Kwh area wise $ '!B4 -> 0 | I4: =('Kwh Consumption'!K5+'Kwh Consumption'!L5)*' Kwh area wise $ '!B4 -> 0 | J4: =('Kwh Consumption'!M5+'Kwh Consumption'!N5+'Kwh Consumption'!O5+'Kwh Consumption'!P5+'Kwh Consumption'!Q5+'Kwh Consumption'!R5)*' Kwh area wise $ '!B4 -> 0 | K4: =('Kwh Consumption'!S5+'Kwh Consumption'!T5)*' Kwh area wise $ '!B4 -> 0 | L4: ='Kwh Consumption'!U5*' Kwh area wise $ '!B4 -> 0 | M4: ='Kwh Consumption'!V5*' Kwh area wise $ '!B4 -> 0
A5: ='Kwh Reading'!A6 -> 44837 | B5: =TOTAL!F4 -> 0 | C5: ='Kwh Consumption'!B6*' Kwh area wise $ '!B5 -> 0 | D5: ='Kwh Consumption'!C6*' Kwh area wise $ '!B5 -> 0 | E5: ='Kwh Consumption'!D6*' Kwh area wise $ '!B5 -> 0 | F5: ='Kwh Consumption'!E6*' Kwh area wise $ '!B5 -> 0 | G5: =('Kwh Consumption'!F6+'Kwh Consumption'!G6+'Kwh Consumption'!H6)*' Kwh area wise $ '!B5 -> 0 | H5: =('Kwh Consumption'!I6+'Kwh Consumption'!J6)*' Kwh area wise $ '!B5 -> 0 | I5: =('Kwh Consumption'!K6+'Kwh Consumption'!L6)*' Kwh area wise $ '!B5 -> 0 | J5: =('Kwh Consumption'!M6+'Kwh Consumption'!N6+'Kwh Consumption'!O6+'Kwh Consumption'!P6+'Kwh Consumption'!Q6+'Kwh Consumption'!R6)*' Kwh area wise $ '!B5 -> 0 | K5: =('Kwh Consumption'!S6+'Kwh Consumption'!T6)*' Kwh area wise $ '!B5 -> 0 | L5: ='Kwh Consumption'!U6*' Kwh area wise $ '!B5 -> 0 | M5: ='Kwh Consumption'!V6*' Kwh area wise $ '!B5 -> 0
A6: ='Kwh Reading'!A7 -> 44838 | B6: =TOTAL!F5 -> 0 | C6: ='Kwh Consumption'!B7*' Kwh area wise $ '!B6 -> 0 | D6: ='Kwh Consumption'!C7*' Kwh area wise $ '!B6 -> 0 | E6: ='Kwh Consumption'!D7*' Kwh area wise $ '!B6 -> 0 | F6: ='Kwh Consumption'!E7*' Kwh area wise $ '!B6 -> 0 | G6: =('Kwh Consumption'!F7+'Kwh Consumption'!G7+'Kwh Consumption'!H7)*' Kwh area wise $ '!B6 -> 0 | H6: =('Kwh Consumption'!I7+'Kwh Consumption'!J7)*' Kwh area wise $ '!B6 -> 0 | I6: =('Kwh Consumption'!K7+'Kwh Consumption'!L7)*' Kwh area wise $ '!B6 -> 0 | J6: =('Kwh Consumption'!M7+'Kwh Consumption'!N7+'Kwh Consumption'!O7+'Kwh Consumption'!P7+'Kwh Consumption'!Q7+'Kwh Consumption'!R7)*' Kwh area wise $ '!B6 -> 0 | K6: =('Kwh Consumption'!S7+'Kwh Consumption'!T7)*' Kwh area wise $ '!B6 -> 0 | L6: ='Kwh Consumption'!U7*' Kwh area wise $ '!B6 -> 0 | M6: ='Kwh Consumption'!V7*' Kwh area wise $ '!B6 -> 0
A7: ='Kwh Reading'!A8 -> 44839 | B7: =TOTAL!F6 -> 0 | C7: ='Kwh Consumption'!B8*' Kwh area wise $ '!B7 -> 0 | D7: ='Kwh Consumption'!C8*' Kwh area wise $ '!B7 -> 0 | E7: ='Kwh Consumption'!D8*' Kwh area wise $ '!B7 -> 0 | F7: ='Kwh Consumption'!E8*' Kwh area wise $ '!B7 -> 0 | G7: =('Kwh Consumption'!F8+'Kwh Consumption'!G8+'Kwh Consumption'!H8)*' Kwh area wise $ '!B7 -> 0 | H7: =('Kwh Consumption'!I8+'Kwh Consumption'!J8)*' Kwh area wise $ '!B7 -> 0 | I7: =('Kwh Consumption'!K8+'Kwh Consumption'!L8)*' Kwh area wise $ '!B7 -> 0 | J7: =('Kwh Consumption'!M8+'Kwh Consumption'!N8+'Kwh Consumption'!O8+'Kwh Consumption'!P8+'Kwh Consumption'!Q8+'Kwh Consumption'!R8)*' Kwh area wise $ '!B7 -> 0 | K7: =('Kwh Consumption'!S8+'Kwh Consumption'!T8)*' Kwh area wise $ '!B7 -> 0 | L7: ='Kwh Consumption'!U8*' Kwh area wise $ '!B7 -> 0 | M7: ='Kwh Consumption'!V8*' Kwh area wise $ '!B7 -> 0
A8: ='Kwh Reading'!A9 -> 44840 | B8: =TOTAL!F7 -> 0 | C8: ='Kwh Consumption'!B9*' Kwh area wise $ '!B8 -> 0 | D8: ='Kwh Consumption'!C9*' Kwh area wise $ '!B8 -> 0 | E8: ='Kwh Consumption'!D9*' Kwh area wise $ '!B8 -> 0 | F8: ='Kwh Consumption'!E9*' Kwh area wise $ '!B8 -> 0 | G8: =('Kwh Consumption'!F9+'Kwh Consumption'!G9+'Kwh Consumption'!H9)*' Kwh area wise $ '!B8 -> 0 | H8: =('Kwh Consumption'!I9+'Kwh Consumption'!J9)*' Kwh area wise $ '!B8 -> 0 | I8: =('Kwh Consumption'!K9+'Kwh Consumption'!L9)*' Kwh area wise $ '!B8 -> 0 | J8: =('Kwh Consumption'!M9+'Kwh Consumption'!N9+'Kwh Consumption'!O9+'Kwh Consumption'!P9+'Kwh Consumption'!Q9+'Kwh Consumption'!R9)*' Kwh area wise $ '!B8 -> 0 | K8: =('Kwh Consumption'!S9+'Kwh Consumption'!T9)*' Kwh area wise $ '!B8 -> 0 | L8: ='Kwh Consumption'!U9*' Kwh area wise $ '!B8 -> 0 | M8: ='Kwh Consumption'!V9*' Kwh area wise $ '!B8 -> 0
A9: ='Kwh Reading'!A10 -> 44841 | B9: =TOTAL!F8 -> 0 | C9: ='Kwh Consumption'!B10*' Kwh area wise $ '!B9 -> 0 | D9: ='Kwh Consumption'!C10*' Kwh area wise $ '!B9 -> 0 | E9: ='Kwh Consumption'!D10*' Kwh area wise $ '!B9 -> 0 | F9: ='Kwh Consumption'!E10*' Kwh area wise $ '!B9 -> 0 | G9: =('Kwh Consumption'!F10+'Kwh Consumption'!G10+'Kwh Consumption'!H10)*' Kwh area wise $ '!B9 -> 0 | H9: =('Kwh Consumption'!I10+'Kwh Consumption'!J10)*' Kwh area wise $ '!B9 -> 0 | I9: =('Kwh Consumption'!K10+'Kwh Consumption'!L10)*' Kwh area wise $ '!B9 -> 0 | J9: =('Kwh Consumption'!M10+'Kwh Consumption'!N10+'Kwh Consumption'!O10+'Kwh Consumption'!P10+'Kwh Consumption'!Q10+'Kwh Consumption'!R10)*' Kwh area wise $ '!B9 -> 0 | K9: =('Kwh Consumption'!S10+'Kwh Consumption'!T10)*' Kwh area wise $ '!B9 -> 0 | L9: ='Kwh Consumption'!U10*' Kwh area wise $ '!B9 -> 0 | M9: ='Kwh Consumption'!V10*' Kwh area wise $ '!B9 -> 0
A10: ='Kwh Reading'!A11 -> 44842 | B10: =TOTAL!F9 -> 0 | C10: ='Kwh Consumption'!B11*' Kwh area wise $ '!B10 -> 0 | D10: ='Kwh Consumption'!C11*' Kwh area wise $ '!B10 -> 0 | E10: ='Kwh Consumption'!D11*' Kwh area wise $ '!B10 -> 0 | F10: ='Kwh Consumption'!E11*' Kwh area wise $ '!B10 -> 0 | G10: =('Kwh Consumption'!F11+'Kwh Consumption'!G11+'Kwh Consumption'!H11)*' Kwh area wise $ '!B10 -> 0 | H10: =('Kwh Consumption'!I11+'Kwh Consumption'!J11)*' Kwh area wise $ '!B10 -> 0 | I10: =('Kwh Consumption'!K11+'Kwh Consumption'!L11)*' Kwh area wise $ '!B10 -> 0 | J10: =('Kwh Consumption'!M11+'Kwh Consumption'!N11+'Kwh Consumption'!O11+'Kwh Consumption'!P11+'Kwh Consumption'!Q11+'Kwh Consumption'!R11)*' Kwh area wise $ '!B10 -> 0 | K10: =('Kwh Consumption'!S11+'Kwh Consumption'!T11)*' Kwh area wise $ '!B10 -> 0 | L10: ='Kwh Consumption'!U11*' Kwh area wise $ '!B10 -> 0 | M10: ='Kwh Consumption'!V11*' Kwh area wise $ '!B10 -> 0
A11: ='Kwh Reading'!A12 -> 44843 | B11: =TOTAL!F10 -> 0 | C11: ='Kwh Consumption'!B12*' Kwh area wise $ '!B11 -> 0 | D11: ='Kwh Consumption'!C12*' Kwh area wise $ '!B11 -> 0 | E11: ='Kwh Consumption'!D12*' Kwh area wise $ '!B11 -> 0 | F11: ='Kwh Consumption'!E12*' Kwh area wise $ '!B11 -> 0 | G11: =('Kwh Consumption'!F12+'Kwh Consumption'!G12+'Kwh Consumption'!H12)*' Kwh area wise $ '!B11 -> 0 | H11: =('Kwh Consumption'!I12+'Kwh Consumption'!J12)*' Kwh area wise $ '!B11 -> 0 | I11: =('Kwh Consumption'!K12+'Kwh Consumption'!L12)*' Kwh area wise $ '!B11 -> 0 | J11: =('Kwh Consumption'!M12+'Kwh Consumption'!N12+'Kwh Consumption'!O12+'Kwh Consumption'!P12+'Kwh Consumption'!Q12+'Kwh Consumption'!R12)*' Kwh area wise $ '!B11 -> 0 | K11: =('Kwh Consumption'!S12+'Kwh Consumption'!T12)*' Kwh area wise $ '!B11 -> 0 | L11: ='Kwh Consumption'!U12*' Kwh area wise $ '!B11 -> 0 | M11: ='Kwh Consumption'!V12*' Kwh area wise $ '!B11 -> 0
A12: ='Kwh Reading'!A13 -> 44844 | B12: =TOTAL!F11 -> 0 | C12: ='Kwh Consumption'!B13*' Kwh area wise $ '!B12 -> 0 | D12: ='Kwh Consumption'!C13*' Kwh area wise $ '!B12 -> 0 | E12: ='Kwh Consumption'!D13*' Kwh area wise $ '!B12 -> 0 | F12: ='Kwh Consumption'!E13*' Kwh area wise $ '!B12 -> 0 | G12: =('Kwh Consumption'!F13+'Kwh Consumption'!G13+'Kwh Consumption'!H13)*' Kwh area wise $ '!B12 -> 0 | H12: =('Kwh Consumption'!I13+'Kwh Consumption'!J13)*' Kwh area wise $ '!B12 -> 0 | I12: =('Kwh Consumption'!K13+'Kwh Consumption'!L13)*' Kwh area wise $ '!B12 -> 0 | J12: =('Kwh Consumption'!M13+'Kwh Consumption'!N13+'Kwh Consumption'!O13+'Kwh Consumption'!P13+'Kwh Consumption'!Q13+'Kwh Consumption'!R13)*' Kwh area wise $ '!B12 -> 0 | K12: =('Kwh Consumption'!S13+'Kwh Consumption'!T13)*' Kwh area wise $ '!B12 -> 0 | L12: ='Kwh Consumption'!U13*' Kwh area wise $ '!B12 -> 0 | M12: ='Kwh Consumption'!V13*' Kwh area wise $ '!B12 -> 0
A13: ='Kwh Reading'!A14 -> 44845 | B13: =TOTAL!F12 -> 0 | C13: ='Kwh Consumption'!B14*' Kwh area wise $ '!B13 -> 0 | D13: ='Kwh Consumption'!C14*' Kwh area wise $ '!B13 -> 0 | E13: ='Kwh Consumption'!D14*' Kwh area wise $ '!B13 -> 0 | F13: ='Kwh Consumption'!E14*' Kwh area wise $ '!B13 -> 0 | G13: =('Kwh Consumption'!F14+'Kwh Consumption'!G14+'Kwh Consumption'!H14)*' Kwh area wise $ '!B13 -> 0 | H13: =('Kwh Consumption'!I14+'Kwh Consumption'!J14)*' Kwh area wise $ '!B13 -> 0 | I13: =('Kwh Consumption'!K14+'Kwh Consumption'!L14)*' Kwh area wise $ '!B13 -> 0 | J13: =('Kwh Consumption'!M14+'Kwh Consumption'!N14+'Kwh Consumption'!O14+'Kwh Consumption'!P14+'Kwh Consumption'!Q14+'Kwh Consumption'!R14)*' Kwh area wise $ '!B13 -> 0 | K13: =('Kwh Consumption'!S14+'Kwh Consumption'!T14)*' Kwh area wise $ '!B13 -> 0 | L13: ='Kwh Consumption'!U14*' Kwh area wise $ '!B13 -> 0 | M13: ='Kwh Consumption'!V14*' Kwh area wise $ '!B13 -> 0
A14: ='Kwh Reading'!A15 -> 44846 | B14: =TOTAL!F13 -> 0 | C14: ='Kwh Consumption'!B15*' Kwh area wise $ '!B14 -> 0 | D14: ='Kwh Consumption'!C15*' Kwh area wise $ '!B14 -> 0 | E14: ='Kwh Consumption'!D15*' Kwh area wise $ '!B14 -> 0 | F14: ='Kwh Consumption'!E15*' Kwh area wise $ '!B14 -> 0 | G14: =('Kwh Consumption'!F15+'Kwh Consumption'!G15+'Kwh Consumption'!H15)*' Kwh area wise $ '!B14 -> 0 | H14: =('Kwh Consumption'!I15+'Kwh Consumption'!J15)*' Kwh area wise $ '!B14 -> 0 | I14: =('Kwh Consumption'!K15+'Kwh Consumption'!L15)*' Kwh area wise $ '!B14 -> 0 | J14: =('Kwh Consumption'!M15+'Kwh Consumption'!N15+'Kwh Consumption'!O15+'Kwh Consumption'!P15+'Kwh Consumption'!Q15+'Kwh Consumption'!R15)*' Kwh area wise $ '!B14 -> 0 | K14: =('Kwh Consumption'!S15+'Kwh Consumption'!T15)*' Kwh area wise $ '!B14 -> 0 | L14: ='Kwh Consumption'!U15*' Kwh area wise $ '!B14 -> 0 | M14: ='Kwh Consumption'!V15*' Kwh area wise $ '!B14 -> 0
... A33: ='Kwh Reading'!A34 -> 44865 | B33: =TOTAL!F32 -> 0 | C33: ='Kwh Consumption'!B34*' Kwh area wise $ '!B33 -> 0 | D33: ='Kwh Consumption'!C34*' Kwh area wise $ '!B33 -> 0 | E33: ='Kwh Consumption'!D34*' Kwh area wise $ '!B33 -> 0 | F33: ='Kwh Consumption'!E34*' Kwh area wise $ '!B33 -> 0 | G33: =('Kwh Consumption'!F34+'Kwh Consumption'!G34+'Kwh Consumption'!H34)*' Kwh area wise $ '!B33 -> 0 | H33: =('Kwh Consumption'!I34+'Kwh Consumption'!J34)*' Kwh area wise $ '!B33 -> 0 | I33: =('Kwh Consumption'!K34+'Kwh Consumption'!L34)*' Kwh area wise $ '!B33 -> 0 | J33: =('Kwh Consumption'!M34+'Kwh Consumption'!N34+'Kwh Consumption'!O34+'Kwh Consumption'!P34+'Kwh Consumption'!Q34+'Kwh Consumption'!R34)*' Kwh area wise $ '!B33 -> 0 | K33: =('Kwh Consumption'!S34+'Kwh Consumption'!T34)*' Kwh area wise $ '!B33 -> 0 | L33: ='Kwh Consumption'!U34*' Kwh area wise $ '!B33 -> 0 | M33: ='Kwh Consumption'!V34*' Kwh area wise $ '!B33 -> 0
A34: Total | C34: =SUM(C3:C33) -> 0 | D34: =SUM(D3:D33) -> 0 | E34: =SUM(E3:E33) -> 0 | F34: =SUM(F3:F33) -> 0 | G34: =SUM(G3:G33) -> #VALUE! | H34: =SUM(H3:H33) -> 0 | I34: =SUM(I3:I33) -> 0 | J34: =SUM(J3:J33) -> 0 | ... M34: =SUM(M3:M33) -> #VALUE! | N34: =D34+E34+F34+G34+H34+I34+J34+K34+L34+M34 -> #VALUE!

Sheet Water Reading
B1: Meter 1 | C1: Meter 2 | D1: Meter 6 | E1: Meter 8 | F1: Meter 7 | G1: Meter 9 | H1: Meter 3 | I1: Meter 5 | J1: Meter 10 | K1: Meter 13 | L1: Meter 16 | M1: Meter 17 | N1: Meter 15 | O1: Meter 14 | P1: Meter 4 | Q1: Meter 11 | R1: Meter 12
A2: Date | B2: Main Meter 1 | C2: Main Meter 2 | D2: Beach Bunglow | E2: Kuda Huraa staff | F2: Bodu hura staff | G2: Laundry | H2: Water Bunglow | I2: Main Kitchen | J2: Second stage | K2: Supply jetty | L2: Staff housing A | M2: Staff housing B | N2: Spa | O2: Staff jetty | P2: Main pool | Q2: Reef club pool | R2: Reef club kitchen
A3: 44835 | B3: 15651 | C3: 21597 | D3: 286834 | E3: 279201 | F3: 67264 | G3: 122409 | H3: 62092 | I3: 78752 | J3: 23515 | K3: 1024 | L3: 19242 | M3: 28217 | N3: 8919 | O3: 2333 | P3: 32116 | Q3: 2057 | R3: 639
A4: 44836 | B4: 15789 | C4: 21796 | D4: 287017 | E4: 279278 | F4: 67264 | G4: 122427 | H4: 62092 | I4: 78764 | J4: 23520 | K4: 1024 | L4: 19247 | M4: 28225 | N4: 8920 | O4: 2335 | P4: 32116 | Q4: 2057 | R4: 642
A5: 44837 | B5: 15926 | C5: 21990 | D5: 287138 | E5: 279352 | F5: 67265 | G5: 122455 | H5: 62092 | I5: 78793 | J5: 23526 | K5: 1024 | L5: 19253 | M5: 28230 | N5: 8921 | O5: 2338 | P5: 32130 | Q5: 2064 | R5: 647
A6: 44838 | B6: 16089 | C6: 22231 | D6: 287400 | E6: 279418 | F6: 67265 | G6: 122473 | H6: 62092 | I6: 78802 | J6: 23530 | K6: 1024 | L6: 19257 | M6: 28235 | N6: 8922 | O6: 2340 | P6: 32130 | Q6: 2069 | R6: 649
A7: 44839 | B7: 16211 | C7: 22397 | D7: 287550 | E7: 279482 | F7: 67266 | G7: 122489 | H7: 62092 | I7: 78825 | J7: 23536 | K7: 1024 | L7: 19262 | M7: 28241 | N7: 8923 | O7: 2341 | P7: 32146 | Q7: 2071 | R7: 651
A8: 44840 | B8: 16341 | C8: 22582 | D8: 287705 | E8: 279554 | F8: 67267 | G8: 122510 | H8: 62092 | I8: 78844 | J8: 23542 | K8: 1024 | L8: 19267 | M8: 28247 | N8: 8927 | O8: 2343 | P8: 32146 | Q8: 2078 | R8: 656
A9: 44841 | B9: 16485 | C9: 22789 | D9: 287874 | E9: 279625 | F9: 67267 | G9: 122527 | H9: 62092 | I9: 78886 | J9: 23547 | K9: 1024 | L9: 19270 | M9: 28257 | N9: 8927 | O9: 2345 | P9: 32177 | Q9: 2080 | R9: 659
A10: 44842 | B10: 16622 | C10: 22985 | D10: 288054 | E10: 279694 | F10: 67268 | G10: 122549 | H10: 62092 | I10: 78895 | J10: 23553 | K10: 1024 | L10: 19276 | M10: 28258 | N10: 8928 | O10: 2346 | P10: 32178 | Q10: 2083 | R10: 660
A11: 44843 | B11: 16779 | C11: 23207 | D11: 288248 | E11: 279769 | F11: 67268 | G11: 122574 | H11: 62092 | I11: 78920 | J11: 23559 | K11: 1024 | L11: 19281 | M11: 28263 | N11: 8930 | O11: 2347 | P11: 32193 | Q11: 2089 | R11: 666
A12: 44844 | B12: 16913 | C12: 23399 | D12: 288402 | E12: 279835 | F12: 67268 | G12: 122592 | H12: 62092 | I12: 78946 | J12: 23564 | K12: 1024 | L12: 19286 | M12: 28268 | N12: 8933 | O12: 2348 | P12: 32206 | Q12: 2093 | R12: 669
A13: 44845 | B13: 17085 | C13: 23642 | D13: 288641 | E13: 279902 | F13: 67270 | G13: 122615 | H13: 62092 | I13: 78962 | J13: 23569 | K13: 1024 | L13: 19289 | M13: 28273 | N13: 8935 | O13: 2349 | P13: 32212 | Q13: 2096 | R13: 672
A14: 44846 | B14: 17225 | C14: 23844 | D14: 288811 | E14: 279972 | F14: 67283 | G14: 122637 | H14: 62092 | I14: 78981 | J14: 23575 | K14: 1024 | L14: 19294 | M14: 28278 | N14: 8936 | O14: 2351 | P14: 32222 | Q14: 2098 | R14: 677
... A17: 44849 | B17: 17573 | C17: 24321 | D17: 289112 | E17: 280175 | F17: 67288 | G17: 122709 | H17: 62092 | I17: 79033 | J17: 23593 | K17: 1024 | L17: 19310 | M17: 28290 | N17: 8940 | O17: 2355 | P17: 32241 | Q17: 2102 | R17: 688
A18: 44850
A19: 44851
A20: 44852
A21: 44853
A22: 44854
A23: 44855 | S23: .
A24: 44856
A25: 44857
A26: 44858
A27: 44859
A28: 44860
A29: 44861
A30: 44862
A31: 44863
A32: 44864
A33: 44865
A34: 44866

Sheet Water consumption
A2: Date | B2: RO production (Ro 1 : 4) | C2: Total Consumption M3 (Meter 1 : 2) | E2: Water Bunglow | G2: Beach bunglow | I2: Main Pool | K2: Main kitchen | M2: Reef club kitchen | O2: Reef club pool | Q2: Bodu Huraa staff | S2: Kuda Huraa staff | U2: Laundry | W2: Second stage | Y2: Total
C3: M3 | D3: % of Total production | E3: M3 | F3: % | G3: M3 | H3: % | I3: M3 | J3: % | K3: M3 | L3: % | M3: M3 | N3: % | O3: M3 | P3: % | Q3: M3 | R3: % | S3: M3 | T3: % | U3: M3 | V3: % | W3: M3 | X3: % | Y3: M3 | Z3: %
A4: ='Water Reading'!A3 -> 44835 | B4: =TOTAL!I2 -> 326 | C4: =('Water Reading'!B4-'Water Reading'!B3)+('Water Reading'!C4-'Water Reading'!C3) -> 337 | D4: =C4/B4 -> 1.0337423 | E4: ='Water Reading'!H4-'Water Reading'!H3 -> 0 | F4: =E4/C4 -> 0 | G4: =('Water Reading'!D4-'Water Reading'!D3)-('Water Reading'!R4-'Water Reading'!R3)-('Water Reading'!Q4-'Water Reading'!Q3) -> 180 | H4: =G4/C4 -> 0.53412463 | I4: ='Water Reading'!P4-'Water Reading'!P3 -> 0 | J4: =I4/C4 -> 0 | K4: =('Water Reading'!I4-'Water Reading'!I3)-('Water Reading'!P4-'Water Reading'!P3) -> 12 | L4: =K4/C4 -> 0.035608309 | M4: ='Water Reading'!R4-'Water Reading'!R3 -> 3 | N4: =M4/C4 -> 0.0089020772 | O4: ='Water Reading'!Q4-'Water Reading'!Q3 -> 0 | P4: =O4/C4 -> 0 | Q4: ='Water Reading'!F4-'Water Reading'!F3 -> 0 | R4: =Q4/C4 -> 0 | S4: ='Water Reading'!E4-'Water Reading'!E3 -> 77 | T4: =S4/C4 -> 0.22848665 | U4: ='Water Reading'!G4-'Water Reading'!G3 -> 18 | V4: =U4/C4 -> 0.053412463 | W4: ='Water Reading'!J4-'Water Reading'!J3 -> 5 | X4: =W4/C4 -> 0.014836795 | Y4: =E4+I4+K4+M4+O4+G4+Q4+S4+U4+W4 -> 295 | Z4: =Y4/B4 -> 0.90490798
A5: ='Water Reading'!A4 -> 44836 | B5: =TOTAL!I3 -> 288 | C5: =('Water Reading'!B5-'Water Reading'!B4)+('Water Reading'!C5-'Water Reading'!C4) -> 331 | D5: =C5/B5 -> 1.1493056 | E5: ='Water Reading'!H5-'Water Reading'!H4 -> 0 | F5: =E5/C5 -> 0 | G5: =('Water Reading'!D5-'Water Reading'!D4)-('Water Reading'!R5-'Water Reading'!R4)-('Water Reading'!Q5-'Water Reading'!Q4) -> 109 | H5: =G5/C5 -> 0.32930514 | I5: ='Water Reading'!P5-'Water Reading'!P4 -> 14 | J5: =I5/C5 -> 0.042296073 | K5: =('Water Reading'!I5-'Water Reading'!I4)-('Water Reading'!P5-'Water Reading'!P4) -> 15 | L5: =K5/C5 -> 0.045317221 | M5: ='Water Reading'!R5-'Water Reading'!R4 -> 5 | N5: =M5/C5 -> 0.01510574 | O5: ='Water Reading'!Q5-'Water Reading'!Q4 -> 7 | P5: =O5/C5 -> 0.021148036 | Q5: ='Water Reading'!F5-'Water Reading'!F4 -> 1 | R5: =Q5/C5 -> 0.003021148 | S5: ='Water Reading'!E5-'Water Reading'!E4 -> 74 | T5: =S5/C5 -> 0.22356495 | U5: ='Water Reading'!G5-'Water Reading'!G4 -> 28 | V5: =U5/C5 -> 0.084592145 | W5: ='Water Reading'!J5-'Water Reading'!J4 -> 6 | X5: =W5/C5 -> 0.018126888 | Y5: =E5+I5+K5+M5+O5+G5+Q5+S5+U5+W5 -> 259 | Z5: =Y5/B5 -> 0.89930556
A6: ='Water Reading'!A5 -> 44837 | B6: =TOTAL!I4 -> 357 | C6: =('Water Reading'!B6-'Water Reading'!B5)+('Water Reading'!C6-'Water Reading'!C5) -> 404 | D6: =C6/B6 -> 1.1316527 | E6: ='Water Reading'!H6-'Water Reading'!H5 -> 0 | F6: =E6/C6 -> 0 | G6: =('Water Reading'!D6-'Water Reading'!D5)-('Water Reading'!R6-'Water Reading'!R5)-('Water Reading'!Q6-'Water Reading'!Q5) -> 255 | H6: =G6/C6 -> 0.63118812 | I6: ='Water Reading'!P6-'Water Reading'!P5 -> 0 | J6: =I6/C6 -> 0 | K6: =('Water Reading'!I6-'Water Reading'!I5)-('Water Reading'!P6-'Water Reading'!P5) -> 9 | L6: =K6/C6 -> 0.022277228 | M6: ='Water Reading'!R6-'Water Reading'!R5 -> 2 | N6: =M6/C6 -> 0.004950495 | O6: ='Water Reading'!Q6-'Water Reading'!Q5 -> 5 | P6: =O6/C6 -> 0.012376238 | Q6: ='Water Reading'!F6-'Water Reading'!F5 -> 0 | R6: =Q6/C6 -> 0 | S6: ='Water Reading'!E6-'Water Reading'!E5 -> 66 | T6: =S6/C6 -> 0.16336634 | U6: ='Water Reading'!G6-'Water Reading'!G5 -> 18 | V6: =U6/C6 -> 0.044554455 | W6: ='Water Reading'!J6-'Water Reading'!J5 -> 4 | X6: =W6/C6 -> 0.0099009901 | Y6: =E6+I6+K6+M6+O6+G6+Q6+S6+U6+W6 -> 359 | Z6: =Y6/B6 -> 1.0056022
A7: ='Water Reading'!A6 -> 44838 | B7: =TOTAL!I5 -> 341 | C7: =('Water Reading'!B7-'Water Reading'!B6)+('Water Reading'!C7-'Water Reading'!C6) -> 288 | D7: =C7/B7 -> 0.84457478 | E7: ='Water Reading'!H7-'Water Reading'!H6 -> 0 | F7: =E7/C7 -> 0 | G7: =('Water Reading'!D7-'Water Reading'!D6)-('Water Reading'!R7-'Water Reading'!R6)-('Water Reading'!Q7-'Water Reading'!Q6) -> 146 | H7: =G7/C7 -> 0.50694444 | I7: ='Water Reading'!P7-'Water Reading'!P6 -> 16 | J7: =I7/C7 -> 0.055555556 | K7: =('Water Reading'!I7-'Water Reading'!I6)-('Water Reading'!P7-'Water Reading'!P6) -> 7 | L7: =K7/C7 -> 0.024305556 | M7: ='Water Reading'!R7-'Water Reading'!R6 -> 2 | N7: =M7/C7 -> 0.0069444444 | O7: ='Water Reading'!Q7-'Water Reading'!Q6 -> 2 | P7: =O7/C7 -> 0.0069444444 | Q7: ='Water Reading'!F7-'Water Reading'!F6 -> 1 | R7: =Q7/C7 -> 0.0034722222 | S7: ='Water Reading'!E7-'Water Reading'!E6 -> 64 | T7: =S7/C7 -> 0.22222222 | U7: ='Water Reading'!G7-'Water Reading'!G6 -> 16 | V7: =U7/C7 -> 0.055555556 | W7: ='Water Reading'!J7-'Water Reading'!J6 -> 6 | X7: =W7/C7 -> 0.020833333 | Y7: =E7+I7+K7+M7+O7+G7+Q7+S7+U7+W7 -> 260 | Z7: =Y7/B7 -> 0.76246334
A8: ='Water Reading'!A7 -> 44839 | B8: =TOTAL!I6 -> 283 | C8: =('Water Reading'!B8-'Water Reading'!B7)+('Water Reading'!C8-'Water Reading'!C7) -> 315 | D8: =C8/B8 -> 1.1130742 | E8: ='Water Reading'!H8-'Water Reading'!H7 -> 0 | F8: =E8/C8 -> 0 | G8: =('Water Reading'!D8-'Water Reading'!D7)-('Water Reading'!R8-'Water Reading'!R7)-('Water Reading'!Q8-'Water Reading'!Q7) -> 143 | H8: =G8/C8 -> 0.45396825 | I8: ='Water Reading'!P8-'Water Reading'!P7 -> 0 | J8: =I8/C8 -> 0 | K8: =('Water Reading'!I8-'Water Reading'!I7)-('Water Reading'!P8-'Water Reading'!P7) -> 19 | L8: =K8/C8 -> 0.06031746 | M8: ='Water Reading'!R8-'Water Reading'!R7 -> 5 | N8: =M8/C8 -> 0.015873016 | O8: ='Water Reading'!Q8-'Water Reading'!Q7 -> 7 | P8: =O8/C8 -> 0.022222222 | Q8: ='Water Reading'!F8-'Water Reading'!F7 -> 1 | R8: =Q8/C8 -> 0.0031746032 | S8: ='Water Reading'!E8-'Water Reading'!E7 -> 72 | T8: =S8/C8 -> 0.22857143 | U8: ='Water Reading'!G8-'Water Reading'!G7 -> 21 | V8: =U8/C8 -> 0.066666667 | W8: ='Water Reading'!J8-'Water Reading'!J7 -> 6 | X8: =W8/C8 -> 0.019047619 | Y8: =E8+I8+K8+M8+O8+G8+Q8+S8+U8+W8 -> 274 | Z8: =Y8/B8 -> 0.96819788
