Workbook

Sheet TOTAL
A1: Site Name | B1: Day | C1: Month | D1: Year | E1: Total Electricity Kwh | F1: Electricity Tariff ($/Kwh) | G1: Natual Gas (m3) | H1: Natural Gas $/m3 | I1: Water Utility Supply (m3) m3 | J1: Water Utility Supply (m3) $/m3 | K1: Room Nights | L1: Total Guests
A2: London at Park Lane | B2: 1 | C2: 10 | D2: 2022 | E2: =Submetering!E2+Submetering!F2+Submetering!G2 -> 3586 | F2: =((Submetering!E2+Submetering!F2)*0.11+Submetering!G2*0.0302)/TOTAL!E2 -> 0.0302 | G2: =Submetering!AC2 -> 1492 | H2: 0.255129 | I2: =Submetering!Y2+Submetering!Z2 -> 0 | J2: 2.3196173 | K2: =Submetering!AE2 -> 149 | L2: =Submetering!AF2 -> 230
A3: London at Park Lane | B3: =B2+1 -> 2 | C3: 10 | D3: 2022 | E3: =Submetering!E3+Submetering!F3+Submetering!G3 -> 3298 | F3: =((Submetering!E3+Submetering!F3)*0.11+Submetering!G3*0.0302)/TOTAL!E3 -> 0.0302 | G3: =Submetering!AC3 -> 1340 | H3: 0.255129 | I3: =Submetering!Y3+Submetering!Z3 -> 0 | J3: 2.3196173 | K3: =Submetering!AE3 -> 158 | L3: =Submetering!AF3 -> 243
A4: London at Park Lane | B4: =B3+1 -> 3 | C4: 10 | D4: 2022 | E4: =Submetering!E4+Submetering!F4+Submetering!G4 -> 4148 | F4: =((Submetering!E4+Submetering!F4)*0.11+Submetering!G4*0.0302)/TOTAL!E4 -> 0.0302 | G4: =Submetering!AC4 -> 1773 | H4: 0.255129 | I4: =Submetering!Y4+Submetering!Z4 -> 0 | J4: 2.3196173 | K4: =Submetering!AE4 -> 165 | L4: =Submetering!AF4 -> 233
A5: London at Park Lane | B5: =B4+1 -> 4 | C5: 10 | D5: 2022 | E5: =Submetering!E5+Submetering!F5+Submetering!G5 -> 4005 | F5: =((Submetering!E5+Submetering!F5)*0.11+Submetering!G5*0.0302)/TOTAL!E5 -> 0.0302 | G5: =Submetering!AC5 -> 1667 | H5: 0.255129 | I5: =Submetering!Y5+Submetering!Z5 -> 0 | J5: 2.3196173 | K5: =Submetering!AE5 -> 180 | L5: =Submetering!AF5 -> 254
A6: London at Park Lane | B6: =B5+1 -> 5 | C6: 10 | D6: 2022 | E6: =Submetering!E6+Submetering!F6+Submetering!G6 -> 3646 | F6: =((Submetering!E6+Submetering!F6)*0.11+Submetering!G6*0.0302)/TOTAL!E6 -> 0.0302 | G6: =Submetering!AC6 -> 1654 | H6: 0.255129 | I6: =Submetering!Y6+Submetering!Z6 -> 0 | J6: 2.3196173 | K6: =Submetering!AE6 -> 156 | L6: =Submetering!AF6 -> 226
A7: London at Park Lane | B7: =B6+1 -> 6 | C7: 10 | D7: 2022 | E7: =Submetering!E7+Submetering!F7+Submetering!G7 -> 3720 | F7: =((Submetering!E7+Submetering!F7)*0.11+Submetering!G7*0.0302)/TOTAL!E7 -> 0.0302 | G7: =Submetering!AC7 -> 1274 | H7: 0.255129 | I7: =Submetering!Y7+Submetering!Z7 -> 0 | J7: 2.3196173 | K7: =Submetering!AE7 -> 157 | L7: =Submetering!AF7 -> 241
A8: London at Park Lane | B8: =B7+1 -> 7 | C8: 10 | D8: 2022 | E8: =Submetering!E8+Submetering!F8+Submetering!G8 -> 3809 | F8: =((Submetering!E8+Submetering!F8)*0.11+Submetering!G8*0.0302)/TOTAL!E8 -> 0.0302 | G8: =Submetering!AC8 -> 2041 | H8: 0.255129 | I8: =Submetering!Y8+Submetering!Z8 -> 0 | J8: 2.3196173 | K8: =Submetering!AE8 -> 162 | L8: =Submetering!AF8 -> 262
A9: London at Park Lane | B9: =B8+1 -> 8 | C9: 10 | D9: 2022 | E9: =Submetering!E9+Submetering!F9+Submetering!G9 -> 3533 | F9: =((Submetering!E9+Submetering!F9)*0.11+Submetering!G9*0.0302)/TOTAL!E9 -> 0.0302 | G9: =Submetering!AC9 -> 1720 | H9: 0.255129 | I9: =Submetering!Y9+Submetering!Z9 -> 0 | J9: 2.3196173 | K9: =Submetering!AE9 -> 179 | L9: =Submetering!AF9 -> 307
A10: London at Park Lane | B10: =B9+1 -> 9 | C10: 10 | D10: 2022 | E10: =Submetering!E10+Submetering!F10+Submetering!G10 -> 3747 | F10: =((Submetering!E10+Submetering!F10)*0.11+Submetering!G10*0.0302)/TOTAL!E10 -> 0.0302 | G10: =Submetering!AC10 -> 1606 | H10: 0.255129 | I10: =Submetering!Y10+Submetering!Z10 -> 0 | J10: 2.3196173 | K10: =Submetering!AE10 -> 169 | L10: =Submetering!AF10 -> 294
A11: London at Park Lane | B11: =B10+1 -> 10 | C11: 10 | D11: 2022 | E11: =Submetering!E11+Submetering!F11+Submetering!G11 -> 3859 | F11: =((Submetering!E11+Submetering!F11)*0.11+Submetering!G11*0.0302)/TOTAL!E11 -> 0.0302 | G11: =Submetering!AC11 -> 1665 | H11: 0.255129 | I11: =Submetering!Y11+Submetering!Z11 -> 0 | J11: 2.3196173 | K11: =Submetering!AE11 -> 157 | L11: =Submetering!AF11 -> 252
A12: London at Park Lane | B12: =B11+1 -> 11 | C12: 10 | D12: 2022 | E12: =Submetering!E12+Submetering!F12+Submetering!G12 -> 4096 | F12: =((Submetering!E12+Submetering!F12)*0.11+Submetering!G12*0.0302)/TOTAL!E12 -> 0.0302 | G12: =Submetering!AC12 -> 1928 | H12: 0.255129 | I12: =Submetering!Y12+Submetering!Z12 -> 0 | J12: 2.3196173 | K12: =Submetering!AE12 -> 145 | L12: =Submetering!AF12 -> 230
A13: London at Park Lane | B13: =B12+1 -> 12 | C13: 10 | D13: 2022 | E13: =Submetering!E13+Submetering!F13+Submetering!G13 -> 7551 | F13: =((Submetering!E13+Submetering!F13)*0.11+Submetering!G13*0.0302)/TOTAL!E13 -> 0.0302 | G13: =Submetering!AC13 -> 3378 | H13: 0.255129 | I13: =Submetering!Y13+Submetering!Z13 -> 0 | J13: 2.3196173 | K13: =Submetering!AE13 -> 161 | L13: =Submetering!AF13 -> 246
A14: London at Park Lane | B14: =B13+1 -> 13 | C14: 10 | D14: 2022 | E14: =Submetering!E14+Submetering!F14+Submetering!G14 -> 3548 | F14: =((Submetering!E14+Submetering!F14)*0.11+Submetering!G14*0.0302)/TOTAL!E14 -> 0.0302 | G14: =Submetering!AC14 -> 1624 | H14: 0.255129 | I14: =Submetering!Y14+Submetering!Z14 -> 0 | J14: 2.3196173 | K14: =Submetering!AE14 -> 156 | L14: =Submetering!AF14 -> 229
... A32: London at Park Lane | B32: =B31+1 -> 31 | C32: 10 | D32: 2022 | E32: =Submetering!E32+Submetering!F32+Submetering!G32 -> 0 | F32: =((Submetering!E32+Submetering!F32)*0.11+Submetering!G32*0.0302)/TOTAL!E32 -> #DIV/0! | G32: =Submetering!AC32 -> 0 | H32: 0.255129 | I32: =Submetering!Y32+Submetering!Z32 -> 0 | J32: 2.3196173 | K32: =Submetering!AE32 -> 0 | L32: =Submetering!AF32 -> 0

Sheet Submetering
A1: Site Name | B1: Day | C1: Month | D1: Year | E1: LV Panel 1 KWh | F1: LV Panel 2 KWh | G1: CHP KWh | H1: MCC9 KWh | I1: GF Panel KWh | J1: Kitchen Switch. KWh | K1: Kitchen Panel KWh | L1: MCC3 (AHU) KWh | M1: MCC8 KWh | N1: 1st Floor Plan (KWh) | O1: MCC6(1st floor AHU) KWh | P1: Chiller 1 KWh | Q1: Chiller 2 KWh | R1: MCC 10 (Mechanical Services) KWh | S1: MCC2 CHW KWh | T1: MCC7 (Kitchen) KWh | U1: MCC 5 (Mechanical services) KWh | V1: MCC 4 (Water Services) KWh | W1: MCC1 (KWh) | X1: Laundry db KWh | Y1: City Water 1 m3 | Z1: City Water 2 m3 | AA1: Laundry CW m3 | AB1: Laundry HW m3 | AC1: Natural Gas m3 | AD1: CHP Natural Gas m3 | AE1: Room Nights | AF1: Total Guests
A2: London at Park Lane | B2: 1 | C2: 10 | D2: 2022 | E2: =IF(('FSLPL Daily '!C4-'FSLPL Daily '!C3<0), "0",'FSLPL Daily '!C4-'FSLPL Daily '!C3) -> 0 | F2: =IF(('FSLPL Daily '!E4-'FSLPL Daily '!E3<0), "0",'FSLPL Daily '!E4-'FSLPL Daily '!E3) -> 0 | G2: =IF(('FSLPL Daily '!G4-'FSLPL Daily '!G3<0), "0",'FSLPL Daily '!G4-'FSLPL Daily '!G3) -> 3586 | H2: =IF(('FSLPL Daily '!I4-'FSLPL Daily '!I3<0), "0",'FSLPL Daily '!I4-'FSLPL Daily '!I3) -> 0 | I2: =IF(('FSLPL Daily '!K4-'FSLPL Daily '!K3<0), "0",'FSLPL Daily '!K4-'FSLPL Daily '!K3) -> 0 | J2: =IF(('FSLPL Daily '!M4-'FSLPL Daily '!M3<0), "0",'FSLPL Daily '!M4-'FSLPL Daily '!M3) -> 0 | K2: =IF(('FSLPL Daily '!O4-'FSLPL Daily '!O3<0), "0",'FSLPL Daily '!O4-'FSLPL Daily '!O3) -> 0 | L2: =IF(('FSLPL Daily '!Q4-'FSLPL Daily '!Q3<0), "0",'FSLPL Daily '!Q4-'FSLPL Daily '!Q3) -> 0 | M2: =IF(('FSLPL Daily '!S4-'FSLPL Daily '!S3<0), "0",'FSLPL Daily '!S4-'FSLPL Daily '!S3) -> 0 | N2: =IF(('FSLPL Daily '!U4-'FSLPL Daily '!U3<0), "0",'FSLPL Daily '!U4-'FSLPL Daily '!U3) -> 0 | O2: =IF(('FSLPL Daily '!W4-'FSLPL Daily '!W3<0), "0",'FSLPL Daily '!W4-'FSLPL Daily '!W3) -> 0 | P2: =IF(('FSLPL Daily '!Y4-'FSLPL Daily '!Y3<0), "0",'FSLPL Daily '!Y4-'FSLPL Daily '!Y3) -> 0 | Q2: =IF(('FSLPL Daily '!AA4-'FSLPL Daily '!AA3<0), "0",'FSLPL Daily '!AA4-'FSLPL Daily '!AA3) -> 0 | R2: =IF(('FSLPL Daily '!AC4-'FSLPL Daily '!AC3<0), "0",'FSLPL Daily '!AC4-'FSLPL Daily '!AC3) -> 0 | S2: =IF(('FSLPL Daily '!AE4-'FSLPL Daily '!AE3<0), "0",'FSLPL Daily '!AE4-'FSLPL Daily '!AE3) -> 0 | T2: =IF(('FSLPL Daily '!AG4-'FSLPL Daily '!AG3<0), "0",'FSLPL Daily '!AG4-'FSLPL Daily '!AG3) -> 0 | U2: =IF(('FSLPL Daily '!AI4-'FSLPL Daily '!AI3<0), "0",'FSLPL Daily '!AI4-'FSLPL Daily '!AI3) -> 0 | V2: =IF(('FSLPL Daily '!AK4-'FSLPL Daily '!AK3<0), "0",'FSLPL Daily '!AK4-'FSLPL Daily '!AK3) -> 0 | W2: =IF(('FSLPL Daily '!AM4-'FSLPL Daily '!AM3<0), "0",'FSLPL Daily '!AM4-'FSLPL Daily '!AM3) -> 0 | X2: =IF(('FSLPL Daily '!AO4-'FSLPL Daily '!AO3<0), "0",'FSLPL Daily '!AO4-'FSLPL Daily '!AO3) -> 0 | Y2: ='FSLPL Daily '!AS4 -> 0 | Z2: ='FSLPL Daily '!AU4 -> 0 | AA2: =IF(('FSLPL Daily '!AV4-'FSLPL Daily '!AV3<0), "0",'FSLPL Daily '!AV4-'FSLPL Daily '!AV3) -> #VALUE! | AB2: =IF(('FSLPL Daily '!AX4-'FSLPL Daily '!AX3<0), "0",'FSLPL Daily '!AX4-'FSLPL Daily '!AX3) -> #VALUE! | AC2: =IF(('FSLPL Daily '!AZ4-'FSLPL Daily '!AZ3<0), "0",'FSLPL Daily '!AZ4-'FSLPL Daily '!AZ3) -> 1492 | AD2: =IF(('FSLPL Daily '!BB4-'FSLPL Daily '!BB3<0), "0",'FSLPL Daily '!BB4-'FSLPL Daily '!BB3) -> 1147 | AE2: ='FSLPL Daily '!BD4 -> 149 | AF2: ='FSLPL Daily '!BE4 -> 230
A3: London at Park Lane | B3: =B2+1 -> 2 | C3: 10 | D3: 2022 | E3: =IF(('FSLPL Daily '!C5-'FSLPL Daily '!C4<0), "0",'FSLPL Daily '!C5-'FSLPL Daily '!C4) -> 0 | F3: =IF(('FSLPL Daily '!E5-'FSLPL Daily '!E4<0), "0",'FSLPL Daily '!E5-'FSLPL Daily '!E4) -> 0 | G3: =IF(('FSLPL Daily '!G5-'FSLPL Daily '!G4<0), "0",'FSLPL Daily '!G5-'FSLPL Daily '!G4) -> 3298 | H3: =IF(('FSLPL Daily '!I5-'FSLPL Daily '!I4<0), "0",'FSLPL Daily '!I5-'FSLPL Daily '!I4) -> 0 | I3: =IF(('FSLPL Daily '!K5-'FSLPL Daily '!K4<0), "0",'FSLPL Daily '!K5-'FSLPL Daily '!K4) -> 0 | J3: =IF(('FSLPL Daily '!M5-'FSLPL Daily '!M4<0), "0",'FSLPL Daily '!M5-'FSLPL Daily '!M4) -> 0 | K3: =IF(('FSLPL Daily '!O5-'FSLPL Daily '!O4<0), "0",'FSLPL Daily '!O5-'FSLPL Daily '!O4) -> 0 | L3: =IF(('FSLPL Daily '!Q5-'FSLPL Daily '!Q4<0), "0",'FSLPL Daily '!Q5-'FSLPL Daily '!Q4) -> 0 | M3: =IF(('FSLPL Daily '!S5-'FSLPL Daily '!S4<0), "0",'FSLPL Daily '!S5-'FSLPL Daily '!S4) -> 0 | N3: =IF(('FSLPL Daily '!U5-'FSLPL Daily '!U4<0), "0",'FSLPL Daily '!U5-'FSLPL Daily '!U4) -> 0 | O3: =IF(('FSLPL Daily '!W5-'FSLPL Daily '!W4<0), "0",'FSLPL Daily '!W5-'FSLPL Daily '!W4) -> 0 | P3: =IF(('FSLPL Daily '!Y5-'FSLPL Daily '!Y4<0), "0",'FSLPL Daily '!Y5-'FSLPL Daily '!Y4) -> 0 | Q3: =IF(('FSLPL Daily '!AA5-'FSLPL Daily '!AA4<0), "0",'FSLPL Daily '!AA5-'FSLPL Daily '!AA4) -> 0 | R3: =IF(('FSLPL Daily '!AC5-'FSLPL Daily '!AC4<0), "0",'FSLPL Daily '!AC5-'FSLPL Daily '!AC4) -> 0 | S3: =IF(('FSLPL Daily '!AE5-'FSLPL Daily '!AE4<0), "0",'FSLPL Daily '!AE5-'FSLPL Daily '!AE4) -> 0 | T3: =IF(('FSLPL Daily '!AG5-'FSLPL Daily '!AG4<0), "0",'FSLPL Daily '!AG5-'FSLPL Daily '!AG4) -> 0 | U3: =IF(('FSLPL Daily '!AI5-'FSLPL Daily '!AI4<0), "0",'FSLPL Daily '!AI5-'FSLPL Daily '!AI4) -> 0 | V3: =IF(('FSLPL Daily '!AK5-'FSLPL Daily '!AK4<0), "0",'FSLPL Daily '!AK5-'FSLPL Daily '!AK4) -> 0 | W3: =IF(('FSLPL Daily '!AM5-'FSLPL Daily '!AM4<0), "0",'FSLPL Daily '!AM5-'FSLPL Daily '!AM4) -> 0 | X3: =IF(('FSLPL Daily '!AO5-'FSLPL Daily '!AO4<0), "0",'FSLPL Daily '!AO5-'FSLPL Daily '!AO4) -> 0 | Y3: ='FSLPL Daily '!AS5 -> 0 | Z3: ='FSLPL Daily '!AU5 -> 0 | AA3: =IF(('FSLPL Daily '!AV5-'FSLPL Daily '!AV4<0), "0",'FSLPL Daily '!AV5-'FSLPL Daily '!AV4) -> 14 | AB3: =IF(('FSLPL Daily '!AX5-'FSLPL Daily '!AX4<0), "0",'FSLPL Daily '!AX5-'FSLPL Daily '!AX4) -> 2 | AC3: =IF(('FSLPL Daily '!AZ5-'FSLPL Daily '!AZ4<0), "0",'FSLPL Daily '!AZ5-'FSLPL Daily '!AZ4) -> 1340 | AD3: =IF(('FSLPL Daily '!BB5-'FSLPL Daily '!BB4<0), "0",'FSLPL Daily '!BB5-'FSLPL Daily '!BB4) -> 1051 | AE3: ='FSLPL Daily '!BD5 -> 158 | AF3: ='FSLPL Daily '!BE5 -> 243
A4: London at Park Lane | B4: =B3+1 -> 3 | C4: 10 | D4: 2022 | E4: =IF(('FSLPL Daily '!C6-'FSLPL Daily '!C5<0), "0",'FSLPL Daily '!C6-'FSLPL Daily '!C5) -> 0 | F4: =IF(('FSLPL Daily '!E6-'FSLPL Daily '!E5<0), "0",'FSLPL Daily '!E6-'FSLPL Daily '!E5) -> 0 | G4: =IF(('FSLPL Daily '!G6-'FSLPL Daily '!G5<0), "0",'FSLPL Daily '!G6-'FSLPL Daily '!G5) -> 4148 | H4: =IF(('FSLPL Daily '!I6-'FSLPL Daily '!I5<0), "0",'FSLPL Daily '!I6-'FSLPL Daily '!I5) -> 0 | I4: =IF(('FSLPL Daily '!K6-'FSLPL Daily '!K5<0), "0",'FSLPL Daily '!K6-'FSLPL Daily '!K5) -> 0 | J4: =IF(('FSLPL Daily '!M6-'FSLPL Daily '!M5<0), "0",'FSLPL Daily '!M6-'FSLPL Daily '!M5) -> 0 | K4: =IF(('FSLPL Daily '!O6-'FSLPL Daily '!O5<0), "0",'FSLPL Daily '!O6-'FSLPL Daily '!O5) -> 0 | L4: =IF(('FSLPL Daily '!Q6-'FSLPL Daily '!Q5<0), "0",'FSLPL Daily '!Q6-'FSLPL Daily '!Q5) -> 0 | M4: =IF(('FSLPL Daily '!S6-'FSLPL Daily '!S5<0), "0",'FSLPL Daily '!S6-'FSLPL Daily '!S5) -> 0 | N4: =IF(('FSLPL Daily '!U6-'FSLPL Daily '!U5<0), "0",'FSLPL Daily '!U6-'FSLPL Daily '!U5) -> 0 | O4: =IF(('FSLPL Daily '!W6-'FSLPL Daily '!W5<0), "0",'FSLPL Daily '!W6-'FSLPL Daily '!W5) -> 0 | P4: =IF(('FSLPL Daily '!Y6-'FSLPL Daily '!Y5<0), "0",'FSLPL Daily '!Y6-'FSLPL Daily '!Y5) -> 0 | Q4: =IF(('FSLPL Daily '!AA6-'FSLPL Daily '!AA5<0), "0",'FSLPL Daily '!AA6-'FSLPL Daily '!AA5) -> 0 | R4: =IF(('FSLPL Daily '!AC6-'FSLPL Daily '!AC5<0), "0",'FSLPL Daily '!AC6-'FSLPL Daily '!AC5) -> 0 | S4: =IF(('FSLPL Daily '!AE6-'FSLPL Daily '!AE5<0), "0",'FSLPL Daily '!AE6-'FSLPL Daily '!AE5) -> 0 | T4: =IF(('FSLPL Daily '!AG6-'FSLPL Daily '!AG5<0), "0",'FSLPL Daily '!AG6-'FSLPL Daily '!AG5) -> 0 | U4: =IF(('FSLPL Daily '!AI6-'FSLPL Daily '!AI5<0), "0",'FSLPL Daily '!AI6-'FSLPL Daily '!AI5) -> 0 | V4: =IF(('FSLPL Daily '!AK6-'FSLPL Daily '!AK5<0), "0",'FSLPL Daily '!AK6-'FSLPL Daily '!AK5) -> 0 | W4: =IF(('FSLPL Daily '!AM6-'FSLPL Daily '!AM5<0), "0",'FSLPL Daily '!AM6-'FSLPL Daily '!AM5) -> 0 | X4: =IF(('FSLPL Daily '!AO6-'FSLPL Daily '!AO5<0), "0",'FSLPL Daily '!AO6-'FSLPL Daily '!AO5) -> 0 | Y4: ='FSLPL Daily '!AS6 -> 0 | Z4: ='FSLPL Daily '!AU6 -> 0 | AA4: =IF(('FSLPL Daily '!AV6-'FSLPL Daily '!AV5<0), "0",'FSLPL Daily '!AV6-'FSLPL Daily '!AV5) -> 21 | AB4: =IF(('FSLPL Daily '!AX6-'FSLPL Daily '!AX5<0), "0",'FSLPL Daily '!AX6-'FSLPL Daily '!AX5) -> 3 | AC4: =IF(('FSLPL Daily '!AZ6-'FSLPL Daily '!AZ5<0), "0",'FSLPL Daily '!AZ6-'FSLPL Daily '!AZ5) -> 1773 | AD4: =IF(('FSLPL Daily '!BB6-'FSLPL Daily '!BB5<0), "0",'FSLPL Daily '!BB6-'FSLPL Daily '!BB5) -> 1311 | AE4: ='FSLPL Daily '!BD6 -> 165 | AF4: ='FSLPL Daily '!BE6 -> 233
A5: London at Park Lane | B5: =B4+1 -> 4 | C5: 10 | D5: 2022 | E5: =IF(('FSLPL Daily '!C7-'FSLPL Daily '!C6<0), "0",'FSLPL Daily '!C7-'FSLPL Daily '!C6) -> 0 | F5: =IF(('FSLPL Daily '!E7-'FSLPL Daily '!E6<0), "0",'FSLPL Daily '!E7-'FSLPL Daily '!E6) -> 0 | G5: =IF(('FSLPL Daily '!G7-'FSLPL Daily '!G6<0), "0",'FSLPL Daily '!G7-'FSLPL Daily '!G6) -> 4005 | H5: =IF(('FSLPL Daily '!I7-'FSLPL Daily '!I6<0), "0",'FSLPL Daily '!I7-'FSLPL Daily '!I6) -> 0 | I5: =IF(('FSLPL Daily '!K7-'FSLPL Daily '!K6<0), "0",'FSLPL Daily '!K7-'FSLPL Daily '!K6) -> 0 | J5: =IF(('FSLPL Daily '!M7-'FSLPL Daily '!M6<0), "0",'FSLPL Daily '!M7-'FSLPL Daily '!M6) -> 0 | K5: =IF(('FSLPL Daily '!O7-'FSLPL Daily '!O6<0), "0",'FSLPL Daily '!O7-'FSLPL Daily '!O6) -> 0 | L5: =IF(('FSLPL Daily '!Q7-'FSLPL Daily '!Q6<0), "0",'FSLPL Daily '!Q7-'FSLPL Daily '!Q6) -> 0 | M5: =IF(('FSLPL Daily '!S7-'FSLPL Daily '!S6<0), "0",'FSLPL Daily '!S7-'FSLPL Daily '!S6) -> 0 | N5: =IF(('FSLPL Daily '!U7-'FSLPL Daily '!U6<0), "0",'FSLPL Daily '!U7-'FSLPL Daily '!U6) -> 0 | O5: =IF(('FSLPL Daily '!W7-'FSLPL Daily '!W6<0), "0",'FSLPL Daily '!W7-'FSLPL Daily '!W6) -> 0 | P5: =IF(('FSLPL Daily '!Y7-'FSLPL Daily '!Y6<0), "0",'FSLPL Daily '!Y7-'FSLPL Daily '!Y6) -> 0 | Q5: =IF(('FSLPL Daily '!AA7-'FSLPL Daily '!AA6<0), "0",'FSLPL Daily '!AA7-'FSLPL Daily '!AA6) -> 0 | R5: =IF(('FSLPL Daily '!AC7-'FSLPL Daily '!AC6<0), "0",'FSLPL Daily '!AC7-'FSLPL Daily '!AC6) -> 0 | S5: =IF(('FSLPL Daily '!AE7-'FSLPL Daily '!AE6<0), "0",'FSLPL Daily '!AE7-'FSLPL Daily '!AE6) -> 0 | T5: =IF(('FSLPL Daily '!AG7-'FSLPL Daily '!AG6<0), "0",'FSLPL Daily '!AG7-'FSLPL Daily '!AG6) -> 0 | U5: =IF(('FSLPL Daily '!AI7-'FSLPL Daily '!AI6<0), "0",'FSLPL Daily '!AI7-'FSLPL Daily '!AI6) -> 0 | V5: =IF(('FSLPL Daily '!AK7-'FSLPL Daily '!AK6<0), "0",'FSLPL Daily '!AK7-'FSLPL Daily '!AK6) -> 0 | W5: =IF(('FSLPL Daily '!AM7-'FSLPL Daily '!AM6<0), "0",'FSLPL Daily '!AM7-'FSLPL Daily '!AM6) -> 0 | X5: =IF(('FSLPL Daily '!AO7-'FSLPL Daily '!AO6<0), "0",'FSLPL Daily '!AO7-'FSLPL Daily '!AO6) -> 0 | Y5: ='FSLPL Daily '!AS7 -> 0 | Z5: ='FSLPL Daily '!AU7 -> 0 | AA5: =IF(('FSLPL Daily '!AV7-'FSLPL Daily '!AV6<0), "0",'FSLPL Daily '!AV7-'FSLPL Daily '!AV6) -> 18 | AB5: =IF(('FSLPL Daily '!AX7-'FSLPL Daily '!AX6<0), "0",'FSLPL Daily '!AX7-'FSLPL Daily '!AX6) -> 2 | AC5: =IF(('FSLPL Daily '!AZ7-'FSLPL Daily '!AZ6<0), "0",'FSLPL Daily '!AZ7-'FSLPL Daily '!AZ6) -> 1667 | AD5: =IF(('FSLPL Daily '!BB7-'FSLPL Daily '!BB6<0), "0",'FSLPL Daily '!BB7-'FSLPL Daily '!BB6) -> 1293 | AE5: ='FSLPL Daily '!BD7 -> 180 | AF5: ='FSLPL Daily '!BE7 -> 254
A6: London at Park Lane | B6: =B5+1 -> 5 | C6: 10 | D6: 2022 | E6: =IF(('FSLPL Daily '!C8-'FSLPL Daily '!C7<0), "0",'FSLPL Daily '!C8-'FSLPL Daily '!C7) -> 0 | F6: =IF(('FSLPL Daily '!E8-'FSLPL Daily '!E7<0), "0",'FSLPL Daily '!E8-'FSLPL Daily '!E7) -> 0 | G6: =IF(('FSLPL Daily '!G8-'FSLPL Daily '!G7<0), "0",'FSLPL Daily '!G8-'FSLPL Daily '!G7) -> 3646 | H6: =IF(('FSLPL Daily '!I8-'FSLPL Daily '!I7<0), "0",'FSLPL Daily '!I8-'FSLPL Daily '!I7) -> 0 | I6: =IF(('FSLPL Daily '!K8-'FSLPL Daily '!K7<0), "0",'FSLPL Daily '!K8-'FSLPL Daily '!K7) -> 0 | J6: =IF(('FSLPL Daily '!M8-'FSLPL Daily '!M7<0), "0",'FSLPL Daily '!M8-'FSLPL Daily '!M7) -> 0 | K6: =IF(('FSLPL Daily '!O8-'FSLPL Daily '!O7<0), "0",'FSLPL Daily '!O8-'FSLPL Daily '!O7) -> 0 | L6: =IF(('FSLPL Daily '!Q8-'FSLPL Daily '!Q7<0), "0",'FSLPL Daily '!Q8-'FSLPL Daily '!Q7) -> 0 | M6: =IF(('FSLPL Daily '!S8-'FSLPL Daily '!S7<0), "0",'FSLPL Daily '!S8-'FSLPL Daily '!S7) -> 0 | N6: =IF(('FSLPL Daily '!U8-'FSLPL Daily '!U7<0), "0",'FSLPL Daily '!U8-'FSLPL Daily '!U7) -> 0 | O6: =IF(('FSLPL Daily '!W8-'FSLPL Daily '!W7<0), "0",'FSLPL Daily '!W8-'FSLPL Daily '!W7) -> 0 | P6: =IF(('FSLPL Daily '!Y8-'FSLPL Daily '!Y7<0), "0",'FSLPL Daily '!Y8-'FSLPL Daily '!Y7) -> 0 | Q6: =IF(('FSLPL Daily '!AA8-'FSLPL Daily '!AA7<0), "0",'FSLPL Daily '!AA8-'FSLPL Daily '!AA7) -> 0 | R6: =IF(('FSLPL Daily '!AC8-'FSLPL Daily '!AC7<0), "0",'FSLPL Daily '!AC8-'FSLPL Daily '!AC7) -> 0 | S6: =IF(('FSLPL Daily '!AE8-'FSLPL Daily '!AE7<0), "0",'FSLPL Daily '!AE8-'FSLPL Daily '!AE7) -> 0 | T6: =IF(('FSLPL Daily '!AG8-'FSLPL Daily '!AG7<0), "0",'FSLPL Daily '!AG8-'FSLPL Daily '!AG7) -> 0 | U6: =IF(('FSLPL Daily '!AI8-'FSLPL Daily '!AI7<0), "0",'FSLPL Daily '!AI8-'FSLPL Daily '!AI7) -> 0 | V6: =IF(('FSLPL Daily '!AK8-'FSLPL Daily '!AK7<0), "0",'FSLPL Daily '!AK8-'FSLPL Daily '!AK7) -> 0 | W6: =IF(('FSLPL Daily '!AM8-'FSLPL Daily '!AM7<0), "0",'FSLPL Daily '!AM8-'FSLPL Daily '!AM7) -> 0 | X6: =IF(('FSLPL Daily '!AO8-'FSLPL Daily '!AO7<0), "0",'FSLPL Daily '!AO8-'FSLPL Daily '!AO7) -> 0 | Y6: ='FSLPL Daily '!AS8 -> 0 | Z6: ='FSLPL Daily '!AU8 -> 0 | AA6: =IF(('FSLPL Daily '!AV8-'FSLPL Daily '!AV7<0), "0",'FSLPL Daily '!AV8-'FSLPL Daily '!AV7) -> 17 | AB6: =IF(('FSLPL Daily '!AX8-'FSLPL Daily '!AX7<0), "0",'FSLPL Daily '!AX8-'FSLPL Daily '!AX7) -> 1 | AC6: =IF(('FSLPL Daily '!AZ8-'FSLPL Daily '!AZ7<0), "0",'FSLPL Daily '!AZ8-'FSLPL Daily '!AZ7) -> 1654 | AD6: =IF(('FSLPL Daily '!BB8-'FSLPL Daily '!BB7<0), "0",'FSLPL Daily '!BB8-'FSLPL Daily '!BB7) -> 1187 | AE6: ='FSLPL Daily '!BD8 -> 156 | AF6: ='FSLPL Daily '!BE8 -> 226
A7: London at Park Lane | B7: =B6+1 -> 6 | C7: 10 | D7: 2022 | E7: =IF(('FSLPL Daily '!C9-'FSLPL Daily '!C8<0), "0",'FSLPL Daily '!C9-'FSLPL Daily '!C8) -> 0 | F7: =IF(('FSLPL Daily '!E9-'FSLPL Daily '!E8<0), "0",'FSLPL Daily '!E9-'FSLPL Daily '!E8) -> 0 | G7: =IF(('FSLPL Daily '!G9-'FSLPL Daily '!G8<0), "0",'FSLPL Daily '!G9-'FSLPL Daily '!G8) -> 3720 | H7: =IF(('FSLPL Daily '!I9-'FSLPL Daily '!I8<0), "0",'FSLPL Daily '!I9-'FSLPL Daily '!I8) -> 0 | I7: =IF(('FSLPL Daily '!K9-'FSLPL Daily '!K8<0), "0",'FSLPL Daily '!K9-'FSLPL Daily '!K8) -> 0 | J7: =IF(('FSLPL Daily '!M9-'FSLPL Daily '!M8<0), "0",'FSLPL Daily '!M9-'FSLPL Daily '!M8) -> 0 | K7: =IF(('FSLPL Daily '!O9-'FSLPL Daily '!O8<0), "0",'FSLPL Daily '!O9-'FSLPL Daily '!O8) -> 0 | L7: =IF(('FSLPL Daily '!Q9-'FSLPL Daily '!Q8<0), "0",'FSLPL Daily '!Q9-'FSLPL Daily '!Q8) -> 0 | M7: =IF(('FSLPL Daily '!S9-'FSLPL Daily '!S8<0), "0",'FSLPL Daily '!S9-'FSLPL Daily '!S8) -> 0 | N7: =IF(('FSLPL Daily '!U9-'FSLPL Daily '!U8<0), "0",'FSLPL Daily '!U9-'FSLPL Daily '!U8) -> 0 | O7: =IF(('FSLPL Daily '!W9-'FSLPL Daily '!W8<0), "0",'FSLPL Daily '!W9-'FSLPL Daily '!W8) -> 0 | P7: =IF(('FSLPL Daily '!Y9-'FSLPL Daily '!Y8<0), "0",'FSLPL Daily '!Y9-'FSLPL Daily '!Y8) -> 0 | Q7: =IF(('FSLPL Daily '!AA9-'FSLPL Daily '!AA8<0), "0",'FSLPL Daily '!AA9-'FSLPL Daily '!AA8) -> 0 | R7: =IF(('FSLPL Daily '!AC9-'FSLPL Daily '!AC8<0), "0",'FSLPL Daily '!AC9-'FSLPL Daily '!AC8) -> 0 | S7: =IF(('FSLPL Daily '!AE9-'FSLPL Daily '!AE8<0), "0",'FSLPL Daily '!AE9-'FSLPL Daily '!AE8) -> 0 | T7: =IF(('FSLPL Daily '!AG9-'FSLPL Daily '!AG8<0), "0",'FSLPL Daily '!AG9-'FSLPL Daily '!AG8) -> 0 | U7: =IF(('FSLPL Daily '!AI9-'FSLPL Daily '!AI8<0), "0",'FSLPL Daily '!AI9-'FSLPL Daily '!AI8) -> 0 | V7: =IF(('FSLPL Daily '!AK9-'FSLPL Daily '!AK8<0), "0",'FSLPL Daily '!AK9-'FSLPL Daily '!AK8) -> 0 | W7: =IF(('FSLPL Daily '!AM9-'FSLPL Daily '!AM8<0), "0",'FSLPL Daily '!AM9-'FSLPL Daily '!AM8) -> 0 | X7: =IF(('FSLPL Daily '!AO9-'FSLPL Daily '!AO8<0), "0",'FSLPL Daily '!AO9-'FSLPL Daily '!AO8) -> 0 | Y7: ='FSLPL Daily '!AS9 -> 0 | Z7: ='FSLPL Daily '!AU9 -> 0 | AA7: =IF(('FSLPL Daily '!AV9-'FSLPL Daily '!AV8<0), "0",'FSLPL Daily '!AV9-'FSLPL Daily '!AV8) -> 14 | AB7: =IF(('FSLPL Daily '!AX9-'FSLPL Daily '!AX8<0), "0",'FSLPL Daily '!AX9-'FSLPL Daily '!AX8) -> 3 | AC7: =IF(('FSLPL Daily '!AZ9-'FSLPL Daily '!AZ8<0), "0",'FSLPL Daily '!AZ9-'FSLPL Daily '!AZ8) -> 1274 | AD7: =IF(('FSLPL Daily '!BB9-'FSLPL Daily '!BB8<0), "0",'FSLPL Daily '!BB9-'FSLPL Daily '!BB8) -> 1242 | AE7: ='FSLPL Daily '!BD9 -> 157 | AF7: ='FSLPL Daily '!BE9 -> 241
A8: London at Park Lane | B8: =B7+1 -> 7 | C8: 10 | D8: 2022 | E8: =IF(('FSLPL Daily '!C10-'FSLPL Daily '!C9<0), "0",'FSLPL Daily '!C10-'FSLPL Daily '!C9) -> 0 | F8: =IF(('FSLPL Daily '!E10-'FSLPL Daily '!E9<0), "0",'FSLPL Daily '!E10-'FSLPL Daily '!E9) -> 0 | G8: =IF(('FSLPL Daily '!G10-'FSLPL Daily '!G9<0), "0",'FSLPL Daily '!G10-'FSLPL Daily '!G9) -> 3809 | H8: =IF(('FSLPL Daily '!I10-'FSLPL Daily '!I9<0), "0",'FSLPL Daily '!I10-'FSLPL Daily '!I9) -> 0 | I8: =IF(('FSLPL Daily '!K10-'FSLPL Daily '!K9<0), "0",'FSLPL Daily '!K10-'FSLPL Daily '!K9) -> 0 | J8: =IF(('FSLPL Daily '!M10-'FSLPL Daily '!M9<0), "0",'FSLPL Daily '!M10-'FSLPL Daily '!M9) -> 0 | K8: =IF(('FSLPL Daily '!O10-'FSLPL Daily '!O9<0), "0",'FSLPL Daily '!O10-'FSLPL Daily '!O9) -> 0 | L8: =IF(('FSLPL Daily '!Q10-'FSLPL Daily '!Q9<0), "0",'FSLPL Daily '!Q10-'FSLPL Daily '!Q9) -> 0 | M8: =IF(('FSLPL Daily '!S10-'FSLPL Daily '!S9<0), "0",'FSLPL Daily '!S10-'FSLPL Daily '!S9) -> 0 | N8: =IF(('FSLPL Daily '!U10-'FSLPL Daily '!U9<0), "0",'FSLPL Daily '!U10-'FSLPL Daily '!U9) -> 0 | O8: =IF(('FSLPL Daily '!W10-'FSLPL Daily '!W9<0), "0",'FSLPL Daily '!W10-'FSLPL Daily '!W9) -> 0 | P8: =IF(('FSLPL Daily '!Y10-'FSLPL Daily '!Y9<0), "0",'FSLPL Daily '!Y10-'FSLPL Daily '!Y9) -> 0 | Q8: =IF(('FSLPL Daily '!AA10-'FSLPL Daily '!AA9<0), "0",'FSLPL Daily '!AA10-'FSLPL Daily '!AA9) -> 0 | R8: =IF(('FSLPL Daily '!AC10-'FSLPL Daily '!AC9<0), "0",'FSLPL Daily '!AC10-'FSLPL Daily '!AC9) -> 0 | S8: =IF(('FSLPL Daily '!AE10-'FSLPL Daily '!AE9<0), "0",'FSLPL Daily '!AE10-'FSLPL Daily '!AE9) -> 0 | T8: =IF(('FSLPL Daily '!AG10-'FSLPL Daily '!AG9<0), "0",'FSLPL Daily '!AG10-'FSLPL Daily '!AG9) -> 0 | U8: =IF(('FSLPL Daily '!AI10-'FSLPL Daily '!AI9<0), "0",'FSLPL Daily '!AI10-'FSLPL Daily '!AI9) -> 0 | V8: =IF(('FSLPL Daily '!AK10-'FSLPL Daily '!AK9<0), "0",'FSLPL Daily '!AK10-'FSLPL Daily '!AK9) -> 0 | W8: =IF(('FSLPL Daily '!AM10-'FSLPL Daily '!AM9<0), "0",'FSLPL Daily '!AM10-'FSLPL Daily '!AM9) -> 0 | X8: =IF(('FSLPL Daily '!AO10-'FSLPL Daily '!AO9<0), "0",'FSLPL Daily '!AO10-'FSLPL Daily '!AO9) -> 0 | Y8: ='FSLPL Daily '!AS10 -> 0 | Z8: ='FSLPL Daily '!AU10 -> 0 | AA8: =IF(('FSLPL Daily '!AV10-'FSLPL Daily '!AV9<0), "0",'FSLPL Daily '!AV10-'FSLPL Daily '!AV9) -> 16 | AB8: =IF(('FSLPL Daily '!AX10-'FSLPL Daily '!AX9<0), "0",'FSLPL Daily '!AX10-'FSLPL Daily '!AX9) -> 2 | AC8: =IF(('FSLPL Daily '!AZ10-'FSLPL Daily '!AZ9<0), "0",'FSLPL Daily '!AZ10-'FSLPL Daily '!AZ9) -> 2041 | AD8: =IF(('FSLPL Daily '!BB10-'FSLPL Daily '!BB9<0), "0",'FSLPL Daily '!BB10-'FSLPL Daily '!BB9) -> 1177 | AE8: ='FSLPL Daily '!BD10 -> 162 | AF8: ='FSLPL Daily '!BE10 -> 262
A9: London at Park Lane | B9: =B8+1 -> 8 | C9: 10 | D9: 2022 | E9: =IF(('FSLPL Daily '!C11-'FSLPL Daily '!C10<0), "0",'FSLPL Daily '!C11-'FSLPL Daily '!C10) -> 0 | F9: =IF(('FSLPL Daily '!E11-'FSLPL Daily '!E10<0), "0",'FSLPL Daily '!E11-'FSLPL Daily '!E10) -> 0 | G9: =IF(('FSLPL Daily '!G11-'FSLPL Daily '!G10<0), "0",'FSLPL Daily '!G11-'FSLPL Daily '!G10) -> 3533 | H9: =IF(('FSLPL Daily '!I11-'FSLPL Daily '!I10<0), "0",'FSLPL Daily '!I11-'FSLPL Daily '!I10) -> 0 | I9: =IF(('FSLPL Daily '!K11-'FSLPL Daily '!K10<0), "0",'FSLPL Daily '!K11-'FSLPL Daily '!K10) -> 0 | J9: =IF(('FSLPL Daily '!M11-'FSLPL Daily '!M10<0), "0",'FSLPL Daily '!M11-'FSLPL Daily '!M10) -> 0 | K9: =IF(('FSLPL Daily '!O11-'FSLPL Daily '!O10<0), "0",'FSLPL Daily '!O11-'FSLPL Daily '!O10) -> 0 | L9: =IF(('FSLPL Daily '!Q11-'FSLPL Daily '!Q10<0), "0",'FSLPL Daily '!Q11-'FSLPL Daily '!Q10) -> 0 | M9: =IF(('FSLPL Daily '!S11-'FSLPL Daily '!S10<0), "0",'FSLPL Daily '!S11-'FSLPL Daily '!S10) -> 0 | N9: =IF(('FSLPL Daily '!U11-'FSLPL Daily '!U10<0), "0",'FSLPL Daily '!U11-'FSLPL Daily '!U10) -> 0 | O9: =IF(('FSLPL Daily '!W11-'FSLPL Daily '!W10<0), "0",'FSLPL Daily '!W11-'FSLPL Daily '!W10) -> 0 | P9: =IF(('FSLPL Daily '!Y11-'FSLPL Daily '!Y10<0), "0",'FSLPL Daily '!Y11-'FSLPL Daily '!Y10) -> 0 | Q9: =IF(('FSLPL Daily '!AA11-'FSLPL Daily '!AA10<0), "0",'FSLPL Daily '!AA11-'FSLPL Daily '!AA10) -> 0 | R9: =IF(('FSLPL Daily '!AC11-'FSLPL Daily '!AC10<0), "0",'FSLPL Daily '!AC11-'FSLPL Daily '!AC10) -> 0 | S9: =IF(('FSLPL Daily '!AE11-'FSLPL Daily '!AE10<0), "0",'FSLPL Daily '!AE11-'FSLPL Daily '!AE10) -> 0 | T9: =IF(('FSLPL Daily '!AG11-'FSLPL Daily '!AG10<0), "0",'FSLPL Daily '!AG11-'FSLPL Daily '!AG10) -> 0 | U9: =IF(('FSLPL Daily '!AI11-'FSLPL Daily '!AI10<0), "0",'FSLPL Daily '!AI11-'FSLPL Daily '!AI10) -> 0 | V9: =IF(('FSLPL Daily '!AK11-'FSLPL Daily '!AK10<0), "0",'FSLPL Daily '!AK11-'FSLPL Daily '!AK10) -> 0 | W9: =IF(('FSLPL Daily '!AM11-'FSLPL Daily '!AM10<0), "0",'FSLPL Daily '!AM11-'FSLPL Daily '!AM10) -> 0 | X9: =IF(('FSLPL Daily '!AO11-'FSLPL Daily '!AO10<0), "0",'FSLPL Daily '!AO11-'FSLPL Daily '!AO10) -> 0 | Y9: ='FSLPL Daily '!AS11 -> 0 | Z9: ='FSLPL Daily '!AU11 -> 0 | AA9: =IF(('FSLPL Daily '!AV11-'FSLPL Daily '!AV10<0), "0",'FSLPL Daily '!AV11-'FSLPL Daily '!AV10) -> 18 | AB9: =IF(('FSLPL Daily '!AX11-'FSLPL Daily '!AX10<0), "0",'FSLPL Daily '!AX11-'FSLPL Daily '!AX10) -> 2 | AC9: =IF(('FSLPL Daily '!AZ11-'FSLPL Daily '!AZ10<0), "0",'FSLPL Daily '!AZ11-'FSLPL Daily '!AZ10) -> 1720 | AD9: =IF(('FSLPL Daily '!BB11-'FSLPL Daily '!BB10<0), "0",'FSLPL Daily '!BB11-'FSLPL Daily '!BB10) -> 1130 | AE9: ='FSLPL Daily '!BD11 -> 179 | AF9: ='FSLPL Daily '!BE11 -> 307
A10: London at Park Lane | B10: =B9+1 -> 9 | C10: 10 | D10: 2022 | E10: =IF(('FSLPL Daily '!C12-'FSLPL Daily '!C11<0), "0",'FSLPL Daily '!C12-'FSLPL Daily '!C11) -> 0 | F10: =IF(('FSLPL Daily '!E12-'FSLPL Daily '!E11<0), "0",'FSLPL Daily '!E12-'FSLPL Daily '!E11) -> 0 | G10: =IF(('FSLPL Daily '!G12-'FSLPL Daily '!G11<0), "0",'FSLPL Daily '!G12-'FSLPL Daily '!G11) -> 3747 | H10: =IF(('FSLPL Daily '!I12-'FSLPL Daily '!I11<0), "0",'FSLPL Daily '!I12-'FSLPL Daily '!I11) -> 0 | I10: =IF(('FSLPL Daily '!K12-'FSLPL Daily '!K11<0), "0",'FSLPL Daily '!K12-'FSLPL Daily '!K11) -> 0 | J10: =IF(('FSLPL Daily '!M12-'FSLPL Daily '!M11<0), "0",'FSLPL Daily '!M12-'FSLPL Daily '!M11) -> 0 | K10: =IF(('FSLPL Daily '!O12-'FSLPL Daily '!O11<0), "0",'FSLPL Daily '!O12-'FSLPL Daily '!O11) -> 0 | L10: =IF(('FSLPL Daily '!Q12-'FSLPL Daily '!Q11<0), "0",'FSLPL Daily '!Q12-'FSLPL Daily '!Q11) -> 0 | M10: =IF(('FSLPL Daily '!S12-'FSLPL Daily '!S11<0), "0",'FSLPL Daily '!S12-'FSLPL Daily '!S11) -> 0 | N10: =IF(('FSLPL Daily '!U12-'FSLPL Daily '!U11<0), "0",'FSLPL Daily '!U12-'FSLPL Daily '!U11) -> 0 | O10: =IF(('FSLPL Daily '!W12-'FSLPL Daily '!W11<0), "0",'FSLPL Daily '!W12-'FSLPL Daily '!W11) -> 0 | P10: =IF(('FSLPL Daily '!Y12-'FSLPL Daily '!Y11<0), "0",'FSLPL Daily '!Y12-'FSLPL Daily '!Y11) -> 0 | Q10: =IF(('FSLPL Daily '!AA12-'FSLPL Daily '!AA11<0), "0",'FSLPL Daily '!AA12-'FSLPL Daily '!AA11) -> 0 | R10: =IF(('FSLPL Daily '!AC12-'FSLPL Daily '!AC11<0), "0",'FSLPL Daily '!AC12-'FSLPL Daily '!AC11) -> 0 | S10: =IF(('FSLPL Daily '!AE12-'FSLPL Daily '!AE11<0), "0",'FSLPL Daily '!AE12-'FSLPL Daily '!AE11) -> 0 | T10: =IF(('FSLPL Daily '!AG12-'FSLPL Daily '!AG11<0), "0",'FSLPL Daily '!AG12-'FSLPL Daily '!AG11) -> 0 | U10: =IF(('FSLPL Daily '!AI12-'FSLPL Daily '!AI11<0), "0",'FSLPL Daily '!AI12-'FSLPL Daily '!AI11) -> 0 | V10: =IF(('FSLPL Daily '!AK12-'FSLPL Daily '!AK11<0), "0",'FSLPL Daily '!AK12-'FSLPL Daily '!AK11) -> 0 | W10: =IF(('FSLPL Daily '!AM12-'FSLPL Daily '!AM11<0), "0",'FSLPL Daily '!AM12-'FSLPL Daily '!AM11) -> 0 | X10: =IF(('FSLPL Daily '!AO12-'FSLPL Daily '!AO11<0), "0",'FSLPL Daily '!AO12-'FSLPL Daily '!AO11) -> 0 | Y10: ='FSLPL Daily '!AS12 -> 0 | Z10: ='FSLPL Daily '!AU12 -> 0 | AA10: =IF(('FSLPL Daily '!AV12-'FSLPL Daily '!AV11<0), "0",'FSLPL Daily '!AV12-'FSLPL Daily '!AV11) -> 18 | AB10: =IF(('FSLPL Daily '!AX12-'FSLPL Daily '!AX11<0), "0",'FSLPL Daily '!AX12-'FSLPL Daily '!AX11) -> 2 | AC10: =IF(('FSLPL Daily '!AZ12-'FSLPL Daily '!AZ11<0), "0",'FSLPL Daily '!AZ12-'FSLPL Daily '!AZ11) -> 1606 | AD10: =IF(('FSLPL Daily '!BB12-'FSLPL Daily '!BB11<0), "0",'FSLPL Daily '!BB12-'FSLPL Daily '!BB11) -> 1205 | AE10: ='FSLPL Daily '!BD12 -> 169 | AF10: ='FSLPL Daily '!BE12 -> 294
A11: London at Park Lane | B11: =B10+1 -> 10 | C11: 10 | D11: 2022 | E11: =IF(('FSLPL Daily '!C13-'FSLPL Daily '!C12<0), "0",'FSLPL Daily '!C13-'FSLPL Daily '!C12) -> 0 | F11: =IF(('FSLPL Daily '!E13-'FSLPL Daily '!E12<0), "0",'FSLPL Daily '!E13-'FSLPL Daily '!E12) -> 0 | G11: =IF(('FSLPL Daily '!G13-'FSLPL Daily '!G12<0), "0",'FSLPL Daily '!G13-'FSLPL Daily '!G12) -> 3859 | H11: =IF(('FSLPL Daily '!I13-'FSLPL Daily '!I12<0), "0",'FSLPL Daily '!I13-'FSLPL Daily '!I12) -> 0 | I11: =IF(('FSLPL Daily '!K13-'FSLPL Daily '!K12<0), "0",'FSLPL Daily '!K13-'FSLPL Daily '!K12) -> 0 | J11: =IF(('FSLPL Daily '!M13-'FSLPL Daily '!M12<0), "0",'FSLPL Daily '!M13-'FSLPL Daily '!M12) -> 0 | K11: =IF(('FSLPL Daily '!O13-'FSLPL Daily '!O12<0), "0",'FSLPL Daily '!O13-'FSLPL Daily '!O12) -> 0 | L11: =IF(('FSLPL Daily '!Q13-'FSLPL Daily '!Q12<0), "0",'FSLPL Daily '!Q13-'FSLPL Daily '!Q12) -> 0 | M11: =IF(('FSLPL Daily '!S13-'FSLPL Daily '!S12<0), "0",'FSLPL Daily '!S13-'FSLPL Daily '!S12) -> 0 | N11: =IF(('FSLPL Daily '!U13-'FSLPL Daily '!U12<0), "0",'FSLPL Daily '!U13-'FSLPL Daily '!U12) -> 0 | O11: =IF(('FSLPL Daily '!W13-'FSLPL Daily '!W12<0), "0",'FSLPL Daily '!W13-'FSLPL Daily '!W12) -> 0 | P11: =IF(('FSLPL Daily '!Y13-'FSLPL Daily '!Y12<0), "0",'FSLPL Daily '!Y13-'FSLPL Daily '!Y12) -> 0 | Q11: =IF(('FSLPL Daily '!AA13-'FSLPL Daily '!AA12<0), "0",'FSLPL Daily '!AA13-'FSLPL Daily '!AA12) -> 0 | R11: =IF(('FSLPL Daily '!AC13-'FSLPL Daily '!AC12<0), "0",'FSLPL Daily '!AC13-'FSLPL Daily '!AC12) -> 0 | S11: =IF(('FSLPL Daily '!AE13-'FSLPL Daily '!AE12<0), "0",'FSLPL Daily '!AE13-'FSLPL Daily '!AE12) -> 0 | T11: =IF(('FSLPL Daily '!AG13-'FSLPL Daily '!AG12<0), "0",'FSLPL Daily '!AG13-'FSLPL Daily '!AG12) -> 0 | U11: =IF(('FSLPL Daily '!AI13-'FSLPL Daily '!AI12<0), "0",'FSLPL Daily '!AI13-'FSLPL Daily '!AI12) -> 0 | V11: =IF(('FSLPL Daily '!AK13-'FSLPL Daily '!AK12<0), "0",'FSLPL Daily '!AK13-'FSLPL Daily '!AK12) -> 0 | W11: =IF(('FSLPL Daily '!AM13-'FSLPL Daily '!AM12<0), "0",'FSLPL Daily '!AM13-'FSLPL Daily '!AM12) -> 0 | X11: =IF(('FSLPL Daily '!AO13-'FSLPL Daily '!AO12<0), "0",'FSLPL Daily '!AO13-'FSLPL Daily '!AO12) -> 0 | Y11: ='FSLPL Daily '!AS13 -> 0 | Z11: ='FSLPL Daily '!AU13 -> 0 | AA11: =IF(('FSLPL Daily '!AV13-'FSLPL Daily '!AV12<0), "0",'FSLPL Daily '!AV13-'FSLPL Daily '!AV12) -> 15 | AB11: =IF(('FSLPL Daily '!AX13-'FSLPL Daily '!AX12<0), "0",'FSLPL Daily '!AX13-'FSLPL Daily '!AX12) -> 2 | AC11: =IF(('FSLPL Daily '!AZ13-'FSLPL Daily '!AZ12<0), "0",'FSLPL Daily '!AZ13-'FSLPL Daily '!AZ12) -> 1665 | AD11: =IF(('FSLPL Daily '!BB13-'FSLPL Daily '!BB12<0), "0",'FSLPL Daily '!BB13-'FSLPL Daily '!BB12) -> 1226 | AE11: ='FSLPL Daily '!BD13 -> 157 | AF11: ='FSLPL Daily '!BE13 -> 252
A12: London at Park Lane | B12: =B11+1 -> 11 | C12: 10 | D12: 2022 | E12: =IF(('FSLPL Daily '!C14-'FSLPL Daily '!C13<0), "0",'FSLPL Daily '!C14-'FSLPL Daily '!C13) -> 0 | F12: =IF(('FSLPL Daily '!E14-'FSLPL Daily '!E13<0), "0",'FSLPL Daily '!E14-'FSLPL Daily '!E13) -> 0 | G12: =IF(('FSLPL Daily '!G14-'FSLPL Daily '!G13<0), "0",'FSLPL Daily '!G14-'FSLPL Daily '!G13) -> 4096 | H12: =IF(('FSLPL Daily '!I14-'FSLPL Daily '!I13<0), "0",'FSLPL Daily '!I14-'FSLPL Daily '!I13) -> 0 | I12: =IF(('FSLPL Daily '!K14-'FSLPL Daily '!K13<0), "0",'FSLPL Daily '!K14-'FSLPL Daily '!K13) -> 0 | J12: =IF(('FSLPL Daily '!M14-'FSLPL Daily '!M13<0), "0",'FSLPL Daily '!M14-'FSLPL Daily '!M13) -> 0 | K12: =IF(('FSLPL Daily '!O14-'FSLPL Daily '!O13<0), "0",'FSLPL Daily '!O14-'FSLPL Daily '!O13) -> 0 | L12: =IF(('FSLPL Daily '!Q14-'FSLPL Daily '!Q13<0), "0",'FSLPL Daily '!Q14-'FSLPL Daily '!Q13) -> 0 | M12: =IF(('FSLPL Daily '!S14-'FSLPL Daily '!S13<0), "0",'FSLPL Daily '!S14-'FSLPL Daily '!S13) -> 0 | N12: =IF(('FSLPL Daily '!U14-'FSLPL Daily '!U13<0), "0",'FSLPL Daily '!U14-'FSLPL Daily '!U13) -> 0 | O12: =IF(('FSLPL Daily '!W14-'FSLPL Daily '!W13<0), "0",'FSLPL Daily '!W14-'FSLPL Daily '!W13) -> 0 | P12: =IF(('FSLPL Daily '!Y14-'FSLPL Daily '!Y13<0), "0",'FSLPL Daily '!Y14-'FSLPL Daily '!Y13) -> 0 | Q12: =IF(('FSLPL Daily '!AA14-'FSLPL Daily '!AA13<0), "0",'FSLPL Daily '!AA14-'FSLPL Daily '!AA13) -> 0 | R12: =IF(('FSLPL Daily '!AC14-'FSLPL Daily '!AC13<0), "0",'FSLPL Daily '!AC14-'FSLPL Daily '!AC13) -> 0 | S12: =IF(('FSLPL Daily '!AE14-'FSLPL Daily '!AE13<0), "0",'FSLPL Daily '!AE14-'FSLPL Daily '!AE13) -> 0 | T12: =IF(('FSLPL Daily '!AG14-'FSLPL Daily '!AG13<0), "0",'FSLPL Daily '!AG14-'FSLPL Daily '!AG13) -> 0 | U12: =IF(('FSLPL Daily '!AI14-'FSLPL Daily '!AI13<0), "0",'FSLPL Daily '!AI14-'FSLPL Daily '!AI13) -> 0 | V12: =IF(('FSLPL Daily '!AK14-'FSLPL Daily '!AK13<0), "0",'FSLPL Daily '!AK14-'FSLPL Daily '!AK13) -> 0 | W12: =IF(('FSLPL Daily '!AM14-'FSLPL Daily '!AM13<0), "0",'FSLPL Daily '!AM14-'FSLPL Daily '!AM13) -> 0 | X12: =IF(('FSLPL Daily '!AO14-'FSLPL Daily '!AO13<0), "0",'FSLPL Daily '!AO14-'FSLPL Daily '!AO13) -> 0 | Y12: ='FSLPL Daily '!AS14 -> 0 | Z12: ='FSLPL Daily '!AU14 -> 0 | AA12: =IF(('FSLPL Daily '!AV14-'FSLPL Daily '!AV13<0), "0",'FSLPL Daily '!AV14-'FSLPL Daily '!AV13) -> 15 | AB12: =IF(('FSLPL Daily '!AX14-'FSLPL Daily '!AX13<0), "0",'FSLPL Daily '!AX14-'FSLPL Daily '!AX13) -> 2 | AC12: =IF(('FSLPL Daily '!AZ14-'FSLPL Daily '!AZ13<0), "0",'FSLPL Daily '!AZ14-'FSLPL Daily '!AZ13) -> 1928 | AD12: =IF(('FSLPL Daily '!BB14-'FSLPL Daily '!BB13<0), "0",'FSLPL Daily '!BB14-'FSLPL Daily '!BB13) -> 1289 | AE12: ='FSLPL Daily '!BD14 -> 145 | AF12: ='FSLPL Daily '!BE14 -> 230
A13: London at Park Lane | B13: =B12+1 -> 12 | C13: 10 | D13: 2022 | E13: =IF(('FSLPL Daily '!C15-'FSLPL Daily '!C14<0), "0",'FSLPL Daily '!C15-'FSLPL Daily '!C14) -> 0 | F13: =IF(('FSLPL Daily '!E15-'FSLPL Daily '!E14<0), "0",'FSLPL Daily '!E15-'FSLPL Daily '!E14) -> 0 | G13: =IF(('FSLPL Daily '!G15-'FSLPL Daily '!G14<0), "0",'FSLPL Daily '!G15-'FSLPL Daily '!G14) -> 7551 | H13: =IF(('FSLPL Daily '!I15-'FSLPL Daily '!I14<0), "0",'FSLPL Daily '!I15-'FSLPL Daily '!I14) -> 0 | I13: =IF(('FSLPL Daily '!K15-'FSLPL Daily '!K14<0), "0",'FSLPL Daily '!K15-'FSLPL Daily '!K14) -> 0 | J13: =IF(('FSLPL Daily '!M15-'FSLPL Daily '!M14<0), "0",'FSLPL Daily '!M15-'FSLPL Daily '!M14) -> 0 | K13: =IF(('FSLPL Daily '!O15-'FSLPL Daily '!O14<0), "0",'FSLPL Daily '!O15-'FSLPL Daily '!O14) -> 0 | L13: =IF(('FSLPL Daily '!Q15-'FSLPL Daily '!Q14<0), "0",'FSLPL Daily '!Q15-'FSLPL Daily '!Q14) -> 0 | M13: =IF(('FSLPL Daily '!S15-'FSLPL Daily '!S14<0), "0",'FSLPL Daily '!S15-'FSLPL Daily '!S14) -> 0 | N13: =IF(('FSLPL Daily '!U15-'FSLPL Daily '!U14<0), "0",'FSLPL Daily '!U15-'FSLPL Daily '!U14) -> 0 | O13: =IF(('FSLPL Daily '!W15-'FSLPL Daily '!W14<0), "0",'FSLPL Daily '!W15-'FSLPL Daily '!W14) -> 0 | P13: =IF(('FSLPL Daily '!Y15-'FSLPL Daily '!Y14<0), "0",'FSLPL Daily '!Y15-'FSLPL Daily '!Y14) -> 0 | Q13: =IF(('FSLPL Daily '!AA15-'FSLPL Daily '!AA14<0), "0",'FSLPL Daily '!AA15-'FSLPL Daily '!AA14) -> 0 | R13: =IF(('FSLPL Daily '!AC15-'FSLPL Daily '!AC14<0), "0",'FSLPL Daily '!AC15-'FSLPL Daily '!AC14) -> 0 | S13: =IF(('FSLPL Daily '!AE15-'FSLPL Daily '!AE14<0), "0",'FSLPL Daily '!AE15-'FSLPL Daily '!AE14) -> 0 | T13: =IF(('FSLPL Daily '!AG15-'FSLPL Daily '!AG14<0), "0",'FSLPL Daily '!AG15-'FSLPL Daily '!AG14) -> 0 | U13: =IF(('FSLPL Daily '!AI15-'FSLPL Daily '!AI14<0), "0",'FSLPL Daily '!AI15-'FSLPL Daily '!AI14) -> 0 | V13: =IF(('FSLPL Daily '!AK15-'FSLPL Daily '!AK14<0), "0",'FSLPL Daily '!AK15-'FSLPL Daily '!AK14) -> 0 | W13: =IF(('FSLPL Daily '!AM15-'FSLPL Daily '!AM14<0), "0",'FSLPL Daily '!AM15-'FSLPL Daily '!AM14) -> 0 | X13: =IF(('FSLPL Daily '!AO15-'FSLPL Daily '!AO14<0), "0",'FSLPL Daily '!AO15-'FSLPL Daily '!AO14) -> 0 | Y13: ='FSLPL Daily '!AS15 -> 0 | Z13: ='FSLPL Daily '!AU15 -> 0 | AA13: =IF(('FSLPL Daily '!AV15-'FSLPL Daily '!AV14<0), "0",'FSLPL Daily '!AV15-'FSLPL Daily '!AV14) -> 35 | AB13: =IF(('FSLPL Daily '!AX15-'FSLPL Daily '!AX14<0), "0",'FSLPL Daily '!AX15-'FSLPL Daily '!AX14) -> 4 | AC13: =IF(('FSLPL Daily '!AZ15-'FSLPL Daily '!AZ14<0), "0",'FSLPL Daily '!AZ15-'FSLPL Daily '!AZ14) -> 3378 | AD13: =IF(('FSLPL Daily '!BB15-'FSLPL Daily '!BB14<0), "0",'FSLPL Daily '!BB15-'FSLPL Daily '!BB14) -> 2394 | AE13: ='FSLPL Daily '!BD15 -> 161 | AF13: ='FSLPL Daily '!BE15 -> 246
A14: London at Park Lane | B14: =B13+1 -> 13 | C14: 10 | D14: 2022 | E14: =IF(('FSLPL Daily '!C16-'FSLPL Daily '!C15<0), "0",'FSLPL Daily '!C16-'FSLPL Daily '!C15) -> 0 | F14: =IF(('FSLPL Daily '!E16-'FSLPL Daily '!E15<0), "0",'FSLPL Daily '!E16-'FSLPL Daily '!E15) -> 0 | G14: =IF(('FSLPL Daily '!G16-'FSLPL Daily '!G15<0), "0",'FSLPL Daily '!G16-'FSLPL Daily '!G15) -> 3548 | H14: =IF(('FSLPL Daily '!I16-'FSLPL Daily '!I15<0), "0",'FSLPL Daily '!I16-'FSLPL Daily '!I15) -> 0 | I14: =IF(('FSLPL Daily '!K16-'FSLPL Daily '!K15<0), "0",'FSLPL Daily '!K16-'FSLPL Daily '!K15) -> 0 | J14: =IF(('FSLPL Daily '!M16-'FSLPL Daily '!M15<0), "0",'FSLPL Daily '!M16-'FSLPL Daily '!M15) -> 0 | K14: =IF(('FSLPL Daily '!O16-'FSLPL Daily '!O15<0), "0",'FSLPL Daily '!O16-'FSLPL Daily '!O15) -> 0 | L14: =IF(('FSLPL Daily '!Q16-'FSLPL Daily '!Q15<0), "0",'FSLPL Daily '!Q16-'FSLPL Daily '!Q15) -> 0 | M14: =IF(('FSLPL Daily '!S16-'FSLPL Daily '!S15<0), "0",'FSLPL Daily '!S16-'FSLPL Daily '!S15) -> 0 | N14: =IF(('FSLPL Daily '!U16-'FSLPL Daily '!U15<0), "0",'FSLPL Daily '!U16-'FSLPL Daily '!U15) -> 0 | O14: =IF(('FSLPL Daily '!W16-'FSLPL Daily '!W15<0), "0",'FSLPL Daily '!W16-'FSLPL Daily '!W15) -> 0 | P14: =IF(('FSLPL Daily '!Y16-'FSLPL Daily '!Y15<0), "0",'FSLPL Daily '!Y16-'FSLPL Daily '!Y15) -> 0 | Q14: =IF(('FSLPL Daily '!AA16-'FSLPL Daily '!AA15<0), "0",'FSLPL Daily '!AA16-'FSLPL Daily '!AA15) -> 0 | R14: =IF(('FSLPL Daily '!AC16-'FSLPL Daily '!AC15<0), "0",'FSLPL Daily '!AC16-'FSLPL Daily '!AC15) -> 0 | S14: =IF(('FSLPL Daily '!AE16-'FSLPL Daily '!AE15<0), "0",'FSLPL Daily '!AE16-'FSLPL Daily '!AE15) -> 0 | T14: =IF(('FSLPL Daily '!AG16-'FSLPL Daily '!AG15<0), "0",'FSLPL Daily '!AG16-'FSLPL Daily '!AG15) -> 0 | U14: =IF(('FSLPL Daily '!AI16-'FSLPL Daily '!AI15<0), "0",'FSLPL Daily '!AI16-'FSLPL Daily '!AI15) -> 0 | V14: =IF(('FSLPL Daily '!AK16-'FSLPL Daily '!AK15<0), "0",'FSLPL Daily '!AK16-'FSLPL Daily '!AK15) -> 0 | W14: =IF(('FSLPL Daily '!AM16-'FSLPL Daily '!AM15<0), "0",'FSLPL Daily '!AM16-'FSLPL Daily '!AM15) -> 0 | X14: =IF(('FSLPL Daily '!AO16-'FSLPL Daily '!AO15<0), "0",'FSLPL Daily '!AO16-'FSLPL Daily '!AO15) -> 0 | Y14: ='FSLPL Daily '!AS16 -> 0 | Z14: ='FSLPL Daily '!AU16 -> 0 | AA14: =IF(('FSLPL Daily '!AV16-'FSLPL Daily '!AV15<0), "0",'FSLPL Daily '!AV16-'FSLPL Daily '!AV15) -> 17 | AB14: =IF(('FSLPL Daily '!AX16-'FSLPL Daily '!AX15<0), "0",'FSLPL Daily '!AX16-'FSLPL Daily '!AX15) -> 2 | AC14: =IF(('FSLPL Daily '!AZ16-'FSLPL Daily '!AZ15<0), "0",'FSLPL Daily '!AZ16-'FSLPL Daily '!AZ15) -> 1624 | AD14: =IF(('FSLPL Daily '!BB16-'FSLPL Daily '!BB15<0), "0",'FSLPL Daily '!BB16-'FSLPL Daily '!BB15) -> 1135 | AE14: ='FSLPL Daily '!BD16 -> 156 | AF14: ='FSLPL Daily '!BE16 -> 229
... A30: London at Park Lane | B30: =B29+1 -> 29 | C30: 10 | D30: 2022 | E30: =IF(('FSLPL Daily '!C32-'FSLPL Daily '!C31<0), "0",'FSLPL Daily '!C32-'FSLPL Daily '!C31) -> 0 | F30: =IF(('FSLPL Daily '!E32-'FSLPL Daily '!E31<0), "0",'FSLPL Daily '!E32-'FSLPL Daily '!E31) -> 0 | G30: =IF(('FSLPL Daily '!G32-'FSLPL Daily '!G31<0), "0",'FSLPL Daily '!G32-'FSLPL Daily '!G31) -> 0 | H30: =IF(('FSLPL Daily '!I32-'FSLPL Daily '!I31<0), "0",'FSLPL Daily '!I32-'FSLPL Daily '!I31) -> 0 | I30: =IF(('FSLPL Daily '!K32-'FSLPL Daily '!K31<0), "0",'FSLPL Daily '!K32-'FSLPL Daily '!K31) -> 0 | J30: =IF(('FSLPL Daily '!M32-'FSLPL Daily '!M31<0), "0",'FSLPL Daily '!M32-'FSLPL Daily '!M31) -> 0 | K30: =IF(('FSLPL Daily '!O32-'FSLPL Daily '!O31<0), "0",'FSLPL Daily '!O32-'FSLPL Daily '!O31) -> 0 | L30: =IF(('FSLPL Daily '!Q32-'FSLPL Daily '!Q31<0), "0",'FSLPL Daily '!Q32-'FSLPL Daily '!Q31) -> 0 | M30: =IF(('FSLPL Daily '!S32-'FSLPL Daily '!S31<0), "0",'FSLPL Daily '!S32-'FSLPL Daily '!S31) -> 0 | N30: =IF(('FSLPL Daily '!U32-'FSLPL Daily '!U31<0), "0",'FSLPL Daily '!U32-'FSLPL Daily '!U31) -> 0 | O30: =IF(('FSLPL Daily '!W32-'FSLPL Daily '!W31<0), "0",'FSLPL Daily '!W32-'FSLPL Daily '!W31) -> 0 | P30: =IF(('FSLPL Daily '!Y32-'FSLPL Daily '!Y31<0), "0",'FSLPL Daily '!Y32-'FSLPL Daily '!Y31) -> 0 | Q30: =IF(('FSLPL Daily '!AA32-'FSLPL Daily '!AA31<0), "0",'FSLPL Daily '!AA32-'FSLPL Daily '!AA31) -> 0 | R30: =IF(('FSLPL Daily '!AC32-'FSLPL Daily '!AC31<0), "0",'FSLPL Daily '!AC32-'FSLPL Daily '!AC31) -> 0 | S30: =IF(('FSLPL Daily '!AE32-'FSLPL Daily '!AE31<0), "0",'FSLPL Daily '!AE32-'FSLPL Daily '!AE31) -> 0 | T30: =IF(('FSLPL Daily '!AG32-'FSLPL Daily '!AG31<0), "0",'FSLPL Daily '!AG32-'FSLPL Daily '!AG31) -> 0 | U30: =IF(('FSLPL Daily '!AI32-'FSLPL Daily '!AI31<0), "0",'FSLPL Daily '!AI32-'FSLPL Daily '!AI31) -> 0 | V30: =IF(('FSLPL Daily '!AK32-'FSLPL Daily '!AK31<0), "0",'FSLPL Daily '!AK32-'FSLPL Daily '!AK31) -> 0 | W30: =IF(('FSLPL Daily '!AM32-'FSLPL Daily '!AM31<0), "0",'FSLPL Daily '!AM32-'FSLPL Daily '!AM31) -> 0 | X30: =IF(('FSLPL Daily '!AO32-'FSLPL Daily '!AO31<0), "0",'FSLPL Daily '!AO32-'FSLPL Daily '!AO31) -> 0 | Y30: ='FSLPL Daily '!AS32 -> 0 | Z30: ='FSLPL Daily '!AU32 -> 0 | AA30: =IF(('FSLPL Daily '!AV32-'FSLPL Daily '!AV31<0), "0",'FSLPL Daily '!AV32-'FSLPL Daily '!AV31) -> 0 | AB30: =IF(('FSLPL Daily '!AX32-'FSLPL Daily '!AX31<0), "0",'FSLPL Daily '!AX32-'FSLPL Daily '!AX31) -> 0 | AC30: =IF(('FSLPL Daily '!AZ32-'FSLPL Daily '!AZ31<0), "0",'FSLPL Daily '!AZ32-'FSLPL Daily '!AZ31) -> 0 | AD30: =IF(('FSLPL Daily '!BB32-'FSLPL Daily '!BB31<0), "0",'FSLPL Daily '!BB32-'FSLPL Daily '!BB31) -> 0 | AE30: ='FSLPL Daily '!BD32 -> 0 | AF30: ='FSLPL Daily '!BE32 -> 0
A31: London at Park Lane | B31: 30 | C31: 10 | D31: 2022 | E31: =IF(('FSLPL Daily '!C33-'FSLPL Daily '!C32<0), "0",'FSLPL Daily '!C33-'FSLPL Daily '!C32) -> 0 | F31: =IF(('FSLPL Daily '!E33-'FSLPL Daily '!E32<0), "0",'FSLPL Daily '!E33-'FSLPL Daily '!E32) -> 0 | G31: =IF(('FSLPL Daily '!G33-'FSLPL Daily '!G32<0), "0",'FSLPL Daily '!G33-'FSLPL Daily '!G32) -> 0 | H31: =IF(('FSLPL Daily '!I33-'FSLPL Daily '!I32<0), "0",'FSLPL Daily '!I33-'FSLPL Daily '!I32) -> 0 | I31: =IF(('FSLPL Daily '!K33-'FSLPL Daily '!K32<0), "0",'FSLPL Daily '!K33-'FSLPL Daily '!K32) -> 0 | J31: =IF(('FSLPL Daily '!M33-'FSLPL Daily '!M32<0), "0",'FSLPL Daily '!M33-'FSLPL Daily '!M32) -> 0 | K31: =IF(('FSLPL Daily '!O33-'FSLPL Daily '!O32<0), "0",'FSLPL Daily '!O33-'FSLPL Daily '!O32) -> 0 | L31: =IF(('FSLPL Daily '!Q33-'FSLPL Daily '!Q32<0), "0",'FSLPL Daily '!Q33-'FSLPL Daily '!Q32) -> 0 | M31: =IF(('FSLPL Daily '!S33-'FSLPL Daily '!S32<0), "0",'FSLPL Daily '!S33-'FSLPL Daily '!S32) -> 0 | N31: =IF(('FSLPL Daily '!U33-'FSLPL Daily '!U32<0), "0",'FSLPL Daily '!U33-'FSLPL Daily '!U32) -> 0 | O31: =IF(('FSLPL Daily '!W33-'FSLPL Daily '!W32<0), "0",'FSLPL Daily '!W33-'FSLPL Daily '!W32) -> 0 | P31: =IF(('FSLPL Daily '!Y33-'FSLPL Daily '!Y32<0), "0",'FSLPL Daily '!Y33-'FSLPL Daily '!Y32) -> 0 | Q31: =IF(('FSLPL Daily '!AA33-'FSLPL Daily '!AA32<0), "0",'FSLPL Daily '!AA33-'FSLPL Daily '!AA32) -> 0 | R31: =IF(('FSLPL Daily '!AC33-'FSLPL Daily '!AC32<0), "0",'FSLPL Daily '!AC33-'FSLPL Daily '!AC32) -> 0 | S31: =IF(('FSLPL Daily '!AE33-'FSLPL Daily '!AE32<0), "0",'FSLPL Daily '!AE33-'FSLPL Daily '!AE32) -> 0 | T31: =IF(('FSLPL Daily '!AG33-'FSLPL Daily '!AG32<0), "0",'FSLPL Daily '!AG33-'FSLPL Daily '!AG32) -> 0 | U31: =IF(('FSLPL Daily '!AI33-'FSLPL Daily '!AI32<0), "0",'FSLPL Daily '!AI33-'FSLPL Daily '!AI32) -> 0 | V31: =IF(('FSLPL Daily '!AK33-'FSLPL Daily '!AK32<0), "0",'FSLPL Daily '!AK33-'FSLPL Daily '!AK32) -> 0 | W31: =IF(('FSLPL Daily '!AM33-'FSLPL Daily '!AM32<0), "0",'FSLPL Daily '!AM33-'FSLPL Daily '!AM32) -> 0 | X31: =IF(('FSLPL Daily '!AO33-'FSLPL Daily '!AO32<0), "0",'FSLPL Daily '!AO33-'FSLPL Daily '!AO32) -> 0 | Y31: ='FSLPL Daily '!AS33 -> 0 | Z31: ='FSLPL Daily '!AU33 -> 0 | AA31: =IF(('FSLPL Daily '!AV33-'FSLPL Daily '!AV32<0), "0",'FSLPL Daily '!AV33-'FSLPL Daily '!AV32) -> 0 | AB31: =IF(('FSLPL Daily '!AX33-'FSLPL Daily '!AX32<0), "0",'FSLPL Daily '!AX33-'FSLPL Daily '!AX32) -> 0 | AC31: =IF(('FSLPL Daily '!AZ33-'FSLPL Daily '!AZ32<0), "0",'FSLPL Daily '!AZ33-'FSLPL Daily '!AZ32) -> 0 | AD31: =IF(('FSLPL Daily '!BB33-'FSLPL Daily '!BB32<0), "0",'FSLPL Daily '!BB33-'FSLPL Daily '!BB32) -> 0 | AE31: ='FSLPL Daily '!BD33 -> 0 | AF31: ='FSLPL Daily '!BE33 -> 0
A32: London at Park Lane | B32: 31 | C32: 10 | D32: 2022 | E32: =IF(('FSLPL Daily '!C34-'FSLPL Daily '!C33<0), "0",'FSLPL Daily '!C34-'FSLPL Daily '!C33) -> 0 | F32: =IF(('FSLPL Daily '!E34-'FSLPL Daily '!E33<0), "0",'FSLPL Daily '!E34-'FSLPL Daily '!E33) -> 0 | G32: =IF(('FSLPL Daily '!G34-'FSLPL Daily '!G33<0), "0",'FSLPL Daily '!G34-'FSLPL Daily '!G33) -> 0 | H32: =IF(('FSLPL Daily '!I34-'FSLPL Daily '!I33<0), "0",'FSLPL Daily '!I34-'FSLPL Daily '!I33) -> 0 | I32: =IF(('FSLPL Daily '!K34-'FSLPL Daily '!K33<0), "0",'FSLPL Daily '!K34-'FSLPL Daily '!K33) -> 0 | J32: =IF(('FSLPL Daily '!M34-'FSLPL Daily '!M33<0), "0",'FSLPL Daily '!M34-'FSLPL Daily '!M33) -> 0 | K32: =IF(('FSLPL Daily '!O34-'FSLPL Daily '!O33<0), "0",'FSLPL Daily '!O34-'FSLPL Daily '!O33) -> 0 | L32: =IF(('FSLPL Daily '!Q34-'FSLPL Daily '!Q33<0), "0",'FSLPL Daily '!Q34-'FSLPL Daily '!Q33) -> 0 | M32: =IF(('FSLPL Daily '!S34-'FSLPL Daily '!S33<0), "0",'FSLPL Daily '!S34-'FSLPL Daily '!S33) -> 0 | N32: =IF(('FSLPL Daily '!U34-'FSLPL Daily '!U33<0), "0",'FSLPL Daily '!U34-'FSLPL Daily '!U33) -> 0 | O32: =IF(('FSLPL Daily '!W34-'FSLPL Daily '!W33<0), "0",'FSLPL Daily '!W34-'FSLPL Daily '!W33) -> 0 | P32: =IF(('FSLPL Daily '!Y34-'FSLPL Daily '!Y33<0), "0",'FSLPL Daily '!Y34-'FSLPL Daily '!Y33) -> 0 | Q32: =IF(('FSLPL Daily '!AA34-'FSLPL Daily '!AA33<0), "0",'FSLPL Daily '!AA34-'FSLPL Daily '!AA33) -> 0 | R32: =IF(('FSLPL Daily '!AC34-'FSLPL Daily '!AC33<0), "0",'FSLPL Daily '!AC34-'FSLPL Daily '!AC33) -> 0 | S32: =IF(('FSLPL Daily '!AE34-'FSLPL Daily '!AE33<0), "0",'FSLPL Daily '!AE34-'FSLPL Daily '!AE33) -> 0 | T32: =IF(('FSLPL Daily '!AG34-'FSLPL Daily '!AG33<0), "0",'FSLPL Daily '!AG34-'FSLPL Daily '!AG33) -> 0 | U32: =IF(('FSLPL Daily '!AI34-'FSLPL Daily '!AI33<0), "0",'FSLPL Daily '!AI34-'FSLPL Daily '!AI33) -> 0 | V32: =IF(('FSLPL Daily '!AK34-'FSLPL Daily '!AK33<0), "0",'FSLPL Daily '!AK34-'FSLPL Daily '!AK33) -> 0 | W32: =IF(('FSLPL Daily '!AM34-'FSLPL Daily '!AM33<0), "0",'FSLPL Daily '!AM34-'FSLPL Daily '!AM33) -> 0 | X32: =IF(('FSLPL Daily '!AO34-'FSLPL Daily '!AO33<0), "0",'FSLPL Daily '!AO34-'FSLPL Daily '!AO33) -> 0 | Y32: ='FSLPL Daily '!AS34 -> 0 | Z32: ='FSLPL Daily '!AU34 -> 0 | AA32: =IF(('FSLPL Daily '!AV34-'FSLPL Daily '!AV33<0), "0",'FSLPL Daily '!AV34-'FSLPL Daily '!AV33) -> 0 | AB32: =IF(('FSLPL Daily '!AX34-'FSLPL Daily '!AX33<0), "0",'FSLPL Daily '!AX34-'FSLPL Daily '!AX33) -> 0 | AC32: =IF(('FSLPL Daily '!AZ34-'FSLPL Daily '!AZ33<0), "0",'FSLPL Daily '!AZ34-'FSLPL Daily '!AZ33) -> 0 | AD32: =IF(('FSLPL Daily '!BB34-'FSLPL Daily '!BB33<0), "0",'FSLPL Daily '!BB34-'FSLPL Daily '!BB33) -> 0 | AE32: ='FSLPL Daily '!BD34 -> 0 | AF32: ='FSLPL Daily '!BE34 -> 0

Sheet FSLPL Daily 
A1: Days | C1: LV Panel 1 KWh | E1: LV Panel 2 KWh | G1: CHP KWh | I1: MCC9 KWh | K1: GF Panel KWh | M1: Kitchen Switchboard | O1: Kitchen Panel | Q1: MCC3 (AHU) KWh | S1: MCC8 KWh | U1: 1st Floor Panel (KWh) | W1: MCC6(1st floor AHU) KWh | Y1: Chiller 1 KWh | AA1: Chiller 2 KWh | AC1: MCC 10 (Mechanical Services) KWh | AE1: MCC2 CHW KWh | AG1: MCC7 (Kitchen) KWh | AI1: MCC 5 (Mechanical services) KWh | AK1: MCC 4 (Water Services) KWh | AM1: MCC1 (KWh) | AO1: Laundry db KWh | AR1: Hamilton Place Water 1 m3 | AT1: Old Parklane Water 2 m3 | AV1: Laundry: Cold Water m3 | AX1: Laundry: Hot Water m3 | AZ1: Natural Gas m3 | BB1: CHP Natural Gas m3
A2: Date | C2: Reading KWH | D2: Difference KWH | E2: Reading KWH | F2: Difference KWH | G2: Reading KWH | H2: Difference KWH | I2: Reading KWH | J2: Difference KWH | K2: Reading KWH | L2: Difference KWH | M2: Reading KWH | N2: Difference KWH | O2: Reading KWH | P2: Difference KWH | Q2: Reading KWH | R2: Difference KWH | S2: Reading KWH | T2: Difference KWH | U2: Reading KWH | V2: Difference KWH | W2: Reading KWH | X2: Difference KWH | Y2: Reading KWH | Z2: Difference KWH | AA2: Reading KWH | AB2: Difference KWH | AC2: Reading KWH | AD2: Difference KWH | AE2: Reading KWH | AF2: Difference KWH | AG2: Reading KWH | AH2: Difference KWH | AI2: Reading KWH | AJ2: Difference KWH | AK2: Reading KWH | AL2: Difference KWH | AM2: Reading KWH | AN2: Difference KWH | AO2: Reading KWH | AP2: Difference KWH | AR2: Reading m³ | AS2: Daily Consumption m³ | AT2: Reading m³ | AU2: Daily Consumption m³ | AV2: Reading m³ | AW2: Daily Consumption m³ | AX2: Reading m³ | AY2: Daily Consumption m³ | AZ2: Reading Liters | BA2: Daily Consumption L | BB2: Reading Liters | BC2: Daily Consumption L | BD2: ROOM NIGHTS | BE2: TOTAL GUESTS
A3: 44834 | D3: =IF((C3-C2<0), "0",C3-C2) -> #VALUE! | G3: 13406571 | J3: =IF((I4-I3<0), "",I4-I3) -> 0 | L3: =IF((K4-K3<0), "",K4-K3) -> 0 | N3: =IF((M4-M3<0), "",M4-M3) -> 0 | P3: =IF((O4-O3<0), "",O4-O3) -> 0 | R3: =IF((Q4-Q3<0), "",Q4-Q3) -> 0 | T3: =IF((S4-S3<0), "",S4-S3) -> 0 | V3: =IF((U4-U3<0), "",U4-U3) -> 0 | X3: =IF((W4-W3<0), "",W4-W3) -> 0 | Z3: =IF((Y4-Y3<0), "",Y4-Y3) -> 0 | AB3: =IF((AA4-AA3<0), "",AA4-AA3) -> 0 | AD3: =IF((AC4-AC3<0), "",AC4-AC3) -> 0 | AF3: =IF((AE4-AE3<0), "",AE4-AE3) -> 0 | AH3: =IF((AG4-AG3<0), "",AG4-AG3) -> 0 | AJ3: =IF((AI4-AI3<0), "",AI4-AI3) -> 0 | AL3: =IF((AK4-AK3<0), "",AK4-AK3) -> 0 | AN3: =IF((AM4-AM3<0), "",AM4-AM3) -> 0 | AP3: =IF((AO4-AO3<0), "",AO4-AO3) -> 0 | AS3: 0 | AU3: 0 | AV3: No reading | AX3: No reading | AY3: =IF((AX3-AX2<0), "",AX3-AX2) -> #VALUE! | AZ3: 8192135 | BA3: =IF((AZ3-AZ2<0), "",AZ3-AZ2) -> #VALUE! | BB3: 1875767 | BC3: =IF((BB3-BB2<0), "",BB3-BB2) -> #VALUE! | BF3: 12.24 | BH3: =193*(BF3/100) -> 23.6232
A4: 44835 | D4: =IF((C4-C3<0), "0",C4-C3) -> 0 | G4: 13410157 | H4: =IF((G5-G4<0), "0",G5-G4) -> 3298 | AS4: 0 | AU4: 0 | AV4: 96318 | AX4: 1346 | AY4: =IF((AX4-AX3<0), "",AX4-AX3) -> #VALUE! | AZ4: 8193627 | BA4: =IF((AZ4-AZ3<0), "",AZ4-AZ3) -> 1492 | BB4: 1876914 | BC4: =IF((BB4-BB3<0), "",BB4-BB3) -> 1147 | BD4: 149 | BE4: 230 | BF4: 20.92 | BH4: =193*(BF4/100) -> 40.3756
A5: 44836 | D5: =IF((C5-C4<0), "0",C5-C4) -> 0 | F5: =IF((E5-E4<0), "0",E5-E4) -> 0 | G5: 13413455 | J5: =IF((I5-I4<0), "0",I5-I4) -> 0 | L5: =IF((K5-K4<0), "0",K5-K4) -> 0 | N5: =IF((M5-M4<0), "0",M5-M4) -> 0 | P5: =IF((O5-O4<0), "0",O5-O4) -> 0 | R5: =IF((Q5-Q4<0), "0",Q5-Q4) -> 0 | T5: =IF((S5-S4<0), "0",S5-S4) -> 0 | V5: =IF((U5-U4<0), "",U5-U4) -> 0 | X5: =IF((W5-W4<0), "",W5-W4) -> 0 | Z5: =IF((Y5-Y4<0), "",Y5-Y4) -> 0 | AB5: =IF((AA5-AA4<0), "",AA5-AA4) -> 0 | AD5: =IF((AC5-AC4<0), "",AC5-AC4) -> 0 | AF5: =IF((AE5-AE4<0), "",AE5-AE4) -> 0 | AH5: =IF((AG5-AG4<0), "",AG5-AG4) -> 0 | AJ5: =IF((AI5-AI4<0), "",AI5-AI4) -> 0 | AL5: =IF((AK5-AK4<0), "",AK5-AK4) -> 0 | AN5: =IF((AM5-AM4<0), "",AM5-AM4) -> 0 | AP5: =IF((AO5-AO4<0), "",AO5-AO4) -> 0 | AS5: 0 | AU5: 0 | AV5: 96332 | AW5: =IF((AV5-AV4<0), "",AV5-AV4) -> 14 | AX5: 1348 | AY5: =IF((AX5-AX4<0), "",AX5-AX4) -> 2 | AZ5: 8194967 | BA5: =IF((AZ5-AZ4<0), "",AZ5-AZ4) -> 1340 | BB5: 1877965 | BC5: =IF((BB5-BB4<0), "",BB5-BB4) -> 1051 | BD5: 158 | BE5: 243 | BF5: 18.95 | BH5: =193*(BF5/100) -> 36.5735
A6: 44837 | D6: =IF((C6-C5<0), "0",C6-C5) -> 0 | F6: =IF((E6-E5<0), "0",E6-E5) -> 0 | G6: 13417603 | H6: =IF((G6-G5<0), "0",G6-G5) -> 4148 | J6: =IF((I6-I5<0), "0",I6-I5) -> 0 | L6: =IF((K6-K5<0), "0",K6-K5) -> 0 | N6: =IF((M6-M5<0), "0",M6-M5) -> 0 | P6: =IF((O6-O5<0), "0",O6-O5) -> 0 | R6: =IF((Q6-Q5<0), "0",Q6-Q5) -> 0 | T6: =IF((S6-S5<0), "0",S6-S5) -> 0 | V6: =IF((U6-U5<0), "",U6-U5) -> 0 | X6: =IF((W6-W5<0), "",W6-W5) -> 0 | Z6: =IF((Y6-Y5<0), "",Y6-Y5) -> 0 | AB6: =IF((AA6-AA5<0), "",AA6-AA5) -> 0 | AD6: =IF((AC6-AC5<0), "",AC6-AC5) -> 0 | AF6: =IF((AE6-AE5<0), "",AE6-AE5) -> 0 | AH6: =IF((AG6-AG5<0), "",AG6-AG5) -> 0 | AJ6: =IF((AI6-AI5<0), "",AI6-AI5) -> 0 | AL6: =IF((AK6-AK5<0), "",AK6-AK5) -> 0 | AN6: =IF((AM6-AM5<0), "",AM6-AM5) -> 0 | AP6: =IF((AO6-AO5<0), "",AO6-AO5) -> 0 | AS6: 0 | AU6: 0 | AV6: 96353 | AW6: =IF((AV6-AV5<0), "",AV6-AV5) -> 21 | AX6: 1351 | AY6: =IF((AX6-AX5<0), "",AX6-AX5) -> 3 | AZ6: 8196740 | BA6: =IF((AZ6-AZ5<0), "",AZ6-AZ5) -> 1773 | BB6: 1879276 | BC6: =IF((BB6-BB5<0), "",BB6-BB5) -> 1311 | BD6: 165 | BE6: 233 | BF6: 22.37 | BH6: =193*(BF6/100) -> 43.1741
A7: 44838 | D7: =IF((C7-C6<0), "0",C7-C6) -> 0 | F7: =IF((E7-E6<0), "0",E7-E6) -> 0 | G7: 13421608 | H7: =IF((G7-G6<0), "0",G7-G6) -> 4005 | J7: =IF((I7-I6<0), "0",I7-I6) -> 0 | L7: =IF((K7-K6<0), "0",K7-K6) -> 0 | N7: =IF((M7-M6<0), "0",M7-M6) -> 0 | P7: =IF((O7-O6<0), "0",O7-O6) -> 0 | R7: =IF((Q7-Q6<0), "0",Q7-Q6) -> 0 | T7: =IF((S7-S6<0), "0",S7-S6) -> 0 | V7: =IF((U7-U6<0), "",U7-U6) -> 0 | X7: =IF((W7-W6<0), "",W7-W6) -> 0 | Z7: =IF((Y7-Y6<0), "",Y7-Y6) -> 0 | AB7: =IF((AA7-AA6<0), "",AA7-AA6) -> 0 | AD7: =IF((AC7-AC6<0), "",AC7-AC6) -> 0 | AF7: =IF((AE7-AE6<0), "",AE7-AE6) -> 0 | AH7: =IF((AG7-AG6<0), "",AG7-AG6) -> 0 | AJ7: =IF((AI7-AI6<0), "",AI7-AI6) -> 0 | AL7: =IF((AK7-AK6<0), "",AK7-AK6) -> 0 | AN7: =IF((AM7-AM6<0), "",AM7-AM6) -> 0 | AP7: =IF((AO7-AO6<0), "",AO7-AO6) -> 0 | AS7: 0 | AU7: 0 | AV7: 96371 | AW7: =IF((AV7-AV6<0), "",AV7-AV6) -> 18 | AX7: 1353 | AY7: =IF((AX7-AX6<0), "",AX7-AX6) -> 2 | AZ7: 8198407 | BA7: =IF((AZ7-AZ6<0), "",AZ7-AZ6) -> 1667 | BB7: 1880569 | BC7: =IF((BB7-BB6<0), "",BB7-BB6) -> 1293 | BD7: 180 | BE7: 254 | BF7: 27.63 | BH7: =193*(BF7/100) -> 53.3259
A8: 44839 | D8: =IF((C8-C7<0), "0",C8-C7) -> 0 | F8: =IF((E8-E7<0), "0",E8-E7) -> 0 | G8: 13425254 | H8: =IF((G8-G7<0), "0",G8-G7) -> 3646 | J8: =IF((I8-I7<0), "0",I8-I7) -> 0 | L8: =IF((K8-K7<0), "0",K8-K7) -> 0 | N8: =IF((M8-M7<0), "0",M8-M7) -> 0 | P8: =IF((O8-O7<0), "0",O8-O7) -> 0 | R8: =IF((Q8-Q7<0), "0",Q8-Q7) -> 0 | T8: =IF((S8-S7<0), "0",S8-S7) -> 0 | V8: =IF((U8-U7<0), "",U8-U7) -> 0 | X8: =IF((W8-W7<0), "",W8-W7) -> 0 | Z8: =IF((Y8-Y7<0), "",Y8-Y7) -> 0 | AB8: =IF((AA8-AA7<0), "",AA8-AA7) -> 0 | AD8: =IF((AC8-AC7<0), "",AC8-AC7) -> 0 | AF8: =IF((AE8-AE7<0), "",AE8-AE7) -> 0 | AH8: =IF((AG8-AG7<0), "",AG8-AG7) -> 0 | AJ8: =IF((AI8-AI7<0), "",AI8-AI7) -> 0 | AL8: =IF((AK8-AK7<0), "",AK8-AK7) -> 0 | AN8: =IF((AM8-AM7<0), "",AM8-AM7) -> 0 | AP8: =IF((AO8-AO7<0), "",AO8-AO7) -> 0 | AS8: 0 | AU8: 0 | AV8: 96388 | AW8: =IF((AV8-AV7<0), "",AV8-AV7) -> 17 | AX8: 1354 | AY8: =IF((AX8-AX7<0), "",AX8-AX7) -> 1 | AZ8: 8200061 | BA8: =IF((AZ8-AZ7<0), "",AZ8-AZ7) -> 1654 | BB8: 1881756 | BC8: =IF((BB8-BB7<0), "",BB8-BB7) -> 1187 | BD8: 156 | BE8: 226 | BF8: 26.97 | BH8: =193*(BF8/100) -> 52.0521
A9: 44840 | D9: =IF((C9-C8<0), "0",C9-C8) -> 0 | F9: =IF((E9-E8<0), "0",E9-E8) -> 0 | G9: 13428974 | H9: =IF((G9-G8<0), "0",G9-G8) -> 3720 | J9: =IF((I9-I8<0), "0",I9-I8) -> 0 | L9: =IF((K9-K8<0), "0",K9-K8) -> 0 | N9: =IF((M9-M8<0), "0",M9-M8) -> 0 | P9: =IF((O9-O8<0), "0",O9-O8) -> 0 | R9: =IF((Q9-Q8<0), "0",Q9-Q8) -> 0 | T9: =IF((S9-S8<0), "0",S9-S8) -> 0 | V9: =IF((U9-U8<0), "",U9-U8) -> 0 | X9: =IF((W9-W8<0), "",W9-W8) -> 0 | Z9: =IF((Y9-Y8<0), "",Y9-Y8) -> 0 | AB9: =IF((AA9-AA8<0), "",AA9-AA8) -> 0 | AD9: =IF((AC9-AC8<0), "",AC9-AC8) -> 0 | AF9: =IF((AE9-AE8<0), "",AE9-AE8) -> 0 | AH9: =IF((AG9-AG8<0), "",AG9-AG8) -> 0 | AJ9: =IF((AI9-AI8<0), "",AI9-AI8) -> 0 | AL9: =IF((AK9-AK8<0), "",AK9-AK8) -> 0 | AN9: =IF((AM9-AM8<0), "",AM9-AM8) -> 0 | AP9: =IF((AO9-AO8<0), "",AO9-AO8) -> 0 | AS9: 0 | AU9: 0 | AV9: 96402 | AW9: =IF((AV9-AV8<0), "",AV9-AV8) -> 14 | AX9: 1357 | AY9: =IF((AX9-AX8<0), "",AX9-AX8) -> 3 | AZ9: 8201335 | BA9: =IF((AZ9-AZ8<0), "",AZ9-AZ8) -> 1274 | BB9: 1882998 | BC9: =IF((BB9-BB8<0), "",BB9-BB8) -> 1242 | BD9: 157 | BE9: 241 | BF9: 22.52 | BH9: =193*(BF9/100) -> 43.4636
A10: 44841 | D10: =IF((C10-C9<0), "0",C10-C9) -> 0 | F10: =IF((E10-E9<0), "0",E10-E9) -> 0 | G10: 13432783 | H10: =IF((G10-G9<0), "0",G10-G9) -> 3809 | J10: =IF((I10-I9<0), "0",I10-I9) -> 0 | L10: =IF((K10-K9<0), "0",K10-K9) -> 0 | N10: =IF((M10-M9<0), "0",M10-M9) -> 0 | P10: =IF((O10-O9<0), "0",O10-O9) -> 0 | R10: =IF((Q10-Q9<0), "0",Q10-Q9) -> 0 | T10: =IF((S10-S9<0), "0",S10-S9) -> 0 | V10: =IF((U10-U9<0), "",U10-U9) -> 0 | X10: =IF((W10-W9<0), "",W10-W9) -> 0 | Z10: =IF((Y10-Y9<0), "",Y10-Y9) -> 0 | AB10: =IF((AA10-AA9<0), "",AA10-AA9) -> 0 | AD10: =IF((AC10-AC9<0), "",AC10-AC9) -> 0 | AF10: =IF((AE10-AE9<0), "",AE10-AE9) -> 0 | AH10: =IF((AG10-AG9<0), "",AG10-AG9) -> 0 | AJ10: =IF((AI10-AI9<0), "",AI10-AI9) -> 0 | AL10: =IF((AK10-AK9<0), "",AK10-AK9) -> 0 | AN10: =IF((AM10-AM9<0), "",AM10-AM9) -> 0 | AP10: =IF((AO10-AO9<0), "",AO10-AO9) -> 0 | AS10: 0 | AU10: 0 | AV10: 96418 | AW10: =IF((AV10-AV9<0), "",AV10-AV9) -> 16 | AX10: 1359 | AY10: =IF((AX10-AX9<0), "",AX10-AX9) -> 2 | AZ10: 8203376 | BA10: =IF((AZ10-AZ9<0), "",AZ10-AZ9) -> 2041 | BB10: 1884175 | BC10: =IF((BB10-BB9<0), "",BB10-BB9) -> 1177 | BD10: 162 | BE10: 262 | BF10: 21.19 | BH10: =193*(BF10/100) -> 40.8967
A11: 44842 | D11: =IF((C11-C10<0), "0",C11-C10) -> 0 | F11: =IF((E11-E10<0), "0",E11-E10) -> 0 | G11: 13436316 | H11: =IF((G11-G10<0), "0",G11-G10) -> 3533 | J11: =IF((I11-I10<0), "0",I11-I10) -> 0 | L11: =IF((K11-K10<0), "0",K11-K10) -> 0 | N11: =IF((M11-M10<0), "0",M11-M10) -> 0 | P11: =IF((O11-O10<0), "0",O11-O10) -> 0 | R11: =IF((Q11-Q10<0), "0",Q11-Q10) -> 0 | T11: =IF((S11-S10<0), "0",S11-S10) -> 0 | V11: =IF((U11-U10<0), "",U11-U10) -> 0 | X11: =IF((W11-W10<0), "",W11-W10) -> 0 | Z11: =IF((Y11-Y10<0), "",Y11-Y10) -> 0 | AB11: =IF((AA11-AA10<0), "",AA11-AA10) -> 0 | AD11: =IF((AC11-AC10<0), "",AC11-AC10) -> 0 | AF11: =IF((AE11-AE10<0), "",AE11-AE10) -> 0 | AH11: =IF((AG11-AG10<0), "",AG11-AG10) -> 0 | AJ11: =IF((AI11-AI10<0), "",AI11-AI10) -> 0 | AL11: =IF((AK11-AK10<0), "",AK11-AK10) -> 0 | AN11: =IF((AM11-AM10<0), "",AM11-AM10) -> 0 | AP11: =IF((AO11-AO10<0), "",AO11-AO10) -> 0 | AS11: 0 | AU11: 0 | AV11: 96436 | AW11: =IF((AV11-AV10<0), "",AV11-AV10) -> 18 | AX11: 1361 | AY11: =IF((AX11-AX10<0), "",AX11-AX10) -> 2 | AZ11: 8205096 | BA11: =IF((AZ11-AZ10<0), "",AZ11-AZ10) -> 1720 | BB11: 1885305 | BC11: =IF((BB11-BB10<0), "",BB11-BB10) -> 1130 | BD11: 179 | BE11: 307 | BF11: 22 | BH11: =193*(BF11/100) -> 42.46
