Workbook

Sheet TOTAL
A1: Site Name | B1: Day | C1: Month | D1: Year | E1: Total Electricity Kwh | F1: Electricity Tariff ($/Kwh) | G1: Natual Gas (m3) | H1: Natural Gas $/m3 | I1: Water Utility Supply (m3) m3 | J1: Water Utility Supply (m3) $/m3 | K1: Room Nights | L1: Total Guests | M1: Utilities day cost dh
A2: Mumbai | B2: 1 | C2: 10 | D2: 2022 | E2: =(IF('Daily HLP'!H4>0,'Daily HLP'!H4,0)) -> 25669 | F2: 9.97 | G2: =(IF('Daily HLP'!L4>0,'Daily HLP'!L4,0)) -> 967 | H2: 75 | I2: =(IF('Daily HLP'!O4>0,'Daily HLP'!O4,0)) -> 304 | J2: 100 | K2: =Occupancy!G2 -> 119 | L2: =Occupancy!F2 -> 306 | M2: =E2*F2+G2*H2+#REF!*#REF!+I2*J2 -> #REF!
A3: Mumbai | B3: =B2+1 -> 2 | C3: 10 | D3: 2022 | E3: =(IF('Daily HLP'!H5>0,'Daily HLP'!H5,0)) -> 25669 | F3: 9.97 | G3: =(IF('Daily HLP'!L5>0,'Daily HLP'!L5,0)) -> 1045 | H3: 75 | I3: =(IF('Daily HLP'!O5>0,'Daily HLP'!O5,0)) -> 238 | J3: 100 | K3: =Occupancy!G3 -> 130 | L3: =Occupancy!F3 -> 406 | M3: =E3*F3+G3*H3+#REF!*#REF!+I3*J3 -> #REF!
A4: Mumbai | B4: =B3+1 -> 3 | C4: 10 | D4: 2022 | E4: =(IF('Daily HLP'!H6>0,'Daily HLP'!H6,0)) -> 23596 | F4: 9.97 | G4: =(IF('Daily HLP'!L6>0,'Daily HLP'!L6,0)) -> 981 | H4: 75 | I4: =(IF('Daily HLP'!O6>0,'Daily HLP'!O6,0)) -> 344 | J4: 100 | K4: =Occupancy!G4 -> 140 | L4: =Occupancy!F4 -> 744 | M4: =E4*F4+G4*H4+#REF!*#REF!+I4*J4 -> #REF!
A5: Mumbai | B5: =B4+1 -> 4 | C5: 10 | D5: 2022 | E5: =(IF('Daily HLP'!H7>0,'Daily HLP'!H7,0)) -> 25639 | F5: 9.97 | G5: =(IF('Daily HLP'!L7>0,'Daily HLP'!L7,0)) -> 977 | H5: 75 | I5: =(IF('Daily HLP'!O7>0,'Daily HLP'!O7,0)) -> 291 | J5: 100 | K5: =Occupancy!G5 -> 147 | L5: =Occupancy!F5 -> 534 | M5: =E5*F5+G5*H5+#REF!*#REF!+I5*J5 -> #REF!
A6: Mumbai | B6: =B5+1 -> 5 | C6: 10 | D6: 2022 | E6: =(IF('Daily HLP'!H8>0,'Daily HLP'!H8,0)) -> 24834 | F6: 9.97 | G6: =(IF('Daily HLP'!L8>0,'Daily HLP'!L8,0)) -> 953 | H6: 75 | I6: =(IF('Daily HLP'!O8>0,'Daily HLP'!O8,0)) -> 251 | J6: 100 | K6: =Occupancy!G6 -> 143 | L6: =Occupancy!F6 -> 428 | M6: =E6*F6+G6*H6+#REF!*#REF!+I6*J6 -> #REF!
A7: Mumbai | B7: =B6+1 -> 6 | C7: 10 | D7: 2022 | E7: =(IF('Daily HLP'!H9>0,'Daily HLP'!H9,0)) -> 25510 | F7: 9.97 | G7: =(IF('Daily HLP'!L9>0,'Daily HLP'!L9,0)) -> 1040 | H7: 75 | I7: =(IF('Daily HLP'!O9>0,'Daily HLP'!O9,0)) -> 290 | J7: 100 | K7: =Occupancy!G7 -> 138 | L7: =Occupancy!F7 -> 596 | M7: =E7*F7+G7*H7+#REF!*#REF!+I7*J7 -> #REF!
A8: Mumbai | B8: =B7+1 -> 7 | C8: 10 | D8: 2022 | E8: =(IF('Daily HLP'!H10>0,'Daily HLP'!H10,0)) -> 25534 | F8: 9.97 | G8: =(IF('Daily HLP'!L10>0,'Daily HLP'!L10,0)) -> 1021 | H8: 75 | I8: =(IF('Daily HLP'!O10>0,'Daily HLP'!O10,0)) -> 295 | J8: 100 | K8: =Occupancy!G8 -> 125 | L8: =Occupancy!F8 -> 315 | M8: =E8*F8+G8*H8+#REF!*#REF!+I8*J8 -> #REF!
A9: Mumbai | B9: =B8+1 -> 8 | C9: 10 | D9: 2022 | E9: =(IF('Daily HLP'!H11>0,'Daily HLP'!H11,0)) -> 25069 | F9: 9.97 | G9: =(IF('Daily HLP'!L11>0,'Daily HLP'!L11,0)) -> 1021 | H9: 75 | I9: =(IF('Daily HLP'!O11>0,'Daily HLP'!O11,0)) -> 297 | J9: 100 | K9: =Occupancy!G9 -> 140 | L9: =Occupancy!F9 -> 361 | M9: =E9*F9+G9*H9+#REF!*#REF!+I9*J9 -> #REF!
A10: Mumbai | B10: =B9+1 -> 9 | C10: 10 | D10: 2022 | E10: =(IF('Daily HLP'!H12>0,'Daily HLP'!H12,0)) -> 25853.95 | F10: 9.97 | G10: =(IF('Daily HLP'!L12>0,'Daily HLP'!L12,0)) -> 1093 | H10: 75 | I10: =(IF('Daily HLP'!O12>0,'Daily HLP'!O12,0)) -> 332 | J10: 100 | K10: =Occupancy!G10 -> 125 | L10: =Occupancy!F10 -> 667 | M10: =E10*F10+G10*H10+#REF!*#REF!+I10*J10 -> #REF!
A11: Mumbai | B11: =B10+1 -> 10 | C11: 10 | D11: 2022 | E11: =(IF('Daily HLP'!H13>0,'Daily HLP'!H13,0)) -> 25692.02 | F11: 9.97 | G11: =(IF('Daily HLP'!L13>0,'Daily HLP'!L13,0)) -> 1003.92 | H11: 75 | I11: =(IF('Daily HLP'!O13>0,'Daily HLP'!O13,0)) -> 230 | J11: 100 | K11: =Occupancy!G11 -> 102 | L11: =Occupancy!F11 -> 795 | M11: =E11*F11+G11*H11+#REF!*#REF!+I11*J11 -> #REF!
A12: Mumbai | B12: =B11+1 -> 11 | C12: 10 | D12: 2022 | E12: =(IF('Daily HLP'!H14>0,'Daily HLP'!H14,0)) -> 25252.9 | F12: 9.97 | G12: =(IF('Daily HLP'!L14>0,'Daily HLP'!L14,0)) -> 1018.7 | H12: 75 | I12: =(IF('Daily HLP'!O14>0,'Daily HLP'!O14,0)) -> 335 | J12: 100 | K12: =Occupancy!G12 -> 96 | L12: =Occupancy!F12 -> 363 | M12: =E12*F12+G12*H12+#REF!*#REF!+I12*J12 -> #REF!
A13: Mumbai | B13: =B12+1 -> 12 | C13: 10 | D13: 2022 | E13: =(IF('Daily HLP'!H15>0,'Daily HLP'!H15,0)) -> 24898.2 | F13: 9.97 | G13: =(IF('Daily HLP'!L15>0,'Daily HLP'!L15,0)) -> 1030.01 | H13: 75 | I13: =(IF('Daily HLP'!O15>0,'Daily HLP'!O15,0)) -> 307 | J13: 100 | K13: =Occupancy!G13 -> 123 | L13: =Occupancy!F13 -> 0 | M13: =E13*F13+G13*H13+#REF!*#REF!+I13*J13 -> #REF!
A14: Mumbai | B14: =B13+1 -> 13 | C14: 10 | D14: 2022 | E14: =(IF('Daily HLP'!H16>0,'Daily HLP'!H16,0)) -> 24813.93 | F14: 9.97 | G14: =(IF('Daily HLP'!L16>0,'Daily HLP'!L16,0)) -> 1072.37 | H14: 75 | I14: =(IF('Daily HLP'!O16>0,'Daily HLP'!O16,0)) -> 309 | J14: 100 | K14: =Occupancy!G14 -> 124 | L14: =Occupancy!F14 -> 575 | M14: =E14*F14+G14*H14+#REF!*#REF!+I14*J14 -> #REF!
... A31: Mumbai | B31: =B30+1 -> 30 | C31: 10 | D31: 2022 | E31: =(IF('Daily HLP'!H33>0,'Daily HLP'!H33,0)) -> 26551 | F31: 9.97 | G31: =(IF('Daily HLP'!L33>0,'Daily HLP'!L33,0)) -> 1020.7 | H31: 75 | I31: =(IF('Daily HLP'!O33>0,'Daily HLP'!O33,0)) -> 320 | J31: 100 | K31: =Occupancy!G31 -> 0 | L31: =Occupancy!F31 -> 0 | M31: =E31*F31+G31*H31+#REF!*#REF!+I31*J31 -> #REF!
A32: Mumbai | B32: =B31+1 -> 31 | C32: 10 | D32: 2022 | E32: =(IF('Daily HLP'!H34>0,'Daily HLP'!H34,0)) -> 233466 | F32: 9.97 | G32: =(IF('Daily HLP'!L34>0,'Daily HLP'!L34,0)) -> 967 | H32: 75 | I32: =(IF('Daily HLP'!O34>0,'Daily HLP'!O34,0)) -> 0 | J32: 100 | K32: =Occupancy!G32 -> 0 | L32: =Occupancy!F32 -> 0

Sheet Submetering
A1: Site Name | B1: Day | C1: Month | D1: Year | E1: ='Section Load'!F4 -> HVAC | F1: ='Section Load'!G4 -> Fire & Emergency PP | G1: ='Section Load'!H4 -> Main PP | H1: ='Section Load'!I4 -> Lighting PP | I1: ='Section Load'!J4 -> CH-1+ CH2+CH3+CH4 | J1: ='Section Load'!K4 -> Chilled water Pump | K1: ='Section Load'!L4 -> Ball Room-1 | L1: ='Section Load'!M4 -> Ball Room-2 | ... AL1: ='Section Load'!AM4 -> Cooling Tower | AM1: R.o.plant | AN1: STP Water Prod | AO1: Domestic Zone-1 | AP1: Domestic Zone-2 | AQ1: Domestic Zone-3 | AR1: Flush Zone -1 | AS1: Flush Zone -2 | AT1: Flush Zone -3 | AU1: Swimming pool | AV1: B2 Laundry | AW1: Boiler Feed Water | AX1: cooling tower filling water | AY1: STP flush(new water meter) | AZ1: Garden Water Pump | BA1: Flush Zone 2 pump meter | BB1: Flush Zone 3 Pump Meter (wtp transfer ) | BC1: Flush Tanker-Zone-1 | BD1: Total Domestic Water (Tanker (R.O) +BMC) | BE1: Total Domestic Consumption | BF1: Total STP Consumption | BG1: ='Section Load'!AN4 -> MGL | BH1: ='Section Load'!AO4 -> HWG | BI1: ='Section Load'!AP4 -> Prato | BJ1: ='Section Load'!AQ4 -> BR-1 | BK1: ='Section Load'!AR4 -> SanQi IND | BL1: ='Section Load'!AS4 -> SanQi JPN | BM1: ='Section Load'!AT4 -> Boiler
A2: Mumbai | B2: 1 | C2: 10 | D2: 2022 | E2: =(IF('Section Load'!F5>0,'Section Load'!F5,0)) -> 3617 | F2: =(IF('Section Load'!G5>0,'Section Load'!G5,0)) -> 1067 | G2: =(IF('Section Load'!H5>0,'Section Load'!H5,0)) -> 2230.76 | H2: =(IF('Section Load'!I5>0,'Section Load'!I5,0)) -> 4405 | I2: =(IF('Section Load'!J5>0,'Section Load'!J5,0)) -> 7106 | J2: =(IF('Section Load'!K5>0,'Section Load'!K5,0)) -> 2965 | K2: =(IF('Section Load'!L5>0,'Section Load'!L5,0)) -> 1611 | L2: =(IF('Section Load'!M5>0,'Section Load'!M5,0)) -> 694 | ... AL2: =(IF('Section Load'!AM5>0,'Section Load'!AM5,0)) -> 847 | AM2: =(IF('Water Report'!$D$7>0,'Water Report'!$D$7,0)) -> 98 | AN2: =(IF('Water Report'!$D$8>0,'Water Report'!$D$8,0)) -> 0 | AO2: =(IF('Water Report'!$D$9>0,'Water Report'!$D$9,0)) -> 103 | AP2: =(IF('Water Report'!$D$10>0,'Water Report'!$D$10,0)) -> 9 | AQ2: =(IF('Water Report'!$D$11>0,'Water Report'!$D$11,0)) -> 40 | AR2: =(IF('Water Report'!$D$13>0,'Water Report'!$D$13,0)) -> 26 | AS2: =(IF('Water Report'!$D$14>0,'Water Report'!$D$14,0)) -> 5 | AT2: =(IF('Water Report'!$D$15>0,'Water Report'!$D$15,0)) -> 14 | AU2: =(IF('Water Report'!$D$17>0,'Water Report'!$D$17,0)) -> 1 | AV2: =(IF('Water Report'!$D$18>0,'Water Report'!$D$18,0)) -> 13 | AW2: =(IF('Water Report'!$D$19>0,'Water Report'!$D$19,0)) -> 11 | AX2: =(IF('Water Report'!$D$21>0,'Water Report'!$D$21,0)) -> 0 | AY2: =(IF('Water Report'!$D$22>0,'Water Report'!$D$22,0)) -> 0 | AZ2: =(IF('Water Report'!$D$23>0,'Water Report'!$D$23,0)) -> 0 | BA2: =(IF('Water Report'!$D$14>0,'Water Report'!$D$14,0)) -> 5 | BB2: =(IF('Water Report'!$D$15>0,'Water Report'!$D$15,0)) -> 14 | BC2: =(IF('Water Report'!$D$13>0,'Water Report'!$D$13,0)) -> 26 | BD2: =(IF('Water Report'!$D$24>0,'Water Report'!$D$24,0)) -> 304 | BE2: =(IF('Water Report'!$D$25>0,'Water Report'!$D$25,0)) -> 171 | BF2: =(IF('Water Report'!$D$27>0,'Water Report'!$D$27,0)) -> 26 | BG2: =(IF('Section Load'!AN5>0,'Section Load'!AN5,0)) -> 967 | BH2: =(IF('Section Load'!AO5>0,'Section Load'!AO5,0)) -> 279 | BI2: =(IF('Section Load'!AP5>0,'Section Load'!AP5,0)) -> 0 | BJ2: =(IF('Section Load'!AQ5>0,'Section Load'!AQ5,0)) -> 118 | BK2: =(IF('Section Load'!AR5>0,'Section Load'!AR5,0)) -> 28 | BL2: =(IF('Section Load'!AS5>0,'Section Load'!AS5,0)) -> 0 | BM2: =(IF('Section Load'!AT5>0,'Section Load'!AT5,0)) -> 542
A3: Mumbai | B3: =B2+1 -> 2 | C3: 10 | D3: 2022 | E3: =(IF('Section Load'!F6>0,'Section Load'!F6,0)) -> 3529.1 | F3: =(IF('Section Load'!G6>0,'Section Load'!G6,0)) -> 959.04 | G3: =(IF('Section Load'!H6>0,'Section Load'!H6,0)) -> 2199.71 | H3: =(IF('Section Load'!I6>0,'Section Load'!I6,0)) -> 4057 | I3: =(IF('Section Load'!J6>0,'Section Load'!J6,0)) -> 6160.8 | J3: =(IF('Section Load'!K6>0,'Section Load'!K6,0)) -> 2991.7 | K3: =(IF('Section Load'!L6>0,'Section Load'!L6,0)) -> 1483.4 | L3: =(IF('Section Load'!M6>0,'Section Load'!M6,0)) -> 964.21 | ... AL3: =(IF('Section Load'!AM6>0,'Section Load'!AM6,0)) -> 839.5 | AM3: =(IF('Water Report'!$E$7>0,'Water Report'!$E$7,0)) -> 94 | AN3: =(IF('Water Report'!$E$8>0,'Water Report'!$E$8,0)) -> 0 | AO3: =(IF('Water Report'!$E$9>0,'Water Report'!$E$9,0)) -> 103 | AP3: =(IF('Water Report'!$E$10>0,'Water Report'!$E$10,0)) -> 12 | AQ3: =(IF('Water Report'!$E$11>0,'Water Report'!$E$11,0)) -> 27 | AR3: =(IF('Water Report'!$E$13>0,'Water Report'!$E$13,0)) -> 15 | AS3: =(IF('Water Report'!$E$14>0,'Water Report'!$E$14,0)) -> 4 | AT3: =(IF('Water Report'!$E$15>0,'Water Report'!$E$15,0)) -> 8 | AU3: =(IF('Water Report'!$E$17>0,'Water Report'!$E$17,0)) -> 4 | AV3: =(IF('Water Report'!$E$18>0,'Water Report'!$E$18,0)) -> 12 | AW3: =(IF('Water Report'!$E$19>0,'Water Report'!$E$19,0)) -> 13 | AX3: =(IF('Water Report'!$E$21>0,'Water Report'!$E$21,0)) -> 0 | AY3: =(IF('Water Report'!$E$22>0,'Water Report'!$E$22,0)) -> 0 | AZ3: =(IF('Water Report'!$E$23>0,'Water Report'!$E$23,0)) -> 0 | BA3: =(IF('Water Report'!$E$14>0,'Water Report'!$E$14,0)) -> 4 | BB3: =(IF('Water Report'!$E$15>0,'Water Report'!$E$15,0)) -> 8 | BC3: =(IF('Water Report'!$E$13>0,'Water Report'!$E$13,0)) -> 15 | BD3: =(IF('Water Report'!$E$24>0,'Water Report'!$E$24,0)) -> 238 | BE3: =(IF('Water Report'!$E$25>0,'Water Report'!$E$25,0)) -> 154 | BF3: =(IF('Water Report'!$E$27>0,'Water Report'!$E$27,0)) -> 15 | BG3: =(IF('Section Load'!AN6>0,'Section Load'!AN6,0)) -> 1045 | BH3: =(IF('Section Load'!AO6>0,'Section Load'!AO6,0)) -> 283.21 | BI3: =(IF('Section Load'!AP6>0,'Section Load'!AP6,0)) -> 0.8 | BJ3: =(IF('Section Load'!AQ6>0,'Section Load'!AQ6,0)) -> 110 | BK3: =(IF('Section Load'!AR6>0,'Section Load'!AR6,0)) -> 46 | BL3: =(IF('Section Load'!AS6>0,'Section Load'!AS6,0)) -> 0 | BM3: =(IF('Section Load'!AT6>0,'Section Load'!AT6,0)) -> 605.39
A4: Mumbai | B4: =B3+1 -> 3 | C4: 10 | D4: 2022 | E4: =(IF('Section Load'!F7>0,'Section Load'!F7,0)) -> 3700.57 | F4: =(IF('Section Load'!G7>0,'Section Load'!G7,0)) -> 1017.46 | G4: =(IF('Section Load'!H7>0,'Section Load'!H7,0)) -> 2275.44 | H4: =(IF('Section Load'!I7>0,'Section Load'!I7,0)) -> 4163.9 | I4: =(IF('Section Load'!J7>0,'Section Load'!J7,0)) -> 6605.88 | J4: =(IF('Section Load'!K7>0,'Section Load'!K7,0)) -> 3078.01 | K4: =(IF('Section Load'!L7>0,'Section Load'!L7,0)) -> 1436.43 | L4: =(IF('Section Load'!M7>0,'Section Load'!M7,0)) -> 664.79 | ... AL4: =(IF('Section Load'!AM7>0,'Section Load'!AM7,0)) -> 826.27 | AM4: =(IF('Water Report'!$F$7>0,'Water Report'!$F$7,0)) -> 86 | AN4: =(IF('Water Report'!$F$8>0,'Water Report'!$F$8,0)) -> 0 | AO4: =(IF('Water Report'!$F$9>0,'Water Report'!$G$9,0)) -> 89 | AP4: =(IF('Water Report'!$F$10>0,'Water Report'!$F$10,0)) -> 4 | AQ4: =(IF('Water Report'!$F$11>0,'Water Report'!$F$11,0)) -> 15 | AR4: =(IF('Water Report'!$F$13>0,'Water Report'!$F$13,0)) -> 24 | AS4: =(IF('Water Report'!$F$14>0,'Water Report'!$F$14,0)) -> 1 | AT4: =(IF('Water Report'!$F$15>0,'Water Report'!$F$15,0)) -> 13 | AU4: =(IF('Water Report'!$F$17>0,'Water Report'!$F$17,0)) -> 0 | AV4: =(IF('Water Report'!$F$18>0,'Water Report'!$F$18,0)) -> 12 | AW4: =(IF('Water Report'!$F$19>0,'Water Report'!$F$19,0)) -> 12 | AX4: =(IF('Water Report'!$F$21>0,'Water Report'!$F$21,0)) -> 0 | AY4: =(IF('Water Report'!$F$22>0,'Water Report'!$F$22,0)) -> 0 | AZ4: =(IF('Water Report'!$F$23>0,'Water Report'!$F$23,0)) -> 0 | BA4: =(IF('Water Report'!$F$14>0,'Water Report'!$F$14,0)) -> 1 | BB4: =(IF('Water Report'!$F$15>0,'Water Report'!$F$15,0)) -> 13 | BC4: =(IF('Water Report'!$F$13>0,'Water Report'!$F$13,0)) -> 24 | BD4: =(IF('Water Report'!$F$24>0,'Water Report'!$F$24,0)) -> 344 | BE4: =(IF('Water Report'!$F$25>0,'Water Report'!$F$25,0)) -> 141 | BF4: =(IF('Water Report'!$F$27>0,'Water Report'!$F$27,0)) -> 24 | BG4: =(IF('Section Load'!AN7>0,'Section Load'!AN7,0)) -> 981 | BH4: =(IF('Section Load'!AO7>0,'Section Load'!AO7,0)) -> 288.49 | BI4: =(IF('Section Load'!AP7>0,'Section Load'!AP7,0)) -> 0.2 | BJ4: =(IF('Section Load'!AQ7>0,'Section Load'!AQ7,0)) -> 103 | BK4: =(IF('Section Load'!AR7>0,'Section Load'!AR7,0)) -> 36 | BL4: =(IF('Section Load'!AS7>0,'Section Load'!AS7,0)) -> 0 | BM4: =(IF('Section Load'!AT7>0,'Section Load'!AT7,0)) -> 553.31
A5: Mumbai | B5: =B4+1 -> 4 | C5: 10 | D5: 2022 | E5: =(IF('Section Load'!F8>0,'Section Load'!F8,0)) -> 3962.99 | F5: =(IF('Section Load'!G8>0,'Section Load'!G8,0)) -> 1024.92 | G5: =(IF('Section Load'!H8>0,'Section Load'!H8,0)) -> 2197.64 | H5: =(IF('Section Load'!I8>0,'Section Load'!I8,0)) -> 4052.85 | I5: =(IF('Section Load'!J8>0,'Section Load'!J8,0)) -> 7399.45 | J5: =(IF('Section Load'!K8>0,'Section Load'!K8,0)) -> 3033.32 | K5: =(IF('Section Load'!L8>0,'Section Load'!L8,0)) -> 1415 | L5: =(IF('Section Load'!M8>0,'Section Load'!M8,0)) -> 691.59 | ... AL5: =(IF('Section Load'!AM8>0,'Section Load'!AM8,0)) -> 867.08 | AM5: =(IF('Water Report'!$G$7>0,'Water Report'!$F$7,0)) -> 86 | AN5: =(IF('Water Report'!$G$8>0,'Water Report'!$F$8,0)) -> 0 | AO5: =(IF('Water Report'!$G$9>0,'Water Report'!$H$9,0)) -> 101 | AP5: =(IF('Water Report'!$G$10>0,'Water Report'!$G$10,0)) -> 8 | AQ5: =(IF('Water Report'!$G$11>0,'Water Report'!$G$11,0)) -> 17 | AR5: =(IF('Water Report'!$G$13>0,'Water Report'!$G$13,0)) -> 38 | AS5: =(IF('Water Report'!$G$14>0,'Water Report'!$G$14,0)) -> 3 | AT5: =(IF('Water Report'!$G$15>0,'Water Report'!$G$15,0)) -> 8 | AU5: =(IF('Water Report'!$G$17>0,'Water Report'!$G$17,0)) -> 3 | AV5: =(IF('Water Report'!$G$18>0,'Water Report'!$G$18,0)) -> 12 | AW5: =(IF('Water Report'!$G$19>0,'Water Report'!$G$19,0)) -> 10 | AX5: =(IF('Water Report'!$G$21>0,'Water Report'!$G$21,0)) -> 0 | AY5: =(IF('Water Report'!$G$22>0,'Water Report'!$G$22,0)) -> 0 | AZ5: =(IF('Water Report'!$G$23>0,'Water Report'!$G$23,0)) -> 0 | BA5: =(IF('Water Report'!$G$14>0,'Water Report'!$G$14,0)) -> 3 | BB5: =(IF('Water Report'!$G$15>0,'Water Report'!$G$15,0)) -> 8 | BC5: =(IF('Water Report'!$G$13>0,'Water Report'!$G$13,0)) -> 38 | BD5: =(IF('Water Report'!$G$24>0,'Water Report'!$G$24,0)) -> 291 | BE5: =(IF('Water Report'!$G$25>0,'Water Report'!$G$25,0)) -> 125 | BF5: =(IF('Water Report'!$G$27>0,'Water Report'!$G$27,0)) -> 38 | BG5: =(IF('Section Load'!AN8>0,'Section Load'!AN8,0)) -> 977 | BH5: =(IF('Section Load'!AO8>0,'Section Load'!AO8,0)) -> 281.18 | BI5: =(IF('Section Load'!AP8>0,'Section Load'!AP8,0)) -> 0 | BJ5: =(IF('Section Load'!AQ8>0,'Section Load'!AQ8,0)) -> 84.8 | BK5: =(IF('Section Load'!AR8>0,'Section Load'!AR8,0)) -> 46.8 | BL5: =(IF('Section Load'!AS8>0,'Section Load'!AS8,0)) -> 0 | BM5: =(IF('Section Load'!AT8>0,'Section Load'!AT8,0)) -> 564.42
A6: Mumbai | B6: =B5+1 -> 5 | C6: 10 | D6: 2022 | E6: =(IF('Section Load'!F9>0,'Section Load'!F9,0)) -> 3963.52 | F6: =(IF('Section Load'!G9>0,'Section Load'!G9,0)) -> 1015.43 | G6: =(IF('Section Load'!H9>0,'Section Load'!H9,0)) -> 2219.48 | H6: =(IF('Section Load'!I9>0,'Section Load'!I9,0)) -> 4140.44 | I6: =(IF('Section Load'!J9>0,'Section Load'!J9,0)) -> 6958.74 | J6: =(IF('Section Load'!K9>0,'Section Load'!K9,0)) -> 2755.6 | K6: =(IF('Section Load'!L9>0,'Section Load'!L9,0)) -> 1359.32 | L6: =(IF('Section Load'!M9>0,'Section Load'!M9,0)) -> 638.52 | ... AL6: =(IF('Section Load'!AM9>0,'Section Load'!AM9,0)) -> 866.88 | AM6: =(IF('Water Report'!$H$7>0,'Water Report'!$H$7,0)) -> 80 | AN6: =(IF('Water Report'!$H$8>0,'Water Report'!$H$8,0)) -> 0 | AO6: =(IF('Water Report'!$H$9>0,'Water Report'!$H$9,0)) -> 101 | AP6: =(IF('Water Report'!$H$10>0,'Water Report'!$H$10,0)) -> 6 | AQ6: =(IF('Water Report'!$H$11>0,'Water Report'!$H$11,0)) -> 18 | AR6: =(IF('Water Report'!$H$13>0,'Water Report'!$H$13,0)) -> 44 | AS6: =(IF('Water Report'!$H$14>0,'Water Report'!$H$14,0)) -> 2 | AT6: =(IF('Water Report'!$H$15>0,'Water Report'!$H$15,0)) -> 8 | AU6: =(IF('Water Report'!$H$17>0,'Water Report'!$H$17,0)) -> 1 | AV6: =(IF('Water Report'!$H$18>0,'Water Report'!$H$18,0)) -> 9 | AW6: =(IF('Water Report'!$H$19>0,'Water Report'!$H$19,0)) -> 9 | AX6: =(IF('Water Report'!$H$21>0,'Water Report'!$H$21,0)) -> 0 | AY6: =(IF('Water Report'!$H$22>0,'Water Report'!$H$22,0)) -> 0 | AZ6: =(IF('Water Report'!$H$23>0,'Water Report'!$H$23,0)) -> 0 | BA6: =(IF('Water Report'!$H$14>0,'Water Report'!$H$14,0)) -> 2 | BB6: =(IF('Water Report'!$H$15>0,'Water Report'!$H$15,0)) -> 8 | BC6: =(IF('Water Report'!$H$13>0,'Water Report'!$H$13,0)) -> 44 | BD6: =(IF('Water Report'!$H$24>0,'Water Report'!$H$24,0)) -> 251 | BE6: =(IF('Water Report'!$H$25>0,'Water Report'!$H$25,0)) -> 135 | BF6: =(IF('Water Report'!$H$27>0,'Water Report'!$H$27,0)) -> 44 | BG6: =(IF('Section Load'!AN9>0,'Section Load'!AN9,0)) -> 953 | BH6: =(IF('Section Load'!AO9>0,'Section Load'!AO9,0)) -> 308.72 | BI6: =(IF('Section Load'!AP9>0,'Section Load'!AP9,0)) -> 0 | BJ6: =(IF('Section Load'!AQ9>0,'Section Load'!AQ9,0)) -> 108.2 | BK6: =(IF('Section Load'!AR9>0,'Section Load'!AR9,0)) -> 46.2 | BL6: =(IF('Section Load'!AS9>0,'Section Load'!AS9,0)) -> 0 | BM6: =(IF('Section Load'!AT9>0,'Section Load'!AT9,0)) -> 490.68
A7: Mumbai | B7: =B6+1 -> 6 | C7: 10 | D7: 2022 | E7: =(IF('Section Load'!F10>0,'Section Load'!F10,0)) -> 3669.77 | F7: =(IF('Section Load'!G10>0,'Section Load'!G10,0)) -> 997.15 | G7: =(IF('Section Load'!H10>0,'Section Load'!H10,0)) -> 2197.73 | H7: =(IF('Section Load'!I10>0,'Section Load'!I10,0)) -> 4226.62 | I7: =(IF('Section Load'!J10>0,'Section Load'!J10,0)) -> 5349.13 | J7: =(IF('Section Load'!K10>0,'Section Load'!K10,0)) -> 2958.37 | K7: =(IF('Section Load'!L10>0,'Section Load'!L10,0)) -> 1554.85 | L7: =(IF('Section Load'!M10>0,'Section Load'!M10,0)) -> 638.89 | ... AL7: =(IF('Section Load'!AM10>0,'Section Load'!AM10,0)) -> 844.27 | AM7: =(IF('Water Report'!$I$7>0,'Water Report'!$I$7,0)) -> 76 | AN7: =(IF('Water Report'!$I$8>0,'Water Report'!$I$8,0)) -> 0 | AO7: =(IF('Water Report'!$I$9>0,'Water Report'!$I$9,0)) -> 89 | AP7: =(IF('Water Report'!$I$10>0,'Water Report'!$I$10,0)) -> 11 | AQ7: =(IF('Water Report'!$I$11>0,'Water Report'!$I$11,0)) -> 18 | AR7: =(IF('Water Report'!$I$13>0,'Water Report'!$I$13,0)) -> 37 | AS7: =(IF('Water Report'!$I$14>0,'Water Report'!$I$14,0)) -> 4 | AT7: =(IF('Water Report'!$I$15>0,'Water Report'!$I$15,0)) -> 7 | AU7: =(IF('Water Report'!$I$17>0,'Water Report'!$I$17,0)) -> 1 | AV7: =(IF('Water Report'!$I$18>0,'Water Report'!$I$18,0)) -> 14 | AW7: =(IF('Water Report'!$I$19>0,'Water Report'!$I$19,0)) -> 12 | AX7: =(IF('Water Report'!$I$21>0,'Water Report'!$I$21,0)) -> 0 | AY7: =(IF('Water Report'!$I$22>0,'Water Report'!$I$22,0)) -> 0 | AZ7: =(IF('Water Report'!$I$23>0,'Water Report'!$I$23,0)) -> 0 | BA7: =(IF('Water Report'!$I$14>0,'Water Report'!$I$14,0)) -> 4 | BB7: =(IF('Water Report'!$I$15>0,'Water Report'!$I$15,0)) -> 7 | BC7: =(IF('Water Report'!$I$13>0,'Water Report'!$I$13,0)) -> 37 | BD7: =(IF('Water Report'!$I$24>0,'Water Report'!$I$24,0)) -> 290 | BE7: =(IF('Water Report'!$I$25>0,'Water Report'!$I$25,0)) -> 129 | BF7: =(IF('Water Report'!$I$27>0,'Water Report'!$I$27,0)) -> 37 | BG7: =(IF('Section Load'!AN10>0,'Section Load'!AN10,0)) -> 1040 | BH7: =(IF('Section Load'!AO10>0,'Section Load'!AO10,0)) -> 298.4 | BI7: =(IF('Section Load'!AP10>0,'Section Load'!AP10,0)) -> 0 | BJ7: =(IF('Section Load'!AQ10>0,'Section Load'!AQ10,0)) -> 112 | BK7: =(IF('Section Load'!AR10>0,'Section Load'!AR10,0)) -> 49 | BL7: =(IF('Section Load'!AS10>0,'Section Load'!AS10,0)) -> 0.4 | BM7: =(IF('Section Load'!AT10>0,'Section Load'!AT10,0)) -> 580.2
A8: Mumbai | B8: =B7+1 -> 7 | C8: 10 | D8: 2022 | E8: =(IF('Section Load'!F11>0,'Section Load'!F11,0)) -> 3706 | F8: =(IF('Section Load'!G11>0,'Section Load'!G11,0)) -> 1011 | G8: =(IF('Section Load'!H11>0,'Section Load'!H11,0)) -> 2277 | H8: =(IF('Section Load'!I11>0,'Section Load'!I11,0)) -> 4329 | I8: =(IF('Section Load'!J11>0,'Section Load'!J11,0)) -> 5136 | J8: =(IF('Section Load'!K11>0,'Section Load'!K11,0)) -> 2960 | K8: =(IF('Section Load'!L11>0,'Section Load'!L11,0)) -> 1624 | L8: =(IF('Section Load'!M11>0,'Section Load'!M11,0)) -> 855 | ... AL8: =(IF('Section Load'!AM11>0,'Section Load'!AM11,0)) -> 841 | AM8: =(IF('Water Report'!$J$7>0,'Water Report'!$J$7,0)) -> 96 | AN8: =(IF('Water Report'!$J$8>0,'Water Report'!$J$8,0)) -> 0 | AO8: =(IF('Water Report'!$J$9>0,'Water Report'!$J$9,0)) -> 103 | AP8: =(IF('Water Report'!$J$10>0,'Water Report'!$J$10,0)) -> 17 | AQ8: =(IF('Water Report'!$J$11>0,'Water Report'!$J$11,0)) -> 20 | AR8: =(IF('Water Report'!$J$13>0,'Water Report'!$J$13,0)) -> 16 | AS8: =(IF('Water Report'!$J$14>0,'Water Report'!$J$14,0)) -> 1 | AT8: =(IF('Water Report'!$J$15>0,'Water Report'!$J$15,0)) -> 8 | AU8: =(IF('Water Report'!$J$17>0,'Water Report'!$J$17,0)) -> 0 | AV8: =(IF('Water Report'!$J$18>0,'Water Report'!$J$18,0)) -> 12 | AW8: =(IF('Water Report'!$J$19>0,'Water Report'!$J$19,0)) -> 9 | AX8: =(IF('Water Report'!$J$21>0,'Water Report'!$J$21,0)) -> 0 | AY8: =(IF('Water Report'!$J$22>0,'Water Report'!$J$22,0)) -> 0 | AZ8: =(IF('Water Report'!$J$23>0,'Water Report'!$J$23,0)) -> 0 | BA8: =(IF('Water Report'!$J$14>0,'Water Report'!$J$14,0)) -> 1 | BB8: =(IF('Water Report'!$J$15>0,'Water Report'!$J$15,0)) -> 8 | BC8: =(IF('Water Report'!$J$13>0,'Water Report'!$J$13,0)) -> 16 | BD8: =(IF('Water Report'!$J$24>0,'Water Report'!$J$24,0)) -> 295 | BE8: =(IF('Water Report'!$J$25>0,'Water Report'!$J$25,0)) -> 149 | BF8: =(IF('Water Report'!$J$27>0,'Water Report'!$J$27,0)) -> 16 | BG8: =(IF('Section Load'!AN11>0,'Section Load'!AN11,0)) -> 1021 | BH8: =(IF('Section Load'!AO11>0,'Section Load'!AO11,0)) -> 301 | BI8: =(IF('Section Load'!AP11>0,'Section Load'!AP11,0)) -> 0 | BJ8: =(IF('Section Load'!AQ11>0,'Section Load'!AQ11,0)) -> 116 | BK8: =(IF('Section Load'!AR11>0,'Section Load'!AR11,0)) -> 51 | BL8: =(IF('Section Load'!AS11>0,'Section Load'!AS11,0)) -> 0 | BM8: =(IF('Section Load'!AT11>0,'Section Load'!AT11,0)) -> 553
A9: Mumbai | B9: =B8+1 -> 8 | C9: 10 | D9: 2022 | E9: =(IF('Section Load'!F12>0,'Section Load'!F12,0)) -> 3651.05 | F9: =(IF('Section Load'!G12>0,'Section Load'!G12,0)) -> 1068 | G9: =(IF('Section Load'!H12>0,'Section Load'!H12,0)) -> 2310 | H9: =(IF('Section Load'!I12>0,'Section Load'!I12,0)) -> 4330.19 | I9: =(IF('Section Load'!J12>0,'Section Load'!J12,0)) -> 7147.63 | J9: =(IF('Section Load'!K12>0,'Section Load'!K12,0)) -> 3052 | K9: =(IF('Section Load'!L12>0,'Section Load'!L12,0)) -> 1247 | L9: =(IF('Section Load'!M12>0,'Section Load'!M12,0)) -> 863 | ... AL9: =(IF('Section Load'!AM12>0,'Section Load'!AM12,0)) -> 775 | AM9: =(IF('Water Report'!$K$7>0,'Water Report'!$K$7,0)) -> 102 | AN9: =(IF('Water Report'!$K$8>0,'Water Report'!$K$8,0)) -> 0 | AO9: =(IF('Water Report'!$K$9>0,'Water Report'!$K$9,0)) -> 108 | AP9: =(IF('Water Report'!$K$10>0,'Water Report'!$K$10,0)) -> 26 | AQ9: =(IF('Water Report'!$K$11>0,'Water Report'!$K$11,0)) -> 29 | AR9: =(IF('Water Report'!$K$13>0,'Water Report'!$K$13,0)) -> 25 | AS9: =(IF('Water Report'!$K$14>0,'Water Report'!$K$14,0)) -> 4 | AT9: =(IF('Water Report'!$K$15>0,'Water Report'!$K$15,0)) -> 9 | AU9: =(IF('Water Report'!$K$17>0,'Water Report'!$K$17,0)) -> 0 | AV9: =(IF('Water Report'!$K$18>0,'Water Report'!$K$18,0)) -> 16 | AW9: =(IF('Water Report'!$K$19>0,'Water Report'!$K$19,0)) -> 10 | AX9: =(IF('Water Report'!$K$21>0,'Water Report'!$K$21,0)) -> 0 | AY9: =(IF('Water Report'!$K$22>0,'Water Report'!$K$22,0)) -> 0 | AZ9: =(IF('Water Report'!$K$23>0,'Water Report'!$K$23,0)) -> 0 | BA9: =(IF('Water Report'!$K$14>0,'Water Report'!$K$14,0)) -> 4 | BB9: =(IF('Water Report'!$K$15>0,'Water Report'!$K$15,0)) -> 9 | BC9: =(IF('Water Report'!$K$13>0,'Water Report'!$K$13,0)) -> 25 | BD9: =(IF('Water Report'!$K$24>0,'Water Report'!$K$24,0)) -> 297 | BE9: =(IF('Water Report'!$K$25>0,'Water Report'!$K$25,0)) -> 176 | BF9: =(IF('Water Report'!$K$27>0,'Water Report'!$K$27,0)) -> 25 | BG9: =(IF('Section Load'!AN12>0,'Section Load'!AN12,0)) -> 1021 | BH9: =(IF('Section Load'!AO12>0,'Section Load'!AO12,0)) -> 302 | BI9: =(IF('Section Load'!AP12>0,'Section Load'!AP12,0)) -> 0 | BJ9: =(IF('Section Load'!AQ12>0,'Section Load'!AQ12,0)) -> 110 | BK9: =(IF('Section Load'!AR12>0,'Section Load'!AR12,0)) -> 52 | BL9: =(IF('Section Load'!AS12>0,'Section Load'!AS12,0)) -> 0 | BM9: =(IF('Section Load'!AT12>0,'Section Load'!AT12,0)) -> 557
A10: Mumbai | B10: =B9+1 -> 9 | C10: 10 | D10: 2022 | E10: =(IF('Section Load'!F13>0,'Section Load'!F13,0)) -> 3585.73 | F10: =(IF('Section Load'!G13>0,'Section Load'!G13,0)) -> 1033.59 | G10: =(IF('Section Load'!H13>0,'Section Load'!H13,0)) -> 2271.71 | H10: =(IF('Section Load'!I13>0,'Section Load'!I13,0)) -> 4016.23 | I10: =(IF('Section Load'!J13>0,'Section Load'!J13,0)) -> 6669.65 | J10: =(IF('Section Load'!K13>0,'Section Load'!K13,0)) -> 3267.03 | K10: =(IF('Section Load'!L13>0,'Section Load'!L13,0)) -> 1563.15 | L10: =(IF('Section Load'!M13>0,'Section Load'!M13,0)) -> 858.43 | ... AL10: =(IF('Section Load'!AM13>0,'Section Load'!AM13,0)) -> 876.19 | AM10: =(IF('Water Report'!$L$7>0,'Water Report'!$L$7,0)) -> 106 | AN10: =(IF('Water Report'!$L$8>0,'Water Report'!$L$8,0)) -> 0 | AO10: =(IF('Water Report'!$L$9>0,'Water Report'!$L$9,0)) -> 105 | AP10: =(IF('Water Report'!$L$10>0,'Water Report'!$L$10,0)) -> 12 | AQ10: =(IF('Water Report'!$L$11>0,'Water Report'!$L$11,0)) -> 17 | AR10: =(IF('Water Report'!$L$13>0,'Water Report'!$L$13,0)) -> 32 | AS10: =(IF('Water Report'!$L$14>0,'Water Report'!$L$14,0)) -> 6 | AT10: =(IF('Water Report'!$L$15>0,'Water Report'!$L$15,0)) -> 6 | AU10: =(IF('Water Report'!$L$17>0,'Water Report'!$L$17,0)) -> 0 | AV10: =(IF('Water Report'!$L$18>0,'Water Report'!$L$18,0)) -> 15 | AW10: =(IF('Water Report'!$L$19>0,'Water Report'!$L$19,0)) -> 13 | AX10: =(IF('Water Report'!$L$21>0,'Water Report'!$L$21,0)) -> 0 | AY10: =(IF('Water Report'!$L$22>0,'Water Report'!$L$22,0)) -> 0 | AZ10: =(IF('Water Report'!$L$23>0,'Water Report'!$L$23,0)) -> 0 | BA10: =(IF('Water Report'!$L$14>0,'Water Report'!$L$14,0)) -> 6 | BB10: =(IF('Water Report'!$L$15>0,'Water Report'!$L$15,0)) -> 6 | BC10: =(IF('Water Report'!$L$13>0,'Water Report'!$L$13,0)) -> 32 | BD10: =(IF('Water Report'!$L$24>0,'Water Report'!$L$24,0)) -> 332 | BE10: =(IF('Water Report'!$L$25>0,'Water Report'!$L$25,0)) -> 146 | BF10: =(IF('Water Report'!$L$27>0,'Water Report'!$L$27,0)) -> 32 | BG10: =(IF('Section Load'!AN13>0,'Section Load'!AN13,0)) -> 1093 | BH10: =(IF('Section Load'!AO13>0,'Section Load'!AO13,0)) -> 313.02 | BI10: =(IF('Section Load'!AP13>0,'Section Load'!AP13,0)) -> 0 | BJ10: =(IF('Section Load'!AQ13>0,'Section Load'!AQ13,0)) -> 107.64 | BK10: =(IF('Section Load'!AR13>0,'Section Load'!AR13,0)) -> 53 | BL10: =(IF('Section Load'!AS13>0,'Section Load'!AS13,0)) -> 0 | BM10: =(IF('Section Load'!AT13>0,'Section Load'!AT13,0)) -> 619.34
A11: Mumbai | B11: =B10+1 -> 10 | C11: 10 | D11: 2022 | E11: =(IF('Section Load'!F14>0,'Section Load'!F14,0)) -> 3508.68 | F11: =(IF('Section Load'!G14>0,'Section Load'!G14,0)) -> 1043.56 | G11: =(IF('Section Load'!H14>0,'Section Load'!H14,0)) -> 2128.32 | H11: =(IF('Section Load'!I14>0,'Section Load'!I14,0)) -> 4009.12 | I11: =(IF('Section Load'!J14>0,'Section Load'!J14,0)) -> 5322.59 | J11: =(IF('Section Load'!K14>0,'Section Load'!K14,0)) -> 3088.44 | K11: =(IF('Section Load'!L14>0,'Section Load'!L14,0)) -> 1987.32 | L11: =(IF('Section Load'!M14>0,'Section Load'!M14,0)) -> 777.18 | ... AL11: =(IF('Section Load'!AM14>0,'Section Load'!AM14,0)) -> 860.08 | AM11: =(IF('Water Report'!$M$7>0,'Water Report'!$M$7,0)) -> 75 | AN11: =(IF('Water Report'!$M$8>0,'Water Report'!$M$8,0)) -> 0 | AO11: =(IF('Water Report'!$M$9>0,'Water Report'!$M$9,0)) -> 98 | AP11: =(IF('Water Report'!$M$10>0,'Water Report'!$M$10,0)) -> 11 | AQ11: =(IF('Water Report'!$M$11>0,'Water Report'!$M$11,0)) -> 23 | AR11: =(IF('Water Report'!$M$13>0,'Water Report'!$M$13,0)) -> 49 | AS11: =(IF('Water Report'!$M$14>0,'Water Report'!$M$14,0)) -> 3 | AT11: =(IF('Water Report'!$M$15>0,'Water Report'!$M$15,0)) -> 7 | AU11: =(IF('Water Report'!$M$17>0,'Water Report'!$M$17,0)) -> 2 | AV11: =(IF('Water Report'!$M$18>0,'Water Report'!$M$18,0)) -> 12 | AW11: =(IF('Water Report'!$M$19>0,'Water Report'!$M$19,0)) -> 9 | AX11: =(IF('Water Report'!$M$21>0,'Water Report'!$M$21,0)) -> 0 | AY11: =(IF('Water Report'!$M$22>0,'Water Report'!$M$22,0)) -> 0 | AZ11: =(IF('Water Report'!$M$23>0,'Water Report'!$M$23,0)) -> 0 | BA11: =(IF('Water Report'!$M$14>0,'Water Report'!$M$14,0)) -> 3 | BB11: =(IF('Water Report'!$M$15>0,'Water Report'!$M$15,0)) -> 7 | BC11: =(IF('Water Report'!$M$13>0,'Water Report'!$M$13,0)) -> 49 | BD11: =(IF('Water Report'!$M$24>0,'Water Report'!$M$24,0)) -> 230 | BE11: =(IF('Water Report'!$M$25>0,'Water Report'!$M$25,0)) -> 142 | BF11: =(IF('Water Report'!$M$27>0,'Water Report'!$M$27,0)) -> 49 | BG11: =(IF('Section Load'!AN14>0,'Section Load'!AN14,0)) -> 1003.92 | BH11: =(IF('Section Load'!AO14>0,'Section Load'!AO14,0)) -> 320.62 | BI11: =(IF('Section Load'!AP14>0,'Section Load'!AP14,0)) -> 0 | BJ11: =(IF('Section Load'!AQ14>0,'Section Load'!AQ14,0)) -> 94.79 | BK11: =(IF('Section Load'!AR14>0,'Section Load'!AR14,0)) -> 62.5 | BL11: =(IF('Section Load'!AS14>0,'Section Load'!AS14,0)) -> 0 | BM11: =(IF('Section Load'!AT14>0,'Section Load'!AT14,0)) -> 526.01
A12: Mumbai | B12: =B11+1 -> 11 | C12: 10 | D12: 2022 | E12: =(IF('Section Load'!F15>0,'Section Load'!F15,0)) -> 3486.6 | F12: =(IF('Section Load'!G15>0,'Section Load'!G15,0)) -> 1017.09 | G12: =(IF('Section Load'!H15>0,'Section Load'!H15,0)) -> 2187.64 | H12: =(IF('Section Load'!I15>0,'Section Load'!I15,0)) -> 4276.32 | I12: =(IF('Section Load'!J15>0,'Section Load'!J15,0)) -> 5153.37 | J12: =(IF('Section Load'!K15>0,'Section Load'!K15,0)) -> 2778 | K12: =(IF('Section Load'!L15>0,'Section Load'!L15,0)) -> 1539.8 | L12: =(IF('Section Load'!M15>0,'Section Load'!M15,0)) -> 1047.3 | ... AL12: =(IF('Section Load'!AM15>0,'Section Load'!AM15,0)) -> 879.74 | AM12: =(IF('Water Report'!$N$7>0,'Water Report'!$N$7,0)) -> 107 | AN12: =(IF('Water Report'!$N$8>0,'Water Report'!$N$8,0)) -> 0 | AO12: =(IF('Water Report'!$N$9>0,'Water Report'!$N$9,0)) -> 95 | AP12: =(IF('Water Report'!$N$10>0,'Water Report'!$N$10,0)) -> 11 | AQ12: =(IF('Water Report'!$N$11>0,'Water Report'!$N$11,0)) -> 22 | AR12: =(IF('Water Report'!$N$13>0,'Water Report'!$N$13,0)) -> 25 | AS12: =(IF('Water Report'!$N$14>0,'Water Report'!$N$14,0)) -> 4 | AT12: =(IF('Water Report'!$N$15>0,'Water Report'!$N$15,0)) -> 13 | AU12: =(IF('Water Report'!$N$17>0,'Water Report'!$N$17,0)) -> 2 | AV12: =(IF('Water Report'!$N$18>0,'Water Report'!$N$18,0)) -> 15 | AW12: =(IF('Water Report'!$N$19>0,'Water Report'!$N$19,0)) -> 10 | AX12: =(IF('Water Report'!$N$21>0,'Water Report'!$N$21,0)) -> 3 | AY12: =(IF('Water Report'!$N$22>0,'Water Report'!$N$22,0)) -> 0 | AZ12: =(IF('Water Report'!$N$23>0,'Water Report'!$N$23,0)) -> 0 | BA12: =(IF('Water Report'!$N$14>0,'Water Report'!$N$14,0)) -> 4 | BB12: =(IF('Water Report'!$N$15>0,'Water Report'!$N$15,0)) -> 13 | BC12: =(IF('Water Report'!$N$13>0,'Water Report'!$N$13,0)) -> 25 | BD12: =(IF('Water Report'!$N$24>0,'Water Report'!$N$24,0)) -> 335 | BE12: =(IF('Water Report'!$N$25>0,'Water Report'!$N$25,0)) -> 145 | BF12: =(IF('Water Report'!$N$27>0,'Water Report'!$N$27,0)) -> 28 | BG12: =(IF('Section Load'!AN15>0,'Section Load'!AN15,0)) -> 1018.7 | BH12: =(IF('Section Load'!AO15>0,'Section Load'!AO15,0)) -> 297.17 | BI12: =(IF('Section Load'!AP15>0,'Section Load'!AP15,0)) -> 0 | BJ12: =(IF('Section Load'!AQ15>0,'Section Load'!AQ15,0)) -> 120.74 | BK12: =(IF('Section Load'!AR15>0,'Section Load'!AR15,0)) -> 58.5 | BL12: =(IF('Section Load'!AS15>0,'Section Load'!AS15,0)) -> 0 | BM12: =(IF('Section Load'!AT15>0,'Section Load'!AT15,0)) -> 542.29
A13: Mumbai | B13: =B12+1 -> 12 | C13: 10 | D13: 2022 | E13: =(IF('Section Load'!F16>0,'Section Load'!F16,0)) -> 3468.92 | F13: =(IF('Section Load'!G16>0,'Section Load'!G16,0)) -> 1007.6 | G13: =(IF('Section Load'!H16>0,'Section Load'!H16,0)) -> 2223.4 | H13: =(IF('Section Load'!I16>0,'Section Load'!I16,0)) -> 4336.16 | I13: =(IF('Section Load'!J16>0,'Section Load'!J16,0)) -> 4875.71 | J13: =(IF('Section Load'!K16>0,'Section Load'!K16,0)) -> 2783.44 | K13: =(IF('Section Load'!L16>0,'Section Load'!L16,0)) -> 1507.88 | L13: =(IF('Section Load'!M16>0,'Section Load'!M16,0)) -> 1019.64 | ... AL13: =(IF('Section Load'!AM16>0,'Section Load'!AM16,0)) -> 952.8 | AM13: =(IF('Water Report'!$O$7>0,'Water Report'!$O$7,0)) -> 107 | AN13: =(IF('Water Report'!$O$8>0,'Water Report'!$O$8,0)) -> 0 | AO13: =(IF('Water Report'!$O$9>0,'Water Report'!$O$9,0)) -> 123 | AP13: =(IF('Water Report'!$O$10>0,'Water Report'!$O$10,0)) -> 9 | AQ13: =(IF('Water Report'!$O$11>0,'Water Report'!$O$11,0)) -> 14 | AR13: =(IF('Water Report'!$O$13>0,'Water Report'!$O$13,0)) -> 43 | AS13: =(IF('Water Report'!$O$14>0,'Water Report'!$O$14,0)) -> 6 | AT13: =(IF('Water Report'!$O$15>0,'Water Report'!$O$15,0)) -> 7 | AU13: =(IF('Water Report'!$O$17>0,'Water Report'!$O$17,0)) -> 9 | AV13: =(IF('Water Report'!$O$18>0,'Water Report'!$O$18,0)) -> 15 | AW13: =(IF('Water Report'!$O$19>0,'Water Report'!$O$19,0)) -> 10 | AX13: =(IF('Water Report'!$O$21>0,'Water Report'!$O$21,0)) -> 0 | AY13: =(IF('Water Report'!$O$22>0,'Water Report'!$O$22,0)) -> 0 | AZ13: =(IF('Water Report'!$O$23>0,'Water Report'!$O$23,0)) -> 0 | BA13: =(IF('Water Report'!$O$14>0,'Water Report'!$O$14,0)) -> 6 | BB13: =(IF('Water Report'!$O$15>0,'Water Report'!$O$15,0)) -> 7 | BC13: =(IF('Water Report'!$O$13>0,'Water Report'!$O$13,0)) -> 43 | BD13: =(IF('Water Report'!$O$24>0,'Water Report'!$O$24,0)) -> 307 | BE13: =(IF('Water Report'!$O$25>0,'Water Report'!$O$25,0)) -> 159 | BF13: =(IF('Water Report'!$O$27>0,'Water Report'!$O$27,0)) -> 43 | BG13: =(IF('Section Load'!AN16>0,'Section Load'!AN16,0)) -> 1030.01 | BH13: =(IF('Section Load'!AO16>0,'Section Load'!AO16,0)) -> 292.22 | BI13: =(IF('Section Load'!AP16>0,'Section Load'!AP16,0)) -> 0 | BJ13: =(IF('Section Load'!AQ16>0,'Section Load'!AQ16,0)) -> 128.84 | BK13: =(IF('Section Load'!AR16>0,'Section Load'!AR16,0)) -> 56.5 | BL13: =(IF('Section Load'!AS16>0,'Section Load'!AS16,0)) -> 0 | BM13: =(IF('Section Load'!AT16>0,'Section Load'!AT16,0)) -> 552.85
A14: Mumbai | B14: =B13+1 -> 13 | C14: 10 | D14: 2022 | E14: =(IF('Section Load'!F17>0,'Section Load'!F17,0)) -> 3683.02 | F14: =(IF('Section Load'!G17>0,'Section Load'!G17,0)) -> 989.47 | G14: =(IF('Section Load'!H17>0,'Section Load'!H17,0)) -> 2231.93 | H14: =(IF('Section Load'!I17>0,'Section Load'!I17,0)) -> 4038.17 | I14: =(IF('Section Load'!J17>0,'Section Load'!J17,0)) -> 4786.96 | J14: =(IF('Section Load'!K17>0,'Section Load'!K17,0)) -> 2808.09 | K14: =(IF('Section Load'!L17>0,'Section Load'!L17,0)) -> 2066.85 | L14: =(IF('Section Load'!M17>0,'Section Load'!M17,0)) -> 870.45 | ... AL14: =(IF('Section Load'!AM17>0,'Section Load'!AM17,0)) -> 1033.19 | AM14: =(IF('Water Report'!$P$7>0,'Water Report'!$P$7,0)) -> 100 | AN14: =(IF('Water Report'!$P$8>0,'Water Report'!$P$8,0)) -> 0 | AO14: =(IF('Water Report'!$P$9>0,'Water Report'!$P$9,0)) -> 113 | AP14: =(IF('Water Report'!$P$10>0,'Water Report'!$P$10,0)) -> 9 | AQ14: =(IF('Water Report'!$P$11>0,'Water Report'!$P$11,0)) -> 19 | AR14: =(IF('Water Report'!$P$13>0,'Water Report'!$P$13,0)) -> 30 | AS14: =(IF('Water Report'!$P$14>0,'Water Report'!$P$14,0)) -> 2 | AT14: =(IF('Water Report'!$P$15>0,'Water Report'!$P$15,0)) -> 12 | AU14: =(IF('Water Report'!$P$17>0,'Water Report'!$P$17,0)) -> 0 | AV14: =(IF('Water Report'!$P$18>0,'Water Report'!$P$18,0)) -> 15 | AW14: =(IF('Water Report'!$P$19>0,'Water Report'!$P$19,0)) -> 10 | AX14: =(IF('Water Report'!$P$21>0,'Water Report'!$P$21,0)) -> 0 | AY14: =(IF('Water Report'!$P$22>0,'Water Report'!$P$22,0)) -> 0 | AZ14: =(IF('Water Report'!$P$23>0,'Water Report'!$P$23,0)) -> 0 | BA14: =(IF('Water Report'!$P$14>0,'Water Report'!$P$14,0)) -> 2 | BB14: =(IF('Water Report'!$P$15>0,'Water Report'!$P$15,0)) -> 12 | BC14: =(IF('Water Report'!$P$13>0,'Water Report'!$P$13,0)) -> 30 | BD14: =(IF('Water Report'!$P$24>0,'Water Report'!$P$24,0)) -> 309 | BE14: =(IF('Water Report'!$P$25>0,'Water Report'!$P$25,0)) -> 155 | BF14: =(IF('Water Report'!$P$27>0,'Water Report'!$P$27,0)) -> 30 | BG14: =(IF('Section Load'!AN17>0,'Section Load'!AN17,0)) -> 1072.37 | BH14: =(IF('Section Load'!AO17>0,'Section Load'!AO17,0)) -> 289.97 | BI14: =(IF('Section Load'!AP17>0,'Section Load'!AP17,0)) -> 0 | BJ14: =(IF('Section Load'!AQ17>0,'Section Load'!AQ17,0)) -> 118.99 | BK14: =(IF('Section Load'!AR17>0,'Section Load'!AR17,0)) -> 60.5 | BL14: =(IF('Section Load'!AS17>0,'Section Load'!AS17,0)) -> 0 | BM14: =(IF('Section Load'!AT17>0,'Section Load'!AT17,0)) -> 602.91
A15: Mumbai | B15: =B14+1 -> 14 | C15: 10 | D15: 2022 | E15: =(IF('Section Load'!F18>0,'Section Load'!F18,0)) -> 3733 | F15: =(IF('Section Load'!G18>0,'Section Load'!G18,0)) -> 1049 | G15: =(IF('Section Load'!H18>0,'Section Load'!H18,0)) -> 2349.24 | H15: =(IF('Section Load'!I18>0,'Section Load'!I18,0)) -> 4081.81 | I15: =(IF('Section Load'!J18>0,'Section Load'!J18,0)) -> 5095.09 | J15: =(IF('Section Load'!K18>0,'Section Load'!K18,0)) -> 2926 | K15: =(IF('Section Load'!L18>0,'Section Load'!L18,0)) -> 1895 | L15: =(IF('Section Load'!M18>0,'Section Load'!M18,0)) -> 1103 | ... AL15: =(IF('Section Load'!AM18>0,'Section Load'!AM18,0)) -> 1037 | AM15: =(IF('Water Report'!$Q$7>0,'Water Report'!$Q$7,0)) -> 110 | AN15: =(IF('Water Report'!$Q$8>0,'Water Report'!$Q$8,0)) -> 0 | AO15: =(IF('Water Report'!$Q$9>0,'Water Report'!$Q$9,0)) -> 118 | AP15: =(IF('Water Report'!$Q$10>0,'Water Report'!$Q$10,0)) -> 18 | AQ15: =(IF('Water Report'!$Q$11>0,'Water Report'!$Q$11,0)) -> 16 | AR15: =(IF('Water Report'!$Q$13>0,'Water Report'!$Q$13,0)) -> 38 | AS15: =(IF('Water Report'!$Q$14>0,'Water Report'!$Q$14,0)) -> 2 | AT15: =(IF('Water Report'!$Q$15>0,'Water Report'!$Q$15,0)) -> 6 | AU15: =(IF('Water Report'!$Q$17>0,'Water Report'!$Q$17,0)) -> 0 | AV15: =(IF('Water Report'!$Q$18>0,'Water Report'!$Q$18,0)) -> 12 | AW15: =(IF('Water Report'!$Q$19>0,'Water Report'!$Q$19,0)) -> 12 | AX15: =(IF('Water Report'!$Q$21>0,'Water Report'!$Q$21,0)) -> 0 | AY15: =(IF('Water Report'!$Q$22>0,'Water Report'!$Q$22,0)) -> 0 | AZ15: =(IF('Water Report'!$Q$23>0,'Water Report'!$Q$23,0)) -> 0 | BA15: =(IF('Water Report'!$Q$14>0,'Water Report'!$Q$14,0)) -> 2 | BB15: =(IF('Water Report'!$Q$15>0,'Water Report'!$Q$15,0)) -> 6 | BC15: =(IF('Water Report'!$Q$13>0,'Water Report'!$Q$13,0)) -> 38 | BD15: =(IF('Water Report'!$Q$24>0,'Water Report'!$Q$24,0)) -> 267 | BE15: =(IF('Water Report'!$Q$25>0,'Water Report'!$Q$25,0)) -> 160 | BF15: =(IF('Water Report'!$Q$27>0,'Water Report'!$Q$27,0)) -> 38 | BG15: =(IF('Section Load'!AN18>0,'Section Load'!AN18,0)) -> 1198 | BH15: =(IF('Section Load'!AO18>0,'Section Load'!AO18,0)) -> 297 | BI15: =(IF('Section Load'!AP18>0,'Section Load'!AP18,0)) -> 0 | BJ15: =(IF('Section Load'!AQ18>0,'Section Load'!AQ18,0)) -> 125 | BK15: =(IF('Section Load'!AR18>0,'Section Load'!AR18,0)) -> 53 | BL15: =(IF('Section Load'!AS18>0,'Section Load'!AS18,0)) -> 0 | BM15: =(IF('Section Load'!AT18>0,'Section Load'!AT18,0)) -> 723
A16: Mumbai | B16: =B15+1 -> 15 | C16: 10 | D16: 2022 | E16: =(IF('Section Load'!F19>0,'Section Load'!F19,0)) -> 3550 | F16: =(IF('Section Load'!G19>0,'Section Load'!G19,0)) -> 1047 | G16: =(IF('Section Load'!H19>0,'Section Load'!H19,0)) -> 2442 | H16: =(IF('Section Load'!I19>0,'Section Load'!I19,0)) -> 4192 | I16: =(IF('Section Load'!J19>0,'Section Load'!J19,0)) -> 5793.45 | J16: =(IF('Section Load'!K19>0,'Section Load'!K19,0)) -> 2989 | K16: =(IF('Section Load'!L19>0,'Section Load'!L19,0)) -> 1909 | L16: =(IF('Section Load'!M19>0,'Section Load'!M19,0)) -> 1089 | ... AL16: =(IF('Section Load'!AM19>0,'Section Load'!AM19,0)) -> 896 | AM16: =(IF('Water Report'!$R$7>0,'Water Report'!$R$7,0)) -> 124 | AN16: =(IF('Water Report'!$R$8>0,'Water Report'!$R$8,0)) -> 0 | AO16: =(IF('Water Report'!$R$9>0,'Water Report'!$R$9,0)) -> 133 | AP16: =(IF('Water Report'!$R$10>0,'Water Report'!$R$10,0)) -> 7 | AQ16: =(IF('Water Report'!$R$11>0,'Water Report'!$R$11,0)) -> 22 | AR16: =(IF('Water Report'!$R$13>0,'Water Report'!$R$13,0)) -> 41 | AS16: =(IF('Water Report'!$R$14>0,'Water Report'!$R$14,0)) -> 5 | AT16: =(IF('Water Report'!$R$15>0,'Water Report'!$R$15,0)) -> 23 | AU16: =(IF('Water Report'!$R$17>0,'Water Report'!$R$17,0)) -> 0 | AV16: =(IF('Water Report'!$R$18>0,'Water Report'!$R$18,0)) -> 16 | AW16: =(IF('Water Report'!$R$19>0,'Water Report'!$R$19,0)) -> 12 | AX16: =(IF('Water Report'!$R$21>0,'Water Report'!$R$21,0)) -> 0 | AY16: =(IF('Water Report'!$R$22>0,'Water Report'!$R$22,0)) -> 0 | AZ16: =(IF('Water Report'!$R$23>0,'Water Report'!$R$23,0)) -> 0 | BA16: =(IF('Water Report'!$R$14>0,'Water Report'!$R$14,0)) -> 5 | BB16: =(IF('Water Report'!$R$15>0,'Water Report'!$R$15,0)) -> 23 | BC16: =(IF('Water Report'!$R$13>0,'Water Report'!$R$13,0)) -> 41 | BD16: =(IF('Water Report'!$R$24>0,'Water Report'!$R$24,0)) -> 322 | BE16: =(IF('Water Report'!$R$25>0,'Water Report'!$R$25,0)) -> 190 | BF16: =(IF('Water Report'!$R$27>0,'Water Report'!$R$27,0)) -> 41 | BG16: =(IF('Section Load'!AN19>0,'Section Load'!AN19,0)) -> 917 | BH16: =(IF('Section Load'!AO19>0,'Section Load'!AO19,0)) -> 278 | BI16: =(IF('Section Load'!AP19>0,'Section Load'!AP19,0)) -> 0 | BJ16: =(IF('Section Load'!AQ19>0,'Section Load'!AQ19,0)) -> 129 | BK16: =(IF('Section Load'!AR19>0,'Section Load'!AR19,0)) -> 59 | BL16: =(IF('Section Load'!AS19>0,'Section Load'!AS19,0)) -> 0 | BM16: =(IF('Section Load'!AT19>0,'Section Load'!AT19,0)) -> 451
A17: Mumbai | B17: =B16+1 -> 16 | C17: 10 | D17: 2022 | E17: =(IF('Section Load'!F20>0,'Section Load'!F20,0)) -> 3658.36 | F17: =(IF('Section Load'!G20>0,'Section Load'!G20,0)) -> 996.01 | G17: =(IF('Section Load'!H20>0,'Section Load'!H20,0)) -> 2438.7 | H17: =(IF('Section Load'!I20>0,'Section Load'!I20,0)) -> 4307.47 | I17: =(IF('Section Load'!J20>0,'Section Load'!J20,0)) -> 4009.24 | J17: =(IF('Section Load'!K20>0,'Section Load'!K20,0)) -> 2689.59 | K17: =(IF('Section Load'!L20>0,'Section Load'!L20,0)) -> 1710.9 | L17: =(IF('Section Load'!M20>0,'Section Load'!M20,0)) -> 1115.6 | ... AL17: =(IF('Section Load'!AM20>0,'Section Load'!AM20,0)) -> 850.47 | AM17: =(IF('Water Report'!$S$7>0,'Water Report'!$S$7,0)) -> 125 | AN17: =(IF('Water Report'!$S$8>0,'Water Report'!$S$8,0)) -> 0 | AO17: =(IF('Water Report'!$S$9>0,'Water Report'!$S$9,0)) -> 123 | AP17: =(IF('Water Report'!$S$10>0,'Water Report'!$D$10,0)) -> 9 | AQ17: =(IF('Water Report'!$S$11>0,'Water Report'!$D$11,0)) -> 40 | AR17: =(IF('Water Report'!$S$13>0,'Water Report'!$D$13,0)) -> 26 | AS17: =(IF('Water Report'!$S$14>0,'Water Report'!$D$14,0)) -> 5 | AT17: =(IF('Water Report'!$S$15>0,'Water Report'!$D$15,0)) -> 14 | AU17: =(IF('Water Report'!$S$17>0,'Water Report'!$D$17,0)) -> 1 | AV17: =(IF('Water Report'!$S$18>0,'Water Report'!$D$18,0)) -> 13 | AW17: =(IF('Water Report'!$S$19>0,'Water Report'!$D$19,0)) -> 11 | AX17: =(IF('Water Report'!$S$21>0,'Water Report'!$D$21,0)) -> 0 | AY17: =(IF('Water Report'!$S$22>0,'Water Report'!$D$22,0)) -> 0 | AZ17: =(IF('Water Report'!$S$23>0,'Water Report'!$D$23,0)) -> 0 | BA17: =(IF('Water Report'!$S$14>0,'Water Report'!$D$14,0)) -> 5 | BB17: =(IF('Water Report'!$S$15>0,'Water Report'!$D$15,0)) -> 14 | BC17: =(IF('Water Report'!$S$13>0,'Water Report'!$D$13,0)) -> 26 | BD17: =(IF('Water Report'!$S$24>0,'Water Report'!$D$24,0)) -> 304 | BE17: =(IF('Water Report'!$S$25>0,'Water Report'!$D$25,0)) -> 171 | BF17: =(IF('Water Report'!$S$27>0,'Water Report'!$D$27,0)) -> 26 | BG17: =(IF('Section Load'!AN20>0,'Section Load'!AN20,0)) -> 1098 | BH17: =(IF('Section Load'!AO20>0,'Section Load'!AO20,0)) -> 295.57 | BI17: =(IF('Section Load'!AP20>0,'Section Load'!AP20,0)) -> 0.8 | BJ17: =(IF('Section Load'!AQ20>0,'Section Load'!AQ20,0)) -> 138.3 | BK17: =(IF('Section Load'!AR20>0,'Section Load'!AR20,0)) -> 67 | BL17: =(IF('Section Load'!AS20>0,'Section Load'!AS20,0)) -> 0 | BM17: =(IF('Section Load'!AT20>0,'Section Load'!AT20,0)) -> 597.33
A18: Mumbai | B18: =B17+1 -> 17 | C18: 10 | D18: 2022 | E18: =(IF('Section Load'!F21>0,'Section Load'!F21,0)) -> 3802.68 | F18: =(IF('Section Load'!G21>0,'Section Load'!G21,0)) -> 1050.88 | G18: =(IF('Section Load'!H21>0,'Section Load'!H21,0)) -> 2335.61 | H18: =(IF('Section Load'!I21>0,'Section Load'!I21,0)) -> 4426.04 | I18: =(IF('Section Load'!J21>0,'Section Load'!J21,0)) -> 4623.94 | J18: =(IF('Section Load'!K21>0,'Section Load'!K21,0)) -> 2939.12 | K18: =(IF('Section Load'!L21>0,'Section Load'!L21,0)) -> 1442.69 | L18: =(IF('Section Load'!M21>0,'Section Load'!M21,0)) -> 717.19 | ... AL18: =(IF('Section Load'!AM21>0,'Section Load'!AM21,0)) -> 840.33 | AM18: =(IF('Water Report'!$T$7>0,'Water Report'!$T$7,0)) -> 117 | AN18: =(IF('Water Report'!$T$8>0,'Water Report'!$T$8,0)) -> 0 | AO18: =(IF('Water Report'!$T$9>0,'Water Report'!$T$9,0)) -> 108 | AP18: =(IF('Water Report'!$T$10>0,'Water Report'!$T$10,0)) -> 10 | AQ18: =(IF('Water Report'!$T$11>0,'Water Report'!$T$11,0)) -> 20 | AR18: =(IF('Water Report'!$T$13>0,'Water Report'!$T$13,0)) -> 34 | AS18: =(IF('Water Report'!$T$14>0,'Water Report'!$T$14,0)) -> 7 | AT18: =(IF('Water Report'!$T$15>0,'Water Report'!$T$15,0)) -> 11 | AU18: =(IF('Water Report'!$T$17>0,'Water Report'!$T$17,0)) -> 2 | AV18: =(IF('Water Report'!$T$18>0,'Water Report'!$T$18,0)) -> 12 | AW18: =(IF('Water Report'!$T$19>0,'Water Report'!$T$19,0)) -> 14 | AX18: =(IF('Water Report'!$T$21>0,'Water Report'!$T$21,0)) -> 0 | AY18: =(IF('Water Report'!$T$22>0,'Water Report'!$T$22,0)) -> 0 | AZ18: =(IF('Water Report'!$T$23>0,'Water Report'!$T$23,0)) -> 0 | BA18: =(IF('Water Report'!$T$14>0,'Water Report'!$T$14,0)) -> 7 | BB18: =(IF('Water Report'!$T$15>0,'Water Report'!$T$15,0)) -> 11 | BC18: =(IF('Water Report'!$T$13>0,'Water Report'!$T$13,0)) -> 34 | BD18: =(IF('Water Report'!$T$24>0,'Water Report'!$T$24,0)) -> 302 | BE18: =(IF('Water Report'!$T$25>0,'Water Report'!$T$25,0)) -> 156 | BF18: =(IF('Water Report'!$T$27>0,'Water Report'!$T$27,0)) -> 34 | BG18: =(IF('Section Load'!AN21>0,'Section Load'!AN21,0)) -> 1022 | BH18: =(IF('Section Load'!AO21>0,'Section Load'!AO21,0)) -> 291.03 | BI18: =(IF('Section Load'!AP21>0,'Section Load'!AP21,0)) -> 0 | BJ18: =(IF('Section Load'!AQ21>0,'Section Load'!AQ21,0)) -> 100.9 | BK18: =(IF('Section Load'!AR21>0,'Section Load'!AR21,0)) -> 43 | BL18: =(IF('Section Load'!AS21>0,'Section Load'!AS21,0)) -> 0 | BM18: =(IF('Section Load'!AT21>0,'Section Load'!AT21,0)) -> 588.87
A19: Mumbai | B19: =B18+1 -> 18 | C19: 10 | D19: 2022 | E19: =(IF('Section Load'!F22>0,'Section Load'!F22,0)) -> 3749.26 | F19: =(IF('Section Load'!G22>0,'Section Load'!G22,0)) -> 1041 | G19: =(IF('Section Load'!H22>0,'Section Load'!H22,0)) -> 2281.56 | H19: =(IF('Section Load'!I22>0,'Section Load'!I22,0)) -> 4369.18 | I19: =(IF('Section Load'!J22>0,'Section Load'!J22,0)) -> 5273.78 | J19: =(IF('Section Load'!K22>0,'Section Load'!K22,0)) -> 2706.48 | K19: =(IF('Section Load'!L22>0,'Section Load'!L22,0)) -> 1410.01 | L19: =(IF('Section Load'!M22>0,'Section Load'!M22,0)) -> 713.44 | ... AL19: =(IF('Section Load'!AM22>0,'Section Load'!AM22,0)) -> 855.9 | AM19: =(IF('Water Report'!$U$7>0,'Water Report'!$U$7,0)) -> 104 | AN19: =(IF('Water Report'!$U$8>0,'Water Report'!$U$8,0)) -> 0 | AO19: =(IF('Water Report'!$U$9>0,'Water Report'!$U$9,0)) -> 101 | AP19: =(IF('Water Report'!$U$10>0,'Water Report'!$U$10,0)) -> 9 | AQ19: =(IF('Water Report'!$U$11>0,'Water Report'!$U$11,0)) -> 20 | AR19: =(IF('Water Report'!$U$13>0,'Water Report'!$U$13,0)) -> 42 | AS19: =(IF('Water Report'!$U$14>0,'Water Report'!$U$14,0)) -> 8 | AT19: =(IF('Water Report'!$U$15>0,'Water Report'!$U$15,0)) -> 7 | AU19: =(IF('Water Report'!$U$17>0,'Water Report'!$U$17,0)) -> 1 | AV19: =(IF('Water Report'!$U$18>0,'Water Report'!$U$18,0)) -> 14 | AW19: =(IF('Water Report'!$U$19>0,'Water Report'!$U$19,0)) -> 12 | AX19: =(IF('Water Report'!$U$21>0,'Water Report'!$U$21,0)) -> 0 | AY19: =(IF('Water Report'!$U$22>0,'Water Report'!$U$22,0)) -> 0 | AZ19: =(IF('Water Report'!$U$23>0,'Water Report'!$U$23,0)) -> 0 | BA19: =(IF('Water Report'!$U$14>0,'Water Report'!$U$14,0)) -> 8 | BB19: =(IF('Water Report'!$U$15>0,'Water Report'!$U$15,0)) -> 7 | BC19: =(IF('Water Report'!$U$13>0,'Water Report'!$U$13,0)) -> 42 | BD19: =(IF('Water Report'!$U$24>0,'Water Report'!$U$24,0)) -> 273 | BE19: =(IF('Water Report'!$U$25>0,'Water Report'!$U$25,0)) -> 145 | BF19: =(IF('Water Report'!$U$27>0,'Water Report'!$U$27,0)) -> 42 | BG19: =(IF('Section Load'!AN22>0,'Section Load'!AN22,0)) -> 1031.5 | BH19: =(IF('Section Load'!AO22>0,'Section Load'!AO22,0)) -> 290.1 | BI19: =(IF('Section Load'!AP22>0,'Section Load'!AP22,0)) -> 0 | BJ19: =(IF('Section Load'!AQ22>0,'Section Load'!AQ22,0)) -> 121.8 | BK19: =(IF('Section Load'!AR22>0,'Section Load'!AR22,0)) -> 40 | BL19: =(IF('Section Load'!AS22>0,'Section Load'!AS22,0)) -> 0 | BM19: =(IF('Section Load'!AT22>0,'Section Load'!AT22,0)) -> 579.6
A20: Mumbai | B20: =B19+1 -> 19 | C20: 10 | D20: 2022 | E20: =(IF('Section Load'!F23>0,'Section Load'!F23,0)) -> 4013.7 | F20: =(IF('Section Load'!G23>0,'Section Load'!G23,0)) -> 1043.8 | G20: =(IF('Section Load'!H23>0,'Section Load'!H23,0)) -> 2405.13 | H20: =(IF('Section Load'!I23>0,'Section Load'!I23,0)) -> 4246.5 | I20: =(IF('Section Load'!J23>0,'Section Load'!J23,0)) -> 7428.34 | J20: =(IF('Section Load'!K23>0,'Section Load'!K23,0)) -> 2886.81 | K20: =(IF('Section Load'!L23>0,'Section Load'!L23,0)) -> 1307.4 | L20: =(IF('Section Load'!M23>0,'Section Load'!M23,0)) -> 903.77 | ... AL20: =(IF('Section Load'!AM23>0,'Section Load'!AM23,0)) -> 860.3 | AM20: =(IF('Water Report'!$V$7>0,'Water Report'!$V$7,0)) -> 105 | AN20: =(IF('Water Report'!$V$8>0,'Water Report'!$V$8,0)) -> 0 | AO20: =(IF('Water Report'!$V$9>0,'Water Report'!$V$9,0)) -> 112 | AP20: =(IF('Water Report'!$V$10>0,'Water Report'!$V$10,0)) -> 7 | AQ20: =(IF('Water Report'!$V$11>0,'Water Report'!$V$11,0)) -> 14 | AR20: =(IF('Water Report'!$V$13>0,'Water Report'!$V$13,0)) -> 37 | AS20: =(IF('Water Report'!$V$14>0,'Water Report'!$V$14,0)) -> 10 | AT20: =(IF('Water Report'!$V$15>0,'Water Report'!$V$15,0)) -> 7 | AU20: =(IF('Water Report'!$V$17>0,'Water Report'!$V$17,0)) -> 0 | AV20: =(IF('Water Report'!$V$18>0,'Water Report'!$V$18,0)) -> 12 | AW20: =(IF('Water Report'!$V$19>0,'Water Report'!$V$19,0)) -> 15 | AX20: =(IF('Water Report'!$V$21>0,'Water Report'!$V$21,0)) -> 0 | AY20: =(IF('Water Report'!$V$22>0,'Water Report'!$V$22,0)) -> 0 | AZ20: =(IF('Water Report'!$V$23>0,'Water Report'!$V$23,0)) -> 0 | BA20: =(IF('Water Report'!$V$14>0,'Water Report'!$V$14,0)) -> 10 | BB20: =(IF('Water Report'!$V$15>0,'Water Report'!$V$15,0)) -> 7 | BC20: =(IF('Water Report'!$V$13>0,'Water Report'!$V$13,0)) -> 37 | BD20: =(IF('Water Report'!$V$24>0,'Water Report'!$V$24,0)) -> 303 | BE20: =(IF('Water Report'!$V$25>0,'Water Report'!$V$25,0)) -> 150 | BF20: =(IF('Water Report'!$V$27>0,'Water Report'!$V$27,0)) -> 37 | BG20: =(IF('Section Load'!AN23>0,'Section Load'!AN23,0)) -> 1137.5 | BH20: =(IF('Section Load'!AO23>0,'Section Load'!AO23,0)) -> 289.3 | BI20: =(IF('Section Load'!AP23>0,'Section Load'!AP23,0)) -> 0 | BJ20: =(IF('Section Load'!AQ23>0,'Section Load'!AQ23,0)) -> 116 | BK20: =(IF('Section Load'!AR23>0,'Section Load'!AR23,0)) -> 45 | BL20: =(IF('Section Load'!AS23>0,'Section Load'!AS23,0)) -> 0 | BM20: =(IF('Section Load'!AT23>0,'Section Load'!AT23,0)) -> 687.2
A21: Mumbai | B21: =B20+1 -> 20 | C21: 10 | D21: 2022 | E21: =(IF('Section Load'!F24>0,'Section Load'!F24,0)) -> 3470 | F21: =(IF('Section Load'!G24>0,'Section Load'!G24,0)) -> 1071 | G21: =(IF('Section Load'!H24>0,'Section Load'!H24,0)) -> 2240 | H21: =(IF('Section Load'!I24>0,'Section Load'!I24,0)) -> 4212 | I21: =(IF('Section Load'!J24>0,'Section Load'!J24,0)) -> 8383.7 | J21: =(IF('Section Load'!K24>0,'Section Load'!K24,0)) -> 3030 | K21: =(IF('Section Load'!L24>0,'Section Load'!L24,0)) -> 1305 | L21: =(IF('Section Load'!M24>0,'Section Load'!M24,0)) -> 1055 | ... AL21: =(IF('Section Load'!AM24>0,'Section Load'!AM24,0)) -> 835 | AM21: =(IF('Water Report'!$W$7>0,'Water Report'!$W$7,0)) -> 100 | AN21: =(IF('Water Report'!$W$8>0,'Water Report'!$W$8,0)) -> 0 | AO21: =(IF('Water Report'!$W$9>0,'Water Report'!$W$9,0)) -> 115 | AP21: =(IF('Water Report'!$W$10>0,'Water Report'!$W$10,0)) -> 8 | AQ21: =(IF('Water Report'!$W$11>0,'Water Report'!$W$11,0)) -> 18 | AR21: =(IF('Water Report'!$W$13>0,'Water Report'!$W$13,0)) -> 25 | AS21: =(IF('Water Report'!$W$14>0,'Water Report'!$W$14,0)) -> 7 | AT21: =(IF('Water Report'!$W$15>0,'Water Report'!$W$15,0)) -> 13 | AU21: =(IF('Water Report'!$W$17>0,'Water Report'!$W$17,0)) -> 1 | AV21: =(IF('Water Report'!$W$18>0,'Water Report'!$W$18,0)) -> 13 | AW21: =(IF('Water Report'!$W$19>0,'Water Report'!$W$19,0)) -> 16 | AX21: =(IF('Water Report'!$W$21>0,'Water Report'!$W$21,0)) -> 0 | AY21: =(IF('Water Report'!$W$22>0,'Water Report'!$W$22,0)) -> 0 | AZ21: =(IF('Water Report'!$W$23>0,'Water Report'!$W$23,0)) -> 0 | BA21: =(IF('Water Report'!$W$14>0,'Water Report'!$W$14,0)) -> 7 | BB21: =(IF('Water Report'!$W$15>0,'Water Report'!$W$15,0)) -> 13 | BC21: =(IF('Water Report'!$W$13>0,'Water Report'!$W$13,0)) -> 25 | BD21: =(IF('Water Report'!$W$24>0,'Water Report'!$W$24,0)) -> 341 | BE21: =(IF('Water Report'!$W$25>0,'Water Report'!$W$25,0)) -> 161 | BF21: =(IF('Water Report'!$W$27>0,'Water Report'!$W$27,0)) -> 25 | BG21: =(IF('Section Load'!AN24>0,'Section Load'!AN24,0)) -> 1111 | BH21: =(IF('Section Load'!AO24>0,'Section Load'!AO24,0)) -> 287 | BI21: =(IF('Section Load'!AP24>0,'Section Load'!AP24,0)) -> 0 | BJ21: =(IF('Section Load'!AQ24>0,'Section Load'!AQ24,0)) -> 121 | BK21: =(IF('Section Load'!AR24>0,'Section Load'!AR24,0)) -> 51 | BL21: =(IF('Section Load'!AS24>0,'Section Load'!AS24,0)) -> 0 | BM21: =(IF('Section Load'!AT24>0,'Section Load'!AT24,0)) -> 652
A22: Mumbai | B22: =B21+1 -> 21 | C22: 10 | D22: 2022 | E22: =(IF('Section Load'!F25>0,'Section Load'!F25,0)) -> 3655.55 | F22: =(IF('Section Load'!G25>0,'Section Load'!G25,0)) -> 1102 | G22: =(IF('Section Load'!H25>0,'Section Load'!H25,0)) -> 2256 | H22: =(IF('Section Load'!I25>0,'Section Load'!I25,0)) -> 4287.81 | I22: =(IF('Section Load'!J25>0,'Section Load'!J25,0)) -> 7334 | J22: =(IF('Section Load'!K25>0,'Section Load'!K25,0)) -> 2848 | K22: =(IF('Section Load'!L25>0,'Section Load'!L25,0)) -> 1421 | L22: =(IF('Section Load'!M25>0,'Section Load'!M25,0)) -> 873 | ... AL22: =(IF('Section Load'!AM25>0,'Section Load'!AM25,0)) -> 839 | AM22: =(IF('Water Report'!$X$7>0,'Water Report'!$X$7,0)) -> 110 | AN22: =(IF('Water Report'!$X$8>0,'Water Report'!$X$8,0)) -> 0 | AO22: =(IF('Water Report'!$X$9>0,'Water Report'!$X$9,0)) -> 125 | AP22: =(IF('Water Report'!$X$10>0,'Water Report'!$X$10,0)) -> 7 | AQ22: =(IF('Water Report'!$X$11>0,'Water Report'!$X$11,0)) -> 20 | AR22: =(IF('Water Report'!$X$13>0,'Water Report'!$X$13,0)) -> 28 | AS22: =(IF('Water Report'!$X$14>0,'Water Report'!$X$14,0)) -> 2 | AT22: =(IF('Water Report'!$X$15>0,'Water Report'!$X$15,0)) -> 10 | AU22: =(IF('Water Report'!$X$17>0,'Water Report'!$X$17,0)) -> 0 | AV22: =(IF('Water Report'!$X$18>0,'Water Report'!$X$18,0)) -> 14 | AW22: =(IF('Water Report'!$X$19>0,'Water Report'!$X$19,0)) -> 12 | AX22: =(IF('Water Report'!$X$21>0,'Water Report'!$X$21,0)) -> 0 | AY22: =(IF('Water Report'!$X$22>0,'Water Report'!$X$22,0)) -> 0 | AZ22: =(IF('Water Report'!$X$23>0,'Water Report'!$X$23,0)) -> 0 | BA22: =(IF('Water Report'!$X$14>0,'Water Report'!$X$14,0)) -> 2 | BB22: =(IF('Water Report'!$X$15>0,'Water Report'!$X$15,0)) -> 10 | BC22: =(IF('Water Report'!$X$13>0,'Water Report'!$X$13,0)) -> 28 | BD22: =(IF('Water Report'!$X$24>0,'Water Report'!$X$24,0)) -> 311 | BE22: =(IF('Water Report'!$X$25>0,'Water Report'!$X$25,0)) -> 164 | BF22: =(IF('Water Report'!$X$27>0,'Water Report'!$X$27,0)) -> 28 | BG22: =(IF('Section Load'!AN25>0,'Section Load'!AN25,0)) -> 987 | BH22: =(IF('Section Load'!AO25>0,'Section Load'!AO25,0)) -> 290 | BI22: =(IF('Section Load'!AP25>0,'Section Load'!AP25,0)) -> 0 | BJ22: =(IF('Section Load'!AQ25>0,'Section Load'!AQ25,0)) -> 93 | BK22: =(IF('Section Load'!AR25>0,'Section Load'!AR25,0)) -> 43 | BL22: =(IF('Section Load'!AS25>0,'Section Load'!AS25,0)) -> 0 | BM22: =(IF('Section Load'!AT25>0,'Section Load'!AT25,0)) -> 561
