Workbook

Sheet Info
C6: Electricite | H6: Gas | N6: Eau
F27: =K27-1 -> 44886 | H27: Consommation d'énergie | K27: =TODAY() -> 44887
H29: * Electricite : | J29: =VLOOKUP($K$27,'Consommation mensuel énergie'!B10:X40,14,FALSE) -> #N/A | K29: Kw
H31: * Gaz : | J31: =VLOOKUP(F27,'Consommation mensuel énergie'!B10:X40,21,FALSE) -> #N/A | K31: Kg
H33: * Eau : | J33: =VLOOKUP($K$27,'Consommation mensuel énergie'!B10:X40,5,FALSE) -> #N/A | K33: m3
E35: Tache | G35: 1 er | H35: 2 éme | I35: 3 éme | J35: 4 éme | K35: 5 éme | L35: Total | M35: Pourcentage
E36: PRP | G36: =COUNTA(PRP!C2:C21) -> 0 | H36: =COUNTA(PRP!F2:F47) -> 0 | I36: =COUNTA(PRP!I2:I50) -> 0 | J36: =COUNTA(PRP!L2:L50) -> 0 | K36: =COUNTA(PRP!O2:O23) -> 11 | L36: =COUNTA(PRP!O2:O23,PRP!L2:L50,PRP!I2:I50,PRP!F2:F47,PRP!C2:C21) -> 11 | M36: =L36/186 -> 0.059139785
E37: Rain shower head ( HK ) | G37: =COUNTA('Rain shower Heaad'!C2:C21) -> 18 | H37: =COUNTA('Rain shower Heaad'!F2:F47) -> 46 | I37: =COUNTA('Rain shower Heaad'!I2:I50) -> 49 | J37: =COUNTA('Rain shower Heaad'!L2:L50) -> 32 | K37: =COUNTA('Rain shower Heaad'!O2:O23) -> 19 | L37: =COUNTA('Rain shower Heaad'!O2:O23,'Rain shower Heaad'!L2:L50,'Rain shower Heaad'!I2:I50,'Rain shower Heaad'!F2:F47,'Rain shower Heaad'!C2:C21) -> 164 | M37: =L37/186 -> 0.88172043

Sheet PRP
A1: Chambre | B1: Quantite | C1: Date | D1: Chambre. | E1: Quantite , | F1: Date. | G1: Chambre.. | H1: Quantite.. | I1: Date, | J1: Chambre, | K1: Quantite ,2 | L1: Date., | M1: Chambre,, | N1: Quantite,, | O1: Date,,
A2: 101 | D2: 201 | G2: 301 | J2: 401 | M2: 501
A3: 102 | D3: 202 | G3: 302 | J3: 402 | M3: 502 | O3: 44564
A4: 104 | D4: 203 | G4: 303 | J4: 403 | M4: 504 | O4: 44567
A5: 106 | D5: 204 | G5: 304 | J5: 404 | M5: 505 | O5: 44565
A6: 108 | D6: 205 | G6: 305 | J6: 405 | M6: 506 | O6: 44566
A7: 110 | D7: 206 | G7: 306 | J7: 406 | M7: 507 | O7: 44568
A8: 112 | D8: 207 | G8: 307 | J8: 407 | M8: 508 | O8: 44573
A9: 114 | D9: 208 | G9: 308 | J9: 408 | M9: 509 | O9: 44569
A10: 116 | D10: 209 | G10: 309 | J10: 409 | M10: 510 | O10: 44571
A11: 118 | D11: 210 | G11: 310 | J11: 410 | M11: 511
A12: 132 | D12: 211 | G12: 311 | J12: 411 | M12: 512 | O12: 44572
A13: 134 | D13: 212 | G13: 312 | J13: 412 | M13: 514
A14: 138 | D14: 214 | G14: 314 | J14: 414 | M14: 515 | O14: 44574
A15: 146 | D15: 215 | G15: 315 | J15: 415 | M15: 516 | O15: 44575
A16: 148 | D16: 216 | G16: 316 | J16: 416 | M16: 518
A17: 150 | D17: 217 | G17: 317 | J17: 417 | M17: 519
A18: 152 | D18: 218 | G18: 318 | J18: 418 | M18: 521
A19: 154 | D19: 219 | G19: 319 | J19: 419 | M19: 523
A20: 156 | D20: 221 | G20: 321 | J20: 421 | M20: 525
A21: 158 | D21: 223 | G21: 323 | J21: 423 | M21: 527
D22: 225 | G22: 325 | J22: 425 | M22: 529
D23: 227 | G23: 327 | J23: 427 | M23: 531
D24: 229 | G24: 329 | J24: 429
D25: 231 | G25: 331 | J25: 431
D26: 232 | G26: 332 | J26: 432
D27: 234 | G27: 334 | J27: 434
D28: 238 | G28: 336 | J28: 436
D29: 243 | G29: 338 | J29: 438
D30: 244 | G30: 339 | J30: 439
D31: 245 | G31: 341 | J31: 441
D32: 246 | G32: 343 | J32: 443
D33: 247 | G33: 344 | J33: 444
D34: 248 | G34: 345 | J34: 445
D35: 249 | G35: 346 | J35: 446
... D47: 261 | G47: 358 | J47: 458
G48: 359 | J48: 459
G49: 360 | J49: 460
G50: 361 | J50: 461

Sheet Rain shower Heaad
A1: Chambre | B1: Quantite | C1: Date | D1: Chambre. | E1: Quantite , | F1: Date. | G1: Chambre.. | H1: Quantite.. | I1: Date, | J1: Chambre, | K1: Quantite ,2 | L1: Date., | M1: Chambre,, | N1: Quantite,, | O1: Date,,
A2: 101 | D2: 201 | F2: 44578 | G2: 301 | I2: 44576 | J2: 401 | L2: 44571 | M2: 501
A3: 102 | C3: 44583 | D3: 202 | F3: 44578 | G3: 302 | I3: 44576 | J3: 402 | L3: 44571 | M3: 502 | O3: 44566
A4: 104 | C4: 44583 | D4: 203 | F4: 44578 | G4: 303 | I4: 44576 | J4: 403 | L4: 44568 | M4: 504 | O4: 44570
A5: 106 | C5: 44583 | D5: 204 | F5: 44578 | G5: 304 | I5: 44576 | J5: 404 | L5: 44568 | M5: 505 | O5: 44566
A6: 108 | C6: 44583 | D6: 205 | F6: 44578 | G6: 305 | I6: 44576 | J6: 405 | L6: 44568 | M6: 506 | O6: 44566
A7: 110 | C7: 44583 | D7: 206 | F7: 44578 | G7: 306 | I7: 44576 | J7: 406 | L7: 44569 | M7: 507 | O7: 44566
A8: 112 | C8: 44583 | D8: 207 | F8: 44578 | G8: 307 | I8: 44576 | J8: 407 | L8: 44568 | M8: 508 | O8: 44566
A9: 114 | C9: 44583 | D9: 208 | F9: 44578 | G9: 308 | I9: 44576 | J9: 408 | L9: 44568 | M9: 509 | O9: 44566
A10: 116 | C10: 44583 | D10: 209 | F10: 44580 | G10: 309 | I10: 44576 | J10: 409 | L10: 44569 | M10: 510 | O10: 44570
A11: 118 | C11: 44583 | D11: 210 | F11: 44580 | G11: 310 | I11: 44575 | J11: 410 | L11: 44569 | M11: 511 | O11: 44566
A12: 132 | C12: 44583 | D12: 211 | F12: 44580 | G12: 311 | I12: 44575 | J12: 411 | L12: 44569 | M12: 512 | O12: 44570
A13: 134 | D13: 212 | F13: 44580 | G13: 312 | I13: 44575 | J13: 412 | M13: 514
A14: 138 | C14: 44583 | D14: 214 | F14: 44580 | G14: 314 | I14: 44575 | J14: 414 | M14: 515 | O14: 44566
A15: 146 | C15: 44583 | D15: 215 | F15: 44580 | G15: 315 | I15: 44575 | J15: 415 | L15: 44569 | M15: 516 | O15: 44566
A16: 148 | C16: 44583 | D16: 216 | F16: 44580 | G16: 316 | I16: 44575 | J16: 416 | M16: 518 | O16: 44568
A17: 150 | C17: 44583 | D17: 217 | F17: 44580 | G17: 317 | I17: 44575 | J17: 417 | L17: 44569 | M17: 519
A18: 152 | C18: 44583 | D18: 218 | F18: 44580 | G18: 318 | I18: 44575 | J18: 418 | L18: 44573 | M18: 521 | O18: 44566
A19: 154 | C19: 44583 | D19: 219 | F19: 44580 | G19: 319 | I19: 44575 | J19: 419 | L19: 44569 | M19: 523 | O19: 44566
A20: 156 | C20: 44583 | D20: 221 | F20: 44581 | G20: 321 | I20: 44575 | J20: 421 | L20: 44569 | M20: 525 | O20: 44566
A21: 158 | C21: 44583 | D21: 223 | F21: 44581 | G21: 323 | I21: 44575 | J21: 423 | L21: 44578 | M21: 527 | O21: 44566
D22: 225 | F22: 44581 | G22: 325 | I22: 44575 | J22: 425 | L22: 44578 | M22: 529 | O22: 44566
D23: 227 | F23: 44581 | G23: 327 | I23: 44575 | J23: 427 | M23: 531 | O23: 44566
D24: 229 | F24: 44581 | G24: 329 | I24: 44575 | J24: 429 | L24: 44573
D25: 231 | F25: 44581 | G25: 331 | I25: 44575 | J25: 431 | L25: 44573
D26: 232 | F26: 44581 | G26: 332 | I26: 44575 | J26: 432
D27: 234 | F27: 44581 | G27: 334 | I27: 44574 | J27: 434
D28: 238 | F28: 44581 | G28: 336 | I28: 44574 | J28: 436 | L28: 44571
D29: 243 | F29: 44581 | G29: 338 | I29: 44574 | J29: 438
D30: 244 | F30: 44581 | G30: 339 | I30: 44574 | J30: 439
D31: 245 | F31: 44581 | G31: 341 | I31: 44574 | J31: 441
D32: 246 | F32: 44581 | G32: 343 | I32: 44574 | J32: 443
D33: 247 | F33: 44581 | G33: 344 | I33: 44572 | J33: 444 | L33: 44570
D34: 248 | F34: 44581 | G34: 345 | I34: 44572 | J34: 445
D35: 249 | F35: 44581 | G35: 346 | I35: 44572 | J35: 446 | L35: 44570
D36: 250 | F36: 44581 | G36: 347 | I36: 44572 | J36: 447 | L36: 44570
D37: 251 | F37: 44581 | G37: 348 | I37: 44572 | J37: 448 | L37: 44570
D38: 252 | F38: 44581 | G38: 349 | I38: 44574 | J38: 449
D39: 253 | F39: 44581 | G39: 350 | I39: 44573 | J39: 450
D40: 254 | F40: 44581 | G40: 351 | I40: 44573 | J40: 451
...

Sheet détail
A2: Tache | D2: Statut | E2: Technicien | F2: Description
A3: Contrôle servomoteur E G
A4: Contrôle servomoteur E C
A5: Nettoyage filtre ventilo-convecteur
A6: Nettoyage Batterie V C
A7: Nettoyage filtre a tamis
A8: Nettoyage polinioum
A9: Nettoyage bac de V C
A10: Serrage Boite de raccordement
A11: Serrage armoire Electrique
A12: Serrage armoire INNCOM
A13: Contrôle les vanne froid et chaud
A14: Purge circuit chaude et froid de V C
... A42: Note :

Sheet livraison annuel GAZ
C5: Gaz en KG
C7: Janvier | D7: Février | E7: Mars | F7: avril | G7: Mai | H7: juin | I7: Juillet | J7: aout | K7: Septembre | L7: Octobre | M7: Novembre | N7: Décembre
B8: Année 2015 | L8: 19365 | M8: 21235 | N8: 34053
B9: Année 2016 | C9: 23598 | D9: 28302 | E9: 23000 | F9: 28601 | G9: 24612 | H9: 16695 | I9: 10756 | J9: 14749 | K9: 18297 | L9: 20801 | M9: 22927 | N9: 38265
B10: Année 2017 | C10: 39843 | D10: 27644 | E10: 31207 | F10: 34231 | G10: 21149.42 | H10: 19502 | I10: 22293 | J10: 21244 | K10: 20201 | L10: 21000 | M10: 30135 | N10: 28841
B11: Année 2018 | C11: 33210.62 | D11: 27328.669 | E11: 22296.292 | F11: 18205.006 | G11: 16641.811 | H11: 17087.758 | I11: 13220.239 | J11: 15457.909 | K11: 10651.944 | L11: 13951.846 | M11: 24676.263 | N11: 21781.575
B12: Année 2019 | C12: 26669.535 | D12: 26601.294 | E12: 23114.126 | F12: 20873.811 | G12: 14596.168 | H12: 10659.35 | I12: 18584.299 | J12: 10559.898 | K12: 8546.524 | L12: 17517.306 | M12: 20452.198 | N12: 27341.365
B13: Année 2020 | C13: 30735.958 | D13: 21724.443 | E13: 11128.573 | F13: 4506.022 | G13: 0 | H13: 2998.372 | I13: 8663.559 | J13: 4731.905 | K13: 4832.415 | L13: 13092.221 | M13: 17284.017 | N13: 16432.856
B14: Année 2021 | C14: 16222.314 | D14: 13578.901 | E14: 18500.717 | F14: 11555.476 | G14: 10801.651 | H14: 13800.552 | I14: 9448.469 | J14: 8828.481 | K14: 11498.344 | L14: 11280.396 | M14: 20677.552 | N14: 12106.165
B15: Année 2022
C16: GAZ en DH HT
C18: Janvier | D18: Février | E18: Mars | F18: avril | G18: Mai | H18: juin | I18: Juillet | J18: aout | K18: Septembre | L18: Octobre | M18: Novembre | N18: Décembre
B19: Année 2015 | L19: 222503.85 | M19: 248385.8 | N19: 412790.47
B20: Année 2016 | C20: 281335.36 | D20: 329491.88 | E20: 263166 | F20: 334402.89 | G20: 287763.5 | H20: 200206.44 | I20: 128985.95 | J20: 174687.16 | K20: 221708.41 | L20: 257125.33 | M20: 290283.33 | N20: 491751.17
B21: Année 2017 | C21: 534222.91 | D21: 397841.39 | E21: 463317.85 | F21: 473982.96 | G21: 288617.67 | H21: 262138.08 | I21: 290959.32 | J21: 277268.19 | K21: 269109.64 | L21: 279753.6 | M21: 411233.26 | N21: 393575.46
B22: Année 2018 | C22: 433913.36 | D22: 365261.33 | E22: 291312.2 | F22: 213834.18 | G22: 197886.11 | H22: 143537.17 | I22: 111050.01 | J22: 129846.44 | K22: 97997.885 | L22: 117195.51 | M22: 207280.61 | N22: 182965.23
B23: Année 2019 | C23: 224024.09 | D23: 223450.87 | E23: 209182.84 | F23: 188907.99 | G23: 129176.09 | H23: 94335.247 | I23: 144957.53 | J23: 77405.108 | K23: 62646.876 | L23: 128403.6 | M23: 149916.66 | N23: 217831.39
B24: Année 2020 | C24: 244876.45 | D24: 193260.64 | E24: 87871.212 | F24: 35579.55 | G24: 0 | H24: 23675.145 | I24: 72782.559 | J24: 40462.52 | K24: 41321.981 | L24: 111951.58 | M24: 151252.43 | N24: 147090.49
B25: Année 2021 | C25: 175249.66 | D25: 133357.03 | E25: 160956.24 | F25: 100532.64 | G25: 93974.364 | H25: 120064.8 | I25: 79461.624 | J25: 84841.702 | K25: 114581 | L25: 126919.12 | M25: 216928.2 | N25: 127005.78
B26: Année 2022

Sheet Consommation mensuel énergie
I2: Consommation mensuel Eau /électricité/Gaz
B8: Date | D8: ROOM Nights | E8: Guests | F8: Cons Eau/Hotel | H8: Consommation du jour en DH | K8: date / électr | L8: ELECTRICITE en KWH | O8: total | Q8: Consommation du jour en DH | S8: Cons Elec/Villa | U8: Cons Elec/RIAD | V8: GAZ en Kg | X8: Consommation du jour en DH
L9: creuse 81 | M9: pleine 82 | N9: pointe 83
B10: 44562 | D10: 21 | E10: 40 | F10: ='[1]Suivi EAU-ELEC'!E9 -> 8.8 | H10: =F10*8.79 -> 77.352 | K10: 42278 | L10: ='[1]Suivi EAU-ELEC'!G9 -> 2484 | M10: ='[1]Suivi EAU-ELEC'!I9 -> 3362 | N10: ='[1]Suivi EAU-ELEC'!K9 -> 1521 | O10: =L10+M10+N10 -> 7367 | Q10: =L10*0.6985+M10*0.9514+N10*1.3304 -> 6957.2192 | V10: ='[1]Suvi Gaz'!O4 -> 191.99526 | X10: =V10*11.565 -> 2220.4252
B11: 44563 | D11: 16 | E11: 36 | F11: ='[1]Suivi EAU-ELEC'!E10 -> 35 | H11: =F11*8.79 -> 307.65 | K11: 42279 | L11: ='[1]Suivi EAU-ELEC'!G10 -> 2452 | M11: ='[1]Suivi EAU-ELEC'!I10 -> 3357 | N11: ='[1]Suivi EAU-ELEC'!K10 -> 1493 | O11: =L11+M11+N11 -> 7302 | Q11: =L11*0.6985+M11*0.9514+N14*1.3304 -> 8271.1534 | V11: ='[1]Suvi Gaz'!O5 -> 191.99526 | X11: =V11*11.565 -> 2220.4252
B12: 44564 | D12: 10 | E12: 19 | F12: ='[1]Suivi EAU-ELEC'!E11 -> 53 | H12: =F12*8.79 -> 465.87 | K12: 42280 | L12: ='[1]Suivi EAU-ELEC'!G11 -> 2448 | M12: ='[1]Suivi EAU-ELEC'!I11 -> 3259 | N12: ='[1]Suivi EAU-ELEC'!K11 -> 1482 | O12: =L12+M12+N12 -> 7189 | Q12: =L12*0.6985+M12*0.9514+N12*1.3304 -> 6782.1934 | V12: ='[1]Suvi Gaz'!O6 -> 351.99131 | X12: =V12*11.565 -> 4070.7795
B13: 44565 | D13: 10 | E13: 15 | F13: ='[1]Suivi EAU-ELEC'!E12 -> 42.9 | H13: =F13*8.79 -> 377.091 | K13: 42281 | L13: ='[1]Suivi EAU-ELEC'!G12 -> 2417 | M13: ='[1]Suivi EAU-ELEC'!I12 -> 3239 | N13: ='[1]Suivi EAU-ELEC'!K12 -> 503 | O13: =L13+M13+N13 -> 6159 | Q13: =L13*0.6985+M13*0.9514+N13*1.3304 -> 5439.0503 | V13: ='[1]Suvi Gaz'!O7 -> 384.7164 | X13: =V13*11.565 -> 4449.2452
B14: 44566 | D14: 10 | E14: 15 | F14: ='[1]Suivi EAU-ELEC'!E13 -> 48.4 | H14: =F14*8.79 -> 425.436 | K14: 42282 | L14: ='[1]Suivi EAU-ELEC'!G13 -> 2492 | M14: ='[1]Suivi EAU-ELEC'!I13 -> 3356 | N14: ='[1]Suivi EAU-ELEC'!K13 -> 2529 | O14: =L14+M14+N14 -> 8377 | Q14: =L14*0.6985+M14*0.9514+N14*1.3304 -> 8298.142 | V14: ='[1]Suvi Gaz'!O8 -> 287.99289 | X14: =V14*11.565 -> 3330.6378
B15: 44567 | D15: 9 | E15: 15 | F15: ='[1]Suivi EAU-ELEC'!E14 -> 49.9 | H15: =F15*8.79 -> 438.621 | K15: 42283 | L15: ='[1]Suivi EAU-ELEC'!G14 -> 2531 | M15: ='[1]Suivi EAU-ELEC'!I14 -> 3310 | N15: ='[1]Suivi EAU-ELEC'!K14 -> 1454 | O15: =L15+M15+N15 -> 7295 | Q15: =L15*0.6985+M15*0.9514+N15*1.3304 -> 6851.4391 | V15: ='[1]Suvi Gaz'!O9 -> 127.99684 | X15: =V15*11.565 -> 1480.2835
B16: 44568 | D16: 15 | E16: 30 | F16: ='[1]Suivi EAU-ELEC'!E15 -> 39.8 | H16: =F16*8.79 -> 349.842 | K16: 42284 | L16: ='[1]Suivi EAU-ELEC'!G15 -> 2418 | M16: ='[1]Suivi EAU-ELEC'!I15 -> 3206 | N16: ='[1]Suivi EAU-ELEC'!K15 -> 1462 | O16: =L16+M16+N16 -> 7086 | Q16: =L16*0.6985+M16*0.9514+N16*1.3304 -> 6684.2062 | V16: ='[1]Suvi Gaz'!O10 -> 191.99526 | X16: =V16*11.565 -> 2220.4252
B17: 44569 | D17: 18 | E17: 28 | F17: ='[1]Suivi EAU-ELEC'!E16 -> 41 | H17: =F17*8.79 -> 360.39 | K17: 42285 | L17: ='[1]Suivi EAU-ELEC'!G16 -> 2490 | M17: ='[1]Suivi EAU-ELEC'!I16 -> 3204 | N17: ='[1]Suivi EAU-ELEC'!K16 -> 1522 | O17: =L17+M17+N17 -> 7216 | Q17: =L17*0.6985+M17*0.9514+N17*1.3304 -> 6812.4194 | V17: ='[1]Suvi Gaz'!O11 -> 287.99289 | X17: =V17*11.565 -> 3330.6378
B18: 44570 | D18: 13 | E18: 22 | F18: ='[1]Suivi EAU-ELEC'!E17 -> 49 | H18: =F18*8.79 -> 430.71 | K18: 42286 | L18: ='[1]Suivi EAU-ELEC'!G17 -> 2321 | M18: ='[1]Suivi EAU-ELEC'!I17 -> 3066 | N18: ='[1]Suivi EAU-ELEC'!K17 -> 1463 | O18: =L18+M18+N18 -> 6850 | Q18: =L18*0.6985+M18*0.9514+N18*1.3304 -> 6484.5861 | V18: ='[1]Suvi Gaz'!O12 -> 383.99052 | X18: =V18*11.565 -> 4440.8504
B19: 44571 | D19: 13 | E19: 21 | F19: ='[1]Suivi EAU-ELEC'!E18 -> 43 | H19: =F19*8.79 -> 377.97 | K19: 42287 | L19: ='[1]Suivi EAU-ELEC'!G18 -> 2371 | M19: ='[1]Suivi EAU-ELEC'!I18 -> 3040 | N19: ='[1]Suivi EAU-ELEC'!K18 -> 1420 | O19: =L19+M19+N19 -> 6831 | Q19: =L19*0.6985+M19*0.9514+N19*1.3304 -> 6437.5675 | V19: ='[1]Suvi Gaz'!O13 -> 159.99605 | X19: =V19*11.565 -> 1850.3543
B20: 44572 | D20: 13 | E20: 19 | F20: ='[1]Suivi EAU-ELEC'!E19 -> 45.3 | H20: =F20*8.79 -> 398.187 | K20: 42288 | L20: ='[1]Suivi EAU-ELEC'!G19 -> 2166 | M20: ='[1]Suivi EAU-ELEC'!I19 -> 2940 | N20: ='[1]Suivi EAU-ELEC'!K19 -> 1415 | O20: =L20+M20+N20 -> 6521 | Q20: =L20*0.6985+M20*0.9514+N20*1.3304 -> 6192.583 | V20: ='[1]Suvi Gaz'!O14 -> 127.99684 | X20: =V20*11.565 -> 1480.2835
B21: 44573 | D21: 13 | E21: 17 | F21: ='[1]Suivi EAU-ELEC'!E20 -> 39.6 | H21: =F21*8.79 -> 348.084 | K21: 42289 | L21: ='[1]Suivi EAU-ELEC'!G20 -> 2319 | M21: ='[1]Suivi EAU-ELEC'!I20 -> 2916 | N21: ='[1]Suivi EAU-ELEC'!K20 -> 1376 | O21: =L21+M21+N21 -> 6611 | Q21: =L21*0.6985+M21*0.9514+N21*1.3304 -> 6224.7343 | V21: ='[1]Suvi Gaz'!O15 -> 159.99605 | X21: =V21*11.565 -> 1850.3543
B22: 44574 | D22: 11 | E22: 16 | F22: ='[1]Suivi EAU-ELEC'!E21 -> 43.5 | H22: =F22*8.79 -> 382.365 | K22: 42290 | L22: ='[1]Suivi EAU-ELEC'!G21 -> 2428 | M22: ='[1]Suivi EAU-ELEC'!I21 -> 3035 | N22: ='[1]Suivi EAU-ELEC'!K21 -> 1442 | O22: =L22+M22+N22 -> 6905 | Q22: =L22*0.6985+M22*0.9514+N22*1.3304 -> 6501.8938 | V22: ='[1]Suvi Gaz'!O16 -> 127.99684 | X22: =V22*11.565 -> 1480.2835
B23: 44575 | D23: 18 | E23: 26 | F23: ='[1]Suivi EAU-ELEC'!E22 -> 42.2 | H23: =F23*8.79 -> 370.938 | K23: 42291 | L23: ='[1]Suivi EAU-ELEC'!G22 -> 2101 | M23: ='[1]Suivi EAU-ELEC'!I22 -> 3085 | N23: ='[1]Suivi EAU-ELEC'!K22 -> 1391 | O23: =L23+M23+N23 -> 6577 | Q23: =L23*0.6985+M23*0.9514+N23*1.3304 -> 6253.2039 | V23: ='[1]Suvi Gaz'!O17 -> 255.99368 | X23: =V23*11.565 -> 2960.5669
... B27: 44579 | D27: 4 | E27: 6 | F27: ='[1]Suivi EAU-ELEC'!E26 -> 33.1 | H27: =F27*8.79 -> 290.949 | K27: 42295 | L27: ='[1]Suivi EAU-ELEC'!G26 -> 2159 | M27: ='[1]Suivi EAU-ELEC'!I26 -> 2788 | N27: ='[1]Suivi EAU-ELEC'!K26 -> 1237 | O27: =L27+M27+N27 -> 6184 | Q27: =L27*0.6985+M27*0.9514+N27*1.3304 -> 5806.2695 | V27: ='[1]Suvi Gaz'!O21 -> 191.99526 | X27: =V27*11.565 -> 2220.4252
B28: 44580 | F28: ='[1]Suivi EAU-ELEC'!E27 -> 48.5 | H28: =F28*8.79 -> 426.315 | K28: 42296 | L28: ='[1]Suivi EAU-ELEC'!G27 -> 1993 | M28: ='[1]Suivi EAU-ELEC'!I27 -> 2606 | N28: ='[1]Suivi EAU-ELEC'!K27 -> 1260 | O28: =L28+M28+N28 -> 5859 | Q28: =L28*0.6985+M28*0.9514+N28*1.3304 -> 5547.7629 | V28: =VLOOKUP('Suvi Gaz'!A22,'Suvi Gaz'!A17:P42,15,FALSE) -> 287.99289 | X28: =V28*11.565 -> 3330.6378
B29: 44581 | F29: =VLOOKUP(B29,'Suivi EAU-ELEC'!A21:K40,5,FALSE) -> 43.4 | H29: =F29*8.79 -> 381.486 | K29: 42297 | L29: =VLOOKUP(B29,'Suivi EAU-ELEC'!A20:K40,7,FALSE) -> 2253 | M29: =VLOOKUP(B29,'Suivi EAU-ELEC'!A20:K40,9,FALSE) -> 2560 | N29: =VLOOKUP(B29,'Suivi EAU-ELEC'!A20:K40,11,FALSE) -> 1228 | O29: =L29+M29+N29 -> 6041 | Q29: =L29*0.6985+M29*0.9514+N29*1.3304 -> 5643.0357 | V29: =VLOOKUP('Suvi Gaz'!A23,'Suvi Gaz'!A18:P43,15,FALSE) -> 127.99684 | X29: =V29*11.565 -> 1480.2835
B30: 44582 | F30: =VLOOKUP(B30,'Suivi EAU-ELEC'!A22:K41,5,FALSE) -> 34 | H30: =F30*8.79 -> 298.86 | K30: 42298 | L30: =VLOOKUP(B30,'Suivi EAU-ELEC'!A21:K41,7,FALSE) -> 2039 | M30: =VLOOKUP(B30,'Suivi EAU-ELEC'!A21:K41,9,FALSE) -> 2506 | N30: =VLOOKUP(B30,'Suivi EAU-ELEC'!A21:K41,11,FALSE) -> 1170 | O30: =L30+M30+N30 -> 5715 | Q30: =L30*0.6985+M30*0.9514+N30*1.3304 -> 5365.0179 | V30: =VLOOKUP('Suvi Gaz'!A24,'Suvi Gaz'!A19:P44,15,FALSE) -> 223.99447 | X30: =V30*11.565 -> 2590.496
B31: 44583 | F31: =VLOOKUP(B31,'Suivi EAU-ELEC'!A23:K42,5,FALSE) -> 53 | H31: =F31*8.79 -> 465.87 | K31: 42299 | L31: =VLOOKUP(B31,'Suivi EAU-ELEC'!A22:K42,7,FALSE) -> 2172 | M31: =VLOOKUP(B31,'Suivi EAU-ELEC'!A22:K42,9,FALSE) -> 2617 | N31: =VLOOKUP(B31,'Suivi EAU-ELEC'!A22:K42,11,FALSE) -> 1247 | O31: =L31+M31+N31 -> 6036 | Q31: =L31*0.6985+M31*0.9514+N31*1.3304 -> 5665.9646 | V31: =VLOOKUP('Suvi Gaz'!A25,'Suvi Gaz'!A20:P45,15,FALSE) -> 319.9921 | X31: =V31*11.565 -> 3700.7086
B32: 44584 | F32: =VLOOKUP(B32,'Suivi EAU-ELEC'!A24:K43,5,FALSE) -> 39 | H32: =F32*8.79 -> 342.81 | K32: 42300 | L32: =VLOOKUP(B32,'Suivi EAU-ELEC'!A23:K43,7,FALSE) -> 2103 | M32: =VLOOKUP(B32,'Suivi EAU-ELEC'!A23:K43,9,FALSE) -> 2572 | N32: =VLOOKUP(B32,'Suivi EAU-ELEC'!A23:K43,11,FALSE) -> 1263 | O32: =L32+M32+N32 -> 5938 | Q32: =L32*0.6985+M32*0.9514+N32*1.3304 -> 5596.2415 | V32: =VLOOKUP('Suvi Gaz'!A26,'Suvi Gaz'!A21:P46,15,FALSE) -> 159.99605 | X32: =V32*11.565 -> 1850.3543
B33: 44585 | F33: =VLOOKUP(B33,'Suivi EAU-ELEC'!A25:K44,5,FALSE) -> 38 | H33: =F33*8.79 -> 334.02 | K33: 42301 | L33: =VLOOKUP(B33,'Suivi EAU-ELEC'!A24:K44,7,FALSE) -> 2198 | M33: =VLOOKUP(B33,'Suivi EAU-ELEC'!A24:K44,9,FALSE) -> 2616 | N33: =VLOOKUP(B33,'Suivi EAU-ELEC'!A24:K44,11,FALSE) -> 1256 | O33: =L33+M33+N33 -> 6070 | Q33: =L33*0.6985+M33*0.9514+N33*1.3304 -> 5695.1478 | V33: =VLOOKUP('Suvi Gaz'!A27,'Suvi Gaz'!A22:P47,15,FALSE) -> 0 | X33: =V33*11.565 -> 0
B34: 44586 | F34: =VLOOKUP(B34,'Suivi EAU-ELEC'!A26:K45,5,FALSE) -> 0 | H34: =F34*8.79 -> 0 | K34: 42302 | L34: =VLOOKUP(B34,'Suivi EAU-ELEC'!A25:K45,7,FALSE) -> 0 | M34: =VLOOKUP(B34,'Suivi EAU-ELEC'!A25:K45,9,FALSE) -> 0 | N34: =VLOOKUP(B34,'Suivi EAU-ELEC'!A25:K45,11,FALSE) -> 0 | O34: =L34+M34+N34 -> 0 | Q34: =L34*0.6985+M34*0.9514+N34*1.3304 -> 0 | V34: =VLOOKUP('Suvi Gaz'!A28,'Suvi Gaz'!A23:P48,15,FALSE) -> 0 | X34: =V34*11.565 -> 0
B35: 44587 | F35: =VLOOKUP(B35,'Suivi EAU-ELEC'!A27:K46,5,FALSE) -> 0 | H35: =F35*8.79 -> 0 | K35: 42303 | L35: =VLOOKUP(B35,'Suivi EAU-ELEC'!A26:K46,7,FALSE) -> 0 | M35: =VLOOKUP(B35,'Suivi EAU-ELEC'!A26:K46,9,FALSE) -> 0 | N35: =VLOOKUP(B35,'Suivi EAU-ELEC'!A26:K46,11,FALSE) -> 0 | O35: =L35+M35+N35 -> 0 | Q35: =L35*0.6985+M35*0.9514+N35*1.3304 -> 0 | V35: =VLOOKUP('Suvi Gaz'!A29,'Suvi Gaz'!A24:P49,15,FALSE) -> 0 | X35: =V35*11.565 -> 0
B36: 44588 | F36: =VLOOKUP(B36,'Suivi EAU-ELEC'!A28:K47,5,FALSE) -> 0 | H36: =F36*8.79 -> 0 | K36: 42304 | L36: =VLOOKUP(B36,'Suivi EAU-ELEC'!A27:K47,7,FALSE) -> 0 | M36: =VLOOKUP(B36,'Suivi EAU-ELEC'!A27:K47,9,FALSE) -> 0 | N36: =VLOOKUP(B36,'Suivi EAU-ELEC'!A27:K47,11,FALSE) -> 0 | O36: =L36+M36+N36 -> 0 | Q36: =L36*0.6985+M36*0.9514+N36*1.3304 -> 0 | V36: =VLOOKUP('Suvi Gaz'!A30,'Suvi Gaz'!A25:P50,15,FALSE) -> 0 | X36: =V36*11.565 -> 0
B37: 44589 | F37: =VLOOKUP(B37,'Suivi EAU-ELEC'!A29:K48,5,FALSE) -> 0 | H37: =F37*8.79 -> 0 | L37: =VLOOKUP(B37,'Suivi EAU-ELEC'!A28:K48,7,FALSE) -> 0 | M37: =VLOOKUP(B37,'Suivi EAU-ELEC'!A28:K48,9,FALSE) -> 0 | N37: =VLOOKUP(B37,'Suivi EAU-ELEC'!A28:K48,11,FALSE) -> 0 | O37: =L37+M37+N37 -> 0 | Q37: =L37*0.6985+M37*0.9514+N37*1.3304 -> 0 | V37: =VLOOKUP('Suvi Gaz'!A31,'Suvi Gaz'!A26:P51,15,FALSE) -> 0 | X37: =V37*11.565 -> 0
B38: 44590 | F38: =VLOOKUP(B38,'Suivi EAU-ELEC'!A30:K49,5,FALSE) -> 0 | H38: =F38*8.79 -> 0 | L38: =VLOOKUP(B38,'Suivi EAU-ELEC'!A29:K49,7,FALSE) -> 0 | M38: =VLOOKUP(B38,'Suivi EAU-ELEC'!A29:K49,9,FALSE) -> 0 | N38: =VLOOKUP(B38,'Suivi EAU-ELEC'!A29:K49,11,FALSE) -> 0 | O38: =L38+M38+N38 -> 0 | Q38: =L38*0.6985+M38*0.9514+N38*1.3304 -> 0 | V38: =VLOOKUP('Suvi Gaz'!A32,'Suvi Gaz'!A27:P52,15,FALSE) -> 0 | X38: =V38*11.565 -> 0
B39: 44591 | F39: =VLOOKUP(B39,'Suivi EAU-ELEC'!A31:K50,5,FALSE) -> 0 | H39: =F39*8.79 -> 0 | L39: =VLOOKUP(B39,'Suivi EAU-ELEC'!A30:K50,7,FALSE) -> 0 | M39: =VLOOKUP(B39,'Suivi EAU-ELEC'!A30:K50,9,FALSE) -> 0 | N39: =VLOOKUP(B39,'Suivi EAU-ELEC'!A30:K50,11,FALSE) -> 0 | O39: =L39+M39+N39 -> 0 | Q39: =L39*0.6985+M39*0.9514+N39*1.3304 -> 0 | V39: =VLOOKUP('Suvi Gaz'!A33,'Suvi Gaz'!A28:P53,15,FALSE) -> 0 | X39: =V39*11.565 -> 0
B40: 44592 | F40: =VLOOKUP(B40,'Suivi EAU-ELEC'!A32:K51,5,FALSE) -> 0 | H40: =F40*8.79 -> 0 | L40: =VLOOKUP(B40,'Suivi EAU-ELEC'!A31:K51,7,FALSE) -> 0 | M40: =VLOOKUP(B40,'Suivi EAU-ELEC'!A31:K51,9,FALSE) -> 0 | N40: =VLOOKUP(B40,'Suivi EAU-ELEC'!A31:K51,11,FALSE) -> 0 | O40: =L40+M40+N40 -> 0 | Q40: =L40*0.6985+M40*0.9514+N40*1.3304 -> 0 | V40: =VLOOKUP('Suvi Gaz'!A34,'Suvi Gaz'!A29:P54,15,FALSE) -> 0 | X40: =V40*11.565 -> 0
D41: =SUM(D10:D40) -> 237 | E41: =SUM(E10:E40) -> 383 | F41: =SUM(F10:F40) -> 1002.8 | H41: =SUM(H10:H40) -> 8814.612 | L41: =SUM(L10:L40) -> 54925 | M41: =SUM(M10:M40) -> 71022 | N41: =SUM(N10:N40) -> 33150 | O41: =SUM(O10:O40) -> 159097 | Q41: =SUM(Q10:Q40) -> 151416.5 | S41: =SUM(S10:S40) -> 0 | U41: =SUM(U10:U40) -> 0 | V41: =SUM(V10:V40) -> 5216.5971 | X41: =SUM(X10:X40) -> 60329.946
A43: Désignation | H43: COUTS | I43: Consommations | L43: Consommations /DHs | N43: TOTAL Consommations /DHs
A44: ELECTRICITE / Kw/h | D44: creuse 81 | E44: creuse 81 | F44: creuse 81 | H44: 0.6985 | I44: =L41 -> 54925 | L44: =I44*H44 -> 38365.113 | N44: =L44+L45+L46 -> 150038.2
D45: pleine 82 | E45: pleine 82 | F45: pleine 82 | H45: 0.9514 | I45: =M41 -> 71022 | L45: =I45*H45 -> 67570.331
D46: pointe 83 | E46: pointe 83 | F46: pointe 83 | H46: 1.3304 | I46: =N41 -> 33150 | L46: =I46*H46 -> 44102.76
N47: =N44*1.3 -> 195049.66
A48: EAU HOTEL M3 | H48: 8.79 | I48: =F41 -> 1002.8 | L48: =I48*H48 -> 8814.612 | N48: =L48 -> 8814.612
A49: GAZ Kg | H49: 11.565 | I49: =V41 -> 5216.5971 | L49: =I49*H49 -> 60329.946 | N49: =L49 -> 60329.946

Sheet Suvi Gaz
F1: suivi Gaz JAN 2022
Q2: 803 | T2: 519 | W2: 800 | Z2: 802
B3: Relvé C1 | C3: cons C1 | D3: Relvé C2 | E3: cons C2 | F3: Relvé C3 | G3: cons C3 | H3: Relvé C4 | I3: cons C4 | J3: ∑ des relevés | K3: moyen general % | L3: con.j | M3: ∑ de volume en L | N3: cons./jen L | O3: cons./jen Kg | P3: cons./jen DH | Q3: livraison C1 | R3: %Avant | S3: % Après | T3: livraison C2 | U3: %Avant | V3: % Après | W3: livraison C3 | X3: %Avant | Y3: % Après | Z3: livraison C4 | AA3: %Avant | AB3: % Après | AC3: total livraison litre | AD3: moyen general % Avant L | AE3: moyen general % Aaprés L
A4: 44562 | B4: 71 | C4: =IF(AC4>0,((B4-R4)+(S4-B5)),IF(B5=0, ,(B4-B5))) -> 1 | D4: 72 | E4: =IF(AC4>0,((D4-U4)+(V4-D5)),IF(D5=0, ,(D4-D5))) -> 2 | F4: 75 | G4: =IF(AC4>0,((F4-X4)+(Y4-F5)),IF(F5=0, ,(F4-F5))) -> 1 | H4: 73 | I4: =IF(AC4>0,((H4-AA4)+(AB4-H5)),IF(H5=0, ,(H4-H5))) -> 2 | J4: =B4+D4+F4+H4 -> 291 | K4: =J4/4 -> 72.75 | L4: =IF(AC4>0,((K4-AD4)+(AE4-K5)),IF(K5=0, ,(K4-K5))) -> 1.5 | M4: =6049*4 -> 24196 | N4: =L4*M4/100 -> 362.94 | O4: =N4*0.529 -> 191.99526 | P4: =O4*11.565 -> 2220.4252 | AC4: =Q4+T4+W4+Z4 -> 0 | AD4: =(R4+U4+X4+AA4)/4 -> 0 | AE4: =(S4+V4+Y4+AB4)/4 -> 0
A5: 44563 | B5: 70 | C5: =IF(AC5>0,((B5-R5)+(S5-B6)),IF(B6=0, ,(B5-B6))) -> 1 | D5: 70 | E5: =IF(AC5>0,((D5-U5)+(V5-D6)),IF(D6=0, ,(D5-D6))) -> 2 | F5: 74 | G5: =IF(AC5>0,((F5-X5)+(Y5-F6)),IF(F6=0, ,(F5-F6))) -> 1 | H5: 71 | I5: =IF(AC5>0,((H5-AA5)+(AB5-H6)),IF(H6=0, ,(H5-H6))) -> 2 | J5: =B5+D5+F5+H5 -> 285 | K5: =J5/4 -> 71.25 | L5: =IF(AC5>0,((K5-AD5)+(AE5-K6)),IF(K6=0, ,(K5-K6))) -> 1.5 | M5: =6049*4 -> 24196 | N5: =L5*M5/100 -> 362.94 | O5: =N5*0.529 -> 191.99526 | P5: =O5*11.565 -> 2220.4252 | AC5: =Q5+T5+W5+Z5 -> 0 | AD5: =(R5+U5+X5+AA5)/4 -> 0 | AE5: =(S5+V5+Y5+AB5)/4 -> 0
A6: 44564 | B6: 69 | C6: =IF(AC6>0,((B6-R6)+(S6-B7)),IF(B7=0, ,(B6-B7))) -> 4 | D6: 68 | E6: =IF(AC6>0,((D6-U6)+(V6-D7)),IF(D7=0, ,(D6-D7))) -> 3 | F6: 73 | G6: =IF(AC6>0,((F6-X6)+(Y6-F7)),IF(F7=0, ,(F6-F7))) -> 3 | H6: 69 | I6: =IF(AC6>0,((H6-AA6)+(AB6-H7)),IF(H7=0, ,(H6-H7))) -> 1 | J6: =B6+D6+F6+H6 -> 279 | K6: =J6/4 -> 69.75 | L6: =IF(AC6>0,((K6-AD6)+(AE6-K7)),IF(K7=0, ,(K6-K7))) -> 2.75 | M6: =6049*4 -> 24196 | N6: =L6*M6/100 -> 665.39 | O6: =N6*0.529 -> 351.99131 | P6: =O6*11.565 -> 4070.7795 | AC6: =Q6+T6+W6+Z6 -> 0 | AD6: =(R6+U6+X6+AA6)/4 -> 0 | AE6: =(S6+V6+Y6+AB6)/4 -> 0
A7: 44565 | B7: 65 | C7: =IF(AC7>0,((B7-R7)+(S7-B8)),IF(B8=0, ,(B7-B8))) -> 3 | D7: 65 | E7: =IF(AC7>0,((D7-U7)+(V7-D8)),IF(D8=0, ,(D7-D8))) -> 1 | F7: 70 | G7: =IF(AC7>0,((F7-X7)+(Y7-F8)),IF(F8=0, ,(F7-F8))) -> 6 | H7: 68 | I7: =IF(AC7>0,((H7-AA7)+(AB7-H8)),IF(H8=0, ,(H7-H8))) -> 2 | J7: =B7+D7+F7+H7 -> 268 | K7: =J7/4 -> 67 | L7: =IF(AC7>0,((K7-AD7)+(AE7-K8)),IF(K8=0, ,(K7-K8))) -> 3 | M7: =6049*4 -> 24196 | N7: =L7*M7/100 -> 725.88 | O7: =N7*0.53 -> 384.7164 | P7: =O7*11.565 -> 4449.2452 | AC7: =Q7+T7+W7+Z7 -> 0 | AD7: =(R7+U7+X7+AA7)/4 -> 0 | AE7: =(S7+V7+Y7+AB7)/4 -> 0
A8: 44566 | B8: 62 | C8: =IF(AC8>0,((B8-R8)+(S8-B9)),IF(B9=0, ,(B8-B9))) -> 2 | D8: 64 | E8: =IF(AC8>0,((D8-U8)+(V8-D9)),IF(D9=0, ,(D8-D9))) -> 4 | F8: 64 | G8: =IF(AC8>0,((F8-X8)+(Y8-F9)),IF(F9=0, ,(F8-F9))) -> 2 | H8: 66 | I8: =IF(AC8>0,((H8-AA8)+(AB8-H9)),IF(H9=0, ,(H8-H9))) -> 1 | J8: =B8+D8+F8+H8 -> 256 | K8: =J8/4 -> 64 | L8: =IF(AC8>0,((K8-AD8)+(AE8-K9)),IF(K9=0, ,(K8-K9))) -> 2.25 | M8: =6049*4 -> 24196 | N8: =L8*M8/100 -> 544.41 | O8: =N8*0.529 -> 287.99289 | P8: =O8*11.565 -> 3330.6378 | AC8: =Q8+T8+W8+Z8 -> 0 | AD8: =(R8+U8+X8+AA8)/4 -> 0 | AE8: =(S8+V8+Y8+AB8)/4 -> 0
A9: 44567 | B9: 60 | C9: =IF(AC9>0,((B9-R9)+(S9-B10)),IF(B10=0, ,(B9-B10))) -> 0 | D9: 60 | E9: =IF(AC9>0,((D9-U9)+(V9-D10)),IF(D10=0, ,(D9-D10))) -> 1 | F9: 62 | G9: =IF(AC9>0,((F9-X9)+(Y9-F10)),IF(F10=0, ,(F9-F10))) -> 2 | H9: 65 | I9: =IF(AC9>0,((H9-AA9)+(AB9-H10)),IF(H10=0, ,(H9-H10))) -> 1 | J9: =B9+D9+F9+H9 -> 247 | K9: =J9/4 -> 61.75 | L9: =IF(AC9>0,((K9-AD9)+(AE9-K10)),IF(K10=0, ,(K9-K10))) -> 1 | M9: =6049*4 -> 24196 | N9: =L9*M9/100 -> 241.96 | O9: =N9*0.529 -> 127.99684 | P9: =O9*11.565 -> 1480.2835 | AC9: =Q9+T9+W9+Z9 -> 0 | AD9: =(R9+U9+X9+AA9)/4 -> 0 | AE9: =(S9+V9+Y9+AB9)/4 -> 0
A10: 44568 | B10: 60 | C10: =IF(AC10>0,((B10-R10)+(S10-B11)),IF(B11=0, ,(B10-B11))) -> 1 | D10: 59 | E10: =IF(AC10>0,((D10-U10)+(V10-D11)),IF(D11=0, ,(D10-D11))) -> 1 | F10: 60 | G10: =IF(AC10>0,((F10-X10)+(Y10-F11)),IF(F11=0, ,(F10-F11))) -> 2 | H10: 64 | I10: =IF(AC10>0,((H10-AA10)+(AB10-H11)),IF(H11=0, ,(H10-H11))) -> 2 | J10: =B10+D10+F10+H10 -> 243 | K10: =J10/4 -> 60.75 | L10: =IF(AC10>0,((K10-AD10)+(AE10-K11)),IF(K11=0, ,(K10-K11))) -> 1.5 | M10: =6049*4 -> 24196 | N10: =L10*M10/100 -> 362.94 | O10: =N10*0.529 -> 191.99526 | P10: =O10*11.565 -> 2220.4252 | AC10: =Q10+T10+W10+Z10 -> 0 | AD10: =(R10+U10+X10+AA10)/4 -> 0 | AE10: =(S10+V10+Y10+AB10)/4 -> 0
A11: 44569 | B11: 59 | C11: =IF(AC11>0,((B11-R11)+(S11-B12)),IF(B12=0, ,(B11-B12))) -> 4 | D11: 58 | E11: =IF(AC11>0,((D11-U11)+(V11-D12)),IF(D12=0, ,(D11-D12))) -> 3 | F11: 58 | G11: =IF(AC11>0,((F11-X11)+(Y11-F12)),IF(F12=0, ,(F11-F12))) -> 0 | H11: 62 | I11: =IF(AC11>0,((H11-AA11)+(AB11-H12)),IF(H12=0, ,(H11-H12))) -> 2 | J11: =B11+D11+F11+H11 -> 237 | K11: =J11/4 -> 59.25 | L11: =IF(AC11>0,((K11-AD11)+(AE11-K12)),IF(K12=0, ,(K11-K12))) -> 2.25 | M11: =6049*4 -> 24196 | N11: =L11*M11/100 -> 544.41 | O11: =N11*0.529 -> 287.99289 | P11: =O11*11.565 -> 3330.6378 | AC11: =Q11+T11+W11+Z11 -> 0 | AD11: =(R11+U11+X11+AA11)/4 -> 0 | AE11: =(S11+V11+Y11+AB11)/4 -> 0
A12: 44570 | B12: 55 | C12: =IF(AC12>0,((B12-R12)+(S12-B13)),IF(B13=0, ,(B12-B13))) -> 3 | D12: 55 | E12: =IF(AC12>0,((D12-U12)+(V12-D13)),IF(D13=0, ,(D12-D13))) -> 4 | F12: 58 | G12: =IF(AC12>0,((F12-X12)+(Y12-F13)),IF(F13=0, ,(F12-F13))) -> 2 | H12: 60 | I12: =IF(AC12>0,((H12-AA12)+(AB12-H13)),IF(H13=0, ,(H12-H13))) -> 3 | J12: =B12+D12+F12+H12 -> 228 | K12: =J12/4 -> 57 | L12: =IF(AC12>0,((K12-AD12)+(AE12-K13)),IF(K13=0, ,(K12-K13))) -> 3 | M12: =6049*4 -> 24196 | N12: =L12*M12/100 -> 725.88 | O12: =N12*0.529 -> 383.99052 | P12: =O12*11.565 -> 4440.8504 | AC12: =Q12+T12+W12+Z12 -> 0 | AD12: =(R12+U12+X12+AA12)/4 -> 0 | AE12: =(S12+V12+Y12+AB12)/4 -> 0
A13: 44571 | B13: 52 | C13: =IF(AC13>0,((B13-R13)+(S13-B14)),IF(B14=0, ,(B13-B14))) -> 3 | D13: 51 | E13: =IF(AC13>0,((D13-U13)+(V13-D14)),IF(D14=0, ,(D13-D14))) -> 2 | F13: 56 | G13: =IF(AC13>0,((F13-X13)+(Y13-F14)),IF(F14=0, ,(F13-F14))) -> 0 | H13: 57 | I13: =IF(AC13>0,((H13-AA13)+(AB13-H14)),IF(H14=0, ,(H13-H14))) -> 0 | J13: =B13+D13+F13+H13 -> 216 | K13: =J13/4 -> 54 | L13: =IF(AC13>0,((K13-AD13)+(AE13-K14)),IF(K14=0, ,(K13-K14))) -> 1.25 | M13: =6049*4 -> 24196 | N13: =L13*M13/100 -> 302.45 | O13: =N13*0.529 -> 159.99605 | P13: =O13*11.565 -> 1850.3543 | Q13: 2432 | R13: 50 | S13: 85 | T13: 2458 | U13: 50 | V13: 85 | W13: 2186 | X13: 56 | Y13: 85 | Z13: 2111 | AA13: 57 | AB13: 85 | AC13: =Q13+T13+W13+Z13 -> 9187 | AD13: =(R13+U13+X13+AA13)/4 -> 53.25 | AE13: =(S13+V13+Y13+AB13)/4 -> 85
A14: 44572 | B14: 84 | C14: =IF(AC14>0,((B14-R14)+(S14-B15)),IF(B15=0, ,(B14-B15))) -> 1 | D14: 84 | E14: =IF(AC14>0,((D14-U14)+(V14-D15)),IF(D15=0, ,(D14-D15))) -> 1 | F14: 85 | G14: =IF(AC14>0,((F14-X14)+(Y14-F15)),IF(F15=0, ,(F14-F15))) -> 1 | H14: 85 | I14: =IF(AC14>0,((H14-AA14)+(AB14-H15)),IF(H15=0, ,(H14-H15))) -> 1 | J14: =B14+D14+F14+H14 -> 338 | K14: =J14/4 -> 84.5 | L14: =IF(AC14>0,((K14-AD14)+(AE14-K15)),IF(K15=0, ,(K14-K15))) -> 1 | M14: =6049*4 -> 24196 | N14: =L14*M14/100 -> 241.96 | O14: =N14*0.529 -> 127.99684 | P14: =O14*11.565 -> 1480.2835 | AC14: =Q14+T14+W14+Z14 -> 0 | AD14: =(R14+U14+X14+AA14)/4 -> 0 | AE14: =(S14+V14+Y14+AB14)/4 -> 0
A15: 44573 | B15: 83 | C15: =IF(AC15>0,((B15-R15)+(S15-B16)),IF(B16=0, ,(B15-B16))) -> 0 | D15: 83 | E15: =IF(AC15>0,((D15-U15)+(V15-D16)),IF(D16=0, ,(D15-D16))) -> 0 | F15: 84 | G15: =IF(AC15>0,((F15-X15)+(Y15-F16)),IF(F16=0, ,(F15-F16))) -> 2 | H15: 84 | I15: =IF(AC15>0,((H15-AA15)+(AB15-H16)),IF(H16=0, ,(H15-H16))) -> 3 | J15: =B15+D15+F15+H15 -> 334 | K15: =J15/4 -> 83.5 | L15: =IF(AC15>0,((K15-AD15)+(AE15-K16)),IF(K16=0, ,(K15-K16))) -> 1.25 | M15: =6049*4 -> 24196 | N15: =L15*M15/100 -> 302.45 | O15: =N15*0.529 -> 159.99605 | P15: =O15*11.565 -> 1850.3543 | AC15: =Q15+T15+W15+Z15 -> 0 | AD15: =(R15+U15+X15+AA15)/4 -> 0 | AE15: =(S15+V15+Y15+AB15)/4 -> 0
A16: 44574 | B16: 83 | C16: =IF(AC16>0,((B16-R16)+(S16-B17)),IF(B17=0, ,(B16-B17))) -> 1 | D16: 83 | E16: =IF(AC16>0,((D16-U16)+(V16-D17)),IF(D17=0, ,(D16-D17))) -> 0 | F16: 82 | G16: =IF(AC16>0,((F16-X16)+(Y16-F17)),IF(F17=0, ,(F16-F17))) -> 2 | H16: 81 | I16: =IF(AC16>0,((H16-AA16)+(AB16-H17)),IF(H17=0, ,(H16-H17))) -> 1 | J16: =B16+D16+F16+H16 -> 329 | K16: =J16/4 -> 82.25 | L16: =IF(AC16>0,((K16-AD16)+(AE16-K17)),IF(K17=0, ,(K16-K17))) -> 1 | M16: =6049*4 -> 24196 | N16: =L16*M16/100 -> 241.96 | O16: =N16*0.529 -> 127.99684 | P16: =O16*11.565 -> 1480.2835 | AC16: =Q16+T16+W16+Z16 -> 0 | AD16: =(R16+U16+X16+AA16)/4 -> 0 | AE16: =(S16+V16+Y16+AB16)/4 -> 0
A17: 44575 | B17: 82 | C17: =IF(AC17>0,((B17-R17)+(S17-B18)),IF(B18=0, ,(B17-B18))) -> 4 | D17: 83 | E17: =IF(AC17>0,((D17-U17)+(V17-D18)),IF(D18=0, ,(D17-D18))) -> 4 | F17: 80 | G17: =IF(AC17>0,((F17-X17)+(Y17-F18)),IF(F18=0, ,(F17-F18))) -> 0 | H17: 80 | I17: =IF(AC17>0,((H17-AA17)+(AB17-H18)),IF(H18=0, ,(H17-H18))) -> 0 | J17: =B17+D17+F17+H17 -> 325 | K17: =J17/4 -> 81.25 | L17: =IF(AC17>0,((K17-AD17)+(AE17-K18)),IF(K18=0, ,(K17-K18))) -> 2 | M17: =6049*4 -> 24196 | N17: =L17*M17/100 -> 483.92 | O17: =N17*0.529 -> 255.99368 | P17: =O17*11.565 -> 2960.5669 | AC17: =Q17+T17+W17+Z17 -> 0 | AD17: =(R17+U17+X17+AA17)/4 -> 0 | AE17: =(S17+V17+Y17+AB17)/4 -> 0
A18: 44576 | B18: 78 | C18: =IF(AC18>0,((B18-R18)+(S18-B19)),IF(B19=0, ,(B18-B19))) -> 2 | D18: 79 | E18: =IF(AC18>0,((D18-U18)+(V18-D19)),IF(D19=0, ,(D18-D19))) -> 3 | F18: 80 | G18: =IF(AC18>0,((F18-X18)+(Y18-F19)),IF(F19=0, ,(F18-F19))) -> 2 | H18: 80 | I18: =IF(AC18>0,((H18-AA18)+(AB18-H19)),IF(H19=0, ,(H18-H19))) -> 3 | J18: =B18+D18+F18+H18 -> 317 | K18: =J18/4 -> 79.25 | L18: =IF(AC18>0,((K18-AD18)+(AE18-K19)),IF(K19=0, ,(K18-K19))) -> 2.5 | M18: =6049*4 -> 24196 | N18: =L18*M18/100 -> 604.9 | O18: =N18*0.529 -> 319.9921 | P18: =O18*11.565 -> 3700.7086 | AC18: =Q18+T18+W18+Z18 -> 0 | AD18: =(R18+U18+X18+AA18)/4 -> 0 | AE18: =(S18+V18+Y18+AB18)/4 -> 0
A19: 44577 | B19: 76 | C19: =IF(AC19>0,((B19-R19)+(S19-B20)),IF(B20=0, ,(B19-B20))) -> 1 | D19: 76 | E19: =IF(AC19>0,((D19-U19)+(V19-D20)),IF(D20=0, ,(D19-D20))) -> 1 | F19: 78 | G19: =IF(AC19>0,((F19-X19)+(Y19-F20)),IF(F20=0, ,(F19-F20))) -> 2 | H19: 77 | I19: =IF(AC19>0,((H19-AA19)+(AB19-H20)),IF(H20=0, ,(H19-H20))) -> 2 | J19: =B19+D19+F19+H19 -> 307 | K19: =J19/4 -> 76.75 | L19: =IF(AC19>0,((K19-AD19)+(AE19-K20)),IF(K20=0, ,(K19-K20))) -> 1.5 | M19: =6049*4 -> 24196 | N19: =L19*M19/100 -> 362.94 | O19: =N19*0.529 -> 191.99526 | P19: =O19*11.565 -> 2220.4252 | AC19: =Q19+T19+W19+Z19 -> 0 | AD19: =(R19+U19+X19+AA19)/4 -> 0 | AE19: =(S19+V19+Y19+AB19)/4 -> 0
A20: 44578 | B20: 75 | C20: =IF(AC20>0,((B20-R20)+(S20-B21)),IF(B21=0, ,(B20-B21))) -> 1 | D20: 75 | E20: =IF(AC20>0,((D20-U20)+(V20-D21)),IF(D21=0, ,(D20-D21))) -> 1 | F20: 76 | G20: =IF(AC20>0,((F20-X20)+(Y20-F21)),IF(F21=0, ,(F20-F21))) -> 2 | H20: 75 | I20: =IF(AC20>0,((H20-AA20)+(AB20-H21)),IF(H21=0, ,(H20-H21))) -> 1 | J20: =B20+D20+F20+H20 -> 301 | K20: =J20/4 -> 75.25 | L20: =IF(AC20>0,((K20-AD20)+(AE20-K21)),IF(K21=0, ,(K20-K21))) -> 1.25 | M20: =6049*4 -> 24196 | N20: =L20*M20/100 -> 302.45 | O20: =N20*0.529 -> 159.99605 | P20: =O20*11.565 -> 1850.3543 | AC20: =Q20+T20+W20+Z20 -> 0 | AD20: =(R20+U20+X20+AA20)/4 -> 0 | AE20: =(S20+V20+Y20+AB20)/4 -> 0
A21: 44579 | B21: 74 | C21: =IF(AC21>0,((B21-R21)+(S21-B22)),IF(B22=0, ,(B21-B22))) -> 1 | D21: 74 | E21: =IF(AC21>0,((D21-U21)+(V21-D22)),IF(D22=0, ,(D21-D22))) -> 2 | F21: 74 | G21: =IF(AC21>0,((F21-X21)+(Y21-F22)),IF(F22=0, ,(F21-F22))) -> 2 | H21: 74 | I21: =IF(AC21>0,((H21-AA21)+(AB21-H22)),IF(H22=0, ,(H21-H22))) -> 1 | J21: =B21+D21+F21+H21 -> 296 | K21: =J21/4 -> 74 | L21: =IF(AC21>0,((K21-AD21)+(AE21-K22)),IF(K22=0, ,(K21-K22))) -> 1.5 | M21: =6049*4 -> 24196 | N21: =L21*M21/100 -> 362.94 | O21: =N21*0.529 -> 191.99526 | P21: =O21*11.565 -> 2220.4252 | AC21: =Q21+T21+W21+Z21 -> 0 | AD21: =(R21+U21+X21+AA21)/4 -> 0 | AE21: =(S21+V21+Y21+AB21)/4 -> 0
A22: 44580 | B22: 73 | C22: =IF(AC22>0,((B22-R22)+(S22-B23)),IF(B23=0, ,(B22-B23))) -> 3 | D22: 72 | E22: =IF(AC22>0,((D22-U22)+(V22-D23)),IF(D23=0, ,(D22-D23))) -> 2 | F22: 72 | G22: =IF(AC22>0,((F22-X22)+(Y22-F23)),IF(F23=0, ,(F22-F23))) -> 1 | H22: 73 | I22: =IF(AC22>0,((H22-AA22)+(AB22-H23)),IF(H23=0, ,(H22-H23))) -> 3 | J22: =B22+D22+F22+H22 -> 290 | K22: =J22/4 -> 72.5 | L22: =IF(AC22>0,((K22-AD22)+(AE22-K23)),IF(K23=0, ,(K22-K23))) -> 2.25 | M22: =6049*4 -> 24196 | N22: =L22*M22/100 -> 544.41 | O22: =N22*0.529 -> 287.99289 | P22: =O22*11.565 -> 3330.6378 | AC22: =Q22+T22+W22+Z22 -> 0 | AD22: =(R22+U22+X22+AA22)/4 -> 0 | AE22: =(S22+V22+Y22+AB22)/4 -> 0
A23: 44581 | B23: 70 | C23: =IF(AC23>0,((B23-R23)+(S23-B24)),IF(B24=0, ,(B23-B24))) -> 1 | D23: 70 | E23: =IF(AC23>0,((D23-U23)+(V23-D24)),IF(D24=0, ,(D23-D24))) -> 2 | F23: 71 | G23: =IF(AC23>0,((F23-X23)+(Y23-F24)),IF(F24=0, ,(F23-F24))) -> 1 | H23: 70 | I23: =IF(AC23>0,((H23-AA23)+(AB23-H24)),IF(H24=0, ,(H23-H24))) -> 0 | J23: =B23+D23+F23+H23 -> 281 | K23: =J23/4 -> 70.25 | L23: =IF(AC23>0,((K23-AD23)+(AE23-K24)),IF(K24=0, ,(K23-K24))) -> 1 | M23: =6049*4 -> 24196 | N23: =L23*M23/100 -> 241.96 | O23: =N23*0.529 -> 127.99684 | P23: =O23*11.565 -> 1480.2835 | AC23: =Q23+T23+W23+Z23 -> 0 | AD23: =(R23+U23+X23+AA23)/4 -> 0 | AE23: =(S23+V23+Y23+AB23)/4 -> 0
A24: 44582 | B24: 69 | C24: =IF(AC24>0,((B24-R24)+(S24-B25)),IF(B25=0, ,(B24-B25))) -> 1 | D24: 68 | E24: =IF(AC24>0,((D24-U24)+(V24-D25)),IF(D25=0, ,(D24-D25))) -> 2 | F24: 70 | G24: =IF(AC24>0,((F24-X24)+(Y24-F25)),IF(F25=0, ,(F24-F25))) -> 3 | H24: 70 | I24: =IF(AC24>0,((H24-AA24)+(AB24-H25)),IF(H25=0, ,(H24-H25))) -> 1 | J24: =B24+D24+F24+H24 -> 277 | K24: =J24/4 -> 69.25 | L24: =IF(AC24>0,((K24-AD24)+(AE24-K25)),IF(K25=0, ,(K24-K25))) -> 1.75 | M24: =6049*4 -> 24196 | N24: =L24*M24/100 -> 423.43 | O24: =N24*0.529 -> 223.99447 | P24: =O24*11.565 -> 2590.496 | AC24: =Q24+T24+W24+Z24 -> 0 | AD24: =(R24+U24+X24+AA24)/4 -> 0 | AE24: =(S24+V24+Y24+AB24)/4 -> 0
A25: 44583 | B25: 68 | C25: =IF(AC25>0,((B25-R25)+(S25-B26)),IF(B26=0, ,(B25-B26))) -> 3 | D25: 66 | E25: =IF(AC25>0,((D25-U25)+(V25-D26)),IF(D26=0, ,(D25-D26))) -> 4 | F25: 67 | G25: =IF(AC25>0,((F25-X25)+(Y25-F26)),IF(F26=0, ,(F25-F26))) -> 0 | H25: 69 | I25: =IF(AC25>0,((H25-AA25)+(AB25-H26)),IF(H26=0, ,(H25-H26))) -> 3 | J25: =B25+D25+F25+H25 -> 270 | K25: =J25/4 -> 67.5 | L25: =IF(AC25>0,((K25-AD25)+(AE25-K26)),IF(K26=0, ,(K25-K26))) -> 2.5 | M25: =6049*4 -> 24196 | N25: =L25*M25/100 -> 604.9 | O25: =N25*0.529 -> 319.9921 | P25: =O25*11.565 -> 3700.7086 | AC25: =Q25+T25+W25+Z25 -> 0 | AD25: =(R25+U25+X25+AA25)/4 -> 0 | AE25: =(S25+V25+Y25+AB25)/4 -> 0
... A27: 44585 | B27: 64 | C27: =IF(AC27>0,((B27-R27)+(S27-B28)),IF(B28=0, ,(B27-B28))) -> 0 | D27: 60 | E27: =IF(AC27>0,((D27-U27)+(V27-D28)),IF(D28=0, ,(D27-D28))) -> 0 | F27: 66 | G27: =IF(AC27>0,((F27-X27)+(Y27-F28)),IF(F28=0, ,(F27-F28))) -> 0 | H27: 65 | I27: =IF(AC27>0,((H27-AA27)+(AB27-H28)),IF(H28=0, ,(H27-H28))) -> 0 | J27: =B27+D27+F27+H27 -> 255 | K27: =J27/4 -> 63.75 | L27: =IF(AC27>0,((K27-AD27)+(AE27-K28)),IF(K28=0, ,(K27-K28))) -> 0 | M27: =6049*4 -> 24196 | N27: =L27*M27/100 -> 0 | O27: =N27*0.529 -> 0 | P27: =O27*11.565 -> 0 | AC27: =Q27+T27+W27+Z27 -> 0 | AD27: =(R27+U27+X27+AA27)/4 -> 0 | AE27: =(S27+V27+Y27+AB27)/4 -> 0
A28: 44586 | C28: =IF(AC28>0,((B28-R28)+(S28-B29)),IF(B29=0, ,(B28-B29))) -> 0 | E28: =IF(AC28>0,((D28-U28)+(V28-D29)),IF(D29=0, ,(D28-D29))) -> 0 | G28: =IF(AC28>0,((F28-X28)+(Y28-F29)),IF(F29=0, ,(F28-F29))) -> 0 | I28: =IF(AC28>0,((H28-AA28)+(AB28-H29)),IF(H29=0, ,(H28-H29))) -> 0 | J28: =B28+D28+F28+H28 -> 0 | K28: =J28/4 -> 0 | L28: =IF(AC28>0,((K28-AD28)+(AE28-K29)),IF(K29=0, ,(K28-K29))) -> 0 | M28: =6049*4 -> 24196 | N28: =L28*M28/100 -> 0 | O28: =N28*0.529 -> 0 | P28: =O28*11.565 -> 0 | AC28: =Q28+T28+W28+Z28 -> 0 | AD28: =(R28+U28+X28+AA28)/4 -> 0 | AE28: =(S28+V28+Y28+AB28)/4 -> 0
A29: 44587 | C29: =IF(AC29>0,((B29-R29)+(S29-B30)),IF(B30=0, ,(B29-B30))) -> 0 | E29: =IF(AC29>0,((D29-U29)+(V29-D30)),IF(D30=0, ,(D29-D30))) -> 0 | G29: =IF(AC29>0,((F29-X29)+(Y29-F30)),IF(F30=0, ,(F29-F30))) -> 0 | I29: =IF(AC29>0,((H29-AA29)+(AB29-H30)),IF(H30=0, ,(H29-H30))) -> 0 | J29: =B29+D29+F29+H29 -> 0 | K29: =J29/4 -> 0 | L29: =IF(AC29>0,((K29-AD29)+(AE29-K30)),IF(K30=0, ,(K29-K30))) -> 0 | M29: =6049*4 -> 24196 | N29: =L29*M29/100 -> 0 | O29: =N29*0.529 -> 0 | P29: =O29*11.565 -> 0 | AC29: =Q29+T29+W29+Z29 -> 0 | AD29: =(R29+U29+X29+AA29)/4 -> 0 | AE29: =(S29+V29+Y29+AB29)/4 -> 0
A30: 44588 | C30: =IF(AC30>0,((B30-R30)+(S30-B31)),IF(B31=0, ,(B30-B31))) -> 0 | E30: =IF(AC30>0,((D30-U30)+(V30-D31)),IF(D31=0, ,(D30-D31))) -> 0 | G30: =IF(AC30>0,((F30-X30)+(Y30-F31)),IF(F31=0, ,(F30-F31))) -> 0 | I30: =IF(AC30>0,((H30-AA30)+(AB30-H31)),IF(H31=0, ,(H30-H31))) -> 0 | J30: =B30+D30+F30+H30 -> 0 | K30: =J30/4 -> 0 | L30: =IF(AC30>0,((K30-AD30)+(AE30-K31)),IF(K31=0, ,(K30-K31))) -> 0 | M30: =6049*4 -> 24196 | N30: =L30*M30/100 -> 0 | O30: =N30*0.529 -> 0 | P30: =O30*11.565 -> 0 | AC30: =Q30+T30+W30+Z30 -> 0 | AD30: =(R30+U30+X30+AA30)/4 -> 0 | AE30: =(S30+V30+Y30+AB30)/4 -> 0
A31: 44589 | C31: =IF(AC31>0,((B31-R31)+(S31-B32)),IF(B32=0, ,(B31-B32))) -> 0 | E31: =IF(AC31>0,((D31-U31)+(V31-D32)),IF(D32=0, ,(D31-D32))) -> 0 | G31: =IF(AC31>0,((F31-X31)+(Y31-F32)),IF(F32=0, ,(F31-F32))) -> 0 | I31: =IF(AC31>0,((H31-AA31)+(AB31-H32)),IF(H32=0, ,(H31-H32))) -> 0 | J31: =B31+D31+F31+H31 -> 0 | K31: =J31/4 -> 0 | L31: =IF(AC31>0,((K31-AD31)+(AE31-K32)),IF(K32=0, ,(K31-K32))) -> 0 | M31: =6049*4 -> 24196 | N31: =L31*M31/100 -> 0 | O31: =N31*0.529 -> 0 | P31: =O31*11.565 -> 0 | AC31: =Q31+T31+W31+Z31 -> 0 | AD31: =(R31+U31+X31+AA31)/4 -> 0 | AE31: =(S31+V31+Y31+AB31)/4 -> 0
A32: 44590 | C32: =IF(AC32>0,((B32-R32)+(S32-B33)),IF(B33=0, ,(B32-B33))) -> 0 | E32: =IF(AC32>0,((D32-U32)+(V32-D33)),IF(D33=0, ,(D32-D33))) -> 0 | G32: =IF(AC32>0,((F32-X32)+(Y32-F33)),IF(F33=0, ,(F32-F33))) -> 0 | I32: =IF(AC32>0,((H32-AA32)+(AB32-H33)),IF(H33=0, ,(H32-H33))) -> 0 | J32: =B32+D32+F32+H32 -> 0 | K32: =J32/4 -> 0 | L32: =IF(AC32>0,((K32-AD32)+(AE32-K33)),IF(K33=0, ,(K32-K33))) -> 0 | M32: =6049*4 -> 24196 | N32: =L32*M32/100 -> 0 | O32: =N32*0.529 -> 0 | P32: =O32*11.565 -> 0 | AC32: =Q32+T32+W32+Z32 -> 0 | AD32: =(R32+U32+X32+AA32)/4 -> 0 | AE32: =(S32+V32+Y32+AB32)/4 -> 0
A33: 44591 | C33: =IF(AC33>0,((B33-R33)+(S33-B34)),IF(B34=0, ,(B33-B34))) -> 0 | E33: =IF(AC33>0,((D33-U33)+(V33-D34)),IF(D34=0, ,(D33-D34))) -> 0 | G33: =IF(AC33>0,((F33-X33)+(Y33-F34)),IF(F34=0, ,(F33-F34))) -> 0 | I33: =IF(AC33>0,((H33-AA33)+(AB33-H34)),IF(H34=0, ,(H33-H34))) -> 0 | J33: =B33+D33+F33+H33 -> 0 | K33: =J33/4 -> 0 | L33: =IF(AC33>0,((K33-AD33)+(AE33-K34)),IF(K34=0, ,(K33-K34))) -> 0 | M33: =6049*4 -> 24196 | N33: =L33*M33/100 -> 0 | O33: =N33*0.529 -> 0 | P33: =O33*11.565 -> 0 | AC33: =Q33+T33+W33+Z33 -> 0 | AD33: =(R33+U33+X33+AA33)/4 -> 0 | AE33: =(S33+V33+Y33+AB33)/4 -> 0
A34: 44592 | C34: =IF(AC34>0,((B34-R34)+(S34-B35)),IF(B35=0, ,(B34-B35))) -> 0 | E34: =IF(AC34>0,((D34-U34)+(V34-D35)),IF(D35=0, ,(D34-D35))) -> 0 | G34: =IF(AC34>0,((F34-X34)+(Y34-F35)),IF(F35=0, ,(F34-F35))) -> 0 | I34: =IF(AC34>0,((H34-AA34)+(AB34-H35)),IF(H35=0, ,(H34-H35))) -> 0 | J34: =B34+D34+F34+H34 -> 0 | K34: =J34/4 -> 0 | L34: =IF(AC34>0,((K34-AD34)+(AE34-K35)),IF(K35=0, ,(K34-K35))) -> 0 | M34: =6049*4 -> 24196 | N34: =L34*M34/100 -> 0 | O34: =N34*0.529 -> 0 | P34: =O34*11.565 -> 0 | AC34: =Q34+T34+W34+Z34 -> 0 | AD34: =(R34+U34+X34+AA34)/4 -> 0 | AE34: =(S34+V34+Y34+AB34)/4 -> 0
A35: 44593 | C35: =IF(AC35>0,((B35-R35)+(S35-B36)),IF(B36=0, ,(B35-B36))) -> 0 | E35: =IF(AC35>0,((D35-U35)+(V35-D36)),IF(D36=0, ,(D35-D36))) -> 0 | G35: =IF(AC35>0,((F35-X35)+(Y35-F36)),IF(F36=0, ,(F35-F36))) -> 0 | I35: =IF(AC35>0,((H35-AA35)+(AB35-H36)),IF(H36=0, ,(H35-H36))) -> 0 | J35: =B35+D35+F35+H35 -> 0 | K35: =J35/4 -> 0 | L35: =IF(AC35>0,((K35-AD35)+(AE35-K36)),IF(K36=0, ,(K35-K36))) -> 0 | M35: =6049*4 -> 24196 | N35: =L35*M35/100 -> 0 | O35: =N35*0.529 -> 0 | P35: =O35*11.565 -> 0 | AC35: =Q35+T35+W35+Z35 -> 0 | AD35: =(R35+U35+X35+AA35)/4 -> 0 | AE35: =(S35+V35+Y35+AB35)/4 -> 0
C36: =IF(AC36>0,((B36-R36)+(S36-B37)),IF(B37=0, ,(B36-B37))) -> 0 | E36: =IF(AC36>0,((D36-U36)+(V36-D37)),IF(D37=0, ,(D36-D37))) -> 0 | G36: =IF(AC36>0,((F36-X36)+(Y36-F37)),IF(F37=0, ,(F36-F37))) -> 0 | I36: =IF(AC36>0,((H36-AA36)+(AB36-H37)),IF(H37=0, ,(H36-H37))) -> 0 | J36: =B36+D36+F36+H36 -> 0 | K36: =J36/4 -> 0 | L36: =IF(AC36>0,((K36-AD36)+(AE36-K37)),IF(K37=0, ,(K36-K37))) -> 0 | M36: =6049*4 -> 24196 | N36: =L36*M36/100 -> 0 | O36: =N36*0.529 -> 0 | P36: =O36*11.565 -> 0 | AC36: =Q36+T36+W36+Z36 -> 0 | AD36: =(R36+U36+X36+AA36)/4 -> 0 | AE36: =(S36+V36+Y36+AB36)/4 -> 0
C37: =IF(AC37>0,((B37-R37)+(S37-B38)),IF(B38=0, ,(B37-B38))) -> 0 | E37: =IF(AC37:AC60>0,((D37-U37)+(V37-D38)),IF(D38=0, ,(D37-D38))) -> 0 | G37: =IF(AC37>0,((F37-X37)+(Y37-F38)),IF(F38=0, ,(F37-F38))) -> 0 | I37: =IF(AC37>0,((H37-AA37)+(AB37-H38)),IF(H38=0, ,(H37-H38))) -> 0 | J37: =B37+D37+F37+H37 -> 0 | K37: =J37/4 -> 0 | L37: =IF(AC37>0,((K37-AD37)+(AE37-K38)),IF(K38=0, ,(K37-K38))) -> 0 | M37: =6049*4 -> 24196 | N37: =L37*M37/100 -> 0 | O37: =N37*0.529 -> 0 | P37: =O37*11.565 -> 0 | AC37: =Q37+T37+W37+Z37 -> 0 | AD37: =(R37+U37+X37+AA37)/4 -> 0 | AE37: =(S37+V37+Y37+AB37)/4 -> 0
C38: =IF(AC38>0,((B38-R38)+(S38-B39)),IF(B39=0, ,(B38-B39))) -> 0 | E38: =IF(AC38:AC61>0,((D38-U38)+(V38-D39)),IF(D39=0, ,(D38-D39))) -> 0 | G38: =IF(AC38>0,((F38-X38)+(Y38-F39)),IF(F39=0, ,(F38-F39))) -> 0 | I38: =IF(AC38>0,((H38-AA38)+(AB38-H39)),IF(H39=0, ,(H38-H39))) -> 0 | J38: =B38+D38+F38+H38 -> 0 | K38: =J38/4 -> 0 | L38: =IF(AC38>0,((K38-AD38)+(AE38-K39)),IF(K39=0, ,(K38-K39))) -> 0 | M38: =6049*4 -> 24196 | N38: =L38*M38/100 -> 0 | O38: =N38*0.53 -> 0 | P38: =O38*11.565 -> 0 | AC38: =Q38+T38+W38+Z38 -> 0 | AD38: =(R38+U38+X38+AA38)/4 -> 0 | AE38: =(S38+V38+Y38+AB38)/4 -> 0
C39: =IF(AC39>0,((B39-R39)+(S39-B40)),IF(B40=0, ,(B39-B40))) -> 0 | E39: =IF(AC39>0,((D39-U39)+(V39-D40)),IF(D40=0, ,(D39-D40))) -> 0 | G39: =IF(AC39>0,((F39-X39)+(Y39-F40)),IF(F40=0, ,(F39-F40))) -> 0 | I39: =IF(AC39>0,((H39-AA39)+(AB39-H40)),IF(H40=0, ,(H39-H40))) -> 0 | J39: =B39+D39+F39+H39 -> 0 | K39: =J39/4 -> 0 | L39: =IF(AC39>0,((K39-AD39)+(AE39-K40)),IF(K40=0, ,(K39-K40))) -> 0 | M39: =6049*4 -> 24196 | N39: =L39*M39/100 -> 0 | O39: =N39*0.53 -> 0 | P39: =O39*11.2513 -> 0 | AC39: =Q39+T39+W39+Z39 -> 0 | AD39: =(R39+U39+X39+AA39)/4 -> 0 | AE39: =(S39+V39+Y39+AB39)/4 -> 0
C40: =IF(AC40>0,((B40-R40)+(S40-B41)),IF(B41=0, ,(B40-B41))) -> 0 | E40: =IF(AC40>0,((D40-U40)+(V40-D41)),IF(D41=0, ,(D40-D41))) -> 0 | G40: =IF(AC40>0,((F40-X40)+(Y40-F41)),IF(F41=0, ,(F40-F41))) -> 0 | I40: =IF(AC40>0,((H40-AA40)+(AB40-H41)),IF(H41=0, ,(H40-H41))) -> 0 | J40: =B40+D40+F40+H40 -> 0 | K40: =J40/4 -> 0 | L40: =IF(AC40>0,((K40-AD40)+(AE40-K41)),IF(K41=0, ,(K40-K41))) -> 0 | M40: =6049*4 -> 24196 | N40: =L40*M40/100 -> 0 | O40: =N40*0.53 -> 0 | P40: =O40*9.965 -> 0 | AC40: =Q40+T40+W40+Z40 -> 0 | AD40: =(R40+U40+X40+AA40)/4 -> 0 | AE40: =(S40+V40+Y40+AB40)/4 -> 0
C41: =IF(AC41>0,((B41-R41)+(S41-B42)),IF(B42=0, ,(B41-B42))) -> 0 | E41: =IF(AC41>0,((D41-U41)+(V41-D42)),IF(D42=0, ,(D41-D42))) -> 0 | G41: =IF(AC41>0,((F41-X41)+(Y41-F42)),IF(F42=0, ,(F41-F42))) -> 0 | I41: =IF(AC41>0,((H41-AA41)+(AB41-H42)),IF(H42=0, ,(H41-H42))) -> 0 | J41: =B41+D41+F41+H41 -> 0 | K41: =J41/4 -> 0 | L41: =IF(AC41>0,((K41-AD41)+(AE41-K42)),IF(K42=0, ,(K41-K42))) -> 0 | M41: =6049*4 -> 24196 | N41: =L41*M41/100 -> 0 | O41: =N41*0.53 -> 0 | P41: =O41*9.965 -> 0 | AC41: =Q41+T41+W41+Z41 -> 0 | AD41: =(R41+U41+X41+AA41)/4 -> 0 | AE41: =(S41+V41+Y41+AB41)/4 -> 0
...

Sheet Suivi EAU-ELEC
E1: Suivi Compteur d'Eau- électricité Lydec- JAN 2022 | J1: Département Engineering 2022
A7: Date/électriqie | B7: Incendie | D7: Eau m3 | F7: Electricité Kw/h
B8: Compteur | C8: Consommation | D8: Compteur | E8: Consommation | F8: Compteur H.Creuse | G8: Consommation H.Creuse | H8: Compteur H.Pleine | I8: Consommation H.Pleine | J8: Compteur H.Pointe | K8: Consommation H.Pointe
A9: 44562 | B9: 2560 | C9: 0 | D9: 132699 | E9: 8.8 | F9: 11364390 | G9: 2484 | H9: 19320037 | I9: 3362 | J9: 8481098 | K9: 1521
A10: 44563 | B10: 2560 | C10: =B10-B9 -> 0 | D10: 132734 | E10: =D10-D9 -> 35 | F10: 11366842 | G10: =F10-F9 -> 2452 | H10: 19323394 | I10: =H10-H9 -> 3357 | J10: 8482591 | K10: =J10-J9 -> 1493
A11: 44564 | B11: 2560 | C11: =B11-B10 -> 0 | D11: 132787 | E11: =D11-D10 -> 53 | F11: 11369290 | G11: =F11-F10 -> 2448 | H11: 19326653 | I11: =H11-H10 -> 3259 | J11: 8484073 | K11: =J11-J10 -> 1482
A12: 44565 | B12: 2560 | C12: =B12-B11 -> 0 | D12: 132829.9 | E12: =D12-D11 -> 42.9 | F12: 11371707 | G12: =F12-F11 -> 2417 | H12: 19329892 | I12: =H12-H11 -> 3239 | J12: 8484576 | K12: =J12-J11 -> 503
A13: 44566 | B13: 2560 | C13: =B13-B12 -> 0 | D13: 132878.3 | E13: =D13-D12 -> 48.4 | F13: 11374199 | G13: =F13-F12 -> 2492 | H13: 19333248 | I13: =H13-H12 -> 3356 | J13: 8487105 | K13: =J13-J12 -> 2529
A14: 44567 | B14: 2560 | C14: =B14-B13 -> 0 | D14: 132928.2 | E14: =D14-D13 -> 49.9 | F14: 11376730 | G14: =F14-F13 -> 2531 | H14: 19336558 | I14: =H14-H13 -> 3310 | J14: 8488559 | K14: =J14-J13 -> 1454
A15: 44568 | B15: 2560 | C15: =B15-B14 -> 0 | D15: 132968 | E15: =D15-D14 -> 39.8 | F15: 11379148 | G15: =F15-F14 -> 2418 | H15: 19339764 | I15: =H15-H14 -> 3206 | J15: 8490021 | K15: =J15-J14 -> 1462
A16: 44569 | B16: 2560 | C16: =B16-B15 -> 0 | D16: 133009 | E16: =D16-D15 -> 41 | F16: 11381638 | G16: =F16-F15 -> 2490 | H16: 19342968 | I16: =H16-H15 -> 3204 | J16: 8491543 | K16: =J16-J15 -> 1522
A17: 44570 | B17: 2560 | C17: =B17-B16 -> 0 | D17: 133058 | E17: =D17-D16 -> 49 | F17: 11383959 | G17: =F17-F16 -> 2321 | H17: 19346034 | I17: =H17-H16 -> 3066 | J17: 8493006 | K17: =J17-J16 -> 1463
A18: 44571 | B18: 2560 | C18: =B18-B17 -> 0 | D18: 133101 | E18: =D18-D17 -> 43 | F18: 11386330 | G18: =F18-F17 -> 2371 | H18: 19349074 | I18: =H18-H17 -> 3040 | J18: 8494426 | K18: =J18-J17 -> 1420
A19: 44572 | B19: 2560 | C19: =B19-B18 -> 0 | D19: 133146.3 | E19: =D19-D18 -> 45.3 | F19: 11388496 | G19: =F19-F18 -> 2166 | H19: 19352014 | I19: =H19-H18 -> 2940 | J19: 8495841 | K19: =J19-J18 -> 1415
A20: 44573 | B20: 2560 | C20: =B20-B19 -> 0 | D20: 133185.9 | E20: =D20-D19 -> 39.6 | F20: 11390815 | G20: =F20-F19 -> 2319 | H20: 19354930 | I20: =H20-H19 -> 2916 | J20: 8497217 | K20: =J20-J19 -> 1376
A21: 44574 | B21: 2560 | C21: =B21-B20 -> 0 | D21: 133229.4 | E21: =D21-D20 -> 43.5 | F21: 11393243 | G21: =F21-F20 -> 2428 | H21: 19357965 | I21: =H21-H20 -> 3035 | J21: 8498659 | K21: =J21-J20 -> 1442
... A31: 44584 | B31: 2560 | C31: =B31-B30 -> 0 | D31: 133655 | E31: =D31-D30 -> 39 | F31: 11414633 | G31: =F31-F30 -> 2103 | H31: 19385081 | I31: =H31-H30 -> 2572 | J31: 8511471 | K31: =J31-J30 -> 1263
A32: 44585 | B32: 2560 | D32: 133693 | E32: =D32-D31 -> 38 | F32: 11416831 | G32: =F32-F31 -> 2198 | H32: 19387697 | I32: =H32-H31 -> 2616 | J32: 8512727 | K32: =J32-J31 -> 1256
A33: 44586
A34: 44587
A35: 44588
A36: 44589
A37: 44590
A38: 44591
A39: 44592
A40: 44593

Sheet cons annuel électr
C5: électricité en KW
C7: Janvier | D7: Février | E7: Mars | F7: avril | G7: Mai | H7: juin | I7: Juillet | J7: aout | K7: Septembre | L7: Octobre | M7: Novembre | N7: Décembre
B8: Année 2015 | L8: 544520 | M8: 561765 | N8: 546771
B9: Année 2016 | C9: 564170 | D9: 532072 | E9: 405239 | F9: 469130 | G9: 543877 | H9: 605744 | I9: 722083 | J9: 802210 | K9: 762933 | L9: 670848 | M9: 626451 | N9: 557392
B10: Année 2017 | C10: 520977 | D10: 541271 | E10: 508392 | F10: 659200 | G10: 705703 | H10: 784214 | I10: 823726 | J10: 913736 | K10: 831734 | L10: 794243 | M10: 688127 | N10: 577067
B11: Année 2018 | C11: 586355 | D11: 563735 | E11: 512313 | F11: 573440 | G11: 535115 | H11: 570139 | I11: 669302 | J11: 704714 | K11: 682717 | L11: 581239 | M11: 438561 | N11: 400672
B12: Année 2019 | C12: 388363 | D12: 407737 | E12: 392102 | F12: 454554 | G12: 448580 | H12: 535391 | I12: 549301 | J12: 576078 | K12: 612675 | L12: 542640 | M12: 507495 | N12: 444826
B13: Année 2020 | C13: 417018 | D13: 434912 | E13: 278008 | F13: 90895 | G13: 70143 | H13: 76577 | I13: 238549 | J13: 371235 | K13: 295161 | L13: 318184 | M13: 297355 | N13: 260661
B14: Année 2021 | C14: 239911 | D14: 247692 | E14: 242350 | F14: 282564 | G14: 272836 | H14: 362809 | I14: 454598 | J14: 470109 | K14: 458455 | L14: 444199 | M14: 374528 | N14: 256419
B15: Année 2022
C16: électricité en DH HT
C18: Janvier | D18: Février | E18: Mars | F18: avril | G18: Mai | H18: juin | I18: Juillet | J18: aout | K18: Septembre | L18: Octobre | M18: Novembre | N18: Décembre
B19: Année 2015 | L19: 527344.76 | M19: 542887.95 | N19: 530789.1
B20: Année 2016 | C20: 577599.26 | D20: 549500.3 | E20: 437038.73 | F20: 498381.29 | G20: 567710.59 | H20: 626665.41 | I20: 732996.54 | J20: 807380.12 | K20: 765103.7 | L20: 674808.61 | M20: 636029.23 | N20: 575999.91
B21: Année 2017 | C21: 565777.06 | D21: 589465.87 | E21: 559348.97 | F21: 706566.83 | G21: 750048.77 | H21: 823657.04 | I21: 863911.21 | J21: 948371.74 | K21: 870086.49 | L21: 828237.33 | M21: 728226.36 | N21: 620794.43
B22: Année 2018 | C22: 629018.45 | D22: 609232.05 | E22: 564099.54 | F22: 625412.74 | G22: 591310.65 | H22: 627578.14 | I22: 723790.51 | J22: 756208.25 | K22: 734211.55 | L22: 634725.02 | M22: 492313.54 | N22: 430486.08
B23: Année 2019 | C23: 417767.5 | D23: 437511.45 | E23: 422948.91 | F23: 483026.43 | G23: 494466.66 | H23: 589026.66 | I23: 597445.77 | J23: 624719.21 | K23: 662255.27 | L23: 572138.69 | M23: 536725.71 | N23: 473017.45
B24: Année 2020 | C24: 445089.46 | D24: 464838.33 | E24: 310234.48 | F24: 132086.12 | G24: 81934.238 | H24: 88016.123 | I24: 290744.44 | J24: 372885.54 | K24: 328998.33 | L24: 350713.84 | M24: 329624.09 | N24: 294931.2
B25: Année 2021 | C25: 274561.56 | D25: 283692.47 | E25: 278888.13 | F25: 318224.92 | G25: 309500.68 | H25: 396582.06 | I25: 498105.11 | J25: 506423.32 | K25: 486424.27 | L25: 473503.95 | M25: 403992.35 | N25: 289205.49
B26: Année 2022
