Workbook

Sheet TOTAL
A1: Site Name | B1: Day | C1: Month | D1: Year | E1: Total Electricity Kwh | F1: Electricity Tariff ($/Kwh) | G1: LPG (Kg) | H1: LPG $/Kg | I1: Water Utility Supply (m3) m3 | J1: Water Utility Supply (m3) $/m3 | K1: Irrigation Water (m3) m3 | L1: Irrigation water $/m3 | M1: Room Nights
A2: Seychelles | B2: 1 | C2: 11 | D2: 2022 | E2: =SUM('FS Seychelles'!D3:I3)*1000 -> 19720 | F2: =(('FS Seychelles'!O3*'FS Seychelles'!P3)+('FS Seychelles'!Q3*'FS Seychelles'!R3))/TOTAL!E2 -> 0.71045019 | G2: =('FS Seychelles'!$Z$10+'FS Seychelles'!$Z$15)/30 -> 295.66667 | H2: 1.05 | I2: =SUM('FS Seychelles'!S3:W3) -> 269 | J2: 0 | K2: ='FS Seychelles'!AA3 -> 135 | L2: 0 | M2: ='FS Seychelles'!B3 -> 68.8
A3: Seychelles | B3: =B2+1 -> 2 | C3: =C2 -> 11 | D3: 2022 | E3: =SUM('FS Seychelles'!D4:I4)*1000 -> 19040 | F3: =(('FS Seychelles'!O4*'FS Seychelles'!P4)+('FS Seychelles'!Q4*'FS Seychelles'!R4))/TOTAL!E3 -> 0.69456491 | G3: =('FS Seychelles'!$Z$10+'FS Seychelles'!$Z$15)/30 -> 295.66667 | H3: =H2 -> 1.05 | I3: =SUM('FS Seychelles'!S4:W4) -> 238 | J3: =J2 -> 0 | K3: ='FS Seychelles'!AA4 -> 158 | L3: =L2 -> 0 | M3: ='FS Seychelles'!B4 -> 71.4
A4: Seychelles | B4: =B3+1 -> 3 | C4: =C3 -> 11 | D4: 2022 | E4: =SUM('FS Seychelles'!D5:I5)*1000 -> 19430 | F4: =(('FS Seychelles'!O5*'FS Seychelles'!P5)+('FS Seychelles'!Q5*'FS Seychelles'!R5))/TOTAL!E4 -> 0.74379028 | G4: =('FS Seychelles'!$Z$10+'FS Seychelles'!$Z$15)/30 -> 295.66667 | H4: =H3 -> 1.05 | I4: =SUM('FS Seychelles'!S5:W5) -> 284 | J4: =J3 -> 0 | K4: ='FS Seychelles'!AA5 -> 100 | L4: =L3 -> 0 | M4: ='FS Seychelles'!B5 -> 71.4
A5: Seychelles | B5: =B4+1 -> 4 | C5: =C4 -> 11 | D5: 2022 | E5: =SUM('FS Seychelles'!D6:I6)*1000 -> 19820 | F5: =(('FS Seychelles'!O6*'FS Seychelles'!P6)+('FS Seychelles'!Q6*'FS Seychelles'!R6))/TOTAL!E5 -> 0.70830368 | G5: =('FS Seychelles'!$Z$10+'FS Seychelles'!$Z$15)/30 -> 295.66667 | H5: =H4 -> 1.05 | I5: =SUM('FS Seychelles'!S6:W6) -> 241 | J5: =J4 -> 0 | K5: ='FS Seychelles'!AA6 -> 129 | L5: =L4 -> 0 | M5: ='FS Seychelles'!B6 -> 74
A6: Seychelles | B6: =B5+1 -> 5 | C6: =C5 -> 11 | D6: 2022 | E6: =SUM('FS Seychelles'!D7:I7)*1000 -> 19580 | F6: =(('FS Seychelles'!O7*'FS Seychelles'!P7)+('FS Seychelles'!Q7*'FS Seychelles'!R7))/TOTAL!E6 -> 0.77448278 | G6: =('FS Seychelles'!$Z$10+'FS Seychelles'!$Z$15)/30 -> 295.66667 | H6: =H5 -> 1.05 | I6: =SUM('FS Seychelles'!S7:W7) -> 259 | J6: =J5 -> 0 | K6: ='FS Seychelles'!AA7 -> 120 | L6: =L5 -> 0 | M6: ='FS Seychelles'!B7 -> 64.9
A7: Seychelles | B7: =B6+1 -> 6 | C7: =C6 -> 11 | D7: 2022 | E7: =SUM('FS Seychelles'!D8:I8)*1000 -> 18190 | F7: =(('FS Seychelles'!O8*'FS Seychelles'!P8)+('FS Seychelles'!Q8*'FS Seychelles'!R8))/TOTAL!E7 -> 0.70459559 | G7: =('FS Seychelles'!$Z$10+'FS Seychelles'!$Z$15)/30 -> 295.66667 | H7: =H6 -> 1.05 | I7: =SUM('FS Seychelles'!S8:W8) -> 221 | J7: =J6 -> 0 | K7: ='FS Seychelles'!AA8 -> 156 | L7: =L6 -> 0 | M7: ='FS Seychelles'!B8 -> 68.8
A8: Seychelles | B8: =B7+1 -> 7 | C8: =C7 -> 11 | D8: 2022 | E8: =SUM('FS Seychelles'!D9:I9)*1000 -> 19300 | F8: =(('FS Seychelles'!O9*'FS Seychelles'!P9)+('FS Seychelles'!Q9*'FS Seychelles'!R9))/TOTAL!E8 -> 0.69628364 | G8: =('FS Seychelles'!$Z$10+'FS Seychelles'!$Z$15)/30 -> 295.66667 | H8: =H7 -> 1.05 | I8: =SUM('FS Seychelles'!S9:W9) -> 218 | J8: =J7 -> 0 | K8: ='FS Seychelles'!AA9 -> 163 | L8: =L7 -> 0 | M8: ='FS Seychelles'!B9 -> 74
A9: Seychelles | B9: =B8+1 -> 8 | C9: =C8 -> 11 | D9: 2022 | E9: =SUM('FS Seychelles'!D10:I10)*1000 -> 19650 | F9: =(('FS Seychelles'!O10*'FS Seychelles'!P10)+('FS Seychelles'!Q10*'FS Seychelles'!R10))/TOTAL!E9 -> 0.73192741 | G9: =('FS Seychelles'!$Z$10+'FS Seychelles'!$Z$15)/30 -> 295.66667 | H9: =H8 -> 1.05 | I9: =SUM('FS Seychelles'!S10:W10) -> 290 | J9: =J8 -> 0 | K9: ='FS Seychelles'!AA10 -> 105 | L9: =L8 -> 0 | M9: ='FS Seychelles'!B10 -> 68.8
A10: Seychelles | B10: =B9+1 -> 9 | C10: =C9 -> 11 | D10: 2022 | E10: =SUM('FS Seychelles'!D11:I11)*1000 -> 19680 | F10: =(('FS Seychelles'!O11*'FS Seychelles'!P11)+('FS Seychelles'!Q11*'FS Seychelles'!R11))/TOTAL!E10 -> 0.63903027 | G10: =('FS Seychelles'!$Z$10+'FS Seychelles'!$Z$15)/30 -> 295.66667 | H10: =H9 -> 1.05 | I10: =SUM('FS Seychelles'!S11:W11) -> 219 | J10: =J9 -> 0 | K10: ='FS Seychelles'!AA11 -> 99 | L10: =L9 -> 0 | M10: ='FS Seychelles'!B11 -> 68.8
A11: Seychelles | B11: =B10+1 -> 10 | C11: =C10 -> 11 | D11: 2022 | E11: =SUM('FS Seychelles'!D12:I12)*1000 -> 19890 | F11: =(('FS Seychelles'!O12*'FS Seychelles'!P12)+('FS Seychelles'!Q12*'FS Seychelles'!R12))/TOTAL!E11 -> 0.64741873 | G11: =('FS Seychelles'!$Z$10+'FS Seychelles'!$Z$15)/30 -> 295.66667 | H11: =H10 -> 1.05 | I11: =SUM('FS Seychelles'!S12:W12) -> 169 | J11: =J10 -> 0 | K11: ='FS Seychelles'!AA12 -> 126 | L11: =L10 -> 0 | M11: ='FS Seychelles'!B12 -> 68.8
A12: Seychelles | B12: =B11+1 -> 11 | C12: =C11 -> 11 | D12: 2022 | E12: =SUM('FS Seychelles'!D13:I13)*1000 -> 20080 | F12: =(('FS Seychelles'!O13*'FS Seychelles'!P13)+('FS Seychelles'!Q13*'FS Seychelles'!R13))/TOTAL!E12 -> 0.69806788 | G12: =('FS Seychelles'!$Z$10+'FS Seychelles'!$Z$15)/30 -> 295.66667 | H12: =H11 -> 1.05 | I12: =SUM('FS Seychelles'!S13:W13) -> 242 | J12: =J11 -> 0 | K12: ='FS Seychelles'!AA13 -> 104 | L12: =L11 -> 0 | M12: ='FS Seychelles'!B13 -> 71.4
A13: Seychelles | B13: =B12+1 -> 12 | C13: =C12 -> 11 | D13: 2022 | E13: =SUM('FS Seychelles'!D14:I14)*1000 -> 20160 | F13: =(('FS Seychelles'!O14*'FS Seychelles'!P14)+('FS Seychelles'!Q14*'FS Seychelles'!R14))/TOTAL!E13 -> 0.69750675 | G13: =('FS Seychelles'!$Z$10+'FS Seychelles'!$Z$15)/30 -> 295.66667 | H13: =H12 -> 1.05 | I13: =SUM('FS Seychelles'!S14:W14) -> 220 | J13: =J12 -> 0 | K13: ='FS Seychelles'!AA14 -> 163 | L13: =L12 -> 0 | M13: ='FS Seychelles'!B14 -> 55.8
A14: Seychelles | B14: =B13+1 -> 13 | C14: =C13 -> 11 | D14: 2022 | E14: =SUM('FS Seychelles'!D15:I15)*1000 -> 19530 | F14: =(('FS Seychelles'!O15*'FS Seychelles'!P15)+('FS Seychelles'!Q15*'FS Seychelles'!R15))/TOTAL!E14 -> 0.67130115 | G14: =('FS Seychelles'!$Z$10+'FS Seychelles'!$Z$15)/30 -> 295.66667 | H14: =H13 -> 1.05 | I14: =SUM('FS Seychelles'!S15:W15) -> 219 | J14: =J13 -> 0 | K14: ='FS Seychelles'!AA15 -> 102 | L14: =L13 -> 0 | M14: ='FS Seychelles'!B15 -> 63.6
... A31: Seychelles | B31: =B30+1 -> 30 | C31: =C30 -> 11 | D31: 2022 | E31: =SUM('FS Seychelles'!D32:I32)*1000 -> 0 | F31: =(('FS Seychelles'!O32*'FS Seychelles'!P32)+('FS Seychelles'!Q32*'FS Seychelles'!R32))/TOTAL!E31 -> #DIV/0! | G31: =('FS Seychelles'!$Z$10+'FS Seychelles'!$Z$15)/30 -> 295.66667 | H31: =H30 -> 1.05 | I31: =SUM('FS Seychelles'!S32:W32) -> 0 | J31: =J30 -> 0 | K31: ='FS Seychelles'!AA32 -> -54273 | L31: =L30 -> 0 | M31: ='FS Seychelles'!B32 -> 0
A32: Seychelles

Sheet Submetering 
A1: Site Name | B1: Day | C1: Month | D1: Year | E1: Room Night | F1: SS-A - KWh | G1: SS-B- KWh | H1: SS-C- KWh | I1: FIRE PUMP- KWh | J1: CASINO- KWh | K1: BOH- KWh | L1: Generator#1 - KWh | M1: Generator#2- KWh | N1: Generator#3- KWh | O1: Generator#4- KWh | P1: Generator#5- KWh | Q1: DIESEL - Liter | R1: PUC - KWh | S1: BOH Water- m3 | T1: WT59- m3 | U1: WT08- m3 | V1: PUC (HOH)- m3 | W1: Fire Pump- m3 | X1: LPG (Kg)
A2: Seychelles | B2: 1 | C2: 11 | D2: 2022 | E2: ='FS Seychelles'!B3 -> 68.8 | F2: ='FS Seychelles'!D3*1000 -> 2880 | G2: ='FS Seychelles'!E3*1000 -> 4540 | H2: ='FS Seychelles'!F3*1000 -> 5440 | I2: ='FS Seychelles'!G3*1000 -> 1450 | J2: ='FS Seychelles'!H3*1000 -> 1450 | K2: ='FS Seychelles'!I3*1000 -> 3960 | L2: ='FS Seychelles'!J3 -> 7113 | M2: ='FS Seychelles'!K3 -> 15674 | N2: ='FS Seychelles'!L3 -> 10502 | O2: ='FS Seychelles'!M3 -> 2301 | P2: ='FS Seychelles'!N3 -> 0 | Q2: ='FS Seychelles'!O3 -> 7865 | R2: ='FS Seychelles'!Q3 -> 0 | S2: ='FS Seychelles'!S3 -> 46 | T2: ='FS Seychelles'!T3 -> 18 | U2: ='FS Seychelles'!U3 -> 103 | V2: ='FS Seychelles'!V3 -> 102 | W2: ='FS Seychelles'!W3 -> 0 | X2: =('FS Seychelles'!Z9+'FS Seychelles'!Z15)/30 -> 295.66667
A3: Seychelles | B3: =B2+1 -> 2 | C3: =C2 -> 11 | D3: 2022 | E3: ='FS Seychelles'!B4 -> 71.4 | F3: ='FS Seychelles'!D4*1000 -> 2630 | G3: ='FS Seychelles'!E4*1000 -> 4240 | H3: ='FS Seychelles'!F4*1000 -> 5430 | I3: ='FS Seychelles'!G4*1000 -> 1430 | J3: ='FS Seychelles'!H4*1000 -> 1430 | K3: ='FS Seychelles'!I4*1000 -> 3880 | L3: ='FS Seychelles'!J4 -> 0 | M3: ='FS Seychelles'!K4 -> 9433 | N3: ='FS Seychelles'!L4 -> 9480 | O3: ='FS Seychelles'!M4 -> 5218 | P3: ='FS Seychelles'!N4 -> 9433 | Q3: ='FS Seychelles'!O4 -> 7424 | R3: ='FS Seychelles'!Q4 -> 0 | S3: ='FS Seychelles'!S4 -> 61 | T3: ='FS Seychelles'!T4 -> 3 | U3: ='FS Seychelles'!U4 -> 71 | V3: ='FS Seychelles'!V4 -> 103 | W3: ='FS Seychelles'!W4 -> 0 | X3: =('FS Seychelles'!Z10+'FS Seychelles'!Z16)/30 -> 0
A4: Seychelles | B4: =B3+1 -> 3 | C4: =C3 -> 11 | D4: 2022 | E4: ='FS Seychelles'!B5 -> 71.4 | F4: ='FS Seychelles'!D5*1000 -> 2900 | G4: ='FS Seychelles'!E5*1000 -> 4310 | H4: ='FS Seychelles'!F5*1000 -> 5420 | I4: ='FS Seychelles'!G5*1000 -> 1410 | J4: ='FS Seychelles'!H5*1000 -> 1410 | K4: ='FS Seychelles'!I5*1000 -> 3980 | L4: ='FS Seychelles'!J5 -> 0 | M4: ='FS Seychelles'!K5 -> 8437 | N4: ='FS Seychelles'!L5 -> 12258 | O4: ='FS Seychelles'!M5 -> 4105 | P4: ='FS Seychelles'!N5 -> 12130 | Q4: ='FS Seychelles'!O5 -> 8113 | R4: ='FS Seychelles'!Q5 -> 0 | S4: ='FS Seychelles'!S5 -> 66 | T4: ='FS Seychelles'!T5 -> 5 | U4: ='FS Seychelles'!U5 -> 109 | V4: ='FS Seychelles'!V5 -> 104 | W4: ='FS Seychelles'!W5 -> 0 | X4: =('FS Seychelles'!Z11+'FS Seychelles'!Z17)/30 -> 0
A5: Seychelles | B5: =B4+1 -> 4 | C5: =C4 -> 11 | D5: 2022 | E5: ='FS Seychelles'!B6 -> 74 | F5: ='FS Seychelles'!D6*1000 -> 2870 | G5: ='FS Seychelles'!E6*1000 -> 4510 | H5: ='FS Seychelles'!F6*1000 -> 5540 | I5: ='FS Seychelles'!G6*1000 -> 1440 | J5: ='FS Seychelles'!H6*1000 -> 1440 | K5: ='FS Seychelles'!I6*1000 -> 4020 | L5: ='FS Seychelles'!J6 -> 0 | M5: ='FS Seychelles'!K6 -> 9950 | N5: ='FS Seychelles'!L6 -> 11102 | O5: ='FS Seychelles'!M6 -> 4561 | P5: ='FS Seychelles'!N6 -> 11057 | Q5: ='FS Seychelles'!O6 -> 7881 | R5: ='FS Seychelles'!Q6 -> 0 | S5: ='FS Seychelles'!S6 -> 64 | T5: ='FS Seychelles'!T6 -> 4 | U5: ='FS Seychelles'!U6 -> 97 | V5: ='FS Seychelles'!V6 -> 76 | W5: ='FS Seychelles'!W6 -> 0 | X5: =('FS Seychelles'!Z12+'FS Seychelles'!Z18)/30 -> 0
A6: Seychelles | B6: =B5+1 -> 5 | C6: =C5 -> 11 | D6: 2022 | E6: ='FS Seychelles'!B7 -> 64.9 | F6: ='FS Seychelles'!D7*1000 -> 2790 | G6: ='FS Seychelles'!E7*1000 -> 4400 | H6: ='FS Seychelles'!F7*1000 -> 5660 | I6: ='FS Seychelles'!G7*1000 -> 1430 | J6: ='FS Seychelles'!H7*1000 -> 1430 | K6: ='FS Seychelles'!I7*1000 -> 3870 | L6: ='FS Seychelles'!J7 -> 0 | M6: ='FS Seychelles'!K7 -> 7759 | N6: ='FS Seychelles'!L7 -> 8406 | O6: ='FS Seychelles'!M7 -> 10187 | P6: ='FS Seychelles'!N7 -> 10263 | Q6: ='FS Seychelles'!O7 -> 8513 | R6: ='FS Seychelles'!Q7 -> 0 | S6: ='FS Seychelles'!S7 -> 63 | T6: ='FS Seychelles'!T7 -> 13 | U6: ='FS Seychelles'!U7 -> 83 | V6: ='FS Seychelles'!V7 -> 100 | W6: ='FS Seychelles'!W7 -> 0 | X6: =('FS Seychelles'!Z13+'FS Seychelles'!Z19)/30 -> 0
A7: Seychelles | B7: =B6+1 -> 6 | C7: =C6 -> 11 | D7: 2022 | E7: ='FS Seychelles'!B8 -> 68.8 | F7: ='FS Seychelles'!D8*1000 -> 2540 | G7: ='FS Seychelles'!E8*1000 -> 3910 | H7: ='FS Seychelles'!F8*1000 -> 5490 | I7: ='FS Seychelles'!G8*1000 -> 1330 | J7: ='FS Seychelles'!H8*1000 -> 1330 | K7: ='FS Seychelles'!I8*1000 -> 3590 | L7: ='FS Seychelles'!J8 -> 0 | M7: ='FS Seychelles'!K8 -> 5577 | N7: ='FS Seychelles'!L8 -> 10731 | O7: ='FS Seychelles'!M8 -> 5511 | P7: ='FS Seychelles'!N8 -> 10581 | Q7: ='FS Seychelles'!O8 -> 7195 | R7: ='FS Seychelles'!Q8 -> 0 | S7: ='FS Seychelles'!S8 -> 54 | T7: ='FS Seychelles'!T8 -> 9 | U7: ='FS Seychelles'!U8 -> 76 | V7: ='FS Seychelles'!V8 -> 82 | W7: ='FS Seychelles'!W8 -> 0 | X7: =('FS Seychelles'!Z14+'FS Seychelles'!Z20)/30 -> 0
A8: Seychelles | B8: =B7+1 -> 7 | C8: =C7 -> 11 | D8: 2022 | E8: ='FS Seychelles'!B9 -> 74 | F8: ='FS Seychelles'!D9*1000 -> 2640 | G8: ='FS Seychelles'!E9*1000 -> 4220 | H8: ='FS Seychelles'!F9*1000 -> 5640 | I8: ='FS Seychelles'!G9*1000 -> 1440 | J8: ='FS Seychelles'!H9*1000 -> 1440 | K8: ='FS Seychelles'!I9*1000 -> 3920 | L8: ='FS Seychelles'!J9 -> 0 | M8: ='FS Seychelles'!K9 -> 2961 | N8: ='FS Seychelles'!L9 -> 10293 | O8: ='FS Seychelles'!M9 -> 10604 | P8: ='FS Seychelles'!N9 -> 9549 | Q8: ='FS Seychelles'!O9 -> 7544 | R8: ='FS Seychelles'!Q9 -> 0 | S8: ='FS Seychelles'!S9 -> 64 | T8: ='FS Seychelles'!T9 -> 11 | U8: ='FS Seychelles'!U9 -> 57 | V8: ='FS Seychelles'!V9 -> 86 | W8: ='FS Seychelles'!W9 -> 0 | X8: =('FS Seychelles'!Z15+'FS Seychelles'!Z21)/30 -> 295.66667
A9: Seychelles | B9: =B8+1 -> 8 | C9: =C8 -> 11 | D9: 2022 | E9: ='FS Seychelles'!B10 -> 68.8 | F9: ='FS Seychelles'!D10*1000 -> 2880 | G9: ='FS Seychelles'!E10*1000 -> 4470 | H9: ='FS Seychelles'!F10*1000 -> 5580 | I9: ='FS Seychelles'!G10*1000 -> 1380 | J9: ='FS Seychelles'!H10*1000 -> 1380 | K9: ='FS Seychelles'!I10*1000 -> 3960 | L9: ='FS Seychelles'!J10 -> 0 | M9: ='FS Seychelles'!K10 -> 10678 | N9: ='FS Seychelles'!L10 -> 10119 | O9: ='FS Seychelles'!M10 -> 5390 | P9: ='FS Seychelles'!N10 -> 10161 | Q9: ='FS Seychelles'!O10 -> 8074 | R9: ='FS Seychelles'!Q10 -> 0 | S9: ='FS Seychelles'!S10 -> 60 | T9: ='FS Seychelles'!T10 -> 4 | U9: ='FS Seychelles'!U10 -> 106 | V9: ='FS Seychelles'!V10 -> 120 | W9: ='FS Seychelles'!W10 -> 0 | X9: =('FS Seychelles'!Z16+'FS Seychelles'!Z22)/30 -> 0
A10: Seychelles | B10: =B9+1 -> 9 | C10: =C9 -> 11 | D10: 2022 | E10: ='FS Seychelles'!B11 -> 68.8 | F10: ='FS Seychelles'!D11*1000 -> 2970 | G10: ='FS Seychelles'!E11*1000 -> 4420 | H10: ='FS Seychelles'!F11*1000 -> 5610 | I10: ='FS Seychelles'!G11*1000 -> 1380 | J10: ='FS Seychelles'!H11*1000 -> 1380 | K10: ='FS Seychelles'!I11*1000 -> 3920 | L10: ='FS Seychelles'!J11 -> 0 | M10: ='FS Seychelles'!K11 -> 10175 | N10: ='FS Seychelles'!L11 -> 8645 | O10: ='FS Seychelles'!M11 -> 5077 | P10: ='FS Seychelles'!N11 -> 10119 | Q10: ='FS Seychelles'!O11 -> 7060 | R10: ='FS Seychelles'!Q11 -> 0 | S10: ='FS Seychelles'!S11 -> 72 | T10: ='FS Seychelles'!T11 -> 7 | U10: ='FS Seychelles'!U11 -> 40 | V10: ='FS Seychelles'!V11 -> 100 | W10: ='FS Seychelles'!W11 -> 0 | X10: =('FS Seychelles'!Z17+'FS Seychelles'!Z23)/30 -> 0
A11: Seychelles | B11: =B10+1 -> 10 | C11: =C10 -> 11 | D11: 2022 | E11: ='FS Seychelles'!B12 -> 68.8 | F11: ='FS Seychelles'!D12*1000 -> 3030 | G11: ='FS Seychelles'!E12*1000 -> 4420 | H11: ='FS Seychelles'!F12*1000 -> 5740 | I11: ='FS Seychelles'!G12*1000 -> 1400 | J11: ='FS Seychelles'!H12*1000 -> 1400 | K11: ='FS Seychelles'!I12*1000 -> 3900 | L11: ='FS Seychelles'!J12 -> 0 | M11: ='FS Seychelles'!K12 -> 10083 | N11: ='FS Seychelles'!L12 -> 12804 | O11: ='FS Seychelles'!M12 -> 1515 | P11: ='FS Seychelles'!N12 -> 8960 | Q11: ='FS Seychelles'!O12 -> 7229 | R11: ='FS Seychelles'!Q12 -> 0 | S11: ='FS Seychelles'!S12 -> 62 | T11: ='FS Seychelles'!T12 -> 4 | U11: ='FS Seychelles'!U12 -> 47 | V11: ='FS Seychelles'!V12 -> 56 | W11: ='FS Seychelles'!W12 -> 0 | X11: =('FS Seychelles'!Z18+'FS Seychelles'!Z24)/30 -> 0
A12: Seychelles | B12: =B11+1 -> 11 | C12: =C11 -> 11 | D12: 2022 | E12: ='FS Seychelles'!B13 -> 71.4 | F12: ='FS Seychelles'!D13*1000 -> 3060 | G12: ='FS Seychelles'!E13*1000 -> 4520 | H12: ='FS Seychelles'!F13*1000 -> 5650 | I12: ='FS Seychelles'!G13*1000 -> 1440 | J12: ='FS Seychelles'!H13*1000 -> 1440 | K12: ='FS Seychelles'!I13*1000 -> 3970 | L12: ='FS Seychelles'!J13 -> 0 | M12: ='FS Seychelles'!K13 -> 9928 | N12: ='FS Seychelles'!L13 -> 9840 | O12: ='FS Seychelles'!M13 -> 8738 | P12: ='FS Seychelles'!N13 -> 8476 | Q12: ='FS Seychelles'!O13 -> 7869 | R12: ='FS Seychelles'!Q13 -> 0 | S12: ='FS Seychelles'!S13 -> 63 | T12: ='FS Seychelles'!T13 -> 3 | U12: ='FS Seychelles'!U13 -> 73 | V12: ='FS Seychelles'!V13 -> 103 | W12: ='FS Seychelles'!W13 -> 0 | X12: =('FS Seychelles'!Z19+'FS Seychelles'!Z25)/30 -> 0
A13: Seychelles | B13: =B12+1 -> 12 | C13: =C12 -> 11 | D13: 2022 | E13: ='FS Seychelles'!B14 -> 55.8 | F13: ='FS Seychelles'!D14*1000 -> 3110 | G13: ='FS Seychelles'!E14*1000 -> 4440 | H13: ='FS Seychelles'!F14*1000 -> 5960 | I13: ='FS Seychelles'!G14*1000 -> 1400 | J13: ='FS Seychelles'!H14*1000 -> 1400 | K13: ='FS Seychelles'!I14*1000 -> 3850 | L13: ='FS Seychelles'!J14 -> 0 | M13: ='FS Seychelles'!K14 -> 10125 | N13: ='FS Seychelles'!L14 -> 3132 | O13: ='FS Seychelles'!M14 -> 10282 | P13: ='FS Seychelles'!N14 -> 10860 | Q13: ='FS Seychelles'!O14 -> 7894 | R13: ='FS Seychelles'!Q14 -> 0 | S13: ='FS Seychelles'!S14 -> 57 | T13: ='FS Seychelles'!T14 -> 8 | U13: ='FS Seychelles'!U14 -> 55 | V13: ='FS Seychelles'!V14 -> 100 | W13: ='FS Seychelles'!W14 -> 0 | X13: =('FS Seychelles'!Z20+'FS Seychelles'!Z26)/30 -> 0
A14: Seychelles | B14: =B13+1 -> 13 | C14: =C13 -> 11 | D14: 2022 | E14: ='FS Seychelles'!B15 -> 63.6 | F14: ='FS Seychelles'!D15*1000 -> 3160 | G14: ='FS Seychelles'!E15*1000 -> 4330 | H14: ='FS Seychelles'!F15*1000 -> 5540 | I14: ='FS Seychelles'!G15*1000 -> 1370 | J14: ='FS Seychelles'!H15*1000 -> 1370 | K14: ='FS Seychelles'!I15*1000 -> 3760 | L14: ='FS Seychelles'!J15 -> 0 | M14: ='FS Seychelles'!K15 -> 10886 | N14: ='FS Seychelles'!L15 -> 9732 | O14: ='FS Seychelles'!M15 -> 4424 | P14: ='FS Seychelles'!N15 -> 8198 | Q14: ='FS Seychelles'!O15 -> 7360 | R14: ='FS Seychelles'!Q15 -> 0 | S14: ='FS Seychelles'!S15 -> 59 | T14: ='FS Seychelles'!T15 -> 8 | U14: ='FS Seychelles'!U15 -> 76 | V14: ='FS Seychelles'!V15 -> 76 | W14: ='FS Seychelles'!W15 -> 0 | X14: =('FS Seychelles'!Z21+'FS Seychelles'!Z27)/30 -> 0
... A20: Seychelles | B20: =B19+1 -> 19 | C20: =C19 -> 11 | D20: 2022 | E20: ='FS Seychelles'!B21 -> 61 | F20: ='FS Seychelles'!D21*1000 -> 3100 | G20: ='FS Seychelles'!E21*1000 -> 4550 | H20: ='FS Seychelles'!F21*1000 -> 5960 | I20: ='FS Seychelles'!G21*1000 -> 1450 | J20: ='FS Seychelles'!H21*1000 -> 1450 | K20: ='FS Seychelles'!I21*1000 -> 3880 | L20: ='FS Seychelles'!J21 -> 0 | M20: ='FS Seychelles'!K21 -> 9999 | N20: ='FS Seychelles'!L21 -> 10663 | O20: ='FS Seychelles'!M21 -> 5529 | P20: ='FS Seychelles'!N21 -> 9576 | Q20: ='FS Seychelles'!O21 -> 8075 | R20: ='FS Seychelles'!Q21 -> 0 | S20: ='FS Seychelles'!S21 -> 61 | T20: ='FS Seychelles'!T21 -> 10 | U20: ='FS Seychelles'!U21 -> 84 | V20: ='FS Seychelles'!V21 -> 96 | W20: ='FS Seychelles'!W21 -> 0 | X20: =('FS Seychelles'!Z27+'FS Seychelles'!Z33)/30 -> 0
A21: Seychelles | B21: =B20+1 -> 20 | C21: =C20 -> 11 | D21: 2022 | E21: ='FS Seychelles'!B22 -> 63.6 | F21: ='FS Seychelles'!D22*1000 -> 2780 | G21: ='FS Seychelles'!E22*1000 -> 4390 | H21: ='FS Seychelles'!F22*1000 -> 5660 | I21: ='FS Seychelles'!G22*1000 -> 1420 | J21: ='FS Seychelles'!H22*1000 -> 1630 | K21: ='FS Seychelles'!I22*1000 -> 3790 | L21: ='FS Seychelles'!J22 -> 0 | M21: ='FS Seychelles'!K22 -> 10134 | N21: ='FS Seychelles'!L22 -> 11218 | O21: ='FS Seychelles'!M22 -> 5268 | P21: ='FS Seychelles'!N23 -> 8157 | Q21: ='FS Seychelles'!O22 -> 7124 | R21: ='FS Seychelles'!Q22 -> 0 | S21: ='FS Seychelles'!S22 -> 58 | T21: ='FS Seychelles'!T22 -> 6 | U21: ='FS Seychelles'!U22 -> 84 | V21: ='FS Seychelles'!V22 -> 70 | W21: ='FS Seychelles'!W22 -> 0 | X21: =('FS Seychelles'!Z28+'FS Seychelles'!Z34)/30 -> 0
A22: Seychelles | B22: =B21+1 -> 21 | C22: =C21 -> 11 | D22: 2022 | E22: ='FS Seychelles'!B23 -> 62.3 | F22: ='FS Seychelles'!D23*1000 -> 2390 | G22: ='FS Seychelles'!E23*1000 -> 3900 | H22: ='FS Seychelles'!F23*1000 -> 5370 | I22: ='FS Seychelles'!G23*1000 -> 1420 | J22: ='FS Seychelles'!H23*1000 -> 1700 | K22: ='FS Seychelles'!I23*1000 -> 3890 | L22: ='FS Seychelles'!J23 -> 0 | M22: ='FS Seychelles'!K23 -> 10219 | N22: ='FS Seychelles'!L23 -> 7629 | O22: ='FS Seychelles'!M23 -> 2470 | P22: ='FS Seychelles'!N24 -> 10938 | Q22: ='FS Seychelles'!O23 -> 7114 | R22: ='FS Seychelles'!Q23 -> 0 | S22: ='FS Seychelles'!S23 -> 64 | T22: ='FS Seychelles'!T23 -> 5 | U22: ='FS Seychelles'!U23 -> 62 | V22: ='FS Seychelles'!V23 -> 102 | W22: ='FS Seychelles'!W23 -> 0 | X22: =('FS Seychelles'!Z29+'FS Seychelles'!Z35)/30 -> 0
A23: Seychelles | B23: =B22+1 -> 22 | C23: =C22 -> 11 | D23: 2022 | E23: ='FS Seychelles'!B24 -> 63.6 | F23: ='FS Seychelles'!D24*1000 -> 2560 | G23: ='FS Seychelles'!E24*1000 -> 4280 | H23: ='FS Seychelles'!F24*1000 -> 5210 | I23: ='FS Seychelles'!G24*1000 -> 1440 | J23: ='FS Seychelles'!H24*1000 -> 1660 | K23: ='FS Seychelles'!I24*1000 -> 3760 | L23: ='FS Seychelles'!J24 -> 0 | M23: ='FS Seychelles'!K24 -> 6352 | N23: ='FS Seychelles'!L24 -> 7421 | O23: ='FS Seychelles'!M24 -> 11890 | P23: ='FS Seychelles'!N25 -> 0 | Q23: ='FS Seychelles'!O24 -> 7823 | R23: ='FS Seychelles'!Q24 -> 0 | S23: ='FS Seychelles'!S24 -> 60 | T23: ='FS Seychelles'!T24 -> 0 | U23: ='FS Seychelles'!U24 -> 78 | V23: ='FS Seychelles'!V24 -> 63 | W23: ='FS Seychelles'!W24 -> 0 | X23: =('FS Seychelles'!Z30+'FS Seychelles'!Z36)/30 -> 0
A24: Seychelles | B24: =B23+1 -> 23 | C24: =C23 -> 11 | D24: 2022 | E24: ='FS Seychelles'!B25 -> 64.9 | F24: ='FS Seychelles'!D25*1000 -> 3070 | G24: ='FS Seychelles'!E25*1000 -> 4570 | H24: ='FS Seychelles'!F25*1000 -> 5550 | I24: ='FS Seychelles'!G25*1000 -> 1380 | J24: ='FS Seychelles'!H25*1000 -> 1670 | K24: ='FS Seychelles'!I25*1000 -> 3890 | L24: ='FS Seychelles'!J25 -> 6533 | M24: ='FS Seychelles'!K25 -> 12520 | N24: ='FS Seychelles'!L25 -> 9106 | O24: ='FS Seychelles'!M25 -> 5680 | P24: ='FS Seychelles'!N25 -> 0 | Q24: ='FS Seychelles'!O25 -> 7593 | R24: ='FS Seychelles'!Q25 -> 0 | S24: ='FS Seychelles'!S25 -> 64 | T24: ='FS Seychelles'!T25 -> 7 | U24: ='FS Seychelles'!U25 -> 86 | V24: ='FS Seychelles'!V25 -> 54 | W24: ='FS Seychelles'!W25 -> 0 | X24: =('FS Seychelles'!Z31+'FS Seychelles'!Z37)/30 -> 0
A25: Seychelles | B25: =B24+1 -> 24 | C25: =C24 -> 11 | D25: 2022 | E25: ='FS Seychelles'!B26 -> 74 | F25: ='FS Seychelles'!D26*1000 -> 3100 | G25: ='FS Seychelles'!E26*1000 -> 4320 | H25: ='FS Seychelles'!F26*1000 -> 5690 | I25: ='FS Seychelles'!G26*1000 -> 1420 | J25: ='FS Seychelles'!H26*1000 -> 1640 | K25: ='FS Seychelles'!I26*1000 -> 3860 | L25: ='FS Seychelles'!J26 -> 12331 | M25: ='FS Seychelles'!K26 -> 10878 | N25: ='FS Seychelles'!L26 -> 0 | O25: ='FS Seychelles'!M26 -> 11004 | P25: ='FS Seychelles'!N26 -> 0 | Q25: ='FS Seychelles'!O26 -> 8058 | R25: ='FS Seychelles'!Q26 -> 0 | S25: ='FS Seychelles'!S26 -> 56 | T25: ='FS Seychelles'!T26 -> 1 | U25: ='FS Seychelles'!U26 -> 55 | V25: ='FS Seychelles'!V26 -> 106 | W25: ='FS Seychelles'!W26 -> 0 | X25: =('FS Seychelles'!Z32+'FS Seychelles'!Z38)/30 -> 0
A26: Seychelles | B26: =B25+1 -> 25 | C26: =C25 -> 11 | D26: 2022 | E26: ='FS Seychelles'!B27 -> 62.3 | F26: ='FS Seychelles'!D27*1000 -> 2810 | G26: ='FS Seychelles'!E27*1000 -> 4210 | H26: ='FS Seychelles'!F27*1000 -> 5340 | I26: ='FS Seychelles'!G27*1000 -> 1430 | J26: ='FS Seychelles'!H27*1000 -> 1650 | K26: ='FS Seychelles'!I27*1000 -> 3950 | L26: ='FS Seychelles'!J27 -> 3307 | M26: ='FS Seychelles'!K27 -> 14888 | N26: ='FS Seychelles'!L27 -> 0 | O26: ='FS Seychelles'!M27 -> 10936 | P26: ='FS Seychelles'!N27 -> 4355 | Q26: ='FS Seychelles'!O27 -> 7916 | R26: ='FS Seychelles'!Q27 -> 0 | S26: ='FS Seychelles'!S27 -> 58 | T26: ='FS Seychelles'!T27 -> 6 | U26: ='FS Seychelles'!U27 -> 75 | V26: ='FS Seychelles'!V27 -> 73 | W26: ='FS Seychelles'!W27 -> 0 | X26: =('FS Seychelles'!Z33+'FS Seychelles'!Z39)/30 -> 0
A27: Seychelles | B27: =B26+1 -> 26 | C27: =C26 -> 11 | D27: 2022 | E27: ='FS Seychelles'!B28 -> 53.2 | F27: ='FS Seychelles'!D28*1000 -> 3330 | G27: ='FS Seychelles'!E28*1000 -> 4530 | H27: ='FS Seychelles'!F28*1000 -> 5540 | I27: ='FS Seychelles'!G28*1000 -> 1430 | J27: ='FS Seychelles'!H28*1000 -> 1750 | K27: ='FS Seychelles'!I28*1000 -> 3920 | L27: ='FS Seychelles'!J28 -> 5514 | M27: ='FS Seychelles'!K28 -> 10318 | N27: ='FS Seychelles'!L28 -> 0 | O27: ='FS Seychelles'!M28 -> 0 | P27: ='FS Seychelles'!N28 -> 6032 | Q27: ='FS Seychelles'!O28 -> 4799 | R27: ='FS Seychelles'!Q28 -> 0 | S27: ='FS Seychelles'!S28 -> 66 | T27: ='FS Seychelles'!T28 -> 7 | U27: ='FS Seychelles'!U28 -> 82 | V27: ='FS Seychelles'!V28 -> 113 | W27: ='FS Seychelles'!W28 -> 0 | X27: =('FS Seychelles'!Z34+'FS Seychelles'!Z40)/30 -> 0
A28: Seychelles | B28: =B27+1 -> 27 | C28: =C27 -> 11 | D28: 2022 | E28: ='FS Seychelles'!B29 -> 64.9 | F28: ='FS Seychelles'!D29*1000 -> 3420 | G28: ='FS Seychelles'!E29*1000 -> 4910 | H28: ='FS Seychelles'!F29*1000 -> 5600 | I28: ='FS Seychelles'!G29*1000 -> 1440 | J28: ='FS Seychelles'!H29*1000 -> 1800 | K28: ='FS Seychelles'!I29*1000 -> 3950 | L28: ='FS Seychelles'!J29 -> 6857 | M28: ='FS Seychelles'!K29 -> 6628 | N28: ='FS Seychelles'!L29 -> 9415 | O28: ='FS Seychelles'!M29 -> 0 | P28: ='FS Seychelles'!N29 -> 13106 | Q28: ='FS Seychelles'!O29 -> 7460 | R28: ='FS Seychelles'!Q29 -> 0 | S28: ='FS Seychelles'!S29 -> 57 | T28: ='FS Seychelles'!T29 -> 5 | U28: ='FS Seychelles'!U29 -> 77 | V28: ='FS Seychelles'!V29 -> 100 | W28: ='FS Seychelles'!W29 -> 0 | X28: =('FS Seychelles'!Z35+'FS Seychelles'!Z41)/30 -> 0
A29: Seychelles | B29: =B28+1 -> 28 | C29: =C28 -> 11 | D29: 2022 | E29: ='FS Seychelles'!B30 -> 58.4 | F29: ='FS Seychelles'!D30*1000 -> 3780 | G29: ='FS Seychelles'!E30*1000 -> 4870 | H29: ='FS Seychelles'!F30*1000 -> 5800 | I29: ='FS Seychelles'!G30*1000 -> 1340 | J29: ='FS Seychelles'!H30*1000 -> 2040 | K29: ='FS Seychelles'!I30*1000 -> 4050 | L29: ='FS Seychelles'!J30 -> 5604 | M29: ='FS Seychelles'!K30 -> 8517 | N29: ='FS Seychelles'!L30 -> 13662 | O29: ='FS Seychelles'!M30 -> 0 | P29: ='FS Seychelles'!N30 -> 9757 | Q29: ='FS Seychelles'!O30 -> 8175 | R29: ='FS Seychelles'!Q30 -> 0 | S29: ='FS Seychelles'!S30 -> 67 | T29: ='FS Seychelles'!T30 -> 9 | U29: ='FS Seychelles'!U30 -> 95 | V29: ='FS Seychelles'!V30 -> 106 | W29: ='FS Seychelles'!W30 -> 0 | X29: =('FS Seychelles'!Z36+'FS Seychelles'!Z42)/30 -> 0
A30: Seychelles | B30: =B29+1 -> 29 | C30: =C29 -> 11 | D30: 2022 | E30: ='FS Seychelles'!B31 -> 50.9 | F30: ='FS Seychelles'!D31*1000 -> 3460 | G30: ='FS Seychelles'!E31*1000 -> 4610 | H30: ='FS Seychelles'!F31*1000 -> 5770 | I30: ='FS Seychelles'!G31*1000 -> 1440 | J30: ='FS Seychelles'!H31*1000 -> 1900 | K30: ='FS Seychelles'!I31*1000 -> 3980 | L30: ='FS Seychelles'!J31 -> 10010 | M30: ='FS Seychelles'!K31 -> 9904 | N30: ='FS Seychelles'!L31 -> 10946 | O30: ='FS Seychelles'!M31 -> 0 | P30: ='FS Seychelles'!N31 -> 6568 | Q30: ='FS Seychelles'!O31 -> 7743 | R30: ='FS Seychelles'!Q31 -> 0 | S30: ='FS Seychelles'!S31 -> 40 | T30: ='FS Seychelles'!T31 -> -11 | U30: ='FS Seychelles'!U31 -> 69 | V30: ='FS Seychelles'!V31 -> 78 | W30: ='FS Seychelles'!W31 -> 0 | X30: =('FS Seychelles'!Z37+'FS Seychelles'!Z43)/30 -> 0
A31: Seychelles | B31: =B30+1 -> 30 | C31: =C30 -> 11 | D31: 2022 | E31: ='FS Seychelles'!B32 -> 0 | F31: ='FS Seychelles'!D32*1000 -> 0 | G31: ='FS Seychelles'!E32*1000 -> 0 | H31: ='FS Seychelles'!F32*1000 -> 0 | I31: ='FS Seychelles'!G32*1000 -> 0 | J31: ='FS Seychelles'!H32*1000 -> 0 | K31: ='FS Seychelles'!I32*1000 -> 0 | L31: ='FS Seychelles'!J32 -> 0 | M31: ='FS Seychelles'!K32 -> 0 | N31: ='FS Seychelles'!L32 -> 0 | O31: ='FS Seychelles'!M32 -> 0 | P31: ='FS Seychelles'!N32 -> 0 | Q31: ='FS Seychelles'!O32 -> 0 | R31: ='FS Seychelles'!Q32 -> 0 | S31: ='FS Seychelles'!S32 -> 0 | T31: ='FS Seychelles'!T32 -> 0 | U31: ='FS Seychelles'!U32 -> 0 | V31: ='FS Seychelles'!V32 -> 0 | W31: ='FS Seychelles'!W32 -> 0 | X31: =('FS Seychelles'!Z38+'FS Seychelles'!Z44)/30 -> 0
A32: Seychelles

Sheet FS Seychelles
A2: DATE | B2: Room Night % | C2: Food Covers (Customers) | D2: SS-A (MWH) | E2: SS-B (MWH) | F2: SS-C (MWH) | G2: FIRE PUMP (MWH) | H2: CASINO (MWH) | I2: BOH (MWH) | J2: Generator#1 (KWH) | K2: Generator#2 (KWH) | L2: Generator#3 (KWH) | M2: Generator#4 (KWH) | N2: Generator#5 (KWH) | O2: DIESEL (Liter) | P2: DIESEL TARIFF (Euro/Liter) | Q2: PUC (KWh) | R2: PUC Tariff (Euro/KWh) | S2: BOH Water (m3) | T2: WT59 (m3) | U2: WT08 (m3) | V2: PUC HOH (m3) | W2: Fire Tank (m3) | X2: LPG (Kg) | AA2: STP Irrigation Water (m3) | AB2: Fire tank 250 (m3) | AC2: Comment
A3: 44866 | B3: 68.8 | C3: 472 | D3: ='EMS Gridvis'!B2 -> 2.88 | E3: ='EMS Gridvis'!C2 -> 4.54 | F3: ='EMS Gridvis'!D2 -> 5.44 | G3: ='EMS Gridvis'!H2 -> 1.45 | H3: ='EMS Gridvis'!I2 -> 1.45 | I3: ='EMS Gridvis'!J2 -> 3.96 | J3: =Generator!D4 -> 7113 | K3: =Generator!H4 -> 15674 | L3: =Generator!L4 -> 10502 | M3: =Generator!P4 -> 2301 | N3: =Generator!T4 -> 0 | O3: =SUM(Generator!C4,Generator!G4,Generator!K4,Generator!O4,Generator!S4) -> 7865 | P3: =24.03/13.49 -> 1.7813195 | R3: 1.84 | S3: ='RO Plant'!B4 -> 46 | T3: ='RO Plant'!N4 -> 18 | U3: ='RO Plant'!F4 -> 103 | V3: ='RO Plant'!I4 -> 102 | W3: ='RO Plant'!G4 -> 0 | X3: CYLINDER DELIVERY (KG) | AA3: =AB3-AC3 -> 135 | AB3: 51397 | AC3: 51262 | AD3: 44865
A4: 44867 | B4: 71.4 | C4: 485 | D4: ='EMS Gridvis'!B3 -> 2.63 | E4: ='EMS Gridvis'!C3 -> 4.24 | F4: ='EMS Gridvis'!D3 -> 5.43 | G4: ='EMS Gridvis'!H3 -> 1.43 | H4: ='EMS Gridvis'!I3 -> 1.43 | I4: ='EMS Gridvis'!J3 -> 3.88 | J4: =Generator!D5 -> 0 | K4: =Generator!H5 -> 9433 | L4: =Generator!L5 -> 9480 | M4: =Generator!P5 -> 5218 | N4: =Generator!T5 -> 9433 | O4: =SUM(Generator!C5,Generator!G5,Generator!K5,Generator!O5,Generator!S5) -> 7424 | P4: =24.03/13.49 -> 1.7813195 | R4: =R3 -> 1.84 | S4: ='RO Plant'!B5 -> 61 | T4: ='RO Plant'!N5 -> 3 | U4: ='RO Plant'!F5 -> 71 | V4: ='RO Plant'!I5 -> 103 | W4: ='RO Plant'!G5 -> 0 | X4: Unit (kg) | Y4: Quantity | Z4: Sub total | AA4: =AB4-AB3 -> 158 | AB4: 51555
A5: 44868 | B5: 71.4 | C5: 493 | D5: ='EMS Gridvis'!B4 -> 2.9 | E5: ='EMS Gridvis'!C4 -> 4.31 | F5: ='EMS Gridvis'!D4 -> 5.42 | G5: ='EMS Gridvis'!H4 -> 1.41 | H5: ='EMS Gridvis'!I4 -> 1.41 | I5: ='EMS Gridvis'!J4 -> 3.98 | J5: =Generator!D6 -> 0 | K5: =Generator!H6 -> 8437 | L5: =Generator!L6 -> 12258 | M5: =Generator!P6 -> 4105 | N5: =Generator!T6 -> 12130 | O5: =SUM(Generator!C6,Generator!G6,Generator!K6,Generator!O6,Generator!S6) -> 8113 | P5: =24.03/13.49 -> 1.7813195 | R5: =R4 -> 1.84 | S5: ='RO Plant'!B6 -> 66 | T5: ='RO Plant'!N6 -> 5 | U5: ='RO Plant'!F6 -> 109 | V5: ='RO Plant'!I6 -> 104 | W5: ='RO Plant'!G6 -> 0 | X5: 9 | Y5: 0 | Z5: =X5*Y5 -> 0 | AA5: =AB5-AB4 -> 100 | AB5: 51655
A6: 44869 | B6: 74 | C6: 533 | D6: ='EMS Gridvis'!B5 -> 2.87 | E6: ='EMS Gridvis'!C5 -> 4.51 | F6: ='EMS Gridvis'!D5 -> 5.54 | G6: ='EMS Gridvis'!H5 -> 1.44 | H6: ='EMS Gridvis'!I5 -> 1.44 | I6: ='EMS Gridvis'!J5 -> 4.02 | J6: =Generator!D7 -> 0 | K6: =Generator!H7 -> 9950 | L6: =Generator!L7 -> 11102 | M6: =Generator!P7 -> 4561 | N6: =Generator!T7 -> 11057 | O6: =SUM(Generator!C7,Generator!G7,Generator!K7,Generator!O7,Generator!S7) -> 7881 | P6: =24.03/13.49 -> 1.7813195 | R6: =R5 -> 1.84 | S6: ='RO Plant'!B7 -> 64 | T6: ='RO Plant'!N7 -> 4 | U6: ='RO Plant'!F7 -> 97 | V6: ='RO Plant'!I7 -> 76 | W6: ='RO Plant'!G7 -> 0 | X6: 10 | Y6: 0 | Z6: =X6*Y6 -> 0 | AA6: =AB6-AB5 -> 129 | AB6: 51784
A7: 44870 | B7: 64.9 | C7: 476 | D7: ='EMS Gridvis'!B6 -> 2.79 | E7: ='EMS Gridvis'!C6 -> 4.4 | F7: ='EMS Gridvis'!D6 -> 5.66 | G7: ='EMS Gridvis'!H6 -> 1.43 | H7: ='EMS Gridvis'!I6 -> 1.43 | I7: ='EMS Gridvis'!J6 -> 3.87 | J7: =Generator!D8 -> 0 | K7: =Generator!H8 -> 7759 | L7: =Generator!L8 -> 8406 | M7: =Generator!P8 -> 10187 | N7: =Generator!T8 -> 10263 | O7: =SUM(Generator!C8,Generator!G8,Generator!K8,Generator!O8,Generator!S8) -> 8513 | P7: =24.03/13.49 -> 1.7813195 | R7: =R6 -> 1.84 | S7: ='RO Plant'!B8 -> 63 | T7: ='RO Plant'!N8 -> 13 | U7: ='RO Plant'!F8 -> 83 | V7: ='RO Plant'!I8 -> 100 | W7: ='RO Plant'!G8 -> 0 | X7: 12 | Y7: 0 | Z7: =X7*Y7 -> 0 | AA7: =AB7-AB6 -> 120 | AB7: 51904
A8: 44871 | B8: 68.8 | C8: 463 | D8: ='EMS Gridvis'!B7 -> 2.54 | E8: ='EMS Gridvis'!C7 -> 3.91 | F8: ='EMS Gridvis'!D7 -> 5.49 | G8: ='EMS Gridvis'!H7 -> 1.33 | H8: ='EMS Gridvis'!I7 -> 1.33 | I8: ='EMS Gridvis'!J7 -> 3.59 | J8: =Generator!D9 -> 0 | K8: =Generator!H9 -> 5577 | L8: =Generator!L9 -> 10731 | M8: =Generator!P9 -> 5511 | N8: =Generator!T9 -> 10581 | O8: =SUM(Generator!C9,Generator!G9,Generator!K9,Generator!O9,Generator!S9) -> 7195 | P8: =24.03/13.49 -> 1.7813195 | R8: =R7 -> 1.84 | S8: ='RO Plant'!B9 -> 54 | T8: ='RO Plant'!N9 -> 9 | U8: ='RO Plant'!F9 -> 76 | V8: ='RO Plant'!I9 -> 82 | W8: ='RO Plant'!G9 -> 0 | X8: 20 | Y8: 0 | Z8: =X8*Y8 -> 0 | AA8: =AB8-AB7 -> 156 | AB8: 52060
A9: 44872 | B9: 74 | C9: 412 | D9: ='EMS Gridvis'!B8 -> 2.64 | E9: ='EMS Gridvis'!C8 -> 4.22 | F9: ='EMS Gridvis'!D8 -> 5.64 | G9: ='EMS Gridvis'!H8 -> 1.44 | H9: ='EMS Gridvis'!I8 -> 1.44 | I9: ='EMS Gridvis'!J8 -> 3.92 | J9: =Generator!D10 -> 0 | K9: =Generator!H10 -> 2961 | L9: =Generator!L10 -> 10293 | M9: =Generator!P10 -> 10604 | N9: =Generator!T10 -> 9549 | O9: =SUM(Generator!C10,Generator!G10,Generator!K10,Generator!O10,Generator!S10) -> 7544 | P9: =24.03/13.49 -> 1.7813195 | R9: =R8 -> 1.84 | S9: ='RO Plant'!B10 -> 64 | T9: ='RO Plant'!N10 -> 11 | U9: ='RO Plant'!F10 -> 57 | V9: ='RO Plant'!I10 -> 86 | W9: ='RO Plant'!G10 -> 0 | X9: 24 | Y9: 0 | Z9: =X9*Y9 -> 0 | AA9: =AB9-AB8 -> 163 | AB9: 52223
A10: 44873 | B10: 68.8 | C10: 370 | D10: ='EMS Gridvis'!B9 -> 2.88 | E10: ='EMS Gridvis'!C9 -> 4.47 | F10: ='EMS Gridvis'!D9 -> 5.58 | G10: ='EMS Gridvis'!H9 -> 1.38 | H10: ='EMS Gridvis'!I9 -> 1.38 | I10: ='EMS Gridvis'!J9 -> 3.96 | J10: =Generator!D11 -> 0 | K10: =Generator!H11 -> 10678 | L10: =Generator!L11 -> 10119 | M10: =Generator!P11 -> 5390 | N10: =Generator!T11 -> 10161 | O10: =SUM(Generator!C11,Generator!G11,Generator!K11,Generator!O11,Generator!S11) -> 8074 | P10: =24.03/13.49 -> 1.7813195 | R10: =25.21/13.6813 -> 1.8426612 | S10: ='RO Plant'!B11 -> 60 | T10: ='RO Plant'!N11 -> 4 | U10: ='RO Plant'!F11 -> 106 | V10: ='RO Plant'!I11 -> 120 | W10: ='RO Plant'!G11 -> 0 | Y10: Total | Z10: =SUM(Z5:Z9) -> 0 | AA10: =AB10-AB9 -> 105 | AB10: 52328
A11: 44874 | B11: 68.8 | C11: 372 | D11: ='EMS Gridvis'!B10 -> 2.97 | E11: ='EMS Gridvis'!C10 -> 4.42 | F11: ='EMS Gridvis'!D10 -> 5.61 | G11: ='EMS Gridvis'!H10 -> 1.38 | H11: ='EMS Gridvis'!I10 -> 1.38 | I11: ='EMS Gridvis'!J10 -> 3.92 | J11: =Generator!D12 -> 0 | K11: =Generator!H12 -> 10175 | L11: =Generator!L12 -> 8645 | M11: =Generator!P12 -> 5077 | N11: =Generator!T12 -> 10119 | O11: =SUM(Generator!C12,Generator!G12,Generator!K12,Generator!O12,Generator!S12) -> 7060 | P11: =24.03/13.49 -> 1.7813195 | R11: =R10 -> 1.8426612 | S11: ='RO Plant'!B12 -> 72 | T11: ='RO Plant'!N12 -> 7 | U11: ='RO Plant'!F12 -> 40 | V11: ='RO Plant'!I12 -> 100 | W11: ='RO Plant'!G12 -> 0 | X11: TRUCK DELIVERY (KG) | AA11: =AB11-AB10 -> 99 | AB11: 52427
A12: 44875 | B12: 68.8 | C12: 428 | D12: ='EMS Gridvis'!B11 -> 3.03 | E12: ='EMS Gridvis'!C11 -> 4.42 | F12: ='EMS Gridvis'!D11 -> 5.74 | G12: ='EMS Gridvis'!H11 -> 1.4 | H12: ='EMS Gridvis'!I11 -> 1.4 | I12: ='EMS Gridvis'!J11 -> 3.9 | J12: =Generator!D13 -> 0 | K12: =Generator!H13 -> 10083 | L12: =Generator!L13 -> 12804 | M12: =Generator!P13 -> 1515 | N12: =Generator!T13 -> 8960 | O12: =SUM(Generator!C13,Generator!G13,Generator!K13,Generator!O13,Generator!S13) -> 7229 | P12: =24.03/13.49 -> 1.7813195 | R12: =R11 -> 1.8426612 | S12: ='RO Plant'!B13 -> 62 | T12: ='RO Plant'!N13 -> 4 | U12: ='RO Plant'!F13 -> 47 | V12: ='RO Plant'!I13 -> 56 | W12: ='RO Plant'!G13 -> 0 | Y12: Sub Total | AA12: =AB12-AB11 -> 126 | AB12: 52553
A13: 44876 | B13: 71.4 | C13: 400 | D13: ='EMS Gridvis'!B12 -> 3.06 | E13: ='EMS Gridvis'!C12 -> 4.52 | F13: ='EMS Gridvis'!D12 -> 5.65 | G13: ='EMS Gridvis'!H12 -> 1.44 | H13: ='EMS Gridvis'!I12 -> 1.44 | I13: ='EMS Gridvis'!J12 -> 3.97 | J13: =Generator!D14 -> 0 | K13: =Generator!H14 -> 9928 | L13: =Generator!L14 -> 9840 | M13: =Generator!P14 -> 8738 | N13: =Generator!T14 -> 8476 | O13: =SUM(Generator!C14,Generator!G14,Generator!K14,Generator!O14,Generator!S14) -> 7869 | P13: =24.03/13.49 -> 1.7813195 | R13: =R12 -> 1.8426612 | S13: ='RO Plant'!B14 -> 63 | T13: ='RO Plant'!N14 -> 3 | U13: ='RO Plant'!F14 -> 73 | V13: ='RO Plant'!I14 -> 103 | W13: ='RO Plant'!G14 -> 0 | X13: Sitronel | Y13: 5250 | AA13: =AB13-AB12 -> 104 | AB13: 52657
A14: 44877 | B14: 55.8 | C14: 390 | D14: ='EMS Gridvis'!B13 -> 3.11 | E14: ='EMS Gridvis'!C13 -> 4.44 | F14: ='EMS Gridvis'!D13 -> 5.96 | G14: ='EMS Gridvis'!H13 -> 1.4 | H14: ='EMS Gridvis'!I13 -> 1.4 | I14: ='EMS Gridvis'!J13 -> 3.85 | J14: =Generator!D15 -> 0 | K14: =Generator!H15 -> 10125 | L14: =Generator!L15 -> 3132 | M14: =Generator!P15 -> 10282 | N14: =Generator!T15 -> 10860 | O14: =SUM(Generator!C15,Generator!G15,Generator!K15,Generator!O15,Generator!S15) -> 7894 | P14: =24.03/13.49 -> 1.7813195 | R14: =R13 -> 1.8426612 | S14: ='RO Plant'!B15 -> 57 | T14: ='RO Plant'!N15 -> 8 | U14: ='RO Plant'!F15 -> 55 | V14: ='RO Plant'!I15 -> 100 | W14: ='RO Plant'!G15 -> 0 | X14: Zez | Y14: 3620 | AA14: =AB14-AB13 -> 163 | AB14: 52820
A15: 44878 | B15: 63.6 | C15: 368 | D15: ='EMS Gridvis'!B14 -> 3.16 | E15: ='EMS Gridvis'!C14 -> 4.33 | F15: ='EMS Gridvis'!D14 -> 5.54 | G15: ='EMS Gridvis'!H14 -> 1.37 | H15: ='EMS Gridvis'!I14 -> 1.37 | I15: ='EMS Gridvis'!J14 -> 3.76 | J15: =Generator!D16 -> 0 | K15: =Generator!H16 -> 10886 | L15: =Generator!L16 -> 9732 | M15: =Generator!P16 -> 4424 | N15: =Generator!T16 -> 8198 | O15: =SUM(Generator!C16,Generator!G16,Generator!K16,Generator!O16,Generator!S16) -> 7360 | P15: =24.03/13.49 -> 1.7813195 | R15: =R14 -> 1.8426612 | S15: ='RO Plant'!B16 -> 59 | T15: ='RO Plant'!N16 -> 8 | U15: ='RO Plant'!F16 -> 76 | V15: ='RO Plant'!I16 -> 76 | W15: ='RO Plant'!G16 -> 0 | Y15: Total | Z15: =SUM(Y13:Z14) -> 8870 | AA15: =AB15-AB14 -> 102 | AB15: 52922
A16: 44879 | B16: 49.4 | C16: 297 | D16: ='EMS Gridvis'!B15 -> 3.2 | E16: ='EMS Gridvis'!C15 -> 4.23 | F16: ='EMS Gridvis'!D15 -> 5.41 | G16: ='EMS Gridvis'!H15 -> 1.38 | H16: ='EMS Gridvis'!I15 -> 1.38 | I16: ='EMS Gridvis'!J15 -> 3.98 | J16: =Generator!D17 -> 0 | K16: =Generator!H17 -> 8443 | L16: =Generator!L17 -> 6902 | M16: =Generator!P17 -> 6491 | N16: =Generator!T17 -> 11969 | O16: =SUM(Generator!C17,Generator!G17,Generator!K17,Generator!O17,Generator!S17) -> 7598 | P16: =24.03/13.49 -> 1.7813195 | R16: =R15 -> 1.8426612 | S16: ='RO Plant'!B17 -> 59 | T16: ='RO Plant'!N17 -> 3 | U16: ='RO Plant'!F17 -> 66 | V16: ='RO Plant'!I17 -> 49 | W16: ='RO Plant'!G17 -> 0 | AA16: =AB16-AB15 -> 91 | AB16: 53013
A17: 44880 | B17: 51.9 | C17: 306 | D17: ='EMS Gridvis'!B16 -> 3.46 | E17: ='EMS Gridvis'!C16 -> 4.39 | F17: ='EMS Gridvis'!D16 -> 5.68 | G17: ='EMS Gridvis'!H16 -> 1.38 | H17: ='EMS Gridvis'!I16 -> 1.38 | I17: ='EMS Gridvis'!J16 -> 3.99 | J17: =Generator!D18 -> 0 | K17: =Generator!H18 -> 14676 | L17: =Generator!L18 -> 9787 | M17: =Generator!P18 -> 0 | N17: =Generator!T18 -> 10014 | O17: =SUM(Generator!C18,Generator!G18,Generator!K18,Generator!O18,Generator!S18) -> 7369 | P17: =24.03/13.49 -> 1.7813195 | R17: =R16 -> 1.8426612 | S17: ='RO Plant'!B18 -> 62 | T17: ='RO Plant'!N18 -> 9 | U17: ='RO Plant'!F18 -> 71 | V17: ='RO Plant'!I18 -> 94 | W17: ='RO Plant'!G18 -> 0 | AA17: =AB17-AB16 -> 124 | AB17: 53137
A18: 44881 | B18: 54.5 | C18: 308 | D18: ='EMS Gridvis'!B17 -> 3.28 | E18: ='EMS Gridvis'!C17 -> 4.4 | F18: ='EMS Gridvis'!D17 -> 5.7 | G18: ='EMS Gridvis'!H17 -> 1.4 | H18: ='EMS Gridvis'!I17 -> 1.4 | I18: ='EMS Gridvis'!J17 -> 3.94 | J18: =Generator!D19 -> 0 | K18: =Generator!H19 -> 11672 | L18: =Generator!L19 -> 14180 | M18: =Generator!P19 -> 0 | N18: =Generator!T19 -> 9465 | O18: =SUM(Generator!C19,Generator!G19,Generator!K19,Generator!O19,Generator!S19) -> 7492 | P18: =24.03/13.49 -> 1.7813195 | R18: =R17 -> 1.8426612 | S18: ='RO Plant'!B19 -> 62 | T18: ='RO Plant'!N19 -> 3 | U18: ='RO Plant'!F19 -> 73 | V18: ='RO Plant'!I19 -> 101 | W18: ='RO Plant'!G19 -> 0 | AA18: =AB18-AB17 -> 128 | AB18: 53265
A19: 44882 | B19: 66.2 | C19: 367 | D19: ='EMS Gridvis'!B18 -> 3.23 | E19: ='EMS Gridvis'!C18 -> 4.6 | F19: ='EMS Gridvis'!D18 -> 5.87 | G19: ='EMS Gridvis'!H18 -> 1.45 | H19: ='EMS Gridvis'!I18 -> 1.45 | I19: ='EMS Gridvis'!J18 -> 4.01 | J19: =Generator!D20 -> 0 | K19: =Generator!H20 -> 7179 | L19: =Generator!L20 -> 10312 | M19: =Generator!P20 -> 8059 | N19: =Generator!T20 -> 9757 | O19: =SUM(Generator!C20,Generator!G20,Generator!K20,Generator!O20,Generator!S20) -> 8013 | P19: =24.03/13.49 -> 1.7813195 | R19: =R18 -> 1.8426612 | S19: ='RO Plant'!B20 -> 57 | T19: ='RO Plant'!N20 -> 28 | U19: ='RO Plant'!F20 -> 79 | V19: ='RO Plant'!I20 -> 96 | W19: ='RO Plant'!G20 -> 0 | AA19: =AB19-AB18 -> 133 | AB19: 53398
A20: 44883 | B20: 57.1 | C20: 396 | D20: ='EMS Gridvis'!B19 -> 3.32 | E20: ='EMS Gridvis'!C19 -> 4.84 | F20: ='EMS Gridvis'!D19 -> 6.03 | G20: ='EMS Gridvis'!H19 -> 1.46 | H20: ='EMS Gridvis'!I19 -> 1.46 | I20: ='EMS Gridvis'!J19 -> 4.05 | J20: =Generator!D21 -> 0 | K20: =Generator!H21 -> 10122 | L20: =Generator!L21 -> 5331 | M20: =Generator!P21 -> 8326 | N20: =Generator!T21 -> 12673 | O20: =SUM(Generator!C21,Generator!G21,Generator!K21,Generator!O21,Generator!S21) -> 8176 | P20: =24.03/13.49 -> 1.7813195 | R20: =R19 -> 1.8426612 | S20: ='RO Plant'!B21 -> 67 | T20: ='RO Plant'!N21 -> 14 | U20: ='RO Plant'!F21 -> 53 | V20: ='RO Plant'!I21 -> 100 | W20: ='RO Plant'!G21 -> 0 | AA20: =AB20-AB19 -> 115 | AB20: 53513
A21: 44884 | B21: 61 | C21: 337 | D21: ='EMS Gridvis'!B20 -> 3.1 | E21: ='EMS Gridvis'!C20 -> 4.55 | F21: ='EMS Gridvis'!D20 -> 5.96 | G21: ='EMS Gridvis'!H20 -> 1.45 | H21: ='EMS Gridvis'!I20 -> 1.45 | I21: ='EMS Gridvis'!J20 -> 3.88 | J21: =Generator!D22 -> 0 | K21: =Generator!H22 -> 9999 | L21: =Generator!L22 -> 10663 | M21: =Generator!P22 -> 5529 | N21: =Generator!T22 -> 9576 | O21: =SUM(Generator!C22,Generator!G22,Generator!K22,Generator!O22,Generator!S22) -> 8075 | P21: =24.03/13.49 -> 1.7813195 | R21: =R20 -> 1.8426612 | S21: ='RO Plant'!B22 -> 61 | T21: ='RO Plant'!N22 -> 10 | U21: ='RO Plant'!F22 -> 84 | V21: ='RO Plant'!I22 -> 96 | W21: ='RO Plant'!G22 -> 0 | AA21: =AB21-AB20 -> 7 | AB21: 53520
A22: 44885 | B22: 63.6 | C22: 331 | D22: ='EMS Gridvis'!B21 -> 2.78 | E22: ='EMS Gridvis'!C21 -> 4.39 | F22: ='EMS Gridvis'!D21 -> 5.66 | G22: ='EMS Gridvis'!H21 -> 1.42 | H22: ='EMS Gridvis'!I21 -> 1.63 | I22: ='EMS Gridvis'!J21 -> 3.79 | J22: =Generator!D23 -> 0 | K22: =Generator!H23 -> 10134 | L22: =Generator!L23 -> 11218 | M22: =Generator!P23 -> 5268 | N22: =Generator!T23 -> 7364 | O22: =SUM(Generator!C23,Generator!G23,Generator!K23,Generator!O23,Generator!S23) -> 7124 | P22: =24.03/13.49 -> 1.7813195 | R22: =R21 -> 1.8426612 | S22: ='RO Plant'!B23 -> 58 | T22: ='RO Plant'!N23 -> 6 | U22: ='RO Plant'!F23 -> 84 | V22: ='RO Plant'!I23 -> 70 | W22: ='RO Plant'!G23 -> 0 | AA22: =AB22-AB21 -> -53520
A23: 44886 | B23: 62.3 | C23: 319 | D23: ='EMS Gridvis'!B22 -> 2.39 | E23: ='EMS Gridvis'!C22 -> 3.9 | F23: ='EMS Gridvis'!D22 -> 5.37 | G23: ='EMS Gridvis'!H22 -> 1.42 | H23: ='EMS Gridvis'!I22 -> 1.7 | I23: ='EMS Gridvis'!J22 -> 3.89 | J23: =Generator!D24 -> 0 | K23: =Generator!H24 -> 10219 | L23: =Generator!L24 -> 7629 | M23: =Generator!P24 -> 2470 | N23: =Generator!T24 -> 8157 | O23: =SUM(Generator!C24,Generator!G24,Generator!K24,Generator!O24,Generator!S24) -> 7114 | P23: =24.03/13.49 -> 1.7813195 | R23: =R22 -> 1.8426612 | S23: ='RO Plant'!B24 -> 64 | T23: ='RO Plant'!N24 -> 5 | U23: ='RO Plant'!F24 -> 62 | V23: ='RO Plant'!I24 -> 102 | W23: ='RO Plant'!G24 -> 0 | AB23: =AVERAGE(AB3:AB22) -> 52533.211
A24: 44887 | B24: 63.6 | C24: 322 | D24: ='EMS Gridvis'!B23 -> 2.56 | E24: ='EMS Gridvis'!C23 -> 4.28 | F24: ='EMS Gridvis'!D23 -> 5.21 | G24: ='EMS Gridvis'!H23 -> 1.44 | H24: ='EMS Gridvis'!I23 -> 1.66 | I24: ='EMS Gridvis'!J23 -> 3.76 | J24: =Generator!D25 -> 0 | K24: =Generator!H25 -> 6352 | L24: =Generator!L25 -> 7421 | M24: =Generator!P25 -> 11890 | N24: =Generator!T25 -> 10938 | O24: =SUM(Generator!C25,Generator!G25,Generator!K25,Generator!O25,Generator!S25) -> 7823 | P24: =24.03/13.49 -> 1.7813195 | R24: =R23 -> 1.8426612 | S24: ='RO Plant'!B25 -> 60 | T24: ='RO Plant'!N25 -> 0 | U24: ='RO Plant'!F25 -> 78 | V24: ='RO Plant'!I25 -> 63 | W24: ='RO Plant'!G25 -> 0
A25: 44888 | B25: 64.9 | C25: 326 | D25: ='EMS Gridvis'!B24 -> 3.07 | E25: ='EMS Gridvis'!C24 -> 4.57 | F25: ='EMS Gridvis'!D24 -> 5.55 | G25: ='EMS Gridvis'!H24 -> 1.38 | H25: ='EMS Gridvis'!I24 -> 1.67 | I25: ='EMS Gridvis'!J24 -> 3.89 | J25: =Generator!D26 -> 6533 | K25: =Generator!H26 -> 12520 | L25: =Generator!L26 -> 9106 | M25: =Generator!P26 -> 5680 | N25: =Generator!T26 -> 0 | O25: =SUM(Generator!C26,Generator!G26,Generator!K26,Generator!O26,Generator!S26) -> 7593 | P25: =24.03/13.49 -> 1.7813195 | R25: =R24 -> 1.8426612 | S25: ='RO Plant'!B26 -> 64 | T25: ='RO Plant'!N26 -> 7 | U25: ='RO Plant'!F26 -> 86 | V25: ='RO Plant'!I26 -> 54 | W25: ='RO Plant'!G26 -> 0 | AB25: 53572
A26: 44889 | B26: 74 | C26: 357 | D26: ='EMS Gridvis'!B25 -> 3.1 | E26: ='EMS Gridvis'!C25 -> 4.32 | F26: ='EMS Gridvis'!D25 -> 5.69 | G26: ='EMS Gridvis'!H25 -> 1.42 | H26: ='EMS Gridvis'!I25 -> 1.64 | I26: ='EMS Gridvis'!J25 -> 3.86 | J26: =Generator!D27 -> 12331 | K26: =Generator!H27 -> 10878 | L26: =Generator!L27 -> 0 | M26: =Generator!P27 -> 11004 | N26: =Generator!T27 -> 0 | O26: =SUM(Generator!C27,Generator!G27,Generator!K27,Generator!O27,Generator!S27) -> 8058 | P26: =24.03/13.49 -> 1.7813195 | R26: =R25 -> 1.8426612 | S26: ='RO Plant'!B27 -> 56 | T26: ='RO Plant'!N27 -> 1 | U26: ='RO Plant'!F27 -> 55 | V26: ='RO Plant'!I27 -> 106 | W26: ='RO Plant'!G27 -> 0 | AA26: =AB26-AB25 -> 95 | AB26: 53667
A27: 44890 | B27: 62.3 | C27: 403 | D27: ='EMS Gridvis'!B26 -> 2.81 | E27: ='EMS Gridvis'!C26 -> 4.21 | F27: ='EMS Gridvis'!D26 -> 5.34 | G27: ='EMS Gridvis'!H26 -> 1.43 | H27: ='EMS Gridvis'!I26 -> 1.65 | I27: ='EMS Gridvis'!J26 -> 3.95 | J27: =Generator!D28 -> 3307 | K27: =Generator!H28 -> 14888 | L27: =Generator!L28 -> 0 | M27: =Generator!P28 -> 10936 | N27: =Generator!T28 -> 4355 | O27: =SUM(Generator!C28,Generator!G28,Generator!K28,Generator!O28,Generator!S28) -> 7916 | P27: =24.03/13.49 -> 1.7813195 | R27: =R26 -> 1.8426612 | S27: ='RO Plant'!B28 -> 58 | T27: ='RO Plant'!N28 -> 6 | U27: ='RO Plant'!F28 -> 75 | V27: ='RO Plant'!I28 -> 73 | W27: ='RO Plant'!G28 -> 0 | AA27: =AB27-AB26 -> 113 | AB27: 53780
A28: 44891 | B28: 53.2 | C28: 377 | D28: ='EMS Gridvis'!B27 -> 3.33 | E28: ='EMS Gridvis'!C27 -> 4.53 | F28: ='EMS Gridvis'!D27 -> 5.54 | G28: ='EMS Gridvis'!H27 -> 1.43 | H28: ='EMS Gridvis'!I27 -> 1.75 | I28: ='EMS Gridvis'!J27 -> 3.92 | J28: =Generator!D29 -> 5514 | K28: =Generator!H29 -> 10318 | L28: =Generator!L29 -> 0 | M28: =Generator!P29 -> 0 | N28: =Generator!T29 -> 6032 | O28: =SUM(Generator!C29,Generator!G29,Generator!K29,Generator!O29,Generator!S29) -> 4799 | P28: =24.03/13.49 -> 1.7813195 | R28: =R27 -> 1.8426612 | S28: ='RO Plant'!B29 -> 66 | T28: ='RO Plant'!N29 -> 7 | U28: ='RO Plant'!F29 -> 82 | V28: ='RO Plant'!I29 -> 113 | W28: ='RO Plant'!G29 -> 0 | AA28: =AB28-AB27 -> 102 | AB28: 53882
A29: 44892 | B29: 64.9 | C29: 376 | D29: ='EMS Gridvis'!B28 -> 3.42 | E29: ='EMS Gridvis'!C28 -> 4.91 | F29: ='EMS Gridvis'!D28 -> 5.6 | G29: ='EMS Gridvis'!H28 -> 1.44 | H29: ='EMS Gridvis'!I28 -> 1.8 | I29: ='EMS Gridvis'!J28 -> 3.95 | J29: =Generator!D30 -> 6857 | K29: =Generator!H30 -> 6628 | L29: =Generator!L30 -> 9415 | M29: =Generator!P30 -> 0 | N29: =Generator!T30 -> 13106 | O29: =SUM(Generator!C30,Generator!G30,Generator!K30,Generator!O30,Generator!S30) -> 7460 | P29: =24.03/13.49 -> 1.7813195 | R29: =R28 -> 1.8426612 | S29: ='RO Plant'!B30 -> 57 | T29: ='RO Plant'!N30 -> 5 | U29: ='RO Plant'!F30 -> 77 | V29: ='RO Plant'!I30 -> 100 | W29: ='RO Plant'!G30 -> 0 | AA29: =AB29-AB28 -> 143 | AB29: 54025
A30: 44893 | B30: 58.4 | C30: 383 | D30: ='EMS Gridvis'!B29 -> 3.78 | E30: ='EMS Gridvis'!C29 -> 4.87 | F30: ='EMS Gridvis'!D29 -> 5.8 | G30: ='EMS Gridvis'!H29 -> 1.34 | H30: ='EMS Gridvis'!I29 -> 2.04 | I30: ='EMS Gridvis'!J29 -> 4.05 | J30: =Generator!D31 -> 5604 | K30: =Generator!H31 -> 8517 | L30: =Generator!L31 -> 13662 | M30: =Generator!P31 -> 0 | N30: =Generator!T31 -> 9757 | O30: =SUM(Generator!C31,Generator!G31,Generator!K31,Generator!O31,Generator!S31) -> 8175 | P30: =24.03/13.49 -> 1.7813195 | R30: =R29 -> 1.8426612 | S30: ='RO Plant'!B31 -> 67 | T30: ='RO Plant'!N31 -> 9 | U30: ='RO Plant'!F31 -> 95 | V30: ='RO Plant'!I31 -> 106 | W30: ='RO Plant'!G31 -> 0 | AA30: =AB30-AB29 -> 133 | AB30: 54158
A31: 44894 | B31: 50.9 | C31: 363 | D31: ='EMS Gridvis'!B30 -> 3.46 | E31: ='EMS Gridvis'!C30 -> 4.61 | F31: ='EMS Gridvis'!D30 -> 5.77 | G31: ='EMS Gridvis'!H30 -> 1.44 | H31: ='EMS Gridvis'!I30 -> 1.9 | I31: ='EMS Gridvis'!J30 -> 3.98 | J31: =Generator!D32 -> 10010 | K31: =Generator!H32 -> 9904 | L31: =Generator!L32 -> 10946 | M31: =Generator!P32 -> 0 | N31: =Generator!T32 -> 6568 | O31: =SUM(Generator!C32,Generator!G32,Generator!K32,Generator!O32,Generator!S32) -> 7743 | P31: =24.03/13.49 -> 1.7813195 | R31: =R30 -> 1.8426612 | S31: ='RO Plant'!B32 -> 40 | T31: ='RO Plant'!N32 -> -11 | U31: ='RO Plant'!F32 -> 69 | V31: ='RO Plant'!I32 -> 78 | W31: ='RO Plant'!G32 -> 0 | AA31: =AB31-AB30 -> 115 | AB31: 54273
A32: 44895 | D32: ='EMS Gridvis'!B31 -> 0 | E32: ='EMS Gridvis'!C31 -> 0 | F32: ='EMS Gridvis'!D31 -> 0 | G32: ='EMS Gridvis'!H31 -> 0 | H32: ='EMS Gridvis'!I31 -> 0 | I32: ='EMS Gridvis'!J31 -> 0 | J32: =Generator!D33 -> 0 | K32: =Generator!H33 -> 0 | L32: =Generator!L33 -> 0 | M32: =Generator!P33 -> 0 | N32: =Generator!T33 -> 0 | O32: =SUM(Generator!C33,Generator!G33,Generator!K33,Generator!O33,Generator!S33) -> 0 | P32: =24.03/13.49 -> 1.7813195 | R32: =R31 -> 1.8426612 | S32: ='RO Plant'!B33 -> 0 | T32: ='RO Plant'!N33 -> 0 | U32: ='RO Plant'!F33 -> 0 | V32: ='RO Plant'!I33 -> 0 | W32: ='RO Plant'!G33 -> 0 | AA32: =AB32-AB31 -> -54273

Sheet RO Plant
A1: Location | B1: BOH | C1: E-Resort | D1: North RVs | E1: Kannel,300,400,500,600,SRV,300,400 | F1: Zez,SPA,MV,100,200 | G1: STP | H1: From E-Resort | I1: BOH | J1: SRV | N1: Formula
A2: DATE | B2: BOH Water (m3) | C2: E-Resort (m3) | D2: North RVs (m3) | E2: WT59 (m3) | F2: WT08 (m3) | G2: Fire Tank (m3) | H2: PUC (E- Resort) (m3) | I2: PUC HOH (m3) | J2: SRV1 (m3) | K2: SRV2 (m3) | L2: SRV3 (m3) | N2: Excluding all SRVs
A3: Average reading | B3: 60.633333 | C3: 32.333333 | D3: 133.03333 | E3: 168.23333 | F3: 76.666667 | G3: 0 | H3: 13.166667 | I3: 93.233333 | J3: 12.566667 | K3: 35.666667 | L3: 24.733333
A4: 44866 | B4: 46 | C4: 20 | D4: 163 | E4: 189 | F4: 103 | G4: 0 | H4: 0 | I4: 102 | J4: 5 | K4: 42 | L4: 19 | N4: =K4-(J4+L4) -> 18
A5: 44867 | B5: 61 | C5: 23 | D5: 180 | E5: 191 | F5: 71 | G5: 0 | H5: 0 | I5: 103 | J5: 9 | K5: 64 | L5: 52 | N5: =K5-(J5+L5) -> 3
A6: 44868 | B6: 66 | C6: 25 | D6: 177 | E6: 195 | F6: 109 | G6: 0 | H6: 0 | I6: 104 | J6: 6 | K6: 39 | L6: 28 | N6: =K6-(J6+L6) -> 5
A7: 44869 | B7: 64 | C7: 19 | D7: 194 | E7: 174 | F7: 97 | G7: 0 | H7: 65 | I7: 76 | J7: 9 | K7: 37 | L7: 24 | N7: =K7-(J7+L7) -> 4
A8: 44870 | B8: 63 | C8: 17 | D8: 162 | E8: 225 | F8: 83 | G8: 0 | H8: 78 | I8: 100 | J8: 6 | K8: 25 | L8: 6 | N8: =K8-(J8+L8) -> 13
A9: 44871 | B9: 54 | C9: 20 | D9: 121 | E9: 118 | F9: 76 | G9: 0 | H9: 0 | I9: 82 | J9: 5 | K9: 23 | L9: 9 | N9: =K9-(J9+L9) -> 9
A10: 44872 | B10: 64 | C10: 22 | D10: 131 | E10: 118 | F10: 57 | G10: 0 | H10: 71 | I10: 86 | J10: 1 | K10: 34 | L10: 22 | N10: =K10-(J10+L10) -> 11
A11: 44873 | B11: 60 | C11: 29 | D11: 140 | E11: 108 | F11: 106 | G11: 0 | H11: 65 | I11: 120 | J11: 3 | K11: 35 | L11: 28 | N11: =K11-(J11+L11) -> 4
A12: 44874 | B12: 72 | C12: 27 | D12: 137 | E12: 166 | F12: 40 | G12: 0 | H12: 0 | I12: 100 | J12: 2 | K12: 44 | L12: 35 | N12: =K12-(J12+L12) -> 7
A13: 44875 | B13: 62 | C13: 17 | D13: 152 | E13: 150 | F13: 47 | G13: 0 | H13: 0 | I13: 56 | J13: 5 | K13: 39 | L13: 30 | N13: =K13-(J13+L13) -> 4
A14: 44876 | B14: 63 | C14: 34 | D14: 164 | E14: 95 | F14: 73 | G14: 0 | H14: 0 | I14: 103 | J14: 5 | K14: 54 | L14: 46 | N14: =K14-(J14+L14) -> 3
A15: 44877 | B15: 57 | C15: 24 | D15: 174 | E15: 139 | F15: 55 | G15: 0 | H15: 0 | I15: 100 | J15: 5 | K15: 43 | L15: 30 | N15: =K15-(J15+L15) -> 8
... A26: 44888 | B26: 64 | C26: 27 | D26: 140 | E26: 73 | F26: 86 | G26: 0 | H26: 0 | I26: 54 | J26: 2 | K26: 38 | L26: 29 | N26: =K26-(J26+L26) -> 7
A27: 44889 | B27: 56 | C27: 39 | D27: 125 | E27: 116 | F27: 55 | G27: 0 | H27: 0 | I27: 106 | J27: 11 | K27: 32 | L27: 22 | N27: 1
A28: 44890 | B28: 58 | C28: 31 | D28: 163 | E28: 160 | F28: 75 | G28: 0 | H28: 0 | I28: 73 | J28: 2 | K28: 40 | L28: 32 | N28: =K28-(J28+L28) -> 6
A29: 44891 | B29: 66 | C29: 21 | D29: 110 | E29: 119 | F29: 82 | G29: 0 | H29: 0 | I29: 113 | J29: 0 | K29: 34 | L29: 27 | N29: =K29-(J29+L29) -> 7
A30: 44892 | B30: 57 | C30: 20 | D30: 116 | E30: 115 | F30: 77 | G30: 0 | H30: 0 | I30: 100 | J30: 2 | K30: 35 | L30: 28 | N30: =K30-(J30+L30) -> 5
A31: 44893 | B31: 67 | C31: 34 | D31: 147 | E31: 156 | F31: 95 | G31: 0 | H31: 0 | I31: 106 | J31: 3 | K31: 44 | L31: 32 | N31: =K31-(J31+L31) -> 9
A32: 44894 | B32: 40 | C32: 29 | D32: 164 | F32: 69 | G32: 0 | H32: 0 | I32: 78 | J32: 22 | K32: 40 | L32: 29 | N32: =K32-(J32+L32) -> -11
A33: 44895 | N33: =K33-(J33+L33) -> 0
N34: =K34-(J34+L34) -> 0
A35: TOTAL | B35: =SUM(B4:B34) -> 1749 | C35: =SUM(C4:C34) -> 707 | D35: =SUM(D4:D34) -> 4645 | E35: =SUM(E4:E34) -> 4165 | F35: =SUM(F4:F34) -> 2182 | G35: =SUM(G4:G34) -> 0 | H35: =SUM(H4:H34) -> 422 | I35: =SUM(I4:I34) -> 2609 | J35: =SUM(J4:J34) -> 167 | L35: =SUM(L4:L34) -> 800 | N35: =E35-J35-(L35+3) -> 3195

Sheet Generator
B2: Generator#1 | F2: Generator#2 | J2: Generator#3 | N2: Generator#4 | R2: Generator#5 | AB2: Taken 8AM
A3: DATE | B3: Running Hours | C3: Daily Fuel Burned | D3: Daily Energy Consumed | F3: Running Hours | G3: Daily Fuel Burned | H3: Daily Energy Consumed | J3: Running Hours | K3: Daily Fuel Burned | L3: Daily Energy Consumed | N3: Running Hours | O3: Daily Fuel Burned | P3: Daily Energy Consumed | R3: Running Hours | S3: Daily Fuel Burned | T3: Daily Energy Consumed | V3: Occupancy | W3: Total hours per day | X3: Total fuel burned (liters) | Y3: Total consumed energy (KWH) | Z3: 0
A4: 44866 | B4: 11 | C4: 1485 | D4: 7113 | F4: 24 | G4: 3523 | H4: 15674 | J4: 18 | K4: 2186 | L4: 10502 | N4: 4 | O4: 671 | P4: 2301 | R4: 0 | S4: 0 | T4: 0 | V4: ='FS Seychelles'!B3 -> 68.8 | W4: =SUM(B4,F4,J4,N4,R4) -> 57 | X4: =SUM(C4,G4,K4,O4,S4) -> 7865 | Y4: =SUM(D4,H4,L4,P4,T4) -> 35590
A5: 44867 | B5: 0 | C5: 0 | D5: 0 | F5: 17 | G5: 2112 | H5: 9433 | J5: 15 | K5: 1925 | L5: 9480 | N5: 9 | O5: 1391 | P5: 5218 | R5: 15 | S5: 1996 | T5: 9433 | V5: ='FS Seychelles'!B4 -> 71.4 | W5: =SUM(B5,F5,J5,N5,R5) -> 56 | X5: =SUM(C5,G5,K5,O5,S5) -> 7424 | Y5: =SUM(D5,H5,L5,P5,T5) -> 33564
A6: 44868 | B6: 0 | C6: 0 | D6: 0 | F6: 14 | G6: 1912 | H6: 8437 | J6: 17 | K6: 2476 | L6: 12258 | N6: 8 | O6: 1192 | P6: 4105 | R6: 17 | S6: 2533 | T6: 12130 | V6: ='FS Seychelles'!B5 -> 71.4 | W6: =SUM(B6,F6,J6,N6,R6) -> 56 | X6: =SUM(C6,G6,K6,O6,S6) -> 8113 | Y6: =SUM(D6,H6,L6,P6,T6) -> 36930
A7: 44869 | B7: 0 | C7: 0 | D7: 0 | F7: 17 | G7: 2190 | H7: 9950 | J7: 16 | K7: 2191 | L7: 11102 | N7: 8 | O7: 1184 | P7: 4561 | R7: 16 | S7: 2316 | T7: 11057 | V7: ='FS Seychelles'!B6 -> 74 | W7: =SUM(B7,F7,J7,N7,R7) -> 57 | X7: =SUM(C7,G7,K7,O7,S7) -> 7881 | Y7: =SUM(D7,H7,L7,P7,T7) -> 36670
A8: 44870 | B8: 0 | C8: 0 | D8: 0 | F8: 2 | G8: 1731 | H8: 7759 | J8: 12 | K8: 1742 | L8: 8406 | N8: 17 | O8: 2818 | P8: 10187 | R8: 15 | S8: 2222 | T8: 10263 | V8: ='FS Seychelles'!B7 -> 64.9 | W8: =SUM(B8,F8,J8,N8,R8) -> 46 | X8: =SUM(C8,G8,K8,O8,S8) -> 8513 | Y8: =SUM(D8,H8,L8,P8,T8) -> 36615
A9: 44871 | B9: 0 | C9: 0 | D9: 0 | F9: 10 | G9: 1284 | H9: 5577 | J9: 15 | K9: 2148 | L9: 10731 | N9: 10 | O9: 1532 | P9: 5511 | R9: 14 | S9: 2231 | T9: 10581 | V9: ='FS Seychelles'!B8 -> 68.8 | W9: =SUM(B9,F9,J9,N9,R9) -> 49 | X9: =SUM(C9,G9,K9,O9,S9) -> 7195 | Y9: =SUM(D9,H9,L9,P9,T9) -> 32400
A10: 44872 | B10: 0 | C10: 0 | D10: 0 | F10: 5 | G10: 586 | H10: 2961 | J10: 16 | K10: 2118 | L10: 10293 | N10: 18 | O10: 2840 | P10: 10604 | R10: 15 | S10: 2000 | T10: 9549 | V10: ='FS Seychelles'!B9 -> 74 | W10: =SUM(B10,F10,J10,N10,R10) -> 54 | X10: =SUM(C10,G10,K10,O10,S10) -> 7544 | Y10: =SUM(D10,H10,L10,P10,T10) -> 33407
A11: 44873 | B11: 0 | C11: 0 | D11: 0 | F11: 16 | G11: 2340 | H11: 10678 | J11: 18 | K11: 2078 | L11: 10119 | N11: 9 | O11: 1492 | P11: 5390 | R11: 16 | S11: 2164 | T11: 10161 | V11: ='FS Seychelles'!B10 -> 68.8 | W11: =SUM(B11,F11,J11,N11,R11) -> 59 | X11: =SUM(C11,G11,K11,O11,S11) -> 8074 | Y11: =SUM(D11,H11,L11,P11,T11) -> 36348
A12: 44874 | B12: 0 | C12: 0 | D12: 0 | F12: 15 | G12: 2207 | H12: 10175 | J12: 14 | K12: 1818 | L12: 8645 | N12: 9 | O12: 889 | P12: 5077 | R12: 13 | S12: 2146 | T12: 10119 | V12: ='FS Seychelles'!B11 -> 68.8 | W12: =SUM(B12,F12,J12,N12,R12) -> 51 | X12: =SUM(C12,G12,K12,O12,S12) -> 7060 | Y12: =SUM(D12,H12,L12,P12,T12) -> 34016
A13: 44875 | B13: 0 | C13: 0 | D13: 0 | F13: 15 | G13: 2208 | H13: 10083 | J13: 21 | K13: 2701 | L13: 12804 | N13: 5 | O13: 423 | P13: 1515 | R13: 15 | S13: 1897 | T13: 8960 | V13: ='FS Seychelles'!B12 -> 68.8 | W13: =SUM(B13,F13,J13,N13,R13) -> 56 | X13: =SUM(C13,G13,K13,O13,S13) -> 7229 | Y13: =SUM(D13,H13,L13,P13,T13) -> 33362
A14: 44876 | B14: 0 | C14: 0 | D14: 0 | F14: 14 | G14: 2154 | H14: 9928 | J14: 16 | K14: 1875 | L14: 9840 | N14: 15 | O14: 2040 | P14: 8738 | R14: 11 | S14: 1800 | T14: 8476 | V14: ='FS Seychelles'!B13 -> 71.4 | W14: =SUM(B14,F14,J14,N14,R14) -> 56 | X14: =SUM(C14,G14,K14,O14,S14) -> 7869 | Y14: =SUM(D14,H14,L14,P14,T14) -> 36982
A15: 44877 | B15: 0 | C15: 0 | D15: 0 | F15: 14 | G15: 2164 | H15: 10125 | J15: 5 | K15: 637 | L15: 3132 | N15: 17 | O15: 2790 | P15: 10282 | R15: 18 | S15: 2303 | T15: 10860 | V15: ='FS Seychelles'!B14 -> 55.8 | W15: =SUM(B15,F15,J15,N15,R15) -> 54 | X15: =SUM(C15,G15,K15,O15,S15) -> 7894 | Y15: =SUM(D15,H15,L15,P15,T15) -> 34399
A16: 44878 | B16: 0 | C16: 0 | D16: 0 | F16: 17 | G16: 2406 | H16: 10886 | J16: 14 | K16: 1930 | L16: 9732 | N16: 8 | O16: 1243 | P16: 4424 | R16: 15 | S16: 1781 | T16: 8198 | V16: ='FS Seychelles'!B15 -> 63.6 | W16: =SUM(B16,F16,J16,N16,R16) -> 54 | X16: =SUM(C16,G16,K16,O16,S16) -> 7360 | Y16: =SUM(D16,H16,L16,P16,T16) -> 33240
A17: 44879 | B17: 0 | C17: 0 | D17: 0 | F17: 12 | G17: 1841 | H17: 8443 | J17: 11 | K17: 1405 | L17: 6902 | N17: 11 | O17: 1787 | P17: 6491 | R17: 19 | S17: 2565 | T17: 11969 | V17: ='FS Seychelles'!B16 -> 49.4 | W17: =SUM(B17,F17,J17,N17,R17) -> 53 | X17: =SUM(C17,G17,K17,O17,S17) -> 7598 | Y17: =SUM(D17,H17,L17,P17,T17) -> 33805 | Z17: =AA17-AA16 -> 0 | AA17: =SUM(AB17,AC17) -> 0
A18: 44880 | B18: 0 | C18: 0 | D18: 0 | F18: 24 | G18: 3291 | H18: 14676 | J18: 13 | K18: 1982 | L18: 9787 | N18: 0 | O18: 0 | P18: 0 | R18: 18 | S18: 2096 | T18: 10014 | V18: ='FS Seychelles'!B17 -> 51.9 | W18: =SUM(B18,F18,J18,N18,R18) -> 55 | X18: =SUM(C18,G18,K18,O18,S18) -> 7369 | Y18: =SUM(D18,H18,L18,P18,T18) -> 34477 | Z18: =AA18-AA17 -> 0 | AA18: =SUM(AB18,AC18) -> 0
A19: 44881 | B19: 0 | C19: 0 | D19: 0 | F19: 19 | G19: 2589 | H19: 11672 | J19: 22 | K19: 2900 | L19: 14180 | N19: 0 | O19: 0 | P19: 0 | R19: 15 | S19: 2003 | T19: 9465 | V19: ='FS Seychelles'!B18 -> 54.5 | W19: =SUM(B19,F19,J19,N19,R19) -> 56 | X19: =SUM(C19,G19,K19,O19,S19) -> 7492 | Y19: =SUM(D19,H19,L19,P19,T19) -> 35317 | Z19: =AA19-AA18 -> 0 | AA19: =SUM(AB19,AC19) -> 0
A20: 44882 | B20: 0 | C20: 0 | D20: 0 | F20: 11 | G20: 1581 | H20: 7179 | J20: 16 | K20: 2088 | L20: 10312 | N20: 14 | O20: 2238 | P20: 8059 | R20: 14 | S20: 2106 | T20: 9757 | V20: ='FS Seychelles'!B19 -> 66.2 | W20: =SUM(B20,F20,J20,N20,R20) -> 55 | X20: =SUM(C20,G20,K20,O20,S20) -> 8013 | Y20: =SUM(D20,H20,L20,P20,T20) -> 35307 | Z20: =AA20-AA19 -> 0 | AA20: =SUM(AB20,AC20) -> 0
A21: 44883 | B21: 0 | C21: 0 | D21: 0 | F21: 14 | G21: 2116 | H21: 10122 | J21: 8 | K21: 1085 | L21: 5331 | N21: 13 | O21: 2175 | P21: 8326 | R21: 19 | S21: 2800 | T21: 12673 | V21: ='FS Seychelles'!B20 -> 57.1 | W21: =SUM(B21,F21,J21,N21,R21) -> 54 | X21: =SUM(C21,G21,K21,O21,S21) -> 8176 | Y21: =SUM(D21,H21,L21,P21,T21) -> 36452 | Z21: =AA21-AA20 -> 0 | AA21: =SUM(AB21,AC21) -> 0
