Workbook

Sheet Total
A1: Site Name | B1: Day | C1: Month | D1: Year | E1: Total Electricity Kwh | F1: Electricity Tariff ($/Kwh) | G1: Natual Gas (m3) | H1: Natural Gas $/m3 | I1: Water Utility Supply (m3) m3 | J1: Water Utility Supply (m3) $/m3 | K1: Room Nights
A2: Cairo at The First Residence | B2: 1 | C2: 8 | D2: 2022 | E2: =Elect!BS6+Submetering!AH2 -> 37716.658 | F2: ='Utility Consnsumption'!K13/'Utility Consnsumption'!J13 -> 1.3444936 | G2: =Gas!K7+Submetering!AR2 -> 1701.02 | H2: 3.8 | I2: =Water!H7+Submetering!AM2 -> 425.46 | J2: 10 | K2: =Elect!BT6 -> 227
A3: Cairo at The First Residence | B3: =B2+1 -> 2 | C3: 8 | D3: 2022 | E3: =Elect!BS7+Submetering!AH3 -> 32447.179 | F3: =F2 -> 1.3444936 | G3: =Gas!K8+Submetering!AR3 -> 1708.84 | H3: 3.8 | I3: =Water!H8+Submetering!AM3 -> 456.9 | J3: 10 | K3: =Elect!BT7 -> 243
A4: Cairo at The First Residence | B4: =B3+1 -> 3 | C4: 8 | D4: 2022 | E4: =Elect!BS8+Submetering!AH4 -> 43550.145 | F4: =F3 -> 1.3444936 | G4: =Gas!K9+Submetering!AR4 -> 1779.26 | H4: 3.8 | I4: =Water!H9+Submetering!AM4 -> 439.18 | J4: 10 | K4: =Elect!BT8 -> 220
A5: Cairo at The First Residence | B5: =B4+1 -> 4 | C5: 8 | D5: 2022 | E5: =Elect!BS9+Submetering!AH5 -> 34563.173 | F5: =F4 -> 1.3444936 | G5: =Gas!K10+Submetering!AR5 -> 1556.96 | H5: 3.8 | I5: =Water!H10+Submetering!AM5 -> 468.4 | J5: 10 | K5: =Elect!BT9 -> 203
A6: Cairo at The First Residence | B6: =B5+1 -> 5 | C6: 8 | D6: 2022 | E6: =Elect!BS10+Submetering!AH6 -> 41780.65 | F6: =F5 -> 1.3444936 | G6: =Gas!K11+Submetering!AR6 -> 1726.72 | H6: 3.8 | I6: =Water!H11+Submetering!AM6 -> 459.16 | J6: 10 | K6: =Elect!BT10 -> 187
A7: Cairo at The First Residence | B7: =B6+1 -> 6 | C7: 8 | D7: 2022 | E7: =Elect!BS11+Submetering!AH7 -> 37544.313 | F7: =F6 -> 1.3444936 | G7: =Gas!K12+Submetering!AR7 -> 1690.68 | H7: 3.8 | I7: =Water!H12+Submetering!AM7 -> 442.24 | J7: 10 | K7: =Elect!BT11 -> 203
A8: Cairo at The First Residence | B8: =B7+1 -> 7 | C8: 8 | D8: 2022 | E8: =Elect!BS12+Submetering!AH8 -> 33954.184 | F8: =F7 -> 1.3444936 | G8: =Gas!K13+Submetering!AR8 -> 1786.74 | H8: 3.8 | I8: =Water!H13+Submetering!AM8 -> 452.1 | J8: 10 | K8: =Elect!BT12 -> 234
A9: Cairo at The First Residence | B9: =B8+1 -> 8 | C9: 8 | D9: 2022 | E9: =Elect!BS13+Submetering!AH9 -> 34826.414 | F9: =F8 -> 1.3444936 | G9: =Gas!K14+Submetering!AR9 -> 1814.12 | H9: 3.8 | I9: =Water!H14+Submetering!AM9 -> 465.8 | J9: 10 | K9: =Elect!BT13 -> 248
A10: Cairo at The First Residence | B10: =B9+1 -> 9 | C10: 8 | D10: 2022 | E10: =Elect!BS14+Submetering!AH10 -> 30403.21 | F10: =F9 -> 1.3444936 | G10: =Gas!K15+Submetering!AR10 -> 1780.4067 | H10: 3.8 | I10: =Water!H15+Submetering!AM10 -> 431.32 | J10: 10 | K10: =Elect!BT14 -> 252
A11: Cairo at The First Residence | B11: =B10+1 -> 10 | C11: 8 | D11: 2022 | E11: =Elect!BS15+Submetering!AH11 -> 33600.61 | F11: =F10 -> 1.3444936 | G11: =Gas!K16+Submetering!AR11 -> 1832.6533 | H11: 3.8 | I11: =Water!H16+Submetering!AM11 -> 437.5 | J11: 10 | K11: =Elect!BT15 -> 246
A12: Cairo at The First Residence | B12: =B11+1 -> 11 | C12: 8 | D12: 2022 | E12: =Elect!BS16+Submetering!AH12 -> 37892.73 | F12: =F11 -> 1.3444936 | G12: =Gas!K17+Submetering!AR12 -> 1791.8222 | H12: 3.8 | I12: =Water!H17+Submetering!AM12 -> 432.38 | J12: 10 | K12: =Elect!BT16 -> 206
A13: Cairo at The First Residence | B13: =B12+1 -> 12 | C13: 8 | D13: 2022 | E13: =Elect!BS17+Submetering!AH13 -> 38359.069 | F13: =F12 -> 1.3444936 | G13: =Gas!K18+Submetering!AR13 -> 1799.2578 | H13: 3.8 | I13: =Water!H18+Submetering!AM13 -> 437.8 | J13: 10 | K13: =Elect!BT17 -> 174
A14: Cairo at The First Residence | B14: =B13+1 -> 13 | C14: 8 | D14: 2022 | E14: =Elect!BS18+Submetering!AH14 -> 32800.977 | F14: =F13 -> 1.3444936 | G14: =Gas!K19+Submetering!AR14 -> 1800.74 | H14: 3.8 | I14: =Water!H19+Submetering!AM14 -> 412.96 | J14: 10 | K14: =Elect!BT18 -> 162
... A32: Cairo at The First Residence | B32: =B31+1 -> 31 | C32: 8 | D32: 2022 | E32: =Elect!BS36+Submetering!AH32 -> 22919.465 | F32: =F31 -> 1.3444936 | G32: =Gas!K37+Submetering!AR32 -> 1663.8733 | H32: 3.8 | I32: =Water!H37+Submetering!AM32 -> 303.14667 | J32: 10 | K32: =Elect!BT36 -> 238

Sheet Submetering
A1: Site Name | B1: Day | C1: Month | D1: Year | E1: Electricity | F1: Main Feeder -KWh | G1: T2+T8 -KWh | H1: La Gourmandize -KWh | I1: Casino 3rd floor EM -KWh | J1: Casino 3rd floor Normal -KWh | K1: Chiller 1 -KWh | L1: Chiller 2 -KWh | M1: Chiller 3 -KWh | N1: Chiller 4 -KWh | O1: Chiller 5 -KWh | P1: Chiller 6 -KWh | Q1: Cooling towers -KWh | R1: Chiller Pumps -KWh | S1: Cooling Tower Pumps -KWh | T1: Fiber Chiller -KWh | U1: Mall Ceiling light -KWh | V1: LG Bakery -KWh | W1: LG Bakery light ( Old lockers ) -KWh | X1: MCCR1 -KWh | Y1: Children Swimming Pool -KWh | Z1: DPH1 -KWh | AA1: Guest Rooms Emerg. -KWh | AB1: Hotel Hoods -KWh | AC1: Main G2 -KWh | AD1: Old Casino Emergency -KWh | AE1: L / A -KWh | AF1: L / B -KWh | AG1: L / C -KWh | AH1: Boat -KWh | AI1: Water | AJ1: Main water meter 1 -m3 | AK1: Main water meter 2 -m3 | AL1: Main water meter 3 -m3 | AM1: Boat -m3 | AN1: Gas | AO1: Main Gas Flow Meter -m3 | AP1: Laundry Gas Flow Meter -m3 | AQ1: Gourmandize Gas Flow Meter -m3 | AR1: Boat -m3 | AS1: Room Nights
A2: Cairo at The First Residence | B2: 1 | C2: 8 | D2: 2022 | F2: =Elect!J6 -> 2039 | G2: =Elect!K6 -> 1738 | H2: =Elect!Q6 -> 810 | I2: =Elect!S6 -> 145 | J2: =Elect!U6 -> 258 | K2: =Elect!W6 -> 3414.26 | L2: =Elect!Y6 -> 4526.73 | M2: =Elect!AA6 -> 0 | N2: =Elect!AC6 -> 0 | O2: =Elect!AE6 -> 84.27 | P2: =Elect!AG6 -> 1672.68 | Q2: =Elect!AI6 -> 1172.36 | R2: =Elect!AK6 -> 3972.35 | S2: =Elect!AM6 -> 101.76 | T2: =Elect!AP6 -> 347.5125 | U2: =Elect!AR6 -> 193 | V2: =Elect!AT6 -> 304.68585 | W2: =Elect!AV6 -> 45 | X2: =Elect!AX6 -> 930 | Y2: =Elect!AZ6 -> 12 | Z2: =Elect!BB6 -> 4938 | AA2: =Elect!BD6 -> 284 | AB2: =Elect!BF6 -> 55 | AC2: =Elect!BH6 -> 6683.05 | AD2: =Elect!BL6 -> 265 | AE2: =Elect!BN6 -> 1564 | AF2: =Elect!BP6 -> 127 | AG2: =Elect!BR6 -> 171 | AH2: =Boat!C4 -> 6131 | AJ2: =Water!C7 -> 121.8 | AK2: =Water!E7 -> 150.8 | AL2: =Water!G7 -> 125.86 | AM2: =Boat!E4 -> 27 | AO2: =Gas!C7 -> 1258.22 | AP2: =Gas!E7 -> 317.8 | AQ2: =Gas!G7 -> 68 | AR2: =Boat!G4 -> 125 | AS2: =Elect!BT6 -> 227
A3: Cairo at The First Residence | B3: =B2+1 -> 2 | C3: 8 | D3: 2022 | F3: =Elect!J7 -> 0 | G3: =Elect!K7 -> 3340 | H3: =Elect!Q7 -> 570 | I3: =Elect!S7 -> 134 | J3: =Elect!U7 -> 257 | K3: =Elect!W7 -> 3476.8 | L3: =Elect!Y7 -> 3827.66 | M3: =Elect!AA7 -> 0 | N3: =Elect!AC7 -> 0 | O3: =Elect!AE7 -> 1726.74 | P3: =Elect!AG7 -> 10.6 | Q3: =Elect!AI7 -> 1035.62 | R3: =Elect!AK7 -> 3576.97 | S3: =Elect!AM7 -> 102.29 | T3: =Elect!AP7 -> 290.1375 | U3: =Elect!AR7 -> 154 | V3: =Elect!AT7 -> 179.76179 | W3: =Elect!AV7 -> 61 | X3: =Elect!AX7 -> 804 | Y3: =Elect!AZ7 -> 10 | Z3: =Elect!BB7 -> 5316 | AA3: =Elect!BD7 -> 252 | AB3: =Elect!BF7 -> 112 | AC3: =Elect!BH7 -> 6520.6 | AD3: =Elect!BL7 -> 293 | AE3: =Elect!BN7 -> 1399 | AF3: =Elect!BP7 -> 113 | AG3: =Elect!BR7 -> 150 | AH3: =Boat!C5 -> 4421 | AJ3: =Water!C8 -> 133.4 | AK3: =Water!E8 -> 174 | AL3: =Water!G8 -> 130.5 | AM3: =Boat!E5 -> 19 | AO3: =Gas!C8 -> 1361.04 | AP3: =Gas!E8 -> 254.8 | AQ3: =Gas!G8 -> 97 | AR3: =Boat!G5 -> 93 | AS3: =Elect!BT7 -> 243
A4: Cairo at The First Residence | B4: =B3+1 -> 3 | C4: 8 | D4: 2022 | F4: =Elect!J8 -> 5969.1111 | G4: =Elect!K8 -> 4452 | H4: =Elect!Q8 -> 750 | I4: =Elect!S8 -> 147 | J4: =Elect!U8 -> 268 | K4: =Elect!W8 -> 3896.03 | L4: =Elect!Y8 -> 4479.03 | M4: =Elect!AA8 -> 102.29 | N4: =Elect!AC8 -> 0 | O4: =Elect!AE8 -> 1694.41 | P4: =Elect!AG8 -> 11.13 | Q4: =Elect!AI8 -> 1181.37 | R4: =Elect!AK8 -> 4571.78 | S4: =Elect!AM8 -> 134.62 | T4: =Elect!AP8 -> 310.1625 | U4: =Elect!AR8 -> 153 | V4: =Elect!AT8 -> 179.76179 | W4: =Elect!AV8 -> 69 | X4: =Elect!AX8 -> 1062 | Y4: =Elect!AZ8 -> 12 | Z4: =Elect!BB8 -> 6552 | AA4: =Elect!BD8 -> 247 | AB4: =Elect!BF8 -> 55 | AC4: =Elect!BH8 -> 6852.45 | AD4: =Elect!BL8 -> 282 | AE4: =Elect!BN8 -> 1350 | AF4: =Elect!BP8 -> 109 | AG4: =Elect!BR8 -> 140 | AH4: =Boat!C6 -> 5268 | AJ4: =Water!C9 -> 127.6 | AK4: =Water!E9 -> 156.6 | AL4: =Water!G9 -> 133.98 | AM4: =Boat!E6 -> 21 | AO4: =Gas!C9 -> 1246.56 | AP4: =Gas!E9 -> 385.7 | AQ4: =Gas!G9 -> 96 | AR4: =Boat!G6 -> 147 | AS4: =Elect!BT8 -> 220
A5: Cairo at The First Residence | B5: =B4+1 -> 4 | C5: 8 | D5: 2022 | F5: =Elect!J9 -> 5969.1111 | G5: =Elect!K9 -> 3105 | H5: =Elect!Q9 -> 720 | I5: =Elect!S9 -> 139 | J5: =Elect!U9 -> 240 | K5: =Elect!W9 -> 2661.13 | L5: =Elect!Y9 -> 0 | M5: =Elect!AA9 -> 3184.24 | N5: =Elect!AC9 -> 0 | O5: =Elect!AE9 -> 1634.52 | P5: =Elect!AG9 -> 11.13 | Q5: =Elect!AI9 -> 969.9 | R5: =Elect!AK9 -> 3366.56 | S5: =Elect!AM9 -> 102.82 | T5: =Elect!AP9 -> 286.2 | U5: =Elect!AR9 -> 148 | V5: =Elect!AT9 -> 179.76179 | W5: =Elect!AV9 -> 57 | X5: =Elect!AX9 -> 775 | Y5: =Elect!AZ9 -> 11 | Z5: =Elect!BB9 -> 3775 | AA5: =Elect!BD9 -> 286 | AB5: =Elect!BF9 -> 35 | AC5: =Elect!BH9 -> 6274.8 | AD5: =Elect!BL9 -> 248 | AE5: =Elect!BN9 -> 1290 | AF5: =Elect!BP9 -> 106 | AG5: =Elect!BR9 -> 143 | AH5: =Boat!C7 -> 4116 | AJ5: =Water!C10 -> 139.2 | AK5: =Water!E10 -> 185.6 | AL5: =Water!G10 -> 127.6 | AM5: =Boat!E7 -> 16 | AO5: =Gas!C10 -> 1182.96 | AP5: =Gas!E10 -> 287 | AQ5: =Gas!G10 -> 79 | AR5: =Boat!G7 -> 87 | AS5: =Elect!BT9 -> 203
A6: Cairo at The First Residence | B6: =B5+1 -> 5 | C6: 8 | D6: 2022 | F6: =Elect!J10 -> 5969.1111 | G6: =Elect!K10 -> 3812 | H6: =Elect!Q10 -> 540 | I6: =Elect!S10 -> 149 | J6: =Elect!U10 -> 264 | K6: =Elect!W10 -> 3505.95 | L6: =Elect!Y10 -> 0 | M6: =Elect!AA10 -> 4058.21 | N6: =Elect!AC10 -> 0 | O6: =Elect!AE10 -> 1595.3 | P6: =Elect!AG10 -> 10.07 | Q6: =Elect!AI10 -> 1115.12 | R6: =Elect!AK10 -> 4081.53 | S6: =Elect!AM10 -> 120.31 | T6: =Elect!AP10 -> 276.6375 | U6: =Elect!AR10 -> 150 | V6: =Elect!AT10 -> 179.76179 | W6: =Elect!AV10 -> 65 | X6: =Elect!AX10 -> 963 | Y6: =Elect!AZ10 -> 12 | Z6: =Elect!BB10 -> 6654 | AA6: =Elect!BD10 -> 273 | AB6: =Elect!BF10 -> 55 | AC6: =Elect!BH10 -> 6417.65 | AD6: =Elect!BL10 -> 247 | AE6: =Elect!BN10 -> 1315 | AF6: =Elect!BP10 -> 108 | AG6: =Elect!BR10 -> 152 | AH6: =Boat!C8 -> 5739 | AJ6: =Water!C11 -> 127.6 | AK6: =Water!E11 -> 174 | AL6: =Water!G11 -> 134.56 | AM6: =Boat!E8 -> 23 | AO6: =Gas!C11 -> 1321.82 | AP6: =Gas!E11 -> 284.9 | AQ6: =Gas!G11 -> 90 | AR6: =Boat!G8 -> 120 | AS6: =Elect!BT10 -> 187
A7: Cairo at The First Residence | B7: =B6+1 -> 6 | C7: 8 | D7: 2022 | F7: =Elect!J11 -> 5969.1111 | G7: =Elect!K11 -> 3532 | H7: =Elect!Q11 -> 540 | I7: =Elect!S11 -> 136 | J7: =Elect!U11 -> 231 | K7: =Elect!W11 -> 2624.56 | L7: =Elect!Y11 -> 0 | M7: =Elect!AA11 -> 3516.02 | N7: =Elect!AC11 -> 0 | O7: =Elect!AE11 -> 1488.24 | P7: =Elect!AG11 -> 11.66 | Q7: =Elect!AI11 -> 915.84 | R7: =Elect!AK11 -> 3757.7 | S7: =Elect!AM11 -> 110.24 | T7: =Elect!AP11 -> 263.025 | U7: =Elect!AR11 -> 138 | V7: =Elect!AT11 -> 230.26701 | W7: =Elect!AV11 -> 49 | X7: =Elect!AX11 -> 909 | Y7: =Elect!AZ11 -> 10 | Z7: =Elect!BB11 -> 4910 | AA7: =Elect!BD11 -> 286 | AB7: =Elect!BF11 -> 50 | AC7: =Elect!BH11 -> 6297.65 | AD7: =Elect!BL11 -> 273 | AE7: =Elect!BN11 -> 1231 | AF7: =Elect!BP11 -> 112 | AG7: =Elect!BR11 -> 124 | AH7: =Boat!C9 -> 5468 | AJ7: =Water!C12 -> 127.6 | AK7: =Water!E12 -> 162.4 | AL7: =Water!G12 -> 132.24 | AM7: =Boat!E9 -> 20 | AO7: =Gas!C12 -> 1185.08 | AP7: =Gas!E12 -> 285.6 | AQ7: =Gas!G12 -> 80 | AR7: =Boat!G9 -> 220 | AS7: =Elect!BT11 -> 203
A8: Cairo at The First Residence | B8: =B7+1 -> 7 | C8: 8 | D8: 2022 | F8: =Elect!J12 -> 5969.1111 | G8: =Elect!K12 -> 2492 | H8: =Elect!Q12 -> 510 | I8: =Elect!S12 -> 150 | J8: =Elect!U12 -> 254 | K8: =Elect!W12 -> 1480.29 | L8: =Elect!Y12 -> 0 | M8: =Elect!AA12 -> 3054.92 | N8: =Elect!AC12 -> 0 | O8: =Elect!AE12 -> 1375.88 | P8: =Elect!AG12 -> 11.13 | Q8: =Elect!AI12 -> 669.92 | R8: =Elect!AK12 -> 2972.77 | S8: =Elect!AM12 -> 98.05 | T8: =Elect!AP12 -> 235.4625 | U8: =Elect!AR12 -> 175 | V8: =Elect!AT12 -> 170 | W8: =Elect!AV12 -> 33 | X8: =Elect!AX12 -> 790 | Y8: =Elect!AZ12 -> 12 | Z8: =Elect!BB12 -> 5256 | AA8: =Elect!BD12 -> 285 | AB8: =Elect!BF12 -> 45 | AC8: =Elect!BH12 -> 6744.65 | AD8: =Elect!BL12 -> 332 | AE8: =Elect!BN12 -> 1459 | AF8: =Elect!BP12 -> 124 | AG8: =Elect!BR12 -> 150 | AH8: =Boat!C10 -> 4066 | AJ8: =Water!C13 -> 127.6 | AK8: =Water!E13 -> 168.2 | AL8: =Water!G13 -> 136.3 | AM8: =Boat!E10 -> 20 | AO8: =Gas!C13 -> 1414.04 | AP8: =Gas!E13 -> 301.7 | AQ8: =Gas!G13 -> 90 | AR8: =Boat!G10 -> 71 | AS8: =Elect!BT12 -> 234
A9: Cairo at The First Residence | B9: =B8+1 -> 8 | C9: 8 | D9: 2022 | F9: =Elect!J13 -> 5969.1111 | G9: =Elect!K13 -> 4301 | H9: =Elect!Q13 -> 570 | I9: =Elect!S13 -> 156 | J9: =Elect!U13 -> 271 | K9: =Elect!W13 -> 0 | L9: =Elect!Y13 -> 0 | M9: =Elect!AA13 -> 4574.43 | N9: =Elect!AC13 -> 320.12 | O9: =Elect!AE13 -> 198.22 | P9: =Elect!AG13 -> 976.79 | Q9: =Elect!AI13 -> 621.16 | R9: =Elect!AK13 -> 3209.15 | S9: =Elect!AM13 -> 126.67 | T9: =Elect!AP13 -> 266.5125 | U9: =Elect!AR13 -> 176 | V9: =Elect!AT13 -> 163 | W9: =Elect!AV13 -> 45 | X9: =Elect!AX13 -> 927 | Y9: =Elect!AZ13 -> 12 | Z9: =Elect!BB13 -> 5256 | AA9: =Elect!BD13 -> 234 | AB9: =Elect!BF13 -> 50 | AC9: =Elect!BH13 -> 6065.25 | AD9: =Elect!BL13 -> 290 | AE9: =Elect!BN13 -> 1159 | AF9: =Elect!BP13 -> 116 | AG9: =Elect!BR13 -> 134 | AH9: =Boat!C11 -> 5066 | AJ9: =Water!C14 -> 139.2 | AK9: =Water!E14 -> 179.8 | AL9: =Water!G14 -> 121.8 | AM9: =Boat!E11 -> 25 | AO9: =Gas!C14 -> 1406.62 | AP9: =Gas!E14 -> 311.5 | AQ9: =Gas!G14 -> 85 | AR9: =Boat!G11 -> 96 | AS9: =Elect!BT13 -> 248
A10: Cairo at The First Residence | B10: =B9+1 -> 9 | C10: 8 | D10: 2022 | F10: =Elect!J14 -> 5969.1111 | G10: =Elect!K14 -> 2717 | H10: =Elect!Q14 -> 450 | I10: =Elect!S14 -> 112 | J10: =Elect!U14 -> 191 | K10: =Elect!W14 -> 1423.05 | L10: =Elect!Y14 -> 0 | M10: =Elect!AA14 -> 3030.01 | N10: =Elect!AC14 -> 0 | O10: =Elect!AE14 -> 9.54 | P10: =Elect!AG14 -> 820.44 | Q10: =Elect!AI14 -> 380.01 | R10: =Elect!AK14 -> 2541.35 | S10: =Elect!AM14 -> 94.87 | T10: =Elect!AP14 -> 226.4625 | U10: =Elect!AR14 -> 152 | V10: =Elect!AT14 -> 167.66667 | W10: =Elect!AV14 -> 30 | X10: =Elect!AX14 -> 681 | Y10: =Elect!AZ14 -> 8 | Z10: =Elect!BB14 -> 3823 | AA10: =Elect!BD14 -> 184 | AB10: =Elect!BF14 -> 201 | AC10: =Elect!BH14 -> 4679.7 | AD10: =Elect!BL14 -> 219 | AE10: =Elect!BN14 -> 1566 | AF10: =Elect!BP14 -> 88 | AG10: =Elect!BR14 -> 102 | AH10: =Boat!C12 -> 5532 | AJ10: =Water!C15 -> 121.8 | AK10: =Water!E15 -> 162.4 | AL10: =Water!G15 -> 124.12 | AM10: =Boat!E12 -> 23 | AO10: =Gas!C15 -> 1350.44 | AP10: =Gas!E15 -> 304.96667 | AQ10: =Gas!G15 -> 90 | AR10: =Boat!G12 -> 125 | AS10: =Elect!BT14 -> 252
A11: Cairo at The First Residence | B11: =B10+1 -> 10 | C11: 8 | D11: 2022 | F11: =Elect!J15 -> 5969.1111 | G11: =Elect!K15 -> 3773 | H11: =Elect!Q15 -> 530 | I11: =Elect!S15 -> 141.33333 | J11: =Elect!U15 -> 244.33333 | K11: =Elect!W15 -> 1984.85 | L11: =Elect!Y15 -> 0 | M11: =Elect!AA15 -> 4059.6233 | N11: =Elect!AC15 -> 0 | O11: =Elect!AE15 -> 29.326667 | P11: =Elect!AG15 -> 924.67333 | Q11: =Elect!AI15 -> 540.77667 | R11: =Elect!AK15 -> 2986.55 | S11: =Elect!AM15 -> 116.07 | T11: =Elect!AP15 -> 253.1625 | U11: =Elect!AR15 -> 168 | V11: =Elect!AT15 -> 166.5 | W11: =Elect!AV15 -> 40 | X11: =Elect!AX15 -> 845 | Y11: =Elect!AZ15 -> 10.666667 | Z11: =Elect!BB15 -> 4778.3333 | AA11: =Elect!BD15 -> 217.33333 | AB11: =Elect!BF15 -> 100.33333 | AC11: =Elect!BH15 -> 5481.3 | AD11: =Elect!BL15 -> 266.33333 | AE11: =Elect!BN15 -> 1566 | AF11: =Elect!BP15 -> 106.66667 | AG11: =Elect!BR15 -> 123.33333 | AH11: =Boat!C13 -> 4399 | AJ11: =Water!C16 -> 127.6 | AK11: =Water!E16 -> 162.4 | AL11: =Water!G16 -> 130.5 | AM11: =Boat!E13 -> 17 | AO11: =Gas!C16 -> 1427.82 | AP11: =Gas!E16 -> 306.83333 | AQ11: =Gas!G16 -> 92 | AR11: =Boat!G13 -> 98 | AS11: =Elect!BT15 -> 246
A12: Cairo at The First Residence | B12: =B11+1 -> 11 | C12: 8 | D12: 2022 | F12: =Elect!J16 -> 5969.1111 | G12: =Elect!K16 -> 3190 | H12: =Elect!Q16 -> 490 | I12: =Elect!S16 -> 139.66667 | J12: =Elect!U16 -> 274.66667 | K12: =Elect!W16 -> 3870.06 | L12: =Elect!Y16 -> 0 | M12: =Elect!AA16 -> 3559.6567 | N12: =Elect!AC16 -> 0 | O12: =Elect!AE16 -> 0 | P12: =Elect!AG16 -> 0 | Q12: =Elect!AI16 -> 467.81333 | R12: =Elect!AK16 -> 3479.45 | S12: =Elect!AM16 -> 104.41 | T12: =Elect!AP16 -> 270.4125 | U12: =Elect!AR16 -> 153 | V12: =Elect!AT16 -> 80.833333 | W12: =Elect!AV16 -> 69 | X12: =Elect!AX16 -> 832 | Y12: =Elect!AZ16 -> 11.333333 | Z12: =Elect!BB16 -> 5508.6667 | AA12: =Elect!BD16 -> 251.66667 | AB12: =Elect!BF16 -> 38.666667 | AC12: =Elect!BH16 -> 7703.65 | AD12: =Elect!BL16 -> 297.66667 | AE12: =Elect!BN16 -> 549 | AF12: =Elect!BP16 -> 147.33333 | AG12: =Elect!BR16 -> 135.66667 | AH12: =Boat!C14 -> 5033 | AJ12: =Water!C17 -> 123.73333 | AK12: =Water!E17 -> 162.4 | AL12: =Water!G17 -> 126.24667 | AM12: =Boat!E14 -> 20 | AO12: =Gas!C17 -> 1376.2333 | AP12: =Gas!E17 -> 305.58889 | AQ12: =Gas!G17 -> 90.666667 | AR12: =Boat!G14 -> 110 | AS12: =Elect!BT16 -> 206
A13: Cairo at The First Residence | B13: =B12+1 -> 12 | C13: 8 | D13: 2022 | F13: =Elect!J17 -> 5969.1111 | G13: =Elect!K17 -> 4248 | H13: =Elect!Q17 -> 510 | I13: =Elect!S17 -> 152 | J13: =Elect!U17 -> 283 | K13: =Elect!W17 -> 3870.06 | L13: =Elect!Y17 -> 0 | M13: =Elect!AA17 -> 3884.9 | N13: =Elect!AC17 -> 0 | O13: =Elect!AE17 -> 8.8333333 | P13: =Elect!AG17 -> 164.3 | Q13: =Elect!AI17 -> 566.57 | R13: =Elect!AK17 -> 3818.65 | S13: =Elect!AM17 -> 119.25 | T13: =Elect!AP17 -> 257.4 | U13: =Elect!AR17 -> 266 | V13: =Elect!AT17 -> 137.94444 | W13: =Elect!AV17 -> 55 | X13: =Elect!AX17 -> 884 | Y13: =Elect!AZ17 -> 12 | Z13: =Elect!BB17 -> 5828 | AA13: =Elect!BD17 -> 240 | AB13: =Elect!BF17 -> 70 | AC13: =Elect!BH17 -> 6664.05 | AD13: =Elect!BL17 -> 265 | AE13: =Elect!BN17 -> 1487 | AF13: =Elect!BP17 -> 84 | AG13: =Elect!BR17 -> 140 | AH13: =Boat!C15 -> 5033 | AJ13: =Water!C18 -> 125.66667 | AK13: =Water!E18 -> 156.6 | AL13: =Water!G18 -> 129.53333 | AM13: =Boat!E15 -> 26 | AO13: =Gas!C18 -> 1324.6467 | AP13: =Gas!E18 -> 293.61111 | AQ13: =Gas!G18 -> 82.333333 | AR13: =Boat!G15 -> 181 | AS13: =Elect!BT17 -> 174
A14: Cairo at The First Residence | B14: =B13+1 -> 13 | C14: 8 | D14: 2022 | F14: =Elect!J18 -> 5969.1111 | G14: =Elect!K18 -> 3683 | H14: =Elect!Q18 -> 510 | I14: =Elect!S18 -> 130 | J14: =Elect!U18 -> 233 | K14: =Elect!W18 -> 906.3 | L14: =Elect!Y18 -> 0 | M14: =Elect!AA18 -> 3556.83 | N14: =Elect!AC18 -> 0 | O14: =Elect!AE18 -> 11.13 | P14: =Elect!AG18 -> 630.7 | Q14: =Elect!AI18 -> 445.73 | R14: =Elect!AK18 -> 3116.4 | S14: =Elect!AM18 -> 102.82 | T14: =Elect!AP18 -> 193.95 | U14: =Elect!AR18 -> 144 | V14: =Elect!AT18 -> 306.05556 | W14: =Elect!AV18 -> 45 | X14: =Elect!AX18 -> 767 | Y14: =Elect!AZ18 -> 10 | Z14: =Elect!BB18 -> 4491 | AA14: =Elect!BD18 -> 199 | AB14: =Elect!BF18 -> 65 | AC14: =Elect!BH18 -> 5618.95 | AD14: =Elect!BL18 -> 197 | AE14: =Elect!BN18 -> 1268 | AF14: =Elect!BP18 -> 101 | AG14: =Elect!BR18 -> 134 | AH14: =Boat!C16 -> 5712 | AJ14: =Water!C19 -> 121.8 | AK14: =Water!E19 -> 162.4 | AL14: =Water!G19 -> 128.76 | AM14: =Boat!E16 -> 0 | AO14: =Gas!C19 -> 1355.74 | AP14: =Gas!E19 -> 308 | AQ14: =Gas!G19 -> 100 | AR14: =Boat!G16 -> 137 | AS14: =Elect!BT18 -> 162
... A32: Cairo at The First Residence | B32: =B31+1 -> 31 | C32: 8 | D32: 2022 | F32: =Elect!J36 -> 5783.5 | G32: =Elect!K36 -> 3567.1111 | H32: =Elect!Q36 -> 570 | I32: =Elect!S36 -> 142.22222 | J32: =Elect!U36 -> 264 | K32: =Elect!W36 -> 0 | L32: =Elect!Y36 -> 0 | M32: =Elect!AA36 -> 0 | N32: =Elect!AC36 -> 0 | O32: =Elect!AE36 -> 12.985 | P32: =Elect!AG36 -> 11.66 | Q32: =Elect!AI36 -> 0 | R32: =Elect!AK36 -> 3256.585 | S32: =Elect!AM36 -> 108.385 | T32: =Elect!AP36 -> 242.325 | U32: =Elect!AR36 -> 194 | V32: =Elect!AT36 -> 164 | W32: =Elect!AV36 -> 41.5 | X32: =Elect!AX36 -> 918 | Y32: =Elect!AZ36 -> 11 | Z32: =Elect!BB36 -> 5314 | AA32: =Elect!BD36 -> 271.5 | AB32: =Elect!BF36 -> 70 | AC32: =Elect!BH36 -> 5950.025 | AD32: =Elect!BL36 -> 234 | AE32: =Elect!BN36 -> 1295 | AF32: =Elect!BP36 -> 110.5 | AG32: =Elect!BR36 -> 141 | AH32: =Boat!C34 -> 0 | AJ32: =Water!C37 -> 108.26667 | AK32: =Water!E37 -> 145 | AL32: =Water!G37 -> 49.88 | AM32: =Boat!E34 -> 0 | AO32: =Gas!C37 -> 1357.5067 | AP32: =Gas!E37 -> 306.36667 | AQ32: =Gas!G37 -> 79 | AR32: =Boat!G34 -> 0 | AS32: =Elect!BT36 -> 238

Sheet Boat
B1: Electricity | D1: Water | F1: Gas
B2: Read | C2: Cons | D2: Read | E2: Cons | F2: Read | G2: Cons
B3: 3231504 | D3: 3897 | F3: 94828
A4: 1 | B4: 3237635 | C4: =B4-B3 -> 6131 | D4: 3924 | E4: =D4-D3 -> 27 | F4: 94953 | G4: =F4-F3 -> 125
A5: 2 | B5: 3242056 | C5: =B5-B4 -> 4421 | D5: 3943 | E5: =D5-D4 -> 19 | F5: 95046 | G5: =F5-F4 -> 93
A6: 3 | B6: 3247324 | C6: =B6-B5 -> 5268 | D6: 3964 | E6: =D6-D5 -> 21 | F6: 95193 | G6: =F6-F5 -> 147
A7: 4 | B7: 3251440 | C7: =B7-B6 -> 4116 | D7: 3980 | E7: =D7-D6 -> 16 | F7: 95280 | G7: =F7-F6 -> 87
A8: 5 | B8: 3257179 | C8: =B8-B7 -> 5739 | D8: 4003 | E8: =D8-D7 -> 23 | F8: 95400 | G8: =F8-F7 -> 120
A9: 6 | B9: 3262647 | C9: =B9-B8 -> 5468 | D9: 4023 | E9: =D9-D8 -> 20 | F9: 95620 | G9: =F9-F8 -> 220
A10: 7 | B10: 3266713 | C10: =B10-B9 -> 4066 | D10: 4043 | E10: =D10-D9 -> 20 | F10: 95691 | G10: =F10-F9 -> 71
A11: 8 | B11: 3271779 | C11: =B11-B10 -> 5066 | D11: 4068 | E11: =D11-D10 -> 25 | F11: 95787 | G11: =F11-F10 -> 96
A12: 9 | B12: 3277311 | C12: =B12-B11 -> 5532 | D12: 4091 | E12: =D12-D11 -> 23 | F12: 95912 | G12: =F12-F11 -> 125
A13: 10 | B13: 3281710 | C13: =B13-B12 -> 4399 | D13: 4108 | E13: =D13-D12 -> 17 | F13: 96010 | G13: =F13-F12 -> 98
A14: 11 | B14: 3286743 | C14: =B14-B13 -> 5033 | D14: 4128 | E14: =D14-D13 -> 20 | F14: 96120 | G14: =F14-F13 -> 110
A15: 12 | B15: 3291776 | C15: =B15-B14 -> 5033 | D15: 4154 | E15: =D15-D14 -> 26 | F15: 96301 | G15: =F15-F14 -> 181
A16: 13 | B16: 3297488 | C16: =B16-B15 -> 5712 | D16: 4154 | E16: =D16-D15 -> 0 | F16: 96438 | G16: =F16-F15 -> 137
A17: 14 | C17: =B17-B16 -> -3297488 | E17: =D17-D16 -> -4154 | G17: =F17-F16 -> -96438
A18: 15 | C18: =B18-B17 -> 0 | E18: =D18-D17 -> 0 | G18: =F18-F17 -> 0
A19: 16 | C19: =B19-B18 -> 0 | E19: =D19-D18 -> 0 | G19: =F19-F18 -> 0
A20: 17 | C20: =B20-B19 -> 0 | E20: =D20-D19 -> 0 | G20: =F20-F19 -> 0
A21: 18 | C21: =B21-B20 -> 0 | E21: =D21-D20 -> 0 | G21: =F21-F20 -> 0
A22: 19 | C22: =B22-B21 -> 0 | E22: =D22-D21 -> 0 | G22: =F22-F21 -> 0
A23: 20 | C23: =B23-B22 -> 0 | E23: =D23-D22 -> 0 | G23: =F23-F22 -> 0
A24: 21 | C24: =B24-B23 -> 0 | E24: =D24-D23 -> 0 | G24: =F24-F23 -> 0
A25: 22 | C25: =B25-B24 -> 0 | E25: =D25-D24 -> 0 | G25: =F25-F24 -> 0
A26: 23 | C26: =B26-B25 -> 0 | E26: =D26-D25 -> 0 | G26: =F26-F25 -> 0
A27: 24 | C27: =B27-B26 -> 0 | E27: =D27-D26 -> 0 | G27: =F27-F26 -> 0
A28: 25 | C28: =B28-B27 -> 0 | E28: =D28-D27 -> 0 | G28: =F28-F27 -> 0
... A34: 31 | C34: =B34-B33 -> 0 | E34: =D34-D33 -> 0 | G34: =F34-F33 -> 0
A35: Sum | C35: =SUM(C4:C34) -> -3231504 | E35: =SUM(E4:E34) -> -3897 | G35: =SUM(G4:G34) -> -94828

Sheet Elect
A1: 44835 | M1: Electricity | BP1: Gourmandise UP | BR1: 1.6 | BS1: Power Taxes | BU1: Max Demand | BW1: 500 | BX1: Electricity UP | BZ1: 1.15
BS2: Light Taxes | BU2: PF Penalty | BX2: Max. Demand UP | BZ2: 30
A3: Date | B3: COUNTER (1) | D3: MD | F3: KVAR | H3: n | I3: Guest Rooms Consumption | R3: Casino Consumption | V3: Plant Room Shared Loads | AO3: To Be Charged By First Arabian | BK3: From Main Panel G2 | BS3: Total Consumption. | BT3: No. Of | BU3: KWH/ | BV3: No. Of | BW3: KWH/ | BX3: Total Cost | BY3: L.E\ | BZ3: L.E\
B4: Reading | C4: Consp. F: *800 | D4: Reading | E4: Consp F: 80 | F4: Reading | G4: Consp. F:*10 | I4: Main Feeder | J4: Consp | K4: T2+T8 | L4: Trans T2 | M4: Consp | N4: Trans T8 | O4: Consp | P4: La Gourmandize | Q4: Consp *30 | R4: Casino 3rd floor EM | S4: Consp | T4: Casino 3rd floor Normal | U4: Consp | V4: Chiller 1 | W4: Consp 53% | X4: Chiller 2 | Y4: Consp 53% | Z4: Chiller 3 | AA4: Consp 53% | AB4: Chiller 4 | AC4: Consp 53% | AD4: Chiller 5 | AE4: Consp 53% | AF4: Chiller 6 | AG4: Consp 53% | AH4: Cooling Towers | AI4: Consp 53% | AJ4: Chiller Pumps | AK4: Consp 53% | AL4: Cooling Tower Pumps | AM4: Consp 53% | AN4: Total Plant Room Consp | AO4: Fiber Chiller (N24) | AP4: Consp | AQ4: Mall Ceiling light (N4) | AR4: Consp | AS4: LG Bakery (N2) | AT4: Consp | AU4: LG Bakery light ( Old lockers ) | AV4: Consp | AW4: MCCR1 | AX4: Consp | AY4: Children Swimming pool | AZ4: Consp | BA4: DPH1 | BB4: Consp | BC4: Guest Rooms Emergency | BD4: Consp | BE4: Hotel Hoods | BF4: Consp | BG4: Main G2 | BH4: Consp | BI4: Total Consp From First Arabian | BJ4: First Arabian Charge Back | BK4: Old Casino Emergency | BL4: Consp | BM4: L / A | BN4: Consp | BO4: L / B | BP4: Consp | BQ4: L / C | BR4: Consp | BT4: Rooms | BU4: room | BV4: guest | BW4: guest | BY4: Room | BZ4: Guest
A5: Last Month Reading | I5: 25358857 | J5: =IF(I5>=I4,I5-I4,0) -> 0 | K5: =M5+O5 -> 0 | L5: 153545 | M5: =IF(L5>=L4,L5-L4,0) -> 0 | N5: 194426 | O5: =IF(N5>=N4,N5-N4,0) -> 0 | P5: 226098 | Q5: =IF(P5>=P4,P5-P4,0)*30 -> 0 | R5: 217431 | S5: =IF(R5>=R4,R5-R4,0) -> 0 | T5: 396865 | U5: =IF(T5>=T4,T5-T4,0) -> 0 | V5: 472400 | W5: =IF(V5>=V4,V5-V4,0)*0.53 -> 0 | X5: 734024 | Y5: =IF(X5>=X4,X5-X4,0)*0.53 -> 0 | Z5: 684478 | AA5: =IF(Z5>=Z4,Z5-Z4,0)*0.53 -> 0 | AB5: 68783 | AC5: =IF(AB5>=AB4,AB5-AB4,0)*0.53 -> 0 | AD5: 842083 | AE5: =IF(AD5>=AD4,AD5-AD4,0)*0.53 -> 0 | AF5: 996740 | AG5: =IF(AF5>=AF4,AF5-AF4,0)*0.53 -> 0 | AH5: 358033 | AI5: =IF(AH5>=AH4,AH5-AH4,0)*0.53 -> 0 | AJ5: 178289 | AK5: =IF(AJ5>=AJ4,AJ5-AJ4,0)*0.53 -> 0 | AL5: 554371 | AM5: =IF(AL5>=AL4,AL5-AL4,0)*0.53 -> 0 | AN5: =W5+Y5+AA5+AC5+AE5+AG5+AI5+AK5+AM5 -> 0 | AO5: 8049644 | AP5: =IF(AO5>=AO4,AO5-AO4,0)*0.1125 -> 0 | AQ5: 737609 | AR5: =IF(AQ5>=AQ4,AQ5-AQ4,0) -> 0 | AS5: 4234 | AT5: =IF(AS5>=AS4,AS5-AS4,0) -> 0 | AU5: 823094 | AV5: =IF(AU5>=AU4,AU5-AU4,0) -> 0 | AW5: 2827168 | AX5: =IF(AW5>=AW4,AW5-AW4,0) -> 0 | AY5: 230844 | AZ5: =IF(AY5>=AY4,AY5-AY4,0) -> 0 | BA5: 20483962 | BB5: =IF(BA5>=BA4,BA5-BA4,0) -> 0 | BC5: 624512 | BD5: =IF(BC5>=BC4,BC5-BC4,0) -> 0 | BE5: 41468 | BF5: =IF(BE5>=BE4,BE5-BE4,0) -> 0 | BG5: 25720443 | BH5: =IF(BG5>=BG4,BG5-BG4,0)-(0.45*BN5)-(0.45*BP5)-BR5 -> 0 | BI5: =AP5+AR5+AT5+AV5+AX5+AZ5+BB5+BD5+BF5+BH5 -> 0 | BJ5: =BI5+AN5 -> 0 | BK5: 1480954 | BL5: =IF(BK5>=BK4,BK5-BK4,0) -> 0 | BM5: 4229427 | BN5: =IF(BM5>=BM4,BM5-BM4,0) -> 0 | BO5: 442405 | BP5: =IF(BO5>=BO4,BO5-BO4,0) -> 0 | BQ5: 553744 | BR5: =IF(BQ5>=BQ4,BQ5-BQ4,0) -> 0
A6: 1 | C6: =IF(+B6-B5>0,B6-B5,(B6-B5)>0)*800 -> 0 | E6: =IF(+D6-D5>0,D6-D5,(D6-D5)>0)*80 -> 0 | G6: =IF(+F6-F5>0,F6-F5,(F6-F5)>0)*10 -> 0 | H6: 56 | I6: 25360896 | J6: =IF(I6>=I5,I6-I5,0) -> 2039 | K6: =M6+O6 -> 1738 | L6: 155159 | M6: =IF(L6>=L5,L6-L5,0) -> 1614 | N6: 194550 | O6: =IF(N6>=N5,N6-N5,0) -> 124 | P6: 226125 | Q6: =IF(P6>=P5,P6-P5,0)*30 -> 810 | R6: 217576 | S6: =IF(R6>=R5,R6-R5,0) -> 145 | T6: 397123 | U6: =IF(T6>=T5,T6-T5,0) -> 258 | V6: 478842 | W6: =IF(V6>=V5,V6-V5,0)*0.53 -> 3414.26 | X6: 742565 | Y6: =IF(X6>=X5,X6-X5,0)*0.53 -> 4526.73 | Z6: 684478 | AA6: =IF(Z6>=Z5,Z6-Z5,0)*0.53 -> 0 | AB6: 68783 | AC6: =IF(AB6>=AB5,AB6-AB5,0)*0.53 -> 0 | AD6: 842242 | AE6: =IF(AD6>=AD5,AD6-AD5,0)*0.53 -> 84.27 | AF6: 999896 | AG6: =IF(AF6>=AF5,AF6-AF5,0)*0.53 -> 1672.68 | AH6: 360245 | AI6: =IF(AH6>=AH5,AH6-AH5,0)*0.53 -> 1172.36 | AJ6: 185784 | AK6: =IF(AJ6>=AJ5,AJ6-AJ5,0)*0.53 -> 3972.35 | AL6: 554563 | AM6: =IF(AL6>=AL5,AL6-AL5,0)*0.53 -> 101.76 | AN6: =W6+Y6+AA6+AC6+AE6+AG6+AI6+AK6+AM6 -> 14944.41 | AO6: 8052733 | AP6: =IF(AO6>=AO5,AO6-AO5,0)*0.1125 -> 347.5125 | AQ6: 737802 | AR6: =IF(AQ6>=AQ5,AQ6-AQ5,0) -> 193 | AS6: 4538.6858 | AT6: =IF(AS6>=AS5,AS6-AS5,0) -> 304.68585 | AU6: 823139 | AV6: =IF(AU6>=AU5,AU6-AU5,0) -> 45 | AW6: 2828098 | AX6: =IF(AW6>=AW5,AW6-AW5,0) -> 930 | AY6: 230856 | AZ6: =IF(AY6>=AY5,AY6-AY5,0) -> 12 | BA6: 20488900 | BB6: =IF(BA6>=BA5,BA6-BA5,0) -> 4938 | BC6: 624796 | BD6: =IF(BC6>=BC5,BC6-BC5,0) -> 284 | BE6: 41523 | BF6: =IF(BE6>=BE5,BE6-BE5,0) -> 55 | BG6: 25728058 | BH6: =IF(BG6>=BG5,BG6-BG5,0)-(0.45*BN6)-(0.45*BP6)-BR6 -> 6683.05 | BI6: =AP6+AR6+AT6+AV6+AX6+AZ6+BB6+BD6+BF6+BH6 -> 13792.248 | BJ6: =BI6+AN6 -> 28736.658 | BK6: 1481219 | BL6: =IF(BK6>=BK5,BK6-BK5,0) -> 265 | BM6: 4230991 | BN6: =IF(BM6>=BM5,BM6-BM5,0) -> 1564 | BO6: 442532 | BP6: =IF(BO6>=BO5,BO6-BO5,0) -> 127 | BQ6: 553915 | BR6: =IF(BQ6>=BQ5,BQ6-BQ5,0) -> 171 | BS6: =J6+Q6+AN6+BI6 -> 31585.658 | BT6: 227 | BU6: =IF(BS6>0,BS6/BT5,0) -> #DIV/0! | BW6: =IF(BS6>0,BS6/BV6,0) -> #DIV/0! | BX6: =((BS6-Q6)*$BZ$1)+(Q6*$BR$1) -> 36688.007 | BY6: =IF(BX6>0,BX6/BT5,0) -> #DIV/0! | BZ6: =IF(BX6>0,BX6/BV6,0) -> #DIV/0!
A7: 2 | I7: 25250634 | J7: =IF(I7>=I6,I7-I6,0) -> 0 | K7: =M7+O7 -> 3340 | L7: 156963 | M7: =IF(L7>=L6,L7-L6,0) -> 1804 | N7: 196086 | O7: =IF(N7>=N6,N7-N6,0) -> 1536 | P7: 226144 | Q7: =IF(P7>=P6,P7-P6,0)*30 -> 570 | R7: 217710 | S7: =IF(R7>=R6,R7-R6,0) -> 134 | T7: 397380 | U7: =IF(T7>=T6,T7-T6,0) -> 257 | V7: 485402 | W7: =IF(V7>=V6,V7-V6,0)*0.53 -> 3476.8 | X7: 749787 | Y7: =IF(X7>=X6,X7-X6,0)*0.53 -> 3827.66 | Z7: 684478 | AA7: =IF(Z7>=Z6,Z7-Z6,0)*0.53 -> 0 | AB7: 68783 | AC7: =IF(AB7>=AB6,AB7-AB6,0)*0.53 -> 0 | AD7: 845500 | AE7: =IF(AD7>=AD6,AD7-AD6,0)*0.53 -> 1726.74 | AF7: 999916 | AG7: =IF(AF7>=AF6,AF7-AF6,0)*0.53 -> 10.6 | AH7: 362199 | AI7: =IF(AH7>=AH6,AH7-AH6,0)*0.53 -> 1035.62 | AJ7: 192533 | AK7: =IF(AJ7>=AJ6,AJ7-AJ6,0)*0.53 -> 3576.97 | AL7: 554756 | AM7: =IF(AL7>=AL6,AL7-AL6,0)*0.53 -> 102.29 | AN7: =W7+Y7+AA7+AC7+AE7+AG7+AI7+AK7+AM7 -> 13756.68 | AO7: 8055312 | AP7: =IF(AO7>=AO6,AO7-AO6,0)*0.1125 -> 290.1375 | AQ7: 737956 | AR7: =IF(AQ7>=AQ6,AQ7-AQ6,0) -> 154 | AS7: 4718.4476 | AT7: =IF(AS7>=AS6,AS7-AS6,0) -> 179.76179 | AU7: 823200 | AV7: =IF(AU7>=AU6,AU7-AU6,0) -> 61 | AW7: 2828902 | AX7: =IF(AW7>=AW6,AW7-AW6,0) -> 804 | AY7: 230866 | AZ7: =IF(AY7>=AY6,AY7-AY6,0) -> 10 | BA7: 20494216 | BB7: =IF(BA7>=BA6,BA7-BA6,0) -> 5316 | BC7: 625048 | BD7: =IF(BC7>=BC6,BC7-BC6,0) -> 252 | BE7: 41635 | BF7: =IF(BE7>=BE6,BE7-BE6,0) -> 112 | BG7: 25735409 | BH7: =IF(BG7>=BG6,BG7-BG6,0)-(0.45*BN7)-(0.45*BP7)-BR7 -> 6520.6 | BI7: =AP7+AR7+AT7+AV7+AX7+AZ7+BB7+BD7+BF7+BH7 -> 13699.499 | BJ7: =BI7+AN7 -> 27456.179 | BK7: 1481512 | BL7: =IF(BK7>=BK6,BK7-BK6,0) -> 293 | BM7: 4232390 | BN7: =IF(BM7>=BM6,BM7-BM6,0) -> 1399 | BO7: 442645 | BP7: =IF(BO7>=BO6,BO7-BO6,0) -> 113 | BQ7: 554065 | BR7: =IF(BQ7>=BQ6,BQ7-BQ6,0) -> 150 | BS7: =J7+Q7+AN7+BI7 -> 28026.179 | BT7: 243 | BU7: =IF(BS7>0,BS7/BT6,0) -> 123.46334 | BW7: =IF(BS7>0,BS7/BV7,0) -> #DIV/0! | BX7: =((BS7-Q7)*$BZ$1)+(Q7*$BR$1) -> 32486.606 | BY7: =IF(BX7>0,BX7/BT6,0) -> 143.1128 | BZ7: =IF(BX7>0,BX7/BV7,0) -> #DIV/0!
A8: 3 | C8: =IF(+B8-B7>0,B8-B7,(B8-B7)>0)*800 -> 0 | E8: =IF(+D8-D7>0,D8-D7,(D8-D7)>0)*80 -> 0 | G8: =IF(+F8-F7>0,F8-F7,(F8-F7)>0)*10 -> 0 | H8: 57 | I8: 25256603 | J8: =IF(I8>=I7,I8-I7,0) -> 5969.1111 | K8: =M8+O8 -> 4452 | L8: 159406 | M8: =IF(L8>=L7,L8-L7,0) -> 2443 | N8: 198095 | O8: =IF(N8>=N7,N8-N7,0) -> 2009 | P8: 226169 | Q8: =IF(P8>=P7,P8-P7,0)*30 -> 750 | R8: 217857 | S8: =IF(R8>=R7,R8-R7,0) -> 147 | T8: 397648 | U8: =IF(T8>=T7,T8-T7,0) -> 268 | V8: 492753 | W8: =IF(V8>=V7,V8-V7,0)*0.53 -> 3896.03 | X8: 758238 | Y8: =IF(X8>=X7,X8-X7,0)*0.53 -> 4479.03 | Z8: 684671 | AA8: =IF(Z8>=Z7,Z8-Z7,0)*0.53 -> 102.29 | AB8: 68783 | AC8: =IF(AB8>=AB7,AB8-AB7,0)*0.53 -> 0 | AD8: 848697 | AE8: =IF(AD8>=AD7,AD8-AD7,0)*0.53 -> 1694.41 | AF8: 999937 | AG8: =IF(AF8>=AF7,AF8-AF7,0)*0.53 -> 11.13 | AH8: 364428 | AI8: =IF(AH8>=AH7,AH8-AH7,0)*0.53 -> 1181.37 | AJ8: 201159 | AK8: =IF(AJ8>=AJ7,AJ8-AJ7,0)*0.53 -> 4571.78 | AL8: 555010 | AM8: =IF(AL8>=AL7,AL8-AL7,0)*0.53 -> 134.62 | AN8: =W8+Y8+AA8+AC8+AE8+AG8+AI8+AK8+AM8 -> 16070.66 | AO8: 8058069 | AP8: =IF(AO8>=AO7,AO8-AO7,0)*0.1125 -> 310.1625 | AQ8: 738109 | AR8: =IF(AQ8>=AQ7,AQ8-AQ7,0) -> 153 | AS8: 4898.2094 | AT8: =IF(AS8>=AS7,AS8-AS7,0) -> 179.76179 | AU8: 823269 | AV8: =IF(AU8>=AU7,AU8-AU7,0) -> 69 | AW8: 2829964 | AX8: =IF(AW8>=AW7,AW8-AW7,0) -> 1062 | AY8: 230878 | AZ8: =IF(AY8>=AY7,AY8-AY7,0) -> 12 | BA8: 20500768 | BB8: =IF(BA8>=BA7,BA8-BA7,0) -> 6552 | BC8: 625295 | BD8: =IF(BC8>=BC7,BC8-BC7,0) -> 247 | BE8: 41690 | BF8: =IF(BE8>=BE7,BE8-BE7,0) -> 55 | BG8: 25743058 | BH8: =IF(BG8>=BG7,BG8-BG7,0)-(0.45*BN8)-(0.45*BP8)-BR8 -> 6852.45 | BI8: =AP8+AR8+AT8+AV8+AX8+AZ8+BB8+BD8+BF8+BH8 -> 15492.374 | BJ8: =BI8+AN8 -> 31563.034 | BK8: 1481794 | BL8: =IF(BK8>=BK7,BK8-BK7,0) -> 282 | BM8: 4233740 | BN8: =IF(BM8>=BM7,BM8-BM7,0) -> 1350 | BO8: 442754 | BP8: =IF(BO8>=BO7,BO8-BO7,0) -> 109 | BQ8: 554205 | BR8: =IF(BQ8>=BQ7,BQ8-BQ7,0) -> 140 | BS8: =J8+Q8+AN8+BI8 -> 38282.145 | BT8: 220 | BU8: =IF(BS8>0,BS8/BT7,0) -> 157.53969 | BW8: =IF(BS8>0,BS8/BV8,0) -> #DIV/0! | BX8: =((BS8-Q8)*$BZ$1)+(Q8*$BR$1) -> 44361.967 | BY8: =IF(BX8>0,BX8/BT7,0) -> 182.55954 | BZ8: =IF(BX8>0,BX8/BV8,0) -> #DIV/0!
A9: 4 | C9: =IF(+B9-B8>0,B9-B8,(B9-B8)>0)*800 -> 0 | E9: =IF(+D9-D8>0,D9-D8,(D9-D8)>0)*80 -> 0 | G9: =IF(+F9-F8>0,F9-F8,(F9-F8)>0)*10 -> 0 | I9: 25262572 | J9: =IF(I9>=I8,I9-I8,0) -> 5969.1111 | K9: =M9+O9 -> 3105 | L9: 161132 | M9: =IF(L9>=L8,L9-L8,0) -> 1726 | N9: 199474 | O9: =IF(N9>=N8,N9-N8,0) -> 1379 | P9: 226193 | Q9: =IF(P9>=P8,P9-P8,0)*30 -> 720 | R9: 217996 | S9: =IF(R9>=R8,R9-R8,0) -> 139 | T9: 397888 | U9: =IF(T9>=T8,T9-T8,0) -> 240 | V9: 497774 | W9: =IF(V9>=V8,V9-V8,0)*0.53 -> 2661.13 | X9: 758238 | Y9: =IF(X9>=X8,X9-X8,0)*0.53 -> 0 | Z9: 690679 | AA9: =IF(Z9>=Z8,Z9-Z8,0)*0.53 -> 3184.24 | AB9: 68783 | AC9: =IF(AB9>=AB8,AB9-AB8,0)*0.53 -> 0 | AD9: 851781 | AE9: =IF(AD9>=AD8,AD9-AD8,0)*0.53 -> 1634.52 | AF9: 999958 | AG9: =IF(AF9>=AF8,AF9-AF8,0)*0.53 -> 11.13 | AH9: 366258 | AI9: =IF(AH9>=AH8,AH9-AH8,0)*0.53 -> 969.9 | AJ9: 207511 | AK9: =IF(AJ9>=AJ8,AJ9-AJ8,0)*0.53 -> 3366.56 | AL9: 555204 | AM9: =IF(AL9>=AL8,AL9-AL8,0)*0.53 -> 102.82 | AN9: =W9+Y9+AA9+AC9+AE9+AG9+AI9+AK9+AM9 -> 11930.3 | AO9: 8060613 | AP9: =IF(AO9>=AO8,AO9-AO8,0)*0.1125 -> 286.2 | AQ9: 738257 | AR9: =IF(AQ9>=AQ8,AQ9-AQ8,0) -> 148 | AS9: 5077.9712 | AT9: =IF(AS9>=AS8,AS9-AS8,0) -> 179.76179 | AU9: 823326 | AV9: =IF(AU9>=AU8,AU9-AU8,0) -> 57 | AW9: 2830739 | AX9: =IF(AW9>=AW8,AW9-AW8,0) -> 775 | AY9: 230889 | AZ9: =IF(AY9>=AY8,AY9-AY8,0) -> 11 | BA9: 20504543 | BB9: =IF(BA9>=BA8,BA9-BA8,0) -> 3775 | BC9: 625581 | BD9: =IF(BC9>=BC8,BC9-BC8,0) -> 286 | BE9: 41725 | BF9: =IF(BE9>=BE8,BE9-BE8,0) -> 35 | BG9: 25750104 | BH9: =IF(BG9>=BG8,BG9-BG8,0)-(0.45*BN9)-(0.45*BP9)-BR9 -> 6274.8 | BI9: =AP9+AR9+AT9+AV9+AX9+AZ9+BB9+BD9+BF9+BH9 -> 11827.762 | BJ9: =BI9+AN9 -> 23758.062 | BK9: 1482042 | BL9: =IF(BK9>=BK8,BK9-BK8,0) -> 248 | BM9: 4235030 | BN9: =IF(BM9>=BM8,BM9-BM8,0) -> 1290 | BO9: 442860 | BP9: =IF(BO9>=BO8,BO9-BO8,0) -> 106 | BQ9: 554348 | BR9: =IF(BQ9>=BQ8,BQ9-BQ8,0) -> 143 | BS9: =J9+Q9+AN9+BI9 -> 30447.173 | BT9: 203 | BU9: =IF(BS9>0,BS9/BT8,0) -> 138.39624 | BW9: =IF(BS9>0,BS9/BV9,0) -> #DIV/0! | BX9: =((BS9-Q9)*$BZ$1)+(Q9*$BR$1) -> 35338.249 | BY9: =IF(BX9>0,BX9/BT8,0) -> 160.6284 | BZ9: =IF(BX9>0,BX9/BV9,0) -> #DIV/0!
A10: 5 | C10: =IF(+B10-B9>0,B10-B9,(B10-B9)>0)*800 -> 0 | E10: =IF(+D10-D9>0,D10-D9,(D10-D9)>0)*80 -> 0 | G10: =IF(+F10-F9>0,F10-F9,(F10-F9)>0)*10 -> 0 | H10: 58 | I10: 25268541 | J10: =IF(I10>=I9,I10-I9,0) -> 5969.1111 | K10: =M10+O10 -> 3812 | L10: 163245 | M10: =IF(L10>=L9,L10-L9,0) -> 2113 | N10: 201173 | O10: =IF(N10>=N9,N10-N9,0) -> 1699 | P10: 226211 | Q10: =IF(P10>=P9,P10-P9,0)*30 -> 540 | R10: 218145 | S10: =IF(R10>=R9,R10-R9,0) -> 149 | T10: 398152 | U10: =IF(T10>=T9,T10-T9,0) -> 264 | V10: 504389 | W10: =IF(V10>=V9,V10-V9,0)*0.53 -> 3505.95 | X10: 758238 | Y10: =IF(X10>=X9,X10-X9,0)*0.53 -> 0 | Z10: 698336 | AA10: =IF(Z10>=Z9,Z10-Z9,0)*0.53 -> 4058.21 | AB10: 68783 | AC10: =IF(AB10>=AB9,AB10-AB9,0)*0.53 -> 0 | AD10: 854791 | AE10: =IF(AD10>=AD9,AD10-AD9,0)*0.53 -> 1595.3 | AF10: 999977 | AG10: =IF(AF10>=AF9,AF10-AF9,0)*0.53 -> 10.07 | AH10: 368362 | AI10: =IF(AH10>=AH9,AH10-AH9,0)*0.53 -> 1115.12 | AJ10: 215212 | AK10: =IF(AJ10>=AJ9,AJ10-AJ9,0)*0.53 -> 4081.53 | AL10: 555431 | AM10: =IF(AL10>=AL9,AL10-AL9,0)*0.53 -> 120.31 | AN10: =W10+Y10+AA10+AC10+AE10+AG10+AI10+AK10+AM10 -> 14486.49 | AO10: 8063072 | AP10: =IF(AO10>=AO9,AO10-AO9,0)*0.1125 -> 276.6375 | AQ10: 738407 | AR10: =IF(AQ10>=AQ9,AQ10-AQ9,0) -> 150 | AS10: 5257.733 | AT10: =IF(AS10>=AS9,AS10-AS9,0) -> 179.76179 | AU10: 823391 | AV10: =IF(AU10>=AU9,AU10-AU9,0) -> 65 | AW10: 2831702 | AX10: =IF(AW10>=AW9,AW10-AW9,0) -> 963 | AY10: 230901 | AZ10: =IF(AY10>=AY9,AY10-AY9,0) -> 12 | BA10: 20511197 | BB10: =IF(BA10>=BA9,BA10-BA9,0) -> 6654 | BC10: 625854 | BD10: =IF(BC10>=BC9,BC10-BC9,0) -> 273 | BE10: 41780 | BF10: =IF(BE10>=BE9,BE10-BE9,0) -> 55 | BG10: 25757314 | BH10: =IF(BG10>=BG9,BG10-BG9,0)-(0.45*BN10)-(0.45*BP10)-BR10 -> 6417.65 | BI10: =AP10+AR10+AT10+AV10+AX10+AZ10+BB10+BD10+BF10+BH10 -> 15046.049 | BJ10: =BI10+AN10 -> 29532.539 | BK10: 1482289 | BL10: =IF(BK10>=BK9,BK10-BK9,0) -> 247 | BM10: 4236345 | BN10: =IF(BM10>=BM9,BM10-BM9,0) -> 1315 | BO10: 442968 | BP10: =IF(BO10>=BO9,BO10-BO9,0) -> 108 | BQ10: 554500 | BR10: =IF(BQ10>=BQ9,BQ10-BQ9,0) -> 152 | BS10: =J10+Q10+AN10+BI10 -> 36041.65 | BT10: 187 | BU10: =IF(BS10>0,BS10/BT9,0) -> 177.54508 | BW10: =IF(BS10>0,BS10/BV10,0) -> #DIV/0! | BX10: =((BS10-Q10)*$BZ$1)+(Q10*$BR$1) -> 41690.898 | BY10: =IF(BX10>0,BX10/BT9,0) -> 205.37388 | BZ10: =IF(BX10>0,BX10/BV10,0) -> #DIV/0!
A11: 6 | C11: =IF(+B11-B10>0,B11-B10,(B11-B10)>0)*800 -> 0 | E11: =IF(+D11-D10>0,D11-D10,(D11-D10)>0)*80 -> 0 | G11: =IF(+F11-F10>0,F11-F10,(F11-F10)>0)*10 -> 0 | I11: 25274511 | J11: =IF(I11>=I10,I11-I10,0) -> 5969.1111 | K11: =M11+O11 -> 3532 | L11: 165229 | M11: =IF(L11>=L10,L11-L10,0) -> 1984 | N11: 202721 | O11: =IF(N11>=N10,N11-N10,0) -> 1548 | P11: 226229 | Q11: =IF(P11>=P10,P11-P10,0)*30 -> 540 | R11: 218281 | S11: =IF(R11>=R10,R11-R10,0) -> 136 | T11: 398383 | U11: =IF(T11>=T10,T11-T10,0) -> 231 | V11: 509341 | W11: =IF(V11>=V10,V11-V10,0)*0.53 -> 2624.56 | X11: 758238 | Y11: =IF(X11>=X10,X11-X10,0)*0.53 -> 0 | Z11: 704970 | AA11: =IF(Z11>=Z10,Z11-Z10,0)*0.53 -> 3516.02 | AB11: 68783 | AC11: =IF(AB11>=AB10,AB11-AB10,0)*0.53 -> 0 | AD11: 857599 | AE11: =IF(AD11>=AD10,AD11-AD10,0)*0.53 -> 1488.24 | AF11: 999999 | AG11: =IF(AF11>=AF10,AF11-AF10,0)*0.53 -> 11.66 | AH11: 370090 | AI11: =IF(AH11>=AH10,AH11-AH10,0)*0.53 -> 915.84 | AJ11: 222302 | AK11: =IF(AJ11>=AJ10,AJ11-AJ10,0)*0.53 -> 3757.7 | AL11: 555639 | AM11: =IF(AL11>=AL10,AL11-AL10,0)*0.53 -> 110.24 | AN11: =W11+Y11+AA11+AC11+AE11+AG11+AI11+AK11+AM11 -> 12424.26 | AO11: 8065410 | AP11: =IF(AO11>=AO10,AO11-AO10,0)*0.1125 -> 263.025 | AQ11: 738545 | AR11: =IF(AQ11>=AQ10,AQ11-AQ10,0) -> 138 | AS11: 5488 | AT11: =IF(AS11>=AS10,AS11-AS10,0) -> 230.26701 | AU11: 823440 | AV11: =IF(AU11>=AU10,AU11-AU10,0) -> 49 | AW11: 2832611 | AX11: =IF(AW11>=AW10,AW11-AW10,0) -> 909 | AY11: 230911 | AZ11: =IF(AY11>=AY10,AY11-AY10,0) -> 10 | BA11: 20516107 | BB11: =IF(BA11>=BA10,BA11-BA10,0) -> 4910 | BC11: 626140 | BD11: =IF(BC11>=BC10,BC11-BC10,0) -> 286 | BE11: 41830 | BF11: =IF(BE11>=BE10,BE11-BE10,0) -> 50 | BG11: 25764340 | BH11: =IF(BG11>=BG10,BG11-BG10,0)-(0.45*BN11)-(0.45*BP11)-BR11 -> 6297.65 | BI11: =AP11+AR11+AT11+AV11+AX11+AZ11+BB11+BD11+BF11+BH11 -> 13142.942 | BJ11: =BI11+AN11 -> 25567.202 | BK11: 1482562 | BL11: =IF(BK11>=BK10,BK11-BK10,0) -> 273 | BM11: 4237576 | BN11: =IF(BM11>=BM10,BM11-BM10,0) -> 1231 | BO11: 443080 | BP11: =IF(BO11>=BO10,BO11-BO10,0) -> 112 | BQ11: 554624 | BR11: =IF(BQ11>=BQ10,BQ11-BQ10,0) -> 124 | BS11: =J11+Q11+AN11+BI11 -> 32076.313 | BT11: 203 | BU11: =IF(BS11>0,BS11/BT10,0) -> 171.53109 | BW11: =IF(BS11>0,BS11/BV11,0) -> #DIV/0! | BX11: =((BS11-Q11)*$BZ$1)+(Q11*$BR$1) -> 37130.76 | BY11: =IF(BX11>0,BX11/BT10,0) -> 198.56021 | BZ11: =IF(BX11>0,BX11/BV11,0) -> #DIV/0!
A12: 7 | C12: =IF(+B12-B11>0,B12-B11,(B12-B11)>0)*800 -> 0 | E12: =IF(+D12-D11>0,D12-D11,(D12-D11)>0)*80 -> 0 | G12: =IF(+F12-F11>0,F12-F11,(F12-F11)>0)*10 -> 0 | H12: 59 | I12: 25280480 | J12: =IF(I12>=I11,I12-I11,0) -> 5969.1111 | K12: =M12+O12 -> 2492 | L12: 166992 | M12: =IF(L12>=L11,L12-L11,0) -> 1763 | N12: 203450 | O12: =IF(N12>=N11,N12-N11,0) -> 729 | P12: 226246 | Q12: =IF(P12>=P11,P12-P11,0)*30 -> 510 | R12: 218431 | S12: =IF(R12>=R11,R12-R11,0) -> 150 | T12: 398637 | U12: =IF(T12>=T11,T12-T11,0) -> 254 | V12: 512134 | W12: =IF(V12>=V11,V12-V11,0)*0.53 -> 1480.29 | X12: 758238 | Y12: =IF(X12>=X11,X12-X11,0)*0.53 -> 0 | Z12: 710734 | AA12: =IF(Z12>=Z11,Z12-Z11,0)*0.53 -> 3054.92 | AB12: 68783 | AC12: =IF(AB12>=AB11,AB12-AB11,0)*0.53 -> 0 | AD12: 860195 | AE12: =IF(AD12>=AD11,AD12-AD11,0)*0.53 -> 1375.88 | AF12: 1000020 | AG12: =IF(AF12>=AF11,AF12-AF11,0)*0.53 -> 11.13 | AH12: 371354 | AI12: =IF(AH12>=AH11,AH12-AH11,0)*0.53 -> 669.92 | AJ12: 227911 | AK12: =IF(AJ12>=AJ11,AJ12-AJ11,0)*0.53 -> 2972.77 | AL12: 555824 | AM12: =IF(AL12>=AL11,AL12-AL11,0)*0.53 -> 98.05 | AN12: =W12+Y12+AA12+AC12+AE12+AG12+AI12+AK12+AM12 -> 9662.96 | AO12: 8067503 | AP12: =IF(AO12>=AO11,AO12-AO11,0)*0.1125 -> 235.4625 | AQ12: 738720 | AR12: =IF(AQ12>=AQ11,AQ12-AQ11,0) -> 175 | AS12: 5658 | AT12: =IF(AS12>=AS11,AS12-AS11,0) -> 170 | AU12: 823473 | AV12: =IF(AU12>=AU11,AU12-AU11,0) -> 33 | AW12: 2833401 | AX12: =IF(AW12>=AW11,AW12-AW11,0) -> 790 | AY12: 230923 | AZ12: =IF(AY12>=AY11,AY12-AY11,0) -> 12 | BA12: 20521363 | BB12: =IF(BA12>=BA11,BA12-BA11,0) -> 5256 | BC12: 626425 | BD12: =IF(BC12>=BC11,BC12-BC11,0) -> 285 | BE12: 41875 | BF12: =IF(BE12>=BE11,BE12-BE11,0) -> 45 | BG12: 25771947 | BH12: =IF(BG12>=BG11,BG12-BG11,0)-(0.45*BN12)-(0.45*BP12)-BR12 -> 6744.65 | BI12: =AP12+AR12+AT12+AV12+AX12+AZ12+BB12+BD12+BF12+BH12 -> 13746.112 | BJ12: =BI12+AN12 -> 23409.072 | BK12: 1482894 | BL12: =IF(BK12>=BK11,BK12-BK11,0) -> 332 | BM12: 4239035 | BN12: =IF(BM12>=BM11,BM12-BM11,0) -> 1459 | BO12: 443204 | BP12: =IF(BO12>=BO11,BO12-BO11,0) -> 124 | BQ12: 554774 | BR12: =IF(BQ12>=BQ11,BQ12-BQ11,0) -> 150 | BS12: =J12+Q12+AN12+BI12 -> 29888.184 | BT12: 234 | BU12: =IF(BS12>0,BS12/BT11,0) -> 147.23243 | BW12: =IF(BS12>0,BS12/BV12,0) -> #DIV/0! | BX12: =((BS12-Q12)*$BZ$1)+(Q12*$BR$1) -> 34600.911 | BY12: =IF(BX12>0,BX12/BT11,0) -> 170.44784 | BZ12: =IF(BX12>0,BX12/BV12,0) -> #DIV/0!
A13: 8 | C13: =IF(+B13-B12>0,B13-B12,(B13-B12)>0)*800 -> 0 | E13: =IF(+D13-D12>0,D13-D12,(D13-D12)>0)*80 -> 0 | G13: =IF(+F13-F12>0,F13-F12,(F13-F12)>0)*10 -> 0 | I13: 25286449 | J13: =IF(I13>=I12,I13-I12,0) -> 5969.1111 | K13: =M13+O13 -> 4301 | L13: 169145 | M13: =IF(L13>=L12,L13-L12,0) -> 2153 | N13: 205598 | O13: =IF(N13>=N12,N13-N12,0) -> 2148 | P13: 226265 | Q13: =IF(P13>=P12,P13-P12,0)*30 -> 570 | R13: 218587 | S13: =IF(R13>=R12,R13-R12,0) -> 156 | T13: 398908 | U13: =IF(T13>=T12,T13-T12,0) -> 271 | V13: 512134 | W13: =IF(V13>=V12,V13-V12,0)*0.53 -> 0 | X13: 758238 | Y13: =IF(X13>=X12,X13-X12,0)*0.53 -> 0 | Z13: 719365 | AA13: =IF(Z13>=Z12,Z13-Z12,0)*0.53 -> 4574.43 | AB13: 69387 | AC13: =IF(AB13>=AB12,AB13-AB12,0)*0.53 -> 320.12 | AD13: 860569 | AE13: =IF(AD13>=AD12,AD13-AD12,0)*0.53 -> 198.22 | AF13: 1001863 | AG13: =IF(AF13>=AF12,AF13-AF12,0)*0.53 -> 976.79 | AH13: 372526 | AI13: =IF(AH13>=AH12,AH13-AH12,0)*0.53 -> 621.16 | AJ13: 233966 | AK13: =IF(AJ13>=AJ12,AJ13-AJ12,0)*0.53 -> 3209.15 | AL13: 556063 | AM13: =IF(AL13>=AL12,AL13-AL12,0)*0.53 -> 126.67 | AN13: =W13+Y13+AA13+AC13+AE13+AG13+AI13+AK13+AM13 -> 10026.54 | AO13: 8069872 | AP13: =IF(AO13>=AO12,AO13-AO12,0)*0.1125 -> 266.5125 | AQ13: 738896 | AR13: =IF(AQ13>=AQ12,AQ13-AQ12,0) -> 176 | AS13: 5821 | AT13: =IF(AS13>=AS12,AS13-AS12,0) -> 163 | AU13: 823518 | AV13: =IF(AU13>=AU12,AU13-AU12,0) -> 45 | AW13: 2834328 | AX13: =IF(AW13>=AW12,AW13-AW12,0) -> 927 | AY13: 230935 | AZ13: =IF(AY13>=AY12,AY13-AY12,0) -> 12 | BA13: 20526619 | BB13: =IF(BA13>=BA12,BA13-BA12,0) -> 5256 | BC13: 626659 | BD13: =IF(BC13>=BC12,BC13-BC12,0) -> 234 | BE13: 41925 | BF13: =IF(BE13>=BE12,BE13-BE12,0) -> 50 | BG13: 25778720 | BH13: =IF(BG13>=BG12,BG13-BG12,0)-(0.45*BN13)-(0.45*BP13)-BR13 -> 6065.25 | BI13: =AP13+AR13+AT13+AV13+AX13+AZ13+BB13+BD13+BF13+BH13 -> 13194.763 | BJ13: =BI13+AN13 -> 23221.303 | BK13: 1483184 | BL13: =IF(BK13>=BK12,BK13-BK12,0) -> 290 | BM13: 4240194 | BN13: =IF(BM13>=BM12,BM13-BM12,0) -> 1159 | BO13: 443320 | BP13: =IF(BO13>=BO12,BO13-BO12,0) -> 116 | BQ13: 554908 | BR13: =IF(BQ13>=BQ12,BQ13-BQ12,0) -> 134 | BS13: =J13+Q13+AN13+BI13 -> 29760.414 | BT13: 248 | BU13: =IF(BS13>0,BS13/BT12,0) -> 127.18125 | BW13: =IF(BS13>0,BS13/BV13,0) -> #DIV/0! | BX13: =((BS13-Q13)*$BZ$1)+(Q13*$BR$1) -> 34480.976 | BY13: =IF(BX13>0,BX13/BT12,0) -> 147.3546 | BZ13: =IF(BX13>0,BX13/BV13,0) -> #DIV/0!
A14: 9 | C14: =IF(+B14-B13>0,B14-B13,(B14-B13)>0)*800 -> 0 | E14: =IF(+D14-D13>0,D14-D13,(D14-D13)>0)*80 -> 0 | G14: =IF(+F14-F13>0,F14-F13,(F14-F13)>0)*10 -> 0 | H14: 60 | I14: 25292418 | J14: =IF(I14>=I13,I14-I13,0) -> 5969.1111 | K14: =M14+O14 -> 2717 | L14: 170677 | M14: =IF(L14>=L13,L14-L13,0) -> 1532 | N14: 206783 | O14: =IF(N14>=N13,N14-N13,0) -> 1185 | P14: 226280 | Q14: =IF(P14>=P13,P14-P13,0)*30 -> 450 | R14: 218699 | S14: =IF(R14>=R13,R14-R13,0) -> 112 | T14: 399099 | U14: =IF(T14>=T13,T14-T13,0) -> 191 | V14: 514819 | W14: =IF(V14>=V13,V14-V13,0)*0.53 -> 1423.05 | X14: 758238 | Y14: =IF(X14>=X13,X14-X13,0)*0.53 -> 0 | Z14: 725082 | AA14: =IF(Z14>=Z13,Z14-Z13,0)*0.53 -> 3030.01 | AB14: 69387 | AC14: =IF(AB14>=AB13,AB14-AB13,0)*0.53 -> 0 | AD14: 860587 | AE14: =IF(AD14>=AD13,AD14-AD13,0)*0.53 -> 9.54 | AF14: 1003411 | AG14: =IF(AF14>=AF13,AF14-AF13,0)*0.53 -> 820.44 | AH14: 373243 | AI14: =IF(AH14>=AH13,AH14-AH13,0)*0.53 -> 380.01 | AJ14: 238761 | AK14: =IF(AJ14>=AJ13,AJ14-AJ13,0)*0.53 -> 2541.35 | AL14: 556242 | AM14: =IF(AL14>=AL13,AL14-AL13,0)*0.53 -> 94.87 | AN14: =W14+Y14+AA14+AC14+AE14+AG14+AI14+AK14+AM14 -> 8299.27 | AO14: 8071885 | AP14: =IF(AO14>=AO13,AO14-AO13,0)*0.1125 -> 226.4625 | AQ14: 739048 | AR14: =IF(AQ14>=AQ13,AQ14-AQ13,0) -> 152 | AS14: 5988.6667 | AT14: =IF(AS14>=AS13,AS14-AS13,0) -> 167.66667 | AU14: 823548 | AV14: =IF(AU14>=AU13,AU14-AU13,0) -> 30 | AW14: 2835009 | AX14: =IF(AW14>=AW13,AW14-AW13,0) -> 681 | AY14: 230943 | AZ14: =IF(AY14>=AY13,AY14-AY13,0) -> 8 | BA14: 20530442 | BB14: =IF(BA14>=BA13,BA14-BA13,0) -> 3823 | BC14: 626843 | BD14: =IF(BC14>=BC13,BC14-BC13,0) -> 184 | BE14: 42126 | BF14: =IF(BE14>=BE13,BE14-BE13,0) -> 201 | BG14: 25784246 | BH14: =IF(BG14>=BG13,BG14-BG13,0)-(0.45*BN14)-(0.45*BP14)-BR14 -> 4679.7 | BI14: =AP14+AR14+AT14+AV14+AX14+AZ14+BB14+BD14+BF14+BH14 -> 10152.829 | BJ14: =BI14+AN14 -> 18452.099 | BK14: 1483403 | BL14: =IF(BK14>=BK13,BK14-BK13,0) -> 219 | BM14: 4241760 | BN14: =IF(BM14>=BM13,BM14-BM13,0) -> 1566 | BO14: 443408 | BP14: =IF(BO14>=BO13,BO14-BO13,0) -> 88 | BQ14: 555010 | BR14: =IF(BQ14>=BQ13,BQ14-BQ13,0) -> 102 | BS14: =J14+Q14+AN14+BI14 -> 24871.21 | BT14: 252 | BU14: =IF(BS14>0,BS14/BT13,0) -> 100.28714 | BW14: =IF(BS14>0,BS14/BV14,0) -> #DIV/0! | BX14: =((BS14-Q14)*$BZ$1)+(Q14*$BR$1) -> 28804.392 | BY14: =IF(BX14>0,BX14/BT13,0) -> 116.14674 | BZ14: =IF(BX14>0,BX14/BV14,0) -> #DIV/0!
A15: 10 | C15: =IF(+B15-B14>0,B15-B14,(B15-B14)>0)*800 -> 0 | E15: =IF(+D15-D14>0,D15-D14,(D15-D14)>0)*80 -> 0 | G15: =IF(+F15-F14>0,F15-F14,(F15-F14)>0)*10 -> 0 | I15: 25298387 | J15: =IF(I15>=I14,I15-I14,0) -> 5969.1111 | K15: =M15+O15 -> 3773 | L15: 172623 | M15: =IF(L15>=L14,L15-L14,0) -> 1946 | N15: 208610 | O15: =IF(N15>=N14,N15-N14,0) -> 1827 | P15: 226297.67 | Q15: =IF(P15>=P14,P15-P14,0)*30 -> 530 | R15: 218840.33 | S15: =IF(R15>=R14,R15-R14,0) -> 141.33333 | T15: 399343.33 | U15: =IF(T15>=T14,T15-T14,0) -> 244.33333 | V15: 518564 | W15: =IF(V15>=V14,V15-V14,0)*0.53 -> 1984.85 | X15: 758238 | Y15: =IF(X15>=X14,X15-X14,0)*0.53 -> 0 | Z15: 732741.67 | AA15: =IF(Z15>=Z14,Z15-Z14,0)*0.53 -> 4059.6233 | AB15: 69387 | AC15: =IF(AB15>=AB14,AB15-AB14,0)*0.53 -> 0 | AD15: 860642.33 | AE15: =IF(AD15>=AD14,AD15-AD14,0)*0.53 -> 29.326667 | AF15: 1005155.7 | AG15: =IF(AF15>=AF14,AF15-AF14,0)*0.53 -> 924.67333 | AH15: 374263.33 | AI15: =IF(AH15>=AH14,AH15-AH14,0)*0.53 -> 540.77667 | AJ15: 244396 | AK15: =IF(AJ15>=AJ14,AJ15-AJ14,0)*0.53 -> 2986.55 | AL15: 556461 | AM15: =IF(AL15>=AL14,AL15-AL14,0)*0.53 -> 116.07 | AN15: =W15+Y15+AA15+AC15+AE15+AG15+AI15+AK15+AM15 -> 10641.87 | AO15: 8074135.3 | AP15: =IF(AO15>=AO14,AO15-AO14,0)*0.1125 -> 253.1625 | AQ15: 739216 | AR15: =IF(AQ15>=AQ14,AQ15-AQ14,0) -> 168 | AS15: 6155.1667 | AT15: =IF(AS15>=AS14,AS15-AS14,0) -> 166.5 | AU15: 823588 | AV15: =IF(AU15>=AU14,AU15-AU14,0) -> 40 | AW15: 2835854 | AX15: =IF(AW15>=AW14,AW15-AW14,0) -> 845 | AY15: 230953.67 | AZ15: =IF(AY15>=AY14,AY15-AY14,0) -> 10.666667 | BA15: 20535220 | BB15: =IF(BA15>=BA14,BA15-BA14,0) -> 4778.3333 | BC15: 627060.33 | BD15: =IF(BC15>=BC14,BC15-BC14,0) -> 217.33333 | BE15: 42226.333 | BF15: =IF(BE15>=BE14,BE15-BE14,0) -> 100.33333 | BG15: 25790603 | BH15: =IF(BG15>=BG14,BG15-BG14,0)-(0.45*BN15)-(0.45*BP15)-BR15 -> 5481.3 | BI15: =AP15+AR15+AT15+AV15+AX15+AZ15+BB15+BD15+BF15+BH15 -> 12060.629 | BJ15: =BI15+AN15 -> 22702.499 | BK15: 1483669.3 | BL15: =IF(BK15>=BK14,BK15-BK14,0) -> 266.33333 | BM15: 4243326 | BN15: =IF(BM15>=BM14,BM15-BM14,0) -> 1566 | BO15: 443514.67 | BP15: =IF(BO15>=BO14,BO15-BO14,0) -> 106.66667 | BQ15: 555133.33 | BR15: =IF(BQ15>=BQ14,BQ15-BQ14,0) -> 123.33333 | BS15: =J15+Q15+AN15+BI15 -> 29201.61 | BT15: 246 | BU15: =IF(BS15>0,BS15/BT14,0) -> 115.87941 | BW15: =IF(BS15>0,BS15/BV15,0) -> #DIV/0! | BX15: =((BS15-Q15)*$BZ$1)+(Q15*$BR$1) -> 33820.352 | BY15: =IF(BX15>0,BX15/BT14,0) -> 134.20775 | BZ15: =IF(BX15>0,BX15/BV15,0) -> #DIV/0!
A16: 11 | C16: =IF(+B16-B15>0,B16-B15,(B16-B15)>0)*800 -> 0 | E16: =IF(+D16-D15>0,D16-D15,(D16-D15)>0)*80 -> 0 | G16: =IF(+F16-F15>0,F16-F15,(F16-F15)>0)*10 -> 0 | H16: 61 | I16: 25304356 | J16: =IF(I16>=I15,I16-I15,0) -> 5969.1111 | K16: =M16+O16 -> 3190 | L16: 174448 | M16: =IF(L16>=L15,L16-L15,0) -> 1825 | N16: 209975 | O16: =IF(N16>=N15,N16-N15,0) -> 1365 | P16: 226314 | Q16: =IF(P16>=P15,P16-P15,0)*30 -> 490 | R16: 218980 | S16: =IF(R16>=R15,R16-R15,0) -> 139.66667 | T16: 399618 | U16: =IF(T16>=T15,T16-T15,0) -> 274.66667 | V16: 525866 | W16: =IF(V16>=V15,V16-V15,0)*0.53 -> 3870.06 | X16: 758238 | Y16: =IF(X16>=X15,X16-X15,0)*0.53 -> 0 | Z16: 739458 | AA16: =IF(Z16>=Z15,Z16-Z15,0)*0.53 -> 3559.6567 | AB16: 69387 | AC16: =IF(AB16>=AB15,AB16-AB15,0)*0.53 -> 0 | AD16: 860642.33 | AE16: =IF(AD16>=AD15,AD16-AD15,0)*0.53 -> 0 | AF16: 1005130 | AG16: =IF(AF16>=AF15,AF16-AF15,0)*0.53 -> 0 | AH16: 375146 | AI16: =IF(AH16>=AH15,AH16-AH15,0)*0.53 -> 467.81333 | AJ16: 250961 | AK16: =IF(AJ16>=AJ15,AJ16-AJ15,0)*0.53 -> 3479.45 | AL16: 556658 | AM16: =IF(AL16>=AL15,AL16-AL15,0)*0.53 -> 104.41 | AN16: =W16+Y16+AA16+AC16+AE16+AG16+AI16+AK16+AM16 -> 11481.39 | AO16: 8076539 | AP16: =IF(AO16>=AO15,AO16-AO15,0)*0.1125 -> 270.4125 | AQ16: 739369 | AR16: =IF(AQ16>=AQ15,AQ16-AQ15,0) -> 153 | AS16: 6236 | AT16: =IF(AS16>=AS15,AS16-AS15,0) -> 80.833333 | AU16: 823657 | AV16: =IF(AU16>=AU15,AU16-AU15,0) -> 69 | AW16: 2836686 | AX16: =IF(AW16>=AW15,AW16-AW15,0) -> 832 | AY16: 230965 | AZ16: =IF(AY16>=AY15,AY16-AY15,0) -> 11.333333 | BA16: 20540729 | BB16: =IF(BA16>=BA15,BA16-BA15,0) -> 5508.6667 | BC16: 627312 | BD16: =IF(BC16>=BC15,BC16-BC15,0) -> 251.66667 | BE16: 42265 | BF16: =IF(BE16>=BE15,BE16-BE15,0) -> 38.666667 | BG16: 25798756 | BH16: =IF(BG16>=BG15,BG16-BG15,0)-(0.45*BN16)-(0.45*BP16)-BR16 -> 7703.65 | BI16: =AP16+AR16+AT16+AV16+AX16+AZ16+BB16+BD16+BF16+BH16 -> 14919.229 | BJ16: =BI16+AN16 -> 26400.619 | BK16: 1483967 | BL16: =IF(BK16>=BK15,BK16-BK15,0) -> 297.66667 | BM16: 4243875 | BN16: =IF(BM16>=BM15,BM16-BM15,0) -> 549 | BO16: 443662 | BP16: =IF(BO16>=BO15,BO16-BO15,0) -> 147.33333 | BQ16: 555269 | BR16: =IF(BQ16>=BQ15,BQ16-BQ15,0) -> 135.66667 | BS16: =J16+Q16+AN16+BI16 -> 32859.73 | BT16: 206 | BU16: =IF(BS16>0,BS16/BT15,0) -> 133.57614 | BW16: =IF(BS16>0,BS16/BV16,0) -> #DIV/0! | BX16: =((BS16-Q16)*$BZ$1)+(Q16*$BR$1) -> 38009.19 | BY16: =IF(BX16>0,BX16/BT15,0) -> 154.5089 | BZ16: =IF(BX16>0,BX16/BV16,0) -> #DIV/0!
A17: 12 | C17: =IF(+B17-B16>0,B17-B16,(B17-B16)>0)*800 -> 0 | E17: =IF(+D17-D16>0,D17-D16,(D17-D16)>0)*80 -> 0 | G17: =IF(+F17-F16>0,F17-F16,(F17-F16)>0)*10 -> 0 | I17: 25310325 | J17: =IF(I17>=I16,I17-I16,0) -> 5969.1111 | K17: =M17+O17 -> 4248 | L17: 176584 | M17: =IF(L17>=L16,L17-L16,0) -> 2136 | N17: 212087 | O17: =IF(N17>=N16,N17-N16,0) -> 2112 | P17: 226331 | Q17: =IF(P17>=P16,P17-P16,0)*30 -> 510 | R17: 219132 | S17: =IF(R17>=R16,R17-R16,0) -> 152 | T17: 399901 | U17: =IF(T17>=T16,T17-T16,0) -> 283 | V17: 533168 | W17: =IF(V17>=V16,V17-V16,0)*0.53 -> 3870.06 | X17: 758238 | Y17: =IF(X17>=X16,X17-X16,0)*0.53 -> 0 | Z17: 746788 | AA17: =IF(Z17>=Z16,Z17-Z16,0)*0.53 -> 3884.9 | AB17: 69387 | AC17: =IF(AB17>=AB16,AB17-AB16,0)*0.53 -> 0 | AD17: 860659 | AE17: =IF(AD17>=AD16,AD17-AD16,0)*0.53 -> 8.8333333 | AF17: 1005440 | AG17: =IF(AF17>=AF16,AF17-AF16,0)*0.53 -> 164.3 | AH17: 376215 | AI17: =IF(AH17>=AH16,AH17-AH16,0)*0.53 -> 566.57 | AJ17: 258166 | AK17: =IF(AJ17>=AJ16,AJ17-AJ16,0)*0.53 -> 3818.65 | AL17: 556883 | AM17: =IF(AL17>=AL16,AL17-AL16,0)*0.53 -> 119.25 | AN17: =W17+Y17+AA17+AC17+AE17+AG17+AI17+AK17+AM17 -> 12432.563 | AO17: 8078827 | AP17: =IF(AO17>=AO16,AO17-AO16,0)*0.1125 -> 257.4 | AQ17: 739635 | AR17: =IF(AQ17>=AQ16,AQ17-AQ16,0) -> 266 | AS17: 6373.9444 | AT17: =IF(AS17>=AS16,AS17-AS16,0) -> 137.94444 | AU17: 823712 | AV17: =IF(AU17>=AU16,AU17-AU16,0) -> 55 | AW17: 2837570 | AX17: =IF(AW17>=AW16,AW17-AW16,0) -> 884 | AY17: 230977 | AZ17: =IF(AY17>=AY16,AY17-AY16,0) -> 12 | BA17: 20546557 | BB17: =IF(BA17>=BA16,BA17-BA16,0) -> 5828 | BC17: 627552 | BD17: =IF(BC17>=BC16,BC17-BC16,0) -> 240 | BE17: 42335 | BF17: =IF(BE17>=BE16,BE17-BE16,0) -> 70 | BG17: 25806267 | BH17: =IF(BG17>=BG16,BG17-BG16,0)-(0.45*BN17)-(0.45*BP17)-BR17 -> 6664.05 | BI17: =AP17+AR17+AT17+AV17+AX17+AZ17+BB17+BD17+BF17+BH17 -> 14414.394 | BJ17: =BI17+AN17 -> 26846.958 | BK17: 1484232 | BL17: =IF(BK17>=BK16,BK17-BK16,0) -> 265 | BM17: 4245362 | BN17: =IF(BM17>=BM16,BM17-BM16,0) -> 1487 | BO17: 443746 | BP17: =IF(BO17>=BO16,BO17-BO16,0) -> 84 | BQ17: 555409 | BR17: =IF(BQ17>=BQ16,BQ17-BQ16,0) -> 140 | BS17: =J17+Q17+AN17+BI17 -> 33326.069 | BT17: 174 | BU17: =IF(BS17>0,BS17/BT16,0) -> 161.77703 | BW17: =IF(BS17>0,BS17/BV17,0) -> #DIV/0! | BX17: =((BS17-Q17)*$BZ$1)+(Q17*$BR$1) -> 38554.479 | BY17: =IF(BX17>0,BX17/BT16,0) -> 187.15767 | BZ17: =IF(BX17>0,BX17/BV17,0) -> #DIV/0!
A18: 13 | C18: =IF(+B18-B17>0,B18-B17,(B18-B17)>0)*800 -> 0 | E18: =IF(+D18-D17>0,D18-D17,(D18-D17)>0)*80 -> 0 | G18: =IF(+F18-F17>0,F18-F17,(F18-F17)>0)*10 -> 0 | H18: 62 | I18: 25316294 | J18: =IF(I18>=I17,I18-I17,0) -> 5969.1111 | K18: =M18+O18 -> 3683 | L18: 178414 | M18: =IF(L18>=L17,L18-L17,0) -> 1830 | N18: 213940 | O18: =IF(N18>=N17,N18-N17,0) -> 1853 | P18: 226348 | Q18: =IF(P18>=P17,P18-P17,0)*30 -> 510 | R18: 219262 | S18: =IF(R18>=R17,R18-R17,0) -> 130 | T18: 400134 | U18: =IF(T18>=T17,T18-T17,0) -> 233 | V18: 534878 | W18: =IF(V18>=V17,V18-V17,0)*0.53 -> 906.3 | X18: 758238 | Y18: =IF(X18>=X17,X18-X17,0)*0.53 -> 0 | Z18: 753499 | AA18: =IF(Z18>=Z17,Z18-Z17,0)*0.53 -> 3556.83 | AB18: 69387 | AC18: =IF(AB18>=AB17,AB18-AB17,0)*0.53 -> 0 | AD18: 860680 | AE18: =IF(AD18>=AD17,AD18-AD17,0)*0.53 -> 11.13 | AF18: 1006630 | AG18: =IF(AF18>=AF17,AF18-AF17,0)*0.53 -> 630.7 | AH18: 377056 | AI18: =IF(AH18>=AH17,AH18-AH17,0)*0.53 -> 445.73 | AJ18: 264046 | AK18: =IF(AJ18>=AJ17,AJ18-AJ17,0)*0.53 -> 3116.4 | AL18: 557077 | AM18: =IF(AL18>=AL17,AL18-AL17,0)*0.53 -> 102.82 | AN18: =W18+Y18+AA18+AC18+AE18+AG18+AI18+AK18+AM18 -> 8769.91 | AO18: 8080551 | AP18: =IF(AO18>=AO17,AO18-AO17,0)*0.1125 -> 193.95 | AQ18: 739779 | AR18: =IF(AQ18>=AQ17,AQ18-AQ17,0) -> 144 | AS18: 6680 | AT18: =IF(AS18>=AS17,AS18-AS17,0) -> 306.05556 | AU18: 823757 | AV18: =IF(AU18>=AU17,AU18-AU17,0) -> 45 | AW18: 2838337 | AX18: =IF(AW18>=AW17,AW18-AW17,0) -> 767 | AY18: 230987 | AZ18: =IF(AY18>=AY17,AY18-AY17,0) -> 10 | BA18: 20551048 | BB18: =IF(BA18>=BA17,BA18-BA17,0) -> 4491 | BC18: 627751 | BD18: =IF(BC18>=BC17,BC18-BC17,0) -> 199 | BE18: 42400 | BF18: =IF(BE18>=BE17,BE18-BE17,0) -> 65 | BG18: 25812636 | BH18: =IF(BG18>=BG17,BG18-BG17,0)-(0.45*BN18)-(0.45*BP18)-BR18 -> 5618.95 | BI18: =AP18+AR18+AT18+AV18+AX18+AZ18+BB18+BD18+BF18+BH18 -> 11839.956 | BJ18: =BI18+AN18 -> 20609.866 | BK18: 1484429 | BL18: =IF(BK18>=BK17,BK18-BK17,0) -> 197 | BM18: 4246630 | BN18: =IF(BM18>=BM17,BM18-BM17,0) -> 1268 | BO18: 443847 | BP18: =IF(BO18>=BO17,BO18-BO17,0) -> 101 | BQ18: 555543 | BR18: =IF(BQ18>=BQ17,BQ18-BQ17,0) -> 134 | BS18: =J18+Q18+AN18+BI18 -> 27088.977 | BT18: 162 | BU18: =IF(BS18>0,BS18/BT17,0) -> 155.68377 | BW18: =IF(BS18>0,BS18/BV18,0) -> #DIV/0! | BX18: =((BS18-Q18)*$BZ$1)+(Q18*$BR$1) -> 31381.823 | BY18: =IF(BX18>0,BX18/BT17,0) -> 180.35531 | BZ18: =IF(BX18>0,BX18/BV18,0) -> #DIV/0!
A19: 14 | C19: =IF(+B19-B18>0,B19-B18,(B19-B18)>0)*800 -> 0 | E19: =IF(+D19-D18>0,D19-D18,(D19-D18)>0)*80 -> 0 | G19: =IF(+F19-F18>0,F19-F18,(F19-F18)>0)*10 -> 0 | I19: 25322263 | J19: =IF(I19>=I18,I19-I18,0) -> 5969.1111 | K19: =M19+O19 -> 3870 | L19: 180433 | M19: =IF(L19>=L18,L19-L18,0) -> 2019 | N19: 215791 | O19: =IF(N19>=N18,N19-N18,0) -> 1851 | P19: 226367 | Q19: =IF(P19>=P18,P19-P18,0)*30 -> 570 | R19: 219410 | S19: =IF(R19>=R18,R19-R18,0) -> 148 | T19: 400405 | U19: =IF(T19>=T18,T19-T18,0) -> 271 | V19: 537153 | W19: =IF(V19>=V18,V19-V18,0)*0.53 -> 1205.75 | X19: 758048 | Y19: =IF(X19>=X18,X19-X18,0)*0.53 -> 0 | Z19: 759048 | AA19: =IF(Z19>=Z18,Z19-Z18,0)*0.53 -> 2940.97 | AB19: 70768 | AC19: =IF(AB19>=AB18,AB19-AB18,0)*0.53 -> 731.93 | AD19: 860705 | AE19: =IF(AD19>=AD18,AD19-AD18,0)*0.53 -> 13.25 | AF19: 1007983 | AG19: =IF(AF19>=AF18,AF19-AF18,0)*0.53 -> 717.09 | AH19: 377982 | AI19: =IF(AH19>=AH18,AH19-AH18,0)*0.53 -> 490.78 | AJ19: 270905 | AK19: =IF(AJ19>=AJ18,AJ19-AJ18,0)*0.53 -> 3635.27 | AL19: 557289 | AM19: =IF(AL19>=AL18,AL19-AL18,0)*0.53 -> 112.36 | AN19: =W19+Y19+AA19+AC19+AE19+AG19+AI19+AK19+AM19 -> 9847.4 | AO19: 8082560 | AP19: =IF(AO19>=AO18,AO19-AO18,0)*0.1125 -> 226.0125 | AQ19: 739944 | AR19: =IF(AQ19>=AQ18,AQ19-AQ18,0) -> 165 | AS19: 6847 | AT19: =IF(AS19>=AS18,AS19-AS18,0) -> 167 | AU19: 823798 | AV19: =IF(AU19>=AU18,AU19-AU18,0) -> 41 | AW19: 2839169 | AX19: =IF(AW19>=AW18,AW19-AW18,0) -> 832 | AY19: 230998 | AZ19: =IF(AY19>=AY18,AY19-AY18,0) -> 11 | BA19: 20556233 | BB19: =IF(BA19>=BA18,BA19-BA18,0) -> 5185 | BC19: 627977 | BD19: =IF(BC19>=BC18,BC19-BC18,0) -> 226 | BE19: 42463 | BF19: =IF(BE19>=BE18,BE19-BE18,0) -> 63 | BG19: 25819849 | BH19: =IF(BG19>=BG18,BG19-BG18,0)-(0.45*BN19)-(0.45*BP19)-BR19 -> 6394.7 | BI19: =AP19+AR19+AT19+AV19+AX19+AZ19+BB19+BD19+BF19+BH19 -> 13310.712 | BJ19: =BI19+AN19 -> 23158.113 | BK19: 1484688 | BL19: =IF(BK19>=BK18,BK19-BK18,0) -> 259 | BM19: 4248011 | BN19: =IF(BM19>=BM18,BM19-BM18,0) -> 1381 | BO19: 443960 | BP19: =IF(BO19>=BO18,BO19-BO18,0) -> 113 | BQ19: 555689 | BR19: =IF(BQ19>=BQ18,BQ19-BQ18,0) -> 146 | BS19: =J19+Q19+AN19+BI19 -> 29697.224 | BT19: 207 | BU19: =IF(BS19>0,BS19/BT18,0) -> 183.3162 | BW19: =IF(BS19>0,BS19/BV19,0) -> #DIV/0! | BX19: =((BS19-Q19)*$BZ$1)+(Q19*$BR$1) -> 34408.307 | BY19: =IF(BX19>0,BX19/BT18,0) -> 212.39696 | BZ19: =IF(BX19>0,BX19/BV19,0) -> #DIV/0!
