Workbook

Sheet TOTAL
A1: Site Name | B1: Day | C1: Month | D1: Year | E1: Total Electricity Kwh | F1: Electricity Tariff ($/Kwh) | G1: LPG (Kg) | H1: LPG $/Kg | I1: Water Utility Supply (m3) m3 | J1: Water Utility Supply (m3) $/m3 | K1: Irrigation Water (m3) m3 | L1: Irrigation water $/m3 | M1: Room Nights
A2: Seychelles | B2: 1 | C2: 12 | D2: 2022 | E2: =SUM('FS Seychelles'!D3:I3)*1000 -> 20770 | F2: =(('FS Seychelles'!O3*'FS Seychelles'!P3)+('FS Seychelles'!Q3*'FS Seychelles'!R3))/TOTAL!E2 -> 0 | G2: =('FS Seychelles'!$Z$10+'FS Seychelles'!$Z$15)/30 -> 0 | H2: 1.05 | I2: =SUM('FS Seychelles'!S3:W3) -> 383 | J2: 0 | K2: ='FS Seychelles'!AA3 -> 103 | L2: 0 | M2: ='FS Seychelles'!B3 -> 55.8
A3: Seychelles | B3: =B2+1 -> 2 | C3: =C2 -> 12 | D3: 2022 | E3: =SUM('FS Seychelles'!D4:I4)*1000 -> 18700 | F3: =(('FS Seychelles'!O4*'FS Seychelles'!P4)+('FS Seychelles'!Q4*'FS Seychelles'!R4))/TOTAL!E3 -> 0 | G3: =('FS Seychelles'!$Z$10+'FS Seychelles'!$Z$15)/30 -> 0 | H3: =H2 -> 1.05 | I3: =SUM('FS Seychelles'!S4:W4) -> 330 | J3: =J2 -> 0 | K3: ='FS Seychelles'!AA4 -> 136 | L3: =L2 -> 0 | M3: ='FS Seychelles'!B4 -> 59.7
A4: Seychelles | B4: =B3+1 -> 3 | C4: =C3 -> 12 | D4: 2022 | E4: =SUM('FS Seychelles'!D5:I5)*1000 -> 20060 | F4: =(('FS Seychelles'!O5*'FS Seychelles'!P5)+('FS Seychelles'!Q5*'FS Seychelles'!R5))/TOTAL!E4 -> 0 | G4: =('FS Seychelles'!$Z$10+'FS Seychelles'!$Z$15)/30 -> 0 | H4: =H3 -> 1.05 | I4: =SUM('FS Seychelles'!S5:W5) -> 313 | J4: =J3 -> 0 | K4: ='FS Seychelles'!AA5 -> 109 | L4: =L3 -> 0 | M4: ='FS Seychelles'!B5 -> 57.1
A5: Seychelles | B5: =B4+1 -> 4 | C5: =C4 -> 12 | D5: 2022 | E5: =SUM('FS Seychelles'!D6:I6)*1000 -> 19560 | F5: =(('FS Seychelles'!O6*'FS Seychelles'!P6)+('FS Seychelles'!Q6*'FS Seychelles'!R6))/TOTAL!E5 -> 0 | G5: =('FS Seychelles'!$Z$10+'FS Seychelles'!$Z$15)/30 -> 0 | H5: =H4 -> 1.05 | I5: =SUM('FS Seychelles'!S6:W6) -> 377 | J5: =J4 -> 0 | K5: ='FS Seychelles'!AA6 -> 97 | L5: =L4 -> 0 | M5: ='FS Seychelles'!B6 -> 40.3
A6: Seychelles | B6: =B5+1 -> 5 | C6: =C5 -> 12 | D6: 2022 | E6: =SUM('FS Seychelles'!D7:I7)*1000 -> 19690 | F6: =(('FS Seychelles'!O7*'FS Seychelles'!P7)+('FS Seychelles'!Q7*'FS Seychelles'!R7))/TOTAL!E6 -> 0 | G6: =('FS Seychelles'!$Z$10+'FS Seychelles'!$Z$15)/30 -> 0 | H6: =H5 -> 1.05 | I6: =SUM('FS Seychelles'!S7:W7) -> 387 | J6: =J5 -> 0 | K6: ='FS Seychelles'!AA7 -> 58 | L6: =L5 -> 0 | M6: ='FS Seychelles'!B7 -> 39
A7: Seychelles | B7: =B6+1 -> 6 | C7: =C6 -> 12 | D7: 2022 | E7: =SUM('FS Seychelles'!D8:I8)*1000 -> 0 | F7: =(('FS Seychelles'!O8*'FS Seychelles'!P8)+('FS Seychelles'!Q8*'FS Seychelles'!R8))/TOTAL!E7 -> #DIV/0! | G7: =('FS Seychelles'!$Z$10+'FS Seychelles'!$Z$15)/30 -> 0 | H7: =H6 -> 1.05 | I7: =SUM('FS Seychelles'!S8:W8) -> 0 | J7: =J6 -> 0 | K7: ='FS Seychelles'!AA8 -> 56 | L7: =L6 -> 0 | M7: ='FS Seychelles'!B8 -> 0
A8: Seychelles | B8: =B7+1 -> 7 | C8: =C7 -> 12 | D8: 2022 | E8: =SUM('FS Seychelles'!D9:I9)*1000 -> 0 | F8: =(('FS Seychelles'!O9*'FS Seychelles'!P9)+('FS Seychelles'!Q9*'FS Seychelles'!R9))/TOTAL!E8 -> #DIV/0! | G8: =('FS Seychelles'!$Z$10+'FS Seychelles'!$Z$15)/30 -> 0 | H8: =H7 -> 1.05 | I8: =SUM('FS Seychelles'!S9:W9) -> 0 | J8: =J7 -> 0 | K8: ='FS Seychelles'!AA9 -> -54932 | L8: =L7 -> 0 | M8: ='FS Seychelles'!B9 -> 0
A9: Seychelles | B9: =B8+1 -> 8 | C9: =C8 -> 12 | D9: 2022 | E9: =SUM('FS Seychelles'!D10:I10)*1000 -> 0 | F9: =(('FS Seychelles'!O10*'FS Seychelles'!P10)+('FS Seychelles'!Q10*'FS Seychelles'!R10))/TOTAL!E9 -> #DIV/0! | G9: =('FS Seychelles'!$Z$10+'FS Seychelles'!$Z$15)/30 -> 0 | H9: =H8 -> 1.05 | I9: =SUM('FS Seychelles'!S10:W10) -> 0 | J9: =J8 -> 0 | K9: ='FS Seychelles'!AA10 -> 0 | L9: =L8 -> 0 | M9: ='FS Seychelles'!B10 -> 0
A10: Seychelles | B10: =B9+1 -> 9 | C10: =C9 -> 12 | D10: 2022 | E10: =SUM('FS Seychelles'!D11:I11)*1000 -> 0 | F10: =(('FS Seychelles'!O11*'FS Seychelles'!P11)+('FS Seychelles'!Q11*'FS Seychelles'!R11))/TOTAL!E10 -> #DIV/0! | G10: =('FS Seychelles'!$Z$10+'FS Seychelles'!$Z$15)/30 -> 0 | H10: =H9 -> 1.05 | I10: =SUM('FS Seychelles'!S11:W11) -> 0 | J10: =J9 -> 0 | K10: ='FS Seychelles'!AA11 -> 0 | L10: =L9 -> 0 | M10: ='FS Seychelles'!B11 -> 0
A11: Seychelles | B11: =B10+1 -> 10 | C11: =C10 -> 12 | D11: 2022 | E11: =SUM('FS Seychelles'!D12:I12)*1000 -> 0 | F11: =(('FS Seychelles'!O12*'FS Seychelles'!P12)+('FS Seychelles'!Q12*'FS Seychelles'!R12))/TOTAL!E11 -> #DIV/0! | G11: =('FS Seychelles'!$Z$10+'FS Seychelles'!$Z$15)/30 -> 0 | H11: =H10 -> 1.05 | I11: =SUM('FS Seychelles'!S12:W12) -> 0 | J11: =J10 -> 0 | K11: ='FS Seychelles'!AA12 -> 0 | L11: =L10 -> 0 | M11: ='FS Seychelles'!B12 -> 0
A12: Seychelles | B12: =B11+1 -> 11 | C12: =C11 -> 12 | D12: 2022 | E12: =SUM('FS Seychelles'!D13:I13)*1000 -> 0 | F12: =(('FS Seychelles'!O13*'FS Seychelles'!P13)+('FS Seychelles'!Q13*'FS Seychelles'!R13))/TOTAL!E12 -> #DIV/0! | G12: =('FS Seychelles'!$Z$10+'FS Seychelles'!$Z$15)/30 -> 0 | H12: =H11 -> 1.05 | I12: =SUM('FS Seychelles'!S13:W13) -> 0 | J12: =J11 -> 0 | K12: ='FS Seychelles'!AA13 -> 0 | L12: =L11 -> 0 | M12: ='FS Seychelles'!B13 -> 0
A13: Seychelles | B13: =B12+1 -> 12 | C13: =C12 -> 12 | D13: 2022 | E13: =SUM('FS Seychelles'!D14:I14)*1000 -> 0 | F13: =(('FS Seychelles'!O14*'FS Seychelles'!P14)+('FS Seychelles'!Q14*'FS Seychelles'!R14))/TOTAL!E13 -> #DIV/0! | G13: =('FS Seychelles'!$Z$10+'FS Seychelles'!$Z$15)/30 -> 0 | H13: =H12 -> 1.05 | I13: =SUM('FS Seychelles'!S14:W14) -> 0 | J13: =J12 -> 0 | K13: ='FS Seychelles'!AA14 -> 0 | L13: =L12 -> 0 | M13: ='FS Seychelles'!B14 -> 0
A14: Seychelles | B14: =B13+1 -> 13 | C14: =C13 -> 12 | D14: 2022 | E14: =SUM('FS Seychelles'!D15:I15)*1000 -> 0 | F14: =(('FS Seychelles'!O15*'FS Seychelles'!P15)+('FS Seychelles'!Q15*'FS Seychelles'!R15))/TOTAL!E14 -> #DIV/0! | G14: =('FS Seychelles'!$Z$10+'FS Seychelles'!$Z$15)/30 -> 0 | H14: =H13 -> 1.05 | I14: =SUM('FS Seychelles'!S15:W15) -> 0 | J14: =J13 -> 0 | K14: ='FS Seychelles'!AA15 -> 0 | L14: =L13 -> 0 | M14: ='FS Seychelles'!B15 -> 0
... A32: Seychelles | B32: =B31+1 -> 31 | C32: =C31 -> 12 | D32: 2022 | E32: =SUM('FS Seychelles'!D33:I33)*1000 -> 0 | F32: =(('FS Seychelles'!O33*'FS Seychelles'!P33)+('FS Seychelles'!Q33*'FS Seychelles'!R33))/TOTAL!E32 -> #DIV/0! | G32: =('FS Seychelles'!$Z$10+'FS Seychelles'!$Z$15)/30 -> 0 | H32: =H31 -> 1.05 | I32: =SUM('FS Seychelles'!S33:W33) -> 0 | J32: =J31 -> 0 | K32: ='FS Seychelles'!AA33 -> 0 | L32: =L31 -> 0 | M32: ='FS Seychelles'!B33 -> 0

Sheet Submetering 
A1: Site Name | B1: Day | C1: Month | D1: Year | E1: Room Night | F1: SS-A - KWh | G1: SS-B- KWh | H1: SS-C- KWh | I1: FIRE PUMP- KWh | J1: CASINO- KWh | K1: BOH- KWh | L1: Generator#1 - KWh | M1: Generator#2- KWh | N1: Generator#3- KWh | O1: Generator#4- KWh | P1: Generator#5- KWh | Q1: DIESEL - Liter | R1: PUC - KWh | S1: BOH Water- m3 | T1: WT59- m3 | U1: WT08- m3 | V1: PUC (HOH)- m3 | W1: Fire Pump- m3 | X1: LPG (Kg)
A2: Seychelles | B2: 1 | C2: 12 | D2: 2022 | E2: ='FS Seychelles'!B3 -> 55.8 | F2: ='FS Seychelles'!D3*1000 -> 3070 | G2: ='FS Seychelles'!E3*1000 -> 4400 | H2: ='FS Seychelles'!F3*1000 -> 5880 | I2: ='FS Seychelles'!G3*1000 -> 1530 | J2: ='FS Seychelles'!H3*1000 -> 1880 | K2: ='FS Seychelles'!I3*1000 -> 4010 | L2: ='FS Seychelles'!J3 -> 12787 | M2: ='FS Seychelles'!K3 -> 10907 | N2: ='FS Seychelles'!L3 -> 5248 | O2: ='FS Seychelles'!M3 -> 0 | P2: ='FS Seychelles'!N3 -> 7520 | Q2: ='FS Seychelles'!O3 -> 0 | R2: ='FS Seychelles'!Q3 -> 0 | S2: ='FS Seychelles'!S3 -> 60 | T2: ='FS Seychelles'!T3 -> 152 | U2: ='FS Seychelles'!U3 -> 71 | V2: ='FS Seychelles'!V3 -> 100 | W2: ='FS Seychelles'!W3 -> 0 | X2: =('FS Seychelles'!Z9+'FS Seychelles'!Z15)/30 -> 0
A3: Seychelles | B3: =B2+1 -> 2 | C3: =C2 -> 12 | D3: 2022 | E3: ='FS Seychelles'!B4 -> 59.7 | F3: ='FS Seychelles'!D4*1000 -> 2480 | G3: ='FS Seychelles'!E4*1000 -> 3870 | H3: ='FS Seychelles'!F4*1000 -> 5370 | I3: ='FS Seychelles'!G4*1000 -> 1450 | J3: ='FS Seychelles'!H4*1000 -> 1710 | K3: ='FS Seychelles'!I4*1000 -> 3820 | L3: ='FS Seychelles'!J4 -> 5363 | M3: ='FS Seychelles'!K4 -> 10782 | N3: ='FS Seychelles'!L4 -> 5378 | O3: ='FS Seychelles'!M4 -> 0 | P3: ='FS Seychelles'!N4 -> 10802 | Q3: ='FS Seychelles'!O4 -> 0 | R3: ='FS Seychelles'!Q4 -> 0 | S3: ='FS Seychelles'!S4 -> 58 | T3: ='FS Seychelles'!T4 -> 97 | U3: ='FS Seychelles'!U4 -> 75 | V3: ='FS Seychelles'!V4 -> 100 | W3: ='FS Seychelles'!W4 -> 0 | X3: =('FS Seychelles'!Z10+'FS Seychelles'!Z16)/30 -> 0
A4: Seychelles | B4: =B3+1 -> 3 | C4: =C3 -> 12 | D4: 2022 | E4: ='FS Seychelles'!B5 -> 57.1 | F4: ='FS Seychelles'!D5*1000 -> 2940 | G4: ='FS Seychelles'!E5*1000 -> 4320 | H4: ='FS Seychelles'!F5*1000 -> 5750 | I4: ='FS Seychelles'!G5*1000 -> 1440 | J4: ='FS Seychelles'!H5*1000 -> 1770 | K4: ='FS Seychelles'!I5*1000 -> 3840 | L4: ='FS Seychelles'!J5 -> 8388 | M4: ='FS Seychelles'!K5 -> 6931 | N4: ='FS Seychelles'!L5 -> 11861 | O4: ='FS Seychelles'!M5 -> 0 | P4: ='FS Seychelles'!N5 -> 5766 | Q4: ='FS Seychelles'!O5 -> 0 | R4: ='FS Seychelles'!Q5 -> 0 | S4: ='FS Seychelles'!S5 -> 57 | T4: ='FS Seychelles'!T5 -> 67 | U4: ='FS Seychelles'!U5 -> 87 | V4: ='FS Seychelles'!V5 -> 102 | W4: ='FS Seychelles'!W5 -> 0 | X4: =('FS Seychelles'!Z11+'FS Seychelles'!Z17)/30 -> 0
A5: Seychelles | B5: =B4+1 -> 4 | C5: =C4 -> 12 | D5: 2022 | E5: ='FS Seychelles'!B6 -> 40.3 | F5: ='FS Seychelles'!D6*1000 -> 3080 | G5: ='FS Seychelles'!E6*1000 -> 4450 | H5: ='FS Seychelles'!F6*1000 -> 5480 | I5: ='FS Seychelles'!G6*1000 -> 1230 | J5: ='FS Seychelles'!H6*1000 -> 1690 | K5: ='FS Seychelles'!I6*1000 -> 3630 | L5: ='FS Seychelles'!J6 -> 10905 | M5: ='FS Seychelles'!K6 -> 8754 | N5: ='FS Seychelles'!L6 -> 7905 | O5: ='FS Seychelles'!M6 -> 0 | P5: ='FS Seychelles'!N6 -> 8073 | Q5: ='FS Seychelles'!O6 -> 0 | R5: ='FS Seychelles'!Q6 -> 0 | S5: ='FS Seychelles'!S6 -> 71 | T5: ='FS Seychelles'!T6 -> 145 | U5: ='FS Seychelles'!U6 -> 63 | V5: ='FS Seychelles'!V6 -> 98 | W5: ='FS Seychelles'!W6 -> 0 | X5: =('FS Seychelles'!Z12+'FS Seychelles'!Z18)/30 -> 0
A6: Seychelles | B6: =B5+1 -> 5 | C6: =C5 -> 12 | D6: 2022 | E6: ='FS Seychelles'!B7 -> 39 | F6: ='FS Seychelles'!D7*1000 -> 3240 | G6: ='FS Seychelles'!E7*1000 -> 4320 | H6: ='FS Seychelles'!F7*1000 -> 5480 | I6: ='FS Seychelles'!G7*1000 -> 1140 | J6: ='FS Seychelles'!H7*1000 -> 1740 | K6: ='FS Seychelles'!I7*1000 -> 3770 | L6: ='FS Seychelles'!J7 -> 5104 | M6: ='FS Seychelles'!K7 -> 15185 | N6: ='FS Seychelles'!L7 -> 8249 | O6: ='FS Seychelles'!M7 -> 0 | P6: ='FS Seychelles'!N7 -> 4060 | Q6: ='FS Seychelles'!O7 -> 0 | R6: ='FS Seychelles'!Q7 -> 0 | S6: ='FS Seychelles'!S7 -> 60 | T6: ='FS Seychelles'!T7 -> 155 | U6: ='FS Seychelles'!U7 -> 71 | V6: ='FS Seychelles'!V7 -> 101 | W6: ='FS Seychelles'!W7 -> 0 | X6: =('FS Seychelles'!Z13+'FS Seychelles'!Z19)/30 -> 0
A7: Seychelles | B7: =B6+1 -> 6 | C7: =C6 -> 12 | D7: 2022 | E7: ='FS Seychelles'!B8 -> 0 | F7: ='FS Seychelles'!D8*1000 -> 0 | G7: ='FS Seychelles'!E8*1000 -> 0 | H7: ='FS Seychelles'!F8*1000 -> 0 | I7: ='FS Seychelles'!G8*1000 -> 0 | J7: ='FS Seychelles'!H8*1000 -> 0 | K7: ='FS Seychelles'!I8*1000 -> 0 | L7: ='FS Seychelles'!J8 -> 0 | M7: ='FS Seychelles'!K8 -> 0 | N7: ='FS Seychelles'!L8 -> 0 | O7: ='FS Seychelles'!M8 -> 0 | P7: ='FS Seychelles'!N8 -> 0 | Q7: ='FS Seychelles'!O8 -> 0 | R7: ='FS Seychelles'!Q8 -> 0 | S7: ='FS Seychelles'!S8 -> 0 | T7: ='FS Seychelles'!T8 -> 0 | U7: ='FS Seychelles'!U8 -> 0 | V7: ='FS Seychelles'!V8 -> 0 | W7: ='FS Seychelles'!W8 -> 0 | X7: =('FS Seychelles'!Z14+'FS Seychelles'!Z20)/30 -> 0
A8: Seychelles | B8: =B7+1 -> 7 | C8: =C7 -> 12 | D8: 2022 | E8: ='FS Seychelles'!B9 -> 0 | F8: ='FS Seychelles'!D9*1000 -> 0 | G8: ='FS Seychelles'!E9*1000 -> 0 | H8: ='FS Seychelles'!F9*1000 -> 0 | I8: ='FS Seychelles'!G9*1000 -> 0 | J8: ='FS Seychelles'!H9*1000 -> 0 | K8: ='FS Seychelles'!I9*1000 -> 0 | L8: ='FS Seychelles'!J9 -> 0 | M8: ='FS Seychelles'!K9 -> 0 | N8: ='FS Seychelles'!L9 -> 0 | O8: ='FS Seychelles'!M9 -> 0 | P8: ='FS Seychelles'!N9 -> 0 | Q8: ='FS Seychelles'!O9 -> 0 | R8: ='FS Seychelles'!Q9 -> 0 | S8: ='FS Seychelles'!S9 -> 0 | T8: ='FS Seychelles'!T9 -> 0 | U8: ='FS Seychelles'!U9 -> 0 | V8: ='FS Seychelles'!V9 -> 0 | W8: ='FS Seychelles'!W9 -> 0 | X8: =('FS Seychelles'!Z15+'FS Seychelles'!Z21)/30 -> 0
A9: Seychelles | B9: =B8+1 -> 8 | C9: =C8 -> 12 | D9: 2022 | E9: ='FS Seychelles'!B10 -> 0 | F9: ='FS Seychelles'!D10*1000 -> 0 | G9: ='FS Seychelles'!E10*1000 -> 0 | H9: ='FS Seychelles'!F10*1000 -> 0 | I9: ='FS Seychelles'!G10*1000 -> 0 | J9: ='FS Seychelles'!H10*1000 -> 0 | K9: ='FS Seychelles'!I10*1000 -> 0 | L9: ='FS Seychelles'!J10 -> 0 | M9: ='FS Seychelles'!K10 -> 0 | N9: ='FS Seychelles'!L10 -> 0 | O9: ='FS Seychelles'!M10 -> 0 | P9: ='FS Seychelles'!N10 -> 0 | Q9: ='FS Seychelles'!O10 -> 0 | R9: ='FS Seychelles'!Q10 -> 0 | S9: ='FS Seychelles'!S10 -> 0 | T9: ='FS Seychelles'!T10 -> 0 | U9: ='FS Seychelles'!U10 -> 0 | V9: ='FS Seychelles'!V10 -> 0 | W9: ='FS Seychelles'!W10 -> 0 | X9: =('FS Seychelles'!Z16+'FS Seychelles'!Z22)/30 -> 0
A10: Seychelles | B10: =B9+1 -> 9 | C10: =C9 -> 12 | D10: 2022 | E10: ='FS Seychelles'!B11 -> 0 | F10: ='FS Seychelles'!D11*1000 -> 0 | G10: ='FS Seychelles'!E11*1000 -> 0 | H10: ='FS Seychelles'!F11*1000 -> 0 | I10: ='FS Seychelles'!G11*1000 -> 0 | J10: ='FS Seychelles'!H11*1000 -> 0 | K10: ='FS Seychelles'!I11*1000 -> 0 | L10: ='FS Seychelles'!J11 -> 0 | M10: ='FS Seychelles'!K11 -> 0 | N10: ='FS Seychelles'!L11 -> 0 | O10: ='FS Seychelles'!M11 -> 0 | P10: ='FS Seychelles'!N11 -> 0 | Q10: ='FS Seychelles'!O11 -> 0 | R10: ='FS Seychelles'!Q11 -> 0 | S10: ='FS Seychelles'!S11 -> 0 | T10: ='FS Seychelles'!T11 -> 0 | U10: ='FS Seychelles'!U11 -> 0 | V10: ='FS Seychelles'!V11 -> 0 | W10: ='FS Seychelles'!W11 -> 0 | X10: =('FS Seychelles'!Z17+'FS Seychelles'!Z23)/30 -> 0
A11: Seychelles | B11: =B10+1 -> 10 | C11: =C10 -> 12 | D11: 2022 | E11: ='FS Seychelles'!B12 -> 0 | F11: ='FS Seychelles'!D12*1000 -> 0 | G11: ='FS Seychelles'!E12*1000 -> 0 | H11: ='FS Seychelles'!F12*1000 -> 0 | I11: ='FS Seychelles'!G12*1000 -> 0 | J11: ='FS Seychelles'!H12*1000 -> 0 | K11: ='FS Seychelles'!I12*1000 -> 0 | L11: ='FS Seychelles'!J12 -> 0 | M11: ='FS Seychelles'!K12 -> 0 | N11: ='FS Seychelles'!L12 -> 0 | O11: ='FS Seychelles'!M12 -> 0 | P11: ='FS Seychelles'!N12 -> 0 | Q11: ='FS Seychelles'!O12 -> 0 | R11: ='FS Seychelles'!Q12 -> 0 | S11: ='FS Seychelles'!S12 -> 0 | T11: ='FS Seychelles'!T12 -> 0 | U11: ='FS Seychelles'!U12 -> 0 | V11: ='FS Seychelles'!V12 -> 0 | W11: ='FS Seychelles'!W12 -> 0 | X11: =('FS Seychelles'!Z18+'FS Seychelles'!Z24)/30 -> 0
A12: Seychelles | B12: =B11+1 -> 11 | C12: =C11 -> 12 | D12: 2022 | E12: ='FS Seychelles'!B13 -> 0 | F12: ='FS Seychelles'!D13*1000 -> 0 | G12: ='FS Seychelles'!E13*1000 -> 0 | H12: ='FS Seychelles'!F13*1000 -> 0 | I12: ='FS Seychelles'!G13*1000 -> 0 | J12: ='FS Seychelles'!H13*1000 -> 0 | K12: ='FS Seychelles'!I13*1000 -> 0 | L12: ='FS Seychelles'!J13 -> 0 | M12: ='FS Seychelles'!K13 -> 0 | N12: ='FS Seychelles'!L13 -> 0 | O12: ='FS Seychelles'!M13 -> 0 | P12: ='FS Seychelles'!N13 -> 0 | Q12: ='FS Seychelles'!O13 -> 0 | R12: ='FS Seychelles'!Q13 -> 0 | S12: ='FS Seychelles'!S13 -> 0 | T12: ='FS Seychelles'!T13 -> 0 | U12: ='FS Seychelles'!U13 -> 0 | V12: ='FS Seychelles'!V13 -> 0 | W12: ='FS Seychelles'!W13 -> 0 | X12: =('FS Seychelles'!Z19+'FS Seychelles'!Z25)/30 -> 0
A13: Seychelles | B13: =B12+1 -> 12 | C13: =C12 -> 12 | D13: 2022 | E13: ='FS Seychelles'!B14 -> 0 | F13: ='FS Seychelles'!D14*1000 -> 0 | G13: ='FS Seychelles'!E14*1000 -> 0 | H13: ='FS Seychelles'!F14*1000 -> 0 | I13: ='FS Seychelles'!G14*1000 -> 0 | J13: ='FS Seychelles'!H14*1000 -> 0 | K13: ='FS Seychelles'!I14*1000 -> 0 | L13: ='FS Seychelles'!J14 -> 0 | M13: ='FS Seychelles'!K14 -> 0 | N13: ='FS Seychelles'!L14 -> 0 | O13: ='FS Seychelles'!M14 -> 0 | P13: ='FS Seychelles'!N14 -> 0 | Q13: ='FS Seychelles'!O14 -> 0 | R13: ='FS Seychelles'!Q14 -> 0 | S13: ='FS Seychelles'!S14 -> 0 | T13: ='FS Seychelles'!T14 -> 0 | U13: ='FS Seychelles'!U14 -> 0 | V13: ='FS Seychelles'!V14 -> 0 | W13: ='FS Seychelles'!W14 -> 0 | X13: =('FS Seychelles'!Z20+'FS Seychelles'!Z26)/30 -> 0
A14: Seychelles | B14: =B13+1 -> 13 | C14: =C13 -> 12 | D14: 2022 | E14: ='FS Seychelles'!B15 -> 0 | F14: ='FS Seychelles'!D15*1000 -> 0 | G14: ='FS Seychelles'!E15*1000 -> 0 | H14: ='FS Seychelles'!F15*1000 -> 0 | I14: ='FS Seychelles'!G15*1000 -> 0 | J14: ='FS Seychelles'!H15*1000 -> 0 | K14: ='FS Seychelles'!I15*1000 -> 0 | L14: ='FS Seychelles'!J15 -> 0 | M14: ='FS Seychelles'!K15 -> 0 | N14: ='FS Seychelles'!L15 -> 0 | O14: ='FS Seychelles'!M15 -> 0 | P14: ='FS Seychelles'!N15 -> 0 | Q14: ='FS Seychelles'!O15 -> 0 | R14: ='FS Seychelles'!Q15 -> 0 | S14: ='FS Seychelles'!S15 -> 0 | T14: ='FS Seychelles'!T15 -> 0 | U14: ='FS Seychelles'!U15 -> 0 | V14: ='FS Seychelles'!V15 -> 0 | W14: ='FS Seychelles'!W15 -> 0 | X14: =('FS Seychelles'!Z21+'FS Seychelles'!Z27)/30 -> 0
... A20: Seychelles | B20: =B19+1 -> 19 | C20: =C19 -> 12 | D20: 2022 | E20: ='FS Seychelles'!B21 -> 0 | F20: ='FS Seychelles'!D21*1000 -> 0 | G20: ='FS Seychelles'!E21*1000 -> 0 | H20: ='FS Seychelles'!F21*1000 -> 0 | I20: ='FS Seychelles'!G21*1000 -> 0 | J20: ='FS Seychelles'!H21*1000 -> 0 | K20: ='FS Seychelles'!I21*1000 -> 0 | L20: ='FS Seychelles'!J21 -> 0 | M20: ='FS Seychelles'!K21 -> 0 | N20: ='FS Seychelles'!L21 -> 0 | O20: ='FS Seychelles'!M21 -> 0 | P20: ='FS Seychelles'!N21 -> 0 | Q20: ='FS Seychelles'!O21 -> 0 | R20: ='FS Seychelles'!Q21 -> 0 | S20: ='FS Seychelles'!S21 -> 0 | T20: ='FS Seychelles'!T21 -> 0 | U20: ='FS Seychelles'!U21 -> 0 | V20: ='FS Seychelles'!V21 -> 0 | W20: ='FS Seychelles'!W21 -> 0 | X20: =('FS Seychelles'!Z27+'FS Seychelles'!Z33)/30 -> 0
A21: Seychelles | B21: =B20+1 -> 20 | C21: =C20 -> 12 | D21: 2022 | E21: ='FS Seychelles'!B22 -> 0 | F21: ='FS Seychelles'!D22*1000 -> 0 | G21: ='FS Seychelles'!E22*1000 -> 0 | H21: ='FS Seychelles'!F22*1000 -> 0 | I21: ='FS Seychelles'!G22*1000 -> 0 | J21: ='FS Seychelles'!H22*1000 -> 0 | K21: ='FS Seychelles'!I22*1000 -> 0 | L21: ='FS Seychelles'!J22 -> 0 | M21: ='FS Seychelles'!K22 -> 0 | N21: ='FS Seychelles'!L22 -> 0 | O21: ='FS Seychelles'!M22 -> 0 | P21: ='FS Seychelles'!N23 -> 0 | Q21: ='FS Seychelles'!O22 -> 0 | R21: ='FS Seychelles'!Q22 -> 0 | S21: ='FS Seychelles'!S22 -> 0 | T21: ='FS Seychelles'!T22 -> 0 | U21: ='FS Seychelles'!U22 -> 0 | V21: ='FS Seychelles'!V22 -> 0 | W21: ='FS Seychelles'!W22 -> 0 | X21: =('FS Seychelles'!Z28+'FS Seychelles'!Z34)/30 -> 0
A22: Seychelles | B22: =B21+1 -> 21 | C22: =C21 -> 12 | D22: 2022 | E22: ='FS Seychelles'!B23 -> 0 | F22: ='FS Seychelles'!D23*1000 -> 0 | G22: ='FS Seychelles'!E23*1000 -> 0 | H22: ='FS Seychelles'!F23*1000 -> 0 | I22: ='FS Seychelles'!G23*1000 -> 0 | J22: ='FS Seychelles'!H23*1000 -> 0 | K22: ='FS Seychelles'!I23*1000 -> 0 | L22: ='FS Seychelles'!J23 -> 0 | M22: ='FS Seychelles'!K23 -> 0 | N22: ='FS Seychelles'!L23 -> 0 | O22: ='FS Seychelles'!M23 -> 0 | P22: ='FS Seychelles'!N24 -> 0 | Q22: ='FS Seychelles'!O23 -> 0 | R22: ='FS Seychelles'!Q23 -> 0 | S22: ='FS Seychelles'!S23 -> 0 | T22: ='FS Seychelles'!T23 -> 0 | U22: ='FS Seychelles'!U23 -> 0 | V22: ='FS Seychelles'!V23 -> 0 | W22: ='FS Seychelles'!W23 -> 0 | X22: =('FS Seychelles'!Z29+'FS Seychelles'!Z35)/30 -> 0
A23: Seychelles | B23: =B22+1 -> 22 | C23: =C22 -> 12 | D23: 2022 | E23: ='FS Seychelles'!B24 -> 0 | F23: ='FS Seychelles'!D24*1000 -> 0 | G23: ='FS Seychelles'!E24*1000 -> 0 | H23: ='FS Seychelles'!F24*1000 -> 0 | I23: ='FS Seychelles'!G24*1000 -> 0 | J23: ='FS Seychelles'!H24*1000 -> 0 | K23: ='FS Seychelles'!I24*1000 -> 0 | L23: ='FS Seychelles'!J24 -> 0 | M23: ='FS Seychelles'!K24 -> 0 | N23: ='FS Seychelles'!L24 -> 0 | O23: ='FS Seychelles'!M24 -> 0 | P23: ='FS Seychelles'!N25 -> 0 | Q23: ='FS Seychelles'!O24 -> 0 | R23: ='FS Seychelles'!Q24 -> 0 | S23: ='FS Seychelles'!S24 -> 0 | T23: ='FS Seychelles'!T24 -> 0 | U23: ='FS Seychelles'!U24 -> 0 | V23: ='FS Seychelles'!V24 -> 0 | W23: ='FS Seychelles'!W24 -> 0 | X23: =('FS Seychelles'!Z30+'FS Seychelles'!Z36)/30 -> 0
A24: Seychelles | B24: =B23+1 -> 23 | C24: =C23 -> 12 | D24: 2022 | E24: ='FS Seychelles'!B25 -> 0 | F24: ='FS Seychelles'!D25*1000 -> 0 | G24: ='FS Seychelles'!E25*1000 -> 0 | H24: ='FS Seychelles'!F25*1000 -> 0 | I24: ='FS Seychelles'!G25*1000 -> 0 | J24: ='FS Seychelles'!H25*1000 -> 0 | K24: ='FS Seychelles'!I25*1000 -> 0 | L24: ='FS Seychelles'!J25 -> 0 | M24: ='FS Seychelles'!K25 -> 0 | N24: ='FS Seychelles'!L25 -> 0 | O24: ='FS Seychelles'!M25 -> 0 | P24: ='FS Seychelles'!N25 -> 0 | Q24: ='FS Seychelles'!O25 -> 0 | R24: ='FS Seychelles'!Q25 -> 0 | S24: ='FS Seychelles'!S25 -> 0 | T24: ='FS Seychelles'!T25 -> 0 | U24: ='FS Seychelles'!U25 -> 0 | V24: ='FS Seychelles'!V25 -> 0 | W24: ='FS Seychelles'!W25 -> 0 | X24: =('FS Seychelles'!Z31+'FS Seychelles'!Z37)/30 -> 0
A25: Seychelles | B25: =B24+1 -> 24 | C25: =C24 -> 12 | D25: 2022 | E25: ='FS Seychelles'!B26 -> 0 | F25: ='FS Seychelles'!D26*1000 -> 0 | G25: ='FS Seychelles'!E26*1000 -> 0 | H25: ='FS Seychelles'!F26*1000 -> 0 | I25: ='FS Seychelles'!G26*1000 -> 0 | J25: ='FS Seychelles'!H26*1000 -> 0 | K25: ='FS Seychelles'!I26*1000 -> 0 | L25: ='FS Seychelles'!J26 -> 0 | M25: ='FS Seychelles'!K26 -> 0 | N25: ='FS Seychelles'!L26 -> 0 | O25: ='FS Seychelles'!M26 -> 0 | P25: ='FS Seychelles'!N26 -> 0 | Q25: ='FS Seychelles'!O26 -> 0 | R25: ='FS Seychelles'!Q26 -> 0 | S25: ='FS Seychelles'!S26 -> 0 | T25: ='FS Seychelles'!T26 -> 0 | U25: ='FS Seychelles'!U26 -> 0 | V25: ='FS Seychelles'!V26 -> 0 | W25: ='FS Seychelles'!W26 -> 0 | X25: =('FS Seychelles'!Z32+'FS Seychelles'!Z38)/30 -> 0
A26: Seychelles | B26: =B25+1 -> 25 | C26: =C25 -> 12 | D26: 2022 | E26: ='FS Seychelles'!B27 -> 0 | F26: ='FS Seychelles'!D27*1000 -> 0 | G26: ='FS Seychelles'!E27*1000 -> 0 | H26: ='FS Seychelles'!F27*1000 -> 0 | I26: ='FS Seychelles'!G27*1000 -> 0 | J26: ='FS Seychelles'!H27*1000 -> 0 | K26: ='FS Seychelles'!I27*1000 -> 0 | L26: ='FS Seychelles'!J27 -> 0 | M26: ='FS Seychelles'!K27 -> 0 | N26: ='FS Seychelles'!L27 -> 0 | O26: ='FS Seychelles'!M27 -> 0 | P26: ='FS Seychelles'!N27 -> 0 | Q26: ='FS Seychelles'!O27 -> 0 | R26: ='FS Seychelles'!Q27 -> 0 | S26: ='FS Seychelles'!S27 -> 0 | T26: ='FS Seychelles'!T27 -> 0 | U26: ='FS Seychelles'!U27 -> 0 | V26: ='FS Seychelles'!V27 -> 0 | W26: ='FS Seychelles'!W27 -> 0 | X26: =('FS Seychelles'!Z33+'FS Seychelles'!Z39)/30 -> 0
A27: Seychelles | B27: =B26+1 -> 26 | C27: =C26 -> 12 | D27: 2022 | E27: ='FS Seychelles'!B28 -> 0 | F27: ='FS Seychelles'!D28*1000 -> 0 | G27: ='FS Seychelles'!E28*1000 -> 0 | H27: ='FS Seychelles'!F28*1000 -> 0 | I27: ='FS Seychelles'!G28*1000 -> 0 | J27: ='FS Seychelles'!H28*1000 -> 0 | K27: ='FS Seychelles'!I28*1000 -> 0 | L27: ='FS Seychelles'!J28 -> 0 | M27: ='FS Seychelles'!K28 -> 0 | N27: ='FS Seychelles'!L28 -> 0 | O27: ='FS Seychelles'!M28 -> 0 | P27: ='FS Seychelles'!N28 -> 0 | Q27: ='FS Seychelles'!O28 -> 0 | R27: ='FS Seychelles'!Q28 -> 0 | S27: ='FS Seychelles'!S28 -> 0 | T27: ='FS Seychelles'!T28 -> 0 | U27: ='FS Seychelles'!U28 -> 0 | V27: ='FS Seychelles'!V28 -> 0 | W27: ='FS Seychelles'!W28 -> 0 | X27: =('FS Seychelles'!Z34+'FS Seychelles'!Z40)/30 -> 0
A28: Seychelles | B28: =B27+1 -> 27 | C28: =C27 -> 12 | D28: 2022 | E28: ='FS Seychelles'!B29 -> 0 | F28: ='FS Seychelles'!D29*1000 -> 0 | G28: ='FS Seychelles'!E29*1000 -> 0 | H28: ='FS Seychelles'!F29*1000 -> 0 | I28: ='FS Seychelles'!G29*1000 -> 0 | J28: ='FS Seychelles'!H29*1000 -> 0 | K28: ='FS Seychelles'!I29*1000 -> 0 | L28: ='FS Seychelles'!J29 -> 0 | M28: ='FS Seychelles'!K29 -> 0 | N28: ='FS Seychelles'!L29 -> 0 | O28: ='FS Seychelles'!M29 -> 0 | P28: ='FS Seychelles'!N29 -> 0 | Q28: ='FS Seychelles'!O29 -> 0 | R28: ='FS Seychelles'!Q29 -> 0 | S28: ='FS Seychelles'!S29 -> 0 | T28: ='FS Seychelles'!T29 -> 0 | U28: ='FS Seychelles'!U29 -> 0 | V28: ='FS Seychelles'!V29 -> 0 | W28: ='FS Seychelles'!W29 -> 0 | X28: =('FS Seychelles'!Z35+'FS Seychelles'!Z41)/30 -> 0
A29: Seychelles | B29: =B28+1 -> 28 | C29: =C28 -> 12 | D29: 2022 | E29: ='FS Seychelles'!B30 -> 0 | F29: ='FS Seychelles'!D30*1000 -> 0 | G29: ='FS Seychelles'!E30*1000 -> 0 | H29: ='FS Seychelles'!F30*1000 -> 0 | I29: ='FS Seychelles'!G30*1000 -> 0 | J29: ='FS Seychelles'!H30*1000 -> 0 | K29: ='FS Seychelles'!I30*1000 -> 0 | L29: ='FS Seychelles'!J30 -> 0 | M29: ='FS Seychelles'!K30 -> 0 | N29: ='FS Seychelles'!L30 -> 0 | O29: ='FS Seychelles'!M30 -> 0 | P29: ='FS Seychelles'!N30 -> 0 | Q29: ='FS Seychelles'!O30 -> 0 | R29: ='FS Seychelles'!Q30 -> 0 | S29: ='FS Seychelles'!S30 -> 0 | T29: ='FS Seychelles'!T30 -> 0 | U29: ='FS Seychelles'!U30 -> 0 | V29: ='FS Seychelles'!V30 -> 0 | W29: ='FS Seychelles'!W30 -> 0 | X29: =('FS Seychelles'!Z36+'FS Seychelles'!Z42)/30 -> 0
A30: Seychelles | B30: =B29+1 -> 29 | C30: =C29 -> 12 | D30: 2022 | E30: ='FS Seychelles'!B31 -> 0 | F30: ='FS Seychelles'!D31*1000 -> 0 | G30: ='FS Seychelles'!E31*1000 -> 0 | H30: ='FS Seychelles'!F31*1000 -> 0 | I30: ='FS Seychelles'!G31*1000 -> 0 | J30: ='FS Seychelles'!H31*1000 -> 0 | K30: ='FS Seychelles'!I31*1000 -> 0 | L30: ='FS Seychelles'!J31 -> 0 | M30: ='FS Seychelles'!K31 -> 0 | N30: ='FS Seychelles'!L31 -> 0 | O30: ='FS Seychelles'!M31 -> 0 | P30: ='FS Seychelles'!N31 -> 0 | Q30: ='FS Seychelles'!O31 -> 0 | R30: ='FS Seychelles'!Q31 -> 0 | S30: ='FS Seychelles'!S31 -> 0 | T30: ='FS Seychelles'!T31 -> 0 | U30: ='FS Seychelles'!U31 -> 0 | V30: ='FS Seychelles'!V31 -> 0 | W30: ='FS Seychelles'!W31 -> 0 | X30: =('FS Seychelles'!Z37+'FS Seychelles'!Z43)/30 -> 0
A31: Seychelles | B31: =B30+1 -> 30 | C31: =C30 -> 12 | D31: 2022 | E31: ='FS Seychelles'!B32 -> 0 | F31: ='FS Seychelles'!D32*1000 -> 0 | G31: ='FS Seychelles'!E32*1000 -> 0 | H31: ='FS Seychelles'!F32*1000 -> 0 | I31: ='FS Seychelles'!G32*1000 -> 0 | J31: ='FS Seychelles'!H32*1000 -> 0 | K31: ='FS Seychelles'!I32*1000 -> 0 | L31: ='FS Seychelles'!J32 -> 0 | M31: ='FS Seychelles'!K32 -> 0 | N31: ='FS Seychelles'!L32 -> 0 | O31: ='FS Seychelles'!M32 -> 0 | P31: ='FS Seychelles'!N32 -> 0 | Q31: ='FS Seychelles'!O32 -> 0 | R31: ='FS Seychelles'!Q32 -> 0 | S31: ='FS Seychelles'!S32 -> 0 | T31: ='FS Seychelles'!T32 -> 0 | U31: ='FS Seychelles'!U32 -> 0 | V31: ='FS Seychelles'!V32 -> 0 | W31: ='FS Seychelles'!W32 -> 0 | X31: =('FS Seychelles'!Z38+'FS Seychelles'!Z44)/30 -> 0
A32: Seychelles | B32: 31 | C32: 12 | D32: 2022 | E32: 0 | F32: 0 | G32: 0 | H32: 0 | I32: 0 | J32: 0 | K32: 0 | L32: 0 | M32: 0 | N32: 0 | O32: 0 | P32: 0 | Q32: 0 | R32: 0 | S32: 0 | T32: 0 | U32: 0 | V32: 0 | W32: 0 | X32: 0

Sheet FS Seychelles
A2: DATE | B2: Room Night % | C2: Food Covers (Customers) | D2: SS-A (MWH) | E2: SS-B (MWH) | F2: SS-C (MWH) | G2: FIRE PUMP (MWH) | H2: CASINO (MWH) | I2: BOH (MWH) | J2: Generator#1 (KWH) | K2: Generator#2 (KWH) | L2: Generator#3 (KWH) | M2: Generator#4 (KWH) | N2: Generator#5 (KWH) | O2: DIESEL (Liter) | P2: DIESEL TARIFF (Euro/Liter) | Q2: PUC (KWh) | R2: PUC Tariff (Euro/KWh) | S2: BOH Water (m3) | T2: WT59 (m3) | U2: WT08 (m3) | V2: PUC HOH (m3) | W2: Fire Tank (m3) | X2: LPG (Kg) | AA2: STP Irrigation Water (m3) | AB2: Fire tank 250 (m3) | AC2: Comment
A3: 44896 | B3: 55.8 | C3: 345 | D3: ='EMS Gridvis'!B2 -> 3.07 | E3: ='EMS Gridvis'!C2 -> 4.4 | F3: ='EMS Gridvis'!D2 -> 5.88 | G3: ='EMS Gridvis'!H2 -> 1.53 | H3: ='EMS Gridvis'!I2 -> 1.88 | I3: ='EMS Gridvis'!J2 -> 4.01 | J3: =Generator!D4 -> 12787 | K3: =Generator!H4 -> 10907 | L3: =Generator!L4 -> 5248 | M3: =Generator!P4 -> 0 | N3: =Generator!T4 -> 7520 | P3: =23.84/13.49 -> 1.767235 | R3: 1.84 | S3: ='RO Plant'!B4 -> 60 | T3: ='RO Plant'!E4 -> 152 | U3: ='RO Plant'!F4 -> 71 | V3: ='RO Plant'!I4 -> 100 | W3: ='RO Plant'!G4 -> 0 | X3: CYLINDER DELIVERY (KG) | AA3: =AB3-AC3 -> 103 | AB3: 54476 | AC3: 54373 | AD3: 44895
A4: 44897 | B4: 59.7 | C4: 402 | D4: ='EMS Gridvis'!B3 -> 2.48 | E4: ='EMS Gridvis'!C3 -> 3.87 | F4: ='EMS Gridvis'!D3 -> 5.37 | G4: ='EMS Gridvis'!H3 -> 1.45 | H4: ='EMS Gridvis'!I3 -> 1.71 | I4: ='EMS Gridvis'!J3 -> 3.82 | J4: =Generator!D5 -> 5363 | K4: =Generator!H5 -> 10782 | L4: =Generator!L5 -> 5378 | M4: =Generator!P5 -> 0 | N4: =Generator!T5 -> 10802 | P4: =23.94/13.49 -> 1.7746479 | R4: 1.84 | S4: ='RO Plant'!B5 -> 58 | T4: ='RO Plant'!E5 -> 97 | U4: ='RO Plant'!F5 -> 75 | V4: ='RO Plant'!I5 -> 100 | W4: ='RO Plant'!G5 -> 0 | X4: Unit (kg) | Y4: Quantity | Z4: Sub total | AA4: =AB4-AB3 -> 136 | AB4: 54612
A5: 44898 | B5: 57.1 | C5: 402 | D5: ='EMS Gridvis'!B4 -> 2.94 | E5: ='EMS Gridvis'!C4 -> 4.32 | F5: ='EMS Gridvis'!D4 -> 5.75 | G5: ='EMS Gridvis'!H4 -> 1.44 | H5: ='EMS Gridvis'!I4 -> 1.77 | I5: ='EMS Gridvis'!J4 -> 3.84 | J5: =Generator!D6 -> 8388 | K5: =Generator!H6 -> 6931 | L5: =Generator!L6 -> 11861 | M5: =Generator!P6 -> 0 | N5: =Generator!T6 -> 5766 | P5: =23.94/13.49 -> 1.7746479 | R5: 1.84 | S5: ='RO Plant'!B6 -> 57 | T5: ='RO Plant'!E6 -> 67 | U5: ='RO Plant'!F6 -> 87 | V5: ='RO Plant'!I6 -> 102 | W5: ='RO Plant'!G6 -> 0 | X5: 9 | Y5: 0 | Z5: =X5*Y5 -> 0 | AA5: =AB5-AB4 -> 109 | AB5: 54721
A6: 44899 | B6: 40.3 | C6: 315 | D6: ='EMS Gridvis'!B5 -> 3.08 | E6: ='EMS Gridvis'!C5 -> 4.45 | F6: ='EMS Gridvis'!D5 -> 5.48 | G6: ='EMS Gridvis'!H5 -> 1.23 | H6: ='EMS Gridvis'!I5 -> 1.69 | I6: ='EMS Gridvis'!J5 -> 3.63 | J6: =Generator!D7 -> 10905 | K6: =Generator!H7 -> 8754 | L6: =Generator!L7 -> 7905 | M6: =Generator!P7 -> 0 | N6: =Generator!T7 -> 8073 | P6: =23.94/13.49 -> 1.7746479 | R6: 1.84 | S6: ='RO Plant'!B7 -> 71 | T6: ='RO Plant'!E7 -> 145 | U6: ='RO Plant'!F7 -> 63 | V6: ='RO Plant'!I7 -> 98 | W6: ='RO Plant'!G7 -> 0 | X6: 10 | Y6: 0 | Z6: =X6*Y6 -> 0 | AA6: =AB6-AB5 -> 97 | AB6: 54818
A7: 44900 | B7: 39 | C7: 206 | D7: ='EMS Gridvis'!B6 -> 3.24 | E7: ='EMS Gridvis'!C6 -> 4.32 | F7: ='EMS Gridvis'!D6 -> 5.48 | G7: ='EMS Gridvis'!H6 -> 1.14 | H7: ='EMS Gridvis'!I6 -> 1.74 | I7: ='EMS Gridvis'!J6 -> 3.77 | J7: =Generator!D8 -> 5104 | K7: =Generator!H8 -> 15185 | L7: =Generator!L8 -> 8249 | M7: =Generator!P8 -> 0 | N7: =Generator!T8 -> 4060 | P7: =23.94/13.49 -> 1.7746479 | R7: 1.84 | S7: ='RO Plant'!B8 -> 60 | T7: ='RO Plant'!E8 -> 155 | U7: ='RO Plant'!F8 -> 71 | V7: ='RO Plant'!I8 -> 101 | W7: ='RO Plant'!G8 -> 0 | X7: 12 | Y7: 0 | Z7: =X7*Y7 -> 0 | AA7: =AB7-AB6 -> 58 | AB7: 54876
A8: 44901 | D8: ='EMS Gridvis'!B7 -> 0 | E8: ='EMS Gridvis'!C7 -> 0 | F8: ='EMS Gridvis'!D7 -> 0 | G8: ='EMS Gridvis'!H7 -> 0 | H8: ='EMS Gridvis'!I7 -> 0 | I8: ='EMS Gridvis'!J7 -> 0 | J8: =Generator!D9 -> 0 | K8: =Generator!H9 -> 0 | L8: =Generator!L9 -> 0 | M8: =Generator!P9 -> 0 | N8: =Generator!T9 -> 0 | P8: =23.94/13.49 -> 1.7746479 | R8: 1.84 | S8: ='RO Plant'!B9 -> 0 | T8: ='RO Plant'!E9 -> 0 | U8: ='RO Plant'!F9 -> 0 | V8: ='RO Plant'!I9 -> 0 | W8: ='RO Plant'!G9 -> 0 | X8: 20 | Y8: 0 | Z8: =X8*Y8 -> 0 | AA8: =AB8-AB7 -> 56 | AB8: 54932
A9: 44902 | D9: ='EMS Gridvis'!B8 -> 0 | E9: ='EMS Gridvis'!C8 -> 0 | F9: ='EMS Gridvis'!D8 -> 0 | G9: ='EMS Gridvis'!H8 -> 0 | H9: ='EMS Gridvis'!I8 -> 0 | I9: ='EMS Gridvis'!J8 -> 0 | J9: =Generator!D10 -> 0 | K9: =Generator!H10 -> 0 | L9: =Generator!L10 -> 0 | M9: =Generator!P10 -> 0 | N9: =Generator!T10 -> 0 | P9: =23.94/13.49 -> 1.7746479 | R9: 1.84 | S9: ='RO Plant'!B10 -> 0 | T9: ='RO Plant'!E10 -> 0 | U9: ='RO Plant'!F10 -> 0 | V9: ='RO Plant'!I10 -> 0 | W9: ='RO Plant'!G10 -> 0 | X9: 24 | Y9: 0 | Z9: =X9*Y9 -> 0 | AA9: =AB9-AB8 -> -54932
A10: 44903 | D10: ='EMS Gridvis'!B9 -> 0 | E10: ='EMS Gridvis'!C9 -> 0 | F10: ='EMS Gridvis'!D9 -> 0 | G10: ='EMS Gridvis'!H9 -> 0 | H10: ='EMS Gridvis'!I9 -> 0 | I10: ='EMS Gridvis'!J9 -> 0 | J10: =Generator!D11 -> 0 | K10: =Generator!H11 -> 0 | L10: =Generator!L11 -> 0 | M10: =Generator!P11 -> 0 | N10: =Generator!T11 -> 0 | P10: =23.94/13.49 -> 1.7746479 | R10: 1.84 | S10: ='RO Plant'!B11 -> 0 | T10: ='RO Plant'!E11 -> 0 | U10: ='RO Plant'!F11 -> 0 | V10: ='RO Plant'!I11 -> 0 | W10: ='RO Plant'!G11 -> 0 | Y10: Total | Z10: =SUM(Z5:Z9) -> 0
A11: 44904 | D11: ='EMS Gridvis'!B10 -> 0 | E11: ='EMS Gridvis'!C10 -> 0 | F11: ='EMS Gridvis'!D10 -> 0 | G11: ='EMS Gridvis'!H10 -> 0 | H11: ='EMS Gridvis'!I10 -> 0 | I11: ='EMS Gridvis'!J10 -> 0 | J11: =Generator!D12 -> 0 | K11: =Generator!H12 -> 0 | L11: =Generator!L12 -> 0 | M11: =Generator!P12 -> 0 | N11: =Generator!T12 -> 0 | P11: =23.94/13.49 -> 1.7746479 | R11: 1.84 | S11: ='RO Plant'!B12 -> 0 | T11: ='RO Plant'!E12 -> 0 | U11: ='RO Plant'!F12 -> 0 | V11: ='RO Plant'!I12 -> 0 | W11: ='RO Plant'!G12 -> 0 | X11: TRUCK DELIVERY (KG) | AA11: =AB12+AB11 -> 0
A12: 44905 | D12: ='EMS Gridvis'!B11 -> 0 | E12: ='EMS Gridvis'!C11 -> 0 | F12: ='EMS Gridvis'!D11 -> 0 | G12: ='EMS Gridvis'!H11 -> 0 | H12: ='EMS Gridvis'!I11 -> 0 | I12: ='EMS Gridvis'!J11 -> 0 | J12: =Generator!D13 -> 0 | K12: =Generator!H13 -> 0 | L12: =Generator!L13 -> 0 | M12: =Generator!P13 -> 0 | N12: =Generator!T13 -> 0 | P12: =23.94/13.49 -> 1.7746479 | R12: 1.84 | S12: ='RO Plant'!B13 -> 0 | T12: ='RO Plant'!E13 -> 0 | U12: ='RO Plant'!F13 -> 0 | V12: ='RO Plant'!I13 -> 0 | W12: ='RO Plant'!G13 -> 0 | Y12: Sub Total | AA12: =AB12-AB11 -> 0
A13: 44906 | D13: ='EMS Gridvis'!B12 -> 0 | E13: ='EMS Gridvis'!C12 -> 0 | F13: ='EMS Gridvis'!D12 -> 0 | G13: ='EMS Gridvis'!H12 -> 0 | H13: ='EMS Gridvis'!I12 -> 0 | I13: ='EMS Gridvis'!J12 -> 0 | J13: =Generator!D14 -> 0 | K13: =Generator!H14 -> 0 | L13: =Generator!L14 -> 0 | M13: =Generator!P14 -> 0 | N13: =Generator!T14 -> 0 | P13: =23.94/13.49 -> 1.7746479 | R13: 1.84 | S13: ='RO Plant'!B14 -> 0 | T13: ='RO Plant'!E14 -> 0 | U13: ='RO Plant'!F14 -> 0 | V13: ='RO Plant'!I14 -> 0 | W13: ='RO Plant'!G14 -> 0 | X13: Sitronel | Y13: 0 | AA13: =AB13-AB12 -> 0
A14: 44907 | D14: ='EMS Gridvis'!B13 -> 0 | E14: ='EMS Gridvis'!C13 -> 0 | F14: ='EMS Gridvis'!D13 -> 0 | G14: ='EMS Gridvis'!H13 -> 0 | H14: ='EMS Gridvis'!I13 -> 0 | I14: ='EMS Gridvis'!J13 -> 0 | J14: =Generator!D15 -> 0 | K14: =Generator!H15 -> 0 | L14: =Generator!L15 -> 0 | M14: =Generator!P15 -> 0 | N14: =Generator!T15 -> 0 | P14: =23.94/13.49 -> 1.7746479 | R14: 1.84 | S14: ='RO Plant'!B15 -> 0 | T14: ='RO Plant'!E15 -> 0 | U14: ='RO Plant'!F15 -> 0 | V14: ='RO Plant'!I15 -> 0 | W14: ='RO Plant'!G15 -> 0 | X14: Zez | Y14: 0 | AA14: =AB14-AB13 -> 0
A15: 44908 | D15: ='EMS Gridvis'!B14 -> 0 | E15: ='EMS Gridvis'!C14 -> 0 | F15: ='EMS Gridvis'!D14 -> 0 | G15: ='EMS Gridvis'!H14 -> 0 | H15: ='EMS Gridvis'!I14 -> 0 | I15: ='EMS Gridvis'!J14 -> 0 | J15: =Generator!D16 -> 0 | K15: =Generator!H16 -> 0 | L15: =Generator!L16 -> 0 | M15: =Generator!P16 -> 0 | N15: =Generator!T16 -> 0 | P15: =23.94/13.49 -> 1.7746479 | R15: 1.84 | S15: ='RO Plant'!B16 -> 0 | T15: ='RO Plant'!E16 -> 0 | U15: ='RO Plant'!F16 -> 0 | V15: ='RO Plant'!I16 -> 0 | W15: ='RO Plant'!G16 -> 0 | Y15: Total | Z15: =SUM(Y13:Z14) -> 0 | AA15: =AB15-AB14 -> 0
A16: 44909 | D16: ='EMS Gridvis'!B15 -> 0 | E16: ='EMS Gridvis'!C15 -> 0 | F16: ='EMS Gridvis'!D15 -> 0 | G16: ='EMS Gridvis'!H15 -> 0 | H16: ='EMS Gridvis'!I15 -> 0 | I16: ='EMS Gridvis'!J15 -> 0 | J16: =Generator!D17 -> 0 | K16: =Generator!H17 -> 0 | L16: =Generator!L17 -> 0 | M16: =Generator!P17 -> 0 | N16: =Generator!T17 -> 0 | P16: =23.94/13.49 -> 1.7746479 | R16: 1.84 | S16: ='RO Plant'!B17 -> 0 | T16: ='RO Plant'!E17 -> 0 | U16: ='RO Plant'!F17 -> 0 | V16: ='RO Plant'!I17 -> 0 | W16: ='RO Plant'!G17 -> 0 | AA16: =AB16-AB15 -> 0
A17: 44910 | D17: ='EMS Gridvis'!B16 -> 0 | E17: ='EMS Gridvis'!C16 -> 0 | F17: ='EMS Gridvis'!D16 -> 0 | G17: ='EMS Gridvis'!H16 -> 0 | H17: ='EMS Gridvis'!I16 -> 0 | I17: ='EMS Gridvis'!J16 -> 0 | J17: =Generator!D18 -> 0 | K17: =Generator!H18 -> 0 | L17: =Generator!L18 -> 0 | M17: =Generator!P18 -> 0 | N17: =Generator!T18 -> 0 | P17: =23.94/13.49 -> 1.7746479 | R17: 1.84 | S17: ='RO Plant'!B18 -> 0 | T17: ='RO Plant'!E18 -> 0 | U17: ='RO Plant'!F18 -> 0 | V17: ='RO Plant'!I18 -> 0 | W17: ='RO Plant'!G18 -> 0 | AA17: =AB17-AB16 -> 0
A18: 44911 | D18: ='EMS Gridvis'!B17 -> 0 | E18: ='EMS Gridvis'!C17 -> 0 | F18: ='EMS Gridvis'!D17 -> 0 | G18: ='EMS Gridvis'!H17 -> 0 | H18: ='EMS Gridvis'!I17 -> 0 | I18: ='EMS Gridvis'!J17 -> 0 | J18: =Generator!D19 -> 0 | K18: =Generator!H19 -> 0 | L18: =Generator!L19 -> 0 | M18: =Generator!P19 -> 0 | N18: =Generator!T19 -> 0 | P18: =23.94/13.49 -> 1.7746479 | R18: 1.84 | S18: ='RO Plant'!B19 -> 0 | T18: ='RO Plant'!E19 -> 0 | U18: ='RO Plant'!F19 -> 0 | V18: ='RO Plant'!I19 -> 0 | W18: ='RO Plant'!G19 -> 0 | AA18: =AB18-AB17 -> 0
A19: 44912 | D19: ='EMS Gridvis'!B18 -> 0 | E19: ='EMS Gridvis'!C18 -> 0 | F19: ='EMS Gridvis'!D18 -> 0 | G19: ='EMS Gridvis'!H18 -> 0 | H19: ='EMS Gridvis'!I18 -> 0 | I19: ='EMS Gridvis'!J18 -> 0 | J19: =Generator!D20 -> 0 | K19: =Generator!H20 -> 0 | L19: =Generator!L20 -> 0 | M19: =Generator!P20 -> 0 | N19: =Generator!T20 -> 0 | P19: =23.94/13.49 -> 1.7746479 | R19: 1.84 | S19: ='RO Plant'!B20 -> 0 | T19: ='RO Plant'!E20 -> 0 | U19: ='RO Plant'!F20 -> 0 | V19: ='RO Plant'!I20 -> 0 | W19: ='RO Plant'!G20 -> 0 | AA19: =AB19-AB18 -> 0
A20: 44913 | D20: ='EMS Gridvis'!B19 -> 0 | E20: ='EMS Gridvis'!C19 -> 0 | F20: ='EMS Gridvis'!D19 -> 0 | G20: ='EMS Gridvis'!H19 -> 0 | H20: ='EMS Gridvis'!I19 -> 0 | I20: ='EMS Gridvis'!J19 -> 0 | J20: =Generator!D21 -> 0 | K20: =Generator!H21 -> 0 | L20: =Generator!L21 -> 0 | M20: =Generator!P21 -> 0 | N20: =Generator!T21 -> 0 | P20: =23.94/13.49 -> 1.7746479 | R20: 1.84 | S20: ='RO Plant'!B21 -> 0 | T20: ='RO Plant'!E21 -> 0 | U20: ='RO Plant'!F21 -> 0 | V20: ='RO Plant'!I21 -> 0 | W20: ='RO Plant'!G21 -> 0 | AA20: =AB20-AB19 -> 0
A21: 44914 | D21: ='EMS Gridvis'!B20 -> 0 | E21: ='EMS Gridvis'!C20 -> 0 | F21: ='EMS Gridvis'!D20 -> 0 | G21: ='EMS Gridvis'!H20 -> 0 | H21: ='EMS Gridvis'!I20 -> 0 | I21: ='EMS Gridvis'!J20 -> 0 | J21: =Generator!D22 -> 0 | K21: =Generator!H22 -> 0 | L21: =Generator!L22 -> 0 | M21: =Generator!P22 -> 0 | N21: =Generator!T22 -> 0 | P21: =23.94/13.49 -> 1.7746479 | R21: 1.84 | S21: ='RO Plant'!B22 -> 0 | T21: ='RO Plant'!E22 -> 0 | U21: ='RO Plant'!F22 -> 0 | V21: ='RO Plant'!I22 -> 0 | W21: ='RO Plant'!G22 -> 0 | AA21: =AB21-AB20 -> 0
A22: 44915 | D22: ='EMS Gridvis'!B21 -> 0 | E22: ='EMS Gridvis'!C21 -> 0 | F22: ='EMS Gridvis'!D21 -> 0 | G22: ='EMS Gridvis'!H21 -> 0 | H22: ='EMS Gridvis'!I21 -> 0 | I22: ='EMS Gridvis'!J21 -> 0 | J22: =Generator!D23 -> 0 | K22: =Generator!H23 -> 0 | L22: =Generator!L23 -> 0 | M22: =Generator!P23 -> 0 | N22: =Generator!T23 -> 0 | P22: =23.94/13.49 -> 1.7746479 | R22: 1.84 | S22: ='RO Plant'!B23 -> 0 | T22: ='RO Plant'!E23 -> 0 | U22: ='RO Plant'!F23 -> 0 | V22: ='RO Plant'!I23 -> 0 | W22: ='RO Plant'!G23 -> 0 | AA22: =AB22-AB21 -> 0
A23: 44916 | D23: ='EMS Gridvis'!B22 -> 0 | E23: ='EMS Gridvis'!C22 -> 0 | F23: ='EMS Gridvis'!D22 -> 0 | G23: ='EMS Gridvis'!H22 -> 0 | H23: ='EMS Gridvis'!I22 -> 0 | I23: ='EMS Gridvis'!J22 -> 0 | J23: =Generator!D24 -> 0 | K23: =Generator!H24 -> 0 | L23: =Generator!L24 -> 0 | M23: =Generator!P24 -> 0 | N23: =Generator!T24 -> 0 | P23: =23.94/13.49 -> 1.7746479 | R23: 1.84 | S23: ='RO Plant'!B24 -> 0 | T23: ='RO Plant'!E24 -> 0 | U23: ='RO Plant'!F24 -> 0 | V23: ='RO Plant'!I24 -> 0 | W23: ='RO Plant'!G24 -> 0 | AA23: =AB23-AB22 -> 0
A24: 44917 | D24: ='EMS Gridvis'!B23 -> 0 | E24: ='EMS Gridvis'!C23 -> 0 | F24: ='EMS Gridvis'!D23 -> 0 | G24: ='EMS Gridvis'!H23 -> 0 | H24: ='EMS Gridvis'!I23 -> 0 | I24: ='EMS Gridvis'!J23 -> 0 | J24: =Generator!D25 -> 0 | K24: =Generator!H25 -> 0 | L24: =Generator!L25 -> 0 | M24: =Generator!P25 -> 0 | N24: =Generator!T25 -> 0 | P24: =23.94/13.49 -> 1.7746479 | R24: 1.84 | S24: ='RO Plant'!B25 -> 0 | T24: ='RO Plant'!E25 -> 0 | U24: ='RO Plant'!F25 -> 0 | V24: ='RO Plant'!I25 -> 0 | W24: ='RO Plant'!G25 -> 0 | AA24: =AB24-AB23 -> 0
A25: 44918 | D25: ='EMS Gridvis'!B24 -> 0 | E25: ='EMS Gridvis'!C24 -> 0 | F25: ='EMS Gridvis'!D24 -> 0 | G25: ='EMS Gridvis'!H24 -> 0 | H25: ='EMS Gridvis'!I24 -> 0 | I25: ='EMS Gridvis'!J24 -> 0 | J25: =Generator!D26 -> 0 | K25: =Generator!H26 -> 0 | L25: =Generator!L26 -> 0 | M25: =Generator!P26 -> 0 | N25: =Generator!T26 -> 0 | P25: =23.94/13.49 -> 1.7746479 | R25: 1.84 | S25: ='RO Plant'!B26 -> 0 | T25: ='RO Plant'!E26 -> 0 | U25: ='RO Plant'!F26 -> 0 | V25: ='RO Plant'!I26 -> 0 | W25: ='RO Plant'!G26 -> 0 | AA25: =AB25-AB24 -> 0
A26: 44919 | D26: ='EMS Gridvis'!B25 -> 0 | E26: ='EMS Gridvis'!C25 -> 0 | F26: ='EMS Gridvis'!D25 -> 0 | G26: ='EMS Gridvis'!H25 -> 0 | H26: ='EMS Gridvis'!I25 -> 0 | I26: ='EMS Gridvis'!J25 -> 0 | J26: =Generator!D27 -> 0 | K26: =Generator!H27 -> 0 | L26: =Generator!L27 -> 0 | M26: =Generator!P27 -> 0 | N26: =Generator!T27 -> 0 | P26: =23.94/13.49 -> 1.7746479 | R26: 1.84 | S26: ='RO Plant'!B27 -> 0 | T26: ='RO Plant'!E27 -> 0 | U26: ='RO Plant'!F27 -> 0 | V26: ='RO Plant'!I27 -> 0 | W26: ='RO Plant'!G27 -> 0 | AA26: =AB26-AB25 -> 0
A27: 44920 | D27: ='EMS Gridvis'!B26 -> 0 | E27: ='EMS Gridvis'!C26 -> 0 | F27: ='EMS Gridvis'!D26 -> 0 | G27: ='EMS Gridvis'!H26 -> 0 | H27: ='EMS Gridvis'!I26 -> 0 | I27: ='EMS Gridvis'!J26 -> 0 | J27: =Generator!D28 -> 0 | K27: =Generator!H28 -> 0 | L27: =Generator!L28 -> 0 | M27: =Generator!P28 -> 0 | N27: =Generator!T28 -> 0 | P27: =23.94/13.49 -> 1.7746479 | R27: 1.84 | S27: ='RO Plant'!B28 -> 0 | T27: ='RO Plant'!E28 -> 0 | U27: ='RO Plant'!F28 -> 0 | V27: ='RO Plant'!I28 -> 0 | W27: ='RO Plant'!G28 -> 0 | AA27: =AB27-AB26 -> 0
... A33: 44926 | D33: ='EMS Gridvis'!B32 -> 0 | E33: ='EMS Gridvis'!C32 -> 0 | F33: ='EMS Gridvis'!D32 -> 0 | G33: ='EMS Gridvis'!H32 -> 0 | H33: ='EMS Gridvis'!I32 -> 0 | I33: ='EMS Gridvis'!J32 -> 0 | J33: =Generator!D34 -> 0 | K33: =Generator!H34 -> 0 | L33: =Generator!L34 -> 0 | M33: =Generator!P34 -> 0 | N33: =Generator!T34 -> 0 | P33: =23.94/13.49 -> 1.7746479 | R33: 1.84 | S33: ='RO Plant'!B34 -> 0 | T33: ='RO Plant'!E34 -> 0 | U33: ='RO Plant'!F34 -> 0 | V33: ='RO Plant'!I34 -> 0 | W33: ='RO Plant'!G34 -> 0 | AA33: =AB33-AB32 -> 0
D35: =SUM(D33:I33) -> 0 | S35: =SUM(S33:W33) -> 0 | Y35: =SUM(Z15,Z10) -> 0
D36: =D35*1000 -> 0

Sheet RO Plant
A1: Location | B1: BOH | C1: E-Resort | D1: North RVs | E1: Kannel,300,400,500,600,SRV,300,400 | F1: Zez,SPA,MV,100,200 | G1: STP | H1: From E-Resort | I1: BOH | J1: SRV | N1: Formula
A2: DATE | B2: BOH Water (m3) | C2: E-Resort (m3) | D2: North RVs (m3) | E2: WT59 (m3) | F2: WT08 (m3) | G2: Fire Tank (m3) | H2: PUC (E- Resort) (m3) | I2: PUC HOH (m3) | J2: SRV1 (m3) | K2: SRV2 (m3) | L2: SRV3 (m3) | N2: Excluding all SRVs
A3: Average reading | B3: 60.633333 | C3: 32.333333 | D3: 133.03333 | E3: 168.23333 | F3: 76.666667 | G3: 0 | H3: 13.166667 | I3: 93.233333 | J3: 12.566667 | K3: 35.666667 | L3: 24.733333
A4: 44896 | B4: 60 | C4: 24 | D4: 214 | E4: 152 | F4: 71 | G4: 0 | H4: 0 | I4: 100 | J4: 13 | K4: 32 | L4: 29 | N4: =K4-(J4+L4) -> -10
A5: 44897 | B5: 58 | C5: 14 | D5: 135 | E5: 97 | F5: 75 | G5: 0 | H5: 0 | I5: 100 | J5: 0 | K5: 28 | L5: 27 | N5: =K5-(J5+L5) -> 1
A6: 44898 | B6: 57 | C6: 31 | D6: 125 | E6: 67 | F6: 87 | G6: 0 | H6: 0 | I6: 102 | J6: 10 | K6: 38 | L6: 22 | N6: =K6-(J6+L6) -> 6
A7: 44899 | B7: 71 | C7: 22 | D7: 139 | E7: 145 | F7: 63 | G7: 0 | H7: 0 | I7: 98 | J7: 14 | K7: 34 | L7: 27 | N7: =K7-(J7+L7) -> -7
A8: 44900 | B8: 60 | C8: 28 | D8: 141 | E8: 155 | F8: 71 | G8: 0 | H8: 0 | I8: 101 | J8: 19 | K8: 46 | L8: 51 | N8: =K8-(J8+L8) -> -24
A9: 44901 | N9: =K9-(J9+L9) -> 0
A10: 44902 | N10: =K10-(J10+L10) -> 0
A11: 44903 | N11: =K11-(J11+L11) -> 0
A12: 44904 | N12: =K12-(J12+L12) -> 0
A13: 44905 | N13: =K13-(J13+L13) -> 0
A14: 44906 | N14: =K14-(J14+L14) -> 0
A15: 44907 | N15: =K15-(J15+L15) -> 0
A16: 44908 | N16: =K16-(J16+L16) -> 0
A17: 44909 | N17: =K17-(J17+L17) -> 0
A18: 44910 | N18: =K18-(J18+L18) -> 0
A19: 44911 | N19: =K19-(J19+L19) -> 0
A20: 44912 | N20: =K20-(J20+L20) -> 0
... A26: 44918 | N26: =K26-(J26+L26) -> 0
A27: 44919 | N27: 0
A28: 44920 | N28: =K28-(J28+L28) -> 0
A29: 44921 | N29: =K29-(J29+L29) -> 0
A30: 44922 | N30: =K30-(J30+L30) -> 0
A31: 44923 | N31: =K31-(J31+L31) -> 0
A32: 44924 | N32: =K32-(J32+L32) -> 0
A33: 44925 | N33: =K33-(J33+L33) -> 0
A34: 44926 | N34: =K34-(J34+L34) -> 0
A35: TOTAL | B35: =SUM(B4:B34) -> 306 | C35: =SUM(C4:C34) -> 119 | D35: =SUM(D4:D34) -> 754 | E35: =SUM(E4:E34) -> 616 | F35: =SUM(F4:F34) -> 367 | G35: =SUM(G4:G34) -> 0 | H35: =SUM(H4:H34) -> 0 | I35: =SUM(I4:I34) -> 501 | J35: =SUM(J4:J34) -> 56 | L35: =SUM(L4:L34) -> 156 | N35: =E35-J35-(L35+3) -> 401

Sheet Generator
B2: Generator#1 | F2: Generator#2 | J2: Generator#3 | N2: Generator#4 | R2: Generator#5 | AB2: Taken 8AM
A3: DATE | B3: Running Hours | C3: Daily Fuel Burned | D3: Daily Energy Consumed | F3: Running Hours | G3: Daily Fuel Burned | H3: Daily Energy Consumed | J3: Running Hours | K3: Daily Fuel Burned | L3: Daily Energy Consumed | N3: Running Hours | O3: Daily Fuel Burned | P3: Daily Energy Consumed | R3: Running Hours | S3: Daily Fuel Burned | T3: Daily Energy Consumed | V3: Occupancy | W3: Total hours per day | X3: Total fuel burned (liters) | Y3: Total consumed energy (KWH) | Z3: 0
A4: 44896 | B4: 21 | C4: 2761 | D4: 12787 | F4: 15 | G4: 2359 | H4: 10907 | J4: 10 | K4: 1135 | L4: 5248 | N4: 0 | O4: 0 | P4: 0 | R4: 10 | S4: 1588 | T4: 7520 | W4: =SUM(B4,F4,J4,N4,R4) -> 56 | X4: =SUM(C4,G4,K4,O4,S4) -> 7843 | Y4: =SUM(D4,H4,L4,P4,T4) -> 36462
A5: 44897 | B5: 9 | C5: 1191 | D5: 5363 | F5: 15 | G5: 2333 | H5: 10782 | J5: 9 | K5: 1082 | L5: 5378 | N5: 0 | O5: 0 | P5: 0 | R5: 15 | S5: 2436 | T5: 10802 | W5: =SUM(B5,F5,J5,N5,R5) -> 48 | X5: =SUM(C5,G5,K5,O5,S5) -> 7042 | Y5: =SUM(D5,H5,L5,P5,T5) -> 32325
A6: 44898 | B6: 14 | C6: 1752 | D6: 8388 | F6: 11 | G6: 1517 | H6: 6931 | J6: 20 | K6: 2421 | L6: 11861 | N6: 0 | O6: 0 | P6: 0 | R6: 9 | S6: 1261 | T6: 5766 | W6: =SUM(B6,F6,J6,N6,R6) -> 54 | X6: =SUM(C6,G6,K6,O6,S6) -> 6951 | Y6: =SUM(D6,H6,L6,P6,T6) -> 32946
A7: 44899 | B7: 18 | C7: 2262 | D7: 10905 | F7: 14 | G7: 1963 | H7: 8754 | J7: 13 | K7: 1619 | L7: 7905 | N7: 0 | O7: 0 | P7: 0 | R7: 13 | S7: 1894 | T7: 8073 | W7: =SUM(B7,F7,J7,N7,R7) -> 58 | X7: =SUM(C7,G7,K7,O7,S7) -> 7738 | Y7: =SUM(D7,H7,L7,P7,T7) -> 35637
A8: 44900 | B8: 9 | C8: 1132 | D8: 5104 | F8: 24 | G8: 3332 | H8: 15185 | J8: 13 | K8: 1667 | L8: 8249 | N8: 0 | O8: 0 | P8: 0 | R8: 7 | S8: 922 | T8: 4060 | W8: =SUM(B8,F8,J8,N8,R8) -> 53 | X8: =SUM(C8,G8,K8,O8,S8) -> 7053 | Y8: =SUM(D8,H8,L8,P8,T8) -> 32598
A9: 44901 | W9: =SUM(B9,F9,J9,N9,R9) -> 0 | X9: =SUM(C9,G9,K9,O9,S9) -> 0 | Y9: =SUM(D9,H9,L9,P9,T9) -> 0
A10: 44902 | W10: =SUM(B10,F10,J10,N10,R10) -> 0 | X10: =SUM(C10,G10,K10,O10,S10) -> 0 | Y10: =SUM(D10,H10,L10,P10,T10) -> 0
A11: 44903 | W11: =SUM(B11,F11,J11,N11,R11) -> 0 | X11: =SUM(C11,G11,K11,O11,S11) -> 0 | Y11: =SUM(D11,H11,L11,P11,T11) -> 0
A12: 44904 | W12: =SUM(B12,F12,J12,N12,R12) -> 0 | X12: =SUM(C12,G12,K12,O12,S12) -> 0 | Y12: =SUM(D12,H12,L12,P12,T12) -> 0
A13: 44905 | W13: =SUM(B13,F13,J13,N13,R13) -> 0 | X13: =SUM(C13,G13,K13,O13,S13) -> 0 | Y13: =SUM(D13,H13,L13,P13,T13) -> 0
A14: 44906 | W14: =SUM(B14,F14,J14,N14,R14) -> 0 | X14: =SUM(C14,G14,K14,O14,S14) -> 0 | Y14: =SUM(D14,H14,L14,P14,T14) -> 0
A15: 44907 | W15: =SUM(B15,F15,J15,N15,R15) -> 0 | X15: =SUM(C15,G15,K15,O15,S15) -> 0 | Y15: =SUM(D15,H15,L15,P15,T15) -> 0
A16: 44908 | W16: =SUM(B16,F16,J16,N16,R16) -> 0 | X16: =SUM(C16,G16,K16,O16,S16) -> 0 | Y16: =SUM(D16,H16,L16,P16,T16) -> 0
A17: 44909 | W17: =SUM(B17,F17,J17,N17,R17) -> 0 | X17: =SUM(C17,G17,K17,O17,S17) -> 0 | Y17: =SUM(D17,H17,L17,P17,T17) -> 0 | Z17: =AA17-AA16 -> 0 | AA17: =SUM(AB17,AC17) -> 0
A18: 44910 | W18: =SUM(B18,F18,J18,N18,R18) -> 0 | X18: =SUM(C18,G18,K18,O18,S18) -> 0 | Y18: =SUM(D18,H18,L18,P18,T18) -> 0 | Z18: =AA18-AA17 -> 0 | AA18: =SUM(AB18,AC18) -> 0
A19: 44911 | W19: =SUM(B19,F19,J19,N19,R19) -> 0 | X19: =SUM(C19,G19,K19,O19,S19) -> 0 | Y19: =SUM(D19,H19,L19,P19,T19) -> 0 | Z19: =AA19-AA18 -> 0 | AA19: =SUM(AB19,AC19) -> 0
A20: 44912 | W20: =SUM(B20,F20,J20,N20,R20) -> 0 | X20: =SUM(C20,G20,K20,O20,S20) -> 0 | Y20: =SUM(D20,H20,L20,P20,T20) -> 0 | Z20: =AA20-AA19 -> 0 | AA20: =SUM(AB20,AC20) -> 0
A21: 44913 | W21: =SUM(B21,F21,J21,N21,R21) -> 0 | X21: =SUM(C21,G21,K21,O21,S21) -> 0 | Y21: =SUM(D21,H21,L21,P21,T21) -> 0 | Z21: =AA21-AA20 -> 0 | AA21: =SUM(AB21,AC21) -> 0
A22: 44914 | W22: =SUM(B22,F22,J22,N22,R22) -> 0 | X22: =SUM(C22,G22,K22,O22,S22) -> 0 | Y22: =SUM(D22,H22,L22,P22,T22) -> 0 | Z22: =AA22-AA21 -> 0 | AA22: =SUM(AB22,AC22) -> 0
A23: 44915 | W23: =SUM(B23,F23,J23,N23,R23) -> 0 | X23: =SUM(C23,G23,K23,O23,S23) -> 0 | Y23: =SUM(D23,H23,L23,P23,T23) -> 0 | Z23: =AA23-AA22 -> 0 | AA23: =SUM(AB23,AC23) -> 0
A24: 44916 | W24: =SUM(B24,F24,J24,N24,R24) -> 0 | X24: =SUM(C24,G24,K24,O24,S24) -> 0 | Y24: =SUM(D24,H24,L24,P24,T24) -> 0 | Z24: =AA24-AA23 -> 0 | AA24: =SUM(AB24,AC24) -> 0
A25: 44917 | W25: =SUM(B25,F25,J25,N25,R25) -> 0 | X25: =SUM(C25,G25,K25,O25,S25) -> 0 | Y25: =SUM(D25,H25,L25,P25,T25) -> 0 | Z25: =AA25-AA24 -> 0 | AA25: =SUM(AB25,AC25) -> 0
A26: 44918 | W26: =SUM(B26,F26,J26,N26,R26) -> 0 | X26: =SUM(C26,G26,K26,O26,S26) -> 0 | Y26: =SUM(D26,H26,L26,P26,T26) -> 0 | Z26: =AA26-AA25 -> 0 | AA26: =SUM(AB26,AC26) -> 0
A27: 44919 | W27: =SUM(B27,F27,J27,N27,R27) -> 0 | X27: =SUM(C27,G27,K27,O27,S27) -> 0 | Y27: =SUM(D27,H27,L27,P27,T27) -> 0 | Z27: =AA27-AA26 -> 0 | AA27: =SUM(AB27,AC27) -> 0
A28: 44920 | W28: =SUM(B28,F28,J28,N28,R28) -> 0 | X28: =SUM(C28,G28,K28,O28,S28) -> 0 | Y28: =SUM(D28,H28,L28,P28,T28) -> 0 | Z28: =AA28-AA27 -> 0 | AA28: =SUM(AB28,AC28) -> 0
... A34: 44926 | W34: =SUM(B34,F34,J34,N34,R34) -> 0 | X34: =SUM(C34,G34,K34,O34,S34) -> 0 | Y34: =SUM(D34,H34,L34,P34,T34) -> 0 | Z34: =AA34-AA33 -> 0 | AA34: =SUM(AB34,AC34) -> 0
A35: DATE | B35: Running Hours | C35: Daily Fuel Burned | D35: Daily Energy Consumed | F35: Running Hours | G35: Daily Fuel Burned | H35: Daily Energy Consumed | J35: Running Hours | K35: Daily Fuel Burned | L35: Daily Energy Consumed | N35: Running Hours | O35: Daily Fuel Burned | P35: Daily Energy Consumed | R35: Running Hours | S35: Daily Fuel Burned | T35: Daily Energy Consumed | W35: =SUM(W4:W34) -> 269 | X35: =SUM(X4:X34) -> 36627 | Y35: =SUM(Y4:Y34) -> 169968
A36: TOTAL | B36: =SUM(B4:B34) -> 71 | C36: =SUM(C4:C34) -> 9098 | D36: =SUM(D4:D34) -> 42547 | F36: =SUM(F4:F34) -> 79 | G36: =SUM(G4:G34) -> 11504 | H36: =SUM(H4:H34) -> 52559 | J36: =SUM(J4:J34) -> 65 | K36: =SUM(K4:K34) -> 7924 | L36: =SUM(L4:L34) -> 38641 | N36: =SUM(N4:N34) -> 0 | O36: =SUM(O4:O34) -> 0 | P36: =SUM(P4:P34) -> 0 | R36: =SUM(R4:R34) -> 54 | S36: =SUM(S4:S34) -> 8101 | T36: =SUM(T4:T34) -> 36221
B37: Generator#1 | F37: Generator#2 | J37: Generator#3 | N37: Generator#4 | R37: Generator#5
A38: DATE | B38: Fuel burned Per Hour | C38: Energy Consumed Per Hour | D38: Engine Efficiency | E38: Load % | F38: Fuel burned Per Hour | G38: Energy Consumed Per Hour | H38: Engine Efficiency | I38: Load % | J38: Fuel burned Per Hour | K38: Energy Consumed Per Hour | L38: Engine Efficiency | M38: Load % | N38: Fuel burned Per Hour | O38: Energy Consumed Per Hour | P38: Engine Efficiency | Q38: Load % | R38: Fuel burned Per Hour | S38: Energy Consumed Per Hour | T38: Engine Efficiency | U38: Load %
A39: =A4 -> 44896 | B39: =C4/B4 -> 131.47619 | C39: =D4/B4 -> 608.90476 | D39: =C39/B39 -> 4.631293 | E39: =(C39/1120)*100 -> 54.366497 | F39: =G4/F4 -> 157.26667 | G39: =H4/F4 -> 727.13333 | H39: =G39/F39 -> 4.6235693 | I39: =(G39/1120)*100 -> 64.922619 | J39: =K4/J4 -> 113.5 | K39: =L4/J4 -> 524.8 | L39: =K39/J39 -> 4.6237885 | M39: =(K39/1120)*100 -> 46.857143 | N39: =O4/N4 -> #DIV/0! | O39: =P4/N4 -> #DIV/0! | P39: =O39/N39 -> #DIV/0! | Q39: =(O39/1120)*100 -> #DIV/0! | R39: =S4/R4 -> 158.8 | S39: =T4/R4 -> 752 | T39: =S39/R39 -> 4.7355164 | U39: =(S39/1120)*100 -> 67.142857
A40: =A5 -> 44897 | B40: =C5/B5 -> 132.33333 | C40: =D5/B5 -> 595.88889 | D40: =C40/B40 -> 4.5029387 | E40: =(C40/1120)*100 -> 53.204365 | F40: =G5/F5 -> 155.53333 | G40: =H5/F5 -> 718.8 | H40: =G40/F40 -> 4.6215174 | I40: =(G40/1120)*100 -> 64.178571 | J40: =K5/J5 -> 120.22222 | K40: =L5/J5 -> 597.55556 | L40: =K40/J40 -> 4.9704251 | M40: =(K40/1120)*100 -> 53.353175 | N40: =O5/N5 -> #DIV/0! | O40: =P5/N5 -> #DIV/0! | P40: =O40/N40 -> #DIV/0! | Q40: =(O40/1120)*100 -> #DIV/0! | R40: =S5/R5 -> 162.4 | S40: =T5/R5 -> 720.13333 | T40: =S40/R40 -> 4.4343186 | U40: =(S40/1120)*100 -> 64.297619
A41: =A6 -> 44898 | B41: =C6/B6 -> 125.14286 | C41: =D6/B6 -> 599.14286 | D41: =C41/B41 -> 4.7876712 | E41: =(C41/1120)*100 -> 53.494898 | F41: =G6/F6 -> 137.90909 | G41: =H6/F6 -> 630.09091 | H41: =G41/F41 -> 4.568886 | I41: =(G41/1120)*100 -> 56.258117 | J41: =K6/J6 -> 121.05 | K41: =L6/J6 -> 593.05 | L41: =K41/J41 -> 4.8992152 | M41: =(K41/1120)*100 -> 52.950893 | N41: =O6/N6 -> #DIV/0! | O41: =P6/N6 -> #DIV/0! | P41: =O41/N41 -> #DIV/0! | Q41: =(O41/1120)*100 -> #DIV/0! | R41: =S6/R6 -> 140.11111 | S41: =T6/R6 -> 640.66667 | T41: =S41/R41 -> 4.5725615 | U41: =(S41/1120)*100 -> 57.202381
A42: =A7 -> 44899 | B42: =C7/B7 -> 125.66667 | C42: =D7/B7 -> 605.83333 | D42: =C42/B42 -> 4.8209549 | E42: =(C42/1120)*100 -> 54.092262 | F42: =G7/F7 -> 140.21429 | G42: =H7/F7 -> 625.28571 | H42: =G42/F42 -> 4.4595008 | I42: =(G42/1120)*100 -> 55.829082 | J42: =K7/J7 -> 124.53846 | K42: =L7/J7 -> 608.07692 | L42: =K42/J42 -> 4.8826436 | M42: =(K42/1120)*100 -> 54.292582 | N42: =O7/N7 -> #DIV/0! | O42: =P7/N7 -> #DIV/0! | P42: =O42/N42 -> #DIV/0! | Q42: =(O42/1120)*100 -> #DIV/0! | R42: =S7/R7 -> 145.69231 | S42: =T7/R7 -> 621 | T42: =S42/R42 -> 4.2624076 | U42: =(S42/1120)*100 -> 55.446429
A43: =A8 -> 44900 | B43: =C8/B8 -> 125.77778 | C43: =D8/B8 -> 567.11111 | D43: =C43/B43 -> 4.5088339 | E43: =(C43/1120)*100 -> 50.634921 | F43: =G8/F8 -> 138.83333 | G43: =H8/F8 -> 632.70833 | H43: =G43/F43 -> 4.5573229 | I43: =(G43/1120)*100 -> 56.491815 | J43: =K8/J8 -> 128.23077 | K43: =L8/J8 -> 634.53846 | L43: =K43/J43 -> 4.9484103 | M43: =(K43/1120)*100 -> 56.65522 | N43: =O8/N8 -> #DIV/0! | O43: =P8/N8 -> #DIV/0! | P43: =O43/N43 -> #DIV/0! | Q43: =(O43/1120)*100 -> #DIV/0! | R43: =S8/R8 -> 131.71429 | S43: =T8/R8 -> 580 | T43: =S43/R43 -> 4.4034707 | U43: =(S43/1120)*100 -> 51.785714
A44: =A9 -> 44901 | B44: =C9/B9 -> #DIV/0! | C44: =D9/B9 -> #DIV/0! | D44: =C44/B44 -> #DIV/0! | E44: =(C44/1120)*100 -> #DIV/0! | F44: =G9/F9 -> #DIV/0! | G44: =H9/F9 -> #DIV/0! | H44: =G44/F44 -> #DIV/0! | I44: =(G44/1120)*100 -> #DIV/0! | J44: =K9/J9 -> #DIV/0! | K44: =L9/J9 -> #DIV/0! | L44: =K44/J44 -> #DIV/0! | M44: =(K44/1120)*100 -> #DIV/0! | N44: =O9/N9 -> #DIV/0! | O44: =P9/N9 -> #DIV/0! | P44: =O44/N44 -> #DIV/0! | Q44: =(O44/1120)*100 -> #DIV/0! | R44: =S9/R9 -> #DIV/0! | S44: =T9/R9 -> #DIV/0! | T44: =S44/R44 -> #DIV/0! | U44: =(S44/1120)*100 -> #DIV/0!
A45: =A10 -> 44902 | B45: =C10/B10 -> #DIV/0! | C45: =D10/B10 -> #DIV/0! | D45: =C45/B45 -> #DIV/0! | E45: =(C45/1120)*100 -> #DIV/0! | F45: =G10/F10 -> #DIV/0! | G45: =H10/F10 -> #DIV/0! | H45: =G45/F45 -> #DIV/0! | I45: =(G45/1120)*100 -> #DIV/0! | J45: =K10/J10 -> #DIV/0! | K45: =L10/J10 -> #DIV/0! | L45: =K45/J45 -> #DIV/0! | M45: =(K45/1120)*100 -> #DIV/0! | N45: =O10/N10 -> #DIV/0! | O45: =P10/N10 -> #DIV/0! | P45: =O45/N45 -> #DIV/0! | Q45: =(O45/1120)*100 -> #DIV/0! | R45: =S10/R10 -> #DIV/0! | S45: =T10/R10 -> #DIV/0! | T45: =S45/R45 -> #DIV/0! | U45: =(S45/1120)*100 -> #DIV/0!
A46: =A11 -> 44903 | B46: =C11/B11 -> #DIV/0! | C46: =D11/B11 -> #DIV/0! | D46: =C46/B46 -> #DIV/0! | E46: =(C46/1120)*100 -> #DIV/0! | F46: =G11/F11 -> #DIV/0! | G46: =H11/F11 -> #DIV/0! | H46: =G46/F46 -> #DIV/0! | I46: =(G46/1120)*100 -> #DIV/0! | J46: =K11/J11 -> #DIV/0! | K46: =L11/J11 -> #DIV/0! | L46: =K46/J46 -> #DIV/0! | M46: =(K46/1120)*100 -> #DIV/0! | N46: =O11/N11 -> #DIV/0! | O46: =P11/N11 -> #DIV/0! | P46: =O46/N46 -> #DIV/0! | Q46: =(O46/1120)*100 -> #DIV/0! | R46: =S11/R11 -> #DIV/0! | S46: =T11/R11 -> #DIV/0! | T46: =S46/R46 -> #DIV/0! | U46: =(S46/1120)*100 -> #DIV/0!
...

Sheet EMS Gridvis
A1: DAY | B1: SS-A | C1: SS-B | D1: SS-C | E1: SS-D1 | F1: SS-D2 | G1: SS-E | H1: FIRE PUMP | I1: CASINO | J1: BOH | K1: PUC
A2: 1 | B2: 3.07 | C2: 4.4 | D2: 5.88 | E2: 1.75 | F2: 2.48 | G2: 2.93 | H2: 1.53 | I2: 1.88 | J2: 4.01 | K2: 0
A3: 2 | B3: 2.48 | C3: 3.87 | D3: 5.37 | E3: 1.42 | F3: 2.09 | G3: 2.45 | H3: 1.45 | I3: 1.71 | J3: 3.82 | K3: 0
A4: 3 | B4: 2.94 | C4: 4.32 | D4: 5.75 | E4: 1.54 | F4: 2.26 | G4: 2.68 | H4: 1.44 | I4: 1.77 | J4: 3.84 | K4: 0
A5: 4 | B5: 3.08 | C5: 4.45 | D5: 5.48 | E5: 1.66 | F5: 2.33 | G5: 2.77 | H5: 1.23 | I5: 1.69 | J5: 3.63 | K5: 0
A6: 5 | B6: 3.24 | C6: 4.32 | D6: 5.48 | E6: 1.9 | F6: 2.56 | G6: 2.62 | H6: 1.14 | I6: 1.74 | J6: 3.77 | K6: 0
A7: 6 | K7: 0
A8: 7 | K8: 0
A9: 8 | K9: 0
A10: 9 | K10: 0
A11: 10 | K11: 0
A12: 11 | K12: 0
A13: 12 | K13: 0
A14: 13 | K14: 0
A15: 14 | K15: 0
A16: 15 | K16: 0
A17: 16 | K17: 0
A18: 17 | K18: 0
... A32: 31 | K32: 0
