Workbook

Sheet TOTAL
A1: Site Name | B1: Day | C1: Month | D1: Year | E1: Total Electricity Kwh | F1: Electricity Tariff ($/Kwh) | G1: LPG (Kg) | H1: LPG $/Kg | I1: Water Utility Supply (m3) m3 | J1: Water Utility Supply (m3) $/m3 | K1: Room Nights | L1: Food Covers
A2: Maldives at Landaa Giraavaru | B2: 1 | C2: 10 | D2: 2021 | E2: ='Maldives at LG Daily'!D5 -> 23451 | F2: 0.93 | G2: ='Maldives at LG Daily'!F5 -> 180 | H2: 1.24 | I2: ='Maldives at LG Daily'!H5 -> 0 | J2: 2.16 | K2: ='Maldives at LG Daily'!I5 -> 0 | L2: ='Maldives at LG Daily'!J5 -> 1797
A3: Maldives at Landaa Giraavaru | B3: =B2+1 -> 2 | C3: 10 | D3: 2021 | E3: ='Maldives at LG Daily'!D6 -> 21626 | F3: 0.93 | G3: ='Maldives at LG Daily'!F6 -> 45 | H3: 1.24 | I3: ='Maldives at LG Daily'!H6 -> 5232 | J3: 2.16 | K3: ='Maldives at LG Daily'!I6 -> 5275 | L3: ='Maldives at LG Daily'!J6 -> 2735
A4: Maldives at Landaa Giraavaru | B4: =B3+1 -> 3 | C4: 10 | D4: 2021 | E4: ='Maldives at LG Daily'!D7 -> 23924 | F4: 0.93 | G4: ='Maldives at LG Daily'!F7 -> 0 | H4: 1.24 | I4: ='Maldives at LG Daily'!H7 -> 5467 | J4: 2.16 | K4: ='Maldives at LG Daily'!I7 -> 3209 | L4: ='Maldives at LG Daily'!J7 -> 2624
A5: Maldives at Landaa Giraavaru | B5: =B4+1 -> 4 | C5: 10 | D5: 2021 | E5: ='Maldives at LG Daily'!D8 -> 23294 | F5: 0.93 | G5: ='Maldives at LG Daily'!F8 -> 0 | H5: 1.24 | I5: ='Maldives at LG Daily'!H8 -> 5758 | J5: 2.16 | K5: ='Maldives at LG Daily'!I8 -> 7157 | L5: ='Maldives at LG Daily'!J8 -> 1595
A6: Maldives at Landaa Giraavaru | B6: =B5+1 -> 5 | C6: 10 | D6: 2021 | E6: ='Maldives at LG Daily'!D9 -> 22493 | F6: 0.93 | G6: ='Maldives at LG Daily'!F9 -> 0 | H6: 1.24 | I6: ='Maldives at LG Daily'!H9 -> 10548 | J6: 2.16 | K6: ='Maldives at LG Daily'!I9 -> 2548 | L6: ='Maldives at LG Daily'!J9 -> 27
A7: Maldives at Landaa Giraavaru | B7: =B6+1 -> 6 | C7: 10 | D7: 2021 | E7: ='Maldives at LG Daily'!D10 -> 23652 | F7: 0.93 | G7: ='Maldives at LG Daily'!F10 -> 0 | H7: 1.24 | I7: ='Maldives at LG Daily'!H10 -> 9782 | J7: 2.16 | K7: ='Maldives at LG Daily'!I10 -> 6770 | L7: ='Maldives at LG Daily'!J10 -> 1524
A8: Maldives at Landaa Giraavaru | B8: =B7+1 -> 7 | C8: 10 | D8: 2021 | E8: ='Maldives at LG Daily'!D11 -> 24002 | F8: 0.93 | G8: ='Maldives at LG Daily'!F11 -> 45 | H8: 1.24 | I8: ='Maldives at LG Daily'!H11 -> 7514 | J8: 2.16 | K8: ='Maldives at LG Daily'!I11 -> 2259 | L8: ='Maldives at LG Daily'!J11 -> 2657
A9: Maldives at Landaa Giraavaru | B9: =B8+1 -> 8 | C9: 10 | D9: 2021 | E9: ='Maldives at LG Daily'!D12 -> 24528 | F9: 0.93 | G9: ='Maldives at LG Daily'!F12 -> 0 | H9: 1.24 | I9: ='Maldives at LG Daily'!H12 -> 8568 | J9: 2.16 | K9: ='Maldives at LG Daily'!I12 -> 1552 | L9: ='Maldives at LG Daily'!J12 -> 1657
A10: Maldives at Landaa Giraavaru | B10: =B9+1 -> 9 | C10: 10 | D10: 2021 | E10: ='Maldives at LG Daily'!D13 -> 25400 | F10: 0.93 | G10: ='Maldives at LG Daily'!F13 -> 90 | H10: 1.24 | I10: ='Maldives at LG Daily'!H13 -> 8114 | J10: 2.16 | K10: ='Maldives at LG Daily'!I13 -> 3348 | L10: ='Maldives at LG Daily'!J13 -> 2157
A11: Maldives at Landaa Giraavaru | B11: =B10+1 -> 10 | C11: 10 | D11: 2021 | E11: ='Maldives at LG Daily'!D14 -> 25384 | F11: 0.93 | G11: ='Maldives at LG Daily'!F14 -> 0 | H11: 1.24 | I11: ='Maldives at LG Daily'!H14 -> 9992 | J11: 2.16 | K11: ='Maldives at LG Daily'!I14 -> 5298 | L11: ='Maldives at LG Daily'!J14 -> 1966
A12: Maldives at Landaa Giraavaru | B12: =B11+1 -> 11 | C12: 10 | D12: 2021 | E12: ='Maldives at LG Daily'!D15 -> 26115 | F12: 0.93 | G12: ='Maldives at LG Daily'!F15 -> 0 | H12: 1.24 | I12: ='Maldives at LG Daily'!H15 -> 5674 | J12: 2.16 | K12: ='Maldives at LG Daily'!I15 -> 422 | L12: ='Maldives at LG Daily'!J15 -> 3230
A13: Maldives at Landaa Giraavaru | B13: =B12+1 -> 12 | C13: 10 | D13: 2021 | E13: ='Maldives at LG Daily'!D16 -> 25368 | F13: 0.93 | G13: ='Maldives at LG Daily'!F16 -> 0 | H13: 1.24 | I13: ='Maldives at LG Daily'!H16 -> 6028 | J13: 2.16 | K13: ='Maldives at LG Daily'!I16 -> 0 | L13: ='Maldives at LG Daily'!J16 -> 2611
A14: Maldives at Landaa Giraavaru | B14: =B13+1 -> 13 | C14: 10 | D14: 2021 | E14: ='Maldives at LG Daily'!D17 -> 26433 | F14: 0.93 | G14: ='Maldives at LG Daily'!F17 -> 90 | H14: 1.24 | I14: ='Maldives at LG Daily'!H17 -> 9672 | J14: 2.16 | K14: ='Maldives at LG Daily'!I17 -> 4600 | L14: ='Maldives at LG Daily'!J17 -> 3947
... A30: Maldives at Landaa Giraavaru | B30: =B29+1 -> 29 | C30: 10 | D30: 2021 | E30: ='Maldives at LG Daily'!D33 -> 27036 | F30: 0.93 | G30: ='Maldives at LG Daily'!F33 -> 45 | H30: 1.24 | I30: ='Maldives at LG Daily'!H33 -> 4324 | J30: 2.16 | K30: ='Maldives at LG Daily'!I33 -> 1831 | L30: ='Maldives at LG Daily'!J33 -> 4310
A31: Maldives at Landaa Giraavaru | B31: 30 | C31: 10 | D31: 2021 | E31: ='Maldives at LG Daily'!D34 -> 26752 | F31: 0.93 | G31: ='Maldives at LG Daily'!F34 -> 0 | H31: 1.24 | I31: ='Maldives at LG Daily'!H34 -> 8451 | J31: 2.16 | K31: ='Maldives at LG Daily'!I34 -> 0 | L31: ='Maldives at LG Daily'!J34 -> 4396
A32: Maldives at Landaa Giraavaru | B32: 31 | C32: 10 | D32: 2021 | E32: ='Maldives at LG Daily'!D35 -> 27036 | F32: 0.93 | G32: ='Maldives at LG Daily'!F35 -> 45 | H32: 1.24 | I32: ='Maldives at LG Daily'!H35 -> 8540 | J32: 2.16 | K32: ='Maldives at LG Daily'!I35 -> 4461 | L32: ='Maldives at LG Daily'!J35 -> 1022

Sheet Submetering 
A1: Site Name | B1: Day | C1: Month | D1: Year | E1: GENSET NO 1 | F1: GENSET NO 2 | G1: GENSET NO 3 | H1: GENSET NO 4 | I1: GENSET NO 5 | J1: Main BLU FEEDER PANEL 1 | K1: Main BLU FEEDER PANEL 2 | L1: Main POWER HOUSE FEEDER PANEL NO:3 | M1: Main Kitchen -7 | N1: Main Kitchen -10 | O1: Water treatment Plant | P1: Sewage treatment Plant | Q1: Laundry--8SSB (Machineries) | R1: Laundry-9 (HR/Tuck Shop Building) | S1: New staff accomodation (E0) | T1: Staff block-16(E2-E3) | U1: Staff Block Feeder-3(E4-E5) | V1: Management block-5 (M1 to M6) | W1: SNR STAFF BLOCK (PC Block) | X1: BOAT DOCK FEEDER - 22 | Y1: RECEPTION Building Full (Finance/Reservation) | Z1: DIVE CENTER (Inc MDC and Recreation) | AA1: 301-307 | AB1: 308-314 | AC1: 315-320 | AD1: 401-407 | AE1: 408-414 | AF1: 415-420 | AG1: SPA - 1 | AH1: SPA - 2 | AI1: BLU KITCHEN - 1 | AJ1: BLU KITCHEN - 2 | AK1: AL BARAKATH | AL1: STAFF KITCHEN | AM1: R/O Plant A | AN1: R/O Plant B | AO1: R/O Plant C | AP1: R/O Plant D | AQ1: Laundry | AR1: Staff Block - E0 | AS1: Staff Block - E1 | AT1: Staff Block - E2 | AU1: Staff Block - E3 | AV1: Staff Block - E4 | AW1: Staff Block - E5 | AX1: Management Block | AY1: PC Block | AZ1: GM Bungalow | BA1: Boat Dock | BB1: Supply Jetty | BC1: Main Kitchen | BD1: Day Facility | BE1: Reception | BF1: Main Pool | BG1: Dive Center | BH1: Albarakthu | BI1: Blu Resturant | BJ1: Main Jetty | BK1: Landaa Estate | BL1: ROOM NIGHTS | BM1: Total Food Covers
A2: Maldives at Landaa Giraavaru | B2: 1 | C2: 10 | D2: 2021 | E2: 11980 | F2: 0 | G2: 0 | H2: 1797 | I2: 9674 | J2: 2022 | K2: 3360 | L2: 13461 | M2: 1500 | N2: 2615 | O2: 1500 | P2: 796 | Q2: 580 | R2: 785 | S2: 443 | T2: 871 | U2: 865 | V2: 1205 | W2: 944 | X2: 355 | Y2: 1250 | Z2: 380 | AA2: 0 | AB2: 700 | AC2: 410 | AD2: 910 | AE2: 710 | AF2: 490 | AG2: 170 | AH2: 143 | AI2: 630 | AJ2: 200 | AK2: 220 | AL2: 490 | AM2: 0 | AN2: 14 | AO2: 249 | AP2: 77 | AQ2: 16 | AR2: 5 | AS2: 6 | AT2: 9 | AU2: 6 | AV2: 7 | AW2: 7 | AX2: 10 | AY2: 2 | AZ2: 0 | BA2: 4 | BB2: 9 | BC2: 22 | BD2: 5 | BE2: 1 | BF2: 23 | BG2: 3 | BH2: 1 | BI2: 26 | BJ2: 1 | BK2: 0 | BL2: 11.7 | BM2: 94
A3: Maldives at Landaa Giraavaru | B3: 2 | C3: 10 | D3: 2021 | E3: 399 | F3: 5232 | G3: 5275 | H3: 2735 | I3: 7985 | J3: 1986 | K3: 3311 | L3: 11790 | M3: 1500 | N3: 2541 | O3: 1500 | P3: 701 | Q3: 570 | R3: 600 | S3: 370 | T3: 760 | U3: 660 | V3: 1000 | W3: 135 | X3: 360 | Y3: 1180 | Z3: 350 | AA3: 1770 | AB3: 700 | AC3: 450 | AD3: 910 | AE3: 880 | AF3: 440 | AG3: 170 | AH3: 109 | AI3: 620 | AJ3: 220 | AK3: 310 | AL3: 490 | AM3: 70 | AN3: 8 | AO3: 256 | AP3: 15 | AQ3: 15 | AR3: 4 | AS3: 5 | AT3: 10 | AU3: 6 | AV3: 6 | AW3: 7 | AX3: 10 | AY3: 2 | AZ3: 0 | BA3: 3 | BB3: 3 | BC3: 21 | BD3: 4 | BE3: 1 | BF3: 5 | BG3: 1 | BH3: 2 | BI3: 22 | BJ3: 1 | BK3: 1 | BL3: 15.5 | BM3: 119
A4: Maldives at Landaa Giraavaru | B4: 3 | C4: 10 | D4: 2021 | E4: 4555 | F4: 5467 | G4: 3209 | H4: 2624 | I4: 8069 | J4: 2234 | K4: 3865 | L4: 12898 | M4: 1500 | N4: 2753 | O4: 1500 | P4: 756 | Q4: 580 | R4: 1200 | S4: 410 | T4: 910 | U4: 730 | V4: 1400 | W4: 179 | X4: 400 | Y4: 1240 | Z4: 410 | AA4: 820 | AB4: 760 | AC4: 520 | AD4: 1080 | AE4: 870 | AF4: 445 | AG4: 190 | AH4: 120 | AI4: 640 | AJ4: 220 | AK4: 290 | AL4: 350 | AM4: 25 | AN4: 10 | AO4: 249 | AP4: 62 | AQ4: 16 | AR4: 7 | AS4: 7 | AT4: 10 | AU4: 7 | AV4: 9 | AW4: 7 | AX4: 11 | AY4: 3 | AZ4: 1 | BA4: 4 | BB4: 0 | BC4: 24 | BD4: 7 | BE4: 0 | BF4: 7 | BG4: 1 | BH4: 1 | BI4: 0 | BJ4: 2 | BK4: 8 | BL4: 19.4 | BM4: 156
A5: Maldives at Landaa Giraavaru | B5: 4 | C5: 10 | D5: 2021 | E5: 7287 | F5: 5758 | G5: 7157 | H5: 1595 | I5: 1497 | J5: 2208 | K5: 3858 | L5: 13231 | M5: 1500 | N5: 2550 | O5: 1500 | P5: 753 | Q5: 540 | R5: 700 | S5: 407 | T5: 980 | U5: 760 | V5: 1300 | W5: 151 | X5: 430 | Y5: 1180 | Z5: 410 | AA5: 760 | AB5: 770 | AC5: 440 | AD5: 1080 | AE5: 880 | AF5: 795 | AG5: 180 | AH5: 122 | AI5: 610 | AJ5: 210 | AK5: 400 | AL5: 650 | AM5: 11 | AN5: 62 | AO5: 222 | AP5: 45 | AQ5: 16 | AR5: 6 | AS5: 6 | AT5: 8 | AU5: 7 | AV5: 7 | AW5: 7 | AX5: 8 | AY5: 2 | AZ5: 0 | BA5: 10 | BB5: 3 | BC5: 20 | BD5: 4 | BE5: 1 | BF5: 9 | BG5: 2 | BH5: 2 | BI5: 0 | BJ5: 3 | BK5: 11 | BL5: 18.4 | BM5: 141
A6: Maldives at Landaa Giraavaru | B6: 5 | C6: 10 | D6: 2021 | E6: 4695 | F6: 10548 | G6: 2548 | H6: 27 | I6: 4675 | J6: 2083 | K6: 3329 | L6: 12533 | M6: 1600 | N6: 2609 | O6: 1400 | P6: 803 | Q6: 530 | R6: 1300 | S6: 376 | T6: 960 | U6: 670 | V6: 1400 | W6: 130 | X6: 420 | Y6: 1150 | Z6: 350 | AA6: 610 | AB6: 680 | AC6: 390 | AD6: 1000 | AE6: 750 | AF6: 510 | AG6: 170 | AH6: 138 | AI6: 590 | AJ6: 210 | AK6: 320 | AL6: 530 | AM6: 1 | AN6: 0 | AO6: 217 | AP6: 57 | AQ6: 21 | AR6: 6 | AS6: 8 | AT6: 9 | AU6: 5 | AV6: 4 | AW6: 9 | AX6: 8 | AY6: 1 | AZ6: 0 | BA6: 2 | BB6: 5 | BC6: 21 | BD6: 3 | BE6: 1 | BF6: 3 | BG6: 2 | BH6: 3 | BI6: 0 | BJ6: 2 | BK6: 0 | BL6: 18.4 | BM6: 131
A7: Maldives at Landaa Giraavaru | B7: 6 | C7: 10 | D7: 2021 | E7: 5576 | F7: 9782 | G7: 6770 | H7: 1524 | I7: 0 | J7: 2341 | K7: 4031 | L7: 12944 | M7: 1600 | N7: 2746 | O7: 1500 | P7: 809 | Q7: 600 | R7: 700 | S7: 379 | T7: 960 | U7: 730 | V7: 1300 | W7: 155 | X7: 430 | Y7: 1200 | Z7: 380 | AA7: 750 | AB7: 750 | AC7: 480 | AD7: 1280 | AE7: 860 | AF7: 650 | AG7: 190 | AH7: 138 | AI7: 610 | AJ7: 230 | AK7: 300 | AL7: 480 | AM7: 3 | AN7: 61 | AO7: 225 | AP7: 75 | AQ7: 10 | AR7: 5 | AS7: 8 | AT7: 8 | AU7: 7 | AV7: 9 | AW7: 4 | AX7: 12 | AY7: 3 | AZ7: 0 | BA7: 5 | BB7: 0 | BC7: 21 | BD7: 7 | BE7: 0 | BF7: 2 | BG7: 1 | BH7: 1 | BI7: 0 | BJ7: 2 | BK7: 5 | BL7: 14.6 | BM7: 122
A8: Maldives at Landaa Giraavaru | B8: 7 | C8: 10 | D8: 2021 | E8: 4603 | F8: 7514 | G8: 2259 | H8: 2657 | I8: 6969 | J8: 2355 | K8: 4044 | L8: 12706 | M8: 1600 | N8: 2711 | O8: 1500 | P8: 687 | Q8: 560 | R8: 1500 | S8: 393 | T8: 920 | U8: 770 | V8: 1200 | W8: 120 | X8: 460 | Y8: 1210 | Z8: 380 | AA8: 750 | AB8: 810 | AC8: 500 | AD8: 1290 | AE8: 880 | AF8: 650 | AG8: 180 | AH8: 129 | AI8: 640 | AJ8: 200 | AK8: 350 | AL8: 520 | AM8: 0 | AN8: 53 | AO8: 218 | AP8: 52 | AQ8: 15 | AR8: 6 | AS8: 5 | AT8: 10 | AU8: 7 | AV8: 7 | AW8: 7 | AX8: 11 | AY8: 1 | AZ8: 0 | BA8: 2 | BB8: 2 | BC8: 20 | BD8: 6 | BE8: 1 | BF8: 4 | BG8: 2 | BH8: 2 | BI8: 62 | BJ8: 1 | BK8: 3 | BL8: 15.5 | BM8: 134
A9: Maldives at Landaa Giraavaru | B9: 8 | C9: 10 | D9: 2021 | E9: 6403 | F9: 8568 | G9: 1552 | H9: 1657 | I9: 6348 | J9: 2472 | K9: 4490 | L9: 13014 | M9: 1700 | N9: 2815 | O9: 1400 | P9: 734 | Q9: 580 | R9: 800 | S9: 399 | T9: 990 | U9: 830 | V9: 1300 | W9: 163 | X9: 410 | Y9: 1210 | Z9: 470 | AA9: 850 | AB9: 840 | AC9: 550 | AD9: 1280 | AE9: 1130 | AF9: 680 | AG9: 250 | AH9: 132 | AI9: 650 | AJ9: 260 | AK9: 310 | AL9: 500 | AM9: 0 | AN9: 44 | AO9: 211 | AP9: 82 | AQ9: 17 | AR9: 4 | AS9: 2 | AT9: 10 | AU9: 5 | AV9: 6 | AW9: 7 | AX9: 9 | AY9: 2 | AZ9: 1 | BA9: 2 | BB9: 7 | BC9: 22 | BD9: 5 | BE9: 1 | BF9: 2 | BG9: 1 | BH9: 0 | BI9: 0 | BJ9: 2 | BK9: 4 | BL9: 17.5 | BM9: 126
A10: Maldives at Landaa Giraavaru | B10: 9 | C10: 10 | D10: 2021 | E10: 6008 | F10: 8114 | G10: 3348 | H10: 2157 | I10: 5773 | J10: 2526 | K10: 4139 | L10: 13392 | M10: 1600 | N10: 2794 | O10: 1800 | P10: 807 | Q10: 570 | R10: 1300 | S10: 420 | T10: 970 | U10: 860 | V10: 1200 | W10: 169 | X10: 410 | Y10: 1210 | Z10: 390 | AA10: 830 | AB10: 800 | AC10: 490 | AD10: 1390 | AE10: 1040 | AF10: 650 | AG10: 210 | AH10: 139 | AI10: 690 | AJ10: 230 | AK10: 250 | AL10: 460 | AM10: 3 | AN10: 106 | AO10: 212 | AP10: 26 | AQ10: 14 | AR10: 5 | AS10: 2 | AT10: 11 | AU10: 8 | AV10: 7 | AW10: 9 | AX10: 9 | AY10: 1 | AZ10: 2 | BA10: 7 | BB10: 0 | BC10: 23 | BD10: 6 | BE10: 0 | BF10: 4 | BG10: 2 | BH10: 1 | BI10: 0 | BJ10: 2 | BK10: 11 | BL10: 12.6 | BM10: 130
A11: Maldives at Landaa Giraavaru | B11: 10 | C11: 10 | D11: 2021 | E11: 2427 | F11: 9992 | G11: 5298 | H11: 1966 | I11: 5701 | J11: 2580 | K11: 4418 | L11: 13908 | M11: 1600 | N11: 2850 | O11: 1800 | P11: 832 | Q11: 590 | R11: 800 | S11: 447 | T11: 1010 | U11: 890 | V11: 1400 | W11: 156 | X11: 420 | Y11: 1190 | Z11: 430 | AA11: 990 | AB11: 720 | AC11: 460 | AD11: 1430 | AE11: 950 | AF11: 710 | AG11: 150 | AH11: 136 | AI11: 690 | AJ11: 220 | AK11: 330 | AL11: 480 | AM11: 0 | AN11: 65 | AO11: 219 | AP11: 90 | AQ11: 16 | AR11: 5 | AS11: 17 | AT11: 8 | AU11: 5 | AV11: 6 | AW11: 9 | AX11: 7 | AY11: 1 | AZ11: 0 | BA11: 2 | BB11: 1 | BC11: 23 | BD11: 0 | BE11: 1 | BF11: 4 | BG11: 2 | BH11: 3 | BI11: 45 | BJ11: 2 | BK11: 4 | BL11: 12.6 | BM11: 116
A12: Maldives at Landaa Giraavaru | B12: 11 | C12: 10 | D12: 2021 | E12: 8397 | F12: 5674 | G12: 422 | H12: 3230 | I12: 8392 | J12: 2400 | K12: 4486 | L12: 13888 | M12: 1500 | N12: 2797 | O12: 1700 | P12: 800 | Q12: 620 | R12: 1300 | S12: 428 | T12: 1000 | U12: 880 | V12: 1400 | W12: 157 | X12: 460 | Y12: 1200 | Z12: 400 | AA12: 890 | AB12: 720 | AC12: 510 | AD12: 1430 | AE12: 950 | AF12: 780 | AG12: 250 | AH12: 132 | AI12: 640 | AJ12: 240 | AK12: 330 | AL12: 530 | AM12: 0 | AN12: 91 | AO12: 209 | AP12: 72 | AQ12: 15 | AR12: 6 | AS12: 14 | AT12: 14 | AU12: 4 | AV12: 8 | AW12: 8 | AX12: 8 | AY12: 3 | AZ12: 3 | BA12: 8 | BB12: 3 | BC12: 25 | BD12: 4 | BE12: 0 | BF12: 7 | BG12: 3 | BH12: 1 | BI12: 12 | BJ12: 1 | BK12: 37 | BL12: 12.6 | BM12: 119
A13: Maldives at Landaa Giraavaru | B13: 12 | C13: 10 | D13: 2021 | E13: 8365 | F13: 6028 | G13: 0 | H13: 2611 | I13: 8364 | J13: 2579 | K13: 4633 | L13: 13425 | M13: 1600 | N13: 2758 | O13: 1600 | P13: 812 | Q13: 580 | R13: 800 | S13: 432 | T13: 990 | U13: 840 | V13: 1200 | W13: 151 | X13: 420 | Y13: 1250 | Z13: 410 | AA13: 860 | AB13: 750 | AC13: 630 | AD13: 1440 | AE13: 980 | AF13: 890 | AG13: 180 | AH13: 113 | AI13: 680 | AJ13: 190 | AK13: 300 | AL13: 520 | AM13: 0 | AN13: 61 | AO13: 275 | AP13: 80 | AQ13: 16 | AR13: 6 | AS13: 7 | AT13: 10 | AU13: 9 | AV13: 6 | AW13: 8 | AX13: 7 | AY13: 1 | AZ13: 0 | BA13: 8 | BB13: 6 | BC13: 24 | BD13: 5 | BE13: 1 | BF13: 8 | BG13: 2 | BH13: 2 | BI13: 12 | BJ13: 3 | BK13: 17 | BL13: 11.7 | BM13: 118
... A32: Maldives at Landaa Giraavaru | B32: 31 | C32: 10 | D32: 2021 | E32: 1772 | F32: 8540 | G32: 4461 | H32: 1022 | I32: 11241 | J32: 2721 | K32: 4505 | L32: 13894 | M32: 1600 | N32: 2897 | O32: 2200 | P32: 881 | Q32: 730 | R32: 1600 | S32: 442 | T32: 930 | U32: 900 | V32: 1000 | W32: 170 | X32: 440 | Y32: 1240 | Z32: 420 | AA32: 980 | AB32: 800 | AC32: 610 | AD32: 1300 | AE32: 790 | AF32: 770 | AG32: 180 | AH32: 0 | AI32: 730 | AJ32: 240 | AK32: 340 | AL32: 530 | AM32: 0 | AN32: 94 | AO32: 270 | AP32: 78 | AQ32: 21 | AR32: 5 | AS32: 9 | AT32: 11 | AU32: 7 | AV32: 7 | AW32: 9 | AX32: 7 | AY32: 3 | AZ32: 2 | BA32: 6 | BB32: 1 | BC32: 29 | BD32: 5 | BE32: 3 | BF32: 11 | BG32: 3 | BH32: 4 | BI32: 19 | BJ32: 1 | BK32: 2 | BL32: 31.1 | BM32: 195

Sheet Maldives at LG Daily
A2: Days | C2: Electricity Meter (KWh) | E2: Gas Kg | G2: GENSET NO 1 | H2: GENSET NO 2 | I2: GENSET NO 3 | J2: GENSET NO 4 | K2: GENSET NO 5 | L2: Main BLU FEEDER PANEL 1 | M2: Main BLU FEEDER PANEL 2 | N2: Main POWER HOUSE FEEDER PANEL NO:3 | O2: Main Kitchen -7 | P2: Main Kitchen -10 | Q2: Water treatment Plant | R2: Sewage treatment Plant | S2: Laundry--8SSB (Machineries) | T2: Laundry-9 (HR/Tuck Shop Building) | U2: New staff accomodation (E0) | V2: Staff block-16(E2-E3) | W2: Staff Block Feeder-3(E4-E5) | X2: Management block-5 (M1 to M6) | Y2: SNR STAFF BLOCK (PC Block) | Z2: BOAT DOCK FEEDER - 22 | AA2: RECEPTION Building Full (Finance/Reservation) | AB2: DIVE CENTER (Inc MDC and Recreation) | AC2: 301-307 | AD2: 308-314 | AE2: 315-320 | AF2: 401-407 | AG2: 408-414 | AH2: 415-420 | AI2: SPA - 1 | AJ2: SPA - 2 | AK2: BLU KITCHEN - 1 | AL2: BLU KITCHEN - 2 | AM2: AL BARAKATH | AN2: STAFF KITCHEN | AO2: Water m3 | AQ2: R/O Plant A | AR2: R/O Plant B | AS2: R/O Plant C | AT2: R/O Plant D | AU2: Laundry | AV2: Staff Block - E0 | AW2: Staff Block - E1 | AX2: Staff Block - E2 | AY2: Staff Block - E3 | AZ2: Staff Block - E4 | BA2: Staff Block - E5 | BB2: Management Block | BC2: PC Block | BD2: GM Bungalow | BE2: Boat Dock | BF2: Supply Jetty | BG2: Main Kitchen | BH2: Day Facility | BI2: Reception | BJ2: Main Pool | BK2: Dive Center | BL2: Albarakthu | BM2: Blu Resturant | BN2: Main Jetty | BO2: Landaa Estate
A3: Date | C3: Reading KWH | D3: Difference KWH | E3: Reading Kg | F3: Difference Kg | G3: KWh | H3: KWh | I3: KWh | J3: KWh | K3: KWh | L3: KWh | M3: KWh | N3: KWh | O3: KWh | P3: KWh | Q3: KWh | R3: KWh | S3: KWh | T3: KWh | U3: KWh | V3: KWh | W3: KWh | X3: KWh | Y3: KWh | Z3: KWh | AA3: KWh | AB3: KWh | AC3: KWh | AD3: KWh | AE3: KWh | AF3: KWh | AG3: KWh | AH3: KWh | AI3: KWh | AJ3: KWh | AK3: KWh | AL3: KWh | AM3: KWh | AN3: KWh | AO3: Reading m³ | AP3: Daily Consumption m³ | AQ3: Daily Consumption m³ | AR3: Daily Consumption m³ | AS3: Daily Consumption m³ | AT3: Daily Consumption m³ | AU3: Daily Consumption m³ | AV3: Daily Consumption m³ | AW3: Daily Consumption m³ | AX3: Daily Consumption m³ | AY3: Daily Consumption m³ | AZ3: Daily Consumption m³ | BA3: Daily Consumption m³ | BB3: Daily Consumption m³ | BC3: Daily Consumption m³ | BD3: Daily Consumption m³ | BE3: Daily Consumption m³ | BF3: Daily Consumption m³ | BG3: Daily Consumption m³ | BH3: Daily Consumption m³ | BI3: Daily Consumption m³ | BJ3: Daily Consumption m³ | BK3: Daily Consumption m³ | BL3: Daily Consumption m³ | BM3: Daily Consumption m³ | BN3: Daily Consumption m³ | BO3: Daily Consumption m³ | BP3: ROOM NIGHTS | BQ3: Total Food Covers
A4: 44469 | C4: 93663559 | D4: 31701 | F4: 90 | AO4: 1003522 | AP4: 318 | BP4: ='[1]Room Nights and Food Covers'!B4 -> 14.6 | BQ4: ='[1]Room Nights and Food Covers'!C4 -> 159
A5: =A4+1 -> 44470 | C5: =SUM('GENSET #1'!C10+'GENSET #2'!C10+'GENSET #3'!C10+'GENSET #4'!C10+'GENSET #5'!C10) -> 93687010 | D5: =IF((C5-C4<0), "0",C5-C4) -> 23451 | E5: ='Gas-2'!G6 -> 180 | F5: =IF((E5-E4<0), "0",E5-E4) -> 180 | G5: ='GENSET #1'!D10 -> 11980 | H5: ='GENSET #2'!D10 -> 0 | I5: ='GENSET #3'!D10 -> 0 | J5: ='GENSET #4'!D10 -> 1797 | K5: ='GENSET #5'!D10 -> 9674 | L5: ='FEEDER Consumption '!E5 -> 2022 | M5: ='FEEDER Consumption '!J5 -> 3360 | N5: ='FEEDER Consumption '!O5 -> 13461 | O5: ='FEEDER Consumption '!T5 -> 1500 | P5: ='FEEDER Consumption '!Y5 -> 2615 | Q5: ='FEEDER Consumption '!AD5 -> 1500 | R5: ='FEEDER Consumption '!AI5 -> 796 | S5: ='FEEDER Consumption '!AN5 -> 580 | T5: ='FEEDER Consumption '!AS5 -> 785 | U5: ='FEEDER Consumption '!AX5 -> 443 | V5: ='FEEDER Consumption '!BH5 -> 865 | W5: ='FEEDER Consumption '!BH5 -> 865 | X5: ='FEEDER Consumption '!BM5 -> 1205 | Y5: ='FEEDER Consumption '!BR5 -> 944 | Z5: ='FEEDER Consumption '!BW5 -> 355 | AA5: ='FEEDER Consumption '!CB5 -> 1250 | AB5: ='FEEDER Consumption '!CG5 -> 380 | AC5: ='FEEDER Consumption '!CL5 -> 0 | AD5: ='FEEDER Consumption '!CQ5 -> 700 | AE5: ='FEEDER Consumption '!CV5 -> 410 | AF5: ='FEEDER Consumption '!DA5 -> 910 | AG5: ='FEEDER Consumption '!DF5 -> 710 | AH5: ='FEEDER Consumption '!DK5 -> 490 | AI5: ='FEEDER Consumption '!DP5 -> 170 | AJ5: ='FEEDER Consumption '!DU5 -> 143 | AK5: ='FEEDER Consumption '!DZ5 -> 630 | AL5: ='FEEDER Consumption '!EE5 -> 200 | AM5: ='FEEDER Consumption '!EJ5 -> 220 | AN5: ='FEEDER Consumption '!EO5 -> 490 | AO5: =SUM(WATER!C6+WATER!H6+WATER!M6+WATER!R6) -> 1003862 | AP5: =IF((AO5-AO4<0), "0",AO5-AO4) -> 340 | AQ5: =WATER!D6 -> 0 | AR5: =[1]WATER!I6 -> 0 | AS5: =[1]WATER!N6 -> 190 | AT5: =[1]WATER!S6 -> 10 | AU5: =[1]WATER!AD6 -> 18 | AV5: =[1]WATER!AI6 -> 6 | AW5: =[1]WATER!AN6 -> 0 | AX5: =[1]WATER!AS6 -> 10 | AY5: =[1]WATER!AX6 -> 8 | AZ5: =[1]WATER!BC6 -> 7 | BA5: =[1]WATER!BH6 -> 10 | BB5: =[1]WATER!BM6 -> 5 | BC5: =[1]WATER!BR6 -> 1 | BD5: =[1]WATER!BW6 -> 0 | BE5: =[1]WATER!CB6 -> 4 | BF5: =[1]WATER!CG6 -> 1 | BG5: =[1]WATER!CL6 -> 24 | BH5: =[1]WATER!CQ6 -> 7 | BI5: =[1]WATER!CV6 -> 0 | BJ5: =[1]WATER!DA6 -> 1 | BK5: =[1]WATER!DF6 -> 1 | BL5: =[1]WATER!DK6 -> 0 | BM5: =[1]WATER!DP6 -> 7 | BN5: =[1]WATER!DU6 -> 0 | BO5: =[1]WATER!DZ6 -> 0 | BP5: ='[1]Room Nights and Food Covers'!B5 -> 11.7 | BQ5: ='[1]Room Nights and Food Covers'!C5 -> 94
A6: =A5+1 -> 44471 | C6: =SUM('GENSET #1'!C11+'GENSET #2'!C11+'GENSET #3'!C11+'GENSET #4'!C11+'GENSET #5'!C11) -> 93708636 | D6: =IF((C6-C5<0), "0",C6-C5) -> 21626 | E6: ='Gas-2'!G7 -> 225 | F6: =IF((E6-E5<0), "0",E6-E5) -> 45 | G6: ='GENSET #1'!D11 -> 399 | H6: ='GENSET #2'!D11 -> 5232 | I6: ='GENSET #3'!D11 -> 5275 | J6: ='GENSET #4'!D11 -> 2735 | K6: ='GENSET #5'!D11 -> 7985 | L6: ='FEEDER Consumption '!E6 -> 1986 | M6: ='FEEDER Consumption '!J6 -> 3311 | N6: ='FEEDER Consumption '!O6 -> 11790 | O6: ='FEEDER Consumption '!T6 -> 1500 | P6: ='FEEDER Consumption '!Y6 -> 2541 | Q6: ='FEEDER Consumption '!AD6 -> 1500 | R6: ='FEEDER Consumption '!AI6 -> 701 | S6: ='FEEDER Consumption '!AN6 -> 570 | T6: ='FEEDER Consumption '!AS6 -> 600 | U6: ='FEEDER Consumption '!AX6 -> 370 | V6: ='FEEDER Consumption '!BH6 -> 660 | W6: ='FEEDER Consumption '!BH6 -> 660 | X6: ='FEEDER Consumption '!BM6 -> 1000 | Y6: ='FEEDER Consumption '!BR6 -> 135 | Z6: ='FEEDER Consumption '!BW6 -> 360 | AA6: ='FEEDER Consumption '!CB6 -> 1180 | AB6: ='FEEDER Consumption '!CG6 -> 350 | AC6: ='FEEDER Consumption '!CL6 -> 1770 | AD6: ='FEEDER Consumption '!CQ6 -> 700 | AE6: ='FEEDER Consumption '!CV6 -> 450 | AF6: ='FEEDER Consumption '!DA6 -> 910 | AG6: ='FEEDER Consumption '!DF6 -> 880 | AH6: ='FEEDER Consumption '!DK6 -> 440 | AI6: ='FEEDER Consumption '!DP6 -> 170 | AJ6: ='FEEDER Consumption '!DU6 -> 109 | AK6: ='FEEDER Consumption '!DZ6 -> 620 | AL6: ='FEEDER Consumption '!EE6 -> 220 | AM6: ='FEEDER Consumption '!EJ6 -> 310 | AN6: ='FEEDER Consumption '!EO6 -> 490 | AO6: =SUM(WATER!C7+WATER!H7+WATER!M7+WATER!R7) -> 1004211 | AP6: =IF((AO6-AO5<0), "0",AO6-AO5) -> 349 | AQ6: =[1]WATER!D7 -> 71 | AR6: =[1]WATER!I7 -> 0 | AS6: =[1]WATER!N7 -> 143 | AT6: =[1]WATER!S7 -> 113 | AU6: =[1]WATER!AD7 -> 17 | AV6: =[1]WATER!AI7 -> 13 | AW6: =[1]WATER!AN7 -> 16 | AX6: =[1]WATER!AS7 -> 12 | AY6: =[1]WATER!AX7 -> 7 | AZ6: =[1]WATER!BC7 -> 7 | BA6: =[1]WATER!BH7 -> 10 | BB6: =[1]WATER!BM7 -> 10 | BC6: =[1]WATER!BR7 -> 1 | BD6: =[1]WATER!BW7 -> 1 | BE6: =[1]WATER!CB7 -> 5 | BF6: =[1]WATER!CG7 -> 1 | BG6: =[1]WATER!CL7 -> 22 | BH6: =[1]WATER!CQ7 -> 8 | BI6: =[1]WATER!CV7 -> 1 | BJ6: =[1]WATER!DA7 -> 1 | BK6: =[1]WATER!DF7 -> 2 | BL6: =[1]WATER!DK7 -> 5 | BM6: =[1]WATER!DP7 -> 5 | BN6: =[1]WATER!DU7 -> 1 | BO6: =[1]WATER!DZ7 -> 2 | BP6: ='[1]Room Nights and Food Covers'!B6 -> 15.5 | BQ6: ='[1]Room Nights and Food Covers'!C6 -> 119
A7: =A6+1 -> 44472 | C7: =SUM('GENSET #1'!C12+'GENSET #2'!C12+'GENSET #3'!C12+'GENSET #4'!C12+'GENSET #5'!C12) -> 93732560 | D7: =IF((C7-C6<0), "0",C7-C6) -> 23924 | E7: ='Gas-2'!G8 -> 225 | F7: =IF((E7-E6<0), "0",E7-E6) -> 0 | G7: ='GENSET #1'!D12 -> 4555 | H7: ='GENSET #2'!D12 -> 5467 | I7: ='GENSET #3'!D12 -> 3209 | J7: ='GENSET #4'!D12 -> 2624 | K7: ='GENSET #5'!D12 -> 8069 | L7: ='FEEDER Consumption '!E7 -> 2234 | M7: ='FEEDER Consumption '!J7 -> 3865 | N7: ='FEEDER Consumption '!O7 -> 12898 | O7: ='FEEDER Consumption '!T7 -> 1500 | P7: ='FEEDER Consumption '!Y7 -> 2753 | Q7: ='FEEDER Consumption '!AD7 -> 1500 | R7: ='FEEDER Consumption '!AI7 -> 756 | S7: ='FEEDER Consumption '!AN7 -> 580 | T7: ='FEEDER Consumption '!AS7 -> 1200 | U7: ='FEEDER Consumption '!AX7 -> 410 | V7: ='FEEDER Consumption '!BH7 -> 730 | W7: ='FEEDER Consumption '!BH7 -> 730 | X7: ='FEEDER Consumption '!BM7 -> 1400 | Y7: ='FEEDER Consumption '!BR7 -> 179 | Z7: ='FEEDER Consumption '!BW7 -> 400 | AA7: ='FEEDER Consumption '!CB7 -> 1240 | AB7: ='FEEDER Consumption '!CG7 -> 410 | AC7: ='FEEDER Consumption '!CL7 -> 820 | AD7: ='FEEDER Consumption '!CQ7 -> 760 | AE7: ='FEEDER Consumption '!CV7 -> 520 | AF7: ='FEEDER Consumption '!DA7 -> 1080 | AG7: ='FEEDER Consumption '!DF7 -> 870 | AH7: ='FEEDER Consumption '!DK7 -> 445 | AI7: ='FEEDER Consumption '!DP7 -> 190 | AJ7: ='FEEDER Consumption '!DU7 -> 120 | AK7: ='FEEDER Consumption '!DZ7 -> 640 | AL7: ='FEEDER Consumption '!EE7 -> 220 | AM7: ='FEEDER Consumption '!EJ7 -> 290 | AN7: ='FEEDER Consumption '!EO7 -> 350 | AO7: =SUM(WATER!C8+WATER!H8+WATER!M8+WATER!R8) -> 1004557 | AP7: =IF((AO7-AO6<0), "0",AO7-AO6) -> 346 | AQ7: =[1]WATER!D8 -> 65 | AR7: =[1]WATER!I8 -> 0 | AS7: =[1]WATER!N8 -> 197 | AT7: =[1]WATER!S8 -> 109 | AU7: =[1]WATER!AD8 -> 18 | AV7: =[1]WATER!AI8 -> 4 | AW7: =[1]WATER!AN8 -> 9 | AX7: =[1]WATER!AS8 -> 11 | AY7: =[1]WATER!AX8 -> 7 | AZ7: =[1]WATER!BC8 -> 8 | BA7: =[1]WATER!BH8 -> 0 | BB7: =[1]WATER!BM8 -> 8 | BC7: =[1]WATER!BR8 -> 0 | BD7: =[1]WATER!BW8 -> 0 | BE7: =[1]WATER!CB8 -> 4 | BF7: =[1]WATER!CG8 -> 1 | BG7: =[1]WATER!CL8 -> 26 | BH7: =[1]WATER!CQ8 -> 7 | BI7: =[1]WATER!CV8 -> 0 | BJ7: =[1]WATER!DA8 -> 0 | BK7: =[1]WATER!DF8 -> 3 | BL7: =[1]WATER!DK8 -> 3 | BM7: =[1]WATER!DP8 -> 0 | BN7: =[1]WATER!DU8 -> 1 | BO7: =[1]WATER!DZ8 -> 1 | BP7: ='[1]Room Nights and Food Covers'!B7 -> 19.4 | BQ7: ='[1]Room Nights and Food Covers'!C7 -> 156
A8: =A7+1 -> 44473 | C8: =SUM('GENSET #1'!C13+'GENSET #2'!C13+'GENSET #3'!C13+'GENSET #4'!C13+'GENSET #5'!C13) -> 93755854 | D8: =IF((C8-C7<0), "0",C8-C7) -> 23294 | E8: ='Gas-2'!G9 -> 225 | F8: =IF((E8-E7<0), "0",E8-E7) -> 0 | G8: ='GENSET #1'!D13 -> 7287 | H8: ='GENSET #2'!D13 -> 5758 | I8: ='GENSET #3'!D13 -> 7157 | J8: ='GENSET #4'!D13 -> 1595 | K8: ='GENSET #5'!D13 -> 1497 | L8: ='FEEDER Consumption '!E8 -> 2208 | M8: ='FEEDER Consumption '!J8 -> 3858 | N8: ='FEEDER Consumption '!O8 -> 13231 | O8: ='FEEDER Consumption '!T8 -> 1500 | P8: ='FEEDER Consumption '!Y8 -> 2550 | Q8: ='FEEDER Consumption '!AD8 -> 1500 | R8: ='FEEDER Consumption '!AI8 -> 753 | S8: ='FEEDER Consumption '!AN8 -> 540 | T8: ='FEEDER Consumption '!AS8 -> 700 | U8: ='FEEDER Consumption '!AX8 -> 407 | V8: ='FEEDER Consumption '!BH8 -> 760 | W8: ='FEEDER Consumption '!BH8 -> 760 | X8: ='FEEDER Consumption '!BM8 -> 1300 | Y8: ='FEEDER Consumption '!BR8 -> 151 | Z8: ='FEEDER Consumption '!BW8 -> 430 | AA8: ='FEEDER Consumption '!CB8 -> 1180 | AB8: ='FEEDER Consumption '!CG8 -> 410 | AC8: ='FEEDER Consumption '!CL8 -> 760 | AD8: ='FEEDER Consumption '!CQ8 -> 770 | AE8: ='FEEDER Consumption '!CV8 -> 440 | AF8: ='FEEDER Consumption '!DA8 -> 1080 | AG8: ='FEEDER Consumption '!DF8 -> 880 | AH8: ='FEEDER Consumption '!DK8 -> 795 | AI8: ='FEEDER Consumption '!DP8 -> 180 | AJ8: ='FEEDER Consumption '!DU8 -> 122 | AK8: ='FEEDER Consumption '!DZ8 -> 610 | AL8: ='FEEDER Consumption '!EE8 -> 210 | AM8: ='FEEDER Consumption '!EJ8 -> 400 | AN8: ='FEEDER Consumption '!EO8 -> 650 | AO8: =SUM(WATER!C9+WATER!H9+WATER!M9+WATER!R9) -> 1004897 | AP8: =IF((AO8-AO7<0), "0",AO8-AO7) -> 340 | AQ8: =[1]WATER!D9 -> 66 | AR8: =[1]WATER!I9 -> 0 | AS8: =[1]WATER!N9 -> 179 | AT8: =[1]WATER!S9 -> 94 | AU8: =[1]WATER!AD9 -> 17 | AV8: =[1]WATER!AI9 -> 5 | AW8: =[1]WATER!AN9 -> 9 | AX8: =[1]WATER!AS9 -> 10 | AY8: =[1]WATER!AX9 -> 7 | AZ8: =[1]WATER!BC9 -> 7 | BA8: =[1]WATER!BH9 -> 0 | BB8: =[1]WATER!BM9 -> 7 | BC8: =[1]WATER!BR9 -> 4 | BD8: =[1]WATER!BW9 -> 0 | BE8: =[1]WATER!CB9 -> 6 | BF8: =[1]WATER!CG9 -> 5 | BG8: =[1]WATER!CL9 -> 24 | BH8: =[1]WATER!CQ9 -> 7 | BI8: =[1]WATER!CV9 -> 1 | BJ8: =[1]WATER!DA9 -> 0 | BK8: =[1]WATER!DF9 -> 2 | BL8: =[1]WATER!DK9 -> 5 | BM8: =[1]WATER!DP9 -> 50 | BN8: =[1]WATER!DU9 -> 1 | BO8: =[1]WATER!DZ9 -> 2 | BP8: ='[1]Room Nights and Food Covers'!B8 -> 18.4 | BQ8: ='[1]Room Nights and Food Covers'!C8 -> 141
A9: =A8+1 -> 44474 | C9: =SUM('GENSET #1'!C14+'GENSET #2'!C14+'GENSET #3'!C14+'GENSET #4'!C14+'GENSET #5'!C14) -> 93778347 | D9: =IF((C9-C8<0), "0",C9-C8) -> 22493 | E9: ='Gas-2'!G10 -> 225 | F9: =IF((E9-E8<0), "0",E9-E8) -> 0 | G9: ='GENSET #1'!D14 -> 4695 | H9: ='GENSET #2'!D14 -> 10548 | I9: ='GENSET #3'!D14 -> 2548 | J9: ='GENSET #4'!D14 -> 27 | K9: ='GENSET #5'!D14 -> 4675 | L9: ='FEEDER Consumption '!E9 -> 2083 | M9: ='FEEDER Consumption '!J9 -> 3329 | N9: ='FEEDER Consumption '!O9 -> 12533 | O9: ='FEEDER Consumption '!T9 -> 1600 | P9: ='FEEDER Consumption '!Y9 -> 2609 | Q9: ='FEEDER Consumption '!AD9 -> 1400 | R9: ='FEEDER Consumption '!AI9 -> 803 | S9: ='FEEDER Consumption '!AN9 -> 530 | T9: ='FEEDER Consumption '!AS9 -> 1300 | U9: ='FEEDER Consumption '!AX9 -> 376 | V9: ='FEEDER Consumption '!BH9 -> 670 | W9: ='FEEDER Consumption '!BH9 -> 670 | X9: ='FEEDER Consumption '!BM9 -> 1400 | Y9: ='FEEDER Consumption '!BR9 -> 130 | Z9: ='FEEDER Consumption '!BW9 -> 420 | AA9: ='FEEDER Consumption '!CB9 -> 1150 | AB9: ='FEEDER Consumption '!CG9 -> 350 | AC9: ='FEEDER Consumption '!CL9 -> 610 | AD9: ='FEEDER Consumption '!CQ9 -> 680 | AE9: ='FEEDER Consumption '!CV9 -> 390 | AF9: ='FEEDER Consumption '!DA9 -> 1000 | AG9: ='FEEDER Consumption '!DF9 -> 750 | AH9: ='FEEDER Consumption '!DK9 -> 510 | AI9: ='FEEDER Consumption '!DP9 -> 170 | AJ9: ='FEEDER Consumption '!DU9 -> 138 | AK9: ='FEEDER Consumption '!DZ9 -> 590 | AL9: ='FEEDER Consumption '!EE9 -> 210 | AM9: ='FEEDER Consumption '!EJ9 -> 320 | AN9: ='FEEDER Consumption '!EO9 -> 530 | AO9: =SUM(WATER!C10+WATER!H10+WATER!M10+WATER!R10) -> 1005172 | AP9: =IF((AO9-AO8<0), "0",AO9-AO8) -> 275 | AQ9: =[1]WATER!D10 -> 70 | AR9: =[1]WATER!I10 -> 0 | AS9: =[1]WATER!N10 -> 179 | AT9: =[1]WATER!S10 -> 85 | AU9: =[1]WATER!AD10 -> 18 | AV9: =[1]WATER!AI10 -> 5 | AW9: =[1]WATER!AN10 -> 8 | AX9: =[1]WATER!AS10 -> 10 | AY9: =[1]WATER!AX10 -> 7 | AZ9: =[1]WATER!BC10 -> 8 | BA9: =[1]WATER!BH10 -> 19 | BB9: =[1]WATER!BM10 -> 7 | BC9: =[1]WATER!BR10 -> 1 | BD9: =[1]WATER!BW10 -> 1 | BE9: =[1]WATER!CB10 -> 4 | BF9: =[1]WATER!CG10 -> 2 | BG9: =[1]WATER!CL10 -> 27 | BH9: =[1]WATER!CQ10 -> 7 | BI9: =[1]WATER!CV10 -> 1 | BJ9: =[1]WATER!DA10 -> 3 | BK9: =[1]WATER!DF10 -> 3 | BL9: =[1]WATER!DK10 -> 9 | BM9: =[1]WATER!DP10 -> 0 | BN9: =[1]WATER!DU10 -> 10 | BO9: =[1]WATER!DZ10 -> 3 | BP9: ='[1]Room Nights and Food Covers'!B9 -> 18.4 | BQ9: ='[1]Room Nights and Food Covers'!C9 -> 131
A10: =A9+1 -> 44475 | C10: =SUM('GENSET #1'!C15+'GENSET #2'!C15+'GENSET #3'!C15+'GENSET #4'!C15+'GENSET #5'!C15) -> 93801999 | D10: =IF((C10-C9<0), "0",C10-C9) -> 23652 | E10: ='Gas-2'!G11 -> 225 | F10: =IF((E10-E9<0), "0",E10-E9) -> 0 | G10: ='GENSET #1'!D15 -> 5576 | H10: ='GENSET #2'!D15 -> 9782 | I10: ='GENSET #3'!D15 -> 6770 | J10: ='GENSET #4'!D15 -> 1524 | K10: ='GENSET #5'!D15 -> 0 | L10: ='FEEDER Consumption '!E10 -> 2341 | M10: ='FEEDER Consumption '!J10 -> 4031 | N10: ='FEEDER Consumption '!O10 -> 12944 | O10: ='FEEDER Consumption '!T10 -> 1600 | P10: ='FEEDER Consumption '!Y10 -> 2746 | Q10: ='FEEDER Consumption '!AD10 -> 1500 | R10: ='FEEDER Consumption '!AI10 -> 809 | S10: ='FEEDER Consumption '!AN10 -> 600 | T10: ='FEEDER Consumption '!AS10 -> 700 | U10: ='FEEDER Consumption '!AX10 -> 379 | V10: ='FEEDER Consumption '!BH10 -> 730 | W10: ='FEEDER Consumption '!BH10 -> 730 | X10: ='FEEDER Consumption '!BM10 -> 1300 | Y10: ='FEEDER Consumption '!BR10 -> 155 | Z10: ='FEEDER Consumption '!BW10 -> 430 | AA10: ='FEEDER Consumption '!CB10 -> 1200 | AB10: ='FEEDER Consumption '!CG10 -> 380 | AC10: ='FEEDER Consumption '!CL10 -> 750 | AD10: ='FEEDER Consumption '!CQ10 -> 750 | AE10: ='FEEDER Consumption '!CV10 -> 480 | AF10: ='FEEDER Consumption '!DA10 -> 1280 | AG10: ='FEEDER Consumption '!DF10 -> 860 | AH10: ='FEEDER Consumption '!DK10 -> 650 | AI10: ='FEEDER Consumption '!DP10 -> 190 | AJ10: ='FEEDER Consumption '!DU10 -> 138 | AK10: ='FEEDER Consumption '!DZ10 -> 610 | AL10: ='FEEDER Consumption '!EE10 -> 230 | AM10: ='FEEDER Consumption '!EJ10 -> 300 | AN10: ='FEEDER Consumption '!EO10 -> 480 | AO10: =SUM(WATER!C11+WATER!H11+WATER!M11+WATER!R11) -> 1005536 | AP10: =IF((AO10-AO9<0), "0",AO10-AO9) -> 364 | AQ10: =[1]WATER!D11 -> 52 | AR10: =[1]WATER!I11 -> 0 | AS10: =[1]WATER!N11 -> 200 | AT10: =[1]WATER!S11 -> 69 | AU10: =[1]WATER!AD11 -> 20 | AV10: =[1]WATER!AI11 -> 6 | AW10: =[1]WATER!AN11 -> 9 | AX10: =[1]WATER!AS11 -> 12 | AY10: =[1]WATER!AX11 -> 7 | AZ10: =[1]WATER!BC11 -> 7 | BA10: =[1]WATER!BH11 -> 7 | BB10: =[1]WATER!BM11 -> 8 | BC10: =[1]WATER!BR11 -> 2 | BD10: =[1]WATER!BW11 -> -1 | BE10: =[1]WATER!CB11 -> 4 | BF10: =[1]WATER!CG11 -> 1 | BG10: =[1]WATER!CL11 -> 24 | BH10: =[1]WATER!CQ11 -> 7 | BI10: =[1]WATER!CV11 -> 0 | BJ10: =[1]WATER!DA11 -> 3 | BK10: =[1]WATER!DF11 -> 4 | BL10: =[1]WATER!DK11 -> 4 | BM10: =[1]WATER!DP11 -> 38 | BN10: =[1]WATER!DU11 -> 1 | BO10: =[1]WATER!DZ11 -> 2 | BP10: ='[1]Room Nights and Food Covers'!B10 -> 14.6 | BQ10: ='[1]Room Nights and Food Covers'!C10 -> 122
A11: =A10+1 -> 44476 | C11: =SUM('GENSET #1'!C16+'GENSET #2'!C16+'GENSET #3'!C16+'GENSET #4'!C16+'GENSET #5'!C16) -> 93826001 | D11: =IF((C11-C10<0), "0",C11-C10) -> 24002 | E11: ='Gas-2'!G12 -> 270 | F11: =IF((E11-E10<0), "0",E11-E10) -> 45 | G11: ='GENSET #1'!D16 -> 4603 | H11: ='GENSET #2'!D16 -> 7514 | I11: ='GENSET #3'!D16 -> 2259 | J11: ='GENSET #4'!D16 -> 2657 | K11: ='GENSET #5'!D16 -> 6969 | L11: ='FEEDER Consumption '!E11 -> 2355 | M11: ='FEEDER Consumption '!J11 -> 4044 | N11: ='FEEDER Consumption '!O11 -> 12706 | O11: ='FEEDER Consumption '!T11 -> 1600 | P11: ='FEEDER Consumption '!Y11 -> 2711 | Q11: ='FEEDER Consumption '!AD11 -> 1500 | R11: ='FEEDER Consumption '!AI11 -> 687 | S11: ='FEEDER Consumption '!AN11 -> 560 | T11: ='FEEDER Consumption '!AS11 -> 1500 | U11: ='FEEDER Consumption '!AX11 -> 393 | V11: ='FEEDER Consumption '!BH11 -> 770 | W11: ='FEEDER Consumption '!BH11 -> 770 | X11: ='FEEDER Consumption '!BM11 -> 1200 | Y11: ='FEEDER Consumption '!BR11 -> 120 | Z11: ='FEEDER Consumption '!BW11 -> 460 | AA11: ='FEEDER Consumption '!CB11 -> 1210 | AB11: ='FEEDER Consumption '!CG11 -> 380 | AC11: ='FEEDER Consumption '!CL11 -> 750 | AD11: ='FEEDER Consumption '!CQ11 -> 810 | AE11: ='FEEDER Consumption '!CV11 -> 500 | AF11: ='FEEDER Consumption '!DA11 -> 1290 | AG11: ='FEEDER Consumption '!DF11 -> 880 | AH11: ='FEEDER Consumption '!DK11 -> 650 | AI11: ='FEEDER Consumption '!DP11 -> 180 | AJ11: ='FEEDER Consumption '!DU11 -> 129 | AK11: ='FEEDER Consumption '!DZ11 -> 640 | AL11: ='FEEDER Consumption '!EE11 -> 200 | AM11: ='FEEDER Consumption '!EJ11 -> 350 | AN11: ='FEEDER Consumption '!EO11 -> 520 | AO11: =SUM(WATER!C12+WATER!H12+WATER!M12+WATER!R12) -> 1005859 | AP11: =IF((AO11-AO10<0), "0",AO11-AO10) -> 323 | AQ11: =[1]WATER!D12 -> 71 | AR11: =[1]WATER!I12 -> 0 | AS11: =[1]WATER!N12 -> 214 | AT11: =[1]WATER!S12 -> 97 | AU11: =[1]WATER!AD12 -> 18 | AV11: =[1]WATER!AI12 -> 6 | AW11: =[1]WATER!AN12 -> 9 | AX11: =[1]WATER!AS12 -> 11 | AY11: =[1]WATER!AX12 -> 8 | AZ11: =[1]WATER!BC12 -> 7 | BA11: =[1]WATER!BH12 -> 7 | BB11: =[1]WATER!BM12 -> 8 | BC11: =[1]WATER!BR12 -> 2 | BD11: =[1]WATER!BW12 -> 2 | BE11: =[1]WATER!CB12 -> 8 | BF11: =[1]WATER!CG12 -> 4 | BG11: =[1]WATER!CL12 -> 25 | BH11: =[1]WATER!CQ12 -> 7 | BI11: =[1]WATER!CV12 -> 1 | BJ11: =[1]WATER!DA12 -> 3 | BK11: =[1]WATER!DF12 -> 3 | BL11: =[1]WATER!DK12 -> 4 | BM11: =[1]WATER!DP12 -> 38 | BN11: =[1]WATER!DU12 -> 2 | BO11: =[1]WATER!DZ12 -> 1 | BP11: ='[1]Room Nights and Food Covers'!B11 -> 15.5 | BQ11: ='[1]Room Nights and Food Covers'!C11 -> 134
A12: =A11+1 -> 44477 | C12: =SUM('GENSET #1'!C17+'GENSET #2'!C17+'GENSET #3'!C17+'GENSET #4'!C17+'GENSET #5'!C17) -> 93850529 | D12: =IF((C12-C11<0), "0",C12-C11) -> 24528 | E12: ='Gas-2'!G13 -> 225 | F12: =IF((E12-E11<0), "0",E12-E11) -> 0 | G12: ='GENSET #1'!D17 -> 6403 | H12: ='GENSET #2'!D17 -> 8568 | I12: ='GENSET #3'!D17 -> 1552 | J12: ='GENSET #4'!D17 -> 1657 | K12: ='GENSET #5'!D17 -> 6348 | L12: ='FEEDER Consumption '!E12 -> 2472 | M12: ='FEEDER Consumption '!J12 -> 4490 | N12: ='FEEDER Consumption '!O12 -> 13014 | O12: ='FEEDER Consumption '!T12 -> 1700 | P12: ='FEEDER Consumption '!Y12 -> 2815 | Q12: ='FEEDER Consumption '!AD12 -> 1400 | R12: ='FEEDER Consumption '!AI12 -> 734 | S12: ='FEEDER Consumption '!AN12 -> 580 | T12: ='FEEDER Consumption '!AS12 -> 800 | U12: ='FEEDER Consumption '!AX12 -> 399 | V12: ='FEEDER Consumption '!BH12 -> 830 | W12: ='FEEDER Consumption '!BH12 -> 830 | X12: ='FEEDER Consumption '!BM12 -> 1300 | Y12: ='FEEDER Consumption '!BR12 -> 163 | Z12: ='FEEDER Consumption '!BW12 -> 410 | AA12: ='FEEDER Consumption '!CB12 -> 1210 | AB12: ='FEEDER Consumption '!CG12 -> 470 | AC12: ='FEEDER Consumption '!CL12 -> 850 | AD12: ='FEEDER Consumption '!CQ12 -> 840 | AE12: ='FEEDER Consumption '!CV12 -> 550 | AF12: ='FEEDER Consumption '!DA12 -> 1280 | AG12: ='FEEDER Consumption '!DF12 -> 1130 | AH12: ='FEEDER Consumption '!DK12 -> 680 | AI12: ='FEEDER Consumption '!DP12 -> 250 | AJ12: ='FEEDER Consumption '!DU12 -> 132 | AK12: ='FEEDER Consumption '!DZ12 -> 650 | AL12: ='FEEDER Consumption '!EE12 -> 260 | AM12: ='FEEDER Consumption '!EJ12 -> 310 | AN12: ='FEEDER Consumption '!EO12 -> 500 | AO12: =SUM(WATER!C13+WATER!H13+WATER!M13+WATER!R13) -> 1006196 | AP12: =IF((AO12-AO11<0), "0",AO12-AO11) -> 337 | AQ12: =[1]WATER!D13 -> 38 | AR12: =[1]WATER!I13 -> 0 | AS12: =[1]WATER!N13 -> 202 | AT12: =[1]WATER!S13 -> 111 | AU12: =[1]WATER!AD13 -> 19 | AV12: =[1]WATER!AI13 -> 6 | AW12: =[1]WATER!AN13 -> 9 | AX12: =[1]WATER!AS13 -> 12 | AY12: =[1]WATER!AX13 -> 8 | AZ12: =[1]WATER!BC13 -> 7 | BA12: =[1]WATER!BH13 -> 8 | BB12: =[1]WATER!BM13 -> 8 | BC12: =[1]WATER!BR13 -> 2 | BD12: =[1]WATER!BW13 -> 0 | BE12: =[1]WATER!CB13 -> 3 | BF12: =[1]WATER!CG13 -> 1 | BG12: =[1]WATER!CL13 -> 24 | BH12: =[1]WATER!CQ13 -> 8 | BI12: =[1]WATER!CV13 -> 3 | BJ12: =[1]WATER!DA13 -> 6 | BK12: =[1]WATER!DF13 -> 3 | BL12: =[1]WATER!DK13 -> 0 | BM12: =[1]WATER!DP13 -> 3 | BN12: =[1]WATER!DU13 -> 1 | BO12: =[1]WATER!DZ13 -> 2 | BP12: ='[1]Room Nights and Food Covers'!B12 -> 17.5 | BQ12: ='[1]Room Nights and Food Covers'!C12 -> 126
A13: =A12+1 -> 44478 | C13: =SUM('GENSET #1'!C18+'GENSET #2'!C18+'GENSET #3'!C18+'GENSET #4'!C18+'GENSET #5'!C18) -> 93875929 | D13: =IF((C13-C12<0), "0",C13-C12) -> 25400 | E13: ='Gas-2'!G14 -> 315 | F13: =IF((E13-E12<0), "0",E13-E12) -> 90 | G13: ='GENSET #1'!D18 -> 6008 | H13: ='GENSET #2'!D18 -> 8114 | I13: ='GENSET #3'!D18 -> 3348 | J13: ='GENSET #4'!D18 -> 2157 | K13: ='GENSET #5'!D18 -> 5773 | L13: ='FEEDER Consumption '!E13 -> 2526 | M13: ='FEEDER Consumption '!J13 -> 4139 | N13: ='FEEDER Consumption '!O13 -> 13392 | O13: ='FEEDER Consumption '!T13 -> 1600 | P13: ='FEEDER Consumption '!Y13 -> 2794 | Q13: ='FEEDER Consumption '!AD13 -> 1800 | R13: ='FEEDER Consumption '!AI13 -> 807 | S13: ='FEEDER Consumption '!AN13 -> 570 | T13: ='FEEDER Consumption '!AS13 -> 1300 | U13: ='FEEDER Consumption '!AX13 -> 420 | V13: ='FEEDER Consumption '!BH13 -> 860 | W13: ='FEEDER Consumption '!BH13 -> 860 | X13: ='FEEDER Consumption '!BM13 -> 1200 | Y13: ='FEEDER Consumption '!BR13 -> 169 | Z13: ='FEEDER Consumption '!BW13 -> 410 | AA13: ='FEEDER Consumption '!CB13 -> 1210 | AB13: ='FEEDER Consumption '!CG13 -> 390 | AC13: ='FEEDER Consumption '!CL13 -> 830 | AD13: ='FEEDER Consumption '!CQ13 -> 800 | AE13: ='FEEDER Consumption '!CV13 -> 490 | AF13: ='FEEDER Consumption '!DA13 -> 1390 | AG13: ='FEEDER Consumption '!DF13 -> 1040 | AH13: ='FEEDER Consumption '!DK13 -> 650 | AI13: ='FEEDER Consumption '!DP13 -> 210 | AJ13: ='FEEDER Consumption '!DU13 -> 139 | AK13: ='FEEDER Consumption '!DZ13 -> 690 | AL13: ='FEEDER Consumption '!EE13 -> 230 | AM13: ='FEEDER Consumption '!EJ13 -> 250 | AN13: ='FEEDER Consumption '!EO13 -> 460 | AO13: =SUM(WATER!C14+WATER!H14+WATER!M14+WATER!R14) -> 1006543 | AP13: =IF((AO13-AO12<0), "0",AO13-AO12) -> 347 | AQ13: =[1]WATER!D14 -> 55 | AR13: =[1]WATER!I14 -> 0 | AS13: =[1]WATER!N14 -> 197 | AT13: =[1]WATER!S14 -> 145 | AU13: =[1]WATER!AD14 -> 19 | AV13: =[1]WATER!AI14 -> 5 | AW13: =[1]WATER!AN14 -> 8 | AX13: =[1]WATER!AS14 -> 12 | AY13: =[1]WATER!AX14 -> 7 | AZ13: =[1]WATER!BC14 -> 7 | BA13: =[1]WATER!BH14 -> 7 | BB13: =[1]WATER!BM14 -> 7 | BC13: =[1]WATER!BR14 -> 3 | BD13: =[1]WATER!BW14 -> 0 | BE13: =[1]WATER!CB14 -> 6 | BF13: =[1]WATER!CG14 -> 0 | BG13: =[1]WATER!CL14 -> 23 | BH13: =[1]WATER!CQ14 -> 8 | BI13: =[1]WATER!CV14 -> 0 | BJ13: =[1]WATER!DA14 -> 5 | BK13: =[1]WATER!DF14 -> 3 | BL13: =[1]WATER!DK14 -> 5 | BM13: =[1]WATER!DP14 -> 0 | BN13: =[1]WATER!DU14 -> 3 | BO13: =[1]WATER!DZ14 -> 1 | BP13: ='[1]Room Nights and Food Covers'!B13 -> 12.6 | BQ13: ='[1]Room Nights and Food Covers'!C13 -> 130
A14: =A13+1 -> 44479 | C14: =SUM('GENSET #1'!C19+'GENSET #2'!C19+'GENSET #3'!C19+'GENSET #4'!C19+'GENSET #5'!C19) -> 93901313 | D14: =IF((C14-C13<0), "0",C14-C13) -> 25384 | E14: ='Gas-2'!G15 -> 270 | F14: =IF((E14-E13<0), "0",E14-E13) -> 0 | G14: ='GENSET #1'!D19 -> 2427 | H14: ='GENSET #2'!D19 -> 9992 | I14: ='GENSET #3'!D19 -> 5298 | J14: ='GENSET #4'!D19 -> 1966 | K14: ='GENSET #5'!D19 -> 5701 | L14: ='FEEDER Consumption '!E14 -> 2580 | M14: ='FEEDER Consumption '!J14 -> 4418 | N14: ='FEEDER Consumption '!O14 -> 13908 | O14: ='FEEDER Consumption '!T14 -> 1600 | P14: ='FEEDER Consumption '!Y14 -> 2850 | Q14: ='FEEDER Consumption '!AD14 -> 1800 | R14: ='FEEDER Consumption '!AI14 -> 832 | S14: ='FEEDER Consumption '!AN14 -> 590 | T14: ='FEEDER Consumption '!AS14 -> 800 | U14: ='FEEDER Consumption '!AX14 -> 447 | V14: ='FEEDER Consumption '!BH14 -> 890 | W14: ='FEEDER Consumption '!BH14 -> 890 | X14: ='FEEDER Consumption '!BM14 -> 1400 | Y14: ='FEEDER Consumption '!BR14 -> 156 | Z14: ='FEEDER Consumption '!BW14 -> 420 | AA14: ='FEEDER Consumption '!CB14 -> 1190 | AB14: ='FEEDER Consumption '!CG14 -> 430 | AC14: ='FEEDER Consumption '!CL14 -> 990 | AD14: ='FEEDER Consumption '!CQ14 -> 720 | AE14: ='FEEDER Consumption '!CV14 -> 460 | AF14: ='FEEDER Consumption '!DA14 -> 1430 | AG14: ='FEEDER Consumption '!DF14 -> 950 | AH14: ='FEEDER Consumption '!DK14 -> 710 | AI14: ='FEEDER Consumption '!DP14 -> 150 | AJ14: ='FEEDER Consumption '!DU14 -> 136 | AK14: ='FEEDER Consumption '!DZ14 -> 690 | AL14: ='FEEDER Consumption '!EE14 -> 220 | AM14: ='FEEDER Consumption '!EJ14 -> 330 | AN14: ='FEEDER Consumption '!EO14 -> 480 | AO14: =SUM(WATER!C15+WATER!H15+WATER!M15+WATER!R15) -> 1006917 | AP14: =IF((AO14-AO13<0), "0",AO14-AO13) -> 374 | AQ14: =[1]WATER!D15 -> 38 | AR14: =[1]WATER!I15 -> 0 | AS14: =[1]WATER!N15 -> 230 | AT14: =[1]WATER!S15 -> 110 | AU14: =[1]WATER!AD15 -> 15 | AV14: =[1]WATER!AI15 -> 6 | AW14: =[1]WATER!AN15 -> 10 | AX14: =[1]WATER!AS15 -> 13 | AY14: =[1]WATER!AX15 -> 7 | AZ14: =[1]WATER!BC15 -> 7 | BA14: =[1]WATER!BH15 -> 7 | BB14: =[1]WATER!BM15 -> 8 | BC14: =[1]WATER!BR15 -> 2 | BD14: =[1]WATER!BW15 -> 0 | BE14: =[1]WATER!CB15 -> 5 | BF14: =[1]WATER!CG15 -> 1 | BG14: =[1]WATER!CL15 -> 24 | BH14: =[1]WATER!CQ15 -> 6 | BI14: =[1]WATER!CV15 -> 1 | BJ14: =[1]WATER!DA15 -> 5 | BK14: =[1]WATER!DF15 -> 1 | BL14: =[1]WATER!DK15 -> 3 | BM14: =[1]WATER!DP15 -> 0 | BN14: =[1]WATER!DU15 -> 1 | BO14: =[1]WATER!DZ15 -> 1 | BP14: ='[1]Room Nights and Food Covers'!B14 -> 12.6 | BQ14: ='[1]Room Nights and Food Covers'!C14 -> 116
A15: =A14+1 -> 44480 | C15: =SUM('GENSET #1'!C20+'GENSET #2'!C20+'GENSET #3'!C20+'GENSET #4'!C20+'GENSET #5'!C20) -> 93927428 | D15: =IF((C15-C14<0), "0",C15-C14) -> 26115 | E15: ='Gas-2'!G16 -> 180 | F15: =IF((E15-E14<0), "0",E15-E14) -> 0 | G15: ='GENSET #1'!D20 -> 8397 | H15: ='GENSET #2'!D20 -> 5674 | I15: ='GENSET #3'!D20 -> 422 | J15: ='GENSET #4'!D20 -> 3230 | K15: ='GENSET #5'!D20 -> 8392 | L15: ='FEEDER Consumption '!E15 -> 2400 | M15: ='FEEDER Consumption '!J15 -> 4486 | N15: ='FEEDER Consumption '!O15 -> 13888 | O15: ='FEEDER Consumption '!T15 -> 1500 | P15: ='FEEDER Consumption '!Y15 -> 2797 | Q15: ='FEEDER Consumption '!AD15 -> 1700 | R15: ='FEEDER Consumption '!AI15 -> 800 | S15: ='FEEDER Consumption '!AN15 -> 620 | T15: ='FEEDER Consumption '!AS15 -> 1300 | U15: ='FEEDER Consumption '!AX15 -> 428 | V15: ='FEEDER Consumption '!BH15 -> 880 | W15: ='FEEDER Consumption '!BH15 -> 880 | X15: ='FEEDER Consumption '!BM15 -> 1400 | Y15: ='FEEDER Consumption '!BR15 -> 157 | Z15: ='FEEDER Consumption '!BW15 -> 460 | AA15: ='FEEDER Consumption '!CB15 -> 1200 | AB15: ='FEEDER Consumption '!CG15 -> 400 | AC15: ='FEEDER Consumption '!CL15 -> 890 | AD15: ='FEEDER Consumption '!CQ15 -> 720 | AE15: ='FEEDER Consumption '!CV15 -> 510 | AF15: ='FEEDER Consumption '!DA15 -> 1430 | AG15: ='FEEDER Consumption '!DF15 -> 950 | AH15: ='FEEDER Consumption '!DK15 -> 780 | AI15: ='FEEDER Consumption '!DP15 -> 250 | AJ15: ='FEEDER Consumption '!DU15 -> 132 | AK15: ='FEEDER Consumption '!DZ15 -> 640 | AL15: ='FEEDER Consumption '!EE15 -> 240 | AM15: ='FEEDER Consumption '!EJ15 -> 330 | AN15: ='FEEDER Consumption '!EO15 -> 530 | AO15: =SUM(WATER!C16+WATER!H16+WATER!M16+WATER!R16) -> 1007289 | AP15: =IF((AO15-AO14<0), "0",AO15-AO14) -> 372 | AQ15: =[1]WATER!D16 -> 32 | AR15: =[1]WATER!I16 -> 0 | AS15: =[1]WATER!N16 -> 218 | AT15: =[1]WATER!S16 -> 72 | AU15: =[1]WATER!AD16 -> 17 | AV15: =[1]WATER!AI16 -> 5 | AW15: =[1]WATER!AN16 -> 0 | AX15: =[1]WATER!AS16 -> 11 | AY15: =[1]WATER!AX16 -> 7 | AZ15: =[1]WATER!BC16 -> 6 | BA15: =[1]WATER!BH16 -> 7 | BB15: =[1]WATER!BM16 -> 6 | BC15: =[1]WATER!BR16 -> 2 | BD15: =[1]WATER!BW16 -> 2 | BE15: =[1]WATER!CB16 -> 6 | BF15: =[1]WATER!CG16 -> 4 | BG15: =[1]WATER!CL16 -> 25 | BH15: =[1]WATER!CQ16 -> 6 | BI15: =[1]WATER!CV16 -> 0 | BJ15: =[1]WATER!DA16 -> 7 | BK15: =[1]WATER!DF16 -> 4 | BL15: =[1]WATER!DK16 -> 4 | BM15: =[1]WATER!DP16 -> 0 | BN15: =[1]WATER!DU16 -> 1 | BO15: =[1]WATER!DZ16 -> 1 | BP15: ='[1]Room Nights and Food Covers'!B15 -> 12.6 | BQ15: ='[1]Room Nights and Food Covers'!C15 -> 119
A16: =A15+1 -> 44481 | C16: =SUM('GENSET #1'!C21+'GENSET #2'!C21+'GENSET #3'!C21+'GENSET #4'!C21+'GENSET #5'!C21) -> 93952796 | D16: =IF((C16-C15<0), "0",C16-C15) -> 25368 | E16: ='Gas-2'!G17 -> 180 | F16: =IF((E16-E15<0), "0",E16-E15) -> 0 | G16: ='GENSET #1'!D21 -> 8365 | H16: ='GENSET #2'!D21 -> 6028 | I16: ='GENSET #3'!D21 -> 0 | J16: ='GENSET #4'!D21 -> 2611 | K16: ='GENSET #5'!D21 -> 8364 | L16: ='FEEDER Consumption '!E16 -> 2579 | M16: ='FEEDER Consumption '!J16 -> 4633 | N16: ='FEEDER Consumption '!O16 -> 13425 | O16: ='FEEDER Consumption '!T16 -> 1600 | P16: ='FEEDER Consumption '!Y16 -> 2758 | Q16: ='FEEDER Consumption '!AD16 -> 1600 | R16: ='FEEDER Consumption '!AI16 -> 812 | S16: ='FEEDER Consumption '!AN16 -> 580 | T16: ='FEEDER Consumption '!AS16 -> 800 | U16: ='FEEDER Consumption '!AX16 -> 432 | V16: ='FEEDER Consumption '!BH16 -> 840 | W16: ='FEEDER Consumption '!BH16 -> 840 | X16: ='FEEDER Consumption '!BM16 -> 1200 | Y16: ='FEEDER Consumption '!BR16 -> 151 | Z16: ='FEEDER Consumption '!BW16 -> 420 | AA16: ='FEEDER Consumption '!CB16 -> 1250 | AB16: ='FEEDER Consumption '!CG16 -> 410 | AC16: ='FEEDER Consumption '!CL16 -> 860 | AD16: ='FEEDER Consumption '!CQ16 -> 750 | AE16: ='FEEDER Consumption '!CV16 -> 630 | AF16: ='FEEDER Consumption '!DA16 -> 1440 | AG16: ='FEEDER Consumption '!DF16 -> 980 | AH16: ='FEEDER Consumption '!DK16 -> 890 | AI16: ='FEEDER Consumption '!DP16 -> 180 | AJ16: ='FEEDER Consumption '!DU16 -> 113 | AK16: ='FEEDER Consumption '!DZ16 -> 680 | AL16: ='FEEDER Consumption '!EE16 -> 190 | AM16: ='FEEDER Consumption '!EJ16 -> 300 | AN16: ='FEEDER Consumption '!EO16 -> 520 | AO16: =SUM(WATER!C17+WATER!H17+WATER!M17+WATER!R17) -> 1007705 | AP16: =IF((AO16-AO15<0), "0",AO16-AO15) -> 416 | AQ16: =[1]WATER!D17 -> 19 | AR16: =[1]WATER!I17 -> 0 | AS16: =[1]WATER!N17 -> 186 | AT16: =[1]WATER!S17 -> 113 | AU16: =[1]WATER!AD17 -> 16 | AV16: =[1]WATER!AI17 -> 6 | AW16: =[1]WATER!AN17 -> 0 | AX16: =[1]WATER!AS17 -> 13 | AY16: =[1]WATER!AX17 -> 8 | AZ16: =[1]WATER!BC17 -> 7 | BA16: =[1]WATER!BH17 -> 8 | BB16: =[1]WATER!BM17 -> 9 | BC16: =[1]WATER!BR17 -> 2 | BD16: =[1]WATER!BW17 -> 0 | BE16: =[1]WATER!CB17 -> 4 | BF16: =[1]WATER!CG17 -> 2 | BG16: =[1]WATER!CL17 -> 28 | BH16: =[1]WATER!CQ17 -> 7 | BI16: =[1]WATER!CV17 -> 1 | BJ16: =[1]WATER!DA17 -> -3 | BK16: =[1]WATER!DF17 -> 2 | BL16: =[1]WATER!DK17 -> 4 | BM16: =[1]WATER!DP17 -> 50 | BN16: =[1]WATER!DU17 -> 0 | BO16: =[1]WATER!DZ17 -> 1 | BP16: ='[1]Room Nights and Food Covers'!B16 -> 11.7 | BQ16: ='[1]Room Nights and Food Covers'!C16 -> 118
A17: =A16+1 -> 44482 | C17: =SUM('GENSET #1'!C22+'GENSET #2'!C22+'GENSET #3'!C22+'GENSET #4'!C22+'GENSET #5'!C22) -> 93979229 | D17: =IF((C17-C16<0), "0",C17-C16) -> 26433 | E17: ='Gas-2'!G18 -> 270 | F17: =IF((E17-E16<0), "0",E17-E16) -> 90 | G17: ='GENSET #1'!D22 -> 5400 | H17: ='GENSET #2'!D22 -> 9672 | I17: ='GENSET #3'!D22 -> 4600 | J17: ='GENSET #4'!D22 -> 3947 | K17: ='GENSET #5'!D22 -> 2814 | L17: ='FEEDER Consumption '!E17 -> 2672 | M17: ='FEEDER Consumption '!J17 -> 4818 | N17: ='FEEDER Consumption '!O17 -> 13914 | O17: ='FEEDER Consumption '!T17 -> 1600 | P17: ='FEEDER Consumption '!Y17 -> 2654 | Q17: ='FEEDER Consumption '!AD17 -> 1800 | R17: ='FEEDER Consumption '!AI17 -> 820 | S17: ='FEEDER Consumption '!AN17 -> 600 | T17: ='FEEDER Consumption '!AS17 -> 1300 | U17: ='FEEDER Consumption '!AX17 -> 462 | V17: ='FEEDER Consumption '!BH17 -> 850 | W17: ='FEEDER Consumption '!BH17 -> 850 | X17: ='FEEDER Consumption '!BM17 -> 1200 | Y17: ='FEEDER Consumption '!BR17 -> 140 | Z17: ='FEEDER Consumption '!BW17 -> 420 | AA17: ='FEEDER Consumption '!CB17 -> 1220 | AB17: ='FEEDER Consumption '!CG17 -> 420 | AC17: ='FEEDER Consumption '!CL17 -> 820 | AD17: ='FEEDER Consumption '!CQ17 -> 840 | AE17: ='FEEDER Consumption '!CV17 -> 600 | AF17: ='FEEDER Consumption '!DA17 -> 1520 | AG17: ='FEEDER Consumption '!DF17 -> 1050 | AH17: ='FEEDER Consumption '!DK17 -> 960 | AI17: ='FEEDER Consumption '!DP17 -> 200 | AJ17: ='FEEDER Consumption '!DU17 -> 133 | AK17: ='FEEDER Consumption '!DZ17 -> 730 | AL17: ='FEEDER Consumption '!EE17 -> 230 | AM17: ='FEEDER Consumption '!EJ17 -> 340 | AN17: ='FEEDER Consumption '!EO17 -> 480 | AO17: =SUM(WATER!C18+WATER!H18+WATER!M18+WATER!R18) -> 1008081 | AP17: =IF((AO17-AO16<0), "0",AO17-AO16) -> 376 | AQ17: =[1]WATER!D18 -> 0 | AR17: =[1]WATER!I18 -> 0 | AS17: =[1]WATER!N18 -> 199 | AT17: =[1]WATER!S18 -> 111 | AU17: =[1]WATER!AD18 -> 16 | AV17: =[1]WATER!AI18 -> 6 | AW17: =[1]WATER!AN18 -> 0 | AX17: =[1]WATER!AS18 -> 6 | AY17: =[1]WATER!AX18 -> 7 | AZ17: =[1]WATER!BC18 -> 6 | BA17: =[1]WATER!BH18 -> 7 | BB17: =[1]WATER!BM18 -> 7 | BC17: =[1]WATER!BR18 -> 2 | BD17: =[1]WATER!BW18 -> 0 | BE17: =[1]WATER!CB18 -> 6 | BF17: =[1]WATER!CG18 -> 2 | BG17: =[1]WATER!CL18 -> 26 | BH17: =[1]WATER!CQ18 -> 3 | BI17: =[1]WATER!CV18 -> 1 | BJ17: =[1]WATER!DA18 -> 8 | BK17: =[1]WATER!DF18 -> 2 | BL17: =[1]WATER!DK18 -> 4 | BM17: =[1]WATER!DP18 -> 0 | BN17: =[1]WATER!DU18 -> 1 | BO17: =[1]WATER!DZ18 -> 0 | BP17: ='[1]Room Nights and Food Covers'!B17 -> 13.6 | BQ17: ='[1]Room Nights and Food Covers'!C17 -> 106
... A35: =A34+1 -> 44500 | C35: =SUM('GENSET #1'!C40+'GENSET #2'!C40+'GENSET #3'!C40+'GENSET #4'!C40+'GENSET #5'!C40) -> 94445379 | D35: =IF((C35-C34<0), "0",C35-C34) -> 27036 | E35: ='Gas-2'!G36 -> 270 | F35: =IF((E35-E34<0), "0",E35-E34) -> 45 | G35: ='GENSET #1'!D40 -> 1772 | H35: ='GENSET #2'!D40 -> 8540 | I35: ='GENSET #3'!D40 -> 4461 | J35: ='GENSET #4'!D40 -> 1022 | K35: ='GENSET #5'!D40 -> 11241 | L35: ='FEEDER Consumption '!E35 -> 2721 | M35: ='FEEDER Consumption '!J35 -> 4505 | N35: ='FEEDER Consumption '!O35 -> 13894 | O35: ='FEEDER Consumption '!T35 -> 1600 | P35: ='FEEDER Consumption '!Y35 -> 2897 | Q35: ='FEEDER Consumption '!AD35 -> 2200 | R35: ='FEEDER Consumption '!AI35 -> 881 | S35: ='FEEDER Consumption '!AN35 -> 730 | T35: ='FEEDER Consumption '!AS35 -> 1600 | U35: ='FEEDER Consumption '!AX35 -> 442 | V35: ='FEEDER Consumption '!BH35 -> 900 | W35: ='FEEDER Consumption '!BH35 -> 900 | X35: ='FEEDER Consumption '!BM35 -> 1000 | Y35: ='FEEDER Consumption '!BR35 -> 170 | Z35: ='FEEDER Consumption '!BW35 -> 440 | AA35: ='FEEDER Consumption '!CB35 -> 1240 | AB35: ='FEEDER Consumption '!CG35 -> 420 | AC35: ='FEEDER Consumption '!CL35 -> 980 | AD35: ='FEEDER Consumption '!CQ35 -> 800 | AE35: ='FEEDER Consumption '!CV35 -> 610 | AF35: ='FEEDER Consumption '!DA35 -> 1300 | AG35: ='FEEDER Consumption '!DF35 -> 790 | AH35: ='FEEDER Consumption '!DK35 -> 770 | AI35: ='FEEDER Consumption '!DP35 -> 180 | AJ35: ='FEEDER Consumption '!DU35 -> 0 | AK35: ='FEEDER Consumption '!DZ35 -> 730 | AL35: ='FEEDER Consumption '!EE35 -> 240 | AM35: ='FEEDER Consumption '!EJ35 -> 340 | AN35: ='FEEDER Consumption '!EO35 -> 530 | AO35: =SUM(WATER!C36+WATER!H36+WATER!M36+WATER!R36) -> 1015437 | AP35: =IF((AO35-AO34<0), "0",AO35-AO34) -> 442 | AQ35: =[1]WATER!D36 -> 202 | AR35: =[1]WATER!I36 -> 0 | AS35: =[1]WATER!N36 -> 41 | AT35: =[1]WATER!S36 -> 133 | AU35: =[1]WATER!AD36 -> 18 | AV35: =[1]WATER!AI36 -> 6 | AW35: =[1]WATER!AN36 -> 15 | AX35: =[1]WATER!AS36 -> 11 | AY35: =[1]WATER!AX36 -> 7 | AZ35: =[1]WATER!BC36 -> 7 | BA35: =[1]WATER!BH36 -> 1 | BB35: =[1]WATER!BM36 -> 9 | BC35: =[1]WATER!BR36 -> 1 | BD35: =[1]WATER!BW36 -> 0 | BE35: =[1]WATER!CB36 -> 1 | BF35: =[1]WATER!CG36 -> 2 | BG35: =[1]WATER!CL36 -> 0 | BH35: =[1]WATER!CQ36 -> 9 | BI35: =[1]WATER!CV36 -> 0 | BJ35: =[1]WATER!DA36 -> 1 | BK35: =[1]WATER!DF36 -> 3 | BL35: =[1]WATER!DK36 -> 3 | BM35: =[1]WATER!DP36 -> 7 | BN35: =[1]WATER!DU36 -> 2 | BO35: =[1]WATER!DZ36 -> 1 | BP35: ='[1]Room Nights and Food Covers'!B35 -> 31.1 | BQ35: ='[1]Room Nights and Food Covers'!C35 -> 195

Sheet Finance Only
A1: Four Seasons Landaa Giraavaru
A3: Property | B3: MLG | G3: 44470 | H3: =NOW() -> 44909.753 | J3: =H3-G3 -> 439.75305
A4: Month | B4: October
A5: Year | B5: 2021
A7: DAY | B7: Electricity Consumption ( kwh) | C7: Diesel Consumption (Liters) | D7: Solar Power Consumption(kwh) | E7: Gas Consumption (kg) | F7: Water Consumption ( m3) | G7: Occupancy | H7: Weather | I7: Ambian Temperature | J7: Electricity Variance (Today vs Yesterday)
A8: 1 | B8: =SUM('GENSET #1:GENSET #5'!D10) -> 23451 | C8: ='Diesel consumption'!D5 -> 6480 | D8: ='SOLAR METER READING'!D9 -> 1933 | E8: ='Gas-2'!G6 -> 180 | F8: =WATER!V6 -> 340 | G8: =WATER!W6 -> 0 | H8: ='SOLAR METER READING'!E9 -> rainin | I8: ='SOLAR METER READING'!F9 -> 27
A9: 2 | B9: =SUM('GENSET #1:GENSET #5'!D11) -> 21626 | C9: ='Diesel consumption'!D6 -> 5670 | D9: ='SOLAR METER READING'!D10 -> 3108 | E9: ='Gas-2'!G7 -> 225 | F9: =WATER!V7 -> 349 | G9: =WATER!W7 -> 5275 | H9: ='SOLAR METER READING'!E10 -> sunny | I9: ='SOLAR METER READING'!F10 -> 30 | J9: =B9-B8 -> -1825
A10: 3 | B10: =SUM('GENSET #1:GENSET #5'!D12) -> 23924 | C10: ='Diesel consumption'!D7 -> 6470 | D10: ='SOLAR METER READING'!D11 -> 3264 | E10: ='Gas-2'!G8 -> 225 | F10: =WATER!V8 -> 346 | G10: =WATER!W8 -> 3209 | H10: ='SOLAR METER READING'!E11 -> sunny | I10: ='SOLAR METER READING'!F11 -> 30 | J10: =B10-B9 -> 2298
A11: 4 | B11: =SUM('GENSET #1:GENSET #5'!D13) -> 23294 | C11: ='Diesel consumption'!D8 -> 6620 | D11: ='SOLAR METER READING'!D12 -> 2470 | E11: ='Gas-2'!G9 -> 225 | F11: =WATER!V9 -> 340 | G11: =WATER!W9 -> 7157 | H11: ='SOLAR METER READING'!E12 -> cloudy | I11: ='SOLAR METER READING'!F12 -> 28 | J11: =B11-B10 -> -630
A12: 5 | B12: =SUM('GENSET #1:GENSET #5'!D14) -> 22493 | C12: ='Diesel consumption'!D9 -> 6340 | D12: ='SOLAR METER READING'!D13 -> 2124 | E12: ='Gas-2'!G10 -> 225 | F12: =WATER!V10 -> 275 | G12: =WATER!W10 -> 2548 | H12: ='SOLAR METER READING'!E13 -> cloudy | I12: ='SOLAR METER READING'!F13 -> 28 | J12: =B12-B11 -> -801
A13: 6 | B13: =SUM('GENSET #1:GENSET #5'!D15) -> 23652 | C13: ='Diesel consumption'!D10 -> 6530 | D13: ='SOLAR METER READING'!D14 -> 2705 | E13: ='Gas-2'!G11 -> 225 | F13: =WATER!V11 -> 364 | G13: =WATER!W11 -> 6770 | H13: ='SOLAR METER READING'!E14 -> cloudy | I13: ='SOLAR METER READING'!F14 -> 28 | J13: =B13-B12 -> 1159
A14: 7 | B14: =SUM('GENSET #1:GENSET #5'!D16) -> 24002 | C14: ='Diesel consumption'!D11 -> 6620 | D14: ='SOLAR METER READING'!D15 -> 2968 | E14: ='Gas-2'!G12 -> 270 | F14: =WATER!V12 -> 323 | G14: =WATER!W12 -> 2259 | H14: ='SOLAR METER READING'!E15 -> cloudy | I14: ='SOLAR METER READING'!F15 -> 28 | J14: =B14-B13 -> 350
A15: 8 | B15: =SUM('GENSET #1:GENSET #5'!D17) -> 24528 | C15: ='Diesel consumption'!D12 -> 6900 | D15: ='SOLAR METER READING'!D16 -> 3156 | E15: ='Gas-2'!G13 -> 225 | F15: =WATER!V13 -> 337 | G15: =WATER!W13 -> 1552 | H15: ='SOLAR METER READING'!E16 -> sunny | I15: ='SOLAR METER READING'!F16 -> 31 | J15: =B15-B14 -> 526
A16: 9 | B16: =SUM('GENSET #1:GENSET #5'!D18) -> 25400 | C16: ='Diesel consumption'!D13 -> 7130 | D16: ='SOLAR METER READING'!D17 -> 2859 | E16: ='Gas-2'!G14 -> 315 | F16: =WATER!V14 -> 347 | G16: =WATER!W14 -> 3348 | H16: ='SOLAR METER READING'!E17 -> cloudy | I16: ='SOLAR METER READING'!F17 -> 28 | J16: =B16-B15 -> 872
A17: 10 | B17: =SUM('GENSET #1:GENSET #5'!D19) -> 25384 | C17: ='Diesel consumption'!D14 -> 6650 | D17: ='SOLAR METER READING'!D18 -> 2885 | E17: ='Gas-2'!G15 -> 270 | F17: =WATER!V15 -> 374 | G17: =WATER!W15 -> 5298 | H17: ='SOLAR METER READING'!E18 -> cloudy | I17: ='SOLAR METER READING'!F18 -> 29 | J17: =B17-B16 -> -16
A18: 11 | B18: =SUM('GENSET #1:GENSET #5'!D20) -> 26115 | C18: ='Diesel consumption'!D15 -> 7320 | D18: ='SOLAR METER READING'!D19 -> 2890 | E18: ='Gas-2'!G16 -> 180 | F18: =WATER!V16 -> 372 | G18: =WATER!W16 -> 422 | H18: ='SOLAR METER READING'!E19 -> cloudy | I18: ='SOLAR METER READING'!F19 -> 28 | J18: =B18-B17 -> 731
A19: 12 | B19: =SUM('GENSET #1:GENSET #5'!D21) -> 25368 | C19: ='Diesel consumption'!D16 -> 7060 | D19: ='SOLAR METER READING'!D20 -> 3200 | E19: ='Gas-2'!G17 -> 180 | F19: =WATER!V17 -> 416 | G19: =WATER!W17 -> 0 | H19: ='SOLAR METER READING'!E20 -> sunny | I19: ='SOLAR METER READING'!F20 -> 29 | J19: =B19-B18 -> -747
A20: 13 | B20: =SUM('GENSET #1:GENSET #5'!D22) -> 26433 | C20: ='Diesel consumption'!D17 -> 7470 | D20: ='SOLAR METER READING'!D21 -> 3184 | E20: ='Gas-2'!G18 -> 270 | F20: =WATER!V18 -> 376 | G20: =WATER!W18 -> 4600 | H20: ='SOLAR METER READING'!E21 -> sunny | I20: ='SOLAR METER READING'!F21 -> 29 | J20: =B20-B19 -> 1065
... A38: 31 | B38: =SUM('GENSET #1:GENSET #5'!D40) -> 27036 | C38: ='Diesel consumption'!D35 -> 7410 | D38: ='SOLAR METER READING'!D39 -> 2686 | E38: ='Gas-2'!G36 -> 270 | F38: =WATER!V36 -> 442 | G38: =WATER!W36 -> 4461 | H38: ='SOLAR METER READING'!E39 -> cloudy | I38: ='SOLAR METER READING'!F39 -> 29 | J38: =B38-B37 -> 284
A39: Total | B39: =SUM(B8:B38) -> 781820 | C39: =SUM(C8:C38) -> 216710 | D39: =SUM(D8:D38) -> 86666 | E39: =SUM(E8:E38) -> 7380 | F39: =SUM(F8:F38) -> 11915 | G39: =SUM(G8:G37)/30 -> 2884.9 | H39: ='SOLAR METER READING'!E40 -> 0 | I39: ='SOLAR METER READING'!F40 -> 0
A40: Avg | B40: =B39/J3 -> 1777.8614 | C40: =C39/J3 -> 492.79931 | D40: =D39/J3 -> 197.07879 | E40: =E39/J3 -> 16.782146 | F40: =F39/J3 -> 27.094752

Sheet Room Nights and Food Covers
A2: Days
A3: Date | B3: ROOM NIGHTS | C3: Total Food Covers
A4: 44469 | B4: 21 | C4: 222
A5: =A4+1 -> 44470 | B5: 12.6 | C5: 100
A6: =A5+1 -> 44471 | B6: 9.7 | C6: 88
A7: =A6+1 -> 44472 | B7: 10.7 | C7: 76
A8: =A7+1 -> 44473 | B8: 11.7 | C8: 71
A9: =A8+1 -> 44474 | B9: 18.4 | C9: 92
A10: =A9+1 -> 44475 | B10: 20.4 | C10: 129
A11: =A10+1 -> 44476 | B11: 21.4 | C11: 137
A12: =A11+1 -> 44477 | B12: 21.4 | C12: 129
A13: =A12+1 -> 44478 | B13: 20.4 | C13: 119
A14: =A13+1 -> 44479 | B14: 20.4 | C14: 144
A15: =A14+1 -> 44480 | B15: 23.3 | C15: 158
