Workbook

Sheet TOTAL
A1: Site Name | B1: Day | C1: Month | D1: Year | E1: Total Electricity Kwh | F1: Electricity Tariff ($/Kwh) | G1: LPG (Kg) | H1: LPG $/Kg | I1: Water Utility Supply (m3) m3 | J1: Water Utility Supply (m3) $/m3 | K1: Room Nights | L1: Food Covers
A2: Maldives at Landaa Giraavaru | B2: 1 | C2: 10 | D2: 2022 | E2: ='Maldives at LG Daily'!D5 -> 23230 | F2: 0.832 | G2: ='Maldives at LG Daily'!F5 -> 270 | H2: 1.24 | I2: ='Maldives at LG Daily'!H5 -> 7742 | J2: 0 | K2: ='Maldives at LG Daily'!I5 -> 0 | L2: ='Maldives at LG Daily'!J5 -> 2524
A3: Maldives at Landaa Giraavaru | B3: 2 | C3: 10 | D3: 2022 | E3: ='Maldives at LG Daily'!D6 -> 22901 | F3: 0.832 | G3: ='Maldives at LG Daily'!F6 -> 0 | H3: 1.24 | I3: ='Maldives at LG Daily'!H6 -> 6795 | J3: 0 | K3: ='Maldives at LG Daily'!I6 -> 0 | L3: ='Maldives at LG Daily'!J6 -> 240
A4: Maldives at Landaa Giraavaru | B4: 3 | C4: 10 | D4: 2022 | E4: ='Maldives at LG Daily'!D7 -> 23398 | F4: 0.832 | G4: ='Maldives at LG Daily'!F7 -> 45 | H4: 1.24 | I4: ='Maldives at LG Daily'!H7 -> 6146 | J4: 0 | K4: ='Maldives at LG Daily'!I7 -> 0 | L4: ='Maldives at LG Daily'!J7 -> 1563
A5: Maldives at Landaa Giraavaru | B5: 4 | C5: 10 | D5: 2022 | E5: ='Maldives at LG Daily'!D8 -> 24673 | F5: 0.832 | G5: ='Maldives at LG Daily'!F8 -> 0 | H5: 1.24 | I5: ='Maldives at LG Daily'!H8 -> 6238 | J5: 0 | K5: ='Maldives at LG Daily'!I8 -> 0 | L5: ='Maldives at LG Daily'!J8 -> 2154
A6: Maldives at Landaa Giraavaru | B6: 5 | C6: 10 | D6: 2022 | E6: ='Maldives at LG Daily'!D9 -> 25199 | F6: 0.832 | G6: ='Maldives at LG Daily'!F9 -> 0 | H6: 1.24 | I6: ='Maldives at LG Daily'!H9 -> 5870 | J6: 0 | K6: ='Maldives at LG Daily'!I9 -> 7678 | L6: ='Maldives at LG Daily'!J9 -> 2292
A7: Maldives at Landaa Giraavaru | B7: 6 | C7: 10 | D7: 2022 | E7: ='Maldives at LG Daily'!D10 -> 24031 | F7: 0.832 | G7: ='Maldives at LG Daily'!F10 -> 90 | H7: 1.24 | I7: ='Maldives at LG Daily'!H10 -> 10014 | J7: 0 | K7: ='Maldives at LG Daily'!I10 -> 2203 | L7: ='Maldives at LG Daily'!J10 -> 580
A8: Maldives at Landaa Giraavaru | B8: 7 | C8: 10 | D8: 2022 | E8: ='Maldives at LG Daily'!D11 -> 24598 | F8: 0.832 | G8: ='Maldives at LG Daily'!F11 -> 0 | H8: 1.24 | I8: ='Maldives at LG Daily'!H11 -> 17635 | J8: 0 | K8: ='Maldives at LG Daily'!I11 -> 0 | L8: ='Maldives at LG Daily'!J11 -> 3040
A9: Maldives at Landaa Giraavaru | B9: 8 | C9: 10 | D9: 2022 | E9: ='Maldives at LG Daily'!D12 -> 24492 | F9: 0.832 | G9: ='Maldives at LG Daily'!F12 -> 90 | H9: 1.24 | I9: ='Maldives at LG Daily'!H12 -> 7513 | J9: 0 | K9: ='Maldives at LG Daily'!I12 -> 0 | L9: ='Maldives at LG Daily'!J12 -> 2520
A10: Maldives at Landaa Giraavaru | B10: 9 | C10: 10 | D10: 2022 | E10: ='Maldives at LG Daily'!D13 -> 24788 | F10: 0.832 | G10: ='Maldives at LG Daily'!F13 -> 0 | H10: 1.24 | I10: ='Maldives at LG Daily'!H13 -> 5699 | J10: 0 | K10: ='Maldives at LG Daily'!I13 -> 0 | L10: ='Maldives at LG Daily'!J13 -> 2184
A11: Maldives at Landaa Giraavaru | B11: 10 | C11: 10 | D11: 2022 | E11: ='Maldives at LG Daily'!D14 -> 23241 | F11: 0.832 | G11: ='Maldives at LG Daily'!F14 -> 0 | H11: 1.24 | I11: ='Maldives at LG Daily'!H14 -> 6279 | J11: 0 | K11: ='Maldives at LG Daily'!I14 -> 0 | L11: ='Maldives at LG Daily'!J14 -> 1241
A12: Maldives at Landaa Giraavaru | B12: 11 | C12: 10 | D12: 2022 | E12: ='Maldives at LG Daily'!D15 -> 22785 | F12: 0.832 | G12: ='Maldives at LG Daily'!F15 -> 0 | H12: 1.24 | I12: ='Maldives at LG Daily'!H15 -> 5829 | J12: 0 | K12: ='Maldives at LG Daily'!I15 -> 0 | L12: ='Maldives at LG Daily'!J15 -> 270
A13: Maldives at Landaa Giraavaru | B13: 12 | C13: 10 | D13: 2022 | E13: ='Maldives at LG Daily'!D16 -> 20882 | F13: 0.832 | G13: ='Maldives at LG Daily'!F16 -> 135 | H13: 1.24 | I13: ='Maldives at LG Daily'!H16 -> 6063 | J13: 0 | K13: ='Maldives at LG Daily'!I16 -> 0 | L13: ='Maldives at LG Daily'!J16 -> 0
... A31: Maldives at Landaa Giraavaru | B31: 30 | C31: 10 | D31: 2022 | E31: ='Maldives at LG Daily'!D34 -> 24684 | F31: 1.832 | G31: ='Maldives at LG Daily'!F34 -> 45 | H31: 2.24 | I31: ='Maldives at LG Daily'!H34 -> 12511 | J31: 1 | K31: ='Maldives at LG Daily'!I34 -> 4317 | L31: ='Maldives at LG Daily'!J34 -> 0
A32: Maldives at Landaa Giraavaru | B32: 31 | C32: 10 | D32: 2022 | E32: ='Maldives at LG Daily'!D36 -> 0 | F32: 0.832 | G32: ='Maldives at LG Daily'!F36 -> 0 | H32: 1.24 | I32: ='Maldives at LG Daily'!H36 -> 0 | J32: 0 | K32: ='Maldives at LG Daily'!I36 -> 0 | L32: ='Maldives at LG Daily'!J36 -> 0

Sheet Submetering 
A1: Site Name | B1: Day | C1: Month | D1: Year | E1: GENSET NO 1 | F1: GENSET NO 2 | G1: GENSET NO 3 | H1: GENSET NO 4 | I1: GENSET NO 5 | J1: Main BLU FEEDER PANEL 1 | K1: Main BLU FEEDER PANEL 2 | L1: Main POWER HOUSE FEEDER PANEL NO:3 | M1: Main Kitchen -7 | N1: Main Kitchen -10 | O1: Water treatment Plant | P1: Sewage treatment Plant | Q1: Laundry--8SSB (Machineries) | R1: Laundry-9 (HR/Tuck Shop Building) | S1: New staff accomodation (E0) | T1: Staff block-16(E2-E3) | U1: Staff Block Feeder-3(E4-E5) | V1: Management block-5 (M1 to M6) | W1: SNR STAFF BLOCK (PC Block) | X1: BOAT DOCK FEEDER - 22 | Y1: RECEPTION Building Full (Finance/Reservation) | Z1: DIVE CENTER (Inc MDC and Recreation) | AA1: 301-307 | AB1: 308-314 | AC1: 315-320 | AD1: 401-407 | AE1: 408-414 | AF1: 415-420 | AG1: SPA - 1 | AH1: SPA - 2 | AI1: BLU KITCHEN - 1 | AJ1: BLU KITCHEN - 2 | AK1: AL BARAKATH | AL1: STAFF KITCHEN | AM1: R/O Plant A | AN1: R/O Plant B | AO1: R/O Plant C | AP1: R/O Plant D | AQ1: Laundry | AR1: Staff Block - E0 | AS1: Staff Block - E1 | AT1: Staff Block - E2 | AU1: Staff Block - E3 | AV1: Staff Block - E4 | AW1: Staff Block - E5 | AX1: Management Block | AY1: PC Block | AZ1: GM Bungalow | BA1: Boat Dock | BB1: Supply Jetty | BC1: Main Kitchen | BD1: Day Facility | BE1: Reception | BF1: Main Pool | BG1: Dive Center | BH1: Albarakthu | BI1: Blu Resturant | BJ1: Main Jetty | BK1: Landaa Estate
A2: Maldives at Landaa Giraavaru | B2: 1 | C2: 10 | D2: 2022 | E2: ='Maldives at LG Daily'!G5 -> 6494 | F2: ='Maldives at LG Daily'!H5 -> 7742 | G2: ='Maldives at LG Daily'!I5 -> 0 | H2: ='Maldives at LG Daily'!J5 -> 2524 | I2: ='Maldives at LG Daily'!K5 -> 6470 | J2: ='Maldives at LG Daily'!L5 -> 3070 | K2: ='Maldives at LG Daily'!M5 -> 3775 | L2: ='Maldives at LG Daily'!N5 -> 10853 | ... AL2: ='Maldives at LG Daily'!AN5 -> 940 | AM2: ='Maldives at LG Daily'!AQ5 -> 74 | AN2: ='Maldives at LG Daily'!AR5 -> 0 | AO2: ='Maldives at LG Daily'!AS5 -> 190 | AP2: ='Maldives at LG Daily'!AT5 -> 10 | AQ2: ='Maldives at LG Daily'!AU5 -> 18 | AR2: ='Maldives at LG Daily'!AV5 -> 6 | AS2: ='Maldives at LG Daily'!AW5 -> 0 | AT2: ='Maldives at LG Daily'!AX5 -> 10 | ... BK2: ='Maldives at LG Daily'!BO5 -> 0
A3: Maldives at Landaa Giraavaru | B3: 2 | C3: 10 | D3: 2022 | E3: ='Maldives at LG Daily'!G6 -> 7927 | F3: 0.832 | G3: ='Maldives at LG Daily'!F6 -> 0 | H3: 1.24 | I3: ='Maldives at LG Daily'!H6 -> 6795 | J3: ='Maldives at LG Daily'!L6 -> 3240 | K3: ='Maldives at LG Daily'!M6 -> 3366 | L3: ='Maldives at LG Daily'!N6 -> 11442 | M3: ='Maldives at LG Daily'!O6 -> 2300 | N3: ='Maldives at LG Daily'!P6 -> 2724 | O3: ='Maldives at LG Daily'!Q6 -> 2000 | P3: ='Maldives at LG Daily'!R6 -> 532 | Q3: ='Maldives at LG Daily'!S6 -> 700 | ... AL3: ='Maldives at LG Daily'!AN6 -> 0 | AM3: ='Maldives at LG Daily'!AQ6 -> 71 | AN3: ='Maldives at LG Daily'!AR6 -> 0 | AO3: ='Maldives at LG Daily'!AS6 -> 143 | AP3: ='Maldives at LG Daily'!AT6 -> 113 | AQ3: ='Maldives at LG Daily'!AU6 -> 17 | AR3: ='Maldives at LG Daily'!AV6 -> 13 | AS3: ='Maldives at LG Daily'!AW6 -> 16 | AT3: ='Maldives at LG Daily'!AX6 -> 12 | ... BK3: ='Maldives at LG Daily'!BO6 -> 2
A4: Maldives at Landaa Giraavaru | B4: 3 | C4: 10 | D4: 2022 | E4: ='Maldives at LG Daily'!G7 -> 7798 | F4: 0.832 | G4: ='Maldives at LG Daily'!F7 -> 45 | H4: 1.24 | I4: ='Maldives at LG Daily'!H7 -> 6146 | J4: ='Maldives at LG Daily'!L7 -> 3803 | K4: ='Maldives at LG Daily'!M7 -> 3651 | L4: ='Maldives at LG Daily'!N7 -> 10493 | M4: ='Maldives at LG Daily'!O7 -> 2400 | N4: ='Maldives at LG Daily'!P7 -> 2719 | O4: ='Maldives at LG Daily'!Q7 -> 2100 | P4: ='Maldives at LG Daily'!R7 -> 465 | Q4: ='Maldives at LG Daily'!S7 -> 0 | ... AL4: ='Maldives at LG Daily'!AN7 -> 500 | AM4: ='Maldives at LG Daily'!AQ7 -> 65 | AN4: ='Maldives at LG Daily'!AR7 -> 0 | AO4: ='Maldives at LG Daily'!AS7 -> 197 | AP4: ='Maldives at LG Daily'!AT7 -> 109 | AQ4: ='Maldives at LG Daily'!AU7 -> 18 | AR4: ='Maldives at LG Daily'!AV7 -> 4 | AS4: ='Maldives at LG Daily'!AW7 -> 9 | AT4: ='Maldives at LG Daily'!AX7 -> 11 | ... BK4: ='Maldives at LG Daily'!BO7 -> 1
A5: Maldives at Landaa Giraavaru | B5: 4 | C5: 10 | D5: 2022 | E5: ='Maldives at LG Daily'!G8 -> 8163 | F5: 0.832 | G5: ='Maldives at LG Daily'!F8 -> 0 | H5: 1.24 | I5: ='Maldives at LG Daily'!H8 -> 6238 | J5: ='Maldives at LG Daily'!L8 -> 3968 | K5: ='Maldives at LG Daily'!M8 -> 4033 | L5: ='Maldives at LG Daily'!N8 -> 11294 | M5: ='Maldives at LG Daily'!O8 -> 2500 | N5: ='Maldives at LG Daily'!P8 -> 2748 | O5: ='Maldives at LG Daily'!Q8 -> 2100 | P5: ='Maldives at LG Daily'!R8 -> 484 | Q5: ='Maldives at LG Daily'!S8 -> 484 | ... AL5: ='Maldives at LG Daily'!AN8 -> 520 | AM5: ='Maldives at LG Daily'!AQ8 -> 66 | AN5: ='Maldives at LG Daily'!AR8 -> 0 | AO5: ='Maldives at LG Daily'!AS8 -> 179 | AP5: ='Maldives at LG Daily'!AT8 -> 94 | AQ5: ='Maldives at LG Daily'!AU8 -> 17 | AR5: ='Maldives at LG Daily'!AV8 -> 5 | AS5: ='Maldives at LG Daily'!AW8 -> 9 | AT5: ='Maldives at LG Daily'!AX8 -> 10 | ... BK5: ='Maldives at LG Daily'!BO8 -> 2
A6: Maldives at Landaa Giraavaru | B6: 5 | C6: 10 | D6: 2022 | E6: ='Maldives at LG Daily'!G9 -> 4056 | F6: 0.832 | G6: ='Maldives at LG Daily'!F9 -> 0 | H6: 1.24 | I6: ='Maldives at LG Daily'!H9 -> 5870 | J6: ='Maldives at LG Daily'!L9 -> 3861 | K6: ='Maldives at LG Daily'!M9 -> 4036 | L6: ='Maldives at LG Daily'!N9 -> 11168 | M6: ='Maldives at LG Daily'!O9 -> 2500 | N6: ='Maldives at LG Daily'!P9 -> 2658 | O6: ='Maldives at LG Daily'!Q9 -> 2000 | P6: ='Maldives at LG Daily'!R9 -> 474 | Q6: ='Maldives at LG Daily'!S9 -> 9018 | ... AL6: ='Maldives at LG Daily'!AN9 -> 0 | AM6: ='Maldives at LG Daily'!AQ9 -> 70 | AN6: ='Maldives at LG Daily'!AR9 -> 0 | AO6: ='Maldives at LG Daily'!AS9 -> 179 | AP6: ='Maldives at LG Daily'!AT9 -> 85 | AQ6: ='Maldives at LG Daily'!AU9 -> 18 | AR6: ='Maldives at LG Daily'!AV9 -> 5 | AS6: ='Maldives at LG Daily'!AW9 -> 8 | AT6: ='Maldives at LG Daily'!AX9 -> 10 | ... BK6: ='Maldives at LG Daily'!BO9 -> 3
A7: Maldives at Landaa Giraavaru | B7: 6 | C7: 10 | D7: 2022 | E7: ='Maldives at LG Daily'!G10 -> 7205 | F7: 0.832 | G7: ='Maldives at LG Daily'!F10 -> 90 | H7: 1.24 | I7: ='Maldives at LG Daily'!H10 -> 10014 | J7: ='Maldives at LG Daily'!L10 -> 3594 | K7: ='Maldives at LG Daily'!M10 -> 4179 | L7: ='Maldives at LG Daily'!N10 -> 11132 | M7: ='Maldives at LG Daily'!O10 -> 2600 | N7: ='Maldives at LG Daily'!P10 -> 2761 | O7: ='Maldives at LG Daily'!Q10 -> 1800 | P7: ='Maldives at LG Daily'!R10 -> 445 | Q7: ='Maldives at LG Daily'!S10 -> 800 | ... AL7: ='Maldives at LG Daily'!AN10 -> 5510 | AM7: ='Maldives at LG Daily'!AQ10 -> 52 | AN7: ='Maldives at LG Daily'!AR10 -> 0 | AO7: ='Maldives at LG Daily'!AS10 -> 200 | AP7: ='Maldives at LG Daily'!AT10 -> 69 | AQ7: ='Maldives at LG Daily'!AU10 -> 20 | AR7: ='Maldives at LG Daily'!AV10 -> 6 | AS7: ='Maldives at LG Daily'!AW10 -> 9 | AT7: ='Maldives at LG Daily'!AX10 -> 12 | ... BK7: ='Maldives at LG Daily'!BO10 -> 2
A8: Maldives at Landaa Giraavaru | B8: 7 | C8: 10 | D8: 2022 | E8: ='Maldives at LG Daily'!G11 -> 3923 | F8: 0.832 | G8: ='Maldives at LG Daily'!F11 -> 0 | H8: 1.24 | I8: ='Maldives at LG Daily'!H11 -> 17635 | J8: ='Maldives at LG Daily'!L11 -> 3293 | K8: ='Maldives at LG Daily'!M11 -> 4021 | L8: ='Maldives at LG Daily'!N11 -> 11388 | M8: ='Maldives at LG Daily'!O11 -> 2500 | N8: ='Maldives at LG Daily'!P11 -> 2915 | O8: ='Maldives at LG Daily'!Q11 -> 2200 | P8: ='Maldives at LG Daily'!R11 -> 466 | Q8: ='Maldives at LG Daily'!S11 -> 800 | ... AL8: ='Maldives at LG Daily'!AN11 -> 480 | AM8: ='Maldives at LG Daily'!AQ11 -> 71 | AN8: ='Maldives at LG Daily'!AR11 -> 0 | AO8: ='Maldives at LG Daily'!AS11 -> 214 | AP8: ='Maldives at LG Daily'!AT11 -> 97 | AQ8: ='Maldives at LG Daily'!AU11 -> 18 | AR8: ='Maldives at LG Daily'!AV11 -> 6 | AS8: ='Maldives at LG Daily'!AW11 -> 9 | AT8: ='Maldives at LG Daily'!AX11 -> 11 | ... BK8: ='Maldives at LG Daily'!BO11 -> 1
A9: Maldives at Landaa Giraavaru | B9: 8 | C9: 10 | D9: 2022 | E9: ='Maldives at LG Daily'!G12 -> 7139 | F9: 0.832 | G9: ='Maldives at LG Daily'!F12 -> 90 | H9: 1.24 | I9: ='Maldives at LG Daily'!H12 -> 7513 | J9: ='Maldives at LG Daily'!L12 -> 3701 | K9: ='Maldives at LG Daily'!M12 -> 3723 | L9: ='Maldives at LG Daily'!N12 -> 11752 | M9: ='Maldives at LG Daily'!O12 -> 2500 | N9: ='Maldives at LG Daily'!P12 -> 2996 | O9: ='Maldives at LG Daily'!Q12 -> 2300 | P9: ='Maldives at LG Daily'!R12 -> 443 | Q9: ='Maldives at LG Daily'!S12 -> 800 | ... AL9: ='Maldives at LG Daily'!AN12 -> 500 | AM9: ='Maldives at LG Daily'!AQ12 -> 38 | AN9: ='Maldives at LG Daily'!AR12 -> 0 | AO9: ='Maldives at LG Daily'!AS12 -> 202 | AP9: ='Maldives at LG Daily'!AT12 -> 111 | AQ9: ='Maldives at LG Daily'!AU12 -> 19 | AR9: ='Maldives at LG Daily'!AV12 -> 6 | AS9: ='Maldives at LG Daily'!AW12 -> 9 | AT9: ='Maldives at LG Daily'!AX12 -> 12 | ... BK9: ='Maldives at LG Daily'!BO12 -> 2
A10: Maldives at Landaa Giraavaru | B10: 9 | C10: 10 | D10: 2022 | E10: ='Maldives at LG Daily'!G13 -> 8458 | F10: 0.832 | G10: ='Maldives at LG Daily'!F13 -> 0 | H10: 1.24 | I10: ='Maldives at LG Daily'!H13 -> 5699 | J10: ='Maldives at LG Daily'!L13 -> 3657 | K10: ='Maldives at LG Daily'!M13 -> 3809 | L10: ='Maldives at LG Daily'!N13 -> 11679 | M10: ='Maldives at LG Daily'!O13 -> 2500 | N10: ='Maldives at LG Daily'!P13 -> 2801 | O10: ='Maldives at LG Daily'!Q13 -> 2200 | P10: ='Maldives at LG Daily'!R13 -> 473 | Q10: ='Maldives at LG Daily'!S13 -> 800 | ... AL10: ='Maldives at LG Daily'!AN13 -> 470 | AM10: ='Maldives at LG Daily'!AQ13 -> 55 | AN10: ='Maldives at LG Daily'!AR13 -> 0 | AO10: ='Maldives at LG Daily'!AS13 -> 197 | AP10: ='Maldives at LG Daily'!AT13 -> 145 | AQ10: ='Maldives at LG Daily'!AU13 -> 19 | AR10: ='Maldives at LG Daily'!AV13 -> 5 | AS10: ='Maldives at LG Daily'!AW13 -> 8 | AT10: ='Maldives at LG Daily'!AX13 -> 12 | ... BK10: ='Maldives at LG Daily'!BO13 -> 1
A11: Maldives at Landaa Giraavaru | B11: 10 | C11: 10 | D11: 2022 | E11: ='Maldives at LG Daily'!G14 -> 7884 | F11: 0.832 | G11: ='Maldives at LG Daily'!F14 -> 0 | H11: 1.24 | I11: ='Maldives at LG Daily'!H14 -> 6279 | J11: ='Maldives at LG Daily'!L14 -> 3285 | K11: ='Maldives at LG Daily'!M14 -> 3381 | L11: ='Maldives at LG Daily'!N14 -> 11478 | M11: ='Maldives at LG Daily'!O14 -> 2400 | N11: ='Maldives at LG Daily'!P14 -> 2684 | O11: ='Maldives at LG Daily'!Q14 -> 1800 | P11: ='Maldives at LG Daily'!R14 -> 465 | Q11: ='Maldives at LG Daily'!S14 -> 700 | ... AL11: ='Maldives at LG Daily'!AN14 -> 490 | AM11: ='Maldives at LG Daily'!AQ14 -> 38 | AN11: ='Maldives at LG Daily'!AR14 -> 0 | AO11: ='Maldives at LG Daily'!AS14 -> 230 | AP11: ='Maldives at LG Daily'!AT14 -> 110 | AQ11: ='Maldives at LG Daily'!AU14 -> 15 | AR11: ='Maldives at LG Daily'!AV14 -> 6 | AS11: ='Maldives at LG Daily'!AW14 -> 10 | AT11: ='Maldives at LG Daily'!AX14 -> 13 | ... BK11: ='Maldives at LG Daily'!BO14 -> 1
A12: Maldives at Landaa Giraavaru | B12: 11 | C12: 10 | D12: 2022 | E12: ='Maldives at LG Daily'!G15 -> 8298 | F12: 0.832 | G12: ='Maldives at LG Daily'!F15 -> 0 | H12: 1.24 | I12: ='Maldives at LG Daily'!H15 -> 5829 | J12: ='Maldives at LG Daily'!L15 -> 3102 | K12: ='Maldives at LG Daily'!M15 -> 3409 | L12: ='Maldives at LG Daily'!N15 -> 10860 | M12: ='Maldives at LG Daily'!O15 -> 2200 | N12: ='Maldives at LG Daily'!P15 -> 2506 | O12: ='Maldives at LG Daily'!Q15 -> 1900 | P12: ='Maldives at LG Daily'!R15 -> 480 | Q12: ='Maldives at LG Daily'!S15 -> 600 | ... AL12: ='Maldives at LG Daily'!AN15 -> 480 | AM12: ='Maldives at LG Daily'!AQ15 -> 32 | AN12: ='Maldives at LG Daily'!AR15 -> 0 | AO12: ='Maldives at LG Daily'!AS15 -> 218 | AP12: ='Maldives at LG Daily'!AT15 -> 72 | AQ12: ='Maldives at LG Daily'!AU15 -> 17 | AR12: ='Maldives at LG Daily'!AV15 -> 5 | AS12: ='Maldives at LG Daily'!AW15 -> 0 | AT12: ='Maldives at LG Daily'!AX15 -> 11 | ... BK12: ='Maldives at LG Daily'!BO15 -> 1
A13: Maldives at Landaa Giraavaru | B13: 12 | C13: 10 | D13: 2022 | E13: ='Maldives at LG Daily'!G16 -> 7407 | F13: 0.832 | G13: ='Maldives at LG Daily'!F16 -> 135 | H13: 1.24 | I13: ='Maldives at LG Daily'!H16 -> 6063 | J13: ='Maldives at LG Daily'!L16 -> 2909 | K13: ='Maldives at LG Daily'!M16 -> 3012 | L13: ='Maldives at LG Daily'!N16 -> 10242 | M13: ='Maldives at LG Daily'!O16 -> 2200 | N13: ='Maldives at LG Daily'!P16 -> 2474 | O13: ='Maldives at LG Daily'!Q16 -> 1700 | P13: ='Maldives at LG Daily'!R16 -> 446 | Q13: ='Maldives at LG Daily'!S16 -> 700 | ... AL13: ='Maldives at LG Daily'!AN16 -> 440 | AM13: ='Maldives at LG Daily'!AQ16 -> 19 | AN13: ='Maldives at LG Daily'!AR16 -> 0 | AO13: ='Maldives at LG Daily'!AS16 -> 186 | AP13: ='Maldives at LG Daily'!AT16 -> 113 | AQ13: ='Maldives at LG Daily'!AU16 -> 16 | AR13: ='Maldives at LG Daily'!AV16 -> 6 | AS13: ='Maldives at LG Daily'!AW16 -> 0 | AT13: ='Maldives at LG Daily'!AX16 -> 13 | ... BK13: ='Maldives at LG Daily'!BO16 -> 1
A14: Maldives at Landaa Giraavaru | B14: 13 | C14: 10 | D14: 2022 | E14: ='Maldives at LG Daily'!G17 -> 6662 | F14: 0.832 | G14: ='Maldives at LG Daily'!F17 -> 0 | H14: 1.24 | I14: ='Maldives at LG Daily'!H17 -> 8399 | J14: ='Maldives at LG Daily'!L17 -> 2885 | K14: ='Maldives at LG Daily'!M17 -> 2831 | L14: ='Maldives at LG Daily'!N17 -> 11299 | M14: ='Maldives at LG Daily'!O17 -> 2100 | N14: ='Maldives at LG Daily'!P17 -> 2435 | O14: ='Maldives at LG Daily'!Q17 -> 1400 | P14: ='Maldives at LG Daily'!R17 -> 521 | Q14: ='Maldives at LG Daily'!S17 -> 600 | ... AL14: ='Maldives at LG Daily'!AN17 -> 460 | AM14: ='Maldives at LG Daily'!AQ17 -> 0 | AN14: ='Maldives at LG Daily'!AR17 -> 0 | AO14: ='Maldives at LG Daily'!AS17 -> 199 | AP14: ='Maldives at LG Daily'!AT17 -> 111 | AQ14: ='Maldives at LG Daily'!AU17 -> 16 | AR14: ='Maldives at LG Daily'!AV17 -> 6 | AS14: ='Maldives at LG Daily'!AW17 -> 0 | AT14: ='Maldives at LG Daily'!AX17 -> 6 | ... BK14: ='Maldives at LG Daily'!BO17 -> 0
... A31: Maldives at Landaa Giraavaru | B31: 30 | C31: 10 | D31: 2022 | E31: ='Maldives at LG Daily'!G34 -> 3678 | F31: 1.832 | G31: ='Maldives at LG Daily'!F34 -> 45 | H31: 2.24 | I31: ='Maldives at LG Daily'!H34 -> 12511 | J31: ='Maldives at LG Daily'!L34 -> 3694 | K31: ='Maldives at LG Daily'!M34 -> 3851 | L31: ='Maldives at LG Daily'!N34 -> 11298 | M31: ='Maldives at LG Daily'!O34 -> 2600 | N31: ='Maldives at LG Daily'!P34 -> 2793 | O31: ='Maldives at LG Daily'!Q34 -> 1800 | P31: ='Maldives at LG Daily'!R34 -> 493 | Q31: ='Maldives at LG Daily'!S34 -> 700 | ... AL31: ='Maldives at LG Daily'!AN34 -> 490 | AM31: ='Maldives at LG Daily'!AQ34 -> 194 | AN31: ='Maldives at LG Daily'!AR34 -> 0 | AO31: ='Maldives at LG Daily'!AS34 -> 0 | AP31: ='Maldives at LG Daily'!AT34 -> 149 | AQ31: ='Maldives at LG Daily'!AU34 -> 26 | AR31: ='Maldives at LG Daily'!AV34 -> 0 | AS31: ='Maldives at LG Daily'!AW34 -> 0 | AT31: ='Maldives at LG Daily'!AX34 -> 0 | ... BK31: ='Maldives at LG Daily'!BO34 -> 0
A32: Maldives at Landaa Giraavaru | B32: 31 | C32: 10 | D32: 2022 | E32: ='Maldives at LG Daily'!G35 -> 7457 | F32: 0.832 | G32: ='Maldives at LG Daily'!F36 -> 0 | H32: 1.24 | I32: ='Maldives at LG Daily'!H36 -> 0 | J32: ='Maldives at LG Daily'!L35 -> 3747 | K32: ='Maldives at LG Daily'!M35 -> 3713 | L32: ='Maldives at LG Daily'!N35 -> 11230 | M32: ='Maldives at LG Daily'!O35 -> 2400 | N32: ='Maldives at LG Daily'!P35 -> 2712 | O32: ='Maldives at LG Daily'!Q35 -> 1900 | P32: ='Maldives at LG Daily'!R35 -> 471 | Q32: ='Maldives at LG Daily'!S35 -> 700 | ... AL32: ='Maldives at LG Daily'!AN35 -> 510 | AM32: ='Maldives at LG Daily'!AQ35 -> 202 | AN32: ='Maldives at LG Daily'!AR35 -> 0 | AO32: ='Maldives at LG Daily'!AS35 -> 41 | AP32: ='Maldives at LG Daily'!AT35 -> 133 | AQ32: ='Maldives at LG Daily'!AU35 -> 18 | AR32: ='Maldives at LG Daily'!AV35 -> 6 | AS32: ='Maldives at LG Daily'!AW35 -> 15 | AT32: ='Maldives at LG Daily'!AX35 -> 11 | ... BK32: ='Maldives at LG Daily'!BO35 -> 1

Sheet Maldives at LG Daily
A2: Days | C2: Electricity Meter (KWh) | E2: Gas Kg | G2: GENSET NO 1 | H2: GENSET NO 2 | I2: GENSET NO 3 | J2: GENSET NO 4 | K2: GENSET NO 5 | L2: Main BLU FEEDER PANEL 1 | M2: Main BLU FEEDER PANEL 2 | N2: Main POWER HOUSE FEEDER PANEL NO:3 | O2: Main Kitchen -7 | P2: Main Kitchen -10 | Q2: Water treatment Plant | R2: Sewage treatment Plant | S2: Laundry--8SSB (Machineries) | T2: Laundry-9 (HR/Tuck Shop Building) | U2: New staff accomodation (E0) | V2: Staff block-16(E2-E3) | W2: Staff Block Feeder-3(E4-E5) | X2: Management block-5 (M1 to M6) | Y2: SNR STAFF BLOCK (PC Block) | Z2: BOAT DOCK FEEDER - 22 | AA2: RECEPTION Building Full (Finance/Reservation) | AB2: DIVE CENTER (Inc MDC and Recreation) | AC2: 301-307 | AD2: 308-314 | AE2: 315-320 | AF2: 401-407 | AG2: 408-414 | AH2: 415-420 | AI2: SPA - 1 | AJ2: SPA - 2 | AK2: BLU KITCHEN - 1 | AL2: BLU KITCHEN - 2 | AM2: AL BARAKATH | AN2: STAFF KITCHEN | AO2: Water m3 | AQ2: R/O Plant A | AR2: R/O Plant B | AS2: R/O Plant C | AT2: R/O Plant D | AU2: Laundry | AV2: Staff Block - E0 | AW2: Staff Block - E1 | AX2: Staff Block - E2 | AY2: Staff Block - E3 | AZ2: Staff Block - E4 | BA2: Staff Block - E5 | BB2: Management Block | BC2: PC Block | BD2: GM Bungalow | BE2: Boat Dock | BF2: Supply Jetty | BG2: Main Kitchen | BH2: Day Facility | BI2: Reception | BJ2: Main Pool | BK2: Dive Center | BL2: Albarakthu | BM2: Blu Resturant | BN2: Main Jetty | BO2: Landaa Estate
A3: Date | C3: Reading KWH | D3: Difference KWH | E3: Reading Kg | F3: Difference Kg | G3: KWh | H3: KWh | I3: KWh | J3: KWh | K3: KWh | L3: KWh | M3: KWh | N3: KWh | O3: KWh | P3: KWh | Q3: KWh | R3: KWh | S3: KWh | T3: KWh | U3: KWh | V3: KWh | W3: KWh | X3: KWh | Y3: KWh | Z3: KWh | AA3: KWh | AB3: KWh | AC3: KWh | AD3: KWh | AE3: KWh | AF3: KWh | AG3: KWh | AH3: KWh | AI3: KWh | AJ3: KWh | AK3: KWh | AL3: KWh | AM3: KWh | AN3: KWh | AO3: Reading m³ | AP3: Daily Consumption m³ | AQ3: Daily Consumption m³ | AR3: Daily Consumption m³ | AS3: Daily Consumption m³ | AT3: Daily Consumption m³ | AU3: Daily Consumption m³ | AV3: Daily Consumption m³ | AW3: Daily Consumption m³ | AX3: Daily Consumption m³ | AY3: Daily Consumption m³ | AZ3: Daily Consumption m³ | BA3: Daily Consumption m³ | BB3: Daily Consumption m³ | BC3: Daily Consumption m³ | BD3: Daily Consumption m³ | BE3: Daily Consumption m³ | BF3: Daily Consumption m³ | BG3: Daily Consumption m³ | BH3: Daily Consumption m³ | BI3: Daily Consumption m³ | BJ3: Daily Consumption m³ | BK3: Daily Consumption m³ | BL3: Daily Consumption m³ | BM3: Daily Consumption m³ | BN3: Daily Consumption m³ | BO3: Daily Consumption m³ | BP3: ROOM NIGHTS | BQ3: Total Food Covers
A4: 44834 | C4: 103210660 | D4: 31701 | E4: ='[1]Gas-2'!G5 -> 0 | F4: 90 | AO4: =SUM([1]WATER!G6,[1]WATER!L6,[1]WATER!Q6,[1]WATER!B6) -> 1132736 | AP4: 318 | BP4: ='Room Nights and Food Covers'!B4 -> 14.6 | BQ4: ='Room Nights and Food Covers'!C4 -> 159
A5: =A4+1 -> 44835 | C5: =SUM('GENSET #1'!C10+'GENSET #2'!C10+'GENSET #3'!C10+'GENSET #4'!C10+'GENSET #5'!C10) -> 103233890 | D5: =IF((C5-C4<0), "0",C5-C4) -> 23230 | E5: ='Gas-2'!G6 -> 270 | F5: =IF((E5-E4<0), "0",E5-E4) -> 270 | G5: ='GENSET #1'!D10 -> 6494 | H5: ='GENSET #2'!D10 -> 7742 | I5: ='GENSET #3'!D10 -> 0 | J5: ='GENSET #4'!D10 -> 2524 | K5: ='GENSET #5'!D10 -> 6470 | L5: ='FEEDER Consumption '!E5 -> 3070 | M5: ='FEEDER Consumption '!J5 -> 3775 | N5: ='FEEDER Consumption '!O5 -> 10853 | O5: ='FEEDER Consumption '!T5 -> 2300 | P5: ='FEEDER Consumption '!Y5 -> 2737 | Q5: ='FEEDER Consumption '!AD5 -> 2000 | R5: ='FEEDER Consumption '!AJ5 -> 475 | S5: ='FEEDER Consumption '!AO5 -> 700 | T5: ='FEEDER Consumption '!AT5 -> 1300 | U5: ='FEEDER Consumption '!AY5 -> 321 | V5: ='FEEDER Consumption '!BI5 -> 300 | W5: ='FEEDER Consumption '!BI5 -> 300 | X5: ='FEEDER Consumption '!BN5 -> 500 | Y5: ='FEEDER Consumption '!BS5 -> 100 | Z5: ='FEEDER Consumption '!BX5 -> 420 | AA5: ='FEEDER Consumption '!CC5 -> 1100 | AB5: ='FEEDER Consumption '!CH5 -> 450 | AC5: ='FEEDER Consumption '!CM5 -> 1400 | AD5: ='FEEDER Consumption '!CR5 -> 1260 | AE5: ='FEEDER Consumption '!DB5 -> 1740 | AF5: ='FEEDER Consumption '!DB5 -> 1740 | AG5: ='FEEDER Consumption '!DG5 -> 1140 | AH5: ='FEEDER Consumption '!DL5 -> 0 | AI5: ='FEEDER Consumption '!DQ5 -> 580 | AJ5: ='FEEDER Consumption '!DV5 -> 210 | AK5: ='FEEDER Consumption '!EA5 -> 7270 | AL5: ='FEEDER Consumption '!EF5 -> 500 | AM5: ='FEEDER Consumption '!EK5 -> 460 | AN5: ='FEEDER Consumption '!EP5 -> 940 | AO5: =SUM([1]WATER!C6,[1]WATER!H6,[1]WATER!M6,[1]WATER!R6) -> 1133118 | AP5: =IF((AO5-AO4<0), "0",AO5-AO4) -> 382 | AQ5: =WATER!D6 -> 74 | AR5: =WATER!I6 -> 0 | AS5: =WATER!N6 -> 190 | AT5: =WATER!S6 -> 10 | AU5: =WATER!AD6 -> 18 | AV5: =WATER!AI6 -> 6 | AW5: =WATER!AN6 -> 0 | AX5: =WATER!AS6 -> 10 | AY5: =WATER!AX6 -> 8 | AZ5: =WATER!BC6 -> 7 | BA5: =WATER!BH6 -> 10 | BB5: =WATER!BM6 -> 5 | BC5: =WATER!BR6 -> 1 | BD5: =WATER!BW6 -> 0 | BE5: =WATER!CB6 -> 4 | BF5: =WATER!CG6 -> 1 | BG5: =WATER!CL6 -> 24 | BH5: =WATER!CQ6 -> 7 | BI5: =WATER!CV6 -> 0 | BJ5: =WATER!DA6 -> 1 | BK5: =WATER!DF6 -> 1 | BL5: =WATER!DK6 -> 0 | BM5: =WATER!DP6 -> 7 | BN5: =WATER!DU6 -> 0 | BO5: =WATER!DZ6 -> 0 | BP5: ='Room Nights and Food Covers'!B5 -> 11.7 | BQ5: ='Room Nights and Food Covers'!C5 -> 94
A6: =A5+1 -> 44836 | C6: =SUM('GENSET #1'!C11+'GENSET #2'!C11+'GENSET #3'!C11+'GENSET #4'!C11+'GENSET #5'!C11) -> 103256791 | D6: =IF((C6-C5<0), "0",C6-C5) -> 22901 | E6: ='Gas-2'!G7 -> 270 | F6: =IF((E6-E5<0), "0",E6-E5) -> 0 | G6: ='GENSET #1'!D11 -> 7927 | H6: ='GENSET #2'!D11 -> 6795 | I6: ='GENSET #3'!D11 -> 0 | J6: ='GENSET #4'!D11 -> 240 | K6: ='GENSET #5'!D11 -> 7939 | L6: ='FEEDER Consumption '!E6 -> 3240 | M6: ='FEEDER Consumption '!J6 -> 3366 | N6: ='FEEDER Consumption '!O6 -> 11442 | O6: ='FEEDER Consumption '!T6 -> 2300 | P6: ='FEEDER Consumption '!Y6 -> 2724 | Q6: ='FEEDER Consumption '!AD6 -> 2000 | R6: ='FEEDER Consumption '!AJ6 -> 532 | S6: ='FEEDER Consumption '!AO6 -> 700 | T6: ='FEEDER Consumption '!AT6 -> 1000 | U6: ='FEEDER Consumption '!AY6 -> 340 | V6: ='FEEDER Consumption '!BI6 -> 300 | W6: ='FEEDER Consumption '!BI6 -> 300 | X6: ='FEEDER Consumption '!BN6 -> 600 | Y6: ='FEEDER Consumption '!BS6 -> 140 | Z6: ='FEEDER Consumption '!BX6 -> 480 | AA6: ='FEEDER Consumption '!CC6 -> 1200 | AB6: ='FEEDER Consumption '!CH6 -> 430 | AC6: ='FEEDER Consumption '!CM6 -> 0 | AD6: ='FEEDER Consumption '!CR6 -> 0 | AE6: ='FEEDER Consumption '!DB6 -> 0 | AF6: ='FEEDER Consumption '!DB6 -> 0 | AG6: ='FEEDER Consumption '!DG6 -> 0 | AH6: ='FEEDER Consumption '!DL6 -> 0 | AI6: ='FEEDER Consumption '!DQ6 -> 0 | AJ6: ='FEEDER Consumption '!DV6 -> 0 | AK6: ='FEEDER Consumption '!EA6 -> 0 | AL6: ='FEEDER Consumption '!EF6 -> 0 | AM6: ='FEEDER Consumption '!EK6 -> 0 | AN6: ='FEEDER Consumption '!EP6 -> 0 | AO6: =SUM([1]WATER!C7,[1]WATER!H7,[1]WATER!M7,[1]WATER!R7) -> 1133470 | AP6: =IF((AO6-AO5<0), "0",AO6-AO5) -> 352 | AQ6: =WATER!D7 -> 71 | AR6: =WATER!I7 -> 0 | AS6: =WATER!N7 -> 143 | AT6: =WATER!S7 -> 113 | AU6: =WATER!AD7 -> 17 | AV6: =WATER!AI7 -> 13 | AW6: =WATER!AN7 -> 16 | AX6: =WATER!AS7 -> 12 | AY6: =WATER!AX7 -> 7 | AZ6: =WATER!BC7 -> 7 | BA6: =WATER!BH7 -> 10 | BB6: =WATER!BM7 -> 10 | BC6: =WATER!BR7 -> 1 | BD6: =WATER!BW7 -> 1 | BE6: =WATER!CB7 -> 5 | BF6: =WATER!CG7 -> 1 | BG6: =WATER!CL7 -> 22 | BH6: =WATER!CQ7 -> 8 | BI6: =WATER!CV7 -> 1 | BJ6: =WATER!DA7 -> 1 | BK6: =WATER!DF7 -> 2 | BL6: =WATER!DK7 -> 5 | BM6: =WATER!DP7 -> 5 | BN6: =WATER!DU7 -> 1 | BO6: =WATER!DZ7 -> 2 | BP6: ='Room Nights and Food Covers'!B6 -> 15.5 | BQ6: ='Room Nights and Food Covers'!C6 -> 119
A7: =A6+1 -> 44837 | C7: =SUM('GENSET #1'!C12+'GENSET #2'!C12+'GENSET #3'!C12+'GENSET #4'!C12+'GENSET #5'!C12) -> 103280189 | D7: =IF((C7-C6<0), "0",C7-C6) -> 23398 | E7: ='Gas-2'!G8 -> 315 | F7: =IF((E7-E6<0), "0",E7-E6) -> 45 | G7: ='GENSET #1'!D12 -> 7798 | H7: ='GENSET #2'!D12 -> 6146 | I7: ='GENSET #3'!D12 -> 0 | J7: ='GENSET #4'!D12 -> 1563 | K7: ='GENSET #5'!D12 -> 7891 | L7: ='FEEDER Consumption '!E7 -> 3803 | M7: ='FEEDER Consumption '!J7 -> 3651 | N7: ='FEEDER Consumption '!O7 -> 10493 | O7: ='FEEDER Consumption '!T7 -> 2400 | P7: ='FEEDER Consumption '!Y7 -> 2719 | Q7: ='FEEDER Consumption '!AD7 -> 2100 | R7: ='FEEDER Consumption '!AJ7 -> 465 | S7: ='FEEDER Consumption '!AO7 -> 0 | T7: ='FEEDER Consumption '!AT7 -> 1300 | U7: ='FEEDER Consumption '!AY7 -> 327 | V7: ='FEEDER Consumption '!BI7 -> 200 | W7: ='FEEDER Consumption '!BI7 -> 200 | X7: ='FEEDER Consumption '!BN7 -> 500 | Y7: ='FEEDER Consumption '!BS7 -> 130 | Z7: ='FEEDER Consumption '!BX7 -> 410 | AA7: ='FEEDER Consumption '!CC7 -> 1100 | AB7: ='FEEDER Consumption '!CH7 -> 510 | AC7: ='FEEDER Consumption '!CM7 -> 910 | AD7: ='FEEDER Consumption '!CR7 -> 700 | AE7: ='FEEDER Consumption '!DB7 -> 790 | AF7: ='FEEDER Consumption '!DB7 -> 790 | AG7: ='FEEDER Consumption '!DG7 -> 750 | AH7: ='FEEDER Consumption '!DL7 -> 0 | AI7: ='FEEDER Consumption '!DQ7 -> 320 | AJ7: ='FEEDER Consumption '!DV7 -> 110 | AK7: ='FEEDER Consumption '!EA7 -> 1120 | AL7: ='FEEDER Consumption '!EF7 -> 270 | AM7: ='FEEDER Consumption '!EK7 -> 400 | AN7: ='FEEDER Consumption '!EP7 -> 500 | AO7: =SUM([1]WATER!C8,[1]WATER!H8,[1]WATER!M8,[1]WATER!R8) -> 1133855 | AP7: =IF((AO7-AO6<0), "0",AO7-AO6) -> 385 | AQ7: =WATER!D8 -> 65 | AR7: =WATER!I8 -> 0 | AS7: =WATER!N8 -> 197 | AT7: =WATER!S8 -> 109 | AU7: =WATER!AD8 -> 18 | AV7: =WATER!AI8 -> 4 | AW7: =WATER!AN8 -> 9 | AX7: =WATER!AS8 -> 11 | AY7: =WATER!AX8 -> 7 | AZ7: =WATER!BC8 -> 8 | BA7: =WATER!BH8 -> 0 | BB7: =WATER!BM8 -> 8 | BC7: =WATER!BR8 -> 0 | BD7: =WATER!BW8 -> 0 | BE7: =WATER!CB8 -> 4 | BF7: =WATER!CG8 -> 1 | BG7: =WATER!CL8 -> 26 | BH7: =WATER!CQ8 -> 7 | BI7: =WATER!CV8 -> 0 | BJ7: =WATER!DA8 -> 0 | BK7: =WATER!DF8 -> 3 | BL7: =WATER!DK8 -> 3 | BM7: =WATER!DP8 -> 0 | BN7: =WATER!DU8 -> 1 | BO7: =WATER!DZ8 -> 1 | BP7: ='Room Nights and Food Covers'!B7 -> 19.4 | BQ7: ='Room Nights and Food Covers'!C7 -> 156
A8: =A7+1 -> 44838 | C8: =SUM('GENSET #1'!C13+'GENSET #2'!C13+'GENSET #3'!C13+'GENSET #4'!C13+'GENSET #5'!C13) -> 103304862 | D8: =IF((C8-C7<0), "0",C8-C7) -> 24673 | E8: ='Gas-2'!G9 -> 270 | F8: =IF((E8-E7<0), "0",E8-E7) -> 0 | G8: ='GENSET #1'!D13 -> 8163 | H8: ='GENSET #2'!D13 -> 6238 | I8: ='GENSET #3'!D13 -> 0 | J8: ='GENSET #4'!D13 -> 2154 | K8: ='GENSET #5'!D13 -> 8118 | L8: ='FEEDER Consumption '!E8 -> 3968 | M8: ='FEEDER Consumption '!J8 -> 4033 | N8: ='FEEDER Consumption '!O8 -> 11294 | O8: ='FEEDER Consumption '!T8 -> 2500 | P8: ='FEEDER Consumption '!Y8 -> 2748 | Q8: ='FEEDER Consumption '!AD8 -> 2100 | R8: ='FEEDER Consumption '!AJ8 -> 484 | S8: ='FEEDER Consumption '!AO8 -> 484 | T8: ='FEEDER Consumption '!AT8 -> 900 | U8: ='FEEDER Consumption '!AY8 -> 372 | V8: ='FEEDER Consumption '!BI8 -> 300 | W8: ='FEEDER Consumption '!BI8 -> 300 | X8: ='FEEDER Consumption '!BN8 -> 500 | Y8: ='FEEDER Consumption '!BS8 -> 150 | Z8: ='FEEDER Consumption '!BX8 -> 420 | AA8: ='FEEDER Consumption '!CC8 -> 1200 | AB8: ='FEEDER Consumption '!CH8 -> 480 | AC8: ='FEEDER Consumption '!CM8 -> 860 | AD8: ='FEEDER Consumption '!CR8 -> 850 | AE8: ='FEEDER Consumption '!DB8 -> 830 | AF8: ='FEEDER Consumption '!DB8 -> 830 | AG8: ='FEEDER Consumption '!DG8 -> 780 | AH8: ='FEEDER Consumption '!DL8 -> 580 | AI8: ='FEEDER Consumption '!DQ8 -> 290 | AJ8: ='FEEDER Consumption '!DV8 -> 170 | AK8: ='FEEDER Consumption '!EA8 -> 800 | AL8: ='FEEDER Consumption '!EF8 -> 250 | AM8: ='FEEDER Consumption '!EK8 -> 340 | AN8: ='FEEDER Consumption '!EP8 -> 520 | AO8: =SUM([1]WATER!C9,[1]WATER!H9,[1]WATER!M9,[1]WATER!R9) -> 1134230 | AP8: =IF((AO8-AO7<0), "0",AO8-AO7) -> 375 | AQ8: =WATER!D9 -> 66 | AR8: =WATER!I9 -> 0 | AS8: =WATER!N9 -> 179 | AT8: =WATER!S9 -> 94 | AU8: =WATER!AD9 -> 17 | AV8: =WATER!AI9 -> 5 | AW8: =WATER!AN9 -> 9 | AX8: =WATER!AS9 -> 10 | AY8: =WATER!AX9 -> 7 | AZ8: =WATER!BC9 -> 7 | BA8: =WATER!BH9 -> 0 | BB8: =WATER!BM9 -> 7 | BC8: =WATER!BR9 -> 4 | BD8: =WATER!BW9 -> 0 | BE8: =WATER!CB9 -> 6 | BF8: =WATER!CG9 -> 5 | BG8: =WATER!CL9 -> 24 | BH8: =WATER!CQ9 -> 7 | BI8: =WATER!CV9 -> 1 | BJ8: =WATER!DA9 -> 0 | BK8: =WATER!DF9 -> 2 | BL8: =WATER!DK9 -> 5 | BM8: =WATER!DP9 -> 50 | BN8: =WATER!DU9 -> 1 | BO8: =WATER!DZ9 -> 2 | BP8: ='Room Nights and Food Covers'!B8 -> 18.4 | BQ8: ='Room Nights and Food Covers'!C8 -> 141
A9: =A8+1 -> 44839 | C9: =SUM('GENSET #1'!C14+'GENSET #2'!C14+'GENSET #3'!C14+'GENSET #4'!C14+'GENSET #5'!C14) -> 103330061 | D9: =IF((C9-C8<0), "0",C9-C8) -> 25199 | E9: ='Gas-2'!G10 -> 225 | F9: =IF((E9-E8<0), "0",E9-E8) -> 0 | G9: ='GENSET #1'!D14 -> 4056 | H9: ='GENSET #2'!D14 -> 5870 | I9: ='GENSET #3'!D14 -> 7678 | J9: ='GENSET #4'!D14 -> 2292 | K9: ='GENSET #5'!D14 -> 5303 | L9: ='FEEDER Consumption '!E9 -> 3861 | M9: ='FEEDER Consumption '!J9 -> 4036 | N9: ='FEEDER Consumption '!O9 -> 11168 | O9: ='FEEDER Consumption '!T9 -> 2500 | P9: ='FEEDER Consumption '!Y9 -> 2658 | Q9: ='FEEDER Consumption '!AD9 -> 2000 | R9: ='FEEDER Consumption '!AJ9 -> 474 | S9: ='FEEDER Consumption '!AO9 -> 9018 | T9: ='FEEDER Consumption '!AT9 -> 1400 | U9: ='FEEDER Consumption '!AY9 -> 373 | V9: ='FEEDER Consumption '!BI9 -> 300 | W9: ='FEEDER Consumption '!BI9 -> 300 | X9: ='FEEDER Consumption '!BN9 -> 500 | Y9: ='FEEDER Consumption '!BS9 -> 130 | Z9: ='FEEDER Consumption '!BX9 -> 380 | AA9: ='FEEDER Consumption '!CC9 -> 1300 | AB9: ='FEEDER Consumption '!CH9 -> 490 | AC9: ='FEEDER Consumption '!CM9 -> 970 | AD9: ='FEEDER Consumption '!CR9 -> 880 | AE9: ='FEEDER Consumption '!DB9 -> 960 | AF9: ='FEEDER Consumption '!DB9 -> 960 | AG9: ='FEEDER Consumption '!DG9 -> 700 | AH9: ='FEEDER Consumption '!DL9 -> 600 | AI9: ='FEEDER Consumption '!DQ9 -> 320 | AJ9: ='FEEDER Consumption '!DV9 -> 140 | AK9: ='FEEDER Consumption '!EA9 -> 910 | AL9: ='FEEDER Consumption '!EF9 -> 260 | AM9: ='FEEDER Consumption '!EK9 -> 400 | AN9: ='FEEDER Consumption '!EP9 -> 0 | AO9: =SUM([1]WATER!C10,[1]WATER!H10,[1]WATER!M10,[1]WATER!R10) -> 1134601 | AP9: =IF((AO9-AO8<0), "0",AO9-AO8) -> 371 | AQ9: =WATER!D10 -> 70 | AR9: =WATER!I10 -> 0 | AS9: =WATER!N10 -> 179 | AT9: =WATER!S10 -> 85 | AU9: =WATER!AD10 -> 18 | AV9: =WATER!AI10 -> 5 | AW9: =WATER!AN10 -> 8 | AX9: =WATER!AS10 -> 10 | AY9: =WATER!AX10 -> 7 | AZ9: =WATER!BC10 -> 8 | BA9: =WATER!BH10 -> 19 | BB9: =WATER!BM10 -> 7 | BC9: =WATER!BR10 -> 1 | BD9: =WATER!BW10 -> 1 | BE9: =WATER!CB10 -> 4 | BF9: =WATER!CG10 -> 2 | BG9: =WATER!CL10 -> 27 | BH9: =WATER!CQ10 -> 7 | BI9: =WATER!CV10 -> 1 | BJ9: =WATER!DA10 -> 3 | BK9: =WATER!DF10 -> 3 | BL9: =WATER!DK10 -> 9 | BM9: =WATER!DP10 -> 0 | BN9: =WATER!DU10 -> 10 | BO9: =WATER!DZ10 -> 3 | BP9: ='Room Nights and Food Covers'!B9 -> 18.4 | BQ9: ='Room Nights and Food Covers'!C9 -> 131
A10: =A9+1 -> 44840 | C10: =SUM('GENSET #1'!C15+'GENSET #2'!C15+'GENSET #3'!C15+'GENSET #4'!C15+'GENSET #5'!C15) -> 103354092 | D10: =IF((C10-C9<0), "0",C10-C9) -> 24031 | E10: ='Gas-2'!G11 -> 315 | F10: =IF((E10-E9<0), "0",E10-E9) -> 90 | G10: ='GENSET #1'!D15 -> 7205 | H10: ='GENSET #2'!D15 -> 10014 | I10: ='GENSET #3'!D15 -> 2203 | J10: ='GENSET #4'!D15 -> 580 | K10: ='GENSET #5'!D15 -> 4029 | L10: ='FEEDER Consumption '!E10 -> 3594 | M10: ='FEEDER Consumption '!J10 -> 4179 | N10: ='FEEDER Consumption '!O10 -> 11132 | O10: ='FEEDER Consumption '!T10 -> 2600 | P10: ='FEEDER Consumption '!Y10 -> 2761 | Q10: ='FEEDER Consumption '!AD10 -> 1800 | R10: ='FEEDER Consumption '!AJ10 -> 445 | S10: ='FEEDER Consumption '!AO10 -> 800 | T10: ='FEEDER Consumption '!AT10 -> 700 | U10: ='FEEDER Consumption '!AY10 -> 387 | V10: ='FEEDER Consumption '!BI10 -> 200 | W10: ='FEEDER Consumption '!BI10 -> 200 | X10: ='FEEDER Consumption '!BN10 -> 600 | Y10: ='FEEDER Consumption '!BS10 -> 150 | Z10: ='FEEDER Consumption '!BX10 -> 390 | AA10: ='FEEDER Consumption '!CC10 -> 1200 | AB10: ='FEEDER Consumption '!CH10 -> 490 | AC10: ='FEEDER Consumption '!CM10 -> 890 | AD10: ='FEEDER Consumption '!CR10 -> 770 | AE10: ='FEEDER Consumption '!DB10 -> 1030 | AF10: ='FEEDER Consumption '!DB10 -> 1030 | AG10: ='FEEDER Consumption '!DG10 -> 830 | AH10: ='FEEDER Consumption '!DL10 -> 640 | AI10: ='FEEDER Consumption '!DQ10 -> 310 | AJ10: ='FEEDER Consumption '!DV10 -> 120 | AK10: ='FEEDER Consumption '!EA10 -> 880 | AL10: ='FEEDER Consumption '!EF10 -> 240 | AM10: ='FEEDER Consumption '!EK10 -> 350 | AN10: ='FEEDER Consumption '!EP10 -> 5510 | AO10: =SUM([1]WATER!C11,[1]WATER!H11,[1]WATER!M11,[1]WATER!R11) -> 1134986 | AP10: =IF((AO10-AO9<0), "0",AO10-AO9) -> 385 | AQ10: =WATER!D11 -> 52 | AR10: =WATER!I11 -> 0 | AS10: =WATER!N11 -> 200 | AT10: =WATER!S11 -> 69 | AU10: =WATER!AD11 -> 20 | AV10: =WATER!AI11 -> 6 | AW10: =WATER!AN11 -> 9 | AX10: =WATER!AS11 -> 12 | AY10: =WATER!AX11 -> 7 | AZ10: =WATER!BC11 -> 7 | BA10: =WATER!BH11 -> 7 | BB10: =WATER!BM11 -> 8 | BC10: =WATER!BR11 -> 2 | BD10: =WATER!BW11 -> -1 | BE10: =WATER!CB11 -> 4 | BF10: =WATER!CG11 -> 1 | BG10: =WATER!CL11 -> 24 | BH10: =WATER!CQ11 -> 7 | BI10: =WATER!CV11 -> 0 | BJ10: =WATER!DA11 -> 3 | BK10: =WATER!DF11 -> 4 | BL10: =WATER!DK11 -> 4 | BM10: =WATER!DP11 -> 38 | BN10: =WATER!DU11 -> 1 | BO10: =WATER!DZ11 -> 2 | BP10: ='Room Nights and Food Covers'!B10 -> 14.6 | BQ10: ='Room Nights and Food Covers'!C10 -> 122
A11: =A10+1 -> 44841 | C11: =SUM('GENSET #1'!C16+'GENSET #2'!C16+'GENSET #3'!C16+'GENSET #4'!C16+'GENSET #5'!C16) -> 103378690 | D11: =IF((C11-C10<0), "0",C11-C10) -> 24598 | E11: ='Gas-2'!G12 -> 225 | F11: =IF((E11-E10<0), "0",E11-E10) -> 0 | G11: ='GENSET #1'!D16 -> 3923 | H11: ='GENSET #2'!D16 -> 17635 | I11: ='GENSET #3'!D16 -> 0 | J11: ='GENSET #4'!D16 -> 3040 | K11: ='GENSET #5'!D16 -> 0 | L11: ='FEEDER Consumption '!E11 -> 3293 | M11: ='FEEDER Consumption '!J11 -> 4021 | N11: ='FEEDER Consumption '!O11 -> 11388 | O11: ='FEEDER Consumption '!T11 -> 2500 | P11: ='FEEDER Consumption '!Y11 -> 2915 | Q11: ='FEEDER Consumption '!AD11 -> 2200 | R11: ='FEEDER Consumption '!AJ11 -> 466 | S11: ='FEEDER Consumption '!AO11 -> 800 | T11: ='FEEDER Consumption '!AT11 -> 1400 | U11: ='FEEDER Consumption '!AY11 -> 399 | V11: ='FEEDER Consumption '!BI11 -> 300 | W11: ='FEEDER Consumption '!BI11 -> 300 | X11: ='FEEDER Consumption '!BN11 -> 600 | Y11: ='FEEDER Consumption '!BS11 -> 160 | Z11: ='FEEDER Consumption '!BX11 -> 400 | AA11: ='FEEDER Consumption '!CC11 -> 1200 | AB11: ='FEEDER Consumption '!CH11 -> 550 | AC11: ='FEEDER Consumption '!CM11 -> 890 | AD11: ='FEEDER Consumption '!CR11 -> 750 | AE11: ='FEEDER Consumption '!DB11 -> 1090 | AF11: ='FEEDER Consumption '!DB11 -> 1090 | AG11: ='FEEDER Consumption '!DG11 -> 870 | AH11: ='FEEDER Consumption '!DL11 -> 600 | AI11: ='FEEDER Consumption '!DQ11 -> 120 | AJ11: ='FEEDER Consumption '!DV11 -> 110 | AK11: ='FEEDER Consumption '!EA11 -> 790 | AL11: ='FEEDER Consumption '!EF11 -> 240 | AM11: ='FEEDER Consumption '!EK11 -> 210 | AN11: ='FEEDER Consumption '!EP11 -> 480 | AO11: =SUM([1]WATER!C12,[1]WATER!H12,[1]WATER!M12,[1]WATER!R12) -> 1135359 | AP11: =IF((AO11-AO10<0), "0",AO11-AO10) -> 373 | AQ11: =WATER!D12 -> 71 | AR11: =WATER!I12 -> 0 | AS11: =WATER!N12 -> 214 | AT11: =WATER!S12 -> 97 | AU11: =WATER!AD12 -> 18 | AV11: =WATER!AI12 -> 6 | AW11: =WATER!AN12 -> 9 | AX11: =WATER!AS12 -> 11 | AY11: =WATER!AX12 -> 8 | AZ11: =WATER!BC12 -> 7 | BA11: =WATER!BH12 -> 7 | BB11: =WATER!BM12 -> 8 | BC11: =WATER!BR12 -> 2 | BD11: =WATER!BW12 -> 2 | BE11: =WATER!CB12 -> 8 | BF11: =WATER!CG12 -> 4 | BG11: =WATER!CL12 -> 25 | BH11: =WATER!CQ12 -> 7 | BI11: =WATER!CV12 -> 1 | BJ11: =WATER!DA12 -> 3 | BK11: =WATER!DF12 -> 3 | BL11: =WATER!DK12 -> 4 | BM11: =WATER!DP12 -> 38 | BN11: =WATER!DU12 -> 2 | BO11: =WATER!DZ12 -> 1 | BP11: ='Room Nights and Food Covers'!B11 -> 15.5 | BQ11: ='Room Nights and Food Covers'!C11 -> 134
A12: =A11+1 -> 44842 | C12: =SUM('GENSET #1'!C17+'GENSET #2'!C17+'GENSET #3'!C17+'GENSET #4'!C17+'GENSET #5'!C17) -> 103403182 | D12: =IF((C12-C11<0), "0",C12-C11) -> 24492 | E12: ='Gas-2'!G13 -> 315 | F12: =IF((E12-E11<0), "0",E12-E11) -> 90 | G12: ='GENSET #1'!D17 -> 7139 | H12: ='GENSET #2'!D17 -> 7513 | I12: ='GENSET #3'!D17 -> 0 | J12: ='GENSET #4'!D17 -> 2520 | K12: ='GENSET #5'!D17 -> 7320 | L12: ='FEEDER Consumption '!E12 -> 3701 | M12: ='FEEDER Consumption '!J12 -> 3723 | N12: ='FEEDER Consumption '!O12 -> 11752 | O12: ='FEEDER Consumption '!T12 -> 2500 | P12: ='FEEDER Consumption '!Y12 -> 2996 | Q12: ='FEEDER Consumption '!AD12 -> 2300 | R12: ='FEEDER Consumption '!AJ12 -> 443 | S12: ='FEEDER Consumption '!AO12 -> 800 | T12: ='FEEDER Consumption '!AT12 -> 700 | U12: ='FEEDER Consumption '!AY12 -> 415 | V12: ='FEEDER Consumption '!BI12 -> 300 | W12: ='FEEDER Consumption '!BI12 -> 300 | X12: ='FEEDER Consumption '!BN12 -> 600 | Y12: ='FEEDER Consumption '!BS12 -> 170 | Z12: ='FEEDER Consumption '!BX12 -> 440 | AA12: ='FEEDER Consumption '!CC12 -> 1200 | AB12: ='FEEDER Consumption '!CH12 -> 490 | AC12: ='FEEDER Consumption '!CM12 -> 850 | AD12: ='FEEDER Consumption '!CR12 -> 700 | AE12: ='FEEDER Consumption '!DB12 -> 820 | AF12: ='FEEDER Consumption '!DB12 -> 820 | AG12: ='FEEDER Consumption '!DG12 -> 840 | AH12: ='FEEDER Consumption '!DL12 -> 510 | AI12: ='FEEDER Consumption '!DQ12 -> 460 | AJ12: ='FEEDER Consumption '!DV12 -> 120 | AK12: ='FEEDER Consumption '!EA12 -> 900 | AL12: ='FEEDER Consumption '!EF12 -> 230 | AM12: ='FEEDER Consumption '!EK12 -> 320 | AN12: ='FEEDER Consumption '!EP12 -> 500 | AO12: =SUM([1]WATER!C13,[1]WATER!H13,[1]WATER!M13,[1]WATER!R13) -> 1135763 | AP12: =IF((AO12-AO11<0), "0",AO12-AO11) -> 404 | AQ12: =WATER!D13 -> 38 | AR12: =WATER!I13 -> 0 | AS12: =WATER!N13 -> 202 | AT12: =WATER!S13 -> 111 | AU12: =WATER!AD13 -> 19 | AV12: =WATER!AI13 -> 6 | AW12: =WATER!AN13 -> 9 | AX12: =WATER!AS13 -> 12 | AY12: =WATER!AX13 -> 8 | AZ12: =WATER!BC13 -> 7 | BA12: =WATER!BH13 -> 8 | BB12: =WATER!BM13 -> 8 | BC12: =WATER!BR13 -> 2 | BD12: =WATER!BW13 -> 0 | BE12: =WATER!CB13 -> 3 | BF12: =WATER!CG13 -> 1 | BG12: =WATER!CL13 -> 24 | BH12: =WATER!CQ13 -> 8 | BI12: =WATER!CV13 -> 3 | BJ12: =WATER!DA13 -> 6 | BK12: =WATER!DF13 -> 3 | BL12: =WATER!DK13 -> 0 | BM12: =WATER!DP13 -> 3 | BN12: =WATER!DU13 -> 1 | BO12: =WATER!DZ13 -> 2 | BP12: ='Room Nights and Food Covers'!B12 -> 17.5 | BQ12: ='Room Nights and Food Covers'!C12 -> 126
A13: =A12+1 -> 44843 | C13: =SUM('GENSET #1'!C18+'GENSET #2'!C18+'GENSET #3'!C18+'GENSET #4'!C18+'GENSET #5'!C18) -> 103427970 | D13: =IF((C13-C12<0), "0",C13-C12) -> 24788 | E13: ='Gas-2'!G14 -> 270 | F13: =IF((E13-E12<0), "0",E13-E12) -> 0 | G13: ='GENSET #1'!D18 -> 8458 | H13: ='GENSET #2'!D18 -> 5699 | I13: ='GENSET #3'!D18 -> 0 | J13: ='GENSET #4'!D18 -> 2184 | K13: ='GENSET #5'!D18 -> 8447 | L13: ='FEEDER Consumption '!E13 -> 3657 | M13: ='FEEDER Consumption '!J13 -> 3809 | N13: ='FEEDER Consumption '!O13 -> 11679 | O13: ='FEEDER Consumption '!T13 -> 2500 | P13: ='FEEDER Consumption '!Y13 -> 2801 | Q13: ='FEEDER Consumption '!AD13 -> 2200 | R13: ='FEEDER Consumption '!AJ13 -> 473 | S13: ='FEEDER Consumption '!AO13 -> 800 | T13: ='FEEDER Consumption '!AT13 -> 1100 | U13: ='FEEDER Consumption '!AY13 -> 392 | V13: ='FEEDER Consumption '!BI13 -> 300 | W13: ='FEEDER Consumption '!BI13 -> 300 | X13: ='FEEDER Consumption '!BN13 -> 600 | Y13: ='FEEDER Consumption '!BS13 -> 150 | Z13: ='FEEDER Consumption '!BX13 -> 400 | AA13: ='FEEDER Consumption '!CC13 -> 1100 | AB13: ='FEEDER Consumption '!CH13 -> 490 | AC13: ='FEEDER Consumption '!CM13 -> 980 | AD13: ='FEEDER Consumption '!CR13 -> 650 | AE13: ='FEEDER Consumption '!DB13 -> 980 | AF13: ='FEEDER Consumption '!DB13 -> 980 | AG13: ='FEEDER Consumption '!DG13 -> 930 | AH13: ='FEEDER Consumption '!DL13 -> 490 | AI13: ='FEEDER Consumption '!DQ13 -> 280 | AJ13: ='FEEDER Consumption '!DV13 -> 110 | AK13: ='FEEDER Consumption '!EA13 -> 880 | AL13: ='FEEDER Consumption '!EF13 -> 240 | AM13: ='FEEDER Consumption '!EK13 -> 370 | AN13: ='FEEDER Consumption '!EP13 -> 470 | AO13: =SUM([1]WATER!C14,[1]WATER!H14,[1]WATER!M14,[1]WATER!R14) -> 1136119 | AP13: =IF((AO13-AO12<0), "0",AO13-AO12) -> 356 | AQ13: =WATER!D14 -> 55 | AR13: =WATER!I14 -> 0 | AS13: =WATER!N14 -> 197 | AT13: =WATER!S14 -> 145 | AU13: =WATER!AD14 -> 19 | AV13: =WATER!AI14 -> 5 | AW13: =WATER!AN14 -> 8 | AX13: =WATER!AS14 -> 12 | AY13: =WATER!AX14 -> 7 | AZ13: =WATER!BC14 -> 7 | BA13: =WATER!BH14 -> 7 | BB13: =WATER!BM14 -> 7 | BC13: =WATER!BR14 -> 3 | BD13: =WATER!BW14 -> 0 | BE13: =WATER!CB14 -> 6 | BF13: =WATER!CG14 -> 0 | BG13: =WATER!CL14 -> 23 | BH13: =WATER!CQ14 -> 8 | BI13: =WATER!CV14 -> 0 | BJ13: =WATER!DA14 -> 5 | BK13: =WATER!DF14 -> 3 | BL13: =WATER!DK14 -> 5 | BM13: =WATER!DP14 -> 0 | BN13: =WATER!DU14 -> 3 | BO13: =WATER!DZ14 -> 1 | BP13: ='Room Nights and Food Covers'!B13 -> 12.6 | BQ13: ='Room Nights and Food Covers'!C13 -> 130
A14: =A13+1 -> 44844 | C14: =SUM('GENSET #1'!C19+'GENSET #2'!C19+'GENSET #3'!C19+'GENSET #4'!C19+'GENSET #5'!C19) -> 103451211 | D14: =IF((C14-C13<0), "0",C14-C13) -> 23241 | E14: ='Gas-2'!G15 -> 270 | F14: =IF((E14-E13<0), "0",E14-E13) -> 0 | G14: ='GENSET #1'!D19 -> 7884 | H14: ='GENSET #2'!D19 -> 6279 | I14: ='GENSET #3'!D19 -> 0 | J14: ='GENSET #4'!D19 -> 1241 | K14: ='GENSET #5'!D19 -> 7837 | L14: ='FEEDER Consumption '!E14 -> 3285 | M14: ='FEEDER Consumption '!J14 -> 3381 | N14: ='FEEDER Consumption '!O14 -> 11478 | O14: ='FEEDER Consumption '!T14 -> 2400 | P14: ='FEEDER Consumption '!Y14 -> 2684 | Q14: ='FEEDER Consumption '!AD14 -> 1800 | R14: ='FEEDER Consumption '!AJ14 -> 465 | S14: ='FEEDER Consumption '!AO14 -> 700 | T14: ='FEEDER Consumption '!AT14 -> 900 | U14: ='FEEDER Consumption '!AY14 -> 361 | V14: ='FEEDER Consumption '!BI14 -> 300 | W14: ='FEEDER Consumption '!BI14 -> 300 | X14: ='FEEDER Consumption '!BN14 -> 600 | Y14: ='FEEDER Consumption '!BS14 -> 150 | Z14: ='FEEDER Consumption '!BX14 -> 440 | AA14: ='FEEDER Consumption '!CC14 -> 1200 | AB14: ='FEEDER Consumption '!CH14 -> 450 | AC14: ='FEEDER Consumption '!CM14 -> 890 | AD14: ='FEEDER Consumption '!CR14 -> 750 | AE14: ='FEEDER Consumption '!DB14 -> 830 | AF14: ='FEEDER Consumption '!DB14 -> 830 | AG14: ='FEEDER Consumption '!DG14 -> 670 | AH14: ='FEEDER Consumption '!DL14 -> 210 | AI14: ='FEEDER Consumption '!DQ14 -> 280 | AJ14: ='FEEDER Consumption '!DV14 -> 90 | AK14: ='FEEDER Consumption '!EA14 -> 760 | AL14: ='FEEDER Consumption '!EF14 -> 240 | AM14: ='FEEDER Consumption '!EK14 -> 360 | AN14: ='FEEDER Consumption '!EP14 -> 490 | AO14: =SUM([1]WATER!C15,[1]WATER!H15,[1]WATER!M15,[1]WATER!R15) -> 1136567 | AP14: =IF((AO14-AO13<0), "0",AO14-AO13) -> 448 | AQ14: =WATER!D15 -> 38 | AR14: =WATER!I15 -> 0 | AS14: =WATER!N15 -> 230 | AT14: =WATER!S15 -> 110 | AU14: =WATER!AD15 -> 15 | AV14: =WATER!AI15 -> 6 | AW14: =WATER!AN15 -> 10 | AX14: =WATER!AS15 -> 13 | AY14: =WATER!AX15 -> 7 | AZ14: =WATER!BC15 -> 7 | BA14: =WATER!BH15 -> 7 | BB14: =WATER!BM15 -> 8 | BC14: =WATER!BR15 -> 2 | BD14: =WATER!BW15 -> 0 | BE14: =WATER!CB15 -> 5 | BF14: =WATER!CG15 -> 1 | BG14: =WATER!CL15 -> 24 | BH14: =WATER!CQ15 -> 6 | BI14: =WATER!CV15 -> 1 | BJ14: =WATER!DA15 -> 5 | BK14: =WATER!DF15 -> 1 | BL14: =WATER!DK15 -> 3 | BM14: =WATER!DP15 -> 0 | BN14: =WATER!DU15 -> 1 | BO14: =WATER!DZ15 -> 1 | BP14: ='Room Nights and Food Covers'!B14 -> 12.6 | BQ14: ='Room Nights and Food Covers'!C14 -> 116
A15: =A14+1 -> 44845 | C15: =SUM('GENSET #1'!C20+'GENSET #2'!C20+'GENSET #3'!C20+'GENSET #4'!C20+'GENSET #5'!C20) -> 103473996 | D15: =IF((C15-C14<0), "0",C15-C14) -> 22785 | E15: ='Gas-2'!G16 -> 180 | F15: =IF((E15-E14<0), "0",E15-E14) -> 0 | G15: ='GENSET #1'!D20 -> 8298 | H15: ='GENSET #2'!D20 -> 5829 | I15: ='GENSET #3'!D20 -> 0 | J15: ='GENSET #4'!D20 -> 270 | K15: ='GENSET #5'!D20 -> 8388 | L15: ='FEEDER Consumption '!E15 -> 3102 | M15: ='FEEDER Consumption '!J15 -> 3409 | N15: ='FEEDER Consumption '!O15 -> 10860 | O15: ='FEEDER Consumption '!T15 -> 2200 | P15: ='FEEDER Consumption '!Y15 -> 2506 | Q15: ='FEEDER Consumption '!AD15 -> 1900 | R15: ='FEEDER Consumption '!AJ15 -> 480 | S15: ='FEEDER Consumption '!AO15 -> 600 | T15: ='FEEDER Consumption '!AT15 -> 1200 | U15: ='FEEDER Consumption '!AY15 -> 366 | V15: ='FEEDER Consumption '!BI15 -> 300 | W15: ='FEEDER Consumption '!BI15 -> 300 | X15: ='FEEDER Consumption '!BN15 -> 600 | Y15: ='FEEDER Consumption '!BS15 -> 140 | Z15: ='FEEDER Consumption '!BX15 -> 400 | AA15: ='FEEDER Consumption '!CC15 -> 1100 | AB15: ='FEEDER Consumption '!CH15 -> 510 | AC15: ='FEEDER Consumption '!CM15 -> 840 | AD15: ='FEEDER Consumption '!CR15 -> 730 | AE15: ='FEEDER Consumption '!DB15 -> 850 | AF15: ='FEEDER Consumption '!DB15 -> 850 | AG15: ='FEEDER Consumption '!DG15 -> 640 | AH15: ='FEEDER Consumption '!DL15 -> 660 | AI15: ='FEEDER Consumption '!DQ15 -> 260 | AJ15: ='FEEDER Consumption '!DV15 -> 130 | AK15: ='FEEDER Consumption '!EA15 -> 750 | AL15: ='FEEDER Consumption '!EF15 -> 250 | AM15: ='FEEDER Consumption '!EK15 -> 340 | AN15: ='FEEDER Consumption '!EP15 -> 480 | AO15: =SUM([1]WATER!C16,[1]WATER!H16,[1]WATER!M16,[1]WATER!R16) -> 1136996 | AP15: =IF((AO15-AO14<0), "0",AO15-AO14) -> 429 | AQ15: =WATER!D16 -> 32 | AR15: =WATER!I16 -> 0 | AS15: =WATER!N16 -> 218 | AT15: =WATER!S16 -> 72 | AU15: =WATER!AD16 -> 17 | AV15: =WATER!AI16 -> 5 | AW15: =WATER!AN16 -> 0 | AX15: =WATER!AS16 -> 11 | AY15: =WATER!AX16 -> 7 | AZ15: =WATER!BC16 -> 6 | BA15: =WATER!BH16 -> 7 | BB15: =WATER!BM16 -> 6 | BC15: =WATER!BR16 -> 2 | BD15: =WATER!BW16 -> 2 | BE15: =WATER!CB16 -> 6 | BF15: =WATER!CG16 -> 4 | BG15: =WATER!CL16 -> 25 | BH15: =WATER!CQ16 -> 6 | BI15: =WATER!CV16 -> 0 | BJ15: =WATER!DA16 -> 7 | BK15: =WATER!DF16 -> 4 | BL15: =WATER!DK16 -> 4 | BM15: =WATER!DP16 -> 0 | BN15: =WATER!DU16 -> 1 | BO15: =WATER!DZ16 -> 1 | BP15: ='Room Nights and Food Covers'!B15 -> 12.6 | BQ15: ='Room Nights and Food Covers'!C15 -> 119
A16: =A15+1 -> 44846 | C16: =SUM('GENSET #1'!C21+'GENSET #2'!C21+'GENSET #3'!C21+'GENSET #4'!C21+'GENSET #5'!C21) -> 103494878 | D16: =IF((C16-C15<0), "0",C16-C15) -> 20882 | E16: ='Gas-2'!G17 -> 315 | F16: =IF((E16-E15<0), "0",E16-E15) -> 135 | G16: ='GENSET #1'!D21 -> 7407 | H16: ='GENSET #2'!D21 -> 6063 | I16: ='GENSET #3'!D21 -> 0 | J16: ='GENSET #4'!D21 -> 0 | K16: ='GENSET #5'!D21 -> 7412 | L16: ='FEEDER Consumption '!E16 -> 2909 | M16: ='FEEDER Consumption '!J16 -> 3012 | N16: ='FEEDER Consumption '!O16 -> 10242 | O16: ='FEEDER Consumption '!T16 -> 2200 | P16: ='FEEDER Consumption '!Y16 -> 2474 | Q16: ='FEEDER Consumption '!AD16 -> 1700 | R16: ='FEEDER Consumption '!AJ16 -> 446 | S16: ='FEEDER Consumption '!AO16 -> 700 | T16: ='FEEDER Consumption '!AT16 -> 700 | U16: ='FEEDER Consumption '!AY16 -> 325 | V16: ='FEEDER Consumption '!BI16 -> 300 | W16: ='FEEDER Consumption '!BI16 -> 300 | X16: ='FEEDER Consumption '!BN16 -> 500 | Y16: ='FEEDER Consumption '!BS16 -> 140 | Z16: ='FEEDER Consumption '!BX16 -> 390 | AA16: ='FEEDER Consumption '!CC16 -> 1100 | AB16: ='FEEDER Consumption '!CH16 -> 380 | AC16: ='FEEDER Consumption '!CM16 -> 790 | AD16: ='FEEDER Consumption '!CR16 -> 560 | AE16: ='FEEDER Consumption '!DB16 -> 800 | AF16: ='FEEDER Consumption '!DB16 -> 800 | AG16: ='FEEDER Consumption '!DG16 -> 450 | AH16: ='FEEDER Consumption '!DL16 -> 430 | AI16: ='FEEDER Consumption '!DQ16 -> 260 | AJ16: ='FEEDER Consumption '!DV16 -> 120 | AK16: ='FEEDER Consumption '!EA16 -> 750 | AL16: ='FEEDER Consumption '!EF16 -> 260 | AM16: ='FEEDER Consumption '!EK16 -> 370 | AN16: ='FEEDER Consumption '!EP16 -> 440 | AO16: =SUM([1]WATER!C17,[1]WATER!H17,[1]WATER!M17,[1]WATER!R17) -> 1137515 | AP16: =IF((AO16-AO15<0), "0",AO16-AO15) -> 519 | AQ16: =WATER!D17 -> 19 | AR16: =WATER!I17 -> 0 | AS16: =WATER!N17 -> 186 | AT16: =WATER!S17 -> 113 | AU16: =WATER!AD17 -> 16 | AV16: =WATER!AI17 -> 6 | AW16: =WATER!AN17 -> 0 | AX16: =WATER!AS17 -> 13 | AY16: =WATER!AX17 -> 8 | AZ16: =WATER!BC17 -> 7 | BA16: =WATER!BH17 -> 8 | BB16: =WATER!BM17 -> 9 | BC16: =WATER!BR17 -> 2 | BD16: =WATER!BW17 -> 0 | BE16: =WATER!CB17 -> 4 | BF16: =WATER!CG17 -> 2 | BG16: =WATER!CL17 -> 28 | BH16: =WATER!CQ17 -> 7 | BI16: =WATER!CV17 -> 1 | BJ16: =WATER!DA17 -> -3 | BK16: =WATER!DF17 -> 2 | BL16: =WATER!DK17 -> 4 | BM16: =WATER!DP17 -> 50 | BN16: =WATER!DU17 -> 0 | BO16: =WATER!DZ17 -> 1 | BP16: ='Room Nights and Food Covers'!B16 -> 11.7 | BQ16: ='Room Nights and Food Covers'!C16 -> 118
... A35: =A34+1 -> 44865 | C35: =SUM('GENSET #1'!C40+'GENSET #2'!C40+'GENSET #3'!C40+'GENSET #4'!C40+'GENSET #5'!C40) -> 103941271 | D35: =IF((C35-C34<0), "0",C35-C34) -> 24517 | E35: ='Gas-2'!G36 -> 180 | F35: =IF((E35-E34<0), "0",E35-E34) -> 0 | G35: ='GENSET #1'!D40 -> 7457 | H35: ='GENSET #2'!D40 -> 11828 | I35: ='GENSET #3'!D40 -> 1002 | J35: ='GENSET #4'!D40 -> 0 | K35: ='GENSET #5'!D40 -> 4230 | L35: ='FEEDER Consumption '!E35 -> 3747 | M35: ='FEEDER Consumption '!J35 -> 3713 | N35: ='FEEDER Consumption '!O35 -> 11230 | O35: ='FEEDER Consumption '!T35 -> 2400 | P35: ='FEEDER Consumption '!Y35 -> 2712 | Q35: ='FEEDER Consumption '!AD35 -> 1900 | R35: ='FEEDER Consumption '!AJ35 -> 471 | S35: ='FEEDER Consumption '!AO35 -> 700 | T35: ='FEEDER Consumption '!AT35 -> 1300 | U35: ='FEEDER Consumption '!AY35 -> 387 | V35: ='FEEDER Consumption '!BI35 -> 300 | W35: ='FEEDER Consumption '!BI35 -> 300 | X35: ='FEEDER Consumption '!BN35 -> 600 | Y35: ='FEEDER Consumption '!BS35 -> 140 | Z35: ='FEEDER Consumption '!BX35 -> 470 | AA35: ='FEEDER Consumption '!CC35 -> 1200 | AB35: ='FEEDER Consumption '!CH35 -> 490 | AC35: ='FEEDER Consumption '!CM35 -> 69 | AD35: ='FEEDER Consumption '!CR35 -> 760 | AE35: ='FEEDER Consumption '!DB35 -> 780 | AF35: ='FEEDER Consumption '!DB35 -> 780 | AG35: ='FEEDER Consumption '!DG35 -> 860 | AH35: ='FEEDER Consumption '!DL35 -> 640 | AI35: ='FEEDER Consumption '!DQ35 -> 280 | AJ35: ='FEEDER Consumption '!DV35 -> 140 | AK35: ='FEEDER Consumption '!EA35 -> 920 | AL35: ='FEEDER Consumption '!EF35 -> 300 | AM35: ='FEEDER Consumption '!EK35 -> 370 | AN35: ='FEEDER Consumption '!EP35 -> 510 | AO35: =SUM([1]WATER!C36,[1]WATER!H36,[1]WATER!M36,[1]WATER!R36) -> 0 | AP35: =IF((AO35-AO34<0), "0",AO35-AO34) -> 0 | AQ35: =WATER!D36 -> 202 | AR35: =WATER!I36 -> 0 | AS35: =WATER!N36 -> 41 | AT35: =WATER!S36 -> 133 | AU35: =WATER!AD36 -> 18 | AV35: =WATER!AI36 -> 6 | AW35: =WATER!AN36 -> 15 | AX35: =WATER!AS36 -> 11 | AY35: =WATER!AX36 -> 7 | AZ35: =WATER!BC36 -> 7 | BA35: =WATER!BH36 -> 1 | BB35: =WATER!BM36 -> 9 | BC35: =WATER!BR36 -> 1 | BD35: =WATER!BW36 -> 0 | BE35: =WATER!CB36 -> 1 | BF35: =WATER!CG36 -> 2 | BG35: =WATER!CL36 -> 0 | BH35: =WATER!CQ36 -> 9 | BI35: =WATER!CV36 -> 0 | BJ35: =WATER!DA36 -> 1 | BK35: =WATER!DF36 -> 3 | BL35: =WATER!DK36 -> 3 | BM35: =WATER!DP36 -> 7 | BN35: =WATER!DU36 -> 2 | BO35: =WATER!DZ36 -> 1 | BP35: ='Room Nights and Food Covers'!B35 -> 31.1 | BQ35: ='Room Nights and Food Covers'!C35 -> 195

Sheet Finance Only
A1: Four Seasons Landaa Giraavaru
A3: Property | B3: MLG | G3: 44470 | H3: =NOW() -> 44909.642 | J3: =H3-G3 -> 439.64186
A4: Month | B4: 44836
A5: Year | B5: 2022
A7: DAY | B7: Electricity Consumption ( kwh) | C7: Diesel Consumption (Liters) | D7: Solar Power Consumption(kwh) | E7: Gas Consumption (kg) | F7: Water Consumption ( m3) | G7: Occupancy | H7: Weather | I7: Ambian Temperature | J7: Electricity Variance (Today vs Yesterday)
A8: 1 | B8: =SUM('GENSET #1:GENSET #5'!D10) -> 23230 | C8: ='Diesel consumption'!D5 -> 6530 | D8: ='SOLAR METER READING'!D9 -> 2398 | E8: ='Gas-2'!G6 -> 270 | F8: =WATER!V6 -> 274 | G8: =WATER!W6 -> 0 | H8: ='SOLAR METER READING'!E9 -> 0 | I8: ='SOLAR METER READING'!F9 -> 0
A9: 2 | B9: =SUM('GENSET #1:GENSET #5'!D11) -> 22901 | C9: ='Diesel consumption'!D6 -> 6440 | D9: ='SOLAR METER READING'!D10 -> 1415 | E9: ='Gas-2'!G7 -> 270 | F9: =WATER!V7 -> 327 | G9: =WATER!W7 -> 0 | H9: ='SOLAR METER READING'!E10 -> 0 | I9: ='SOLAR METER READING'!F10 -> 0 | J9: =B9-B8 -> -329
A10: 3 | B10: =SUM('GENSET #1:GENSET #5'!D12) -> 23398 | C10: ='Diesel consumption'!D7 -> 6620 | D10: ='SOLAR METER READING'!D11 -> 3170 | E10: ='Gas-2'!G8 -> 315 | F10: =WATER!V8 -> 371 | G10: =WATER!W8 -> 0 | H10: ='SOLAR METER READING'!E11 -> 0 | I10: ='SOLAR METER READING'!F11 -> 0 | J10: =B10-B9 -> 497
A11: 4 | B11: =SUM('GENSET #1:GENSET #5'!D13) -> 24673 | C11: ='Diesel consumption'!D8 -> 6980 | D11: ='SOLAR METER READING'!D12 -> 2884 | E11: ='Gas-2'!G9 -> 270 | F11: =WATER!V9 -> 339 | G11: =WATER!W9 -> 0 | H11: ='SOLAR METER READING'!E12 -> 0 | I11: ='SOLAR METER READING'!F12 -> 0 | J11: =B11-B10 -> 1275
A12: 5 | B12: =SUM('GENSET #1:GENSET #5'!D14) -> 25199 | C12: ='Diesel consumption'!D9 -> 7050 | D12: ='SOLAR METER READING'!D13 -> 3110 | E12: ='Gas-2'!G10 -> 225 | F12: =WATER!V10 -> 334 | G12: =WATER!W10 -> 7678 | H12: ='SOLAR METER READING'!E13 -> 0 | I12: ='SOLAR METER READING'!F13 -> 0 | J12: =B12-B11 -> 526
A13: 6 | B13: =SUM('GENSET #1:GENSET #5'!D15) -> 24031 | C13: ='Diesel consumption'!D10 -> 7050 | D13: ='SOLAR METER READING'!D14 -> 3186 | E13: ='Gas-2'!G11 -> 315 | F13: =WATER!V11 -> 321 | G13: =WATER!W11 -> 2203 | H13: ='SOLAR METER READING'!E14 -> 0 | I13: ='SOLAR METER READING'!F14 -> 0 | J13: =B13-B12 -> -1168
A14: 7 | B14: =SUM('GENSET #1:GENSET #5'!D16) -> 24598 | C14: ='Diesel consumption'!D11 -> 7140 | D14: ='SOLAR METER READING'!D15 -> 3122 | E14: ='Gas-2'!G12 -> 225 | F14: =WATER!V12 -> 382 | G14: =WATER!W12 -> 0 | H14: ='SOLAR METER READING'!E15 -> 0 | I14: ='SOLAR METER READING'!F15 -> 0 | J14: =B14-B13 -> 567
A15: 8 | B15: =SUM('GENSET #1:GENSET #5'!D17) -> 24492 | C15: ='Diesel consumption'!D12 -> 6910 | D15: ='SOLAR METER READING'!D16 -> 3185 | E15: ='Gas-2'!G13 -> 315 | F15: =WATER!V13 -> 351 | G15: =WATER!W13 -> 0 | H15: ='SOLAR METER READING'!E16 -> 0 | I15: ='SOLAR METER READING'!F16 -> 0 | J15: =B15-B14 -> -106
A16: 9 | B16: =SUM('GENSET #1:GENSET #5'!D18) -> 24788 | C16: ='Diesel consumption'!D13 -> 6970 | D16: ='SOLAR METER READING'!D17 -> 3319 | E16: ='Gas-2'!G14 -> 270 | F16: =WATER!V14 -> 397 | G16: =WATER!W14 -> 0 | H16: ='SOLAR METER READING'!E17 -> 0 | I16: ='SOLAR METER READING'!F17 -> 0 | J16: =B16-B15 -> 296
A17: 10 | B17: =SUM('GENSET #1:GENSET #5'!D19) -> 23241 | C17: ='Diesel consumption'!D14 -> 6780 | D17: ='SOLAR METER READING'!D18 -> 2255 | E17: ='Gas-2'!G15 -> 270 | F17: =WATER!V15 -> 378 | G17: =WATER!W15 -> 0 | H17: ='SOLAR METER READING'!E18 -> 0 | I17: ='SOLAR METER READING'!F18 -> 0 | J17: =B17-B16 -> -1547
A18: 11 | B18: =SUM('GENSET #1:GENSET #5'!D20) -> 22785 | C18: ='Diesel consumption'!D15 -> 6340 | D18: ='SOLAR METER READING'!D19 -> 2633 | E18: ='Gas-2'!G16 -> 180 | F18: =WATER!V16 -> 322 | G18: =WATER!W16 -> 0 | H18: ='SOLAR METER READING'!E19 -> 0 | I18: ='SOLAR METER READING'!F19 -> 0 | J18: =B18-B17 -> -456
A19: 12 | B19: =SUM('GENSET #1:GENSET #5'!D21) -> 20882 | C19: ='Diesel consumption'!D16 -> 5860 | D19: ='SOLAR METER READING'!D20 -> 2540 | E19: ='Gas-2'!G17 -> 315 | F19: =WATER!V17 -> 318 | G19: =WATER!W17 -> 0 | H19: ='SOLAR METER READING'!E20 -> 0 | I19: ='SOLAR METER READING'!F20 -> 0 | J19: =B19-B18 -> -1903
A20: 13 | B20: =SUM('GENSET #1:GENSET #5'!D22) -> 22278 | C20: ='Diesel consumption'!D17 -> 6340 | D20: ='SOLAR METER READING'!D21 -> 502 | E20: ='Gas-2'!G18 -> 225 | F20: =WATER!V18 -> 310 | G20: =WATER!W18 -> 0 | H20: ='SOLAR METER READING'!E21 -> 0 | I20: ='SOLAR METER READING'!F21 -> 0 | J20: =B20-B19 -> 1396
... A36: 29 | B36: =SUM('GENSET #1:GENSET #5'!D38) -> 24259 | C36: ='Diesel consumption'!D33 -> 6890 | D36: ='SOLAR METER READING'!D37 -> 2367 | E36: ='Gas-2'!G34 -> 180 | F36: =WATER!V34 -> 319 | G36: =WATER!W34 -> 7043 | H36: ='SOLAR METER READING'!E37 -> 0 | I36: ='SOLAR METER READING'!F37 -> 0 | J36: =B36-B35 -> 610
