Workbook

Sheet TOTAL
A1: Site Name | B1: Day | C1: Month | D1: Year | E1: Total Electricity Kwh | F1: Electricity Tariff ($/Kwh) | G1: LPG (Kg) | H1: LPG $/Kg | I1: Water Utility Supply (m3) m3 | J1: Water Utility Supply (m3) $/m3 | K1: Room Nights | L1: Food Covers
A2: Maldives at Landaa Giraavaru | B2: 1 | C2: 11 | D2: 2022 | E2: ='Maldives at LG Daily'!D5 -> 24170 | F2: 0.27 | G2: ='Maldives at LG Daily'!E5 -> 90 | H2: 1.24 | I2: ='Maldives at LG Daily'!AP5 -> 382 | J2: 0 | K2: ='Maldives at LG Daily'!BP5 -> 30.1 | L2: ='Maldives at LG Daily'!BQ5 -> 244
A3: Maldives at Landaa Giraavaru | B3: 2 | C3: 11 | D3: 2022 | E3: ='Maldives at LG Daily'!D6 -> 25024 | F3: 0.27 | G3: ='Maldives at LG Daily'!E6 -> 270 | H3: 1.24 | I3: ='Maldives at LG Daily'!AP6 -> 352 | J3: 0 | K3: ='Maldives at LG Daily'!BP6 -> 34 | L3: ='Maldives at LG Daily'!BQ6 -> 237
A4: Maldives at Landaa Giraavaru | B4: 3 | C4: 11 | D4: 2022 | E4: ='Maldives at LG Daily'!D7 -> 25240 | F4: 0.27 | G4: ='Maldives at LG Daily'!E7 -> 225 | H4: 1.24 | I4: ='Maldives at LG Daily'!AP7 -> 385 | J4: 0 | K4: ='Maldives at LG Daily'!BP7 -> 34 | L4: ='Maldives at LG Daily'!BQ7 -> 307
A5: Maldives at Landaa Giraavaru | B5: 4 | C5: 11 | D5: 2022 | E5: ='Maldives at LG Daily'!D8 -> 26491 | F5: 0.27 | G5: ='Maldives at LG Daily'!E8 -> 270 | H5: 1.24 | I5: ='Maldives at LG Daily'!AP8 -> 375 | J5: 0 | K5: ='Maldives at LG Daily'!BP8 -> 40.8 | L5: ='Maldives at LG Daily'!BQ8 -> 306
A6: Maldives at Landaa Giraavaru | B6: 5 | C6: 11 | D6: 2022 | E6: ='Maldives at LG Daily'!D9 -> 26146 | F6: 0.27 | G6: ='Maldives at LG Daily'!E9 -> 225 | H6: 1.24 | I6: ='Maldives at LG Daily'!AP9 -> 371 | J6: 0 | K6: ='Maldives at LG Daily'!BP9 -> 38.8 | L6: ='Maldives at LG Daily'!BQ9 -> 298
A7: Maldives at Landaa Giraavaru | B7: 6 | C7: 11 | D7: 2022 | E7: ='Maldives at LG Daily'!D10 -> 26840 | F7: 0.27 | G7: ='Maldives at LG Daily'!E10 -> 270 | H7: 1.24 | I7: ='Maldives at LG Daily'!AP10 -> 385 | J7: 0 | K7: ='Maldives at LG Daily'!BP10 -> 31.1 | L7: ='Maldives at LG Daily'!BQ10 -> 299
A8: Maldives at Landaa Giraavaru | B8: 7 | C8: 11 | D8: 2022 | E8: ='Maldives at LG Daily'!D11 -> 26304 | F8: 0.27 | G8: ='Maldives at LG Daily'!E11 -> 270 | H8: 1.24 | I8: ='Maldives at LG Daily'!AP11 -> 373 | J8: 0 | K8: ='Maldives at LG Daily'!BP11 -> 29.1 | L8: ='Maldives at LG Daily'!BQ11 -> 247
A9: Maldives at Landaa Giraavaru | B9: 8 | C9: 11 | D9: 2022 | E9: ='Maldives at LG Daily'!D12 -> 26622 | F9: 0.27 | G9: ='Maldives at LG Daily'!E12 -> 270 | H9: 1.24 | I9: ='Maldives at LG Daily'!AP12 -> 404 | J9: 0 | K9: ='Maldives at LG Daily'!BP12 -> 34 | L9: ='Maldives at LG Daily'!BQ12 -> 274
A10: Maldives at Landaa Giraavaru | B10: 9 | C10: 11 | D10: 2022 | E10: ='Maldives at LG Daily'!D13 -> 26674 | F10: 0.27 | G10: ='Maldives at LG Daily'!E13 -> 270 | H10: 1.24 | I10: ='Maldives at LG Daily'!AP13 -> 356 | J10: 0 | K10: ='Maldives at LG Daily'!BP13 -> 29.1 | L10: ='Maldives at LG Daily'!BQ13 -> 222
A11: Maldives at Landaa Giraavaru | B11: 10 | C11: 11 | D11: 2022 | E11: ='Maldives at LG Daily'!D14 -> 26265 | F11: 0.27 | G11: ='Maldives at LG Daily'!E14 -> 90 | H11: 1.24 | I11: ='Maldives at LG Daily'!AP14 -> 448 | J11: 0 | K11: ='Maldives at LG Daily'!BP14 -> 27.2 | L11: ='Maldives at LG Daily'!BQ14 -> 209
A12: Maldives at Landaa Giraavaru | B12: 11 | C12: 11 | D12: 2022 | E12: ='Maldives at LG Daily'!D15 -> 26961 | F12: 0.27 | G12: ='Maldives at LG Daily'!E15 -> 90 | H12: 1.24 | I12: ='Maldives at LG Daily'!AP15 -> 429 | J12: 0 | K12: ='Maldives at LG Daily'!BP15 -> 30.1 | L12: ='Maldives at LG Daily'!BQ15 -> 226
A13: Maldives at Landaa Giraavaru | B13: 12 | C13: 11 | D13: 2022 | E13: ='Maldives at LG Daily'!D16 -> 26816 | F13: 0.27 | G13: ='Maldives at LG Daily'!E16 -> 450 | H13: 1.24 | I13: ='Maldives at LG Daily'!AP16 -> 519 | J13: 0 | K13: ='Maldives at LG Daily'!BP16 -> 36.9 | L13: ='Maldives at LG Daily'!BQ16 -> 237
... A31: Maldives at Landaa Giraavaru | B31: 30 | C31: 11 | D31: 2022 | E31: ='Maldives at LG Daily'!D34 -> 25963 | F31: 0.27 | G31: ='Maldives at LG Daily'!E34 -> 270 | H31: 2.24 | I31: ='Maldives at LG Daily'!AP34 -> 353 | J31: 1 | K31: ='Maldives at LG Daily'!BP34 -> 35.9 | L31: ='Maldives at LG Daily'!BQ34 -> 264

Sheet Submetering 
A1: Site Name | B1: Day | C1: Month | D1: Year | E1: GENSET NO 1 | F1: GENSET NO 2 | G1: GENSET NO 3 | H1: GENSET NO 4 | I1: GENSET NO 5 | J1: Main BLU FEEDER PANEL 1 | K1: Main BLU FEEDER PANEL 2 | L1: Main POWER HOUSE FEEDER PANEL NO:3 | M1: Main Kitchen -7 | N1: Main Kitchen -10 | O1: Water treatment Plant | P1: Sewage treatment Plant | Q1: Laundry--8SSB (Machineries) | R1: Laundry-9 (HR/Tuck Shop Building) | S1: New staff accomodation (E0) | T1: Staff block-16(E2-E3) | U1: Staff Block Feeder-3(E4-E5) | V1: Management block-5 (M1 to M6) | W1: SNR STAFF BLOCK (PC Block) | X1: BOAT DOCK FEEDER - 22 | Y1: RECEPTION Building Full (Finance/Reservation) | Z1: DIVE CENTER (Inc MDC and Recreation) | AA1: 301-307 | AB1: 308-314 | AC1: 315-320 | AD1: 401-407 | AE1: 408-414 | AF1: 415-420 | AG1: SPA - 1 | AH1: SPA - 2 | AI1: BLU KITCHEN - 1 | AJ1: BLU KITCHEN - 2 | AK1: AL BARAKATH | AL1: STAFF KITCHEN | AM1: R/O Plant A | AN1: R/O Plant B | AO1: R/O Plant C | AP1: R/O Plant D | AQ1: Laundry | AR1: Staff Block - E0 | AS1: Staff Block - E1 | AT1: Staff Block - E2 | AU1: Staff Block - E3 | AV1: Staff Block - E4 | AW1: Staff Block - E5 | AX1: Management Block | AY1: PC Block | AZ1: GM Bungalow | BA1: Boat Dock | BB1: Supply Jetty | BC1: Main Kitchen | BD1: Day Facility | BE1: Reception | BF1: Main Pool | BG1: Dive Center | BH1: Albarakthu | BI1: Blu Resturant | BJ1: Main Jetty | BK1: Landaa Estate | BL1: ROOM NIGHTS | BM1: Total Food Covers
A2: Maldives at Landaa Giraavaru | B2: 1 | C2: 11 | D2: 2022 | E2: ='Maldives at LG Daily'!G5 -> 1746 | F2: ='Maldives at LG Daily'!H5 -> 9811 | G2: ='Maldives at LG Daily'!I5 -> 7417 | H2: ='Maldives at LG Daily'!J5 -> 0 | I2: ='Maldives at LG Daily'!K5 -> 5196 | J2: ='Maldives at LG Daily'!L5 -> 3680 | K2: ='Maldives at LG Daily'!M5 -> 3861 | L2: ='Maldives at LG Daily'!N5 -> 10978 | ... AL2: ='Maldives at LG Daily'!AN5 -> 430 | AM2: ='Maldives at LG Daily'!AQ5 -> 222 | AN2: ='Maldives at LG Daily'!AR5 -> 0 | AO2: ='Maldives at LG Daily'!AS5 -> 50 | AP2: ='Maldives at LG Daily'!AT5 -> 110 | AQ2: ='Maldives at LG Daily'!AU5 -> 19 | AR2: ='Maldives at LG Daily'!AV5 -> 5 | AS2: ='Maldives at LG Daily'!AW5 -> 8 | AT2: ='Maldives at LG Daily'!AX5 -> 12 | ... BK2: ='Maldives at LG Daily'!BO5 -> 2 | BL2: ='Rooms nights and Food Covers'!B5 -> 30.1 | BM2: ='Rooms nights and Food Covers'!C5 -> 244
A3: Maldives at Landaa Giraavaru | B3: 2 | C3: 11 | D3: 2022 | E3: ='Maldives at LG Daily'!G6 -> 5831 | F3: ='Maldives at LG Daily'!H6 -> 9777 | G3: ='Maldives at LG Daily'!I6 -> 7500 | H3: ='Maldives at LG Daily'!J6 -> 0 | I3: ='Maldives at LG Daily'!K6 -> 1916 | J3: ='Maldives at LG Daily'!L6 -> 4018 | K3: ='Maldives at LG Daily'!M6 -> 3979 | L3: ='Maldives at LG Daily'!N6 -> 11389 | ... AL3: ='Maldives at LG Daily'!AN6 -> 500 | AM3: ='Maldives at LG Daily'!AQ6 -> 205 | AN3: ='Maldives at LG Daily'!AR6 -> 0 | AO3: ='Maldives at LG Daily'!AS6 -> 34 | AP3: ='Maldives at LG Daily'!AT6 -> 113 | AQ3: ='Maldives at LG Daily'!AU6 -> 21 | AR3: ='Maldives at LG Daily'!AV6 -> 6 | AS3: ='Maldives at LG Daily'!AW6 -> 10 | AT3: ='Maldives at LG Daily'!AX6 -> 12 | ... BK3: ='Maldives at LG Daily'!BO6 -> 0 | BL3: ='Rooms nights and Food Covers'!B6 -> 34 | BM3: ='Rooms nights and Food Covers'!C6 -> 237
A4: Maldives at Landaa Giraavaru | B4: 3 | C4: 11 | D4: 2022 | E4: ='Maldives at LG Daily'!G7 -> 7475 | F4: ='Maldives at LG Daily'!H7 -> 6525 | G4: ='Maldives at LG Daily'!I7 -> 4471 | H4: ='Maldives at LG Daily'!J7 -> 0 | I4: ='Maldives at LG Daily'!K7 -> 6769 | J4: ='Maldives at LG Daily'!L7 -> 3803 | K4: ='Maldives at LG Daily'!M7 -> 4138 | L4: ='Maldives at LG Daily'!N7 -> 11452 | ... AL4: ='Maldives at LG Daily'!AN7 -> 460 | AM4: ='Maldives at LG Daily'!AQ7 -> 239 | AN4: ='Maldives at LG Daily'!AR7 -> 0 | AO4: ='Maldives at LG Daily'!AS7 -> 24 | AP4: ='Maldives at LG Daily'!AT7 -> 122 | AQ4: ='Maldives at LG Daily'!AU7 -> 20 | AR4: ='Maldives at LG Daily'!AV7 -> 8 | AS4: ='Maldives at LG Daily'!AW7 -> 9 | AT4: ='Maldives at LG Daily'!AX7 -> 12 | ... BK4: ='Maldives at LG Daily'!BO7 -> 0 | BL4: ='Rooms nights and Food Covers'!B7 -> 34 | BM4: ='Rooms nights and Food Covers'!C7 -> 307
A5: Maldives at Landaa Giraavaru | B5: 4 | C5: 11 | D5: 2022 | E5: ='Maldives at LG Daily'!G8 -> 9100 | F5: ='Maldives at LG Daily'!H8 -> 2952 | G5: ='Maldives at LG Daily'!I8 -> 9160 | H5: ='Maldives at LG Daily'!J8 -> 0 | I5: ='Maldives at LG Daily'!K8 -> 5279 | J5: ='Maldives at LG Daily'!L8 -> 4186 | K5: ='Maldives at LG Daily'!M8 -> 4483 | L5: ='Maldives at LG Daily'!N8 -> 11928 | ... AL5: ='Maldives at LG Daily'!AN8 -> 0 | AM5: ='Maldives at LG Daily'!AQ8 -> 230 | AN5: ='Maldives at LG Daily'!AR8 -> 0 | AO5: ='Maldives at LG Daily'!AS8 -> 1 | AP5: ='Maldives at LG Daily'!AT8 -> 144 | AQ5: ='Maldives at LG Daily'!AU8 -> 21 | AR5: ='Maldives at LG Daily'!AV8 -> 4 | AS5: ='Maldives at LG Daily'!AW8 -> 9 | AT5: ='Maldives at LG Daily'!AX8 -> 13 | ... BK5: ='Maldives at LG Daily'!BO8 -> 0 | BL5: ='Rooms nights and Food Covers'!B8 -> 40.8 | BM5: ='Rooms nights and Food Covers'!C8 -> 306
A6: Maldives at Landaa Giraavaru | B6: 5 | C6: 11 | D6: 2022 | E6: ='Maldives at LG Daily'!G9 -> 9784 | F6: ='Maldives at LG Daily'!H9 -> 834 | G6: ='Maldives at LG Daily'!I9 -> 5744 | H6: ='Maldives at LG Daily'!J9 -> 0 | I6: ='Maldives at LG Daily'!K9 -> 9784 | J6: ='Maldives at LG Daily'!L9 -> 4156 | K6: ='Maldives at LG Daily'!M9 -> 4344 | L6: ='Maldives at LG Daily'!N9 -> 11380 | ... AL6: ='Maldives at LG Daily'!AN9 -> 920 | AM6: ='Maldives at LG Daily'!AQ9 -> 213 | AN6: ='Maldives at LG Daily'!AR9 -> 0 | AO6: ='Maldives at LG Daily'!AS9 -> 29 | AP6: ='Maldives at LG Daily'!AT9 -> 129 | AQ6: ='Maldives at LG Daily'!AU9 -> 21 | AR6: ='Maldives at LG Daily'!AV9 -> 6 | AS6: ='Maldives at LG Daily'!AW9 -> 10 | AT6: ='Maldives at LG Daily'!AX9 -> 13 | ... BK6: ='Maldives at LG Daily'!BO9 -> 6 | BL6: ='Rooms nights and Food Covers'!B9 -> 38.8 | BM6: ='Rooms nights and Food Covers'!C9 -> 298
A7: Maldives at Landaa Giraavaru | B7: 6 | C7: 11 | D7: 2022 | E7: ='Maldives at LG Daily'!G10 -> 3169 | F7: ='Maldives at LG Daily'!H10 -> 11280 | G7: ='Maldives at LG Daily'!I10 -> 8335 | H7: ='Maldives at LG Daily'!J10 -> 0 | I7: ='Maldives at LG Daily'!K10 -> 4056 | J7: ='Maldives at LG Daily'!L10 -> 4442 | K7: ='Maldives at LG Daily'!M10 -> 4481 | L7: ='Maldives at LG Daily'!N10 -> 12061 | ... AL7: ='Maldives at LG Daily'!AN10 -> 540 | AM7: ='Maldives at LG Daily'!AQ10 -> 245 | AN7: ='Maldives at LG Daily'!AR10 -> 0 | AO7: ='Maldives at LG Daily'!AS10 -> 0 | AP7: ='Maldives at LG Daily'!AT10 -> 140 | AQ7: ='Maldives at LG Daily'!AU10 -> 22 | AR7: ='Maldives at LG Daily'!AV10 -> 6 | AS7: ='Maldives at LG Daily'!AW10 -> 10 | AT7: ='Maldives at LG Daily'!AX10 -> 11 | ... BK7: ='Maldives at LG Daily'!BO10 -> 2 | BL7: ='Rooms nights and Food Covers'!B10 -> 31.1 | BM7: ='Rooms nights and Food Covers'!C10 -> 299
A8: Maldives at Landaa Giraavaru | B8: 7 | C8: 11 | D8: 2022 | E8: ='Maldives at LG Daily'!G11 -> 7349 | F8: ='Maldives at LG Daily'!H11 -> 9634 | G8: ='Maldives at LG Daily'!I11 -> 4237 | H8: ='Maldives at LG Daily'!J11 -> 0 | I8: ='Maldives at LG Daily'!K11 -> 5084 | J8: ='Maldives at LG Daily'!L11 -> 4402 | K8: ='Maldives at LG Daily'!M11 -> 4141 | L8: ='Maldives at LG Daily'!N11 -> 11776 | ... AL8: ='Maldives at LG Daily'!AN11 -> 510 | AM8: ='Maldives at LG Daily'!AQ11 -> 229 | AN8: ='Maldives at LG Daily'!AR11 -> 0 | AO8: ='Maldives at LG Daily'!AS11 -> 0 | AP8: ='Maldives at LG Daily'!AT11 -> 144 | AQ8: ='Maldives at LG Daily'!AU11 -> 25 | AR8: ='Maldives at LG Daily'!AV11 -> 6 | AS8: ='Maldives at LG Daily'!AW11 -> 9 | AT8: ='Maldives at LG Daily'!AX11 -> 11 | ... BK8: ='Maldives at LG Daily'!BO11 -> 2 | BL8: ='Rooms nights and Food Covers'!B11 -> 29.1 | BM8: ='Rooms nights and Food Covers'!C11 -> 247
A9: Maldives at Landaa Giraavaru | B9: 8 | C9: 11 | D9: 2022 | E9: ='Maldives at LG Daily'!G12 -> 2387 | F9: ='Maldives at LG Daily'!H12 -> 13482 | G9: ='Maldives at LG Daily'!I12 -> 4128 | H9: ='Maldives at LG Daily'!J12 -> 0 | I9: ='Maldives at LG Daily'!K12 -> 6625 | J9: ='Maldives at LG Daily'!L12 -> 4404 | K9: ='Maldives at LG Daily'!M12 -> 4063 | L9: ='Maldives at LG Daily'!N12 -> 11713 | ... AL9: ='Maldives at LG Daily'!AN12 -> 460 | AM9: ='Maldives at LG Daily'!AQ12 -> 254 | AN9: ='Maldives at LG Daily'!AR12 -> 0 | AO9: ='Maldives at LG Daily'!AS12 -> 1 | AP9: ='Maldives at LG Daily'!AT12 -> 149 | AQ9: ='Maldives at LG Daily'!AU12 -> 20 | AR9: ='Maldives at LG Daily'!AV12 -> 7 | AS9: ='Maldives at LG Daily'!AW12 -> 9 | AT9: ='Maldives at LG Daily'!AX12 -> 10 | ... BK9: ='Maldives at LG Daily'!BO12 -> 1 | BL9: ='Rooms nights and Food Covers'!B12 -> 34 | BM9: ='Rooms nights and Food Covers'!C12 -> 274
A10: Maldives at Landaa Giraavaru | B10: 9 | C10: 11 | D10: 2022 | E10: ='Maldives at LG Daily'!G13 -> 6611 | F10: ='Maldives at LG Daily'!H13 -> 9452 | G10: ='Maldives at LG Daily'!I13 -> 7873 | H10: ='Maldives at LG Daily'!J13 -> 0 | I10: ='Maldives at LG Daily'!K13 -> 2738 | J10: ='Maldives at LG Daily'!L13 -> 4316 | K10: ='Maldives at LG Daily'!M13 -> 3767 | L10: ='Maldives at LG Daily'!N13 -> 12008 | ... AL10: ='Maldives at LG Daily'!AN13 -> 520 | AM10: ='Maldives at LG Daily'!AQ13 -> 224 | AN10: ='Maldives at LG Daily'!AR13 -> 0 | AO10: ='Maldives at LG Daily'!AS13 -> 0 | AP10: ='Maldives at LG Daily'!AT13 -> 132 | AQ10: ='Maldives at LG Daily'!AU13 -> 24 | AR10: ='Maldives at LG Daily'!AV13 -> 6 | AS10: ='Maldives at LG Daily'!AW13 -> 9 | AT10: ='Maldives at LG Daily'!AX13 -> 10 | ... BK10: ='Maldives at LG Daily'!BO13 -> 1 | BL10: ='Rooms nights and Food Covers'!B13 -> 29.1 | BM10: ='Rooms nights and Food Covers'!C13 -> 222
A11: Maldives at Landaa Giraavaru | B11: 10 | C11: 11 | D11: 2022 | E11: ='Maldives at LG Daily'!G14 -> 1193 | F11: ='Maldives at LG Daily'!H14 -> 11688 | G11: ='Maldives at LG Daily'!I14 -> 9219 | H11: ='Maldives at LG Daily'!J14 -> 0 | I11: ='Maldives at LG Daily'!K14 -> 4165 | J11: ='Maldives at LG Daily'!L14 -> 4316 | K11: ='Maldives at LG Daily'!M14 -> 3767 | L11: ='Maldives at LG Daily'!N14 -> 12008 | ... AL11: ='Maldives at LG Daily'!AN14 -> 530 | AM11: ='Maldives at LG Daily'!AQ14 -> 249 | AN11: ='Maldives at LG Daily'!AR14 -> 0 | AO11: ='Maldives at LG Daily'!AS14 -> 48 | AP11: ='Maldives at LG Daily'!AT14 -> 151 | AQ11: ='Maldives at LG Daily'!AU14 -> 22 | AR11: ='Maldives at LG Daily'!AV14 -> 6 | AS11: ='Maldives at LG Daily'!AW14 -> 11 | AT11: ='Maldives at LG Daily'!AX14 -> 10 | ... BK11: ='Maldives at LG Daily'!BO14 -> 3 | BL11: ='Rooms nights and Food Covers'!B14 -> 27.2 | BM11: ='Rooms nights and Food Covers'!C14 -> 209
A12: Maldives at Landaa Giraavaru | B12: 11 | C12: 11 | D12: 2022 | E12: ='Maldives at LG Daily'!G15 -> 7249 | F12: ='Maldives at LG Daily'!H15 -> 8458 | G12: ='Maldives at LG Daily'!I15 -> 5845 | H12: ='Maldives at LG Daily'!J15 -> 0 | I12: ='Maldives at LG Daily'!K15 -> 5409 | J12: ='Maldives at LG Daily'!L15 -> 3849 | K12: ='Maldives at LG Daily'!M15 -> 3771 | L12: ='Maldives at LG Daily'!N15 -> 13626 | ... AL12: ='Maldives at LG Daily'!AN15 -> 530 | AM12: ='Maldives at LG Daily'!AQ15 -> 247 | AN12: ='Maldives at LG Daily'!AR15 -> 21 | AO12: ='Maldives at LG Daily'!AS15 -> 22 | AP12: ='Maldives at LG Daily'!AT15 -> 139 | AQ12: ='Maldives at LG Daily'!AU15 -> 20 | AR12: ='Maldives at LG Daily'!AV15 -> 6 | AS12: ='Maldives at LG Daily'!AW15 -> 9 | AT12: ='Maldives at LG Daily'!AX15 -> 10 | ... BK12: ='Maldives at LG Daily'!BO15 -> 1 | BL12: ='Rooms nights and Food Covers'!B15 -> 30.1 | BM12: ='Rooms nights and Food Covers'!C15 -> 226
A13: Maldives at Landaa Giraavaru | B13: 12 | C13: 11 | D13: 2022 | E13: ='Maldives at LG Daily'!G16 -> 4553 | F13: ='Maldives at LG Daily'!H16 -> 12675 | G13: ='Maldives at LG Daily'!I16 -> 9545 | H13: ='Maldives at LG Daily'!J16 -> 0 | I13: ='Maldives at LG Daily'!K16 -> 43 | J13: ='Maldives at LG Daily'!L16 -> 3978 | K13: ='Maldives at LG Daily'!M16 -> 4164 | L13: ='Maldives at LG Daily'!N16 -> 12679 | ... AL13: ='Maldives at LG Daily'!AN16 -> 540 | AM13: ='Maldives at LG Daily'!AQ16 -> 244 | AN13: ='Maldives at LG Daily'!AR16 -> 119 | AO13: ='Maldives at LG Daily'!AS16 -> 22 | AP13: ='Maldives at LG Daily'!AT16 -> 134 | AQ13: ='Maldives at LG Daily'!AU16 -> 23 | AR13: ='Maldives at LG Daily'!AV16 -> 7 | AS13: ='Maldives at LG Daily'!AW16 -> 9 | AT13: ='Maldives at LG Daily'!AX16 -> 10 | ... BK13: ='Maldives at LG Daily'!BO16 -> 7 | BL13: ='Rooms nights and Food Covers'!B16 -> 36.9 | BM13: ='Rooms nights and Food Covers'!C16 -> 237
... A31: Maldives at Landaa Giraavaru | B31: 30 | C31: 11 | D31: 2022 | E31: ='Maldives at LG Daily'!G34 -> 7081 | F31: ='Maldives at LG Daily'!H34 -> 7070 | G31: ='Maldives at LG Daily'!I34 -> 3789 | H31: ='Maldives at LG Daily'!J34 -> 0 | I31: ='Maldives at LG Daily'!K34 -> 8023 | J31: ='Maldives at LG Daily'!L34 -> 3797 | K31: ='Maldives at LG Daily'!M34 -> 4393 | L31: ='Maldives at LG Daily'!N34 -> 11846 | ... AL31: ='Maldives at LG Daily'!AN34 -> 490 | AM31: ='Maldives at LG Daily'!AQ34 -> 204 | AN31: ='Maldives at LG Daily'!AR34 -> 101 | AO31: ='Maldives at LG Daily'!AS34 -> 0 | AP31: ='Maldives at LG Daily'!AT34 -> 48 | AQ31: ='Maldives at LG Daily'!AU34 -> 20 | AR31: ='Maldives at LG Daily'!AV34 -> 6 | AS31: ='Maldives at LG Daily'!AW34 -> 9 | AT31: ='Maldives at LG Daily'!AX34 -> 10 | ... BK31: ='Maldives at LG Daily'!BO34 -> 2 | BL31: ='Rooms nights and Food Covers'!B34 -> 35.9 | BM31: ='Rooms nights and Food Covers'!C34 -> 264

Sheet Maldives at LG Daily
A2: Days | C2: Electricity Meter (KWh) | E2: Gas Kg | G2: GENSET NO 1 | H2: GENSET NO 2 | I2: GENSET NO 3 | J2: GENSET NO 4 | K2: GENSET NO 5 | L2: Main BLU FEEDER PANEL 1 | M2: Main BLU FEEDER PANEL 2 | N2: Main POWER HOUSE FEEDER PANEL NO:3 | O2: Main Kitchen -7 | P2: Main Kitchen -10 | Q2: Water treatment Plant | R2: Sewage treatment Plant | S2: Laundry--8SSB (Machineries) | T2: Laundry-9 (HR/Tuck Shop Building) | U2: New staff accomodation (E0) | V2: Staff block-16(E2-E3) | W2: Staff Block Feeder-3(E4-E5) | X2: Management block-5 (M1 to M6) | Y2: SNR STAFF BLOCK (PC Block) | Z2: BOAT DOCK FEEDER - 22 | AA2: RECEPTION Building Full (Finance/Reservation) | AB2: DIVE CENTER (Inc MDC and Recreation) | AC2: 301-307 | AD2: 308-314 | AE2: 315-320 | AF2: 401-407 | AG2: 408-414 | AH2: 415-420 | AI2: SPA - 1 | AJ2: SPA - 2 | AK2: BLU KITCHEN - 1 | AL2: BLU KITCHEN - 2 | AM2: AL BARAKATH | AN2: STAFF KITCHEN | AO2: Water m3 | AQ2: R/O Plant A | AR2: R/O Plant B | AS2: R/O Plant C | AT2: R/O Plant D | AU2: Laundry | AV2: Staff Block - E0 | AW2: Staff Block - E1 | AX2: Staff Block - E2 | AY2: Staff Block - E3 | AZ2: Staff Block - E4 | BA2: Staff Block - E5 | BB2: Management Block | BC2: PC Block | BD2: GM Bungalow | BE2: Boat Dock | BF2: Supply Jetty | BG2: Main Kitchen | BH2: Day Facility | BI2: Reception | BJ2: Main Pool | BK2: Dive Center | BL2: Albarakthu | BM2: Blu Resturant | BN2: Main Jetty | BO2: Landaa Estate
A3: Date | C3: Reading KWH | D3: Difference KWH | E3: Reading Kg | F3: Difference Kg | G3: KWh | H3: KWh | I3: KWh | J3: KWh | K3: KWh | L3: KWh | M3: KWh | N3: KWh | O3: KWh | P3: KWh | Q3: KWh | R3: KWh | S3: KWh | T3: KWh | U3: KWh | V3: KWh | W3: KWh | X3: KWh | Y3: KWh | Z3: KWh | AA3: KWh | AB3: KWh | AC3: KWh | AD3: KWh | AE3: KWh | AF3: KWh | AG3: KWh | AH3: KWh | AI3: KWh | AJ3: KWh | AK3: KWh | AL3: KWh | AM3: KWh | AN3: KWh | AO3: Reading m³ | AP3: Daily Consumption m³ | AQ3: Daily Consumption m³ | AR3: Daily Consumption m³ | AS3: Daily Consumption m³ | AT3: Daily Consumption m³ | AU3: Daily Consumption m³ | AV3: Daily Consumption m³ | AW3: Daily Consumption m³ | AX3: Daily Consumption m³ | AY3: Daily Consumption m³ | AZ3: Daily Consumption m³ | BA3: Daily Consumption m³ | BB3: Daily Consumption m³ | BC3: Daily Consumption m³ | BD3: Daily Consumption m³ | BE3: Daily Consumption m³ | BF3: Daily Consumption m³ | BG3: Daily Consumption m³ | BH3: Daily Consumption m³ | BI3: Daily Consumption m³ | BJ3: Daily Consumption m³ | BK3: Daily Consumption m³ | BL3: Daily Consumption m³ | BM3: Daily Consumption m³ | BN3: Daily Consumption m³ | BO3: Daily Consumption m³ | BP3: ROOM NIGHTS | BQ3: Total Food Covers
A4: 44865 | C4: 103941271 | D4: 31701 | E4: ='Gas-2'!G5 -> 0 | F4: 90 | AO4: =SUM(WATER!G6,WATER!L6,WATER!Q6,WATER!B6) -> 1132736 | AP4: 318 | BP4: ='Rooms nights and Food Covers'!B4 -> 32 | BQ4: ='Rooms nights and Food Covers'!C4 -> 195
A5: =A4+1 -> 44866 | C5: =SUM('GENSET #1'!C10+'GENSET #2'!C10+'GENSET #3'!C10+'GENSET #4'!C10+'GENSET #5'!C10) -> 103965441 | D5: =IF((C5-C4<0), "0",C5-C4) -> 24170 | E5: ='Gas-2'!G6 -> 90 | F5: =IF((E5-E4<0), "0",E5-E4) -> 90 | G5: ='GENSET #1'!D10 -> 1746 | H5: ='GENSET #2'!D10 -> 9811 | I5: ='GENSET #3'!D10 -> 7417 | J5: ='GENSET #4'!D10 -> 0 | K5: ='GENSET #5'!D10 -> 5196 | L5: ='FEEDER Consumption '!E5 -> 3680 | M5: ='FEEDER Consumption '!J5 -> 3861 | N5: ='FEEDER Consumption '!O5 -> 10978 | O5: ='FEEDER Consumption '!T5 -> 2400 | P5: ='FEEDER Consumption '!Y5 -> 2791 | Q5: ='FEEDER Consumption '!AD5 -> 1800 | R5: ='FEEDER Consumption '!AJ5 -> 465 | S5: ='FEEDER Consumption '!AO5 -> 800 | T5: ='FEEDER Consumption '!AT5 -> 1200 | U5: ='FEEDER Consumption '!AY5 -> 4020 | V5: ='FEEDER Consumption '!BI5 -> 200 | W5: ='FEEDER Consumption '!BI5 -> 200 | X5: ='FEEDER Consumption '!BN5 -> 1100 | Y5: ='FEEDER Consumption '!BS5 -> 140 | Z5: ='FEEDER Consumption '!BX5 -> 420 | AA5: ='FEEDER Consumption '!CC5 -> 1100 | AB5: ='FEEDER Consumption '!CH5 -> 410 | AC5: ='FEEDER Consumption '!CM5 -> 700 | AD5: ='FEEDER Consumption '!CR5 -> 700 | AE5: ='FEEDER Consumption '!DB5 -> 910 | AF5: ='FEEDER Consumption '!DB5 -> 910 | AG5: ='FEEDER Consumption '!DG5 -> 750 | AH5: ='FEEDER Consumption '!DL5 -> 620 | AI5: ='FEEDER Consumption '!DQ5 -> 270 | AJ5: ='FEEDER Consumption '!DV5 -> 140 | AK5: ='FEEDER Consumption '!EA5 -> 890 | AL5: ='FEEDER Consumption '!EF5 -> 270 | AM5: ='FEEDER Consumption '!EK5 -> 330 | AN5: ='FEEDER Consumption '!EP5 -> 430 | AO5: =SUM(WATER!C6,WATER!H6,WATER!M6,WATER!R6) -> 1133118 | AP5: =IF((AO5-AO4<0), "0",AO5-AO4) -> 382 | AQ5: =WATER!D6 -> 222 | AR5: =WATER!I6 -> 0 | AS5: =WATER!N6 -> 50 | AT5: =WATER!S6 -> 110 | AU5: =WATER!AD6 -> 19 | AV5: =WATER!AI6 -> 5 | AW5: =WATER!AN6 -> 8 | AX5: =WATER!AS6 -> 12 | AY5: =WATER!AX6 -> 9 | AZ5: =WATER!BC6 -> 6 | BA5: =WATER!BH6 -> 18 | BB5: =WATER!BM6 -> 8 | BC5: =WATER!BR6 -> 2 | BD5: =WATER!BW6 -> 0 | BE5: =WATER!CB6 -> 2 | BF5: =WATER!CG6 -> 3 | BG5: =WATER!CL6 -> 50 | BH5: =WATER!CQ6 -> 8 | BI5: =WATER!CV6 -> 1 | BJ5: =WATER!DA6 -> 1 | BK5: =WATER!DF6 -> 6 | BL5: =WATER!DK6 -> 3 | BM5: =WATER!DP6 -> 40 | BN5: =WATER!DU6 -> 2 | BO5: =WATER!DZ6 -> 2 | BP5: ='Rooms nights and Food Covers'!B5 -> 30.1 | BQ5: ='Rooms nights and Food Covers'!C5 -> 244
A6: =A5+1 -> 44867 | C6: =SUM('GENSET #1'!C11+'GENSET #2'!C11+'GENSET #3'!C11+'GENSET #4'!C11+'GENSET #5'!C11) -> 103990465 | D6: =IF((C6-C5<0), "0",C6-C5) -> 25024 | E6: ='Gas-2'!G7 -> 270 | F6: =IF((E6-E5<0), "0",E6-E5) -> 180 | G6: ='GENSET #1'!D11 -> 5831 | H6: ='GENSET #2'!D11 -> 9777 | I6: ='GENSET #3'!D11 -> 7500 | J6: ='GENSET #4'!D11 -> 0 | K6: ='GENSET #5'!D11 -> 1916 | L6: ='FEEDER Consumption '!E6 -> 4018 | M6: ='FEEDER Consumption '!J6 -> 3979 | N6: ='FEEDER Consumption '!O6 -> 11389 | O6: ='FEEDER Consumption '!T6 -> 2600 | P6: ='FEEDER Consumption '!Y6 -> 2867 | Q6: ='FEEDER Consumption '!AD6 -> 1700 | R6: ='FEEDER Consumption '!AJ6 -> 520 | S6: ='FEEDER Consumption '!AO6 -> 700 | T6: ='FEEDER Consumption '!AT6 -> 1300 | U6: ='FEEDER Consumption '!AY6 -> 4310 | V6: ='FEEDER Consumption '!BI6 -> 300 | W6: ='FEEDER Consumption '!BI6 -> 300 | X6: ='FEEDER Consumption '!BN6 -> 500 | Y6: ='FEEDER Consumption '!BS6 -> 170 | Z6: ='FEEDER Consumption '!BX6 -> 370 | AA6: ='FEEDER Consumption '!CC6 -> 1200 | AB6: ='FEEDER Consumption '!CH6 -> 420 | AC6: ='FEEDER Consumption '!CM6 -> 840 | AD6: ='FEEDER Consumption '!CR6 -> 760 | AE6: ='FEEDER Consumption '!DB6 -> 980 | AF6: ='FEEDER Consumption '!DB6 -> 980 | AG6: ='FEEDER Consumption '!DG6 -> 700 | AH6: ='FEEDER Consumption '!DL6 -> 670 | AI6: ='FEEDER Consumption '!DQ6 -> 310 | AJ6: ='FEEDER Consumption '!DV6 -> 130 | AK6: ='FEEDER Consumption '!EA6 -> 1000 | AL6: ='FEEDER Consumption '!EF6 -> 290 | AM6: ='FEEDER Consumption '!EK6 -> 350 | AN6: ='FEEDER Consumption '!EP6 -> 500 | AO6: =SUM(WATER!C7,WATER!H7,WATER!M7,WATER!R7) -> 1133470 | AP6: =IF((AO6-AO5<0), "0",AO6-AO5) -> 352 | AQ6: =WATER!D7 -> 205 | AR6: =WATER!I7 -> 0 | AS6: =WATER!N7 -> 34 | AT6: =WATER!S7 -> 113 | AU6: =WATER!AD7 -> 21 | AV6: =WATER!AI7 -> 6 | AW6: =WATER!AN7 -> 10 | AX6: =WATER!AS7 -> 12 | AY6: =WATER!AX7 -> 9 | AZ6: =WATER!BC7 -> 7 | BA6: =WATER!BH7 -> 10 | BB6: =WATER!BM7 -> 8 | BC6: =WATER!BR7 -> 1 | BD6: =WATER!BW7 -> 3 | BE6: =WATER!CB7 -> 2 | BF6: =WATER!CG7 -> 1 | BG6: =WATER!CL7 -> 26 | BH6: =WATER!CQ7 -> 9 | BI6: =WATER!CV7 -> 0 | BJ6: =WATER!DA7 -> 1 | BK6: =WATER!DF7 -> 2 | BL6: =WATER!DK7 -> 2 | BM6: =WATER!DP7 -> 30 | BN6: =WATER!DU7 -> 6 | BO6: =WATER!DZ7 -> 0 | BP6: ='Rooms nights and Food Covers'!B6 -> 34 | BQ6: ='Rooms nights and Food Covers'!C6 -> 237
A7: =A6+1 -> 44868 | C7: =SUM('GENSET #1'!C12+'GENSET #2'!C12+'GENSET #3'!C12+'GENSET #4'!C12+'GENSET #5'!C12) -> 104015705 | D7: =IF((C7-C6<0), "0",C7-C6) -> 25240 | E7: ='Gas-2'!G8 -> 225 | F7: =IF((E7-E6<0), "0",E7-E6) -> 0 | G7: ='GENSET #1'!D12 -> 7475 | H7: ='GENSET #2'!D12 -> 6525 | I7: ='GENSET #3'!D12 -> 4471 | J7: ='GENSET #4'!D12 -> 0 | K7: ='GENSET #5'!D12 -> 6769 | L7: ='FEEDER Consumption '!E7 -> 3803 | M7: ='FEEDER Consumption '!J7 -> 4138 | N7: ='FEEDER Consumption '!O7 -> 11452 | O7: ='FEEDER Consumption '!T7 -> 2600 | P7: ='FEEDER Consumption '!Y7 -> 2789 | Q7: ='FEEDER Consumption '!AD7 -> 1700 | R7: ='FEEDER Consumption '!AJ7 -> 498 | S7: ='FEEDER Consumption '!AO7 -> 800 | T7: ='FEEDER Consumption '!AT7 -> 1300 | U7: ='FEEDER Consumption '!AY7 -> 4080 | V7: ='FEEDER Consumption '!BI7 -> 300 | W7: ='FEEDER Consumption '!BI7 -> 300 | X7: ='FEEDER Consumption '!BN7 -> 600 | Y7: ='FEEDER Consumption '!BS7 -> 160 | Z7: ='FEEDER Consumption '!BX7 -> 440 | AA7: ='FEEDER Consumption '!CC7 -> 1100 | AB7: ='FEEDER Consumption '!CH7 -> 510 | AC7: ='FEEDER Consumption '!CM7 -> 960 | AD7: ='FEEDER Consumption '!CR7 -> 760 | AE7: ='FEEDER Consumption '!DB7 -> 1100 | AF7: ='FEEDER Consumption '!DB7 -> 1100 | AG7: ='FEEDER Consumption '!DG7 -> 710 | AH7: ='FEEDER Consumption '!DL7 -> 670 | AI7: ='FEEDER Consumption '!DQ7 -> 300 | AJ7: ='FEEDER Consumption '!DV7 -> 130 | AK7: ='FEEDER Consumption '!EA7 -> 890 | AL7: ='FEEDER Consumption '!EF7 -> 270 | AM7: ='FEEDER Consumption '!EK7 -> 350 | AN7: ='FEEDER Consumption '!EP7 -> 460 | AO7: =SUM(WATER!C8,WATER!H8,WATER!M8,WATER!R8) -> 1133855 | AP7: =IF((AO7-AO6<0), "0",AO7-AO6) -> 385 | AQ7: =WATER!D8 -> 239 | AR7: =WATER!I8 -> 0 | AS7: =WATER!N8 -> 24 | AT7: =WATER!S8 -> 122 | AU7: =WATER!AD8 -> 20 | AV7: =WATER!AI8 -> 8 | AW7: =WATER!AN8 -> 9 | AX7: =WATER!AS8 -> 12 | AY7: =WATER!AX8 -> 8 | AZ7: =WATER!BC8 -> 7 | BA7: =WATER!BH8 -> 9 | BB7: =WATER!BM8 -> 8 | BC7: =WATER!BR8 -> 1 | BD7: =WATER!BW8 -> 0 | BE7: =WATER!CB8 -> 6 | BF7: =WATER!CG8 -> 2 | BG7: =WATER!CL8 -> 24 | BH7: =WATER!CQ8 -> 7 | BI7: =WATER!CV8 -> 2 | BJ7: =WATER!DA8 -> 6 | BK7: =WATER!DF8 -> 2 | BL7: =WATER!DK8 -> 2 | BM7: =WATER!DP8 -> 20 | BN7: =WATER!DU8 -> 0 | BO7: =WATER!DZ8 -> 0 | BP7: ='Rooms nights and Food Covers'!B7 -> 34 | BQ7: ='Rooms nights and Food Covers'!C7 -> 307
A8: =A7+1 -> 44869 | C8: =SUM('GENSET #1'!C13+'GENSET #2'!C13+'GENSET #3'!C13+'GENSET #4'!C13+'GENSET #5'!C13) -> 104042196 | D8: =IF((C8-C7<0), "0",C8-C7) -> 26491 | E8: ='Gas-2'!G9 -> 270 | F8: =IF((E8-E7<0), "0",E8-E7) -> 45 | G8: ='GENSET #1'!D13 -> 9100 | H8: ='GENSET #2'!D13 -> 2952 | I8: ='GENSET #3'!D13 -> 9160 | J8: ='GENSET #4'!D13 -> 0 | K8: ='GENSET #5'!D13 -> 5279 | L8: ='FEEDER Consumption '!E8 -> 4186 | M8: ='FEEDER Consumption '!J8 -> 4483 | N8: ='FEEDER Consumption '!O8 -> 11928 | O8: ='FEEDER Consumption '!T8 -> 2500 | P8: ='FEEDER Consumption '!Y8 -> 2833 | Q8: ='FEEDER Consumption '!AD8 -> 2000 | R8: ='FEEDER Consumption '!AJ8 -> 481 | S8: ='FEEDER Consumption '!AO8 -> 800 | T8: ='FEEDER Consumption '!AT8 -> 1300 | U8: ='FEEDER Consumption '!AY8 -> 4080 | V8: ='FEEDER Consumption '!BI8 -> 300 | W8: ='FEEDER Consumption '!BI8 -> 300 | X8: ='FEEDER Consumption '!BN8 -> 0 | Y8: ='FEEDER Consumption '!BS8 -> 160 | Z8: ='FEEDER Consumption '!BX8 -> 420 | AA8: ='FEEDER Consumption '!CC8 -> 1100 | AB8: ='FEEDER Consumption '!CH8 -> 450 | AC8: ='FEEDER Consumption '!CM8 -> 980 | AD8: ='FEEDER Consumption '!CR8 -> 850 | AE8: ='FEEDER Consumption '!DB8 -> 1250 | AF8: ='FEEDER Consumption '!DB8 -> 1250 | AG8: ='FEEDER Consumption '!DG8 -> 790 | AH8: ='FEEDER Consumption '!DL8 -> 640 | AI8: ='FEEDER Consumption '!DQ8 -> 290 | AJ8: ='FEEDER Consumption '!DV8 -> 170 | AK8: ='FEEDER Consumption '!EA8 -> 960 | AL8: ='FEEDER Consumption '!EF8 -> 250 | AM8: ='FEEDER Consumption '!EK8 -> 0 | AN8: ='FEEDER Consumption '!EP8 -> 0 | AO8: =SUM(WATER!C9,WATER!H9,WATER!M9,WATER!R9) -> 1134230 | AP8: =IF((AO8-AO7<0), "0",AO8-AO7) -> 375 | AQ8: =WATER!D9 -> 230 | AR8: =WATER!I9 -> 0 | AS8: =WATER!N9 -> 1 | AT8: =WATER!S9 -> 144 | AU8: =WATER!AD9 -> 21 | AV8: =WATER!AI9 -> 4 | AW8: =WATER!AN9 -> 9 | AX8: =WATER!AS9 -> 13 | AY8: =WATER!AX9 -> 8 | AZ8: =WATER!BC9 -> 6 | BA8: =WATER!BH9 -> 9 | BB8: =WATER!BM9 -> 8 | BC8: =WATER!BR9 -> 0 | BD8: =WATER!BW9 -> 0 | BE8: =WATER!CB9 -> 3 | BF8: =WATER!CG9 -> 0 | BG8: =WATER!CL9 -> 0 | BH8: =WATER!CQ9 -> 0 | BI8: =WATER!CV9 -> 0 | BJ8: =WATER!DA9 -> 2 | BK8: =WATER!DF9 -> 2 | BL8: =WATER!DK9 -> 2 | BM8: =WATER!DP9 -> 0 | BN8: =WATER!DU9 -> 0 | BO8: =WATER!DZ9 -> 0 | BP8: ='Rooms nights and Food Covers'!B8 -> 40.8 | BQ8: ='Rooms nights and Food Covers'!C8 -> 306
A9: =A8+1 -> 44870 | C9: =SUM('GENSET #1'!C14+'GENSET #2'!C14+'GENSET #3'!C14+'GENSET #4'!C14+'GENSET #5'!C14) -> 104068342 | D9: =IF((C9-C8<0), "0",C9-C8) -> 26146 | E9: ='Gas-2'!G10 -> 225 | F9: =IF((E9-E8<0), "0",E9-E8) -> 0 | G9: ='GENSET #1'!D14 -> 9784 | H9: ='GENSET #2'!D14 -> 834 | I9: ='GENSET #3'!D14 -> 5744 | J9: ='GENSET #4'!D14 -> 0 | K9: ='GENSET #5'!D14 -> 9784 | L9: ='FEEDER Consumption '!E9 -> 4156 | M9: ='FEEDER Consumption '!J9 -> 4344 | N9: ='FEEDER Consumption '!O9 -> 11380 | O9: ='FEEDER Consumption '!T9 -> 2500 | P9: ='FEEDER Consumption '!Y9 -> 2773 | Q9: ='FEEDER Consumption '!AD9 -> 1700 | R9: ='FEEDER Consumption '!AJ9 -> 494 | S9: ='FEEDER Consumption '!AO9 -> 700 | T9: ='FEEDER Consumption '!AT9 -> 1400 | U9: ='FEEDER Consumption '!AY9 -> 3790 | V9: ='FEEDER Consumption '!BI9 -> 300 | W9: ='FEEDER Consumption '!BI9 -> 300 | X9: ='FEEDER Consumption '!BN9 -> 500 | Y9: ='FEEDER Consumption '!BS9 -> 160 | Z9: ='FEEDER Consumption '!BX9 -> 400 | AA9: ='FEEDER Consumption '!CC9 -> 1200 | AB9: ='FEEDER Consumption '!CH9 -> 430 | AC9: ='FEEDER Consumption '!CM9 -> 870 | AD9: ='FEEDER Consumption '!CR9 -> 870 | AE9: ='FEEDER Consumption '!DB9 -> 1130 | AF9: ='FEEDER Consumption '!DB9 -> 1130 | AG9: ='FEEDER Consumption '!DG9 -> 750 | AH9: ='FEEDER Consumption '!DL9 -> 640 | AI9: ='FEEDER Consumption '!DQ9 -> 270 | AJ9: ='FEEDER Consumption '!DV9 -> 150 | AK9: ='FEEDER Consumption '!EA9 -> 930 | AL9: ='FEEDER Consumption '!EF9 -> 250 | AM9: ='FEEDER Consumption '!EK9 -> 580 | AN9: ='FEEDER Consumption '!EP9 -> 920 | AO9: =SUM(WATER!C10,WATER!H10,WATER!M10,WATER!R10) -> 1134601 | AP9: =IF((AO9-AO8<0), "0",AO9-AO8) -> 371 | AQ9: =WATER!D10 -> 213 | AR9: =WATER!I10 -> 0 | AS9: =WATER!N10 -> 29 | AT9: =WATER!S10 -> 129 | AU9: =WATER!AD10 -> 21 | AV9: =WATER!AI10 -> 6 | AW9: =WATER!AN10 -> 10 | AX9: =WATER!AS10 -> 13 | AY9: =WATER!AX10 -> 9 | AZ9: =WATER!BC10 -> 6 | BA9: =WATER!BH10 -> 9 | BB9: =WATER!BM10 -> 8 | BC9: =WATER!BR10 -> 3 | BD9: =WATER!BW10 -> 0 | BE9: =WATER!CB10 -> 3 | BF9: =WATER!CG10 -> 4 | BG9: =WATER!CL10 -> 50 | BH9: =WATER!CQ10 -> 18 | BI9: =WATER!CV10 -> 1 | BJ9: =WATER!DA10 -> 4 | BK9: =WATER!DF10 -> 2 | BL9: =WATER!DK10 -> 0 | BM9: =WATER!DP10 -> 0 | BN9: =WATER!DU10 -> 1 | BO9: =WATER!DZ10 -> 6 | BP9: ='Rooms nights and Food Covers'!B9 -> 38.8 | BQ9: ='Rooms nights and Food Covers'!C9 -> 298
A10: =A9+1 -> 44871 | C10: =SUM('GENSET #1'!C15+'GENSET #2'!C15+'GENSET #3'!C15+'GENSET #4'!C15+'GENSET #5'!C15) -> 104095182 | D10: =IF((C10-C9<0), "0",C10-C9) -> 26840 | E10: ='Gas-2'!G11 -> 270 | F10: =IF((E10-E9<0), "0",E10-E9) -> 45 | G10: ='GENSET #1'!D15 -> 3169 | H10: ='GENSET #2'!D15 -> 11280 | I10: ='GENSET #3'!D15 -> 8335 | J10: ='GENSET #4'!D15 -> 0 | K10: ='GENSET #5'!D15 -> 4056 | L10: ='FEEDER Consumption '!E10 -> 4442 | M10: ='FEEDER Consumption '!J10 -> 4481 | N10: ='FEEDER Consumption '!O10 -> 12061 | O10: ='FEEDER Consumption '!T10 -> 2700 | P10: ='FEEDER Consumption '!Y10 -> 2898 | Q10: ='FEEDER Consumption '!AD10 -> 1900 | R10: ='FEEDER Consumption '!AJ10 -> 502 | S10: ='FEEDER Consumption '!AO10 -> 700 | T10: ='FEEDER Consumption '!AT10 -> 1500 | U10: ='FEEDER Consumption '!AY10 -> 4150 | V10: ='FEEDER Consumption '!BI10 -> 200 | W10: ='FEEDER Consumption '!BI10 -> 200 | X10: ='FEEDER Consumption '!BN10 -> 600 | Y10: ='FEEDER Consumption '!BS10 -> 150 | Z10: ='FEEDER Consumption '!BX10 -> 400 | AA10: ='FEEDER Consumption '!CC10 -> 1200 | AB10: ='FEEDER Consumption '!CH10 -> 490 | AC10: ='FEEDER Consumption '!CM10 -> 910 | AD10: ='FEEDER Consumption '!CR10 -> 860 | AE10: ='FEEDER Consumption '!DB10 -> 1250 | AF10: ='FEEDER Consumption '!DB10 -> 1250 | AG10: ='FEEDER Consumption '!DG10 -> 870 | AH10: ='FEEDER Consumption '!DL10 -> 680 | AI10: ='FEEDER Consumption '!DQ10 -> 240 | AJ10: ='FEEDER Consumption '!DV10 -> 120 | AK10: ='FEEDER Consumption '!EA10 -> 1020 | AL10: ='FEEDER Consumption '!EF10 -> 300 | AM10: ='FEEDER Consumption '!EK10 -> 360 | AN10: ='FEEDER Consumption '!EP10 -> 540 | AO10: =SUM(WATER!C11,WATER!H11,WATER!M11,WATER!R11) -> 1134986 | AP10: =IF((AO10-AO9<0), "0",AO10-AO9) -> 385 | AQ10: =WATER!D11 -> 245 | AR10: =WATER!I11 -> 0 | AS10: =WATER!N11 -> 0 | AT10: =WATER!S11 -> 140 | AU10: =WATER!AD11 -> 22 | AV10: =WATER!AI11 -> 6 | AW10: =WATER!AN11 -> 10 | AX10: =WATER!AS11 -> 11 | AY10: =WATER!AX11 -> 8 | AZ10: =WATER!BC11 -> 7 | BA10: =WATER!BH11 -> 11 | BB10: =WATER!BM11 -> 9 | BC10: =WATER!BR11 -> 2 | BD10: =WATER!BW11 -> 0 | BE10: =WATER!CB11 -> 2 | BF10: =WATER!CG11 -> 1 | BG10: =WATER!CL11 -> 28 | BH10: =WATER!CQ11 -> 8 | BI10: =WATER!CV11 -> 1 | BJ10: =WATER!DA11 -> 2 | BK10: =WATER!DF11 -> 2 | BL10: =WATER!DK11 -> 4 | BM10: =WATER!DP11 -> 27 | BN10: =WATER!DU11 -> 5 | BO10: =WATER!DZ11 -> 2 | BP10: ='Rooms nights and Food Covers'!B10 -> 31.1 | BQ10: ='Rooms nights and Food Covers'!C10 -> 299
A11: =A10+1 -> 44872 | C11: =SUM('GENSET #1'!C16+'GENSET #2'!C16+'GENSET #3'!C16+'GENSET #4'!C16+'GENSET #5'!C16) -> 104121486 | D11: =IF((C11-C10<0), "0",C11-C10) -> 26304 | E11: ='Gas-2'!G12 -> 270 | F11: =IF((E11-E10<0), "0",E11-E10) -> 0 | G11: ='GENSET #1'!D16 -> 7349 | H11: ='GENSET #2'!D16 -> 9634 | I11: ='GENSET #3'!D16 -> 4237 | J11: ='GENSET #4'!D16 -> 0 | K11: ='GENSET #5'!D16 -> 5084 | L11: ='FEEDER Consumption '!E11 -> 4402 | M11: ='FEEDER Consumption '!J11 -> 4141 | N11: ='FEEDER Consumption '!O11 -> 11776 | O11: ='FEEDER Consumption '!T11 -> 2400 | P11: ='FEEDER Consumption '!Y11 -> 2811 | Q11: ='FEEDER Consumption '!AD11 -> 1900 | R11: ='FEEDER Consumption '!AJ11 -> 458 | S11: ='FEEDER Consumption '!AO11 -> 700 | T11: ='FEEDER Consumption '!AT11 -> 1300 | U11: ='FEEDER Consumption '!AY11 -> 3910 | V11: ='FEEDER Consumption '!BI11 -> 300 | W11: ='FEEDER Consumption '!BI11 -> 300 | X11: ='FEEDER Consumption '!BN11 -> 500 | Y11: ='FEEDER Consumption '!BS11 -> 160 | Z11: ='FEEDER Consumption '!BX11 -> 450 | AA11: ='FEEDER Consumption '!CC11 -> 1100 | AB11: ='FEEDER Consumption '!CH11 -> 460 | AC11: ='FEEDER Consumption '!CM11 -> 810 | AD11: ='FEEDER Consumption '!CR11 -> 910 | AE11: ='FEEDER Consumption '!DB11 -> 1050 | AF11: ='FEEDER Consumption '!DB11 -> 1050 | AG11: ='FEEDER Consumption '!DG11 -> 740 | AH11: ='FEEDER Consumption '!DL11 -> 610 | AI11: ='FEEDER Consumption '!DQ11 -> 350 | AJ11: ='FEEDER Consumption '!DV11 -> 120 | AK11: ='FEEDER Consumption '!EA11 -> 1000 | AL11: ='FEEDER Consumption '!EF11 -> 250 | AM11: ='FEEDER Consumption '!EK11 -> 330 | AN11: ='FEEDER Consumption '!EP11 -> 510 | AO11: =SUM(WATER!C12,WATER!H12,WATER!M12,WATER!R12) -> 1135359 | AP11: =IF((AO11-AO10<0), "0",AO11-AO10) -> 373 | AQ11: =WATER!D12 -> 229 | AR11: =WATER!I12 -> 0 | AS11: =WATER!N12 -> 0 | AT11: =WATER!S12 -> 144 | AU11: =WATER!AD12 -> 25 | AV11: =WATER!AI12 -> 6 | AW11: =WATER!AN12 -> 9 | AX11: =WATER!AS12 -> 11 | AY11: =WATER!AX12 -> 9 | AZ11: =WATER!BC12 -> 7 | BA11: =WATER!BH12 -> 8 | BB11: =WATER!BM12 -> 7 | BC11: =WATER!BR12 -> 2 | BD11: =WATER!BW12 -> 2 | BE11: =WATER!CB12 -> 3 | BF11: =WATER!CG12 -> 1 | BG11: =WATER!CL12 -> 27 | BH11: =WATER!CQ12 -> 8 | BI11: =WATER!CV12 -> 1 | BJ11: =WATER!DA12 -> 3 | BK11: =WATER!DF12 -> 13 | BL11: =WATER!DK12 -> 3 | BM11: =WATER!DP12 -> 0 | BN11: =WATER!DU12 -> 3 | BO11: =WATER!DZ12 -> 2 | BP11: ='Rooms nights and Food Covers'!B11 -> 29.1 | BQ11: ='Rooms nights and Food Covers'!C11 -> 247
A12: =A11+1 -> 44873 | C12: =SUM('GENSET #1'!C17+'GENSET #2'!C17+'GENSET #3'!C17+'GENSET #4'!C17+'GENSET #5'!C17) -> 104148108 | D12: =IF((C12-C11<0), "0",C12-C11) -> 26622 | E12: ='Gas-2'!G13 -> 270 | F12: =IF((E12-E11<0), "0",E12-E11) -> 0 | G12: ='GENSET #1'!D17 -> 2387 | H12: ='GENSET #2'!D17 -> 13482 | I12: ='GENSET #3'!D17 -> 4128 | J12: ='GENSET #4'!D17 -> 0 | K12: ='GENSET #5'!D17 -> 6625 | L12: ='FEEDER Consumption '!E12 -> 4404 | M12: ='FEEDER Consumption '!J12 -> 4063 | N12: ='FEEDER Consumption '!O12 -> 11713 | O12: ='FEEDER Consumption '!T12 -> 2400 | P12: ='FEEDER Consumption '!Y12 -> 2943 | Q12: ='FEEDER Consumption '!AD12 -> 1900 | R12: ='FEEDER Consumption '!AJ12 -> 500 | S12: ='FEEDER Consumption '!AO12 -> 800 | T12: ='FEEDER Consumption '!AT12 -> 1600 | U12: ='FEEDER Consumption '!AY12 -> 4020 | V12: ='FEEDER Consumption '!BI12 -> 300 | W12: ='FEEDER Consumption '!BI12 -> 300 | X12: ='FEEDER Consumption '!BN12 -> 600 | Y12: ='FEEDER Consumption '!BS12 -> 150 | Z12: ='FEEDER Consumption '!BX12 -> 450 | AA12: ='FEEDER Consumption '!CC12 -> 1200 | AB12: ='FEEDER Consumption '!CH12 -> 430 | AC12: ='FEEDER Consumption '!CM12 -> 1040 | AD12: ='FEEDER Consumption '!CR12 -> 960 | AE12: ='FEEDER Consumption '!DB12 -> 1070 | AF12: ='FEEDER Consumption '!DB12 -> 1070 | AG12: ='FEEDER Consumption '!DG12 -> 780 | AH12: ='FEEDER Consumption '!DL12 -> 640 | AI12: ='FEEDER Consumption '!DQ12 -> 290 | AJ12: ='FEEDER Consumption '!DV12 -> 150 | AK12: ='FEEDER Consumption '!EA12 -> 1110 | AL12: ='FEEDER Consumption '!EF12 -> 220 | AM12: ='FEEDER Consumption '!EK12 -> 370 | AN12: ='FEEDER Consumption '!EP12 -> 460 | AO12: =SUM(WATER!C13,WATER!H13,WATER!M13,WATER!R13) -> 1135763 | AP12: =IF((AO12-AO11<0), "0",AO12-AO11) -> 404 | AQ12: =WATER!D13 -> 254 | AR12: =WATER!I13 -> 0 | AS12: =WATER!N13 -> 1 | AT12: =WATER!S13 -> 149 | AU12: =WATER!AD13 -> 20 | AV12: =WATER!AI13 -> 7 | AW12: =WATER!AN13 -> 9 | AX12: =WATER!AS13 -> 10 | AY12: =WATER!AX13 -> 8 | AZ12: =WATER!BC13 -> 6 | BA12: =WATER!BH13 -> 8 | BB12: =WATER!BM13 -> 8 | BC12: =WATER!BR13 -> 2 | BD12: =WATER!BW13 -> 0 | BE12: =WATER!CB13 -> 5 | BF12: =WATER!CG13 -> 5 | BG12: =WATER!CL13 -> 32 | BH12: =WATER!CQ13 -> 8 | BI12: =WATER!CV13 -> 1 | BJ12: =WATER!DA13 -> 6 | BK12: =WATER!DF13 -> 4 | BL12: =WATER!DK13 -> 5 | BM12: =WATER!DP13 -> 33 | BN12: =WATER!DU13 -> 2 | BO12: =WATER!DZ13 -> 1 | BP12: ='Rooms nights and Food Covers'!B12 -> 34 | BQ12: ='Rooms nights and Food Covers'!C12 -> 274
A13: =A12+1 -> 44874 | C13: =SUM('GENSET #1'!C18+'GENSET #2'!C18+'GENSET #3'!C18+'GENSET #4'!C18+'GENSET #5'!C18) -> 104174782 | D13: =IF((C13-C12<0), "0",C13-C12) -> 26674 | E13: ='Gas-2'!G14 -> 270 | F13: =IF((E13-E12<0), "0",E13-E12) -> 0 | G13: ='GENSET #1'!D18 -> 6611 | H13: ='GENSET #2'!D18 -> 9452 | I13: ='GENSET #3'!D18 -> 7873 | J13: ='GENSET #4'!D18 -> 0 | K13: ='GENSET #5'!D18 -> 2738 | L13: ='FEEDER Consumption '!E13 -> 4316 | M13: ='FEEDER Consumption '!J13 -> 3767 | N13: ='FEEDER Consumption '!O13 -> 12008 | O13: ='FEEDER Consumption '!T13 -> 2500 | P13: ='FEEDER Consumption '!Y13 -> 2909 | Q13: ='FEEDER Consumption '!AD13 -> 1800 | R13: ='FEEDER Consumption '!AJ13 -> 506 | S13: ='FEEDER Consumption '!AO13 -> 700 | T13: ='FEEDER Consumption '!AT13 -> 1800 | U13: ='FEEDER Consumption '!AY13 -> 3950 | V13: ='FEEDER Consumption '!BI13 -> 300 | W13: ='FEEDER Consumption '!BI13 -> 300 | X13: ='FEEDER Consumption '!BN13 -> 600 | Y13: ='FEEDER Consumption '!BS13 -> 180 | Z13: ='FEEDER Consumption '!BX13 -> 410 | AA13: ='FEEDER Consumption '!CC13 -> 1200 | AB13: ='FEEDER Consumption '!CH13 -> 380 | AC13: ='FEEDER Consumption '!CM13 -> 820 | AD13: ='FEEDER Consumption '!CR13 -> 730 | AE13: ='FEEDER Consumption '!DB13 -> 0 | AF13: ='FEEDER Consumption '!DB13 -> 0 | AG13: ='FEEDER Consumption '!DG13 -> 690 | AH13: ='FEEDER Consumption '!DL13 -> 540 | AI13: ='FEEDER Consumption '!DQ13 -> 260 | AJ13: ='FEEDER Consumption '!DV13 -> 110 | AK13: ='FEEDER Consumption '!EA13 -> 870 | AL13: ='FEEDER Consumption '!EF13 -> 200 | AM13: ='FEEDER Consumption '!EK13 -> 430 | AN13: ='FEEDER Consumption '!EP13 -> 520 | AO13: =SUM(WATER!C14,WATER!H14,WATER!M14,WATER!R14) -> 1136119 | AP13: =IF((AO13-AO12<0), "0",AO13-AO12) -> 356 | AQ13: =WATER!D14 -> 224 | AR13: =WATER!I14 -> 0 | AS13: =WATER!N14 -> 0 | AT13: =WATER!S14 -> 132 | AU13: =WATER!AD14 -> 24 | AV13: =WATER!AI14 -> 6 | AW13: =WATER!AN14 -> 9 | AX13: =WATER!AS14 -> 10 | AY13: =WATER!AX14 -> 8 | AZ13: =WATER!BC14 -> 6 | BA13: =WATER!BH14 -> 9 | BB13: =WATER!BM14 -> 7 | BC13: =WATER!BR14 -> 2 | BD13: =WATER!BW14 -> 0 | BE13: =WATER!CB14 -> 4 | BF13: =WATER!CG14 -> 2 | BG13: =WATER!CL14 -> 32 | BH13: =WATER!CQ14 -> 7 | BI13: =WATER!CV14 -> 1 | BJ13: =WATER!DA14 -> 9 | BK13: =WATER!DF14 -> 3 | BL13: =WATER!DK14 -> 2 | BM13: =WATER!DP14 -> 19 | BN13: =WATER!DU14 -> 1 | BO13: =WATER!DZ14 -> 1 | BP13: ='Rooms nights and Food Covers'!B13 -> 29.1 | BQ13: ='Rooms nights and Food Covers'!C13 -> 222
A14: =A13+1 -> 44875 | C14: =SUM('GENSET #1'!C19+'GENSET #2'!C19+'GENSET #3'!C19+'GENSET #4'!C19+'GENSET #5'!C19) -> 104201047 | D14: =IF((C14-C13<0), "0",C14-C13) -> 26265 | E14: ='Gas-2'!G15 -> 90 | F14: =IF((E14-E13<0), "0",E14-E13) -> 0 | G14: ='GENSET #1'!D19 -> 1193 | H14: ='GENSET #2'!D19 -> 11688 | I14: ='GENSET #3'!D19 -> 9219 | J14: ='GENSET #4'!D19 -> 0 | K14: ='GENSET #5'!D19 -> 4165 | L14: ='FEEDER Consumption '!E14 -> 4316 | M14: ='FEEDER Consumption '!J14 -> 3767 | N14: ='FEEDER Consumption '!O14 -> 12008 | O14: ='FEEDER Consumption '!T14 -> 2500 | P14: ='FEEDER Consumption '!Y14 -> 2899 | Q14: ='FEEDER Consumption '!AD14 -> 2200 | R14: ='FEEDER Consumption '!AJ14 -> 499 | S14: ='FEEDER Consumption '!AO14 -> 700 | T14: ='FEEDER Consumption '!AT14 -> 1300 | U14: ='FEEDER Consumption '!AY14 -> 3860 | V14: ='FEEDER Consumption '!BI14 -> 200 | W14: ='FEEDER Consumption '!BI14 -> 200 | X14: ='FEEDER Consumption '!BN14 -> 500 | Y14: ='FEEDER Consumption '!BS14 -> 210 | Z14: ='FEEDER Consumption '!BX14 -> 470 | AA14: ='FEEDER Consumption '!CC14 -> 1100 | AB14: ='FEEDER Consumption '!CH14 -> 510 | AC14: ='FEEDER Consumption '!CM14 -> 830 | AD14: ='FEEDER Consumption '!CR14 -> 790 | AE14: ='FEEDER Consumption '!DB14 -> 850 | AF14: ='FEEDER Consumption '!DB14 -> 850 | AG14: ='FEEDER Consumption '!DG14 -> 670 | AH14: ='FEEDER Consumption '!DL14 -> 560 | AI14: ='FEEDER Consumption '!DQ14 -> 250 | AJ14: ='FEEDER Consumption '!DV14 -> 140 | AK14: ='FEEDER Consumption '!EA14 -> 970 | AL14: ='FEEDER Consumption '!EF14 -> 240 | AM14: ='FEEDER Consumption '!EK14 -> 350 | AN14: ='FEEDER Consumption '!EP14 -> 530 | AO14: =SUM(WATER!C15,WATER!H15,WATER!M15,WATER!R15) -> 1136567 | AP14: =IF((AO14-AO13<0), "0",AO14-AO13) -> 448 | AQ14: =WATER!D15 -> 249 | AR14: =WATER!I15 -> 0 | AS14: =WATER!N15 -> 48 | AT14: =WATER!S15 -> 151 | AU14: =WATER!AD15 -> 22 | AV14: =WATER!AI15 -> 6 | AW14: =WATER!AN15 -> 11 | AX14: =WATER!AS15 -> 10 | AY14: =WATER!AX15 -> 9 | AZ14: =WATER!BC15 -> 7 | BA14: =WATER!BH15 -> 8 | BB14: =WATER!BM15 -> 8 | BC14: =WATER!BR15 -> 1 | BD14: =WATER!BW15 -> 0 | BE14: =WATER!CB15 -> 2 | BF14: =WATER!CG15 -> 0 | BG14: =WATER!CL15 -> 27 | BH14: =WATER!CQ15 -> 11 | BI14: =WATER!CV15 -> 1 | BJ14: =WATER!DA15 -> 5 | BK14: =WATER!DF15 -> 2 | BL14: =WATER!DK15 -> 6 | BM14: =WATER!DP15 -> 14 | BN14: =WATER!DU15 -> 3 | BO14: =WATER!DZ15 -> 3 | BP14: ='Rooms nights and Food Covers'!B14 -> 27.2 | BQ14: ='Rooms nights and Food Covers'!C14 -> 209
A15: =A14+1 -> 44876 | C15: =SUM('GENSET #1'!C20+'GENSET #2'!C20+'GENSET #3'!C20+'GENSET #4'!C20+'GENSET #5'!C20) -> 104228008 | D15: =IF((C15-C14<0), "0",C15-C14) -> 26961 | E15: ='Gas-2'!G16 -> 90 | F15: =IF((E15-E14<0), "0",E15-E14) -> 0 | G15: ='GENSET #1'!D20 -> 7249 | H15: ='GENSET #2'!D20 -> 8458 | I15: ='GENSET #3'!D20 -> 5845 | J15: ='GENSET #4'!D20 -> 0 | K15: ='GENSET #5'!D20 -> 5409 | L15: ='FEEDER Consumption '!E15 -> 3849 | M15: ='FEEDER Consumption '!J15 -> 3771 | N15: ='FEEDER Consumption '!O15 -> 13626 | O15: ='FEEDER Consumption '!T15 -> 2500 | P15: ='FEEDER Consumption '!Y15 -> 2843 | Q15: ='FEEDER Consumption '!AD15 -> 2500 | R15: ='FEEDER Consumption '!AJ15 -> 490 | S15: ='FEEDER Consumption '!AO15 -> 800 | T15: ='FEEDER Consumption '!AT15 -> 1400 | U15: ='FEEDER Consumption '!AY15 -> 4000 | V15: ='FEEDER Consumption '!BI15 -> 300 | W15: ='FEEDER Consumption '!BI15 -> 300 | X15: ='FEEDER Consumption '!BN15 -> 600 | Y15: ='FEEDER Consumption '!BS15 -> 190 | Z15: ='FEEDER Consumption '!BX15 -> 410 | AA15: ='FEEDER Consumption '!CC15 -> 1200 | AB15: ='FEEDER Consumption '!CH15 -> 440 | AC15: ='FEEDER Consumption '!CM15 -> 830 | AD15: ='FEEDER Consumption '!CR15 -> 670 | AE15: ='FEEDER Consumption '!DB15 -> 820 | AF15: ='FEEDER Consumption '!DB15 -> 820 | AG15: ='FEEDER Consumption '!DG15 -> 820 | AH15: ='FEEDER Consumption '!DL15 -> 660 | AI15: ='FEEDER Consumption '!DQ15 -> 250 | AJ15: ='FEEDER Consumption '!DV15 -> 140 | AK15: ='FEEDER Consumption '!EA15 -> 910 | AL15: ='FEEDER Consumption '!EF15 -> 270 | AM15: ='FEEDER Consumption '!EK15 -> 250 | AN15: ='FEEDER Consumption '!EP15 -> 530 | AO15: =SUM(WATER!C16,WATER!H16,WATER!M16,WATER!R16) -> 1136996 | AP15: =IF((AO15-AO14<0), "0",AO15-AO14) -> 429 | AQ15: =WATER!D16 -> 247 | AR15: =WATER!I16 -> 21 | AS15: =WATER!N16 -> 22 | AT15: =WATER!S16 -> 139 | AU15: =WATER!AD16 -> 20 | AV15: =WATER!AI16 -> 6 | AW15: =WATER!AN16 -> 9 | AX15: =WATER!AS16 -> 10 | AY15: =WATER!AX16 -> 8 | AZ15: =WATER!BC16 -> 6 | BA15: =WATER!BH16 -> 8 | BB15: =WATER!BM16 -> 7 | BC15: =WATER!BR16 -> 2 | BD15: =WATER!BW16 -> 0 | BE15: =WATER!CB16 -> 4 | BF15: =WATER!CG16 -> 3 | BG15: =WATER!CL16 -> 25 | BH15: =WATER!CQ16 -> 10 | BI15: =WATER!CV16 -> 1 | BJ15: =WATER!DA16 -> 2 | BK15: =WATER!DF16 -> 3 | BL15: =WATER!DK16 -> 3 | BM15: =WATER!DP16 -> 16 | BN15: =WATER!DU16 -> 1 | BO15: =WATER!DZ16 -> 1 | BP15: ='Rooms nights and Food Covers'!B15 -> 30.1 | BQ15: ='Rooms nights and Food Covers'!C15 -> 226
A16: =A15+1 -> 44877 | C16: =SUM('GENSET #1'!C21+'GENSET #2'!C21+'GENSET #3'!C21+'GENSET #4'!C21+'GENSET #5'!C21) -> 104254824 | D16: =IF((C16-C15<0), "0",C16-C15) -> 26816 | E16: ='Gas-2'!G17 -> 450 | F16: =IF((E16-E15<0), "0",E16-E15) -> 360 | G16: ='GENSET #1'!D21 -> 4553 | H16: ='GENSET #2'!D21 -> 12675 | I16: ='GENSET #3'!D21 -> 9545 | J16: ='GENSET #4'!D21 -> 0 | K16: ='GENSET #5'!D21 -> 43 | L16: ='FEEDER Consumption '!E16 -> 3978 | M16: ='FEEDER Consumption '!J16 -> 4164 | N16: ='FEEDER Consumption '!O16 -> 12679 | O16: ='FEEDER Consumption '!T16 -> 2400 | P16: ='FEEDER Consumption '!Y16 -> 2861 | Q16: ='FEEDER Consumption '!AD16 -> 2700 | R16: ='FEEDER Consumption '!AJ16 -> 509 | S16: ='FEEDER Consumption '!AO16 -> 700 | T16: ='FEEDER Consumption '!AT16 -> 1400 | U16: ='FEEDER Consumption '!AY16 -> 3710 | V16: ='FEEDER Consumption '!BI16 -> 300 | W16: ='FEEDER Consumption '!BI16 -> 300 | X16: ='FEEDER Consumption '!BN16 -> 500 | Y16: ='FEEDER Consumption '!BS16 -> 140 | Z16: ='FEEDER Consumption '!BX16 -> 370 | AA16: ='FEEDER Consumption '!CC16 -> 1100 | AB16: ='FEEDER Consumption '!CH16 -> 460 | AC16: ='FEEDER Consumption '!CM16 -> 850 | AD16: ='FEEDER Consumption '!CR16 -> 710 | AE16: ='FEEDER Consumption '!DB16 -> 1020 | AF16: ='FEEDER Consumption '!DB16 -> 1020 | AG16: ='FEEDER Consumption '!DG16 -> 820 | AH16: ='FEEDER Consumption '!DL16 -> 760 | AI16: ='FEEDER Consumption '!DQ16 -> 260 | AJ16: ='FEEDER Consumption '!DV16 -> 110 | AK16: ='FEEDER Consumption '!EA16 -> 900 | AL16: ='FEEDER Consumption '!EF16 -> 250 | AM16: ='FEEDER Consumption '!EK16 -> 340 | AN16: ='FEEDER Consumption '!EP16 -> 540 | AO16: =SUM(WATER!C17,WATER!H17,WATER!M17,WATER!R17) -> 1137515 | AP16: =IF((AO16-AO15<0), "0",AO16-AO15) -> 519 | AQ16: =WATER!D17 -> 244 | AR16: =WATER!I17 -> 119 | AS16: =WATER!N17 -> 22 | AT16: =WATER!S17 -> 134 | AU16: =WATER!AD17 -> 23 | AV16: =WATER!AI17 -> 7 | AW16: =WATER!AN17 -> 9 | AX16: =WATER!AS17 -> 10 | AY16: =WATER!AX17 -> 10 | AZ16: =WATER!BC17 -> 7 | BA16: =WATER!BH17 -> 8 | BB16: =WATER!BM17 -> 8 | BC16: =WATER!BR17 -> 2 | BD16: =WATER!BW17 -> 1 | BE16: =WATER!CB17 -> 1 | BF16: =WATER!CG17 -> 2 | BG16: =WATER!CL17 -> 38 | BH16: =WATER!CQ17 -> 9 | BI16: =WATER!CV17 -> 1 | BJ16: =WATER!DA17 -> 4 | BK16: =WATER!DF17 -> 3 | BL16: =WATER!DK17 -> 1 | BM16: =WATER!DP17 -> 15 | BN16: =WATER!DU17 -> 3 | BO16: =WATER!DZ17 -> 7 | BP16: ='Rooms nights and Food Covers'!B16 -> 36.9 | BQ16: ='Rooms nights and Food Covers'!C16 -> 237
... A34: =A33+1 -> 44895 | C34: =SUM('GENSET #1'!C39+'GENSET #2'!C39+'GENSET #3'!C39+'GENSET #4'!C39+'GENSET #5'!C39) -> 104697810 | D34: =IF((C34-C33<0), "0",C34-C33) -> 25963 | E34: ='Gas-2'!G35 -> 270 | F34: =IF((E34-E33<0), "0",E34-E33) -> 90 | G34: ='GENSET #1'!D39 -> 7081 | H34: ='GENSET #2'!D39 -> 7070 | I34: ='GENSET #3'!D39 -> 3789 | J34: ='GENSET #4'!D39 -> 0 | K34: ='GENSET #5'!D39 -> 8023 | L34: ='FEEDER Consumption '!E34 -> 3797 | M34: ='FEEDER Consumption '!J34 -> 4393 | N34: ='FEEDER Consumption '!O34 -> 11846 | O34: ='FEEDER Consumption '!T34 -> 2400 | P34: ='FEEDER Consumption '!Y34 -> 2808 | Q34: ='FEEDER Consumption '!AD34 -> 3900 | R34: ='FEEDER Consumption '!AJ34 -> 407 | S34: ='FEEDER Consumption '!AO34 -> 700 | T34: ='FEEDER Consumption '!AT34 -> 1300 | U34: ='FEEDER Consumption '!AY34 -> 3930 | V34: ='FEEDER Consumption '!BI34 -> 300 | W34: ='FEEDER Consumption '!BI34 -> 300 | X34: ='FEEDER Consumption '!BN34 -> 500 | Y34: ='FEEDER Consumption '!BS34 -> 170 | Z34: ='FEEDER Consumption '!BX34 -> 440 | AA34: ='FEEDER Consumption '!CC34 -> 1300 | AB34: ='FEEDER Consumption '!CH34 -> 740 | AC34: ='FEEDER Consumption '!CM34 -> 840 | AD34: ='FEEDER Consumption '!CR34 -> 1770 | AE34: ='FEEDER Consumption '!DB34 -> 1000 | AF34: ='FEEDER Consumption '!DB34 -> 1000 | AG34: ='FEEDER Consumption '!DG34 -> 840 | AH34: ='FEEDER Consumption '!DL34 -> 630 | AI34: ='FEEDER Consumption '!DQ34 -> 0 | AJ34: ='FEEDER Consumption '!DV34 -> 0 | AK34: ='FEEDER Consumption '!EA34 -> 930 | AL34: ='FEEDER Consumption '!EF34 -> 260 | AM34: ='FEEDER Consumption '!EK34 -> 770 | AN34: ='FEEDER Consumption '!EP34 -> 490 | AO34: =SUM(WATER!C35,WATER!H35,WATER!M35,WATER!R35) -> 1143399 | AP34: =IF((AO34-AO33<0), "0",AO34-AO33) -> 353 | AQ34: =WATER!D35 -> 204 | AR34: =WATER!I35 -> 101 | AS34: =WATER!N35 -> 0 | AT34: =WATER!S35 -> 48 | AU34: =WATER!AD35 -> 20 | AV34: =WATER!AI35 -> 6 | AW34: =WATER!AN35 -> 9 | AX34: =WATER!AS35 -> 10 | AY34: =WATER!AX35 -> 7 | AZ34: =WATER!BC35 -> 6 | BA34: =WATER!BH35 -> 4 | BB34: =WATER!BM35 -> 7 | BC34: =WATER!BR35 -> 1 | BD34: =WATER!BW35 -> 1 | BE34: =WATER!CB35 -> 2 | BF34: =WATER!CG35 -> 1 | BG34: =WATER!CL35 -> 26 | BH34: =WATER!CQ35 -> 11 | BI34: =WATER!CV35 -> 1 | BJ34: =WATER!DA35 -> -29 | BK34: =WATER!DF35 -> 3 | BL34: =WATER!DK35 -> 2 | BM34: =WATER!DP35 -> 15 | BN34: =WATER!DU35 -> 1 | BO34: =WATER!DZ35 -> 2 | BP34: ='Rooms nights and Food Covers'!B34 -> 35.9 | BQ34: ='Rooms nights and Food Covers'!C34 -> 264

Sheet Rooms nights and Food Covers
A2: Days
A3: Date | B3: ROOM NIGHTS | C3: Total Food Covers
A4: 44865 | B4: 32 | C4: 195
A5: =A4+1 -> 44866 | B5: 30.1 | C5: 244
A6: =A5+1 -> 44867 | B6: 34 | C6: 237
A7: =A6+1 -> 44868 | B7: 34 | C7: 307
A8: =A7+1 -> 44869 | B8: 40.8 | C8: 306
A9: =A8+1 -> 44870 | B9: 38.8 | C9: 298
A10: =A9+1 -> 44871 | B10: 31.1 | C10: 299
A11: =A10+1 -> 44872 | B11: 29.1 | C11: 247
A12: =A11+1 -> 44873 | B12: 34 | C12: 274
A13: =A12+1 -> 44874 | B13: 29.1 | C13: 222
A14: =A13+1 -> 44875 | B14: 27.2 | C14: 209
A15: =A14+1 -> 44876 | B15: 30.1 | C15: 226
A16: =A15+1 -> 44877 | B16: 36.9 | C16: 237
... A34: =A33+1 -> 44895 | B34: 35.9 | C34: 264

Sheet Finance Only
A1: Four Seasons Landaa Giraavaru
A3: Property | B3: MLG | G3: 44470 | H3: =NOW() -> 44909.764 | J3: =H3-G3 -> 439.76365
A4: Month | B4: 44867
A5: Year | B5: 2022
A7: DAY | B7: Electricity Consumption ( kwh) | C7: Diesel Consumption (Liters) | D7: Solar Power Consumption(kwh) | E7: Gas Consumption (kg) | F7: Water Consumption ( m3) | G7: Occupancy | H7: Weather | I7: Ambian Temperature | J7: Electricity Variance (Today vs Yesterday)
A8: 1 | B8: =SUM('GENSET #1:GENSET #5'!D10) -> 24170 | C8: ='Diesel consumption'!D5 -> 6640 | D8: ='SOLAR METER READING'!D9 -> 3114 | E8: ='Gas-2'!G6 -> 90 | F8: =WATER!V6 -> 382 | G8: =WATER!W6 -> 30.1 | H8: ='SOLAR METER READING'!E9 -> 0 | I8: ='SOLAR METER READING'!F9 -> 0
A9: 2 | B9: =SUM('GENSET #1:GENSET #5'!D11) -> 25024 | C9: ='Diesel consumption'!D6 -> 6920 | D9: ='SOLAR METER READING'!D10 -> 3123 | E9: ='Gas-2'!G7 -> 270 | F9: =WATER!V7 -> 352 | G9: =WATER!W7 -> 34 | H9: ='SOLAR METER READING'!E10 -> 0 | I9: ='SOLAR METER READING'!F10 -> 0 | J9: =B9-B8 -> 854
A10: 3 | B10: =SUM('GENSET #1:GENSET #5'!D12) -> 25240 | C10: ='Diesel consumption'!D7 -> 7140 | D10: ='SOLAR METER READING'!D11 -> 3013 | E10: ='Gas-2'!G8 -> 225 | F10: =WATER!V8 -> 385 | G10: =WATER!W8 -> 34 | H10: ='SOLAR METER READING'!E11 -> 0 | I10: ='SOLAR METER READING'!F11 -> 0 | J10: =B10-B9 -> 216
A11: 4 | B11: =SUM('GENSET #1:GENSET #5'!D13) -> 26491 | C11: ='Diesel consumption'!D8 -> 7510 | D11: ='SOLAR METER READING'!D12 -> 3102 | E11: ='Gas-2'!G9 -> 270 | F11: =WATER!V9 -> 375 | G11: =WATER!W9 -> 40.8 | H11: ='SOLAR METER READING'!E12 -> 0 | I11: ='SOLAR METER READING'!F12 -> 0 | J11: =B11-B10 -> 1251
A12: 5 | B12: =SUM('GENSET #1:GENSET #5'!D14) -> 26146 | C12: ='Diesel consumption'!D9 -> 7530 | D12: ='SOLAR METER READING'!D13 -> 2935 | E12: ='Gas-2'!G10 -> 225 | F12: =WATER!V10 -> 371 | G12: =WATER!W10 -> 38.8 | H12: ='SOLAR METER READING'!E13 -> 0 | I12: ='SOLAR METER READING'!F13 -> 0 | J12: =B12-B11 -> -345
A13: 6 | B13: =SUM('GENSET #1:GENSET #5'!D15) -> 26840 | C13: ='Diesel consumption'!D10 -> 7310 | D13: ='SOLAR METER READING'!D14 -> 2929 | E13: ='Gas-2'!G11 -> 270 | F13: =WATER!V11 -> 385 | G13: =WATER!W11 -> 31.1 | H13: ='SOLAR METER READING'!E14 -> 0 | I13: ='SOLAR METER READING'!F14 -> 0 | J13: =B13-B12 -> 694
A14: 7 | B14: =SUM('GENSET #1:GENSET #5'!D16) -> 26304 | C14: ='Diesel consumption'!D11 -> 7450 | D14: ='SOLAR METER READING'!D15 -> 3040 | E14: ='Gas-2'!G12 -> 270 | F14: =WATER!V12 -> 373 | G14: =WATER!W12 -> 29.1 | H14: ='SOLAR METER READING'!E15 -> 0 | I14: ='SOLAR METER READING'!F15 -> 0 | J14: =B14-B13 -> -536
A15: 8 | B15: =SUM('GENSET #1:GENSET #5'!D17) -> 26622 | C15: ='Diesel consumption'!D12 -> 7440 | D15: ='SOLAR METER READING'!D16 -> 2999 | E15: ='Gas-2'!G13 -> 270 | F15: =WATER!V13 -> 404 | G15: =WATER!W13 -> 34 | H15: ='SOLAR METER READING'!E16 -> 0 | I15: ='SOLAR METER READING'!F16 -> 0 | J15: =B15-B14 -> 318
A16: 9 | B16: =SUM('GENSET #1:GENSET #5'!D18) -> 26674 | C16: ='Diesel consumption'!D13 -> 7570 | D16: ='SOLAR METER READING'!D17 -> 2587 | E16: ='Gas-2'!G14 -> 270 | F16: =WATER!V14 -> 356 | G16: =WATER!W14 -> 29.1 | H16: ='SOLAR METER READING'!E17 -> 0 | I16: ='SOLAR METER READING'!F17 -> 0 | J16: =B16-B15 -> 52
A17: 10 | B17: =SUM('GENSET #1:GENSET #5'!D19) -> 26265 | C17: ='Diesel consumption'!D14 -> 7210 | D17: ='SOLAR METER READING'!D18 -> 2468 | E17: ='Gas-2'!G15 -> 90 | F17: =WATER!V15 -> 448 | G17: =WATER!W15 -> 27.2 | H17: ='SOLAR METER READING'!E18 -> 0 | I17: ='SOLAR METER READING'!F18 -> 0 | J17: =B17-B16 -> -409
A18: 11 | B18: =SUM('GENSET #1:GENSET #5'!D20) -> 26961 | C18: ='Diesel consumption'!D15 -> 7560 | D18: ='SOLAR METER READING'!D19 -> 2326 | E18: ='Gas-2'!G16 -> 90 | F18: =WATER!V16 -> 429 | G18: =WATER!W16 -> 30.1 | H18: ='SOLAR METER READING'!E19 -> 0 | I18: ='SOLAR METER READING'!F19 -> 0 | J18: =B18-B17 -> 696
A19: 12 | B19: =SUM('GENSET #1:GENSET #5'!D21) -> 26816 | C19: ='Diesel consumption'!D16 -> 7570 | D19: ='SOLAR METER READING'!D20 -> 2599 | E19: ='Gas-2'!G17 -> 450 | F19: =WATER!V17 -> 519 | G19: =WATER!W17 -> 36.9 | H19: ='SOLAR METER READING'!E20 -> 0 | I19: ='SOLAR METER READING'!F20 -> 0 | J19: =B19-B18 -> -145
A20: 13 | B20: =SUM('GENSET #1:GENSET #5'!D22) -> 26047 | C20: ='Diesel consumption'!D17 -> 7310 | D20: ='SOLAR METER READING'!D21 -> 2537 | E20: ='Gas-2'!G18 -> 135 | F20: =WATER!V18 -> 486 | G20: =WATER!W18 -> 39.8 | H20: ='SOLAR METER READING'!E21 -> 0 | I20: ='SOLAR METER READING'!F21 -> 0 | J20: =B20-B19 -> -769
... A36: 29 | B36: =SUM('GENSET #1:GENSET #5'!D38) -> 25763 | C36: ='Diesel consumption'!D33 -> 7150 | D36: ='SOLAR METER READING'!D37 -> 2693 | E36: ='Gas-2'!G34 -> 180 | F36: =WATER!V34 -> 340 | G36: =WATER!W34 -> 38.8 | H36: ='SOLAR METER READING'!E37 -> 0 | I36: ='SOLAR METER READING'!F37 -> 0 | J36: =B36-B35 -> 544
A37: 30 | B37: =SUM('GENSET #1:GENSET #5'!D39) -> 25963 | C37: ='Diesel consumption'!D34 -> 7330 | D37: ='SOLAR METER READING'!D38 -> 2950 | E37: ='Gas-2'!G35 -> 270 | F37: =WATER!V35 -> 353 | G37: 18 | H37: ='SOLAR METER READING'!E38 -> 0 | I37: ='SOLAR METER READING'!F38 -> 0 | J37: =B37-B36 -> 200
A38: 31 | B38: =SUM('GENSET #1:GENSET #5'!D40) -> 0 | C38: ='Diesel consumption'!D35 -> 0 | D38: ='SOLAR METER READING'!D39 -> 0 | E38: ='Gas-2'!#REF! -> #REF! | F38: =WATER!V36 -> 0 | G38: =WATER!W36 -> #REF! | H38: ='SOLAR METER READING'!E39 -> 0
A39: Total | B39: =SUM(B8:B38) -> 756539 | C39: =SUM(C8:C38) -> 212170 | D39: =SUM(D8:D38) -> 78310 | E39: =SUM(E8:E37) -> 6795 | F39: =SUM(F8:F38) -> 10663 | G39: =SUM(G8:G37)/30 -> 35.16 | H39: ='SOLAR METER READING'!E40 -> 0 | I39: ='SOLAR METER READING'!F40 -> 0
A40: Avg | B40: =B39/A41 -> 25217.967 | C40: =C39/A41 -> 7072.3333 | D40: =D39/A41 -> 2610.3333 | E40: =E39/A41 -> 226.5 | F40: =F39/A41 -> 355.43333
A41: 30

Sheet GENSET #1
C1: 1000 KVA
C3: NO#1
A6: 44867
B8: GENSET NO 1
A9: DAY | B9: YESTARDAY | C9: TODAY | D9: Final Electricity Consumption( KWh)
A10: 1 | B10: 20206709 | C10: 20208455 | D10: =MAX(0,C10-B10) -> 1746
A11: 2 | B11: =C10 -> 20208455 | C11: 20214286 | D11: =MAX(0,C11-B11) -> 5831
A12: 3 | B12: =C11 -> 20214286 | C12: 20221761 | D12: =MAX(0,C12-B12) -> 7475
A13: 4 | B13: =C12 -> 20221761 | C13: 20230861 | D13: =MAX(0,C13-B13) -> 9100
A14: 5 | B14: =C13 -> 20230861 | C14: 20240645 | D14: =MAX(0,C14-B14) -> 9784
A15: 6 | B15: =C14 -> 20240645 | C15: 20243814 | D15: =MAX(0,C15-B15) -> 3169
A16: 7 | B16: =C15 -> 20243814 | C16: 20251163 | D16: =MAX(0,C16-B16) -> 7349
A17: 8 | B17: =C16 -> 20251163 | C17: 20253550 | D17: =MAX(0,C17-B17) -> 2387
A18: 9 | B18: =C17 -> 20253550 | C18: 20260161 | D18: =MAX(0,C18-B18) -> 6611
A19: 10 | B19: =C18 -> 20260161 | C19: 20261354 | D19: =MAX(0,C19-B19) -> 1193
A20: 11 | B20: =C19 -> 20261354 | C20: 20268603 | D20: =MAX(0,C20-B20) -> 7249
A21: 12 | B21: =C20 -> 20268603 | C21: 20273156 | D21: =MAX(0,C21-B21) -> 4553
A22: 13 | B22: =C21 -> 20273156 | C22: 20283084 | D22: =MAX(0,C22-B22) -> 9928
... A38: 29 | B38: =C37 -> 20348872 | C38: 20351653 | D38: =MAX(0,C38-B38) -> 2781
