Workbook

Sheet TOTAL
A1: Site Name | B1: Day | C1: Month | D1: Year | E1: Total Electricity Kwh | F1: Electricity Tariff ($/Kwh) | G1: Natual Gas (m3) | H1: Natural Gas $/m3 | I1: Water Utility Supply (m3) m3 | J1: Water Utility Supply (m3) $/m3 | K1: Room Nights | L1: Total Guests
A2: Milan | B2: 1 | C2: 11 | D2: 2022 | E2: ='Hotel Data'!X5 -> 11450 | F2: 0.55 | G2: ='Hotel Data'!E5 -> 290 | H2: 2 | I2: ='Hotel Data'!K5 -> 137 | J2: 1
A3: Milan | B3: =B2+1 -> 2 | C3: 11 | D3: 2022 | E3: ='Hotel Data'!X6 -> 11241 | F3: 0.55 | G3: ='Hotel Data'!E6 -> 342 | H3: 2 | I3: ='Hotel Data'!K6 -> 124 | J3: 1
A4: Milan | B4: =B3+1 -> 3 | C4: 11 | D4: 2022 | E4: ='Hotel Data'!X7 -> 11394 | F4: 0.55 | G4: ='Hotel Data'!E7 -> 440 | H4: 2 | I4: ='Hotel Data'!K7 -> 192 | J4: 1
A5: Milan | B5: =B4+1 -> 4 | C5: 11 | D5: 2022 | E5: ='Hotel Data'!X8 -> 10967 | F5: 0.55 | G5: ='Hotel Data'!E8 -> 678 | H5: 2 | I5: ='Hotel Data'!K8 -> 168 | J5: 1
A6: Milan | B6: =B5+1 -> 5 | C6: 11 | D6: 2022 | E6: ='Hotel Data'!X9 -> 10939 | F6: 0.55 | G6: ='Hotel Data'!E9 -> 532 | H6: 2 | I6: ='Hotel Data'!K9 -> 150 | J6: 1
A7: Milan | B7: =B6+1 -> 6 | C7: 11 | D7: 2022 | E7: ='Hotel Data'!X10 -> 10672 | F7: 0.55 | G7: ='Hotel Data'!E10 -> 844 | H7: 2 | I7: ='Hotel Data'!K10 -> 162 | J7: 1
A8: Milan | B8: =B7+1 -> 7 | C8: 11 | D8: 2022 | E8: ='Hotel Data'!X11 -> 10495 | F8: 0.55 | G8: ='Hotel Data'!E11 -> 670 | H8: 2 | I8: ='Hotel Data'!K11 -> 165 | J8: 1
A9: Milan | B9: =B8+1 -> 8 | C9: 11 | D9: 2022 | E9: ='Hotel Data'!X12 -> 10643 | F9: 0.55 | G9: ='Hotel Data'!E12 -> 486 | H9: 2 | I9: ='Hotel Data'!K12 -> 239 | J9: 1
A10: Milan | B10: =B9+1 -> 9 | C10: 11 | D10: 2022 | E10: ='Hotel Data'!X13 -> 11120 | F10: 0.55 | G10: ='Hotel Data'!E13 -> 475 | H10: 2 | I10: ='Hotel Data'!K13 -> 271 | J10: 1
A11: Milan | B11: =B10+1 -> 10 | C11: 11 | D11: 2022 | E11: ='Hotel Data'!X14 -> 10837 | F11: 0.55 | G11: ='Hotel Data'!E14 -> 399 | H11: 2 | I11: ='Hotel Data'!K14 -> 258 | J11: 1
A12: Milan | B12: =B11+1 -> 11 | C12: 11 | D12: 2022 | E12: ='Hotel Data'!X15 -> 10578 | F12: 0.55 | G12: ='Hotel Data'!E15 -> 412 | H12: 2 | I12: ='Hotel Data'!K15 -> 261 | J12: 1
A13: Milan | B13: =B12+1 -> 12 | C13: 11 | D13: 2022 | E13: ='Hotel Data'!X16 -> 10527 | F13: 0.55 | G13: ='Hotel Data'!E16 -> 542 | H13: 2 | I13: ='Hotel Data'!K16 -> 250 | J13: 1
A14: Milan | B14: =B13+1 -> 13 | C14: 11 | D14: 2022 | E14: ='Hotel Data'!X17 -> 10458 | F14: 0.55 | G14: ='Hotel Data'!E17 -> 444 | H14: 2 | I14: ='Hotel Data'!K17 -> 231 | J14: 1
... A31: Milan | B31: =B30+1 -> 30 | C31: 11 | D31: 2022 | E31: ='Hotel Data'!X34 -> 12141 | F31: 0.55 | G31: ='Hotel Data'!E34 -> 684 | H31: 2 | I31: ='Hotel Data'!K34 -> 159 | J31: 1
A32: Milan | B32: =B31+1 -> 31 | F32: 0.55 | G32: ='Hotel Data'!E35 -> 0 | H32: 2 | I32: ='Hotel Data'!K35 -> 0 | J32: 1

Sheet Submetering 
A1: Site Name | B1: Day | C1: Month | D1: Year | E1: GAS RISCALD.(m3) | F1: GAS CUCINA (m3) | G1: H2O CONDIZION.ADD (m3) | H1: REINT. H2O ADD (m3) | I1: H2O ADD F CUC P (m3) | J1: H2O SANIT. CALDA (m3) | K1: ENEL CUC.PRINC. P (KWh) | L1: ENEL CUC.PRINC. N. (KWh) | M1: ENEL CUC.PREP. (KWh) | N1: ENEL CUC.VERANDA (KWh) | O1: ENEL LAVANDERIA (KWh) | P1: Room Nights | Q1: Total Guest
A3: Milan | B3: 1 | C3: 11 | D3: 2022 | E3: ='Hotel Data'!E5 -> 290 | F3: ='Hotel Data'!G5 -> 1 | G3: ='Hotel Data'!O5 -> 7 | H3: ='Hotel Data'!Q5 -> 0 | I3: ='Hotel Data'!S5 -> 0 | J3: ='Hotel Data'!U5 -> 21 | K3: ='Hotel Data'!AD5 -> 312 | L3: ='Hotel Data'!AG5 -> 1146 | M3: ='Hotel Data'!AJ5 -> 176 | N3: ='Hotel Data'!AN5 -> 505 | O3: ='Hotel Data'!AR5 -> 272 | P3: 75 | Q3: 133
A4: Milan | B4: =B3+1 -> 2 | C4: 11 | D4: 2022 | E4: ='Hotel Data'!E6 -> 342 | F4: ='Hotel Data'!G6 -> 0 | G4: ='Hotel Data'!O6 -> 5 | H4: ='Hotel Data'!Q6 -> 2 | I4: ='Hotel Data'!S6 -> 0 | J4: ='Hotel Data'!U6 -> 23 | K4: ='Hotel Data'!AD6 -> 263 | L4: ='Hotel Data'!AG6 -> 1208 | M4: ='Hotel Data'!AJ6 -> 152 | N4: ='Hotel Data'!AN6 -> 484 | O4: ='Hotel Data'!AR6 -> 256 | P4: 81 | Q4: 138
A5: Milan | B5: =B4+1 -> 3 | C5: 11 | D5: 2022 | E5: ='Hotel Data'!E7 -> 440 | F5: ='Hotel Data'!G7 -> 0 | G5: ='Hotel Data'!O7 -> 6 | H5: ='Hotel Data'!Q7 -> 26 | I5: ='Hotel Data'!S7 -> 0 | J5: ='Hotel Data'!U7 -> 51 | K5: ='Hotel Data'!AD7 -> 242 | L5: ='Hotel Data'!AG7 -> 1259 | M5: ='Hotel Data'!AJ7 -> 144 | N5: ='Hotel Data'!AN7 -> 519 | O5: ='Hotel Data'!AR7 -> 256 | P5: 68 | Q5: 122
A6: Milan | B6: =B5+1 -> 4 | C6: 11 | D6: 2022 | E6: ='Hotel Data'!E8 -> 678 | F6: ='Hotel Data'!G8 -> 0 | G6: ='Hotel Data'!O8 -> 8 | H6: ='Hotel Data'!Q8 -> 27 | I6: ='Hotel Data'!S8 -> 0 | J6: ='Hotel Data'!U8 -> 52 | K6: ='Hotel Data'!AD8 -> 221 | L6: ='Hotel Data'!AG8 -> 1227 | M6: ='Hotel Data'!AJ8 -> 176 | N6: ='Hotel Data'!AN8 -> 507 | O6: ='Hotel Data'!AR8 -> 256 | P6: 65 | Q6: 122
A7: Milan | B7: =B6+1 -> 5 | C7: 11 | D7: 2022 | E7: ='Hotel Data'!E9 -> 532 | F7: ='Hotel Data'!G9 -> 1 | G7: ='Hotel Data'!O9 -> 6 | H7: ='Hotel Data'!Q9 -> 24 | I7: ='Hotel Data'!S9 -> 0 | J7: ='Hotel Data'!U9 -> 48 | K7: ='Hotel Data'!AD9 -> 221 | L7: ='Hotel Data'!AG9 -> 1330 | M7: ='Hotel Data'!AJ9 -> 184 | N7: ='Hotel Data'!AN9 -> 551 | O7: ='Hotel Data'!AR9 -> 184 | P7: 83 | Q7: 159
A8: Milan | B8: =B7+1 -> 6 | C8: 11 | D8: 2022 | E8: ='Hotel Data'!E10 -> 844 | F8: ='Hotel Data'!G10 -> 1 | G8: ='Hotel Data'!O10 -> 7 | H8: ='Hotel Data'!Q10 -> 22 | I8: ='Hotel Data'!S10 -> 0 | J8: ='Hotel Data'!U10 -> 49 | K8: ='Hotel Data'!AD10 -> 214 | L8: ='Hotel Data'!AG10 -> 1295 | M8: ='Hotel Data'!AJ10 -> 232 | N8: ='Hotel Data'!AN10 -> 567 | O8: ='Hotel Data'!AR10 -> 264 | P8: 73 | Q8: 130
A9: Milan | B9: =B8+1 -> 7 | C9: 11 | D9: 2022 | E9: ='Hotel Data'!E11 -> 670 | F9: ='Hotel Data'!G11 -> 0 | G9: ='Hotel Data'!O11 -> 6 | H9: ='Hotel Data'!Q11 -> 22 | I9: ='Hotel Data'!S11 -> 0 | J9: ='Hotel Data'!U11 -> 47 | K9: ='Hotel Data'!AD11 -> 219 | L9: ='Hotel Data'!AG11 -> 1148 | M9: ='Hotel Data'!AJ11 -> 200 | N9: ='Hotel Data'!AN11 -> 531 | O9: ='Hotel Data'!AR11 -> 280 | P9: 98 | Q9: 161
A10: Milan | B10: =B9+1 -> 8 | C10: 11 | D10: 2022 | E10: ='Hotel Data'!E12 -> 486 | F10: ='Hotel Data'!G12 -> 1 | G10: ='Hotel Data'!O12 -> 5 | H10: ='Hotel Data'!Q12 -> 88 | I10: ='Hotel Data'!S12 -> 0 | J10: ='Hotel Data'!U12 -> 119 | K10: ='Hotel Data'!AD12 -> 217 | L10: ='Hotel Data'!AG12 -> 1179 | M10: ='Hotel Data'!AJ12 -> 216 | N10: ='Hotel Data'!AN12 -> 517 | O10: ='Hotel Data'!AR12 -> 256 | P10: 103 | Q10: 173
A11: Milan | B11: =B10+1 -> 9 | C11: 11 | D11: 2022 | E11: ='Hotel Data'!E13 -> 475 | F11: ='Hotel Data'!G13 -> 0 | G11: ='Hotel Data'!O13 -> 5 | H11: ='Hotel Data'!Q13 -> 106 | I11: ='Hotel Data'!S13 -> 0 | J11: ='Hotel Data'!U13 -> 139 | K11: ='Hotel Data'!AD13 -> 214 | L11: ='Hotel Data'!AG13 -> 1288 | M11: ='Hotel Data'!AJ13 -> 208 | N11: ='Hotel Data'!AN13 -> 496 | O11: ='Hotel Data'!AR13 -> 288 | P11: 103 | Q11: 173
A12: Milan | B12: =B11+1 -> 10 | C12: 11 | D12: 2022 | E12: ='Hotel Data'!E14 -> 399 | F12: ='Hotel Data'!G14 -> 0 | G12: ='Hotel Data'!O14 -> 5 | H12: ='Hotel Data'!Q14 -> 107 | I12: ='Hotel Data'!S14 -> 0 | J12: ='Hotel Data'!U14 -> 136 | K12: ='Hotel Data'!AD14 -> 217 | L12: ='Hotel Data'!AG14 -> 1294 | M12: ='Hotel Data'!AJ14 -> 336 | N12: ='Hotel Data'!AN14 -> 541 | O12: ='Hotel Data'!AR14 -> 304 | P12: 103 | Q12: 103
A13: Milan | B13: =B12+1 -> 11 | C13: 11 | D13: 2022 | E13: ='Hotel Data'!E15 -> 412 | F13: ='Hotel Data'!G15 -> 0 | G13: ='Hotel Data'!O15 -> 5 | H13: ='Hotel Data'!Q15 -> 107 | I13: ='Hotel Data'!S15 -> 0 | J13: ='Hotel Data'!U15 -> 138 | K13: ='Hotel Data'!AD15 -> 225 | L13: ='Hotel Data'!AG15 -> 1149 | M13: ='Hotel Data'!AJ15 -> 176 | N13: ='Hotel Data'!AN15 -> 544 | O13: ='Hotel Data'!AR15 -> 304 | P13: 99 | Q13: 172
A14: Milan | B14: =B13+1 -> 12 | C14: 11 | D14: 2022 | E14: ='Hotel Data'!E16 -> 542 | F14: ='Hotel Data'!G16 -> 0 | G14: ='Hotel Data'!O16 -> 4 | H14: ='Hotel Data'!Q16 -> 89 | I14: ='Hotel Data'!S16 -> 0 | J14: ='Hotel Data'!U16 -> 118 | K14: ='Hotel Data'!AD16 -> 231 | L14: ='Hotel Data'!AG16 -> 1384 | M14: ='Hotel Data'!AJ16 -> 216 | N14: ='Hotel Data'!AN16 -> 552 | O14: ='Hotel Data'!AR16 -> 320 | P14: 82 | Q14: 138
A15: Milan | B15: =B14+1 -> 13 | C15: 11 | D15: 2022 | E15: ='Hotel Data'!E17 -> 444 | F15: ='Hotel Data'!G17 -> 0 | G15: ='Hotel Data'!O17 -> 6 | H15: ='Hotel Data'!Q17 -> 120 | I15: ='Hotel Data'!S17 -> 0 | J15: ='Hotel Data'!U17 -> 154 | K15: ='Hotel Data'!AD17 -> 229 | L15: ='Hotel Data'!AG17 -> 1350 | M15: ='Hotel Data'!AJ17 -> 224 | N15: ='Hotel Data'!AN17 -> 566 | O15: ='Hotel Data'!AR17 -> 312 | P15: 79 | Q15: 146
... A32: Milan | B32: =B31+1 -> 30 | C32: 11 | D32: 2022 | E32: ='Hotel Data'!E34 -> 684 | F32: ='Hotel Data'!G34 -> 0 | G32: ='Hotel Data'!O34 -> 5 | H32: ='Hotel Data'!Q34 -> 16 | I32: ='Hotel Data'!S34 -> 0 | J32: ='Hotel Data'!U34 -> 40 | K32: ='Hotel Data'!AD34 -> 241 | L32: ='Hotel Data'!AG34 -> 1315 | M32: ='Hotel Data'!AJ34 -> 312 | N32: ='Hotel Data'!AN34 -> 521 | O32: ='Hotel Data'!AR34 -> 240 | P32: 61 | Q32: 117
A33: Milan | B33: =B32+1 -> 31 | E33: ='Hotel Data'!E35 -> 0 | F33: ='Hotel Data'!G35 -> 0 | G33: ='Hotel Data'!O35 -> 0 | H33: ='Hotel Data'!Q35 -> 0 | I33: ='Hotel Data'!S35 -> 0 | J33: ='Hotel Data'!U35 -> 0 | K33: ='Hotel Data'!AD35 -> 0 | L33: ='Hotel Data'!AG35 -> 0 | M33: ='Hotel Data'!AJ35 -> 0 | N33: ='Hotel Data'!AN35 -> 0 | O33: ='Hotel Data'!AR35 -> 0 | P33: =TOTAL!K32 -> 0 | Q33: =TOTAL!L32 -> 0

Sheet Hotel Data
D1: GAS RISCALD. | F1: GAS CUCINA | H1: H2O GENERALE | N1: H2O CONDIZION.ADD | P1: REINT. H2O ADD rfrig | R1: H2O ADD F CUC P | T1: H2O SANIT. CALDA | V1: ENEL ATTIVA | Y1: ENEL REATT. | AB1: ENEL CUC.PRINC. P | AE1: ENEL CUC.PRINC. N. | AH1: ENEL CUC.PREP. | AL1: ENEL CUC.VERANDA | AP1: ENEL LAVANDERIA | AS1: TEMPER.GG. | AU1: RICAVI | AV1: REFRIGERATA | AW1: lt/ G | AZ1: GAS RISCALDAM. | BA1: GAS CUCINA | BB1: ACQUA GENER. | BC1: ACQUA CONDIZ. | BD1: ENERGIA | BE1: Proiezione BA | BF1: ENEL CUC.PRINC | BG1: ENEL CUC.PREP. | BH1: ENEL CUC.VER. | BI1: ENEL LAVAND.
A3: GG | B3: ORA | C3: NOTE | D3: LETTURA MC | E3: DIFF. G | F3: LETTURA MC | G3: DIFF. G | H3: LETTURA MC | I3: DIFF. G | J3: lett. BA | K3: DIFF. G | L3: GUESTS | M3: mcxcl | N3: LETTURA MC | O3: DIFF. G | P3: LETTURA MC | Q3: DIFF. G | R3: LETTURA MC | S3: DIFF. G | T3: LETTURA MC | U3: DIFF. G | V3: LET. KWH*2200 | W3: DIFF. G | X3: Consumo BA | Y3: LET.KWT | Z3: DIFF. G | AB3: LET. KWH | AC3: DIFF. G | AD3: Consumo BA | AE3: LET. KWH | AF3: DIFF. G | AG3: Consumo BA | AH3: LET. KWH*80 | AI3: DIFF. G | AJ3: Consumo BA | AK3: COVERS | AL3: LET. KWH | AM3: DIFF. G | AN3: Consumo BA | AO3: COVERS | AP3: LET. KWH*80 | AQ3: DIFF. G | AR3: Consumo BA | AS3: MIN | AT3: MAX | AU3: LAVANDERIA
D4: 354523 | F4: 7087 | H4: 108241 | J4: 622402 | N4: 14926 | P4: =[1]October!P37 -> 98446 | R4: 42 | T4: 204357 | V4: 5641.45 | Y4: 1072.99 | AB4: 1776489 | AE4: 5261860 | AH4: 34257 | AL4: 246721 | AP4: 47018 | AV4: =[1]October!AV37 -> 0 | AX4: 563 | AZ4: =D40 -> 0 | BA4: =F40 -> 0 | BB4: =H40 -> 0 | BC4: =N40 -> 0 | BD4: 380000 | BE4: =BD4 -> 380000 | BF4: 42009 | BG4: 6152 | BH4: 19645 | BI4: 10384
A5: 1 | B5: 00:00 | D5: 354813 | E5: =IF(ISBLANK(D5),0,D5-D4) -> 290 | F5: 7088 | G5: =IF(ISBLANK(F5),0,F5-F4) -> 1 | H5: 108386 | I5: =IF(ISBLANK(H5),0,H5-H4) -> 145 | J5: 622539 | K5: =IF(ISBLANK(J5),0,J5-J4) -> 137 | M5: =I5/L5 -> #DIV/0! | N5: 14933 | O5: =IF(ISBLANK(N5),0,N5-N4) -> 7 | P5: 98446 | Q5: =IF(ISBLANK(P5),0,P5-P4) -> 0 | R5: 42 | S5: =IF(ISBLANK(R5),0,R5-R4) -> 0 | T5: 204378 | U5: =IF(ISBLANK(T5),0,T5-T4) -> 21 | W5: =IF(ISBLANK(V5),0,SUM(V5-V4)*2200) -> 0 | X5: 11450 | Z5: =IF(ISBLANK(Y5),0,Y5-Y4)*2200 -> 0 | AA5: 2100 | AC5: =IF(ISBLANK(AB5),0,SUM(AB5-AB4)) -> 0 | AD5: 312 | AF5: =IF(ISBLANK(AE5),0,SUM(AE5-AE4)) -> 0 | AG5: 1146 | AI5: =IF(ISBLANK(AH5),0,AH5-AH4)*80 -> 0 | AJ5: 176 | AM5: =IF(ISBLANK(AL5),0,AL5-AL4) -> 0 | AN5: 505 | AQ5: =IF(ISBLANK(AP5),0,AP5-AP4)*80 -> 0 | AR5: 272 | AS5: 10 | AT5: 18 | AW5: =IF(ISBLANK(AV5),0,AV5-AV4) -> 0 | AX5: 563 | AY5: =IF(ISBLANK(AX5),0,AX5-AX4) -> 0 | AZ5: =IF(D5<>0,(+D5-D$8)/A5*30,0) -> -43800 | BA5: =IF(F5<>0,(+F5-F$8)/$A5*30,0) -> 0 | BB5: =IF(H5<>0,(+H5-H$8)/$A5*30,0) -> -15270 | BC5: =IF(N5<>0,(+N5-N$8)/$A5*30,0) -> -570 | BD5: =IF(V5<>0,(+V5-V$8)*2200/$A5*30,0) -> 0 | BE5: =IF(X5<>0,AVERAGE(X5:X$11)*30,) -> 330677.14 | BF5: =IF(AD5+AG5<>0,AVERAGE(AD5:AD$11)*30+AVERAGE(AG5:AG$11)*30,) -> 44164.286 | BG5: =IF(AJ5<>0,AVERAGE(AJ5:AJ$11)*30,) -> 5417.1429 | BH5: =IF(AN5<>0,AVERAGE(AN5:AN$11)*30,) -> 15702.857 | BI5: =IF(AR5<>0,AVERAGE(AR5:AR$11)*30,) -> 7577.1429
A6: =1+A5 -> 2 | B6: 00:00 | D6: 355155 | E6: =IF(ISBLANK(D6),0,D6-D5) -> 342 | F6: 7088 | G6: =IF(ISBLANK(F6),0,F6-F5) -> 0 | H6: 108517 | I6: =IF(ISBLANK(H6),0,H6-H5) -> 131 | J6: 622663 | K6: =IF(ISBLANK(J6),0,J6-J5) -> 124 | M6: =I6/L6 -> #DIV/0! | N6: 14938 | O6: =IF(ISBLANK(N6),0,N6-N5) -> 5 | P6: 98448 | Q6: =IF(ISBLANK(P6),0,P6-P5) -> 2 | R6: 42 | S6: =IF(ISBLANK(R6),0,R6-R5) -> 0 | T6: 204401 | U6: =IF(ISBLANK(T6),0,T6-T5) -> 23 | W6: =IF(ISBLANK(V6),0,SUM(V6-V5)*2200) -> 0 | X6: 11241 | Z6: =IF(ISBLANK(Y6),0,Y6-Y5)*2200 -> 0 | AA6: 2122 | AC6: =IF(ISBLANK(AB6),0,SUM(AB6-AB5)) -> 0 | AD6: 263 | AF6: =IF(ISBLANK(AE6),0,SUM(AE6-AE5)) -> 0 | AG6: 1208 | AI6: =IF(ISBLANK(AH6),0,AH6-AH5)*80 -> 0 | AJ6: 152 | AM6: =IF(ISBLANK(AL6),0,AL6-AL5) -> 0 | AN6: 484 | AQ6: =IF(ISBLANK(AP6),0,AP6-AP5)*80 -> 0 | AR6: 256 | AS6: 13 | AT6: 19 | AW6: =IF(ISBLANK(AV6),0,AV6-AV5) -> 0 | AX6: 564 | AY6: =IF(ISBLANK(AX6),0,AX6-AX5) -> 1 | AZ6: =IF(D6<>0,(+D6-D$8)/A6*30,0) -> -16770 | BA6: =IF(F6<>0,(+F6-F$8)/$A6*30,0) -> 0 | BB6: =IF(H6<>0,(+H6-H$8)/$A6*30,0) -> -5670 | BC6: =IF(N6<>0,(+N6-N$8)/$A6*30,0) -> -210 | BD6: =IF(V6<>0,(+V6-V$8)*2200/$A6*30,0) -> 0 | BE6: =IF(X6<>0,AVERAGE(X6:X$11)*30,) -> 328540 | BF6: =IF(AD6+AG6<>0,AVERAGE(AD6:AD$11)*30+AVERAGE(AG6:AG$11)*30,) -> 44235 | BG6: =IF(AJ6<>0,AVERAGE(AJ6:AJ$11)*30,) -> 5440 | BH6: =IF(AN6<>0,AVERAGE(AN6:AN$11)*30,) -> 15795 | BI6: =IF(AR6<>0,AVERAGE(AR6:AR$11)*30,) -> 7480
A7: =1+A6 -> 3 | B7: 00:00 | D7: 355595 | E7: =IF(ISBLANK(D7),0,D7-D6) -> 440 | F7: 7088 | G7: =IF(ISBLANK(F7),0,F7-F6) -> 0 | H7: 108718 | I7: =IF(ISBLANK(H7),0,H7-H6) -> 201 | J7: 622855 | K7: =IF(ISBLANK(J7),0,J7-J6) -> 192 | M7: =I7/L7 -> #DIV/0! | N7: 14944 | O7: =IF(ISBLANK(N7),0,N7-N6) -> 6 | P7: 98474 | Q7: =IF(ISBLANK(P7),0,P7-P6) -> 26 | R7: 42 | S7: =IF(ISBLANK(R7),0,R7-R6) -> 0 | T7: 204452 | U7: =IF(ISBLANK(T7),0,T7-T6) -> 51 | W7: =IF(ISBLANK(V7),0,SUM(V7-V6)*2200) -> 0 | X7: 11394 | Z7: =IF(ISBLANK(Y7),0,Y7-Y6)*2200 -> 0 | AA7: 2227 | AC7: =IF(ISBLANK(AB7),0,SUM(AB7-AB6)) -> 0 | AD7: 242 | AF7: =IF(ISBLANK(AE7),0,SUM(AE7-AE6)) -> 0 | AG7: 1259 | AI7: =IF(ISBLANK(AH7),0,AH7-AH6)*80 -> 0 | AJ7: 144 | AM7: =IF(ISBLANK(AL7),0,AL7-AL6) -> 0 | AN7: 519 | AQ7: =IF(ISBLANK(AP7),0,AP7-AP6)*80 -> 0 | AR7: 256 | AS7: 10 | AT7: 16 | AW7: =IF(ISBLANK(AV7),0,AV7-AV6) -> 0 | AX7: 566 | AY7: =IF(ISBLANK(AX7),0,AX7-AX6) -> 2 | AZ7: =IF(D7<>0,(+D7-D$8)/A7*30,0) -> -6780 | BA7: =IF(F7<>0,(+F7-F$8)/$A7*30,0) -> 0 | BB7: =IF(H7<>0,(+H7-H$8)/$A7*30,0) -> -1770 | BC7: =IF(N7<>0,(+N7-N$8)/$A7*30,0) -> -80 | BD7: =IF(V7<>0,(+V7-V$8)*2200/$A7*30,0) -> 0 | BE7: =IF(X7<>0,AVERAGE(X7:X$11)*30,) -> 326802 | BF7: =IF(AD7+AG7<>0,AVERAGE(AD7:AD$11)*30+AVERAGE(AG7:AG$11)*30,) -> 44256 | BG7: =IF(AJ7<>0,AVERAGE(AJ7:AJ$11)*30,) -> 5616 | BH7: =IF(AN7<>0,AVERAGE(AN7:AN$11)*30,) -> 16050 | BI7: =IF(AR7<>0,AVERAGE(AR7:AR$11)*30,) -> 7440
A8: =1+A7 -> 4 | B8: 00:00 | D8: 356273 | E8: =IF(ISBLANK(D8),0,D8-D7) -> 678 | F8: 7088 | G8: =IF(ISBLANK(F8),0,F8-F7) -> 0 | H8: 108895 | I8: =IF(ISBLANK(H8),0,H8-H7) -> 177 | J8: 623023 | K8: =IF(ISBLANK(J8),0,J8-J7) -> 168 | M8: =I8/L8 -> #DIV/0! | N8: 14952 | O8: =IF(ISBLANK(N8),0,N8-N7) -> 8 | P8: 98501 | Q8: =IF(ISBLANK(P8),0,P8-P7) -> 27 | R8: 42 | S8: =IF(ISBLANK(R8),0,R8-R7) -> 0 | T8: 204504 | U8: =IF(ISBLANK(T8),0,T8-T7) -> 52 | W8: =IF(ISBLANK(V8),0,SUM(V8-V7)*2200) -> 0 | X8: 10967 | Z8: =IF(ISBLANK(Y8),0,Y8-Y7)*2200 -> 0 | AA8: 2159 | AC8: =IF(ISBLANK(AB8),0,SUM(AB8-AB7)) -> 0 | AD8: 221 | AF8: =IF(ISBLANK(AE8),0,SUM(AE8-AE7)) -> 0 | AG8: 1227 | AI8: =IF(ISBLANK(AH8),0,AH8-AH7)*80 -> 0 | AJ8: 176 | AM8: =IF(ISBLANK(AL8),0,AL8-AL7) -> 0 | AN8: 507 | AQ8: =IF(ISBLANK(AP8),0,AP8-AP7)*80 -> 0 | AR8: 256 | AS8: 8 | AT8: 17 | AW8: =IF(ISBLANK(AV8),0,AV8-AV7) -> 0 | AX8: 566 | AY8: =IF(ISBLANK(AX8),0,AX8-AX7) -> 0 | AZ8: =IF(D8<>0,(+D8-D$8)/A8*30,0) -> 0 | BA8: =IF(F8<>0,(+F8-F$8)/$A8*30,0) -> 0 | BB8: =IF(H8<>0,(+H8-H$8)/$A8*30,0) -> 0 | BC8: =IF(N8<>0,(+N8-N$8)/$A8*30,0) -> 0 | BD8: =IF(V8<>0,(+V8-V$8)*2200/$A8*30,0) -> 0 | BE8: =IF(X8<>0,AVERAGE(X8:X$11)*30,) -> 323047.5 | BF8: =IF(AD8+AG8<>0,AVERAGE(AD8:AD$11)*30+AVERAGE(AG8:AG$11)*30,) -> 44062.5 | BG8: =IF(AJ8<>0,AVERAGE(AJ8:AJ$11)*30,) -> 5940 | BH8: =IF(AN8<>0,AVERAGE(AN8:AN$11)*30,) -> 16170 | BI8: =IF(AR8<>0,AVERAGE(AR8:AR$11)*30,) -> 7380
A9: =1+A8 -> 5 | B9: 00:00 | D9: 356805 | E9: =IF(ISBLANK(D9),0,D9-D8) -> 532 | F9: 7089 | G9: =IF(ISBLANK(F9),0,F9-F8) -> 1 | H9: 109053 | I9: =IF(ISBLANK(H9),0,H9-H8) -> 158 | J9: 623173 | K9: =IF(ISBLANK(J9),0,J9-J8) -> 150 | M9: =I9/L9 -> #DIV/0! | N9: 14958 | O9: =IF(ISBLANK(N9),0,N9-N8) -> 6 | P9: 98525 | Q9: =IF(ISBLANK(P9),0,P9-P8) -> 24 | R9: 42 | S9: =IF(ISBLANK(R9),0,R9-R8) -> 0 | T9: 204552 | U9: =IF(ISBLANK(T9),0,T9-T8) -> 48 | W9: =IF(ISBLANK(V9),0,SUM(V9-V8)*2200) -> 0 | X9: 10939 | Z9: =IF(ISBLANK(Y9),0,Y9-Y8)*2200 -> 0 | AA9: 2128 | AC9: =IF(ISBLANK(AB9),0,SUM(AB9-AB8)) -> 0 | AD9: 221 | AF9: =IF(ISBLANK(AE9),0,SUM(AE9-AE8)) -> 0 | AG9: 1330 | AI9: =IF(ISBLANK(AH9),0,AH9-AH8)*80 -> 0 | AJ9: 184 | AM9: =IF(ISBLANK(AL9),0,AL9-AL8) -> 0 | AN9: 551 | AQ9: =IF(ISBLANK(AP9),0,AP9-AP8)*80 -> 0 | AR9: 184 | AS9: 4 | AT9: 15 | AW9: =IF(ISBLANK(AV9),0,AV9-AV8) -> 0 | AX9: 566 | AY9: =IF(ISBLANK(AX9),0,AX9-AX8) -> 0 | AZ9: =IF(D9<>0,(+D9-D$8)/A9*30,0) -> 3192 | BA9: =IF(F9<>0,(+F9-F$8)/$A9*30,0) -> 6 | BB9: =IF(H9<>0,(+H9-H$8)/$A9*30,0) -> 948 | BC9: =IF(N9<>0,(+N9-N$8)/$A9*30,0) -> 36 | BD9: =IF(V9<>0,(+V9-V$8)*2200/$A9*30,0) -> 0 | BE9: =IF(X9<>0,AVERAGE(X9:X$11)*30,) -> 321060 | BF9: =IF(AD9+AG9<>0,AVERAGE(AD9:AD$11)*30+AVERAGE(AG9:AG$11)*30,) -> 44270 | BG9: =IF(AJ9<>0,AVERAGE(AJ9:AJ$11)*30,) -> 6160 | BH9: =IF(AN9<>0,AVERAGE(AN9:AN$11)*30,) -> 16490 | BI9: =IF(AR9<>0,AVERAGE(AR9:AR$11)*30,) -> 7280
A10: =1+A9 -> 6 | B10: 00:00 | D10: 357649 | E10: =IF(ISBLANK(D10),0,D10-D9) -> 844 | F10: 7090 | G10: =IF(ISBLANK(F10),0,F10-F9) -> 1 | H10: 109223 | I10: =IF(ISBLANK(H10),0,H10-H9) -> 170 | J10: 623335 | K10: =IF(ISBLANK(J10),0,J10-J9) -> 162 | M10: =I10/L10 -> #DIV/0! | N10: 14965 | O10: =IF(ISBLANK(N10),0,N10-N9) -> 7 | P10: 98547 | Q10: =IF(ISBLANK(P10),0,P10-P9) -> 22 | R10: 42 | S10: =IF(ISBLANK(R10),0,R10-R9) -> 0 | T10: 204601 | U10: =IF(ISBLANK(T10),0,T10-T9) -> 49 | W10: =IF(ISBLANK(V10),0,SUM(V10-V9)*2200) -> 0 | X10: 10672 | Z10: =IF(ISBLANK(Y10),0,Y10-Y9)*2200 -> 0 | AA10: 2088 | AC10: =IF(ISBLANK(AB10),0,SUM(AB10-AB9)) -> 0 | AD10: 214 | AF10: =IF(ISBLANK(AE10),0,SUM(AE10-AE9)) -> 0 | AG10: 1295 | AI10: =IF(ISBLANK(AH10),0,AH10-AH9)*80 -> 0 | AJ10: 232 | AM10: =IF(ISBLANK(AL10),0,AL10-AL9) -> 0 | AN10: 567 | AQ10: =IF(ISBLANK(AP10),0,AP10-AP9)*80 -> 0 | AR10: 264 | AS10: 3 | AT10: 17 | AW10: =IF(ISBLANK(AV10),0,AV10-AV9) -> 0 | AX10: 567 | AY10: =IF(ISBLANK(AX10),0,AX10-AX9) -> 1 | AZ10: =IF(D10<>0,(+D10-D$8)/A10*30,0) -> 6880 | BA10: =IF(F10<>0,(+F10-F$8)/$A10*30,0) -> 10 | BB10: =IF(H10<>0,(+H10-H$8)/$A10*30,0) -> 1640 | BC10: =IF(N10<>0,(+N10-N$8)/$A10*30,0) -> 65 | BD10: =IF(V10<>0,(+V10-V$8)*2200/$A10*30,0) -> 0 | BE10: =IF(X10<>0,AVERAGE(X10:X$11)*30,) -> 317505 | BF10: =IF(AD10+AG10<>0,AVERAGE(AD10:AD$11)*30+AVERAGE(AG10:AG$11)*30,) -> 43140 | BG10: =IF(AJ10<>0,AVERAGE(AJ10:AJ$11)*30,) -> 6480 | BH10: =IF(AN10<>0,AVERAGE(AN10:AN$11)*30,) -> 16470 | BI10: =IF(AR10<>0,AVERAGE(AR10:AR$11)*30,) -> 8160
A11: =1+A10 -> 7 | B11: 00:00 | D11: 358319 | E11: =IF(ISBLANK(D11),0,D11-D10) -> 670 | F11: 7090 | G11: =IF(ISBLANK(F11),0,F11-F10) -> 0 | H11: 109397 | I11: =IF(ISBLANK(H11),0,H11-H10) -> 174 | J11: 623500 | K11: =IF(ISBLANK(J11),0,J11-J10) -> 165 | M11: =I11/L11 -> #DIV/0! | N11: 14971 | O11: =IF(ISBLANK(N11),0,N11-N10) -> 6 | P11: 98569 | Q11: =IF(ISBLANK(P11),0,P11-P10) -> 22 | R11: 42 | S11: =IF(ISBLANK(R11),0,R11-R10) -> 0 | T11: 204648 | U11: =IF(ISBLANK(T11),0,T11-T10) -> 47 | W11: =IF(ISBLANK(V11),0,SUM(V11-V10)*2200) -> 0 | X11: 10495 | Z11: =IF(ISBLANK(Y11),0,Y11-Y10)*2200 -> 0 | AA11: 1759 | AC11: =IF(ISBLANK(AB11),0,SUM(AB11-AB10)) -> 0 | AD11: 219 | AF11: =IF(ISBLANK(AE11),0,SUM(AE11-AE10)) -> 0 | AG11: 1148 | AI11: =IF(ISBLANK(AH11),0,AH11-AH10)*80 -> 0 | AJ11: 200 | AM11: =IF(ISBLANK(AL11),0,AL11-AL10) -> 0 | AN11: 531 | AQ11: =IF(ISBLANK(AP11),0,AP11-AP10)*80 -> 0 | AR11: 280 | AS11: 9 | AT11: 16 | AW11: =IF(ISBLANK(AV11),0,AV11-AV10) -> 0 | AX11: 567 | AY11: =IF(ISBLANK(AX11),0,AX11-AX10) -> 0 | AZ11: =IF(D11<>0,(+D11-D$8)/A11*30,0) -> 8768.5714 | BA11: =IF(F11<>0,(+F11-F$8)/$A11*30,0) -> 8.5714286 | BB11: =IF(H11<>0,(+H11-H$8)/$A11*30,0) -> 2151.4286 | BC11: =IF(N11<>0,(+N11-N$8)/$A11*30,0) -> 81.428571 | BD11: =IF(V11<>0,(+V11-V$8)*2200/$A11*30,0) -> 0 | BE11: =IF(X11<>0,AVERAGE(X$11:X11)*30,) -> 314850 | BF11: =IF(AD11+AG11<>0,AVERAGE(AD$11:AD11)*30+AVERAGE(AG$11:AG11)*30,) -> 41010 | BG11: =IF(AJ11<>0,AVERAGE(AJ$11:AJ11)*30,) -> 6000 | BH11: =IF(AN11<>0,AVERAGE(AN$11:AN11)*30,) -> 15930 | BI11: =IF(AR11<>0,AVERAGE(AR$11:AR11)*30,) -> 8400
A12: =1+A11 -> 8 | B12: 00:00 | D12: 358805 | E12: =IF(ISBLANK(D12),0,D12-D11) -> 486 | F12: 7091 | G12: =IF(ISBLANK(F12),0,F12-F11) -> 1 | H12: 109647 | I12: =IF(ISBLANK(H12),0,H12-H11) -> 250 | J12: 623739 | K12: =IF(ISBLANK(J12),0,J12-J11) -> 239 | M12: =I12/L12 -> #DIV/0! | N12: 14976 | O12: =IF(ISBLANK(N12),0,N12-N11) -> 5 | P12: 98657 | Q12: =IF(ISBLANK(P12),0,P12-P11) -> 88 | R12: 42 | S12: =IF(ISBLANK(R12),0,R12-R11) -> 0 | T12: 204767 | U12: =IF(ISBLANK(T12),0,T12-T11) -> 119 | W12: =IF(ISBLANK(V12),0,SUM(V12-V11)*2200) -> 0 | X12: 10643 | Z12: =IF(ISBLANK(Y12),0,Y12-Y11)*2200 -> 0 | AA12: 1718 | AC12: =IF(ISBLANK(AB12),0,SUM(AB12-AB11)) -> 0 | AD12: 217 | AF12: =IF(ISBLANK(AE12),0,SUM(AE12-AE11)) -> 0 | AG12: 1179 | AI12: =IF(ISBLANK(AH12),0,AH12-AH11)*80 -> 0 | AJ12: 216 | AM12: =IF(ISBLANK(AL12),0,AL12-AL11) -> 0 | AN12: 517 | AQ12: =IF(ISBLANK(AP12),0,AP12-AP11)*80 -> 0 | AR12: 256 | AS12: 8 | AT12: 17 | AW12: =IF(ISBLANK(AV12),0,AV12-AV11) -> 0 | AX12: 567 | AY12: =IF(ISBLANK(AX12),0,AX12-AX11) -> 0 | AZ12: =IF(D12<>0,(+D12-D$8)/A12*30,0) -> 9495 | BA12: =IF(F12<>0,(+F12-F$8)/$A12*30,0) -> 11.25 | BB12: =IF(H12<>0,(+H12-H$8)/$A12*30,0) -> 2820 | BC12: =IF(N12<>0,(+N12-N$8)/$A12*30,0) -> 90 | BD12: =IF(V12<>0,(+V12-V$8)*2200/$A12*30,0) -> 0 | BE12: =IF(X12<>0,AVERAGE(X$11:X12)*30,) -> 317070 | BF12: =IF(AD12+AG12<>0,AVERAGE(AD$11:AD12)*30+AVERAGE(AG$11:AG12)*30,) -> 41445 | BG12: =IF(AJ12<>0,AVERAGE(AJ$11:AJ12)*30,) -> 6240 | BH12: =IF(AN12<>0,AVERAGE(AN$11:AN12)*30,) -> 15720 | BI12: =IF(AR12<>0,AVERAGE(AR$11:AR12)*30,) -> 8040
A13: 9 | B13: 00:00 | C13: piscina in manutenzione | D13: 359280 | E13: =IF(ISBLANK(D13),0,D13-D12) -> 475 | F13: 7091 | G13: =IF(ISBLANK(F13),0,F13-F12) -> 0 | H13: 109929 | I13: =IF(ISBLANK(H13),0,H13-H12) -> 282 | J13: 624010 | K13: =IF(ISBLANK(J13),0,J13-J12) -> 271 | M13: =I13/L13 -> #DIV/0! | N13: 14981 | O13: =IF(ISBLANK(N13),0,N13-N12) -> 5 | P13: 98763 | Q13: =IF(ISBLANK(P13),0,P13-P12) -> 106 | R13: 42 | S13: =IF(ISBLANK(R13),0,R13-R12) -> 0 | T13: 204906 | U13: =IF(ISBLANK(T13),0,T13-T12) -> 139 | W13: =IF(ISBLANK(V13),0,SUM(V13-V12)*2200) -> 0 | X13: 11120 | Z13: =IF(ISBLANK(Y13),0,Y13-Y12)*2200 -> 0 | AA13: 1990 | AC13: =IF(ISBLANK(AB13),0,SUM(AB13-AB12)) -> 0 | AD13: 214 | AF13: =IF(ISBLANK(AE13),0,SUM(AE13-AE12)) -> 0 | AG13: 1288 | AI13: =IF(ISBLANK(AH13),0,AH13-AH12)*80 -> 0 | AJ13: 208 | AM13: =IF(ISBLANK(AL13),0,AL13-AL12) -> 0 | AN13: 496 | AQ13: =IF(ISBLANK(AP13),0,AP13-AP12)*80 -> 0 | AR13: 288 | AS13: 8 | AT13: 15 | AW13: =IF(ISBLANK(AV13),0,AV13-AV12) -> 0 | AX13: 577 | AY13: =IF(ISBLANK(AX13),0,AX13-AX12) -> 10 | AZ13: =IF(D13<>0,(+D13-D$8)/A13*30,0) -> 10023.333 | BA13: =IF(F13<>0,(+F13-F$8)/$A13*30,0) -> 10 | BB13: =IF(H13<>0,(+H13-H$8)/$A13*30,0) -> 3446.6667 | BC13: =IF(N13<>0,(+N13-N$8)/$A13*30,0) -> 96.666667 | BD13: =IF(V13<>0,(+V13-V$8)*2200/$A13*30,0) -> 0 | BE13: =IF(X13<>0,AVERAGE(X$11:X13)*30,) -> 322580 | BF13: =IF(AD13+AG13<>0,AVERAGE(AD$11:AD13)*30+AVERAGE(AG$11:AG13)*30,) -> 42650 | BG13: =IF(AJ13<>0,AVERAGE(AJ$11:AJ13)*30,) -> 6240 | BH13: =IF(AN13<>0,AVERAGE(AN$11:AN13)*30,) -> 15440 | BI13: =IF(AR13<>0,AVERAGE(AR$11:AR13)*30,) -> 8240
A14: =1+A13 -> 10 | B14: 00:00 | D14: 359679 | E14: =IF(ISBLANK(D14),0,D14-D13) -> 399 | F14: 7091 | G14: =IF(ISBLANK(F14),0,F14-F13) -> 0 | H14: 110199 | I14: =IF(ISBLANK(H14),0,H14-H13) -> 270 | J14: 624268 | K14: =IF(ISBLANK(J14),0,J14-J13) -> 258 | M14: =I14/L14 -> #DIV/0! | N14: 14986 | O14: =IF(ISBLANK(N14),0,N14-N13) -> 5 | P14: 98870 | Q14: =IF(ISBLANK(P14),0,P14-P13) -> 107 | R14: 42 | S14: =IF(ISBLANK(R14),0,R14-R13) -> 0 | T14: 205042 | U14: =IF(ISBLANK(T14),0,T14-T13) -> 136 | V14: 5696.3 | W14: =IF(ISBLANK(V14),0,SUM(V14-V13)*2200) -> 12531860 | X14: 10837 | Y14: 1082.91 | Z14: =IF(ISBLANK(Y14),0,Y14-Y13)*2200 -> 2382402 | AA14: 1552 | AB14: 1778826 | AC14: =IF(ISBLANK(AB14),0,SUM(AB14-AB13)) -> 1778826 | AD14: 217 | AE14: 5274230 | AF14: =IF(ISBLANK(AE14),0,SUM(AE14-AE13)) -> 5274230 | AG14: 1294 | AH14: 34282.3 | AI14: =IF(ISBLANK(AH14),0,AH14-AH13)*80 -> 2742584 | AJ14: 336 | AL14: 251940 | AM14: =IF(ISBLANK(AL14),0,AL14-AL13) -> 251940 | AN14: 541 | AP14: 47051.3 | AQ14: =IF(ISBLANK(AP14),0,AP14-AP13)*80 -> 3764104 | AR14: 304 | AS14: 9 | AT14: 15 | AW14: =IF(ISBLANK(AV14),0,AV14-AV13) -> 0 | AX14: 577 | AY14: =IF(ISBLANK(AX14),0,AX14-AX13) -> 0 | AZ14: =IF(D14<>0,(+D14-D$8)/A14*30,0) -> 10218 | BA14: =IF(F14<>0,(+F14-F$8)/$A14*30,0) -> 9 | BB14: =IF(H14<>0,(+H14-H$8)/$A14*30,0) -> 3912 | BC14: =IF(N14<>0,(+N14-N$8)/$A14*30,0) -> 102 | BD14: =IF(V14<>0,(+V14-V$8)*2200/$A14*30,0) -> 37595580 | BE14: =IF(X14<>0,AVERAGE(X$11:X14)*30,) -> 323212.5 | BF14: =IF(AD14+AG14<>0,AVERAGE(AD$11:AD14)*30+AVERAGE(AG$11:AG14)*30,) -> 43320 | BG14: =IF(AJ14<>0,AVERAGE(AJ$11:AJ14)*30,) -> 7200 | BH14: =IF(AN14<>0,AVERAGE(AN$11:AN14)*30,) -> 15637.5 | BI14: =IF(AR14<>0,AVERAGE(AR$11:AR14)*30,) -> 8460
A15: =1+A14 -> 11 | B15: 00:00 | D15: 360091 | E15: =IF(ISBLANK(D15),0,D15-D14) -> 412 | F15: 7091 | G15: =IF(ISBLANK(F15),0,F15-F14) -> 0 | H15: 110471 | I15: =IF(ISBLANK(H15),0,H15-H14) -> 272 | J15: 624529 | K15: =IF(ISBLANK(J15),0,J15-J14) -> 261 | M15: =I15/L15 -> #DIV/0! | N15: 14991 | O15: =IF(ISBLANK(N15),0,N15-N14) -> 5 | P15: 98977 | Q15: =IF(ISBLANK(P15),0,P15-P14) -> 107 | R15: 42 | S15: =IF(ISBLANK(R15),0,R15-R14) -> 0 | T15: 205180 | U15: =IF(ISBLANK(T15),0,T15-T14) -> 138 | W15: =IF(ISBLANK(V15),0,SUM(V15-V14)*2200) -> 0 | X15: 10578 | Z15: =IF(ISBLANK(Y15),0,Y15-Y14)*2200 -> 0 | AA15: 1681 | AC15: =IF(ISBLANK(AB15),0,SUM(AB15-AB14)) -> 0 | AD15: 225 | AF15: =IF(ISBLANK(AE15),0,SUM(AE15-AE14)) -> 0 | AG15: 1149 | AI15: =IF(ISBLANK(AH15),0,AH15-AH14)*80 -> 0 | AJ15: 176 | AM15: =IF(ISBLANK(AL15),0,AL15-AL14) -> 0 | AN15: 544 | AQ15: =IF(ISBLANK(AP15),0,AP15-AP14)*80 -> 0 | AR15: 304 | AS15: 10 | AT15: 18 | AW15: =IF(ISBLANK(AV15),0,AV15-AV14) -> 0 | AX15: 577 | AY15: =IF(ISBLANK(AX15),0,AX15-AX14) -> 0 | AZ15: =IF(D15<>0,(+D15-D$8)/A15*30,0) -> 10412.727 | BA15: =IF(F15<>0,(+F15-F$8)/$A15*30,0) -> 8.1818182 | BB15: =IF(H15<>0,(+H15-H$8)/$A15*30,0) -> 4298.1818 | BC15: =IF(N15<>0,(+N15-N$8)/$A15*30,0) -> 106.36364 | BD15: =IF(V15<>0,(+V15-V$8)*2200/$A15*30,0) -> 0 | BE15: =IF(X15<>0,AVERAGE(X$11:X15)*30,) -> 322038 | BF15: =IF(AD15+AG15<>0,AVERAGE(AD$11:AD15)*30+AVERAGE(AG$11:AG15)*30,) -> 42900 | BG15: =IF(AJ15<>0,AVERAGE(AJ$11:AJ15)*30,) -> 6816 | BH15: =IF(AN15<>0,AVERAGE(AN$11:AN15)*30,) -> 15774 | BI15: =IF(AR15<>0,AVERAGE(AR$11:AR15)*30,) -> 8592
A16: =1+A15 -> 12 | B16: 00:00 | D16: 360633 | E16: =IF(ISBLANK(D16),0,D16-D15) -> 542 | F16: 7091 | G16: =IF(ISBLANK(F16),0,F16-F15) -> 0 | H16: 110732 | I16: =IF(ISBLANK(H16),0,H16-H15) -> 261 | J16: 624779 | K16: =IF(ISBLANK(J16),0,J16-J15) -> 250 | M16: =I16/L16 -> #DIV/0! | N16: 14995 | O16: =IF(ISBLANK(N16),0,N16-N15) -> 4 | P16: 99066 | Q16: =IF(ISBLANK(P16),0,P16-P15) -> 89 | R16: 42 | S16: =IF(ISBLANK(R16),0,R16-R15) -> 0 | T16: 205298 | U16: =IF(ISBLANK(T16),0,T16-T15) -> 118 | W16: =IF(ISBLANK(V16),0,SUM(V16-V15)*2200) -> 0 | X16: 10527 | Z16: =IF(ISBLANK(Y16),0,Y16-Y15)*2200 -> 0 | AA16: 1583 | AC16: =IF(ISBLANK(AB16),0,SUM(AB16-AB15)) -> 0 | AD16: 231 | AF16: =IF(ISBLANK(AE16),0,SUM(AE16-AE15)) -> 0 | AG16: 1384 | AI16: =IF(ISBLANK(AH16),0,AH16-AH15)*80 -> 0 | AJ16: 216 | AM16: =IF(ISBLANK(AL16),0,AL16-AL15) -> 0 | AN16: 552 | AQ16: =IF(ISBLANK(AP16),0,AP16-AP15)*80 -> 0 | AR16: 320 | AS16: 12 | AT16: 18 | AW16: =IF(ISBLANK(AV16),0,AV16-AV15) -> 0 | AX16: 585 | AY16: =IF(ISBLANK(AX16),0,AX16-AX15) -> 8 | AZ16: =IF(D16<>0,(+D16-D$8)/A16*30,0) -> 10900 | BA16: =IF(F16<>0,(+F16-F$8)/$A16*30,0) -> 7.5 | BB16: =IF(H16<>0,(+H16-H$8)/$A16*30,0) -> 4592.5 | BC16: =IF(N16<>0,(+N16-N$8)/$A16*30,0) -> 107.5 | BD16: =IF(V16<>0,(+V16-V$8)*2200/$A16*30,0) -> 0 | BE16: =IF(X16<>0,AVERAGE(X$11:X16)*30,) -> 321000 | BF16: =IF(AD16+AG16<>0,AVERAGE(AD$11:AD16)*30+AVERAGE(AG$11:AG16)*30,) -> 43825 | BG16: =IF(AJ16<>0,AVERAGE(AJ$11:AJ16)*30,) -> 6760 | BH16: =IF(AN16<>0,AVERAGE(AN$11:AN16)*30,) -> 15905 | BI16: =IF(AR16<>0,AVERAGE(AR$11:AR16)*30,) -> 8760
A17: 13 | B17: 00:00 | D17: 361077 | E17: =IF(ISBLANK(D17),0,D17-D16) -> 444 | F17: 7091 | G17: =IF(ISBLANK(F17),0,F17-F16) -> 0 | H17: 110973 | I17: =IF(ISBLANK(H17),0,H17-H16) -> 241 | J17: 625010 | K17: =IF(ISBLANK(J17),0,J17-J16) -> 231 | M17: =I17/L17 -> #DIV/0! | N17: 15001 | O17: =IF(ISBLANK(N17),0,N17-N16) -> 6 | P17: 99186 | Q17: =IF(ISBLANK(P17),0,P17-P16) -> 120 | R17: 42 | S17: =IF(ISBLANK(R17),0,R17-R16) -> 0 | T17: 205452 | U17: =IF(ISBLANK(T17),0,T17-T16) -> 154 | W17: =IF(ISBLANK(V17),0,SUM(V17-V16)*2200) -> 0 | X17: 10458 | Z17: =IF(ISBLANK(Y17),0,Y17-Y16)*2200 -> 0 | AA17: 1540 | AC17: =IF(ISBLANK(AB17),0,SUM(AB17-AB16)) -> 0 | AD17: 229 | AF17: =IF(ISBLANK(AE17),0,SUM(AE17-AE16)) -> 0 | AG17: 1350 | AI17: =IF(ISBLANK(AH17),0,AH17-AH16)*80 -> 0 | AJ17: 224 | AM17: =IF(ISBLANK(AL17),0,AL17-AL16) -> 0 | AN17: 566 | AQ17: =IF(ISBLANK(AP17),0,AP17-AP16)*80 -> 0 | AR17: 312 | AS17: 8 | AT17: 17 | AW17: =IF(ISBLANK(AV17),0,AV17-AV16) -> 0 | AX17: 586 | AY17: =IF(ISBLANK(AX17),0,AX17-AX16) -> 1 | AZ17: =IF(D17<>0,(+D17-D$8)/A17*30,0) -> 11086.154 | BA17: =IF(F17<>0,(+F17-F$8)/$A17*30,0) -> 6.9230769 | BB17: =IF(H17<>0,(+H17-H$8)/$A17*30,0) -> 4795.3846 | BC17: =IF(N17<>0,(+N17-N$8)/$A17*30,0) -> 113.07692 | BD17: =IF(V17<>0,(+V17-V$8)*2200/$A17*30,0) -> 0 | BE17: =IF(X17<>0,AVERAGE(X$11:X17)*30,) -> 319962.86 | BF17: =IF(AD17+AG17<>0,AVERAGE(AD$11:AD17)*30+AVERAGE(AG$11:AG17)*30,) -> 44331.429 | BG17: =IF(AJ17<>0,AVERAGE(AJ$11:AJ17)*30,) -> 6754.2857 | BH17: =IF(AN17<>0,AVERAGE(AN$11:AN17)*30,) -> 16058.571 | BI17: =IF(AR17<>0,AVERAGE(AR$11:AR17)*30,) -> 8845.7143
A18: =1+A17 -> 14 | B18: 00:00 | D18: 361637 | E18: =IF(ISBLANK(D18),0,D18-D17) -> 560 | F18: 7091 | G18: =IF(ISBLANK(F18),0,F18-F17) -> 0 | H18: 111248 | I18: =IF(ISBLANK(H18),0,H18-H17) -> 275 | J18: 625274 | K18: =IF(ISBLANK(J18),0,J18-J17) -> 264 | M18: =I18/L18 -> #DIV/0! | N18: 15006 | O18: =IF(ISBLANK(N18),0,N18-N17) -> 5 | P18: 99295 | Q18: =IF(ISBLANK(P18),0,P18-P17) -> 109 | R18: 43 | S18: =IF(ISBLANK(R18),0,R18-R17) -> 1 | T18: 205591 | U18: =IF(ISBLANK(T18),0,T18-T17) -> 139 | W18: =IF(ISBLANK(V18),0,SUM(V18-V17)*2200) -> 0 | X18: 10581 | Z18: =IF(ISBLANK(Y18),0,Y18-Y17)*2200 -> 0 | AA18: 1502 | AC18: =IF(ISBLANK(AB18),0,SUM(AB18-AB17)) -> 0 | AD18: 223 | AF18: =IF(ISBLANK(AE18),0,SUM(AE18-AE17)) -> 0 | AG18: 1230 | AI18: =IF(ISBLANK(AH18),0,AH18-AH17)*80 -> 0 | AJ18: 288 | AM18: =IF(ISBLANK(AL18),0,AL18-AL17) -> 0 | AN18: 537 | AQ18: =IF(ISBLANK(AP18),0,AP18-AP17)*80 -> 0 | AR18: 256 | AS18: 7 | AT18: 10 | AW18: =IF(ISBLANK(AV18),0,AV18-AV17) -> 0 | AX18: 588 | AY18: =IF(ISBLANK(AX18),0,AX18-AX17) -> 2 | AZ18: =IF(D18<>0,(+D18-D$8)/A18*30,0) -> 11494.286 | BA18: =IF(F18<>0,(+F18-F$8)/$A18*30,0) -> 6.4285714 | BB18: =IF(H18<>0,(+H18-H$8)/$A18*30,0) -> 5042.1429 | BC18: =IF(N18<>0,(+N18-N$8)/$A18*30,0) -> 115.71429 | BD18: =IF(V18<>0,(+V18-V$8)*2200/$A18*30,0) -> 0 | BE18: =IF(X18<>0,AVERAGE(X$11:X18)*30,) -> 319646.25 | BF18: =IF(AD18+AG18<>0,AVERAGE(AD$11:AD18)*30+AVERAGE(AG$11:AG18)*30,) -> 44238.75 | BG18: =IF(AJ18<>0,AVERAGE(AJ$11:AJ18)*30,) -> 6990 | BH18: =IF(AN18<>0,AVERAGE(AN$11:AN18)*30,) -> 16065 | BI18: =IF(AR18<>0,AVERAGE(AR$11:AR18)*30,) -> 8700
A19: =1+A18 -> 15 | B19: 00:00 | D19: 362213 | E19: =IF(ISBLANK(D19),0,D19-D18) -> 576 | F19: 7091 | G19: =IF(ISBLANK(F19),0,F19-F18) -> 0 | H19: 111499 | I19: =IF(ISBLANK(H19),0,H19-H18) -> 251 | J19: 625514 | K19: =IF(ISBLANK(J19),0,J19-J18) -> 240 | M19: =I19/L19 -> #DIV/0! | N19: 15011 | O19: =IF(ISBLANK(N19),0,N19-N18) -> 5 | P19: 99400 | Q19: =IF(ISBLANK(P19),0,P19-P18) -> 105 | R19: 43 | S19: =IF(ISBLANK(R19),0,R19-R18) -> 0 | T19: 205725 | U19: =IF(ISBLANK(T19),0,T19-T18) -> 134 | W19: =IF(ISBLANK(V19),0,SUM(V19-V18)*2200) -> 0 | X19: 10642 | Z19: =IF(ISBLANK(Y19),0,Y19-Y18)*2200 -> 0 | AA19: 1527 | AC19: =IF(ISBLANK(AB19),0,SUM(AB19-AB18)) -> 0 | AD19: 212 | AF19: =IF(ISBLANK(AE19),0,SUM(AE19-AE18)) -> 0 | AG19: 2524 | AI19: =IF(ISBLANK(AH19),0,AH19-AH18)*80 -> 0 | AJ19: 240 | AM19: =IF(ISBLANK(AL19),0,AL19-AL18) -> 0 | AN19: 543 | AQ19: =IF(ISBLANK(AP19),0,AP19-AP18)*80 -> 0 | AR19: 240 | AS19: 5 | AT19: 9 | AW19: =IF(ISBLANK(AV19),0,AV19-AV18) -> 0 | AX19: 591 | AY19: =IF(ISBLANK(AX19),0,AX19-AX18) -> 3 | AZ19: =IF(D19<>0,(+D19-D$8)/A19*30,0) -> 11880 | BA19: =IF(F19<>0,(+F19-F$8)/$A19*30,0) -> 6 | BB19: =IF(H19<>0,(+H19-H$8)/$A19*30,0) -> 5208 | BC19: =IF(N19<>0,(+N19-N$8)/$A19*30,0) -> 118 | BD19: =IF(V19<>0,(+V19-V$8)*2200/$A19*30,0) -> 0 | BE19: =IF(X19<>0,AVERAGE(X$11:X19)*30,) -> 319603.33 | BF19: =IF(AD19+AG19<>0,AVERAGE(AD$11:AD19)*30+AVERAGE(AG$11:AG19)*30,) -> 48443.333 | BG19: =IF(AJ19<>0,AVERAGE(AJ$11:AJ19)*30,) -> 7013.3333 | BH19: =IF(AN19<>0,AVERAGE(AN$11:AN19)*30,) -> 16090 | BI19: =IF(AR19<>0,AVERAGE(AR$11:AR19)*30,) -> 8533.3333
A20: =1+A19 -> 16 | B20: 00:00 | D20: 362623 | E20: =IF(ISBLANK(D20),0,D20-D19) -> 410 | F20: 7093 | G20: =IF(ISBLANK(F20),0,F20-F19) -> 2 | H20: 111772 | I20: =IF(ISBLANK(H20),0,H20-H19) -> 273 | J20: 625776 | K20: =IF(ISBLANK(J20),0,J20-J19) -> 262 | M20: =I20/L20 -> #DIV/0! | N20: 15015 | O20: =IF(ISBLANK(N20),0,N20-N19) -> 4 | P20: 99502 | Q20: =IF(ISBLANK(P20),0,P20-P19) -> 102 | R20: 43 | S20: =IF(ISBLANK(R20),0,R20-R19) -> 0 | T20: 205852 | U20: =IF(ISBLANK(T20),0,T20-T19) -> 127 | W20: =IF(ISBLANK(V20),0,SUM(V20-V19)*2200) -> 0 | X20: 11003 | Z20: =IF(ISBLANK(Y20),0,Y20-Y19)*2200 -> 0 | AA20: 1793 | AC20: =IF(ISBLANK(AB20),0,SUM(AB20-AB19)) -> 0 | AD20: 220 | AF20: =IF(ISBLANK(AE20),0,SUM(AE20-AE19)) -> 0 | AG20: 1265 | AI20: =IF(ISBLANK(AH20),0,AH20-AH19)*80 -> 0 | AJ20: 240 | AM20: =IF(ISBLANK(AL20),0,AL20-AL19) -> 0 | AN20: 517 | AQ20: =IF(ISBLANK(AP20),0,AP20-AP19)*80 -> 0 | AR20: 280 | AS20: 9 | AT20: 12 | AW20: =IF(ISBLANK(AV20),0,AV20-AV19) -> 0 | AX20: 593 | AY20: =IF(ISBLANK(AX20),0,AX20-AX19) -> 2 | AZ20: =IF(D20<>0,(+D20-D$8)/A20*30,0) -> 11906.25 | BA20: =IF(F20<>0,(+F20-F$8)/$A20*30,0) -> 9.375 | BB20: =IF(H20<>0,(+H20-H$8)/$A20*30,0) -> 5394.375 | BC20: =IF(N20<>0,(+N20-N$8)/$A20*30,0) -> 118.125 | BD20: =IF(V20<>0,(+V20-V$8)*2200/$A20*30,0) -> 0 | BE20: =IF(X20<>0,AVERAGE(X$11:X20)*30,) -> 320652 | BF20: =IF(AD20+AG20<>0,AVERAGE(AD$11:AD20)*30+AVERAGE(AG$11:AG20)*30,) -> 48054 | BG20: =IF(AJ20<>0,AVERAGE(AJ$11:AJ20)*30,) -> 7032 | BH20: =IF(AN20<>0,AVERAGE(AN$11:AN20)*30,) -> 16032 | BI20: =IF(AR20<>0,AVERAGE(AR$11:AR20)*30,) -> 8520
A21: =1+A20 -> 17 | B21: 00:00 | D21: 363034 | E21: =IF(ISBLANK(D21),0,D21-D20) -> 411 | F21: 7094 | G21: =IF(ISBLANK(F21),0,F21-F20) -> 1 | H21: 112025 | I21: =IF(ISBLANK(H21),0,H21-H20) -> 253 | J21: 626018 | K21: =IF(ISBLANK(J21),0,J21-J20) -> 242 | M21: =I21/L21 -> #DIV/0! | N21: 15021 | O21: =IF(ISBLANK(N21),0,N21-N20) -> 6 | P21: 99607 | Q21: =IF(ISBLANK(P21),0,P21-P20) -> 105 | R21: 43 | S21: =IF(ISBLANK(R21),0,R21-R20) -> 0 | T21: 205986 | U21: =IF(ISBLANK(T21),0,T21-T20) -> 134 | W21: =IF(ISBLANK(V21),0,SUM(V21-V20)*2200) -> 0 | X21: 11041 | Z21: =IF(ISBLANK(Y21),0,Y21-Y20)*2200 -> 0 | AA21: 1780 | AC21: =IF(ISBLANK(AB21),0,SUM(AB21-AB20)) -> 0 | AD21: 223 | AF21: =IF(ISBLANK(AE21),0,SUM(AE21-AE20)) -> 0 | AG21: 1249 | AI21: =IF(ISBLANK(AH21),0,AH21-AH20)*80 -> 0 | AJ21: 264 | AM21: =IF(ISBLANK(AL21),0,AL21-AL20) -> 0 | AN21: 490 | AQ21: =IF(ISBLANK(AP21),0,AP21-AP20)*80 -> 0 | AR21: 288 | AS21: 6 | AT21: 12 | AW21: =IF(ISBLANK(AV21),0,AV21-AV20) -> 0 | AX21: 595 | AY21: =IF(ISBLANK(AX21),0,AX21-AX20) -> 2 | AZ21: =IF(D21<>0,(+D21-D$8)/A21*30,0) -> 11931.176 | BA21: =IF(F21<>0,(+F21-F$8)/$A21*30,0) -> 10.588235 | BB21: =IF(H21<>0,(+H21-H$8)/$A21*30,0) -> 5523.5294 | BC21: =IF(N21<>0,(+N21-N$8)/$A21*30,0) -> 121.76471 | BD21: =IF(V21<>0,(+V21-V$8)*2200/$A21*30,0) -> 0 | BE21: =IF(X21<>0,AVERAGE(X$11:X21)*30,) -> 321613.64 | BF21: =IF(AD21+AG21<>0,AVERAGE(AD$11:AD21)*30+AVERAGE(AG$11:AG21)*30,) -> 47700 | BG21: =IF(AJ21<>0,AVERAGE(AJ$11:AJ21)*30,) -> 7112.7273 | BH21: =IF(AN21<>0,AVERAGE(AN$11:AN21)*30,) -> 15910.909 | BI21: =IF(AR21<>0,AVERAGE(AR$11:AR21)*30,) -> 8530.9091
A22: =1+A21 -> 18 | B22: 00:00 | D22: 363294 | E22: =IF(ISBLANK(D22),0,D22-D21) -> 260 | F22: 7095 | G22: =IF(ISBLANK(F22),0,F22-F21) -> 1 | H22: 112267 | I22: =IF(ISBLANK(H22),0,H22-H21) -> 242 | J22: 626251 | K22: =IF(ISBLANK(J22),0,J22-J21) -> 233 | M22: =I22/L22 -> #DIV/0! | N22: 15025 | O22: =IF(ISBLANK(N22),0,N22-N21) -> 4 | P22: 99712 | Q22: =IF(ISBLANK(P22),0,P22-P21) -> 105 | R22: 43 | S22: =IF(ISBLANK(R22),0,R22-R21) -> 0 | T22: 206120 | U22: =IF(ISBLANK(T22),0,T22-T21) -> 134 | W22: =IF(ISBLANK(V22),0,SUM(V22-V21)*2200) -> 0 | X22: 11248 | Z22: =IF(ISBLANK(Y22),0,Y22-Y21)*2200 -> 0 | AA22: 1831 | AC22: =IF(ISBLANK(AB22),0,SUM(AB22-AB21)) -> 0 | AD22: 237 | AF22: =IF(ISBLANK(AE22),0,SUM(AE22-AE21)) -> 0 | AG22: 1315 | AI22: =IF(ISBLANK(AH22),0,AH22-AH21)*80 -> 0 | AJ22: 152 | AM22: =IF(ISBLANK(AL22),0,AL22-AL21) -> 0 | AN22: 536 | AQ22: =IF(ISBLANK(AP22),0,AP22-AP21)*80 -> 0 | AR22: 264 | AS22: 4 | AT22: 12 | AW22: =IF(ISBLANK(AV22),0,AV22-AV21) -> 0 | AX22: 599 | AY22: =IF(ISBLANK(AX22),0,AX22-AX21) -> 4 | AZ22: =IF(D22<>0,(+D22-D$8)/A22*30,0) -> 11701.667 | BA22: =IF(F22<>0,(+F22-F$8)/$A22*30,0) -> 11.666667 | BB22: =IF(H22<>0,(+H22-H$8)/$A22*30,0) -> 5620 | BC22: =IF(N22<>0,(+N22-N$8)/$A22*30,0) -> 121.66667 | BD22: =IF(V22<>0,(+V22-V$8)*2200/$A22*30,0) -> 0 | BE22: =IF(X22<>0,AVERAGE(X$11:X22)*30,) -> 322932.5 | BF22: =IF(AD22+AG22<>0,AVERAGE(AD$11:AD22)*30+AVERAGE(AG$11:AG22)*30,) -> 47605 | BG22: =IF(AJ22<>0,AVERAGE(AJ$11:AJ22)*30,) -> 6900 | BH22: =IF(AN22<>0,AVERAGE(AN$11:AN22)*30,) -> 15925 | BI22: =IF(AR22<>0,AVERAGE(AR$11:AR22)*30,) -> 8480
A23: =1+A22 -> 19 | B23: 00:00 | D23: 363577 | E23: =IF(ISBLANK(D23),0,D23-D22) -> 283 | F23: 7095 | G23: =IF(ISBLANK(F23),0,F23-F22) -> 0 | H23: 112499 | I23: =IF(ISBLANK(H23),0,H23-H22) -> 232 | J23: 626474 | K23: =IF(ISBLANK(J23),0,J23-J22) -> 223 | M23: =I23/L23 -> #DIV/0! | N23: 15029 | O23: =IF(ISBLANK(N23),0,N23-N22) -> 4 | P23: 99803 | Q23: =IF(ISBLANK(P23),0,P23-P22) -> 91 | R23: 43 | S23: =IF(ISBLANK(R23),0,R23-R22) -> 0 | T23: 206237 | U23: =IF(ISBLANK(T23),0,T23-T22) -> 117 | W23: =IF(ISBLANK(V23),0,SUM(V23-V22)*2200) -> 0 | X23: 11586 | Z23: =IF(ISBLANK(Y23),0,Y23-Y22)*2200 -> 0 | AA23: 1978 | AC23: =IF(ISBLANK(AB23),0,SUM(AB23-AB22)) -> 0 | AD23: 226 | AF23: =IF(ISBLANK(AE23),0,SUM(AE23-AE22)) -> 0 | AG23: 1459 | AI23: =IF(ISBLANK(AH23),0,AH23-AH22)*80 -> 0 | AJ23: 232 | AM23: =IF(ISBLANK(AL23),0,AL23-AL22) -> 0 | AN23: 583 | AQ23: =IF(ISBLANK(AP23),0,AP23-AP22)*80 -> 0 | AR23: 272 | AS23: 6 | AT23: 13 | AW23: =IF(ISBLANK(AV23),0,AV23-AV22) -> 0 | AX23: 602 | AY23: =IF(ISBLANK(AX23),0,AX23-AX22) -> 3 | AZ23: =IF(D23<>0,(+D23-D$8)/A23*30,0) -> 11532.632 | BA23: =IF(F23<>0,(+F23-F$8)/$A23*30,0) -> 11.052632 | BB23: =IF(H23<>0,(+H23-H$8)/$A23*30,0) -> 5690.5263 | BC23: =IF(N23<>0,(+N23-N$8)/$A23*30,0) -> 121.57895 | BD23: =IF(V23<>0,(+V23-V$8)*2200/$A23*30,0) -> 0 | BE23: =IF(X23<>0,AVERAGE(X$11:X23)*30,) -> 324828.46 | BF23: =IF(AD23+AG23<>0,AVERAGE(AD$11:AD23)*30+AVERAGE(AG$11:AG23)*30,) -> 47831.538 | BG23: =IF(AJ23<>0,AVERAGE(AJ$11:AJ23)*30,) -> 6904.6154 | BH23: =IF(AN23<>0,AVERAGE(AN$11:AN23)*30,) -> 16045.385 | BI23: =IF(AR23<>0,AVERAGE(AR$11:AR23)*30,) -> 8455.3846
A24: =1+A23 -> 20 | B24: 00:00 | D24: 363925 | E24: =IF(ISBLANK(D24),0,D24-D23) -> 348 | F24: 7095 | G24: =IF(ISBLANK(F24),0,F24-F23) -> 0 | H24: 112747 | I24: =IF(ISBLANK(H24),0,H24-H23) -> 248 | J24: 626711 | K24: =IF(ISBLANK(J24),0,J24-J23) -> 237 | M24: =I24/L24 -> #DIV/0! | N24: 15034 | O24: =IF(ISBLANK(N24),0,N24-N23) -> 5 | P24: 99911 | Q24: =IF(ISBLANK(P24),0,P24-P23) -> 108 | R24: 43 | S24: 0 | T24: 206377 | U24: =IF(ISBLANK(T24),0,T24-T23) -> 140 | V24: 5750.61 | W24: =IF(ISBLANK(V24),0,SUM(V24-V23)*2200) -> 12651342 | X24: 11257 | Y24: 1091.43 | Z24: =IF(ISBLANK(Y24),0,Y24-Y23)*2200 -> 2401146 | AA24: 1888 | AB24: 1781064.8 | AC24: =IF(ISBLANK(AB24),0,SUM(AB24-AB23)) -> 1781064.8 | AD24: 221 | AE24: 5287229 | AF24: =IF(ISBLANK(AE24),0,SUM(AE24-AE23)) -> 5287229 | AG24: 1355 | AH24: 34310.5 | AI24: =IF(ISBLANK(AH24),0,AH24-AH23)*80 -> 2744840 | AJ24: 224 | AL24: 257312 | AM24: =IF(ISBLANK(AL24),0,AL24-AL23) -> 257312 | AN24: 512 | AP24: 47086.4 | AQ24: =IF(ISBLANK(AP24),0,AP24-AP23)*80 -> 3766912 | AR24: 304 | AS24: 5 | AT24: 15 | AW24: =IF(ISBLANK(AV24),0,AV24-AV23) -> 0 | AX24: 603 | AY24: =IF(ISBLANK(AX24),0,AX24-AX23) -> 1 | AZ24: =IF(D24<>0,(+D24-D$8)/A24*30,0) -> 11478 | BA24: =IF(F24<>0,(+F24-F$8)/$A24*30,0) -> 10.5 | BB24: =IF(H24<>0,(+H24-H$8)/$A24*30,0) -> 5778 | BC24: =IF(N24<>0,(+N24-N$8)/$A24*30,0) -> 123 | BD24: =IF(V24<>0,(+V24-V$8)*2200/$A24*30,0) -> 18977013 | BE24: =IF(X24<>0,AVERAGE(X$11:X24)*30,) -> 325748.57 | BF24: =IF(AD24+AG24<>0,AVERAGE(AD$11:AD24)*30+AVERAGE(AG$11:AG24)*30,) -> 47792.143 | BG24: =IF(AJ24<>0,AVERAGE(AJ$11:AJ24)*30,) -> 6891.4286 | BH24: =IF(AN24<>0,AVERAGE(AN$11:AN24)*30,) -> 15996.429 | BI24: =IF(AR24<>0,AVERAGE(AR$11:AR24)*30,) -> 8502.8571
A25: =1+A24 -> 21 | B25: 00:00 | D25: 364576 | E25: =IF(ISBLANK(D25),0,D25-D24) -> 651 | F25: 7095 | G25: =IF(ISBLANK(F25),0,F25-F24) -> 0 | H25: 113008 | I25: =IF(ISBLANK(H25),0,H25-H24) -> 261 | J25: 626962 | K25: =IF(ISBLANK(J25),0,J25-J24) -> 251 | M25: =I25/L25 -> #DIV/0! | N25: 15039 | O25: =IF(ISBLANK(N25),0,N25-N24) -> 5 | P25: 99921 | Q25: =IF(ISBLANK(P25),0,P25-P24) -> 10 | R25: 43 | S25: =IF(ISBLANK(R25),0,R25-R24) -> 0 | T25: 206512 | U25: =IF(ISBLANK(T25),0,T25-T24) -> 135 | W25: =IF(ISBLANK(V25),0,SUM(V25-V24)*2200) -> 0 | X25: 10246 | Z25: =IF(ISBLANK(Y25),0,Y25-Y24)*2200 -> 0 | AA25: 1366 | AC25: =IF(ISBLANK(AB25),0,SUM(AB25-AB24)) -> 0 | AD25: 218 | AF25: =IF(ISBLANK(AE25),0,SUM(AE25-AE24)) -> 0 | AG25: 1226 | AI25: =IF(ISBLANK(AH25),0,AH25-AH24)*80 -> 0 | AJ25: 144 | AM25: =IF(ISBLANK(AL25),0,AL25-AL24) -> 0 | AN25: 467 | AQ25: =IF(ISBLANK(AP25),0,AP25-AP24)*80 -> 0 | AR25: 280 | AS25: 5 | AT25: 8 | AW25: =IF(ISBLANK(AV25),0,AV25-AV24) -> 0 | AX25: 604 | AY25: =IF(ISBLANK(AX25),0,AX25-AX24) -> 1 | AZ25: =IF(D25<>0,(+D25-D$8)/A25*30,0) -> 11861.429 | BA25: =IF(F25<>0,(+F25-F$8)/$A25*30,0) -> 10 | BB25: =IF(H25<>0,(+H25-H$8)/$A25*30,0) -> 5875.7143 | BC25: =IF(N25<>0,(+N25-N$8)/$A25*30,0) -> 124.28571 | BD25: =IF(V25<>0,(+V25-V$8)*2200/$A25*30,0) -> 0 | BE25: =IF(X25<>0,AVERAGE(X$11:X25)*30,) -> 324524 | BF25: =IF(AD25+AG25<>0,AVERAGE(AD$11:AD25)*30+AVERAGE(AG$11:AG25)*30,) -> 47494 | BG25: =IF(AJ25<>0,AVERAGE(AJ$11:AJ25)*30,) -> 6720 | BH25: =IF(AN25<>0,AVERAGE(AN$11:AN25)*30,) -> 15864 | BI25: =IF(AR25<>0,AVERAGE(AR$11:AR25)*30,) -> 8496
A26: =1+A25 -> 22 | B26: 00:00 | D26: 365070 | E26: =IF(ISBLANK(D26),0,D26-D25) -> 494 | F26: 7095 | G26: =IF(ISBLANK(F26),0,F26-F25) -> 0 | H26: 113251 | I26: =IF(ISBLANK(H26),0,H26-H25) -> 243 | J26: 627195 | K26: =IF(ISBLANK(J26),0,J26-J25) -> 233 | M26: =I26/L26 -> #DIV/0! | N26: 15044 | O26: =IF(ISBLANK(N26),0,N26-N25) -> 5 | P26: 100120 | Q26: =IF(ISBLANK(P26),0,P26-P25) -> 199 | R26: 43 | S26: =IF(ISBLANK(R26),0,R26-R25) -> 0 | T26: 206638 | U26: =IF(ISBLANK(T26),0,T26-T25) -> 126 | W26: =IF(ISBLANK(V26),0,SUM(V26-V25)*2200) -> 0 | X26: 11208 | Z26: =IF(ISBLANK(Y26),0,Y26-Y25)*2200 -> 0 | AA26: 1778 | AC26: =IF(ISBLANK(AB26),0,SUM(AB26-AB25)) -> 0 | AD26: 227 | AF26: =IF(ISBLANK(AE26),0,SUM(AE26-AE25)) -> 0 | AG26: 1287 | AI26: =IF(ISBLANK(AH26),0,AH26-AH25)*80 -> 0 | AJ26: 232 | AM26: =IF(ISBLANK(AL26),0,AL26-AL25) -> 0 | AN26: 471 | AQ26: =IF(ISBLANK(AP26),0,AP26-AP25)*80 -> 0 | AR26: 280 | AS26: 9 | AT26: 13 | AW26: =IF(ISBLANK(AV26),0,AV26-AV25) -> 0 | AX26: 606 | AY26: =IF(ISBLANK(AX26),0,AX26-AX25) -> 2 | AZ26: =IF(D26<>0,(+D26-D$8)/A26*30,0) -> 11995.909 | BA26: =IF(F26<>0,(+F26-F$8)/$A26*30,0) -> 9.5454545 | BB26: =IF(H26<>0,(+H26-H$8)/$A26*30,0) -> 5940 | BC26: =IF(N26<>0,(+N26-N$8)/$A26*30,0) -> 125.45455 | BD26: =IF(V26<>0,(+V26-V$8)*2200/$A26*30,0) -> 0 | BE26: =IF(X26<>0,AVERAGE(X$11:X26)*30,) -> 325256.25 | BF26: =IF(AD26+AG26<>0,AVERAGE(AD$11:AD26)*30+AVERAGE(AG$11:AG26)*30,) -> 47364.375 | BG26: =IF(AJ26<>0,AVERAGE(AJ$11:AJ26)*30,) -> 6735 | BH26: =IF(AN26<>0,AVERAGE(AN$11:AN26)*30,) -> 15755.625 | BI26: =IF(AR26<>0,AVERAGE(AR$11:AR26)*30,) -> 8490
A27: =1+A26 -> 23 | B27: 00:00 | D27: 365528 | E27: =IF(ISBLANK(D27),0,D27-D26) -> 458 | F27: 7096 | G27: =IF(ISBLANK(F27),0,F27-F26) -> 1 | H27: 113499 | I27: =IF(ISBLANK(H27),0,H27-H26) -> 248 | J27: 627433 | K27: =IF(ISBLANK(J27),0,J27-J26) -> 238 | M27: =I27/L27 -> #DIV/0! | N27: 15049 | O27: =IF(ISBLANK(N27),0,N27-N26) -> 5 | P27: 100226 | Q27: =IF(ISBLANK(P27),0,P27-P26) -> 106 | R27: 43 | S27: =IF(ISBLANK(R27),0,R27-R26) -> 0 | T27: 206772 | U27: =IF(ISBLANK(T27),0,T27-T26) -> 134 | W27: =IF(ISBLANK(V27),0,SUM(V27-V26)*2200) -> 0 | X27: 11672 | Z27: =IF(ISBLANK(Y27),0,Y27-Y26)*2200 -> 0 | AA27: 1904 | AC27: =IF(ISBLANK(AB27),0,SUM(AB27-AB26)) -> 0 | AD27: 237 | AF27: =IF(ISBLANK(AE27),0,SUM(AE27-AE26)) -> 0 | AG27: 1258 | AI27: =IF(ISBLANK(AH27),0,AH27-AH26)*80 -> 0 | AJ27: 192 | AM27: =IF(ISBLANK(AL27),0,AL27-AL26) -> 0 | AN27: 525 | AQ27: =IF(ISBLANK(AP27),0,AP27-AP26)*80 -> 0 | AR27: 280 | AS27: 10 | AT27: 13 | AW27: =IF(ISBLANK(AV27),0,AV27-AV26) -> 0 | AX27: 608 | AY27: =IF(ISBLANK(AX27),0,AX27-AX26) -> 2 | AZ27: =IF(D27<>0,(+D27-D$8)/A27*30,0) -> 12071.739 | BA27: =IF(F27<>0,(+F27-F$8)/$A27*30,0) -> 10.434783 | BB27: =IF(H27<>0,(+H27-H$8)/$A27*30,0) -> 6005.2174 | BC27: =IF(N27<>0,(+N27-N$8)/$A27*30,0) -> 126.52174 | BD27: =IF(V27<>0,(+V27-V$8)*2200/$A27*30,0) -> 0 | BE27: =IF(X27<>0,AVERAGE(X$11:X27)*30,) -> 326721.18 | BF27: =IF(AD27+AG27<>0,AVERAGE(AD$11:AD27)*30+AVERAGE(AG$11:AG27)*30,) -> 47216.471 | BG27: =IF(AJ27<>0,AVERAGE(AJ$11:AJ27)*30,) -> 6677.6471 | BH27: =IF(AN27<>0,AVERAGE(AN$11:AN27)*30,) -> 15755.294 | BI27: =IF(AR27<>0,AVERAGE(AR$11:AR27)*30,) -> 8484.7059
A28: =1+A27 -> 24 | B28: 00:00 | D28: 366019 | E28: =IF(ISBLANK(D28),0,D28-D27) -> 491 | F28: 7086 | G28: =IF(ISBLANK(F28),0,F28-F27) -> -10 | H28: 113713 | I28: =IF(ISBLANK(H28),0,H28-H27) -> 214 | J28: 627638 | K28: =IF(ISBLANK(J28),0,J28-J27) -> 205 | M28: =I28/L28 -> #DIV/0! | N28: 15053 | O28: =IF(ISBLANK(N28),0,N28-N27) -> 4 | P28: 100306 | Q28: =IF(ISBLANK(P28),0,P28-P27) -> 80 | R28: 43 | S28: =IF(ISBLANK(R28),0,R28-R27) -> 0 | T28: 206880 | U28: =IF(ISBLANK(T28),0,T28-T27) -> 108 | W28: =IF(ISBLANK(V28),0,SUM(V28-V27)*2200) -> 0 | X28: 11495 | Z28: =IF(ISBLANK(Y28),0,Y28-Y27)*2200 -> 0 | AA28: 1912 | AC28: =IF(ISBLANK(AB28),0,SUM(AB28-AB27)) -> 0 | AD28: 234 | AF28: =IF(ISBLANK(AE28),0,SUM(AE28-AE27)) -> 0 | AG28: 1232 | AI28: =IF(ISBLANK(AH28),0,AH28-AH27)*80 -> 0 | AJ28: 200 | AM28: =IF(ISBLANK(AL28),0,AL28-AL27) -> 0 | AN28: 487 | AQ28: =IF(ISBLANK(AP28),0,AP28-AP27)*80 -> 0 | AR28: 304 | AS28: 9 | AT28: 14 | AW28: =IF(ISBLANK(AV28),0,AV28-AV27) -> 0 | AX28: 608 | AY28: =IF(ISBLANK(AX28),0,AX28-AX27) -> 0 | AZ28: =IF(D28<>0,(+D28-D$8)/A28*30,0) -> 12182.5 | BA28: =IF(F28<>0,(+F28-F$8)/$A28*30,0) -> -2.5 | BB28: =IF(H28<>0,(+H28-H$8)/$A28*30,0) -> 6022.5 | BC28: =IF(N28<>0,(+N28-N$8)/$A28*30,0) -> 126.25 | BD28: =IF(V28<>0,(+V28-V$8)*2200/$A28*30,0) -> 0 | BE28: =IF(X28<>0,AVERAGE(X$11:X28)*30,) -> 327728.33 | BF28: =IF(AD28+AG28<>0,AVERAGE(AD$11:AD28)*30+AVERAGE(AG$11:AG28)*30,) -> 47036.667 | BG28: =IF(AJ28<>0,AVERAGE(AJ$11:AJ28)*30,) -> 6640 | BH28: =IF(AN28<>0,AVERAGE(AN$11:AN28)*30,) -> 15691.667 | BI28: =IF(AR28<>0,AVERAGE(AR$11:AR28)*30,) -> 8520
A29: =1+A28 -> 25 | B29: 00:00 | D29: 366508 | E29: =IF(ISBLANK(D29),0,D29-D28) -> 489 | F29: 7097 | G29: =IF(ISBLANK(F29),0,F29-F28) -> 11 | H29: 113904 | I29: =IF(ISBLANK(H29),0,H29-H28) -> 191 | J29: 627821 | K29: =IF(ISBLANK(J29),0,J29-J28) -> 183 | M29: =I29/L29 -> #DIV/0! | N29: 15058 | O29: =IF(ISBLANK(N29),0,N29-N28) -> 5 | P29: 100324 | Q29: =IF(ISBLANK(P29),0,P29-P28) -> 18 | R29: 43 | S29: =IF(ISBLANK(R29),0,R29-R28) -> 0 | T29: 206938 | U29: =IF(ISBLANK(T29),0,T29-T28) -> 58 | W29: =IF(ISBLANK(V29),0,SUM(V29-V28)*2200) -> 0 | X29: 11790 | Z29: =IF(ISBLANK(Y29),0,Y29-Y28)*2200 -> 0 | AA29: 1965 | AC29: =IF(ISBLANK(AB29),0,SUM(AB29-AB28)) -> 0 | AD29: 289 | AF29: =IF(ISBLANK(AE29),0,SUM(AE29-AE28)) -> 0 | AG29: 1259 | AI29: =IF(ISBLANK(AH29),0,AH29-AH28)*80 -> 0 | AJ29: 208 | AM29: =IF(ISBLANK(AL29),0,AL29-AL28) -> 0 | AN29: 524 | AQ29: =IF(ISBLANK(AP29),0,AP29-AP28)*80 -> 0 | AR29: 328 | AS29: 10 | AT29: 14 | AW29: =IF(ISBLANK(AV29),0,AV29-AV28) -> 0 | AX29: 609 | AY29: =IF(ISBLANK(AX29),0,AX29-AX28) -> 1 | AZ29: =IF(D29<>0,(+D29-D$8)/A29*30,0) -> 12282 | BA29: =IF(F29<>0,(+F29-F$8)/$A29*30,0) -> 10.8 | BB29: =IF(H29<>0,(+H29-H$8)/$A29*30,0) -> 6010.8 | BC29: =IF(N29<>0,(+N29-N$8)/$A29*30,0) -> 127.2 | BD29: =IF(V29<>0,(+V29-V$8)*2200/$A29*30,0) -> 0 | BE29: =IF(X29<>0,AVERAGE(X$11:X29)*30,) -> 329095.26 | BF29: =IF(AD29+AG29<>0,AVERAGE(AD$11:AD29)*30+AVERAGE(AG$11:AG29)*30,) -> 47005.263 | BG29: =IF(AJ29<>0,AVERAGE(AJ$11:AJ29)*30,) -> 6618.9474 | BH29: =IF(AN29<>0,AVERAGE(AN$11:AN29)*30,) -> 15693.158 | BI29: =IF(AR29<>0,AVERAGE(AR$11:AR29)*30,) -> 8589.4737
A30: =1+A29 -> 26 | B30: 00:00 | D30: 366947 | E30: =IF(ISBLANK(D30),0,D30-D29) -> 439 | F30: 7098 | G30: =IF(ISBLANK(F30),0,F30-F29) -> 1 | H30: 114066 | I30: =IF(ISBLANK(H30),0,H30-H29) -> 162 | J30: 627976 | K30: =IF(ISBLANK(J30),0,J30-J29) -> 155 | M30: =I30/L30 -> #DIV/0! | N30: 15063 | O30: =IF(ISBLANK(N30),0,N30-N29) -> 5 | P30: 100342 | Q30: =IF(ISBLANK(P30),0,P30-P29) -> 18 | R30: 43 | S30: =IF(ISBLANK(R30),0,R30-R29) -> 0 | T30: 206990 | U30: =IF(ISBLANK(T30),0,T30-T29) -> 52 | W30: =IF(ISBLANK(V30),0,SUM(V30-V29)*2200) -> 0 | X30: 11590 | Z30: =IF(ISBLANK(Y30),0,Y30-Y29)*2200 -> 0 | AA30: 1925 | AC30: =IF(ISBLANK(AB30),0,SUM(AB30-AB29)) -> 0 | AD30: 310 | AF30: =IF(ISBLANK(AE30),0,SUM(AE30-AE29)) -> 0 | AG30: 1356 | AI30: =IF(ISBLANK(AH30),0,AH30-AH29)*80 -> 0 | AJ30: 168 | AM30: =IF(ISBLANK(AL30),0,AL30-AL29) -> 0 | AN30: 505 | AQ30: =IF(ISBLANK(AP30),0,AP30-AP29)*80 -> 0 | AR30: 288 | AS30: 1 | AT30: 13 | AW30: =IF(ISBLANK(AV30),0,AV30-AV29) -> 0 | AX30: 609 | AY30: =IF(ISBLANK(AX30),0,AX30-AX29) -> 0 | AZ30: =IF(D30<>0,(+D30-D$8)/A30*30,0) -> 12316.154 | BA30: =IF(F30<>0,(+F30-F$8)/$A30*30,0) -> 11.538462 | BB30: =IF(H30<>0,(+H30-H$8)/$A30*30,0) -> 5966.5385 | BC30: =IF(N30<>0,(+N30-N$8)/$A30*30,0) -> 128.07692 | BD30: =IF(V30<>0,(+V30-V$8)*2200/$A30*30,0) -> 0 | BE30: =IF(X30<>0,AVERAGE(X$11:X30)*30,) -> 330025.5 | BF30: =IF(AD30+AG30<>0,AVERAGE(AD$11:AD30)*30+AVERAGE(AG$11:AG30)*30,) -> 47154 | BG30: =IF(AJ30<>0,AVERAGE(AJ$11:AJ30)*30,) -> 6540 | BH30: =IF(AN30<>0,AVERAGE(AN$11:AN30)*30,) -> 15666 | BI30: =IF(AR30<>0,AVERAGE(AR$11:AR30)*30,) -> 8592
A31: =1+A30 -> 27 | B31: 00:00 | D31: 367413 | E31: =IF(ISBLANK(D31),0,D31-D30) -> 466 | F31: 7098 | G31: =IF(ISBLANK(F31),0,F31-F30) -> 0 | H31: 114228 | I31: =IF(ISBLANK(H31),0,H31-H30) -> 162 | J31: 628132 | K31: =IF(ISBLANK(J31),0,J31-J30) -> 156 | M31: =I31/L31 -> #DIV/0! | N31: 15068 | O31: =IF(ISBLANK(N31),0,N31-N30) -> 5 | P31: 100358 | Q31: =IF(ISBLANK(P31),0,P31-P30) -> 16 | R31: 44 | S31: =IF(ISBLANK(R31),0,R31-R30) -> 1 | T31: 207031 | U31: =IF(ISBLANK(T31),0,T31-T30) -> 41 | W31: =IF(ISBLANK(V31),0,SUM(V31-V30)*2200) -> 0 | X31: 11758 | Z31: =IF(ISBLANK(Y31),0,Y31-Y30)*2200 -> 0 | AA31: 2045 | AC31: =IF(ISBLANK(AB31),0,SUM(AB31-AB30)) -> 0 | AD31: 310 | AF31: =IF(ISBLANK(AE31),0,SUM(AE31-AE30)) -> 0 | AG31: 1305 | AI31: =IF(ISBLANK(AH31),0,AH31-AH30)*80 -> 0 | AJ31: 240 | AM31: =IF(ISBLANK(AL31),0,AL31-AL30) -> 0 | AN31: 453 | AQ31: =IF(ISBLANK(AP31),0,AP31-AP30)*80 -> 0 | AR31: 272 | AS31: 2 | AT31: 12 | AW31: =IF(ISBLANK(AV31),0,AV31-AV30) -> 0 | AX31: 610 | AY31: =IF(ISBLANK(AX31),0,AX31-AX30) -> 1 | AZ31: =IF(D31<>0,(+D31-D$8)/A31*30,0) -> 12377.778 | BA31: =IF(F31<>0,(+F31-F$8)/$A31*30,0) -> 11.111111 | BB31: =IF(H31<>0,(+H31-H$8)/$A31*30,0) -> 5925.5556 | BC31: =IF(N31<>0,(+N31-N$8)/$A31*30,0) -> 128.88889 | BD31: =IF(V31<>0,(+V31-V$8)*2200/$A31*30,0) -> 0 | BE31: =IF(X31<>0,AVERAGE(X$11:X31)*30,) -> 331107.14 | BF31: =IF(AD31+AG31<>0,AVERAGE(AD$11:AD31)*30+AVERAGE(AG$11:AG31)*30,) -> 47215.714 | BG31: =IF(AJ31<>0,AVERAGE(AJ$11:AJ31)*30,) -> 6571.4286 | BH31: =IF(AN31<>0,AVERAGE(AN$11:AN31)*30,) -> 15567.143 | BI31: =IF(AR31<>0,AVERAGE(AR$11:AR31)*30,) -> 8571.4286
A32: =1+A31 -> 28 | B32: 00:00 | D32: 367931 | E32: =IF(ISBLANK(D32),0,D32-D31) -> 518 | F32: 7099 | G32: =IF(ISBLANK(F32),0,F32-F31) -> 1 | H32: 114391 | I32: =IF(ISBLANK(H32),0,H32-H31) -> 163 | J32: 628288 | K32: =IF(ISBLANK(J32),0,J32-J31) -> 156 | M32: =I32/L32 -> #DIV/0! | N32: 15073 | O32: =IF(ISBLANK(N32),0,N32-N31) -> 5 | P32: 100374 | Q32: =IF(ISBLANK(P32),0,P32-P31) -> 16 | R32: 44 | S32: =IF(ISBLANK(R32),0,R32-R31) -> 0 | T32: 207067 | U32: =IF(ISBLANK(T32),0,T32-T31) -> 36 | W32: =IF(ISBLANK(V32),0,SUM(V32-V31)*2200) -> 0 | X32: 12041 | Z32: =IF(ISBLANK(Y32),0,Y32-Y31)*2200 -> 0 | AA32: 2168 | AC32: =IF(ISBLANK(AB32),0,SUM(AB32-AB31)) -> 0 | AD32: 315 | AF32: =IF(ISBLANK(AE32),0,SUM(AE32-AE31)) -> 0 | AG32: 1252 | AI32: =IF(ISBLANK(AH32),0,AH32-AH31)*80 -> 0 | AJ32: 256 | AM32: =IF(ISBLANK(AL32),0,AL32-AL31) -> 0 | AN32: 414 | AQ32: =IF(ISBLANK(AP32),0,AP32-AP31)*80 -> 0 | AR32: 264 | AS32: 2 | AT32: 6 | AW32: =IF(ISBLANK(AV32),0,AV32-AV31) -> 0 | AX32: 611 | AY32: =IF(ISBLANK(AX32),0,AX32-AX31) -> 1 | AZ32: =IF(D32<>0,(+D32-D$8)/A32*30,0) -> 12490.714 | BA32: =IF(F32<>0,(+F32-F$8)/$A32*30,0) -> 11.785714 | BB32: =IF(H32<>0,(+H32-H$8)/$A32*30,0) -> 5888.5714 | BC32: =IF(N32<>0,(+N32-N$8)/$A32*30,0) -> 129.64286 | BD32: =IF(V32<>0,(+V32-V$8)*2200/$A32*30,0) -> 0 | BE32: =IF(X32<>0,AVERAGE(X$11:X32)*30,) -> 332476.36 | BF32: =IF(AD32+AG32<>0,AVERAGE(AD$11:AD32)*30+AVERAGE(AG$11:AG32)*30,) -> 47206.364 | BG32: =IF(AJ32<>0,AVERAGE(AJ$11:AJ32)*30,) -> 6621.8182 | BH32: =IF(AN32<>0,AVERAGE(AN$11:AN32)*30,) -> 15424.091 | BI32: =IF(AR32<>0,AVERAGE(AR$11:AR32)*30,) -> 8541.8182
A33: =1+A32 -> 29 | B33: 00:00 | D33: 368492 | E33: =IF(ISBLANK(D33),0,D33-D32) -> 561 | F33: 7099 | G33: =IF(ISBLANK(F33),0,F33-F32) -> 0 | H33: 114549 | I33: =IF(ISBLANK(H33),0,H33-H32) -> 158 | J33: 628439 | K33: =IF(ISBLANK(J33),0,J33-J32) -> 151 | M33: =I33/L33 -> #DIV/0! | N33: 15078 | O33: =IF(ISBLANK(N33),0,N33-N32) -> 5 | P33: 100391 | Q33: =IF(ISBLANK(P33),0,P33-P32) -> 17 | R33: 44 | S33: =IF(ISBLANK(R33),0,R33-R32) -> 0 | T33: 207101 | U33: =IF(ISBLANK(T33),0,T33-T32) -> 34 | W33: =IF(ISBLANK(V33),0,SUM(V33-V32)*2200) -> 0 | X33: 11808 | Z33: =IF(ISBLANK(Y33),0,Y33-Y32)*2200 -> 0 | AA33: 2123 | AC33: =IF(ISBLANK(AB33),0,SUM(AB33-AB32)) -> 0 | AD33: 241 | AF33: 0 | AG33: 1263 | AI33: =IF(ISBLANK(AH33),0,AH33-AH32)*80 -> 0 | AJ33: 224 | AM33: =IF(ISBLANK(AL33),0,AL33-AL32) -> 0 | AN33: 420 | AQ33: =IF(ISBLANK(AP33),0,AP33-AP32)*80 -> 0 | AR33: 256 | AS33: 4 | AT33: 8 | AW33: =IF(ISBLANK(AV33),0,AV33-AV32) -> 0 | AX33: 612 | AY33: =IF(ISBLANK(AX33),0,AX33-AX32) -> 1 | AZ33: =IF(D33<>0,(+D33-D$8)/A33*30,0) -> 12640.345 | BA33: =IF(F33<>0,(+F33-F$8)/$A33*30,0) -> 11.37931 | BB33: =IF(H33<>0,(+H33-H$8)/$A33*30,0) -> 5848.9655 | BC33: =IF(N33<>0,(+N33-N$8)/$A33*30,0) -> 130.34483 | BD33: =IF(V33<>0,(+V33-V$8)*2200/$A33*30,0) -> 0 | BE33: =IF(X33<>0,AVERAGE(X$11:X33)*30,) -> 333422.61 | BF33: =IF(AD33+AG33<>0,AVERAGE(AD$11:AD33)*30+AVERAGE(AG$11:AG33)*30,) -> 47115.652 | BG33: =IF(AJ33<>0,AVERAGE(AJ$11:AJ33)*30,) -> 6626.087 | BH33: =IF(AN33<>0,AVERAGE(AN$11:AN33)*30,) -> 15301.304 | BI33: =IF(AR33<>0,AVERAGE(AR$11:AR33)*30,) -> 8504.3478
A34: =1+A33 -> 30 | B34: 00:00 | D34: 369176 | E34: =IF(ISBLANK(D34),0,D34-D33) -> 684 | F34: 7099 | G34: =IF(ISBLANK(F34),0,F34-F33) -> 0 | H34: 114715 | I34: =IF(ISBLANK(H34),0,H34-H33) -> 166 | J34: 628598 | K34: =IF(ISBLANK(J34),0,J34-J33) -> 159 | M34: =I34/L34 -> #DIV/0! | N34: 15083 | O34: =IF(ISBLANK(N34),0,N34-N33) -> 5 | P34: 100407 | Q34: =IF(ISBLANK(P34),0,P34-P33) -> 16 | R34: 44 | S34: =IF(ISBLANK(R34),0,R34-R33) -> 0 | T34: 207141 | U34: =IF(ISBLANK(T34),0,T34-T33) -> 40 | V34: 5808.74 | W34: =IF(ISBLANK(V34),0,SUM(V34-V33)*2200) -> 12779228 | X34: 12141 | Y34: 1101.143 | Z34: =IF(ISBLANK(Y34),0,Y34-Y33)*2200 -> 2422514.6 | AA34: 2147 | AB34: 1783697.8 | AC34: =IF(ISBLANK(AB34),0,SUM(AB34-AB33)) -> 1783697.8 | AD34: 241 | AE34: 5300045 | AG34: 1315 | AH34: 34337.7 | AI34: =IF(ISBLANK(AH34),0,AH34-AH33)*80 -> 2747016 | AJ34: 312 | AL34: 262109.3 | AM34: =IF(ISBLANK(AL34),0,AL34-AL33) -> 262109.3 | AN34: 521 | AP34: 47121.7 | AQ34: =IF(ISBLANK(AP34),0,AP34-AP33)*80 -> 3769736 | AR34: 240 | AS34: 3 | AT34: 6 | AW34: =IF(ISBLANK(AV34),0,AV34-AV33) -> 0 | AX34: 613 | AY34: =IF(ISBLANK(AX34),0,AX34-AX33) -> 1 | AZ34: =IF(D34<>0,(+D34-D$8)/A34*30,0) -> 12903 | BA34: =IF(F34<>0,(+F34-F$8)/$A34*30,0) -> 11 | BB34: =IF(H34<>0,(+H34-H$8)/$A34*30,0) -> 5820 | BC34: =IF(N34<>0,(+N34-N$8)/$A34*30,0) -> 131 | BD34: =IF(V34<>0,(+V34-V$8)*2200/$A34*30,0) -> 12779228 | BE34: =IF(X34<>0,AVERAGE(X$11:X34)*30,) -> 334706.25 | BF34: =IF(AD34+AG34<>0,AVERAGE(AD$11:AD34)*30+AVERAGE(AG$11:AG34)*30,) -> 47097.5 | BG34: =IF(AJ34<>0,AVERAGE(AJ$11:AJ34)*30,) -> 6740 | BH34: =IF(AN34<>0,AVERAGE(AN$11:AN34)*30,) -> 15315 | BI34: =IF(AR34<>0,AVERAGE(AR$11:AR34)*30,) -> 8450
A35: =1+A34 -> 31 | B35: 00:00 | E35: =IF(ISBLANK(D35),0,D35-D34) -> 0 | G35: =IF(ISBLANK(F35),0,F35-F34) -> 0 | I35: =IF(ISBLANK(H35),0,H35-H34) -> 0 | K35: =IF(ISBLANK(J35),0,J35-J34) -> 0 | M35: =I35/L35 -> #DIV/0! | O35: =IF(ISBLANK(N35),0,N35-N34) -> 0 | Q35: =IF(ISBLANK(P35),0,P35-P34) -> 0 | S35: =IF(ISBLANK(R35),0,R35-R34) -> 0 | U35: =IF(ISBLANK(T35),0,T35-T34) -> 0 | W35: =IF(ISBLANK(V35),0,SUM(V35-V34)*2200) -> 0 | Z35: =IF(ISBLANK(Y35),0,Y35-Y34)*2200 -> 0 | AC35: =IF(ISBLANK(AB35),0,SUM(AB35-AB24)) -> 0 | AI35: =IF(ISBLANK(AH35),0,AH35-AH34)*80 -> 0 | AM35: =IF(ISBLANK(AL35),0,AL35-AL34) -> 0 | AQ35: =IF(ISBLANK(AP35),0,AP35-AP34)*80 -> 0 | AW35: =IF(ISBLANK(AV35),0,AV35-AV34) -> 0 | AY35: =IF(ISBLANK(AX35),0,AX35-AX34) -> 0 | AZ35: =IF(D35<>0,(+D35-D$10)/$A35*31,0) -> 0 | BA35: =IF(F35<>0,(+F35-F$10)/$A35*31,0) -> 0 | BB35: =IF(H35<>0,(+H35-H$10)/$A35*31,0) -> 0 | BC35: =IF(N35<>0,(+N35-N$10)/$A35*31,0) -> 0 | BD35: =IF(V35<>0,(+V35-V$10)*2200/$A35*31,0) -> 0 | BE35: =IF(X35<>0,AVERAGE(X$11:X35)*31,) -> 0 | BF35: =IF(AD35+AG35<>0,AVERAGE(AD$11:AD35)*31+AVERAGE(AG$11:AG35)*31,) -> 0 | BG35: =IF(AJ35<>0,AVERAGE(AJ$11:AJ35)*31,) -> 0 | BH35: =IF(AN35<>0,AVERAGE(AN$11:AN35)*31,) -> 0 | BI35: =IF(AR35<>0,AVERAGE(AR$11:AR35)*31,) -> 0
