Workbook

Sheet TOTAL
A1: Site Name | B1: Day | C1: Month | D1: Year | E1: Total Electricity Kwh | F1: Electricity Tariff ($/Kwh) | G1: Total Fuel Oil (Liter) | H1: Fuel Oil $/Liter | I1: Water Utility Supply (m3) m3 | J1: Water Utility Supply (m3) $/m3 | K1: LPG (Kg) | L1: LPG $/Kg | M1: Room Nights | N1: Total Guests | O1: Food Covers
A2: Maldives at Kuda Huraa | B2: 1 | C2: 12 | D2: 2022 | E2: 16850 | G2: 4682 | I2: 251 | M2: 30.2 | N2: 72 | O2: 176
A3: Maldives at Kuda Huraa | B3: =B2+1 -> 2 | C3: 12 | D3: 2022 | E3: 17160 | G3: 4716 | I3: 221 | M3: 32.3 | N3: 77 | O3: 237
A4: Maldives at Kuda Huraa | B4: =B3+1 -> 3 | C4: 12 | D4: 2022 | E4: 16600 | G4: 4532 | I4: 281 | M4: 30.2 | N4: 77 | O4: 174
A5: Maldives at Kuda Huraa | B5: =B4+1 -> 4 | C5: 12 | D5: 2022 | E5: 16520 | G5: 4586 | I5: 345 | M5: 30.2 | N5: 69 | O5: 208
A6: Maldives at Kuda Huraa | B6: =B5+1 -> 5 | C6: 12 | D6: 2022 | E6: 18500 | G6: 4968 | I6: 252 | M6: 22.9 | N6: 57 | O6: 189
A7: Maldives at Kuda Huraa | B7: =B6+1 -> 6 | C7: 12 | D7: 2022 | E7: 17510 | G7: 5020 | I7: 266 | M7: 20.8 | N7: 54 | O7: 142
A8: Maldives at Kuda Huraa | B8: =B7+1 -> 7 | C8: 12 | D8: 2022 | E8: 16310 | G8: 4600 | I8: 275 | M8: 20.8 | N8: 51 | O8: 126
A9: Maldives at Kuda Huraa | B9: =B8+1 -> 8 | C9: 12 | D9: 2022 | E9: 17980 | G9: 4830 | I9: 265 | M9: 18.8 | N9: 51 | O9: 128
A10: Maldives at Kuda Huraa | B10: =B9+1 -> 9 | C10: 12 | D10: 2022 | E10: 17700 | G10: 4871 | I10: 289 | M10: 16.7 | N10: 42 | O10: 117
A11: Maldives at Kuda Huraa | B11: =B10+1 -> 10 | C11: 12 | D11: 2022 | E11: 19260 | G11: 5191 | I11: 247 | M11: 19.8 | N11: 60 | O11: 123
A12: Maldives at Kuda Huraa | B12: =B11+1 -> 11 | C12: 12 | D12: 2022 | E12: 18670 | G12: 5121 | I12: 286 | M12: 20.8 | N12: 65 | O12: 136
A13: Maldives at Kuda Huraa | B13: =B12+1 -> 12 | C13: 12 | D13: 2022 | E13: 18950 | G13: 5217 | I13: 280 | M13: 26 | N13: 77 | O13: 173
A14: Maldives at Kuda Huraa | B14: =B13+1 -> 13 | C14: 12 | D14: 2022 | E14: 17860 | G14: 5073 | I14: 284 | M14: 27.1 | N14: 75 | O14: 191
... A24: Maldives at Kuda Huraa | B24: =B23+1 -> 23 | C24: 12 | D24: 2022 | E24: 18690 | G24: 5085 | I24: 312 | M24: 50 | N24: 140 | O24: 356
A25: Maldives at Kuda Huraa | B25: =B24+1 -> 24 | C25: 12 | D25: 2022
A26: Maldives at Kuda Huraa | B26: =B25+1 -> 25 | C26: 12 | D26: 2022
A27: Maldives at Kuda Huraa | B27: =B26+1 -> 26 | C27: 12 | D27: 2022
A28: Maldives at Kuda Huraa | B28: =B27+1 -> 27 | C28: 12 | D28: 2022
A29: Maldives at Kuda Huraa | B29: =B28+1 -> 28 | C29: 12 | D29: 2022
A30: Maldives at Kuda Huraa | B30: =B29+1 -> 29 | C30: 12 | D30: 2022
A31: Maldives at Kuda Huraa | B31: =B30+1 -> 30 | C31: 12 | D31: 2022
A32: Total | E32: =SUM(E2:E31) -> 412000 | F32: 0 | G32: =SUM(G2:G31) -> 113572 | H32: 0 | I32: =SUM(I2:I31) -> 6452 | J32: 0 | K32: =SUM(K2:K31) -> 0 | L32: 0 | M32: =SUM(M2:M31) -> 640.7 | N32: =SUM(N2:N31) -> 1753 | O32: =SUM(O2:O31) -> 4443

Sheet Submeters
A1: Site Name | B1: Day | C1: Month | D1: Year | E1: Reef Club | F1: Kitchen | G1: Pastry | H1: Laundry | I1: Laundry A | J1: Laundry B | K1: Laundry C | L1: STP -1 &2 | M1: STP -3 | N1: M - Block /PC | O1: B&C Block | P1: Feeder -101-112 | Q1: Feeder -113-123 | R1: Feeder -124-134 | S1: Feeder -201-208 | T1: Feeder -209-216 | U1: Feeder -217-224 | V1: Feeder -301-319 | W1: Feeder 401-419 | X1: Spa
A2: Maldives at Kuda Huraa | B2: 1 | C2: 12 | D2: 2022 | E2: =('Kwh Reading'!T5-'Kwh Reading'!T4)*1000 -> 480 | F2: =('Kwh Reading'!F5-'Kwh Reading'!F4)*1000000 -> 2600 | G2: =('Kwh Reading'!C5-'Kwh Reading'!C4)*1000 -> 260 | H2: =I2+J2+K2 -> 950 | I2: =('Kwh Reading'!J5-'Kwh Reading'!J4)*1000 -> 450 | J2: =('Kwh Reading'!K5-'Kwh Reading'!K4)*1000 -> 310 | K2: =('Kwh Reading'!L5-'Kwh Reading'!L4)*1000 -> 190 | L2: =('Kwh Reading'!R5-'Kwh Reading'!R4)*1000 -> 0 | M2: =('Kwh Reading'!S5-'Kwh Reading'!S4)*1000 -> 0 | N2: =('Kwh Reading'!I5-'Kwh Reading'!I4)*1000 -> 260 | O2: =('Kwh Reading'!B5-'Kwh Reading'!B4)*1000000 -> 900 | P2: =('Kwh Reading'!M5-'Kwh Reading'!M4)*1000 -> 340 | Q2: =('Kwh Reading'!H5-'Kwh Reading'!H4)*1000000 -> 500 | R2: =('Kwh Reading'!P5-'Kwh Reading'!P4)*1000000 -> 400 | S2: =('Kwh Reading'!G5-'Kwh Reading'!G4)*1000000 -> 400 | T2: =('Kwh Reading'!Q5-'Kwh Reading'!Q4)*1000 -> 260 | U2: =('Kwh Reading'!N5-'Kwh Reading'!N4)*1000 -> 270 | V2: ='Kwh Reading'!E5-'Kwh Reading'!E4 -> 2021.39 | W2: ='Kwh Reading'!D5-'Kwh Reading'!D4 -> 1554.06 | X2: =('Kwh Reading'!O5-'Kwh Reading'!O4)*1000 -> 240
A3: Maldives at Kuda Huraa | B3: =B2+1 -> 2 | C3: 12 | D3: 2022 | E3: =('Kwh Reading'!T6-'Kwh Reading'!T5)*1000 -> 420 | F3: =('Kwh Reading'!F6-'Kwh Reading'!F5)*1000000 -> 2600 | G3: =('Kwh Reading'!C6-'Kwh Reading'!C5)*1000 -> 260 | H3: =I3+J3+K3 -> 890 | I3: =('Kwh Reading'!J6-'Kwh Reading'!J5)*1000 -> 400 | J3: =('Kwh Reading'!K6-'Kwh Reading'!K5)*1000 -> 270 | K3: =('Kwh Reading'!L6-'Kwh Reading'!L5)*1000 -> 220 | L3: =('Kwh Reading'!R6-'Kwh Reading'!R5)*1000 -> 0 | M3: =('Kwh Reading'!S6-'Kwh Reading'!S5)*1000 -> 0 | N3: =('Kwh Reading'!I6-'Kwh Reading'!I5)*1000 -> 240 | O3: =('Kwh Reading'!B6-'Kwh Reading'!B5)*1000000 -> 1000 | P3: =('Kwh Reading'!M6-'Kwh Reading'!M5)*1000 -> 370 | Q3: =('Kwh Reading'!H6-'Kwh Reading'!H5)*1000000 -> 600 | R3: =('Kwh Reading'!P6-'Kwh Reading'!P5)*1000000 -> 400 | S3: =('Kwh Reading'!G6-'Kwh Reading'!G5)*1000000 -> 500 | T3: =('Kwh Reading'!Q6-'Kwh Reading'!Q5)*1000 -> 290 | U3: =('Kwh Reading'!N6-'Kwh Reading'!N5)*1000 -> 270 | V3: ='Kwh Reading'!E6-'Kwh Reading'!E5 -> 2016.69 | W3: ='Kwh Reading'!D6-'Kwh Reading'!D5 -> 1335.7 | X3: =('Kwh Reading'!O6-'Kwh Reading'!O5)*1000 -> 270
A4: Maldives at Kuda Huraa | B4: =B3+1 -> 3 | C4: 12 | D4: 2022 | E4: =('Kwh Reading'!T7-'Kwh Reading'!T6)*1000 -> 540 | F4: =('Kwh Reading'!F7-'Kwh Reading'!F6)*1000000 -> 2600 | G4: =('Kwh Reading'!C7-'Kwh Reading'!C6)*1000 -> 250 | H4: =I4+J4+K4 -> 890 | I4: =('Kwh Reading'!J7-'Kwh Reading'!J6)*1000 -> 410 | J4: =('Kwh Reading'!K7-'Kwh Reading'!K6)*1000 -> 280 | K4: =('Kwh Reading'!L7-'Kwh Reading'!L6)*1000 -> 200 | L4: =('Kwh Reading'!R7-'Kwh Reading'!R6)*1000 -> 0 | M4: =('Kwh Reading'!S7-'Kwh Reading'!S6)*1000 -> 0 | N4: =('Kwh Reading'!I7-'Kwh Reading'!I6)*1000 -> 280 | O4: =('Kwh Reading'!B7-'Kwh Reading'!B6)*1000000 -> 900 | P4: =('Kwh Reading'!M7-'Kwh Reading'!M6)*1000 -> 340 | Q4: =('Kwh Reading'!H7-'Kwh Reading'!H6)*1000000 -> 400 | R4: =('Kwh Reading'!P7-'Kwh Reading'!P6)*1000000 -> 400 | S4: =('Kwh Reading'!G7-'Kwh Reading'!G6)*1000000 -> 500 | T4: =('Kwh Reading'!Q7-'Kwh Reading'!Q6)*1000 -> 260 | U4: =('Kwh Reading'!N7-'Kwh Reading'!N6)*1000 -> 290 | V4: ='Kwh Reading'!E7-'Kwh Reading'!E6 -> 2040.08 | W4: ='Kwh Reading'!D7-'Kwh Reading'!D6 -> 1304.56 | X4: =('Kwh Reading'!O7-'Kwh Reading'!O6)*1000 -> 240
A5: Maldives at Kuda Huraa | B5: =B4+1 -> 4 | C5: 12 | D5: 2022 | E5: =('Kwh Reading'!T8-'Kwh Reading'!T7)*1000 -> 460 | F5: =('Kwh Reading'!F8-'Kwh Reading'!F7)*1000000 -> 2600 | G5: =('Kwh Reading'!C8-'Kwh Reading'!C7)*1000 -> 270 | H5: =I5+J5+K5 -> 890 | I5: =('Kwh Reading'!J8-'Kwh Reading'!J7)*1000 -> 370 | J5: =('Kwh Reading'!K8-'Kwh Reading'!K7)*1000 -> 320 | K5: =('Kwh Reading'!L8-'Kwh Reading'!L7)*1000 -> 200 | L5: =('Kwh Reading'!R8-'Kwh Reading'!R7)*1000 -> 0 | M5: =('Kwh Reading'!S8-'Kwh Reading'!S7)*1000 -> 0 | N5: =('Kwh Reading'!I8-'Kwh Reading'!I7)*1000 -> 230 | O5: =('Kwh Reading'!B8-'Kwh Reading'!B7)*1000000 -> 900 | P5: =('Kwh Reading'!M8-'Kwh Reading'!M7)*1000 -> 380 | Q5: =('Kwh Reading'!H8-'Kwh Reading'!H7)*1000000 -> 400 | R5: =('Kwh Reading'!P8-'Kwh Reading'!P7)*1000000 -> 400 | S5: =('Kwh Reading'!G8-'Kwh Reading'!G7)*1000000 -> 400 | T5: =('Kwh Reading'!Q8-'Kwh Reading'!Q7)*1000 -> 210 | U5: =('Kwh Reading'!N8-'Kwh Reading'!N7)*1000 -> 240 | V5: ='Kwh Reading'!E8-'Kwh Reading'!E7 -> 1954.88 | W5: ='Kwh Reading'!D8-'Kwh Reading'!D7 -> 1117.84 | X5: =('Kwh Reading'!O8-'Kwh Reading'!O7)*1000 -> 250
A6: Maldives at Kuda Huraa | B6: =B5+1 -> 5 | C6: 12 | D6: 2022 | E6: =('Kwh Reading'!T9-'Kwh Reading'!T8)*1000 -> 370 | F6: =('Kwh Reading'!F9-'Kwh Reading'!F8)*1000000 -> 2600 | G6: =('Kwh Reading'!C9-'Kwh Reading'!C8)*1000 -> 250 | H6: =I6+J6+K6 -> 1010 | I6: =('Kwh Reading'!J9-'Kwh Reading'!J8)*1000 -> 500 | J6: =('Kwh Reading'!K9-'Kwh Reading'!K8)*1000 -> 300 | K6: =('Kwh Reading'!L9-'Kwh Reading'!L8)*1000 -> 210 | L6: =('Kwh Reading'!R9-'Kwh Reading'!R8)*1000 -> 0 | M6: =('Kwh Reading'!S9-'Kwh Reading'!S8)*1000 -> 0 | N6: =('Kwh Reading'!I9-'Kwh Reading'!I8)*1000 -> 260 | O6: =('Kwh Reading'!B9-'Kwh Reading'!B8)*1000000 -> 1100 | P6: =('Kwh Reading'!M9-'Kwh Reading'!M8)*1000 -> 460 | Q6: =('Kwh Reading'!H9-'Kwh Reading'!H8)*1000000 -> 500 | R6: =('Kwh Reading'!P9-'Kwh Reading'!P8)*1000000 -> 500 | S6: =('Kwh Reading'!G9-'Kwh Reading'!G8)*1000000 -> 500 | T6: =('Kwh Reading'!Q9-'Kwh Reading'!Q8)*1000 -> 300 | U6: =('Kwh Reading'!N9-'Kwh Reading'!N8)*1000 -> 330 | V6: ='Kwh Reading'!E9-'Kwh Reading'!E8 -> 2321.44 | W6: ='Kwh Reading'!D9-'Kwh Reading'!D8 -> 1614.52 | X6: =('Kwh Reading'!O9-'Kwh Reading'!O8)*1000 -> 230
A7: Maldives at Kuda Huraa | B7: =B6+1 -> 6 | C7: 12 | D7: 2022 | E7: =('Kwh Reading'!T10-'Kwh Reading'!T9)*1000 -> 340 | F7: =('Kwh Reading'!F10-'Kwh Reading'!F9)*1000000 -> 2500 | G7: =('Kwh Reading'!C10-'Kwh Reading'!C9)*1000 -> 270 | H7: =I7+J7+K7 -> 870 | I7: =('Kwh Reading'!J10-'Kwh Reading'!J9)*1000 -> 340 | J7: =('Kwh Reading'!K10-'Kwh Reading'!K9)*1000 -> 290 | K7: =('Kwh Reading'!L10-'Kwh Reading'!L9)*1000 -> 240 | L7: =('Kwh Reading'!R10-'Kwh Reading'!R9)*1000 -> 0 | M7: =('Kwh Reading'!S10-'Kwh Reading'!S9)*1000 -> 0 | N7: =('Kwh Reading'!I10-'Kwh Reading'!I9)*1000 -> 280 | O7: =('Kwh Reading'!B10-'Kwh Reading'!B9)*1000000 -> 1100 | P7: =('Kwh Reading'!M10-'Kwh Reading'!M9)*1000 -> 380 | Q7: =('Kwh Reading'!H10-'Kwh Reading'!H9)*1000000 -> 600 | R7: =('Kwh Reading'!P10-'Kwh Reading'!P9)*1000000 -> 400 | S7: =('Kwh Reading'!G10-'Kwh Reading'!G9)*1000000 -> 500 | T7: =('Kwh Reading'!Q10-'Kwh Reading'!Q9)*1000 -> 320 | U7: =('Kwh Reading'!N10-'Kwh Reading'!N9)*1000 -> 320 | V7: ='Kwh Reading'!E10-'Kwh Reading'!E9 -> 2413.16 | W7: ='Kwh Reading'!D10-'Kwh Reading'!D9 -> 1637.04 | X7: =('Kwh Reading'!O10-'Kwh Reading'!O9)*1000 -> 200
A8: Maldives at Kuda Huraa | B8: =B7+1 -> 7 | C8: 12 | D8: 2022 | E8: =('Kwh Reading'!T11-'Kwh Reading'!T10)*1000 -> 710 | F8: =('Kwh Reading'!F11-'Kwh Reading'!F10)*1000000 -> 2500 | G8: =('Kwh Reading'!C11-'Kwh Reading'!C10)*1000 -> 270 | H8: =I8+J8+K8 -> 900 | I8: =('Kwh Reading'!J11-'Kwh Reading'!J10)*1000 -> 380 | J8: =('Kwh Reading'!K11-'Kwh Reading'!K10)*1000 -> 290 | K8: =('Kwh Reading'!L11-'Kwh Reading'!L10)*1000 -> 230 | L8: =('Kwh Reading'!R11-'Kwh Reading'!R10)*1000 -> 0 | M8: =('Kwh Reading'!S11-'Kwh Reading'!S10)*1000 -> 0 | N8: =('Kwh Reading'!I11-'Kwh Reading'!I10)*1000 -> 260 | O8: =('Kwh Reading'!B11-'Kwh Reading'!B10)*1000000 -> 1000 | P8: =('Kwh Reading'!M11-'Kwh Reading'!M10)*1000 -> 340 | Q8: =('Kwh Reading'!H11-'Kwh Reading'!H10)*1000000 -> 500 | R8: =('Kwh Reading'!P11-'Kwh Reading'!P10)*1000000 -> 400 | S8: =('Kwh Reading'!G11-'Kwh Reading'!G10)*1000000 -> 400 | T8: =('Kwh Reading'!Q11-'Kwh Reading'!Q10)*1000 -> 250 | U8: =('Kwh Reading'!N11-'Kwh Reading'!N10)*1000 -> 290 | V8: ='Kwh Reading'!E11-'Kwh Reading'!E10 -> 2223.2 | W8: ='Kwh Reading'!D11-'Kwh Reading'!D10 -> 1465.93 | X8: =('Kwh Reading'!O11-'Kwh Reading'!O10)*1000 -> 210
A9: Maldives at Kuda Huraa | B9: =B8+1 -> 8 | C9: 12 | D9: 2022 | E9: =('Kwh Reading'!T12-'Kwh Reading'!T11)*1000 -> 460 | F9: =('Kwh Reading'!F12-'Kwh Reading'!F11)*1000000 -> 2600 | G9: =('Kwh Reading'!C12-'Kwh Reading'!C11)*1000 -> 270 | H9: =I9+J9+K9 -> 920 | I9: =('Kwh Reading'!J12-'Kwh Reading'!J11)*1000 -> 410 | J9: =('Kwh Reading'!K12-'Kwh Reading'!K11)*1000 -> 280 | K9: =('Kwh Reading'!L12-'Kwh Reading'!L11)*1000 -> 230 | L9: =('Kwh Reading'!R12-'Kwh Reading'!R11)*1000 -> 0 | M9: =('Kwh Reading'!S12-'Kwh Reading'!S11)*1000 -> 0 | N9: =('Kwh Reading'!I12-'Kwh Reading'!I11)*1000 -> 290 | O9: =('Kwh Reading'!B12-'Kwh Reading'!B11)*1000000 -> 900 | P9: =('Kwh Reading'!M12-'Kwh Reading'!M11)*1000 -> 390 | Q9: =('Kwh Reading'!H12-'Kwh Reading'!H11)*1000000 -> 500 | R9: =('Kwh Reading'!P12-'Kwh Reading'!P11)*1000000 -> 500 | S9: =('Kwh Reading'!G12-'Kwh Reading'!G11)*1000000 -> 400 | T9: =('Kwh Reading'!Q12-'Kwh Reading'!Q11)*1000 -> 320 | U9: =('Kwh Reading'!N12-'Kwh Reading'!N11)*1000 -> 310 | V9: ='Kwh Reading'!E12-'Kwh Reading'!E11 -> 2533.64 | W9: ='Kwh Reading'!D12-'Kwh Reading'!D11 -> 1634.82 | X9: =('Kwh Reading'!O12-'Kwh Reading'!O11)*1000 -> 210
A10: Maldives at Kuda Huraa | B10: =B9+1 -> 9 | C10: 12 | D10: 2022 | E10: =('Kwh Reading'!T13-'Kwh Reading'!T12)*1000 -> 500 | F10: =('Kwh Reading'!F13-'Kwh Reading'!F12)*1000000 -> 2600 | G10: =('Kwh Reading'!C13-'Kwh Reading'!C12)*1000 -> 270 | H10: =I10+J10+K10 -> 1280 | I10: =('Kwh Reading'!J13-'Kwh Reading'!J12)*1000 -> 680 | J10: =('Kwh Reading'!K13-'Kwh Reading'!K12)*1000 -> 330 | K10: =('Kwh Reading'!L13-'Kwh Reading'!L12)*1000 -> 270 | L10: =('Kwh Reading'!R13-'Kwh Reading'!R12)*1000 -> 0 | M10: =('Kwh Reading'!S13-'Kwh Reading'!S12)*1000 -> 0 | N10: =('Kwh Reading'!I13-'Kwh Reading'!I12)*1000 -> 300 | O10: =('Kwh Reading'!B13-'Kwh Reading'!B12)*1000000 -> 1000 | P10: =('Kwh Reading'!M13-'Kwh Reading'!M12)*1000 -> 360 | Q10: =('Kwh Reading'!H13-'Kwh Reading'!H12)*1000000 -> 500 | R10: =('Kwh Reading'!P13-'Kwh Reading'!P12)*1000000 -> 500 | S10: =('Kwh Reading'!G13-'Kwh Reading'!G12)*1000000 -> 400 | T10: =('Kwh Reading'!Q13-'Kwh Reading'!Q12)*1000 -> 340 | U10: =('Kwh Reading'!N13-'Kwh Reading'!N12)*1000 -> 310 | V10: ='Kwh Reading'!E13-'Kwh Reading'!E12 -> 2553.41 | W10: ='Kwh Reading'!D13-'Kwh Reading'!D12 -> 1566.57 | X10: =('Kwh Reading'!O13-'Kwh Reading'!O12)*1000 -> 260
A11: Maldives at Kuda Huraa | B11: =B10+1 -> 10 | C11: 12 | D11: 2022 | E11: =('Kwh Reading'!T14-'Kwh Reading'!T13)*1000 -> 520 | F11: =('Kwh Reading'!F14-'Kwh Reading'!F13)*1000000 -> 2500 | G11: =('Kwh Reading'!C14-'Kwh Reading'!C13)*1000 -> 260 | H11: =I11+J11+K11 -> 960 | I11: =('Kwh Reading'!J14-'Kwh Reading'!J13)*1000 -> 410 | J11: =('Kwh Reading'!K14-'Kwh Reading'!K13)*1000 -> 260 | K11: =('Kwh Reading'!L14-'Kwh Reading'!L13)*1000 -> 290 | L11: =('Kwh Reading'!R14-'Kwh Reading'!R13)*1000 -> 0 | M11: =('Kwh Reading'!S14-'Kwh Reading'!S13)*1000 -> 0 | N11: =('Kwh Reading'!I14-'Kwh Reading'!I13)*1000 -> 280 | O11: =('Kwh Reading'!B14-'Kwh Reading'!B13)*1000000 -> 900 | P11: =('Kwh Reading'!M14-'Kwh Reading'!M13)*1000 -> 390 | Q11: =('Kwh Reading'!H14-'Kwh Reading'!H13)*1000000 -> 400 | R11: =('Kwh Reading'!P14-'Kwh Reading'!P13)*1000000 -> 400 | S11: =('Kwh Reading'!G14-'Kwh Reading'!G13)*1000000 -> 400 | T11: =('Kwh Reading'!Q14-'Kwh Reading'!Q13)*1000 -> 200 | U11: =('Kwh Reading'!N14-'Kwh Reading'!N13)*1000 -> 310 | V11: ='Kwh Reading'!E14-'Kwh Reading'!E13 -> 2751.11 | W11: ='Kwh Reading'!D14-'Kwh Reading'!D13 -> 1764.39 | X11: =('Kwh Reading'!O14-'Kwh Reading'!O13)*1000 -> 230
A12: Maldives at Kuda Huraa | B12: =B11+1 -> 11 | C12: 12 | D12: 2022 | E12: =('Kwh Reading'!T15-'Kwh Reading'!T14)*1000 -> 510 | F12: =('Kwh Reading'!F15-'Kwh Reading'!F14)*1000000 -> 2400 | G12: =('Kwh Reading'!C15-'Kwh Reading'!C14)*1000 -> 260 | H12: =I12+J12+K12 -> 1080 | I12: =('Kwh Reading'!J15-'Kwh Reading'!J14)*1000 -> 470 | J12: =('Kwh Reading'!K15-'Kwh Reading'!K14)*1000 -> 280 | K12: =('Kwh Reading'!L15-'Kwh Reading'!L14)*1000 -> 330 | L12: =('Kwh Reading'!R15-'Kwh Reading'!R14)*1000 -> 0 | M12: =('Kwh Reading'!S15-'Kwh Reading'!S14)*1000 -> 0 | N12: =('Kwh Reading'!I15-'Kwh Reading'!I14)*1000 -> 300 | O12: =('Kwh Reading'!B15-'Kwh Reading'!B14)*1000000 -> 1000 | P12: =('Kwh Reading'!M15-'Kwh Reading'!M14)*1000 -> 370 | Q12: =('Kwh Reading'!H15-'Kwh Reading'!H14)*1000000 -> 500 | R12: =('Kwh Reading'!P15-'Kwh Reading'!P14)*1000000 -> 500 | S12: =('Kwh Reading'!G15-'Kwh Reading'!G14)*1000000 -> 400 | T12: =('Kwh Reading'!Q15-'Kwh Reading'!Q14)*1000 -> 220 | U12: =('Kwh Reading'!N15-'Kwh Reading'!N14)*1000 -> 370 | V12: ='Kwh Reading'!E15-'Kwh Reading'!E14 -> 2843.58 | W12: ='Kwh Reading'!D15-'Kwh Reading'!D14 -> 1797.98 | X12: =('Kwh Reading'!O15-'Kwh Reading'!O14)*1000 -> 220
A13: Maldives at Kuda Huraa | B13: =B12+1 -> 12 | C13: 12 | D13: 2022 | E13: =('Kwh Reading'!T16-'Kwh Reading'!T15)*1000 -> 470 | F13: =('Kwh Reading'!F16-'Kwh Reading'!F15)*1000000 -> 2500 | G13: =('Kwh Reading'!C16-'Kwh Reading'!C15)*1000 -> 260 | H13: =I13+J13+K13 -> 1280 | I13: =('Kwh Reading'!J16-'Kwh Reading'!J15)*1000 -> 590 | J13: =('Kwh Reading'!K16-'Kwh Reading'!K15)*1000 -> 320 | K13: =('Kwh Reading'!L16-'Kwh Reading'!L15)*1000 -> 370 | L13: =('Kwh Reading'!R16-'Kwh Reading'!R15)*1000 -> 0 | M13: =('Kwh Reading'!S16-'Kwh Reading'!S15)*1000 -> 0 | N13: =('Kwh Reading'!I16-'Kwh Reading'!I15)*1000 -> 190 | O13: =('Kwh Reading'!B16-'Kwh Reading'!B15)*1000000 -> 1000 | P13: =('Kwh Reading'!M16-'Kwh Reading'!M15)*1000 -> 390 | Q13: =('Kwh Reading'!H16-'Kwh Reading'!H15)*1000000 -> 500 | R13: =('Kwh Reading'!P16-'Kwh Reading'!P15)*1000000 -> 500 | S13: =('Kwh Reading'!G16-'Kwh Reading'!G15)*1000000 -> 500 | T13: =('Kwh Reading'!Q16-'Kwh Reading'!Q15)*1000 -> 230 | U13: =('Kwh Reading'!N16-'Kwh Reading'!N15)*1000 -> 330 | V13: ='Kwh Reading'!E16-'Kwh Reading'!E15 -> 2596.35 | W13: ='Kwh Reading'!D16-'Kwh Reading'!D15 -> 1790.42 | X13: =('Kwh Reading'!O16-'Kwh Reading'!O15)*1000 -> 230
A14: Maldives at Kuda Huraa | B14: =B13+1 -> 13 | C14: 12 | D14: 2022 | E14: =('Kwh Reading'!T17-'Kwh Reading'!T16)*1000 -> 480 | F14: =('Kwh Reading'!F17-'Kwh Reading'!F16)*1000000 -> 2500 | G14: =('Kwh Reading'!C17-'Kwh Reading'!C16)*1000 -> 270 | H14: =I14+J14+K14 -> 1250 | I14: =('Kwh Reading'!J17-'Kwh Reading'!J16)*1000 -> 550 | J14: =('Kwh Reading'!K17-'Kwh Reading'!K16)*1000 -> 350 | K14: =('Kwh Reading'!L17-'Kwh Reading'!L16)*1000 -> 350 | L14: =('Kwh Reading'!R17-'Kwh Reading'!R16)*1000 -> 0 | M14: =('Kwh Reading'!S17-'Kwh Reading'!S16)*1000 -> 0 | N14: =('Kwh Reading'!I17-'Kwh Reading'!I16)*1000 -> 370 | O14: =('Kwh Reading'!B17-'Kwh Reading'!B16)*1000000 -> 1000 | P14: =('Kwh Reading'!M17-'Kwh Reading'!M16)*1000 -> 390 | Q14: =('Kwh Reading'!H17-'Kwh Reading'!H16)*1000000 -> 600 | R14: =('Kwh Reading'!P17-'Kwh Reading'!P16)*1000000 -> 500 | S14: =('Kwh Reading'!G17-'Kwh Reading'!G16)*1000000 -> 500 | T14: =('Kwh Reading'!Q17-'Kwh Reading'!Q16)*1000 -> 260 | U14: =('Kwh Reading'!N17-'Kwh Reading'!N16)*1000 -> 300 | V14: ='Kwh Reading'!E17-'Kwh Reading'!E16 -> 2316.28 | W14: ='Kwh Reading'!D17-'Kwh Reading'!D16 -> 1623.26 | X14: =('Kwh Reading'!O17-'Kwh Reading'!O16)*1000 -> 250
... A31: Maldives at Kuda Huraa | B31: =B30+1 -> 30 | C31: 12 | D31: 2022 | E31: =('Kwh Reading'!T34-'Kwh Reading'!T33)*1000 -> 0 | F31: =('Kwh Reading'!F34-'Kwh Reading'!F33)*1000000 -> 0 | G31: =('Kwh Reading'!C34-'Kwh Reading'!C33)*1000 -> 0 | H31: =I31+J31+K31 -> 0 | I31: =('Kwh Reading'!J34-'Kwh Reading'!J33)*1000 -> 0 | J31: =('Kwh Reading'!K34-'Kwh Reading'!K33)*1000 -> 0 | K31: =('Kwh Reading'!L34-'Kwh Reading'!L33)*1000 -> 0 | L31: =('Kwh Reading'!R34-'Kwh Reading'!R33)*1000 -> 0 | M31: =('Kwh Reading'!S34-'Kwh Reading'!S33)*1000 -> 0 | N31: =('Kwh Reading'!I34-'Kwh Reading'!I33)*1000 -> 0 | O31: =('Kwh Reading'!B34-'Kwh Reading'!B33)*1000000 -> 0 | P31: =('Kwh Reading'!M34-'Kwh Reading'!M33)*1000 -> 0 | Q31: =('Kwh Reading'!H34-'Kwh Reading'!H33)*1000000 -> 0 | R31: =('Kwh Reading'!P34-'Kwh Reading'!P33)*1000000 -> 0 | S31: =('Kwh Reading'!G34-'Kwh Reading'!G33)*1000000 -> 0 | T31: =('Kwh Reading'!Q34-'Kwh Reading'!Q33)*1000 -> 0 | U31: =('Kwh Reading'!N34-'Kwh Reading'!N33)*1000 -> 0 | V31: ='Kwh Reading'!E34-'Kwh Reading'!E33 -> 0 | W31: ='Kwh Reading'!D34-'Kwh Reading'!D33 -> 0 | X31: =('Kwh Reading'!O34-'Kwh Reading'!O33)*1000 -> 0
A32: Total | E32: =SUM(E2:E31) -> -669490 | F32: =SUM(F2:F31) -> -3730700 | G32: =SUM(G2:G31) -> -359650 | I32: =SUM(I2:I31) -> -551630 | J32: =SUM(J2:J31) -> -514230 | K32: =SUM(K2:K31) -> -352970 | L32: =SUM(L2:L31) -> -190150 | M32: =SUM(M2:M31) -> -179050 | N32: =SUM(N2:N31) -> -390720 | O32: =SUM(O2:O31) -> -1570200 | P32: =SUM(P2:P31) -> -875560 | ... X32: =SUM(X2:X31) -> -261560

Sheet Kwh Reading
A1: Electric Consumption Record (4pm)
A2: Month | B2: BOH-1/ B&C Block GWH | C2: Pastry MWH | D2: Feeder 401-419 KWH | E2: Feeder 301-319 KWH | F2: Kitchen GWH | G2: Feeder 201-208 GWH | H2: Feeder 113-123 | I2: M - Block /PC MWH | J2: Laundry MWH | M2: Feeder 101-112 MWH | N2: Feeder 217-224 | O2: Spa MWH | P2: Feeder 124-134 | Q2: Feeder 209-216 | R2: STP -1 &2 MWH | S2: STP -3 MWH | T2: Reef Club MWH | V2: Room Nights | W2: Total Guests | X2: Food Covers
J3: A | K3: B | L3: C
A4: 44896 | B4: 1.5702 | C4: 359.65 | D4: 83546.98 | E4: 9566351.4 | F4: 3.7307 | G4: 1.1667 | H4: 1.0916 | I4: 390.72 | J4: 551.63 | K4: 514.23 | L4: 352.97 | M4: 875.56 | N4: 791.51 | O4: 261.56 | P4: 1.0627 | Q4: 769.61 | R4: 190.15 | S4: 179.05 | T4: 669.49
A5: 44897 | B5: 1.5711 | C5: 359.91 | D5: 85101.04 | E5: 9568372.8 | F5: 3.7333 | G5: 1.1671 | H5: 1.0921 | I5: 390.98 | J5: 552.08 | K5: 514.54 | L5: 353.16 | M5: 875.9 | N5: 791.78 | O5: 261.8 | P5: 1.0631 | Q5: 769.87 | R5: 190.15 | S5: 179.05 | T5: 669.97
A6: 44898 | B6: 1.5721 | C6: 360.17 | D6: 86436.74 | E6: 9570389.5 | F6: 3.7359 | G6: 1.1676 | H6: 1.0927 | I6: 391.22 | J6: 552.48 | K6: 514.81 | L6: 353.38 | M6: 876.27 | N6: 792.05 | O6: 262.07 | P6: 1.0635 | Q6: 770.16 | R6: 190.15 | S6: 179.05 | T6: 670.39
A7: 44899 | B7: 1.573 | C7: 360.42 | D7: 87741.3 | E7: 9572429.6 | F7: 3.7385 | G7: 1.1681 | H7: 1.0931 | I7: 391.5 | J7: 552.89 | K7: 515.09 | L7: 353.58 | M7: 876.61 | N7: 792.34 | O7: 262.31 | P7: 1.0639 | Q7: 770.42 | R7: 190.15 | S7: 179.05 | T7: 670.93
A8: 44900 | B8: 1.5739 | C8: 360.69 | D8: 88859.14 | E8: 9574384.4 | F8: 3.7411 | G8: 1.1685 | H8: 1.0935 | I8: 391.73 | J8: 553.26 | K8: 515.41 | L8: 353.78 | M8: 876.99 | N8: 792.58 | O8: 262.56 | P8: 1.0643 | Q8: 770.63 | R8: 190.15 | S8: 179.05 | T8: 671.39
A9: 44901 | B9: 1.575 | C9: 360.94 | D9: 90473.66 | E9: 9576705.9 | F9: 3.7437 | G9: 1.169 | H9: 1.094 | I9: 391.99 | J9: 553.76 | K9: 515.71 | L9: 353.99 | M9: 877.45 | N9: 792.91 | O9: 262.79 | P9: 1.0648 | Q9: 770.93 | R9: 190.15 | S9: 179.05 | T9: 671.76
A10: 44902 | B10: 1.5761 | C10: 361.21 | D10: 92110.7 | E10: 9579119 | F10: 3.7462 | G10: 1.1695 | H10: 1.0946 | I10: 392.27 | J10: 554.1 | K10: 516 | L10: 354.23 | M10: 877.83 | N10: 793.23 | O10: 262.99 | P10: 1.0652 | Q10: 771.25 | R10: 190.15 | S10: 179.05 | T10: 672.1
A11: 44903 | B11: 1.5771 | C11: 361.48 | D11: 93576.63 | E11: 9581342.2 | F11: 3.7487 | G11: 1.1699 | H11: 1.0951 | I11: 392.53 | J11: 554.48 | K11: 516.29 | L11: 354.46 | M11: 878.17 | N11: 793.52 | O11: 263.2 | P11: 1.0656 | Q11: 771.5 | R11: 190.15 | S11: 179.05 | T11: 672.81
A12: 44904 | B12: 1.578 | C12: 361.75 | D12: 95211.45 | E12: 9583875.9 | F12: 3.7513 | G12: 1.1703 | H12: 1.0956 | I12: 392.82 | J12: 554.89 | K12: 516.57 | L12: 354.69 | M12: 878.56 | N12: 793.83 | O12: 263.41 | P12: 1.0661 | Q12: 771.82 | R12: 190.15 | S12: 179.05 | T12: 673.27
A13: 44905 | B13: 1.579 | C13: 362.02 | D13: 96778.02 | E13: 9586429.3 | F13: 3.7539 | G13: 1.1707 | H13: 1.0961 | I13: 393.12 | J13: 555.57 | K13: 516.9 | L13: 354.96 | M13: 878.92 | N13: 794.14 | O13: 263.67 | P13: 1.0666 | Q13: 772.16 | R13: 190.15 | S13: 179.05 | T13: 673.77
A14: 44906 | B14: 1.5799 | C14: 362.28 | D14: 98542.41 | E14: 9589180.4 | F14: 3.7564 | G14: 1.1711 | H14: 1.0965 | I14: 393.4 | J14: 555.98 | K14: 517.16 | L14: 355.25 | M14: 879.31 | N14: 794.45 | O14: 263.9 | P14: 1.067 | Q14: 772.36 | R14: 190.15 | S14: 179.05 | T14: 674.29
A15: 44907 | B15: 1.5809 | C15: 362.54 | D15: 100340.39 | E15: 9592024 | F15: 3.7588 | G15: 1.1715 | H15: 1.097 | I15: 393.7 | J15: 556.45 | K15: 517.44 | L15: 355.58 | M15: 879.68 | N15: 794.82 | O15: 264.12 | P15: 1.0675 | Q15: 772.58 | R15: 190.15 | S15: 179.05 | T15: 674.8
... A27: 44919 | B27: 1.5931 | C27: 365.77 | D27: 119467.4 | E27: 9619992.6 | F27: 3.7885 | G27: 1.1772 | H27: 1.1034 | I27: 397.17 | J27: 562.59 | K27: 521.75 | L27: 359.89 | M27: 884.23 | N27: 798.93 | O27: 266.84 | P27: 1.0726 | Q27: 776.65 | R27: 190.15 | S27: 179.05 | T27: 680.65
A28: 44920
A29: 44921
A30: 44922
A31: 44923
A32: 44924
A33: 44925
A34: 44926 | V34: =SUM(V4:V33) -> 0 | W34: =SUM(W4:W33) -> 0 | X34: =SUM(X4:X33) -> 0
T41: ……..

Sheet Kwh area wise 
A2: Month | B2: Total KWH | C2: Reef Club Kitchen KWH | D2: Main Kitchen KWH | E2: Pastry Kitchen KWH | F2: Laundry KWH | G2: STP KWH | H2: Kuda Huraa Accomodation KWH | I2: Guest Room Beach Pavilion & Beach Bungalow KWH | J2: Guest Room Water Bungalow KWH | K2: Spa KWH | L2: Others KWH
A3: ='Kwh Reading'!A4 -> 44896 | B3: =TOTAL!E2 -> 16850 | C3: =Submeters!E2 -> 480 | D3: =Submeters!F2 -> 2600 | E3: =Submeters!G2 -> 260 | F3: =(Submeters!I2+Submeters!J2+Submeters!K2) -> 950 | G3: =(Submeters!L2+Submeters!M2) -> 0 | H3: =(Submeters!N2+Submeters!O2) -> 1160 | I3: =(Submeters!P2+Submeters!Q2+Submeters!R2+Submeters!S2+Submeters!T2+Submeters!U2) -> 2170 | J3: =(Submeters!V2+Submeters!W2) -> 3575.45 | K3: =Submeters!X2 -> 240 | L3: =B3-C3-D3-E3-F3-G3-H3-I3-J3-K3 -> 5414.55
A4: ='Kwh Reading'!A5 -> 44897 | B4: =TOTAL!E3 -> 17160 | C4: =Submeters!E3 -> 420 | D4: =Submeters!F3 -> 2600 | E4: =Submeters!G3 -> 260 | F4: =(Submeters!I3+Submeters!J3+Submeters!K3) -> 890 | G4: =(Submeters!L3+Submeters!M3) -> 0 | H4: =(Submeters!N3+Submeters!O3) -> 1240 | I4: =(Submeters!P3+Submeters!Q3+Submeters!R3+Submeters!S3+Submeters!T3+Submeters!U3) -> 2430 | J4: =(Submeters!V3+Submeters!W3) -> 3352.39 | K4: =Submeters!X3 -> 270 | L4: =B4-C4-D4-E4-F4-G4-H4-I4-J4-K4 -> 5697.61
A5: ='Kwh Reading'!A6 -> 44898 | B5: =TOTAL!E4 -> 16600 | C5: =Submeters!E4 -> 540 | D5: =Submeters!F4 -> 2600 | E5: =Submeters!G4 -> 250 | F5: =(Submeters!I4+Submeters!J4+Submeters!K4) -> 890 | G5: =(Submeters!L4+Submeters!M4) -> 0 | H5: =(Submeters!N4+Submeters!O4) -> 1180 | I5: =(Submeters!P4+Submeters!Q4+Submeters!R4+Submeters!S4+Submeters!T4+Submeters!U4) -> 2190 | J5: =(Submeters!V4+Submeters!W4) -> 3344.64 | K5: =Submeters!X4 -> 240 | L5: =B5-C5-D5-E5-F5-G5-H5-I5-J5-K5 -> 5365.36
A6: ='Kwh Reading'!A7 -> 44899 | B6: =TOTAL!E5 -> 16520 | C6: =Submeters!E5 -> 460 | D6: =Submeters!F5 -> 2600 | E6: =Submeters!G5 -> 270 | F6: =(Submeters!I5+Submeters!J5+Submeters!K5) -> 890 | G6: =(Submeters!L5+Submeters!M5) -> 0 | H6: =(Submeters!N5+Submeters!O5) -> 1130 | I6: =(Submeters!P5+Submeters!Q5+Submeters!R5+Submeters!S5+Submeters!T5+Submeters!U5) -> 2030 | J6: =(Submeters!V5+Submeters!W5) -> 3072.72 | K6: =Submeters!X5 -> 250 | L6: =B6-C6-D6-E6-F6-G6-H6-I6-J6-K6 -> 5817.28
A7: ='Kwh Reading'!A8 -> 44900 | B7: =TOTAL!E6 -> 18500 | C7: =Submeters!E6 -> 370 | D7: =Submeters!F6 -> 2600 | E7: =Submeters!G6 -> 250 | F7: =(Submeters!I6+Submeters!J6+Submeters!K6) -> 1010 | G7: =(Submeters!L6+Submeters!M6) -> 0 | H7: =(Submeters!N6+Submeters!O6) -> 1360 | I7: =(Submeters!P6+Submeters!Q6+Submeters!R6+Submeters!S6+Submeters!T6+Submeters!U6) -> 2590 | J7: =(Submeters!V6+Submeters!W6) -> 3935.96 | K7: =Submeters!X6 -> 230 | L7: =B7-C7-D7-E7-F7-G7-H7-I7-J7-K7 -> 6154.04
A8: ='Kwh Reading'!A9 -> 44901 | B8: =TOTAL!E7 -> 17510 | C8: =Submeters!E7 -> 340 | D8: =Submeters!F7 -> 2500 | E8: =Submeters!G7 -> 270 | F8: =(Submeters!I7+Submeters!J7+Submeters!K7) -> 870 | G8: =(Submeters!L7+Submeters!M7) -> 0 | H8: =(Submeters!N7+Submeters!O7) -> 1380 | I8: =(Submeters!P7+Submeters!Q7+Submeters!R7+Submeters!S7+Submeters!T7+Submeters!U7) -> 2520 | J8: =(Submeters!V7+Submeters!W7) -> 4050.2 | K8: =Submeters!X7 -> 200 | L8: =B8-C8-D8-E8-F8-G8-H8-I8-J8-K8 -> 5379.8
A9: ='Kwh Reading'!A10 -> 44902 | B9: =TOTAL!E8 -> 16310 | C9: =Submeters!E8 -> 710 | D9: =Submeters!F8 -> 2500 | E9: =Submeters!G8 -> 270 | F9: =(Submeters!I8+Submeters!J8+Submeters!K8) -> 900 | G9: =(Submeters!L8+Submeters!M8) -> 0 | H9: =(Submeters!N8+Submeters!O8) -> 1260 | I9: =(Submeters!P8+Submeters!Q8+Submeters!R8+Submeters!S8+Submeters!T8+Submeters!U8) -> 2180 | J9: =(Submeters!V8+Submeters!W8) -> 3689.13 | K9: =Submeters!X8 -> 210 | L9: =B9-C9-D9-E9-F9-G9-H9-I9-J9-K9 -> 4590.87
A10: ='Kwh Reading'!A11 -> 44903 | B10: =TOTAL!E9 -> 17980 | C10: =Submeters!E9 -> 460 | D10: =Submeters!F9 -> 2600 | E10: =Submeters!G9 -> 270 | F10: =(Submeters!I9+Submeters!J9+Submeters!K9) -> 920 | G10: =(Submeters!L9+Submeters!M9) -> 0 | H10: =(Submeters!N9+Submeters!O9) -> 1190 | I10: =(Submeters!P9+Submeters!Q9+Submeters!R9+Submeters!S9+Submeters!T9+Submeters!U9) -> 2420 | J10: =(Submeters!V9+Submeters!W9) -> 4168.46 | K10: =Submeters!X9 -> 210 | L10: =B10-C10-D10-E10-F10-G10-H10-I10-J10-K10 -> 5741.54
A11: ='Kwh Reading'!A12 -> 44904 | B11: =TOTAL!E10 -> 17700 | C11: =Submeters!E10 -> 500 | D11: =Submeters!F10 -> 2600 | E11: =Submeters!G10 -> 270 | F11: =(Submeters!I10+Submeters!J10+Submeters!K10) -> 1280 | G11: =(Submeters!L10+Submeters!M10) -> 0 | H11: =(Submeters!N10+Submeters!O10) -> 1300 | I11: =(Submeters!P10+Submeters!Q10+Submeters!R10+Submeters!S10+Submeters!T10+Submeters!U10) -> 2410 | J11: =(Submeters!V10+Submeters!W10) -> 4119.98 | K11: =Submeters!X10 -> 260 | L11: =B11-C11-D11-E11-F11-G11-H11-I11-J11-K11 -> 4960.02
A12: ='Kwh Reading'!A13 -> 44905 | B12: =TOTAL!E11 -> 19260 | C12: =Submeters!E11 -> 520 | D12: =Submeters!F11 -> 2500 | E12: =Submeters!G11 -> 260 | F12: =(Submeters!I11+Submeters!J11+Submeters!K11) -> 960 | G12: =(Submeters!L11+Submeters!M11) -> 0 | H12: =(Submeters!N11+Submeters!O11) -> 1180 | I12: =(Submeters!P11+Submeters!Q11+Submeters!R11+Submeters!S11+Submeters!T11+Submeters!U11) -> 2100 | J12: =(Submeters!V11+Submeters!W11) -> 4515.5 | K12: =Submeters!X11 -> 230 | L12: =B12-C12-D12-E12-F12-G12-H12-I12-J12-K12 -> 6994.5
A13: ='Kwh Reading'!A14 -> 44906 | B13: =TOTAL!E12 -> 18670 | C13: =Submeters!E12 -> 510 | D13: =Submeters!F12 -> 2400 | E13: =Submeters!G12 -> 260 | F13: =(Submeters!I12+Submeters!J12+Submeters!K12) -> 1080 | G13: =(Submeters!L12+Submeters!M12) -> 0 | H13: =(Submeters!N12+Submeters!O12) -> 1300 | I13: =(Submeters!P12+Submeters!Q12+Submeters!R12+Submeters!S12+Submeters!T12+Submeters!U12) -> 2360 | J13: =(Submeters!V12+Submeters!W12) -> 4641.56 | K13: =Submeters!X12 -> 220 | L13: =B13-C13-D13-E13-F13-G13-H13-I13-J13-K13 -> 5898.44
A14: ='Kwh Reading'!A15 -> 44907 | B14: =TOTAL!E13 -> 18950 | C14: =Submeters!E13 -> 470 | D14: =Submeters!F13 -> 2500 | E14: =Submeters!G13 -> 260 | F14: =(Submeters!I13+Submeters!J13+Submeters!K13) -> 1280 | G14: =(Submeters!L13+Submeters!M13) -> 0 | H14: =(Submeters!N13+Submeters!O13) -> 1190 | I14: =(Submeters!P13+Submeters!Q13+Submeters!R13+Submeters!S13+Submeters!T13+Submeters!U13) -> 2450 | J14: =(Submeters!V13+Submeters!W13) -> 4386.77 | K14: =Submeters!X13 -> 230 | L14: =B14-C14-D14-E14-F14-G14-H14-I14-J14-K14 -> 6183.23
... A30: ='Kwh Reading'!A31 -> 44923 | B30: =TOTAL!E29 -> 0 | C30: =Submeters!E29 -> 0 | D30: =Submeters!F29 -> 0 | E30: =Submeters!G29 -> 0 | F30: =(Submeters!I29+Submeters!J29+Submeters!K29) -> 0 | G30: =(Submeters!L29+Submeters!M29) -> 0 | H30: =(Submeters!N29+Submeters!O29) -> 0 | I30: =(Submeters!P29+Submeters!Q29+Submeters!R29+Submeters!S29+Submeters!T29+Submeters!U29) -> 0 | J30: =(Submeters!V29+Submeters!W29) -> 0 | K30: =Submeters!X29 -> 0 | L30: =B30-C30-D30-E30-F30-G30-H30-I30-J30-K30 -> 0
A31: ='Kwh Reading'!A32 -> 44924 | B31: =TOTAL!#REF! -> #REF! | C31: =Submeters!E30 -> 0 | D31: =Submeters!F30 -> 0 | E31: =Submeters!G30 -> 0 | F31: =(Submeters!I30+Submeters!J30+Submeters!K30) -> 0 | G31: =(Submeters!L30+Submeters!M30) -> 0 | H31: =(Submeters!N30+Submeters!O30) -> 0 | I31: =(Submeters!P30+Submeters!Q30+Submeters!R30+Submeters!S30+Submeters!T30+Submeters!U30) -> 0 | J31: =(Submeters!V30+Submeters!W30) -> 0 | K31: =Submeters!X30 -> 0 | L31: =B31-C31-D31-E31-F31-G31-H31-I31-J31-K31 -> #REF!
A32: ='Kwh Reading'!A33 -> 44925 | B32: =TOTAL!E31 -> 0 | C32: =Submeters!E31 -> 0 | D32: =Submeters!F31 -> 0 | E32: =Submeters!G31 -> 0 | F32: =(Submeters!I31+Submeters!J31+Submeters!K31) -> 0 | G32: =(Submeters!L31+Submeters!M31) -> 0 | H32: =(Submeters!N31+Submeters!O31) -> 0 | I32: =(Submeters!P31+Submeters!Q31+Submeters!R31+Submeters!S31+Submeters!T31+Submeters!U31) -> 0 | J32: =(Submeters!V31+Submeters!W31) -> 0 | K32: =Submeters!X31 -> 0 | L32: =B32-C32-D32-E32-F32-G32-H32-I32-J32-K32 -> 0
A33: Total kwh | B33: =SUM(B3:B32) -> #REF! | C33: =SUM(C3:C32) -> -669490 | D33: =SUM(D3:D32) -> -3730700 | E33: =SUM(E3:E32) -> -359650 | F33: =SUM(F3:F32) -> -1418830 | G33: =SUM(G3:G32) -> -369200 | H33: =SUM(H3:H32) -> -1960920 | I33: =SUM(I3:I32) -> -5757680 | ... L33: =SUM(L3:L32) -> #REF! | M33: =C33+D33+E33+F33+G33+H33+I33+J33+K33+L33 -> #REF!
A35: Total $ | B35: =TOTAL!F2 -> 0 | C35: =C33*B35 -> 0 | D35: =D33*B35 -> 0 | E35: =E33*B35 -> 0 | F35: =F33*B35 -> 0 | G35: =G33*B35 -> 0 | H35: =H33*B35 -> 0 | I35: =I33*B35 -> 0 | J35: =J33*B35 -> 0 | K35: =K33*B35 -> 0 | L35: =L33*B35 -> #REF! | M35: =C35+D35+E35+F35+G35+H35+I35+J35+K35+L35 -> #REF!

Sheet  Kwh area wise $ 
A2: Month | B2: $ /Per KWH | C2: Total $ | D2: Reef Club $ | E2: Kitchen $ | F2: Pastry $ | G2: Laundry $ | H2: STP $ | I2: Kuda Huraa Accomodation $ | J2: Guest Room Beach Pavilion & Beach Bungalow $ | K2: Guest Room Water Bungalow $ | L2: Spa $ | M2: Others $
A3: ='Kwh Reading'!A4 -> 44896 | B3: =TOTAL!F2 -> 0 | C3: =Submeters!#REF!*' Kwh area wise $ '!B3 -> #REF! | D3: =Submeters!E2*' Kwh area wise $ '!B3 -> 0 | E3: =Submeters!F2*' Kwh area wise $ '!B3 -> 0 | F3: =Submeters!G2*' Kwh area wise $ '!B3 -> 0 | G3: =(Submeters!I2+Submeters!J2+Submeters!K2)*' Kwh area wise $ '!B3 -> 0 | H3: =(Submeters!L2+Submeters!M2)*' Kwh area wise $ '!B3 -> 0 | I3: =(Submeters!N2+Submeters!O2)*' Kwh area wise $ '!B3 -> 0 | J3: =(Submeters!P2+Submeters!Q2+Submeters!R2+Submeters!S2+Submeters!T2+Submeters!U2)*' Kwh area wise $ '!B3 -> 0 | K3: =(Submeters!V2+Submeters!W2)*' Kwh area wise $ '!B3 -> 0 | L3: =Submeters!X2*' Kwh area wise $ '!B3 -> 0 | M3: =Submeters!#REF!*' Kwh area wise $ '!B3 -> #REF!
A4: ='Kwh Reading'!A5 -> 44897 | B4: =TOTAL!F3 -> 0 | C4: =Submeters!#REF!*' Kwh area wise $ '!B4 -> #REF! | D4: =Submeters!E3*' Kwh area wise $ '!B4 -> 0 | E4: =Submeters!F3*' Kwh area wise $ '!B4 -> 0 | F4: =Submeters!G3*' Kwh area wise $ '!B4 -> 0 | G4: =(Submeters!I3+Submeters!J3+Submeters!K3)*' Kwh area wise $ '!B4 -> 0 | H4: =(Submeters!L3+Submeters!M3)*' Kwh area wise $ '!B4 -> 0 | I4: =(Submeters!N3+Submeters!O3)*' Kwh area wise $ '!B4 -> 0 | J4: =(Submeters!P3+Submeters!Q3+Submeters!R3+Submeters!S3+Submeters!T3+Submeters!U3)*' Kwh area wise $ '!B4 -> 0 | K4: =(Submeters!V3+Submeters!W3)*' Kwh area wise $ '!B4 -> 0 | L4: =Submeters!X3*' Kwh area wise $ '!B4 -> 0 | M4: =Submeters!#REF!*' Kwh area wise $ '!B4 -> #REF!
A5: ='Kwh Reading'!A6 -> 44898 | B5: =TOTAL!F4 -> 0 | C5: =Submeters!#REF!*' Kwh area wise $ '!B5 -> #REF! | D5: =Submeters!E4*' Kwh area wise $ '!B5 -> 0 | E5: =Submeters!F4*' Kwh area wise $ '!B5 -> 0 | F5: =Submeters!G4*' Kwh area wise $ '!B5 -> 0 | G5: =(Submeters!I4+Submeters!J4+Submeters!K4)*' Kwh area wise $ '!B5 -> 0 | H5: =(Submeters!L4+Submeters!M4)*' Kwh area wise $ '!B5 -> 0 | I5: =(Submeters!N4+Submeters!O4)*' Kwh area wise $ '!B5 -> 0 | J5: =(Submeters!P4+Submeters!Q4+Submeters!R4+Submeters!S4+Submeters!T4+Submeters!U4)*' Kwh area wise $ '!B5 -> 0 | K5: =(Submeters!V4+Submeters!W4)*' Kwh area wise $ '!B5 -> 0 | L5: =Submeters!X4*' Kwh area wise $ '!B5 -> 0 | M5: =Submeters!#REF!*' Kwh area wise $ '!B5 -> #REF!
A6: ='Kwh Reading'!A7 -> 44899 | B6: =TOTAL!F5 -> 0 | C6: =Submeters!#REF!*' Kwh area wise $ '!B6 -> #REF! | D6: =Submeters!E5*' Kwh area wise $ '!B6 -> 0 | E6: =Submeters!F5*' Kwh area wise $ '!B6 -> 0 | F6: =Submeters!G5*' Kwh area wise $ '!B6 -> 0 | G6: =(Submeters!I5+Submeters!J5+Submeters!K5)*' Kwh area wise $ '!B6 -> 0 | H6: =(Submeters!L5+Submeters!M5)*' Kwh area wise $ '!B6 -> 0 | I6: =(Submeters!N5+Submeters!O5)*' Kwh area wise $ '!B6 -> 0 | J6: =(Submeters!P5+Submeters!Q5+Submeters!R5+Submeters!S5+Submeters!T5+Submeters!U5)*' Kwh area wise $ '!B6 -> 0 | K6: =(Submeters!V5+Submeters!W5)*' Kwh area wise $ '!B6 -> 0 | L6: =Submeters!X5*' Kwh area wise $ '!B6 -> 0 | M6: =Submeters!#REF!*' Kwh area wise $ '!B6 -> #REF!
A7: ='Kwh Reading'!A8 -> 44900 | B7: =TOTAL!F6 -> 0 | C7: =Submeters!#REF!*' Kwh area wise $ '!B7 -> #REF! | D7: =Submeters!E6*' Kwh area wise $ '!B7 -> 0 | E7: =Submeters!F6*' Kwh area wise $ '!B7 -> 0 | F7: =Submeters!G6*' Kwh area wise $ '!B7 -> 0 | G7: =(Submeters!I6+Submeters!J6+Submeters!K6)*' Kwh area wise $ '!B7 -> 0 | H7: =(Submeters!L6+Submeters!M6)*' Kwh area wise $ '!B7 -> 0 | I7: =(Submeters!N6+Submeters!O6)*' Kwh area wise $ '!B7 -> 0 | J7: =(Submeters!P6+Submeters!Q6+Submeters!R6+Submeters!S6+Submeters!T6+Submeters!U6)*' Kwh area wise $ '!B7 -> 0 | K7: =(Submeters!V6+Submeters!W6)*' Kwh area wise $ '!B7 -> 0 | L7: =Submeters!X6*' Kwh area wise $ '!B7 -> 0 | M7: =Submeters!#REF!*' Kwh area wise $ '!B7 -> #REF!
A8: ='Kwh Reading'!A9 -> 44901 | B8: =TOTAL!F7 -> 0 | C8: =Submeters!#REF!*' Kwh area wise $ '!B8 -> #REF! | D8: =Submeters!E7*' Kwh area wise $ '!B8 -> 0 | E8: =Submeters!F7*' Kwh area wise $ '!B8 -> 0 | F8: =Submeters!G7*' Kwh area wise $ '!B8 -> 0 | G8: =(Submeters!I7+Submeters!J7+Submeters!K7)*' Kwh area wise $ '!B8 -> 0 | H8: =(Submeters!L7+Submeters!M7)*' Kwh area wise $ '!B8 -> 0 | I8: =(Submeters!N7+Submeters!O7)*' Kwh area wise $ '!B8 -> 0 | J8: =(Submeters!P7+Submeters!Q7+Submeters!R7+Submeters!S7+Submeters!T7+Submeters!U7)*' Kwh area wise $ '!B8 -> 0 | K8: =(Submeters!V7+Submeters!W7)*' Kwh area wise $ '!B8 -> 0 | L8: =Submeters!X7*' Kwh area wise $ '!B8 -> 0 | M8: =Submeters!#REF!*' Kwh area wise $ '!B8 -> #REF!
A9: ='Kwh Reading'!A10 -> 44902 | B9: =TOTAL!F8 -> 0 | C9: =Submeters!#REF!*' Kwh area wise $ '!B9 -> #REF! | D9: =Submeters!E8*' Kwh area wise $ '!B9 -> 0 | E9: =Submeters!F8*' Kwh area wise $ '!B9 -> 0 | F9: =Submeters!G8*' Kwh area wise $ '!B9 -> 0 | G9: =(Submeters!I8+Submeters!J8+Submeters!K8)*' Kwh area wise $ '!B9 -> 0 | H9: =(Submeters!L8+Submeters!M8)*' Kwh area wise $ '!B9 -> 0 | I9: =(Submeters!N8+Submeters!O8)*' Kwh area wise $ '!B9 -> 0 | J9: =(Submeters!P8+Submeters!Q8+Submeters!R8+Submeters!S8+Submeters!T8+Submeters!U8)*' Kwh area wise $ '!B9 -> 0 | K9: =(Submeters!V8+Submeters!W8)*' Kwh area wise $ '!B9 -> 0 | L9: =Submeters!X8*' Kwh area wise $ '!B9 -> 0 | M9: =Submeters!#REF!*' Kwh area wise $ '!B9 -> #REF!
A10: ='Kwh Reading'!A11 -> 44903 | B10: =TOTAL!F9 -> 0 | C10: =Submeters!#REF!*' Kwh area wise $ '!B10 -> #REF! | D10: =Submeters!E9*' Kwh area wise $ '!B10 -> 0 | E10: =Submeters!F9*' Kwh area wise $ '!B10 -> 0 | F10: =Submeters!G9*' Kwh area wise $ '!B10 -> 0 | G10: =(Submeters!I9+Submeters!J9+Submeters!K9)*' Kwh area wise $ '!B10 -> 0 | H10: =(Submeters!L9+Submeters!M9)*' Kwh area wise $ '!B10 -> 0 | I10: =(Submeters!N9+Submeters!O9)*' Kwh area wise $ '!B10 -> 0 | J10: =(Submeters!P9+Submeters!Q9+Submeters!R9+Submeters!S9+Submeters!T9+Submeters!U9)*' Kwh area wise $ '!B10 -> 0 | K10: =(Submeters!V9+Submeters!W9)*' Kwh area wise $ '!B10 -> 0 | L10: =Submeters!X9*' Kwh area wise $ '!B10 -> 0 | M10: =Submeters!#REF!*' Kwh area wise $ '!B10 -> #REF!
A11: ='Kwh Reading'!A12 -> 44904 | B11: =TOTAL!F10 -> 0 | C11: =Submeters!#REF!*' Kwh area wise $ '!B11 -> #REF! | D11: =Submeters!E10*' Kwh area wise $ '!B11 -> 0 | E11: =Submeters!F10*' Kwh area wise $ '!B11 -> 0 | F11: =Submeters!G10*' Kwh area wise $ '!B11 -> 0 | G11: =(Submeters!I10+Submeters!J10+Submeters!K10)*' Kwh area wise $ '!B11 -> 0 | H11: =(Submeters!L10+Submeters!M10)*' Kwh area wise $ '!B11 -> 0 | I11: =(Submeters!N10+Submeters!O10)*' Kwh area wise $ '!B11 -> 0 | J11: =(Submeters!P10+Submeters!Q10+Submeters!R10+Submeters!S10+Submeters!T10+Submeters!U10)*' Kwh area wise $ '!B11 -> 0 | K11: =(Submeters!V10+Submeters!W10)*' Kwh area wise $ '!B11 -> 0 | L11: =Submeters!X10*' Kwh area wise $ '!B11 -> 0 | M11: =Submeters!#REF!*' Kwh area wise $ '!B11 -> #REF!
A12: ='Kwh Reading'!A13 -> 44905 | B12: =TOTAL!F11 -> 0 | C12: =Submeters!#REF!*' Kwh area wise $ '!B12 -> #REF! | D12: =Submeters!E11*' Kwh area wise $ '!B12 -> 0 | E12: =Submeters!F11*' Kwh area wise $ '!B12 -> 0 | F12: =Submeters!G11*' Kwh area wise $ '!B12 -> 0 | G12: =(Submeters!I11+Submeters!J11+Submeters!K11)*' Kwh area wise $ '!B12 -> 0 | H12: =(Submeters!L11+Submeters!M11)*' Kwh area wise $ '!B12 -> 0 | I12: =(Submeters!N11+Submeters!O11)*' Kwh area wise $ '!B12 -> 0 | J12: =(Submeters!P11+Submeters!Q11+Submeters!R11+Submeters!S11+Submeters!T11+Submeters!U11)*' Kwh area wise $ '!B12 -> 0 | K12: =(Submeters!V11+Submeters!W11)*' Kwh area wise $ '!B12 -> 0 | L12: =Submeters!X11*' Kwh area wise $ '!B12 -> 0 | M12: =Submeters!#REF!*' Kwh area wise $ '!B12 -> #REF!
A13: ='Kwh Reading'!A14 -> 44906 | B13: =TOTAL!F12 -> 0 | C13: =Submeters!#REF!*' Kwh area wise $ '!B13 -> #REF! | D13: =Submeters!E12*' Kwh area wise $ '!B13 -> 0 | E13: =Submeters!F12*' Kwh area wise $ '!B13 -> 0 | F13: =Submeters!G12*' Kwh area wise $ '!B13 -> 0 | G13: =(Submeters!I12+Submeters!J12+Submeters!K12)*' Kwh area wise $ '!B13 -> 0 | H13: =(Submeters!L12+Submeters!M12)*' Kwh area wise $ '!B13 -> 0 | I13: =(Submeters!N12+Submeters!O12)*' Kwh area wise $ '!B13 -> 0 | J13: =(Submeters!P12+Submeters!Q12+Submeters!R12+Submeters!S12+Submeters!T12+Submeters!U12)*' Kwh area wise $ '!B13 -> 0 | K13: =(Submeters!V12+Submeters!W12)*' Kwh area wise $ '!B13 -> 0 | L13: =Submeters!X12*' Kwh area wise $ '!B13 -> 0 | M13: =Submeters!#REF!*' Kwh area wise $ '!B13 -> #REF!
A14: ='Kwh Reading'!A15 -> 44907 | B14: =TOTAL!F13 -> 0 | C14: =Submeters!#REF!*' Kwh area wise $ '!B14 -> #REF! | D14: =Submeters!E13*' Kwh area wise $ '!B14 -> 0 | E14: =Submeters!F13*' Kwh area wise $ '!B14 -> 0 | F14: =Submeters!G13*' Kwh area wise $ '!B14 -> 0 | G14: =(Submeters!I13+Submeters!J13+Submeters!K13)*' Kwh area wise $ '!B14 -> 0 | H14: =(Submeters!L13+Submeters!M13)*' Kwh area wise $ '!B14 -> 0 | I14: =(Submeters!N13+Submeters!O13)*' Kwh area wise $ '!B14 -> 0 | J14: =(Submeters!P13+Submeters!Q13+Submeters!R13+Submeters!S13+Submeters!T13+Submeters!U13)*' Kwh area wise $ '!B14 -> 0 | K14: =(Submeters!V13+Submeters!W13)*' Kwh area wise $ '!B14 -> 0 | L14: =Submeters!X13*' Kwh area wise $ '!B14 -> 0 | M14: =Submeters!#REF!*' Kwh area wise $ '!B14 -> #REF!
... A32: ='Kwh Reading'!A33 -> 44925 | B32: =TOTAL!F31 -> 0 | C32: =Submeters!#REF!*' Kwh area wise $ '!B32 -> #REF! | D32: =Submeters!E31*' Kwh area wise $ '!B32 -> 0 | E32: =Submeters!F31*' Kwh area wise $ '!B32 -> 0 | F32: =Submeters!G31*' Kwh area wise $ '!B32 -> 0 | G32: =(Submeters!I31+Submeters!J31+Submeters!K31)*' Kwh area wise $ '!B32 -> 0 | H32: =(Submeters!L31+Submeters!M31)*' Kwh area wise $ '!B32 -> 0 | I32: =(Submeters!N31+Submeters!O31)*' Kwh area wise $ '!B32 -> 0 | J32: =(Submeters!P31+Submeters!Q31+Submeters!R31+Submeters!S31+Submeters!T31+Submeters!U31)*' Kwh area wise $ '!B32 -> 0 | K32: =(Submeters!V31+Submeters!W31)*' Kwh area wise $ '!B32 -> 0 | L32: =Submeters!X31*' Kwh area wise $ '!B32 -> 0 | M32: =Submeters!#REF!*' Kwh area wise $ '!B32 -> #REF!
A33: Total | C33: =SUM(C3:C32) -> #REF! | D33: =SUM(D3:D32) -> 0 | E33: =SUM(E3:E32) -> 0 | F33: =SUM(F3:F32) -> 0 | G33: =SUM(G3:G32) -> 0 | H33: =SUM(H3:H32) -> 0 | I33: =SUM(I3:I32) -> 0 | J33: =SUM(J3:J32) -> 0 | ... M33: =SUM(M3:M32) -> #REF! | N33: =D33+E33+F33+G33+H33+I33+J33+K33+L33+M33 -> #REF!

Sheet Water Reading
B1: Meter 1 | C1: Meter 2 | D1: Meter 6 | E1: Meter 8 | F1: Meter 7 | G1: Meter 9 | H1: Meter 3 | I1: Meter 5 | J1: Meter 10 | K1: Meter 13 | L1: Meter 16 | M1: Meter 17 | N1: Meter 15 | O1: Meter 14 | P1: Meter 4 | Q1: Meter 11 | R1: Meter 12
A2: Date | B2: Main Meter 1 | C2: Main Meter 2 | D2: Beach Bunglow | E2: Kuda Huraa staff | F2: Bodu hura staff | G2: Laundry | H2: Water Bunglow | I2: Main Kitchen | J2: Second stage | K2: Supply jetty | L2: Staff housing A | M2: Staff housing B | N2: Spa | O2: Staff jetty | P2: Main pool | Q2: Reef club pool | R2: Reef club kitchen
A3: 44896 | B3: 23072 | C3: 33759 | D3: 296508 | E3: 283600 | F3: 67394 | G3: 123848 | H3: 62092 | I3: 79804 | J3: 23871 | K3: 1024 | L3: 19485 | M3: 28561 | N3: 9047 | O3: 2427 | P3: 32676 | Q3: 2220 | R3: 860
A4: 44897 | B4: 23166 | C4: 33949 | D4: 296620 | E4: 283687 | F4: 67394 | G4: 123871 | H4: 62092 | I4: 79827 | J4: 23877 | K4: 1024 | L4: 19488 | M4: 28567 | N4: 9048 | O4: 2428 | P4: 32676 | Q4: 2220 | R4: 864
A5: 44898 | B5: 23253 | C5: 34126 | D5: 296726 | E5: 283766 | F5: 67395 | G5: 123894 | H5: 62092 | I5: 79834 | J5: 23882 | K5: 1024 | L5: 19492 | M5: 28572 | N5: 9050 | O5: 2429 | P5: 32680 | Q5: 2221 | R5: 867
A6: 44899 | B6: 23345 | C6: 34356 | D6: 296909 | E6: 283834 | F6: 67395 | G6: 123915 | H6: 62092 | I6: 79837 | J6: 23888 | K6: 1024 | L6: 19495 | M6: 28577 | N6: 9052 | O6: 2429 | P6: 32690 | Q6: 2226 | R6: 873
A7: 44900 | B7: 23473 | C7: 34657 | D7: 297125 | E7: 283913 | F7: 67396 | G7: 123941 | H7: 62092 | I7: 79854 | J7: 23894 | K7: 1024 | L7: 19498 | M7: 28584 | N7: 9053 | O7: 2431 | P7: 32708 | Q7: 2227 | R7: 876
A8: 44901 | B8: 23554 | C8: 34868 | D8: 297273 | E8: 283982 | F8: 67397 | G8: 123959 | H8: 62092 | I8: 79864 | J8: 23900 | K8: 1024 | L8: 19501 | M8: 28589 | N8: 9054 | O8: 2432 | P8: 32710 | Q8: 2228 | R8: 880
A9: 44902 | B9: 23642 | C9: 35085 | D9: 297420 | E9: 284055 | F9: 67398 | G9: 123980 | H9: 62092 | I9: 79883 | J9: 23905 | K9: 1024 | L9: 19504 | M9: 28596 | N9: 9055 | O9: 2436 | P9: 32716 | Q9: 2230 | R9: 884
A10: 44903 | B10: 23751 | C10: 35271 | D10: 297560 | E10: 284127 | F10: 67398 | G10: 124004 | H10: 18 | I10: 79898 | J10: 23911 | K10: 1024 | L10: 19511 | M10: 28602 | N10: 9056 | O10: 2437 | P10: 32737 | Q10: 2234 | R10: 887
A11: 44904 | B11: 23837 | C11: 35474 | D11: 297688 | E11: 284202 | F11: 67399 | G11: 124026 | H11: 31 | I11: 79919 | J11: 23916 | K11: 1024 | L11: 19516 | M11: 28607 | N11: 9057 | O11: 2438 | P11: 32751 | Q11: 2234 | R11: 890
A12: 44905 | B12: 23928 | C12: 35696 | D12: 297831 | E12: 284283 | F12: 67400 | G12: 124059 | H12: 46 | I12: 79929 | J12: 23922 | K12: 1024 | L12: 19522 | M12: 28613 | N12: 9058 | O12: 2440 | P12: 32756 | Q12: 2238 | R12: 894
A13: 44906 | B13: 24005 | C13: 35892 | D13: 297949 | E13: 284365 | F13: 67401 | G13: 124078 | H13: 64 | I13: 79933 | J13: 23927 | K13: 1024 | L13: 19527 | M13: 28620 | N13: 9059 | O13: 2441 | P13: 32756 | Q13: 2239 | R13: 899
A14: 44907 | B14: 24100 | C14: 36125 | D14: 298080 | E14: 284453 | F14: 67401 | G14: 124100 | H14: 83 | I14: 79953 | J14: 23933 | K14: 1024 | L14: 19533 | M14: 28626 | N14: 9060 | O14: 2443 | P14: 32770 | Q14: 2245 | R14: 903
... A22: 44915 | B22: 24782 | C22: 38124 | D22: 299408 | E22: 285103 | F22: 67408 | G22: 124300 | H22: 233 | I22: 80043 | J22: 23983 | K22: 1024 | L22: 19561 | M22: 28681 | N22: 9072 | O22: 2457 | P22: 32827 | Q22: 2325 | R22: 932
A23: 44916 | B23: 24921 | C23: 38285 | D23: 299547 | E23: 285176 | F23: 67409 | G23: 124329 | H23: 252 | I23: 80045 | J23: 23989 | K23: 1024 | L23: 19564 | M23: 28681 | N23: 9072 | O23: 2458 | P23: 32829 | Q23: 2327 | R23: 939 | S23: .
A24: 44917 | B24: 25017 | C24: 38478 | D24: 299660 | E24: 285253 | F24: 67410 | G24: 124354 | H24: 275 | I24: 80059 | J24: 23995 | K24: 1024 | L24: 19567 | M24: 28687 | N24: 9074 | O24: 2460 | P24: 32834 | Q24: 2327 | R24: 944
A25: 44918 | B25: 25128 | C25: 38695 | D25: 299811 | E25: 285330 | F25: 67411 | G25: 124379 | H25: 296 | I25: 80079 | J25: 24000 | K25: 1024 | L25: 19570 | M25: 28694 | N25: 907 | O25: 2463 | P25: 32848 | Q25: 2333 | R25: 950
A26: 44919 | B26: 25283 | C26: 38892 | D26: 299966 | E26: 285417 | F26: 67411 | G26: 124409 | H26: 324 | I26: 80083 | J26: 24008 | K26: 1024 | L26: 19573 | M26: 28700 | N26: 9076 | O26: 2465 | P26: 32848 | Q26: 2336 | R26: 956
A27: 44920
A28: 44921
A29: 44922
A30: 44923
A31: 44924
A32: 44925
A33: 44926

Sheet Water consumption
A2: Date | B2: RO production (Ro 1 : 4) | C2: Total Consumption M3 (Meter 1 : 2) | E2: Water Bunglow | G2: Beach bunglow | I2: Main Pool | K2: Main kitchen | M2: Reef club kitchen | O2: Reef club pool | Q2: Bodu Huraa staff | S2: Kuda Huraa staff | U2: Laundry | W2: Second stage | Y2: Total
C3: M3 | D3: % of Total production | E3: M3 | F3: % | G3: M3 | H3: % | I3: M3 | J3: % | K3: M3 | L3: % | M3: M3 | N3: % | O3: M3 | P3: % | Q3: M3 | R3: % | S3: M3 | T3: % | U3: M3 | V3: % | W3: M3 | X3: % | Y3: M3 | Z3: %
A4: ='Water Reading'!A3 -> 44896 | B4: =TOTAL!I2 -> 251 | C4: =('Water Reading'!B4-'Water Reading'!B3)+('Water Reading'!C4-'Water Reading'!C3) -> 284 | D4: =C4/B4 -> 1.1314741 | E4: ='Water Reading'!H4-'Water Reading'!H3 -> 0 | F4: =E4/C4 -> 0 | G4: =('Water Reading'!D4-'Water Reading'!D3)-('Water Reading'!R4-'Water Reading'!R3)-('Water Reading'!Q4-'Water Reading'!Q3) -> 108 | H4: =G4/C4 -> 0.38028169 | I4: ='Water Reading'!P4-'Water Reading'!P3 -> 0 | J4: =I4/C4 -> 0 | K4: =('Water Reading'!I4-'Water Reading'!I3)-('Water Reading'!P4-'Water Reading'!P3) -> 23 | L4: =K4/C4 -> 0.080985915 | M4: ='Water Reading'!R4-'Water Reading'!R3 -> 4 | N4: =M4/C4 -> 0.014084507 | O4: ='Water Reading'!Q4-'Water Reading'!Q3 -> 0 | P4: =O4/C4 -> 0 | Q4: ='Water Reading'!F4-'Water Reading'!F3 -> 0 | R4: =Q4/C4 -> 0 | S4: ='Water Reading'!E4-'Water Reading'!E3 -> 87 | T4: =S4/C4 -> 0.30633803 | U4: ='Water Reading'!G4-'Water Reading'!G3 -> 23 | V4: =U4/C4 -> 0.080985915 | W4: ='Water Reading'!J4-'Water Reading'!J3 -> 6 | X4: =W4/C4 -> 0.021126761 | Y4: =E4+I4+K4+M4+O4+G4+Q4+S4+U4+W4 -> 251 | Z4: =Y4/B4 -> 1
A5: ='Water Reading'!A4 -> 44897 | B5: =TOTAL!I3 -> 221 | C5: =('Water Reading'!B5-'Water Reading'!B4)+('Water Reading'!C5-'Water Reading'!C4) -> 264 | D5: =C5/B5 -> 1.1945701 | E5: ='Water Reading'!H5-'Water Reading'!H4 -> 0 | F5: =E5/C5 -> 0 | G5: =('Water Reading'!D5-'Water Reading'!D4)-('Water Reading'!R5-'Water Reading'!R4)-('Water Reading'!Q5-'Water Reading'!Q4) -> 102 | H5: =G5/C5 -> 0.38636364 | I5: ='Water Reading'!P5-'Water Reading'!P4 -> 4 | J5: =I5/C5 -> 0.015151515 | K5: =('Water Reading'!I5-'Water Reading'!I4)-('Water Reading'!P5-'Water Reading'!P4) -> 3 | L5: =K5/C5 -> 0.011363636 | M5: ='Water Reading'!R5-'Water Reading'!R4 -> 3 | N5: =M5/C5 -> 0.011363636 | O5: ='Water Reading'!Q5-'Water Reading'!Q4 -> 1 | P5: =O5/C5 -> 0.0037878788 | Q5: ='Water Reading'!F5-'Water Reading'!F4 -> 1 | R5: =Q5/C5 -> 0.0037878788 | S5: ='Water Reading'!E5-'Water Reading'!E4 -> 79 | T5: =S5/C5 -> 0.29924242 | U5: ='Water Reading'!G5-'Water Reading'!G4 -> 23 | V5: =U5/C5 -> 0.087121212 | W5: ='Water Reading'!J5-'Water Reading'!J4 -> 5 | X5: =W5/C5 -> 0.018939394 | Y5: =E5+I5+K5+M5+O5+G5+Q5+S5+U5+W5 -> 221 | Z5: =Y5/B5 -> 1
A6: ='Water Reading'!A5 -> 44898 | B6: =TOTAL!I4 -> 281 | C6: =('Water Reading'!B6-'Water Reading'!B5)+('Water Reading'!C6-'Water Reading'!C5) -> 322 | D6: =C6/B6 -> 1.1459075 | E6: ='Water Reading'!H6-'Water Reading'!H5 -> 0 | F6: =E6/C6 -> 0 | G6: =('Water Reading'!D6-'Water Reading'!D5)-('Water Reading'!R6-'Water Reading'!R5)-('Water Reading'!Q6-'Water Reading'!Q5) -> 172 | H6: =G6/C6 -> 0.53416149 | I6: ='Water Reading'!P6-'Water Reading'!P5 -> 10 | J6: =I6/C6 -> 0.031055901 | K6: =('Water Reading'!I6-'Water Reading'!I5)-('Water Reading'!P6-'Water Reading'!P5) -> -7 | L6: =K6/C6 -> -0.02173913 | M6: ='Water Reading'!R6-'Water Reading'!R5 -> 6 | N6: =M6/C6 -> 0.01863354 | O6: ='Water Reading'!Q6-'Water Reading'!Q5 -> 5 | P6: =O6/C6 -> 0.01552795 | Q6: ='Water Reading'!F6-'Water Reading'!F5 -> 0 | R6: =Q6/C6 -> 0 | S6: ='Water Reading'!E6-'Water Reading'!E5 -> 68 | T6: =S6/C6 -> 0.21118012 | U6: ='Water Reading'!G6-'Water Reading'!G5 -> 21 | V6: =U6/C6 -> 0.065217391 | W6: ='Water Reading'!J6-'Water Reading'!J5 -> 6 | X6: =W6/C6 -> 0.01863354 | Y6: =E6+I6+K6+M6+O6+G6+Q6+S6+U6+W6 -> 281 | Z6: =Y6/B6 -> 1
A7: ='Water Reading'!A6 -> 44899 | B7: =TOTAL!I5 -> 345 | C7: =('Water Reading'!B7-'Water Reading'!B6)+('Water Reading'!C7-'Water Reading'!C6) -> 429 | D7: =C7/B7 -> 1.2434783 | E7: ='Water Reading'!H7-'Water Reading'!H6 -> 0 | F7: =E7/C7 -> 0 | G7: =('Water Reading'!D7-'Water Reading'!D6)-('Water Reading'!R7-'Water Reading'!R6)-('Water Reading'!Q7-'Water Reading'!Q6) -> 212 | H7: =G7/C7 -> 0.49417249 | I7: ='Water Reading'!P7-'Water Reading'!P6 -> 18 | J7: =I7/C7 -> 0.041958042 | K7: =('Water Reading'!I7-'Water Reading'!I6)-('Water Reading'!P7-'Water Reading'!P6) -> -1 | L7: =K7/C7 -> -0.0023310023 | M7: ='Water Reading'!R7-'Water Reading'!R6 -> 3 | N7: =M7/C7 -> 0.006993007 | O7: ='Water Reading'!Q7-'Water Reading'!Q6 -> 1 | P7: =O7/C7 -> 0.0023310023 | Q7: ='Water Reading'!F7-'Water Reading'!F6 -> 1 | R7: =Q7/C7 -> 0.0023310023 | S7: ='Water Reading'!E7-'Water Reading'!E6 -> 79 | T7: =S7/C7 -> 0.18414918 | U7: ='Water Reading'!G7-'Water Reading'!G6 -> 26 | V7: =U7/C7 -> 0.060606061 | W7: ='Water Reading'!J7-'Water Reading'!J6 -> 6 | X7: =W7/C7 -> 0.013986014 | Y7: =E7+I7+K7+M7+O7+G7+Q7+S7+U7+W7 -> 345 | Z7: =Y7/B7 -> 1
A8: ='Water Reading'!A7 -> 44900 | B8: =TOTAL!I6 -> 252 | C8: =('Water Reading'!B8-'Water Reading'!B7)+('Water Reading'!C8-'Water Reading'!C7) -> 292 | D8: =C8/B8 -> 1.1587302 | E8: ='Water Reading'!H8-'Water Reading'!H7 -> 0 | F8: =E8/C8 -> 0 | G8: =('Water Reading'!D8-'Water Reading'!D7)-('Water Reading'!R8-'Water Reading'!R7)-('Water Reading'!Q8-'Water Reading'!Q7) -> 143 | H8: =G8/C8 -> 0.48972603 | I8: ='Water Reading'!P8-'Water Reading'!P7 -> 2 | J8: =I8/C8 -> 0.0068493151 | K8: =('Water Reading'!I8-'Water Reading'!I7)-('Water Reading'!P8-'Water Reading'!P7) -> 8 | L8: =K8/C8 -> 0.02739726 | M8: ='Water Reading'!R8-'Water Reading'!R7 -> 4 | N8: =M8/C8 -> 0.01369863 | O8: ='Water Reading'!Q8-'Water Reading'!Q7 -> 1 | P8: =O8/C8 -> 0.0034246575 | Q8: ='Water Reading'!F8-'Water Reading'!F7 -> 1 | R8: =Q8/C8 -> 0.0034246575 | S8: ='Water Reading'!E8-'Water Reading'!E7 -> 69 | T8: =S8/C8 -> 0.23630137 | U8: ='Water Reading'!G8-'Water Reading'!G7 -> 18 | V8: =U8/C8 -> 0.061643836 | W8: ='Water Reading'!J8-'Water Reading'!J7 -> 6 | X8: =W8/C8 -> 0.020547945 | Y8: =E8+I8+K8+M8+O8+G8+Q8+S8+U8+W8 -> 252 | Z8: =Y8/B8 -> 1
A9: ='Water Reading'!A8 -> 44901 | B9: =TOTAL!I7 -> 266 | C9: =('Water Reading'!B9-'Water Reading'!B8)+('Water Reading'!C9-'Water Reading'!C8) -> 305 | D9: =C9/B9 -> 1.1466165 | E9: ='Water Reading'!H9-'Water Reading'!H8 -> 0 | F9: =E9/C9 -> 0 | G9: =('Water Reading'!D9-'Water Reading'!D8)-('Water Reading'!R9-'Water Reading'!R8)-('Water Reading'!Q9-'Water Reading'!Q8) -> 141 | H9: =G9/C9 -> 0.46229508 | I9: ='Water Reading'!P9-'Water Reading'!P8 -> 6 | J9: =I9/C9 -> 0.019672131 | K9: =('Water Reading'!I9-'Water Reading'!I8)-('Water Reading'!P9-'Water Reading'!P8) -> 13 | L9: =K9/C9 -> 0.042622951 | M9: ='Water Reading'!R9-'Water Reading'!R8 -> 4 | N9: =M9/C9 -> 0.013114754 | O9: ='Water Reading'!Q9-'Water Reading'!Q8 -> 2 | P9: =O9/C9 -> 0.006557377 | Q9: ='Water Reading'!F9-'Water Reading'!F8 -> 1 | R9: =Q9/C9 -> 0.0032786885 | S9: ='Water Reading'!E9-'Water Reading'!E8 -> 73 | T9: =S9/C9 -> 0.23934426 | U9: ='Water Reading'!G9-'Water Reading'!G8 -> 21 | V9: =U9/C9 -> 0.068852459 | W9: ='Water Reading'!J9-'Water Reading'!J8 -> 5 | X9: =W9/C9 -> 0.016393443 | Y9: =E9+I9+K9+M9+O9+G9+Q9+S9+U9+W9 -> 266 | Z9: =Y9/B9 -> 1
A10: ='Water Reading'!A9 -> 44902 | B10: =TOTAL!I8 -> 275 | C10: =('Water Reading'!B10-'Water Reading'!B9)+('Water Reading'!C10-'Water Reading'!C9) -> 295 | D10: =C10/B10 -> 1.0727273 | E10: 18 | F10: 0.061016949 | G10: =('Water Reading'!D10-'Water Reading'!D9)-('Water Reading'!R10-'Water Reading'!R9)-('Water Reading'!Q10-'Water Reading'!Q9) -> 133 | H10: =G10/C10 -> 0.45084746 | I10: ='Water Reading'!P10-'Water Reading'!P9 -> 21 | J10: =I10/C10 -> 0.071186441 | K10: =('Water Reading'!I10-'Water Reading'!I9)-('Water Reading'!P10-'Water Reading'!P9) -> -6 | L10: =K10/C10 -> -0.020338983 | M10: ='Water Reading'!R10-'Water Reading'!R9 -> 3 | N10: =M10/C10 -> 0.010169492 | O10: ='Water Reading'!Q10-'Water Reading'!Q9 -> 4 | P10: =O10/C10 -> 0.013559322 | Q10: ='Water Reading'!F10-'Water Reading'!F9 -> 0 | R10: =Q10/C10 -> 0 | S10: ='Water Reading'!E10-'Water Reading'!E9 -> 72 | T10: =S10/C10 -> 0.2440678 | U10: ='Water Reading'!G10-'Water Reading'!G9 -> 24 | V10: =U10/C10 -> 0.081355932 | W10: ='Water Reading'!J10-'Water Reading'!J9 -> 6 | X10: =W10/C10 -> 0.020338983 | Y10: =E10+I10+K10+M10+O10+G10+Q10+S10+U10+W10 -> 275 | Z10: =Y10/B10 -> 1
A11: ='Water Reading'!A10 -> 44903 | B11: =TOTAL!I9 -> 265 | C11: =('Water Reading'!B11-'Water Reading'!B10)+('Water Reading'!C11-'Water Reading'!C10) -> 289 | D11: =C11/B11 -> 1.090566 | E11: ='Water Reading'!H11-'Water Reading'!H10 -> 13 | F11: =E11/C11 -> 0.044982699 | G11: =('Water Reading'!D11-'Water Reading'!D10)-('Water Reading'!R11-'Water Reading'!R10)-('Water Reading'!Q11-'Water Reading'!Q10) -> 125 | H11: =G11/C11 -> 0.43252595 | I11: ='Water Reading'!P11-'Water Reading'!P10 -> 14 | J11: =I11/C11 -> 0.048442907 | K11: =('Water Reading'!I11-'Water Reading'!I10)-('Water Reading'!P11-'Water Reading'!P10) -> 7 | L11: =K11/C11 -> 0.024221453 | M11: ='Water Reading'!R11-'Water Reading'!R10 -> 3 | N11: =M11/C11 -> 0.010380623 | O11: ='Water Reading'!Q11-'Water Reading'!Q10 -> 0 | P11: =O11/C11 -> 0 | Q11: ='Water Reading'!F11-'Water Reading'!F10 -> 1 | R11: =Q11/C11 -> 0.0034602076 | S11: ='Water Reading'!E11-'Water Reading'!E10 -> 75 | T11: =S11/C11 -> 0.25951557 | U11: ='Water Reading'!G11-'Water Reading'!G10 -> 22 | V11: =U11/C11 -> 0.076124567 | W11: ='Water Reading'!J11-'Water Reading'!J10 -> 5 | X11: =W11/C11 -> 0.017301038 | Y11: =E11+I11+K11+M11+O11+G11+Q11+S11+U11+W11 -> 265 | Z11: =Y11/B11 -> 1
A12: ='Water Reading'!A11 -> 44904 | B12: =TOTAL!I10 -> 289 | C12: =('Water Reading'!B12-'Water Reading'!B11)+('Water Reading'!C12-'Water Reading'!C11) -> 313 | D12: =C12/B12 -> 1.083045 | E12: ='Water Reading'!H12-'Water Reading'!H11 -> 15 | F12: =E12/C12 -> 0.047923323 | G12: =('Water Reading'!D12-'Water Reading'!D11)-('Water Reading'!R12-'Water Reading'!R11)-('Water Reading'!Q12-'Water Reading'!Q11) -> 135 | H12: =G12/C12 -> 0.4313099 | I12: ='Water Reading'!P12-'Water Reading'!P11 -> 5 | J12: =I12/C12 -> 0.015974441 | K12: =('Water Reading'!I12-'Water Reading'!I11)-('Water Reading'!P12-'Water Reading'!P11) -> 5 | L12: =K12/C12 -> 0.015974441 | M12: ='Water Reading'!R12-'Water Reading'!R11 -> 4 | N12: =M12/C12 -> 0.012779553 | O12: ='Water Reading'!Q12-'Water Reading'!Q11 -> 4 | P12: =O12/C12 -> 0.012779553 | Q12: ='Water Reading'!F12-'Water Reading'!F11 -> 1 | R12: =Q12/C12 -> 0.0031948882 | S12: ='Water Reading'!E12-'Water Reading'!E11 -> 81 | T12: =S12/C12 -> 0.25878594 | U12: ='Water Reading'!G12-'Water Reading'!G11 -> 33 | V12: =U12/C12 -> 0.10543131 | W12: ='Water Reading'!J12-'Water Reading'!J11 -> 6 | X12: =W12/C12 -> 0.019169329 | Y12: =E12+I12+K12+M12+O12+G12+Q12+S12+U12+W12 -> 289 | Z12: =Y12/B12 -> 1
A13: ='Water Reading'!A12 -> 44905 | B13: =TOTAL!I11 -> 247 | C13: =('Water Reading'!B13-'Water Reading'!B12)+('Water Reading'!C13-'Water Reading'!C12) -> 273 | D13: =C13/B13 -> 1.1052632 | E13: ='Water Reading'!H13-'Water Reading'!H12 -> 18 | F13: =E13/C13 -> 0.065934066 | G13: =('Water Reading'!D13-'Water Reading'!D12)-('Water Reading'!R13-'Water Reading'!R12)-('Water Reading'!Q13-'Water Reading'!Q12) -> 112 | H13: =G13/C13 -> 0.41025641 | I13: ='Water Reading'!P13-'Water Reading'!P12 -> 0 | J13: =I13/C13 -> 0 | K13: =('Water Reading'!I13-'Water Reading'!I12)-('Water Reading'!P13-'Water Reading'!P12) -> 4 | L13: =K13/C13 -> 0.014652015 | M13: ='Water Reading'!R13-'Water Reading'!R12 -> 5 | N13: =M13/C13 -> 0.018315018 | O13: ='Water Reading'!Q13-'Water Reading'!Q12 -> 1 | P13: =O13/C13 -> 0.0036630037 | Q13: ='Water Reading'!F13-'Water Reading'!F12 -> 1 | R13: =Q13/C13 -> 0.0036630037 | S13: ='Water Reading'!E13-'Water Reading'!E12 -> 82 | T13: =S13/C13 -> 0.3003663 | U13: ='Water Reading'!G13-'Water Reading'!G12 -> 19 | V13: =U13/C13 -> 0.06959707 | W13: ='Water Reading'!J13-'Water Reading'!J12 -> 5 | X13: =W13/C13 -> 0.018315018 | Y13: =E13+I13+K13+M13+O13+G13+Q13+S13+U13+W13 -> 247 | Z13: =Y13/B13 -> 1
