Workbook

Sheet Total
A1: Site Name | B1: Day | C1: Month | D1: Year | E1: Total Electricity Kwh | F1: Electricity Tariff ($/Kwh) | G1: Total Fuel Oil (Liter) | H1: Fuel Oil $/Liter | I1: LPG (Kg) | J1: LPG $/Kg | K1: Water Utility Supply (m3) m3 | L1: Water Utility Supply (m3) $/m3 | M1: Irrigation Water (m3) m3 | N1: Irrigation water $/m3 | O1: Room Nights
A2: Beirut | B2: 1 | C2: 12 | D2: 2022 | E2: =ELEC!N4 -> 2827 | F2: =SUM('EDl log'!T4) -> 0.28237359 | G2: =-tanks!AW6 -> 154 | H2: =tanks!AV6 -> 0.953 | I2: =('B5'!AU5)*0.51 -> 0 | J2: ='B5'!AX5/0.51 -> 1.5686275 | K2: =WATER!I6 -> 0 | L2: =SUM(WATER!J6) -> 0 | M2: =WATER!Q6 -> 0 | N2: 0.6 | O2: =ELEC!B4 -> 0
A3: Beirut | B3: =B2+1 -> 2 | C3: 12 | D3: =D2 -> 2022 | E3: =ELEC!N5 -> 0 | F3: =SUM('EDl log'!T5) -> 0 | G3: =-tanks!AW7 -> 0 | H3: =tanks!AV7 -> 0.953 | I3: =('B5'!AU6)*0.51 -> 0 | J3: ='B5'!AX6/0.51 -> 1.5686275 | K3: =WATER!I7 -> 0 | L3: =SUM(WATER!J7) -> 0 | M3: =WATER!Q7 -> 0 | N3: 0.6 | O3: =ELEC!B5 -> 0
A4: Beirut | B4: =B3+1 -> 3 | C4: 12 | D4: =D3 -> 2022 | E4: =ELEC!N6 -> 0 | F4: =SUM('EDl log'!T6) -> 0 | G4: =-tanks!AW8 -> 0 | H4: =tanks!AV8 -> 0.953 | I4: =('B5'!AU7)*0.51 -> 0 | J4: ='B5'!AX7/0.51 -> 1.5686275 | K4: =WATER!I8 -> 0 | L4: =SUM(WATER!J8) -> 0 | M4: =WATER!Q8 -> 0 | N4: 0.6 | O4: =ELEC!B6 -> 0
A5: Beirut | B5: =B4+1 -> 4 | C5: 12 | D5: =D4 -> 2022 | E5: =ELEC!N7 -> 2978 | F5: =SUM('EDl log'!T7) -> 0.37486876 | G5: =-tanks!AW9 -> 152 | H5: =tanks!AV9 -> 0.953 | I5: =('B5'!AU8)*0.51 -> 0 | J5: ='B5'!AX8/0.51 -> 1.5686275 | K5: =WATER!I9 -> 23 | L5: =SUM(WATER!J9) -> 10.518934 | M5: =WATER!Q9 -> 0 | N5: 0.6 | O5: =ELEC!B7 -> 0
A6: Beirut | B6: =B5+1 -> 5 | C6: 12 | D6: =D5 -> 2022 | E6: =ELEC!N8 -> 2462 | F6: =SUM('EDl log'!T8) -> 0.39168122 | G6: =-tanks!AW10 -> 193 | H6: =tanks!AV10 -> 0.953 | I6: =('B5'!AU9)*0.51 -> 0 | J6: ='B5'!AX9/0.51 -> 1.5686275 | K6: =WATER!I10 -> 152 | L6: =SUM(WATER!J10) -> 1.5916808 | M6: =WATER!Q10 -> 0 | N6: 0.6 | O6: =ELEC!B8 -> 0
A7: Beirut | B7: =B6+1 -> 6 | C7: 12 | D7: =D6 -> 2022 | E7: =ELEC!N9 -> 2985 | F7: =SUM('EDl log'!T9) -> 0.36442183 | G7: =-tanks!AW11 -> 116 | H7: =tanks!AV11 -> 0.953 | I7: =('B5'!AU10)*0.51 -> 0 | J7: ='B5'!AX10/0.51 -> 1.5686275 | K7: =WATER!I11 -> 0 | L7: =SUM(WATER!J11) -> 0 | M7: =WATER!Q11 -> 0 | N7: 0.6 | O7: =ELEC!B9 -> 0
A8: Beirut | B8: =B7+1 -> 7 | C8: 12 | D8: =D7 -> 2022 | E8: =ELEC!N10 -> 2160 | F8: =SUM('EDl log'!T10) -> 0.40301395 | G8: =-tanks!AW12 -> 68 | H8: =tanks!AV12 -> 0.953 | I8: =('B5'!AU11)*0.51 -> 0 | J8: ='B5'!AX11/0.51 -> 1.5686275 | K8: =WATER!I12 -> 115 | L8: =SUM(WATER!J12) -> 2.1037868 | M8: =WATER!Q12 -> 0 | N8: 0.6 | O8: =ELEC!B10 -> 0
A9: Beirut | B9: =B8+1 -> 8 | C9: 12 | D9: =D8 -> 2022 | E9: =ELEC!N11 -> 2668 | F9: =SUM('EDl log'!T11) -> 0.29227516 | G9: =-tanks!AW13 -> 176 | H9: =tanks!AV13 -> 0.953 | I9: =('B5'!AU12)*0.51 -> 0 | J9: ='B5'!AX12/0.51 -> 1.5686275 | K9: =WATER!I13 -> 0 | L9: =SUM(WATER!J13) -> 0 | M9: =WATER!Q13 -> 0 | N9: 0.6 | O9: =ELEC!B11 -> 0
A10: Beirut | B10: =B9+1 -> 9 | C10: 12 | D10: =D9 -> 2022 | E10: =ELEC!N12 -> 0 | F10: =SUM('EDl log'!T12) -> 0 | G10: =-tanks!AW14 -> 0 | H10: =tanks!AV14 -> 0.953 | I10: =('B5'!AU13)*0.51 -> 0 | J10: ='B5'!AX13/0.51 -> 1.5686275 | K10: =WATER!I14 -> 0 | L10: =SUM(WATER!J14) -> 0 | M10: =WATER!Q14 -> 0 | N10: 0.6 | O10: =ELEC!B12 -> 0
A11: Beirut | B11: =B10+1 -> 10 | C11: 12 | D11: =D10 -> 2022 | E11: =ELEC!N13 -> 0 | F11: =SUM('EDl log'!T13) -> 0 | G11: =-tanks!AW15 -> 0 | H11: =tanks!AV15 -> 0.953 | I11: =('B5'!AU14)*0.51 -> 0 | J11: ='B5'!AX14/0.51 -> 1.5686275 | K11: =WATER!I15 -> 0 | L11: =SUM(WATER!J15) -> 0 | M11: =WATER!Q15 -> 0 | N11: 0.6 | O11: =ELEC!B13 -> 0
A12: Beirut | B12: =B11+1 -> 11 | C12: 12 | D12: =D11 -> 2022 | E12: =ELEC!N14 -> 2740 | F12: =SUM('EDl log'!T14) -> 0.05797097 | G12: =-tanks!AW16 -> 235 | H12: =tanks!AV16 -> 0.8 | I12: =('B5'!AU15)*0.51 -> 0 | J12: ='B5'!AX15/0.51 -> 1.5686275 | K12: =WATER!I16 -> 11 | L12: =SUM(WATER!J16) -> 21.994135 | M12: =WATER!Q16 -> 0 | N12: 0.6 | O12: =ELEC!B14 -> 0
A13: Beirut | B13: =B12+1 -> 12 | C13: 12 | D13: =D12 -> 2022 | E13: =ELEC!N15 -> 2411 | F13: =SUM('EDl log'!T15) -> 0.24294904 | G13: =-tanks!AW17 -> 477 | H13: =tanks!AV17 -> 0.8 | I13: =('B5'!AU16)*0.51 -> 0 | J13: ='B5'!AX16/0.51 -> 1.5686275 | K13: =WATER!I17 -> 0 | L13: =SUM(WATER!J17) -> 0 | M13: =WATER!Q17 -> 0 | N13: 0.6 | O13: =ELEC!B15 -> 0
A14: Beirut | B14: =B13+1 -> 13 | C14: 12 | D14: =D13 -> 2022 | E14: =ELEC!N16 -> 2847 | F14: =SUM('EDl log'!T16) -> 0.28511069 | G14: =-tanks!AW18 -> 138 | H14: =tanks!AV18 -> 0.8 | I14: =('B5'!AU17)*0.51 -> 0 | J14: ='B5'!AX17/0.51 -> 1.5686275 | K14: =WATER!I18 -> 95 | L14: =SUM(WATER!J18) -> 2.5466893 | M14: =WATER!Q18 -> 0 | N14: 0.6 | O14: =ELEC!B16 -> 0
... A32: Beirut | B32: =B31+1 -> 31 | C32: 12 | D32: =D31 -> 2022 | E32: =ELEC!N34 -> 0 | F32: =SUM('EDl log'!T34) -> 0 | G32: =-tanks!AW36 -> 0 | H32: =tanks!AV36 -> 0.88 | I32: =('B5'!AU35)*0.51 -> 0 | J32: ='B5'!AX35/0.51 -> 1.5686275 | K32: =WATER!I36 -> 0 | L32: =SUM(WATER!J36) -> 0 | M32: =WATER!Q36 -> 0 | N32: 0.6 | O32: =ELEC!B34 -> 0

Sheet tanks
B2: Tank 1 | D2: Tank 2 | F2: Tank 3 | H2: Tank 4 | J2: Tank 5 | L2: Tank 6 | N2: Tank 7 | P2: Tank 8 | R2: Tank 9 | T2: Tank 10 | V2: Tank 11 | Z2: Tank 1 | AB2: Tank 2 | AD2: Tank 3 | AF2: Tank 4 | AH2: Tank 5 | AJ2: Tank 6 | AL2: Tank 7
B3: 6670 | D3: =SUM(B3) -> 6670 | F3: =SUM(D3) -> 6670 | H3: =SUM(F3) -> 6670 | J3: =SUM(H3) -> 6670 | L3: =SUM(J3) -> 6670 | N3: =SUM(L3) -> 6670 | P3: =SUM(N3) -> 6670 | R3: =SUM(P3) -> 6670 | T3: =SUM(R3) -> 6670 | V3: =SUM(T3) -> 6670 | W3: =SUM(B3:V3) -> 73370 | Z3: 2800 | AB3: 2800 | AD3: 2800 | AF3: 2800 | AH3: 2800 | AJ3: 2800 | AL3: 2800 | AM3: =SUM(Z3:AL3) -> 19600 | AO3: =SUM(AM3+W3) -> 92970 | AR3: Total sotck | AS3: Diesel Cons Per day | AT3: Diesel Delivery | BE3: Genset Co | BF3: Steam | BG3: Boil | BH3: Outdoor temperature
B4: =B3/310 -> 21.516129 | D4: =SUM(B4) -> 21.516129 | F4: =SUM(D4) -> 21.516129 | H4: =SUM(F4) -> 21.516129 | J4: =SUM(H4) -> 21.516129 | L4: =SUM(J4) -> 21.516129 | N4: =SUM(L4) -> 21.516129 | P4: =SUM(N4) -> 21.516129 | R4: =SUM(P4) -> 21.516129 | T4: =SUM(R4) -> 21.516129 | V4: =SUM(T4) -> 21.516129 | Z4: =Z3/280 -> 10 | AA4: =AA3/280 -> 0 | AB4: =AB3/280 -> 10 | AC4: =AC3/280 -> 0 | AD4: =AD3/280 -> 10 | AE4: =AE3/280 -> 0 | AF4: =AF3/280 -> 10 | AG4: =AG3/280 -> 0 | ... AL4: =AL3/280 -> 10 | AT4: Delivery | AU4: Cost /L | AW4: Boiler+Steam | AX4: Generator | AZ4: Occupancy | BA4: AVE TEPM | BB4: AVE Humidity
A5: =[1]tanks!$A$35 -> 44895 | B5: =[1]tanks!B35 -> 243 | C5: =[1]tanks!C35 -> 5228.4194 | D5: =[1]tanks!D35 -> 243 | E5: =[1]tanks!E35 -> 5228.4194 | F5: =[1]tanks!F35 -> 243 | G5: =[1]tanks!G35 -> 5228.4194 | H5: =[1]tanks!H35 -> 243 | I5: =[1]tanks!I35 -> 5228.4194 | ... AO5: =[1]tanks!AO35 -> 17500 | AQ5: =[1]tanks!AQ35 -> 0.80684751 | AR5: =[1]tanks!AR35 -> 75012.613 | AS5: =[1]tanks!AS35 -> -31.290323 | AT5: =[1]tanks!AT35 -> 10765 | AU5: =[1]tanks!AU35 -> 0.953 | AV5: =[1]tanks!AV35 -> 0.953 | AW5: =[1]tanks!AW35 -> -223 | AX5: =[1]tanks!AX35 -> 191.70968 | ... BK5: =[1]tanks!BK35 -> 0.16013393
A6: =ELEC!C4 -> 44896 | B6: ='B5'!B5 -> 240 | C6: =B6*$B$4 -> 5163.871 | D6: =SUM(B6) -> 240 | E6: =D6*$B$4 -> 5163.871 | F6: =SUM(D6) -> 240 | G6: =F6*$B$4 -> 5163.871 | H6: =SUM(F6) -> 240 | I6: =H6*$B$4 -> 5163.871 | J6: =SUM(H6) -> 240 | K6: =J6*$B$4 -> 5163.871 | L6: =SUM(J6) -> 240 | M6: =L6*$B$4 -> 5163.871 | N6: =SUM(L6) -> 240 | O6: =N6*$B$4 -> 5163.871 | P6: =SUM(N6) -> 240 | Q6: =P6*$B$4 -> 5163.871 | R6: =SUM(P6) -> 240 | S6: =R6*$B$4 -> 5163.871 | T6: =SUM(R6) -> 240 | U6: =T6*$B$4 -> 5163.871 | V6: =SUM(T6) -> 240 | W6: =V6*$B$4 -> 5163.871 | X6: =SUM(Y6/73370) -> 0.77419355 | Y6: =SUM(C6+E6+G6+I6+K6+M6+O6+Q6+S6+U6+W6) -> 56802.581 | Z6: ='B5'!C5 -> 247 | AA6: =SUM(Z6*$Z$4) -> 2470 | AB6: =SUM(Z6) -> 247 | AC6: =SUM(AB6*$Z$4) -> 2470 | AD6: =SUM(AB6) -> 247 | AE6: =SUM(AD6*$Z$4) -> 2470 | AF6: =SUM(AD6) -> 247 | AG6: =SUM(AF6*$Z$4) -> 2470 | AH6: =SUM(AF6) -> 247 | AI6: =SUM(AH6*$Z$4) -> 2470 | AJ6: =SUM(AH6) -> 247 | AK6: =SUM(AJ6*$Z$4) -> 2470 | AL6: =SUM(AJ6) -> 247 | AM6: =SUM(AL6*$Z$4) -> 2470 | AN6: =SUM(AO6/19600) -> 0.88214286 | AO6: =SUM(AA6+AC6+AE6+AG6+AI6+AK6+AM6) -> 17290 | AQ6: =SUM(AR6/92970) -> 0.7969515 | AR6: =Y6+AO6 -> 74092.581 | AS6: =SUM(AR6-AR5-AT6) -> -920.03226 | AV6: =IF(AT6>0,AU6,AV5) -> 0.953 | AW6: =-SUM('B5'!AI5) -> -154 | AX6: =-SUM(AW6-AS6) -> -766.03226 | AY6: =SUM(AX6+AW6) -> -920.03226 | AZ6: =ELEC!A4 -> 0 | BA6: ='General information '!D5 -> 19 | BB6: =SUM('General information '!E5) -> 0.69 | BC6: =IF(AR3>=AR6,0,1) -> 0 | BD6: 19222 | BE6: =(305/1185)*ELEC!Q5 -> 0 | BG6: =#REF!-BE6 -> #REF! | BH6: 21 | BI6: 12 | BJ6: =AX6/BI6 -> -63.836022
A7: =ELEC!C5 -> 44897 | B7: ='B5'!B6 -> 240 | C7: =B7*$B$4 -> 5163.871 | D7: =SUM(B7) -> 240 | E7: =D7*$B$4 -> 5163.871 | F7: =SUM(D7) -> 240 | G7: =F7*$B$4 -> 5163.871 | H7: =SUM(F7) -> 240 | I7: =H7*$B$4 -> 5163.871 | J7: =SUM(H7) -> 240 | K7: =J7*$B$4 -> 5163.871 | L7: =SUM(J7) -> 240 | M7: =L7*$B$4 -> 5163.871 | N7: =SUM(L7) -> 240 | O7: =N7*$B$4 -> 5163.871 | P7: =SUM(N7) -> 240 | Q7: =P7*$B$4 -> 5163.871 | R7: =SUM(P7) -> 240 | S7: =R7*$B$4 -> 5163.871 | T7: =SUM(R7) -> 240 | U7: =T7*$B$4 -> 5163.871 | V7: =SUM(T7) -> 240 | W7: =V7*$B$4 -> 5163.871 | X7: =SUM(Y7/73370) -> 0.77419355 | Y7: =SUM(C7+E7+G7+I7+K7+M7+O7+Q7+S7+U7+W7) -> 56802.581 | Z7: ='B5'!C6 -> 247 | AA7: =SUM(Z7*$Z$4) -> 2470 | AB7: =SUM(Z7) -> 247 | AC7: =SUM(AB7*$Z$4) -> 2470 | AD7: =SUM(AB7) -> 247 | AE7: =SUM(AD7*$Z$4) -> 2470 | AF7: =SUM(AD7) -> 247 | AG7: =SUM(AF7*$Z$4) -> 2470 | AH7: =SUM(AF7) -> 247 | AI7: =SUM(AH7*$Z$4) -> 2470 | AJ7: =SUM(AH7) -> 247 | AK7: =SUM(AJ7*$Z$4) -> 2470 | AL7: =SUM(AJ7) -> 247 | AM7: =SUM(AL7*$Z$4) -> 2470 | AN7: =SUM(AO7/19600) -> 0.88214286 | AO7: =SUM(AA7+AC7+AE7+AG7+AI7+AK7+AM7) -> 17290 | AQ7: =SUM(AR7/92970) -> 0.7969515 | AR7: =Y7+AO7 -> 74092.581 | AS7: =SUM(AR7-AR6-AT7) -> 0 | AV7: =IF(AT7>0,AU7,AV6) -> 0.953 | AW7: =-SUM('B5'!AI6) -> 0 | AX7: =-SUM(AW7-AS7) -> 0 | AY7: =SUM(AX7+AW7) -> 0 | AZ7: =ELEC!A5 -> 0 | BA7: ='General information '!D6 -> 0 | BB7: =SUM('General information '!E6) -> 0 | BC7: 0 | BD7: 19222 | BE7: =(305/1185)*ELEC!Q6 -> 0 | BG7: =#REF!-BE7 -> #REF! | BH7: 19 | BI7: 15 | BJ7: =AX7/BI7 -> 0
A8: =ELEC!C6 -> 44898 | B8: ='B5'!B7 -> 240 | C8: =B8*$B$4 -> 5163.871 | D8: =SUM(B8) -> 240 | E8: =D8*$B$4 -> 5163.871 | F8: =SUM(D8) -> 240 | G8: =F8*$B$4 -> 5163.871 | H8: =SUM(F8) -> 240 | I8: =H8*$B$4 -> 5163.871 | J8: =SUM(H8) -> 240 | K8: =J8*$B$4 -> 5163.871 | L8: =SUM(J8) -> 240 | M8: =L8*$B$4 -> 5163.871 | N8: =SUM(L8) -> 240 | O8: =N8*$B$4 -> 5163.871 | P8: =SUM(N8) -> 240 | Q8: =P8*$B$4 -> 5163.871 | R8: =SUM(P8) -> 240 | S8: =R8*$B$4 -> 5163.871 | T8: =SUM(R8) -> 240 | U8: =T8*$B$4 -> 5163.871 | V8: =SUM(T8) -> 240 | W8: =V8*$B$4 -> 5163.871 | X8: =SUM(Y8/73370) -> 0.77419355 | Y8: =SUM(C8+E8+G8+I8+K8+M8+O8+Q8+S8+U8+W8) -> 56802.581 | Z8: ='B5'!C7 -> 247 | AA8: =SUM(Z8*$Z$4) -> 2470 | AB8: =SUM(Z8) -> 247 | AC8: =SUM(AB8*$Z$4) -> 2470 | AD8: =SUM(AB8) -> 247 | AE8: =SUM(AD8*$Z$4) -> 2470 | AF8: =SUM(AD8) -> 247 | AG8: =SUM(AF8*$Z$4) -> 2470 | AH8: =SUM(AF8) -> 247 | AI8: =SUM(AH8*$Z$4) -> 2470 | AJ8: =SUM(AH8) -> 247 | AK8: =SUM(AJ8*$Z$4) -> 2470 | AL8: =SUM(AJ8) -> 247 | AM8: =SUM(AL8*$Z$4) -> 2470 | AN8: =SUM(AO8/19600) -> 0.88214286 | AO8: =SUM(AA8+AC8+AE8+AG8+AI8+AK8+AM8) -> 17290 | AQ8: =SUM(AR8/92970) -> 0.7969515 | AR8: =Y8+AO8 -> 74092.581 | AS8: =SUM(AR8-AR7-AT8) -> 0 | AV8: =IF(AT8>0,AU8,AV7) -> 0.953 | AW8: =-SUM('B5'!AI7) -> 0 | AX8: =-SUM(AW8-AS8) -> 0 | AY8: =SUM(AX8+AW8) -> 0 | AZ8: =ELEC!A6 -> 0 | BA8: ='General information '!D7 -> 0 | BB8: =SUM('General information '!E7) -> 0 | BC8: =IF(AR7>=AR8,0,1) -> 0 | BD8: 19222 | BE8: =(305/1185)*ELEC!Q7 -> 794.5443 | BG8: =#REF!-BE8 -> #REF! | BH8: 16 | BI8: 9 | BJ8: =AX8/BI8 -> 0 | BK8: =GEN!AF5 -> #DIV/0!
A9: =ELEC!C7 -> 44899 | B9: ='B5'!B8 -> 236 | C9: =B9*$B$4 -> 5077.8065 | D9: =SUM(B9) -> 236 | E9: =D9*$B$4 -> 5077.8065 | F9: =SUM(D9) -> 236 | G9: =F9*$B$4 -> 5077.8065 | H9: =SUM(F9) -> 236 | I9: =H9*$B$4 -> 5077.8065 | J9: =SUM(H9) -> 236 | K9: =J9*$B$4 -> 5077.8065 | L9: =SUM(J9) -> 236 | M9: =L9*$B$4 -> 5077.8065 | N9: =SUM(L9) -> 236 | O9: =N9*$B$4 -> 5077.8065 | P9: =SUM(N9) -> 236 | Q9: =P9*$B$4 -> 5077.8065 | R9: =SUM(P9) -> 236 | S9: =R9*$B$4 -> 5077.8065 | T9: =SUM(R9) -> 236 | U9: =T9*$B$4 -> 5077.8065 | V9: =SUM(T9) -> 236 | W9: =V9*$B$4 -> 5077.8065 | X9: =SUM(Y9/73370) -> 0.76129032 | Y9: =SUM(C9+E9+G9+I9+K9+M9+O9+Q9+S9+U9+W9) -> 55855.871 | Z9: ='B5'!C8 -> 242 | AA9: =SUM(Z9*$Z$4) -> 2420 | AB9: =SUM(Z9) -> 242 | AC9: =SUM(AB9*$Z$4) -> 2420 | AD9: =SUM(AB9) -> 242 | AE9: =SUM(AD9*$Z$4) -> 2420 | AF9: =SUM(AD9) -> 242 | AG9: =SUM(AF9*$Z$4) -> 2420 | AH9: =SUM(AF9) -> 242 | AI9: =SUM(AH9*$Z$4) -> 2420 | AJ9: =SUM(AH9) -> 242 | AK9: =SUM(AJ9*$Z$4) -> 2420 | AL9: =SUM(AJ9) -> 242 | AM9: =SUM(AL9*$Z$4) -> 2420 | AN9: =SUM(AO9/19600) -> 0.86428571 | AO9: =SUM(AA9+AC9+AE9+AG9+AI9+AK9+AM9) -> 16940 | AQ9: =SUM(AR9/92970) -> 0.78300388 | AR9: =Y9+AO9 -> 72795.871 | AS9: =SUM(AR9-AR8-AT9) -> -1296.7097 | AV9: =IF(AT9>0,AU9,AV8) -> 0.953 | AW9: =-SUM('B5'!AI8) -> -152 | AX9: =-SUM(AW9-AS9) -> -1144.7097 | AY9: =SUM(AX9+AW9) -> -1296.7097 | AZ9: =ELEC!A7 -> 0 | BA9: ='General information '!D8 -> 19 | BB9: =SUM('General information '!E8) -> 0.55 | BC9: =IF(AR8>=AR9,0,1) -> 0 | BD9: 19222 | BE9: =(305/1185)*ELEC!Q8 -> 635.99578 | BG9: =#REF!-BE9 -> #REF! | BH9: 18 | BI9: 6 | BJ9: =AX9/BI9 -> -190.78495 | BK9: =GEN!AF6 -> 0.14841346
A10: =ELEC!C8 -> 44900 | B10: ='B5'!B9 -> 232 | C10: =B10*$B$4 -> 4991.7419 | D10: =SUM(B10) -> 232 | E10: =D10*$B$4 -> 4991.7419 | F10: =SUM(D10) -> 232 | G10: =F10*$B$4 -> 4991.7419 | H10: =SUM(F10) -> 232 | I10: =H10*$B$4 -> 4991.7419 | J10: =SUM(H10) -> 232 | K10: =J10*$B$4 -> 4991.7419 | L10: =SUM(J10) -> 232 | M10: =L10*$B$4 -> 4991.7419 | N10: =SUM(L10) -> 232 | O10: =N10*$B$4 -> 4991.7419 | P10: =SUM(N10) -> 232 | Q10: =P10*$B$4 -> 4991.7419 | R10: =SUM(P10) -> 232 | S10: =R10*$B$4 -> 4991.7419 | T10: =SUM(R10) -> 232 | U10: =T10*$B$4 -> 4991.7419 | V10: =SUM(T10) -> 232 | W10: =V10*$B$4 -> 4991.7419 | X10: =SUM(Y10/73370) -> 0.7483871 | Y10: =SUM(C10+E10+G10+I10+K10+M10+O10+Q10+S10+U10+W10) -> 54909.161 | Z10: ='B5'!C9 -> 239 | AA10: =SUM(Z10*$Z$4) -> 2390 | AB10: =SUM(Z10) -> 239 | AC10: =SUM(AB10*$Z$4) -> 2390 | AD10: =SUM(AB10) -> 239 | AE10: =SUM(AD10*$Z$4) -> 2390 | AF10: =SUM(AD10) -> 239 | AG10: =SUM(AF10*$Z$4) -> 2390 | AH10: =SUM(AF10) -> 239 | AI10: =SUM(AH10*$Z$4) -> 2390 | AJ10: =SUM(AH10) -> 239 | AK10: =SUM(AJ10*$Z$4) -> 2390 | AL10: =SUM(AJ10) -> 239 | AM10: =SUM(AL10*$Z$4) -> 2390 | AN10: =SUM(AO10/19600) -> 0.85357143 | AO10: =SUM(AA10+AC10+AE10+AG10+AI10+AK10+AM10) -> 16730 | AQ10: =SUM(AR10/92970) -> 0.77056213 | AR10: =Y10+AO10 -> 71639.161 | AS10: =SUM(AR10-AR9-AT10) -> -1156.7097 | AV10: =IF(AT10>0,AU10,AV9) -> 0.953 | AW10: =-SUM('B5'!AI9) -> -193 | AX10: =-SUM(AW10-AS10) -> -963.70968 | AY10: =SUM(AX10+AW10) -> -1156.7097 | AZ10: =ELEC!A8 -> 0 | BA10: ='General information '!D9 -> 19 | BB10: =SUM('General information '!E9) -> 0.58 | BC10: =IF(AR9>=AR10,0,1) -> 0 | BD10: 19222 | BE10: =(305/1185)*ELEC!Q9 -> 784.24895 | BG10: =#REF!-BE10 -> #REF! | BH10: 16 | BI10: 7 | BJ10: =AX10/BI10 -> -137.67281 | BK10: =GEN!AF7 -> 0.17159722
A11: =ELEC!C9 -> 44901 | B11: ='B5'!B10 -> 228 | C11: =B11*$B$4 -> 4905.6774 | D11: =SUM(B11) -> 228 | E11: =D11*$B$4 -> 4905.6774 | F11: =SUM(D11) -> 228 | G11: =F11*$B$4 -> 4905.6774 | H11: =SUM(F11) -> 228 | I11: =H11*$B$4 -> 4905.6774 | J11: =SUM(H11) -> 228 | K11: =J11*$B$4 -> 4905.6774 | L11: =SUM(J11) -> 228 | M11: =L11*$B$4 -> 4905.6774 | N11: =SUM(L11) -> 228 | O11: =N11*$B$4 -> 4905.6774 | P11: =SUM(N11) -> 228 | Q11: =P11*$B$4 -> 4905.6774 | R11: =SUM(P11) -> 228 | S11: =R11*$B$4 -> 4905.6774 | T11: =SUM(R11) -> 228 | U11: =T11*$B$4 -> 4905.6774 | V11: =SUM(T11) -> 228 | W11: =V11*$B$4 -> 4905.6774 | X11: =SUM(Y11/73370) -> 0.73548387 | Y11: =SUM(C11+E11+G11+I11+K11+M11+O11+Q11+S11+U11+W11) -> 53962.452 | Z11: ='B5'!C10 -> 235 | AA11: =SUM(Z11*$Z$4) -> 2350 | AB11: =SUM(Z11) -> 235 | AC11: =SUM(AB11*$Z$4) -> 2350 | AD11: =SUM(AB11) -> 235 | AE11: =SUM(AD11*$Z$4) -> 2350 | AF11: =SUM(AD11) -> 235 | AG11: =SUM(AF11*$Z$4) -> 2350 | AH11: =SUM(AF11) -> 235 | AI11: =SUM(AH11*$Z$4) -> 2350 | AJ11: =SUM(AH11) -> 235 | AK11: =SUM(AJ11*$Z$4) -> 2350 | AL11: =SUM(AJ11) -> 235 | AM11: =SUM(AL11*$Z$4) -> 2350 | AN11: =SUM(AO11/19600) -> 0.83928571 | AO11: =SUM(AA11+AC11+AE11+AG11+AI11+AK11+AM11) -> 16450 | AQ11: =SUM(AR11/92970) -> 0.75736745 | AR11: =Y11+AO11 -> 70412.452 | AS11: =SUM(AR11-AR10-AT11) -> -1226.7097 | AV11: =IF(AT11>0,AU11,AV10) -> 0.953 | AW11: =-SUM('B5'!AI10) -> -116 | AX11: =-SUM(AW11-AS11) -> -1110.7097 | AY11: =SUM(AX11+AW11) -> -1226.7097 | AZ11: =ELEC!A9 -> 0 | BA11: ='General information '!D10 -> 18.5 | BB11: =SUM('General information '!E10) -> 0.58 | BC11: =IF(AR10>=AR11,0,1) -> 0 | BD11: 19222 | BE11: =(305/1185)*ELEC!Q10 -> 565.21519 | BG11: =#REF!-BE11 -> #REF! | BH11: 16.5 | BI11: 9.3 | BJ11: =AX11/BI11 -> -119.43115
A12: =ELEC!C10 -> 44902 | B12: ='B5'!B11 -> 225 | C12: =B12*$B$4 -> 4841.129 | D12: =SUM(B12) -> 225 | E12: =D12*$B$4 -> 4841.129 | F12: =SUM(D12) -> 225 | G12: =F12*$B$4 -> 4841.129 | H12: =SUM(F12) -> 225 | I12: =H12*$B$4 -> 4841.129 | J12: =SUM(H12) -> 225 | K12: =J12*$B$4 -> 4841.129 | L12: =SUM(J12) -> 225 | M12: =L12*$B$4 -> 4841.129 | N12: =SUM(L12) -> 225 | O12: =N12*$B$4 -> 4841.129 | P12: =SUM(N12) -> 225 | Q12: =P12*$B$4 -> 4841.129 | R12: =SUM(P12) -> 225 | S12: =R12*$B$4 -> 4841.129 | T12: =SUM(R12) -> 225 | U12: =T12*$B$4 -> 4841.129 | V12: =SUM(T12) -> 225 | W12: =V12*$B$4 -> 4841.129 | X12: =SUM(Y12/73370) -> 0.72580645 | Y12: =SUM(C12+E12+G12+I12+K12+M12+O12+Q12+S12+U12+W12) -> 53252.419 | Z12: ='B5'!C11 -> 232 | AA12: =SUM(Z12*$Z$4) -> 2320 | AB12: =SUM(Z12) -> 232 | AC12: =SUM(AB12*$Z$4) -> 2320 | AD12: =SUM(AB12) -> 232 | AE12: =SUM(AD12*$Z$4) -> 2320 | AF12: =SUM(AD12) -> 232 | AG12: =SUM(AF12*$Z$4) -> 2320 | AH12: =SUM(AF12) -> 232 | AI12: =SUM(AH12*$Z$4) -> 2320 | AJ12: =SUM(AH12) -> 232 | AK12: =SUM(AJ12*$Z$4) -> 2320 | AL12: =SUM(AJ12) -> 232 | AM12: =SUM(AL12*$Z$4) -> 2320 | AN12: =SUM(AO12/19600) -> 0.82857143 | AO12: =SUM(AA12+AC12+AE12+AG12+AI12+AK12+AM12) -> 16240 | AQ12: =SUM(AR12/92970) -> 0.74747144 | AR12: =Y12+AO12 -> 69492.419 | AS12: =SUM(AR12-AR11-AT12) -> -920.03226 | AV12: =IF(AT12>0,AU12,AV11) -> 0.953 | AW12: =-SUM('B5'!AI11) -> -68 | AX12: =-SUM(AW12-AS12) -> -852.03226 | AY12: =SUM(AX12+AW12) -> -920.03226 | AZ12: =ELEC!A10 -> 0 | BA12: ='General information '!D11 -> 18 | BB12: =SUM('General information '!E11) -> 0.66 | BC12: =IF(AR11>=AR12,0,1) -> 0 | BD12: 19222 | BE12: =(305/1185)*ELEC!Q11 -> 703.43038 | BG12: =#REF!-BE12 -> #REF! | BH12: 15.5 | BI12: 3.7 | BJ12: =AX12/BI12 -> -230.27899
A13: =ELEC!C11 -> 44903 | B13: ='B5'!B12 -> 222 | C13: =B13*$B$4 -> 4776.5806 | D13: =SUM(B13) -> 222 | E13: =D13*$B$4 -> 4776.5806 | F13: =SUM(D13) -> 222 | G13: =F13*$B$4 -> 4776.5806 | H13: =SUM(F13) -> 222 | I13: =H13*$B$4 -> 4776.5806 | J13: =SUM(H13) -> 222 | K13: =J13*$B$4 -> 4776.5806 | L13: =SUM(J13) -> 222 | M13: =L13*$B$4 -> 4776.5806 | N13: =SUM(L13) -> 222 | O13: =N13*$B$4 -> 4776.5806 | P13: =SUM(N13) -> 222 | Q13: =P13*$B$4 -> 4776.5806 | R13: =SUM(P13) -> 222 | S13: =R13*$B$4 -> 4776.5806 | T13: =SUM(R13) -> 222 | U13: =T13*$B$4 -> 4776.5806 | V13: =SUM(T13) -> 222 | W13: =V13*$B$4 -> 4776.5806 | X13: =SUM(Y13/73370) -> 0.71612903 | Y13: =SUM(C13+E13+G13+I13+K13+M13+O13+Q13+S13+U13+W13) -> 52542.387 | Z13: ='B5'!C12 -> 229 | AA13: =SUM(Z13*$Z$4) -> 2290 | AB13: =SUM(Z13) -> 229 | AC13: =SUM(AB13*$Z$4) -> 2290 | AD13: =SUM(AB13) -> 229 | AE13: =SUM(AD13*$Z$4) -> 2290 | AF13: =SUM(AD13) -> 229 | AG13: =SUM(AF13*$Z$4) -> 2290 | AH13: =SUM(AF13) -> 229 | AI13: =SUM(AH13*$Z$4) -> 2290 | AJ13: =SUM(AH13) -> 229 | AK13: =SUM(AJ13*$Z$4) -> 2290 | AL13: =SUM(AJ13) -> 229 | AM13: =SUM(AL13*$Z$4) -> 2290 | AN13: =SUM(AO13/19600) -> 0.81785714 | AO13: =SUM(AA13+AC13+AE13+AG13+AI13+AK13+AM13) -> 16030 | AQ13: =SUM(AR13/92970) -> 0.73757542 | AR13: =Y13+AO13 -> 68572.387 | AS13: =SUM(AR13-AR12-AT13) -> -920.03226 | AV13: =IF(AT13>0,AU13,AV12) -> 0.953 | AW13: =-SUM('B5'!AI12) -> -176 | AX13: =-SUM(AW13-AS13) -> -744.03226 | AY13: =SUM(AX13+AW13) -> -920.03226 | AZ13: =ELEC!A11 -> 0 | BA13: ='General information '!D12 -> 18.5 | BB13: =SUM('General information '!E12) -> 0.67 | BC13: =IF(AR12>=AR13,0,1) -> 0 | BD13: 19222 | BE13: =(305/1185)*ELEC!Q12 -> 0 | BG13: =#REF!-BE13 -> #REF! | BI13: 5 | BJ13: =AX13/BI13 -> -148.80645 | BK13: =GEN!AF10 -> 0.15528409
A14: =ELEC!C12 -> 44904 | B14: ='B5'!B13 -> 222 | C14: =B14*$B$4 -> 4776.5806 | D14: =SUM(B14) -> 222 | E14: =D14*$B$4 -> 4776.5806 | F14: =SUM(D14) -> 222 | G14: =F14*$B$4 -> 4776.5806 | H14: =SUM(F14) -> 222 | I14: =H14*$B$4 -> 4776.5806 | J14: =SUM(H14) -> 222 | K14: =J14*$B$4 -> 4776.5806 | L14: =SUM(J14) -> 222 | M14: =L14*$B$4 -> 4776.5806 | N14: =SUM(L14) -> 222 | O14: =N14*$B$4 -> 4776.5806 | P14: =SUM(N14) -> 222 | Q14: =P14*$B$4 -> 4776.5806 | R14: =SUM(P14) -> 222 | S14: =R14*$B$4 -> 4776.5806 | T14: =SUM(R14) -> 222 | U14: =T14*$B$4 -> 4776.5806 | V14: =SUM(T14) -> 222 | W14: =V14*$B$4 -> 4776.5806 | X14: =SUM(Y14/73370) -> 0.71612903 | Y14: =SUM(C14+E14+G14+I14+K14+M14+O14+Q14+S14+U14+W14) -> 52542.387 | Z14: ='B5'!C13 -> 229 | AA14: =SUM(Z14*$Z$4) -> 2290 | AB14: =SUM(Z14) -> 229 | AC14: =SUM(AB14*$Z$4) -> 2290 | AD14: =SUM(AB14) -> 229 | AE14: =SUM(AD14*$Z$4) -> 2290 | AF14: =SUM(AD14) -> 229 | AG14: =SUM(AF14*$Z$4) -> 2290 | AH14: =SUM(AF14) -> 229 | AI14: =SUM(AH14*$Z$4) -> 2290 | AJ14: =SUM(AH14) -> 229 | AK14: =SUM(AJ14*$Z$4) -> 2290 | AL14: =SUM(AJ14) -> 229 | AM14: =SUM(AL14*$Z$4) -> 2290 | AN14: =SUM(AO14/19600) -> 0.81785714 | AO14: =SUM(AA14+AC14+AE14+AG14+AI14+AK14+AM14) -> 16030 | AQ14: =SUM(AR14/92970) -> 0.73757542 | AR14: =Y14+AO14 -> 68572.387 | AS14: =SUM(AR14-AR13-AT14) -> 0 | AV14: =IF(AT14>0,AU14,AV13) -> 0.953 | AW14: =-SUM('B5'!AI13) -> 0 | AX14: =-SUM(AW14-AS14) -> 0 | AY14: =SUM(AX14+AW14) -> 0 | AZ14: =ELEC!A12 -> 0 | BA14: ='General information '!D13 -> 0 | BB14: =SUM('General information '!E13) -> 0 | BC14: =IF(AR13>=AR14,0,1) -> 0 | BD14: 19222 | BE14: =(305/1185)*ELEC!Q13 -> 0 | BG14: =#REF!-BE14 -> #REF! | BI14: 3 | BJ14: =AX14/BI14 -> 0 | BK14: =GEN!AF11 -> #DIV/0!
A15: =ELEC!C13 -> 44905 | B15: ='B5'!B14 -> 222 | C15: =B15*$B$4 -> 4776.5806 | D15: =SUM(B15) -> 222 | E15: =D15*$B$4 -> 4776.5806 | F15: =SUM(D15) -> 222 | G15: =F15*$B$4 -> 4776.5806 | H15: =SUM(F15) -> 222 | I15: =H15*$B$4 -> 4776.5806 | J15: =SUM(H15) -> 222 | K15: =J15*$B$4 -> 4776.5806 | L15: =SUM(J15) -> 222 | M15: =L15*$B$4 -> 4776.5806 | N15: =SUM(L15) -> 222 | O15: =N15*$B$4 -> 4776.5806 | P15: =SUM(N15) -> 222 | Q15: =P15*$B$4 -> 4776.5806 | R15: =SUM(P15) -> 222 | S15: =R15*$B$4 -> 4776.5806 | T15: =SUM(R15) -> 222 | U15: =T15*$B$4 -> 4776.5806 | V15: =SUM(T15) -> 222 | W15: =V15*$B$4 -> 4776.5806 | X15: =SUM(Y15/73370) -> 0.71612903 | Y15: =SUM(C15+E15+G15+I15+K15+M15+O15+Q15+S15+U15+W15) -> 52542.387 | Z15: ='B5'!C14 -> 229 | AA15: =SUM(Z15*$Z$4) -> 2290 | AB15: =SUM(Z15) -> 229 | AC15: =SUM(AB15*$Z$4) -> 2290 | AD15: =SUM(AB15) -> 229 | AE15: =SUM(AD15*$Z$4) -> 2290 | AF15: =SUM(AD15) -> 229 | AG15: =SUM(AF15*$Z$4) -> 2290 | AH15: =SUM(AF15) -> 229 | AI15: =SUM(AH15*$Z$4) -> 2290 | AJ15: =SUM(AH15) -> 229 | AK15: =SUM(AJ15*$Z$4) -> 2290 | AL15: =SUM(AJ15) -> 229 | AM15: =SUM(AL15*$Z$4) -> 2290 | AN15: =SUM(AO15/19600) -> 0.81785714 | AO15: =SUM(AA15+AC15+AE15+AG15+AI15+AK15+AM15) -> 16030 | AQ15: =SUM(AR15/92970) -> 0.73757542 | AR15: =Y15+AO15 -> 68572.387 | AS15: =SUM(AR15-AR14-AT15) -> 0 | AV15: =IF(AT15>0,AU15,AV14) -> 0.953 | AW15: =-SUM('B5'!AI14) -> 0 | AX15: =-SUM(AW15-AS15) -> 0 | AY15: =SUM(AX15+AW15) -> 0 | AZ15: =ELEC!A13 -> 0 | BA15: ='General information '!D14 -> 0 | BB15: =SUM('General information '!E14) -> 0 | BC15: =IF(AR14>=AR15,0,1) -> 0 | BD15: 19222 | BE15: =(305/1185)*ELEC!Q14 -> 719.90295 | BG15: =#REF!-BE15 -> #REF! | BI15: 4 | BJ15: =AX15/BI15 -> 0 | BK15: =GEN!AF12 -> #DIV/0!
A16: =ELEC!C14 -> 44906 | B16: ='B5'!B15 -> 240 | C16: =B16*$B$4 -> 5163.871 | D16: =SUM(B16) -> 240 | E16: =D16*$B$4 -> 5163.871 | F16: =SUM(D16) -> 240 | G16: =F16*$B$4 -> 5163.871 | H16: =SUM(F16) -> 240 | I16: =H16*$B$4 -> 5163.871 | J16: =SUM(H16) -> 240 | K16: =J16*$B$4 -> 5163.871 | L16: =SUM(J16) -> 240 | M16: =L16*$B$4 -> 5163.871 | N16: =SUM(L16) -> 240 | O16: =N16*$B$4 -> 5163.871 | P16: =SUM(N16) -> 240 | Q16: =P16*$B$4 -> 5163.871 | R16: =SUM(P16) -> 240 | S16: =R16*$B$4 -> 5163.871 | T16: =SUM(R16) -> 240 | U16: =T16*$B$4 -> 5163.871 | V16: =SUM(T16) -> 240 | W16: =V16*$B$4 -> 5163.871 | X16: =SUM(Y16/73370) -> 0.77419355 | Y16: =SUM(C16+E16+G16+I16+K16+M16+O16+Q16+S16+U16+W16) -> 56802.581 | Z16: ='B5'!C15 -> 247 | AA16: =SUM(Z16*$Z$4) -> 2470 | AB16: =SUM(Z16) -> 247 | AC16: =SUM(AB16*$Z$4) -> 2470 | AD16: =SUM(AB16) -> 247 | AE16: =SUM(AD16*$Z$4) -> 2470 | AF16: =SUM(AD16) -> 247 | AG16: =SUM(AF16*$Z$4) -> 2470 | AH16: =SUM(AF16) -> 247 | AI16: =SUM(AH16*$Z$4) -> 2470 | AJ16: =SUM(AH16) -> 247 | AK16: =SUM(AJ16*$Z$4) -> 2470 | AL16: =SUM(AJ16) -> 247 | AM16: =SUM(AL16*$Z$4) -> 2470 | AN16: =SUM(AO16/19600) -> 0.88214286 | AO16: =SUM(AA16+AC16+AE16+AG16+AI16+AK16+AM16) -> 17290 | AQ16: =SUM(AR16/92970) -> 0.7969515 | AR16: =Y16+AO16 -> 74092.581 | AS16: =SUM(AR16-AR15-AT16) -> -239.80645 | AT16: 5760 | AU16: 0.8 | AV16: =IF(AT16>0,AU16,AV15) -> 0.8 | AW16: =-SUM('B5'!AI15) -> -235 | AX16: =-SUM(AW16-AS16) -> -4.8064516 | AY16: =SUM(AX16+AW16) -> -239.80645 | AZ16: =ELEC!A14 -> 0 | BA16: ='General information '!D15 -> 18 | BB16: =SUM('General information '!E15) -> 0.57 | BC16: =IF(AR15>=AR16,0,1) -> 1 | BD16: 19222 | BE16: =(305/1185)*ELEC!Q15 -> 569.33333 | BG16: =#REF!-BE16 -> #REF! | BI16: 3 | BJ16: =AX16/BI16 -> -1.6021505 | BK16: =GEN!AF13 -> 0.1748125
A17: =ELEC!C15 -> 44907 | B17: ='B5'!B16 -> 237 | C17: =B17*$B$4 -> 5099.3226 | D17: =SUM(B17) -> 237 | E17: =D17*$B$4 -> 5099.3226 | F17: =SUM(D17) -> 237 | G17: =F17*$B$4 -> 5099.3226 | H17: =SUM(F17) -> 237 | I17: =H17*$B$4 -> 5099.3226 | J17: =SUM(H17) -> 237 | K17: =J17*$B$4 -> 5099.3226 | L17: =SUM(J17) -> 237 | M17: =L17*$B$4 -> 5099.3226 | N17: =SUM(L17) -> 237 | O17: =N17*$B$4 -> 5099.3226 | P17: =SUM(N17) -> 237 | Q17: =P17*$B$4 -> 5099.3226 | R17: =SUM(P17) -> 237 | S17: =R17*$B$4 -> 5099.3226 | T17: =SUM(R17) -> 237 | U17: =T17*$B$4 -> 5099.3226 | V17: =SUM(T17) -> 237 | W17: =V17*$B$4 -> 5099.3226 | X17: =SUM(Y17/73370) -> 0.76451613 | Y17: =SUM(C17+E17+G17+I17+K17+M17+O17+Q17+S17+U17+W17) -> 56092.548 | Z17: ='B5'!C16 -> 243 | AA17: =SUM(Z17*$Z$4) -> 2430 | AB17: =SUM(Z17) -> 243 | AC17: =SUM(AB17*$Z$4) -> 2430 | AD17: =SUM(AB17) -> 243 | AE17: =SUM(AD17*$Z$4) -> 2430 | AF17: =SUM(AD17) -> 243 | AG17: =SUM(AF17*$Z$4) -> 2430 | AH17: =SUM(AF17) -> 243 | AI17: =SUM(AH17*$Z$4) -> 2430 | AJ17: =SUM(AH17) -> 243 | AK17: =SUM(AJ17*$Z$4) -> 2430 | AL17: =SUM(AJ17) -> 243 | AM17: =SUM(AL17*$Z$4) -> 2430 | AN17: =SUM(AO17/19600) -> 0.86785714 | AO17: =SUM(AA17+AC17+AE17+AG17+AI17+AK17+AM17) -> 17010 | AQ17: =SUM(AR17/92970) -> 0.78630255 | AR17: =Y17+AO17 -> 73102.548 | AS17: =SUM(AR17-AR16-AT17) -> -990.03226 | AV17: =IF(AT17>0,AU17,AV16) -> 0.8 | AW17: =-SUM('B5'!AI16) -> -477 | AX17: =-SUM(AW17-AS17) -> -513.03226 | AY17: =SUM(AX17+AW17) -> -990.03226 | AZ17: =ELEC!A15 -> 0 | BA17: ='General information '!D16 -> 19 | BB17: =SUM('General information '!E16) -> 0.54 | BC17: =IF(AR16>=AR17,0,1) -> 0 | BD17: 19222 | BE17: =(305/1185)*ELEC!Q16 -> 587.35021 | BG17: =#REF!-BE17 -> #REF! | BI17: 4 | BJ17: =AX17/BI17 -> -128.25806 | BK17: =GEN!AF14 -> 0.12568182
A18: =ELEC!C16 -> 44908 | B18: ='B5'!B17 -> 234 | C18: =B18*$B$4 -> 5034.7742 | D18: =SUM(B18) -> 234 | E18: =D18*$B$4 -> 5034.7742 | F18: =SUM(D18) -> 234 | G18: =F18*$B$4 -> 5034.7742 | H18: =SUM(F18) -> 234 | I18: =H18*$B$4 -> 5034.7742 | J18: =SUM(H18) -> 234 | K18: =J18*$B$4 -> 5034.7742 | L18: =SUM(J18) -> 234 | M18: =L18*$B$4 -> 5034.7742 | N18: =SUM(L18) -> 234 | O18: =N18*$B$4 -> 5034.7742 | P18: =SUM(N18) -> 234 | Q18: =P18*$B$4 -> 5034.7742 | R18: =SUM(P18) -> 234 | S18: =R18*$B$4 -> 5034.7742 | T18: =SUM(R18) -> 234 | U18: =T18*$B$4 -> 5034.7742 | V18: =SUM(T18) -> 234 | W18: =V18*$B$4 -> 5034.7742 | X18: =SUM(Y18/73370) -> 0.75483871 | Y18: =SUM(C18+E18+G18+I18+K18+M18+O18+Q18+S18+U18+W18) -> 55382.516 | Z18: ='B5'!C17 -> 240 | AA18: =SUM(Z18*$Z$4) -> 2400 | AB18: =SUM(Z18) -> 240 | AC18: =SUM(AB18*$Z$4) -> 2400 | AD18: =SUM(AB18) -> 240 | AE18: =SUM(AD18*$Z$4) -> 2400 | AF18: =SUM(AD18) -> 240 | AG18: =SUM(AF18*$Z$4) -> 2400 | AH18: =SUM(AF18) -> 240 | AI18: =SUM(AH18*$Z$4) -> 2400 | AJ18: =SUM(AH18) -> 240 | AK18: =SUM(AJ18*$Z$4) -> 2400 | AL18: =SUM(AJ18) -> 240 | AM18: =SUM(AL18*$Z$4) -> 2400 | AN18: =SUM(AO18/19600) -> 0.85714286 | AO18: =SUM(AA18+AC18+AE18+AG18+AI18+AK18+AM18) -> 16800 | AQ18: =SUM(AR18/92970) -> 0.77640654 | AR18: =Y18+AO18 -> 72182.516 | AS18: =SUM(AR18-AR17-AT18) -> -920.03226 | AV18: =IF(AT18>0,AU18,AV17) -> 0.8 | AW18: =-SUM('B5'!AI17) -> -138 | AX18: =-SUM(AW18-AS18) -> -782.03226 | AY18: =SUM(AX18+AW18) -> -920.03226 | AZ18: =ELEC!A16 -> 0 | BA18: ='General information '!D17 -> 20.5 | BB18: =SUM('General information '!E17) -> 0.57 | BC18: =IF(AR17>=AR18,0,1) -> 0 | BD18: 19222 | BE18: =(305/1185)*ELEC!Q17 -> 561.61181 | BG18: =#REF!-BE18 -> #REF! | BI18: 5 | BJ18: =AX18/BI18 -> -156.40645
A19: =ELEC!C17 -> 44909 | B19: ='B5'!B18 -> 230 | C19: =B19*$B$4 -> 4948.7097 | D19: =SUM(B19) -> 230 | E19: =D19*$B$4 -> 4948.7097 | F19: =SUM(D19) -> 230 | G19: =F19*$B$4 -> 4948.7097 | H19: =SUM(F19) -> 230 | I19: =H19*$B$4 -> 4948.7097 | J19: =SUM(H19) -> 230 | K19: =J19*$B$4 -> 4948.7097 | L19: =SUM(J19) -> 230 | M19: =L19*$B$4 -> 4948.7097 | N19: =SUM(L19) -> 230 | O19: =N19*$B$4 -> 4948.7097 | P19: =SUM(N19) -> 230 | Q19: =P19*$B$4 -> 4948.7097 | R19: =SUM(P19) -> 230 | S19: =R19*$B$4 -> 4948.7097 | T19: =SUM(R19) -> 230 | U19: =T19*$B$4 -> 4948.7097 | V19: =SUM(T19) -> 230 | W19: =V19*$B$4 -> 4948.7097 | X19: =SUM(Y19/73370) -> 0.74193548 | Y19: =SUM(C19+E19+G19+I19+K19+M19+O19+Q19+S19+U19+W19) -> 54435.806 | Z19: ='B5'!C18 -> 236 | AA19: =SUM(Z19*$Z$4) -> 2360 | AB19: =SUM(Z19) -> 236 | AC19: =SUM(AB19*$Z$4) -> 2360 | AD19: =SUM(AB19) -> 236 | AE19: =SUM(AD19*$Z$4) -> 2360 | AF19: =SUM(AD19) -> 236 | AG19: =SUM(AF19*$Z$4) -> 2360 | AH19: =SUM(AF19) -> 236 | AI19: =SUM(AH19*$Z$4) -> 2360 | AJ19: =SUM(AH19) -> 236 | AK19: =SUM(AJ19*$Z$4) -> 2360 | AL19: =SUM(AJ19) -> 236 | AM19: =SUM(AL19*$Z$4) -> 2360 | AN19: =SUM(AO19/19600) -> 0.84285714 | AO19: =SUM(AA19+AC19+AE19+AG19+AI19+AK19+AM19) -> 16520 | AQ19: =SUM(AR19/92970) -> 0.76321186 | AR19: =Y19+AO19 -> 70955.806 | AS19: =SUM(AR19-AR18-AT19) -> -1226.7097 | AV19: =IF(AT19>0,AU19,AV18) -> 0.8 | AW19: =-SUM('B5'!AI18) -> -47 | AX19: =-SUM(AW19-AS19) -> -1179.7097 | AY19: =SUM(AX19+AW19) -> -1226.7097 | AZ19: =ELEC!A17 -> 0 | BA19: ='General information '!D18 -> 19 | BB19: =SUM('General information '!E18) -> 0.64 | BC19: =IF(AR18>=AR19,0,1) -> 0 | BD19: 19222 | BE19: =(305/1185)*ELEC!Q18 -> 692.36287 | BG19: =#REF!-BE19 -> #REF! | BI19: 6 | BJ19: =AX19/BI19 -> -196.61828
A20: =ELEC!C18 -> 44910 | B20: ='B5'!B19 -> 252 | C20: =B20*$B$4 -> 5422.0645 | D20: =SUM(B20) -> 252 | E20: =D20*$B$4 -> 5422.0645 | F20: =SUM(D20) -> 252 | G20: =F20*$B$4 -> 5422.0645 | H20: =SUM(F20) -> 252 | I20: =H20*$B$4 -> 5422.0645 | J20: =SUM(H20) -> 252 | K20: =J20*$B$4 -> 5422.0645 | L20: =SUM(J20) -> 252 | M20: =L20*$B$4 -> 5422.0645 | N20: =SUM(L20) -> 252 | O20: =N20*$B$4 -> 5422.0645 | P20: =SUM(N20) -> 252 | Q20: =P20*$B$4 -> 5422.0645 | R20: =SUM(P20) -> 252 | S20: =R20*$B$4 -> 5422.0645 | T20: =SUM(R20) -> 252 | U20: =T20*$B$4 -> 5422.0645 | V20: =SUM(T20) -> 252 | W20: =V20*$B$4 -> 5422.0645 | X20: =SUM(Y20/73370) -> 0.81290323 | Y20: =SUM(C20+E20+G20+I20+K20+M20+O20+Q20+S20+U20+W20) -> 59642.71 | Z20: ='B5'!C19 -> 258 | AA20: =SUM(Z20*$Z$4) -> 2580 | AB20: =SUM(Z20) -> 258 | AC20: =SUM(AB20*$Z$4) -> 2580 | AD20: =SUM(AB20) -> 258 | AE20: =SUM(AD20*$Z$4) -> 2580 | AF20: =SUM(AD20) -> 258 | AG20: =SUM(AF20*$Z$4) -> 2580 | AH20: =SUM(AF20) -> 258 | AI20: =SUM(AH20*$Z$4) -> 2580 | AJ20: =SUM(AH20) -> 258 | AK20: =SUM(AJ20*$Z$4) -> 2580 | AL20: =SUM(AJ20) -> 258 | AM20: =SUM(AL20*$Z$4) -> 2580 | AN20: =SUM(AO20/19600) -> 0.92142857 | AO20: =SUM(AA20+AC20+AE20+AG20+AI20+AK20+AM20) -> 18060 | AQ20: =SUM(AR20/92970) -> 0.83578261 | AR20: =Y20+AO20 -> 77702.71 | AS20: =SUM(AR20-AR19-AT20) -> -53.096774 | AT20: 6800 | AU20: 0.88 | AV20: =IF(AT20>0,AU20,AV19) -> 0.88 | AW20: =-SUM('B5'!AI19) -> -326 | AX20: =-SUM(AW20-AS20) -> 272.90323 | AY20: =SUM(AX20+AW20) -> -53.096774 | AZ20: =ELEC!A18 -> 0 | BA20: ='General information '!D19 -> 19 | BB20: =SUM('General information '!E19) -> 0.78 | BC20: =IF(AR19>=AR20,0,1) -> 1 | BD20: 19222 | BE20: =(305/1185)*ELEC!Q19 -> 0 | BG20: =#REF!-BE20 -> #REF! | BI20: 7 | BJ20: =AX20/BI20 -> 38.986175 | BK20: =GEN!AF17 -> 0.15284091
A21: =ELEC!C19 -> 44911 | B21: ='B5'!B20 -> 252 | C21: =B21*$B$4 -> 5422.0645 | D21: =SUM(B21) -> 252 | E21: =D21*$B$4 -> 5422.0645 | F21: =SUM(D21) -> 252 | G21: =F21*$B$4 -> 5422.0645 | H21: =SUM(F21) -> 252 | I21: =H21*$B$4 -> 5422.0645 | J21: =SUM(H21) -> 252 | K21: =J21*$B$4 -> 5422.0645 | L21: =SUM(J21) -> 252 | M21: =L21*$B$4 -> 5422.0645 | N21: =SUM(L21) -> 252 | O21: =N21*$B$4 -> 5422.0645 | P21: =SUM(N21) -> 252 | Q21: =P21*$B$4 -> 5422.0645 | R21: =SUM(P21) -> 252 | S21: =R21*$B$4 -> 5422.0645 | T21: =SUM(R21) -> 252 | U21: =T21*$B$4 -> 5422.0645 | V21: =SUM(T21) -> 252 | W21: =V21*$B$4 -> 5422.0645 | X21: =SUM(Y21/73370) -> 0.81290323 | Y21: =SUM(C21+E21+G21+I21+K21+M21+O21+Q21+S21+U21+W21) -> 59642.71 | Z21: ='B5'!C20 -> 258 | AA21: =SUM(Z21*$Z$4) -> 2580 | AB21: =SUM(Z21) -> 258 | AC21: =SUM(AB21*$Z$4) -> 2580 | AD21: =SUM(AB21) -> 258 | AE21: =SUM(AD21*$Z$4) -> 2580 | AF21: =SUM(AD21) -> 258 | AG21: =SUM(AF21*$Z$4) -> 2580 | AH21: =SUM(AF21) -> 258 | AI21: =SUM(AH21*$Z$4) -> 2580 | AJ21: =SUM(AH21) -> 258 | AK21: =SUM(AJ21*$Z$4) -> 2580 | AL21: =SUM(AJ21) -> 258 | AM21: =SUM(AL21*$Z$4) -> 2580 | AN21: =SUM(AO21/19600) -> 0.92142857 | AO21: =SUM(AA21+AC21+AE21+AG21+AI21+AK21+AM21) -> 18060 | AQ21: =SUM(AR21/92970) -> 0.83578261 | AR21: =Y21+AO21 -> 77702.71 | AS21: =SUM(AR21-AR20-AT21) -> 0 | AV21: =IF(AT21>0,AU21,AV20) -> 0.88 | AW21: =-SUM('B5'!AI20) -> 0 | AX21: =-SUM(AW21-AS21) -> 0 | AY21: =SUM(AX21+AW21) -> 0 | AZ21: =ELEC!A19 -> 0 | BA21: ='General information '!D20 -> 0 | BB21: =SUM('General information '!E20) -> 0 | BC21: =IF(AR20>=AR21,0,1) -> 0 | BD21: 19222 | BE21: =(305/1185)*ELEC!Q20 -> 0 | BG21: =#REF!-BE21 -> #REF! | BI21: 8 | BJ21: =AX21/BI21 -> 0 | BK21: =GEN!AF18 -> #DIV/0!
A22: =ELEC!C20 -> 44912 | B22: ='B5'!B21 -> 252 | C22: =B22*$B$4 -> 5422.0645 | D22: =SUM(B22) -> 252 | E22: =D22*$B$4 -> 5422.0645 | F22: =SUM(D22) -> 252 | G22: =F22*$B$4 -> 5422.0645 | H22: =SUM(F22) -> 252 | I22: =H22*$B$4 -> 5422.0645 | J22: =SUM(H22) -> 252 | K22: =J22*$B$4 -> 5422.0645 | L22: =SUM(J22) -> 252 | M22: =L22*$B$4 -> 5422.0645 | N22: =SUM(L22) -> 252 | O22: =N22*$B$4 -> 5422.0645 | P22: =SUM(N22) -> 252 | Q22: =P22*$B$4 -> 5422.0645 | R22: =SUM(P22) -> 252 | S22: =R22*$B$4 -> 5422.0645 | T22: =SUM(R22) -> 252 | U22: =T22*$B$4 -> 5422.0645 | V22: =SUM(T22) -> 252 | W22: =V22*$B$4 -> 5422.0645 | X22: =SUM(Y22/73370) -> 0.81290323 | Y22: =SUM(C22+E22+G22+I22+K22+M22+O22+Q22+S22+U22+W22) -> 59642.71 | Z22: ='B5'!C21 -> 258 | AA22: =SUM(Z22*$Z$4) -> 2580 | AB22: =SUM(Z22) -> 258 | AC22: =SUM(AB22*$Z$4) -> 2580 | AD22: =SUM(AB22) -> 258 | AE22: =SUM(AD22*$Z$4) -> 2580 | AF22: =SUM(AD22) -> 258 | AG22: =SUM(AF22*$Z$4) -> 2580 | AH22: =SUM(AF22) -> 258 | AI22: =SUM(AH22*$Z$4) -> 2580 | AJ22: =SUM(AH22) -> 258 | AK22: =SUM(AJ22*$Z$4) -> 2580 | AL22: =SUM(AJ22) -> 258 | AM22: =SUM(AL22*$Z$4) -> 2580 | AN22: =SUM(AO22/19600) -> 0.92142857 | AO22: =SUM(AA22+AC22+AE22+AG22+AI22+AK22+AM22) -> 18060 | AQ22: =SUM(AR22/92970) -> 0.83578261 | AR22: =Y22+AO22 -> 77702.71 | AS22: =SUM(AR22-AR21-AT22) -> 0 | AV22: =IF(AT22>0,AU22,AV21) -> 0.88 | AW22: =-SUM('B5'!AI21) -> 0 | AX22: =-SUM(AW22-AS22) -> 0 | AY22: =SUM(AX22+AW22) -> 0 | AZ22: =ELEC!A20 -> 0 | BA22: ='General information '!D21 -> 0 | BB22: =SUM('General information '!E21) -> 0 | BC22: =IF(AR21>=AR22,0,1) -> 0 | BD22: 19222 | BE22: =(305/1185)*ELEC!Q21 -> 642.173 | BG22: =#REF!-BE22 -> #REF! | BI22: 9 | BJ22: =AX22/BI22 -> 0 | BK22: =GEN!AF19 -> #DIV/0!
A23: =ELEC!C21 -> 44913 | B23: ='B5'!B22 -> 248 | C23: =B23*$B$4 -> 5336 | D23: =SUM(B23) -> 248 | E23: =D23*$B$4 -> 5336 | F23: =SUM(D23) -> 248 | G23: =F23*$B$4 -> 5336 | H23: =SUM(F23) -> 248 | I23: =H23*$B$4 -> 5336 | J23: =SUM(H23) -> 248 | K23: =J23*$B$4 -> 5336 | L23: =SUM(J23) -> 248 | M23: =L23*$B$4 -> 5336 | N23: =SUM(L23) -> 248 | O23: =N23*$B$4 -> 5336 | P23: =SUM(N23) -> 248 | Q23: =P23*$B$4 -> 5336 | R23: =SUM(P23) -> 248 | S23: =R23*$B$4 -> 5336 | T23: =SUM(R23) -> 248 | U23: =T23*$B$4 -> 5336 | V23: =SUM(T23) -> 248 | W23: =V23*$B$4 -> 5336 | X23: =SUM(Y23/73370) -> 0.8 | Y23: =SUM(C23+E23+G23+I23+K23+M23+O23+Q23+S23+U23+W23) -> 58696 | Z23: ='B5'!C22 -> 254 | AA23: =SUM(Z23*$Z$4) -> 2540 | AB23: =SUM(Z23) -> 254 | AC23: =SUM(AB23*$Z$4) -> 2540 | AD23: =SUM(AB23) -> 254 | AE23: =SUM(AD23*$Z$4) -> 2540 | AF23: =SUM(AD23) -> 254 | AG23: =SUM(AF23*$Z$4) -> 2540 | AH23: =SUM(AF23) -> 254 | AI23: =SUM(AH23*$Z$4) -> 2540 | AJ23: =SUM(AH23) -> 254 | AK23: =SUM(AJ23*$Z$4) -> 2540 | AL23: =SUM(AJ23) -> 254 | AM23: =SUM(AL23*$Z$4) -> 2540 | AN23: =SUM(AO23/19600) -> 0.90714286 | AO23: =SUM(AA23+AC23+AE23+AG23+AI23+AK23+AM23) -> 17780 | AQ23: =SUM(AR23/92970) -> 0.82258793 | AR23: =Y23+AO23 -> 76476 | AS23: =SUM(AR23-AR22-AT23) -> -1226.7097 | AV23: =IF(AT23>0,AU23,AV22) -> 0.88 | AW23: =-SUM('B5'!AI22) -> -281 | AX23: =-SUM(AW23-AS23) -> -945.70968 | AY23: =SUM(AX23+AW23) -> -1226.7097 | AZ23: =ELEC!A21 -> 0 | BA23: ='General information '!D22 -> 19 | BB23: =SUM('General information '!E22) -> 0.59 | BC23: =IF(AR22>=AR23,0,1) -> 0 | BD23: 19222 | BE23: =(305/1185)*ELEC!Q22 -> 689.27426 | BG23: =#REF!-BE23 -> #REF! | BI23: 10 | BJ23: =AX23/BI23 -> -94.570968 | BK23: =GEN!AF20 -> 0.14176136
A24: =ELEC!C22 -> 44914 | B24: ='B5'!B23 -> 244 | C24: =B24*$B$4 -> 5249.9355 | D24: =SUM(B24) -> 244 | E24: =D24*$B$4 -> 5249.9355 | F24: =SUM(D24) -> 244 | G24: =F24*$B$4 -> 5249.9355 | H24: =SUM(F24) -> 244 | I24: =H24*$B$4 -> 5249.9355 | J24: =SUM(H24) -> 244 | K24: =J24*$B$4 -> 5249.9355 | L24: =SUM(J24) -> 244 | M24: =L24*$B$4 -> 5249.9355 | N24: =SUM(L24) -> 244 | O24: =N24*$B$4 -> 5249.9355 | P24: =SUM(N24) -> 244 | Q24: =P24*$B$4 -> 5249.9355 | R24: =SUM(P24) -> 244 | S24: =R24*$B$4 -> 5249.9355 | T24: =SUM(R24) -> 244 | U24: =T24*$B$4 -> 5249.9355 | V24: =SUM(T24) -> 244 | W24: =V24*$B$4 -> 5249.9355 | X24: =SUM(Y24/73370) -> 0.78709677 | Y24: =SUM(C24+E24+G24+I24+K24+M24+O24+Q24+S24+U24+W24) -> 57749.29 | Z24: ='B5'!C23 -> 250 | AA24: =SUM(Z24*$Z$4) -> 2500 | AB24: =SUM(Z24) -> 250 | AC24: =SUM(AB24*$Z$4) -> 2500 | AD24: =SUM(AB24) -> 250 | AE24: =SUM(AD24*$Z$4) -> 2500 | AF24: =SUM(AD24) -> 250 | AG24: =SUM(AF24*$Z$4) -> 2500 | AH24: =SUM(AF24) -> 250 | AI24: =SUM(AH24*$Z$4) -> 2500 | AJ24: =SUM(AH24) -> 250 | AK24: =SUM(AJ24*$Z$4) -> 2500 | AL24: =SUM(AJ24) -> 250 | AM24: =SUM(AL24*$Z$4) -> 2500 | AN24: =SUM(AO24/19600) -> 0.89285714 | AO24: =SUM(AA24+AC24+AE24+AG24+AI24+AK24+AM24) -> 17500 | AQ24: =SUM(AR24/92970) -> 0.80939325 | AR24: =Y24+AO24 -> 75249.29 | AS24: =SUM(AR24-AR23-AT24) -> -1226.7097 | AV24: =IF(AT24>0,AU24,AV23) -> 0.88 | AW24: =-SUM('B5'!AI23) -> -162 | AX24: =-SUM(AW24-AS24) -> -1064.7097 | AY24: =SUM(AX24+AW24) -> -1226.7097 | AZ24: =ELEC!A22 -> 0 | BA24: ='General information '!D23 -> 18.5 | BB24: =SUM('General information '!E23) -> 0.53 | BC24: =IF(AR23>=AR24,0,1) -> 0 | BD24: 19222 | BE24: =(305/1185)*ELEC!Q23 -> 755.16456 | BG24: =#REF!-BE24 -> #REF! | BI24: 11 | BJ24: =AX24/BI24 -> -96.791789 | BK24: =GEN!AF21 -> 0.13947917
A25: =ELEC!C23 -> 44915 | B25: ='B5'!B24 -> 240 | C25: =B25*$B$4 -> 5163.871 | D25: =SUM(B25) -> 240 | E25: =D25*$B$4 -> 5163.871 | F25: =SUM(D25) -> 240 | G25: =F25*$B$4 -> 5163.871 | H25: =SUM(F25) -> 240 | I25: =H25*$B$4 -> 5163.871 | J25: =SUM(H25) -> 240 | K25: =J25*$B$4 -> 5163.871 | L25: =SUM(J25) -> 240 | M25: =L25*$B$4 -> 5163.871 | N25: =SUM(L25) -> 240 | O25: =N25*$B$4 -> 5163.871 | P25: =SUM(N25) -> 240 | Q25: =P25*$B$4 -> 5163.871 | R25: =SUM(P25) -> 240 | S25: =R25*$B$4 -> 5163.871 | T25: =SUM(R25) -> 240 | U25: =T25*$B$4 -> 5163.871 | V25: =SUM(T25) -> 240 | W25: =V25*$B$4 -> 5163.871 | X25: =SUM(Y25/73370) -> 0.77419355 | Y25: =SUM(C25+E25+G25+I25+K25+M25+O25+Q25+S25+U25+W25) -> 56802.581 | Z25: ='B5'!C24 -> 247 | AA25: =SUM(Z25*$Z$4) -> 2470 | AB25: =SUM(Z25) -> 247 | AC25: =SUM(AB25*$Z$4) -> 2470 | AD25: =SUM(AB25) -> 247 | AE25: =SUM(AD25*$Z$4) -> 2470 | AF25: =SUM(AD25) -> 247 | AG25: =SUM(AF25*$Z$4) -> 2470 | AH25: =SUM(AF25) -> 247 | AI25: =SUM(AH25*$Z$4) -> 2470 | AJ25: =SUM(AH25) -> 247 | AK25: =SUM(AJ25*$Z$4) -> 2470 | AL25: =SUM(AJ25) -> 247 | AM25: =SUM(AL25*$Z$4) -> 2470 | AN25: =SUM(AO25/19600) -> 0.88214286 | AO25: =SUM(AA25+AC25+AE25+AG25+AI25+AK25+AM25) -> 17290 | AQ25: =SUM(AR25/92970) -> 0.7969515 | AR25: =Y25+AO25 -> 74092.581 | AS25: =SUM(AR25-AR24-AT25) -> -1156.7097 | AV25: =IF(AT25>0,AU25,AV24) -> 0.88 | AW25: =-SUM('B5'!AI24) -> -128 | AX25: =-SUM(AW25-AS25) -> -1028.7097 | AY25: =SUM(AX25+AW25) -> -1156.7097 | AZ25: =ELEC!A23 -> 0 | BA25: ='General information '!D24 -> 18 | BB25: =SUM('General information '!E24) -> 0.49 | BC25: =IF(AR24>=AR25,0,1) -> 0 | BD25: 19222 | BE25: =(305/1185)*ELEC!Q24 -> 482.59494 | BG25: =#REF!-BE25 -> #REF! | BI25: 12 | BJ25: =AX25/BI25 -> -85.725806
A26: =ELEC!C24 -> 44916 | B26: ='B5'!B25 -> 237 | C26: =B26*$B$4 -> 5099.3226 | D26: =SUM(B26) -> 237 | E26: =D26*$B$4 -> 5099.3226 | F26: =SUM(D26) -> 237 | G26: =F26*$B$4 -> 5099.3226 | H26: =SUM(F26) -> 237 | I26: =H26*$B$4 -> 5099.3226 | J26: =SUM(H26) -> 237 | K26: =J26*$B$4 -> 5099.3226 | L26: =SUM(J26) -> 237 | M26: =L26*$B$4 -> 5099.3226 | N26: =SUM(L26) -> 237 | O26: =N26*$B$4 -> 5099.3226 | P26: =SUM(N26) -> 237 | Q26: =P26*$B$4 -> 5099.3226 | R26: =SUM(P26) -> 237 | S26: =R26*$B$4 -> 5099.3226 | T26: =SUM(R26) -> 237 | U26: =T26*$B$4 -> 5099.3226 | V26: =SUM(T26) -> 237 | W26: =V26*$B$4 -> 5099.3226 | X26: =SUM(Y26/73370) -> 0.76451613 | Y26: =SUM(C26+E26+G26+I26+K26+M26+O26+Q26+S26+U26+W26) -> 56092.548 | Z26: ='B5'!C25 -> 242 | AA26: =SUM(Z26*$Z$4) -> 2420 | AB26: =SUM(Z26) -> 242 | AC26: =SUM(AB26*$Z$4) -> 2420 | AD26: =SUM(AB26) -> 242 | AE26: =SUM(AD26*$Z$4) -> 2420 | AF26: =SUM(AD26) -> 242 | AG26: =SUM(AF26*$Z$4) -> 2420 | AH26: =SUM(AF26) -> 242 | AI26: =SUM(AH26*$Z$4) -> 2420 | AJ26: =SUM(AH26) -> 242 | AK26: =SUM(AJ26*$Z$4) -> 2420 | AL26: =SUM(AJ26) -> 242 | AM26: =SUM(AL26*$Z$4) -> 2420 | AN26: =SUM(AO26/19600) -> 0.86428571 | AO26: =SUM(AA26+AC26+AE26+AG26+AI26+AK26+AM26) -> 16940 | AQ26: =SUM(AR26/92970) -> 0.78554962 | AR26: =Y26+AO26 -> 73032.548 | AS26: =SUM(AR26-AR25-AT26) -> -1060.0323 | AV26: =IF(AT26>0,AU26,AV25) -> 0.88 | AW26: =-SUM('B5'!AI25) -> 0 | AX26: =-SUM(AW26-AS26) -> -1060.0323 | AY26: =SUM(AX26+AW26) -> -1060.0323 | AZ26: =ELEC!A24 -> 0 | BA26: ='General information '!D25 -> 16.5 | BB26: =SUM('General information '!E25) -> 0.48 | BC26: =IF(AR25>=AR26,0,1) -> 0 | BD26: 19222 | BE26: =(305/1185)*ELEC!Q25 -> 605.62447 | BG26: =#REF!-BE26 -> #REF! | BI26: 13 | BJ26: =AX26/BI26 -> -81.540943
A27: =ELEC!C25 -> 44917 | B27: ='B5'!B26 -> 234.5 | C27: =B27*$B$4 -> 5045.5323 | D27: =SUM(B27) -> 234.5 | E27: =D27*$B$4 -> 5045.5323 | F27: =SUM(D27) -> 234.5 | G27: =F27*$B$4 -> 5045.5323 | H27: =SUM(F27) -> 234.5 | I27: =H27*$B$4 -> 5045.5323 | J27: =SUM(H27) -> 234.5 | K27: =J27*$B$4 -> 5045.5323 | L27: =SUM(J27) -> 234.5 | M27: =L27*$B$4 -> 5045.5323 | N27: =SUM(L27) -> 234.5 | O27: =N27*$B$4 -> 5045.5323 | P27: =SUM(N27) -> 234.5 | Q27: =P27*$B$4 -> 5045.5323 | R27: =SUM(P27) -> 234.5 | S27: =R27*$B$4 -> 5045.5323 | T27: =SUM(R27) -> 234.5 | U27: =T27*$B$4 -> 5045.5323 | V27: =SUM(T27) -> 234.5 | W27: =V27*$B$4 -> 5045.5323 | X27: =SUM(Y27/73370) -> 0.75645161 | Y27: =SUM(C27+E27+G27+I27+K27+M27+O27+Q27+S27+U27+W27) -> 55500.855 | Z27: ='B5'!C26 -> 240 | AA27: =SUM(Z27*$Z$4) -> 2400 | AB27: =SUM(Z27) -> 240 | AC27: =SUM(AB27*$Z$4) -> 2400 | AD27: =SUM(AB27) -> 240 | AE27: =SUM(AD27*$Z$4) -> 2400 | AF27: =SUM(AD27) -> 240 | AG27: =SUM(AF27*$Z$4) -> 2400 | AH27: =SUM(AF27) -> 240 | AI27: =SUM(AH27*$Z$4) -> 2400 | AJ27: =SUM(AH27) -> 240 | AK27: =SUM(AJ27*$Z$4) -> 2400 | AL27: =SUM(AJ27) -> 240 | AM27: =SUM(AL27*$Z$4) -> 2400 | AN27: =SUM(AO27/19600) -> 0.85714286 | AO27: =SUM(AA27+AC27+AE27+AG27+AI27+AK27+AM27) -> 16800 | AQ27: =SUM(AR27/92970) -> 0.77767941 | AR27: =Y27+AO27 -> 72300.855 | AS27: =SUM(AR27-AR26-AT27) -> -731.69355 | AV27: =IF(AT27>0,AU27,AV26) -> 0.88 | AW27: =-SUM('B5'!AI26) -> -239 | AX27: =-SUM(AW27-AS27) -> -492.69355 | AY27: =SUM(AX27+AW27) -> -731.69355 | AZ27: =ELEC!A25 -> 0 | BA27: ='General information '!D26 -> 16.5 | BB27: =SUM('General information '!E26) -> 0.48 | BC27: =IF(AR26>=AR27,0,1) -> 0 | BD27: 19222 | BE27: =(305/1185)*ELEC!Q26 -> 101.66667 | BG27: =#REF!-BE27 -> #REF! | BI27: 14 | BJ27: =AX27/BI27 -> -35.192396 | BK27: =GEN!AF24 -> 0.12255208
A28: =ELEC!C26 -> 44918 | B28: ='B5'!B27 -> 234.5 | C28: =B28*$B$4 -> 5045.5323 | D28: =SUM(B28) -> 234.5 | E28: =D28*$B$4 -> 5045.5323 | F28: =SUM(D28) -> 234.5 | G28: =F28*$B$4 -> 5045.5323 | H28: =SUM(F28) -> 234.5 | I28: =H28*$B$4 -> 5045.5323 | J28: =SUM(H28) -> 234.5 | K28: =J28*$B$4 -> 5045.5323 | L28: =SUM(J28) -> 234.5 | M28: =L28*$B$4 -> 5045.5323 | N28: =SUM(L28) -> 234.5 | O28: =N28*$B$4 -> 5045.5323 | P28: =SUM(N28) -> 234.5 | Q28: =P28*$B$4 -> 5045.5323 | R28: =SUM(P28) -> 234.5 | S28: =R28*$B$4 -> 5045.5323 | T28: =SUM(R28) -> 234.5 | U28: =T28*$B$4 -> 5045.5323 | V28: =SUM(T28) -> 234.5 | W28: =V28*$B$4 -> 5045.5323 | X28: =SUM(Y28/73370) -> 0.75645161 | Y28: =SUM(C28+E28+G28+I28+K28+M28+O28+Q28+S28+U28+W28) -> 55500.855 | Z28: ='B5'!C27 -> 240 | AA28: =SUM(Z28*$Z$4) -> 2400 | AB28: =SUM(Z28) -> 240 | AC28: =SUM(AB28*$Z$4) -> 2400 | AD28: =SUM(AB28) -> 240 | AE28: =SUM(AD28*$Z$4) -> 2400 | AF28: =SUM(AD28) -> 240 | AG28: =SUM(AF28*$Z$4) -> 2400 | AH28: =SUM(AF28) -> 240 | AI28: =SUM(AH28*$Z$4) -> 2400 | AJ28: =SUM(AH28) -> 240 | AK28: =SUM(AJ28*$Z$4) -> 2400 | AL28: =SUM(AJ28) -> 240 | AM28: =SUM(AL28*$Z$4) -> 2400 | AN28: =SUM(AO28/19600) -> 0.85714286 | AO28: =SUM(AA28+AC28+AE28+AG28+AI28+AK28+AM28) -> 16800 | AQ28: =SUM(AR28/92970) -> 0.77767941 | AR28: =Y28+AO28 -> 72300.855 | AS28: =SUM(AR28-AR27-AT28) -> 0 | AV28: =IF(AT28>0,AU28,AV27) -> 0.88 | AW28: =-SUM('B5'!AI27) -> 0 | AX28: =-SUM(AW28-AS28) -> 0 | AY28: =SUM(AX28+AW28) -> 0 | AZ28: =ELEC!A26 -> 0 | BA28: ='General information '!D27 -> 0 | BB28: =SUM('General information '!E27) -> 0 | BC28: =IF(AR27>=AR28,0,1) -> 0 | BD28: 19222 | BE28: =(305/1185)*ELEC!Q27 -> 0 | BG28: =#REF!-BE28 -> #REF! | BI28: 15 | BJ28: =AX28/BI28 -> 0 | BK28: =GEN!AF25 -> #DIV/0!
A29: =ELEC!C27 -> 44919 | B29: ='B5'!B28 -> 234.5 | C29: =B29*$B$4 -> 5045.5323 | D29: =SUM(B29) -> 234.5 | E29: =D29*$B$4 -> 5045.5323 | F29: =SUM(D29) -> 234.5 | G29: =F29*$B$4 -> 5045.5323 | H29: =SUM(F29) -> 234.5 | I29: =H29*$B$4 -> 5045.5323 | J29: =SUM(H29) -> 234.5 | K29: =J29*$B$4 -> 5045.5323 | L29: =SUM(J29) -> 234.5 | M29: =L29*$B$4 -> 5045.5323 | N29: =SUM(L29) -> 234.5 | O29: =N29*$B$4 -> 5045.5323 | P29: =SUM(N29) -> 234.5 | Q29: =P29*$B$4 -> 5045.5323 | R29: =SUM(P29) -> 234.5 | S29: =R29*$B$4 -> 5045.5323 | T29: =SUM(R29) -> 234.5 | U29: =T29*$B$4 -> 5045.5323 | V29: =SUM(T29) -> 234.5 | W29: =V29*$B$4 -> 5045.5323 | X29: =SUM(Y29/73370) -> 0.75645161 | Y29: =SUM(C29+E29+G29+I29+K29+M29+O29+Q29+S29+U29+W29) -> 55500.855 | Z29: ='B5'!C28 -> 240 | AA29: =SUM(Z29*$Z$4) -> 2400 | AB29: =SUM(Z29) -> 240 | AC29: =SUM(AB29*$Z$4) -> 2400 | AD29: =SUM(AB29) -> 240 | AE29: =SUM(AD29*$Z$4) -> 2400 | AF29: =SUM(AD29) -> 240 | AG29: =SUM(AF29*$Z$4) -> 2400 | AH29: =SUM(AF29) -> 240 | AI29: =SUM(AH29*$Z$4) -> 2400 | AJ29: =SUM(AH29) -> 240 | AK29: =SUM(AJ29*$Z$4) -> 2400 | AL29: =SUM(AJ29) -> 240 | AM29: =SUM(AL29*$Z$4) -> 2400 | AN29: =SUM(AO29/19600) -> 0.85714286 | AO29: =SUM(AA29+AC29+AE29+AG29+AI29+AK29+AM29) -> 16800 | AQ29: =SUM(AR29/92970) -> 0.77767941 | AR29: =Y29+AO29 -> 72300.855 | AS29: =SUM(AR29-AR28-AT29) -> 0 | AV29: =IF(AT29>0,AU29,AV28) -> 0.88 | AW29: =-SUM('B5'!AI28) -> 0 | AX29: =-SUM(AW29-AS29) -> 0 | AY29: =SUM(AX29+AW29) -> 0 | AZ29: =ELEC!A27 -> 0 | BA29: ='General information '!D28 -> 0 | BB29: =SUM('General information '!E28) -> 0 | BC29: =IF(AR28>=AR29,0,1) -> 0 | BD29: 19222 | BE29: =(305/1185)*ELEC!Q28 -> 0 | BG29: =#REF!-BE29 -> #REF! | BI29: 16 | BJ29: =AX29/BI29 -> 0 | BK29: =GEN!AF26 -> #DIV/0!
A30: =ELEC!C28 -> 44920 | B30: ='B5'!B29 -> 234.5 | C30: =B30*$B$4 -> 5045.5323 | D30: =SUM(B30) -> 234.5 | E30: =D30*$B$4 -> 5045.5323 | F30: =SUM(D30) -> 234.5 | G30: =F30*$B$4 -> 5045.5323 | H30: =SUM(F30) -> 234.5 | I30: =H30*$B$4 -> 5045.5323 | J30: =SUM(H30) -> 234.5 | K30: =J30*$B$4 -> 5045.5323 | L30: =SUM(J30) -> 234.5 | M30: =L30*$B$4 -> 5045.5323 | N30: =SUM(L30) -> 234.5 | O30: =N30*$B$4 -> 5045.5323 | P30: =SUM(N30) -> 234.5 | Q30: =P30*$B$4 -> 5045.5323 | R30: =SUM(P30) -> 234.5 | S30: =R30*$B$4 -> 5045.5323 | T30: =SUM(R30) -> 234.5 | U30: =T30*$B$4 -> 5045.5323 | V30: =SUM(T30) -> 234.5 | W30: =V30*$B$4 -> 5045.5323 | X30: =SUM(Y30/73370) -> 0.75645161 | Y30: =SUM(C30+E30+G30+I30+K30+M30+O30+Q30+S30+U30+W30) -> 55500.855 | Z30: ='B5'!C29 -> 240 | AA30: =SUM(Z30*$Z$4) -> 2400 | AB30: =SUM(Z30) -> 240 | AC30: =SUM(AB30*$Z$4) -> 2400 | AD30: =SUM(AB30) -> 240 | AE30: =SUM(AD30*$Z$4) -> 2400 | AF30: =SUM(AD30) -> 240 | AG30: =SUM(AF30*$Z$4) -> 2400 | AH30: =SUM(AF30) -> 240 | AI30: =SUM(AH30*$Z$4) -> 2400 | AJ30: =SUM(AH30) -> 240 | AK30: =SUM(AJ30*$Z$4) -> 2400 | AL30: =SUM(AJ30) -> 240 | AM30: =SUM(AL30*$Z$4) -> 2400 | AN30: =SUM(AO30/19600) -> 0.85714286 | AO30: =SUM(AA30+AC30+AE30+AG30+AI30+AK30+AM30) -> 16800 | AQ30: =SUM(AR30/92970) -> 0.77767941 | AR30: =Y30+AO30 -> 72300.855 | AS30: =SUM(AR30-AR29-AT30) -> 0 | AV30: =IF(AT30>0,AU30,AV29) -> 0.88 | AW30: =-SUM('B5'!AI29) -> 0 | AX30: =-SUM(AW30-AS30) -> 0 | AY30: =SUM(AX30+AW30) -> 0 | AZ30: =ELEC!A28 -> 0 | BA30: ='General information '!D29 -> 0 | BB30: =SUM('General information '!E29) -> 0 | BC30: =IF(AR29>=AR30,0,1) -> 0 | BD30: 19222 | BE30: =(305/1185)*ELEC!Q29 -> 374.75105 | BG30: =#REF!-BE30 -> #REF! | BI30: 17 | BJ30: =AX30/BI30 -> 0 | BK30: =GEN!AF27 -> #DIV/0!
A31: =ELEC!C29 -> 44921 | B31: ='B5'!B30 -> 231 | C31: =B31*$B$4 -> 4970.2258 | D31: =SUM(B31) -> 231 | E31: =D31*$B$4 -> 4970.2258 | F31: =SUM(D31) -> 231 | G31: =F31*$B$4 -> 4970.2258 | H31: =SUM(F31) -> 231 | I31: =H31*$B$4 -> 4970.2258 | J31: =SUM(H31) -> 231 | K31: =J31*$B$4 -> 4970.2258 | L31: =SUM(J31) -> 231 | M31: =L31*$B$4 -> 4970.2258 | N31: =SUM(L31) -> 231 | O31: =N31*$B$4 -> 4970.2258 | P31: =SUM(N31) -> 231 | Q31: =P31*$B$4 -> 4970.2258 | R31: =SUM(P31) -> 231 | S31: =R31*$B$4 -> 4970.2258 | T31: =SUM(R31) -> 231 | U31: =T31*$B$4 -> 4970.2258 | V31: =SUM(T31) -> 231 | W31: =V31*$B$4 -> 4970.2258 | X31: =SUM(Y31/73370) -> 0.74516129 | Y31: =SUM(C31+E31+G31+I31+K31+M31+O31+Q31+S31+U31+W31) -> 54672.484 | Z31: ='B5'!C30 -> 238 | AA31: =SUM(Z31*$Z$4) -> 2380 | AB31: =SUM(Z31) -> 238 | AC31: =SUM(AB31*$Z$4) -> 2380 | AD31: =SUM(AB31) -> 238 | AE31: =SUM(AD31*$Z$4) -> 2380 | AF31: =SUM(AD31) -> 238 | AG31: =SUM(AF31*$Z$4) -> 2380 | AH31: =SUM(AF31) -> 238 | AI31: =SUM(AH31*$Z$4) -> 2380 | AJ31: =SUM(AH31) -> 238 | AK31: =SUM(AJ31*$Z$4) -> 2380 | AL31: =SUM(AJ31) -> 238 | AM31: =SUM(AL31*$Z$4) -> 2380 | AN31: =SUM(AO31/19600) -> 0.85 | AO31: =SUM(AA31+AC31+AE31+AG31+AI31+AK31+AM31) -> 16660 | AQ31: =SUM(AR31/92970) -> 0.76726346 | AR31: =Y31+AO31 -> 71332.484 | AS31: =SUM(AR31-AR30-AT31) -> -968.37097 | AV31: =IF(AT31>0,AU31,AV30) -> 0.88 | AW31: =-SUM('B5'!AI30) -> -175 | AX31: =-SUM(AW31-AS31) -> -793.37097 | AY31: =SUM(AX31+AW31) -> -968.37097 | AZ31: =ELEC!A29 -> 0 | BA31: ='General information '!D30 -> 13.5 | BB31: =SUM('General information '!E30) -> 0.52 | BC31: =IF(AR30>=AR31,0,1) -> 0 | BD31: 19222 | BE31: =(305/1185)*ELEC!Q30 -> 591.46835 | BG31: =#REF!-BE31 -> #REF! | BI31: 18 | BJ31: =AX31/BI31 -> -44.076165 | BK31: =GEN!AF28 -> 0.10111111
A32: =ELEC!C30 -> 44922 | B32: ='B5'!B31 -> 228 | C32: =B32*$B$4 -> 4905.6774 | D32: =SUM(B32) -> 228 | E32: =D32*$B$4 -> 4905.6774 | F32: =SUM(D32) -> 228 | G32: =F32*$B$4 -> 4905.6774 | H32: =SUM(F32) -> 228 | I32: =H32*$B$4 -> 4905.6774 | J32: =SUM(H32) -> 228 | K32: =J32*$B$4 -> 4905.6774 | L32: =SUM(J32) -> 228 | M32: =L32*$B$4 -> 4905.6774 | N32: =SUM(L32) -> 228 | O32: =N32*$B$4 -> 4905.6774 | P32: =SUM(N32) -> 228 | Q32: =P32*$B$4 -> 4905.6774 | R32: =SUM(P32) -> 228 | S32: =R32*$B$4 -> 4905.6774 | T32: =SUM(R32) -> 228 | U32: =T32*$B$4 -> 4905.6774 | V32: =SUM(T32) -> 228 | W32: =V32*$B$4 -> 4905.6774 | X32: =SUM(Y32/73370) -> 0.73548387 | Y32: =SUM(C32+E32+G32+I32+K32+M32+O32+Q32+S32+U32+W32) -> 53962.452 | Z32: ='B5'!C31 -> 235 | AA32: =SUM(Z32*$Z$4) -> 2350 | AB32: =SUM(Z32) -> 235 | AC32: =SUM(AB32*$Z$4) -> 2350 | AD32: =SUM(AB32) -> 235 | AE32: =SUM(AD32*$Z$4) -> 2350 | AF32: =SUM(AD32) -> 235 | AG32: =SUM(AF32*$Z$4) -> 2350 | AH32: =SUM(AF32) -> 235 | AI32: =SUM(AH32*$Z$4) -> 2350 | AJ32: =SUM(AH32) -> 235 | AK32: =SUM(AJ32*$Z$4) -> 2350 | AL32: =SUM(AJ32) -> 235 | AM32: =SUM(AL32*$Z$4) -> 2350 | AN32: =SUM(AO32/19600) -> 0.83928571 | AO32: =SUM(AA32+AC32+AE32+AG32+AI32+AK32+AM32) -> 16450 | AQ32: =SUM(AR32/92970) -> 0.75736745 | AR32: =Y32+AO32 -> 70412.452 | AS32: =SUM(AR32-AR31-AT32) -> -920.03226 | AV32: =IF(AT32>0,AU32,AV31) -> 0.88 | AW32: =-SUM('B5'!AI31) -> -177 | AX32: =-SUM(AW32-AS32) -> -743.03226 | AY32: =SUM(AX32+AW32) -> -920.03226 | AZ32: =ELEC!A30 -> 0 | BA32: ='General information '!D31 -> 65 | BB32: =SUM('General information '!E31) -> 0.65 | BC32: =IF(AR31>=AR32,0,1) -> 0 | BD32: 19222 | BE32: =(305/1185)*ELEC!Q31 -> 0 | BG32: =#REF!-BE32 -> #REF! | BI32: 19 | BJ32: =AX32/BI32 -> -39.106961 | BK32: =GEN!AF29 -> 0.13056818
A33: =ELEC!C31 -> 44923 | B33: ='B5'!B32 -> 228 | C33: =B33*$B$4 -> 4905.6774 | D33: =SUM(B33) -> 228 | E33: =D33*$B$4 -> 4905.6774 | F33: =SUM(D33) -> 228 | G33: =F33*$B$4 -> 4905.6774 | H33: =SUM(F33) -> 228 | I33: =H33*$B$4 -> 4905.6774 | J33: =SUM(H33) -> 228 | K33: =J33*$B$4 -> 4905.6774 | L33: =SUM(J33) -> 228 | M33: =L33*$B$4 -> 4905.6774 | N33: =SUM(L33) -> 228 | O33: =N33*$B$4 -> 4905.6774 | P33: =SUM(N33) -> 228 | Q33: =P33*$B$4 -> 4905.6774 | R33: =SUM(P33) -> 228 | S33: =R33*$B$4 -> 4905.6774 | T33: =SUM(R33) -> 228 | U33: =T33*$B$4 -> 4905.6774 | V33: =SUM(T33) -> 228 | W33: =V33*$B$4 -> 4905.6774 | X33: =SUM(Y33/73370) -> 0.73548387 | Y33: =SUM(C33+E33+G33+I33+K33+M33+O33+Q33+S33+U33+W33) -> 53962.452 | Z33: ='B5'!C32 -> 235 | AA33: =SUM(Z33*$Z$4) -> 2350 | AB33: =SUM(Z33) -> 235 | AC33: =SUM(AB33*$Z$4) -> 2350 | AD33: =SUM(AB33) -> 235 | AE33: =SUM(AD33*$Z$4) -> 2350 | AF33: =SUM(AD33) -> 235 | AG33: =SUM(AF33*$Z$4) -> 2350 | AH33: =SUM(AF33) -> 235 | AI33: =SUM(AH33*$Z$4) -> 2350 | AJ33: =SUM(AH33) -> 235 | AK33: =SUM(AJ33*$Z$4) -> 2350 | AL33: =SUM(AJ33) -> 235 | AM33: =SUM(AL33*$Z$4) -> 2350 | AN33: =SUM(AO33/19600) -> 0.83928571 | AO33: =SUM(AA33+AC33+AE33+AG33+AI33+AK33+AM33) -> 16450 | AQ33: =SUM(AR33/92970) -> 0.75736745 | AR33: =Y33+AO33 -> 70412.452 | AS33: =SUM(AR33-AR32-AT33) -> 0 | AV33: =IF(AT33>0,AU33,AV32) -> 0.88 | AW33: =-SUM('B5'!AI32) -> 0 | AX33: =-SUM(AW33-AS33) -> 0 | AY33: =SUM(AX33+AW33) -> 0 | AZ33: =ELEC!A31 -> 0 | BA33: ='General information '!D32 -> 0 | BB33: =SUM('General information '!E32) -> 0 | BC33: =IF(AR32>=AR33,0,1) -> 0 | BD33: 19222 | BE33: =(305/1185)*ELEC!#REF! -> #REF! | BG33: =#REF!-BE33 -> #REF! | BI33: 20 | BJ33: =AX33/BI33 -> 0 | BK33: =GEN!AF30 -> #DIV/0!
A34: =ELEC!C32 -> 44924 | B34: ='B5'!B33 -> 228 | C34: =B34*$B$4 -> 4905.6774 | D34: =SUM(B34) -> 228 | E34: =D34*$B$4 -> 4905.6774 | F34: =SUM(D34) -> 228 | G34: =F34*$B$4 -> 4905.6774 | H34: =SUM(F34) -> 228 | I34: =H34*$B$4 -> 4905.6774 | J34: =SUM(H34) -> 228 | K34: =J34*$B$4 -> 4905.6774 | L34: =SUM(J34) -> 228 | M34: =L34*$B$4 -> 4905.6774 | N34: =SUM(L34) -> 228 | O34: =N34*$B$4 -> 4905.6774 | P34: =SUM(N34) -> 228 | Q34: =P34*$B$4 -> 4905.6774 | R34: =SUM(P34) -> 228 | S34: =R34*$B$4 -> 4905.6774 | T34: =SUM(R34) -> 228 | U34: =T34*$B$4 -> 4905.6774 | V34: =SUM(T34) -> 228 | W34: =V34*$B$4 -> 4905.6774 | X34: =SUM(Y34/73370) -> 0.73548387 | Y34: =SUM(C34+E34+G34+I34+K34+M34+O34+Q34+S34+U34+W34) -> 53962.452 | Z34: ='B5'!C33 -> 235 | AA34: =SUM(Z34*$Z$4) -> 2350 | AB34: =SUM(Z34) -> 235 | AC34: =SUM(AB34*$Z$4) -> 2350 | AD34: =SUM(AB34) -> 235 | AE34: =SUM(AD34*$Z$4) -> 2350 | AF34: =SUM(AD34) -> 235 | AG34: =SUM(AF34*$Z$4) -> 2350 | AH34: =SUM(AF34) -> 235 | AI34: =SUM(AH34*$Z$4) -> 2350 | AJ34: =SUM(AH34) -> 235 | AK34: =SUM(AJ34*$Z$4) -> 2350 | AL34: =SUM(AJ34) -> 235 | AM34: =SUM(AL34*$Z$4) -> 2350 | AN34: =SUM(AO34/19600) -> 0.83928571 | AO34: =SUM(AA34+AC34+AE34+AG34+AI34+AK34+AM34) -> 16450 | AQ34: =SUM(AR34/92970) -> 0.75736745 | AR34: =Y34+AO34 -> 70412.452 | AS34: =SUM(AR34-AR33-AT34) -> 0 | AV34: =IF(AT34>0,AU34,AV33) -> 0.88 | AW34: =-SUM('B5'!AI33) -> 0 | AX34: =-SUM(AW34-AS34) -> 0 | AY34: =SUM(AX34+AW34) -> 0 | AZ34: =ELEC!A32 -> 0 | BA34: ='General information '!D33 -> 0 | BB34: =SUM('General information '!E33) -> 0 | BC34: =IF(AR33>=AR34,0,1) -> 0 | BD34: 19223 | BE34: =(305/1185)*ELEC!#REF! -> #REF! | BG34: =#REF!-BE34 -> #REF! | BI34: 21 | BJ34: =AX34/BI34 -> 0 | BK34: =GEN!AF31 -> #DIV/0!
A35: =ELEC!C33 -> 44925 | B35: ='B5'!B34 -> 228 | C35: =B35*$B$4 -> 4905.6774 | D35: =SUM(B35) -> 228 | E35: =D35*$B$4 -> 4905.6774 | F35: =SUM(D35) -> 228 | G35: =F35*$B$4 -> 4905.6774 | H35: =SUM(F35) -> 228 | I35: =H35*$B$4 -> 4905.6774 | J35: =SUM(H35) -> 228 | K35: =J35*$B$4 -> 4905.6774 | L35: =SUM(J35) -> 228 | M35: =L35*$B$4 -> 4905.6774 | N35: =SUM(L35) -> 228 | O35: =N35*$B$4 -> 4905.6774 | P35: =SUM(N35) -> 228 | Q35: =P35*$B$4 -> 4905.6774 | R35: =SUM(P35) -> 228 | S35: =R35*$B$4 -> 4905.6774 | T35: =SUM(R35) -> 228 | U35: =T35*$B$4 -> 4905.6774 | V35: =SUM(T35) -> 228 | W35: =V35*$B$4 -> 4905.6774 | X35: =SUM(Y35/73370) -> 0.73548387 | Y35: =SUM(C35+E35+G35+I35+K35+M35+O35+Q35+S35+U35+W35) -> 53962.452 | Z35: ='B5'!C34 -> 235 | AA35: =SUM(Z35*$Z$4) -> 2350 | AB35: =SUM(Z35) -> 235 | AC35: =SUM(AB35*$Z$4) -> 2350 | AD35: =SUM(AB35) -> 235 | AE35: =SUM(AD35*$Z$4) -> 2350 | AF35: =SUM(AD35) -> 235 | AG35: =SUM(AF35*$Z$4) -> 2350 | AH35: =SUM(AF35) -> 235 | AI35: =SUM(AH35*$Z$4) -> 2350 | AJ35: =SUM(AH35) -> 235 | AK35: =SUM(AJ35*$Z$4) -> 2350 | AL35: =SUM(AJ35) -> 235 | AM35: =SUM(AL35*$Z$4) -> 2350 | AN35: =SUM(AO35/19600) -> 0.83928571 | AO35: =SUM(AA35+AC35+AE35+AG35+AI35+AK35+AM35) -> 16450 | AQ35: =SUM(AR35/92970) -> 0.75736745 | AR35: =Y35+AO35 -> 70412.452 | AS35: =SUM(AR35-AR34-AT35) -> 0 | AV35: =IF(AT35>0,AU35,AV34) -> 0.88 | AW35: =-SUM('B5'!AI34) -> 0 | AX35: =-SUM(AW35-AS35) -> 0 | AY35: =SUM(AX35+AW35) -> 0 | AZ35: =ELEC!A33 -> 0 | BA35: ='General information '!D34 -> 0 | BB35: =SUM('General information '!E34) -> 0 | BC35: =IF(AR34>=AR35,0,1) -> 0 | BD35: 19224 | BE35: =(305/1185)*ELEC!#REF! -> #REF! | BG35: =#REF!-BE35 -> #REF! | BI35: 22 | BJ35: =AX35/BI35 -> 0 | BK35: =GEN!AF32 -> #DIV/0!
