Workbook

Sheet TOTAL
A1: Site Name | B1: Day | C1: Month | D1: Year | E1: Total Electricity Kwh | F1: Electricity Tariff ($/Kwh) | G1: LPG (Kg) | H1: LPG $/Kg | I1: Water Utility Supply (m3) m3 | J1: Water Utility Supply (m3) $/m3 | K1: Room Nights | L1: Total Guests | M1: Utilities day cost dh
A2: Casablanca | B2: 1 | C2: 12 | D2: 2022 | E2: =submetering!E2+submetering!F2+submetering!G2 -> 13281 | F2: 1.05 | G2: ='Consommation mensuel énergie'!V10 -> 351.99131 | H2: 12.44 | I2: ='Consommation mensuel énergie'!F10 -> 112.1 | J2: 11.4 | K2: ='Consommation mensuel énergie'!D10 -> 88 | L2: ='Consommation mensuel énergie'!E10 -> 107 | M2: =E2*F2+G2*H2+#REF!*#REF!+I2*J2 -> #REF!
A3: Casablanca | B3: =B2+1 -> 2 | C3: 12 | D3: 2022 | E3: =submetering!E3+submetering!F3+submetering!G3 -> 13854 | F3: 1.05 | G3: ='Consommation mensuel énergie'!V11 -> 223.99447 | H3: 12.44 | I3: ='Consommation mensuel énergie'!F11 -> 125 | J3: 11.4 | K3: ='Consommation mensuel énergie'!D11 -> 102 | L3: ='Consommation mensuel énergie'!E11 -> 145 | M3: =E3*F3+G3*H3+#REF!*#REF!+I3*J3 -> #REF!
A4: Casablanca | B4: =B3+1 -> 3 | C4: 12 | D4: 2022 | E4: =submetering!E4+submetering!F4+submetering!G4 -> 13502 | F4: 1.05 | G4: ='Consommation mensuel énergie'!V12 -> 479.98815 | H4: 12.44 | I4: ='Consommation mensuel énergie'!F12 -> 122 | J4: 11.4 | K4: ='Consommation mensuel énergie'!D12 -> 80 | L4: ='Consommation mensuel énergie'!E12 -> 120 | M4: =E4*F4+G4*H4+#REF!*#REF!+I4*J4 -> #REF!
A5: Casablanca | B5: =B4+1 -> 4 | C5: 12 | D5: 2022 | E5: =submetering!E5+submetering!F5+submetering!G5 -> 13046 | F5: 1.05 | G5: ='Consommation mensuel énergie'!V13 -> 545.0149 | H5: 12.44 | I5: ='Consommation mensuel énergie'!F13 -> 131 | J5: 11.4 | K5: ='Consommation mensuel énergie'!D13 -> 86 | L5: ='Consommation mensuel énergie'!E13 -> 135 | M5: =E5*F5+G5*H5+#REF!*#REF!+I5*J5 -> #REF!
A6: Casablanca | B6: =B5+1 -> 5 | C6: 12 | D6: 2022 | E6: =submetering!E6+submetering!F6+submetering!G6 -> 13133 | F6: 1.05 | G6: ='Consommation mensuel énergie'!V14 -> 255.99368 | H6: 12.44 | I6: ='Consommation mensuel énergie'!F14 -> 122 | J6: 11.4 | K6: ='Consommation mensuel énergie'!D14 -> 108 | L6: ='Consommation mensuel énergie'!E14 -> 142 | M6: =E6*F6+G6*H6+#REF!*#REF!+I6*J6 -> #REF!
A7: Casablanca | B7: =B6+1 -> 6 | C7: 12 | D7: 2022 | E7: =submetering!E7+submetering!F7+submetering!G7 -> 12619 | F7: 1.05 | G7: ='Consommation mensuel énergie'!V15 -> 287.99289 | H7: 12.44 | I7: ='Consommation mensuel énergie'!F15 -> 132 | J7: 11.4 | K7: ='Consommation mensuel énergie'!D15 -> 105 | L7: ='Consommation mensuel énergie'!E15 -> 139 | M7: =E7*F7+G7*H7+#REF!*#REF!+I7*J7 -> #REF!
A8: Casablanca | B8: =B7+1 -> 7 | C8: 12 | D8: 2022 | E8: =submetering!E8+submetering!F8+submetering!G8 -> 14152 | F8: 1.05 | G8: ='Consommation mensuel énergie'!V16 -> 1215.97 | H8: 12.44 | I8: ='Consommation mensuel énergie'!F16 -> 121 | J8: 11.4 | K8: ='Consommation mensuel énergie'!D16 -> 114 | L8: ='Consommation mensuel énergie'!E16 -> 154 | M8: =E8*F8+G8*H8+#REF!*#REF!+I8*J8 -> #REF!
A9: Casablanca | B9: =B8+1 -> 8 | C9: 12 | D9: 2022 | E9: =submetering!E9+submetering!F9+submetering!G9 -> 13927 | F9: 1.05 | G9: ='Consommation mensuel énergie'!V17 -> 351.99131 | H9: 12.44 | I9: ='Consommation mensuel énergie'!F17 -> 110 | J9: 11.4 | K9: ='Consommation mensuel énergie'!D17 -> 107 | L9: ='Consommation mensuel énergie'!E17 -> 141 | M9: =E9*F9+G9*H9+#REF!*#REF!+I9*J9 -> #REF!
A10: Casablanca | B10: =B9+1 -> 9 | C10: 12 | D10: 2022 | E10: =submetering!E10+submetering!F10+submetering!G10 -> 14120 | F10: 1.05 | G10: ='Consommation mensuel énergie'!V18 -> 255.99368 | H10: 12.44 | I10: ='Consommation mensuel énergie'!F18 -> 141 | J10: 11.4 | K10: ='Consommation mensuel énergie'!D18 -> 125 | L10: ='Consommation mensuel énergie'!E18 -> 174 | M10: =E10*F10+G10*H10+#REF!*#REF!+I10*J10 -> #REF!
A11: Casablanca | B11: =B10+1 -> 10 | C11: 12 | D11: 2022 | E11: =submetering!E11+submetering!F11+submetering!G11 -> 15645 | F11: 1.05 | G11: ='Consommation mensuel énergie'!V19 -> 383.99052 | H11: 12.44 | I11: ='Consommation mensuel énergie'!F19 -> 129 | J11: 11.4 | K11: ='Consommation mensuel énergie'!D19 -> 96 | L11: ='Consommation mensuel énergie'!E19 -> 135 | M11: =E11*F11+G11*H11+#REF!*#REF!+I11*J11 -> #REF!
A12: Casablanca | B12: =B11+1 -> 11 | C12: 12 | D12: 2022 | E12: =submetering!E12+submetering!F12+submetering!G12 -> 14067 | F12: 1.05 | G12: ='Consommation mensuel énergie'!V20 -> 383.99052 | H12: 12.44 | I12: ='Consommation mensuel énergie'!F20 -> 114 | J12: 11.4 | K12: ='Consommation mensuel énergie'!D20 -> 77 | L12: ='Consommation mensuel énergie'!E20 -> 124 | M12: =E12*F12+G12*H12+#REF!*#REF!+I12*J12 -> #REF!
A13: Casablanca | B13: =B12+1 -> 12 | C13: 12 | D13: 2022 | E13: =submetering!E13+submetering!F13+submetering!G13 -> 12381 | F13: 1.05 | G13: ='Consommation mensuel énergie'!V21 -> 255.99368 | H13: 12.44 | I13: ='Consommation mensuel énergie'!F21 -> 120 | J13: 11.4 | K13: ='Consommation mensuel énergie'!D21 -> 66 | L13: ='Consommation mensuel énergie'!E21 -> 93 | M13: =E13*F13+G13*H13+#REF!*#REF!+I13*J13 -> #REF!
A14: Casablanca | B14: =B13+1 -> 13 | C14: 12 | D14: 2022 | E14: =submetering!E14+submetering!F14+submetering!G14 -> 14829 | F14: 1.05 | G14: ='Consommation mensuel énergie'!V22 -> 479.98815 | H14: 12.44 | I14: ='Consommation mensuel énergie'!F22 -> 89 | J14: 11.4 | K14: ='Consommation mensuel énergie'!D22 -> 106 | L14: ='Consommation mensuel énergie'!E22 -> 137 | M14: =E14*F14+G14*H14+#REF!*#REF!+I14*J14 -> #REF!
... A26: Casablanca | B26: =B25+1 -> 25 | C26: 12 | D26: 2022 | E26: =submetering!E26+submetering!F26+submetering!G26 -> 12976 | F26: 1.05 | G26: ='Consommation mensuel énergie'!V34 -> 511.98736 | H26: 12.44 | I26: ='Consommation mensuel énergie'!F34 -> 126 | J26: 11.4 | K26: ='Consommation mensuel énergie'!D34 -> 120 | L26: ='Consommation mensuel énergie'!E34 -> 220 | M26: =E26*F26+G26*H26+#REF!*#REF!+I26*J26 -> #REF!
A27: Casablanca | B27: =B26+1 -> 26 | C27: 12 | D27: 2022 | E27: =submetering!E27+submetering!F27+submetering!G27 -> 13228 | F27: 1.05 | G27: ='Consommation mensuel énergie'!V35 -> 447.98894 | H27: 12.44 | I27: ='Consommation mensuel énergie'!F35 -> 170 | J27: 11.4 | K27: ='Consommation mensuel énergie'!D35 -> 117 | L27: ='Consommation mensuel énergie'!E35 -> 221
A28: Casablanca | B28: =B27+1 -> 27 | C28: 12 | D28: 2022 | E28: =submetering!E28+submetering!F28+submetering!G28 -> 13553 | F28: 1.05 | G28: ='Consommation mensuel énergie'!V36 -> 863.97867 | H28: 12.44 | I28: ='Consommation mensuel énergie'!F36 -> 153 | J28: 11.4 | K28: ='Consommation mensuel énergie'!D36 -> 160 | L28: ='Consommation mensuel énergie'!E36 -> 297
A29: Casablanca | B29: =B28+1 -> 28 | C29: 12 | D29: 2022 | E29: =submetering!E29+submetering!F29+submetering!G29 -> 12945 | F29: 1.05 | G29: ='Consommation mensuel énergie'!V37 -> 0 | H29: 12.44 | I29: ='Consommation mensuel énergie'!F37 -> 161 | J29: 11.4 | K29: ='Consommation mensuel énergie'!D37 -> 151 | L29: ='Consommation mensuel énergie'!E37 -> 284
A30: Casablanca | B30: =B29+1 -> 29 | C30: 12 | D30: 2022 | E30: =submetering!E30+submetering!F30+submetering!G30 -> 0 | F30: 1.05 | G30: ='Consommation mensuel énergie'!V38 -> 0 | H30: 12.44 | I30: ='Consommation mensuel énergie'!F38 -> 0 | J30: 11.4 | K30: ='Consommation mensuel énergie'!D38 -> 0 | L30: ='Consommation mensuel énergie'!E38 -> 0 | M30: =E30*F30+G30*H30+#REF!*#REF!+I30*J30 -> #REF!
A31: Casablanca | B31: =B30+1 -> 30 | C31: 12 | D31: 2022 | E31: =submetering!E31+submetering!F31+submetering!G31 -> 0 | F31: 1.05 | G31: ='Consommation mensuel énergie'!V39 -> 0 | H31: 12.44 | I31: ='Consommation mensuel énergie'!F39 -> 0 | J31: 11.4 | K31: ='Consommation mensuel énergie'!D39 -> 0 | L31: ='Consommation mensuel énergie'!E39 -> 0
A32: Casablanca | B32: =B31+1 -> 31 | C32: 12 | D32: 2022 | E32: =submetering!E32+submetering!F32+submetering!G32 -> 0 | F32: 1.05 | G32: ='Consommation mensuel énergie'!V40 -> 0 | H32: 12.44 | I32: ='Consommation mensuel énergie'!F40 -> 0 | J32: 11.4 | K32: ='Consommation mensuel énergie'!D40 -> 0 | L32: ='Consommation mensuel énergie'!E40 -> 0

Sheet submetering
A1: Site Name | B1: Day | C1: Month | D1: Year | E1: Creuse 81 - KWh | F1: Pleine 82-KWh | G1: Pointe 83 - KWh | H1: Room Nights | I1: Total Guests | J1: Utilities day cost dh
A2: Casablanca | B2: 1 | C2: 12 | D2: 2022 | E2: ='Consommation mensuel énergie'!L10 -> 4442 | F2: ='Consommation mensuel énergie'!M10 -> 5771 | G2: ='Consommation mensuel énergie'!N10 -> 3068 | H2: ='Consommation mensuel énergie'!D10 -> 88 | I2: ='Consommation mensuel énergie'!E10 -> 107 | J2: =E2*F2+G2*#REF!+#REF!*#REF!+#REF!*#REF! -> #REF!
A3: Casablanca | B3: =B2+1 -> 2 | C3: 12 | D3: 2022 | E3: ='Consommation mensuel énergie'!L11 -> 4516 | F3: ='Consommation mensuel énergie'!M11 -> 6383 | G3: ='Consommation mensuel énergie'!N14 -> 2955 | H3: ='Consommation mensuel énergie'!D11 -> 102 | I3: ='Consommation mensuel énergie'!E11 -> 145 | J3: =E3*F3+G3*#REF!+#REF!*#REF!+#REF!*#REF! -> #REF!
A4: Casablanca | B4: =B3+1 -> 3 | C4: 12 | D4: 2022 | E4: ='Consommation mensuel énergie'!L12 -> 4355 | F4: ='Consommation mensuel énergie'!M12 -> 6149 | G4: ='Consommation mensuel énergie'!N12 -> 2998 | H4: ='Consommation mensuel énergie'!D12 -> 80 | I4: ='Consommation mensuel énergie'!E12 -> 120 | J4: =E4*F4+G4*#REF!+#REF!*#REF!+#REF!*#REF! -> #REF!
A5: Casablanca | B5: =B4+1 -> 4 | C5: 12 | D5: 2022 | E5: ='Consommation mensuel énergie'!L13 -> 3999 | F5: ='Consommation mensuel énergie'!M13 -> 6195 | G5: ='Consommation mensuel énergie'!N13 -> 2852 | H5: ='Consommation mensuel énergie'!D13 -> 86 | I5: ='Consommation mensuel énergie'!E13 -> 135 | J5: =E5*F5+G5*#REF!+#REF!*#REF!+#REF!*#REF! -> #REF!
A6: Casablanca | B6: =B5+1 -> 5 | C6: 12 | D6: 2022 | E6: ='Consommation mensuel énergie'!L14 -> 4096 | F6: ='Consommation mensuel énergie'!M14 -> 6082 | G6: ='Consommation mensuel énergie'!N14 -> 2955 | H6: ='Consommation mensuel énergie'!D14 -> 108 | I6: ='Consommation mensuel énergie'!E14 -> 142 | J6: =E6*F6+G6*#REF!+#REF!*#REF!+#REF!*#REF! -> #REF!
A7: Casablanca | B7: =B6+1 -> 6 | C7: 12 | D7: 2022 | E7: ='Consommation mensuel énergie'!L15 -> 3949 | F7: ='Consommation mensuel énergie'!M15 -> 5925 | G7: ='Consommation mensuel énergie'!N15 -> 2745 | H7: ='Consommation mensuel énergie'!D15 -> 105 | I7: ='Consommation mensuel énergie'!E15 -> 139 | J7: =E7*F7+G7*#REF!+#REF!*#REF!+#REF!*#REF! -> #REF!
A8: Casablanca | B8: =B7+1 -> 7 | C8: 12 | D8: 2022 | E8: ='Consommation mensuel énergie'!L16 -> 4297 | F8: ='Consommation mensuel énergie'!M16 -> 6773 | G8: ='Consommation mensuel énergie'!N16 -> 3082 | H8: ='Consommation mensuel énergie'!D16 -> 114 | I8: ='Consommation mensuel énergie'!E16 -> 154 | J8: =E8*F8+G8*#REF!+#REF!*#REF!+#REF!*#REF! -> #REF!
A9: Casablanca | B9: =B8+1 -> 8 | C9: 12 | D9: 2022 | E9: ='Consommation mensuel énergie'!L17 -> 3957 | F9: ='Consommation mensuel énergie'!M17 -> 6853 | G9: ='Consommation mensuel énergie'!N17 -> 3117 | H9: ='Consommation mensuel énergie'!D17 -> 107 | I9: ='Consommation mensuel énergie'!E17 -> 141 | J9: =E9*F9+G9*#REF!+#REF!*#REF!+#REF!*#REF! -> #REF!
A10: Casablanca | B10: =B9+1 -> 9 | C10: 12 | D10: 2022 | E10: ='Consommation mensuel énergie'!L18 -> 4428 | F10: ='Consommation mensuel énergie'!M18 -> 6569 | G10: ='Consommation mensuel énergie'!N18 -> 3123 | H10: ='Consommation mensuel énergie'!D18 -> 125 | I10: ='Consommation mensuel énergie'!E18 -> 174 | J10: =E10*F10+G10*#REF!+#REF!*#REF!+#REF!*#REF! -> #REF!
A11: Casablanca | B11: =B10+1 -> 10 | C11: 12 | D11: 2022 | E11: ='Consommation mensuel énergie'!L19 -> 4757 | F11: ='Consommation mensuel énergie'!M19 -> 7543 | G11: ='Consommation mensuel énergie'!N19 -> 3345 | H11: ='Consommation mensuel énergie'!D19 -> 96 | I11: ='Consommation mensuel énergie'!E19 -> 135 | J11: =E11*F11+G11*#REF!+#REF!*#REF!+#REF!*#REF! -> #REF!
A12: Casablanca | B12: =B11+1 -> 11 | C12: 12 | D12: 2022 | E12: ='Consommation mensuel énergie'!L20 -> 4074 | F12: ='Consommation mensuel énergie'!M20 -> 6459 | G12: ='Consommation mensuel énergie'!N20 -> 3534 | H12: ='Consommation mensuel énergie'!D20 -> 77 | I12: ='Consommation mensuel énergie'!E20 -> 124 | J12: =E12*F12+G12*#REF!+#REF!*#REF!+#REF!*#REF! -> #REF!
A13: Casablanca | B13: =B12+1 -> 12 | C13: 12 | D13: 2022 | E13: ='Consommation mensuel énergie'!L21 -> 4146 | F13: ='Consommation mensuel énergie'!M21 -> 5509 | G13: ='Consommation mensuel énergie'!N21 -> 2726 | H13: ='Consommation mensuel énergie'!D21 -> 66 | I13: ='Consommation mensuel énergie'!E21 -> 93 | J13: =E13*F13+G13*#REF!+#REF!*#REF!+#REF!*#REF! -> #REF!
A14: Casablanca | B14: =B13+1 -> 13 | C14: 12 | D14: 2022 | E14: ='Consommation mensuel énergie'!L22 -> 4395 | F14: ='Consommation mensuel énergie'!M22 -> 7225 | G14: ='Consommation mensuel énergie'!N22 -> 3209 | H14: ='Consommation mensuel énergie'!D22 -> 106 | I14: ='Consommation mensuel énergie'!E22 -> 137 | J14: =E14*F14+G14*#REF!+#REF!*#REF!+#REF!*#REF! -> #REF!
A15: Casablanca | B15: =B14+1 -> 14 | C15: 12 | D15: 2022 | E15: ='Consommation mensuel énergie'!L23 -> 4130 | F15: ='Consommation mensuel énergie'!M23 -> 6810 | G15: ='Consommation mensuel énergie'!N23 -> 3248 | H15: ='Consommation mensuel énergie'!D23 -> 132 | I15: ='Consommation mensuel énergie'!E23 -> 159 | J15: =E15*F15+G15*#REF!+#REF!*#REF!+#REF!*#REF! -> #REF!
... A26: Casablanca | B26: =B25+1 -> 25 | C26: 12 | D26: 2022 | E26: ='Consommation mensuel énergie'!L34 -> 4041 | F26: ='Consommation mensuel énergie'!M34 -> 5901 | G26: ='Consommation mensuel énergie'!N34 -> 3034 | H26: ='Consommation mensuel énergie'!D34 -> 120 | I26: ='Consommation mensuel énergie'!E34 -> 220 | J26: =E26*F26+G26*#REF!+#REF!*#REF!+#REF!*#REF! -> #REF!
A27: Casablanca | B27: =B26+1 -> 26 | C27: 12 | D27: 2022 | E27: ='Consommation mensuel énergie'!L35 -> 4322 | F27: ='Consommation mensuel énergie'!M35 -> 5985 | G27: ='Consommation mensuel énergie'!N35 -> 2921 | H27: ='Consommation mensuel énergie'!D35 -> 117 | I27: ='Consommation mensuel énergie'!E35 -> 221
A28: Casablanca | B28: =B27+1 -> 27 | C28: 12 | D28: 2022 | E28: ='Consommation mensuel énergie'!L36 -> 4450 | F28: ='Consommation mensuel énergie'!M36 -> 6089 | G28: ='Consommation mensuel énergie'!N36 -> 3014 | H28: ='Consommation mensuel énergie'!D36 -> 160 | I28: ='Consommation mensuel énergie'!E36 -> 297
A29: Casablanca | B29: =B28+1 -> 28 | C29: 12 | D29: 2022 | E29: ='Consommation mensuel énergie'!L37 -> 3883 | F29: ='Consommation mensuel énergie'!M37 -> 6047 | G29: ='Consommation mensuel énergie'!N37 -> 3015 | H29: ='Consommation mensuel énergie'!D37 -> 151 | I29: ='Consommation mensuel énergie'!E37 -> 284
A30: Casablanca | B30: =B29+1 -> 29 | C30: 12 | D30: 2022 | E30: ='Consommation mensuel énergie'!L38 -> 0 | F30: ='Consommation mensuel énergie'!M38 -> 0 | G30: ='Consommation mensuel énergie'!N38 -> 0 | H30: ='Consommation mensuel énergie'!D38 -> 0 | I30: ='Consommation mensuel énergie'!E38 -> 0 | J30: =E30*F30+G30*#REF!+#REF!*#REF!+#REF!*#REF! -> #REF!
A31: Casablanca | B31: =B30+1 -> 30 | C31: 12 | D31: 2022 | E31: ='Consommation mensuel énergie'!L39 -> 0 | F31: ='Consommation mensuel énergie'!M39 -> 0 | G31: ='Consommation mensuel énergie'!N39 -> 0 | H31: ='Consommation mensuel énergie'!D39 -> 0 | I31: ='Consommation mensuel énergie'!E39 -> 0
A32: Casablanca | B32: =B31+1 -> 31 | C32: 12 | D32: 2022 | E32: ='Consommation mensuel énergie'!L40 -> 0 | F32: ='Consommation mensuel énergie'!M40 -> 0 | G32: ='Consommation mensuel énergie'!N40 -> 0 | H32: ='Consommation mensuel énergie'!D40 -> 0 | I32: ='Consommation mensuel énergie'!E40 -> 0

Sheet Consommation mensuel énergie
I2: Consommation mensuel Eau /électricité/Gaz
B8: Date | D8: ROOM Nights | E8: Guests | F8: Cons Eau/Hotel | H8: Consommation du jour en DH | K8: date / électr | L8: ELECTRICITE en KWH | O8: total | Q8: Consommation du jour en DH | S8: Cons Elec/Villa | U8: Cons Elec/RIAD | V8: GAZ en Kg | X8: Consommation du jour en DH
L9: creuse 81 | M9: pleine 82 | N9: pointe 83
B10: 44896 | D10: 88 | E10: 107 | F10: ='Suivi EAU-ELEC'!E9 -> 112.1 | H10: =F10*8.79 -> 985.359 | K10: 42278 | L10: ='Suivi EAU-ELEC'!G9 -> 4442 | M10: ='Suivi EAU-ELEC'!I9 -> 5771 | N10: ='Suivi EAU-ELEC'!K9 -> 3068 | O10: =L10+M10+N10 -> 13281 | Q10: =L10*0.6985+M10*0.9514+N10*1.3304 -> 12674.934 | V10: ='Suvi Gaz'!O4 -> 351.99131 | X10: =V10*12.44 -> 4378.7719
B11: 44897 | D11: 102 | E11: 145 | F11: ='Suivi EAU-ELEC'!E10 -> 125 | H11: =F11*8.79 -> 1098.75 | K11: 42279 | L11: ='Suivi EAU-ELEC'!G10 -> 4516 | M11: ='Suivi EAU-ELEC'!I10 -> 6383 | N11: ='Suivi EAU-ELEC'!K10 -> 2866 | O11: =L11+M11+N11 -> 13765 | Q11: =L11*0.6985+M11*0.9514+N14*1.3304 -> 13158.544 | V11: ='Suvi Gaz'!O5 -> 223.99447 | X11: =V11*12.44 -> 2786.4912
B12: 44898 | D12: 80 | E12: 120 | F12: ='Suivi EAU-ELEC'!E11 -> 122 | H12: =F12*8.79 -> 1072.38 | K12: 42280 | L12: ='Suivi EAU-ELEC'!G11 -> 4355 | M12: ='Suivi EAU-ELEC'!I11 -> 6149 | N12: ='Suivi EAU-ELEC'!K11 -> 2998 | O12: =L12+M12+N12 -> 13502 | Q12: =L12*0.6985+M12*0.9514+N12*1.3304 -> 12880.665 | V12: ='Suvi Gaz'!O6 -> 479.98815 | X12: =V12*12.44 -> 5971.0526
B13: 44899 | D13: 86 | E13: 135 | F13: ='Suivi EAU-ELEC'!E12 -> 131 | H13: =F13*8.79 -> 1151.49 | K13: 42281 | L13: ='Suivi EAU-ELEC'!G12 -> 3999 | M13: ='Suivi EAU-ELEC'!I12 -> 6195 | N13: ='Suivi EAU-ELEC'!K12 -> 2852 | O13: =L13+M13+N13 -> 13046 | Q13: =L13*0.6985+M13*0.9514+N13*1.3304 -> 12481.525 | V13: ='Suvi Gaz'!O7 -> 545.0149 | X13: =V13*12.44 -> 6779.9854
B14: 44900 | D14: 108 | E14: 142 | F14: ='Suivi EAU-ELEC'!E13 -> 122 | H14: =F14*8.79 -> 1072.38 | K14: 42282 | L14: ='Suivi EAU-ELEC'!G13 -> 4096 | M14: ='Suivi EAU-ELEC'!I13 -> 6082 | N14: ='Suivi EAU-ELEC'!K13 -> 2955 | O14: =L14+M14+N14 -> 13133 | Q14: =L14*0.6985+M14*0.9514+N14*1.3304 -> 12578.803 | V14: ='Suvi Gaz'!O8 -> 255.99368 | X14: =V14*12.44 -> 3184.5614
B15: 44901 | D15: 105 | E15: 139 | F15: ='Suivi EAU-ELEC'!E14 -> 132 | H15: =F15*8.79 -> 1160.28 | K15: 42283 | L15: ='Suivi EAU-ELEC'!G14 -> 3949 | M15: ='Suivi EAU-ELEC'!I14 -> 5925 | N15: ='Suivi EAU-ELEC'!K14 -> 2745 | O15: =L15+M15+N15 -> 12619 | Q15: =L15*0.6985+M15*0.9514+N15*1.3304 -> 12047.37 | V15: ='Suvi Gaz'!O9 -> 287.99289 | X15: =V15*12.44 -> 3582.6316
B16: 44902 | D16: 114 | E16: 154 | F16: ='Suivi EAU-ELEC'!E15 -> 121 | H16: =F16*8.79 -> 1063.59 | K16: 42284 | L16: ='Suivi EAU-ELEC'!G15 -> 4297 | M16: ='Suivi EAU-ELEC'!I15 -> 6773 | N16: ='Suivi EAU-ELEC'!K15 -> 3082 | O16: =L16+M16+N16 -> 14152 | Q16: =L16*0.6985+M16*0.9514+N16*1.3304 -> 13545.579 | V16: ='Suvi Gaz'!O10 -> 1215.97 | X16: =V16*12.44 -> 15126.667
B17: 44903 | D17: 107 | E17: 141 | F17: ='Suivi EAU-ELEC'!E16 -> 110 | H17: =F17*8.79 -> 966.9 | K17: 42285 | L17: ='Suivi EAU-ELEC'!G16 -> 3957 | M17: ='Suivi EAU-ELEC'!I16 -> 6853 | N17: ='Suivi EAU-ELEC'!K16 -> 3117 | O17: =L17+M17+N17 -> 13927 | Q17: =L17*0.6985+M17*0.9514+N17*1.3304 -> 13430.766 | V17: ='Suvi Gaz'!O11 -> 351.99131 | X17: =V17*12.44 -> 4378.7719
B18: 44904 | D18: 125 | E18: 174 | F18: ='Suivi EAU-ELEC'!E17 -> 141 | H18: =F18*8.79 -> 1239.39 | K18: 42286 | L18: ='Suivi EAU-ELEC'!G17 -> 4428 | M18: ='Suivi EAU-ELEC'!I17 -> 6569 | N18: ='Suivi EAU-ELEC'!K17 -> 3123 | O18: =L18+M18+N18 -> 14120 | Q18: =L18*0.6985+M18*0.9514+N18*1.3304 -> 13497.544 | V18: ='Suvi Gaz'!O12 -> 255.99368 | X18: =V18*12.44 -> 3184.5614
B19: 44905 | D19: 96 | E19: 135 | F19: ='Suivi EAU-ELEC'!E18 -> 129 | H19: =F19*8.79 -> 1133.91 | K19: 42287 | L19: ='Suivi EAU-ELEC'!G18 -> 4757 | M19: ='Suivi EAU-ELEC'!I18 -> 7543 | N19: ='Suivi EAU-ELEC'!K18 -> 3345 | O19: =L19+M19+N19 -> 15645 | Q19: =L19*0.6985+M19*0.9514+N19*1.3304 -> 14949.363 | V19: ='Suvi Gaz'!O13 -> 383.99052 | X19: =V19*12.44 -> 4776.8421
B20: 44906 | D20: 77 | E20: 124 | F20: ='Suivi EAU-ELEC'!E19 -> 114 | H20: =F20*8.79 -> 1002.06 | K20: 42288 | L20: ='Suivi EAU-ELEC'!G19 -> 4074 | M20: ='Suivi EAU-ELEC'!I19 -> 6459 | N20: ='Suivi EAU-ELEC'!K19 -> 3534 | O20: =L20+M20+N20 -> 14067 | Q20: =L20*0.6985+M20*0.9514+N20*1.3304 -> 13692.415 | V20: ='Suvi Gaz'!O14 -> 383.99052 | X20: =V20*12.44 -> 4776.8421
B21: 44907 | D21: 66 | E21: 93 | F21: ='Suivi EAU-ELEC'!E20 -> 120 | H21: =F21*8.79 -> 1054.8 | K21: 42289 | L21: ='Suivi EAU-ELEC'!G20 -> 4146 | M21: ='Suivi EAU-ELEC'!I20 -> 5509 | N21: ='Suivi EAU-ELEC'!K20 -> 2726 | O21: =L21+M21+N21 -> 12381 | Q21: =L21*0.6985+M21*0.9514+N21*1.3304 -> 11763.914 | V21: ='Suvi Gaz'!O15 -> 255.99368 | X21: =V21*12.44 -> 3184.5614
B22: 44908 | D22: 106 | E22: 137 | F22: ='Suivi EAU-ELEC'!E21 -> 89 | H22: =F22*8.79 -> 782.31 | K22: 42290 | L22: ='Suivi EAU-ELEC'!G21 -> 4395 | M22: ='Suivi EAU-ELEC'!I21 -> 7225 | N22: ='Suivi EAU-ELEC'!K21 -> 3209 | O22: =L22+M22+N22 -> 14829 | Q22: =L22*0.6985+M22*0.9514+N22*1.3304 -> 14213.026 | V22: ='Suvi Gaz'!O16 -> 479.98815 | X22: =V22*12.44 -> 5971.0526
B23: 44909 | D23: 132 | E23: 159 | F23: ='Suivi EAU-ELEC'!E22 -> 116 | H23: =F23*8.79 -> 1019.64 | K23: 42291 | L23: ='Suivi EAU-ELEC'!G22 -> 4130 | M23: ='Suivi EAU-ELEC'!I22 -> 6810 | N23: ='Suivi EAU-ELEC'!K22 -> 3248 | O23: =L23+M23+N23 -> 14188 | Q23: =L23*0.6985+M23*0.9514+N23*1.3304 -> 13684.978 | V23: ='Suvi Gaz'!O17 -> 511.98736 | X23: =V23*12.44 -> 6369.1228
... B36: 44922 | D36: 160 | E36: 297 | F36: ='Suivi EAU-ELEC'!E35 -> 153 | H36: =F36*8.79 -> 1344.87 | K36: 42304 | L36: ='Suivi EAU-ELEC'!G35 -> 4450 | M36: ='Suivi EAU-ELEC'!I35 -> 6089 | N36: ='Suivi EAU-ELEC'!K35 -> 3014 | O36: =L36+M36+N36 -> 13553 | Q36: =L36*0.6985+M36*0.9514+N36*1.3304 -> 12911.225 | V36: ='Suvi Gaz'!O30 -> 863.97867 | X36: =V36*12.44 -> 10747.895
B37: 44923 | D37: 151 | E37: 284 | F37: ='Suivi EAU-ELEC'!E36 -> 161 | H37: =F37*8.79 -> 1415.19 | L37: ='Suivi EAU-ELEC'!G36 -> 3883 | M37: ='Suivi EAU-ELEC'!I36 -> 6047 | N37: ='Suivi EAU-ELEC'!K36 -> 3015 | O37: =L37+M37+N37 -> 12945 | Q37: =L37*0.6985+M37*0.9514+N37*1.3304 -> 12476.547 | V37: ='Suvi Gaz'!O31 -> 0 | X37: =V37*12.44 -> 0
B38: 44924 | F38: ='Suivi EAU-ELEC'!E37 -> 0 | H38: =F38*8.79 -> 0 | L38: ='Suivi EAU-ELEC'!G37 -> 0 | M38: ='Suivi EAU-ELEC'!I37 -> 0 | N38: ='Suivi EAU-ELEC'!K37 -> 0 | O38: =L38+M38+N38 -> 0 | Q38: =L38*0.6985+M38*0.9514+N38*1.3304 -> 0 | V38: ='Suvi Gaz'!O32 -> 0 | X38: =V38*12.44 -> 0
B39: 44925 | F39: ='Suivi EAU-ELEC'!E38 -> 0 | H39: =F39*8.79 -> 0 | L39: ='Suivi EAU-ELEC'!G38 -> 0 | M39: ='Suivi EAU-ELEC'!I38 -> 0 | N39: ='Suivi EAU-ELEC'!K38 -> 0 | O39: =L39+M39+N39 -> 0 | Q39: =L39*0.6985+M39*0.9514+N39*1.3304 -> 0 | V39: ='Suvi Gaz'!O33 -> 0 | X39: =V39*12.44 -> 0
B40: 44926 | F40: ='Suivi EAU-ELEC'!E39 -> 0 | H40: =F40*8.79 -> 0 | L40: ='Suivi EAU-ELEC'!G39 -> 0 | M40: ='Suivi EAU-ELEC'!I39 -> 0 | N40: ='Suivi EAU-ELEC'!K39 -> 0 | O40: =L40+M40+N40 -> 0 | Q40: =L40*0.6985+M40*0.9514+N40*1.3304 -> 0 | V40: ='Suvi Gaz'!O34 -> 0 | X40: =V40*12.44 -> 0
D41: =SUM(D10:D40) -> 2836 | E41: =SUM(E10:E40) -> 4403 | F41: =SUM(F10:F40) -> 3468.1 | H41: =SUM(H10:H40) -> 30484.599 | L41: =SUM(L10:L40) -> 118437 | M41: =SUM(M10:M40) -> 177882 | N41: =SUM(N10:N40) -> 84498 | O41: =SUM(O10:O40) -> 380817 | Q41: =SUM(Q10:Q40) -> 364499.72 | S41: =SUM(S10:S40) -> 0 | U41: =SUM(U10:U40) -> 0 | V41: =SUM(V10:V40) -> 12384.723 | X41: =SUM(X10:X40) -> 154065.95
A43: Désignation | H43: COUTS | I43: Consommations | L43: Consommations /DHs | N43: TOTAL Consommations /DHs
A44: ELECTRICITE / Kw/h | D44: creuse 81 | E44: creuse 81 | F44: creuse 81 | H44: 0.6985 | I44: =L41 -> 118437 | L44: =I44*H44 -> 82728.245 | N44: =L44+L45+L46 -> 364381.32
D45: pleine 82 | E45: pleine 82 | F45: pleine 82 | H45: 0.9514 | I45: =M41 -> 177882 | L45: =I45*H45 -> 169236.93
D46: pointe 83 | E46: pointe 83 | F46: pointe 83 | H46: 1.3304 | I46: =N41 -> 84498 | L46: =I46*H46 -> 112416.14
N47: =N44*1.3 -> 473695.71
A48: EAU HOTEL M3 | H48: 8.79 | I48: =F41 -> 3468.1 | L48: =I48*H48 -> 30484.599 | N48: =L48 -> 30484.599
A49: GAZ Kg | H49: 12.44 | I49: =V41 -> 12384.723 | L49: =I49*H49 -> 154065.95 | N49: =L49 -> 154065.95

Sheet facture électricité
C1: Estimation de la consommation électrique Decembre 2022 | H1: Fiche technique
H3: DT fourseasons CBL
A7: N° de compteur | C7: Ancienne date de lecture | E7: Nouvelle date de lecture | F7: N de jours de consommation | G7: Heures pleines | H7: Heures creuses | I7: Heures de pointe
A8: 95670781 | C8: 44893 | E8: 44923 | F8: 30jours
A11: Type de comptage | C11: Puissance installée KVA | E11: Puissance souscrite KVA | G11: Puissance appelée KVA | I11: Dépassement de la puissance souscrite KVA
A12: 4T | C12: 3750 | E12: 1000 | G12: 939
A16: Eléments de relève | C16: Nouvel Index | D16: Ancien Index | E16: Consommation | F16: Energie révaluée | G16: Consommation Compteur démarquant | I16: Energie à facturer
A17: HEURES PLEINE | C17: 21995481 | D17: 21805434 | E17: =MIN(C17-D17) -> 190047 | F17: =+E17 -> 190047 | I17: =+E17 -> 190047
A18: HEURES CREUSES | C18: 12883997 | D18: 12757348 | E18: =MIN(C18-D18) -> 126649 | F18: =+E18 -> 126649 | I18: =+E18 -> 126649
A19: HEURES DE POINTE | C19: 9648730 | D19: 9558420 | E19: =AVERAGE(C19-D19) -> 90310 | F19: =+E19 -> 90310 | I19: =+E19 -> 90310
A20: TOTAL | E20: =SUM(E17:E19) -> 407006
A23: Détail de la facture | D23: Quantité | E23: Prix unitaire | F23: Montant HT | G23: TVA | I23: Montant TTC
G24: Taux % | H24: Montant
A25: ENERGIE ACTIVE H. PLEINES | D25: =+E17 -> 190047 | E25: 0.9514 | F25: =PRODUCT(D25*E25) -> 180810.72 | G25: 14 | H25: =PRODUCT(0.14,F25) -> 25313.5 | I25: =SUM(H25,F25) -> 206124.22
A26: ENERGIE ACTIVE H. CREUSES | D26: =+E18 -> 126649 | E26: 0.6985 | F26: =PRODUCT(D26*E26) -> 88464.326 | G26: 14 | H26: =PRODUCT(0.14,F26) -> 12385.006 | I26: =SUM(H26,F26) -> 100849.33
A27: ENETGIE ACTIVE H. DE POINTE | D27: =+E19 -> 90310 | E27: 1.3304 | F27: =PRODUCT(D27*E27) -> 120148.42 | G27: 14 | H27: =PRODUCT(0.14,F27) -> 16820.779 | I27: =SUM(H27,F27) -> 136969.2
A28: REDEVANCE DE PUISSANCE | D28: 1000 | E28: 43.88167 | F28: =PRODUCT(D28,E28) -> 43881.67 | G28: 14 | H28: =PRODUCT(0.14,F28) -> 6143.4338 | I28: =SUM(H28,F28) -> 50025.104
A29: DEPASSEMENT DE PUISSANCE | D29: 0 | E29: =E28*1.5 -> 65.822505 | F29: =PRODUCT(D29,E29) -> 0 | G29: 14 | H29: =PRODUCT(0.14,F29) -> 0 | I29: =SUM(H29,F29) -> 0
A30: ENTRETIEN COMPTAGE | F30: 841 | G30: 20 | H30: =PRODUCT(F30,0.2) -> 168.2 | I30: =SUM(H30,F30) -> 1009.2
A31: LOCATION COMPTAGE | F31: 1492 | G31: 7 | H31: =PRODUCT(F31,0.07) -> 104.44 | I31: =SUM(H31,F31) -> 1596.44
A32: Total | F32: =SUM(F25:F31) -> 435638.14 | I32: =SUM(I25:J31) -> 496573.5

Sheet Suivi EAU-ELEC
E1: Suivi Compteur d'Eau- électricité Lydec- Dec 2022 | J1: Département Engineering 2022
A7: Date/électriqie | B7: Incendie | D7: Eau m3 | F7: Electricité Kw/h
B8: Compteur | C8: Consommation | D8: Compteur | E8: Consommation | F8: Compteur H.Creuse | G8: Consommation H.Creuse | H8: Compteur H.Pleine | I8: Consommation H.Pleine | J8: Compteur H.Pointe | K8: Consommation H.Pointe
A9: 44896 | B9: 2594 | C9: 0 | D9: 176437 | E9: =D9-176324.9 -> 112.1 | F9: 12772402 | G9: =F9-'[1]Eau-elec'!$F$38 -> 4442 | H9: 21823370 | I9: =H9-'[1]Eau-elec'!$H$38 -> 5771 | J9: 9567300 | K9: =J9-'[1]Eau-elec'!$J$38 -> 3068
A10: 44897 | B10: 2594 | C10: =B10-B9 -> 0 | D10: 176562 | E10: =D10-D9 -> 125 | F10: 12776918 | G10: =F10-F9 -> 4516 | H10: 21829753 | I10: =H10-H9 -> 6383 | J10: 9570166 | K10: =J10-J9 -> 2866
A11: 44898 | B11: 2594 | C11: =B11-B10 -> 0 | D11: 176684 | E11: =D11-D10 -> 122 | F11: 12781273 | G11: =F11-F10 -> 4355 | H11: 21835902 | I11: =H11-H10 -> 6149 | J11: 9573164 | K11: =J11-J10 -> 2998
A12: 44899 | B12: 2594 | C12: =B12-B11 -> 0 | D12: 176815 | E12: =D12-D11 -> 131 | F12: 12785272 | G12: =F12-F11 -> 3999 | H12: 21842097 | I12: =H12-H11 -> 6195 | J12: 9576016 | K12: =J12-J11 -> 2852
A13: 44900 | B13: 2594 | C13: =B13-B12 -> 0 | D13: 176937 | E13: =D13-D12 -> 122 | F13: 12789368 | G13: =F13-F12 -> 4096 | H13: 21848179 | I13: =H13-H12 -> 6082 | J13: 9578971 | K13: =J13-J12 -> 2955
A14: 44901 | B14: 2594 | C14: =B14-B13 -> 0 | D14: 177069 | E14: =D14-D13 -> 132 | F14: 12793317 | G14: =F14-F13 -> 3949 | H14: 21854104 | I14: =H14-H13 -> 5925 | J14: 9581716 | K14: =J14-J13 -> 2745
A15: 44902 | B15: 2594 | C15: =B15-B14 -> 0 | D15: 177190 | E15: =D15-D14 -> 121 | F15: 12797614 | G15: =F15-F14 -> 4297 | H15: 21860877 | I15: =H15-H14 -> 6773 | J15: 9584798 | K15: =J15-J14 -> 3082
A16: 44903 | B16: 2594 | C16: =B16-B15 -> 0 | D16: =177190+110 -> 177300 | E16: =D16-D15 -> 110 | F16: 12801571 | G16: =F16-F15 -> 3957 | H16: 21867730 | I16: =H16-H15 -> 6853 | J16: 9587915 | K16: =J16-J15 -> 3117
A17: 44904 | B17: 2594 | C17: =B17-B16 -> 0 | D17: =D15+251 -> 177441 | E17: =D17-D16 -> 141 | F17: 12805999 | G17: =F17-F16 -> 4428 | H17: 21874299 | I17: =H17-H16 -> 6569 | J17: 9591038 | K17: =J17-J16 -> 3123
A18: 44905 | B18: 2594 | C18: =B18-B17 -> 0 | D18: 177570 | E18: =D18-D17 -> 129 | F18: 12810756 | G18: =F18-F17 -> 4757 | H18: 21881842 | I18: =H18-H17 -> 7543 | J18: 9594383 | K18: =J18-J17 -> 3345
A19: 44906 | B19: 2594 | C19: =B19-B18 -> 0 | D19: 177684 | E19: =D19-D18 -> 114 | F19: 12814830 | G19: =F19-F18 -> 4074 | H19: 21888301 | I19: =H19-H18 -> 6459 | J19: 9597917 | K19: =J19-J18 -> 3534
A20: 44907 | B20: 2594 | C20: =B20-B19 -> 0 | D20: 177804 | E20: =D20-D19 -> 120 | F20: 12818976 | G20: =F20-F19 -> 4146 | H20: 21893810 | I20: =H20-H19 -> 5509 | J20: 9600643 | K20: =J20-J19 -> 2726
A21: 44908 | B21: 2594 | C21: =B21-B20 -> 0 | D21: 177893 | E21: =D21-D20 -> 89 | F21: 12823371 | G21: =F21-F20 -> 4395 | H21: 21901035 | I21: =H21-H20 -> 7225 | J21: 9603852 | K21: =J21-J20 -> 3209
A22: 44909 | B22: 2594 | C22: 0 | D22: 178009 | E22: =D22-D21 -> 116 | F22: 12827501 | G22: =F22-F21 -> 4130 | H22: 21907845 | I22: =H22-H21 -> 6810 | J22: 9607100 | K22: =J22-J21 -> 3248
A23: 44910 | B23: 2594 | C23: 0 | D23: 178125 | E23: =D23-D22 -> 116 | F23: 12831737 | G23: =F23-F22 -> 4236 | H23: 21915182 | I23: =H23-H22 -> 7337 | J23: 9610167 | K23: =J23-J22 -> 3067
A24: 44911 | B24: 2594 | C24: 0 | D24: 178252 | E24: =D24-D23 -> 127 | F24: 12836276 | G24: =F24-F23 -> 4539 | H24: 21921435 | I24: =H24-H23 -> 6253 | J24: 9613037 | K24: =J24-J23 -> 2870
A25: 44912 | B25: 2594 | C25: 0 | D25: 178335 | E25: =D25-D24 -> 83 | F25: 12840720 | G25: =F25-F24 -> 4444 | H25: 21928635 | I25: =H25-H24 -> 7200 | J25: 9616356 | K25: =J25-J24 -> 3319
A26: 44913 | B26: 2594 | C26: 0 | D26: 178469 | E26: =D26-D25 -> 134 | F26: 12845101 | G26: =F26-F25 -> 4381 | H26: 21934652 | I26: =H26-H25 -> 6017 | J26: 9619411 | K26: =J26-J25 -> 3055
A27: 44914 | B27: 2594 | C27: 0 | D27: 178565 | E27: =D27-D26 -> 96 | F27: 12849227 | G27: =F27-F26 -> 4126 | H27: 21940627 | I27: =H27-H26 -> 5975 | J27: 9622226 | K27: =J27-J26 -> 2815
A28: 44915 | B28: 2594 | C28: 0 | D28: 178669 | E28: =D28-D27 -> 104 | F28: 12853283 | G28: =F28-F27 -> 4056 | H28: 21947087 | I28: =H28-H27 -> 6460 | J28: 9625179 | K28: =J28-J27 -> 2953
A29: 44916 | B29: 2594 | C29: 0 | D29: 178816 | E29: =D29-D28 -> 147 | F29: 12857442 | G29: =F29-F28 -> 4159 | H29: 21953240 | I29: =H29-H28 -> 6153 | J29: 9628182 | K29: =J29-J28 -> 3003
A30: 44917 | B30: 2594 | C30: 0 | D30: 178936 | E30: =D30-D29 -> 120 | F30: 12861508 | G30: =F30-F29 -> 4066 | H30: 21959418 | I30: =H30-H29 -> 6178 | J30: 9631216 | K30: =J30-J29 -> 3034
A31: 44918 | B31: 2594 | C31: 0 | D31: 179066 | E31: =D31-D30 -> 130 | F31: 12865689 | G31: =F31-F30 -> 4181 | H31: 21965539 | I31: =H31-H30 -> 6121 | J31: 9634057 | K31: =J31-J30 -> 2841
A32: 44919 | B32: 2594 | C32: 0 | D32: 179183 | E32: =D32-D31 -> 117 | F32: 12869701 | G32: =F32-F31 -> 4012 | H32: 21971459 | I32: =H32-H31 -> 5920 | J32: 9636746 | K32: =J32-J31 -> 2689
A33: 44920 | B33: 2594 | C33: 0 | D33: 179309 | E33: =D33-D32 -> 126 | F33: 12873742 | G33: =F33-F32 -> 4041 | H33: 21977360 | I33: =H33-H32 -> 5901 | J33: 9639780 | K33: =J33-J32 -> 3034
... A36: 44923 | B36: 2594 | C36: 0 | D36: 179793 | E36: =D36-D35 -> 161 | F36: 12886397 | G36: =F36-F35 -> 3883 | H36: 21995481 | I36: =H36-H35 -> 6047 | J36: 9648730 | K36: =J36-J35 -> 3015
A37: 44924
A38: 44925
A39: 44926
A40: 44927

Sheet Suvi Gaz
F1: suivi Gaz Dec 2022
Q2: 803 | T2: 519 | W2: 800 | Z2: 802
B3: Relvé C1 | C3: cons C1 | D3: Relvé C2 | E3: cons C2 | F3: Relvé C3 | G3: cons C3 | H3: Relvé C4 | I3: cons C4 | J3: ∑ des relevés | K3: moyen general % | L3: con.j | M3: ∑ de volume en L | N3: cons./jen L | O3: cons./jen Kg | P3: cons./jen DH | Q3: livraison C1 | R3: %Avant | S3: % Après | T3: livraison C2 | U3: %Avant | V3: % Après | W3: livraison C3 | X3: %Avant | Y3: % Après | Z3: livraison C4 | AA3: %Avant | AB3: % Après | AC3: total livraison litre | AD3: moyen general % Avant L | AE3: moyen general % Aaprés L
A4: 44896 | B4: 48 | C4: =IF(AC4>0,((B4-R4)+(S4-B5)),IF(B5=0, ,(B4-B5))) -> 2 | D4: 45 | E4: =IF(AC4>0,((D4-U4)+(V4-D5)),IF(D5=0, ,(D4-D5))) -> 4 | F4: 52 | G4: =IF(AC4>0,((F4-X4)+(Y4-F5)),IF(F5=0, ,(F4-F5))) -> 3 | H4: 48 | I4: =IF(AC4>0,((H4-AA4)+(AB4-H5)),IF(H5=0, ,(H4-H5))) -> 2 | J4: =B4+D4+F4+H4 -> 193 | K4: =J4/4 -> 48.25 | L4: =IF(AC4>0,((K4-AD4)+(AE4-K5)),IF(K5=0, ,(K4-K5))) -> 2.75 | M4: =6049*4 -> 24196 | N4: =L4*M4/100 -> 665.39 | O4: =N4*0.529 -> 351.99131 | P4: =O4*12.44 -> 4378.7719 | AC4: =Q4+T4+W4+Z4 -> 0 | AD4: =(R4+U4+X4+AA4)/4 -> 0 | AE4: =(S4+V4+Y4+AB4)/4 -> 0
A5: 44897 | B5: 46 | C5: =IF(AC5>0,((B5-R5)+(S5-B6)),IF(B6=0, ,(B5-B6))) -> 6 | D5: 41 | E5: =IF(AC5>0,((D5-U5)+(V5-D6)),IF(D6=0, ,(D5-D6))) -> 0 | F5: 49 | G5: =IF(AC5>0,((F5-X5)+(Y5-F6)),IF(F6=0, ,(F5-F6))) -> 0 | H5: 46 | I5: =IF(AC5>0,((H5-AA5)+(AB5-H6)),IF(H6=0, ,(H5-H6))) -> 1 | J5: =B5+D5+F5+H5 -> 182 | K5: =J5/4 -> 45.5 | L5: =IF(AC5>0,((K5-AD5)+(AE5-K6)),IF(K6=0, ,(K5-K6))) -> 1.75 | M5: =6049*4 -> 24196 | N5: =L5*M5/100 -> 423.43 | O5: =N5*0.529 -> 223.99447 | P5: =O5*12.44 -> 2786.4912 | Q5: 2100 | R5: 46 | S5: 66 | T5: 2096 | U5: 41 | V5: 65 | W5: 2098 | X5: 49 | Y5: 70 | Z5: 2095 | AA5: 46 | AB5: 71 | AC5: =Q5+T5+W5+Z5 -> 8389 | AD5: =(R5+U5+X5+AA5)/4 -> 45.5 | AE5: =(S5+V5+Y5+AB5)/4 -> 68
A6: 44898 | B6: 60 | C6: =IF(AC6>0,((B6-R6)+(S6-B7)),IF(B7=0, ,(B6-B7))) -> 2 | D6: 65 | E6: =IF(AC6>0,((D6-U6)+(V6-D7)),IF(D7=0, ,(D6-D7))) -> 3 | F6: 70 | G6: =IF(AC6>0,((F6-X6)+(Y6-F7)),IF(F7=0, ,(F6-F7))) -> 5 | H6: 70 | I6: =IF(AC6>0,((H6-AA6)+(AB6-H7)),IF(H7=0, ,(H6-H7))) -> 5 | J6: =B6+D6+F6+H6 -> 265 | K6: =J6/4 -> 66.25 | L6: =IF(AC6>0,((K6-AD6)+(AE6-K7)),IF(K7=0, ,(K6-K7))) -> 3.75 | M6: =6049*4 -> 24196 | N6: =L6*M6/100 -> 907.35 | O6: =N6*0.529 -> 479.98815 | P6: =O6*12.44 -> 5971.0526 | AC6: =Q6+T6+W6+Z6 -> 0 | AD6: =(R6+U6+X6+AA6)/4 -> 0 | AE6: =(S6+V6+Y6+AB6)/4 -> 0
A7: 44899 | B7: 58 | C7: =IF(AC7>0,((B7-R7)+(S7-B8)),IF(B8=0, ,(B7-B8))) -> 3 | D7: 62 | E7: =IF(AC7>0,((D7-U7)+(V7-D8)),IF(D8=0, ,(D7-D8))) -> 4 | F7: 65 | G7: =IF(AC7>0,((F7-X7)+(Y7-F8)),IF(F8=0, ,(F7-F8))) -> 5 | H7: 65 | I7: =IF(AC7>0,((H7-AA7)+(AB7-H8)),IF(H8=0, ,(H7-H8))) -> 5 | J7: =B7+D7+F7+H7 -> 250 | K7: =J7/4 -> 62.5 | L7: =IF(AC7>0,((K7-AD7)+(AE7-K8)),IF(K8=0, ,(K7-K8))) -> 4.25 | M7: =6049*4 -> 24196 | N7: =L7*M7/100 -> 1028.33 | O7: =N7*0.53 -> 545.0149 | P7: =O7*12.44 -> 6779.9854 | AC7: =Q7+T7+W7+Z7 -> 0 | AD7: =(R7+U7+X7+AA7)/4 -> 0 | AE7: =(S7+V7+Y7+AB7)/4 -> 0
A8: 44900 | B8: 55 | C8: =IF(AC8>0,((B8-R8)+(S8-B9)),IF(B9=0, ,(B8-B9))) -> 3 | D8: 58 | E8: =IF(AC8>0,((D8-U8)+(V8-D9)),IF(D9=0, ,(D8-D9))) -> 3 | F8: 60 | G8: =IF(AC8>0,((F8-X8)+(Y8-F9)),IF(F9=0, ,(F8-F9))) -> 0 | H8: 60 | I8: =IF(AC8>0,((H8-AA8)+(AB8-H9)),IF(H9=0, ,(H8-H9))) -> 2 | J8: =B8+D8+F8+H8 -> 233 | K8: =J8/4 -> 58.25 | L8: =IF(AC8>0,((K8-AD8)+(AE8-K9)),IF(K9=0, ,(K8-K9))) -> 2 | M8: =6049*4 -> 24196 | N8: =L8*M8/100 -> 483.92 | O8: =N8*0.529 -> 255.99368 | P8: =O8*12.44 -> 3184.5614 | AC8: =Q8+T8+W8+Z8 -> 0 | AD8: =(R8+U8+X8+AA8)/4 -> 0 | AE8: =(S8+V8+Y8+AB8)/4 -> 0
A9: 44901 | B9: 52 | C9: =IF(AC9>0,((B9-R9)+(S9-B10)),IF(B10=0, ,(B9-B10))) -> 3 | D9: 55 | E9: =IF(AC9>0,((D9-U9)+(V9-D10)),IF(D10=0, ,(D9-D10))) -> 3 | F9: 60 | G9: =IF(AC9>0,((F9-X9)+(Y9-F10)),IF(F10=0, ,(F9-F10))) -> 1 | H9: 58 | I9: =IF(AC9>0,((H9-AA9)+(AB9-H10)),IF(H10=0, ,(H9-H10))) -> 2 | J9: =B9+D9+F9+H9 -> 225 | K9: =J9/4 -> 56.25 | L9: =IF(AC9>0,((K9-AD9)+(AE9-K10)),IF(K10=0, ,(K9-K10))) -> 2.25 | M9: =6049*4 -> 24196 | N9: =L9*M9/100 -> 544.41 | O9: =N9*0.529 -> 287.99289 | P9: =O9*12.44 -> 3582.6316 | AC9: =Q9+T9+W9+Z9 -> 0 | AD9: =(R9+U9+X9+AA9)/4 -> 0 | AE9: =(S9+V9+Y9+AB9)/4 -> 0
A10: 44902 | B10: 49 | C10: =IF(AC10>0,((B10-R10)+(S10-B11)),IF(B11=0, ,(B10-B11))) -> 3 | D10: 52 | E10: =IF(AC10>0,((D10-U10)+(V10-D11)),IF(D11=0, ,(D10-D11))) -> 9 | F10: 59 | G10: =IF(AC10>0,((F10-X10)+(Y10-F11)),IF(F11=0, ,(F10-F11))) -> 13 | H10: 56 | I10: =IF(AC10>0,((H10-AA10)+(AB10-H11)),IF(H11=0, ,(H10-H11))) -> 13 | J10: =B10+D10+F10+H10 -> 216 | K10: =J10/4 -> 54 | L10: =IF(AC10>0,((K10-AD10)+(AE10-K11)),IF(K11=0, ,(K10-K11))) -> 9.5 | M10: =6049*4 -> 24196 | N10: =L10*M10/100 -> 2298.62 | O10: =N10*0.529 -> 1215.97 | P10: =O10*12.44 -> 15126.667 | Q10: 2809 | R10: 46 | S10: 85 | T10: 2992 | U10: 45 | V10: 85 | W10: 2628 | X10: 48 | Y10: 85 | Z10: 2956 | AA10: 45 | AB10: 85 | AC10: =Q10+T10+W10+Z10 -> 11385 | AD10: =(R10+U10+X10+AA10)/4 -> 46 | AE10: =(S10+V10+Y10+AB10)/4 -> 85
A11: 44903 | B11: 85 | C11: =IF(AC11>0,((B11-R11)+(S11-B12)),IF(B12=0, ,(B11-B12))) -> 3 | D11: 83 | E11: =IF(AC11>0,((D11-U11)+(V11-D12)),IF(D12=0, ,(D11-D12))) -> 2 | F11: 83 | G11: =IF(AC11>0,((F11-X11)+(Y11-F12)),IF(F12=0, ,(F11-F12))) -> 3 | H11: 83 | I11: =IF(AC11>0,((H11-AA11)+(AB11-H12)),IF(H12=0, ,(H11-H12))) -> 3 | J11: =B11+D11+F11+H11 -> 334 | K11: =J11/4 -> 83.5 | L11: =IF(AC11>0,((K11-AD11)+(AE11-K12)),IF(K12=0, ,(K11-K12))) -> 2.75 | M11: =6049*4 -> 24196 | N11: =L11*M11/100 -> 665.39 | O11: =N11*0.529 -> 351.99131 | P11: =O11*12.44 -> 4378.7719 | AC11: =Q11+T11+W11+Z11 -> 0 | AD11: =(R11+U11+X11+AA11)/4 -> 0 | AE11: =(S11+V11+Y11+AB11)/4 -> 0
A12: 44904 | B12: 82 | C12: =IF(AC12>0,((B12-R12)+(S12-B13)),IF(B13=0, ,(B12-B13))) -> 0 | D12: 81 | E12: =IF(AC12>0,((D12-U12)+(V12-D13)),IF(D13=0, ,(D12-D13))) -> 1 | F12: 80 | G12: =IF(AC12>0,((F12-X12)+(Y12-F13)),IF(F13=0, ,(F12-F13))) -> 2 | H12: 80 | I12: =IF(AC12>0,((H12-AA12)+(AB12-H13)),IF(H13=0, ,(H12-H13))) -> 5 | J12: =B12+D12+F12+H12 -> 323 | K12: =J12/4 -> 80.75 | L12: =IF(AC12>0,((K12-AD12)+(AE12-K13)),IF(K13=0, ,(K12-K13))) -> 2 | M12: =6049*4 -> 24196 | N12: =L12*M12/100 -> 483.92 | O12: =N12*0.529 -> 255.99368 | P12: =O12*12.44 -> 3184.5614 | AC12: =Q12+T12+W12+Z12 -> 0 | AD12: =(R12+U12+X12+AA12)/4 -> 0 | AE12: =(S12+V12+Y12+AB12)/4 -> 0
A13: 44905 | B13: 82 | C13: =IF(AC13>0,((B13-R13)+(S13-B14)),IF(B14=0, ,(B13-B14))) -> 2 | D13: 80 | E13: =IF(AC13>0,((D13-U13)+(V13-D14)),IF(D14=0, ,(D13-D14))) -> 3 | F13: 78 | G13: =IF(AC13>0,((F13-X13)+(Y13-F14)),IF(F14=0, ,(F13-F14))) -> 4 | H13: 75 | I13: =IF(AC13>0,((H13-AA13)+(AB13-H14)),IF(H14=0, ,(H13-H14))) -> 3 | J13: =B13+D13+F13+H13 -> 315 | K13: =J13/4 -> 78.75 | L13: =IF(AC13>0,((K13-AD13)+(AE13-K14)),IF(K14=0, ,(K13-K14))) -> 3 | M13: =6049*4 -> 24196 | N13: =L13*M13/100 -> 725.88 | O13: =N13*0.529 -> 383.99052 | P13: =O13*12.44 -> 4776.8421 | AC13: =Q13+T13+W13+Z13 -> 0 | AD13: =(R13+U13+X13+AA13)/4 -> 0 | AE13: =(S13+V13+Y13+AB13)/4 -> 0
A14: 44906 | B14: 80 | C14: =IF(AC14>0,((B14-R14)+(S14-B15)),IF(B15=0, ,(B14-B15))) -> 2 | D14: 77 | E14: =IF(AC14>0,((D14-U14)+(V14-D15)),IF(D15=0, ,(D14-D15))) -> 3 | F14: 74 | G14: =IF(AC14>0,((F14-X14)+(Y14-F15)),IF(F15=0, ,(F14-F15))) -> 4 | H14: 72 | I14: =IF(AC14>0,((H14-AA14)+(AB14-H15)),IF(H15=0, ,(H14-H15))) -> 3 | J14: =B14+D14+F14+H14 -> 303 | K14: =J14/4 -> 75.75 | L14: =IF(AC14>0,((K14-AD14)+(AE14-K15)),IF(K15=0, ,(K14-K15))) -> 3 | M14: =6049*4 -> 24196 | N14: =L14*M14/100 -> 725.88 | O14: =N14*0.529 -> 383.99052 | P14: =O14*12.44 -> 4776.8421 | AC14: =Q14+T14+W14+Z14 -> 0 | AD14: =(R14+U14+X14+AA14)/4 -> 0 | AE14: =(S14+V14+Y14+AB14)/4 -> 0
A15: 44907 | B15: 78 | C15: =IF(AC15>0,((B15-R15)+(S15-B16)),IF(B16=0, ,(B15-B16))) -> 3 | D15: 74 | E15: =IF(AC15>0,((D15-U15)+(V15-D16)),IF(D16=0, ,(D15-D16))) -> 2 | F15: 70 | G15: =IF(AC15>0,((F15-X15)+(Y15-F16)),IF(F16=0, ,(F15-F16))) -> 0 | H15: 69 | I15: =IF(AC15>0,((H15-AA15)+(AB15-H16)),IF(H16=0, ,(H15-H16))) -> 3 | J15: =B15+D15+F15+H15 -> 291 | K15: =J15/4 -> 72.75 | L15: =IF(AC15>0,((K15-AD15)+(AE15-K16)),IF(K16=0, ,(K15-K16))) -> 2 | M15: =6049*4 -> 24196 | N15: =L15*M15/100 -> 483.92 | O15: =N15*0.529 -> 255.99368 | P15: =O15*11.565 -> 2960.5669 | AC15: =Q15+T15+W15+Z15 -> 0 | AD15: =(R15+U15+X15+AA15)/4 -> 0 | AE15: =(S15+V15+Y15+AB15)/4 -> 0
A16: 44908 | B16: 75 | C16: =IF(AC16>0,((B16-R16)+(S16-B17)),IF(B17=0, ,(B16-B17))) -> 5 | D16: 72 | E16: =IF(AC16>0,((D16-U16)+(V16-D17)),IF(D17=0, ,(D16-D17))) -> 2 | F16: 70 | G16: =IF(AC16>0,((F16-X16)+(Y16-F17)),IF(F17=0, ,(F16-F17))) -> 5 | H16: 66 | I16: =IF(AC16>0,((H16-AA16)+(AB16-H17)),IF(H17=0, ,(H16-H17))) -> 3 | J16: =B16+D16+F16+H16 -> 283 | K16: =J16/4 -> 70.75 | L16: =IF(AC16>0,((K16-AD16)+(AE16-K17)),IF(K17=0, ,(K16-K17))) -> 3.75 | M16: =6049*4 -> 24196 | N16: =L16*M16/100 -> 907.35 | O16: =N16*0.529 -> 479.98815 | P16: =O16*11.565 -> 5551.063 | AC16: =Q16+T16+W16+Z16 -> 0 | AD16: =(R16+U16+X16+AA16)/4 -> 0 | AE16: =(S16+V16+Y16+AB16)/4 -> 0
A17: 44909 | B17: 70 | C17: =IF(AC17>0,((B17-R17)+(S17-B18)),IF(B18=0, ,(B17-B18))) -> 5 | D17: 70 | E17: =IF(AC17>0,((D17-U17)+(V17-D18)),IF(D18=0, ,(D17-D18))) -> 6 | F17: 65 | G17: =IF(AC17>0,((F17-X17)+(Y17-F18)),IF(F18=0, ,(F17-F18))) -> 2 | H17: 63 | I17: =IF(AC17>0,((H17-AA17)+(AB17-H18)),IF(H18=0, ,(H17-H18))) -> 3 | J17: =B17+D17+F17+H17 -> 268 | K17: =J17/4 -> 67 | L17: =IF(AC17>0,((K17-AD17)+(AE17-K18)),IF(K18=0, ,(K17-K18))) -> 4 | M17: =6049*4 -> 24196 | N17: =L17*M17/100 -> 967.84 | O17: =N17*0.529 -> 511.98736 | P17: =O17*11.565 -> 5921.1338 | AC17: =Q17+T17+W17+Z17 -> 0 | AD17: =(R17+U17+X17+AA17)/4 -> 0 | AE17: =(S17+V17+Y17+AB17)/4 -> 0
A18: 44910 | B18: 65 | C18: =IF(AC18>0,((B18-R18)+(S18-B19)),IF(B19=0, ,(B18-B19))) -> 0 | D18: 64 | E18: =IF(AC18>0,((D18-U18)+(V18-D19)),IF(D19=0, ,(D18-D19))) -> 0 | F18: 63 | G18: =IF(AC18>0,((F18-X18)+(Y18-F19)),IF(F19=0, ,(F18-F19))) -> 3 | H18: 60 | I18: =IF(AC18>0,((H18-AA18)+(AB18-H19)),IF(H19=0, ,(H18-H19))) -> 1 | J18: =B18+D18+F18+H18 -> 252 | K18: =J18/4 -> 63 | L18: =IF(AC18>0,((K18-AD18)+(AE18-K19)),IF(K19=0, ,(K18-K19))) -> 1 | M18: =6049*4 -> 24196 | N18: =L18*M18/100 -> 241.96 | O18: =N18*0.529 -> 127.99684 | P18: =O18*11.565 -> 1480.2835 | AC18: =Q18+T18+W18+Z18 -> 0 | AD18: =(R18+U18+X18+AA18)/4 -> 0 | AE18: =(S18+V18+Y18+AB18)/4 -> 0
A19: 44911 | B19: 65 | C19: =IF(AC19>0,((B19-R19)+(S19-B20)),IF(B20=0, ,(B19-B20))) -> 4 | D19: 64 | E19: =IF(AC19>0,((D19-U19)+(V19-D20)),IF(D20=0, ,(D19-D20))) -> 4 | F19: 60 | G19: =IF(AC19>0,((F19-X19)+(Y19-F20)),IF(F20=0, ,(F19-F20))) -> 4 | H19: 59 | I19: =IF(AC19>0,((H19-AA19)+(AB19-H20)),IF(H20=0, ,(H19-H20))) -> 4 | J19: =B19+D19+F19+H19 -> 248 | K19: =J19/4 -> 62 | L19: =IF(AC19>0,((K19-AD19)+(AE19-K20)),IF(K20=0, ,(K19-K20))) -> 4 | M19: =6049*4 -> 24196 | N19: =L19*M19/100 -> 967.84 | O19: =N19*0.529 -> 511.98736 | P19: =O19*11.565 -> 5921.1338 | AC19: =Q19+T19+W19+Z19 -> 0 | AD19: =(R19+U19+X19+AA19)/4 -> 0 | AE19: =(S19+V19+Y19+AB19)/4 -> 0
A20: 44912 | B20: 61 | C20: =IF(AC20>0,((B20-R20)+(S20-B21)),IF(B21=0, ,(B20-B21))) -> 3 | D20: 60 | E20: =IF(AC20>0,((D20-U20)+(V20-D21)),IF(D21=0, ,(D20-D21))) -> 3 | F20: 56 | G20: =IF(AC20>0,((F20-X20)+(Y20-F21)),IF(F21=0, ,(F20-F21))) -> 4 | H20: 55 | I20: =IF(AC20>0,((H20-AA20)+(AB20-H21)),IF(H21=0, ,(H20-H21))) -> 4 | J20: =B20+D20+F20+H20 -> 232 | K20: =J20/4 -> 58 | L20: =IF(AC20>0,((K20-AD20)+(AE20-K21)),IF(K21=0, ,(K20-K21))) -> 3.5 | M20: =6049*4 -> 24196 | N20: =L20*M20/100 -> 846.86 | O20: =N20*0.529 -> 447.98894 | P20: =O20*11.565 -> 5180.9921 | AC20: =Q20+T20+W20+Z20 -> 0 | AD20: =(R20+U20+X20+AA20)/4 -> 0 | AE20: =(S20+V20+Y20+AB20)/4 -> 0
A21: 44913 | B21: 58 | C21: =IF(AC21>0,((B21-R21)+(S21-B22)),IF(B22=0, ,(B21-B22))) -> 4 | D21: 57 | E21: =IF(AC21>0,((D21-U21)+(V21-D22)),IF(D22=0, ,(D21-D22))) -> 7 | F21: 52 | G21: =IF(AC21>0,((F21-X21)+(Y21-F22)),IF(F22=0, ,(F21-F22))) -> 3 | H21: 51 | I21: =IF(AC21>0,((H21-AA21)+(AB21-H22)),IF(H22=0, ,(H21-H22))) -> 6 | J21: =B21+D21+F21+H21 -> 218 | K21: =J21/4 -> 54.5 | L21: =IF(AC21>0,((K21-AD21)+(AE21-K22)),IF(K22=0, ,(K21-K22))) -> 5 | M21: =6049*4 -> 24196 | N21: =L21*M21/100 -> 1209.8 | O21: =N21*0.529 -> 639.9842 | P21: =O21*11.565 -> 7401.4173 | AC21: =Q21+T21+W21+Z21 -> 0 | AD21: =(R21+U21+X21+AA21)/4 -> 0 | AE21: =(S21+V21+Y21+AB21)/4 -> 0
A22: 44914 | B22: 54 | C22: =IF(AC22>0,((B22-R22)+(S22-B23)),IF(B23=0, ,(B22-B23))) -> 2 | D22: 50 | E22: =IF(AC22>0,((D22-U22)+(V22-D23)),IF(D23=0, ,(D22-D23))) -> 0 | F22: 49 | G22: =IF(AC22>0,((F22-X22)+(Y22-F23)),IF(F23=0, ,(F22-F23))) -> 9 | H22: 45 | I22: =IF(AC22>0,((H22-AA22)+(AB22-H23)),IF(H23=0, ,(H22-H23))) -> 7 | J22: =B22+D22+F22+H22 -> 198 | K22: =J22/4 -> 49.5 | L22: =IF(AC22>0,((K22-AD22)+(AE22-K23)),IF(K23=0, ,(K22-K23))) -> 4.5 | M22: =6049*4 -> 24196 | N22: =L22*M22/100 -> 1088.82 | O22: =N22*0.529 -> 575.98578 | P22: =O22*11.565 -> 6661.2755 | Q22: 2237 | R22: 52 | S22: 80 | T22: 2333 | U22: 50 | V22: 80 | W22: 2527 | X22: 42 | Y22: 80 | Z22: 2555 | AA22: 45 | AB22: 85 | AC22: =Q22+T22+W22+Z22 -> 9652 | AD22: =(R22+U22+X22+AA22)/4 -> 47.25 | AE22: =(S22+V22+Y22+AB22)/4 -> 81.25
A23: 44915 | B23: 80 | C23: =IF(AC23>0,((B23-R23)+(S23-B24)),IF(B24=0, ,(B23-B24))) -> 3 | D23: 80 | E23: =IF(AC23>0,((D23-U23)+(V23-D24)),IF(D24=0, ,(D23-D24))) -> 2 | F23: 78 | G23: =IF(AC23>0,((F23-X23)+(Y23-F24)),IF(F24=0, ,(F23-F24))) -> 1 | H23: 78 | I23: =IF(AC23>0,((H23-AA23)+(AB23-H24)),IF(H24=0, ,(H23-H24))) -> 1 | J23: =B23+D23+F23+H23 -> 316 | K23: =J23/4 -> 79 | L23: =IF(AC23>0,((K23-AD23)+(AE23-K24)),IF(K24=0, ,(K23-K24))) -> 1.75 | M23: =6049*4 -> 24196 | N23: =L23*M23/100 -> 423.43 | O23: =N23*0.529 -> 223.99447 | P23: =O23*11.565 -> 2590.496 | AC23: =Q23+T23+W23+Z23 -> 0 | AD23: =(R23+U23+X23+AA23)/4 -> 0 | AE23: =(S23+V23+Y23+AB23)/4 -> 0
A24: 44916 | B24: 77 | C24: =IF(AC24>0,((B24-R24)+(S24-B25)),IF(B25=0, ,(B24-B25))) -> 2 | D24: 78 | E24: =IF(AC24>0,((D24-U24)+(V24-D25)),IF(D25=0, ,(D24-D25))) -> 2 | F24: 77 | G24: =IF(AC24>0,((F24-X24)+(Y24-F25)),IF(F25=0, ,(F24-F25))) -> 2 | H24: 77 | I24: =IF(AC24>0,((H24-AA24)+(AB24-H25)),IF(H25=0, ,(H24-H25))) -> 3 | J24: =B24+D24+F24+H24 -> 309 | K24: =J24/4 -> 77.25 | L24: =IF(AC24>0,((K24-AD24)+(AE24-K25)),IF(K25=0, ,(K24-K25))) -> 2.25 | M24: =6049*4 -> 24196 | N24: =L24*M24/100 -> 544.41 | O24: =N24*0.529 -> 287.99289 | P24: =O24*11.565 -> 3330.6378 | AC24: =Q24+T24+W24+Z24 -> 0 | AD24: =(R24+U24+X24+AA24)/4 -> 0 | AE24: =(S24+V24+Y24+AB24)/4 -> 0
A25: 44917 | B25: 75 | C25: =IF(AC25>0,((B25-R25)+(S25-B26)),IF(B26=0, ,(B25-B26))) -> 3 | D25: 76 | E25: =IF(AC25>0,((D25-U25)+(V25-D26)),IF(D26=0, ,(D25-D26))) -> 2 | F25: 75 | G25: =IF(AC25>0,((F25-X25)+(Y25-F26)),IF(F26=0, ,(F25-F26))) -> 3 | H25: 74 | I25: =IF(AC25>0,((H25-AA25)+(AB25-H26)),IF(H26=0, ,(H25-H26))) -> 3 | J25: =B25+D25+F25+H25 -> 300 | K25: =J25/4 -> 75 | L25: =IF(AC25>0,((K25-AD25)+(AE25-K26)),IF(K26=0, ,(K25-K26))) -> 2.75 | M25: =6049*4 -> 24196 | N25: =L25*M25/100 -> 665.39 | O25: =N25*0.529 -> 351.99131 | P25: =O25*11.565 -> 4070.7795 | AC25: =Q25+T25+W25+Z25 -> 0 | AD25: =(R25+U25+X25+AA25)/4 -> 0 | AE25: =(S25+V25+Y25+AB25)/4 -> 0
A26: 44918 | B26: 72 | C26: =IF(AC26>0,((B26-R26)+(S26-B27)),IF(B27=0, ,(B26-B27))) -> 4 | D26: 74 | E26: =IF(AC26>0,((D26-U26)+(V26-D27)),IF(D27=0, ,(D26-D27))) -> 5 | F26: 72 | G26: =IF(AC26>0,((F26-X26)+(Y26-F27)),IF(F27=0, ,(F26-F27))) -> 4 | H26: 71 | I26: =IF(AC26>0,((H26-AA26)+(AB26-H27)),IF(H27=0, ,(H26-H27))) -> 4 | J26: =B26+D26+F26+H26 -> 289 | K26: =J26/4 -> 72.25 | L26: =IF(AC26>0,((K26-AD26)+(AE26-K27)),IF(K27=0, ,(K26-K27))) -> 4.25 | M26: =6049*4 -> 24196 | N26: =L26*M26/100 -> 1028.33 | O26: =N26*0.529 -> 543.98657 | P26: =O26*11.565 -> 6291.2047 | AC26: =Q26+T26+W26+Z26 -> 0 | AD26: =(R26+U26+X26+AA26)/4 -> 0 | AE26: =(S26+V26+Y26+AB26)/4 -> 0
A27: 44919 | B27: 68 | C27: =IF(AC27>0,((B27-R27)+(S27-B28)),IF(B28=0, ,(B27-B28))) -> 8 | D27: 69 | E27: =IF(AC27>0,((D27-U27)+(V27-D28)),IF(D28=0, ,(D27-D28))) -> 9 | F27: 68 | G27: =IF(AC27>0,((F27-X27)+(Y27-F28)),IF(F28=0, ,(F27-F28))) -> 7 | H27: 67 | I27: =IF(AC27>0,((H27-AA27)+(AB27-H28)),IF(H28=0, ,(H27-H28))) -> 3 | J27: =B27+D27+F27+H27 -> 272 | K27: =J27/4 -> 68 | L27: =IF(AC27>0,((K27-AD27)+(AE27-K28)),IF(K28=0, ,(K27-K28))) -> 6.75 | M27: =6049*4 -> 24196 | N27: =L27*M27/100 -> 1633.23 | O27: =N27*0.529 -> 863.97867 | P27: =O27*11.565 -> 9991.9133 | AC27: =Q27+T27+W27+Z27 -> 0 | AD27: =(R27+U27+X27+AA27)/4 -> 0 | AE27: =(S27+V27+Y27+AB27)/4 -> 0
A28: 44920 | B28: 60 | C28: =IF(AC28>0,((B28-R28)+(S28-B29)),IF(B29=0, ,(B28-B29))) -> 5 | D28: 60 | E28: =IF(AC28>0,((D28-U28)+(V28-D29)),IF(D29=0, ,(D28-D29))) -> 5 | F28: 61 | G28: =IF(AC28>0,((F28-X28)+(Y28-F29)),IF(F29=0, ,(F28-F29))) -> 2 | H28: 64 | I28: =IF(AC28>0,((H28-AA28)+(AB28-H29)),IF(H29=0, ,(H28-H29))) -> 4 | J28: =B28+D28+F28+H28 -> 245 | K28: =J28/4 -> 61.25 | L28: =IF(AC28>0,((K28-AD28)+(AE28-K29)),IF(K29=0, ,(K28-K29))) -> 4 | M28: =6049*4 -> 24196 | N28: =L28*M28/100 -> 967.84 | O28: =N28*0.529 -> 511.98736 | P28: =O28*11.565 -> 5921.1338 | AC28: =Q28+T28+W28+Z28 -> 0 | AD28: =(R28+U28+X28+AA28)/4 -> 0 | AE28: =(S28+V28+Y28+AB28)/4 -> 0
A29: 44921 | B29: 55 | C29: =IF(AC29>0,((B29-R29)+(S29-B30)),IF(B30=0, ,(B29-B30))) -> 5 | D29: 55 | E29: =IF(AC29>0,((D29-U29)+(V29-D30)),IF(D30=0, ,(D29-D30))) -> 4 | F29: 59 | G29: =IF(AC29>0,((F29-X29)+(Y29-F30)),IF(F30=0, ,(F29-F30))) -> 3 | H29: 60 | I29: =IF(AC29>0,((H29-AA29)+(AB29-H30)),IF(H30=0, ,(H29-H30))) -> 2 | J29: =B29+D29+F29+H29 -> 229 | K29: =J29/4 -> 57.25 | L29: =IF(AC29>0,((K29-AD29)+(AE29-K30)),IF(K30=0, ,(K29-K30))) -> 3.5 | M29: =6049*4 -> 24196 | N29: =L29*M29/100 -> 846.86 | O29: =N29*0.529 -> 447.98894 | P29: =O29*11.565 -> 5180.9921 | AC29: =Q29+T29+W29+Z29 -> 0 | AD29: =(R29+U29+X29+AA29)/4 -> 0 | AE29: =(S29+V29+Y29+AB29)/4 -> 0
A30: 44922 | B30: 50 | C30: =IF(AC30>0,((B30-R30)+(S30-B31)),IF(B31=0, ,(B30-B31))) -> 5 | D30: 51 | E30: =IF(AC30>0,((D30-U30)+(V30-D31)),IF(D31=0, ,(D30-D31))) -> 6 | F30: 56 | G30: =IF(AC30>0,((F30-X30)+(Y30-F31)),IF(F31=0, ,(F30-F31))) -> 8 | H30: 58 | I30: =IF(AC30>0,((H30-AA30)+(AB30-H31)),IF(H31=0, ,(H30-H31))) -> 8 | J30: =B30+D30+F30+H30 -> 215 | K30: =J30/4 -> 53.75 | L30: =IF(AC30>0,((K30-AD30)+(AE30-K31)),IF(K31=0, ,(K30-K31))) -> 6.75 | M30: =6049*4 -> 24196 | N30: =L30*M30/100 -> 1633.23 | O30: =N30*0.529 -> 863.97867 | P30: =O30*11.565 -> 9991.9133 | Q30: 2950 | R30: 48 | S30: 83 | T30: 2915 | U30: 50 | V30: 85 | W30: 2911 | X30: 50 | Y30: 85 | Z30: 2918 | AA30: 50 | AB30: 85 | AC30: =Q30+T30+W30+Z30 -> 11694 | AD30: =(R30+U30+X30+AA30)/4 -> 49.5 | AE30: =(S30+V30+Y30+AB30)/4 -> 84.5
A31: 44923 | B31: 80 | C31: =IF(AC31>0,((B31-R31)+(S31-B32)),IF(B32=0, ,(B31-B32))) -> 0 | D31: 80 | E31: =IF(AC31>0,((D31-U31)+(V31-D32)),IF(D32=0, ,(D31-D32))) -> 0 | F31: 83 | G31: =IF(AC31>0,((F31-X31)+(Y31-F32)),IF(F32=0, ,(F31-F32))) -> 0 | H31: 85 | I31: =IF(AC31>0,((H31-AA31)+(AB31-H32)),IF(H32=0, ,(H31-H32))) -> 0 | J31: =B31+D31+F31+H31 -> 328 | K31: =J31/4 -> 82 | L31: =IF(AC31>0,((K31-AD31)+(AE31-K32)),IF(K32=0, ,(K31-K32))) -> 0 | M31: =6049*4 -> 24196 | N31: =L31*M31/100 -> 0 | O31: =N31*0.529 -> 0 | P31: =O31*11.565 -> 0 | AC31: =Q31+T31+W31+Z31 -> 0 | AD31: =(R31+U31+X31+AA31)/4 -> 0 | AE31: =(S31+V31+Y31+AB31)/4 -> 0
A32: 44924 | C32: =IF(AC32>0,((B32-R32)+(S32-B33)),IF(B33=0, ,(B32-B33))) -> 0 | E32: =IF(AC32>0,((D32-U32)+(V32-D33)),IF(D33=0, ,(D32-D33))) -> 0 | G32: =IF(AC32>0,((F32-X32)+(Y32-F33)),IF(F33=0, ,(F32-F33))) -> 0 | I32: =IF(AC32>0,((H32-AA32)+(AB32-H33)),IF(H33=0, ,(H32-H33))) -> 0 | J32: =B32+D32+F32+H32 -> 0 | K32: =J32/4 -> 0 | L32: =IF(AC32>0,((K32-AD32)+(AE32-K33)),IF(K33=0, ,(K32-K33))) -> 0 | M32: =6049*4 -> 24196 | N32: =L32*M32/100 -> 0 | O32: =N32*0.529 -> 0 | P32: =O32*11.565 -> 0 | AC32: =Q32+T32+W32+Z32 -> 0 | AD32: =(R32+U32+X32+AA32)/4 -> 0 | AE32: =(S32+V32+Y32+AB32)/4 -> 0
A33: 44925 | C33: =IF(AC33>0,((B33-R33)+(S33-B34)),IF(B34=0, ,(B33-B34))) -> 0 | E33: =IF(AC33>0,((D33-U33)+(V33-D34)),IF(D34=0, ,(D33-D34))) -> 0 | G33: =IF(AC33>0,((F33-X33)+(Y33-F34)),IF(F34=0, ,(F33-F34))) -> 0 | I33: =IF(AC33>0,((H33-AA33)+(AB33-H34)),IF(H34=0, ,(H33-H34))) -> 0 | J33: =B33+D33+F33+H33 -> 0 | K33: =J33/4 -> 0 | L33: =IF(AC33>0,((K33-AD33)+(AE33-K34)),IF(K34=0, ,(K33-K34))) -> 0 | M33: =6049*4 -> 24196 | N33: =L33*M33/100 -> 0 | O33: =N33*0.529 -> 0 | P33: =O33*11.565 -> 0 | AC33: =Q33+T33+W33+Z33 -> 0 | AD33: =(R33+U33+X33+AA33)/4 -> 0 | AE33: =(S33+V33+Y33+AB33)/4 -> 0
A34: 44926 | C34: =IF(AC34>0,((B34-R34)+(S34-B35)),IF(B35=0, ,(B34-B35))) -> 0 | E34: =IF(AC34>0,((D34-U34)+(V34-D35)),IF(D35=0, ,(D34-D35))) -> 0 | G34: =IF(AC34>0,((F34-X34)+(Y34-F35)),IF(F35=0, ,(F34-F35))) -> 0 | I34: =IF(AC34>0,((H34-AA34)+(AB34-H35)),IF(H35=0, ,(H34-H35))) -> 0 | J34: =B34+D34+F34+H34 -> 0 | K34: =J34/4 -> 0 | L34: =IF(AC34>0,((K34-AD34)+(AE34-K35)),IF(K35=0, ,(K34-K35))) -> 0 | M34: =6049*4 -> 24196 | N34: =L34*M34/100 -> 0 | O34: =N34*0.529 -> 0 | P34: =O34*11.565 -> 0 | AC34: =Q34+T34+W34+Z34 -> 0 | AD34: =(R34+U34+X34+AA34)/4 -> 0 | AE34: =(S34+V34+Y34+AB34)/4 -> 0
A35: 44927 | C35: =IF(AC35>0,((B35-R35)+(S35-B36)),IF(B36=0, ,(B35-B36))) -> 0 | E35: =IF(AC35>0,((D35-U35)+(V35-D36)),IF(D36=0, ,(D35-D36))) -> 0 | G35: =IF(AC35>0,((F35-X35)+(Y35-F36)),IF(F36=0, ,(F35-F36))) -> 0 | I35: =IF(AC35>0,((H35-AA35)+(AB35-H36)),IF(H36=0, ,(H35-H36))) -> 0 | J35: =B35+D35+F35+H35 -> 0 | K35: =J35/4 -> 0 | L35: =IF(AC35>0,((K35-AD35)+(AE35-K36)),IF(K36=0, ,(K35-K36))) -> 0 | M35: =6049*4 -> 24196 | N35: =L35*M35/100 -> 0 | O35: =N35*0.529 -> 0 | P35: =O35*11.565 -> 0 | AC35: =Q35+T35+W35+Z35 -> 0 | AD35: =(R35+U35+X35+AA35)/4 -> 0 | AE35: =(S35+V35+Y35+AB35)/4 -> 0
C36: =IF(AC36>0,((B36-R36)+(S36-B37)),IF(B37=0, ,(B36-B37))) -> 0 | E36: =IF(AC36>0,((D36-U36)+(V36-D37)),IF(D37=0, ,(D36-D37))) -> 0 | G36: =IF(AC36>0,((F36-X36)+(Y36-F37)),IF(F37=0, ,(F36-F37))) -> 0 | I36: =IF(AC36>0,((H36-AA36)+(AB36-H37)),IF(H37=0, ,(H36-H37))) -> 0 | J36: =B36+D36+F36+H36 -> 0 | K36: =J36/4 -> 0 | L36: =IF(AC36>0,((K36-AD36)+(AE36-K37)),IF(K37=0, ,(K36-K37))) -> 0 | M36: =6049*4 -> 24196 | N36: =L36*M36/100 -> 0 | O36: =N36*0.529 -> 0 | P36: =O36*11.565 -> 0 | AC36: =Q36+T36+W36+Z36 -> 0 | AD36: =(R36+U36+X36+AA36)/4 -> 0 | AE36: =(S36+V36+Y36+AB36)/4 -> 0
C37: =IF(AC37>0,((B37-R37)+(S37-B38)),IF(B38=0, ,(B37-B38))) -> 0 | E37: =IF(AC37:AC60>0,((D37-U37)+(V37-D38)),IF(D38=0, ,(D37-D38))) -> 0 | G37: =IF(AC37>0,((F37-X37)+(Y37-F38)),IF(F38=0, ,(F37-F38))) -> 0 | I37: =IF(AC37>0,((H37-AA37)+(AB37-H38)),IF(H38=0, ,(H37-H38))) -> 0 | J37: =B37+D37+F37+H37 -> 0 | K37: =J37/4 -> 0 | L37: =IF(AC37>0,((K37-AD37)+(AE37-K38)),IF(K38=0, ,(K37-K38))) -> 0 | M37: =6049*4 -> 24196 | N37: =L37*M37/100 -> 0 | O37: =N37*0.529 -> 0 | P37: =O37*11.565 -> 0 | AC37: =Q37+T37+W37+Z37 -> 0 | AD37: =(R37+U37+X37+AA37)/4 -> 0 | AE37: =(S37+V37+Y37+AB37)/4 -> 0
C38: =IF(AC38>0,((B38-R38)+(S38-B39)),IF(B39=0, ,(B38-B39))) -> 0 | E38: =IF(AC38:AC61>0,((D38-U38)+(V38-D39)),IF(D39=0, ,(D38-D39))) -> 0 | G38: =IF(AC38>0,((F38-X38)+(Y38-F39)),IF(F39=0, ,(F38-F39))) -> 0 | I38: =IF(AC38>0,((H38-AA38)+(AB38-H39)),IF(H39=0, ,(H38-H39))) -> 0 | J38: =B38+D38+F38+H38 -> 0 | K38: =J38/4 -> 0 | L38: =IF(AC38>0,((K38-AD38)+(AE38-K39)),IF(K39=0, ,(K38-K39))) -> 0 | M38: =6049*4 -> 24196 | N38: =L38*M38/100 -> 0 | O38: =N38*0.53 -> 0 | P38: =O38*11.2513 -> 0 | AC38: =Q38+T38+W38+Z38 -> 0 | AD38: =(R38+U38+X38+AA38)/4 -> 0 | AE38: =(S38+V38+Y38+AB38)/4 -> 0
C39: =IF(AC39>0,((B39-R39)+(S39-B40)),IF(B40=0, ,(B39-B40))) -> 0 | E39: =IF(AC39>0,((D39-U39)+(V39-D40)),IF(D40=0, ,(D39-D40))) -> 0 | G39: =IF(AC39>0,((F39-X39)+(Y39-F40)),IF(F40=0, ,(F39-F40))) -> 0 | I39: =IF(AC39>0,((H39-AA39)+(AB39-H40)),IF(H40=0, ,(H39-H40))) -> 0 | J39: =B39+D39+F39+H39 -> 0 | K39: =J39/4 -> 0 | L39: =IF(AC39>0,((K39-AD39)+(AE39-K40)),IF(K40=0, ,(K39-K40))) -> 0 | M39: =6049*4 -> 24196 | N39: =L39*M39/100 -> 0 | O39: =N39*0.53 -> 0 | P39: =O39*11.2513 -> 0 | AC39: =Q39+T39+W39+Z39 -> 0 | AD39: =(R39+U39+X39+AA39)/4 -> 0 | AE39: =(S39+V39+Y39+AB39)/4 -> 0
C40: =IF(AC40>0,((B40-R40)+(S40-B41)),IF(B41=0, ,(B40-B41))) -> 0 | E40: =IF(AC40>0,((D40-U40)+(V40-D41)),IF(D41=0, ,(D40-D41))) -> 0 | G40: =IF(AC40>0,((F40-X40)+(Y40-F41)),IF(F41=0, ,(F40-F41))) -> 0 | I40: =IF(AC40>0,((H40-AA40)+(AB40-H41)),IF(H41=0, ,(H40-H41))) -> 0 | J40: =B40+D40+F40+H40 -> 0 | K40: =J40/4 -> 0 | L40: =IF(AC40>0,((K40-AD40)+(AE40-K41)),IF(K41=0, ,(K40-K41))) -> 0 | M40: =6049*4 -> 24196 | N40: =L40*M40/100 -> 0 | O40: =N40*0.53 -> 0 | P40: =O40*9.965 -> 0 | AC40: =Q40+T40+W40+Z40 -> 0 | AD40: =(R40+U40+X40+AA40)/4 -> 0 | AE40: =(S40+V40+Y40+AB40)/4 -> 0
...

Sheet Facture journalier D'élect
C1: Estimation de la consommation électrique Dec 2022 | H1: Fiche technique
H3: DT fourseasons CBL
A7: N° de compteur | C7: Ancienne date de lecture | E7: Nouvelle date de lecture | F7: N de jours de consommation | G7: Heures pleines | H7: Heures creuses | I7: Heures de pointe
A8: 95670781 | C8: 44922 | E8: 44923 | F8: 01jours
A11: Type de comptage | C11: Puissance installée KVA | E11: Puissance souscrite KVA | G11: Puissance appelée KVA | I11: Dépassement de la puissance souscrite KVA
A12: 4T | C12: 3750 | E12: 1000 | G12: 939
A16: Eléments de relève | C16: Nouvel Index | D16: Ancien Index | E16: Consommation | F16: Energie révaluée | G16: Consommation Compteur démarquant | I16: Energie à facturer
A17: HEURES PLEINE | C17: 21995481 | D17: 21989434 | E17: =MIN(C17-D17) -> 6047 | F17: =+E17 -> 6047 | I17: =+E17 -> 6047
A18: HEURES CREUSES | C18: 12886397 | D18: 12882514 | E18: =MIN(C18-D18) -> 3883 | F18: =+E18 -> 3883 | I18: =+E18 -> 3883
A19: HEURES DE POINTE | C19: 9648730 | D19: 9645715 | E19: =AVERAGE(C19-D19) -> 3015 | F19: =+E19 -> 3015 | I19: =+E19 -> 3015
A20: TOTAL | E20: =SUM(E17:E19) -> 12945
A23: Détail de la facture | D23: Quantité | E23: Prix unitaire | F23: Montant HT | G23: TVA | I23: Montant TTC
G24: Taux % | H24: Montant
A25: ENERGIE ACTIVE H. PLEINES | D25: =+E17 -> 6047 | E25: 0.9514 | F25: =PRODUCT(D25*E25) -> 5753.1158 | G25: 14 | H25: =PRODUCT(0.14,F25) -> 805.43621 | I25: =SUM(H25,F25) -> 6558.552
A26: ENERGIE ACTIVE H. CREUSES | D26: =+E18 -> 3883 | E26: 0.6985 | F26: =PRODUCT(D26*E26) -> 2712.2755 | G26: 14 | H26: =PRODUCT(0.14,F26) -> 379.71857 | I26: =SUM(H26,F26) -> 3091.9941
A27: ENETGIE ACTIVE H. DE POINTE | D27: =+E19 -> 3015 | E27: 1.3304 | F27: =PRODUCT(D27*E27) -> 4011.156 | G27: 14 | H27: =PRODUCT(0.14,F27) -> 561.56184 | I27: =SUM(H27,F27) -> 4572.7178
A28: REDEVANCE DE PUISSANCE | D28: 1000 | E28: 43.88167 | F28: =PRODUCT(D28,E28) -> 43881.67 | G28: 14 | H28: =PRODUCT(0.14,F28) -> 6143.4338 | I28: =SUM(H28,F28) -> 50025.104
A29: DEPASSEMENT DE PUISSANCE | D29: 0 | E29: 48.97249 | F29: =PRODUCT(D29,E29) -> 0 | G29: 14 | H29: =PRODUCT(0.14,F29) -> 0 | I29: =SUM(H29,F29) -> 0
A30: ENTRETIEN COMPTAGE | F30: 841 | G30: 20 | H30: =PRODUCT(F30,0.2) -> 168.2 | I30: =SUM(H30,F30) -> 1009.2
A31: LOCATION COMPTAGE | F31: 1492 | G31: 7 | H31: =PRODUCT(F31,0.07) -> 104.44 | I31: =SUM(H31,F31) -> 1596.44
A32: Total | F32: =SUM(F25:F31) -> 58691.217 | I32: =SUM(I25:J31) -> 66854.008

Sheet facture d'eau
B1: Estimation de la consommation d'Eau Sanitaire Dec 2022 | F1: Fiche technique
F3: DT fourseasons CBL
A7: N° de compteur | B7: Type de relevé | C7: Ancien index | D7: Ancienne date de lecture | E7: Nouvel index | F7: Nouvelle date de lecture | G7: Consommation M3 | H7: N de jours de consommation
B8: RELEVEE | C8: 0 | D8: 44166 | E8: 0 | F8: 44562 | G8: =E8-C8 -> 0
B10: Quantité | D10: Prix unitaire HT | F10: Montant HT
A11: Redevances Fixes | F11: 23
A12: Consommation eau
A13: Tranche unique | B13: =G8 -> 0 | D13: 8.79 | F13: =PRODUCT(D13,B13) -> 0
A14: Assainissement
A16: Tranche 1 | B16: 0 | D16: 0 | F16: =PRODUCT(D16,B16) -> 0
A17: Tranche 2 | B17: 0 | D17: 0 | F17: =PRODUCT(D17,B17) -> 0
A18: Tranche 3 | B18: 0 | D18: 0 | F18: =PRODUCT(D18,B18) -> 0
A19: Tranche 4 | B19: =G8 -> 0 | D19: 2.61 | F19: =PRODUCT(D19,B19) -> 0
