Workbook

Sheet TOTAL
A1: Site Name | B1: Day | C1: Month | D1: Year | E1: Total Electricity Kwh | F1: Electricity Tariff ($/Kwh) | G1: LPG (Kg) | H1: LPG $/Kg | I1: Water Utility Supply (m3) m3 | J1: Water Utility Supply (m3) $/m3 | K1: Irrigation Water (m3) m3 | L1: Irrigation water $/m3 | M1: Room Nights | N1: Total Guests
A2: Dubai at Jumeirah Beach | B2: 1 | C2: 12 | D2: 2022 | E2: =Submetering!M2+Submetering!N2+Submetering!O2+Submetering!P2+Submetering!Q2+Submetering!R2+Submetering!S2+Submetering!T2+Submetering!U2+Submetering!V2 -> 44091.6 | F2: 0.44448 | G2: =Submetering!Z2+Submetering!AA2+Submetering!AB2 -> 644.49 | H2: =1.74/0.52 -> 3.3461538 | I2: =Submetering!G2 -> 732 | J2: 13.83 | K2: =Submetering!BL2 -> 164 | L2: 1.2 | M2: =Submetering!E2 -> 94.8 | N2: =Submetering!F2 -> 182
A3: Dubai at Jumeirah Beach | B3: =B2+1 -> 2 | C3: 12 | D3: 2022 | E3: =Submetering!M3+Submetering!N3+Submetering!O3+Submetering!P3+Submetering!Q3+Submetering!R3+Submetering!S3+Submetering!T3+Submetering!U3+Submetering!V3 -> 43945.44 | F3: 0.44448 | G3: =Submetering!Z3+Submetering!AA3+Submetering!AB3 -> 621.81 | H3: =1.74/0.52 -> 3.3461538 | I3: =Submetering!G3 -> 673 | J3: 13.83 | K3: =Submetering!BL3 -> 176 | L3: 1.2 | M3: =Submetering!E3 -> 78.21 | N3: =Submetering!F3 -> 154
A4: Dubai at Jumeirah Beach | B4: =B3+1 -> 3 | C4: 12 | D4: 2022 | E4: =Submetering!M4+Submetering!N4+Submetering!O4+Submetering!P4+Submetering!Q4+Submetering!R4+Submetering!S4+Submetering!T4+Submetering!U4+Submetering!V4 -> 41850.48 | F4: 0.44448 | G4: =Submetering!Z4+Submetering!AA4+Submetering!AB4 -> 604.8 | H4: =1.74/0.52 -> 3.3461538 | I4: =Submetering!G4 -> 724 | J4: 13.83 | K4: =Submetering!BL4 -> 169 | L4: 1.2 | M4: =Submetering!E4 -> 85.32 | N4: =Submetering!F4 -> 162
A5: Dubai at Jumeirah Beach | B5: =B4+1 -> 4 | C5: 12 | D5: 2022 | E5: =Submetering!M5+Submetering!N5+Submetering!O5+Submetering!P5+Submetering!Q5+Submetering!R5+Submetering!S5+Submetering!T5+Submetering!U5+Submetering!V5 -> 42678.72 | F5: 0.44448 | G5: =Submetering!Z5+Submetering!AA5+Submetering!AB5 -> 667.17 | H5: =1.74/0.52 -> 3.3461538 | I5: =Submetering!G5 -> 664 | J5: 13.83 | K5: =Submetering!BL5 -> 162 | L5: 1.2 | M5: =Submetering!E5 -> 82.95 | N5: =Submetering!F5 -> 146
A6: Dubai at Jumeirah Beach | B6: =B5+1 -> 5 | C6: 12 | D6: 2022 | E6: =Submetering!M6+Submetering!N6+Submetering!O6+Submetering!P6+Submetering!Q6+Submetering!R6+Submetering!S6+Submetering!T6+Submetering!U6+Submetering!V6 -> 42142.8 | F6: 0.44448 | G6: =Submetering!Z6+Submetering!AA6+Submetering!AB6 -> 636.93 | H6: =1.74/0.52 -> 3.3461538 | I6: =Submetering!G6 -> 669 | J6: 13.83 | K6: =Submetering!BL6 -> 138 | L6: 1.2 | M6: =Submetering!E6 -> 97.17 | N6: =Submetering!F6 -> 166
A7: Dubai at Jumeirah Beach | B7: =B6+1 -> 6 | C7: 12 | D7: 2022 | E7: =Submetering!M7+Submetering!N7+Submetering!O7+Submetering!P7+Submetering!Q7+Submetering!R7+Submetering!S7+Submetering!T7+Submetering!U7+Submetering!V7 -> 41801.76 | F7: 0.44448 | G7: =Submetering!Z7+Submetering!AA7+Submetering!AB7 -> 627.48 | H7: =1.74/0.52 -> 3.3461538 | I7: =Submetering!G7 -> 677 | J7: 13.83 | K7: =Submetering!BL7 -> 137 | L7: 1.2 | M7: =Submetering!E7 -> 111.39 | N7: =Submetering!F7 -> 177
A8: Dubai at Jumeirah Beach | B8: =B7+1 -> 7 | C8: 12 | D8: 2022 | E8: =Submetering!M8+Submetering!N8+Submetering!O8+Submetering!P8+Submetering!Q8+Submetering!R8+Submetering!S8+Submetering!T8+Submetering!U8+Submetering!V8 -> 41996.64 | F8: 0.44448 | G8: =Submetering!Z8+Submetering!AA8+Submetering!AB8 -> 678.51 | H8: =1.74/0.52 -> 3.3461538 | I8: =Submetering!G8 -> 671 | J8: 13.83 | K8: =Submetering!BL8 -> 133 | L8: 1.2 | M8: =Submetering!E8 -> 130.35 | N8: =Submetering!F8 -> 202
A9: Dubai at Jumeirah Beach | B9: =B8+1 -> 8 | C9: 12 | D9: 2022 | E9: =Submetering!M9+Submetering!N9+Submetering!O9+Submetering!P9+Submetering!Q9+Submetering!R9+Submetering!S9+Submetering!T9+Submetering!U9+Submetering!V9 -> 47355.84 | F9: 0.44448 | G9: =Submetering!Z9+Submetering!AA9+Submetering!AB9 -> 725.76 | H9: =1.74/0.52 -> 3.3461538 | I9: =Submetering!G9 -> 775 | J9: 13.83 | K9: =Submetering!BL9 -> 149 | L9: 1.2 | M9: =Submetering!E9 -> 144.57 | N9: =Submetering!F9 -> 227
A10: Dubai at Jumeirah Beach | B10: =B9+1 -> 9 | C10: 12 | D10: 2022 | E10: =Submetering!M10+Submetering!N10+Submetering!O10+Submetering!P10+Submetering!Q10+Submetering!R10+Submetering!S10+Submetering!T10+Submetering!U10+Submetering!V10 -> 38537.52 | F10: 0.44448 | G10: =Submetering!Z10+Submetering!AA10+Submetering!AB10 -> 716.31 | H10: =1.74/0.52 -> 3.3461538 | I10: =Submetering!G10 -> 706 | J10: 13.83 | K10: =Submetering!BL10 -> 122 | L10: 1.2 | M10: =Submetering!E10 -> 151.68 | N10: =Submetering!F10 -> 240
A11: Dubai at Jumeirah Beach | B11: =B10+1 -> 10 | C11: 12 | D11: 2022 | E11: =Submetering!M11+Submetering!N11+Submetering!O11+Submetering!P11+Submetering!Q11+Submetering!R11+Submetering!S11+Submetering!T11+Submetering!U11+Submetering!V11 -> 41412 | F11: 0.44448 | G11: =Submetering!Z11+Submetering!AA11+Submetering!AB11 -> 801.36 | H11: =1.74/0.52 -> 3.3461538 | I11: =Submetering!G11 -> 715 | J11: 13.83 | K11: =Submetering!BL11 -> 140 | L11: 1.2 | M11: =Submetering!E11 -> 151.68 | N11: =Submetering!F11 -> 256
A12: Dubai at Jumeirah Beach | B12: =B11+1 -> 11 | C12: 12 | D12: 2022 | E12: =Submetering!M12+Submetering!N12+Submetering!O12+Submetering!P12+Submetering!Q12+Submetering!R12+Submetering!S12+Submetering!T12+Submetering!U12+Submetering!V12 -> 41168.4 | F12: 0.44448 | G12: =Submetering!Z12+Submetering!AA12+Submetering!AB12 -> 827.82 | H12: =1.74/0.52 -> 3.3461538 | I12: =Submetering!G12 -> 694 | J12: 13.83 | K12: =Submetering!BL12 -> 149 | L12: 1.2 | M12: =Submetering!E12 -> 144.57 | N12: =Submetering!F12 -> 226
A13: Dubai at Jumeirah Beach | B13: =B12+1 -> 12 | C13: 12 | D13: 2022 | E13: =Submetering!M13+Submetering!N13+Submetering!O13+Submetering!P13+Submetering!Q13+Submetering!R13+Submetering!S13+Submetering!T13+Submetering!U13+Submetering!V13 -> 42045.36 | F13: 0.44448 | G13: =Submetering!Z13+Submetering!AA13+Submetering!AB13 -> 839.16 | H13: =1.74/0.52 -> 3.3461538 | I13: =Submetering!G13 -> 744 | J13: 13.83 | K13: =Submetering!BL13 -> 139 | L13: 1.2 | M13: =Submetering!E13 -> 135.09 | N13: =Submetering!F13 -> 232
A14: Dubai at Jumeirah Beach | B14: =B13+1 -> 13 | C14: 12 | D14: 2022 | E14: =Submetering!M14+Submetering!N14+Submetering!O14+Submetering!P14+Submetering!Q14+Submetering!R14+Submetering!S14+Submetering!T14+Submetering!U14+Submetering!V14 -> 36929.76 | F14: 0.44448 | G14: =Submetering!Z14+Submetering!AA14+Submetering!AB14 -> 859.95 | H14: =1.74/0.52 -> 3.3461538 | I14: =Submetering!G14 -> 569 | J14: 13.83 | K14: =Submetering!BL14 -> 137 | L14: 1.2 | M14: =Submetering!E14 -> 106.65 | N14: =Submetering!F14 -> 193
... A27: Dubai at Jumeirah Beach | B27: =B26+1 -> 26 | C27: 12 | D27: 2022 | E27: =Submetering!M27+Submetering!N27+Submetering!O27+Submetering!P27+Submetering!Q27+Submetering!R27+Submetering!S27+Submetering!T27+Submetering!U27+Submetering!V27 -> 36783.6 | F27: 0.44448 | G27: =Submetering!Z27+Submetering!AA27+Submetering!AB27 -> 863.73 | H27: =1.74/0.52 -> 3.3461538 | I27: =Submetering!G27 -> 554 | J27: 13.83 | K27: =Submetering!BL27 -> 216 | L27: 1.2 | M27: =Submetering!E27 -> 173.01 | N27: =Submetering!F27 -> 418
A28: Dubai at Jumeirah Beach | B28: =B27+1 -> 27 | C28: 12 | D28: 2022 | E28: =Submetering!M28+Submetering!N28+Submetering!O28+Submetering!P28+Submetering!Q28+Submetering!R28+Submetering!S28+Submetering!T28+Submetering!U28+Submetering!V28 -> 37075.92 | F28: 0.44448 | G28: =Submetering!Z28+Submetering!AA28+Submetering!AB28 -> 765.45 | H28: =1.74/0.52 -> 3.3461538 | I28: =Submetering!G28 -> 554 | J28: 13.83 | K28: =Submetering!BL28 -> 179 | L28: 1.2 | M28: =Submetering!E29 -> 220.41 | N28: =Submetering!F28 -> 466
A29: Dubai at Jumeirah Beach | B29: =B28+1 -> 28 | C29: 12 | D29: 2022 | E29: =Submetering!M29+Submetering!N29+Submetering!O29+Submetering!P29+Submetering!Q29+Submetering!R29+Submetering!S29+Submetering!T29+Submetering!U29+Submetering!V29 -> 38440.08 | F29: 0.44448 | G29: =Submetering!Z29+Submetering!AA29+Submetering!AB29 -> 927.99 | H29: =1.74/0.52 -> 3.3461538 | I29: =Submetering!G29 -> 659 | J29: 13.83 | K29: =Submetering!BL29 -> 1 | L29: 1.2 | M29: =Submetering!#REF! -> #REF! | N29: =Submetering!F29 -> 464
A30: Dubai at Jumeirah Beach | B30: =B29+1 -> 29 | C30: 12 | D30: 2022 | E30: =Submetering!M30+Submetering!N30+Submetering!O30+Submetering!P30+Submetering!Q30+Submetering!R30+Submetering!S30+Submetering!T30+Submetering!U30+Submetering!V30 -> 39219.6 | F30: 0.44448 | G30: =Submetering!Z30+Submetering!AA30+Submetering!AB30 -> 856.17 | H30: =1.74/0.52 -> 3.3461538 | I30: =Submetering!G30 -> 660 | J30: 13.83 | K30: =Submetering!BL30 -> 0 | L30: 1.2 | M30: =Submetering!E30 -> 218.04 | N30: =Submetering!F30 -> 464
A31: Dubai at Jumeirah Beach | B31: =B30+1 -> 30 | C31: 12 | D31: 2022 | E31: =Submetering!M31+Submetering!N31+Submetering!O31+Submetering!P31+Submetering!Q31+Submetering!R31+Submetering!S31+Submetering!T31+Submetering!U31+Submetering!V31 -> 0 | F31: 0.44448 | G31: =Submetering!Z31+Submetering!AA31+Submetering!AB31 -> 0 | H31: =1.74/0.52 -> 3.3461538 | I31: =Submetering!G31 -> 0 | J31: 13.83 | K31: =Submetering!BL31 -> 0 | L31: 1.2 | M31: =Submetering!E31 -> 0 | N31: =Submetering!F31 -> 464
A32: Dubai at Jumeirah Beach | B32: =B31+1 -> 31 | C32: 12 | D32: 2022 | E32: =Submetering!M32+Submetering!N32+Submetering!O32+Submetering!P32+Submetering!Q32+Submetering!R32+Submetering!S32+Submetering!T32+Submetering!U32+Submetering!V32 -> 0 | F32: 0.44448 | G32: =Submetering!Z32+Submetering!AA32+Submetering!AB32 -> 0 | H32: =1.74/0.52 -> 3.3461538 | I32: =Submetering!G32 -> 0 | J32: 13.83 | K32: =Submetering!BL32 -> 0 | L32: 1.2 | M32: =Submetering!E32 -> 0 | N32: =Submetering!F32 -> 0

Sheet Submetering
A1: Site Name | B1: Day | C1: Month | D1: Year | E1: Room Nights | F1: Total Guests | G1: Potable Water -IG (m3) | H1: Resort Water (m3) | I1: Irrigation Water (m3) | J1: Domestic Water for Irrigation (m3) | K1: Cooling Tower Water (m3) | L1: Cooling Tower Blowdown (m3) | M1: EMDB-1 All Pumps (KWh) | N1: EMDB-2 Elevators (KWh) | O1: MDB-1 Chiller #1 (KWh) | P1: MDB-2 Chiller #2 (KWh) | Q1: MDB-3 Chiller #3(KWh) | R1: MDB-4 North Riser (KWh) | S1: MDB-5 North Riser (KWh) | T1: MDB-6 Main Kitchen (KWh) | U1: MDB-7 South Riser (KWh) | V1: MDB-8 F&B (KWh) | W1: Chiller 1 (Kwh cooling) | X1: Chiller 2 (Kwh cooling) | Y1: Chiller 3 (Kwh cooling) | Z1: Steam Boiler LPG (Kg) | AA1: Solar Hot Water Boiler LPG (Kg) | AB1: Low Temp Hot Water Boiler LPG (Kg) | AC1: Steam Boiler Steam (Kg) | AD1: Ird Kitchen (Kg) | AE1: Suq Kitchen (Kg) | AF1: Bakery Kitchen (Kg) | AG1: Shai Saloon Kitchen (kg) | AH1: Banquet Kitchen (Kg) | AI1: Sea Fu Kitchen (Kg) | AJ1: Jean George Cold Water (m³) | AK1: Jean George Hot Water (m³) | AL1: Coya Cold Water (m³) | AM1: Coya Hot Water (m³) | AN1: Nusrat Cold Water (m³) | AO1: Nusrat Hot Water (m³) | AP1: Provocateur Cold Water (m³) | AQ1: Provocateur Hot Water (m³) | AR1: Scalini Cold Water (m³) | AS1: Scalini Hot Water (m³) | AT1: F&B V Irrigation (m³) | AU1: MDB Coya (KWh) | AV1: MDB Jean Georges (KWh) | AW1: MDB Nusrat(KWh) | AX1: SMDB Provocateur (KWh) | AY1: SMDB Scalini (KWh) | AZ1: Common ESMDB (KWh) | BA1: Chilled Water Coya (Kwh) | BB1: Chilled Water Coya Cold Room (Kwh) | BC1: Chilled Water Jean Georges (Kwh) | BD1: Chilled Water Nusrat (Kwh) | BE1: Chilled Water Provocateur A (Kwh) | BF1: Chilled Water Provocateur B (Kwh) | BG1: Coya LPG (Kg) | BH1: Nusrat LPG (Kg) | BI1: Jean Georges LPG (Kg) | BJ1: Provocateur LPG (Kg) | BK1: Scalini LPG (Kg) | BL1: TSE Irrigation (m3)
A2: Dubai at Jumeirah Beach | B2: 1 | C2: 12 | D2: 2022 | E2: =237*0.4 -> 94.8 | F2: =154+28 -> 182 | G2: ='DJB Daily Readings'!C10-'DJB Daily Readings'!C9 -> 732 | H2: ='DJB Daily Readings'!F10-'DJB Daily Readings'!F9 -> 427 | I2: ='DJB Daily Readings'!K10-'DJB Daily Readings'!K9 -> 277 | J2: ='DJB Daily Readings'!K10-'DJB Daily Readings'!K9 -> 277 | K2: ='DJB Daily Readings'!O10-'DJB Daily Readings'!O9 -> 131 | L2: ='DJB Daily Readings'!R10-'DJB Daily Readings'!R9 -> 18 | M2: ='DJB Daily Readings'!U10-'DJB Daily Readings'!U9 -> 2630.88 | N2: ='DJB Daily Readings'!X10-'DJB Daily Readings'!X9 -> 4579.68 | O2: ='DJB Daily Readings'!AA10-'DJB Daily Readings'!AA9 -> 0 | P2: ='DJB Daily Readings'!AD10-'DJB Daily Readings'!AD9 -> 48.72 | Q2: ='DJB Daily Readings'!AG10-'DJB Daily Readings'!AG9 -> 12959.52 | R2: ='DJB Daily Readings'!AJ10-'DJB Daily Readings'!AJ9 -> 5943.84 | S2: ='DJB Daily Readings'!AM10-'DJB Daily Readings'!AM9 -> 4384.8 | T2: ='DJB Daily Readings'!AP10-'DJB Daily Readings'!AP9 -> 4872 | U2: ='DJB Daily Readings'!AS10-'DJB Daily Readings'!AS9 -> 3118.08 | V2: ='DJB Daily Readings'!AV10-'DJB Daily Readings'!AV9 -> 5554.08 | W2: ='DJB Daily Readings'!AZ10-'DJB Daily Readings'!AZ9 -> 0 | X2: ='DJB Daily Readings'!BC10-'DJB Daily Readings'!BC9 -> 0 | Y2: ='DJB Daily Readings'!BF10-'DJB Daily Readings'!BF9 -> 65200 | Z2: =('DJB Daily Readings'!CK10-'DJB Daily Readings'!CK9)*1.89 -> 137.97 | AA2: =('DJB Daily Readings'!CN10-'DJB Daily Readings'!CN9)*1.89 -> 192.78 | AB2: =('DJB Daily Readings'!CQ10-'DJB Daily Readings'!CQ9)*1.89 -> 313.74 | AC2: ='DJB Daily Readings'!CT10-'DJB Daily Readings'!CT9 -> 168 | AD2: =('DJB Daily Readings'!BY10-'DJB Daily Readings'!BY9)*1.89 -> 39.69 | AE2: =('DJB Daily Readings'!CA10-'DJB Daily Readings'!CA9)*1.89 -> 37.8 | AF2: =('DJB Daily Readings'!CC10-'DJB Daily Readings'!CC9)*1.89 -> 13.23 | AG2: =('DJB Daily Readings'!CE10-'DJB Daily Readings'!CE9)*1.89 -> 18.9 | AH2: =('DJB Daily Readings'!CG10-'DJB Daily Readings'!CG9)*1.89 -> 34.02 | AI2: =('DJB Daily Readings'!CI10-'DJB Daily Readings'!CI9)*1.89 -> 64.26 | AJ2: ='DJB Daily Readings'!CY10-'DJB Daily Readings'!CY9 -> 5 | AK2: ='DJB Daily Readings'!CW10-'DJB Daily Readings'!CW9 -> 8 | AL2: ='DJB Daily Readings'!DC10-'DJB Daily Readings'!DC9 -> 15 | AM2: ='DJB Daily Readings'!DA10-'DJB Daily Readings'!DA9 -> 16 | AN2: ='DJB Daily Readings'!DG10-'DJB Daily Readings'!DG9 -> 6 | AO2: ='DJB Daily Readings'!DE10-'DJB Daily Readings'!DE9 -> 10 | AP2: ='DJB Daily Readings'!DK10-'DJB Daily Readings'!DK9 -> 8 | AQ2: ='DJB Daily Readings'!DI10-'DJB Daily Readings'!DI9 -> 9 | AR2: ='DJB Daily Readings'!DO10-'DJB Daily Readings'!DO9 -> 9 | AS2: ='DJB Daily Readings'!DM10-'DJB Daily Readings'!DM9 -> 4 | AT2: ='DJB Daily Readings'!DQ10-'DJB Daily Readings'!DQ9 -> 10 | AU2: ='DJB Daily Readings'!DT10-'DJB Daily Readings'!DT9 -> 12 | AW2: ='DJB Daily Readings'!DX10-'DJB Daily Readings'!DX9 -> 6.8 | AX2: ='DJB Daily Readings'!DZ10-'DJB Daily Readings'!DZ9 -> 6.8 | AY2: ='DJB Daily Readings'!EB10-'DJB Daily Readings'!EB9 -> 608 | AZ2: ='DJB Daily Readings'!ED10-'DJB Daily Readings'!ED9 -> 154.9 | BA2: ='DJB Daily Readings'!EG10-'DJB Daily Readings'!EG9 -> 4400 | BB2: ='DJB Daily Readings'!EI10-'DJB Daily Readings'!EI9 -> 340 | BC2: ='DJB Daily Readings'!EQ10-'DJB Daily Readings'!EQ9 -> 5600 | BD2: ='DJB Daily Readings'!EK10-'DJB Daily Readings'!EK9 -> 2000 | BE2: ='DJB Daily Readings'!EM10-'DJB Daily Readings'!EM9 -> 400 | BF2: ='DJB Daily Readings'!EO10-'DJB Daily Readings'!EO9 -> 700 | BG2: =('DJB Daily Readings'!ET10-'DJB Daily Readings'!ET9)*1.89 -> 30.24 | BH2: =('DJB Daily Readings'!EV10-'DJB Daily Readings'!EV9)*1.89 -> 24.57 | BI2: =('DJB Daily Readings'!EZ10-'DJB Daily Readings'!EZ9)*1.89 -> 28.35 | BJ2: =('DJB Daily Readings'!EX10-'DJB Daily Readings'!EX9)*1.89 -> 15.12 | BK2: =('DJB Daily Readings'!FB10-'DJB Daily Readings'!FB9)*1.89 -> 68.04 | BL2: ='DJB Daily Readings'!J9 -> 164
A3: Dubai at Jumeirah Beach | B3: =B2+1 -> 2 | C3: 12 | D3: 2022 | E3: =237*0.33 -> 78.21 | F3: =136+18 -> 154 | G3: ='DJB Daily Readings'!C11-'DJB Daily Readings'!C10 -> 673 | H3: ='DJB Daily Readings'!F11-'DJB Daily Readings'!F10 -> 428 | I3: ='DJB Daily Readings'!K11-'DJB Daily Readings'!K10 -> 262 | J3: ='DJB Daily Readings'!K11-'DJB Daily Readings'!K10 -> 262 | K3: ='DJB Daily Readings'!O11-'DJB Daily Readings'!O10 -> 122 | L3: ='DJB Daily Readings'!R11-'DJB Daily Readings'!R10 -> 11 | M3: ='DJB Daily Readings'!U11-'DJB Daily Readings'!U10 -> 2728.32 | N3: ='DJB Daily Readings'!X11-'DJB Daily Readings'!X10 -> 4628.4 | O3: ='DJB Daily Readings'!AA11-'DJB Daily Readings'!AA10 -> 48.72 | P3: ='DJB Daily Readings'!AD11-'DJB Daily Readings'!AD10 -> 389.76 | Q3: ='DJB Daily Readings'!AG11-'DJB Daily Readings'!AG10 -> 12813.36 | R3: ='DJB Daily Readings'!AJ11-'DJB Daily Readings'!AJ10 -> 5700.24 | S3: ='DJB Daily Readings'!AM11-'DJB Daily Readings'!AM10 -> 4043.76 | T3: ='DJB Daily Readings'!AP11-'DJB Daily Readings'!AP10 -> 4677.12 | U3: ='DJB Daily Readings'!AS11-'DJB Daily Readings'!AS10 -> 3020.64 | V3: ='DJB Daily Readings'!AV11-'DJB Daily Readings'!AV10 -> 5895.12 | W3: ='DJB Daily Readings'!AZ11-'DJB Daily Readings'!AZ10 -> 0 | X3: ='DJB Daily Readings'!BC11-'DJB Daily Readings'!BC10 -> 0 | Y3: ='DJB Daily Readings'!BF11-'DJB Daily Readings'!BF10 -> 64700 | Z3: =('DJB Daily Readings'!CK11-'DJB Daily Readings'!CK10)*1.89 -> 134.19 | AA3: =('DJB Daily Readings'!CN11-'DJB Daily Readings'!CN10)*1.89 -> 187.11 | AB3: =('DJB Daily Readings'!CQ11-'DJB Daily Readings'!CQ10)*1.89 -> 300.51 | AC3: ='DJB Daily Readings'!CT11-'DJB Daily Readings'!CT10 -> 165 | AD3: =('DJB Daily Readings'!BY11-'DJB Daily Readings'!BY10)*1.89 -> 35.91 | AE3: =('DJB Daily Readings'!CA11-'DJB Daily Readings'!CA10)*1.89 -> 35.91 | AF3: =('DJB Daily Readings'!CC11-'DJB Daily Readings'!CC10)*1.89 -> 11.34 | AG3: =('DJB Daily Readings'!CE11-'DJB Daily Readings'!CE10)*1.89 -> 18.9 | AH3: =('DJB Daily Readings'!CG11-'DJB Daily Readings'!CG10)*1.89 -> 26.46 | AI3: =('DJB Daily Readings'!CI11-'DJB Daily Readings'!CI10)*1.89 -> 60.48 | AJ3: ='DJB Daily Readings'!CY11-'DJB Daily Readings'!CY10 -> 5 | AK3: ='DJB Daily Readings'!CW11-'DJB Daily Readings'!CW10 -> 8 | AL3: ='DJB Daily Readings'!DC11-'DJB Daily Readings'!DC10 -> 12 | AM3: ='DJB Daily Readings'!DA11-'DJB Daily Readings'!DA10 -> 15 | AN3: ='DJB Daily Readings'!DG11-'DJB Daily Readings'!DG10 -> 4 | AO3: ='DJB Daily Readings'!DE11-'DJB Daily Readings'!DE10 -> 10 | AP3: ='DJB Daily Readings'!DK11-'DJB Daily Readings'!DK10 -> 8 | AQ3: ='DJB Daily Readings'!DI11-'DJB Daily Readings'!DI10 -> 9 | AR3: ='DJB Daily Readings'!DO11-'DJB Daily Readings'!DO10 -> 10 | AS3: ='DJB Daily Readings'!DM11-'DJB Daily Readings'!DM10 -> 4 | AT3: ='DJB Daily Readings'!DQ11-'DJB Daily Readings'!DQ10 -> 5 | AU3: ='DJB Daily Readings'!DT11-'DJB Daily Readings'!DT10 -> 10.9 | AW3: ='DJB Daily Readings'!DX11-'DJB Daily Readings'!DX10 -> 6.5 | AX3: ='DJB Daily Readings'!DZ11-'DJB Daily Readings'!DZ10 -> 6.9 | AY3: ='DJB Daily Readings'!EB11-'DJB Daily Readings'!EB10 -> 614 | AZ3: ='DJB Daily Readings'!ED11-'DJB Daily Readings'!ED10 -> 148.3 | BA3: ='DJB Daily Readings'!EG11-'DJB Daily Readings'!EG10 -> 4300 | BB3: ='DJB Daily Readings'!EI11-'DJB Daily Readings'!EI10 -> 290 | BC3: ='DJB Daily Readings'!EQ11-'DJB Daily Readings'!EQ10 -> 5100 | BD3: ='DJB Daily Readings'!EK11-'DJB Daily Readings'!EK10 -> 2100 | BE3: ='DJB Daily Readings'!EM11-'DJB Daily Readings'!EM10 -> 600 | BF3: ='DJB Daily Readings'!EO11-'DJB Daily Readings'!EO10 -> 750 | BG3: =('DJB Daily Readings'!ET11-'DJB Daily Readings'!ET10)*1.89 -> 30.24 | BH3: =('DJB Daily Readings'!EV11-'DJB Daily Readings'!EV10)*1.89 -> 20.79 | BI3: =('DJB Daily Readings'!EZ11-'DJB Daily Readings'!EZ10)*1.89 -> 34.02 | BJ3: =('DJB Daily Readings'!EX11-'DJB Daily Readings'!EX10)*1.89 -> 20.79 | BK3: =('DJB Daily Readings'!FB11-'DJB Daily Readings'!FB10)*1.89 -> 66.15 | BL3: ='DJB Daily Readings'!J11 -> 176
A4: Dubai at Jumeirah Beach | B4: =B3+1 -> 3 | C4: 12 | D4: 2022 | E4: =237*0.36 -> 85.32 | F4: =152+10 -> 162 | G4: ='DJB Daily Readings'!C12-'DJB Daily Readings'!C11 -> 724 | H4: ='DJB Daily Readings'!F12-'DJB Daily Readings'!F11 -> 431 | I4: ='DJB Daily Readings'!K12-'DJB Daily Readings'!K11 -> 250 | J4: ='DJB Daily Readings'!K12-'DJB Daily Readings'!K11 -> 250 | K4: ='DJB Daily Readings'!O12-'DJB Daily Readings'!O11 -> 122 | L4: ='DJB Daily Readings'!R12-'DJB Daily Readings'!R11 -> 12 | M4: ='DJB Daily Readings'!U12-'DJB Daily Readings'!U11 -> 2484.72 | N4: ='DJB Daily Readings'!X12-'DJB Daily Readings'!X11 -> 4287.36 | O4: ='DJB Daily Readings'!AA12-'DJB Daily Readings'!AA11 -> 1023.12 | P4: ='DJB Daily Readings'!AD12-'DJB Daily Readings'!AD11 -> 11546.64 | Q4: ='DJB Daily Readings'!AG12-'DJB Daily Readings'!AG11 -> 0 | R4: ='DJB Daily Readings'!AJ12-'DJB Daily Readings'!AJ11 -> 5359.2 | S4: ='DJB Daily Readings'!AM12-'DJB Daily Readings'!AM11 -> 3995.04 | T4: ='DJB Daily Readings'!AP12-'DJB Daily Readings'!AP11 -> 4384.8 | U4: ='DJB Daily Readings'!AS12-'DJB Daily Readings'!AS11 -> 3069.36 | V4: ='DJB Daily Readings'!AV12-'DJB Daily Readings'!AV11 -> 5700.24 | W4: ='DJB Daily Readings'!AZ12-'DJB Daily Readings'!AZ11 -> 0 | X4: ='DJB Daily Readings'!BC12-'DJB Daily Readings'!BC11 -> 64000 | Y4: ='DJB Daily Readings'!BF12-'DJB Daily Readings'!BF11 -> 2200 | Z4: =('DJB Daily Readings'!CK12-'DJB Daily Readings'!CK11)*1.89 -> 134.19 | AA4: =('DJB Daily Readings'!CN12-'DJB Daily Readings'!CN11)*1.89 -> 192.78 | AB4: =('DJB Daily Readings'!CQ12-'DJB Daily Readings'!CQ11)*1.89 -> 277.83 | AC4: ='DJB Daily Readings'!CT12-'DJB Daily Readings'!CT11 -> 165 | AD4: =('DJB Daily Readings'!BY12-'DJB Daily Readings'!BY11)*1.89 -> 34.02 | AE4: =('DJB Daily Readings'!CA12-'DJB Daily Readings'!CA11)*1.89 -> 35.91 | AF4: =('DJB Daily Readings'!CC12-'DJB Daily Readings'!CC11)*1.89 -> 13.23 | AG4: =('DJB Daily Readings'!CE12-'DJB Daily Readings'!CE11)*1.89 -> 20.79 | AH4: =('DJB Daily Readings'!CG12-'DJB Daily Readings'!CG11)*1.89 -> 26.46 | AI4: =('DJB Daily Readings'!CI12-'DJB Daily Readings'!CI11)*1.89 -> 68.04 | AJ4: ='DJB Daily Readings'!CY12-'DJB Daily Readings'!CY11 -> 5 | AK4: ='DJB Daily Readings'!CW12-'DJB Daily Readings'!CW11 -> 7 | AL4: ='DJB Daily Readings'!DC12-'DJB Daily Readings'!DC11 -> 10 | AM4: ='DJB Daily Readings'!DA12-'DJB Daily Readings'!DA11 -> 12 | AN4: ='DJB Daily Readings'!DG12-'DJB Daily Readings'!DG11 -> 6 | AO4: ='DJB Daily Readings'!DE12-'DJB Daily Readings'!DE11 -> 9 | AP4: ='DJB Daily Readings'!DK12-'DJB Daily Readings'!DK11 -> 7 | AQ4: ='DJB Daily Readings'!DI12-'DJB Daily Readings'!DI11 -> 9 | AR4: ='DJB Daily Readings'!DO12-'DJB Daily Readings'!DO11 -> 9 | AS4: ='DJB Daily Readings'!DM12-'DJB Daily Readings'!DM11 -> 3 | AT4: ='DJB Daily Readings'!DQ12-'DJB Daily Readings'!DQ11 -> 6 | AU4: ='DJB Daily Readings'!DT12-'DJB Daily Readings'!DT11 -> 11.9 | AW4: ='DJB Daily Readings'!DX12-'DJB Daily Readings'!DX11 -> 6.7 | AX4: ='DJB Daily Readings'!DZ12-'DJB Daily Readings'!DZ11 -> 8.1 | AY4: ='DJB Daily Readings'!EB12-'DJB Daily Readings'!EB11 -> 620 | AZ4: ='DJB Daily Readings'!ED12-'DJB Daily Readings'!ED11 -> 159 | BA4: ='DJB Daily Readings'!EG12-'DJB Daily Readings'!EG11 -> 5600 | BB4: ='DJB Daily Readings'!EI12-'DJB Daily Readings'!EI11 -> 270 | BC4: ='DJB Daily Readings'!EQ12-'DJB Daily Readings'!EQ11 -> 5800 | BD4: ='DJB Daily Readings'!EK12-'DJB Daily Readings'!EK11 -> 2500 | BE4: ='DJB Daily Readings'!EM12-'DJB Daily Readings'!EM11 -> 600 | BF4: ='DJB Daily Readings'!EO12-'DJB Daily Readings'!EO11 -> 800 | BG4: =('DJB Daily Readings'!ET12-'DJB Daily Readings'!ET11)*1.89 -> 32.13 | BH4: =('DJB Daily Readings'!EV12-'DJB Daily Readings'!EV11)*1.89 -> 26.46 | BI4: =('DJB Daily Readings'!EZ12-'DJB Daily Readings'!EZ11)*1.89 -> 28.35 | BJ4: =('DJB Daily Readings'!EX12-'DJB Daily Readings'!EX11)*1.89 -> 18.9 | BK4: =('DJB Daily Readings'!FB12-'DJB Daily Readings'!FB11)*1.89 -> 62.37 | BL4: ='DJB Daily Readings'!J12 -> 169
A5: Dubai at Jumeirah Beach | B5: =B4+1 -> 4 | C5: 12 | D5: 2022 | E5: =237*0.35 -> 82.95 | F5: =136+10 -> 146 | G5: ='DJB Daily Readings'!C13-'DJB Daily Readings'!C12 -> 664 | H5: ='DJB Daily Readings'!F13-'DJB Daily Readings'!F12 -> 411 | I5: ='DJB Daily Readings'!K13-'DJB Daily Readings'!K12 -> 248 | J5: ='DJB Daily Readings'!K13-'DJB Daily Readings'!K12 -> 248 | K5: ='DJB Daily Readings'!O13-'DJB Daily Readings'!O12 -> 116 | L5: ='DJB Daily Readings'!R13-'DJB Daily Readings'!R12 -> 10 | M5: ='DJB Daily Readings'!U13-'DJB Daily Readings'!U12 -> 2582.16 | N5: ='DJB Daily Readings'!X13-'DJB Daily Readings'!X12 -> 4482.24 | O5: ='DJB Daily Readings'!AA13-'DJB Daily Readings'!AA12 -> 925.68 | P5: ='DJB Daily Readings'!AD13-'DJB Daily Readings'!AD12 -> 11546.64 | Q5: ='DJB Daily Readings'!AG13-'DJB Daily Readings'!AG12 -> 0 | R5: ='DJB Daily Readings'!AJ13-'DJB Daily Readings'!AJ12 -> 5700.24 | S5: ='DJB Daily Readings'!AM13-'DJB Daily Readings'!AM12 -> 4141.2 | T5: ='DJB Daily Readings'!AP13-'DJB Daily Readings'!AP12 -> 4433.52 | U5: ='DJB Daily Readings'!AS13-'DJB Daily Readings'!AS12 -> 3069.36 | V5: ='DJB Daily Readings'!AV13-'DJB Daily Readings'!AV12 -> 5797.68 | W5: ='DJB Daily Readings'!AZ13-'DJB Daily Readings'!AZ12 -> 0 | X5: ='DJB Daily Readings'!BC13-'DJB Daily Readings'!BC12 -> 63600 | Y5: ='DJB Daily Readings'!BF13-'DJB Daily Readings'!BF12 -> 0 | Z5: =('DJB Daily Readings'!CK13-'DJB Daily Readings'!CK12)*1.89 -> 137.97 | AA5: =('DJB Daily Readings'!CN13-'DJB Daily Readings'!CN12)*1.89 -> 196.56 | AB5: =('DJB Daily Readings'!CQ13-'DJB Daily Readings'!CQ12)*1.89 -> 332.64 | AC5: ='DJB Daily Readings'!CT13-'DJB Daily Readings'!CT12 -> 170 | AD5: =('DJB Daily Readings'!BY13-'DJB Daily Readings'!BY12)*1.89 -> 35.91 | AE5: =('DJB Daily Readings'!CA13-'DJB Daily Readings'!CA12)*1.89 -> 37.8 | AF5: =('DJB Daily Readings'!CC13-'DJB Daily Readings'!CC12)*1.89 -> 9.45 | AG5: =('DJB Daily Readings'!CE13-'DJB Daily Readings'!CE12)*1.89 -> 17.01 | AH5: =('DJB Daily Readings'!CG13-'DJB Daily Readings'!CG12)*1.89 -> 24.57 | AI5: =('DJB Daily Readings'!CI13-'DJB Daily Readings'!CI12)*1.89 -> 69.93 | AJ5: ='DJB Daily Readings'!CY13-'DJB Daily Readings'!CY12 -> 4 | AK5: ='DJB Daily Readings'!CW13-'DJB Daily Readings'!CW12 -> 8 | AL5: ='DJB Daily Readings'!DC13-'DJB Daily Readings'!DC12 -> 16 | AM5: ='DJB Daily Readings'!DA13-'DJB Daily Readings'!DA12 -> 22 | AN5: ='DJB Daily Readings'!DG13-'DJB Daily Readings'!DG12 -> 9 | AO5: ='DJB Daily Readings'!DE13-'DJB Daily Readings'!DE12 -> 12 | AP5: ='DJB Daily Readings'!DK13-'DJB Daily Readings'!DK12 -> 14 | AQ5: ='DJB Daily Readings'!DI13-'DJB Daily Readings'!DI12 -> 16 | AR5: ='DJB Daily Readings'!DO13-'DJB Daily Readings'!DO12 -> 8 | AS5: ='DJB Daily Readings'!DM13-'DJB Daily Readings'!DM12 -> 5 | AT5: ='DJB Daily Readings'!DQ13-'DJB Daily Readings'!DQ12 -> 5 | AU5: ='DJB Daily Readings'!DT13-'DJB Daily Readings'!DT12 -> 10.6 | AW5: ='DJB Daily Readings'!DX13-'DJB Daily Readings'!DX12 -> 6.5 | AX5: ='DJB Daily Readings'!DZ13-'DJB Daily Readings'!DZ12 -> 7.4 | AY5: ='DJB Daily Readings'!EB13-'DJB Daily Readings'!EB12 -> 550 | AZ5: ='DJB Daily Readings'!ED13-'DJB Daily Readings'!ED12 -> 148.3 | BA5: ='DJB Daily Readings'!EG13-'DJB Daily Readings'!EG12 -> 4700 | BB5: ='DJB Daily Readings'!EI13-'DJB Daily Readings'!EI12 -> 280 | BC5: ='DJB Daily Readings'!EQ13-'DJB Daily Readings'!EQ12 -> 4700 | BD5: ='DJB Daily Readings'!EK13-'DJB Daily Readings'!EK12 -> 2200 | BE5: ='DJB Daily Readings'!EM13-'DJB Daily Readings'!EM12 -> 600 | BF5: ='DJB Daily Readings'!EO13-'DJB Daily Readings'!EO12 -> 750 | BG5: =('DJB Daily Readings'!ET13-'DJB Daily Readings'!ET12)*1.89 -> 30.24 | BH5: =('DJB Daily Readings'!EV13-'DJB Daily Readings'!EV12)*1.89 -> 20.79 | BI5: =('DJB Daily Readings'!EZ13-'DJB Daily Readings'!EZ12)*1.89 -> 24.57 | BJ5: =('DJB Daily Readings'!EX13-'DJB Daily Readings'!EX12)*1.89 -> 18.9 | BK5: =('DJB Daily Readings'!FB13-'DJB Daily Readings'!FB12)*1.89 -> 51.03 | BL5: ='DJB Daily Readings'!J13 -> 162
A6: Dubai at Jumeirah Beach | B6: =B5+1 -> 5 | C6: 12 | D6: 2022 | E6: =237*0.41 -> 97.17 | F6: =157+9 -> 166 | G6: ='DJB Daily Readings'!C14-'DJB Daily Readings'!C13 -> 669 | H6: ='DJB Daily Readings'!F14-'DJB Daily Readings'!F13 -> 352 | I6: ='DJB Daily Readings'!K14-'DJB Daily Readings'!K13 -> 271 | J6: ='DJB Daily Readings'!K14-'DJB Daily Readings'!K13 -> 271 | K6: ='DJB Daily Readings'!O14-'DJB Daily Readings'!O13 -> 120 | L6: ='DJB Daily Readings'!R14-'DJB Daily Readings'!R13 -> 18 | M6: ='DJB Daily Readings'!U14-'DJB Daily Readings'!U13 -> 2484.72 | N6: ='DJB Daily Readings'!X14-'DJB Daily Readings'!X13 -> 4628.4 | O6: ='DJB Daily Readings'!AA14-'DJB Daily Readings'!AA13 -> 876.96 | P6: ='DJB Daily Readings'!AD14-'DJB Daily Readings'!AD13 -> 11205.6 | Q6: ='DJB Daily Readings'!AG14-'DJB Daily Readings'!AG13 -> 0 | R6: ='DJB Daily Readings'!AJ14-'DJB Daily Readings'!AJ13 -> 5700.24 | S6: ='DJB Daily Readings'!AM14-'DJB Daily Readings'!AM13 -> 4189.92 | T6: ='DJB Daily Readings'!AP14-'DJB Daily Readings'!AP13 -> 4336.08 | U6: ='DJB Daily Readings'!AS14-'DJB Daily Readings'!AS13 -> 3020.64 | V6: ='DJB Daily Readings'!AV14-'DJB Daily Readings'!AV13 -> 5700.24 | W6: ='DJB Daily Readings'!AZ14-'DJB Daily Readings'!AZ13 -> 0 | X6: ='DJB Daily Readings'!BC14-'DJB Daily Readings'!BC13 -> 62700 | Y6: ='DJB Daily Readings'!BF14-'DJB Daily Readings'!BF13 -> 0 | Z6: =('DJB Daily Readings'!CK14-'DJB Daily Readings'!CK13)*1.89 -> 134.19 | AA6: =('DJB Daily Readings'!CN14-'DJB Daily Readings'!CN13)*1.89 -> 187.11 | AB6: =('DJB Daily Readings'!CQ14-'DJB Daily Readings'!CQ13)*1.89 -> 315.63 | AC6: ='DJB Daily Readings'!CT14-'DJB Daily Readings'!CT13 -> 164 | AD6: =('DJB Daily Readings'!BY14-'DJB Daily Readings'!BY13)*1.89 -> 34.02 | AE6: =('DJB Daily Readings'!CA14-'DJB Daily Readings'!CA13)*1.89 -> 35.91 | AF6: =('DJB Daily Readings'!CC14-'DJB Daily Readings'!CC13)*1.89 -> 13.23 | AG6: =('DJB Daily Readings'!CE14-'DJB Daily Readings'!CE13)*1.89 -> 20.79 | AH6: =('DJB Daily Readings'!CG14-'DJB Daily Readings'!CG13)*1.89 -> 24.57 | AI6: =('DJB Daily Readings'!CI14-'DJB Daily Readings'!CI13)*1.89 -> 62.37 | AJ6: ='DJB Daily Readings'!CY14-'DJB Daily Readings'!CY13 -> 5 | AK6: ='DJB Daily Readings'!CW14-'DJB Daily Readings'!CW13 -> 5 | AL6: ='DJB Daily Readings'!DC14-'DJB Daily Readings'!DC13 -> 12 | AM6: ='DJB Daily Readings'!DA14-'DJB Daily Readings'!DA13 -> 13 | AN6: ='DJB Daily Readings'!DG14-'DJB Daily Readings'!DG13 -> 6 | AO6: ='DJB Daily Readings'!DE14-'DJB Daily Readings'!DE13 -> 10 | AP6: ='DJB Daily Readings'!DK14-'DJB Daily Readings'!DK13 -> 8 | AQ6: ='DJB Daily Readings'!DI14-'DJB Daily Readings'!DI13 -> 9 | AR6: ='DJB Daily Readings'!DO14-'DJB Daily Readings'!DO13 -> 7 | AS6: ='DJB Daily Readings'!DM14-'DJB Daily Readings'!DM13 -> 3 | AT6: ='DJB Daily Readings'!DQ14-'DJB Daily Readings'!DQ13 -> 6 | AU6: ='DJB Daily Readings'!DT14-'DJB Daily Readings'!DT13 -> 10.7 | AW6: ='DJB Daily Readings'!DX14-'DJB Daily Readings'!DX13 -> 6.3 | AX6: ='DJB Daily Readings'!DZ14-'DJB Daily Readings'!DZ13 -> 6.6 | AY6: ='DJB Daily Readings'!EB14-'DJB Daily Readings'!EB13 -> 562 | AZ6: ='DJB Daily Readings'!ED14-'DJB Daily Readings'!ED13 -> 151.1 | BA6: ='DJB Daily Readings'!EG14-'DJB Daily Readings'!EG13 -> 4900 | BB6: ='DJB Daily Readings'!EI14-'DJB Daily Readings'!EI13 -> 280 | BC6: ='DJB Daily Readings'!EQ14-'DJB Daily Readings'!EQ13 -> 4500 | BD6: ='DJB Daily Readings'!EK14-'DJB Daily Readings'!EK13 -> 2300 | BE6: ='DJB Daily Readings'!EM14-'DJB Daily Readings'!EM13 -> 600 | BF6: ='DJB Daily Readings'!EO14-'DJB Daily Readings'!EO13 -> 750 | BG6: =('DJB Daily Readings'!ET14-'DJB Daily Readings'!ET13)*1.89 -> 30.24 | BH6: =('DJB Daily Readings'!EV14-'DJB Daily Readings'!EV13)*1.89 -> 20.79 | BI6: =('DJB Daily Readings'!EZ14-'DJB Daily Readings'!EZ13)*1.89 -> 22.68 | BJ6: =('DJB Daily Readings'!EX14-'DJB Daily Readings'!EX13)*1.89 -> 18.9 | BK6: =('DJB Daily Readings'!FB14-'DJB Daily Readings'!FB13)*1.89 -> 62.37 | BL6: ='DJB Daily Readings'!J14 -> 138
A7: Dubai at Jumeirah Beach | B7: =B6+1 -> 6 | C7: 12 | D7: 2022 | E7: =237*0.47 -> 111.39 | F7: =167+10 -> 177 | G7: ='DJB Daily Readings'!C15-'DJB Daily Readings'!C14 -> 677 | H7: ='DJB Daily Readings'!F15-'DJB Daily Readings'!F14 -> 400 | I7: ='DJB Daily Readings'!K15-'DJB Daily Readings'!K14 -> 260 | J7: ='DJB Daily Readings'!K15-'DJB Daily Readings'!K14 -> 260 | K7: ='DJB Daily Readings'!O15-'DJB Daily Readings'!O14 -> 116 | L7: ='DJB Daily Readings'!R15-'DJB Daily Readings'!R14 -> 8 | M7: ='DJB Daily Readings'!U15-'DJB Daily Readings'!U14 -> 2533.44 | N7: ='DJB Daily Readings'!X15-'DJB Daily Readings'!X14 -> 4530.96 | O7: ='DJB Daily Readings'!AA15-'DJB Daily Readings'!AA14 -> 876.96 | P7: ='DJB Daily Readings'!AD15-'DJB Daily Readings'!AD14 -> 10962 | Q7: ='DJB Daily Readings'!AG15-'DJB Daily Readings'!AG14 -> 0 | R7: ='DJB Daily Readings'!AJ15-'DJB Daily Readings'!AJ14 -> 5456.64 | S7: ='DJB Daily Readings'!AM15-'DJB Daily Readings'!AM14 -> 4141.2 | T7: ='DJB Daily Readings'!AP15-'DJB Daily Readings'!AP14 -> 4433.52 | U7: ='DJB Daily Readings'!AS15-'DJB Daily Readings'!AS14 -> 3312.96 | V7: ='DJB Daily Readings'!AV15-'DJB Daily Readings'!AV14 -> 5554.08 | W7: ='DJB Daily Readings'!AZ15-'DJB Daily Readings'!AZ14 -> 0 | X7: ='DJB Daily Readings'!BC15-'DJB Daily Readings'!BC14 -> 63700 | Y7: ='DJB Daily Readings'!BF15-'DJB Daily Readings'!BF14 -> 0 | Z7: =('DJB Daily Readings'!CK15-'DJB Daily Readings'!CK14)*1.89 -> 134.19 | AA7: =('DJB Daily Readings'!CN15-'DJB Daily Readings'!CN14)*1.89 -> 192.78 | AB7: =('DJB Daily Readings'!CQ15-'DJB Daily Readings'!CQ14)*1.89 -> 300.51 | AC7: ='DJB Daily Readings'!CT15-'DJB Daily Readings'!CT14 -> 165 | AD7: =('DJB Daily Readings'!BY15-'DJB Daily Readings'!BY14)*1.89 -> 35.91 | AE7: =('DJB Daily Readings'!CA15-'DJB Daily Readings'!CA14)*1.89 -> 34.02 | AF7: =('DJB Daily Readings'!CC15-'DJB Daily Readings'!CC14)*1.89 -> 13.23 | AG7: =('DJB Daily Readings'!CE15-'DJB Daily Readings'!CE14)*1.89 -> 20.79 | AH7: =('DJB Daily Readings'!CG15-'DJB Daily Readings'!CG14)*1.89 -> 34.02 | AI7: =('DJB Daily Readings'!CI15-'DJB Daily Readings'!CI14)*1.89 -> 54.81 | AJ7: ='DJB Daily Readings'!CY15-'DJB Daily Readings'!CY14 -> 2 | AK7: ='DJB Daily Readings'!CW15-'DJB Daily Readings'!CW14 -> 6 | AL7: ='DJB Daily Readings'!DC15-'DJB Daily Readings'!DC14 -> 14 | AM7: ='DJB Daily Readings'!DA15-'DJB Daily Readings'!DA14 -> 14 | AN7: ='DJB Daily Readings'!DG15-'DJB Daily Readings'!DG14 -> 5 | AO7: ='DJB Daily Readings'!DE15-'DJB Daily Readings'!DE14 -> 10 | AP7: ='DJB Daily Readings'!DK15-'DJB Daily Readings'!DK14 -> 8 | AQ7: ='DJB Daily Readings'!DI15-'DJB Daily Readings'!DI14 -> 9 | AR7: ='DJB Daily Readings'!DO15-'DJB Daily Readings'!DO14 -> 8 | AS7: ='DJB Daily Readings'!DM15-'DJB Daily Readings'!DM14 -> 3 | AT7: ='DJB Daily Readings'!DQ15-'DJB Daily Readings'!DQ14 -> 7 | AU7: ='DJB Daily Readings'!DT15-'DJB Daily Readings'!DT14 -> 10.9 | AW7: ='DJB Daily Readings'!DX15-'DJB Daily Readings'!DX14 -> 6.4 | AX7: ='DJB Daily Readings'!DZ15-'DJB Daily Readings'!DZ14 -> 6.4 | AY7: ='DJB Daily Readings'!EB15-'DJB Daily Readings'!EB14 -> 561 | AZ7: ='DJB Daily Readings'!ED15-'DJB Daily Readings'!ED14 -> 151.1 | BA7: ='DJB Daily Readings'!EG15-'DJB Daily Readings'!EG14 -> 4300 | BB7: ='DJB Daily Readings'!EI15-'DJB Daily Readings'!EI14 -> 270 | BC7: ='DJB Daily Readings'!EQ15-'DJB Daily Readings'!EQ14 -> 4300 | BD7: ='DJB Daily Readings'!EK15-'DJB Daily Readings'!EK14 -> 2200 | BE7: ='DJB Daily Readings'!EM15-'DJB Daily Readings'!EM14 -> 500 | BF7: ='DJB Daily Readings'!EO15-'DJB Daily Readings'!EO14 -> 720 | BG7: =('DJB Daily Readings'!ET15-'DJB Daily Readings'!ET14)*1.89 -> 30.24 | BH7: =('DJB Daily Readings'!EV15-'DJB Daily Readings'!EV14)*1.89 -> 18.9 | BI7: =('DJB Daily Readings'!EZ15-'DJB Daily Readings'!EZ14)*1.89 -> 18.9 | BJ7: =('DJB Daily Readings'!EX15-'DJB Daily Readings'!EX14)*1.89 -> 13.23 | BK7: =('DJB Daily Readings'!FB15-'DJB Daily Readings'!FB14)*1.89 -> 54.81 | BL7: ='DJB Daily Readings'!J15 -> 137
A8: Dubai at Jumeirah Beach | B8: =B7+1 -> 7 | C8: 12 | D8: 2022 | E8: =237*0.55 -> 130.35 | F8: =191+11 -> 202 | G8: ='DJB Daily Readings'!C16-'DJB Daily Readings'!C15 -> 671 | H8: ='DJB Daily Readings'!F16-'DJB Daily Readings'!F15 -> 394 | I8: ='DJB Daily Readings'!K16-'DJB Daily Readings'!K15 -> 251 | J8: ='DJB Daily Readings'!K16-'DJB Daily Readings'!K15 -> 251 | K8: ='DJB Daily Readings'!O16-'DJB Daily Readings'!O15 -> 111 | L8: ='DJB Daily Readings'!R16-'DJB Daily Readings'!R15 -> 13 | M8: ='DJB Daily Readings'!U16-'DJB Daily Readings'!U15 -> 2630.88 | N8: ='DJB Daily Readings'!X16-'DJB Daily Readings'!X15 -> 4530.96 | O8: ='DJB Daily Readings'!AA16-'DJB Daily Readings'!AA15 -> 876.96 | P8: ='DJB Daily Readings'!AD16-'DJB Daily Readings'!AD15 -> 10669.68 | Q8: ='DJB Daily Readings'!AG16-'DJB Daily Readings'!AG15 -> 0 | R8: ='DJB Daily Readings'!AJ16-'DJB Daily Readings'!AJ15 -> 5602.8 | S8: ='DJB Daily Readings'!AM16-'DJB Daily Readings'!AM15 -> 4384.8 | T8: ='DJB Daily Readings'!AP16-'DJB Daily Readings'!AP15 -> 4336.08 | U8: ='DJB Daily Readings'!AS16-'DJB Daily Readings'!AS15 -> 3264.24 | V8: ='DJB Daily Readings'!AV16-'DJB Daily Readings'!AV15 -> 5700.24 | W8: ='DJB Daily Readings'!AZ16-'DJB Daily Readings'!AZ15 -> 0 | X8: ='DJB Daily Readings'!BC16-'DJB Daily Readings'!BC15 -> 57700 | Y8: ='DJB Daily Readings'!BF16-'DJB Daily Readings'!BF15 -> 0 | Z8: =('DJB Daily Readings'!CK16-'DJB Daily Readings'!CK15)*1.89 -> 132.3 | AA8: =('DJB Daily Readings'!CN16-'DJB Daily Readings'!CN15)*1.89 -> 189 | AB8: =('DJB Daily Readings'!CQ16-'DJB Daily Readings'!CQ15)*1.89 -> 357.21 | AC8: ='DJB Daily Readings'!CT16-'DJB Daily Readings'!CT15 -> 164 | AD8: =('DJB Daily Readings'!BY16-'DJB Daily Readings'!BY15)*1.89 -> 37.8 | AE8: =('DJB Daily Readings'!CA16-'DJB Daily Readings'!CA15)*1.89 -> 35.91 | AF8: =('DJB Daily Readings'!CC16-'DJB Daily Readings'!CC15)*1.89 -> 13.23 | AG8: =('DJB Daily Readings'!CE16-'DJB Daily Readings'!CE15)*1.89 -> 17.01 | AH8: =('DJB Daily Readings'!CG16-'DJB Daily Readings'!CG15)*1.89 -> 26.46 | AI8: =('DJB Daily Readings'!CI16-'DJB Daily Readings'!CI15)*1.89 -> 60.48 | AJ8: ='DJB Daily Readings'!CY16-'DJB Daily Readings'!CY15 -> 7 | AK8: ='DJB Daily Readings'!CW16-'DJB Daily Readings'!CW15 -> 9 | AL8: ='DJB Daily Readings'!DC16-'DJB Daily Readings'!DC15 -> 12 | AM8: ='DJB Daily Readings'!DA16-'DJB Daily Readings'!DA15 -> 15 | AN8: ='DJB Daily Readings'!DG16-'DJB Daily Readings'!DG15 -> 6 | AO8: ='DJB Daily Readings'!DE16-'DJB Daily Readings'!DE15 -> 10 | AP8: ='DJB Daily Readings'!DK16-'DJB Daily Readings'!DK15 -> 6 | AQ8: ='DJB Daily Readings'!DI16-'DJB Daily Readings'!DI15 -> 8 | AR8: ='DJB Daily Readings'!DO16-'DJB Daily Readings'!DO15 -> 8 | AS8: ='DJB Daily Readings'!DM16-'DJB Daily Readings'!DM15 -> 4 | AT8: ='DJB Daily Readings'!DQ16-'DJB Daily Readings'!DQ15 -> 6 | AU8: ='DJB Daily Readings'!DT16-'DJB Daily Readings'!DT15 -> 11.5 | AW8: ='DJB Daily Readings'!DX16-'DJB Daily Readings'!DX15 -> 6.5 | AX8: ='DJB Daily Readings'!DZ16-'DJB Daily Readings'!DZ15 -> 5.7 | AY8: ='DJB Daily Readings'!EB16-'DJB Daily Readings'!EB15 -> 540 | AZ8: ='DJB Daily Readings'!ED16-'DJB Daily Readings'!ED15 -> 153.3 | BA8: ='DJB Daily Readings'!EG16-'DJB Daily Readings'!EG15 -> 4100 | BB8: ='DJB Daily Readings'!EI16-'DJB Daily Readings'!EI15 -> 270 | BC8: ='DJB Daily Readings'!EQ16-'DJB Daily Readings'!EQ15 -> 4700 | BD8: ='DJB Daily Readings'!EK16-'DJB Daily Readings'!EK15 -> 2000 | BE8: ='DJB Daily Readings'!EM16-'DJB Daily Readings'!EM15 -> 300 | BF8: ='DJB Daily Readings'!EO16-'DJB Daily Readings'!EO15 -> 720 | BG8: =('DJB Daily Readings'!ET16-'DJB Daily Readings'!ET15)*1.89 -> 28.35 | BH8: =('DJB Daily Readings'!EV16-'DJB Daily Readings'!EV15)*1.89 -> 22.68 | BI8: =('DJB Daily Readings'!EZ16-'DJB Daily Readings'!EZ15)*1.89 -> 28.35 | BJ8: =('DJB Daily Readings'!EX16-'DJB Daily Readings'!EX15)*1.89 -> 15.12 | BK8: =('DJB Daily Readings'!FB16-'DJB Daily Readings'!FB15)*1.89 -> 60.48 | BL8: ='DJB Daily Readings'!J16 -> 133
A9: Dubai at Jumeirah Beach | B9: =B8+1 -> 8 | C9: 12 | D9: 2022 | E9: =237*0.61 -> 144.57 | F9: =209+18 -> 227 | G9: ='DJB Daily Readings'!C17-'DJB Daily Readings'!C16 -> 775 | H9: ='DJB Daily Readings'!F17-'DJB Daily Readings'!F16 -> 438 | I9: ='DJB Daily Readings'!K17-'DJB Daily Readings'!K16 -> 273 | J9: ='DJB Daily Readings'!K17-'DJB Daily Readings'!K16 -> 273 | K9: ='DJB Daily Readings'!O17-'DJB Daily Readings'!O16 -> 119 | L9: ='DJB Daily Readings'!R17-'DJB Daily Readings'!R16 -> 10 | M9: ='DJB Daily Readings'!U17-'DJB Daily Readings'!U16 -> 2923.2 | N9: ='DJB Daily Readings'!X17-'DJB Daily Readings'!X16 -> 4969.44 | O9: ='DJB Daily Readings'!AA17-'DJB Daily Readings'!AA16 -> 1266.72 | P9: ='DJB Daily Readings'!AD17-'DJB Daily Readings'!AD16 -> 12277.44 | Q9: ='DJB Daily Readings'!AG17-'DJB Daily Readings'!AG16 -> 292.32 | R9: ='DJB Daily Readings'!AJ17-'DJB Daily Readings'!AJ16 -> 6187.44 | S9: ='DJB Daily Readings'!AM17-'DJB Daily Readings'!AM16 -> 4774.56 | T9: ='DJB Daily Readings'!AP17-'DJB Daily Readings'!AP16 -> 4872 | U9: ='DJB Daily Readings'!AS17-'DJB Daily Readings'!AS16 -> 3605.28 | V9: ='DJB Daily Readings'!AV17-'DJB Daily Readings'!AV16 -> 6187.44 | W9: ='DJB Daily Readings'!AZ17-'DJB Daily Readings'!AZ16 -> 800 | X9: ='DJB Daily Readings'!BC17-'DJB Daily Readings'!BC16 -> 61900 | Y9: ='DJB Daily Readings'!BF17-'DJB Daily Readings'!BF16 -> 1300 | Z9: =('DJB Daily Readings'!CK17-'DJB Daily Readings'!CK16)*1.89 -> 143.64 | AA9: =('DJB Daily Readings'!CN17-'DJB Daily Readings'!CN16)*1.89 -> 209.79 | AB9: =('DJB Daily Readings'!CQ17-'DJB Daily Readings'!CQ16)*1.89 -> 372.33 | AC9: ='DJB Daily Readings'!CT17-'DJB Daily Readings'!CT16 -> 176 | AD9: =('DJB Daily Readings'!BY17-'DJB Daily Readings'!BY16)*1.89 -> 34.02 | AE9: =('DJB Daily Readings'!CA17-'DJB Daily Readings'!CA16)*1.89 -> 39.69 | AF9: =('DJB Daily Readings'!CC17-'DJB Daily Readings'!CC16)*1.89 -> 11.34 | AG9: =('DJB Daily Readings'!CE17-'DJB Daily Readings'!CE16)*1.89 -> 22.68 | AH9: =('DJB Daily Readings'!CG17-'DJB Daily Readings'!CG16)*1.89 -> 32.13 | AI9: =('DJB Daily Readings'!CI17-'DJB Daily Readings'!CI16)*1.89 -> 58.59 | AJ9: ='DJB Daily Readings'!CY17-'DJB Daily Readings'!CY16 -> 5 | AK9: ='DJB Daily Readings'!CW17-'DJB Daily Readings'!CW16 -> 9 | AL9: ='DJB Daily Readings'!DC17-'DJB Daily Readings'!DC16 -> 14 | AM9: ='DJB Daily Readings'!DA17-'DJB Daily Readings'!DA16 -> 11 | AN9: ='DJB Daily Readings'!DG17-'DJB Daily Readings'!DG16 -> 7 | AO9: ='DJB Daily Readings'!DE17-'DJB Daily Readings'!DE16 -> 12 | AP9: ='DJB Daily Readings'!DK17-'DJB Daily Readings'!DK16 -> 11 | AQ9: ='DJB Daily Readings'!DI17-'DJB Daily Readings'!DI16 -> 9 | AR9: ='DJB Daily Readings'!DO17-'DJB Daily Readings'!DO16 -> 9 | AS9: ='DJB Daily Readings'!DM17-'DJB Daily Readings'!DM16 -> 3 | AT9: ='DJB Daily Readings'!DQ17-'DJB Daily Readings'!DQ16 -> 10 | AU9: ='DJB Daily Readings'!DT17-'DJB Daily Readings'!DT16 -> 12 | AW9: ='DJB Daily Readings'!DX17-'DJB Daily Readings'!DX16 -> 7 | AX9: ='DJB Daily Readings'!DZ17-'DJB Daily Readings'!DZ16 -> 6.9 | AY9: ='DJB Daily Readings'!EB17-'DJB Daily Readings'!EB16 -> 571 | AZ9: ='DJB Daily Readings'!ED17-'DJB Daily Readings'!ED16 -> 164.2 | BA9: ='DJB Daily Readings'!EG17-'DJB Daily Readings'!EG16 -> 4500 | BB9: ='DJB Daily Readings'!EI17-'DJB Daily Readings'!EI16 -> 290 | BC9: ='DJB Daily Readings'!EQ17-'DJB Daily Readings'!EQ16 -> 5400 | BD9: ='DJB Daily Readings'!EK17-'DJB Daily Readings'!EK16 -> 2400 | BE9: ='DJB Daily Readings'!EM17-'DJB Daily Readings'!EM16 -> 400 | BF9: ='DJB Daily Readings'!EO17-'DJB Daily Readings'!EO16 -> 760 | BG9: =('DJB Daily Readings'!ET17-'DJB Daily Readings'!ET16)*1.89 -> 32.13 | BH9: =('DJB Daily Readings'!EV17-'DJB Daily Readings'!EV16)*1.89 -> 26.46 | BI9: =('DJB Daily Readings'!EZ17-'DJB Daily Readings'!EZ16)*1.89 -> 28.35 | BJ9: =('DJB Daily Readings'!EX17-'DJB Daily Readings'!EX16)*1.89 -> 17.01 | BK9: =('DJB Daily Readings'!FB17-'DJB Daily Readings'!FB16)*1.89 -> 73.71 | BL9: ='DJB Daily Readings'!J17 -> 149
A10: Dubai at Jumeirah Beach | B10: =B9+1 -> 9 | C10: 12 | D10: 2022 | E10: =237*0.64 -> 151.68 | F10: =219+21 -> 240 | G10: ='DJB Daily Readings'!C18-'DJB Daily Readings'!C17 -> 706 | H10: ='DJB Daily Readings'!F18-'DJB Daily Readings'!F17 -> 417 | I10: ='DJB Daily Readings'!K18-'DJB Daily Readings'!K17 -> 214 | J10: ='DJB Daily Readings'!K18-'DJB Daily Readings'!K17 -> 214 | K10: ='DJB Daily Readings'!O18-'DJB Daily Readings'!O17 -> 106 | L10: ='DJB Daily Readings'!R18-'DJB Daily Readings'!R17 -> 9 | M10: ='DJB Daily Readings'!U18-'DJB Daily Readings'!U17 -> 2387.28 | N10: ='DJB Daily Readings'!X18-'DJB Daily Readings'!X17 -> 4141.2 | O10: ='DJB Daily Readings'!AA18-'DJB Daily Readings'!AA17 -> 828.24 | P10: ='DJB Daily Readings'!AD18-'DJB Daily Readings'!AD17 -> 9061.92 | Q10: ='DJB Daily Readings'!AG18-'DJB Daily Readings'!AG17 -> 292.32 | R10: ='DJB Daily Readings'!AJ18-'DJB Daily Readings'!AJ17 -> 5359.2 | S10: ='DJB Daily Readings'!AM18-'DJB Daily Readings'!AM17 -> 3946.32 | T10: ='DJB Daily Readings'!AP18-'DJB Daily Readings'!AP17 -> 4141.2 | U10: ='DJB Daily Readings'!AS18-'DJB Daily Readings'!AS17 -> 2874.48 | V10: ='DJB Daily Readings'!AV18-'DJB Daily Readings'!AV17 -> 5505.36 | W10: ='DJB Daily Readings'!AZ18-'DJB Daily Readings'!AZ17 -> 0 | X10: ='DJB Daily Readings'!BC18-'DJB Daily Readings'!BC17 -> 55200 | Y10: ='DJB Daily Readings'!BF18-'DJB Daily Readings'!BF17 -> 0 | Z10: =('DJB Daily Readings'!CK18-'DJB Daily Readings'!CK17)*1.89 -> 124.74 | AA10: =('DJB Daily Readings'!CN18-'DJB Daily Readings'!CN17)*1.89 -> 177.66 | AB10: =('DJB Daily Readings'!CQ18-'DJB Daily Readings'!CQ17)*1.89 -> 413.91 | AC10: ='DJB Daily Readings'!CT18-'DJB Daily Readings'!CT17 -> 154 | AD10: =('DJB Daily Readings'!BY18-'DJB Daily Readings'!BY17)*1.89 -> 32.13 | AE10: =('DJB Daily Readings'!CA18-'DJB Daily Readings'!CA17)*1.89 -> 34.02 | AF10: =('DJB Daily Readings'!CC18-'DJB Daily Readings'!CC17)*1.89 -> 9.45 | AG10: =('DJB Daily Readings'!CE18-'DJB Daily Readings'!CE17)*1.89 -> 18.9 | AH10: =('DJB Daily Readings'!CG18-'DJB Daily Readings'!CG17)*1.89 -> 22.68 | AI10: =('DJB Daily Readings'!CI18-'DJB Daily Readings'!CI17)*1.89 -> 54.81 | AJ10: ='DJB Daily Readings'!CY18-'DJB Daily Readings'!CY17 -> 5 | AK10: ='DJB Daily Readings'!CW18-'DJB Daily Readings'!CW17 -> 8 | AL10: ='DJB Daily Readings'!DC18-'DJB Daily Readings'!DC17 -> 13 | AM10: ='DJB Daily Readings'!DA18-'DJB Daily Readings'!DA17 -> 15 | AN10: ='DJB Daily Readings'!DG18-'DJB Daily Readings'!DG17 -> 7 | AO10: ='DJB Daily Readings'!DE18-'DJB Daily Readings'!DE17 -> 9 | AP10: ='DJB Daily Readings'!DK18-'DJB Daily Readings'!DK17 -> 10 | AQ10: ='DJB Daily Readings'!DI18-'DJB Daily Readings'!DI17 -> 9 | AR10: ='DJB Daily Readings'!DO18-'DJB Daily Readings'!DO17 -> 9 | AS10: ='DJB Daily Readings'!DM18-'DJB Daily Readings'!DM17 -> 3 | AT10: ='DJB Daily Readings'!DQ18-'DJB Daily Readings'!DQ17 -> 0 | AU10: ='DJB Daily Readings'!DT18-'DJB Daily Readings'!DT17 -> 10.2 | AW10: ='DJB Daily Readings'!DX18-'DJB Daily Readings'!DX17 -> 5.9 | AX10: ='DJB Daily Readings'!DZ18-'DJB Daily Readings'!DZ17 -> 7.1 | AY10: ='DJB Daily Readings'!EB18-'DJB Daily Readings'!EB17 -> 545 | AZ10: ='DJB Daily Readings'!ED18-'DJB Daily Readings'!ED17 -> 119.2 | BA10: ='DJB Daily Readings'!EG18-'DJB Daily Readings'!EG17 -> 3600 | BB10: ='DJB Daily Readings'!EI18-'DJB Daily Readings'!EI17 -> 250 | BC10: ='DJB Daily Readings'!EQ18-'DJB Daily Readings'!EQ17 -> 3300 | BD10: ='DJB Daily Readings'!EK18-'DJB Daily Readings'!EK17 -> 1700 | BE10: ='DJB Daily Readings'!EM18-'DJB Daily Readings'!EM17 -> 300 | BF10: ='DJB Daily Readings'!EO18-'DJB Daily Readings'!EO17 -> 630 | BG10: =('DJB Daily Readings'!ET18-'DJB Daily Readings'!ET17)*1.89 -> 26.46 | BH10: =('DJB Daily Readings'!EV18-'DJB Daily Readings'!EV17)*1.89 -> 18.9 | BI10: =('DJB Daily Readings'!EZ18-'DJB Daily Readings'!EZ17)*1.89 -> 28.35 | BJ10: =('DJB Daily Readings'!EX18-'DJB Daily Readings'!EX17)*1.89 -> 20.79 | BK10: =('DJB Daily Readings'!FB18-'DJB Daily Readings'!FB17)*1.89 -> 62.37 | BL10: ='DJB Daily Readings'!J18 -> 122
A11: Dubai at Jumeirah Beach | B11: =B10+1 -> 10 | C11: 12 | D11: 2022 | E11: =237*0.64 -> 151.68 | F11: =232+24 -> 256 | G11: ='DJB Daily Readings'!C19-'DJB Daily Readings'!C18 -> 715 | H11: ='DJB Daily Readings'!F19-'DJB Daily Readings'!F18 -> 473 | I11: ='DJB Daily Readings'!K19-'DJB Daily Readings'!K18 -> 248 | J11: ='DJB Daily Readings'!K19-'DJB Daily Readings'!K18 -> 248 | K11: ='DJB Daily Readings'!O19-'DJB Daily Readings'!O18 -> 108 | L11: ='DJB Daily Readings'!R19-'DJB Daily Readings'!R18 -> 6 | M11: ='DJB Daily Readings'!U19-'DJB Daily Readings'!U18 -> 2046.24 | N11: ='DJB Daily Readings'!X19-'DJB Daily Readings'!X18 -> 4433.52 | O11: ='DJB Daily Readings'!AA19-'DJB Daily Readings'!AA18 -> 9646.56 | P11: ='DJB Daily Readings'!AD19-'DJB Daily Readings'!AD18 -> 974.4 | Q11: ='DJB Daily Readings'!AG19-'DJB Daily Readings'!AG18 -> 389.76 | R11: ='DJB Daily Readings'!AJ19-'DJB Daily Readings'!AJ18 -> 5651.52 | S11: ='DJB Daily Readings'!AM19-'DJB Daily Readings'!AM18 -> 4482.24 | T11: ='DJB Daily Readings'!AP19-'DJB Daily Readings'!AP18 -> 4872 | U11: ='DJB Daily Readings'!AS19-'DJB Daily Readings'!AS18 -> 2971.92 | V11: ='DJB Daily Readings'!AV19-'DJB Daily Readings'!AV18 -> 5943.84 | W11: ='DJB Daily Readings'!AZ19-'DJB Daily Readings'!AZ18 -> 51100 | X11: ='DJB Daily Readings'!BC19-'DJB Daily Readings'!BC18 -> 2100 | Y11: ='DJB Daily Readings'!BF19-'DJB Daily Readings'!BF18 -> 0 | Z11: =('DJB Daily Readings'!CK19-'DJB Daily Readings'!CK18)*1.89 -> 134.19 | AA11: =('DJB Daily Readings'!CN19-'DJB Daily Readings'!CN18)*1.89 -> 204.12 | AB11: =('DJB Daily Readings'!CQ19-'DJB Daily Readings'!CQ18)*1.89 -> 463.05 | AC11: ='DJB Daily Readings'!CT19-'DJB Daily Readings'!CT18 -> 167 | AD11: =('DJB Daily Readings'!BY19-'DJB Daily Readings'!BY18)*1.89 -> 35.91 | AE11: =('DJB Daily Readings'!CA19-'DJB Daily Readings'!CA18)*1.89 -> 34.02 | AF11: =('DJB Daily Readings'!CC19-'DJB Daily Readings'!CC18)*1.89 -> 11.34 | AG11: =('DJB Daily Readings'!CE19-'DJB Daily Readings'!CE18)*1.89 -> 18.9 | AH11: =('DJB Daily Readings'!CG19-'DJB Daily Readings'!CG18)*1.89 -> 28.35 | AI11: =('DJB Daily Readings'!CI19-'DJB Daily Readings'!CI18)*1.89 -> 60.48 | AJ11: ='DJB Daily Readings'!CY19-'DJB Daily Readings'!CY18 -> 5 | AK11: ='DJB Daily Readings'!CW19-'DJB Daily Readings'!CW18 -> 8 | AL11: ='DJB Daily Readings'!DC19-'DJB Daily Readings'!DC18 -> 9 | AM11: ='DJB Daily Readings'!DA19-'DJB Daily Readings'!DA18 -> 11 | AN11: ='DJB Daily Readings'!DG19-'DJB Daily Readings'!DG18 -> 7 | AO11: ='DJB Daily Readings'!DE19-'DJB Daily Readings'!DE18 -> 10 | AP11: ='DJB Daily Readings'!DK19-'DJB Daily Readings'!DK18 -> 10 | AQ11: ='DJB Daily Readings'!DI19-'DJB Daily Readings'!DI18 -> 9 | AR11: ='DJB Daily Readings'!DO19-'DJB Daily Readings'!DO18 -> 9 | AS11: ='DJB Daily Readings'!DM19-'DJB Daily Readings'!DM18 -> 3 | AT11: ='DJB Daily Readings'!DQ19-'DJB Daily Readings'!DQ18 -> 0 | AU11: ='DJB Daily Readings'!DT19-'DJB Daily Readings'!DT18 -> 11.7 | AW11: ='DJB Daily Readings'!DX19-'DJB Daily Readings'!DX18 -> 6.6 | AX11: ='DJB Daily Readings'!DZ19-'DJB Daily Readings'!DZ18 -> 7.5 | AY11: ='DJB Daily Readings'!EB19-'DJB Daily Readings'!EB18 -> 578 | AZ11: ='DJB Daily Readings'!ED19-'DJB Daily Readings'!ED18 -> 134.4 | BA11: ='DJB Daily Readings'!EG19-'DJB Daily Readings'!EG18 -> 2700 | BB11: ='DJB Daily Readings'!EI19-'DJB Daily Readings'!EI18 -> 270 | BC11: ='DJB Daily Readings'!EQ19-'DJB Daily Readings'!EQ18 -> 2700 | BD11: ='DJB Daily Readings'!EK19-'DJB Daily Readings'!EK18 -> 1500 | BE11: ='DJB Daily Readings'!EM19-'DJB Daily Readings'!EM18 -> 300 | BF11: ='DJB Daily Readings'!EO19-'DJB Daily Readings'!EO18 -> 700 | BG11: =('DJB Daily Readings'!ET19-'DJB Daily Readings'!ET18)*1.89 -> 30.24 | BH11: =('DJB Daily Readings'!EV19-'DJB Daily Readings'!EV18)*1.89 -> 20.79 | BI11: =('DJB Daily Readings'!EZ19-'DJB Daily Readings'!EZ18)*1.89 -> 28.35 | BJ11: =('DJB Daily Readings'!EX19-'DJB Daily Readings'!EX18)*1.89 -> 20.79 | BK11: =('DJB Daily Readings'!FB19-'DJB Daily Readings'!FB18)*1.89 -> 56.7 | BL11: ='DJB Daily Readings'!J19 -> 140
A12: Dubai at Jumeirah Beach | B12: =B11+1 -> 11 | C12: 12 | D12: 2022 | E12: =237*0.61 -> 144.57 | F12: =203+23 -> 226 | G12: ='DJB Daily Readings'!C20-'DJB Daily Readings'!C19 -> 694 | H12: ='DJB Daily Readings'!F20-'DJB Daily Readings'!F19 -> 442 | I12: ='DJB Daily Readings'!K20-'DJB Daily Readings'!K19 -> 255 | J12: ='DJB Daily Readings'!K20-'DJB Daily Readings'!K19 -> 255 | K12: ='DJB Daily Readings'!O20-'DJB Daily Readings'!O19 -> 88 | L12: ='DJB Daily Readings'!R20-'DJB Daily Readings'!R19 -> 4 | M12: ='DJB Daily Readings'!U20-'DJB Daily Readings'!U19 -> 1948.8 | N12: ='DJB Daily Readings'!X20-'DJB Daily Readings'!X19 -> 4628.4 | O12: ='DJB Daily Readings'!AA20-'DJB Daily Readings'!AA19 -> 9013.2 | P12: ='DJB Daily Readings'!AD20-'DJB Daily Readings'!AD19 -> 682.08 | Q12: ='DJB Daily Readings'!AG20-'DJB Daily Readings'!AG19 -> 584.64 | R12: ='DJB Daily Readings'!AJ20-'DJB Daily Readings'!AJ19 -> 5895.12 | S12: ='DJB Daily Readings'!AM20-'DJB Daily Readings'!AM19 -> 4384.8 | T12: ='DJB Daily Readings'!AP20-'DJB Daily Readings'!AP19 -> 4677.12 | U12: ='DJB Daily Readings'!AS20-'DJB Daily Readings'!AS19 -> 3361.68 | V12: ='DJB Daily Readings'!AV20-'DJB Daily Readings'!AV19 -> 5992.56 | W12: ='DJB Daily Readings'!AZ20-'DJB Daily Readings'!AZ19 -> 48100 | X12: ='DJB Daily Readings'!BC20-'DJB Daily Readings'!BC19 -> 0 | Y12: ='DJB Daily Readings'!BF20-'DJB Daily Readings'!BF19 -> 0 | Z12: =('DJB Daily Readings'!CK20-'DJB Daily Readings'!CK19)*1.89 -> 137.97 | AA12: =('DJB Daily Readings'!CN20-'DJB Daily Readings'!CN19)*1.89 -> 207.9 | AB12: =('DJB Daily Readings'!CQ20-'DJB Daily Readings'!CQ19)*1.89 -> 481.95 | AC12: ='DJB Daily Readings'!CT20-'DJB Daily Readings'!CT19 -> 172 | AD12: =('DJB Daily Readings'!BY20-'DJB Daily Readings'!BY19)*1.89 -> 37.8 | AE12: =('DJB Daily Readings'!CA20-'DJB Daily Readings'!CA19)*1.89 -> 35.91 | AF12: =('DJB Daily Readings'!CC20-'DJB Daily Readings'!CC19)*1.89 -> 13.23 | AG12: =('DJB Daily Readings'!CE20-'DJB Daily Readings'!CE19)*1.89 -> 20.79 | AH12: =('DJB Daily Readings'!CG20-'DJB Daily Readings'!CG19)*1.89 -> 26.46 | AI12: =('DJB Daily Readings'!CI20-'DJB Daily Readings'!CI19)*1.89 -> 69.93 | AJ12: ='DJB Daily Readings'!CY20-'DJB Daily Readings'!CY19 -> 3 | AK12: ='DJB Daily Readings'!CW20-'DJB Daily Readings'!CW19 -> 3 | AL12: ='DJB Daily Readings'!DC20-'DJB Daily Readings'!DC19 -> 15 | AM12: ='DJB Daily Readings'!DA20-'DJB Daily Readings'!DA19 -> 25 | AN12: ='DJB Daily Readings'!DG20-'DJB Daily Readings'!DG19 -> 5 | AO12: ='DJB Daily Readings'!DE20-'DJB Daily Readings'!DE19 -> 7 | AP12: ='DJB Daily Readings'!DK20-'DJB Daily Readings'!DK19 -> 10 | AQ12: ='DJB Daily Readings'!DI20-'DJB Daily Readings'!DI19 -> 14 | AR12: ='DJB Daily Readings'!DO20-'DJB Daily Readings'!DO19 -> 5 | AS12: ='DJB Daily Readings'!DM20-'DJB Daily Readings'!DM19 -> 6 | AT12: ='DJB Daily Readings'!DQ20-'DJB Daily Readings'!DQ19 -> 15 | AU12: ='DJB Daily Readings'!DT20-'DJB Daily Readings'!DT19 -> 11 | AW12: ='DJB Daily Readings'!DX20-'DJB Daily Readings'!DX19 -> 6.6 | AX12: ='DJB Daily Readings'!DZ20-'DJB Daily Readings'!DZ19 -> 7.4 | AY12: ='DJB Daily Readings'!EB20-'DJB Daily Readings'!EB19 -> 553 | AZ12: ='DJB Daily Readings'!ED20-'DJB Daily Readings'!ED19 -> 128.2 | BA12: ='DJB Daily Readings'!EG20-'DJB Daily Readings'!EG19 -> 3800 | BB12: ='DJB Daily Readings'!EI20-'DJB Daily Readings'!EI19 -> 230 | BC12: ='DJB Daily Readings'!EQ20-'DJB Daily Readings'!EQ19 -> 1700 | BD12: ='DJB Daily Readings'!EK20-'DJB Daily Readings'!EK19 -> 1900 | BE12: ='DJB Daily Readings'!EM20-'DJB Daily Readings'!EM19 -> 400 | BF12: ='DJB Daily Readings'!EO20-'DJB Daily Readings'!EO19 -> 630 | BG12: =('DJB Daily Readings'!ET20-'DJB Daily Readings'!ET19)*1.89 -> 28.35 | BH12: =('DJB Daily Readings'!EV20-'DJB Daily Readings'!EV19)*1.89 -> 18.9 | BI12: =('DJB Daily Readings'!EZ20-'DJB Daily Readings'!EZ19)*1.89 -> 20.79 | BJ12: =('DJB Daily Readings'!EX20-'DJB Daily Readings'!EX19)*1.89 -> 20.79 | BK12: =('DJB Daily Readings'!FB20-'DJB Daily Readings'!FB19)*1.89 -> 62.37 | BL12: ='DJB Daily Readings'!J20 -> 149
