Workbook

Sheet TOTAL
A1: Site Name | B1: Day | C1: Month | D1: Year | E1: Total Electricity Kwh | F1: Electricity Tariff ($/Kwh) | G1: LPG (Kg) | H1: LPG $/Kg | I1: Water Utility Supply (m3) m3 | J1: Water Utility Supply (m3) $/m3 | K1: Irrigation Water (m3) m3 | L1: Irrigation water $/m3 | M1: Room Nights
A2: Seychelles | B2: 1 | C2: 12 | D2: 2022 | E2: =SUM('FS Seychelles'!D3:M3)*1000 -> 27930 | F2: =(('FS Seychelles'!S3*'FS Seychelles'!T3)+('FS Seychelles'!U3*'FS Seychelles'!V3))/TOTAL!E2 -> 0.53069139 | G2: =('FS Seychelles'!$AF$10+'FS Seychelles'!$AF$15)/30 -> 168.7 | H2: 1.05 | I2: =SUM('FS Seychelles'!W3:AC3) -> 621 | J2: 5.36 | K2: ='FS Seychelles'!AG3 -> 103 | L2: 0 | M2: ='FS Seychelles'!B3 -> 55.8
A3: Seychelles | B3: =B2+1 -> 2 | C3: =C2 -> 12 | D3: 2022 | E3: =SUM('FS Seychelles'!D4:M4)*1000 -> 24660 | F3: =(('FS Seychelles'!S4*'FS Seychelles'!T4)+('FS Seychelles'!U4*'FS Seychelles'!V4))/TOTAL!E3 -> 0.54365998 | G3: =('FS Seychelles'!$AF$10+'FS Seychelles'!$AF$15)/30 -> 168.7 | H3: =H2 -> 1.05 | I3: =SUM('FS Seychelles'!W4:AC4) -> 479 | J3: =J2 -> 5.36 | K3: ='FS Seychelles'!AG4 -> 136 | L3: =L2 -> 0 | M3: ='FS Seychelles'!B4 -> 59.7
A4: Seychelles | B4: =B3+1 -> 3 | C4: =C3 -> 12 | D4: 2022 | E4: =SUM('FS Seychelles'!D5:M5)*1000 -> 26540 | F4: =(('FS Seychelles'!S5*'FS Seychelles'!T5)+('FS Seychelles'!U5*'FS Seychelles'!V5))/TOTAL!E4 -> 0.49908956 | G4: =('FS Seychelles'!$AF$10+'FS Seychelles'!$AF$15)/30 -> 168.7 | H4: =H3 -> 1.05 | I4: =SUM('FS Seychelles'!W5:AC5) -> 469 | J4: =J3 -> 5.36 | K4: ='FS Seychelles'!AG5 -> 109 | L4: =L3 -> 0 | M4: ='FS Seychelles'!B5 -> 57.1
A5: Seychelles | B5: =B4+1 -> 4 | C5: =C4 -> 12 | D5: 2022 | E5: =SUM('FS Seychelles'!D6:M6)*1000 -> 26320 | F5: =(('FS Seychelles'!S6*'FS Seychelles'!T6)+('FS Seychelles'!U6*'FS Seychelles'!V6))/TOTAL!E5 -> 0.55610375 | G5: =('FS Seychelles'!$AF$10+'FS Seychelles'!$AF$15)/30 -> 168.7 | H5: =H4 -> 1.05 | I5: =SUM('FS Seychelles'!W6:AC6) -> 538 | J5: =J4 -> 5.36 | K5: ='FS Seychelles'!AG6 -> 97 | L5: =L4 -> 0 | M5: ='FS Seychelles'!B6 -> 40.3
A6: Seychelles | B6: =B5+1 -> 5 | C6: =C5 -> 12 | D6: 2022 | E6: =SUM('FS Seychelles'!D7:M7)*1000 -> 26770 | F6: =(('FS Seychelles'!S7*'FS Seychelles'!T7)+('FS Seychelles'!U7*'FS Seychelles'!V7))/TOTAL!E6 -> 0.50153511 | G6: =('FS Seychelles'!$AF$10+'FS Seychelles'!$AF$15)/30 -> 168.7 | H6: =H5 -> 1.05 | I6: =SUM('FS Seychelles'!W7:AC7) -> 556 | J6: =J5 -> 5.36 | K6: ='FS Seychelles'!AG7 -> 58 | L6: =L5 -> 0 | M6: ='FS Seychelles'!B7 -> 39
A7: Seychelles | B7: =B6+1 -> 6 | C7: =C6 -> 12 | D7: 2022 | E7: =SUM('FS Seychelles'!D8:M8)*1000 -> 26480 | F7: =(('FS Seychelles'!S8*'FS Seychelles'!T8)+('FS Seychelles'!U8*'FS Seychelles'!V8))/TOTAL!E7 -> 0.56308807 | G7: =('FS Seychelles'!$AF$10+'FS Seychelles'!$AF$15)/30 -> 168.7 | H7: =H6 -> 1.05 | I7: =SUM('FS Seychelles'!W8:AC8) -> 533 | J7: =J6 -> 5.36 | K7: ='FS Seychelles'!AG8 -> 110 | L7: =L6 -> 0 | M7: ='FS Seychelles'!B8 -> 48.1
A8: Seychelles | B8: =B7+1 -> 7 | C8: =C7 -> 12 | D8: 2022 | E8: =SUM('FS Seychelles'!D9:M9)*1000 -> 26910 | F8: =(('FS Seychelles'!S9*'FS Seychelles'!T9)+('FS Seychelles'!U9*'FS Seychelles'!V9))/TOTAL!E8 -> 0.53786938 | G8: =('FS Seychelles'!$AF$10+'FS Seychelles'!$AF$15)/30 -> 168.7 | H8: =H7 -> 1.05 | I8: =SUM('FS Seychelles'!W9:AC9) -> 519 | J8: =J7 -> 5.36 | K8: ='FS Seychelles'!AG9 -> 121 | L8: =L7 -> 0 | M8: ='FS Seychelles'!B9 -> 48.1
A9: Seychelles | B9: =B8+1 -> 8 | C9: =C8 -> 12 | D9: 2022 | E9: =SUM('FS Seychelles'!D10:M10)*1000 -> 26540 | F9: =(('FS Seychelles'!S10*'FS Seychelles'!T10)+('FS Seychelles'!U10*'FS Seychelles'!V10))/TOTAL!E9 -> 0.63119936 | G9: =('FS Seychelles'!$AF$10+'FS Seychelles'!$AF$15)/30 -> 168.7 | H9: =H8 -> 1.05 | I9: =SUM('FS Seychelles'!W10:AC10) -> 608 | J9: =J8 -> 5.36 | K9: ='FS Seychelles'!AG10 -> 113 | L9: =L8 -> 0 | M9: ='FS Seychelles'!B10 -> 49.4
A10: Seychelles | B10: =B9+1 -> 9 | C10: =C9 -> 12 | D10: 2022 | E10: =SUM('FS Seychelles'!D11:M11)*1000 -> 26860 | F10: =(('FS Seychelles'!S11*'FS Seychelles'!T11)+('FS Seychelles'!U11*'FS Seychelles'!V11))/TOTAL!E10 -> 0.39978147 | G10: =('FS Seychelles'!$AF$10+'FS Seychelles'!$AF$15)/30 -> 168.7 | H10: =H9 -> 1.05 | I10: =SUM('FS Seychelles'!W11:AC11) -> 509 | J10: =J9 -> 5.36 | K10: ='FS Seychelles'!AG11 -> 138 | L10: =L9 -> 0 | M10: ='FS Seychelles'!B11 -> 49.4
A11: Seychelles | B11: =B10+1 -> 10 | C11: =C10 -> 12 | D11: 2022 | E11: =SUM('FS Seychelles'!D12:M12)*1000 -> 27770 | F11: =(('FS Seychelles'!S12*'FS Seychelles'!T12)+('FS Seychelles'!U12*'FS Seychelles'!V12))/TOTAL!E11 -> 0.52242141 | G11: =('FS Seychelles'!$AF$10+'FS Seychelles'!$AF$15)/30 -> 168.7 | H11: =H10 -> 1.05 | I11: =SUM('FS Seychelles'!W12:AC12) -> 539 | J11: =J10 -> 5.36 | K11: ='FS Seychelles'!AG12 -> 111 | L11: =L10 -> 0 | M11: ='FS Seychelles'!B12 -> 53.2
A12: Seychelles | B12: =B11+1 -> 11 | C12: =C11 -> 12 | D12: 2022 | E12: =SUM('FS Seychelles'!D13:M13)*1000 -> 27650 | F12: =(('FS Seychelles'!S13*'FS Seychelles'!T13)+('FS Seychelles'!U13*'FS Seychelles'!V13))/TOTAL!E12 -> 0.5149737 | G12: =('FS Seychelles'!$AF$10+'FS Seychelles'!$AF$15)/30 -> 168.7 | H12: =H11 -> 1.05 | I12: =SUM('FS Seychelles'!W13:AC13) -> 561 | J12: =J11 -> 5.36 | K12: ='FS Seychelles'!AG13 -> 73 | L12: =L11 -> 0 | M12: ='FS Seychelles'!B13 -> 49.4
A13: Seychelles | B13: =B12+1 -> 12 | C13: =C12 -> 12 | D13: 2022 | E13: =SUM('FS Seychelles'!D14:M14)*1000 -> 29350 | F13: =(('FS Seychelles'!S14*'FS Seychelles'!T14)+('FS Seychelles'!U14*'FS Seychelles'!V14))/TOTAL!E13 -> 0.51784094 | G13: =('FS Seychelles'!$AF$10+'FS Seychelles'!$AF$15)/30 -> 168.7 | H13: =H12 -> 1.05 | I13: =SUM('FS Seychelles'!W14:AC14) -> 605 | J13: =J12 -> 5.36 | K13: ='FS Seychelles'!AG14 -> 113 | L13: =L12 -> 0 | M13: ='FS Seychelles'!B14 -> 51.9
A14: Seychelles | B14: =B13+1 -> 13 | C14: =C13 -> 12 | D14: 2022 | E14: =SUM('FS Seychelles'!D15:M15)*1000 -> 27040 | F14: =(('FS Seychelles'!S15*'FS Seychelles'!T15)+('FS Seychelles'!U15*'FS Seychelles'!V15))/TOTAL!E14 -> 0.50842202 | G14: =('FS Seychelles'!$AF$10+'FS Seychelles'!$AF$15)/30 -> 168.7 | H14: =H13 -> 1.05 | I14: =SUM('FS Seychelles'!W15:AC15) -> 570 | J14: =J13 -> 5.36 | K14: ='FS Seychelles'!AG15 -> 96 | L14: =L13 -> 0 | M14: ='FS Seychelles'!B15 -> 51.9
... A32: Seychelles | B32: =B31+1 -> 31 | C32: =C31 -> 12 | D32: 2022 | E32: =SUM('FS Seychelles'!D33:M33)*1000 -> 26814.589 | F32: =(('FS Seychelles'!S33*'FS Seychelles'!T33)+('FS Seychelles'!U33*'FS Seychelles'!V33))/TOTAL!E32 -> 0.61880419 | G32: =('FS Seychelles'!$AF$10+'FS Seychelles'!$AF$15)/30 -> 168.7 | H32: =H31 -> 1.05 | I32: =SUM('FS Seychelles'!W33:AC33) -> 578.76008 | J32: =J31 -> 5.36 | K32: ='FS Seychelles'!AG33 -> 136.43333 | L32: =L31 -> 0 | M32: ='FS Seychelles'!B33 -> 79.2

Sheet Submetering 
A1: Site Name | B1: Day | C1: Month | D1: Year | E1: Room Night | F1: SS-A - KWh | G1: SS-B- KWh | H1: SS-C- KWh | I1: SS-D1- KWh | J1: SS-D2- KWh | K1: SS-E- KWh | L1: FIRE PUMP- KWh | M1: CASINO- KWh | N1: BOH- KWh | O1: PUC- KWh | P1: Generator#1 - KWh | Q1: Generator#2- KWh | R1: Generator#3- KWh | S1: Generator#4- KWh | T1: Generator#5- KWh | U1: DIESEL - Liter | V1: PUC - KWh | W1: BOH Water- m3 | X1: E-resort m3 | Y1: North RV m3 | Z1: WT59- m3 | AA1: WT08- m3 | AB1: PUC (E-Resort)- m3 | AC1: PUC (HOH)- m3 | AD1: LPG (Kg)
A2: Seychelles | B2: 1 | C2: 12 | D2: 2022 | E2: ='FS Seychelles'!B3 -> 55.8 | F2: ='FS Seychelles'!D3*1000 -> 3070 | G2: ='FS Seychelles'!E3*1000 -> 4400 | H2: ='FS Seychelles'!F3*1000 -> 5880 | I2: ='FS Seychelles'!G3*1000 -> 1750 | J2: ='FS Seychelles'!H3*1000 -> 2480 | K2: ='FS Seychelles'!I3*1000 -> 2930 | L2: ='FS Seychelles'!J3*1000 -> 1530 | M2: ='FS Seychelles'!K3*1000 -> 1880 | ... O2: ='FS Seychelles'!M3*1000 -> 0 | P2: ='FS Seychelles'!N3 -> 12787 | Q2: ='FS Seychelles'!O3 -> 10907 | R2: ='FS Seychelles'!P3 -> 5248 | S2: ='FS Seychelles'!Q3 -> 0 | T2: ='FS Seychelles'!R3 -> 7520 | U2: ='FS Seychelles'!S3 -> 7843 | V2: ='FS Seychelles'!U3 -> 522.71 | W2: ='FS Seychelles'!W3 -> 60 | X2: ='FS Seychelles'!X3 -> 24 | Y2: ='FS Seychelles'!Y3 -> 214 | Z2: ='FS Seychelles'!Z3 -> 152 | AA2: ='FS Seychelles'!AA3 -> 71 | AB2: ='FS Seychelles'!AB3 -> 0 | AC2: ='FS Seychelles'!AC3 -> 100 | AD2: =('FS Seychelles'!AF9+'FS Seychelles'!AF15)/30 -> 104.7
A3: Seychelles | B3: =B2+1 -> 2 | C3: =C2 -> 12 | D3: 2022 | E3: ='FS Seychelles'!B4 -> 59.7 | F3: ='FS Seychelles'!D4*1000 -> 2480 | G3: ='FS Seychelles'!E4*1000 -> 3870 | H3: ='FS Seychelles'!F4*1000 -> 5370 | I3: ='FS Seychelles'!G4*1000 -> 1420 | J3: ='FS Seychelles'!H4*1000 -> 2090 | K3: ='FS Seychelles'!I4*1000 -> 2450 | L3: ='FS Seychelles'!J4*1000 -> 1450 | M3: ='FS Seychelles'!K4*1000 -> 1710 | ... O3: ='FS Seychelles'!M4*1000 -> 0 | P3: ='FS Seychelles'!N4 -> 5363 | Q3: ='FS Seychelles'!O4 -> 10782 | R3: ='FS Seychelles'!P4 -> 5378 | S3: ='FS Seychelles'!Q4 -> 0 | T3: ='FS Seychelles'!R4 -> 10802 | U3: ='FS Seychelles'!S4 -> 7042 | V3: ='FS Seychelles'!U4 -> 522.71 | W3: ='FS Seychelles'!W4 -> 58 | X3: ='FS Seychelles'!X4 -> 14 | Y3: ='FS Seychelles'!Y4 -> 135 | Z3: ='FS Seychelles'!Z4 -> 97 | AA3: ='FS Seychelles'!AA4 -> 75 | AB3: ='FS Seychelles'!AB4 -> 0 | AC3: ='FS Seychelles'!AC4 -> 100 | AD3: =('FS Seychelles'!AF10+'FS Seychelles'!AF16)/30 -> 64
A4: Seychelles | B4: =B3+1 -> 3 | C4: =C3 -> 12 | D4: 2022 | E4: ='FS Seychelles'!B5 -> 57.1 | F4: ='FS Seychelles'!D5*1000 -> 2940 | G4: ='FS Seychelles'!E5*1000 -> 4320 | H4: ='FS Seychelles'!F5*1000 -> 5750 | I4: ='FS Seychelles'!G5*1000 -> 1540 | J4: ='FS Seychelles'!H5*1000 -> 2260 | K4: ='FS Seychelles'!I5*1000 -> 2680 | L4: ='FS Seychelles'!J5*1000 -> 1440 | M4: ='FS Seychelles'!K5*1000 -> 1770 | ... O4: ='FS Seychelles'!M5*1000 -> 0 | P4: ='FS Seychelles'!N5 -> 8388 | Q4: ='FS Seychelles'!O5 -> 6931 | R4: ='FS Seychelles'!P5 -> 11861 | S4: ='FS Seychelles'!Q5 -> 0 | T4: ='FS Seychelles'!R5 -> 5766 | U4: ='FS Seychelles'!S5 -> 6951 | V4: ='FS Seychelles'!U5 -> 522.71 | W4: ='FS Seychelles'!W5 -> 57 | X4: ='FS Seychelles'!X5 -> 31 | Y4: ='FS Seychelles'!Y5 -> 125 | Z4: ='FS Seychelles'!Z5 -> 67 | AA4: ='FS Seychelles'!AA5 -> 87 | AB4: ='FS Seychelles'!AB5 -> 0 | AC4: ='FS Seychelles'!AC5 -> 102 | AD4: =('FS Seychelles'!AF11+'FS Seychelles'!AF17)/30 -> 0
A5: Seychelles | B5: =B4+1 -> 4 | C5: =C4 -> 12 | D5: 2022 | E5: ='FS Seychelles'!B6 -> 40.3 | F5: ='FS Seychelles'!D6*1000 -> 3080 | G5: ='FS Seychelles'!E6*1000 -> 4450 | H5: ='FS Seychelles'!F6*1000 -> 5480 | I5: ='FS Seychelles'!G6*1000 -> 1660 | J5: ='FS Seychelles'!H6*1000 -> 2330 | K5: ='FS Seychelles'!I6*1000 -> 2770 | L5: ='FS Seychelles'!J6*1000 -> 1230 | M5: ='FS Seychelles'!K6*1000 -> 1690 | ... O5: ='FS Seychelles'!M6*1000 -> 0 | P5: ='FS Seychelles'!N6 -> 10905 | Q5: ='FS Seychelles'!O6 -> 8754 | R5: ='FS Seychelles'!P6 -> 7905 | S5: ='FS Seychelles'!Q6 -> 0 | T5: ='FS Seychelles'!R6 -> 8073 | U5: ='FS Seychelles'!S6 -> 7738 | V5: ='FS Seychelles'!U6 -> 522.71 | W5: ='FS Seychelles'!W6 -> 71 | X5: ='FS Seychelles'!X6 -> 22 | Y5: ='FS Seychelles'!Y6 -> 139 | Z5: ='FS Seychelles'!Z6 -> 145 | AA5: ='FS Seychelles'!AA6 -> 63 | AB5: ='FS Seychelles'!AB6 -> 0 | AC5: ='FS Seychelles'!AC6 -> 98 | AD5: =('FS Seychelles'!AF12+'FS Seychelles'!AF18)/30 -> 0
A6: Seychelles | B6: =B5+1 -> 5 | C6: =C5 -> 12 | D6: 2022 | E6: ='FS Seychelles'!B7 -> 39 | F6: ='FS Seychelles'!D7*1000 -> 3240 | G6: ='FS Seychelles'!E7*1000 -> 4320 | H6: ='FS Seychelles'!F7*1000 -> 5480 | I6: ='FS Seychelles'!G7*1000 -> 1900 | J6: ='FS Seychelles'!H7*1000 -> 2560 | K6: ='FS Seychelles'!I7*1000 -> 2620 | L6: ='FS Seychelles'!J7*1000 -> 1140 | M6: ='FS Seychelles'!K7*1000 -> 1740 | ... O6: ='FS Seychelles'!M7*1000 -> 0 | P6: ='FS Seychelles'!N7 -> 5104 | Q6: ='FS Seychelles'!O7 -> 15185 | R6: ='FS Seychelles'!P7 -> 8249 | S6: ='FS Seychelles'!Q7 -> 0 | T6: ='FS Seychelles'!R7 -> 4060 | U6: ='FS Seychelles'!S7 -> 7053 | V6: ='FS Seychelles'!U7 -> 522.71 | W6: ='FS Seychelles'!W7 -> 60 | X6: ='FS Seychelles'!X7 -> 28 | Y6: ='FS Seychelles'!Y7 -> 141 | Z6: ='FS Seychelles'!Z7 -> 155 | AA6: ='FS Seychelles'!AA7 -> 71 | AB6: ='FS Seychelles'!AB7 -> 0 | AC6: ='FS Seychelles'!AC7 -> 101 | AD6: =('FS Seychelles'!AF13+'FS Seychelles'!AF19)/30 -> 0
A7: Seychelles | B7: =B6+1 -> 6 | C7: =C6 -> 12 | D7: 2022 | E7: ='FS Seychelles'!B8 -> 48.1 | F7: ='FS Seychelles'!D8*1000 -> 3230 | G7: ='FS Seychelles'!E8*1000 -> 4060 | H7: ='FS Seychelles'!F8*1000 -> 5610 | I7: ='FS Seychelles'!G8*1000 -> 2010 | J7: ='FS Seychelles'!H8*1000 -> 2480 | K7: ='FS Seychelles'!I8*1000 -> 2370 | L7: ='FS Seychelles'!J8*1000 -> 1200 | M7: ='FS Seychelles'!K8*1000 -> 1710 | ... O7: ='FS Seychelles'!M8*1000 -> 0 | P7: ='FS Seychelles'!N8 -> 5958 | Q7: ='FS Seychelles'!O8 -> 7287 | R7: ='FS Seychelles'!P8 -> 13165 | S7: ='FS Seychelles'!Q8 -> 0 | T7: ='FS Seychelles'!R8 -> 10663 | U7: ='FS Seychelles'!S8 -> 7893 | V7: ='FS Seychelles'!U8 -> 522.71 | W7: ='FS Seychelles'!W8 -> 62 | X7: ='FS Seychelles'!X8 -> 34 | Y7: ='FS Seychelles'!Y8 -> 164 | Z7: ='FS Seychelles'!Z8 -> 101 | AA7: ='FS Seychelles'!AA8 -> 69 | AB7: ='FS Seychelles'!AB8 -> 0 | AC7: ='FS Seychelles'!AC8 -> 103 | AD7: =('FS Seychelles'!AF14+'FS Seychelles'!AF20)/30 -> 0
A8: Seychelles | B8: =B7+1 -> 7 | C8: =C7 -> 12 | D8: 2022 | E8: ='FS Seychelles'!B9 -> 48.1 | F8: ='FS Seychelles'!D9*1000 -> 3200 | G8: ='FS Seychelles'!E9*1000 -> 4420 | H8: ='FS Seychelles'!F9*1000 -> 5680 | I8: ='FS Seychelles'!G9*1000 -> 2300 | J8: ='FS Seychelles'!H9*1000 -> 2460 | K8: ='FS Seychelles'!I9*1000 -> 2290 | L8: ='FS Seychelles'!J9*1000 -> 1120 | M8: ='FS Seychelles'!K9*1000 -> 1740 | ... O8: ='FS Seychelles'!M9*1000 -> 0 | P8: ='FS Seychelles'!N9 -> 6875 | Q8: ='FS Seychelles'!O9 -> 8665 | R8: ='FS Seychelles'!P9 -> 15453 | S8: ='FS Seychelles'!Q9 -> 0 | T8: ='FS Seychelles'!R9 -> 4705 | U8: ='FS Seychelles'!S9 -> 7646 | V8: ='FS Seychelles'!U9 -> 522.71 | W8: ='FS Seychelles'!W9 -> 63 | X8: ='FS Seychelles'!X9 -> 21 | Y8: ='FS Seychelles'!Y9 -> 166 | Z8: ='FS Seychelles'!Z9 -> 93 | AA8: ='FS Seychelles'!AA9 -> 73 | AB8: ='FS Seychelles'!AB9 -> 0 | AC8: ='FS Seychelles'!AC9 -> 103 | AD8: =('FS Seychelles'!AF15+'FS Seychelles'!AF21)/30 -> 104.7
A9: Seychelles | B9: =B8+1 -> 8 | C9: =C8 -> 12 | D9: 2022 | E9: ='FS Seychelles'!B10 -> 49.4 | F9: ='FS Seychelles'!D10*1000 -> 2870 | G9: ='FS Seychelles'!E10*1000 -> 4400 | H9: ='FS Seychelles'!F10*1000 -> 5640 | I9: ='FS Seychelles'!G10*1000 -> 2000 | J9: ='FS Seychelles'!H10*1000 -> 2250 | K9: ='FS Seychelles'!I10*1000 -> 2260 | L9: ='FS Seychelles'!J10*1000 -> 1360 | M9: ='FS Seychelles'!K10*1000 -> 1790 | ... O9: ='FS Seychelles'!M10*1000 -> 0 | P9: ='FS Seychelles'!N10 -> 12242 | Q9: ='FS Seychelles'!O10 -> 9846 | R9: ='FS Seychelles'!P10 -> 11840 | S9: ='FS Seychelles'!Q10 -> 0 | T9: ='FS Seychelles'!R10 -> 9202 | U9: ='FS Seychelles'!S10 -> 8935 | V9: ='FS Seychelles'!U10 -> 522.71 | W9: ='FS Seychelles'!W10 -> 61 | X9: ='FS Seychelles'!X10 -> 23 | Y9: ='FS Seychelles'!Y10 -> 166 | Z9: ='FS Seychelles'!Z10 -> 167 | AA9: ='FS Seychelles'!AA10 -> 84 | AB9: ='FS Seychelles'!AB10 -> 0 | AC9: ='FS Seychelles'!AC10 -> 107 | AD9: =('FS Seychelles'!AF16+'FS Seychelles'!AF22)/30 -> 0
A10: Seychelles | B10: =B9+1 -> 9 | C10: =C9 -> 12 | D10: 2022 | E10: ='FS Seychelles'!B11 -> 49.4 | F10: ='FS Seychelles'!D11*1000 -> 2950 | G10: ='FS Seychelles'!E11*1000 -> 4190 | H10: ='FS Seychelles'!F11*1000 -> 5860 | I10: ='FS Seychelles'!G11*1000 -> 2190 | J10: ='FS Seychelles'!H11*1000 -> 2310 | K10: ='FS Seychelles'!I11*1000 -> 2440 | L10: ='FS Seychelles'!J11*1000 -> 1370 | M10: ='FS Seychelles'!K11*1000 -> 1680 | ... O10: ='FS Seychelles'!M11*1000 -> 0 | P10: ='FS Seychelles'!N11 -> 12070 | Q10: ='FS Seychelles'!O11 -> 7118 | R10: ='FS Seychelles'!P11 -> 7111 | S10: ='FS Seychelles'!Q11 -> 0 | T10: ='FS Seychelles'!R11 -> 0 | U10: ='FS Seychelles'!S11 -> 5532 | V10: ='FS Seychelles'!U11 -> 522.71 | W10: ='FS Seychelles'!W11 -> 65 | X10: ='FS Seychelles'!X11 -> 37 | Y10: ='FS Seychelles'!Y11 -> 130 | Z10: ='FS Seychelles'!Z11 -> 143 | AA10: ='FS Seychelles'!AA11 -> 61 | AB10: ='FS Seychelles'!AB11 -> 0 | AC10: ='FS Seychelles'!AC11 -> 73 | AD10: =('FS Seychelles'!AF17+'FS Seychelles'!AF23)/30 -> 0
A11: Seychelles | B11: =B10+1 -> 10 | C11: =C10 -> 12 | D11: 2022 | E11: ='FS Seychelles'!B12 -> 53.2 | F11: ='FS Seychelles'!D12*1000 -> 3020 | G11: ='FS Seychelles'!E12*1000 -> 4260 | H11: ='FS Seychelles'!F12*1000 -> 5970 | I11: ='FS Seychelles'!G12*1000 -> 2170 | J11: ='FS Seychelles'!H12*1000 -> 2440 | K11: ='FS Seychelles'!I12*1000 -> 2740 | L11: ='FS Seychelles'!J12*1000 -> 1410 | M11: ='FS Seychelles'!K12*1000 -> 1700 | ... O11: ='FS Seychelles'!M12*1000 -> 0 | P11: ='FS Seychelles'!N12 -> 7052 | Q11: ='FS Seychelles'!O12 -> 6371 | R11: ='FS Seychelles'!P12 -> 7160 | S11: ='FS Seychelles'!Q12 -> 0 | T11: ='FS Seychelles'!R12 -> 16007 | U11: ='FS Seychelles'!S12 -> 7665 | V11: ='FS Seychelles'!U12 -> 522.71 | W11: ='FS Seychelles'!W12 -> 60 | X11: ='FS Seychelles'!X12 -> 38 | Y11: ='FS Seychelles'!Y12 -> 159 | Z11: ='FS Seychelles'!Z12 -> 118 | AA11: ='FS Seychelles'!AA12 -> 67 | AB11: ='FS Seychelles'!AB12 -> 0 | AC11: ='FS Seychelles'!AC12 -> 97 | AD11: =('FS Seychelles'!AF18+'FS Seychelles'!AF24)/30 -> 0
A12: Seychelles | B12: =B11+1 -> 11 | C12: =C11 -> 12 | D12: 2022 | E12: ='FS Seychelles'!B13 -> 49.4 | F12: ='FS Seychelles'!D13*1000 -> 3370 | G12: ='FS Seychelles'!E13*1000 -> 4560 | H12: ='FS Seychelles'!F13*1000 -> 5750 | I12: ='FS Seychelles'!G13*1000 -> 2040 | J12: ='FS Seychelles'!H13*1000 -> 2310 | K12: ='FS Seychelles'!I13*1000 -> 2700 | L12: ='FS Seychelles'!J13*1000 -> 1380 | M12: ='FS Seychelles'!K13*1000 -> 1640 | ... O12: ='FS Seychelles'!M13*1000 -> 0 | P12: ='FS Seychelles'!N13 -> 9494 | Q12: ='FS Seychelles'!O13 -> 6503 | R12: ='FS Seychelles'!P13 -> 13349 | S12: ='FS Seychelles'!Q13 -> 0 | T12: ='FS Seychelles'!R13 -> 7081 | U12: ='FS Seychelles'!S13 -> 7513 | V12: ='FS Seychelles'!U13 -> 522.71 | W12: ='FS Seychelles'!W13 -> 59 | X12: ='FS Seychelles'!X13 -> 22 | Y12: ='FS Seychelles'!Y13 -> 160 | Z12: ='FS Seychelles'!Z13 -> 138 | AA12: ='FS Seychelles'!AA13 -> 78 | AB12: ='FS Seychelles'!AB13 -> 0 | AC12: ='FS Seychelles'!AC13 -> 104 | AD12: =('FS Seychelles'!AF19+'FS Seychelles'!AF25)/30 -> 0
A13: Seychelles | B13: =B12+1 -> 12 | C13: =C12 -> 12 | D13: 2022 | E13: ='FS Seychelles'!B14 -> 51.9 | F13: ='FS Seychelles'!D14*1000 -> 3280 | G13: ='FS Seychelles'!E14*1000 -> 4470 | H13: ='FS Seychelles'!F14*1000 -> 6020 | I13: ='FS Seychelles'!G14*1000 -> 2420 | J13: ='FS Seychelles'!H14*1000 -> 3110 | K13: ='FS Seychelles'!I14*1000 -> 2760 | L13: ='FS Seychelles'!J14*1000 -> 1470 | M13: ='FS Seychelles'!K14*1000 -> 1690 | ... O13: ='FS Seychelles'!M14*1000 -> 0 | P13: ='FS Seychelles'!N14 -> 10521 | Q13: ='FS Seychelles'!O14 -> 9206 | R13: ='FS Seychelles'!P14 -> 5706 | S13: ='FS Seychelles'!Q14 -> 2875 | T13: ='FS Seychelles'!R14 -> 9377 | U13: ='FS Seychelles'!S14 -> 8056 | V13: ='FS Seychelles'!U14 -> 522.71 | W13: ='FS Seychelles'!W14 -> 68 | X13: ='FS Seychelles'!X14 -> 34 | Y13: ='FS Seychelles'!Y14 -> 170 | Z13: ='FS Seychelles'!Z14 -> 142 | AA13: ='FS Seychelles'!AA14 -> 99 | AB13: ='FS Seychelles'!AB14 -> 0 | AC13: ='FS Seychelles'!AC14 -> 92 | AD13: =('FS Seychelles'!AF20+'FS Seychelles'!AF26)/30 -> 0
A14: Seychelles | B14: =B13+1 -> 13 | C14: =C13 -> 12 | D14: 2022 | E14: ='FS Seychelles'!B15 -> 51.9 | F14: ='FS Seychelles'!D15*1000 -> 3030 | G14: ='FS Seychelles'!E15*1000 -> 4390 | H14: ='FS Seychelles'!F15*1000 -> 5700 | I14: ='FS Seychelles'!G15*1000 -> 2010 | J14: ='FS Seychelles'!H15*1000 -> 2700 | K14: ='FS Seychelles'!I15*1000 -> 2540 | L14: ='FS Seychelles'!J15*1000 -> 1180 | M14: ='FS Seychelles'!K15*1000 -> 1690 | ... O14: ='FS Seychelles'!M15*1000 -> 0 | P14: ='FS Seychelles'!N15 -> 6254 | Q14: ='FS Seychelles'!O15 -> 10085 | R14: ='FS Seychelles'!P15 -> 5890 | S14: ='FS Seychelles'!Q15 -> 2723 | T14: ='FS Seychelles'!R15 -> 10069 | U14: ='FS Seychelles'!S15 -> 7235 | V14: ='FS Seychelles'!U15 -> 522.71 | W14: ='FS Seychelles'!W15 -> 63 | X14: ='FS Seychelles'!X15 -> 19 | Y14: ='FS Seychelles'!Y15 -> 162 | Z14: ='FS Seychelles'!Z15 -> 136 | AA14: ='FS Seychelles'!AA15 -> 91 | AB14: ='FS Seychelles'!AB15 -> 0 | AC14: ='FS Seychelles'!AC15 -> 99 | AD14: =('FS Seychelles'!AF21+'FS Seychelles'!AF27)/30 -> 0
... A20: Seychelles | B20: =B19+1 -> 19 | C20: =C19 -> 12 | D20: 2022 | E20: ='FS Seychelles'!B21 -> 79.2 | F20: ='FS Seychelles'!D21*1000 -> 2520 | G20: ='FS Seychelles'!E21*1000 -> 4220 | H20: ='FS Seychelles'!F21*1000 -> 5650 | I20: ='FS Seychelles'!G21*1000 -> 1740 | J20: ='FS Seychelles'!H21*1000 -> 2390 | K20: ='FS Seychelles'!I21*1000 -> 2160 | L20: ='FS Seychelles'!J21*1000 -> 1440 | M20: ='FS Seychelles'!K21*1000 -> 1620 | ... O20: ='FS Seychelles'!M21*1000 -> 0 | P20: ='FS Seychelles'!N21 -> 9964 | Q20: ='FS Seychelles'!O21 -> 9953 | R20: ='FS Seychelles'!P21 -> 5813 | S20: ='FS Seychelles'!Q21 -> 1298 | T20: ='FS Seychelles'!R21 -> 5712 | U20: ='FS Seychelles'!S21 -> 6982 | V20: ='FS Seychelles'!U21 -> 522.71 | W20: ='FS Seychelles'!W21 -> 77 | X20: ='FS Seychelles'!X21 -> 29 | Y20: ='FS Seychelles'!Y21 -> 120 | Z20: ='FS Seychelles'!Z21 -> 123 | AA20: ='FS Seychelles'!AA21 -> 77 | AB20: ='FS Seychelles'!AB21 -> 0 | AC20: ='FS Seychelles'!AC21 -> 103 | AD20: =('FS Seychelles'!AF27+'FS Seychelles'!AF33)/30 -> 0
A21: Seychelles | B21: =B20+1 -> 20 | C21: =C20 -> 12 | D21: 2022 | E21: ='FS Seychelles'!B22 -> 76.6 | F21: ='FS Seychelles'!D22*1000 -> 2870 | G21: ='FS Seychelles'!E22*1000 -> 4140 | H21: ='FS Seychelles'!F22*1000 -> 5600 | I21: ='FS Seychelles'!G22*1000 -> 1650 | J21: ='FS Seychelles'!H22*1000 -> 2300 | K21: ='FS Seychelles'!I22*1000 -> 2240 | L21: ='FS Seychelles'!J22*1000 -> 1360 | M21: ='FS Seychelles'!K22*1000 -> 1570 | ... O21: ='FS Seychelles'!M22*1000 -> 0 | P21: ='FS Seychelles'!N22 -> 16199 | Q21: ='FS Seychelles'!O22 -> 10584 | R21: ='FS Seychelles'!P22 -> 5628 | S21: ='FS Seychelles'!Q22 -> 0 | T21: ='FS Seychelles'!R23 -> 11265 | U21: ='FS Seychelles'!S22 -> 6859 | V21: ='FS Seychelles'!U22 -> 522.71 | W21: ='FS Seychelles'!W22 -> 86 | X21: ='FS Seychelles'!X22 -> 30 | Y21: ='FS Seychelles'!Y22 -> 153 | Z21: ='FS Seychelles'!Z22 -> 174 | AA21: ='FS Seychelles'!AA22 -> 108 | AB21: ='FS Seychelles'!AB22 -> 0 | AC21: ='FS Seychelles'!AC22 -> 104 | AD21: =('FS Seychelles'!AF28+'FS Seychelles'!AF34)/30 -> 0
A22: Seychelles | B22: =B21+1 -> 21 | C22: =C21 -> 12 | D22: 2022 | E22: ='FS Seychelles'!B23 -> 66.2 | F22: ='FS Seychelles'!D23*1000 -> 3150 | G22: ='FS Seychelles'!E23*1000 -> 4480 | H22: ='FS Seychelles'!F23*1000 -> 6030 | I22: ='FS Seychelles'!G23*1000 -> 1960 | J22: ='FS Seychelles'!H23*1000 -> 2560 | K22: ='FS Seychelles'!I23*1000 -> 2370 | L22: ='FS Seychelles'!J23*1000 -> 1380 | M22: ='FS Seychelles'!K23*1000 -> 1710 | ... O22: ='FS Seychelles'!M23*1000 -> 0 | P22: ='FS Seychelles'!N23 -> 5965 | Q22: ='FS Seychelles'!O23 -> 10543 | R22: ='FS Seychelles'!P23 -> 5900 | S22: ='FS Seychelles'!Q23 -> 4117 | T22: ='FS Seychelles'!R24 -> 9915 | U22: ='FS Seychelles'!S23 -> 8133 | V22: ='FS Seychelles'!U23 -> 522.71 | W22: ='FS Seychelles'!W23 -> 83 | X22: ='FS Seychelles'!X23 -> 68 | Y22: ='FS Seychelles'!Y23 -> 143 | Z22: ='FS Seychelles'!Z23 -> 190 | AA22: ='FS Seychelles'!AA23 -> 90 | AB22: ='FS Seychelles'!AB23 -> 0 | AC22: ='FS Seychelles'!AC23 -> 92 | AD22: =('FS Seychelles'!AF29+'FS Seychelles'!AF35)/30 -> 0
A23: Seychelles | B23: =B22+1 -> 22 | C23: =C22 -> 12 | D23: 2022 | E23: ='FS Seychelles'!B24 -> 58.4 | F23: ='FS Seychelles'!D24*1000 -> 2840 | G23: ='FS Seychelles'!E24*1000 -> 4620 | H23: ='FS Seychelles'!F24*1000 -> 6080 | I23: ='FS Seychelles'!G24*1000 -> 2000 | J23: ='FS Seychelles'!H24*1000 -> 2650 | K23: ='FS Seychelles'!I24*1000 -> 2840 | L23: ='FS Seychelles'!J24*1000 -> 1380 | M23: ='FS Seychelles'!K24*1000 -> 1700 | ... O23: ='FS Seychelles'!M24*1000 -> 0 | P23: ='FS Seychelles'!N24 -> 6137 | Q23: ='FS Seychelles'!O24 -> 9708 | R23: ='FS Seychelles'!P24 -> 6227 | S23: ='FS Seychelles'!Q24 -> 5251 | T23: ='FS Seychelles'!R25 -> 10554 | U23: ='FS Seychelles'!S24 -> 8094 | V23: ='FS Seychelles'!U24 -> 522.71 | W23: ='FS Seychelles'!W24 -> 83 | X23: ='FS Seychelles'!X24 -> 18 | Y23: ='FS Seychelles'!Y24 -> 125 | Z23: ='FS Seychelles'!Z24 -> 134 | AA23: ='FS Seychelles'!AA24 -> 83 | AB23: ='FS Seychelles'!AB24 -> 0 | AC23: ='FS Seychelles'!AC24 -> 83 | AD23: =('FS Seychelles'!AF30+'FS Seychelles'!AF36)/30 -> 0
A24: Seychelles | B24: =B23+1 -> 23 | C24: =C23 -> 12 | D24: 2022 | E24: ='FS Seychelles'!B25 -> 57.1 | F24: ='FS Seychelles'!D25*1000 -> 2780 | G24: ='FS Seychelles'!E25*1000 -> 4550 | H24: ='FS Seychelles'!F25*1000 -> 6110 | I24: ='FS Seychelles'!G25*1000 -> 2410 | J24: ='FS Seychelles'!H25*1000 -> 2770 | K24: ='FS Seychelles'!I25*1000 -> 2760 | L24: ='FS Seychelles'!J25*1000 -> 1420 | M24: ='FS Seychelles'!K25*1000 -> 1730 | ... O24: ='FS Seychelles'!M25*1000 -> 0 | P24: ='FS Seychelles'!N25 -> 5399 | Q24: ='FS Seychelles'!O25 -> 10535 | R24: ='FS Seychelles'!P25 -> 5412 | S24: ='FS Seychelles'!Q25 -> 5207 | T24: ='FS Seychelles'!R25 -> 10554 | U24: ='FS Seychelles'!S25 -> 7979 | V24: ='FS Seychelles'!U25 -> 522.71 | W24: ='FS Seychelles'!W25 -> 78 | X24: ='FS Seychelles'!X25 -> 20 | Y24: ='FS Seychelles'!Y25 -> 141 | Z24: ='FS Seychelles'!Z25 -> 108 | AA24: ='FS Seychelles'!AA25 -> 90 | AB24: ='FS Seychelles'!AB25 -> 0 | AC24: ='FS Seychelles'!AC25 -> 87 | AD24: =('FS Seychelles'!AF31+'FS Seychelles'!AF37)/30 -> 0
A25: Seychelles | B25: =B24+1 -> 24 | C25: =C24 -> 12 | D25: 2022 | E25: ='FS Seychelles'!B26 -> 61 | F25: ='FS Seychelles'!D26*1000 -> 2750 | G25: ='FS Seychelles'!E26*1000 -> 4600 | H25: ='FS Seychelles'!F26*1000 -> 6260 | I25: ='FS Seychelles'!G26*1000 -> 2610 | J25: ='FS Seychelles'!H26*1000 -> 2710 | K25: ='FS Seychelles'!I26*1000 -> 2760 | L25: ='FS Seychelles'!J26*1000 -> 1350 | M25: ='FS Seychelles'!K26*1000 -> 1730 | ... O25: ='FS Seychelles'!M26*1000 -> 0 | P25: ='FS Seychelles'!N26 -> 0 | Q25: ='FS Seychelles'!O26 -> 10539 | R25: ='FS Seychelles'!P26 -> 5642 | S25: ='FS Seychelles'!Q26 -> 11449 | T25: ='FS Seychelles'!R26 -> 10664 | U25: ='FS Seychelles'!S26 -> 8664 | V25: ='FS Seychelles'!U26 -> 522.71 | W25: ='FS Seychelles'!W26 -> 80 | X25: ='FS Seychelles'!X26 -> 31 | Y25: ='FS Seychelles'!Y26 -> 138 | Z25: ='FS Seychelles'!Z26 -> 117 | AA25: ='FS Seychelles'!AA26 -> 92 | AB25: ='FS Seychelles'!AB26 -> 73 | AC25: ='FS Seychelles'!AC26 -> 86 | AD25: =('FS Seychelles'!AF32+'FS Seychelles'!AF38)/30 -> 0
A26: Seychelles | B26: =B25+1 -> 25 | C26: =C25 -> 12 | D26: 2022 | E26: ='FS Seychelles'!B27 -> 64.9 | F26: ='FS Seychelles'!D27*1000 -> 2910 | G26: ='FS Seychelles'!E27*1000 -> 4790 | H26: ='FS Seychelles'!F27*1000 -> 6140 | I26: ='FS Seychelles'!G27*1000 -> 2740 | J26: ='FS Seychelles'!H27*1000 -> 2740 | K26: ='FS Seychelles'!I27*1000 -> 2156.0714 | L26: ='FS Seychelles'!J27*1000 -> 1370 | M26: ='FS Seychelles'!K27*1000 -> 1880 | ... O26: ='FS Seychelles'!M27*1000 -> 0 | P26: ='FS Seychelles'!N27 -> 7304 | Q26: ='FS Seychelles'!O27 -> 8995 | R26: ='FS Seychelles'!P27 -> 7202 | S26: ='FS Seychelles'!Q27 -> 6271 | T26: ='FS Seychelles'!R27 -> 9418 | U26: ='FS Seychelles'!S27 -> 8574 | V26: ='FS Seychelles'!U27 -> 522.71 | W26: ='FS Seychelles'!W27 -> 84 | X26: ='FS Seychelles'!X27 -> 23 | Y26: ='FS Seychelles'!Y27 -> 164 | Z26: ='FS Seychelles'!Z27 -> 106 | AA26: ='FS Seychelles'!AA27 -> 87 | AB26: ='FS Seychelles'!AB27 -> 65 | AC26: ='FS Seychelles'!AC27 -> 87 | AD26: =('FS Seychelles'!AF33+'FS Seychelles'!AF39)/30 -> 0
A27: Seychelles | B27: =B26+1 -> 26 | C27: =C26 -> 12 | D27: 2022 | E27: ='FS Seychelles'!B28 -> 74 | F27: ='FS Seychelles'!D28*1000 -> 3070 | G27: ='FS Seychelles'!E28*1000 -> 5060 | H27: ='FS Seychelles'!F28*1000 -> 6350 | I27: ='FS Seychelles'!G28*1000 -> 2910 | J27: ='FS Seychelles'!H28*1000 -> 3160 | K27: ='FS Seychelles'!I28*1000 -> 2156.0714 | L27: ='FS Seychelles'!J28*1000 -> 1360 | M27: ='FS Seychelles'!K28*1000 -> 1830 | ... O27: ='FS Seychelles'!M28*1000 -> 0 | P27: ='FS Seychelles'!N28 -> 6653 | Q27: ='FS Seychelles'!O28 -> 9810 | R27: ='FS Seychelles'!P28 -> 6461 | S27: ='FS Seychelles'!Q28 -> 7497 | T27: ='FS Seychelles'!R28 -> 9788 | U27: ='FS Seychelles'!S28 -> 8585 | V27: ='FS Seychelles'!U28 -> 522.71 | W27: ='FS Seychelles'!W28 -> 93 | X27: ='FS Seychelles'!X28 -> 20 | Y27: ='FS Seychelles'!Y28 -> 159 | Z27: ='FS Seychelles'!Z28 -> 111 | AA27: ='FS Seychelles'!AA28 -> 100 | AB27: ='FS Seychelles'!AB28 -> 92 | AC27: ='FS Seychelles'!AC28 -> 87 | AD27: =('FS Seychelles'!AF34+'FS Seychelles'!AF40)/30 -> 0
A28: Seychelles | B28: =B27+1 -> 27 | C28: =C27 -> 12 | D28: 2022 | E28: ='FS Seychelles'!B29 -> 87 | F28: ='FS Seychelles'!D29*1000 -> 2820 | G28: ='FS Seychelles'!E29*1000 -> 4850 | H28: ='FS Seychelles'!F29*1000 -> 6400 | I28: ='FS Seychelles'!G29*1000 -> 2760 | J28: ='FS Seychelles'!H29*1000 -> 3120 | K28: ='FS Seychelles'!I29*1000 -> 2156.0714 | L28: ='FS Seychelles'!J29*1000 -> 1190 | M28: ='FS Seychelles'!K29*1000 -> 1660 | ... O28: ='FS Seychelles'!M29*1000 -> 0 | P28: ='FS Seychelles'!N29 -> 6788 | Q28: ='FS Seychelles'!O29 -> 9198 | R28: ='FS Seychelles'!P29 -> 6707 | S28: ='FS Seychelles'!Q29 -> 8054 | T28: ='FS Seychelles'!R29 -> 9389 | U28: ='FS Seychelles'!S29 -> 8712 | V28: ='FS Seychelles'!U29 -> 522.71 | W28: ='FS Seychelles'!W29 -> 26 | X28: ='FS Seychelles'!X29 -> 22 | Y28: ='FS Seychelles'!Y29 -> 183 | Z28: ='FS Seychelles'!Z29 -> 119 | AA28: ='FS Seychelles'!AA29 -> 108 | AB28: ='FS Seychelles'!AB29 -> 70 | AC28: ='FS Seychelles'!AC29 -> 87 | AD28: =('FS Seychelles'!AF35+'FS Seychelles'!AF41)/30 -> 0
A29: Seychelles | B29: =B28+1 -> 28 | C29: =C28 -> 12 | D29: 2022 | E29: ='FS Seychelles'!B30 -> 83.1 | F29: ='FS Seychelles'!D30*1000 -> 3370 | G29: ='FS Seychelles'!E30*1000 -> 5080 | H29: ='FS Seychelles'!F30*1000 -> 6540 | I29: ='FS Seychelles'!G30*1000 -> 2850 | J29: ='FS Seychelles'!H30*1000 -> 3100 | K29: ='FS Seychelles'!I30*1000 -> 2156.0714 | L29: ='FS Seychelles'!J30*1000 -> 1390 | M29: ='FS Seychelles'!K30*1000 -> 1840 | ... O29: ='FS Seychelles'!M30*1000 -> 0 | P29: ='FS Seychelles'!N30 -> 5573 | Q29: ='FS Seychelles'!O30 -> 10046 | R29: ='FS Seychelles'!P30 -> 14718 | S29: ='FS Seychelles'!Q30 -> 1003 | T29: ='FS Seychelles'!R30 -> 11674 | U29: ='FS Seychelles'!S30 -> 9200 | V29: ='FS Seychelles'!U30 -> 522.71 | W29: ='FS Seychelles'!W30 -> 67.898148 | X29: ='FS Seychelles'!X30 -> 31 | Y29: ='FS Seychelles'!Y30 -> 140 | Z29: ='FS Seychelles'!Z30 -> 171 | AA29: ='FS Seychelles'!AA30 -> 105 | AB29: ='FS Seychelles'!AB30 -> 85 | AC29: ='FS Seychelles'!AC30 -> 85 | AD29: =('FS Seychelles'!AF36+'FS Seychelles'!AF42)/30 -> 0
A30: Seychelles | B30: =B29+1 -> 29 | C30: =C29 -> 12 | D30: 2022 | E30: ='FS Seychelles'!B31 -> 84.4 | F30: ='FS Seychelles'!D31*1000 -> 2640 | G30: ='FS Seychelles'!E31*1000 -> 3700 | H30: ='FS Seychelles'!F31*1000 -> 4650 | I30: ='FS Seychelles'!G31*1000 -> 2030 | J30: ='FS Seychelles'!H31*1000 -> 2560 | K30: ='FS Seychelles'!I31*1000 -> 2156.0714 | L30: ='FS Seychelles'!J31*1000 -> 987 | M30: ='FS Seychelles'!K31*1000 -> 1280 | ... O30: ='FS Seychelles'!M31*1000 -> 0 | P30: ='FS Seychelles'!N31 -> 10680 | Q30: ='FS Seychelles'!O31 -> 10497 | R30: ='FS Seychelles'!P31 -> 7315 | S30: ='FS Seychelles'!Q31 -> 9088 | T30: ='FS Seychelles'!R31 -> 7159 | U30: ='FS Seychelles'!S31 -> 9714 | V30: ='FS Seychelles'!U31 -> 522.71 | W30: ='FS Seychelles'!W31 -> 43 | X30: ='FS Seychelles'!X31 -> 22 | Y30: ='FS Seychelles'!Y31 -> 166 | Z30: ='FS Seychelles'!Z31 -> 168 | AA30: ='FS Seychelles'!AA31 -> 88 | AB30: ='FS Seychelles'!AB31 -> 73 | AC30: ='FS Seychelles'!AC31 -> 88 | AD30: =('FS Seychelles'!AF37+'FS Seychelles'!AF43)/30 -> 0
A31: Seychelles | B31: =B30+1 -> 30 | C31: =C30 -> 12 | D31: 2022 | E31: ='FS Seychelles'!B32 -> 75.3 | F31: ='FS Seychelles'!D32*1000 -> 2934.1379 | G31: ='FS Seychelles'!E32*1000 -> 4385.1724 | H31: ='FS Seychelles'!F32*1000 -> 5803.7931 | I31: ='FS Seychelles'!G32*1000 -> 2095.8621 | J31: ='FS Seychelles'!H32*1000 -> 2526.5517 | K31: ='FS Seychelles'!I32*1000 -> 2156.0714 | L31: ='FS Seychelles'!J32*1000 -> 1334.7241 | M31: ='FS Seychelles'!K32*1000 -> 1703.7931 | ... O31: ='FS Seychelles'!M32*1000 -> 0 | P31: ='FS Seychelles'!N32 -> 10163 | Q31: ='FS Seychelles'!O32 -> 10091 | R31: ='FS Seychelles'!P32 -> 6643 | S31: ='FS Seychelles'!Q32 -> 8684 | T31: ='FS Seychelles'!R32 -> 6541 | U31: ='FS Seychelles'!S32 -> 11028 | V31: ='FS Seychelles'!U32 -> 522.71 | W31: ='FS Seychelles'!W32 -> 21 | X31: ='FS Seychelles'!X32 -> 35 | Y31: ='FS Seychelles'!Y32 -> 164 | Z31: ='FS Seychelles'!Z32 -> 149 | AA31: ='FS Seychelles'!AA32 -> 106 | AB31: ='FS Seychelles'!AB32 -> 87 | AC31: ='FS Seychelles'!AC32 -> 85 | AD31: =('FS Seychelles'!AF38+'FS Seychelles'!AF44)/30 -> 0
A32: Seychelles | B32: 31 | C32: 12 | D32: 2022 | E32: 0 | F32: 0 | G32: 0 | H32: 0 | I32: ='FS Seychelles'!G33*1000 -> 2095.8621 | J32: ='FS Seychelles'!H33*1000 -> 2526.5517 | K32: ='FS Seychelles'!I33*1000 -> 2156.0714 | L32: 0 | M32: 0 | N32: 0 | O32: ='FS Seychelles'!M33*1000 -> 0 | P32: 0 | Q32: 0 | R32: 0 | S32: 0 | T32: 0 | U32: 0 | V32: 0 | W32: 0 | X32: ='FS Seychelles'!X33 -> 28.708333 | Y32: ='FS Seychelles'!Y33 -> 152.32708 | Z32: ='FS Seychelles'!Z33 -> 131.58222 | AA32: ='FS Seychelles'!AA33 -> 84.389583 | AB32: ='FS Seychelles'!AB33 -> 20.633333 | AC32: ='FS Seychelles'!AC33 -> 95.614583 | AD32: 0

Sheet FS Seychelles
A2: DATE | B2: Room Night % | C2: Food Covers (Customers) | D2: SS-A (MWH) | E2: SS-B (MWH) | F2: SS-C (MWH) | G2: SS-D1 (MWH) | H2: SS-D2 (MWH) | I2: SS-E (MWH) | J2: FIRE PUMP (MWH) | K2: CASINO (MWH) | L2: BOH (MWH) | M2: PUC (MWH) | N2: Generator#1 (KWH) | O2: Generator#2 (KWH) | P2: Generator#3 (KWH) | Q2: Generator#4 (KWH) | R2: Generator#5 (KWH) | S2: DIESEL (Liter) | T2: DIESEL TARIFF (Euro/Liter) | U2: PUC (KWh) | V2: PUC Tariff (Euro/KWh) | W2: BOH Water (m3) | X2: E-Resort (m3) | Y2: North RV (m3) | Z2: WT59 (m3) | AA2: WT08 (m3) | AB2: PUC E-resort(m3) | AC2: PUC HOH (m3) | AD2: LPG (Kg) | AG2: STP Irrigation Water (m3) | AH2: Fire tank 250 (m3) | AI2: Comment
A3: 44896 | B3: 55.8 | C3: 345 | D3: ='EMS Gridvis'!B2 -> 3.07 | E3: ='EMS Gridvis'!C2 -> 4.4 | F3: ='EMS Gridvis'!D2 -> 5.88 | G3: ='EMS Gridvis'!E2 -> 1.75 | H3: ='EMS Gridvis'!F2 -> 2.48 | I3: ='EMS Gridvis'!G2 -> 2.93 | J3: ='EMS Gridvis'!H2 -> 1.53 | K3: ='EMS Gridvis'!I2 -> 1.88 | ... M3: ='EMS Gridvis'!K2 -> 0 | N3: =Generator!D4 -> 12787 | O3: =Generator!H4 -> 10907 | P3: =Generator!L4 -> 5248 | Q3: =Generator!P4 -> 0 | R3: =Generator!T4 -> 7520 | S3: =Generator!X4 -> 7843 | T3: =23.84/13.49 -> 1.767235 | U3: 522.71 | V3: 1.84 | W3: ='RO Plant'!B4 -> 60 | X3: ='RO Plant'!C4 -> 24 | Y3: ='RO Plant'!D4 -> 214 | Z3: ='RO Plant'!E4 -> 152 | AA3: ='RO Plant'!F4 -> 71 | AB3: ='RO Plant'!G4 -> 0 | AC3: ='RO Plant'!H4 -> 100 | AD3: CYLINDER DELIVERY (KG) | AG3: =AH3-AI3 -> 103 | AH3: 54476 | AI3: 54373 | AJ3: 44895
A4: 44897 | B4: 59.7 | C4: 402 | D4: ='EMS Gridvis'!B3 -> 2.48 | E4: ='EMS Gridvis'!C3 -> 3.87 | F4: ='EMS Gridvis'!D3 -> 5.37 | G4: ='EMS Gridvis'!E3 -> 1.42 | H4: ='EMS Gridvis'!F3 -> 2.09 | I4: ='EMS Gridvis'!G3 -> 2.45 | J4: ='EMS Gridvis'!H3 -> 1.45 | K4: ='EMS Gridvis'!I3 -> 1.71 | ... M4: ='EMS Gridvis'!K3 -> 0 | N4: =Generator!D5 -> 5363 | O4: =Generator!H5 -> 10782 | P4: =Generator!L5 -> 5378 | Q4: =Generator!P5 -> 0 | R4: =Generator!T5 -> 10802 | S4: =Generator!X5 -> 7042 | T4: =23.84/13.49 -> 1.767235 | U4: 522.71 | V4: 1.84 | W4: ='RO Plant'!B5 -> 58 | X4: ='RO Plant'!C5 -> 14 | Y4: ='RO Plant'!D5 -> 135 | Z4: ='RO Plant'!E5 -> 97 | AA4: ='RO Plant'!F5 -> 75 | AB4: ='RO Plant'!G5 -> 0 | AC4: ='RO Plant'!H5 -> 100 | AD4: Unit (kg) | AE4: Quantity | AF4: Sub total | AG4: =AH4-AH3 -> 136 | AH4: 54612
A5: 44898 | B5: 57.1 | C5: 402 | D5: ='EMS Gridvis'!B4 -> 2.94 | E5: ='EMS Gridvis'!C4 -> 4.32 | F5: ='EMS Gridvis'!D4 -> 5.75 | G5: ='EMS Gridvis'!E4 -> 1.54 | H5: ='EMS Gridvis'!F4 -> 2.26 | I5: ='EMS Gridvis'!G4 -> 2.68 | J5: ='EMS Gridvis'!H4 -> 1.44 | K5: ='EMS Gridvis'!I4 -> 1.77 | ... M5: ='EMS Gridvis'!K4 -> 0 | N5: =Generator!D6 -> 8388 | O5: =Generator!H6 -> 6931 | P5: =Generator!L6 -> 11861 | Q5: =Generator!P6 -> 0 | R5: =Generator!T6 -> 5766 | S5: =Generator!X6 -> 6951 | T5: =23.84/13.49 -> 1.767235 | U5: 522.71 | V5: 1.84 | W5: ='RO Plant'!B6 -> 57 | X5: ='RO Plant'!C6 -> 31 | Y5: ='RO Plant'!D6 -> 125 | Z5: ='RO Plant'!E6 -> 67 | AA5: ='RO Plant'!F6 -> 87 | AB5: ='RO Plant'!G6 -> 0 | AC5: ='RO Plant'!H6 -> 102 | AD5: 9 | AE5: 0 | AF5: =AD5*AE5 -> 0 | AG5: =AH5-AH4 -> 109 | AH5: 54721
A6: 44899 | B6: 40.3 | C6: 315 | D6: ='EMS Gridvis'!B5 -> 3.08 | E6: ='EMS Gridvis'!C5 -> 4.45 | F6: ='EMS Gridvis'!D5 -> 5.48 | G6: ='EMS Gridvis'!E5 -> 1.66 | H6: ='EMS Gridvis'!F5 -> 2.33 | I6: ='EMS Gridvis'!G5 -> 2.77 | J6: ='EMS Gridvis'!H5 -> 1.23 | K6: ='EMS Gridvis'!I5 -> 1.69 | ... M6: ='EMS Gridvis'!K5 -> 0 | N6: =Generator!D7 -> 10905 | O6: =Generator!H7 -> 8754 | P6: =Generator!L7 -> 7905 | Q6: =Generator!P7 -> 0 | R6: =Generator!T7 -> 8073 | S6: =Generator!X7 -> 7738 | T6: =23.84/13.49 -> 1.767235 | U6: 522.71 | V6: 1.84 | W6: ='RO Plant'!B7 -> 71 | X6: ='RO Plant'!C7 -> 22 | Y6: ='RO Plant'!D7 -> 139 | Z6: ='RO Plant'!E7 -> 145 | AA6: ='RO Plant'!F7 -> 63 | AB6: ='RO Plant'!G7 -> 0 | AC6: ='RO Plant'!H7 -> 98 | AD6: 10 | AE6: 0 | AF6: =AD6*AE6 -> 0 | AG6: =AH6-AH5 -> 97 | AH6: 54818
A7: 44900 | B7: 39 | C7: 206 | D7: ='EMS Gridvis'!B6 -> 3.24 | E7: ='EMS Gridvis'!C6 -> 4.32 | F7: ='EMS Gridvis'!D6 -> 5.48 | G7: ='EMS Gridvis'!E6 -> 1.9 | H7: ='EMS Gridvis'!F6 -> 2.56 | I7: ='EMS Gridvis'!G6 -> 2.62 | J7: ='EMS Gridvis'!H6 -> 1.14 | K7: ='EMS Gridvis'!I6 -> 1.74 | ... M7: ='EMS Gridvis'!K6 -> 0 | N7: =Generator!D8 -> 5104 | O7: =Generator!H8 -> 15185 | P7: =Generator!L8 -> 8249 | Q7: =Generator!P8 -> 0 | R7: =Generator!T8 -> 4060 | S7: =Generator!X8 -> 7053 | T7: =23.84/13.49 -> 1.767235 | U7: 522.71 | V7: 1.84 | W7: ='RO Plant'!B8 -> 60 | X7: ='RO Plant'!C8 -> 28 | Y7: ='RO Plant'!D8 -> 141 | Z7: ='RO Plant'!E8 -> 155 | AA7: ='RO Plant'!F8 -> 71 | AB7: ='RO Plant'!G8 -> 0 | AC7: ='RO Plant'!H8 -> 101 | AD7: 12 | AE7: 0 | AF7: =AD7*AE7 -> 0 | AG7: =AH7-AH6 -> 58 | AH7: 54876
A8: 44901 | B8: 48.1 | C8: 235 | D8: ='EMS Gridvis'!B7 -> 3.23 | E8: ='EMS Gridvis'!C7 -> 4.06 | F8: ='EMS Gridvis'!D7 -> 5.61 | G8: ='EMS Gridvis'!E7 -> 2.01 | H8: ='EMS Gridvis'!F7 -> 2.48 | I8: ='EMS Gridvis'!G7 -> 2.37 | J8: ='EMS Gridvis'!H7 -> 1.2 | K8: ='EMS Gridvis'!I7 -> 1.71 | ... M8: ='EMS Gridvis'!K7 -> 0 | N8: =Generator!D9 -> 5958 | O8: =Generator!H9 -> 7287 | P8: =Generator!L9 -> 13165 | Q8: =Generator!P9 -> 0 | R8: =Generator!T9 -> 10663 | S8: =Generator!X9 -> 7893 | T8: =23.84/13.49 -> 1.767235 | U8: 522.71 | V8: 1.84 | W8: ='RO Plant'!B9 -> 62 | X8: ='RO Plant'!C9 -> 34 | Y8: ='RO Plant'!D9 -> 164 | Z8: ='RO Plant'!E9 -> 101 | AA8: ='RO Plant'!F9 -> 69 | AB8: ='RO Plant'!G9 -> 0 | AC8: ='RO Plant'!H9 -> 103 | AD8: 20 | AE8: 96 | AF8: =AD8*AE8 -> 1920 | AG8: =AH8-AH7 -> 110 | AH8: 54986
A9: 44902 | B9: 48.1 | C9: 304 | D9: ='EMS Gridvis'!B8 -> 3.2 | E9: ='EMS Gridvis'!C8 -> 4.42 | F9: ='EMS Gridvis'!D8 -> 5.68 | G9: ='EMS Gridvis'!E8 -> 2.3 | H9: ='EMS Gridvis'!F8 -> 2.46 | I9: ='EMS Gridvis'!G8 -> 2.29 | J9: ='EMS Gridvis'!H8 -> 1.12 | K9: ='EMS Gridvis'!I8 -> 1.74 | ... M9: ='EMS Gridvis'!K8 -> 0 | N9: =Generator!D10 -> 6875 | O9: =Generator!H10 -> 8665 | P9: =Generator!L10 -> 15453 | Q9: =Generator!P10 -> 0 | R9: =Generator!T10 -> 4705 | S9: =Generator!X10 -> 7646 | T9: =23.84/13.49 -> 1.767235 | U9: 522.71 | V9: 1.84 | W9: ='RO Plant'!B10 -> 63 | X9: ='RO Plant'!C10 -> 21 | Y9: ='RO Plant'!D10 -> 166 | Z9: ='RO Plant'!E10 -> 93 | AA9: ='RO Plant'!F10 -> 73 | AB9: ='RO Plant'!G10 -> 0 | AC9: ='RO Plant'!H10 -> 103 | AD9: 24 | AE9: 0 | AF9: =AD9*AE9 -> 0 | AG9: =AH9-AH8 -> 121 | AH9: 55107
A10: 44903 | B10: 49.4 | C10: 335 | D10: ='EMS Gridvis'!B9 -> 2.87 | E10: ='EMS Gridvis'!C9 -> 4.4 | F10: ='EMS Gridvis'!D9 -> 5.64 | G10: ='EMS Gridvis'!E9 -> 2 | H10: ='EMS Gridvis'!F9 -> 2.25 | I10: ='EMS Gridvis'!G9 -> 2.26 | J10: ='EMS Gridvis'!H9 -> 1.36 | K10: ='EMS Gridvis'!I9 -> 1.79 | ... M10: ='EMS Gridvis'!K9 -> 0 | N10: =Generator!D11 -> 12242 | O10: =Generator!H11 -> 9846 | P10: =Generator!L11 -> 11840 | Q10: =Generator!P11 -> 0 | R10: =Generator!T11 -> 9202 | S10: =Generator!X11 -> 8935 | T10: =23.84/13.49 -> 1.767235 | U10: 522.71 | V10: 1.84 | W10: ='RO Plant'!B11 -> 61 | X10: ='RO Plant'!C11 -> 23 | Y10: ='RO Plant'!D11 -> 166 | Z10: ='RO Plant'!E11 -> 167 | AA10: ='RO Plant'!F11 -> 84 | AB10: ='RO Plant'!G11 -> 0 | AC10: ='RO Plant'!H11 -> 107 | AE10: Total | AF10: =SUM(AF5:AF9) -> 1920 | AG10: =AH10-AH9 -> 113 | AH10: 55220
A11: 44904 | B11: 49.4 | C11: 336 | D11: ='EMS Gridvis'!B10 -> 2.95 | E11: ='EMS Gridvis'!C10 -> 4.19 | F11: ='EMS Gridvis'!D10 -> 5.86 | G11: ='EMS Gridvis'!E10 -> 2.19 | H11: ='EMS Gridvis'!F10 -> 2.31 | I11: ='EMS Gridvis'!G10 -> 2.44 | J11: ='EMS Gridvis'!H10 -> 1.37 | K11: ='EMS Gridvis'!I10 -> 1.68 | ... M11: ='EMS Gridvis'!K10 -> 0 | N11: =Generator!D12 -> 12070 | O11: =Generator!H12 -> 7118 | P11: =Generator!L12 -> 7111 | Q11: =Generator!P12 -> 0 | R11: =Generator!T12 -> 0 | S11: =Generator!X12 -> 5532 | T11: =23.84/13.49 -> 1.767235 | U11: 522.71 | V11: 1.84 | W11: ='RO Plant'!B12 -> 65 | X11: ='RO Plant'!C12 -> 37 | Y11: ='RO Plant'!D12 -> 130 | Z11: ='RO Plant'!E12 -> 143 | AA11: ='RO Plant'!F12 -> 61 | AB11: ='RO Plant'!G12 -> 0 | AC11: ='RO Plant'!H12 -> 73 | AD11: TRUCK DELIVERY (KG) | AG11: =AH11-AH10 -> 138 | AH11: 55358
A12: 44905 | B12: 53.2 | C12: 344 | D12: ='EMS Gridvis'!B11 -> 3.02 | E12: ='EMS Gridvis'!C11 -> 4.26 | F12: ='EMS Gridvis'!D11 -> 5.97 | G12: ='EMS Gridvis'!E11 -> 2.17 | H12: ='EMS Gridvis'!F11 -> 2.44 | I12: ='EMS Gridvis'!G11 -> 2.74 | J12: ='EMS Gridvis'!H11 -> 1.41 | K12: ='EMS Gridvis'!I11 -> 1.7 | ... M12: ='EMS Gridvis'!K11 -> 0 | N12: =Generator!D13 -> 7052 | O12: =Generator!H13 -> 6371 | P12: =Generator!L13 -> 7160 | Q12: =Generator!P13 -> 0 | R12: =Generator!T13 -> 16007 | S12: =Generator!X13 -> 7665 | T12: =23.84/13.49 -> 1.767235 | U12: 522.71 | V12: 1.84 | W12: ='RO Plant'!B13 -> 60 | X12: ='RO Plant'!C13 -> 38 | Y12: ='RO Plant'!D13 -> 159 | Z12: ='RO Plant'!E13 -> 118 | AA12: ='RO Plant'!F13 -> 67 | AB12: ='RO Plant'!G13 -> 0 | AC12: ='RO Plant'!H13 -> 97 | AE12: Sub Total | AG12: =AH12-AH11 -> 111 | AH12: 55469
A13: 44906 | B13: 49.4 | C13: 329 | D13: ='EMS Gridvis'!B12 -> 3.37 | E13: ='EMS Gridvis'!C12 -> 4.56 | F13: ='EMS Gridvis'!D12 -> 5.75 | G13: ='EMS Gridvis'!E12 -> 2.04 | H13: ='EMS Gridvis'!F12 -> 2.31 | I13: ='EMS Gridvis'!G12 -> 2.7 | J13: ='EMS Gridvis'!H12 -> 1.38 | K13: ='EMS Gridvis'!I12 -> 1.64 | ... M13: ='EMS Gridvis'!K12 -> 0 | N13: =Generator!D14 -> 9494 | O13: =Generator!H14 -> 6503 | P13: =Generator!L14 -> 13349 | Q13: =Generator!P14 -> 0 | R13: =Generator!T14 -> 7081 | S13: =Generator!X14 -> 7513 | T13: =23.84/13.49 -> 1.767235 | U13: 522.71 | V13: 1.84 | W13: ='RO Plant'!B14 -> 59 | X13: ='RO Plant'!C14 -> 22 | Y13: ='RO Plant'!D14 -> 160 | Z13: ='RO Plant'!E14 -> 138 | AA13: ='RO Plant'!F14 -> 78 | AB13: ='RO Plant'!G14 -> 0 | AC13: ='RO Plant'!H14 -> 104 | AD13: Sitronel | AE13: 1746 | AG13: =AH13-AH12 -> 73 | AH13: 55542
A14: 44907 | B14: 51.9 | C14: 309 | D14: ='EMS Gridvis'!B13 -> 3.28 | E14: ='EMS Gridvis'!C13 -> 4.47 | F14: ='EMS Gridvis'!D13 -> 6.02 | G14: ='EMS Gridvis'!E13 -> 2.42 | H14: ='EMS Gridvis'!F13 -> 3.11 | I14: ='EMS Gridvis'!G13 -> 2.76 | J14: ='EMS Gridvis'!H13 -> 1.47 | K14: ='EMS Gridvis'!I13 -> 1.69 | ... M14: ='EMS Gridvis'!K13 -> 0 | N14: =Generator!D15 -> 10521 | O14: =Generator!H15 -> 9206 | P14: =Generator!L15 -> 5706 | Q14: =Generator!P15 -> 2875 | R14: =Generator!T15 -> 9377 | S14: =Generator!X15 -> 8056 | T14: =23.84/13.49 -> 1.767235 | U14: 522.71 | V14: 1.84 | W14: ='RO Plant'!B15 -> 68 | X14: ='RO Plant'!C15 -> 34 | Y14: ='RO Plant'!D15 -> 170 | Z14: ='RO Plant'!E15 -> 142 | AA14: ='RO Plant'!F15 -> 99 | AB14: ='RO Plant'!G15 -> 0 | AC14: ='RO Plant'!H15 -> 92 | AD14: Zez | AE14: 1395 | AG14: =AH14-AH13 -> 113 | AH14: 55655
A15: 44908 | B15: 51.9 | C15: 312 | D15: ='EMS Gridvis'!B14 -> 3.03 | E15: ='EMS Gridvis'!C14 -> 4.39 | F15: ='EMS Gridvis'!D14 -> 5.7 | G15: ='EMS Gridvis'!E14 -> 2.01 | H15: ='EMS Gridvis'!F14 -> 2.7 | I15: ='EMS Gridvis'!G14 -> 2.54 | J15: ='EMS Gridvis'!H14 -> 1.18 | K15: ='EMS Gridvis'!I14 -> 1.69 | ... M15: ='EMS Gridvis'!K14 -> 0 | N15: =Generator!D16 -> 6254 | O15: =Generator!H16 -> 10085 | P15: =Generator!L16 -> 5890 | Q15: =Generator!P16 -> 2723 | R15: =Generator!T16 -> 10069 | S15: =Generator!X16 -> 7235 | T15: =23.84/13.49 -> 1.767235 | U15: 522.71 | V15: 1.84 | W15: ='RO Plant'!B16 -> 63 | X15: ='RO Plant'!C16 -> 19 | Y15: ='RO Plant'!D16 -> 162 | Z15: ='RO Plant'!E16 -> 136 | AA15: ='RO Plant'!F16 -> 91 | AB15: ='RO Plant'!G16 -> 0 | AC15: ='RO Plant'!H16 -> 99 | AE15: Total | AF15: =SUM(AE13:AF14) -> 3141 | AG15: =AH15-AH14 -> 96 | AH15: 55751
A16: 44909 | B16: 57.1 | C16: 393 | D16: ='EMS Gridvis'!B15 -> 3.25 | E16: ='EMS Gridvis'!C15 -> 4.77 | F16: ='EMS Gridvis'!D15 -> 5.86 | G16: ='EMS Gridvis'!E15 -> 2.35 | H16: ='EMS Gridvis'!F15 -> 2.4 | I16: ='EMS Gridvis'!G15 -> 2.5 | J16: ='EMS Gridvis'!H15 -> 1.46 | K16: ='EMS Gridvis'!I15 -> 1.71 | ... M16: ='EMS Gridvis'!K15 -> 0 | N16: =Generator!D17 -> 5717 | O16: =Generator!H17 -> 9917 | P16: =Generator!L17 -> 5774 | Q16: =Generator!P17 -> 4975 | R16: =Generator!T17 -> 9974 | S16: =Generator!X17 -> 8376 | T16: =23.84/13.49 -> 1.767235 | U16: 522.71 | V16: 1.84 | W16: ='RO Plant'!B17 -> 74 | X16: ='RO Plant'!C17 -> 27 | Y16: ='RO Plant'!D17 -> 162 | Z16: ='RO Plant'!E17 -> 124 | AA16: ='RO Plant'!F17 -> 73 | AB16: ='RO Plant'!G17 -> 0 | AC16: ='RO Plant'!H17 -> 105 | AG16: =AH16-AH15 -> 107 | AH16: 55858
A17: 44910 | B17: 61 | C17: 360 | D17: ='EMS Gridvis'!B16 -> 3.06 | E17: ='EMS Gridvis'!C16 -> 4.57 | F17: ='EMS Gridvis'!D16 -> 5.95 | G17: ='EMS Gridvis'!E16 -> 2.19 | H17: ='EMS Gridvis'!F16 -> 2.52 | I17: ='EMS Gridvis'!G16 -> 2.72 | J17: ='EMS Gridvis'!H16 -> 1.42 | K17: ='EMS Gridvis'!I16 -> 1.77 | ... M17: ='EMS Gridvis'!K16 -> 0 | N17: =Generator!D18 -> 5827 | O17: =Generator!H18 -> 10009 | P17: =Generator!L18 -> 5887 | Q17: =Generator!P18 -> 4048 | R17: =Generator!T18 -> 10164 | S17: =Generator!X18 -> 6992 | T17: =23.84/13.49 -> 1.767235 | U17: 522.71 | V17: 1.84 | W17: ='RO Plant'!B18 -> 68 | X17: ='RO Plant'!C18 -> 27 | Y17: ='RO Plant'!D18 -> 161 | Z17: ='RO Plant'!E18 -> 123 | AA17: ='RO Plant'!F18 -> 86 | AB17: ='RO Plant'!G18 -> 74 | AC17: ='RO Plant'!H18 -> 104 | AG17: =AH17-AH16 -> 164 | AH17: 56022
A18: 44911 | B18: 61 | C18: 344 | D18: ='EMS Gridvis'!B17 -> 2.25 | E18: ='EMS Gridvis'!C17 -> 3.41 | F18: ='EMS Gridvis'!D17 -> 5.34 | G18: ='EMS Gridvis'!E17 -> 1.82 | H18: ='EMS Gridvis'!F17 -> 2.06 | I18: ='EMS Gridvis'!G17 -> 2.24 | J18: ='EMS Gridvis'!H17 -> 1.48 | K18: ='EMS Gridvis'!I17 -> 1.58 | ... M18: ='EMS Gridvis'!K17 -> 0 | N18: =Generator!D19 -> 5417 | O18: =Generator!H19 -> 10261 | P18: =Generator!L19 -> 5358 | Q18: =Generator!P19 -> 0 | R18: =Generator!T19 -> 10339 | S18: =Generator!X19 -> 6766 | T18: =23.84/13.49 -> 1.767235 | U18: 522.71 | V18: 1.84 | W18: ='RO Plant'!B19 -> 63 | X18: ='RO Plant'!C19 -> 51 | Y18: ='RO Plant'!D19 -> 139 | Z18: ='RO Plant'!E19 -> 126.73333 | AA18: ='RO Plant'!F19 -> 79 | AB18: ='RO Plant'!G19 -> 0 | AC18: ='RO Plant'!H19 -> 103 | AG18: =AH18-AH17 -> 181 | AH18: 56203
A19: 44912 | B19: 50.6 | C19: 309 | D19: ='EMS Gridvis'!B18 -> 2.63 | E19: ='EMS Gridvis'!C18 -> 3.98 | F19: ='EMS Gridvis'!D18 -> 5.59 | G19: ='EMS Gridvis'!E18 -> 1.64 | H19: ='EMS Gridvis'!F18 -> 2.24 | I19: ='EMS Gridvis'!G18 -> 2.1 | J19: ='EMS Gridvis'!H18 -> 1.31 | K19: ='EMS Gridvis'!I18 -> 1.74 | ... M19: ='EMS Gridvis'!K18 -> 0 | N19: =Generator!D20 -> 10478 | O19: =Generator!H20 -> 9639 | P19: =Generator!L20 -> 4990 | Q19: =Generator!P20 -> 2567 | R19: =Generator!T20 -> 4030 | S19: =Generator!X20 -> 6851 | T19: =23.84/13.49 -> 1.767235 | U19: 522.71 | V19: 1.84 | W19: ='RO Plant'!B20 -> 63.25 | X19: ='RO Plant'!C20 -> 28.25 | Y19: ='RO Plant'!D20 -> 155.8125 | Z19: ='RO Plant'!E20 -> 126.73333 | AA19: ='RO Plant'!F20 -> 76.6875 | AB19: ='RO Plant'!G20 -> 0 | AC19: ='RO Plant'!H20 -> 99.4375 | AG19: =AH19-AH18 -> 266 | AH19: 56469
A20: 44913 | B20: 67.5 | C20: 510 | D20: ='EMS Gridvis'!B19 -> 2.42 | E20: ='EMS Gridvis'!C19 -> 4.24 | F20: ='EMS Gridvis'!D19 -> 5.57 | G20: ='EMS Gridvis'!E19 -> 1.71 | H20: ='EMS Gridvis'!F19 -> 2.21 | I20: ='EMS Gridvis'!G19 -> 2.13 | J20: ='EMS Gridvis'!H19 -> 1.13 | K20: ='EMS Gridvis'!I19 -> 1.63 | ... M20: ='EMS Gridvis'!K19 -> 0 | N20: =Generator!D21 -> 6082 | O20: =Generator!H21 -> 8841 | P20: =Generator!L21 -> 6085 | Q20: =Generator!P21 -> 3177 | R20: =Generator!T21 -> 8994 | S20: =Generator!X21 -> 7164 | T20: =23.84/13.49 -> 1.767235 | U20: 522.71 | V20: 1.84 | W20: ='RO Plant'!B21 -> 68 | X20: ='RO Plant'!C21 -> 32 | Y20: ='RO Plant'!D21 -> 125 | Z20: ='RO Plant'!E21 -> 123 | AA20: ='RO Plant'!F21 -> 94 | AB20: ='RO Plant'!G21 -> 0 | AC20: ='RO Plant'!H21 -> 104 | AG20: =AH20-AH19 -> 187 | AH20: 56656
A21: 44914 | B21: 79.2 | C21: 577 | D21: ='EMS Gridvis'!B20 -> 2.52 | E21: ='EMS Gridvis'!C20 -> 4.22 | F21: ='EMS Gridvis'!D20 -> 5.65 | G21: ='EMS Gridvis'!E20 -> 1.74 | H21: ='EMS Gridvis'!F20 -> 2.39 | I21: ='EMS Gridvis'!G20 -> 2.16 | J21: ='EMS Gridvis'!H20 -> 1.44 | K21: ='EMS Gridvis'!I20 -> 1.62 | ... M21: ='EMS Gridvis'!K20 -> 0 | N21: =Generator!D22 -> 9964 | O21: =Generator!H22 -> 9953 | P21: =Generator!L22 -> 5813 | Q21: =Generator!P22 -> 1298 | R21: =Generator!T22 -> 5712 | S21: =Generator!X22 -> 6982 | T21: =23.84/13.49 -> 1.767235 | U21: 522.71 | V21: 1.84 | W21: ='RO Plant'!B22 -> 77 | X21: ='RO Plant'!C22 -> 29 | Y21: ='RO Plant'!D22 -> 120 | Z21: ='RO Plant'!E22 -> 123 | AA21: ='RO Plant'!F22 -> 77 | AB21: ='RO Plant'!G22 -> 0 | AC21: ='RO Plant'!H22 -> 103 | AG21: =AH21-AH20 -> 91 | AH21: 56747
A22: 44915 | B22: 76.6 | C22: 618 | D22: ='EMS Gridvis'!B21 -> 2.87 | E22: ='EMS Gridvis'!C21 -> 4.14 | F22: ='EMS Gridvis'!D21 -> 5.6 | G22: ='EMS Gridvis'!E21 -> 1.65 | H22: ='EMS Gridvis'!F21 -> 2.3 | I22: ='EMS Gridvis'!G21 -> 2.24 | J22: ='EMS Gridvis'!H21 -> 1.36 | K22: ='EMS Gridvis'!I21 -> 1.57 | ... M22: ='EMS Gridvis'!K21 -> 0 | N22: =Generator!D23 -> 16199 | O22: =Generator!H23 -> 10584 | P22: =Generator!L23 -> 5628 | Q22: =Generator!P23 -> 0 | R22: =Generator!T23 -> 0 | S22: =Generator!X23 -> 6859 | T22: =23.84/13.49 -> 1.767235 | U22: 522.71 | V22: 1.84 | W22: ='RO Plant'!B23 -> 86 | X22: ='RO Plant'!C23 -> 30 | Y22: ='RO Plant'!D23 -> 153 | Z22: ='RO Plant'!E23 -> 174 | AA22: ='RO Plant'!F23 -> 108 | AB22: ='RO Plant'!G23 -> 0 | AC22: ='RO Plant'!H23 -> 104 | AG22: =AH22-AH21 -> 154 | AH22: 56901
A23: 44916 | B23: 66.2 | C23: 504 | D23: ='EMS Gridvis'!B22 -> 3.15 | E23: ='EMS Gridvis'!C22 -> 4.48 | F23: ='EMS Gridvis'!D22 -> 6.03 | G23: ='EMS Gridvis'!E22 -> 1.96 | H23: ='EMS Gridvis'!F22 -> 2.56 | I23: ='EMS Gridvis'!G22 -> 2.37 | J23: ='EMS Gridvis'!H22 -> 1.38 | K23: ='EMS Gridvis'!I22 -> 1.71 | ... M23: ='EMS Gridvis'!K22 -> 0 | N23: =Generator!D24 -> 5965 | O23: =Generator!H24 -> 10543 | P23: =Generator!L24 -> 5900 | Q23: =Generator!P24 -> 4117 | R23: =Generator!T24 -> 11265 | S23: =Generator!X24 -> 8133 | T23: =23.84/13.49 -> 1.767235 | U23: 522.71 | V23: 1.84 | W23: ='RO Plant'!B24 -> 83 | X23: ='RO Plant'!C24 -> 68 | Y23: ='RO Plant'!D24 -> 143 | Z23: ='RO Plant'!E24 -> 190 | AA23: ='RO Plant'!F24 -> 90 | AB23: ='RO Plant'!G24 -> 0 | AC23: ='RO Plant'!H24 -> 92 | AG23: =AH23-AH22 -> 197 | AH23: 57098
A24: 44917 | B24: 58.4 | C24: 616 | D24: ='EMS Gridvis'!B23 -> 2.84 | E24: ='EMS Gridvis'!C23 -> 4.62 | F24: ='EMS Gridvis'!D23 -> 6.08 | G24: ='EMS Gridvis'!E23 -> 2 | H24: ='EMS Gridvis'!F23 -> 2.65 | I24: ='EMS Gridvis'!G23 -> 2.84 | J24: ='EMS Gridvis'!H23 -> 1.38 | K24: ='EMS Gridvis'!I23 -> 1.7 | ... M24: ='EMS Gridvis'!K23 -> 0 | N24: =Generator!D25 -> 6137 | O24: =Generator!H25 -> 9708 | P24: =Generator!L25 -> 6227 | Q24: =Generator!P25 -> 5251 | R24: =Generator!T25 -> 9915 | S24: =Generator!X25 -> 8094 | T24: =23.84/13.49 -> 1.767235 | U24: 522.71 | V24: 1.84 | W24: ='RO Plant'!B25 -> 83 | X24: ='RO Plant'!C25 -> 18 | Y24: ='RO Plant'!D25 -> 125 | Z24: ='RO Plant'!E25 -> 134 | AA24: ='RO Plant'!F25 -> 83 | AB24: ='RO Plant'!G25 -> 0 | AC24: ='RO Plant'!H25 -> 83 | AG24: =AH24-AH23 -> 181 | AH24: 57279
A25: 44918 | B25: 57.1 | C25: 441 | D25: ='EMS Gridvis'!B24 -> 2.78 | E25: ='EMS Gridvis'!C24 -> 4.55 | F25: ='EMS Gridvis'!D24 -> 6.11 | G25: ='EMS Gridvis'!E24 -> 2.41 | H25: ='EMS Gridvis'!F24 -> 2.77 | I25: ='EMS Gridvis'!G24 -> 2.76 | J25: ='EMS Gridvis'!H24 -> 1.42 | K25: ='EMS Gridvis'!I24 -> 1.73 | ... M25: ='EMS Gridvis'!K24 -> 0 | N25: =Generator!D26 -> 5399 | O25: =Generator!H26 -> 10535 | P25: =Generator!L26 -> 5412 | Q25: =Generator!P26 -> 5207 | R25: =Generator!T26 -> 10554 | S25: =Generator!X26 -> 7979 | T25: =23.84/13.49 -> 1.767235 | U25: 522.71 | V25: 1.84 | W25: ='RO Plant'!B26 -> 78 | X25: ='RO Plant'!C26 -> 20 | Y25: ='RO Plant'!D26 -> 141 | Z25: ='RO Plant'!E26 -> 108 | AA25: ='RO Plant'!F26 -> 90 | AB25: ='RO Plant'!G26 -> 0 | AC25: ='RO Plant'!H26 -> 87 | AG25: =AH25-AH24 -> 190 | AH25: 57469
A26: 44919 | B26: 61 | C26: 380 | D26: ='EMS Gridvis'!B25 -> 2.75 | E26: ='EMS Gridvis'!C25 -> 4.6 | F26: ='EMS Gridvis'!D25 -> 6.26 | G26: ='EMS Gridvis'!E25 -> 2.61 | H26: ='EMS Gridvis'!F25 -> 2.71 | I26: ='EMS Gridvis'!G25 -> 2.76 | J26: ='EMS Gridvis'!H25 -> 1.35 | K26: ='EMS Gridvis'!I25 -> 1.73 | ... M26: ='EMS Gridvis'!K25 -> 0 | N26: =Generator!D27 -> 0 | O26: =Generator!H27 -> 10539 | P26: =Generator!L27 -> 5642 | Q26: =Generator!P27 -> 11449 | R26: =Generator!T27 -> 10664 | S26: =Generator!X27 -> 8664 | T26: =23.84/13.49 -> 1.767235 | U26: 522.71 | V26: 1.84 | W26: ='RO Plant'!B27 -> 80 | X26: ='RO Plant'!C27 -> 31 | Y26: ='RO Plant'!D27 -> 138 | Z26: ='RO Plant'!E27 -> 117 | AA26: ='RO Plant'!F27 -> 92 | AB26: ='RO Plant'!G27 -> 73 | AC26: ='RO Plant'!H27 -> 86 | AG26: =AH26-AH25 -> 149 | AH26: 57618
A27: 44920 | B27: 64.9 | C27: 565 | D27: ='EMS Gridvis'!B26 -> 2.91 | E27: ='EMS Gridvis'!C26 -> 4.79 | F27: ='EMS Gridvis'!D26 -> 6.14 | G27: ='EMS Gridvis'!E26 -> 2.74 | H27: ='EMS Gridvis'!F26 -> 2.74 | I27: ='EMS Gridvis'!G26 -> 2.1560714 | J27: ='EMS Gridvis'!H26 -> 1.37 | K27: ='EMS Gridvis'!I26 -> 1.88 | ... M27: ='EMS Gridvis'!K26 -> 0 | N27: =Generator!D28 -> 7304 | O27: =Generator!H28 -> 8995 | P27: =Generator!L28 -> 7202 | Q27: =Generator!P28 -> 6271 | R27: =Generator!T28 -> 9418 | S27: =Generator!X28 -> 8574 | T27: =23.84/13.49 -> 1.767235 | U27: 522.71 | V27: 1.84 | W27: ='RO Plant'!B28 -> 84 | X27: ='RO Plant'!C28 -> 23 | Y27: ='RO Plant'!D28 -> 164 | Z27: ='RO Plant'!E28 -> 106 | AA27: ='RO Plant'!F28 -> 87 | AB27: ='RO Plant'!G28 -> 65 | AC27: ='RO Plant'!H28 -> 87 | AG27: =AH27-AH26 -> 141 | AH27: 57759
... A32: 44925 | B32: 75.3 | C32: 569 | D32: ='EMS Gridvis'!B31 -> 2.9341379 | E32: ='EMS Gridvis'!C31 -> 4.3851724 | F32: ='EMS Gridvis'!D31 -> 5.8037931 | G32: ='EMS Gridvis'!E31 -> 2.0958621 | H32: ='EMS Gridvis'!F31 -> 2.5265517 | I32: ='EMS Gridvis'!G31 -> 2.1560714 | J32: ='EMS Gridvis'!H31 -> 1.3347241 | K32: ='EMS Gridvis'!I31 -> 1.7037931 | ... M32: ='EMS Gridvis'!K31 -> 0 | N32: =Generator!D33 -> 10163 | O32: =Generator!H33 -> 10091 | P32: =Generator!L33 -> 6643 | Q32: =Generator!P33 -> 8684 | R32: =Generator!T33 -> 6541 | S32: =Generator!X33 -> 11028 | T32: =23.84/13.49 -> 1.767235 | U32: 522.71 | V32: 1.84 | W32: ='RO Plant'!B33 -> 21 | X32: ='RO Plant'!C33 -> 35 | Y32: ='RO Plant'!D33 -> 164 | Z32: ='RO Plant'!E33 -> 149 | AA32: ='RO Plant'!F33 -> 106 | AB32: ='RO Plant'!G33 -> 87 | AC32: ='RO Plant'!H33 -> 85 | AG32: =AH32-AH31 -> 105 | AH32: 58466
A33: 44926 | B33: 79.2 | C33: 741 | D33: ='EMS Gridvis'!B32 -> 2.9341379 | E33: ='EMS Gridvis'!C32 -> 4.3851724 | F33: ='EMS Gridvis'!D32 -> 5.8037931 | G33: ='EMS Gridvis'!E32 -> 2.0958621 | H33: ='EMS Gridvis'!F32 -> 2.5265517 | I33: ='EMS Gridvis'!G32 -> 2.1560714 | J33: ='EMS Gridvis'!H32 -> 1.3347241 | K33: ='EMS Gridvis'!I32 -> 1.7037931 | ... M33: ='EMS Gridvis'!K32 -> 0 | N33: =Generator!D34 -> 9930 | O33: =Generator!H34 -> 9817 | P33: =Generator!L34 -> 6672 | Q33: =Generator!P34 -> 7190 | R33: =Generator!T34 -> 6575 | S33: =Generator!X34 -> 8845 | T33: =23.84/13.49 -> 1.767235 | U33: 522.71 | V33: 1.84 | W33: ='RO Plant'!B34 -> 65.504938 | X33: ='RO Plant'!C34 -> 28.708333 | Y33: ='RO Plant'!D34 -> 152.32708 | Z33: ='RO Plant'!E34 -> 131.58222 | AA33: ='RO Plant'!F34 -> 84.389583 | AB33: ='RO Plant'!G34 -> 20.633333 | AC33: ='RO Plant'!H34 -> 95.614583 | AG33: =AVERAGE(AG3:AG32) -> 136.43333 | AH33: 58602
B35: Sum per SS MWH | D35: =SUM(D3:D33) -> 90.958276 | E35: =SUM(E3:E33) -> 135.94034 | F35: =SUM(F3:F33) -> 179.91759 | G35: =SUM(G3:G33) -> 64.971724 | H35: =SUM(H3:H33) -> 78.323103 | I35: =SUM(I3:I33) -> 75.4625 | J35: =SUM(J3:J33) -> 41.376448 | K35: =SUM(K3:K33) -> 52.817586 | ... M35: =SUM(M3:M33) -> 0 | W35: =SUM(W33:AC33) -> 578.76008 | AE35: =SUM(AF15,AF10) -> 5061
B36: Sum per SS KWH | D36: =D35*1000 -> 90958.276 | E36: =E35*1000 -> 135940.34 | F36: =F35*1000 -> 179917.59 | G36: =G35*1000 -> 64971.724 | H36: =H35*1000 -> 78323.103 | I36: =I35*1000 -> 75462.5 | J36: =J35*1000 -> 41376.448 | K36: =K35*1000 -> 52817.586 | ... M36: =M35*1000 -> 0
B37: Sum total SS KWH | D37: =SUM(D36:L36) -> 839876.53

Sheet RO Plant
A1: Location | B1: BOH | C1: E-Resort | D1: North RVs | E1: Kannel,300,400,500,600,SRV,300,400 | F1: Zez,SPA,MV,100,200 | G1: From E-Resort | H1: BOH | I1: SRV | M1: Formula
A2: DATE | B2: BOH Water (m3) | C2: E-Resort (m3) | D2: North RVs (m3) | E2: WT59 (m3) | F2: WT08 (m3) | G2: PUC (E- Resort) (m3) | H2: PUC HOH (m3) | I2: PUC HOH (m3) | J2: PUC HOH (m3) | K2: PUC HOH (m3) | L2: PUC HOH (m3) | M2: PUC HOH (m3) | N2: PUC HOH (m3) | O2: Remarks
A3: Average reading | B3: 60.633333 | C3: 32.333333 | D3: 133.03333 | E3: 168.23333 | F3: 76.666667 | G3: 13.166667 | H3: 93.233333 | I3: 12.566667 | J3: 35.666667 | K3: 24.733333
A4: 44896 | B4: 60 | C4: 24 | D4: 214 | E4: 152 | F4: 71 | G4: 0 | H4: 100 | I4: 13 | J4: 32 | K4: 29 | M4: =J4-(I4+K4) -> -10 | N4: =M4 -> -10
A5: 44897 | B5: 58 | C5: 14 | D5: 135 | E5: 97 | F5: 75 | G5: 0 | H5: 100 | I5: 0 | J5: 28 | K5: 27 | M5: =J5-(I5+K5) -> 1 | N5: =M5 -> 1
A6: 44898 | B6: 57 | C6: 31 | D6: 125 | E6: 67 | F6: 87 | G6: 0 | H6: 102 | I6: 10 | J6: 38 | K6: 22 | M6: =J6-(I6+K6) -> 6 | N6: =M6 -> 6
A7: 44899 | B7: 71 | C7: 22 | D7: 139 | E7: 145 | F7: 63 | G7: 0 | H7: 98 | I7: 14 | J7: 34 | K7: 27 | M7: =J7-(I7+K7) -> -7 | N7: =M7 -> -7
A8: 44900 | B8: 60 | C8: 28 | D8: 141 | E8: 155 | F8: 71 | G8: 0 | H8: 101 | I8: 19 | J8: 46 | K8: 51 | M8: =J8-(I8+K8) -> -24 | N8: =M8 -> -24
A9: 44901 | B9: 62 | C9: 34 | D9: 164 | E9: 101 | F9: 69 | G9: 0 | H9: 103 | I9: 11 | J9: 48 | K9: 27 | M9: =J9-(I9+K9) -> 10 | N9: =M9 -> 10
A10: 44902 | B10: 63 | C10: 21 | D10: 166 | E10: 93 | F10: 73 | G10: 0 | H10: 103 | I10: 12 | J10: 39 | K10: 28 | M10: =J10-(I10+K10) -> -1 | N10: =M10 -> -1
A11: 44903 | B11: 61 | C11: 23 | D11: 166 | E11: 167 | F11: 84 | G11: 0 | H11: 107 | I11: 16 | J11: 64 | K11: 38 | M11: =J11-(I11+K11) -> 10 | N11: =M11 -> 10
A12: 44904 | B12: 65 | C12: 37 | D12: 130 | E12: 143 | F12: 61 | G12: 0 | H12: 73 | I12: 14 | J12: 34 | K12: 19 | M12: =J12-(I12+K12) -> 1 | N12: =M12 -> 1
A13: 44905 | B13: 60 | C13: 38 | D13: 159 | E13: 118 | F13: 67 | G13: 0 | H13: 97 | I13: 9 | J13: 37 | K13: 21 | M13: =J13-(I13+K13) -> 7 | N13: =M13 -> 7
A14: 44906 | B14: 59 | C14: 22 | D14: 160 | E14: 138 | F14: 78 | G14: 0 | H14: 104 | I14: 7 | J14: 46 | K14: 21 | M14: =J14-(I14+K14) -> 18 | N14: =M14 -> 18
A15: 44907 | B15: 68 | C15: 34 | D15: 170 | E15: 142 | F15: 99 | G15: 0 | H15: 92 | I15: 14 | J15: 42 | K15: 31 | M15: =J15-(I15+K15) -> -3 | N15: =M15 -> -3
... A18: 44910 | B18: 68 | C18: 27 | D18: 161 | E18: 123 | F18: 86 | G18: 74 | H18: 104 | I18: 1 | J18: 48 | K18: 27 | M18: =J18-(I18+K18) -> 20 | N18: =M18 -> 20
