Workbook

Sheet TOTAL
A1: Site Name | B1: Day | C1: Month | D1: Year | E1: Total Electricity Kwh | F1: Electricity Tariff ($/Kwh) | G1: Natual Gas (m3) | H1: Natural Gas $/m3 | I1: Water Utility Supply (m3) m3 | J1: Water Utility Supply (m3) $/m3 | K1: Room Nights | L1: Total Guests | M1: Utilities day cost dh
A2: Mumbai | B2: 1 | C2: 1 | D2: 2023 | E2: =(IF('Daily HLP'!H4>0,'Daily HLP'!H4,0)) -> 21364 | F2: 10 | G2: =(IF('Daily HLP'!L4>0,'Daily HLP'!L4,0)) -> 1177.142 | H2: 66 | I2: =(IF('Daily HLP'!O4>0,'Daily HLP'!O4,0)) -> 278 | J2: 100 | M2: =E2*F2+G2*H2+#REF!*#REF!+I2*J2 -> #REF!
A3: Mumbai | B3: =B2+1 -> 2 | C3: 1 | D3: 2023 | E3: =(IF('Daily HLP'!H5>0,'Daily HLP'!H5,0)) -> 20873 | F3: 10 | G3: =(IF('Daily HLP'!L5>0,'Daily HLP'!L5,0)) -> 1199.5 | H3: 66 | I3: =(IF('Daily HLP'!O5>0,'Daily HLP'!O5,0)) -> 278 | J3: 100 | M3: =E3*F3+G3*H3+#REF!*#REF!+I3*J3 -> #REF!
A4: Mumbai | B4: =B3+1 -> 3 | C4: 1 | D4: 2023 | E4: =(IF('Daily HLP'!H6>0,'Daily HLP'!H6,0)) -> 21837 | F4: 10 | G4: =(IF('Daily HLP'!L6>0,'Daily HLP'!L6,0)) -> 1202 | H4: 66 | I4: =(IF('Daily HLP'!O6>0,'Daily HLP'!O6,0)) -> 322 | J4: 100 | M4: =E4*F4+G4*H4+#REF!*#REF!+I4*J4 -> #REF!
A5: Mumbai | B5: =B4+1 -> 4 | C5: 1 | D5: 2023 | E5: =(IF('Daily HLP'!H7>0,'Daily HLP'!H7,0)) -> 21196 | F5: 10 | G5: =(IF('Daily HLP'!L7>0,'Daily HLP'!L7,0)) -> 1072 | H5: 66 | I5: =(IF('Daily HLP'!O7>0,'Daily HLP'!O7,0)) -> 267 | J5: 100 | M5: =E5*F5+G5*H5+#REF!*#REF!+I5*J5 -> #REF!
A6: Mumbai | B6: =B5+1 -> 5 | C6: 1 | D6: 2023 | E6: =(IF('Daily HLP'!H8>0,'Daily HLP'!H8,0)) -> 21078 | F6: 10 | G6: =(IF('Daily HLP'!L8>0,'Daily HLP'!L8,0)) -> 1031 | H6: 66 | I6: =(IF('Daily HLP'!O8>0,'Daily HLP'!O8,0)) -> 183 | J6: 100 | M6: =E6*F6+G6*H6+#REF!*#REF!+I6*J6 -> #REF!
A7: Mumbai | B7: =B6+1 -> 6 | C7: 1 | D7: 2023 | E7: =(IF('Daily HLP'!H9>0,'Daily HLP'!H9,0)) -> 20586 | F7: 10 | G7: =(IF('Daily HLP'!L9>0,'Daily HLP'!L9,0)) -> 1061 | H7: 66 | I7: =(IF('Daily HLP'!O9>0,'Daily HLP'!O9,0)) -> 306 | J7: 100 | M7: =E7*F7+G7*H7+#REF!*#REF!+I7*J7 -> #REF!
A8: Mumbai | B8: =B7+1 -> 7 | C8: 1 | D8: 2023 | E8: =(IF('Daily HLP'!H10>0,'Daily HLP'!H10,0)) -> 21581 | F8: 10 | G8: =(IF('Daily HLP'!L10>0,'Daily HLP'!L10,0)) -> 1141 | H8: 66 | I8: =(IF('Daily HLP'!O10>0,'Daily HLP'!O10,0)) -> 224 | J8: 100 | M8: =E8*F8+G8*H8+#REF!*#REF!+I8*J8 -> #REF!
A9: Mumbai | B9: =B8+1 -> 8 | C9: 1 | D9: 2023 | E9: =(IF('Daily HLP'!H11>0,'Daily HLP'!H11,0)) -> 21598 | F9: 10 | G9: =(IF('Daily HLP'!L11>0,'Daily HLP'!L11,0)) -> 1112 | H9: 66 | I9: =(IF('Daily HLP'!O11>0,'Daily HLP'!O11,0)) -> 297 | J9: 100 | M9: =E9*F9+G9*H9+#REF!*#REF!+I9*J9 -> #REF!
A10: Mumbai | B10: =B9+1 -> 9 | C10: 1 | D10: 2023 | E10: =(IF('Daily HLP'!H12>0,'Daily HLP'!H12,0)) -> 20473 | F10: 10 | G10: =(IF('Daily HLP'!L12>0,'Daily HLP'!L12,0)) -> 1155 | H10: 66 | I10: =(IF('Daily HLP'!O12>0,'Daily HLP'!O12,0)) -> 243 | J10: 100 | M10: =E10*F10+G10*H10+#REF!*#REF!+I10*J10 -> #REF!
A11: Mumbai | B11: =B10+1 -> 10 | C11: 1 | D11: 2023 | E11: =(IF('Daily HLP'!H13>0,'Daily HLP'!H13,0)) -> 21756 | F11: 10 | G11: =(IF('Daily HLP'!L13>0,'Daily HLP'!L13,0)) -> 1088 | H11: 66 | I11: =(IF('Daily HLP'!O13>0,'Daily HLP'!O13,0)) -> 258 | J11: 100 | M11: =E11*F11+G11*H11+#REF!*#REF!+I11*J11 -> #REF!
A12: Mumbai | B12: =B11+1 -> 11 | C12: 1 | D12: 2023 | E12: =(IF('Daily HLP'!H14>0,'Daily HLP'!H14,0)) -> 21784 | F12: 10 | G12: =(IF('Daily HLP'!L14>0,'Daily HLP'!L14,0)) -> 1166.458 | H12: 66 | I12: =(IF('Daily HLP'!O14>0,'Daily HLP'!O14,0)) -> 310 | J12: 100 | M12: =E12*F12+G12*H12+#REF!*#REF!+I12*J12 -> #REF!
A13: Mumbai | B13: =B12+1 -> 12 | C13: 1 | D13: 2023 | E13: =(IF('Daily HLP'!H15>0,'Daily HLP'!H15,0)) -> 21436 | F13: 10 | G13: =(IF('Daily HLP'!L15>0,'Daily HLP'!L15,0)) -> 1163.522 | H13: 66 | I13: =(IF('Daily HLP'!O15>0,'Daily HLP'!O15,0)) -> 245 | J13: 100 | M13: =E13*F13+G13*H13+#REF!*#REF!+I13*J13 -> #REF!
A14: Mumbai | B14: =B13+1 -> 13 | C14: 1 | D14: 2023 | E14: =(IF('Daily HLP'!H16>0,'Daily HLP'!H16,0)) -> 22115 | F14: 10 | G14: =(IF('Daily HLP'!L16>0,'Daily HLP'!L16,0)) -> 1140.02 | H14: 66 | I14: =(IF('Daily HLP'!O16>0,'Daily HLP'!O16,0)) -> 223 | J14: 100 | M14: =E14*F14+G14*H14+#REF!*#REF!+I14*J14 -> #REF!
... A31: Mumbai | B31: =B30+1 -> 30 | C31: 1 | D31: 2023 | E31: =(IF('Daily HLP'!H33>0,'Daily HLP'!H33,0)) -> 21529.17 | F31: 10 | G31: =(IF('Daily HLP'!L33>0,'Daily HLP'!L33,0)) -> 1214.29 | H31: 66 | I31: =(IF('Daily HLP'!O33>0,'Daily HLP'!O33,0)) -> 363 | J31: 100 | M31: =E31*F31+G31*H31+#REF!*#REF!+I31*J31 -> #REF!
A32: Mumbai | B32: =B31+1 -> 31 | C32: 1 | D32: 2023 | E32: =(IF('Daily HLP'!H34>0,'Daily HLP'!H34,0)) -> 22341.83 | F32: 10 | G32: =(IF('Daily HLP'!L34>0,'Daily HLP'!L34,0)) -> 1090.358 | H32: 66 | I32: =(IF('Daily HLP'!O34>0,'Daily HLP'!O34,0)) -> 228 | J32: 100

Sheet Submetering
A1: Site Name | B1: Day | C1: Month | D1: Year | E1: ='Section Load'!F4 -> HVAC | F1: ='Section Load'!G4 -> Fire & Emergency PP | G1: ='Section Load'!H4 -> Main PP | H1: ='Section Load'!I4 -> Lighting PP | I1: ='Section Load'!J4 -> CH-1+ CH2+CH3+CH4 | J1: ='Section Load'!K4 -> Chilled water Pump | K1: ='Section Load'!L4 -> Ball Room-1 | L1: ='Section Load'!M4 -> Ball Room-2 | ... AL1: ='Section Load'!AM4 -> Cooling Tower | AM1: R.o.plant | AN1: STP Water Prod | AO1: Domestic Zone-1 | AP1: Domestic Zone-2 | AQ1: Domestic Zone-3 | AR1: Flush Zone -1 | AS1: Flush Zone -2 | AT1: Flush Zone -3 | AU1: Swimming pool | AV1: B2 Laundry | AW1: Boiler Feed Water | AX1: cooling tower filling water | AY1: STP flush(new water meter) | AZ1: Garden Water Pump | BA1: Flush Zone 2 pump meter | BB1: Flush Zone 3 Pump Meter (wtp transfer ) | BC1: Flush Tanker-Zone-1 | BD1: Total Domestic Water (Tanker (R.O) +BMC) | BE1: Total Domestic Consumption | BF1: Total STP Consumption | BG1: ='Section Load'!AN4 -> MGL | BH1: ='Section Load'!AO4 -> HWG | BI1: ='Section Load'!AP4 -> Prato | BJ1: ='Section Load'!AQ4 -> BR-1 | BK1: ='Section Load'!AR4 -> SanQi IND | BL1: ='Section Load'!AS4 -> SanQi JPN | BM1: ='Section Load'!AT4 -> Boiler
A2: Mumbai | B2: 1 | C2: 1 | D2: 2023 | E2: =(IF('Section Load'!F5>0,'Section Load'!F5,0)) -> 3465.01 | F2: =(IF('Section Load'!G5>0,'Section Load'!G5,0)) -> 1430.4 | G2: =(IF('Section Load'!H5>0,'Section Load'!H5,0)) -> 420.64 | H2: =(IF('Section Load'!I5>0,'Section Load'!I5,0)) -> 2801.99 | I2: =(IF('Section Load'!J5>0,'Section Load'!J5,0)) -> 4210.54 | J2: =(IF('Section Load'!K5>0,'Section Load'!K5,0)) -> 2505.35 | K2: =(IF('Section Load'!L5>0,'Section Load'!L5,0)) -> 1374.79 | L2: =(IF('Section Load'!M5>0,'Section Load'!M5,0)) -> 947.57 | ... AL2: =(IF('Section Load'!AM5>0,'Section Load'!AM5,0)) -> 761 | AM2: =(IF('Water Report'!$D$7>0,'Water Report'!$D$7,0)) -> 91.5 | AN2: =(IF('Water Report'!$D$8>0,'Water Report'!$D$8,0)) -> 101 | AO2: =(IF('Water Report'!$D$9>0,'Water Report'!$D$9,0)) -> 127 | AP2: =(IF('Water Report'!$D$10>0,'Water Report'!$D$10,0)) -> 12 | AQ2: =(IF('Water Report'!$D$11>0,'Water Report'!$D$11,0)) -> 32 | AR2: =(IF('Water Report'!$D$13>0,'Water Report'!$D$13,0)) -> 20 | AS2: =(IF('Water Report'!$D$14>0,'Water Report'!$D$14,0)) -> 13 | AT2: =(IF('Water Report'!$D$15>0,'Water Report'!$D$15,0)) -> 10 | AU2: =(IF('Water Report'!$D$17>0,'Water Report'!$D$17,0)) -> 1 | AV2: =(IF('Water Report'!$D$18>0,'Water Report'!$D$18,0)) -> 0 | AW2: =(IF('Water Report'!$D$19>0,'Water Report'!$D$19,0)) -> 14 | AX2: =(IF('Water Report'!$D$21>0,'Water Report'!$D$21,0)) -> 109 | AY2: =(IF('Water Report'!$D$22>0,'Water Report'!$D$22,0)) -> 0 | AZ2: =(IF('Water Report'!$D$23>0,'Water Report'!$D$23,0)) -> 0 | BA2: =(IF('Water Report'!$D$14>0,'Water Report'!$D$14,0)) -> 13 | BB2: =(IF('Water Report'!$D$15>0,'Water Report'!$D$15,0)) -> 10 | BC2: =(IF('Water Report'!$D$13>0,'Water Report'!$D$13,0)) -> 20 | BD2: =(IF('Water Report'!$D$24>0,'Water Report'!$D$24,0)) -> 278 | BE2: =(IF('Water Report'!$D$25>0,'Water Report'!$D$25,0)) -> 194 | BF2: =(IF('Water Report'!$D$27>0,'Water Report'!$D$27,0)) -> 129 | BG2: =(IF('Section Load'!AN5>0,'Section Load'!AN5,0)) -> 1177.142 | BH2: =(IF('Section Load'!AO5>0,'Section Load'!AO5,0)) -> 316 | BI2: =(IF('Section Load'!AP5>0,'Section Load'!AP5,0)) -> 0 | BJ2: =(IF('Section Load'!AQ5>0,'Section Load'!AQ5,0)) -> 120 | BK2: =(IF('Section Load'!AR5>0,'Section Load'!AR5,0)) -> 59 | BL2: =(IF('Section Load'!AS5>0,'Section Load'!AS5,0)) -> 0 | BM2: =(IF('Section Load'!AT5>0,'Section Load'!AT5,0)) -> 682.642
A3: Mumbai | B3: =B2+1 -> 2 | C3: 1 | D3: 2023 | E3: =(IF('Section Load'!F6>0,'Section Load'!F6,0)) -> 3053.12 | F3: =(IF('Section Load'!G6>0,'Section Load'!G6,0)) -> 1463.93 | G3: =(IF('Section Load'!H6>0,'Section Load'!H6,0)) -> 2497.28 | H3: =(IF('Section Load'!I6>0,'Section Load'!I6,0)) -> 2851.56 | I3: =(IF('Section Load'!J6>0,'Section Load'!J6,0)) -> 4203.27 | J3: =(IF('Section Load'!K6>0,'Section Load'!K6,0)) -> 2410.08 | K3: =(IF('Section Load'!L6>0,'Section Load'!L6,0)) -> 1219.72 | L3: =(IF('Section Load'!M6>0,'Section Load'!M6,0)) -> 989.76 | ... AL3: =(IF('Section Load'!AM6>0,'Section Load'!AM6,0)) -> 694 | AM3: =(IF('Water Report'!$E$7>0,'Water Report'!$E$7,0)) -> 90 | AN3: =(IF('Water Report'!$E$8>0,'Water Report'!$E$8,0)) -> 110 | AO3: =(IF('Water Report'!$E$9>0,'Water Report'!$E$9,0)) -> 124 | AP3: =(IF('Water Report'!$E$10>0,'Water Report'!$E$10,0)) -> 13 | AQ3: =(IF('Water Report'!$E$11>0,'Water Report'!$E$11,0)) -> 22 | AR3: =(IF('Water Report'!$E$13>0,'Water Report'!$E$13,0)) -> 4 | AS3: =(IF('Water Report'!$E$14>0,'Water Report'!$E$14,0)) -> 8 | AT3: =(IF('Water Report'!$E$15>0,'Water Report'!$E$15,0)) -> 7 | AU3: =(IF('Water Report'!$E$17>0,'Water Report'!$E$17,0)) -> 1 | AV3: =(IF('Water Report'!$E$18>0,'Water Report'!$E$18,0)) -> 13 | AW3: =(IF('Water Report'!$E$19>0,'Water Report'!$E$19,0)) -> 18 | AX3: =(IF('Water Report'!$E$21>0,'Water Report'!$E$21,0)) -> 100 | AY3: =(IF('Water Report'!$E$22>0,'Water Report'!$E$22,0)) -> 0 | AZ3: =(IF('Water Report'!$E$23>0,'Water Report'!$E$23,0)) -> 11 | BA3: =(IF('Water Report'!$E$14>0,'Water Report'!$E$14,0)) -> 8 | BB3: =(IF('Water Report'!$E$15>0,'Water Report'!$E$15,0)) -> 7 | BC3: =(IF('Water Report'!$E$13>0,'Water Report'!$E$13,0)) -> 4 | BD3: =(IF('Water Report'!$E$24>0,'Water Report'!$E$24,0)) -> 278 | BE3: =(IF('Water Report'!$E$25>0,'Water Report'!$E$25,0)) -> 174 | BF3: =(IF('Water Report'!$E$27>0,'Water Report'!$E$27,0)) -> 115 | BG3: =(IF('Section Load'!AN6>0,'Section Load'!AN6,0)) -> 1199.5 | BH3: =(IF('Section Load'!AO6>0,'Section Load'!AO6,0)) -> 359.82 | BI3: =(IF('Section Load'!AP6>0,'Section Load'!AP6,0)) -> 0 | BJ3: =(IF('Section Load'!AQ6>0,'Section Load'!AQ6,0)) -> 104 | BK3: =(IF('Section Load'!AR6>0,'Section Load'!AR6,0)) -> 47 | BL3: =(IF('Section Load'!AS6>0,'Section Load'!AS6,0)) -> 0 | BM3: =(IF('Section Load'!AT6>0,'Section Load'!AT6,0)) -> 688.68
A4: Mumbai | B4: =B3+1 -> 3 | C4: 1 | D4: 2023 | E4: =(IF('Section Load'!F7>0,'Section Load'!F7,0)) -> 3487.88 | F4: =(IF('Section Load'!G7>0,'Section Load'!G7,0)) -> 1407.87 | G4: =(IF('Section Load'!H7>0,'Section Load'!H7,0)) -> 2529.35 | H4: =(IF('Section Load'!I7>0,'Section Load'!I7,0)) -> 2805.49 | I4: =(IF('Section Load'!J7>0,'Section Load'!J7,0)) -> 4668.11 | J4: =(IF('Section Load'!K7>0,'Section Load'!K7,0)) -> 2365.68 | K4: =(IF('Section Load'!L7>0,'Section Load'!L7,0)) -> 1788.39 | L4: =(IF('Section Load'!M7>0,'Section Load'!M7,0)) -> 938.44 | ... AL4: =(IF('Section Load'!AM7>0,'Section Load'!AM7,0)) -> 0 | AM4: =(IF('Water Report'!$F$7>0,'Water Report'!$F$7,0)) -> 158 | AN4: =(IF('Water Report'!$F$8>0,'Water Report'!$F$8,0)) -> 91 | AO4: =(IF('Water Report'!$F$9>0,'Water Report'!$G$9,0)) -> 102 | AP4: =(IF('Water Report'!$F$10>0,'Water Report'!$F$10,0)) -> 12 | AQ4: =(IF('Water Report'!$F$11>0,'Water Report'!$F$11,0)) -> 25 | AR4: =(IF('Water Report'!$F$13>0,'Water Report'!$F$13,0)) -> 24 | AS4: =(IF('Water Report'!$F$14>0,'Water Report'!$F$14,0)) -> 7 | AT4: =(IF('Water Report'!$F$15>0,'Water Report'!$F$15,0)) -> 7 | AU4: =(IF('Water Report'!$F$17>0,'Water Report'!$F$17,0)) -> 2 | AV4: =(IF('Water Report'!$F$18>0,'Water Report'!$F$18,0)) -> 13 | AW4: =(IF('Water Report'!$F$19>0,'Water Report'!$F$19,0)) -> 17 | AX4: =(IF('Water Report'!$F$21>0,'Water Report'!$F$21,0)) -> 115 | AY4: =(IF('Water Report'!$F$22>0,'Water Report'!$F$22,0)) -> 0 | AZ4: =(IF('Water Report'!$F$23>0,'Water Report'!$F$23,0)) -> 0 | BA4: =(IF('Water Report'!$F$14>0,'Water Report'!$F$14,0)) -> 7 | BB4: =(IF('Water Report'!$F$15>0,'Water Report'!$F$15,0)) -> 7 | BC4: =(IF('Water Report'!$F$13>0,'Water Report'!$F$13,0)) -> 24 | BD4: =(IF('Water Report'!$F$24>0,'Water Report'!$F$24,0)) -> 322 | BE4: =(IF('Water Report'!$F$25>0,'Water Report'!$F$25,0)) -> 176 | BF4: =(IF('Water Report'!$F$27>0,'Water Report'!$F$27,0)) -> 139 | BG4: =(IF('Section Load'!AN7>0,'Section Load'!AN7,0)) -> 1202 | BH4: =(IF('Section Load'!AO7>0,'Section Load'!AO7,0)) -> 296.94 | BI4: =(IF('Section Load'!AP7>0,'Section Load'!AP7,0)) -> 0 | BJ4: =(IF('Section Load'!AQ7>0,'Section Load'!AQ7,0)) -> 115 | BK4: =(IF('Section Load'!AR7>0,'Section Load'!AR7,0)) -> 42 | BL4: =(IF('Section Load'!AS7>0,'Section Load'!AS7,0)) -> 0 | BM4: =(IF('Section Load'!AT7>0,'Section Load'!AT7,0)) -> 748.06
A5: Mumbai | B5: =B4+1 -> 4 | C5: 1 | D5: 2023 | E5: =(IF('Section Load'!F8>0,'Section Load'!F8,0)) -> 2814.85 | F5: =(IF('Section Load'!G8>0,'Section Load'!G8,0)) -> 1416.93 | G5: =(IF('Section Load'!H8>0,'Section Load'!H8,0)) -> 2404.13 | H5: =(IF('Section Load'!I8>0,'Section Load'!I8,0)) -> 2869.93 | I5: =(IF('Section Load'!J8>0,'Section Load'!J8,0)) -> 4497.06 | J5: =(IF('Section Load'!K8>0,'Section Load'!K8,0)) -> 2309.89 | K5: =(IF('Section Load'!L8>0,'Section Load'!L8,0)) -> 1602.1 | L5: =(IF('Section Load'!M8>0,'Section Load'!M8,0)) -> 750.43 | ... AL5: =(IF('Section Load'!AM8>0,'Section Load'!AM8,0)) -> 0 | AM5: =(IF('Water Report'!$G$7>0,'Water Report'!$F$7,0)) -> 158 | AN5: =(IF('Water Report'!$G$8>0,'Water Report'!$F$8,0)) -> 91 | AO5: =(IF('Water Report'!$G$9>0,'Water Report'!$H$9,0)) -> 118 | AP5: =(IF('Water Report'!$G$10>0,'Water Report'!$G$10,0)) -> 19 | AQ5: =(IF('Water Report'!$G$11>0,'Water Report'!$G$11,0)) -> 19 | AR5: =(IF('Water Report'!$G$13>0,'Water Report'!$G$13,0)) -> 30 | AS5: =(IF('Water Report'!$G$14>0,'Water Report'!$G$14,0)) -> 0 | AT5: =(IF('Water Report'!$G$15>0,'Water Report'!$G$15,0)) -> 7 | AU5: =(IF('Water Report'!$G$17>0,'Water Report'!$G$17,0)) -> 2 | AV5: =(IF('Water Report'!$G$18>0,'Water Report'!$G$18,0)) -> 13 | AW5: =(IF('Water Report'!$G$19>0,'Water Report'!$G$19,0)) -> 14 | AX5: =(IF('Water Report'!$G$21>0,'Water Report'!$G$21,0)) -> 119 | AY5: =(IF('Water Report'!$G$22>0,'Water Report'!$G$22,0)) -> 0 | AZ5: =(IF('Water Report'!$G$23>0,'Water Report'!$G$23,0)) -> 0 | BA5: =(IF('Water Report'!$G$14>0,'Water Report'!$G$14,0)) -> 0 | BB5: =(IF('Water Report'!$G$15>0,'Water Report'!$G$15,0)) -> 7 | BC5: =(IF('Water Report'!$G$13>0,'Water Report'!$G$13,0)) -> 30 | BD5: =(IF('Water Report'!$G$24>0,'Water Report'!$G$24,0)) -> 267 | BE5: =(IF('Water Report'!$G$25>0,'Water Report'!$G$25,0)) -> 147 | BF5: =(IF('Water Report'!$G$27>0,'Water Report'!$G$27,0)) -> 149 | BG5: =(IF('Section Load'!AN8>0,'Section Load'!AN8,0)) -> 1072 | BH5: =(IF('Section Load'!AO8>0,'Section Load'!AO8,0)) -> 303.24 | BI5: =(IF('Section Load'!AP8>0,'Section Load'!AP8,0)) -> 0 | BJ5: =(IF('Section Load'!AQ8>0,'Section Load'!AQ8,0)) -> 65 | BK5: =(IF('Section Load'!AR8>0,'Section Load'!AR8,0)) -> 61 | BL5: =(IF('Section Load'!AS8>0,'Section Load'!AS8,0)) -> 0 | BM5: =(IF('Section Load'!AT8>0,'Section Load'!AT8,0)) -> 643.26
A6: Mumbai | B6: =B5+1 -> 5 | C6: 1 | D6: 2023 | E6: =(IF('Section Load'!F9>0,'Section Load'!F9,0)) -> 3067 | F6: =(IF('Section Load'!G9>0,'Section Load'!G9,0)) -> 1489 | G6: =(IF('Section Load'!H9>0,'Section Load'!H9,0)) -> 2509.01 | H6: =(IF('Section Load'!I9>0,'Section Load'!I9,0)) -> 2895 | I6: =(IF('Section Load'!J9>0,'Section Load'!J9,0)) -> 4539.2 | J6: =(IF('Section Load'!K9>0,'Section Load'!K9,0)) -> 2309 | K6: =(IF('Section Load'!L9>0,'Section Load'!L9,0)) -> 1163 | L6: =(IF('Section Load'!M9>0,'Section Load'!M9,0)) -> 820.9 | ... AL6: =(IF('Section Load'!AM9>0,'Section Load'!AM9,0)) -> 0 | AM6: =(IF('Water Report'!$H$7>0,'Water Report'!$H$7,0)) -> 124 | AN6: =(IF('Water Report'!$H$8>0,'Water Report'!$H$8,0)) -> 114 | AO6: =(IF('Water Report'!$H$9>0,'Water Report'!$H$9,0)) -> 118 | AP6: =(IF('Water Report'!$H$10>0,'Water Report'!$H$10,0)) -> 13 | AQ6: =(IF('Water Report'!$H$11>0,'Water Report'!$H$11,0)) -> 24 | AR6: =(IF('Water Report'!$H$13>0,'Water Report'!$H$13,0)) -> 22 | AS6: =(IF('Water Report'!$H$14>0,'Water Report'!$H$14,0)) -> 4 | AT6: =(IF('Water Report'!$H$15>0,'Water Report'!$H$15,0)) -> 6 | AU6: =(IF('Water Report'!$H$17>0,'Water Report'!$H$17,0)) -> 0 | AV6: =(IF('Water Report'!$H$18>0,'Water Report'!$H$18,0)) -> 19 | AW6: =(IF('Water Report'!$H$19>0,'Water Report'!$H$19,0)) -> 13 | AX6: =(IF('Water Report'!$H$21>0,'Water Report'!$H$21,0)) -> 133 | AY6: =(IF('Water Report'!$H$22>0,'Water Report'!$H$22,0)) -> 0 | AZ6: =(IF('Water Report'!$H$23>0,'Water Report'!$H$23,0)) -> 10 | BA6: =(IF('Water Report'!$H$14>0,'Water Report'!$H$14,0)) -> 4 | BB6: =(IF('Water Report'!$H$15>0,'Water Report'!$H$15,0)) -> 6 | BC6: =(IF('Water Report'!$H$13>0,'Water Report'!$H$13,0)) -> 22 | BD6: =(IF('Water Report'!$H$24>0,'Water Report'!$H$24,0)) -> 183 | BE6: =(IF('Water Report'!$H$25>0,'Water Report'!$H$25,0)) -> 165 | BF6: =(IF('Water Report'!$H$27>0,'Water Report'!$H$27,0)) -> 165 | BG6: =(IF('Section Load'!AN9>0,'Section Load'!AN9,0)) -> 1031 | BH6: =(IF('Section Load'!AO9>0,'Section Load'!AO9,0)) -> 303 | BI6: =(IF('Section Load'!AP9>0,'Section Load'!AP9,0)) -> 0 | BJ6: =(IF('Section Load'!AQ9>0,'Section Load'!AQ9,0)) -> 130 | BK6: =(IF('Section Load'!AR9>0,'Section Load'!AR9,0)) -> 43 | BL6: =(IF('Section Load'!AS9>0,'Section Load'!AS9,0)) -> 0.4 | BM6: =(IF('Section Load'!AT9>0,'Section Load'!AT9,0)) -> 554.6
A7: Mumbai | B7: =B6+1 -> 6 | C7: 1 | D7: 2023 | E7: =(IF('Section Load'!F10>0,'Section Load'!F10,0)) -> 2935 | F7: =(IF('Section Load'!G10>0,'Section Load'!G10,0)) -> 1465 | G7: =(IF('Section Load'!H10>0,'Section Load'!H10,0)) -> 2505 | H7: =(IF('Section Load'!I10>0,'Section Load'!I10,0)) -> 2773 | I7: =(IF('Section Load'!J10>0,'Section Load'!J10,0)) -> 4307 | J7: =(IF('Section Load'!K10>0,'Section Load'!K10,0)) -> 2270 | K7: =(IF('Section Load'!L10>0,'Section Load'!L10,0)) -> 1228 | L7: =(IF('Section Load'!M10>0,'Section Load'!M10,0)) -> 849 | ... AL7: =(IF('Section Load'!AM10>0,'Section Load'!AM10,0)) -> 0 | AM7: =(IF('Water Report'!$I$7>0,'Water Report'!$I$7,0)) -> 114 | AN7: =(IF('Water Report'!$I$8>0,'Water Report'!$I$8,0)) -> 114 | AO7: =(IF('Water Report'!$I$9>0,'Water Report'!$I$9,0)) -> 146 | AP7: =(IF('Water Report'!$I$10>0,'Water Report'!$I$10,0)) -> 16 | AQ7: =(IF('Water Report'!$I$11>0,'Water Report'!$I$11,0)) -> 30 | AR7: =(IF('Water Report'!$I$13>0,'Water Report'!$I$13,0)) -> 21 | AS7: =(IF('Water Report'!$I$14>0,'Water Report'!$I$14,0)) -> 4 | AT7: =(IF('Water Report'!$I$15>0,'Water Report'!$I$15,0)) -> 11 | AU7: =(IF('Water Report'!$I$17>0,'Water Report'!$I$17,0)) -> 1 | AV7: =(IF('Water Report'!$I$18>0,'Water Report'!$I$18,0)) -> 12 | AW7: =(IF('Water Report'!$I$19>0,'Water Report'!$I$19,0)) -> 13 | AX7: =(IF('Water Report'!$I$21>0,'Water Report'!$I$21,0)) -> 157 | AY7: =(IF('Water Report'!$I$22>0,'Water Report'!$I$22,0)) -> 0 | AZ7: =(IF('Water Report'!$I$23>0,'Water Report'!$I$23,0)) -> 7 | BA7: =(IF('Water Report'!$I$14>0,'Water Report'!$I$14,0)) -> 4 | BB7: =(IF('Water Report'!$I$15>0,'Water Report'!$I$15,0)) -> 11 | BC7: =(IF('Water Report'!$I$13>0,'Water Report'!$I$13,0)) -> 21 | BD7: =(IF('Water Report'!$I$24>0,'Water Report'!$I$24,0)) -> 306 | BE7: =(IF('Water Report'!$I$25>0,'Water Report'!$I$25,0)) -> 207 | BF7: =(IF('Water Report'!$I$27>0,'Water Report'!$I$27,0)) -> 185 | BG7: =(IF('Section Load'!AN10>0,'Section Load'!AN10,0)) -> 1061 | BH7: =(IF('Section Load'!AO10>0,'Section Load'!AO10,0)) -> 307 | BI7: =(IF('Section Load'!AP10>0,'Section Load'!AP10,0)) -> 0 | BJ7: =(IF('Section Load'!AQ10>0,'Section Load'!AQ10,0)) -> 100 | BK7: =(IF('Section Load'!AR10>0,'Section Load'!AR10,0)) -> 52 | BL7: =(IF('Section Load'!AS10>0,'Section Load'!AS10,0)) -> 0 | BM7: =(IF('Section Load'!AT10>0,'Section Load'!AT10,0)) -> 602
A8: Mumbai | B8: =B7+1 -> 7 | C8: 1 | D8: 2023 | E8: =(IF('Section Load'!F11>0,'Section Load'!F11,0)) -> 2982 | F8: =(IF('Section Load'!G11>0,'Section Load'!G11,0)) -> 1528 | G8: =(IF('Section Load'!H11>0,'Section Load'!H11,0)) -> 2485 | H8: =(IF('Section Load'!I11>0,'Section Load'!I11,0)) -> 2864 | I8: =(IF('Section Load'!J11>0,'Section Load'!J11,0)) -> 4797 | J8: =(IF('Section Load'!K11>0,'Section Load'!K11,0)) -> 2251 | K8: =(IF('Section Load'!L11>0,'Section Load'!L11,0)) -> 1307 | L8: =(IF('Section Load'!M11>0,'Section Load'!M11,0)) -> 1091 | ... AL8: =(IF('Section Load'!AM11>0,'Section Load'!AM11,0)) -> 0 | AM8: =(IF('Water Report'!$J$7>0,'Water Report'!$J$7,0)) -> 66 | AN8: =(IF('Water Report'!$J$8>0,'Water Report'!$J$8,0)) -> 96 | AO8: =(IF('Water Report'!$J$9>0,'Water Report'!$J$9,0)) -> 123 | AP8: =(IF('Water Report'!$J$10>0,'Water Report'!$J$10,0)) -> 20 | AQ8: =(IF('Water Report'!$J$11>0,'Water Report'!$J$11,0)) -> 20 | AR8: =(IF('Water Report'!$J$13>0,'Water Report'!$J$13,0)) -> 24 | AS8: =(IF('Water Report'!$J$14>0,'Water Report'!$J$14,0)) -> 5 | AT8: =(IF('Water Report'!$J$15>0,'Water Report'!$J$15,0)) -> 5 | AU8: =(IF('Water Report'!$J$17>0,'Water Report'!$J$17,0)) -> 1 | AV8: =(IF('Water Report'!$J$18>0,'Water Report'!$J$18,0)) -> 11 | AW8: =(IF('Water Report'!$J$19>0,'Water Report'!$J$19,0)) -> 15 | AX8: =(IF('Water Report'!$J$21>0,'Water Report'!$J$21,0)) -> 87 | AY8: =(IF('Water Report'!$J$22>0,'Water Report'!$J$22,0)) -> 0 | AZ8: =(IF('Water Report'!$J$23>0,'Water Report'!$J$23,0)) -> 8 | BA8: =(IF('Water Report'!$J$14>0,'Water Report'!$J$14,0)) -> 5 | BB8: =(IF('Water Report'!$J$15>0,'Water Report'!$J$15,0)) -> 5 | BC8: =(IF('Water Report'!$J$13>0,'Water Report'!$J$13,0)) -> 24 | BD8: =(IF('Water Report'!$J$24>0,'Water Report'!$J$24,0)) -> 224 | BE8: =(IF('Water Report'!$J$25>0,'Water Report'!$J$25,0)) -> 173 | BF8: =(IF('Water Report'!$J$27>0,'Water Report'!$J$27,0)) -> 119 | BG8: =(IF('Section Load'!AN11>0,'Section Load'!AN11,0)) -> 1141 | BH8: =(IF('Section Load'!AO11>0,'Section Load'!AO11,0)) -> 307 | BI8: =(IF('Section Load'!AP11>0,'Section Load'!AP11,0)) -> 0 | BJ8: =(IF('Section Load'!AQ11>0,'Section Load'!AQ11,0)) -> 90 | BK8: =(IF('Section Load'!AR11>0,'Section Load'!AR11,0)) -> 47 | BL8: =(IF('Section Load'!AS11>0,'Section Load'!AS11,0)) -> 0 | BM8: =(IF('Section Load'!AT11>0,'Section Load'!AT11,0)) -> 697
A9: Mumbai | B9: =B8+1 -> 8 | C9: 1 | D9: 2023 | E9: =(IF('Section Load'!F12>0,'Section Load'!F12,0)) -> 3011 | F9: =(IF('Section Load'!G12>0,'Section Load'!G12,0)) -> 1552 | G9: =(IF('Section Load'!H12>0,'Section Load'!H12,0)) -> 2595 | H9: =(IF('Section Load'!I12>0,'Section Load'!I12,0)) -> 2814 | I9: =(IF('Section Load'!J12>0,'Section Load'!J12,0)) -> 4796 | J9: =(IF('Section Load'!K12>0,'Section Load'!K12,0)) -> 2385 | K9: =(IF('Section Load'!L12>0,'Section Load'!L12,0)) -> 1432 | L9: =(IF('Section Load'!M12>0,'Section Load'!M12,0)) -> 719 | ... AL9: =(IF('Section Load'!AM12>0,'Section Load'!AM12,0)) -> 0 | AM9: =(IF('Water Report'!$K$7>0,'Water Report'!$K$7,0)) -> 134 | AN9: =(IF('Water Report'!$K$8>0,'Water Report'!$K$8,0)) -> 108 | AO9: =(IF('Water Report'!$K$9>0,'Water Report'!$K$9,0)) -> 115 | AP9: =(IF('Water Report'!$K$10>0,'Water Report'!$K$10,0)) -> 441 | AQ9: =(IF('Water Report'!$K$11>0,'Water Report'!$K$11,0)) -> 23 | AR9: =(IF('Water Report'!$K$13>0,'Water Report'!$K$13,0)) -> 17 | AS9: =(IF('Water Report'!$K$14>0,'Water Report'!$K$14,0)) -> 4 | AT9: =(IF('Water Report'!$K$15>0,'Water Report'!$K$15,0)) -> 14 | AU9: =(IF('Water Report'!$K$17>0,'Water Report'!$K$17,0)) -> 0 | AV9: =(IF('Water Report'!$K$18>0,'Water Report'!$K$18,0)) -> 11 | AW9: =(IF('Water Report'!$K$19>0,'Water Report'!$K$19,0)) -> 14 | AX9: =(IF('Water Report'!$K$21>0,'Water Report'!$K$21,0)) -> 105 | AY9: =(IF('Water Report'!$K$22>0,'Water Report'!$K$22,0)) -> 0 | AZ9: =(IF('Water Report'!$K$23>0,'Water Report'!$K$23,0)) -> 0 | BA9: =(IF('Water Report'!$K$14>0,'Water Report'!$K$14,0)) -> 4 | BB9: =(IF('Water Report'!$K$15>0,'Water Report'!$K$15,0)) -> 14 | BC9: =(IF('Water Report'!$K$13>0,'Water Report'!$K$13,0)) -> 17 | BD9: =(IF('Water Report'!$K$24>0,'Water Report'!$K$24,0)) -> 297 | BE9: =(IF('Water Report'!$K$25>0,'Water Report'!$K$25,0)) -> 597 | BF9: =(IF('Water Report'!$K$27>0,'Water Report'!$K$27,0)) -> 122 | BG9: =(IF('Section Load'!AN12>0,'Section Load'!AN12,0)) -> 1112 | BH9: =(IF('Section Load'!AO12>0,'Section Load'!AO12,0)) -> 299 | BI9: =(IF('Section Load'!AP12>0,'Section Load'!AP12,0)) -> 0 | BJ9: =(IF('Section Load'!AQ12>0,'Section Load'!AQ12,0)) -> 106 | BK9: =(IF('Section Load'!AR12>0,'Section Load'!AR12,0)) -> 48 | BL9: =(IF('Section Load'!AS12>0,'Section Load'!AS12,0)) -> 0 | BM9: =(IF('Section Load'!AT12>0,'Section Load'!AT12,0)) -> 659
A10: Mumbai | B10: =B9+1 -> 9 | C10: 1 | D10: 2023 | E10: =(IF('Section Load'!F13>0,'Section Load'!F13,0)) -> 2914.72 | F10: =(IF('Section Load'!G13>0,'Section Load'!G13,0)) -> 1591.19 | G10: =(IF('Section Load'!H13>0,'Section Load'!H13,0)) -> 2560.43 | H10: =(IF('Section Load'!I13>0,'Section Load'!I13,0)) -> 2799.18 | I10: =(IF('Section Load'!J13>0,'Section Load'!J13,0)) -> 3941.31 | J10: =(IF('Section Load'!K13>0,'Section Load'!K13,0)) -> 2366.59 | K10: =(IF('Section Load'!L13>0,'Section Load'!L13,0)) -> 1264.7 | L10: =(IF('Section Load'!M13>0,'Section Load'!M13,0)) -> 829.67 | ... AL10: =(IF('Section Load'!AM13>0,'Section Load'!AM13,0)) -> 0.17 | AM10: =(IF('Water Report'!$L$7>0,'Water Report'!$L$7,0)) -> 141.9 | AN10: =(IF('Water Report'!$L$8>0,'Water Report'!$L$8,0)) -> 117 | AO10: =(IF('Water Report'!$L$9>0,'Water Report'!$L$9,0)) -> 135 | AP10: =(IF('Water Report'!$L$10>0,'Water Report'!$L$10,0)) -> 475 | AQ10: =(IF('Water Report'!$L$11>0,'Water Report'!$L$11,0)) -> 23 | AR10: =(IF('Water Report'!$L$13>0,'Water Report'!$L$13,0)) -> 15 | AS10: =(IF('Water Report'!$L$14>0,'Water Report'!$L$14,0)) -> 1 | AT10: =(IF('Water Report'!$L$15>0,'Water Report'!$L$15,0)) -> 7 | AU10: =(IF('Water Report'!$L$17>0,'Water Report'!$L$17,0)) -> 2 | AV10: =(IF('Water Report'!$L$18>0,'Water Report'!$L$18,0)) -> 14 | AW10: =(IF('Water Report'!$L$19>0,'Water Report'!$L$19,0)) -> 16 | AX10: =(IF('Water Report'!$L$21>0,'Water Report'!$L$21,0)) -> 105 | AY10: =(IF('Water Report'!$L$22>0,'Water Report'!$L$22,0)) -> 0 | AZ10: =(IF('Water Report'!$L$23>0,'Water Report'!$L$23,0)) -> 0 | BA10: =(IF('Water Report'!$L$14>0,'Water Report'!$L$14,0)) -> 1 | BB10: =(IF('Water Report'!$L$15>0,'Water Report'!$L$15,0)) -> 7 | BC10: =(IF('Water Report'!$L$13>0,'Water Report'!$L$13,0)) -> 15 | BD10: =(IF('Water Report'!$L$24>0,'Water Report'!$L$24,0)) -> 243 | BE10: =(IF('Water Report'!$L$25>0,'Water Report'!$L$25,0)) -> 641 | BF10: =(IF('Water Report'!$L$27>0,'Water Report'!$L$27,0)) -> 120 | BG10: =(IF('Section Load'!AN13>0,'Section Load'!AN13,0)) -> 1155 | BH10: =(IF('Section Load'!AO13>0,'Section Load'!AO13,0)) -> 300.488 | BI10: =(IF('Section Load'!AP13>0,'Section Load'!AP13,0)) -> 0 | BJ10: =(IF('Section Load'!AQ13>0,'Section Load'!AQ13,0)) -> 107 | BK10: =(IF('Section Load'!AR13>0,'Section Load'!AR13,0)) -> 39 | BL10: =(IF('Section Load'!AS13>0,'Section Load'!AS13,0)) -> 0 | BM10: =(IF('Section Load'!AT13>0,'Section Load'!AT13,0)) -> 708.512
A11: Mumbai | B11: =B10+1 -> 10 | C11: 1 | D11: 2023 | E11: =(IF('Section Load'!F14>0,'Section Load'!F14,0)) -> 3062.52 | F11: =(IF('Section Load'!G14>0,'Section Load'!G14,0)) -> 1475.98 | G11: =(IF('Section Load'!H14>0,'Section Load'!H14,0)) -> 2505.36 | H11: =(IF('Section Load'!I14>0,'Section Load'!I14,0)) -> 2694.72 | I11: =(IF('Section Load'!J14>0,'Section Load'!J14,0)) -> 4480.54 | J11: =(IF('Section Load'!K14>0,'Section Load'!K14,0)) -> 2357.04 | K11: =(IF('Section Load'!L14>0,'Section Load'!L14,0)) -> 1856.85 | L11: =(IF('Section Load'!M14>0,'Section Load'!M14,0)) -> 1144.33 | ... AL11: =(IF('Section Load'!AM14>0,'Section Load'!AM14,0)) -> 0 | AM11: =(IF('Water Report'!$M$7>0,'Water Report'!$M$7,0)) -> 131.4 | AN11: =(IF('Water Report'!$M$8>0,'Water Report'!$M$8,0)) -> 114 | AO11: =(IF('Water Report'!$M$9>0,'Water Report'!$M$9,0)) -> 125 | AP11: =(IF('Water Report'!$M$10>0,'Water Report'!$M$10,0)) -> 40 | AQ11: =(IF('Water Report'!$M$11>0,'Water Report'!$M$11,0)) -> 21 | AR11: =(IF('Water Report'!$M$13>0,'Water Report'!$M$13,0)) -> 21 | AS11: =(IF('Water Report'!$M$14>0,'Water Report'!$M$14,0)) -> 5 | AT11: =(IF('Water Report'!$M$15>0,'Water Report'!$M$15,0)) -> 2 | AU11: =(IF('Water Report'!$M$17>0,'Water Report'!$M$17,0)) -> 2 | AV11: =(IF('Water Report'!$M$18>0,'Water Report'!$M$18,0)) -> 11 | AW11: =(IF('Water Report'!$M$19>0,'Water Report'!$M$19,0)) -> 14 | AX11: =(IF('Water Report'!$M$21>0,'Water Report'!$M$21,0)) -> 129 | AY11: =(IF('Water Report'!$M$22>0,'Water Report'!$M$22,0)) -> 0 | AZ11: =(IF('Water Report'!$M$23>0,'Water Report'!$M$23,0)) -> 0 | BA11: =(IF('Water Report'!$M$14>0,'Water Report'!$M$14,0)) -> 5 | BB11: =(IF('Water Report'!$M$15>0,'Water Report'!$M$15,0)) -> 2 | BC11: =(IF('Water Report'!$M$13>0,'Water Report'!$M$13,0)) -> 21 | BD11: =(IF('Water Report'!$M$24>0,'Water Report'!$M$24,0)) -> 258 | BE11: =(IF('Water Report'!$M$25>0,'Water Report'!$M$25,0)) -> 193 | BF11: =(IF('Water Report'!$M$27>0,'Water Report'!$M$27,0)) -> 150 | BG11: =(IF('Section Load'!AN14>0,'Section Load'!AN14,0)) -> 1088 | BH11: =(IF('Section Load'!AO14>0,'Section Load'!AO14,0)) -> 293.612 | BI11: =(IF('Section Load'!AP14>0,'Section Load'!AP14,0)) -> 0 | BJ11: =(IF('Section Load'!AQ14>0,'Section Load'!AQ14,0)) -> 103 | BK11: =(IF('Section Load'!AR14>0,'Section Load'!AR14,0)) -> 40 | BL11: =(IF('Section Load'!AS14>0,'Section Load'!AS14,0)) -> 0 | BM11: =(IF('Section Load'!AT14>0,'Section Load'!AT14,0)) -> 651.788
A12: Mumbai | B12: =B11+1 -> 11 | C12: 1 | D12: 2023 | E12: =(IF('Section Load'!F15>0,'Section Load'!F15,0)) -> 3119.1 | F12: =(IF('Section Load'!G15>0,'Section Load'!G15,0)) -> 1558.9 | G12: =(IF('Section Load'!H15>0,'Section Load'!H15,0)) -> 2568.5 | H12: =(IF('Section Load'!I15>0,'Section Load'!I15,0)) -> 2815.86 | I12: =(IF('Section Load'!J15>0,'Section Load'!J15,0)) -> 4569.71 | J12: =(IF('Section Load'!K15>0,'Section Load'!K15,0)) -> 2386.16 | K12: =(IF('Section Load'!L15>0,'Section Load'!L15,0)) -> 1443.96 | L12: =(IF('Section Load'!M15>0,'Section Load'!M15,0)) -> 799.27 | ... AL12: =(IF('Section Load'!AM15>0,'Section Load'!AM15,0)) -> 0 | AM12: =(IF('Water Report'!$N$7>0,'Water Report'!$N$7,0)) -> 146.7 | AN12: =(IF('Water Report'!$N$8>0,'Water Report'!$N$8,0)) -> 107 | AO12: =(IF('Water Report'!$N$9>0,'Water Report'!$N$9,0)) -> 150 | AP12: =(IF('Water Report'!$N$10>0,'Water Report'!$N$10,0)) -> 47 | AQ12: =(IF('Water Report'!$N$11>0,'Water Report'!$N$11,0)) -> 19 | AR12: =(IF('Water Report'!$N$13>0,'Water Report'!$N$13,0)) -> 21 | AS12: =(IF('Water Report'!$N$14>0,'Water Report'!$N$14,0)) -> 3 | AT12: =(IF('Water Report'!$N$15>0,'Water Report'!$N$15,0)) -> 2 | AU12: =(IF('Water Report'!$N$17>0,'Water Report'!$N$17,0)) -> 2 | AV12: =(IF('Water Report'!$N$18>0,'Water Report'!$N$18,0)) -> 13 | AW12: =(IF('Water Report'!$N$19>0,'Water Report'!$N$19,0)) -> 15 | AX12: =(IF('Water Report'!$N$21>0,'Water Report'!$N$21,0)) -> 100 | AY12: =(IF('Water Report'!$N$22>0,'Water Report'!$N$22,0)) -> 0 | AZ12: =(IF('Water Report'!$N$23>0,'Water Report'!$N$23,0)) -> 18 | BA12: =(IF('Water Report'!$N$14>0,'Water Report'!$N$14,0)) -> 3 | BB12: =(IF('Water Report'!$N$15>0,'Water Report'!$N$15,0)) -> 2 | BC12: =(IF('Water Report'!$N$13>0,'Water Report'!$N$13,0)) -> 21 | BD12: =(IF('Water Report'!$N$24>0,'Water Report'!$N$24,0)) -> 310 | BE12: =(IF('Water Report'!$N$25>0,'Water Report'!$N$25,0)) -> 221 | BF12: =(IF('Water Report'!$N$27>0,'Water Report'!$N$27,0)) -> 139 | BG12: =(IF('Section Load'!AN15>0,'Section Load'!AN15,0)) -> 1166.458 | BH12: =(IF('Section Load'!AO15>0,'Section Load'!AO15,0)) -> 990961 | BI12: =(IF('Section Load'!AP15>0,'Section Load'!AP15,0)) -> 0 | BJ12: =(IF('Section Load'!AQ15>0,'Section Load'!AQ15,0)) -> 122.2 | BK12: =(IF('Section Load'!AR15>0,'Section Load'!AR15,0)) -> 52 | BL12: =(IF('Section Load'!AS15>0,'Section Load'!AS15,0)) -> 0 | BM12: =(IF('Section Load'!AT15>0,'Section Load'!AT15,0)) -> 0
A13: Mumbai | B13: =B12+1 -> 12 | C13: 1 | D13: 2023 | E13: =(IF('Section Load'!F16>0,'Section Load'!F16,0)) -> 3121.16 | F13: =(IF('Section Load'!G16>0,'Section Load'!G16,0)) -> 1491.68 | G13: =(IF('Section Load'!H16>0,'Section Load'!H16,0)) -> 2491.86 | H13: =(IF('Section Load'!I16>0,'Section Load'!I16,0)) -> 2692.17 | I13: =(IF('Section Load'!J16>0,'Section Load'!J16,0)) -> 3166.2 | J13: =(IF('Section Load'!K16>0,'Section Load'!K16,0)) -> 2592.76 | K13: =(IF('Section Load'!L16>0,'Section Load'!L16,0)) -> 1312.28 | L13: =(IF('Section Load'!M16>0,'Section Load'!M16,0)) -> 775.73 | ... AL13: =(IF('Section Load'!AM16>0,'Section Load'!AM16,0)) -> 0 | AM13: =(IF('Water Report'!$O$7>0,'Water Report'!$O$7,0)) -> 0 | AN13: =(IF('Water Report'!$O$8>0,'Water Report'!$O$8,0)) -> 119 | AO13: =(IF('Water Report'!$O$9>0,'Water Report'!$O$9,0)) -> 92 | AP13: =(IF('Water Report'!$O$10>0,'Water Report'!$O$10,0)) -> 23 | AQ13: =(IF('Water Report'!$O$11>0,'Water Report'!$O$11,0)) -> 3 | AR13: =(IF('Water Report'!$O$13>0,'Water Report'!$O$13,0)) -> 15 | AS13: =(IF('Water Report'!$O$14>0,'Water Report'!$O$14,0)) -> 4 | AT13: =(IF('Water Report'!$O$15>0,'Water Report'!$O$15,0)) -> 2 | AU13: =(IF('Water Report'!$O$17>0,'Water Report'!$O$17,0)) -> 2 | AV13: =(IF('Water Report'!$O$18>0,'Water Report'!$O$18,0)) -> 13 | AW13: =(IF('Water Report'!$O$19>0,'Water Report'!$O$19,0)) -> 14 | AX13: =(IF('Water Report'!$O$21>0,'Water Report'!$O$21,0)) -> 142 | AY13: =(IF('Water Report'!$O$22>0,'Water Report'!$O$22,0)) -> 0 | AZ13: =(IF('Water Report'!$O$23>0,'Water Report'!$O$23,0)) -> 4 | BA13: =(IF('Water Report'!$O$14>0,'Water Report'!$O$14,0)) -> 4 | BB13: =(IF('Water Report'!$O$15>0,'Water Report'!$O$15,0)) -> 2 | BC13: =(IF('Water Report'!$O$13>0,'Water Report'!$O$13,0)) -> 15 | BD13: =(IF('Water Report'!$O$24>0,'Water Report'!$O$24,0)) -> 245 | BE13: =(IF('Water Report'!$O$25>0,'Water Report'!$O$25,0)) -> 124 | BF13: =(IF('Water Report'!$O$27>0,'Water Report'!$O$27,0)) -> 161 | BG13: =(IF('Section Load'!AN16>0,'Section Load'!AN16,0)) -> 1163.522 | BH13: =(IF('Section Load'!AO16>0,'Section Load'!AO16,0)) -> 297.9 | BI13: =(IF('Section Load'!AP16>0,'Section Load'!AP16,0)) -> 0.2 | BJ13: =(IF('Section Load'!AQ16>0,'Section Load'!AQ16,0)) -> 116.8 | BK13: =(IF('Section Load'!AR16>0,'Section Load'!AR16,0)) -> 56 | BL13: =(IF('Section Load'!AS16>0,'Section Load'!AS16,0)) -> 0 | BM13: =(IF('Section Load'!AT16>0,'Section Load'!AT16,0)) -> 692.622
A14: Mumbai | B14: =B13+1 -> 13 | C14: 1 | D14: 2023 | E14: =(IF('Section Load'!F17>0,'Section Load'!F17,0)) -> 3212.5 | F14: =(IF('Section Load'!G17>0,'Section Load'!G17,0)) -> 1405.25 | G14: =(IF('Section Load'!H17>0,'Section Load'!H17,0)) -> 2482.09 | H14: =(IF('Section Load'!I17>0,'Section Load'!I17,0)) -> 2910.07 | I14: =(IF('Section Load'!J17>0,'Section Load'!J17,0)) -> 2810.38 | J14: =(IF('Section Load'!K17>0,'Section Load'!K17,0)) -> 2631.45 | K14: =(IF('Section Load'!L17>0,'Section Load'!L17,0)) -> 1542.21 | L14: =(IF('Section Load'!M17>0,'Section Load'!M17,0)) -> 821 | ... AL14: =(IF('Section Load'!AM17>0,'Section Load'!AM17,0)) -> 0.17 | AM14: =(IF('Water Report'!$P$7>0,'Water Report'!$P$7,0)) -> 0 | AN14: =(IF('Water Report'!$P$8>0,'Water Report'!$P$8,0)) -> 117 | AO14: =(IF('Water Report'!$P$9>0,'Water Report'!$P$9,0)) -> 132 | AP14: =(IF('Water Report'!$P$10>0,'Water Report'!$P$10,0)) -> 46 | AQ14: =(IF('Water Report'!$P$11>0,'Water Report'!$P$11,0)) -> 49 | AR14: =(IF('Water Report'!$P$13>0,'Water Report'!$P$13,0)) -> 13 | AS14: =(IF('Water Report'!$P$14>0,'Water Report'!$P$14,0)) -> 4 | AT14: =(IF('Water Report'!$P$15>0,'Water Report'!$P$15,0)) -> 26 | AU14: =(IF('Water Report'!$P$17>0,'Water Report'!$P$17,0)) -> 2 | AV14: =(IF('Water Report'!$P$18>0,'Water Report'!$P$18,0)) -> 12 | AW14: =(IF('Water Report'!$P$19>0,'Water Report'!$P$19,0)) -> 15 | AX14: =(IF('Water Report'!$P$21>0,'Water Report'!$P$21,0)) -> 112 | AY14: =(IF('Water Report'!$P$22>0,'Water Report'!$P$22,0)) -> 0 | AZ14: =(IF('Water Report'!$P$23>0,'Water Report'!$P$23,0)) -> 0 | BA14: =(IF('Water Report'!$P$14>0,'Water Report'!$P$14,0)) -> 4 | BB14: =(IF('Water Report'!$P$15>0,'Water Report'!$P$15,0)) -> 26 | BC14: =(IF('Water Report'!$P$13>0,'Water Report'!$P$13,0)) -> 13 | BD14: =(IF('Water Report'!$P$24>0,'Water Report'!$P$24,0)) -> 223 | BE14: =(IF('Water Report'!$P$25>0,'Water Report'!$P$25,0)) -> 257 | BF14: =(IF('Water Report'!$P$27>0,'Water Report'!$P$27,0)) -> 125 | BG14: =(IF('Section Load'!AN17>0,'Section Load'!AN17,0)) -> 1140.02 | BH14: =(IF('Section Load'!AO17>0,'Section Load'!AO17,0)) -> 298 | BI14: =(IF('Section Load'!AP17>0,'Section Load'!AP17,0)) -> 0 | BJ14: =(IF('Section Load'!AQ17>0,'Section Load'!AQ17,0)) -> 102 | BK14: =(IF('Section Load'!AR17>0,'Section Load'!AR17,0)) -> 54 | BL14: =(IF('Section Load'!AS17>0,'Section Load'!AS17,0)) -> 0 | BM14: =(IF('Section Load'!AT17>0,'Section Load'!AT17,0)) -> 686.42
A15: Mumbai | B15: =B14+1 -> 14 | C15: 1 | D15: 2023 | E15: =(IF('Section Load'!F18>0,'Section Load'!F18,0)) -> 3265.78 | F15: =(IF('Section Load'!G18>0,'Section Load'!G18,0)) -> 1401.91 | G15: =(IF('Section Load'!H18>0,'Section Load'!H18,0)) -> 2392.99 | H15: =(IF('Section Load'!I18>0,'Section Load'!I18,0)) -> 2750.22 | I15: =(IF('Section Load'!J18>0,'Section Load'!J18,0)) -> 2290.11 | J15: =(IF('Section Load'!K18>0,'Section Load'!K18,0)) -> 2644.99 | K15: =(IF('Section Load'!L18>0,'Section Load'!L18,0)) -> 1284.79 | L15: =(IF('Section Load'!M18>0,'Section Load'!M18,0)) -> 786.79 | ... AL15: =(IF('Section Load'!AM18>0,'Section Load'!AM18,0)) -> 0 | AM15: =(IF('Water Report'!$Q$7>0,'Water Report'!$Q$7,0)) -> 0 | AN15: =(IF('Water Report'!$Q$8>0,'Water Report'!$Q$8,0)) -> 127 | AO15: =(IF('Water Report'!$Q$9>0,'Water Report'!$Q$9,0)) -> 132 | AP15: =(IF('Water Report'!$Q$10>0,'Water Report'!$Q$10,0)) -> 46 | AQ15: =(IF('Water Report'!$Q$11>0,'Water Report'!$Q$11,0)) -> 33 | AR15: =(IF('Water Report'!$Q$13>0,'Water Report'!$Q$13,0)) -> 12 | AS15: =(IF('Water Report'!$Q$14>0,'Water Report'!$Q$14,0)) -> 2 | AT15: =(IF('Water Report'!$Q$15>0,'Water Report'!$Q$15,0)) -> 14 | AU15: =(IF('Water Report'!$Q$17>0,'Water Report'!$Q$17,0)) -> 0 | AV15: =(IF('Water Report'!$Q$18>0,'Water Report'!$Q$18,0)) -> 14 | AW15: =(IF('Water Report'!$Q$19>0,'Water Report'!$Q$19,0)) -> 12 | AX15: =(IF('Water Report'!$Q$21>0,'Water Report'!$Q$21,0)) -> 105 | AY15: =(IF('Water Report'!$Q$22>0,'Water Report'!$Q$22,0)) -> 0 | AZ15: =(IF('Water Report'!$Q$23>0,'Water Report'!$Q$23,0)) -> 10 | BA15: =(IF('Water Report'!$Q$14>0,'Water Report'!$Q$14,0)) -> 2 | BB15: =(IF('Water Report'!$Q$15>0,'Water Report'!$Q$15,0)) -> 14 | BC15: =(IF('Water Report'!$Q$13>0,'Water Report'!$Q$13,0)) -> 12 | BD15: =(IF('Water Report'!$Q$24>0,'Water Report'!$Q$24,0)) -> 289 | BE15: =(IF('Water Report'!$Q$25>0,'Water Report'!$Q$25,0)) -> 227 | BF15: =(IF('Water Report'!$Q$27>0,'Water Report'!$Q$27,0)) -> 127 | BG15: =(IF('Section Load'!AN18>0,'Section Load'!AN18,0)) -> 1190 | BH15: =(IF('Section Load'!AO18>0,'Section Load'!AO18,0)) -> 291 | BI15: =(IF('Section Load'!AP18>0,'Section Load'!AP18,0)) -> 0 | BJ15: =(IF('Section Load'!AQ18>0,'Section Load'!AQ18,0)) -> 112 | BK15: =(IF('Section Load'!AR18>0,'Section Load'!AR18,0)) -> 54 | BL15: =(IF('Section Load'!AS18>0,'Section Load'!AS18,0)) -> 0 | BM15: =(IF('Section Load'!AT18>0,'Section Load'!AT18,0)) -> 733
A16: Mumbai | B16: =B15+1 -> 15 | C16: 1 | D16: 2023 | E16: =(IF('Section Load'!F19>0,'Section Load'!F19,0)) -> 3735.89 | F16: =(IF('Section Load'!G19>0,'Section Load'!G19,0)) -> 1412.64 | G16: =(IF('Section Load'!H19>0,'Section Load'!H19,0)) -> 2492.64 | H16: =(IF('Section Load'!I19>0,'Section Load'!I19,0)) -> 2641.68 | I16: =(IF('Section Load'!J19>0,'Section Load'!J19,0)) -> 2576.71 | J16: =(IF('Section Load'!K19>0,'Section Load'!K19,0)) -> 2621.32 | K16: =(IF('Section Load'!L19>0,'Section Load'!L19,0)) -> 1243.72 | L16: =(IF('Section Load'!M19>0,'Section Load'!M19,0)) -> 693.6 | ... AL16: =(IF('Section Load'!AM19>0,'Section Load'!AM19,0)) -> 0 | AM16: =(IF('Water Report'!$R$7>0,'Water Report'!$R$7,0)) -> 143.5 | AN16: =(IF('Water Report'!$R$8>0,'Water Report'!$R$8,0)) -> 104 | AO16: =(IF('Water Report'!$R$9>0,'Water Report'!$R$9,0)) -> 121 | AP16: =(IF('Water Report'!$R$10>0,'Water Report'!$R$10,0)) -> 42 | AQ16: =(IF('Water Report'!$R$11>0,'Water Report'!$R$11,0)) -> 7 | AR16: =(IF('Water Report'!$R$13>0,'Water Report'!$R$13,0)) -> 33 | AS16: =(IF('Water Report'!$R$14>0,'Water Report'!$R$14,0)) -> 4 | AT16: =(IF('Water Report'!$R$15>0,'Water Report'!$R$15,0)) -> 4 | AU16: =(IF('Water Report'!$R$17>0,'Water Report'!$R$17,0)) -> 0 | AV16: =(IF('Water Report'!$R$18>0,'Water Report'!$R$18,0)) -> 7 | AW16: =(IF('Water Report'!$R$19>0,'Water Report'!$R$19,0)) -> 5 | AX16: =(IF('Water Report'!$R$21>0,'Water Report'!$R$21,0)) -> 64 | AY16: =(IF('Water Report'!$R$22>0,'Water Report'!$R$22,0)) -> 0 | AZ16: =(IF('Water Report'!$R$23>0,'Water Report'!$R$23,0)) -> 0 | BA16: =(IF('Water Report'!$R$14>0,'Water Report'!$R$14,0)) -> 4 | BB16: =(IF('Water Report'!$R$15>0,'Water Report'!$R$15,0)) -> 4 | BC16: =(IF('Water Report'!$R$13>0,'Water Report'!$R$13,0)) -> 33 | BD16: =(IF('Water Report'!$R$24>0,'Water Report'!$R$24,0)) -> 355 | BE16: =(IF('Water Report'!$R$25>0,'Water Report'!$R$25,0)) -> 178 | BF16: =(IF('Water Report'!$R$27>0,'Water Report'!$R$27,0)) -> 97 | BG16: =(IF('Section Load'!AN19>0,'Section Load'!AN19,0)) -> 1011 | BH16: =(IF('Section Load'!AO19>0,'Section Load'!AO19,0)) -> 113 | BI16: =(IF('Section Load'!AP19>0,'Section Load'!AP19,0)) -> 0.2 | BJ16: =(IF('Section Load'!AQ19>0,'Section Load'!AQ19,0)) -> 93 | BK16: =(IF('Section Load'!AR19>0,'Section Load'!AR19,0)) -> 40 | BL16: =(IF('Section Load'!AS19>0,'Section Load'!AS19,0)) -> 0 | BM16: =(IF('Section Load'!AT19>0,'Section Load'!AT19,0)) -> 764.8
A17: Mumbai | B17: =B16+1 -> 16 | C17: 1 | D17: 2023 | E17: =(IF('Section Load'!F20>0,'Section Load'!F20,0)) -> 2441.33 | F17: =(IF('Section Load'!G20>0,'Section Load'!G20,0)) -> 1520.45 | G17: =(IF('Section Load'!H20>0,'Section Load'!H20,0)) -> 2503.13 | H17: =(IF('Section Load'!I20>0,'Section Load'!I20,0)) -> 2793.1 | I17: =(IF('Section Load'!J20>0,'Section Load'!J20,0)) -> 2955.18 | J17: =(IF('Section Load'!K20>0,'Section Load'!K20,0)) -> 2697.69 | K17: =(IF('Section Load'!L20>0,'Section Load'!L20,0)) -> 1176.49 | L17: =(IF('Section Load'!M20>0,'Section Load'!M20,0)) -> 698.61 | ... AL17: =(IF('Section Load'!AM20>0,'Section Load'!AM20,0)) -> 0 | AM17: =(IF('Water Report'!$S$7>0,'Water Report'!$S$7,0)) -> 85.5 | AN17: =(IF('Water Report'!$S$8>0,'Water Report'!$S$8,0)) -> 113 | AO17: =(IF('Water Report'!$S$9>0,'Water Report'!$S$9,0)) -> 107 | AP17: =(IF('Water Report'!$S$10>0,'Water Report'!$D$10,0)) -> 12 | AQ17: =(IF('Water Report'!$S$11>0,'Water Report'!$D$11,0)) -> 32 | AR17: =(IF('Water Report'!$S$13>0,'Water Report'!$D$13,0)) -> 20 | AS17: =(IF('Water Report'!$S$14>0,'Water Report'!$D$14,0)) -> 13 | AT17: =(IF('Water Report'!$S$15>0,'Water Report'!$D$15,0)) -> 10 | AU17: =(IF('Water Report'!$S$17>0,'Water Report'!$D$17,0)) -> 1 | AV17: =(IF('Water Report'!$S$18>0,'Water Report'!$D$18,0)) -> -1 | AW17: =(IF('Water Report'!$S$19>0,'Water Report'!$D$19,0)) -> 14 | AX17: =(IF('Water Report'!$S$21>0,'Water Report'!$D$21,0)) -> 109 | AY17: =(IF('Water Report'!$S$22>0,'Water Report'!$D$22,0)) -> 0 | AZ17: =(IF('Water Report'!$S$23>0,'Water Report'!$D$23,0)) -> 0 | BA17: =(IF('Water Report'!$S$14>0,'Water Report'!$D$14,0)) -> 13 | BB17: =(IF('Water Report'!$S$15>0,'Water Report'!$D$15,0)) -> 10 | BC17: =(IF('Water Report'!$S$13>0,'Water Report'!$D$13,0)) -> 20 | BD17: =(IF('Water Report'!$S$24>0,'Water Report'!$D$24,0)) -> 278 | BE17: =(IF('Water Report'!$S$25>0,'Water Report'!$D$25,0)) -> 194 | BF17: =(IF('Water Report'!$S$27>0,'Water Report'!$D$27,0)) -> 129 | BG17: =(IF('Section Load'!AN20>0,'Section Load'!AN20,0)) -> 1059 | BH17: =(IF('Section Load'!AO20>0,'Section Load'!AO20,0)) -> 356 | BI17: =(IF('Section Load'!AP20>0,'Section Load'!AP20,0)) -> 0 | BJ17: =(IF('Section Load'!AQ20>0,'Section Load'!AQ20,0)) -> 101 | BK17: =(IF('Section Load'!AR20>0,'Section Load'!AR20,0)) -> 48 | BL17: =(IF('Section Load'!AS20>0,'Section Load'!AS20,0)) -> 0 | BM17: =(IF('Section Load'!AT20>0,'Section Load'!AT20,0)) -> 554
A18: Mumbai | B18: =B17+1 -> 17 | C18: 1 | D18: 2023 | E18: =(IF('Section Load'!F21>0,'Section Load'!F21,0)) -> 2993 | F18: =(IF('Section Load'!G21>0,'Section Load'!G21,0)) -> 1424 | G18: =(IF('Section Load'!H21>0,'Section Load'!H21,0)) -> 2431 | H18: =(IF('Section Load'!I21>0,'Section Load'!I21,0)) -> 2759 | I18: =(IF('Section Load'!J21>0,'Section Load'!J21,0)) -> 2147.37 | J18: =(IF('Section Load'!K21>0,'Section Load'!K21,0)) -> 2642 | K18: =(IF('Section Load'!L21>0,'Section Load'!L21,0)) -> 1107 | L18: =(IF('Section Load'!M21>0,'Section Load'!M21,0)) -> 734 | ... AL18: =(IF('Section Load'!AM21>0,'Section Load'!AM21,0)) -> 0 | AM18: =(IF('Water Report'!$T$7>0,'Water Report'!$T$7,0)) -> 96 | AN18: =(IF('Water Report'!$T$8>0,'Water Report'!$T$8,0)) -> 84 | AO18: =(IF('Water Report'!$T$9>0,'Water Report'!$T$9,0)) -> 118 | AP18: =(IF('Water Report'!$T$10>0,'Water Report'!$T$10,0)) -> 9 | AQ18: =(IF('Water Report'!$T$11>0,'Water Report'!$T$11,0)) -> 19 | AR18: =(IF('Water Report'!$T$13>0,'Water Report'!$T$13,0)) -> 14 | AS18: =(IF('Water Report'!$T$14>0,'Water Report'!$T$14,0)) -> 2 | AT18: =(IF('Water Report'!$T$15>0,'Water Report'!$T$15,0)) -> 5 | AU18: =(IF('Water Report'!$T$17>0,'Water Report'!$T$17,0)) -> 0 | AV18: =(IF('Water Report'!$T$18>0,'Water Report'!$T$18,0)) -> 10 | AW18: =(IF('Water Report'!$T$19>0,'Water Report'!$T$19,0)) -> 15 | AX18: =(IF('Water Report'!$T$21>0,'Water Report'!$T$21,0)) -> 105 | AY18: =(IF('Water Report'!$T$22>0,'Water Report'!$T$22,0)) -> 0 | AZ18: =(IF('Water Report'!$T$23>0,'Water Report'!$T$23,0)) -> 0 | BA18: =(IF('Water Report'!$T$14>0,'Water Report'!$T$14,0)) -> 2 | BB18: =(IF('Water Report'!$T$15>0,'Water Report'!$T$15,0)) -> 5 | BC18: =(IF('Water Report'!$T$13>0,'Water Report'!$T$13,0)) -> 14 | BD18: =(IF('Water Report'!$T$24>0,'Water Report'!$T$24,0)) -> 205 | BE18: =(IF('Water Report'!$T$25>0,'Water Report'!$T$25,0)) -> 153 | BF18: =(IF('Water Report'!$T$27>0,'Water Report'!$T$27,0)) -> 119 | BG18: =(IF('Section Load'!AN21>0,'Section Load'!AN21,0)) -> 922 | BH18: =(IF('Section Load'!AO21>0,'Section Load'!AO21,0)) -> 300 | BI18: =(IF('Section Load'!AP21>0,'Section Load'!AP21,0)) -> 0 | BJ18: =(IF('Section Load'!AQ21>0,'Section Load'!AQ21,0)) -> 82 | BK18: =(IF('Section Load'!AR21>0,'Section Load'!AR21,0)) -> 51 | BL18: =(IF('Section Load'!AS21>0,'Section Load'!AS21,0)) -> 0 | BM18: =(IF('Section Load'!AT21>0,'Section Load'!AT21,0)) -> 489
A19: Mumbai | B19: =B18+1 -> 18 | C19: 1 | D19: 2023 | E19: =(IF('Section Load'!F22>0,'Section Load'!F22,0)) -> 2991 | F19: =(IF('Section Load'!G22>0,'Section Load'!G22,0)) -> 1400 | G19: =(IF('Section Load'!H22>0,'Section Load'!H22,0)) -> 2550 | H19: =(IF('Section Load'!I22>0,'Section Load'!I22,0)) -> 2725 | I19: =(IF('Section Load'!J22>0,'Section Load'!J22,0)) -> 2492 | J19: =(IF('Section Load'!K22>0,'Section Load'!K22,0)) -> 2635 | K19: =(IF('Section Load'!L22>0,'Section Load'!L22,0)) -> 1107 | L19: =(IF('Section Load'!M22>0,'Section Load'!M22,0)) -> 686 | ... AL19: =(IF('Section Load'!AM22>0,'Section Load'!AM22,0)) -> 0 | AM19: =(IF('Water Report'!$U$7>0,'Water Report'!$U$7,0)) -> 106 | AN19: =(IF('Water Report'!$U$8>0,'Water Report'!$U$8,0)) -> 81 | AO19: =(IF('Water Report'!$U$9>0,'Water Report'!$U$9,0)) -> 127 | AP19: =(IF('Water Report'!$U$10>0,'Water Report'!$U$10,0)) -> 7 | AQ19: =(IF('Water Report'!$U$11>0,'Water Report'!$U$11,0)) -> 25 | AR19: =(IF('Water Report'!$U$13>0,'Water Report'!$U$13,0)) -> 12 | AS19: =(IF('Water Report'!$U$14>0,'Water Report'!$U$14,0)) -> 2 | AT19: =(IF('Water Report'!$U$15>0,'Water Report'!$U$15,0)) -> 14 | AU19: =(IF('Water Report'!$U$17>0,'Water Report'!$U$17,0)) -> 1 | AV19: =(IF('Water Report'!$U$18>0,'Water Report'!$U$18,0)) -> 10 | AW19: =(IF('Water Report'!$U$19>0,'Water Report'!$U$19,0)) -> 15 | AX19: =(IF('Water Report'!$U$21>0,'Water Report'!$U$21,0)) -> 105 | AY19: =(IF('Water Report'!$U$22>0,'Water Report'!$U$22,0)) -> 0 | AZ19: =(IF('Water Report'!$U$23>0,'Water Report'!$U$23,0)) -> 11 | BA19: =(IF('Water Report'!$U$14>0,'Water Report'!$U$14,0)) -> 2 | BB19: =(IF('Water Report'!$U$15>0,'Water Report'!$U$15,0)) -> 14 | BC19: =(IF('Water Report'!$U$13>0,'Water Report'!$U$13,0)) -> 12 | BD19: =(IF('Water Report'!$U$24>0,'Water Report'!$U$24,0)) -> 284 | BE19: =(IF('Water Report'!$U$25>0,'Water Report'!$U$25,0)) -> 175 | BF19: =(IF('Water Report'!$U$27>0,'Water Report'!$U$27,0)) -> 128 | BG19: =(IF('Section Load'!AN22>0,'Section Load'!AN22,0)) -> 1106 | BH19: =(IF('Section Load'!AO22>0,'Section Load'!AO22,0)) -> 283 | BI19: =(IF('Section Load'!AP22>0,'Section Load'!AP22,0)) -> 0 | BJ19: =(IF('Section Load'!AQ22>0,'Section Load'!AQ22,0)) -> 117 | BK19: =(IF('Section Load'!AR22>0,'Section Load'!AR22,0)) -> 53 | BL19: =(IF('Section Load'!AS22>0,'Section Load'!AS22,0)) -> 0 | BM19: =(IF('Section Load'!AT22>0,'Section Load'!AT22,0)) -> 653
A20: Mumbai | B20: =B19+1 -> 19 | C20: 1 | D20: 2023 | E20: =(IF('Section Load'!F23>0,'Section Load'!F23,0)) -> 2808.46 | F20: =(IF('Section Load'!G23>0,'Section Load'!G23,0)) -> 1485.01 | G20: =(IF('Section Load'!H23>0,'Section Load'!H23,0)) -> 2582.67 | H20: =(IF('Section Load'!I23>0,'Section Load'!I23,0)) -> 2754.66 | I20: =(IF('Section Load'!J23>0,'Section Load'!J23,0)) -> 2703.44 | J20: =(IF('Section Load'!K23>0,'Section Load'!K23,0)) -> 2584 | K20: =(IF('Section Load'!L23>0,'Section Load'!L23,0)) -> 1693.8 | L20: =(IF('Section Load'!M23>0,'Section Load'!M23,0)) -> 993.19 | ... AL20: =(IF('Section Load'!AM23>0,'Section Load'!AM23,0)) -> 0 | AM20: =(IF('Water Report'!$V$7>0,'Water Report'!$V$7,0)) -> 106 | AN20: =(IF('Water Report'!$V$8>0,'Water Report'!$V$8,0)) -> 105 | AO20: =(IF('Water Report'!$V$9>0,'Water Report'!$V$9,0)) -> 126 | AP20: =(IF('Water Report'!$V$10>0,'Water Report'!$V$10,0)) -> 8 | AQ20: =(IF('Water Report'!$V$11>0,'Water Report'!$V$11,0)) -> 26 | AR20: =(IF('Water Report'!$V$13>0,'Water Report'!$V$13,0)) -> 34 | AS20: =(IF('Water Report'!$V$14>0,'Water Report'!$V$14,0)) -> 8 | AT20: =(IF('Water Report'!$V$15>0,'Water Report'!$V$15,0)) -> 7 | AU20: =(IF('Water Report'!$V$17>0,'Water Report'!$V$17,0)) -> 2 | AV20: =(IF('Water Report'!$V$18>0,'Water Report'!$V$18,0)) -> 13 | AW20: =(IF('Water Report'!$V$19>0,'Water Report'!$V$19,0)) -> 19 | AX20: =(IF('Water Report'!$V$21>0,'Water Report'!$V$21,0)) -> 98 | AY20: =(IF('Water Report'!$V$22>0,'Water Report'!$V$22,0)) -> 0 | AZ20: =(IF('Water Report'!$V$23>0,'Water Report'!$V$23,0)) -> 0 | BA20: =(IF('Water Report'!$V$14>0,'Water Report'!$V$14,0)) -> 8 | BB20: =(IF('Water Report'!$V$15>0,'Water Report'!$V$15,0)) -> 7 | BC20: =(IF('Water Report'!$V$13>0,'Water Report'!$V$13,0)) -> 34 | BD20: =(IF('Water Report'!$V$24>0,'Water Report'!$V$24,0)) -> 231 | BE20: =(IF('Water Report'!$V$25>0,'Water Report'!$V$25,0)) -> 175 | BF20: =(IF('Water Report'!$V$27>0,'Water Report'!$V$27,0)) -> 132 | BG20: =(IF('Section Load'!AN23>0,'Section Load'!AN23,0)) -> 1171.8 | BH20: =(IF('Section Load'!AO23>0,'Section Load'!AO23,0)) -> 335 | BI20: =(IF('Section Load'!AP23>0,'Section Load'!AP23,0)) -> 0 | BJ20: =(IF('Section Load'!AQ23>0,'Section Load'!AQ23,0)) -> 102.5 | BK20: =(IF('Section Load'!AR23>0,'Section Load'!AR23,0)) -> 52 | BL20: =(IF('Section Load'!AS23>0,'Section Load'!AS23,0)) -> 0 | BM20: =(IF('Section Load'!AT23>0,'Section Load'!AT23,0)) -> 682.3
A21: Mumbai | B21: =B20+1 -> 20 | C21: 1 | D21: 2023 | E21: =(IF('Section Load'!F24>0,'Section Load'!F24,0)) -> 2786.54 | F21: =(IF('Section Load'!G24>0,'Section Load'!G24,0)) -> 1459.99 | G21: =(IF('Section Load'!H24>0,'Section Load'!H24,0)) -> 2619.33 | H21: =(IF('Section Load'!I24>0,'Section Load'!I24,0)) -> 2766.34 | I21: =(IF('Section Load'!J24>0,'Section Load'!J24,0)) -> 2725.19 | J21: =(IF('Section Load'!K24>0,'Section Load'!K24,0)) -> 2679 | K21: =(IF('Section Load'!L24>0,'Section Load'!L24,0)) -> 1490.2 | L21: =(IF('Section Load'!M24>0,'Section Load'!M24,0)) -> 853.81 | ... AL21: =(IF('Section Load'!AM24>0,'Section Load'!AM24,0)) -> 0 | AM21: =(IF('Water Report'!$W$7>0,'Water Report'!$W$7,0)) -> 121 | AN21: =(IF('Water Report'!$W$8>0,'Water Report'!$W$8,0)) -> 94 | AO21: =(IF('Water Report'!$W$9>0,'Water Report'!$W$9,0)) -> 139 | AP21: =(IF('Water Report'!$W$10>0,'Water Report'!$W$10,0)) -> 16 | AQ21: =(IF('Water Report'!$W$11>0,'Water Report'!$W$11,0)) -> 24 | AR21: =(IF('Water Report'!$W$13>0,'Water Report'!$W$13,0)) -> 20 | AS21: =(IF('Water Report'!$W$14>0,'Water Report'!$W$14,0)) -> 6 | AT21: =(IF('Water Report'!$W$15>0,'Water Report'!$W$15,0)) -> 7 | AU21: =(IF('Water Report'!$W$17>0,'Water Report'!$W$17,0)) -> 1 | AV21: =(IF('Water Report'!$W$18>0,'Water Report'!$W$18,0)) -> 12 | AW21: =(IF('Water Report'!$W$19>0,'Water Report'!$W$19,0)) -> 17 | AX21: =(IF('Water Report'!$W$21>0,'Water Report'!$W$21,0)) -> 77 | AY21: =(IF('Water Report'!$W$22>0,'Water Report'!$W$22,0)) -> 0 | AZ21: =(IF('Water Report'!$W$23>0,'Water Report'!$W$23,0)) -> 0 | BA21: =(IF('Water Report'!$W$14>0,'Water Report'!$W$14,0)) -> 6 | BB21: =(IF('Water Report'!$W$15>0,'Water Report'!$W$15,0)) -> 7 | BC21: =(IF('Water Report'!$W$13>0,'Water Report'!$W$13,0)) -> 20 | BD21: =(IF('Water Report'!$W$24>0,'Water Report'!$W$24,0)) -> 276 | BE21: =(IF('Water Report'!$W$25>0,'Water Report'!$W$25,0)) -> 192 | BF21: =(IF('Water Report'!$W$27>0,'Water Report'!$W$27,0)) -> 97 | BG21: =(IF('Section Load'!AN24>0,'Section Load'!AN24,0)) -> 1194.2 | BH21: =(IF('Section Load'!AO24>0,'Section Load'!AO24,0)) -> 329 | BI21: =(IF('Section Load'!AP24>0,'Section Load'!AP24,0)) -> 0 | BJ21: =(IF('Section Load'!AQ24>0,'Section Load'!AQ24,0)) -> 108.5 | BK21: =(IF('Section Load'!AR24>0,'Section Load'!AR24,0)) -> 59 | BL21: =(IF('Section Load'!AS24>0,'Section Load'!AS24,0)) -> 0 | BM21: =(IF('Section Load'!AT24>0,'Section Load'!AT24,0)) -> 697.7
A22: Mumbai | B22: =B21+1 -> 21 | C22: 1 | D22: 2023 | E22: =(IF('Section Load'!F25>0,'Section Load'!F25,0)) -> 2795 | F22: =(IF('Section Load'!G25>0,'Section Load'!G25,0)) -> 1407 | G22: =(IF('Section Load'!H25>0,'Section Load'!H25,0)) -> 2664 | H22: =(IF('Section Load'!I25>0,'Section Load'!I25,0)) -> 2740 | I22: =(IF('Section Load'!J25>0,'Section Load'!J25,0)) -> 2544.86 | J22: =(IF('Section Load'!K25>0,'Section Load'!K25,0)) -> 2637 | K22: =(IF('Section Load'!L25>0,'Section Load'!L25,0)) -> 1159 | L22: =(IF('Section Load'!M25>0,'Section Load'!M25,0)) -> 944 | ... AL22: =(IF('Section Load'!AM25>0,'Section Load'!AM25,0)) -> 0 | AM22: =(IF('Water Report'!$X$7>0,'Water Report'!$X$7,0)) -> 168 | AN22: =(IF('Water Report'!$X$8>0,'Water Report'!$X$8,0)) -> 111 | AO22: =(IF('Water Report'!$X$9>0,'Water Report'!$X$9,0)) -> 149 | AP22: =(IF('Water Report'!$X$10>0,'Water Report'!$X$10,0)) -> 13 | AQ22: =(IF('Water Report'!$X$11>0,'Water Report'!$X$11,0)) -> 24 | AR22: =(IF('Water Report'!$X$13>0,'Water Report'!$X$13,0)) -> 10 | AS22: =(IF('Water Report'!$X$14>0,'Water Report'!$X$14,0)) -> 4 | AT22: =(IF('Water Report'!$X$15>0,'Water Report'!$X$15,0)) -> 8 | AU22: =(IF('Water Report'!$X$17>0,'Water Report'!$X$17,0)) -> 1 | AV22: =(IF('Water Report'!$X$18>0,'Water Report'!$X$18,0)) -> 16 | AW22: =(IF('Water Report'!$X$19>0,'Water Report'!$X$19,0)) -> 23 | AX22: =(IF('Water Report'!$X$21>0,'Water Report'!$X$21,0)) -> 127 | AY22: =(IF('Water Report'!$X$22>0,'Water Report'!$X$22,0)) -> 0 | AZ22: =(IF('Water Report'!$X$23>0,'Water Report'!$X$23,0)) -> 11 | BA22: =(IF('Water Report'!$X$14>0,'Water Report'!$X$14,0)) -> 4 | BB22: =(IF('Water Report'!$X$15>0,'Water Report'!$X$15,0)) -> 8 | BC22: =(IF('Water Report'!$X$13>0,'Water Report'!$X$13,0)) -> 10 | BD22: =(IF('Water Report'!$X$24>0,'Water Report'!$X$24,0)) -> 261 | BE22: =(IF('Water Report'!$X$25>0,'Water Report'!$X$25,0)) -> 198 | BF22: =(IF('Water Report'!$X$27>0,'Water Report'!$X$27,0)) -> 148 | BG22: =(IF('Section Load'!AN25>0,'Section Load'!AN25,0)) -> 1220 | BH22: =(IF('Section Load'!AO25>0,'Section Load'!AO25,0)) -> 324 | BI22: =(IF('Section Load'!AP25>0,'Section Load'!AP25,0)) -> 0 | BJ22: =(IF('Section Load'!AQ25>0,'Section Load'!AQ25,0)) -> 102 | BK22: =(IF('Section Load'!AR25>0,'Section Load'!AR25,0)) -> 65 | BL22: =(IF('Section Load'!AS25>0,'Section Load'!AS25,0)) -> 0 | BM22: =(IF('Section Load'!AT25>0,'Section Load'!AT25,0)) -> 729
A23: Mumbai | B23: =B22+1 -> 22 | C23: 1 | D23: 2023 | E23: =(IF('Section Load'!F26>0,'Section Load'!F26,0)) -> 2756 | F23: =(IF('Section Load'!G26>0,'Section Load'!G26,0)) -> 1477 | G23: =(IF('Section Load'!H26>0,'Section Load'!H26,0)) -> 2557 | H23: =(IF('Section Load'!I26>0,'Section Load'!I26,0)) -> 2680 | I23: =(IF('Section Load'!J26>0,'Section Load'!J26,0)) -> 2007 | J23: =(IF('Section Load'!K26>0,'Section Load'!K26,0)) -> 2638 | K23: =(IF('Section Load'!L26>0,'Section Load'!L26,0)) -> 1059 | L23: =(IF('Section Load'!M26>0,'Section Load'!M26,0)) -> 921 | ... AL23: =(IF('Section Load'!AM26>0,'Section Load'!AM26,0)) -> 0 | AM23: =(IF('Water Report'!$Y$7>0,'Water Report'!$Y$7,0)) -> 160 | AN23: =(IF('Water Report'!$Y$8>0,'Water Report'!$Y$8,0)) -> 123 | AO23: =(IF('Water Report'!$Y$9>0,'Water Report'!$Y$9,0)) -> 141 | AP23: =(IF('Water Report'!$Y$10>0,'Water Report'!$Y$10,0)) -> 57 | AQ23: =(IF('Water Report'!$Y$11>0,'Water Report'!$Y$11,0)) -> 26 | AR23: =(IF('Water Report'!$Y$13>0,'Water Report'!$Y$13,0)) -> 25 | AS23: =(IF('Water Report'!$Y$14>0,'Water Report'!$Y$14,0)) -> 3 | AT23: =(IF('Water Report'!$Y$15>0,'Water Report'!$Y$15,0)) -> 5 | AU23: =(IF('Water Report'!$Y$17>0,'Water Report'!$Y$17,0)) -> 0 | AV23: =(IF('Water Report'!$Y$18>0,'Water Report'!$Y$18,0)) -> 13 | AW23: =(IF('Water Report'!$Y$19>0,'Water Report'!$Y$19,0)) -> 16 | AX23: =(IF('Water Report'!$Y$21>0,'Water Report'!$Y$21,0)) -> 91 | AY23: =(IF('Water Report'!$Y$22>0,'Water Report'!$Y$22,0)) -> 0 | AZ23: =(IF('Water Report'!$Y$23>0,'Water Report'!$Y$23,0)) -> 0 | BA23: =(IF('Water Report'!$Y$14>0,'Water Report'!$Y$14,0)) -> 3 | BB23: =(IF('Water Report'!$Y$15>0,'Water Report'!$Y$15,0)) -> 5 | BC23: =(IF('Water Report'!$Y$13>0,'Water Report'!$Y$13,0)) -> 25 | BD23: =(IF('Water Report'!$Y$24>0,'Water Report'!$Y$24,0)) -> 275 | BE23: =(IF('Water Report'!$Y$25>0,'Water Report'!$Y$25,0)) -> 232 | BF23: =(IF('Water Report'!$Y$27>0,'Water Report'!$Y$27,0)) -> 116 | BG23: =(IF('Section Load'!AN26>0,'Section Load'!AN26,0)) -> 1281 | BH23: =(IF('Section Load'!AO26>0,'Section Load'!AO26,0)) -> 336 | BI23: =(IF('Section Load'!AP26>0,'Section Load'!AP26,0)) -> 0 | BJ23: =(IF('Section Load'!AQ26>0,'Section Load'!AQ26,0)) -> 114 | BK23: =(IF('Section Load'!AR26>0,'Section Load'!AR26,0)) -> 64 | BL23: =(IF('Section Load'!AS26>0,'Section Load'!AS26,0)) -> 0 | BM23: =(IF('Section Load'!AT26>0,'Section Load'!AT26,0)) -> 767
