Workbook

Sheet TOTAL
A1: Site Name | B1: Day | C1: Month | D1: Year | E1: Total Electricity Kwh | F1: Electricity Tariff ($/Kwh) | G1: Total Fuel Oil (Liter) | H1: Fuel Oil $/Liter | I1: Water Utility Supply (m3) m3 | J1: Water Utility Supply (m3) $/m3 | K1: LPG (Kg) | L1: LPG $/Kg | M1: Room Nights | N1: Total Guests | O1: Food Covers
A2: Maldives at Kuda Huraa | B2: 1 | C2: 1 | D2: 2023 | E2: 21240 | G2: 5598 | I2: 498 | M2: 92.7 | N2: 244 | O2: 663
A3: Maldives at Kuda Huraa | B3: =B2+1 -> 2 | C3: 1 | D3: 2023 | E3: 20900 | G3: 6109 | I3: 407 | M3: 84.4 | N3: 220 | O3: 637
A4: Maldives at Kuda Huraa | B4: =B3+1 -> 3 | C4: 1 | D4: 2023 | E4: 20900 | G4: 5967 | I4: 441 | M4: 93.8 | N4: 238 | O4: 638
A5: Maldives at Kuda Huraa | B5: =B4+1 -> 4 | C5: 1 | D5: 2023 | E5: 21310 | G5: 5901 | I5: 591 | M5: 91.7 | N5: 232 | O5: 669
A6: Maldives at Kuda Huraa | B6: =B5+1 -> 5 | C6: 1 | D6: 2023 | E6: 20670 | G6: 5600 | I6: 460 | M6: 87.5 | N6: 209 | O6: 548
A7: Maldives at Kuda Huraa | B7: =B6+1 -> 6 | C7: 1 | D7: 2023 | E7: 21630 | G7: 6114 | I7: 445 | M7: 85.4 | N7: 211 | O7: 561
A8: Maldives at Kuda Huraa | B8: =B7+1 -> 7 | C8: 1 | D8: 2023 | E8: 21700 | G8: 6047 | I8: 457 | M8: 83.3 | N8: 208 | O8: 583
A9: Maldives at Kuda Huraa | B9: =B8+1 -> 8 | C9: 1 | D9: 2023 | E9: 21120 | G9: 5873 | I9: 488 | M9: 79.2 | N9: 194 | O9: 563
A10: Maldives at Kuda Huraa | B10: =B9+1 -> 9 | C10: 1 | D10: 2023 | E10: 21040 | G10: 5933 | I10: 451 | M10: 75 | N10: 191 | O10: 517
A11: Maldives at Kuda Huraa | B11: =B10+1 -> 10 | C11: 1 | D11: 2023 | E11: 20440 | G11: 5791 | I11: 447 | M11: 65.6 | N11: 174 | O11: 438
A12: Maldives at Kuda Huraa | B12: =B11+1 -> 11 | C12: 1 | D12: 2023 | E12: 20340 | G12: 5732 | I12: 426 | M12: 62.5 | N12: 159 | O12: 426
A13: Maldives at Kuda Huraa | B13: =B12+1 -> 12 | C13: 1 | D13: 2023 | E13: 19520 | G13: 5473 | I13: 416 | M13: 59.4 | N13: 146 | O13: 392
A14: Maldives at Kuda Huraa | B14: =B13+1 -> 13 | C14: 1 | D14: 2023 | E14: 19990 | G14: 5261 | I14: 427 | M14: 58.3 | N14: 138 | O14: 380
... A30: Maldives at Kuda Huraa | B30: =B29+1 -> 29 | C30: 1 | D30: 2023 | E30: 16210 | G30: 4425 | I30: 272 | M30: 45.8 | N30: 98 | O30: 245
A31: Maldives at Kuda Huraa | B31: =B30+1 -> 30 | C31: 1 | D31: 2023 | E31: 0 | G31: 0 | I31: 0
A32: Maldives at Kuda Huraa | B32: =B31+1 -> 31 | C32: 1 | D32: 2023 | E32: 0 | G32: 0 | I32: 0
A33: Total | E33: =SUM(E2:E32) -> 571720 | F33: 0 | G33: =SUM(G2:G32) -> 158294 | H33: 0 | I33: =SUM(I2:I32) -> 11677 | J33: 0 | K33: =SUM(K2:K31) -> 0 | L33: 0 | M33: =SUM(M2:M32) -> 1722.9 | N33: =SUM(N2:N32) -> 4137 | O33: =SUM(O2:O32) -> 11175

Sheet Submeters
A1: Site Name | B1: Day | C1: Month | D1: Year | E1: Reef Club | F1: Kitchen | G1: Pastry | H1: Laundry | I1: Laundry A | J1: Laundry B | K1: Laundry C | L1: STP -1 &2 | M1: STP -3 | N1: M - Block /PC | O1: B&C Block | P1: Feeder -101-112 | Q1: Feeder -113-123 | R1: Feeder -124-134 | S1: Feeder -201-208 | T1: Feeder -209-216 | U1: Feeder -217-224 | V1: Feeder -301-319 | W1: Feeder 401-419 | X1: Spa
A2: Maldives at Kuda Huraa | B2: 1 | C2: 1 | D2: 2023 | E2: 0 | F2: 0 | G2: 0 | H2: =I2+J2+K2 -> 2120 | I2: =('Kwh Reading'!J5-'Kwh Reading'!J4)*1000 -> 1010 | J2: =('Kwh Reading'!K5-'Kwh Reading'!K4)*1000 -> 560 | K2: =('Kwh Reading'!L5-'Kwh Reading'!L4)*1000 -> 550 | L2: =('Kwh Reading'!R5-'Kwh Reading'!R4)*1000 -> 0 | M2: =('Kwh Reading'!S5-'Kwh Reading'!S4)*1000 -> 0 | N2: =('Kwh Reading'!I5-'Kwh Reading'!I4)*1000 -> 360 | O2: =('Kwh Reading'!B5-'Kwh Reading'!B4)*1000000 -> 1100 | P2: =('Kwh Reading'!M5-'Kwh Reading'!M4)*1000 -> 480 | Q2: =('Kwh Reading'!H5-'Kwh Reading'!H4)*1000000 -> 700 | R2: =('Kwh Reading'!P5-'Kwh Reading'!P4)*1000000 -> 500 | S2: =('Kwh Reading'!G5-'Kwh Reading'!G4)*1000000 -> 500 | T2: =('Kwh Reading'!Q5-'Kwh Reading'!Q4)*1000 -> 400 | U2: =('Kwh Reading'!N5-'Kwh Reading'!N4)*1000 -> 390 | V2: ='Kwh Reading'!E5-'Kwh Reading'!E4 -> 2594.8 | W2: ='Kwh Reading'!D5-'Kwh Reading'!D4 -> 1461.45 | X2: =('Kwh Reading'!O5-'Kwh Reading'!O4)*1000 -> 270
A3: Maldives at Kuda Huraa | B3: =B2+1 -> 2 | C3: 1 | D3: 2023 | E3: =('Kwh Reading'!T6-'Kwh Reading'!T5)*1000 -> 700 | F3: =('Kwh Reading'!F6-'Kwh Reading'!F5)*1000000 -> 2600 | G3: =('Kwh Reading'!C6-'Kwh Reading'!C5)*1000 -> 300 | H3: =I3+J3+K3 -> 2130 | I3: =('Kwh Reading'!J6-'Kwh Reading'!J5)*1000 -> 1000 | J3: =('Kwh Reading'!K6-'Kwh Reading'!K5)*1000 -> 550 | K3: =('Kwh Reading'!L6-'Kwh Reading'!L5)*1000 -> 580 | L3: =('Kwh Reading'!R6-'Kwh Reading'!R5)*1000 -> 0 | M3: =('Kwh Reading'!S6-'Kwh Reading'!S5)*1000 -> 0 | N3: =('Kwh Reading'!I6-'Kwh Reading'!I5)*1000 -> 340 | O3: =('Kwh Reading'!B6-'Kwh Reading'!B5)*1000000 -> 1100 | P3: =('Kwh Reading'!M6-'Kwh Reading'!M5)*1000 -> 450 | Q3: =('Kwh Reading'!H6-'Kwh Reading'!H5)*1000000 -> 700 | R3: =('Kwh Reading'!P6-'Kwh Reading'!P5)*1000000 -> 500 | S3: =('Kwh Reading'!G6-'Kwh Reading'!G5)*1000000 -> 500 | T3: =('Kwh Reading'!Q6-'Kwh Reading'!Q5)*1000 -> 390 | U3: =('Kwh Reading'!N6-'Kwh Reading'!N5)*1000 -> 400 | V3: ='Kwh Reading'!E6-'Kwh Reading'!E5 -> 2864.43 | W3: ='Kwh Reading'!D6-'Kwh Reading'!D5 -> 1578.76 | X3: =('Kwh Reading'!O6-'Kwh Reading'!O5)*1000 -> 300
A4: Maldives at Kuda Huraa | B4: =B3+1 -> 3 | C4: 1 | D4: 2023 | E4: =('Kwh Reading'!T7-'Kwh Reading'!T6)*1000 -> 660 | F4: =('Kwh Reading'!F7-'Kwh Reading'!F6)*1000000 -> 2600 | G4: =('Kwh Reading'!C7-'Kwh Reading'!C6)*1000 -> 270 | H4: =I4+J4+K4 -> 1990 | I4: =('Kwh Reading'!J7-'Kwh Reading'!J6)*1000 -> 960 | J4: =('Kwh Reading'!K7-'Kwh Reading'!K6)*1000 -> 520 | K4: =('Kwh Reading'!L7-'Kwh Reading'!L6)*1000 -> 510 | L4: =('Kwh Reading'!R7-'Kwh Reading'!R6)*1000 -> 0 | M4: =('Kwh Reading'!S7-'Kwh Reading'!S6)*1000 -> 0 | N4: =('Kwh Reading'!I7-'Kwh Reading'!I6)*1000 -> 330 | O4: =('Kwh Reading'!B7-'Kwh Reading'!B6)*1000000 -> 1000 | P4: =('Kwh Reading'!M7-'Kwh Reading'!M6)*1000 -> 480 | Q4: =('Kwh Reading'!H7-'Kwh Reading'!H6)*1000000 -> 600 | R4: =('Kwh Reading'!P7-'Kwh Reading'!P6)*1000000 -> 400 | S4: =('Kwh Reading'!G7-'Kwh Reading'!G6)*1000000 -> 500 | T4: =('Kwh Reading'!Q7-'Kwh Reading'!Q6)*1000 -> 360 | U4: =('Kwh Reading'!N7-'Kwh Reading'!N6)*1000 -> 370 | V4: ='Kwh Reading'!E7-'Kwh Reading'!E6 -> 2674.3 | W4: ='Kwh Reading'!D7-'Kwh Reading'!D6 -> 1533.05 | X4: =('Kwh Reading'!O7-'Kwh Reading'!O6)*1000 -> 280
A5: Maldives at Kuda Huraa | B5: =B4+1 -> 4 | C5: 1 | D5: 2023 | E5: =('Kwh Reading'!T8-'Kwh Reading'!T7)*1000 -> 660 | F5: =('Kwh Reading'!F8-'Kwh Reading'!F7)*1000000 -> 2600 | G5: =('Kwh Reading'!C8-'Kwh Reading'!C7)*1000 -> 290 | H5: =I5+J5+K5 -> 2080 | I5: =('Kwh Reading'!J8-'Kwh Reading'!J7)*1000 -> 990 | J5: =('Kwh Reading'!K8-'Kwh Reading'!K7)*1000 -> 570 | K5: =('Kwh Reading'!L8-'Kwh Reading'!L7)*1000 -> 520 | L5: =('Kwh Reading'!R8-'Kwh Reading'!R7)*1000 -> 0 | M5: =('Kwh Reading'!S8-'Kwh Reading'!S7)*1000 -> 0 | N5: =('Kwh Reading'!I8-'Kwh Reading'!I7)*1000 -> 320 | O5: =('Kwh Reading'!B8-'Kwh Reading'!B7)*1000000 -> 1100 | P5: =('Kwh Reading'!M8-'Kwh Reading'!M7)*1000 -> 520 | Q5: =('Kwh Reading'!H8-'Kwh Reading'!H7)*1000000 -> 700 | R5: =('Kwh Reading'!P8-'Kwh Reading'!P7)*1000000 -> 600 | S5: =('Kwh Reading'!G8-'Kwh Reading'!G7)*1000000 -> 600 | T5: =('Kwh Reading'!Q8-'Kwh Reading'!Q7)*1000 -> 370 | U5: =('Kwh Reading'!N8-'Kwh Reading'!N7)*1000 -> 400 | V5: ='Kwh Reading'!E8-'Kwh Reading'!E7 -> 2734.96 | W5: ='Kwh Reading'!D8-'Kwh Reading'!D7 -> 1641.5 | X5: =('Kwh Reading'!O8-'Kwh Reading'!O7)*1000 -> 260
A6: Maldives at Kuda Huraa | B6: =B5+1 -> 5 | C6: 1 | D6: 2023 | E6: =('Kwh Reading'!T9-'Kwh Reading'!T8)*1000 -> 640 | F6: =('Kwh Reading'!F9-'Kwh Reading'!F8)*1000000 -> 2500 | G6: =('Kwh Reading'!C9-'Kwh Reading'!C8)*1000 -> 290 | H6: =I6+J6+K6 -> 1980 | I6: =('Kwh Reading'!J9-'Kwh Reading'!J8)*1000 -> 890 | J6: =('Kwh Reading'!K9-'Kwh Reading'!K8)*1000 -> 530 | K6: =('Kwh Reading'!L9-'Kwh Reading'!L8)*1000 -> 560 | L6: =('Kwh Reading'!R9-'Kwh Reading'!R8)*1000 -> 0 | M6: =('Kwh Reading'!S9-'Kwh Reading'!S8)*1000 -> 0 | N6: =('Kwh Reading'!I9-'Kwh Reading'!I8)*1000 -> 340 | O6: =('Kwh Reading'!B9-'Kwh Reading'!B8)*1000000 -> 1100 | P6: =('Kwh Reading'!M9-'Kwh Reading'!M8)*1000 -> 480 | Q6: =('Kwh Reading'!H9-'Kwh Reading'!H8)*1000000 -> 700 | R6: =('Kwh Reading'!P9-'Kwh Reading'!P8)*1000000 -> 600 | S6: =('Kwh Reading'!G9-'Kwh Reading'!G8)*1000000 -> 500 | T6: =('Kwh Reading'!Q9-'Kwh Reading'!Q8)*1000 -> 360 | U6: =('Kwh Reading'!N9-'Kwh Reading'!N8)*1000 -> 350 | V6: ='Kwh Reading'!E9-'Kwh Reading'!E8 -> 2827.42 | W6: ='Kwh Reading'!D9-'Kwh Reading'!D8 -> 1619.62 | X6: =('Kwh Reading'!O9-'Kwh Reading'!O8)*1000 -> 280
A7: Maldives at Kuda Huraa | B7: =B6+1 -> 6 | C7: 1 | D7: 2023 | E7: =('Kwh Reading'!T10-'Kwh Reading'!T9)*1000 -> 450 | F7: =('Kwh Reading'!F10-'Kwh Reading'!F9)*1000000 -> 2600 | G7: =('Kwh Reading'!C10-'Kwh Reading'!C9)*1000 -> 280 | H7: =I7+J7+K7 -> 1840 | I7: =('Kwh Reading'!J10-'Kwh Reading'!J9)*1000 -> 830 | J7: =('Kwh Reading'!K10-'Kwh Reading'!K9)*1000 -> 510 | K7: =('Kwh Reading'!L10-'Kwh Reading'!L9)*1000 -> 500 | L7: =('Kwh Reading'!R10-'Kwh Reading'!R9)*1000 -> 0 | M7: =('Kwh Reading'!S10-'Kwh Reading'!S9)*1000 -> 0 | N7: =('Kwh Reading'!I10-'Kwh Reading'!I9)*1000 -> 340 | O7: =('Kwh Reading'!B10-'Kwh Reading'!B9)*1000000 -> 1100 | P7: =('Kwh Reading'!M10-'Kwh Reading'!M9)*1000 -> 500 | Q7: =('Kwh Reading'!H10-'Kwh Reading'!H9)*1000000 -> 800 | R7: =('Kwh Reading'!P10-'Kwh Reading'!P9)*1000000 -> 500 | S7: =('Kwh Reading'!G10-'Kwh Reading'!G9)*1000000 -> 500 | T7: =('Kwh Reading'!Q10-'Kwh Reading'!Q9)*1000 -> 360 | U7: =('Kwh Reading'!N10-'Kwh Reading'!N9)*1000 -> 350 | V7: ='Kwh Reading'!E10-'Kwh Reading'!E9 -> 2766.15 | W7: ='Kwh Reading'!D10-'Kwh Reading'!D9 -> 1745.37 | X7: =('Kwh Reading'!O10-'Kwh Reading'!O9)*1000 -> 280
A8: Maldives at Kuda Huraa | B8: =B7+1 -> 7 | C8: 1 | D8: 2023 | E8: =('Kwh Reading'!T11-'Kwh Reading'!T10)*1000 -> 690 | F8: =('Kwh Reading'!F11-'Kwh Reading'!F10)*1000000 -> 2500 | G8: =('Kwh Reading'!C11-'Kwh Reading'!C10)*1000 -> 270 | H8: =I8+J8+K8 -> 2490 | I8: =('Kwh Reading'!J11-'Kwh Reading'!J10)*1000 -> 940 | J8: =('Kwh Reading'!K11-'Kwh Reading'!K10)*1000 -> 480 | K8: =('Kwh Reading'!L11-'Kwh Reading'!L10)*1000 -> 1070 | L8: =('Kwh Reading'!R11-'Kwh Reading'!R10)*1000 -> 0 | M8: =('Kwh Reading'!S11-'Kwh Reading'!S10)*1000 -> 0 | N8: =('Kwh Reading'!I11-'Kwh Reading'!I10)*1000 -> 310 | O8: =('Kwh Reading'!B11-'Kwh Reading'!B10)*1000000 -> 1200 | P8: =('Kwh Reading'!M11-'Kwh Reading'!M10)*1000 -> 520 | Q8: =('Kwh Reading'!H11-'Kwh Reading'!H10)*1000000 -> 700 | R8: =('Kwh Reading'!P11-'Kwh Reading'!P10)*1000000 -> 500 | S8: =('Kwh Reading'!G11-'Kwh Reading'!G10)*1000000 -> 500 | T8: =('Kwh Reading'!Q11-'Kwh Reading'!Q10)*1000 -> 360 | U8: =('Kwh Reading'!N11-'Kwh Reading'!N10)*1000 -> 400 | V8: ='Kwh Reading'!E11-'Kwh Reading'!E10 -> 2842.29 | W8: ='Kwh Reading'!D11-'Kwh Reading'!D10 -> 1799.06 | X8: =('Kwh Reading'!O11-'Kwh Reading'!O10)*1000 -> 290
A9: Maldives at Kuda Huraa | B9: =B8+1 -> 8 | C9: 1 | D9: 2023 | E9: =('Kwh Reading'!T12-'Kwh Reading'!T11)*1000 -> 630 | F9: =('Kwh Reading'!F12-'Kwh Reading'!F11)*1000000 -> 2600 | G9: =('Kwh Reading'!C12-'Kwh Reading'!C11)*1000 -> 280 | H9: =I9+J9+K9 -> 1510 | I9: =('Kwh Reading'!J12-'Kwh Reading'!J11)*1000 -> 910 | J9: =('Kwh Reading'!K12-'Kwh Reading'!K11)*1000 -> 540 | K9: =('Kwh Reading'!L12-'Kwh Reading'!L11)*1000 -> 60 | L9: =('Kwh Reading'!R12-'Kwh Reading'!R11)*1000 -> 0 | M9: =('Kwh Reading'!S12-'Kwh Reading'!S11)*1000 -> 0 | N9: =('Kwh Reading'!I12-'Kwh Reading'!I11)*1000 -> 300 | O9: =('Kwh Reading'!B12-'Kwh Reading'!B11)*1000000 -> 1100 | P9: =('Kwh Reading'!M12-'Kwh Reading'!M11)*1000 -> 450 | Q9: =('Kwh Reading'!H12-'Kwh Reading'!H11)*1000000 -> 700 | R9: =('Kwh Reading'!P12-'Kwh Reading'!P11)*1000000 -> 500 | S9: =('Kwh Reading'!G12-'Kwh Reading'!G11)*1000000 -> 500 | T9: =('Kwh Reading'!Q12-'Kwh Reading'!Q11)*1000 -> 400 | U9: =('Kwh Reading'!N12-'Kwh Reading'!N11)*1000 -> 400 | V9: ='Kwh Reading'!E12-'Kwh Reading'!E11 -> 2653.07 | W9: ='Kwh Reading'!D12-'Kwh Reading'!D11 -> 1648.01 | X9: =('Kwh Reading'!O12-'Kwh Reading'!O11)*1000 -> 290
A10: Maldives at Kuda Huraa | B10: =B9+1 -> 9 | C10: 1 | D10: 2023 | E10: =('Kwh Reading'!T13-'Kwh Reading'!T12)*1000 -> 570 | F10: =('Kwh Reading'!F13-'Kwh Reading'!F12)*1000000 -> 2700 | G10: =('Kwh Reading'!C13-'Kwh Reading'!C12)*1000 -> 270 | H10: =I10+J10+K10 -> 2028 | I10: =('Kwh Reading'!J13-'Kwh Reading'!J12)*1000 -> 988 | J10: =('Kwh Reading'!K13-'Kwh Reading'!K12)*1000 -> 530 | K10: =('Kwh Reading'!L13-'Kwh Reading'!L12)*1000 -> 510 | L10: =('Kwh Reading'!R13-'Kwh Reading'!R12)*1000 -> 0 | M10: =('Kwh Reading'!S13-'Kwh Reading'!S12)*1000 -> 0 | N10: =('Kwh Reading'!I13-'Kwh Reading'!I12)*1000 -> 300 | O10: =('Kwh Reading'!B13-'Kwh Reading'!B12)*1000000 -> 1100 | P10: =('Kwh Reading'!M13-'Kwh Reading'!M12)*1000 -> 460 | Q10: =('Kwh Reading'!H13-'Kwh Reading'!H12)*1000000 -> 700 | R10: =('Kwh Reading'!P13-'Kwh Reading'!P12)*1000000 -> 600 | S10: =('Kwh Reading'!G13-'Kwh Reading'!G12)*1000000 -> 600 | T10: =('Kwh Reading'!Q13-'Kwh Reading'!Q12)*1000 -> 340 | U10: =('Kwh Reading'!N13-'Kwh Reading'!N12)*1000 -> 360 | V10: ='Kwh Reading'!E13-'Kwh Reading'!E12 -> 2734.17 | W10: ='Kwh Reading'!D13-'Kwh Reading'!D12 -> 1885.63 | X10: =('Kwh Reading'!O13-'Kwh Reading'!O12)*1000 -> 250
A11: Maldives at Kuda Huraa | B11: =B10+1 -> 10 | C11: 1 | D11: 2023 | E11: =('Kwh Reading'!T14-'Kwh Reading'!T13)*1000 -> 540 | F11: =('Kwh Reading'!F14-'Kwh Reading'!F13)*1000000 -> 2600 | G11: =('Kwh Reading'!C14-'Kwh Reading'!C13)*1000 -> 300 | H11: =I11+J11+K11 -> 2142 | I11: =('Kwh Reading'!J14-'Kwh Reading'!J13)*1000 -> 1072 | J11: =('Kwh Reading'!K14-'Kwh Reading'!K13)*1000 -> 520 | K11: =('Kwh Reading'!L14-'Kwh Reading'!L13)*1000 -> 550 | L11: =('Kwh Reading'!R14-'Kwh Reading'!R13)*1000 -> 0 | M11: =('Kwh Reading'!S14-'Kwh Reading'!S13)*1000 -> 0 | N11: =('Kwh Reading'!I14-'Kwh Reading'!I13)*1000 -> 300 | O11: =('Kwh Reading'!B14-'Kwh Reading'!B13)*1000000 -> 1100 | P11: =('Kwh Reading'!M14-'Kwh Reading'!M13)*1000 -> 460 | Q11: =('Kwh Reading'!H14-'Kwh Reading'!H13)*1000000 -> 700 | R11: =('Kwh Reading'!P14-'Kwh Reading'!P13)*1000000 -> 500 | S11: =('Kwh Reading'!G14-'Kwh Reading'!G13)*1000000 -> 500 | T11: =('Kwh Reading'!Q14-'Kwh Reading'!Q13)*1000 -> 320 | U11: =('Kwh Reading'!N14-'Kwh Reading'!N13)*1000 -> 400 | V11: ='Kwh Reading'!E14-'Kwh Reading'!E13 -> 2626.94 | W11: ='Kwh Reading'!D14-'Kwh Reading'!D13 -> 1693.718 | X11: =('Kwh Reading'!O14-'Kwh Reading'!O13)*1000 -> 260
A12: Maldives at Kuda Huraa | B12: =B11+1 -> 11 | C12: 1 | D12: 2023 | E12: =('Kwh Reading'!T15-'Kwh Reading'!T14)*1000 -> 590 | F12: =('Kwh Reading'!F15-'Kwh Reading'!F14)*1000000 -> 2600 | G12: =('Kwh Reading'!C15-'Kwh Reading'!C14)*1000 -> 260 | H12: =I12+J12+K12 -> 1790 | I12: =('Kwh Reading'!J15-'Kwh Reading'!J14)*1000 -> 770 | J12: =('Kwh Reading'!K15-'Kwh Reading'!K14)*1000 -> 500 | K12: =('Kwh Reading'!L15-'Kwh Reading'!L14)*1000 -> 520 | L12: =('Kwh Reading'!R15-'Kwh Reading'!R14)*1000 -> 0 | M12: =('Kwh Reading'!S15-'Kwh Reading'!S14)*1000 -> 0 | N12: =('Kwh Reading'!I15-'Kwh Reading'!I14)*1000 -> 270 | O12: =('Kwh Reading'!B15-'Kwh Reading'!B14)*1000000 -> 1100 | P12: =('Kwh Reading'!M15-'Kwh Reading'!M14)*1000 -> 490 | Q12: =('Kwh Reading'!H15-'Kwh Reading'!H14)*1000000 -> 600 | R12: =('Kwh Reading'!P15-'Kwh Reading'!P14)*1000000 -> 400 | S12: =('Kwh Reading'!G15-'Kwh Reading'!G14)*1000000 -> 500 | T12: =('Kwh Reading'!Q15-'Kwh Reading'!Q14)*1000 -> 380 | U12: =('Kwh Reading'!N15-'Kwh Reading'!N14)*1000 -> 380 | V12: ='Kwh Reading'!E15-'Kwh Reading'!E14 -> 2610.91 | W12: ='Kwh Reading'!D15-'Kwh Reading'!D14 -> 1537.022 | X12: =('Kwh Reading'!O15-'Kwh Reading'!O14)*1000 -> 220
A13: Maldives at Kuda Huraa | B13: =B12+1 -> 12 | C13: 1 | D13: 2023 | E13: =('Kwh Reading'!T16-'Kwh Reading'!T15)*1000 -> 440 | F13: =('Kwh Reading'!F16-'Kwh Reading'!F15)*1000000 -> 2600 | G13: =('Kwh Reading'!C16-'Kwh Reading'!C15)*1000 -> 290 | H13: =I13+J13+K13 -> 1680 | I13: =('Kwh Reading'!J16-'Kwh Reading'!J15)*1000 -> 780 | J13: =('Kwh Reading'!K16-'Kwh Reading'!K15)*1000 -> 460 | K13: =('Kwh Reading'!L16-'Kwh Reading'!L15)*1000 -> 440 | L13: =('Kwh Reading'!R16-'Kwh Reading'!R15)*1000 -> 0 | M13: =('Kwh Reading'!S16-'Kwh Reading'!S15)*1000 -> 0 | N13: =('Kwh Reading'!I16-'Kwh Reading'!I15)*1000 -> 300 | O13: =('Kwh Reading'!B16-'Kwh Reading'!B15)*1000000 -> 1000 | P13: =('Kwh Reading'!M16-'Kwh Reading'!M15)*1000 -> 520 | Q13: =('Kwh Reading'!H16-'Kwh Reading'!H15)*1000000 -> 700 | R13: =('Kwh Reading'!P16-'Kwh Reading'!P15)*1000000 -> 600 | S13: =('Kwh Reading'!G16-'Kwh Reading'!G15)*1000000 -> 600 | T13: =('Kwh Reading'!Q16-'Kwh Reading'!Q15)*1000 -> 340 | U13: =('Kwh Reading'!N16-'Kwh Reading'!N15)*1000 -> 360 | V13: ='Kwh Reading'!E16-'Kwh Reading'!E15 -> 2421.43 | W13: ='Kwh Reading'!D16-'Kwh Reading'!D15 -> 1361.8 | X13: =('Kwh Reading'!O16-'Kwh Reading'!O15)*1000 -> 250
A14: Maldives at Kuda Huraa | B14: =B13+1 -> 13 | C14: 1 | D14: 2023 | E14: =('Kwh Reading'!T17-'Kwh Reading'!T16)*1000 -> 450 | F14: =('Kwh Reading'!F17-'Kwh Reading'!F16)*1000000 -> 2500 | G14: =('Kwh Reading'!C17-'Kwh Reading'!C16)*1000 -> 270 | H14: =I14+J14+K14 -> 1520 | I14: =('Kwh Reading'!J17-'Kwh Reading'!J16)*1000 -> 620 | J14: =('Kwh Reading'!K17-'Kwh Reading'!K16)*1000 -> 430 | K14: =('Kwh Reading'!L17-'Kwh Reading'!L16)*1000 -> 470 | L14: =('Kwh Reading'!R17-'Kwh Reading'!R16)*1000 -> 0 | M14: =('Kwh Reading'!S17-'Kwh Reading'!S16)*1000 -> 0 | N14: =('Kwh Reading'!I17-'Kwh Reading'!I16)*1000 -> 270 | O14: =('Kwh Reading'!B17-'Kwh Reading'!B16)*1000000 -> 1000 | P14: =('Kwh Reading'!M17-'Kwh Reading'!M16)*1000 -> 460 | Q14: =('Kwh Reading'!H17-'Kwh Reading'!H16)*1000000 -> 600 | R14: =('Kwh Reading'!P17-'Kwh Reading'!P16)*1000000 -> 400 | S14: =('Kwh Reading'!G17-'Kwh Reading'!G16)*1000000 -> 500 | T14: =('Kwh Reading'!Q17-'Kwh Reading'!Q16)*1000 -> 360 | U14: =('Kwh Reading'!N17-'Kwh Reading'!N16)*1000 -> 370 | V14: ='Kwh Reading'!E17-'Kwh Reading'!E16 -> 2266.15 | W14: ='Kwh Reading'!D17-'Kwh Reading'!D16 -> 1459.41 | X14: =('Kwh Reading'!O17-'Kwh Reading'!O16)*1000 -> 240
... A31: Maldives at Kuda Huraa | B31: =B30+1 -> 30 | C31: 1 | D31: 2023 | E31: =('Kwh Reading'!T34-'Kwh Reading'!T33)*1000 -> -701400 | F31: =('Kwh Reading'!F34-'Kwh Reading'!F33)*1000000 -> -3883500 | G31: =('Kwh Reading'!C34-'Kwh Reading'!C33)*1000 -> -375750 | H31: =I31+J31+K31 -> -1503500 | I31: =('Kwh Reading'!J34-'Kwh Reading'!J33)*1000 -> -590000 | J31: =('Kwh Reading'!K34-'Kwh Reading'!K33)*1000 -> -537640 | K31: =('Kwh Reading'!L34-'Kwh Reading'!L33)*1000 -> -375860 | L31: =('Kwh Reading'!R34-'Kwh Reading'!R33)*1000 -> 0 | M31: =('Kwh Reading'!S34-'Kwh Reading'!S33)*1000 -> 0 | N31: =('Kwh Reading'!I34-'Kwh Reading'!I33)*1000 -> -408610 | O31: =('Kwh Reading'!B34-'Kwh Reading'!B33)*1000000 -> -1633100 | P31: =('Kwh Reading'!M34-'Kwh Reading'!M33)*1000 -> -900920 | Q31: =('Kwh Reading'!H34-'Kwh Reading'!H33)*1000000 -> -1127200 | R31: =('Kwh Reading'!P34-'Kwh Reading'!P33)*1000000 -> -1090200 | S31: =('Kwh Reading'!G34-'Kwh Reading'!G33)*1000000 -> -1195900 | T31: =('Kwh Reading'!Q34-'Kwh Reading'!Q33)*1000 -> -790130 | U31: =('Kwh Reading'!N34-'Kwh Reading'!N33)*1000 -> -813420 | V31: ='Kwh Reading'!E34-'Kwh Reading'!E33 -> -9716611.7 | W31: ='Kwh Reading'!D34-'Kwh Reading'!D33 -> -179780.67 | X31: =('Kwh Reading'!O34-'Kwh Reading'!O33)*1000 -> -276010
A32: Maldives at Kuda Huraa | B32: =B31+1 -> 31 | C32: 1 | D32: 2023
A33: Total | E33: =SUM(E2:E31) -> -686220 | F33: =SUM(F2:F31) -> -3812500 | G33: =SUM(G2:G31) -> -368230 | I33: =SUM(I2:I31) -> -568930 | J33: =SUM(J2:J31) -> -525350 | K33: =SUM(K2:K31) -> -363610 | L33: =SUM(L2:L31) -> 0 | M33: =SUM(M2:M31) -> 0 | N33: =SUM(N2:N31) -> -400020 | O33: =SUM(O2:O31) -> -1601900 | P33: =SUM(P2:P31) -> -887790 | ... X33: =SUM(X2:X31) -> -268880

Sheet Kwh Reading
A1: Electric Consumption Record (4pm)
A2: Month | B2: BOH-1/ B&C Block GWH | C2: Pastry MWH | D2: Feeder 401-419 KWH | E2: Feeder 301-319 KWH | F2: Kitchen GWH | G2: Feeder 201-208 GWH | H2: Feeder 113-123 | I2: M - Block /PC MWH | J2: Laundry MWH | M2: Feeder 101-112 MWH | N2: Feeder 217-224 | O2: Spa MWH | P2: Feeder 124-134 | Q2: Feeder 209-216 | R2: STP -1 &2 MWH | S2: STP -3 MWH | T2: Reef Club MWH | V2: Room Nights | W2: Total Guests | X2: Food Covers
J3: A | K3: B | L3: C
A4: 44927 | B4: 1.6019 | C4: 367.94 | D4: 134269.28 | E4: 9642325.1 | F4: 3.8098 | G4: 1.1812 | H4: 1.109 | I4: 400.02 | J4: 568.93 | K4: 525.35 | L4: 363.61 | M4: 887.79 | N4: 802.5 | O4: 268.88 | P4: 1.0766 | Q4: 780 | R4: 0 | S4: 0 | T4: 685.55
A5: 44928 | B5: 1.603 | C5: 368.23 | D5: 135730.73 | E5: 9644919.9 | F5: 3.8125 | G5: 1.1817 | H5: 1.1097 | I5: 400.38 | J5: 569.94 | K5: 525.91 | L5: 364.16 | M5: 888.27 | N5: 802.89 | O5: 269.15 | P5: 1.0771 | Q5: 780.4 | R5: 0 | S5: 0 | T5: 686.22
A6: 44929 | B6: 1.6041 | C6: 368.53 | D6: 137309.49 | E6: 9647784.3 | F6: 3.8151 | G6: 1.1822 | H6: 1.1104 | I6: 400.72 | J6: 570.94 | K6: 526.46 | L6: 364.74 | M6: 888.72 | N6: 803.29 | O6: 269.45 | P6: 1.0776 | Q6: 780.79 | R6: 0 | S6: 0 | T6: 686.92
A7: 44930 | B7: 1.6051 | C7: 368.8 | D7: 138842.54 | E7: 9650458.6 | F7: 3.8177 | G7: 1.1827 | H7: 1.111 | I7: 401.05 | J7: 571.9 | K7: 526.98 | L7: 365.25 | M7: 889.2 | N7: 803.66 | O7: 269.73 | P7: 1.078 | Q7: 781.15 | R7: 0 | S7: 0 | T7: 687.58
A8: 44931 | B8: 1.6062 | C8: 369.09 | D8: 140484.04 | E8: 9653193.6 | F8: 3.8203 | G8: 1.1833 | H8: 1.1117 | I8: 401.37 | J8: 572.89 | K8: 527.55 | L8: 365.77 | M8: 889.72 | N8: 804.06 | O8: 269.99 | P8: 1.0786 | Q8: 781.52 | R8: 0 | S8: 0 | T8: 688.24
A9: 44932 | B9: 1.6073 | C9: 369.38 | D9: 142103.66 | E9: 9656021 | F9: 3.8228 | G9: 1.1838 | H9: 1.1124 | I9: 401.71 | J9: 573.78 | K9: 528.08 | L9: 366.33 | M9: 890.2 | N9: 804.41 | O9: 270.27 | P9: 1.0792 | Q9: 781.88 | R9: 0 | S9: 0 | T9: 688.88
A10: 44933 | B10: 1.6084 | C10: 369.66 | D10: 143849.03 | E10: 9658787.2 | F10: 3.8254 | G10: 1.1843 | H10: 1.1132 | I10: 402.05 | J10: 574.61 | K10: 528.59 | L10: 366.83 | M10: 890.7 | N10: 804.76 | O10: 270.55 | P10: 1.0797 | Q10: 782.24 | R10: 0 | S10: 0 | T10: 689.33
A11: 44934 | B11: 1.6096 | C11: 369.93 | D11: 145648.09 | E11: 9661629.5 | F11: 3.8279 | G11: 1.1848 | H11: 1.1139 | I11: 402.36 | J11: 575.55 | K11: 529.07 | L11: 367.9 | M11: 891.22 | N11: 805.16 | O11: 270.84 | P11: 1.0802 | Q11: 782.6 | R11: 0 | S11: 0 | T11: 690.02
A12: 44935 | B12: 1.6107 | C12: 370.21 | D12: 147296.1 | E12: 9664282.5 | F12: 3.8305 | G12: 1.1853 | H12: 1.1146 | I12: 402.66 | J12: 576.46 | K12: 529.61 | L12: 367.96 | M12: 891.67 | N12: 805.56 | O12: 271.13 | P12: 1.0807 | Q12: 783 | R12: 0 | S12: 0 | T12: 690.65
A13: 44936 | B13: 1.6118 | C13: 370.48 | D13: 149181.73 | E13: 9667016.7 | F13: 3.8332 | G13: 1.1859 | H13: 1.1153 | I13: 402.96 | J13: 577.448 | K13: 530.14 | L13: 368.47 | M13: 892.13 | N13: 805.92 | O13: 271.38 | P13: 1.0813 | Q13: 783.34 | R13: 0 | S13: 0 | T13: 691.22
A14: 44937 | B14: 1.6129 | C14: 370.78 | D14: 150875.45 | E14: 9669643.6 | F14: 3.8358 | G14: 1.1864 | H14: 1.116 | I14: 403.26 | J14: 578.52 | K14: 530.66 | L14: 369.02 | M14: 892.59 | N14: 806.32 | O14: 271.64 | P14: 1.0818 | Q14: 783.66 | R14: 0 | S14: 0 | T14: 691.76
A15: 44938 | B15: 1.614 | C15: 371.04 | D15: 152412.47 | E15: 9672254.6 | F15: 3.8384 | G15: 1.1869 | H15: 1.1166 | I15: 403.53 | J15: 579.29 | K15: 531.16 | L15: 369.54 | M15: 893.08 | N15: 806.7 | O15: 271.86 | P15: 1.0822 | Q15: 784.04 | R15: 0 | S15: 0 | T15: 692.35
... A33: 44956 | B33: 1.6331 | C33: 375.75 | D33: 179780.67 | E33: 9716611.7 | F33: 3.8835 | G33: 1.1959 | H33: 1.1272 | I33: 408.61 | J33: 590 | K33: 537.64 | L33: 375.86 | M33: 900.92 | N33: 813.42 | O33: 276.01 | P33: 1.0902 | Q33: 790.13 | R33: 0 | S33: 0 | T33: 701.4
A34: 44957 | B34: 0 | C34: 0 | D34: 0 | E34: 0 | F34: 0 | G34: 0 | H34: 0 | I34: 0 | J34: 0 | K34: 0 | L34: 0 | M34: 0 | N34: 0 | O34: 0 | P34: 0 | Q34: 0 | R34: 0 | S34: 0 | T34: 0 | V34: =SUM(V4:V33) -> 0 | W34: =SUM(W4:W33) -> 0 | X34: =SUM(X4:X33) -> 0
T41: ……..

Sheet Kwh area wise 
A2: Month | B2: Total KWH | C2: Reef Club Kitchen KWH | D2: Main Kitchen KWH | E2: Pastry Kitchen KWH | F2: Laundry KWH | G2: STP KWH | H2: Kuda Huraa Accomodation KWH | I2: Guest Room Beach Pavilion & Beach Bungalow KWH | J2: Guest Room Water Bungalow KWH | K2: Spa KWH | L2: Others KWH
A3: ='Kwh Reading'!A4 -> 44927 | B3: =TOTAL!E2 -> 21240 | C3: =Submeters!E2 -> 0 | D3: =Submeters!F2 -> 0 | E3: =Submeters!G2 -> 0 | F3: =(Submeters!I2+Submeters!J2+Submeters!K2) -> 2120 | G3: =(Submeters!L2+Submeters!M2) -> 0 | H3: =(Submeters!N2+Submeters!O2) -> 1460 | I3: =(Submeters!P2+Submeters!Q2+Submeters!R2+Submeters!S2+Submeters!T2+Submeters!U2) -> 2970 | J3: =(Submeters!V2+Submeters!W2) -> 4056.25 | K3: =Submeters!X2 -> 270 | L3: =B3-C3-D3-E3-F3-G3-H3-I3-J3-K3 -> 10363.75
A4: ='Kwh Reading'!A5 -> 44928 | B4: =TOTAL!E3 -> 20900 | C4: =Submeters!E3 -> 700 | D4: =Submeters!F3 -> 2600 | E4: =Submeters!G3 -> 300 | F4: =(Submeters!I3+Submeters!J3+Submeters!K3) -> 2130 | G4: =(Submeters!L3+Submeters!M3) -> 0 | H4: =(Submeters!N3+Submeters!O3) -> 1440 | I4: =(Submeters!P3+Submeters!Q3+Submeters!R3+Submeters!S3+Submeters!T3+Submeters!U3) -> 2940 | J4: =(Submeters!V3+Submeters!W3) -> 4443.19 | K4: =Submeters!X3 -> 300 | L4: =B4-C4-D4-E4-F4-G4-H4-I4-J4-K4 -> 6046.81
A5: ='Kwh Reading'!A6 -> 44929 | B5: =TOTAL!E4 -> 20900 | C5: =Submeters!E4 -> 660 | D5: =Submeters!F4 -> 2600 | E5: =Submeters!G4 -> 270 | F5: =(Submeters!I4+Submeters!J4+Submeters!K4) -> 1990 | G5: =(Submeters!L4+Submeters!M4) -> 0 | H5: =(Submeters!N4+Submeters!O4) -> 1330 | I5: =(Submeters!P4+Submeters!Q4+Submeters!R4+Submeters!S4+Submeters!T4+Submeters!U4) -> 2710 | J5: =(Submeters!V4+Submeters!W4) -> 4207.35 | K5: =Submeters!X4 -> 280 | L5: =B5-C5-D5-E5-F5-G5-H5-I5-J5-K5 -> 6852.65
A6: ='Kwh Reading'!A7 -> 44930 | B6: =TOTAL!E5 -> 21310 | C6: =Submeters!E5 -> 660 | D6: =Submeters!F5 -> 2600 | E6: =Submeters!G5 -> 290 | F6: =(Submeters!I5+Submeters!J5+Submeters!K5) -> 2080 | G6: =(Submeters!L5+Submeters!M5) -> 0 | H6: =(Submeters!N5+Submeters!O5) -> 1420 | I6: =(Submeters!P5+Submeters!Q5+Submeters!R5+Submeters!S5+Submeters!T5+Submeters!U5) -> 3190 | J6: =(Submeters!V5+Submeters!W5) -> 4376.46 | K6: =Submeters!X5 -> 260 | L6: =B6-C6-D6-E6-F6-G6-H6-I6-J6-K6 -> 6433.54
A7: ='Kwh Reading'!A8 -> 44931 | B7: =TOTAL!E6 -> 20670 | C7: =Submeters!E6 -> 640 | D7: =Submeters!F6 -> 2500 | E7: =Submeters!G6 -> 290 | F7: =(Submeters!I6+Submeters!J6+Submeters!K6) -> 1980 | G7: =(Submeters!L6+Submeters!M6) -> 0 | H7: =(Submeters!N6+Submeters!O6) -> 1440 | I7: =(Submeters!P6+Submeters!Q6+Submeters!R6+Submeters!S6+Submeters!T6+Submeters!U6) -> 2990 | J7: =(Submeters!V6+Submeters!W6) -> 4447.04 | K7: =Submeters!X6 -> 280 | L7: =B7-C7-D7-E7-F7-G7-H7-I7-J7-K7 -> 6102.96
A8: ='Kwh Reading'!A9 -> 44932 | B8: =TOTAL!E7 -> 21630 | C8: =Submeters!E7 -> 450 | D8: =Submeters!F7 -> 2600 | E8: =Submeters!G7 -> 280 | F8: =(Submeters!I7+Submeters!J7+Submeters!K7) -> 1840 | G8: =(Submeters!L7+Submeters!M7) -> 0 | H8: =(Submeters!N7+Submeters!O7) -> 1440 | I8: =(Submeters!P7+Submeters!Q7+Submeters!R7+Submeters!S7+Submeters!T7+Submeters!U7) -> 3010 | J8: =(Submeters!V7+Submeters!W7) -> 4511.52 | K8: =Submeters!X7 -> 280 | L8: =B8-C8-D8-E8-F8-G8-H8-I8-J8-K8 -> 7218.48
A9: ='Kwh Reading'!A10 -> 44933 | B9: =TOTAL!E8 -> 21700 | C9: =Submeters!E8 -> 690 | D9: =Submeters!F8 -> 2500 | E9: =Submeters!G8 -> 270 | F9: =(Submeters!I8+Submeters!J8+Submeters!K8) -> 2490 | G9: =(Submeters!L8+Submeters!M8) -> 0 | H9: =(Submeters!N8+Submeters!O8) -> 1510 | I9: =(Submeters!P8+Submeters!Q8+Submeters!R8+Submeters!S8+Submeters!T8+Submeters!U8) -> 2980 | J9: =(Submeters!V8+Submeters!W8) -> 4641.35 | K9: =Submeters!X8 -> 290 | L9: =B9-C9-D9-E9-F9-G9-H9-I9-J9-K9 -> 6328.65
A10: ='Kwh Reading'!A11 -> 44934 | B10: =TOTAL!E9 -> 21120 | C10: =Submeters!E9 -> 630 | D10: =Submeters!F9 -> 2600 | E10: =Submeters!G9 -> 280 | F10: =(Submeters!I9+Submeters!J9+Submeters!K9) -> 1510 | G10: =(Submeters!L9+Submeters!M9) -> 0 | H10: =(Submeters!N9+Submeters!O9) -> 1400 | I10: =(Submeters!P9+Submeters!Q9+Submeters!R9+Submeters!S9+Submeters!T9+Submeters!U9) -> 2950 | J10: =(Submeters!V9+Submeters!W9) -> 4301.08 | K10: =Submeters!X9 -> 290 | L10: =B10-C10-D10-E10-F10-G10-H10-I10-J10-K10 -> 7158.92
A11: ='Kwh Reading'!A12 -> 44935 | B11: =TOTAL!E10 -> 21040 | C11: =Submeters!E10 -> 570 | D11: =Submeters!F10 -> 2700 | E11: =Submeters!G10 -> 270 | F11: =(Submeters!I10+Submeters!J10+Submeters!K10) -> 2028 | G11: =(Submeters!L10+Submeters!M10) -> 0 | H11: =(Submeters!N10+Submeters!O10) -> 1400 | I11: =(Submeters!P10+Submeters!Q10+Submeters!R10+Submeters!S10+Submeters!T10+Submeters!U10) -> 3060 | J11: =(Submeters!V10+Submeters!W10) -> 4619.8 | K11: =Submeters!X10 -> 250 | L11: =B11-C11-D11-E11-F11-G11-H11-I11-J11-K11 -> 6142.2
A12: ='Kwh Reading'!A13 -> 44936 | B12: =TOTAL!E11 -> 20440 | C12: =Submeters!E11 -> 540 | D12: =Submeters!F11 -> 2600 | E12: =Submeters!G11 -> 300 | F12: =(Submeters!I11+Submeters!J11+Submeters!K11) -> 2142 | G12: =(Submeters!L11+Submeters!M11) -> 0 | H12: =(Submeters!N11+Submeters!O11) -> 1400 | I12: =(Submeters!P11+Submeters!Q11+Submeters!R11+Submeters!S11+Submeters!T11+Submeters!U11) -> 2880 | J12: =(Submeters!V11+Submeters!W11) -> 4320.658 | K12: =Submeters!X11 -> 260 | L12: =B12-C12-D12-E12-F12-G12-H12-I12-J12-K12 -> 5997.342
A13: ='Kwh Reading'!A14 -> 44937 | B13: =TOTAL!E12 -> 20340 | C13: =Submeters!E12 -> 590 | D13: =Submeters!F12 -> 2600 | E13: =Submeters!G12 -> 260 | F13: =(Submeters!I12+Submeters!J12+Submeters!K12) -> 1790 | G13: =(Submeters!L12+Submeters!M12) -> 0 | H13: =(Submeters!N12+Submeters!O12) -> 1370 | I13: =(Submeters!P12+Submeters!Q12+Submeters!R12+Submeters!S12+Submeters!T12+Submeters!U12) -> 2750 | J13: =(Submeters!V12+Submeters!W12) -> 4147.932 | K13: =Submeters!X12 -> 220 | L13: =B13-C13-D13-E13-F13-G13-H13-I13-J13-K13 -> 6612.068
A14: ='Kwh Reading'!A15 -> 44938 | B14: =TOTAL!E13 -> 19520 | C14: =Submeters!E13 -> 440 | D14: =Submeters!F13 -> 2600 | E14: =Submeters!G13 -> 290 | F14: =(Submeters!I13+Submeters!J13+Submeters!K13) -> 1680 | G14: =(Submeters!L13+Submeters!M13) -> 0 | H14: =(Submeters!N13+Submeters!O13) -> 1300 | I14: =(Submeters!P13+Submeters!Q13+Submeters!R13+Submeters!S13+Submeters!T13+Submeters!U13) -> 3120 | J14: =(Submeters!V13+Submeters!W13) -> 3783.23 | K14: =Submeters!X13 -> 250 | L14: =B14-C14-D14-E14-F14-G14-H14-I14-J14-K14 -> 6056.77
... A32: ='Kwh Reading'!A33 -> 44956 | B32: =TOTAL!E31 -> 0 | C32: =Submeters!E31 -> -701400 | D32: =Submeters!F31 -> -3883500 | E32: =Submeters!G31 -> -375750 | F32: =(Submeters!I31+Submeters!J31+Submeters!K31) -> -1503500 | G32: =(Submeters!L31+Submeters!M31) -> 0 | H32: =(Submeters!N31+Submeters!O31) -> -2041710 | I32: =(Submeters!P31+Submeters!Q31+Submeters!R31+Submeters!S31+Submeters!T31+Submeters!U31) -> -5917770 | J32: =(Submeters!V31+Submeters!W31) -> -9896392.3 | K32: =Submeters!X31 -> -276010 | L32: =B32-C32-D32-E32-F32-G32-H32-I32-J32-K32 -> 24596032
A33: Total kwh | B33: =SUM(B3:B32) -> 571720 | C33: =SUM(C3:C32) -> -686220 | D33: =SUM(D3:D32) -> -3812500 | E33: =SUM(E3:E32) -> -368230 | F33: =SUM(F3:F32) -> -1457890 | G33: =SUM(G3:G32) -> 0 | H33: =SUM(H3:H32) -> -2001920 | I33: =SUM(I3:I32) -> -5837090 | ... L33: =SUM(L3:L32) -> 24781044 | M33: =C33+D33+E33+F33+G33+H33+I33+J33+K33+L33 -> 571720
A35: Total $ | B35: =TOTAL!F2 -> 0 | C35: =C33*B35 -> 0 | D35: =D33*B35 -> 0 | E35: =E33*B35 -> 0 | F35: =F33*B35 -> 0 | G35: =G33*B35 -> 0 | H35: =H33*B35 -> 0 | I35: =I33*B35 -> 0 | J35: =J33*B35 -> 0 | K35: =K33*B35 -> 0 | L35: =L33*B35 -> 0 | M35: =C35+D35+E35+F35+G35+H35+I35+J35+K35+L35 -> 0

Sheet  Kwh area wise $ 
A2: Month | B2: $ /Per KWH | C2: Total $ | D2: Reef Club $ | E2: Kitchen $ | F2: Pastry $ | G2: Laundry $ | H2: STP $ | I2: Kuda Huraa Accomodation $ | J2: Guest Room Beach Pavilion & Beach Bungalow $ | K2: Guest Room Water Bungalow $ | L2: Spa $ | M2: Others $
A3: ='Kwh Reading'!A4 -> 44927 | B3: =TOTAL!F2 -> 0 | C3: =Submeters!#REF!*' Kwh area wise $ '!B3 -> #REF! | D3: =Submeters!E2*' Kwh area wise $ '!B3 -> 0 | E3: =Submeters!F2*' Kwh area wise $ '!B3 -> 0 | F3: =Submeters!G2*' Kwh area wise $ '!B3 -> 0 | G3: =(Submeters!I2+Submeters!J2+Submeters!K2)*' Kwh area wise $ '!B3 -> 0 | H3: =(Submeters!L2+Submeters!M2)*' Kwh area wise $ '!B3 -> 0 | I3: =(Submeters!N2+Submeters!O2)*' Kwh area wise $ '!B3 -> 0 | J3: =(Submeters!P2+Submeters!Q2+Submeters!R2+Submeters!S2+Submeters!T2+Submeters!U2)*' Kwh area wise $ '!B3 -> 0 | K3: =(Submeters!V2+Submeters!W2)*' Kwh area wise $ '!B3 -> 0 | L3: =Submeters!X2*' Kwh area wise $ '!B3 -> 0 | M3: =Submeters!#REF!*' Kwh area wise $ '!B3 -> #REF!
A4: ='Kwh Reading'!A5 -> 44928 | B4: =TOTAL!F3 -> 0 | C4: =Submeters!#REF!*' Kwh area wise $ '!B4 -> #REF! | D4: =Submeters!E3*' Kwh area wise $ '!B4 -> 0 | E4: =Submeters!F3*' Kwh area wise $ '!B4 -> 0 | F4: =Submeters!G3*' Kwh area wise $ '!B4 -> 0 | G4: =(Submeters!I3+Submeters!J3+Submeters!K3)*' Kwh area wise $ '!B4 -> 0 | H4: =(Submeters!L3+Submeters!M3)*' Kwh area wise $ '!B4 -> 0 | I4: =(Submeters!N3+Submeters!O3)*' Kwh area wise $ '!B4 -> 0 | J4: =(Submeters!P3+Submeters!Q3+Submeters!R3+Submeters!S3+Submeters!T3+Submeters!U3)*' Kwh area wise $ '!B4 -> 0 | K4: =(Submeters!V3+Submeters!W3)*' Kwh area wise $ '!B4 -> 0 | L4: =Submeters!X3*' Kwh area wise $ '!B4 -> 0 | M4: =Submeters!#REF!*' Kwh area wise $ '!B4 -> #REF!
A5: ='Kwh Reading'!A6 -> 44929 | B5: =TOTAL!F4 -> 0 | C5: =Submeters!#REF!*' Kwh area wise $ '!B5 -> #REF! | D5: =Submeters!E4*' Kwh area wise $ '!B5 -> 0 | E5: =Submeters!F4*' Kwh area wise $ '!B5 -> 0 | F5: =Submeters!G4*' Kwh area wise $ '!B5 -> 0 | G5: =(Submeters!I4+Submeters!J4+Submeters!K4)*' Kwh area wise $ '!B5 -> 0 | H5: =(Submeters!L4+Submeters!M4)*' Kwh area wise $ '!B5 -> 0 | I5: =(Submeters!N4+Submeters!O4)*' Kwh area wise $ '!B5 -> 0 | J5: =(Submeters!P4+Submeters!Q4+Submeters!R4+Submeters!S4+Submeters!T4+Submeters!U4)*' Kwh area wise $ '!B5 -> 0 | K5: =(Submeters!V4+Submeters!W4)*' Kwh area wise $ '!B5 -> 0 | L5: =Submeters!X4*' Kwh area wise $ '!B5 -> 0 | M5: =Submeters!#REF!*' Kwh area wise $ '!B5 -> #REF!
A6: ='Kwh Reading'!A7 -> 44930 | B6: =TOTAL!F5 -> 0 | C6: =Submeters!#REF!*' Kwh area wise $ '!B6 -> #REF! | D6: =Submeters!E5*' Kwh area wise $ '!B6 -> 0 | E6: =Submeters!F5*' Kwh area wise $ '!B6 -> 0 | F6: =Submeters!G5*' Kwh area wise $ '!B6 -> 0 | G6: =(Submeters!I5+Submeters!J5+Submeters!K5)*' Kwh area wise $ '!B6 -> 0 | H6: =(Submeters!L5+Submeters!M5)*' Kwh area wise $ '!B6 -> 0 | I6: =(Submeters!N5+Submeters!O5)*' Kwh area wise $ '!B6 -> 0 | J6: =(Submeters!P5+Submeters!Q5+Submeters!R5+Submeters!S5+Submeters!T5+Submeters!U5)*' Kwh area wise $ '!B6 -> 0 | K6: =(Submeters!V5+Submeters!W5)*' Kwh area wise $ '!B6 -> 0 | L6: =Submeters!X5*' Kwh area wise $ '!B6 -> 0 | M6: =Submeters!#REF!*' Kwh area wise $ '!B6 -> #REF!
A7: ='Kwh Reading'!A8 -> 44931 | B7: =TOTAL!F6 -> 0 | C7: =Submeters!#REF!*' Kwh area wise $ '!B7 -> #REF! | D7: =Submeters!E6*' Kwh area wise $ '!B7 -> 0 | E7: =Submeters!F6*' Kwh area wise $ '!B7 -> 0 | F7: =Submeters!G6*' Kwh area wise $ '!B7 -> 0 | G7: =(Submeters!I6+Submeters!J6+Submeters!K6)*' Kwh area wise $ '!B7 -> 0 | H7: =(Submeters!L6+Submeters!M6)*' Kwh area wise $ '!B7 -> 0 | I7: =(Submeters!N6+Submeters!O6)*' Kwh area wise $ '!B7 -> 0 | J7: =(Submeters!P6+Submeters!Q6+Submeters!R6+Submeters!S6+Submeters!T6+Submeters!U6)*' Kwh area wise $ '!B7 -> 0 | K7: =(Submeters!V6+Submeters!W6)*' Kwh area wise $ '!B7 -> 0 | L7: =Submeters!X6*' Kwh area wise $ '!B7 -> 0 | M7: =Submeters!#REF!*' Kwh area wise $ '!B7 -> #REF!
A8: ='Kwh Reading'!A9 -> 44932 | B8: =TOTAL!F7 -> 0 | C8: =Submeters!#REF!*' Kwh area wise $ '!B8 -> #REF! | D8: =Submeters!E7*' Kwh area wise $ '!B8 -> 0 | E8: =Submeters!F7*' Kwh area wise $ '!B8 -> 0 | F8: =Submeters!G7*' Kwh area wise $ '!B8 -> 0 | G8: =(Submeters!I7+Submeters!J7+Submeters!K7)*' Kwh area wise $ '!B8 -> 0 | H8: =(Submeters!L7+Submeters!M7)*' Kwh area wise $ '!B8 -> 0 | I8: =(Submeters!N7+Submeters!O7)*' Kwh area wise $ '!B8 -> 0 | J8: =(Submeters!P7+Submeters!Q7+Submeters!R7+Submeters!S7+Submeters!T7+Submeters!U7)*' Kwh area wise $ '!B8 -> 0 | K8: =(Submeters!V7+Submeters!W7)*' Kwh area wise $ '!B8 -> 0 | L8: =Submeters!X7*' Kwh area wise $ '!B8 -> 0 | M8: =Submeters!#REF!*' Kwh area wise $ '!B8 -> #REF!
A9: ='Kwh Reading'!A10 -> 44933 | B9: =TOTAL!F8 -> 0 | C9: =Submeters!#REF!*' Kwh area wise $ '!B9 -> #REF! | D9: =Submeters!E8*' Kwh area wise $ '!B9 -> 0 | E9: =Submeters!F8*' Kwh area wise $ '!B9 -> 0 | F9: =Submeters!G8*' Kwh area wise $ '!B9 -> 0 | G9: =(Submeters!I8+Submeters!J8+Submeters!K8)*' Kwh area wise $ '!B9 -> 0 | H9: =(Submeters!L8+Submeters!M8)*' Kwh area wise $ '!B9 -> 0 | I9: =(Submeters!N8+Submeters!O8)*' Kwh area wise $ '!B9 -> 0 | J9: =(Submeters!P8+Submeters!Q8+Submeters!R8+Submeters!S8+Submeters!T8+Submeters!U8)*' Kwh area wise $ '!B9 -> 0 | K9: =(Submeters!V8+Submeters!W8)*' Kwh area wise $ '!B9 -> 0 | L9: =Submeters!X8*' Kwh area wise $ '!B9 -> 0 | M9: =Submeters!#REF!*' Kwh area wise $ '!B9 -> #REF!
A10: ='Kwh Reading'!A11 -> 44934 | B10: =TOTAL!F9 -> 0 | C10: =Submeters!#REF!*' Kwh area wise $ '!B10 -> #REF! | D10: =Submeters!E9*' Kwh area wise $ '!B10 -> 0 | E10: =Submeters!F9*' Kwh area wise $ '!B10 -> 0 | F10: =Submeters!G9*' Kwh area wise $ '!B10 -> 0 | G10: =(Submeters!I9+Submeters!J9+Submeters!K9)*' Kwh area wise $ '!B10 -> 0 | H10: =(Submeters!L9+Submeters!M9)*' Kwh area wise $ '!B10 -> 0 | I10: =(Submeters!N9+Submeters!O9)*' Kwh area wise $ '!B10 -> 0 | J10: =(Submeters!P9+Submeters!Q9+Submeters!R9+Submeters!S9+Submeters!T9+Submeters!U9)*' Kwh area wise $ '!B10 -> 0 | K10: =(Submeters!V9+Submeters!W9)*' Kwh area wise $ '!B10 -> 0 | L10: =Submeters!X9*' Kwh area wise $ '!B10 -> 0 | M10: =Submeters!#REF!*' Kwh area wise $ '!B10 -> #REF!
A11: ='Kwh Reading'!A12 -> 44935 | B11: =TOTAL!F10 -> 0 | C11: =Submeters!#REF!*' Kwh area wise $ '!B11 -> #REF! | D11: =Submeters!E10*' Kwh area wise $ '!B11 -> 0 | E11: =Submeters!F10*' Kwh area wise $ '!B11 -> 0 | F11: =Submeters!G10*' Kwh area wise $ '!B11 -> 0 | G11: =(Submeters!I10+Submeters!J10+Submeters!K10)*' Kwh area wise $ '!B11 -> 0 | H11: =(Submeters!L10+Submeters!M10)*' Kwh area wise $ '!B11 -> 0 | I11: =(Submeters!N10+Submeters!O10)*' Kwh area wise $ '!B11 -> 0 | J11: =(Submeters!P10+Submeters!Q10+Submeters!R10+Submeters!S10+Submeters!T10+Submeters!U10)*' Kwh area wise $ '!B11 -> 0 | K11: =(Submeters!V10+Submeters!W10)*' Kwh area wise $ '!B11 -> 0 | L11: =Submeters!X10*' Kwh area wise $ '!B11 -> 0 | M11: =Submeters!#REF!*' Kwh area wise $ '!B11 -> #REF!
A12: ='Kwh Reading'!A13 -> 44936 | B12: =TOTAL!F11 -> 0 | C12: =Submeters!#REF!*' Kwh area wise $ '!B12 -> #REF! | D12: =Submeters!E11*' Kwh area wise $ '!B12 -> 0 | E12: =Submeters!F11*' Kwh area wise $ '!B12 -> 0 | F12: =Submeters!G11*' Kwh area wise $ '!B12 -> 0 | G12: =(Submeters!I11+Submeters!J11+Submeters!K11)*' Kwh area wise $ '!B12 -> 0 | H12: =(Submeters!L11+Submeters!M11)*' Kwh area wise $ '!B12 -> 0 | I12: =(Submeters!N11+Submeters!O11)*' Kwh area wise $ '!B12 -> 0 | J12: =(Submeters!P11+Submeters!Q11+Submeters!R11+Submeters!S11+Submeters!T11+Submeters!U11)*' Kwh area wise $ '!B12 -> 0 | K12: =(Submeters!V11+Submeters!W11)*' Kwh area wise $ '!B12 -> 0 | L12: =Submeters!X11*' Kwh area wise $ '!B12 -> 0 | M12: =Submeters!#REF!*' Kwh area wise $ '!B12 -> #REF!
A13: ='Kwh Reading'!A14 -> 44937 | B13: =TOTAL!F12 -> 0 | C13: =Submeters!#REF!*' Kwh area wise $ '!B13 -> #REF! | D13: =Submeters!E12*' Kwh area wise $ '!B13 -> 0 | E13: =Submeters!F12*' Kwh area wise $ '!B13 -> 0 | F13: =Submeters!G12*' Kwh area wise $ '!B13 -> 0 | G13: =(Submeters!I12+Submeters!J12+Submeters!K12)*' Kwh area wise $ '!B13 -> 0 | H13: =(Submeters!L12+Submeters!M12)*' Kwh area wise $ '!B13 -> 0 | I13: =(Submeters!N12+Submeters!O12)*' Kwh area wise $ '!B13 -> 0 | J13: =(Submeters!P12+Submeters!Q12+Submeters!R12+Submeters!S12+Submeters!T12+Submeters!U12)*' Kwh area wise $ '!B13 -> 0 | K13: =(Submeters!V12+Submeters!W12)*' Kwh area wise $ '!B13 -> 0 | L13: =Submeters!X12*' Kwh area wise $ '!B13 -> 0 | M13: =Submeters!#REF!*' Kwh area wise $ '!B13 -> #REF!
A14: ='Kwh Reading'!A15 -> 44938 | B14: =TOTAL!F13 -> 0 | C14: =Submeters!#REF!*' Kwh area wise $ '!B14 -> #REF! | D14: =Submeters!E13*' Kwh area wise $ '!B14 -> 0 | E14: =Submeters!F13*' Kwh area wise $ '!B14 -> 0 | F14: =Submeters!G13*' Kwh area wise $ '!B14 -> 0 | G14: =(Submeters!I13+Submeters!J13+Submeters!K13)*' Kwh area wise $ '!B14 -> 0 | H14: =(Submeters!L13+Submeters!M13)*' Kwh area wise $ '!B14 -> 0 | I14: =(Submeters!N13+Submeters!O13)*' Kwh area wise $ '!B14 -> 0 | J14: =(Submeters!P13+Submeters!Q13+Submeters!R13+Submeters!S13+Submeters!T13+Submeters!U13)*' Kwh area wise $ '!B14 -> 0 | K14: =(Submeters!V13+Submeters!W13)*' Kwh area wise $ '!B14 -> 0 | L14: =Submeters!X13*' Kwh area wise $ '!B14 -> 0 | M14: =Submeters!#REF!*' Kwh area wise $ '!B14 -> #REF!
... A32: ='Kwh Reading'!A33 -> 44956 | B32: =TOTAL!F31 -> 0 | C32: =Submeters!#REF!*' Kwh area wise $ '!B32 -> #REF! | D32: =Submeters!E31*' Kwh area wise $ '!B32 -> 0 | E32: =Submeters!F31*' Kwh area wise $ '!B32 -> 0 | F32: =Submeters!G31*' Kwh area wise $ '!B32 -> 0 | G32: =(Submeters!I31+Submeters!J31+Submeters!K31)*' Kwh area wise $ '!B32 -> 0 | H32: =(Submeters!L31+Submeters!M31)*' Kwh area wise $ '!B32 -> 0 | I32: =(Submeters!N31+Submeters!O31)*' Kwh area wise $ '!B32 -> 0 | J32: =(Submeters!P31+Submeters!Q31+Submeters!R31+Submeters!S31+Submeters!T31+Submeters!U31)*' Kwh area wise $ '!B32 -> 0 | K32: =(Submeters!V31+Submeters!W31)*' Kwh area wise $ '!B32 -> 0 | L32: =Submeters!X31*' Kwh area wise $ '!B32 -> 0 | M32: =Submeters!#REF!*' Kwh area wise $ '!B32 -> #REF!
A33: Total | C33: =SUM(C3:C32) -> #REF! | D33: =SUM(D3:D32) -> 0 | E33: =SUM(E3:E32) -> 0 | F33: =SUM(F3:F32) -> 0 | G33: =SUM(G3:G32) -> 0 | H33: =SUM(H3:H32) -> 0 | I33: =SUM(I3:I32) -> 0 | J33: =SUM(J3:J32) -> 0 | ... M33: =SUM(M3:M32) -> #REF! | N33: =D33+E33+F33+G33+H33+I33+J33+K33+L33+M33 -> #REF!

Sheet Water Reading
B1: Meter 1 | C1: Meter 2 | D1: Meter 6 | E1: Meter 8 | F1: Meter 7 | G1: Meter 9 | H1: Meter 3 | I1: Meter 5 | J1: Meter 10 | K1: Meter 13 | L1: Meter 16 | M1: Meter 17 | N1: Meter 15 | O1: Meter 14 | P1: Meter 4 | Q1: Meter 11 | R1: Meter 12
A2: Date | B2: Main Meter 1 | C2: Main Meter 2 | D2: Beach Bunglow | E2: Kuda Huraa staff | F2: Bodu hura staff | G2: Laundry | H2: Water Bunglow | I2: Main Kitchen | J2: Second stage | K2: Supply jetty | L2: Staff housing A | M2: Staff housing B | N2: Spa | O2: Staff jetty | P2: Main pool | Q2: Reef club pool | R2: Reef club kitchen
A3: 44927 | B3: 26481 | C3: 41073 | D3: 301189 | E3: 286364 | F3: 26304 | G3: 124686 | H3: 614 | I3: 80326 | J3: 24068 | K3: 1024 | L3: 19597 | M3: 28749 | N3: 9090 | O3: 2479 | P3: 33017 | Q3: 2365 | R3: 1004
A4: 44928 | B4: 26661 | C4: 41423 | D4: 301366 | E4: 286536 | F4: 26304 | G4: 124732 | H4: 657 | I4: 80377 | J4: 24076 | K4: 1024 | L4: 19600 | M4: 28754 | N4: 9093 | O4: 2482 | P4: 33024 | Q4: 2368 | R4: 1011
A5: 44929 | B5: 26843 | C5: 41694 | D5: 301572 | E5: 286626 | F5: 26304 | G5: 124770 | H5: 700 | I5: 80399 | J5: 24084 | K5: 1024 | L5: 28761 | M5: 28761 | N5: 9097 | O5: 2484 | P5: 33030 | Q5: 2375 | R5: 1019
A6: 44930 | B6: 27035 | C6: 41983 | D6: 301799 | E6: 286716 | F6: 26342 | G6: 124781 | H6: 746 | I6: 80421 | J6: 24091 | K6: 1024 | L6: 19606 | M6: 28767 | N6: 9099 | O6: 2486 | P6: 33032 | Q6: 2379 | R6: 1026
A7: 44931 | B7: 27260 | C7: 42327 | D7: 302072 | E7: 286802 | F7: 26371 | G7: 124855 | H7: 849 | I7: 80439 | J7: 24099 | K7: 1024 | L7: 19609 | M7: 28773 | N7: 9102 | O7: 2488 | P7: 33095 | Q7: 2380 | R7: 1034
A8: 44932 | B8: 27450 | C8: 42602 | D8: 302302 | E8: 286879 | F8: 26401 | G8: 124894 | H8: 904 | I8: 80461 | J8: 24106 | K8: 1024 | L8: 19613 | M8: 28780 | N8: 9104 | O8: 2490 | P8: 33109 | Q8: 2387 | R8: 1039
A9: 44933 | B9: 27688 | C9: 42852 | D9: 302502 | E9: 286965 | F9: 26443 | G9: 124931 | H9: 966 | I9: 80471 | J9: 24114 | K9: 1024 | L9: 19616 | M9: 28786 | N9: 9107 | O9: 2491 | P9: 33111 | Q9: 2388 | R9: 1043
A10: 44934 | B10: 27816 | C10: 43158 | D10: 302747 | E10: 287049 | F10: 26477 | G10: 124971 | H10: 1010 | I10: 80499 | J10: 24122 | K10: 1024 | L10: 19619 | M10: 28792 | N10: 9109 | O10: 2495 | P10: 33139 | Q10: 2394 | R10: 1051
A11: 44935 | B11: 27991 | C11: 43467 | D11: 303008 | E11: 287139 | F11: 26514 | G11: 125010 | H11: 1059 | I11: 80504 | J11: 24129 | K11: 1024 | L11: 19623 | M11: 28802 | N11: 9111 | O11: 2498 | P11: 33145 | Q11: 2401 | R11: 1059
A12: 44936 | B12: 28134 | C12: 43752 | D12: 303232 | E12: 287220 | F12: 26548 | G12: 125049 | H12: 1094 | I12: 80535 | J12: 24136 | K12: 1024 | L12: 19627 | M12: 28809 | N12: 9113 | O12: 2500 | P12: 33160 | Q12: 2408 | R12: 1065
A13: 44937 | B13: 28322 | C13: 44035 | D13: 303451 | E13: 287300 | F13: 26584 | G13: 125091 | H13: 1137 | I13: 80555 | J13: 24143 | K13: 1024 | L13: 19630 | M13: 28816 | N13: 9116 | O13: 2502 | P13: 33176 | Q13: 2420 | R13: 1070
A14: 44938 | B14: 28478 | C14: 44311 | D14: 303643 | E14: 287396 | F14: 26617 | G14: 125133 | H14: 1175 | I14: 80574 | J14: 24149 | K14: 1024 | L14: 19633 | M14: 28822 | N14: 9137 | O14: 2504 | P14: 33190 | Q14: 2427 | R14: 1076
... A22: 44946 | B22: 29894 | C22: 46238 | D22: 305339 | E22: 288076 | F22: 26897 | G22: 125377 | H22: 1457 | I22: 80679 | J22: 24203 | K22: 1024 | L22: 19660 | M22: 28880 | N22: 9155 | O22: 2524 | P22: 33235 | Q22: 2467 | R22: 1113
A23: 44947 | B23: 30033 | C23: 46485 | D23: 305509 | E23: 288158 | F23: 26933 | G23: 125399 | H23: 1509 | I23: 80706 | J23: 24209 | K23: 1024 | L23: 19663 | M23: 28888 | N23: 9157 | O23: 2526 | P23: 33239 | Q23: 2470 | R23: 1117 | S23: .
A24: 44948 | B24: 30210 | C24: 46691 | D24: 305701 | E24: 288241 | F24: 26967 | G24: 125424 | H24: 1538 | I24: 80717 | J24: 24215 | K24: 1024 | L24: 19667 | M24: 28896 | N24: 9159 | O24: 2528 | P24: 33282 | Q24: 2470 | R24: 1118
A25: 44949 | B25: 30369 | C25: 46897 | D25: 305869 | E25: 288326 | F25: 27002 | G25: 125447 | H25: 1569 | I25: 80737 | J25: 24221 | K25: 1024 | L25: 19670 | M25: 28902 | N25: 9163 | O25: 2530 | P25: 33298 | Q25: 2483 | R25: 1122
A26: 44950 | B26: 30486 | C26: 47108 | D26: 306017 | E26: 288404 | F26: 27033 | G26: 125471 | H26: 1603 | I26: 80742 | J26: 24228 | K26: 1024 | L26: 19674 | M26: 28909 | N26: 9167 | O26: 2533 | P26: 33298 | Q26: 2491 | R26: 1127
A27: 44951 | B27: 30634 | C27: 47299 | D27: 306168 | E27: 288487 | F27: 27067 | G27: 125497 | H27: 1626 | I27: 80768 | J27: 24234 | K27: 1024 | L27: 19676 | M27: 28917 | N27: 9171 | O27: 2535 | P27: 33315 | Q27: 2500 | R27: 1131
A28: 44952 | B28: 30720 | C28: 47457 | D28: 306256 | E28: 288557 | F28: 27098 | G28: 125519 | H28: 1643 | I28: 80779 | J28: 24246 | K28: 1024 | L28: 19680 | M28: 28924 | N28: 9173 | O28: 2536 | P28: 33315 | Q28: 2500 | R28: 1135
A29: 44953 | B29: 30834 | C29: 47656 | D29: 306386 | E29: 288634 | F29: 27129 | G29: 125543 | H29: 1666 | I29: 80791 | J29: 24247 | K29: 1024 | L29: 19682 | M29: 28931 | N29: 9174 | O29: 2538 | P29: 33329 | Q29: 2504 | R29: 1139
A30: 44954 | B30: 30944 | C30: 47852 | D30: 306499 | E30: 288702 | F30: 27156 | G30: 125565 | H30: 1696 | I30: 80824 | J30: 24253 | K30: 1024 | L30: 19685 | M30: 28936 | N30: 9178 | O30: 2540 | P30: 33330 | Q30: 2505 | R30: 1143
A31: 44955 | B31: 31045 | C31: 48037 | D31: 306612 | E31: 288777 | F31: 27190 | G31: 125590 | H31: 1724 | I31: 80828 | J31: 24260 | K31: 1024 | L31: 19688 | M31: 28944 | N31: 9179 | O31: 2542 | P31: 33355 | Q31: 2512 | R31: 1146
A32: 44956 | B32: 31140 | C32: 48212 | D32: 306715 | E32: 288846 | F32: 27218 | G32: 125612 | H32: 1746 | I32: 80850 | J32: 24266 | K32: 1024 | L32: 19691 | M32: 28950 | N32: 9180 | O32: 2544 | P32: 33370 | Q32: 2516 | R32: 1150
A33: 44957 | B33: 0 | C33: 0 | D33: 0 | E33: 0 | F33: 0 | G33: 0 | H33: 0 | I33: 0 | J33: 0 | K33: 0 | L33: 0 | M33: 0 | N33: 0 | O33: 0 | P33: 0 | Q33: 0 | R33: 0

Sheet Water consumption
A2: Date | B2: RO production (Ro 1 : 4) | C2: Total Consumption M3 (Meter 1 : 2) | E2: Water Bunglow | G2: Beach bunglow | I2: Main Pool | K2: Main kitchen | M2: Reef club kitchen | O2: Reef club pool | Q2: Bodu Huraa staff | S2: Kuda Huraa staff | U2: Laundry | W2: Second stage | Y2: Total
C3: M3 | D3: % of Total production | E3: M3 | F3: % | G3: M3 | H3: % | I3: M3 | J3: % | K3: M3 | L3: % | M3: M3 | N3: % | O3: M3 | P3: % | Q3: M3 | R3: % | S3: M3 | T3: % | U3: M3 | V3: % | W3: M3 | X3: % | Y3: M3 | Z3: %
A4: ='Water Reading'!A3 -> 44927 | B4: =TOTAL!I2 -> 498 | C4: =('Water Reading'!B4-'Water Reading'!B3)+('Water Reading'!C4-'Water Reading'!C3) -> 530 | D4: =C4/B4 -> 1.064257 | E4: ='Water Reading'!H4-'Water Reading'!H3 -> 43 | F4: =E4/C4 -> 0.081132075 | G4: =('Water Reading'!D4-'Water Reading'!D3)-('Water Reading'!R4-'Water Reading'!R3)-('Water Reading'!Q4-'Water Reading'!Q3) -> 167 | H4: =G4/C4 -> 0.31509434 | I4: ='Water Reading'!P4-'Water Reading'!P3 -> 7 | J4: =I4/C4 -> 0.013207547 | K4: =('Water Reading'!I4-'Water Reading'!I3)-('Water Reading'!P4-'Water Reading'!P3) -> 44 | L4: =K4/C4 -> 0.083018868 | M4: ='Water Reading'!R4-'Water Reading'!R3 -> 7 | N4: =M4/C4 -> 0.013207547 | O4: ='Water Reading'!Q4-'Water Reading'!Q3 -> 3 | P4: =O4/C4 -> 0.0056603774 | Q4: ='Water Reading'!F4-'Water Reading'!F3 -> 0 | R4: =Q4/C4 -> 0 | S4: ='Water Reading'!E4-'Water Reading'!E3 -> 172 | T4: =S4/C4 -> 0.3245283 | U4: ='Water Reading'!G4-'Water Reading'!G3 -> 46 | V4: =U4/C4 -> 0.086792453 | W4: ='Water Reading'!J4-'Water Reading'!J3 -> 8 | X4: =W4/C4 -> 0.01509434 | Y4: =E4+I4+K4+M4+O4+G4+Q4+S4+U4+W4 -> 497 | Z4: =Y4/B4 -> 0.99799197
A5: ='Water Reading'!A4 -> 44928 | B5: =TOTAL!I3 -> 407 | C5: =('Water Reading'!B5-'Water Reading'!B4)+('Water Reading'!C5-'Water Reading'!C4) -> 453 | D5: =C5/B5 -> 1.1130221 | E5: ='Water Reading'!H5-'Water Reading'!H4 -> 43 | F5: =E5/C5 -> 0.094922737 | G5: =('Water Reading'!D5-'Water Reading'!D4)-('Water Reading'!R5-'Water Reading'!R4)-('Water Reading'!Q5-'Water Reading'!Q4) -> 191 | H5: =G5/C5 -> 0.42163355 | I5: ='Water Reading'!P5-'Water Reading'!P4 -> 6 | J5: =I5/C5 -> 0.013245033 | K5: =('Water Reading'!I5-'Water Reading'!I4)-('Water Reading'!P5-'Water Reading'!P4) -> 16 | L5: =K5/C5 -> 0.035320088 | M5: ='Water Reading'!R5-'Water Reading'!R4 -> 8 | N5: =M5/C5 -> 0.017660044 | O5: ='Water Reading'!Q5-'Water Reading'!Q4 -> 7 | P5: =O5/C5 -> 0.015452539 | Q5: ='Water Reading'!F5-'Water Reading'!F4 -> 0 | R5: =Q5/C5 -> 0 | S5: ='Water Reading'!E5-'Water Reading'!E4 -> 90 | T5: =S5/C5 -> 0.1986755 | U5: ='Water Reading'!G5-'Water Reading'!G4 -> 38 | V5: =U5/C5 -> 0.08388521 | W5: ='Water Reading'!J5-'Water Reading'!J4 -> 8 | X5: =W5/C5 -> 0.017660044 | Y5: =E5+I5+K5+M5+O5+G5+Q5+S5+U5+W5 -> 407 | Z5: =Y5/B5 -> 1
A6: ='Water Reading'!A5 -> 44929 | B6: =TOTAL!I4 -> 441 | C6: =('Water Reading'!B6-'Water Reading'!B5)+('Water Reading'!C6-'Water Reading'!C5) -> 481 | D6: =C6/B6 -> 1.0907029 | E6: ='Water Reading'!H6-'Water Reading'!H5 -> 46 | F6: =E6/C6 -> 0.095634096 | G6: =('Water Reading'!D6-'Water Reading'!D5)-('Water Reading'!R6-'Water Reading'!R5)-('Water Reading'!Q6-'Water Reading'!Q5) -> 216 | H6: =G6/C6 -> 0.44906445 | I6: ='Water Reading'!P6-'Water Reading'!P5 -> 2 | J6: =I6/C6 -> 0.0041580042 | K6: =('Water Reading'!I6-'Water Reading'!I5)-('Water Reading'!P6-'Water Reading'!P5) -> 20 | L6: =K6/C6 -> 0.041580042 | M6: ='Water Reading'!R6-'Water Reading'!R5 -> 7 | N6: =M6/C6 -> 0.014553015 | O6: ='Water Reading'!Q6-'Water Reading'!Q5 -> 4 | P6: =O6/C6 -> 0.0083160083 | Q6: ='Water Reading'!F6-'Water Reading'!F5 -> 38 | R6: =Q6/C6 -> 0.079002079 | S6: ='Water Reading'!E6-'Water Reading'!E5 -> 90 | T6: =S6/C6 -> 0.18711019 | U6: ='Water Reading'!G6-'Water Reading'!G5 -> 11 | V6: =U6/C6 -> 0.022869023 | W6: ='Water Reading'!J6-'Water Reading'!J5 -> 7 | X6: =W6/C6 -> 0.014553015 | Y6: =E6+I6+K6+M6+O6+G6+Q6+S6+U6+W6 -> 441 | Z6: =Y6/B6 -> 1
A7: ='Water Reading'!A6 -> 44930 | B7: =TOTAL!I5 -> 591 | C7: =('Water Reading'!B7-'Water Reading'!B6)+('Water Reading'!C7-'Water Reading'!C6) -> 569 | D7: =C7/B7 -> 0.96277496 | E7: ='Water Reading'!H7-'Water Reading'!H6 -> 103 | F7: =E7/C7 -> 0.18101933 | G7: =('Water Reading'!D7-'Water Reading'!D6)-('Water Reading'!R7-'Water Reading'!R6)-('Water Reading'!Q7-'Water Reading'!Q6) -> 264 | H7: =G7/C7 -> 0.46397188 | I7: ='Water Reading'!P7-'Water Reading'!P6 -> 63 | J7: =I7/C7 -> 0.11072056 | K7: =('Water Reading'!I7-'Water Reading'!I6)-('Water Reading'!P7-'Water Reading'!P6) -> -45 | L7: =K7/C7 -> -0.079086116 | M7: ='Water Reading'!R7-'Water Reading'!R6 -> 8 | N7: =M7/C7 -> 0.014059754 | O7: ='Water Reading'!Q7-'Water Reading'!Q6 -> 1 | P7: =O7/C7 -> 0.0017574692 | Q7: ='Water Reading'!F7-'Water Reading'!F6 -> 29 | R7: =Q7/C7 -> 0.050966608 | S7: ='Water Reading'!E7-'Water Reading'!E6 -> 86 | T7: =S7/C7 -> 0.15114236 | U7: ='Water Reading'!G7-'Water Reading'!G6 -> 74 | V7: =U7/C7 -> 0.13005272 | W7: ='Water Reading'!J7-'Water Reading'!J6 -> 8 | X7: =W7/C7 -> 0.014059754 | Y7: =E7+I7+K7+M7+O7+G7+Q7+S7+U7+W7 -> 591 | Z7: =Y7/B7 -> 1
A8: ='Water Reading'!A7 -> 44931 | B8: =TOTAL!I6 -> 460 | C8: =('Water Reading'!B8-'Water Reading'!B7)+('Water Reading'!C8-'Water Reading'!C7) -> 465 | D8: =C8/B8 -> 1.0108696 | E8: ='Water Reading'!H8-'Water Reading'!H7 -> 55 | F8: =E8/C8 -> 0.11827957 | G8: =('Water Reading'!D8-'Water Reading'!D7)-('Water Reading'!R8-'Water Reading'!R7)-('Water Reading'!Q8-'Water Reading'!Q7) -> 218 | H8: =G8/C8 -> 0.4688172 | I8: ='Water Reading'!P8-'Water Reading'!P7 -> 14 | J8: =I8/C8 -> 0.030107527 | K8: =('Water Reading'!I8-'Water Reading'!I7)-('Water Reading'!P8-'Water Reading'!P7) -> 8 | L8: =K8/C8 -> 0.017204301 | M8: ='Water Reading'!R8-'Water Reading'!R7 -> 5 | N8: =M8/C8 -> 0.010752688 | O8: ='Water Reading'!Q8-'Water Reading'!Q7 -> 7 | P8: =O8/C8 -> 0.015053763 | Q8: ='Water Reading'!F8-'Water Reading'!F7 -> 30 | R8: =Q8/C8 -> 0.064516129 | S8: ='Water Reading'!E8-'Water Reading'!E7 -> 77 | T8: =S8/C8 -> 0.1655914 | U8: ='Water Reading'!G8-'Water Reading'!G7 -> 39 | V8: =U8/C8 -> 0.083870968 | W8: ='Water Reading'!J8-'Water Reading'!J7 -> 7 | X8: =W8/C8 -> 0.015053763 | Y8: =E8+I8+K8+M8+O8+G8+Q8+S8+U8+W8 -> 460 | Z8: =Y8/B8 -> 1
A9: ='Water Reading'!A8 -> 44932 | B9: =TOTAL!I7 -> 445 | C9: =('Water Reading'!B9-'Water Reading'!B8)+('Water Reading'!C9-'Water Reading'!C8) -> 488 | D9: =C9/B9 -> 1.0966292 | E9: ='Water Reading'!H9-'Water Reading'!H8 -> 62 | F9: =E9/C9 -> 0.12704918 | G9: =('Water Reading'!D9-'Water Reading'!D8)-('Water Reading'!R9-'Water Reading'!R8)-('Water Reading'!Q9-'Water Reading'!Q8) -> 195 | H9: =G9/C9 -> 0.39959016 | I9: ='Water Reading'!P9-'Water Reading'!P8 -> 2 | J9: =I9/C9 -> 0.0040983607 | K9: =('Water Reading'!I9-'Water Reading'!I8)-('Water Reading'!P9-'Water Reading'!P8) -> 8 | L9: =K9/C9 -> 0.016393443 | M9: ='Water Reading'!R9-'Water Reading'!R8 -> 4 | N9: =M9/C9 -> 0.0081967213 | O9: ='Water Reading'!Q9-'Water Reading'!Q8 -> 1 | P9: =O9/C9 -> 0.0020491803 | Q9: ='Water Reading'!F9-'Water Reading'!F8 -> 42 | R9: =Q9/C9 -> 0.086065574 | S9: ='Water Reading'!E9-'Water Reading'!E8 -> 86 | T9: =S9/C9 -> 0.17622951 | U9: ='Water Reading'!G9-'Water Reading'!G8 -> 37 | V9: =U9/C9 -> 0.075819672 | W9: ='Water Reading'!J9-'Water Reading'!J8 -> 8 | X9: =W9/C9 -> 0.016393443 | Y9: =E9+I9+K9+M9+O9+G9+Q9+S9+U9+W9 -> 445 | Z9: =Y9/B9 -> 1
A10: ='Water Reading'!A9 -> 44933 | B10: =TOTAL!I8 -> 457 | C10: =('Water Reading'!B10-'Water Reading'!B9)+('Water Reading'!C10-'Water Reading'!C9) -> 434 | D10: =C10/B10 -> 0.94967177 | E10: 18 | F10: 0.061016949 | G10: =('Water Reading'!D10-'Water Reading'!D9)-('Water Reading'!R10-'Water Reading'!R9)-('Water Reading'!Q10-'Water Reading'!Q9) -> 231 | H10: =G10/C10 -> 0.53225806 | I10: ='Water Reading'!P10-'Water Reading'!P9 -> 28 | J10: =I10/C10 -> 0.064516129 | K10: =('Water Reading'!I10-'Water Reading'!I9)-('Water Reading'!P10-'Water Reading'!P9) -> 0 | L10: =K10/C10 -> 0 | M10: ='Water Reading'!R10-'Water Reading'!R9 -> 8 | N10: =M10/C10 -> 0.01843318 | O10: ='Water Reading'!Q10-'Water Reading'!Q9 -> 6 | P10: =O10/C10 -> 0.013824885 | Q10: ='Water Reading'!F10-'Water Reading'!F9 -> 34 | R10: =Q10/C10 -> 0.078341014 | S10: ='Water Reading'!E10-'Water Reading'!E9 -> 84 | T10: =S10/C10 -> 0.19354839 | U10: ='Water Reading'!G10-'Water Reading'!G9 -> 40 | V10: =U10/C10 -> 0.092165899 | W10: ='Water Reading'!J10-'Water Reading'!J9 -> 8 | X10: =W10/C10 -> 0.01843318 | Y10: =E10+I10+K10+M10+O10+G10+Q10+S10+U10+W10 -> 457 | Z10: =Y10/B10 -> 1
A11: ='Water Reading'!A10 -> 44934 | B11: =TOTAL!I9 -> 488 | C11: =('Water Reading'!B11-'Water Reading'!B10)+('Water Reading'!C11-'Water Reading'!C10) -> 484 | D11: =C11/B11 -> 0.99180328 | E11: ='Water Reading'!H11-'Water Reading'!H10 -> 49 | F11: =E11/C11 -> 0.10123967 | G11: =('Water Reading'!D11-'Water Reading'!D10)-('Water Reading'!R11-'Water Reading'!R10)-('Water Reading'!Q11-'Water Reading'!Q10) -> 246 | H11: =G11/C11 -> 0.50826446 | I11: ='Water Reading'!P11-'Water Reading'!P10 -> 6 | J11: =I11/C11 -> 0.012396694 | K11: =('Water Reading'!I11-'Water Reading'!I10)-('Water Reading'!P11-'Water Reading'!P10) -> -1 | L11: =K11/C11 -> -0.0020661157 | M11: ='Water Reading'!R11-'Water Reading'!R10 -> 8 | N11: =M11/C11 -> 0.016528926 | O11: ='Water Reading'!Q11-'Water Reading'!Q10 -> 7 | P11: =O11/C11 -> 0.01446281 | Q11: ='Water Reading'!F11-'Water Reading'!F10 -> 37 | R11: =Q11/C11 -> 0.076446281 | S11: ='Water Reading'!E11-'Water Reading'!E10 -> 90 | T11: =S11/C11 -> 0.18595041 | U11: ='Water Reading'!G11-'Water Reading'!G10 -> 39 | V11: =U11/C11 -> 0.080578512 | W11: ='Water Reading'!J11-'Water Reading'!J10 -> 7 | X11: =W11/C11 -> 0.01446281 | Y11: =E11+I11+K11+M11+O11+G11+Q11+S11+U11+W11 -> 488 | Z11: =Y11/B11 -> 1
A12: ='Water Reading'!A11 -> 44935 | B12: =TOTAL!I10 -> 451 | C12: =('Water Reading'!B12-'Water Reading'!B11)+('Water Reading'!C12-'Water Reading'!C11) -> 428 | D12: =C12/B12 -> 0.94900222 | E12: ='Water Reading'!H12-'Water Reading'!H11 -> 35 | F12: =E12/C12 -> 0.081775701 | G12: =('Water Reading'!D12-'Water Reading'!D11)-('Water Reading'!R12-'Water Reading'!R11)-('Water Reading'!Q12-'Water Reading'!Q11) -> 211 | H12: =G12/C12 -> 0.49299065 | I12: ='Water Reading'!P12-'Water Reading'!P11 -> 15 | J12: =I12/C12 -> 0.035046729 | K12: =('Water Reading'!I12-'Water Reading'!I11)-('Water Reading'!P12-'Water Reading'!P11) -> 16 | L12: =K12/C12 -> 0.037383178 | M12: ='Water Reading'!R12-'Water Reading'!R11 -> 6 | N12: =M12/C12 -> 0.014018692 | O12: ='Water Reading'!Q12-'Water Reading'!Q11 -> 7 | P12: =O12/C12 -> 0.01635514 | Q12: ='Water Reading'!F12-'Water Reading'!F11 -> 34 | R12: =Q12/C12 -> 0.079439252 | S12: ='Water Reading'!E12-'Water Reading'!E11 -> 81 | T12: =S12/C12 -> 0.18925234 | U12: ='Water Reading'!G12-'Water Reading'!G11 -> 39 | V12: =U12/C12 -> 0.091121495 | W12: ='Water Reading'!J12-'Water Reading'!J11 -> 7 | X12: =W12/C12 -> 0.01635514 | Y12: =E12+I12+K12+M12+O12+G12+Q12+S12+U12+W12 -> 451 | Z12: =Y12/B12 -> 1
