Workbook

Sheet TOTAL
A1: Site Name | B1: Day | C1: Month | D1: Year | E1: Total Electricity Kwh | F1: Electricity Tariff ($/Kwh) | G1: Natual Gas (m3) | H1: Natural Gas $/m3 | I1: Water Utility Supply (m3) m3 | J1: Water Utility Supply (m3) $/m3 | K1: Room Nights | L1: Total Guests
A2: Hong Kong | B2: 1 | C2: 11 | D2: 2022 | E2: =Combine!G3 -> 68310 | F2: 1.8924352 | G2: =Combine!M3 -> 5040.4662 | H2: 9.4525541 | I2: =Combine!J3 -> 758.413 | J2: 8.3787078 | K2: =Combine!N3 -> 655 | L2: =Combine!O3 -> 1193
A3: Hong Kong | B3: 2 | C3: 11 | D3: 2022 | E3: =Combine!G4 -> 68530 | F3: 1.8924352 | G3: =Combine!M4 -> 5894.216 | H3: 9.4525541 | I3: =Combine!J4 -> 823.308 | J3: 8.3787078 | K3: =Combine!N4 -> 620 | L3: =Combine!O4 -> 1136
A4: Hong Kong | B4: 3 | C4: 11 | D4: 2022 | E4: =Combine!G5 -> 72440 | F4: 1.8924352 | G4: =Combine!M5 -> 6946.832 | H4: 9.4525541 | I4: =Combine!J5 -> 850.725 | J4: 8.3787078 | K4: =Combine!N5 -> 566 | L4: =Combine!O5 -> 1078
A5: Hong Kong | B5: 4 | C5: 11 | D5: 2022 | E5: =Combine!G6 -> 71430 | F5: 1.8924352 | G5: =Combine!M6 -> 5799.9814 | H5: 9.4525541 | I5: =Combine!J6 -> 820.04 | J5: 8.3787078 | K5: =Combine!N6 -> 544 | L5: =Combine!O6 -> 1072
A6: Hong Kong | B6: 5 | C6: 11 | D6: 2022 | E6: =Combine!G7 -> 69340 | F6: 1.8924352 | G6: =Combine!M7 -> 5664.8205 | H6: 9.4525541 | I6: =Combine!J7 -> 837.565 | J6: 8.3787078 | K6: =Combine!N7 -> 534 | L6: =Combine!O7 -> 1073
A7: Hong Kong | B7: 6 | C7: 11 | D7: 2022 | E7: =Combine!G8 -> 66390 | F7: 1.8924352 | G7: =Combine!M8 -> 5946.597 | H7: 9.4525541 | I7: =Combine!J8 -> 874.5 | J7: 8.3787078 | K7: =Combine!N8 -> 554 | L7: =Combine!O8 -> 1093
A8: Hong Kong | B8: 7 | C8: 11 | D8: 2022 | E8: =Combine!G9 -> 66820 | F8: 1.8924352 | G8: =Combine!M9 -> 5361.5615 | H8: 9.4525541 | I8: =Combine!J9 -> 803.119 | J8: 8.3787078 | K8: =Combine!N9 -> 577 | L8: =Combine!O9 -> 1123
A9: Hong Kong | B9: 8 | C9: 11 | D9: 2022 | E9: =Combine!G10 -> 68810 | F9: 1.8924352 | G9: =Combine!M10 -> 5263.7141 | H9: 9.4525541 | I9: =Combine!J10 -> 769 | J9: 8.3787078 | K9: =Combine!N10 -> 550 | L9: =Combine!O10 -> 1076
A10: Hong Kong | B10: 9 | C10: 11 | D10: 2022 | E10: =Combine!G11 -> 70200 | F10: 1.8924352 | G10: =Combine!M11 -> 5271.1733 | H10: 9.4525541 | I10: =Combine!J11 -> 741.8 | J10: 8.3787078 | K10: =Combine!N11 -> 550 | L10: =Combine!O11 -> 1085
A11: Hong Kong | B11: 10 | C11: 11 | D11: 2022 | E11: =Combine!G12 -> 73010 | F11: 1.8924352 | G11: =Combine!M12 -> 5358.1974 | H11: 9.4525541 | I11: =Combine!J12 -> 672.35 | J11: 8.3787078 | K11: =Combine!N12 -> 568 | L11: =Combine!O12 -> 1118
A12: Hong Kong | B12: 11 | C12: 11 | D12: 2022 | E12: =Combine!G13 -> 77190 | F12: 1.8924352 | G12: =Combine!M13 -> 4915.6177 | H12: 9.4525541 | I12: =Combine!J13 -> 667.4 | J12: 8.3787078 | K12: =Combine!N13 -> 576 | L12: =Combine!O13 -> 1165
A13: Hong Kong | B13: 12 | C13: 11 | D13: 2022 | E13: =Combine!G14 -> 73690 | F13: 1.8924352 | G13: =Combine!M14 -> 5457.6535 | H13: 9.4525541 | I13: =Combine!J14 -> 774.7 | J13: 8.3787078 | K13: =Combine!N14 -> 590 | L13: =Combine!O14 -> 1218
... A31: Hong Kong | B31: 30 | C31: 11 | D31: 2022 | E31: =Combine!G32 -> 74350 | F31: 1.8924352 | G31: =Combine!M32 -> 5253.1904 | H31: 9.4525541 | I31: =Combine!J32 -> 1525.5 | J31: 8.3787078 | K31: =Combine!N32 -> 519 | L31: =Combine!O32 -> 1004
A32: Hong Kong

Sheet Combine
E1: FSH | F1: FSP | G1: FSH & FSP | H1: FSH | I1: FSP | J1: FSH & FSP | K1: FSH | L1: FSP | M1: FSH & FSP | N1: FSH & FSP
A2: Site Name | B2: Day | C2: Month | E2: Total Electricity Kwh | F2: Total Electricity Kwh | G2: Total Electricity Kwh | H2: Water Utility supply (m3) | I2: Water Utility supply (m3) | J2: Water Utility supply (m3) | K2: Town Gas (mJ) | L2: 335 | M2: Town Gas (m3) | N2: Occ room | O2: Total Guest | P2: Total Rooms | Q2: Temp ( C )
A3: FSHK | B3: 1 | C3: 11 | D3: 2022 | E3: ='Athens Daily - EL'!AP8 -> 38710.5 | F3: ='Athens Daily - EL'!AQ8 -> 29599.5 | G3: =SUM(E3,F3) -> 68310 | H3: ='Athens Daily - Water'!R7 -> 537.163 | I3: ='Athens Daily - Water'!S7 -> 221.25 | J3: =SUM(H3,I3) -> 758.413 | K3: ='Athens Daily - Gas'!BH9 -> 125041.2 | L3: ='Athens Daily - Gas'!BI9 -> 69571.2 | M3: =SUM(K3,L3)/38.61 -> 5040.4662 | N3: =Occ!G10 -> 655 | O3: =Occ!H10 -> 1193 | P3: 918
A4: FSHK | B4: 2 | C4: 11 | D4: 2022 | E4: ='Athens Daily - EL'!AP9 -> 39174.4 | F4: ='Athens Daily - EL'!AQ9 -> 29355.6 | G4: =SUM(E4,F4) -> 68530 | H4: ='Athens Daily - Water'!R8 -> 628.308 | I4: ='Athens Daily - Water'!S8 -> 195 | J4: =SUM(H4,I4) -> 823.308 | K4: ='Athens Daily - Gas'!BH10 -> 138910.08 | L4: ='Athens Daily - Gas'!BI10 -> 88665.6 | M4: =SUM(K4,L4)/38.61 -> 5894.216 | N4: =Occ!G11 -> 620 | O4: =Occ!H11 -> 1136 | P4: 918
A5: FSHK | B5: 3 | C5: 11 | D5: 2022 | E5: ='Athens Daily - EL'!AP10 -> 40728.5 | F5: ='Athens Daily - EL'!AQ10 -> 31711.5 | G5: =SUM(E5,F5) -> 72440 | H5: ='Athens Daily - Water'!R9 -> 644.475 | I5: ='Athens Daily - Water'!S9 -> 206.25 | J5: =SUM(H5,I5) -> 850.725 | K5: ='Athens Daily - Gas'!BH11 -> 179129.18 | L5: ='Athens Daily - Gas'!BI11 -> 89088 | M5: =SUM(K5,L5)/38.61 -> 6946.832 | N5: =Occ!G12 -> 566 | O5: =Occ!H12 -> 1078 | P5: 918
A6: FSHK | B6: 4 | C6: 11 | D6: 2022 | E6: ='Athens Daily - EL'!AP11 -> 40035.4 | F6: ='Athens Daily - EL'!AQ11 -> 31394.6 | G6: =SUM(E6,F6) -> 71430 | H6: ='Athens Daily - Water'!R10 -> 613.74 | I6: ='Athens Daily - Water'!S10 -> 206.3 | J6: =SUM(H6,I6) -> 820.04 | K6: ='Athens Daily - Gas'!BH12 -> 138660.48 | L6: ='Athens Daily - Gas'!BI12 -> 85276.8 | M6: =SUM(K6,L6)/38.61 -> 5799.9814 | N6: =Occ!G13 -> 544 | O6: =Occ!H13 -> 1072 | P6: 918
A7: FSHK | B7: 5 | C7: 11 | D7: 2022 | E7: ='Athens Daily - EL'!AP12 -> 39543.2 | F7: ='Athens Daily - EL'!AQ12 -> 29796.8 | G7: =SUM(E7,F7) -> 69340 | H7: ='Athens Daily - Water'!R11 -> 625.165 | I7: ='Athens Daily - Water'!S11 -> 212.4 | J7: =SUM(H7,I7) -> 837.565 | K7: ='Athens Daily - Gas'!BH13 -> 137627.52 | L7: ='Athens Daily - Gas'!BI13 -> 81091.2 | M7: =SUM(K7,L7)/38.61 -> 5664.8205 | N7: =Occ!G14 -> 534 | O7: =Occ!H14 -> 1073 | P7: 918
A8: FSHK | B8: 6 | C8: 11 | D8: 2022 | E8: ='Athens Daily - EL'!AP13 -> 38092.8 | F8: ='Athens Daily - EL'!AQ13 -> 28297.2 | G8: =SUM(E8,F8) -> 66390 | H8: ='Athens Daily - Water'!R12 -> 654 | I8: ='Athens Daily - Water'!S12 -> 220.5 | J8: =SUM(H8,I8) -> 874.5 | K8: ='Athens Daily - Gas'!BH14 -> 151482.91 | L8: ='Athens Daily - Gas'!BI14 -> 78115.2 | M8: =SUM(K8,L8)/38.61 -> 5946.597 | N8: =Occ!G15 -> 554 | O8: =Occ!H15 -> 1093 | P8: 918
A9: FSHK | B9: 7 | C9: 11 | D9: 2022 | E9: ='Athens Daily - EL'!AP14 -> 37212.9 | F9: ='Athens Daily - EL'!AQ14 -> 29607.1 | G9: =SUM(E9,F9) -> 66820 | H9: ='Athens Daily - Water'!R13 -> 600.169 | I9: ='Athens Daily - Water'!S13 -> 202.95 | J9: =SUM(H9,I9) -> 803.119 | K9: ='Athens Daily - Gas'!BH15 -> 133473.89 | L9: ='Athens Daily - Gas'!BI15 -> 73536 | M9: =SUM(K9,L9)/38.61 -> 5361.5615 | N9: =Occ!G16 -> 577 | O9: =Occ!H16 -> 1123 | P9: 918
A10: FSHK | B10: 8 | C10: 11 | D10: 2022 | E10: ='Athens Daily - EL'!AP15 -> 38913 | F10: ='Athens Daily - EL'!AQ15 -> 29897 | G10: =SUM(E10,F10) -> 68810 | H10: ='Athens Daily - Water'!R14 -> 558 | I10: ='Athens Daily - Water'!S14 -> 211 | J10: =SUM(H10,I10) -> 769 | K10: ='Athens Daily - Gas'!BH16 -> 128745.6 | L10: ='Athens Daily - Gas'!BI16 -> 74486.4 | M10: =SUM(K10,L10)/38.61 -> 5263.7141 | N10: =Occ!G17 -> 550 | O10: =Occ!H17 -> 1076 | P10: 918
A11: FSHK | B11: 9 | C11: 11 | D11: 2022 | E11: ='Athens Daily - EL'!AP16 -> 39289.2 | F11: ='Athens Daily - EL'!AQ16 -> 30910.8 | G11: =SUM(E11,F11) -> 70200 | H11: ='Athens Daily - Water'!R15 -> 544 | I11: ='Athens Daily - Water'!S15 -> 197.8 | J11: =SUM(H11,I11) -> 741.8 | K11: ='Athens Daily - Gas'!BH17 -> 129235.2 | L11: ='Athens Daily - Gas'!BI17 -> 74284.8 | M11: =SUM(K11,L11)/38.61 -> 5271.1733 | N11: =Occ!G18 -> 550 | O11: =Occ!H18 -> 1085 | P11: 918
A12: FSHK | B12: 10 | C12: 11 | D12: 2022 | E12: ='Athens Daily - EL'!AP17 -> 40665 | F12: ='Athens Daily - EL'!AQ17 -> 32345 | G12: =SUM(E12,F12) -> 73010 | H12: ='Athens Daily - Water'!R16 -> 453 | I12: ='Athens Daily - Water'!S16 -> 219.35 | J12: =SUM(H12,I12) -> 672.35 | K12: ='Athens Daily - Gas'!BH18 -> 133305.6 | L12: ='Athens Daily - Gas'!BI18 -> 73574.4 | M12: =SUM(K12,L12)/38.61 -> 5358.1974 | N12: =Occ!G19 -> 568 | O12: =Occ!H19 -> 1118 | P12: 918
A13: FSHK | B13: 11 | C13: 11 | D13: 2022 | E13: ='Athens Daily - EL'!AP18 -> 43460.3 | F13: ='Athens Daily - EL'!AQ18 -> 33729.7 | G13: =SUM(E13,F13) -> 77190 | H13: ='Athens Daily - Water'!R17 -> 467 | I13: ='Athens Daily - Water'!S17 -> 200.4 | J13: =SUM(H13,I13) -> 667.4 | K13: ='Athens Daily - Gas'!BH19 -> 120537.6 | L13: ='Athens Daily - Gas'!BI19 -> 69254.4 | M13: =SUM(K13,L13)/38.61 -> 4915.6177 | N13: =Occ!G20 -> 576 | O13: =Occ!H20 -> 1165 | P13: 918
A14: FSHK | B14: 12 | C14: 11 | D14: 2022 | E14: ='Athens Daily - EL'!AP19 -> 41687.3 | F14: ='Athens Daily - EL'!AQ19 -> 32002.7 | G14: =SUM(E14,F14) -> 73690 | H14: ='Athens Daily - Water'!R18 -> 559 | I14: ='Athens Daily - Water'!S18 -> 215.7 | J14: =SUM(H14,I14) -> 774.7 | K14: ='Athens Daily - Gas'!BH20 -> 135350.4 | L14: ='Athens Daily - Gas'!BI20 -> 75369.6 | M14: =SUM(K14,L14)/38.61 -> 5457.6535 | N14: =Occ!G21 -> 590 | O14: =Occ!H21 -> 1218 | P14: 918
... A32: FSHK | B32: 30 | C32: 11 | D32: 2022 | E32: ='Athens Daily - EL'!AP37 -> 41820 | F32: ='Athens Daily - EL'!AQ37 -> 32530 | G32: =SUM(E32,F32) -> 74350 | H32: ='Athens Daily - Water'!R36 -> 1102 | I32: ='Athens Daily - Water'!S36 -> 423.5 | J32: =SUM(H32,I32) -> 1525.5 | K32: ='Athens Daily - Gas'!BH38 -> 131910.48 | L32: ='Athens Daily - Gas'!BI38 -> 70915.2 | M32: =SUM(K32,L32)/38.61 -> 5253.1904 | N32: =Occ!G39 -> 519 | O32: =Occ!H39 -> 1004 | P32: 918

Sheet Occ
A1: Property: | B1: FS Hotel Hong Kong
C3: Year: 2021
C4: Actual
C5: Working
C6: Total Rooms
B7: Day of month | C7: Month: Nov 2022
B8: Net Amount | G8: Data to be input in HEP
B9: Daily Average | C9: FSH Occ Rooms | D9: no.of guest | E9: FSP Occ rooms | F9: no.of guest | G9: Total OCC | H9: Total Guest | I9: Total Rooms
B10: 01 | C10: 244 | D10: 314 | E10: 411 | F10: 879 | G10: =SUM(C10+E10) -> 655 | H10: =D10+F10 -> 1193 | I10: 918
B11: 02 | C11: 208 | D11: 256 | E11: 412 | F11: 880 | G11: =SUM(C11+E11) -> 620 | H11: =D11+F11 -> 1136 | I11: 918
B12: 03 | C12: 156 | D12: 199 | E12: 410 | F12: 879 | G12: =SUM(C12+E12) -> 566 | H12: =D12+F12 -> 1078 | I12: 918
B13: 04 | C13: 131 | D13: 187 | E13: 413 | F13: 885 | G13: =SUM(C13+E13) -> 544 | H13: =D13+F13 -> 1072 | I13: 918
B14: 05 | C14: 135 | D14: 202 | E14: 399 | F14: 871 | G14: =SUM(C14+E14) -> 534 | H14: =D14+F14 -> 1073 | I14: 918
B15: 06 | C15: 159 | D15: 221 | E15: 395 | F15: 872 | G15: =SUM(C15+E15) -> 554 | H15: =D15+F15 -> 1093 | I15: 918
B16: 07 | C16: 183 | D16: 253 | E16: 394 | F16: 870 | G16: =SUM(C16+E16) -> 577 | H16: =D16+F16 -> 1123 | I16: 918
B17: 08 | C17: 159 | D17: 211 | E17: 391 | F17: 865 | G17: =SUM(C17+E17) -> 550 | H17: =D17+F17 -> 1076 | I17: 918
B18: 09 | C18: 161 | D18: 222 | E18: 389 | F18: 863 | G18: =SUM(C18+E18) -> 550 | H18: =D18+F18 -> 1085 | I18: 918
B19: 10 | C19: 178 | D19: 256 | E19: 390 | F19: 862 | G19: =SUM(C19+E19) -> 568 | H19: =D19+F19 -> 1118 | I19: 918
B20: 11 | C20: 182 | D20: 295 | E20: 394 | F20: 870 | G20: =SUM(C20+E20) -> 576 | H20: =D20+F20 -> 1165 | I20: 918
B21: 12 | C21: 199 | D21: 348 | E21: 391 | F21: 870 | G21: =SUM(C21+E21) -> 590 | H21: =D21+F21 -> 1218 | I21: 918
... B39: 30 | C39: 195 | D39: 272 | E39: 324 | F39: 732 | G39: =SUM(C39+E39) -> 519 | H39: =D39+F39 -> 1004 | I39: 918
C42: =SUM(C10:C40) -> 5641 | D42: =SUM(D10:D40) -> 8459

Sheet Total - FSH
A1: Site Name | B1: Day | C1: Month | E1: Total Electricity Kwh | F1: Electricity Tariff ($/Kwh) | G1: Town Gas (mJ) | H1: Town Gas (m3) | I1: Town Gas $/mJ | J1: Water Utility supply (m3) | K1: Water Utility (m3) $/m3 | L1: Rooms Nights | M1: Total Guests | N1: Temp
A2: FSHK | B2: 1 | C2: 1 | D2: 2021 | E2: ='Athens Daily - EL'!AP8 -> 38710.5 | G2: ='Athens Daily - Gas'!BH9 -> 125041.2 | H2: =G2/38.3 -> 3264.7833 | J2: ='Athens Daily - Water'!R7 -> 537.163 | L2: 142 | M2: =L2*2 -> 284 | N2: 10
A3: FSHK | B3: 2 | C3: 1 | D3: 2021 | E3: ='Athens Daily - EL'!AP9 -> 39174.4 | G3: ='Athens Daily - Gas'!BH11 -> 179129.18 | H3: =G3/38.3 -> 4677.0022 | J3: ='Athens Daily - Water'!R8 -> 628.308 | L3: 102 | M3: =L3*2 -> 204 | N3: 12
A4: FSHK | B4: 3 | C4: 1 | D4: 2021 | E4: ='Athens Daily - EL'!AP10 -> 40728.5 | G4: ='Athens Daily - Gas'!BH12 -> 138660.48 | H4: =G4/38.3 -> 3620.3781 | J4: ='Athens Daily - Water'!R9 -> 644.475 | L4: 55 | M4: =L4*2 -> 110 | N4: 15
A5: FSHK | B5: 4 | C5: 1 | D5: 2021 | E5: ='Athens Daily - EL'!AP11 -> 40035.4 | G5: ='Athens Daily - Gas'!BH13 -> 137627.52 | H5: =G5/38.3 -> 3593.4078 | J5: ='Athens Daily - Water'!R10 -> 613.74 | L5: 45 | M5: =L5*2 -> 90 | N5: 17
A6: FSHK | B6: 5 | C6: 1 | D6: 2021 | E6: ='Athens Daily - EL'!AP12 -> 39543.2 | G6: ='Athens Daily - Gas'!BH14 -> 151482.91 | H6: =G6/38.3 -> 3955.1674 | J6: ='Athens Daily - Water'!R11 -> 625.165 | L6: 34 | M6: =L6*2 -> 68 | N6: 15
A7: FSHK | B7: 6 | C7: 1 | D7: 2021 | E7: ='Athens Daily - EL'!AP13 -> 38092.8 | G7: ='Athens Daily - Gas'!BH15 -> 133473.89 | H7: =G7/38.3 -> 3484.9579 | J7: ='Athens Daily - Water'!R12 -> 654 | L7: 36 | M7: =L7*2 -> 72
A8: FSHK | B8: 7 | C8: 1 | D8: 2021 | E8: ='Athens Daily - EL'!AP14 -> 37212.9 | G8: ='Athens Daily - Gas'!BH16 -> 128745.6 | H8: =G8/38.3 -> 3361.5039 | J8: ='Athens Daily - Water'!R13 -> 600.169 | L8: 60 | M8: =L8*2 -> 120
A9: FSHK | B9: 8 | C9: 1 | D9: 2021 | E9: ='Athens Daily - EL'!AP15 -> 38913 | G9: ='Athens Daily - Gas'!BH17 -> 129235.2 | H9: =G9/38.3 -> 3374.2872 | J9: ='Athens Daily - Water'!R14 -> 558 | L9: 64 | M9: =L9*2 -> 128
A10: FSHK | B10: 9 | C10: 1 | D10: 2021 | E10: ='Athens Daily - EL'!AP16 -> 39289.2 | G10: ='Athens Daily - Gas'!BH18 -> 133305.6 | H10: =G10/38.3 -> 3480.564 | J10: ='Athens Daily - Water'!R15 -> 544 | L10: 100 | M10: =L10*2 -> 200 | N10: 9
A11: FSHK | B11: 10 | C11: 1 | D11: 2021 | E11: ='Athens Daily - EL'!AP17 -> 40665 | G11: ='Athens Daily - Gas'!BH19 -> 120537.6 | H11: =G11/38.3 -> 3147.1958 | J11: ='Athens Daily - Water'!R16 -> 453 | L11: 63 | M11: =L11*2 -> 126 | N11: 12
A12: FSHK | B12: 11 | C12: 1 | D12: 2021 | E12: ='Athens Daily - EL'!AP18 -> 43460.3 | G12: ='Athens Daily - Gas'!BH20 -> 135350.4 | H12: =G12/38.3 -> 3533.953 | J12: ='Athens Daily - Water'!R17 -> 467 | L12: 39 | M12: =L12*2 -> 78 | N12: 12
A13: FSHK | B13: 12 | C13: 1 | D13: 2021 | E13: ='Athens Daily - EL'!AP19 -> 41687.3 | G13: ='Athens Daily - Gas'!BH21 -> 142252.8 | H13: =G13/38.3 -> 3714.1723 | J13: ='Athens Daily - Water'!R18 -> 559 | L13: 43 | M13: =L13*2 -> 86 | N13: 10
A14: FSHK | B14: 13 | C14: 1 | D14: 2021 | E14: ='Athens Daily - EL'!AP20 -> 42654.8 | G14: ='Athens Daily - Gas'!BH22 -> 198547.2 | H14: =G14/38.3 -> 5184 | J14: ='Athens Daily - Water'!R19 -> 570 | L14: 46 | M14: =L14*2 -> 92 | N14: 12
A15: FSHK | B15: 14 | C15: 1 | D15: 2021 | E15: ='Athens Daily - EL'!AP21 -> 37452.4 | G15: ='Athens Daily - Gas'!BH23 -> 145113.6 | H15: =G15/38.3 -> 3788.8668 | J15: ='Athens Daily - Water'!R20 -> 498 | L15: 55 | M15: =L15*2 -> 110 | N15: 13
A16: FSHK | B16: 15 | C16: 1 | D16: 2021 | E16: ='Athens Daily - EL'!AP22 -> 38648.2 | G16: ='Athens Daily - Gas'!BH24 -> 80908.8 | H16: =G16/38.3 -> 2112.5013 | J16: ='Athens Daily - Water'!R21 -> 447 | L16: 74 | M16: =L16*2 -> 148 | N16: 13
A17: FSHK | B17: 16 | C17: 1 | D17: 2021 | E17: ='Athens Daily - EL'!AP23 -> 45666.9 | G17: ='Athens Daily - Gas'!BH25 -> 84940.8 | H17: =G17/38.3 -> 2217.7755 | J17: ='Athens Daily - Water'!R22 -> 438 | L17: 149 | M17: =L17*2 -> 298
A18: FSHK | B18: 17 | C18: 1 | D18: 2021 | E18: ='Athens Daily - EL'!AP24 -> 36078.6 | G18: ='Athens Daily - Gas'!BH26 -> 132268.8 | H18: =G18/38.3 -> 3453.4935 | J18: ='Athens Daily - Water'!R23 -> 480 | L18: 64 | M18: =L18*2 -> 128
A19: FSHK | B19: 18 | C19: 1 | D19: 2021 | E19: ='Athens Daily - EL'!AP25 -> 45451.2 | G19: ='Athens Daily - Gas'!BH27 -> 132720.91 | H19: =G19/38.3 -> 3465.298 | J19: ='Athens Daily - Water'!R24 -> 495 | L19: 58 | M19: =L19*2 -> 116
A20: FSHK | B20: 19 | C20: 1 | D20: 2021 | E20: ='Athens Daily - EL'!AP26 -> 43510.5 | G20: ='Athens Daily - Gas'!BH28 -> 137315.62 | H20: =G20/38.3 -> 3585.2641 | J20: ='Athens Daily - Water'!R25 -> 495.0151 | L20: 69 | M20: =L20*2 -> 138
A21: FSHK | B21: 20 | C21: 1 | D21: 2021 | E21: ='Athens Daily - EL'!AP27 -> 41068.8 | G21: ='Athens Daily - Gas'!BH29 -> 127005.55 | H21: =G21/38.3 -> 3316.0719 | J21: ='Athens Daily - Water'!R26 -> 590.7193 | L21: 42 | M21: =L21*2 -> 84
A22: FSHK | B22: 21 | C22: 1 | D22: 2021 | E22: ='Athens Daily - EL'!AP28 -> 38382.3 | G22: ='Athens Daily - Gas'!BH30 -> 132902.74 | H22: =G22/38.3 -> 3470.0453 | J22: ='Athens Daily - Water'!R27 -> 496.4658 | L22: 45 | M22: =L22*2 -> 90
A23: FSHK | B23: 22 | C23: 1 | D23: 2021 | E23: ='Athens Daily - EL'!AP29 -> 41043 | G23: ='Athens Daily - Gas'!BH31 -> 113335.3 | H23: =G23/38.3 -> 2959.1461 | J23: ='Athens Daily - Water'!R28 -> 448.4813 | L23: 82 | M23: =L23*2 -> 164 | N23: 19
A24: FSHK | B24: 23 | C24: 1 | D24: 2021 | E24: ='Athens Daily - EL'!AP30 -> 41391.3 | G24: ='Athens Daily - Gas'!BH32 -> 121455.89 | H24: =G24/38.3 -> 3171.172 | J24: ='Athens Daily - Water'!R29 -> 477.3185 | L24: 170 | M24: =L24*2 -> 340 | N24: 20
A25: FSHK | B25: 24 | C25: 1 | D25: 2021 | E25: ='Athens Daily - EL'!AP31 -> 41542.3 | G25: ='Athens Daily - Gas'!BH33 -> 124828.8 | H25: =G25/38.3 -> 3259.2376 | J25: ='Athens Daily - Water'!R30 -> 494 | L25: 91 | M25: =L25*2 -> 182 | N25: 19
A26: FSHK | B26: 25 | C26: 1 | D26: 2021 | E26: ='Athens Daily - EL'!AP32 -> 42152.1 | G26: ='Athens Daily - Gas'!BH34 -> 134102.59 | H26: =G26/38.3 -> 3501.3732 | J26: ='Athens Daily - Water'!R31 -> 493 | L26: 56 | M26: =L26*2 -> 112
A27: FSHK | B27: 26 | C27: 1 | D27: 2021 | E27: ='Athens Daily - EL'!AP33 -> 42013.6 | G27: ='Athens Daily - Gas'!BH35 -> 128976.67 | H27: =G27/38.3 -> 3367.5371 | J27: ='Athens Daily - Water'!R32 -> 541 | M27: =L27*2 -> 0
A28: FSHK | B28: 27 | C28: 1 | D28: 2021 | E28: ='Athens Daily - EL'!AP34 -> 43390.8 | G28: ='Athens Daily - Gas'!BH36 -> 138907.82 | H28: =G28/38.3 -> 3626.8361 | J28: ='Athens Daily - Water'!R33 -> 562 | M28: =L28*2 -> 0
A29: FSHK | B29: 28 | C29: 1 | D29: 2021 | E29: ='Athens Daily - EL'!AP35 -> 42233.7 | G29: ='Athens Daily - Gas'!BH37 -> 129817.68 | H29: =G29/38.3 -> 3389.4956 | J29: ='Athens Daily - Water'!R34 -> 565 | M29: =L29*2 -> 0
A30: FSHK | B30: 29 | C30: 1 | D30: 2021 | E30: ='Athens Daily - EL'!AP36 -> 45387.6 | G30: ='Athens Daily - Gas'!BH38 -> 131910.48 | H30: =G30/38.3 -> 3444.1379 | J30: ='Athens Daily - Water'!R36 -> 1102 | M30: =L30*2 -> 0
A31: FSHK | B31: 30 | C31: 1 | D31: 2021 | E31: ='Athens Daily - EL'!AP37 -> 41820 | G31: ='Athens Daily - Gas'!#REF! -> #REF! | H31: =G31/38.3 -> #REF! | J31: ='Athens Daily - Water'!R37 -> 0 | M31: =L31*2 -> 0
A32: FSHK | B32: 31 | C32: 1 | D32: 2021 | E32: ='Athens Daily - EL'!#REF! -> #REF! | G32: ='Athens Daily - Gas'!BH39 -> 0 | H32: =G32/38.3 -> 0 | J32: ='Athens Daily - Water'!R38 -> 0 | M32: =L32*2 -> 0

Sheet Total - FSP
A1: Site Name | B1: Day | C1: Month | D1: Year | E1: Total Electricity Kwh | F1: Electricity Tariff ($/Kwh) | G1: Town Gas (mJ) | H1: Town Gas $/mJ | I1: Water Utility supply (m3) | J1: Water Utility (m3) $/m3 | K1: Rooms Nights | L1: Total Guests
A2: FSHK | B2: 1 | C2: 1 | D2: 2021 | E2: ='Athens Daily - EL'!AQ8 -> 29599.5 | G2: ='Athens Daily - Gas'!BI9 -> 69571.2 | I2: ='Athens Daily - Water'!S7 -> 221.25 | K2: 286 | L2: 2
A3: FSHK | B3: 2 | C3: 1 | D3: 2021 | E3: ='Athens Daily - EL'!AQ9 -> 29355.6 | G3: ='Athens Daily - Gas'!BI11 -> 89088 | I3: ='Athens Daily - Water'!S8 -> 195 | K3: 285 | L3: 2
A4: FSHK | B4: 3 | C4: 1 | D4: 2021 | E4: ='Athens Daily - EL'!AQ10 -> 31711.5 | G4: ='Athens Daily - Gas'!BI12 -> 85276.8 | I4: ='Athens Daily - Water'!S9 -> 206.25 | K4: 282 | L4: 2
A5: FSHK | B5: 4 | C5: 1 | D5: 2021 | E5: ='Athens Daily - EL'!AQ11 -> 31394.6 | G5: ='Athens Daily - Gas'!BI13 -> 81091.2 | I5: ='Athens Daily - Water'!S10 -> 206.3 | K5: 284 | L5: 2
A6: FSHK | B6: 5 | C6: 1 | D6: 2021 | E6: ='Athens Daily - EL'!AQ12 -> 29796.8 | G6: ='Athens Daily - Gas'!BI14 -> 78115.2 | I6: ='Athens Daily - Water'!S11 -> 212.4 | K6: 286 | L6: 2
A7: FSHK | B7: 6 | C7: 1 | D7: 2021 | E7: ='Athens Daily - EL'!AQ13 -> 28297.2 | G7: ='Athens Daily - Gas'!BI15 -> 73536 | I7: ='Athens Daily - Water'!S12 -> 220.5 | K7: 288 | L7: 2
A8: FSHK | B8: 7 | C8: 1 | D8: 2021 | E8: ='Athens Daily - EL'!AQ14 -> 29607.1 | G8: ='Athens Daily - Gas'!BI16 -> 74486.4 | I8: ='Athens Daily - Water'!S13 -> 202.95 | K8: 286 | L8: 2
A9: FSHK | B9: 8 | C9: 1 | D9: 2021 | E9: ='Athens Daily - EL'!AQ15 -> 29897 | G9: ='Athens Daily - Gas'!BI17 -> 74284.8 | I9: ='Athens Daily - Water'!S14 -> 211 | K9: 287 | L9: 2
A10: FSHK | B10: 9 | C10: 1 | D10: 2021 | E10: ='Athens Daily - EL'!AQ16 -> 30910.8 | G10: ='Athens Daily - Gas'!BI18 -> 73574.4 | I10: ='Athens Daily - Water'!S15 -> 197.8 | K10: 284 | L10: 2
A11: FSHK | B11: 10 | C11: 1 | D11: 2021 | E11: ='Athens Daily - EL'!AQ17 -> 32345 | G11: ='Athens Daily - Gas'!BI19 -> 69254.4 | I11: ='Athens Daily - Water'!S16 -> 219.35 | K11: 284 | L11: 2
A12: FSHK | B12: 11 | C12: 1 | D12: 2021 | E12: ='Athens Daily - EL'!AQ18 -> 33729.7 | G12: ='Athens Daily - Gas'!BI20 -> 75369.6 | I12: ='Athens Daily - Water'!S17 -> 200.4 | K12: 284 | L12: 2
A13: FSHK | B13: 12 | C13: 1 | D13: 2021 | E13: ='Athens Daily - EL'!AQ19 -> 32002.7 | G13: ='Athens Daily - Gas'!BI21 -> 76291.2 | I13: ='Athens Daily - Water'!S18 -> 215.7 | K13: 286 | L13: 2
A14: FSHK | B14: 13 | C14: 1 | D14: 2021 | E14: ='Athens Daily - EL'!AQ20 -> 33155.2 | G14: ='Athens Daily - Gas'!BI22 -> 118108.8 | I14: ='Athens Daily - Water'!S19 -> 231.1 | K14: 287 | L14: 2
... A29: FSHK | B29: 28 | C29: 1 | D29: 2021 | E29: ='Athens Daily - EL'!AQ35 -> 34306.3 | G29: ='Athens Daily - Gas'!BI37 -> 71500.8 | I29: ='Athens Daily - Water'!S34 -> 221.05 | K29: 290 | L29: 2
A30: FSHK | B30: 29 | C30: 1 | D30: 2021 | E30: ='Athens Daily - EL'!AQ36 -> 35162.4 | G30: ='Athens Daily - Gas'!BI38 -> 70915.2 | I30: ='Athens Daily - Water'!S36 -> 423.5 | K30: 291 | L30: 2
A31: FSHK | B31: 30 | C31: 1 | D31: 2021 | E31: ='Athens Daily - EL'!AQ37 -> 32530 | G31: ='Athens Daily - Gas'!#REF! -> #REF! | I31: ='Athens Daily - Water'!S37 -> 0 | K31: 290 | L31: 2
A32: FSHK | B32: 31 | C32: 1 | D32: 2021 | E32: ='Athens Daily - EL'!#REF! -> #REF! | G32: ='Athens Daily - Gas'!BI39 -> 0 | I32: ='Athens Daily - Water'!S38 -> 0

Sheet Athens Daily - EL
C1: FSH | E1: FSH | G1: FSH | K1: FSH | M1: FSH | O1: FSH & FSP | S1: FSH & FSP | W1: FSH & FSP | AA1: FSH & FSP | AE1: FSP | AG1: FSP | AI1: FSP | AK1: FSP | AM1: FSP
C2: HOT Normal and Essential power for linen chute(9/F-45/F), HOT water pump at 8/F, Podium dimmer supply(P1-P6), MVAC system(B1/F-B2/F), Bus station BPTT supply. | E2: HOT Normal Power for Guest rooms supply (9/F-45/F), MVAC system (2/F & 46/F), P&D system(46/F) Podium MVAC system (P1/F-P6/F) | G2: P5 Pool Plant, Laundry (hotel 70%,Place 30%), 9/F - 28/F public area, 29/F 46/F Public area Podium normal power supply for water feature(G/F), Chiller WCC-01(B2/F)(FSH 50%, FSP 50%) | K2: Podium normal power for Administration office(P5/F & P6/F), P&D system supply(B2/F), Planter lighting supply(Open Space), Kitchen public supply(B1/F, P1/F, P2/F, P3/F, P4/F & P6/F), BMS room supply(B1/F), Security room supply(G/F), Computer & PABX room | M2: Podium normal power supply for Public supply(P1/F - P6/F), Kitchen(B1/F, P1/F, P2/F, P3/F, P4/F & P6/F), P&D system supply(B1/F), Refuse room supply(G/F), Gas boiler supply(B2/F) and MVAC system supply(P1/F-P6/F). | O2: Podium normal power supply for main P&D system supply(B1/F), MVAC chilled water pump(B1/F) Chiller WCC-02(B2/F) (FSH 50%, FSP 50%) | S2: Chiller # 3 (FSH 50%, FSP 50%) | W2: Chiller # 4 (FSH 50%, FSP 50%) | AA2: Chiller # 5 (FSH 50%, FSP 50%) | AE2: SHT normal power for Guest rooms supply (11/F-23/F). | AG2: SHT normal power for Guest rooms supply (25/F-57/F). | AI2: SHT Essential Power for Public Power supply, F.S. Pump (9/F, 57/F & 39/F), Podium F.S. pump(P1M), Lift LT/S1-LT/S7(LM/F), Lift LT/S8-S9(59/F) and Lift LT/S10(8/F). | AK2: SHT normal power for Guest rooms supply (25/F-57/F). | AM2: SHT normal power for MVAC System(8/F & 40/F), Public supply (8-R/F), P&D system(40/F & 60/F), swimming pool(57/F), SWB 3&4(40/F)
C3: 5065546 | E3: 5065547 | G3: 5008272 | K3: 5065548 | M3: 5465545 | O3: 5008273 | S3: 5018351 | W3: 5018354 | AA3: 5018350 | AE3: 5065543 | AG3: 5065544 | AI3: 5065541 | AK3: 5065542 | AM3: 5065540 | AP3: Daily Total consumption
C4: TXW1 | E4: TXW4 | G4: TXW2 | K4: TXC2 | M4: TXC1 | O4: TXW3 | S4: TXN1 | W4: TXN2 | AA4: TXN3 | AE4: TXN4 | AG4: TXE1 | AI4: TXE2 | AK4: TXE3 | AM4: TXE4
A5: Tariff Type | C5: MD-LV | E5: MD-LV | G5: MD-LV | K5: MD-LV | M5: MD-LV | O5: MD-LV | S5: Non-Residential | W5: Non-Residential | AA5: Non-Residential | AE5: MD-LV | AG5: MD-LV | AI5: MD-LV | AK5: MD-LV | AM5: MD-LV
A6: Date | C6: Reading Kwh | D6: Differecne Kwh | E6: Reading Kwh | F6: Differecne Kwh | G6: Reading Kwh | H6: Differecne Kwh | I6: 49 | J6: 51 | K6: Reading Kwh | L6: Differecne Kwh | M6: Reading Kwh | N6: Differecne Kwh | O6: Reading Kwh | P6: Differecne Kwh | Q6: 49 | R6: 51 | S6: Reading Kwh | T6: Differecne Kwh | U6: 49 | V6: 51 | W6: Reading Kwh | X6: Differecne Kwh | Y6: 49 | Z6: 51 | AA6: Reading Kwh | AB6: Differecne Kwh | AC6: 49 | AD6: 51 | AE6: Reading Kwh | AF6: Differecne Kwh | AG6: Reading Kwh | AH6: Differecne Kwh | AI6: Reading Kwh | AJ6: Differecne Kwh | AK6: Reading Kwh | AL6: Differecne Kwh | AM6: Reading Kwh | AN6: Differecne Kwh | AP6: FSH | AQ6: FSP
A7: 44865 | C7: 324980 | E7: 557198 | G7: 357599 | K7: 476493 | M7: 761478 | O7: 478772 | S7: 466087 | W7: 240318 | AA7: 313798 | AE7: 92287 | AG7: 174725 | AI7: 311070 | AK7: 157666 | AM7: 827864
A8: 44866 | C8: 325371 | D8: =(C8-C7)*10 -> 3910 | E8: 557973 | F8: =(E8-E7)*10 -> 7750 | G8: 358954 | H8: =(G8-G7)*10 -> 13550 | I8: =H8*I6/100 -> 6639.5 | J8: =H8*J6/100 -> 6910.5 | K8: 477131 | L8: =(K8-K7)*10 -> 6380 | M8: 762592 | N8: =(M8-M7)*10 -> 11140 | O8: 479353 | P8: =(O8-O7)*10 -> 5810 | Q8: =P8*Q6/100 -> 2846.9 | R8: =P8*R6/100 -> 2963.1 | S8: 466089 | T8: =(S8-S7)*10 -> 20 | U8: =T8*U6/100 -> 9.8 | V8: =T8*V6/100 -> 10.2 | W8: 240321 | X8: =(W8-W7)*10 -> 30 | Y8: =X8*Y6/100 -> 14.7 | Z8: =X8*Z6/100 -> 15.3 | AA8: 313802 | AB8: =(AA8-AA7)*10 -> 40 | AC8: =AB8*AC6/100 -> 19.6 | AD8: =AB8*AD6/100 -> 20.4 | AE8: 92417 | AF8: =(AE8-AE7)*10 -> 1300 | AG8: 174982 | AH8: =(AG8-AG7)*10 -> 2570 | AI8: 311472 | AJ8: =(AI8-AI7)*10 -> 4020 | AK8: 157873 | AL8: =(AK8-AK7)*10 -> 2070 | AM8: 828836 | AN8: =(AM8-AM7)*10 -> 9720 | AP8: =SUM(D8,F8,I8,L8,N8,Q8,U8,Y8,AC8) -> 38710.5 | AQ8: =SUM(R8,V8,Z8,AD8,AF8,AH8,AJ8,AL8,AN8,J8) -> 29599.5
A9: =SUM(A8+1) -> 44867 | C9: 325775 | D9: =(C9-C8)*10 -> 4040 | E9: 558794 | F9: =(E9-E8)*10 -> 8210 | G9: 360332 | H9: =(G9-G8)*10 -> 13780 | I9: =H9*I6/100 -> 6752.2 | J9: =H9*J6/100 -> 7027.8 | K9: 477781 | L9: =(K9-K8)*10 -> 6500 | M9: 763676 | N9: =(M9-M8)*10 -> 10840 | O9: 479924 | P9: =(O9-O8)*10 -> 5710 | Q9: =P9*Q6/100 -> 2797.9 | R9: =P9*R6/100 -> 2912.1 | S9: 466091 | T9: =(S9-S8)*10 -> 20 | U9: =T9*U6/100 -> 9.8 | V9: =T9*V6/100 -> 10.2 | W9: 240323 | X9: =(W9-W8)*10 -> 20 | Y9: =X9*Y6/100 -> 9.8 | Z9: =X9*Z6/100 -> 10.2 | AA9: 313805 | AB9: =(AA9-AA8)*10 -> 30 | AC9: =AB9*AC6/100 -> 14.7 | AD9: =AB9*AD6/100 -> 15.3 | AE9: 92557 | AF9: =(AE9-AE8)*10 -> 1400 | AG9: 175237 | AH9: =(AG9-AG8)*10 -> 2550 | AI9: 311866 | AJ9: =(AI9-AI8)*10 -> 3940 | AK9: 158086 | AL9: =(AK9-AK8)*10 -> 2130 | AM9: 829772 | AN9: =(AM9-AM8)*10 -> 9360 | AP9: =SUM(D9,F9,I9,L9,N9,Q9,U9,Y9,AC9) -> 39174.4 | AQ9: =SUM(R9,V9,Z9,AD9,AF9,AH9,AJ9,AL9,AN9,J9) -> 29355.6
A10: =SUM(A9+1) -> 44868 | C10: 326169 | D10: =(C10-C9)*10 -> 3940 | E10: 559577 | F10: =(E10-E9)*10 -> 7830 | G10: 361617 | H10: =(G10-G9)*10 -> 12850 | I10: =H10*I6/100 -> 6296.5 | J10: =H10*J6/100 -> 6553.5 | K10: 478411 | L10: =(K10-K9)*10 -> 6300 | M10: 764783 | N10: =(M10-M9)*10 -> 11070 | O10: 480996 | P10: =(O10-O9)*10 -> 10720 | Q10: =P10*Q6/100 -> 5252.8 | R10: =P10*R6/100 -> 5467.2 | S10: 466093 | T10: =(S10-S9)*10 -> 20 | U10: =T10*U6/100 -> 9.8 | V10: =T10*V6/100 -> 10.2 | W10: 240325 | X10: =(W10-W9)*10 -> 20 | Y10: =X10*Y6/100 -> 9.8 | Z10: =X10*Z6/100 -> 10.2 | AA10: 313809 | AB10: =(AA10-AA9)*10 -> 40 | AC10: =AB10*AC6/100 -> 19.6 | AD10: =AB10*AD6/100 -> 20.4 | AE10: 92693 | AF10: =(AE10-AE9)*10 -> 1360 | AG10: 175492 | AH10: =(AG10-AG9)*10 -> 2550 | AI10: 312271 | AJ10: =(AI10-AI9)*10 -> 4050 | AK10: 158296 | AL10: =(AK10-AK9)*10 -> 2100 | AM10: 830731 | AN10: =(AM10-AM9)*10 -> 9590 | AP10: =SUM(D10,F10,I10,L10,N10,Q10,U10,Y10,AC10) -> 40728.5 | AQ10: =SUM(R10,V10,Z10,AD10,AF10,AH10,AJ10,AL10,AN10,J10) -> 31711.5
A11: =SUM(A10+1) -> 44869 | C11: 326547 | D11: =(C11-C10)*10 -> 3780 | E11: 560328 | F11: =(E11-E10)*10 -> 7510 | G11: 362797 | H11: =(G11-G10)*10 -> 11800 | I11: =H11*I6/100 -> 5782 | J11: =H11*J6/100 -> 6018 | K11: 479024 | L11: =(K11-K10)*10 -> 6130 | M11: 765895 | N11: =(M11-M10)*10 -> 11120 | O11: 482016 | P11: =(O11-O10)*10 -> 10200 | Q11: =P11*Q6/100 -> 4998 | R11: =P11*R6/100 -> 5202 | S11: 466147 | T11: =(S11-S10)*10 -> 540 | U11: =T11*U6/100 -> 264.6 | V11: =T11*V6/100 -> 275.4 | W11: 240378 | X11: =(W11-W10)*10 -> 530 | Y11: =X11*Y6/100 -> 259.7 | Z11: =X11*Z6/100 -> 270.3 | AA11: 313848 | AB11: =(AA11-AA10)*10 -> 390 | AC11: =AB11*AC6/100 -> 191.1 | AD11: =AB11*AD6/100 -> 198.9 | AE11: 92828 | AF11: =(AE11-AE10)*10 -> 1350 | AG11: 175745 | AH11: =(AG11-AG10)*10 -> 2530 | AI11: 312672 | AJ11: =(AI11-AI10)*10 -> 4010 | AK11: 158504 | AL11: =(AK11-AK10)*10 -> 2080 | AM11: 831677 | AN11: =(AM11-AM10)*10 -> 9460 | AP11: =SUM(D11,F11,I11,L11,N11,Q11,U11,Y11,AC11) -> 40035.4 | AQ11: =SUM(R11,V11,Z11,AD11,AF11,AH11,AJ11,AL11,AN11,J11) -> 31394.6
A12: =SUM(A11+1) -> 44870 | C12: 326936 | D12: =(C12-C11)*10 -> 3890 | E12: 561098 | F12: =(E12-E11)*10 -> 7700 | G12: 364065 | H12: =(G12-G11)*10 -> 12680 | I12: =H12*I6/100 -> 6213.2 | J12: =H12*J6/100 -> 6466.8 | K12: 479673 | L12: =(K12-K11)*10 -> 6490 | M12: 767028 | N12: =(M12-M11)*10 -> 11330 | O12: 482807 | P12: =(O12-O11)*10 -> 7910 | Q12: =P12*Q6/100 -> 3875.9 | R12: =P12*R6/100 -> 4034.1 | S12: 466150 | T12: =(S12-S11)*10 -> 30 | U12: =T12*U6/100 -> 14.7 | V12: =T12*V6/100 -> 15.3 | W12: 240380 | X12: =(W12-W11)*10 -> 20 | Y12: =X12*Y6/100 -> 9.8 | Z12: =X12*Z6/100 -> 10.2 | AA12: 313852 | AB12: =(AA12-AA11)*10 -> 40 | AC12: =AB12*AC6/100 -> 19.6 | AD12: =AB12*AD6/100 -> 20.4 | AE12: 92965 | AF12: =(AE12-AE11)*10 -> 1370 | AG12: 176002 | AH12: =(AG12-AG11)*10 -> 2570 | AI12: 313066 | AJ12: =(AI12-AI11)*10 -> 3940 | AK12: 158715 | AL12: =(AK12-AK11)*10 -> 2110 | AM12: 832603 | AN12: =(AM12-AM11)*10 -> 9260 | AP12: =SUM(D12,F12,I12,L12,N12,Q12,U12,Y12,AC12) -> 39543.2 | AQ12: =SUM(R12,V12,Z12,AD12,AF12,AH12,AJ12,AL12,AN12,J12) -> 29796.8
A13: =SUM(A12+1) -> 44871 | C13: 327315 | D13: =(C13-C12)*10 -> 3790 | E13: 561867 | F13: =(E13-E12)*10 -> 7690 | G13: 364544 | H13: =(G13-G12)*10 -> 4790 | I13: =H13*I6/100 -> 2347.1 | J13: =H13*J6/100 -> 2442.9 | K13: 480297 | L13: =(K13-K12)*10 -> 6240 | M13: 768099 | N13: =(M13-M12)*10 -> 10710 | O13: 484292 | P13: =(O13-O12)*10 -> 14850 | Q13: =P13*Q6/100 -> 7276.5 | R13: =P13*R6/100 -> 7573.5 | S13: 466152 | T13: =(S13-S12)*10 -> 20 | U13: =T13*U6/100 -> 9.8 | V13: =T13*V6/100 -> 10.2 | W13: 240382 | X13: =(W13-W12)*10 -> 20 | Y13: =X13*Y6/100 -> 9.8 | Z13: =X13*Z6/100 -> 10.2 | AA13: 313856 | AB13: =(AA13-AA12)*10 -> 40 | AC13: =AB13*AC6/100 -> 19.6 | AD13: =AB13*AD6/100 -> 20.4 | AE13: 93093 | AF13: =(AE13-AE12)*10 -> 1280 | AG13: 176239 | AH13: =(AG13-AG12)*10 -> 2370 | AI13: 313441 | AJ13: =(AI13-AI12)*10 -> 3750 | AK13: 158918 | AL13: =(AK13-AK12)*10 -> 2030 | AM13: 833484 | AN13: =(AM13-AM12)*10 -> 8810 | AP13: =SUM(D13,F13,I13,L13,N13,Q13,U13,Y13,AC13) -> 38092.8 | AQ13: =SUM(R13,V13,Z13,AD13,AF13,AH13,AJ13,AL13,AN13,J13) -> 28297.2
A14: =SUM(A13+1) -> 44872 | C14: 327698 | D14: =(C14-C13)*10 -> 3830 | E14: 562646 | F14: =(E14-E13)*10 -> 7790 | G14: 365349 | H14: =(G14-G13)*10 -> 8050 | I14: =H14*I6/100 -> 3944.5 | J14: =H14*J6/100 -> 4105.5 | K14: 480916 | L14: =(K14-K13)*10 -> 6190 | M14: 769049 | N14: =(M14-M13)*10 -> 9500 | O14: 485500 | P14: =(O14-O13)*10 -> 12080 | Q14: =P14*Q6/100 -> 5919.2 | R14: =P14*R6/100 -> 6160.8 | S14: 466154 | T14: =(S14-S13)*10 -> 20 | U14: =T14*U6/100 -> 9.8 | V14: =T14*V6/100 -> 10.2 | W14: 240385 | X14: =(W14-W13)*10 -> 30 | Y14: =X14*Y6/100 -> 14.7 | Z14: =X14*Z6/100 -> 15.3 | AA14: 313859 | AB14: =(AA14-AA13)*10 -> 30 | AC14: =AB14*AC6/100 -> 14.7 | AD14: =AB14*AD6/100 -> 15.3 | AE14: 93225 | AF14: =(AE14-AE13)*10 -> 1320 | AG14: 176492 | AH14: =(AG14-AG13)*10 -> 2530 | AI14: 313839 | AJ14: =(AI14-AI13)*10 -> 3980 | AK14: 159126 | AL14: =(AK14-AK13)*10 -> 2080 | AM14: 834423 | AN14: =(AM14-AM13)*10 -> 9390 | AP14: =SUM(D14,F14,I14,L14,N14,Q14,U14,Y14,AC14) -> 37212.9 | AQ14: =SUM(R14,V14,Z14,AD14,AF14,AH14,AJ14,AL14,AN14,J14) -> 29607.1
A15: =SUM(A14+1) -> 44873 | C15: 328073 | D15: =(C15-C14)*10 -> 3750 | E15: 563404 | F15: =(E15-E14)*10 -> 7580 | G15: 366500 | H15: =(G15-G14)*10 -> 11510 | I15: =H15*I6/100 -> 5639.9 | J15: =H15*J6/100 -> 5870.1 | K15: 481540 | L15: =(K15-K14)*10 -> 6240 | M15: 770120 | N15: =(M15-M14)*10 -> 10710 | O15: 486511 | P15: =(O15-O14)*10 -> 10110 | Q15: =P15*Q6/100 -> 4953.9 | R15: =P15*R6/100 -> 5156.1 | S15: 466156 | T15: =(S15-S14)*10 -> 20 | U15: =T15*U6/100 -> 9.8 | V15: =T15*V6/100 -> 10.2 | W15: 240387 | X15: =(W15-W14)*10 -> 20 | Y15: =X15*Y6/100 -> 9.8 | Z15: =X15*Z6/100 -> 10.2 | AA15: 313863 | AB15: =(AA15-AA14)*10 -> 40 | AC15: =AB15*AC6/100 -> 19.6 | AD15: =AB15*AD6/100 -> 20.4 | AE15: 93356 | AF15: =(AE15-AE14)*10 -> 1310 | AG15: 176739 | AH15: =(AG15-AG14)*10 -> 2470 | AI15: 314227 | AJ15: =(AI15-AI14)*10 -> 3880 | AK15: 159327 | AL15: =(AK15-AK14)*10 -> 2010 | AM15: 835339 | AN15: =(AM15-AM14)*10 -> 9160 | AP15: =SUM(D15,F15,I15,L15,N15,Q15,U15,Y15,AC15) -> 38913 | AQ15: =SUM(R15,V15,Z15,AD15,AF15,AH15,AJ15,AL15,AN15,J15) -> 29897
A16: =SUM(A15+1) -> 44874 | C16: 328453 | D16: =(C16-C15)*10 -> 3800 | E16: 564135 | F16: =(E16-E15)*10 -> 7310 | G16: 367762 | H16: =(G16-G15)*10 -> 12620 | I16: =H16*I6/100 -> 6183.8 | J16: =H16*J6/100 -> 6436.2 | K16: 482154 | L16: =(K16-K15)*10 -> 6140 | M16: 771193 | N16: =(M16-M15)*10 -> 10730 | O16: 487550 | P16: =(O16-O15)*10 -> 10390 | Q16: =P16*Q6/100 -> 5091.1 | R16: =P16*R6/100 -> 5298.9 | S16: 466158 | T16: =(S16-S15)*10 -> 20 | U16: =T16*U6/100 -> 9.8 | V16: =T16*V6/100 -> 10.2 | W16: 240389 | X16: =(W16-W15)*10 -> 20 | Y16: =X16*Y6/100 -> 9.8 | Z16: =X16*Z6/100 -> 10.2 | AA16: 313866 | AB16: =(AA16-AA15)*10 -> 30 | AC16: =AB16*AC6/100 -> 14.7 | AD16: =AB16*AD6/100 -> 15.3 | AE16: 93489 | AF16: =(AE16-AE15)*10 -> 1330 | AG16: 176990 | AH16: =(AG16-AG15)*10 -> 2510 | AI16: 314612 | AJ16: =(AI16-AI15)*10 -> 3850 | AK16: 159529 | AL16: =(AK16-AK15)*10 -> 2020 | AM16: 836282 | AN16: =(AM16-AM15)*10 -> 9430 | AP16: =SUM(D16,F16,I16,L16,N16,Q16,U16,Y16,AC16) -> 39289.2 | AQ16: =SUM(R16,V16,Z16,AD16,AF16,AH16,AJ16,AL16,AN16,J16) -> 30910.8
A17: =SUM(A16+1) -> 44875 | C17: 328842 | D17: =(C17-C16)*10 -> 3890 | E17: 564878 | F17: =(E17-E16)*10 -> 7430 | G17: 369124 | H17: =(G17-G16)*10 -> 13620 | I17: =H17*I6/100 -> 6673.8 | J17: =H17*J6/100 -> 6946.2 | K17: 482750 | L17: =(K17-K16)*10 -> 5960 | M17: 772282 | N17: =(M17-M16)*10 -> 10890 | O17: 488730 | P17: =(O17-O16)*10 -> 11800 | Q17: =P17*Q6/100 -> 5782 | R17: =P17*R6/100 -> 6018 | S17: 466160 | T17: =(S17-S16)*10 -> 20 | U17: =T17*U6/100 -> 9.8 | V17: =T17*V6/100 -> 10.2 | W17: 240391 | X17: =(W17-W16)*10 -> 20 | Y17: =X17*Y6/100 -> 9.8 | Z17: =X17*Z6/100 -> 10.2 | AA17: 313870 | AB17: =(AA17-AA16)*10 -> 40 | AC17: =AB17*AC6/100 -> 19.6 | AD17: =AB17*AD6/100 -> 20.4 | AE17: 93622 | AF17: =(AE17-AE16)*10 -> 1330 | AG17: 177243 | AH17: =(AG17-AG16)*10 -> 2530 | AI17: 315009 | AJ17: =(AI17-AI16)*10 -> 3970 | AK17: 159730 | AL17: =(AK17-AK16)*10 -> 2010 | AM17: 837232 | AN17: =(AM17-AM16)*10 -> 9500 | AP17: =SUM(D17,F17,I17,L17,N17,Q17,U17,Y17,AC17) -> 40665 | AQ17: =SUM(R17,V17,Z17,AD17,AF17,AH17,AJ17,AL17,AN17,J17) -> 32345
A18: =SUM(A17+1) -> 44876 | C18: 329243 | D18: =(C18-C17)*10 -> 4010 | E18: 565693 | F18: =(E18-E17)*10 -> 8150 | G18: 370575 | H18: =(G18-G17)*10 -> 14510 | I18: =H18*I6/100 -> 7109.9 | J18: =H18*J6/100 -> 7400.1 | K18: 483386 | L18: =(K18-K17)*10 -> 6360 | M18: 773430 | N18: =(M18-M17)*10 -> 11480 | O18: 490018 | P18: =(O18-O17)*10 -> 12880 | Q18: =P18*Q6/100 -> 6311.2 | R18: =P18*R6/100 -> 6568.8 | S18: 466162 | T18: =(S18-S17)*10 -> 20 | U18: =T18*U6/100 -> 9.8 | V18: =T18*V6/100 -> 10.2 | W18: 240393 | X18: =(W18-W17)*10 -> 20 | Y18: =X18*Y6/100 -> 9.8 | Z18: =X18*Z6/100 -> 10.2 | AA18: 313874 | AB18: =(AA18-AA17)*10 -> 40 | AC18: =AB18*AC6/100 -> 19.6 | AD18: =AB18*AD6/100 -> 20.4 | AE18: 93756 | AF18: =(AE18-AE17)*10 -> 1340 | AG18: 177506 | AH18: =(AG18-AG17)*10 -> 2630 | AI18: 315408 | AJ18: =(AI18-AI17)*10 -> 3990 | AK18: 159937 | AL18: =(AK18-AK17)*10 -> 2070 | AM18: 838201 | AN18: =(AM18-AM17)*10 -> 9690 | AP18: =SUM(D18,F18,I18,L18,N18,Q18,U18,Y18,AC18) -> 43460.3 | AQ18: =SUM(R18,V18,Z18,AD18,AF18,AH18,AJ18,AL18,AN18,J18) -> 33729.7
A19: =SUM(A18+1) -> 44877 | C19: 329635 | D19: =(C19-C18)*10 -> 3920 | E19: 566474 | F19: =(E19-E18)*10 -> 7810 | G19: 371617 | H19: =(G19-G18)*10 -> 10420 | I19: =H19*I6/100 -> 5105.8 | J19: =H19*J6/100 -> 5314.2 | K19: 484029 | L19: =(K19-K18)*10 -> 6430 | M19: 774569 | N19: =(M19-M18)*10 -> 11390 | O19: 491443 | P19: =(O19-O18)*10 -> 14250 | Q19: =P19*Q6/100 -> 6982.5 | R19: =P19*R6/100 -> 7267.5 | S19: 466165 | T19: =(S19-S18)*10 -> 30 | U19: =T19*U6/100 -> 14.7 | V19: =T19*V6/100 -> 15.3 | W19: 240396 | X19: =(W19-W18)*10 -> 30 | Y19: =X19*Y6/100 -> 14.7 | Z19: =X19*Z6/100 -> 15.3 | AA19: 313878 | AB19: =(AA19-AA18)*10 -> 40 | AC19: =AB19*AC6/100 -> 19.6 | AD19: =AB19*AD6/100 -> 20.4 | AE19: 93893 | AF19: =(AE19-AE18)*10 -> 1370 | AG19: 177758 | AH19: =(AG19-AG18)*10 -> 2520 | AI19: 315804 | AJ19: =(AI19-AI18)*10 -> 3960 | AK19: 160144 | AL19: =(AK19-AK18)*10 -> 2070 | AM19: 839146 | AN19: =(AM19-AM18)*10 -> 9450 | AP19: =SUM(D19,F19,I19,L19,N19,Q19,U19,Y19,AC19) -> 41687.3 | AQ19: =SUM(R19,V19,Z19,AD19,AF19,AH19,AJ19,AL19,AN19,J19) -> 32002.7
A20: =SUM(A19+1) -> 44878 | C20: 330048 | D20: =(C20-C19)*10 -> 4130 | E20: 567279 | F20: =(E20-E19)*10 -> 8050 | G20: 372726 | H20: =(G20-G19)*10 -> 11090 | I20: =H20*I6/100 -> 5434.1 | J20: =H20*J6/100 -> 5655.9 | K20: 484647 | L20: =(K20-K19)*10 -> 6180 | M20: 775650 | N20: =(M20-M19)*10 -> 10810 | O20: 493079 | P20: =(O20-O19)*10 -> 16360 | Q20: =P20*Q6/100 -> 8016.4 | R20: =P20*R6/100 -> 8343.6 | S20: 466167 | T20: =(S20-S19)*10 -> 20 | U20: =T20*U6/100 -> 9.8 | V20: =T20*V6/100 -> 10.2 | W20: 240398 | X20: =(W20-W19)*10 -> 20 | Y20: =X20*Y6/100 -> 9.8 | Z20: =X20*Z6/100 -> 10.2 | AA20: 313881 | AB20: =(AA20-AA19)*10 -> 30 | AC20: =AB20*AC6/100 -> 14.7 | AD20: =AB20*AD6/100 -> 15.3 | AE20: 94023 | AF20: =(AE20-AE19)*10 -> 1300 | AG20: 178005 | AH20: =(AG20-AG19)*10 -> 2470 | AI20: 316183 | AJ20: =(AI20-AI19)*10 -> 3790 | AK20: 160347 | AL20: =(AK20-AK19)*10 -> 2030 | AM20: 840099 | AN20: =(AM20-AM19)*10 -> 9530 | AP20: =SUM(D20,F20,I20,L20,N20,Q20,U20,Y20,AC20) -> 42654.8 | AQ20: =SUM(R20,V20,Z20,AD20,AF20,AH20,AJ20,AL20,AN20,J20) -> 33155.2
A21: =SUM(A20+1) -> 44879 | C21: 330420 | D21: =(C21-C20)*10 -> 3720 | E21: 567997 | F21: =(E21-E20)*10 -> 7180 | G21: 373962 | H21: =(G21-G20)*10 -> 12360 | I21: =H21*I6/100 -> 6056.4 | J21: =H21*J6/100 -> 6303.6 | K21: 485242 | L21: =(K21-K20)*10 -> 5950 | M21: 776595 | N21: =(M21-M20)*10 -> 9450 | O21: 494111 | P21: =(O21-O20)*10 -> 10320 | Q21: =P21*Q6/100 -> 5056.8 | R21: =P21*R6/100 -> 5263.2 | S21: 466169 | T21: =(S21-S20)*10 -> 20 | U21: =T21*U6/100 -> 9.8 | V21: =T21*V6/100 -> 10.2 | W21: 240400 | X21: =(W21-W20)*10 -> 20 | Y21: =X21*Y6/100 -> 9.8 | Z21: =X21*Z6/100 -> 10.2 | AA21: 313885 | AB21: =(AA21-AA20)*10 -> 40 | AC21: =AB21*AC6/100 -> 19.6 | AD21: =AB21*AD6/100 -> 20.4 | AE21: 94151 | AF21: =(AE21-AE20)*10 -> 1280 | AG21: 178241 | AH21: =(AG21-AG20)*10 -> 2360 | AI21: 316554 | AJ21: =(AI21-AI20)*10 -> 3710 | AK21: 160537 | AL21: =(AK21-AK20)*10 -> 1900 | AM21: 840984 | AN21: =(AM21-AM20)*10 -> 8850 | AP21: =SUM(D21,F21,I21,L21,N21,Q21,U21,Y21,AC21) -> 37452.4 | AQ21: =SUM(R21,V21,Z21,AD21,AF21,AH21,AJ21,AL21,AN21,J21) -> 29707.6
A22: =SUM(A21+1) -> 44880 | C22: 330805 | D22: =(C22-C21)*10 -> 3850 | E22: 568755 | F22: =(E22-E21)*10 -> 7580 | G22: 374969 | H22: =(G22-G21)*10 -> 10070 | I22: =H22*I6/100 -> 4934.3 | J22: =H22*J6/100 -> 5135.7 | K22: 485694 | L22: =(K22-K21)*10 -> 4520 | M22: 777680 | N22: =(M22-M21)*10 -> 10850 | O22: 495515 | P22: =(O22-O21)*10 -> 14040 | Q22: =P22*Q6/100 -> 6879.6 | R22: =P22*R6/100 -> 7160.4 | S22: 466171 | T22: =(S22-S21)*10 -> 20 | U22: =T22*U6/100 -> 9.8 | V22: =T22*V6/100 -> 10.2 | W22: 240402 | X22: =(W22-W21)*10 -> 20 | Y22: =X22*Y6/100 -> 9.8 | Z22: =X22*Z6/100 -> 10.2 | AA22: 313888 | AB22: =(AA22-AA21)*10 -> 30 | AC22: =AB22*AC6/100 -> 14.7 | AD22: =AB22*AD6/100 -> 15.3 | AE22: 94282 | AF22: =(AE22-AE21)*10 -> 1310 | AG22: 178494 | AH22: =(AG22-AG21)*10 -> 2530 | AI22: 316945 | AJ22: =(AI22-AI21)*10 -> 3910 | AK22: 160739 | AL22: =(AK22-AK21)*10 -> 2020 | AM22: 841926 | AN22: =(AM22-AM21)*10 -> 9420 | AP22: =SUM(D22,F22,I22,L22,N22,Q22,U22,Y22,AC22) -> 38648.2 | AQ22: =SUM(R22,V22,Z22,AD22,AF22,AH22,AJ22,AL22,AN22,J22) -> 31521.8
A23: =SUM(A22+1) -> 44881 | C23: 331207 | D23: =(C23-C22)*10 -> 4020 | E23: 569802 | F23: =(E23-E22)*10 -> 10470 | G23: 376254 | H23: =(G23-G22)*10 -> 12850 | I23: =H23*I6/100 -> 6296.5 | J23: =H23*J6/100 -> 6553.5 | K23: 486455 | L23: =(K23-K22)*10 -> 7610 | M23: 778772 | N23: =(M23-M22)*10 -> 10920 | O23: 496802 | P23: =(O23-O22)*10 -> 12870 | Q23: =P23*Q6/100 -> 6306.3 | R23: =P23*R6/100 -> 6563.7 | S23: 466173 | T23: =(S23-S22)*10 -> 20 | U23: =T23*U6/100 -> 9.8 | V23: =T23*V6/100 -> 10.2 | W23: 240405 | X23: =(W23-W22)*10 -> 30 | Y23: =X23*Y6/100 -> 14.7 | Z23: =X23*Z6/100 -> 15.3 | AA23: 313892 | AB23: =(AA23-AA22)*10 -> 40 | AC23: =AB23*AC6/100 -> 19.6 | AD23: =AB23*AD6/100 -> 20.4 | AE23: 94410 | AF23: =(AE23-AE22)*10 -> 1280 | AG23: 178759 | AH23: =(AG23-AG22)*10 -> 2650 | AI23: 317339 | AJ23: =(AI23-AI22)*10 -> 3940 | AK23: 160948 | AL23: =(AK23-AK22)*10 -> 2090 | AM23: 842866 | AN23: =(AM23-AM22)*10 -> 9400 | AP23: =SUM(D23,F23,I23,L23,N23,Q23,U23,Y23,AC23) -> 45666.9 | AQ23: =SUM(R23,V23,Z23,AD23,AF23,AH23,AJ23,AL23,AN23,J23) -> 32523.1
A24: =SUM(A23+1) -> 44882 | C24: =(C23+C25)/2 -> 331601.5 | D24: =(C24-C23)*10 -> 3945 | E24: =(E23+E25)/2 -> 570463.5 | F24: =(E24-E23)*10 -> 6615 | G24: =(G23+G25)/2 -> 377621 | H24: =(G24-G23)*10 -> 13670 | I24: =H24*I6/100 -> 6698.3 | J24: =H24*J6/100 -> 6971.7 | K24: =(K23+K25)/2 -> 487092.5 | L24: =(K24-K23)*10 -> 6375 | M24: 779871 | N24: =(M24-M23)*10 -> 10990 | O24: 497092 | P24: =(O24-O23)*10 -> 2900 | Q24: =P24*Q6/100 -> 1421 | R24: =P24*R6/100 -> 1479 | S24: 466175 | T24: =(S24-S23)*10 -> 20 | U24: =T24*U6/100 -> 9.8 | V24: =T24*V6/100 -> 10.2 | W24: 240407 | X24: =(W24-W23)*10 -> 20 | Y24: =X24*Y6/100 -> 9.8 | Z24: =X24*Z6/100 -> 10.2 | AA24: 313895 | AB24: =(AA24-AA23)*10 -> 30 | AC24: =AB24*AC6/100 -> 14.7 | AD24: =AB24*AD6/100 -> 15.3 | AE24: 94541 | AF24: =(AE24-AE23)*10 -> 1310 | AG24: 179013 | AH24: =(AG24-AG23)*10 -> 2540 | AI24: 317727 | AJ24: =(AI24-AI23)*10 -> 3880 | AK24: 161153 | AL24: =(AK24-AK23)*10 -> 2050 | AM24: 843810 | AN24: =(AM24-AM23)*10 -> 9440 | AP24: =SUM(D24,F24,I24,L24,N24,Q24,U24,Y24,AC24) -> 36078.6 | AQ24: =SUM(R24,V24,Z24,AD24,AF24,AH24,AJ24,AL24,AN24,J24) -> 27706.4
A25: =SUM(A24+1) -> 44883 | C25: 331996 | D25: =(C25-C24)*10 -> 3945 | E25: 571125 | F25: =(E25-E24)*10 -> 6615 | G25: 378988 | H25: =(G25-G24)*10 -> 13670 | I25: =H25*I6/100 -> 6698.3 | J25: =H25*J6/100 -> 6971.7 | K25: 487730 | L25: =(K25-K24)*10 -> 6375 | M25: 780989 | N25: =(M25-M24)*10 -> 11180 | O25: 499241 | P25: =(O25-O24)*10 -> 21490 | Q25: =P25*Q6/100 -> 10530.1 | R25: =P25*R6/100 -> 10959.9 | S25: 466191 | T25: =(S25-S24)*10 -> 160 | U25: =T25*U6/100 -> 78.4 | V25: =T25*V6/100 -> 81.6 | W25: 240409 | X25: =(W25-W24)*10 -> 20 | Y25: =X25*Y6/100 -> 9.8 | Z25: =X25*Z6/100 -> 10.2 | AA25: 313899 | AB25: =(AA25-AA24)*10 -> 40 | AC25: =AB25*AC6/100 -> 19.6 | AD25: =AB25*AD6/100 -> 20.4 | AE25: 94674 | AF25: =(AE25-AE24)*10 -> 1330 | AG25: 179275 | AH25: =(AG25-AG24)*10 -> 2620 | AI25: 318134 | AJ25: =(AI25-AI24)*10 -> 4070 | AK25: 161365 | AL25: =(AK25-AK24)*10 -> 2120 | AM25: 844770 | AN25: =(AM25-AM24)*10 -> 9600 | AP25: =SUM(D25,F25,I25,L25,N25,Q25,U25,Y25,AC25) -> 45451.2 | AQ25: =SUM(R25,V25,Z25,AD25,AF25,AH25,AJ25,AL25,AN25,J25) -> 37783.8
A26: =SUM(A25+1) -> 44884 | C26: 332416 | D26: =(C26-C25)*10 -> 4200 | E26: 571965 | F26: =(E26-E25)*10 -> 8400 | G26: 380132 | H26: =(G26-G25)*10 -> 11440 | I26: =H26*I6/100 -> 5605.6 | J26: =H26*J6/100 -> 5834.4 | K26: 488352 | L26: =(K26-K25)*10 -> 6220 | M26: 782113 | N26: =(M26-M25)*10 -> 11240 | O26: 500834 | P26: =(O26-O25)*10 -> 15930 | Q26: =P26*Q6/100 -> 7805.7 | R26: =P26*R6/100 -> 8124.3 | S26: 466194 | T26: =(S26-S25)*10 -> 30 | U26: =T26*U6/100 -> 14.7 | V26: =T26*V6/100 -> 15.3 | W26: 240411 | X26: =(W26-W25)*10 -> 20 | Y26: =X26*Y6/100 -> 9.8 | Z26: =X26*Z6/100 -> 10.2 | AA26: 313902 | AB26: =(AA26-AA25)*10 -> 30 | AC26: =AB26*AC6/100 -> 14.7 | AD26: =AB26*AD6/100 -> 15.3 | AE26: 94805 | AF26: =(AE26-AE25)*10 -> 1310 | AG26: 179525 | AH26: =(AG26-AG25)*10 -> 2500 | AI26: 318535 | AJ26: =(AI26-AI25)*10 -> 4010 | AK26: 161577 | AL26: =(AK26-AK25)*10 -> 2120 | AM26: 845740 | AN26: =(AM26-AM25)*10 -> 9700 | AP26: =SUM(D26,F26,I26,L26,N26,Q26,U26,Y26,AC26) -> 43510.5 | AQ26: =SUM(R26,V26,Z26,AD26,AF26,AH26,AJ26,AL26,AN26,J26) -> 33639.5
A27: =SUM(A26+1) -> 44885 | C27: 332796 | D27: =(C27-C26)*10 -> 3800 | E27: 572707 | F27: =(E27-E26)*10 -> 7420 | G27: 381173 | H27: =(G27-G26)*10 -> 10410 | I27: =H27*I6/100 -> 5100.9 | J27: =H27*J6/100 -> 5309.1 | K27: 488992 | L27: =(K27-K26)*10 -> 6400 | M27: 783227 | N27: =(M27-M26)*10 -> 11140 | O27: 502297 | P27: =(O27-O26)*10 -> 14630 | Q27: =P27*Q6/100 -> 7168.7 | R27: =P27*R6/100 -> 7461.3 | S27: 466196 | T27: =(S27-S26)*10 -> 20 | U27: =T27*U6/100 -> 9.8 | V27: =T27*V6/100 -> 10.2 | W27: 240414 | X27: =(W27-W26)*10 -> 30 | Y27: =X27*Y6/100 -> 14.7 | Z27: =X27*Z6/100 -> 15.3 | AA27: 313905 | AB27: =(AA27-AA26)*10 -> 30 | AC27: =AB27*AC6/100 -> 14.7 | AD27: =AB27*AD6/100 -> 15.3 | AE27: 94933 | AF27: =(AE27-AE26)*10 -> 1280 | AG27: 179760 | AH27: =(AG27-AG26)*10 -> 2350 | AI27: 318909 | AJ27: =(AI27-AI26)*10 -> 3740 | AK27: 161784 | AL27: =(AK27-AK26)*10 -> 2070 | AM27: 846652 | AN27: =(AM27-AM26)*10 -> 9120 | AP27: =SUM(D27,F27,I27,L27,N27,Q27,U27,Y27,AC27) -> 41068.8 | AQ27: =SUM(R27,V27,Z27,AD27,AF27,AH27,AJ27,AL27,AN27,J27) -> 31371.2
A28: =SUM(A27+1) -> 44886 | C28: 333182 | D28: =(C28-C27)*10 -> 3860 | E28: 573437 | F28: =(E28-E27)*10 -> 7300 | G28: 382417 | H28: =(G28-G27)*10 -> 12440 | I28: =H28*I6/100 -> 6095.6 | J28: =H28*J6/100 -> 6344.4 | K28: 489589 | L28: =(K28-K27)*10 -> 5970 | M28: 784212 | N28: =(M28-M27)*10 -> 9850 | O28: 503372 | P28: =(O28-O27)*10 -> 10750 | Q28: =P28*Q6/100 -> 5267.5 | R28: =P28*R6/100 -> 5482.5 | S28: 466198 | T28: =(S28-S27)*10 -> 20 | U28: =T28*U6/100 -> 9.8 | V28: =T28*V6/100 -> 10.2 | W28: 240416 | X28: =(W28-W27)*10 -> 20 | Y28: =X28*Y6/100 -> 9.8 | Z28: =X28*Z6/100 -> 10.2 | AA28: 313909 | AB28: =(AA28-AA27)*10 -> 40 | AC28: =AB28*AC6/100 -> 19.6 | AD28: =AB28*AD6/100 -> 20.4 | AE28: 95060 | AF28: =(AE28-AE27)*10 -> 1270 | AG28: 180089 | AH28: =(AG28-AG27)*10 -> 3290 | AI28: 319297 | AJ28: =(AI28-AI27)*10 -> 3880 | AK28: 161992 | AL28: =(AK28-AK27)*10 -> 2080 | AM28: 847562 | AN28: =(AM28-AM27)*10 -> 9100 | AP28: =SUM(D28,F28,I28,L28,N28,Q28,U28,Y28,AC28) -> 38382.3 | AQ28: =SUM(R28,V28,Z28,AD28,AF28,AH28,AJ28,AL28,AN28,J28) -> 31487.7
A29: =SUM(A28+1) -> 44887 | C29: 333575 | D29: =(C29-C28)*10 -> 3930 | E29: 574217 | F29: =(E29-E28)*10 -> 7800 | G29: 383713 | H29: =(G29-G28)*10 -> 12960 | I29: =H29*I6/100 -> 6350.4 | J29: =H29*J6/100 -> 6609.6 | K29: 490198 | L29: =(K29-K28)*10 -> 6090 | M29: 785324 | N29: =(M29-M28)*10 -> 11120 | O29: 504539 | P29: =(O29-O28)*10 -> 11670 | Q29: =P29*Q6/100 -> 5718.3 | R29: =P29*R6/100 -> 5951.7 | S29: 466200 | T29: =(S29-S28)*10 -> 20 | U29: =T29*U6/100 -> 9.8 | V29: =T29*V6/100 -> 10.2 | W29: 240418 | X29: =(W29-W28)*10 -> 20 | Y29: =X29*Y6/100 -> 9.8 | Z29: =X29*Z6/100 -> 10.2 | AA29: 313912 | AB29: =(AA29-AA28)*10 -> 30 | AC29: =AB29*AC6/100 -> 14.7 | AD29: =AB29*AD6/100 -> 15.3 | AE29: 95186 | AF29: =(AE29-AE28)*10 -> 1260 | AG29: 180258 | AH29: =(AG29-AG28)*10 -> 1690 | AI29: 319688 | AJ29: =(AI29-AI28)*10 -> 3910 | AK29: 162194 | AL29: =(AK29-AK28)*10 -> 2020 | AM29: 848467 | AN29: =(AM29-AM28)*10 -> 9050 | AP29: =SUM(D29,F29,I29,L29,N29,Q29,U29,Y29,AC29) -> 41043 | AQ29: =SUM(R29,V29,Z29,AD29,AF29,AH29,AJ29,AL29,AN29,J29) -> 30527
A30: =SUM(A29+1) -> 44888 | C30: 333962 | D30: =(C30-C29)*10 -> 3870 | E30: 574976 | F30: =(E30-E29)*10 -> 7590 | G30: 385024 | H30: =(G30-G29)*10 -> 13110 | I30: =H30*I6/100 -> 6423.9 | J30: =H30*J6/100 -> 6686.1 | K30: 490815 | L30: =(K30-K29)*10 -> 6170 | M30: 786457 | N30: =(M30-M29)*10 -> 11330 | O30: 505757 | P30: =(O30-O29)*10 -> 12180 | Q30: =P30*Q6/100 -> 5968.2 | R30: =P30*R6/100 -> 6211.8 | S30: 466202 | T30: =(S30-S29)*10 -> 20 | U30: =T30*U6/100 -> 9.8 | V30: =T30*V6/100 -> 10.2 | W30: 240420 | X30: =(W30-W29)*10 -> 20 | Y30: =X30*Y6/100 -> 9.8 | Z30: =X30*Z6/100 -> 10.2 | AA30: 313916 | AB30: =(AA30-AA29)*10 -> 40 | AC30: =AB30*AC6/100 -> 19.6 | AD30: =AB30*AD6/100 -> 20.4 | AE30: 95322 | AF30: =(AE30-AE29)*10 -> 1360 | AG30: 180513 | AH30: =(AG30-AG29)*10 -> 2550 | AI30: 320085 | AJ30: =(AI30-AI29)*10 -> 3970 | AK30: 162403 | AL30: =(AK30-AK29)*10 -> 2090 | AM30: 849411 | AN30: =(AM30-AM29)*10 -> 9440 | AP30: =SUM(D30,F30,I30,L30,N30,Q30,U30,Y30,AC30) -> 41391.3 | AQ30: =SUM(R30,V30,Z30,AD30,AF30,AH30,AJ30,AL30,AN30,J30) -> 32348.7
A31: =SUM(A30+1) -> 44889 | C31: 334355 | D31: =(C31-C30)*10 -> 3930 | E31: 575765 | F31: =(E31-E30)*10 -> 7890 | G31: 386295 | H31: =(G31-G30)*10 -> 12710 | I31: =H31*I6/100 -> 6227.9 | J31: =H31*J6/100 -> 6482.1 | K31: 491437 | L31: =(K31-K30)*10 -> 6220 | M31: 787618 | N31: =(M31-M30)*10 -> 11610 | O31: 506906 | P31: =(O31-O30)*10 -> 11490 | Q31: =P31*Q6/100 -> 5630.1 | R31: =P31*R6/100 -> 5859.9 | S31: 466204 | T31: =(S31-S30)*10 -> 20 | U31: =T31*U6/100 -> 9.8 | V31: =T31*V6/100 -> 10.2 | W31: 240422 | X31: =(W31-W30)*10 -> 20 | Y31: =X31*Y6/100 -> 9.8 | Z31: =X31*Z6/100 -> 10.2 | AA31: 313919 | AB31: =(AA31-AA30)*10 -> 30 | AC31: =AB31*AC6/100 -> 14.7 | AD31: =AB31*AD6/100 -> 15.3 | AE31: 95459 | AF31: =(AE31-AE30)*10 -> 1370 | AG31: 180772 | AH31: =(AG31-AG30)*10 -> 2590 | AI31: 320492 | AJ31: =(AI31-AI30)*10 -> 4070 | AK31: 162618 | AL31: =(AK31-AK30)*10 -> 2150 | AM31: 850398 | AN31: =(AM31-AM30)*10 -> 9870 | AP31: =SUM(D31,F31,I31,L31,N31,Q31,U31,Y31,AC31) -> 41542.3 | AQ31: =SUM(R31,V31,Z31,AD31,AF31,AH31,AJ31,AL31,AN31,J31) -> 32427.7
A32: =SUM(A31+1) -> 44890 | C32: 334749 | D32: =(C32-C31)*10 -> 3940 | E32: 576557 | F32: =(E32-E31)*10 -> 7920 | G32: 387300 | H32: =(G32-G31)*10 -> 10050 | I32: =H32*I6/100 -> 4924.5 | J32: =H32*J6/100 -> 5125.5 | K32: 492097 | L32: =(K32-K31)*10 -> 6600 | M32: 788797 | N32: =(M32-M31)*10 -> 11790 | O32: 508322 | P32: =(O32-O31)*10 -> 14160 | Q32: =P32*Q6/100 -> 6938.4 | R32: =P32*R6/100 -> 7221.6 | S32: 466206 | T32: =(S32-S31)*10 -> 20 | U32: =T32*U6/100 -> 9.8 | V32: =T32*V6/100 -> 10.2 | W32: 240425 | X32: =(W32-W31)*10 -> 30 | Y32: =X32*Y6/100 -> 14.7 | Z32: =X32*Z6/100 -> 15.3 | AA32: 313922 | AB32: =(AA32-AA31)*10 -> 30 | AC32: =AB32*AC6/100 -> 14.7 | AD32: =AB32*AD6/100 -> 15.3 | AE32: 95599 | AF32: =(AE32-AE31)*10 -> 1400 | AG32: 181023 | AH32: =(AG32-AG31)*10 -> 2510 | AI32: 320891 | AJ32: =(AI32-AI31)*10 -> 3990 | AK32: 162830 | AL32: =(AK32-AK31)*10 -> 2120 | AM32: 851340 | AN32: =(AM32-AM31)*10 -> 9420 | AP32: =SUM(D32,F32,I32,L32,N32,Q32,U32,Y32,AC32) -> 42152.1 | AQ32: =SUM(R32,V32,Z32,AD32,AF32,AH32,AJ32,AL32,AN32,J32) -> 31827.9
A33: =SUM(A32+1) -> 44891 | C33: 335151 | D33: =(C33-C32)*10 -> 4020 | E33: 577346 | F33: =(E33-E32)*10 -> 7890 | G33: 388604 | H33: =(G33-G32)*10 -> 13040 | I33: =H33*I6/100 -> 6389.6 | J33: =H33*J6/100 -> 6650.4 | K33: 492729 | L33: =(K33-K32)*10 -> 6320 | M33: 789968 | N33: =(M33-M32)*10 -> 11710 | O33: 509474 | P33: =(O33-O32)*10 -> 11520 | Q33: =P33*Q6/100 -> 5644.8 | R33: =P33*R6/100 -> 5875.2 | S33: 466208 | T33: =(S33-S32)*10 -> 20 | U33: =T33*U6/100 -> 9.8 | V33: =T33*V6/100 -> 10.2 | W33: 240427 | X33: =(W33-W32)*10 -> 20 | Y33: =X33*Y6/100 -> 9.8 | Z33: =X33*Z6/100 -> 10.2 | AA33: 313926 | AB33: =(AA33-AA32)*10 -> 40 | AC33: =AB33*AC6/100 -> 19.6 | AD33: =AB33*AD6/100 -> 20.4 | AE33: 95737 | AF33: =(AE33-AE32)*10 -> 1380 | AG33: 181274 | AH33: =(AG33-AG32)*10 -> 2510 | AI33: 321277 | AJ33: =(AI33-AI32)*10 -> 3860 | AK33: 163052 | AL33: =(AK33-AK32)*10 -> 2220 | AM33: 852275 | AN33: =(AM33-AM32)*10 -> 9350 | AP33: =SUM(D33,F33,I33,L33,N33,Q33,U33,Y33,AC33) -> 42013.6 | AQ33: =SUM(R33,V33,Z33,AD33,AF33,AH33,AJ33,AL33,AN33,J33) -> 31886.4
A34: =SUM(A33+1) -> 44892 | C34: 335558 | D34: =(C34-C33)*10 -> 4070 | E34: 578147 | F34: =(E34-E33)*10 -> 8010 | G34: 389980 | H34: =(G34-G33)*10 -> 13760 | I34: =H34*I6/100 -> 6742.4 | J34: =H34*J6/100 -> 7017.6 | K34: 493381 | L34: =(K34-K33)*10 -> 6520 | M34: 791128 | N34: =(M34-M33)*10 -> 11600 | O34: 510782 | P34: =(O34-O33)*10 -> 13080 | Q34: =P34*Q6/100 -> 6409.2 | R34: =P34*R6/100 -> 6670.8 | S34: 466211 | T34: =(S34-S33)*10 -> 30 | U34: =T34*U6/100 -> 14.7 | V34: =T34*V6/100 -> 15.3 | W34: 240429 | X34: =(W34-W33)*10 -> 20 | Y34: =X34*Y6/100 -> 9.8 | Z34: =X34*Z6/100 -> 10.2 | AA34: 313929 | AB34: =(AA34-AA33)*10 -> 30 | AC34: =AB34*AC6/100 -> 14.7 | AD34: =AB34*AD6/100 -> 15.3 | AE34: 95872 | AF34: =(AE34-AE33)*10 -> 1350 | AG34: 181519 | AH34: =(AG34-AG33)*10 -> 2450 | AI34: 321655 | AJ34: =(AI34-AI33)*10 -> 3780 | AK34: 163277 | AL34: =(AK34-AK33)*10 -> 2250 | AM34: 853209 | AN34: =(AM34-AM33)*10 -> 9340 | AP34: =SUM(D34,F34,I34,L34,N34,Q34,U34,Y34,AC34) -> 43390.8 | AQ34: =SUM(R34,V34,Z34,AD34,AF34,AH34,AJ34,AL34,AN34,J34) -> 32899.2
A35: =SUM(A34+1) -> 44893 | C35: 335947 | D35: =(C35-C34)*10 -> 3890 | E35: 578887 | F35: =(E35-E34)*10 -> 7400 | G35: 391275 | H35: =(G35-G34)*10 -> 12950 | I35: =H35*I6/100 -> 6345.5 | J35: =H35*J6/100 -> 6604.5 | K35: 493989 | L35: =(K35-K34)*10 -> 6080 | M35: 792138 | N35: =(M35-M34)*10 -> 10100 | O35: 512029 | P35: =(O35-O34)*10 -> 12470 | Q35: =P35*Q6/100 -> 6110.3 | R35: =P35*R6/100 -> 6359.7 | S35: 466677 | T35: =(S35-S34)*10 -> 4660 | U35: =T35*U6/100 -> 2283.4 | V35: =T35*V6/100 -> 2376.6 | W35: 240431 | X35: =(W35-W34)*10 -> 20 | Y35: =X35*Y6/100 -> 9.8 | Z35: =X35*Z6/100 -> 10.2 | AA35: 313932 | AB35: =(AA35-AA34)*10 -> 30 | AC35: =AB35*AC6/100 -> 14.7 | AD35: =AB35*AD6/100 -> 15.3 | AE35: 95998 | AF35: =(AE35-AE34)*10 -> 1260 | AG35: 181764 | AH35: =(AG35-AG34)*10 -> 2450 | AI35: 322037 | AJ35: =(AI35-AI34)*10 -> 3820 | AK35: 163485 | AL35: =(AK35-AK34)*10 -> 2080 | AM35: 854142 | AN35: =(AM35-AM34)*10 -> 9330 | AP35: =SUM(D35,F35,I35,L35,N35,Q35,U35,Y35,AC35) -> 42233.7 | AQ35: =SUM(R35,V35,Z35,AD35,AF35,AH35,AJ35,AL35,AN35,J35) -> 34306.3
A36: =SUM(A35+1) -> 44894 | C36: 336350 | D36: =(C36-C35)*10 -> 4030 | E36: 579700 | F36: =(E36-E35)*10 -> 8130 | G36: 392034 | H36: =(G36-G35)*10 -> 7590 | I36: =H36*I6/100 -> 3719.1 | J36: =H36*J6/100 -> 3870.9 | K36: 494629 | L36: =(K36-K35)*10 -> 6400 | M36: 793290 | N36: =(M36-M35)*10 -> 11520 | O36: 513524 | P36: =(O36-O35)*10 -> 14950 | Q36: =P36*Q6/100 -> 7325.5 | R36: =P36*R6/100 -> 7624.5 | S36: 467224 | T36: =(S36-S35)*10 -> 5470 | U36: =T36*U6/100 -> 2680.3 | V36: =T36*V6/100 -> 2789.7 | W36: 240433 | X36: =(W36-W35)*10 -> 20 | Y36: =X36*Y6/100 -> 9.8 | Z36: =X36*Z6/100 -> 10.2 | AA36: 314253 | AB36: =(AA36-AA35)*10 -> 3210 | AC36: =AB36*AC6/100 -> 1572.9 | AD36: =AB36*AD6/100 -> 1637.1 | AE36: 96129 | AF36: =(AE36-AE35)*10 -> 1310 | AG36: 182004 | AH36: =(AG36-AG35)*10 -> 2400 | AI36: 322413 | AJ36: =(AI36-AI35)*10 -> 3760 | AK36: 163687 | AL36: =(AK36-AK35)*10 -> 2020 | AM36: 855116 | AN36: =(AM36-AM35)*10 -> 9740 | AP36: =SUM(D36,F36,I36,L36,N36,Q36,U36,Y36,AC36) -> 45387.6 | AQ36: =SUM(R36,V36,Z36,AD36,AF36,AH36,AJ36,AL36,AN36,J36) -> 35162.4
A37: =SUM(A36+1) -> 44895 | C37: 336759 | D37: =(C37-C36)*10 -> 4090 | E37: 580470 | F37: =(E37-E36)*10 -> 7700 | G37: 392391 | H37: =(G37-G36)*10 -> 3570 | I37: =H37*I6/100 -> 1749.3 | J37: =H37*J6/100 -> 1820.7 | K37: 495249 | L37: =(K37-K36)*10 -> 6200 | M37: 794448 | N37: =(M37-M36)*10 -> 11580 | O37: 515099 | P37: =(O37-O36)*10 -> 15750 | Q37: =P37*Q6/100 -> 7717.5 | R37: =P37*R6/100 -> 8032.5 | S37: 467786 | T37: =(S37-S36)*10 -> 5620 | U37: =T37*U6/100 -> 2753.8 | V37: =T37*V6/100 -> 2866.2 | W37: 240435 | X37: =(W37-W36)*10 -> 20 | Y37: =X37*Y6/100 -> 9.8 | Z37: =X37*Z6/100 -> 10.2 | AA37: 314257 | AB37: =(AA37-AA36)*10 -> 40 | AC37: =AB37*AC6/100 -> 19.6 | AD37: =AB37*AD6/100 -> 20.4 | AE37: 96261 | AF37: =(AE37-AE36)*10 -> 1320 | AG37: 182257 | AH37: =(AG37-AG36)*10 -> 2530 | AI37: 322809 | AJ37: =(AI37-AI36)*10 -> 3960 | AK37: 163898 | AL37: =(AK37-AK36)*10 -> 2110 | AM37: 856102 | AN37: =(AM37-AM36)*10 -> 9860 | AP37: =SUM(D37,F37,I37,L37,N37,Q37,U37,Y37,AC37) -> 41820 | AQ37: =SUM(R37,V37,Z37,AD37,AF37,AH37,AJ37,AL37,AN37,J37) -> 32530
A38: Daily Record | D38: =SUM(D8:D37) -> 117790 | F38: =SUM(F8:F37) -> 232720 | H38: =SUM(H8:H37) -> 347920 | I38: =H38*I6/100 -> 170480.8 | J38: =H38*J6/100 -> 177439.2 | L38: =SUM(L8:L37) -> 187560 | N38: =SUM(N8:N37) -> 329700 | P38: =SUM(P8:P37) -> 363270 | Q38: =P38*Q6/100 -> 178002.3 | R38: =P38*R6/100 -> 185267.7 | T38: =SUM(T8:T37) -> 16990 | U38: =T38*U6/100 -> 8325.1 | V38: =T38*V6/100 -> 8664.9 | X38: =SUM(X8:X37) -> 1170 | Y38: =X38*Y6/100 -> 573.3 | Z38: =X38*Z6/100 -> 596.7 | AB38: =SUM(AB8:AB37) -> 4590 | AC38: =AB38*AC6/100 -> 2249.1 | AD38: =AB38*AD6/100 -> 2340.9 | AF38: =SUM(AF8:AF37) -> 39740 | AH38: =SUM(AH8:AH37) -> 75320 | AJ38: =SUM(AJ8:AJ37) -> 117390 | AL38: =SUM(AL8:AL37) -> 62320 | AN38: =SUM(AN8:AN37) -> 282380 | AP38: =SUM(AP8:AP37) -> 1227400.6 | AQ38: =SUM(AQ8:AQ37) -> 951459.4
AQ39: =SUM(AN38,AL38,AJ38,AH38,AF38,AD38,Z38,V38,R38,J38) -> 951459.4
A40: Monthly Record | C40: 324590 | E40: 556496 | G40: 356394 | K40: 475886 | M40: 760523 | O40: 477788 | S40: 466085 | W40: 240316 | AA40: 313794
...

Sheet Athens Daily - Water
C1: FSH | E1: FSH | G1: FSH | I1: FSH | K1: FSH & FSP | O1: FSP
C2: Hotel & podium Fresh Water | E2: Food & Beverage Outlets | G2: Fountains | I2: Swimming Pool | K2: Laundry (FSH 55% : FSP 45%) | O2: Place - Guest Floor Fresh Water
C3: M16601852 | E3: M118410300 | G3: M16449102 | I3: M9192527 / M21-501197 | K3: M16601455 | O3: M16601818 | R3: Daily Total consumption
A4: Tariff Type
A5: Date | C5: Reading | D5: Differecne m3 | E5: Reading | F5: Differecne m3 | G5: Reading | H5: Differecne m3 | I5: Reading | J5: Differecne m3 | K5: Reading | L5: Differecne m3 | M5: FSH | N5: FSP | O5: Reading | P5: Differecne m3
A6: 44865 | C6: 88352 | E6: 142941 | G6: 478.31 | K6: 49602 | M6: =L6*55% -> 0 | N6: =L6*45% -> 0 | O6: 51014
A7: 44866 | C7: 88611 | D7: =(C7-C6) -> 259 | E7: 143218 | F7: =(E7-E6) -> 277 | G7: 479.473 | H7: =(G7-G6) -> 1.163 | I7: 23402 | J7: =(I7-I6) -> 23402 | K7: 49767 | L7: =(K7-K6) -> 165 | M7: =L7*55% -> 90.75 | N7: =L7*45% -> 74.25 | O7: 51161 | P7: =(O7-O6) -> 147 | R7: =SUM(D7,F7,M70,H7) -> 537.163 | S7: =SUM(N7,P7) -> 221.25
