Workbook

Sheet TOTAL
A1: Site Name | B1: Day | C1: Month | D1: Year | E1: Total Electricity Kwh | F1: Electricity Tariff ($/Kwh) | G1: Natual Gas (m3) | H1: Natural Gas $/m3 | I1: Water Utility Supply (m3) m3 | J1: Water Utility Supply (m3) $/m3 | K1: Room Nights | L1: Total Guests | M1: Utilities day cost dh
A2: Mumbai | B2: 1 | C2: 12 | D2: 2022 | E2: =(IF('Daily HLP'!H4>0,'Daily HLP'!H4,0)) -> 22590.8 | F2: 10 | G2: =(IF('Daily HLP'!L4>0,'Daily HLP'!L4,0)) -> 982.4 | H2: 66 | I2: =(IF('Daily HLP'!O4>0,'Daily HLP'!O4,0)) -> 303 | J2: 100 | K2: =Occupancy!G2 -> 161 | L2: =Occupancy!F2 -> 451 | M2: =E2*F2+G2*H2+#REF!*#REF!+I2*J2 -> #REF!
A3: Mumbai | B3: =B2+1 -> 2 | C3: 12 | D3: 2022 | E3: =(IF('Daily HLP'!H5>0,'Daily HLP'!H5,0)) -> 22181.55 | F3: 10 | G3: =(IF('Daily HLP'!L5>0,'Daily HLP'!L5,0)) -> 1119.95 | H3: 66 | I3: =(IF('Daily HLP'!O5>0,'Daily HLP'!O5,0)) -> 313 | J3: 100 | K3: =Occupancy!G3 -> 152 | L3: =Occupancy!F3 -> 351 | M3: =E3*F3+G3*H3+#REF!*#REF!+I3*J3 -> #REF!
A4: Mumbai | B4: =B3+1 -> 3 | C4: 12 | D4: 2022 | E4: =(IF('Daily HLP'!H6>0,'Daily HLP'!H6,0)) -> 22630.65 | F4: 10 | G4: =(IF('Daily HLP'!L6>0,'Daily HLP'!L6,0)) -> 1133.65 | H4: 66 | I4: =(IF('Daily HLP'!O6>0,'Daily HLP'!O6,0)) -> 326 | J4: 100 | K4: =Occupancy!G4 -> 176 | L4: =Occupancy!F4 -> 369 | M4: =E4*F4+G4*H4+#REF!*#REF!+I4*J4 -> #REF!
A5: Mumbai | B5: =B4+1 -> 4 | C5: 12 | D5: 2022 | E5: =(IF('Daily HLP'!H7>0,'Daily HLP'!H7,0)) -> 23512 | F5: 10 | G5: =(IF('Daily HLP'!L7>0,'Daily HLP'!L7,0)) -> 1075.7 | H5: 66 | I5: =(IF('Daily HLP'!O7>0,'Daily HLP'!O7,0)) -> 269 | J5: 100 | K5: =Occupancy!G5 -> 179 | L5: =Occupancy!F5 -> 455 | M5: =E5*F5+G5*H5+#REF!*#REF!+I5*J5 -> #REF!
A6: Mumbai | B6: =B5+1 -> 5 | C6: 12 | D6: 2022 | E6: =(IF('Daily HLP'!H8>0,'Daily HLP'!H8,0)) -> 23970 | F6: 10 | G6: =(IF('Daily HLP'!L8>0,'Daily HLP'!L8,0)) -> 1103.3 | H6: 66 | I6: =(IF('Daily HLP'!O8>0,'Daily HLP'!O8,0)) -> 311 | J6: 100 | K6: =Occupancy!G6 -> 174 | L6: =Occupancy!F6 -> 482 | M6: =E6*F6+G6*H6+#REF!*#REF!+I6*J6 -> #REF!
A7: Mumbai | B7: =B6+1 -> 6 | C7: 12 | D7: 2022 | E7: =(IF('Daily HLP'!H9>0,'Daily HLP'!H9,0)) -> 22796 | F7: 10 | G7: =(IF('Daily HLP'!L9>0,'Daily HLP'!L9,0)) -> 1119.4 | H7: 66 | I7: =(IF('Daily HLP'!O9>0,'Daily HLP'!O9,0)) -> 363 | J7: 100 | K7: =Occupancy!G7 -> 167 | L7: =Occupancy!F7 -> 551 | M7: =E7*F7+G7*H7+#REF!*#REF!+I7*J7 -> #REF!
A8: Mumbai | B8: =B7+1 -> 7 | C8: 12 | D8: 2022 | E8: =(IF('Daily HLP'!H10>0,'Daily HLP'!H10,0)) -> 22420 | F8: 10 | G8: =(IF('Daily HLP'!L10>0,'Daily HLP'!L10,0)) -> 1104.6 | H8: 66 | I8: =(IF('Daily HLP'!O10>0,'Daily HLP'!O10,0)) -> 269 | J8: 100 | K8: =Occupancy!G8 -> 161 | L8: =Occupancy!F8 -> 658 | M8: =E8*F8+G8*H8+#REF!*#REF!+I8*J8 -> #REF!
A9: Mumbai | B9: =B8+1 -> 8 | C9: 12 | D9: 2022 | E9: =(IF('Daily HLP'!H11>0,'Daily HLP'!H11,0)) -> 23804.71 | F9: 10 | G9: =(IF('Daily HLP'!L11>0,'Daily HLP'!L11,0)) -> 1148.17 | H9: 66 | I9: =(IF('Daily HLP'!O11>0,'Daily HLP'!O11,0)) -> 293 | J9: 100 | K9: =Occupancy!G9 -> 145 | L9: =Occupancy!F9 -> 542 | M9: =E9*F9+G9*H9+#REF!*#REF!+I9*J9 -> #REF!
A10: Mumbai | B10: =B9+1 -> 9 | C10: 12 | D10: 2022 | E10: =(IF('Daily HLP'!H12>0,'Daily HLP'!H12,0)) -> 23775.84 | F10: 10 | G10: =(IF('Daily HLP'!L12>0,'Daily HLP'!L12,0)) -> 1100.83 | H10: 66 | I10: =(IF('Daily HLP'!O12>0,'Daily HLP'!O12,0)) -> 336 | J10: 100 | K10: =Occupancy!G10 -> 161 | L10: =Occupancy!F10 -> 398 | M10: =E10*F10+G10*H10+#REF!*#REF!+I10*J10 -> #REF!
A11: Mumbai | B11: =B10+1 -> 10 | C11: 12 | D11: 2022 | E11: =(IF('Daily HLP'!H13>0,'Daily HLP'!H13,0)) -> 22630.8 | F11: 10 | G11: =(IF('Daily HLP'!L13>0,'Daily HLP'!L13,0)) -> 1067.45 | H11: 66 | I11: =(IF('Daily HLP'!O13>0,'Daily HLP'!O13,0)) -> 325 | J11: 100 | K11: =Occupancy!G11 -> 158 | L11: =Occupancy!F11 -> 474 | M11: =E11*F11+G11*H11+#REF!*#REF!+I11*J11 -> #REF!
A12: Mumbai | B12: =B11+1 -> 11 | C12: 12 | D12: 2022 | E12: =(IF('Daily HLP'!H14>0,'Daily HLP'!H14,0)) -> 21797.04 | F12: 10 | G12: =(IF('Daily HLP'!L14>0,'Daily HLP'!L14,0)) -> 1121.55 | H12: 66 | I12: =(IF('Daily HLP'!O14>0,'Daily HLP'!O14,0)) -> 296 | J12: 100 | K12: =Occupancy!G12 -> 164 | L12: =Occupancy!F12 -> 0 | M12: =E12*F12+G12*H12+#REF!*#REF!+I12*J12 -> #REF!
A13: Mumbai | B13: =B12+1 -> 12 | C13: 12 | D13: 2022 | E13: =(IF('Daily HLP'!H15>0,'Daily HLP'!H15,0)) -> 22425.61 | F13: 10 | G13: =(IF('Daily HLP'!L15>0,'Daily HLP'!L15,0)) -> 1100 | H13: 66 | I13: =(IF('Daily HLP'!O15>0,'Daily HLP'!O15,0)) -> 411 | J13: 100 | K13: =Occupancy!G13 -> 164 | L13: =Occupancy!F13 -> 0 | M13: =E13*F13+G13*H13+#REF!*#REF!+I13*J13 -> #REF!
A14: Mumbai | B14: =B13+1 -> 13 | C14: 12 | D14: 2022 | E14: =(IF('Daily HLP'!H16>0,'Daily HLP'!H16,0)) -> 23047 | F14: 10 | G14: =(IF('Daily HLP'!L16>0,'Daily HLP'!L16,0)) -> 1014 | H14: 66 | I14: =(IF('Daily HLP'!O16>0,'Daily HLP'!O16,0)) -> 378 | J14: 100 | K14: =Occupancy!G14 -> 167 | L14: =Occupancy!F14 -> 0 | M14: =E14*F14+G14*H14+#REF!*#REF!+I14*J14 -> #REF!
... A31: Mumbai | B31: =B30+1 -> 30 | C31: 12 | D31: 2022 | E31: =(IF('Daily HLP'!H33>0,'Daily HLP'!H33,0)) -> 21529.17 | F31: 10 | G31: =(IF('Daily HLP'!L33>0,'Daily HLP'!L33,0)) -> 1214.29 | H31: 66 | I31: =(IF('Daily HLP'!O33>0,'Daily HLP'!O33,0)) -> 363 | J31: 100 | K31: =Occupancy!G31 -> 0 | L31: =Occupancy!F31 -> 0 | M31: =E31*F31+G31*H31+#REF!*#REF!+I31*J31 -> #REF!
A32: Mumbai | B32: =B31+1 -> 31 | C32: 12 | D32: 2022 | E32: =(IF('Daily HLP'!H34>0,'Daily HLP'!H34,0)) -> 22341.83 | F32: 10 | G32: =(IF('Daily HLP'!L34>0,'Daily HLP'!L34,0)) -> 1090.358 | H32: 66 | I32: =(IF('Daily HLP'!O34>0,'Daily HLP'!O34,0)) -> 228 | J32: 100 | K32: =Occupancy!G32 -> 0 | L32: =Occupancy!F32 -> 0

Sheet Submetering
A1: Site Name | B1: Day | C1: Month | D1: Year | E1: ='Section Load'!F4 -> HVAC | F1: ='Section Load'!G4 -> Fire & Emergency PP | G1: ='Section Load'!H4 -> Main PP | H1: ='Section Load'!I4 -> Lighting PP | I1: ='Section Load'!J4 -> CH-1+ CH2+CH3+CH4 | J1: ='Section Load'!K4 -> Chilled water Pump | K1: ='Section Load'!L4 -> Ball Room-1 | L1: ='Section Load'!M4 -> Ball Room-2 | ... AL1: ='Section Load'!AM4 -> Cooling Tower | AM1: R.o.plant | AN1: STP Water Prod | AO1: Domestic Zone-1 | AP1: Domestic Zone-2 | AQ1: Domestic Zone-3 | AR1: Flush Zone -1 | AS1: Flush Zone -2 | AT1: Flush Zone -3 | AU1: Swimming pool | AV1: B2 Laundry | AW1: Boiler Feed Water | AX1: cooling tower filling water | AY1: STP flush(new water meter) | AZ1: Garden Water Pump | BA1: Flush Zone 2 pump meter | BB1: Flush Zone 3 Pump Meter (wtp transfer ) | BC1: Flush Tanker-Zone-1 | BD1: Total Domestic Water (Tanker (R.O) +BMC) | BE1: Total Domestic Consumption | BF1: Total STP Consumption | BG1: ='Section Load'!AN4 -> MGL | BH1: ='Section Load'!AO4 -> HWG | BI1: ='Section Load'!AP4 -> Prato | BJ1: ='Section Load'!AQ4 -> BR-1 | BK1: ='Section Load'!AR4 -> SanQi IND | BL1: ='Section Load'!AS4 -> SanQi JPN | BM1: ='Section Load'!AT4 -> Boiler
A2: Mumbai | B2: 1 | C2: 12 | D2: 2022 | E2: =(IF('Section Load'!F5>0,'Section Load'!F5,0)) -> 3203 | F2: =(IF('Section Load'!G5>0,'Section Load'!G5,0)) -> 1051.37 | G2: =(IF('Section Load'!H5>0,'Section Load'!H5,0)) -> 2366.32 | H2: =(IF('Section Load'!I5>0,'Section Load'!I5,0)) -> 4254.48 | I2: =(IF('Section Load'!J5>0,'Section Load'!J5,0)) -> 3381.14 | J2: =(IF('Section Load'!K5>0,'Section Load'!K5,0)) -> 2399.44 | K2: =(IF('Section Load'!L5>0,'Section Load'!L5,0)) -> 1742.12 | L2: =(IF('Section Load'!M5>0,'Section Load'!M5,0)) -> 961.69 | ... AL2: =(IF('Section Load'!AM5>0,'Section Load'!AM5,0)) -> 769 | AM2: =(IF('Water Report'!$D$7>0,'Water Report'!$D$7,0)) -> 134 | AN2: =(IF('Water Report'!$D$8>0,'Water Report'!$D$8,0)) -> 33 | AO2: =(IF('Water Report'!$D$9>0,'Water Report'!$D$9,0)) -> 141 | AP2: =(IF('Water Report'!$D$10>0,'Water Report'!$D$10,0)) -> 10 | AQ2: =(IF('Water Report'!$D$11>0,'Water Report'!$D$11,0)) -> 19 | AR2: =(IF('Water Report'!$D$13>0,'Water Report'!$D$13,0)) -> 45 | AS2: =(IF('Water Report'!$D$14>0,'Water Report'!$D$14,0)) -> 5 | AT2: =(IF('Water Report'!$D$15>0,'Water Report'!$D$15,0)) -> 8 | AU2: =(IF('Water Report'!$D$17>0,'Water Report'!$D$17,0)) -> 2 | AV2: =(IF('Water Report'!$D$18>0,'Water Report'!$D$18,0)) -> 11 | AW2: =(IF('Water Report'!$D$19>0,'Water Report'!$D$19,0)) -> 13 | AX2: =(IF('Water Report'!$D$21>0,'Water Report'!$D$21,0)) -> 42 | AY2: =(IF('Water Report'!$D$22>0,'Water Report'!$D$22,0)) -> 0 | AZ2: =(IF('Water Report'!$D$23>0,'Water Report'!$D$23,0)) -> 0 | BA2: =(IF('Water Report'!$D$14>0,'Water Report'!$D$14,0)) -> 5 | BB2: =(IF('Water Report'!$D$15>0,'Water Report'!$D$15,0)) -> 8 | BC2: =(IF('Water Report'!$D$13>0,'Water Report'!$D$13,0)) -> 45 | BD2: =(IF('Water Report'!$D$24>0,'Water Report'!$D$24,0)) -> 303 | BE2: =(IF('Water Report'!$D$25>0,'Water Report'!$D$25,0)) -> 183 | BF2: =(IF('Water Report'!$D$27>0,'Water Report'!$D$27,0)) -> 87 | BG2: =(IF('Section Load'!AN5>0,'Section Load'!AN5,0)) -> 982.4 | BH2: =(IF('Section Load'!AO5>0,'Section Load'!AO5,0)) -> 282.58 | BI2: =(IF('Section Load'!AP5>0,'Section Load'!AP5,0)) -> 0.8 | BJ2: =(IF('Section Load'!AQ5>0,'Section Load'!AQ5,0)) -> 138 | BK2: =(IF('Section Load'!AR5>0,'Section Load'!AR5,0)) -> 47 | BL2: =(IF('Section Load'!AS5>0,'Section Load'!AS5,0)) -> 0 | BM2: =(IF('Section Load'!AT5>0,'Section Load'!AT5,0)) -> 514.02
A3: Mumbai | B3: =B2+1 -> 2 | C3: 12 | D3: 2022 | E3: =(IF('Section Load'!F6>0,'Section Load'!F6,0)) -> 3192.8 | F3: =(IF('Section Load'!G6>0,'Section Load'!G6,0)) -> 1025.96 | G3: =(IF('Section Load'!H6>0,'Section Load'!H6,0)) -> 2471.36 | H3: =(IF('Section Load'!I6>0,'Section Load'!I6,0)) -> 4202.16 | I3: =(IF('Section Load'!J6>0,'Section Load'!J6,0)) -> 3267.04 | J3: =(IF('Section Load'!K6>0,'Section Load'!K6,0)) -> 2386.32 | K3: =(IF('Section Load'!L6>0,'Section Load'!L6,0)) -> 1434 | L3: =(IF('Section Load'!M6>0,'Section Load'!M6,0)) -> 1103.55 | ... AL3: =(IF('Section Load'!AM6>0,'Section Load'!AM6,0)) -> 735 | AM3: =(IF('Water Report'!$E$7>0,'Water Report'!$E$7,0)) -> 109 | AN3: =(IF('Water Report'!$E$8>0,'Water Report'!$E$8,0)) -> 90 | AO3: =(IF('Water Report'!$E$9>0,'Water Report'!$E$9,0)) -> 114 | AP3: =(IF('Water Report'!$E$10>0,'Water Report'!$E$10,0)) -> 20 | AQ3: =(IF('Water Report'!$E$11>0,'Water Report'!$E$11,0)) -> 16 | AR3: =(IF('Water Report'!$E$13>0,'Water Report'!$E$13,0)) -> 46 | AS3: =(IF('Water Report'!$E$14>0,'Water Report'!$E$14,0)) -> 3 | AT3: =(IF('Water Report'!$E$15>0,'Water Report'!$E$15,0)) -> 11 | AU3: =(IF('Water Report'!$E$17>0,'Water Report'!$E$17,0)) -> 4 | AV3: =(IF('Water Report'!$E$18>0,'Water Report'!$E$18,0)) -> 13 | AW3: =(IF('Water Report'!$E$19>0,'Water Report'!$E$19,0)) -> 13 | AX3: =(IF('Water Report'!$E$21>0,'Water Report'!$E$21,0)) -> 105 | AY3: =(IF('Water Report'!$E$22>0,'Water Report'!$E$22,0)) -> 0 | AZ3: =(IF('Water Report'!$E$23>0,'Water Report'!$E$23,0)) -> 0 | BA3: =(IF('Water Report'!$E$14>0,'Water Report'!$E$14,0)) -> 3 | BB3: =(IF('Water Report'!$E$15>0,'Water Report'!$E$15,0)) -> 11 | BC3: =(IF('Water Report'!$E$13>0,'Water Report'!$E$13,0)) -> 46 | BD3: =(IF('Water Report'!$E$24>0,'Water Report'!$E$24,0)) -> 313 | BE3: =(IF('Water Report'!$E$25>0,'Water Report'!$E$25,0)) -> 164 | BF3: =(IF('Water Report'!$E$27>0,'Water Report'!$E$27,0)) -> 151 | BG3: =(IF('Section Load'!AN6>0,'Section Load'!AN6,0)) -> 1119.95 | BH3: =(IF('Section Load'!AO6>0,'Section Load'!AO6,0)) -> 291.76 | BI3: =(IF('Section Load'!AP6>0,'Section Load'!AP6,0)) -> 0 | BJ3: =(IF('Section Load'!AQ6>0,'Section Load'!AQ6,0)) -> 144 | BK3: =(IF('Section Load'!AR6>0,'Section Load'!AR6,0)) -> 56.8 | BL3: =(IF('Section Load'!AS6>0,'Section Load'!AS6,0)) -> 0 | BM3: =(IF('Section Load'!AT6>0,'Section Load'!AT6,0)) -> 627.79
A4: Mumbai | B4: =B3+1 -> 3 | C4: 12 | D4: 2022 | E4: =(IF('Section Load'!F7>0,'Section Load'!F7,0)) -> 3215.99 | F4: =(IF('Section Load'!G7>0,'Section Load'!G7,0)) -> 1030.82 | G4: =(IF('Section Load'!H7>0,'Section Load'!H7,0)) -> 2376.79 | H4: =(IF('Section Load'!I7>0,'Section Load'!I7,0)) -> 4054.8 | I4: =(IF('Section Load'!J7>0,'Section Load'!J7,0)) -> 3387.9 | J4: =(IF('Section Load'!K7>0,'Section Load'!K7,0)) -> 2408.44 | K4: =(IF('Section Load'!L7>0,'Section Load'!L7,0)) -> 1803.18 | L4: =(IF('Section Load'!M7>0,'Section Load'!M7,0)) -> 1154.72 | ... AL4: =(IF('Section Load'!AM7>0,'Section Load'!AM7,0)) -> 778 | AM4: =(IF('Water Report'!$F$7>0,'Water Report'!$F$7,0)) -> 109 | AN4: =(IF('Water Report'!$F$8>0,'Water Report'!$F$8,0)) -> 80 | AO4: =(IF('Water Report'!$F$9>0,'Water Report'!$G$9,0)) -> 122 | AP4: =(IF('Water Report'!$F$10>0,'Water Report'!$F$10,0)) -> 9 | AQ4: =(IF('Water Report'!$F$11>0,'Water Report'!$F$11,0)) -> 32 | AR4: =(IF('Water Report'!$F$13>0,'Water Report'!$F$13,0)) -> 19 | AS4: =(IF('Water Report'!$F$14>0,'Water Report'!$F$14,0)) -> 5 | AT4: =(IF('Water Report'!$F$15>0,'Water Report'!$F$15,0)) -> 6 | AU4: =(IF('Water Report'!$F$17>0,'Water Report'!$F$17,0)) -> 2 | AV4: =(IF('Water Report'!$F$18>0,'Water Report'!$F$18,0)) -> 12 | AW4: =(IF('Water Report'!$F$19>0,'Water Report'!$F$19,0)) -> 11 | AX4: =(IF('Water Report'!$F$21>0,'Water Report'!$F$21,0)) -> 75 | AY4: =(IF('Water Report'!$F$22>0,'Water Report'!$F$22,0)) -> 0 | AZ4: =(IF('Water Report'!$F$23>0,'Water Report'!$F$23,0)) -> 8 | BA4: =(IF('Water Report'!$F$14>0,'Water Report'!$F$14,0)) -> 5 | BB4: =(IF('Water Report'!$F$15>0,'Water Report'!$F$15,0)) -> 6 | BC4: =(IF('Water Report'!$F$13>0,'Water Report'!$F$13,0)) -> 19 | BD4: =(IF('Water Report'!$F$24>0,'Water Report'!$F$24,0)) -> 326 | BE4: =(IF('Water Report'!$F$25>0,'Water Report'!$F$25,0)) -> 173 | BF4: =(IF('Water Report'!$F$27>0,'Water Report'!$F$27,0)) -> 102 | BG4: =(IF('Section Load'!AN7>0,'Section Load'!AN7,0)) -> 1133.65 | BH4: =(IF('Section Load'!AO7>0,'Section Load'!AO7,0)) -> 287.09 | BI4: =(IF('Section Load'!AP7>0,'Section Load'!AP7,0)) -> 0 | BJ4: =(IF('Section Load'!AQ7>0,'Section Load'!AQ7,0)) -> 155 | BK4: =(IF('Section Load'!AR7>0,'Section Load'!AR7,0)) -> 71.2 | BL4: =(IF('Section Load'!AS7>0,'Section Load'!AS7,0)) -> 0 | BM4: =(IF('Section Load'!AT7>0,'Section Load'!AT7,0)) -> 620.36
A5: Mumbai | B5: =B4+1 -> 4 | C5: 12 | D5: 2022 | E5: =(IF('Section Load'!F8>0,'Section Load'!F8,0)) -> 3375.53 | F5: =(IF('Section Load'!G8>0,'Section Load'!G8,0)) -> 1092.73 | G5: =(IF('Section Load'!H8>0,'Section Load'!H8,0)) -> 2388.08 | H5: =(IF('Section Load'!I8>0,'Section Load'!I8,0)) -> 4044.24 | I5: =(IF('Section Load'!J8>0,'Section Load'!J8,0)) -> 3975.93 | J5: =(IF('Section Load'!K8>0,'Section Load'!K8,0)) -> 2485.6 | K5: =(IF('Section Load'!L8>0,'Section Load'!L8,0)) -> 1479.13 | L5: =(IF('Section Load'!M8>0,'Section Load'!M8,0)) -> 1308.44 | ... AL5: =(IF('Section Load'!AM8>0,'Section Load'!AM8,0)) -> 730 | AM5: =(IF('Water Report'!$G$7>0,'Water Report'!$F$7,0)) -> 109 | AN5: =(IF('Water Report'!$G$8>0,'Water Report'!$F$8,0)) -> 80 | AO5: =(IF('Water Report'!$G$9>0,'Water Report'!$H$9,0)) -> 128 | AP5: =(IF('Water Report'!$G$10>0,'Water Report'!$G$10,0)) -> 9 | AQ5: =(IF('Water Report'!$G$11>0,'Water Report'!$G$11,0)) -> 26 | AR5: =(IF('Water Report'!$G$13>0,'Water Report'!$G$13,0)) -> 31 | AS5: =(IF('Water Report'!$G$14>0,'Water Report'!$G$14,0)) -> 2 | AT5: =(IF('Water Report'!$G$15>0,'Water Report'!$G$15,0)) -> 8 | AU5: =(IF('Water Report'!$G$17>0,'Water Report'!$G$17,0)) -> 1 | AV5: =(IF('Water Report'!$G$18>0,'Water Report'!$G$18,0)) -> 13 | AW5: =(IF('Water Report'!$G$19>0,'Water Report'!$G$19,0)) -> 13 | AX5: =(IF('Water Report'!$G$21>0,'Water Report'!$G$21,0)) -> 48 | AY5: =(IF('Water Report'!$G$22>0,'Water Report'!$G$22,0)) -> 0 | AZ5: =(IF('Water Report'!$G$23>0,'Water Report'!$G$23,0)) -> 0 | BA5: =(IF('Water Report'!$G$14>0,'Water Report'!$G$14,0)) -> 2 | BB5: =(IF('Water Report'!$G$15>0,'Water Report'!$G$15,0)) -> 8 | BC5: =(IF('Water Report'!$G$13>0,'Water Report'!$G$13,0)) -> 31 | BD5: =(IF('Water Report'!$G$24>0,'Water Report'!$G$24,0)) -> 269 | BE5: =(IF('Water Report'!$G$25>0,'Water Report'!$G$25,0)) -> 167 | BF5: =(IF('Water Report'!$G$27>0,'Water Report'!$G$27,0)) -> 79 | BG5: =(IF('Section Load'!AN8>0,'Section Load'!AN8,0)) -> 1075.7 | BH5: =(IF('Section Load'!AO8>0,'Section Load'!AO8,0)) -> 306.84 | BI5: =(IF('Section Load'!AP8>0,'Section Load'!AP8,0)) -> 0 | BJ5: =(IF('Section Load'!AQ8>0,'Section Load'!AQ8,0)) -> 124 | BK5: =(IF('Section Load'!AR8>0,'Section Load'!AR8,0)) -> 21 | BL5: =(IF('Section Load'!AS8>0,'Section Load'!AS8,0)) -> 0 | BM5: =(IF('Section Load'!AT8>0,'Section Load'!AT8,0)) -> 623.86
A6: Mumbai | B6: =B5+1 -> 5 | C6: 12 | D6: 2022 | E6: =(IF('Section Load'!F9>0,'Section Load'!F9,0)) -> 3180.82 | F6: =(IF('Section Load'!G9>0,'Section Load'!G9,0)) -> 1082.57 | G6: =(IF('Section Load'!H9>0,'Section Load'!H9,0)) -> 2268.82 | H6: =(IF('Section Load'!I9>0,'Section Load'!I9,0)) -> 3946.86 | I6: =(IF('Section Load'!J9>0,'Section Load'!J9,0)) -> 4224.85 | J6: =(IF('Section Load'!K9>0,'Section Load'!K9,0)) -> 2443.73 | K6: =(IF('Section Load'!L9>0,'Section Load'!L9,0)) -> 1596.5 | L6: =(IF('Section Load'!M9>0,'Section Load'!M9,0)) -> 1200.49 | ... AL6: =(IF('Section Load'!AM9>0,'Section Load'!AM9,0)) -> 746 | AM6: =(IF('Water Report'!$H$7>0,'Water Report'!$H$7,0)) -> 96 | AN6: =(IF('Water Report'!$H$8>0,'Water Report'!$H$8,0)) -> 48 | AO6: =(IF('Water Report'!$H$9>0,'Water Report'!$H$9,0)) -> 128 | AP6: =(IF('Water Report'!$H$10>0,'Water Report'!$H$10,0)) -> 7 | AQ6: =(IF('Water Report'!$H$11>0,'Water Report'!$H$11,0)) -> 14 | AR6: =(IF('Water Report'!$H$13>0,'Water Report'!$H$13,0)) -> 18 | AS6: =(IF('Water Report'!$H$14>0,'Water Report'!$H$14,0)) -> 3 | AT6: =(IF('Water Report'!$H$15>0,'Water Report'!$H$15,0)) -> 5 | AU6: =(IF('Water Report'!$H$17>0,'Water Report'!$H$17,0)) -> 0 | AV6: =(IF('Water Report'!$H$18>0,'Water Report'!$H$18,0)) -> 10 | AW6: =(IF('Water Report'!$H$19>0,'Water Report'!$H$19,0)) -> 11 | AX6: =(IF('Water Report'!$H$21>0,'Water Report'!$H$21,0)) -> 18 | AY6: =(IF('Water Report'!$H$22>0,'Water Report'!$H$22,0)) -> 0 | AZ6: =(IF('Water Report'!$H$23>0,'Water Report'!$H$23,0)) -> 11 | BA6: =(IF('Water Report'!$H$14>0,'Water Report'!$H$14,0)) -> 3 | BB6: =(IF('Water Report'!$H$15>0,'Water Report'!$H$15,0)) -> 5 | BC6: =(IF('Water Report'!$H$13>0,'Water Report'!$H$13,0)) -> 18 | BD6: =(IF('Water Report'!$H$24>0,'Water Report'!$H$24,0)) -> 311 | BE6: =(IF('Water Report'!$H$25>0,'Water Report'!$H$25,0)) -> 157 | BF6: =(IF('Water Report'!$H$27>0,'Water Report'!$H$27,0)) -> 47 | BG6: =(IF('Section Load'!AN9>0,'Section Load'!AN9,0)) -> 1103.3 | BH6: =(IF('Section Load'!AO9>0,'Section Load'!AO9,0)) -> 302.7 | BI6: =(IF('Section Load'!AP9>0,'Section Load'!AP9,0)) -> 0 | BJ6: =(IF('Section Load'!AQ9>0,'Section Load'!AQ9,0)) -> 146 | BK6: =(IF('Section Load'!AR9>0,'Section Load'!AR9,0)) -> 76 | BL6: =(IF('Section Load'!AS9>0,'Section Load'!AS9,0)) -> 0.4 | BM6: =(IF('Section Load'!AT9>0,'Section Load'!AT9,0)) -> 578.2
A7: Mumbai | B7: =B6+1 -> 6 | C7: 12 | D7: 2022 | E7: =(IF('Section Load'!F10>0,'Section Load'!F10,0)) -> 3102.55 | F7: =(IF('Section Load'!G10>0,'Section Load'!G10,0)) -> 1091.71 | G7: =(IF('Section Load'!H10>0,'Section Load'!H10,0)) -> 2350.95 | H7: =(IF('Section Load'!I10>0,'Section Load'!I10,0)) -> 4047.78 | I7: =(IF('Section Load'!J10>0,'Section Load'!J10,0)) -> 3777.7 | J7: =(IF('Section Load'!K10>0,'Section Load'!K10,0)) -> 2370.6 | K7: =(IF('Section Load'!L10>0,'Section Load'!L10,0)) -> 1360.99 | L7: =(IF('Section Load'!M10>0,'Section Load'!M10,0)) -> 944.99 | ... AL7: =(IF('Section Load'!AM10>0,'Section Load'!AM10,0)) -> 709 | AM7: =(IF('Water Report'!$I$7>0,'Water Report'!$I$7,0)) -> 113 | AN7: =(IF('Water Report'!$I$8>0,'Water Report'!$I$8,0)) -> 46 | AO7: =(IF('Water Report'!$I$9>0,'Water Report'!$I$9,0)) -> 153 | AP7: =(IF('Water Report'!$I$10>0,'Water Report'!$I$10,0)) -> 5 | AQ7: =(IF('Water Report'!$I$11>0,'Water Report'!$I$11,0)) -> 17 | AR7: =(IF('Water Report'!$I$13>0,'Water Report'!$I$13,0)) -> 18 | AS7: =(IF('Water Report'!$I$14>0,'Water Report'!$I$14,0)) -> 3 | AT7: =(IF('Water Report'!$I$15>0,'Water Report'!$I$15,0)) -> 5 | AU7: =(IF('Water Report'!$I$17>0,'Water Report'!$I$17,0)) -> 1 | AV7: =(IF('Water Report'!$I$18>0,'Water Report'!$I$18,0)) -> 10 | AW7: =(IF('Water Report'!$I$19>0,'Water Report'!$I$19,0)) -> 16 | AX7: =(IF('Water Report'!$I$21>0,'Water Report'!$I$21,0)) -> 56 | AY7: =(IF('Water Report'!$I$22>0,'Water Report'!$I$22,0)) -> 0 | AZ7: =(IF('Water Report'!$I$23>0,'Water Report'!$I$23,0)) -> 0 | BA7: =(IF('Water Report'!$I$14>0,'Water Report'!$I$14,0)) -> 3 | BB7: =(IF('Water Report'!$I$15>0,'Water Report'!$I$15,0)) -> 5 | BC7: =(IF('Water Report'!$I$13>0,'Water Report'!$I$13,0)) -> 18 | BD7: =(IF('Water Report'!$I$24>0,'Water Report'!$I$24,0)) -> 363 | BE7: =(IF('Water Report'!$I$25>0,'Water Report'!$I$25,0)) -> 183 | BF7: =(IF('Water Report'!$I$27>0,'Water Report'!$I$27,0)) -> 74 | BG7: =(IF('Section Load'!AN10>0,'Section Load'!AN10,0)) -> 1119.4 | BH7: =(IF('Section Load'!AO10>0,'Section Load'!AO10,0)) -> 291.932 | BI7: =(IF('Section Load'!AP10>0,'Section Load'!AP10,0)) -> 0 | BJ7: =(IF('Section Load'!AQ10>0,'Section Load'!AQ10,0)) -> 106 | BK7: =(IF('Section Load'!AR10>0,'Section Load'!AR10,0)) -> 54 | BL7: =(IF('Section Load'!AS10>0,'Section Load'!AS10,0)) -> 0 | BM7: =(IF('Section Load'!AT10>0,'Section Load'!AT10,0)) -> 667.468
A8: Mumbai | B8: =B7+1 -> 7 | C8: 12 | D8: 2022 | E8: =(IF('Section Load'!F11>0,'Section Load'!F11,0)) -> 2378.35 | F8: =(IF('Section Load'!G11>0,'Section Load'!G11,0)) -> 1099.43 | G8: =(IF('Section Load'!H11>0,'Section Load'!H11,0)) -> 2462.48 | H8: =(IF('Section Load'!I11>0,'Section Load'!I11,0)) -> 4041.41 | I8: =(IF('Section Load'!J11>0,'Section Load'!J11,0)) -> 3991.22 | J8: =(IF('Section Load'!K11>0,'Section Load'!K11,0)) -> 2477.07 | K8: =(IF('Section Load'!L11>0,'Section Load'!L11,0)) -> 1309.36 | L8: =(IF('Section Load'!M11>0,'Section Load'!M11,0)) -> 907.22 | ... AL8: =(IF('Section Load'!AM11>0,'Section Load'!AM11,0)) -> 732 | AM8: =(IF('Water Report'!$J$7>0,'Water Report'!$J$7,0)) -> 122 | AN8: =(IF('Water Report'!$J$8>0,'Water Report'!$J$8,0)) -> 70 | AO8: =(IF('Water Report'!$J$9>0,'Water Report'!$J$9,0)) -> 125 | AP8: =(IF('Water Report'!$J$10>0,'Water Report'!$J$10,0)) -> 55455 | AQ8: =(IF('Water Report'!$J$11>0,'Water Report'!$J$11,0)) -> 16 | AR8: =(IF('Water Report'!$J$13>0,'Water Report'!$J$13,0)) -> 23 | AS8: =(IF('Water Report'!$J$14>0,'Water Report'!$J$14,0)) -> 3 | AT8: =(IF('Water Report'!$J$15>0,'Water Report'!$J$15,0)) -> 8 | AU8: =(IF('Water Report'!$J$17>0,'Water Report'!$J$17,0)) -> 2 | AV8: =(IF('Water Report'!$J$18>0,'Water Report'!$J$18,0)) -> 10 | AW8: =(IF('Water Report'!$J$19>0,'Water Report'!$J$19,0)) -> 16 | AX8: =(IF('Water Report'!$J$21>0,'Water Report'!$J$21,0)) -> 45 | AY8: =(IF('Water Report'!$J$22>0,'Water Report'!$J$22,0)) -> 0 | AZ8: =(IF('Water Report'!$J$23>0,'Water Report'!$J$23,0)) -> 0 | BA8: =(IF('Water Report'!$J$14>0,'Water Report'!$J$14,0)) -> 3 | BB8: =(IF('Water Report'!$J$15>0,'Water Report'!$J$15,0)) -> 8 | BC8: =(IF('Water Report'!$J$13>0,'Water Report'!$J$13,0)) -> 23 | BD8: =(IF('Water Report'!$J$24>0,'Water Report'!$J$24,0)) -> 269 | BE8: =(IF('Water Report'!$J$25>0,'Water Report'!$J$25,0)) -> 55607 | BF8: =(IF('Water Report'!$J$27>0,'Water Report'!$J$27,0)) -> 68 | BG8: =(IF('Section Load'!AN11>0,'Section Load'!AN11,0)) -> 1104.6 | BH8: =(IF('Section Load'!AO11>0,'Section Load'!AO11,0)) -> 270.042 | BI8: =(IF('Section Load'!AP11>0,'Section Load'!AP11,0)) -> 0 | BJ8: =(IF('Section Load'!AQ11>0,'Section Load'!AQ11,0)) -> 124.7 | BK8: =(IF('Section Load'!AR11>0,'Section Load'!AR11,0)) -> 56 | BL8: =(IF('Section Load'!AS11>0,'Section Load'!AS11,0)) -> 0 | BM8: =(IF('Section Load'!AT11>0,'Section Load'!AT11,0)) -> 654.258
A9: Mumbai | B9: =B8+1 -> 8 | C9: 12 | D9: 2022 | E9: =(IF('Section Load'!F12>0,'Section Load'!F12,0)) -> 3949 | F9: =(IF('Section Load'!G12>0,'Section Load'!G12,0)) -> 1129.94 | G9: =(IF('Section Load'!H12>0,'Section Load'!H12,0)) -> 2509.36 | H9: =(IF('Section Load'!I12>0,'Section Load'!I12,0)) -> 4125.79 | I9: =(IF('Section Load'!J12>0,'Section Load'!J12,0)) -> 4345.66 | J9: =(IF('Section Load'!K12>0,'Section Load'!K12,0)) -> 2578.24 | K9: =(IF('Section Load'!L12>0,'Section Load'!L12,0)) -> 1624.88 | L9: =(IF('Section Load'!M12>0,'Section Load'!M12,0)) -> 1015.08 | ... AL9: =(IF('Section Load'!AM12>0,'Section Load'!AM12,0)) -> 786 | AM9: =(IF('Water Report'!$K$7>0,'Water Report'!$K$7,0)) -> 112 | AN9: =(IF('Water Report'!$K$8>0,'Water Report'!$K$8,0)) -> 53 | AO9: =(IF('Water Report'!$K$9>0,'Water Report'!$K$9,0)) -> 129 | AP9: =(IF('Water Report'!$K$10>0,'Water Report'!$K$10,0)) -> 6 | AQ9: =(IF('Water Report'!$K$11>0,'Water Report'!$K$11,0)) -> 15 | AR9: =(IF('Water Report'!$K$13>0,'Water Report'!$K$13,0)) -> 34 | AS9: =(IF('Water Report'!$K$14>0,'Water Report'!$K$14,0)) -> 3 | AT9: =(IF('Water Report'!$K$15>0,'Water Report'!$K$15,0)) -> 5 | AU9: =(IF('Water Report'!$K$17>0,'Water Report'!$K$17,0)) -> 0 | AV9: =(IF('Water Report'!$K$18>0,'Water Report'!$K$18,0)) -> 12 | AW9: =(IF('Water Report'!$K$19>0,'Water Report'!$K$19,0)) -> 12 | AX9: =(IF('Water Report'!$K$21>0,'Water Report'!$K$21,0)) -> 76 | AY9: =(IF('Water Report'!$K$22>0,'Water Report'!$K$22,0)) -> 0 | AZ9: =(IF('Water Report'!$K$23>0,'Water Report'!$K$23,0)) -> 0 | BA9: =(IF('Water Report'!$K$14>0,'Water Report'!$K$14,0)) -> 3 | BB9: =(IF('Water Report'!$K$15>0,'Water Report'!$K$15,0)) -> 5 | BC9: =(IF('Water Report'!$K$13>0,'Water Report'!$K$13,0)) -> 34 | BD9: =(IF('Water Report'!$K$24>0,'Water Report'!$K$24,0)) -> 293 | BE9: =(IF('Water Report'!$K$25>0,'Water Report'!$K$25,0)) -> 158 | BF9: =(IF('Water Report'!$K$27>0,'Water Report'!$K$27,0)) -> 110 | BG9: =(IF('Section Load'!AN12>0,'Section Load'!AN12,0)) -> 1148.17 | BH9: =(IF('Section Load'!AO12>0,'Section Load'!AO12,0)) -> 320.726 | BI9: =(IF('Section Load'!AP12>0,'Section Load'!AP12,0)) -> 0 | BJ9: =(IF('Section Load'!AQ12>0,'Section Load'!AQ12,0)) -> 156.3 | BK9: =(IF('Section Load'!AR12>0,'Section Load'!AR12,0)) -> 49.9 | BL9: =(IF('Section Load'!AS12>0,'Section Load'!AS12,0)) -> 0.4 | BM9: =(IF('Section Load'!AT12>0,'Section Load'!AT12,0)) -> 620.844
A10: Mumbai | B10: =B9+1 -> 9 | C10: 12 | D10: 2022 | E10: =(IF('Section Load'!F13>0,'Section Load'!F13,0)) -> 3484.28 | F10: =(IF('Section Load'!G13>0,'Section Load'!G13,0)) -> 1153.43 | G10: =(IF('Section Load'!H13>0,'Section Load'!H13,0)) -> 2664.8 | H10: =(IF('Section Load'!I13>0,'Section Load'!I13,0)) -> 4238.16 | I10: =(IF('Section Load'!J13>0,'Section Load'!J13,0)) -> 3719.72 | J10: =(IF('Section Load'!K13>0,'Section Load'!K13,0)) -> 2540.6 | K10: =(IF('Section Load'!L13>0,'Section Load'!L13,0)) -> 1680.24 | L10: =(IF('Section Load'!M13>0,'Section Load'!M13,0)) -> 1217.34 | ... AL10: =(IF('Section Load'!AM13>0,'Section Load'!AM13,0)) -> 715 | AM10: =(IF('Water Report'!$L$7>0,'Water Report'!$L$7,0)) -> 136 | AN10: =(IF('Water Report'!$L$8>0,'Water Report'!$L$8,0)) -> 92 | AO10: =(IF('Water Report'!$L$9>0,'Water Report'!$L$9,0)) -> 155 | AP10: =(IF('Water Report'!$L$10>0,'Water Report'!$L$10,0)) -> 17 | AQ10: =(IF('Water Report'!$L$11>0,'Water Report'!$L$11,0)) -> 21 | AR10: =(IF('Water Report'!$L$13>0,'Water Report'!$L$13,0)) -> 20 | AS10: =(IF('Water Report'!$L$14>0,'Water Report'!$L$14,0)) -> 7 | AT10: =(IF('Water Report'!$L$15>0,'Water Report'!$L$15,0)) -> 8 | AU10: =(IF('Water Report'!$L$17>0,'Water Report'!$L$17,0)) -> 0 | AV10: =(IF('Water Report'!$L$18>0,'Water Report'!$L$18,0)) -> 13 | AW10: =(IF('Water Report'!$L$19>0,'Water Report'!$L$19,0)) -> 12 | AX10: =(IF('Water Report'!$L$21>0,'Water Report'!$L$21,0)) -> 80 | AY10: =(IF('Water Report'!$L$22>0,'Water Report'!$L$22,0)) -> 0 | AZ10: =(IF('Water Report'!$L$23>0,'Water Report'!$L$23,0)) -> 0 | BA10: =(IF('Water Report'!$L$14>0,'Water Report'!$L$14,0)) -> 7 | BB10: =(IF('Water Report'!$L$15>0,'Water Report'!$L$15,0)) -> 8 | BC10: =(IF('Water Report'!$L$13>0,'Water Report'!$L$13,0)) -> 20 | BD10: =(IF('Water Report'!$L$24>0,'Water Report'!$L$24,0)) -> 336 | BE10: =(IF('Water Report'!$L$25>0,'Water Report'!$L$25,0)) -> 208 | BF10: =(IF('Water Report'!$L$27>0,'Water Report'!$L$27,0)) -> 100 | BG10: =(IF('Section Load'!AN13>0,'Section Load'!AN13,0)) -> 1100.83 | BH10: =(IF('Section Load'!AO13>0,'Section Load'!AO13,0)) -> 311.3 | BI10: =(IF('Section Load'!AP13>0,'Section Load'!AP13,0)) -> 0 | BJ10: =(IF('Section Load'!AQ13>0,'Section Load'!AQ13,0)) -> 169.07 | BK10: =(IF('Section Load'!AR13>0,'Section Load'!AR13,0)) -> 57.1 | BL10: =(IF('Section Load'!AS13>0,'Section Load'!AS13,0)) -> 0 | BM10: =(IF('Section Load'!AT13>0,'Section Load'!AT13,0)) -> 563.36
A11: Mumbai | B11: =B10+1 -> 10 | C11: 12 | D11: 2022 | E11: =(IF('Section Load'!F14>0,'Section Load'!F14,0)) -> 3178.4 | F11: =(IF('Section Load'!G14>0,'Section Load'!G14,0)) -> 1099.91 | G11: =(IF('Section Load'!H14>0,'Section Load'!H14,0)) -> 2586 | H11: =(IF('Section Load'!I14>0,'Section Load'!I14,0)) -> 4085.28 | I11: =(IF('Section Load'!J14>0,'Section Load'!J14,0)) -> 3216.14 | J11: =(IF('Section Load'!K14>0,'Section Load'!K14,0)) -> 2560.8 | K11: =(IF('Section Load'!L14>0,'Section Load'!L14,0)) -> 1718.76 | L11: =(IF('Section Load'!M14>0,'Section Load'!M14,0)) -> 1092.58 | ... AL11: =(IF('Section Load'!AM14>0,'Section Load'!AM14,0)) -> 640 | AM11: =(IF('Water Report'!$M$7>0,'Water Report'!$M$7,0)) -> 143 | AN11: =(IF('Water Report'!$M$8>0,'Water Report'!$M$8,0)) -> 102 | AO11: =(IF('Water Report'!$M$9>0,'Water Report'!$M$9,0)) -> 152 | AP11: =(IF('Water Report'!$M$10>0,'Water Report'!$M$10,0)) -> 9 | AQ11: =(IF('Water Report'!$M$11>0,'Water Report'!$M$11,0)) -> 30 | AR11: =(IF('Water Report'!$M$13>0,'Water Report'!$M$13,0)) -> 41 | AS11: =(IF('Water Report'!$M$14>0,'Water Report'!$M$14,0)) -> 6 | AT11: =(IF('Water Report'!$M$15>0,'Water Report'!$M$15,0)) -> 8 | AU11: =(IF('Water Report'!$M$17>0,'Water Report'!$M$17,0)) -> 4 | AV11: =(IF('Water Report'!$M$18>0,'Water Report'!$M$18,0)) -> 12 | AW11: =(IF('Water Report'!$M$19>0,'Water Report'!$M$19,0)) -> 12 | AX11: =(IF('Water Report'!$M$21>0,'Water Report'!$M$21,0)) -> 152 | AY11: =(IF('Water Report'!$M$22>0,'Water Report'!$M$22,0)) -> 0 | AZ11: =(IF('Water Report'!$M$23>0,'Water Report'!$M$23,0)) -> 0 | BA11: =(IF('Water Report'!$M$14>0,'Water Report'!$M$14,0)) -> 6 | BB11: =(IF('Water Report'!$M$15>0,'Water Report'!$M$15,0)) -> 8 | BC11: =(IF('Water Report'!$M$13>0,'Water Report'!$M$13,0)) -> 41 | BD11: =(IF('Water Report'!$M$24>0,'Water Report'!$M$24,0)) -> 325 | BE11: =(IF('Water Report'!$M$25>0,'Water Report'!$M$25,0)) -> 205 | BF11: =(IF('Water Report'!$M$27>0,'Water Report'!$M$27,0)) -> 193 | BG11: =(IF('Section Load'!AN14>0,'Section Load'!AN14,0)) -> 1067.45 | BH11: =(IF('Section Load'!AO14>0,'Section Load'!AO14,0)) -> 272.74 | BI11: =(IF('Section Load'!AP14>0,'Section Load'!AP14,0)) -> 0 | BJ11: =(IF('Section Load'!AQ14>0,'Section Load'!AQ14,0)) -> 122.93 | BK11: =(IF('Section Load'!AR14>0,'Section Load'!AR14,0)) -> 54 | BL11: =(IF('Section Load'!AS14>0,'Section Load'!AS14,0)) -> 0 | BM11: =(IF('Section Load'!AT14>0,'Section Load'!AT14,0)) -> 618.18
A12: Mumbai | B12: =B11+1 -> 11 | C12: 12 | D12: 2022 | E12: =(IF('Section Load'!F15>0,'Section Load'!F15,0)) -> 3185.92 | F12: =(IF('Section Load'!G15>0,'Section Load'!G15,0)) -> 1031.92 | G12: =(IF('Section Load'!H15>0,'Section Load'!H15,0)) -> 2507.73 | H12: =(IF('Section Load'!I15>0,'Section Load'!I15,0)) -> 3897.76 | I12: =(IF('Section Load'!J15>0,'Section Load'!J15,0)) -> 3042.66 | J12: =(IF('Section Load'!K15>0,'Section Load'!K15,0)) -> 2372.64 | K12: =(IF('Section Load'!L15>0,'Section Load'!L15,0)) -> 1424.2 | L12: =(IF('Section Load'!M15>0,'Section Load'!M15,0)) -> 1133.64 | ... AL12: =(IF('Section Load'!AM15>0,'Section Load'!AM15,0)) -> 750 | AM12: =(IF('Water Report'!$N$7>0,'Water Report'!$N$7,0)) -> 121 | AN12: =(IF('Water Report'!$N$8>0,'Water Report'!$N$8,0)) -> 51 | AO12: =(IF('Water Report'!$N$9>0,'Water Report'!$N$9,0)) -> 131 | AP12: =(IF('Water Report'!$N$10>0,'Water Report'!$N$10,0)) -> 11 | AQ12: =(IF('Water Report'!$N$11>0,'Water Report'!$N$11,0)) -> 18 | AR12: =(IF('Water Report'!$N$13>0,'Water Report'!$N$13,0)) -> 22 | AS12: =(IF('Water Report'!$N$14>0,'Water Report'!$N$14,0)) -> 6 | AT12: =(IF('Water Report'!$N$15>0,'Water Report'!$N$15,0)) -> 6 | AU12: =(IF('Water Report'!$N$17>0,'Water Report'!$N$17,0)) -> 0 | AV12: =(IF('Water Report'!$N$18>0,'Water Report'!$N$18,0)) -> 13 | AW12: =(IF('Water Report'!$N$19>0,'Water Report'!$N$19,0)) -> 13 | AX12: =(IF('Water Report'!$N$21>0,'Water Report'!$N$21,0)) -> 140 | AY12: =(IF('Water Report'!$N$22>0,'Water Report'!$N$22,0)) -> 0 | AZ12: =(IF('Water Report'!$N$23>0,'Water Report'!$N$23,0)) -> 0 | BA12: =(IF('Water Report'!$N$14>0,'Water Report'!$N$14,0)) -> 6 | BB12: =(IF('Water Report'!$N$15>0,'Water Report'!$N$15,0)) -> 6 | BC12: =(IF('Water Report'!$N$13>0,'Water Report'!$N$13,0)) -> 22 | BD12: =(IF('Water Report'!$N$24>0,'Water Report'!$N$24,0)) -> 296 | BE12: =(IF('Water Report'!$N$25>0,'Water Report'!$N$25,0)) -> 172 | BF12: =(IF('Water Report'!$N$27>0,'Water Report'!$N$27,0)) -> 162 | BG12: =(IF('Section Load'!AN15>0,'Section Load'!AN15,0)) -> 1121.55 | BH12: =(IF('Section Load'!AO15>0,'Section Load'!AO15,0)) -> 265.36 | BI12: =(IF('Section Load'!AP15>0,'Section Load'!AP15,0)) -> 0 | BJ12: =(IF('Section Load'!AQ15>0,'Section Load'!AQ15,0)) -> 118.34 | BK12: =(IF('Section Load'!AR15>0,'Section Load'!AR15,0)) -> 62.2 | BL12: =(IF('Section Load'!AS15>0,'Section Load'!AS15,0)) -> 0 | BM12: =(IF('Section Load'!AT15>0,'Section Load'!AT15,0)) -> 675.65
A13: Mumbai | B13: =B12+1 -> 12 | C13: 12 | D13: 2022 | E13: =(IF('Section Load'!F16>0,'Section Load'!F16,0)) -> 3424.5 | F13: =(IF('Section Load'!G16>0,'Section Load'!G16,0)) -> 1048.66 | G13: =(IF('Section Load'!H16>0,'Section Load'!H16,0)) -> 2429.92 | H13: =(IF('Section Load'!I16>0,'Section Load'!I16,0)) -> 4085.82 | I13: =(IF('Section Load'!J16>0,'Section Load'!J16,0)) -> 3707.45 | J13: =(IF('Section Load'!K16>0,'Section Load'!K16,0)) -> 2405.05 | K13: =(IF('Section Load'!L16>0,'Section Load'!L16,0)) -> 1380.57 | L13: =(IF('Section Load'!M16>0,'Section Load'!M16,0)) -> 1112.15 | ... AL13: =(IF('Section Load'!AM16>0,'Section Load'!AM16,0)) -> 720 | AM13: =(IF('Water Report'!$O$7>0,'Water Report'!$O$7,0)) -> 101 | AN13: =(IF('Water Report'!$O$8>0,'Water Report'!$O$8,0)) -> 1 | AO13: =(IF('Water Report'!$O$9>0,'Water Report'!$O$9,0)) -> 123 | AP13: =(IF('Water Report'!$O$10>0,'Water Report'!$O$10,0)) -> 7 | AQ13: =(IF('Water Report'!$O$11>0,'Water Report'!$O$11,0)) -> 16 | AR13: =(IF('Water Report'!$O$13>0,'Water Report'!$O$13,0)) -> 34 | AS13: =(IF('Water Report'!$O$14>0,'Water Report'!$O$14,0)) -> 6 | AT13: =(IF('Water Report'!$O$15>0,'Water Report'!$O$15,0)) -> 5 | AU13: =(IF('Water Report'!$O$17>0,'Water Report'!$O$17,0)) -> 0 | AV13: =(IF('Water Report'!$O$18>0,'Water Report'!$O$18,0)) -> 11 | AW13: =(IF('Water Report'!$O$19>0,'Water Report'!$O$19,0)) -> 12 | AX13: =(IF('Water Report'!$O$21>0,'Water Report'!$O$21,0)) -> 124 | AY13: =(IF('Water Report'!$O$22>0,'Water Report'!$O$22,0)) -> 0 | AZ13: =(IF('Water Report'!$O$23>0,'Water Report'!$O$23,0)) -> 0 | BA13: =(IF('Water Report'!$O$14>0,'Water Report'!$O$14,0)) -> 6 | BB13: =(IF('Water Report'!$O$15>0,'Water Report'!$O$15,0)) -> 5 | BC13: =(IF('Water Report'!$O$13>0,'Water Report'!$O$13,0)) -> 34 | BD13: =(IF('Water Report'!$O$24>0,'Water Report'!$O$24,0)) -> 411 | BE13: =(IF('Water Report'!$O$25>0,'Water Report'!$O$25,0)) -> 157 | BF13: =(IF('Water Report'!$O$27>0,'Water Report'!$O$27,0)) -> 158 | BG13: =(IF('Section Load'!AN16>0,'Section Load'!AN16,0)) -> 1100 | BH13: =(IF('Section Load'!AO16>0,'Section Load'!AO16,0)) -> 297.9 | BI13: =(IF('Section Load'!AP16>0,'Section Load'!AP16,0)) -> 0.2 | BJ13: =(IF('Section Load'!AQ16>0,'Section Load'!AQ16,0)) -> 124.66 | BK13: =(IF('Section Load'!AR16>0,'Section Load'!AR16,0)) -> 49.8 | BL13: =(IF('Section Load'!AS16>0,'Section Load'!AS16,0)) -> 0 | BM13: =(IF('Section Load'!AT16>0,'Section Load'!AT16,0)) -> 627.44
A14: Mumbai | B14: =B13+1 -> 13 | C14: 12 | D14: 2022 | E14: =(IF('Section Load'!F17>0,'Section Load'!F17,0)) -> 3155.31 | F14: =(IF('Section Load'!G17>0,'Section Load'!G17,0)) -> 989 | G14: =(IF('Section Load'!H17>0,'Section Load'!H17,0)) -> 2439 | H14: =(IF('Section Load'!I17>0,'Section Load'!I17,0)) -> 3939 | I14: =(IF('Section Load'!J17>0,'Section Load'!J17,0)) -> 3994.19 | J14: =(IF('Section Load'!K17>0,'Section Load'!K17,0)) -> 2292.15 | K14: =(IF('Section Load'!L17>0,'Section Load'!L17,0)) -> 1259 | L14: =(IF('Section Load'!M17>0,'Section Load'!M17,0)) -> 1045 | ... AL14: =(IF('Section Load'!AM17>0,'Section Load'!AM17,0)) -> 727 | AM14: =(IF('Water Report'!$P$7>0,'Water Report'!$P$7,0)) -> 100 | AN14: =(IF('Water Report'!$P$8>0,'Water Report'!$P$8,0)) -> 20 | AO14: =(IF('Water Report'!$P$9>0,'Water Report'!$P$9,0)) -> 125 | AP14: =(IF('Water Report'!$P$10>0,'Water Report'!$P$10,0)) -> 8 | AQ14: =(IF('Water Report'!$P$11>0,'Water Report'!$P$11,0)) -> 18 | AR14: =(IF('Water Report'!$P$13>0,'Water Report'!$P$13,0)) -> 30 | AS14: =(IF('Water Report'!$P$14>0,'Water Report'!$P$14,0)) -> 5 | AT14: =(IF('Water Report'!$P$15>0,'Water Report'!$P$15,0)) -> 7 | AU14: =(IF('Water Report'!$P$17>0,'Water Report'!$P$17,0)) -> 0 | AV14: =(IF('Water Report'!$P$18>0,'Water Report'!$P$18,0)) -> 12 | AW14: =(IF('Water Report'!$P$19>0,'Water Report'!$P$19,0)) -> 13 | AX14: =(IF('Water Report'!$P$21>0,'Water Report'!$P$21,0)) -> 110 | AY14: =(IF('Water Report'!$P$22>0,'Water Report'!$P$22,0)) -> 0 | AZ14: =(IF('Water Report'!$P$23>0,'Water Report'!$P$23,0)) -> 0 | BA14: =(IF('Water Report'!$P$14>0,'Water Report'!$P$14,0)) -> 5 | BB14: =(IF('Water Report'!$P$15>0,'Water Report'!$P$15,0)) -> 7 | BC14: =(IF('Water Report'!$P$13>0,'Water Report'!$P$13,0)) -> 30 | BD14: =(IF('Water Report'!$P$24>0,'Water Report'!$P$24,0)) -> 378 | BE14: =(IF('Water Report'!$P$25>0,'Water Report'!$P$25,0)) -> 163 | BF14: =(IF('Water Report'!$P$27>0,'Water Report'!$P$27,0)) -> 140 | BG14: =(IF('Section Load'!AN17>0,'Section Load'!AN17,0)) -> 1014 | BH14: =(IF('Section Load'!AO17>0,'Section Load'!AO17,0)) -> 298 | BI14: =(IF('Section Load'!AP17>0,'Section Load'!AP17,0)) -> 0 | BJ14: =(IF('Section Load'!AQ17>0,'Section Load'!AQ17,0)) -> 111 | BK14: =(IF('Section Load'!AR17>0,'Section Load'!AR17,0)) -> 47 | BL14: =(IF('Section Load'!AS17>0,'Section Load'!AS17,0)) -> 0 | BM14: =(IF('Section Load'!AT17>0,'Section Load'!AT17,0)) -> 558.4
A15: Mumbai | B15: =B14+1 -> 14 | C15: 12 | D15: 2022 | E15: =(IF('Section Load'!F18>0,'Section Load'!F18,0)) -> 3419.69 | F15: =(IF('Section Load'!G18>0,'Section Load'!G18,0)) -> 1067 | G15: =(IF('Section Load'!H18>0,'Section Load'!H18,0)) -> 2633 | H15: =(IF('Section Load'!I18>0,'Section Load'!I18,0)) -> 3636 | I15: =(IF('Section Load'!J18>0,'Section Load'!J18,0)) -> 7314.81 | J15: =(IF('Section Load'!K18>0,'Section Load'!K18,0)) -> 2841.85 | K15: =(IF('Section Load'!L18>0,'Section Load'!L18,0)) -> 1665 | L15: =(IF('Section Load'!M18>0,'Section Load'!M18,0)) -> 1258 | ... AL15: =(IF('Section Load'!AM18>0,'Section Load'!AM18,0)) -> 830 | AM15: =(IF('Water Report'!$Q$7>0,'Water Report'!$Q$7,0)) -> 123 | AN15: =(IF('Water Report'!$Q$8>0,'Water Report'!$Q$8,0)) -> 26 | AO15: =(IF('Water Report'!$Q$9>0,'Water Report'!$Q$9,0)) -> 149 | AP15: =(IF('Water Report'!$Q$10>0,'Water Report'!$Q$10,0)) -> 13 | AQ15: =(IF('Water Report'!$Q$11>0,'Water Report'!$Q$11,0)) -> 22 | AR15: =(IF('Water Report'!$Q$13>0,'Water Report'!$Q$13,0)) -> 29 | AS15: =(IF('Water Report'!$Q$14>0,'Water Report'!$Q$14,0)) -> 10 | AT15: =(IF('Water Report'!$Q$15>0,'Water Report'!$Q$15,0)) -> 8 | AU15: =(IF('Water Report'!$Q$17>0,'Water Report'!$Q$17,0)) -> 0 | AV15: =(IF('Water Report'!$Q$18>0,'Water Report'!$Q$18,0)) -> 11 | AW15: =(IF('Water Report'!$Q$19>0,'Water Report'!$Q$19,0)) -> 12 | AX15: =(IF('Water Report'!$Q$21>0,'Water Report'!$Q$21,0)) -> 135 | AY15: =(IF('Water Report'!$Q$22>0,'Water Report'!$Q$22,0)) -> 0 | AZ15: =(IF('Water Report'!$Q$23>0,'Water Report'!$Q$23,0)) -> 39 | BA15: =(IF('Water Report'!$Q$14>0,'Water Report'!$Q$14,0)) -> 10 | BB15: =(IF('Water Report'!$Q$15>0,'Water Report'!$Q$15,0)) -> 8 | BC15: =(IF('Water Report'!$Q$13>0,'Water Report'!$Q$13,0)) -> 29 | BD15: =(IF('Water Report'!$Q$24>0,'Water Report'!$Q$24,0)) -> 377 | BE15: =(IF('Water Report'!$Q$25>0,'Water Report'!$Q$25,0)) -> 202 | BF15: =(IF('Water Report'!$Q$27>0,'Water Report'!$Q$27,0)) -> 203 | BG15: =(IF('Section Load'!AN18>0,'Section Load'!AN18,0)) -> 1060 | BH15: =(IF('Section Load'!AO18>0,'Section Load'!AO18,0)) -> 291 | BI15: =(IF('Section Load'!AP18>0,'Section Load'!AP18,0)) -> 0.2 | BJ15: =(IF('Section Load'!AQ18>0,'Section Load'!AQ18,0)) -> 122 | BK15: =(IF('Section Load'!AR18>0,'Section Load'!AR18,0)) -> 47 | BL15: =(IF('Section Load'!AS18>0,'Section Load'!AS18,0)) -> 0 | BM15: =(IF('Section Load'!AT18>0,'Section Load'!AT18,0)) -> 599.8
A16: Mumbai | B16: =B15+1 -> 15 | C16: 12 | D16: 2022 | E16: =(IF('Section Load'!F19>0,'Section Load'!F19,0)) -> 3092 | F16: =(IF('Section Load'!G19>0,'Section Load'!G19,0)) -> 1075 | G16: =(IF('Section Load'!H19>0,'Section Load'!H19,0)) -> 591.76 | H16: =(IF('Section Load'!I19>0,'Section Load'!I19,0)) -> 4668 | I16: =(IF('Section Load'!J19>0,'Section Load'!J19,0)) -> 6679.45 | J16: =(IF('Section Load'!K19>0,'Section Load'!K19,0)) -> 4668 | K16: =(IF('Section Load'!L19>0,'Section Load'!L19,0)) -> 1451 | L16: =(IF('Section Load'!M19>0,'Section Load'!M19,0)) -> 1125 | ... AL16: =(IF('Section Load'!AM19>0,'Section Load'!AM19,0)) -> 738 | AM16: =(IF('Water Report'!$R$7>0,'Water Report'!$R$7,0)) -> 107 | AN16: =(IF('Water Report'!$R$8>0,'Water Report'!$R$8,0)) -> 81 | AO16: =(IF('Water Report'!$R$9>0,'Water Report'!$R$9,0)) -> 142 | AP16: =(IF('Water Report'!$R$10>0,'Water Report'!$R$10,0)) -> 8 | AQ16: =(IF('Water Report'!$R$11>0,'Water Report'!$R$11,0)) -> 25 | AR16: =(IF('Water Report'!$R$13>0,'Water Report'!$R$13,0)) -> 34 | AS16: =(IF('Water Report'!$R$14>0,'Water Report'!$R$14,0)) -> 7 | AT16: =(IF('Water Report'!$R$15>0,'Water Report'!$R$15,0)) -> 11 | AU16: =(IF('Water Report'!$R$17>0,'Water Report'!$R$17,0)) -> 0 | AV16: =(IF('Water Report'!$R$18>0,'Water Report'!$R$18,0)) -> 10 | AW16: =(IF('Water Report'!$R$19>0,'Water Report'!$R$19,0)) -> 13 | AX16: =(IF('Water Report'!$R$21>0,'Water Report'!$R$21,0)) -> 121 | AY16: =(IF('Water Report'!$R$22>0,'Water Report'!$R$22,0)) -> 0 | AZ16: =(IF('Water Report'!$R$23>0,'Water Report'!$R$23,0)) -> 2 | BA16: =(IF('Water Report'!$R$14>0,'Water Report'!$R$14,0)) -> 7 | BB16: =(IF('Water Report'!$R$15>0,'Water Report'!$R$15,0)) -> 11 | BC16: =(IF('Water Report'!$R$13>0,'Water Report'!$R$13,0)) -> 34 | BD16: =(IF('Water Report'!$R$24>0,'Water Report'!$R$24,0)) -> 382 | BE16: =(IF('Water Report'!$R$25>0,'Water Report'!$R$25,0)) -> 193 | BF16: =(IF('Water Report'!$R$27>0,'Water Report'!$R$27,0)) -> 157 | BG16: =(IF('Section Load'!AN19>0,'Section Load'!AN19,0)) -> 1060 | BH16: =(IF('Section Load'!AO19>0,'Section Load'!AO19,0)) -> 113 | BI16: =(IF('Section Load'!AP19>0,'Section Load'!AP19,0)) -> 0 | BJ16: =(IF('Section Load'!AQ19>0,'Section Load'!AQ19,0)) -> 117 | BK16: =(IF('Section Load'!AR19>0,'Section Load'!AR19,0)) -> 59 | BL16: =(IF('Section Load'!AS19>0,'Section Load'!AS19,0)) -> 0 | BM16: =(IF('Section Load'!AT19>0,'Section Load'!AT19,0)) -> 771
A17: Mumbai | B17: =B16+1 -> 16 | C17: 12 | D17: 2022 | E17: =(IF('Section Load'!F20>0,'Section Load'!F20,0)) -> 3286.12 | F17: =(IF('Section Load'!G20>0,'Section Load'!G20,0)) -> 1038.43 | G17: =(IF('Section Load'!H20>0,'Section Load'!H20,0)) -> 0.59 | H17: =(IF('Section Load'!I20>0,'Section Load'!I20,0)) -> 4071.46 | I17: =(IF('Section Load'!J20>0,'Section Load'!J20,0)) -> 6364.66 | J17: =(IF('Section Load'!K20>0,'Section Load'!K20,0)) -> 5085 | K17: =(IF('Section Load'!L20>0,'Section Load'!L20,0)) -> 1329.27 | L17: =(IF('Section Load'!M20>0,'Section Load'!M20,0)) -> 1024.79 | ... AL17: =(IF('Section Load'!AM20>0,'Section Load'!AM20,0)) -> 697 | AM17: =(IF('Water Report'!$S$7>0,'Water Report'!$S$7,0)) -> 161.4 | AN17: =(IF('Water Report'!$S$8>0,'Water Report'!$S$8,0)) -> 59 | AO17: =(IF('Water Report'!$S$9>0,'Water Report'!$S$9,0)) -> 149 | AP17: =(IF('Water Report'!$S$10>0,'Water Report'!$D$10,0)) -> 10 | AQ17: =(IF('Water Report'!$S$11>0,'Water Report'!$D$11,0)) -> 19 | AR17: =(IF('Water Report'!$S$13>0,'Water Report'!$D$13,0)) -> 45 | AS17: =(IF('Water Report'!$S$14>0,'Water Report'!$D$14,0)) -> 5 | AT17: =(IF('Water Report'!$S$15>0,'Water Report'!$D$15,0)) -> 8 | AU17: =(IF('Water Report'!$S$17>0,'Water Report'!$D$17,0)) -> 2 | AV17: =(IF('Water Report'!$S$18>0,'Water Report'!$D$18,0)) -> 11 | AW17: =(IF('Water Report'!$S$19>0,'Water Report'!$D$19,0)) -> 13 | AX17: =(IF('Water Report'!$S$21>0,'Water Report'!$D$21,0)) -> 42 | AY17: =(IF('Water Report'!$S$22>0,'Water Report'!$D$22,0)) -> 0 | AZ17: =(IF('Water Report'!$S$23>0,'Water Report'!$D$23,0)) -> 0 | BA17: =(IF('Water Report'!$S$14>0,'Water Report'!$D$14,0)) -> 5 | BB17: =(IF('Water Report'!$S$15>0,'Water Report'!$D$15,0)) -> 8 | BC17: =(IF('Water Report'!$S$13>0,'Water Report'!$D$13,0)) -> 45 | BD17: =(IF('Water Report'!$S$24>0,'Water Report'!$D$24,0)) -> 303 | BE17: =(IF('Water Report'!$S$25>0,'Water Report'!$D$25,0)) -> 183 | BF17: =(IF('Water Report'!$S$27>0,'Water Report'!$D$27,0)) -> 87 | BG17: =(IF('Section Load'!AN20>0,'Section Load'!AN20,0)) -> 1026 | BH17: =(IF('Section Load'!AO20>0,'Section Load'!AO20,0)) -> 476 | BI17: =(IF('Section Load'!AP20>0,'Section Load'!AP20,0)) -> 0 | BJ17: =(IF('Section Load'!AQ20>0,'Section Load'!AQ20,0)) -> 104.98 | BK17: =(IF('Section Load'!AR20>0,'Section Load'!AR20,0)) -> 47 | BL17: =(IF('Section Load'!AS20>0,'Section Load'!AS20,0)) -> 0 | BM17: =(IF('Section Load'!AT20>0,'Section Load'!AT20,0)) -> 398.02
A18: Mumbai | B18: =B17+1 -> 17 | C18: 12 | D18: 2022 | E18: =(IF('Section Load'!F21>0,'Section Load'!F21,0)) -> 3112.34 | F18: =(IF('Section Load'!G21>0,'Section Load'!G21,0)) -> 1046.19 | G18: =(IF('Section Load'!H21>0,'Section Load'!H21,0)) -> 0 | H18: =(IF('Section Load'!I21>0,'Section Load'!I21,0)) -> 4177.52 | I18: =(IF('Section Load'!J21>0,'Section Load'!J21,0)) -> 5853 | J18: =(IF('Section Load'!K21>0,'Section Load'!K21,0)) -> 2554.59 | K18: =(IF('Section Load'!L21>0,'Section Load'!L21,0)) -> 1633.64 | L18: =(IF('Section Load'!M21>0,'Section Load'!M21,0)) -> 1147.02 | ... AL18: =(IF('Section Load'!AM21>0,'Section Load'!AM21,0)) -> 818 | AM18: =(IF('Water Report'!$T$7>0,'Water Report'!$T$7,0)) -> 163.6 | AN18: =(IF('Water Report'!$T$8>0,'Water Report'!$T$8,0)) -> 83 | AO18: =(IF('Water Report'!$T$9>0,'Water Report'!$T$9,0)) -> 153 | AP18: =(IF('Water Report'!$T$10>0,'Water Report'!$T$10,0)) -> 14 | AQ18: =(IF('Water Report'!$T$11>0,'Water Report'!$T$11,0)) -> 33 | AR18: =(IF('Water Report'!$T$13>0,'Water Report'!$T$13,0)) -> 39 | AS18: =(IF('Water Report'!$T$14>0,'Water Report'!$T$14,0)) -> 12 | AT18: =(IF('Water Report'!$T$15>0,'Water Report'!$T$15,0)) -> 6 | AU18: =(IF('Water Report'!$T$17>0,'Water Report'!$T$17,0)) -> 2 | AV18: =(IF('Water Report'!$T$18>0,'Water Report'!$T$18,0)) -> 11 | AW18: =(IF('Water Report'!$T$19>0,'Water Report'!$T$19,0)) -> 14 | AX18: =(IF('Water Report'!$T$21>0,'Water Report'!$T$21,0)) -> 140 | AY18: =(IF('Water Report'!$T$22>0,'Water Report'!$T$22,0)) -> 0 | AZ18: =(IF('Water Report'!$T$23>0,'Water Report'!$T$23,0)) -> 0 | BA18: =(IF('Water Report'!$T$14>0,'Water Report'!$T$14,0)) -> 12 | BB18: =(IF('Water Report'!$T$15>0,'Water Report'!$T$15,0)) -> 6 | BC18: =(IF('Water Report'!$T$13>0,'Water Report'!$T$13,0)) -> 39 | BD18: =(IF('Water Report'!$T$24>0,'Water Report'!$T$24,0)) -> 353 | BE18: =(IF('Water Report'!$T$25>0,'Water Report'!$T$25,0)) -> 218 | BF18: =(IF('Water Report'!$T$27>0,'Water Report'!$T$27,0)) -> 179 | BG18: =(IF('Section Load'!AN21>0,'Section Load'!AN21,0)) -> 1093 | BH18: =(IF('Section Load'!AO21>0,'Section Load'!AO21,0)) -> 299.35 | BI18: =(IF('Section Load'!AP21>0,'Section Load'!AP21,0)) -> 0 | BJ18: =(IF('Section Load'!AQ21>0,'Section Load'!AQ21,0)) -> 126.02 | BK18: =(IF('Section Load'!AR21>0,'Section Load'!AR21,0)) -> 48 | BL18: =(IF('Section Load'!AS21>0,'Section Load'!AS21,0)) -> 0 | BM18: =(IF('Section Load'!AT21>0,'Section Load'!AT21,0)) -> 619.63
A19: Mumbai | B19: =B18+1 -> 18 | C19: 12 | D19: 2022 | E19: =(IF('Section Load'!F22>0,'Section Load'!F22,0)) -> 3141.48 | F19: =(IF('Section Load'!G22>0,'Section Load'!G22,0)) -> 1024.29 | G19: =(IF('Section Load'!H22>0,'Section Load'!H22,0)) -> 0 | H19: =(IF('Section Load'!I22>0,'Section Load'!I22,0)) -> 4065.21 | I19: =(IF('Section Load'!J22>0,'Section Load'!J22,0)) -> 4692.33 | J19: =(IF('Section Load'!K22>0,'Section Load'!K22,0)) -> 2839.48 | K19: =(IF('Section Load'!L22>0,'Section Load'!L22,0)) -> 1261.09 | L19: =(IF('Section Load'!M22>0,'Section Load'!M22,0)) -> 1445.09 | ... AL19: =(IF('Section Load'!AM22>0,'Section Load'!AM22,0)) -> 831 | AM19: =(IF('Water Report'!$U$7>0,'Water Report'!$U$7,0)) -> 112.5 | AN19: =(IF('Water Report'!$U$8>0,'Water Report'!$U$8,0)) -> 76 | AO19: =(IF('Water Report'!$U$9>0,'Water Report'!$U$9,0)) -> 140 | AP19: =(IF('Water Report'!$U$10>0,'Water Report'!$U$10,0)) -> 10 | AQ19: =(IF('Water Report'!$U$11>0,'Water Report'!$U$11,0)) -> 22 | AR19: =(IF('Water Report'!$U$13>0,'Water Report'!$U$13,0)) -> 21 | AS19: =(IF('Water Report'!$U$14>0,'Water Report'!$U$14,0)) -> 5 | AT19: =(IF('Water Report'!$U$15>0,'Water Report'!$U$15,0)) -> 7 | AU19: =(IF('Water Report'!$U$17>0,'Water Report'!$U$17,0)) -> 2 | AV19: =(IF('Water Report'!$U$18>0,'Water Report'!$U$18,0)) -> 12 | AW19: =(IF('Water Report'!$U$19>0,'Water Report'!$U$19,0)) -> 13 | AX19: =(IF('Water Report'!$U$21>0,'Water Report'!$U$21,0)) -> 183 | AY19: =(IF('Water Report'!$U$22>0,'Water Report'!$U$22,0)) -> 0 | AZ19: =(IF('Water Report'!$U$23>0,'Water Report'!$U$23,0)) -> 0 | BA19: =(IF('Water Report'!$U$14>0,'Water Report'!$U$14,0)) -> 5 | BB19: =(IF('Water Report'!$U$15>0,'Water Report'!$U$15,0)) -> 7 | BC19: =(IF('Water Report'!$U$13>0,'Water Report'!$U$13,0)) -> 21 | BD19: =(IF('Water Report'!$U$24>0,'Water Report'!$U$24,0)) -> 307 | BE19: =(IF('Water Report'!$U$25>0,'Water Report'!$U$25,0)) -> 184 | BF19: =(IF('Water Report'!$U$27>0,'Water Report'!$U$27,0)) -> 204 | BG19: =(IF('Section Load'!AN22>0,'Section Load'!AN22,0)) -> 1164 | BH19: =(IF('Section Load'!AO22>0,'Section Load'!AO22,0)) -> 292.18 | BI19: =(IF('Section Load'!AP22>0,'Section Load'!AP22,0)) -> 0 | BJ19: =(IF('Section Load'!AQ22>0,'Section Load'!AQ22,0)) -> 148 | BK19: =(IF('Section Load'!AR22>0,'Section Load'!AR22,0)) -> 55 | BL19: =(IF('Section Load'!AS22>0,'Section Load'!AS22,0)) -> 0 | BM19: =(IF('Section Load'!AT22>0,'Section Load'!AT22,0)) -> 668.82
A20: Mumbai | B20: =B19+1 -> 19 | C20: 12 | D20: 2022 | E20: =(IF('Section Load'!F23>0,'Section Load'!F23,0)) -> 3279.57 | F20: =(IF('Section Load'!G23>0,'Section Load'!G23,0)) -> 1033.45 | G20: =(IF('Section Load'!H23>0,'Section Load'!H23,0)) -> 0 | H20: =(IF('Section Load'!I23>0,'Section Load'!I23,0)) -> 4100.43 | I20: =(IF('Section Load'!J23>0,'Section Load'!J23,0)) -> 3758.08 | J20: =(IF('Section Load'!K23>0,'Section Load'!K23,0)) -> 2408.12 | K20: =(IF('Section Load'!L23>0,'Section Load'!L23,0)) -> 1329.59 | L20: =(IF('Section Load'!M23>0,'Section Load'!M23,0)) -> 956.6 | ... AL20: =(IF('Section Load'!AM23>0,'Section Load'!AM23,0)) -> 713 | AM20: =(IF('Water Report'!$V$7>0,'Water Report'!$V$7,0)) -> 102.5 | AN20: =(IF('Water Report'!$V$8>0,'Water Report'!$V$8,0)) -> 43 | AO20: =(IF('Water Report'!$V$9>0,'Water Report'!$V$9,0)) -> 121 | AP20: =(IF('Water Report'!$V$10>0,'Water Report'!$V$10,0)) -> 8 | AQ20: =(IF('Water Report'!$V$11>0,'Water Report'!$V$11,0)) -> 19 | AR20: =(IF('Water Report'!$V$13>0,'Water Report'!$V$13,0)) -> 26 | AS20: =(IF('Water Report'!$V$14>0,'Water Report'!$V$14,0)) -> 5 | AT20: =(IF('Water Report'!$V$15>0,'Water Report'!$V$15,0)) -> 7 | AU20: =(IF('Water Report'!$V$17>0,'Water Report'!$V$17,0)) -> 2 | AV20: =(IF('Water Report'!$V$18>0,'Water Report'!$V$18,0)) -> 12 | AW20: =(IF('Water Report'!$V$19>0,'Water Report'!$V$19,0)) -> 12 | AX20: =(IF('Water Report'!$V$21>0,'Water Report'!$V$21,0)) -> 92 | AY20: =(IF('Water Report'!$V$22>0,'Water Report'!$V$22,0)) -> 0 | AZ20: =(IF('Water Report'!$V$23>0,'Water Report'!$V$23,0)) -> 0 | BA20: =(IF('Water Report'!$V$14>0,'Water Report'!$V$14,0)) -> 5 | BB20: =(IF('Water Report'!$V$15>0,'Water Report'!$V$15,0)) -> 7 | BC20: =(IF('Water Report'!$V$13>0,'Water Report'!$V$13,0)) -> 26 | BD20: =(IF('Water Report'!$V$24>0,'Water Report'!$V$24,0)) -> 388 | BE20: =(IF('Water Report'!$V$25>0,'Water Report'!$V$25,0)) -> 160 | BF20: =(IF('Water Report'!$V$27>0,'Water Report'!$V$27,0)) -> 118 | BG20: =(IF('Section Load'!AN23>0,'Section Load'!AN23,0)) -> 1022 | BH20: =(IF('Section Load'!AO23>0,'Section Load'!AO23,0)) -> 298.36 | BI20: =(IF('Section Load'!AP23>0,'Section Load'!AP23,0)) -> 0 | BJ20: =(IF('Section Load'!AQ23>0,'Section Load'!AQ23,0)) -> 91 | BK20: =(IF('Section Load'!AR23>0,'Section Load'!AR23,0)) -> 56 | BL20: =(IF('Section Load'!AS23>0,'Section Load'!AS23,0)) -> 0 | BM20: =(IF('Section Load'!AT23>0,'Section Load'!AT23,0)) -> 576.64
A21: Mumbai | B21: =B20+1 -> 20 | C21: 12 | D21: 2022 | E21: =(IF('Section Load'!F24>0,'Section Load'!F24,0)) -> 3272.08 | F21: =(IF('Section Load'!G24>0,'Section Load'!G24,0)) -> 1016.64 | G21: =(IF('Section Load'!H24>0,'Section Load'!H24,0)) -> 0 | H21: =(IF('Section Load'!I24>0,'Section Load'!I24,0)) -> 4036.38 | I21: =(IF('Section Load'!J24>0,'Section Load'!J24,0)) -> 3723.72 | J21: =(IF('Section Load'!K24>0,'Section Load'!K24,0)) -> 2528.81 | K21: =(IF('Section Load'!L24>0,'Section Load'!L24,0)) -> 1771.41 | L21: =(IF('Section Load'!M24>0,'Section Load'!M24,0)) -> 796.5 | ... AL21: =(IF('Section Load'!AM24>0,'Section Load'!AM24,0)) -> 718 | AM21: =(IF('Water Report'!$W$7>0,'Water Report'!$W$7,0)) -> 116 | AN21: =(IF('Water Report'!$W$8>0,'Water Report'!$W$8,0)) -> 32 | AO21: =(IF('Water Report'!$W$9>0,'Water Report'!$W$9,0)) -> 140 | AP21: =(IF('Water Report'!$W$10>0,'Water Report'!$W$10,0)) -> 12 | AQ21: =(IF('Water Report'!$W$11>0,'Water Report'!$W$11,0)) -> 22 | AR21: =(IF('Water Report'!$W$13>0,'Water Report'!$W$13,0)) -> 32 | AS21: =(IF('Water Report'!$W$14>0,'Water Report'!$W$14,0)) -> 3 | AT21: =(IF('Water Report'!$W$15>0,'Water Report'!$W$15,0)) -> 6 | AU21: =(IF('Water Report'!$W$17>0,'Water Report'!$W$17,0)) -> 1 | AV21: =(IF('Water Report'!$W$18>0,'Water Report'!$W$18,0)) -> 12 | AW21: =(IF('Water Report'!$W$19>0,'Water Report'!$W$19,0)) -> 15 | AX21: =(IF('Water Report'!$W$21>0,'Water Report'!$W$21,0)) -> 152 | AY21: =(IF('Water Report'!$W$22>0,'Water Report'!$W$22,0)) -> 0 | AZ21: =(IF('Water Report'!$W$23>0,'Water Report'!$W$23,0)) -> 0 | BA21: =(IF('Water Report'!$W$14>0,'Water Report'!$W$14,0)) -> 3 | BB21: =(IF('Water Report'!$W$15>0,'Water Report'!$W$15,0)) -> 6 | BC21: =(IF('Water Report'!$W$13>0,'Water Report'!$W$13,0)) -> 32 | BD21: =(IF('Water Report'!$W$24>0,'Water Report'!$W$24,0)) -> 289 | BE21: =(IF('Water Report'!$W$25>0,'Water Report'!$W$25,0)) -> 183 | BF21: =(IF('Water Report'!$W$27>0,'Water Report'!$W$27,0)) -> 184 | BG21: =(IF('Section Load'!AN24>0,'Section Load'!AN24,0)) -> 1116 | BH21: =(IF('Section Load'!AO24>0,'Section Load'!AO24,0)) -> 286.11 | BI21: =(IF('Section Load'!AP24>0,'Section Load'!AP24,0)) -> 0 | BJ21: =(IF('Section Load'!AQ24>0,'Section Load'!AQ24,0)) -> 94 | BK21: =(IF('Section Load'!AR24>0,'Section Load'!AR24,0)) -> 40 | BL21: =(IF('Section Load'!AS24>0,'Section Load'!AS24,0)) -> 0 | BM21: =(IF('Section Load'!AT24>0,'Section Load'!AT24,0)) -> 695.89
A22: Mumbai | B22: =B21+1 -> 21 | C22: 12 | D22: 2022 | E22: =(IF('Section Load'!F25>0,'Section Load'!F25,0)) -> 3207.41 | F22: =(IF('Section Load'!G25>0,'Section Load'!G25,0)) -> 1355.31 | G22: =(IF('Section Load'!H25>0,'Section Load'!H25,0)) -> 1247.41 | H22: =(IF('Section Load'!I25>0,'Section Load'!I25,0)) -> 3398 | I22: =(IF('Section Load'!J25>0,'Section Load'!J25,0)) -> 3921 | J22: =(IF('Section Load'!K25>0,'Section Load'!K25,0)) -> 2438 | K22: =(IF('Section Load'!L25>0,'Section Load'!L25,0)) -> 1174 | L22: =(IF('Section Load'!M25>0,'Section Load'!M25,0)) -> 863 | ... AL22: =(IF('Section Load'!AM25>0,'Section Load'!AM25,0)) -> 788 | AM22: =(IF('Water Report'!$X$7>0,'Water Report'!$X$7,0)) -> 112 | AN22: =(IF('Water Report'!$X$8>0,'Water Report'!$X$8,0)) -> 70 | AO22: =(IF('Water Report'!$X$9>0,'Water Report'!$X$9,0)) -> 128 | AP22: =(IF('Water Report'!$X$10>0,'Water Report'!$X$10,0)) -> 8 | AQ22: =(IF('Water Report'!$X$11>0,'Water Report'!$X$11,0)) -> 21 | AR22: =(IF('Water Report'!$X$13>0,'Water Report'!$X$13,0)) -> 22 | AS22: =(IF('Water Report'!$X$14>0,'Water Report'!$X$14,0)) -> 8 | AT22: =(IF('Water Report'!$X$15>0,'Water Report'!$X$15,0)) -> 11 | AU22: =(IF('Water Report'!$X$17>0,'Water Report'!$X$17,0)) -> 0 | AV22: =(IF('Water Report'!$X$18>0,'Water Report'!$X$18,0)) -> 14 | AW22: =(IF('Water Report'!$X$19>0,'Water Report'!$X$19,0)) -> 12 | AX22: =(IF('Water Report'!$X$21>0,'Water Report'!$X$21,0)) -> 137 | AY22: =(IF('Water Report'!$X$22>0,'Water Report'!$X$22,0)) -> 0 | AZ22: =(IF('Water Report'!$X$23>0,'Water Report'!$X$23,0)) -> 24 | BA22: =(IF('Water Report'!$X$14>0,'Water Report'!$X$14,0)) -> 8 | BB22: =(IF('Water Report'!$X$15>0,'Water Report'!$X$15,0)) -> 11 | BC22: =(IF('Water Report'!$X$13>0,'Water Report'!$X$13,0)) -> 22 | BD22: =(IF('Water Report'!$X$24>0,'Water Report'!$X$24,0)) -> 360 | BE22: =(IF('Water Report'!$X$25>0,'Water Report'!$X$25,0)) -> 176 | BF22: =(IF('Water Report'!$X$27>0,'Water Report'!$X$27,0)) -> 183 | BG22: =(IF('Section Load'!AN25>0,'Section Load'!AN25,0)) -> 1103 | BH22: =(IF('Section Load'!AO25>0,'Section Load'!AO25,0)) -> 290 | BI22: =(IF('Section Load'!AP25>0,'Section Load'!AP25,0)) -> 0 | BJ22: =(IF('Section Load'!AQ25>0,'Section Load'!AQ25,0)) -> 115 | BK22: =(IF('Section Load'!AR25>0,'Section Load'!AR25,0)) -> 60 | BL22: =(IF('Section Load'!AS25>0,'Section Load'!AS25,0)) -> 0 | BM22: =(IF('Section Load'!AT25>0,'Section Load'!AT25,0)) -> 638
